setblock ~1 ~0 ~65 stained_hardened_clay 6  
fill ~6 ~0 ~11 ~14 ~0 ~11 planks 1  
fill ~6 ~0 ~53 ~14 ~0 ~53 planks 1  
fill ~6 ~0 ~54 ~14 ~0 ~54 planks 1  
fill ~6 ~0 ~55 ~9 ~0 ~55 planks 1  
fill ~6 ~0 ~56 ~14 ~0 ~56 planks 1  
fill ~6 ~0 ~57 ~14 ~0 ~57 planks 1  
fill ~7 ~0 ~7 ~12 ~0 ~7 planks 1  
fill ~7 ~0 ~8 ~13 ~0 ~8 planks 1  
fill ~7 ~0 ~9 ~13 ~0 ~9 planks 1  
fill ~7 ~0 ~10 ~9 ~0 ~10 planks 1  
fill ~7 ~0 ~12 ~14 ~0 ~12 planks 1  
fill ~7 ~0 ~13 ~13 ~0 ~13 planks 1  
fill ~7 ~0 ~52 ~13 ~0 ~52 planks 1  
fill ~7 ~0 ~58 ~13 ~0 ~58 planks 1  
fill ~8 ~0 ~6 ~9 ~0 ~6 planks 1  
fill ~8 ~0 ~14 ~17 ~0 ~14 planks 1  
fill ~8 ~0 ~51 ~14 ~0 ~51 planks 1  
fill ~8 ~0 ~59 ~12 ~0 ~59 planks 1  
fill ~12 ~0 ~10 ~14 ~0 ~10 planks 1  
fill ~12 ~0 ~55 ~14 ~0 ~55 planks 1  
fill ~15 ~0 ~15 ~16 ~0 ~15 log 1  
fill ~15 ~0 ~18 ~18 ~0 ~18 log 1 
setblock ~15 ~0 ~20 log 1  
fill ~15 ~0 ~21 ~17 ~0 ~21 planks 1 
setblock ~15 ~0 ~23 planks 1  
fill ~15 ~0 ~25 ~15 ~0 ~28 planks 1  
fill ~15 ~0 ~30 ~15 ~0 ~31 planks 1  
fill ~15 ~0 ~34 ~19 ~0 ~34 planks 1  
fill ~15 ~0 ~35 ~15 ~13 ~35 log 1  
fill ~15 ~0 ~38 ~15 ~0 ~39 planks 1 
setblock ~15 ~0 ~40 log 1 
setblock ~15 ~0 ~42 log 1  
fill ~15 ~0 ~44 ~15 ~0 ~45 planks 1  
fill ~15 ~0 ~47 ~16 ~0 ~47 log 1  
fill ~15 ~0 ~50 ~18 ~0 ~50 planks 1 
setblock ~15 ~0 ~51 log 1  
fill ~16 ~0 ~16 ~22 ~0 ~16 log 1  
fill ~16 ~0 ~19 ~19 ~0 ~19 planks 1  
fill ~16 ~0 ~20 ~16 ~0 ~19 planks 1  
fill ~16 ~0 ~22 ~16 ~0 ~25 log 1  
fill ~16 ~0 ~26 ~16 ~0 ~29 planks 1  
fill ~16 ~0 ~30 ~18 ~0 ~30 log 1  
fill ~16 ~0 ~31 ~20 ~0 ~31 planks 1  
fill ~16 ~0 ~32 ~17 ~0 ~32 planks 1  
fill ~16 ~0 ~33 ~16 ~0 ~31 planks 1  
fill ~16 ~0 ~35 ~18 ~0 ~35 planks 1  
fill ~16 ~0 ~36 ~16 ~0 ~37 planks 1  
fill ~16 ~0 ~38 ~16 ~0 ~39 log 1  
fill ~16 ~0 ~40 ~17 ~0 ~40 planks 1  
fill ~16 ~0 ~41 ~18 ~0 ~41 log 1 
setblock ~16 ~0 ~42 planks 1  
fill ~16 ~0 ~43 ~16 ~0 ~45 log 1  
fill ~16 ~0 ~48 ~16 ~0 ~51 planks 1 
setblock ~17 ~0 ~15 planks 1 
setblock ~17 ~0 ~17 log 1  
fill ~17 ~0 ~20 ~18 ~0 ~20 log 1  
fill ~17 ~0 ~22 ~18 ~0 ~22 planks 1  
fill ~17 ~0 ~23 ~18 ~0 ~23 planks 1  
fill ~17 ~0 ~24 ~17 ~0 ~26 log 1  
fill ~17 ~0 ~27 ~25 ~0 ~27 planks 1  
fill ~17 ~0 ~28 ~17 ~0 ~29 planks 1 
setblock ~17 ~0 ~33 log 1  
fill ~17 ~0 ~36 ~17 ~0 ~37 log 1 
setblock ~17 ~0 ~38 planks 1 
setblock ~17 ~0 ~39 log 1 
setblock ~17 ~0 ~42 log 1  
fill ~17 ~0 ~43 ~17 ~0 ~44 planks 1  
fill ~17 ~0 ~45 ~17 ~0 ~46 log 1 
setblock ~17 ~0 ~47 planks 1  
fill ~17 ~0 ~48 ~18 ~0 ~48 log 1 
setblock ~17 ~0 ~49 planks 1 
setblock ~17 ~0 ~51 log 1  
fill ~18 ~0 ~14 ~21 ~0 ~14 log 1  
fill ~18 ~0 ~15 ~19 ~0 ~15 log 1  
fill ~18 ~0 ~17 ~19 ~0 ~17 planks 1 
setblock ~18 ~0 ~21 log 1  
fill ~18 ~0 ~24 ~20 ~0 ~24 planks 1  
fill ~18 ~0 ~25 ~22 ~0 ~25 log 1 
setblock ~18 ~0 ~26 planks 1  
fill ~18 ~0 ~28 ~19 ~0 ~28 log 1  
fill ~18 ~0 ~29 ~19 ~0 ~29 planks 1 
setblock ~18 ~0 ~32 log 1  
fill ~18 ~0 ~33 ~20 ~0 ~33 planks 1  
fill ~18 ~0 ~36 ~18 ~0 ~37 planks 1  
fill ~18 ~0 ~38 ~19 ~0 ~38 concrete 14  
fill ~18 ~0 ~39 ~19 ~0 ~39 concrete 14  
fill ~18 ~0 ~40 ~29 ~0 ~40 concrete 14  
fill ~18 ~0 ~42 ~19 ~0 ~42 planks 1 
setblock ~18 ~0 ~43 log 1  
fill ~18 ~0 ~44 ~18 ~0 ~46 planks 1 
setblock ~18 ~0 ~47 log 1 
setblock ~18 ~0 ~49 log 1  
fill ~18 ~0 ~51 ~19 ~0 ~51 planks 1 
setblock ~19 ~0 ~18 planks 1  
fill ~19 ~0 ~20 ~19 ~0 ~21 planks 1  
fill ~19 ~0 ~22 ~19 ~0 ~23 log 1  
fill ~19 ~0 ~26 ~20 ~0 ~26 log 1  
fill ~19 ~0 ~30 ~21 ~0 ~30 planks 1 
setblock ~19 ~0 ~32 planks 1  
fill ~19 ~0 ~35 ~21 ~0 ~35 log 1  
fill ~19 ~0 ~36 ~19 ~0 ~35 log 1 
setblock ~19 ~0 ~37 planks 1  
fill ~19 ~0 ~41 ~30 ~0 ~41 concrete 14 
setblock ~19 ~0 ~43 planks 1 
setblock ~19 ~0 ~44 log 1  
fill ~19 ~0 ~45 ~20 ~0 ~45 planks 1  
fill ~19 ~0 ~46 ~20 ~0 ~46 planks 1  
fill ~19 ~0 ~47 ~20 ~0 ~47 planks 1  
fill ~19 ~0 ~48 ~20 ~0 ~48 planks 1  
fill ~19 ~0 ~49 ~22 ~0 ~49 planks 1  
fill ~19 ~0 ~50 ~21 ~0 ~50 log 1 
setblock ~20 ~0 ~15 planks 1  
fill ~20 ~0 ~17 ~20 ~0 ~20 log 1  
fill ~20 ~0 ~21 ~20 ~0 ~22 planks 1  
fill ~20 ~0 ~23 ~21 ~0 ~23 log 1 
setblock ~20 ~0 ~28 planks 1 
setblock ~20 ~0 ~29 log 1  
fill ~20 ~0 ~32 ~24 ~0 ~32 log 1  
fill ~20 ~0 ~34 ~23 ~0 ~34 log 1  
fill ~20 ~0 ~36 ~22 ~0 ~36 planks 1 
setblock ~20 ~0 ~37 log 1 
setblock ~20 ~0 ~38 planks 1  
fill ~20 ~0 ~39 ~21 ~0 ~39 log 1  
fill ~20 ~0 ~42 ~20 ~0 ~43 log 1  
fill ~20 ~0 ~44 ~24 ~0 ~44 planks 1 
setblock ~20 ~0 ~51 log 1  
fill ~21 ~0 ~15 ~22 ~0 ~15 log 1  
fill ~21 ~0 ~17 ~21 ~0 ~18 planks 1  
fill ~21 ~0 ~19 ~23 ~0 ~19 log 1  
fill ~21 ~0 ~20 ~22 ~0 ~20 log 1  
fill ~21 ~0 ~21 ~22 ~0 ~21 log 1  
fill ~21 ~0 ~22 ~22 ~0 ~22 planks 1  
fill ~21 ~0 ~24 ~22 ~0 ~24 log 1  
fill ~21 ~0 ~26 ~22 ~0 ~26 planks 1  
fill ~21 ~0 ~28 ~23 ~0 ~28 log 1  
fill ~21 ~0 ~29 ~24 ~0 ~29 planks 1 
setblock ~21 ~0 ~31 log 1  
fill ~21 ~0 ~33 ~22 ~0 ~33 log 1 
setblock ~21 ~0 ~37 planks 1  
fill ~21 ~0 ~38 ~24 ~0 ~38 log 1  
fill ~21 ~0 ~42 ~21 ~0 ~44 planks 1  
fill ~21 ~0 ~45 ~22 ~0 ~45 log 1  
fill ~21 ~0 ~46 ~21 ~0 ~48 log 1 
setblock ~21 ~0 ~51 planks 1 
setblock ~22 ~0 ~14 planks 1  
fill ~22 ~0 ~17 ~23 ~0 ~17 log 1  
fill ~22 ~0 ~18 ~23 ~0 ~18 planks 1 
setblock ~22 ~0 ~23 planks 1 
setblock ~22 ~0 ~30 log 1 
setblock ~22 ~0 ~31 planks 1  
fill ~22 ~0 ~35 ~23 ~0 ~35 planks 1 
setblock ~22 ~0 ~37 log 1 
setblock ~22 ~0 ~39 planks 1  
fill ~22 ~0 ~42 ~22 ~0 ~43 log 1  
fill ~22 ~0 ~46 ~23 ~0 ~46 planks 1  
fill ~22 ~0 ~47 ~23 ~0 ~47 log 1  
fill ~22 ~0 ~48 ~23 ~0 ~48 planks 1  
fill ~22 ~0 ~50 ~23 ~0 ~50 planks 1 
setblock ~22 ~0 ~51 log 1  
fill ~23 ~0 ~14 ~25 ~0 ~14 log 1  
fill ~23 ~0 ~15 ~23 ~0 ~16 planks 1  
fill ~23 ~0 ~20 ~23 ~0 ~21 planks 1  
fill ~23 ~0 ~22 ~24 ~0 ~22 log 1  
fill ~23 ~0 ~23 ~23 ~0 ~22 log 1  
fill ~23 ~0 ~24 ~23 ~0 ~25 planks 1 
setblock ~23 ~0 ~26 log 1  
fill ~23 ~0 ~30 ~24 ~0 ~30 planks 1 
setblock ~23 ~0 ~31 log 1  
fill ~23 ~0 ~33 ~24 ~0 ~33 planks 1 
setblock ~23 ~0 ~36 log 1 
setblock ~23 ~0 ~37 planks 1 
setblock ~23 ~0 ~42 planks 1 
setblock ~23 ~0 ~43 log 1 
setblock ~23 ~0 ~45 planks 1 
setblock ~23 ~0 ~49 log 1  
fill ~23 ~0 ~51 ~24 ~0 ~51 planks 1  
fill ~24 ~0 ~15 ~25 ~0 ~15 log 1  
fill ~24 ~0 ~16 ~25 ~0 ~16 log 1  
fill ~24 ~0 ~17 ~25 ~0 ~17 planks 1 
setblock ~24 ~0 ~18 log 1 
setblock ~24 ~0 ~19 planks 1  
fill ~24 ~0 ~20 ~26 ~0 ~20 log 1  
fill ~24 ~0 ~21 ~30 ~0 ~21 log 1 
setblock ~24 ~0 ~23 planks 1  
fill ~24 ~0 ~24 ~26 ~0 ~24 log 1  
fill ~24 ~0 ~25 ~29 ~0 ~25 planks 1  
fill ~24 ~0 ~26 ~24 ~0 ~25 planks 1 
setblock ~24 ~0 ~28 planks 1 
setblock ~24 ~0 ~31 planks 1  
fill ~24 ~0 ~34 ~26 ~0 ~34 planks 1 
setblock ~24 ~0 ~35 log 1  
fill ~24 ~0 ~36 ~25 ~0 ~36 planks 1 
setblock ~24 ~0 ~37 log 1 
setblock ~24 ~0 ~43 planks 1 
setblock ~24 ~0 ~46 log 1 
setblock ~24 ~0 ~50 log 1 
setblock ~25 ~0 ~18 planks 1 
setblock ~25 ~0 ~19 log 1 
setblock ~25 ~0 ~22 planks 1  
fill ~25 ~0 ~23 ~40 ~0 ~23 log 1  
fill ~25 ~0 ~26 ~26 ~0 ~26 log 1  
fill ~25 ~0 ~28 ~29 ~0 ~28 log 1  
fill ~25 ~0 ~29 ~25 ~0 ~31 log 1 
setblock ~25 ~0 ~32 planks 1  
fill ~25 ~0 ~33 ~28 ~0 ~33 log 1  
fill ~25 ~0 ~35 ~28 ~0 ~35 planks 1  
fill ~25 ~0 ~37 ~25 ~0 ~38 planks 1  
fill ~25 ~0 ~42 ~28 ~0 ~42 cobblestone 0 
setblock ~26 ~0 ~14 planks 1  
fill ~26 ~0 ~15 ~28 ~0 ~15 cobblestone 0  
fill ~26 ~0 ~16 ~31 ~0 ~16 cobblestone 0  
fill ~26 ~0 ~17 ~31 ~0 ~17 cobblestone 0 
setblock ~26 ~0 ~18 log 1  
fill ~26 ~0 ~19 ~27 ~0 ~19 planks 1  
fill ~26 ~0 ~22 ~27 ~0 ~22 log 1  
fill ~26 ~0 ~27 ~39 ~0 ~27 log 1  
fill ~26 ~0 ~29 ~26 ~0 ~31 planks 1 
setblock ~26 ~0 ~32 log 1  
fill ~26 ~0 ~36 ~27 ~0 ~36 log 1  
fill ~26 ~0 ~37 ~26 ~0 ~36 log 1 
setblock ~26 ~0 ~38 planks 1 
setblock ~26 ~0 ~45 cobblestone 0 
setblock ~27 ~0 ~14 cobblestone 0  
fill ~27 ~0 ~18 ~31 ~0 ~18 cobblestone 0 
setblock ~27 ~0 ~20 planks 1 
setblock ~27 ~0 ~24 planks 1  
fill ~27 ~0 ~26 ~30 ~0 ~26 planks 1 
setblock ~27 ~0 ~29 log 1  
fill ~27 ~0 ~30 ~28 ~0 ~30 planks 1 
setblock ~27 ~0 ~31 log 1  
fill ~27 ~0 ~32 ~29 ~0 ~32 planks 1  
fill ~27 ~0 ~34 ~28 ~0 ~34 log 1  
fill ~27 ~0 ~37 ~29 ~0 ~37 planks 1  
fill ~27 ~0 ~39 ~38 ~0 ~39 cobblestone 0  
fill ~27 ~0 ~43 ~29 ~0 ~43 cobblestone 0  
fill ~27 ~0 ~44 ~30 ~0 ~44 cobblestone 0  
fill ~27 ~0 ~46 ~31 ~0 ~46 cobblestone 0  
fill ~27 ~0 ~47 ~31 ~0 ~47 cobblestone 0  
fill ~27 ~0 ~48 ~31 ~0 ~48 cobblestone 0  
fill ~27 ~0 ~50 ~31 ~0 ~50 cobblestone 0  
fill ~27 ~0 ~51 ~31 ~0 ~51 cobblestone 0  
fill ~27 ~0 ~52 ~31 ~0 ~52 cobblestone 0  
fill ~27 ~0 ~56 ~29 ~0 ~56 stonebrick 0  
fill ~27 ~0 ~57 ~29 ~0 ~57 stonebrick 0  
fill ~27 ~0 ~58 ~29 ~0 ~58 stonebrick 0  
fill ~27 ~0 ~59 ~29 ~0 ~59 stonebrick 0  
fill ~27 ~0 ~60 ~29 ~0 ~60 stonebrick 0  
fill ~27 ~0 ~61 ~29 ~0 ~61 stonebrick 0  
fill ~27 ~0 ~62 ~29 ~0 ~62 stonebrick 0 
setblock ~28 ~0 ~14 log 1  
fill ~28 ~0 ~19 ~29 ~0 ~19 cobblestone 0  
fill ~28 ~0 ~20 ~29 ~0 ~20 log 1  
fill ~28 ~0 ~22 ~29 ~0 ~22 planks 1  
fill ~28 ~0 ~24 ~37 ~0 ~24 log 1  
fill ~28 ~0 ~29 ~30 ~0 ~29 planks 1  
fill ~28 ~0 ~31 ~29 ~0 ~31 planks 1 
setblock ~28 ~0 ~36 planks 1  
fill ~28 ~0 ~45 ~31 ~0 ~45 cobblestone 0  
fill ~28 ~0 ~49 ~31 ~0 ~49 cobblestone 0  
fill ~28 ~0 ~53 ~31 ~0 ~53 cobblestone 0  
fill ~28 ~0 ~54 ~29 ~0 ~54 stonebrick 0  
fill ~28 ~0 ~55 ~29 ~0 ~55 stonebrick 0  
fill ~29 ~0 ~14 ~30 ~0 ~14 planks 1  
fill ~29 ~0 ~15 ~29 ~0 ~14 planks 1 
setblock ~29 ~0 ~30 log 1  
fill ~29 ~0 ~33 ~29 ~0 ~34 planks 1  
fill ~29 ~0 ~35 ~30 ~0 ~35 log 1  
fill ~29 ~0 ~36 ~29 ~0 ~35 log 1  
fill ~29 ~0 ~42 ~31 ~0 ~42 concrete 14  
fill ~30 ~0 ~15 ~31 ~0 ~15 cobblestone 0 
setblock ~30 ~0 ~19 log 1  
fill ~30 ~0 ~20 ~31 ~0 ~20 cobblestone 0 
setblock ~30 ~0 ~22 log 1  
fill ~30 ~0 ~25 ~31 ~0 ~25 log 1 
setblock ~30 ~0 ~28 planks 1  
fill ~30 ~0 ~30 ~31 ~0 ~30 planks 1  
fill ~30 ~0 ~31 ~30 ~0 ~33 log 1  
fill ~30 ~0 ~34 ~31 ~0 ~34 planks 1  
fill ~30 ~0 ~36 ~31 ~0 ~36 planks 1  
fill ~30 ~0 ~38 ~35 ~0 ~38 cobblestone 0  
fill ~30 ~0 ~40 ~35 ~0 ~40 cobblestone 0  
fill ~30 ~0 ~43 ~35 ~0 ~43 concrete 14  
fill ~30 ~0 ~54 ~31 ~0 ~54 cobblestone 0  
fill ~30 ~0 ~55 ~31 ~0 ~55 cobblestone 0  
fill ~30 ~0 ~56 ~31 ~0 ~56 cobblestone 0  
fill ~30 ~0 ~57 ~31 ~0 ~57 cobblestone 0  
fill ~30 ~0 ~58 ~31 ~0 ~58 cobblestone 0  
fill ~30 ~0 ~59 ~31 ~0 ~59 cobblestone 0  
fill ~30 ~0 ~60 ~31 ~0 ~60 cobblestone 0  
fill ~30 ~0 ~61 ~31 ~0 ~61 cobblestone 0  
fill ~30 ~0 ~62 ~31 ~0 ~62 cobblestone 0 
setblock ~31 ~0 ~14 log 1 
setblock ~31 ~0 ~19 cobblestone 0  
fill ~31 ~0 ~21 ~31 ~0 ~22 cobblestone 0 
setblock ~31 ~0 ~26 log 1  
fill ~31 ~0 ~28 ~31 ~0 ~29 log 1 
setblock ~31 ~0 ~31 planks 1  
fill ~31 ~0 ~32 ~31 ~0 ~33 log 1  
fill ~31 ~0 ~35 ~34 ~0 ~35 planks 1  
fill ~31 ~0 ~41 ~34 ~0 ~41 cobblestone 0  
fill ~31 ~0 ~44 ~34 ~0 ~44 concrete 14  
fill ~32 ~0 ~14 ~33 ~0 ~14 planks 1  
fill ~32 ~0 ~15 ~33 ~0 ~15 planks 1  
fill ~32 ~0 ~16 ~33 ~0 ~16 concrete 14  
fill ~32 ~0 ~17 ~33 ~0 ~17 concrete 14  
fill ~32 ~0 ~18 ~33 ~0 ~18 concrete 14  
fill ~32 ~0 ~19 ~33 ~0 ~19 concrete 14  
fill ~32 ~0 ~20 ~33 ~0 ~20 concrete 14  
fill ~32 ~0 ~21 ~33 ~0 ~21 concrete 14  
fill ~32 ~0 ~22 ~33 ~0 ~22 concrete 14  
fill ~32 ~0 ~25 ~33 ~0 ~25 planks 1  
fill ~32 ~0 ~26 ~33 ~0 ~26 planks 1  
fill ~32 ~0 ~28 ~33 ~0 ~28 planks 1  
fill ~32 ~0 ~29 ~34 ~0 ~29 log 1  
fill ~32 ~0 ~30 ~33 ~0 ~30 log 1  
fill ~32 ~0 ~31 ~33 ~0 ~31 log 1  
fill ~32 ~0 ~32 ~33 ~0 ~32 planks 1  
fill ~32 ~0 ~33 ~33 ~0 ~33 planks 1  
fill ~32 ~0 ~34 ~33 ~0 ~34 log 1  
fill ~32 ~0 ~36 ~36 ~0 ~36 log 1  
fill ~32 ~0 ~42 ~33 ~0 ~42 cobblestone 0  
fill ~32 ~0 ~45 ~33 ~0 ~45 concrete 14  
fill ~32 ~0 ~46 ~33 ~0 ~46 concrete 14  
fill ~32 ~0 ~47 ~33 ~0 ~47 concrete 14  
fill ~32 ~0 ~48 ~33 ~0 ~48 concrete 14  
fill ~32 ~0 ~49 ~33 ~0 ~49 concrete 14  
fill ~32 ~0 ~50 ~33 ~0 ~50 concrete 14  
fill ~32 ~0 ~51 ~33 ~0 ~51 concrete 14  
fill ~32 ~0 ~52 ~33 ~0 ~52 concrete 14  
fill ~32 ~0 ~53 ~33 ~0 ~53 concrete 14  
fill ~32 ~0 ~54 ~33 ~0 ~54 concrete 14  
fill ~32 ~0 ~55 ~33 ~0 ~55 concrete 14  
fill ~32 ~0 ~56 ~33 ~0 ~56 concrete 14  
fill ~32 ~0 ~57 ~33 ~0 ~57 concrete 14  
fill ~32 ~0 ~58 ~33 ~0 ~58 concrete 14  
fill ~32 ~0 ~59 ~33 ~0 ~59 concrete 14  
fill ~32 ~0 ~60 ~33 ~0 ~60 concrete 14  
fill ~32 ~0 ~61 ~33 ~0 ~61 concrete 14  
fill ~32 ~0 ~62 ~33 ~0 ~62 concrete 14 
setblock ~34 ~0 ~14 log 1  
fill ~34 ~0 ~15 ~35 ~0 ~15 cobblestone 0  
fill ~34 ~0 ~16 ~39 ~0 ~16 cobblestone 0  
fill ~34 ~0 ~17 ~39 ~0 ~17 cobblestone 0  
fill ~34 ~0 ~18 ~38 ~0 ~18 cobblestone 0  
fill ~34 ~0 ~19 ~34 ~0 ~22 cobblestone 0  
fill ~34 ~0 ~25 ~35 ~0 ~25 log 1  
fill ~34 ~0 ~26 ~34 ~0 ~23 log 1 
setblock ~34 ~0 ~28 log 1  
fill ~34 ~0 ~30 ~35 ~0 ~30 planks 1  
fill ~34 ~0 ~31 ~34 ~0 ~30 planks 1  
fill ~34 ~0 ~32 ~35 ~0 ~32 log 1  
fill ~34 ~0 ~33 ~35 ~0 ~33 log 1  
fill ~34 ~0 ~34 ~36 ~0 ~34 planks 1  
fill ~34 ~0 ~42 ~36 ~0 ~42 concrete 14  
fill ~34 ~0 ~45 ~37 ~0 ~45 cobblestone 0  
fill ~34 ~0 ~46 ~38 ~0 ~46 cobblestone 0  
fill ~34 ~0 ~47 ~38 ~0 ~47 cobblestone 0  
fill ~34 ~0 ~48 ~38 ~0 ~48 cobblestone 0  
fill ~34 ~0 ~49 ~37 ~0 ~49 cobblestone 0  
fill ~34 ~0 ~50 ~38 ~0 ~50 cobblestone 0  
fill ~34 ~0 ~51 ~38 ~0 ~51 cobblestone 0  
fill ~34 ~0 ~52 ~38 ~0 ~52 cobblestone 0  
fill ~34 ~0 ~53 ~37 ~0 ~53 cobblestone 0  
fill ~34 ~0 ~54 ~35 ~0 ~54 cobblestone 0  
fill ~34 ~0 ~55 ~35 ~0 ~55 cobblestone 0  
fill ~34 ~0 ~56 ~35 ~0 ~56 cobblestone 0  
fill ~34 ~0 ~57 ~35 ~0 ~57 cobblestone 0  
fill ~34 ~0 ~58 ~35 ~0 ~58 cobblestone 0  
fill ~34 ~0 ~59 ~35 ~0 ~59 cobblestone 0  
fill ~34 ~0 ~60 ~35 ~0 ~60 cobblestone 0  
fill ~34 ~0 ~61 ~35 ~0 ~61 cobblestone 0  
fill ~34 ~0 ~62 ~35 ~0 ~62 cobblestone 0  
fill ~35 ~0 ~14 ~36 ~0 ~14 planks 1 
setblock ~35 ~0 ~19 log 1 
setblock ~35 ~0 ~20 cobblestone 0  
fill ~35 ~0 ~21 ~41 ~0 ~21 log 1  
fill ~35 ~0 ~22 ~35 ~0 ~21 log 1  
fill ~35 ~0 ~26 ~38 ~0 ~26 planks 1  
fill ~35 ~0 ~28 ~35 ~0 ~30 planks 1 
setblock ~35 ~0 ~31 log 1  
fill ~35 ~0 ~35 ~36 ~0 ~35 log 1  
fill ~35 ~0 ~41 ~46 ~0 ~41 concrete 14  
fill ~35 ~0 ~44 ~38 ~0 ~44 cobblestone 0 
setblock ~36 ~0 ~15 planks 1  
fill ~36 ~0 ~19 ~37 ~0 ~19 cobblestone 0  
fill ~36 ~0 ~20 ~37 ~0 ~20 log 1  
fill ~36 ~0 ~22 ~37 ~0 ~22 planks 1  
fill ~36 ~0 ~25 ~42 ~0 ~25 planks 1  
fill ~36 ~0 ~28 ~40 ~0 ~28 log 1  
fill ~36 ~0 ~29 ~37 ~0 ~29 planks 1 
setblock ~36 ~0 ~30 log 1  
fill ~36 ~0 ~31 ~37 ~0 ~31 planks 1  
fill ~36 ~0 ~32 ~38 ~0 ~32 planks 1  
fill ~36 ~0 ~33 ~36 ~0 ~31 planks 1  
fill ~36 ~0 ~37 ~38 ~0 ~37 planks 1  
fill ~36 ~0 ~40 ~47 ~0 ~40 concrete 14  
fill ~36 ~0 ~43 ~38 ~0 ~43 cobblestone 0  
fill ~36 ~0 ~54 ~37 ~0 ~54 stonebrick 0  
fill ~36 ~0 ~55 ~37 ~0 ~55 stonebrick 0  
fill ~36 ~0 ~56 ~38 ~0 ~56 stonebrick 0  
fill ~36 ~0 ~57 ~38 ~0 ~57 stonebrick 0  
fill ~36 ~0 ~58 ~38 ~0 ~58 stonebrick 0  
fill ~36 ~0 ~59 ~38 ~0 ~59 stonebrick 0  
fill ~36 ~0 ~60 ~38 ~0 ~60 stonebrick 0  
fill ~36 ~0 ~61 ~38 ~0 ~61 stonebrick 0  
fill ~36 ~0 ~62 ~38 ~0 ~62 stonebrick 0 
setblock ~37 ~0 ~14 log 1  
fill ~37 ~0 ~15 ~39 ~0 ~15 cobblestone 0  
fill ~37 ~0 ~30 ~39 ~0 ~30 planks 1  
fill ~37 ~0 ~33 ~40 ~0 ~33 log 1  
fill ~37 ~0 ~34 ~38 ~0 ~34 log 1  
fill ~37 ~0 ~35 ~40 ~0 ~35 planks 1  
fill ~37 ~0 ~36 ~37 ~0 ~35 planks 1  
fill ~37 ~0 ~42 ~40 ~0 ~42 cobblestone 0 
setblock ~38 ~0 ~14 cobblestone 0  
fill ~38 ~0 ~19 ~39 ~0 ~19 planks 1  
fill ~38 ~0 ~20 ~38 ~0 ~19 planks 1  
fill ~38 ~0 ~22 ~39 ~0 ~22 log 1 
setblock ~38 ~0 ~24 planks 1 
setblock ~38 ~0 ~29 log 1 
setblock ~38 ~0 ~31 log 1  
fill ~38 ~0 ~36 ~39 ~0 ~36 log 1 
setblock ~39 ~0 ~14 planks 1 
setblock ~39 ~0 ~18 log 1  
fill ~39 ~0 ~20 ~41 ~0 ~20 log 1  
fill ~39 ~0 ~24 ~41 ~0 ~24 log 1  
fill ~39 ~0 ~26 ~40 ~0 ~26 log 1 
setblock ~39 ~0 ~29 planks 1 
setblock ~39 ~0 ~31 planks 1 
setblock ~39 ~0 ~32 log 1  
fill ~39 ~0 ~34 ~41 ~0 ~34 planks 1 
setblock ~39 ~0 ~37 log 1  
fill ~39 ~0 ~38 ~40 ~0 ~38 planks 1 
setblock ~39 ~0 ~45 cobblestone 0  
fill ~39 ~0 ~57 ~39 ~0 ~59 cobblestone 0  
fill ~40 ~0 ~14 ~42 ~0 ~14 log 1  
fill ~40 ~0 ~15 ~41 ~0 ~15 log 1  
fill ~40 ~0 ~16 ~41 ~0 ~16 log 1  
fill ~40 ~0 ~17 ~41 ~0 ~17 planks 1  
fill ~40 ~0 ~18 ~40 ~0 ~17 planks 1 
setblock ~40 ~0 ~19 log 1 
setblock ~40 ~0 ~22 planks 1  
fill ~40 ~0 ~27 ~50 ~0 ~27 planks 1  
fill ~40 ~0 ~29 ~40 ~0 ~31 log 1 
setblock ~40 ~0 ~32 planks 1  
fill ~40 ~0 ~36 ~41 ~0 ~36 planks 1  
fill ~40 ~0 ~37 ~40 ~1 ~37 planks 1 
setblock ~40 ~0 ~59 cobblestone 0 
setblock ~41 ~0 ~18 log 1 
setblock ~41 ~0 ~19 planks 1  
fill ~41 ~0 ~22 ~42 ~0 ~22 log 1 
setblock ~41 ~0 ~23 planks 1 
setblock ~41 ~0 ~26 planks 1  
fill ~41 ~0 ~28 ~41 ~0 ~31 planks 1  
fill ~41 ~0 ~32 ~45 ~0 ~32 log 1  
fill ~41 ~0 ~33 ~42 ~0 ~33 planks 1 
setblock ~41 ~0 ~35 log 1  
fill ~41 ~0 ~37 ~41 ~0 ~38 log 1  
fill ~41 ~0 ~43 ~41 ~0 ~44 planks 1 
setblock ~41 ~0 ~46 log 1 
setblock ~41 ~0 ~50 log 1  
fill ~41 ~0 ~51 ~42 ~0 ~51 planks 1  
fill ~42 ~0 ~15 ~42 ~0 ~16 planks 1  
fill ~42 ~0 ~17 ~43 ~0 ~17 log 1  
fill ~42 ~0 ~18 ~44 ~0 ~18 planks 1  
fill ~42 ~0 ~19 ~45 ~0 ~19 log 1  
fill ~42 ~0 ~20 ~42 ~0 ~21 planks 1 
setblock ~42 ~0 ~23 log 1 
setblock ~42 ~0 ~24 planks 1 
setblock ~42 ~0 ~26 log 1  
fill ~42 ~0 ~28 ~44 ~0 ~28 log 1  
fill ~42 ~0 ~29 ~44 ~0 ~29 planks 1  
fill ~42 ~0 ~30 ~42 ~0 ~29 planks 1 
setblock ~42 ~0 ~31 log 1  
fill ~42 ~0 ~34 ~45 ~0 ~34 log 1  
fill ~42 ~0 ~35 ~43 ~0 ~35 planks 1 
setblock ~42 ~0 ~36 log 1 
setblock ~42 ~0 ~37 planks 1  
fill ~42 ~0 ~38 ~44 ~0 ~38 log 1 
setblock ~42 ~0 ~42 planks 1  
fill ~42 ~0 ~43 ~43 ~0 ~43 log 1  
fill ~42 ~0 ~44 ~45 ~0 ~44 planks 1  
fill ~42 ~0 ~45 ~42 ~0 ~46 planks 1  
fill ~42 ~0 ~47 ~44 ~0 ~47 log 1  
fill ~42 ~0 ~48 ~43 ~0 ~48 planks 1 
setblock ~42 ~0 ~49 log 1  
fill ~42 ~0 ~50 ~43 ~0 ~50 planks 1 
setblock ~43 ~0 ~14 planks 1  
fill ~43 ~0 ~15 ~44 ~0 ~15 log 1  
fill ~43 ~0 ~16 ~49 ~0 ~16 log 1  
fill ~43 ~0 ~20 ~45 ~0 ~20 log 1  
fill ~43 ~0 ~21 ~44 ~0 ~21 log 1  
fill ~43 ~0 ~22 ~45 ~0 ~22 planks 1  
fill ~43 ~0 ~23 ~43 ~0 ~22 planks 1  
fill ~43 ~0 ~24 ~44 ~0 ~24 log 1  
fill ~43 ~0 ~25 ~49 ~0 ~25 log 1  
fill ~43 ~0 ~26 ~44 ~0 ~26 planks 1 
setblock ~43 ~0 ~30 log 1 
setblock ~43 ~0 ~31 planks 1  
fill ~43 ~0 ~33 ~44 ~0 ~33 log 1  
fill ~43 ~0 ~36 ~45 ~0 ~36 planks 1 
setblock ~43 ~0 ~37 log 1 
setblock ~43 ~0 ~39 planks 1 
setblock ~43 ~0 ~42 log 1  
fill ~43 ~0 ~45 ~44 ~0 ~45 log 1 
setblock ~43 ~0 ~46 planks 1  
fill ~43 ~0 ~49 ~46 ~0 ~49 planks 1 
setblock ~43 ~0 ~51 log 1  
fill ~44 ~0 ~14 ~47 ~0 ~14 log 1 
setblock ~44 ~0 ~17 planks 1  
fill ~44 ~0 ~23 ~46 ~0 ~23 log 1  
fill ~44 ~0 ~30 ~46 ~0 ~30 planks 1 
setblock ~44 ~0 ~31 log 1  
fill ~44 ~0 ~35 ~46 ~0 ~35 log 1 
setblock ~44 ~0 ~37 planks 1  
fill ~44 ~0 ~39 ~45 ~0 ~39 log 1  
fill ~44 ~0 ~42 ~44 ~0 ~44 planks 1 
setblock ~44 ~0 ~46 log 1 
setblock ~44 ~0 ~48 log 1  
fill ~44 ~0 ~50 ~46 ~0 ~50 log 1 
setblock ~44 ~0 ~51 planks 1 
setblock ~45 ~0 ~15 planks 1  
fill ~45 ~0 ~17 ~45 ~0 ~20 log 1  
fill ~45 ~0 ~21 ~46 ~0 ~21 planks 1  
fill ~45 ~0 ~24 ~47 ~0 ~24 planks 1  
fill ~45 ~0 ~26 ~46 ~0 ~26 log 1 
setblock ~45 ~0 ~28 planks 1 
setblock ~45 ~0 ~29 log 1  
fill ~45 ~0 ~31 ~50 ~0 ~31 planks 1  
fill ~45 ~0 ~33 ~47 ~0 ~33 planks 1 
setblock ~45 ~0 ~37 log 1 
setblock ~45 ~0 ~38 planks 1  
fill ~45 ~0 ~42 ~45 ~0 ~43 log 1  
fill ~45 ~0 ~45 ~47 ~0 ~45 planks 1  
fill ~45 ~0 ~46 ~47 ~0 ~46 planks 1  
fill ~45 ~0 ~47 ~46 ~0 ~47 planks 1  
fill ~45 ~0 ~48 ~46 ~0 ~48 planks 1 
setblock ~45 ~0 ~51 log 1  
fill ~46 ~0 ~15 ~47 ~0 ~15 log 1  
fill ~46 ~0 ~17 ~47 ~0 ~17 planks 1  
fill ~46 ~0 ~18 ~46 ~0 ~21 planks 1 
setblock ~46 ~0 ~22 log 1  
fill ~46 ~0 ~28 ~47 ~0 ~28 log 1  
fill ~46 ~0 ~29 ~49 ~0 ~29 planks 1 
setblock ~46 ~0 ~32 planks 1  
fill ~46 ~0 ~34 ~50 ~0 ~34 planks 1 
setblock ~46 ~0 ~36 log 1  
fill ~46 ~0 ~37 ~47 ~0 ~37 planks 1  
fill ~46 ~0 ~38 ~47 ~0 ~38 concrete 14  
fill ~46 ~0 ~39 ~47 ~0 ~39 concrete 14  
fill ~46 ~0 ~42 ~47 ~0 ~42 planks 1  
fill ~46 ~0 ~43 ~46 ~0 ~42 planks 1 
setblock ~46 ~0 ~44 log 1  
fill ~46 ~0 ~51 ~47 ~0 ~51 planks 1  
fill ~47 ~0 ~18 ~50 ~0 ~18 log 1  
fill ~47 ~0 ~19 ~49 ~0 ~19 planks 1  
fill ~47 ~0 ~20 ~48 ~0 ~20 log 1  
fill ~47 ~0 ~21 ~47 ~0 ~20 log 1  
fill ~47 ~0 ~22 ~48 ~0 ~22 planks 1  
fill ~47 ~0 ~23 ~48 ~0 ~23 planks 1 
setblock ~47 ~0 ~26 planks 1  
fill ~47 ~0 ~30 ~49 ~0 ~30 log 1 
setblock ~47 ~0 ~32 log 1  
fill ~47 ~0 ~35 ~49 ~0 ~35 planks 1  
fill ~47 ~0 ~36 ~47 ~0 ~33 planks 1  
fill ~47 ~0 ~41 ~49 ~0 ~41 log 1 
setblock ~47 ~0 ~43 log 1  
fill ~47 ~0 ~44 ~48 ~0 ~44 planks 1  
fill ~47 ~0 ~47 ~47 ~0 ~49 log 1  
fill ~47 ~0 ~50 ~50 ~0 ~50 planks 1  
fill ~48 ~0 ~14 ~57 ~0 ~14 planks 1  
fill ~48 ~0 ~15 ~48 ~0 ~14 planks 1 
setblock ~48 ~0 ~17 log 1  
fill ~48 ~0 ~21 ~50 ~0 ~21 planks 1  
fill ~48 ~0 ~24 ~49 ~0 ~24 log 1 
setblock ~48 ~0 ~26 log 1  
fill ~48 ~0 ~28 ~50 ~0 ~28 planks 1  
fill ~48 ~0 ~32 ~49 ~0 ~32 planks 1 
setblock ~48 ~0 ~33 log 1  
fill ~48 ~0 ~36 ~48 ~0 ~37 log 1 
setblock ~48 ~0 ~38 planks 1  
fill ~48 ~0 ~39 ~49 ~0 ~39 log 1  
fill ~48 ~0 ~40 ~49 ~0 ~40 planks 1 
setblock ~48 ~0 ~42 log 1 
setblock ~48 ~0 ~43 planks 1  
fill ~48 ~0 ~45 ~49 ~0 ~45 log 1  
fill ~48 ~0 ~46 ~48 ~0 ~45 log 1 
setblock ~48 ~0 ~47 planks 1 
setblock ~48 ~0 ~48 log 1  
fill ~48 ~0 ~49 ~49 ~0 ~49 planks 1 
setblock ~48 ~0 ~51 log 1  
fill ~49 ~0 ~15 ~50 ~0 ~15 log 1 
setblock ~49 ~0 ~20 planks 1  
fill ~49 ~0 ~22 ~49 ~0 ~25 log 1  
fill ~49 ~0 ~26 ~50 ~0 ~26 planks 1 
setblock ~49 ~0 ~33 planks 1  
fill ~49 ~0 ~36 ~49 ~0 ~37 planks 1 
setblock ~49 ~0 ~38 log 1 
setblock ~49 ~0 ~42 planks 1  
fill ~49 ~0 ~43 ~49 ~0 ~45 log 1  
fill ~49 ~0 ~47 ~50 ~0 ~47 log 1 
setblock ~49 ~0 ~48 planks 1 
setblock ~49 ~0 ~51 planks 1 
setblock ~50 ~0 ~20 log 1 
setblock ~50 ~0 ~23 planks 1 
setblock ~50 ~0 ~25 planks 1 
setblock ~50 ~0 ~30 planks 1  
fill ~50 ~0 ~35 ~50 ~13 ~35 log 1  
fill ~50 ~0 ~38 ~50 ~0 ~39 planks 1 
setblock ~50 ~0 ~40 log 1 
setblock ~50 ~0 ~42 log 1  
fill ~50 ~0 ~44 ~50 ~0 ~45 planks 1 
setblock ~50 ~0 ~51 log 1  
fill ~51 ~0 ~51 ~57 ~0 ~51 planks 1  
fill ~51 ~0 ~53 ~59 ~0 ~53 planks 1  
fill ~51 ~0 ~54 ~59 ~0 ~54 planks 1  
fill ~51 ~0 ~55 ~54 ~0 ~55 planks 1  
fill ~51 ~0 ~56 ~59 ~0 ~56 planks 1  
fill ~51 ~0 ~57 ~59 ~0 ~57 planks 1  
fill ~52 ~0 ~6 ~60 ~0 ~6 planks 1  
fill ~52 ~0 ~7 ~60 ~0 ~7 planks 1  
fill ~52 ~0 ~8 ~60 ~0 ~8 planks 1  
fill ~52 ~0 ~9 ~58 ~0 ~9 planks 1  
fill ~52 ~0 ~10 ~54 ~0 ~10 planks 1  
fill ~52 ~0 ~11 ~59 ~0 ~11 planks 1  
fill ~52 ~0 ~12 ~59 ~0 ~12 planks 1  
fill ~52 ~0 ~13 ~58 ~0 ~13 planks 1  
fill ~52 ~0 ~52 ~58 ~0 ~52 planks 1  
fill ~52 ~0 ~58 ~58 ~0 ~58 planks 1  
fill ~53 ~0 ~59 ~57 ~0 ~59 planks 1  
fill ~57 ~0 ~10 ~59 ~0 ~10 planks 1  
fill ~57 ~0 ~55 ~59 ~0 ~55 planks 1 
setblock ~60 ~0 ~14 planks 1 
setblock ~3 ~1 ~8 cobblestone 0  
fill ~3 ~1 ~9 ~3 ~1 ~11 log 1  
fill ~3 ~1 ~12 ~3 ~2 ~12 cobblestone 0  
fill ~3 ~1 ~53 ~3 ~2 ~53 cobblestone 0  
fill ~3 ~1 ~54 ~3 ~1 ~56 log 1 
setblock ~3 ~1 ~57 cobblestone 0 
setblock ~4 ~1 ~7 log 5  
fill ~4 ~1 ~8 ~5 ~1 ~8 stonebrick 0  
fill ~4 ~1 ~9 ~5 ~1 ~9 cobblestone 0  
fill ~4 ~1 ~10 ~5 ~1 ~10 stonebrick 0 
setblock ~4 ~1 ~11 stone 0  
fill ~4 ~1 ~12 ~4 ~2 ~12 stonebrick 0 
setblock ~4 ~1 ~13 fence 1  
fill ~4 ~1 ~19 ~4 ~1 ~21 stone_brick_stairs 0  
fill ~4 ~1 ~44 ~4 ~1 ~46 stone_brick_stairs 0 
setblock ~4 ~1 ~52 fence 1  
fill ~4 ~1 ~53 ~4 ~2 ~53 stonebrick 0 
setblock ~4 ~1 ~54 stone 0  
fill ~4 ~1 ~55 ~5 ~1 ~55 stonebrick 0  
fill ~4 ~1 ~56 ~5 ~1 ~56 cobblestone 0  
fill ~4 ~1 ~57 ~5 ~1 ~57 stonebrick 0 
setblock ~4 ~1 ~58 log 5 
setblock ~5 ~1 ~6 fence 1  
fill ~5 ~1 ~7 ~5 ~19 ~7 log 1 
setblock ~5 ~1 ~11 stonebrick 0 
setblock ~5 ~1 ~12 cobblestone 0  
fill ~5 ~1 ~13 ~5 ~19 ~13 log 1 
setblock ~5 ~1 ~14 log 9 
setblock ~5 ~1 ~18 stone_brick_stairs 2  
fill ~5 ~1 ~19 ~15 ~1 ~19 stonebrick 0  
fill ~5 ~1 ~20 ~14 ~1 ~20 stonebrick 0  
fill ~5 ~1 ~21 ~14 ~1 ~21 stonebrick 0 
setblock ~5 ~1 ~22 stone_brick_stairs 0 
setblock ~5 ~1 ~43 stone_brick_stairs 0  
fill ~5 ~1 ~44 ~14 ~1 ~44 stonebrick 0  
fill ~5 ~1 ~45 ~14 ~1 ~45 stonebrick 0  
fill ~5 ~1 ~46 ~15 ~1 ~46 stonebrick 0 
setblock ~5 ~1 ~47 stone_brick_stairs 3 
setblock ~5 ~1 ~51 log 9  
fill ~5 ~1 ~52 ~5 ~19 ~52 log 1 
setblock ~5 ~1 ~53 cobblestone 0 
setblock ~5 ~1 ~54 stonebrick 0  
fill ~5 ~1 ~58 ~5 ~19 ~58 log 1 
setblock ~5 ~1 ~59 fence 1 
setblock ~6 ~1 ~5 log 5  
fill ~6 ~1 ~6 ~7 ~1 ~6 cobblestone 0  
fill ~6 ~1 ~7 ~6 ~1 ~6 cobblestone 0 
setblock ~6 ~1 ~11 chest 5 
setblock ~6 ~1 ~12 bookshelf 0 
setblock ~6 ~1 ~13 stone 0  
fill ~6 ~1 ~14 ~7 ~1 ~14 stonebrick 0 
setblock ~6 ~1 ~15 fence 1  
fill ~6 ~1 ~17 ~7 ~1 ~17 stone_brick_stairs 2  
fill ~6 ~1 ~18 ~15 ~1 ~18 stonebrick 0  
fill ~6 ~1 ~22 ~14 ~1 ~22 stonebrick 0  
fill ~6 ~1 ~23 ~7 ~1 ~23 stone_brick_stairs 3  
fill ~6 ~1 ~42 ~7 ~1 ~42 stone_brick_stairs 2  
fill ~6 ~1 ~43 ~14 ~1 ~43 stonebrick 0  
fill ~6 ~1 ~47 ~15 ~1 ~47 stonebrick 0  
fill ~6 ~1 ~48 ~7 ~1 ~48 stone_brick_stairs 3 
setblock ~6 ~1 ~50 fence 1  
fill ~6 ~1 ~51 ~7 ~1 ~51 stonebrick 0 
setblock ~6 ~1 ~52 stone 0 
setblock ~6 ~1 ~53 bookshelf 0 
setblock ~6 ~1 ~54 chest 5  
fill ~6 ~1 ~58 ~6 ~1 ~59 cobblestone 0 
setblock ~6 ~1 ~60 log 5 
setblock ~7 ~1 ~4 fence 1  
fill ~7 ~1 ~5 ~7 ~19 ~5 log 1  
fill ~7 ~1 ~15 ~7 ~19 ~15 log 1 
setblock ~7 ~1 ~16 log 9  
fill ~7 ~1 ~24 ~7 ~1 ~25 stone_brick_stairs 0  
fill ~7 ~1 ~40 ~7 ~1 ~41 stone_brick_stairs 0 
setblock ~7 ~1 ~49 log 9  
fill ~7 ~1 ~50 ~7 ~19 ~50 log 1 
setblock ~7 ~1 ~59 cobblestone 0  
fill ~7 ~1 ~60 ~7 ~19 ~60 log 1 
setblock ~7 ~1 ~61 fence 1  
fill ~8 ~1 ~3 ~8 ~1 ~4 stonebrick 0  
fill ~8 ~1 ~5 ~8 ~2 ~5 stone 0  
fill ~8 ~1 ~15 ~9 ~1 ~15 stonebrick 0  
fill ~8 ~1 ~16 ~8 ~2 ~16 stone 0  
fill ~8 ~1 ~17 ~8 ~2 ~17 cobblestone 0  
fill ~8 ~1 ~23 ~14 ~1 ~23 stonebrick 0  
fill ~8 ~1 ~24 ~14 ~1 ~24 stonebrick 0  
fill ~8 ~1 ~25 ~14 ~1 ~25 stonebrick 0 
setblock ~8 ~1 ~26 stone_slab 5 
setblock ~8 ~1 ~39 stone_slab 5  
fill ~8 ~1 ~40 ~14 ~1 ~40 stonebrick 0  
fill ~8 ~1 ~41 ~14 ~1 ~41 stonebrick 0  
fill ~8 ~1 ~42 ~14 ~1 ~42 stonebrick 0 
setblock ~8 ~1 ~48 cobblestone 0  
fill ~8 ~1 ~49 ~9 ~1 ~49 stonebrick 0  
fill ~8 ~1 ~50 ~9 ~1 ~50 stonebrick 0  
fill ~8 ~1 ~60 ~8 ~2 ~60 stone 0  
fill ~8 ~1 ~61 ~8 ~1 ~62 stonebrick 0  
fill ~9 ~1 ~3 ~11 ~1 ~3 log 1 
setblock ~9 ~1 ~4 cobblestone 0  
fill ~9 ~1 ~5 ~9 ~2 ~5 stonebrick 0  
fill ~9 ~1 ~16 ~9 ~2 ~16 cobblestone 0  
fill ~9 ~1 ~17 ~11 ~1 ~17 stonebrick 0  
fill ~9 ~1 ~26 ~12 ~1 ~26 stonebrick 0 
setblock ~9 ~1 ~27 stone_slab 5 
setblock ~9 ~1 ~29 stone_slab 5 
setblock ~9 ~1 ~31 stone_slab 5 
setblock ~9 ~1 ~34 stone_slab 5 
setblock ~9 ~1 ~36 stone_slab 5 
setblock ~9 ~1 ~38 stone_slab 5  
fill ~9 ~1 ~39 ~12 ~1 ~39 stonebrick 0  
fill ~9 ~1 ~48 ~11 ~1 ~48 stonebrick 0  
fill ~9 ~1 ~60 ~9 ~2 ~60 stonebrick 0 
setblock ~9 ~1 ~61 cobblestone 0  
fill ~9 ~1 ~62 ~11 ~1 ~62 log 1 
setblock ~10 ~1 ~4 stonebrick 0  
fill ~10 ~1 ~5 ~11 ~1 ~5 cobblestone 0  
fill ~10 ~1 ~6 ~12 ~1 ~6 log 1  
fill ~10 ~1 ~10 ~10 ~2 ~10 stone 0  
fill ~10 ~1 ~15 ~12 ~1 ~15 stone 0  
fill ~10 ~1 ~16 ~11 ~1 ~16 stone 0  
fill ~10 ~1 ~27 ~14 ~1 ~27 stonebrick 0 
setblock ~10 ~1 ~28 stone_slab 5  
fill ~10 ~1 ~29 ~14 ~1 ~29 stonebrick 0 
setblock ~10 ~1 ~30 stone_slab 5  
fill ~10 ~1 ~31 ~14 ~1 ~31 stonebrick 0  
fill ~10 ~1 ~32 ~10 ~1 ~33 stone_slab 5  
fill ~10 ~1 ~34 ~14 ~1 ~34 stonebrick 0 
setblock ~10 ~1 ~35 stone_slab 5  
fill ~10 ~1 ~36 ~14 ~1 ~36 stonebrick 0 
setblock ~10 ~1 ~37 stone_slab 5  
fill ~10 ~1 ~38 ~14 ~1 ~38 stonebrick 0 
setblock ~10 ~1 ~49 cobblestone 0  
fill ~10 ~1 ~50 ~12 ~1 ~50 stone 0  
fill ~10 ~1 ~55 ~10 ~2 ~55 stone 0  
fill ~10 ~1 ~59 ~12 ~1 ~59 log 1  
fill ~10 ~1 ~60 ~11 ~1 ~60 cobblestone 0 
setblock ~10 ~1 ~61 stonebrick 0 
setblock ~11 ~1 ~4 stone 0 
setblock ~11 ~1 ~10 stone_slab 5 
setblock ~11 ~1 ~11 stone_slab 13  
fill ~11 ~1 ~28 ~14 ~1 ~28 stonebrick 0  
fill ~11 ~1 ~30 ~14 ~1 ~30 stonebrick 0  
fill ~11 ~1 ~32 ~14 ~1 ~32 stonebrick 0  
fill ~11 ~1 ~33 ~14 ~1 ~33 stonebrick 0  
fill ~11 ~1 ~35 ~14 ~1 ~35 stonebrick 0  
fill ~11 ~1 ~37 ~14 ~1 ~37 stonebrick 0  
fill ~11 ~1 ~49 ~12 ~1 ~49 stone 0 
setblock ~11 ~1 ~54 stone_slab 13 
setblock ~11 ~1 ~55 stone_slab 5 
setblock ~11 ~1 ~61 stone 0  
fill ~12 ~1 ~3 ~12 ~2 ~3 stonebrick 0  
fill ~12 ~1 ~4 ~12 ~1 ~3 stonebrick 0  
fill ~12 ~1 ~5 ~12 ~2 ~5 stone 0  
fill ~12 ~1 ~16 ~14 ~1 ~16 stonebrick 0  
fill ~12 ~1 ~17 ~12 ~2 ~17 cobblestone 0  
fill ~12 ~1 ~48 ~12 ~2 ~48 stone 0  
fill ~12 ~1 ~60 ~12 ~2 ~60 stone 0  
fill ~12 ~1 ~61 ~12 ~1 ~62 stonebrick 0 
setblock ~13 ~1 ~4 log 9  
fill ~13 ~1 ~5 ~13 ~19 ~5 log 1 
setblock ~13 ~1 ~6 stone 0 
setblock ~13 ~1 ~7 log 1  
fill ~13 ~1 ~15 ~13 ~20 ~15 monster_egg 2  
fill ~13 ~1 ~17 ~15 ~1 ~17 stonebrick 0 
setblock ~13 ~1 ~26 monster_egg 2 
setblock ~13 ~1 ~39 monster_egg 2  
fill ~13 ~1 ~48 ~13 ~21 ~48 stonebrick 0  
fill ~13 ~1 ~49 ~13 ~21 ~49 stonebrick 0  
fill ~13 ~1 ~50 ~13 ~19 ~50 stonebrick 0 
setblock ~13 ~1 ~58 log 1 
setblock ~13 ~1 ~59 stone 0  
fill ~13 ~1 ~60 ~13 ~19 ~60 log 1 
setblock ~13 ~1 ~61 log 9 
setblock ~14 ~1 ~5 fence 1  
fill ~14 ~1 ~6 ~14 ~2 ~6 stonebrick 0  
fill ~14 ~1 ~7 ~14 ~3 ~7 stonebrick 0  
fill ~14 ~1 ~8 ~14 ~1 ~9 log 1 
setblock ~14 ~1 ~13 stone 0  
fill ~14 ~1 ~15 ~14 ~22 ~15 stonebrick 0  
fill ~14 ~1 ~26 ~14 ~35 ~26 stonebrick 0  
fill ~14 ~1 ~39 ~14 ~35 ~39 stonebrick 0  
fill ~14 ~1 ~48 ~14 ~1 ~50 monster_egg 2 
setblock ~14 ~1 ~52 stone 0 
setblock ~14 ~1 ~53 bookshelf 0  
fill ~14 ~1 ~56 ~14 ~1 ~57 log 1  
fill ~14 ~1 ~58 ~14 ~3 ~58 stonebrick 0  
fill ~14 ~1 ~59 ~14 ~2 ~59 stonebrick 0 
setblock ~14 ~1 ~60 fence 1 
setblock ~15 ~1 ~6 log 9  
fill ~15 ~1 ~7 ~15 ~19 ~7 log 1  
fill ~15 ~1 ~8 ~15 ~3 ~8 stonebrick 0  
fill ~15 ~1 ~9 ~15 ~3 ~9 stone 0  
fill ~15 ~1 ~10 ~15 ~1 ~11 stone 0  
fill ~15 ~1 ~12 ~15 ~1 ~13 stonebrick 0  
fill ~15 ~1 ~16 ~15 ~15 ~16 log 1 
setblock ~15 ~1 ~20 stone_brick_stairs 1  
fill ~15 ~1 ~21 ~15 ~1 ~25 stone_slab 5 
setblock ~15 ~1 ~26 stone_brick_stairs 1 
setblock ~15 ~1 ~27 stone_slab 5 
setblock ~15 ~1 ~28 stone_brick_stairs 1 
setblock ~15 ~1 ~29 stone_slab 5  
fill ~15 ~1 ~30 ~15 ~13 ~30 log 1  
fill ~15 ~1 ~31 ~15 ~1 ~34 stone_brick_stairs 1 
setblock ~15 ~1 ~36 stone_slab 5 
setblock ~15 ~1 ~37 stone_brick_stairs 1 
setblock ~15 ~1 ~38 stone_slab 5 
setblock ~15 ~1 ~39 stone_brick_stairs 1  
fill ~15 ~1 ~40 ~15 ~1 ~44 stone_slab 5 
setblock ~15 ~1 ~45 stone_brick_stairs 1  
fill ~15 ~1 ~48 ~15 ~3 ~48 stonebrick 0  
fill ~15 ~1 ~49 ~15 ~15 ~49 log 1  
fill ~15 ~1 ~52 ~16 ~1 ~52 stonebrick 0  
fill ~15 ~1 ~53 ~16 ~1 ~53 stonebrick 0  
fill ~15 ~1 ~54 ~15 ~1 ~56 stone 0  
fill ~15 ~1 ~57 ~15 ~3 ~57 stonebrick 0  
fill ~15 ~1 ~58 ~15 ~19 ~58 log 1 
setblock ~15 ~1 ~59 log 9 
setblock ~16 ~1 ~7 fence 1  
fill ~16 ~1 ~8 ~17 ~1 ~8 cobblestone 0  
fill ~16 ~1 ~9 ~26 ~1 ~9 stonebrick 0  
fill ~16 ~1 ~10 ~27 ~1 ~10 stonebrick 0  
fill ~16 ~1 ~11 ~16 ~2 ~11 stone 0  
fill ~16 ~1 ~12 ~16 ~3 ~12 cobblestone 0  
fill ~16 ~1 ~13 ~27 ~1 ~13 stonebrick 0 
setblock ~16 ~1 ~16 log 5 
setblock ~16 ~1 ~17 stone_brick_stairs 1 
setblock ~16 ~1 ~18 stone_slab 5 
setblock ~16 ~1 ~19 stone_brick_stairs 1 
setblock ~16 ~1 ~30 log 5 
setblock ~16 ~1 ~35 log 5 
setblock ~16 ~1 ~46 stone_brick_stairs 1 
setblock ~16 ~1 ~47 stone_slab 5 
setblock ~16 ~1 ~48 stone_brick_stairs 1 
setblock ~16 ~1 ~49 log 5  
fill ~16 ~1 ~54 ~26 ~1 ~54 stonebrick 0  
fill ~16 ~1 ~55 ~27 ~1 ~55 stonebrick 0  
fill ~16 ~1 ~56 ~26 ~1 ~56 stonebrick 0  
fill ~16 ~1 ~57 ~17 ~1 ~57 cobblestone 0 
setblock ~16 ~1 ~58 fence 1  
fill ~17 ~1 ~6 ~17 ~1 ~7 stone_brick_stairs 0  
fill ~17 ~1 ~11 ~48 ~1 ~11 stonebrick 0  
fill ~17 ~1 ~12 ~17 ~2 ~12 stone 0  
fill ~17 ~1 ~52 ~17 ~14 ~52 log 1  
fill ~17 ~1 ~53 ~17 ~2 ~53 cobblestone 0  
fill ~17 ~1 ~58 ~17 ~1 ~59 stone_brick_stairs 0 
setblock ~18 ~1 ~5 stone_brick_stairs 0  
fill ~18 ~1 ~6 ~22 ~1 ~6 stonebrick 0  
fill ~18 ~1 ~7 ~22 ~1 ~7 stonebrick 0  
fill ~18 ~1 ~8 ~25 ~1 ~8 stonebrick 0  
fill ~18 ~1 ~12 ~47 ~1 ~12 stonebrick 0
fill ~18 ~1 ~53 ~27 ~1 ~53 stonebrick 0  
fill ~18 ~1 ~57 ~25 ~1 ~57 stonebrick 0  
fill ~18 ~1 ~58 ~22 ~1 ~58 stonebrick 0  
fill ~18 ~1 ~59 ~22 ~1 ~59 stonebrick 0 
setblock ~18 ~1 ~60 stone_brick_stairs 0  
fill ~19 ~1 ~4 ~20 ~1 ~4 stone_brick_stairs 2  
fill ~19 ~1 ~5 ~21 ~1 ~5 stonebrick 0  
fill ~19 ~1 ~60 ~21 ~1 ~60 stonebrick 0  
fill ~19 ~1 ~61 ~21 ~1 ~61 stone_brick_stairs 3  
fill ~21 ~1 ~52 ~21 ~14 ~52 log 1 
setblock ~22 ~1 ~5 stone_brick_stairs 2 
setblock ~22 ~1 ~14 log 5 
setblock ~22 ~1 ~20 log 5 
setblock ~22 ~1 ~32 log 5 
setblock ~22 ~1 ~38 log 5  
fill ~22 ~1 ~52 ~23 ~1 ~52 stonebrick 0 
setblock ~22 ~1 ~60 stone_brick_stairs 3  
fill ~23 ~1 ~6 ~23 ~1 ~7 stone_brick_stairs 1  
fill ~23 ~1 ~14 ~23 ~13 ~14 log 1  
fill ~23 ~1 ~16 ~25 ~1 ~16 stonebrick 0  
fill ~23 ~1 ~18 ~24 ~1 ~18 stonebrick 0  
fill ~23 ~1 ~20 ~23 ~14 ~20 log 1  
fill ~23 ~1 ~21 ~25 ~1 ~21 stonebrick 0  
fill ~23 ~1 ~31 ~25 ~1 ~31 stonebrick 0  
fill ~23 ~1 ~32 ~23 ~13 ~32 log 1  
fill ~23 ~1 ~34 ~24 ~1 ~34 stonebrick 0  
fill ~23 ~1 ~36 ~24 ~1 ~36 stonebrick 0  
fill ~23 ~1 ~38 ~23 ~14 ~38 log 1  
fill ~23 ~1 ~39 ~26 ~1 ~39 stonebrick 0 
setblock ~23 ~1 ~42 cobblestone 0  
fill ~23 ~1 ~58 ~23 ~1 ~59 stone_brick_stairs 1  
fill ~24 ~1 ~7 ~25 ~1 ~7 stone_brick_stairs 2  
fill ~24 ~1 ~14 ~24 ~22 ~14 stonebrick 0  
fill ~24 ~1 ~15 ~24 ~23 ~15 stonebrick 0  
fill ~24 ~1 ~17 ~24 ~25 ~17 stonebrick 0  
fill ~24 ~1 ~19 ~27 ~1 ~19 stonebrick 0  
fill ~24 ~1 ~20 ~24 ~28 ~20 stonebrick 0 
setblock ~24 ~1 ~22 stonebrick 0 
setblock ~24 ~1 ~30 stonebrick 0  
fill ~24 ~1 ~32 ~24 ~14 ~32 stonebrick 0  
fill ~24 ~1 ~33 ~24 ~14 ~33 stonebrick 0  
fill ~24 ~1 ~35 ~24 ~32 ~35 stonebrick 0  
fill ~24 ~1 ~37 ~24 ~14 ~37 stonebrick 0  
fill ~24 ~1 ~38 ~24 ~14 ~38 stonebrick 0  
fill ~24 ~1 ~42 ~26 ~1 ~42 stonebrick 0  
fill ~24 ~1 ~43 ~26 ~1 ~43 stonebrick 0 
setblock ~24 ~1 ~44 stone_brick_stairs 0  
fill ~24 ~1 ~45 ~25 ~1 ~45 stonebrick 0  
fill ~24 ~1 ~46 ~24 ~1 ~51 planks 1  
fill ~24 ~1 ~52 ~24 ~2 ~52 monster_egg 2  
fill ~24 ~1 ~58 ~25 ~1 ~58 stone_brick_stairs 3  
fill ~25 ~1 ~14 ~25 ~18 ~14 log 1  
fill ~25 ~1 ~18 ~25 ~18 ~18 log 1  
fill ~25 ~1 ~20 ~26 ~1 ~20 log 1  
fill ~25 ~1 ~32 ~25 ~13 ~32 log 1  
fill ~25 ~1 ~33 ~25 ~1 ~35 planks 1  
fill ~25 ~1 ~36 ~25 ~1 ~37 furnace 5  
fill ~25 ~1 ~38 ~26 ~1 ~38 log 1  
fill ~25 ~1 ~44 ~26 ~1 ~44 stonebrick 0  
fill ~25 ~1 ~46 ~26 ~1 ~46 stonebrick 0  
fill ~25 ~1 ~47 ~25 ~2 ~47 stonebrick 0  
fill ~25 ~1 ~48 ~26 ~1 ~48 stonebrick 0  
fill ~25 ~1 ~49 ~25 ~14 ~49 stonebrick 0  
fill ~25 ~1 ~50 ~26 ~1 ~50 stonebrick 0  
fill ~25 ~1 ~51 ~25 ~4 ~51 stonebrick 0  
fill ~25 ~1 ~52 ~26 ~1 ~52 stonebrick 0 
setblock ~26 ~1 ~8 stone_slab 5  
fill ~26 ~1 ~18 ~26 ~9 ~18 stonebrick 0 
setblock ~26 ~1 ~27 dropper 0 
setblock ~26 ~1 ~32 log 5  
fill ~26 ~1 ~37 ~26 ~10 ~37 ladder 2  
fill ~26 ~1 ~45 ~26 ~10 ~45 log 1 
setblock ~26 ~1 ~47 stone_slab 5  
fill ~26 ~1 ~49 ~26 ~10 ~49 log 1 
setblock ~26 ~1 ~51 stone_slab 5 
setblock ~27 ~1 ~9 stone_slab 5  
fill ~27 ~1 ~14 ~27 ~8 ~14 ladder 3  
fill ~27 ~1 ~26 ~27 ~1 ~28 spruce_stairs 4 
setblock ~27 ~1 ~29 dropper 0 
setblock ~27 ~1 ~33 dropper 0  
fill ~27 ~1 ~38 ~30 ~1 ~38 stonebrick 0 
setblock ~27 ~1 ~45 spruce_stairs 1 
setblock ~27 ~1 ~49 spruce_stairs 1  
fill ~27 ~1 ~54 ~27 ~11 ~54 log 1 
setblock ~28 ~1 ~10 stone_slab 5 
setblock ~28 ~1 ~13 monster_egg 2 
setblock ~28 ~1 ~26 spruce_stairs 6 
setblock ~28 ~1 ~28 spruce_stairs 7 
setblock ~28 ~1 ~31 spruce_stairs 4 
setblock ~28 ~1 ~32 spruce_stairs 7 
setblock ~28 ~1 ~33 spruce_stairs 4  
fill ~28 ~1 ~39 ~28 ~3 ~39 stonebrick 0 
setblock ~29 ~1 ~9 stone_slab 5 
setblock ~29 ~1 ~10 stonebrick 0  
fill ~29 ~1 ~13 ~36 ~1 ~13 stonebrick 0  
fill ~29 ~1 ~14 ~29 ~9 ~14 log 1  
fill ~29 ~1 ~15 ~29 ~1 ~14 log 1  
fill ~29 ~1 ~26 ~29 ~1 ~28 spruce_stairs 5 
setblock ~29 ~1 ~30 dropper 0  
fill ~29 ~1 ~31 ~30 ~1 ~31 spruce_stairs 6  
fill ~29 ~1 ~33 ~30 ~1 ~33 spruce_stairs 7  
fill ~29 ~1 ~37 ~29 ~13 ~37 log 1 
setblock ~30 ~1 ~10 stone_slab 5  
fill ~30 ~1 ~14 ~35 ~1 ~14 stonebrick 0 
setblock ~30 ~1 ~19 stonebrick 0 
setblock ~30 ~1 ~27 dropper 0 
setblock ~30 ~1 ~32 spruce_stairs 5 
setblock ~30 ~1 ~34 dropper 0  
fill ~30 ~1 ~37 ~35 ~1 ~37 stonebrick 0 
setblock ~30 ~1 ~39 stone_brick_stairs 3 
setblock ~31 ~1 ~9 stone_slab 5 
setblock ~31 ~1 ~10 stonebrick 0 
setblock ~31 ~1 ~31 dropper 0  
fill ~32 ~1 ~10 ~33 ~1 ~10 stone_slab 5  
fill ~32 ~1 ~15 ~33 ~1 ~15 stone_brick_stairs 3  
fill ~32 ~1 ~38 ~33 ~1 ~38 stonebrick 0  
fill ~32 ~1 ~39 ~33 ~1 ~39 stonebrick 0 
setblock ~33 ~1 ~27 dropper 0 
setblock ~33 ~1 ~30 dropper 0 
setblock ~33 ~1 ~33 dropper 0 
setblock ~34 ~1 ~9 stone_slab 5 
setblock ~34 ~1 ~10 stonebrick 0  
fill ~34 ~1 ~27 ~34 ~1 ~34 spruce_stairs 4 
setblock ~35 ~1 ~10 stone_slab 5 
setblock ~35 ~1 ~19 stonebrick 0 
setblock ~35 ~1 ~35 dropper 0  
fill ~35 ~1 ~38 ~38 ~1 ~38 stonebrick 0 
setblock ~35 ~1 ~39 stone_brick_stairs 3 
setblock ~36 ~1 ~9 stone_slab 5 
setblock ~36 ~1 ~10 stonebrick 0  
fill ~36 ~1 ~14 ~36 ~9 ~14 log 1  
fill ~36 ~1 ~15 ~36 ~1 ~14 log 1 
setblock ~36 ~1 ~26 dropper 0  
fill ~36 ~1 ~27 ~36 ~1 ~34 spruce_stairs 5  
fill ~36 ~1 ~37 ~36 ~13 ~37 log 1 
setblock ~37 ~1 ~10 stone_slab 5 
setblock ~37 ~1 ~13 monster_egg 2 
setblock ~37 ~1 ~28 dropper 0 
setblock ~37 ~1 ~31 dropper 0 
setblock ~37 ~1 ~34 dropper 0  
fill ~37 ~1 ~39 ~37 ~3 ~39 stonebrick 0 
setblock ~38 ~1 ~9 stone_slab 5  
fill ~38 ~1 ~10 ~48 ~1 ~10 stonebrick 0  
fill ~38 ~1 ~13 ~50 ~1 ~13 stonebrick 0  
fill ~38 ~1 ~14 ~38 ~8 ~14 ladder 3  
fill ~38 ~1 ~19 ~41 ~1 ~19 stonebrick 0 
setblock ~38 ~1 ~45 spruce_stairs 0 
setblock ~38 ~1 ~49 spruce_stairs 0  
fill ~38 ~1 ~53 ~47 ~1 ~53 stonebrick 0  
fill ~38 ~1 ~54 ~38 ~11 ~54 log 1  
fill ~38 ~1 ~55 ~46 ~1 ~55 stonebrick 0 
setblock ~39 ~1 ~8 stone_slab 5  
fill ~39 ~1 ~9 ~48 ~1 ~9 stonebrick 0  
fill ~39 ~1 ~18 ~39 ~9 ~18 stonebrick 0 
setblock ~39 ~1 ~20 log 5  
fill ~39 ~1 ~32 ~40 ~1 ~32 log 5  
fill ~39 ~1 ~37 ~39 ~10 ~37 ladder 2  
fill ~39 ~1 ~38 ~40 ~1 ~38 log 1  
fill ~39 ~1 ~39 ~42 ~1 ~39 stonebrick 0  
fill ~39 ~1 ~42 ~41 ~1 ~42 stonebrick 0  
fill ~39 ~1 ~43 ~41 ~1 ~43 stonebrick 0  
fill ~39 ~1 ~44 ~40 ~1 ~44 stonebrick 0  
fill ~39 ~1 ~45 ~39 ~10 ~45 log 1  
fill ~39 ~1 ~46 ~40 ~1 ~46 stonebrick 0 
setblock ~39 ~1 ~47 stone_slab 5  
fill ~39 ~1 ~48 ~40 ~1 ~48 stonebrick 0  
fill ~39 ~1 ~49 ~39 ~10 ~49 log 1  
fill ~39 ~1 ~50 ~40 ~1 ~50 stonebrick 0 
setblock ~39 ~1 ~51 stone_slab 5  
fill ~39 ~1 ~52 ~40 ~1 ~52 stonebrick 0  
fill ~39 ~1 ~54 ~48 ~1 ~54 stonebrick 0  
fill ~39 ~1 ~56 ~48 ~1 ~56 stonebrick 0  
fill ~40 ~1 ~7 ~41 ~1 ~7 stone_brick_stairs 2  
fill ~40 ~1 ~8 ~47 ~1 ~8 stonebrick 0  
fill ~40 ~1 ~14 ~40 ~14 ~14 log 1  
fill ~40 ~1 ~16 ~42 ~1 ~16 stonebrick 0  
fill ~40 ~1 ~18 ~40 ~14 ~18 log 1  
fill ~40 ~1 ~20 ~40 ~13 ~20 log 1  
fill ~40 ~1 ~21 ~42 ~1 ~21 stonebrick 0  
fill ~40 ~1 ~31 ~42 ~1 ~31 stonebrick 0  
fill ~40 ~1 ~33 ~40 ~1 ~37 planks 1  
fill ~40 ~1 ~45 ~41 ~1 ~45 stonebrick 0  
fill ~40 ~1 ~47 ~40 ~2 ~47 stonebrick 0  
fill ~40 ~1 ~49 ~40 ~14 ~49 stonebrick 0  
fill ~40 ~1 ~51 ~40 ~4 ~51 stonebrick 0  
fill ~40 ~1 ~57 ~47 ~1 ~57 stonebrick 0  
fill ~40 ~1 ~58 ~41 ~1 ~58 stone_brick_stairs 3  
fill ~41 ~1 ~14 ~41 ~14 ~14 stonebrick 0  
fill ~41 ~1 ~15 ~41 ~14 ~15 stonebrick 0  
fill ~41 ~1 ~17 ~41 ~14 ~17 stonebrick 0  
fill ~41 ~1 ~18 ~42 ~1 ~18 stonebrick 0  
fill ~41 ~1 ~20 ~41 ~14 ~20 stonebrick 0 
setblock ~41 ~1 ~22 stonebrick 0 
setblock ~41 ~1 ~30 stonebrick 0  
fill ~41 ~1 ~32 ~41 ~14 ~32 stonebrick 0  
fill ~41 ~1 ~33 ~41 ~14 ~33 stonebrick 0  
fill ~41 ~1 ~34 ~42 ~1 ~34 stonebrick 0  
fill ~41 ~1 ~35 ~41 ~32 ~35 stonebrick 0  
fill ~41 ~1 ~36 ~42 ~1 ~36 stonebrick 0  
fill ~41 ~1 ~37 ~41 ~14 ~37 stonebrick 0  
fill ~41 ~1 ~38 ~41 ~14 ~38 stonebrick 0 
setblock ~41 ~1 ~44 stone_brick_stairs 1  
fill ~41 ~1 ~46 ~41 ~1 ~51 planks 1  
fill ~41 ~1 ~52 ~41 ~2 ~52 monster_egg 2  
fill ~42 ~1 ~6 ~42 ~1 ~7 stone_brick_stairs 0  
fill ~42 ~1 ~14 ~42 ~13 ~14 log 1  
fill ~42 ~1 ~20 ~42 ~14 ~20 log 1  
fill ~42 ~1 ~32 ~42 ~13 ~32 log 1  
fill ~42 ~1 ~38 ~42 ~14 ~38 log 1 
setblock ~42 ~1 ~42 cobblestone 0  
fill ~42 ~1 ~52 ~43 ~1 ~52 stonebrick 0  
fill ~42 ~1 ~58 ~42 ~1 ~59 stone_brick_stairs 0 
setblock ~43 ~1 ~5 stone_brick_stairs 2  
fill ~43 ~1 ~6 ~47 ~1 ~6 stonebrick 0  
fill ~43 ~1 ~7 ~47 ~1 ~7 stonebrick 0 
setblock ~43 ~1 ~14 log 5 
setblock ~43 ~1 ~20 log 5 
setblock ~43 ~1 ~32 log 5 
setblock ~43 ~1 ~38 log 5  
fill ~43 ~1 ~58 ~47 ~1 ~58 stonebrick 0  
fill ~43 ~1 ~59 ~47 ~1 ~59 stonebrick 0 
setblock ~43 ~1 ~60 stone_brick_stairs 3  
fill ~44 ~1 ~5 ~46 ~1 ~5 stonebrick 0  
fill ~44 ~1 ~52 ~44 ~14 ~52 log 1  
fill ~44 ~1 ~60 ~46 ~1 ~60 stonebrick 0  
fill ~44 ~1 ~61 ~46 ~1 ~61 stone_brick_stairs 3 
setblock ~47 ~1 ~5 stone_brick_stairs 1 
setblock ~47 ~1 ~60 stone_brick_stairs 1  
fill ~48 ~1 ~6 ~48 ~1 ~7 stone_brick_stairs 1  
fill ~48 ~1 ~8 ~48 ~2 ~8 cobblestone 0  
fill ~48 ~1 ~12 ~48 ~2 ~12 cobblestone 0  
fill ~48 ~1 ~52 ~48 ~14 ~52 log 1  
fill ~48 ~1 ~53 ~48 ~2 ~53 cobblestone 0  
fill ~48 ~1 ~55 ~48 ~20 ~55 stonebrick 0  
fill ~48 ~1 ~57 ~48 ~2 ~57 cobblestone 0  
fill ~48 ~1 ~58 ~48 ~1 ~59 stone_brick_stairs 1 
setblock ~49 ~1 ~7 log 5  
fill ~49 ~1 ~8 ~49 ~2 ~8 stone 0  
fill ~49 ~1 ~9 ~50 ~1 ~9 cobblestone 0  
fill ~49 ~1 ~10 ~49 ~1 ~11 stone 0  
fill ~49 ~1 ~12 ~50 ~1 ~12 stonebrick 0 
setblock ~49 ~1 ~16 log 5 
setblock ~49 ~1 ~17 stone_brick_stairs 0 
setblock ~49 ~1 ~18 stone_slab 5 
setblock ~49 ~1 ~19 stone_brick_stairs 0 
setblock ~49 ~1 ~30 log 5 
setblock ~49 ~1 ~35 log 5 
setblock ~49 ~1 ~46 stone_brick_stairs 0 
setblock ~49 ~1 ~47 stone_slab 5 
setblock ~49 ~1 ~48 stone_brick_stairs 0 
setblock ~49 ~1 ~49 log 5  
fill ~49 ~1 ~52 ~50 ~1 ~52 stonebrick 0  
fill ~49 ~1 ~53 ~50 ~1 ~53 stonebrick 0  
fill ~49 ~1 ~54 ~50 ~1 ~54 stone 0  
fill ~49 ~1 ~55 ~49 ~1 ~54 stone 0  
fill ~49 ~1 ~56 ~50 ~1 ~56 cobblestone 0  
fill ~49 ~1 ~57 ~49 ~2 ~57 stone 0 
setblock ~49 ~1 ~58 log 5 
setblock ~50 ~1 ~6 fence 1  
fill ~50 ~1 ~7 ~50 ~19 ~7 log 1 
setblock ~50 ~1 ~8 stonebrick 0 
setblock ~50 ~1 ~10 cobblestone 0  
fill ~50 ~1 ~11 ~50 ~3 ~11 stone 0  
fill ~50 ~1 ~16 ~50 ~14 ~16 log 1  
fill ~50 ~1 ~17 ~52 ~1 ~17 stonebrick 0  
fill ~50 ~1 ~18 ~59 ~1 ~18 stonebrick 0  
fill ~50 ~1 ~19 ~60 ~1 ~19 stonebrick 0 
setblock ~50 ~1 ~20 stone_brick_stairs 0  
fill ~50 ~1 ~21 ~50 ~1 ~25 stone_slab 5 
setblock ~50 ~1 ~26 stone_brick_stairs 0 
setblock ~50 ~1 ~27 stone_slab 5 
setblock ~50 ~1 ~28 stone_brick_stairs 0 
setblock ~50 ~1 ~29 stone_slab 5  
fill ~50 ~1 ~30 ~50 ~13 ~30 log 1  
fill ~50 ~1 ~31 ~50 ~1 ~34 stone_brick_stairs 0 
setblock ~50 ~1 ~36 stone_slab 5 
setblock ~50 ~1 ~37 stone_brick_stairs 0 
setblock ~50 ~1 ~38 stone_slab 5 
setblock ~50 ~1 ~39 stone_brick_stairs 0  
fill ~50 ~1 ~40 ~50 ~1 ~44 stone_slab 5 
setblock ~50 ~1 ~45 stone_brick_stairs 0  
fill ~50 ~1 ~46 ~60 ~1 ~46 stonebrick 0  
fill ~50 ~1 ~47 ~59 ~1 ~47 stonebrick 0  
fill ~50 ~1 ~48 ~50 ~3 ~48 stonebrick 0  
fill ~50 ~1 ~49 ~50 ~14 ~49 log 1 
setblock ~50 ~1 ~55 cobblestone 0 
setblock ~50 ~1 ~57 stonebrick 0  
fill ~50 ~1 ~58 ~50 ~19 ~58 log 1 
setblock ~50 ~1 ~59 fence 1 
setblock ~51 ~1 ~5 log 5  
fill ~51 ~1 ~6 ~52 ~1 ~6 cobblestone 0  
fill ~51 ~1 ~7 ~51 ~1 ~6 cobblestone 0 
setblock ~51 ~1 ~11 chest 5 
setblock ~51 ~1 ~12 bookshelf 0 
setblock ~51 ~1 ~13 stone 0  
fill ~51 ~1 ~15 ~52 ~1 ~15 stonebrick 0  
fill ~51 ~1 ~16 ~52 ~1 ~16 stonebrick 0  
fill ~51 ~1 ~20 ~60 ~1 ~20 stonebrick 0  
fill ~51 ~1 ~21 ~60 ~1 ~21 stonebrick 0  
fill ~51 ~1 ~22 ~59 ~1 ~22 stonebrick 0  
fill ~51 ~1 ~23 ~57 ~1 ~23 stonebrick 0  
fill ~51 ~1 ~24 ~57 ~1 ~24 stonebrick 0  
fill ~51 ~1 ~25 ~57 ~1 ~25 stonebrick 0  
fill ~51 ~1 ~26 ~56 ~1 ~26 stonebrick 0  
fill ~51 ~1 ~27 ~55 ~1 ~27 stonebrick 0  
fill ~51 ~1 ~28 ~54 ~1 ~28 stonebrick 0  
fill ~51 ~1 ~29 ~55 ~1 ~29 stonebrick 0  
fill ~51 ~1 ~30 ~54 ~1 ~30 stonebrick 0  
fill ~51 ~1 ~31 ~55 ~1 ~31 stonebrick 0  
fill ~51 ~1 ~32 ~54 ~1 ~32 stonebrick 0  
fill ~51 ~1 ~33 ~54 ~1 ~33 stonebrick 0  
fill ~51 ~1 ~34 ~55 ~1 ~34 stonebrick 0  
fill ~51 ~1 ~35 ~54 ~1 ~35 stonebrick 0  
fill ~51 ~1 ~36 ~55 ~1 ~36 stonebrick 0  
fill ~51 ~1 ~37 ~54 ~1 ~37 stonebrick 0  
fill ~51 ~1 ~38 ~55 ~1 ~38 stonebrick 0  
fill ~51 ~1 ~39 ~51 ~35 ~39 stonebrick 0  
fill ~51 ~1 ~40 ~57 ~1 ~40 stonebrick 0  
fill ~51 ~1 ~41 ~57 ~1 ~41 stonebrick 0  
fill ~51 ~1 ~42 ~57 ~1 ~42 stonebrick 0  
fill ~51 ~1 ~43 ~59 ~1 ~43 stonebrick 0  
fill ~51 ~1 ~44 ~60 ~1 ~44 stonebrick 0  
fill ~51 ~1 ~45 ~60 ~1 ~45 stonebrick 0  
fill ~51 ~1 ~48 ~51 ~1 ~50 monster_egg 2 
setblock ~51 ~1 ~52 stone 0 
setblock ~51 ~1 ~53 bookshelf 0 
setblock ~51 ~1 ~54 chest 5  
fill ~51 ~1 ~58 ~51 ~1 ~59 cobblestone 0 
setblock ~51 ~1 ~60 log 5  
fill ~52 ~1 ~5 ~52 ~19 ~5 log 1  
fill ~52 ~1 ~48 ~52 ~21 ~48 stonebrick 0 
setblock ~52 ~1 ~49 monster_egg 2  
fill ~52 ~1 ~50 ~52 ~20 ~50 stonebrick 0 
setblock ~52 ~1 ~59 cobblestone 0  
fill ~52 ~1 ~60 ~52 ~19 ~60 log 1 
setblock ~52 ~1 ~61 fence 1  
fill ~53 ~1 ~3 ~53 ~2 ~3 stonebrick 0  
fill ~53 ~1 ~4 ~57 ~1 ~4 stonebrick 0  
fill ~53 ~1 ~5 ~53 ~3 ~5 stonebrick 0  
fill ~53 ~1 ~15 ~54 ~1 ~15 stone 0  
fill ~53 ~1 ~16 ~53 ~1 ~17 stone 0  
fill ~53 ~1 ~39 ~56 ~1 ~39 stonebrick 0  
fill ~53 ~1 ~48 ~53 ~2 ~48 cobblestone 0  
fill ~53 ~1 ~49 ~53 ~3 ~49 stonebrick 0  
fill ~53 ~1 ~50 ~54 ~1 ~50 stone 0  
fill ~53 ~1 ~60 ~53 ~3 ~60 stonebrick 0  
fill ~53 ~1 ~61 ~54 ~1 ~61 stone 0  
fill ~53 ~1 ~62 ~53 ~1 ~61 stone 0  
fill ~54 ~1 ~3 ~56 ~1 ~3 log 1  
fill ~54 ~1 ~5 ~54 ~2 ~5 stone 0  
fill ~54 ~1 ~16 ~56 ~1 ~16 cobblestone 0  
fill ~54 ~1 ~17 ~56 ~1 ~17 stonebrick 0  
fill ~54 ~1 ~48 ~56 ~1 ~48 stonebrick 0  
fill ~54 ~1 ~49 ~55 ~1 ~49 stone 0  
fill ~54 ~1 ~60 ~54 ~2 ~60 stone 0  
fill ~54 ~1 ~62 ~56 ~1 ~62 log 1 
setblock ~55 ~1 ~5 stonebrick 0  
fill ~55 ~1 ~6 ~57 ~1 ~6 log 1 
setblock ~55 ~1 ~10 cobblestone 0  
fill ~55 ~1 ~15 ~55 ~3 ~15 stonebrick 0 
setblock ~55 ~1 ~28 stone_slab 5 
setblock ~55 ~1 ~30 stone_slab 5  
fill ~55 ~1 ~32 ~55 ~1 ~33 stone_slab 5 
setblock ~55 ~1 ~35 stone_slab 5 
setblock ~55 ~1 ~37 stone_slab 5  
fill ~55 ~1 ~50 ~55 ~3 ~50 stonebrick 0 
setblock ~55 ~1 ~55 cobblestone 0  
fill ~55 ~1 ~59 ~57 ~1 ~59 log 1  
fill ~55 ~1 ~60 ~55 ~1 ~61 stonebrick 0 
setblock ~56 ~1 ~5 stone 0 
setblock ~56 ~1 ~10 stone_slab 5 
setblock ~56 ~1 ~11 stone_slab 13 
setblock ~56 ~1 ~15 stone 0 
setblock ~56 ~1 ~27 stone_slab 5 
setblock ~56 ~1 ~29 stone_slab 5 
setblock ~56 ~1 ~31 stone_slab 5 
setblock ~56 ~1 ~34 stone_slab 5 
setblock ~56 ~1 ~36 stone_slab 5 
setblock ~56 ~1 ~38 stone_slab 5  
fill ~56 ~1 ~49 ~56 ~2 ~49 cobblestone 0 
setblock ~56 ~1 ~50 stone 0 
setblock ~56 ~1 ~54 stone_slab 13 
setblock ~56 ~1 ~55 stone_slab 5 
setblock ~56 ~1 ~60 stone 0  
fill ~56 ~1 ~61 ~57 ~1 ~61 stonebrick 0  
fill ~57 ~1 ~3 ~57 ~2 ~3 stonebrick 0 
setblock ~57 ~1 ~5 cobblestone 0 
setblock ~57 ~1 ~15 cobblestone 0 
setblock ~57 ~1 ~16 stone 0 
setblock ~57 ~1 ~17 cobblestone 0 
setblock ~57 ~1 ~26 stone_slab 5 
setblock ~57 ~1 ~39 stone_slab 5  
fill ~57 ~1 ~48 ~57 ~2 ~48 cobblestone 0  
fill ~57 ~1 ~49 ~57 ~2 ~49 stone 0 
setblock ~57 ~1 ~50 cobblestone 0 
setblock ~57 ~1 ~60 cobblestone 0 
setblock ~57 ~1 ~62 stone 0  
fill ~58 ~1 ~5 ~58 ~19 ~5 log 1  
fill ~58 ~1 ~6 ~59 ~1 ~6 stone 0 
setblock ~58 ~1 ~7 log 1  
fill ~58 ~1 ~14 ~58 ~3 ~14 stone 0  
fill ~58 ~1 ~15 ~58 ~19 ~15 log 1 
setblock ~58 ~1 ~16 fence 1  
fill ~58 ~1 ~17 ~59 ~1 ~17 stone_brick_stairs 2  
fill ~58 ~1 ~23 ~59 ~1 ~23 stone_brick_stairs 3  
fill ~58 ~1 ~24 ~58 ~1 ~25 stone_brick_stairs 1  
fill ~58 ~1 ~40 ~58 ~1 ~41 stone_brick_stairs 1  
fill ~58 ~1 ~42 ~59 ~1 ~42 stone_brick_stairs 2  
fill ~58 ~1 ~48 ~59 ~1 ~48 stone_brick_stairs 3 
setblock ~58 ~1 ~49 log 9  
fill ~58 ~1 ~50 ~58 ~19 ~50 log 1  
fill ~58 ~1 ~51 ~58 ~3 ~51 stone 0 
setblock ~58 ~1 ~58 log 1  
fill ~58 ~1 ~59 ~59 ~1 ~59 stone 0  
fill ~58 ~1 ~60 ~58 ~19 ~60 log 1 
setblock ~58 ~1 ~61 log 9 
setblock ~59 ~1 ~5 fence 1 
setblock ~59 ~1 ~7 stonebrick 0  
fill ~59 ~1 ~8 ~59 ~1 ~9 log 1 
setblock ~59 ~1 ~13 stone 0 
setblock ~59 ~1 ~14 stonebrick 0 
setblock ~59 ~1 ~15 log 5 
setblock ~59 ~1 ~50 log 5 
setblock ~59 ~1 ~51 stonebrick 0 
setblock ~59 ~1 ~52 stone 0  
fill ~59 ~1 ~56 ~59 ~1 ~57 log 1 
setblock ~59 ~1 ~58 stonebrick 0 
setblock ~59 ~1 ~60 fence 1 
setblock ~60 ~1 ~6 log 9  
fill ~60 ~1 ~7 ~60 ~19 ~7 log 1  
fill ~60 ~1 ~8 ~62 ~1 ~8 stonebrick 0  
fill ~60 ~1 ~9 ~60 ~1 ~10 stone 0  
fill ~60 ~1 ~11 ~61 ~1 ~11 cobblestone 0  
fill ~60 ~1 ~12 ~60 ~4 ~12 cobblestone 0  
fill ~60 ~1 ~13 ~60 ~19 ~13 log 1 
setblock ~60 ~1 ~14 fence 1 
setblock ~60 ~1 ~18 stone_brick_stairs 2 
setblock ~60 ~1 ~22 stone_brick_stairs 1 
setblock ~60 ~1 ~43 stone_brick_stairs 1 
setblock ~60 ~1 ~47 stone_brick_stairs 3 
setblock ~60 ~1 ~51 fence 1  
fill ~60 ~1 ~52 ~60 ~19 ~52 log 1  
fill ~60 ~1 ~53 ~60 ~4 ~53 cobblestone 0  
fill ~60 ~1 ~54 ~61 ~1 ~54 cobblestone 0  
fill ~60 ~1 ~55 ~60 ~1 ~56 stone 0  
fill ~60 ~1 ~57 ~62 ~1 ~57 stonebrick 0  
fill ~60 ~1 ~58 ~60 ~19 ~58 log 1 
setblock ~60 ~1 ~59 log 9 
setblock ~61 ~1 ~7 fence 1 
setblock ~61 ~1 ~9 cobblestone 0  
fill ~61 ~1 ~10 ~61 ~3 ~10 stonebrick 0 
setblock ~61 ~1 ~12 stone 0 
setblock ~61 ~1 ~13 log 5  
fill ~61 ~1 ~19 ~61 ~1 ~21 stone_brick_stairs 1  
fill ~61 ~1 ~44 ~61 ~1 ~46 stone_brick_stairs 1 
setblock ~61 ~1 ~52 log 5 
setblock ~61 ~1 ~53 stone 0  
fill ~61 ~1 ~55 ~61 ~3 ~55 stonebrick 0 
setblock ~61 ~1 ~56 cobblestone 0 
setblock ~61 ~1 ~58 fence 1  
fill ~62 ~1 ~9 ~62 ~1 ~11 log 1  
fill ~62 ~1 ~12 ~62 ~2 ~12 stonebrick 0  
fill ~62 ~1 ~53 ~62 ~2 ~53 stonebrick 0  
fill ~62 ~1 ~54 ~62 ~1 ~56 log 1 
setblock ~3 ~2 ~8 stone 0  
fill ~3 ~2 ~9 ~3 ~2 ~11 spruce_stairs 4  
fill ~3 ~2 ~54 ~3 ~2 ~56 spruce_stairs 4 
setblock ~3 ~2 ~57 stone 0 
setblock ~4 ~2 ~7 fence 1  
fill ~4 ~2 ~8 ~5 ~2 ~8 cobblestone 0  
fill ~4 ~2 ~9 ~4 ~2 ~10 stone 0 
setblock ~4 ~2 ~11 cobblestone 0 
setblock ~4 ~2 ~13 log 5 
setblock ~4 ~2 ~19 double_stone_slab 13 
setblock ~4 ~2 ~20 stone_slab 5 
setblock ~4 ~2 ~21 double_stone_slab 13 
setblock ~4 ~2 ~44 double_stone_slab 13 
setblock ~4 ~2 ~45 stone_slab 5 
setblock ~4 ~2 ~46 double_stone_slab 13 
setblock ~4 ~2 ~52 log 5 
setblock ~4 ~2 ~54 cobblestone 0  
fill ~4 ~2 ~55 ~5 ~2 ~55 stone 0  
fill ~4 ~2 ~56 ~4 ~2 ~55 stone 0  
fill ~4 ~2 ~57 ~5 ~2 ~57 cobblestone 0 
setblock ~4 ~2 ~58 fence 1 
setblock ~5 ~2 ~6 log 9 
setblock ~5 ~2 ~9 cobblestone 0  
fill ~5 ~2 ~10 ~5 ~2 ~12 stone 0 
setblock ~5 ~2 ~14 fence 1 
setblock ~5 ~2 ~18 stone_slab 5  
fill ~5 ~2 ~19 ~16 ~2 ~19 stonebrick 0  
fill ~5 ~2 ~20 ~15 ~2 ~20 stonebrick 0  
fill ~5 ~2 ~21 ~13 ~2 ~21 stonebrick 0 
setblock ~5 ~2 ~22 stone_slab 5 
setblock ~5 ~2 ~43 stone_slab 5  
fill ~5 ~2 ~44 ~13 ~2 ~44 stonebrick 0  
fill ~5 ~2 ~45 ~15 ~2 ~45 stonebrick 0  
fill ~5 ~2 ~46 ~16 ~2 ~46 stonebrick 0 
setblock ~5 ~2 ~47 stone_slab 5 
setblock ~5 ~2 ~51 fence 1  
fill ~5 ~2 ~53 ~5 ~3 ~53 stone 0  
fill ~5 ~2 ~54 ~5 ~3 ~54 stone 0 
setblock ~5 ~2 ~56 cobblestone 0 
setblock ~5 ~2 ~59 log 9 
setblock ~6 ~2 ~5 fence 1  
fill ~6 ~2 ~6 ~6 ~2 ~7 stone 0 
setblock ~6 ~2 ~13 stonebrick 0 
setblock ~6 ~2 ~14 cobblestone 0 
setblock ~6 ~2 ~15 log 5 
setblock ~6 ~2 ~17 stone_slab 5  
fill ~6 ~2 ~18 ~15 ~2 ~18 stonebrick 0  
fill ~6 ~2 ~22 ~13 ~2 ~22 stonebrick 0 
setblock ~6 ~2 ~23 stone_slab 5 
setblock ~6 ~2 ~42 stone_slab 5  
fill ~6 ~2 ~43 ~13 ~2 ~43 stonebrick 0  
fill ~6 ~2 ~47 ~15 ~2 ~47 stonebrick 0 
setblock ~6 ~2 ~48 stone_slab 5 
setblock ~6 ~2 ~50 log 5 
setblock ~6 ~2 ~51 cobblestone 0 
setblock ~6 ~2 ~52 stonebrick 0  
fill ~6 ~2 ~58 ~6 ~3 ~58 stone 0  
fill ~6 ~2 ~59 ~6 ~2 ~58 stone 0 
setblock ~6 ~2 ~60 fence 1 
setblock ~7 ~2 ~4 log 9  
fill ~7 ~2 ~6 ~7 ~3 ~6 stonebrick 0 
setblock ~7 ~2 ~14 stonebrick 0 
setblock ~7 ~2 ~16 fence 1 
setblock ~7 ~2 ~17 double_stone_slab 13 
setblock ~7 ~2 ~23 double_stone_slab 13  
fill ~7 ~2 ~24 ~7 ~2 ~25 stone_slab 5  
fill ~7 ~2 ~40 ~7 ~2 ~41 stone_slab 5 
setblock ~7 ~2 ~42 double_stone_slab 13 
setblock ~7 ~2 ~48 double_stone_slab 13 
setblock ~7 ~2 ~49 fence 1 
setblock ~7 ~2 ~51 stonebrick 0  
fill ~7 ~2 ~59 ~7 ~3 ~59 stonebrick 0 
setblock ~7 ~2 ~61 log 9  
fill ~8 ~2 ~3 ~8 ~2 ~5 stone 0  
fill ~8 ~2 ~15 ~8 ~3 ~15 stone 0  
fill ~8 ~2 ~23 ~13 ~2 ~23 stonebrick 0  
fill ~8 ~2 ~24 ~13 ~2 ~24 stonebrick 0  
fill ~8 ~2 ~25 ~13 ~2 ~25 stonebrick 0  
fill ~8 ~2 ~40 ~13 ~2 ~40 stonebrick 0  
fill ~8 ~2 ~41 ~13 ~2 ~41 stonebrick 0  
fill ~8 ~2 ~42 ~13 ~2 ~42 stonebrick 0  
fill ~8 ~2 ~48 ~11 ~2 ~48 stonebrick 0  
fill ~8 ~2 ~49 ~9 ~2 ~49 cobblestone 0  
fill ~8 ~2 ~50 ~8 ~3 ~50 stone 0  
fill ~8 ~2 ~61 ~9 ~2 ~61 stone 0  
fill ~8 ~2 ~62 ~8 ~2 ~60 stone 0  
fill ~9 ~2 ~3 ~11 ~2 ~3 spruce_stairs 6 
setblock ~9 ~2 ~4 stone 0 
setblock ~9 ~2 ~11 stone_slab 13  
fill ~9 ~2 ~15 ~11 ~2 ~15 cobblestone 0  
fill ~9 ~2 ~17 ~11 ~2 ~17 stonebrick 0  
fill ~9 ~2 ~50 ~11 ~2 ~50 cobblestone 0 
setblock ~9 ~2 ~54 stone_slab 13  
fill ~9 ~2 ~62 ~11 ~2 ~62 spruce_stairs 7 
setblock ~10 ~2 ~4 cobblestone 0  
fill ~10 ~2 ~5 ~12 ~2 ~5 stone 0 
setblock ~10 ~2 ~6 chest 3 
setblock ~10 ~2 ~11 stone_slab 5  
fill ~10 ~2 ~16 ~10 ~3 ~16 cobblestone 0  
fill ~10 ~2 ~26 ~15 ~2 ~26 stonebrick 0  
fill ~10 ~2 ~39 ~15 ~2 ~39 stonebrick 0 
setblock ~10 ~2 ~49 stonebrick 0 
setblock ~10 ~2 ~54 stone_slab 5 
setblock ~10 ~2 ~59 chest 2  
fill ~10 ~2 ~60 ~12 ~2 ~60 stone 0 
setblock ~10 ~2 ~61 cobblestone 0  
fill ~11 ~2 ~4 ~11 ~3 ~4 stonebrick 0  
fill ~11 ~2 ~16 ~14 ~2 ~16 stonebrick 0  
fill ~11 ~2 ~27 ~14 ~2 ~27 stonebrick 0  
fill ~11 ~2 ~28 ~15 ~2 ~28 stonebrick 0  
fill ~11 ~2 ~29 ~14 ~2 ~29 stonebrick 0  
fill ~11 ~2 ~30 ~14 ~2 ~30 stonebrick 0  
fill ~11 ~2 ~31 ~15 ~2 ~31 stonebrick 0  
fill ~11 ~2 ~32 ~15 ~2 ~32 stonebrick 0  
fill ~11 ~2 ~33 ~15 ~2 ~33 stonebrick 0  
fill ~11 ~2 ~34 ~15 ~2 ~34 stonebrick 0  
fill ~11 ~2 ~35 ~14 ~2 ~35 stonebrick 0  
fill ~11 ~2 ~36 ~14 ~2 ~36 stonebrick 0  
fill ~11 ~2 ~37 ~15 ~2 ~37 stonebrick 0  
fill ~11 ~2 ~38 ~14 ~2 ~38 stonebrick 0  
fill ~11 ~2 ~49 ~11 ~1 ~49 stone 0  
fill ~11 ~2 ~61 ~11 ~3 ~61 stonebrick 0 
setblock ~12 ~2 ~4 cobblestone 0  
fill ~12 ~2 ~15 ~12 ~3 ~15 stonebrick 0  
fill ~12 ~2 ~49 ~12 ~2 ~50 stonebrick 0 
setblock ~12 ~2 ~61 cobblestone 0 
setblock ~12 ~2 ~62 stonebrick 0 
setblock ~13 ~2 ~4 fence 1 
setblock ~13 ~2 ~6 cobblestone 0  
fill ~13 ~2 ~17 ~16 ~2 ~17 stonebrick 0 
setblock ~13 ~2 ~59 cobblestone 0 
setblock ~13 ~2 ~61 fence 1 
setblock ~14 ~2 ~5 log 5 
setblock ~14 ~2 ~13 cobblestone 0  
fill ~14 ~2 ~21 ~14 ~2 ~25 stone_brick_stairs 5  
fill ~14 ~2 ~40 ~14 ~2 ~44 stone_brick_stairs 5  
fill ~14 ~2 ~48 ~14 ~48 ~48 stonebrick 0  
fill ~14 ~2 ~49 ~14 ~24 ~49 stonebrick 0  
fill ~14 ~2 ~50 ~14 ~22 ~50 stonebrick 0 
setblock ~14 ~2 ~52 cobblestone 0 
setblock ~14 ~2 ~60 log 5 
setblock ~15 ~2 ~6 fence 1  
fill ~15 ~2 ~10 ~16 ~2 ~10 cobblestone 0 
setblock ~15 ~2 ~11 stonebrick 0 
setblock ~15 ~2 ~12 stone 0  
fill ~15 ~2 ~13 ~17 ~2 ~13 stonebrick 0  
fill ~15 ~2 ~52 ~16 ~2 ~52 stonebrick 0  
fill ~15 ~2 ~53 ~16 ~2 ~53 stonebrick 0  
fill ~15 ~2 ~54 ~26 ~2 ~54 stonebrick 0  
fill ~15 ~2 ~55 ~16 ~2 ~55 cobblestone 0  
fill ~15 ~2 ~56 ~16 ~2 ~56 stone 0 
setblock ~15 ~2 ~59 fence 1 
setblock ~16 ~2 ~7 log 5  
fill ~16 ~2 ~8 ~16 ~1 ~8 cobblestone 0 
setblock ~16 ~2 ~9 stone 0 
setblock ~16 ~2 ~16 fence 1 
setblock ~16 ~2 ~30 anvil 0 
setblock ~16 ~2 ~35 anvil 0 
setblock ~16 ~2 ~48 stonebrick 0 
setblock ~16 ~2 ~49 fence 1  
fill ~16 ~2 ~57 ~16 ~1 ~57 cobblestone 0 
setblock ~16 ~2 ~58 log 5 
setblock ~17 ~2 ~6 stone_slab 5 
setblock ~17 ~2 ~7 double_stone_slab 13  
fill ~17 ~2 ~8 ~25 ~2 ~8 stonebrick 0  
fill ~17 ~2 ~9 ~25 ~2 ~9 stonebrick 0  
fill ~17 ~2 ~10 ~26 ~2 ~10 stonebrick 0  
fill ~17 ~2 ~11 ~49 ~2 ~11 stonebrick 0  
fill ~17 ~2 ~55 ~26 ~2 ~55 stonebrick 0  
fill ~17 ~2 ~56 ~25 ~2 ~56 stonebrick 0  
fill ~17 ~2 ~57 ~25 ~2 ~57 stonebrick 0 
setblock ~17 ~2 ~58 double_stone_slab 13 
setblock ~17 ~2 ~59 stone_slab 5 
setblock ~18 ~2 ~5 stone_slab 5  
fill ~18 ~2 ~6 ~22 ~2 ~6 stonebrick 0  
fill ~18 ~2 ~7 ~22 ~2 ~7 stonebrick 0  
fill ~18 ~2 ~12 ~47 ~2 ~12 stonebrick 0 
setblock ~18 ~2 ~13 stone_brick_stairs 1  
fill ~18 ~2 ~58 ~22 ~2 ~58 stonebrick 0  
fill ~18 ~2 ~59 ~22 ~2 ~59 stonebrick 0 
setblock ~18 ~2 ~60 stone_slab 5 
setblock ~19 ~2 ~4 double_stone_slab 13  
fill ~19 ~2 ~5 ~21 ~2 ~5 stonebrick 0  
fill ~19 ~2 ~13 ~19 ~3 ~13 stonebrick 0 
setblock ~19 ~2 ~53 stone_slab 13  
fill ~19 ~2 ~60 ~21 ~2 ~60 stonebrick 0 
setblock ~19 ~2 ~61 double_stone_slab 13 
setblock ~20 ~2 ~4 stone_slab 5 
setblock ~20 ~2 ~13 stone_brick_stairs 3 
setblock ~20 ~2 ~61 stone_slab 5  
fill ~21 ~2 ~13 ~44 ~2 ~13 stonebrick 0  
fill ~21 ~2 ~53 ~26 ~2 ~53 stonebrick 0 
setblock ~21 ~2 ~61 double_stone_slab 13 
setblock ~22 ~2 ~5 stone_slab 5 
setblock ~22 ~2 ~14 fence 1 
setblock ~22 ~2 ~20 fence 1 
setblock ~22 ~2 ~32 fence 1 
setblock ~22 ~2 ~38 fence 1 
setblock ~22 ~2 ~52 stone_brick_stairs 2 
setblock ~22 ~2 ~60 stone_slab 5 
setblock ~23 ~2 ~6 stone_slab 5 
setblock ~23 ~2 ~7 double_stone_slab 13  
fill ~23 ~2 ~16 ~25 ~2 ~16 stonebrick 0  
fill ~23 ~2 ~18 ~24 ~2 ~18 stonebrick 0  
fill ~23 ~2 ~34 ~24 ~2 ~34 stonebrick 0  
fill ~23 ~2 ~36 ~24 ~2 ~36 stonebrick 0  
fill ~23 ~2 ~39 ~26 ~2 ~39 stonebrick 0  
fill ~23 ~2 ~42 ~26 ~2 ~42 stonebrick 0  
fill ~23 ~2 ~52 ~23 ~3 ~52 stonebrick 0 
setblock ~23 ~2 ~58 double_stone_slab 13 
setblock ~23 ~2 ~59 stone_slab 5  
fill ~24 ~2 ~7 ~25 ~2 ~7 stone_slab 5  
fill ~24 ~2 ~19 ~26 ~2 ~19 stonebrick 0  
fill ~24 ~2 ~21 ~24 ~14 ~21 stonebrick 0  
fill ~24 ~2 ~31 ~24 ~32 ~31 stonebrick 0  
fill ~24 ~2 ~43 ~26 ~2 ~43 stonebrick 0 
setblock ~24 ~2 ~44 stone_brick_stairs 4  
fill ~24 ~2 ~45 ~25 ~2 ~45 stonebrick 0  
fill ~24 ~2 ~58 ~25 ~2 ~58 stone_slab 5  
fill ~25 ~2 ~20 ~25 ~13 ~20 log 1  
fill ~25 ~2 ~38 ~26 ~2 ~38 log 1  
fill ~25 ~2 ~44 ~25 ~14 ~44 stonebrick 0  
fill ~25 ~2 ~46 ~25 ~14 ~46 stonebrick 0  
fill ~25 ~2 ~48 ~25 ~4 ~48 stonebrick 0  
fill ~25 ~2 ~50 ~25 ~1 ~50 stonebrick 0  
fill ~25 ~2 ~52 ~25 ~11 ~52 stonebrick 0 
setblock ~26 ~2 ~20 fence 1 
setblock ~26 ~2 ~32 fence 1 
setblock ~26 ~2 ~44 stone_slab 5 
setblock ~27 ~2 ~19 stone_brick_stairs 1  
fill ~27 ~2 ~38 ~30 ~2 ~38 stonebrick 0 
setblock ~27 ~2 ~45 dropper 0 
setblock ~27 ~2 ~49 dropper 0 
setblock ~30 ~2 ~14 stone_brick_stairs 7 
setblock ~30 ~2 ~19 anvil 3  
fill ~30 ~2 ~37 ~35 ~2 ~37 stonebrick 0  
fill ~31 ~2 ~14 ~31 ~3 ~14 stonebrick 0 
setblock ~31 ~2 ~15 stone_brick_stairs 7  
fill ~32 ~2 ~14 ~33 ~2 ~14 stone_slab 5  
fill ~32 ~2 ~38 ~33 ~2 ~38 stonebrick 0  
fill ~32 ~2 ~39 ~33 ~2 ~39 stonebrick 0  
fill ~34 ~2 ~14 ~34 ~3 ~14 stonebrick 0 
setblock ~34 ~2 ~15 stone_brick_stairs 7 
setblock ~35 ~2 ~14 stone_brick_stairs 7 
setblock ~35 ~2 ~19 anvil 3  
fill ~35 ~2 ~38 ~38 ~2 ~38 stonebrick 0 
setblock ~38 ~2 ~19 stone_brick_stairs 0 
setblock ~38 ~2 ~45 dropper 0 
setblock ~38 ~2 ~49 dropper 0  
fill ~39 ~2 ~10 ~48 ~2 ~10 stonebrick 0  
fill ~39 ~2 ~19 ~41 ~2 ~19 stonebrick 0 
setblock ~39 ~2 ~20 fence 1 
setblock ~39 ~2 ~32 fence 1  
fill ~39 ~2 ~38 ~40 ~2 ~38 log 1  
fill ~39 ~2 ~39 ~42 ~2 ~39 stonebrick 0  
fill ~39 ~2 ~42 ~42 ~2 ~42 stonebrick 0  
fill ~39 ~2 ~43 ~41 ~2 ~43 stonebrick 0 
setblock ~39 ~2 ~44 stone_slab 5  
fill ~39 ~2 ~53 ~44 ~2 ~53 stonebrick 0  
fill ~39 ~2 ~54 ~49 ~2 ~54 stonebrick 0  
fill ~39 ~2 ~55 ~46 ~2 ~55 stonebrick 0  
fill ~40 ~2 ~7 ~41 ~2 ~7 stone_slab 5  
fill ~40 ~2 ~8 ~47 ~2 ~8 stonebrick 0  
fill ~40 ~2 ~9 ~48 ~2 ~9 stonebrick 0  
fill ~40 ~2 ~16 ~42 ~2 ~16 stonebrick 0  
fill ~40 ~2 ~32 ~40 ~13 ~32 log 1  
fill ~40 ~2 ~44 ~40 ~14 ~44 stonebrick 0  
fill ~40 ~2 ~45 ~41 ~2 ~45 stonebrick 0  
fill ~40 ~2 ~46 ~40 ~14 ~46 stonebrick 0  
fill ~40 ~2 ~48 ~40 ~4 ~48 stonebrick 0 
setblock ~40 ~2 ~50 stonebrick 0  
fill ~40 ~2 ~52 ~40 ~11 ~52 stonebrick 0  
fill ~40 ~2 ~56 ~48 ~2 ~56 stonebrick 0  
fill ~40 ~2 ~57 ~47 ~2 ~57 stonebrick 0  
fill ~40 ~2 ~58 ~41 ~2 ~58 stone_slab 5  
fill ~41 ~2 ~18 ~42 ~2 ~18 stonebrick 0  
fill ~41 ~2 ~21 ~41 ~14 ~21 stonebrick 0  
fill ~41 ~2 ~31 ~41 ~32 ~31 stonebrick 0  
fill ~41 ~2 ~34 ~42 ~2 ~34 stonebrick 0  
fill ~41 ~2 ~36 ~42 ~2 ~36 stonebrick 0 
setblock ~41 ~2 ~44 stone_brick_stairs 5 
setblock ~42 ~2 ~6 stone_slab 5 
setblock ~42 ~2 ~7 double_stone_slab 13  
fill ~42 ~2 ~52 ~42 ~3 ~52 stonebrick 0 
setblock ~42 ~2 ~58 double_stone_slab 13 
setblock ~42 ~2 ~59 stone_slab 5 
setblock ~43 ~2 ~5 stone_slab 5  
fill ~43 ~2 ~6 ~47 ~2 ~6 stonebrick 0  
fill ~43 ~2 ~7 ~47 ~2 ~7 stonebrick 0 
setblock ~43 ~2 ~14 fence 1 
setblock ~43 ~2 ~20 fence 1 
setblock ~43 ~2 ~32 fence 1 
setblock ~43 ~2 ~38 fence 1 
setblock ~43 ~2 ~52 stone_brick_stairs 2  
fill ~43 ~2 ~58 ~47 ~2 ~58 stonebrick 0  
fill ~43 ~2 ~59 ~47 ~2 ~59 stonebrick 0 
setblock ~43 ~2 ~60 stone_slab 5  
fill ~44 ~2 ~5 ~46 ~2 ~5 stonebrick 0  
fill ~44 ~2 ~60 ~46 ~2 ~60 stonebrick 0 
setblock ~44 ~2 ~61 double_stone_slab 13 
setblock ~45 ~2 ~13 stone_brick_stairs 3 
setblock ~45 ~2 ~61 stone_slab 5  
fill ~46 ~2 ~13 ~46 ~3 ~13 stonebrick 0 
setblock ~46 ~2 ~53 stone_slab 13 
setblock ~46 ~2 ~61 double_stone_slab 13 
setblock ~47 ~2 ~5 stone_slab 5 
setblock ~47 ~2 ~13 stone_brick_stairs 0 
setblock ~47 ~2 ~60 stone_slab 5 
setblock ~48 ~2 ~6 stone_slab 5 
setblock ~48 ~2 ~7 double_stone_slab 13  
fill ~48 ~2 ~13 ~50 ~2 ~13 stonebrick 0 
setblock ~48 ~2 ~58 double_stone_slab 13 
setblock ~48 ~2 ~59 stone_slab 5 
setblock ~49 ~2 ~7 fence 1  
fill ~49 ~2 ~9 ~49 ~1 ~9 cobblestone 0  
fill ~49 ~2 ~10 ~49 ~3 ~10 cobblestone 0  
fill ~49 ~2 ~12 ~50 ~2 ~12 stonebrick 0 
setblock ~49 ~2 ~16 fence 1  
fill ~49 ~2 ~17 ~52 ~2 ~17 stonebrick 0  
fill ~49 ~2 ~19 ~60 ~2 ~19 stonebrick 0 
setblock ~49 ~2 ~30 anvil 0 
setblock ~49 ~2 ~35 anvil 0  
fill ~49 ~2 ~46 ~60 ~2 ~46 stonebrick 0 
setblock ~49 ~2 ~48 stonebrick 0 
setblock ~49 ~2 ~49 fence 1  
fill ~49 ~2 ~52 ~50 ~2 ~52 stonebrick 0  
fill ~49 ~2 ~53 ~50 ~2 ~53 stonebrick 0  
fill ~49 ~2 ~55 ~49 ~3 ~55 cobblestone 0  
fill ~49 ~2 ~56 ~49 ~1 ~56 cobblestone 0 
setblock ~49 ~2 ~58 fence 1 
setblock ~50 ~2 ~6 log 9 
setblock ~50 ~2 ~8 stone 0 
setblock ~50 ~2 ~9 stonebrick 0 
setblock ~50 ~2 ~10 stone 0  
fill ~50 ~2 ~18 ~59 ~2 ~18 stonebrick 0  
fill ~50 ~2 ~20 ~60 ~2 ~20 stonebrick 0  
fill ~50 ~2 ~26 ~55 ~2 ~26 stonebrick 0  
fill ~50 ~2 ~28 ~54 ~2 ~28 stonebrick 0  
fill ~50 ~2 ~31 ~54 ~2 ~31 stonebrick 0  
fill ~50 ~2 ~32 ~54 ~2 ~32 stonebrick 0  
fill ~50 ~2 ~33 ~54 ~2 ~33 stonebrick 0  
fill ~50 ~2 ~34 ~54 ~2 ~34 stonebrick 0  
fill ~50 ~2 ~37 ~54 ~2 ~37 stonebrick 0 
setblock ~50 ~2 ~39 stonebrick 0  
fill ~50 ~2 ~45 ~60 ~2 ~45 stonebrick 0  
fill ~50 ~2 ~47 ~59 ~2 ~47 stonebrick 0  
fill ~50 ~2 ~54 ~50 ~3 ~54 stone 0  
fill ~50 ~2 ~55 ~50 ~2 ~54 stone 0 
setblock ~50 ~2 ~56 stonebrick 0 
setblock ~50 ~2 ~57 stone 0 
setblock ~50 ~2 ~59 log 9 
setblock ~51 ~2 ~5 fence 1  
fill ~51 ~2 ~6 ~52 ~2 ~6 stone 0  
fill ~51 ~2 ~7 ~51 ~2 ~6 stone 0 
setblock ~51 ~2 ~13 cobblestone 0  
fill ~51 ~2 ~15 ~53 ~2 ~15 stonebrick 0  
fill ~51 ~2 ~16 ~53 ~2 ~16 stonebrick 0  
fill ~51 ~2 ~21 ~51 ~2 ~25 stone_brick_stairs 4  
fill ~51 ~2 ~27 ~54 ~2 ~27 stonebrick 0  
fill ~51 ~2 ~29 ~54 ~2 ~29 stonebrick 0  
fill ~51 ~2 ~30 ~54 ~2 ~30 stonebrick 0  
fill ~51 ~2 ~35 ~54 ~2 ~35 stonebrick 0  
fill ~51 ~2 ~36 ~54 ~2 ~36 stonebrick 0  
fill ~51 ~2 ~38 ~54 ~2 ~38 stonebrick 0  
fill ~51 ~2 ~40 ~51 ~2 ~44 stone_brick_stairs 4  
fill ~51 ~2 ~48 ~51 ~48 ~48 stonebrick 0  
fill ~51 ~2 ~49 ~54 ~2 ~49 stonebrick 0  
fill ~51 ~2 ~50 ~51 ~23 ~50 stonebrick 0 
setblock ~51 ~2 ~52 cobblestone 0  
fill ~51 ~2 ~58 ~51 ~2 ~59 stone 0 
setblock ~51 ~2 ~60 fence 1  
fill ~52 ~2 ~21 ~60 ~2 ~21 stonebrick 0  
fill ~52 ~2 ~22 ~59 ~2 ~22 stonebrick 0  
fill ~52 ~2 ~23 ~57 ~2 ~23 stonebrick 0  
fill ~52 ~2 ~24 ~57 ~2 ~24 stonebrick 0
fill ~52 ~2 ~25 ~57 ~2 ~25 stonebrick 0  
fill ~52 ~2 ~39 ~55 ~2 ~39 stonebrick 0  
fill ~52 ~2 ~40 ~57 ~2 ~40 stonebrick 0  
fill ~52 ~2 ~41 ~57 ~2 ~41 stonebrick 0  
fill ~52 ~2 ~42 ~57 ~2 ~42 stonebrick 0  
fill ~52 ~2 ~43 ~59 ~2 ~43 stonebrick 0  
fill ~52 ~2 ~44 ~60 ~2 ~44 stonebrick 0  
fill ~52 ~2 ~59 ~52 ~3 ~59 stone 0 
setblock ~52 ~2 ~61 log 9  
fill ~53 ~2 ~4 ~57 ~2 ~4 stonebrick 0 
setblock ~53 ~2 ~17 stone 0  
fill ~53 ~2 ~50 ~53 ~4 ~50 stonebrick 0  
fill ~53 ~2 ~61 ~53 ~3 ~61 stone 0 
setblock ~53 ~2 ~62 cobblestone 0  
fill ~54 ~2 ~3 ~56 ~2 ~3 spruce_stairs 6 
setblock ~54 ~2 ~11 stone_slab 13  
fill ~54 ~2 ~15 ~54 ~3 ~15 cobblestone 0  
fill ~54 ~2 ~16 ~54 ~4 ~16 stone 0  
fill ~54 ~2 ~17 ~57 ~2 ~17 stonebrick 0  
fill ~54 ~2 ~48 ~56 ~2 ~48 stonebrick 0  
fill ~54 ~2 ~50 ~54 ~3 ~50 cobblestone 0 
setblock ~54 ~2 ~54 stone_slab 13 
setblock ~54 ~2 ~61 stonebrick 0  
fill ~54 ~2 ~62 ~56 ~2 ~62 spruce_stairs 7 
setblock ~55 ~2 ~5 stone 0 
setblock ~55 ~2 ~6 chest 3 
setblock ~55 ~2 ~10 stone 0 
setblock ~55 ~2 ~11 stone_slab 5 
setblock ~55 ~2 ~16 cobblestone 0  
fill ~55 ~2 ~49 ~55 ~3 ~49 cobblestone 0 
setblock ~55 ~2 ~54 stone_slab 5 
setblock ~55 ~2 ~55 stone 0 
setblock ~55 ~2 ~59 chest 2  
fill ~55 ~2 ~60 ~55 ~2 ~61 stone 0  
fill ~56 ~2 ~5 ~57 ~2 ~5 stonebrick 0  
fill ~56 ~2 ~15 ~57 ~2 ~15 stonebrick 0  
fill ~56 ~2 ~16 ~56 ~3 ~16 stone 0  
fill ~56 ~2 ~50 ~57 ~2 ~50 stonebrick 0  
fill ~56 ~2 ~60 ~57 ~2 ~60 stonebrick 0  
fill ~56 ~2 ~61 ~56 ~3 ~61 stone 0  
fill ~57 ~2 ~16 ~57 ~3 ~16 stonebrick 0  
fill ~57 ~2 ~61 ~57 ~3 ~61 cobblestone 0  
fill ~57 ~2 ~62 ~57 ~2 ~61 cobblestone 0  
fill ~58 ~2 ~6 ~59 ~2 ~6 stone 0 
setblock ~58 ~2 ~16 log 9 
setblock ~58 ~2 ~17 double_stone_slab 13 
setblock ~58 ~2 ~23 double_stone_slab 13  
fill ~58 ~2 ~24 ~58 ~2 ~25 stone_slab 5  
fill ~58 ~2 ~40 ~58 ~2 ~41 stone_slab 5 
setblock ~58 ~2 ~42 double_stone_slab 13 
setblock ~58 ~2 ~48 double_stone_slab 13 
setblock ~58 ~2 ~49 fence 1  
fill ~58 ~2 ~59 ~59 ~2 ~59 stone 0 
setblock ~58 ~2 ~61 fence 1 
setblock ~59 ~2 ~5 log 5 
setblock ~59 ~2 ~7 stone 0  
fill ~59 ~2 ~13 ~59 ~3 ~13 cobblestone 0 
setblock ~59 ~2 ~14 stone 0 
setblock ~59 ~2 ~15 fence 1 
setblock ~59 ~2 ~17 stone_slab 5 
setblock ~59 ~2 ~23 stone_slab 5 
setblock ~59 ~2 ~42 stone_slab 5 
setblock ~59 ~2 ~48 stone_slab 5 
setblock ~59 ~2 ~50 fence 1 
setblock ~59 ~2 ~51 stone 0  
fill ~59 ~2 ~52 ~59 ~3 ~52 cobblestone 0 
setblock ~59 ~2 ~58 stone 0 
setblock ~59 ~2 ~60 log 5 
setblock ~60 ~2 ~6 fence 1  
fill ~60 ~2 ~8 ~61 ~2 ~8 stonebrick 0  
fill ~60 ~2 ~9 ~60 ~2 ~10 cobblestone 0 
setblock ~60 ~2 ~11 stone 0 
setblock ~60 ~2 ~14 log 9 
setblock ~60 ~2 ~18 stone_slab 5 
setblock ~60 ~2 ~22 stone_slab 5 
setblock ~60 ~2 ~43 stone_slab 5 
setblock ~60 ~2 ~47 stone_slab 5 
setblock ~60 ~2 ~51 log 9 
setblock ~60 ~2 ~54 stone 0  
fill ~60 ~2 ~55 ~60 ~3 ~55 cobblestone 0  
fill ~60 ~2 ~56 ~60 ~2 ~55 cobblestone 0  
fill ~60 ~2 ~57 ~61 ~2 ~57 stonebrick 0 
setblock ~60 ~2 ~59 fence 1 
setblock ~61 ~2 ~7 log 5 
setblock ~61 ~2 ~9 stonebrick 0  
fill ~61 ~2 ~11 ~61 ~3 ~11 stonebrick 0 
setblock ~61 ~2 ~12 cobblestone 0 
setblock ~61 ~2 ~13 fence 1 
setblock ~61 ~2 ~19 double_stone_slab 13 
setblock ~61 ~2 ~20 stone_slab 5 
setblock ~61 ~2 ~21 double_stone_slab 13 
setblock ~61 ~2 ~44 double_stone_slab 13 
setblock ~61 ~2 ~45 stone_slab 5 
setblock ~61 ~2 ~46 double_stone_slab 13 
setblock ~61 ~2 ~52 fence 1 
setblock ~61 ~2 ~53 cobblestone 0  
fill ~61 ~2 ~54 ~61 ~3 ~54 stonebrick 0 
setblock ~61 ~2 ~56 stonebrick 0 
setblock ~61 ~2 ~58 log 5 
setblock ~62 ~2 ~8 stone 0  
fill ~62 ~2 ~9 ~62 ~2 ~11 spruce_stairs 5  
fill ~62 ~2 ~54 ~62 ~2 ~56 spruce_stairs 5 
setblock ~62 ~2 ~57 stone 0 
setblock ~3 ~3 ~8 stone_brick_stairs 0 
setblock ~3 ~3 ~12 stone_brick_stairs 0 
setblock ~3 ~3 ~53 stone_brick_stairs 0 
setblock ~3 ~3 ~57 stone_brick_stairs 0 
setblock ~4 ~3 ~7 log 5  
fill ~4 ~3 ~8 ~5 ~3 ~8 stonebrick 0  
fill ~4 ~3 ~9 ~4 ~3 ~10 cobblestone 0  
fill ~4 ~3 ~11 ~5 ~3 ~11 stone 0  
fill ~4 ~3 ~12 ~5 ~3 ~12 stone 0 
setblock ~4 ~3 ~13 fence 1 
setblock ~4 ~3 ~52 fence 1  
fill ~4 ~3 ~53 ~4 ~3 ~54 stone 0  
fill ~4 ~3 ~55 ~5 ~3 ~55 cobblestone 0  
fill ~4 ~3 ~56 ~4 ~3 ~55 cobblestone 0  
fill ~4 ~3 ~57 ~5 ~3 ~57 stonebrick 0 
setblock ~4 ~3 ~58 log 5 
setblock ~5 ~3 ~6 fence 1  
fill ~5 ~3 ~9 ~5 ~4 ~9 stone 0 
setblock ~5 ~3 ~10 cobblestone 0 
setblock ~5 ~3 ~14 log 9  
fill ~5 ~3 ~19 ~15 ~3 ~19 stonebrick 0  
fill ~5 ~3 ~20 ~14 ~3 ~20 stonebrick 0  
fill ~5 ~3 ~21 ~14 ~3 ~21 stonebrick 0  
fill ~5 ~3 ~44 ~14 ~3 ~44 stonebrick 0  
fill ~5 ~3 ~45 ~14 ~3 ~45 stonebrick 0  
fill ~5 ~3 ~46 ~15 ~3 ~46 stonebrick 0 
setblock ~5 ~3 ~51 log 9  
fill ~5 ~3 ~56 ~5 ~4 ~56 stone 0 
setblock ~5 ~3 ~59 fence 1 
setblock ~6 ~3 ~5 log 5 
setblock ~6 ~3 ~6 stonebrick 0 
setblock ~6 ~3 ~7 stone 0  
fill ~6 ~3 ~8 ~6 ~3 ~9 bookshelf 0 
setblock ~6 ~3 ~13 cobblestone 0  
fill ~6 ~3 ~14 ~6 ~4 ~14 stonebrick 0 
setblock ~6 ~3 ~15 fence 1  
fill ~6 ~3 ~18 ~14 ~3 ~18 stonebrick 0  
fill ~6 ~3 ~22 ~14 ~3 ~22 stonebrick 0  
fill ~6 ~3 ~43 ~14 ~3 ~43 stonebrick 0  
fill ~6 ~3 ~47 ~14 ~3 ~47 stonebrick 0 
setblock ~6 ~3 ~50 fence 1  
fill ~6 ~3 ~51 ~6 ~4 ~51 stonebrick 0 
setblock ~6 ~3 ~52 cobblestone 0  
fill ~6 ~3 ~56 ~6 ~3 ~57 bookshelf 0 
setblock ~6 ~3 ~59 stonebrick 0 
setblock ~6 ~3 ~60 log 5 
setblock ~7 ~3 ~4 fence 1 
setblock ~7 ~3 ~14 cobblestone 0 
setblock ~7 ~3 ~16 log 9 
setblock ~7 ~3 ~49 log 9 
setblock ~7 ~3 ~51 cobblestone 0 
setblock ~7 ~3 ~61 fence 1 
setblock ~8 ~3 ~3 stone_brick_stairs 2  
fill ~8 ~3 ~4 ~9 ~3 ~4 cobblestone 0  
fill ~8 ~3 ~5 ~9 ~3 ~5 cobblestone 0  
fill ~8 ~3 ~16 ~8 ~3 ~25 stonebrick 0  
fill ~8 ~3 ~40 ~14 ~3 ~40 stonebrick 0  
fill ~8 ~3 ~41 ~14 ~3 ~41 stonebrick 0  
fill ~8 ~3 ~42 ~14 ~3 ~42 stonebrick 0  
fill ~8 ~3 ~48 ~15 ~3 ~48 stonebrick 0  
fill ~8 ~3 ~49 ~8 ~4 ~49 stone 0  
fill ~8 ~3 ~60 ~9 ~3 ~60 cobblestone 0  
fill ~8 ~3 ~61 ~9 ~3 ~61 cobblestone 0 
setblock ~8 ~3 ~62 stone_brick_stairs 3 
setblock ~9 ~3 ~9 stone_slab 13 
setblock ~9 ~3 ~10 stone_slab 5  
fill ~9 ~3 ~15 ~10 ~3 ~15 stonebrick 0 
setblock ~9 ~3 ~16 stone 0  
fill ~9 ~3 ~17 ~15 ~3 ~17 stonebrick 0  
fill ~9 ~3 ~23 ~14 ~3 ~23 stonebrick 0  
fill ~9 ~3 ~24 ~14 ~3 ~24 stonebrick 0  
fill ~9 ~3 ~25 ~14 ~3 ~25 stonebrick 0  
fill ~9 ~3 ~49 ~9 ~7 ~49 stonebrick 0  
fill ~9 ~3 ~50 ~10 ~3 ~50 stonebrick 0 
setblock ~9 ~3 ~55 stone_slab 5 
setblock ~9 ~3 ~56 stone_slab 13 
setblock ~10 ~3 ~4 stone 0  
fill ~10 ~3 ~5 ~11 ~3 ~5 stonebrick 0  
fill ~10 ~3 ~10 ~10 ~4 ~10 cobblestone 0  
fill ~10 ~3 ~26 ~14 ~3 ~26 stonebrick 0  
fill ~10 ~3 ~39 ~14 ~3 ~39 stonebrick 0  
fill ~10 ~3 ~49 ~10 ~5 ~49 stone 0  
fill ~10 ~3 ~55 ~10 ~4 ~55 cobblestone 0  
fill ~10 ~3 ~60 ~11 ~3 ~60 stonebrick 0 
setblock ~10 ~3 ~61 stone 0  
fill ~11 ~3 ~6 ~12 ~3 ~6 chest 3  
fill ~11 ~3 ~15 ~11 ~3 ~16 stone 0  
fill ~11 ~3 ~27 ~14 ~3 ~27 stonebrick 0  
fill ~11 ~3 ~28 ~14 ~3 ~28 stonebrick 0  
fill ~11 ~3 ~29 ~14 ~3 ~29 stonebrick 0  
fill ~11 ~3 ~30 ~14 ~3 ~30 stonebrick 0  
fill ~11 ~3 ~31 ~14 ~3 ~31 stonebrick 0  
fill ~11 ~3 ~32 ~14 ~3 ~32 stonebrick 0  
fill ~11 ~3 ~33 ~14 ~3 ~33 stonebrick 0  
fill ~11 ~3 ~34 ~14 ~3 ~34 stonebrick 0  
fill ~11 ~3 ~35 ~14 ~3 ~35 stonebrick 0  
fill ~11 ~3 ~36 ~14 ~3 ~36 stonebrick 0  
fill ~11 ~3 ~37 ~14 ~3 ~37 stonebrick 0  
fill ~11 ~3 ~38 ~14 ~3 ~38 stonebrick 0  
fill ~11 ~3 ~49 ~11 ~5 ~49 stonebrick 0 
setblock ~11 ~3 ~50 stone 0  
fill ~11 ~3 ~59 ~12 ~3 ~59 chest 2 
setblock ~12 ~3 ~3 stone_brick_stairs 2 
setblock ~12 ~3 ~4 stonebrick 0  
fill ~12 ~3 ~5 ~12 ~4 ~5 cobblestone 0  
fill ~12 ~3 ~16 ~14 ~3 ~16 stonebrick 0 
setblock ~12 ~3 ~49 stone 0 
setblock ~12 ~3 ~50 stonebrick 0  
fill ~12 ~3 ~60 ~12 ~4 ~60 cobblestone 0 
setblock ~12 ~3 ~61 stonebrick 0 
setblock ~12 ~3 ~62 stone_brick_stairs 3 
setblock ~13 ~3 ~4 log 9 
setblock ~13 ~3 ~6 stonebrick 0  
fill ~13 ~3 ~14 ~13 ~4 ~14 stonebrick 0  
fill ~13 ~3 ~51 ~13 ~4 ~51 stonebrick 0 
setblock ~13 ~3 ~59 stonebrick 0 
setblock ~13 ~3 ~61 log 9 
setblock ~14 ~3 ~5 fence 1 
setblock ~14 ~3 ~6 stone 0  
fill ~14 ~3 ~13 ~51 ~3 ~13 stonebrick 0 
setblock ~14 ~3 ~14 stone 0 
setblock ~14 ~3 ~51 stone 0  
fill ~14 ~3 ~52 ~15 ~3 ~52 stonebrick 0 
setblock ~14 ~3 ~59 stone 0 
setblock ~14 ~3 ~60 fence 1 
setblock ~15 ~3 ~6 log 9  
fill ~15 ~3 ~10 ~16 ~3 ~10 cobblestone 0  
fill ~15 ~3 ~11 ~16 ~3 ~11 cobblestone 0  
fill ~15 ~3 ~12 ~15 ~3 ~10 cobblestone 0 
setblock ~15 ~3 ~20 stone_brick_stairs 5  
fill ~15 ~3 ~22 ~15 ~3 ~24 stone_brick_stairs 5 
setblock ~15 ~3 ~26 stone_brick_stairs 5 
setblock ~15 ~3 ~28 stone_brick_stairs 5  
fill ~15 ~3 ~31 ~15 ~3 ~34 stone_brick_stairs 5 
setblock ~15 ~3 ~37 stone_brick_stairs 5 
setblock ~15 ~3 ~39 stone_brick_stairs 5  
fill ~15 ~3 ~41 ~15 ~3 ~43 stone_brick_stairs 5 
setblock ~15 ~3 ~45 stone_brick_stairs 5  
fill ~15 ~3 ~53 ~17 ~3 ~53 stonebrick 0  
fill ~15 ~3 ~54 ~15 ~3 ~55 cobblestone 0  
fill ~15 ~3 ~56 ~15 ~1 ~56 stone 0 
setblock ~15 ~3 ~59 log 9 
setblock ~16 ~3 ~7 fence 1 
setblock ~16 ~3 ~8 stone 0 
setblock ~16 ~3 ~9 cobblestone 0 
setblock ~16 ~3 ~16 log 5 
setblock ~16 ~3 ~17 stone_brick_stairs 5 
setblock ~16 ~3 ~19 stone_brick_stairs 5 
setblock ~16 ~3 ~30 log 5 
setblock ~16 ~3 ~35 log 5 
setblock ~16 ~3 ~46 stone_brick_stairs 5 
setblock ~16 ~3 ~48 stone_brick_stairs 5 
setblock ~16 ~3 ~49 log 5 
setblock ~16 ~3 ~52 stone_brick_stairs 2  
fill ~16 ~3 ~54 ~26 ~3 ~54 stonebrick 0  
fill ~16 ~3 ~55 ~16 ~3 ~56 cobblestone 0 
setblock ~16 ~3 ~57 stone 0 
setblock ~16 ~3 ~58 fence 1  
fill ~17 ~3 ~8 ~25 ~3 ~8 stonebrick 0  
fill ~17 ~3 ~9 ~25 ~3 ~9 stonebrick 0  
fill ~17 ~3 ~10 ~26 ~3 ~10 stonebrick 0  
fill ~17 ~3 ~11 ~48 ~3 ~11 stonebrick 0  
fill ~17 ~3 ~12 ~50 ~3 ~12 stonebrick 0  
fill ~17 ~3 ~55 ~26 ~3 ~55 stonebrick 0  
fill ~17 ~3 ~56 ~25 ~3 ~56 stonebrick 0  
fill ~17 ~3 ~57 ~25 ~3 ~57 stonebrick 0  
fill ~18 ~3 ~6 ~22 ~3 ~6 stonebrick 0  
fill ~18 ~3 ~7 ~22 ~3 ~7 stonebrick 0  
fill ~18 ~3 ~58 ~22 ~3 ~58 stonebrick 0  
fill ~18 ~3 ~59 ~22 ~3 ~59 stonebrick 0  
fill ~19 ~3 ~5 ~21 ~3 ~5 stonebrick 0  
fill ~19 ~3 ~60 ~21 ~3 ~60 stonebrick 0  
fill ~21 ~3 ~53 ~26 ~3 ~53 stonebrick 0 
setblock ~22 ~3 ~14 log 5 
setblock ~22 ~3 ~20 log 5 
setblock ~22 ~3 ~32 log 5 
setblock ~22 ~3 ~38 log 5  
fill ~22 ~3 ~52 ~22 ~5 ~52 stonebrick 0  
fill ~23 ~3 ~39 ~26 ~3 ~39 stonebrick 0  
fill ~23 ~3 ~42 ~26 ~3 ~42 stonebrick 0  
fill ~24 ~3 ~16 ~24 ~24 ~16 stonebrick 0  
fill ~24 ~3 ~18 ~24 ~26 ~18 stonebrick 0  
fill ~24 ~3 ~19 ~27 ~3 ~19 stonebrick 0  
fill ~24 ~3 ~34 ~24 ~14 ~34 stonebrick 0  
fill ~24 ~3 ~36 ~24 ~14 ~36 stonebrick 0  
fill ~24 ~3 ~52 ~24 ~19 ~52 stonebrick 0  
fill ~25 ~3 ~38 ~26 ~3 ~38 log 1  
fill ~25 ~3 ~43 ~25 ~14 ~43 stonebrick 0  
fill ~25 ~3 ~45 ~25 ~14 ~45 stonebrick 0 
setblock ~25 ~3 ~47 stone_brick_stairs 0 
setblock ~25 ~3 ~50 stone_brick_stairs 0 
setblock ~26 ~3 ~20 log 5 
setblock ~26 ~3 ~32 log 5  
fill ~27 ~3 ~38 ~29 ~3 ~38 stonebrick 0 
setblock ~28 ~3 ~37 chest 2  
fill ~30 ~3 ~14 ~30 ~5 ~14 stonebrick 0  
fill ~30 ~3 ~37 ~35 ~3 ~37 stonebrick 0  
fill ~32 ~3 ~38 ~33 ~3 ~38 stonebrick 0  
fill ~32 ~3 ~39 ~33 ~3 ~39 stone_brick_stairs 3  
fill ~35 ~3 ~14 ~35 ~5 ~14 stonebrick 0  
fill ~36 ~3 ~38 ~38 ~3 ~38 stonebrick 0  
fill ~38 ~3 ~19 ~41 ~3 ~19 stonebrick 0  
fill ~39 ~3 ~10 ~48 ~3 ~10 stonebrick 0 
setblock ~39 ~3 ~20 log 5 
setblock ~39 ~3 ~32 log 5  
fill ~39 ~3 ~38 ~40 ~3 ~38 log 1  
fill ~39 ~3 ~39 ~42 ~3 ~39 stonebrick 0  
fill ~39 ~3 ~42 ~42 ~3 ~42 stonebrick 0  
fill ~39 ~3 ~53 ~44 ~3 ~53 stonebrick 0  
fill ~39 ~3 ~54 ~45 ~3 ~54 stonebrick 0  
fill ~39 ~3 ~55 ~48 ~3 ~55 stonebrick 0  
fill ~40 ~3 ~8 ~49 ~3 ~8 stonebrick 0  
fill ~40 ~3 ~9 ~48 ~3 ~9 stonebrick 0  
fill ~40 ~3 ~43 ~40 ~14 ~43 stonebrick 0  
fill ~40 ~3 ~45 ~40 ~14 ~45 stonebrick 0 
setblock ~40 ~3 ~47 stone_brick_stairs 1 
setblock ~40 ~3 ~50 stone_brick_stairs 1  
fill ~40 ~3 ~56 ~48 ~3 ~56 stonebrick 0  
fill ~40 ~3 ~57 ~49 ~3 ~57 stonebrick 0  
fill ~41 ~3 ~16 ~41 ~14 ~16 stonebrick 0  
fill ~41 ~3 ~18 ~41 ~14 ~18 stonebrick 0  
fill ~41 ~3 ~34 ~41 ~14 ~34 stonebrick 0  
fill ~41 ~3 ~36 ~41 ~14 ~36 stonebrick 0  
fill ~41 ~3 ~52 ~41 ~20 ~52 stonebrick 0  
fill ~43 ~3 ~6 ~47 ~3 ~6 stonebrick 0  
fill ~43 ~3 ~7 ~47 ~3 ~7 stonebrick 0 
setblock ~43 ~3 ~14 log 5 
setblock ~43 ~3 ~20 log 5 
setblock ~43 ~3 ~32 log 5 
setblock ~43 ~3 ~38 log 5  
fill ~43 ~3 ~52 ~43 ~5 ~52 stonebrick 0  
fill ~43 ~3 ~58 ~47 ~3 ~58 stonebrick 0  
fill ~43 ~3 ~59 ~47 ~3 ~59 stonebrick 0  
fill ~44 ~3 ~5 ~46 ~3 ~5 stonebrick 0  
fill ~44 ~3 ~60 ~46 ~3 ~60 stonebrick 0 
setblock ~46 ~3 ~54 stone_brick_stairs 2  
fill ~47 ~3 ~54 ~48 ~3 ~54 stonebrick 0  
fill ~48 ~3 ~53 ~50 ~3 ~53 stonebrick 0 
setblock ~49 ~3 ~7 log 5 
setblock ~49 ~3 ~9 stone 0 
setblock ~49 ~3 ~11 stone 0 
setblock ~49 ~3 ~16 log 5 
setblock ~49 ~3 ~17 stone_brick_stairs 4 
setblock ~49 ~3 ~19 stone_brick_stairs 4 
setblock ~49 ~3 ~30 log 5 
setblock ~49 ~3 ~35 log 5 
setblock ~49 ~3 ~46 stone_brick_stairs 4 
setblock ~49 ~3 ~48 stone_brick_stairs 4 
setblock ~49 ~3 ~49 log 5 
setblock ~49 ~3 ~52 stone_brick_stairs 2 
setblock ~49 ~3 ~54 stone 0 
setblock ~49 ~3 ~56 stone 0 
setblock ~49 ~3 ~58 log 5 
setblock ~50 ~3 ~6 fence 1  
fill ~50 ~3 ~8 ~50 ~6 ~8 cobblestone 0  
fill ~50 ~3 ~9 ~50 ~3 ~10 cobblestone 0  
fill ~50 ~3 ~17 ~57 ~3 ~17 stonebrick 0  
fill ~50 ~3 ~19 ~60 ~3 ~19 stonebrick 0 
setblock ~50 ~3 ~20 stone_brick_stairs 4  
fill ~50 ~3 ~22 ~50 ~3 ~24 stone_brick_stairs 4 
setblock ~50 ~3 ~26 stone_brick_stairs 4 
setblock ~50 ~3 ~28 stone_brick_stairs 4  
fill ~50 ~3 ~31 ~50 ~3 ~34 stone_brick_stairs 4 
setblock ~50 ~3 ~37 stone_brick_stairs 4 
setblock ~50 ~3 ~39 stone_brick_stairs 4  
fill ~50 ~3 ~41 ~50 ~3 ~43 stone_brick_stairs 4 
setblock ~50 ~3 ~45 stone_brick_stairs 4  
fill ~50 ~3 ~46 ~60 ~3 ~46 stonebrick 0  
fill ~50 ~3 ~52 ~51 ~3 ~52 stonebrick 0  
fill ~50 ~3 ~55 ~50 ~4 ~55 cobblestone 0  
fill ~50 ~3 ~56 ~50 ~3 ~57 cobblestone 0 
setblock ~50 ~3 ~59 fence 1 
setblock ~51 ~3 ~5 log 5  
fill ~51 ~3 ~6 ~51 ~4 ~6 stonebrick 0  
fill ~51 ~3 ~7 ~51 ~4 ~7 stonebrick 0  
fill ~51 ~3 ~8 ~51 ~3 ~9 bookshelf 0 
setblock ~51 ~3 ~14 stone 0  
fill ~51 ~3 ~15 ~53 ~3 ~15 stonebrick 0  
fill ~51 ~3 ~16 ~53 ~3 ~16 stonebrick 0  
fill ~51 ~3 ~18 ~59 ~3 ~18 stonebrick 0  
fill ~51 ~3 ~20 ~60 ~3 ~20 stonebrick 0  
fill ~51 ~3 ~21 ~60 ~3 ~21 stonebrick 0  
fill ~51 ~3 ~22 ~59 ~3 ~22 stonebrick 0  
fill ~51 ~3 ~23 ~57 ~3 ~23 stonebrick 0  
fill ~51 ~3 ~24 ~57 ~3 ~24 stonebrick 0  
fill ~51 ~3 ~25 ~57 ~3 ~25 stonebrick 0  
fill ~51 ~3 ~26 ~55 ~3 ~26 stonebrick 0  
fill ~51 ~3 ~27 ~54 ~3 ~27 stonebrick 0  
fill ~51 ~3 ~28 ~54 ~3 ~28 stonebrick 0  
fill ~51 ~3 ~29 ~54 ~3 ~29 stonebrick 0  
fill ~51 ~3 ~30 ~54 ~3 ~30 stonebrick 0  
fill ~51 ~3 ~31 ~54 ~3 ~31 stonebrick 0  
fill ~51 ~3 ~32 ~54 ~3 ~32 stonebrick 0  
fill ~51 ~3 ~33 ~54 ~3 ~33 stonebrick 0  
fill ~51 ~3 ~34 ~54 ~3 ~34 stonebrick 0  
fill ~51 ~3 ~35 ~54 ~3 ~35 stonebrick 0  
fill ~51 ~3 ~36 ~54 ~3 ~36 stonebrick 0  
fill ~51 ~3 ~37 ~54 ~3 ~37 stonebrick 0  
fill ~51 ~3 ~38 ~54 ~3 ~38 stonebrick 0  
fill ~51 ~3 ~40 ~57 ~3 ~40 stonebrick 0  
fill ~51 ~3 ~41 ~57 ~3 ~41 stonebrick 0  
fill ~51 ~3 ~42 ~57 ~3 ~42 stonebrick 0  
fill ~51 ~3 ~43 ~59 ~3 ~43 stonebrick 0  
fill ~51 ~3 ~44 ~60 ~3 ~44 stonebrick 0  
fill ~51 ~3 ~45 ~60 ~3 ~45 stonebrick 0  
fill ~51 ~3 ~47 ~59 ~3 ~47 stonebrick 0  
fill ~51 ~3 ~49 ~53 ~3 ~49 stonebrick 0 
setblock ~51 ~3 ~51 stone 0  
fill ~51 ~3 ~56 ~51 ~3 ~57 bookshelf 0  
fill ~51 ~3 ~58 ~51 ~4 ~58 stonebrick 0  
fill ~51 ~3 ~59 ~51 ~4 ~59 stonebrick 0 
setblock ~51 ~3 ~60 log 5 
setblock ~52 ~3 ~4 fence 1 
setblock ~52 ~3 ~6 stone 0  
fill ~52 ~3 ~14 ~52 ~4 ~14 stonebrick 0  
fill ~52 ~3 ~39 ~55 ~3 ~39 stonebrick 0  
fill ~52 ~3 ~51 ~52 ~4 ~51 stonebrick 0 
setblock ~52 ~3 ~61 fence 1 
setblock ~53 ~3 ~3 stone_brick_stairs 6  
fill ~53 ~3 ~4 ~54 ~3 ~4 stone 0  
fill ~53 ~3 ~48 ~57 ~3 ~48 stonebrick 0 
setblock ~53 ~3 ~62 stone_brick_stairs 3  
fill ~54 ~3 ~5 ~55 ~3 ~5 stonebrick 0 
setblock ~54 ~3 ~9 stone_slab 13 
setblock ~54 ~3 ~10 stone_slab 5 
setblock ~54 ~3 ~49 stone 0 
setblock ~54 ~3 ~55 stone_slab 5 
setblock ~54 ~3 ~56 stone_slab 13  
fill ~54 ~3 ~60 ~55 ~3 ~60 stonebrick 0 
setblock ~54 ~3 ~61 stone 0 
setblock ~55 ~3 ~4 stonebrick 0 
setblock ~55 ~3 ~10 stonebrick 0  
fill ~55 ~3 ~16 ~55 ~5 ~16 stonebrick 0 
setblock ~55 ~3 ~55 stonebrick 0 
setblock ~55 ~3 ~61 stonebrick 0 
setblock ~56 ~3 ~4 stone 0 
setblock ~56 ~3 ~5 cobblestone 0  
fill ~56 ~3 ~6 ~57 ~3 ~6 chest 3  
fill ~56 ~3 ~15 ~57 ~3 ~15 stone 0  
fill ~56 ~3 ~49 ~56 ~3 ~50 stone 0  
fill ~56 ~3 ~59 ~57 ~3 ~59 chest 2 
setblock ~56 ~3 ~60 cobblestone 0 
setblock ~57 ~3 ~3 stone_brick_stairs 6 
setblock ~57 ~3 ~4 cobblestone 0 
setblock ~57 ~3 ~5 stone 0 
setblock ~57 ~3 ~49 stonebrick 0 
setblock ~57 ~3 ~50 stone 0 
setblock ~57 ~3 ~60 stone 0 
setblock ~57 ~3 ~62 stone_brick_stairs 3 
setblock ~58 ~3 ~4 log 9 
setblock ~58 ~3 ~6 cobblestone 0 
setblock ~58 ~3 ~16 fence 1 
setblock ~58 ~3 ~49 log 9 
setblock ~58 ~3 ~59 cobblestone 0 
setblock ~58 ~3 ~61 log 9 
setblock ~59 ~3 ~5 fence 1 
setblock ~59 ~3 ~6 stonebrick 0  
fill ~59 ~3 ~7 ~59 ~4 ~7 cobblestone 0 
setblock ~59 ~3 ~14 cobblestone 0 
setblock ~59 ~3 ~15 log 5 
setblock ~59 ~3 ~50 log 5 
setblock ~59 ~3 ~51 cobblestone 0  
fill ~59 ~3 ~58 ~59 ~4 ~58 cobblestone 0 
setblock ~59 ~3 ~59 stonebrick 0 
setblock ~59 ~3 ~60 fence 1 
setblock ~60 ~3 ~6 log 9  
fill ~60 ~3 ~8 ~61 ~3 ~8 stonebrick 0  
fill ~60 ~3 ~9 ~60 ~4 ~9 stonebrick 0  
fill ~60 ~3 ~10 ~60 ~3 ~12 cobblestone 0 
setblock ~60 ~3 ~14 fence 1 
setblock ~60 ~3 ~51 fence 1 
setblock ~60 ~3 ~54 cobblestone 0  
fill ~60 ~3 ~56 ~60 ~4 ~56 stonebrick 0  
fill ~60 ~3 ~57 ~61 ~3 ~57 stonebrick 0 
setblock ~60 ~3 ~59 log 9 
setblock ~61 ~3 ~7 fence 1 
setblock ~61 ~3 ~9 cobblestone 0 
setblock ~61 ~3 ~12 stone 0 
setblock ~61 ~3 ~13 log 5 
setblock ~61 ~3 ~52 log 5 
setblock ~61 ~3 ~53 stone 0 
setblock ~61 ~3 ~56 cobblestone 0 
setblock ~61 ~3 ~58 fence 1 
setblock ~62 ~3 ~8 stone_brick_stairs 5 
setblock ~62 ~3 ~12 stone_brick_stairs 5 
setblock ~62 ~3 ~53 stone_brick_stairs 5 
setblock ~62 ~3 ~57 stone_brick_stairs 5  
fill ~2 ~4 ~9 ~3 ~4 ~9 stone_slab 13  
fill ~2 ~4 ~11 ~3 ~4 ~11 stone_slab 13  
fill ~2 ~4 ~54 ~3 ~4 ~54 stone_slab 13  
fill ~2 ~4 ~56 ~3 ~4 ~56 stone_slab 13 
setblock ~3 ~4 ~8 stonebrick 0 
setblock ~3 ~4 ~10 stone_slab 13 
setblock ~3 ~4 ~12 stonebrick 0 
setblock ~3 ~4 ~53 stonebrick 0 
setblock ~3 ~4 ~55 stone_slab 13 
setblock ~3 ~4 ~57 stonebrick 0 
setblock ~4 ~4 ~7 fence 1  
fill ~4 ~4 ~8 ~5 ~4 ~8 stone 0  
fill ~4 ~4 ~9 ~4 ~5 ~9 stonebrick 0  
fill ~4 ~4 ~10 ~4 ~4 ~9 stonebrick 0  
fill ~4 ~4 ~11 ~4 ~3 ~11 stone 0 
setblock ~4 ~4 ~12 cobblestone 0 
setblock ~4 ~4 ~13 log 5 
setblock ~4 ~4 ~52 log 5 
setblock ~4 ~4 ~53 cobblestone 0 
setblock ~4 ~4 ~54 stone 0  
fill ~4 ~4 ~55 ~4 ~4 ~56 stonebrick 0  
fill ~4 ~4 ~57 ~5 ~4 ~57 stone 0 
setblock ~4 ~4 ~58 fence 1 
setblock ~5 ~4 ~6 log 9 
setblock ~5 ~4 ~10 stone 0  
fill ~5 ~4 ~11 ~5 ~6 ~11 cobblestone 0 
setblock ~5 ~4 ~12 stonebrick 0 
setblock ~5 ~4 ~14 fence 1  
fill ~5 ~4 ~19 ~14 ~4 ~19 stonebrick 0  
fill ~5 ~4 ~20 ~14 ~4 ~20 stonebrick 0  
fill ~5 ~4 ~21 ~14 ~4 ~21 stonebrick 0  
fill ~5 ~4 ~44 ~14 ~4 ~44 stonebrick 0  
fill ~5 ~4 ~45 ~14 ~4 ~45 stonebrick 0  
fill ~5 ~4 ~46 ~14 ~4 ~46 stonebrick 0 
setblock ~5 ~4 ~51 fence 1 
setblock ~5 ~4 ~53 stonebrick 0  
fill ~5 ~4 ~54 ~5 ~6 ~54 cobblestone 0 
setblock ~5 ~4 ~55 stone 0 
setblock ~5 ~4 ~59 log 9 
setblock ~6 ~4 ~5 fence 1  
fill ~6 ~4 ~6 ~7 ~4 ~6 cobblestone 0  
fill ~6 ~4 ~7 ~6 ~4 ~6 cobblestone 0 
setblock ~6 ~4 ~8 planks 1  
fill ~6 ~4 ~9 ~6 ~4 ~11 dropper 9 
setblock ~6 ~4 ~12 planks 1 
setblock ~6 ~4 ~13 stone 0 
setblock ~6 ~4 ~15 log 5  
fill ~6 ~4 ~18 ~14 ~4 ~18 stonebrick 0  
fill ~6 ~4 ~22 ~13 ~4 ~22 stonebrick 0  
fill ~6 ~4 ~43 ~13 ~4 ~43 stonebrick 0  
fill ~6 ~4 ~47 ~14 ~4 ~47 stonebrick 0 
setblock ~6 ~4 ~50 log 5 
setblock ~6 ~4 ~52 stone 0 
setblock ~6 ~4 ~53 planks 1  
fill ~6 ~4 ~54 ~6 ~4 ~56 dropper 9 
setblock ~6 ~4 ~57 planks 1  
fill ~6 ~4 ~58 ~6 ~4 ~59 cobblestone 0 
setblock ~6 ~4 ~60 fence 1 
setblock ~7 ~4 ~4 log 9 
setblock ~7 ~4 ~7 planks 1 
setblock ~7 ~4 ~8 dropper 9 
setblock ~7 ~4 ~12 dropper 9 
setblock ~7 ~4 ~13 planks 1 
setblock ~7 ~4 ~14 stonebrick 0 
setblock ~7 ~4 ~16 fence 1 
setblock ~7 ~4 ~49 fence 1 
setblock ~7 ~4 ~51 stonebrick 0 
setblock ~7 ~4 ~52 planks 1 
setblock ~7 ~4 ~53 dropper 9 
setblock ~7 ~4 ~57 dropper 9 
setblock ~7 ~4 ~58 planks 1 
setblock ~7 ~4 ~59 cobblestone 0 
setblock ~7 ~4 ~61 log 9 
setblock ~8 ~4 ~3 cobblestone 0  
fill ~8 ~4 ~4 ~10 ~4 ~4 stonebrick 0  
fill ~8 ~4 ~5 ~10 ~4 ~5 stonebrick 0 
setblock ~8 ~4 ~6 planks 1 
setblock ~8 ~4 ~7 dropper 9 
setblock ~8 ~4 ~13 dropper 9 
setblock ~8 ~4 ~14 planks 1  
fill ~8 ~4 ~15 ~8 ~5 ~15 cobblestone 0 
setblock ~8 ~4 ~16 stone 0  
fill ~8 ~4 ~17 ~11 ~4 ~17 stonebrick 0  
fill ~8 ~4 ~23 ~13 ~4 ~23 stonebrick 0  
fill ~8 ~4 ~24 ~13 ~4 ~24 stonebrick 0  
fill ~8 ~4 ~25 ~14 ~4 ~25 stonebrick 0  
fill ~8 ~4 ~40 ~14 ~4 ~40 stonebrick 0  
fill ~8 ~4 ~41 ~13 ~4 ~41 stonebrick 0  
fill ~8 ~4 ~42 ~13 ~4 ~42 stonebrick 0  
fill ~8 ~4 ~48 ~11 ~4 ~48 stonebrick 0  
fill ~8 ~4 ~50 ~8 ~5 ~50 cobblestone 0 
setblock ~8 ~4 ~51 planks 1 
setblock ~8 ~4 ~52 dropper 9 
setblock ~8 ~4 ~58 dropper 9 
setblock ~8 ~4 ~59 planks 1  
fill ~8 ~4 ~60 ~10 ~4 ~60 stonebrick 0  
fill ~8 ~4 ~61 ~10 ~4 ~61 stonebrick 0 
setblock ~8 ~4 ~62 cobblestone 0  
fill ~9 ~4 ~2 ~9 ~4 ~3 stone_slab 13  
fill ~9 ~4 ~6 ~11 ~4 ~6 dropper 9  
fill ~9 ~4 ~14 ~11 ~4 ~14 dropper 9  
fill ~9 ~4 ~15 ~10 ~4 ~15 stonebrick 0  
fill ~9 ~4 ~16 ~10 ~4 ~16 stonebrick 0  
fill ~9 ~4 ~50 ~10 ~4 ~50 stonebrick 0  
fill ~9 ~4 ~51 ~11 ~4 ~51 dropper 9  
fill ~9 ~4 ~59 ~11 ~4 ~59 dropper 9  
fill ~9 ~4 ~62 ~11 ~4 ~62 stone_slab 13  
fill ~9 ~4 ~63 ~9 ~4 ~62 stone_slab 13  
fill ~10 ~4 ~3 ~11 ~4 ~3 stone_slab 13 
setblock ~10 ~4 ~9 stone_slab 5  
fill ~10 ~4 ~26 ~14 ~4 ~26 stonebrick 0  
fill ~10 ~4 ~39 ~14 ~4 ~39 stonebrick 0 
setblock ~10 ~4 ~56 stone_slab 5 
setblock ~11 ~4 ~2 stone_slab 13  
fill ~11 ~4 ~4 ~12 ~4 ~4 cobblestone 0 
setblock ~11 ~4 ~5 stone 0 
setblock ~11 ~4 ~9 stone_slab 13  
fill ~11 ~4 ~15 ~11 ~4 ~16 cobblestone 0  
fill ~11 ~4 ~27 ~14 ~4 ~27 stonebrick 0  
fill ~11 ~4 ~28 ~14 ~4 ~28 stonebrick 0  
fill ~11 ~4 ~29 ~14 ~4 ~29 stonebrick 0  
fill ~11 ~4 ~30 ~14 ~4 ~30 stonebrick 0  
fill ~11 ~4 ~31 ~14 ~4 ~31 stonebrick 0  
fill ~11 ~4 ~32 ~14 ~4 ~32 stonebrick 0  
fill ~11 ~4 ~33 ~14 ~4 ~33 stonebrick 0  
fill ~11 ~4 ~34 ~14 ~4 ~34 stonebrick 0  
fill ~11 ~4 ~35 ~14 ~4 ~35 stonebrick 0  
fill ~11 ~4 ~36 ~14 ~4 ~36 stonebrick 0  
fill ~11 ~4 ~37 ~14 ~4 ~37 stonebrick 0  
fill ~11 ~4 ~38 ~14 ~4 ~38 stonebrick 0 
setblock ~11 ~4 ~50 cobblestone 0 
setblock ~11 ~4 ~56 stone_slab 13 
setblock ~11 ~4 ~60 stone 0  
fill ~11 ~4 ~61 ~12 ~4 ~61 cobblestone 0 
setblock ~11 ~4 ~63 stone_slab 13 
setblock ~12 ~4 ~3 cobblestone 0 
setblock ~12 ~4 ~6 planks 1 
setblock ~12 ~4 ~7 dropper 9 
setblock ~12 ~4 ~13 dropper 9 
setblock ~12 ~4 ~14 planks 1 
setblock ~12 ~4 ~15 stone 0 
setblock ~12 ~4 ~16 cobblestone 0 
setblock ~12 ~4 ~17 stone 0 
setblock ~12 ~4 ~48 cobblestone 0  
fill ~12 ~4 ~49 ~12 ~5 ~49 stonebrick 0 
setblock ~12 ~4 ~50 stone 0 
setblock ~12 ~4 ~51 planks 1 
setblock ~12 ~4 ~52 dropper 9 
setblock ~12 ~4 ~58 dropper 9 
setblock ~12 ~4 ~59 planks 1 
setblock ~12 ~4 ~62 cobblestone 0 
setblock ~13 ~4 ~4 fence 1 
setblock ~13 ~4 ~6 stone 0 
setblock ~13 ~4 ~7 planks 1 
setblock ~13 ~4 ~8 dropper 9 
setblock ~13 ~4 ~12 dropper 9 
setblock ~13 ~4 ~13 planks 1  
fill ~13 ~4 ~16 ~14 ~4 ~16 stonebrick 0  
fill ~13 ~4 ~17 ~14 ~4 ~17 stonebrick 0 
setblock ~13 ~4 ~52 planks 1 
setblock ~13 ~4 ~53 dropper 9 
setblock ~13 ~4 ~57 dropper 9 
setblock ~13 ~4 ~58 planks 1 
setblock ~13 ~4 ~59 stone 0 
setblock ~13 ~4 ~61 fence 1 
setblock ~14 ~4 ~5 log 5 
setblock ~14 ~4 ~6 stonebrick 0  
fill ~14 ~4 ~7 ~14 ~5 ~7 stone 0 
setblock ~14 ~4 ~8 planks 1  
fill ~14 ~4 ~9 ~14 ~4 ~11 dropper 9 
setblock ~14 ~4 ~12 planks 1  
fill ~14 ~4 ~13 ~18 ~4 ~13 stonebrick 0  
fill ~14 ~4 ~14 ~14 ~5 ~14 stonebrick 0  
fill ~14 ~4 ~22 ~14 ~4 ~24 stone_brick_stairs 5  
fill ~14 ~4 ~41 ~14 ~4 ~43 stone_brick_stairs 5  
fill ~14 ~4 ~51 ~14 ~5 ~51 stonebrick 0  
fill ~14 ~4 ~52 ~16 ~4 ~52 stonebrick 0 
setblock ~14 ~4 ~53 planks 1  
fill ~14 ~4 ~54 ~14 ~4 ~56 dropper 9 
setblock ~14 ~4 ~57 planks 1  
fill ~14 ~4 ~58 ~14 ~5 ~58 stone 0 
setblock ~14 ~4 ~59 stonebrick 0 
setblock ~14 ~4 ~60 log 5 
setblock ~15 ~4 ~6 fence 1  
fill ~15 ~4 ~8 ~16 ~4 ~8 cobblestone 0  
fill ~15 ~4 ~9 ~15 ~4 ~10 cobblestone 0  
fill ~15 ~4 ~11 ~15 ~7 ~11 stone 0  
fill ~15 ~4 ~12 ~16 ~4 ~12 stone 0  
fill ~15 ~4 ~14 ~15 ~4 ~15 stone_slab 13 
setblock ~15 ~4 ~17 stone_brick_stairs 1 
setblock ~15 ~4 ~18 anvil 0 
setblock ~15 ~4 ~19 stone_brick_stairs 1 
setblock ~15 ~4 ~31 stone_brick_stairs 1 
setblock ~15 ~4 ~34 stone_brick_stairs 1 
setblock ~15 ~4 ~46 stone_brick_stairs 1 
setblock ~15 ~4 ~47 anvil 0 
setblock ~15 ~4 ~48 stone_brick_stairs 1  
fill ~15 ~4 ~50 ~15 ~4 ~51 stone_slab 13  
fill ~15 ~4 ~53 ~16 ~4 ~53 cobblestone 0  
fill ~15 ~4 ~54 ~15 ~7 ~54 stone 0  
fill ~15 ~4 ~55 ~15 ~4 ~57 cobblestone 0 
setblock ~15 ~4 ~59 fence 1 
setblock ~16 ~4 ~7 log 5  
fill ~16 ~4 ~9 ~16 ~4 ~10 stone 0 
setblock ~16 ~4 ~11 cobblestone 0 
setblock ~16 ~4 ~16 fence 1 
setblock ~16 ~4 ~30 fence 1 
setblock ~16 ~4 ~35 fence 1 
setblock ~16 ~4 ~49 fence 1  
fill ~16 ~4 ~54 ~26 ~4 ~54 stonebrick 0  
fill ~16 ~4 ~55 ~16 ~4 ~56 stone 0  
fill ~16 ~4 ~57 ~16 ~5 ~57 cobblestone 0 
setblock ~16 ~4 ~58 log 5  
fill ~17 ~4 ~8 ~25 ~4 ~8 stonebrick 0  
fill ~17 ~4 ~9 ~25 ~4 ~9 stonebrick 0  
fill ~17 ~4 ~10 ~26 ~4 ~10 stonebrick 0  
fill ~17 ~4 ~11 ~48 ~4 ~11 stonebrick 0 
setblock ~17 ~4 ~12 cobblestone 0 
setblock ~17 ~4 ~53 stone 0  
fill ~17 ~4 ~55 ~26 ~4 ~55 stonebrick 0  
fill ~17 ~4 ~56 ~25 ~4 ~56 stonebrick 0  
fill ~17 ~4 ~57 ~25 ~4 ~57 stonebrick 0  
fill ~18 ~4 ~6 ~22 ~4 ~6 stonebrick 0  
fill ~18 ~4 ~7 ~22 ~4 ~7 stonebrick 0  
fill ~18 ~4 ~12 ~47 ~4 ~12 stonebrick 0  
fill ~18 ~4 ~58 ~22 ~4 ~58 stonebrick 0  
fill ~18 ~4 ~59 ~22 ~4 ~59 stonebrick 0  
fill ~19 ~4 ~5 ~21 ~4 ~5 stonebrick 0 
setblock ~19 ~4 ~13 stone_brick_stairs 0  
fill ~19 ~4 ~60 ~21 ~4 ~60 stonebrick 0  
fill ~20 ~4 ~13 ~45 ~4 ~13 stonebrick 0 
setblock ~21 ~4 ~53 stone_brick_stairs 0 
setblock ~22 ~4 ~14 fence 1 
setblock ~22 ~4 ~20 fence 1 
setblock ~22 ~4 ~32 fence 1 
setblock ~22 ~4 ~38 fence 1  
fill ~22 ~4 ~53 ~26 ~4 ~53 stonebrick 0 
setblock ~23 ~4 ~16 anvil 2 
setblock ~23 ~4 ~18 anvil 2 
setblock ~23 ~4 ~34 anvil 2 
setblock ~23 ~4 ~36 anvil 2  
fill ~23 ~4 ~39 ~26 ~4 ~39 stonebrick 0  
fill ~23 ~4 ~42 ~26 ~4 ~42 stonebrick 0 
setblock ~23 ~4 ~52 stone_brick_stairs 2  
fill ~24 ~4 ~19 ~27 ~4 ~19 stonebrick 0  
fill ~24 ~4 ~40 ~24 ~4 ~41 fence 1 
setblock ~25 ~4 ~15 stone_slab 13 
setblock ~25 ~4 ~16 anvil 2 
setblock ~25 ~4 ~17 stone_slab 13  
fill ~25 ~4 ~38 ~26 ~4 ~38 log 1  
fill ~25 ~4 ~47 ~25 ~14 ~47 stonebrick 0  
fill ~25 ~4 ~50 ~25 ~14 ~50 stonebrick 0 
setblock ~26 ~4 ~20 fence 1 
setblock ~26 ~4 ~32 fence 1  
fill ~27 ~4 ~38 ~29 ~4 ~38 stonebrick 0 
setblock ~28 ~4 ~19 stone_brick_stairs 5  
fill ~30 ~4 ~37 ~35 ~4 ~37 stonebrick 0 
setblock ~31 ~4 ~14 stone_brick_stairs 7  
fill ~32 ~4 ~36 ~33 ~4 ~36 stone_brick_stairs 6  
fill ~32 ~4 ~38 ~33 ~4 ~38 stonebrick 0 
setblock ~34 ~4 ~14 stone_brick_stairs 7  
fill ~36 ~4 ~38 ~38 ~4 ~38 stonebrick 0 
setblock ~37 ~4 ~19 stone_brick_stairs 4  
fill ~38 ~4 ~19 ~41 ~4 ~19 stonebrick 0  
fill ~39 ~4 ~10 ~49 ~4 ~10 stonebrick 0 
setblock ~39 ~4 ~20 fence 1 
setblock ~39 ~4 ~32 fence 1  
fill ~39 ~4 ~38 ~40 ~4 ~38 log 1  
fill ~39 ~4 ~39 ~42 ~4 ~39 stonebrick 0  
fill ~39 ~4 ~42 ~42 ~4 ~42 stonebrick 0  
fill ~39 ~4 ~53 ~43 ~4 ~53 stonebrick 0  
fill ~39 ~4 ~54 ~48 ~4 ~54 stonebrick 0  
fill ~39 ~4 ~55 ~49 ~4 ~55 stonebrick 0  
fill ~40 ~4 ~8 ~48 ~4 ~8 stonebrick 0  
fill ~40 ~4 ~9 ~50 ~4 ~9 stonebrick 0 
setblock ~40 ~4 ~15 stone_slab 13 
setblock ~40 ~4 ~16 anvil 2 
setblock ~40 ~4 ~17 stone_slab 13  
fill ~40 ~4 ~47 ~40 ~14 ~47 stonebrick 0  
fill ~40 ~4 ~50 ~40 ~14 ~50 stonebrick 0  
fill ~40 ~4 ~56 ~50 ~4 ~56 stonebrick 0  
fill ~40 ~4 ~57 ~48 ~4 ~57 stonebrick 0  
fill ~41 ~4 ~40 ~41 ~4 ~41 fence 1 
setblock ~42 ~4 ~16 anvil 2 
setblock ~42 ~4 ~18 anvil 2 
setblock ~42 ~4 ~34 anvil 2 
setblock ~42 ~4 ~36 anvil 2 
setblock ~42 ~4 ~52 stone_brick_stairs 2  
fill ~43 ~4 ~6 ~47 ~4 ~6 stonebrick 0  
fill ~43 ~4 ~7 ~47 ~4 ~7 stonebrick 0 
setblock ~43 ~4 ~14 fence 1 
setblock ~43 ~4 ~20 fence 1 
setblock ~43 ~4 ~32 fence 1 
setblock ~43 ~4 ~38 fence 1  
fill ~43 ~4 ~58 ~47 ~4 ~58 stonebrick 0  
fill ~43 ~4 ~59 ~47 ~4 ~59 stonebrick 0  
fill ~44 ~4 ~5 ~46 ~4 ~5 stonebrick 0 
setblock ~44 ~4 ~53 stone_brick_stairs 1  
fill ~44 ~4 ~60 ~46 ~4 ~60 stonebrick 0 
setblock ~46 ~4 ~13 stone_brick_stairs 1  
fill ~47 ~4 ~13 ~51 ~4 ~13 stonebrick 0 
setblock ~48 ~4 ~12 stone 0 
setblock ~48 ~4 ~53 stone 0 
setblock ~49 ~4 ~7 fence 1 
setblock ~49 ~4 ~8 stone 0  
fill ~49 ~4 ~11 ~50 ~4 ~11 cobblestone 0  
fill ~49 ~4 ~12 ~50 ~4 ~12 cobblestone 0 
setblock ~49 ~4 ~16 fence 1 
setblock ~49 ~4 ~30 fence 1 
setblock ~49 ~4 ~35 fence 1 
setblock ~49 ~4 ~49 fence 1  
fill ~49 ~4 ~52 ~51 ~4 ~52 stonebrick 0  
fill ~49 ~4 ~53 ~50 ~4 ~53 cobblestone 0  
fill ~49 ~4 ~54 ~50 ~4 ~54 cobblestone 0 
setblock ~49 ~4 ~57 stone 0 
setblock ~49 ~4 ~58 fence 1 
setblock ~50 ~4 ~6 log 9 
setblock ~50 ~4 ~10 cobblestone 0  
fill ~50 ~4 ~14 ~50 ~4 ~15 stone_slab 13 
setblock ~50 ~4 ~17 stone_brick_stairs 0 
setblock ~50 ~4 ~18 anvil 0 
setblock ~50 ~4 ~19 stone_brick_stairs 0 
setblock ~50 ~4 ~31 stone_brick_stairs 0 
setblock ~50 ~4 ~34 stone_brick_stairs 0 
setblock ~50 ~4 ~46 stone_brick_stairs 0 
setblock ~50 ~4 ~47 anvil 0 
setblock ~50 ~4 ~48 stone_brick_stairs 0  
fill ~50 ~4 ~50 ~50 ~4 ~51 stone_slab 13  
fill ~50 ~4 ~57 ~50 ~6 ~57 cobblestone 0 
setblock ~50 ~4 ~59 log 9 
setblock ~51 ~4 ~5 fence 1 
setblock ~51 ~4 ~8 planks 1  
fill ~51 ~4 ~9 ~51 ~4 ~11 dropper 9 
setblock ~51 ~4 ~12 planks 1  
fill ~51 ~4 ~14 ~51 ~5 ~14 stonebrick 0  
fill ~51 ~4 ~15 ~53 ~4 ~15 stonebrick 0  
fill ~51 ~4 ~16 ~53 ~4 ~16 stonebrick 0  
fill ~51 ~4 ~17 ~52 ~4 ~17 stonebrick 0  
fill ~51 ~4 ~18 ~59 ~4 ~18 stonebrick 0  
fill ~51 ~4 ~19 ~60 ~4 ~19 stonebrick 0  
fill ~51 ~4 ~20 ~60 ~4 ~20 stonebrick 0  
fill ~51 ~4 ~21 ~60 ~4 ~21 stonebrick 0  
fill ~51 ~4 ~22 ~51 ~4 ~24 stone_brick_stairs 4  
fill ~51 ~4 ~25 ~57 ~4 ~25 stonebrick 0  
fill ~51 ~4 ~26 ~55 ~4 ~26 stonebrick 0  
fill ~51 ~4 ~27 ~54 ~4 ~27 stonebrick 0  
fill ~51 ~4 ~28 ~54 ~4 ~28 stonebrick 0  
fill ~51 ~4 ~29 ~54 ~4 ~29 stonebrick 0  
fill ~51 ~4 ~30 ~54 ~4 ~30 stonebrick 0  
fill ~51 ~4 ~31 ~54 ~4 ~31 stonebrick 0  
fill ~51 ~4 ~32 ~54 ~4 ~32 stonebrick 0  
fill ~51 ~4 ~33 ~54 ~4 ~33 stonebrick 0  
fill ~51 ~4 ~34 ~54 ~4 ~34 stonebrick 0  
fill ~51 ~4 ~35 ~54 ~4 ~35 stonebrick 0  
fill ~51 ~4 ~36 ~54 ~4 ~36 stonebrick 0  
fill ~51 ~4 ~37 ~54 ~4 ~37 stonebrick 0  
fill ~51 ~4 ~38 ~54 ~4 ~38 stonebrick 0  
fill ~51 ~4 ~40 ~57 ~4 ~40 stonebrick 0  
fill ~51 ~4 ~41 ~51 ~4 ~43 stone_brick_stairs 4  
fill ~51 ~4 ~44 ~60 ~4 ~44 stonebrick 0  
fill ~51 ~4 ~45 ~60 ~4 ~45 stonebrick 0  
fill ~51 ~4 ~46 ~60 ~4 ~46 stonebrick 0  
fill ~51 ~4 ~47 ~59 ~4 ~47 stonebrick 0  
fill ~51 ~4 ~49 ~52 ~4 ~49 stonebrick 0  
fill ~51 ~4 ~51 ~51 ~5 ~51 stonebrick 0 
setblock ~51 ~4 ~53 planks 1  
fill ~51 ~4 ~54 ~51 ~4 ~56 dropper 9 
setblock ~51 ~4 ~57 planks 1 
setblock ~51 ~4 ~60 fence 1 
setblock ~52 ~4 ~4 log 9  
fill ~52 ~4 ~6 ~52 ~5 ~6 stonebrick 0 
setblock ~52 ~4 ~7 planks 1 
setblock ~52 ~4 ~8 dropper 9 
setblock ~52 ~4 ~12 dropper 9 
setblock ~52 ~4 ~13 planks 1
fill ~52 ~4 ~22 ~59 ~4 ~22 stonebrick 0  
fill ~52 ~4 ~23 ~57 ~4 ~23 stonebrick 0  
fill ~52 ~4 ~24 ~57 ~4 ~24 stonebrick 0  
fill ~52 ~4 ~39 ~55 ~4 ~39 stonebrick 0  
fill ~52 ~4 ~41 ~57 ~4 ~41 stonebrick 0  
fill ~52 ~4 ~42 ~57 ~4 ~42 stonebrick 0  
fill ~52 ~4 ~43 ~59 ~4 ~43 stonebrick 0 
setblock ~52 ~4 ~52 planks 1 
setblock ~52 ~4 ~53 dropper 9 
setblock ~52 ~4 ~57 dropper 9 
setblock ~52 ~4 ~58 planks 1  
fill ~52 ~4 ~59 ~52 ~5 ~59 stonebrick 0 
setblock ~52 ~4 ~61 log 9 
setblock ~53 ~4 ~3 stone 0  
fill ~53 ~4 ~4 ~54 ~4 ~4 cobblestone 0  
fill ~53 ~4 ~5 ~53 ~4 ~4 cobblestone 0 
setblock ~53 ~4 ~6 planks 1 
setblock ~53 ~4 ~7 dropper 9 
setblock ~53 ~4 ~13 dropper 9 
setblock ~53 ~4 ~14 planks 1 
setblock ~53 ~4 ~17 cobblestone 0 
setblock ~53 ~4 ~48 stone 0  
fill ~53 ~4 ~49 ~54 ~4 ~49 cobblestone 0 
setblock ~53 ~4 ~51 planks 1 
setblock ~53 ~4 ~52 dropper 9 
setblock ~53 ~4 ~58 dropper 9 
setblock ~53 ~4 ~59 planks 1  
fill ~53 ~4 ~60 ~53 ~4 ~61 cobblestone 0 
setblock ~53 ~4 ~62 stone 0  
fill ~54 ~4 ~2 ~54 ~4 ~3 stone_slab 13  
fill ~54 ~4 ~5 ~56 ~4 ~5 stone 0  
fill ~54 ~4 ~6 ~56 ~4 ~6 dropper 9  
fill ~54 ~4 ~14 ~56 ~4 ~14 dropper 9  
fill ~54 ~4 ~15 ~54 ~8 ~15 stone 0  
fill ~54 ~4 ~17 ~57 ~4 ~17 stonebrick 0  
fill ~54 ~4 ~48 ~57 ~4 ~48 stonebrick 0  
fill ~54 ~4 ~50 ~54 ~8 ~50 stone 0  
fill ~54 ~4 ~51 ~56 ~4 ~51 dropper 9  
fill ~54 ~4 ~59 ~56 ~4 ~59 dropper 9  
fill ~54 ~4 ~60 ~56 ~4 ~60 stone 0 
setblock ~54 ~4 ~61 cobblestone 0  
fill ~54 ~4 ~62 ~56 ~4 ~62 stone_slab 13  
fill ~54 ~4 ~63 ~54 ~4 ~62 stone_slab 13  
fill ~55 ~4 ~3 ~56 ~4 ~3 stone_slab 13  
fill ~55 ~4 ~4 ~55 ~5 ~4 stone 0 
setblock ~55 ~4 ~9 stone_slab 5  
fill ~55 ~4 ~10 ~55 ~5 ~10 cobblestone 0  
fill ~55 ~4 ~15 ~56 ~4 ~15 cobblestone 0  
fill ~55 ~4 ~49 ~56 ~4 ~49 stonebrick 0  
fill ~55 ~4 ~50 ~56 ~4 ~50 cobblestone 0  
fill ~55 ~4 ~55 ~55 ~5 ~55 cobblestone 0 
setblock ~55 ~4 ~56 stone_slab 5  
fill ~55 ~4 ~61 ~55 ~5 ~61 stone 0 
setblock ~56 ~4 ~2 stone_slab 13 
setblock ~56 ~4 ~4 stonebrick 0 
setblock ~56 ~4 ~9 stone_slab 13 
setblock ~56 ~4 ~16 cobblestone 0 
setblock ~56 ~4 ~56 stone_slab 13 
setblock ~56 ~4 ~61 stonebrick 0 
setblock ~56 ~4 ~63 stone_slab 13  
fill ~57 ~4 ~3 ~57 ~4 ~4 stone 0 
setblock ~57 ~4 ~5 cobblestone 0 
setblock ~57 ~4 ~6 planks 1 
setblock ~57 ~4 ~7 dropper 9 
setblock ~57 ~4 ~13 dropper 9 
setblock ~57 ~4 ~14 planks 1  
fill ~57 ~4 ~15 ~57 ~5 ~15 stonebrick 0  
fill ~57 ~4 ~16 ~57 ~5 ~16 stone 0 
setblock ~57 ~4 ~49 stone 0  
fill ~57 ~4 ~50 ~57 ~5 ~50 stonebrick 0 
setblock ~57 ~4 ~51 planks 1 
setblock ~57 ~4 ~52 dropper 9 
setblock ~57 ~4 ~58 dropper 9 
setblock ~57 ~4 ~59 planks 1 
setblock ~57 ~4 ~60 cobblestone 0  
fill ~57 ~4 ~61 ~57 ~5 ~61 stone 0  
fill ~57 ~4 ~62 ~57 ~4 ~61 stone 0 
setblock ~58 ~4 ~4 fence 1 
setblock ~58 ~4 ~6 stonebrick 0 
setblock ~58 ~4 ~7 planks 1 
setblock ~58 ~4 ~8 dropper 9 
setblock ~58 ~4 ~12 dropper 9 
setblock ~58 ~4 ~13 planks 1  
fill ~58 ~4 ~14 ~59 ~4 ~14 stonebrick 0 
setblock ~58 ~4 ~16 log 9 
setblock ~58 ~4 ~49 fence 1  
fill ~58 ~4 ~51 ~59 ~4 ~51 stonebrick 0 
setblock ~58 ~4 ~52 planks 1 
setblock ~58 ~4 ~53 dropper 9 
setblock ~58 ~4 ~57 dropper 9 
setblock ~58 ~4 ~58 planks 1 
setblock ~58 ~4 ~59 stonebrick 0 
setblock ~58 ~4 ~61 fence 1 
setblock ~59 ~4 ~5 log 5 
setblock ~59 ~4 ~6 cobblestone 0 
setblock ~59 ~4 ~8 planks 1  
fill ~59 ~4 ~9 ~59 ~4 ~11 dropper 9 
setblock ~59 ~4 ~12 planks 1 
setblock ~59 ~4 ~13 stonebrick 0 
setblock ~59 ~4 ~15 fence 1 
setblock ~59 ~4 ~50 fence 1 
setblock ~59 ~4 ~52 stonebrick 0 
setblock ~59 ~4 ~53 planks 1  
fill ~59 ~4 ~54 ~59 ~4 ~56 dropper 9 
setblock ~59 ~4 ~57 planks 1 
setblock ~59 ~4 ~59 cobblestone 0 
setblock ~59 ~4 ~60 log 5 
setblock ~60 ~4 ~6 fence 1  
fill ~60 ~4 ~8 ~60 ~6 ~8 stonebrick 0  
fill ~60 ~4 ~10 ~60 ~4 ~11 stonebrick 0 
setblock ~60 ~4 ~14 log 9 
setblock ~60 ~4 ~51 log 9  
fill ~60 ~4 ~54 ~60 ~7 ~54 stonebrick 0  
fill ~60 ~4 ~55 ~60 ~4 ~54 stonebrick 0  
fill ~60 ~4 ~57 ~60 ~6 ~57 stonebrick 0 
setblock ~60 ~4 ~59 fence 1 
setblock ~61 ~4 ~7 log 5  
fill ~61 ~4 ~8 ~61 ~4 ~9 stone 0  
fill ~61 ~4 ~10 ~61 ~5 ~10 cobblestone 0  
fill ~61 ~4 ~11 ~61 ~5 ~11 cobblestone 0  
fill ~61 ~4 ~12 ~61 ~5 ~12 cobblestone 0 
setblock ~61 ~4 ~13 fence 1 
setblock ~61 ~4 ~52 fence 1  
fill ~61 ~4 ~53 ~61 ~5 ~53 cobblestone 0  
fill ~61 ~4 ~54 ~61 ~5 ~54 cobblestone 0  
fill ~61 ~4 ~55 ~61 ~5 ~55 cobblestone 0  
fill ~61 ~4 ~56 ~61 ~4 ~57 stone 0 
setblock ~61 ~4 ~58 log 5 
setblock ~62 ~4 ~8 cobblestone 0  
fill ~62 ~4 ~9 ~63 ~4 ~9 stone_slab 13  
fill ~62 ~4 ~10 ~62 ~4 ~11 stone_slab 13  
fill ~62 ~4 ~12 ~62 ~5 ~12 stone 0  
fill ~62 ~4 ~53 ~62 ~5 ~53 stone 0  
fill ~62 ~4 ~54 ~63 ~4 ~54 stone_slab 13  
fill ~62 ~4 ~55 ~62 ~4 ~56 stone_slab 13 
setblock ~62 ~4 ~57 cobblestone 0 
