setblock ~8 ~45 ~24 chest 5  
setblock ~8 ~46 ~24 chest 5  
setblock ~8 ~47 ~24 chest 5  
setblock ~2 ~45 ~26 lit_furnace 5  
setblock ~8 ~45 ~25 chest 5  
setblock ~8 ~46 ~25 chest 5  
setblock ~8 ~47 ~25 chest 5  
fill ~17 ~0 ~21 ~17 ~6 ~21 stone 0  
fill ~18 ~0 ~20 ~19 ~0 ~20 stone 0  
fill ~18 ~0 ~23 ~18 ~10 ~23 stone 0  
fill ~17 ~1 ~22 ~19 ~1 ~22 stone 0  
fill ~18 ~1 ~20 ~18 ~7 ~20 stone 0 
setblock ~18 ~1 ~21 cobblestone 0  
fill ~18 ~1 ~24 ~19 ~1 ~24 stone 0  
fill ~18 ~1 ~25 ~18 ~2 ~25 stone 0  
fill ~19 ~1 ~19 ~19 ~7 ~19 stone 0 
setblock ~19 ~1 ~20 cobblestone 0 
setblock ~19 ~1 ~21 stone 0  
fill ~19 ~1 ~23 ~19 ~10 ~23 stone 0 
setblock ~20 ~1 ~20 stone 0  
fill ~16 ~2 ~24 ~17 ~2 ~24 stone 0  
fill ~16 ~2 ~25 ~18 ~2 ~25 stone 0  
fill ~16 ~2 ~26 ~16 ~3 ~26 stone 0  
fill ~17 ~2 ~22 ~19 ~2 ~22 stone 0  
fill ~17 ~2 ~23 ~17 ~2 ~21 stone 0 
setblock ~18 ~2 ~21 stone 0 
setblock ~18 ~2 ~24 mossy_cobblestone 0  
fill ~19 ~2 ~20 ~19 ~6 ~20 stone 0 
setblock ~19 ~2 ~21 cobblestone 0 
setblock ~19 ~2 ~24 stone 0 
setblock ~20 ~2 ~20 mossy_cobblestone 0  
fill ~20 ~2 ~21 ~20 ~20 ~21 stone 0 
setblock ~20 ~2 ~22 mossy_cobblestone 0  
fill ~20 ~2 ~23 ~20 ~8 ~23 stone 0  
fill ~16 ~3 ~23 ~16 ~4 ~23 stone 0 
setblock ~16 ~3 ~24 cobblestone 0  
fill ~16 ~3 ~25 ~16 ~2 ~25 stone 0  
fill ~17 ~3 ~22 ~20 ~3 ~22 stone 0 
setblock ~17 ~3 ~23 cobblestone 0  
fill ~17 ~3 ~24 ~18 ~3 ~24 stone 0 
setblock ~17 ~3 ~25 mossy_cobblestone 0  
fill ~17 ~3 ~26 ~17 ~5 ~26 stone 0 
setblock ~18 ~3 ~21 cobblestone 0  
fill ~18 ~3 ~25 ~18 ~4 ~25 cobblestone 0  
fill ~19 ~3 ~21 ~19 ~4 ~21 stone 0  
fill ~19 ~3 ~24 ~19 ~4 ~24 mossy_cobblestone 0  
fill ~20 ~3 ~19 ~20 ~5 ~19 stone 0  
fill ~20 ~3 ~20 ~21 ~3 ~20 stone 0  
fill ~21 ~3 ~21 ~21 ~4 ~21 stone 0  
fill ~16 ~4 ~24 ~18 ~4 ~24 stone 0  
fill ~16 ~4 ~25 ~16 ~4 ~26 mossy_cobblestone 0  
fill ~16 ~4 ~27 ~16 ~11 ~27 stone 0  
fill ~16 ~4 ~28 ~16 ~32 ~28 stone 0  
fill ~17 ~4 ~22 ~20 ~4 ~22 stone 0  
fill ~17 ~4 ~23 ~17 ~24 ~23 stone 0  
fill ~17 ~4 ~25 ~17 ~10 ~25 stone 0  
fill ~18 ~4 ~21 ~18 ~5 ~21 stone 0  
fill ~19 ~4 ~25 ~19 ~7 ~25 stone 0 
setblock ~20 ~4 ~20 cobblestone 0  
fill ~21 ~4 ~19 ~21 ~8 ~19 stone 0  
fill ~21 ~4 ~20 ~22 ~4 ~20 stone 0 
setblock ~16 ~5 ~21 stone 0 
setblock ~16 ~5 ~23 cobblestone 0  
fill ~16 ~5 ~24 ~20 ~5 ~24 stone 0  
fill ~16 ~5 ~25 ~16 ~6 ~25 stone 0  
fill ~16 ~5 ~26 ~16 ~6 ~26 stone 0 
setblock ~16 ~5 ~29 cobblestone 0  
fill ~17 ~5 ~22 ~21 ~5 ~22 stone 0  
fill ~17 ~5 ~27 ~17 ~5 ~29 stone 0 
setblock ~18 ~5 ~19 stone 0  
fill ~18 ~5 ~25 ~18 ~9 ~25 stone 0  
fill ~18 ~5 ~26 ~18 ~12 ~26 stone 0 
setblock ~19 ~5 ~21 mossy_cobblestone 0  
fill ~20 ~5 ~18 ~20 ~8 ~18 stone 0  
fill ~20 ~5 ~20 ~22 ~5 ~20 stone 0 
setblock ~21 ~5 ~21 mossy_cobblestone 0 
setblock ~21 ~5 ~23 stone 0  
fill ~22 ~5 ~19 ~22 ~6 ~19 stone 0  
fill ~22 ~5 ~21 ~22 ~8 ~21 stone 0  
fill ~15 ~6 ~26 ~15 ~7 ~26 stone 0  
fill ~16 ~6 ~20 ~21 ~6 ~20 stone 0 
setblock ~16 ~6 ~21 cobblestone 0  
fill ~16 ~6 ~22 ~18 ~6 ~22 stone 0  
fill ~16 ~6 ~23 ~16 ~6 ~29 stone 0  
fill ~17 ~6 ~24 ~22 ~6 ~24 stone 0 
setblock ~17 ~6 ~26 cobblestone 0 
setblock ~17 ~6 ~27 mossy_cobblestone 0 
setblock ~17 ~6 ~28 cobblestone 0  
fill ~17 ~6 ~29 ~17 ~17 ~29 stone 0 
setblock ~18 ~6 ~19 cobblestone 0 
setblock ~18 ~6 ~21 mossy_cobblestone 0  
fill ~18 ~6 ~27 ~18 ~14 ~27 stone 0 
setblock ~18 ~6 ~28 mossy_cobblestone 0  
fill ~19 ~6 ~21 ~19 ~8 ~21 stone 0  
fill ~19 ~6 ~22 ~20 ~6 ~22 cobblestone 0 
setblock ~19 ~6 ~26 mossy_cobblestone 0 
setblock ~20 ~6 ~19 cobblestone 0  
fill ~21 ~6 ~21 ~21 ~9 ~21 stone 0  
fill ~21 ~6 ~22 ~21 ~23 ~22 stone 0 
setblock ~21 ~6 ~23 cobblestone 0  
fill ~21 ~6 ~25 ~22 ~6 ~25 stone 0 
setblock ~22 ~6 ~20 cobblestone 0 
setblock ~23 ~6 ~16 mossy_cobblestone 0  
fill ~24 ~6 ~16 ~24 ~11 ~16 stone 0  
fill ~26 ~6 ~17 ~26 ~11 ~17 stone 0 
setblock ~27 ~6 ~16 cobblestone 0  
fill ~14 ~7 ~25 ~14 ~7 ~26 stone 0  
fill ~15 ~7 ~22 ~15 ~9 ~22 stone 0  
fill ~15 ~7 ~23 ~16 ~7 ~23 mossy_cobblestone 0  
fill ~15 ~7 ~24 ~15 ~10 ~24 stone 0  
fill ~15 ~7 ~25 ~16 ~7 ~25 mossy_cobblestone 0  
fill ~16 ~7 ~20 ~18 ~7 ~20 stone 0  
fill ~16 ~7 ~21 ~16 ~7 ~20 stone 0  
fill ~16 ~7 ~22 ~16 ~9 ~22 mossy_cobblestone 0 
setblock ~16 ~7 ~24 mossy_cobblestone 0 
setblock ~16 ~7 ~26 cobblestone 0  
fill ~16 ~7 ~29 ~16 ~13 ~29 stone 0  
fill ~17 ~7 ~19 ~21 ~7 ~19 stone 0 
setblock ~17 ~7 ~21 mossy_cobblestone 0  
fill ~17 ~7 ~22 ~21 ~7 ~22 stone 0  
fill ~17 ~7 ~24 ~22 ~7 ~24 stone 0 
setblock ~17 ~7 ~26 stone 0 
setblock ~17 ~7 ~27 cobblestone 0  
fill ~17 ~7 ~28 ~18 ~7 ~28 stone 0 
setblock ~18 ~7 ~21 stone 0  
fill ~18 ~7 ~29 ~18 ~16 ~29 stone 0 
setblock ~19 ~7 ~20 cobblestone 0  
fill ~19 ~7 ~26 ~20 ~7 ~26 stone 0 
setblock ~19 ~7 ~27 mossy_cobblestone 0  
fill ~20 ~7 ~20 ~22 ~7 ~20 stone 0  
fill ~20 ~7 ~25 ~22 ~7 ~25 stone 0  
fill ~20 ~7 ~27 ~22 ~7 ~27 stone 0  
fill ~20 ~7 ~28 ~21 ~7 ~28 cobblestone 0  
fill ~21 ~7 ~17 ~22 ~7 ~17 stone 0  
fill ~21 ~7 ~18 ~22 ~7 ~18 stone 0  
fill ~21 ~7 ~23 ~22 ~7 ~23 stone 0 
setblock ~21 ~7 ~26 mossy_cobblestone 0  
fill ~21 ~7 ~29 ~21 ~8 ~29 stone 0 
setblock ~22 ~7 ~19 cobblestone 0  
fill ~22 ~7 ~26 ~22 ~11 ~26 stone 0  
fill ~23 ~7 ~16 ~23 ~8 ~16 stone 0  
fill ~23 ~7 ~19 ~23 ~33 ~19 stone 0  
fill ~24 ~7 ~17 ~26 ~7 ~17 stone 0  
fill ~25 ~7 ~16 ~26 ~7 ~16 stone 0  
fill ~27 ~7 ~16 ~27 ~8 ~16 mossy_cobblestone 0  
fill ~27 ~7 ~18 ~27 ~13 ~18 stone 0 
setblock ~14 ~8 ~25 mossy_cobblestone 0  
fill ~14 ~8 ~26 ~14 ~13 ~26 stone 0  
fill ~15 ~8 ~21 ~16 ~8 ~21 mossy_cobblestone 0  
fill ~15 ~8 ~23 ~22 ~8 ~23 stone 0  
fill ~15 ~8 ~25 ~18 ~8 ~25 stone 0 
setblock ~15 ~8 ~26 cobblestone 0  
fill ~15 ~8 ~27 ~15 ~12 ~27 stone 0  
fill ~16 ~8 ~19 ~18 ~8 ~19 stone 0 
setblock ~16 ~8 ~20 mossy_cobblestone 0  
fill ~16 ~8 ~24 ~17 ~8 ~24 stone 0  
fill ~16 ~8 ~26 ~16 ~11 ~26 stone 0  
fill ~17 ~8 ~20 ~17 ~18 ~20 stone 0  
fill ~17 ~8 ~21 ~17 ~10 ~21 stone 0  
fill ~17 ~8 ~22 ~22 ~8 ~22 stone 0  
fill ~17 ~8 ~26 ~17 ~9 ~26 mossy_cobblestone 0  
fill ~17 ~8 ~27 ~17 ~9 ~27 stone 0  
fill ~17 ~8 ~28 ~17 ~9 ~28 stone 0  
fill ~17 ~8 ~30 ~18 ~8 ~30 stone 0  
fill ~18 ~8 ~18 ~18 ~9 ~18 stone 0  
fill ~18 ~8 ~20 ~18 ~8 ~21 cobblestone 0 
setblock ~18 ~8 ~24 cobblestone 0 
setblock ~18 ~8 ~28 mossy_cobblestone 0  
fill ~19 ~8 ~17 ~19 ~15 ~17 stone 0 
setblock ~19 ~8 ~19 mossy_cobblestone 0  
fill ~19 ~8 ~20 ~23 ~8 ~20 stone 0  
fill ~19 ~8 ~24 ~22 ~8 ~24 stone 0  
fill ~19 ~8 ~25 ~19 ~8 ~26 cobblestone 0  
fill ~19 ~8 ~27 ~22 ~8 ~27 stone 0 
setblock ~19 ~8 ~28 cobblestone 0  
fill ~19 ~8 ~29 ~21 ~8 ~29 stone 0  
fill ~20 ~8 ~19 ~20 ~10 ~19 stone 0  
fill ~20 ~8 ~25 ~22 ~8 ~25 stone 0 
setblock ~20 ~8 ~26 mossy_cobblestone 0  
fill ~20 ~8 ~28 ~21 ~8 ~28 stone 0  
fill ~21 ~8 ~17 ~24 ~8 ~17 stone 0  
fill ~21 ~8 ~18 ~23 ~8 ~18 stone 0  
fill ~21 ~8 ~26 ~21 ~12 ~26 stone 0  
fill ~22 ~8 ~19 ~22 ~15 ~19 stone 0 
setblock ~22 ~8 ~28 cobblestone 0  
fill ~23 ~8 ~21 ~23 ~10 ~21 stone 0 
setblock ~23 ~8 ~25 cobblestone 0 
setblock ~24 ~8 ~19 cobblestone 0  
fill ~25 ~8 ~16 ~26 ~8 ~16 stone 0 
setblock ~25 ~8 ~17 mossy_cobblestone 0  
fill ~26 ~8 ~18 ~26 ~10 ~18 stone 0 
setblock ~27 ~8 ~17 cobblestone 0  
fill ~28 ~8 ~17 ~28 ~11 ~17 stone 0  
fill ~28 ~8 ~19 ~28 ~9 ~19 stone 0 
setblock ~13 ~9 ~24 mossy_cobblestone 0  
fill ~13 ~9 ~26 ~13 ~12 ~26 stone 0  
fill ~14 ~9 ~23 ~19 ~9 ~23 stone 0  
fill ~14 ~9 ~25 ~21 ~9 ~25 stone 0  
fill ~15 ~9 ~20 ~18 ~9 ~20 stone 0  
fill ~15 ~9 ~21 ~17 ~9 ~21 stone 0  
fill ~15 ~9 ~26 ~15 ~10 ~26 mossy_cobblestone 0  
fill ~15 ~9 ~28 ~15 ~11 ~28 stone 0 
setblock ~16 ~9 ~19 mossy_cobblestone 0  
fill ~16 ~9 ~24 ~17 ~9 ~24 stone 0  
fill ~17 ~9 ~18 ~17 ~12 ~18 stone 0  
fill ~17 ~9 ~19 ~20 ~9 ~19 stone 0  
fill ~17 ~9 ~22 ~21 ~9 ~22 stone 0  
fill ~17 ~9 ~30 ~19 ~9 ~30 stone 0 
setblock ~18 ~9 ~21 cobblestone 0 
setblock ~18 ~9 ~24 mossy_cobblestone 0  
fill ~18 ~9 ~28 ~22 ~9 ~28 stone 0  
fill ~19 ~9 ~18 ~19 ~10 ~18 stone 0 
setblock ~19 ~9 ~20 cobblestone 0 
setblock ~19 ~9 ~21 mossy_cobblestone 0  
fill ~19 ~9 ~24 ~24 ~9 ~24 stone 0  
fill ~19 ~9 ~26 ~24 ~9 ~26 stone 0  
fill ~19 ~9 ~27 ~23 ~9 ~27 stone 0  
fill ~19 ~9 ~29 ~20 ~9 ~29 stone 0  
fill ~20 ~9 ~17 ~20 ~10 ~17 stone 0 
setblock ~20 ~9 ~18 cobblestone 0  
fill ~20 ~9 ~20 ~23 ~9 ~20 stone 0  
fill ~20 ~9 ~23 ~22 ~9 ~23 cobblestone 0  
fill ~21 ~9 ~17 ~22 ~9 ~17 cobblestone 0  
fill ~21 ~9 ~18 ~24 ~9 ~18 stone 0 
setblock ~21 ~9 ~19 mossy_cobblestone 0  
fill ~21 ~9 ~29 ~22 ~9 ~29 mossy_cobblestone 0  
fill ~22 ~9 ~21 ~22 ~9 ~23 cobblestone 0 
setblock ~22 ~9 ~25 mossy_cobblestone 0 
setblock ~23 ~9 ~16 mossy_cobblestone 0  
fill ~23 ~9 ~17 ~23 ~10 ~17 stone 0  
fill ~23 ~9 ~23 ~23 ~12 ~23 stone 0  
fill ~23 ~9 ~25 ~24 ~9 ~25 stone 0 
setblock ~24 ~9 ~17 mossy_cobblestone 0  
fill ~24 ~9 ~19 ~24 ~12 ~19 stone 0 
setblock ~24 ~9 ~20 cobblestone 0  
fill ~25 ~9 ~16 ~27 ~9 ~16 stone 0  
fill ~25 ~9 ~17 ~25 ~9 ~16 stone 0 
setblock ~25 ~9 ~18 cobblestone 0 
setblock ~27 ~9 ~17 mossy_cobblestone 0 
setblock ~28 ~9 ~18 cobblestone 0  
fill ~13 ~10 ~24 ~16 ~10 ~24 stone 0  
fill ~13 ~10 ~25 ~14 ~10 ~25 stone 0  
fill ~14 ~10 ~21 ~20 ~10 ~21 stone 0  
fill ~14 ~10 ~22 ~14 ~11 ~22 stone 0  
fill ~14 ~10 ~23 ~15 ~10 ~23 stone 0  
fill ~14 ~10 ~27 ~14 ~15 ~27 stone 0  
fill ~15 ~10 ~19 ~15 ~11 ~19 stone 0  
fill ~15 ~10 ~20 ~15 ~19 ~20 stone 0  
fill ~15 ~10 ~22 ~15 ~11 ~22 mossy_cobblestone 0  
fill ~15 ~10 ~25 ~15 ~11 ~25 cobblestone 0  
fill ~16 ~10 ~18 ~16 ~11 ~18 mossy_cobblestone 0  
fill ~16 ~10 ~19 ~16 ~12 ~19 cobblestone 0 
setblock ~16 ~10 ~20 mossy_cobblestone 0  
fill ~16 ~10 ~22 ~23 ~10 ~22 stone 0 
setblock ~16 ~10 ~23 mossy_cobblestone 0  
fill ~16 ~10 ~25 ~16 ~12 ~25 stone 0  
fill ~17 ~10 ~17 ~17 ~20 ~17 stone 0  
fill ~17 ~10 ~19 ~24 ~10 ~19 stone 0 
setblock ~17 ~10 ~24 cobblestone 0 
setblock ~17 ~10 ~26 stone 0  
fill ~17 ~10 ~27 ~17 ~10 ~28 cobblestone 0  
fill ~17 ~10 ~30 ~17 ~13 ~30 stone 0 
setblock ~18 ~10 ~18 cobblestone 0  
fill ~18 ~10 ~20 ~18 ~12 ~20 stone 0  
fill ~18 ~10 ~24 ~20 ~10 ~24 stone 0  
fill ~18 ~10 ~25 ~18 ~11 ~25 cobblestone 0  
fill ~18 ~10 ~28 ~19 ~10 ~28 stone 0 
setblock ~18 ~10 ~30 mossy_cobblestone 0 
setblock ~19 ~10 ~20 mossy_cobblestone 0  
fill ~19 ~10 ~25 ~24 ~10 ~25 stone 0  
fill ~19 ~10 ~26 ~23 ~10 ~26 stone 0  
fill ~19 ~10 ~27 ~22 ~10 ~27 stone 0  
fill ~19 ~10 ~29 ~20 ~10 ~29 stone 0  
fill ~19 ~10 ~30 ~19 ~10 ~21 stone 0  
fill ~20 ~10 ~18 ~20 ~15 ~18 stone 0  
fill ~20 ~10 ~20 ~24 ~10 ~20 stone 0  
fill ~20 ~10 ~23 ~20 ~9 ~23 cobblestone 0 
setblock ~20 ~10 ~28 mossy_cobblestone 0 
setblock ~20 ~10 ~30 cobblestone 0  
fill ~21 ~10 ~17 ~24 ~10 ~17 stone 0 
setblock ~21 ~10 ~18 mossy_cobblestone 0 
setblock ~21 ~10 ~21 cobblestone 0  
fill ~21 ~10 ~23 ~24 ~10 ~23 stone 0 
setblock ~21 ~10 ~24 cobblestone 0  
fill ~21 ~10 ~28 ~22 ~10 ~28 stone 0  
fill ~21 ~10 ~29 ~21 ~9 ~29 mossy_cobblestone 0 
setblock ~22 ~10 ~15 stone 0  
fill ~22 ~10 ~18 ~23 ~10 ~18 stone 0  
fill ~22 ~10 ~21 ~22 ~18 ~21 stone 0  
fill ~22 ~10 ~24 ~25 ~10 ~24 stone 0  
fill ~22 ~10 ~29 ~22 ~22 ~29 stone 0 
setblock ~23 ~10 ~16 stone 0  
fill ~23 ~10 ~27 ~23 ~10 ~28 mossy_cobblestone 0  
fill ~24 ~10 ~15 ~24 ~14 ~15 stone 0 
setblock ~24 ~10 ~18 mossy_cobblestone 0 
setblock ~24 ~10 ~21 cobblestone 0 
setblock ~24 ~10 ~26 mossy_cobblestone 0  
fill ~24 ~10 ~27 ~24 ~13 ~27 stone 0  
fill ~24 ~10 ~28 ~24 ~10 ~27 stone 0  
fill ~25 ~10 ~16 ~27 ~10 ~16 stone 0 
setblock ~25 ~10 ~17 mossy_cobblestone 0  
fill ~25 ~10 ~18 ~25 ~15 ~18 stone 0 
setblock ~25 ~10 ~21 mossy_cobblestone 0 
setblock ~25 ~10 ~25 mossy_cobblestone 0  
fill ~26 ~10 ~19 ~27 ~10 ~19 stone 0  
fill ~27 ~10 ~17 ~27 ~12 ~17 stone 0  
fill ~28 ~10 ~18 ~29 ~10 ~18 stone 0 
setblock ~28 ~10 ~19 mossy_cobblestone 0 
setblock ~13 ~11 ~23 cobblestone 0  
fill ~13 ~11 ~24 ~14 ~11 ~24 stone 0  
fill ~13 ~11 ~25 ~13 ~21 ~25 stone 0 
setblock ~14 ~11 ~20 cobblestone 0  
fill ~14 ~11 ~21 ~16 ~11 ~21 stone 0  
fill ~14 ~11 ~23 ~14 ~9 ~23 stone 0  
fill ~14 ~11 ~25 ~14 ~12 ~25 cobblestone 0 
setblock ~15 ~11 ~18 cobblestone 0  
fill ~15 ~11 ~23 ~15 ~11 ~25 cobblestone 0  
fill ~15 ~11 ~26 ~15 ~16 ~26 stone 0 
setblock ~16 ~11 ~17 mossy_cobblestone 0  
fill ~16 ~11 ~20 ~16 ~12 ~20 stone 0  
fill ~16 ~11 ~22 ~21 ~11 ~22 stone 0  
fill ~16 ~11 ~23 ~16 ~12 ~23 stone 0 
setblock ~16 ~11 ~24 cobblestone 0  
fill ~17 ~11 ~19 ~17 ~17 ~19 stone 0  
fill ~17 ~11 ~21 ~17 ~12 ~21 mossy_cobblestone 0  
fill ~17 ~11 ~24 ~25 ~11 ~24 stone 0 
setblock ~17 ~11 ~25 cobblestone 0 
setblock ~17 ~11 ~26 mossy_cobblestone 0  
fill ~17 ~11 ~27 ~17 ~13 ~27 stone 0  
fill ~17 ~11 ~28 ~23 ~11 ~28 stone 0  
fill ~17 ~11 ~31 ~18 ~11 ~31 stone 0  
fill ~18 ~11 ~17 ~18 ~13 ~17 stone 0  
fill ~18 ~11 ~18 ~19 ~11 ~18 mossy_cobblestone 0 
setblock ~18 ~11 ~19 cobblestone 0 
setblock ~18 ~11 ~21 stone 0 
setblock ~18 ~11 ~23 mossy_cobblestone 0 
setblock ~18 ~11 ~30 stone 0  
fill ~19 ~11 ~19 ~19 ~17 ~19 stone 0  
fill ~19 ~11 ~20 ~26 ~11 ~20 stone 0 
setblock ~19 ~11 ~21 mossy_cobblestone 0 
setblock ~19 ~11 ~23 cobblestone 0  
fill ~19 ~11 ~25 ~22 ~11 ~25 stone 0  
fill ~19 ~11 ~26 ~24 ~11 ~26 stone 0  
fill ~19 ~11 ~27 ~21 ~11 ~27 stone 0  
fill ~19 ~11 ~29 ~23 ~11 ~29 stone 0  
fill ~19 ~11 ~30 ~19 ~12 ~30 cobblestone 0 
setblock ~20 ~11 ~17 mossy_cobblestone 0 
setblock ~20 ~11 ~19 cobblestone 0  
fill ~20 ~11 ~23 ~26 ~11 ~23 stone 0  
fill ~20 ~11 ~30 ~21 ~11 ~30 stone 0  
fill ~21 ~11 ~17 ~22 ~11 ~17 stone 0  
fill ~21 ~11 ~18 ~22 ~11 ~18 stone 0  
fill ~21 ~11 ~19 ~21 ~11 ~17 stone 0  
fill ~21 ~11 ~21 ~21 ~14 ~21 stone 0 
setblock ~22 ~11 ~15 cobblestone 0 
setblock ~22 ~11 ~22 mossy_cobblestone 0 
setblock ~22 ~11 ~27 cobblestone 0  
fill ~23 ~11 ~15 ~23 ~12 ~15 stone 0 
setblock ~23 ~11 ~16 cobblestone 0 
setblock ~23 ~11 ~17 mossy_cobblestone 0 
setblock ~23 ~11 ~18 cobblestone 0  
fill ~23 ~11 ~21 ~23 ~12 ~21 cobblestone 0  
fill ~23 ~11 ~22 ~26 ~11 ~22 stone 0 
setblock ~23 ~11 ~25 mossy_cobblestone 0  
fill ~23 ~11 ~27 ~23 ~13 ~27 stone 0  
fill ~24 ~11 ~13 ~24 ~20 ~13 stone 0  
fill ~24 ~11 ~14 ~26 ~11 ~14 stone 0  
fill ~24 ~11 ~17 ~28 ~11 ~17 stone 0  
fill ~24 ~11 ~18 ~24 ~16 ~18 stone 0  
fill ~24 ~11 ~21 ~25 ~11 ~21 stone 0  
fill ~24 ~11 ~25 ~26 ~11 ~25 stone 0 
setblock ~24 ~11 ~28 mossy_cobblestone 0  
fill ~25 ~11 ~13 ~25 ~12 ~13 mossy_cobblestone 0  
fill ~25 ~11 ~15 ~26 ~11 ~15 stone 0  
fill ~25 ~11 ~16 ~25 ~7 ~16 stone 0 
setblock ~26 ~11 ~16 mossy_cobblestone 0 
setblock ~26 ~11 ~18 cobblestone 0  
fill ~26 ~11 ~19 ~27 ~11 ~19 mossy_cobblestone 0 
setblock ~27 ~11 ~15 mossy_cobblestone 0  
fill ~27 ~11 ~16 ~28 ~11 ~16 stone 0  
fill ~28 ~11 ~18 ~29 ~11 ~18 stone 0  
fill ~28 ~11 ~19 ~28 ~13 ~19 stone 0  
fill ~29 ~11 ~7 ~29 ~13 ~7 stone 0  
fill ~29 ~11 ~8 ~29 ~12 ~8 stone 0  
fill ~29 ~11 ~9 ~29 ~11 ~7 stone 0 
setblock ~29 ~11 ~17 cobblestone 0  
fill ~32 ~11 ~9 ~32 ~14 ~9 stone 0  
fill ~13 ~12 ~20 ~24 ~12 ~20 stone 0  
fill ~13 ~12 ~21 ~13 ~17 ~21 stone 0  
fill ~13 ~12 ~22 ~13 ~17 ~22 stone 0  
fill ~13 ~12 ~23 ~13 ~25 ~23 stone 0  
fill ~13 ~12 ~24 ~13 ~13 ~24 stone 0  
fill ~14 ~12 ~17 ~20 ~12 ~17 stone 0  
fill ~14 ~12 ~18 ~20 ~12 ~18 stone 0  
fill ~14 ~12 ~19 ~16 ~12 ~19 cobblestone 0  
fill ~14 ~12 ~21 ~14 ~12 ~24 mossy_cobblestone 0  
fill ~14 ~12 ~28 ~14 ~17 ~28 stone 0  
fill ~15 ~12 ~16 ~16 ~12 ~16 stone 0 
setblock ~15 ~12 ~21 cobblestone 0  
fill ~15 ~12 ~22 ~15 ~16 ~22 stone 0  
fill ~15 ~12 ~23 ~15 ~17 ~23 stone 0  
fill ~15 ~12 ~24 ~17 ~12 ~24 stone 0  
fill ~15 ~12 ~25 ~15 ~18 ~25 stone 0 
setblock ~15 ~12 ~28 cobblestone 0 
setblock ~16 ~12 ~21 stone 0 
setblock ~16 ~12 ~22 cobblestone 0 
setblock ~16 ~12 ~26 cobblestone 0 
setblock ~16 ~12 ~27 mossy_cobblestone 0  
fill ~17 ~12 ~15 ~20 ~12 ~15 stone 0 
setblock ~17 ~12 ~16 cobblestone 0  
fill ~17 ~12 ~22 ~19 ~12 ~22 stone 0  
fill ~17 ~12 ~25 ~21 ~12 ~25 stone 0  
fill ~17 ~12 ~26 ~17 ~13 ~26 stone 0 
setblock ~17 ~12 ~28 cobblestone 0  
fill ~17 ~12 ~31 ~19 ~12 ~31 stone 0  
fill ~18 ~12 ~16 ~23 ~12 ~16 stone 0 
setblock ~18 ~12 ~19 mossy_cobblestone 0 
setblock ~18 ~12 ~21 cobblestone 0  
fill ~18 ~12 ~23 ~18 ~12 ~24 cobblestone 0  
fill ~18 ~12 ~28 ~24 ~12 ~28 stone 0 
setblock ~18 ~12 ~30 mossy_cobblestone 0 
setblock ~18 ~12 ~32 mossy_cobblestone 0 
setblock ~19 ~12 ~21 stone 0  
fill ~19 ~12 ~23 ~20 ~12 ~23 stone 0  
fill ~19 ~12 ~24 ~21 ~12 ~24 stone 0 
setblock ~19 ~12 ~26 mossy_cobblestone 0  
fill ~19 ~12 ~27 ~19 ~26 ~27 stone 0  
fill ~19 ~12 ~29 ~19 ~13 ~29 mossy_cobblestone 0 
setblock ~20 ~12 ~19 stone 0 
setblock ~20 ~12 ~22 cobblestone 0 
setblock ~20 ~12 ~26 stone 0  
fill ~20 ~12 ~27 ~20 ~13 ~27 mossy_cobblestone 0  
fill ~20 ~12 ~29 ~20 ~28 ~29 stone 0  
fill ~20 ~12 ~30 ~23 ~12 ~30 stone 0  
fill ~21 ~12 ~17 ~21 ~12 ~18 mossy_cobblestone 0 
setblock ~21 ~12 ~19 cobblestone 0  
fill ~21 ~12 ~23 ~22 ~12 ~23 mossy_cobblestone 0  
fill ~21 ~12 ~27 ~25 ~12 ~27 stone 0 
setblock ~21 ~12 ~29 mossy_cobblestone 0  
fill ~22 ~12 ~15 ~22 ~14 ~15 stone 0 
setblock ~22 ~12 ~17 cobblestone 0  
fill ~22 ~12 ~18 ~29 ~12 ~18 stone 0  
fill ~22 ~12 ~22 ~26 ~12 ~22 stone 0  
fill ~22 ~12 ~24 ~23 ~12 ~24 mossy_cobblestone 0  
fill ~22 ~12 ~25 ~22 ~12 ~26 cobblestone 0  
fill ~23 ~12 ~13 ~23 ~19 ~13 stone 0  
fill ~23 ~12 ~17 ~24 ~12 ~17 stone 0  
fill ~23 ~12 ~25 ~27 ~12 ~25 stone 0 
setblock ~23 ~12 ~26 mossy_cobblestone 0  
fill ~23 ~12 ~29 ~24 ~12 ~29 stone 0 
setblock ~24 ~12 ~14 mossy_cobblestone 0  
fill ~24 ~12 ~16 ~25 ~12 ~16 cobblestone 0 
setblock ~24 ~12 ~21 cobblestone 0  
fill ~24 ~12 ~23 ~24 ~12 ~29 stone 0  
fill ~25 ~12 ~14 ~26 ~12 ~14 stone 0  
fill ~25 ~12 ~15 ~27 ~12 ~15 stone 0  
fill ~25 ~12 ~17 ~26 ~12 ~17 mossy_cobblestone 0  
fill ~25 ~12 ~19 ~28 ~12 ~19 stone 0 
setblock ~25 ~12 ~20 cobblestone 0  
fill ~25 ~12 ~21 ~26 ~12 ~21 stone 0  
fill ~25 ~12 ~23 ~25 ~13 ~23 mossy_cobblestone 0  
fill ~25 ~12 ~24 ~27 ~12 ~24 stone 0  
fill ~25 ~12 ~26 ~26 ~12 ~26 stone 0  
fill ~26 ~12 ~16 ~27 ~12 ~16 stone 0  
fill ~26 ~12 ~20 ~26 ~14 ~20 stone 0  
fill ~26 ~12 ~23 ~27 ~12 ~23 stone 0  
fill ~28 ~12 ~16 ~28 ~12 ~17 mossy_cobblestone 0 
setblock ~28 ~12 ~20 stone 0 
setblock ~29 ~12 ~6 cobblestone 0 
setblock ~29 ~12 ~9 cobblestone 0 
setblock ~29 ~12 ~10 mossy_cobblestone 0  
fill ~29 ~12 ~17 ~29 ~16 ~17 stone 0  
fill ~30 ~12 ~7 ~30 ~12 ~8 stone 0 
setblock ~30 ~12 ~9 mossy_cobblestone 0  
fill ~30 ~12 ~10 ~32 ~12 ~10 stone 0  
fill ~31 ~12 ~8 ~32 ~12 ~8 stone 0  
fill ~31 ~12 ~9 ~31 ~13 ~9 stone 0  
fill ~13 ~13 ~18 ~14 ~13 ~18 stone 0  
fill ~13 ~13 ~20 ~15 ~13 ~20 stone 0 
setblock ~13 ~13 ~26 mossy_cobblestone 0  
fill ~14 ~13 ~17 ~14 ~14 ~17 stone 0 
setblock ~14 ~13 ~19 mossy_cobblestone 0  
fill ~14 ~13 ~21 ~14 ~15 ~21 stone 0  
fill ~14 ~13 ~22 ~14 ~14 ~22 mossy_cobblestone 0  
fill ~14 ~13 ~23 ~14 ~16 ~23 stone 0  
fill ~14 ~13 ~24 ~27 ~13 ~24 stone 0  
fill ~14 ~13 ~25 ~14 ~22 ~25 stone 0  
fill ~15 ~13 ~16 ~17 ~13 ~16 stone 0  
fill ~15 ~13 ~17 ~15 ~13 ~18 mossy_cobblestone 0  
fill ~15 ~13 ~19 ~19 ~13 ~19 stone 0  
fill ~15 ~13 ~21 ~16 ~13 ~21 mossy_cobblestone 0 
setblock ~15 ~13 ~27 mossy_cobblestone 0  
fill ~15 ~13 ~28 ~15 ~28 ~28 stone 0  
fill ~15 ~13 ~29 ~15 ~18 ~29 stone 0  
fill ~16 ~13 ~17 ~16 ~20 ~17 stone 0  
fill ~16 ~13 ~18 ~16 ~21 ~18 stone 0  
fill ~16 ~13 ~20 ~16 ~14 ~20 mossy_cobblestone 0  
fill ~16 ~13 ~22 ~17 ~13 ~22 stone 0 
setblock ~16 ~13 ~23 cobblestone 0 
setblock ~16 ~13 ~25 mossy_cobblestone 0  
fill ~16 ~13 ~26 ~16 ~17 ~26 stone 0  
fill ~16 ~13 ~27 ~16 ~13 ~26 stone 0  
fill ~16 ~13 ~30 ~16 ~14 ~30 stone 0 
setblock ~17 ~13 ~15 cobblestone 0  
fill ~17 ~13 ~18 ~18 ~13 ~18 mossy_cobblestone 0  
fill ~17 ~13 ~21 ~18 ~13 ~21 stone 0  
fill ~17 ~13 ~25 ~22 ~13 ~25 stone 0  
fill ~17 ~13 ~28 ~23 ~13 ~28 stone 0  
fill ~17 ~13 ~31 ~18 ~13 ~31 stone 0  
fill ~18 ~13 ~15 ~18 ~18 ~15 stone 0  
fill ~18 ~13 ~16 ~18 ~14 ~16 cobblestone 0 
setblock ~18 ~13 ~20 cobblestone 0 
setblock ~18 ~13 ~22 mossy_cobblestone 0  
fill ~18 ~13 ~23 ~22 ~13 ~23 stone 0 
setblock ~18 ~13 ~26 mossy_cobblestone 0 
setblock ~18 ~13 ~30 cobblestone 0  
fill ~18 ~13 ~32 ~19 ~13 ~32 stone 0 
setblock ~19 ~13 ~15 cobblestone 0  
fill ~19 ~13 ~16 ~19 ~22 ~16 stone 0 
setblock ~19 ~13 ~18 cobblestone 0  
fill ~19 ~13 ~20 ~20 ~13 ~20 stone 0 
setblock ~19 ~13 ~21 cobblestone 0  
fill ~19 ~13 ~22 ~24 ~13 ~22 stone 0  
fill ~19 ~13 ~26 ~19 ~15 ~26 stone 0  
fill ~19 ~13 ~30 ~21 ~13 ~30 stone 0 
setblock ~19 ~13 ~31 cobblestone 0  
fill ~20 ~13 ~15 ~22 ~13 ~15 stone 0  
fill ~20 ~13 ~16 ~20 ~14 ~16 cobblestone 0  
fill ~20 ~13 ~17 ~26 ~13 ~17 stone 0  
fill ~20 ~13 ~19 ~20 ~14 ~19 mossy_cobblestone 0 
setblock ~20 ~13 ~26 cobblestone 0  
fill ~20 ~13 ~31 ~20 ~16 ~31 stone 0 
setblock ~20 ~13 ~32 mossy_cobblestone 0  
fill ~21 ~13 ~16 ~21 ~18 ~16 stone 0  
fill ~21 ~13 ~18 ~21 ~41 ~18 stone 0  
fill ~21 ~13 ~19 ~21 ~14 ~19 stone 0  
fill ~21 ~13 ~20 ~22 ~13 ~20 mossy_cobblestone 0 
setblock ~21 ~13 ~26 mossy_cobblestone 0  
fill ~21 ~13 ~27 ~24 ~13 ~27 stone 0  
fill ~21 ~13 ~29 ~21 ~17 ~29 stone 0 
setblock ~21 ~13 ~31 mossy_cobblestone 0 
setblock ~22 ~13 ~14 mossy_cobblestone 0 
setblock ~22 ~13 ~16 cobblestone 0 
setblock ~22 ~13 ~18 mossy_cobblestone 0  
fill ~22 ~13 ~26 ~26 ~13 ~26 stone 0 
setblock ~22 ~13 ~30 mossy_cobblestone 0 
setblock ~23 ~13 ~15 cobblestone 0  
fill ~23 ~13 ~16 ~28 ~13 ~16 stone 0  
fill ~23 ~13 ~18 ~23 ~15 ~18 stone 0  
fill ~23 ~13 ~20 ~24 ~13 ~20 stone 0  
fill ~23 ~13 ~21 ~26 ~13 ~21 stone 0 
setblock ~23 ~13 ~23 cobblestone 0 
setblock ~23 ~13 ~25 cobblestone 0  
fill ~23 ~13 ~29 ~25 ~13 ~29 stone 0  
fill ~23 ~13 ~30 ~24 ~13 ~30 stone 0  
fill ~23 ~13 ~31 ~23 ~19 ~31 stone 0  
fill ~24 ~13 ~14 ~26 ~13 ~14 stone 0  
fill ~24 ~13 ~19 ~24 ~14 ~19 cobblestone 0 
setblock ~24 ~13 ~23 mossy_cobblestone 0  
fill ~24 ~13 ~25 ~27 ~13 ~25 stone 0 
setblock ~24 ~13 ~28 mossy_cobblestone 0  
fill ~25 ~13 ~13 ~26 ~13 ~13 stone 0  
fill ~25 ~13 ~15 ~26 ~13 ~15 stone 0  
fill ~25 ~13 ~19 ~26 ~13 ~19 stone 0 
setblock ~25 ~13 ~20 mossy_cobblestone 0 
setblock ~25 ~13 ~22 mossy_cobblestone 0 
setblock ~25 ~13 ~27 cobblestone 0  
fill ~25 ~13 ~28 ~25 ~20 ~28 stone 0  
fill ~26 ~13 ~18 ~26 ~17 ~18 stone 0  
fill ~26 ~13 ~22 ~27 ~13 ~22 stone 0  
fill ~26 ~13 ~23 ~27 ~13 ~23 stone 0 
setblock ~27 ~13 ~15 cobblestone 0 
setblock ~27 ~13 ~17 mossy_cobblestone 0  
fill ~27 ~13 ~19 ~27 ~14 ~19 mossy_cobblestone 0  
fill ~27 ~13 ~20 ~27 ~19 ~20 stone 0 
setblock ~28 ~13 ~8 mossy_cobblestone 0  
fill ~28 ~13 ~9 ~32 ~13 ~9 stone 0  
fill ~28 ~13 ~17 ~28 ~13 ~19 stone 0  
fill ~28 ~13 ~20 ~28 ~14 ~20 cobblestone 0 
setblock ~29 ~13 ~6 mossy_cobblestone 0 
setblock ~29 ~13 ~8 cobblestone 0  
fill ~29 ~13 ~10 ~33 ~13 ~10 stone 0 
setblock ~29 ~13 ~16 cobblestone 0  
fill ~29 ~13 ~18 ~29 ~17 ~18 stone 0  
fill ~29 ~13 ~19 ~29 ~15 ~19 stone 0 
setblock ~30 ~13 ~6 cobblestone 0  
fill ~30 ~13 ~7 ~31 ~13 ~7 mossy_cobblestone 0  
fill ~30 ~13 ~8 ~33 ~13 ~8 stone 0  
fill ~31 ~13 ~6 ~31 ~24 ~6 stone 0  
fill ~32 ~13 ~7 ~32 ~16 ~7 stone 0  
fill ~32 ~13 ~11 ~32 ~15 ~11 stone 0 
setblock ~34 ~13 ~9 stone 0  
fill ~11 ~14 ~23 ~11 ~30 ~23 stone 0  
fill ~12 ~14 ~19 ~19 ~14 ~19 stone 0  
fill ~12 ~14 ~21 ~12 ~15 ~21 stone 0  
fill ~12 ~14 ~22 ~12 ~28 ~22 stone 0  
fill ~12 ~14 ~24 ~13 ~14 ~24 mossy_cobblestone 0 
setblock ~12 ~14 ~25 cobblestone 0  
fill ~13 ~14 ~18 ~26 ~14 ~18 stone 0  
fill ~13 ~14 ~20 ~15 ~14 ~20 stone 0  
fill ~13 ~14 ~26 ~13 ~24 ~26 stone 0 
setblock ~13 ~14 ~27 mossy_cobblestone 0  
fill ~14 ~14 ~24 ~18 ~14 ~24 stone 0 
setblock ~14 ~14 ~26 mossy_cobblestone 0  
fill ~15 ~14 ~16 ~17 ~14 ~16 stone 0  
fill ~15 ~14 ~17 ~15 ~15 ~17 stone 0  
fill ~15 ~14 ~21 ~15 ~13 ~21 mossy_cobblestone 0  
fill ~15 ~14 ~27 ~15 ~16 ~27 stone 0  
fill ~16 ~14 ~21 ~16 ~21 ~21 stone 0  
fill ~16 ~14 ~22 ~16 ~21 ~22 stone 0  
fill ~16 ~14 ~23 ~16 ~16 ~23 stone 0  
fill ~16 ~14 ~25 ~17 ~14 ~25 stone 0  
fill ~16 ~14 ~27 ~17 ~14 ~27 mossy_cobblestone 0 
setblock ~16 ~14 ~29 mossy_cobblestone 0 
setblock ~17 ~14 ~15 stone 0  
fill ~17 ~14 ~21 ~18 ~14 ~21 cobblestone 0 
setblock ~17 ~14 ~22 mossy_cobblestone 0 
setblock ~17 ~14 ~26 cobblestone 0  
fill ~17 ~14 ~28 ~21 ~14 ~28 stone 0 
setblock ~17 ~14 ~30 mossy_cobblestone 0  
fill ~17 ~14 ~31 ~24 ~14 ~31 stone 0 
setblock ~18 ~14 ~17 mossy_cobblestone 0  
fill ~18 ~14 ~20 ~27 ~14 ~20 stone 0  
fill ~18 ~14 ~22 ~27 ~14 ~22 stone 0  
fill ~18 ~14 ~23 ~25 ~14 ~23 stone 0 
setblock ~18 ~14 ~25 mossy_cobblestone 0  
fill ~18 ~14 ~26 ~18 ~16 ~26 stone 0  
fill ~18 ~14 ~30 ~18 ~18 ~30 stone 0 
setblock ~18 ~14 ~32 mossy_cobblestone 0  
fill ~19 ~14 ~14 ~20 ~14 ~14 stone 0  
fill ~19 ~14 ~15 ~24 ~14 ~15 stone 0  
fill ~19 ~14 ~21 ~19 ~18 ~21 stone 0 
setblock ~19 ~14 ~24 mossy_cobblestone 0  
fill ~19 ~14 ~25 ~21 ~14 ~25 stone 0  
fill ~19 ~14 ~29 ~19 ~14 ~30 cobblestone 0  
fill ~19 ~14 ~32 ~22 ~14 ~32 stone 0  
fill ~20 ~14 ~17 ~27 ~14 ~17 stone 0 
setblock ~20 ~14 ~24 cobblestone 0  
fill ~20 ~14 ~26 ~25 ~14 ~26 stone 0  
fill ~20 ~14 ~27 ~22 ~14 ~27 stone 0  
fill ~20 ~14 ~30 ~25 ~14 ~30 stone 0  
fill ~21 ~14 ~24 ~21 ~15 ~24 stone 0  
fill ~22 ~14 ~14 ~28 ~14 ~14 stone 0  
fill ~22 ~14 ~16 ~28 ~14 ~16 stone 0  
fill ~22 ~14 ~24 ~22 ~14 ~25 mossy_cobblestone 0 
setblock ~22 ~14 ~28 cobblestone 0  
fill ~23 ~14 ~21 ~26 ~14 ~21 stone 0  
fill ~23 ~14 ~24 ~24 ~14 ~24 stone 0  
fill ~23 ~14 ~25 ~23 ~22 ~25 stone 0  
fill ~23 ~14 ~27 ~24 ~14 ~27 mossy_cobblestone 0  
fill ~23 ~14 ~28 ~26 ~14 ~28 stone 0  
fill ~23 ~14 ~29 ~26 ~14 ~29 stone 0 
setblock ~24 ~14 ~25 mossy_cobblestone 0  
fill ~25 ~14 ~13 ~27 ~14 ~13 stone 0 
setblock ~25 ~14 ~15 mossy_cobblestone 0  
fill ~25 ~14 ~19 ~26 ~14 ~19 stone 0 
setblock ~25 ~14 ~24 cobblestone 0  
fill ~25 ~14 ~25 ~27 ~14 ~25 stone 0  
fill ~25 ~14 ~27 ~27 ~14 ~27 stone 0  
fill ~26 ~14 ~15 ~27 ~14 ~15 stone 0  
fill ~26 ~14 ~23 ~26 ~15 ~23 mossy_cobblestone 0  
fill ~26 ~14 ~24 ~27 ~14 ~24 stone 0 
setblock ~26 ~14 ~26 cobblestone 0  
fill ~27 ~14 ~18 ~28 ~14 ~18 cobblestone 0  
fill ~27 ~14 ~23 ~27 ~23 ~23 stone 0  
fill ~27 ~14 ~26 ~27 ~16 ~26 stone 0  
fill ~28 ~14 ~6 ~31 ~14 ~6 stone 0  
fill ~28 ~14 ~7 ~28 ~16 ~7 cobblestone 0  
fill ~28 ~14 ~8 ~33 ~14 ~8 stone 0  
fill ~28 ~14 ~9 ~29 ~14 ~9 stone 0 
setblock ~28 ~14 ~17 cobblestone 0 
setblock ~28 ~14 ~19 cobblestone 0  
fill ~29 ~14 ~7 ~29 ~15 ~7 mossy_cobblestone 0  
fill ~29 ~14 ~10 ~34 ~14 ~10 stone 0 
setblock ~29 ~14 ~16 mossy_cobblestone 0 
setblock ~29 ~14 ~20 stone 0 
setblock ~30 ~14 ~5 stone 0  
fill ~30 ~14 ~7 ~30 ~18 ~7 stone 0  
fill ~30 ~14 ~9 ~31 ~14 ~9 mossy_cobblestone 0  
fill ~30 ~14 ~19 ~30 ~18 ~19 stone 0 
setblock ~31 ~14 ~7 mossy_cobblestone 0  
fill ~31 ~14 ~11 ~31 ~18 ~11 stone 0  
fill ~31 ~14 ~12 ~34 ~14 ~12 stone 0  
fill ~33 ~14 ~9 ~33 ~23 ~9 stone 0  
fill ~33 ~14 ~11 ~33 ~15 ~11 cobblestone 0 
setblock ~34 ~14 ~9 cobblestone 0  
fill ~34 ~14 ~11 ~34 ~16 ~11 stone 0  
fill ~11 ~15 ~20 ~11 ~19 ~20 stone 0  
fill ~11 ~15 ~21 ~11 ~23 ~21 stone 0  
fill ~11 ~15 ~22 ~11 ~15 ~20 stone 0  
fill ~11 ~15 ~24 ~19 ~15 ~24 stone 0  
fill ~12 ~15 ~19 ~12 ~14 ~19 stone 0  
fill ~12 ~15 ~20 ~13 ~15 ~20 mossy_cobblestone 0  
fill ~12 ~15 ~25 ~12 ~17 ~25 stone 0  
fill ~12 ~15 ~26 ~12 ~16 ~26 stone 0  
fill ~13 ~15 ~18 ~14 ~15 ~18 stone 0  
fill ~13 ~15 ~19 ~13 ~16 ~19 cobblestone 0  
fill ~13 ~15 ~27 ~13 ~17 ~27 stone 0  
fill ~14 ~15 ~17 ~14 ~16 ~17 cobblestone 0  
fill ~14 ~15 ~19 ~17 ~15 ~19 stone 0  
fill ~14 ~15 ~20 ~14 ~20 ~20 stone 0 
setblock ~14 ~15 ~22 cobblestone 0  
fill ~14 ~15 ~26 ~14 ~17 ~26 stone 0  
fill ~14 ~15 ~29 ~14 ~23 ~29 stone 0  
fill ~15 ~15 ~16 ~29 ~15 ~16 stone 0 
setblock ~15 ~15 ~18 cobblestone 0 
setblock ~15 ~15 ~21 cobblestone 0 
setblock ~16 ~15 ~20 stone 0  
fill ~16 ~15 ~25 ~17 ~15 ~25 stone 0  
fill ~16 ~15 ~27 ~17 ~15 ~27 stone 0  
fill ~16 ~15 ~29 ~16 ~17 ~29 stone 0 
setblock ~16 ~15 ~30 mossy_cobblestone 0 
setblock ~17 ~15 ~15 mossy_cobblestone 0  
fill ~17 ~15 ~18 ~18 ~15 ~18 stone 0 
setblock ~17 ~15 ~21 mossy_cobblestone 0  
fill ~17 ~15 ~22 ~27 ~15 ~22 stone 0  
fill ~17 ~15 ~26 ~17 ~19 ~26 stone 0  
fill ~17 ~15 ~28 ~26 ~15 ~28 stone 0  
fill ~17 ~15 ~30 ~17 ~23 ~30 stone 0  
fill ~17 ~15 ~31 ~25 ~15 ~31 stone 0  
fill ~18 ~15 ~14 ~28 ~15 ~14 stone 0 
setblock ~18 ~15 ~17 stone 0 
setblock ~18 ~15 ~19 cobblestone 0  
fill ~18 ~15 ~20 ~18 ~25 ~20 stone 0  
fill ~18 ~15 ~21 ~18 ~18 ~21 stone 0  
fill ~18 ~15 ~23 ~25 ~15 ~23 stone 0 
setblock ~18 ~15 ~25 cobblestone 0 
setblock ~18 ~15 ~27 mossy_cobblestone 0  
fill ~18 ~15 ~32 ~23 ~15 ~32 stone 0  
fill ~19 ~15 ~15 ~21 ~15 ~15 stone 0 
setblock ~19 ~15 ~18 cobblestone 0 
setblock ~19 ~15 ~20 mossy_cobblestone 0  
fill ~19 ~15 ~25 ~24 ~15 ~25 stone 0 
setblock ~19 ~15 ~29 mossy_cobblestone 0  
fill ~19 ~15 ~30 ~23 ~15 ~30 stone 0  
fill ~20 ~15 ~13 ~27 ~15 ~13 stone 0 
setblock ~20 ~15 ~17 cobblestone 0  
fill ~20 ~15 ~19 ~20 ~16 ~19 cobblestone 0  
fill ~20 ~15 ~20 ~24 ~15 ~20 stone 0 
setblock ~20 ~15 ~24 mossy_cobblestone 0  
fill ~20 ~15 ~26 ~21 ~15 ~26 stone 0  
fill ~20 ~15 ~27 ~27 ~15 ~27 stone 0  
fill ~21 ~15 ~17 ~22 ~15 ~17 stone 0 
setblock ~21 ~15 ~19 mossy_cobblestone 0  
fill ~21 ~15 ~21 ~21 ~16 ~21 mossy_cobblestone 0  
fill ~21 ~15 ~33 ~21 ~16 ~33 stone 0 
setblock ~22 ~15 ~15 mossy_cobblestone 0 
setblock ~22 ~15 ~18 cobblestone 0  
fill ~22 ~15 ~24 ~23 ~15 ~24 stone 0 
setblock ~22 ~15 ~26 cobblestone 0  
fill ~23 ~15 ~15 ~23 ~17 ~15 stone 0 
setblock ~23 ~15 ~17 mossy_cobblestone 0 
setblock ~23 ~15 ~21 cobblestone 0  
fill ~23 ~15 ~26 ~24 ~15 ~26 stone 0  
fill ~23 ~15 ~29 ~23 ~22 ~29 stone 0 
setblock ~24 ~15 ~15 cobblestone 0  
fill ~24 ~15 ~17 ~29 ~15 ~17 stone 0  
fill ~24 ~15 ~19 ~24 ~17 ~19 stone 0 
setblock ~24 ~15 ~21 mossy_cobblestone 0  
fill ~24 ~15 ~24 ~24 ~17 ~24 cobblestone 0  
fill ~24 ~15 ~29 ~25 ~15 ~29 cobblestone 0  
fill ~24 ~15 ~30 ~24 ~15 ~29 cobblestone 0  
fill ~25 ~15 ~15 ~28 ~15 ~15 stone 0 
setblock ~25 ~15 ~19 mossy_cobblestone 0 
setblock ~25 ~15 ~20 cobblestone 0  
fill ~25 ~15 ~21 ~27 ~15 ~21 stone 0  
fill ~25 ~15 ~24 ~28 ~15 ~24 stone 0  
fill ~25 ~15 ~25 ~25 ~15 ~26 mossy_cobblestone 0 
setblock ~25 ~15 ~30 mossy_cobblestone 0 
setblock ~26 ~15 ~8 cobblestone 0  
fill ~26 ~15 ~9 ~31 ~15 ~9 stone 0  
fill ~26 ~15 ~11 ~26 ~18 ~11 stone 0 
setblock ~26 ~15 ~12 mossy_cobblestone 0  
fill ~26 ~15 ~19 ~30 ~15 ~19 stone 0  
fill ~26 ~15 ~20 ~26 ~16 ~20 mossy_cobblestone 0  
fill ~26 ~15 ~25 ~27 ~15 ~25 stone 0  
fill ~26 ~15 ~26 ~26 ~17 ~26 stone 0  
fill ~26 ~15 ~29 ~26 ~21 ~29 stone 0  
fill ~27 ~15 ~7 ~27 ~16 ~7 stone 0  
fill ~27 ~15 ~8 ~27 ~15 ~7 stone 0 
setblock ~27 ~15 ~10 cobblestone 0  
fill ~27 ~15 ~12 ~27 ~18 ~12 stone 0 
setblock ~27 ~15 ~18 mossy_cobblestone 0 
setblock ~27 ~15 ~28 cobblestone 0  
fill ~28 ~15 ~6 ~31 ~15 ~6 stone 0  
fill ~28 ~15 ~8 ~29 ~15 ~8 cobblestone 0  
fill ~28 ~15 ~18 ~28 ~17 ~18 stone 0 
setblock ~28 ~15 ~20 stone 0 
setblock ~28 ~15 ~23 mossy_cobblestone 0  
fill ~29 ~15 ~10 ~29 ~16 ~10 stone 0 
setblock ~29 ~15 ~20 mossy_cobblestone 0 
setblock ~30 ~15 ~5 mossy_cobblestone 0  
fill ~30 ~15 ~8 ~32 ~15 ~8 stone 0 
setblock ~30 ~15 ~10 cobblestone 0  
fill ~30 ~15 ~11 ~30 ~23 ~11 stone 0 
setblock ~30 ~15 ~18 mossy_cobblestone 0  
fill ~31 ~15 ~7 ~31 ~19 ~7 stone 0  
fill ~31 ~15 ~10 ~34 ~15 ~10 stone 0  
fill ~31 ~15 ~12 ~34 ~15 ~12 stone 0 
setblock ~32 ~15 ~9 cobblestone 0 
setblock ~32 ~15 ~13 cobblestone 0 
setblock ~33 ~15 ~8 cobblestone 0  
fill ~34 ~15 ~9 ~34 ~16 ~9 stone 0 
setblock ~11 ~16 ~22 mossy_cobblestone 0  
fill ~11 ~16 ~24 ~20 ~16 ~24 stone 0  
fill ~11 ~16 ~25 ~11 ~17 ~25 stone 0  
fill ~11 ~16 ~26 ~11 ~17 ~26 stone 0 
setblock ~12 ~16 ~19 cobblestone 0  
fill ~12 ~16 ~20 ~15 ~16 ~20 stone 0 
setblock ~12 ~16 ~21 mossy_cobblestone 0  
fill ~12 ~16 ~23 ~12 ~19 ~23 stone 0  
fill ~13 ~16 ~17 ~13 ~17 ~17 stone 0   
fill ~13 ~16 ~18 ~17 ~16 ~18 stone 0  
fill ~13 ~16 ~28 ~13 ~20 ~28 stone 0 
setblock ~14 ~16 ~16 mossy_cobblestone 0  
fill ~14 ~16 ~19 ~15 ~16 ~19 stone 0 
setblock ~14 ~16 ~21 mossy_cobblestone 0  
fill ~14 ~16 ~22 ~14 ~22 ~22 stone 0 
setblock ~14 ~16 ~27 mossy_cobblestone 0  
fill ~15 ~16 ~16 ~19 ~16 ~16 stone 0 
setblock ~15 ~16 ~17 cobblestone 0  
fill ~15 ~16 ~21 ~15 ~19 ~21 stone 0 
setblock ~16 ~16 ~19 mossy_cobblestone 0 
setblock ~16 ~16 ~20 cobblestone 0 
setblock ~16 ~16 ~25 cobblestone 0  
fill ~16 ~16 ~27 ~22 ~16 ~27 stone 0  
fill ~16 ~16 ~30 ~16 ~17 ~30 stone 0 
setblock ~17 ~16 ~15 stone 0 
setblock ~17 ~16 ~21 cobblestone 0  
fill ~17 ~16 ~22 ~22 ~16 ~22 stone 0  
fill ~17 ~16 ~25 ~19 ~16 ~25 stone 0  
fill ~17 ~16 ~28 ~20 ~16 ~28 stone 0 
setblock ~17 ~16 ~31 mossy_cobblestone 0  
fill ~18 ~16 ~14 ~19 ~16 ~14 stone 0  
fill ~18 ~16 ~17 ~19 ~16 ~17 mossy_cobblestone 0  
fill ~18 ~16 ~18 ~18 ~16 ~17 mossy_cobblestone 0 
setblock ~18 ~16 ~19 stone 0  
fill ~18 ~16 ~23 ~18 ~19 ~23 stone 0  
fill ~18 ~16 ~31 ~21 ~16 ~31 stone 0  
fill ~18 ~16 ~32 ~19 ~16 ~32 stone 0  
fill ~19 ~16 ~15 ~25 ~16 ~15 stone 0  
fill ~19 ~16 ~18 ~19 ~17 ~18 stone 0  
fill ~19 ~16 ~20 ~24 ~16 ~20 stone 0 
setblock ~19 ~16 ~23 mossy_cobblestone 0 
setblock ~19 ~16 ~26 cobblestone 0  
fill ~19 ~16 ~29 ~19 ~17 ~29 stone 0  
fill ~19 ~16 ~30 ~19 ~27 ~30 stone 0 
setblock ~20 ~16 ~11 mossy_cobblestone 0  
fill ~20 ~16 ~12 ~20 ~20 ~12 stone 0  
fill ~20 ~16 ~13 ~21 ~16 ~13 stone 0 
setblock ~20 ~16 ~14 cobblestone 0  
fill ~20 ~16 ~16 ~20 ~18 ~16 cobblestone 0  
fill ~20 ~16 ~17 ~20 ~17 ~17 stone 0  
fill ~20 ~16 ~18 ~20 ~17 ~18 mossy_cobblestone 0  
fill ~20 ~16 ~23 ~24 ~16 ~23 stone 0 
setblock ~20 ~16 ~25 mossy_cobblestone 0  
fill ~20 ~16 ~26 ~21 ~16 ~26 stone 0 
setblock ~20 ~16 ~30 cobblestone 0 
setblock ~20 ~16 ~32 cobblestone 0  
fill ~20 ~16 ~33 ~20 ~31 ~33 stone 0  
fill ~21 ~16 ~14 ~28 ~16 ~14 stone 0 
setblock ~21 ~16 ~17 mossy_cobblestone 0  
fill ~21 ~16 ~19 ~21 ~21 ~19 stone 0 
setblock ~21 ~16 ~24 mossy_cobblestone 0  
fill ~21 ~16 ~25 ~27 ~16 ~25 stone 0 
setblock ~21 ~16 ~28 cobblestone 0  
fill ~21 ~16 ~30 ~21 ~23 ~30 stone 0  
fill ~21 ~16 ~32 ~23 ~16 ~32 stone 0 
setblock ~22 ~16 ~13 cobblestone 0  
fill ~22 ~16 ~16 ~24 ~16 ~16 stone 0  
fill ~22 ~16 ~17 ~25 ~16 ~17 stone 0  
fill ~22 ~16 ~18 ~22 ~29 ~18 stone 0 
setblock ~22 ~16 ~19 mossy_cobblestone 0  
fill ~22 ~16 ~24 ~22 ~20 ~24 stone 0 
setblock ~22 ~16 ~26 mossy_cobblestone 0  
fill ~22 ~16 ~28 ~22 ~18 ~28 stone 0 
setblock ~22 ~16 ~30 mossy_cobblestone 0 
setblock ~22 ~16 ~31 cobblestone 0 
setblock ~22 ~16 ~33 cobblestone 0  
fill ~23 ~16 ~12 ~28 ~16 ~12 stone 0 
setblock ~23 ~16 ~18 cobblestone 0  
fill ~23 ~16 ~21 ~23 ~19 ~21 stone 0 
setblock ~23 ~16 ~22 mossy_cobblestone 0 
setblock ~23 ~16 ~24 mossy_cobblestone 0  
fill ~23 ~16 ~26 ~27 ~16 ~26 stone 0  
fill ~23 ~16 ~27 ~24 ~16 ~27 mossy_cobblestone 0  
fill ~23 ~16 ~28 ~23 ~16 ~27 mossy_cobblestone 0  
fill ~23 ~16 ~30 ~26 ~16 ~30 stone 0 
setblock ~24 ~16 ~21 cobblestone 0  
fill ~24 ~16 ~22 ~27 ~16 ~22 stone 0 
setblock ~24 ~16 ~28 stone 0 
setblock ~24 ~16 ~29 cobblestone 0  
fill ~24 ~16 ~31 ~25 ~16 ~31 stone 0  
fill ~25 ~16 ~13 ~27 ~16 ~13 stone 0  
fill ~25 ~16 ~16 ~25 ~17 ~16 mossy_cobblestone 0 
setblock ~25 ~16 ~18 mossy_cobblestone 0  
fill ~25 ~16 ~19 ~28 ~16 ~19 stone 0 
setblock ~25 ~16 ~20 mossy_cobblestone 0  
fill ~25 ~16 ~21 ~25 ~19 ~21 stone 0 
setblock ~25 ~16 ~23 mossy_cobblestone 0  
fill ~25 ~16 ~24 ~28 ~16 ~24 stone 0  
fill ~25 ~16 ~27 ~28 ~16 ~27 stone 0 
setblock ~25 ~16 ~29 mossy_cobblestone 0 
setblock ~26 ~16 ~7 mossy_cobblestone 0  
fill ~26 ~16 ~8 ~26 ~16 ~14 stone 0 
setblock ~26 ~16 ~15 mossy_cobblestone 0  
fill ~26 ~16 ~16 ~29 ~16 ~16 stone 0 
setblock ~26 ~16 ~17 cobblestone 0 
setblock ~26 ~16 ~21 mossy_cobblestone 0  
fill ~26 ~16 ~23 ~26 ~23 ~23 stone 0 
setblock ~26 ~16 ~28 cobblestone 0 
setblock ~27 ~16 ~8 mossy_cobblestone 0  
fill ~27 ~16 ~9 ~34 ~16 ~9 stone 0  
fill ~27 ~16 ~10 ~29 ~16 ~10 stone 0  
fill ~27 ~16 ~11 ~27 ~22 ~11 stone 0  
fill ~27 ~16 ~15 ~28 ~16 ~15 stone 0  
fill ~27 ~16 ~17 ~30 ~16 ~17 stone 0  
fill ~27 ~16 ~18 ~27 ~16 ~9 stone 0  
fill ~27 ~16 ~21 ~27 ~18 ~21 stone 0  
fill ~27 ~16 ~28 ~27 ~25 ~28 stone 0  
fill ~28 ~16 ~6 ~31 ~16 ~6 stone 0  
fill ~28 ~16 ~8 ~30 ~16 ~8 stone 0 
setblock ~28 ~16 ~13 cobblestone 0 
setblock ~28 ~16 ~20 mossy_cobblestone 0  
fill ~28 ~16 ~23 ~28 ~20 ~23 stone 0  
fill ~29 ~16 ~5 ~30 ~16 ~5 stone 0  
fill ~29 ~16 ~7 ~29 ~32 ~7 stone 0 
setblock ~29 ~16 ~15 mossy_cobblestone 0 
setblock ~29 ~16 ~19 mossy_cobblestone 0  
fill ~29 ~16 ~20 ~30 ~16 ~20 stone 0  
fill ~30 ~16 ~10 ~30 ~17 ~10 mossy_cobblestone 0  
fill ~30 ~16 ~18 ~30 ~25 ~18 stone 0  
fill ~31 ~16 ~8 ~32 ~16 ~8 cobblestone 0  
fill ~31 ~16 ~10 ~33 ~16 ~10 stone 0  
fill ~31 ~16 ~12 ~32 ~16 ~12 stone 0 
setblock ~32 ~16 ~11 cobblestone 0  
fill ~32 ~16 ~13 ~34 ~16 ~13 stone 0 
setblock ~33 ~16 ~8 stone 0  
fill ~33 ~16 ~11 ~33 ~18 ~11 stone 0 
setblock ~33 ~16 ~12 cobblestone 0 
setblock ~34 ~16 ~10 cobblestone 0  
fill ~34 ~16 ~12 ~34 ~29 ~12 stone 0 
setblock ~35 ~16 ~11 cobblestone 0 
setblock ~35 ~16 ~12 mossy_cobblestone 0 
setblock ~9 ~17 ~18 cobblestone 0  
fill ~9 ~17 ~19 ~9 ~19 ~19 stone 0  
fill ~9 ~17 ~20 ~9 ~18 ~20 stone 0  
fill ~10 ~17 ~22 ~14 ~17 ~22 stone 0  
fill ~10 ~17 ~24 ~18 ~17 ~24 stone 0  
fill ~11 ~17 ~17 ~22 ~17 ~17 stone 0  
fill ~11 ~17 ~18 ~12 ~17 ~18 stone 0  
fill ~12 ~17 ~16 ~15 ~17 ~16 stone 0  
fill ~12 ~17 ~19 ~13 ~17 ~19 stone 0  
fill ~12 ~17 ~20 ~29 ~17 ~20 stone 0  
fill ~12 ~17 ~21 ~12 ~17 ~16 stone 0 
setblock ~12 ~17 ~26 cobblestone 0  
fill ~12 ~17 ~27 ~12 ~25 ~27 stone 0 
setblock ~13 ~17 ~18 cobblestone 0 
setblock ~13 ~17 ~29 stone 0  
fill ~14 ~17 ~18 ~19 ~17 ~18 stone 0 
setblock ~14 ~17 ~19 mossy_cobblestone 0  
fill ~14 ~17 ~21 ~14 ~18 ~21 stone 0 
setblock ~14 ~17 ~23 cobblestone 0 
setblock ~14 ~17 ~27 cobblestone 0  
fill ~15 ~17 ~19 ~17 ~17 ~19 stone 0 
setblock ~15 ~17 ~22 mossy_cobblestone 0  
fill ~15 ~17 ~26 ~15 ~17 ~27 mossy_cobblestone 0  
fill ~15 ~17 ~30 ~15 ~18 ~30 stone 0  
fill ~16 ~17 ~15 ~16 ~20 ~15 stone 0 
setblock ~16 ~17 ~16 mossy_cobblestone 0 
setblock ~16 ~17 ~23 cobblestone 0  
fill ~16 ~17 ~25 ~21 ~17 ~25 stone 0  
fill ~16 ~17 ~27 ~27 ~17 ~27 stone 0  
fill ~17 ~17 ~15 ~17 ~17 ~16 cobblestone 0 
setblock ~17 ~17 ~21 mossy_cobblestone 0 
setblock ~17 ~17 ~22 cobblestone 0  
fill ~17 ~17 ~28 ~18 ~17 ~28 stone 0  
fill ~17 ~17 ~31 ~18 ~17 ~31 stone 0  
fill ~18 ~17 ~14 ~18 ~18 ~14 stone 0  
fill ~18 ~17 ~16 ~18 ~25 ~16 stone 0 
setblock ~18 ~17 ~19 cobblestone 0 
setblock ~18 ~17 ~22 mossy_cobblestone 0 
setblock ~18 ~17 ~26 cobblestone 0 
setblock ~18 ~17 ~29 cobblestone 0  
fill ~18 ~17 ~32 ~20 ~17 ~32 stone 0  
fill ~19 ~17 ~10 ~19 ~17 ~11 stone 0  
fill ~19 ~17 ~14 ~19 ~18 ~14 mossy_cobblestone 0  
fill ~19 ~17 ~15 ~19 ~14 ~15 stone 0  
fill ~19 ~17 ~22 ~19 ~24 ~22 stone 0  
fill ~19 ~17 ~23 ~19 ~21 ~23 stone 0 
setblock ~19 ~17 ~24 mossy_cobblestone 0 
setblock ~19 ~17 ~26 stone 0 
setblock ~19 ~17 ~28 cobblestone 0 
setblock ~19 ~17 ~31 mossy_cobblestone 0  
fill ~19 ~17 ~33 ~19 ~35 ~33 stone 0 
setblock ~20 ~17 ~11 stone 0  
fill ~20 ~17 ~13 ~29 ~17 ~13 stone 0  
fill ~20 ~17 ~14 ~24 ~17 ~14 stone 0 
setblock ~20 ~17 ~15 cobblestone 0  
fill ~20 ~17 ~19 ~20 ~20 ~19 stone 0 
setblock ~20 ~17 ~22 cobblestone 0 
setblock ~20 ~17 ~23 mossy_cobblestone 0  
fill ~20 ~17 ~24 ~23 ~17 ~24 stone 0  
fill ~20 ~17 ~26 ~20 ~18 ~26 mossy_cobblestone 0  
fill ~20 ~17 ~28 ~23 ~17 ~28 stone 0 
setblock ~20 ~17 ~30 stone 0 
setblock ~20 ~17 ~31 cobblestone 0  
fill ~21 ~17 ~12 ~24 ~17 ~12 stone 0 
setblock ~21 ~17 ~15 mossy_cobblestone 0  
fill ~21 ~17 ~21 ~21 ~22 ~21 stone 0  
fill ~21 ~17 ~23 ~28 ~17 ~23 stone 0  
fill ~21 ~17 ~26 ~26 ~17 ~26 stone 0  
fill ~21 ~17 ~31 ~28 ~17 ~31 stone 0  
fill ~21 ~17 ~32 ~21 ~17 ~33 cobblestone 0 
setblock ~22 ~17 ~15 stone 0 
setblock ~22 ~17 ~16 cobblestone 0  
fill ~22 ~17 ~19 ~22 ~20 ~19 stone 0  
fill ~22 ~17 ~22 ~28 ~17 ~22 stone 0 
setblock ~22 ~17 ~25 cobblestone 0  
fill ~22 ~17 ~30 ~25 ~17 ~30 stone 0  
fill ~22 ~17 ~32 ~24 ~17 ~32 stone 0  
fill ~22 ~17 ~33 ~25 ~17 ~33 stone 0  
fill ~23 ~17 ~11 ~28 ~17 ~11 stone 0  
fill ~23 ~17 ~16 ~24 ~17 ~16 stone 0 
setblock ~23 ~17 ~17 cobblestone 0  
fill ~23 ~17 ~18 ~23 ~21 ~18 stone 0 
setblock ~24 ~17 ~10 mossy_cobblestone 0  
fill ~24 ~17 ~15 ~27 ~17 ~15 stone 0  
fill ~24 ~17 ~17 ~24 ~26 ~17 stone 0 
setblock ~24 ~17 ~18 cobblestone 0  
fill ~24 ~17 ~21 ~24 ~24 ~21 stone 0  
fill ~24 ~17 ~25 ~25 ~17 ~25 stone 0  
fill ~24 ~17 ~28 ~24 ~18 ~28 cobblestone 0  
fill ~24 ~17 ~29 ~28 ~17 ~29 stone 0  
fill ~25 ~17 ~8 ~26 ~17 ~8 mossy_cobblestone 0 
setblock ~25 ~17 ~12 cobblestone 0 
setblock ~25 ~17 ~14 cobblestone 0 
setblock ~25 ~17 ~17 mossy_cobblestone 0  
fill ~25 ~17 ~18 ~25 ~22 ~18 stone 0  
fill ~25 ~17 ~19 ~25 ~18 ~19 stone 0  
fill ~25 ~17 ~24 ~27 ~17 ~24 stone 0  
fill ~25 ~17 ~32 ~25 ~18 ~32 cobblestone 0 
setblock ~26 ~17 ~7 stone 0  
fill ~26 ~17 ~9 ~30 ~17 ~9 stone 0  
fill ~26 ~17 ~10 ~28 ~17 ~10 stone 0  
fill ~26 ~17 ~12 ~26 ~19 ~12 stone 0 
setblock ~26 ~17 ~14 mossy_cobblestone 0  
fill ~26 ~17 ~16 ~29 ~17 ~16 stone 0  
fill ~26 ~17 ~17 ~28 ~17 ~17 stone 0 
setblock ~26 ~17 ~19 mossy_cobblestone 0  
fill ~26 ~17 ~21 ~26 ~22 ~21 stone 0 
setblock ~26 ~17 ~25 mossy_cobblestone 0  
fill ~26 ~17 ~28 ~26 ~29 ~28 stone 0 
setblock ~26 ~17 ~30 cobblestone 0  
fill ~26 ~17 ~32 ~27 ~17 ~32 stone 0 
setblock ~27 ~17 ~6 mossy_cobblestone 0 
setblock ~27 ~17 ~7 cobblestone 0  
fill ~27 ~17 ~8 ~29 ~17 ~8 stone 0  
fill ~27 ~17 ~14 ~27 ~22 ~14 stone 0 
setblock ~27 ~17 ~18 mossy_cobblestone 0  
fill ~27 ~17 ~19 ~30 ~17 ~19 stone 0  
fill ~27 ~17 ~25 ~28 ~17 ~25 stone 0 
setblock ~27 ~17 ~26 mossy_cobblestone 0  
fill ~27 ~17 ~30 ~27 ~18 ~30 stone 0  
fill ~28 ~17 ~6 ~28 ~14 ~6 stone 0  
fill ~28 ~17 ~7 ~28 ~25 ~7 stone 0 
setblock ~28 ~17 ~12 stone 0  
fill ~28 ~17 ~14 ~28 ~17 ~15 cobblestone 0 
setblock ~28 ~17 ~21 cobblestone 0 
setblock ~28 ~17 ~24 mossy_cobblestone 0  
fill ~28 ~17 ~26 ~28 ~17 ~27 cobblestone 0  
fill ~28 ~17 ~28 ~28 ~25 ~28 stone 0  
fill ~29 ~17 ~5 ~29 ~17 ~6 mossy_cobblestone 0  
fill ~29 ~17 ~10 ~29 ~17 ~11 cobblestone 0 
setblock ~29 ~17 ~12 mossy_cobblestone 0  
fill ~29 ~17 ~15 ~29 ~33 ~15 stone 0 
setblock ~29 ~17 ~17 mossy_cobblestone 0  
fill ~29 ~17 ~30 ~29 ~22 ~30 stone 0  
fill ~30 ~17 ~5 ~30 ~27 ~5 stone 0  
fill ~30 ~17 ~6 ~30 ~20 ~6 stone 0 
setblock ~30 ~17 ~8 cobblestone 0  
fill ~30 ~17 ~12 ~35 ~17 ~12 stone 0  
fill ~30 ~17 ~17 ~31 ~17 ~17 stone 0 
setblock ~30 ~17 ~20 mossy_cobblestone 0  
fill ~31 ~17 ~8 ~31 ~22 ~8 stone 0 
setblock ~31 ~17 ~9 mossy_cobblestone 0  
fill ~31 ~17 ~10 ~34 ~17 ~10 stone 0 
setblock ~31 ~17 ~13 mossy_cobblestone 0  
fill ~31 ~17 ~18 ~31 ~19 ~18 stone 0 
setblock ~32 ~17 ~7 mossy_cobblestone 0  
fill ~32 ~17 ~8 ~33 ~17 ~8 cobblestone 0 
setblock ~32 ~17 ~9 stone 0  
fill ~32 ~17 ~11 ~32 ~22 ~11 stone 0  
fill ~32 ~17 ~13 ~34 ~17 ~13 stone 0  
fill ~32 ~17 ~14 ~32 ~18 ~14 stone 0  
fill ~34 ~17 ~9 ~34 ~18 ~9 cobblestone 0 
setblock ~34 ~17 ~11 mossy_cobblestone 0  
fill ~35 ~17 ~11 ~35 ~23 ~11 stone 0  
fill ~8 ~18 ~20 ~8 ~27 ~20 stone 0  
fill ~8 ~18 ~21 ~8 ~22 ~21 stone 0  
fill ~9 ~18 ~17 ~9 ~19 ~17 stone 0  
fill ~9 ~18 ~18 ~10 ~18 ~18 stone 0 
setblock ~10 ~18 ~19 mossy_cobblestone 0  
fill ~10 ~18 ~22 ~10 ~22 ~22 stone 0  
fill ~10 ~18 ~23 ~10 ~31 ~23 stone 0  
fill ~10 ~18 ~24 ~11 ~18 ~24 stone 0  
fill ~11 ~18 ~17 ~12 ~18 ~17 stone 0 
setblock ~11 ~18 ~18 mossy_cobblestone 0  
fill ~11 ~18 ~19 ~16 ~18 ~19 stone 0 
setblock ~11 ~18 ~22 cobblestone 0  
fill ~11 ~18 ~25 ~12 ~18 ~25 mossy_cobblestone 0  
fill ~11 ~18 ~26 ~11 ~18 ~25 mossy_cobblestone 0  
fill ~11 ~18 ~27 ~11 ~24 ~27 stone 0  
fill ~12 ~18 ~16 ~12 ~27 ~16 stone 0  
fill ~12 ~18 ~18 ~13 ~18 ~18 stone 0 
setblock ~12 ~18 ~20 cobblestone 0  
fill ~12 ~18 ~21 ~13 ~18 ~21 mossy_cobblestone 0 
setblock ~12 ~18 ~24 cobblestone 0  
fill ~12 ~18 ~26 ~12 ~20 ~26 stone 0  
fill ~12 ~18 ~28 ~12 ~23 ~28 stone 0 
setblock ~13 ~18 ~16 mossy_cobblestone 0  
fill ~13 ~18 ~17 ~14 ~18 ~17 cobblestone 0 
setblock ~13 ~18 ~20 mossy_cobblestone 0  
fill ~13 ~18 ~22 ~13 ~19 ~22 mossy_cobblestone 0  
fill ~13 ~18 ~24 ~15 ~18 ~24 stone 0  
fill ~13 ~18 ~27 ~15 ~18 ~27 mossy_cobblestone 0 
setblock ~13 ~18 ~29 cobblestone 0  
fill ~14 ~18 ~15 ~14 ~20 ~15 stone 0  
fill ~14 ~18 ~16 ~16 ~18 ~16 stone 0  
fill ~14 ~18 ~18 ~14 ~19 ~18 cobblestone 0  
fill ~14 ~18 ~23 ~14 ~20 ~23 stone 0 
setblock ~14 ~18 ~26 cobblestone 0 
setblock ~14 ~18 ~28 cobblestone 0  
fill ~14 ~18 ~30 ~14 ~19 ~30 stone 0 
setblock ~15 ~18 ~15 mossy_cobblestone 0  
fill ~15 ~18 ~17 ~15 ~19 ~17 stone 0  
fill ~15 ~18 ~18 ~15 ~18 ~16 stone 0  
fill ~15 ~18 ~22 ~15 ~19 ~22 cobblestone 0  
fill ~15 ~18 ~23 ~15 ~18 ~22 cobblestone 0  
fill ~15 ~18 ~26 ~15 ~25 ~26 stone 0  
fill ~16 ~18 ~20 ~16 ~25 ~20 stone 0  
fill ~16 ~18 ~23 ~16 ~25 ~23 stone 0  
fill ~16 ~18 ~24 ~16 ~19 ~24 cobblestone 0  
fill ~16 ~18 ~25 ~16 ~18 ~24 cobblestone 0 
setblock ~16 ~18 ~26 mossy_cobblestone 0  
fill ~16 ~18 ~27 ~17 ~18 ~27 stone 0  
fill ~16 ~18 ~29 ~17 ~18 ~29 mossy_cobblestone 0  
fill ~16 ~18 ~30 ~16 ~19 ~30 cobblestone 0  
fill ~17 ~18 ~15 ~17 ~19 ~15 stone 0 
setblock ~17 ~18 ~16 mossy_cobblestone 0  
fill ~17 ~18 ~18 ~18 ~18 ~18 stone 0 
setblock ~17 ~18 ~19 cobblestone 0  
fill ~17 ~18 ~21 ~17 ~19 ~21 cobblestone 0  
fill ~17 ~18 ~22 ~23 ~18 ~22 stone 0  
fill ~17 ~18 ~24 ~17 ~22 ~24 stone 0  
fill ~17 ~18 ~25 ~20 ~18 ~25 stone 0  
fill ~17 ~18 ~28 ~23 ~18 ~28 stone 0  
fill ~17 ~18 ~31 ~19 ~18 ~31 stone 0  
fill ~18 ~18 ~12 ~20 ~18 ~12 stone 0  
fill ~18 ~18 ~17 ~19 ~18 ~17 stone 0  
fill ~18 ~18 ~19 ~18 ~22 ~19 stone 0 
setblock ~18 ~18 ~24 mossy_cobblestone 0  
fill ~18 ~18 ~26 ~18 ~24 ~26 stone 0  
fill ~18 ~18 ~27 ~18 ~19 ~27 cobblestone 0 
setblock ~18 ~18 ~29 stone 0  
fill ~18 ~18 ~32 ~23 ~18 ~32 stone 0  
fill ~19 ~18 ~10 ~19 ~18 ~11 cobblestone 0 
setblock ~19 ~18 ~13 cobblestone 0 
setblock ~19 ~18 ~15 mossy_cobblestone 0 
setblock ~19 ~18 ~18 mossy_cobblestone 0 
setblock ~19 ~18 ~19 cobblestone 0  
fill ~19 ~18 ~20 ~30 ~18 ~20 stone 0  
fill ~19 ~18 ~24 ~22 ~18 ~24 stone 0 
setblock ~19 ~18 ~26 cobblestone 0 
setblock ~19 ~18 ~29 cobblestone 0  
fill ~20 ~18 ~10 ~21 ~18 ~10 stone 0 
setblock ~20 ~18 ~11 mossy_cobblestone 0  
fill ~20 ~18 ~13 ~20 ~19 ~13 stone 0  
fill ~20 ~18 ~14 ~23 ~18 ~14 stone 0  
fill ~20 ~18 ~15 ~21 ~18 ~15 stone 0 
setblock ~20 ~18 ~17 mossy_cobblestone 0  
fill ~20 ~18 ~18 ~20 ~19 ~18 stone 0  
fill ~20 ~18 ~23 ~21 ~18 ~23 stone 0 
setblock ~20 ~18 ~27 cobblestone 0  
fill ~20 ~18 ~30 ~20 ~18 ~31 mossy_cobblestone 0 
setblock ~20 ~18 ~34 stone 0  
fill ~21 ~18 ~11 ~21 ~18 ~12 cobblestone 0  
fill ~21 ~18 ~13 ~21 ~19 ~13 mossy_cobblestone 0  
fill ~21 ~18 ~17 ~27 ~18 ~17 stone 0  
fill ~21 ~18 ~25 ~22 ~18 ~25 mossy_cobblestone 0  
fill ~21 ~18 ~26 ~21 ~20 ~26 stone 0  
fill ~21 ~18 ~27 ~27 ~18 ~27 stone 0 
setblock ~21 ~18 ~29 mossy_cobblestone 0  
fill ~21 ~18 ~31 ~28 ~18 ~31 stone 0 
setblock ~21 ~18 ~33 mossy_cobblestone 0  
fill ~22 ~18 ~11 ~27 ~18 ~11 stone 0  
fill ~22 ~18 ~12 ~23 ~18 ~12 stone 0  
fill ~22 ~18 ~13 ~22 ~21 ~13 stone 0 
setblock ~22 ~18 ~15 cobblestone 0  
fill ~22 ~18 ~16 ~29 ~18 ~16 stone 0 
setblock ~22 ~18 ~23 cobblestone 0  
fill ~22 ~18 ~26 ~22 ~19 ~26 cobblestone 0  
fill ~22 ~18 ~30 ~25 ~18 ~30 stone 0  
fill ~22 ~18 ~33 ~25 ~18 ~33 stone 0 
setblock ~23 ~18 ~15 mossy_cobblestone 0  
fill ~23 ~18 ~23 ~28 ~18 ~23 stone 0  
fill ~23 ~18 ~24 ~24 ~18 ~24 mossy_cobblestone 0  
fill ~23 ~18 ~26 ~23 ~23 ~26 stone 0  
fill ~24 ~18 ~10 ~25 ~18 ~10 stone 0  
fill ~24 ~18 ~12 ~25 ~18 ~12 mossy_cobblestone 0  
fill ~24 ~18 ~14 ~25 ~18 ~14 mossy_cobblestone 0  
fill ~24 ~18 ~15 ~25 ~18 ~15 stone 0  
fill ~24 ~18 ~18 ~24 ~22 ~18 stone 0 
setblock ~24 ~18 ~19 cobblestone 0 
setblock ~24 ~18 ~22 cobblestone 0  
fill ~24 ~18 ~25 ~27 ~18 ~25 stone 0  
fill ~24 ~18 ~26 ~26 ~18 ~26 cobblestone 0  
fill ~24 ~18 ~29 ~29 ~18 ~29 stone 0 
setblock ~24 ~18 ~32 mossy_cobblestone 0  
fill ~25 ~18 ~8 ~25 ~19 ~8 stone 0  
fill ~25 ~18 ~9 ~26 ~18 ~9 stone 0  
fill ~25 ~18 ~13 ~31 ~18 ~13 stone 0  
fill ~25 ~18 ~22 ~29 ~18 ~22 stone 0  
fill ~25 ~18 ~24 ~28 ~18 ~24 stone 0 
setblock ~26 ~18 ~7 cobblestone 0 
setblock ~26 ~18 ~8 mossy_cobblestone 0 
setblock ~26 ~18 ~10 mossy_cobblestone 0  
fill ~26 ~18 ~14 ~26 ~23 ~14 stone 0 
setblock ~26 ~18 ~15 cobblestone 0 
setblock ~26 ~18 ~18 mossy_cobblestone 0 
setblock ~26 ~18 ~19 cobblestone 0 
setblock ~26 ~18 ~30 mossy_cobblestone 0  
fill ~26 ~18 ~32 ~28 ~18 ~32 stone 0 
setblock ~26 ~18 ~33 mossy_cobblestone 0  
fill ~27 ~18 ~6 ~27 ~21 ~6 stone 0  
fill ~27 ~18 ~7 ~27 ~21 ~7 stone 0  
fill ~27 ~18 ~8 ~28 ~18 ~8 stone 0  
fill ~27 ~18 ~9 ~27 ~19 ~9 cobblestone 0  
fill ~27 ~18 ~10 ~27 ~18 ~9 cobblestone 0  
fill ~27 ~18 ~15 ~27 ~22 ~15 stone 0  
fill ~27 ~18 ~18 ~27 ~20 ~18 stone 0  
fill ~27 ~18 ~19 ~27 ~19 ~19 stone 0  
fill ~27 ~18 ~26 ~29 ~18 ~26 stone 0  
fill ~28 ~18 ~5 ~30 ~18 ~5 stone 0  
fill ~28 ~18 ~6 ~28 ~19 ~6 cobblestone 0  
fill ~28 ~18 ~9 ~31 ~18 ~9 stone 0  
fill ~28 ~18 ~10 ~34 ~18 ~10 stone 0  
fill ~28 ~18 ~11 ~28 ~18 ~12 mossy_cobblestone 0  
fill ~28 ~18 ~14 ~32 ~18 ~14 stone 0 
setblock ~28 ~18 ~15 cobblestone 0  
fill ~28 ~18 ~17 ~28 ~18 ~19 cobblestone 0 
setblock ~28 ~18 ~21 stone 0  
fill ~28 ~18 ~25 ~28 ~19 ~25 cobblestone 0 
setblock ~28 ~18 ~27 cobblestone 0  
fill ~28 ~18 ~30 ~28 ~24 ~30 stone 0  
fill ~29 ~18 ~6 ~29 ~19 ~6 stone 0 
setblock ~29 ~18 ~8 cobblestone 0  
fill ~29 ~18 ~11 ~29 ~26 ~11 stone 0  
fill ~29 ~18 ~12 ~35 ~18 ~12 stone 0  
fill ~29 ~18 ~17 ~31 ~18 ~17 stone 0 
setblock ~29 ~18 ~18 cobblestone 0  
fill ~29 ~18 ~19 ~29 ~24 ~19 stone 0 
setblock ~29 ~18 ~21 cobblestone 0 
setblock ~29 ~18 ~24 cobblestone 0 
setblock ~29 ~18 ~28 mossy_cobblestone 0  
fill ~29 ~18 ~31 ~29 ~19 ~31 mossy_cobblestone 0  
fill ~30 ~18 ~8 ~30 ~19 ~8 stone 0  
fill ~30 ~18 ~15 ~30 ~21 ~15 stone 0  
fill ~30 ~18 ~30 ~30 ~33 ~30 stone 0  
fill ~31 ~18 ~19 ~31 ~19 ~19 stone 0  
fill ~32 ~18 ~7 ~32 ~24 ~7 stone 0  
fill ~32 ~18 ~8 ~32 ~18 ~7 stone 0 
setblock ~32 ~18 ~9 mossy_cobblestone 0 
setblock ~32 ~18 ~13 cobblestone 0 
setblock ~33 ~18 ~8 cobblestone 0  
fill ~33 ~18 ~13 ~33 ~25 ~13 stone 0  
fill ~34 ~18 ~11 ~34 ~19 ~11 stone 0  
fill ~34 ~18 ~13 ~34 ~19 ~13 mossy_cobblestone 0  
fill ~35 ~18 ~13 ~35 ~20 ~13 stone 0 
setblock ~8 ~19 ~19 stone 0  
fill ~9 ~19 ~16 ~9 ~35 ~16 stone 0  
fill ~9 ~19 ~18 ~11 ~19 ~18 stone 0 
setblock ~9 ~19 ~20 cobblestone 0 
setblock ~9 ~19 ~21 mossy_cobblestone 0  
fill ~10 ~19 ~17 ~22 ~19 ~17 stone 0  
fill ~10 ~19 ~19 ~24 ~19 ~19 stone 0  
fill ~10 ~19 ~20 ~10 ~20 ~20 stone 0  
fill ~10 ~19 ~21 ~10 ~27 ~21 stone 0  
fill ~10 ~19 ~24 ~13 ~19 ~24 stone 0  
fill ~10 ~19 ~25 ~11 ~19 ~25 mossy_cobblestone 0  
fill ~11 ~19 ~16 ~11 ~20 ~16 stone 0  
fill ~11 ~19 ~22 ~11 ~23 ~22 stone 0  
fill ~11 ~19 ~26 ~11 ~23 ~26 stone 0 
setblock ~12 ~19 ~18 mossy_cobblestone 0  
fill ~12 ~19 ~20 ~16 ~19 ~20 stone 0  
fill ~12 ~19 ~21 ~13 ~19 ~21 stone 0  
fill ~12 ~19 ~25 ~12 ~22 ~25 stone 0  
fill ~13 ~19 ~16 ~13 ~20 ~16 cobblestone 0  
fill ~13 ~19 ~18 ~13 ~20 ~18 cobblestone 0 
setblock ~13 ~19 ~27 cobblestone 0  
fill ~13 ~19 ~29 ~13 ~29 ~29 stone 0 
setblock ~14 ~19 ~14 mossy_cobblestone 0  
fill ~14 ~19 ~16 ~20 ~19 ~16 stone 0 
setblock ~14 ~19 ~21 cobblestone 0 
setblock ~14 ~19 ~24 mossy_cobblestone 0  
fill ~14 ~19 ~26 ~14 ~21 ~26 stone 0  
fill ~14 ~19 ~27 ~16 ~19 ~27 stone 0  
fill ~14 ~19 ~28 ~14 ~19 ~25 stone 0 
setblock ~15 ~19 ~15 stone 0 
setblock ~15 ~19 ~18 cobblestone 0  
fill ~15 ~19 ~23 ~15 ~20 ~23 stone 0  
fill ~15 ~19 ~24 ~15 ~26 ~24 stone 0  
fill ~15 ~19 ~25 ~15 ~20 ~25 mossy_cobblestone 0 
setblock ~15 ~19 ~29 cobblestone 0  
fill ~15 ~19 ~30 ~15 ~20 ~30 mossy_cobblestone 0  
fill ~15 ~19 ~31 ~15 ~22 ~31 stone 0  
fill ~16 ~19 ~14 ~17 ~19 ~14 stone 0  
fill ~16 ~19 ~25 ~24 ~19 ~25 stone 0  
fill ~16 ~19 ~26 ~16 ~25 ~26 stone 0  
fill ~16 ~19 ~29 ~17 ~19 ~29 stone 0  
fill ~16 ~19 ~31 ~17 ~19 ~31 mossy_cobblestone 0  
fill ~17 ~19 ~13 ~20 ~19 ~13 stone 0  
fill ~17 ~19 ~18 ~31 ~19 ~18 stone 0 
setblock ~17 ~19 ~20 cobblestone 0 
setblock ~17 ~19 ~22 cobblestone 0 
setblock ~17 ~19 ~27 cobblestone 0  
fill ~17 ~19 ~28 ~21 ~19 ~28 stone 0  
fill ~18 ~19 ~10 ~20 ~19 ~10 stone 0  
fill ~18 ~19 ~11 ~21 ~19 ~11 stone 0  
fill ~18 ~19 ~12 ~21 ~19 ~12 stone 0 
setblock ~18 ~19 ~14 mossy_cobblestone 0 
setblock ~18 ~19 ~15 cobblestone 0 
setblock ~18 ~19 ~21 cobblestone 0  
fill ~18 ~19 ~22 ~18 ~20 ~22 stone 0  
fill ~18 ~19 ~24 ~19 ~19 ~24 stone 0  
fill ~18 ~19 ~29 ~18 ~20 ~29 mossy_cobblestone 0  
fill ~18 ~19 ~30 ~18 ~19 ~29 mossy_cobblestone 0  
fill ~18 ~19 ~31 ~19 ~19 ~31 stone 0  
fill ~18 ~19 ~32 ~20 ~19 ~32 stone 0  
fill ~19 ~19 ~14 ~24 ~19 ~14 stone 0  
fill ~19 ~19 ~15 ~24 ~19 ~15 stone 0  
fill ~19 ~19 ~20 ~19 ~20 ~20 mossy_cobblestone 0  
fill ~19 ~19 ~21 ~19 ~19 ~20 mossy_cobblestone 0  
fill ~19 ~19 ~26 ~21 ~19 ~26 stone 0  
fill ~19 ~19 ~29 ~19 ~21 ~29 stone 0  
fill ~20 ~19 ~20 ~28 ~19 ~20 stone 0  
fill ~20 ~19 ~22 ~20 ~20 ~22 stone 0  
fill ~20 ~19 ~23 ~29 ~19 ~23 stone 0 
setblock ~20 ~19 ~24 mossy_cobblestone 0 
setblock ~20 ~19 ~27 stone 0  
fill ~20 ~19 ~30 ~20 ~26 ~30 stone 0 
setblock ~20 ~19 ~31 cobblestone 0 
setblock ~20 ~19 ~34 mossy_cobblestone 0  
fill ~21 ~19 ~10 ~21 ~20 ~10 cobblestone 0  
fill ~21 ~19 ~16 ~22 ~19 ~16 mossy_cobblestone 0 
setblock ~21 ~19 ~24 cobblestone 0 
setblock ~21 ~19 ~27 cobblestone 0  
fill ~21 ~19 ~29 ~21 ~20 ~29 stone 0  
fill ~21 ~19 ~31 ~23 ~19 ~31 stone 0 
setblock ~21 ~19 ~32 mossy_cobblestone 0  
fill ~21 ~19 ~33 ~26 ~19 ~33 stone 0  
fill ~22 ~19 ~11 ~23 ~19 ~11 mossy_cobblestone 0 
setblock ~22 ~19 ~12 cobblestone 0 
setblock ~22 ~19 ~21 cobblestone 0 
setblock ~22 ~19 ~22 mossy_cobblestone 0  
fill ~22 ~19 ~27 ~22 ~19 ~28 mossy_cobblestone 0  
fill ~22 ~19 ~30 ~22 ~20 ~30 stone 0  
fill ~22 ~19 ~32 ~22 ~21 ~32 stone 0  
fill ~23 ~19 ~10 ~30 ~19 ~10 stone 0  
fill ~23 ~19 ~12 ~26 ~19 ~12 stone 0  
fill ~23 ~19 ~16 ~25 ~19 ~16 stone 0 
setblock ~23 ~19 ~17 mossy_cobblestone 0  
fill ~23 ~19 ~22 ~29 ~19 ~22 stone 0  
fill ~23 ~19 ~24 ~25 ~19 ~24 stone 0  
fill ~23 ~19 ~27 ~26 ~19 ~27 stone 0  
fill ~23 ~19 ~28 ~30 ~19 ~28 stone 0 
setblock ~23 ~19 ~30 cobblestone 0 
setblock ~23 ~19 ~32 mossy_cobblestone 0  
fill ~24 ~19 ~6 ~27 ~19 ~6 stone 0  
fill ~24 ~19 ~7 ~29 ~19 ~7 stone 0 
setblock ~24 ~19 ~9 stone 0  
fill ~24 ~19 ~11 ~25 ~19 ~11 stone 0  
fill ~24 ~19 ~26 ~27 ~19 ~26 stone 0 
setblock ~24 ~19 ~29 cobblestone 0  
fill ~24 ~19 ~30 ~26 ~19 ~30 stone 0 
setblock ~24 ~19 ~31 mossy_cobblestone 0  
fill ~24 ~19 ~32 ~28 ~19 ~32 stone 0  
fill ~24 ~19 ~34 ~24 ~22 ~34 stone 0  
fill ~25 ~19 ~9 ~28 ~19 ~9 cobblestone 0  
fill ~25 ~19 ~13 ~25 ~20 ~13 stone 0 
setblock ~25 ~19 ~14 mossy_cobblestone 0 
setblock ~25 ~19 ~15 cobblestone 0  
fill ~25 ~19 ~17 ~31 ~19 ~17 stone 0 
setblock ~25 ~19 ~19 mossy_cobblestone 0 
setblock ~25 ~19 ~25 cobblestone 0 
setblock ~25 ~19 ~29 stone 0  
fill ~25 ~19 ~31 ~28 ~19 ~31 stone 0  
fill ~26 ~19 ~5 ~26 ~20 ~5 cobblestone 0 
setblock ~26 ~19 ~8 cobblestone 0 
setblock ~26 ~19 ~11 cobblestone 0 
setblock ~26 ~19 ~13 mossy_cobblestone 0  
fill ~26 ~19 ~15 ~26 ~34 ~15 stone 0 
setblock ~26 ~19 ~16 mossy_cobblestone 0 
setblock ~26 ~19 ~19 stone 0 
setblock ~26 ~19 ~24 cobblestone 0  
fill ~26 ~19 ~25 ~26 ~23 ~25 stone 0 
setblock ~27 ~19 ~8 mossy_cobblestone 0 
setblock ~27 ~19 ~12 cobblestone 0  
fill ~27 ~19 ~13 ~28 ~19 ~13 stone 0  
fill ~27 ~19 ~16 ~30 ~19 ~16 stone 0  
fill ~27 ~19 ~21 ~28 ~19 ~21 cobblestone 0  
fill ~27 ~19 ~24 ~28 ~19 ~24 stone 0 
setblock ~27 ~19 ~25 cobblestone 0 
setblock ~27 ~19 ~27 cobblestone 0 
setblock ~27 ~19 ~29 mossy_cobblestone 0  
fill ~27 ~19 ~30 ~27 ~20 ~30 cobblestone 0  
fill ~28 ~19 ~5 ~30 ~19 ~5 stone 0  
fill ~28 ~19 ~8 ~31 ~19 ~8 stone 0  
fill ~28 ~19 ~11 ~28 ~20 ~11 stone 0  
fill ~28 ~19 ~12 ~35 ~19 ~12 stone 0  
fill ~28 ~19 ~14 ~28 ~18 ~14 stone 0  
fill ~28 ~19 ~15 ~28 ~19 ~10 stone 0  
fill ~28 ~19 ~19 ~28 ~23 ~19 stone 0  
fill ~28 ~19 ~26 ~29 ~19 ~26 cobblestone 0  
fill ~28 ~19 ~27 ~29 ~19 ~27 stone 0  
fill ~28 ~19 ~29 ~29 ~19 ~29 stone 0  
fill ~29 ~19 ~4 ~29 ~20 ~4 stone 0  
fill ~29 ~19 ~9 ~34 ~19 ~9 stone 0 
setblock ~29 ~19 ~13 mossy_cobblestone 0  
fill ~29 ~19 ~14 ~29 ~20 ~14 cobblestone 0  
fill ~29 ~19 ~20 ~29 ~20 ~20 cobblestone 0  
fill ~29 ~19 ~21 ~29 ~26 ~21 stone 0 
setblock ~29 ~19 ~24 mossy_cobblestone 0  
fill ~29 ~19 ~25 ~30 ~19 ~25 stone 0 
setblock ~30 ~19 ~7 mossy_cobblestone 0  
fill ~30 ~19 ~13 ~33 ~19 ~13 stone 0  
fill ~30 ~19 ~14 ~31 ~19 ~14 stone 0 
setblock ~30 ~19 ~19 mossy_cobblestone 0  
fill ~30 ~19 ~20 ~30 ~21 ~20 stone 0  
fill ~30 ~19 ~22 ~30 ~20 ~22 cobblestone 0 
setblock ~30 ~19 ~31 cobblestone 0  
fill ~31 ~19 ~10 ~31 ~19 ~11 mossy_cobblestone 0 
setblock ~31 ~19 ~20 cobblestone 0 
setblock ~32 ~19 ~8 cobblestone 0  
fill ~32 ~19 ~10 ~34 ~19 ~10 stone 0 
setblock ~32 ~19 ~14 cobblestone 0  
fill ~33 ~19 ~8 ~33 ~27 ~8 stone 0 
setblock ~33 ~19 ~11 mossy_cobblestone 0 
setblock ~7 ~20 ~21 mossy_cobblestone 0  
fill ~8 ~20 ~17 ~8 ~24 ~17 stone 0  
fill ~8 ~20 ~19 ~9 ~20 ~19 mossy_cobblestone 0 
setblock ~9 ~20 ~17 cobblestone 0  
fill ~9 ~20 ~18 ~12 ~20 ~18 stone 0  
fill ~9 ~20 ~20 ~9 ~24 ~20 stone 0  
fill ~9 ~20 ~21 ~9 ~21 ~21 stone 0  
fill ~10 ~20 ~17 ~14 ~20 ~17 stone 0  
fill ~10 ~20 ~19 ~15 ~20 ~19 stone 0  
fill ~10 ~20 ~24 ~15 ~20 ~24 stone 0  
fill ~10 ~20 ~25 ~14 ~20 ~25 stone 0 
setblock ~11 ~20 ~20 cobblestone 0  
fill ~12 ~20 ~20 ~12 ~23 ~20 stone 0  
fill ~12 ~20 ~21 ~12 ~23 ~21 stone 0 
setblock ~12 ~20 ~23 cobblestone 0  
fill ~12 ~20 ~29 ~12 ~22 ~29 stone 0 
setblock ~13 ~20 ~15 stone 0  
fill ~13 ~20 ~20 ~13 ~20 ~21 mossy_cobblestone 0  
fill ~13 ~20 ~22 ~13 ~23 ~22 stone 0 
setblock ~13 ~20 ~27 mossy_cobblestone 0  
fill ~13 ~20 ~30 ~13 ~25 ~30 stone 0  
fill ~14 ~20 ~14 ~19 ~20 ~14 stone 0 
setblock ~14 ~20 ~16 cobblestone 0  
fill ~14 ~20 ~18 ~19 ~20 ~18 stone 0  
fill ~14 ~20 ~21 ~14 ~26 ~21 stone 0  
fill ~14 ~20 ~27 ~14 ~20 ~28 cobblestone 0 
setblock ~14 ~20 ~30 cobblestone 0 
setblock ~15 ~20 ~13 mossy_cobblestone 0 
setblock ~15 ~20 ~15 mossy_cobblestone 0  
fill ~15 ~20 ~16 ~21 ~20 ~16 stone 0 
setblock ~15 ~20 ~17 cobblestone 0  
fill ~15 ~20 ~20 ~15 ~20 ~21 cobblestone 0  
fill ~15 ~20 ~22 ~15 ~21 ~22 stone 0 
setblock ~15 ~20 ~27 mossy_cobblestone 0  
fill ~15 ~20 ~29 ~16 ~20 ~29 stone 0  
fill ~16 ~20 ~13 ~19 ~20 ~13 stone 0 
setblock ~16 ~20 ~19 mossy_cobblestone 0  
fill ~16 ~20 ~24 ~16 ~20 ~25 mossy_cobblestone 0  
fill ~16 ~20 ~27 ~19 ~20 ~27 stone 0 
setblock ~16 ~20 ~30 mossy_cobblestone 0  
fill ~16 ~20 ~31 ~18 ~20 ~31 stone 0  
fill ~17 ~20 ~11 ~18 ~20 ~11 mossy_cobblestone 0  
fill ~17 ~20 ~12 ~17 ~20 ~11 mossy_cobblestone 0 
setblock ~17 ~20 ~15 cobblestone 0  
fill ~17 ~20 ~19 ~17 ~25 ~19 stone 0  
fill ~17 ~20 ~20 ~17 ~21 ~20 stone 0  
fill ~17 ~20 ~21 ~22 ~20 ~21 stone 0  
fill ~17 ~20 ~22 ~17 ~27 ~22 stone 0  
fill ~17 ~20 ~25 ~18 ~20 ~25 stone 0 
setblock ~17 ~20 ~26 mossy_cobblestone 0  
fill ~17 ~20 ~28 ~17 ~21 ~28 stone 0 
setblock ~17 ~20 ~29 mossy_cobblestone 0  
fill ~17 ~20 ~32 ~19 ~20 ~32 stone 0  
fill ~18 ~20 ~10 ~19 ~20 ~10 stone 0  
fill ~18 ~20 ~12 ~18 ~27 ~12 stone 0  
fill ~18 ~20 ~15 ~22 ~20 ~15 stone 0  
fill ~18 ~20 ~17 ~18 ~21 ~17 cobblestone 0  
fill ~18 ~20 ~23 ~18 ~20 ~24 cobblestone 0 
setblock ~18 ~20 ~28 cobblestone 0  
fill ~18 ~20 ~30 ~18 ~22 ~30 stone 0  
fill ~19 ~20 ~11 ~33 ~20 ~11 stone 0 
setblock ~19 ~20 ~12 cobblestone 0  
fill ~19 ~20 ~17 ~28 ~20 ~17 stone 0 
setblock ~19 ~20 ~19 mossy_cobblestone 0  
fill ~19 ~20 ~24 ~27 ~20 ~24 stone 0 
setblock ~19 ~20 ~25 cobblestone 0  
fill ~19 ~20 ~26 ~24 ~20 ~26 stone 0  
fill ~19 ~20 ~28 ~19 ~22 ~28 stone 0 
setblock ~19 ~20 ~31 cobblestone 0  
fill ~20 ~20 ~9 ~20 ~20 ~10 cobblestone 0 
setblock ~20 ~20 ~13 cobblestone 0 
setblock ~20 ~20 ~14 mossy_cobblestone 0 
setblock ~20 ~20 ~18 cobblestone 0  
fill ~20 ~20 ~20 ~26 ~20 ~20 stone 0  
fill ~20 ~20 ~23 ~20 ~23 ~23 stone 0  
fill ~20 ~20 ~25 ~26 ~20 ~25 stone 0 
setblock ~20 ~20 ~27 cobblestone 0 
setblock ~20 ~20 ~28 mossy_cobblestone 0  
fill ~20 ~20 ~31 ~21 ~20 ~31 stone 0 
setblock ~20 ~20 ~32 mossy_cobblestone 0  
fill ~20 ~20 ~34 ~24 ~20 ~34 stone 0  
fill ~21 ~20 ~12 ~21 ~21 ~12 cobblestone 0  
fill ~21 ~20 ~13 ~21 ~29 ~13 stone 0  
fill ~21 ~20 ~14 ~27 ~20 ~14 stone 0 
setblock ~21 ~20 ~23 mossy_cobblestone 0  
fill ~21 ~20 ~27 ~24 ~20 ~27 stone 0  
fill ~21 ~20 ~28 ~23 ~20 ~28 cobblestone 0  
fill ~21 ~20 ~32 ~21 ~22 ~32 stone 0  
fill ~21 ~20 ~33 ~21 ~28 ~33 stone 0 
setblock ~22 ~20 ~10 mossy_cobblestone 0  
fill ~22 ~20 ~12 ~25 ~20 ~12 stone 0 
setblock ~22 ~20 ~16 mossy_cobblestone 0  
fill ~22 ~20 ~22 ~25 ~20 ~22 stone 0  
fill ~22 ~20 ~23 ~30 ~20 ~23 stone 0  
fill ~22 ~20 ~31 ~23 ~20 ~31 mossy_cobblestone 0 
setblock ~22 ~20 ~33 cobblestone 0  
fill ~23 ~20 ~10 ~28 ~20 ~10 stone 0 
setblock ~23 ~20 ~13 mossy_cobblestone 0 
setblock ~23 ~20 ~15 mossy_cobblestone 0  
fill ~23 ~20 ~16 ~25 ~20 ~16 stone 0  
fill ~23 ~20 ~21 ~23 ~21 ~21 mossy_cobblestone 0  
fill ~23 ~20 ~30 ~23 ~21 ~30 stone 0  
fill ~23 ~20 ~32 ~29 ~20 ~32 stone 0  
fill ~23 ~20 ~33 ~23 ~22 ~33 stone 0  
fill ~24 ~20 ~5 ~24 ~21 ~5 stone 0  
fill ~24 ~20 ~6 ~24 ~38 ~6 stone 0  
fill ~24 ~20 ~7 ~30 ~20 ~7 stone 0  
fill ~24 ~20 ~8 ~25 ~20 ~8 cobblestone 0  
fill ~24 ~20 ~9 ~24 ~22 ~9 mossy_cobblestone 0  
fill ~24 ~20 ~15 ~27 ~20 ~15 stone 0  
fill ~24 ~20 ~19 ~25 ~20 ~19 stone 0  
fill ~24 ~20 ~28 ~24 ~22 ~28 stone 0  
fill ~24 ~20 ~29 ~24 ~20 ~30 mossy_cobblestone 0  
fill ~24 ~20 ~31 ~26 ~20 ~31 stone 0 
setblock ~24 ~20 ~33 mossy_cobblestone 0 
setblock ~25 ~20 ~6 mossy_cobblestone 0  
fill ~25 ~20 ~9 ~28 ~20 ~9 stone 0 
setblock ~25 ~20 ~21 mossy_cobblestone 0 
setblock ~25 ~20 ~26 cobblestone 0  
fill ~25 ~20 ~27 ~25 ~21 ~27 mossy_cobblestone 0 
setblock ~25 ~20 ~29 cobblestone 0  
fill ~25 ~20 ~30 ~26 ~20 ~30 stone 0  
fill ~25 ~20 ~33 ~26 ~20 ~33 stone 0 
setblock ~26 ~20 ~6 cobblestone 0  
fill ~26 ~20 ~8 ~27 ~20 ~8 stone 0 
setblock ~26 ~20 ~12 cobblestone 0  
fill ~26 ~20 ~13 ~27 ~20 ~13 stone 0  
fill ~26 ~20 ~16 ~27 ~20 ~16 cobblestone 0 
setblock ~26 ~20 ~18 stone 0 
setblock ~26 ~20 ~19 mossy_cobblestone 0 
setblock ~26 ~20 ~22 cobblestone 0  
fill ~26 ~20 ~26 ~26 ~30 ~26 stone 0  
fill ~26 ~20 ~27 ~29 ~20 ~27 stone 0  
fill ~27 ~20 ~5 ~30 ~20 ~5 stone 0  
fill ~27 ~20 ~12 ~29 ~20 ~12 stone 0 
setblock ~27 ~20 ~19 cobblestone 0  
fill ~27 ~20 ~20 ~27 ~21 ~20 mossy_cobblestone 0  
fill ~27 ~20 ~21 ~27 ~21 ~21 stone 0  
fill ~27 ~20 ~22 ~29 ~20 ~22 stone 0  
fill ~27 ~20 ~25 ~27 ~20 ~26 mossy_cobblestone 0  
fill ~27 ~20 ~29 ~31 ~20 ~29 stone 0  
fill ~27 ~20 ~31 ~28 ~20 ~31 cobblestone 0  
fill ~28 ~20 ~6 ~28 ~23 ~6 stone 0 
setblock ~28 ~20 ~8 mossy_cobblestone 0 
setblock ~28 ~20 ~13 mossy_cobblestone 0  
fill ~28 ~20 ~14 ~28 ~20 ~15 cobblestone 0  
fill ~28 ~20 ~16 ~30 ~20 ~16 stone 0 
setblock ~28 ~20 ~18 stone 0  
fill ~28 ~20 ~20 ~28 ~23 ~20 stone 0 
setblock ~28 ~20 ~21 cobblestone 0 
setblock ~28 ~20 ~24 mossy_cobblestone 0  
fill ~28 ~20 ~25 ~29 ~20 ~25 stone 0  
fill ~28 ~20 ~26 ~28 ~20 ~25 stone 0 
setblock ~29 ~20 ~6 mossy_cobblestone 0  
fill ~29 ~20 ~8 ~29 ~22 ~8 stone 0  
fill ~29 ~20 ~9 ~29 ~21 ~9 mossy_cobblestone 0  
fill ~29 ~20 ~10 ~30 ~20 ~10 mossy_cobblestone 0  
fill ~29 ~20 ~13 ~36 ~20 ~13 stone 0  
fill ~29 ~20 ~17 ~29 ~20 ~18 mossy_cobblestone 0  
fill ~29 ~20 ~24 ~30 ~20 ~24 stone 0  
fill ~29 ~20 ~26 ~30 ~20 ~26 mossy_cobblestone 0 
setblock ~29 ~20 ~28 mossy_cobblestone 0  
fill ~29 ~20 ~31 ~30 ~20 ~31 stone 0   

KittysCommands:  
setblock ~30 ~20 ~8 mossy_cobblestone 0 
setblock ~30 ~20 ~9 cobblestone 0 
setblock ~30 ~20 ~12 cobblestone 0  
fill ~30 ~20 ~14 ~30 ~21 ~14 stone 0  
fill ~30 ~20 ~17 ~31 ~20 ~17 stone 0  
fill ~30 ~20 ~19 ~30 ~21 ~19 stone 0  
fill ~30 ~20 ~21 ~30 ~34 ~21 stone 0 
setblock ~30 ~20 ~25 cobblestone 0 
setblock ~30 ~20 ~27 cobblestone 0  
fill ~30 ~20 ~28 ~30 ~21 ~28 stone 0 
setblock ~31 ~20 ~7 mossy_cobblestone 0  
fill ~31 ~20 ~9 ~31 ~23 ~9 stone 0  
fill ~31 ~20 ~10 ~34 ~20 ~10 stone 0  
fill ~31 ~20 ~12 ~35 ~20 ~12 stone 0 
setblock ~31 ~20 ~14 cobblestone 0  
fill ~31 ~20 ~15 ~31 ~28 ~15 stone 0  
fill ~31 ~20 ~18 ~31 ~20 ~19 mossy_cobblestone 0 
setblock ~31 ~20 ~20 stone 0 
setblock ~32 ~20 ~8 stone 0 
setblock ~32 ~20 ~9 cobblestone 0  
fill ~32 ~20 ~14 ~34 ~20 ~14 stone 0 
setblock ~32 ~20 ~18 stone 0  
fill ~34 ~20 ~9 ~34 ~22 ~9 stone 0 
setblock ~34 ~20 ~11 mossy_cobblestone 0  
fill ~6 ~21 ~20 ~9 ~21 ~20 stone 0  
fill ~7 ~21 ~19 ~8 ~21 ~19 stone 0  
fill ~7 ~21 ~21 ~7 ~25 ~21 stone 0 
setblock ~7 ~21 ~22 mossy_cobblestone 0  
fill ~8 ~21 ~18 ~25 ~21 ~18 stone 0  
fill ~9 ~21 ~17 ~12 ~21 ~17 stone 0 
setblock ~9 ~21 ~19 cobblestone 0  
fill ~9 ~21 ~22 ~9 ~22 ~22 stone 0  
fill ~10 ~21 ~16 ~10 ~22 ~16 stone 0  
fill ~10 ~21 ~19 ~10 ~21 ~20 mossy_cobblestone 0 
setblock ~10 ~21 ~24 mossy_cobblestone 0  
fill ~10 ~21 ~25 ~23 ~21 ~25 stone 0 
setblock ~10 ~21 ~26 mossy_cobblestone 0 
setblock ~11 ~21 ~16 cobblestone 0  
fill ~11 ~21 ~19 ~12 ~21 ~19 stone 0  
fill ~11 ~21 ~20 ~11 ~29 ~20 stone 0  
fill ~11 ~21 ~24 ~15 ~21 ~24 stone 0 
setblock ~11 ~21 ~28 mossy_cobblestone 0 
setblock ~11 ~21 ~29 cobblestone 0  
fill ~12 ~21 ~15 ~12 ~24 ~15 stone 0 
setblock ~12 ~21 ~23 mossy_cobblestone 0 
setblock ~12 ~21 ~26 mossy_cobblestone 0 
setblock ~13 ~21 ~15 mossy_cobblestone 0  
fill ~13 ~21 ~16 ~14 ~21 ~16 stone 0 
setblock ~13 ~21 ~17 cobblestone 0 
setblock ~13 ~21 ~19 mossy_cobblestone 0  
fill ~13 ~21 ~20 ~13 ~23 ~20 stone 0  
fill ~13 ~21 ~21 ~13 ~26 ~21 stone 0  
fill ~13 ~21 ~27 ~24 ~21 ~27 stone 0 
setblock ~13 ~21 ~28 cobblestone 0  
fill ~14 ~21 ~14 ~14 ~20 ~14 stone 0 
setblock ~14 ~21 ~15 cobblestone 0 
setblock ~14 ~21 ~17 stone 0  
fill ~14 ~21 ~19 ~15 ~21 ~19 stone 0 
setblock ~14 ~21 ~20 mossy_cobblestone 0 
setblock ~14 ~21 ~23 cobblestone 0 
setblock ~14 ~21 ~28 stone 0  
fill ~14 ~21 ~30 ~21 ~21 ~30 stone 0  
fill ~14 ~21 ~31 ~14 ~23 ~31 stone 0  
fill ~15 ~21 ~12 ~15 ~25 ~12 stone 0  
fill ~15 ~21 ~13 ~23 ~21 ~13 stone 0 
setblock ~15 ~21 ~14 cobblestone 0  
fill ~15 ~21 ~15 ~15 ~23 ~15 stone 0 
setblock ~15 ~21 ~16 cobblestone 0  
fill ~15 ~21 ~17 ~16 ~21 ~17 mossy_cobblestone 0  
fill ~15 ~21 ~20 ~15 ~27 ~20 stone 0  
fill ~15 ~21 ~21 ~15 ~24 ~21 stone 0 
setblock ~15 ~21 ~23 mossy_cobblestone 0  
fill ~15 ~21 ~29 ~20 ~21 ~29 stone 0 
setblock ~16 ~21 ~12 mossy_cobblestone 0  
fill ~16 ~21 ~14 ~30 ~21 ~14 stone 0 
setblock ~16 ~21 ~15 mossy_cobblestone 0  
fill ~16 ~21 ~16 ~16 ~24 ~16 stone 0 
setblock ~16 ~21 ~19 cobblestone 0 
setblock ~16 ~21 ~24 cobblestone 0  
fill ~16 ~21 ~31 ~17 ~21 ~31 stone 0  
fill ~16 ~21 ~32 ~18 ~21 ~32 stone 0  
fill ~17 ~21 ~10 ~21 ~21 ~10 stone 0 
setblock ~17 ~21 ~11 cobblestone 0  
fill ~17 ~21 ~12 ~17 ~35 ~12 stone 0  
fill ~17 ~21 ~15 ~23 ~21 ~15 stone 0  
fill ~17 ~21 ~16 ~17 ~21 ~17 cobblestone 0  
fill ~17 ~21 ~21 ~19 ~21 ~21 stone 0 
setblock ~17 ~21 ~26 cobblestone 0  
fill ~18 ~21 ~11 ~18 ~22 ~11 stone 0 
setblock ~18 ~21 ~22 mossy_cobblestone 0  
fill ~18 ~21 ~23 ~18 ~21 ~30 stone 0 
setblock ~18 ~21 ~31 mossy_cobblestone 0  
fill ~19 ~21 ~9 ~21 ~21 ~9 stone 0 
setblock ~19 ~21 ~11 cobblestone 0  
fill ~19 ~21 ~12 ~19 ~25 ~12 stone 0 
setblock ~19 ~21 ~17 cobblestone 0  
fill ~19 ~21 ~19 ~19 ~24 ~19 stone 0  
fill ~19 ~21 ~20 ~22 ~21 ~20 stone 0 
setblock ~19 ~21 ~24 cobblestone 0  
fill ~19 ~21 ~26 ~20 ~21 ~26 stone 0  
fill ~19 ~21 ~31 ~19 ~27 ~31 stone 0 
setblock ~19 ~21 ~32 cobblestone 0  
fill ~20 ~21 ~11 ~20 ~22 ~11 mossy_cobblestone 0 
setblock ~20 ~21 ~12 cobblestone 0  
fill ~20 ~21 ~16 ~22 ~21 ~16 stone 0  
fill ~20 ~21 ~17 ~21 ~21 ~17 stone 0 
setblock ~20 ~21 ~19 mossy_cobblestone 0  
fill ~20 ~21 ~21 ~20 ~21 ~22 cobblestone 0  
fill ~20 ~21 ~24 ~21 ~21 ~24 stone 0  
fill ~20 ~21 ~28 ~24 ~21 ~28 stone 0 
setblock ~20 ~21 ~31 cobblestone 0  
fill ~20 ~21 ~32 ~20 ~26 ~32 stone 0 
setblock ~20 ~21 ~34 mossy_cobblestone 0  
fill ~21 ~21 ~11 ~27 ~21 ~11 stone 0  
fill ~21 ~21 ~23 ~27 ~21 ~23 stone 0 
setblock ~21 ~21 ~26 mossy_cobblestone 0 
setblock ~21 ~21 ~29 cobblestone 0  
fill ~21 ~21 ~31 ~22 ~21 ~31 stone 0  
fill ~21 ~21 ~34 ~22 ~21 ~34 stone 0 
setblock ~22 ~21 ~10 cobblestone 0 
setblock ~22 ~21 ~12 cobblestone 0  
fill ~22 ~21 ~17 ~23 ~21 ~17 mossy_cobblestone 0 
setblock ~22 ~21 ~19 cobblestone 0  
fill ~22 ~21 ~21 ~22 ~21 ~23 stone 0  
fill ~22 ~21 ~24 ~23 ~21 ~24 mossy_cobblestone 0  
fill ~22 ~21 ~26 ~22 ~22 ~26 stone 0 
setblock ~22 ~21 ~30 cobblestone 0 
setblock ~22 ~21 ~33 stone 0  
fill ~23 ~21 ~7 ~30 ~21 ~7 stone 0  
fill ~23 ~21 ~8 ~24 ~21 ~8 stone 0  
fill ~23 ~21 ~9 ~23 ~24 ~9 stone 0  
fill ~23 ~21 ~10 ~25 ~21 ~10 stone 0  
fill ~23 ~21 ~12 ~27 ~21 ~12 stone 0 
setblock ~23 ~21 ~16 mossy_cobblestone 0 
setblock ~23 ~21 ~20 mossy_cobblestone 0  
fill ~23 ~21 ~22 ~30 ~21 ~22 stone 0  
fill ~23 ~21 ~31 ~23 ~21 ~32 mossy_cobblestone 0 
setblock ~23 ~21 ~34 cobblestone 0 
setblock ~23 ~21 ~35 stone 0  
fill ~24 ~21 ~13 ~24 ~22 ~13 cobblestone 0 
setblock ~24 ~21 ~15 cobblestone 0  
fill ~24 ~21 ~16 ~29 ~21 ~16 stone 0  
fill ~24 ~21 ~19 ~25 ~21 ~19 stone 0  
fill ~24 ~21 ~20 ~26 ~21 ~20 stone 0  
fill ~24 ~21 ~24 ~24 ~25 ~24 stone 0  
fill ~24 ~21 ~25 ~24 ~21 ~26 cobblestone 0  
fill ~24 ~21 ~29 ~27 ~21 ~29 stone 0  
fill ~24 ~21 ~30 ~24 ~22 ~30 stone 0  
fill ~24 ~21 ~31 ~25 ~21 ~31 stone 0 
setblock ~24 ~21 ~32 cobblestone 0  
fill ~24 ~21 ~33 ~24 ~26 ~33 stone 0  
fill ~25 ~21 ~5 ~30 ~21 ~5 stone 0  
fill ~25 ~21 ~6 ~29 ~21 ~6 stone 0 
setblock ~25 ~21 ~8 cobblestone 0  
fill ~25 ~21 ~9 ~28 ~21 ~9 stone 0 
setblock ~25 ~21 ~13 mossy_cobblestone 0  
fill ~25 ~21 ~15 ~25 ~23 ~15 stone 0  
fill ~25 ~21 ~17 ~29 ~21 ~17 stone 0 
setblock ~25 ~21 ~21 stone 0  
fill ~25 ~21 ~24 ~25 ~22 ~24 cobblestone 0  
fill ~25 ~21 ~25 ~25 ~28 ~25 stone 0 
setblock ~25 ~21 ~26 mossy_cobblestone 0 
setblock ~25 ~21 ~28 mossy_cobblestone 0 
setblock ~25 ~21 ~30 mossy_cobblestone 0  
fill ~25 ~21 ~32 ~25 ~24 ~32 stone 0 
setblock ~25 ~21 ~33 mossy_cobblestone 0  
fill ~25 ~21 ~34 ~25 ~22 ~34 stone 0  
fill ~26 ~21 ~8 ~26 ~23 ~8 stone 0 
setblock ~26 ~21 ~10 mossy_cobblestone 0  
fill ~26 ~21 ~13 ~28 ~21 ~13 stone 0 
setblock ~26 ~21 ~18 mossy_cobblestone 0  
fill ~26 ~21 ~19 ~26 ~22 ~19 cobblestone 0  
fill ~26 ~21 ~24 ~30 ~21 ~24 stone 0 
setblock ~26 ~21 ~27 mossy_cobblestone 0  
fill ~26 ~21 ~30 ~31 ~21 ~30 stone 0 
setblock ~26 ~21 ~31 mossy_cobblestone 0 
setblock ~26 ~21 ~32 cobblestone 0  
fill ~26 ~21 ~33 ~28 ~21 ~33 stone 0  
fill ~27 ~21 ~4 ~28 ~21 ~4 stone 0 
setblock ~27 ~21 ~8 mossy_cobblestone 0  
fill ~27 ~21 ~10 ~34 ~21 ~10 stone 0  
fill ~27 ~21 ~18 ~28 ~21 ~18 cobblestone 0  
fill ~27 ~21 ~19 ~27 ~22 ~19 stone 0  
fill ~27 ~21 ~25 ~30 ~21 ~25 stone 0  
fill ~27 ~21 ~26 ~27 ~27 ~26 stone 0  
fill ~27 ~21 ~27 ~28 ~21 ~27 stone 0  
fill ~27 ~21 ~31 ~28 ~21 ~31 stone 0  
fill ~27 ~21 ~32 ~27 ~26 ~32 stone 0  
fill ~28 ~21 ~3 ~28 ~24 ~3 stone 0  
fill ~28 ~21 ~8 ~28 ~23 ~8 stone 0  
fill ~28 ~21 ~11 ~28 ~21 ~12 mossy_cobblestone 0  
fill ~28 ~21 ~15 ~28 ~23 ~15 stone 0  
fill ~28 ~21 ~21 ~28 ~24 ~21 stone 0 
setblock ~28 ~21 ~23 mossy_cobblestone 0 
setblock ~28 ~21 ~26 mossy_cobblestone 0 
setblock ~28 ~21 ~29 mossy_cobblestone 0 
setblock ~28 ~21 ~32 cobblestone 0 
setblock ~29 ~21 ~4 mossy_cobblestone 0  
fill ~29 ~21 ~12 ~30 ~21 ~12 stone 0  
fill ~29 ~21 ~13 ~29 ~22 ~13 mossy_cobblestone 0 
setblock ~29 ~21 ~18 stone 0  
fill ~29 ~21 ~20 ~29 ~28 ~20 stone 0  
fill ~29 ~21 ~23 ~30 ~21 ~23 stone 0  
fill ~29 ~21 ~26 ~30 ~21 ~26 stone 0 
setblock ~29 ~21 ~27 cobblestone 0  
fill ~29 ~21 ~28 ~29 ~23 ~28 stone 0  
fill ~29 ~21 ~29 ~31 ~21 ~29 stone 0  
fill ~29 ~21 ~31 ~30 ~21 ~31 cobblestone 0 
setblock ~29 ~21 ~32 mossy_cobblestone 0 
setblock ~30 ~21 ~6 cobblestone 0  
fill ~30 ~21 ~8 ~30 ~21 ~15 stone 0 
setblock ~30 ~21 ~16 mossy_cobblestone 0  
fill ~30 ~21 ~17 ~31 ~21 ~17 cobblestone 0 
setblock ~30 ~21 ~27 stone 0  
fill ~30 ~21 ~32 ~30 ~22 ~32 stone 0 
setblock ~30 ~21 ~34 cobblestone 0 
setblock ~31 ~21 ~7 cobblestone 0 
setblock ~31 ~21 ~11 stone 0  
fill ~31 ~21 ~12 ~32 ~21 ~12 cobblestone 0  
fill ~31 ~21 ~13 ~34 ~21 ~13 stone 0 
setblock ~31 ~21 ~14 mossy_cobblestone 0  
fill ~31 ~21 ~18 ~32 ~21 ~18 cobblestone 0  
fill ~31 ~21 ~19 ~31 ~21 ~20 cobblestone 0  
fill ~31 ~21 ~28 ~31 ~26 ~28 stone 0  
fill ~31 ~21 ~31 ~31 ~22 ~31 stone 0 
setblock ~32 ~21 ~8 mossy_cobblestone 0 
setblock ~32 ~21 ~9 stone 0  
fill ~32 ~21 ~14 ~34 ~21 ~14 stone 0  
fill ~32 ~21 ~19 ~32 ~22 ~19 stone 0  
fill ~33 ~21 ~11 ~35 ~21 ~11 stone 0  
fill ~33 ~21 ~12 ~33 ~22 ~12 stone 0  
fill ~35 ~21 ~12 ~35 ~28 ~12 stone 0 
setblock ~35 ~21 ~13 mossy_cobblestone 0  
fill ~36 ~21 ~13 ~36 ~32 ~13 stone 0  
fill ~6 ~22 ~18 ~15 ~22 ~18 stone 0  
fill ~6 ~22 ~19 ~7 ~22 ~19 stone 0  
fill ~6 ~22 ~20 ~16 ~22 ~20 stone 0  
fill ~7 ~22 ~22 ~14 ~22 ~22 stone 0 
setblock ~8 ~22 ~16 stone 0 
setblock ~8 ~22 ~19 mossy_cobblestone 0  
fill ~8 ~22 ~23 ~13 ~22 ~23 stone 0  
fill ~9 ~22 ~15 ~10 ~22 ~15 stone 0  
fill ~9 ~22 ~17 ~10 ~22 ~17 stone 0  
fill ~9 ~22 ~19 ~20 ~22 ~19 stone 0 
setblock ~9 ~22 ~21 cobblestone 0  
fill ~9 ~22 ~24 ~12 ~22 ~24 stone 0  
fill ~10 ~22 ~14 ~10 ~23 ~14 stone 0  
fill ~10 ~22 ~25 ~10 ~27 ~25 stone 0  
fill ~10 ~22 ~26 ~10 ~28 ~26 stone 0  
fill ~11 ~22 ~16 ~11 ~25 ~16 stone 0 
setblock ~11 ~22 ~17 cobblestone 0 
setblock ~11 ~22 ~25 cobblestone 0  
fill ~11 ~22 ~28 ~11 ~31 ~28 stone 0  
fill ~11 ~22 ~29 ~11 ~24 ~29 stone 0 
setblock ~12 ~22 ~14 mossy_cobblestone 0 
setblock ~12 ~22 ~17 mossy_cobblestone 0  
fill ~12 ~22 ~26 ~12 ~25 ~26 stone 0 
setblock ~12 ~22 ~30 mossy_cobblestone 0  
fill ~13 ~22 ~14 ~13 ~22 ~23 stone 0 
setblock ~13 ~22 ~24 mossy_cobblestone 0 
setblock ~13 ~22 ~25 cobblestone 0  
fill ~13 ~22 ~27 ~15 ~22 ~27 stone 0  
fill ~13 ~22 ~28 ~13 ~22 ~26 stone 0  
fill ~14 ~22 ~14 ~14 ~23 ~14 mossy_cobblestone 0  
fill ~14 ~22 ~15 ~14 ~24 ~15 stone 0  
fill ~14 ~22 ~16 ~27 ~22 ~16 stone 0  
fill ~14 ~22 ~17 ~15 ~22 ~17 cobblestone 0 
setblock ~14 ~22 ~23 mossy_cobblestone 0  
fill ~14 ~22 ~24 ~14 ~23 ~24 stone 0 
setblock ~14 ~22 ~26 cobblestone 0 
setblock ~14 ~22 ~28 mossy_cobblestone 0  
fill ~14 ~22 ~30 ~22 ~22 ~30 stone 0  
fill ~15 ~22 ~11 ~19 ~22 ~11 stone 0  
fill ~15 ~22 ~13 ~19 ~22 ~13 stone 0  
fill ~15 ~22 ~14 ~15 ~29 ~14 stone 0  
fill ~15 ~22 ~22 ~15 ~22 ~23 cobblestone 0  
fill ~15 ~22 ~25 ~17 ~22 ~25 stone 0  
fill ~15 ~22 ~29 ~15 ~20 ~29 stone 0  
fill ~16 ~22 ~12 ~16 ~25 ~12 stone 0 
setblock ~16 ~22 ~14 mossy_cobblestone 0  
fill ~16 ~22 ~15 ~18 ~22 ~15 stone 0  
fill ~16 ~22 ~17 ~16 ~31 ~17 stone 0 
setblock ~16 ~22 ~18 mossy_cobblestone 0 
setblock ~16 ~22 ~21 cobblestone 0 
setblock ~16 ~22 ~22 mossy_cobblestone 0  
fill ~16 ~22 ~24 ~16 ~23 ~24 stone 0 
setblock ~16 ~22 ~27 cobblestone 0 
setblock ~16 ~22 ~29 mossy_cobblestone 0  
fill ~16 ~22 ~31 ~24 ~22 ~31 stone 0  
fill ~16 ~22 ~32 ~21 ~22 ~32 stone 0 
setblock ~17 ~22 ~10 mossy_cobblestone 0  
fill ~17 ~22 ~14 ~19 ~22 ~14 stone 0 
setblock ~17 ~22 ~17 mossy_cobblestone 0  
fill ~17 ~22 ~18 ~22 ~22 ~18 stone 0  
fill ~17 ~22 ~20 ~17 ~22 ~21 mossy_cobblestone 0  
fill ~17 ~22 ~26 ~17 ~22 ~27 stone 0 
setblock ~17 ~22 ~28 mossy_cobblestone 0  
fill ~17 ~22 ~29 ~18 ~22 ~29 stone 0  
fill ~17 ~22 ~33 ~17 ~24 ~33 stone 0  
fill ~18 ~22 ~9 ~23 ~22 ~9 stone 0  
fill ~18 ~22 ~10 ~26 ~22 ~10 stone 0  
fill ~18 ~22 ~17 ~31 ~22 ~17 stone 0  
fill ~18 ~22 ~21 ~18 ~27 ~21 stone 0  
fill ~18 ~22 ~22 ~18 ~27 ~22 stone 0  
fill ~18 ~22 ~23 ~19 ~22 ~23 mossy_cobblestone 0  
fill ~18 ~22 ~24 ~20 ~22 ~24 stone 0 
setblock ~18 ~22 ~25 cobblestone 0  
fill ~18 ~22 ~27 ~18 ~29 ~27 stone 0  
fill ~18 ~22 ~28 ~18 ~22 ~26 stone 0 
setblock ~18 ~22 ~33 cobblestone 0  
fill ~19 ~22 ~8 ~20 ~22 ~8 stone 0  
fill ~19 ~22 ~15 ~19 ~23 ~15 mossy_cobblestone 0  
fill ~19 ~22 ~20 ~19 ~22 ~21 mossy_cobblestone 0  
fill ~19 ~22 ~25 ~19 ~23 ~25 stone 0  
fill ~19 ~22 ~26 ~29 ~22 ~26 stone 0 
setblock ~19 ~22 ~29 cobblestone 0  
fill ~20 ~22 ~12 ~31 ~22 ~12 stone 0 
setblock ~20 ~22 ~13 mossy_cobblestone 0 
setblock ~20 ~22 ~14 cobblestone 0  
fill ~20 ~22 ~15 ~29 ~22 ~15 stone 0  
fill ~20 ~22 ~20 ~29 ~22 ~20 stone 0  
fill ~20 ~22 ~21 ~20 ~29 ~21 stone 0  
fill ~20 ~22 ~22 ~20 ~26 ~22 stone 0 
setblock ~20 ~22 ~25 mossy_cobblestone 0  
fill ~20 ~22 ~27 ~25 ~22 ~27 stone 0 
setblock ~20 ~22 ~28 mossy_cobblestone 0  
fill ~20 ~22 ~34 ~28 ~22 ~34 stone 0  
fill ~21 ~22 ~11 ~24 ~22 ~11 stone 0  
fill ~21 ~22 ~14 ~21 ~24 ~14 stone 0 
setblock ~21 ~22 ~19 mossy_cobblestone 0  
fill ~21 ~22 ~23 ~21 ~23 ~23 stone 0  
fill ~21 ~22 ~24 ~21 ~22 ~25 cobblestone 0  
fill ~21 ~22 ~28 ~24 ~22 ~28 stone 0  
fill ~21 ~22 ~29 ~21 ~23 ~29 stone 0  
fill ~22 ~22 ~13 ~22 ~22 ~14 cobblestone 0  
fill ~22 ~22 ~19 ~22 ~27 ~19 stone 0 
setblock ~22 ~22 ~21 cobblestone 0  
fill ~22 ~22 ~22 ~27 ~22 ~22 stone 0  
fill ~22 ~22 ~23 ~23 ~22 ~23 mossy_cobblestone 0  
fill ~22 ~22 ~24 ~24 ~22 ~24 stone 0  
fill ~22 ~22 ~25 ~22 ~28 ~25 stone 0  
fill ~22 ~22 ~32 ~22 ~23 ~32 cobblestone 0  
fill ~22 ~22 ~33 ~22 ~22 ~32 cobblestone 0  
fill ~22 ~22 ~35 ~23 ~22 ~35 mossy_cobblestone 0  
fill ~23 ~22 ~7 ~26 ~22 ~7 stone 0 
setblock ~23 ~22 ~8 mossy_cobblestone 0 
setblock ~23 ~22 ~13 mossy_cobblestone 0  
fill ~23 ~22 ~14 ~23 ~33 ~14 stone 0 
setblock ~23 ~22 ~18 cobblestone 0  
fill ~23 ~22 ~21 ~23 ~25 ~21 stone 0 
setblock ~23 ~22 ~30 mossy_cobblestone 0  
fill ~23 ~22 ~32 ~30 ~22 ~32 stone 0  
fill ~24 ~22 ~5 ~24 ~23 ~5 mossy_cobblestone 0  
fill ~24 ~22 ~8 ~29 ~22 ~8 stone 0  
fill ~24 ~22 ~14 ~25 ~22 ~14 cobblestone 0  
fill ~24 ~22 ~19 ~25 ~22 ~19 stone 0  
fill ~24 ~22 ~23 ~25 ~22 ~23 cobblestone 0  
fill ~24 ~22 ~25 ~24 ~23 ~25 stone 0  
fill ~24 ~22 ~29 ~25 ~22 ~29 stone 0  
fill ~24 ~22 ~35 ~24 ~23 ~35 stone 0  
fill ~25 ~22 ~5 ~30 ~22 ~5 stone 0 
setblock ~25 ~22 ~6 mossy_cobblestone 0 
setblock ~25 ~22 ~9 cobblestone 0 
setblock ~25 ~22 ~11 mossy_cobblestone 0  
fill ~25 ~22 ~13 ~26 ~22 ~13 stone 0 
setblock ~25 ~22 ~21 mossy_cobblestone 0  
fill ~25 ~22 ~28 ~25 ~23 ~28 cobblestone 0  
fill ~25 ~22 ~30 ~31 ~22 ~30 stone 0 
setblock ~25 ~22 ~31 mossy_cobblestone 0  
fill ~25 ~22 ~33 ~25 ~24 ~33 stone 0 
setblock ~26 ~22 ~4 cobblestone 0  
fill ~26 ~22 ~6 ~26 ~25 ~6 stone 0  
fill ~26 ~22 ~9 ~31 ~22 ~9 stone 0 
setblock ~26 ~22 ~11 stone 0  
fill ~26 ~22 ~18 ~26 ~28 ~18 stone 0  
fill ~26 ~22 ~24 ~27 ~22 ~24 stone 0 
setblock ~26 ~22 ~27 cobblestone 0 
setblock ~26 ~22 ~29 mossy_cobblestone 0  
fill ~26 ~22 ~31 ~26 ~28 ~31 stone 0 
setblock ~26 ~22 ~33 cobblestone 0 
setblock ~26 ~22 ~35 stone 0  
fill ~27 ~22 ~3 ~27 ~25 ~3 stone 0  
fill ~27 ~22 ~4 ~29 ~22 ~4 stone 0  
fill ~27 ~22 ~6 ~27 ~23 ~6 mossy_cobblestone 0 
setblock ~27 ~22 ~7 cobblestone 0 
setblock ~27 ~22 ~10 mossy_cobblestone 0  
fill ~27 ~22 ~13 ~29 ~22 ~13 mossy_cobblestone 0 
setblock ~27 ~22 ~18 mossy_cobblestone 0 
setblock ~27 ~22 ~21 mossy_cobblestone 0  
fill ~27 ~22 ~25 ~30 ~22 ~25 stone 0  
fill ~27 ~22 ~27 ~27 ~20 ~27 stone 0  
fill ~27 ~22 ~29 ~29 ~22 ~29 stone 0 
setblock ~27 ~22 ~31 mossy_cobblestone 0  
fill ~27 ~22 ~33 ~30 ~22 ~33 stone 0  
fill ~28 ~22 ~10 ~31 ~22 ~10 stone 0  
fill ~28 ~22 ~11 ~28 ~24 ~11 stone 0  
fill ~28 ~22 ~14 ~29 ~22 ~14 stone 0 
setblock ~28 ~22 ~16 cobblestone 0  
fill ~28 ~22 ~18 ~28 ~23 ~18 stone 0 
setblock ~28 ~22 ~22 mossy_cobblestone 0  
fill ~28 ~22 ~23 ~28 ~23 ~23 stone 0 
setblock ~28 ~22 ~24 mossy_cobblestone 0 
setblock ~28 ~22 ~27 cobblestone 0  
fill ~28 ~22 ~31 ~31 ~22 ~31 stone 0 
setblock ~29 ~22 ~6 cobblestone 0  
fill ~29 ~22 ~16 ~30 ~22 ~16 stone 0 
setblock ~29 ~22 ~18 cobblestone 0  
fill ~29 ~22 ~22 ~30 ~22 ~22 stone 0 
setblock ~29 ~22 ~23 cobblestone 0  
fill ~29 ~22 ~24 ~30 ~22 ~24 stone 0  
fill ~29 ~22 ~27 ~29 ~28 ~27 stone 0  
fill ~30 ~22 ~6 ~30 ~24 ~6 stone 0 
setblock ~30 ~22 ~7 mossy_cobblestone 0  
fill ~30 ~22 ~8 ~30 ~24 ~8 cobblestone 0  
fill ~30 ~22 ~13 ~33 ~22 ~13 stone 0 
setblock ~30 ~22 ~14 mossy_cobblestone 0 
setblock ~30 ~22 ~15 cobblestone 0  
fill ~30 ~22 ~19 ~30 ~22 ~20 cobblestone 0 
setblock ~30 ~22 ~23 stone 0 
setblock ~30 ~22 ~26 cobblestone 0  
fill ~30 ~22 ~27 ~31 ~22 ~27 mossy_cobblestone 0  
fill ~30 ~22 ~28 ~30 ~22 ~29 cobblestone 0 
setblock ~30 ~22 ~34 mossy_cobblestone 0  
fill ~31 ~22 ~7 ~31 ~34 ~7 stone 0 
setblock ~31 ~22 ~11 mossy_cobblestone 0  
fill ~31 ~22 ~14 ~34 ~22 ~14 stone 0  
fill ~31 ~22 ~18 ~31 ~22 ~19 mossy_cobblestone 0  
fill ~31 ~22 ~20 ~31 ~24 ~20 stone 0 
setblock ~31 ~22 ~21 mossy_cobblestone 0  
fill ~31 ~22 ~29 ~31 ~27 ~29 stone 0 
setblock ~31 ~22 ~32 cobblestone 0  
fill ~31 ~22 ~34 ~31 ~24 ~34 stone 0  
fill ~32 ~22 ~8 ~32 ~25 ~8 stone 0 
setblock ~32 ~22 ~9 mossy_cobblestone 0  
fill ~32 ~22 ~10 ~34 ~22 ~10 cobblestone 0 
setblock ~32 ~22 ~12 mossy_cobblestone 0  
fill ~32 ~22 ~18 ~32 ~23 ~18 cobblestone 0 
setblock ~32 ~22 ~20 cobblestone 0 
setblock ~32 ~22 ~30 mossy_cobblestone 0 
setblock ~32 ~22 ~33 cobblestone 0  
fill ~33 ~22 ~11 ~35 ~22 ~11 stone 0  
fill ~33 ~22 ~31 ~33 ~23 ~31 stone 0 
setblock ~34 ~22 ~13 cobblestone 0 
setblock ~35 ~22 ~13 stone 0 
setblock ~5 ~23 ~19 cobblestone 0  
fill ~6 ~23 ~18 ~9 ~23 ~18 stone 0  
fill ~6 ~23 ~19 ~9 ~23 ~19 stone 0  
fill ~6 ~23 ~20 ~32 ~23 ~20 stone 0  
fill ~6 ~23 ~21 ~6 ~27 ~21 stone 0  
fill ~7 ~23 ~15 ~7 ~23 ~16 stone 0 
setblock ~7 ~23 ~17 cobblestone 0  
fill ~7 ~23 ~22 ~8 ~23 ~22 stone 0 
setblock ~7 ~23 ~23 mossy_cobblestone 0 
setblock ~8 ~23 ~16 cobblestone 0 
setblock ~8 ~23 ~21 mossy_cobblestone 0  
fill ~8 ~23 ~23 ~29 ~23 ~23 stone 0  
fill ~8 ~23 ~24 ~16 ~23 ~24 stone 0  
fill ~9 ~23 ~15 ~9 ~28 ~15 stone 0  
fill ~9 ~23 ~17 ~13 ~23 ~17 stone 0 
setblock ~9 ~23 ~21 stone 0 
setblock ~9 ~23 ~22 cobblestone 0 
setblock ~9 ~23 ~25 cobblestone 0  
fill ~10 ~23 ~15 ~10 ~23 ~16 cobblestone 0  
fill ~10 ~23 ~18 ~10 ~23 ~19 mossy_cobblestone 0 
setblock ~10 ~23 ~22 mossy_cobblestone 0  
fill ~10 ~23 ~27 ~10 ~24 ~27 stone 0  
fill ~11 ~23 ~14 ~12 ~23 ~14 stone 0 
setblock ~11 ~23 ~15 mossy_cobblestone 0  
fill ~11 ~23 ~18 ~14 ~23 ~18 stone 0  
fill ~11 ~23 ~19 ~13 ~23 ~19 stone 0  
fill ~11 ~23 ~25 ~11 ~25 ~25 stone 0 
setblock ~11 ~23 ~30 stone 0 
setblock ~12 ~23 ~13 stone 0  
fill ~12 ~23 ~25 ~13 ~23 ~25 mossy_cobblestone 0  
fill ~12 ~23 ~29 ~12 ~23 ~31 cobblestone 0 
setblock ~13 ~23 ~14 mossy_cobblestone 0  
fill ~13 ~23 ~15 ~13 ~25 ~15 stone 0  
fill ~13 ~23 ~16 ~18 ~23 ~16 stone 0  
fill ~13 ~23 ~27 ~13 ~23 ~28 cobblestone 0 
setblock ~13 ~23 ~31 cobblestone 0  
fill ~13 ~23 ~32 ~13 ~41 ~32 stone 0  
fill ~14 ~23 ~13 ~24 ~23 ~13 stone 0  
fill ~14 ~23 ~17 ~14 ~22 ~17 cobblestone 0 
setblock ~14 ~23 ~19 mossy_cobblestone 0 
setblock ~14 ~23 ~22 cobblestone 0 
setblock ~14 ~23 ~25 cobblestone 0 
setblock ~14 ~23 ~26 mossy_cobblestone 0  
fill ~14 ~23 ~27 ~19 ~23 ~27 stone 0  
fill ~14 ~23 ~28 ~14 ~41 ~28 stone 0  
fill ~14 ~23 ~30 ~14 ~24 ~30 stone 0  
fill ~15 ~23 ~10 ~20 ~23 ~10 stone 0  
fill ~15 ~23 ~11 ~17 ~23 ~11 stone 0  
fill ~15 ~23 ~17 ~15 ~25 ~17 stone 0 
setblock ~15 ~23 ~18 mossy_cobblestone 0 
setblock ~15 ~23 ~19 cobblestone 0  
fill ~15 ~23 ~22 ~21 ~23 ~22 stone 0  
fill ~15 ~23 ~25 ~22 ~23 ~25 stone 0 
setblock ~15 ~23 ~29 cobblestone 0  
fill ~15 ~23 ~30 ~15 ~23 ~31 mossy_cobblestone 0  
fill ~15 ~23 ~32 ~15 ~27 ~32 stone 0  
fill ~16 ~23 ~14 ~19 ~23 ~14 stone 0 
setblock ~16 ~23 ~15 mossy_cobblestone 0  
fill ~16 ~23 ~18 ~17 ~23 ~18 stone 0  
fill ~16 ~23 ~19 ~16 ~29 ~19 stone 0  
fill ~16 ~23 ~21 ~16 ~24 ~21 stone 0  
fill ~16 ~23 ~29 ~17 ~23 ~29 stone 0  
fill ~16 ~23 ~30 ~16 ~31 ~30 stone 0  
fill ~16 ~23 ~31 ~28 ~23 ~31 stone 0 
setblock ~16 ~23 ~32 cobblestone 0  
fill ~17 ~23 ~9 ~27 ~23 ~9 stone 0  
fill ~17 ~23 ~15 ~18 ~23 ~15 stone 0  
fill ~17 ~23 ~17 ~21 ~23 ~17 stone 0 
setblock ~17 ~23 ~21 mossy_cobblestone 0 
setblock ~17 ~23 ~24 cobblestone 0 
setblock ~17 ~23 ~26 cobblestone 0  
fill ~17 ~23 ~28 ~17 ~33 ~28 stone 0  
fill ~17 ~23 ~32 ~20 ~23 ~32 stone 0 
setblock ~18 ~23 ~11 mossy_cobblestone 0 
setblock ~18 ~23 ~18 mossy_cobblestone 0 
setblock ~18 ~23 ~19 cobblestone 0  
fill ~18 ~23 ~24 ~20 ~23 ~24 stone 0  
fill ~18 ~23 ~28 ~19 ~23 ~28 mossy_cobblestone 0  
fill ~18 ~23 ~29 ~18 ~23 ~30 cobblestone 0 
setblock ~18 ~23 ~33 mossy_cobblestone 0  
fill ~18 ~23 ~34 ~18 ~32 ~34 stone 0  
fill ~19 ~23 ~7 ~19 ~25 ~7 stone 0  
fill ~19 ~23 ~8 ~21 ~23 ~8 stone 0  
fill ~19 ~23 ~11 ~25 ~23 ~11 stone 0 
setblock ~19 ~23 ~16 mossy_cobblestone 0  
fill ~19 ~23 ~18 ~23 ~23 ~18 stone 0 
setblock ~19 ~23 ~21 cobblestone 0  
fill ~19 ~23 ~26 ~21 ~23 ~26 stone 0  
fill ~19 ~23 ~29 ~19 ~25 ~29 stone 0  
fill ~20 ~23 ~12 ~21 ~23 ~12 stone 0  
fill ~20 ~23 ~14 ~20 ~23 ~15 mossy_cobblestone 0  
fill ~20 ~23 ~16 ~21 ~23 ~16 stone 0  
fill ~20 ~23 ~19 ~20 ~29 ~19 stone 0 
setblock ~20 ~23 ~27 cobblestone 0  
fill ~20 ~23 ~28 ~23 ~23 ~28 stone 0  
fill ~20 ~23 ~34 ~23 ~23 ~34 stone 0  
fill ~21 ~23 ~7 ~21 ~29 ~7 stone 0 
setblock ~21 ~23 ~10 mossy_cobblestone 0  
fill ~21 ~23 ~15 ~26 ~23 ~15 stone 0 
setblock ~21 ~23 ~19 cobblestone 0 
setblock ~21 ~23 ~21 mossy_cobblestone 0 
setblock ~21 ~23 ~24 mossy_cobblestone 0  
fill ~21 ~23 ~27 ~21 ~25 ~27 mossy_cobblestone 0 
setblock ~21 ~23 ~32 cobblestone 0 
setblock ~21 ~23 ~35 cobblestone 0  
fill ~22 ~23 ~10 ~34 ~23 ~10 stone 0 
setblock ~22 ~23 ~12 mossy_cobblestone 0  
fill ~22 ~23 ~14 ~22 ~24 ~14 cobblestone 0  
fill ~22 ~23 ~16 ~22 ~24 ~16 cobblestone 0  
fill ~22 ~23 ~17 ~22 ~23 ~16 cobblestone 0  
fill ~22 ~23 ~21 ~22 ~42 ~21 stone 0 
setblock ~22 ~23 ~22 cobblestone 0  
fill ~22 ~23 ~24 ~22 ~30 ~24 stone 0 
setblock ~22 ~23 ~26 mossy_cobblestone 0  
fill ~22 ~23 ~27 ~26 ~23 ~27 stone 0 
setblock ~22 ~23 ~29 mossy_cobblestone 0  
fill ~22 ~23 ~30 ~23 ~23 ~30 stone 0  
fill ~22 ~23 ~33 ~22 ~40 ~33 stone 0  
fill ~22 ~23 ~35 ~25 ~23 ~35 stone 0  
fill ~23 ~23 ~5 ~23 ~27 ~5 stone 0  
fill ~23 ~23 ~6 ~23 ~24 ~6 stone 0  
fill ~23 ~23 ~7 ~23 ~24 ~7 cobblestone 0  
fill ~23 ~23 ~8 ~28 ~23 ~8 stone 0  
fill ~23 ~23 ~12 ~24 ~23 ~12 stone 0  
fill ~23 ~23 ~16 ~25 ~23 ~16 stone 0  
fill ~23 ~23 ~17 ~23 ~25 ~17 stone 0  
fill ~23 ~23 ~22 ~31 ~23 ~22 stone 0  
fill ~23 ~23 ~24 ~23 ~23 ~25 cobblestone 0 
setblock ~23 ~23 ~29 cobblestone 0  
fill ~23 ~23 ~32 ~23 ~24 ~32 stone 0 
setblock ~23 ~23 ~33 cobblestone 0  
fill ~24 ~23 ~7 ~34 ~23 ~7 stone 0  
fill ~24 ~23 ~14 ~26 ~23 ~14 stone 0 
setblock ~24 ~23 ~18 cobblestone 0  
fill ~24 ~23 ~19 ~26 ~23 ~19 stone 0  
fill ~24 ~23 ~26 ~31 ~23 ~26 stone 0 
setblock ~24 ~23 ~28 mossy_cobblestone 0  
fill ~24 ~23 ~29 ~32 ~23 ~29 stone 0 
setblock ~24 ~23 ~30 cobblestone 0 
setblock ~24 ~23 ~32 cobblestone 0  
fill ~24 ~23 ~34 ~24 ~24 ~34 mossy_cobblestone 0  
fill ~25 ~23 ~4 ~29 ~23 ~4 stone 0 
setblock ~25 ~23 ~5 cobblestone 0  
fill ~25 ~23 ~6 ~25 ~26 ~6 stone 0  
fill ~25 ~23 ~12 ~25 ~24 ~12 cobblestone 0  
fill ~25 ~23 ~13 ~25 ~23 ~12 cobblestone 0 
setblock ~25 ~23 ~17 stone 0 
setblock ~25 ~23 ~18 mossy_cobblestone 0  
fill ~25 ~23 ~21 ~25 ~25 ~21 stone 0  
fill ~25 ~23 ~24 ~25 ~34 ~24 stone 0  
fill ~25 ~23 ~30 ~28 ~23 ~30 stone 0 
setblock ~25 ~23 ~34 cobblestone 0 
setblock ~26 ~23 ~3 mossy_cobblestone 0  
fill ~26 ~23 ~5 ~27 ~23 ~5 stone 0  
fill ~26 ~23 ~11 ~27 ~23 ~11 mossy_cobblestone 0  
fill ~26 ~23 ~12 ~28 ~23 ~12 stone 0  
fill ~26 ~23 ~13 ~26 ~25 ~13 stone 0  
fill ~26 ~23 ~16 ~26 ~23 ~17 mossy_cobblestone 0 
setblock ~26 ~23 ~21 mossy_cobblestone 0 
setblock ~26 ~23 ~24 cobblestone 0  
fill ~26 ~23 ~32 ~26 ~36 ~32 stone 0  
fill ~26 ~23 ~33 ~26 ~29 ~33 stone 0  
fill ~26 ~23 ~34 ~28 ~23 ~34 stone 0  
fill ~26 ~23 ~35 ~26 ~24 ~35 mossy_cobblestone 0  
fill ~27 ~23 ~13 ~27 ~23 ~14 cobblestone 0 
setblock ~27 ~23 ~15 mossy_cobblestone 0  
fill ~27 ~23 ~16 ~28 ~23 ~16 stone 0  
fill ~27 ~23 ~17 ~28 ~23 ~17 stone 0  
fill ~27 ~23 ~18 ~27 ~31 ~18 stone 0 
setblock ~27 ~23 ~19 mossy_cobblestone 0  
fill ~27 ~23 ~21 ~27 ~30 ~21 stone 0  
fill ~27 ~23 ~24 ~31 ~23 ~24 stone 0  
fill ~27 ~23 ~25 ~31 ~23 ~25 stone 0 
setblock ~27 ~23 ~27 cobblestone 0  
fill ~27 ~23 ~33 ~27 ~24 ~33 mossy_cobblestone 0 
setblock ~27 ~23 ~35 cobblestone 0 
setblock ~28 ~23 ~5 cobblestone 0  
fill ~28 ~23 ~9 ~29 ~23 ~9 cobblestone 0  
fill ~28 ~23 ~13 ~34 ~23 ~13 stone 0 
setblock ~28 ~23 ~14 cobblestone 0  
fill ~28 ~23 ~27 ~28 ~26 ~27 stone 0  
fill ~28 ~23 ~32 ~29 ~23 ~32 stone 0 
setblock ~28 ~23 ~33 cobblestone 0  
fill ~28 ~23 ~35 ~28 ~24 ~35 stone 0 
setblock ~29 ~23 ~5 mossy_cobblestone 0  
fill ~29 ~23 ~6 ~29 ~28 ~6 stone 0 
setblock ~29 ~23 ~8 mossy_cobblestone 0  
fill ~29 ~23 ~12 ~30 ~23 ~12 cobblestone 0  
fill ~29 ~23 ~14 ~34 ~23 ~14 stone 0 
setblock ~29 ~23 ~16 mossy_cobblestone 0 
setblock ~29 ~23 ~17 cobblestone 0  
fill ~29 ~23 ~18 ~29 ~24 ~18 stone 0 
setblock ~29 ~23 ~30 mossy_cobblestone 0  
fill ~29 ~23 ~31 ~29 ~24 ~31 cobblestone 0  
fill ~29 ~23 ~33 ~32 ~23 ~33 stone 0 
setblock ~29 ~23 ~34 cobblestone 0  
fill ~30 ~23 ~9 ~30 ~25 ~9 stone 0  
fill ~30 ~23 ~15 ~30 ~37 ~15 stone 0  
fill ~30 ~23 ~16 ~30 ~24 ~16 stone 0 
setblock ~30 ~23 ~17 mossy_cobblestone 0  
fill ~30 ~23 ~19 ~31 ~23 ~19 stone 0 
setblock ~30 ~23 ~23 cobblestone 0  
fill ~30 ~23 ~27 ~31 ~23 ~27 stone 0  
fill ~30 ~23 ~28 ~30 ~26 ~28 stone 0  
fill ~30 ~23 ~31 ~30 ~26 ~31 stone 0  
fill ~30 ~23 ~32 ~30 ~24 ~32 cobblestone 0  
fill ~30 ~23 ~34 ~30 ~29 ~34 stone 0  
fill ~30 ~23 ~35 ~30 ~28 ~35 stone 0 
setblock ~31 ~23 ~8 mossy_cobblestone 0  
fill ~31 ~23 ~11 ~31 ~31 ~11 stone 0  
fill ~31 ~23 ~12 ~32 ~23 ~12 stone 0  
fill ~31 ~23 ~17 ~31 ~23 ~30 stone 0 
setblock ~31 ~23 ~31 cobblestone 0  
fill ~31 ~23 ~32 ~31 ~25 ~32 stone 0  
fill ~32 ~23 ~9 ~32 ~33 ~9 stone 0 
setblock ~32 ~23 ~11 mossy_cobblestone 0 
setblock ~32 ~23 ~15 mossy_cobblestone 0 
setblock ~32 ~23 ~19 cobblestone 0  
fill ~32 ~23 ~28 ~32 ~26 ~28 stone 0  
fill ~32 ~23 ~30 ~33 ~23 ~30 stone 0  
fill ~32 ~23 ~31 ~32 ~27 ~31 stone 0 
setblock ~33 ~23 ~6 cobblestone 0  
fill ~33 ~23 ~11 ~35 ~23 ~11 stone 0  
fill ~33 ~23 ~12 ~33 ~24 ~12 mossy_cobblestone 0  
fill ~33 ~23 ~32 ~33 ~27 ~32 stone 0  
fill ~34 ~23 ~6 ~34 ~28 ~6 stone 0 
setblock ~34 ~23 ~9 cobblestone 0 
setblock ~35 ~23 ~8 cobblestone 0  
fill ~35 ~23 ~13 ~35 ~23 ~14 mossy_cobblestone 0  
fill ~36 ~23 ~14 ~36 ~24 ~14 cobblestone 0  
fill ~4 ~24 ~18 ~7 ~24 ~18 stone 0  
fill ~5 ~24 ~19 ~5 ~24 ~21 stone 0  
fill ~6 ~24 ~17 ~9 ~24 ~17 stone 0 
setblock ~6 ~24 ~19 cobblestone 0  
fill ~6 ~24 ~20 ~6 ~28 ~20 stone 0  
fill ~6 ~24 ~22 ~7 ~24 ~22 stone 0 
setblock ~7 ~24 ~15 cobblestone 0  
fill ~7 ~24 ~16 ~21 ~24 ~16 stone 0  
fill ~7 ~24 ~19 ~24 ~24 ~19 stone 0 
setblock ~7 ~24 ~20 cobblestone 0  
fill ~7 ~24 ~23 ~19 ~24 ~23 stone 0  
fill ~8 ~24 ~14 ~9 ~24 ~14 stone 0  
fill ~8 ~24 ~15 ~8 ~25 ~15 stone 0 
setblock ~8 ~24 ~18 cobblestone 0  
fill ~8 ~24 ~21 ~8 ~27 ~21 stone 0 
setblock ~8 ~24 ~22 mossy_cobblestone 0 
setblock ~8 ~24 ~24 mossy_cobblestone 0  
fill ~9 ~24 ~18 ~11 ~24 ~18 stone 0 
setblock ~9 ~24 ~21 mossy_cobblestone 0  
fill ~9 ~24 ~22 ~10 ~24 ~22 stone 0  
fill ~9 ~24 ~24 ~12 ~24 ~24 stone 0 
setblock ~9 ~24 ~25 mossy_cobblestone 0 
setblock ~10 ~24 ~14 cobblestone 0  
fill ~10 ~24 ~15 ~14 ~24 ~15 stone 0 
setblock ~10 ~24 ~17 mossy_cobblestone 0  
fill ~10 ~24 ~20 ~10 ~37 ~20 stone 0  
fill ~10 ~24 ~28 ~10 ~25 ~28 mossy_cobblestone 0  
fill ~11 ~24 ~13 ~11 ~24 ~20 stone 0  
fill ~11 ~24 ~21 ~11 ~24 ~22 mossy_cobblestone 0  
fill ~11 ~24 ~26 ~11 ~25 ~26 mossy_cobblestone 0 
setblock ~11 ~24 ~30 cobblestone 0  
fill ~12 ~24 ~12 ~12 ~26 ~12 stone 0 
setblock ~12 ~24 ~13 cobblestone 0  
fill ~12 ~24 ~14 ~16 ~24 ~14 stone 0  
fill ~12 ~24 ~17 ~24 ~24 ~17 stone 0 
setblock ~12 ~24 ~18 mossy_cobblestone 0  
fill ~12 ~24 ~20 ~12 ~24 ~21 cobblestone 0  
fill ~12 ~24 ~25 ~16 ~24 ~25 stone 0 
setblock ~12 ~24 ~28 mossy_cobblestone 0  
fill ~12 ~24 ~29 ~12 ~32 ~29 stone 0  
fill ~12 ~24 ~30 ~12 ~30 ~30 stone 0  
fill ~12 ~24 ~31 ~13 ~24 ~31 stone 0  
fill ~13 ~24 ~18 ~15 ~24 ~18 stone 0 
setblock ~13 ~24 ~20 mossy_cobblestone 0 
setblock ~13 ~24 ~22 cobblestone 0  
fill ~13 ~24 ~24 ~14 ~24 ~24 cobblestone 0  
fill ~13 ~24 ~27 ~16 ~24 ~27 stone 0  
fill ~13 ~24 ~28 ~13 ~25 ~28 cobblestone 0 
setblock ~14 ~24 ~11 cobblestone 0  
fill ~14 ~24 ~12 ~14 ~28 ~12 stone 0  
fill ~14 ~24 ~13 ~14 ~27 ~13 stone 0  
fill ~14 ~24 ~20 ~14 ~28 ~20 stone 0  
fill ~14 ~24 ~22 ~20 ~24 ~22 stone 0 
setblock ~14 ~24 ~26 stone 0 
setblock ~14 ~24 ~29 mossy_cobblestone 0  
fill ~14 ~24 ~31 ~14 ~25 ~31 cobblestone 0  
fill ~14 ~24 ~32 ~14 ~26 ~32 stone 0  
fill ~15 ~24 ~10 ~17 ~24 ~10 stone 0  
fill ~15 ~24 ~11 ~19 ~24 ~11 stone 0 
setblock ~15 ~24 ~13 cobblestone 0 
setblock ~15 ~24 ~15 cobblestone 0  
fill ~15 ~24 ~29 ~15 ~31 ~29 stone 0  
fill ~15 ~24 ~30 ~15 ~25 ~30 stone 0  
fill ~15 ~24 ~31 ~15 ~26 ~31 stone 0 
setblock ~16 ~24 ~9 cobblestone 0  
fill ~16 ~24 ~13 ~17 ~24 ~13 stone 0  
fill ~16 ~24 ~15 ~17 ~24 ~15 stone 0 
setblock ~16 ~24 ~18 cobblestone 0  
fill ~16 ~24 ~24 ~17 ~24 ~24 mossy_cobblestone 0  
fill ~16 ~24 ~29 ~16 ~25 ~29 mossy_cobblestone 0 
setblock ~16 ~24 ~31 cobblestone 0  
fill ~16 ~24 ~32 ~28 ~24 ~32 stone 0 
setblock ~16 ~24 ~33 mossy_cobblestone 0 
setblock ~17 ~24 ~8 cobblestone 0  
fill ~17 ~24 ~9 ~20 ~24 ~9 stone 0 
setblock ~17 ~24 ~14 cobblestone 0  
fill ~17 ~24 ~18 ~18 ~24 ~18 stone 0  
fill ~17 ~24 ~20 ~17 ~26 ~20 stone 0  
fill ~17 ~24 ~21 ~17 ~31 ~21 stone 0  
fill ~17 ~24 ~25 ~18 ~24 ~25 cobblestone 0  
fill ~17 ~24 ~26 ~17 ~25 ~26 stone 0 
setblock ~17 ~24 ~27 mossy_cobblestone 0  
fill ~17 ~24 ~29 ~20 ~24 ~29 stone 0  
fill ~17 ~24 ~30 ~17 ~25 ~30 cobblestone 0  
fill ~17 ~24 ~31 ~24 ~24 ~31 stone 0  
fill ~18 ~24 ~8 ~18 ~27 ~8 stone 0 
setblock ~18 ~24 ~10 mossy_cobblestone 0 
setblock ~18 ~24 ~13 mossy_cobblestone 0  
fill ~18 ~24 ~14 ~19 ~24 ~14 stone 0 
setblock ~18 ~24 ~15 mossy_cobblestone 0  
fill ~18 ~24 ~24 ~19 ~24 ~24 stone 0 
setblock ~18 ~24 ~28 stone 0  
fill ~18 ~24 ~30 ~18 ~28 ~30 stone 0  
fill ~18 ~24 ~33 ~18 ~29 ~33 stone 0 
setblock ~19 ~24 ~8 mossy_cobblestone 0  
fill ~19 ~24 ~10 ~26 ~24 ~10 stone 0  
fill ~19 ~24 ~13 ~22 ~24 ~13 stone 0  
fill ~19 ~24 ~15 ~24 ~24 ~15 stone 0 
setblock ~19 ~24 ~18 cobblestone 0  
fill ~19 ~24 ~20 ~22 ~24 ~20 stone 0  
fill ~19 ~24 ~21 ~19 ~41 ~21 stone 0 
setblock ~19 ~24 ~25 mossy_cobblestone 0 
setblock ~19 ~24 ~26 cobblestone 0  
fill ~19 ~24 ~28 ~19 ~25 ~28 mossy_cobblestone 0  
fill ~19 ~24 ~34 ~23 ~24 ~34 stone 0  
fill ~20 ~24 ~6 ~20 ~28 ~6 stone 0  
fill ~20 ~24 ~7 ~20 ~24 ~10 stone 0 
setblock ~20 ~24 ~11 mossy_cobblestone 0  
fill ~20 ~24 ~12 ~20 ~27 ~12 stone 0 
setblock ~20 ~24 ~14 cobblestone 0  
fill ~20 ~24 ~18 ~20 ~29 ~18 stone 0  
fill ~20 ~24 ~23 ~20 ~25 ~23 mossy_cobblestone 0 
setblock ~20 ~24 ~24 cobblestone 0  
fill ~20 ~24 ~25 ~23 ~24 ~25 stone 0  
fill ~20 ~24 ~26 ~22 ~24 ~26 stone 0  
fill ~20 ~24 ~27 ~20 ~24 ~34 stone 0  
fill ~21 ~24 ~8 ~22 ~24 ~8 stone 0 
setblock ~21 ~24 ~9 cobblestone 0  
fill ~21 ~24 ~11 ~29 ~24 ~11 stone 0 
setblock ~21 ~24 ~12 mossy_cobblestone 0  
fill ~21 ~24 ~21 ~21 ~37 ~21 stone 0 
setblock ~21 ~24 ~22 mossy_cobblestone 0  
fill ~21 ~24 ~23 ~22 ~24 ~23 cobblestone 0  
fill ~21 ~24 ~24 ~21 ~33 ~24 stone 0  
fill ~21 ~24 ~28 ~23 ~24 ~28 stone 0  
fill ~21 ~24 ~29 ~21 ~24 ~30 cobblestone 0  
fill ~21 ~24 ~35 ~23 ~24 ~35 stone 0  
fill ~22 ~24 ~5 ~22 ~35 ~5 stone 0  
fill ~22 ~24 ~6 ~22 ~25 ~6 stone 0 
setblock ~22 ~24 ~7 cobblestone 0   
fill ~22 ~24 ~9 ~22 ~26 ~9 stone 0  
fill ~22 ~24 ~12 ~24 ~24 ~12 stone 0 
setblock ~22 ~24 ~22 stone 0 
setblock ~22 ~24 ~27 cobblestone 0  
fill ~22 ~24 ~29 ~26 ~24 ~29 stone 0  
fill ~22 ~24 ~30 ~28 ~24 ~30 stone 0  
fill ~23 ~24 ~4 ~23 ~27 ~4 stone 0 
setblock ~23 ~24 ~8 cobblestone 0  
fill ~23 ~24 ~13 ~24 ~24 ~13 mossy_cobblestone 0  
fill ~23 ~24 ~16 ~26 ~24 ~16 stone 0  
fill ~23 ~24 ~18 ~27 ~24 ~18 stone 0 
setblock ~23 ~24 ~20 mossy_cobblestone 0 
setblock ~23 ~24 ~22 mossy_cobblestone 0  
fill ~23 ~24 ~23 ~25 ~24 ~23 stone 0  
fill ~23 ~24 ~24 ~23 ~27 ~24 stone 0 
setblock ~23 ~24 ~26 mossy_cobblestone 0  
fill ~23 ~24 ~27 ~26 ~24 ~27 stone 0  
fill ~23 ~24 ~33 ~23 ~27 ~33 stone 0  
fill ~24 ~24 ~5 ~24 ~31 ~5 stone 0  
fill ~24 ~24 ~7 ~34 ~24 ~7 stone 0  
fill ~24 ~24 ~8 ~24 ~31 ~8 stone 0 
setblock ~24 ~24 ~9 mossy_cobblestone 0  
fill ~24 ~24 ~14 ~24 ~36 ~14 stone 0  
fill ~24 ~24 ~20 ~25 ~24 ~20 stone 0  
fill ~24 ~24 ~22 ~25 ~24 ~22 stone 0 
setblock ~24 ~24 ~25 cobblestone 0  
fill ~24 ~24 ~26 ~24 ~32 ~26 stone 0 
setblock ~24 ~24 ~28 cobblestone 0 
setblock ~24 ~24 ~35 cobblestone 0  
fill ~25 ~24 ~4 ~26 ~24 ~4 stone 0 
setblock ~25 ~24 ~5 mossy_cobblestone 0 
setblock ~25 ~24 ~8 mossy_cobblestone 0 
setblock ~25 ~24 ~9 cobblestone 0  
fill ~25 ~24 ~13 ~25 ~31 ~13 stone 0 
setblock ~25 ~24 ~14 mossy_cobblestone 0 
setblock ~25 ~24 ~15 cobblestone 0 
setblock ~25 ~24 ~17 mossy_cobblestone 0 
setblock ~25 ~24 ~19 mossy_cobblestone 0 
setblock ~25 ~24 ~26 mossy_cobblestone 0  
fill ~25 ~24 ~28 ~25 ~29 ~28 stone 0 
setblock ~25 ~24 ~31 cobblestone 0  
fill ~25 ~24 ~34 ~31 ~24 ~34 stone 0  
fill ~25 ~24 ~35 ~25 ~25 ~35 mossy_cobblestone 0  
fill ~26 ~24 ~3 ~26 ~26 ~3 stone 0  
fill ~26 ~24 ~5 ~33 ~24 ~5 stone 0 
setblock ~26 ~24 ~8 cobblestone 0  
fill ~26 ~24 ~9 ~26 ~25 ~9 stone 0  
fill ~26 ~24 ~12 ~27 ~24 ~12 stone 0 
setblock ~26 ~24 ~14 cobblestone 0  
fill ~26 ~24 ~17 ~30 ~24 ~17 stone 0  
fill ~26 ~24 ~19 ~27 ~24 ~19 stone 0  
fill ~26 ~24 ~20 ~26 ~25 ~20 cobblestone 0  
fill ~26 ~24 ~21 ~26 ~26 ~21 stone 0  
fill ~26 ~24 ~22 ~27 ~24 ~22 cobblestone 0  
fill ~26 ~24 ~23 ~27 ~24 ~23 mossy_cobblestone 0  
fill ~26 ~24 ~24 ~28 ~24 ~24 stone 0  
fill ~26 ~24 ~25 ~26 ~25 ~25 mossy_cobblestone 0 
setblock ~26 ~24 ~36 stone 0  
fill ~27 ~24 ~4 ~28 ~24 ~4 mossy_cobblestone 0  
fill ~27 ~24 ~6 ~27 ~26 ~6 stone 0  
fill ~27 ~24 ~8 ~27 ~26 ~8 stone 0 
setblock ~27 ~24 ~9 cobblestone 0 
setblock ~27 ~24 ~10 mossy_cobblestone 0  
fill ~27 ~24 ~13 ~27 ~24 ~14 mossy_cobblestone 0 
setblock ~27 ~24 ~15 stone 0  
fill ~27 ~24 ~16 ~27 ~27 ~16 cobblestone 0  
fill ~27 ~24 ~20 ~27 ~38 ~20 stone 0 
setblock ~27 ~24 ~25 cobblestone 0 
setblock ~27 ~24 ~27 mossy_cobblestone 0 
setblock ~27 ~24 ~29 cobblestone 0  
fill ~27 ~24 ~31 ~28 ~24 ~31 stone 0  
fill ~27 ~24 ~35 ~27 ~39 ~35 stone 0 
setblock ~28 ~24 ~6 mossy_cobblestone 0 
setblock ~28 ~24 ~8 cobblestone 0  
fill ~28 ~24 ~9 ~30 ~24 ~9 stone 0  
fill ~28 ~24 ~10 ~31 ~24 ~10 stone 0 
setblock ~28 ~24 ~12 mossy_cobblestone 0  
fill ~28 ~24 ~13 ~36 ~24 ~13 stone 0  
fill ~28 ~24 ~14 ~32 ~24 ~14 stone 0 
setblock ~28 ~24 ~15 cobblestone 0  
fill ~28 ~24 ~16 ~31 ~24 ~16 stone 0  
fill ~28 ~24 ~18 ~28 ~26 ~18 mossy_cobblestone 0  
fill ~28 ~24 ~19 ~28 ~24 ~18 mossy_cobblestone 0  
fill ~28 ~24 ~20 ~28 ~25 ~20 cobblestone 0  
fill ~28 ~24 ~22 ~30 ~24 ~22 stone 0  
fill ~28 ~24 ~23 ~29 ~24 ~23 cobblestone 0  
fill ~28 ~24 ~25 ~30 ~24 ~25 stone 0  
fill ~28 ~24 ~26 ~32 ~24 ~26 stone 0  
fill ~28 ~24 ~29 ~28 ~28 ~29 stone 0  
fill ~28 ~24 ~33 ~29 ~24 ~33 stone 0 
setblock ~29 ~24 ~4 stone 0  
fill ~29 ~24 ~8 ~29 ~30 ~8 stone 0  
fill ~29 ~24 ~12 ~32 ~24 ~12 stone 0 
setblock ~29 ~24 ~24 mossy_cobblestone 0 
setblock ~29 ~24 ~28 mossy_cobblestone 0  
fill ~29 ~24 ~29 ~29 ~24 ~32 cobblestone 0  
fill ~29 ~24 ~35 ~29 ~27 ~35 stone 0 
setblock ~29 ~24 ~36 cobblestone 0 
setblock ~30 ~24 ~11 mossy_cobblestone 0  
fill ~30 ~24 ~19 ~32 ~24 ~19 stone 0  
fill ~30 ~24 ~20 ~30 ~33 ~20 stone 0  
fill ~30 ~24 ~23 ~31 ~24 ~23 stone 0  
fill ~30 ~24 ~24 ~31 ~24 ~24 stone 0  
fill ~30 ~24 ~27 ~31 ~24 ~27 stone 0  
fill ~30 ~24 ~29 ~30 ~29 ~29 stone 0 
setblock ~30 ~24 ~33 cobblestone 0  
fill ~31 ~24 ~8 ~31 ~28 ~8 stone 0 
setblock ~31 ~24 ~9 cobblestone 0 
setblock ~31 ~24 ~17 mossy_cobblestone 0  
fill ~31 ~24 ~18 ~32 ~24 ~18 stone 0  
fill ~31 ~24 ~21 ~32 ~24 ~21 stone 0 
setblock ~31 ~24 ~22 cobblestone 0 
setblock ~31 ~24 ~25 cobblestone 0  
fill ~31 ~24 ~30 ~33 ~24 ~30 stone 0  
fill ~31 ~24 ~31 ~31 ~26 ~31 stone 0  
fill ~31 ~24 ~33 ~32 ~24 ~33 stone 0  
fill ~32 ~24 ~6 ~34 ~24 ~6 stone 0 
setblock ~32 ~24 ~10 mossy_cobblestone 0  
fill ~32 ~24 ~11 ~34 ~24 ~11 stone 0  
