fill ~1 ~-1 ~1 ~2 ~-1 ~1 grass 0  
fill ~1 ~-1 ~2 ~2 ~-1 ~2 grass 0  
fill ~1 ~-1 ~3 ~25 ~-1 ~3 grass 0  
fill ~1 ~-1 ~4 ~25 ~-1 ~4 grass 0  
fill ~1 ~-1 ~5 ~25 ~-1 ~5 grass 0  
fill ~1 ~-1 ~6 ~25 ~-1 ~6 grass 0  
fill ~1 ~-1 ~7 ~25 ~-1 ~7 grass 0  
fill ~1 ~-1 ~8 ~25 ~-1 ~8 grass 0  
fill ~1 ~-1 ~9 ~2 ~-1 ~9 grass 0  
fill ~1 ~-1 ~10 ~2 ~-1 ~10 grass 0  
fill ~1 ~-1 ~11 ~2 ~-1 ~11 grass 0  
fill ~1 ~-1 ~12 ~2 ~-1 ~12 grass 0  
fill ~1 ~-1 ~13 ~2 ~-1 ~13 grass 0  
fill ~1 ~-1 ~14 ~2 ~-1 ~14 grass 0  
fill ~1 ~-1 ~15 ~2 ~-1 ~15 grass 0  
fill ~1 ~-1 ~16 ~2 ~-1 ~16 grass 0  
fill ~1 ~-1 ~17 ~2 ~-1 ~17 grass 0  
fill ~1 ~-1 ~18 ~2 ~-1 ~18 grass 0  
fill ~1 ~-1 ~19 ~2 ~-1 ~19 grass 0  
fill ~1 ~-1 ~20 ~2 ~-1 ~20 grass 0  
fill ~1 ~-1 ~21 ~2 ~-1 ~21 grass 0  
fill ~1 ~-1 ~22 ~2 ~-1 ~22 grass 0  
fill ~1 ~-1 ~23 ~2 ~-1 ~23 grass 0  
fill ~1 ~-1 ~24 ~2 ~-1 ~24 grass 0  
fill ~1 ~-1 ~25 ~2 ~-1 ~25 grass 0  
fill ~1 ~-1 ~26 ~2 ~-1 ~26 grass 0  
fill ~1 ~-1 ~27 ~2 ~-1 ~27 grass 0  
fill ~1 ~-1 ~28 ~2 ~-1 ~28 grass 0  
fill ~1 ~-1 ~29 ~2 ~-1 ~29 grass 0  
fill ~1 ~-1 ~30 ~2 ~-1 ~30 grass 0  
fill ~1 ~-1 ~31 ~2 ~-1 ~31 grass 0  
fill ~1 ~-1 ~32 ~2 ~-1 ~32 grass 0  
fill ~1 ~-1 ~33 ~2 ~-1 ~33 grass 0  
fill ~1 ~-1 ~34 ~2 ~-1 ~34 grass 0  
fill ~1 ~-1 ~35 ~2 ~-1 ~35 grass 0  
fill ~1 ~-1 ~36 ~2 ~-1 ~36 grass 0  
fill ~1 ~-1 ~37 ~2 ~-1 ~37 grass 0  
fill ~1 ~-1 ~38 ~2 ~-1 ~38 grass 0  
fill ~1 ~-1 ~39 ~2 ~-1 ~39 grass 0  
fill ~1 ~-1 ~40 ~2 ~-1 ~40 grass 0  
fill ~1 ~-1 ~41 ~2 ~-1 ~41 grass 0  
fill ~1 ~-1 ~42 ~2 ~-1 ~42 grass 0  
fill ~1 ~-1 ~43 ~2 ~-1 ~43 grass 0  
fill ~1 ~-1 ~44 ~2 ~-1 ~44 grass 0  
fill ~1 ~-1 ~45 ~2 ~-1 ~45 grass 0  
fill ~1 ~-1 ~46 ~2 ~-1 ~46 grass 0  
fill ~1 ~-1 ~47 ~2 ~-1 ~47 grass 0  
fill ~1 ~-1 ~48 ~2 ~-1 ~48 grass 0  
fill ~1 ~-1 ~49 ~2 ~-1 ~49 grass 0  
fill ~1 ~-1 ~50 ~2 ~-1 ~50 grass 0  
fill ~1 ~-1 ~51 ~2 ~-1 ~51 grass 0  
fill ~1 ~-1 ~52 ~2 ~-1 ~52 grass 0  
fill ~1 ~-1 ~53 ~2 ~-1 ~53 grass 0  
fill ~1 ~-1 ~54 ~2 ~-1 ~54 grass 0  
fill ~1 ~-1 ~55 ~7 ~-1 ~55 grass 0  
fill ~1 ~-1 ~56 ~7 ~-1 ~56 grass 0  
fill ~1 ~-1 ~57 ~7 ~-1 ~57 grass 0  
fill ~1 ~-1 ~58 ~7 ~-1 ~58 grass 0  
fill ~1 ~-1 ~59 ~7 ~-1 ~59 grass 0  
fill ~1 ~-1 ~60 ~7 ~-1 ~60 grass 0  
fill ~1 ~-1 ~61 ~9 ~-1 ~61 grass 0  
fill ~1 ~-1 ~62 ~7 ~-1 ~62 grass 0  
fill ~1 ~-1 ~63 ~7 ~-1 ~63 grass 0  
fill ~1 ~-1 ~64 ~7 ~-1 ~64 grass 0  
fill ~1 ~-1 ~65 ~9 ~-1 ~65 grass 0  
fill ~1 ~-1 ~66 ~9 ~-1 ~66 grass 0  
fill ~1 ~-1 ~67 ~9 ~-1 ~67 grass 0  
fill ~1 ~-1 ~68 ~9 ~-1 ~68 grass 0  
fill ~1 ~-1 ~69 ~9 ~-1 ~69 grass 0  
fill ~1 ~-1 ~70 ~9 ~-1 ~70 grass 0  
fill ~1 ~-1 ~71 ~9 ~-1 ~71 grass 0  
fill ~1 ~-1 ~72 ~9 ~-1 ~72 grass 0  
fill ~1 ~-1 ~73 ~9 ~-1 ~73 grass 0  
fill ~1 ~-1 ~74 ~10 ~-1 ~74 grass 0  
fill ~1 ~-1 ~75 ~24 ~-1 ~75 grass 0  
fill ~1 ~-1 ~76 ~24 ~-1 ~76 grass 0  
fill ~1 ~-1 ~77 ~24 ~-1 ~77 grass 0  
fill ~1 ~-1 ~78 ~2 ~-1 ~78 grass 0  
fill ~1 ~-1 ~79 ~2 ~-1 ~79 grass 0  
fill ~1 ~-1 ~80 ~2 ~-1 ~80 grass 0  
fill ~1 ~-1 ~81 ~2 ~-1 ~81 grass 0  
fill ~1 ~-1 ~82 ~2 ~-1 ~82 grass 0  
fill ~1 ~-1 ~83 ~2 ~-1 ~83 grass 0  
fill ~1 ~-1 ~84 ~2 ~-1 ~84 grass 0  
fill ~1 ~-1 ~85 ~2 ~-1 ~85 grass 0  
fill ~1 ~-1 ~86 ~2 ~-1 ~86 grass 0  
fill ~1 ~-1 ~87 ~2 ~-1 ~87 grass 0  
fill ~1 ~-1 ~88 ~2 ~-1 ~88 grass 0  
fill ~1 ~-1 ~89 ~2 ~-1 ~89 grass 0  
fill ~1 ~-1 ~90 ~2 ~-1 ~90 grass 0  
fill ~1 ~-1 ~91 ~2 ~-1 ~91 grass 0  
fill ~1 ~-1 ~92 ~2 ~-1 ~92 grass 0  
fill ~1 ~-1 ~93 ~2 ~-1 ~93 grass 0  
fill ~1 ~-1 ~94 ~24 ~-1 ~94 grass 0  
fill ~1 ~-1 ~95 ~24 ~-1 ~95 grass 0  
fill ~1 ~-1 ~96 ~24 ~-1 ~96 grass 0  
fill ~1 ~-1 ~97 ~24 ~-1 ~97 grass 0  
fill ~1 ~-1 ~98 ~24 ~-1 ~98 grass 0  
fill ~1 ~-1 ~99 ~24 ~-1 ~99 grass 0  
fill ~1 ~-1 ~100 ~24 ~-1 ~100 grass 0  
fill ~1 ~-1 ~101 ~24 ~-1 ~101 grass 0  
fill ~1 ~-1 ~102 ~24 ~-1 ~102 grass 0  
fill ~1 ~-1 ~103 ~24 ~-1 ~103 grass 0  
fill ~1 ~-1 ~104 ~2 ~-1 ~104 grass 0  
fill ~1 ~-1 ~105 ~24 ~-1 ~105 grass 0  
fill ~1 ~-1 ~106 ~2 ~-1 ~106 grass 0  
fill ~1 ~-1 ~107 ~24 ~-1 ~107 grass 0  
fill ~1 ~-1 ~108 ~24 ~-1 ~108 grass 0  
fill ~1 ~-1 ~109 ~24 ~-1 ~109 grass 0  
fill ~1 ~-1 ~110 ~24 ~-1 ~110 grass 0  
fill ~1 ~-1 ~111 ~24 ~-1 ~111 grass 0  
fill ~1 ~-1 ~112 ~24 ~-1 ~112 grass 0  
fill ~1 ~-1 ~113 ~24 ~-1 ~113 grass 0  
fill ~1 ~-1 ~114 ~24 ~-1 ~114 grass 0  
fill ~1 ~-1 ~115 ~24 ~-1 ~115 grass 0  
fill ~1 ~-1 ~116 ~24 ~-1 ~116 grass 0  
fill ~1 ~-1 ~117 ~24 ~-1 ~117 grass 0  
fill ~1 ~-1 ~118 ~24 ~-1 ~118 grass 0  
fill ~1 ~-1 ~119 ~24 ~-1 ~119 grass 0  
fill ~1 ~-1 ~120 ~24 ~-1 ~120 grass 0  
fill ~1 ~-1 ~121 ~24 ~-1 ~121 grass 0  
fill ~1 ~-1 ~122 ~24 ~-1 ~122 grass 0  
fill ~1 ~-1 ~123 ~24 ~-1 ~123 grass 0  
fill ~1 ~-1 ~124 ~24 ~-1 ~124 grass 0  
fill ~1 ~-1 ~125 ~24 ~-1 ~125 grass 0  
fill ~1 ~-1 ~126 ~24 ~-1 ~126 grass 0  
fill ~1 ~-1 ~127 ~24 ~-1 ~127 grass 0  
fill ~1 ~-1 ~128 ~24 ~-1 ~128 grass 0  
fill ~1 ~-1 ~129 ~24 ~-1 ~129 grass 0  
fill ~1 ~-1 ~130 ~24 ~-1 ~130 grass 0  
fill ~1 ~-1 ~131 ~24 ~-1 ~131 grass 0  
fill ~1 ~-1 ~132 ~2 ~-1 ~132 grass 0  
fill ~1 ~-1 ~133 ~24 ~-1 ~133 grass 0  
fill ~1 ~-1 ~134 ~2 ~-1 ~134 grass 0  
fill ~1 ~-1 ~135 ~89 ~-1 ~135 grass 0  
fill ~1 ~-1 ~136 ~120 ~-1 ~136 grass 0  
fill ~1 ~-1 ~137 ~120 ~-1 ~137 grass 0  
fill ~1 ~-1 ~138 ~120 ~-1 ~138 grass 0  
fill ~1 ~-1 ~139 ~120 ~-1 ~139 grass 0  
fill ~1 ~-1 ~140 ~120 ~-1 ~140 grass 0  
fill ~1 ~-1 ~141 ~120 ~-1 ~141 grass 0  
fill ~1 ~-1 ~142 ~120 ~-1 ~142 grass 0  
fill ~1 ~-1 ~143 ~1 ~-1 ~159 dirt 0  
fill ~2 ~-1 ~143 ~120 ~-1 ~143 grass 0  
fill ~2 ~-1 ~144 ~3 ~-1 ~144 dirt 0  
fill ~2 ~-1 ~145 ~4 ~-1 ~145 dirt 0  
fill ~2 ~-1 ~146 ~5 ~-1 ~146 dirt 0  
fill ~2 ~-1 ~147 ~6 ~-1 ~147 dirt 0  
fill ~2 ~-1 ~148 ~6 ~-1 ~148 dirt 0  
fill ~2 ~-1 ~149 ~6 ~-1 ~149 dirt 0  
fill ~2 ~-1 ~150 ~6 ~-1 ~150 dirt 0  
fill ~2 ~-1 ~151 ~6 ~-1 ~151 dirt 0  
fill ~2 ~-1 ~152 ~6 ~-1 ~152 dirt 0  
fill ~2 ~-1 ~153 ~7 ~-1 ~153 dirt 0  
fill ~2 ~-1 ~154 ~7 ~-1 ~154 dirt 0  
fill ~2 ~-1 ~155 ~11 ~-1 ~155 dirt 0  
fill ~2 ~-1 ~156 ~15 ~-1 ~156 dirt 0  
fill ~2 ~-1 ~157 ~17 ~-1 ~157 dirt 0  
fill ~2 ~-1 ~158 ~19 ~-1 ~158 dirt 0  
fill ~2 ~-1 ~159 ~22 ~-1 ~159 dirt 0  
fill ~3 ~-1 ~1 ~116 ~-1 ~1 dirt 0  
fill ~3 ~-1 ~2 ~114 ~-1 ~2 dirt 0  
fill ~3 ~-1 ~9 ~24 ~-1 ~9 dirt 0  
fill ~3 ~-1 ~10 ~24 ~-1 ~10 dirt 0  
fill ~3 ~-1 ~11 ~24 ~-1 ~11 dirt 0  
fill ~3 ~-1 ~12 ~24 ~-1 ~12 dirt 0  
fill ~3 ~-1 ~13 ~24 ~-1 ~13 dirt 0  
fill ~3 ~-1 ~14 ~23 ~-1 ~14 dirt 0  
fill ~3 ~-1 ~15 ~5 ~-1 ~15 dirt 0  
fill ~3 ~-1 ~16 ~23 ~-1 ~16 dirt 0  
fill ~3 ~-1 ~17 ~24 ~-1 ~17 dirt 0  
fill ~3 ~-1 ~18 ~24 ~-1 ~18 dirt 0  
fill ~3 ~-1 ~19 ~28 ~-1 ~19 dirt 0  
fill ~3 ~-1 ~20 ~28 ~-1 ~20 dirt 0  
fill ~3 ~-1 ~21 ~27 ~-1 ~21 dirt 0  
fill ~3 ~-1 ~22 ~27 ~-1 ~22 dirt 0  
fill ~3 ~-1 ~23 ~26 ~-1 ~23 dirt 0  
fill ~3 ~-1 ~24 ~24 ~-1 ~24 dirt 0  
fill ~3 ~-1 ~25 ~24 ~-1 ~25 dirt 0  
fill ~3 ~-1 ~26 ~24 ~-1 ~26 dirt 0  
fill ~3 ~-1 ~27 ~24 ~-1 ~27 dirt 0  
fill ~3 ~-1 ~28 ~24 ~-1 ~28 dirt 0  
fill ~3 ~-1 ~29 ~24 ~-1 ~29 dirt 0  
fill ~3 ~-1 ~30 ~24 ~-1 ~30 dirt 0  
fill ~3 ~-1 ~31 ~7 ~-1 ~31 dirt 0  
fill ~3 ~-1 ~32 ~24 ~-1 ~32 dirt 0  
fill ~3 ~-1 ~33 ~24 ~-1 ~33 dirt 0  
fill ~3 ~-1 ~34 ~24 ~-1 ~34 dirt 0  
fill ~3 ~-1 ~35 ~24 ~-1 ~35 dirt 0  
fill ~3 ~-1 ~36 ~28 ~-1 ~36 dirt 0  
fill ~3 ~-1 ~37 ~28 ~-1 ~37 dirt 0  
fill ~3 ~-1 ~38 ~24 ~-1 ~38 dirt 0  
fill ~3 ~-1 ~39 ~24 ~-1 ~39 dirt 0  
fill ~3 ~-1 ~40 ~14 ~-1 ~40 dirt 0  
fill ~3 ~-1 ~41 ~24 ~-1 ~41 dirt 0  
fill ~3 ~-1 ~42 ~23 ~-1 ~42 dirt 0  
fill ~3 ~-1 ~43 ~24 ~-1 ~43 dirt 0  
fill ~3 ~-1 ~44 ~24 ~-1 ~44 dirt 0  
fill ~3 ~-1 ~45 ~24 ~-1 ~45 dirt 0  
fill ~3 ~-1 ~46 ~8 ~-1 ~46 dirt 0  
fill ~3 ~-1 ~47 ~8 ~-1 ~47 dirt 0  
fill ~3 ~-1 ~48 ~8 ~-1 ~48 dirt 0  
fill ~3 ~-1 ~49 ~8 ~-1 ~49 dirt 0  
fill ~3 ~-1 ~50 ~8 ~-1 ~50 dirt 0  
fill ~3 ~-1 ~51 ~5 ~-1 ~51 dirt 0  
fill ~3 ~-1 ~52 ~22 ~-1 ~52 dirt 0  
fill ~3 ~-1 ~53 ~8 ~-1 ~53 dirt 0  
fill ~3 ~-1 ~54 ~15 ~-1 ~54 dirt 0  
fill ~3 ~-1 ~78 ~15 ~-1 ~78 dirt 0  
fill ~3 ~-1 ~79 ~7 ~-1 ~79 dirt 0  
fill ~3 ~-1 ~80 ~8 ~-1 ~80 dirt 0  
fill ~3 ~-1 ~81 ~7 ~-1 ~81 dirt 0  
fill ~3 ~-1 ~82 ~7 ~-1 ~82 dirt 0  
fill ~3 ~-1 ~83 ~7 ~-1 ~83 dirt 0  
fill ~3 ~-1 ~84 ~7 ~-1 ~84 dirt 0  
fill ~3 ~-1 ~85 ~7 ~-1 ~85 dirt 0  
fill ~3 ~-1 ~86 ~6 ~-1 ~86 dirt 0  
fill ~3 ~-1 ~87 ~6 ~-1 ~87 dirt 0  
fill ~3 ~-1 ~88 ~6 ~-1 ~88 dirt 0  
fill ~3 ~-1 ~89 ~6 ~-1 ~89 dirt 0  
fill ~3 ~-1 ~90 ~5 ~-1 ~90 dirt 0  
fill ~3 ~-1 ~91 ~6 ~-1 ~91 dirt 0  
fill ~3 ~-1 ~92 ~6 ~-1 ~92 dirt 0  
fill ~3 ~-1 ~93 ~4 ~-1 ~93 dirt 0  
fill ~3 ~-1 ~104 ~15 ~-1 ~104 dirt 0  
fill ~3 ~-1 ~106 ~15 ~-1 ~106 dirt 0  
fill ~3 ~-1 ~132 ~15 ~-1 ~132 dirt 0  
fill ~3 ~-1 ~134 ~15 ~-1 ~134 dirt 0  
fill ~4 ~-1 ~144 ~120 ~-1 ~144 grass 0  
fill ~5 ~-1 ~93 ~24 ~-1 ~93 grass 0  
fill ~5 ~-1 ~145 ~27 ~-1 ~145 grass 0 
setblock ~6 ~-1 ~15 grass 0 
setblock ~6 ~-1 ~51 grass 0  
fill ~6 ~-1 ~90 ~24 ~-1 ~90 grass 0  
fill ~6 ~-1 ~146 ~25 ~-1 ~146 grass 0  
fill ~7 ~-1 ~15 ~23 ~-1 ~15 dirt 0  
fill ~7 ~-1 ~51 ~8 ~-1 ~51 dirt 0  
fill ~7 ~-1 ~86 ~24 ~-1 ~86 grass 0  
fill ~7 ~-1 ~87 ~24 ~-1 ~87 grass 0  
fill ~7 ~-1 ~88 ~24 ~-1 ~88 grass 0  
fill ~7 ~-1 ~89 ~24 ~-1 ~89 grass 0  
fill ~7 ~-1 ~91 ~24 ~-1 ~91 grass 0  
fill ~7 ~-1 ~92 ~24 ~-1 ~92 grass 0  
fill ~7 ~-1 ~147 ~25 ~-1 ~147 grass 0  
fill ~7 ~-1 ~148 ~25 ~-1 ~148 grass 0  
fill ~7 ~-1 ~149 ~25 ~-1 ~149 grass 0  
fill ~7 ~-1 ~150 ~25 ~-1 ~150 grass 0  
fill ~7 ~-1 ~151 ~25 ~-1 ~151 grass 0  
fill ~7 ~-1 ~152 ~25 ~-1 ~152 grass 0 
setblock ~8 ~-1 ~31 grass 0  
fill ~8 ~-1 ~55 ~8 ~-1 ~60 dirt 0  
fill ~8 ~-1 ~62 ~8 ~-1 ~64 dirt 0  
fill ~8 ~-1 ~79 ~24 ~-1 ~79 grass 0  
fill ~8 ~-1 ~81 ~24 ~-1 ~81 grass 0  
fill ~8 ~-1 ~82 ~24 ~-1 ~82 grass 0  
fill ~8 ~-1 ~83 ~24 ~-1 ~83 grass 0  
fill ~8 ~-1 ~84 ~24 ~-1 ~84 grass 0  
fill ~8 ~-1 ~85 ~24 ~-1 ~85 grass 0  
fill ~8 ~-1 ~153 ~25 ~-1 ~153 grass 0  
fill ~8 ~-1 ~154 ~25 ~-1 ~154 grass 0  
fill ~9 ~-1 ~31 ~24 ~-1 ~31 dirt 0  
fill ~9 ~-1 ~46 ~9 ~-1 ~51 grass 0  
fill ~9 ~-1 ~53 ~16 ~-1 ~53 grass 0  
fill ~9 ~-1 ~55 ~17 ~-1 ~55 grass 0  
fill ~9 ~-1 ~56 ~9 ~-1 ~77 grass 0 
setblock ~9 ~-1 ~80 grass 0  
fill ~10 ~-1 ~46 ~24 ~-1 ~46 dirt 0  
fill ~10 ~-1 ~47 ~24 ~-1 ~47 dirt 0  
fill ~10 ~-1 ~48 ~23 ~-1 ~48 dirt 0  
fill ~10 ~-1 ~49 ~22 ~-1 ~49 dirt 0  
fill ~10 ~-1 ~50 ~10 ~-1 ~51 grass 0  
fill ~10 ~-1 ~56 ~15 ~-1 ~56 dirt 0  
fill ~10 ~-1 ~57 ~24 ~-1 ~57 dirt 0  
fill ~10 ~-1 ~58 ~14 ~-1 ~58 dirt 0  
fill ~10 ~-1 ~59 ~13 ~-1 ~59 dirt 0  
fill ~10 ~-1 ~60 ~13 ~-1 ~60 dirt 0  
fill ~10 ~-1 ~61 ~13 ~-1 ~61 dirt 0  
fill ~10 ~-1 ~62 ~13 ~-1 ~62 dirt 0  
fill ~10 ~-1 ~63 ~13 ~-1 ~63 dirt 0  
fill ~10 ~-1 ~64 ~13 ~-1 ~64 dirt 0  
fill ~10 ~-1 ~65 ~22 ~-1 ~65 dirt 0  
fill ~10 ~-1 ~66 ~21 ~-1 ~66 dirt 0  
fill ~10 ~-1 ~67 ~21 ~-1 ~67 dirt 0  
fill ~10 ~-1 ~68 ~22 ~-1 ~68 dirt 0  
fill ~10 ~-1 ~69 ~21 ~-1 ~69 dirt 0  
fill ~10 ~-1 ~70 ~20 ~-1 ~70 dirt 0  
fill ~10 ~-1 ~71 ~19 ~-1 ~71 dirt 0  
fill ~10 ~-1 ~72 ~17 ~-1 ~72 dirt 0  
fill ~10 ~-1 ~73 ~15 ~-1 ~73 dirt 0  
fill ~10 ~-1 ~80 ~15 ~-1 ~80 dirt 0  
fill ~11 ~-1 ~50 ~21 ~-1 ~50 dirt 0  
fill ~11 ~-1 ~51 ~14 ~-1 ~51 grass 0  
fill ~11 ~-1 ~74 ~13 ~-1 ~74 dirt 0  
fill ~12 ~-1 ~155 ~25 ~-1 ~155 grass 0  
fill ~14 ~-1 ~59 ~18 ~-1 ~59 grass 0  
fill ~14 ~-1 ~60 ~18 ~-1 ~60 grass 0  
fill ~14 ~-1 ~61 ~18 ~-1 ~61 grass 0  
fill ~14 ~-1 ~62 ~18 ~-1 ~62 grass 0  
fill ~14 ~-1 ~63 ~16 ~-1 ~63 grass 0  
fill ~14 ~-1 ~64 ~14 ~-1 ~59 grass 0  
fill ~14 ~-1 ~74 ~24 ~-1 ~74 grass 0 
setblock ~15 ~-1 ~40 grass 0  
fill ~15 ~-1 ~51 ~21 ~-1 ~51 dirt 0  
fill ~15 ~-1 ~58 ~16 ~-1 ~58 grass 0  
fill ~15 ~-1 ~64 ~23 ~-1 ~64 dirt 0  
fill ~16 ~-1 ~40 ~24 ~-1 ~40 dirt 0 
setblock ~16 ~-1 ~54 grass 0  
fill ~16 ~-1 ~56 ~20 ~-1 ~56 grass 0  
fill ~16 ~-1 ~73 ~24 ~-1 ~73 grass 0  
fill ~16 ~-1 ~78 ~24 ~-1 ~78 grass 0  
fill ~16 ~-1 ~80 ~24 ~-1 ~80 grass 0  
fill ~16 ~-1 ~104 ~24 ~-1 ~104 grass 0  
fill ~16 ~-1 ~106 ~24 ~-1 ~106 grass 0  
fill ~16 ~-1 ~132 ~24 ~-1 ~132 grass 0  
fill ~16 ~-1 ~134 ~24 ~-1 ~134 grass 0  
fill ~16 ~-1 ~156 ~25 ~-1 ~156 grass 0  
fill ~17 ~-1 ~53 ~23 ~-1 ~53 dirt 0  
fill ~17 ~-1 ~54 ~24 ~-1 ~54 dirt 0  
fill ~17 ~-1 ~58 ~24 ~-1 ~58 dirt 0  
fill ~17 ~-1 ~63 ~24 ~-1 ~63 dirt 0  
fill ~18 ~-1 ~55 ~24 ~-1 ~55 dirt 0  
fill ~18 ~-1 ~72 ~24 ~-1 ~72 grass 0  
fill ~18 ~-1 ~157 ~25 ~-1 ~157 grass 0  
fill ~19 ~-1 ~59 ~24 ~-1 ~59 dirt 0  
fill ~19 ~-1 ~60 ~24 ~-1 ~60 dirt 0  
fill ~19 ~-1 ~61 ~24 ~-1 ~61 dirt 0  
fill ~19 ~-1 ~62 ~24 ~-1 ~62 dirt 0  
fill ~20 ~-1 ~71 ~24 ~-1 ~71 grass 0  
fill ~20 ~-1 ~158 ~120 ~-1 ~158 grass 0  
fill ~21 ~-1 ~56 ~24 ~-1 ~56 dirt 0  
fill ~21 ~-1 ~70 ~24 ~-1 ~70 grass 0  
fill ~22 ~-1 ~50 ~24 ~-1 ~50 grass 0  
fill ~22 ~-1 ~51 ~24 ~-1 ~51 grass 0  
fill ~22 ~-1 ~66 ~24 ~-1 ~66 grass 0  
fill ~22 ~-1 ~67 ~25 ~-1 ~67 grass 0  
fill ~22 ~-1 ~69 ~25 ~-1 ~69 grass 0  
fill ~23 ~-1 ~49 ~24 ~-1 ~49 grass 0  
fill ~23 ~-1 ~52 ~24 ~-1 ~52 grass 0  
fill ~23 ~-1 ~65 ~24 ~-1 ~65 grass 0  
fill ~23 ~-1 ~68 ~25 ~-1 ~68 grass 0  
fill ~23 ~-1 ~159 ~120 ~-1 ~159 grass 0  
fill ~24 ~-1 ~14 ~24 ~-1 ~16 grass 0 
setblock ~24 ~-1 ~42 grass 0 
setblock ~24 ~-1 ~48 grass 0 
setblock ~24 ~-1 ~53 grass 0 
setblock ~24 ~-1 ~64 grass 0  
fill ~25 ~-1 ~9 ~38 ~-1 ~9 stone 0  
fill ~25 ~-1 ~10 ~38 ~-1 ~10 stone 0  
fill ~25 ~-1 ~11 ~37 ~-1 ~11 stone 0  
fill ~25 ~-1 ~12 ~38 ~-1 ~12 stone 0  
fill ~25 ~-1 ~13 ~38 ~-1 ~13 stone 0  
fill ~25 ~-1 ~14 ~37 ~-1 ~14 stone 0  
fill ~25 ~-1 ~15 ~27 ~-1 ~15 stone 0  
fill ~25 ~-1 ~16 ~26 ~-1 ~16 stone 0  
fill ~25 ~-1 ~17 ~26 ~-1 ~17 stone 0  
fill ~25 ~-1 ~18 ~25 ~0 ~18 stone 0  
fill ~25 ~-1 ~24 ~25 ~-1 ~25 gravel 0  
fill ~25 ~-1 ~26 ~30 ~-1 ~26 stone 0  
fill ~25 ~-1 ~27 ~26 ~-1 ~27 gravel 0  
fill ~25 ~-1 ~28 ~27 ~-1 ~28 gravel 0  
fill ~25 ~-1 ~29 ~27 ~-1 ~29 gravel 0  
fill ~25 ~-1 ~30 ~25 ~-1 ~35 stone 0  
fill ~25 ~-1 ~38 ~26 ~-1 ~38 stone 0  
fill ~25 ~-1 ~39 ~26 ~-1 ~39 stone 0  
fill ~25 ~-1 ~40 ~26 ~-1 ~40 stone 0  
fill ~25 ~-1 ~41 ~26 ~-1 ~41 stone 0  
fill ~25 ~-1 ~42 ~25 ~-1 ~66 stone 0  
fill ~25 ~-1 ~70 ~26 ~-1 ~70 sand 0  
fill ~25 ~-1 ~71 ~26 ~-1 ~71 sand 0  
fill ~25 ~-1 ~72 ~26 ~-1 ~72 sand 0  
fill ~25 ~-1 ~73 ~26 ~-1 ~73 sand 0  
fill ~25 ~-1 ~74 ~26 ~-1 ~74 sand 0  
fill ~25 ~-1 ~75 ~26 ~-1 ~75 sand 0  
fill ~25 ~-1 ~76 ~26 ~-1 ~76 sand 0  
fill ~25 ~-1 ~77 ~26 ~-1 ~77 sand 0  
fill ~25 ~-1 ~78 ~26 ~-1 ~78 sand 0  
fill ~25 ~-1 ~79 ~26 ~-1 ~79 sand 0  
fill ~25 ~-1 ~80 ~26 ~-1 ~80 sand 0  
fill ~25 ~-1 ~81 ~26 ~-1 ~81 sand 0  
fill ~26 ~-1 ~3 ~34 ~-1 ~3 sand 0  
fill ~26 ~-1 ~4 ~32 ~-1 ~4 sand 0  
fill ~26 ~-1 ~5 ~28 ~-1 ~5 sandstone 0  
fill ~26 ~-1 ~6 ~29 ~-1 ~6 sandstone 0  
fill ~26 ~-1 ~7 ~37 ~-1 ~7 sandstone 0  
fill ~26 ~-1 ~8 ~27 ~-1 ~8 stone 0  
fill ~26 ~-1 ~18 ~29 ~-1 ~18 dirt 0  
fill ~26 ~-1 ~24 ~29 ~-1 ~24 stone 0  
fill ~26 ~-1 ~25 ~28 ~-1 ~25 stone 0  
fill ~26 ~-1 ~30 ~26 ~-1 ~31 gravel 0  
fill ~26 ~-1 ~32 ~26 ~0 ~32 stone 0  
fill ~26 ~-1 ~33 ~26 ~0 ~33 stone 0  
fill ~26 ~-1 ~34 ~28 ~-1 ~34 dirt 0  
fill ~26 ~-1 ~35 ~28 ~-1 ~35 dirt 0  
fill ~26 ~-1 ~43 ~26 ~-1 ~45 gravel 0  
fill ~26 ~-1 ~46 ~26 ~0 ~46 stone 0  
fill ~26 ~-1 ~47 ~26 ~0 ~47 stone 0  
fill ~26 ~-1 ~48 ~26 ~0 ~48 stone 0  
fill ~26 ~-1 ~49 ~26 ~0 ~49 stone 0  
fill ~26 ~-1 ~50 ~26 ~0 ~50 stone 0  
fill ~26 ~-1 ~51 ~26 ~0 ~51 stone 0  
fill ~26 ~-1 ~52 ~26 ~0 ~52 stone 0  
fill ~26 ~-1 ~53 ~26 ~0 ~53 stone 0  
fill ~26 ~-1 ~54 ~26 ~0 ~54 stone 0  
fill ~26 ~-1 ~55 ~26 ~0 ~55 stone 0  
fill ~26 ~-1 ~56 ~26 ~0 ~56 stone 0  
fill ~26 ~-1 ~57 ~26 ~0 ~57 stone 0  
fill ~26 ~-1 ~58 ~26 ~0 ~58 stone 0  
fill ~26 ~-1 ~59 ~26 ~0 ~59 stone 0  
fill ~26 ~-1 ~60 ~26 ~0 ~60 stone 0  
fill ~26 ~-1 ~61 ~26 ~0 ~61 stone 0  
fill ~26 ~-1 ~62 ~26 ~0 ~62 stone 0  
fill ~26 ~-1 ~63 ~26 ~0 ~63 stone 0  
fill ~26 ~-1 ~64 ~26 ~0 ~64 stone 0  
fill ~26 ~-1 ~65 ~28 ~-1 ~65 dirt 0  
fill ~26 ~-1 ~66 ~28 ~-1 ~66 dirt 0  
fill ~26 ~-1 ~67 ~28 ~-1 ~67 dirt 0  
fill ~26 ~-1 ~68 ~28 ~-1 ~68 dirt 0 
setblock ~26 ~-1 ~69 sand 0  
fill ~26 ~-1 ~86 ~28 ~-1 ~86 dirt 0  
fill ~26 ~-1 ~129 ~26 ~0 ~129 stone 0  
fill ~26 ~-1 ~146 ~26 ~-1 ~157 dirt 0  
fill ~27 ~-1 ~16 ~29 ~-1 ~16 dirt 0  
fill ~27 ~-1 ~17 ~29 ~-1 ~17 dirt 0  
fill ~27 ~-1 ~23 ~30 ~-1 ~23 stone 0  
fill ~27 ~-1 ~27 ~27 ~0 ~27 stone 0  
fill ~27 ~-1 ~30 ~28 ~-1 ~30 dirt 0  
fill ~27 ~-1 ~31 ~28 ~-1 ~31 dirt 0  
fill ~27 ~-1 ~32 ~28 ~-1 ~32 dirt 0  
fill ~27 ~-1 ~33 ~28 ~-1 ~33 dirt 0  
fill ~27 ~-1 ~38 ~28 ~-1 ~38 dirt 0  
fill ~27 ~-1 ~39 ~28 ~-1 ~39 dirt 0  
fill ~27 ~-1 ~40 ~28 ~-1 ~40 dirt 0  
fill ~27 ~-1 ~41 ~28 ~-1 ~41 dirt 0  
fill ~27 ~-1 ~42 ~28 ~-1 ~42 dirt 0  
fill ~27 ~-1 ~43 ~28 ~-1 ~43 dirt 0  
fill ~27 ~-1 ~44 ~28 ~-1 ~44 dirt 0  
fill ~27 ~-1 ~45 ~28 ~-1 ~45 dirt 0  
fill ~27 ~-1 ~46 ~28 ~-1 ~46 dirt 0  
fill ~27 ~-1 ~47 ~28 ~-1 ~47 dirt 0  
fill ~27 ~-1 ~48 ~28 ~-1 ~48 dirt 0  
fill ~27 ~-1 ~49 ~28 ~-1 ~49 dirt 0  
fill ~27 ~-1 ~50 ~28 ~-1 ~50 dirt 0  
fill ~27 ~-1 ~51 ~28 ~-1 ~51 dirt 0  
fill ~27 ~-1 ~52 ~28 ~-1 ~52 dirt 0  
fill ~27 ~-1 ~53 ~28 ~-1 ~53 dirt 0  
fill ~27 ~-1 ~54 ~28 ~-1 ~54 dirt 0  
fill ~27 ~-1 ~55 ~28 ~-1 ~55 dirt 0  
fill ~27 ~-1 ~56 ~28 ~-1 ~56 dirt 0  
fill ~27 ~-1 ~57 ~28 ~-1 ~57 dirt 0  
fill ~27 ~-1 ~58 ~28 ~-1 ~58 dirt 0  
fill ~27 ~-1 ~59 ~28 ~-1 ~59 dirt 0  
fill ~27 ~-1 ~60 ~28 ~-1 ~60 dirt 0  
fill ~27 ~-1 ~61 ~28 ~-1 ~61 dirt 0  
fill ~27 ~-1 ~62 ~28 ~-1 ~62 dirt 0  
fill ~27 ~-1 ~63 ~28 ~-1 ~63 dirt 0  
fill ~27 ~-1 ~64 ~28 ~-1 ~64 dirt 0  
fill ~27 ~-1 ~69 ~28 ~-1 ~69 dirt 0  
fill ~27 ~-1 ~70 ~28 ~-1 ~70 dirt 0  
fill ~27 ~-1 ~71 ~28 ~-1 ~71 dirt 0  
fill ~27 ~-1 ~72 ~28 ~-1 ~72 dirt 0  
fill ~27 ~-1 ~73 ~28 ~-1 ~73 dirt 0  
fill ~27 ~-1 ~74 ~28 ~-1 ~74 dirt 0  
fill ~27 ~-1 ~75 ~28 ~-1 ~75 dirt 0  
fill ~27 ~-1 ~76 ~28 ~-1 ~76 dirt 0  
fill ~27 ~-1 ~77 ~28 ~-1 ~77 dirt 0  
fill ~27 ~-1 ~78 ~28 ~-1 ~78 dirt 0  
fill ~27 ~-1 ~79 ~28 ~-1 ~79 dirt 0  
fill ~27 ~-1 ~80 ~28 ~-1 ~80 dirt 0  
fill ~27 ~-1 ~81 ~28 ~-1 ~81 dirt 0  
fill ~27 ~-1 ~82 ~28 ~-1 ~82 dirt 0  
fill ~27 ~-1 ~83 ~28 ~-1 ~83 dirt 0  
fill ~27 ~-1 ~84 ~28 ~-1 ~84 dirt 0  
fill ~27 ~-1 ~85 ~28 ~-1 ~85 dirt 0  
fill ~27 ~-1 ~87 ~28 ~-1 ~87 dirt 0  
fill ~27 ~-1 ~88 ~28 ~-1 ~88 dirt 0  
fill ~27 ~-1 ~89 ~28 ~-1 ~89 dirt 0  
fill ~27 ~-1 ~90 ~28 ~-1 ~90 dirt 0  
fill ~27 ~-1 ~91 ~28 ~-1 ~91 dirt 0  
fill ~27 ~-1 ~92 ~28 ~-1 ~92 dirt 0  
fill ~27 ~-1 ~93 ~28 ~-1 ~93 dirt 0  
fill ~27 ~-1 ~94 ~28 ~-1 ~94 dirt 0  
fill ~27 ~-1 ~95 ~28 ~-1 ~95 dirt 0  
fill ~27 ~-1 ~96 ~28 ~-1 ~96 dirt 0  
fill ~27 ~-1 ~97 ~28 ~-1 ~97 dirt 0  
fill ~27 ~-1 ~98 ~28 ~-1 ~98 dirt 0  
fill ~27 ~-1 ~99 ~28 ~-1 ~99 dirt 0  
fill ~27 ~-1 ~100 ~28 ~-1 ~100 dirt 0  
fill ~27 ~-1 ~101 ~28 ~-1 ~101 dirt 0  
fill ~27 ~-1 ~102 ~28 ~-1 ~102 dirt 0  
fill ~27 ~-1 ~103 ~28 ~-1 ~103 dirt 0  
fill ~27 ~-1 ~104 ~28 ~-1 ~104 dirt 0  
fill ~27 ~-1 ~105 ~28 ~-1 ~105 dirt 0  
fill ~27 ~-1 ~106 ~28 ~-1 ~106 dirt 0  
fill ~27 ~-1 ~107 ~28 ~-1 ~107 dirt 0  
fill ~27 ~-1 ~108 ~28 ~-1 ~108 dirt 0  
fill ~27 ~-1 ~109 ~28 ~-1 ~109 dirt 0  
fill ~27 ~-1 ~110 ~28 ~-1 ~110 dirt 0  
fill ~27 ~-1 ~111 ~28 ~-1 ~111 dirt 0  
fill ~27 ~-1 ~112 ~28 ~-1 ~112 dirt 0  
fill ~27 ~-1 ~113 ~28 ~-1 ~113 dirt 0  
fill ~27 ~-1 ~114 ~28 ~-1 ~114 dirt 0  
fill ~27 ~-1 ~115 ~28 ~-1 ~115 dirt 0  
fill ~27 ~-1 ~116 ~28 ~-1 ~116 dirt 0  
fill ~27 ~-1 ~117 ~28 ~-1 ~117 dirt 0  
fill ~27 ~-1 ~118 ~28 ~-1 ~118 dirt 0  
fill ~27 ~-1 ~119 ~28 ~-1 ~119 dirt 0  
fill ~27 ~-1 ~120 ~28 ~-1 ~120 dirt 0  
fill ~27 ~-1 ~121 ~28 ~-1 ~121 dirt 0  
fill ~27 ~-1 ~122 ~28 ~-1 ~122 dirt 0  
fill ~27 ~-1 ~123 ~28 ~-1 ~123 dirt 0  
fill ~27 ~-1 ~124 ~28 ~-1 ~124 dirt 0  
fill ~27 ~-1 ~125 ~28 ~-1 ~125 dirt 0  
fill ~27 ~-1 ~126 ~28 ~-1 ~126 dirt 0  
fill ~27 ~-1 ~127 ~28 ~-1 ~127 dirt 0  
fill ~27 ~-1 ~128 ~28 ~-1 ~128 dirt 0  
fill ~27 ~-1 ~129 ~28 ~-1 ~129 dirt 0  
fill ~27 ~-1 ~130 ~27 ~0 ~130 stone 0  
fill ~27 ~-1 ~131 ~27 ~0 ~131 stone 0  
fill ~27 ~-1 ~132 ~96 ~-1 ~132 dirt 0  
fill ~27 ~-1 ~133 ~96 ~-1 ~133 dirt 0  
fill ~27 ~-1 ~146 ~27 ~-1 ~159 grass 0 
setblock ~28 ~-1 ~8 sandstone 0 
setblock ~28 ~-1 ~15 dirt 0  
fill ~28 ~-1 ~21 ~36 ~-1 ~21 stone 0  
fill ~28 ~-1 ~22 ~36 ~-1 ~22 stone 0  
fill ~28 ~-1 ~27 ~97 ~-1 ~27 dirt 0  
fill ~28 ~-1 ~28 ~28 ~-1 ~133 dirt 0  
fill ~28 ~-1 ~145 ~28 ~-1 ~157 dirt 0 
setblock ~29 ~-1 ~5 dirt 0 
setblock ~29 ~-1 ~8 stone 0  
fill ~29 ~-1 ~15 ~37 ~-1 ~15 stone 0  
fill ~29 ~-1 ~19 ~36 ~-1 ~19 stone 0  
fill ~29 ~-1 ~20 ~36 ~-1 ~20 stone 0  
fill ~29 ~-1 ~28 ~93 ~-1 ~28 grass 0  
fill ~29 ~-1 ~29 ~29 ~-1 ~131 grass 0  
fill ~29 ~-1 ~145 ~54 ~-1 ~145 grass 0  
fill ~29 ~-1 ~146 ~54 ~-1 ~146 grass 0  
fill ~29 ~-1 ~147 ~54 ~-1 ~147 grass 0  
fill ~29 ~-1 ~148 ~54 ~-1 ~148 grass 0  
fill ~29 ~-1 ~149 ~54 ~-1 ~149 grass 0  
fill ~29 ~-1 ~150 ~54 ~-1 ~150 grass 0  
fill ~29 ~-1 ~151 ~54 ~-1 ~151 grass 0  
fill ~29 ~-1 ~152 ~54 ~-1 ~152 grass 0  
fill ~29 ~-1 ~153 ~54 ~-1 ~153 grass 0  
fill ~29 ~-1 ~154 ~54 ~-1 ~154 grass 0  
fill ~29 ~-1 ~155 ~54 ~-1 ~155 grass 0  
fill ~29 ~-1 ~156 ~54 ~-1 ~156 grass 0  
fill ~29 ~-1 ~157 ~54 ~-1 ~157 grass 0  
fill ~30 ~-1 ~5 ~37 ~-1 ~5 sandstone 0  
fill ~30 ~-1 ~6 ~31 ~-1 ~6 dirt 0  
fill ~30 ~-1 ~8 ~33 ~-1 ~8 sandstone 0  
fill ~30 ~-1 ~16 ~37 ~-1 ~16 stone 0  
fill ~30 ~-1 ~17 ~37 ~-1 ~17 stone 0  
fill ~30 ~-1 ~18 ~36 ~-1 ~18 stone 0  
fill ~30 ~-1 ~29 ~92 ~-1 ~29 wool 0  
fill ~30 ~-1 ~30 ~30 ~-1 ~130 wool 0  
fill ~30 ~-1 ~131 ~93 ~-1 ~131 grass 0  
fill ~31 ~-1 ~25 ~32 ~-1 ~25 stone 0  
fill ~31 ~-1 ~26 ~97 ~-1 ~26 dirt 0  
fill ~31 ~-1 ~30 ~32 ~-1 ~30 grass 0  
fill ~31 ~-1 ~31 ~31 ~-1 ~30 grass 0  
fill ~31 ~-1 ~32 ~32 ~-1 ~32 wool 0  
fill ~31 ~-1 ~33 ~43 ~-1 ~33 wool 13  
fill ~31 ~-1 ~34 ~43 ~-1 ~34 grass 0  
fill ~31 ~-1 ~35 ~43 ~-1 ~35 grass 0  
fill ~31 ~-1 ~36 ~43 ~-1 ~36 wool 13  
fill ~31 ~-1 ~37 ~43 ~-1 ~37 wool 13  
fill ~31 ~-1 ~38 ~43 ~-1 ~38 grass 0  
fill ~31 ~-1 ~39 ~43 ~-1 ~39 grass 0  
fill ~31 ~-1 ~40 ~43 ~-1 ~40 wool 13  
fill ~31 ~-1 ~41 ~43 ~-1 ~41 wool 13  
fill ~31 ~-1 ~42 ~43 ~-1 ~42 grass 0  
fill ~31 ~-1 ~43 ~43 ~-1 ~43 grass 0  
fill ~31 ~-1 ~44 ~43 ~-1 ~44 wool 13  
fill ~31 ~-1 ~45 ~43 ~-1 ~45 wool 13  
fill ~31 ~-1 ~46 ~56 ~-1 ~46 grass 0  
fill ~31 ~-1 ~47 ~57 ~-1 ~47 grass 0  
fill ~31 ~-1 ~48 ~58 ~-1 ~48 wool 13  
fill ~31 ~-1 ~49 ~59 ~-1 ~49 wool 13  
fill ~31 ~-1 ~50 ~91 ~-1 ~50 grass 0  
fill ~31 ~-1 ~51 ~91 ~-1 ~51 grass 0  
fill ~31 ~-1 ~52 ~91 ~-1 ~52 wool 13  
fill ~31 ~-1 ~53 ~91 ~-1 ~53 wool 13  
fill ~31 ~-1 ~54 ~91 ~-1 ~54 grass 0  
fill ~31 ~-1 ~55 ~91 ~-1 ~55 grass 0  
fill ~31 ~-1 ~56 ~91 ~-1 ~56 wool 13  
fill ~31 ~-1 ~57 ~91 ~-1 ~57 wool 13  
fill ~31 ~-1 ~58 ~91 ~-1 ~58 grass 0  
fill ~31 ~-1 ~59 ~91 ~-1 ~59 grass 0  
fill ~31 ~-1 ~60 ~91 ~-1 ~60 wool 13  
fill ~31 ~-1 ~61 ~91 ~-1 ~61 wool 13  
fill ~31 ~-1 ~62 ~91 ~-1 ~62 grass 0  
fill ~31 ~-1 ~63 ~91 ~-1 ~63 grass 0  
fill ~31 ~-1 ~64 ~91 ~-1 ~64 wool 13  
fill ~31 ~-1 ~65 ~91 ~-1 ~65 wool 13  
fill ~31 ~-1 ~66 ~91 ~-1 ~66 grass 0  
fill ~31 ~-1 ~67 ~91 ~-1 ~67 grass 0  
fill ~31 ~-1 ~68 ~91 ~-1 ~68 wool 13  
fill ~31 ~-1 ~69 ~91 ~-1 ~69 wool 13  
fill ~31 ~-1 ~70 ~91 ~-1 ~70 grass 0  
fill ~31 ~-1 ~71 ~58 ~-1 ~71 grass 0  
fill ~31 ~-1 ~72 ~56 ~-1 ~72 wool 13  
fill ~31 ~-1 ~73 ~55 ~-1 ~73 wool 13  
fill ~31 ~-1 ~74 ~54 ~-1 ~74 grass 0  
fill ~31 ~-1 ~75 ~53 ~-1 ~75 grass 0  
fill ~31 ~-1 ~76 ~53 ~-1 ~76 wool 13  
fill ~31 ~-1 ~77 ~52 ~-1 ~77 wool 13  
fill ~31 ~-1 ~78 ~52 ~-1 ~78 grass 0  
fill ~31 ~-1 ~79 ~92 ~-1 ~79 wool 0  
fill ~31 ~-1 ~80 ~52 ~-1 ~80 wool 13  
fill ~31 ~-1 ~81 ~52 ~-1 ~81 grass 0  
fill ~31 ~-1 ~82 ~53 ~-1 ~82 grass 0  
fill ~31 ~-1 ~83 ~53 ~-1 ~83 wool 13  
fill ~31 ~-1 ~84 ~54 ~-1 ~84 wool 13  
fill ~31 ~-1 ~85 ~55 ~-1 ~85 grass 0  
fill ~31 ~-1 ~86 ~56 ~-1 ~86 grass 0  
fill ~31 ~-1 ~87 ~58 ~-1 ~87 wool 13  
fill ~31 ~-1 ~88 ~91 ~-1 ~88 wool 13  
fill ~31 ~-1 ~89 ~91 ~-1 ~89 grass 0  
fill ~31 ~-1 ~90 ~91 ~-1 ~90 grass 0  
fill ~31 ~-1 ~91 ~91 ~-1 ~91 wool 13  
fill ~31 ~-1 ~92 ~91 ~-1 ~92 wool 13  
fill ~31 ~-1 ~93 ~91 ~-1 ~93 grass 0  
fill ~31 ~-1 ~94 ~91 ~-1 ~94 grass 0  
fill ~31 ~-1 ~95 ~91 ~-1 ~95 wool 13  
fill ~31 ~-1 ~96 ~91 ~-1 ~96 wool 13  
fill ~31 ~-1 ~97 ~91 ~-1 ~97 grass 0  
fill ~31 ~-1 ~98 ~91 ~-1 ~98 grass 0  
fill ~31 ~-1 ~99 ~91 ~-1 ~99 wool 13  
fill ~31 ~-1 ~100 ~91 ~-1 ~100 wool 13  
fill ~31 ~-1 ~101 ~91 ~-1 ~101 grass 0  
fill ~31 ~-1 ~102 ~91 ~-1 ~102 grass 0  
fill ~31 ~-1 ~103 ~91 ~-1 ~103 wool 13  
fill ~31 ~-1 ~104 ~91 ~-1 ~104 wool 13  
fill ~31 ~-1 ~105 ~91 ~-1 ~105 grass 0  
fill ~31 ~-1 ~106 ~91 ~-1 ~106 grass 0  
fill ~31 ~-1 ~107 ~91 ~-1 ~107 wool 13  
fill ~31 ~-1 ~108 ~91 ~-1 ~108 wool 13  
fill ~31 ~-1 ~109 ~91 ~-1 ~109 grass 0  
fill ~31 ~-1 ~110 ~59 ~-1 ~110 grass 0  
fill ~31 ~-1 ~111 ~58 ~-1 ~111 wool 13  
fill ~31 ~-1 ~112 ~57 ~-1 ~112 wool 13  
fill ~31 ~-1 ~113 ~56 ~-1 ~113 grass 0  
fill ~31 ~-1 ~114 ~43 ~-1 ~114 grass 0  
fill ~31 ~-1 ~115 ~43 ~-1 ~115 wool 13  
fill ~31 ~-1 ~116 ~43 ~-1 ~116 wool 13  
fill ~31 ~-1 ~117 ~43 ~-1 ~117 grass 0  
fill ~31 ~-1 ~118 ~43 ~-1 ~118 grass 0  
fill ~31 ~-1 ~119 ~43 ~-1 ~119 wool 13  
fill ~31 ~-1 ~120 ~43 ~-1 ~120 wool 13  
fill ~31 ~-1 ~121 ~43 ~-1 ~121 grass 0  
fill ~31 ~-1 ~122 ~43 ~-1 ~122 grass 0  
fill ~31 ~-1 ~123 ~43 ~-1 ~123 wool 13  
fill ~31 ~-1 ~124 ~43 ~-1 ~124 wool 13  
fill ~31 ~-1 ~125 ~43 ~-1 ~125 grass 0  
fill ~31 ~-1 ~126 ~43 ~-1 ~126 grass 0  
fill ~31 ~-1 ~127 ~32 ~-1 ~127 wool 0 
setblock ~31 ~-1 ~128 wool 13  
fill ~31 ~-1 ~129 ~32 ~-1 ~129 grass 0  
fill ~31 ~-1 ~130 ~92 ~-1 ~130 wool 0  
fill ~32 ~-1 ~6 ~33 ~-1 ~6 sandstone 0  
fill ~32 ~-1 ~23 ~33 ~-1 ~23 stone 0  
fill ~32 ~-1 ~31 ~33 ~-1 ~31 wool 0  
fill ~32 ~-1 ~128 ~33 ~-1 ~128 wool 0  
fill ~33 ~-1 ~4 ~35 ~-1 ~4 sandstone 0 
setblock ~33 ~-1 ~30 wool 0  
fill ~33 ~-1 ~32 ~43 ~-1 ~32 wool 13  
fill ~33 ~-1 ~127 ~43 ~-1 ~127 wool 13 
setblock ~33 ~-1 ~129 wool 0 
setblock ~34 ~-1 ~6 stone 0  
fill ~34 ~-1 ~8 ~39 ~-1 ~8 stone 0  
fill ~34 ~-1 ~30 ~43 ~-1 ~30 grass 0  
fill ~34 ~-1 ~31 ~43 ~-1 ~31 grass 0  
fill ~34 ~-1 ~128 ~43 ~-1 ~128 wool 13  
fill ~34 ~-1 ~129 ~43 ~-1 ~129 grass 0 
setblock ~35 ~-1 ~3 sandstone 0 
setblock ~35 ~-1 ~6 sandstone 0  
fill ~36 ~-1 ~3 ~38 ~-1 ~3 stone 0 
setblock ~36 ~-1 ~4 dirt 0  
fill ~36 ~-1 ~6 ~36 ~1 ~6 sand 0 
setblock ~37 ~-1 ~4 stone 0 
setblock ~37 ~-1 ~6 coal_ore 0  
fill ~37 ~-1 ~18 ~39 ~-1 ~18 dirt 0 
setblock ~37 ~-1 ~19 grass 0  
fill ~37 ~-1 ~20 ~39 ~-1 ~20 dirt 0  
fill ~37 ~-1 ~21 ~39 ~-1 ~21 dirt 0  
fill ~38 ~-1 ~4 ~45 ~-1 ~4 dirt 0  
fill ~38 ~-1 ~5 ~45 ~-1 ~5 dirt 0  
fill ~38 ~-1 ~6 ~45 ~-1 ~6 dirt 0 
setblock ~38 ~-1 ~7 coal_ore 0 
setblock ~38 ~-1 ~11 sandstone 0 
setblock ~38 ~-1 ~14 sand 0  
fill ~38 ~-1 ~15 ~120 ~-1 ~15 grass 0  
fill ~38 ~-1 ~16 ~120 ~-1 ~16 grass 0  
fill ~38 ~-1 ~17 ~40 ~-1 ~17 dirt 0  
fill ~38 ~-1 ~19 ~39 ~-1 ~19 dirt 0  
fill ~38 ~-1 ~22 ~39 ~-1 ~22 grass 0  
fill ~39 ~-1 ~3 ~45 ~-1 ~3 dirt 0 
setblock ~39 ~-1 ~7 stone 0  
fill ~39 ~-1 ~9 ~54 ~-1 ~9 grass 0  
fill ~39 ~-1 ~10 ~54 ~-1 ~10 grass 0 
setblock ~39 ~-1 ~11 stone 0  
fill ~39 ~-1 ~12 ~54 ~-1 ~12 grass 0  
fill ~39 ~-1 ~13 ~54 ~-1 ~13 grass 0  
fill ~39 ~-1 ~14 ~54 ~-1 ~14 grass 0  
fill ~40 ~-1 ~7 ~63 ~-1 ~7 dirt 0  
fill ~40 ~-1 ~8 ~54 ~-1 ~8 grass 0  
fill ~40 ~-1 ~11 ~54 ~-1 ~11 grass 0  
fill ~40 ~-1 ~18 ~46 ~-1 ~18 grass 0  
fill ~40 ~-1 ~19 ~44 ~-1 ~19 grass 0  
fill ~40 ~-1 ~20 ~45 ~-1 ~20 grass 0  
fill ~40 ~-1 ~21 ~45 ~-1 ~21 grass 0 
setblock ~40 ~-1 ~22 dirt 0  
fill ~40 ~-1 ~23 ~45 ~-1 ~23 grass 0  
fill ~40 ~-1 ~24 ~44 ~-1 ~24 grass 0  
fill ~40 ~-1 ~25 ~44 ~-1 ~25 dirt 0  
fill ~41 ~-1 ~17 ~47 ~-1 ~17 grass 0  
fill ~41 ~-1 ~22 ~45 ~-1 ~22 grass 0  
fill ~44 ~-1 ~30 ~44 ~-1 ~45 wool 0  
fill ~44 ~-1 ~114 ~78 ~-1 ~114 wool 0  
fill ~44 ~-1 ~115 ~44 ~-1 ~130 wool 0  
fill ~45 ~-1 ~25 ~46 ~-1 ~25 stone 0  
fill ~45 ~-1 ~30 ~54 ~-1 ~30 grass 0  
fill ~45 ~-1 ~31 ~54 ~-1 ~31 grass 0  
fill ~45 ~-1 ~32 ~54 ~-1 ~32 wool 13  
fill ~45 ~-1 ~33 ~54 ~-1 ~33 wool 13  
fill ~45 ~-1 ~34 ~54 ~-1 ~34 grass 0  
fill ~45 ~-1 ~35 ~54 ~-1 ~35 grass 0  
fill ~45 ~-1 ~36 ~54 ~-1 ~36 wool 13  
fill ~45 ~-1 ~37 ~77 ~-1 ~37 wool 13  
fill ~45 ~-1 ~38 ~77 ~-1 ~38 grass 0  
fill ~45 ~-1 ~39 ~77 ~-1 ~39 grass 0  
fill ~45 ~-1 ~40 ~60 ~-1 ~40 wool 13  
fill ~45 ~-1 ~41 ~77 ~-1 ~41 wool 13  
fill ~45 ~-1 ~42 ~77 ~-1 ~42 grass 0  
fill ~45 ~-1 ~43 ~77 ~-1 ~43 grass 0  
fill ~45 ~-1 ~44 ~77 ~-1 ~44 wool 13  
fill ~45 ~-1 ~45 ~78 ~-1 ~45 wool 0  
fill ~45 ~-1 ~115 ~77 ~-1 ~115 wool 13  
fill ~45 ~-1 ~116 ~77 ~-1 ~116 wool 13  
fill ~45 ~-1 ~117 ~77 ~-1 ~117 grass 0  
fill ~45 ~-1 ~118 ~77 ~-1 ~118 grass 0  
fill ~45 ~-1 ~119 ~60 ~-1 ~119 wool 13  
fill ~45 ~-1 ~120 ~77 ~-1 ~120 wool 13  
fill ~45 ~-1 ~121 ~77 ~-1 ~121 grass 0  
fill ~45 ~-1 ~122 ~77 ~-1 ~122 grass 0  
fill ~45 ~-1 ~123 ~54 ~-1 ~123 wool 13  
fill ~45 ~-1 ~124 ~54 ~-1 ~124 wool 13  
fill ~45 ~-1 ~125 ~54 ~-1 ~125 grass 0  
fill ~45 ~-1 ~126 ~54 ~-1 ~126 grass 0  
fill ~45 ~-1 ~127 ~54 ~-1 ~127 wool 13  
fill ~45 ~-1 ~128 ~54 ~-1 ~128 wool 13  
fill ~45 ~-1 ~129 ~54 ~-1 ~129 grass 0  
fill ~46 ~-1 ~3 ~47 ~-1 ~3 grass 0  
fill ~46 ~-1 ~4 ~46 ~-1 ~6 grass 0  
fill ~47 ~-1 ~5 ~47 ~-1 ~6 grass 0  
fill ~50 ~-1 ~17 ~120 ~-1 ~17 grass 0  
fill ~51 ~-1 ~5 ~52 ~-1 ~5 grass 0  
fill ~51 ~-1 ~6 ~65 ~-1 ~6 dirt 0  
fill ~52 ~-1 ~3 ~81 ~-1 ~3 dirt 0  
fill ~52 ~-1 ~4 ~67 ~-1 ~4 dirt 0  
fill ~53 ~-1 ~5 ~67 ~-1 ~5 dirt 0  
fill ~53 ~-1 ~77 ~53 ~-1 ~81 wool 0  
fill ~54 ~-1 ~75 ~54 ~-1 ~76 wool 0  
fill ~54 ~-1 ~77 ~68 ~-1 ~77 wool 13  
fill ~54 ~-1 ~78 ~68 ~-1 ~78 grass 0  
fill ~54 ~-1 ~80 ~68 ~-1 ~80 wool 13  
fill ~54 ~-1 ~81 ~68 ~-1 ~81 grass 0  
fill ~54 ~-1 ~82 ~54 ~-1 ~83 wool 0  
fill ~55 ~-1 ~8 ~55 ~-1 ~14 dirt 0  
fill ~55 ~-1 ~18 ~120 ~-1 ~18 grass 0  
fill ~55 ~-1 ~30 ~55 ~-1 ~36 wool 0 
setblock ~55 ~-1 ~74 wool 0  
fill ~55 ~-1 ~75 ~67 ~-1 ~75 grass 0  
fill ~55 ~-1 ~76 ~67 ~-1 ~76 wool 13  
fill ~55 ~-1 ~82 ~67 ~-1 ~82 grass 0  
fill ~55 ~-1 ~83 ~67 ~-1 ~83 wool 13 
setblock ~55 ~-1 ~84 wool 0  
fill ~55 ~-1 ~123 ~67 ~-1 ~123 wool 0  
fill ~55 ~-1 ~124 ~55 ~-1 ~130 wool 0  
fill ~55 ~-1 ~134 ~57 ~-1 ~134 dirt 0  
fill ~55 ~-1 ~145 ~55 ~-1 ~157 dirt 0  
fill ~56 ~-1 ~8 ~56 ~-1 ~24 grass 0 
setblock ~56 ~-1 ~25 dirt 0  
fill ~56 ~-1 ~30 ~66 ~-1 ~30 grass 0  
fill ~56 ~-1 ~31 ~66 ~-1 ~31 grass 0  
fill ~56 ~-1 ~32 ~66 ~-1 ~32 wool 13  
fill ~56 ~-1 ~33 ~66 ~-1 ~33 wool 13  
fill ~56 ~-1 ~34 ~66 ~-1 ~34 grass 0  
fill ~56 ~-1 ~35 ~66 ~-1 ~35 grass 0  
fill ~56 ~-1 ~36 ~67 ~-1 ~36 wool 0 
setblock ~56 ~-1 ~73 wool 0  
fill ~56 ~-1 ~74 ~66 ~-1 ~74 grass 0  
fill ~56 ~-1 ~84 ~66 ~-1 ~84 wool 13 
setblock ~56 ~-1 ~85 wool 0  
fill ~56 ~-1 ~124 ~66 ~-1 ~124 wool 13  
fill ~56 ~-1 ~125 ~66 ~-1 ~125 grass 0  
fill ~56 ~-1 ~126 ~66 ~-1 ~126 grass 0  
fill ~56 ~-1 ~127 ~66 ~-1 ~127 wool 13  
fill ~56 ~-1 ~128 ~66 ~-1 ~128 wool 13  
fill ~56 ~-1 ~129 ~66 ~-1 ~129 grass 0  
fill ~56 ~-1 ~145 ~56 ~-1 ~159 grass 0  
fill ~57 ~-1 ~8 ~57 ~-1 ~14 dirt 0 
setblock ~57 ~-1 ~46 wool 0  
fill ~57 ~-1 ~72 ~58 ~-1 ~72 wool 0  
fill ~57 ~-1 ~73 ~65 ~-1 ~73 wool 13  
fill ~57 ~-1 ~85 ~65 ~-1 ~85 grass 0  
fill ~57 ~-1 ~86 ~58 ~-1 ~86 wool 0 
setblock ~57 ~-1 ~113 wool 0  
fill ~57 ~-1 ~145 ~57 ~-1 ~146 dirt 0  
fill ~57 ~-1 ~147 ~64 ~-1 ~147 grass 0  
fill ~57 ~-1 ~148 ~57 ~-1 ~157 dirt 0  
fill ~58 ~-1 ~8 ~64 ~-1 ~8 grass 0  
fill ~58 ~-1 ~9 ~64 ~-1 ~9 grass 0  
fill ~58 ~-1 ~10 ~64 ~-1 ~10 grass 0  
fill ~58 ~-1 ~11 ~64 ~-1 ~11 grass 0  
fill ~58 ~-1 ~12 ~64 ~-1 ~12 grass 0  
fill ~58 ~-1 ~13 ~64 ~-1 ~13 grass 0  
fill ~58 ~-1 ~14 ~64 ~-1 ~14 grass 0  
fill ~58 ~-1 ~19 ~120 ~-1 ~19 grass 0  
fill ~58 ~-1 ~25 ~59 ~-1 ~25 stone 0  
fill ~58 ~-1 ~46 ~64 ~-1 ~46 grass 0 
setblock ~58 ~-1 ~47 wool 0 
setblock ~58 ~-1 ~112 wool 0  
fill ~58 ~-1 ~113 ~64 ~-1 ~113 grass 0  
fill ~58 ~-1 ~145 ~64 ~-1 ~145 grass 0  
fill ~58 ~-1 ~146 ~64 ~-1 ~146 grass 0  
fill ~58 ~-1 ~148 ~64 ~-1 ~148 grass 0  
fill ~58 ~-1 ~149 ~64 ~-1 ~149 grass 0  
fill ~58 ~-1 ~150 ~64 ~-1 ~150 grass 0  
fill ~58 ~-1 ~151 ~64 ~-1 ~151 grass 0  
fill ~58 ~-1 ~152 ~64 ~-1 ~152 grass 0   
fill ~58 ~-1 ~153 ~64 ~-1 ~153 grass 0  
fill ~58 ~-1 ~154 ~64 ~-1 ~154 grass 0  
fill ~58 ~-1 ~155 ~64 ~-1 ~155 grass 0  
fill ~58 ~-1 ~156 ~64 ~-1 ~156 grass 0  
fill ~58 ~-1 ~157 ~64 ~-1 ~157 grass 0  
fill ~59 ~-1 ~20 ~120 ~-1 ~20 grass 0  
fill ~59 ~-1 ~47 ~63 ~-1 ~47 grass 0 
setblock ~59 ~-1 ~48 wool 0  
fill ~59 ~-1 ~71 ~63 ~-1 ~71 wool 0  
fill ~59 ~-1 ~72 ~63 ~-1 ~72 wool 13  
fill ~59 ~-1 ~86 ~63 ~-1 ~86 grass 0  
fill ~59 ~-1 ~87 ~63 ~-1 ~87 wool 0 
setblock ~59 ~-1 ~111 wool 0  
fill ~59 ~-1 ~112 ~63 ~-1 ~112 wool 13  
fill ~60 ~-1 ~21 ~120 ~-1 ~21 grass 0  
fill ~60 ~-1 ~22 ~120 ~-1 ~22 grass 0  
fill ~60 ~-1 ~23 ~120 ~-1 ~23 grass 0  
fill ~60 ~-1 ~24 ~94 ~-1 ~24 grass 0  
fill ~60 ~-1 ~25 ~98 ~-1 ~25 dirt 0  
fill ~60 ~-1 ~48 ~62 ~-1 ~48 wool 13  
fill ~60 ~-1 ~49 ~62 ~-1 ~49 wool 0  
fill ~60 ~-1 ~110 ~62 ~-1 ~110 wool 0  
fill ~60 ~-1 ~111 ~62 ~-1 ~111 wool 13 
setblock ~61 ~-1 ~40 wool 0 
setblock ~61 ~-1 ~119 wool 0  
fill ~62 ~-1 ~40 ~77 ~-1 ~40 wool 13  
fill ~62 ~-1 ~119 ~77 ~-1 ~119 wool 13 
setblock ~63 ~-1 ~48 wool 0  
fill ~63 ~-1 ~49 ~91 ~-1 ~49 wool 13  
fill ~63 ~-1 ~110 ~91 ~-1 ~110 grass 0 
setblock ~63 ~-1 ~111 wool 0 
setblock ~64 ~-1 ~7 grass 0 
setblock ~64 ~-1 ~47 wool 0  
fill ~64 ~-1 ~48 ~91 ~-1 ~48 wool 13  
fill ~64 ~-1 ~71 ~91 ~-1 ~71 grass 0  
fill ~64 ~-1 ~72 ~65 ~-1 ~72 wool 0  
fill ~64 ~-1 ~86 ~65 ~-1 ~86 wool 0  
fill ~64 ~-1 ~87 ~91 ~-1 ~87 wool 13  
fill ~64 ~-1 ~111 ~91 ~-1 ~111 wool 13 
setblock ~64 ~-1 ~112 wool 0  
fill ~65 ~-1 ~7 ~65 ~-1 ~14 dirt 0 
setblock ~65 ~-1 ~46 wool 0  
fill ~65 ~-1 ~47 ~91 ~-1 ~47 grass 0  
fill ~65 ~-1 ~112 ~91 ~-1 ~112 wool 13 
setblock ~65 ~-1 ~113 wool 0  
fill ~65 ~-1 ~145 ~65 ~-1 ~157 dirt 0  
fill ~66 ~-1 ~6 ~66 ~-1 ~24 grass 0  
fill ~66 ~-1 ~46 ~91 ~-1 ~46 grass 0  
fill ~66 ~-1 ~72 ~91 ~-1 ~72 wool 13 
setblock ~66 ~-1 ~73 wool 0 
setblock ~66 ~-1 ~85 wool 0  
fill ~66 ~-1 ~86 ~91 ~-1 ~86 grass 0  
fill ~66 ~-1 ~113 ~91 ~-1 ~113 grass 0  
fill ~66 ~-1 ~145 ~93 ~-1 ~145 grass 0  
fill ~66 ~-1 ~146 ~66 ~-1 ~159 grass 0  
fill ~67 ~-1 ~6 ~67 ~-1 ~14 dirt 0  
fill ~67 ~-1 ~30 ~67 ~-1 ~36 wool 0  
fill ~67 ~-1 ~73 ~91 ~-1 ~73 wool 13 
setblock ~67 ~-1 ~74 wool 0 
setblock ~67 ~-1 ~84 wool 0  
fill ~67 ~-1 ~85 ~91 ~-1 ~85 grass 0  
fill ~67 ~-1 ~124 ~67 ~-1 ~130 wool 0  
fill ~67 ~-1 ~146 ~67 ~-1 ~157 dirt 0  
fill ~68 ~-1 ~4 ~69 ~-1 ~4 grass 0  
fill ~68 ~-1 ~5 ~93 ~-1 ~5 grass 0  
fill ~68 ~-1 ~6 ~93 ~-1 ~6 grass 0  
fill ~68 ~-1 ~7 ~93 ~-1 ~7 grass 0  
fill ~68 ~-1 ~8 ~93 ~-1 ~8 grass 0  
fill ~68 ~-1 ~9 ~93 ~-1 ~9 grass 0  
fill ~68 ~-1 ~10 ~93 ~-1 ~10 grass 0  
fill ~68 ~-1 ~11 ~78 ~-1 ~11 grass 0  
fill ~68 ~-1 ~12 ~93 ~-1 ~12 grass 0  
fill ~68 ~-1 ~13 ~93 ~-1 ~13 grass 0  
fill ~68 ~-1 ~14 ~93 ~-1 ~14 grass 0  
fill ~68 ~-1 ~30 ~77 ~-1 ~30 grass 0  
fill ~68 ~-1 ~31 ~77 ~-1 ~31 grass 0  
fill ~68 ~-1 ~32 ~77 ~-1 ~32 wool 13  
fill ~68 ~-1 ~33 ~77 ~-1 ~33 wool 13  
fill ~68 ~-1 ~34 ~77 ~-1 ~34 grass 0  
fill ~68 ~-1 ~35 ~77 ~-1 ~35 grass 0  
fill ~68 ~-1 ~36 ~77 ~-1 ~36 wool 13  
fill ~68 ~-1 ~74 ~91 ~-1 ~74 grass 0  
fill ~68 ~-1 ~75 ~68 ~-1 ~76 wool 0  
fill ~68 ~-1 ~82 ~68 ~-1 ~83 wool 0  
fill ~68 ~-1 ~84 ~91 ~-1 ~84 wool 13  
fill ~68 ~-1 ~123 ~77 ~-1 ~123 wool 13  
fill ~68 ~-1 ~124 ~77 ~-1 ~124 wool 13  
fill ~68 ~-1 ~125 ~77 ~-1 ~125 grass 0  
fill ~68 ~-1 ~126 ~77 ~-1 ~126 grass 0  
fill ~68 ~-1 ~127 ~77 ~-1 ~127 wool 13  
fill ~68 ~-1 ~128 ~77 ~-1 ~128 wool 13  
fill ~68 ~-1 ~129 ~77 ~-1 ~129 grass 0  
fill ~68 ~-1 ~146 ~93 ~-1 ~146 grass 0  
fill ~68 ~-1 ~147 ~93 ~-1 ~147 grass 0  
fill ~68 ~-1 ~148 ~93 ~-1 ~148 grass 0  
fill ~68 ~-1 ~149 ~93 ~-1 ~149 grass 0  
fill ~68 ~-1 ~150 ~93 ~-1 ~150 grass 0  
fill ~68 ~-1 ~151 ~93 ~-1 ~151 grass 0  
fill ~68 ~-1 ~152 ~93 ~-1 ~152 grass 0  
fill ~68 ~-1 ~153 ~93 ~-1 ~153 grass 0  
fill ~68 ~-1 ~154 ~93 ~-1 ~154 grass 0  
fill ~68 ~-1 ~155 ~93 ~-1 ~155 grass 0  
fill ~68 ~-1 ~156 ~93 ~-1 ~156 grass 0  
fill ~68 ~-1 ~157 ~93 ~-1 ~157 grass 0  
fill ~69 ~-1 ~75 ~91 ~-1 ~75 grass 0  
fill ~69 ~-1 ~76 ~91 ~-1 ~76 wool 13  
fill ~69 ~-1 ~77 ~69 ~-1 ~81 wool 0  
fill ~69 ~-1 ~82 ~91 ~-1 ~82 grass 0  
fill ~69 ~-1 ~83 ~91 ~-1 ~83 wool 13  
fill ~70 ~-1 ~4 ~76 ~-1 ~4 dirt 0  
fill ~70 ~-1 ~77 ~91 ~-1 ~77 wool 13  
fill ~70 ~-1 ~78 ~91 ~-1 ~78 grass 0  
fill ~70 ~-1 ~80 ~91 ~-1 ~80 wool 13  
fill ~70 ~-1 ~81 ~91 ~-1 ~81 grass 0  
fill ~77 ~-1 ~4 ~85 ~-1 ~4 grass 0  
fill ~78 ~-1 ~30 ~78 ~-1 ~45 wool 0  
fill ~78 ~-1 ~115 ~78 ~-1 ~130 wool 0 
setblock ~79 ~-1 ~11 dirt 0  
fill ~79 ~-1 ~30 ~88 ~-1 ~30 grass 0  
fill ~79 ~-1 ~31 ~88 ~-1 ~31 grass 0  
fill ~79 ~-1 ~32 ~89 ~-1 ~32 wool 13  
fill ~79 ~-1 ~33 ~91 ~-1 ~33 wool 13  
fill ~79 ~-1 ~34 ~91 ~-1 ~34 grass 0  
fill ~79 ~-1 ~35 ~91 ~-1 ~35 grass 0  
fill ~79 ~-1 ~36 ~91 ~-1 ~36 wool 13  
fill ~79 ~-1 ~37 ~91 ~-1 ~37 wool 13  
fill ~79 ~-1 ~38 ~91 ~-1 ~38 grass 0  
fill ~79 ~-1 ~39 ~91 ~-1 ~39 grass 0  
fill ~79 ~-1 ~40 ~91 ~-1 ~40 wool 13  
fill ~79 ~-1 ~41 ~91 ~-1 ~41 wool 13  
fill ~79 ~-1 ~42 ~91 ~-1 ~42 grass 0  
fill ~79 ~-1 ~43 ~91 ~-1 ~43 grass 0  
fill ~79 ~-1 ~44 ~91 ~-1 ~44 wool 13  
fill ~79 ~-1 ~45 ~91 ~-1 ~45 wool 13  
fill ~79 ~-1 ~114 ~91 ~-1 ~114 grass 0  
fill ~79 ~-1 ~115 ~91 ~-1 ~115 wool 13  
fill ~79 ~-1 ~116 ~91 ~-1 ~116 wool 13  
fill ~79 ~-1 ~117 ~91 ~-1 ~117 grass 0  
fill ~79 ~-1 ~118 ~91 ~-1 ~118 grass 0  
fill ~79 ~-1 ~119 ~91 ~-1 ~119 wool 13  
fill ~79 ~-1 ~120 ~91 ~-1 ~120 wool 13  
fill ~79 ~-1 ~121 ~91 ~-1 ~121 grass 0  
fill ~79 ~-1 ~122 ~91 ~-1 ~122 grass 0  
fill ~79 ~-1 ~123 ~91 ~-1 ~123 wool 13  
fill ~79 ~-1 ~124 ~91 ~-1 ~124 wool 13  
fill ~79 ~-1 ~125 ~91 ~-1 ~125 grass 0  
fill ~79 ~-1 ~126 ~91 ~-1 ~126 grass 0  
fill ~79 ~-1 ~127 ~89 ~-1 ~127 wool 13  
fill ~79 ~-1 ~128 ~88 ~-1 ~128 wool 13  
fill ~79 ~-1 ~129 ~88 ~-1 ~129 grass 0  
fill ~80 ~-1 ~11 ~93 ~-1 ~11 grass 0  
fill ~82 ~-1 ~3 ~84 ~-1 ~3 grass 0  
fill ~82 ~-1 ~134 ~82 ~0 ~134 stone 0  
fill ~83 ~-1 ~134 ~96 ~-1 ~134 dirt 0  
fill ~85 ~-1 ~3 ~97 ~-1 ~3 dirt 0  
fill ~86 ~-1 ~4 ~97 ~-1 ~4 dirt 0  
fill ~89 ~-1 ~30 ~89 ~-1 ~31 wool 0  
fill ~89 ~-1 ~128 ~90 ~-1 ~128 wool 0  
fill ~89 ~-1 ~129 ~89 ~-1 ~128 wool 0  
fill ~90 ~-1 ~30 ~91 ~-1 ~30 grass 0  
fill ~90 ~-1 ~31 ~90 ~-1 ~32 wool 0  
fill ~90 ~-1 ~127 ~92 ~-1 ~127 wool 0  
fill ~90 ~-1 ~129 ~91 ~-1 ~129 grass 0  
fill ~90 ~-1 ~135 ~91 ~-1 ~135 dirt 0 
setblock ~91 ~-1 ~31 grass 0  
fill ~91 ~-1 ~32 ~92 ~-1 ~32 wool 0 
setblock ~91 ~-1 ~128 wool 13  
fill ~92 ~-1 ~30 ~92 ~-1 ~130 wool 0  
fill ~92 ~-1 ~135 ~120 ~-1 ~135 grass 0  
fill ~93 ~-1 ~29 ~93 ~-1 ~131 grass 0  
fill ~94 ~-1 ~5 ~97 ~-1 ~5 dirt 0  
fill ~94 ~-1 ~6 ~94 ~-1 ~14 dirt 0  
fill ~94 ~-1 ~28 ~97 ~-1 ~28 dirt 0  
fill ~94 ~-1 ~29 ~96 ~-1 ~29 dirt 0  
fill ~94 ~-1 ~30 ~95 ~-1 ~30 dirt 0  
fill ~94 ~-1 ~31 ~95 ~-1 ~31 dirt 0  
fill ~94 ~-1 ~32 ~95 ~-1 ~32 dirt 0  
fill ~94 ~-1 ~33 ~96 ~-1 ~33 dirt 0  
fill ~94 ~-1 ~34 ~96 ~-1 ~34 dirt 0  
fill ~94 ~-1 ~35 ~96 ~-1 ~35 dirt 0  
fill ~94 ~-1 ~36 ~96 ~-1 ~36 dirt 0  
fill ~94 ~-1 ~37 ~96 ~-1 ~37 dirt 0  
fill ~94 ~-1 ~38 ~96 ~-1 ~38 dirt 0  
fill ~94 ~-1 ~39 ~96 ~-1 ~39 dirt 0  
fill ~94 ~-1 ~40 ~96 ~-1 ~40 dirt 0  
fill ~94 ~-1 ~41 ~96 ~-1 ~41 dirt 0  
fill ~94 ~-1 ~42 ~95 ~-1 ~42 dirt 0  
fill ~94 ~-1 ~43 ~95 ~-1 ~43 dirt 0  
fill ~94 ~-1 ~44 ~95 ~-1 ~44 dirt 0  
fill ~94 ~-1 ~45 ~95 ~-1 ~45 dirt 0  
fill ~94 ~-1 ~46 ~96 ~-1 ~46 dirt 0  
fill ~94 ~-1 ~47 ~96 ~-1 ~47 dirt 0  
fill ~94 ~-1 ~48 ~95 ~-1 ~48 dirt 0  
fill ~94 ~-1 ~49 ~95 ~-1 ~49 dirt 0  
fill ~94 ~-1 ~50 ~95 ~-1 ~50 dirt 0  
fill ~94 ~-1 ~51 ~95 ~-1 ~51 dirt 0  
fill ~94 ~-1 ~52 ~95 ~-1 ~52 dirt 0  
fill ~94 ~-1 ~53 ~95 ~-1 ~53 dirt 0  
fill ~94 ~-1 ~54 ~95 ~-1 ~54 dirt 0  
fill ~94 ~-1 ~55 ~95 ~-1 ~55 dirt 0  
fill ~94 ~-1 ~56 ~95 ~-1 ~56 dirt 0  
fill ~94 ~-1 ~57 ~95 ~-1 ~57 dirt 0  
fill ~94 ~-1 ~58 ~95 ~-1 ~58 dirt 0  
fill ~94 ~-1 ~59 ~95 ~-1 ~59 dirt 0  
fill ~94 ~-1 ~60 ~95 ~-1 ~60 dirt 0  
fill ~94 ~-1 ~61 ~95 ~-1 ~61 dirt 0  
fill ~94 ~-1 ~62 ~95 ~-1 ~62 dirt 0  
fill ~94 ~-1 ~63 ~95 ~-1 ~63 dirt 0  
fill ~94 ~-1 ~64 ~95 ~-1 ~64 dirt 0  
fill ~94 ~-1 ~65 ~95 ~-1 ~65 dirt 0  
fill ~94 ~-1 ~66 ~95 ~-1 ~66 dirt 0  
fill ~94 ~-1 ~67 ~95 ~-1 ~67 dirt 0  
fill ~94 ~-1 ~68 ~95 ~-1 ~68 dirt 0  
fill ~94 ~-1 ~69 ~95 ~-1 ~69 dirt 0  
fill ~94 ~-1 ~70 ~95 ~-1 ~70 dirt 0  
fill ~94 ~-1 ~71 ~95 ~-1 ~71 dirt 0  
fill ~94 ~-1 ~72 ~95 ~-1 ~72 dirt 0  
fill ~94 ~-1 ~73 ~95 ~-1 ~73 dirt 0  
fill ~94 ~-1 ~74 ~95 ~-1 ~74 dirt 0  
fill ~94 ~-1 ~75 ~95 ~-1 ~75 dirt 0  
fill ~94 ~-1 ~76 ~95 ~-1 ~76 dirt 0  
fill ~94 ~-1 ~77 ~95 ~-1 ~77 dirt 0  
fill ~94 ~-1 ~78 ~95 ~-1 ~78 dirt 0  
fill ~94 ~-1 ~79 ~95 ~-1 ~79 dirt 0  
fill ~94 ~-1 ~80 ~95 ~-1 ~80 dirt 0  
fill ~94 ~-1 ~81 ~95 ~-1 ~81 dirt 0  
fill ~94 ~-1 ~82 ~95 ~-1 ~82 dirt 0  
fill ~94 ~-1 ~83 ~95 ~-1 ~83 dirt 0  
fill ~94 ~-1 ~84 ~95 ~-1 ~84 dirt 0  
fill ~94 ~-1 ~85 ~95 ~-1 ~85 dirt 0  
fill ~94 ~-1 ~86 ~95 ~-1 ~86 dirt 0  
fill ~94 ~-1 ~87 ~95 ~-1 ~87 dirt 0  
fill ~94 ~-1 ~88 ~95 ~-1 ~88 dirt 0  
fill ~94 ~-1 ~89 ~95 ~-1 ~89 dirt 0  
fill ~94 ~-1 ~90 ~95 ~-1 ~90 dirt 0  
fill ~94 ~-1 ~91 ~95 ~-1 ~91 dirt 0  
fill ~94 ~-1 ~92 ~95 ~-1 ~92 dirt 0  
fill ~94 ~-1 ~93 ~95 ~-1 ~93 dirt 0  
fill ~94 ~-1 ~94 ~95 ~-1 ~94 dirt 0  
fill ~94 ~-1 ~95 ~95 ~-1 ~95 dirt 0  
fill ~94 ~-1 ~96 ~95 ~-1 ~96 dirt 0  
fill ~94 ~-1 ~97 ~95 ~-1 ~97 dirt 0  
fill ~94 ~-1 ~98 ~95 ~-1 ~98 dirt 0  
fill ~94 ~-1 ~99 ~95 ~-1 ~99 dirt 0  
fill ~94 ~-1 ~100 ~95 ~-1 ~100 dirt 0  
fill ~94 ~-1 ~101 ~95 ~-1 ~101 dirt 0  
fill ~94 ~-1 ~102 ~95 ~-1 ~102 dirt 0  
fill ~94 ~-1 ~103 ~95 ~-1 ~103 dirt 0  
fill ~94 ~-1 ~104 ~95 ~-1 ~104 dirt 0  
fill ~94 ~-1 ~105 ~95 ~-1 ~105 dirt 0  
fill ~94 ~-1 ~106 ~95 ~-1 ~106 dirt 0  
fill ~94 ~-1 ~107 ~95 ~-1 ~107 dirt 0  
fill ~94 ~-1 ~108 ~95 ~-1 ~108 dirt 0  
fill ~94 ~-1 ~109 ~95 ~-1 ~109 dirt 0  
fill ~94 ~-1 ~110 ~95 ~-1 ~110 dirt 0  
fill ~94 ~-1 ~111 ~95 ~-1 ~111 dirt 0  
fill ~94 ~-1 ~112 ~95 ~-1 ~112 dirt 0  
fill ~94 ~-1 ~113 ~95 ~-1 ~113 dirt 0  
fill ~94 ~-1 ~114 ~95 ~-1 ~114 dirt 0  
fill ~94 ~-1 ~115 ~95 ~-1 ~115 dirt 0  
fill ~94 ~-1 ~116 ~95 ~-1 ~116 dirt 0  
fill ~94 ~-1 ~117 ~95 ~-1 ~117 dirt 0  
fill ~94 ~-1 ~118 ~95 ~-1 ~118 dirt 0  
fill ~94 ~-1 ~119 ~95 ~-1 ~119 dirt 0  
fill ~94 ~-1 ~120 ~95 ~-1 ~120 dirt 0  
fill ~94 ~-1 ~121 ~96 ~-1 ~121 dirt 0  
fill ~94 ~-1 ~122 ~96 ~-1 ~122 dirt 0  
fill ~94 ~-1 ~123 ~96 ~-1 ~123 dirt 0  
fill ~94 ~-1 ~124 ~96 ~-1 ~124 dirt 0  
fill ~94 ~-1 ~125 ~96 ~-1 ~125 dirt 0  
fill ~94 ~-1 ~126 ~96 ~-1 ~126 dirt 0  
fill ~94 ~-1 ~127 ~96 ~-1 ~127 dirt 0  
fill ~94 ~-1 ~128 ~96 ~-1 ~128 dirt 0  
fill ~94 ~-1 ~129 ~96 ~-1 ~129 dirt 0  
fill ~94 ~-1 ~130 ~96 ~-1 ~130 dirt 0  
fill ~94 ~-1 ~131 ~96 ~-1 ~131 dirt 0  
fill ~94 ~-1 ~145 ~94 ~-1 ~157 dirt 0  
fill ~95 ~-1 ~6 ~95 ~-1 ~23 grass 0  
fill ~95 ~-1 ~24 ~97 ~-1 ~24 dirt 0  
fill ~95 ~-1 ~145 ~95 ~-1 ~159 grass 0  
fill ~96 ~-1 ~6 ~97 ~-1 ~6 dirt 0  
fill ~96 ~-1 ~7 ~96 ~-1 ~14 dirt 0  
fill ~96 ~-1 ~30 ~96 ~0 ~30 stone 0  
fill ~96 ~-1 ~45 ~96 ~0 ~45 stone 0  
fill ~96 ~-1 ~145 ~96 ~-1 ~157 dirt 0  
fill ~97 ~-1 ~7 ~120 ~-1 ~7 grass 0  
fill ~97 ~-1 ~8 ~120 ~-1 ~8 grass 0  
fill ~97 ~-1 ~9 ~120 ~-1 ~9 grass 0  
fill ~97 ~-1 ~10 ~120 ~-1 ~10 grass 0  
fill ~97 ~-1 ~11 ~120 ~-1 ~11 grass 0  
fill ~97 ~-1 ~12 ~120 ~-1 ~12 grass 0  
fill ~97 ~-1 ~13 ~120 ~-1 ~13 grass 0  
fill ~97 ~-1 ~14 ~120 ~-1 ~14 grass 0  
fill ~97 ~-1 ~29 ~120 ~-1 ~29 grass 0  
fill ~97 ~-1 ~30 ~120 ~-1 ~30 grass 0  
fill ~97 ~-1 ~31 ~120 ~-1 ~31 grass 0  
fill ~97 ~-1 ~32 ~120 ~-1 ~32 grass 0  
fill ~97 ~-1 ~33 ~120 ~-1 ~33 grass 0  
fill ~97 ~-1 ~34 ~120 ~-1 ~34 grass 0  
fill ~97 ~-1 ~35 ~120 ~-1 ~35 grass 0  
fill ~97 ~-1 ~36 ~120 ~-1 ~36 grass 0  
fill ~97 ~-1 ~37 ~120 ~-1 ~37 grass 0  
fill ~97 ~-1 ~38 ~120 ~-1 ~38 grass 0  
fill ~97 ~-1 ~39 ~120 ~-1 ~39 grass 0  
fill ~97 ~-1 ~40 ~120 ~-1 ~40 grass 0  
fill ~97 ~-1 ~41 ~120 ~-1 ~41 grass 0  
fill ~97 ~-1 ~42 ~120 ~-1 ~42 grass 0  
fill ~97 ~-1 ~43 ~120 ~-1 ~43 grass 0  
fill ~97 ~-1 ~44 ~120 ~-1 ~44 grass 0  
fill ~97 ~-1 ~45 ~120 ~-1 ~45 grass 0  
fill ~97 ~-1 ~46 ~120 ~-1 ~46 grass 0  
fill ~97 ~-1 ~47 ~120 ~-1 ~47 grass 0  
fill ~97 ~-1 ~48 ~120 ~-1 ~48 grass 0  
fill ~97 ~-1 ~49 ~120 ~-1 ~49 grass 0  
fill ~97 ~-1 ~50 ~120 ~-1 ~50 grass 0  
fill ~97 ~-1 ~51 ~120 ~-1 ~51 grass 0  
fill ~97 ~-1 ~52 ~106 ~-1 ~52 grass 0  
fill ~97 ~-1 ~53 ~120 ~-1 ~53 grass 0  
fill ~97 ~-1 ~54 ~106 ~-1 ~54 grass 0  
fill ~97 ~-1 ~55 ~120 ~-1 ~55 grass 0  
fill ~97 ~-1 ~56 ~120 ~-1 ~56 grass 0  
fill ~97 ~-1 ~57 ~120 ~-1 ~57 grass 0  
fill ~97 ~-1 ~58 ~120 ~-1 ~58 grass 0  
fill ~97 ~-1 ~59 ~120 ~-1 ~59 grass 0  
fill ~97 ~-1 ~60 ~120 ~-1 ~60 grass 0  
fill ~97 ~-1 ~61 ~120 ~-1 ~61 grass 0  
fill ~97 ~-1 ~62 ~120 ~-1 ~62 grass 0  
fill ~97 ~-1 ~63 ~120 ~-1 ~63 grass 0  
fill ~97 ~-1 ~64 ~120 ~-1 ~64 grass 0  
fill ~97 ~-1 ~65 ~120 ~-1 ~65 grass 0  
fill ~97 ~-1 ~66 ~120 ~-1 ~66 grass 0  
fill ~97 ~-1 ~67 ~120 ~-1 ~67 grass 0  
fill ~97 ~-1 ~68 ~120 ~-1 ~68 grass 0  
fill ~97 ~-1 ~69 ~120 ~-1 ~69 grass 0  
fill ~97 ~-1 ~70 ~120 ~-1 ~70 grass 0  
fill ~97 ~-1 ~71 ~120 ~-1 ~71 grass 0  
fill ~97 ~-1 ~72 ~120 ~-1 ~72 grass 0  
fill ~97 ~-1 ~73 ~119 ~-1 ~73 dirt 0  
fill ~97 ~-1 ~74 ~120 ~-1 ~74 grass 0  
fill ~97 ~-1 ~75 ~120 ~-1 ~75 grass 0  
fill ~97 ~-1 ~76 ~120 ~-1 ~76 grass 0  
fill ~97 ~-1 ~77 ~107 ~-1 ~77 dirt 0  
fill ~97 ~-1 ~78 ~106 ~-1 ~78 grass 0  
fill ~97 ~-1 ~79 ~106 ~-1 ~79 grass 0  
fill ~97 ~-1 ~80 ~106 ~-1 ~80 grass 0  
fill ~97 ~-1 ~81 ~107 ~-1 ~81 dirt 0  
fill ~97 ~-1 ~82 ~120 ~-1 ~82 grass 0  
fill ~97 ~-1 ~83 ~120 ~-1 ~83 grass 0  
fill ~97 ~-1 ~84 ~120 ~-1 ~84 grass 0  
fill ~97 ~-1 ~85 ~119 ~-1 ~85 dirt 0  
fill ~97 ~-1 ~86 ~120 ~-1 ~86 grass 0  
fill ~97 ~-1 ~87 ~120 ~-1 ~87 grass 0  
fill ~97 ~-1 ~88 ~120 ~-1 ~88 grass 0  
fill ~97 ~-1 ~89 ~120 ~-1 ~89 grass 0  
fill ~97 ~-1 ~90 ~120 ~-1 ~90 grass 0  
fill ~97 ~-1 ~91 ~120 ~-1 ~91 grass 0  
fill ~97 ~-1 ~92 ~120 ~-1 ~92 grass 0  
fill ~97 ~-1 ~93 ~120 ~-1 ~93 grass 0  
fill ~97 ~-1 ~94 ~120 ~-1 ~94 grass 0  
fill ~97 ~-1 ~95 ~107 ~-1 ~95 grass 0  
fill ~97 ~-1 ~96 ~107 ~-1 ~96 grass 0  
fill ~97 ~-1 ~97 ~120 ~-1 ~97 grass 0  
fill ~97 ~-1 ~98 ~120 ~-1 ~98 grass 0  
fill ~97 ~-1 ~99 ~120 ~-1 ~99 grass 0  
fill ~97 ~-1 ~100 ~120 ~-1 ~100 grass 0  
fill ~97 ~-1 ~101 ~120 ~-1 ~101 grass 0  
fill ~97 ~-1 ~102 ~120 ~-1 ~102 grass 0  
fill ~97 ~-1 ~103 ~120 ~-1 ~103 grass 0  
fill ~97 ~-1 ~104 ~106 ~-1 ~104 grass 0  
fill ~97 ~-1 ~105 ~120 ~-1 ~105 grass 0  
fill ~97 ~-1 ~106 ~106 ~-1 ~106 grass 0  
fill ~97 ~-1 ~107 ~120 ~-1 ~107 grass 0  
fill ~97 ~-1 ~108 ~120 ~-1 ~108 grass 0  
fill ~97 ~-1 ~109 ~120 ~-1 ~109 grass 0  
fill ~97 ~-1 ~110 ~112 ~-1 ~110 grass 0  
fill ~97 ~-1 ~111 ~102 ~-1 ~111 grass 0  
fill ~97 ~-1 ~112 ~102 ~-1 ~112 grass 0  
fill ~97 ~-1 ~113 ~120 ~-1 ~113 grass 0  
fill ~97 ~-1 ~114 ~120 ~-1 ~114 grass 0  
fill ~97 ~-1 ~115 ~120 ~-1 ~115 grass 0  
fill ~97 ~-1 ~116 ~120 ~-1 ~116 grass 0  
fill ~97 ~-1 ~117 ~103 ~-1 ~117 grass 0  
fill ~97 ~-1 ~118 ~103 ~-1 ~118 grass 0  
fill ~97 ~-1 ~119 ~111 ~-1 ~119 grass 0  
fill ~97 ~-1 ~120 ~110 ~-1 ~120 grass 0  
fill ~97 ~-1 ~121 ~109 ~-1 ~121 grass 0  
fill ~97 ~-1 ~122 ~110 ~-1 ~122 grass 0  
fill ~97 ~-1 ~123 ~111 ~-1 ~123 grass 0  
fill ~97 ~-1 ~124 ~112 ~-1 ~124 grass 0  
fill ~97 ~-1 ~125 ~112 ~-1 ~125 grass 0  
fill ~97 ~-1 ~126 ~112 ~-1 ~126 grass 0  
fill ~97 ~-1 ~127 ~111 ~-1 ~127 grass 0  
fill ~97 ~-1 ~128 ~111 ~-1 ~128 grass 0  
fill ~97 ~-1 ~129 ~120 ~-1 ~129 grass 0  
fill ~97 ~-1 ~130 ~120 ~-1 ~130 grass 0  
fill ~97 ~-1 ~131 ~120 ~-1 ~131 grass 0  
fill ~97 ~-1 ~132 ~106 ~-1 ~132 grass 0  
fill ~97 ~-1 ~133 ~120 ~-1 ~133 grass 0  
fill ~97 ~-1 ~134 ~106 ~-1 ~134 grass 0  
fill ~97 ~-1 ~145 ~120 ~-1 ~145 grass 0  
fill ~97 ~-1 ~146 ~120 ~-1 ~146 grass 0  
fill ~97 ~-1 ~147 ~120 ~-1 ~147 grass 0  
fill ~97 ~-1 ~148 ~120 ~-1 ~148 grass 0  
fill ~97 ~-1 ~149 ~120 ~-1 ~149 grass 0  
fill ~97 ~-1 ~150 ~120 ~-1 ~150 grass 0  
fill ~97 ~-1 ~151 ~120 ~-1 ~151 grass 0  
fill ~97 ~-1 ~152 ~120 ~-1 ~152 grass 0  
fill ~97 ~-1 ~153 ~120 ~-1 ~153 grass 0  
fill ~97 ~-1 ~154 ~120 ~-1 ~154 grass 0  
fill ~97 ~-1 ~155 ~120 ~-1 ~155 grass 0  
fill ~97 ~-1 ~156 ~120 ~-1 ~156 grass 0  
fill ~97 ~-1 ~157 ~120 ~-1 ~157 grass 0  
fill ~98 ~-1 ~3 ~115 ~-1 ~3 grass 0  
fill ~98 ~-1 ~4 ~115 ~-1 ~4 grass 0  
fill ~98 ~-1 ~5 ~115 ~-1 ~5 grass 0  
fill ~98 ~-1 ~6 ~120 ~-1 ~6 grass 0  
fill ~98 ~-1 ~24 ~120 ~-1 ~24 grass 0  
fill ~98 ~-1 ~26 ~120 ~-1 ~26 grass 0  
fill ~98 ~-1 ~27 ~106 ~-1 ~27 grass 0  
fill ~98 ~-1 ~28 ~120 ~-1 ~28 grass 0  
fill ~99 ~-1 ~25 ~106 ~-1 ~25 grass 0  
fill ~103 ~-1 ~111 ~103 ~-1 ~112 dirt 0  
fill ~104 ~-1 ~111 ~120 ~-1 ~111 grass 0  
fill ~104 ~-1 ~112 ~120 ~-1 ~112 grass 0  
fill ~104 ~-1 ~117 ~104 ~-1 ~118 dirt 0  
fill ~105 ~-1 ~117 ~120 ~-1 ~117 grass 0 
setblock ~105 ~-1 ~118 dirt 0  
fill ~106 ~-1 ~118 ~112 ~-1 ~118 grass 0 
setblock ~107 ~-1 ~52 dirt 0 
setblock ~107 ~-1 ~54 dirt 0  
fill ~107 ~-1 ~78 ~108 ~-1 ~78 dirt 0  
fill ~107 ~-1 ~79 ~107 ~-1 ~81 dirt 0  
fill ~107 ~-1 ~104 ~118 ~-1 ~104 dirt 0  
fill ~107 ~-1 ~106 ~118 ~-1 ~106 dirt 0  
fill ~107 ~-1 ~132 ~118 ~-1 ~132 dirt 0  
fill ~107 ~-1 ~134 ~110 ~-1 ~134 dirt 0 
setblock ~108 ~-1 ~25 dirt 0 
setblock ~108 ~-1 ~27 dirt 0  
fill ~108 ~-1 ~77 ~120 ~-1 ~77 grass 0 
setblock ~108 ~-1 ~79 grass 0 
setblock ~108 ~-1 ~80 dirt 0  
fill ~108 ~-1 ~81 ~120 ~-1 ~81 grass 0  
fill ~108 ~-1 ~95 ~108 ~-1 ~96 dirt 0  
fill ~109 ~-1 ~78 ~120 ~-1 ~78 grass 0 
setblock ~109 ~-1 ~79 dirt 0  
fill ~109 ~-1 ~80 ~120 ~-1 ~80 grass 0  
fill ~109 ~-1 ~95 ~120 ~-1 ~95 grass 0  
fill ~109 ~-1 ~96 ~120 ~-1 ~96 grass 0  
fill ~110 ~-1 ~25 ~112 ~-1 ~25 dirt 0 
setblock ~110 ~-1 ~27 dirt 0  
fill ~110 ~-1 ~79 ~120 ~-1 ~79 grass 0  
fill ~110 ~-1 ~121 ~113 ~-1 ~121 dirt 0  
fill ~111 ~-1 ~27 ~113 ~-1 ~27 gravel 0  
fill ~111 ~-1 ~120 ~113 ~-1 ~120 dirt 0  
fill ~111 ~-1 ~122 ~113 ~-1 ~122 dirt 0  
fill ~112 ~-1 ~119 ~113 ~-1 ~119 dirt 0  
fill ~112 ~-1 ~123 ~113 ~-1 ~123 dirt 0  
fill ~112 ~-1 ~127 ~113 ~-1 ~127 dirt 0  
fill ~112 ~-1 ~128 ~113 ~-1 ~128 dirt 0  
fill ~113 ~-1 ~25 ~118 ~-1 ~25 gravel 0  
fill ~113 ~-1 ~52 ~114 ~-1 ~52 dirt 0  
fill ~113 ~-1 ~54 ~118 ~-1 ~54 dirt 0 
setblock ~113 ~-1 ~110 dirt 0 
setblock ~113 ~-1 ~118 dirt 0  
fill ~113 ~-1 ~124 ~113 ~-1 ~128 dirt 0  
fill ~113 ~-1 ~134 ~115 ~-1 ~134 dirt 0  
fill ~114 ~-1 ~27 ~115 ~-1 ~27 dirt 0  
fill ~114 ~-1 ~110 ~120 ~-1 ~110 grass 0  
fill ~114 ~-1 ~118 ~120 ~-1 ~118 grass 0  
fill ~114 ~-1 ~119 ~120 ~-1 ~119 grass 0  
fill ~114 ~-1 ~120 ~120 ~-1 ~120 grass 0  
fill ~114 ~-1 ~121 ~120 ~-1 ~121 grass 0  
fill ~114 ~-1 ~122 ~120 ~-1 ~122 grass 0  
fill ~114 ~-1 ~123 ~120 ~-1 ~123 grass 0  
fill ~114 ~-1 ~124 ~120 ~-1 ~124 grass 0  
fill ~114 ~-1 ~125 ~120 ~-1 ~125 grass 0  
fill ~114 ~-1 ~126 ~120 ~-1 ~126 grass 0  
fill ~114 ~-1 ~127 ~120 ~-1 ~127 grass 0  
fill ~114 ~-1 ~128 ~120 ~-1 ~128 grass 0 
setblock ~115 ~-1 ~2 grass 0  
fill ~115 ~-1 ~52 ~118 ~-1 ~52 sand 0  
fill ~116 ~-1 ~2 ~120 ~-1 ~2 dirt 0  
fill ~116 ~-1 ~3 ~120 ~-1 ~3 dirt 0  
fill ~116 ~-1 ~4 ~120 ~-1 ~4 dirt 0  
fill ~116 ~-1 ~5 ~120 ~-1 ~5 dirt 0 
setblock ~116 ~-1 ~27 stone 0 
setblock ~116 ~-1 ~134 stone 0  
fill ~117 ~-1 ~1 ~120 ~-1 ~1 gravel 0 
setblock ~117 ~-1 ~27 dirt 0 
setblock ~117 ~-1 ~134 dirt 0 
setblock ~118 ~-1 ~27 gravel 0 
setblock ~118 ~-1 ~134 stone 0  
fill ~119 ~-1 ~25 ~120 ~-1 ~25 grass 0  
fill ~119 ~-1 ~27 ~120 ~-1 ~27 grass 0  
fill ~119 ~-1 ~52 ~120 ~-1 ~52 grass 0  
fill ~119 ~-1 ~54 ~120 ~-1 ~54 grass 0  
fill ~119 ~-1 ~104 ~120 ~-1 ~104 grass 0  
fill ~119 ~-1 ~106 ~120 ~-1 ~106 grass 0  
fill ~119 ~-1 ~132 ~120 ~-1 ~132 grass 0  
fill ~119 ~-1 ~134 ~120 ~-1 ~134 grass 0 
setblock ~120 ~-1 ~73 grass 0 
setblock ~120 ~-1 ~85 grass 0 
setblock ~1 ~0 ~143 grass 0  
fill ~1 ~0 ~144 ~1 ~0 ~159 dirt 0  
fill ~2 ~0 ~144 ~3 ~0 ~144 grass 0  
fill ~2 ~0 ~145 ~3 ~0 ~145 dirt 0  
fill ~2 ~0 ~146 ~4 ~0 ~146 dirt 0  
fill ~2 ~0 ~147 ~5 ~0 ~147 dirt 0  
fill ~2 ~0 ~148 ~5 ~0 ~148 dirt 0  
fill ~2 ~0 ~149 ~5 ~0 ~149 dirt 0  
fill ~2 ~0 ~150 ~5 ~0 ~150 dirt 0  
fill ~2 ~0 ~151 ~5 ~0 ~151 dirt 0  
fill ~2 ~0 ~152 ~6 ~0 ~152 dirt 0  
fill ~2 ~0 ~153 ~6 ~0 ~153 dirt 0  
fill ~2 ~0 ~154 ~6 ~0 ~154 dirt 0  
fill ~2 ~0 ~155 ~7 ~0 ~155 dirt 0  
fill ~2 ~0 ~156 ~7 ~0 ~156 dirt 0  
fill ~2 ~0 ~157 ~8 ~0 ~157 dirt 0  
fill ~2 ~0 ~158 ~13 ~0 ~158 dirt 0  
fill ~2 ~0 ~159 ~16 ~0 ~159 dirt 0  
fill ~3 ~0 ~1 ~114 ~0 ~1 grass 0  
fill ~3 ~0 ~2 ~114 ~0 ~2 grass 0  
fill ~3 ~0 ~9 ~25 ~0 ~9 stone 0  
fill ~3 ~0 ~10 ~21 ~0 ~10 stone 0  
fill ~3 ~0 ~11 ~21 ~0 ~11 stone 0  
fill ~3 ~0 ~12 ~19 ~0 ~12 stone 0  
fill ~3 ~0 ~13 ~18 ~0 ~13 stone 0  
fill ~3 ~0 ~14 ~17 ~0 ~14 stone 0  
fill ~3 ~0 ~15 ~17 ~0 ~15 stone 0  
fill ~3 ~0 ~16 ~17 ~0 ~16 stone 0  
fill ~3 ~0 ~17 ~13 ~0 ~17 stone 0  
fill ~3 ~0 ~18 ~13 ~0 ~18 stone 0  
fill ~3 ~0 ~19 ~13 ~0 ~19 stone 0  
fill ~3 ~0 ~20 ~13 ~0 ~20 stone 0  
fill ~3 ~0 ~21 ~13 ~0 ~21 stone 0  
fill ~3 ~0 ~22 ~13 ~0 ~22 stone 0  
fill ~3 ~0 ~23 ~14 ~0 ~23 stone 0  
fill ~3 ~0 ~24 ~14 ~0 ~24 stone 0  
fill ~3 ~0 ~25 ~15 ~0 ~25 stone 0  
fill ~3 ~0 ~26 ~16 ~0 ~26 stone 0  
fill ~3 ~0 ~27 ~27 ~0 ~27 stone 0  
fill ~3 ~0 ~28 ~24 ~0 ~28 stone 0  
fill ~3 ~0 ~29 ~24 ~0 ~29 stone 0  
fill ~3 ~0 ~30 ~24 ~0 ~30 stone 0  
fill ~3 ~0 ~31 ~9 ~0 ~31 stone 0  
fill ~3 ~0 ~32 ~10 ~0 ~32 stone 0  
fill ~3 ~0 ~33 ~24 ~0 ~33 stone 0  
fill ~3 ~0 ~34 ~24 ~0 ~34 stone 0  
fill ~3 ~0 ~35 ~24 ~0 ~35 stone 0  
fill ~3 ~0 ~36 ~24 ~0 ~36 stone 0  
fill ~3 ~0 ~37 ~15 ~0 ~37 stone 0  
fill ~3 ~0 ~38 ~24 ~0 ~38 stone 0  
fill ~3 ~0 ~39 ~24 ~0 ~39 stone 0  
fill ~3 ~0 ~40 ~24 ~0 ~40 stone 0  
fill ~3 ~0 ~41 ~24 ~0 ~41 stone 0  
fill ~3 ~0 ~42 ~22 ~0 ~42 stone 0  
fill ~3 ~0 ~43 ~22 ~0 ~43 stone 0  
fill ~3 ~0 ~44 ~23 ~0 ~44 stone 0  
fill ~3 ~0 ~45 ~24 ~0 ~45 stone 0  
fill ~3 ~0 ~46 ~8 ~0 ~46 stone 0  
fill ~3 ~0 ~47 ~8 ~0 ~47 stone 0  
fill ~3 ~0 ~48 ~8 ~0 ~48 stone 0  
fill ~3 ~0 ~49 ~8 ~0 ~49 stone 0  
fill ~3 ~0 ~50 ~8 ~0 ~50 stone 0  
fill ~3 ~0 ~51 ~8 ~0 ~51 stone 0  
fill ~3 ~0 ~52 ~8 ~0 ~52 stone 0  
fill ~3 ~0 ~53 ~8 ~0 ~53 stone 0  
fill ~3 ~0 ~54 ~8 ~0 ~54 stone 0  
fill ~3 ~0 ~78 ~3 ~-1 ~78 dirt 0  
fill ~3 ~0 ~79 ~7 ~0 ~79 dirt 0  
fill ~3 ~0 ~80 ~7 ~0 ~80 dirt 0  
fill ~3 ~0 ~81 ~7 ~0 ~81 dirt 0  
fill ~3 ~0 ~82 ~4 ~0 ~82 dirt 0  
fill ~3 ~0 ~83 ~7 ~0 ~83 sand 0  
fill ~3 ~0 ~84 ~7 ~0 ~84 sand 0  
fill ~3 ~0 ~85 ~7 ~0 ~85 sand 0  
fill ~3 ~0 ~86 ~6 ~0 ~86 sand 0  
fill ~3 ~0 ~87 ~6 ~0 ~87 sand 0  
fill ~3 ~0 ~88 ~6 ~0 ~88 sand 0  
fill ~3 ~0 ~89 ~6 ~0 ~89 sand 0  
fill ~3 ~0 ~90 ~5 ~0 ~90 sand 0  
fill ~3 ~0 ~91 ~6 ~0 ~91 sand 0  
fill ~3 ~0 ~92 ~6 ~0 ~92 sand 0  
fill ~3 ~0 ~93 ~4 ~0 ~93 sand 0  
fill ~3 ~0 ~104 ~15 ~0 ~104 iron_block 0  
fill ~3 ~0 ~106 ~15 ~0 ~106 iron_block 0  
fill ~3 ~0 ~132 ~15 ~0 ~132 iron_block 0  
fill ~3 ~0 ~134 ~15 ~0 ~134 iron_block 0  
fill ~4 ~0 ~78 ~6 ~0 ~78 grass 0 
setblock ~4 ~0 ~145 grass 0  
fill ~5 ~0 ~82 ~7 ~0 ~82 sand 0 
setblock ~5 ~0 ~146 grass 0  
fill ~6 ~0 ~147 ~6 ~0 ~151 grass 0  
fill ~7 ~0 ~78 ~7 ~1 ~78 dirt 0  
fill ~7 ~0 ~153 ~7 ~0 ~154 grass 0  
fill ~8 ~0 ~55 ~8 ~1 ~55 stone 0  
fill ~8 ~0 ~56 ~8 ~1 ~56 stone 0  
fill ~8 ~0 ~57 ~8 ~1 ~57 stone 0  
fill ~8 ~0 ~58 ~8 ~0 ~64 stone 0  
fill ~8 ~0 ~78 ~15 ~0 ~78 iron_block 0  
fill ~8 ~0 ~80 ~15 ~0 ~80 iron_block 0  
fill ~8 ~0 ~155 ~11 ~0 ~155 grass 0  
fill ~8 ~0 ~156 ~15 ~0 ~156 grass 0  
fill ~9 ~0 ~52 ~15 ~0 ~52 iron_block 0  
fill ~9 ~0 ~54 ~15 ~0 ~54 iron_block 0  
fill ~9 ~0 ~157 ~17 ~0 ~157 grass 0 
setblock ~10 ~0 ~31 dirt 0  
fill ~10 ~0 ~46 ~14 ~0 ~46 stone 0  
fill ~10 ~0 ~47 ~13 ~0 ~47 stone 0  
fill ~10 ~0 ~48 ~10 ~3 ~48 stone 0  
fill ~10 ~0 ~49 ~10 ~0 ~32 stone 0  
fill ~10 ~0 ~56 ~15 ~0 ~56 stone 0  
fill ~10 ~0 ~57 ~18 ~0 ~57 stone 0  
fill ~10 ~0 ~58 ~14 ~0 ~58 stone 0  
fill ~10 ~0 ~59 ~13 ~0 ~59 stone 0  
fill ~10 ~0 ~60 ~13 ~0 ~60 stone 0  
fill ~10 ~0 ~61 ~13 ~0 ~61 stone 0  
fill ~10 ~0 ~62 ~13 ~0 ~62 stone 0  
fill ~10 ~0 ~63 ~13 ~0 ~63 stone 0  
fill ~10 ~0 ~64 ~13 ~0 ~64 stone 0  
fill ~10 ~0 ~65 ~22 ~0 ~65 stone 0  
fill ~10 ~0 ~66 ~21 ~0 ~66 stone 0  
fill ~10 ~0 ~67 ~21 ~0 ~67 stone 0  
fill ~10 ~0 ~68 ~22 ~0 ~68 stone 0  
fill ~10 ~0 ~69 ~21 ~0 ~69 stone 0  
fill ~10 ~0 ~70 ~13 ~0 ~70 stone 0  
fill ~10 ~0 ~71 ~13 ~0 ~71 stone 0  
fill ~10 ~0 ~72 ~17 ~0 ~72 stone 0  
fill ~10 ~0 ~73 ~15 ~0 ~73 stone 0  
fill ~11 ~0 ~31 ~24 ~0 ~31 stone 0 
setblock ~11 ~0 ~32 dirt 0  
fill ~11 ~0 ~48 ~12 ~0 ~48 iron_ore 0  
fill ~11 ~0 ~49 ~12 ~0 ~49 iron_ore 0  
fill ~11 ~0 ~50 ~14 ~0 ~50 stone 0  
fill ~11 ~0 ~74 ~13 ~0 ~74 stone 0  
fill ~12 ~0 ~32 ~24 ~0 ~32 stone 0  
fill ~13 ~0 ~48 ~13 ~3 ~48 stone 0  
fill ~13 ~0 ~49 ~13 ~3 ~49 stone 0  
fill ~14 ~0 ~17 ~14 ~1 ~17 dirt 0  
fill ~14 ~0 ~18 ~15 ~0 ~18 dirt 0  
fill ~14 ~0 ~19 ~16 ~0 ~19 dirt 0  
fill ~14 ~0 ~20 ~17 ~0 ~20 dirt 0  
fill ~14 ~0 ~21 ~17 ~0 ~21 dirt 0  
fill ~14 ~0 ~22 ~18 ~0 ~22 dirt 0  
fill ~14 ~0 ~47 ~17 ~0 ~47 dirt 0  
fill ~14 ~0 ~48 ~17 ~0 ~48 dirt 0  
fill ~14 ~0 ~49 ~17 ~0 ~49 dirt 0  
fill ~14 ~0 ~70 ~15 ~0 ~70 coal_ore 0  
fill ~14 ~0 ~71 ~14 ~0 ~70 coal_ore 0  
fill ~14 ~0 ~158 ~19 ~0 ~158 grass 0  
fill ~15 ~0 ~17 ~26 ~0 ~17 stone 0  
fill ~15 ~0 ~23 ~18 ~0 ~23 dirt 0  
fill ~15 ~0 ~24 ~18 ~0 ~24 dirt 0  
fill ~15 ~0 ~46 ~17 ~0 ~46 dirt 0  
fill ~15 ~0 ~50 ~16 ~0 ~50 dirt 0  
fill ~15 ~0 ~51 ~15 ~-1 ~51 dirt 0  
fill ~15 ~0 ~64 ~23 ~0 ~64 stone 0  
fill ~15 ~0 ~71 ~19 ~0 ~71 stone 0  
fill ~16 ~0 ~18 ~26 ~0 ~18 stone 0  
fill ~16 ~0 ~25 ~18 ~0 ~25 dirt 0  
fill ~16 ~0 ~37 ~16 ~1 ~37 iron_ore 0  
fill ~16 ~0 ~51 ~21 ~0 ~51 stone 0  
fill ~16 ~0 ~52 ~22 ~0 ~52 stone 0  
fill ~16 ~0 ~70 ~20 ~0 ~70 stone 0  
fill ~17 ~0 ~19 ~25 ~0 ~19 stone 0  
fill ~17 ~0 ~26 ~17 ~1 ~26 dirt 0  
fill ~17 ~0 ~37 ~24 ~0 ~37 stone 0  
fill ~17 ~0 ~50 ~21 ~0 ~50 stone 0  
fill ~17 ~0 ~53 ~23 ~0 ~53 stone 0  
fill ~17 ~0 ~54 ~24 ~0 ~54 stone 0  
fill ~17 ~0 ~58 ~18 ~0 ~58 stone 0  
fill ~17 ~0 ~63 ~24 ~0 ~63 stone 0  
fill ~17 ~0 ~159 ~22 ~0 ~159 grass 0  
fill ~18 ~0 ~14 ~22 ~0 ~14 dirt 0  
fill ~18 ~0 ~15 ~21 ~0 ~15 dirt 0  
fill ~18 ~0 ~16 ~20 ~0 ~16 dirt 0  
fill ~18 ~0 ~20 ~19 ~0 ~20 stone 0  
fill ~18 ~0 ~21 ~18 ~4 ~21 stone 0  
fill ~18 ~0 ~26 ~24 ~0 ~26 stone 0  
fill ~18 ~0 ~46 ~24 ~0 ~46 stone 0  
fill ~18 ~0 ~47 ~24 ~0 ~47 stone 0  
fill ~18 ~0 ~48 ~23 ~0 ~48 stone 0  
fill ~18 ~0 ~49 ~22 ~0 ~49 stone 0  
fill ~18 ~0 ~55 ~24 ~0 ~55 stone 0  
fill ~19 ~0 ~13 ~22 ~0 ~13 dirt 0  
fill ~19 ~0 ~21 ~21 ~0 ~21 gravel 0  
fill ~19 ~0 ~22 ~23 ~0 ~22 gravel 0  
fill ~19 ~0 ~23 ~19 ~2 ~23 stone 0  
fill ~19 ~0 ~24 ~21 ~0 ~24 stone 0  
fill ~19 ~0 ~25 ~22 ~0 ~25 stone 0  
fill ~19 ~0 ~57 ~19 ~0 ~58 coal_ore 0  
fill ~19 ~0 ~59 ~24 ~0 ~59 stone 0  
fill ~19 ~0 ~60 ~24 ~0 ~60 stone 0  
fill ~19 ~0 ~61 ~24 ~0 ~61 stone 0  
fill ~19 ~0 ~62 ~24 ~0 ~62 stone 0  
fill ~20 ~0 ~12 ~23 ~0 ~12 dirt 0 
setblock ~20 ~0 ~20 gravel 0  
fill ~20 ~0 ~23 ~24 ~0 ~23 gravel 0  
fill ~20 ~0 ~57 ~24 ~0 ~57 stone 0  
fill ~20 ~0 ~58 ~24 ~0 ~58 stone 0  
fill ~21 ~0 ~16 ~23 ~0 ~16 stone 0  
fill ~21 ~0 ~20 ~25 ~0 ~20 stone 0  
fill ~21 ~0 ~56 ~24 ~0 ~56 stone 0  
fill ~22 ~0 ~10 ~23 ~0 ~10 dirt 0  
fill ~22 ~0 ~11 ~23 ~0 ~11 dirt 0  
fill ~22 ~0 ~15 ~23 ~0 ~15 stone 0  
fill ~22 ~0 ~21 ~29 ~0 ~21 stone 0  
fill ~22 ~0 ~24 ~24 ~0 ~24 gravel 0  
fill ~23 ~0 ~13 ~25 ~0 ~13 stone 0  
fill ~23 ~0 ~14 ~23 ~2 ~14 stone 0  
fill ~23 ~0 ~25 ~24 ~0 ~25 gravel 0  
fill ~23 ~0 ~42 ~23 ~0 ~43 gravel 0  
fill ~24 ~0 ~10 ~25 ~0 ~10 stone 0  
fill ~24 ~0 ~11 ~25 ~0 ~11 stone 0  
fill ~24 ~0 ~12 ~25 ~0 ~12 stone 0  
fill ~24 ~0 ~22 ~29 ~0 ~22 stone 0  
fill ~24 ~0 ~43 ~24 ~0 ~44 gravel 0 
setblock ~25 ~0 ~14 torch 2  
fill ~25 ~0 ~23 ~29 ~0 ~23 stone 0  
fill ~25 ~0 ~24 ~26 ~0 ~24 stone 0  
fill ~25 ~0 ~25 ~96 ~0 ~25 stone 0  
fill ~25 ~0 ~30 ~25 ~0 ~31 dirt 0  
fill ~25 ~0 ~128 ~25 ~0 ~130 dirt 0  
fill ~26 ~0 ~3 ~26 ~26 ~3 iron_block 0  
fill ~26 ~0 ~4 ~26 ~0 ~14 iron_block 0  
fill ~26 ~0 ~19 ~27 ~0 ~19 dirt 0  
fill ~26 ~0 ~20 ~27 ~0 ~20 dirt 0  
fill ~26 ~0 ~26 ~96 ~0 ~26 stone 0  
fill ~26 ~0 ~28 ~27 ~0 ~28 stone 0  
fill ~26 ~0 ~29 ~27 ~0 ~29 stone 0  
fill ~26 ~0 ~30 ~27 ~0 ~30 stone 0  
fill ~26 ~0 ~31 ~27 ~0 ~31 stone 0  
fill ~26 ~0 ~34 ~27 ~0 ~34 stone 0  
fill ~26 ~0 ~35 ~27 ~0 ~35 stone 0  
fill ~26 ~0 ~36 ~27 ~0 ~36 stone 0  
fill ~26 ~0 ~37 ~27 ~0 ~37 stone 0  
fill ~26 ~0 ~38 ~27 ~0 ~38 stone 0  
fill ~26 ~0 ~39 ~27 ~0 ~39 stone 0  
fill ~26 ~0 ~40 ~27 ~0 ~40 stone 0  
fill ~26 ~0 ~41 ~27 ~0 ~41 stone 0  
fill ~26 ~0 ~42 ~27 ~0 ~42 stone 0  
fill ~26 ~0 ~43 ~27 ~0 ~43 stone 0  
fill ~26 ~0 ~44 ~27 ~0 ~44 stone 0  
fill ~26 ~0 ~45 ~27 ~0 ~45 stone 0  
fill ~26 ~0 ~65 ~27 ~0 ~65 stone 0  
fill ~26 ~0 ~66 ~27 ~0 ~66 stone 0  
fill ~26 ~0 ~67 ~27 ~0 ~67 stone 0  
fill ~26 ~0 ~68 ~27 ~0 ~68 stone 0  
fill ~26 ~0 ~69 ~27 ~0 ~69 stone 0  
fill ~26 ~0 ~70 ~27 ~0 ~70 stone 0  
fill ~26 ~0 ~71 ~27 ~0 ~71 stone 0  
fill ~26 ~0 ~72 ~27 ~0 ~72 stone 0  
fill ~26 ~0 ~73 ~27 ~0 ~73 stone 0  
fill ~26 ~0 ~74 ~27 ~0 ~74 stone 0  
fill ~26 ~0 ~75 ~27 ~0 ~75 stone 0  
fill ~26 ~0 ~76 ~27 ~0 ~76 stone 0  
fill ~26 ~0 ~77 ~27 ~0 ~77 stone 0  
fill ~26 ~0 ~78 ~27 ~0 ~78 stone 0  
fill ~26 ~0 ~79 ~27 ~0 ~79 stone 0  
fill ~26 ~0 ~80 ~27 ~0 ~80 stone 0  
fill ~26 ~0 ~81 ~27 ~0 ~81 stone 0  
fill ~26 ~0 ~82 ~27 ~0 ~82 stone 0  
fill ~26 ~0 ~83 ~27 ~0 ~83 stone 0  
fill ~26 ~0 ~84 ~27 ~0 ~84 stone 0  
fill ~26 ~0 ~85 ~27 ~0 ~85 stone 0  
fill ~26 ~0 ~86 ~27 ~0 ~86 stone 0  
fill ~26 ~0 ~87 ~27 ~0 ~87 stone 0  
fill ~26 ~0 ~88 ~27 ~0 ~88 stone 0  
fill ~26 ~0 ~89 ~27 ~0 ~89 stone 0  
fill ~26 ~0 ~90 ~27 ~0 ~90 stone 0  
fill ~26 ~0 ~91 ~27 ~0 ~91 stone 0  
fill ~26 ~0 ~92 ~27 ~0 ~92 stone 0  
fill ~26 ~0 ~93 ~27 ~0 ~93 stone 0  
fill ~26 ~0 ~94 ~27 ~0 ~94 stone 0  
fill ~26 ~0 ~95 ~27 ~0 ~95 stone 0  
fill ~26 ~0 ~96 ~27 ~0 ~96 stone 0  
fill ~26 ~0 ~97 ~27 ~0 ~97 stone 0  
fill ~26 ~0 ~98 ~27 ~0 ~98 stone 0  
fill ~26 ~0 ~99 ~27 ~0 ~99 stone 0  
fill ~26 ~0 ~100 ~27 ~0 ~100 stone 0  
fill ~26 ~0 ~101 ~27 ~0 ~101 stone 0  
fill ~26 ~0 ~102 ~27 ~0 ~102 stone 0  
fill ~26 ~0 ~103 ~27 ~0 ~103 stone 0  
fill ~26 ~0 ~104 ~27 ~0 ~104 stone 0  
fill ~26 ~0 ~105 ~27 ~0 ~105 stone 0  
fill ~26 ~0 ~106 ~27 ~0 ~106 stone 0  
fill ~26 ~0 ~107 ~27 ~0 ~107 stone 0  
fill ~26 ~0 ~108 ~27 ~0 ~108 stone 0  
fill ~26 ~0 ~109 ~27 ~0 ~109 stone 0  
fill ~26 ~0 ~110 ~27 ~0 ~110 stone 0  
fill ~26 ~0 ~111 ~27 ~0 ~111 stone 0  
fill ~26 ~0 ~112 ~27 ~0 ~112 stone 0  
fill ~26 ~0 ~113 ~27 ~0 ~113 stone 0  
fill ~26 ~0 ~114 ~27 ~0 ~114 stone 0  
fill ~26 ~0 ~115 ~27 ~0 ~115 stone 0  
fill ~26 ~0 ~116 ~27 ~0 ~116 stone 0  
fill ~26 ~0 ~117 ~27 ~0 ~117 stone 0  
fill ~26 ~0 ~118 ~27 ~0 ~118 stone 0  
fill ~26 ~0 ~119 ~27 ~0 ~119 stone 0  
fill ~26 ~0 ~120 ~27 ~0 ~120 stone 0  
fill ~26 ~0 ~121 ~27 ~0 ~121 stone 0  
fill ~26 ~0 ~122 ~27 ~0 ~122 stone 0  
fill ~26 ~0 ~123 ~27 ~0 ~123 stone 0  
fill ~26 ~0 ~124 ~27 ~0 ~124 stone 0  
fill ~26 ~0 ~125 ~27 ~0 ~125 stone 0  
fill ~26 ~0 ~126 ~27 ~0 ~126 stone 0  
fill ~26 ~0 ~127 ~27 ~0 ~127 stone 0  
fill ~26 ~0 ~128 ~27 ~0 ~128 stone 0  
fill ~26 ~0 ~130 ~26 ~0 ~134 stone 0 
setblock ~26 ~0 ~143 torch 5  
fill ~26 ~0 ~145 ~26 ~5 ~145 iron_block 0  
fill ~26 ~0 ~146 ~26 ~0 ~157 iron_block 0  
fill ~27 ~0 ~4 ~27 ~0 ~8 sand 0  
fill ~27 ~0 ~17 ~28 ~0 ~17 dirt 0  
fill ~27 ~0 ~18 ~28 ~0 ~18 dirt 0  
fill ~27 ~0 ~32 ~27 ~0 ~134 stone 0  
fill ~28 ~0 ~3 ~28 ~26 ~3 iron_block 0  
fill ~28 ~0 ~4 ~28 ~0 ~14 iron_block 0  
fill ~28 ~0 ~19 ~29 ~0 ~19 stone 0  
fill ~28 ~0 ~20 ~29 ~0 ~20 stone 0  
fill ~28 ~0 ~27 ~94 ~0 ~27 iron_block 0  
fill ~28 ~0 ~28 ~28 ~0 ~132 iron_block 0  
fill ~28 ~0 ~133 ~96 ~0 ~133 stone 0  
fill ~28 ~0 ~134 ~96 ~0 ~134 stone 0  
fill ~28 ~0 ~145 ~28 ~5 ~145 iron_block 0  
fill ~28 ~0 ~146 ~28 ~0 ~157 iron_block 0  
fill ~29 ~0 ~3 ~35 ~0 ~3 sand 0  
fill ~29 ~0 ~4 ~35 ~0 ~4 sand 0  
fill ~29 ~0 ~5 ~37 ~0 ~5 sand 0  
fill ~29 ~0 ~6 ~36 ~0 ~6 sand 0  
fill ~29 ~0 ~7 ~37 ~0 ~7 sand 0   

KittysCommands:  
setblock ~29 ~0 ~14 torch 1  
fill ~29 ~0 ~17 ~29 ~0 ~23 stone 0  
fill ~29 ~0 ~132 ~94 ~0 ~132 iron_block 0  
fill ~30 ~0 ~24 ~31 ~0 ~24 dirt 0 
setblock ~30 ~0 ~29 torch 5 
setblock ~30 ~0 ~130 torch 5  
fill ~36 ~0 ~3 ~41 ~0 ~3 grass 0  
fill ~36 ~0 ~4 ~38 ~0 ~4 grass 0  
fill ~37 ~0 ~6 ~39 ~0 ~6 dirt 0  
fill ~38 ~0 ~5 ~39 ~0 ~5 dirt 0  
fill ~38 ~0 ~7 ~39 ~0 ~7 dirt 0 
setblock ~39 ~0 ~4 dirt 0  
fill ~40 ~0 ~4 ~42 ~0 ~4 grass 0  
fill ~40 ~0 ~5 ~43 ~0 ~5 grass 0  
fill ~40 ~0 ~6 ~43 ~0 ~6 grass 0  
fill ~40 ~0 ~7 ~47 ~0 ~7 grass 0  
fill ~42 ~0 ~3 ~45 ~0 ~3 dirt 0  
fill ~43 ~0 ~4 ~45 ~0 ~4 dirt 0  
fill ~44 ~0 ~5 ~45 ~0 ~5 dirt 0  
fill ~44 ~0 ~6 ~45 ~0 ~6 dirt 0 
setblock ~48 ~0 ~7 dirt 0 
setblock ~49 ~0 ~7 grass 0  
fill ~50 ~0 ~7 ~54 ~0 ~7 dirt 0  
fill ~51 ~0 ~6 ~54 ~0 ~6 dirt 0 
setblock ~51 ~0 ~145 torch 5  
fill ~52 ~0 ~3 ~52 ~0 ~4 grass 0  
fill ~53 ~0 ~3 ~54 ~0 ~3 dirt 0  
fill ~53 ~0 ~4 ~54 ~0 ~4 dirt 0  
fill ~53 ~0 ~5 ~54 ~0 ~5 dirt 0 
setblock ~54 ~0 ~14 torch 2  
fill ~55 ~0 ~3 ~55 ~26 ~3 iron_block 0  
fill ~55 ~0 ~4 ~55 ~0 ~14 iron_block 0  
fill ~55 ~0 ~145 ~55 ~5 ~145 iron_block 0  
fill ~55 ~0 ~146 ~55 ~0 ~157 iron_block 0  
fill ~56 ~0 ~3 ~56 ~0 ~7 dirt 0  
fill ~57 ~0 ~3 ~57 ~26 ~3 iron_block 0  
fill ~57 ~0 ~4 ~57 ~0 ~14 iron_block 0  
fill ~57 ~0 ~145 ~57 ~5 ~145 iron_block 0  
fill ~57 ~0 ~146 ~57 ~0 ~157 iron_block 0  
fill ~58 ~0 ~3 ~63 ~0 ~3 dirt 0  
fill ~58 ~0 ~4 ~62 ~0 ~4 dirt 0  
fill ~58 ~0 ~5 ~62 ~0 ~5 dirt 0  
fill ~58 ~0 ~6 ~61 ~0 ~6 dirt 0  
fill ~58 ~0 ~7 ~61 ~0 ~7 dirt 0 
setblock ~58 ~0 ~14 torch 1  
fill ~58 ~0 ~28 ~64 ~0 ~28 glass 0  
fill ~58 ~0 ~29 ~58 ~3 ~29 iron_block 0  
fill ~58 ~0 ~130 ~58 ~3 ~130 iron_block 0  
fill ~58 ~0 ~131 ~64 ~0 ~131 glass 0  
fill ~62 ~0 ~6 ~64 ~0 ~6 grass 0  
fill ~62 ~0 ~7 ~63 ~0 ~7 grass 0  
fill ~63 ~0 ~4 ~64 ~0 ~4 grass 0  
fill ~63 ~0 ~5 ~64 ~0 ~5 grass 0 
setblock ~64 ~0 ~3 grass 0 
setblock ~64 ~0 ~14 torch 2  
fill ~64 ~0 ~29 ~64 ~3 ~29 iron_block 0  
fill ~64 ~0 ~130 ~64 ~3 ~130 iron_block 0 
setblock ~64 ~0 ~144 torch 5  
fill ~65 ~0 ~3 ~65 ~26 ~3 iron_block 0  
fill ~65 ~0 ~4 ~65 ~0 ~14 iron_block 0  
fill ~65 ~0 ~145 ~65 ~5 ~145 iron_block 0  
fill ~65 ~0 ~146 ~65 ~0 ~157 iron_block 0  
fill ~66 ~0 ~3 ~66 ~0 ~5 grass 0  
fill ~67 ~0 ~3 ~67 ~26 ~3 iron_block 0  
fill ~67 ~0 ~4 ~67 ~0 ~14 iron_block 0  
fill ~67 ~0 ~145 ~67 ~5 ~145 iron_block 0  
fill ~67 ~0 ~146 ~67 ~0 ~157 iron_block 0  
fill ~68 ~0 ~3 ~81 ~0 ~3 grass 0 
setblock ~68 ~0 ~14 torch 1  
fill ~70 ~0 ~4 ~76 ~0 ~4 grass 0 
setblock ~76 ~0 ~143 torch 5  
fill ~85 ~0 ~3 ~93 ~0 ~3 grass 0  
fill ~86 ~0 ~4 ~93 ~0 ~4 grass 0  
fill ~90 ~0 ~135 ~91 ~0 ~135 dirt 0 
setblock ~92 ~0 ~29 torch 5 
setblock ~92 ~0 ~130 torch 5 
setblock ~93 ~0 ~14 torch 2 
setblock ~93 ~0 ~145 torch 2 
setblock ~93 ~0 ~157 torch 2  
fill ~94 ~0 ~3 ~94 ~26 ~3 iron_block 0  
fill ~94 ~0 ~4 ~94 ~0 ~14 iron_block 0  
fill ~94 ~0 ~28 ~94 ~0 ~132 iron_block 0  
fill ~94 ~0 ~145 ~94 ~5 ~145 iron_block 0  
fill ~94 ~0 ~146 ~94 ~0 ~157 iron_block 0 
setblock ~95 ~0 ~3 dirt 0  
fill ~95 ~0 ~4 ~95 ~0 ~5 grass 0  
fill ~95 ~0 ~27 ~96 ~0 ~27 stone 0  
fill ~95 ~0 ~28 ~96 ~0 ~28 stone 0  
fill ~95 ~0 ~29 ~96 ~0 ~29 stone 0  
fill ~95 ~0 ~30 ~95 ~0 ~134 stone 0  
fill ~96 ~0 ~3 ~96 ~26 ~3 iron_block 0  
fill ~96 ~0 ~4 ~96 ~0 ~14 iron_block 0  
fill ~96 ~0 ~31 ~96 ~0 ~134 stone 0  
fill ~96 ~0 ~145 ~96 ~5 ~145 iron_block 0  
fill ~96 ~0 ~146 ~96 ~0 ~157 iron_block 0  
fill ~97 ~0 ~3 ~97 ~0 ~4 dirt 0  
fill ~97 ~0 ~5 ~97 ~0 ~6 grass 0 
setblock ~97 ~0 ~14 torch 1  
fill ~97 ~0 ~73 ~118 ~0 ~73 stone 0  
fill ~97 ~0 ~74 ~97 ~0 ~76 stone_slab 0  
fill ~97 ~0 ~77 ~107 ~0 ~77 stone 0  
fill ~97 ~0 ~81 ~107 ~0 ~81 stone 0  
fill ~97 ~0 ~82 ~97 ~0 ~84 stone_slab 0  
fill ~97 ~0 ~85 ~118 ~0 ~85 stone 0 
setblock ~97 ~0 ~145 torch 1 
setblock ~97 ~0 ~157 torch 1 
setblock ~103 ~0 ~38 torch 5 
setblock ~107 ~0 ~24 torch 4  
fill ~107 ~0 ~25 ~118 ~0 ~25 iron_block 0  
fill ~107 ~0 ~27 ~118 ~0 ~27 iron_block 0 
setblock ~107 ~0 ~28 torch 3 
setblock ~107 ~0 ~51 torch 4  
fill ~107 ~0 ~52 ~118 ~0 ~52 iron_block 0  
fill ~107 ~0 ~54 ~118 ~0 ~54 iron_block 0 
setblock ~107 ~0 ~55 torch 3  
fill ~107 ~0 ~78 ~108 ~0 ~78 iron_block 0  
fill ~107 ~0 ~79 ~107 ~6 ~79 stone 0  
fill ~107 ~0 ~80 ~108 ~0 ~80 iron_block 0 
setblock ~107 ~0 ~103 torch 4  
fill ~107 ~0 ~104 ~118 ~0 ~104 iron_block 0  
fill ~107 ~0 ~106 ~118 ~0 ~106 iron_block 0 
setblock ~107 ~0 ~107 torch 3 
setblock ~107 ~0 ~131 torch 4  
fill ~107 ~0 ~132 ~118 ~0 ~132 iron_block 0  
fill ~107 ~0 ~134 ~118 ~0 ~134 iron_block 0 
setblock ~107 ~0 ~135 torch 3  
fill ~109 ~0 ~79 ~109 ~4 ~79 stone 0 
setblock ~115 ~0 ~1 dirt 0  
fill ~116 ~0 ~1 ~118 ~0 ~1 gravel 0  
fill ~116 ~0 ~2 ~116 ~0 ~1 gravel 0  
fill ~116 ~0 ~3 ~120 ~0 ~3 stone 0  
fill ~116 ~0 ~4 ~120 ~0 ~4 stone 0  
fill ~116 ~0 ~5 ~119 ~0 ~5 stone 0  
fill ~117 ~0 ~2 ~120 ~0 ~2 stone 0 
setblock ~118 ~0 ~24 torch 4 
setblock ~118 ~0 ~28 torch 3 
setblock ~118 ~0 ~51 torch 4 
setblock ~118 ~0 ~55 torch 3 
setblock ~118 ~0 ~103 torch 4 
setblock ~118 ~0 ~107 torch 3 
setblock ~118 ~0 ~131 torch 4 
setblock ~118 ~0 ~135 torch 3  
fill ~119 ~0 ~1 ~120 ~0 ~1 stone 0  
fill ~119 ~0 ~73 ~119 ~4 ~73 iron_block 0  
fill ~119 ~0 ~85 ~119 ~4 ~85 iron_block 0 
setblock ~120 ~0 ~5 coal_ore 0 
setblock ~1 ~1 ~144 grass 0  
fill ~1 ~1 ~145 ~1 ~1 ~159 dirt 0  
fill ~2 ~1 ~145 ~3 ~1 ~145 grass 0  
fill ~2 ~1 ~146 ~3 ~1 ~146 dirt 0  
fill ~2 ~1 ~147 ~4 ~1 ~147 dirt 0  
fill ~2 ~1 ~148 ~4 ~1 ~148 dirt 0  
fill ~2 ~1 ~149 ~4 ~1 ~149 dirt 0  
fill ~2 ~1 ~150 ~4 ~1 ~150 dirt 0  
fill ~2 ~1 ~151 ~4 ~1 ~151 dirt 0  
fill ~2 ~1 ~152 ~4 ~1 ~152 dirt 0  
fill ~2 ~1 ~153 ~5 ~1 ~153 dirt 0  
fill ~2 ~1 ~154 ~5 ~1 ~154 dirt 0  
fill ~2 ~1 ~155 ~5 ~1 ~155 dirt 0  
fill ~2 ~1 ~156 ~5 ~1 ~156 dirt 0  
fill ~2 ~1 ~157 ~5 ~1 ~157 dirt 0  
fill ~2 ~1 ~158 ~5 ~1 ~158 dirt 0  
fill ~2 ~1 ~159 ~5 ~1 ~159 dirt 0  
fill ~3 ~1 ~9 ~5 ~1 ~9 dirt 0  
fill ~3 ~1 ~10 ~17 ~1 ~10 stone 0  
fill ~3 ~1 ~11 ~17 ~1 ~11 stone 0  
fill ~3 ~1 ~12 ~18 ~1 ~12 stone 0  
fill ~3 ~1 ~13 ~25 ~1 ~13 stone 0  
fill ~3 ~1 ~14 ~23 ~1 ~14 stone 0  
fill ~3 ~1 ~15 ~23 ~1 ~15 stone 0  
fill ~3 ~1 ~16 ~13 ~1 ~16 stone 0  
fill ~3 ~1 ~17 ~10 ~1 ~17 stone 0  
fill ~3 ~1 ~18 ~10 ~1 ~18 stone 0  
fill ~3 ~1 ~19 ~11 ~1 ~19 stone 0  
fill ~3 ~1 ~20 ~13 ~1 ~20 stone 0  
fill ~3 ~1 ~21 ~13 ~1 ~21 stone 0  
fill ~3 ~1 ~22 ~13 ~1 ~22 stone 0  
fill ~3 ~1 ~23 ~14 ~1 ~23 stone 0  
fill ~3 ~1 ~24 ~14 ~1 ~24 stone 0  
fill ~3 ~1 ~25 ~15 ~1 ~25 stone 0  
fill ~3 ~1 ~26 ~16 ~1 ~26 stone 0  
fill ~3 ~1 ~27 ~25 ~1 ~27 stone 0  
fill ~3 ~1 ~28 ~20 ~1 ~28 stone 0  
fill ~3 ~1 ~29 ~21 ~1 ~29 stone 0  
fill ~3 ~1 ~30 ~21 ~1 ~30 stone 0  
fill ~3 ~1 ~31 ~25 ~1 ~31 stone 0  
fill ~3 ~1 ~32 ~25 ~1 ~32 stone 0  
fill ~3 ~1 ~33 ~25 ~1 ~33 stone 0  
fill ~3 ~1 ~34 ~25 ~1 ~34 stone 0 
setblock ~3 ~1 ~35 dirt 0  
fill ~3 ~1 ~36 ~14 ~1 ~36 stone 0  
fill ~3 ~1 ~37 ~14 ~1 ~37 stone 0  
fill ~3 ~1 ~38 ~25 ~1 ~38 stone 0  
fill ~3 ~1 ~39 ~25 ~1 ~39 stone 0  
fill ~3 ~1 ~40 ~25 ~1 ~40 stone 0  
fill ~3 ~1 ~41 ~25 ~1 ~41 stone 0  
fill ~3 ~1 ~42 ~22 ~1 ~42 stone 0  
fill ~3 ~1 ~43 ~22 ~1 ~43 stone 0  
fill ~3 ~1 ~44 ~25 ~1 ~44 stone 0  
fill ~3 ~1 ~45 ~25 ~1 ~45 stone 0  
fill ~3 ~1 ~46 ~8 ~1 ~46 stone 0  
fill ~3 ~1 ~47 ~8 ~1 ~47 stone 0  
fill ~3 ~1 ~48 ~5 ~1 ~48 stone 0  
fill ~3 ~1 ~49 ~4 ~1 ~49 stone 0  
fill ~3 ~1 ~50 ~4 ~1 ~50 stone 0  
fill ~3 ~1 ~51 ~7 ~1 ~51 stone 0  
fill ~3 ~1 ~52 ~8 ~1 ~52 stone 0  
fill ~3 ~1 ~53 ~8 ~1 ~53 stone 0  
fill ~3 ~1 ~54 ~8 ~1 ~54 stone 0  
fill ~3 ~1 ~78 ~3 ~26 ~78 iron_block 0  
fill ~3 ~1 ~79 ~7 ~1 ~79 dirt 0  
fill ~3 ~1 ~80 ~7 ~1 ~80 dirt 0  
fill ~3 ~1 ~81 ~7 ~1 ~81 dirt 0  
fill ~3 ~1 ~82 ~4 ~1 ~82 dirt 0  
fill ~3 ~1 ~83 ~7 ~1 ~83 sand 0  
fill ~3 ~1 ~84 ~7 ~1 ~84 sand 0  
fill ~3 ~1 ~85 ~7 ~1 ~85 sand 0  
fill ~3 ~1 ~86 ~6 ~1 ~86 sand 0  
fill ~3 ~1 ~87 ~6 ~1 ~87 sand 0  
fill ~3 ~1 ~88 ~5 ~1 ~88 sand 0  
fill ~3 ~1 ~89 ~4 ~1 ~89 sand 0  
fill ~3 ~1 ~104 ~3 ~26 ~104 iron_block 0  
fill ~3 ~1 ~106 ~3 ~26 ~106 iron_block 0  
fill ~3 ~1 ~132 ~3 ~26 ~132 iron_block 0  
fill ~3 ~1 ~134 ~3 ~26 ~134 iron_block 0  
fill ~4 ~1 ~35 ~25 ~1 ~35 stone 0 
setblock ~4 ~1 ~146 grass 0  
fill ~5 ~1 ~82 ~7 ~1 ~82 sand 0  
fill ~5 ~1 ~147 ~5 ~1 ~152 grass 0  
fill ~6 ~1 ~9 ~9 ~1 ~9 stone 0  
fill ~6 ~1 ~152 ~6 ~1 ~159 grass 0  
fill ~7 ~1 ~48 ~8 ~1 ~48 stone 0  
fill ~7 ~1 ~155 ~7 ~1 ~159 grass 0  
fill ~8 ~1 ~58 ~8 ~1 ~59 grass 0 
setblock ~8 ~1 ~60 stone 0 
setblock ~8 ~1 ~61 grass 0 
setblock ~8 ~1 ~62 stone 0  
fill ~8 ~1 ~63 ~8 ~1 ~64 grass 0  
fill ~8 ~1 ~157 ~8 ~1 ~159 grass 0  
fill ~9 ~1 ~52 ~9 ~21 ~52 iron_block 0  
fill ~9 ~1 ~54 ~9 ~21 ~54 iron_block 0  
fill ~9 ~1 ~78 ~9 ~21 ~78 iron_block 0  
fill ~9 ~1 ~80 ~9 ~21 ~80 iron_block 0  
fill ~9 ~1 ~104 ~9 ~21 ~104 iron_block 0  
fill ~9 ~1 ~106 ~9 ~21 ~106 iron_block 0  
fill ~9 ~1 ~132 ~9 ~21 ~132 iron_block 0  
fill ~9 ~1 ~134 ~9 ~21 ~134 iron_block 0  
fill ~9 ~1 ~158 ~13 ~1 ~158 grass 0  
fill ~9 ~1 ~159 ~16 ~1 ~159 grass 0  
fill ~10 ~1 ~9 ~10 ~2 ~9 dirt 0  
fill ~10 ~1 ~46 ~25 ~1 ~46 stone 0  
fill ~10 ~1 ~47 ~25 ~1 ~47 stone 0  
fill ~10 ~1 ~57 ~15 ~1 ~57 stone 0  
fill ~10 ~1 ~58 ~14 ~1 ~58 stone 0  
fill ~10 ~1 ~59 ~12 ~1 ~59 stone 0 
setblock ~10 ~1 ~60 dirt 0  
fill ~10 ~1 ~61 ~12 ~1 ~61 stone 0  
fill ~10 ~1 ~62 ~11 ~1 ~62 grass 0  
fill ~11 ~1 ~9 ~14 ~1 ~9 stone 0  
fill ~11 ~1 ~17 ~13 ~1 ~17 gravel 0  
fill ~11 ~1 ~18 ~13 ~1 ~18 gravel 0  
fill ~11 ~1 ~48 ~21 ~1 ~48 stone 0  
fill ~11 ~1 ~49 ~11 ~0 ~49 iron_ore 0  
fill ~11 ~1 ~50 ~21 ~1 ~50 stone 0  
fill ~11 ~1 ~56 ~15 ~1 ~56 stone 0  
fill ~11 ~1 ~60 ~12 ~1 ~60 stone 0  
fill ~12 ~1 ~19 ~13 ~1 ~19 gravel 0  
fill ~12 ~1 ~49 ~12 ~3 ~49 stone 0  
fill ~12 ~1 ~62 ~12 ~1 ~63 stone 0  
fill ~13 ~1 ~64 ~13 ~1 ~67 stone 0  
fill ~14 ~1 ~16 ~17 ~1 ~16 gravel 0  
fill ~14 ~1 ~18 ~15 ~1 ~18 dirt 0  
fill ~14 ~1 ~19 ~16 ~1 ~19 dirt 0  
fill ~14 ~1 ~20 ~17 ~1 ~20 dirt 0  
fill ~14 ~1 ~21 ~17 ~1 ~21 dirt 0  
fill ~14 ~1 ~22 ~18 ~1 ~22 dirt 0  
fill ~14 ~1 ~49 ~21 ~1 ~49 stone 0  
fill ~14 ~1 ~65 ~19 ~1 ~65 stone 0  
fill ~14 ~1 ~66 ~20 ~1 ~66 stone 0  
fill ~14 ~1 ~67 ~19 ~1 ~67 stone 0  
fill ~14 ~1 ~68 ~19 ~1 ~68 stone 0  
fill ~15 ~1 ~9 ~18 ~1 ~9 dirt 0  
fill ~15 ~1 ~17 ~18 ~1 ~17 gravel 0  
fill ~15 ~1 ~23 ~18 ~1 ~23 dirt 0  
fill ~15 ~1 ~24 ~18 ~1 ~24 dirt 0  
fill ~15 ~1 ~36 ~16 ~1 ~36 iron_ore 0  
fill ~15 ~1 ~37 ~15 ~1 ~36 iron_ore 0  
fill ~15 ~1 ~51 ~15 ~2 ~51 stone 0  
fill ~15 ~1 ~52 ~15 ~5 ~52 iron_block 0  
fill ~15 ~1 ~54 ~15 ~5 ~54 iron_block 0  
fill ~15 ~1 ~64 ~15 ~0 ~64 stone 0  
fill ~15 ~1 ~69 ~16 ~1 ~69 stone 0  
fill ~15 ~1 ~78 ~15 ~5 ~78 iron_block 0  
fill ~15 ~1 ~80 ~15 ~5 ~80 iron_block 0  
fill ~15 ~1 ~104 ~15 ~5 ~104 iron_block 0  
fill ~15 ~1 ~106 ~15 ~5 ~106 iron_block 0  
fill ~15 ~1 ~132 ~15 ~5 ~132 iron_block 0  
fill ~15 ~1 ~134 ~15 ~5 ~134 iron_block 0  
fill ~16 ~1 ~18 ~18 ~1 ~18 gravel 0  
fill ~16 ~1 ~25 ~18 ~1 ~25 dirt 0  
fill ~17 ~1 ~19 ~17 ~4 ~19 gravel 0  
fill ~17 ~1 ~36 ~25 ~1 ~36 stone 0  
fill ~17 ~1 ~37 ~25 ~1 ~37 stone 0  
fill ~17 ~1 ~51 ~21 ~1 ~51 stone 0  
fill ~17 ~1 ~52 ~21 ~1 ~52 stone 0  
fill ~17 ~1 ~53 ~22 ~1 ~53 stone 0  
fill ~17 ~1 ~54 ~25 ~1 ~54 stone 0  
fill ~17 ~1 ~64 ~19 ~1 ~64 stone 0  
fill ~17 ~1 ~69 ~20 ~1 ~69 dirt 0  
fill ~18 ~1 ~10 ~20 ~1 ~10 gravel 0  
fill ~18 ~1 ~11 ~20 ~1 ~11 gravel 0  
fill ~18 ~1 ~16 ~23 ~1 ~16 stone 0  
fill ~18 ~1 ~19 ~23 ~1 ~19 stone 0  
fill ~18 ~1 ~20 ~24 ~1 ~20 stone 0  
fill ~18 ~1 ~26 ~25 ~1 ~26 stone 0  
fill ~19 ~1 ~9 ~20 ~1 ~9 gravel 0  
fill ~19 ~1 ~12 ~19 ~2 ~12 gravel 0  
fill ~19 ~1 ~17 ~23 ~1 ~17 stone 0  
fill ~19 ~1 ~18 ~23 ~1 ~18 stone 0  
fill ~19 ~1 ~21 ~27 ~1 ~21 stone 0  
fill ~19 ~1 ~22 ~28 ~1 ~22 stone 0  
fill ~19 ~1 ~24 ~98 ~1 ~24 stone 0  
fill ~19 ~1 ~25 ~25 ~1 ~25 stone 0  
fill ~19 ~1 ~55 ~25 ~1 ~55 stone 0  
fill ~20 ~1 ~12 ~25 ~1 ~12 stone 0  
fill ~20 ~1 ~23 ~98 ~1 ~23 stone 0  
fill ~20 ~1 ~57 ~20 ~0 ~57 stone 0  
fill ~20 ~1 ~61 ~25 ~1 ~61 stone 0  
fill ~20 ~1 ~62 ~22 ~1 ~62 stone 0  
fill ~20 ~1 ~63 ~21 ~1 ~63 stone 0 
setblock ~20 ~1 ~65 dirt 0  
fill ~21 ~1 ~9 ~21 ~1 ~27 stone 0  
fill ~21 ~1 ~56 ~25 ~1 ~56 stone 0  
fill ~21 ~1 ~64 ~21 ~1 ~65 stone 0  
fill ~22 ~1 ~9 ~25 ~1 ~9 dirt 0  
fill ~22 ~1 ~10 ~23 ~1 ~10 stone 0  
fill ~22 ~1 ~11 ~22 ~2 ~11 dirt 0  
fill ~22 ~1 ~57 ~25 ~1 ~57 stone 0  
fill ~22 ~1 ~58 ~25 ~1 ~58 stone 0  
fill ~22 ~1 ~59 ~25 ~1 ~59 stone 0  
fill ~22 ~1 ~60 ~25 ~1 ~60 stone 0  
fill ~22 ~1 ~65 ~22 ~2 ~65 stone 0  
fill ~23 ~1 ~11 ~25 ~1 ~11 stone 0 
setblock ~23 ~1 ~43 gravel 0  
fill ~24 ~1 ~10 ~25 ~1 ~10 dirt 0  
fill ~24 ~1 ~28 ~25 ~1 ~28 stone 0  
fill ~24 ~1 ~29 ~25 ~1 ~29 stone 0  
fill ~24 ~1 ~30 ~25 ~1 ~30 stone 0  
fill ~24 ~1 ~42 ~25 ~1 ~42 stone 0  
fill ~24 ~1 ~43 ~25 ~1 ~43 stone 0  
fill ~24 ~1 ~48 ~25 ~1 ~48 stone 0  
fill ~24 ~1 ~49 ~25 ~1 ~49 stone 0  
fill ~24 ~1 ~50 ~25 ~1 ~50 stone 0  
fill ~24 ~1 ~51 ~25 ~1 ~51 stone 0  
fill ~24 ~1 ~52 ~25 ~1 ~52 stone 0  
fill ~24 ~1 ~53 ~25 ~1 ~53 stone 0  
fill ~24 ~1 ~62 ~25 ~1 ~62 stone 0  
fill ~24 ~1 ~63 ~25 ~1 ~63 stone 0  
fill ~24 ~1 ~64 ~25 ~1 ~64 stone 0  
fill ~24 ~1 ~65 ~25 ~1 ~65 stone 0  
fill ~24 ~1 ~66 ~25 ~1 ~66 stone 0  
fill ~24 ~1 ~67 ~25 ~1 ~67 stone 0  
fill ~24 ~1 ~68 ~25 ~1 ~68 stone 0  
fill ~24 ~1 ~69 ~25 ~1 ~69 stone 0  
fill ~24 ~1 ~70 ~25 ~1 ~70 stone 0  
fill ~24 ~1 ~71 ~25 ~1 ~71 stone 0  
fill ~24 ~1 ~72 ~25 ~1 ~72 stone 0  
fill ~24 ~1 ~73 ~25 ~1 ~73 stone 0  
fill ~24 ~1 ~74 ~25 ~1 ~74 stone 0  
fill ~24 ~1 ~75 ~25 ~1 ~75 stone 0  
fill ~24 ~1 ~76 ~25 ~1 ~76 stone 0  
fill ~24 ~1 ~77 ~25 ~1 ~77 stone 0  
fill ~24 ~1 ~78 ~25 ~1 ~78 stone 0  
fill ~24 ~1 ~79 ~25 ~1 ~79 stone 0  
fill ~24 ~1 ~80 ~25 ~1 ~80 stone 0  
fill ~24 ~1 ~81 ~25 ~1 ~81 stone 0  
fill ~24 ~1 ~82 ~25 ~1 ~82 stone 0  
fill ~24 ~1 ~83 ~25 ~1 ~83 stone 0  
fill ~24 ~1 ~84 ~25 ~1 ~84 stone 0  
fill ~24 ~1 ~85 ~25 ~1 ~85 stone 0  
fill ~24 ~1 ~86 ~25 ~1 ~86 stone 0  
fill ~24 ~1 ~87 ~25 ~1 ~87 stone 0  
fill ~24 ~1 ~88 ~25 ~1 ~88 stone 0  
fill ~24 ~1 ~89 ~25 ~1 ~89 stone 0  
fill ~24 ~1 ~90 ~25 ~1 ~90 stone 0  
fill ~24 ~1 ~91 ~25 ~1 ~91 stone 0  
fill ~24 ~1 ~92 ~25 ~1 ~92 stone 0  
fill ~24 ~1 ~93 ~25 ~1 ~93 stone 0  
fill ~24 ~1 ~94 ~25 ~1 ~94 stone 0  
fill ~24 ~1 ~95 ~25 ~1 ~95 stone 0  
fill ~24 ~1 ~96 ~25 ~1 ~96 stone 0  
fill ~24 ~1 ~97 ~25 ~1 ~97 stone 0  
fill ~24 ~1 ~98 ~25 ~1 ~98 stone 0  
fill ~24 ~1 ~99 ~25 ~1 ~99 stone 0  
fill ~24 ~1 ~100 ~25 ~1 ~100 stone 0  
fill ~24 ~1 ~101 ~25 ~1 ~101 stone 0  
fill ~24 ~1 ~102 ~25 ~1 ~102 stone 0  
fill ~24 ~1 ~103 ~25 ~1 ~103 stone 0  
fill ~24 ~1 ~104 ~25 ~1 ~104 stone 0  
fill ~24 ~1 ~105 ~25 ~1 ~105 stone 0  
fill ~24 ~1 ~106 ~25 ~1 ~106 stone 0  
fill ~24 ~1 ~107 ~25 ~1 ~107 stone 0  
fill ~24 ~1 ~108 ~25 ~1 ~108 stone 0  
fill ~24 ~1 ~109 ~25 ~1 ~109 stone 0  
fill ~24 ~1 ~110 ~25 ~1 ~110 stone 0  
fill ~24 ~1 ~111 ~25 ~1 ~111 stone 0  
fill ~24 ~1 ~112 ~25 ~1 ~112 stone 0  
fill ~24 ~1 ~113 ~25 ~1 ~113 stone 0  
fill ~24 ~1 ~114 ~25 ~1 ~114 stone 0  
fill ~24 ~1 ~115 ~25 ~1 ~115 stone 0  
fill ~24 ~1 ~116 ~25 ~1 ~116 stone 0  
fill ~24 ~1 ~117 ~25 ~1 ~117 stone 0  
fill ~24 ~1 ~118 ~25 ~1 ~118 stone 0  
fill ~24 ~1 ~119 ~25 ~1 ~119 stone 0  
fill ~24 ~1 ~120 ~25 ~1 ~120 stone 0  
fill ~24 ~1 ~121 ~25 ~1 ~121 stone 0  
fill ~24 ~1 ~122 ~25 ~1 ~122 stone 0  
fill ~24 ~1 ~123 ~25 ~1 ~123 stone 0  
fill ~24 ~1 ~124 ~25 ~1 ~124 stone 0  
fill ~24 ~1 ~125 ~25 ~1 ~125 stone 0  
fill ~24 ~1 ~126 ~25 ~1 ~126 stone 0  
fill ~24 ~1 ~127 ~25 ~1 ~127 stone 0  
fill ~24 ~1 ~128 ~25 ~1 ~128 stone 0  
fill ~24 ~1 ~129 ~25 ~1 ~129 stone 0  
fill ~24 ~1 ~130 ~25 ~1 ~130 stone 0  
fill ~24 ~1 ~131 ~25 ~1 ~131 stone 0  
fill ~24 ~1 ~132 ~25 ~1 ~132 stone 0  
fill ~24 ~1 ~133 ~25 ~1 ~133 stone 0  
fill ~24 ~1 ~134 ~25 ~1 ~134 stone 0  
fill ~24 ~1 ~135 ~98 ~1 ~135 stone 0  
fill ~24 ~1 ~136 ~98 ~1 ~136 stone 0  
fill ~26 ~1 ~9 ~26 ~21 ~9 iron_block 0  
fill ~26 ~1 ~14 ~26 ~5 ~14 iron_block 0  
fill ~26 ~1 ~25 ~29 ~1 ~25 stone_slab 0  
fill ~26 ~1 ~26 ~26 ~1 ~28 stone_slab 0 
setblock ~26 ~1 ~29 torch 1 
setblock ~26 ~1 ~30 wool 14 
setblock ~26 ~1 ~31 stone_slab 1 
setblock ~26 ~1 ~32 wool 14 
setblock ~26 ~1 ~33 stone_slab 1 
setblock ~26 ~1 ~34 wool 14 
setblock ~26 ~1 ~35 stone_slab 1 
setblock ~26 ~1 ~36 wool 14 
setblock ~26 ~1 ~37 stone_slab 1 
setblock ~26 ~1 ~38 wool 14 
setblock ~26 ~1 ~39 stone_slab 1 
setblock ~26 ~1 ~40 wool 14 
setblock ~26 ~1 ~41 stone_slab 1 
setblock ~26 ~1 ~42 wool 14 
setblock ~26 ~1 ~43 stone_slab 1 
setblock ~26 ~1 ~44 wool 14 
setblock ~26 ~1 ~45 stone_slab 1 
setblock ~26 ~1 ~46 wool 14 
setblock ~26 ~1 ~47 stone_slab 1 
setblock ~26 ~1 ~48 wool 14 
setblock ~26 ~1 ~49 stone_slab 1 
setblock ~26 ~1 ~50 wool 14 
setblock ~26 ~1 ~51 torch 1  
fill ~26 ~1 ~52 ~26 ~1 ~54 stone_slab 0 
setblock ~26 ~1 ~55 torch 1 
setblock ~26 ~1 ~56 wool 11 
setblock ~26 ~1 ~57 stone_slab 1 
setblock ~26 ~1 ~58 wool 11 
setblock ~26 ~1 ~59 stone_slab 1 
setblock ~26 ~1 ~60 wool 11 
setblock ~26 ~1 ~61 stone_slab 1 
setblock ~26 ~1 ~62 wool 11 
setblock ~26 ~1 ~63 stone_slab 1 
setblock ~26 ~1 ~64 wool 11 
setblock ~26 ~1 ~65 stone_slab 1 
setblock ~26 ~1 ~66 wool 11 
setblock ~26 ~1 ~67 stone_slab 1 
setblock ~26 ~1 ~68 wool 11 
setblock ~26 ~1 ~69 stone_slab 1 
setblock ~26 ~1 ~70 wool 11 
setblock ~26 ~1 ~71 stone_slab 1 
setblock ~26 ~1 ~72 wool 11 
setblock ~26 ~1 ~73 stone_slab 1 
setblock ~26 ~1 ~74 wool 11 
setblock ~26 ~1 ~75 stone_slab 1 
setblock ~26 ~1 ~76 wool 11 
setblock ~26 ~1 ~77 torch 1  
fill ~26 ~1 ~78 ~26 ~1 ~80 stone_slab 0 
setblock ~26 ~1 ~81 torch 1 
setblock ~26 ~1 ~82 wool 14 
setblock ~26 ~1 ~83 stone_slab 1 
setblock ~26 ~1 ~84 wool 14 
setblock ~26 ~1 ~85 stone_slab 1 
setblock ~26 ~1 ~86 wool 14 
setblock ~26 ~1 ~87 stone_slab 1 
setblock ~26 ~1 ~88 wool 14 
setblock ~26 ~1 ~89 stone_slab 1 
setblock ~26 ~1 ~90 wool 14 
setblock ~26 ~1 ~91 stone_slab 1 
setblock ~26 ~1 ~92 wool 14 
setblock ~26 ~1 ~93 stone_slab 1 
setblock ~26 ~1 ~94 wool 14 
setblock ~26 ~1 ~95 stone_slab 1 
setblock ~26 ~1 ~96 wool 14 
setblock ~26 ~1 ~97 stone_slab 1 
setblock ~26 ~1 ~98 wool 14 
setblock ~26 ~1 ~99 stone_slab 1 
setblock ~26 ~1 ~100 wool 14 
setblock ~26 ~1 ~101 stone_slab 1 
setblock ~26 ~1 ~102 wool 14 
setblock ~26 ~1 ~103 torch 1  
fill ~26 ~1 ~104 ~26 ~1 ~106 stone_slab 0 
setblock ~26 ~1 ~107 torch 1 
setblock ~26 ~1 ~108 wool 11 
setblock ~26 ~1 ~109 stone_slab 1 
setblock ~26 ~1 ~110 wool 11 
setblock ~26 ~1 ~111 stone_slab 1 
setblock ~26 ~1 ~112 wool 11 
setblock ~26 ~1 ~113 stone_slab 1 
setblock ~26 ~1 ~114 wool 11 
setblock ~26 ~1 ~115 stone_slab 1 
setblock ~26 ~1 ~116 wool 11 
setblock ~26 ~1 ~117 stone_slab 1 
setblock ~26 ~1 ~118 wool 11 
setblock ~26 ~1 ~119 stone_slab 1 
setblock ~26 ~1 ~120 wool 11 
setblock ~26 ~1 ~121 stone_slab 1 
setblock ~26 ~1 ~122 wool 11 
setblock ~26 ~1 ~123 stone_slab 1 
setblock ~26 ~1 ~124 wool 11 
setblock ~26 ~1 ~125 stone_slab 1 
setblock ~26 ~1 ~126 wool 11 
setblock ~26 ~1 ~127 stone_slab 1 
setblock ~26 ~1 ~128 wool 11 
setblock ~26 ~1 ~129 stone_slab 1 
setblock ~26 ~1 ~130 wool 11 
setblock ~26 ~1 ~131 torch 1  
fill ~26 ~1 ~132 ~26 ~1 ~134 stone_slab 0  
fill ~26 ~1 ~151 ~26 ~21 ~151 iron_block 0  
fill ~26 ~1 ~157 ~26 ~26 ~157 iron_block 0  
fill ~27 ~1 ~134 ~28 ~1 ~134 stone_slab 0  
fill ~28 ~1 ~9 ~28 ~21 ~9 iron_block 0  
fill ~28 ~1 ~14 ~28 ~5 ~14 iron_block 0  
fill ~28 ~1 ~151 ~28 ~21 ~151 iron_block 0  
fill ~28 ~1 ~157 ~28 ~26 ~157 iron_block 0 
setblock ~29 ~1 ~3 torch 1  
fill ~29 ~1 ~5 ~35 ~1 ~5 sand 0  
fill ~29 ~1 ~6 ~36 ~1 ~6 sand 0  
fill ~29 ~1 ~7 ~37 ~1 ~7 sand 0 
setblock ~29 ~1 ~134 torch 4 
setblock ~30 ~1 ~25 torch 3 
setblock ~30 ~1 ~134 wool 14 
setblock ~31 ~1 ~25 wool 11 
setblock ~31 ~1 ~134 stone_slab 1 
setblock ~32 ~1 ~25 stone_slab 1 
setblock ~32 ~1 ~134 wool 14  
fill ~33 ~1 ~4 ~34 ~1 ~4 sand 0 
setblock ~33 ~1 ~25 wool 11 
setblock ~33 ~1 ~134 stone_slab 1 
setblock ~34 ~1 ~25 stone_slab 1 
setblock ~34 ~1 ~134 wool 14 
setblock ~35 ~1 ~25 wool 11 
setblock ~35 ~1 ~134 stone_slab 1 
setblock ~36 ~1 ~25 stone_slab 1 
setblock ~36 ~1 ~134 wool 14 
setblock ~37 ~1 ~5 sand 0  
fill ~37 ~1 ~6 ~39 ~1 ~6 grass 0 
setblock ~37 ~1 ~25 wool 11 
setblock ~37 ~1 ~134 stone_slab 1  
fill ~38 ~1 ~5 ~39 ~1 ~5 grass 0  
fill ~38 ~1 ~7 ~39 ~1 ~7 grass 0 
setblock ~38 ~1 ~25 stone_slab 1 
setblock ~38 ~1 ~134 wool 14 
setblock ~39 ~1 ~4 grass 0 
setblock ~39 ~1 ~25 wool 11 
setblock ~39 ~1 ~134 stone_slab 1 
setblock ~40 ~1 ~25 stone_slab 1 
setblock ~40 ~1 ~134 wool 14 
setblock ~41 ~1 ~25 wool 11 
setblock ~41 ~1 ~134 stone_slab 1  
fill ~41 ~1 ~137 ~41 ~2 ~137 stone 0  
fill ~42 ~1 ~3 ~45 ~1 ~3 grass 0 
setblock ~42 ~1 ~25 stone_slab 1 
setblock ~42 ~1 ~134 wool 14  
fill ~43 ~1 ~4 ~45 ~1 ~4 grass 0 
setblock ~43 ~1 ~25 wool 11 
setblock ~43 ~1 ~134 stone_slab 1  
fill ~44 ~1 ~5 ~45 ~1 ~5 grass 0  
fill ~44 ~1 ~6 ~45 ~1 ~6 grass 0 
setblock ~44 ~1 ~25 stone_slab 1 
setblock ~44 ~1 ~134 wool 14 
setblock ~45 ~1 ~25 wool 11 
setblock ~45 ~1 ~134 stone_slab 1 
setblock ~46 ~1 ~25 stone_slab 1 
setblock ~46 ~1 ~134 wool 14 
setblock ~47 ~1 ~25 wool 11 
setblock ~47 ~1 ~134 stone_slab 1 
setblock ~48 ~1 ~7 grass 0 
setblock ~48 ~1 ~25 stone_slab 1 
setblock ~48 ~1 ~134 wool 14 
setblock ~49 ~1 ~25 wool 11 
setblock ~49 ~1 ~134 stone_slab 1  
fill ~50 ~1 ~7 ~54 ~1 ~7 grass 0 
setblock ~50 ~1 ~25 stone_slab 1 
setblock ~50 ~1 ~134 wool 14  
fill ~51 ~1 ~6 ~54 ~1 ~6 grass 0 
setblock ~51 ~1 ~25 wool 11 
setblock ~51 ~1 ~134 stone_slab 1 
setblock ~52 ~1 ~25 stone_slab 1 
setblock ~52 ~1 ~134 wool 14  
fill ~53 ~1 ~3 ~54 ~1 ~3 grass 0  
fill ~53 ~1 ~4 ~54 ~1 ~4 grass 0  
fill ~53 ~1 ~5 ~54 ~1 ~5 grass 0 
setblock ~53 ~1 ~25 wool 11 
setblock ~53 ~1 ~134 torch 4 
setblock ~54 ~1 ~25 torch 3  
fill ~54 ~1 ~134 ~57 ~1 ~134 stone_slab 0  
fill ~55 ~1 ~9 ~55 ~21 ~9 iron_block 0  
fill ~55 ~1 ~14 ~55 ~5 ~14 iron_block 0  
fill ~55 ~1 ~25 ~57 ~1 ~25 stone_slab 0  
fill ~55 ~1 ~151 ~55 ~21 ~151 iron_block 0  
fill ~55 ~1 ~157 ~55 ~26 ~157 iron_block 0  
fill ~56 ~1 ~3 ~56 ~1 ~7 grass 0  
fill ~57 ~1 ~9 ~57 ~21 ~9 iron_block 0  
fill ~57 ~1 ~14 ~57 ~5 ~14 iron_block 0  
fill ~57 ~1 ~151 ~57 ~21 ~151 iron_block 0  
fill ~57 ~1 ~157 ~57 ~26 ~157 iron_block 0  
fill ~58 ~1 ~3 ~63 ~1 ~3 grass 0  
fill ~58 ~1 ~4 ~62 ~1 ~4 grass 0  
fill ~58 ~1 ~5 ~62 ~1 ~5 grass 0  
fill ~58 ~1 ~6 ~61 ~1 ~6 grass 0  
fill ~58 ~1 ~7 ~61 ~1 ~7 grass 0 
setblock ~58 ~1 ~25 torch 3  
fill ~58 ~1 ~28 ~64 ~1 ~28 glass 0  
fill ~58 ~1 ~131 ~64 ~1 ~131 glass 0 
setblock ~58 ~1 ~134 torch 4 
setblock ~59 ~1 ~25 wool 14 
setblock ~59 ~1 ~134 wool 11 
setblock ~60 ~1 ~25 stone_slab 1 
setblock ~60 ~1 ~134 stone_slab 1 
setblock ~61 ~1 ~25 wool 14 
setblock ~61 ~1 ~134 wool 11 
setblock ~62 ~1 ~25 stone_slab 1 
setblock ~62 ~1 ~134 stone_slab 1 
setblock ~63 ~1 ~25 wool 14 
setblock ~63 ~1 ~134 wool 11 
setblock ~64 ~1 ~3 torch 2 
setblock ~64 ~1 ~25 torch 3 
setblock ~64 ~1 ~134 torch 4  
fill ~65 ~1 ~9 ~65 ~21 ~9 iron_block 0  
fill ~65 ~1 ~14 ~65 ~5 ~14 iron_block 0  
fill ~65 ~1 ~25 ~67 ~1 ~25 stone_slab 0  
fill ~65 ~1 ~134 ~68 ~1 ~134 stone_slab 0  
fill ~65 ~1 ~151 ~65 ~21 ~151 iron_block 0  
fill ~65 ~1 ~157 ~65 ~26 ~157 iron_block 0  
fill ~67 ~1 ~9 ~67 ~21 ~9 iron_block 0  
fill ~67 ~1 ~14 ~67 ~5 ~14 iron_block 0  
fill ~67 ~1 ~151 ~67 ~21 ~151 iron_block 0  
fill ~67 ~1 ~157 ~67 ~26 ~157 iron_block 0 
setblock ~68 ~1 ~3 torch 1 
setblock ~68 ~1 ~25 torch 3 
setblock ~69 ~1 ~25 wool 14 
setblock ~69 ~1 ~134 torch 4 
setblock ~70 ~1 ~25 stone_slab 1 
setblock ~70 ~1 ~134 wool 11 
setblock ~71 ~1 ~25 wool 14 
setblock ~71 ~1 ~134 stone_slab 1 
setblock ~72 ~1 ~25 stone_slab 1 
setblock ~72 ~1 ~134 wool 11 
setblock ~73 ~1 ~25 wool 14 
setblock ~73 ~1 ~134 stone_slab 1 
setblock ~74 ~1 ~25 stone_slab 1 
setblock ~74 ~1 ~134 wool 11 
setblock ~75 ~1 ~25 wool 14 
setblock ~75 ~1 ~134 stone_slab 1 
setblock ~76 ~1 ~25 stone_slab 1 
setblock ~76 ~1 ~134 wool 11 
setblock ~77 ~1 ~25 wool 14 
setblock ~77 ~1 ~134 stone_slab 1 
setblock ~78 ~1 ~25 stone_slab 1 
setblock ~78 ~1 ~134 wool 11 
setblock ~79 ~1 ~25 wool 14 
setblock ~79 ~1 ~134 stone_slab 1 
setblock ~80 ~1 ~25 stone_slab 1 
setblock ~80 ~1 ~134 wool 11 
setblock ~81 ~1 ~25 wool 14 
setblock ~81 ~1 ~134 stone_slab 1 
setblock ~82 ~1 ~25 stone_slab 1 
setblock ~82 ~1 ~134 wool 11 
setblock ~83 ~1 ~25 wool 14 
setblock ~83 ~1 ~134 stone_slab 1 
setblock ~84 ~1 ~25 stone_slab 1 
setblock ~84 ~1 ~134 wool 11 
setblock ~85 ~1 ~25 wool 14 
setblock ~85 ~1 ~134 stone_slab 1 
setblock ~86 ~1 ~25 stone_slab 1 
setblock ~86 ~1 ~134 wool 11 
setblock ~87 ~1 ~25 wool 14 
setblock ~87 ~1 ~134 stone_slab 1 
setblock ~88 ~1 ~25 stone_slab 1 
setblock ~88 ~1 ~134 wool 11 
setblock ~89 ~1 ~25 wool 14 
setblock ~89 ~1 ~134 stone_slab 1 
setblock ~90 ~1 ~25 stone_slab 1 
setblock ~90 ~1 ~134 wool 11 
setblock ~91 ~1 ~25 wool 14 
setblock ~91 ~1 ~134 stone_slab 1 
setblock ~92 ~1 ~25 torch 3 
setblock ~92 ~1 ~134 wool 11 
setblock ~93 ~1 ~3 torch 2  
fill ~93 ~1 ~25 ~96 ~1 ~25 stone_slab 0 
setblock ~93 ~1 ~134 torch 4  
fill ~94 ~1 ~9 ~94 ~21 ~9 iron_block 0  
fill ~94 ~1 ~14 ~94 ~5 ~14 iron_block 0  
fill ~94 ~1 ~134 ~96 ~1 ~134 stone_slab 0  
fill ~94 ~1 ~151 ~94 ~21 ~151 iron_block 0  
fill ~94 ~1 ~157 ~94 ~26 ~157 iron_block 0 
setblock ~95 ~1 ~3 grass 0  
fill ~96 ~1 ~9 ~96 ~21 ~9 iron_block 0  
fill ~96 ~1 ~14 ~96 ~5 ~14 iron_block 0  
fill ~96 ~1 ~26 ~96 ~1 ~28 stone_slab 0 
setblock ~96 ~1 ~29 torch 2 
setblock ~96 ~1 ~30 wool 11 
setblock ~96 ~1 ~31 stone_slab 1 
setblock ~96 ~1 ~32 wool 11 
setblock ~96 ~1 ~33 stone_slab 1 
setblock ~96 ~1 ~34 wool 11 
setblock ~96 ~1 ~35 stone_slab 1 
setblock ~96 ~1 ~36 wool 11 
setblock ~96 ~1 ~37 stone_slab 1 
setblock ~96 ~1 ~38 wool 11 
setblock ~96 ~1 ~39 stone_slab 1 
setblock ~96 ~1 ~40 wool 11 
setblock ~96 ~1 ~41 stone_slab 1 
setblock ~96 ~1 ~42 wool 11 
setblock ~96 ~1 ~43 stone_slab 1 
setblock ~96 ~1 ~44 wool 11 
setblock ~96 ~1 ~45 stone_slab 1 
setblock ~96 ~1 ~46 wool 11 
setblock ~96 ~1 ~47 stone_slab 1 
setblock ~96 ~1 ~48 wool 11 
setblock ~96 ~1 ~49 stone_slab 1 
setblock ~96 ~1 ~50 wool 11 
setblock ~96 ~1 ~51 torch 2  
fill ~96 ~1 ~52 ~96 ~1 ~54 stone_slab 0 
setblock ~96 ~1 ~55 torch 2 
setblock ~96 ~1 ~56 wool 14 
setblock ~96 ~1 ~57 stone_slab 1 
setblock ~96 ~1 ~58 wool 14 
setblock ~96 ~1 ~59 stone_slab 1 
setblock ~96 ~1 ~60 wool 14 
setblock ~96 ~1 ~61 stone_slab 1 
setblock ~96 ~1 ~62 wool 14 
setblock ~96 ~1 ~63 stone_slab 1 
setblock ~96 ~1 ~64 wool 14 
setblock ~96 ~1 ~65 stone_slab 1 
setblock ~96 ~1 ~66 wool 14 
setblock ~96 ~1 ~67 stone_slab 1 
setblock ~96 ~1 ~68 wool 14 
setblock ~96 ~1 ~69 stone_slab 1 
setblock ~96 ~1 ~70 wool 14  
fill ~96 ~1 ~71 ~96 ~1 ~72 stone_slab 1  
fill ~96 ~1 ~73 ~96 ~6 ~73 iron_block 0  
fill ~96 ~1 ~77 ~96 ~6 ~77 iron_block 0  
fill ~96 ~1 ~78 ~96 ~1 ~80 stone_slab 0  
fill ~96 ~1 ~81 ~96 ~6 ~81 iron_block 0  
fill ~96 ~1 ~85 ~96 ~6 ~85 iron_block 0  
fill ~96 ~1 ~86 ~96 ~1 ~87 stone_slab 1 
setblock ~96 ~1 ~88 wool 11 
setblock ~96 ~1 ~89 stone_slab 1 
setblock ~96 ~1 ~90 wool 11 
setblock ~96 ~1 ~91 stone_slab 1 
setblock ~96 ~1 ~92 wool 11 
setblock ~96 ~1 ~93 stone_slab 1 
setblock ~96 ~1 ~94 wool 11 
setblock ~96 ~1 ~95 stone_slab 1 
setblock ~96 ~1 ~96 wool 11 
setblock ~96 ~1 ~97 stone_slab 1 
setblock ~96 ~1 ~98 wool 11 
setblock ~96 ~1 ~99 stone_slab 1 
setblock ~96 ~1 ~100 wool 11 
setblock ~96 ~1 ~101 stone_slab 1 
setblock ~96 ~1 ~102 wool 11 
setblock ~96 ~1 ~103 torch 2  
fill ~96 ~1 ~104 ~96 ~1 ~106 stone_slab 0 
setblock ~96 ~1 ~107 torch 2 
setblock ~96 ~1 ~108 wool 14 
setblock ~96 ~1 ~109 stone_slab 1 
setblock ~96 ~1 ~110 wool 14 
setblock ~96 ~1 ~111 stone_slab 1 
setblock ~96 ~1 ~112 wool 14 
setblock ~96 ~1 ~113 stone_slab 1 
setblock ~96 ~1 ~114 wool 14 
setblock ~96 ~1 ~115 stone_slab 1 
setblock ~96 ~1 ~116 wool 14 
setblock ~96 ~1 ~117 stone_slab 1 
setblock ~96 ~1 ~118 wool 14 
setblock ~96 ~1 ~119 stone_slab 1 
setblock ~96 ~1 ~120 wool 14 
setblock ~96 ~1 ~121 stone_slab 1 
setblock ~96 ~1 ~122 wool 14 
setblock ~96 ~1 ~123 stone_slab 1 
setblock ~96 ~1 ~124 wool 14 
setblock ~96 ~1 ~125 stone_slab 1 
setblock ~96 ~1 ~126 wool 14 
setblock ~96 ~1 ~127 stone_slab 1 
setblock ~96 ~1 ~128 wool 14 
setblock ~96 ~1 ~129 stone_slab 1 
setblock ~96 ~1 ~130 wool 14 
setblock ~96 ~1 ~131 torch 2  
fill ~96 ~1 ~132 ~96 ~1 ~134 stone_slab 0  
fill ~96 ~1 ~151 ~96 ~21 ~151 iron_block 0  
fill ~96 ~1 ~157 ~96 ~26 ~157 iron_block 0  
fill ~97 ~1 ~3 ~97 ~1 ~4 grass 0  
fill ~97 ~1 ~25 ~98 ~1 ~25 stone 0  
fill ~97 ~1 ~26 ~98 ~1 ~26 stone 0  
fill ~97 ~1 ~27 ~98 ~1 ~27 stone 0  
fill ~97 ~1 ~28 ~98 ~1 ~28 stone 0  
fill ~97 ~1 ~29 ~98 ~1 ~29 stone 0  
fill ~97 ~1 ~30 ~98 ~1 ~30 stone 0  
fill ~97 ~1 ~31 ~98 ~1 ~31 stone 0  
fill ~97 ~1 ~32 ~98 ~1 ~32 stone 0  
fill ~97 ~1 ~33 ~98 ~1 ~33 stone 0  
fill ~97 ~1 ~34 ~98 ~1 ~34 stone 0  
fill ~97 ~1 ~35 ~98 ~1 ~35 stone 0  
fill ~97 ~1 ~36 ~98 ~1 ~36 stone 0  
fill ~97 ~1 ~37 ~98 ~1 ~37 stone 0  
fill ~97 ~1 ~38 ~98 ~1 ~38 stone 0  
fill ~97 ~1 ~39 ~98 ~1 ~39 stone 0  
fill ~97 ~1 ~40 ~98 ~1 ~40 stone 0  
fill ~97 ~1 ~41 ~98 ~1 ~41 stone 0  
fill ~97 ~1 ~42 ~98 ~1 ~42 stone 0  
fill ~97 ~1 ~43 ~98 ~1 ~43 stone 0  
fill ~97 ~1 ~44 ~98 ~1 ~44 stone 0  
fill ~97 ~1 ~45 ~98 ~1 ~45 stone 0  
fill ~97 ~1 ~46 ~98 ~1 ~46 stone 0  
fill ~97 ~1 ~47 ~98 ~1 ~47 stone 0  
fill ~97 ~1 ~48 ~98 ~1 ~48 stone 0  
fill ~97 ~1 ~49 ~98 ~1 ~49 stone 0  
fill ~97 ~1 ~50 ~98 ~1 ~50 stone 0  
fill ~97 ~1 ~51 ~98 ~1 ~51 stone 0  
fill ~97 ~1 ~52 ~98 ~1 ~52 stone 0  
fill ~97 ~1 ~53 ~98 ~1 ~53 stone 0  
fill ~97 ~1 ~54 ~98 ~1 ~54 stone 0  
fill ~97 ~1 ~55 ~98 ~1 ~55 stone 0  
fill ~97 ~1 ~56 ~98 ~1 ~56 stone 0  
fill ~97 ~1 ~57 ~98 ~1 ~57 stone 0  
fill ~97 ~1 ~58 ~98 ~1 ~58 stone 0  
fill ~97 ~1 ~59 ~98 ~1 ~59 stone 0  
fill ~97 ~1 ~60 ~98 ~1 ~60 stone 0  
fill ~97 ~1 ~61 ~98 ~1 ~61 stone 0  
fill ~97 ~1 ~62 ~98 ~1 ~62 stone 0  
fill ~97 ~1 ~63 ~98 ~1 ~63 stone 0  
fill ~97 ~1 ~64 ~98 ~1 ~64 stone 0  
fill ~97 ~1 ~65 ~98 ~1 ~65 stone 0  
fill ~97 ~1 ~66 ~98 ~1 ~66 stone 0  
fill ~97 ~1 ~67 ~98 ~1 ~67 stone 0  
fill ~97 ~1 ~68 ~98 ~1 ~68 stone 0  
fill ~97 ~1 ~69 ~98 ~1 ~69 stone 0  
fill ~97 ~1 ~70 ~98 ~1 ~70 stone 0  
fill ~97 ~1 ~71 ~98 ~1 ~71 stone 0  
fill ~97 ~1 ~72 ~98 ~1 ~72 stone 0  
fill ~97 ~1 ~73 ~118 ~1 ~73 stone 0  
fill ~97 ~1 ~77 ~107 ~1 ~77 stone 0  
fill ~97 ~1 ~78 ~98 ~1 ~78 stone 0  
fill ~97 ~1 ~79 ~98 ~1 ~79 stone 0  
fill ~97 ~1 ~80 ~98 ~1 ~80 stone 0  
fill ~97 ~1 ~81 ~107 ~1 ~81 stone 0  
fill ~97 ~1 ~85 ~118 ~1 ~85 stone 0  
fill ~97 ~1 ~86 ~98 ~1 ~86 stone 0  
fill ~97 ~1 ~87 ~98 ~1 ~87 stone 0  
fill ~97 ~1 ~88 ~98 ~1 ~88 stone 0  
fill ~97 ~1 ~89 ~98 ~1 ~89 stone 0  
fill ~97 ~1 ~90 ~98 ~1 ~90 stone 0  
fill ~97 ~1 ~91 ~98 ~1 ~91 stone 0  
fill ~97 ~1 ~92 ~98 ~1 ~92 stone 0  
fill ~97 ~1 ~93 ~98 ~1 ~93 stone 0  
fill ~97 ~1 ~94 ~98 ~1 ~94 stone 0  
fill ~97 ~1 ~95 ~98 ~1 ~95 stone 0  
fill ~97 ~1 ~96 ~98 ~1 ~96 stone 0  
fill ~97 ~1 ~97 ~98 ~1 ~97 stone 0  
fill ~97 ~1 ~98 ~98 ~1 ~98 stone 0  
fill ~97 ~1 ~99 ~98 ~1 ~99 stone 0  
fill ~97 ~1 ~100 ~98 ~1 ~100 stone 0  
fill ~97 ~1 ~101 ~98 ~1 ~101 stone 0  
fill ~97 ~1 ~102 ~98 ~1 ~102 stone 0  
fill ~97 ~1 ~103 ~98 ~1 ~103 stone 0  
fill ~97 ~1 ~104 ~98 ~1 ~104 stone 0  
fill ~97 ~1 ~105 ~98 ~1 ~105 stone 0  
fill ~97 ~1 ~106 ~98 ~1 ~106 stone 0  
fill ~97 ~1 ~107 ~98 ~1 ~107 stone 0  
fill ~97 ~1 ~108 ~98 ~1 ~108 stone 0  
fill ~97 ~1 ~109 ~98 ~1 ~109 stone 0  
fill ~97 ~1 ~110 ~98 ~1 ~110 stone 0  
fill ~97 ~1 ~111 ~98 ~1 ~111 stone 0  
fill ~97 ~1 ~112 ~98 ~1 ~112 stone 0  
fill ~97 ~1 ~113 ~98 ~1 ~113 stone 0  
fill ~97 ~1 ~114 ~98 ~1 ~114 stone 0  
fill ~97 ~1 ~115 ~98 ~1 ~115 stone 0  
fill ~97 ~1 ~116 ~98 ~1 ~116 stone 0  
fill ~97 ~1 ~117 ~98 ~1 ~117 stone 0  
fill ~97 ~1 ~118 ~98 ~1 ~118 stone 0   
fill ~97 ~1 ~119 ~98 ~1 ~119 stone 0  
fill ~97 ~1 ~120 ~98 ~1 ~120 stone 0  
fill ~97 ~1 ~121 ~98 ~1 ~121 stone 0  
fill ~97 ~1 ~122 ~98 ~1 ~122 stone 0  
fill ~97 ~1 ~123 ~98 ~1 ~123 stone 0  
fill ~97 ~1 ~124 ~98 ~1 ~124 stone 0  
fill ~97 ~1 ~125 ~98 ~1 ~125 stone 0  
fill ~97 ~1 ~126 ~98 ~1 ~126 stone 0  
fill ~97 ~1 ~127 ~98 ~1 ~127 stone 0  
fill ~97 ~1 ~128 ~98 ~1 ~128 stone 0  
fill ~97 ~1 ~129 ~98 ~1 ~129 stone 0  
fill ~97 ~1 ~130 ~98 ~1 ~130 stone 0  
fill ~97 ~1 ~131 ~98 ~1 ~131 stone 0  
fill ~97 ~1 ~132 ~98 ~1 ~132 stone 0  
fill ~97 ~1 ~133 ~98 ~1 ~133 stone 0  
fill ~97 ~1 ~134 ~98 ~1 ~134 stone 0  
fill ~99 ~1 ~25 ~100 ~1 ~25 iron_block 0  
fill ~99 ~1 ~27 ~100 ~1 ~27 iron_block 0  
fill ~99 ~1 ~52 ~100 ~1 ~52 iron_block 0  
fill ~99 ~1 ~54 ~100 ~1 ~54 iron_block 0  
fill ~99 ~1 ~78 ~100 ~1 ~78 iron_block 0  
fill ~99 ~1 ~80 ~100 ~1 ~80 iron_block 0  
fill ~99 ~1 ~104 ~100 ~1 ~104 iron_block 0  
fill ~99 ~1 ~106 ~100 ~1 ~106 iron_block 0  
fill ~99 ~1 ~134 ~100 ~1 ~134 iron_block 0  
fill ~107 ~1 ~25 ~107 ~5 ~25 iron_block 0  
fill ~107 ~1 ~27 ~107 ~5 ~27 iron_block 0  
fill ~107 ~1 ~52 ~107 ~5 ~52 iron_block 0  
fill ~107 ~1 ~54 ~107 ~5 ~54 iron_block 0  
fill ~107 ~1 ~78 ~108 ~1 ~78 iron_block 0  
fill ~107 ~1 ~80 ~108 ~1 ~80 iron_block 0  
fill ~107 ~1 ~104 ~107 ~5 ~104 iron_block 0  
fill ~107 ~1 ~106 ~107 ~5 ~106 iron_block 0  
fill ~107 ~1 ~132 ~107 ~5 ~132 iron_block 0  
fill ~107 ~1 ~134 ~107 ~5 ~134 iron_block 0 
setblock ~108 ~1 ~77 torch 4 
setblock ~108 ~1 ~81 torch 3 
setblock ~110 ~1 ~79 torch 1  
fill ~112 ~1 ~25 ~112 ~21 ~25 iron_block 0  
fill ~112 ~1 ~27 ~112 ~21 ~27 iron_block 0  
fill ~112 ~1 ~52 ~112 ~21 ~52 iron_block 0  
fill ~112 ~1 ~54 ~112 ~21 ~54 iron_block 0  
fill ~112 ~1 ~104 ~112 ~21 ~104 iron_block 0  
fill ~112 ~1 ~106 ~112 ~21 ~106 iron_block 0  
fill ~112 ~1 ~132 ~112 ~21 ~132 iron_block 0  
fill ~112 ~1 ~134 ~112 ~21 ~134 iron_block 0  
fill ~115 ~1 ~1 ~120 ~1 ~1 stone 0  
fill ~116 ~1 ~2 ~120 ~1 ~2 stone 0  
fill ~116 ~1 ~3 ~120 ~1 ~3 stone 0  
fill ~116 ~1 ~4 ~120 ~1 ~4 stone 0  
fill ~116 ~1 ~5 ~120 ~1 ~5 stone 0  
fill ~118 ~1 ~25 ~118 ~26 ~25 iron_block 0  
fill ~118 ~1 ~27 ~118 ~26 ~27 iron_block 0  
fill ~118 ~1 ~52 ~118 ~26 ~52 iron_block 0  
fill ~118 ~1 ~54 ~118 ~26 ~54 iron_block 0  
fill ~118 ~1 ~104 ~118 ~26 ~104 iron_block 0  
fill ~118 ~1 ~106 ~118 ~26 ~106 iron_block 0  
fill ~118 ~1 ~132 ~118 ~26 ~132 iron_block 0  
fill ~118 ~1 ~134 ~118 ~26 ~134 iron_block 0  
fill ~1 ~2 ~145 ~1 ~2 ~146 grass 0  
fill ~1 ~2 ~147 ~2 ~2 ~147 dirt 0  
fill ~1 ~2 ~148 ~2 ~2 ~148 dirt 0  
fill ~1 ~2 ~149 ~2 ~2 ~149 dirt 0  
fill ~1 ~2 ~150 ~2 ~2 ~150 dirt 0  
fill ~1 ~2 ~151 ~2 ~2 ~151 dirt 0  
fill ~1 ~2 ~152 ~2 ~2 ~152 dirt 0  
fill ~1 ~2 ~153 ~3 ~2 ~153 dirt 0  
fill ~1 ~2 ~154 ~3 ~2 ~154 dirt 0  
fill ~1 ~2 ~155 ~3 ~2 ~155 dirt 0  
fill ~1 ~2 ~156 ~3 ~2 ~156 dirt 0  
fill ~1 ~2 ~157 ~2 ~2 ~157 dirt 0  
fill ~1 ~2 ~158 ~2 ~2 ~158 dirt 0  
fill ~1 ~2 ~159 ~1 ~2 ~147 dirt 0  
fill ~2 ~2 ~146 ~3 ~2 ~146 grass 0  
fill ~2 ~2 ~159 ~5 ~2 ~159 grass 0  
fill ~3 ~2 ~9 ~14 ~2 ~9 dirt 0  
fill ~3 ~2 ~10 ~3 ~0 ~10 stone 0  
fill ~3 ~2 ~11 ~3 ~0 ~11 stone 0  
fill ~3 ~2 ~12 ~17 ~2 ~12 stone 0  
fill ~3 ~2 ~13 ~17 ~2 ~13 stone 0  
fill ~3 ~2 ~14 ~21 ~2 ~14 stone 0  
fill ~3 ~2 ~15 ~20 ~2 ~15 stone 0  
fill ~3 ~2 ~16 ~12 ~2 ~16 stone 0  
fill ~3 ~2 ~17 ~10 ~2 ~17 stone 0  
fill ~3 ~2 ~18 ~10 ~2 ~18 stone 0  
fill ~3 ~2 ~19 ~11 ~2 ~19 stone 0  
fill ~3 ~2 ~20 ~13 ~2 ~20 stone 0  
fill ~3 ~2 ~21 ~13 ~2 ~21 stone 0  
fill ~3 ~2 ~22 ~13 ~2 ~22 stone 0  
fill ~3 ~2 ~23 ~14 ~2 ~23 stone 0  
fill ~3 ~2 ~24 ~14 ~2 ~24 stone 0  
fill ~3 ~2 ~25 ~16 ~2 ~25 stone 0  
fill ~3 ~2 ~26 ~23 ~2 ~26 stone 0  
fill ~3 ~2 ~27 ~19 ~2 ~27 stone 0  
fill ~3 ~2 ~28 ~23 ~2 ~28 stone 0  
fill ~3 ~2 ~29 ~23 ~2 ~29 stone 0  
fill ~3 ~2 ~30 ~23 ~2 ~30 stone 0  
fill ~3 ~2 ~31 ~23 ~2 ~31 stone 0  
fill ~3 ~2 ~32 ~23 ~2 ~32 stone 0  
fill ~3 ~2 ~33 ~23 ~2 ~33 stone 0 
setblock ~3 ~2 ~34 dirt 0 
setblock ~3 ~2 ~35 grass 0 
setblock ~3 ~2 ~36 dirt 0  
fill ~3 ~2 ~37 ~12 ~2 ~37 stone 0  
fill ~3 ~2 ~38 ~12 ~2 ~38 stone 0  
fill ~3 ~2 ~39 ~10 ~2 ~39 stone 0  
fill ~3 ~2 ~40 ~10 ~2 ~40 stone 0  
fill ~3 ~2 ~41 ~7 ~2 ~41 stone 0  
fill ~3 ~2 ~42 ~6 ~2 ~42 stone 0  
fill ~3 ~2 ~43 ~7 ~2 ~43 stone 0  
fill ~3 ~2 ~44 ~8 ~2 ~44 stone 0  
fill ~3 ~2 ~45 ~8 ~2 ~45 stone 0  
fill ~3 ~2 ~47 ~3 ~0 ~47 stone 0  
fill ~3 ~2 ~48 ~3 ~0 ~48 stone 0  
fill ~3 ~2 ~49 ~3 ~0 ~49 stone 0  
fill ~3 ~2 ~50 ~3 ~0 ~50 stone 0  
fill ~3 ~2 ~51 ~4 ~2 ~51 stone 0  
fill ~3 ~2 ~52 ~7 ~2 ~52 stone 0  
fill ~3 ~2 ~53 ~7 ~2 ~53 stone 0  
fill ~3 ~2 ~54 ~7 ~2 ~54 stone 0  
fill ~3 ~2 ~79 ~7 ~2 ~79 grass 0  
fill ~3 ~2 ~80 ~3 ~-1 ~80 dirt 0  
