fill ~100 ~2 ~71 ~101 ~2 ~71 glowstone 0  
fill ~100 ~2 ~72 ~101 ~2 ~72 glowstone 0  
fill ~55 ~3 ~14 ~56 ~3 ~14 glowstone 0  
fill ~55 ~3 ~15 ~56 ~3 ~15 glowstone 0  
fill ~99 ~3 ~71 ~102 ~3 ~71 glowstone 0  
fill ~99 ~3 ~72 ~102 ~3 ~72 glowstone 0  
fill ~100 ~3 ~70 ~101 ~3 ~70 glowstone 0  
fill ~100 ~3 ~73 ~101 ~3 ~73 glowstone 0  
fill ~37 ~4 ~52 ~38 ~4 ~52 glowstone 0  
fill ~37 ~4 ~53 ~38 ~4 ~53 glowstone 0  
fill ~46 ~4 ~58 ~47 ~4 ~58 glowstone 0  
fill ~46 ~4 ~59 ~47 ~4 ~59 glowstone 0  
fill ~54 ~4 ~14 ~57 ~4 ~14 glowstone 0  
fill ~54 ~4 ~15 ~57 ~4 ~15 glowstone 0  
fill ~55 ~4 ~13 ~56 ~4 ~13 glowstone 0  
fill ~55 ~4 ~16 ~56 ~4 ~16 glowstone 0  
fill ~58 ~4 ~52 ~59 ~4 ~52 glowstone 0  
fill ~58 ~4 ~53 ~59 ~4 ~53 glowstone 0  
fill ~63 ~4 ~16 ~64 ~4 ~16 glowstone 0  
fill ~63 ~4 ~17 ~64 ~4 ~17 glowstone 0  
fill ~77 ~4 ~66 ~78 ~4 ~66 glowstone 0  
fill ~77 ~4 ~67 ~78 ~4 ~67 glowstone 0  
fill ~99 ~4 ~71 ~102 ~4 ~71 glowstone 0  
fill ~99 ~4 ~72 ~102 ~4 ~72 glowstone 0  
fill ~100 ~4 ~70 ~101 ~4 ~70 glowstone 0  
fill ~100 ~4 ~73 ~101 ~4 ~73 glowstone 0  
fill ~8 ~5 ~63 ~9 ~5 ~63 glowstone 0  
fill ~8 ~5 ~64 ~9 ~5 ~64 glowstone 0  
fill ~36 ~5 ~52 ~39 ~5 ~52 glowstone 0  
fill ~36 ~5 ~53 ~39 ~5 ~53 glowstone 0  
fill ~37 ~5 ~51 ~38 ~5 ~51 glowstone 0  
fill ~37 ~5 ~54 ~38 ~5 ~54 glowstone 0  
fill ~45 ~5 ~58 ~48 ~5 ~58 glowstone 0  
fill ~45 ~5 ~59 ~48 ~5 ~59 glowstone 0  
fill ~46 ~5 ~57 ~47 ~5 ~57 glowstone 0  
fill ~46 ~5 ~60 ~47 ~5 ~60 glowstone 0  
fill ~54 ~5 ~14 ~57 ~5 ~14 glowstone 0  
fill ~54 ~5 ~15 ~57 ~5 ~15 glowstone 0  
fill ~55 ~5 ~13 ~56 ~5 ~13 glowstone 0  
fill ~55 ~5 ~16 ~56 ~5 ~16 glowstone 0  
fill ~57 ~5 ~52 ~60 ~5 ~52 glowstone 0  
fill ~57 ~5 ~53 ~60 ~5 ~53 glowstone 0  
fill ~58 ~5 ~51 ~59 ~5 ~51 glowstone 0  
fill ~58 ~5 ~54 ~59 ~5 ~54 glowstone 0  
fill ~62 ~5 ~16 ~65 ~5 ~16 glowstone 0  
fill ~62 ~5 ~17 ~65 ~5 ~17 glowstone 0  
fill ~63 ~5 ~15 ~64 ~5 ~15 glowstone 0  
fill ~63 ~5 ~18 ~64 ~5 ~18 glowstone 0  
fill ~76 ~5 ~66 ~79 ~5 ~66 glowstone 0  
fill ~76 ~5 ~67 ~79 ~5 ~67 glowstone 0  
fill ~77 ~5 ~65 ~78 ~5 ~65 glowstone 0  
fill ~77 ~5 ~68 ~78 ~5 ~68 glowstone 0  
fill ~100 ~5 ~71 ~101 ~5 ~71 glowstone 0  
fill ~100 ~5 ~72 ~101 ~5 ~72 glowstone 0  
fill ~7 ~6 ~63 ~10 ~6 ~63 glowstone 0  
fill ~7 ~6 ~64 ~10 ~6 ~64 glowstone 0  
fill ~8 ~6 ~62 ~9 ~6 ~62 glowstone 0  
fill ~8 ~6 ~65 ~9 ~6 ~65 glowstone 0  
fill ~36 ~6 ~52 ~39 ~6 ~52 glowstone 0  
fill ~36 ~6 ~53 ~39 ~6 ~53 glowstone 0  
fill ~37 ~6 ~51 ~38 ~6 ~51 glowstone 0  
fill ~37 ~6 ~54 ~38 ~6 ~54 glowstone 0  
fill ~45 ~6 ~58 ~48 ~6 ~58 glowstone 0  
fill ~45 ~6 ~59 ~48 ~6 ~59 glowstone 0  
fill ~46 ~6 ~57 ~47 ~6 ~57 glowstone 0  
fill ~46 ~6 ~60 ~47 ~6 ~60 glowstone 0  
fill ~55 ~6 ~14 ~56 ~6 ~14 glowstone 0  
fill ~55 ~6 ~15 ~56 ~6 ~15 glowstone 0  
fill ~57 ~6 ~52 ~60 ~6 ~52 glowstone 0  
fill ~57 ~6 ~53 ~60 ~6 ~53 glowstone 0  
fill ~58 ~6 ~51 ~59 ~6 ~51 glowstone 0  
fill ~58 ~6 ~54 ~59 ~6 ~54 glowstone 0  
fill ~62 ~6 ~16 ~65 ~6 ~16 glowstone 0  
fill ~62 ~6 ~17 ~65 ~6 ~17 glowstone 0  
fill ~63 ~6 ~15 ~64 ~6 ~15 glowstone 0  
fill ~63 ~6 ~18 ~64 ~6 ~18 glowstone 0  
fill ~76 ~6 ~66 ~79 ~6 ~66 glowstone 0  
fill ~76 ~6 ~67 ~79 ~6 ~67 glowstone 0  
fill ~77 ~6 ~65 ~78 ~6 ~65 glowstone 0  
fill ~77 ~6 ~68 ~78 ~6 ~68 glowstone 0  
fill ~7 ~7 ~63 ~10 ~7 ~63 glowstone 0  
fill ~7 ~7 ~64 ~10 ~7 ~64 glowstone 0  
fill ~8 ~7 ~62 ~9 ~7 ~62 glowstone 0  
fill ~8 ~7 ~65 ~9 ~7 ~65 glowstone 0  
fill ~37 ~7 ~52 ~38 ~7 ~52 glowstone 0  
fill ~37 ~7 ~53 ~38 ~7 ~53 glowstone 0  
fill ~46 ~7 ~58 ~47 ~7 ~58 glowstone 0  
fill ~46 ~7 ~59 ~47 ~7 ~59 glowstone 0  
fill ~58 ~7 ~52 ~59 ~7 ~52 glowstone 0  
fill ~58 ~7 ~53 ~59 ~7 ~53 glowstone 0  
fill ~63 ~7 ~16 ~64 ~7 ~16 glowstone 0  
fill ~63 ~7 ~17 ~64 ~7 ~17 glowstone 0  
fill ~77 ~7 ~66 ~78 ~7 ~66 glowstone 0  
fill ~77 ~7 ~67 ~78 ~7 ~67 glowstone 0  
fill ~8 ~8 ~63 ~9 ~8 ~63 glowstone 0  
fill ~8 ~8 ~64 ~9 ~8 ~64 glowstone 0  
fill ~107 ~8 ~56 ~108 ~8 ~56 glowstone 0  
fill ~107 ~8 ~57 ~108 ~8 ~57 glowstone 0  
fill ~106 ~9 ~56 ~109 ~9 ~56 glowstone 0  
fill ~106 ~9 ~57 ~109 ~9 ~57 glowstone 0  
fill ~107 ~9 ~55 ~108 ~9 ~55 glowstone 0  
fill ~107 ~9 ~58 ~108 ~9 ~58 glowstone 0  
fill ~106 ~10 ~56 ~109 ~10 ~56 glowstone 0  
fill ~106 ~10 ~57 ~109 ~10 ~57 glowstone 0  
fill ~107 ~10 ~55 ~108 ~10 ~55 glowstone 0  
fill ~107 ~10 ~58 ~108 ~10 ~58 glowstone 0  
fill ~107 ~11 ~56 ~108 ~11 ~56 glowstone 0  
fill ~107 ~11 ~57 ~108 ~11 ~57 glowstone 0  
fill ~25 ~12 ~68 ~27 ~12 ~68 cobblestone 0  
fill ~25 ~12 ~69 ~27 ~12 ~69 cobblestone 0  
fill ~25 ~12 ~70 ~27 ~12 ~70 cobblestone 0  
fill ~24 ~13 ~67 ~28 ~13 ~67 cobblestone 0  
fill ~24 ~13 ~68 ~28 ~13 ~68 cobblestone 0  
fill ~24 ~13 ~69 ~28 ~13 ~69 cobblestone 0  
fill ~24 ~13 ~70 ~28 ~13 ~70 cobblestone 0  
fill ~24 ~13 ~71 ~28 ~13 ~71 cobblestone 0  
fill ~69 ~13 ~67 ~72 ~13 ~67 redstone_ore 0  
fill ~69 ~13 ~68 ~72 ~13 ~68 redstone_ore 0  
fill ~69 ~13 ~69 ~72 ~13 ~69 redstone_ore 0  
fill ~69 ~13 ~70 ~72 ~13 ~70 redstone_ore 0  
fill ~15 ~14 ~98 ~16 ~14 ~98 glowstone 0  
fill ~15 ~14 ~99 ~16 ~14 ~99 glowstone 0  
fill ~23 ~14 ~68 ~29 ~14 ~68 cobblestone 0  
fill ~23 ~14 ~69 ~29 ~14 ~69 cobblestone 0  
fill ~23 ~14 ~70 ~29 ~14 ~70 cobblestone 0  
fill ~24 ~14 ~67 ~28 ~14 ~67 cobblestone 0  
fill ~24 ~14 ~71 ~28 ~14 ~71 cobblestone 0  
fill ~25 ~14 ~66 ~27 ~14 ~66 cobblestone 0  
fill ~25 ~14 ~72 ~27 ~14 ~72 cobblestone 0  
fill ~67 ~14 ~67 ~74 ~14 ~67 redstone_ore 0  
fill ~67 ~14 ~68 ~74 ~14 ~68 redstone_ore 0  
fill ~67 ~14 ~69 ~74 ~14 ~69 redstone_ore 0  
fill ~67 ~14 ~70 ~74 ~14 ~70 redstone_ore 0  
fill ~68 ~14 ~66 ~73 ~14 ~66 redstone_ore 0  
fill ~68 ~14 ~71 ~73 ~14 ~71 redstone_ore 0  
fill ~69 ~14 ~65 ~72 ~14 ~65 redstone_ore 0  
fill ~69 ~14 ~72 ~72 ~14 ~72 redstone_ore 0  
fill ~14 ~15 ~98 ~17 ~15 ~98 glowstone 0  
fill ~14 ~15 ~99 ~17 ~15 ~99 glowstone 0  
fill ~15 ~15 ~97 ~16 ~15 ~97 glowstone 0  
fill ~15 ~15 ~100 ~16 ~15 ~100 glowstone 0  
fill ~23 ~15 ~68 ~29 ~15 ~68 cobblestone 0  
fill ~23 ~15 ~69 ~29 ~15 ~69 cobblestone 0  
fill ~23 ~15 ~70 ~29 ~15 ~70 cobblestone 0  
fill ~24 ~15 ~67 ~28 ~15 ~67 cobblestone 0  
fill ~24 ~15 ~71 ~28 ~15 ~71 cobblestone 0  
fill ~25 ~15 ~66 ~27 ~15 ~66 cobblestone 0  
fill ~25 ~15 ~72 ~27 ~15 ~72 cobblestone 0  
fill ~52 ~15 ~74 ~57 ~15 ~74 lava 0  
fill ~52 ~15 ~75 ~57 ~15 ~75 lava 0  
fill ~52 ~15 ~76 ~57 ~15 ~76 lava 0  
fill ~52 ~15 ~77 ~57 ~15 ~77 lava 0  
fill ~53 ~15 ~73 ~56 ~15 ~73 lava 0  
fill ~53 ~15 ~78 ~56 ~15 ~78 lava 0  
fill ~66 ~15 ~67 ~75 ~15 ~67 redstone_ore 0  
fill ~66 ~15 ~68 ~75 ~15 ~68 redstone_ore 0  
fill ~66 ~15 ~69 ~75 ~15 ~69 redstone_ore 0  
fill ~66 ~15 ~70 ~75 ~15 ~70 redstone_ore 0  
fill ~67 ~15 ~66 ~74 ~15 ~66 redstone_ore 0  
fill ~67 ~15 ~71 ~74 ~15 ~71 redstone_ore 0  
fill ~68 ~15 ~65 ~73 ~15 ~65 redstone_ore 0  
fill ~68 ~15 ~72 ~73 ~15 ~72 redstone_ore 0  
fill ~69 ~15 ~64 ~72 ~15 ~64 redstone_ore 0  
fill ~69 ~15 ~73 ~72 ~15 ~73 redstone_ore 0  
fill ~11 ~16 ~43 ~12 ~16 ~43 glowstone 0  
fill ~11 ~16 ~44 ~12 ~16 ~44 glowstone 0  
fill ~14 ~16 ~98 ~17 ~16 ~98 glowstone 0  
fill ~14 ~16 ~99 ~17 ~16 ~99 glowstone 0  
fill ~15 ~16 ~97 ~16 ~16 ~97 glowstone 0  
fill ~15 ~16 ~100 ~16 ~16 ~100 glowstone 0  
fill ~23 ~16 ~68 ~29 ~16 ~68 cobblestone 0  
fill ~23 ~16 ~69 ~29 ~16 ~69 cobblestone 0  
fill ~23 ~16 ~70 ~29 ~16 ~70 cobblestone 0  
fill ~24 ~16 ~67 ~28 ~16 ~67 cobblestone 0  
fill ~24 ~16 ~71 ~28 ~16 ~71 cobblestone 0  
fill ~25 ~16 ~66 ~27 ~16 ~66 cobblestone 0  
fill ~25 ~16 ~72 ~27 ~16 ~72 cobblestone 0 
setblock ~30 ~16 ~68 torch 1  
fill ~36 ~16 ~37 ~40 ~16 ~37 wool 1  
fill ~36 ~16 ~38 ~40 ~16 ~38 wool 1  
fill ~36 ~16 ~39 ~40 ~16 ~39 wool 1  
fill ~37 ~16 ~36 ~39 ~16 ~36 wool 1  
fill ~37 ~16 ~40 ~39 ~16 ~40 wool 1  
fill ~50 ~16 ~73 ~59 ~16 ~73 lava 0  
fill ~50 ~16 ~74 ~59 ~16 ~74 lava 0  
fill ~50 ~16 ~75 ~59 ~16 ~75 lava 0  
fill ~50 ~16 ~76 ~59 ~16 ~76 lava 0  
fill ~50 ~16 ~77 ~59 ~16 ~77 lava 0  
fill ~50 ~16 ~78 ~59 ~16 ~78 lava 0  
fill ~51 ~16 ~72 ~58 ~16 ~72 lava 0  
fill ~51 ~16 ~79 ~58 ~16 ~79 lava 0  
fill ~52 ~16 ~71 ~57 ~16 ~71 lava 0  
fill ~52 ~16 ~80 ~57 ~16 ~80 lava 0  
fill ~66 ~16 ~66 ~75 ~16 ~66 redstone_ore 0  
fill ~66 ~16 ~67 ~75 ~16 ~67 redstone_ore 0  
fill ~66 ~16 ~68 ~75 ~16 ~68 redstone_ore 0  
fill ~66 ~16 ~69 ~75 ~16 ~69 redstone_ore 0  
fill ~66 ~16 ~70 ~75 ~16 ~70 redstone_ore 0  
fill ~66 ~16 ~71 ~75 ~16 ~71 redstone_ore 0  
fill ~67 ~16 ~65 ~74 ~16 ~65 redstone_ore 0  
fill ~67 ~16 ~72 ~74 ~16 ~72 redstone_ore 0  
fill ~68 ~16 ~64 ~73 ~16 ~64 redstone_ore 0  
fill ~68 ~16 ~73 ~73 ~16 ~73 redstone_ore 0  
fill ~10 ~17 ~43 ~13 ~17 ~43 glowstone 0  
fill ~10 ~17 ~44 ~13 ~17 ~44 glowstone 0  
fill ~11 ~17 ~42 ~12 ~17 ~42 glowstone 0  
fill ~11 ~17 ~45 ~12 ~17 ~45 glowstone 0  
fill ~12 ~17 ~60 ~15 ~17 ~60 glowstone 0  
fill ~12 ~17 ~61 ~15 ~17 ~61 glowstone 0  
fill ~13 ~17 ~59 ~14 ~17 ~59 glowstone 0  
fill ~13 ~17 ~62 ~14 ~17 ~62 glowstone 0  
fill ~15 ~17 ~22 ~16 ~17 ~22 clay 0  
fill ~15 ~17 ~23 ~16 ~17 ~23 clay 0  
fill ~15 ~17 ~98 ~16 ~17 ~98 glowstone 0  
fill ~15 ~17 ~99 ~16 ~17 ~99 glowstone 0  
fill ~24 ~17 ~67 ~28 ~17 ~67 cobblestone 0  
fill ~24 ~17 ~68 ~28 ~17 ~68 cobblestone 0  
fill ~24 ~17 ~69 ~28 ~17 ~69 cobblestone 0  
fill ~24 ~17 ~70 ~28 ~17 ~70 cobblestone 0  
fill ~24 ~17 ~71 ~28 ~17 ~71 cobblestone 0  
fill ~34 ~17 ~11 ~39 ~17 ~11 wool 4  
fill ~34 ~17 ~12 ~39 ~17 ~12 wool 4  
fill ~34 ~17 ~36 ~42 ~17 ~36 wool 1  
fill ~34 ~17 ~37 ~42 ~17 ~37 wool 1  
fill ~34 ~17 ~38 ~42 ~17 ~38 wool 1  
fill ~34 ~17 ~39 ~42 ~17 ~39 wool 1  
fill ~34 ~17 ~40 ~42 ~17 ~40 wool 1  
fill ~35 ~17 ~10 ~38 ~17 ~10 wool 4  
fill ~35 ~17 ~13 ~38 ~17 ~13 wool 4  
fill ~35 ~17 ~35 ~41 ~17 ~35 wool 1  
fill ~35 ~17 ~41 ~41 ~17 ~41 wool 1  
fill ~36 ~17 ~9 ~37 ~17 ~9 wool 4  
fill ~36 ~17 ~14 ~37 ~17 ~14 wool 4  
fill ~36 ~17 ~34 ~40 ~17 ~34 wool 1  
fill ~36 ~17 ~42 ~40 ~17 ~42 wool 1  
fill ~48 ~17 ~75 ~61 ~17 ~75 lava 0  
fill ~48 ~17 ~76 ~61 ~17 ~76 lava 0  
fill ~49 ~17 ~72 ~60 ~17 ~72 lava 0  
fill ~49 ~17 ~73 ~60 ~17 ~73 lava 0  
fill ~49 ~17 ~74 ~60 ~17 ~74 lava 0  
fill ~49 ~17 ~77 ~60 ~17 ~77 lava 0  
fill ~49 ~17 ~78 ~60 ~17 ~78 lava 0  
fill ~49 ~17 ~79 ~60 ~17 ~79 lava 0  
fill ~50 ~17 ~71 ~59 ~17 ~71 lava 0  
fill ~50 ~17 ~80 ~59 ~17 ~80 lava 0  
fill ~51 ~17 ~70 ~58 ~17 ~70 lava 0  
fill ~51 ~17 ~81 ~58 ~17 ~81 lava 0  
fill ~54 ~17 ~69 ~55 ~17 ~69 lava 0  
fill ~54 ~17 ~82 ~55 ~17 ~82 lava 0  
fill ~65 ~17 ~67 ~76 ~17 ~67 redstone_ore 0  
fill ~65 ~17 ~68 ~76 ~17 ~68 redstone_ore 0  
fill ~65 ~17 ~69 ~76 ~17 ~69 redstone_ore 0  
fill ~65 ~17 ~70 ~76 ~17 ~70 redstone_ore 0  
fill ~66 ~17 ~65 ~75 ~17 ~65 redstone_ore 0  
fill ~66 ~17 ~66 ~75 ~17 ~66 redstone_ore 0  
fill ~66 ~17 ~71 ~75 ~17 ~71 redstone_ore 0  
fill ~66 ~17 ~72 ~75 ~17 ~72 redstone_ore 0  
fill ~67 ~17 ~64 ~74 ~17 ~64 redstone_ore 0  
fill ~67 ~17 ~73 ~74 ~17 ~73 redstone_ore 0  
fill ~69 ~17 ~63 ~72 ~17 ~63 redstone_ore 0  
fill ~69 ~17 ~74 ~72 ~17 ~74 redstone_ore 0  
fill ~86 ~17 ~49 ~91 ~17 ~49 snow 0  
fill ~86 ~17 ~50 ~91 ~17 ~50 snow 0  
fill ~87 ~17 ~48 ~90 ~17 ~48 snow 0  
fill ~87 ~17 ~51 ~90 ~17 ~51 snow 0  
fill ~88 ~17 ~47 ~89 ~17 ~47 snow 0  
fill ~88 ~17 ~52 ~89 ~17 ~52 snow 0  
fill ~6 ~18 ~38 ~8 ~18 ~38 wool 1  
fill ~6 ~18 ~39 ~8 ~18 ~39 wool 1  
fill ~6 ~18 ~40 ~8 ~18 ~40 wool 1  
fill ~10 ~18 ~43 ~13 ~18 ~43 glowstone 0  
fill ~10 ~18 ~44 ~13 ~18 ~44 glowstone 0  
fill ~11 ~18 ~42 ~12 ~18 ~42 glowstone 0  
fill ~11 ~18 ~45 ~12 ~18 ~45 glowstone 0  
fill ~11 ~18 ~60 ~16 ~18 ~60 glowstone 0  
fill ~11 ~18 ~61 ~16 ~18 ~61 glowstone 0  
fill ~12 ~18 ~59 ~15 ~18 ~59 glowstone 0  
fill ~12 ~18 ~62 ~15 ~18 ~62 glowstone 0  
fill ~13 ~18 ~58 ~14 ~18 ~58 glowstone 0  
fill ~13 ~18 ~63 ~14 ~18 ~63 glowstone 0  
fill ~14 ~18 ~22 ~17 ~18 ~22 clay 0  
fill ~14 ~18 ~23 ~17 ~18 ~23 clay 0  
fill ~15 ~18 ~21 ~16 ~18 ~21 clay 0  
fill ~15 ~18 ~24 ~16 ~18 ~24 clay 0  
fill ~25 ~18 ~68 ~27 ~18 ~68 cobblestone 0  
fill ~25 ~18 ~69 ~27 ~18 ~69 cobblestone 0  
fill ~25 ~18 ~70 ~27 ~18 ~70 cobblestone 0 
setblock ~28 ~18 ~69 torch 5  
fill ~33 ~18 ~9 ~40 ~18 ~9 wool 4  
fill ~33 ~18 ~10 ~40 ~18 ~10 wool 4  
fill ~33 ~18 ~11 ~40 ~18 ~11 wool 4  
fill ~33 ~18 ~12 ~40 ~18 ~12 wool 4  
fill ~33 ~18 ~13 ~40 ~18 ~13 wool 4  
fill ~33 ~18 ~14 ~40 ~18 ~14 wool 4  
fill ~33 ~18 ~36 ~43 ~18 ~36 wool 1  
fill ~33 ~18 ~37 ~43 ~18 ~37 wool 1  
fill ~33 ~18 ~38 ~43 ~18 ~38 wool 1  
fill ~33 ~18 ~39 ~43 ~18 ~39 wool 1  
fill ~33 ~18 ~40 ~43 ~18 ~40 wool 1  
fill ~34 ~18 ~8 ~39 ~18 ~8 wool 4  
fill ~34 ~18 ~15 ~39 ~18 ~15 wool 4  
fill ~34 ~18 ~35 ~42 ~18 ~35 wool 1  
fill ~34 ~18 ~41 ~42 ~18 ~41 wool 1  
fill ~35 ~18 ~34 ~41 ~18 ~34 wool 1  
fill ~35 ~18 ~42 ~41 ~18 ~42 wool 1  
fill ~36 ~18 ~33 ~40 ~18 ~33 wool 1  
fill ~36 ~18 ~43 ~40 ~18 ~43 wool 1  
fill ~47 ~18 ~75 ~62 ~18 ~75 lava 0  
fill ~47 ~18 ~76 ~62 ~18 ~76 lava 0  
fill ~48 ~18 ~72 ~61 ~18 ~72 lava 0  
fill ~48 ~18 ~73 ~61 ~18 ~73 lava 0  
fill ~48 ~18 ~74 ~61 ~18 ~74 lava 0  
fill ~48 ~18 ~77 ~61 ~18 ~77 lava 0  
fill ~48 ~18 ~78 ~61 ~18 ~78 lava 0  
fill ~48 ~18 ~79 ~61 ~18 ~79 lava 0  
fill ~49 ~18 ~71 ~60 ~18 ~71 lava 0  
fill ~49 ~18 ~80 ~60 ~18 ~80 lava 0  
fill ~50 ~18 ~70 ~59 ~18 ~70 lava 0  
fill ~50 ~18 ~81 ~59 ~18 ~81 lava 0  
fill ~51 ~18 ~69 ~58 ~18 ~69 lava 0  
fill ~51 ~18 ~82 ~58 ~18 ~82 lava 0  
fill ~54 ~18 ~68 ~55 ~18 ~68 lava 0  
fill ~54 ~18 ~83 ~55 ~18 ~83 lava 0  
fill ~61 ~18 ~56 ~64 ~18 ~56 stone 0  
fill ~61 ~18 ~57 ~64 ~18 ~57 stone 0  
fill ~61 ~18 ~58 ~64 ~18 ~58 stone 0  
fill ~61 ~18 ~59 ~64 ~18 ~59 stone 0  
fill ~65 ~18 ~67 ~76 ~18 ~67 redstone_ore 0  
fill ~65 ~18 ~68 ~76 ~18 ~68 redstone_ore 0  
fill ~65 ~18 ~69 ~76 ~18 ~69 redstone_ore 0  
fill ~65 ~18 ~70 ~76 ~18 ~70 redstone_ore 0  
fill ~66 ~18 ~65 ~75 ~18 ~65 redstone_ore 0  
fill ~66 ~18 ~66 ~75 ~18 ~66 redstone_ore 0  
fill ~66 ~18 ~71 ~75 ~18 ~71 redstone_ore 0  
fill ~66 ~18 ~72 ~75 ~18 ~72 redstone_ore 0  
fill ~67 ~18 ~64 ~74 ~18 ~64 redstone_ore 0  
fill ~67 ~18 ~73 ~74 ~18 ~73 redstone_ore 0  
fill ~69 ~18 ~63 ~72 ~18 ~63 redstone_ore 0  
fill ~69 ~18 ~74 ~72 ~18 ~74 redstone_ore 0  
fill ~85 ~18 ~47 ~92 ~18 ~47 lapis_block 0  
fill ~85 ~18 ~48 ~92 ~18 ~48 lapis_block 0  
fill ~85 ~18 ~49 ~92 ~18 ~49 lapis_block 0  
fill ~85 ~18 ~50 ~92 ~18 ~50 lapis_block 0  
fill ~85 ~18 ~51 ~92 ~18 ~51 lapis_block 0  
fill ~85 ~18 ~52 ~92 ~18 ~52 lapis_block 0  
fill ~86 ~18 ~46 ~91 ~18 ~46 lapis_block 0  
fill ~86 ~18 ~53 ~91 ~18 ~53 lapis_block 0  
fill ~90 ~18 ~83 ~93 ~18 ~83 netherrack 0  
fill ~90 ~18 ~84 ~93 ~18 ~84 netherrack 0  
fill ~90 ~18 ~85 ~93 ~18 ~85 netherrack 0  
fill ~90 ~18 ~86 ~93 ~18 ~86 netherrack 0  
fill ~5 ~19 ~38 ~9 ~19 ~38 wool 1  
fill ~5 ~19 ~39 ~9 ~19 ~39 wool 1  
fill ~5 ~19 ~40 ~9 ~19 ~40 wool 1  
fill ~6 ~19 ~37 ~8 ~19 ~37 wool 1  
fill ~6 ~19 ~41 ~8 ~19 ~41 wool 1  
fill ~11 ~19 ~43 ~12 ~19 ~43 glowstone 0  
fill ~11 ~19 ~44 ~12 ~19 ~44 glowstone 0  
fill ~11 ~19 ~59 ~16 ~19 ~59 glowstone 0  
fill ~11 ~19 ~60 ~16 ~19 ~60 glowstone 0  
fill ~11 ~19 ~61 ~16 ~19 ~61 glowstone 0  
fill ~11 ~19 ~62 ~16 ~19 ~62 glowstone 0  
fill ~12 ~19 ~58 ~15 ~19 ~58 glowstone 0  
fill ~12 ~19 ~63 ~15 ~19 ~63 glowstone 0  
fill ~14 ~19 ~22 ~17 ~19 ~22 clay 0  
fill ~14 ~19 ~23 ~17 ~19 ~23 clay 0  
fill ~15 ~19 ~21 ~16 ~19 ~21 clay 0  
fill ~15 ~19 ~24 ~16 ~19 ~24 clay 0 
setblock ~15 ~19 ~25 torch 3  
fill ~32 ~19 ~9 ~41 ~19 ~9 wool 4  
fill ~32 ~19 ~10 ~41 ~19 ~10 wool 4  
fill ~32 ~19 ~11 ~41 ~19 ~11 wool 4  
fill ~32 ~19 ~12 ~41 ~19 ~12 wool 4  
fill ~32 ~19 ~13 ~41 ~19 ~13 wool 4  
fill ~32 ~19 ~14 ~41 ~19 ~14 wool 4  
fill ~32 ~19 ~36 ~44 ~19 ~36 wool 1  
fill ~32 ~19 ~37 ~44 ~19 ~37 wool 1  
fill ~32 ~19 ~38 ~44 ~19 ~38 wool 1  
fill ~32 ~19 ~39 ~44 ~19 ~39 wool 1  
fill ~32 ~19 ~40 ~44 ~19 ~40 wool 1  
fill ~33 ~19 ~8 ~40 ~19 ~8 wool 4  
fill ~33 ~19 ~15 ~40 ~19 ~15 wool 4  
fill ~33 ~19 ~35 ~43 ~19 ~35 wool 1  
fill ~33 ~19 ~41 ~43 ~19 ~41 wool 1  
fill ~34 ~19 ~7 ~39 ~19 ~7 wool 4  
fill ~34 ~19 ~16 ~39 ~19 ~16 wool 4  
fill ~34 ~19 ~34 ~42 ~19 ~34 wool 1  
fill ~34 ~19 ~42 ~42 ~19 ~42 wool 1  
fill ~35 ~19 ~33 ~41 ~19 ~33 wool 1  
fill ~35 ~19 ~43 ~41 ~19 ~43 wool 1  
fill ~36 ~19 ~32 ~40 ~19 ~32 wool 1  
fill ~36 ~19 ~44 ~40 ~19 ~44 wool 1  
fill ~47 ~19 ~72 ~62 ~19 ~72 lava 0  
fill ~47 ~19 ~73 ~62 ~19 ~73 lava 0  
fill ~47 ~19 ~74 ~62 ~19 ~74 lava 0  
fill ~47 ~19 ~75 ~62 ~19 ~75 lava 0  
fill ~47 ~19 ~76 ~62 ~19 ~76 lava 0  
fill ~47 ~19 ~77 ~62 ~19 ~77 lava 0  
fill ~47 ~19 ~78 ~62 ~19 ~78 lava 0  
fill ~47 ~19 ~79 ~62 ~19 ~79 lava 0  
fill ~48 ~19 ~71 ~61 ~19 ~71 lava 0  
fill ~48 ~19 ~80 ~61 ~19 ~80 lava 0  
fill ~49 ~19 ~70 ~60 ~19 ~70 lava 0  
fill ~49 ~19 ~81 ~60 ~19 ~81 lava 0  
fill ~50 ~19 ~69 ~59 ~19 ~69 lava 0  
fill ~50 ~19 ~82 ~59 ~19 ~82 lava 0  
fill ~51 ~19 ~68 ~58 ~19 ~68 lava 0  
fill ~51 ~19 ~83 ~58 ~19 ~83 lava 0  
fill ~59 ~19 ~57 ~66 ~19 ~57 stone 0  
fill ~59 ~19 ~58 ~66 ~19 ~58 stone 0  
fill ~60 ~19 ~55 ~65 ~19 ~55 stone 0  
fill ~60 ~19 ~56 ~65 ~19 ~56 stone 0  
fill ~60 ~19 ~59 ~65 ~19 ~59 stone 0  
fill ~60 ~19 ~60 ~65 ~19 ~60 stone 0  
fill ~62 ~19 ~54 ~63 ~19 ~54 stone 0  
fill ~62 ~19 ~61 ~63 ~19 ~61 stone 0  
fill ~65 ~19 ~67 ~76 ~19 ~67 redstone_ore 0  
fill ~65 ~19 ~68 ~76 ~19 ~68 redstone_ore 0  
fill ~65 ~19 ~69 ~76 ~19 ~69 redstone_ore 0  
fill ~65 ~19 ~70 ~76 ~19 ~70 redstone_ore 0  
fill ~66 ~19 ~65 ~75 ~19 ~65 redstone_ore 0  
fill ~66 ~19 ~66 ~75 ~19 ~66 redstone_ore 0  
fill ~66 ~19 ~71 ~75 ~19 ~71 redstone_ore 0  
fill ~66 ~19 ~72 ~75 ~19 ~72 redstone_ore 0  
fill ~67 ~19 ~64 ~74 ~19 ~64 redstone_ore 0  
fill ~67 ~19 ~73 ~74 ~19 ~73 redstone_ore 0  
fill ~69 ~19 ~63 ~72 ~19 ~63 redstone_ore 0  
fill ~69 ~19 ~74 ~72 ~19 ~74 redstone_ore 0  
fill ~84 ~19 ~47 ~93 ~19 ~47 lapis_block 0  
fill ~84 ~19 ~48 ~93 ~19 ~48 lapis_block 0  
fill ~84 ~19 ~49 ~93 ~19 ~49 lapis_block 0  
fill ~84 ~19 ~50 ~93 ~19 ~50 lapis_block 0  
fill ~84 ~19 ~51 ~93 ~19 ~51 lapis_block 0  
fill ~84 ~19 ~52 ~93 ~19 ~52 lapis_block 0  
fill ~85 ~19 ~46 ~92 ~19 ~46 lapis_block 0  
fill ~85 ~19 ~53 ~92 ~19 ~53 lapis_block 0  
fill ~86 ~19 ~45 ~91 ~19 ~45 lapis_block 0  
fill ~86 ~19 ~54 ~91 ~19 ~54 lapis_block 0  
fill ~88 ~19 ~84 ~95 ~19 ~84 netherrack 0  
fill ~88 ~19 ~85 ~95 ~19 ~85 netherrack 0  
fill ~89 ~19 ~82 ~94 ~19 ~82 netherrack 0  
fill ~89 ~19 ~83 ~94 ~19 ~83 netherrack 0  
fill ~89 ~19 ~86 ~94 ~19 ~86 netherrack 0  
fill ~89 ~19 ~87 ~94 ~19 ~87 netherrack 0  
fill ~91 ~19 ~81 ~92 ~19 ~81 netherrack 0  
fill ~91 ~19 ~88 ~92 ~19 ~88 netherrack 0  
fill ~5 ~20 ~38 ~9 ~20 ~38 wool 1  
fill ~5 ~20 ~39 ~9 ~20 ~39 wool 1  
fill ~5 ~20 ~40 ~9 ~20 ~40 wool 1  
fill ~6 ~20 ~37 ~8 ~20 ~37 wool 1  
fill ~6 ~20 ~41 ~8 ~20 ~41 wool 1  
fill ~11 ~20 ~59 ~16 ~20 ~59 glowstone 0  
fill ~11 ~20 ~60 ~16 ~20 ~60 glowstone 0  
fill ~11 ~20 ~61 ~16 ~20 ~61 glowstone 0  
fill ~11 ~20 ~62 ~16 ~20 ~62 glowstone 0  
fill ~12 ~20 ~58 ~15 ~20 ~58 glowstone 0  
fill ~12 ~20 ~63 ~15 ~20 ~63 glowstone 0  
fill ~15 ~20 ~22 ~16 ~20 ~22 clay 0  
fill ~15 ~20 ~23 ~16 ~20 ~23 clay 0  
fill ~25 ~20 ~95 ~29 ~20 ~95 clay 0  
fill ~25 ~20 ~96 ~29 ~20 ~96 clay 0  
fill ~25 ~20 ~97 ~29 ~20 ~97 clay 0  
fill ~26 ~20 ~94 ~28 ~20 ~94 clay 0  
fill ~26 ~20 ~98 ~28 ~20 ~98 clay 0  
fill ~31 ~20 ~9 ~42 ~20 ~9 wool 4  
fill ~31 ~20 ~10 ~42 ~20 ~10 wool 4  
fill ~31 ~20 ~11 ~42 ~20 ~11 wool 4  
fill ~31 ~20 ~12 ~42 ~20 ~12 wool 4  
fill ~31 ~20 ~13 ~42 ~20 ~13 wool 4  
fill ~31 ~20 ~14 ~42 ~20 ~14 wool 4  
fill ~32 ~20 ~8 ~41 ~20 ~8 wool 4  
fill ~32 ~20 ~15 ~41 ~20 ~15 wool 4  
fill ~32 ~20 ~35 ~44 ~20 ~35 wool 1  
fill ~32 ~20 ~36 ~44 ~20 ~36 wool 1  
fill ~32 ~20 ~37 ~44 ~20 ~37 wool 1  
fill ~32 ~20 ~38 ~44 ~20 ~38 wool 1  
fill ~32 ~20 ~39 ~44 ~20 ~39 wool 1  
fill ~32 ~20 ~40 ~44 ~20 ~40 wool 1  
fill ~32 ~20 ~41 ~44 ~20 ~41 wool 1  
fill ~33 ~20 ~7 ~40 ~20 ~7 wool 4  
fill ~33 ~20 ~16 ~40 ~20 ~16 wool 4  
fill ~33 ~20 ~34 ~43 ~20 ~34 wool 1  
fill ~33 ~20 ~42 ~43 ~20 ~42 wool 1  
fill ~34 ~20 ~6 ~39 ~20 ~6 wool 4  
fill ~34 ~20 ~17 ~39 ~20 ~17 wool 4  
fill ~34 ~20 ~33 ~42 ~20 ~33 wool 1  
fill ~34 ~20 ~43 ~42 ~20 ~43 wool 1  
fill ~35 ~20 ~32 ~41 ~20 ~32 wool 1  
fill ~35 ~20 ~44 ~41 ~20 ~44 wool 1  
fill ~46 ~20 ~73 ~63 ~20 ~73 lava 0  
fill ~46 ~20 ~74 ~63 ~20 ~74 lava 0  
fill ~46 ~20 ~75 ~63 ~20 ~75 lava 0  
fill ~46 ~20 ~76 ~63 ~20 ~76 lava 0  
fill ~46 ~20 ~77 ~63 ~20 ~77 lava 0  
fill ~46 ~20 ~78 ~63 ~20 ~78 lava 0  
fill ~47 ~20 ~71 ~62 ~20 ~71 lava 0  
fill ~47 ~20 ~72 ~62 ~20 ~72 lava 0  
fill ~47 ~20 ~79 ~62 ~20 ~79 lava 0  
fill ~47 ~20 ~80 ~62 ~20 ~80 lava 0  
fill ~48 ~20 ~70 ~61 ~20 ~70 lava 0  
fill ~48 ~20 ~81 ~61 ~20 ~81 lava 0  
fill ~49 ~20 ~69 ~60 ~20 ~69 lava 0  
fill ~49 ~20 ~82 ~60 ~20 ~82 lava 0  
fill ~50 ~20 ~68 ~59 ~20 ~68 lava 0  
fill ~50 ~20 ~83 ~59 ~20 ~83 lava 0  
fill ~52 ~20 ~67 ~57 ~20 ~67 lava 0  
fill ~52 ~20 ~84 ~57 ~20 ~84 lava 0  
fill ~59 ~20 ~55 ~66 ~20 ~55 stone 0  
fill ~59 ~20 ~56 ~66 ~20 ~56 stone 0  
fill ~59 ~20 ~57 ~66 ~20 ~57 stone 0  
fill ~59 ~20 ~58 ~66 ~20 ~58 stone 0  
fill ~59 ~20 ~59 ~66 ~20 ~59 stone 0  
fill ~59 ~20 ~60 ~66 ~20 ~60 stone 0  
fill ~60 ~20 ~54 ~65 ~20 ~54 stone 0  
fill ~60 ~20 ~61 ~65 ~20 ~61 stone 0  
fill ~65 ~20 ~67 ~76 ~20 ~67 redstone_ore 0  
fill ~65 ~20 ~68 ~76 ~20 ~68 redstone_ore 0  
fill ~65 ~20 ~69 ~76 ~20 ~69 redstone_ore 0  
fill ~65 ~20 ~70 ~76 ~20 ~70 redstone_ore 0  
fill ~66 ~20 ~65 ~75 ~20 ~65 redstone_ore 0  
fill ~66 ~20 ~66 ~75 ~20 ~66 redstone_ore 0  
fill ~66 ~20 ~71 ~75 ~20 ~71 redstone_ore 0  
fill ~66 ~20 ~72 ~75 ~20 ~72 redstone_ore 0  
fill ~67 ~20 ~64 ~74 ~20 ~64 redstone_ore 0  
fill ~67 ~20 ~73 ~74 ~20 ~73 redstone_ore 0  
fill ~69 ~20 ~63 ~72 ~20 ~63 redstone_ore 0  
fill ~69 ~20 ~74 ~72 ~20 ~74 redstone_ore 0  
fill ~83 ~20 ~47 ~94 ~20 ~47 lapis_block 0  
fill ~83 ~20 ~48 ~94 ~20 ~48 lapis_block 0  
fill ~83 ~20 ~49 ~94 ~20 ~49 lapis_block 0  
fill ~83 ~20 ~50 ~94 ~20 ~50 lapis_block 0  
fill ~83 ~20 ~51 ~94 ~20 ~51 lapis_block 0  
fill ~83 ~20 ~52 ~94 ~20 ~52 lapis_block 0  
fill ~84 ~20 ~46 ~93 ~20 ~46 lapis_block 0  
fill ~84 ~20 ~53 ~93 ~20 ~53 lapis_block 0  
fill ~85 ~20 ~45 ~92 ~20 ~45 lapis_block 0  
fill ~85 ~20 ~54 ~92 ~20 ~54 lapis_block 0  
fill ~86 ~20 ~44 ~91 ~20 ~44 lapis_block 0  
fill ~86 ~20 ~55 ~91 ~20 ~55 lapis_block 0  
fill ~88 ~20 ~82 ~95 ~20 ~82 netherrack 0  
fill ~88 ~20 ~83 ~95 ~20 ~83 netherrack 0  
fill ~88 ~20 ~84 ~95 ~20 ~84 netherrack 0  
fill ~88 ~20 ~85 ~95 ~20 ~85 netherrack 0  
fill ~88 ~20 ~86 ~95 ~20 ~86 netherrack 0  
fill ~88 ~20 ~87 ~95 ~20 ~87 netherrack 0  
fill ~89 ~20 ~81 ~94 ~20 ~81 netherrack 0  
fill ~89 ~20 ~88 ~94 ~20 ~88 netherrack 0  
fill ~5 ~21 ~38 ~9 ~21 ~38 wool 1  
fill ~5 ~21 ~39 ~9 ~21 ~39 wool 1  
fill ~5 ~21 ~40 ~9 ~21 ~40 wool 1  
fill ~6 ~21 ~37 ~8 ~21 ~37 wool 1  
fill ~6 ~21 ~41 ~8 ~21 ~41 wool 1  
fill ~11 ~21 ~60 ~16 ~21 ~60 glowstone 0  
fill ~11 ~21 ~61 ~16 ~21 ~61 glowstone 0  
fill ~12 ~21 ~59 ~15 ~21 ~59 glowstone 0  
fill ~12 ~21 ~62 ~15 ~21 ~62 glowstone 0  
fill ~13 ~21 ~58 ~14 ~21 ~58 glowstone 0  
fill ~13 ~21 ~63 ~14 ~21 ~63 glowstone 0  
fill ~23 ~21 ~95 ~31 ~21 ~95 clay 0  
fill ~23 ~21 ~96 ~31 ~21 ~96 clay 0  
fill ~23 ~21 ~97 ~31 ~21 ~97 clay 0  
fill ~24 ~21 ~93 ~30 ~21 ~93 clay 0  
fill ~24 ~21 ~94 ~30 ~21 ~94 clay 0  
fill ~24 ~21 ~98 ~30 ~21 ~98 clay 0  
fill ~24 ~21 ~99 ~30 ~21 ~99 clay 0  
fill ~26 ~21 ~92 ~28 ~21 ~92 clay 0  
fill ~26 ~21 ~100 ~28 ~21 ~100 clay 0  
fill ~30 ~21 ~11 ~43 ~21 ~11 wool 4  
fill ~30 ~21 ~12 ~43 ~21 ~12 wool 4  
fill ~31 ~21 ~8 ~42 ~21 ~8 wool 4  
fill ~31 ~21 ~9 ~42 ~21 ~9 wool 4  
fill ~31 ~21 ~10 ~42 ~21 ~10 wool 4  
fill ~31 ~21 ~13 ~42 ~21 ~13 wool 4  
fill ~31 ~21 ~14 ~42 ~21 ~14 wool 4  
fill ~31 ~21 ~15 ~42 ~21 ~15 wool 4  
fill ~31 ~21 ~37 ~45 ~21 ~37 wool 1  
fill ~31 ~21 ~38 ~45 ~21 ~38 wool 1  
fill ~31 ~21 ~39 ~45 ~21 ~39 wool 1  
fill ~32 ~21 ~7 ~41 ~21 ~7 wool 4  
fill ~32 ~21 ~16 ~41 ~21 ~16 wool 4  
fill ~32 ~21 ~34 ~44 ~21 ~34 wool 1  
fill ~32 ~21 ~35 ~44 ~21 ~35 wool 1  
fill ~32 ~21 ~36 ~44 ~21 ~36 wool 1  
fill ~32 ~21 ~40 ~44 ~21 ~40 wool 1  
fill ~32 ~21 ~41 ~44 ~21 ~41 wool 1  
fill ~32 ~21 ~42 ~44 ~21 ~42 wool 1  
fill ~33 ~21 ~6 ~40 ~21 ~6 wool 4  
fill ~33 ~21 ~17 ~40 ~21 ~17 wool 4  
fill ~33 ~21 ~33 ~43 ~21 ~33 wool 1  
fill ~33 ~21 ~43 ~43 ~21 ~43 wool 1  
fill ~34 ~21 ~32 ~42 ~21 ~32 wool 1  
fill ~34 ~21 ~44 ~42 ~21 ~44 wool 1  
fill ~36 ~21 ~5 ~37 ~21 ~5 wool 4  
fill ~36 ~21 ~18 ~37 ~21 ~18 wool 4  
fill ~37 ~21 ~31 ~39 ~21 ~31 wool 1  
fill ~37 ~21 ~45 ~39 ~21 ~45 wool 1  
fill ~46 ~21 ~72 ~63 ~21 ~72 lava 0  
fill ~46 ~21 ~73 ~63 ~21 ~73 lava 0  
fill ~46 ~21 ~74 ~63 ~21 ~74 lava 0  
fill ~46 ~21 ~75 ~63 ~21 ~75 lava 0  
fill ~46 ~21 ~76 ~63 ~21 ~76 lava 0  
fill ~46 ~21 ~77 ~63 ~21 ~77 lava 0  
fill ~46 ~21 ~78 ~63 ~21 ~78 lava 0  
fill ~46 ~21 ~79 ~63 ~21 ~79 lava 0  
fill ~47 ~21 ~70 ~62 ~21 ~70 lava 0  
fill ~47 ~21 ~71 ~62 ~21 ~71 lava 0  
fill ~47 ~21 ~80 ~62 ~21 ~80 lava 0  
fill ~47 ~21 ~81 ~62 ~21 ~81 lava 0  
fill ~48 ~21 ~69 ~61 ~21 ~69 lava 0  
fill ~48 ~21 ~82 ~61 ~21 ~82 lava 0  
fill ~49 ~21 ~68 ~60 ~21 ~68 lava 0  
fill ~49 ~21 ~83 ~60 ~21 ~83 lava 0  
fill ~51 ~21 ~67 ~58 ~21 ~67 lava 0  
fill ~51 ~21 ~84 ~58 ~21 ~84 lava 0  
fill ~58 ~21 ~56 ~67 ~21 ~56 stone 0  
fill ~58 ~21 ~57 ~67 ~21 ~57 stone 0  
fill ~58 ~21 ~58 ~67 ~21 ~58 stone 0  
fill ~58 ~21 ~59 ~67 ~21 ~59 stone 0  
fill ~59 ~21 ~55 ~66 ~21 ~55 stone 0  
fill ~59 ~21 ~60 ~66 ~21 ~60 stone 0  
fill ~60 ~21 ~54 ~65 ~21 ~54 stone 0  
fill ~60 ~21 ~61 ~65 ~21 ~61 stone 0  
fill ~61 ~21 ~53 ~64 ~21 ~53 stone 0  
fill ~61 ~21 ~62 ~64 ~21 ~62 stone 0  
fill ~66 ~21 ~66 ~75 ~21 ~66 redstone_ore 0  
fill ~66 ~21 ~67 ~75 ~21 ~67 redstone_ore 0  
fill ~66 ~21 ~68 ~75 ~21 ~68 redstone_ore 0  
fill ~66 ~21 ~69 ~75 ~21 ~69 redstone_ore 0  
fill ~66 ~21 ~70 ~75 ~21 ~70 redstone_ore 0  
fill ~66 ~21 ~71 ~75 ~21 ~71 redstone_ore 0  
fill ~67 ~21 ~65 ~74 ~21 ~65 redstone_ore 0  
fill ~67 ~21 ~72 ~74 ~21 ~72 redstone_ore 0  
fill ~68 ~21 ~64 ~73 ~21 ~64 redstone_ore 0  
fill ~68 ~21 ~73 ~73 ~21 ~73 redstone_ore 0  
fill ~82 ~21 ~49 ~95 ~21 ~49 lapis_block 0  
fill ~82 ~21 ~50 ~95 ~21 ~50 lapis_block 0  
fill ~83 ~21 ~46 ~94 ~21 ~46 lapis_block 0  
fill ~83 ~21 ~47 ~94 ~21 ~47 lapis_block 0  
fill ~83 ~21 ~48 ~94 ~21 ~48 lapis_block 0  
fill ~83 ~21 ~51 ~94 ~21 ~51 lapis_block 0  
fill ~83 ~21 ~52 ~93 ~21 ~52 lapis_block 0  
fill ~83 ~21 ~53 ~93 ~21 ~53 lapis_block 0  
fill ~84 ~21 ~45 ~93 ~21 ~45 lapis_block 0  
fill ~84 ~21 ~54 ~93 ~21 ~54 lapis_block 0  
fill ~85 ~21 ~44 ~92 ~21 ~44 lapis_block 0  
fill ~85 ~21 ~55 ~90 ~21 ~55 lapis_block 0  
fill ~87 ~21 ~83 ~96 ~21 ~83 netherrack 0  
fill ~87 ~21 ~84 ~96 ~21 ~84 netherrack 0  
fill ~87 ~21 ~85 ~96 ~21 ~85 netherrack 0  
fill ~87 ~21 ~86 ~96 ~21 ~86 netherrack 0  
fill ~88 ~21 ~43 ~89 ~21 ~43 lapis_block 0  
fill ~88 ~21 ~56 ~88 ~27 ~56 wool 13  
fill ~88 ~21 ~82 ~95 ~21 ~82 netherrack 0  
fill ~88 ~21 ~87 ~95 ~21 ~87 netherrack 0  
fill ~89 ~21 ~56 ~89 ~24 ~56 lapis_block 0  
fill ~89 ~21 ~81 ~94 ~21 ~81 netherrack 0  
fill ~89 ~21 ~88 ~94 ~21 ~88 netherrack 0  
fill ~90 ~21 ~80 ~93 ~21 ~80 netherrack 0  
fill ~90 ~21 ~89 ~93 ~21 ~89 netherrack 0  
fill ~91 ~21 ~55 ~92 ~21 ~55 wool 13  
fill ~94 ~21 ~52 ~94 ~22 ~52 wool 13  
fill ~94 ~21 ~53 ~94 ~22 ~53 wool 13  
fill ~6 ~22 ~38 ~8 ~22 ~38 wool 1  
fill ~6 ~22 ~39 ~8 ~22 ~39 wool 1  
fill ~6 ~22 ~40 ~8 ~22 ~40 wool 1  
fill ~12 ~22 ~60 ~15 ~22 ~60 glowstone 0  
fill ~12 ~22 ~61 ~15 ~22 ~61 glowstone 0  
fill ~13 ~22 ~59 ~14 ~22 ~59 glowstone 0  
fill ~13 ~22 ~62 ~14 ~22 ~62 glowstone 0  
fill ~22 ~22 ~95 ~32 ~22 ~95 clay 0  
fill ~22 ~22 ~96 ~32 ~22 ~96 clay 0  
fill ~22 ~22 ~97 ~32 ~22 ~97 clay 0  
fill ~23 ~22 ~93 ~31 ~22 ~93 clay 0  
fill ~23 ~22 ~94 ~31 ~22 ~94 clay 0  
fill ~23 ~22 ~98 ~31 ~22 ~98 clay 0  
fill ~23 ~22 ~99 ~31 ~22 ~99 clay 0  
fill ~24 ~22 ~92 ~30 ~22 ~92 clay 0  
fill ~24 ~22 ~100 ~30 ~22 ~100 clay 0  
fill ~26 ~22 ~91 ~28 ~22 ~91 clay 0  
fill ~26 ~22 ~101 ~28 ~22 ~101 clay 0  
fill ~30 ~22 ~10 ~43 ~22 ~10 wool 4  
fill ~30 ~22 ~11 ~43 ~22 ~11 wool 4  
fill ~30 ~22 ~12 ~43 ~22 ~12 wool 4  
fill ~30 ~22 ~13 ~43 ~22 ~13 wool 4  
fill ~31 ~22 ~8 ~42 ~22 ~8 wool 4  
fill ~31 ~22 ~9 ~42 ~22 ~9 wool 4  
fill ~31 ~22 ~14 ~42 ~22 ~14 wool 4  
fill ~31 ~22 ~15 ~42 ~22 ~15 wool 4  
fill ~31 ~22 ~36 ~45 ~22 ~36 wool 1  
fill ~31 ~22 ~37 ~45 ~22 ~37 wool 1  
fill ~31 ~22 ~38 ~45 ~22 ~38 wool 1  
fill ~31 ~22 ~39 ~45 ~22 ~39 wool 1  
fill ~31 ~22 ~40 ~45 ~22 ~40 wool 1  
fill ~32 ~22 ~7 ~41 ~22 ~7 wool 4  
fill ~32 ~22 ~16 ~41 ~22 ~16 wool 4  
fill ~32 ~22 ~34 ~44 ~22 ~34 wool 1  
fill ~32 ~22 ~35 ~44 ~22 ~35 wool 1  
fill ~32 ~22 ~41 ~44 ~22 ~41 wool 1  
fill ~32 ~22 ~42 ~44 ~22 ~42 wool 1  
fill ~33 ~22 ~6 ~40 ~22 ~6 wool 4  
fill ~33 ~22 ~17 ~40 ~22 ~17 wool 4  
fill ~33 ~22 ~33 ~43 ~22 ~33 wool 1  
fill ~33 ~22 ~43 ~43 ~22 ~43 wool 1  
fill ~34 ~22 ~32 ~42 ~22 ~32 wool 1  
fill ~34 ~22 ~44 ~42 ~22 ~44 wool 1  
fill ~35 ~22 ~5 ~38 ~22 ~5 wool 4  
fill ~35 ~22 ~18 ~38 ~22 ~18 wool 4  
fill ~36 ~22 ~31 ~40 ~22 ~31 wool 1  
fill ~36 ~22 ~45 ~40 ~22 ~45 wool 1  
fill ~45 ~22 ~74 ~64 ~22 ~74 lava 0  
fill ~45 ~22 ~75 ~64 ~22 ~75 lava 0  
fill ~45 ~22 ~76 ~64 ~22 ~76 lava 0  
fill ~45 ~22 ~77 ~64 ~22 ~77 lava 0  
fill ~46 ~22 ~71 ~63 ~22 ~71 lava 0  
fill ~46 ~22 ~72 ~63 ~22 ~72 lava 0  
fill ~46 ~22 ~73 ~63 ~22 ~73 lava 0  
fill ~46 ~22 ~78 ~63 ~22 ~78 lava 0  
fill ~46 ~22 ~79 ~63 ~22 ~79 lava 0  
fill ~46 ~22 ~80 ~63 ~22 ~80 lava 0  
fill ~47 ~22 ~70 ~62 ~22 ~70 lava 0  
fill ~47 ~22 ~81 ~62 ~22 ~81 lava 0  
fill ~48 ~22 ~69 ~61 ~22 ~69 lava 0  
fill ~48 ~22 ~82 ~61 ~22 ~82 lava 0  
fill ~49 ~22 ~68 ~60 ~22 ~68 lava 0  
fill ~49 ~22 ~83 ~60 ~22 ~83 lava 0  
fill ~50 ~22 ~67 ~59 ~22 ~67 lava 0  
fill ~50 ~22 ~84 ~59 ~22 ~84 lava 0  
fill ~53 ~22 ~66 ~56 ~22 ~66 lava 0  
fill ~53 ~22 ~85 ~56 ~22 ~85 lava 0  
fill ~58 ~22 ~56 ~67 ~22 ~56 stone 0  
fill ~58 ~22 ~57 ~67 ~22 ~57 stone 0  
fill ~58 ~22 ~58 ~67 ~22 ~58 stone 0  
fill ~58 ~22 ~59 ~67 ~22 ~59 stone 0  
fill ~59 ~22 ~54 ~66 ~22 ~54 stone 0  
fill ~59 ~22 ~55 ~66 ~22 ~55 stone 0  
fill ~59 ~22 ~60 ~66 ~22 ~60 stone 0  
fill ~59 ~22 ~61 ~66 ~22 ~61 stone 0  
fill ~61 ~22 ~53 ~64 ~22 ~53 stone 0  
fill ~61 ~22 ~62 ~64 ~22 ~62 stone 0  
fill ~66 ~22 ~67 ~75 ~22 ~67 redstone_ore 0  
fill ~66 ~22 ~68 ~75 ~22 ~68 redstone_ore 0  
fill ~66 ~22 ~69 ~75 ~22 ~69 redstone_ore 0  
fill ~66 ~22 ~70 ~75 ~22 ~70 redstone_ore 0  
fill ~67 ~22 ~66 ~74 ~22 ~66 redstone_ore 0  
fill ~67 ~22 ~71 ~74 ~22 ~71 redstone_ore 0  
fill ~68 ~22 ~65 ~73 ~22 ~65 redstone_ore 0  
fill ~68 ~22 ~72 ~73 ~22 ~72 redstone_ore 0  
fill ~69 ~22 ~64 ~72 ~22 ~64 redstone_ore 0  
fill ~69 ~22 ~73 ~72 ~22 ~73 redstone_ore 0  
fill ~82 ~22 ~48 ~95 ~22 ~48 lapis_block 0  
fill ~82 ~22 ~49 ~95 ~22 ~49 lapis_block 0  
fill ~82 ~22 ~50 ~95 ~22 ~50 lapis_block 0  
fill ~82 ~22 ~51 ~95 ~22 ~51 lapis_block 0  
fill ~83 ~22 ~46 ~94 ~22 ~46 lapis_block 0  
fill ~83 ~22 ~47 ~95 ~22 ~47 lapis_block 0  
fill ~83 ~22 ~52 ~93 ~22 ~52 lapis_block 0  
fill ~83 ~22 ~53 ~93 ~22 ~53 lapis_block 0  
fill ~84 ~22 ~45 ~93 ~22 ~45 lapis_block 0  
fill ~84 ~22 ~54 ~93 ~22 ~54 lapis_block 0  
fill ~85 ~22 ~44 ~92 ~22 ~44 lapis_block 0  
fill ~85 ~22 ~55 ~90 ~22 ~55 lapis_block 0  
fill ~87 ~22 ~43 ~90 ~22 ~43 lapis_block 0  
fill ~87 ~22 ~56 ~87 ~24 ~56 wool 13  
fill ~87 ~22 ~83 ~96 ~22 ~83 netherrack 0  
fill ~87 ~22 ~84 ~96 ~22 ~84 netherrack 0  
fill ~87 ~22 ~85 ~96 ~22 ~85 netherrack 0  
fill ~87 ~22 ~86 ~96 ~22 ~86 netherrack 0  
fill ~88 ~22 ~81 ~95 ~22 ~81 netherrack 0  
fill ~88 ~22 ~82 ~95 ~22 ~82 netherrack 0  
fill ~88 ~22 ~87 ~95 ~22 ~87 netherrack 0  
fill ~88 ~22 ~88 ~95 ~22 ~88 netherrack 0  
fill ~90 ~22 ~56 ~90 ~24 ~56 lapis_block 0  
fill ~90 ~22 ~80 ~93 ~22 ~80 netherrack 0  
fill ~90 ~22 ~89 ~93 ~22 ~89 netherrack 0  
fill ~91 ~22 ~55 ~92 ~22 ~55 wool 13   
setblock ~95 ~22 ~52 wool 13  
fill ~7 ~23 ~79 ~11 ~23 ~79 wool 11  
fill ~7 ~23 ~80 ~11 ~23 ~80 wool 11  
fill ~7 ~23 ~81 ~11 ~23 ~81 wool 11  
fill ~8 ~23 ~78 ~10 ~23 ~78 wool 11  
fill ~8 ~23 ~82 ~10 ~23 ~82 wool 11  
fill ~22 ~23 ~93 ~32 ~23 ~93 clay 0  
fill ~22 ~23 ~94 ~32 ~23 ~94 clay 0  
fill ~22 ~23 ~95 ~32 ~23 ~95 clay 0  
fill ~22 ~23 ~96 ~32 ~23 ~96 clay 0  
fill ~22 ~23 ~97 ~32 ~23 ~97 clay 0  
fill ~22 ~23 ~98 ~32 ~23 ~98 clay 0  
fill ~22 ~23 ~99 ~32 ~23 ~99 clay 0  
fill ~23 ~23 ~92 ~31 ~23 ~92 clay 0  
fill ~23 ~23 ~100 ~31 ~23 ~100 clay 0  
fill ~24 ~23 ~91 ~30 ~23 ~91 clay 0  
fill ~24 ~23 ~101 ~30 ~23 ~101 clay 0  
fill ~29 ~23 ~9 ~44 ~23 ~9 gold_block 0  
fill ~29 ~23 ~10 ~44 ~23 ~10 gold_block 0  
fill ~29 ~23 ~11 ~44 ~23 ~11 gold_block 0  
fill ~29 ~23 ~12 ~44 ~23 ~12 gold_block 0  
fill ~29 ~23 ~13 ~44 ~23 ~13 gold_block 0  
fill ~29 ~23 ~14 ~44 ~23 ~14 gold_block 0  
fill ~30 ~23 ~7 ~43 ~23 ~7 gold_block 0  
fill ~30 ~23 ~8 ~43 ~23 ~8 gold_block 0  
fill ~30 ~23 ~15 ~43 ~23 ~15 gold_block 0  
fill ~30 ~23 ~16 ~43 ~23 ~16 gold_block 0  
fill ~31 ~23 ~6 ~42 ~23 ~6 gold_block 0  
fill ~31 ~23 ~17 ~42 ~23 ~17 gold_block 0  
fill ~31 ~23 ~36 ~45 ~23 ~36 wool 1  
fill ~31 ~23 ~37 ~45 ~23 ~37 wool 1  
fill ~31 ~23 ~38 ~45 ~23 ~38 wool 1  
fill ~31 ~23 ~39 ~45 ~23 ~39 wool 1  
fill ~31 ~23 ~40 ~45 ~23 ~40 wool 1  
fill ~32 ~23 ~5 ~41 ~23 ~5 gold_block 0  
fill ~32 ~23 ~18 ~41 ~23 ~18 gold_block 0  
fill ~32 ~23 ~34 ~44 ~23 ~34 wool 1  
fill ~32 ~23 ~35 ~44 ~23 ~35 wool 1  
fill ~32 ~23 ~41 ~44 ~23 ~41 wool 1  
fill ~32 ~23 ~42 ~44 ~23 ~42 wool 1  
fill ~33 ~23 ~33 ~43 ~23 ~33 wool 1  
fill ~33 ~23 ~43 ~43 ~23 ~43 wool 1  
fill ~34 ~23 ~4 ~39 ~23 ~4 gold_block 0  
fill ~34 ~23 ~19 ~39 ~23 ~19 gold_block 0  
fill ~34 ~23 ~32 ~42 ~23 ~32 wool 1  
fill ~34 ~23 ~44 ~42 ~23 ~44 wool 1 
setblock ~34 ~23 ~45 torch 3  
fill ~36 ~23 ~31 ~40 ~23 ~31 wool 1  
fill ~36 ~23 ~45 ~40 ~23 ~45 wool 1  
fill ~45 ~23 ~73 ~64 ~23 ~73 lava 0  
fill ~45 ~23 ~74 ~64 ~23 ~74 lava 0  
fill ~45 ~23 ~75 ~64 ~23 ~75 lava 0  
fill ~45 ~23 ~76 ~64 ~23 ~76 lava 0  
fill ~45 ~23 ~77 ~64 ~23 ~77 lava 0  
fill ~45 ~23 ~78 ~64 ~23 ~78 lava 0  
fill ~46 ~23 ~71 ~63 ~23 ~71 lava 0  
fill ~46 ~23 ~72 ~63 ~23 ~72 lava 0  
fill ~46 ~23 ~79 ~63 ~23 ~79 lava 0  
fill ~46 ~23 ~80 ~63 ~23 ~80 lava 0  
fill ~47 ~23 ~70 ~62 ~23 ~70 lava 0  
fill ~47 ~23 ~81 ~62 ~23 ~81 lava 0  
fill ~48 ~23 ~69 ~61 ~23 ~69 lava 0  
fill ~48 ~23 ~82 ~61 ~23 ~82 lava 0  
fill ~49 ~23 ~68 ~60 ~23 ~68 lava 0  
fill ~49 ~23 ~83 ~60 ~23 ~83 lava 0  
fill ~50 ~23 ~67 ~59 ~23 ~67 lava 0  
fill ~50 ~23 ~84 ~59 ~23 ~84 lava 0  
fill ~52 ~23 ~66 ~57 ~23 ~66 lava 0  
fill ~52 ~23 ~85 ~57 ~23 ~85 lava 0  
fill ~58 ~23 ~56 ~67 ~23 ~56 stone 0  
fill ~58 ~23 ~57 ~67 ~23 ~57 stone 0  
fill ~58 ~23 ~58 ~67 ~23 ~58 stone 0  
fill ~58 ~23 ~59 ~67 ~23 ~59 stone 0  
fill ~59 ~23 ~54 ~66 ~23 ~54 stone 0  
fill ~59 ~23 ~55 ~66 ~23 ~55 stone 0  
fill ~59 ~23 ~60 ~66 ~23 ~60 stone 0  
fill ~59 ~23 ~61 ~66 ~23 ~61 stone 0  
fill ~61 ~23 ~53 ~64 ~23 ~53 stone 0  
fill ~61 ~23 ~62 ~64 ~23 ~62 stone 0  
fill ~67 ~23 ~67 ~74 ~23 ~67 redstone_ore 0  
fill ~67 ~23 ~68 ~74 ~23 ~68 redstone_ore 0  
fill ~67 ~23 ~69 ~74 ~23 ~69 redstone_ore 0  
fill ~67 ~23 ~70 ~74 ~23 ~70 redstone_ore 0  
fill ~68 ~23 ~66 ~73 ~23 ~66 redstone_ore 0  
fill ~68 ~23 ~71 ~73 ~23 ~71 redstone_ore 0  
fill ~69 ~23 ~65 ~72 ~23 ~65 redstone_ore 0  
fill ~69 ~23 ~72 ~72 ~23 ~72 redstone_ore 0  
fill ~82 ~23 ~47 ~95 ~23 ~47 lapis_block 0  
fill ~82 ~23 ~48 ~95 ~23 ~48 lapis_block 0  
fill ~82 ~23 ~49 ~82 ~26 ~49 wool 13  
fill ~82 ~23 ~50 ~82 ~25 ~50 wool 13  
fill ~82 ~23 ~51 ~82 ~25 ~51 wool 13  
fill ~82 ~23 ~52 ~82 ~24 ~52 wool 13  
fill ~83 ~23 ~46 ~95 ~23 ~46 lapis_block 0  
fill ~83 ~23 ~49 ~96 ~23 ~49 lapis_block 0  
fill ~83 ~23 ~50 ~96 ~23 ~50 lapis_block 0  
fill ~83 ~23 ~51 ~95 ~23 ~51 lapis_block 0  
fill ~83 ~23 ~52 ~95 ~23 ~52 lapis_block 0  
fill ~83 ~23 ~53 ~95 ~23 ~53 lapis_block 0  
fill ~84 ~23 ~45 ~94 ~23 ~45 lapis_block 0  
fill ~84 ~23 ~54 ~94 ~23 ~54 lapis_block 0  
fill ~85 ~23 ~29 ~86 ~23 ~29 glowstone 0  
fill ~85 ~23 ~30 ~86 ~23 ~30 glowstone 0  
fill ~85 ~23 ~44 ~93 ~23 ~44 lapis_block 0  
fill ~85 ~23 ~55 ~90 ~23 ~55 lapis_block 0  
fill ~86 ~23 ~43 ~91 ~23 ~43 lapis_block 0  
fill ~86 ~23 ~56 ~86 ~24 ~56 wool 13 
setblock ~86 ~23 ~83 torch 2  
fill ~87 ~23 ~83 ~96 ~23 ~83 netherrack 0  
fill ~87 ~23 ~84 ~96 ~23 ~84 netherrack 0  
fill ~87 ~23 ~85 ~96 ~23 ~85 netherrack 0  
fill ~87 ~23 ~86 ~96 ~23 ~86 netherrack 0  
fill ~88 ~23 ~81 ~95 ~23 ~81 netherrack 0  
fill ~88 ~23 ~82 ~95 ~23 ~82 netherrack 0  
fill ~88 ~23 ~87 ~95 ~23 ~87 netherrack 0  
fill ~88 ~23 ~88 ~95 ~23 ~88 netherrack 0  
fill ~90 ~23 ~80 ~93 ~23 ~80 netherrack 0  
fill ~90 ~23 ~89 ~93 ~23 ~89 netherrack 0  
fill ~91 ~23 ~55 ~92 ~23 ~55 wool 13 
setblock ~91 ~23 ~56 lapis_block 0  
fill ~93 ~23 ~55 ~93 ~28 ~55 lapis_block 0  
fill ~6 ~24 ~78 ~12 ~24 ~78 wool 11  
fill ~6 ~24 ~79 ~12 ~24 ~79 wool 11  
fill ~6 ~24 ~80 ~12 ~24 ~80 wool 11  
fill ~6 ~24 ~81 ~12 ~24 ~81 wool 11  
fill ~6 ~24 ~82 ~12 ~24 ~82 wool 11  
fill ~7 ~24 ~77 ~11 ~24 ~77 wool 11  
fill ~7 ~24 ~83 ~11 ~24 ~83 wool 11  
fill ~21 ~24 ~95 ~33 ~24 ~95 clay 0  
fill ~21 ~24 ~96 ~33 ~24 ~96 clay 0  
fill ~21 ~24 ~97 ~33 ~24 ~97 clay 0  
fill ~22 ~24 ~93 ~32 ~24 ~93 clay 0  
fill ~22 ~24 ~94 ~32 ~24 ~94 clay 0  
fill ~22 ~24 ~98 ~32 ~24 ~98 clay 0  
fill ~22 ~24 ~99 ~32 ~24 ~99 clay 0  
fill ~23 ~24 ~92 ~31 ~24 ~92 clay 0  
fill ~23 ~24 ~100 ~31 ~24 ~100 clay 0  
fill ~24 ~24 ~91 ~30 ~24 ~91 clay 0  
fill ~24 ~24 ~101 ~30 ~24 ~101 clay 0  
fill ~26 ~24 ~90 ~28 ~24 ~90 clay 0  
fill ~26 ~24 ~102 ~28 ~24 ~102 clay 0  
fill ~30 ~24 ~9 ~43 ~24 ~9 wool 4  
fill ~30 ~24 ~10 ~43 ~24 ~10 wool 4  
fill ~30 ~24 ~11 ~43 ~24 ~11 wool 4  
fill ~30 ~24 ~12 ~43 ~24 ~12 wool 4  
fill ~30 ~24 ~13 ~43 ~24 ~13 wool 4  
fill ~30 ~24 ~14 ~43 ~24 ~14 wool 4  
fill ~31 ~24 ~8 ~42 ~24 ~8 wool 4  
fill ~31 ~24 ~15 ~42 ~24 ~15 wool 4  
fill ~31 ~24 ~36 ~45 ~24 ~36 wool 1  
fill ~31 ~24 ~37 ~45 ~24 ~37 wool 1  
fill ~31 ~24 ~38 ~45 ~24 ~38 wool 1  
fill ~31 ~24 ~39 ~45 ~24 ~39 wool 1  
fill ~31 ~24 ~40 ~45 ~24 ~40 wool 1  
fill ~32 ~24 ~7 ~41 ~24 ~7 wool 4  
fill ~32 ~24 ~16 ~41 ~24 ~16 wool 4  
fill ~32 ~24 ~34 ~44 ~24 ~34 wool 1  
fill ~32 ~24 ~35 ~44 ~24 ~35 wool 1  
fill ~32 ~24 ~41 ~44 ~24 ~41 wool 1  
fill ~32 ~24 ~42 ~44 ~24 ~42 wool 1  
fill ~33 ~24 ~6 ~40 ~24 ~6 wool 4  
fill ~33 ~24 ~17 ~40 ~24 ~17 wool 4  
fill ~33 ~24 ~33 ~43 ~24 ~33 wool 1  
fill ~33 ~24 ~43 ~43 ~24 ~43 wool 1  
fill ~34 ~24 ~5 ~39 ~24 ~5 wool 4  
fill ~34 ~24 ~18 ~39 ~24 ~18 wool 4  
fill ~34 ~24 ~32 ~42 ~24 ~32 wool 1  
fill ~34 ~24 ~44 ~42 ~24 ~44 wool 1  
fill ~36 ~24 ~31 ~40 ~24 ~31 wool 1  
fill ~36 ~24 ~45 ~40 ~24 ~45 wool 1  
fill ~45 ~24 ~73 ~64 ~24 ~73 lava 0  
fill ~45 ~24 ~74 ~64 ~24 ~74 lava 0  
fill ~45 ~24 ~75 ~64 ~24 ~75 lava 0  
fill ~45 ~24 ~76 ~64 ~24 ~76 lava 0  
fill ~45 ~24 ~77 ~64 ~24 ~77 lava 0  
fill ~45 ~24 ~78 ~64 ~24 ~78 lava 0  
fill ~46 ~24 ~71 ~63 ~24 ~71 lava 0  
fill ~46 ~24 ~72 ~63 ~24 ~72 lava 0  
fill ~46 ~24 ~79 ~63 ~24 ~79 lava 0  
fill ~46 ~24 ~80 ~63 ~24 ~80 lava 0  
fill ~47 ~24 ~69 ~62 ~24 ~69 lava 0  
fill ~47 ~24 ~70 ~62 ~24 ~70 lava 0  
fill ~47 ~24 ~81 ~62 ~24 ~81 lava 0  
fill ~47 ~24 ~82 ~62 ~24 ~82 lava 0  
fill ~48 ~24 ~68 ~61 ~24 ~68 lava 0  
fill ~48 ~24 ~83 ~61 ~24 ~83 lava 0  
fill ~50 ~24 ~67 ~59 ~24 ~67 lava 0  
fill ~50 ~24 ~84 ~59 ~24 ~84 lava 0  
fill ~52 ~24 ~66 ~57 ~24 ~66 lava 0  
fill ~52 ~24 ~85 ~57 ~24 ~85 lava 0  
fill ~58 ~24 ~56 ~67 ~24 ~56 stone 0  
fill ~58 ~24 ~57 ~67 ~24 ~57 stone 0  
fill ~58 ~24 ~58 ~67 ~24 ~58 stone 0  
fill ~58 ~24 ~59 ~67 ~24 ~59 stone 0  
fill ~59 ~24 ~55 ~66 ~24 ~55 stone 0  
fill ~59 ~24 ~60 ~66 ~24 ~60 stone 0  
fill ~60 ~24 ~54 ~65 ~24 ~54 stone 0  
fill ~60 ~24 ~61 ~65 ~24 ~61 stone 0  
fill ~61 ~24 ~53 ~64 ~24 ~53 stone 0  
fill ~61 ~24 ~62 ~64 ~24 ~62 stone 0  
fill ~69 ~24 ~67 ~72 ~24 ~67 redstone_ore 0  
fill ~69 ~24 ~68 ~72 ~24 ~68 redstone_ore 0  
fill ~69 ~24 ~69 ~72 ~24 ~69 redstone_ore 0  
fill ~69 ~24 ~70 ~72 ~24 ~70 redstone_ore 0  
fill ~82 ~24 ~47 ~95 ~24 ~47 lapis_block 0  
fill ~82 ~24 ~48 ~96 ~24 ~48 lapis_block 0  
fill ~83 ~24 ~46 ~95 ~24 ~46 lapis_block 0  
fill ~83 ~24 ~49 ~96 ~24 ~49 lapis_block 0  
fill ~83 ~24 ~50 ~96 ~24 ~50 lapis_block 0  
fill ~83 ~24 ~51 ~96 ~24 ~51 lapis_block 0  
fill ~83 ~24 ~52 ~95 ~24 ~52 lapis_block 0  
fill ~83 ~24 ~53 ~95 ~24 ~53 lapis_block 0 
setblock ~83 ~24 ~54 torch 2  
fill ~84 ~24 ~29 ~87 ~24 ~29 glowstone 0  
fill ~84 ~24 ~30 ~87 ~24 ~30 glowstone 0  
fill ~84 ~24 ~45 ~94 ~24 ~45 lapis_block 0  
fill ~84 ~24 ~54 ~94 ~24 ~54 lapis_block 0  
fill ~85 ~24 ~28 ~86 ~24 ~28 glowstone 0  
fill ~85 ~24 ~31 ~86 ~24 ~31 glowstone 0  
fill ~85 ~24 ~44 ~93 ~24 ~44 lapis_block 0  
fill ~85 ~24 ~55 ~90 ~24 ~55 lapis_block 0  
fill ~86 ~24 ~43 ~91 ~24 ~43 lapis_block 0  
fill ~87 ~24 ~83 ~96 ~24 ~83 netherrack 0  
fill ~87 ~24 ~84 ~96 ~24 ~84 netherrack 0  
fill ~87 ~24 ~85 ~96 ~24 ~85 netherrack 0  
fill ~87 ~24 ~86 ~96 ~24 ~86 netherrack 0  
fill ~88 ~24 ~82 ~95 ~24 ~82 netherrack 0  
fill ~88 ~24 ~87 ~95 ~24 ~87 netherrack 0  
fill ~89 ~24 ~81 ~94 ~24 ~81 netherrack 0  
fill ~89 ~24 ~88 ~94 ~24 ~88 netherrack 0  
fill ~90 ~24 ~80 ~93 ~24 ~80 netherrack 0  
fill ~90 ~24 ~89 ~93 ~24 ~89 netherrack 0  
fill ~91 ~24 ~55 ~92 ~24 ~55 wool 13  
fill ~91 ~24 ~56 ~91 ~27 ~56 wool 13  
fill ~5 ~25 ~78 ~13 ~25 ~78 wool 11  
fill ~5 ~25 ~79 ~13 ~25 ~79 wool 11  
fill ~5 ~25 ~80 ~13 ~25 ~80 wool 11  
fill ~5 ~25 ~81 ~13 ~25 ~81 wool 11  
fill ~5 ~25 ~82 ~13 ~25 ~82 wool 11  
fill ~6 ~25 ~77 ~12 ~25 ~77 wool 11  
fill ~6 ~25 ~83 ~12 ~25 ~83 wool 11  
fill ~7 ~25 ~76 ~11 ~25 ~76 wool 11  
fill ~7 ~25 ~84 ~11 ~25 ~84 wool 11  
fill ~21 ~25 ~94 ~33 ~25 ~94 clay 0  
fill ~21 ~25 ~95 ~33 ~25 ~95 clay 0  
fill ~21 ~25 ~96 ~33 ~25 ~96 clay 0  
fill ~21 ~25 ~97 ~33 ~25 ~97 clay 0  
fill ~21 ~25 ~98 ~33 ~25 ~98 clay 0  
fill ~22 ~25 ~92 ~32 ~25 ~92 clay 0  
fill ~22 ~25 ~93 ~32 ~25 ~93 clay 0  
fill ~22 ~25 ~99 ~32 ~25 ~99 clay 0  
fill ~22 ~25 ~100 ~32 ~25 ~100 clay 0  
fill ~23 ~25 ~91 ~31 ~25 ~91 clay 0  
fill ~23 ~25 ~101 ~31 ~25 ~101 clay 0  
fill ~25 ~25 ~90 ~29 ~25 ~90 clay 0  
fill ~25 ~25 ~102 ~29 ~25 ~102 clay 0  
fill ~30 ~25 ~10 ~43 ~25 ~10 wool 4  
fill ~30 ~25 ~11 ~43 ~25 ~11 wool 4  
fill ~30 ~25 ~12 ~43 ~25 ~12 wool 4  
fill ~30 ~25 ~13 ~43 ~25 ~13 wool 4  
fill ~31 ~25 ~8 ~42 ~25 ~8 wool 4  
fill ~31 ~25 ~9 ~42 ~25 ~9 wool 4  
fill ~31 ~25 ~14 ~42 ~25 ~14 wool 4  
fill ~31 ~25 ~15 ~42 ~25 ~15 wool 4  
fill ~31 ~25 ~37 ~45 ~25 ~37 wool 1  
fill ~31 ~25 ~38 ~45 ~25 ~38 wool 1  
fill ~31 ~25 ~39 ~45 ~25 ~39 wool 1  
fill ~32 ~25 ~7 ~41 ~25 ~7 wool 4  
fill ~32 ~25 ~16 ~41 ~25 ~16 wool 4  
fill ~32 ~25 ~34 ~44 ~25 ~34 wool 1  
fill ~32 ~25 ~35 ~44 ~25 ~35 wool 1  
fill ~32 ~25 ~36 ~44 ~25 ~36 wool 1  
fill ~32 ~25 ~40 ~44 ~25 ~40 wool 1  
fill ~32 ~25 ~41 ~44 ~25 ~41 wool 1  
fill ~32 ~25 ~42 ~44 ~25 ~42 wool 1 
setblock ~32 ~25 ~91 torch 4  
fill ~33 ~25 ~6 ~40 ~25 ~6 wool 4  
fill ~33 ~25 ~17 ~40 ~25 ~17 wool 4  
fill ~33 ~25 ~33 ~43 ~25 ~33 wool 1  
fill ~33 ~25 ~43 ~43 ~25 ~43 wool 1  
fill ~34 ~25 ~32 ~42 ~25 ~32 wool 1  
fill ~34 ~25 ~44 ~42 ~25 ~44 wool 1  
fill ~35 ~25 ~5 ~38 ~25 ~5 wool 4  
fill ~35 ~25 ~18 ~38 ~25 ~18 wool 4  
fill ~37 ~25 ~31 ~39 ~25 ~31 wool 1  
fill ~37 ~25 ~45 ~39 ~25 ~45 wool 1 
setblock ~43 ~25 ~14 torch 1 
setblock ~44 ~25 ~43 torch 1  
fill ~45 ~25 ~73 ~64 ~25 ~73 lava 0  
fill ~45 ~25 ~74 ~64 ~25 ~74 lava 0  
fill ~45 ~25 ~75 ~64 ~25 ~75 lava 0  
fill ~45 ~25 ~76 ~64 ~25 ~76 lava 0  
fill ~45 ~25 ~77 ~64 ~25 ~77 lava 0  
fill ~45 ~25 ~78 ~64 ~25 ~78 lava 0  
fill ~46 ~25 ~71 ~63 ~25 ~71 lava 0  
fill ~46 ~25 ~72 ~63 ~25 ~72 lava 0  
fill ~46 ~25 ~79 ~63 ~25 ~79 lava 0  
fill ~46 ~25 ~80 ~63 ~25 ~80 lava 0  
fill ~47 ~25 ~69 ~62 ~25 ~69 lava 0  
fill ~47 ~25 ~70 ~62 ~25 ~70 lava 0  
fill ~47 ~25 ~81 ~62 ~25 ~81 lava 0  
fill ~47 ~25 ~82 ~62 ~25 ~82 lava 0  
fill ~48 ~25 ~68 ~61 ~25 ~68 lava 0  
fill ~48 ~25 ~83 ~61 ~25 ~83 lava 0  
fill ~50 ~25 ~67 ~59 ~25 ~67 lava 0  
fill ~50 ~25 ~84 ~59 ~25 ~84 lava 0  
fill ~52 ~25 ~66 ~57 ~25 ~66 lava 0  
fill ~52 ~25 ~85 ~57 ~25 ~85 lava 0  
fill ~59 ~25 ~55 ~66 ~25 ~55 stone 0  
fill ~59 ~25 ~56 ~66 ~25 ~56 stone 0  
fill ~59 ~25 ~57 ~66 ~25 ~57 stone 0  
fill ~59 ~25 ~58 ~66 ~25 ~58 stone 0  
fill ~59 ~25 ~59 ~66 ~25 ~59 stone 0  
fill ~59 ~25 ~60 ~66 ~25 ~60 stone 0  
fill ~60 ~25 ~54 ~65 ~25 ~54 stone 0  
fill ~60 ~25 ~61 ~65 ~25 ~61 stone 0  
fill ~82 ~25 ~48 ~96 ~25 ~48 lapis_block 0  
fill ~83 ~25 ~46 ~95 ~25 ~46 lapis_block 0  
fill ~83 ~25 ~47 ~96 ~25 ~47 lapis_block 0  
fill ~83 ~25 ~49 ~96 ~25 ~49 lapis_block 0  
fill ~83 ~25 ~50 ~96 ~25 ~50 lapis_block 0  
fill ~83 ~25 ~51 ~96 ~25 ~51 lapis_block 0  
fill ~83 ~25 ~52 ~96 ~25 ~52 lapis_block 0  
fill ~83 ~25 ~53 ~95 ~25 ~53 lapis_block 0  
fill ~84 ~25 ~29 ~87 ~25 ~29 glowstone 0  
fill ~84 ~25 ~30 ~87 ~25 ~30 glowstone 0  
fill ~84 ~25 ~45 ~94 ~25 ~45 lapis_block 0  
fill ~84 ~25 ~54 ~94 ~25 ~54 lapis_block 0  
fill ~85 ~25 ~28 ~86 ~25 ~28 glowstone 0  
fill ~85 ~25 ~31 ~86 ~25 ~31 glowstone 0  
fill ~85 ~25 ~44 ~93 ~25 ~44 lapis_block 0  
fill ~85 ~25 ~55 ~90 ~25 ~55 lapis_block 0  
fill ~87 ~25 ~43 ~92 ~25 ~43 lapis_block 0 
setblock ~87 ~25 ~56 lapis_block 0  
fill ~88 ~25 ~82 ~95 ~25 ~82 netherrack 0  
fill ~88 ~25 ~83 ~95 ~25 ~83 netherrack 0  
fill ~88 ~25 ~84 ~95 ~25 ~84 netherrack 0  
fill ~88 ~25 ~85 ~95 ~25 ~85 netherrack 0  
fill ~88 ~25 ~86 ~95 ~25 ~86 netherrack 0  
fill ~88 ~25 ~87 ~95 ~25 ~87 netherrack 0  
fill ~89 ~25 ~56 ~92 ~25 ~56 wool 13  
fill ~89 ~25 ~81 ~94 ~25 ~81 netherrack 0  
fill ~89 ~25 ~88 ~94 ~25 ~88 netherrack 0  
fill ~91 ~25 ~55 ~92 ~25 ~55 wool 13  
fill ~4 ~26 ~79 ~14 ~26 ~79 wool 11  
fill ~4 ~26 ~80 ~14 ~26 ~80 wool 11  
fill ~4 ~26 ~81 ~14 ~26 ~81 wool 11  
fill ~5 ~26 ~77 ~13 ~26 ~77 wool 11  
fill ~5 ~26 ~78 ~13 ~26 ~78 wool 11  
fill ~5 ~26 ~82 ~13 ~26 ~82 wool 11  
fill ~5 ~26 ~83 ~13 ~26 ~83 wool 11  
fill ~6 ~26 ~76 ~12 ~26 ~76 wool 11  
fill ~6 ~26 ~84 ~12 ~26 ~84 wool 11  
fill ~8 ~26 ~75 ~10 ~26 ~75 wool 11  
fill ~8 ~26 ~85 ~10 ~26 ~85 wool 11  
fill ~21 ~26 ~94 ~33 ~26 ~94 clay 0  
fill ~21 ~26 ~95 ~33 ~26 ~95 clay 0  
fill ~21 ~26 ~96 ~33 ~26 ~96 clay 0  
fill ~21 ~26 ~97 ~33 ~26 ~97 clay 0  
fill ~21 ~26 ~98 ~33 ~26 ~98 clay 0  
fill ~22 ~26 ~92 ~32 ~26 ~92 clay 0  
fill ~22 ~26 ~93 ~32 ~26 ~93 clay 0  
fill ~22 ~26 ~99 ~32 ~26 ~99 clay 0  
fill ~22 ~26 ~100 ~32 ~26 ~100 clay 0  
fill ~23 ~26 ~91 ~31 ~26 ~91 clay 0  
fill ~23 ~26 ~101 ~31 ~26 ~101 clay 0  
fill ~25 ~26 ~90 ~29 ~26 ~90 clay 0  
fill ~25 ~26 ~102 ~29 ~26 ~102 clay 0  
fill ~30 ~26 ~11 ~43 ~26 ~11 wool 4  
fill ~30 ~26 ~12 ~43 ~26 ~12 wool 4  
fill ~31 ~26 ~8 ~42 ~26 ~8 wool 4  
fill ~31 ~26 ~9 ~42 ~26 ~9 wool 4  
fill ~31 ~26 ~10 ~42 ~26 ~10 wool 4  
fill ~31 ~26 ~13 ~42 ~26 ~13 wool 4  
fill ~31 ~26 ~14 ~42 ~26 ~14 wool 4  
fill ~31 ~26 ~15 ~42 ~26 ~15 wool 4  
fill ~32 ~26 ~7 ~41 ~26 ~7 wool 4  
fill ~32 ~26 ~16 ~41 ~26 ~16 wool 4  
fill ~32 ~26 ~35 ~44 ~26 ~35 wool 1  
fill ~32 ~26 ~36 ~44 ~26 ~36 wool 1  
fill ~32 ~26 ~37 ~44 ~26 ~37 wool 1  
fill ~32 ~26 ~38 ~44 ~26 ~38 wool 1  
fill ~32 ~26 ~39 ~44 ~26 ~39 wool 1  
fill ~32 ~26 ~40 ~44 ~26 ~40 wool 1  
fill ~32 ~26 ~41 ~44 ~26 ~41 wool 1  
fill ~33 ~26 ~6 ~40 ~26 ~6 wool 4  
fill ~33 ~26 ~17 ~40 ~26 ~17 wool 4  
fill ~33 ~26 ~34 ~43 ~26 ~34 wool 1  
fill ~33 ~26 ~42 ~43 ~26 ~42 wool 1  
fill ~34 ~26 ~33 ~42 ~26 ~33 wool 1  
fill ~34 ~26 ~43 ~42 ~26 ~43 wool 1  
fill ~35 ~26 ~32 ~41 ~26 ~32 wool 1  
fill ~35 ~26 ~44 ~41 ~26 ~44 wool 1  
fill ~36 ~26 ~5 ~37 ~26 ~5 wool 4  
fill ~36 ~26 ~18 ~37 ~26 ~18 wool 4  
fill ~45 ~26 ~73 ~64 ~26 ~73 lava 0  
fill ~45 ~26 ~74 ~64 ~26 ~74 lava 0  
fill ~45 ~26 ~75 ~64 ~26 ~75 lava 0  
fill ~45 ~26 ~76 ~64 ~26 ~76 lava 0  
fill ~45 ~26 ~77 ~64 ~26 ~77 lava 0  
fill ~45 ~26 ~78 ~64 ~26 ~78 lava 0  
fill ~46 ~26 ~71 ~63 ~26 ~71 lava 0  
fill ~46 ~26 ~72 ~63 ~26 ~72 lava 0  
fill ~46 ~26 ~79 ~63 ~26 ~79 lava 0  
fill ~46 ~26 ~80 ~63 ~26 ~80 lava 0  
fill ~47 ~26 ~70 ~62 ~26 ~70 lava 0  
fill ~47 ~26 ~81 ~62 ~26 ~81 lava 0  
fill ~48 ~26 ~69 ~61 ~26 ~69 lava 0  
fill ~48 ~26 ~82 ~61 ~26 ~82 lava 0  
fill ~49 ~26 ~68 ~60 ~26 ~68 lava 0  
fill ~49 ~26 ~83 ~60 ~26 ~83 lava 0  
fill ~50 ~26 ~67 ~59 ~26 ~67 lava 0  
fill ~50 ~26 ~84 ~59 ~26 ~84 lava 0  
fill ~52 ~26 ~66 ~57 ~26 ~66 lava 0  
fill ~52 ~26 ~85 ~57 ~26 ~85 lava 0  
fill ~59 ~26 ~57 ~66 ~26 ~57 stone 0  
fill ~59 ~26 ~58 ~66 ~26 ~58 stone 0  
fill ~60 ~26 ~55 ~65 ~26 ~55 stone 0  
fill ~60 ~26 ~56 ~65 ~26 ~56 stone 0  
fill ~60 ~26 ~59 ~65 ~26 ~59 stone 0  
fill ~60 ~26 ~60 ~65 ~26 ~60 stone 0  
fill ~62 ~26 ~54 ~63 ~26 ~54 stone 0  
fill ~62 ~26 ~61 ~63 ~26 ~61 stone 0  
fill ~83 ~26 ~46 ~95 ~26 ~46 lapis_block 0  
fill ~83 ~26 ~47 ~84 ~26 ~47 wool 13  
fill ~83 ~26 ~48 ~84 ~26 ~48 wool 13  
fill ~83 ~26 ~49 ~84 ~26 ~49 wool 13  
fill ~83 ~26 ~50 ~84 ~26 ~50 wool 13  
fill ~83 ~26 ~51 ~84 ~26 ~51 wool 13  
fill ~83 ~26 ~52 ~84 ~26 ~52 wool 13  
fill ~83 ~26 ~53 ~84 ~26 ~53 wool 13  
fill ~84 ~26 ~45 ~94 ~26 ~45 lapis_block 0  
fill ~84 ~26 ~54 ~94 ~26 ~54 lapis_block 0  
fill ~85 ~26 ~29 ~86 ~26 ~29 glowstone 0  
fill ~85 ~26 ~30 ~86 ~26 ~30 glowstone 0  
fill ~85 ~26 ~44 ~93 ~26 ~44 lapis_block 0  
fill ~85 ~26 ~47 ~96 ~26 ~47 lapis_block 0  
fill ~85 ~26 ~48 ~96 ~26 ~48 lapis_block 0  
fill ~85 ~26 ~49 ~96 ~26 ~49 lapis_block 0  
fill ~85 ~26 ~50 ~96 ~26 ~50 lapis_block 0  
fill ~85 ~26 ~51 ~96 ~26 ~51 lapis_block 0  
fill ~85 ~26 ~52 ~96 ~26 ~52 lapis_block 0  
fill ~85 ~26 ~53 ~95 ~26 ~53 lapis_block 0  
fill ~85 ~26 ~55 ~90 ~26 ~55 lapis_block 0  
fill ~87 ~26 ~43 ~92 ~26 ~43 lapis_block 0 
setblock ~87 ~26 ~56 wool 13 
setblock ~88 ~26 ~83 torch 4  
fill ~88 ~26 ~84 ~95 ~26 ~84 netherrack 0  
fill ~88 ~26 ~85 ~95 ~26 ~85 netherrack 0  
fill ~89 ~26 ~56 ~92 ~26 ~56 wool 13  
fill ~89 ~26 ~82 ~94 ~26 ~82 netherrack 0  
fill ~89 ~26 ~83 ~94 ~26 ~83 netherrack 0  
fill ~89 ~26 ~86 ~94 ~26 ~86 netherrack 0  
fill ~89 ~26 ~87 ~94 ~26 ~87 netherrack 0  
fill ~91 ~26 ~55 ~92 ~26 ~55 wool 13  
fill ~91 ~26 ~81 ~92 ~26 ~81 netherrack 0  
fill ~91 ~26 ~88 ~92 ~26 ~88 netherrack 0  
fill ~4 ~27 ~78 ~14 ~27 ~78 wool 11  
fill ~4 ~27 ~79 ~14 ~27 ~79 wool 11  
fill ~4 ~27 ~80 ~14 ~27 ~80 wool 11  
fill ~4 ~27 ~81 ~14 ~27 ~81 wool 11  
fill ~4 ~27 ~82 ~14 ~27 ~82 wool 11  
fill ~5 ~27 ~77 ~13 ~27 ~77 wool 11  
fill ~5 ~27 ~83 ~13 ~27 ~83 wool 11  
fill ~6 ~27 ~76 ~12 ~27 ~76 wool 11  
fill ~6 ~27 ~84 ~12 ~27 ~84 wool 11  
fill ~7 ~27 ~75 ~11 ~27 ~75 wool 11  
fill ~7 ~27 ~85 ~11 ~27 ~85 wool 11 
setblock ~14 ~27 ~77 torch 4  
fill ~21 ~27 ~95 ~33 ~27 ~95 clay 0  
fill ~21 ~27 ~96 ~33 ~27 ~96 clay 0  
fill ~21 ~27 ~97 ~33 ~27 ~97 clay 0  
fill ~22 ~27 ~93 ~32 ~27 ~93 clay 0  
fill ~22 ~27 ~94 ~32 ~27 ~94 clay 0  
fill ~22 ~27 ~98 ~32 ~27 ~98 clay 0  
fill ~22 ~27 ~99 ~32 ~27 ~99 clay 0  
fill ~23 ~27 ~92 ~31 ~27 ~92 clay 0  
fill ~23 ~27 ~100 ~31 ~27 ~100 clay 0  
fill ~24 ~27 ~91 ~30 ~27 ~91 clay 0  
fill ~24 ~27 ~101 ~30 ~27 ~101 clay 0  
fill ~26 ~27 ~90 ~28 ~27 ~90 clay 0  
fill ~26 ~27 ~102 ~28 ~27 ~102 clay 0  
fill ~31 ~27 ~9 ~42 ~27 ~9 wool 4  
fill ~31 ~27 ~10 ~42 ~27 ~10 wool 4  
fill ~31 ~27 ~11 ~42 ~27 ~11 wool 4  
fill ~31 ~27 ~12 ~42 ~27 ~12 wool 4  
fill ~31 ~27 ~13 ~42 ~27 ~13 wool 4  
fill ~31 ~27 ~14 ~42 ~27 ~14 wool 4  
fill ~32 ~27 ~8 ~41 ~27 ~8 wool 4  
fill ~32 ~27 ~15 ~41 ~27 ~15 wool 4  
fill ~32 ~27 ~36 ~44 ~27 ~36 wool 1  
fill ~32 ~27 ~37 ~44 ~27 ~37 wool 1  
fill ~32 ~27 ~38 ~44 ~27 ~38 wool 1  
fill ~32 ~27 ~39 ~44 ~27 ~39 wool 1  
fill ~32 ~27 ~40 ~44 ~27 ~40 wool 1  
fill ~33 ~27 ~7 ~40 ~27 ~7 wool 4  
fill ~33 ~27 ~16 ~40 ~27 ~16 wool 4  
fill ~33 ~27 ~35 ~43 ~27 ~35 wool 1  
fill ~33 ~27 ~41 ~43 ~27 ~41 wool 1  
fill ~34 ~27 ~6 ~39 ~27 ~6 wool 4  
fill ~34 ~27 ~17 ~39 ~27 ~17 wool 4  
fill ~34 ~27 ~34 ~42 ~27 ~34 wool 1  
fill ~34 ~27 ~42 ~42 ~27 ~42 wool 1  
fill ~35 ~27 ~33 ~41 ~27 ~33 wool 1  
fill ~35 ~27 ~43 ~41 ~27 ~43 wool 1  
fill ~36 ~27 ~32 ~40 ~27 ~32 wool 1  
fill ~36 ~27 ~44 ~40 ~27 ~44 wool 1  
fill ~45 ~27 ~74 ~64 ~27 ~74 lava 0  
fill ~45 ~27 ~75 ~64 ~27 ~75 lava 0  
fill ~45 ~27 ~76 ~64 ~27 ~76 lava 0  
fill ~45 ~27 ~77 ~64 ~27 ~77 lava 0  
fill ~46 ~27 ~71 ~63 ~27 ~71 lava 0  
fill ~46 ~27 ~72 ~63 ~27 ~72 lava 0  
fill ~46 ~27 ~73 ~63 ~27 ~73 lava 0  
fill ~46 ~27 ~78 ~63 ~27 ~78 lava 0  
fill ~46 ~27 ~79 ~63 ~27 ~79 lava 0  
fill ~46 ~27 ~80 ~63 ~27 ~80 lava 0  
fill ~47 ~27 ~70 ~62 ~27 ~70 lava 0  
fill ~47 ~27 ~81 ~62 ~27 ~81 lava 0  
fill ~48 ~27 ~69 ~61 ~27 ~69 lava 0  
fill ~48 ~27 ~82 ~61 ~27 ~82 lava 0  
fill ~49 ~27 ~68 ~60 ~27 ~68 lava 0  
fill ~49 ~27 ~83 ~60 ~27 ~83 lava 0  
fill ~50 ~27 ~67 ~59 ~27 ~67 lava 0  
fill ~50 ~27 ~84 ~59 ~27 ~84 lava 0  
fill ~53 ~27 ~66 ~56 ~27 ~66 lava 0  
fill ~53 ~27 ~85 ~56 ~27 ~85 lava 0  
fill ~61 ~27 ~56 ~64 ~27 ~56 stone 0  
fill ~61 ~27 ~57 ~64 ~27 ~57 stone 0  
fill ~61 ~27 ~58 ~64 ~27 ~58 stone 0  
fill ~61 ~27 ~59 ~64 ~27 ~59 stone 0  
fill ~83 ~27 ~47 ~84 ~27 ~47 wool 13  
fill ~83 ~27 ~48 ~84 ~27 ~48 wool 13  
fill ~83 ~27 ~49 ~84 ~27 ~49 wool 13  
fill ~83 ~27 ~50 ~84 ~27 ~50 wool 13  
fill ~83 ~27 ~51 ~84 ~27 ~51 wool 13  
fill ~83 ~27 ~52 ~84 ~27 ~52 wool 13  
fill ~83 ~27 ~53 ~84 ~27 ~53 wool 13  
fill ~84 ~27 ~46 ~95 ~27 ~46 lapis_block 0  
fill ~85 ~27 ~45 ~94 ~27 ~45 lapis_block 0  
fill ~85 ~27 ~47 ~95 ~27 ~47 lapis_block 0  
fill ~85 ~27 ~48 ~96 ~27 ~48 lapis_block 0  
fill ~85 ~27 ~49 ~96 ~27 ~49 lapis_block 0  
fill ~85 ~27 ~50 ~96 ~27 ~50 lapis_block 0  
fill ~85 ~27 ~51 ~96 ~27 ~51 lapis_block 0  
fill ~85 ~27 ~52 ~95 ~27 ~52 lapis_block 0  
fill ~85 ~27 ~53 ~95 ~27 ~53 lapis_block 0  
fill ~85 ~27 ~54 ~93 ~27 ~54 lapis_block 0  
fill ~86 ~27 ~44 ~93 ~27 ~44 lapis_block 0  
fill ~86 ~27 ~55 ~92 ~27 ~55 wool 13  
fill ~88 ~27 ~43 ~91 ~27 ~43 lapis_block 0  
fill ~89 ~27 ~56 ~91 ~27 ~56 wool 13  
fill ~90 ~27 ~83 ~93 ~27 ~83 netherrack 0  
fill ~90 ~27 ~84 ~93 ~27 ~84 netherrack 0  
fill ~90 ~27 ~85 ~93 ~27 ~85 netherrack 0  
fill ~90 ~27 ~86 ~93 ~27 ~86 netherrack 0  
fill ~94 ~27 ~54 ~94 ~28 ~54 wool 13  
fill ~4 ~28 ~78 ~14 ~28 ~78 wool 11  
fill ~4 ~28 ~79 ~14 ~28 ~79 wool 11  
fill ~4 ~28 ~80 ~14 ~28 ~80 wool 11  
fill ~4 ~28 ~81 ~14 ~28 ~81 wool 11  
fill ~4 ~28 ~82 ~14 ~28 ~82 wool 11  
fill ~5 ~28 ~77 ~13 ~28 ~77 wool 11  
fill ~5 ~28 ~83 ~13 ~28 ~83 wool 11  
fill ~6 ~28 ~76 ~12 ~28 ~76 wool 11  
fill ~6 ~28 ~84 ~12 ~28 ~84 wool 11  
fill ~7 ~28 ~75 ~11 ~28 ~75 wool 11  
fill ~7 ~28 ~85 ~11 ~28 ~85 wool 11  
fill ~22 ~28 ~93 ~32 ~28 ~93 clay 0  
fill ~22 ~28 ~94 ~32 ~28 ~94 clay 0  
fill ~22 ~28 ~95 ~32 ~28 ~95 clay 0  
fill ~22 ~28 ~96 ~32 ~28 ~96 clay 0  
fill ~22 ~28 ~97 ~32 ~28 ~97 clay 0  
fill ~22 ~28 ~98 ~32 ~28 ~98 clay 0  
fill ~22 ~28 ~99 ~32 ~28 ~99 clay 0  
fill ~23 ~28 ~92 ~31 ~28 ~92 clay 0  
fill ~23 ~28 ~100 ~31 ~28 ~100 clay 0  
fill ~24 ~28 ~91 ~30 ~28 ~91 clay 0  
fill ~24 ~28 ~101 ~30 ~28 ~101 clay 0  
fill ~32 ~28 ~9 ~41 ~28 ~9 wool 4  
fill ~32 ~28 ~10 ~41 ~28 ~10 wool 4  
fill ~32 ~28 ~11 ~41 ~28 ~11 wool 4  
fill ~32 ~28 ~12 ~41 ~28 ~12 wool 4  
fill ~32 ~28 ~13 ~41 ~28 ~13 wool 4  
fill ~32 ~28 ~14 ~41 ~28 ~14 wool 4  
fill ~33 ~28 ~8 ~40 ~28 ~8 wool 4  
fill ~33 ~28 ~15 ~40 ~28 ~15 wool 4  
fill ~33 ~28 ~36 ~43 ~28 ~36 wool 1  
fill ~33 ~28 ~37 ~43 ~28 ~37 wool 1  
fill ~33 ~28 ~38 ~43 ~28 ~38 wool 1  
fill ~33 ~28 ~39 ~43 ~28 ~39 wool 1  
fill ~33 ~28 ~40 ~43 ~28 ~40 wool 1  
fill ~34 ~28 ~7 ~39 ~28 ~7 wool 4  
fill ~34 ~28 ~16 ~39 ~28 ~16 wool 4  
fill ~34 ~28 ~35 ~42 ~28 ~35 wool 1  
fill ~34 ~28 ~41 ~42 ~28 ~41 wool 1  
fill ~35 ~28 ~34 ~41 ~28 ~34 wool 1  
fill ~35 ~28 ~42 ~41 ~28 ~42 wool 1  
fill ~36 ~28 ~33 ~40 ~28 ~33 wool 1  
fill ~36 ~28 ~43 ~40 ~28 ~43 wool 1  
fill ~46 ~28 ~72 ~63 ~28 ~72 lava 0  
fill ~46 ~28 ~73 ~63 ~28 ~73 lava 0  
fill ~46 ~28 ~74 ~63 ~28 ~74 lava 0  
fill ~46 ~28 ~75 ~63 ~28 ~75 lava 0  
fill ~46 ~28 ~76 ~63 ~28 ~76 lava 0  
fill ~46 ~28 ~77 ~63 ~28 ~77 lava 0  
fill ~46 ~28 ~78 ~63 ~28 ~78 lava 0  
fill ~46 ~28 ~79 ~63 ~28 ~79 lava 0  
fill ~47 ~28 ~70 ~62 ~28 ~70 lava 0  
fill ~47 ~28 ~71 ~62 ~28 ~71 lava 0  
fill ~47 ~28 ~80 ~62 ~28 ~80 lava 0  
fill ~47 ~28 ~81 ~62 ~28 ~81 lava 0  
fill ~48 ~28 ~69 ~61 ~28 ~69 lava 0  
fill ~48 ~28 ~82 ~61 ~28 ~82 lava 0  
fill ~49 ~28 ~68 ~60 ~28 ~68 lava 0  
fill ~49 ~28 ~83 ~60 ~28 ~83 lava 0  
fill ~51 ~28 ~67 ~58 ~28 ~67 lava 0  
fill ~51 ~28 ~84 ~58 ~28 ~84 lava 0  
fill ~83 ~28 ~47 ~84 ~28 ~47 wool 13  
fill ~83 ~28 ~48 ~84 ~28 ~48 wool 13  
fill ~83 ~28 ~49 ~84 ~28 ~49 wool 13  
fill ~83 ~28 ~50 ~84 ~28 ~50 wool 13  
fill ~83 ~28 ~51 ~84 ~28 ~51 wool 13  
fill ~83 ~28 ~52 ~84 ~28 ~52 wool 13  
fill ~83 ~28 ~53 ~84 ~28 ~53 wool 13  
fill ~84 ~28 ~46 ~95 ~28 ~46 lapis_block 0  
fill ~85 ~28 ~45 ~94 ~28 ~45 lapis_block 0  
fill ~85 ~28 ~47 ~95 ~28 ~47 lapis_block 0  
fill ~85 ~28 ~48 ~95 ~28 ~48 lapis_block 0  
fill ~85 ~28 ~49 ~96 ~28 ~49 lapis_block 0  
fill ~85 ~28 ~50 ~96 ~28 ~50 lapis_block 0  
fill ~85 ~28 ~51 ~95 ~28 ~51 lapis_block 0  
fill ~85 ~28 ~52 ~95 ~28 ~52 lapis_block 0  
fill ~85 ~28 ~53 ~95 ~28 ~53 lapis_block 0  
fill ~85 ~28 ~54 ~93 ~28 ~54 lapis_block 0  
fill ~86 ~28 ~44 ~93 ~28 ~44 lapis_block 0  
fill ~86 ~28 ~55 ~92 ~28 ~55 wool 13  
fill ~89 ~28 ~43 ~90 ~28 ~43 lapis_block 0  
fill ~89 ~28 ~56 ~90 ~28 ~56 wool 13  
fill ~4 ~29 ~78 ~14 ~29 ~78 wool 11  
fill ~4 ~29 ~79 ~14 ~29 ~79 wool 11  
fill ~4 ~29 ~80 ~14 ~29 ~80 wool 11  
fill ~4 ~29 ~81 ~14 ~29 ~81 wool 11  
fill ~4 ~29 ~82 ~14 ~29 ~82 wool 11  
fill ~5 ~29 ~77 ~13 ~29 ~77 wool 11  
fill ~5 ~29 ~83 ~13 ~29 ~83 wool 11  
fill ~6 ~29 ~76 ~12 ~29 ~76 wool 11  
fill ~6 ~29 ~84 ~12 ~29 ~84 wool 11  
fill ~7 ~29 ~75 ~11 ~29 ~75 wool 11  
fill ~7 ~29 ~85 ~11 ~29 ~85 wool 11 
setblock ~15 ~29 ~80 torch 1  
fill ~22 ~29 ~95 ~32 ~29 ~95 clay 0  
fill ~22 ~29 ~96 ~32 ~29 ~96 clay 0  
fill ~22 ~29 ~97 ~32 ~29 ~97 clay 0  
fill ~23 ~29 ~93 ~31 ~29 ~93 clay 0  
fill ~23 ~29 ~94 ~31 ~29 ~94 clay 0  
fill ~23 ~29 ~98 ~31 ~29 ~98 clay 0  
fill ~23 ~29 ~99 ~31 ~29 ~99 clay 0  
fill ~24 ~29 ~92 ~30 ~29 ~92 clay 0  
fill ~24 ~29 ~100 ~30 ~29 ~100 clay 0  
fill ~26 ~29 ~91 ~28 ~29 ~91 clay 0  
fill ~26 ~29 ~101 ~28 ~29 ~101 clay 0  
fill ~33 ~29 ~9 ~40 ~29 ~9 wool 4  
fill ~33 ~29 ~10 ~40 ~29 ~10 wool 4  
fill ~33 ~29 ~11 ~40 ~29 ~11 wool 4  
fill ~33 ~29 ~12 ~40 ~29 ~12 wool 4  
fill ~33 ~29 ~13 ~40 ~29 ~13 wool 4  
fill ~33 ~29 ~14 ~40 ~29 ~14 wool 4  
fill ~34 ~29 ~8 ~39 ~29 ~8 wool 4  
fill ~34 ~29 ~15 ~39 ~29 ~15 wool 4  
fill ~34 ~29 ~36 ~42 ~29 ~36 wool 1  
fill ~34 ~29 ~37 ~42 ~29 ~37 wool 1  
fill ~34 ~29 ~38 ~42 ~29 ~38 wool 1  
fill ~34 ~29 ~39 ~42 ~29 ~39 wool 1  
fill ~34 ~29 ~40 ~42 ~29 ~40 wool 1  
fill ~35 ~29 ~35 ~41 ~29 ~35 wool 1  
fill ~35 ~29 ~41 ~41 ~29 ~41 wool 1  
fill ~36 ~29 ~34 ~40 ~29 ~34 wool 1  
fill ~36 ~29 ~42 ~40 ~29 ~42 wool 1  
fill ~46 ~29 ~73 ~63 ~29 ~73 lava 0  
fill ~46 ~29 ~74 ~63 ~29 ~74 lava 0  
fill ~46 ~29 ~75 ~63 ~29 ~75 lava 0  
fill ~46 ~29 ~76 ~63 ~29 ~76 lava 0  
fill ~46 ~29 ~77 ~63 ~29 ~77 lava 0  
fill ~46 ~29 ~78 ~63 ~29 ~78 lava 0  
fill ~47 ~29 ~71 ~62 ~29 ~71 lava 0  
fill ~47 ~29 ~72 ~62 ~29 ~72 lava 0  
fill ~47 ~29 ~79 ~62 ~29 ~79 lava 0  
fill ~47 ~29 ~80 ~62 ~29 ~80 lava 0  
fill ~48 ~29 ~70 ~61 ~29 ~70 lava 0  
fill ~48 ~29 ~81 ~61 ~29 ~81 lava 0  
fill ~49 ~29 ~69 ~60 ~29 ~69 lava 0  
fill ~49 ~29 ~82 ~60 ~29 ~82 lava 0  
fill ~50 ~29 ~68 ~59 ~29 ~68 lava 0  
fill ~50 ~29 ~83 ~59 ~29 ~83 lava 0  
fill ~52 ~29 ~67 ~57 ~29 ~67 lava 0  
fill ~52 ~29 ~84 ~57 ~29 ~84 lava 0  
fill ~83 ~29 ~47 ~84 ~29 ~47 wool 13  
fill ~83 ~29 ~48 ~84 ~29 ~48 wool 13  
fill ~83 ~29 ~49 ~84 ~29 ~49 wool 13  
fill ~83 ~29 ~50 ~84 ~29 ~50 wool 13  
fill ~83 ~29 ~51 ~84 ~29 ~51 wool 13  
fill ~83 ~29 ~52 ~84 ~29 ~52 wool 13  
fill ~83 ~29 ~53 ~84 ~29 ~53 wool 13  
fill ~85 ~29 ~46 ~94 ~29 ~46 lapis_block 0  
fill ~85 ~29 ~47 ~95 ~29 ~47 lapis_block 0  
fill ~85 ~29 ~48 ~95 ~29 ~48 lapis_block 0  
fill ~85 ~29 ~49 ~95 ~29 ~49 lapis_block 0  
fill ~85 ~29 ~50 ~95 ~29 ~50 lapis_block 0  
fill ~85 ~29 ~51 ~95 ~29 ~51 lapis_block 0  
fill ~85 ~29 ~52 ~95 ~29 ~52 lapis_block 0  
fill ~85 ~29 ~53 ~94 ~29 ~53 lapis_block 0  
fill ~86 ~29 ~45 ~93 ~29 ~45 lapis_block 0  
fill ~86 ~29 ~54 ~93 ~29 ~54 lapis_block 0 
setblock ~86 ~29 ~55 torch 3  
fill ~87 ~29 ~44 ~92 ~29 ~44 lapis_block 0  
fill ~87 ~29 ~55 ~92 ~29 ~55 wool 13  
fill ~4 ~30 ~79 ~14 ~30 ~79 wool 11  
fill ~4 ~30 ~80 ~14 ~30 ~80 wool 11  
fill ~4 ~30 ~81 ~14 ~30 ~81 wool 11  
fill ~5 ~30 ~77 ~13 ~30 ~77 wool 11  
fill ~5 ~30 ~78 ~13 ~30 ~78 wool 11  
fill ~5 ~30 ~82 ~13 ~30 ~82 wool 11  
fill ~5 ~30 ~83 ~13 ~30 ~83 wool 11  
fill ~6 ~30 ~76 ~12 ~30 ~76 wool 11  
fill ~6 ~30 ~84 ~12 ~30 ~84 wool 11  
fill ~8 ~30 ~75 ~10 ~30 ~75 wool 11  
fill ~8 ~30 ~85 ~10 ~30 ~85 wool 11  
fill ~23 ~30 ~95 ~31 ~30 ~95 clay 0  
fill ~23 ~30 ~96 ~31 ~30 ~96 clay 0  
fill ~23 ~30 ~97 ~31 ~30 ~97 clay 0  
fill ~24 ~30 ~93 ~30 ~30 ~93 clay 0  
fill ~24 ~30 ~94 ~30 ~30 ~94 clay 0  
fill ~24 ~30 ~98 ~30 ~30 ~98 clay 0  
fill ~24 ~30 ~99 ~30 ~30 ~99 clay 0  
fill ~26 ~30 ~92 ~28 ~30 ~92 clay 0  
fill ~26 ~30 ~100 ~28 ~30 ~100 clay 0 
setblock ~30 ~30 ~92 torch 5  
fill ~34 ~30 ~11 ~39 ~30 ~11 wool 4  
fill ~34 ~30 ~12 ~39 ~30 ~12 wool 4  
fill ~35 ~30 ~10 ~38 ~30 ~10 wool 4  
fill ~35 ~30 ~13 ~38 ~30 ~13 wool 4  
fill ~36 ~30 ~9 ~37 ~30 ~9 wool 4  
fill ~36 ~30 ~14 ~37 ~30 ~14 wool 4  
fill ~36 ~30 ~37 ~40 ~30 ~37 wool 1  
fill ~36 ~30 ~38 ~40 ~30 ~38 wool 1  
fill ~36 ~30 ~39 ~40 ~30 ~39 wool 1  
fill ~37 ~30 ~36 ~39 ~30 ~36 wool 1  
fill ~37 ~30 ~40 ~39 ~30 ~40 wool 1  
fill ~47 ~30 ~72 ~62 ~30 ~72 lava 0  
fill ~47 ~30 ~73 ~62 ~30 ~73 lava 0  
fill ~47 ~30 ~74 ~62 ~30 ~74 lava 0  
fill ~47 ~30 ~75 ~62 ~30 ~75 lava 0  
fill ~47 ~30 ~76 ~62 ~30 ~76 lava 0  
fill ~47 ~30 ~77 ~62 ~30 ~77 lava 0  
fill ~47 ~30 ~78 ~62 ~30 ~78 lava 0  
fill ~47 ~30 ~79 ~62 ~30 ~79 lava 0  
fill ~48 ~30 ~71 ~61 ~30 ~71 lava 0  
fill ~48 ~30 ~80 ~61 ~30 ~80 lava 0  
fill ~49 ~30 ~70 ~60 ~30 ~70 lava 0  
fill ~49 ~30 ~81 ~60 ~30 ~81 lava 0  
fill ~50 ~30 ~69 ~59 ~30 ~69 lava 0  
fill ~50 ~30 ~82 ~59 ~30 ~82 lava 0  
fill ~51 ~30 ~68 ~58 ~30 ~68 lava 0  
fill ~51 ~30 ~83 ~58 ~30 ~83 lava 0  
fill ~85 ~30 ~47 ~94 ~30 ~47 lapis_block 0  
fill ~85 ~30 ~48 ~94 ~30 ~48 lapis_block 0  
fill ~85 ~30 ~49 ~94 ~30 ~49 lapis_block 0  
fill ~85 ~30 ~50 ~94 ~30 ~50 lapis_block 0  
fill ~85 ~30 ~51 ~94 ~30 ~51 lapis_block 0  
fill ~85 ~30 ~52 ~94 ~30 ~52 lapis_block 0  
fill ~86 ~30 ~46 ~93 ~30 ~46 lapis_block 0 
setblock ~86 ~30 ~53 snow 0  
fill ~87 ~30 ~45 ~92 ~30 ~45 lapis_block 0  
fill ~87 ~30 ~53 ~93 ~30 ~53 lapis_block 0  
fill ~87 ~30 ~54 ~92 ~30 ~54 lapis_block 0  
fill ~5 ~31 ~78 ~13 ~31 ~78 wool 11  
fill ~5 ~31 ~79 ~13 ~31 ~79 wool 11  
fill ~5 ~31 ~80 ~13 ~31 ~80 wool 11  
fill ~5 ~31 ~81 ~13 ~31 ~81 wool 11  
fill ~5 ~31 ~82 ~13 ~31 ~82 wool 11  
fill ~6 ~31 ~77 ~12 ~31 ~77 wool 11  
fill ~6 ~31 ~83 ~12 ~31 ~83 wool 11  
fill ~7 ~31 ~40 ~8 ~31 ~40 glowstone 0  
fill ~7 ~31 ~41 ~8 ~31 ~41 glowstone 0  
fill ~7 ~31 ~76 ~11 ~31 ~76 wool 11  
fill ~7 ~31 ~84 ~11 ~31 ~84 wool 11  
fill ~25 ~31 ~95 ~29 ~31 ~95 clay 0  
fill ~25 ~31 ~96 ~29 ~31 ~96 clay 0  
fill ~25 ~31 ~97 ~29 ~31 ~97 clay 0  
fill ~26 ~31 ~94 ~28 ~31 ~94 clay 0  
fill ~26 ~31 ~98 ~28 ~31 ~98 clay 0  
fill ~47 ~31 ~75 ~62 ~31 ~75 lava 0  
fill ~47 ~31 ~76 ~62 ~31 ~76 lava 0  
fill ~48 ~31 ~72 ~61 ~31 ~72 lava 0  
fill ~48 ~31 ~73 ~61 ~31 ~73 lava 0  
fill ~48 ~31 ~74 ~61 ~31 ~74 lava 0  
fill ~48 ~31 ~77 ~61 ~31 ~77 lava 0  
fill ~48 ~31 ~78 ~61 ~31 ~78 lava 0  
fill ~48 ~31 ~79 ~61 ~31 ~79 lava 0  
fill ~49 ~31 ~71 ~60 ~31 ~71 lava 0  
fill ~49 ~31 ~80 ~60 ~31 ~80 lava 0  
fill ~50 ~31 ~70 ~59 ~31 ~70 lava 0  
fill ~50 ~31 ~81 ~59 ~31 ~81 lava 0  
fill ~51 ~31 ~69 ~58 ~31 ~69 lava 0  
fill ~51 ~31 ~82 ~58 ~31 ~82 lava 0    
fill ~54 ~31 ~68 ~55 ~31 ~68 lava 0  
fill ~54 ~31 ~83 ~55 ~31 ~83 lava 0  
fill ~86 ~31 ~47 ~93 ~31 ~47 lapis_block 0  
fill ~86 ~31 ~48 ~93 ~31 ~48 lapis_block 0  
fill ~86 ~31 ~49 ~93 ~31 ~49 lapis_block 0  
fill ~86 ~31 ~50 ~93 ~31 ~50 lapis_block 0  
fill ~86 ~31 ~51 ~93 ~31 ~51 lapis_block 0  
fill ~86 ~31 ~52 ~93 ~31 ~52 lapis_block 0  
fill ~87 ~31 ~46 ~92 ~31 ~46 lapis_block 0  
fill ~87 ~31 ~53 ~92 ~31 ~53 lapis_block 0  
fill ~6 ~32 ~40 ~9 ~32 ~40 glowstone 0  
fill ~6 ~32 ~41 ~9 ~32 ~41 glowstone 0  
fill ~6 ~32 ~78 ~12 ~32 ~78 wool 11  
fill ~6 ~32 ~79 ~12 ~32 ~79 wool 11  
fill ~6 ~32 ~80 ~12 ~32 ~80 wool 11  
fill ~6 ~32 ~81 ~12 ~32 ~81 wool 11  
fill ~6 ~32 ~82 ~12 ~32 ~82 wool 11  
fill ~7 ~32 ~39 ~8 ~32 ~39 glowstone 0  
fill ~7 ~32 ~42 ~8 ~32 ~42 glowstone 0  
fill ~7 ~32 ~77 ~11 ~32 ~77 wool 11  
fill ~7 ~32 ~83 ~11 ~32 ~83 wool 11  
fill ~48 ~32 ~75 ~61 ~32 ~75 lava 0  
fill ~48 ~32 ~76 ~61 ~32 ~76 lava 0  
fill ~49 ~32 ~72 ~60 ~32 ~72 lava 0  
fill ~49 ~32 ~73 ~60 ~32 ~73 lava 0  
fill ~49 ~32 ~74 ~60 ~32 ~74 lava 0  
fill ~49 ~32 ~77 ~60 ~32 ~77 lava 0  
fill ~49 ~32 ~78 ~60 ~32 ~78 lava 0  
fill ~49 ~32 ~79 ~60 ~32 ~79 lava 0  
fill ~50 ~32 ~71 ~59 ~32 ~71 lava 0  
fill ~50 ~32 ~80 ~59 ~32 ~80 lava 0  
fill ~51 ~32 ~70 ~58 ~32 ~70 lava 0  
fill ~51 ~32 ~81 ~58 ~32 ~81 lava 0  
fill ~54 ~32 ~69 ~55 ~32 ~69 lava 0  
fill ~54 ~32 ~82 ~55 ~32 ~82 lava 0  
fill ~87 ~32 ~49 ~87 ~32 ~50 lapis_block 0  
fill ~88 ~32 ~48 ~91 ~32 ~48 lapis_block 0  
fill ~88 ~32 ~49 ~90 ~32 ~49 snow 0  
fill ~88 ~32 ~50 ~90 ~32 ~50 snow 0  
fill ~88 ~32 ~51 ~90 ~32 ~51 snow 0  
fill ~89 ~32 ~47 ~90 ~32 ~47 lapis_block 0  
fill ~89 ~32 ~52 ~90 ~32 ~52 lapis_block 0  
fill ~91 ~32 ~49 ~92 ~32 ~49 lapis_block 0  
fill ~91 ~32 ~50 ~92 ~32 ~50 lapis_block 0  
fill ~91 ~32 ~51 ~91 ~32 ~48 lapis_block 0  
fill ~6 ~33 ~40 ~9 ~33 ~40 glowstone 0  
fill ~6 ~33 ~41 ~9 ~33 ~41 glowstone 0  
fill ~7 ~33 ~39 ~8 ~33 ~39 glowstone 0  
fill ~7 ~33 ~42 ~8 ~33 ~42 glowstone 0  
fill ~7 ~33 ~79 ~11 ~33 ~79 wool 11  
fill ~7 ~33 ~80 ~11 ~33 ~80 wool 11  
fill ~7 ~33 ~81 ~11 ~33 ~81 wool 11  
fill ~8 ~33 ~78 ~10 ~33 ~78 wool 11  
fill ~8 ~33 ~82 ~10 ~33 ~82 wool 11  
fill ~50 ~33 ~73 ~59 ~33 ~73 lava 0  
fill ~50 ~33 ~74 ~59 ~33 ~74 lava 0  
fill ~50 ~33 ~75 ~59 ~33 ~75 lava 0  
fill ~50 ~33 ~76 ~59 ~33 ~76 lava 0  
fill ~50 ~33 ~77 ~59 ~33 ~77 lava 0  
fill ~50 ~33 ~78 ~59 ~33 ~78 lava 0  
fill ~51 ~33 ~72 ~58 ~33 ~72 lava 0  
fill ~51 ~33 ~79 ~58 ~33 ~79 lava 0  
fill ~52 ~33 ~71 ~57 ~33 ~71 lava 0  
fill ~52 ~33 ~80 ~57 ~33 ~80 lava 0  
fill ~7 ~34 ~40 ~8 ~34 ~40 glowstone 0  
fill ~7 ~34 ~41 ~8 ~34 ~41 glowstone 0  
fill ~52 ~34 ~74 ~57 ~34 ~74 lava 0  
fill ~52 ~34 ~75 ~57 ~34 ~75 lava 0  
fill ~52 ~34 ~76 ~57 ~34 ~76 lava 0  
fill ~52 ~34 ~77 ~57 ~34 ~77 lava 0  
fill ~53 ~34 ~73 ~56 ~34 ~73 lava 0  
fill ~53 ~34 ~78 ~56 ~34 ~78 lava 0  
fill ~45 ~37 ~24 ~46 ~37 ~24 glowstone 0  
fill ~45 ~37 ~25 ~46 ~37 ~25 glowstone 0  
fill ~44 ~38 ~24 ~47 ~38 ~24 glowstone 0  
fill ~44 ~38 ~25 ~47 ~38 ~25 glowstone 0  
fill ~45 ~38 ~23 ~46 ~38 ~23 glowstone 0  
fill ~45 ~38 ~26 ~46 ~38 ~26 glowstone 0  
fill ~75 ~38 ~24 ~76 ~38 ~24 glowstone 0  
fill ~75 ~38 ~25 ~76 ~38 ~25 glowstone 0  
fill ~44 ~39 ~24 ~47 ~39 ~24 glowstone 0  
fill ~44 ~39 ~25 ~47 ~39 ~25 glowstone 0  
fill ~45 ~39 ~23 ~46 ~39 ~23 glowstone 0  
fill ~45 ~39 ~26 ~46 ~39 ~26 glowstone 0  
fill ~74 ~39 ~24 ~77 ~39 ~24 glowstone 0  
fill ~74 ~39 ~25 ~77 ~39 ~25 glowstone 0  
fill ~75 ~39 ~23 ~76 ~39 ~23 glowstone 0  
fill ~75 ~39 ~26 ~76 ~39 ~26 glowstone 0  
fill ~45 ~40 ~24 ~46 ~40 ~24 glowstone 0  
fill ~45 ~40 ~25 ~46 ~40 ~25 glowstone 0  
fill ~74 ~40 ~24 ~77 ~40 ~24 glowstone 0  
fill ~74 ~40 ~25 ~77 ~40 ~25 glowstone 0  
fill ~75 ~40 ~23 ~76 ~40 ~23 glowstone 0  
fill ~75 ~40 ~26 ~76 ~40 ~26 glowstone 0  
fill ~75 ~41 ~24 ~76 ~41 ~24 glowstone 0  
fill ~75 ~41 ~25 ~76 ~41 ~25 glowstone 0    