fill ~72~49~8 ~79~49~8 minecraft:stained_glass 3
fill ~58~49~9 ~69~49~9 minecraft:stained_glass 3
fill ~70~49~9 ~70~49~11 minecraft:concrete 0
fill ~72~49~9 ~72~49~11 minecraft:concrete 0
fill ~73~49~9 ~84~49~9 minecraft:stained_glass 3
fill ~54~49~10 ~68~49~10 minecraft:stained_glass 3
fill ~69~49~10 ~69~49~12 minecraft:concrete 0
setblock ~71~48~10 minecraft:stone_block_slab 8
setblock ~71~50~10 minecraft:stone_block_slab 0
fill ~73~49~10 ~73~49~12 minecraft:concrete 0
fill ~74~49~10 ~88~49~10 minecraft:stained_glass 3
fill ~50~49~11 ~63~49~11 minecraft:stained_glass 3
fill ~64~48~11 ~69~48~11 minecraft:stone_block_slab 14
fill ~64~49~11 ~67~49~11 minecraft:sea_lantern
fill ~64~50~11 ~69~50~11 minecraft:stone_block_slab 6
fill ~68~49~11 ~68~49~13 minecraft:concrete 0
setblock ~70~48~11 minecraft:stone_block_slab 8
setblock ~70~50~11 minecraft:stone_block_slab 0
fill ~71~48~11 ~71~49~13 minecraft:iron_block
setblock ~71~50~11 minecraft:iron_block
setblock ~72~48~11 minecraft:stone_block_slab 8
setblock ~72~50~11 minecraft:stone_block_slab 0
fill ~73~48~11 ~78~48~11 minecraft:stone_block_slab 14
fill ~73~50~11 ~78~50~11 minecraft:stone_block_slab 6
fill ~74~49~11 ~74~49~13 minecraft:concrete 0
fill ~75~49~11 ~78~49~11 minecraft:sea_lantern
fill ~79~49~11 ~92~49~11 minecraft:stained_glass 3
fill ~48~49~12 ~57~49~12 minecraft:stained_glass 3
fill ~58~48~12 ~63~48~12 minecraft:stone_block_slab 14
fill ~58~49~12 ~63~49~12 minecraft:sea_lantern
fill ~58~50~12 ~63~50~12 minecraft:stone_block_slab 6
fill ~67~49~12 ~67~49~14 minecraft:concrete 0
setblock ~69~48~12 minecraft:stone_block_slab 8
setblock ~69~50~12 minecraft:stone_block_slab 0
fill ~70~48~12 ~70~50~14 minecraft:iron_block
setblock ~71~50~12 minecraft:glowstone
setblock ~71~51~12 minecraft:carpet 0
fill ~72~48~12 ~72~50~14 minecraft:iron_block
setblock ~73~48~12 minecraft:stone_block_slab 8
setblock ~73~50~12 minecraft:stone_block_slab 0
fill ~75~49~12 ~75~49~14 minecraft:concrete 0
fill ~79~48~12 ~84~48~12 minecraft:stone_block_slab 14
fill ~79~49~12 ~84~49~12 minecraft:sea_lantern
fill ~79~50~12 ~84~50~12 minecraft:stone_block_slab 6
fill ~85~49~12 ~94~49~12 minecraft:stained_glass 3
fill ~45~49~13 ~53~49~13 minecraft:stained_glass 3
fill ~54~48~13 ~57~48~13 minecraft:stone_block_slab 14
fill ~54~49~13 ~57~49~13 minecraft:sea_lantern
fill ~54~50~13 ~57~50~13 minecraft:stone_block_slab 6
fill ~66~49~13 ~66~49~19 minecraft:concrete 0
setblock ~68~48~13 minecraft:stone_block_slab 8
setblock ~68~50~13 minecraft:stone_block_slab 0
fill ~69~48~13 ~69~50~15 minecraft:iron_block
setblock ~71~50~13 minecraft:iron_block
fill ~73~48~13 ~73~50~15 minecraft:iron_block
setblock ~74~48~13 minecraft:stone_block_slab 8
setblock ~74~50~13 minecraft:stone_block_slab 0
fill ~76~49~13 ~76~49~19 minecraft:concrete 0
fill ~85~48~13 ~88~48~13 minecraft:stone_block_slab 14
fill ~85~49~13 ~88~49~13 minecraft:sea_lantern
fill ~85~50~13 ~88~50~13 minecraft:stone_block_slab 6
fill ~89~49~13 ~97~49~13 minecraft:stained_glass 3
fill ~43~49~14 ~50~49~14 minecraft:stained_glass 3
fill ~51~48~14 ~53~48~14 minecraft:stone_block_slab 14
fill ~51~49~14 ~53~49~14 minecraft:sea_lantern
fill ~51~50~14 ~53~50~14 minecraft:stone_block_slab 6
fill ~55~48~14 ~55~48~17 minecraft:stone_block_slab 14
fill ~55~49~14 ~55~49~17 minecraft:glowstone
fill ~55~50~14 ~55~50~17 minecraft:stone_block_slab 6
setblock ~59~49~14 minecraft:stone_block_slab 6
fill ~65~49~14 ~65~49~16 minecraft:concrete 0
setblock ~67~48~14 minecraft:stone_block_slab 8
setblock ~67~50~14 minecraft:stone_block_slab 0
fill ~68~48~14 ~68~50~20 minecraft:iron_block
setblock ~71~48~14 minecraft:gold_block
fill ~71~49~14 ~71~49~29 minecraft:iron_block
setblock ~71~50~14 minecraft:gold_block
fill ~74~48~14 ~74~50~20 minecraft:iron_block
setblock ~75~48~14 minecraft:stone_block_slab 8
setblock ~75~50~14 minecraft:stone_block_slab 0
fill ~77~49~14 ~77~49~16 minecraft:concrete 0
setblock ~83~49~14 minecraft:stone_block_slab 6
fill ~87~48~14 ~87~48~17 minecraft:stone_block_slab 14
fill ~87~49~14 ~87~49~17 minecraft:glowstone
fill ~87~50~14 ~87~50~17 minecraft:stone_block_slab 6
fill ~89~48~14 ~91~48~14 minecraft:stone_block_slab 14
fill ~89~49~14 ~91~49~14 minecraft:sea_lantern
fill ~89~50~14 ~91~50~14 minecraft:stone_block_slab 6
fill ~92~49~14 ~99~49~14 minecraft:stained_glass 3
fill ~41~49~15 ~47~49~15 minecraft:stained_glass 3
fill ~48~48~15 ~50~48~15 minecraft:stone_block_slab 14
fill ~48~49~15 ~50~49~15 minecraft:sea_lantern
fill ~48~50~15 ~50~50~15 minecraft:stone_block_slab 6
fill ~60~49~15 ~61~49~15 minecraft:stone_block_slab 6
setblock ~66~48~15 minecraft:stone_block_slab 8
setblock ~66~50~15 minecraft:stone_block_slab 0
fill ~67~48~15 ~67~50~17 minecraft:iron_block
setblock ~70~48~15 minecraft:gold_block
fill ~70~49~15 ~70~49~26 minecraft:iron_block
setblock ~70~50~15 minecraft:gold_block
setblock ~71~48~15 minecraft:concrete 4
setblock ~71~50~15 minecraft:concrete 4
setblock ~72~48~15 minecraft:gold_block
fill ~72~49~15 ~72~49~26 minecraft:iron_block
setblock ~72~50~15 minecraft:gold_block
fill ~75~48~15 ~75~50~17 minecraft:iron_block
setblock ~76~48~15 minecraft:stone_block_slab 8
setblock ~76~50~15 minecraft:stone_block_slab 0
fill ~81~49~15 ~82~49~15 minecraft:stone_block_slab 6
fill ~92~48~15 ~94~48~15 minecraft:stone_block_slab 14
fill ~92~49~15 ~94~49~15 minecraft:sea_lantern
fill ~92~50~15 ~94~50~15 minecraft:stone_block_slab 6
fill ~95~49~15 ~101~49~15 minecraft:stained_glass 3
fill ~39~49~16 ~45~49~16 minecraft:stained_glass 3
fill ~46~48~16 ~47~48~16 minecraft:stone_block_slab 14
fill ~46~49~16 ~47~49~16 minecraft:sea_lantern
fill ~46~50~16 ~47~50~16 minecraft:stone_block_slab 6
fill ~61~49~16 ~62~49~16 minecraft:stone_block_slab 6
setblock ~66~48~16 minecraft:stone_block_slab 14
setblock ~66~50~16 minecraft:stone_block_slab 6
setblock ~69~48~16 minecraft:gold_block
fill ~69~49~16 ~69~49~23 minecraft:iron_block
setblock ~69~50~16 minecraft:gold_block
setblock ~70~48~16 minecraft:concrete 4
setblock ~70~50~16 minecraft:concrete 4
setblock ~71~48~16 minecraft:glowstone
setblock ~71~50~16 minecraft:glowstone
setblock ~72~48~16 minecraft:concrete 4
setblock ~72~50~16 minecraft:concrete 4
setblock ~73~48~16 minecraft:gold_block
fill ~73~49~16 ~73~49~23 minecraft:iron_block
setblock ~73~50~16 minecraft:gold_block
setblock ~76~48~16 minecraft:stone_block_slab 14
setblock ~76~50~16 minecraft:stone_block_slab 6
fill ~80~49~16 ~81~49~16 minecraft:stone_block_slab 6
fill ~95~48~16 ~96~48~16 minecraft:stone_block_slab 14
fill ~95~49~16 ~96~49~16 minecraft:sea_lantern
fill ~95~50~16 ~96~50~16 minecraft:stone_block_slab 6
fill ~97~49~16 ~103~49~16 minecraft:stained_glass 3
fill ~38~49~17 ~43~49~17 minecraft:stained_glass 3
fill ~44~48~17 ~45~48~17 minecraft:stone_block_slab 14
fill ~44~49~17 ~45~49~17 minecraft:sea_lantern
fill ~44~50~17 ~45~50~17 minecraft:stone_block_slab 6
fill ~62~49~17 ~63~49~23 minecraft:stone_block_slab 6
setblock ~69~48~17 minecraft:red_sandstone 0
setblock ~69~50~17 minecraft:red_sandstone 0
fill ~70~48~17 ~70~48~18 minecraft:gold_block
fill ~70~50~17 ~70~50~18 minecraft:gold_block
fill ~71~48~17 ~71~48~18 minecraft:concrete 4
fill ~71~50~17 ~71~50~18 minecraft:concrete 4
fill ~72~48~17 ~72~48~18 minecraft:gold_block
fill ~72~50~17 ~72~50~18 minecraft:gold_block
setblock ~73~48~17 minecraft:red_sandstone 0
setblock ~73~50~17 minecraft:red_sandstone 0
fill ~79~49~17 ~80~49~23 minecraft:stone_block_slab 6
fill ~97~48~17 ~98~48~17 minecraft:stone_block_slab 14
fill ~97~49~17 ~98~49~17 minecraft:sea_lantern
fill ~97~50~17 ~98~50~17 minecraft:stone_block_slab 6
fill ~99~49~17 ~104~49~17 minecraft:stained_glass 3
fill ~36~49~18 ~41~49~18 minecraft:stained_glass 3
fill ~42~48~18 ~43~48~18 minecraft:stone_block_slab 14
fill ~42~49~18 ~43~49~18 minecraft:sea_lantern
fill ~42~50~18 ~43~50~18 minecraft:stone_block_slab 6
fill ~49~49~18 ~50~49~18 minecraft:stone_block_slab 6
setblock ~53~49~18 minecraft:stone_block_slab 6
fill ~56~48~18 ~56~48~20 minecraft:stone_block_slab 14
fill ~56~49~18 ~56~49~20 minecraft:glowstone
fill ~56~50~18 ~56~50~20 minecraft:stone_block_slab 6
setblock ~59~49~18 minecraft:stone_block_slab 6
fill ~67~48~18 ~67~48~19 minecraft:stone_block_slab 14
fill ~67~49~18 ~67~49~22 minecraft:concrete 0
fill ~67~50~18 ~67~50~19 minecraft:stone_block_slab 6
fill ~69~48~18 ~69~48~23 minecraft:iron_block
setblock ~69~50~18 minecraft:glowstone
setblock ~69~51~18 minecraft:carpet 0
fill ~73~48~18 ~73~48~23 minecraft:iron_block
setblock ~73~50~18 minecraft:glowstone
setblock ~73~51~18 minecraft:carpet 0
fill ~75~48~18 ~75~48~19 minecraft:stone_block_slab 14
fill ~75~49~18 ~75~49~22 minecraft:concrete 0
fill ~75~50~18 ~75~50~19 minecraft:stone_block_slab 6
setblock ~83~49~18 minecraft:stone_block_slab 6
fill ~86~48~18 ~86~48~20 minecraft:stone_block_slab 14
fill ~86~49~18 ~86~49~20 minecraft:glowstone
fill ~86~50~18 ~86~50~20 minecraft:stone_block_slab 6
setblock ~89~49~18 minecraft:stone_block_slab 6
fill ~92~49~18 ~93~49~18 minecraft:stone_block_slab 6
fill ~99~48~18 ~100~48~18 minecraft:stone_block_slab 14
fill ~99~49~18 ~100~49~18 minecraft:sea_lantern
fill ~99~50~18 ~100~50~18 minecraft:stone_block_slab 6
fill ~101~49~18 ~106~49~18 minecraft:stained_glass 3
fill ~34~49~19 ~39~49~19 minecraft:stained_glass 3
fill ~40~48~19 ~41~48~19 minecraft:stone_block_slab 14
fill ~40~49~19 ~41~49~19 minecraft:sea_lantern
fill ~40~50~19 ~41~50~19 minecraft:stone_block_slab 6
fill ~48~49~19 ~49~49~19 minecraft:stone_block_slab 6
fill ~51~49~19 ~52~49~19 minecraft:stone_block_slab 6
fill ~60~49~19 ~60~49~20 minecraft:stone_block_slab 6
fill ~64~49~19 ~64~49~20 minecraft:stone_block_slab 6
fill ~69~50~19 ~69~50~23 minecraft:iron_block
fill ~70~48~19 ~70~48~20 minecraft:red_sandstone 0
fill ~70~50~19 ~70~50~20 minecraft:red_sandstone 0
fill ~71~48~19 ~71~48~21 minecraft:gold_block
fill ~71~50~19 ~71~50~21 minecraft:gold_block
fill ~72~48~19 ~72~48~20 minecraft:red_sandstone 0
fill ~72~50~19 ~72~50~20 minecraft:red_sandstone 0
fill ~73~50~19 ~73~50~23 minecraft:iron_block
fill ~78~49~19 ~78~49~20 minecraft:stone_block_slab 6
fill ~82~49~19 ~82~49~20 minecraft:stone_block_slab 6
fill ~90~49~19 ~91~49~19 minecraft:stone_block_slab 6
fill ~93~49~19 ~94~49~19 minecraft:stone_block_slab 6
fill ~101~48~19 ~102~48~19 minecraft:stone_block_slab 14
fill ~101~49~19 ~102~49~19 minecraft:sea_lantern
fill ~101~50~19 ~102~50~19 minecraft:stone_block_slab 6
fill ~103~49~19 ~108~49~19 minecraft:stained_glass 3
fill ~33~49~20 ~37~49~20 minecraft:stained_glass 3
fill ~38~48~20 ~39~48~20 minecraft:stone_block_slab 14
fill ~38~49~20 ~39~49~20 minecraft:sea_lantern
fill ~38~50~20 ~39~50~20 minecraft:stone_block_slab 6
fill ~47~49~20 ~48~49~21 minecraft:stone_block_slab 6
fill ~61~49~20 ~61~49~23 minecraft:stone_block_slab 6
fill ~81~49~20 ~81~49~23 minecraft:stone_block_slab 6
fill ~94~49~20 ~95~49~21 minecraft:stone_block_slab 6
fill ~103~48~20 ~104~48~20 minecraft:stone_block_slab 14
fill ~103~49~20 ~104~49~20 minecraft:sea_lantern
fill ~103~50~20 ~104~50~20 minecraft:stone_block_slab 6
fill ~105~49~20 ~109~49~20 minecraft:stained_glass 3
fill ~32~49~21 ~36~49~21 minecraft:stained_glass 3
setblock ~37~48~21 minecraft:stone_block_slab 14
setblock ~37~49~21 minecraft:sea_lantern
setblock ~37~50~21 minecraft:stone_block_slab 6
fill ~41~49~21 ~43~49~22 minecraft:stone_block_slab 6
fill ~49~49~21 ~49~49~23 minecraft:stone_block_slab 6
fill ~57~48~21 ~57~48~24 minecraft:stone_block_slab 14
fill ~57~49~21 ~57~49~24 minecraft:glowstone
fill ~57~50~21 ~57~50~24 minecraft:stone_block_slab 6
fill ~68~48~21 ~68~48~22 minecraft:stone_block_slab 14
fill ~68~49~21 ~68~49~25 minecraft:concrete 0
fill ~68~50~21 ~68~50~22 minecraft:stone_block_slab 6
fill ~70~48~21 ~70~48~26 minecraft:iron_block
setblock ~70~50~21 minecraft:glowstone
setblock ~70~51~21 minecraft:carpet 0
fill ~72~48~21 ~72~48~26 minecraft:iron_block
setblock ~72~50~21 minecraft:glowstone
setblock ~72~51~21 minecraft:carpet 0
fill ~74~48~21 ~74~48~22 minecraft:stone_block_slab 14
fill ~74~49~21 ~74~49~25 minecraft:concrete 0
fill ~74~50~21 ~74~50~22 minecraft:stone_block_slab 6
fill ~85~48~21 ~85~48~24 minecraft:stone_block_slab 14
fill ~85~49~21 ~85~49~24 minecraft:glowstone
fill ~85~50~21 ~85~50~24 minecraft:stone_block_slab 6
fill ~93~49~21 ~93~49~23 minecraft:stone_block_slab 6
fill ~99~49~21 ~101~49~22 minecraft:stone_block_slab 6
setblock ~105~48~21 minecraft:stone_block_slab 14
setblock ~105~49~21 minecraft:sea_lantern
setblock ~105~50~21 minecraft:stone_block_slab 6
fill ~106~49~21 ~110~49~21 minecraft:stained_glass 3
fill ~30~49~22 ~34~49~22 minecraft:stained_glass 3
fill ~35~48~22 ~36~48~22 minecraft:stone_block_slab 14
fill ~35~49~22 ~36~49~22 minecraft:sea_lantern
fill ~35~50~22 ~36~50~22 minecraft:stone_block_slab 6
fill ~40~49~22 ~40~49~24 minecraft:stone_block_slab 6
fill ~44~49~22 ~44~49~23 minecraft:stone_block_slab 6
setblock ~48~49~22 minecraft:stone_block_slab 6
fill ~50~49~22 ~52~49~23 minecraft:stone_block_slab 6
fill ~60~49~22 ~60~49~23 minecraft:stone_block_slab 6
fill ~64~49~22 ~66~49~22 minecraft:stone_block_slab 6
fill ~70~50~22 ~70~50~26 minecraft:iron_block
fill ~71~48~22 ~71~48~24 minecraft:red_sandstone 0
fill ~71~50~22 ~71~50~24 minecraft:red_sandstone 0
fill ~72~50~22 ~72~50~26 minecraft:iron_block
fill ~76~49~22 ~78~49~22 minecraft:stone_block_slab 6
fill ~82~49~22 ~82~49~23 minecraft:stone_block_slab 6
fill ~90~49~22 ~92~49~23 minecraft:stone_block_slab 6
setblock ~94~49~22 minecraft:stone_block_slab 6
fill ~98~49~22 ~98~49~23 minecraft:stone_block_slab 6
fill ~102~49~22 ~102~49~24 minecraft:stone_block_slab 6
fill ~106~48~22 ~107~48~22 minecraft:stone_block_slab 14
fill ~106~49~22 ~107~49~22 minecraft:sea_lantern
fill ~106~50~22 ~107~50~22 minecraft:stone_block_slab 6
fill ~108~49~22 ~112~49~22 minecraft:stained_glass 3
fill ~29~49~23 ~33~49~23 minecraft:stained_glass 3
setblock ~34~48~23 minecraft:stone_block_slab 14
setblock ~34~49~23 minecraft:sea_lantern
setblock ~34~50~23 minecraft:stone_block_slab 6
fill ~37~48~23 ~37~48~24 minecraft:stone_block_slab 14
fill ~37~49~23 ~37~49~24 minecraft:glowstone
fill ~37~50~23 ~37~50~24 minecraft:stone_block_slab 6
fill ~41~49~23 ~41~49~25 minecraft:stone_block_slab 6
fill ~53~49~23 ~54~49~25 minecraft:stone_block_slab 6
setblock ~59~49~23 minecraft:stone_block_slab 6
fill ~64~49~23 ~67~49~23 minecraft:stained_glass 4
fill ~75~49~23 ~78~49~23 minecraft:stained_glass 4
setblock ~83~49~23 minecraft:stone_block_slab 6
fill ~88~49~23 ~89~49~25 minecraft:stone_block_slab 6
fill ~101~49~23 ~101~49~25 minecraft:stone_block_slab 6
fill ~105~48~23 ~105~48~24 minecraft:stone_block_slab 14
fill ~105~49~23 ~105~49~24 minecraft:glowstone
fill ~105~50~23 ~105~50~24 minecraft:stone_block_slab 6
setblock ~108~48~23 minecraft:stone_block_slab 14
setblock ~108~49~23 minecraft:sea_lantern
setblock ~108~50~23 minecraft:stone_block_slab 6
fill ~109~49~23 ~113~49~23 minecraft:stained_glass 3
fill ~28~49~24 ~32~49~24 minecraft:stained_glass 3
setblock ~33~48~24 minecraft:stone_block_slab 14
setblock ~33~49~24 minecraft:sea_lantern
setblock ~33~50~24 minecraft:stone_block_slab 6
fill ~45~49~24 ~46~49~24 minecraft:stone_block_slab 6
fill ~51~49~24 ~52~49~24 minecraft:stone_block_slab 6
fill ~55~49~24 ~56~49~24 minecraft:stone_block_slab 6
setblock ~58~49~24 minecraft:stone_block_slab 6
fill ~59~49~24 ~63~49~24 minecraft:stained_glass 4
fill ~64~49~24 ~67~49~29 minecraft:stained_glass 0
fill ~69~48~24 ~69~48~25 minecraft:stone_block_slab 14
fill ~69~49~24 ~69~49~28 minecraft:concrete 0
fill ~69~50~24 ~69~50~25 minecraft:stone_block_slab 6
fill ~73~48~24 ~73~48~25 minecraft:stone_block_slab 14
fill ~73~49~24 ~73~49~28 minecraft:concrete 0
fill ~73~50~24 ~73~50~25 minecraft:stone_block_slab 6
fill ~75~49~24 ~78~49~29 minecraft:stained_glass 0
fill ~79~49~24 ~83~49~24 minecraft:stained_glass 4
setblock ~84~49~24 minecraft:stone_block_slab 6
fill ~86~49~24 ~87~49~24 minecraft:stone_block_slab 6
fill ~90~49~24 ~91~49~24 minecraft:stone_block_slab 6
fill ~96~49~24 ~97~49~24 minecraft:stone_block_slab 6
setblock ~109~48~24 minecraft:stone_block_slab 14
setblock ~109~49~24 minecraft:sea_lantern
setblock ~109~50~24 minecraft:stone_block_slab 6
fill ~110~49~24 ~114~49~24 minecraft:stained_glass 3
fill ~27~49~25 ~30~49~25 minecraft:stained_glass 3
fill ~31~48~25 ~32~48~25 minecraft:stone_block_slab 14
fill ~31~49~25 ~32~49~25 minecraft:sea_lantern
fill ~31~50~25 ~32~50~25 minecraft:stone_block_slab 6
setblock ~38~48~25 minecraft:stone_block_slab 14
setblock ~38~49~25 minecraft:glowstone
setblock ~38~50~25 minecraft:stone_block_slab 6
fill ~42~49~25 ~43~49~26 minecraft:stone_block_slab 6
fill ~52~49~25 ~52~49~26 minecraft:stone_block_slab 6
setblock ~55~49~25 minecraft:stone_block_slab 6
fill ~56~49~25 ~57~49~25 minecraft:stained_glass 4
fill ~58~48~25 ~58~48~27 minecraft:stone_block_slab 14
fill ~58~49~25 ~58~49~27 minecraft:glowstone
fill ~58~50~25 ~58~50~27 minecraft:stone_block_slab 6
fill ~59~49~25 ~63~49~27 minecraft:stained_glass 0
fill ~71~48~25 ~71~48~29 minecraft:iron_block
setblock ~71~50~25 minecraft:glowstone
setblock ~71~51~25 minecraft:carpet 0
fill ~79~49~25 ~83~49~27 minecraft:stained_glass 0
fill ~84~48~25 ~84~48~27 minecraft:stone_block_slab 14
fill ~84~49~25 ~84~49~27 minecraft:glowstone
fill ~84~50~25 ~84~50~27 minecraft:stone_block_slab 6
fill ~85~49~25 ~86~49~25 minecraft:stained_glass 4
setblock ~87~49~25 minecraft:stone_block_slab 6
fill ~90~49~25 ~90~49~26 minecraft:stone_block_slab 6
fill ~99~49~25 ~100~49~26 minecraft:stone_block_slab 6
setblock ~104~48~25 minecraft:stone_block_slab 14
setblock ~104~49~25 minecraft:glowstone
setblock ~104~50~25 minecraft:stone_block_slab 6
fill ~110~48~25 ~111~48~25 minecraft:stone_block_slab 14
fill ~110~49~25 ~111~49~25 minecraft:sea_lantern
fill ~110~50~25 ~111~50~25 minecraft:stone_block_slab 6
fill ~112~49~25 ~115~49~25 minecraft:stained_glass 3
fill ~26~49~26 ~29~49~26 minecraft:stained_glass 3
setblock ~30~48~26 minecraft:stone_block_slab 14
setblock ~30~49~26 minecraft:sea_lantern
setblock ~30~50~26 minecraft:stone_block_slab 6
fill ~39~48~26 ~39~48~27 minecraft:stone_block_slab 14
fill ~39~49~26 ~39~49~27 minecraft:glowstone
fill ~39~50~26 ~39~50~27 minecraft:stone_block_slab 6
fill ~44~49~26 ~44~49~28 minecraft:stone_block_slab 6
setblock ~51~49~26 minecraft:stone_block_slab 6
fill ~53~49~26 ~55~49~26 minecraft:stained_glass 4
fill ~56~49~26 ~57~49~31 minecraft:stained_glass 0
fill ~68~49~26 ~68~49~29 minecraft:stained_glass 0
fill ~71~50~26 ~71~50~29 minecraft:iron_block
fill ~74~49~26 ~74~49~29 minecraft:stained_glass 0
fill ~85~49~26 ~86~49~31 minecraft:stained_glass 0
fill ~87~49~26 ~89~49~26 minecraft:stained_glass 4
setblock ~91~49~26 minecraft:stone_block_slab 6
fill ~98~49~26 ~98~49~28 minecraft:stone_block_slab 6
fill ~103~48~26 ~103~48~27 minecraft:stone_block_slab 14
fill ~103~49~26 ~103~49~27 minecraft:glowstone
fill ~103~50~26 ~103~50~27 minecraft:stone_block_slab 6
setblock ~112~48~26 minecraft:stone_block_slab 14
setblock ~112~49~26 minecraft:sea_lantern
setblock ~112~50~26 minecraft:stone_block_slab 6
fill ~113~49~26 ~116~49~26 minecraft:stained_glass 3
fill ~25~49~27 ~28~49~27 minecraft:stained_glass 3
setblock ~29~48~27 minecraft:stone_block_slab 14
setblock ~29~49~27 minecraft:sea_lantern
setblock ~29~50~27 minecraft:stone_block_slab 6
fill ~35~49~27 ~36~49~28 minecraft:stone_block_slab 6
setblock ~43~49~27 minecraft:stone_block_slab 6
fill ~45~49~27 ~47~49~28 minecraft:stone_block_slab 6
fill ~49~49~27 ~50~49~27 minecraft:stone_block_slab 6
fill ~51~49~27 ~52~49~27 minecraft:stained_glass 4
fill ~53~49~27 ~55~49~32 minecraft:stained_glass 0
fill ~70~48~27 ~70~48~28 minecraft:stone_block_slab 14
fill ~70~49~27 ~70~49~31 minecraft:concrete 0
fill ~70~50~27 ~70~50~28 minecraft:stone_block_slab 6
fill ~72~48~27 ~72~48~28 minecraft:stone_block_slab 14
fill ~72~49~27 ~72~49~31 minecraft:concrete 0
fill ~72~50~27 ~72~50~28 minecraft:stone_block_slab 6
fill ~87~49~27 ~89~49~32 minecraft:stained_glass 0
fill ~90~49~27 ~91~49~27 minecraft:stained_glass 4
fill ~92~49~27 ~93~49~27 minecraft:stone_block_slab 6
fill ~95~49~27 ~97~49~28 minecraft:stone_block_slab 6
setblock ~99~49~27 minecraft:stone_block_slab 6
fill ~106~49~27 ~107~49~28 minecraft:stone_block_slab 6
setblock ~113~48~27 minecraft:stone_block_slab 14
setblock ~113~49~27 minecraft:sea_lantern
setblock ~113~50~27 minecraft:stone_block_slab 6
fill ~114~49~27 ~117~49~27 minecraft:stained_glass 3
fill ~24~49~28 ~27~49~28 minecraft:stained_glass 3
setblock ~28~48~28 minecraft:stone_block_slab 14
setblock ~28~49~28 minecraft:sea_lantern
setblock ~28~50~28 minecraft:stone_block_slab 6
setblock ~32~49~28 minecraft:stone_block_slab 6
fill ~34~49~28 ~34~49~30 minecraft:stone_block_slab 6
fill ~37~49~28 ~37~49~35 minecraft:stone_block_slab 6
setblock ~40~48~28 minecraft:stone_block_slab 14
setblock ~40~49~28 minecraft:glowstone
setblock ~40~50~28 minecraft:stone_block_slab 6
setblock ~48~49~28 minecraft:stone_block_slab 6
fill ~49~49~28 ~50~49~28 minecraft:stained_glass 4
fill ~51~49~28 ~52~49~33 minecraft:stained_glass 0
fill ~58~49~28 ~58~49~31 minecraft:stained_glass 0
fill ~59~48~28 ~59~48~31 minecraft:stone_block_slab 14
fill ~59~49~28 ~59~49~31 minecraft:glowstone
fill ~59~50~28 ~59~50~31 minecraft:stone_block_slab 6
fill ~60~49~28 ~63~49~30 minecraft:stained_glass 0
fill ~79~49~28 ~82~49~30 minecraft:stained_glass 0
fill ~83~48~28 ~83~48~31 minecraft:stone_block_slab 14
fill ~83~49~28 ~83~49~31 minecraft:glowstone
fill ~83~50~28 ~83~50~31 minecraft:stone_block_slab 6
fill ~84~49~28 ~84~49~31 minecraft:stained_glass 0
fill ~90~49~28 ~91~49~33 minecraft:stained_glass 0
fill ~92~49~28 ~93~49~28 minecraft:stained_glass 4
setblock ~94~49~28 minecraft:stone_block_slab 6
setblock ~102~48~28 minecraft:stone_block_slab 14
setblock ~102~49~28 minecraft:glowstone
setblock ~102~50~28 minecraft:stone_block_slab 6
fill ~105~49~28 ~105~49~35 minecraft:stone_block_slab 6
fill ~108~49~28 ~108~49~30 minecraft:stone_block_slab 6
setblock ~110~49~28 minecraft:stone_block_slab 6
setblock ~114~48~28 minecraft:stone_block_slab 14
setblock ~114~49~28 minecraft:sea_lantern
setblock ~114~50~28 minecraft:stone_block_slab 6
fill ~115~49~28 ~118~49~28 minecraft:stained_glass 3
fill ~23~49~29 ~26~49~29 minecraft:stained_glass 3
setblock ~27~48~29 minecraft:stone_block_slab 14
setblock ~27~49~29 minecraft:sea_lantern
setblock ~27~50~29 minecraft:stone_block_slab 6
fill ~31~49~29 ~31~49~30 minecraft:stone_block_slab 6
setblock ~36~49~29 minecraft:stone_block_slab 6
fill ~38~49~29 ~38~49~32 minecraft:stone_block_slab 6
fill ~41~48~29 ~41~48~30 minecraft:stone_block_slab 14
fill ~41~49~29 ~41~49~30 minecraft:glowstone
fill ~41~50~29 ~41~50~30 minecraft:stone_block_slab 6
fill ~45~49~29 ~46~49~29 minecraft:stone_block_slab 6
fill ~47~49~29 ~48~49~29 minecraft:stained_glass 4
fill ~49~49~29 ~50~49~34 minecraft:stained_glass 0
setblock ~69~49~29 minecraft:stained_glass 0
setblock ~73~49~29 minecraft:stained_glass 0
fill ~92~49~29 ~93~49~34 minecraft:stained_glass 0
fill ~94~49~29 ~95~49~29 minecraft:stained_glass 4
fill ~96~49~29 ~97~49~29 minecraft:stone_block_slab 6
fill ~101~48~29 ~101~48~30 minecraft:stone_block_slab 14
fill ~101~49~29 ~101~49~30 minecraft:glowstone
fill ~101~50~29 ~101~50~30 minecraft:stone_block_slab 6
fill ~104~49~29 ~104~49~32 minecraft:stone_block_slab 6
setblock ~106~49~29 minecraft:stone_block_slab 6
fill ~111~49~29 ~111~49~30 minecraft:stone_block_slab 6
setblock ~115~48~29 minecraft:stone_block_slab 14
setblock ~115~49~29 minecraft:sea_lantern
setblock ~115~50~29 minecraft:stone_block_slab 6
fill ~116~49~29 ~119~49~29 minecraft:stained_glass 3
fill ~22~49~30 ~25~49~30 minecraft:stained_glass 3
setblock ~26~48~30 minecraft:stone_block_slab 14
setblock ~26~49~30 minecraft:sea_lantern
setblock ~26~50~30 minecraft:stone_block_slab 6
fill ~29~49~30 ~30~49~32 minecraft:stone_block_slab 6
fill ~43~49~30 ~44~49~30 minecraft:stone_block_slab 6
fill ~45~49~30 ~46~49~30 minecraft:stained_glass 4
fill ~47~49~30 ~48~49~36 minecraft:stained_glass 0
setblock ~64~49~30 minecraft:stained_glass 0
fill ~65~49~30 ~69~49~30 minecraft:stained_glass 4
fill ~71~48~30 ~71~48~31 minecraft:stone_block_slab 14
fill ~71~49~30 ~71~49~34 minecraft:concrete 0
fill ~71~50~30 ~71~50~31 minecraft:stone_block_slab 6
fill ~73~49~30 ~77~49~30 minecraft:stained_glass 4
setblock ~78~49~30 minecraft:stained_glass 0
fill ~94~49~30 ~95~49~36 minecraft:stained_glass 0
fill ~96~49~30 ~97~49~30 minecraft:stained_glass 4
fill ~98~49~30 ~99~49~30 minecraft:stone_block_slab 6
fill ~112~49~30 ~113~49~32 minecraft:stone_block_slab 6
setblock ~116~48~30 minecraft:stone_block_slab 14
setblock ~116~49~30 minecraft:sea_lantern
setblock ~116~50~30 minecraft:stone_block_slab 6
fill ~117~49~30 ~120~49~30 minecraft:stained_glass 3
fill ~21~49~31 ~24~49~31 minecraft:stained_glass 3
setblock ~25~48~31 minecraft:stone_block_slab 14
setblock ~25~49~31 minecraft:sea_lantern
setblock ~25~50~31 minecraft:stone_block_slab 6
fill ~28~49~31 ~28~49~33 minecraft:stone_block_slab 6
setblock ~33~49~31 minecraft:stone_block_slab 6
setblock ~42~48~31 minecraft:stone_block_slab 14
setblock ~42~49~31 minecraft:glowstone
setblock ~42~50~31 minecraft:stone_block_slab 6
fill ~43~49~31 ~44~49~31 minecraft:stained_glass 4
fill ~45~49~31 ~46~49~34 minecraft:stained_glass 0
fill ~60~49~31 ~64~49~31 minecraft:stained_glass 4
fill ~78~49~31 ~82~49~31 minecraft:stained_glass 4
fill ~96~49~31 ~97~49~34 minecraft:stained_glass 0
fill ~98~49~31 ~99~49~31 minecraft:stained_glass 4
setblock ~100~48~31 minecraft:stone_block_slab 14
setblock ~100~49~31 minecraft:glowstone
setblock ~100~50~31 minecraft:stone_block_slab 6
setblock ~109~49~31 minecraft:stone_block_slab 6
fill ~114~49~31 ~114~49~33 minecraft:stone_block_slab 6
setblock ~117~48~31 minecraft:stone_block_slab 14
setblock ~117~49~31 minecraft:sea_lantern
setblock ~117~50~31 minecraft:stone_block_slab 6
fill ~118~49~31 ~121~49~31 minecraft:stained_glass 3
fill ~20~49~32 ~23~49~32 minecraft:stained_glass 3
setblock ~24~48~32 minecraft:stone_block_slab 14
setblock ~24~49~32 minecraft:sea_lantern
setblock ~24~50~32 minecraft:stone_block_slab 6
fill ~36~49~32 ~36~49~36 minecraft:stone_block_slab 6
setblock ~41~49~32 minecraft:stone_block_slab 6
setblock ~42~49~32 minecraft:stained_glass 4
fill ~43~48~32 ~43~48~33 minecraft:stone_block_slab 14
fill ~43~49~32 ~43~49~33 minecraft:glowstone
fill ~43~50~32 ~43~50~33 minecraft:stone_block_slab 6
fill ~44~49~32 ~44~49~33 minecraft:stained_glass 0
setblock ~56~49~32 minecraft:stained_glass 0
fill ~57~49~32 ~59~49~32 minecraft:stained_glass 4
fill ~60~48~32 ~60~48~34 minecraft:stone_block_slab 14
fill ~60~49~32 ~60~49~34 minecraft:glowstone
fill ~60~50~32 ~60~50~34 minecraft:stone_block_slab 6
fill ~82~48~32 ~82~48~34 minecraft:stone_block_slab 14
fill ~82~49~32 ~82~49~34 minecraft:glowstone
fill ~82~50~32 ~82~50~34 minecraft:stone_block_slab 6
fill ~83~49~32 ~85~49~32 minecraft:stained_glass 4
setblock ~86~49~32 minecraft:stained_glass 0
fill ~98~49~32 ~98~49~33 minecraft:stained_glass 0
fill ~99~48~32 ~99~48~33 minecraft:stone_block_slab 14
fill ~99~49~32 ~99~49~33 minecraft:glowstone
fill ~99~50~32 ~99~50~33 minecraft:stone_block_slab 6
setblock ~100~49~32 minecraft:stained_glass 4
setblock ~101~49~32 minecraft:stone_block_slab 6
fill ~106~49~32 ~106~49~36 minecraft:stone_block_slab 6
setblock ~118~48~32 minecraft:stone_block_slab 14
setblock ~118~49~32 minecraft:sea_lantern
setblock ~118~50~32 minecraft:stone_block_slab 6
fill ~119~49~32 ~122~49~32 minecraft:stained_glass 3
fill ~20~49~33 ~22~49~34 minecraft:stained_glass 3
fill ~23~48~33 ~23~48~34 minecraft:stone_block_slab 14
fill ~23~49~33 ~23~49~34 minecraft:sea_lantern
fill ~23~50~33 ~23~50~34 minecraft:stone_block_slab 6
setblock ~27~49~33 minecraft:stone_block_slab 6
setblock ~31~49~33 minecraft:stone_block_slab 6
fill ~39~49~33 ~40~49~33 minecraft:stone_block_slab 6
setblock ~41~49~33 minecraft:stained_glass 4
fill ~42~49~33 ~42~49~40 minecraft:stained_glass 0
setblock ~53~49~33 minecraft:stained_glass 0
fill ~54~49~33 ~56~49~33 minecraft:stained_glass 4
fill ~86~49~33 ~88~49~33 minecraft:stained_glass 4
setblock ~89~49~33 minecraft:stained_glass 0
fill ~100~49~33 ~100~49~40 minecraft:stained_glass 0
setblock ~101~49~33 minecraft:stained_glass 4
fill ~102~49~33 ~103~49~33 minecraft:stone_block_slab 6
setblock ~111~49~33 minecraft:stone_block_slab 6
setblock ~115~49~33 minecraft:stone_block_slab 6
fill ~119~48~33 ~119~48~34 minecraft:stone_block_slab 14
fill ~119~49~33 ~119~49~34 minecraft:sea_lantern
fill ~119~50~33 ~119~50~34 minecraft:stone_block_slab 6
fill ~120~49~33 ~122~49~34 minecraft:stained_glass 3
fill ~19~49~34 ~19~49~38 minecraft:stained_glass 3
setblock ~26~49~34 minecraft:stone_block_slab 6
fill ~32~49~34 ~35~49~34 minecraft:stone_block_slab 6
setblock ~38~49~34 minecraft:stone_block_slab 6
fill ~39~49~34 ~40~49~34 minecraft:stained_glass 4
fill ~41~49~34 ~41~49~41 minecraft:stained_glass 0
fill ~43~49~34 ~43~49~39 minecraft:stained_glass 0
setblock ~44~48~34 minecraft:stone_block_slab 14
setblock ~44~49~34 minecraft:glowstone
setblock ~44~50~34 minecraft:stone_block_slab 6
setblock ~51~49~34 minecraft:stained_glass 0
fill ~52~49~34 ~53~49~34 minecraft:stained_glass 4
fill ~89~49~34 ~90~49~34 minecraft:stained_glass 4
setblock ~91~49~34 minecraft:stained_glass 0
setblock ~98~48~34 minecraft:stone_block_slab 14
setblock ~98~49~34 minecraft:glowstone
setblock ~98~50~34 minecraft:stone_block_slab 6
fill ~99~49~34 ~99~49~39 minecraft:stained_glass 0
fill ~101~49~34 ~101~49~41 minecraft:stained_glass 0
fill ~102~49~34 ~103~49~34 minecraft:stained_glass 4
setblock ~104~49~34 minecraft:stone_block_slab 6
fill ~107~49~34 ~110~49~34 minecraft:stone_block_slab 6
setblock ~116~49~34 minecraft:stone_block_slab 6
fill ~123~49~34 ~123~49~38 minecraft:stained_glass 3
fill ~18~49~35 ~18~49~39 minecraft:stained_glass 3
fill ~20~49~35 ~21~49~35 minecraft:stained_glass 3
setblock ~22~48~35 minecraft:stone_block_slab 14
setblock ~22~49~35 minecraft:sea_lantern
setblock ~22~50~35 minecraft:stone_block_slab 6
setblock ~29~49~35 minecraft:stone_block_slab 6
fill ~32~49~35 ~32~49~40 minecraft:stone_block_slab 6
fill ~34~49~35 ~35~49~35 minecraft:stone_block_slab 6
setblock ~38~49~35 minecraft:stained_glass 4
fill ~39~49~35 ~40~49~42 minecraft:stained_glass 0
fill ~44~49~35 ~44~49~38 minecraft:stained_glass 0
fill ~45~48~35 ~45~48~36 minecraft:stone_block_slab 14
fill ~45~49~35 ~45~49~36 minecraft:glowstone
fill ~45~50~35 ~45~50~36 minecraft:stone_block_slab 6
fill ~46~49~35 ~46~49~36 minecraft:stained_glass 0
setblock ~49~49~35 minecraft:stained_glass 0
fill ~50~49~35 ~51~49~35 minecraft:stained_glass 4
setblock ~71~49~35 minecraft:sea_lantern
fill ~91~49~35 ~92~49~35 minecraft:stained_glass 4
setblock ~93~49~35 minecraft:stained_glass 0
fill ~96~49~35 ~96~49~36 minecraft:stained_glass 0
fill ~97~48~35 ~97~48~36 minecraft:stone_block_slab 14
fill ~97~49~35 ~97~49~36 minecraft:glowstone
fill ~97~50~35 ~97~50~36 minecraft:stone_block_slab 6
fill ~98~49~35 ~98~49~38 minecraft:stained_glass 0
fill ~102~49~35 ~103~49~42 minecraft:stained_glass 0
setblock ~104~49~35 minecraft:stained_glass 4
fill ~107~49~35 ~108~49~35 minecraft:stone_block_slab 6
fill ~110~49~35 ~110~49~40 minecraft:stone_block_slab 6
setblock ~113~49~35 minecraft:stone_block_slab 6
setblock ~120~48~35 minecraft:stone_block_slab 14
setblock ~120~49~35 minecraft:sea_lantern
setblock ~120~50~35 minecraft:stone_block_slab 6
fill ~121~49~35 ~122~49~35 minecraft:stained_glass 3
fill ~124~49~35 ~124~49~39 minecraft:stained_glass 3
fill ~17~49~36 ~17~49~41 minecraft:stained_glass 3
setblock ~20~49~36 minecraft:stained_glass 3
setblock ~21~48~36 minecraft:stone_block_slab 14
setblock ~21~49~36 minecraft:sea_lantern
setblock ~21~50~36 minecraft:stone_block_slab 6
fill ~26~49~36 ~28~49~36 minecraft:stone_block_slab 6
fill ~33~49~36 ~33~49~39 minecraft:stone_block_slab 6
setblock ~37~49~36 minecraft:stained_glass 4
fill ~38~49~36 ~38~49~44 minecraft:stained_glass 0
setblock ~49~49~36 minecraft:stained_glass 4
setblock ~93~49~36 minecraft:stained_glass 4
fill ~104~49~36 ~104~49~44 minecraft:stained_glass 0
setblock ~105~49~36 minecraft:stained_glass 4
fill ~109~49~36 ~109~49~39 minecraft:stone_block_slab 6
fill ~114~49~36 ~116~49~36 minecraft:stone_block_slab 6
setblock ~121~48~36 minecraft:stone_block_slab 14
setblock ~121~49~36 minecraft:sea_lantern
setblock ~121~50~36 minecraft:stone_block_slab 6
setblock ~122~49~36 minecraft:stained_glass 3
fill ~125~49~36 ~125~49~41 minecraft:stained_glass 3
fill ~20~48~37 ~20~48~38 minecraft:stone_block_slab 14
fill ~20~49~37 ~20~49~38 minecraft:sea_lantern
fill ~20~50~37 ~20~50~38 minecraft:stone_block_slab 6
fill ~25~49~37 ~26~49~38 minecraft:stone_block_slab 6
setblock ~35~49~37 minecraft:stone_block_slab 6
setblock ~36~49~37 minecraft:stained_glass 4
fill ~37~49~37 ~37~49~45 minecraft:stained_glass 0
fill ~45~49~37 ~45~49~38 minecraft:stained_glass 0
setblock ~46~48~37 minecraft:stone_block_slab 14
setblock ~46~49~37 minecraft:glowstone
setblock ~46~50~37 minecraft:stone_block_slab 6
fill ~47~49~37 ~48~49~37 minecraft:stained_glass 4
fill ~94~49~37 ~95~49~37 minecraft:stained_glass 4
setblock ~96~48~37 minecraft:stone_block_slab 14
setblock ~96~49~37 minecraft:glowstone
setblock ~96~50~37 minecraft:stone_block_slab 6
fill ~97~49~37 ~97~49~38 minecraft:stained_glass 0
fill ~105~49~37 ~105~49~45 minecraft:stained_glass 0
setblock ~106~49~37 minecraft:stained_glass 4
setblock ~107~49~37 minecraft:stone_block_slab 6
fill ~116~49~37 ~117~49~38 minecraft:stone_block_slab 6
fill ~122~48~37 ~122~48~38 minecraft:stone_block_slab 14
fill ~122~49~37 ~122~49~38 minecraft:sea_lantern
fill ~122~50~37 ~122~50~38 minecraft:stone_block_slab 6
fill ~16~49~38 ~16~49~43 minecraft:stained_glass 3
fill ~27~49~38 ~27~49~40 minecraft:stone_block_slab 6
fill ~30~49~38 ~31~49~39 minecraft:stone_block_slab 6
setblock ~34~49~38 minecraft:stone_block_slab 6
setblock ~35~49~38 minecraft:stained_glass 4
fill ~36~49~38 ~36~49~47 minecraft:stained_glass 0
setblock ~46~49~38 minecraft:stained_glass 4
fill ~47~48~38 ~47~48~39 minecraft:stone_block_slab 14
fill ~47~49~38 ~47~49~39 minecraft:glowstone
fill ~47~50~38 ~47~50~39 minecraft:stone_block_slab 6
fill ~95~48~38 ~95~48~39 minecraft:stone_block_slab 14
fill ~95~49~38 ~95~49~39 minecraft:glowstone
fill ~95~50~38 ~95~50~39 minecraft:stone_block_slab 6
setblock ~96~49~38 minecraft:stained_glass 4
fill ~106~49~38 ~106~49~47 minecraft:stained_glass 0
setblock ~107~49~38 minecraft:stained_glass 4
setblock ~108~49~38 minecraft:stone_block_slab 6
fill ~111~49~38 ~112~49~39 minecraft:stone_block_slab 6
fill ~115~49~38 ~115~49~40 minecraft:stone_block_slab 6
fill ~126~49~38 ~126~49~43 minecraft:stained_glass 3
setblock ~19~48~39 minecraft:stone_block_slab 14
setblock ~19~49~39 minecraft:sea_lantern
setblock ~19~50~39 minecraft:stone_block_slab 6
fill ~21~48~39 ~22~48~39 minecraft:stone_block_slab 14
fill ~21~49~39 ~22~49~39 minecraft:glowstone
fill ~21~50~39 ~22~50~39 minecraft:stone_block_slab 6
setblock ~26~49~39 minecraft:stone_block_slab 6
fill ~28~49~39 ~29~49~40 minecraft:stone_block_slab 6
setblock ~34~49~39 minecraft:stained_glass 4
fill ~35~49~39 ~35~49~47 minecraft:stained_glass 0
fill ~44~49~39 ~45~49~39 minecraft:stained_glass 4
fill ~97~49~39 ~98~49~39 minecraft:stained_glass 4
fill ~107~49~39 ~107~49~47 minecraft:stained_glass 0
setblock ~108~49~39 minecraft:stained_glass 4
fill ~113~49~39 ~114~49~40 minecraft:stone_block_slab 6
setblock ~116~49~39 minecraft:stone_block_slab 6
fill ~120~48~39 ~121~48~39 minecraft:stone_block_slab 14
fill ~120~49~39 ~121~49~39 minecraft:glowstone
fill ~120~50~39 ~121~50~39 minecraft:stone_block_slab 6
setblock ~123~48~39 minecraft:stone_block_slab 14
setblock ~123~49~39 minecraft:sea_lantern
setblock ~123~50~39 minecraft:stone_block_slab 6
fill ~15~49~40 ~15~49~45 minecraft:stained_glass 3
fill ~18~48~40 ~18~48~41 minecraft:stone_block_slab 14
fill ~18~49~40 ~18~49~41 minecraft:sea_lantern
fill ~18~50~40 ~18~50~41 minecraft:stone_block_slab 6
setblock ~23~48~40 minecraft:stone_block_slab 14
setblock ~23~49~40 minecraft:glowstone
setblock ~23~50~40 minecraft:stone_block_slab 6
setblock ~30~49~40 minecraft:stone_block_slab 6
setblock ~33~49~40 minecraft:stained_glass 4
fill ~34~49~40 ~34~49~46 minecraft:stained_glass 0
setblock ~43~49~40 minecraft:stained_glass 4
setblock ~48~48~40 minecraft:stone_block_slab 14
setblock ~48~49~40 minecraft:glowstone
setblock ~48~50~40 minecraft:stone_block_slab 6
fill ~69~48~40 ~73~48~40 minecraft:concrete 0
fill ~69~49~40 ~70~49~40 minecraft:stained_glass 3
fill ~69~50~40 ~73~50~40 minecraft:concrete 0
fill ~70~47~40 ~72~47~40 minecraft:prismarine 2
fill ~70~51~40 ~72~51~40 minecraft:prismarine 2
setblock ~71~49~40 minecraft:concrete 0
fill ~72~49~40 ~73~49~40 minecraft:stained_glass 3
setblock ~94~48~40 minecraft:stone_block_slab 14
setblock ~94~49~40 minecraft:glowstone
setblock ~94~50~40 minecraft:stone_block_slab 6
setblock ~99~49~40 minecraft:stained_glass 4
fill ~108~49~40 ~108~49~46 minecraft:stained_glass 0
setblock ~109~49~40 minecraft:stained_glass 4
setblock ~112~49~40 minecraft:stone_block_slab 6
setblock ~119~48~40 minecraft:stone_block_slab 14
setblock ~119~49~40 minecraft:glowstone
setblock ~119~50~40 minecraft:stone_block_slab 6
fill ~124~48~40 ~124~48~41 minecraft:stone_block_slab 14
fill ~124~49~40 ~124~49~41 minecraft:sea_lantern
fill ~124~50~40 ~124~50~41 minecraft:stone_block_slab 6
fill ~127~49~40 ~127~49~45 minecraft:stained_glass 3
fill ~14~49~41 ~14~49~47 minecraft:stained_glass 3
fill ~24~48~41 ~25~48~41 minecraft:stone_block_slab 14
fill ~24~49~41 ~25~49~41 minecraft:glowstone
fill ~24~50~41 ~25~50~41 minecraft:stone_block_slab 6
fill ~31~49~41 ~31~49~42 minecraft:stone_block_slab 6
fill ~32~49~41 ~32~49~42 minecraft:stained_glass 4
fill ~33~49~41 ~33~49~46 minecraft:stained_glass 0
setblock ~42~49~41 minecraft:stained_glass 4
fill ~63~47~41 ~70~47~41 minecraft:prismarine 2
fill ~63~48~41 ~68~48~41 minecraft:concrete 0
fill ~63~49~41 ~64~49~41 minecraft:stained_glass 3
fill ~63~50~41 ~68~50~41 minecraft:concrete 0
fill ~63~51~41 ~70~51~41 minecraft:prismarine 2
fill ~64~45~41 ~78~45~41 minecraft:concrete 0
fill ~64~46~41 ~78~46~41 minecraft:prismarine 2
fill ~64~52~41 ~78~52~41 minecraft:prismarine 2
fill ~64~53~41 ~78~53~41 minecraft:concrete 0
setblock ~65~44~41 minecraft:concrete 0
setblock ~65~49~41 minecraft:concrete 0
fill ~65~54~41 ~65~54~46 minecraft:concrete 0
fill ~66~43~41 ~76~43~41 minecraft:concrete 0
fill ~66~44~41 ~70~44~41 minecraft:stained_glass 3
fill ~66~49~41 ~68~49~41 minecraft:stained_glass 3
fill ~66~54~41 ~70~54~41 minecraft:stained_glass 3
fill ~66~55~41 ~76~55~41 minecraft:concrete 0
fill ~67~42~41 ~75~42~41 minecraft:concrete 0
fill ~67~56~41 ~75~56~41 minecraft:concrete 0
fill ~69~41~41 ~73~41~42 minecraft:concrete 0
fill ~69~48~41 ~70~48~44 minecraft:leaves 3
fill ~69~49~41 ~70~49~43 minecraft:leaves 3
fill ~69~50~41 ~70~50~41 minecraft:leaves 3
fill ~69~57~41 ~73~57~41 minecraft:concrete 0
setblock ~71~44~41 minecraft:concrete 0
setblock ~71~47~41 minecraft:iron_block
setblock ~71~48~41 minecraft:stone 0
fill ~71~49~41 ~71~51~41 minecraft:stained_hardened_clay 9
setblock ~71~54~41 minecraft:concrete 0
fill ~72~44~41 ~76~44~41 minecraft:stained_glass 3
fill ~72~54~41 ~76~54~41 minecraft:stained_glass 3
fill ~73~47~41 ~79~47~41 minecraft:prismarine 2
fill ~73~51~41 ~79~51~41 minecraft:prismarine 2
fill ~74~48~41 ~79~48~41 minecraft:concrete 0
fill ~74~49~41 ~76~49~41 minecraft:stained_glass 3
fill ~74~50~41 ~79~50~41 minecraft:concrete 0
setblock ~77~44~41 minecraft:concrete 0
setblock ~77~49~41 minecraft:concrete 0
setblock ~77~54~41 minecraft:concrete 0
fill ~78~49~41 ~79~49~41 minecraft:stained_glass 3
setblock ~100~49~41 minecraft:stained_glass 4
fill ~109~49~41 ~109~49~46 minecraft:stained_glass 0
fill ~110~49~41 ~110~49~42 minecraft:stained_glass 4
fill ~111~49~41 ~111~49~42 minecraft:stone_block_slab 6
fill ~117~48~41 ~118~48~41 minecraft:stone_block_slab 14
fill ~117~49~41 ~118~49~41 minecraft:glowstone
fill ~117~50~41 ~118~50~41 minecraft:stone_block_slab 6
fill ~128~49~41 ~128~49~47 minecraft:stained_glass 3
fill ~17~48~42 ~17~48~43 minecraft:stone_block_slab 14
fill ~17~49~42 ~17~49~43 minecraft:sea_lantern
fill ~17~50~42 ~17~50~43 minecraft:stone_block_slab 6
fill ~20~49~42 ~22~49~43 minecraft:stone_block_slab 6
setblock ~26~48~42 minecraft:stone_block_slab 14
setblock ~26~49~42 minecraft:glowstone
setblock ~26~50~42 minecraft:stone_block_slab 6
setblock ~41~49~42 minecraft:stained_glass 4
fill ~60~46~42 ~63~47~42 minecraft:prismarine 2
fill ~60~48~42 ~62~48~42 minecraft:concrete 0
fill ~60~49~42 ~62~49~42 minecraft:stained_glass 3
fill ~60~50~42 ~62~50~42 minecraft:concrete 0
fill ~60~51~42 ~62~52~42 minecraft:prismarine 2
fill ~61~44~42 ~64~44~42 minecraft:stained_glass 3
fill ~61~45~42 ~63~45~42 minecraft:concrete 0
fill ~61~53~42 ~65~53~42 minecraft:concrete 0
fill ~61~54~42 ~64~54~42 minecraft:stained_glass 3
fill ~62~42~42 ~70~42~42 minecraft:concrete 0
fill ~62~43~42 ~65~43~42 minecraft:concrete 0
fill ~62~55~42 ~65~56~42 minecraft:concrete 0
fill ~63~41~42 ~68~41~42 minecraft:concrete 0
setblock ~63~51~42 minecraft:blue_glazed_terracotta 5
fill ~63~52~42 ~63~52~46 minecraft:prismarine 2
fill ~63~57~42 ~68~57~42 minecraft:concrete 0
fill ~64~40~42 ~78~40~42 minecraft:concrete 0
fill ~64~46~42 ~70~46~42 minecraft:stone_block_slab 14
fill ~64~47~42 ~68~47~42 minecraft:prismarine 2
setblock ~64~51~42 minecraft:blue_glazed_terracotta 2
fill ~64~52~42 ~65~52~42 minecraft:planks 1
fill ~64~58~42 ~78~58~42 minecraft:concrete 0
fill ~65~48~42 ~65~48~46 minecraft:leaves 3
setblock ~65~51~42 minecraft:blue_glazed_terracotta 5
setblock ~66~39~42 minecraft:concrete 0
setblock ~66~51~42 minecraft:blue_glazed_terracotta 2
fill ~66~52~42 ~70~52~50 minecraft:wool 7
setblock ~66~56~42 minecraft:concrete 0
fill ~66~59~42 ~66~59~43 minecraft:concrete 0
fill ~67~39~42 ~70~39~42 minecraft:stained_glass 3
fill ~67~48~42 ~68~48~42 minecraft:leaves 3
setblock ~67~51~42 minecraft:blue_glazed_terracotta 5
fill ~67~53~42 ~68~53~42 minecraft:bed 2
fill ~67~56~42 ~70~56~43 minecraft:stone_block_slab 8
fill ~67~59~42 ~70~59~42 minecraft:stained_glass 3
fill ~68~38~42 ~74~38~42 minecraft:concrete 0
setblock ~68~51~42 minecraft:blue_glazed_terracotta 2
fill ~68~60~42 ~74~60~42 minecraft:concrete 0
fill ~69~47~42 ~70~47~42 minecraft:dirt 0
setblock ~69~51~42 minecraft:blue_glazed_terracotta 5
fill ~69~57~42 ~70~57~42 minecraft:planks 1
setblock ~70~50~42 minecraft:leaves 3
setblock ~70~51~42 minecraft:blue_glazed_terracotta 2
setblock ~70~53~42 minecraft:chest 3
setblock ~71~39~42 minecraft:concrete 0
fill ~71~42~42 ~71~42~51 minecraft:iron_block
fill ~71~43~42 ~71~57~42 minecraft:prismarine 2
setblock ~71~59~42 minecraft:concrete 0
fill ~72~39~42 ~75~39~42 minecraft:stained_glass 3
fill ~72~42~42 ~80~42~42 minecraft:concrete 0
setblock ~72~46~42 minecraft:sea_lantern
setblock ~72~47~42 minecraft:stone_block_slab 0
fill ~72~59~42 ~75~59~42 minecraft:stained_glass 3
fill ~74~41~42 ~79~41~42 minecraft:concrete 0
fill ~74~57~42 ~79~57~42 minecraft:concrete 0
setblock ~76~39~42 minecraft:concrete 0
fill ~76~56~42 ~80~56~42 minecraft:concrete 0
setblock ~76~59~42 minecraft:concrete 0
fill ~77~43~42 ~80~43~42 minecraft:concrete 0
fill ~77~55~42 ~80~55~42 minecraft:concrete 0
fill ~78~44~42 ~81~44~42 minecraft:stained_glass 3
setblock ~78~46~42 minecraft:sea_lantern
setblock ~78~47~42 minecraft:stone_block_slab 0
fill ~78~54~42 ~81~54~42 minecraft:stained_glass 3
fill ~79~45~42 ~81~45~42 minecraft:concrete 0
fill ~79~46~42 ~82~46~42 minecraft:prismarine 2
fill ~79~52~42 ~82~52~42 minecraft:prismarine 2
fill ~79~53~42 ~81~53~42 minecraft:concrete 0
fill ~80~47~42 ~82~47~42 minecraft:prismarine 2
fill ~80~48~42 ~82~48~42 minecraft:concrete 0
fill ~80~49~42 ~82~49~42 minecraft:stained_glass 3
fill ~80~50~42 ~82~50~42 minecraft:concrete 0
fill ~80~51~42 ~82~51~42 minecraft:prismarine 2
setblock ~101~49~42 minecraft:stained_glass 4
setblock ~116~48~42 minecraft:stone_block_slab 14
setblock ~116~49~42 minecraft:glowstone
setblock ~116~50~42 minecraft:stone_block_slab 6
fill ~120~49~42 ~122~49~43 minecraft:stone_block_slab 6
fill ~125~48~42 ~125~48~43 minecraft:stone_block_slab 14
fill ~125~49~42 ~125~49~43 minecraft:sea_lantern
fill ~125~50~42 ~125~50~43 minecraft:stone_block_slab 6
fill ~13~49~43 ~13~49~49 minecraft:stained_glass 3
fill ~19~49~43 ~19~49~45 minecraft:stone_block_slab 6
fill ~23~49~43 ~23~49~45 minecraft:stone_block_slab 6
fill ~27~48~43 ~28~48~43 minecraft:stone_block_slab 14
fill ~27~49~43 ~28~49~43 minecraft:glowstone
fill ~27~50~43 ~28~50~43 minecraft:stone_block_slab 6
setblock ~30~49~43 minecraft:stone_block_slab 6
setblock ~31~49~43 minecraft:stained_glass 4
fill ~32~49~43 ~32~49~45 minecraft:stained_glass 0
setblock ~39~49~43 minecraft:stained_glass 0
setblock ~40~49~43 minecraft:stained_glass 4
setblock ~58~44~43 minecraft:stained_glass 3
fill ~58~45~43 ~60~45~43 minecraft:concrete 0
fill ~58~46~43 ~60~47~43 minecraft:prismarine 2
fill ~58~48~43 ~59~48~43 minecraft:concrete 0
setblock ~58~49~43 minecraft:stained_glass 3
fill ~58~50~43 ~59~50~43 minecraft:concrete 0
fill ~58~51~43 ~59~52~43 minecraft:prismarine 2
fill ~58~53~43 ~60~53~43 minecraft:concrete 0
setblock ~58~54~43 minecraft:stained_glass 3
fill ~59~42~43 ~65~42~43 minecraft:concrete 0
fill ~59~43~43 ~61~43~43 minecraft:concrete 0
setblock ~59~44~43 minecraft:concrete 0
setblock ~59~49~43 minecraft:concrete 0
fill ~59~54~43 ~59~55~45 minecraft:concrete 0
fill ~59~56~43 ~61~56~43 minecraft:concrete 0
fill ~60~41~43 ~63~41~43 minecraft:concrete 0
setblock ~60~44~43 minecraft:stained_glass 3
fill ~60~48~43 ~60~48~48 minecraft:leaves 3
setblock ~60~51~43 minecraft:blue_glazed_terracotta 4
setblock ~60~52~43 minecraft:planks 1
setblock ~60~54~43 minecraft:stained_glass 3
fill ~60~55~43 ~61~55~43 minecraft:concrete 0
fill ~60~57~43 ~62~57~43 minecraft:concrete 0
fill ~61~40~43 ~63~40~43 minecraft:concrete 0
fill ~61~46~43 ~65~46~43 minecraft:stone_block_slab 14
fill ~61~47~43 ~62~47~43 minecraft:prismarine 2
fill ~61~48~43 ~61~48~45 minecraft:leaves 3
fill ~61~49~43 ~62~49~43 minecraft:leaves 3
setblock ~61~50~43 minecraft:leaves 3
setblock ~61~51~43 minecraft:blue_glazed_terracotta 3
fill ~61~52~43 ~62~52~47 minecraft:prismarine 2
fill ~61~58~43 ~66~58~43 minecraft:concrete 0
fill ~62~39~43 ~65~39~43 minecraft:stained_glass 3
setblock ~62~48~43 minecraft:leaves 3
setblock ~62~51~43 minecraft:blue_glazed_terracotta 4
fill ~62~56~43 ~64~56~44 minecraft:stone_block_slab 8
fill ~62~59~43 ~65~59~43 minecraft:stained_glass 3
fill ~63~38~43 ~67~38~43 minecraft:concrete 0
fill ~63~47~43 ~65~47~43 minecraft:dirt 0
setblock ~63~48~43 minecraft:double_plant 1
setblock ~63~51~43 minecraft:blue_glazed_terracotta 3
fill ~63~53~43 ~64~53~43 minecraft:planks 2
fill ~63~57~43 ~66~57~43 minecraft:planks 1
fill ~63~60~43 ~67~60~43 minecraft:concrete 0
fill ~64~37~43 ~78~37~43 minecraft:concrete 0
fill ~64~41~43 ~70~41~43 minecraft:stone_block_slab 8
fill ~64~48~43 ~64~48~44 minecraft:leaves 3
setblock ~64~51~43 minecraft:blue_glazed_terracotta 4
fill ~64~52~43 ~64~52~46 minecraft:prismarine 2
fill ~64~61~43 ~78~61~43 minecraft:concrete 0
fill ~65~49~43 ~65~49~45 minecraft:leaves 3
fill ~65~50~43 ~65~50~44 minecraft:leaves 3
setblock ~65~51~43 minecraft:blue_glazed_terracotta 3
fill ~65~52~43 ~65~52~46 minecraft:planks 1
fill ~65~53~43 ~65~53~46 minecraft:concrete 0
fill ~65~55~43 ~65~55~46 minecraft:concrete 0
fill ~65~56~43 ~65~56~46 minecraft:double_stone_block_slab 0
fill ~66~36~43 ~76~36~43 minecraft:concrete 0
fill ~66~42~43 ~70~42~47 minecraft:planks 1
setblock ~66~47~43 minecraft:glowstone
fill ~66~48~43 ~66~48~46 minecraft:leaves 3
setblock ~66~51~43 minecraft:blue_glazed_terracotta 4
fill ~66~56~43 ~66~56~50 minecraft:stone_block_slab 8
fill ~66~62~43 ~76~62~43 minecraft:concrete 0
fill ~67~46~43 ~68~46~45 minecraft:stone_block_slab 14
fill ~67~47~43 ~68~47~45 minecraft:dirt 0
setblock ~67~48~43 minecraft:double_plant
setblock ~67~51~43 minecraft:blue_glazed_terracotta 3
fill ~67~57~43 ~70~57~50 minecraft:wool 7
fill ~67~58~43 ~68~58~43 minecraft:bed 2
fill ~68~48~43 ~68~48~45 minecraft:leaves 3
setblock ~68~51~43 minecraft:blue_glazed_terracotta 4
setblock ~69~47~43 minecraft:glowstone
setblock ~69~51~43 minecraft:blue_glazed_terracotta 3
fill ~70~46~43 ~70~46~65 minecraft:stone_block_slab 14
fill ~70~47~43 ~70~47~65 minecraft:dirt 0
setblock ~70~51~43 minecraft:blue_glazed_terracotta 4
setblock ~70~58~43 minecraft:chest 3
fill ~71~38~43 ~71~41~60 minecraft:stained_hardened_clay 12
setblock ~71~43~43 minecraft:stone 0
fill ~71~44~43 ~71~46~43 minecraft:stained_hardened_clay 9
fill ~71~47~43 ~71~47~46 minecraft:iron_block
setblock ~71~48~43 minecraft:stone 0
fill ~71~49~43 ~71~51~43 minecraft:stained_hardened_clay 9
fill ~71~52~43 ~71~52~46 minecraft:iron_block
setblock ~71~53~43 minecraft:stone 0
fill ~71~54~43 ~71~56~43 minecraft:stained_hardened_clay 9
fill ~71~57~43 ~71~57~46 minecraft:iron_block
setblock ~71~58~43 minecraft:stone 0
fill ~71~59~43 ~71~60~43 minecraft:stained_hardened_clay 9
fill ~72~41~43 ~78~41~43 minecraft:stone_block_slab 8
fill ~72~42~43 ~72~42~51 minecraft:concrete 0
fill ~73~42~43 ~76~42~47 minecraft:double_stone_block_slab 0
fill ~75~38~43 ~79~38~43 minecraft:concrete 0
fill ~75~60~43 ~79~60~43 minecraft:concrete 0
fill ~77~39~43 ~80~39~43 minecraft:stained_glass 3
fill ~77~42~43 ~83~42~43 minecraft:concrete 0
fill ~77~59~43 ~80~59~43 minecraft:stained_glass 3
fill ~79~40~43 ~81~41~43 minecraft:concrete 0
fill ~79~58~43 ~81~58~43 minecraft:concrete 0
fill ~80~57~43 ~82~57~43 minecraft:concrete 0
fill ~81~43~43 ~83~43~43 minecraft:concrete 0
fill ~81~55~43 ~83~56~43 minecraft:concrete 0
fill ~82~41~43 ~82~41~44 minecraft:concrete 0
setblock ~82~44~43 minecraft:stained_glass 3
fill ~82~45~43 ~84~45~43 minecraft:concrete 0
fill ~82~53~43 ~84~53~43 minecraft:concrete 0
setblock ~82~54~43 minecraft:stained_glass 3
setblock ~83~44~43 minecraft:concrete 0
fill ~83~46~43 ~84~47~43 minecraft:prismarine 2
fill ~83~48~43 ~84~48~43 minecraft:concrete 0
fill ~83~49~43 ~83~50~43 minecraft:concrete 0
fill ~83~51~43 ~84~52~43 minecraft:prismarine 2
setblock ~83~54~43 minecraft:concrete 0
setblock ~84~44~43 minecraft:stained_glass 3
setblock ~84~49~43 minecraft:stained_glass 3
setblock ~84~50~43 minecraft:concrete 0
setblock ~84~54~43 minecraft:stained_glass 3
setblock ~102~49~43 minecraft:stained_glass 4
setblock ~103~49~43 minecraft:stained_glass 0
fill ~110~49~43 ~110~49~45 minecraft:stained_glass 0
setblock ~111~49~43 minecraft:stained_glass 4
setblock ~112~49~43 minecraft:stone_block_slab 6
fill ~114~48~43 ~115~48~43 minecraft:stone_block_slab 14
fill ~114~49~43 ~115~49~43 minecraft:glowstone
fill ~114~50~43 ~115~50~43 minecraft:stone_block_slab 6
fill ~119~49~43 ~119~49~45 minecraft:stone_block_slab 6
fill ~123~49~43 ~123~49~45 minecraft:stone_block_slab 6
fill ~129~49~43 ~129~49~49 minecraft:stained_glass 3
fill ~16~48~44 ~16~48~45 minecraft:stone_block_slab 14
fill ~16~49~44 ~16~49~45 minecraft:sea_lantern
fill ~16~50~44 ~16~50~45 minecraft:stone_block_slab 6
fill ~20~49~44 ~20~49~46 minecraft:stone_block_slab 6
fill ~24~49~44 ~24~49~46 minecraft:stone_block_slab 6
setblock ~29~48~44 minecraft:stone_block_slab 14
setblock ~29~49~44 minecraft:glowstone
setblock ~29~50~44 minecraft:stone_block_slab 6
setblock ~30~49~44 minecraft:stained_glass 4
setblock ~31~49~44 minecraft:stained_glass 0
setblock ~39~49~44 minecraft:stained_glass 4
fill ~56~44~44 ~57~44~44 minecraft:stained_glass 3
fill ~56~45~44 ~57~45~44 minecraft:concrete 0
fill ~56~46~44 ~57~47~44 minecraft:prismarine 2
fill ~56~48~44 ~57~48~44 minecraft:concrete 0
fill ~56~49~44 ~57~49~44 minecraft:stained_glass 3
fill ~56~50~44 ~57~50~44 minecraft:concrete 0
fill ~56~51~44 ~57~52~44 minecraft:prismarine 2
fill ~56~53~44 ~57~53~44 minecraft:concrete 0
fill ~56~54~44 ~57~54~44 minecraft:stained_glass 3
fill ~57~42~44 ~61~42~44 minecraft:concrete 0
fill ~57~43~44 ~58~43~44 minecraft:concrete 0
fill ~57~55~44 ~58~56~44 minecraft:concrete 0
fill ~58~40~44 ~60~41~44 minecraft:concrete 0
fill ~58~46~44 ~62~46~44 minecraft:stone_block_slab 14
fill ~58~47~44 ~59~47~44 minecraft:prismarine 2
setblock ~58~51~44 minecraft:blue_glazed_terracotta 2
fill ~58~52~44 ~58~52~48 minecraft:prismarine 2
fill ~58~57~44 ~59~58~44 minecraft:concrete 0
setblock ~59~39~44 minecraft:stained_glass 3
setblock ~59~51~44 minecraft:blue_glazed_terracotta 5
fill ~59~52~44 ~59~52~45 minecraft:planks 1
fill ~59~53~44 ~59~53~45 minecraft:concrete 0
fill ~59~56~44 ~59~56~45 minecraft:double_stone_block_slab 0
setblock ~59~59~44 minecraft:stained_glass 3
fill ~60~38~44 ~62~38~44 minecraft:concrete 0
setblock ~60~39~44 minecraft:concrete 0
fill ~60~47~44 ~62~47~44 minecraft:dirt 0
fill ~60~49~44 ~61~49~44 minecraft:leaves 3
setblock ~60~51~44 minecraft:blue_glazed_terracotta 2
fill ~60~52~44 ~60~52~45 minecraft:prismarine 2
setblock ~60~53~44 minecraft:quartz_stairs 1
fill ~60~56~44 ~61~56~45 minecraft:stone_block_slab 8
fill ~60~57~44 ~61~57~44 minecraft:planks 1
fill ~60~58~44 ~61~58~44 minecraft:concrete 0
fill ~60~59~44 ~60~60~47 minecraft:concrete 0
fill ~61~37~44 ~63~37~44 minecraft:concrete 0
setblock ~61~39~44 minecraft:stained_glass 3
fill ~61~41~44 ~65~41~47 minecraft:stone_block_slab 8
setblock ~61~51~44 minecraft:blue_glazed_terracotta 5
setblock ~61~59~44 minecraft:stained_glass 3
fill ~61~60~44 ~62~61~44 minecraft:concrete 0
fill ~62~36~44 ~65~36~44 minecraft:concrete 0
fill ~62~42~44 ~65~42~68 minecraft:planks 1
fill ~62~48~44 ~63~48~44 minecraft:leaves 3
setblock ~62~51~44 minecraft:blue_glazed_terracotta 2
fill ~62~57~44 ~64~57~50 minecraft:prismarine 2
fill ~62~58~44 ~64~58~44 minecraft:planks 2
fill ~62~62~44 ~65~62~44 minecraft:concrete 0
setblock ~63~47~44 minecraft:glowstone
setblock ~63~51~44 minecraft:blue_glazed_terracotta 5
setblock ~63~61~44 minecraft:concrete 0
fill ~64~35~44 ~78~35~44 minecraft:concrete 0
fill ~64~46~44 ~66~46~45 minecraft:stone_block_slab 14
fill ~64~47~44 ~64~47~45 minecraft:dirt 0
setblock ~64~49~44 minecraft:leaves 3
setblock ~64~51~44 minecraft:blue_glazed_terracotta 2
setblock ~64~53~44 minecraft:cauldron 0
setblock ~64~54~44 minecraft:lever 2
fill ~64~61~44 ~64~61~51 minecraft:stone_block_slab 8
fill ~64~63~44 ~78~63~44 minecraft:concrete 0
setblock ~65~47~44 minecraft:log 3
setblock ~65~51~44 minecraft:blue_glazed_terracotta 5
fill ~65~57~44 ~65~57~47 minecraft:planks 1
fill ~65~58~44 ~65~60~47 minecraft:concrete 0
fill ~65~61~44 ~65~61~52 minecraft:double_stone_block_slab 0
setblock ~66~34~44 minecraft:concrete 0
setblock ~66~39~44 minecraft:end_rod 0
setblock ~66~40~44 minecraft:iron_bars
setblock ~66~41~44 minecraft:double_stone_block_slab 0
fill ~66~47~44 ~66~47~45 minecraft:dirt 0
setblock ~66~49~44 minecraft:leaves 3
setblock ~66~51~44 minecraft:blue_glazed_terracotta 2
fill ~66~57~44 ~66~57~50 minecraft:wool 7
fill ~66~61~44 ~70~61~44 minecraft:stone_block_slab 8
fill ~66~62~44 ~70~62~44 minecraft:planks 1
fill ~66~64~44 ~66~64~47 minecraft:concrete 0
fill ~67~34~44 ~70~34~44 minecraft:stained_glass 3
fill ~67~41~44 ~70~41~44 minecraft:stone_block_slab 8
fill ~67~48~44 ~67~48~53 minecraft:leaves 3
setblock ~67~51~44 minecraft:blue_glazed_terracotta 5
fill ~67~56~44 ~67~56~50 minecraft:stone_block_slab 8
fill ~67~64~44 ~70~64~44 minecraft:stained_glass 3
setblock ~68~51~44 minecraft:blue_glazed_terracotta 2
setblock ~68~56~44 minecraft:sea_lantern
fill ~69~46~44 ~69~46~46 minecraft:stone_block_slab 14
setblock ~69~47~44 minecraft:dirt 0
setblock ~69~51~44 minecraft:blue_glazed_terracotta 5
fill ~69~56~44 ~70~56~50 minecraft:stone_block_slab 8
setblock ~70~51~44 minecraft:blue_glazed_terracotta 2
setblock ~71~34~44 minecraft:concrete 0
fill ~71~36~44 ~71~37~60 minecraft:stained_hardened_clay 12
fill ~71~43~44 ~71~45~45 minecraft:glass
fill ~71~46~44 ~71~46~46 minecraft:stained_hardened_clay 9
fill ~71~48~44 ~71~50~45 minecraft:glass
fill ~71~51~44 ~71~51~46 minecraft:stained_hardened_clay 9
fill ~71~53~44 ~71~55~45 minecraft:glass
fill ~71~56~44 ~71~56~46 minecraft:stained_hardened_clay 9
fill ~71~58~44 ~71~60~45 minecraft:glass
fill ~71~61~44 ~71~61~46 minecraft:stained_hardened_clay 9
fill ~71~62~44 ~71~62~46 minecraft:iron_block
setblock ~71~64~44 minecraft:concrete 0
fill ~72~34~44 ~75~34~44 minecraft:stained_glass 3
fill ~72~37~44 ~78~37~47 minecraft:iron_block
setblock ~72~41~44 minecraft:sea_lantern
fill ~72~64~44 ~75~64~44 minecraft:stained_glass 3
fill ~73~41~44 ~75~41~59 minecraft:stone_block_slab 8
setblock ~76~34~44 minecraft:concrete 0
setblock ~76~41~44 minecraft:sea_lantern
setblock ~76~64~44 minecraft:concrete 0
fill ~77~36~44 ~80~36~44 minecraft:concrete 0
fill ~77~41~44 ~81~41~48 minecraft:stone_block_slab 8
fill ~77~42~44 ~80~42~47 minecraft:double_stone_block_slab 0
fill ~77~62~44 ~80~62~44 minecraft:concrete 0
fill ~79~37~44 ~81~37~44 minecraft:concrete 0
fill ~79~61~44 ~81~61~44 minecraft:concrete 0
fill ~80~38~44 ~82~38~44 minecraft:concrete 0
fill ~80~60~44 ~82~60~44 minecraft:concrete 0
setblock ~81~39~44 minecraft:stained_glass 3
fill ~81~42~44 ~85~42~44 minecraft:concrete 0
setblock ~81~59~44 minecraft:stained_glass 3
fill ~82~39~44 ~82~40~44 minecraft:concrete 0
fill ~82~58~44 ~84~58~44 minecraft:concrete 0
setblock ~82~59~44 minecraft:concrete 0
setblock ~83~39~44 minecraft:stained_glass 3
fill ~83~40~44 ~84~41~44 minecraft:concrete 0
setblock ~83~46~44 minecraft:sea_lantern
setblock ~83~47~44 minecraft:stone_block_slab 0
fill ~83~57~44 ~84~57~44 minecraft:concrete 0
setblock ~83~59~44 minecraft:stained_glass 3
fill ~84~43~44 ~85~43~44 minecraft:concrete 0
fill ~84~55~44 ~85~56~44 minecraft:concrete 0
fill ~85~44~44 ~86~44~44 minecraft:stained_glass 3
fill ~85~45~44 ~86~45~44 minecraft:concrete 0
fill ~85~46~44 ~86~47~44 minecraft:prismarine 2
fill ~85~48~44 ~86~48~44 minecraft:concrete 0
fill ~85~49~44 ~86~49~44 minecraft:stained_glass 3
fill ~85~50~44 ~86~50~44 minecraft:concrete 0
fill ~85~51~44 ~86~52~44 minecraft:prismarine 2
fill ~85~53~44 ~86~53~44 minecraft:concrete 0
fill ~85~54~44 ~86~54~44 minecraft:stained_glass 3
setblock ~103~49~44 minecraft:stained_glass 4
setblock ~111~49~44 minecraft:stained_glass 0
setblock ~112~49~44 minecraft:stained_glass 4
setblock ~113~48~44 minecraft:stone_block_slab 14
setblock ~113~49~44 minecraft:glowstone
setblock ~113~50~44 minecraft:stone_block_slab 6
fill ~118~49~44 ~118~49~46 minecraft:stone_block_slab 6
fill ~122~49~44 ~122~49~46 minecraft:stone_block_slab 6
fill ~126~48~44 ~126~48~45 minecraft:stone_block_slab 14
fill ~126~49~44 ~126~49~45 minecraft:sea_lantern
fill ~126~50~44 ~126~50~45 minecraft:stone_block_slab 6
fill ~12~49~45 ~12~49~52 minecraft:stained_glass 3
fill ~25~49~45 ~25~49~49 minecraft:stone_block_slab 6
fill ~28~49~45 ~28~49~46 minecraft:stone_block_slab 6
fill ~29~49~45 ~29~49~46 minecraft:stained_glass 4
fill ~30~48~45 ~31~48~45 minecraft:stone_block_slab 14
fill ~30~49~45 ~31~49~45 minecraft:glowstone
fill ~30~50~45 ~31~50~45 minecraft:stone_block_slab 6
setblock ~38~49~45 minecraft:stained_glass 4
fill ~54~45~45 ~55~45~45 minecraft:concrete 0
fill ~54~46~45 ~55~47~45 minecraft:prismarine 2
fill ~54~48~45 ~55~48~45 minecraft:concrete 0
fill ~54~49~45 ~55~49~45 minecraft:stained_glass 3
fill ~54~50~45 ~55~50~45 minecraft:concrete 0
fill ~54~51~45 ~55~52~45 minecraft:prismarine 2
fill ~54~53~45 ~55~53~45 minecraft:concrete 0
fill ~55~42~45 ~58~42~45 minecraft:concrete 0
fill ~55~43~45 ~56~43~45 minecraft:concrete 0
setblock ~55~44~45 minecraft:stained_glass 3
setblock ~55~54~45 minecraft:stained_glass 3
fill ~55~55~45 ~56~56~45 minecraft:concrete 0
fill ~56~40~45 ~57~41~45 minecraft:concrete 0
fill ~56~46~45 ~59~46~45 minecraft:stone_block_slab 14
fill ~56~47~45 ~57~47~45 minecraft:prismarine 2
setblock ~56~51~45 minecraft:blue_glazed_terracotta 4
fill ~56~52~45 ~57~52~49 minecraft:prismarine 2
fill ~56~57~45 ~57~58~45 minecraft:concrete 0
fill ~57~39~45 ~58~39~45 minecraft:stained_glass 3
setblock ~57~51~45 minecraft:blue_glazed_terracotta 3
fill ~57~56~45 ~58~56~46 minecraft:stone_block_slab 8
fill ~57~59~45 ~58~59~45 minecraft:stained_glass 3
fill ~58~38~45 ~59~38~45 minecraft:concrete 0
fill ~58~41~45 ~60~41~45 minecraft:stone_block_slab 8
fill ~58~47~45 ~59~47~47 minecraft:dirt 0
setblock ~58~48~45 minecraft:double_plant 2
setblock ~58~51~45 minecraft:blue_glazed_terracotta 4
setblock ~58~53~45 minecraft:quartz_stairs 0
setblock ~58~57~45 minecraft:planks 1
setblock ~58~58~45 minecraft:concrete 0
fill ~58~60~45 ~59~60~45 minecraft:concrete 0
fill ~59~37~45 ~60~37~45 minecraft:concrete 0
fill ~59~42~45 ~61~42~72 minecraft:planks 1
fill ~59~48~45 ~59~48~46 minecraft:leaves 3
setblock ~59~51~45 minecraft:blue_glazed_terracotta 3
fill ~59~57~45 ~59~57~52 minecraft:prismarine 2
fill ~59~61~45 ~60~61~45 minecraft:concrete 0
fill ~60~36~45 ~61~36~45 minecraft:concrete 0
setblock ~60~47~45 minecraft:glowstone
fill ~60~49~45 ~60~50~45 minecraft:leaves 3
setblock ~60~51~45 minecraft:blue_glazed_terracotta 4
fill ~60~53~45 ~62~55~45 minecraft:glass_pane
fill ~60~57~45 ~60~57~47 minecraft:planks 1
fill ~60~58~45 ~60~58~47 minecraft:concrete 0
fill ~60~62~45 ~61~62~45 minecraft:concrete 0
fill ~61~35~45 ~63~35~45 minecraft:concrete 0
fill ~61~46~45 ~63~46~46 minecraft:stone_block_slab 14
fill ~61~47~45 ~63~47~46 minecraft:dirt 0
setblock ~61~51~45 minecraft:blue_glazed_terracotta 3
fill ~61~57~45 ~61~57~47 minecraft:prismarine 2
fill ~61~61~45 ~63~61~45 minecraft:stone_block_slab 8
fill ~61~63~45 ~66~63~45 minecraft:concrete 0
fill ~62~34~45 ~65~34~45 minecraft:stained_glass 3
setblock ~62~48~45 minecraft:leaves 3
setblock ~62~49~45 minecraft:leaves 3
setblock ~62~51~45 minecraft:blue_glazed_terracotta 4
setblock ~62~56~45 minecraft:sea_lantern
fill ~62~62~45 ~66~62~45 minecraft:planks 1
fill ~62~64~45 ~65~64~45 minecraft:stained_glass 3
setblock ~63~48~45 minecraft:double_plant 3
setblock ~63~51~45 minecraft:blue_glazed_terracotta 3
fill ~63~56~45 ~64~56~46 minecraft:stone_block_slab 8
fill ~64~33~45 ~78~33~45 minecraft:concrete 0
setblock ~64~48~45 minecraft:red_flower 3
setblock ~64~51~45 minecraft:blue_glazed_terracotta 4
setblock ~64~58~45 minecraft:cauldron 0
setblock ~64~59~45 minecraft:lever 2
fill ~64~65~45 ~78~65~45 minecraft:concrete 0
setblock ~65~47~45 minecraft:dirt 0
setblock ~65~51~45 minecraft:blue_glazed_terracotta 3
fill ~66~41~45 ~66~41~61 minecraft:stone_block_slab 8
setblock ~66~51~45 minecraft:blue_glazed_terracotta 4
fill ~66~61~45 ~67~61~50 minecraft:stone_block_slab 8
fill ~67~32~45 ~75~32~45 minecraft:concrete 0
setblock ~67~36~45 minecraft:end_rod 0
fill ~67~37~45 ~67~40~45 minecraft:iron_bars
setblock ~67~41~45 minecraft:double_stone_block_slab 0
setblock ~67~51~45 minecraft:blue_glazed_terracotta 3
fill ~67~53~45 ~68~53~48 minecraft:carpet 8
fill ~67~62~45 ~70~62~50 minecraft:wool 7
fill ~67~63~45 ~68~63~45 minecraft:bed 2
fill ~67~66~45 ~75~66~45 minecraft:concrete 0
fill ~68~41~45 ~70~41~59 minecraft:stone_block_slab 8
setblock ~68~51~45 minecraft:blue_glazed_terracotta 4
fill ~68~56~45 ~68~56~47 minecraft:stone_block_slab 8
setblock ~68~61~45 minecraft:sea_lantern
setblock ~69~47~45 minecraft:log 3
fill ~69~48~45 ~69~48~66 minecraft:leaves 3
setblock ~69~49~45 minecraft:leaves 3
setblock ~69~51~45 minecraft:blue_glazed_terracotta 3
fill ~69~61~45 ~70~61~50 minecraft:stone_block_slab 8
setblock ~70~48~45 minecraft:double_plant
setblock ~70~51~45 minecraft:blue_glazed_terracotta 4
setblock ~70~63~45 minecraft:chest 4
fill ~71~34~45 ~71~35~60 minecraft:stained_hardened_clay 12
fill ~71~63~45 ~71~63~46 minecraft:stone 0
fill ~71~64~45 ~71~64~46 minecraft:stained_hardened_clay 9
fill ~72~41~45 ~72~41~60 minecraft:stone_block_slab 8
fill ~76~41~45 ~76~41~47 minecraft:stone_block_slab 8
fill ~77~34~45 ~80~34~45 minecraft:stained_glass 3
fill ~77~64~45 ~80~64~45 minecraft:stained_glass 3
fill ~79~35~45 ~81~35~45 minecraft:concrete 0
fill ~79~37~45 ~81~37~48 minecraft:iron_block
fill ~79~63~45 ~81~63~45 minecraft:concrete 0
fill ~81~36~45 ~82~36~45 minecraft:concrete 0
fill ~81~42~45 ~83~42~48 minecraft:double_stone_block_slab 0
fill ~81~62~45 ~82~62~45 minecraft:concrete 0
fill ~82~37~45 ~83~37~45 minecraft:concrete 0
fill ~82~41~45 ~84~41~45 minecraft:stone_block_slab 8
fill ~82~61~45 ~83~61~45 minecraft:concrete 0
fill ~83~38~45 ~84~38~45 minecraft:concrete 0
fill ~83~60~45 ~84~60~45 minecraft:concrete 0
fill ~84~39~45 ~85~39~45 minecraft:stained_glass 3
fill ~84~42~45 ~87~42~45 minecraft:concrete 0
fill ~84~59~45 ~85~59~45 minecraft:stained_glass 3
fill ~85~40~45 ~86~41~45 minecraft:concrete 0
fill ~85~57~45 ~86~58~45 minecraft:concrete 0
fill ~86~43~45 ~87~43~45 minecraft:concrete 0
fill ~86~55~45 ~87~56~45 minecraft:concrete 0
setblock ~87~44~45 minecraft:stained_glass 3
fill ~87~45~45 ~88~45~45 minecraft:concrete 0
fill ~87~46~45 ~88~47~45 minecraft:prismarine 2
fill ~87~48~45 ~88~48~45 minecraft:concrete 0
fill ~87~49~45 ~88~49~45 minecraft:stained_glass 3
fill ~87~50~45 ~88~50~45 minecraft:concrete 0
fill ~87~51~45 ~88~52~45 minecraft:prismarine 2
fill ~87~53~45 ~88~53~45 minecraft:concrete 0
setblock ~87~54~45 minecraft:stained_glass 3
setblock ~104~49~45 minecraft:stained_glass 4
fill ~111~48~45 ~112~48~45 minecraft:stone_block_slab 14
fill ~111~49~45 ~112~49~45 minecraft:glowstone
fill ~111~50~45 ~112~50~45 minecraft:stone_block_slab 6
fill ~113~49~45 ~113~49~46 minecraft:stained_glass 4
fill ~114~49~45 ~114~49~46 minecraft:stone_block_slab 6
fill ~117~49~45 ~117~49~49 minecraft:stone_block_slab 6
fill ~130~49~45 ~130~49~52 minecraft:stained_glass 3
fill ~15~48~46 ~15~48~47 minecraft:stone_block_slab 14
fill ~15~49~46 ~15~49~47 minecraft:sea_lantern
fill ~15~50~46 ~15~50~47 minecraft:stone_block_slab 6
setblock ~21~49~46 minecraft:stone_block_slab 6
fill ~26~49~46 ~26~49~50 minecraft:stone_block_slab 6
fill ~30~49~46 ~31~49~55 minecraft:stained_glass 0
setblock ~32~48~46 minecraft:stone_block_slab 14
setblock ~32~49~46 minecraft:glowstone
setblock ~32~50~46 minecraft:stone_block_slab 6
fill ~37~49~46 ~37~49~47 minecraft:stained_glass 4
fill ~52~47~46 ~55~47~46 minecraft:prismarine 2
fill ~52~48~46 ~53~48~46 minecraft:concrete 0
setblock ~52~49~46 minecraft:stained_glass 3
fill ~52~50~46 ~53~50~46 minecraft:concrete 0
fill ~52~51~46 ~53~51~46 minecraft:prismarine 2
fill ~53~43~46 ~54~43~46 minecraft:concrete 0
fill ~53~44~46 ~53~45~46 minecraft:concrete 0
setblock ~53~46~46 minecraft:prismarine 2
setblock ~53~49~46 minecraft:concrete 0
setblock ~53~52~46 minecraft:prismarine 2
fill ~53~53~46 ~54~53~46 minecraft:concrete 0
fill ~53~54~46 ~53~55~47 minecraft:concrete 0
fill ~54~41~46 ~55~42~46 minecraft:concrete 0
setblock ~54~44~46 minecraft:stained_glass 3
fill ~54~46~46 ~56~46~46 minecraft:stone_block_slab 14
fill ~54~48~46 ~55~48~49 minecraft:leaves 3
setblock ~54~51~46 minecraft:blue_glazed_terracotta 2
setblock ~54~52~46 minecraft:planks 1
setblock ~54~54~46 minecraft:stained_glass 3
fill ~54~55~46 ~54~57~46 minecraft:concrete 0
fill ~55~39~46 ~56~39~46 minecraft:stained_glass 3
setblock ~55~40~46 minecraft:concrete 0
setblock ~55~51~46 minecraft:blue_glazed_terracotta 5
fill ~55~52~46 ~55~52~48 minecraft:prismarine 2
setblock ~55~53~46 minecraft:planks 2
fill ~55~56~46 ~56~56~48 minecraft:stone_block_slab 8
fill ~55~57~46 ~55~58~46 minecraft:concrete 0
fill ~55~59~46 ~56~59~46 minecraft:stained_glass 3
fill ~56~38~46 ~57~38~46 minecraft:concrete 0
fill ~56~41~46 ~59~41~47 minecraft:stone_block_slab 8
setblock ~56~42~46 minecraft:concrete 0
fill ~56~47~46 ~56~47~49 minecraft:dirt 0
setblock ~56~48~46 minecraft:double_plant 
setblock ~56~51~46 minecraft:blue_glazed_terracotta 2
setblock ~56~57~46 minecraft:planks 1
setblock ~56~58~46 minecraft:concrete 0
fill ~56~60~46 ~57~60~46 minecraft:concrete 0
fill ~57~36~46 ~59~36~46 minecraft:concrete 0
fill ~57~37~46 ~58~37~46 minecraft:concrete 0
fill ~57~42~46 ~58~42~72 minecraft:planks 1
setblock ~57~47~46 minecraft:glowstone
setblock ~57~51~46 minecraft:blue_glazed_terracotta 5
fill ~57~53~46 ~59~55~46 minecraft:glass_pane
fill ~57~57~46 ~58~57~49 minecraft:prismarine 2
fill ~57~61~46 ~58~62~46 minecraft:concrete 0
fill ~58~35~46 ~60~35~46 minecraft:concrete 0
fill ~58~46~46 ~60~46~47 minecraft:stone_block_slab 14
setblock ~58~48~46 minecraft:double_plant 3
setblock ~58~51~46 minecraft:blue_glazed_terracotta 2
fill ~58~63~46 ~61~63~46 minecraft:concrete 0
setblock ~59~49~46 minecraft:leaves 3
setblock ~59~51~46 minecraft:blue_glazed_terracotta 5
fill ~59~52~46 ~59~52~48 minecraft:prismarine 2
fill ~59~56~46 ~59~56~48 minecraft:stone_block_slab 8
fill ~59~61~46 ~59~61~52 minecraft:stone_block_slab 8
setblock ~59~62~46 minecraft:concrete 0
setblock ~60~34~46 minecraft:stained_glass 3
setblock ~60~39~46 minecraft:end_rod 0
setblock ~60~40~46 minecraft:iron_bars
setblock ~60~41~46 minecraft:double_stone_block_slab 0
setblock ~60~47~46 minecraft:log 3
setblock ~60~51~46 minecraft:blue_glazed_terracotta 2
fill ~60~52~46 ~60~52~48 minecraft:planks 1
fill ~60~53~46 ~60~55~48 minecraft:concrete 0
fill ~60~56~46 ~60~56~48 minecraft:double_stone_block_slab 0
fill ~60~61~46 ~60~61~47 minecraft:double_stone_block_slab 0
fill ~60~62~46 ~61~62~46 minecraft:planks 1
setblock ~60~64~46 minecraft:stained_glass 3
fill ~61~33~46 ~63~33~46 minecraft:concrete 0
setblock ~61~34~46 minecraft:concrete 0
fill ~61~48~46 ~62~48~46 minecraft:leaves 3
setblock ~61~51~46 minecraft:blue_glazed_terracotta 5
fill ~61~56~46 ~62~56~47 minecraft:stone_block_slab 8
setblock ~61~58~46 minecraft:quartz_stairs 1
fill ~61~61~46 ~61~61~47 minecraft:stone_block_slab 8
fill ~61~64~46 ~61~65~49 minecraft:concrete 0
setblock ~62~51~46 minecraft:blue_glazed_terracotta 2
setblock ~62~61~46 minecraft:sea_lantern
fill ~62~62~46 ~65~62~49 minecraft:prismarine 2
fill ~62~65~46 ~63~65~46 minecraft:concrete 0
fill ~63~32~46 ~70~32~46 minecraft:concrete 0
setblock ~63~48~46 minecraft:tallgrass 2
setblock ~63~51~46 minecraft:blue_glazed_terracotta 5
fill ~63~53~46 ~63~55~46 minecraft:glass_pane
fill ~63~61~46 ~63~61~49 minecraft:stone_block_slab 8
fill ~63~66~46 ~66~66~46 minecraft:concrete 0
fill ~64~46~46 ~67~46~46 minecraft:stone_block_slab 8
fill ~64~47~46 ~67~47~46 minecraft:prismarine 2
setblock ~64~51~46 minecraft:blue_glazed_terracotta 2
fill ~64~63~46 ~65~63~46 minecraft:planks 2
fill ~65~31~46 ~77~31~46 minecraft:concrete 0
setblock ~65~33~46 minecraft:log 2
fill ~65~34~46 ~65~35~46 minecraft:leaves 0
setblock ~65~51~46 minecraft:blue_glazed_terracotta 5
fill ~65~67~46 ~77~67~46 minecraft:concrete 0
setblock ~66~51~46 minecraft:blue_glazed_terracotta 2
fill ~66~62~46 ~66~62~47 minecraft:planks 1
fill ~66~63~46 ~66~63~47 minecraft:concrete 0
fill ~66~65~46 ~66~65~51 minecraft:concrete 0
fill ~67~41~46 ~67~41~50 minecraft:stone_block_slab 8
setblock ~67~49~46 minecraft:leaves 3
setblock ~67~51~46 minecraft:blue_glazed_terracotta 5
fill ~67~58~46 ~68~58~49 minecraft:carpet 8
fill ~67~66~46 ~70~66~47 minecraft:stone_block_slab 8
fill ~68~46~46 ~68~46~66 minecraft:stone_block_slab 14
fill ~68~47~46 ~69~47~46 minecraft:dirt 0
setblock ~68~48~46 minecraft:double_plant 3
setblock ~68~51~46 minecraft:blue_glazed_terracotta 2
fill ~68~61~46 ~68~61~48 minecraft:stone_block_slab 8
fill ~69~30~46 ~73~30~46 minecraft:concrete 0
setblock ~69~51~46 minecraft:blue_glazed_terracotta 5
fill ~69~68~46 ~73~68~46 minecraft:concrete 0
setblock ~70~48~46 minecraft:leaves 3
setblock ~70~51~46 minecraft:blue_glazed_terracotta 2
fill ~71~32~46 ~71~32~61 minecraft:double_stone_block_slab 0
fill ~71~33~46 ~71~33~60 minecraft:sandstone 2
setblock ~71~43~46 minecraft:stone 0
fill ~71~44~46 ~71~45~46 minecraft:stained_hardened_clay 9
setblock ~71~48~46 minecraft:stone 0
fill ~71~49~46 ~71~50~46 minecraft:stained_hardened_clay 9
setblock ~71~53~46 minecraft:stone 0
fill ~71~54~46 ~71~55~46 minecraft:stained_hardened_clay 9
setblock ~71~58~46 minecraft:stone 0
fill ~71~59~46 ~71~60~46 minecraft:stained_hardened_clay 9
fill ~71~65~46 ~71~66~46 minecraft:stained_hardened_clay 9
fill ~72~32~46 ~75~32~47 minecraft:iron_block
setblock ~72~36~46 minecraft:sea_lantern
fill ~76~32~46 ~79~32~46 minecraft:concrete 0
setblock ~76~36~46 minecraft:sea_lantern
fill ~76~66~46 ~79~66~46 minecraft:concrete 0
fill ~79~33~46 ~81~33~46 minecraft:concrete 0
fill ~79~65~46 ~81~65~46 minecraft:concrete 0
setblock ~81~34~46 minecraft:concrete 0
setblock ~81~64~46 minecraft:concrete 0
setblock ~82~34~46 minecraft:stained_glass 3
fill ~82~35~46 ~84~35~46 minecraft:concrete 0
fill ~82~37~46 ~83~37~49 minecraft:iron_block
setblock ~82~41~46 minecraft:sea_lantern
fill ~82~63~46 ~84~63~46 minecraft:concrete 0
setblock ~82~64~46 minecraft:stained_glass 3
fill ~83~36~46 ~85~36~46 minecraft:concrete 0
fill ~83~41~46 ~86~41~51 minecraft:stone_block_slab 8
fill ~83~62~46 ~85~62~46 minecraft:concrete 0
fill ~84~37~46 ~85~37~46 minecraft:concrete 0
fill ~84~42~46 ~85~42~49 minecraft:double_stone_block_slab 0
fill ~84~61~46 ~85~61~46 minecraft:concrete 0
fill ~85~38~46 ~86~38~46 minecraft:concrete 0
fill ~85~60~46 ~86~60~46 minecraft:concrete 0
fill ~86~39~46 ~87~39~46 minecraft:stained_glass 3
fill ~86~42~46 ~88~42~46 minecraft:concrete 0
fill ~86~59~46 ~87~59~46 minecraft:stained_glass 3
fill ~87~40~46 ~87~41~46 minecraft:concrete 0
fill ~87~57~46 ~88~57~46 minecraft:concrete 0
setblock ~87~58~46 minecraft:concrete 0
fill ~88~41~46 ~88~41~47 minecraft:concrete 0
fill ~88~43~46 ~89~43~46 minecraft:concrete 0
setblock ~88~44~46 minecraft:stained_glass 3
setblock ~88~46~46 minecraft:sea_lantern
setblock ~88~47~46 minecraft:stone_block_slab 0
setblock ~88~54~46 minecraft:stained_glass 3
fill ~88~55~46 ~89~55~46 minecraft:concrete 0
setblock ~88~56~46 minecraft:concrete 0
fill ~89~44~46 ~89~45~46 minecraft:concrete 0
fill ~89~46~46 ~89~47~46 minecraft:prismarine 2
fill ~89~48~46 ~90~48~46 minecraft:concrete 0
fill ~89~49~46 ~89~50~46 minecraft:concrete 0
fill ~89~51~46 ~90~51~46 minecraft:prismarine 2
setblock ~89~52~46 minecraft:prismarine 2
fill ~89~53~46 ~89~54~46 minecraft:concrete 0
setblock ~90~47~46 minecraft:prismarine 2
setblock ~90~49~46 minecraft:stained_glass 3
setblock ~90~50~46 minecraft:concrete 0
fill ~105~49~46 ~105~49~47 minecraft:stained_glass 4
setblock ~110~48~46 minecraft:stone_block_slab 14
setblock ~110~49~46 minecraft:glowstone
setblock ~110~50~46 minecraft:stone_block_slab 6
fill ~111~49~46 ~112~49~55 minecraft:stained_glass 0
fill ~116~49~46 ~116~49~50 minecraft:stone_block_slab 6
setblock ~121~49~46 minecraft:stone_block_slab 6
fill ~127~48~46 ~127~48~47 minecraft:stone_block_slab 14
fill ~127~49~46 ~127~49~47 minecraft:sea_lantern
fill ~127~50~46 ~127~50~47 minecraft:stone_block_slab 6
fill ~11~49~47 ~11~49~55 minecraft:stained_glass 3
fill ~22~49~47 ~22~49~48 minecraft:stone_block_slab 6
fill ~27~49~47 ~27~49~48 minecraft:stone_block_slab 6
fill ~28~49~47 ~28~49~48 minecraft:stained_glass 4
fill ~29~49~47 ~29~49~60 minecraft:stained_glass 0
fill ~32~49~47 ~32~49~53 minecraft:stained_glass 0
fill ~33~48~47 ~34~48~47 minecraft:stone_block_slab 14
fill ~33~49~47 ~34~49~47 minecraft:glowstone
fill ~33~50~47 ~34~50~47 minecraft:stone_block_slab 6
fill ~51~45~47 ~52~45~47 minecraft:concrete 0
fill ~51~46~47 ~52~47~47 minecraft:prismarine 2
setblock ~51~48~47 minecraft:concrete 0
setblock ~51~49~47 minecraft:stained_glass 3
setblock ~51~50~47 minecraft:concrete 0
fill ~51~51~47 ~51~52~47 minecraft:prismarine 2
fill ~51~53~47 ~53~53~47 minecraft:concrete 0
fill ~52~42~47 ~54~42~47 minecraft:concrete 0
setblock ~52~43~47 minecraft:concrete 0
setblock ~52~44~47 minecraft:stained_glass 3
setblock ~52~48~47 minecraft:leaves 3
setblock ~52~51~47 minecraft:blue_glazed_terracotta 4
setblock ~52~52~47 minecraft:prismarine 2
setblock ~52~54~47 minecraft:stained_glass 3
fill ~52~55~47 ~52~56~47 minecraft:concrete 0
fill ~53~40~47 ~54~41~47 minecraft:concrete 0
fill ~53~46~47 ~53~46~51 minecraft:stone_block_slab 14
setblock ~53~47~47 minecraft:prismarine 2
setblock ~53~51~47 minecraft:blue_glazed_terracotta 3
setblock ~53~52~47 minecraft:planks 1
fill ~53~56~47 ~53~58~47 minecraft:concrete 0
fill ~54~38~47 ~55~38~47 minecraft:concrete 0
setblock ~54~39~47 minecraft:concrete 0
setblock ~54~47~47 minecraft:glowstone
fill ~54~49~47 ~55~49~48 minecraft:leaves 3
setblock ~54~50~47 minecraft:leaves 3
setblock ~54~51~47 minecraft:blue_glazed_terracotta 4
setblock ~54~52~47 minecraft:prismarine 2
setblock ~54~53~47 minecraft:planks 2
setblock ~54~56~47 minecraft:stone_block_slab 8
fill ~54~57~47 ~54~57~48 minecraft:planks 1
fill ~54~58~47 ~54~60~48 minecraft:concrete 0
fill ~55~37~47 ~56~37~47 minecraft:concrete 0
fill ~55~41~47 ~55~41~50 minecraft:stone_block_slab 8
fill ~55~42~47 ~56~42~72 minecraft:planks 1
fill ~55~46~47 ~57~46~48 minecraft:stone_block_slab 14
setblock ~55~47~47 minecraft:dirt 0
setblock ~55~51~47 minecraft:blue_glazed_terracotta 3
fill ~55~57~47 ~56~57~48 minecraft:prismarine 2
fill ~55~58~47 ~56~58~47 minecraft:planks 2
fill ~55~60~47 ~55~61~47 minecraft:concrete 0
setblock ~56~36~47 minecraft:concrete 0
fill ~56~48~47 ~58~48~47 minecraft:leaves 3
setblock ~56~51~47 minecraft:blue_glazed_terracotta 4
fill ~56~61~47 ~56~62~47 minecraft:concrete 0
setblock ~57~35~47 minecraft:concrete 0
fill ~57~47~47 ~57~47~48 minecraft:dirt 0
setblock ~57~51~47 minecraft:blue_glazed_terracotta 3
setblock ~57~56~47 minecraft:sea_lantern
fill ~57~61~47 ~58~61~47 minecraft:stone_block_slab 8
fill ~57~62~47 ~59~62~47 minecraft:planks 1
fill ~57~63~47 ~59~63~47 minecraft:concrete 0
fill ~58~34~47 ~59~34~47 minecraft:stained_glass 3
fill ~58~43~47 ~61~43~47 minecraft:wool 7
setblock ~58~51~47 minecraft:blue_glazed_terracotta 4
fill ~58~56~47 ~58~56~48 minecraft:stone_block_slab 8
fill ~58~64~47 ~59~64~47 minecraft:stained_glass 3
fill ~59~33~47 ~60~33~47 minecraft:concrete 0
fill ~59~44~47 ~60~44~47 minecraft:stone_block_slab 6
setblock ~59~48~47 minecraft:tallgrass 2
setblock ~59~51~47 minecraft:blue_glazed_terracotta 3
setblock ~59~58~47 minecraft:quartz_stairs 0
fill ~59~65~47 ~60~65~47 minecraft:concrete 0
fill ~60~32~47 ~63~32~47 minecraft:concrete 0
fill ~60~41~47 ~60~41~66 minecraft:stone_block_slab 8
setblock ~60~47~47 minecraft:dirt 0
setblock ~60~51~47 minecraft:blue_glazed_terracotta 4
fill ~60~62~47 ~60~62~53 minecraft:prismarine 2
fill ~60~66~47 ~62~66~47 minecraft:concrete 0
fill ~61~33~47 ~62~33~47 minecraft:birch_stairs 3
fill ~61~46~47 ~63~46~47 minecraft:stone_block_slab 8
fill ~61~47~47 ~63~47~47 minecraft:prismarine 2
setblock ~61~48~47 minecraft:leaves 3
setblock ~61~51~47 minecraft:blue_glazed_terracotta 3
fill ~61~62~47 ~61~62~49 minecraft:planks 1
fill ~61~63~47 ~61~63~49 minecraft:concrete 0
fill ~62~31~47 ~68~31~47 minecraft:concrete 0
setblock ~62~43~47 minecraft:birch_stairs 4
setblock ~62~51~47 minecraft:blue_glazed_terracotta 4
setblock ~62~54~47 minecraft:stone_button 4
setblock ~62~55~47 minecraft:tripwire_hook 1
fill ~62~61~47 ~62~61~50 minecraft:stone_block_slab 8
setblock ~62~63~47 minecraft:quartz_stairs 1
fill ~62~67~47 ~64~67~47 minecraft:concrete 0
setblock ~63~43~47 minecraft:birch_stairs 6
setblock ~63~51~47 minecraft:blue_glazed_terracotta 3
setblock ~63~52~47 minecraft:planks 1
fill ~63~53~47 ~63~55~47 minecraft:concrete 0
fill ~63~56~47 ~64~56~47 minecraft:double_stone_block_slab 0
fill ~63~66~47 ~65~66~47 minecraft:stone_block_slab 8
fill ~64~30~47 ~68~30~47 minecraft:concrete 0
fill ~64~32~47 ~70~32~66 minecraft:planks 1
setblock ~64~51~47 minecraft:blue_glazed_terracotta 4
fill ~64~52~47 ~65~52~51 minecraft:wool 7
setblock ~64~53~47 minecraft:dark_oak_door 1
setblock ~64~55~47 minecraft:concrete 0
fill ~64~68~47 ~70~68~47 minecraft:concrete 0
fill ~65~46~47 ~65~47~47 minecraft:leaves 3
setblock ~65~51~47 minecraft:blue_glazed_terracotta 3
fill ~65~56~47 ~65~56~51 minecraft:stone_block_slab 8
setblock ~65~63~47 minecraft:cauldron 0
setblock ~65~64~47 minecraft:lever 2
fill ~65~67~47 ~70~67~49 minecraft:planks 1
setblock ~66~46~47 minecraft:end_rod 0
setblock ~66~47~47 minecraft:nether_brick_fence
setblock ~66~51~47 minecraft:blue_glazed_terracotta 4
fill ~66~66~47 ~66~66~51 minecraft:double_stone_block_slab 0
fill ~67~29~47 ~70~29~47 minecraft:stained_glass 3
fill ~67~46~47 ~67~46~62 minecraft:stone_block_slab 8
fill ~67~47~47 ~67~47~62 minecraft:prismarine 2
setblock ~67~51~47 minecraft:blue_glazed_terracotta 3
fill ~67~69~47 ~70~69~47 minecraft:stained_glass 3
fill ~68~47~47 ~68~47~66 minecraft:dirt 0
fill ~68~48~47 ~68~48~49 minecraft:leaves 3
setblock ~68~51~47 minecraft:blue_glazed_terracotta 4
fill ~69~31~47 ~70~31~52 minecraft:stone_block_slab 8
setblock ~69~47~47 minecraft:glowstone
setblock ~69~51~47 minecraft:blue_glazed_terracotta 3
setblock ~70~48~47 minecraft:double_plant 2
setblock ~70~51~47 minecraft:blue_glazed_terracotta 4
fill ~70~53~47 ~70~54~48 minecraft:chest 4
fill ~70~58~47 ~70~59~48 minecraft:chest 4
fill ~70~63~47 ~70~64~48 minecraft:chest 4
setblock ~71~29~47 minecraft:concrete 0
setblock ~71~31~47 minecraft:sea_lantern
fill ~71~43~47 ~71~68~47 minecraft:prismarine 2
setblock ~71~69~47 minecraft:concrete 0
fill ~72~29~47 ~75~29~47 minecraft:stained_glass 3
setblock ~72~46~47 minecraft:sea_lantern
setblock ~72~47~47 minecraft:stone_block_slab 0
fill ~72~69~47 ~75~69~47 minecraft:stained_glass 3
fill ~74~30~47 ~78~30~47 minecraft:concrete 0
fill ~74~68~47 ~78~68~47 minecraft:concrete 0
fill ~76~32~47 ~79~32~48 minecraft:iron_block
fill ~78~31~47 ~80~31~47 minecraft:concrete 0
fill ~78~67~47 ~80~67~47 minecraft:concrete 0
fill ~80~32~47 ~82~32~47 minecraft:concrete 0
fill ~80~66~47 ~82~66~47 minecraft:concrete 0
fill ~82~33~47 ~83~33~47 minecraft:concrete 0
fill ~82~41~47 ~82~41~50 minecraft:stone_block_slab 8
fill ~82~65~47 ~83~65~47 minecraft:concrete 0
fill ~83~34~47 ~84~34~47 minecraft:stained_glass 3
fill ~83~64~47 ~84~64~47 minecraft:stained_glass 3
fill ~84~37~47 ~85~37~50 minecraft:iron_block
setblock ~85~35~47 minecraft:concrete 0
setblock ~85~63~47 minecraft:concrete 0
fill ~86~36~47 ~86~37~47 minecraft:concrete 0
fill ~86~42~47 ~87~42~50 minecraft:double_stone_block_slab 0
fill ~86~61~47 ~87~61~47 minecraft:concrete 0
setblock ~86~62~47 minecraft:concrete 0
fill ~87~37~47 ~87~38~47 minecraft:concrete 0
fill ~87~41~47 ~87~41~51 minecraft:stone_block_slab 8
fill ~87~60~47 ~88~60~47 minecraft:concrete 0
fill ~88~38~47 ~88~40~47 minecraft:concrete 0
fill ~88~42~47 ~90~42~47 minecraft:concrete 0
fill ~88~58~47 ~89~58~47 minecraft:concrete 0
setblock ~88~59~47 minecraft:concrete 0
fill ~89~40~47 ~89~41~47 minecraft:concrete 0
fill ~89~56~47 ~90~56~47 minecraft:concrete 0
setblock ~89~57~47 minecraft:concrete 0
setblock ~90~43~47 minecraft:concrete 0
setblock ~90~44~47 minecraft:stained_glass 3
fill ~90~45~47 ~91~45~47 minecraft:concrete 0
fill ~90~46~47 ~91~46~47 minecraft:prismarine 2
fill ~90~52~47 ~91~52~47 minecraft:prismarine 2
fill ~90~53~47 ~91~53~47 minecraft:concrete 0
setblock ~90~54~47 minecraft:stained_glass 3
setblock ~90~55~47 minecraft:concrete 0
setblock ~91~47~47 minecraft:prismarine 2
setblock ~91~48~47 minecraft:concrete 0
setblock ~91~49~47 minecraft:stained_glass 3
setblock ~91~50~47 minecraft:concrete 0
setblock ~91~51~47 minecraft:prismarine 2
setblock ~92~44~47 minecraft:quartz_stairs 4
fill ~92~45~47 ~95~45~47 minecraft:stone_block_slab 6
fill ~93~44~47 ~94~44~47 minecraft:quartz_stairs 6
setblock ~95~44~47 minecraft:quartz_stairs 5
fill ~108~48~47 ~109~48~47 minecraft:stone_block_slab 14
fill ~108~49~47 ~109~49~47 minecraft:glowstone
fill ~108~50~47 ~109~50~47 minecraft:stone_block_slab 6
fill ~110~49~47 ~110~49~53 minecraft:stained_glass 0
fill ~113~49~47 ~113~49~60 minecraft:stained_glass 0
fill ~114~49~47 ~114~49~48 minecraft:stained_glass 4
fill ~115~49~47 ~115~49~48 minecraft:stone_block_slab 6
fill ~120~49~47 ~120~49~48 minecraft:stone_block_slab 6
fill ~131~49~47 ~131~49~55 minecraft:stained_glass 3
fill ~14~48~48 ~14~48~49 minecraft:stone_block_slab 14
fill ~14~49~48 ~14~49~49 minecraft:sea_lantern
fill ~14~50~48 ~14~50~49 minecraft:stone_block_slab 6
fill ~33~49~48 ~34~49~50 minecraft:stained_glass 0
setblock ~35~48~48 minecraft:stone_block_slab 14
setblock ~35~49~48 minecraft:glowstone
setblock ~35~50~48 minecraft:stone_block_slab 6
setblock ~36~49~48 minecraft:stained_glass 4
fill ~50~44~48 ~51~44~48 minecraft:stained_glass 3
setblock ~50~45~48 minecraft:concrete 0
fill ~50~46~48 ~50~47~48 minecraft:prismarine 2
setblock ~50~48~48 minecraft:concrete 0
setblock ~50~49~48 minecraft:stained_glass 3
setblock ~50~50~48 minecraft:concrete 0
fill ~50~51~48 ~50~52~48 minecraft:prismarine 2
fill ~50~53~48 ~51~53~48 minecraft:concrete 0
fill ~50~54~48 ~51~54~48 minecraft:stained_glass 3
fill ~51~41~48 ~52~42~48 minecraft:concrete 0
setblock ~51~43~48 minecraft:concrete 0
fill ~51~46~48 ~52~46~48 minecraft:stone_block_slab 14
setblock ~51~47~48 minecraft:prismarine 2
setblock ~51~51~48 minecraft:blue_glazed_terracotta 5
setblock ~51~52~48 minecraft:planks 1
fill ~51~55~48 ~51~57~48 minecraft:concrete 0
fill ~52~39~48 ~53~39~48 minecraft:stained_glass 3
setblock ~52~40~48 minecraft:concrete 0
fill ~52~47~48 ~54~47~50 minecraft:dirt 0
fill ~52~48~48 ~52~48~49 minecraft:double_plant 2
setblock ~52~51~48 minecraft:blue_glazed_terracotta 2
fill ~52~52~48 ~53~52~53 minecraft:wool 7
fill ~52~56~48 ~53~56~49 minecraft:stone_block_slab 8
fill ~52~57~48 ~52~58~48 minecraft:concrete 0
fill ~52~59~48 ~53~59~48 minecraft:stained_glass 3
fill ~53~37~48 ~54~37~48 minecraft:concrete 0
setblock ~53~38~48 minecraft:concrete 0
fill ~53~41~48 ~54~41~48 minecraft:stone_block_slab 8
fill ~53~42~48 ~54~42~72 minecraft:planks 1
setblock ~53~48~48 minecraft:leaves 3
setblock ~53~51~48 minecraft:blue_glazed_terracotta 5
setblock ~53~57~48 minecraft:planks 1
setblock ~53~58~48 minecraft:concrete 0
fill ~53~60~48 ~53~61~48 minecraft:concrete 0
fill ~54~36~48 ~55~36~48 minecraft:concrete 0
fill ~54~46~48 ~54~46~50 minecraft:stone_block_slab 14
setblock ~54~51~48 minecraft:blue_glazed_terracotta 2
setblock ~54~52~48 minecraft:planks 1
fill ~54~53~48 ~54~55~48 minecraft:concrete 0
setblock ~54~56~48 minecraft:double_stone_block_slab 0
fill ~54~61~48 ~54~62~48 minecraft:concrete 0
fill ~55~35~48 ~56~35~48 minecraft:concrete 0
setblock ~55~47~48 minecraft:log 3
setblock ~55~51~48 minecraft:blue_glazed_terracotta 5
setblock ~55~53~48 minecraft:cauldron 0
setblock ~55~54~48 minecraft:lever 1
setblock ~55~58~48 minecraft:planks 2
fill ~55~61~48 ~57~61~48 minecraft:stone_block_slab 8
fill ~55~62~48 ~55~63~48 minecraft:concrete 0
setblock ~56~34~48 minecraft:concrete 0
fill ~56~41~48 ~57~41~69 minecraft:stone_block_slab 8
fill ~56~48~48 ~56~48~50 minecraft:leaves 3
setblock ~56~51~48 minecraft:blue_glazed_terracotta 2
fill ~56~62~48 ~57~62~48 minecraft:planks 1
fill ~56~63~48 ~57~63~48 minecraft:concrete 0
fill ~56~64~48 ~56~64~50 minecraft:concrete 0
fill ~57~33~48 ~58~33~48 minecraft:concrete 0
setblock ~57~34~48 minecraft:stained_glass 3
setblock ~57~48~48 minecraft:tallgrass 2
setblock ~57~51~48 minecraft:blue_glazed_terracotta 5
fill ~57~53~48 ~57~55~49 minecraft:glass_pane
fill ~57~56~48 ~57~56~49 minecraft:stone_block_slab 8
setblock ~57~64~48 minecraft:stained_glass 3
fill ~57~65~48 ~58~65~48 minecraft:concrete 0
fill ~58~32~48 ~60~32~48 minecraft:concrete 0
setblock ~58~36~48 minecraft:end_rod 0
fill ~58~37~48 ~58~40~48 minecraft:iron_bars
setblock ~58~41~48 minecraft:double_stone_block_slab 0
setblock ~58~43~48 minecraft:wool 7
setblock ~58~46~48 minecraft:stone_block_slab 14
setblock ~58~47~48 minecraft:dirt 0
setblock ~58~48~48 minecraft:red_flower 3
setblock ~58~51~48 minecraft:blue_glazed_terracotta 2
setblock ~58~54~48 minecraft:stone_button 2
setblock ~58~55~48 minecraft:tripwire_hook 2
setblock ~58~61~48 minecraft:sea_lantern
fill ~58~62~48 ~59~62~52 minecraft:prismarine 2
setblock ~58~63~48 minecraft:planks 2
fill ~58~66~48 ~59~66~48 minecraft:concrete 0
fill ~59~31~48 ~63~31~48 minecraft:concrete 0
setblock ~59~33~48 minecraft:log 2
fill ~59~34~48 ~59~35~48 minecraft:leaves 0
fill ~59~41~48 ~59~41~68 minecraft:stone_block_slab 8
fill ~59~43~48 ~60~43~48 minecraft:stone_block_slab 6
fill ~59~46~48 ~60~46~48 minecraft:stone_block_slab 8
fill ~59~47~48 ~60~47~48 minecraft:prismarine 2
setblock ~59~51~48 minecraft:blue_glazed_terracotta 5
fill ~59~67~48 ~61~67~48 minecraft:concrete 0
fill ~60~33~48 ~60~33~49 minecraft:birch_stairs 1
setblock ~60~51~48 minecraft:blue_glazed_terracotta 2
fill ~60~57~48 ~60~57~53 minecraft:prismarine 2
fill ~60~61~48 ~60~61~50 minecraft:stone_block_slab 8
setblock ~60~63~48 minecraft:quartz_stairs 0
fill ~60~66~48 ~60~66~53 minecraft:stone_block_slab 8
fill ~61~30~48 ~63~30~48 minecraft:concrete 0
fill ~61~32~48 ~63~32~89 minecraft:planks 1
fill ~61~41~48 ~63~41~50 minecraft:stone_block_slab 8
setblock ~61~43~48 minecraft:wool 7
setblock ~61~47~48 minecraft:leaves 3
setblock ~61~51~48 minecraft:blue_glazed_terracotta 5
fill ~61~52~48 ~62~52~48 minecraft:planks 1
fill ~61~53~48 ~62~55~48 minecraft:concrete 0
fill ~61~56~48 ~62~56~48 minecraft:double_stone_block_slab 0
fill ~61~57~48 ~61~57~50 minecraft:planks 1
fill ~61~58~48 ~61~60~50 minecraft:concrete 0
fill ~61~61~48 ~61~61~50 minecraft:double_stone_block_slab 0
fill ~61~66~48 ~61~66~49 minecraft:double_stone_block_slab 0
fill ~61~68~48 ~66~68~48 minecraft:concrete 0
setblock ~62~43~48 minecraft:birch_stairs 7
setblock ~62~44~48 minecraft:end_rod 1
setblock ~62~45~48 minecraft:quartz_block 2
setblock ~62~51~48 minecraft:blue_glazed_terracotta 2
fill ~62~66~48 ~62~66~49 minecraft:stone_block_slab 8
fill ~62~67~48 ~64~67~50 minecraft:planks 1
fill ~63~29~48 ~65~29~48 minecraft:stained_glass 3
setblock ~63~43~48 minecraft:birch_stairs 5
setblock ~63~51~48 minecraft:blue_glazed_terracotta 5
fill ~63~52~48 ~63~52~51 minecraft:wool 7
fill ~63~56~48 ~64~56~48 minecraft:stone_block_slab 8
setblock ~63~66~48 minecraft:sea_lantern
fill ~63~69~48 ~65~69~48 minecraft:stained_glass 3
fill ~64~31~48 ~65~31~66 minecraft:stone_block_slab 8
setblock ~64~36~48 minecraft:end_rod 0
fill ~64~37~48 ~64~40~48 minecraft:iron_bars
setblock ~64~41~48 minecraft:double_stone_block_slab 0
setblock ~64~51~48 minecraft:blue_glazed_terracotta 2
fill ~64~66~48 ~65~66~50 minecraft:stone_block_slab 8
fill ~65~41~48 ~65~41~61 minecraft:stone_block_slab 8
setblock ~65~51~48 minecraft:blue_glazed_terracotta 5
setblock ~65~57~48 minecraft:wool 7
setblock ~65~58~48 minecraft:dark_oak_door 0
fill ~65~60~48 ~65~60~52 minecraft:concrete 0
fill ~66~28~48 ~76~28~48 minecraft:concrete 0
setblock ~66~29~48 minecraft:concrete 0
setblock ~66~31~48 minecraft:sea_lantern
fill ~66~42~48 ~70~42~62 minecraft:stone 6
fill ~66~47~48 ~66~48~48 minecraft:leaves 3
setblock ~66~51~48 minecraft:blue_glazed_terracotta 2
setblock ~66~62~48 minecraft:wool 7
setblock ~66~63~48 minecraft:dark_oak_door 0
fill ~66~69~48 ~66~70~48 minecraft:concrete 0
fill ~67~31~48 ~68~31~56 minecraft:stone_block_slab 8
setblock ~67~33~48 minecraft:birch_stairs 3
fill ~67~49~48 ~70~49~48 minecraft:leaves 3
setblock ~67~51~48 minecraft:blue_glazed_terracotta 5
fill ~67~66~48 ~67~66~61 minecraft:stone_block_slab 8
fill ~67~68~48 ~70~68~48 minecraft:birch_stairs 7
fill ~67~70~48 ~76~70~48 minecraft:concrete 0
setblock ~68~51~48 minecraft:blue_glazed_terracotta 2
setblock ~68~56~48 minecraft:sea_lantern
fill ~68~63~48 ~69~63~49 minecraft:carpet 8
setblock ~68~66~48 minecraft:sea_lantern
setblock ~69~33~48 minecraft:birch_stairs 3
fill ~69~46~48 ~69~46~50 minecraft:stone_block_slab 14
setblock ~69~47~48 minecraft:dirt 0
fill ~69~50~48 ~70~50~48 minecraft:leaves 3
setblock ~69~51~48 minecraft:blue_glazed_terracotta 5
fill ~69~66~48 ~70~66~50 minecraft:stone_block_slab 8
setblock ~69~69~48 minecraft:flower_pot 0
fill ~70~48~48 ~70~48~50 minecraft:leaves 3
setblock ~70~51~48 minecraft:blue_glazed_terracotta 2
setblock ~71~43~48 minecraft:stone 0
fill ~71~44~48 ~71~46~48 minecraft:stained_hardened_clay 9
fill ~71~47~48 ~71~47~54 minecraft:iron_block
setblock ~71~48~48 minecraft:stone 0
fill ~71~49~48 ~71~51~48 minecraft:stained_hardened_clay 9
fill ~71~52~48 ~71~52~54 minecraft:iron_block
setblock ~71~53~48 minecraft:stone 0
fill ~71~54~48 ~71~56~48 minecraft:stained_hardened_clay 9
fill ~71~57~48 ~71~57~54 minecraft:iron_block
setblock ~71~58~48 minecraft:stone 0
fill ~71~59~48 ~71~61~48 minecraft:stained_hardened_clay 9
fill ~71~62~48 ~71~62~54 minecraft:iron_block
setblock ~71~63~48 minecraft:stone 0
fill ~71~64~48 ~71~66~48 minecraft:stained_hardened_clay 9
fill ~71~67~48 ~71~67~54 minecraft:iron_block
fill ~71~68~48 ~71~68~51 minecraft:stone 0
fill ~71~69~48 ~71~69~51 minecraft:stained_hardened_clay 9
fill ~72~32~48 ~74~32~60 minecraft:stone 0
setblock ~72~36~48 minecraft:stone_brick_stairs 6
setblock ~72~37~48 minecraft:stone_brick_stairs 3
fill ~73~42~48 ~75~42~63 minecraft:double_stone_block_slab 0
setblock ~75~32~48 minecraft:iron_block
fill ~75~37~48 ~78~37~48 minecraft:iron_block
setblock ~76~29~48 minecraft:concrete 0
setblock ~76~31~48 minecraft:sea_lantern
setblock ~76~42~48 minecraft:glowstone
setblock ~76~69~48 minecraft:concrete 0
fill ~77~29~48 ~79~29~48 minecraft:stained_glass 3
fill ~77~42~48 ~79~42~48 minecraft:quartz_block 2
fill ~77~69~48 ~79~69~48 minecraft:stained_glass 3
fill ~79~30~48 ~81~30~48 minecraft:concrete 0
fill ~79~68~48 ~81~68~48 minecraft:concrete 0
fill ~80~32~48 ~82~32~49 minecraft:iron_block
setblock ~80~42~48 minecraft:double_stone_block_slab 0
fill ~81~31~48 ~83~31~48 minecraft:concrete 0
setblock ~81~36~48 minecraft:sea_lantern
fill ~81~67~48 ~83~67~48 minecraft:concrete 0
fill ~83~32~48 ~84~32~48 minecraft:concrete 0
fill ~83~66~48 ~84~66~48 minecraft:concrete 0
fill ~84~33~48 ~85~33~48 minecraft:concrete 0
fill ~84~65~48 ~85~65~48 minecraft:concrete 0
setblock ~85~34~48 minecraft:stained_glass 3
setblock ~85~64~48 minecraft:stained_glass 3
fill ~86~34~48 ~86~35~48 minecraft:concrete 0
fill ~86~37~48 ~87~37~52 minecraft:iron_block
fill ~86~63~48 ~87~63~48 minecraft:concrete 0
setblock ~86~64~48 minecraft:concrete 0
fill ~87~35~48 ~87~36~48 minecraft:concrete 0
fill ~87~62~48 ~88~62~48 minecraft:concrete 0
fill ~88~36~48 ~88~37~48 minecraft:concrete 0
fill ~88~41~48 ~89~41~48 minecraft:stone_block_slab 8
fill ~88~42~48 ~89~42~52 minecraft:double_stone_block_slab 0
fill ~88~61~48 ~89~61~48 minecraft:concrete 0
fill ~89~37~48 ~89~38~48 minecraft:concrete 0
fill ~89~39~48 ~90~39~48 minecraft:stained_glass 3
fill ~89~59~48 ~90~59~48 minecraft:stained_glass 3
setblock ~89~60~48 minecraft:concrete 0
fill ~90~40~48 ~90~42~48 minecraft:concrete 0
fill ~90~57~48 ~91~57~48 minecraft:concrete 0
setblock ~90~58~48 minecraft:concrete 0
fill ~91~41~48 ~91~42~49 minecraft:concrete 0
setblock ~91~43~48 minecraft:concrete 0
setblock ~91~44~48 minecraft:stained_glass 3
setblock ~91~46~48 minecraft:sea_lantern
setblock ~91~47~48 minecraft:stone_block_slab 0
fill ~91~54~48 ~92~54~48 minecraft:stained_glass 3
fill ~91~55~48 ~91~56~48 minecraft:concrete 0
fill ~92~44~48 ~92~45~48 minecraft:concrete 0
fill ~92~46~48 ~92~47~48 minecraft:prismarine 2
setblock ~92~48~48 minecraft:concrete 0
setblock ~92~49~48 minecraft:stained_glass 3
setblock ~92~50~48 minecraft:concrete 0
fill ~92~51~48 ~92~52~48 minecraft:prismarine 2
setblock ~92~53~48 minecraft:concrete 0
fill ~93~44~48 ~94~44~49 minecraft:stained_glass 3
setblock ~95~44~48 minecraft:quartz_stairs 6
fill ~95~45~48 ~96~45~48 minecraft:stone_block_slab 6
setblock ~96~44~48 minecraft:quartz_stairs 5
setblock ~106~49~48 minecraft:stained_glass 4
setblock ~107~48~48 minecraft:stone_block_slab 14
setblock ~107~49~48 minecraft:glowstone
setblock ~107~50~48 minecraft:stone_block_slab 6
fill ~108~49~48 ~109~49~50 minecraft:stained_glass 0
fill ~128~48~48 ~128~48~49 minecraft:stone_block_slab 14
fill ~128~49~48 ~128~49~49 minecraft:sea_lantern
fill ~128~50~48 ~128~50~49 minecraft:stone_block_slab 6
fill ~18~49~49 ~19~49~50 minecraft:stone_block_slab 6
fill ~27~49~49 ~27~49~50 minecraft:stained_glass 4
fill ~28~49~49 ~28~49~60 minecraft:stained_glass 0
fill ~35~49~49 ~35~49~50 minecraft:stained_glass 4
fill ~36~48~49 ~37~48~49 minecraft:stone_block_slab 14
fill ~36~49~49 ~37~49~49 minecraft:glowstone
fill ~36~50~49 ~37~50~49 minecraft:stone_block_slab 6
setblock ~49~44~49 minecraft:stained_glass 3
setblock ~49~45~49 minecraft:concrete 0
fill ~49~46~49 ~49~47~49 minecraft:prismarine 2
setblock ~49~48~49 minecraft:concrete 0
setblock ~49~49~49 minecraft:stained_glass 3
setblock ~49~50~49 minecraft:concrete 0
fill ~49~51~49 ~49~52~49 minecraft:prismarine 2
setblock ~49~53~49 minecraft:concrete 0
setblock ~49~54~49 minecraft:stained_glass 3
fill ~50~41~49 ~51~42~49 minecraft:concrete 0
setblock ~50~43~49 minecraft:concrete 0
fill ~50~46~49 ~50~46~54 minecraft:stone_block_slab 14
setblock ~50~47~49 minecraft:prismarine 2
setblock ~50~51~49 minecraft:blue_glazed_terracotta 4
fill ~50~52~49 ~51~52~51 minecraft:wool 7
fill ~50~55~49 ~50~57~49 minecraft:concrete 0
setblock ~51~39~49 minecraft:stained_glass 3
setblock ~51~40~49 minecraft:concrete 0
setblock ~51~47~49 minecraft:glowstone
setblock ~51~51~49 minecraft:blue_glazed_terracotta 3
fill ~51~53~49 ~52~53~49 minecraft:bed 2
fill ~51~56~49 ~51~56~52 minecraft:stone_block_slab 8
setblock ~51~57~49 minecraft:planks 1
setblock ~51~58~49 minecraft:concrete 0
setblock ~51~59~49 minecraft:stained_glass 3
fill ~52~37~49 ~52~38~49 minecraft:concrete 0
fill ~52~41~49 ~53~41~53 minecraft:stone_block_slab 8
fill ~52~42~49 ~52~42~72 minecraft:planks 1
fill ~52~46~49 ~52~46~52 minecraft:stone_block_slab 14
setblock ~52~51~49 minecraft:blue_glazed_terracotta 4
fill ~52~57~49 ~54~57~53 minecraft:wool 7
fill ~52~58~49 ~53~58~49 minecraft:bed 2
fill ~52~60~49 ~52~61~49 minecraft:concrete 0
setblock ~53~36~49 minecraft:concrete 0
setblock ~53~48~49 minecraft:double_plant 3
setblock ~53~51~49 minecraft:blue_glazed_terracotta 3
fill ~53~61~49 ~54~61~50 minecraft:stone_block_slab 8
setblock ~53~62~49 minecraft:concrete 0
fill ~54~34~49 ~55~34~49 minecraft:stained_glass 3
setblock ~54~35~49 minecraft:concrete 0
setblock ~54~39~49 minecraft:end_rod 0
setblock ~54~40~49 minecraft:iron_bars
setblock ~54~41~49 minecraft:double_stone_block_slab 0
setblock ~54~51~49 minecraft:blue_glazed_terracotta 4
fill ~54~52~49 ~54~52~55 minecraft:wool 7
fill ~54~56~49 ~54~56~55 minecraft:stone_block_slab 8
fill ~54~62~49 ~56~62~49 minecraft:planks 1
fill ~54~63~49 ~56~63~49 minecraft:concrete 0
fill ~54~64~49 ~55~64~49 minecraft:stained_glass 3
fill ~55~33~49 ~56~33~49 minecraft:concrete 0
fill ~55~46~49 ~56~46~49 minecraft:stone_block_slab 14
fill ~55~47~49 ~55~47~50 minecraft:dirt 0
setblock ~55~51~49 minecraft:blue_glazed_terracotta 3
setblock ~55~52~49 minecraft:planks 1
fill ~55~53~49 ~55~55~49 minecraft:concrete 0
setblock ~55~56~49 minecraft:double_stone_block_slab 0
setblock ~55~57~49 minecraft:planks 1
fill ~55~58~49 ~55~60~49 minecraft:concrete 0
setblock ~55~61~49 minecraft:double_stone_block_slab 0
fill ~55~65~49 ~56~65~49 minecraft:concrete 0
fill ~56~32~49 ~58~32~49 minecraft:concrete 0
setblock ~56~51~49 minecraft:blue_glazed_terracotta 4
setblock ~56~56~49 minecraft:stone_block_slab 8
setblock ~56~57~49 minecraft:prismarine 2
setblock ~56~58~49 minecraft:cauldron 0
setblock ~56~59~49 minecraft:lever 1
fill ~56~61~49 ~58~61~49 minecraft:stone_block_slab 8
fill ~56~66~49 ~57~66~49 minecraft:concrete 0
fill ~57~33~49 ~58~33~49 minecraft:birch_stairs 3
fill ~57~46~49 ~58~46~49 minecraft:stone_block_slab 8
fill ~57~47~49 ~58~47~49 minecraft:prismarine 2
setblock ~57~51~49 minecraft:blue_glazed_terracotta 3
fill ~57~62~49 ~57~62~50 minecraft:prismarine 2
setblock ~57~63~49 minecraft:planks 2
fill ~58~31~49 ~60~31~49 minecraft:concrete 0
fill ~58~41~49 ~58~41~53 minecraft:stone_block_slab 8
setblock ~58~51~49 minecraft:blue_glazed_terracotta 4
fill ~58~52~49 ~59~52~49 minecraft:planks 1
fill ~58~53~49 ~59~55~49 minecraft:concrete 0
