setblock ~31~98~6 minecraft:concrete 15
setblock ~33~98~6 minecraft:concrete 11
setblock ~34~98~6 minecraft:sea_lantern
setblock ~35~98~6 minecraft:concrete 11
setblock ~37~98~6 minecraft:concrete 15
fill ~29~98~7 ~39~98~8 minecraft:double_stone_block_slab 6
fill ~31~97~7 ~31~97~8 minecraft:concrete 15
fill ~31~99~7 ~31~99~8 minecraft:concrete 15
fill ~33~97~7 ~33~97~8 minecraft:concrete 11
fill ~33~99~7 ~33~99~8 minecraft:concrete 11
setblock ~34~97~7 minecraft:sea_lantern
setblock ~34~99~7 minecraft:sea_lantern
fill ~35~97~7 ~35~97~8 minecraft:concrete 11
fill ~35~99~7 ~35~99~8 minecraft:concrete 11
fill ~37~97~7 ~37~97~8 minecraft:concrete 15
fill ~37~99~7 ~37~99~8 minecraft:concrete 15
fill ~25~98~8 ~28~98~9 minecraft:double_stone_block_slab 6
fill ~31~95~8 ~31~96~8 minecraft:concrete 15
setblock ~31~100~8 minecraft:concrete 15
fill ~33~94~8 ~33~96~8 minecraft:concrete 11
fill ~33~100~8 ~33~101~8 minecraft:concrete 11
fill ~34~94~8 ~34~96~8 minecraft:sea_lantern
fill ~34~100~8 ~34~101~8 minecraft:sea_lantern
fill ~35~94~8 ~35~96~8 minecraft:concrete 11
fill ~35~100~8 ~35~101~8 minecraft:concrete 11
fill ~37~95~8 ~37~96~8 minecraft:concrete 15
setblock ~37~100~8 minecraft:concrete 15
fill ~40~98~8 ~43~98~9 minecraft:double_stone_block_slab 6
fill ~23~98~9 ~24~98~10 minecraft:double_stone_block_slab 6
fill ~29~94~9 ~30~94~9 minecraft:double_stone_block_slab 6
fill ~29~95~9 ~39~100~9 minecraft:stained_glass 11
fill ~29~101~9 ~30~101~9 minecraft:double_stone_block_slab 6
setblock ~31~94~9 minecraft:concrete 15
setblock ~31~101~9 minecraft:concrete 15
fill ~32~94~9 ~36~94~9 minecraft:double_stone_block_slab 6
fill ~32~101~9 ~36~101~9 minecraft:double_stone_block_slab 6
setblock ~33~93~9 minecraft:concrete 11
setblock ~33~102~9 minecraft:concrete 11
setblock ~34~93~9 minecraft:sea_lantern
setblock ~34~102~9 minecraft:sea_lantern
setblock ~35~93~9 minecraft:concrete 11
setblock ~35~102~9 minecraft:concrete 11
setblock ~37~94~9 minecraft:concrete 15
setblock ~37~101~9 minecraft:concrete 15
fill ~38~94~9 ~39~94~9 minecraft:double_stone_block_slab 6
fill ~38~101~9 ~39~101~9 minecraft:double_stone_block_slab 6
fill ~44~98~9 ~45~98~10 minecraft:double_stone_block_slab 6
fill ~21~98~10 ~22~98~11 minecraft:double_stone_block_slab 6
fill ~25~94~10 ~28~94~10 minecraft:double_stone_block_slab 6
fill ~25~95~10 ~28~100~10 minecraft:stained_glass 11
fill ~25~101~10 ~28~101~10 minecraft:double_stone_block_slab 6
fill ~29~93~10 ~30~93~10 minecraft:double_stone_block_slab 6
fill ~29~102~10 ~30~102~10 minecraft:double_stone_block_slab 6
setblock ~31~93~10 minecraft:concrete 15
setblock ~31~102~10 minecraft:concrete 15
fill ~32~93~10 ~36~93~10 minecraft:double_stone_block_slab 6
fill ~32~102~10 ~36~102~10 minecraft:double_stone_block_slab 6
setblock ~33~92~10 minecraft:concrete 11
setblock ~33~103~10 minecraft:concrete 11
setblock ~34~92~10 minecraft:sea_lantern
setblock ~34~103~10 minecraft:sea_lantern
setblock ~35~92~10 minecraft:concrete 11
setblock ~35~103~10 minecraft:concrete 11
setblock ~37~93~10 minecraft:concrete 15
setblock ~37~102~10 minecraft:concrete 15
fill ~38~93~10 ~39~93~10 minecraft:double_stone_block_slab 6
fill ~38~102~10 ~39~102~10 minecraft:double_stone_block_slab 6
fill ~40~94~10 ~43~94~10 minecraft:double_stone_block_slab 6
fill ~40~95~10 ~43~100~10 minecraft:stained_glass 11
fill ~40~101~10 ~43~101~10 minecraft:double_stone_block_slab 6
fill ~46~98~10 ~47~98~11 minecraft:double_stone_block_slab 6
fill ~19~98~11 ~20~98~12 minecraft:double_stone_block_slab 6
fill ~23~94~11 ~24~94~11 minecraft:double_stone_block_slab 6
fill ~23~95~11 ~24~100~11 minecraft:stained_glass 11
fill ~23~101~11 ~24~101~11 minecraft:double_stone_block_slab 6
fill ~25~93~11 ~29~93~11 minecraft:double_stone_block_slab 6
fill ~25~102~11 ~29~102~11 minecraft:double_stone_block_slab 6
fill ~30~92~11 ~30~92~12 minecraft:double_stone_block_slab 6
fill ~30~103~11 ~30~103~12 minecraft:double_stone_block_slab 6
fill ~31~92~11 ~31~92~12 minecraft:concrete 15
fill ~31~103~11 ~31~103~12 minecraft:concrete 15
fill ~32~92~11 ~36~92~12 minecraft:double_stone_block_slab 6
fill ~32~103~11 ~36~103~12 minecraft:double_stone_block_slab 6
fill ~33~91~11 ~33~91~12 minecraft:concrete 11
fill ~33~104~11 ~33~104~12 minecraft:concrete 11
fill ~34~91~11 ~34~91~12 minecraft:sea_lantern
fill ~34~104~11 ~34~104~12 minecraft:sea_lantern
fill ~35~91~11 ~35~91~12 minecraft:concrete 11
fill ~35~104~11 ~35~104~12 minecraft:concrete 11
fill ~37~92~11 ~37~92~12 minecraft:concrete 15
fill ~37~103~11 ~37~103~12 minecraft:concrete 15
fill ~38~92~11 ~38~92~12 minecraft:double_stone_block_slab 6
fill ~38~103~11 ~38~103~12 minecraft:double_stone_block_slab 6
fill ~39~93~11 ~43~93~11 minecraft:double_stone_block_slab 6
fill ~39~102~11 ~43~102~11 minecraft:double_stone_block_slab 6
fill ~44~94~11 ~45~94~11 minecraft:double_stone_block_slab 6
fill ~44~95~11 ~45~100~11 minecraft:stained_glass 11
fill ~44~101~11 ~45~101~11 minecraft:double_stone_block_slab 6
fill ~48~98~11 ~49~98~12 minecraft:double_stone_block_slab 6
fill ~17~98~12 ~18~98~13 minecraft:double_stone_block_slab 6
fill ~21~94~12 ~22~94~12 minecraft:double_stone_block_slab 6
fill ~21~95~12 ~22~100~12 minecraft:stained_glass 11
fill ~21~101~12 ~22~101~12 minecraft:double_stone_block_slab 6
fill ~23~93~12 ~25~93~12 minecraft:double_stone_block_slab 6
fill ~23~102~12 ~25~102~12 minecraft:double_stone_block_slab 6
fill ~26~92~12 ~29~92~12 minecraft:double_stone_block_slab 6
fill ~26~103~12 ~29~103~12 minecraft:double_stone_block_slab 6
fill ~39~92~12 ~42~92~12 minecraft:double_stone_block_slab 6
fill ~39~103~12 ~42~103~12 minecraft:double_stone_block_slab 6
fill ~43~93~12 ~45~93~12 minecraft:double_stone_block_slab 6
fill ~43~102~12 ~45~102~12 minecraft:double_stone_block_slab 6
fill ~46~94~12 ~47~94~12 minecraft:double_stone_block_slab 6
fill ~46~95~12 ~47~100~12 minecraft:stained_glass 11
fill ~46~101~12 ~47~101~12 minecraft:double_stone_block_slab 6
fill ~50~98~12 ~51~98~13 minecraft:double_stone_block_slab 6
fill ~16~98~13 ~16~98~14 minecraft:double_stone_block_slab 6
fill ~19~94~13 ~20~94~13 minecraft:double_stone_block_slab 6
fill ~19~95~13 ~20~100~13 minecraft:stained_glass 11
fill ~19~101~13 ~20~101~13 minecraft:double_stone_block_slab 6
fill ~21~93~13 ~23~93~13 minecraft:double_stone_block_slab 6
fill ~21~102~13 ~23~102~13 minecraft:double_stone_block_slab 6
fill ~24~92~13 ~26~92~13 minecraft:double_stone_block_slab 6
fill ~24~103~13 ~26~103~13 minecraft:double_stone_block_slab 6
fill ~27~91~13 ~30~91~15 minecraft:double_stone_block_slab 6
fill ~27~104~13 ~30~104~15 minecraft:double_stone_block_slab 6
fill ~31~91~13 ~31~91~15 minecraft:concrete 15
fill ~31~104~13 ~31~104~15 minecraft:concrete 15
fill ~32~91~13 ~36~91~15 minecraft:double_stone_block_slab 6
fill ~32~104~13 ~36~104~15 minecraft:double_stone_block_slab 6
fill ~33~90~13 ~33~90~15 minecraft:concrete 11
fill ~33~105~13 ~33~105~15 minecraft:concrete 11
fill ~34~90~13 ~34~90~15 minecraft:sea_lantern
fill ~34~105~13 ~34~105~15 minecraft:sea_lantern
fill ~35~90~13 ~35~90~15 minecraft:concrete 11
fill ~35~105~13 ~35~105~15 minecraft:concrete 11
fill ~37~91~13 ~37~91~15 minecraft:concrete 15
fill ~37~104~13 ~37~104~15 minecraft:concrete 15
fill ~38~91~13 ~41~91~15 minecraft:double_stone_block_slab 6
fill ~38~104~13 ~41~104~15 minecraft:double_stone_block_slab 6
fill ~42~92~13 ~44~92~13 minecraft:double_stone_block_slab 6
fill ~42~103~13 ~44~103~13 minecraft:double_stone_block_slab 6
fill ~45~93~13 ~47~93~13 minecraft:double_stone_block_slab 6
fill ~45~102~13 ~47~102~13 minecraft:double_stone_block_slab 6
fill ~48~94~13 ~49~94~13 minecraft:double_stone_block_slab 6
fill ~48~95~13 ~49~100~13 minecraft:stained_glass 11
fill ~48~101~13 ~49~101~13 minecraft:double_stone_block_slab 6
fill ~52~98~13 ~52~98~14 minecraft:double_stone_block_slab 6
fill ~15~98~14 ~15~98~15 minecraft:double_stone_block_slab 6
fill ~17~94~14 ~18~94~14 minecraft:double_stone_block_slab 6
fill ~17~95~14 ~18~100~14 minecraft:stained_glass 11
fill ~17~101~14 ~18~101~14 minecraft:double_stone_block_slab 6
fill ~19~93~14 ~21~93~14 minecraft:double_stone_block_slab 6
fill ~19~102~14 ~21~102~14 minecraft:double_stone_block_slab 6
fill ~22~92~14 ~24~92~14 minecraft:double_stone_block_slab 6
fill ~22~103~14 ~24~103~14 minecraft:double_stone_block_slab 6
fill ~25~91~14 ~26~91~16 minecraft:double_stone_block_slab 6
fill ~25~104~14 ~26~104~16 minecraft:double_stone_block_slab 6
fill ~42~91~14 ~43~91~16 minecraft:double_stone_block_slab 6
fill ~42~104~14 ~43~104~16 minecraft:double_stone_block_slab 6
fill ~44~92~14 ~46~92~14 minecraft:double_stone_block_slab 6
fill ~44~103~14 ~46~103~14 minecraft:double_stone_block_slab 6
fill ~47~93~14 ~49~93~14 minecraft:double_stone_block_slab 6
fill ~47~102~14 ~49~102~14 minecraft:double_stone_block_slab 6
fill ~50~94~14 ~51~94~14 minecraft:double_stone_block_slab 6
fill ~50~95~14 ~51~100~14 minecraft:stained_glass 11
fill ~50~101~14 ~51~101~14 minecraft:double_stone_block_slab 6
fill ~53~98~14 ~53~98~15 minecraft:double_stone_block_slab 6
fill ~14~98~15 ~14~98~16 minecraft:double_stone_block_slab 6
setblock ~16~94~15 minecraft:double_stone_block_slab 6
fill ~16~95~15 ~16~100~15 minecraft:stained_glass 11
setblock ~16~101~15 minecraft:double_stone_block_slab 6
fill ~17~93~15 ~19~93~15 minecraft:double_stone_block_slab 6
fill ~17~102~15 ~19~102~15 minecraft:double_stone_block_slab 6
fill ~20~92~15 ~22~92~15 minecraft:double_stone_block_slab 6
fill ~20~103~15 ~22~103~15 minecraft:double_stone_block_slab 6
fill ~23~91~15 ~24~91~17 minecraft:double_stone_block_slab 6
fill ~23~104~15 ~24~104~17 minecraft:double_stone_block_slab 6
fill ~44~91~15 ~45~91~17 minecraft:double_stone_block_slab 6
fill ~44~104~15 ~45~104~17 minecraft:double_stone_block_slab 6
fill ~46~92~15 ~48~92~15 minecraft:double_stone_block_slab 6
fill ~46~103~15 ~48~103~15 minecraft:double_stone_block_slab 6
fill ~49~93~15 ~51~93~15 minecraft:double_stone_block_slab 6
fill ~49~102~15 ~51~102~15 minecraft:double_stone_block_slab 6
setblock ~52~94~15 minecraft:double_stone_block_slab 6
fill ~52~95~15 ~52~100~15 minecraft:stained_glass 11
setblock ~52~101~15 minecraft:double_stone_block_slab 6
fill ~54~98~15 ~54~98~16 minecraft:double_stone_block_slab 6
fill ~13~98~16 ~13~98~17 minecraft:double_stone_block_slab 6
setblock ~15~94~16 minecraft:double_stone_block_slab 6
fill ~15~95~16 ~15~100~16 minecraft:stained_glass 11
setblock ~15~101~16 minecraft:double_stone_block_slab 6
fill ~16~93~16 ~17~93~16 minecraft:double_stone_block_slab 6
fill ~16~102~16 ~17~102~16 minecraft:double_stone_block_slab 6
fill ~18~92~16 ~20~92~16 minecraft:double_stone_block_slab 6
fill ~18~103~16 ~20~103~16 minecraft:double_stone_block_slab 6
fill ~21~91~16 ~22~91~18 minecraft:double_stone_block_slab 6
fill ~21~104~16 ~22~104~18 minecraft:double_stone_block_slab 6
fill ~27~90~16 ~30~90~31 minecraft:double_stone_block_slab 6
fill ~27~105~16 ~30~105~31 minecraft:double_stone_block_slab 6
fill ~31~90~16 ~31~90~31 minecraft:concrete 15
fill ~31~105~16 ~31~105~31 minecraft:concrete 15
fill ~32~90~16 ~36~90~60 minecraft:double_stone_block_slab 6
fill ~32~105~16 ~36~105~32 minecraft:double_stone_block_slab 6
fill ~33~0~16 ~33~4~16 minecraft:concrete 11
fill ~33~89~16 ~33~89~18 minecraft:concrete 11
fill ~33~106~16 ~33~106~21 minecraft:concrete 11
fill ~34~0~16 ~34~4~16 minecraft:sea_lantern
fill ~34~89~16 ~34~89~21 minecraft:sea_lantern
fill ~34~106~16 ~34~106~28 minecraft:sea_lantern
fill ~35~0~16 ~35~4~16 minecraft:concrete 11
fill ~35~89~16 ~35~89~18 minecraft:concrete 11
fill ~35~106~16 ~35~106~21 minecraft:concrete 11
fill ~37~90~16 ~37~90~31 minecraft:concrete 15
fill ~37~105~16 ~37~105~31 minecraft:concrete 15
fill ~38~90~16 ~41~90~31 minecraft:double_stone_block_slab 6
fill ~38~105~16 ~41~105~31 minecraft:double_stone_block_slab 6
fill ~46~91~16 ~47~91~18 minecraft:double_stone_block_slab 6
fill ~46~104~16 ~47~104~18 minecraft:double_stone_block_slab 6
fill ~48~92~16 ~50~92~16 minecraft:double_stone_block_slab 6
fill ~48~103~16 ~50~103~16 minecraft:double_stone_block_slab 6
fill ~51~93~16 ~52~93~16 minecraft:double_stone_block_slab 6
fill ~51~102~16 ~52~102~16 minecraft:double_stone_block_slab 6
setblock ~53~94~16 minecraft:double_stone_block_slab 6
fill ~53~95~16 ~53~100~16 minecraft:stained_glass 11
setblock ~53~101~16 minecraft:double_stone_block_slab 6
fill ~55~98~16 ~55~98~17 minecraft:double_stone_block_slab 6
fill ~12~98~17 ~12~98~18 minecraft:double_stone_block_slab 6
setblock ~14~94~17 minecraft:double_stone_block_slab 6
fill ~14~95~17 ~14~100~17 minecraft:stained_glass 11
setblock ~14~101~17 minecraft:double_stone_block_slab 6
fill ~15~93~17 ~16~93~17 minecraft:double_stone_block_slab 6
fill ~15~102~17 ~16~102~17 minecraft:double_stone_block_slab 6
fill ~17~92~17 ~18~92~17 minecraft:double_stone_block_slab 6
fill ~17~103~17 ~18~103~17 minecraft:double_stone_block_slab 6
fill ~19~91~17 ~20~91~19 minecraft:double_stone_block_slab 6
fill ~19~104~17 ~20~104~19 minecraft:double_stone_block_slab 6
fill ~25~90~17 ~26~90~34 minecraft:double_stone_block_slab 6
fill ~25~105~17 ~26~105~34 minecraft:double_stone_block_slab 6
fill ~30~0~17 ~32~4~17 minecraft:double_stone_block_slab 6
fill ~33~1~17 ~38~4~17 minecraft:double_stone_block_slab 6
setblock ~33~5~17 minecraft:concrete 11
setblock ~34~5~17 minecraft:sea_lantern
setblock ~35~5~17 minecraft:concrete 11
fill ~36~0~17 ~38~0~17 minecraft:double_stone_block_slab 6
fill ~42~90~17 ~43~90~34 minecraft:double_stone_block_slab 6
fill ~42~105~17 ~43~105~34 minecraft:double_stone_block_slab 6
fill ~48~91~17 ~49~91~19 minecraft:double_stone_block_slab 6
fill ~48~104~17 ~49~104~19 minecraft:double_stone_block_slab 6
fill ~50~92~17 ~51~92~17 minecraft:double_stone_block_slab 6
fill ~50~103~17 ~51~103~17 minecraft:double_stone_block_slab 6
fill ~52~93~17 ~53~93~17 minecraft:double_stone_block_slab 6
fill ~52~102~17 ~53~102~17 minecraft:double_stone_block_slab 6
setblock ~54~94~17 minecraft:double_stone_block_slab 6
fill ~54~95~17 ~54~100~17 minecraft:stained_glass 11
setblock ~54~101~17 minecraft:double_stone_block_slab 6
fill ~56~98~17 ~56~98~18 minecraft:double_stone_block_slab 6
fill ~11~98~18 ~11~98~19 minecraft:double_stone_block_slab 6
setblock ~13~94~18 minecraft:double_stone_block_slab 6
fill ~13~95~18 ~13~100~18 minecraft:stained_glass 11
setblock ~13~101~18 minecraft:double_stone_block_slab 6
fill ~14~93~18 ~15~93~18 minecraft:double_stone_block_slab 6
fill ~14~102~18 ~15~102~18 minecraft:double_stone_block_slab 6
fill ~16~92~18 ~17~92~18 minecraft:double_stone_block_slab 6
fill ~16~103~18 ~17~103~18 minecraft:double_stone_block_slab 6
fill ~18~91~18 ~18~91~21 minecraft:double_stone_block_slab 6
fill ~18~104~18 ~18~104~21 minecraft:double_stone_block_slab 6
fill ~23~90~18 ~24~90~34 minecraft:double_stone_block_slab 6
fill ~23~105~18 ~24~105~34 minecraft:double_stone_block_slab 6
fill ~26~89~18 ~32~89~18 minecraft:concrete 11
fill ~27~0~18 ~29~4~18 minecraft:double_stone_block_slab 6
fill ~30~5~18 ~38~5~18 minecraft:double_stone_block_slab 6
setblock ~33~6~18 minecraft:concrete 11
setblock ~34~6~18 minecraft:sea_lantern
setblock ~35~6~18 minecraft:concrete 11
fill ~36~89~18 ~42~89~18 minecraft:concrete 11
fill ~39~0~18 ~41~4~18 minecraft:double_stone_block_slab 6
fill ~44~90~18 ~45~90~34 minecraft:double_stone_block_slab 6
fill ~44~105~18 ~45~105~34 minecraft:double_stone_block_slab 6
fill ~50~91~18 ~50~91~21 minecraft:double_stone_block_slab 6
fill ~50~104~18 ~50~104~21 minecraft:double_stone_block_slab 6
fill ~51~92~18 ~52~92~18 minecraft:double_stone_block_slab 6
fill ~51~103~18 ~52~103~18 minecraft:double_stone_block_slab 6
fill ~53~93~18 ~54~93~18 minecraft:double_stone_block_slab 6
fill ~53~102~18 ~54~102~18 minecraft:double_stone_block_slab 6
setblock ~55~94~18 minecraft:double_stone_block_slab 6
fill ~55~95~18 ~55~100~18 minecraft:stained_glass 11
setblock ~55~101~18 minecraft:double_stone_block_slab 6
fill ~57~98~18 ~57~98~19 minecraft:double_stone_block_slab 6
fill ~10~98~19 ~10~98~20 minecraft:double_stone_block_slab 6
setblock ~12~94~19 minecraft:double_stone_block_slab 6
fill ~12~95~19 ~12~100~19 minecraft:stained_glass 11
setblock ~12~101~19 minecraft:double_stone_block_slab 6
fill ~13~93~19 ~14~93~19 minecraft:double_stone_block_slab 6
fill ~13~102~19 ~14~102~19 minecraft:double_stone_block_slab 6
fill ~15~92~19 ~16~92~19 minecraft:double_stone_block_slab 6
fill ~15~103~19 ~16~103~19 minecraft:double_stone_block_slab 6
fill ~17~91~19 ~17~91~22 minecraft:double_stone_block_slab 6
fill ~17~104~19 ~17~104~22 minecraft:double_stone_block_slab 6
fill ~21~90~19 ~22~90~34 minecraft:double_stone_block_slab 6
fill ~21~105~19 ~22~105~34 minecraft:double_stone_block_slab 6
fill ~24~0~19 ~26~4~19 minecraft:double_stone_block_slab 6
fill ~24~89~19 ~25~89~19 minecraft:concrete 11
fill ~26~89~19 ~33~89~19 minecraft:sea_lantern
fill ~27~5~19 ~30~5~19 minecraft:double_stone_block_slab 6
fill ~31~6~19 ~37~6~20 minecraft:double_stone_block_slab 6
fill ~33~7~19 ~33~7~20 minecraft:concrete 11
fill ~34~7~19 ~34~7~20 minecraft:sea_lantern
fill ~35~7~19 ~35~7~20 minecraft:concrete 11
fill ~35~89~19 ~42~89~19 minecraft:sea_lantern
fill ~38~5~19 ~41~5~19 minecraft:double_stone_block_slab 6
fill ~42~0~19 ~44~4~19 minecraft:double_stone_block_slab 6
fill ~43~89~19 ~44~89~19 minecraft:concrete 11
fill ~46~90~19 ~47~90~34 minecraft:double_stone_block_slab 6
fill ~46~105~19 ~47~105~34 minecraft:double_stone_block_slab 6
fill ~51~91~19 ~51~91~22 minecraft:double_stone_block_slab 6
fill ~51~104~19 ~51~104~22 minecraft:double_stone_block_slab 6
fill ~52~92~19 ~53~92~19 minecraft:double_stone_block_slab 6
fill ~52~103~19 ~53~103~19 minecraft:double_stone_block_slab 6
fill ~54~93~19 ~55~93~19 minecraft:double_stone_block_slab 6
fill ~54~102~19 ~55~102~19 minecraft:double_stone_block_slab 6
setblock ~56~94~19 minecraft:double_stone_block_slab 6
fill ~56~95~19 ~56~100~19 minecraft:stained_glass 11
setblock ~56~101~19 minecraft:double_stone_block_slab 6
fill ~58~98~19 ~58~98~20 minecraft:double_stone_block_slab 6
fill ~9~98~20 ~9~98~22 minecraft:double_stone_block_slab 6
setblock ~11~94~20 minecraft:double_stone_block_slab 6
fill ~11~95~20 ~11~100~20 minecraft:stained_glass 11
setblock ~11~101~20 minecraft:double_stone_block_slab 6
fill ~12~93~20 ~13~93~20 minecraft:double_stone_block_slab 6
fill ~12~102~20 ~13~102~20 minecraft:double_stone_block_slab 6
fill ~14~92~20 ~15~92~20 minecraft:double_stone_block_slab 6
fill ~14~103~20 ~15~103~20 minecraft:double_stone_block_slab 6
fill ~16~91~20 ~16~91~23 minecraft:double_stone_block_slab 6
fill ~16~104~20 ~16~104~23 minecraft:double_stone_block_slab 6
setblock ~19~91~20 minecraft:double_stone_block_slab 6
setblock ~19~104~20 minecraft:double_stone_block_slab 6
fill ~20~90~20 ~20~90~34 minecraft:double_stone_block_slab 6
fill ~20~105~20 ~20~105~34 minecraft:double_stone_block_slab 6
fill ~22~89~20 ~23~89~20 minecraft:concrete 11
fill ~23~0~20 ~24~4~20 minecraft:double_stone_block_slab 6
fill ~24~89~20 ~25~89~20 minecraft:sea_lantern
fill ~25~5~20 ~27~5~20 minecraft:double_stone_block_slab 6
fill ~26~89~20 ~33~89~20 minecraft:concrete 11
fill ~28~6~20 ~30~6~20 minecraft:double_stone_block_slab 6
fill ~35~89~20 ~42~89~20 minecraft:concrete 11
fill ~38~6~20 ~40~6~20 minecraft:double_stone_block_slab 6
fill ~41~5~20 ~43~5~20 minecraft:double_stone_block_slab 6
fill ~43~89~20 ~44~89~20 minecraft:sea_lantern
fill ~44~1~20 ~45~4~20 minecraft:double_stone_block_slab 6
setblock ~45~0~20 minecraft:double_stone_block_slab 6
fill ~45~89~20 ~46~89~20 minecraft:concrete 11
fill ~48~90~20 ~48~90~34 minecraft:double_stone_block_slab 6
fill ~48~105~20 ~48~105~34 minecraft:double_stone_block_slab 6
setblock ~49~91~20 minecraft:double_stone_block_slab 6
setblock ~49~104~20 minecraft:double_stone_block_slab 6
fill ~52~91~20 ~52~91~23 minecraft:double_stone_block_slab 6
fill ~52~104~20 ~52~104~23 minecraft:double_stone_block_slab 6
fill ~53~92~20 ~54~92~20 minecraft:double_stone_block_slab 6
fill ~53~103~20 ~54~103~20 minecraft:double_stone_block_slab 6
fill ~55~93~20 ~56~93~20 minecraft:double_stone_block_slab 6
fill ~55~102~20 ~56~102~20 minecraft:double_stone_block_slab 6
setblock ~57~94~20 minecraft:double_stone_block_slab 6
fill ~57~95~20 ~57~100~20 minecraft:stained_glass 11
setblock ~57~101~20 minecraft:double_stone_block_slab 6
fill ~59~98~20 ~59~98~22 minecraft:double_stone_block_slab 6
fill ~8~98~21 ~8~98~24 minecraft:double_stone_block_slab 6
fill ~10~94~21 ~10~94~22 minecraft:double_stone_block_slab 6
fill ~10~95~21 ~10~100~22 minecraft:stained_glass 11
fill ~10~101~21 ~10~101~22 minecraft:double_stone_block_slab 6
fill ~11~93~21 ~12~93~21 minecraft:double_stone_block_slab 6
fill ~11~102~21 ~12~102~21 minecraft:double_stone_block_slab 6
fill ~13~92~21 ~14~92~21 minecraft:double_stone_block_slab 6
fill ~13~103~21 ~14~103~21 minecraft:double_stone_block_slab 6
fill ~15~91~21 ~15~91~24 minecraft:double_stone_block_slab 6
fill ~15~104~21 ~15~104~24 minecraft:double_stone_block_slab 6
fill ~19~90~21 ~19~90~34 minecraft:double_stone_block_slab 6
fill ~19~105~21 ~19~105~34 minecraft:double_stone_block_slab 6
fill ~21~0~21 ~21~4~21 minecraft:concrete 15
setblock ~21~89~21 minecraft:concrete 11
fill ~22~0~21 ~22~4~21 minecraft:double_stone_block_slab 6
fill ~22~89~21 ~23~89~21 minecraft:sea_lantern
fill ~23~5~21 ~25~5~21 minecraft:double_stone_block_slab 6
fill ~24~89~21 ~25~89~21 minecraft:concrete 11
fill ~26~6~21 ~28~6~21 minecraft:double_stone_block_slab 6
fill ~28~106~21 ~32~106~21 minecraft:concrete 11
fill ~29~7~21 ~39~7~23 minecraft:double_stone_block_slab 6
fill ~33~8~21 ~33~8~23 minecraft:concrete 11
setblock ~33~89~21 minecraft:concrete 11
fill ~34~8~21 ~34~8~23 minecraft:sea_lantern
fill ~35~8~21 ~35~8~23 minecraft:concrete 11
setblock ~35~89~21 minecraft:concrete 11
fill ~36~106~21 ~40~106~21 minecraft:concrete 11
fill ~40~6~21 ~42~6~21 minecraft:double_stone_block_slab 6
fill ~43~5~21 ~45~5~21 minecraft:double_stone_block_slab 6
fill ~43~89~21 ~44~89~21 minecraft:concrete 11
fill ~45~89~21 ~46~89~21 minecraft:sea_lantern
fill ~46~0~21 ~46~4~21 minecraft:double_stone_block_slab 6
fill ~47~0~21 ~47~4~21 minecraft:concrete 15
setblock ~47~89~21 minecraft:concrete 11
fill ~49~90~21 ~49~90~34 minecraft:double_stone_block_slab 6
fill ~49~105~21 ~49~105~34 minecraft:double_stone_block_slab 6
fill ~53~91~21 ~53~91~24 minecraft:double_stone_block_slab 6
fill ~53~104~21 ~53~104~24 minecraft:double_stone_block_slab 6
fill ~54~92~21 ~55~92~21 minecraft:double_stone_block_slab 6
fill ~54~103~21 ~55~103~21 minecraft:double_stone_block_slab 6
fill ~56~93~21 ~57~93~21 minecraft:double_stone_block_slab 6
fill ~56~102~21 ~57~102~21 minecraft:double_stone_block_slab 6
fill ~58~94~21 ~58~94~22 minecraft:double_stone_block_slab 6
fill ~58~95~21 ~58~100~22 minecraft:stained_glass 11
fill ~58~101~21 ~58~101~22 minecraft:double_stone_block_slab 6
fill ~60~98~21 ~60~98~24 minecraft:double_stone_block_slab 6
fill ~11~93~22 ~11~93~23 minecraft:double_stone_block_slab 6
fill ~11~102~22 ~11~102~23 minecraft:double_stone_block_slab 6
fill ~12~92~22 ~13~92~22 minecraft:double_stone_block_slab 6
fill ~12~103~22 ~13~103~22 minecraft:double_stone_block_slab 6
fill ~14~91~22 ~14~91~26 minecraft:double_stone_block_slab 6
fill ~14~104~22 ~14~104~26 minecraft:double_stone_block_slab 6
fill ~18~90~22 ~18~90~34 minecraft:double_stone_block_slab 6
fill ~18~105~22 ~18~105~34 minecraft:double_stone_block_slab 6
fill ~20~0~22 ~21~4~22 minecraft:double_stone_block_slab 6
setblock ~20~89~22 minecraft:concrete 11
setblock ~21~89~22 minecraft:sea_lantern
setblock ~22~5~22 minecraft:concrete 15
fill ~22~89~22 ~23~89~22 minecraft:concrete 11
setblock ~23~5~22 minecraft:double_stone_block_slab 6
fill ~24~6~22 ~26~6~22 minecraft:double_stone_block_slab 6
fill ~26~106~22 ~27~106~22 minecraft:concrete 11
fill ~27~7~22 ~28~7~24 minecraft:double_stone_block_slab 6
fill ~28~106~22 ~33~106~22 minecraft:sea_lantern
fill ~33~88~22 ~33~88~24 minecraft:concrete 11
fill ~33~158~22 ~35~158~22 minecraft:concrete 11
fill ~34~88~22 ~34~88~24 minecraft:sea_lantern
fill ~35~88~22 ~35~88~24 minecraft:concrete 11
fill ~35~106~22 ~40~106~22 minecraft:sea_lantern
fill ~40~7~22 ~41~7~24 minecraft:double_stone_block_slab 6
fill ~41~106~22 ~42~106~22 minecraft:concrete 11
fill ~42~6~22 ~44~6~22 minecraft:double_stone_block_slab 6
setblock ~45~5~22 minecraft:double_stone_block_slab 6
fill ~45~89~22 ~46~89~22 minecraft:concrete 11
setblock ~46~5~22 minecraft:concrete 15
fill ~47~1~22 ~48~4~22 minecraft:double_stone_block_slab 6
setblock ~47~89~22 minecraft:sea_lantern
setblock ~48~0~22 minecraft:double_stone_block_slab 6
setblock ~48~89~22 minecraft:concrete 11
fill ~50~90~22 ~50~90~34 minecraft:double_stone_block_slab 6
fill ~50~105~22 ~50~105~34 minecraft:double_stone_block_slab 6
fill ~54~91~22 ~54~91~26 minecraft:double_stone_block_slab 6
fill ~54~104~22 ~54~104~26 minecraft:double_stone_block_slab 6
fill ~55~92~22 ~56~92~22 minecraft:double_stone_block_slab 6
fill ~55~103~22 ~56~103~22 minecraft:double_stone_block_slab 6
fill ~57~93~22 ~57~93~23 minecraft:double_stone_block_slab 6
fill ~57~102~22 ~57~102~23 minecraft:double_stone_block_slab 6
fill ~7~98~23 ~7~98~26 minecraft:double_stone_block_slab 6
fill ~9~94~23 ~9~94~24 minecraft:double_stone_block_slab 6
fill ~9~95~23 ~9~100~24 minecraft:stained_glass 11
fill ~9~101~23 ~9~101~24 minecraft:double_stone_block_slab 6
fill ~10~93~23 ~10~93~25 minecraft:double_stone_block_slab 6
fill ~10~102~23 ~10~102~25 minecraft:double_stone_block_slab 6
fill ~12~92~23 ~12~92~24 minecraft:double_stone_block_slab 6
fill ~12~103~23 ~12~103~24 minecraft:double_stone_block_slab 6
fill ~13~91~23 ~13~91~28 minecraft:double_stone_block_slab 6
fill ~13~104~23 ~13~104~28 minecraft:double_stone_block_slab 6
fill ~17~90~23 ~17~90~34 minecraft:double_stone_block_slab 6
fill ~17~105~23 ~17~105~34 minecraft:double_stone_block_slab 6
fill ~19~0~23 ~19~4~23 minecraft:double_stone_block_slab 6
setblock ~19~89~23 minecraft:concrete 11
fill ~20~5~23 ~22~5~23 minecraft:stained_glass 11
setblock ~20~89~23 minecraft:sea_lantern
setblock ~21~89~23 minecraft:concrete 11
setblock ~23~6~23 minecraft:concrete 15
setblock ~24~6~23 minecraft:double_stone_block_slab 6
fill ~24~106~23 ~25~106~23 minecraft:concrete 11
fill ~25~7~23 ~26~7~24 minecraft:double_stone_block_slab 6
fill ~26~106~23 ~27~106~23 minecraft:sea_lantern
fill ~28~106~23 ~33~106~23 minecraft:concrete 11
fill ~33~158~23 ~33~158~25 minecraft:concrete 11
fill ~34~158~23 ~34~158~25 minecraft:sea_lantern
fill ~35~106~23 ~40~106~23 minecraft:concrete 11
fill ~35~158~23 ~35~158~25 minecraft:concrete 11
fill ~41~106~23 ~42~106~23 minecraft:sea_lantern
fill ~42~7~23 ~43~7~24 minecraft:double_stone_block_slab 6
fill ~43~106~23 ~44~106~23 minecraft:concrete 11
setblock ~44~6~23 minecraft:double_stone_block_slab 6
setblock ~45~6~23 minecraft:concrete 15
fill ~46~5~23 ~48~5~23 minecraft:stained_glass 11
setblock ~47~89~23 minecraft:concrete 11
setblock ~48~89~23 minecraft:sea_lantern
fill ~49~0~23 ~49~4~23 minecraft:double_stone_block_slab 6
setblock ~49~89~23 minecraft:concrete 11
fill ~51~90~23 ~51~90~34 minecraft:double_stone_block_slab 6
fill ~51~105~23 ~51~105~34 minecraft:double_stone_block_slab 6
fill ~55~91~23 ~55~91~28 minecraft:double_stone_block_slab 6
fill ~55~104~23 ~55~104~28 minecraft:double_stone_block_slab 6
fill ~56~92~23 ~56~92~24 minecraft:double_stone_block_slab 6
fill ~56~103~23 ~56~103~24 minecraft:double_stone_block_slab 6
fill ~58~93~23 ~58~93~25 minecraft:double_stone_block_slab 6
fill ~58~102~23 ~58~102~25 minecraft:double_stone_block_slab 6
fill ~59~94~23 ~59~94~24 minecraft:double_stone_block_slab 6
fill ~59~95~23 ~59~100~24 minecraft:stained_glass 11
fill ~59~101~23 ~59~101~24 minecraft:double_stone_block_slab 6
fill ~61~98~23 ~61~98~26 minecraft:double_stone_block_slab 6
fill ~11~92~24 ~11~92~26 minecraft:double_stone_block_slab 6
fill ~11~103~24 ~11~103~26 minecraft:double_stone_block_slab 6
fill ~16~90~24 ~16~90~34 minecraft:double_stone_block_slab 6
fill ~16~105~24 ~16~105~34 minecraft:double_stone_block_slab 6
fill ~18~0~24 ~18~4~25 minecraft:double_stone_block_slab 6
setblock ~18~89~24 minecraft:concrete 11
fill ~19~5~24 ~20~5~24 minecraft:stained_glass 11
setblock ~19~89~24 minecraft:sea_lantern
setblock ~20~89~24 minecraft:concrete 11
fill ~21~6~24 ~23~6~24 minecraft:double_stone_block_slab 6
setblock ~23~106~24 minecraft:concrete 11
setblock ~24~7~24 minecraft:concrete 15
fill ~24~106~24 ~25~106~24 minecraft:sea_lantern
fill ~26~106~24 ~27~106~24 minecraft:concrete 11
fill ~29~8~24 ~39~8~24 minecraft:double_stone_block_slab 6
setblock ~33~9~24 minecraft:concrete 11
fill ~33~106~24 ~33~106~28 minecraft:concrete 11
setblock ~34~9~24 minecraft:sea_lantern
setblock ~35~9~24 minecraft:concrete 11
fill ~35~106~24 ~35~106~28 minecraft:concrete 11
fill ~41~106~24 ~42~106~24 minecraft:concrete 11
fill ~43~106~24 ~44~106~24 minecraft:sea_lantern
setblock ~44~7~24 minecraft:concrete 15
fill ~45~6~24 ~47~6~24 minecraft:double_stone_block_slab 6
setblock ~45~106~24 minecraft:concrete 11
fill ~48~5~24 ~49~5~24 minecraft:stained_glass 11
setblock ~48~89~24 minecraft:concrete 11
setblock ~49~89~24 minecraft:sea_lantern
fill ~50~0~24 ~50~4~24 minecraft:double_stone_block_slab 6
setblock ~50~89~24 minecraft:concrete 11
fill ~52~90~24 ~52~90~34 minecraft:double_stone_block_slab 6
fill ~52~105~24 ~52~105~34 minecraft:double_stone_block_slab 6
fill ~57~92~24 ~57~92~26 minecraft:double_stone_block_slab 6
fill ~57~103~24 ~57~103~26 minecraft:double_stone_block_slab 6
fill ~6~98~25 ~6~98~28 minecraft:double_stone_block_slab 6
fill ~8~94~25 ~8~94~26 minecraft:double_stone_block_slab 6
fill ~8~95~25 ~8~100~26 minecraft:stained_glass 11
fill ~8~101~25 ~8~101~26 minecraft:double_stone_block_slab 6
fill ~9~93~25 ~9~93~27 minecraft:double_stone_block_slab 6
fill ~9~102~25 ~9~102~27 minecraft:double_stone_block_slab 6
fill ~12~91~25 ~12~91~30 minecraft:double_stone_block_slab 6
fill ~12~104~25 ~12~104~30 minecraft:double_stone_block_slab 6
fill ~15~90~25 ~15~90~34 minecraft:double_stone_block_slab 6
fill ~15~105~25 ~15~105~34 minecraft:double_stone_block_slab 6
fill ~17~0~25 ~17~4~25 minecraft:concrete 15
setblock ~17~89~25 minecraft:concrete 11
setblock ~18~89~25 minecraft:sea_lantern
fill ~19~5~25 ~19~5~26 minecraft:stained_glass 11
setblock ~19~89~25 minecraft:concrete 11
fill ~20~6~25 ~21~6~25 minecraft:double_stone_block_slab 6
fill ~22~7~25 ~24~7~25 minecraft:stained_glass 11
setblock ~22~106~25 minecraft:concrete 11
setblock ~23~106~25 minecraft:sea_lantern
fill ~24~106~25 ~25~106~25 minecraft:concrete 11
setblock ~25~7~25 minecraft:concrete 15
setblock ~26~7~25 minecraft:double_stone_block_slab 6
fill ~27~8~25 ~29~8~25 minecraft:double_stone_block_slab 6
fill ~30~9~25 ~38~9~25 minecraft:double_stone_block_slab 6
setblock ~33~10~25 minecraft:concrete 11
fill ~33~87~25 ~33~87~26 minecraft:concrete 11
setblock ~34~10~25 minecraft:sea_lantern
fill ~34~87~25 ~34~87~26 minecraft:sea_lantern
setblock ~35~10~25 minecraft:concrete 11
fill ~35~87~25 ~35~87~26 minecraft:concrete 11
fill ~39~8~25 ~41~8~25 minecraft:double_stone_block_slab 6
setblock ~42~7~25 minecraft:double_stone_block_slab 6
setblock ~43~7~25 minecraft:concrete 15
fill ~43~106~25 ~44~106~25 minecraft:concrete 11
fill ~44~7~25 ~46~7~25 minecraft:stained_glass 11
setblock ~45~106~25 minecraft:sea_lantern
setblock ~46~106~25 minecraft:concrete 11
fill ~47~6~25 ~48~6~25 minecraft:double_stone_block_slab 6
fill ~49~5~25 ~49~5~26 minecraft:stained_glass 11
setblock ~49~89~25 minecraft:concrete 11
fill ~50~1~25 ~50~4~25 minecraft:double_stone_block_slab 6
setblock ~50~89~25 minecraft:sea_lantern
fill ~51~0~25 ~51~4~25 minecraft:concrete 15
setblock ~51~89~25 minecraft:concrete 11
fill ~53~90~25 ~53~90~34 minecraft:double_stone_block_slab 6
fill ~53~105~25 ~53~105~34 minecraft:double_stone_block_slab 6
fill ~56~91~25 ~56~91~30 minecraft:double_stone_block_slab 6
fill ~56~104~25 ~56~104~30 minecraft:double_stone_block_slab 6
fill ~59~93~25 ~59~93~27 minecraft:double_stone_block_slab 6
fill ~59~102~25 ~59~102~27 minecraft:double_stone_block_slab 6
fill ~60~94~25 ~60~94~26 minecraft:double_stone_block_slab 6
fill ~60~95~25 ~60~100~26 minecraft:stained_glass 11
fill ~60~101~25 ~60~101~26 minecraft:double_stone_block_slab 6
fill ~62~98~25 ~62~98~28 minecraft:double_stone_block_slab 6
fill ~10~92~26 ~10~92~28 minecraft:double_stone_block_slab 6
fill ~10~103~26 ~10~103~28 minecraft:double_stone_block_slab 6
fill ~16~89~26 ~16~89~27 minecraft:concrete 11
fill ~17~0~26 ~17~4~26 minecraft:double_stone_block_slab 6
fill ~17~89~26 ~17~89~27 minecraft:sea_lantern
setblock ~18~5~26 minecraft:concrete 15
fill ~18~89~26 ~18~89~27 minecraft:concrete 11
fill ~20~6~26 ~20~6~27 minecraft:double_stone_block_slab 6
fill ~21~7~26 ~22~7~26 minecraft:stained_glass 11
setblock ~21~106~26 minecraft:concrete 11
setblock ~22~106~26 minecraft:sea_lantern
fill ~23~7~26 ~25~7~26 minecraft:double_stone_block_slab 6
setblock ~23~106~26 minecraft:concrete 11
setblock ~26~8~26 minecraft:concrete 15
setblock ~27~8~26 minecraft:double_stone_block_slab 6
fill ~28~9~26 ~30~9~26 minecraft:double_stone_block_slab 6
fill ~31~10~26 ~37~10~26 minecraft:double_stone_block_slab 6
fill ~33~11~26 ~33~12~26 minecraft:concrete 11
fill ~33~157~26 ~33~157~27 minecraft:concrete 11
fill ~34~11~26 ~34~12~26 minecraft:sea_lantern
fill ~34~157~26 ~34~157~27 minecraft:sea_lantern
fill ~35~11~26 ~35~12~26 minecraft:concrete 11
fill ~35~157~26 ~35~157~27 minecraft:concrete 11
fill ~38~9~26 ~40~9~26 minecraft:double_stone_block_slab 6
setblock ~41~8~26 minecraft:double_stone_block_slab 6
setblock ~42~8~26 minecraft:concrete 15
fill ~43~7~26 ~45~7~26 minecraft:double_stone_block_slab 6
setblock ~45~106~26 minecraft:concrete 11
fill ~46~7~26 ~47~7~26 minecraft:stained_glass 11
setblock ~46~106~26 minecraft:sea_lantern
setblock ~47~106~26 minecraft:concrete 11
fill ~48~6~26 ~48~6~27 minecraft:double_stone_block_slab 6
setblock ~50~5~26 minecraft:concrete 15
fill ~50~89~26 ~50~89~27 minecraft:concrete 11
fill ~51~0~26 ~51~4~26 minecraft:double_stone_block_slab 6
fill ~51~89~26 ~51~89~27 minecraft:sea_lantern
fill ~52~89~26 ~52~89~27 minecraft:concrete 11
fill ~58~92~26 ~58~92~28 minecraft:double_stone_block_slab 6
fill ~58~103~26 ~58~103~28 minecraft:double_stone_block_slab 6
fill ~5~98~27 ~5~98~32 minecraft:double_stone_block_slab 6
fill ~7~94~27 ~7~94~28 minecraft:double_stone_block_slab 6
fill ~7~95~27 ~7~100~28 minecraft:stained_glass 11
fill ~7~101~27 ~7~101~28 minecraft:double_stone_block_slab 6
fill ~8~93~27 ~8~93~29 minecraft:double_stone_block_slab 6
fill ~8~102~27 ~8~102~29 minecraft:double_stone_block_slab 6
fill ~11~91~27 ~11~91~34 minecraft:double_stone_block_slab 6
fill ~11~104~27 ~11~104~34 minecraft:double_stone_block_slab 6
fill ~14~90~27 ~14~90~34 minecraft:double_stone_block_slab 6
fill ~14~105~27 ~14~105~34 minecraft:double_stone_block_slab 6
fill ~16~0~27 ~16~4~28 minecraft:double_stone_block_slab 6
fill ~17~5~27 ~18~5~27 minecraft:double_stone_block_slab 6
setblock ~19~6~27 minecraft:concrete 15
setblock ~20~106~27 minecraft:concrete 11
fill ~21~7~27 ~21~7~28 minecraft:stained_glass 11
setblock ~21~106~27 minecraft:sea_lantern
fill ~22~7~27 ~23~7~27 minecraft:double_stone_block_slab 6
setblock ~22~106~27 minecraft:concrete 11
fill ~24~8~27 ~26~8~27 minecraft:stained_glass 11
setblock ~27~9~27 minecraft:concrete 15
setblock ~28~9~27 minecraft:double_stone_block_slab 6
fill ~29~10~27 ~31~10~27 minecraft:double_stone_block_slab 6
fill ~32~11~27 ~36~12~27 minecraft:double_stone_block_slab 6
fill ~33~13~27 ~33~13~28 minecraft:concrete 11
setblock ~33~86~27 minecraft:concrete 11
setblock ~34~13~27 minecraft:sea_lantern
setblock ~34~86~27 minecraft:sea_lantern
fill ~35~13~27 ~35~13~28 minecraft:concrete 11
setblock ~35~86~27 minecraft:concrete 11
fill ~37~10~27 ~39~10~27 minecraft:double_stone_block_slab 6
setblock ~40~9~27 minecraft:double_stone_block_slab 6
setblock ~41~9~27 minecraft:concrete 15
fill ~42~8~27 ~44~8~27 minecraft:stained_glass 11
fill ~45~7~27 ~46~7~27 minecraft:double_stone_block_slab 6
setblock ~46~106~27 minecraft:concrete 11
fill ~47~7~27 ~47~7~28 minecraft:stained_glass 11
setblock ~47~106~27 minecraft:sea_lantern
setblock ~48~106~27 minecraft:concrete 11
setblock ~49~6~27 minecraft:concrete 15
fill ~50~5~27 ~51~5~27 minecraft:double_stone_block_slab 6
fill ~52~0~27 ~52~4~27 minecraft:double_stone_block_slab 6
fill ~54~90~27 ~54~90~34 minecraft:double_stone_block_slab 6
fill ~54~105~27 ~54~105~34 minecraft:double_stone_block_slab 6
fill ~57~91~27 ~57~91~34 minecraft:double_stone_block_slab 6
fill ~57~104~27 ~57~104~34 minecraft:double_stone_block_slab 6
fill ~60~93~27 ~60~93~29 minecraft:double_stone_block_slab 6
fill ~60~102~27 ~60~102~29 minecraft:double_stone_block_slab 6
fill ~61~94~27 ~61~94~28 minecraft:double_stone_block_slab 6
fill ~61~95~27 ~61~100~28 minecraft:stained_glass 11
fill ~61~101~27 ~61~101~28 minecraft:double_stone_block_slab 6
fill ~63~98~27 ~63~98~32 minecraft:double_stone_block_slab 6
fill ~9~92~28 ~9~92~30 minecraft:double_stone_block_slab 6
fill ~9~103~28 ~9~103~30 minecraft:double_stone_block_slab 6
fill ~15~0~28 ~15~4~30 minecraft:double_stone_block_slab 6
fill ~15~89~28 ~15~89~29 minecraft:concrete 11
fill ~16~89~28 ~16~89~29 minecraft:sea_lantern
fill ~17~5~28 ~17~5~29 minecraft:double_stone_block_slab 6
fill ~17~89~28 ~17~89~29 minecraft:concrete 11
fill ~18~6~28 ~19~6~28 minecraft:double_stone_block_slab 6
fill ~19~106~28 ~19~106~29 minecraft:concrete 11
setblock ~20~7~28 minecraft:concrete 15
fill ~20~106~28 ~20~106~29 minecraft:sea_lantern
fill ~21~106~28 ~21~106~29 minecraft:concrete 11
fill ~22~7~28 ~22~7~29 minecraft:double_stone_block_slab 6
fill ~23~8~28 ~24~8~28 minecraft:stained_glass 11
fill ~25~9~28 ~27~9~28 minecraft:double_stone_block_slab 6
setblock ~28~10~28 minecraft:concrete 15
fill ~28~89~28 ~30~89~32 minecraft:double_stone_block_slab 6
setblock ~29~10~28 minecraft:double_stone_block_slab 6
fill ~30~11~28 ~32~12~28 minecraft:double_stone_block_slab 6
fill ~31~89~28 ~31~89~31 minecraft:concrete 15
fill ~32~89~28 ~36~89~29 minecraft:double_stone_block_slab 6
fill ~33~12~28 ~38~12~28 minecraft:double_stone_block_slab 6
fill ~33~14~28 ~33~15~28 minecraft:concrete 11
fill ~33~84~28 ~33~85~28 minecraft:concrete 11
setblock ~33~156~28 minecraft:concrete 11
fill ~34~14~28 ~34~15~28 minecraft:sea_lantern
fill ~34~84~28 ~34~85~28 minecraft:sea_lantern
setblock ~34~156~28 minecraft:sea_lantern
fill ~35~14~28 ~35~15~28 minecraft:concrete 11
fill ~35~84~28 ~35~85~28 minecraft:concrete 11
setblock ~35~156~28 minecraft:concrete 11
fill ~36~11~28 ~38~11~28 minecraft:double_stone_block_slab 6
fill ~37~89~28 ~37~89~31 minecraft:concrete 15
fill ~38~89~28 ~40~89~32 minecraft:double_stone_block_slab 6
setblock ~39~10~28 minecraft:double_stone_block_slab 6
setblock ~40~10~28 minecraft:concrete 15
fill ~41~9~28 ~43~9~28 minecraft:double_stone_block_slab 6
fill ~44~8~28 ~45~8~28 minecraft:stained_glass 11
fill ~46~7~28 ~46~7~29 minecraft:double_stone_block_slab 6
fill ~47~106~28 ~47~106~29 minecraft:concrete 11
setblock ~48~7~28 minecraft:concrete 15
fill ~48~106~28 ~48~106~29 minecraft:sea_lantern
fill ~49~6~28 ~50~6~28 minecraft:double_stone_block_slab 6
fill ~49~106~28 ~49~106~29 minecraft:concrete 11
fill ~51~5~28 ~51~5~29 minecraft:double_stone_block_slab 6
fill ~51~89~28 ~51~89~29 minecraft:concrete 11
fill ~52~1~28 ~53~4~28 minecraft:double_stone_block_slab 6
fill ~52~89~28 ~52~89~29 minecraft:sea_lantern
fill ~53~0~28 ~53~0~30 minecraft:double_stone_block_slab 6
fill ~53~89~28 ~53~89~29 minecraft:concrete 11
fill ~59~92~28 ~59~92~30 minecraft:double_stone_block_slab 6
fill ~59~103~28 ~59~103~30 minecraft:double_stone_block_slab 6
fill ~4~98~29 ~4~98~47 minecraft:double_stone_block_slab 6
fill ~6~94~29 ~6~94~32 minecraft:double_stone_block_slab 6
fill ~6~95~29 ~6~100~32 minecraft:stained_glass 11
fill ~6~101~29 ~6~101~32 minecraft:double_stone_block_slab 6
fill ~7~93~29 ~7~93~33 minecraft:double_stone_block_slab 6
fill ~7~102~29 ~7~102~33 minecraft:double_stone_block_slab 6
fill ~10~91~29 ~10~91~34 minecraft:double_stone_block_slab 6
fill ~10~104~29 ~10~104~34 minecraft:double_stone_block_slab 6
fill ~13~90~29 ~13~90~34 minecraft:double_stone_block_slab 6
fill ~13~105~29 ~13~105~34 minecraft:double_stone_block_slab 6
fill ~16~5~29 ~16~5~31 minecraft:double_stone_block_slab 6
fill ~18~6~29 ~18~6~30 minecraft:double_stone_block_slab 6
fill ~19~7~29 ~20~7~32 minecraft:double_stone_block_slab 6
setblock ~21~7~29 minecraft:concrete 15
fill ~23~8~29 ~23~8~30 minecraft:stained_glass 11
fill ~24~9~29 ~25~9~29 minecraft:double_stone_block_slab 6
fill ~26~10~29 ~28~10~29 minecraft:stained_glass 11
fill ~26~89~29 ~27~89~34 minecraft:double_stone_block_slab 6
fill ~29~11~29 ~29~12~29 minecraft:concrete 15
fill ~30~11~29 ~30~12~29 minecraft:double_stone_block_slab 6
fill ~31~13~29 ~37~15~29 minecraft:double_stone_block_slab 6
setblock ~31~106~29 minecraft:concrete 15
fill ~31~159~29 ~37~159~29 minecraft:glowstone
fill ~32~106~29 ~36~106~29 minecraft:double_stone_block_slab 6
fill ~32~157~29 ~36~158~29 minecraft:glowstone
fill ~32~160~29 ~36~161~29 minecraft:glowstone
fill ~33~16~29 ~33~16~30 minecraft:concrete 11
fill ~33~81~29 ~33~83~29 minecraft:concrete 11
fill ~33~107~29 ~33~108~29 minecraft:concrete 11
fill ~33~154~29 ~33~155~29 minecraft:concrete 11
setblock ~34~16~29 minecraft:sea_lantern
fill ~34~81~29 ~34~83~29 minecraft:sea_lantern
fill ~34~107~29 ~34~108~29 minecraft:sea_lantern
fill ~34~154~29 ~34~155~29 minecraft:sea_lantern
setblock ~34~156~29 minecraft:glowstone
setblock ~34~162~29 minecraft:glowstone
fill ~35~16~29 ~35~16~30 minecraft:concrete 11
fill ~35~81~29 ~35~83~29 minecraft:concrete 11
fill ~35~107~29 ~35~108~29 minecraft:concrete 11
fill ~35~154~29 ~35~155~29 minecraft:concrete 11
setblock ~37~106~29 minecraft:concrete 15
fill ~38~11~29 ~38~12~29 minecraft:double_stone_block_slab 6
fill ~39~11~29 ~39~12~29 minecraft:concrete 15
fill ~40~10~29 ~42~10~29 minecraft:stained_glass 11
fill ~41~89~29 ~42~89~34 minecraft:double_stone_block_slab 6
fill ~43~9~29 ~44~9~29 minecraft:double_stone_block_slab 6
fill ~45~8~29 ~45~8~30 minecraft:stained_glass 11
setblock ~47~7~29 minecraft:concrete 15
fill ~48~7~29 ~49~7~32 minecraft:double_stone_block_slab 6
fill ~50~6~29 ~50~6~30 minecraft:double_stone_block_slab 6
fill ~52~5~29 ~52~5~31 minecraft:double_stone_block_slab 6
fill ~53~1~29 ~53~4~30 minecraft:double_stone_block_slab 6
fill ~55~90~29 ~55~90~34 minecraft:double_stone_block_slab 6
fill ~55~105~29 ~55~105~34 minecraft:double_stone_block_slab 6
fill ~58~91~29 ~58~91~34 minecraft:double_stone_block_slab 6
fill ~58~104~29 ~58~104~34 minecraft:double_stone_block_slab 6
fill ~61~93~29 ~61~93~33 minecraft:double_stone_block_slab 6
fill ~61~102~29 ~61~102~33 minecraft:double_stone_block_slab 6
fill ~62~94~29 ~62~94~32 minecraft:double_stone_block_slab 6
fill ~62~95~29 ~62~100~32 minecraft:stained_glass 11
fill ~62~101~29 ~62~101~32 minecraft:double_stone_block_slab 6
fill ~64~98~29 ~64~98~47 minecraft:double_stone_block_slab 6
fill ~8~92~30 ~8~92~34 minecraft:double_stone_block_slab 6
fill ~8~103~30 ~8~103~34 minecraft:double_stone_block_slab 6
fill ~14~89~30 ~14~89~37 minecraft:concrete 11
fill ~15~89~30 ~15~89~46 minecraft:sea_lantern
fill ~16~89~30 ~16~89~37 minecraft:concrete 11
fill ~17~6~30 ~17~6~32 minecraft:double_stone_block_slab 6
fill ~18~106~30 ~18~106~31 minecraft:concrete 11
fill ~19~106~30 ~19~106~31 minecraft:sea_lantern
fill ~20~106~30 ~20~106~31 minecraft:concrete 11
setblock ~21~7~30 minecraft:double_stone_block_slab 6
setblock ~22~8~30 minecraft:concrete 15
fill ~24~9~30 ~24~9~31 minecraft:double_stone_block_slab 6
fill ~25~10~30 ~26~10~30 minecraft:stained_glass 11
fill ~25~89~30 ~25~89~34 minecraft:double_stone_block_slab 6
fill ~27~11~30 ~29~11~30 minecraft:double_stone_block_slab 6
fill ~27~12~30 ~29~12~30 minecraft:stained_glass 11
fill ~29~106~30 ~30~106~30 minecraft:double_stone_block_slab 6
fill ~29~158~30 ~31~158~30 minecraft:glowstone
fill ~29~159~30 ~30~160~30 minecraft:glowstone
fill ~30~13~30 ~30~15~30 minecraft:concrete 15
fill ~30~88~30 ~30~88~32 minecraft:double_stone_block_slab 6
fill ~30~156~30 ~33~156~30 minecraft:glowstone
fill ~30~157~30 ~31~157~30 minecraft:glowstone
fill ~30~161~30 ~31~162~30 minecraft:glowstone
fill ~31~13~30 ~31~15~30 minecraft:double_stone_block_slab 6
fill ~31~88~30 ~31~88~31 minecraft:concrete 15
fill ~31~107~30 ~31~108~30 minecraft:concrete 15
fill ~31~155~30 ~37~155~30 minecraft:glowstone
setblock ~31~160~30 minecraft:glowstone
fill ~31~163~30 ~37~163~30 minecraft:glowstone
fill ~32~15~30 ~37~15~30 minecraft:double_stone_block_slab 6
fill ~32~88~30 ~36~88~31 minecraft:double_stone_block_slab 6
fill ~32~107~30 ~36~108~30 minecraft:double_stone_block_slab 6
fill ~32~162~30 ~33~162~30 minecraft:glowstone
fill ~33~17~30 ~33~80~30 minecraft:concrete 11
fill ~33~109~30 ~33~111~30 minecraft:concrete 11
fill ~33~151~30 ~33~153~30 minecraft:concrete 11
fill ~33~154~30 ~35~154~30 minecraft:glowstone
fill ~33~164~30 ~35~164~30 minecraft:glowstone
fill ~34~17~30 ~34~80~30 minecraft:sea_lantern
fill ~34~109~30 ~34~111~30 minecraft:sea_lantern
fill ~34~151~30 ~34~153~30 minecraft:sea_lantern
fill ~35~17~30 ~35~80~30 minecraft:concrete 11
fill ~35~109~30 ~35~111~30 minecraft:concrete 11
fill ~35~151~30 ~35~153~30 minecraft:concrete 11
fill ~35~156~30 ~38~156~30 minecraft:glowstone
fill ~35~162~30 ~38~162~30 minecraft:glowstone
fill ~37~13~30 ~37~14~30 minecraft:double_stone_block_slab 6
fill ~37~88~30 ~37~88~31 minecraft:concrete 15
fill ~37~107~30 ~37~108~30 minecraft:concrete 15
fill ~37~157~30 ~38~158~30 minecraft:glowstone
fill ~37~160~30 ~39~160~30 minecraft:glowstone
fill ~37~161~30 ~38~161~30 minecraft:glowstone
fill ~38~13~30 ~38~15~30 minecraft:concrete 15
fill ~38~88~30 ~38~88~32 minecraft:double_stone_block_slab 6
fill ~38~106~30 ~39~106~30 minecraft:double_stone_block_slab 6
fill ~38~159~30 ~39~159~30 minecraft:glowstone
fill ~39~11~30 ~41~11~30 minecraft:double_stone_block_slab 6
fill ~39~12~30 ~41~12~30 minecraft:stained_glass 11
setblock ~39~158~30 minecraft:glowstone
fill ~42~10~30 ~43~10~30 minecraft:stained_glass 11
fill ~43~89~30 ~43~89~34 minecraft:double_stone_block_slab 6
fill ~44~9~30 ~44~9~31 minecraft:double_stone_block_slab 6
setblock ~46~8~30 minecraft:concrete 15
setblock ~47~7~30 minecraft:double_stone_block_slab 6
fill ~48~106~30 ~48~106~31 minecraft:concrete 11
fill ~49~106~30 ~49~106~31 minecraft:sea_lantern
fill ~50~106~30 ~50~106~31 minecraft:concrete 11
fill ~51~6~30 ~51~6~32 minecraft:double_stone_block_slab 6
fill ~52~89~30 ~52~89~37 minecraft:concrete 11
fill ~53~89~30 ~53~89~46 minecraft:sea_lantern
fill ~54~89~30 ~54~89~37 minecraft:concrete 11
fill ~60~92~30 ~60~92~34 minecraft:double_stone_block_slab 6
fill ~60~103~30 ~60~103~34 minecraft:double_stone_block_slab 6
fill ~9~91~31 ~9~91~34 minecraft:double_stone_block_slab 6
fill ~9~104~31 ~9~104~34 minecraft:double_stone_block_slab 6
fill ~12~90~31 ~12~90~34 minecraft:double_stone_block_slab 6
fill ~12~105~31 ~12~105~34 minecraft:double_stone_block_slab 6
fill ~14~0~31 ~14~4~33 minecraft:double_stone_block_slab 6
fill ~15~5~31 ~15~5~34 minecraft:double_stone_block_slab 6
fill ~18~7~31 ~18~7~45 minecraft:double_stone_block_slab 6
fill ~21~8~31 ~22~8~31 minecraft:double_stone_block_slab 6
setblock ~23~9~31 minecraft:concrete 15
fill ~25~10~31 ~25~10~32 minecraft:stained_glass 11
fill ~26~11~31 ~27~11~31 minecraft:double_stone_block_slab 6
fill ~26~12~31 ~27~12~31 minecraft:stained_glass 11
fill ~28~13~31 ~30~13~31 minecraft:double_stone_block_slab 6
fill ~28~14~31 ~29~14~31 minecraft:stained_glass 11
fill ~28~15~31 ~30~15~31 minecraft:double_stone_block_slab 6
fill ~28~88~31 ~29~88~33 minecraft:double_stone_block_slab 6
setblock ~28~106~31 minecraft:double_stone_block_slab 6
fill ~28~157~31 ~29~157~31 minecraft:glowstone
fill ~28~158~31 ~28~161~31 minecraft:glowstone
fill ~29~107~31 ~30~108~31 minecraft:double_stone_block_slab 6
fill ~29~155~31 ~30~155~31 minecraft:glowstone
setblock ~29~156~31 minecraft:glowstone
fill ~29~161~31 ~29~163~31 minecraft:glowstone
setblock ~30~14~31 minecraft:double_stone_block_slab 6
fill ~30~154~31 ~32~154~31 minecraft:glowstone
fill ~30~163~31 ~30~164~31 minecraft:glowstone
fill ~31~16~31 ~31~87~31 minecraft:concrete 15
fill ~31~109~31 ~31~111~31 minecraft:concrete 15
fill ~31~164~31 ~32~164~31 minecraft:glowstone
fill ~32~16~31 ~36~87~31 minecraft:double_stone_block_slab 6
fill ~32~89~31 ~36~89~31 minecraft:double_stone_block_slab 6
fill ~32~109~31 ~36~111~31 minecraft:double_stone_block_slab 6
fill ~32~153~31 ~36~153~31 minecraft:glowstone
fill ~32~165~31 ~36~165~31 minecraft:glowstone
fill ~33~112~31 ~33~115~31 minecraft:concrete 11
fill ~33~144~31 ~33~150~31 minecraft:concrete 11
fill ~34~112~31 ~34~115~31 minecraft:sea_lantern
fill ~34~144~31 ~34~150~31 minecraft:sea_lantern
fill ~35~112~31 ~35~115~31 minecraft:concrete 11
fill ~35~144~31 ~35~150~31 minecraft:concrete 11
fill ~36~154~31 ~38~154~31 minecraft:glowstone
fill ~36~164~31 ~38~164~31 minecraft:glowstone
fill ~37~16~31 ~37~87~31 minecraft:concrete 15
fill ~37~109~31 ~37~111~31 minecraft:concrete 15
fill ~38~13~31 ~40~13~31 minecraft:double_stone_block_slab 6
fill ~38~14~31 ~38~15~31 minecraft:double_stone_block_slab 6
fill ~38~107~31 ~39~108~31 minecraft:double_stone_block_slab 6
fill ~38~155~31 ~39~155~31 minecraft:glowstone
fill ~38~163~31 ~39~163~31 minecraft:glowstone
fill ~39~14~31 ~40~14~31 minecraft:stained_glass 11
fill ~39~15~31 ~40~15~31 minecraft:double_stone_block_slab 6
fill ~39~88~31 ~40~88~33 minecraft:double_stone_block_slab 6
fill ~39~156~31 ~39~157~31 minecraft:glowstone
fill ~39~161~31 ~40~161~31 minecraft:glowstone
setblock ~39~162~31 minecraft:glowstone
setblock ~40~106~31 minecraft:double_stone_block_slab 6
fill ~40~157~31 ~40~160~31 minecraft:glowstone
setblock ~41~0~31 minecraft:red_flower 0
fill ~41~11~31 ~42~11~31 minecraft:double_stone_block_slab 6
fill ~41~12~31 ~42~12~31 minecraft:stained_glass 11
fill ~43~10~31 ~43~10~32 minecraft:stained_glass 11
setblock ~45~9~31 minecraft:concrete 15
fill ~46~8~31 ~47~8~31 minecraft:double_stone_block_slab 6
fill ~50~7~31 ~50~7~45 minecraft:double_stone_block_slab 6
fill ~53~5~31 ~53~5~34 minecraft:double_stone_block_slab 6
fill ~54~0~31 ~54~4~33 minecraft:double_stone_block_slab 6
fill ~56~90~31 ~56~90~34 minecraft:double_stone_block_slab 6
fill ~56~105~31 ~56~105~34 minecraft:double_stone_block_slab 6
fill ~59~91~31 ~59~91~34 minecraft:double_stone_block_slab 6
fill ~59~104~31 ~59~104~34 minecraft:double_stone_block_slab 6
fill ~16~6~32 ~16~6~44 minecraft:double_stone_block_slab 6
fill ~17~106~32 ~17~106~37 minecraft:concrete 11
fill ~18~106~32 ~18~106~44 minecraft:sea_lantern
fill ~19~106~32 ~19~106~37 minecraft:concrete 11
fill ~21~8~32 ~21~8~33 minecraft:double_stone_block_slab 6
fill ~22~9~32 ~23~9~32 minecraft:double_stone_block_slab 6
setblock ~24~10~32 minecraft:concrete 15
fill ~24~89~32 ~24~89~34 minecraft:double_stone_block_slab 6
fill ~26~11~32 ~26~11~33 minecraft:double_stone_block_slab 6
fill ~26~12~32 ~26~12~33 minecraft:stained_glass 11
fill ~27~13~32 ~28~13~32 minecraft:double_stone_block_slab 6
fill ~27~14~32 ~28~14~32 minecraft:stained_glass 11
fill ~27~15~32 ~28~15~32 minecraft:double_stone_block_slab 6
fill ~27~88~32 ~27~88~34 minecraft:double_stone_block_slab 6
fill ~27~90~32 ~29~90~32 minecraft:double_stone_block_slab 6
fill ~27~105~32 ~29~105~32 minecraft:double_stone_block_slab 6
setblock ~27~106~32 minecraft:double_stone_block_slab 6
fill ~27~157~32 ~27~157~33 minecraft:glowstone
fill ~27~158~32 ~27~161~32 minecraft:glowstone
fill ~28~107~32 ~28~108~32 minecraft:double_stone_block_slab 6
fill ~28~155~32 ~28~156~32 minecraft:glowstone
fill ~28~162~32 ~28~163~32 minecraft:glowstone
fill ~29~16~32 ~31~16~32 minecraft:double_stone_block_slab 6
fill ~29~17~32 ~30~17~32 minecraft:stained_glass 11
fill ~29~18~32 ~31~18~32 minecraft:double_stone_block_slab 6
fill ~29~19~32 ~30~19~32 minecraft:stained_glass 11
fill ~29~20~32 ~31~20~32 minecraft:double_stone_block_slab 6
fill ~29~21~32 ~30~21~32 minecraft:stained_glass 11
fill ~29~22~32 ~31~22~32 minecraft:double_stone_block_slab 6
fill ~29~23~32 ~30~23~32 minecraft:stained_glass 11
fill ~29~24~32 ~31~24~32 minecraft:double_stone_block_slab 6
fill ~29~25~32 ~30~25~32 minecraft:stained_glass 11
fill ~29~26~32 ~31~26~32 minecraft:double_stone_block_slab 6
fill ~29~27~32 ~30~27~32 minecraft:stained_glass 11
fill ~29~28~32 ~31~28~32 minecraft:double_stone_block_slab 6
fill ~29~29~32 ~30~29~32 minecraft:stained_glass 11
fill ~29~30~32 ~31~30~32 minecraft:double_stone_block_slab 6
fill ~29~31~32 ~30~31~32 minecraft:stained_glass 11
fill ~29~32~32 ~31~32~32 minecraft:double_stone_block_slab 6
fill ~29~33~32 ~30~33~32 minecraft:stained_glass 11
fill ~29~34~32 ~31~34~32 minecraft:double_stone_block_slab 6
fill ~29~35~32 ~30~35~32 minecraft:stained_glass 11
fill ~29~36~32 ~31~36~32 minecraft:double_stone_block_slab 6
fill ~29~37~32 ~30~37~32 minecraft:stained_glass 11
fill ~29~38~32 ~31~38~32 minecraft:double_stone_block_slab 6
fill ~29~39~32 ~30~39~32 minecraft:stained_glass 11
fill ~29~40~32 ~31~40~32 minecraft:double_stone_block_slab 6
fill ~29~41~32 ~30~41~32 minecraft:stained_glass 11
fill ~29~42~32 ~31~42~32 minecraft:double_stone_block_slab 6
fill ~29~43~32 ~30~43~32 minecraft:stained_glass 11
fill ~29~44~32 ~31~44~32 minecraft:double_stone_block_slab 6
fill ~29~45~32 ~30~45~32 minecraft:stained_glass 11
fill ~29~46~32 ~31~46~32 minecraft:double_stone_block_slab 6
fill ~29~47~32 ~30~47~32 minecraft:stained_glass 11
fill ~29~48~32 ~31~48~32 minecraft:double_stone_block_slab 6
fill ~29~49~32 ~30~49~32 minecraft:stained_glass 11
fill ~29~50~32 ~31~50~32 minecraft:double_stone_block_slab 6
fill ~29~51~32 ~30~51~32 minecraft:stained_glass 11
fill ~29~52~32 ~31~52~32 minecraft:double_stone_block_slab 6
fill ~29~53~32 ~30~53~32 minecraft:stained_glass 11
fill ~29~54~32 ~31~54~32 minecraft:double_stone_block_slab 6
fill ~29~55~32 ~30~55~32 minecraft:stained_glass 11
fill ~29~56~32 ~31~56~32 minecraft:double_stone_block_slab 6
fill ~29~57~32 ~30~57~32 minecraft:stained_glass 11
fill ~29~58~32 ~31~58~32 minecraft:double_stone_block_slab 6
fill ~29~59~32 ~30~59~32 minecraft:stained_glass 11
fill ~29~60~32 ~31~60~32 minecraft:double_stone_block_slab 6
fill ~29~61~32 ~30~61~32 minecraft:stained_glass 11
fill ~29~62~32 ~31~62~32 minecraft:double_stone_block_slab 6
fill ~29~63~32 ~30~63~32 minecraft:stained_glass 11
fill ~29~64~32 ~31~64~32 minecraft:double_stone_block_slab 6
fill ~29~65~32 ~30~65~32 minecraft:stained_glass 11
fill ~29~66~32 ~31~66~32 minecraft:double_stone_block_slab 6
fill ~29~67~32 ~30~67~32 minecraft:stained_glass 11
fill ~29~68~32 ~31~68~32 minecraft:double_stone_block_slab 6
fill ~29~69~32 ~30~69~32 minecraft:stained_glass 11
fill ~29~70~32 ~31~70~32 minecraft:double_stone_block_slab 6
fill ~29~71~32 ~30~71~32 minecraft:stained_glass 11
fill ~29~72~32 ~31~72~32 minecraft:double_stone_block_slab 6
fill ~29~73~32 ~30~73~32 minecraft:stained_glass 11
fill ~29~74~32 ~31~74~32 minecraft:double_stone_block_slab 6
fill ~29~75~32 ~30~75~32 minecraft:stained_glass 11
fill ~29~76~32 ~31~76~32 minecraft:double_stone_block_slab 6
fill ~29~77~32 ~30~77~32 minecraft:stained_glass 11
fill ~29~78~32 ~31~78~32 minecraft:double_stone_block_slab 6
fill ~29~79~32 ~30~79~32 minecraft:stained_glass 11
fill ~29~80~32 ~31~80~32 minecraft:double_stone_block_slab 6
fill ~29~81~32 ~30~81~32 minecraft:stained_glass 11
fill ~29~82~32 ~31~82~32 minecraft:double_stone_block_slab 6
fill ~29~83~32 ~30~83~32 minecraft:stained_glass 11
fill ~29~84~32 ~31~84~32 minecraft:double_stone_block_slab 6
fill ~29~85~32 ~30~85~32 minecraft:stained_glass 11
fill ~29~86~32 ~31~87~32 minecraft:double_stone_block_slab 6
fill ~29~109~32 ~30~111~32 minecraft:double_stone_block_slab 6
setblock ~29~154~32 minecraft:glowstone
setblock ~29~164~32 minecraft:glowstone
setblock ~30~90~32 minecraft:concrete 15
setblock ~30~105~32 minecraft:concrete 15
fill ~30~153~32 ~31~153~32 minecraft:glowstone
fill ~30~165~32 ~31~165~32 minecraft:glowstone
setblock ~31~17~32 minecraft:double_stone_block_slab 6
setblock ~31~19~32 minecraft:double_stone_block_slab 6
setblock ~31~21~32 minecraft:double_stone_block_slab 6
setblock ~31~23~32 minecraft:double_stone_block_slab 6
setblock ~31~25~32 minecraft:double_stone_block_slab 6
setblock ~31~27~32 minecraft:double_stone_block_slab 6
setblock ~31~29~32 minecraft:double_stone_block_slab 6
setblock ~31~31~32 minecraft:double_stone_block_slab 6
setblock ~31~33~32 minecraft:double_stone_block_slab 6
setblock ~31~35~32 minecraft:double_stone_block_slab 6
setblock ~31~37~32 minecraft:double_stone_block_slab 6
setblock ~31~39~32 minecraft:double_stone_block_slab 6
setblock ~31~41~32 minecraft:double_stone_block_slab 6
setblock ~31~43~32 minecraft:double_stone_block_slab 6
setblock ~31~45~32 minecraft:double_stone_block_slab 6
setblock ~31~47~32 minecraft:double_stone_block_slab 6
setblock ~31~49~32 minecraft:double_stone_block_slab 6
setblock ~31~51~32 minecraft:double_stone_block_slab 6
setblock ~31~53~32 minecraft:double_stone_block_slab 6
setblock ~31~55~32 minecraft:double_stone_block_slab 6
setblock ~31~57~32 minecraft:double_stone_block_slab 6
setblock ~31~59~32 minecraft:double_stone_block_slab 6
setblock ~31~61~32 minecraft:double_stone_block_slab 6
setblock ~31~63~32 minecraft:double_stone_block_slab 6
setblock ~31~65~32 minecraft:double_stone_block_slab 6
setblock ~31~67~32 minecraft:double_stone_block_slab 6
setblock ~31~69~32 minecraft:double_stone_block_slab 6
setblock ~31~71~32 minecraft:double_stone_block_slab 6
setblock ~31~73~32 minecraft:double_stone_block_slab 6
setblock ~31~75~32 minecraft:double_stone_block_slab 6
setblock ~31~77~32 minecraft:double_stone_block_slab 6
setblock ~31~79~32 minecraft:double_stone_block_slab 6
setblock ~31~81~32 minecraft:double_stone_block_slab 6
setblock ~31~83~32 minecraft:double_stone_block_slab 6
setblock ~31~85~32 minecraft:double_stone_block_slab 6
fill ~31~88~32 ~31~90~32 minecraft:double_stone_block_slab 6
fill ~31~105~32 ~31~105~33 minecraft:double_stone_block_slab 6
fill ~31~112~32 ~31~115~32 minecraft:concrete 15
fill ~32~112~32 ~36~115~32 minecraft:double_stone_block_slab 6
fill ~32~152~32 ~36~152~32 minecraft:glowstone
fill ~32~166~32 ~36~166~32 minecraft:glowstone
fill ~33~116~32 ~33~120~32 minecraft:concrete 11
fill ~33~135~32 ~33~143~32 minecraft:concrete 11
fill ~34~116~32 ~34~120~32 minecraft:sea_lantern
fill ~34~135~32 ~34~143~32 minecraft:sea_lantern
fill ~35~116~32 ~35~120~32 minecraft:concrete 11
fill ~35~135~32 ~35~143~32 minecraft:concrete 11
fill ~37~16~32 ~39~16~32 minecraft:double_stone_block_slab 6
fill ~37~17~32 ~37~90~32 minecraft:double_stone_block_slab 6
fill ~37~105~32 ~37~105~33 minecraft:double_stone_block_slab 6
fill ~37~112~32 ~37~115~32 minecraft:concrete 15
fill ~37~153~32 ~38~153~32 minecraft:glowstone
fill ~37~165~32 ~38~165~32 minecraft:glowstone
fill ~38~17~32 ~39~17~32 minecraft:stained_glass 11
fill ~38~18~32 ~39~18~32 minecraft:double_stone_block_slab 6
fill ~38~19~32 ~39~19~32 minecraft:stained_glass 11
fill ~38~20~32 ~39~20~32 minecraft:double_stone_block_slab 6
fill ~38~21~32 ~39~21~32 minecraft:stained_glass 11
fill ~38~22~32 ~39~22~32 minecraft:double_stone_block_slab 6
fill ~38~23~32 ~39~23~32 minecraft:stained_glass 11
fill ~38~24~32 ~39~24~32 minecraft:double_stone_block_slab 6
fill ~38~25~32 ~39~25~32 minecraft:stained_glass 11
fill ~38~26~32 ~39~26~32 minecraft:double_stone_block_slab 6
fill ~38~27~32 ~39~27~32 minecraft:stained_glass 11
fill ~38~28~32 ~39~28~32 minecraft:double_stone_block_slab 6
fill ~38~29~32 ~39~29~32 minecraft:stained_glass 11
fill ~38~30~32 ~39~30~32 minecraft:double_stone_block_slab 6
fill ~38~31~32 ~39~31~32 minecraft:stained_glass 11
fill ~38~32~32 ~39~32~32 minecraft:double_stone_block_slab 6
fill ~38~33~32 ~39~33~32 minecraft:stained_glass 11
fill ~38~34~32 ~39~34~32 minecraft:double_stone_block_slab 6
fill ~38~35~32 ~39~35~32 minecraft:stained_glass 11
fill ~38~36~32 ~39~36~32 minecraft:double_stone_block_slab 6
fill ~38~37~32 ~39~37~32 minecraft:stained_glass 11
fill ~38~38~32 ~39~38~32 minecraft:double_stone_block_slab 6
fill ~38~39~32 ~39~39~32 minecraft:stained_glass 11
fill ~38~40~32 ~39~40~32 minecraft:double_stone_block_slab 6
fill ~38~41~32 ~39~41~32 minecraft:stained_glass 11
fill ~38~42~32 ~39~42~32 minecraft:double_stone_block_slab 6
fill ~38~43~32 ~39~43~32 minecraft:stained_glass 11
fill ~38~44~32 ~39~44~32 minecraft:double_stone_block_slab 6
fill ~38~45~32 ~39~45~32 minecraft:stained_glass 11
fill ~38~46~32 ~39~46~32 minecraft:double_stone_block_slab 6
fill ~38~47~32 ~39~47~32 minecraft:stained_glass 11
fill ~38~48~32 ~39~48~32 minecraft:double_stone_block_slab 6
fill ~38~49~32 ~39~49~32 minecraft:stained_glass 11
fill ~38~50~32 ~39~50~32 minecraft:double_stone_block_slab 6
fill ~38~51~32 ~39~51~32 minecraft:stained_glass 11
fill ~38~52~32 ~39~52~32 minecraft:double_stone_block_slab 6
fill ~38~53~32 ~39~53~32 minecraft:stained_glass 11
fill ~38~54~32 ~39~54~32 minecraft:double_stone_block_slab 6
fill ~38~55~32 ~39~55~32 minecraft:stained_glass 11
fill ~38~56~32 ~39~56~32 minecraft:double_stone_block_slab 6
fill ~38~57~32 ~39~57~32 minecraft:stained_glass 11
fill ~38~58~32 ~39~58~32 minecraft:double_stone_block_slab 6
fill ~38~59~32 ~39~59~32 minecraft:stained_glass 11
fill ~38~60~32 ~39~60~32 minecraft:double_stone_block_slab 6
fill ~38~61~32 ~39~61~32 minecraft:stained_glass 11
fill ~38~62~32 ~39~62~32 minecraft:double_stone_block_slab 6
fill ~38~63~32 ~39~63~32 minecraft:stained_glass 11
fill ~38~64~32 ~39~64~32 minecraft:double_stone_block_slab 6
fill ~38~65~32 ~39~65~32 minecraft:stained_glass 11
fill ~38~66~32 ~39~66~32 minecraft:double_stone_block_slab 6
fill ~38~67~32 ~39~67~32 minecraft:stained_glass 11
fill ~38~68~32 ~39~68~32 minecraft:double_stone_block_slab 6
fill ~38~69~32 ~39~69~32 minecraft:stained_glass 11
fill ~38~70~32 ~39~70~32 minecraft:double_stone_block_slab 6
fill ~38~71~32 ~39~71~32 minecraft:stained_glass 11
fill ~38~72~32 ~39~72~32 minecraft:double_stone_block_slab 6
fill ~38~73~32 ~39~73~32 minecraft:stained_glass 11
fill ~38~74~32 ~39~74~32 minecraft:double_stone_block_slab 6
fill ~38~75~32 ~39~75~32 minecraft:stained_glass 11
fill ~38~76~32 ~39~76~32 minecraft:double_stone_block_slab 6
fill ~38~77~32 ~39~77~32 minecraft:stained_glass 11
fill ~38~78~32 ~39~78~32 minecraft:double_stone_block_slab 6
fill ~38~79~32 ~39~79~32 minecraft:stained_glass 11
fill ~38~80~32 ~39~80~32 minecraft:double_stone_block_slab 6
fill ~38~81~32 ~39~81~32 minecraft:stained_glass 11
fill ~38~82~32 ~39~82~32 minecraft:double_stone_block_slab 6
fill ~38~83~32 ~39~83~32 minecraft:stained_glass 11
fill ~38~84~32 ~39~84~32 minecraft:double_stone_block_slab 6
fill ~38~85~32 ~39~85~32 minecraft:stained_glass 11
fill ~38~86~32 ~39~87~32 minecraft:double_stone_block_slab 6
setblock ~38~90~32 minecraft:concrete 15
setblock ~38~105~32 minecraft:concrete 15
fill ~38~109~32 ~39~111~32 minecraft:double_stone_block_slab 6
fill ~39~90~32 ~41~90~32 minecraft:double_stone_block_slab 6
fill ~39~105~32 ~41~105~32 minecraft:double_stone_block_slab 6
setblock ~39~154~32 minecraft:glowstone
setblock ~39~164~32 minecraft:glowstone
fill ~40~13~32 ~41~13~32 minecraft:double_stone_block_slab 6
fill ~40~14~32 ~41~14~32 minecraft:stained_glass 11
fill ~40~15~32 ~41~15~32 minecraft:double_stone_block_slab 6
setblock ~40~106~32 minecraft:concrete 15
fill ~40~107~32 ~40~108~32 minecraft:double_stone_block_slab 6
fill ~40~155~32 ~40~156~32 minecraft:glowstone
fill ~40~162~32 ~40~163~32 minecraft:glowstone
fill ~41~88~32 ~41~88~34 minecraft:double_stone_block_slab 6
setblock ~41~106~32 minecraft:double_stone_block_slab 6
fill ~41~157~32 ~41~157~33 minecraft:glowstone
fill ~41~158~32 ~41~161~32 minecraft:glowstone
fill ~42~11~32 ~42~11~33 minecraft:double_stone_block_slab 6
fill ~42~12~32 ~42~12~33 minecraft:stained_glass 11
setblock ~44~10~32 minecraft:concrete 15
fill ~44~89~32 ~44~89~34 minecraft:double_stone_block_slab 6
fill ~45~9~32 ~46~9~32 minecraft:double_stone_block_slab 6
fill ~47~8~32 ~47~8~33 minecraft:double_stone_block_slab 6
fill ~49~106~32 ~49~106~37 minecraft:concrete 11
fill ~50~106~32 ~50~106~44 minecraft:sea_lantern
fill ~51~106~32 ~51~106~37 minecraft:concrete 11
fill ~52~6~32 ~52~6~44 minecraft:double_stone_block_slab 6
fill ~3~98~33 ~3~98~43 minecraft:double_stone_block_slab 6
fill ~5~94~33 ~5~94~34 minecraft:double_stone_block_slab 6
fill ~5~95~33 ~5~100~43 minecraft:stained_glass 11
fill ~5~101~33 ~5~101~34 minecraft:double_stone_block_slab 6
fill ~6~93~33 ~6~93~34 minecraft:double_stone_block_slab 6
fill ~6~102~33 ~6~102~34 minecraft:double_stone_block_slab 6
fill ~17~7~33 ~17~7~43 minecraft:double_stone_block_slab 6
fill ~19~7~33 ~19~7~47 minecraft:double_stone_block_slab 6
fill ~20~8~33 ~20~8~43 minecraft:double_stone_block_slab 6
fill ~22~9~33 ~22~9~34 minecraft:double_stone_block_slab 6
fill ~23~10~33 ~24~10~33 minecraft:double_stone_block_slab 6
fill ~25~11~33 ~25~12~33 minecraft:concrete 15
fill ~26~106~33 ~26~106~34 minecraft:double_stone_block_slab 6
fill ~26~158~33 ~26~158~35 minecraft:glowstone
fill ~26~159~33 ~26~160~34 minecraft:glowstone
fill ~27~13~33 ~27~13~34 minecraft:double_stone_block_slab 6
setblock ~27~14~33 minecraft:stained_glass 11
fill ~27~15~33 ~27~15~34 minecraft:double_stone_block_slab 6
fill ~27~90~33 ~28~90~33 minecraft:double_stone_block_slab 6
fill ~27~105~33 ~28~105~33 minecraft:double_stone_block_slab 6
fill ~27~107~33 ~27~108~34 minecraft:double_stone_block_slab 6
fill ~27~155~33 ~27~155~34 minecraft:glowstone
setblock ~27~156~33 minecraft:glowstone
fill ~27~161~33 ~27~163~33 minecraft:glowstone
fill ~28~16~33 ~29~16~33 minecraft:double_stone_block_slab 6
fill ~28~17~33 ~29~17~33 minecraft:stained_glass 11
fill ~28~18~33 ~29~18~33 minecraft:double_stone_block_slab 6
fill ~28~19~33 ~29~19~33 minecraft:stained_glass 11
fill ~28~20~33 ~29~20~33 minecraft:double_stone_block_slab 6
fill ~28~21~33 ~29~21~33 minecraft:stained_glass 11
fill ~28~22~33 ~29~22~33 minecraft:double_stone_block_slab 6
fill ~28~23~33 ~29~23~33 minecraft:stained_glass 11
fill ~28~24~33 ~29~24~33 minecraft:double_stone_block_slab 6
fill ~28~25~33 ~29~25~33 minecraft:stained_glass 11
fill ~28~26~33 ~29~26~33 minecraft:double_stone_block_slab 6
fill ~28~27~33 ~29~27~33 minecraft:stained_glass 11
fill ~28~28~33 ~29~28~33 minecraft:double_stone_block_slab 6
fill ~28~29~33 ~29~29~33 minecraft:stained_glass 11
fill ~28~30~33 ~29~30~33 minecraft:double_stone_block_slab 6
fill ~28~31~33 ~29~31~33 minecraft:stained_glass 11
fill ~28~32~33 ~29~32~33 minecraft:double_stone_block_slab 6
fill ~28~33~33 ~29~33~33 minecraft:stained_glass 11
fill ~28~34~33 ~29~34~33 minecraft:double_stone_block_slab 6
fill ~28~35~33 ~29~35~33 minecraft:stained_glass 11
fill ~28~36~33 ~29~36~33 minecraft:double_stone_block_slab 6
fill ~28~37~33 ~29~37~33 minecraft:stained_glass 11
fill ~28~38~33 ~29~38~33 minecraft:double_stone_block_slab 6
fill ~28~39~33 ~29~39~33 minecraft:stained_glass 11
fill ~28~40~33 ~29~40~33 minecraft:double_stone_block_slab 6
fill ~28~41~33 ~29~41~33 minecraft:stained_glass 11
fill ~28~42~33 ~29~42~33 minecraft:double_stone_block_slab 6
fill ~28~43~33 ~29~43~33 minecraft:stained_glass 11
fill ~28~44~33 ~29~44~33 minecraft:double_stone_block_slab 6
fill ~28~45~33 ~29~45~33 minecraft:stained_glass 11
fill ~28~46~33 ~29~46~33 minecraft:double_stone_block_slab 6
fill ~28~47~33 ~29~47~33 minecraft:stained_glass 11
fill ~28~48~33 ~29~48~33 minecraft:double_stone_block_slab 6
fill ~28~49~33 ~29~49~33 minecraft:stained_glass 11
fill ~28~50~33 ~29~50~33 minecraft:double_stone_block_slab 6
fill ~28~51~33 ~29~51~33 minecraft:stained_glass 11
fill ~28~52~33 ~29~52~33 minecraft:double_stone_block_slab 6
fill ~28~53~33 ~29~53~33 minecraft:stained_glass 11
fill ~28~54~33 ~29~54~33 minecraft:double_stone_block_slab 6
fill ~28~55~33 ~29~55~33 minecraft:stained_glass 11
fill ~28~56~33 ~29~56~33 minecraft:double_stone_block_slab 6
fill ~28~57~33 ~29~57~33 minecraft:stained_glass 11
fill ~28~58~33 ~29~58~33 minecraft:double_stone_block_slab 6
fill ~28~59~33 ~29~59~33 minecraft:stained_glass 11
fill ~28~60~33 ~29~60~33 minecraft:double_stone_block_slab 6
fill ~28~61~33 ~29~61~33 minecraft:stained_glass 11
fill ~28~62~33 ~29~62~33 minecraft:double_stone_block_slab 6
fill ~28~63~33 ~29~63~33 minecraft:stained_glass 11
fill ~28~64~33 ~29~64~33 minecraft:double_stone_block_slab 6
fill ~28~65~33 ~29~65~33 minecraft:stained_glass 11
fill ~28~66~33 ~29~66~33 minecraft:double_stone_block_slab 6
fill ~28~67~33 ~29~67~33 minecraft:stained_glass 11
fill ~28~68~33 ~29~68~33 minecraft:double_stone_block_slab 6
fill ~28~69~33 ~29~69~33 minecraft:stained_glass 11
fill ~28~70~33 ~29~70~33 minecraft:double_stone_block_slab 6
fill ~28~71~33 ~29~71~33 minecraft:stained_glass 11
fill ~28~72~33 ~29~72~33 minecraft:double_stone_block_slab 6
fill ~28~73~33 ~29~73~33 minecraft:stained_glass 11
fill ~28~74~33 ~29~74~33 minecraft:double_stone_block_slab 6
fill ~28~75~33 ~29~75~33 minecraft:stained_glass 11
fill ~28~76~33 ~29~76~33 minecraft:double_stone_block_slab 6
fill ~28~77~33 ~29~77~33 minecraft:stained_glass 11
fill ~28~78~33 ~29~78~33 minecraft:double_stone_block_slab 6
fill ~28~79~33 ~29~79~33 minecraft:stained_glass 11
fill ~28~80~33 ~29~80~33 minecraft:double_stone_block_slab 6
fill ~28~81~33 ~29~81~33 minecraft:stained_glass 11
fill ~28~82~33 ~29~82~33 minecraft:double_stone_block_slab 6
fill ~28~83~33 ~29~83~33 minecraft:stained_glass 11
fill ~28~84~33 ~29~84~33 minecraft:double_stone_block_slab 6
fill ~28~85~33 ~29~85~33 minecraft:stained_glass 11
fill ~28~86~33 ~29~87~33 minecraft:double_stone_block_slab 6
fill ~28~89~33 ~29~89~33 minecraft:double_stone_block_slab 6
fill ~28~109~33 ~28~111~34 minecraft:double_stone_block_slab 6
setblock ~28~154~33 minecraft:glowstone
setblock ~28~164~33 minecraft:glowstone
setblock ~29~90~33 minecraft:concrete 15
setblock ~29~105~33 minecraft:concrete 15
fill ~29~112~33 ~30~115~33 minecraft:double_stone_block_slab 6
setblock ~29~153~33 minecraft:glowstone
setblock ~29~165~33 minecraft:glowstone
fill ~30~90~33 ~31~90~43 minecraft:double_stone_block_slab 6
fill ~30~105~33 ~30~105~34 minecraft:double_stone_block_slab 6
fill ~30~152~33 ~32~152~33 minecraft:glowstone
fill ~30~166~33 ~32~166~33 minecraft:glowstone
fill ~31~116~33 ~31~120~33 minecraft:concrete 15
setblock ~32~105~33 minecraft:concrete 11
fill ~32~116~33 ~36~120~33 minecraft:double_stone_block_slab 6
setblock ~33~105~33 minecraft:sea_lantern
fill ~33~121~33 ~33~134~33 minecraft:concrete 11
fill ~33~151~33 ~35~151~34 minecraft:glowstone
fill ~33~167~33 ~35~167~34 minecraft:glowstone
setblock ~34~105~33 minecraft:concrete 11
fill ~34~121~33 ~34~134~33 minecraft:sea_lantern
setblock ~35~105~33 minecraft:sea_lantern
fill ~35~121~33 ~35~134~33 minecraft:concrete 11
setblock ~36~105~33 minecraft:concrete 11
fill ~36~152~33 ~38~152~33 minecraft:glowstone
fill ~36~166~33 ~38~166~33 minecraft:glowstone
fill ~37~90~33 ~38~90~43 minecraft:double_stone_block_slab 6
fill ~37~116~33 ~37~120~33 minecraft:concrete 15
fill ~38~105~33 ~38~105~34 minecraft:double_stone_block_slab 6
fill ~38~112~33 ~39~115~33 minecraft:double_stone_block_slab 6
fill ~39~16~33 ~40~16~33 minecraft:double_stone_block_slab 6
fill ~39~17~33 ~40~17~33 minecraft:stained_glass 11
fill ~39~18~33 ~40~18~33 minecraft:double_stone_block_slab 6
fill ~39~19~33 ~40~19~33 minecraft:stained_glass 11
fill ~39~20~33 ~40~20~33 minecraft:double_stone_block_slab 6
fill ~39~21~33 ~40~21~33 minecraft:stained_glass 11
fill ~39~22~33 ~40~22~33 minecraft:double_stone_block_slab 6
fill ~39~23~33 ~40~23~33 minecraft:stained_glass 11
fill ~39~24~33 ~40~24~33 minecraft:double_stone_block_slab 6
fill ~39~25~33 ~40~25~33 minecraft:stained_glass 11
fill ~39~26~33 ~40~26~33 minecraft:double_stone_block_slab 6
fill ~39~27~33 ~40~27~33 minecraft:stained_glass 11
fill ~39~28~33 ~40~28~33 minecraft:double_stone_block_slab 6
fill ~39~29~33 ~40~29~33 minecraft:stained_glass 11
fill ~39~30~33 ~40~30~33 minecraft:double_stone_block_slab 6
fill ~39~31~33 ~40~31~33 minecraft:stained_glass 11
fill ~39~32~33 ~40~32~33 minecraft:double_stone_block_slab 6
fill ~39~33~33 ~40~33~33 minecraft:stained_glass 11
fill ~39~34~33 ~40~34~33 minecraft:double_stone_block_slab 6
fill ~39~35~33 ~40~35~33 minecraft:stained_glass 11
fill ~39~36~33 ~40~36~33 minecraft:double_stone_block_slab 6
fill ~39~37~33 ~40~37~33 minecraft:stained_glass 11
fill ~39~38~33 ~40~38~33 minecraft:double_stone_block_slab 6
fill ~39~39~33 ~40~39~33 minecraft:stained_glass 11
fill ~39~40~33 ~40~40~33 minecraft:double_stone_block_slab 6
fill ~39~41~33 ~40~41~33 minecraft:stained_glass 11
fill ~39~42~33 ~40~42~33 minecraft:double_stone_block_slab 6
fill ~39~43~33 ~40~43~33 minecraft:stained_glass 11
fill ~39~44~33 ~40~44~33 minecraft:double_stone_block_slab 6
fill ~39~45~33 ~40~45~33 minecraft:stained_glass 11
fill ~39~46~33 ~40~46~33 minecraft:double_stone_block_slab 6
fill ~39~47~33 ~40~47~33 minecraft:stained_glass 11
fill ~39~48~33 ~40~48~33 minecraft:double_stone_block_slab 6
fill ~39~49~33 ~40~49~33 minecraft:stained_glass 11
fill ~39~50~33 ~40~50~33 minecraft:double_stone_block_slab 6
fill ~39~51~33 ~40~51~33 minecraft:stained_glass 11
fill ~39~52~33 ~40~52~33 minecraft:double_stone_block_slab 6
fill ~39~53~33 ~40~53~33 minecraft:stained_glass 11
fill ~39~54~33 ~40~54~33 minecraft:double_stone_block_slab 6
fill ~39~55~33 ~40~55~33 minecraft:stained_glass 11
fill ~39~56~33 ~40~56~33 minecraft:double_stone_block_slab 6
fill ~39~57~33 ~40~57~33 minecraft:stained_glass 11
fill ~39~58~33 ~40~58~33 minecraft:double_stone_block_slab 6
fill ~39~59~33 ~40~59~33 minecraft:stained_glass 11
fill ~39~60~33 ~40~60~33 minecraft:double_stone_block_slab 6
fill ~39~61~33 ~40~61~33 minecraft:stained_glass 11
fill ~39~62~33 ~40~62~33 minecraft:double_stone_block_slab 6
fill ~39~63~33 ~40~63~33 minecraft:stained_glass 11
fill ~39~64~33 ~40~64~33 minecraft:double_stone_block_slab 6
fill ~39~65~33 ~40~65~33 minecraft:stained_glass 11
fill ~39~66~33 ~40~66~33 minecraft:double_stone_block_slab 6
fill ~39~67~33 ~40~67~33 minecraft:stained_glass 11
fill ~39~68~33 ~40~68~33 minecraft:double_stone_block_slab 6
fill ~39~69~33 ~40~69~33 minecraft:stained_glass 11
fill ~39~70~33 ~40~70~33 minecraft:double_stone_block_slab 6
fill ~39~71~33 ~40~71~33 minecraft:stained_glass 11
fill ~39~72~33 ~40~72~33 minecraft:double_stone_block_slab 6
fill ~39~73~33 ~40~73~33 minecraft:stained_glass 11
fill ~39~74~33 ~40~74~33 minecraft:double_stone_block_slab 6
fill ~39~75~33 ~40~75~33 minecraft:stained_glass 11
fill ~39~76~33 ~40~76~33 minecraft:double_stone_block_slab 6
fill ~39~77~33 ~40~77~33 minecraft:stained_glass 11
fill ~39~78~33 ~40~78~33 minecraft:double_stone_block_slab 6
fill ~39~79~33 ~40~79~33 minecraft:stained_glass 11
fill ~39~80~33 ~40~80~33 minecraft:double_stone_block_slab 6
fill ~39~81~33 ~40~81~33 minecraft:stained_glass 11
fill ~39~82~33 ~40~82~33 minecraft:double_stone_block_slab 6
fill ~39~83~33 ~40~83~33 minecraft:stained_glass 11
fill ~39~84~33 ~40~84~33 minecraft:double_stone_block_slab 6
fill ~39~85~33 ~40~85~33 minecraft:stained_glass 11
fill ~39~86~33 ~40~87~33 minecraft:double_stone_block_slab 6
fill ~39~89~33 ~40~89~33 minecraft:double_stone_block_slab 6
setblock ~39~90~33 minecraft:concrete 15
setblock ~39~105~33 minecraft:concrete 15
setblock ~39~153~33 minecraft:glowstone
setblock ~39~165~33 minecraft:glowstone
fill ~40~90~33 ~41~90~33 minecraft:double_stone_block_slab 6
fill ~40~105~33 ~41~105~33 minecraft:double_stone_block_slab 6
fill ~40~109~33 ~40~111~34 minecraft:double_stone_block_slab 6
setblock ~40~154~33 minecraft:glowstone
setblock ~40~164~33 minecraft:glowstone
fill ~41~13~33 ~41~13~34 minecraft:double_stone_block_slab 6
setblock ~41~14~33 minecraft:stained_glass 11
fill ~41~15~33 ~41~15~34 minecraft:double_stone_block_slab 6
fill ~41~107~33 ~41~108~34 minecraft:double_stone_block_slab 6
fill ~41~155~33 ~41~155~34 minecraft:glowstone
setblock ~41~156~33 minecraft:glowstone
fill ~41~161~33 ~41~163~33 minecraft:glowstone
fill ~42~106~33 ~42~106~34 minecraft:double_stone_block_slab 6
fill ~42~158~33 ~42~158~35 minecraft:glowstone
fill ~42~159~33 ~42~160~34 minecraft:glowstone
fill ~43~11~33 ~43~12~33 minecraft:concrete 15
fill ~44~10~33 ~45~10~33 minecraft:double_stone_block_slab 6
fill ~46~9~33 ~46~9~34 minecraft:double_stone_block_slab 6
fill ~48~8~33 ~48~8~43 minecraft:double_stone_block_slab 6
fill ~49~7~33 ~49~7~47 minecraft:double_stone_block_slab 6
fill ~51~7~33 ~51~7~43 minecraft:double_stone_block_slab 6
fill ~62~93~33 ~62~93~34 minecraft:double_stone_block_slab 6
fill ~62~102~33 ~62~102~34 minecraft:double_stone_block_slab 6
fill ~63~94~33 ~63~94~34 minecraft:double_stone_block_slab 6
fill ~63~95~33 ~63~100~43 minecraft:stained_glass 11
fill ~63~101~33 ~63~101~34 minecraft:double_stone_block_slab 6
fill ~65~98~33 ~65~98~43 minecraft:double_stone_block_slab 6
setblock ~7~92~34 minecraft:double_stone_block_slab 6
setblock ~7~103~34 minecraft:double_stone_block_slab 6
fill ~13~0~34 ~13~4~42 minecraft:double_stone_block_slab 6
fill ~14~5~34 ~14~5~42 minecraft:double_stone_block_slab 6
fill ~21~9~34 ~21~9~42 minecraft:double_stone_block_slab 6
fill ~23~10~34 ~23~10~35 minecraft:double_stone_block_slab 6
fill ~24~11~34 ~25~12~34 minecraft:double_stone_block_slab 6
fill ~26~13~34 ~26~15~34 minecraft:concrete 15
setblock ~26~88~34 minecraft:double_stone_block_slab 6
fill ~26~156~34 ~26~156~37 minecraft:glowstone
fill ~26~157~34 ~26~157~35 minecraft:glowstone
fill ~26~161~34 ~26~162~35 minecraft:glowstone
setblock ~27~14~34 minecraft:double_stone_block_slab 6
setblock ~27~90~34 minecraft:double_stone_block_slab 6
setblock ~27~105~34 minecraft:double_stone_block_slab 6
fill ~27~154~34 ~27~154~36 minecraft:glowstone
fill ~27~163~34 ~27~164~34 minecraft:glowstone
fill ~28~16~34 ~28~16~35 minecraft:double_stone_block_slab 6
setblock ~28~17~34 minecraft:stained_glass 11
fill ~28~18~34 ~28~18~35 minecraft:double_stone_block_slab 6
setblock ~28~19~34 minecraft:stained_glass 11
fill ~28~20~34 ~28~20~35 minecraft:double_stone_block_slab 6
setblock ~28~21~34 minecraft:stained_glass 11
fill ~28~22~34 ~28~22~35 minecraft:double_stone_block_slab 6
setblock ~28~23~34 minecraft:stained_glass 11
fill ~28~24~34 ~28~24~35 minecraft:double_stone_block_slab 6
setblock ~28~25~34 minecraft:stained_glass 11
fill ~28~26~34 ~28~26~35 minecraft:double_stone_block_slab 6
setblock ~28~27~34 minecraft:stained_glass 11
fill ~28~28~34 ~28~28~35 minecraft:double_stone_block_slab 6
setblock ~28~29~34 minecraft:stained_glass 11
fill ~28~30~34 ~28~30~35 minecraft:double_stone_block_slab 6
setblock ~28~31~34 minecraft:stained_glass 11
fill ~28~32~34 ~28~32~35 minecraft:double_stone_block_slab 6
setblock ~28~33~34 minecraft:stained_glass 11
fill ~28~34~34 ~28~34~35 minecraft:double_stone_block_slab 6
setblock ~28~35~34 minecraft:stained_glass 11
fill ~28~36~34 ~28~36~35 minecraft:double_stone_block_slab 6
setblock ~28~37~34 minecraft:stained_glass 11
fill ~28~38~34 ~28~38~35 minecraft:double_stone_block_slab 6
setblock ~28~39~34 minecraft:stained_glass 11
fill ~28~40~34 ~28~40~35 minecraft:double_stone_block_slab 6
setblock ~28~41~34 minecraft:stained_glass 11
fill ~28~42~34 ~28~42~35 minecraft:double_stone_block_slab 6
setblock ~28~43~34 minecraft:stained_glass 11
fill ~28~44~34 ~28~44~35 minecraft:double_stone_block_slab 6
setblock ~28~45~34 minecraft:stained_glass 11
fill ~28~46~34 ~28~46~35 minecraft:double_stone_block_slab 6
setblock ~28~47~34 minecraft:stained_glass 11
fill ~28~48~34 ~28~48~35 minecraft:double_stone_block_slab 6
setblock ~28~49~34 minecraft:stained_glass 11
fill ~28~50~34 ~28~50~35 minecraft:double_stone_block_slab 6
setblock ~28~51~34 minecraft:stained_glass 11
fill ~28~52~34 ~28~52~35 minecraft:double_stone_block_slab 6
setblock ~28~53~34 minecraft:stained_glass 11
fill ~28~54~34 ~28~54~35 minecraft:double_stone_block_slab 6
setblock ~28~55~34 minecraft:stained_glass 11
fill ~28~56~34 ~28~56~35 minecraft:double_stone_block_slab 6
setblock ~28~57~34 minecraft:stained_glass 11
fill ~28~58~34 ~28~58~35 minecraft:double_stone_block_slab 6
setblock ~28~59~34 minecraft:stained_glass 11
fill ~28~60~34 ~28~60~35 minecraft:double_stone_block_slab 6
setblock ~28~61~34 minecraft:stained_glass 11
fill ~28~62~34 ~28~62~35 minecraft:double_stone_block_slab 6
setblock ~28~63~34 minecraft:stained_glass 11
fill ~28~64~34 ~28~64~35 minecraft:double_stone_block_slab 6
setblock ~28~65~34 minecraft:stained_glass 11
fill ~28~66~34 ~28~66~35 minecraft:double_stone_block_slab 6
setblock ~28~67~34 minecraft:stained_glass 11
fill ~28~68~34 ~28~68~35 minecraft:double_stone_block_slab 6
setblock ~28~69~34 minecraft:stained_glass 11
fill ~28~70~34 ~28~70~35 minecraft:double_stone_block_slab 6
setblock ~28~71~34 minecraft:stained_glass 11
fill ~28~72~34 ~28~72~35 minecraft:double_stone_block_slab 6
setblock ~28~73~34 minecraft:stained_glass 11
fill ~28~74~34 ~28~74~35 minecraft:double_stone_block_slab 6
setblock ~28~75~34 minecraft:stained_glass 11
fill ~28~76~34 ~28~76~35 minecraft:double_stone_block_slab 6
setblock ~28~77~34 minecraft:stained_glass 11
fill ~28~78~34 ~28~78~35 minecraft:double_stone_block_slab 6
setblock ~28~79~34 minecraft:stained_glass 11
fill ~28~80~34 ~28~80~35 minecraft:double_stone_block_slab 6
setblock ~28~81~34 minecraft:stained_glass 11
fill ~28~82~34 ~28~82~35 minecraft:double_stone_block_slab 6
setblock ~28~83~34 minecraft:stained_glass 11
fill ~28~84~34 ~28~84~35 minecraft:double_stone_block_slab 6
setblock ~28~85~34 minecraft:stained_glass 11
fill ~28~86~34 ~28~89~35 minecraft:double_stone_block_slab 6
setblock ~28~90~34 minecraft:concrete 15
setblock ~28~105~34 minecraft:concrete 15
fill ~28~153~34 ~28~153~35 minecraft:glowstone
fill ~28~165~34 ~28~165~35 minecraft:glowstone
fill ~29~90~34 ~29~90~42 minecraft:double_stone_block_slab 6
fill ~29~105~34 ~29~105~35 minecraft:double_stone_block_slab 6
fill ~29~112~34 ~29~115~34 minecraft:double_stone_block_slab 6
fill ~29~152~34 ~30~152~34 minecraft:glowstone
fill ~29~166~34 ~30~166~34 minecraft:glowstone
fill ~30~116~34 ~30~120~34 minecraft:double_stone_block_slab 6
setblock ~31~105~34 minecraft:concrete 11
fill ~31~121~34 ~31~125~34 minecraft:concrete 15
fill ~31~151~34 ~32~151~35 minecraft:glowstone
fill ~31~167~34 ~32~167~35 minecraft:glowstone
fill ~32~105~34 ~36~105~34 minecraft:double_stone_block_slab 6
fill ~32~121~34 ~36~125~34 minecraft:double_stone_block_slab 6
fill ~36~151~34 ~37~151~35 minecraft:glowstone
fill ~36~167~34 ~37~167~35 minecraft:glowstone
setblock ~37~105~34 minecraft:concrete 11
fill ~37~121~34 ~37~125~34 minecraft:concrete 15
fill ~38~116~34 ~38~120~34 minecraft:double_stone_block_slab 6
fill ~38~152~34 ~39~152~34 minecraft:glowstone
fill ~38~166~34 ~39~166~34 minecraft:glowstone
fill ~39~90~34 ~39~90~42 minecraft:double_stone_block_slab 6
fill ~39~105~34 ~39~105~35 minecraft:double_stone_block_slab 6
fill ~39~112~34 ~39~115~34 minecraft:double_stone_block_slab 6
fill ~40~16~34 ~40~16~35 minecraft:double_stone_block_slab 6
setblock ~40~17~34 minecraft:stained_glass 11
fill ~40~18~34 ~40~18~35 minecraft:double_stone_block_slab 6
setblock ~40~19~34 minecraft:stained_glass 11
fill ~40~20~34 ~40~20~35 minecraft:double_stone_block_slab 6
setblock ~40~21~34 minecraft:stained_glass 11
fill ~40~22~34 ~40~22~35 minecraft:double_stone_block_slab 6
setblock ~40~23~34 minecraft:stained_glass 11
fill ~40~24~34 ~40~24~35 minecraft:double_stone_block_slab 6
setblock ~40~25~34 minecraft:stained_glass 11
fill ~40~26~34 ~40~26~35 minecraft:double_stone_block_slab 6
setblock ~40~27~34 minecraft:stained_glass 11
fill ~40~28~34 ~40~28~35 minecraft:double_stone_block_slab 6
setblock ~40~29~34 minecraft:stained_glass 11
fill ~40~30~34 ~40~30~35 minecraft:double_stone_block_slab 6
setblock ~40~31~34 minecraft:stained_glass 11
fill ~40~32~34 ~40~32~35 minecraft:double_stone_block_slab 6
setblock ~40~33~34 minecraft:stained_glass 11
fill ~40~34~34 ~40~34~35 minecraft:double_stone_block_slab 6
setblock ~40~35~34 minecraft:stained_glass 11
fill ~40~36~34 ~40~36~35 minecraft:double_stone_block_slab 6
setblock ~40~37~34 minecraft:stained_glass 11
fill ~40~38~34 ~40~38~35 minecraft:double_stone_block_slab 6
setblock ~40~39~34 minecraft:stained_glass 11
fill ~40~40~34 ~40~40~35 minecraft:double_stone_block_slab 6
setblock ~40~41~34 minecraft:stained_glass 11
fill ~40~42~34 ~40~42~35 minecraft:double_stone_block_slab 6
setblock ~40~43~34 minecraft:stained_glass 11
fill ~40~44~34 ~40~44~35 minecraft:double_stone_block_slab 6
setblock ~40~45~34 minecraft:stained_glass 11
fill ~40~46~34 ~40~46~35 minecraft:double_stone_block_slab 6
setblock ~40~47~34 minecraft:stained_glass 11
fill ~40~48~34 ~40~48~35 minecraft:double_stone_block_slab 6
setblock ~40~49~34 minecraft:stained_glass 11
fill ~40~50~34 ~40~50~35 minecraft:double_stone_block_slab 6
setblock ~40~51~34 minecraft:stained_glass 11
fill ~40~52~34 ~40~52~35 minecraft:double_stone_block_slab 6
setblock ~40~53~34 minecraft:stained_glass 11
fill ~40~54~34 ~40~54~35 minecraft:double_stone_block_slab 6
setblock ~40~55~34 minecraft:stained_glass 11
fill ~40~56~34 ~40~56~35 minecraft:double_stone_block_slab 6
setblock ~40~57~34 minecraft:stained_glass 11
fill ~40~58~34 ~40~58~35 minecraft:double_stone_block_slab 6
setblock ~40~59~34 minecraft:stained_glass 11
fill ~40~60~34 ~40~60~35 minecraft:double_stone_block_slab 6
setblock ~40~61~34 minecraft:stained_glass 11
fill ~40~62~34 ~40~62~35 minecraft:double_stone_block_slab 6
setblock ~40~63~34 minecraft:stained_glass 11
fill ~40~64~34 ~40~64~35 minecraft:double_stone_block_slab 6
setblock ~40~65~34 minecraft:stained_glass 11
fill ~40~66~34 ~40~66~35 minecraft:double_stone_block_slab 6
setblock ~40~67~34 minecraft:stained_glass 11
fill ~40~68~34 ~40~68~35 minecraft:double_stone_block_slab 6
setblock ~40~69~34 minecraft:stained_glass 11
fill ~40~70~34 ~40~70~35 minecraft:double_stone_block_slab 6
setblock ~40~71~34 minecraft:stained_glass 11
fill ~40~72~34 ~40~72~35 minecraft:double_stone_block_slab 6
setblock ~40~73~34 minecraft:stained_glass 11
fill ~40~74~34 ~40~74~35 minecraft:double_stone_block_slab 6
setblock ~40~75~34 minecraft:stained_glass 11
fill ~40~76~34 ~40~76~35 minecraft:double_stone_block_slab 6
setblock ~40~77~34 minecraft:stained_glass 11
fill ~40~78~34 ~40~78~35 minecraft:double_stone_block_slab 6
setblock ~40~79~34 minecraft:stained_glass 11
fill ~40~80~34 ~40~80~35 minecraft:double_stone_block_slab 6
setblock ~40~81~34 minecraft:stained_glass 11
fill ~40~82~34 ~40~82~35 minecraft:double_stone_block_slab 6
setblock ~40~83~34 minecraft:stained_glass 11
fill ~40~84~34 ~40~84~35 minecraft:double_stone_block_slab 6
setblock ~40~85~34 minecraft:stained_glass 11
fill ~40~86~34 ~40~89~35 minecraft:double_stone_block_slab 6
setblock ~40~90~34 minecraft:concrete 15
setblock ~40~105~34 minecraft:concrete 15
fill ~40~153~34 ~40~153~35 minecraft:glowstone
fill ~40~165~34 ~40~165~35 minecraft:glowstone
setblock ~41~14~34 minecraft:double_stone_block_slab 6
setblock ~41~90~34 minecraft:double_stone_block_slab 6
setblock ~41~105~34 minecraft:double_stone_block_slab 6
fill ~41~154~34 ~41~154~36 minecraft:glowstone
fill ~41~163~34 ~41~164~34 minecraft:glowstone
fill ~42~13~34 ~42~15~34 minecraft:concrete 15
setblock ~42~88~34 minecraft:double_stone_block_slab 6
fill ~42~156~34 ~42~156~37 minecraft:glowstone
fill ~42~157~34 ~42~157~35 minecraft:glowstone
fill ~42~161~34 ~42~162~35 minecraft:glowstone
fill ~43~11~34 ~44~12~34 minecraft:double_stone_block_slab 6
fill ~45~10~34 ~45~10~35 minecraft:double_stone_block_slab 6
fill ~47~9~34 ~47~9~42 minecraft:double_stone_block_slab 6
fill ~54~5~34 ~54~5~42 minecraft:double_stone_block_slab 6
fill ~55~0~34 ~55~4~42 minecraft:double_stone_block_slab 6
setblock ~61~92~34 minecraft:double_stone_block_slab 6
setblock ~61~103~34 minecraft:double_stone_block_slab 6
setblock ~2~98~35 minecraft:concrete 15
fill ~3~97~35 ~4~97~35 minecraft:concrete 15
fill ~3~99~35 ~4~99~35 minecraft:concrete 15
fill ~4~95~35 ~4~96~35 minecraft:concrete 15
setblock ~4~100~35 minecraft:concrete 15
setblock ~5~94~35 minecraft:concrete 15
setblock ~5~101~35 minecraft:concrete 15
setblock ~6~93~35 minecraft:concrete 15
setblock ~6~102~35 minecraft:concrete 15
fill ~7~92~35 ~8~92~35 minecraft:concrete 15
fill ~7~103~35 ~8~103~35 minecraft:concrete 15
fill ~9~91~35 ~11~91~35 minecraft:concrete 15
fill ~9~104~35 ~11~104~35 minecraft:concrete 15
fill ~12~90~35 ~27~90~35 minecraft:concrete 15
fill ~12~105~35 ~27~105~35 minecraft:concrete 15
fill ~15~6~35 ~15~6~41 minecraft:double_stone_block_slab 6
fill ~22~10~35 ~22~10~41 minecraft:double_stone_block_slab 6
fill ~24~11~35 ~24~12~36 minecraft:double_stone_block_slab 6
fill ~24~89~35 ~27~89~35 minecraft:concrete 15
fill ~25~13~35 ~26~15~35 minecraft:double_stone_block_slab 6
setblock ~25~106~35 minecraft:concrete 15
fill ~25~159~35 ~25~159~41 minecraft:glowstone
fill ~26~88~35 ~27~88~35 minecraft:concrete 15
fill ~26~107~35 ~26~108~35 minecraft:concrete 15
fill ~26~155~35 ~26~155~41 minecraft:glowstone
setblock ~26~160~35 minecraft:glowstone
fill ~26~163~35 ~26~163~41 minecraft:glowstone
fill ~27~16~35 ~27~87~35 minecraft:concrete 15
fill ~27~109~35 ~27~111~35 minecraft:concrete 15
fill ~27~164~35 ~27~164~36 minecraft:glowstone
setblock ~28~17~35 minecraft:double_stone_block_slab 6
setblock ~28~19~35 minecraft:double_stone_block_slab 6
setblock ~28~21~35 minecraft:double_stone_block_slab 6
setblock ~28~23~35 minecraft:double_stone_block_slab 6
setblock ~28~25~35 minecraft:double_stone_block_slab 6
setblock ~28~27~35 minecraft:double_stone_block_slab 6
setblock ~28~29~35 minecraft:double_stone_block_slab 6
setblock ~28~31~35 minecraft:double_stone_block_slab 6
setblock ~28~33~35 minecraft:double_stone_block_slab 6
setblock ~28~35~35 minecraft:double_stone_block_slab 6
setblock ~28~37~35 minecraft:double_stone_block_slab 6
setblock ~28~39~35 minecraft:double_stone_block_slab 6
setblock ~28~41~35 minecraft:double_stone_block_slab 6
setblock ~28~43~35 minecraft:double_stone_block_slab 6
setblock ~28~45~35 minecraft:double_stone_block_slab 6
setblock ~28~47~35 minecraft:double_stone_block_slab 6
setblock ~28~49~35 minecraft:double_stone_block_slab 6
setblock ~28~51~35 minecraft:double_stone_block_slab 6
setblock ~28~53~35 minecraft:double_stone_block_slab 6
setblock ~28~55~35 minecraft:double_stone_block_slab 6
setblock ~28~57~35 minecraft:double_stone_block_slab 6
setblock ~28~59~35 minecraft:double_stone_block_slab 6
setblock ~28~61~35 minecraft:double_stone_block_slab 6
setblock ~28~63~35 minecraft:double_stone_block_slab 6
setblock ~28~65~35 minecraft:double_stone_block_slab 6
setblock ~28~67~35 minecraft:double_stone_block_slab 6
setblock ~28~69~35 minecraft:double_stone_block_slab 6
setblock ~28~71~35 minecraft:double_stone_block_slab 6
setblock ~28~73~35 minecraft:double_stone_block_slab 6
setblock ~28~75~35 minecraft:double_stone_block_slab 6
setblock ~28~77~35 minecraft:double_stone_block_slab 6
setblock ~28~79~35 minecraft:double_stone_block_slab 6
setblock ~28~81~35 minecraft:double_stone_block_slab 6
setblock ~28~83~35 minecraft:double_stone_block_slab 6
setblock ~28~85~35 minecraft:double_stone_block_slab 6
fill ~28~90~35 ~28~90~41 minecraft:double_stone_block_slab 6
fill ~28~105~35 ~28~105~41 minecraft:double_stone_block_slab 6
fill ~28~112~35 ~28~115~35 minecraft:concrete 15
fill ~29~116~35 ~29~120~35 minecraft:concrete 15
fill ~29~152~35 ~29~152~36 minecraft:glowstone
fill ~29~166~35 ~29~166~36 minecraft:glowstone
setblock ~30~105~35 minecraft:concrete 11
fill ~30~121~35 ~30~125~35 minecraft:concrete 15
fill ~30~151~35 ~30~151~41 minecraft:glowstone
fill ~30~167~35 ~30~167~41 minecraft:glowstone
fill ~31~105~35 ~32~105~35 minecraft:double_stone_block_slab 6
setblock ~31~125~35 minecraft:double_stone_block_slab 6
fill ~32~126~35 ~32~130~35 minecraft:concrete 15
fill ~33~105~35 ~35~105~35 minecraft:concrete 11
fill ~33~126~35 ~35~130~35 minecraft:double_stone_block_slab 6
setblock ~33~151~35 minecraft:glowstone
setblock ~33~167~35 minecraft:glowstone
fill ~34~150~35 ~34~150~41 minecraft:glowstone
fill ~34~168~35 ~34~168~41 minecraft:glowstone
setblock ~35~151~35 minecraft:glowstone
setblock ~35~167~35 minecraft:glowstone
fill ~36~105~35 ~37~105~35 minecraft:double_stone_block_slab 6
fill ~36~126~35 ~36~130~35 minecraft:concrete 15
setblock ~37~125~35 minecraft:double_stone_block_slab 6
setblock ~38~105~35 minecraft:concrete 11
fill ~38~121~35 ~38~125~35 minecraft:concrete 15
fill ~38~151~35 ~38~151~41 minecraft:glowstone
fill ~38~167~35 ~38~167~41 minecraft:glowstone
fill ~39~116~35 ~39~120~35 minecraft:concrete 15
fill ~39~152~35 ~39~152~36 minecraft:glowstone
fill ~39~166~35 ~39~166~36 minecraft:glowstone
setblock ~40~17~35 minecraft:double_stone_block_slab 6
setblock ~40~19~35 minecraft:double_stone_block_slab 6
setblock ~40~21~35 minecraft:double_stone_block_slab 6
setblock ~40~23~35 minecraft:double_stone_block_slab 6
setblock ~40~25~35 minecraft:double_stone_block_slab 6
setblock ~40~27~35 minecraft:double_stone_block_slab 6
setblock ~40~29~35 minecraft:double_stone_block_slab 6
setblock ~40~31~35 minecraft:double_stone_block_slab 6
setblock ~40~33~35 minecraft:double_stone_block_slab 6
setblock ~40~35~35 minecraft:double_stone_block_slab 6
setblock ~40~37~35 minecraft:double_stone_block_slab 6
setblock ~40~39~35 minecraft:double_stone_block_slab 6
setblock ~40~41~35 minecraft:double_stone_block_slab 6
setblock ~40~43~35 minecraft:double_stone_block_slab 6
setblock ~40~45~35 minecraft:double_stone_block_slab 6
setblock ~40~47~35 minecraft:double_stone_block_slab 6
setblock ~40~49~35 minecraft:double_stone_block_slab 6
setblock ~40~51~35 minecraft:double_stone_block_slab 6
setblock ~40~53~35 minecraft:double_stone_block_slab 6
setblock ~40~55~35 minecraft:double_stone_block_slab 6
setblock ~40~57~35 minecraft:double_stone_block_slab 6
setblock ~40~59~35 minecraft:double_stone_block_slab 6
setblock ~40~61~35 minecraft:double_stone_block_slab 6
setblock ~40~63~35 minecraft:double_stone_block_slab 6
setblock ~40~65~35 minecraft:double_stone_block_slab 6
setblock ~40~67~35 minecraft:double_stone_block_slab 6
setblock ~40~69~35 minecraft:double_stone_block_slab 6
setblock ~40~71~35 minecraft:double_stone_block_slab 6
setblock ~40~73~35 minecraft:double_stone_block_slab 6
setblock ~40~75~35 minecraft:double_stone_block_slab 6
setblock ~40~77~35 minecraft:double_stone_block_slab 6
setblock ~40~79~35 minecraft:double_stone_block_slab 6
setblock ~40~81~35 minecraft:double_stone_block_slab 6
setblock ~40~83~35 minecraft:double_stone_block_slab 6
setblock ~40~85~35 minecraft:double_stone_block_slab 6
fill ~40~90~35 ~40~90~41 minecraft:double_stone_block_slab 6
fill ~40~105~35 ~40~105~41 minecraft:double_stone_block_slab 6
fill ~40~112~35 ~40~115~35 minecraft:concrete 15
fill ~41~16~35 ~41~90~35 minecraft:concrete 15
fill ~41~105~35 ~56~105~35 minecraft:concrete 15
fill ~41~109~35 ~41~111~35 minecraft:concrete 15
fill ~41~164~35 ~41~164~36 minecraft:glowstone
fill ~42~13~35 ~43~15~35 minecraft:double_stone_block_slab 6
setblock ~42~88~35 minecraft:concrete 15
fill ~42~90~35 ~56~90~35 minecraft:concrete 15
fill ~42~107~35 ~42~108~35 minecraft:concrete 15
fill ~42~155~35 ~42~155~41 minecraft:glowstone
setblock ~42~160~35 minecraft:glowstone
fill ~42~163~35 ~42~163~41 minecraft:glowstone
fill ~43~89~35 ~44~89~35 minecraft:concrete 15
setblock ~43~106~35 minecraft:concrete 15
fill ~43~159~35 ~43~159~41 minecraft:glowstone
fill ~44~11~35 ~44~12~36 minecraft:double_stone_block_slab 6
fill ~46~10~35 ~46~10~41 minecraft:double_stone_block_slab 6
fill ~53~6~35 ~53~6~41 minecraft:double_stone_block_slab 6
fill ~57~91~35 ~59~91~35 minecraft:concrete 15
fill ~57~104~35 ~59~104~35 minecraft:concrete 15
fill ~60~92~35 ~61~92~35 minecraft:concrete 15
fill ~60~103~35 ~61~103~35 minecraft:concrete 15
setblock ~62~93~35 minecraft:concrete 15
setblock ~62~102~35 minecraft:concrete 15
setblock ~63~94~35 minecraft:concrete 15
setblock ~63~101~35 minecraft:concrete 15
fill ~64~95~35 ~64~97~35 minecraft:concrete 15
fill ~64~99~35 ~65~99~35 minecraft:concrete 15
setblock ~64~100~35 minecraft:concrete 15
setblock ~65~97~35 minecraft:concrete 15
setblock ~66~98~35 minecraft:concrete 15
fill ~5~94~36 ~5~94~40 minecraft:double_stone_block_slab 6
fill ~5~101~36 ~5~101~40 minecraft:double_stone_block_slab 6
fill ~6~93~36 ~6~93~40 minecraft:double_stone_block_slab 6
fill ~6~102~36 ~6~102~40 minecraft:double_stone_block_slab 6
fill ~7~92~36 ~8~92~40 minecraft:double_stone_block_slab 6
fill ~7~103~36 ~8~103~40 minecraft:double_stone_block_slab 6
fill ~9~91~36 ~11~91~40 minecraft:double_stone_block_slab 6
fill ~9~104~36 ~11~104~40 minecraft:double_stone_block_slab 6
fill ~12~90~36 ~27~90~40 minecraft:double_stone_block_slab 6
fill ~12~105~36 ~27~105~40 minecraft:double_stone_block_slab 6
fill ~23~11~36 ~23~12~40 minecraft:double_stone_block_slab 6
fill ~24~89~36 ~27~89~40 minecraft:double_stone_block_slab 6
fill ~25~13~36 ~25~15~41 minecraft:double_stone_block_slab 6
fill ~25~106~36 ~25~106~40 minecraft:double_stone_block_slab 6
fill ~25~157~36 ~25~158~40 minecraft:glowstone
fill ~25~160~36 ~25~161~40 minecraft:glowstone
fill ~26~15~36 ~26~15~41 minecraft:double_stone_block_slab 6
fill ~26~88~36 ~27~88~40 minecraft:double_stone_block_slab 6
fill ~26~107~36 ~26~108~40 minecraft:double_stone_block_slab 6
fill ~26~162~36 ~26~162~37 minecraft:glowstone
fill ~27~16~36 ~27~87~40 minecraft:double_stone_block_slab 6
fill ~27~109~36 ~27~111~40 minecraft:double_stone_block_slab 6
fill ~27~153~36 ~27~153~40 minecraft:glowstone
fill ~27~165~36 ~27~165~40 minecraft:glowstone
fill ~28~112~36 ~28~115~40 minecraft:double_stone_block_slab 6
fill ~28~152~36 ~28~152~40 minecraft:glowstone
fill ~28~166~36 ~28~166~40 minecraft:glowstone
setblock ~29~105~36 minecraft:concrete 11
fill ~29~116~36 ~29~120~40 minecraft:double_stone_block_slab 6
fill ~30~105~36 ~31~105~36 minecraft:double_stone_block_slab 6
fill ~30~121~36 ~30~125~40 minecraft:double_stone_block_slab 6
fill ~31~126~36 ~31~130~36 minecraft:concrete 15
fill ~31~151~36 ~31~151~37 minecraft:glowstone
fill ~31~167~36 ~31~167~37 minecraft:glowstone
setblock ~32~105~36 minecraft:sea_lantern
setblock ~32~130~36 minecraft:double_stone_block_slab 6
fill ~32~150~36 ~33~150~40 minecraft:glowstone
fill ~32~168~36 ~33~168~40 minecraft:glowstone
fill ~33~105~36 ~35~105~36 minecraft:double_stone_block_slab 6
fill ~33~131~36 ~33~135~36 minecraft:concrete 15
fill ~34~131~36 ~34~135~36 minecraft:double_stone_block_slab 6
fill ~35~131~36 ~35~135~36 minecraft:concrete 15
fill ~35~150~36 ~36~150~40 minecraft:glowstone
fill ~35~168~36 ~36~168~40 minecraft:glowstone
setblock ~36~105~36 minecraft:sea_lantern
setblock ~36~130~36 minecraft:double_stone_block_slab 6
fill ~37~105~36 ~38~105~36 minecraft:double_stone_block_slab 6
fill ~37~126~36 ~37~130~36 minecraft:concrete 15
fill ~37~151~36 ~37~151~37 minecraft:glowstone
fill ~37~167~36 ~37~167~37 minecraft:glowstone
fill ~38~121~36 ~38~125~40 minecraft:double_stone_block_slab 6
setblock ~39~105~36 minecraft:concrete 11
fill ~39~116~36 ~39~120~40 minecraft:double_stone_block_slab 6
fill ~40~112~36 ~40~115~40 minecraft:double_stone_block_slab 6
fill ~40~152~36 ~40~152~40 minecraft:glowstone
fill ~40~166~36 ~40~166~40 minecraft:glowstone
fill ~41~16~36 ~41~90~40 minecraft:double_stone_block_slab 6
fill ~41~105~36 ~56~105~40 minecraft:double_stone_block_slab 6
fill ~41~109~36 ~41~111~40 minecraft:double_stone_block_slab 6
fill ~41~153~36 ~41~153~40 minecraft:glowstone
fill ~41~165~36 ~41~165~40 minecraft:glowstone
fill ~42~15~36 ~43~15~41 minecraft:double_stone_block_slab 6
