fill ~169~1~4 ~170~1~4 minecraft:concrete 0
setblock ~171~1~4 minecraft:clay
fill ~172~1~4 ~175~1~4 minecraft:concrete 0
fill ~169~1~5 ~170~1~5 minecraft:stone_block_slab 14
fill ~169~2~5 ~170~2~5 minecraft:stone_block_slab 6
setblock ~171~1~5 minecraft:stone_block_slab 8
setblock ~171~2~5 minecraft:stone_block_slab 0
fill ~172~1~5 ~175~1~5 minecraft:stone_block_slab 14
fill ~172~2~5 ~175~2~5 minecraft:stone_block_slab 6
fill ~168~2~6 ~170~2~6 minecraft:concrete 0
setblock ~171~2~6 minecraft:clay
fill ~172~2~6 ~176~2~6 minecraft:concrete 0
fill ~168~2~7 ~170~2~7 minecraft:stone_block_slab 14
fill ~168~3~7 ~170~3~7 minecraft:stone_block_slab 6
setblock ~171~2~7 minecraft:stone_block_slab 8
setblock ~171~3~7 minecraft:stone_block_slab 0
fill ~172~2~7 ~176~2~7 minecraft:stone_block_slab 14
fill ~172~3~7 ~176~3~7 minecraft:stone_block_slab 6
fill ~167~3~8 ~170~3~8 minecraft:concrete 0
setblock ~171~3~8 minecraft:clay
fill ~172~3~8 ~177~3~8 minecraft:concrete 0
fill ~167~3~9 ~170~3~9 minecraft:stone_block_slab 14
fill ~167~4~9 ~170~4~9 minecraft:stone_block_slab 6
setblock ~171~3~9 minecraft:stone_block_slab 8
setblock ~171~4~9 minecraft:stone_block_slab 0
fill ~172~3~9 ~177~3~9 minecraft:stone_block_slab 14
fill ~172~4~9 ~177~4~9 minecraft:stone_block_slab 6
fill ~166~4~10 ~170~4~10 minecraft:concrete 0
setblock ~171~4~10 minecraft:clay
fill ~172~4~10 ~178~4~10 minecraft:concrete 0
fill ~166~4~11 ~170~4~11 minecraft:stone_block_slab 14
fill ~166~5~11 ~170~5~11 minecraft:stone_block_slab 6
setblock ~171~4~11 minecraft:stone_block_slab 8
setblock ~171~5~11 minecraft:stone_block_slab 0
fill ~172~4~11 ~178~4~11 minecraft:stone_block_slab 14
fill ~172~5~11 ~178~5~11 minecraft:stone_block_slab 6
fill ~165~5~12 ~170~5~12 minecraft:concrete 0
setblock ~171~5~12 minecraft:clay
fill ~172~5~12 ~179~5~12 minecraft:concrete 0
fill ~165~5~13 ~170~5~13 minecraft:stone_block_slab 14
fill ~165~6~13 ~170~6~13 minecraft:stone_block_slab 6
setblock ~171~5~13 minecraft:stone_block_slab 8
setblock ~171~6~13 minecraft:stone_block_slab 0
fill ~172~5~13 ~179~5~13 minecraft:stone_block_slab 14
fill ~172~6~13 ~179~6~13 minecraft:stone_block_slab 6
fill ~164~6~14 ~169~6~14 minecraft:concrete 0
setblock ~170~6~14 minecraft:clay
fill ~171~6~14 ~180~6~14 minecraft:concrete 0
fill ~164~6~15 ~168~6~15 minecraft:stone_block_slab 14
fill ~164~7~15 ~168~7~15 minecraft:stone_block_slab 6
setblock ~169~6~15 minecraft:stone_block_slab 8
setblock ~169~7~15 minecraft:stone_block_slab 0
fill ~170~6~15 ~180~6~15 minecraft:stone_block_slab 14
fill ~170~7~15 ~180~7~15 minecraft:stone_block_slab 6
fill ~165~7~16 ~167~7~16 minecraft:concrete 0
setblock ~168~7~16 minecraft:clay
fill ~169~7~16 ~179~7~16 minecraft:concrete 0
setblock ~166~7~17 minecraft:stone_block_slab 14
setblock ~166~8~17 minecraft:stone_block_slab 6
setblock ~167~7~17 minecraft:stone_block_slab 8
setblock ~167~8~17 minecraft:stone_block_slab 0
fill ~168~7~17 ~178~7~17 minecraft:stone_block_slab 14
fill ~168~8~17 ~178~8~17 minecraft:stone_block_slab 6
fill ~167~8~18 ~177~8~18 minecraft:concrete 0
setblock ~167~9~18 minecraft:stone_brick_stairs 2
setblock ~169~9~18 minecraft:stone_brick_stairs 2
setblock ~171~9~18 minecraft:stone_brick_stairs 2
setblock ~173~9~18 minecraft:stone_brick_stairs 2
setblock ~175~9~18 minecraft:stone_brick_stairs 2
setblock ~177~9~18 minecraft:stone_brick_stairs 2
fill ~162~10~19 ~179~10~19 minecraft:concrete 0
setblock ~162~11~19 minecraft:quartz_stairs 4
fill ~162~13~19 ~179~13~19 minecraft:stone_block_slab 14
fill ~162~14~19 ~179~14~20 minecraft:stone_block_slab 6
fill ~163~11~19 ~164~11~19 minecraft:stone_block_slab 14
setblock ~165~11~19 minecraft:quartz_stairs 4
fill ~167~8~19 ~167~8~20 minecraft:cobblestone_wall 0
fill ~167~9~19 ~167~9~20 minecraft:observer 3
setblock ~169~8~19 minecraft:cobblestone_wall 0
setblock ~169~9~19 minecraft:observer 3
fill ~169~11~19 ~175~11~19 minecraft:stone_block_slab 5
setblock ~171~8~19 minecraft:cobblestone_wall 0
setblock ~171~9~19 minecraft:observer 3
setblock ~173~8~19 minecraft:cobblestone_wall 0
setblock ~173~9~19 minecraft:observer 3
setblock ~175~8~19 minecraft:cobblestone_wall 0
setblock ~175~9~19 minecraft:observer 3
fill ~177~8~19 ~177~8~20 minecraft:cobblestone_wall 0
fill ~177~9~19 ~177~9~20 minecraft:observer 3
setblock ~178~11~19 minecraft:quartz_stairs 5
setblock ~179~11~19 minecraft:stone_block_slab 14
fill ~161~10~20 ~168~10~20 minecraft:concrete 0
setblock ~161~11~20 minecraft:stone_block_slab 14
fill ~161~13~20 ~165~13~20 minecraft:stone_block_slab 14
setblock ~161~14~20 minecraft:stone_block_slab 6
fill ~166~11~20 ~168~11~20 minecraft:stone_block_slab 5
fill ~166~13~20 ~168~13~20 minecraft:double_stone_block_slab 5
fill ~169~8~20 ~175~9~21 minecraft:concrete 0
fill ~169~10~20 ~175~13~20 minecraft:concrete 7
fill ~176~10~20 ~182~10~20 minecraft:concrete 0
fill ~176~11~20 ~178~11~20 minecraft:stone_block_slab 5
fill ~176~13~20 ~182~13~20 minecraft:stone_block_slab 14
setblock ~180~11~20 minecraft:stone_block_slab 14
fill ~180~14~20 ~182~14~20 minecraft:stone_block_slab 6
setblock ~181~11~20 minecraft:quartz_stairs 5
setblock ~182~11~20 minecraft:stone_block_slab 14
fill ~160~10~21 ~165~10~21 minecraft:concrete 0
setblock ~160~11~21 minecraft:stone_block_slab 14
fill ~160~14~21 ~184~14~21 minecraft:concrete 0
fill ~164~11~21 ~165~11~21 minecraft:stone_block_slab 5
fill ~164~13~21 ~165~13~21 minecraft:stone_block_slab 13
fill ~166~8~21 ~168~9~22 minecraft:concrete 0
fill ~166~10~21 ~168~13~21 minecraft:concrete 7
fill ~169~13~21 ~175~13~21 minecraft:concrete 0
fill ~176~8~21 ~178~9~22 minecraft:concrete 0
fill ~176~10~21 ~178~13~21 minecraft:concrete 7
fill ~179~10~21 ~184~10~21 minecraft:concrete 0
fill ~179~11~21 ~180~11~21 minecraft:stone_block_slab 5
fill ~179~13~21 ~180~13~21 minecraft:stone_block_slab 13
setblock ~183~11~21 minecraft:stone_block_slab 14
setblock ~184~11~21 minecraft:quartz_stairs 5
fill ~159~10~22 ~163~10~22 minecraft:concrete 0
setblock ~159~11~22 minecraft:quartz_stairs 4
fill ~159~14~22 ~168~14~22 minecraft:concrete 0
setblock ~163~11~22 minecraft:stone_block_slab 5
setblock ~163~13~22 minecraft:stone_block_slab 13
fill ~164~8~22 ~165~8~23 minecraft:stone_block_slab 14
fill ~164~9~22 ~165~9~23 minecraft:concrete 0
fill ~164~10~22 ~165~13~22 minecraft:concrete 7
fill ~166~13~22 ~168~13~22 minecraft:concrete 0
fill ~176~13~22 ~178~14~22 minecraft:concrete 0
fill ~179~8~22 ~180~8~23 minecraft:stone_block_slab 14
fill ~179~9~22 ~180~9~23 minecraft:concrete 0
fill ~179~10~22 ~180~13~22 minecraft:concrete 7
fill ~179~14~22 ~186~14~22 minecraft:concrete 0
fill ~181~10~22 ~186~10~22 minecraft:concrete 0
setblock ~181~11~22 minecraft:stone_block_slab 5
setblock ~181~13~22 minecraft:stone_block_slab 13
fill ~185~11~22 ~186~11~22 minecraft:stone_block_slab 14
fill ~157~14~23 ~161~14~23 minecraft:stone_block_slab 14
fill ~157~15~23 ~165~15~23 minecraft:stone_block_slab 6
fill ~158~10~23 ~162~10~23 minecraft:concrete 0
setblock ~158~11~23 minecraft:stone_block_slab 14
setblock ~162~11~23 minecraft:stone_block_slab 5
setblock ~162~14~23 minecraft:double_stone_block_slab 5
fill ~163~8~23 ~163~8~24 minecraft:stone_block_slab 14
fill ~163~9~23 ~163~9~24 minecraft:concrete 0
fill ~163~10~23 ~163~14~23 minecraft:concrete 7
fill ~164~10~23 ~165~10~23 minecraft:stone_block_slab 6
fill ~164~13~23 ~165~13~23 minecraft:stone_block_slab 14
fill ~164~14~23 ~165~14~23 minecraft:concrete 0
fill ~179~10~23 ~180~10~23 minecraft:stone_block_slab 6
fill ~179~13~23 ~180~13~23 minecraft:stone_block_slab 14
fill ~179~14~23 ~180~14~23 minecraft:concrete 0
fill ~179~15~23 ~188~15~23 minecraft:stone_block_slab 6
fill ~181~8~23 ~181~8~24 minecraft:stone_block_slab 14
fill ~181~9~23 ~181~9~24 minecraft:concrete 0
fill ~181~10~23 ~181~14~23 minecraft:concrete 7
fill ~182~10~23 ~188~10~23 minecraft:concrete 0
setblock ~182~11~23 minecraft:stone_block_slab 5
setblock ~182~14~23 minecraft:double_stone_block_slab 5
fill ~183~14~23 ~188~14~23 minecraft:stone_block_slab 14
setblock ~187~11~23 minecraft:quartz_stairs 5
setblock ~188~11~23 minecraft:stone_block_slab 14
fill ~154~14~24 ~160~14~24 minecraft:stone_block_slab 14
fill ~154~15~24 ~163~15~24 minecraft:stone_block_slab 6
fill ~157~10~24 ~161~10~26 minecraft:concrete 0
setblock ~157~11~24 minecraft:stone_block_slab 14
setblock ~161~11~24 minecraft:stone_block_slab 5
setblock ~161~14~24 minecraft:double_stone_block_slab 5
fill ~162~9~24 ~162~9~25 minecraft:concrete 0
fill ~162~10~24 ~162~14~24 minecraft:concrete 7
setblock ~163~10~24 minecraft:stone_block_slab 6
setblock ~163~13~24 minecraft:stone_block_slab 14
setblock ~163~14~24 minecraft:concrete 0
setblock ~181~10~24 minecraft:stone_block_slab 6
setblock ~181~13~24 minecraft:stone_block_slab 14
setblock ~181~14~24 minecraft:concrete 0
fill ~181~15~24 ~190~15~24 minecraft:stone_block_slab 6
fill ~182~9~24 ~182~9~25 minecraft:concrete 0
fill ~182~10~24 ~182~14~24 minecraft:concrete 7
fill ~183~10~24 ~190~10~26 minecraft:concrete 0
setblock ~183~11~24 minecraft:stone_block_slab 5
setblock ~183~14~24 minecraft:double_stone_block_slab 5
fill ~184~14~24 ~190~14~24 minecraft:stone_block_slab 14
setblock ~189~11~24 minecraft:stone_block_slab 14
setblock ~190~11~24 minecraft:quartz_stairs 5
fill ~150~15~25 ~162~15~25 minecraft:concrete 0
fill ~156~10~25 ~156~10~30 minecraft:concrete 0
setblock ~156~11~25 minecraft:quartz_stairs 4
fill ~156~13~25 ~157~14~25 minecraft:concrete 7
fill ~157~11~25 ~158~12~25 minecraft:concrete 7
setblock ~160~11~25 minecraft:stone_block_slab 5
setblock ~160~14~25 minecraft:stone_block_slab 13
fill ~161~9~25 ~161~9~26 minecraft:concrete 0
fill ~161~11~25 ~161~14~25 minecraft:concrete 7
setblock ~162~10~25 minecraft:concrete 0
setblock ~162~14~25 minecraft:concrete 0
setblock ~182~10~25 minecraft:concrete 0
fill ~182~14~25 ~182~15~25 minecraft:concrete 0
fill ~183~9~25 ~183~9~26 minecraft:concrete 0
fill ~183~11~25 ~183~14~25 minecraft:concrete 7
fill ~183~15~25 ~192~15~26 minecraft:concrete 0
fill ~184~5~25 ~184~6~25 minecraft:quartz_block 0
setblock ~184~11~25 minecraft:stone_block_slab 5
setblock ~184~14~25 minecraft:stone_block_slab 13
fill ~185~5~25 ~197~6~25 minecraft:concrete 0
fill ~191~10~25 ~192~10~30 minecraft:concrete 0
fill ~191~11~25 ~192~11~25 minecraft:stone_block_slab 14
fill ~145~15~26 ~161~15~26 minecraft:concrete 0
fill ~155~10~26 ~155~10~28 minecraft:concrete 0
setblock ~156~13~26 minecraft:stone_block_slab 8
setblock ~156~14~26 minecraft:stone_block_slab 0
setblock ~157~11~26 minecraft:stone_block_slab 8
setblock ~157~12~26 minecraft:stone_block_slab 0
fill ~157~13~26 ~157~14~26 minecraft:concrete 15
fill ~158~11~26 ~158~12~26 minecraft:concrete 15
fill ~158~13~26 ~160~14~26 minecraft:stained_hardened_clay 9
fill ~159~11~26 ~160~12~26 minecraft:stained_hardened_clay 9
setblock ~160~9~26 minecraft:concrete 0
setblock ~161~11~26 minecraft:stone_brick_stairs 1
setblock ~161~13~26 minecraft:stone_brick_stairs 5
setblock ~161~14~26 minecraft:concrete 0
setblock ~183~14~26 minecraft:concrete 0
fill ~184~7~26 ~184~8~26 minecraft:quartz_block 0
fill ~184~9~26 ~184~9~27 minecraft:concrete 0
fill ~184~11~26 ~184~14~26 minecraft:concrete 7
setblock ~185~5~26 minecraft:quartz_block 0
fill ~185~7~26 ~197~8~26 minecraft:concrete 0
setblock ~185~11~26 minecraft:stone_block_slab 5
setblock ~185~14~26 minecraft:stone_block_slab 13
fill ~186~5~26 ~197~5~26 minecraft:concrete 0
fill ~189~6~26 ~189~6~35 minecraft:stone_block_slab 8
fill ~190~6~26 ~190~6~35 minecraft:concrete 15
fill ~191~6~26 ~195~6~35 minecraft:stained_hardened_clay 9
fill ~193~10~26 ~194~10~30 minecraft:concrete 0
setblock ~193~11~26 minecraft:quartz_stairs 5
fill ~193~15~26 ~194~15~26 minecraft:concrete 0
setblock ~194~11~26 minecraft:stone_block_slab 14
fill ~139~15~27 ~140~15~28 minecraft:stone_block_slab 14
fill ~139~16~27 ~140~16~28 minecraft:stone_block_slab 6
fill ~141~15~27 ~141~15~28 minecraft:stone_block_slab 8
fill ~141~16~27 ~141~16~28 minecraft:stone_block_slab 0
fill ~142~15~27 ~154~15~27 minecraft:stone_block_slab 14
fill ~142~16~27 ~160~16~27 minecraft:stone_block_slab 6
fill ~154~10~27 ~154~10~28 minecraft:concrete 0
setblock ~155~13~27 minecraft:stone_block_slab 8
setblock ~155~14~27 minecraft:stone_block_slab 0
setblock ~155~15~27 minecraft:concrete 15
setblock ~156~11~27 minecraft:stone_block_slab 8
setblock ~156~12~27 minecraft:stone_block_slab 0
fill ~156~13~27 ~156~14~27 minecraft:concrete 15
fill ~156~15~27 ~160~15~27 minecraft:concrete 0
fill ~157~10~27 ~160~10~27 minecraft:concrete 0
fill ~157~11~27 ~157~12~27 minecraft:concrete 15
fill ~157~13~27 ~157~14~27 minecraft:stained_hardened_clay 9
fill ~158~11~27 ~158~14~27 minecraft:sea_lantern
fill ~159~9~27 ~160~9~27 minecraft:stone_block_slab 14
fill ~159~11~27 ~159~14~27 minecraft:stained_glass 3
setblock ~160~11~27 minecraft:stone_block_slab 6
setblock ~160~14~27 minecraft:stone_block_slab 14
fill ~184~10~27 ~190~10~27 minecraft:concrete 0
setblock ~184~11~27 minecraft:stone_block_slab 6
setblock ~184~14~27 minecraft:stone_block_slab 14
setblock ~184~15~27 minecraft:concrete 0
fill ~184~16~27 ~195~16~27 minecraft:stone_block_slab 6
setblock ~185~4~27 minecraft:quartz_block 0
fill ~185~9~27 ~197~9~27 minecraft:concrete 0
fill ~185~11~27 ~185~15~27 minecraft:concrete 7
fill ~186~4~27 ~197~4~27 minecraft:concrete 0
setblock ~186~11~27 minecraft:stone_block_slab 5
setblock ~186~15~27 minecraft:double_stone_block_slab 5
fill ~187~15~27 ~195~15~27 minecraft:stone_block_slab 14
fill ~189~5~27 ~189~5~35 minecraft:stone_block_slab 0
fill ~189~7~27 ~189~7~36 minecraft:stone_block_slab 0
fill ~189~8~27 ~189~8~36 minecraft:stone_block_slab 8
fill ~190~5~27 ~190~5~35 minecraft:concrete 15
fill ~190~7~27 ~190~8~36 minecraft:concrete 15
fill ~191~5~27 ~195~5~35 minecraft:stained_hardened_clay 9
fill ~191~7~27 ~195~8~36 minecraft:stained_hardened_clay 9
fill ~195~10~27 ~197~10~27 minecraft:concrete 0
setblock ~195~11~27 minecraft:stone_block_slab 14
setblock ~196~11~27 minecraft:quartz_stairs 5
setblock ~197~6~27 minecraft:cobblestone_wall 0
fill ~198~6~27 ~201~6~27 minecraft:observer 5
setblock ~202~6~27 minecraft:cobblestone_wall 0
fill ~132~15~28 ~138~15~28 minecraft:stone_block_slab 14
fill ~132~16~28 ~138~16~28 minecraft:stone_block_slab 6
fill ~142~15~28 ~153~15~28 minecraft:stone_block_slab 14
fill ~142~16~28 ~159~16~28 minecraft:stone_block_slab 6
fill ~151~9~28 ~153~10~30 minecraft:concrete 7
setblock ~154~13~28 minecraft:stone_block_slab 8
setblock ~154~14~28 minecraft:stone_block_slab 0
setblock ~154~15~28 minecraft:concrete 15
setblock ~155~11~28 minecraft:stone_block_slab 8
setblock ~155~12~28 minecraft:stone_block_slab 0
fill ~155~13~28 ~155~14~28 minecraft:concrete 15
fill ~155~15~28 ~159~15~29 minecraft:concrete 0
fill ~156~11~28 ~156~12~28 minecraft:concrete 15
fill ~156~13~28 ~156~14~29 minecraft:stained_hardened_clay 9
fill ~157~10~28 ~159~10~29 minecraft:concrete 0
fill ~157~11~28 ~157~14~28 minecraft:sea_lantern
fill ~158~9~28 ~159~9~28 minecraft:stone_block_slab 14
fill ~158~11~28 ~158~14~28 minecraft:stained_glass 3
setblock ~159~11~28 minecraft:stone_block_slab 6
setblock ~159~14~28 minecraft:stone_block_slab 14
setblock ~185~9~28 minecraft:stone_block_slab 14
fill ~185~10~28 ~190~10~29 minecraft:concrete 0
setblock ~185~11~28 minecraft:stone_block_slab 6
setblock ~185~14~28 minecraft:stone_block_slab 14
fill ~185~15~28 ~185~15~29 minecraft:concrete 0
fill ~185~16~28 ~195~16~28 minecraft:stone_block_slab 6
setblock ~186~4~28 minecraft:quartz_block 0
fill ~186~11~28 ~186~15~29 minecraft:concrete 7
fill ~187~4~28 ~197~4~28 minecraft:concrete 0
fill ~187~11~28 ~187~11~29 minecraft:stone_block_slab 5
setblock ~187~15~28 minecraft:double_stone_block_slab 5
fill ~188~15~28 ~195~15~28 minecraft:stone_block_slab 14
fill ~189~9~28 ~189~9~37 minecraft:stone_block_slab 0
fill ~190~9~28 ~190~9~37 minecraft:concrete 15
fill ~191~9~28 ~195~9~37 minecraft:stained_hardened_clay 9
fill ~195~10~28 ~196~10~28 minecraft:concrete 0
fill ~196~6~28 ~197~6~29 minecraft:concrete 7
fill ~196~7~28 ~197~7~28 minecraft:concrete 7
setblock ~197~8~28 minecraft:cobblestone_wall 0
fill ~198~8~28 ~201~8~28 minecraft:observer 5
fill ~201~6~28 ~203~6~29 minecraft:concrete 7
fill ~201~7~28 ~203~7~28 minecraft:concrete 7
setblock ~202~8~28 minecraft:cobblestone_wall 0
fill ~125~15~29 ~126~15~29 minecraft:observer 5
fill ~127~15~29 ~131~15~29 minecraft:cobblestone_wall 0
fill ~132~13~29 ~132~13~30 minecraft:stone_block_slab 6
setblock ~132~15~29 minecraft:cobblestone_wall 0
fill ~132~16~29 ~140~16~29 minecraft:concrete 0
fill ~133~13~29 ~134~13~32 minecraft:concrete 7
fill ~133~14~29 ~135~15~29 minecraft:concrete 7
fill ~139~13~29 ~140~13~32 minecraft:concrete 7
fill ~139~14~29 ~140~15~29 minecraft:concrete 7
fill ~141~16~29 ~141~16~30 minecraft:clay
fill ~142~16~29 ~159~16~29 minecraft:concrete 0
fill ~144~13~29 ~145~13~32 minecraft:concrete 7
fill ~144~14~29 ~145~15~29 minecraft:concrete 7
fill ~149~13~29 ~150~13~32 minecraft:concrete 7
fill ~149~14~29 ~150~15~29 minecraft:concrete 7
fill ~150~9~29 ~150~10~29 minecraft:concrete 7
setblock ~153~15~29 minecraft:concrete 7
fill ~154~9~29 ~156~9~29 minecraft:concrete 7
fill ~154~10~29 ~155~10~29 minecraft:concrete 7
fill ~154~13~29 ~154~13~36 minecraft:concrete 7
setblock ~154~14~29 minecraft:concrete 7
setblock ~154~15~29 minecraft:concrete 0
fill ~155~11~29 ~156~12~29 minecraft:concrete 7
fill ~155~13~29 ~155~14~29 minecraft:stained_hardened_clay 9
fill ~157~11~29 ~159~11~29 minecraft:concrete 0
fill ~157~12~29 ~157~14~29 minecraft:sea_lantern
fill ~158~12~29 ~158~14~29 minecraft:stained_glass 3
setblock ~185~11~29 minecraft:concrete 0
fill ~185~16~29 ~196~16~29 minecraft:concrete 0
setblock ~186~3~29 minecraft:quartz_block 0
fill ~187~3~29 ~197~3~29 minecraft:concrete 0
setblock ~187~15~29 minecraft:stone_block_slab 13
fill ~189~4~29 ~189~4~34 minecraft:stone_block_slab 8
fill ~191~4~29 ~195~4~34 minecraft:stained_hardened_clay 9
fill ~195~10~29 ~195~10~30 minecraft:concrete 0
fill ~196~7~29 ~197~7~36 minecraft:stained_hardened_clay 9
fill ~196~8~29 ~197~9~29 minecraft:concrete 7
setblock ~197~10~29 minecraft:cobblestone_wall 0
fill ~198~7~29 ~200~7~29 minecraft:concrete 8
fill ~198~10~29 ~201~10~29 minecraft:observer 5
fill ~201~7~29 ~201~7~36 minecraft:sea_lantern
fill ~201~8~29 ~203~9~29 minecraft:concrete 7
fill ~202~7~29 ~202~7~36 minecraft:stained_glass 3
setblock ~202~10~29 minecraft:cobblestone_wall 0
fill ~120~14~30 ~121~14~30 minecraft:observer 5
fill ~122~14~30 ~132~14~30 minecraft:cobblestone_wall 0
fill ~132~16~30 ~140~16~30 minecraft:clay
fill ~133~14~30 ~133~15~32 minecraft:concrete 7
fill ~134~14~30 ~135~15~31 minecraft:stained_hardened_clay 9
fill ~135~13~30 ~135~13~31 minecraft:concrete 7
fill ~136~14~30 ~153~15~31 minecraft:concrete 8
fill ~142~16~30 ~148~16~30 minecraft:clay
fill ~149~16~30 ~158~16~30 minecraft:concrete 0
fill ~154~10~30 ~155~10~30 minecraft:concrete 0
fill ~154~14~30 ~155~14~31 minecraft:stained_hardened_clay 9
fill ~154~15~30 ~156~15~30 minecraft:concrete 8
fill ~155~11~30 ~155~13~32 minecraft:concrete 7
fill ~156~11~30 ~156~11~31 minecraft:stained_hardened_clay 9
fill ~156~12~30 ~156~14~32 minecraft:sea_lantern
fill ~157~10~30 ~158~11~30 minecraft:concrete 0
fill ~157~12~30 ~157~14~32 minecraft:stained_glass 3
fill ~157~15~30 ~158~15~30 minecraft:concrete 0
fill ~186~10~30 ~190~10~30 minecraft:concrete 0
fill ~186~11~30 ~186~11~32 minecraft:concrete 0
fill ~186~15~30 ~186~16~30 minecraft:concrete 0
setblock ~187~3~30 minecraft:quartz_block 0
fill ~187~11~30 ~187~15~32 minecraft:concrete 7
fill ~187~16~30 ~196~16~30 minecraft:concrete 0
fill ~188~3~30 ~197~3~30 minecraft:concrete 0
setblock ~188~11~30 minecraft:stone_block_slab 5
setblock ~188~15~30 minecraft:stone_block_slab 13
fill ~196~5~30 ~197~5~31 minecraft:concrete 7
fill ~196~6~30 ~197~6~35 minecraft:stained_hardened_clay 9
fill ~196~8~30 ~197~9~36 minecraft:stained_hardened_clay 9
fill ~196~10~30 ~197~11~30 minecraft:concrete 7
setblock ~197~12~30 minecraft:cobblestone_wall 0
fill ~198~6~30 ~200~6~31 minecraft:concrete 8
fill ~198~7~30 ~200~7~35 minecraft:stained_hardened_clay 9
fill ~198~8~30 ~200~9~30 minecraft:concrete 8
fill ~198~12~30 ~201~12~30 minecraft:observer 5
fill ~201~5~30 ~203~5~31 minecraft:concrete 7
fill ~201~6~30 ~201~6~35 minecraft:sea_lantern
fill ~201~8~30 ~201~9~36 minecraft:sea_lantern
fill ~201~10~30 ~203~11~30 minecraft:concrete 7
fill ~202~6~30 ~202~6~35 minecraft:stained_glass 3
fill ~202~8~30 ~202~9~36 minecraft:stained_glass 3
setblock ~202~12~30 minecraft:cobblestone_wall 0
fill ~115~15~31 ~116~15~31 minecraft:observer 5
fill ~117~15~31 ~132~15~31 minecraft:cobblestone_wall 0
fill ~132~13~31 ~132~13~32 minecraft:concrete 0
fill ~132~16~31 ~132~16~32 minecraft:stone_block_slab 14
fill ~132~17~31 ~140~17~32 minecraft:stone_block_slab 6
fill ~133~12~31 ~133~12~32 minecraft:stone_brick_stairs 4
fill ~133~16~31 ~133~16~32 minecraft:concrete 7
fill ~134~11~31 ~134~11~32 minecraft:stone_brick_stairs 4
fill ~134~12~31 ~135~12~32 minecraft:stone 5
setblock ~134~16~31 minecraft:stained_hardened_clay 9
fill ~135~11~31 ~135~11~32 minecraft:stone 5
fill ~135~16~31 ~135~16~32 minecraft:concrete 7
fill ~136~11~31 ~153~11~31 minecraft:stone_brick_stairs 6
fill ~136~12~31 ~153~12~31 minecraft:stone_brick_stairs 2
fill ~136~16~31 ~138~16~32 minecraft:stone_block_slab 14
setblock ~137~13~31 minecraft:cobblestone_wall 0
fill ~139~16~31 ~140~16~32 minecraft:concrete 7
fill ~141~16~31 ~141~16~32 minecraft:stone_block_slab 8
fill ~141~17~31 ~141~17~32 minecraft:stone_block_slab 0
setblock ~142~13~31 minecraft:cobblestone_wall 0
fill ~142~16~31 ~143~16~32 minecraft:stone_block_slab 14
fill ~142~17~31 ~148~17~32 minecraft:stone_block_slab 6
fill ~144~16~31 ~145~16~32 minecraft:concrete 7
fill ~146~16~31 ~148~16~32 minecraft:stone_block_slab 14
setblock ~147~13~31 minecraft:cobblestone_wall 0
fill ~149~16~31 ~150~16~32 minecraft:concrete 7
setblock ~149~17~31 minecraft:stone_block_slab 0
fill ~150~17~31 ~158~17~31 minecraft:stone_block_slab 6
fill ~151~16~31 ~152~16~32 minecraft:stone_block_slab 14
setblock ~152~13~31 minecraft:cobblestone_wall 0
fill ~153~10~31 ~158~10~32 minecraft:stone_block_slab 14
fill ~153~16~31 ~153~16~36 minecraft:concrete 7
fill ~154~11~31 ~154~12~32 minecraft:stone 5
fill ~154~15~31 ~155~15~31 minecraft:concrete 8
fill ~154~16~31 ~156~16~31 minecraft:stained_hardened_clay 9
fill ~156~15~31 ~156~15~32 minecraft:sea_lantern
fill ~157~11~31 ~158~11~32 minecraft:concrete 0
fill ~157~15~31 ~157~15~32 minecraft:stained_glass 3
fill ~157~16~31 ~158~16~32 minecraft:concrete 0
fill ~158~12~31 ~158~12~32 minecraft:stone_block_slab 6
fill ~158~15~31 ~158~15~32 minecraft:stone_block_slab 14
fill ~186~10~31 ~188~10~32 minecraft:stone_block_slab 14
fill ~186~12~31 ~186~12~32 minecraft:stone_block_slab 6
fill ~186~15~31 ~186~15~32 minecraft:stone_block_slab 14
fill ~186~16~31 ~186~16~32 minecraft:concrete 0
fill ~186~17~31 ~190~17~32 minecraft:stone_block_slab 6
fill ~187~2~31 ~187~2~32 minecraft:quartz_block 0
fill ~187~16~31 ~187~16~32 minecraft:concrete 7
fill ~188~2~31 ~197~2~32 minecraft:concrete 0
fill ~188~11~31 ~195~11~31 minecraft:concrete 8
fill ~188~16~31 ~188~16~32 minecraft:double_stone_block_slab 5
fill ~189~3~31 ~189~3~34 minecraft:stone_block_slab 0
fill ~189~10~31 ~189~10~37 minecraft:stone_block_slab 8
fill ~189~16~31 ~197~16~31 minecraft:stone_block_slab 14
fill ~190~10~31 ~190~10~37 minecraft:concrete 15
fill ~191~3~31 ~195~3~34 minecraft:stained_hardened_clay 9
fill ~191~10~31 ~197~10~37 minecraft:stained_hardened_clay 9
fill ~191~17~31 ~195~18~31 minecraft:concrete 0
fill ~196~11~31 ~197~11~38 minecraft:stained_hardened_clay 9
fill ~196~12~31 ~197~13~31 minecraft:concrete 7
fill ~196~17~31 ~196~18~31 minecraft:clay
setblock ~197~14~31 minecraft:cobblestone_wall 0
fill ~197~17~31 ~197~18~31 minecraft:concrete 0
fill ~198~8~31 ~200~9~35 minecraft:stained_hardened_clay 9
fill ~198~10~31 ~200~11~31 minecraft:concrete 8
fill ~198~14~31 ~201~14~31 minecraft:observer 5
fill ~201~10~31 ~201~11~37 minecraft:sea_lantern
fill ~201~12~31 ~203~13~31 minecraft:concrete 7
fill ~202~10~31 ~202~11~37 minecraft:stained_glass 3
setblock ~202~14~31 minecraft:cobblestone_wall 0
fill ~110~14~32 ~111~14~32 minecraft:observer 5
fill ~112~14~32 ~132~14~32 minecraft:cobblestone_wall 0
fill ~134~14~32 ~135~15~32 minecraft:concrete 7
setblock ~134~16~32 minecraft:concrete 7
fill ~136~11~32 ~153~11~32 minecraft:stone_brick_stairs 7
fill ~136~12~32 ~153~12~32 minecraft:stone_brick_stairs 3
fill ~137~13~32 ~137~14~32 minecraft:cobblestone_wall 0
fill ~139~14~32 ~140~15~32 minecraft:concrete 7
fill ~142~13~32 ~142~14~32 minecraft:cobblestone_wall 0
fill ~144~14~32 ~145~15~32 minecraft:concrete 7
fill ~147~13~32 ~147~14~32 minecraft:cobblestone_wall 0
fill ~149~14~32 ~150~15~32 minecraft:concrete 7
setblock ~149~17~32 minecraft:stone_block_slab 6
setblock ~150~17~32 minecraft:stone_block_slab 0
fill ~151~17~32 ~158~17~32 minecraft:stone_block_slab 6
fill ~152~13~32 ~152~14~32 minecraft:cobblestone_wall 0
fill ~153~15~32 ~155~15~32 minecraft:concrete 7
fill ~154~14~32 ~155~14~32 minecraft:concrete 7
setblock ~154~16~32 minecraft:concrete 7
fill ~155~16~32 ~156~16~32 minecraft:stained_hardened_clay 9
fill ~156~11~32 ~156~11~34 minecraft:concrete 0
fill ~188~11~32 ~195~11~32 minecraft:stained_hardened_clay 9
fill ~188~12~32 ~195~13~32 minecraft:concrete 8
fill ~189~16~32 ~196~16~32 minecraft:stone_block_slab 14
setblock ~191~17~32 minecraft:stone_block_slab 6
fill ~191~19~32 ~195~20~32 minecraft:concrete 0
fill ~192~17~32 ~192~18~32 minecraft:stained_hardened_clay 9
fill ~193~17~32 ~194~17~34 minecraft:concrete 0
fill ~193~18~32 ~195~18~44 minecraft:stained_hardened_clay 9
setblock ~195~17~32 minecraft:stained_hardened_clay 9
fill ~196~4~32 ~197~4~33 minecraft:concrete 7
fill ~196~5~32 ~197~5~35 minecraft:stained_hardened_clay 9
fill ~196~12~32 ~197~13~38 minecraft:stained_hardened_clay 9
fill ~196~14~32 ~197~15~32 minecraft:concrete 7
fill ~196~17~32 ~196~18~32 minecraft:concrete 14
fill ~196~19~32 ~196~20~32 minecraft:clay
setblock ~197~16~32 minecraft:cobblestone_wall 0
fill ~197~19~32 ~197~20~32 minecraft:concrete 0
fill ~198~5~32 ~200~5~33 minecraft:concrete 8
fill ~198~6~32 ~200~6~34 minecraft:stained_hardened_clay 9
fill ~198~10~32 ~200~11~36 minecraft:stained_hardened_clay 9
fill ~198~12~32 ~200~13~32 minecraft:concrete 8
fill ~198~16~32 ~201~16~32 minecraft:observer 5
fill ~201~4~32 ~203~4~33 minecraft:concrete 7
fill ~201~5~32 ~201~5~35 minecraft:sea_lantern
fill ~201~12~32 ~201~13~38 minecraft:sea_lantern
fill ~201~14~32 ~203~15~32 minecraft:concrete 7
fill ~202~5~32 ~202~5~35 minecraft:stained_glass 3
fill ~202~12~32 ~202~13~38 minecraft:stained_glass 3
setblock ~202~16~32 minecraft:cobblestone_wall 0
fill ~132~17~33 ~140~17~33 minecraft:concrete 0
fill ~141~17~33 ~141~17~34 minecraft:clay
fill ~142~17~33 ~150~17~34 minecraft:concrete 0
setblock ~151~17~33 minecraft:clay
fill ~152~17~33 ~157~17~33 minecraft:concrete 0
fill ~153~11~33 ~155~11~34 minecraft:concrete 0
fill ~153~15~33 ~153~15~36 minecraft:concrete 7
fill ~154~14~33 ~154~14~36 minecraft:concrete 7
fill ~154~15~33 ~154~16~35 minecraft:stained_hardened_clay 9
fill ~155~12~33 ~155~12~50 minecraft:concrete 7
fill ~155~13~33 ~155~15~36 minecraft:sea_lantern
fill ~155~16~33 ~155~16~34 minecraft:stained_hardened_clay 9
fill ~156~12~33 ~157~12~36 minecraft:concrete 0
fill ~156~13~33 ~156~15~36 minecraft:stained_glass 3
fill ~156~16~33 ~157~16~34 minecraft:concrete 0
fill ~157~11~33 ~157~11~34 minecraft:concrete 0
fill ~184~13~33 ~195~13~34 minecraft:stained_hardened_clay 9
fill ~184~14~33 ~187~15~33 minecraft:stained_hardened_clay 9
fill ~187~11~33 ~190~11~34 minecraft:concrete 0
fill ~187~12~33 ~187~12~39 minecraft:concrete 0
fill ~187~16~33 ~187~17~34 minecraft:concrete 0
fill ~188~1~33 ~188~1~34 minecraft:quartz_block 0
fill ~188~12~33 ~195~12~41 minecraft:stained_hardened_clay 9
fill ~188~14~33 ~195~15~33 minecraft:concrete 8
setblock ~188~16~33 minecraft:stone_block_slab 13
fill ~188~17~33 ~192~17~34 minecraft:concrete 0
fill ~189~1~33 ~197~1~34 minecraft:concrete 0
setblock ~189~2~33 minecraft:stone_block_slab 8
fill ~191~2~33 ~195~2~33 minecraft:stained_hardened_clay 9
fill ~191~11~33 ~195~11~37 minecraft:stained_hardened_clay 9
fill ~191~21~33 ~195~22~33 minecraft:concrete 0
fill ~192~18~33 ~192~19~44 minecraft:stained_hardened_clay 9
fill ~192~20~33 ~195~20~42 minecraft:stained_hardened_clay 9
fill ~193~19~33 ~195~19~44 minecraft:stained_hardened_clay 9
fill ~195~17~33 ~195~17~34 minecraft:concrete 0
fill ~196~14~33 ~197~14~38 minecraft:stained_hardened_clay 9
fill ~196~15~33 ~197~15~36 minecraft:stained_hardened_clay 9
fill ~196~16~33 ~197~17~33 minecraft:concrete 7
fill ~196~18~33 ~196~18~44 minecraft:concrete 14
fill ~196~20~33 ~196~20~42 minecraft:concrete 14
fill ~196~21~33 ~196~22~33 minecraft:clay
fill ~197~21~33 ~197~22~33 minecraft:concrete 0
fill ~198~12~33 ~200~13~37 minecraft:stained_hardened_clay 9
fill ~198~14~33 ~200~15~33 minecraft:concrete 8
fill ~201~14~33 ~201~14~38 minecraft:sea_lantern
fill ~201~15~33 ~201~15~36 minecraft:sea_lantern
fill ~201~16~33 ~203~17~33 minecraft:concrete 7
fill ~202~14~33 ~202~14~38 minecraft:stained_glass 3
fill ~202~15~33 ~202~15~36 minecraft:stained_glass 3
fill ~136~17~34 ~140~17~34 minecraft:concrete 0
setblock ~151~17~34 minecraft:concrete 0
setblock ~152~17~34 minecraft:clay
fill ~153~17~34 ~157~17~34 minecraft:concrete 0
fill ~184~15~34 ~195~15~34 minecraft:stained_hardened_clay 9
fill ~186~14~34 ~186~14~36 minecraft:concrete 15
fill ~187~14~34 ~195~14~38 minecraft:stained_hardened_clay 9
setblock ~188~2~34 minecraft:quartz_block 0
fill ~188~16~34 ~195~16~34 minecraft:concrete 8
fill ~189~2~34 ~194~2~34 minecraft:concrete 0
fill ~191~23~34 ~195~24~34 minecraft:concrete 0
fill ~192~21~34 ~195~21~40 minecraft:stained_hardened_clay 9
fill ~192~22~34 ~195~22~38 minecraft:stained_hardened_clay 9
fill ~195~2~34 ~195~2~36 minecraft:stained_hardened_clay 9
fill ~196~3~34 ~197~3~35 minecraft:concrete 7
fill ~196~4~34 ~197~4~34 minecraft:stained_hardened_clay 9
fill ~196~16~34 ~197~16~34 minecraft:stained_hardened_clay 9
fill ~196~17~34 ~197~17~34 minecraft:concrete 7
fill ~196~21~34 ~196~21~40 minecraft:concrete 14
fill ~196~23~34 ~196~24~34 minecraft:clay
fill ~197~23~34 ~197~24~34 minecraft:concrete 0
fill ~198~4~34 ~200~4~34 minecraft:concrete 8
fill ~198~5~34 ~200~5~34 minecraft:stained_hardened_clay 9
fill ~198~14~34 ~200~14~36 minecraft:stained_hardened_clay 9
fill ~198~15~34 ~200~15~34 minecraft:stained_hardened_clay 9
fill ~198~16~34 ~200~16~34 minecraft:concrete 8
fill ~201~3~34 ~203~3~35 minecraft:concrete 7
setblock ~201~4~34 minecraft:sea_lantern
setblock ~201~16~34 minecraft:sea_lantern
fill ~201~17~34 ~203~17~34 minecraft:concrete 7
setblock ~202~4~34 minecraft:stained_glass 3
setblock ~202~16~34 minecraft:stained_glass 3
fill ~142~17~35 ~148~17~35 minecraft:stone_block_slab 14
fill ~142~18~35 ~152~18~35 minecraft:stone_block_slab 6
fill ~152~17~35 ~152~17~38 minecraft:concrete 7
fill ~153~11~35 ~157~11~37 minecraft:stone_block_slab 14
fill ~153~12~35 ~154~12~37 minecraft:stone_block_slab 6
fill ~153~17~35 ~155~17~36 minecraft:stained_hardened_clay 9
setblock ~153~18~35 minecraft:stone_block_slab 0
fill ~154~18~35 ~157~18~35 minecraft:stone_block_slab 6
fill ~155~16~35 ~155~16~39 minecraft:sea_lantern
fill ~156~16~35 ~156~16~39 minecraft:stained_glass 3
fill ~156~17~35 ~157~17~38 minecraft:concrete 0
fill ~157~13~35 ~157~13~36 minecraft:stone_block_slab 6
fill ~157~16~35 ~157~16~36 minecraft:stone_block_slab 14
fill ~179~22~35 ~180~22~36 minecraft:stone_block_slab 13
fill ~179~23~35 ~191~23~35 minecraft:observer 5
fill ~181~22~35 ~191~22~36 minecraft:concrete 7
setblock ~181~24~35 minecraft:stone_brick_stairs 4
fill ~182~24~35 ~185~24~35 minecraft:stone_block_slab 13
fill ~184~13~35 ~186~13~36 minecraft:stone_block_slab 13
fill ~184~14~35 ~185~14~36 minecraft:stone_block_slab 5
fill ~184~15~35 ~185~15~36 minecraft:stone_block_slab 13
fill ~184~16~35 ~186~16~36 minecraft:stone_block_slab 5
fill ~186~15~35 ~186~15~38 minecraft:concrete 15
setblock ~186~24~35 minecraft:stone_brick_stairs 4
fill ~187~11~35 ~188~11~37 minecraft:stone_block_slab 14
fill ~187~13~35 ~187~13~36 minecraft:double_stone_block_slab 6
fill ~187~15~35 ~195~15~39 minecraft:stained_hardened_clay 9
fill ~187~16~35 ~187~16~36 minecraft:double_stone_block_slab 6
fill ~187~17~35 ~187~17~38 minecraft:concrete 0
fill ~187~18~35 ~191~18~36 minecraft:stone_block_slab 6
fill ~187~24~35 ~190~24~35 minecraft:stone_block_slab 13
fill ~188~3~35 ~188~4~35 minecraft:quartz_block 0
fill ~188~13~35 ~195~13~41 minecraft:stained_hardened_clay 9
fill ~188~16~35 ~195~17~43 minecraft:stained_hardened_clay 9
fill ~189~3~35 ~194~4~35 minecraft:concrete 0
fill ~189~11~35 ~189~11~37 minecraft:double_stone_block_slab 0
fill ~190~11~35 ~190~11~37 minecraft:concrete 15
fill ~191~0~35 ~191~0~36 minecraft:quartz_block 0
fill ~191~24~35 ~195~24~35 minecraft:concrete 0
fill ~192~0~35 ~197~0~36 minecraft:concrete 0
fill ~192~23~35 ~195~23~36 minecraft:stained_hardened_clay 9
fill ~193~2~35 ~193~2~36 minecraft:stone_block_slab 8
fill ~194~1~35 ~194~2~35 minecraft:concrete 15
setblock ~195~1~35 minecraft:stained_hardened_clay 9
fill ~195~3~35 ~195~4~36 minecraft:stained_hardened_clay 9
fill ~196~4~35 ~197~4~35 minecraft:concrete 7
fill ~196~16~35 ~197~16~36 minecraft:concrete 7
fill ~196~17~35 ~196~17~43 minecraft:concrete 14
fill ~196~22~35 ~199~23~36 minecraft:concrete 7
setblock ~196~24~35 minecraft:clay
setblock ~197~2~35 minecraft:cobblestone_wall 0
setblock ~197~24~35 minecraft:concrete 0
fill ~198~2~35 ~201~2~35 minecraft:observer 5
fill ~198~5~35 ~200~6~35 minecraft:concrete 8
fill ~198~15~35 ~200~15~36 minecraft:concrete 8
fill ~199~21~35 ~201~21~36 minecraft:stone_block_slab 13
fill ~199~24~35 ~201~24~36 minecraft:stone_block_slab 5
fill ~200~22~35 ~200~22~36 minecraft:stone_brick_stairs 1
fill ~200~23~35 ~200~23~36 minecraft:stone_brick_stairs 5
fill ~201~4~35 ~203~4~35 minecraft:concrete 7
fill ~201~16~35 ~203~16~36 minecraft:concrete 7
fill ~201~22~35 ~201~22~36 minecraft:stone_block_slab 5
fill ~201~23~35 ~201~23~36 minecraft:stone_block_slab 13
setblock ~202~2~35 minecraft:cobblestone_wall 0
fill ~202~22~35 ~202~22~36 minecraft:stone_brick_stairs 1
fill ~202~23~35 ~202~23~36 minecraft:stone_brick_stairs 5
fill ~203~22~35 ~203~22~36 minecraft:stone_block_slab 5
fill ~203~23~35 ~203~23~36 minecraft:stone_block_slab 13
fill ~204~22~35 ~205~22~36 minecraft:stone_block_slab 13
fill ~204~23~35 ~205~23~36 minecraft:stone_block_slab 5
fill ~146~17~36 ~148~17~36 minecraft:stone_block_slab 14
fill ~146~18~36 ~153~18~36 minecraft:stone_block_slab 6
setblock ~154~15~36 minecraft:concrete 7
setblock ~154~16~36 minecraft:stained_hardened_clay 9
setblock ~154~18~36 minecraft:stone_block_slab 0
fill ~155~18~36 ~157~18~36 minecraft:stone_block_slab 6
fill ~179~23~36 ~191~23~36 minecraft:concrete 7
fill ~188~5~36 ~188~6~36 minecraft:quartz_block 0
fill ~189~5~36 ~194~6~36 minecraft:concrete 0
setblock ~191~1~36 minecraft:quartz_block 0
fill ~191~24~36 ~195~24~36 minecraft:stone_block_slab 6
fill ~192~1~36 ~197~1~36 minecraft:concrete 0
setblock ~193~3~36 minecraft:stone_block_slab 0
fill ~193~4~36 ~193~4~37 minecraft:stone_block_slab 8
fill ~194~2~36 ~194~4~36 minecraft:concrete 15
fill ~195~5~36 ~195~6~37 minecraft:stained_hardened_clay 9
fill ~196~5~36 ~197~6~36 minecraft:concrete 7
setblock ~196~24~36 minecraft:stone_block_slab 0
setblock ~197~4~36 minecraft:cobblestone_wall 0
setblock ~197~24~36 minecraft:stone_block_slab 6
fill ~198~4~36 ~201~4~36 minecraft:observer 5
fill ~198~7~36 ~200~8~36 minecraft:concrete 8
fill ~198~9~36 ~200~9~36 minecraft:stained_hardened_clay 9
fill ~201~5~36 ~203~6~36 minecraft:concrete 7
setblock ~202~4~36 minecraft:cobblestone_wall 0
setblock ~146~17~37 minecraft:cobblestone_wall 0
fill ~147~17~37 ~148~17~37 minecraft:cobblestone_wall 0
fill ~149~16~37 ~154~16~37 minecraft:concrete 0
setblock ~149~17~37 minecraft:cobblestone_wall 0
fill ~149~18~37 ~154~18~37 minecraft:concrete 0
fill ~150~17~37 ~151~17~37 minecraft:concrete 7
fill ~152~13~37 ~155~13~45 minecraft:concrete 8
fill ~152~14~37 ~154~15~37 minecraft:concrete 8
fill ~153~17~37 ~153~17~39 minecraft:concrete 7
setblock ~154~17~37 minecraft:concrete 8
fill ~155~14~37 ~155~14~44 minecraft:sea_lantern
fill ~155~15~37 ~155~15~39 minecraft:sea_lantern
fill ~155~17~37 ~155~17~38 minecraft:concrete 7
setblock ~155~18~37 minecraft:clay
fill ~156~12~37 ~156~12~45 minecraft:concrete 7
fill ~156~13~37 ~157~13~39 minecraft:concrete 0
fill ~156~14~37 ~156~15~39 minecraft:stained_glass 3
fill ~156~18~37 ~157~18~37 minecraft:concrete 0
fill ~157~12~37 ~157~12~39 minecraft:concrete 0
fill ~184~14~37 ~186~14~38 minecraft:stained_hardened_clay 9
fill ~184~16~37 ~187~16~39 minecraft:stained_hardened_clay 9
fill ~187~13~37 ~187~13~39 minecraft:concrete 0
fill ~187~18~37 ~191~18~38 minecraft:concrete 0
fill ~188~7~37 ~188~8~37 minecraft:quartz_block 0
fill ~189~7~37 ~194~8~37 minecraft:concrete 0
fill ~191~2~37 ~191~3~37 minecraft:quartz_block 0
fill ~191~23~37 ~195~23~37 minecraft:concrete 0
fill ~192~2~37 ~197~3~37 minecraft:concrete 0
setblock ~193~5~37 minecraft:stone_block_slab 0
fill ~193~6~37 ~193~6~38 minecraft:stone_block_slab 8
fill ~194~4~37 ~194~6~37 minecraft:concrete 15
setblock ~195~4~37 minecraft:stained_hardened_clay 9
fill ~195~7~37 ~195~8~38 minecraft:stained_hardened_clay 9
fill ~196~7~37 ~197~8~37 minecraft:concrete 7
fill ~196~9~37 ~197~9~37 minecraft:stained_hardened_clay 9
fill ~196~15~37 ~197~15~38 minecraft:concrete 7
setblock ~196~23~37 minecraft:clay
setblock ~197~6~37 minecraft:cobblestone_wall 0
setblock ~197~23~37 minecraft:concrete 0
fill ~198~6~37 ~201~6~37 minecraft:observer 5
fill ~198~9~37 ~200~10~37 minecraft:concrete 8
fill ~198~11~37 ~200~11~37 minecraft:stained_hardened_clay 9
fill ~198~14~37 ~200~14~38 minecraft:concrete 8
fill ~201~7~37 ~203~8~37 minecraft:concrete 7
setblock ~201~9~37 minecraft:sea_lantern
fill ~201~15~37 ~203~15~38 minecraft:concrete 7
setblock ~202~6~37 minecraft:cobblestone_wall 0
setblock ~202~9~37 minecraft:stained_glass 3
fill ~151~16~38 ~154~16~38 minecraft:concrete 0
fill ~151~18~38 ~155~18~38 minecraft:concrete 0
fill ~152~15~38 ~154~15~45 minecraft:concrete 8
fill ~153~11~38 ~157~11~39 minecraft:concrete 0
fill ~153~14~38 ~154~14~44 minecraft:stained_glass 3
setblock ~154~17~38 minecraft:concrete 7
setblock ~156~18~38 minecraft:clay
fill ~157~18~38 ~157~18~42 minecraft:concrete 0
fill ~187~11~38 ~194~11~40 minecraft:concrete 0
fill ~188~9~38 ~188~10~38 minecraft:quartz_block 0
fill ~189~9~38 ~194~10~38 minecraft:concrete 0
fill ~191~4~38 ~191~5~38 minecraft:quartz_block 0
setblock ~191~22~38 minecraft:stone_block_slab 14
fill ~191~23~38 ~195~23~38 minecraft:stone_block_slab 6
fill ~192~4~38 ~197~5~38 minecraft:concrete 0
setblock ~193~7~38 minecraft:stone_block_slab 0
fill ~193~8~38 ~193~8~39 minecraft:stone_block_slab 8
fill ~194~6~38 ~194~8~38 minecraft:concrete 15
setblock ~195~6~38 minecraft:stained_hardened_clay 9
fill ~195~9~38 ~195~11~39 minecraft:stained_hardened_clay 9
fill ~196~9~38 ~197~10~38 minecraft:concrete 7
setblock ~196~22~38 minecraft:stone_block_slab 8
setblock ~196~23~38 minecraft:stone_block_slab 0
setblock ~197~8~38 minecraft:cobblestone_wall 0
setblock ~197~22~38 minecraft:stone_block_slab 14
setblock ~197~23~38 minecraft:stone_block_slab 6
fill ~198~8~38 ~201~8~38 minecraft:observer 5
fill ~198~11~38 ~200~12~38 minecraft:concrete 8
fill ~198~13~38 ~200~13~38 minecraft:stained_hardened_clay 9
fill ~201~9~38 ~203~10~38 minecraft:concrete 7
setblock ~201~11~38 minecraft:sea_lantern
setblock ~202~8~38 minecraft:cobblestone_wall 0
setblock ~202~11~38 minecraft:stained_glass 3
fill ~152~16~39 ~153~16~39 minecraft:stone_block_slab 14
setblock ~152~17~39 minecraft:stone_block_slab 6
setblock ~152~18~39 minecraft:stone_block_slab 14
fill ~152~19~39 ~156~19~39 minecraft:stone_block_slab 6
setblock ~153~18~39 minecraft:concrete 7
setblock ~154~16~39 minecraft:concrete 7
fill ~154~17~39 ~154~18~39 minecraft:stained_hardened_clay 9
setblock ~155~17~39 minecraft:sea_lantern
fill ~155~18~39 ~156~18~39 minecraft:concrete 0
setblock ~156~17~39 minecraft:stained_glass 3
setblock ~157~14~39 minecraft:stone_block_slab 6
setblock ~157~17~39 minecraft:stone_block_slab 14
setblock ~157~19~39 minecraft:stone_block_slab 0
fill ~184~14~39 ~186~14~39 minecraft:stone_block_slab 13
fill ~184~15~39 ~186~15~39 minecraft:stained_hardened_clay 9
fill ~184~17~39 ~186~17~39 minecraft:stone_block_slab 5
setblock ~187~14~39 minecraft:double_stone_block_slab 6
setblock ~187~17~39 minecraft:double_stone_block_slab 6
setblock ~187~18~39 minecraft:concrete 0
fill ~187~19~39 ~191~19~39 minecraft:stone_block_slab 6
fill ~188~14~39 ~195~14~42 minecraft:stained_hardened_clay 9
fill ~188~18~39 ~191~18~44 minecraft:stained_hardened_clay 9
fill ~191~6~39 ~191~7~39 minecraft:quartz_block 0
fill ~191~22~39 ~195~22~39 minecraft:concrete 0
fill ~192~6~39 ~197~7~39 minecraft:concrete 0
setblock ~193~9~39 minecraft:stone_block_slab 0
fill ~193~10~39 ~193~10~40 minecraft:stone_block_slab 8
fill ~194~8~39 ~194~10~39 minecraft:concrete 15
setblock ~195~8~39 minecraft:stained_hardened_clay 9
fill ~196~11~39 ~197~12~39 minecraft:concrete 7
fill ~196~13~39 ~197~13~39 minecraft:stained_hardened_clay 9
fill ~196~14~39 ~197~14~40 minecraft:concrete 7
setblock ~196~22~39 minecraft:clay
setblock ~197~10~39 minecraft:cobblestone_wall 0
setblock ~197~22~39 minecraft:concrete 0
fill ~198~10~39 ~201~10~39 minecraft:observer 5
fill ~198~13~39 ~200~13~39 minecraft:concrete 8
fill ~201~11~39 ~203~12~39 minecraft:concrete 7
setblock ~201~13~39 minecraft:sea_lantern
fill ~201~14~39 ~203~14~40 minecraft:concrete 7
setblock ~202~10~39 minecraft:cobblestone_wall 0
setblock ~202~13~39 minecraft:stained_glass 3
fill ~152~11~40 ~152~11~41 minecraft:stone_brick_stairs 4
setblock ~152~12~40 minecraft:cobblestone_wall 0
fill ~153~10~40 ~158~10~41 minecraft:stone_block_slab 14
setblock ~153~11~40 minecraft:stone_brick_stairs 6
setblock ~153~12~40 minecraft:stone_brick_stairs 2
fill ~153~16~40 ~154~16~40 minecraft:stone_block_slab 14
setblock ~153~17~40 minecraft:stone_block_slab 6
setblock ~153~18~40 minecraft:stone_block_slab 14
fill ~153~19~40 ~157~19~40 minecraft:stone_block_slab 6
fill ~154~11~40 ~154~12~41 minecraft:stone 5
fill ~154~17~40 ~154~18~40 minecraft:concrete 7
fill ~155~11~40 ~155~11~50 minecraft:concrete 7
fill ~155~15~40 ~155~15~45 minecraft:concrete 8
fill ~155~16~40 ~155~16~42 minecraft:concrete 7
fill ~155~17~40 ~155~18~40 minecraft:stained_hardened_clay 9
fill ~156~11~40 ~157~11~49 minecraft:stained_hardened_clay 9
fill ~156~13~40 ~156~13~45 minecraft:concrete 8
fill ~156~14~40 ~156~17~40 minecraft:sea_lantern
setblock ~156~18~40 minecraft:concrete 0
fill ~157~12~40 ~157~12~45 minecraft:concrete 7
fill ~157~13~40 ~158~13~40 minecraft:concrete 0
fill ~157~14~40 ~157~17~40 minecraft:stained_glass 3
fill ~158~11~40 ~158~12~42 minecraft:concrete 0
setblock ~158~14~40 minecraft:stone_block_slab 6
setblock ~158~17~40 minecraft:stone_block_slab 14
fill ~158~18~40 ~158~18~42 minecraft:concrete 0
setblock ~158~19~40 minecraft:stone_block_slab 0
fill ~186~10~40 ~192~10~40 minecraft:stone_block_slab 14
fill ~186~11~40 ~186~13~42 minecraft:concrete 0
setblock ~186~14~40 minecraft:stone_block_slab 6
setblock ~186~17~40 minecraft:stone_block_slab 14
fill ~186~18~40 ~186~18~42 minecraft:concrete 0
fill ~186~19~40 ~191~19~40 minecraft:stone_block_slab 0
fill ~187~12~40 ~187~13~45 minecraft:stained_hardened_clay 9
fill ~187~14~40 ~187~17~40 minecraft:concrete 7
fill ~187~18~40 ~187~18~46 minecraft:stained_hardened_clay 9
fill ~188~15~40 ~195~15~42 minecraft:stained_hardened_clay 9
fill ~191~8~40 ~191~9~40 minecraft:quartz_block 0
setblock ~191~21~40 minecraft:stone_block_slab 14
fill ~191~22~40 ~195~22~40 minecraft:stone_block_slab 6
fill ~192~5~40 ~196~5~40 minecraft:stone_block_slab 14
setblock ~192~6~40 minecraft:stone_block_slab 6
fill ~192~8~40 ~197~9~40 minecraft:concrete 0
setblock ~193~6~40 minecraft:stone_brick_stairs 3
setblock ~194~6~40 minecraft:stone_block_slab 6
setblock ~194~10~40 minecraft:concrete 15
setblock ~195~6~40 minecraft:stone_brick_stairs 3
fill ~195~10~40 ~195~11~40 minecraft:stained_hardened_clay 9
setblock ~196~6~40 minecraft:stone_block_slab 6
fill ~196~13~40 ~197~13~40 minecraft:concrete 7
setblock ~196~22~40 minecraft:stone_block_slab 0
setblock ~197~12~40 minecraft:cobblestone_wall 0
setblock ~197~21~40 minecraft:stone_block_slab 14
setblock ~197~22~40 minecraft:stone_block_slab 6
fill ~198~12~40 ~201~12~40 minecraft:observer 5
fill ~201~13~40 ~203~13~40 minecraft:concrete 7
setblock ~202~12~40 minecraft:cobblestone_wall 0
setblock ~152~12~41 minecraft:cobblestone_wall 0
setblock ~153~11~41 minecraft:stone_brick_stairs 7
setblock ~153~12~41 minecraft:stone_brick_stairs 3
fill ~154~17~41 ~155~17~42 minecraft:concrete 0
fill ~154~19~41 ~158~19~42 minecraft:concrete 0
fill ~155~18~41 ~155~18~43 minecraft:concrete 7
fill ~156~14~41 ~156~14~45 minecraft:stained_hardened_clay 9
fill ~156~15~41 ~156~18~42 minecraft:sea_lantern
fill ~157~13~41 ~157~13~45 minecraft:concrete 8
fill ~157~14~41 ~158~14~42 minecraft:concrete 0
fill ~157~15~41 ~157~17~42 minecraft:stained_glass 3
fill ~158~13~41 ~158~13~42 minecraft:concrete 0
fill ~186~10~41 ~190~10~41 minecraft:stone_block_slab 14
fill ~186~14~41 ~186~14~42 minecraft:concrete 0
fill ~186~19~41 ~191~19~42 minecraft:concrete 0
fill ~187~11~41 ~192~11~41 minecraft:concrete 0
fill ~187~14~41 ~187~14~45 minecraft:stained_hardened_clay 9
fill ~187~15~41 ~187~17~42 minecraft:concrete 7
setblock ~191~10~41 minecraft:quartz_block 0
fill ~191~21~41 ~195~21~41 minecraft:concrete 0
setblock ~192~5~41 minecraft:concrete 0
setblock ~192~10~41 minecraft:clay
setblock ~193~5~41 minecraft:clay
fill ~193~10~41 ~197~10~41 minecraft:concrete 0
setblock ~193~11~41 minecraft:clay
fill ~194~5~41 ~196~5~41 minecraft:concrete 0
fill ~194~11~41 ~197~11~41 minecraft:concrete 0
setblock ~196~21~41 minecraft:clay
setblock ~197~14~41 minecraft:cobblestone_wall 0
setblock ~197~21~41 minecraft:concrete 0
fill ~198~14~41 ~201~14~41 minecraft:observer 5
setblock ~202~14~41 minecraft:cobblestone_wall 0
fill ~152~9~42 ~153~10~44 minecraft:concrete 7
fill ~154~10~42 ~158~10~42 minecraft:concrete 0
fill ~186~10~42 ~190~10~42 minecraft:concrete 0
fill ~187~11~42 ~188~11~44 minecraft:stained_hardened_clay 9
fill ~188~12~42 ~188~13~44 minecraft:stained_hardened_clay 9
fill ~189~12~42 ~193~13~42 minecraft:concrete 0
setblock ~191~20~42 minecraft:stone_block_slab 14
fill ~191~21~42 ~195~21~42 minecraft:stone_block_slab 6
setblock ~194~12~42 minecraft:clay
setblock ~194~13~42 minecraft:concrete 0
fill ~195~12~42 ~197~12~42 minecraft:concrete 0
setblock ~195~13~42 minecraft:clay
fill ~196~13~42 ~197~13~42 minecraft:concrete 0
setblock ~196~21~42 minecraft:stone_block_slab 0
setblock ~197~20~42 minecraft:stone_block_slab 14
setblock ~197~21~42 minecraft:stone_block_slab 6
fill ~151~9~43 ~151~10~43 minecraft:concrete 7
fill ~154~9~43 ~156~9~43 minecraft:concrete 7
fill ~154~10~43 ~155~10~43 minecraft:concrete 7
fill ~154~17~43 ~155~17~45 minecraft:stone_block_slab 14
setblock ~154~18~43 minecraft:stone_block_slab 6
setblock ~154~19~43 minecraft:stone_block_slab 14
fill ~154~20~43 ~159~20~44 minecraft:stone_block_slab 6
setblock ~155~19~43 minecraft:concrete 7
setblock ~156~10~43 minecraft:concrete 8
fill ~156~15~43 ~156~15~45 minecraft:concrete 8
fill ~156~16~43 ~156~17~44 minecraft:concrete 7
fill ~156~18~43 ~156~19~52 minecraft:stained_hardened_clay 9
fill ~157~9~43 ~159~9~43 minecraft:stone_block_slab 14
fill ~157~10~43 ~158~10~49 minecraft:stained_hardened_clay 9
fill ~157~14~43 ~157~14~45 minecraft:stained_hardened_clay 9
fill ~157~15~43 ~157~18~44 minecraft:sea_lantern
fill ~157~19~43 ~157~19~52 minecraft:stained_hardened_clay 9
fill ~158~11~43 ~158~11~48 minecraft:stained_hardened_clay 9
fill ~158~12~43 ~158~12~45 minecraft:concrete 7
fill ~158~13~43 ~158~13~45 minecraft:concrete 8
fill ~158~14~43 ~159~14~44 minecraft:concrete 0
fill ~158~15~43 ~158~18~44 minecraft:stained_glass 3
fill ~158~19~43 ~159~19~44 minecraft:concrete 0
fill ~159~10~43 ~159~13~44 minecraft:concrete 0
fill ~159~15~43 ~159~15~44 minecraft:stone_block_slab 6
fill ~159~18~43 ~159~18~44 minecraft:stone_block_slab 14
fill ~185~9~43 ~189~9~43 minecraft:stone_block_slab 14
fill ~185~10~43 ~185~14~44 minecraft:concrete 0
fill ~185~15~43 ~185~15~44 minecraft:stone_block_slab 6
fill ~185~18~43 ~185~18~44 minecraft:stone_block_slab 14
fill ~185~19~43 ~185~19~44 minecraft:concrete 0
fill ~185~20~43 ~190~20~44 minecraft:stone_block_slab 6
fill ~186~10~43 ~188~10~44 minecraft:stained_hardened_clay 9
fill ~186~11~43 ~186~14~46 minecraft:stained_hardened_clay 9
fill ~186~15~43 ~186~18~44 minecraft:concrete 7
fill ~186~19~43 ~191~19~44 minecraft:stained_hardened_clay 9
fill ~187~15~43 ~188~15~44 minecraft:stained_hardened_clay 9
fill ~187~16~43 ~187~17~46 minecraft:stained_hardened_clay 9
fill ~188~14~43 ~188~14~44 minecraft:stained_hardened_clay 9
setblock ~189~10~43 minecraft:stone_block_slab 6
fill ~189~14~43 ~195~15~43 minecraft:concrete 0
fill ~191~20~43 ~195~20~43 minecraft:concrete 0
fill ~196~14~43 ~196~15~43 minecraft:clay
setblock ~196~20~43 minecraft:clay
fill ~197~14~43 ~197~15~43 minecraft:concrete 0
setblock ~197~20~43 minecraft:concrete 0
fill ~66~19~44 ~76~19~44 minecraft:concrete 0
setblock ~77~19~44 minecraft:clay
fill ~78~19~44 ~80~19~45 minecraft:concrete 0
fill ~153~17~44 ~153~17~45 minecraft:stone_block_slab 14
setblock ~153~18~44 minecraft:stone_block_slab 6
setblock ~153~19~44 minecraft:stone_block_slab 14
setblock ~153~20~44 minecraft:stone_block_slab 6
fill ~154~9~44 ~159~9~44 minecraft:concrete 0
setblock ~154~10~44 minecraft:concrete 0
fill ~154~18~44 ~154~19~44 minecraft:concrete 7
fill ~155~18~44 ~155~19~52 minecraft:stained_hardened_clay 9
fill ~156~10~44 ~156~10~50 minecraft:concrete 7
fill ~185~9~44 ~189~9~44 minecraft:concrete 0
fill ~188~16~44 ~188~17~44 minecraft:stained_hardened_clay 9
fill ~189~16~44 ~195~17~44 minecraft:concrete 0
fill ~191~20~44 ~195~20~44 minecraft:stone_block_slab 6
fill ~196~16~44 ~196~17~44 minecraft:clay
setblock ~196~19~44 minecraft:stone_block_slab 8
setblock ~196~20~44 minecraft:stone_block_slab 0
fill ~197~16~44 ~197~17~44 minecraft:concrete 0
setblock ~197~19~44 minecraft:stone_block_slab 14
setblock ~197~20~44 minecraft:stone_block_slab 6
fill ~65~19~45 ~75~19~45 minecraft:concrete 0
setblock ~76~19~45 minecraft:clay
setblock ~77~19~45 minecraft:concrete 0
setblock ~81~19~45 minecraft:concrete 0
fill ~151~18~45 ~152~18~45 minecraft:concrete 0
fill ~151~20~45 ~160~20~46 minecraft:concrete 0
fill ~152~14~45 ~155~14~45 minecraft:concrete 8
setblock ~152~19~45 minecraft:stone_block_slab 14
fill ~153~18~45 ~153~19~45 minecraft:concrete 7
fill ~154~8~45 ~159~8~45 minecraft:stone_block_slab 14
fill ~154~9~45 ~155~9~45 minecraft:stone_block_slab 6
fill ~154~18~45 ~154~19~52 minecraft:stained_hardened_clay 9
fill ~156~9~45 ~156~9~50 minecraft:concrete 7
setblock ~156~17~45 minecraft:stone_block_slab 14
fill ~157~9~45 ~159~9~49 minecraft:stained_hardened_clay 9
setblock ~157~15~45 minecraft:concrete 8
fill ~157~16~45 ~157~17~45 minecraft:concrete 7
fill ~157~18~45 ~157~18~52 minecraft:stained_hardened_clay 9
setblock ~158~14~45 minecraft:stained_hardened_clay 9
fill ~158~15~45 ~158~18~45 minecraft:sea_lantern
fill ~158~19~45 ~158~19~52 minecraft:stained_hardened_clay 9
fill ~159~10~45 ~159~11~48 minecraft:stained_hardened_clay 9
setblock ~159~12~45 minecraft:concrete 7
setblock ~159~13~45 minecraft:concrete 8
fill ~159~14~45 ~160~14~45 minecraft:concrete 0
fill ~159~15~45 ~159~18~45 minecraft:stained_glass 3
fill ~159~19~45 ~160~19~45 minecraft:concrete 0
fill ~160~9~45 ~160~13~45 minecraft:concrete 0
setblock ~160~15~45 minecraft:concrete 0
fill ~184~9~45 ~184~15~45 minecraft:concrete 0
fill ~184~19~45 ~184~20~45 minecraft:concrete 0
fill ~185~8~45 ~188~8~45 minecraft:stone_block_slab 14
fill ~185~9~45 ~187~10~46 minecraft:stained_hardened_clay 9
fill ~185~11~45 ~185~14~48 minecraft:stained_hardened_clay 9
fill ~185~15~45 ~185~18~45 minecraft:concrete 7
fill ~185~19~45 ~187~19~46 minecraft:stained_hardened_clay 9
fill ~185~20~45 ~188~20~46 minecraft:concrete 0
fill ~186~15~45 ~187~15~46 minecraft:stained_hardened_clay 9
fill ~186~16~45 ~186~18~48 minecraft:stained_hardened_clay 9
setblock ~187~11~45 minecraft:stained_hardened_clay 9
fill ~188~9~45 ~188~9~46 minecraft:concrete 8
fill ~188~10~45 ~189~10~46 minecraft:concrete 7
fill ~188~11~45 ~189~15~45 minecraft:concrete 7
fill ~188~16~45 ~188~16~46 minecraft:concrete 8
fill ~189~18~45 ~195~18~45 minecraft:concrete 0
fill ~189~19~45 ~197~19~45 minecraft:clay
setblock ~196~18~45 minecraft:clay
setblock ~197~18~45 minecraft:concrete 0
fill ~64~19~46 ~74~19~46 minecraft:stone_block_slab 14
fill ~64~20~46 ~74~20~46 minecraft:stone_block_slab 6
setblock ~75~19~46 minecraft:stone_block_slab 8
setblock ~75~20~46 minecraft:stone_block_slab 0
fill ~76~19~46 ~82~19~47 minecraft:stone_block_slab 14
fill ~76~20~46 ~82~20~47 minecraft:stone_block_slab 6
setblock ~148~20~46 minecraft:concrete 0
fill ~149~18~46 ~150~18~49 minecraft:stone_block_slab 14
fill ~149~19~46 ~150~19~46 minecraft:stone_block_slab 6
setblock ~149~20~46 minecraft:clay
setblock ~150~20~46 minecraft:concrete 0
fill ~151~18~46 ~152~19~46 minecraft:concrete 7
fill ~152~17~46 ~156~17~46 minecraft:concrete 7
fill ~153~15~46 ~157~15~46 minecraft:concrete 7
fill ~153~16~46 ~156~16~46 minecraft:concrete 7
fill ~153~18~46 ~153~19~52 minecraft:stained_hardened_clay 9
fill ~154~8~46 ~160~8~46 minecraft:concrete 0
fill ~154~13~46 ~159~13~46 minecraft:concrete 7
fill ~154~14~46 ~158~14~46 minecraft:concrete 7
fill ~156~12~46 ~160~12~46 minecraft:stained_hardened_clay 9
fill ~157~16~46 ~160~17~48 minecraft:stained_hardened_clay 9
fill ~158~15~46 ~160~15~47 minecraft:stained_hardened_clay 9
fill ~158~18~46 ~160~18~52 minecraft:stained_hardened_clay 9
fill ~159~14~46 ~160~14~46 minecraft:stained_hardened_clay 9
fill ~159~19~46 ~160~19~52 minecraft:stained_hardened_clay 9
fill ~160~9~46 ~160~9~50 minecraft:stained_hardened_clay 9
fill ~160~10~46 ~160~11~48 minecraft:stained_hardened_clay 9
fill ~160~13~46 ~160~13~52 minecraft:stained_hardened_clay 9
setblock ~161~8~46 minecraft:quartz_stairs 5
fill ~161~9~46 ~161~15~46 minecraft:concrete 0
setblock ~161~16~46 minecraft:stone_brick_stairs 1
setblock ~161~18~46 minecraft:stone_brick_stairs 5
fill ~161~19~46 ~161~20~46 minecraft:concrete 0
setblock ~183~8~46 minecraft:quartz_stairs 4
fill ~183~9~46 ~183~15~46 minecraft:concrete 0
fill ~183~19~46 ~183~20~46 minecraft:concrete 0
fill ~184~8~46 ~188~8~46 minecraft:concrete 0
fill ~184~9~46 ~184~10~52 minecraft:stained_hardened_clay 9
fill ~184~11~46 ~184~15~50 minecraft:stained_hardened_clay 9
fill ~184~16~46 ~184~18~46 minecraft:concrete 7
fill ~184~19~46 ~184~19~51 minecraft:stained_hardened_clay 9
setblock ~184~20~46 minecraft:concrete 0
fill ~185~15~46 ~185~18~50 minecraft:stained_hardened_clay 9
fill ~187~11~46 ~187~14~46 minecraft:sea_lantern
fill ~188~11~46 ~188~14~46 minecraft:stained_glass 3
fill ~188~15~46 ~189~15~46 minecraft:concrete 7
fill ~62~19~47 ~73~19~47 minecraft:stone_block_slab 14
fill ~62~20~47 ~73~20~47 minecraft:stone_block_slab 6
setblock ~74~19~47 minecraft:stone_block_slab 8
setblock ~74~20~47 minecraft:stone_block_slab 0
setblock ~75~19~47 minecraft:stone_block_slab 14
setblock ~75~20~47 minecraft:stone_block_slab 6
fill ~83~19~47 ~84~19~47 minecraft:stone_block_slab 14
fill ~83~20~47 ~84~20~47 minecraft:stone_block_slab 6
fill ~94~11~47 ~94~11~48 minecraft:quartz_stairs 4
fill ~94~12~47 ~94~12~49 minecraft:concrete 0
fill ~94~13~47 ~94~13~48 minecraft:quartz_stairs 0
fill ~144~20~47 ~146~20~47 minecraft:concrete 0
fill ~144~21~47 ~148~21~48 minecraft:stone_block_slab 6
fill ~145~19~47 ~146~19~50 minecraft:stone_block_slab 14
fill ~147~19~47 ~148~19~50 minecraft:concrete 0
setblock ~147~20~47 minecraft:stone_block_slab 14
fill ~148~20~47 ~150~20~47 minecraft:concrete 7
fill ~149~19~47 ~151~19~47 minecraft:concrete 7
fill ~149~21~47 ~149~21~48 minecraft:stone_block_slab 0
fill ~150~21~47 ~162~21~48 minecraft:stone_block_slab 6
fill ~151~18~47 ~151~18~50 minecraft:concrete 7
fill ~151~20~47 ~161~20~52 minecraft:stained_hardened_clay 9
fill ~152~17~47 ~152~17~50 minecraft:concrete 7
fill ~152~18~47 ~152~19~50 minecraft:stained_hardened_clay 9
fill ~153~7~47 ~161~7~47 minecraft:stone_block_slab 14
fill ~153~8~47 ~156~8~47 minecraft:stone_block_slab 6
fill ~153~15~47 ~153~16~50 minecraft:concrete 7
fill ~153~17~47 ~156~17~50 minecraft:stained_hardened_clay 9
fill ~154~13~47 ~154~14~50 minecraft:concrete 7
fill ~154~15~47 ~157~15~49 minecraft:stained_hardened_clay 9
fill ~154~16~47 ~156~16~50 minecraft:stained_hardened_clay 9
fill ~155~13~47 ~158~14~47 minecraft:stained_hardened_clay 9
fill ~156~12~47 ~158~12~47 minecraft:stained_hardened_clay 9
fill ~157~8~47 ~157~8~50 minecraft:concrete 7
fill ~158~8~47 ~160~8~49 minecraft:stained_hardened_clay 9
fill ~159~12~47 ~161~12~47 minecraft:concrete 7
fill ~159~13~47 ~159~14~47 minecraft:concrete 7
fill ~160~14~47 ~161~14~47 minecraft:concrete 7
setblock ~161~8~47 minecraft:concrete 0
fill ~161~9~47 ~161~9~50 minecraft:stained_hardened_clay 9
fill ~161~10~47 ~161~11~48 minecraft:stained_hardened_clay 9
setblock ~161~13~47 minecraft:concrete 7
setblock ~161~15~47 minecraft:stained_hardened_clay 9
fill ~161~16~47 ~161~19~47 minecraft:concrete 7
setblock ~162~8~47 minecraft:quartz_stairs 5
fill ~162~9~47 ~162~15~47 minecraft:concrete 0
setblock ~162~16~47 minecraft:stone_block_slab 6
setblock ~162~19~47 minecraft:stone_block_slab 14
setblock ~162~20~47 minecraft:concrete 0
setblock ~182~8~47 minecraft:quartz_stairs 4
fill ~182~9~47 ~182~15~47 minecraft:concrete 0
setblock ~182~16~47 minecraft:stone_block_slab 6
setblock ~182~19~47 minecraft:stone_block_slab 14
setblock ~182~20~47 minecraft:concrete 0
fill ~182~21~47 ~187~21~48 minecraft:stone_block_slab 6
fill ~183~7~47 ~187~7~47 minecraft:stone_block_slab 14
setblock ~183~8~47 minecraft:concrete 0
fill ~183~9~47 ~183~15~52 minecraft:stained_hardened_clay 9
fill ~183~16~47 ~183~19~47 minecraft:concrete 7
fill ~183~20~47 ~186~20~48 minecraft:stained_hardened_clay 9
fill ~184~8~47 ~186~8~48 minecraft:stained_hardened_clay 9
fill ~184~16~47 ~184~16~52 minecraft:stained_hardened_clay 9
fill ~184~17~47 ~184~18~51 minecraft:stained_hardened_clay 9
fill ~185~9~47 ~186~10~48 minecraft:stained_hardened_clay 9
fill ~185~19~47 ~186~19~48 minecraft:stained_hardened_clay 9
fill ~186~11~47 ~186~14~48 minecraft:sea_lantern
fill ~186~15~47 ~186~15~48 minecraft:stained_hardened_clay 9
setblock ~187~8~47 minecraft:stone_block_slab 6
fill ~187~9~47 ~187~9~48 minecraft:concrete 8
fill ~187~10~47 ~188~10~48 minecraft:concrete 7
fill ~187~11~47 ~187~14~48 minecraft:stained_glass 3
fill ~187~15~47 ~188~15~48 minecraft:concrete 7
fill ~187~16~47 ~187~16~48 minecraft:concrete 8
fill ~187~20~47 ~187~20~48 minecraft:stone_block_slab 14
fill ~59~20~48 ~72~20~48 minecraft:concrete 0
setblock ~73~20~48 minecraft:clay
fill ~74~20~48 ~87~20~49 minecraft:concrete 0
fill ~95~10~48 ~95~10~55 minecraft:quartz_stairs 4
setblock ~95~11~48 minecraft:quartz_stairs 1
setblock ~95~13~48 minecraft:quartz_stairs 5
fill ~95~14~48 ~95~14~53 minecraft:quartz_stairs 0
fill ~96~10~48 ~96~10~55 minecraft:concrete 0
fill ~96~14~48 ~96~14~53 minecraft:concrete 0
fill ~139~21~48 ~143~21~48 minecraft:stone_block_slab 6
fill ~141~20~48 ~142~20~50 minecraft:stone_block_slab 14
fill ~143~20~48 ~144~20~50 minecraft:concrete 0
fill ~145~20~48 ~146~20~49 minecraft:stained_hardened_clay 9
setblock ~147~20~48 minecraft:concrete 7
fill ~148~20~48 ~150~20~49 minecraft:stained_hardened_clay 9
fill ~149~19~48 ~151~19~49 minecraft:stained_hardened_clay 9
setblock ~150~9~48 minecraft:cobblestone_wall 0
fill ~151~9~48 ~155~9~48 minecraft:cobblestone_wall 0
fill ~153~7~48 ~162~7~48 minecraft:concrete 0
fill ~155~13~48 ~157~14~48 minecraft:stained_hardened_clay 9
fill ~156~12~48 ~157~12~48 minecraft:stained_hardened_clay 9
fill ~158~12~48 ~158~14~48 minecraft:concrete 0
setblock ~158~15~48 minecraft:stained_hardened_clay 9
fill ~159~12~48 ~161~12~52 minecraft:stained_hardened_clay 9
fill ~159~13~48 ~159~14~52 minecraft:stained_hardened_clay 9
fill ~159~15~48 ~161~15~48 minecraft:concrete 0
fill ~160~14~48 ~161~14~52 minecraft:stained_hardened_clay 9
fill ~161~8~48 ~161~8~50 minecraft:stained_hardened_clay 9
fill ~161~13~48 ~161~13~52 minecraft:stained_hardened_clay 9
fill ~161~16~48 ~161~19~48 minecraft:stained_hardened_clay 9
fill ~162~8~48 ~163~8~48 minecraft:concrete 0
fill ~162~9~48 ~162~10~52 minecraft:stained_hardened_clay 9
setblock ~162~11~48 minecraft:stained_hardened_clay 9
fill ~162~12~48 ~163~14~48 minecraft:concrete 0
setblock ~162~15~48 minecraft:stained_hardened_clay 9
fill ~162~16~48 ~162~19~48 minecraft:concrete 7
fill ~162~20~48 ~162~20~52 minecraft:stained_hardened_clay 9
setblock ~163~7~48 minecraft:quartz_stairs 5
fill ~163~9~48 ~163~11~48 minecraft:concrete 0
setblock ~163~15~48 minecraft:concrete 0
setblock ~163~16~48 minecraft:stone_block_slab 6
setblock ~163~19~48 minecraft:stone_block_slab 14
setblock ~163~20~48 minecraft:concrete 0
setblock ~163~21~48 minecraft:stone_block_slab 6
setblock ~181~7~48 minecraft:quartz_stairs 4
fill ~181~8~48 ~182~8~48 minecraft:concrete 0
fill ~181~9~48 ~181~15~48 minecraft:concrete 0
setblock ~181~16~48 minecraft:stone_block_slab 6
setblock ~181~19~48 minecraft:stone_block_slab 14
setblock ~181~20~48 minecraft:concrete 0
setblock ~181~21~48 minecraft:stone_block_slab 6
fill ~182~7~48 ~187~7~48 minecraft:concrete 0
fill ~182~9~48 ~182~15~52 minecraft:stained_hardened_clay 9
fill ~182~16~48 ~182~19~48 minecraft:concrete 7
fill ~182~20~48 ~182~20~52 minecraft:stained_hardened_clay 9
fill ~183~8~48 ~183~8~52 minecraft:stained_hardened_clay 9
fill ~183~16~48 ~183~19~52 minecraft:stained_hardened_clay 9
fill ~187~17~48 ~187~19~49 minecraft:concrete 7
fill ~55~20~49 ~71~20~49 minecraft:concrete 0
setblock ~72~20~49 minecraft:clay
setblock ~73~20~49 minecraft:concrete 0
fill ~88~20~49 ~91~20~49 minecraft:concrete 0
fill ~93~11~49 ~93~11~54 minecraft:stone_block_slab 13
setblock ~93~12~49 minecraft:stained_hardened_clay 9
fill ~93~13~49 ~93~13~54 minecraft:stone_block_slab 5
fill ~94~11~49 ~94~11~55 minecraft:concrete 0
fill ~94~13~49 ~94~13~68 minecraft:concrete 0
fill ~95~11~49 ~95~13~49 minecraft:concrete 7
fill ~97~9~49 ~97~9~55 minecraft:stone_block_slab 14
setblock ~97~10~49 minecraft:stone_block_slab 6
setblock ~97~14~49 minecraft:stone_block_slab 14
fill ~97~15~49 ~97~15~53 minecraft:stone_block_slab 6
fill ~98~9~49 ~98~9~55 minecraft:concrete 0
fill ~98~15~49 ~98~15~53 minecraft:concrete 0
fill ~117~17~49 ~117~19~53 minecraft:concrete 0
fill ~118~15~49 ~118~16~67 minecraft:concrete 0
fill ~118~20~49 ~118~20~54 minecraft:concrete 0
fill ~118~21~49 ~118~21~52 minecraft:concrete 0
fill ~119~14~49 ~119~14~54 minecraft:concrete 0
fill ~119~22~49 ~119~22~52 minecraft:concrete 0
fill ~120~13~49 ~120~13~54 minecraft:concrete 0
fill ~120~17~49 ~121~19~51 minecraft:concrete 8
fill ~120~23~49 ~120~23~52 minecraft:concrete 0
fill ~121~12~49 ~122~12~54 minecraft:concrete 0
fill ~121~15~49 ~127~16~49 minecraft:concrete 8
fill ~121~20~49 ~127~20~50 minecraft:concrete 8
fill ~121~21~49 ~127~21~49 minecraft:concrete 8
fill ~121~24~49 ~122~24~52 minecraft:concrete 0
fill ~123~11~49 ~125~11~54 minecraft:concrete 0
fill ~123~14~49 ~125~14~50 minecraft:concrete 8
fill ~123~22~49 ~125~22~50 minecraft:concrete 8
fill ~123~25~49 ~125~25~52 minecraft:concrete 0
fill ~126~12~49 ~127~12~53 minecraft:concrete 0
fill ~126~24~49 ~127~24~57 minecraft:concrete 0
fill ~127~17~49 ~128~19~51 minecraft:concrete 8
fill ~128~13~49 ~128~13~52 minecraft:concrete 0
fill ~128~23~49 ~128~23~57 minecraft:concrete 0
fill ~129~14~49 ~129~14~53 minecraft:concrete 0
fill ~129~22~49 ~129~22~57 minecraft:concrete 0
fill ~130~15~49 ~130~16~53 minecraft:concrete 0
fill ~130~20~49 ~130~21~57 minecraft:concrete 0
fill ~131~17~49 ~131~19~54 minecraft:concrete 0
fill ~132~17~49 ~139~17~49 minecraft:stone_brick_stairs 6
fill ~132~18~49 ~139~18~49 minecraft:stone_brick_stairs 2
setblock ~132~19~49 minecraft:cobblestone_wall 0
fill ~132~21~49 ~148~21~50 minecraft:concrete 0
setblock ~135~19~49 minecraft:cobblestone_wall 0
setblock ~138~19~49 minecraft:cobblestone_wall 0
fill ~139~20~49 ~140~20~50 minecraft:stone_block_slab 14
setblock ~147~20~49 minecraft:stained_hardened_clay 9
fill ~149~21~49 ~149~21~50 minecraft:clay
fill ~150~21~49 ~165~21~50 minecraft:concrete 0
setblock ~151~11~49 minecraft:cobblestone_wall 0
fill ~152~6~49 ~163~6~49 minecraft:stone_block_slab 14
fill ~152~7~49 ~156~7~49 minecraft:stone_block_slab 6
fill ~152~11~49 ~154~11~49 minecraft:cobblestone_wall 0
fill ~155~13~49 ~156~14~49 minecraft:stained_hardened_clay 9
setblock ~156~12~49 minecraft:stained_hardened_clay 9
fill ~157~7~49 ~157~7~50 minecraft:concrete 7
fill ~157~12~49 ~157~14~50 minecraft:concrete 8
fill ~157~16~49 ~158~17~52 minecraft:stained_hardened_clay 9
fill ~158~7~49 ~162~7~49 minecraft:stained_hardened_clay 9
fill ~158~11~49 ~158~11~50 minecraft:concrete 8
fill ~158~12~49 ~158~14~50 minecraft:stained_hardened_clay 9
fill ~158~15~49 ~158~15~52 minecraft:concrete 8
fill ~159~10~49 ~161~10~50 minecraft:concrete 8
fill ~159~11~49 ~161~11~50 minecraft:stained_hardened_clay 9
fill ~159~15~49 ~161~15~52 minecraft:stained_hardened_clay 9
fill ~159~16~49 ~161~16~52 minecraft:concrete 8
fill ~159~17~49 ~162~17~52 minecraft:stained_hardened_clay 9
fill ~161~18~49 ~162~19~52 minecraft:stained_hardened_clay 9
fill ~162~8~49 ~163~8~50 minecraft:stained_hardened_clay 9
fill ~162~11~49 ~162~11~52 minecraft:concrete 8
fill ~162~12~49 ~162~14~52 minecraft:stained_hardened_clay 9
fill ~162~15~49 ~162~15~52 minecraft:concrete 8
fill ~162~16~49 ~162~16~52 minecraft:stained_hardened_clay 9
fill ~163~7~49 ~164~7~49 minecraft:concrete 0
fill ~163~9~49 ~163~11~52 minecraft:stained_hardened_clay 9
fill ~163~12~49 ~163~14~49 minecraft:concrete 8
setblock ~163~15~49 minecraft:stained_hardened_clay 9
fill ~163~16~49 ~163~19~49 minecraft:concrete 7
fill ~163~20~49 ~163~20~52 minecraft:stained_hardened_clay 9
fill ~164~8~49 ~165~16~49 minecraft:concrete 0
fill ~164~20~49 ~165~20~49 minecraft:concrete 0
setblock ~165~7~49 minecraft:quartz_stairs 5
setblock ~179~7~49 minecraft:quartz_stairs 4
fill ~179~8~49 ~180~16~49 minecraft:concrete 0
fill ~179~20~49 ~180~21~49 minecraft:concrete 0
fill ~180~7~49 ~181~7~49 minecraft:concrete 0
fill ~181~6~49 ~186~6~49 minecraft:stone_block_slab 14
fill ~181~8~49 ~182~8~52 minecraft:stained_hardened_clay 9
fill ~181~9~49 ~181~15~52 minecraft:stained_hardened_clay 9
fill ~181~16~49 ~181~19~49 minecraft:concrete 7
fill ~181~20~49 ~181~20~52 minecraft:stained_hardened_clay 9
fill ~181~21~49 ~186~21~50 minecraft:concrete 0
fill ~182~7~49 ~185~7~50 minecraft:stained_hardened_clay 9
fill ~182~16~49 ~182~19~52 minecraft:stained_hardened_clay 9
fill ~183~20~49 ~185~20~50 minecraft:stained_hardened_clay 9
fill ~184~8~49 ~185~8~50 minecraft:stained_hardened_clay 9
fill ~185~9~49 ~185~10~50 minecraft:stained_hardened_clay 9
fill ~185~11~49 ~185~14~50 minecraft:sea_lantern
fill ~185~19~49 ~185~19~50 minecraft:stained_hardened_clay 9
setblock ~186~7~49 minecraft:stone_block_slab 6
fill ~186~9~49 ~186~9~50 minecraft:concrete 8
fill ~186~10~49 ~187~10~50 minecraft:concrete 7
fill ~186~11~49 ~186~14~50 minecraft:stained_glass 3
fill ~186~15~49 ~187~15~50 minecraft:concrete 7
fill ~186~16~49 ~186~16~50 minecraft:concrete 8
fill ~186~17~49 ~186~19~51 minecraft:concrete 7
fill ~50~20~50 ~70~20~50 minecraft:stone_block_slab 14
fill ~50~21~50 ~70~21~50 minecraft:stone_block_slab 6
setblock ~71~20~50 minecraft:stone_block_slab 8
setblock ~71~21~50 minecraft:stone_block_slab 0
fill ~72~20~50 ~96~20~51 minecraft:stone_block_slab 14
fill ~72~21~50 ~96~21~51 minecraft:stone_block_slab 6
fill ~94~12~50 ~94~12~53 minecraft:concrete 15
fill ~95~11~50 ~95~13~54 minecraft:stained_hardened_clay 9
fill ~96~11~50 ~97~13~50 minecraft:concrete 7
setblock ~97~10~50 minecraft:concrete 7
setblock ~97~14~50 minecraft:concrete 7
fill ~99~8~50 ~100~8~55 minecraft:stone_block_slab 14
fill ~99~9~50 ~100~9~50 minecraft:stone_block_slab 6
fill ~99~15~50 ~100~15~50 minecraft:stone_block_slab 14
fill ~99~16~50 ~100~16~53 minecraft:stone_block_slab 6
fill ~100~10~50 ~103~10~51 minecraft:concrete 8
fill ~100~11~50 ~100~14~51 minecraft:concrete 8
fill ~101~8~50 ~102~8~55 minecraft:concrete 0
fill ~101~14~50 ~103~14~51 minecraft:concrete 8
fill ~101~16~50 ~102~16~53 minecraft:concrete 0
fill ~118~17~50 ~119~19~50 minecraft:stained_glass 3
fill ~119~15~50 ~120~16~50 minecraft:stained_glass 3
fill ~119~20~50 ~120~21~50 minecraft:stained_glass 3
fill ~120~14~50 ~122~14~50 minecraft:stained_glass 3
fill ~120~22~50 ~122~22~50 minecraft:stained_glass 3
fill ~121~13~50 ~127~13~50 minecraft:stained_glass 3
fill ~121~15~50 ~122~16~50 minecraft:concrete 8
fill ~121~21~50 ~122~21~50 minecraft:concrete 8
fill ~121~23~50 ~127~23~50 minecraft:stained_glass 3
fill ~123~7~50 ~127~7~54 minecraft:concrete 8
fill ~123~8~50 ~127~10~50 minecraft:concrete 8
fill ~123~12~50 ~125~12~50 minecraft:stained_glass 3
fill ~123~15~50 ~125~15~54 minecraft:stained_hardened_clay 9
fill ~123~16~50 ~127~16~50 minecraft:concrete 8
fill ~123~21~50 ~125~21~88 minecraft:stained_hardened_clay 9
fill ~123~24~50 ~125~24~50 minecraft:stained_glass 3
fill ~126~11~50 ~129~11~50 minecraft:concrete 8
fill ~126~14~50 ~128~14~50 minecraft:stained_glass 3
fill ~126~15~50 ~127~15~50 minecraft:concrete 8
fill ~126~21~50 ~127~21~50 minecraft:concrete 8
fill ~126~22~50 ~128~22~50 minecraft:stained_glass 3
fill ~126~25~50 ~127~25~50 minecraft:concrete 8
fill ~128~9~50 ~128~10~50 minecraft:concrete 8
fill ~128~12~50 ~129~12~50 minecraft:concrete 8
fill ~128~15~50 ~129~16~50 minecraft:stained_glass 3
fill ~128~20~50 ~129~21~50 minecraft:stained_glass 3
setblock ~128~24~50 minecraft:concrete 8
fill ~129~13~50 ~130~13~50 minecraft:concrete 8
fill ~129~17~50 ~130~19~50 minecraft:stained_glass 3
setblock ~129~23~50 minecraft:concrete 8
setblock ~130~14~50 minecraft:concrete 8
setblock ~130~22~50 minecraft:concrete 8
fill ~131~15~50 ~131~16~50 minecraft:concrete 8
fill ~131~20~50 ~131~21~50 minecraft:concrete 8
fill ~132~17~50 ~132~19~50 minecraft:concrete 8
fill ~133~17~50 ~134~17~50 minecraft:stone_brick_stairs 7
fill ~133~18~50 ~144~18~50 minecraft:concrete 14
fill ~133~19~50 ~134~19~50 minecraft:stone_block_slab 0
fill ~135~17~50 ~135~17~52 minecraft:concrete 14
fill ~135~19~50 ~135~19~52 minecraft:concrete 14
fill ~136~17~50 ~137~17~50 minecraft:stone_brick_stairs 7
fill ~136~19~50 ~137~19~50 minecraft:stone_block_slab 0
fill ~138~17~50 ~138~17~52 minecraft:concrete 14
fill ~138~19~50 ~138~19~52 minecraft:concrete 14
setblock ~139~17~50 minecraft:stone_brick_stairs 7
fill ~139~19~50 ~140~19~50 minecraft:stone_block_slab 0
setblock ~140~17~50 minecraft:stone_block_slab 8
fill ~141~17~50 ~141~17~52 minecraft:concrete 14
fill ~141~19~50 ~141~19~52 minecraft:concrete 14
fill ~142~17~50 ~143~17~50 minecraft:stone_block_slab 8
fill ~142~19~50 ~143~19~50 minecraft:stone_block_slab 0
fill ~144~17~50 ~144~17~52 minecraft:concrete 14
fill ~144~19~50 ~144~19~52 minecraft:concrete 14
fill ~145~20~50 ~149~20~50 minecraft:concrete 7
setblock ~149~18~50 minecraft:stone_block_slab 14
fill ~149~19~50 ~150~19~50 minecraft:concrete 7
fill ~150~17~50 ~150~17~52 minecraft:stone_brick_stairs 4
setblock ~150~18~50 minecraft:stonebrick 0
setblock ~150~20~50 minecraft:stained_hardened_clay 9
fill ~151~17~50 ~151~17~52 minecraft:stonebrick 0
setblock ~151~19~50 minecraft:stained_hardened_clay 9
fill ~152~6~50 ~166~6~50 minecraft:concrete 0
setblock ~152~13~50 minecraft:cobblestone_wall 0
setblock ~153~13~50 minecraft:cobblestone_wall 0
setblock ~154~15~50 minecraft:concrete 7
fill ~155~13~50 ~155~14~50 minecraft:concrete 7
fill ~155~15~50 ~157~15~50 minecraft:stained_hardened_clay 9
fill ~156~11~50 ~156~12~50 minecraft:concrete 7
fill ~156~13~50 ~156~14~50 minecraft:stained_hardened_clay 9
fill ~157~9~50 ~157~10~50 minecraft:concrete 7
setblock ~157~11~50 minecraft:stained_hardened_clay 9
fill ~158~7~50 ~158~8~50 minecraft:concrete 7
fill ~158~9~50 ~159~9~50 minecraft:stained_hardened_clay 9
setblock ~158~10~50 minecraft:stained_hardened_clay 9
fill ~159~7~50 ~164~7~50 minecraft:stained_hardened_clay 9
fill ~159~8~50 ~160~8~50 minecraft:stained_hardened_clay 9
fill ~163~12~50 ~165~14~51 minecraft:stained_hardened_clay 9
fill ~163~15~50 ~163~15~51 minecraft:concrete 0
fill ~163~16~50 ~163~19~52 minecraft:stained_hardened_clay 9
fill ~164~8~50 ~165~10~52 minecraft:stained_hardened_clay 9
fill ~164~11~50 ~168~11~50 minecraft:concrete 0
fill ~164~15~50 ~165~15~52 minecraft:stained_hardened_clay 9
fill ~164~16~50 ~168~16~50 minecraft:concrete 0
fill ~164~17~50 ~165~19~50 minecraft:concrete 7
fill ~164~20~50 ~165~20~52 minecraft:stained_hardened_clay 9
fill ~165~7~50 ~167~7~50 minecraft:concrete 0
fill ~166~8~50 ~167~10~50 minecraft:concrete 0
fill ~166~12~50 ~168~15~50 minecraft:concrete 0
fill ~166~20~50 ~168~21~50 minecraft:concrete 0
setblock ~167~6~50 minecraft:quartz_stairs 5
setblock ~168~8~50 minecraft:quartz_stairs 5
fill ~168~9~50 ~168~10~50 minecraft:concrete 0
setblock ~176~8~50 minecraft:quartz_stairs 4
fill ~176~9~50 ~178~16~50 minecraft:concrete 0
fill ~176~20~50 ~178~21~50 minecraft:concrete 0
setblock ~177~6~50 minecraft:quartz_stairs 4
fill ~177~7~50 ~179~7~50 minecraft:concrete 0
fill ~177~8~50 ~178~8~50 minecraft:concrete 0
fill ~178~6~50 ~186~6~50 minecraft:concrete 0
fill ~179~8~50 ~180~16~52 minecraft:stained_hardened_clay 9
fill ~179~17~50 ~180~19~50 minecraft:concrete 7
fill ~179~20~50 ~180~20~52 minecraft:stained_hardened_clay 9
fill ~179~21~50 ~180~21~50 minecraft:concrete 0
fill ~180~7~50 ~181~7~52 minecraft:stained_hardened_clay 9
fill ~181~16~50 ~181~19~52 minecraft:stained_hardened_clay 9
fill ~44~20~51 ~69~20~51 minecraft:stone_block_slab 14
fill ~44~21~51 ~69~21~51 minecraft:stone_block_slab 6
setblock ~70~20~51 minecraft:stone_block_slab 8
setblock ~70~21~51 minecraft:stone_block_slab 0
setblock ~71~20~51 minecraft:stone_block_slab 14
setblock ~71~21~51 minecraft:stone_block_slab 6
fill ~92~11~51 ~92~11~54 minecraft:stone_block_slab 13
fill ~92~13~51 ~92~13~54 minecraft:stone_block_slab 5
fill ~96~11~51 ~97~13~54 minecraft:stained_hardened_clay 9
fill ~97~10~51 ~97~10~54 minecraft:stained_hardened_clay 9
fill ~97~14~51 ~97~14~54 minecraft:stained_hardened_clay 9
fill ~97~20~51 ~102~20~51 minecraft:stone_block_slab 14
fill ~97~21~51 ~102~21~51 minecraft:stone_block_slab 6
fill ~98~10~51 ~99~14~51 minecraft:concrete 7
setblock ~99~9~51 minecraft:concrete 7
setblock ~99~15~51 minecraft:concrete 7
setblock ~100~9~51 minecraft:stone_block_slab 6
setblock ~100~15~51 minecraft:stone_block_slab 14
fill ~101~11~51 ~103~13~51 minecraft:stained_glass 3
fill ~103~7~51 ~105~7~55 minecraft:stone_block_slab 14
fill ~103~8~51 ~105~8~51 minecraft:stone_block_slab 6
fill ~103~16~51 ~105~16~51 minecraft:stone_block_slab 14
fill ~103~17~51 ~105~17~53 minecraft:stone_block_slab 6
fill ~104~10~51 ~107~10~52 minecraft:concrete 8
fill ~104~14~51 ~107~14~52 minecraft:concrete 8
fill ~106~7~51 ~108~7~55 minecraft:concrete 0
fill ~106~17~51 ~108~17~53 minecraft:concrete 0
fill ~107~11~51 ~107~13~52 minecraft:concrete 8
fill ~110~8~51 ~110~10~53 minecraft:concrete 14
fill ~111~9~51 ~122~9~53 minecraft:concrete 14
fill ~113~8~51 ~113~8~53 minecraft:concrete 14
fill ~113~10~51 ~113~10~53 minecraft:concrete 14
fill ~116~8~51 ~116~8~53 minecraft:concrete 14
fill ~116~10~51 ~116~10~53 minecraft:concrete 14
fill ~118~17~51 ~119~19~51 minecraft:sea_lantern
fill ~119~8~51 ~119~8~53 minecraft:concrete 14
fill ~119~10~51 ~119~10~53 minecraft:concrete 14
fill ~119~15~51 ~120~16~51 minecraft:sea_lantern
fill ~119~20~51 ~120~21~51 minecraft:sea_lantern
fill ~120~14~51 ~122~14~51 minecraft:sea_lantern
fill ~120~22~51 ~122~22~51 minecraft:sea_lantern
fill ~121~13~51 ~127~13~51 minecraft:sea_lantern
fill ~121~15~51 ~122~15~54 minecraft:stained_hardened_clay 9
fill ~121~16~51 ~121~16~54 minecraft:stained_hardened_clay 9
fill ~121~20~51 ~126~20~51 minecraft:concrete 8
fill ~121~21~51 ~122~21~87 minecraft:stained_hardened_clay 9
fill ~121~23~51 ~127~23~51 minecraft:sea_lantern
fill ~122~8~51 ~122~8~53 minecraft:concrete 14
fill ~122~10~51 ~122~10~53 minecraft:concrete 14
fill ~122~16~51 ~126~16~51 minecraft:concrete 8
fill ~122~17~51 ~126~19~51 minecraft:concrete 7
fill ~123~8~51 ~127~10~53 minecraft:stained_hardened_clay 9
fill ~123~12~51 ~125~12~51 minecraft:sea_lantern
fill ~123~14~51 ~125~14~54 minecraft:stained_hardened_clay 9
fill ~123~22~51 ~125~22~66 minecraft:stained_hardened_clay 9
fill ~123~24~51 ~125~24~51 minecraft:sea_lantern
fill ~126~11~51 ~129~11~51 minecraft:stained_hardened_clay 9
fill ~126~14~51 ~128~14~51 minecraft:sea_lantern
fill ~126~15~51 ~127~15~54 minecraft:stained_hardened_clay 9
fill ~126~21~51 ~127~21~87 minecraft:stained_hardened_clay 9
fill ~126~22~51 ~128~22~51 minecraft:sea_lantern
fill ~127~16~51 ~127~16~54 minecraft:stained_hardened_clay 9
fill ~127~20~51 ~127~20~87 minecraft:stained_hardened_clay 9
fill ~128~8~51 ~130~8~55 minecraft:concrete 7
fill ~128~9~51 ~128~10~51 minecraft:stained_hardened_clay 9
fill ~128~12~51 ~129~12~51 minecraft:stained_hardened_clay 9
fill ~128~15~51 ~129~16~51 minecraft:sea_lantern
fill ~128~20~51 ~129~21~51 minecraft:sea_lantern
fill ~129~9~51 ~130~10~51 minecraft:concrete 7
fill ~129~13~51 ~130~13~51 minecraft:stained_hardened_clay 9
fill ~129~17~51 ~130~19~51 minecraft:sea_lantern
fill ~130~11~51 ~131~12~51 minecraft:concrete 7
setblock ~130~14~51 minecraft:stained_hardened_clay 9
setblock ~131~10~51 minecraft:concrete 7
fill ~131~13~51 ~132~15~51 minecraft:concrete 7
fill ~131~16~51 ~131~16~52 minecraft:concrete 8
setblock ~132~12~51 minecraft:concrete 7
fill ~132~17~51 ~134~19~51 minecraft:concrete 14
fill ~132~21~51 ~136~21~51 minecraft:stone_block_slab 14
fill ~132~22~51 ~148~22~51 minecraft:stone_block_slab 6
fill ~133~14~51 ~133~15~51 minecraft:concrete 7
fill ~135~18~51 ~143~18~52 minecraft:concrete 14
fill ~136~17~51 ~137~17~51 minecraft:concrete 14
fill ~136~19~51 ~137~19~51 minecraft:concrete 14
setblock ~137~21~51 minecraft:quartz_stairs 4
setblock ~138~21~51 minecraft:concrete 0
fill ~139~17~51 ~140~17~51 minecraft:concrete 14
fill ~139~19~51 ~140~19~51 minecraft:concrete 14
fill ~139~21~51 ~149~21~51 minecraft:concrete 7
fill ~142~17~51 ~143~17~51 minecraft:concrete 14
fill ~142~19~51 ~143~19~51 minecraft:concrete 14
fill ~144~18~51 ~151~18~51 minecraft:observer 4
fill ~149~22~51 ~149~22~52 minecraft:stone_block_slab 0
fill ~150~19~51 ~150~19~52 minecraft:stone_brick_stairs 0
fill ~150~20~51 ~150~20~52 minecraft:concrete 8
fill ~150~21~51 ~168~21~52 minecraft:stained_hardened_clay 9
fill ~150~22~51 ~187~22~52 minecraft:stone_block_slab 6
fill ~151~19~51 ~151~19~52 minecraft:concrete 8
fill ~152~17~51 ~152~17~52 minecraft:stone_brick_stairs 5
fill ~152~18~51 ~152~18~52 minecraft:concrete 8
fill ~152~19~51 ~152~19~52 minecraft:stained_hardened_clay 9
fill ~153~17~51 ~153~17~52 minecraft:concrete 8
fill ~154~16~51 ~154~16~52 minecraft:concrete 8
fill ~154~17~51 ~156~17~52 minecraft:stained_hardened_clay 9
fill ~155~15~51 ~155~15~52 minecraft:concrete 8
fill ~155~16~51 ~156~16~52 minecraft:stained_hardened_clay 9
fill ~156~14~51 ~157~14~52 minecraft:concrete 8
fill ~156~15~51 ~157~15~52 minecraft:stained_hardened_clay 9
fill ~157~13~51 ~157~13~52 minecraft:concrete 8
fill ~158~12~51 ~158~12~52 minecraft:concrete 8
fill ~158~13~51 ~158~14~52 minecraft:stained_hardened_clay 9
fill ~159~11~51 ~159~11~52 minecraft:concrete 8
fill ~160~10~51 ~161~10~52 minecraft:concrete 8
fill ~160~11~51 ~161~11~52 minecraft:stained_hardened_clay 9
fill ~161~9~51 ~161~9~52 minecraft:concrete 8
fill ~162~8~51 ~162~8~52 minecraft:concrete 8
fill ~163~7~51 ~163~7~52 minecraft:concrete 8
fill ~163~8~51 ~163~8~52 minecraft:stained_hardened_clay 9
fill ~164~6~51 ~164~6~52 minecraft:concrete 8
fill ~164~7~51 ~167~7~52 minecraft:stained_hardened_clay 9
fill ~164~11~51 ~165~11~51 minecraft:concrete 0
fill ~164~16~51 ~165~16~51 minecraft:concrete 0
fill ~164~17~51 ~165~19~52 minecraft:stained_hardened_clay 9
fill ~165~5~51 ~185~5~51 minecraft:stone_block_slab 14
fill ~165~6~51 ~166~6~52 minecraft:stained_hardened_clay 9
fill ~166~8~51 ~167~11~52 minecraft:stained_hardened_clay 9
fill ~166~12~51 ~166~15~51 minecraft:concrete 0
fill ~166~16~51 ~168~16~52 minecraft:stained_hardened_clay 9
fill ~166~17~51 ~168~19~51 minecraft:concrete 7
fill ~166~20~51 ~167~20~52 minecraft:stained_hardened_clay 9
fill ~167~6~51 ~177~6~51 minecraft:concrete 0
fill ~167~12~51 ~168~15~52 minecraft:stained_hardened_clay 9
fill ~168~7~51 ~169~8~51 minecraft:concrete 0
fill ~168~9~51 ~168~11~52 minecraft:stained_hardened_clay 9
setblock ~168~20~51 minecraft:concrete 7
fill ~169~9~51 ~169~16~51 minecraft:concrete 0
fill ~169~17~51 ~175~17~51 minecraft:stone_block_slab 6
fill ~169~20~51 ~175~20~51 minecraft:stone_block_slab 14
fill ~169~21~51 ~175~21~51 minecraft:concrete 0
fill ~170~16~51 ~175~16~51 minecraft:concrete 0
fill ~171~7~51 ~171~15~51 minecraft:concrete 0
fill ~173~7~51 ~173~15~51 minecraft:concrete 0
fill ~175~7~51 ~176~8~51 minecraft:concrete 0
fill ~175~9~51 ~175~15~51 minecraft:concrete 0
fill ~176~9~51 ~178~16~52 minecraft:stained_hardened_clay 9
fill ~176~17~51 ~178~19~51 minecraft:concrete 7
setblock ~176~20~51 minecraft:concrete 7
fill ~176~21~51 ~184~21~52 minecraft:stained_hardened_clay 9
fill ~177~7~51 ~179~7~52 minecraft:stained_hardened_clay 9
fill ~177~8~51 ~178~8~52 minecraft:stained_hardened_clay 9
fill ~177~20~51 ~178~20~52 minecraft:stained_hardened_clay 9
fill ~178~6~51 ~184~6~52 minecraft:stained_hardened_clay 9
fill ~179~17~51 ~180~19~52 minecraft:stained_hardened_clay 9
fill ~182~7~51 ~184~7~52 minecraft:stained_hardened_clay 9
fill ~183~20~51 ~184~20~52 minecraft:stained_hardened_clay 9
fill ~184~8~51 ~184~8~52 minecraft:stained_hardened_clay 9
fill ~184~11~51 ~184~14~51 minecraft:sea_lantern
fill ~184~15~51 ~184~15~52 minecraft:stained_hardened_clay 9
setblock ~185~6~51 minecraft:stone_block_slab 6
fill ~185~9~51 ~185~9~52 minecraft:concrete 8
fill ~185~10~51 ~186~10~52 minecraft:concrete 7
fill ~185~11~51 ~185~14~51 minecraft:stained_glass 3
fill ~185~15~51 ~186~15~52 minecraft:concrete 7
fill ~185~16~51 ~185~16~52 minecraft:concrete 8
fill ~185~17~51 ~185~19~52 minecraft:concrete 7
fill ~185~21~51 ~187~21~52 minecraft:stone_block_slab 14
fill ~36~21~52 ~68~21~52 minecraft:concrete 0
setblock ~69~21~52 minecraft:clay
fill ~70~21~52 ~109~21~53 minecraft:concrete 0
fill ~98~10~52 ~99~14~54 minecraft:stained_hardened_clay 9
fill ~99~9~52 ~99~9~54 minecraft:stained_hardened_clay 9
fill ~99~15~52 ~99~15~54 minecraft:stained_hardened_clay 9
fill ~100~9~52 ~101~10~52 minecraft:concrete 7
fill ~100~11~52 ~100~15~52 minecraft:concrete 7
fill ~101~11~52 ~103~13~52 minecraft:sea_lantern
fill ~101~14~52 ~103~15~52 minecraft:concrete 7
fill ~102~9~52 ~103~9~52 minecraft:stonebrick 0
setblock ~102~10~52 minecraft:concrete 7
fill ~103~8~52 ~104~8~52 minecraft:stonebrick 0
setblock ~103~10~52 minecraft:stonebrick 0
setblock ~103~16~52 minecraft:concrete 7
fill ~104~9~52 ~109~9~52 minecraft:observer 5
fill ~104~11~52 ~106~13~52 minecraft:stained_glass 3
fill ~104~16~52 ~105~16~52 minecraft:stone_block_slab 14
setblock ~105~8~52 minecraft:stone_block_slab 6
fill ~109~6~52 ~112~6~55 minecraft:stone_block_slab 14
fill ~109~7~52 ~112~7~52 minecraft:stone_block_slab 6
fill ~109~12~52 ~111~14~52 minecraft:concrete 8
fill ~109~17~52 ~112~17~52 minecraft:stone_block_slab 14
fill ~109~18~52 ~112~18~53 minecraft:stone_block_slab 6
fill ~111~8~52 ~112~8~52 minecraft:concrete 14
fill ~111~10~52 ~112~10~52 minecraft:concrete 14
fill ~112~13~52 ~113~13~53 minecraft:concrete 8
fill ~112~14~52 ~112~14~53 minecraft:concrete 8
fill ~113~6~52 ~116~6~55 minecraft:concrete 0
fill ~113~18~52 ~116~18~53 minecraft:concrete 0
fill ~114~8~52 ~115~8~52 minecraft:concrete 14
fill ~114~10~52 ~115~10~52 minecraft:concrete 14
fill ~117~8~52 ~118~8~52 minecraft:concrete 14
fill ~117~10~52 ~118~10~52 minecraft:concrete 14
fill ~118~17~52 ~130~19~54 minecraft:stained_hardened_clay 9
fill ~119~15~52 ~120~16~54 minecraft:stained_hardened_clay 9
fill ~119~20~52 ~126~20~58 minecraft:stained_hardened_clay 9
fill ~119~21~52 ~120~21~86 minecraft:stained_hardened_clay 9
fill ~120~8~52 ~121~8~52 minecraft:concrete 14
fill ~120~10~52 ~121~10~52 minecraft:concrete 14
fill ~120~14~52 ~122~14~54 minecraft:stained_hardened_clay 9
fill ~120~22~52 ~122~22~65 minecraft:stained_hardened_clay 9
fill ~121~13~52 ~127~13~54 minecraft:stained_hardened_clay 9
fill ~121~23~52 ~127~23~57 minecraft:stained_hardened_clay 9
fill ~122~16~52 ~126~16~54 minecraft:stained_hardened_clay 9
fill ~123~12~52 ~125~12~54 minecraft:stained_hardened_clay 9
fill ~123~24~52 ~125~24~57 minecraft:stained_hardened_clay 9
fill ~126~11~52 ~128~11~54 minecraft:stained_hardened_clay 9
fill ~126~14~52 ~128~14~54 minecraft:stained_hardened_clay 9
fill ~126~22~52 ~128~22~66 minecraft:stained_hardened_clay 9
fill ~126~25~52 ~127~25~52 minecraft:concrete 8
fill ~128~9~52 ~128~10~54 minecraft:sea_lantern
fill ~128~12~52 ~128~12~54 minecraft:stained_hardened_clay 9
fill ~128~15~52 ~129~16~55 minecraft:stained_hardened_clay 9
fill ~128~20~52 ~129~21~58 minecraft:stained_hardened_clay 9
setblock ~128~24~52 minecraft:concrete 8
fill ~129~9~52 ~129~10~54 minecraft:stained_glass 3
fill ~129~11~52 ~129~12~54 minecraft:sea_lantern
fill ~129~13~52 ~129~13~54 minecraft:stained_hardened_clay 9
setblock ~129~23~52 minecraft:concrete 8
fill ~130~11~52 ~130~12~54 minecraft:stained_glass 3
fill ~130~13~52 ~130~14~54 minecraft:sea_lantern
setblock ~130~22~52 minecraft:concrete 8
fill ~131~13~52 ~131~14~54 minecraft:stained_glass 3
fill ~131~15~52 ~133~15~55 minecraft:concrete 7
fill ~131~20~52 ~131~21~52 minecraft:concrete 8
fill ~132~16~52 ~133~16~52 minecraft:iron_bars
fill ~132~17~52 ~132~19~52 minecraft:concrete 8
fill ~133~17~52 ~134~17~52 minecraft:stone_block_slab 8
fill ~133~18~52 ~134~18~52 minecraft:concrete 14
fill ~133~19~52 ~134~19~52 minecraft:stone_block_slab 0
fill ~136~17~52 ~137~17~52 minecraft:stone_block_slab 8
fill ~136~19~52 ~137~19~52 minecraft:stone_block_slab 0
fill ~139~17~52 ~140~17~52 minecraft:stone_block_slab 8
fill ~139~19~52 ~140~19~52 minecraft:stone_block_slab 0
fill ~139~21~52 ~144~21~52 minecraft:concrete 0
fill ~139~22~52 ~148~22~52 minecraft:stone_block_slab 6
fill ~142~17~52 ~143~17~52 minecraft:stone_block_slab 8
fill ~142~19~52 ~143~19~52 minecraft:stone_block_slab 0
setblock ~144~18~52 minecraft:concrete 14
fill ~145~21~52 ~149~21~52 minecraft:concrete 7
fill ~150~18~52 ~151~18~52 minecraft:stonebrick 0
fill ~163~12~52 ~163~14~52 minecraft:concrete 8
setblock ~163~15~52 minecraft:stained_hardened_clay 9
fill ~164~11~52 ~165~11~52 minecraft:stained_hardened_clay 9
fill ~164~12~52 ~165~14~53 minecraft:concrete 0
fill ~164~16~52 ~165~16~52 minecraft:stained_hardened_clay 9
fill ~165~5~52 ~185~5~52 minecraft:concrete 0
fill ~166~12~52 ~166~15~52 minecraft:stained_hardened_clay 9
fill ~166~17~52 ~168~19~52 minecraft:stained_hardened_clay 9
fill ~167~6~52 ~177~6~52 minecraft:stained_hardened_clay 9
fill ~168~7~52 ~169~8~52 minecraft:stained_hardened_clay 9
setblock ~168~20~52 minecraft:stained_hardened_clay 9
fill ~169~9~52 ~169~16~52 minecraft:stained_hardened_clay 9
fill ~169~17~52 ~175~20~52 minecraft:concrete 7
fill ~169~21~52 ~175~21~52 minecraft:stained_hardened_clay 9
fill ~170~7~52 ~170~15~52 minecraft:concrete 14
fill ~170~16~52 ~175~16~52 minecraft:stained_hardened_clay 9
fill ~171~7~52 ~171~15~52 minecraft:stained_hardened_clay 9
fill ~172~7~52 ~172~15~52 minecraft:concrete 14
fill ~173~7~52 ~173~15~52 minecraft:stained_hardened_clay 9
fill ~174~7~52 ~174~15~52 minecraft:concrete 14
fill ~175~7~52 ~176~8~52 minecraft:stained_hardened_clay 9
fill ~175~9~52 ~175~15~52 minecraft:stained_hardened_clay 9
fill ~176~17~52 ~178~19~52 minecraft:stained_hardened_clay 9
setblock ~176~20~52 minecraft:stained_hardened_clay 9
fill ~184~11~52 ~184~14~52 minecraft:stained_hardened_clay 9
fill ~184~17~52 ~184~19~52 minecraft:concrete 7
fill ~185~11~52 ~186~14~52 minecraft:concrete 7
fill ~188~21~52 ~189~21~52 minecraft:stone_block_slab 14
fill ~188~22~52 ~189~22~52 minecraft:stone_block_slab 6
fill ~29~21~53 ~67~21~53 minecraft:concrete 0
setblock ~68~21~53 minecraft:clay
setblock ~69~21~53 minecraft:concrete 0
fill ~91~11~53 ~91~11~54 minecraft:stone_block_slab 13
fill ~91~13~53 ~91~13~54 minecraft:stone_block_slab 5
fill ~100~9~53 ~103~15~54 minecraft:stained_hardened_clay 9
fill ~103~8~53 ~103~8~54 minecraft:stained_hardened_clay 9
setblock ~103~16~53 minecraft:stained_hardened_clay 9
fill ~104~8~53 ~109~10~53 minecraft:concrete 7
fill ~104~11~53 ~106~13~53 minecraft:sea_lantern
fill ~104~14~53 ~109~16~53 minecraft:concrete 7
fill ~107~11~53 ~109~13~53 minecraft:concrete 7
setblock ~109~7~53 minecraft:concrete 7
fill ~109~17~53 ~109~17~54 minecraft:concrete 7
fill ~110~7~53 ~112~7~53 minecraft:stone_block_slab 6
fill ~110~12~53 ~111~14~53 minecraft:concrete 8
fill ~110~17~53 ~112~17~53 minecraft:stone_block_slab 14
setblock ~110~21~53 minecraft:clay
fill ~111~21~53 ~117~21~53 minecraft:concrete 0
fill ~113~14~53 ~117~14~53 minecraft:concrete 8
setblock ~114~13~53 minecraft:concrete 8
fill ~117~5~53 ~121~5~55 minecraft:stone_block_slab 14
fill ~117~6~53 ~121~6~53 minecraft:stone_block_slab 6
setblock ~118~21~53 minecraft:clay
setblock ~119~22~53 minecraft:clay
setblock ~120~23~53 minecraft:clay
fill ~121~24~53 ~122~24~53 minecraft:clay
fill ~122~5~53 ~126~5~66 minecraft:concrete 0
fill ~123~25~53 ~124~25~53 minecraft:clay
fill ~124~6~53 ~124~6~54 minecraft:quartz_stairs 4
fill ~125~6~53 ~125~6~66 minecraft:quartz_stairs 1
fill ~125~25~53 ~125~25~57 minecraft:concrete 0
fill ~128~13~53 ~128~13~54 minecraft:stained_hardened_clay 9
fill ~131~16~53 ~131~16~54 minecraft:hopper 4
fill ~131~21~53 ~131~21~56 minecraft:concrete 0
fill ~132~17~53 ~132~17~54 minecraft:lever 1
fill ~133~16~53 ~133~16~54 minecraft:iron_bars
fill ~141~15~53 ~144~15~55 minecraft:concrete 7
setblock ~141~16~53 minecraft:stone_block_slab 14
fill ~142~12~53 ~145~12~55 minecraft:concrete 7
setblock ~142~13~53 minecraft:stone_block_slab 14
setblock ~142~16~53 minecraft:quartz_stairs 5
fill ~143~9~53 ~146~9~55 minecraft:concrete 7
setblock ~143~10~53 minecraft:stone_block_slab 14
setblock ~143~13~53 minecraft:quartz_stairs 5
setblock ~143~16~53 minecraft:stone_block_slab 14
setblock ~144~10~53 minecraft:quartz_stairs 5
setblock ~144~13~53 minecraft:stone_block_slab 14
setblock ~144~16~53 minecraft:quartz_stairs 4
setblock ~144~21~53 minecraft:quartz_stairs 4
fill ~144~22~53 ~148~22~53 minecraft:concrete 0
setblock ~145~10~53 minecraft:stone_block_slab 14
setblock ~145~13~53 minecraft:quartz_stairs 4
fill ~145~19~53 ~145~19~54 minecraft:quartz_stairs 4
fill ~145~20~53 ~189~21~53 minecraft:concrete 0
setblock ~146~10~53 minecraft:quartz_stairs 4
fill ~146~16~53 ~146~16~54 minecraft:quartz_stairs 4
fill ~146~17~53 ~188~19~53 minecraft:concrete 0
fill ~147~13~53 ~147~13~54 minecraft:quartz_stairs 4
fill ~147~14~53 ~163~14~53 minecraft:concrete 0
fill ~147~15~53 ~148~16~54 minecraft:concrete 0
fill ~148~10~53 ~148~10~54 minecraft:quartz_stairs 4
fill ~148~11~53 ~186~11~53 minecraft:concrete 0
fill ~148~12~53 ~149~13~54 minecraft:concrete 0
fill ~149~7~53 ~149~7~54 minecraft:quartz_stairs 4
fill ~149~8~53 ~185~8~53 minecraft:concrete 0
fill ~149~9~53 ~150~10~54 minecraft:concrete 0
fill ~149~16~53 ~187~16~53 minecraft:concrete 0
fill ~149~22~53 ~149~22~54 minecraft:clay
fill ~150~4~53 ~152~4~54 minecraft:stone_block_slab 14
fill ~150~5~53 ~184~7~53 minecraft:concrete 0
fill ~150~13~53 ~163~13~53 minecraft:concrete 0
fill ~150~22~53 ~192~22~54 minecraft:concrete 0
fill ~151~10~53 ~185~10~53 minecraft:concrete 0
fill ~152~15~53 ~187~15~53 minecraft:concrete 0
fill ~153~12~53 ~163~12~53 minecraft:concrete 0
fill ~154~9~53 ~185~9~53 minecraft:concrete 0
fill ~166~12~53 ~186~14~53 minecraft:concrete 0
fill ~182~4~53 ~184~4~66 minecraft:stone_block_slab 14
setblock ~185~7~53 minecraft:quartz_stairs 5
setblock ~186~10~53 minecraft:quartz_stairs 5
setblock ~187~13~53 minecraft:quartz_stairs 5
setblock ~187~14~53 minecraft:concrete 0
setblock ~188~16~53 minecraft:quartz_stairs 5
setblock ~189~19~53 minecraft:quartz_stairs 5
setblock ~190~21~53 minecraft:quartz_stairs 5
fill ~21~21~54 ~66~21~54 minecraft:stone_block_slab 14
fill ~21~22~54 ~66~22~54 minecraft:stone_block_slab 6
setblock ~67~21~54 minecraft:stone_block_slab 8
setblock ~67~22~54 minecraft:stone_block_slab 0
fill ~68~21~54 ~76~21~54 minecraft:stone_block_slab 14
fill ~68~22~54 ~109~22~55 minecraft:stone_block_slab 6
fill ~74~16~54 ~74~18~56 minecraft:concrete 0
fill ~75~14~54 ~76~14~56 minecraft:concrete 0
fill ~75~15~54 ~75~15~56 minecraft:concrete 0
fill ~75~19~54 ~75~19~56 minecraft:concrete 0
fill ~75~20~54 ~76~20~54 minecraft:concrete 0
fill ~77~13~54 ~79~13~56 minecraft:concrete 0
fill ~77~16~54 ~79~16~56 minecraft:concrete 8
fill ~77~17~54 ~77~18~56 minecraft:concrete 8
fill ~77~21~54 ~79~21~56 minecraft:concrete 0
fill ~78~18~54 ~79~18~56 minecraft:concrete 8
fill ~79~17~54 ~79~17~56 minecraft:concrete 8
fill ~80~14~54 ~81~14~55 minecraft:concrete 0
fill ~80~20~54 ~81~20~54 minecraft:concrete 0
fill ~80~21~54 ~86~21~54 minecraft:stone_block_slab 14
fill ~81~15~54 ~81~15~55 minecraft:concrete 0
fill ~81~19~54 ~81~19~55 minecraft:concrete 0
fill ~82~16~54 ~82~18~55 minecraft:concrete 0
fill ~83~17~54 ~85~17~55 minecraft:concrete 0
fill ~86~16~54 ~87~16~55 minecraft:stone_block_slab 14
fill ~86~17~54 ~87~17~55 minecraft:stone_block_slab 6
setblock ~87~21~54 minecraft:stone_brick_stairs 4
fill ~88~16~54 ~89~16~55 minecraft:concrete 0
setblock ~88~20~54 minecraft:stone_brick_stairs 4
fill ~88~21~54 ~113~21~54 minecraft:concrete 8
fill ~89~19~54 ~89~19~55 minecraft:stone_brick_stairs 4
fill ~89~20~54 ~117~20~54 minecraft:concrete 8
fill ~90~15~54 ~90~15~55 minecraft:stone_block_slab 14
fill ~90~16~54 ~90~16~55 minecraft:stone_block_slab 6
fill ~90~18~54 ~90~18~55 minecraft:stone_brick_stairs 4
fill ~90~19~54 ~97~19~54 minecraft:concrete 8
fill ~91~12~54 ~93~12~54 minecraft:stained_hardened_clay 9
fill ~91~15~54 ~91~15~55 minecraft:concrete 0
fill ~91~17~54 ~91~17~55 minecraft:stone_brick_stairs 4
fill ~91~18~54 ~117~18~54 minecraft:concrete 8
fill ~92~14~54 ~92~14~55 minecraft:stone_block_slab 14
fill ~92~15~54 ~92~15~55 minecraft:stone_block_slab 6
fill ~92~16~54 ~92~16~55 minecraft:stone_brick_stairs 4
fill ~92~17~54 ~93~17~54 minecraft:concrete 8
fill ~93~14~54 ~93~14~55 minecraft:concrete 0
fill ~93~15~54 ~93~15~55 minecraft:stone_brick_stairs 4
fill ~93~16~54 ~104~16~54 minecraft:concrete 8
fill ~94~12~54 ~94~12~55 minecraft:concrete 0
fill ~94~14~54 ~94~14~55 minecraft:stone_brick_stairs 4
fill ~94~15~54 ~97~15~54 minecraft:concrete 8
fill ~94~17~54 ~95~17~54 minecraft:stained_glass_pane 3
fill ~95~14~54 ~95~14~65 minecraft:concrete 8
setblock ~96~14~54 minecraft:stained_hardened_clay 9
setblock ~96~17~54 minecraft:concrete 8
fill ~97~17~54 ~98~17~54 minecraft:stained_glass_pane 3
setblock ~98~15~54 minecraft:stained_hardened_clay 9
fill ~98~19~54 ~100~19~54 minecraft:stained_glass_pane 3
fill ~99~17~54 ~105~17~54 minecraft:concrete 8
fill ~101~19~54 ~102~19~54 minecraft:concrete 8
fill ~103~19~54 ~105~19~54 minecraft:stained_glass_pane 3
fill ~104~8~54 ~109~15~54 minecraft:stained_hardened_clay 9
fill ~105~16~54 ~117~16~54 minecraft:concrete 7
fill ~106~17~54 ~108~17~54 minecraft:concrete 7
fill ~106~19~54 ~107~19~54 minecraft:concrete 8
fill ~108~19~54 ~110~19~54 minecraft:stained_glass_pane 3
setblock ~109~7~54 minecraft:stained_hardened_clay 9
fill ~110~7~54 ~117~15~54 minecraft:concrete 7
fill ~110~17~54 ~116~17~54 minecraft:concrete 7
fill ~110~22~54 ~110~22~55 minecraft:stone_block_slab 0
fill ~111~19~54 ~117~19~54 minecraft:concrete 8
fill ~111~22~54 ~118~22~54 minecraft:stone_block_slab 6
fill ~114~21~54 ~114~21~56 minecraft:concrete 0
fill ~115~21~54 ~117~21~59 minecraft:stained_hardened_clay 9
setblock ~117~6~54 minecraft:concrete 7
setblock ~117~17~54 minecraft:concrete 8
fill ~118~6~54 ~121~6~54 minecraft:stone_block_slab 6
setblock ~118~21~54 minecraft:concrete 0
setblock ~119~22~54 minecraft:concrete 0
setblock ~120~23~54 minecraft:concrete 0
fill ~121~24~54 ~122~24~57 minecraft:concrete 0
fill ~123~8~54 ~123~10~54 minecraft:concrete 8
fill ~123~25~54 ~124~25~57 minecraft:concrete 0
fill ~124~8~54 ~127~10~54 minecraft:stained_hardened_clay 9
fill ~126~12~54 ~127~12~54 minecraft:stained_hardened_clay 9
fill ~127~4~54 ~129~4~55 minecraft:stone_block_slab 14
fill ~127~5~54 ~129~5~55 minecraft:stone_block_slab 6
setblock ~129~14~54 minecraft:stained_hardened_clay 9
fill ~130~4~54 ~133~4~54 minecraft:concrete 0
fill ~130~15~54 ~130~15~55 minecraft:stained_hardened_clay 9
fill ~130~16~54 ~130~16~56 minecraft:concrete 0
fill ~132~21~54 ~134~21~56 minecraft:concrete 0
fill ~135~21~54 ~135~21~56 minecraft:clay
fill ~136~21~54 ~137~21~56 minecraft:concrete 0
fill ~137~15~54 ~140~15~55 minecraft:concrete 7
setblock ~137~16~54 minecraft:quartz_stairs 5
fill ~138~12~54 ~141~12~55 minecraft:concrete 7
setblock ~138~13~54 minecraft:quartz_stairs 5
setblock ~138~16~54 minecraft:stone_block_slab 14
fill ~139~9~54 ~142~9~55 minecraft:concrete 7
setblock ~139~10~54 minecraft:quartz_stairs 5
setblock ~139~13~54 minecraft:stone_block_slab 14
setblock ~139~16~54 minecraft:quartz_stairs 4
setblock ~140~10~54 minecraft:stone_block_slab 14
setblock ~140~13~54 minecraft:quartz_stairs 4
setblock ~140~16~54 minecraft:stone_block_slab 14
setblock ~141~10~54 minecraft:quartz_stairs 4
setblock ~141~13~54 minecraft:stone_block_slab 14
setblock ~142~10~54 minecraft:stone_block_slab 14
fill ~144~16~54 ~144~16~55 minecraft:stone_block_slab 14
fill ~145~13~54 ~145~13~55 minecraft:stone_block_slab 14
setblock ~145~20~54 minecraft:quartz_stairs 0
fill ~146~10~54 ~146~10~55 minecraft:stone_block_slab 14
fill ~146~17~54 ~156~20~54 minecraft:concrete 0
setblock ~146~21~54 minecraft:quartz_stairs 0
fill ~147~14~54 ~156~14~54 minecraft:concrete 0
fill ~147~21~54 ~158~21~54 minecraft:concrete 0
setblock ~147~22~54 minecraft:quartz_stairs 0
fill ~148~11~54 ~156~11~54 minecraft:concrete 0
setblock ~148~22~54 minecraft:concrete 0
fill ~149~8~54 ~156~8~54 minecraft:concrete 0
fill ~149~15~54 ~151~15~55 minecraft:concrete 7
fill ~149~16~54 ~156~16~54 minecraft:concrete 0
fill ~150~5~54 ~183~5~54 minecraft:concrete 0
fill ~150~6~54 ~158~6~54 minecraft:concrete 0
fill ~150~7~54 ~157~7~54 minecraft:concrete 0
fill ~150~12~54 ~152~12~55 minecraft:concrete 7
fill ~150~13~54 ~156~13~54 minecraft:concrete 0
fill ~151~9~54 ~153~9~55 minecraft:concrete 7
fill ~151~10~54 ~156~10~54 minecraft:concrete 0
fill ~152~15~54 ~156~15~54 minecraft:concrete 0
fill ~153~12~54 ~156~12~54 minecraft:concrete 0
fill ~154~9~54 ~156~9~54 minecraft:concrete 0
setblock ~157~8~54 minecraft:quartz_stairs 1
setblock ~157~19~54 minecraft:quartz_stairs 5
setblock ~157~20~54 minecraft:concrete 0
setblock ~158~7~54 minecraft:quartz_stairs 1
setblock ~158~20~54 minecraft:quartz_stairs 5
setblock ~159~6~54 minecraft:quartz_stairs 1
setblock ~159~21~54 minecraft:quartz_stairs 5
fill ~160~9~54 ~160~21~54 minecraft:concrete 7
fill ~161~6~54 ~162~8~54 minecraft:concrete 8
fill ~161~9~54 ~162~11~84 minecraft:stained_hardened_clay 9
fill ~161~12~54 ~181~12~54 minecraft:concrete 7
fill ~161~13~54 ~181~13~55 minecraft:stained_hardened_clay 9
fill ~161~14~54 ~181~14~54 minecraft:concrete 7
