setblock ~23 ~0 ~26 quartz_stairs 6 
setblock ~23 ~0 ~27 quartz_stairs 4 
setblock ~23 ~0 ~28 quartz_stairs 7  
fill ~24 ~0 ~24 ~26 ~0 ~24 quartz_stairs 6  
fill ~24 ~0 ~25 ~24 ~0 ~26 quartz_stairs 4  
fill ~24 ~0 ~27 ~30 ~0 ~27 quartz_block 0  
fill ~24 ~0 ~28 ~24 ~0 ~30 quartz_stairs 4  
fill ~25 ~0 ~25 ~29 ~0 ~25 quartz_block 0  
fill ~25 ~0 ~26 ~29 ~0 ~26 quartz_block 0  
fill ~25 ~0 ~28 ~29 ~0 ~28 quartz_block 0  
fill ~25 ~0 ~29 ~29 ~0 ~29 quartz_block 0 
setblock ~25 ~0 ~30 quartz_stairs 7 
setblock ~26 ~0 ~23 quartz_stairs 4 
setblock ~26 ~0 ~30 quartz_stairs 4  
fill ~26 ~0 ~31 ~28 ~0 ~31 quartz_stairs 7 
setblock ~27 ~0 ~23 quartz_stairs 6 
setblock ~27 ~0 ~24 quartz_block 0 
setblock ~27 ~0 ~30 quartz_block 0 
setblock ~28 ~0 ~23 quartz_stairs 5  
fill ~28 ~0 ~24 ~29 ~0 ~24 quartz_stairs 6 
setblock ~28 ~0 ~30 quartz_stairs 5  
fill ~29 ~0 ~30 ~30 ~0 ~30 quartz_stairs 7  
fill ~30 ~0 ~24 ~30 ~0 ~26 quartz_stairs 5  
fill ~30 ~0 ~28 ~30 ~0 ~29 quartz_stairs 5 
setblock ~31 ~0 ~26 quartz_stairs 6 
setblock ~31 ~0 ~27 quartz_stairs 5 
setblock ~31 ~0 ~28 quartz_stairs 7  
fill ~23 ~1 ~26 ~24 ~1 ~26 quartz_block 2  
fill ~23 ~1 ~28 ~24 ~1 ~28 quartz_block 2 
setblock ~24 ~1 ~24 quartz_block 2 
setblock ~24 ~1 ~27 sea_lantern 0 
setblock ~24 ~1 ~30 quartz_block 2 
setblock ~25 ~1 ~25 sea_lantern 0  
fill ~25 ~1 ~26 ~29 ~1 ~26 quartz_block 0  
fill ~25 ~1 ~27 ~29 ~1 ~27 quartz_block 0  
fill ~25 ~1 ~28 ~29 ~1 ~28 quartz_block 0 
setblock ~25 ~1 ~29 sea_lantern 0  
fill ~26 ~1 ~23 ~26 ~1 ~24 quartz_block 2  
fill ~26 ~1 ~25 ~28 ~1 ~25 quartz_block 0  
fill ~26 ~1 ~29 ~28 ~1 ~29 quartz_block 0  
fill ~26 ~1 ~30 ~26 ~1 ~31 quartz_block 2 
setblock ~27 ~1 ~24 sea_lantern 0 
setblock ~27 ~1 ~30 sea_lantern 0  
fill ~28 ~1 ~23 ~28 ~1 ~24 quartz_block 2  
fill ~28 ~1 ~30 ~28 ~1 ~31 quartz_block 2 
setblock ~29 ~1 ~25 sea_lantern 0 
setblock ~29 ~1 ~29 sea_lantern 0 
setblock ~30 ~1 ~24 quartz_block 2  
fill ~30 ~1 ~26 ~31 ~1 ~26 quartz_block 2 
setblock ~30 ~1 ~27 sea_lantern 0  
fill ~30 ~1 ~28 ~31 ~1 ~28 quartz_block 2 
setblock ~30 ~1 ~30 quartz_block 2  
fill ~23 ~2 ~26 ~24 ~2 ~26 quartz_stairs 2 
setblock ~23 ~2 ~27 quartz_stairs 0  
fill ~23 ~2 ~28 ~24 ~2 ~28 quartz_stairs 3  
fill ~24 ~2 ~24 ~24 ~2 ~25 quartz_stairs 0  
fill ~24 ~2 ~27 ~30 ~2 ~27 quartz_block 0  
fill ~24 ~2 ~29 ~24 ~2 ~30 quartz_stairs 0 
setblock ~25 ~2 ~24 quartz_stairs 2  
fill ~25 ~2 ~25 ~29 ~2 ~25 quartz_block 0  
fill ~25 ~2 ~26 ~29 ~2 ~26 quartz_block 0  
fill ~25 ~2 ~28 ~29 ~2 ~28 quartz_block 0  
fill ~25 ~2 ~29 ~29 ~2 ~29 quartz_block 0 
setblock ~25 ~2 ~30 quartz_stairs 3  
fill ~26 ~2 ~23 ~28 ~2 ~23 quartz_stairs 2 
setblock ~26 ~2 ~24 quartz_stairs 0  
fill ~26 ~2 ~30 ~26 ~2 ~31 quartz_stairs 0 
setblock ~27 ~2 ~24 quartz_block 0 
setblock ~27 ~2 ~30 quartz_block 0 
setblock ~27 ~2 ~31 quartz_stairs 3 
setblock ~28 ~2 ~24 quartz_stairs 1  
fill ~28 ~2 ~30 ~28 ~2 ~31 quartz_stairs 1 
setblock ~29 ~2 ~24 quartz_stairs 2  
fill ~29 ~2 ~30 ~30 ~2 ~30 quartz_stairs 3  
fill ~30 ~2 ~24 ~30 ~2 ~25 quartz_stairs 1 
setblock ~30 ~2 ~26 quartz_stairs 2  
fill ~30 ~2 ~28 ~30 ~2 ~29 quartz_stairs 1  
fill ~31 ~2 ~26 ~31 ~2 ~27 quartz_stairs 1 
setblock ~31 ~2 ~28 quartz_stairs 3  
fill ~25 ~3 ~26 ~25 ~3 ~27 quartz_stairs 4 
setblock ~25 ~3 ~28 quartz_stairs 7 
setblock ~26 ~3 ~25 quartz_stairs 4 
setblock ~26 ~3 ~26 quartz_stairs 6  
fill ~26 ~3 ~27 ~28 ~3 ~27 quartz_block 0 
setblock ~26 ~3 ~28 quartz_stairs 4  
fill ~26 ~3 ~29 ~27 ~3 ~29 quartz_stairs 7 
setblock ~27 ~3 ~25 quartz_stairs 6  
fill ~27 ~3 ~26 ~27 ~6 ~26 quartz_block 0  
fill ~27 ~3 ~28 ~27 ~6 ~28 quartz_block 0 
setblock ~28 ~3 ~25 quartz_stairs 5  
fill ~28 ~3 ~26 ~29 ~3 ~26 quartz_stairs 6  
fill ~28 ~3 ~28 ~28 ~3 ~29 quartz_stairs 5 
setblock ~29 ~3 ~27 quartz_stairs 5 
setblock ~29 ~3 ~28 quartz_stairs 7  
fill ~21 ~4 ~27 ~22 ~4 ~27 stone_slab 14  
fill ~22 ~4 ~25 ~22 ~4 ~29 stone_slab 14 
setblock ~23 ~4 ~24 stone_slab 14 
setblock ~23 ~4 ~25 quartz_stairs 6  
fill ~23 ~4 ~26 ~23 ~4 ~28 quartz_stairs 4 
setblock ~23 ~4 ~29 quartz_stairs 7 
setblock ~23 ~4 ~30 stone_slab 14 
setblock ~24 ~4 ~23 stone_slab 14 
setblock ~24 ~4 ~24 quartz_stairs 6 
setblock ~24 ~4 ~25 quartz_stairs 4  
fill ~24 ~4 ~26 ~30 ~4 ~26 quartz_block 0  
fill ~24 ~4 ~27 ~30 ~4 ~27 quartz_block 0  
fill ~24 ~4 ~28 ~30 ~4 ~28 quartz_block 0 
setblock ~24 ~4 ~29 quartz_stairs 4 
setblock ~24 ~4 ~30 quartz_stairs 7 
setblock ~24 ~4 ~31 stone_slab 14  
fill ~25 ~4 ~22 ~29 ~4 ~22 stone_slab 14  
fill ~25 ~4 ~23 ~29 ~4 ~23 quartz_stairs 6 
setblock ~25 ~4 ~24 quartz_stairs 4  
fill ~25 ~4 ~25 ~29 ~4 ~25 quartz_block 0  
fill ~25 ~4 ~29 ~29 ~4 ~29 quartz_block 0 
setblock ~25 ~4 ~30 quartz_stairs 4  
fill ~25 ~4 ~31 ~28 ~4 ~31 quartz_stairs 7  
fill ~25 ~4 ~32 ~29 ~4 ~32 stone_slab 14  
fill ~26 ~4 ~24 ~28 ~4 ~24 quartz_block 0  
fill ~26 ~4 ~30 ~28 ~4 ~30 quartz_block 0 
setblock ~27 ~4 ~21 stone_slab 14 
setblock ~27 ~4 ~33 stone_slab 14 
setblock ~29 ~4 ~24 quartz_stairs 5 
setblock ~29 ~4 ~30 quartz_stairs 7 
setblock ~29 ~4 ~31 quartz_stairs 5 
setblock ~30 ~4 ~23 stone_slab 14 
setblock ~30 ~4 ~24 quartz_stairs 6 
setblock ~30 ~4 ~25 quartz_stairs 5 
setblock ~30 ~4 ~29 quartz_stairs 7 
setblock ~30 ~4 ~30 quartz_stairs 5 
setblock ~30 ~4 ~31 stone_slab 14 
setblock ~31 ~4 ~24 stone_slab 14 
setblock ~31 ~4 ~25 quartz_stairs 6  
fill ~31 ~4 ~26 ~31 ~4 ~29 quartz_stairs 5 
setblock ~31 ~4 ~30 stone_slab 14  
fill ~32 ~4 ~25 ~32 ~4 ~29 stone_slab 14 
setblock ~33 ~4 ~27 stone_slab 14 
setblock ~20 ~5 ~26 quartz_stairs 6 
setblock ~20 ~5 ~27 quartz_stairs 4 
setblock ~20 ~5 ~28 quartz_stairs 7  
fill ~21 ~5 ~24 ~21 ~5 ~26 quartz_stairs 4  
fill ~21 ~5 ~27 ~33 ~5 ~27 quartz_block 0  
fill ~21 ~5 ~28 ~21 ~5 ~29 quartz_stairs 4  
fill ~21 ~5 ~30 ~22 ~5 ~30 quartz_stairs 7 
setblock ~22 ~5 ~23 quartz_stairs 4 
setblock ~22 ~5 ~24 quartz_stairs 6  
fill ~22 ~5 ~25 ~32 ~5 ~25 quartz_block 0  
fill ~22 ~5 ~26 ~32 ~5 ~26 quartz_block 0  
fill ~22 ~5 ~28 ~32 ~5 ~28 quartz_block 0  
fill ~22 ~5 ~29 ~32 ~5 ~29 quartz_block 0 
setblock ~22 ~5 ~31 quartz_stairs 4 
setblock ~23 ~5 ~22 quartz_stairs 4 
setblock ~23 ~5 ~23 quartz_stairs 6  
fill ~23 ~5 ~24 ~31 ~5 ~24 quartz_block 0  
fill ~23 ~5 ~30 ~31 ~5 ~30 quartz_block 0 
setblock ~23 ~5 ~31 quartz_stairs 7 
setblock ~23 ~5 ~32 quartz_stairs 4 
setblock ~24 ~5 ~21 quartz_stairs 4 
setblock ~24 ~5 ~22 quartz_stairs 6  
fill ~24 ~5 ~23 ~30 ~5 ~23 quartz_block 0  
fill ~24 ~5 ~31 ~30 ~5 ~31 quartz_block 0 
setblock ~24 ~5 ~32 quartz_stairs 7 
setblock ~24 ~5 ~33 quartz_stairs 4 
setblock ~25 ~5 ~21 quartz_stairs 6  
fill ~25 ~5 ~22 ~29 ~5 ~22 quartz_block 0  
fill ~25 ~5 ~32 ~29 ~5 ~32 quartz_block 0  
fill ~25 ~5 ~33 ~26 ~5 ~33 quartz_stairs 7  
fill ~26 ~5 ~20 ~26 ~5 ~21 quartz_stairs 4 
setblock ~26 ~5 ~34 quartz_stairs 4 
setblock ~27 ~5 ~20 quartz_stairs 6  
fill ~27 ~5 ~21 ~27 ~6 ~21 quartz_block 0  
fill ~27 ~5 ~33 ~27 ~6 ~33 quartz_block 0 
setblock ~27 ~5 ~34 quartz_stairs 7  
fill ~28 ~5 ~20 ~28 ~5 ~21 quartz_stairs 5  
fill ~28 ~5 ~33 ~29 ~5 ~33 quartz_stairs 7 
setblock ~28 ~5 ~34 quartz_stairs 5 
setblock ~29 ~5 ~21 quartz_stairs 6 
setblock ~30 ~5 ~21 quartz_stairs 5 
setblock ~30 ~5 ~22 quartz_stairs 6 
setblock ~30 ~5 ~32 quartz_stairs 7 
setblock ~30 ~5 ~33 quartz_stairs 5 
setblock ~31 ~5 ~22 quartz_stairs 5 
setblock ~31 ~5 ~23 quartz_stairs 6 
setblock ~31 ~5 ~31 quartz_stairs 7 
setblock ~31 ~5 ~32 quartz_stairs 5 
setblock ~32 ~5 ~23 quartz_stairs 5  
fill ~32 ~5 ~24 ~33 ~5 ~24 quartz_stairs 6  
fill ~32 ~5 ~30 ~33 ~5 ~30 quartz_stairs 7 
setblock ~32 ~5 ~31 quartz_stairs 5  
fill ~33 ~5 ~25 ~33 ~5 ~26 quartz_stairs 5  
fill ~33 ~5 ~28 ~33 ~5 ~29 quartz_stairs 5 
setblock ~34 ~5 ~26 quartz_stairs 6 
setblock ~34 ~5 ~27 quartz_stairs 5 
setblock ~34 ~5 ~28 quartz_stairs 7  
fill ~19 ~6 ~25 ~20 ~6 ~25 quartz_stairs 6  
fill ~19 ~6 ~26 ~19 ~6 ~28 quartz_stairs 4  
fill ~19 ~6 ~29 ~20 ~6 ~29 quartz_stairs 7  
fill ~20 ~6 ~23 ~20 ~6 ~24 quartz_stairs 4  
fill ~20 ~6 ~26 ~34 ~6 ~26 quartz_block 0  
fill ~20 ~6 ~27 ~22 ~6 ~27 quartz_block 0  
fill ~20 ~6 ~28 ~34 ~6 ~28 quartz_block 0 
setblock ~20 ~6 ~30 quartz_stairs 4 
setblock ~20 ~6 ~31 quartz_stairs 7 
setblock ~21 ~6 ~22 quartz_stairs 4 
setblock ~21 ~6 ~23 quartz_stairs 6  
fill ~21 ~6 ~24 ~33 ~6 ~24 quartz_block 0  
fill ~21 ~6 ~25 ~33 ~6 ~25 quartz_block 0  
fill ~21 ~6 ~29 ~33 ~6 ~29 quartz_block 0  
fill ~21 ~6 ~30 ~33 ~6 ~30 quartz_block 0 
setblock ~21 ~6 ~31 quartz_stairs 4 
setblock ~21 ~6 ~32 quartz_stairs 7 
setblock ~22 ~6 ~21 quartz_stairs 4 
setblock ~22 ~6 ~22 quartz_stairs 6  
fill ~22 ~6 ~23 ~26 ~6 ~23 quartz_block 0  
fill ~22 ~6 ~31 ~26 ~6 ~31 quartz_block 0 
setblock ~22 ~6 ~32 quartz_stairs 4 
setblock ~22 ~6 ~33 quartz_stairs 7 
setblock ~23 ~6 ~20 quartz_stairs 4 
setblock ~23 ~6 ~21 quartz_stairs 6  
fill ~23 ~6 ~22 ~31 ~6 ~22 quartz_block 0 
setblock ~23 ~6 ~27 sea_lantern 0  
fill ~23 ~6 ~32 ~31 ~6 ~32 quartz_block 0  
fill ~23 ~6 ~33 ~23 ~6 ~34 quartz_stairs 4  
fill ~24 ~6 ~20 ~25 ~6 ~20 quartz_stairs 6  
fill ~24 ~6 ~21 ~30 ~6 ~21 quartz_block 0  
fill ~24 ~6 ~27 ~26 ~6 ~27 quartz_block 0  
fill ~24 ~6 ~33 ~30 ~6 ~33 quartz_block 0 
setblock ~24 ~6 ~34 quartz_stairs 7 
setblock ~25 ~6 ~19 quartz_stairs 4  
fill ~25 ~6 ~34 ~25 ~6 ~35 quartz_stairs 4  
fill ~26 ~6 ~19 ~28 ~6 ~19 quartz_stairs 6  
fill ~26 ~6 ~20 ~28 ~6 ~20 quartz_block 0  
fill ~26 ~6 ~34 ~28 ~6 ~34 quartz_block 0  
fill ~26 ~6 ~35 ~28 ~6 ~35 quartz_stairs 7 
setblock ~27 ~6 ~23 sea_lantern 0 
setblock ~27 ~6 ~27 sea_lantern 0 
setblock ~27 ~6 ~31 sea_lantern 0  
fill ~28 ~6 ~23 ~32 ~6 ~23 quartz_block 0  
fill ~28 ~6 ~27 ~30 ~6 ~27 quartz_block 0  
fill ~28 ~6 ~31 ~32 ~6 ~31 quartz_block 0 
setblock ~29 ~6 ~19 quartz_stairs 5  
fill ~29 ~6 ~20 ~31 ~6 ~20 quartz_stairs 6  
fill ~29 ~6 ~34 ~29 ~6 ~35 quartz_stairs 5 
setblock ~30 ~6 ~34 quartz_stairs 7 
setblock ~31 ~6 ~21 quartz_stairs 5 
setblock ~31 ~6 ~27 sea_lantern 0  
fill ~31 ~6 ~33 ~31 ~6 ~34 quartz_stairs 5 
setblock ~32 ~6 ~21 quartz_stairs 6 
setblock ~32 ~6 ~22 quartz_stairs 5  
fill ~32 ~6 ~27 ~34 ~6 ~27 quartz_block 0 
setblock ~32 ~6 ~32 quartz_stairs 5 
setblock ~32 ~6 ~33 quartz_stairs 7 
setblock ~33 ~6 ~22 quartz_stairs 6 
setblock ~33 ~6 ~23 quartz_stairs 5 
setblock ~33 ~6 ~31 quartz_stairs 5 
setblock ~33 ~6 ~32 quartz_stairs 7 
setblock ~34 ~6 ~23 quartz_stairs 6  
fill ~34 ~6 ~24 ~34 ~6 ~25 quartz_stairs 5  
fill ~34 ~6 ~29 ~35 ~6 ~29 quartz_stairs 7 
setblock ~34 ~6 ~30 quartz_stairs 5 
setblock ~34 ~6 ~31 quartz_stairs 7 
setblock ~35 ~6 ~25 quartz_stairs 6  
fill ~35 ~6 ~26 ~35 ~6 ~28 quartz_stairs 5 
setblock ~17 ~7 ~24 quartz_stairs 6  
fill ~17 ~7 ~25 ~17 ~7 ~29 quartz_stairs 4 
setblock ~17 ~7 ~30 quartz_stairs 7 
setblock ~18 ~7 ~22 quartz_stairs 6  
fill ~18 ~7 ~23 ~18 ~7 ~24 quartz_stairs 4  
fill ~18 ~7 ~25 ~18 ~7 ~29 quartz_block 0  
fill ~18 ~7 ~30 ~18 ~7 ~31 quartz_stairs 4 
setblock ~18 ~7 ~32 quartz_stairs 7 
setblock ~19 ~7 ~21 quartz_stairs 6 
setblock ~19 ~7 ~22 quartz_stairs 4 
setblock ~19 ~7 ~23 quartz_block 0 
setblock ~19 ~7 ~24 sea_lantern 0  
fill ~19 ~7 ~25 ~20 ~7 ~25 obsidian 0  
fill ~19 ~7 ~26 ~19 ~7 ~29 obsidian 0 
setblock ~19 ~7 ~30 sea_lantern 0 
setblock ~19 ~7 ~31 quartz_block 0 
setblock ~19 ~7 ~32 quartz_stairs 4 
setblock ~19 ~7 ~33 quartz_stairs 7 
setblock ~20 ~7 ~20 quartz_stairs 6 
setblock ~20 ~7 ~21 quartz_stairs 4 
setblock ~20 ~7 ~22 quartz_block 0  
fill ~20 ~7 ~23 ~21 ~7 ~23 obsidian 0  
fill ~20 ~7 ~24 ~20 ~7 ~23 obsidian 0  
fill ~20 ~7 ~26 ~21 ~7 ~26 prismarine 1  
fill ~20 ~7 ~27 ~22 ~7 ~27 obsidian 0 
setblock ~20 ~7 ~28 prismarine 2  
fill ~20 ~7 ~29 ~20 ~7 ~31 obsidian 0 
setblock ~20 ~7 ~32 quartz_block 0 
setblock ~20 ~7 ~33 quartz_stairs 4 
setblock ~20 ~7 ~34 quartz_stairs 7 
setblock ~21 ~7 ~19 quartz_stairs 6 
setblock ~21 ~7 ~20 quartz_stairs 4 
setblock ~21 ~7 ~21 quartz_block 0  
fill ~21 ~7 ~22 ~22 ~7 ~22 obsidian 0  
fill ~21 ~7 ~24 ~21 ~7 ~26 prismarine 1 
setblock ~21 ~7 ~28 prismarine 1  
fill ~21 ~7 ~29 ~21 ~7 ~30 prismarine 2  
fill ~21 ~7 ~31 ~21 ~7 ~32 obsidian 0 
setblock ~21 ~7 ~33 quartz_block 0 
setblock ~21 ~7 ~34 quartz_stairs 4 
setblock ~21 ~7 ~35 quartz_stairs 7  
fill ~22 ~7 ~18 ~22 ~7 ~19 quartz_stairs 4 
setblock ~22 ~7 ~20 quartz_block 0  
fill ~22 ~7 ~21 ~23 ~7 ~21 obsidian 0  
fill ~22 ~7 ~23 ~22 ~7 ~24 prismarine 2 
setblock ~22 ~7 ~25 prismarine 1  
fill ~22 ~7 ~26 ~24 ~7 ~26 obsidian 0  
fill ~22 ~7 ~28 ~24 ~7 ~28 obsidian 0  
fill ~22 ~7 ~29 ~22 ~7 ~30 prismarine 1 
setblock ~22 ~7 ~31 prismarine 2  
fill ~22 ~7 ~32 ~22 ~7 ~33 obsidian 0 
setblock ~22 ~7 ~34 quartz_block 0  
fill ~22 ~7 ~35 ~22 ~7 ~36 quartz_stairs 4 
setblock ~23 ~7 ~18 quartz_stairs 6 
setblock ~23 ~7 ~19 quartz_block 0  
fill ~23 ~7 ~20 ~25 ~7 ~20 obsidian 0 
setblock ~23 ~7 ~22 prismarine 2 
setblock ~23 ~7 ~23 prismarine 1  
fill ~23 ~7 ~24 ~23 ~7 ~25 prismarine 2 
setblock ~23 ~7 ~27 glass 0  
fill ~23 ~7 ~29 ~26 ~7 ~29 prismarine 2  
fill ~23 ~7 ~30 ~23 ~7 ~29 prismarine 2 
setblock ~23 ~7 ~31 prismarine 1  
fill ~23 ~7 ~32 ~24 ~7 ~32 prismarine 2  
fill ~23 ~7 ~33 ~23 ~7 ~34 obsidian 0 
setblock ~23 ~7 ~35 quartz_block 0 
setblock ~23 ~7 ~36 quartz_stairs 7  
fill ~24 ~7 ~17 ~24 ~7 ~18 quartz_stairs 4 
setblock ~24 ~7 ~19 sea_lantern 0  
fill ~24 ~7 ~21 ~25 ~7 ~21 prismarine 2  
fill ~24 ~7 ~22 ~25 ~7 ~22 prismarine 1  
fill ~24 ~7 ~23 ~25 ~7 ~23 prismarine 2  
fill ~24 ~7 ~24 ~24 ~7 ~25 prismarine 1  
fill ~24 ~7 ~27 ~26 ~7 ~27 obsidian 0  
fill ~24 ~7 ~30 ~25 ~7 ~30 prismarine 1  
fill ~24 ~7 ~31 ~25 ~7 ~31 prismarine 2  
fill ~24 ~7 ~33 ~26 ~7 ~33 prismarine 1  
fill ~24 ~7 ~34 ~25 ~7 ~34 obsidian 0 
setblock ~24 ~7 ~35 sea_lantern 0  
fill ~24 ~7 ~36 ~24 ~7 ~37 quartz_stairs 4  
fill ~25 ~7 ~17 ~29 ~7 ~17 quartz_stairs 6  
fill ~25 ~7 ~18 ~29 ~7 ~18 quartz_block 0  
fill ~25 ~7 ~19 ~29 ~7 ~19 obsidian 0  
fill ~25 ~7 ~24 ~25 ~7 ~26 prismarine 2 
setblock ~25 ~7 ~28 prismarine 2 
setblock ~25 ~7 ~32 prismarine 1  
fill ~25 ~7 ~35 ~29 ~7 ~35 obsidian 0  
fill ~25 ~7 ~36 ~29 ~7 ~36 quartz_block 0  
fill ~25 ~7 ~37 ~29 ~7 ~37 quartz_stairs 7 
setblock ~26 ~7 ~20 prismarine 2  
fill ~26 ~7 ~21 ~26 ~8 ~21 prismarine 1  
fill ~26 ~7 ~22 ~28 ~7 ~22 obsidian 0  
fill ~26 ~7 ~23 ~26 ~7 ~24 obsidian 0 
setblock ~26 ~7 ~25 prismarine 2  
fill ~26 ~7 ~26 ~28 ~7 ~26 obsidian 0  
fill ~26 ~7 ~28 ~28 ~7 ~28 obsidian 0  
fill ~26 ~7 ~30 ~28 ~7 ~30 obsidian 0  
fill ~26 ~7 ~31 ~26 ~7 ~32 obsidian 0 
setblock ~26 ~7 ~34 prismarine 1  
fill ~27 ~7 ~20 ~27 ~7 ~22 obsidian 0 
setblock ~27 ~7 ~23 glass 0  
fill ~27 ~7 ~24 ~28 ~7 ~24 obsidian 0  
fill ~27 ~7 ~25 ~27 ~7 ~24 obsidian 0 
setblock ~27 ~7 ~27 glass 0 
setblock ~27 ~7 ~29 obsidian 0 
setblock ~27 ~7 ~31 glass 0  
fill ~27 ~7 ~32 ~28 ~7 ~32 obsidian 0  
fill ~27 ~7 ~33 ~27 ~7 ~35 obsidian 0  
fill ~28 ~7 ~20 ~28 ~7 ~21 prismarine 1 
setblock ~28 ~7 ~23 obsidian 0  
fill ~28 ~7 ~25 ~31 ~7 ~25 prismarine 2  
fill ~28 ~7 ~27 ~30 ~7 ~27 obsidian 0  
fill ~28 ~7 ~29 ~29 ~7 ~29 prismarine 2 
setblock ~28 ~7 ~31 obsidian 0 
setblock ~28 ~7 ~33 prismarine 1 
setblock ~28 ~7 ~34 prismarine 2  
fill ~29 ~7 ~20 ~31 ~7 ~20 obsidian 0  
fill ~29 ~7 ~21 ~30 ~7 ~21 prismarine 1  
fill ~29 ~7 ~22 ~29 ~7 ~21 prismarine 1  
fill ~29 ~7 ~23 ~30 ~7 ~23 prismarine 2  
fill ~29 ~7 ~24 ~30 ~7 ~24 prismarine 1 
setblock ~29 ~7 ~26 prismarine 2 
setblock ~29 ~7 ~28 prismarine 2  
fill ~29 ~7 ~30 ~29 ~7 ~31 prismarine 2  
fill ~29 ~7 ~32 ~30 ~7 ~32 prismarine 1  
fill ~29 ~7 ~33 ~30 ~7 ~33 prismarine 2  
fill ~29 ~7 ~34 ~31 ~7 ~34 obsidian 0 
setblock ~30 ~7 ~17 quartz_stairs 5  
fill ~30 ~7 ~18 ~31 ~7 ~18 quartz_stairs 6 
setblock ~30 ~7 ~19 sea_lantern 0  
fill ~30 ~7 ~22 ~31 ~7 ~22 prismarine 2  
fill ~30 ~7 ~26 ~32 ~7 ~26 obsidian 0  
fill ~30 ~7 ~28 ~32 ~7 ~28 obsidian 0  
fill ~30 ~7 ~29 ~30 ~7 ~30 prismarine 1 
setblock ~30 ~7 ~31 prismarine 2 
setblock ~30 ~7 ~35 sea_lantern 0  
fill ~30 ~7 ~36 ~30 ~7 ~37 quartz_stairs 5 
setblock ~31 ~7 ~19 quartz_block 0  
fill ~31 ~7 ~21 ~32 ~7 ~21 obsidian 0 
setblock ~31 ~7 ~23 prismarine 1 
setblock ~31 ~7 ~24 prismarine 2 
setblock ~31 ~7 ~27 glass 0  
fill ~31 ~7 ~29 ~31 ~7 ~30 prismarine 2 
setblock ~31 ~7 ~31 prismarine 1 
setblock ~31 ~7 ~32 prismarine 2  
fill ~31 ~7 ~33 ~32 ~7 ~33 obsidian 0 
setblock ~31 ~7 ~35 quartz_block 0  
fill ~31 ~7 ~36 ~32 ~7 ~36 quartz_stairs 7 
setblock ~32 ~7 ~18 quartz_stairs 5 
setblock ~32 ~7 ~19 quartz_stairs 6 
setblock ~32 ~7 ~20 quartz_block 0  
fill ~32 ~7 ~22 ~33 ~7 ~22 obsidian 0 
setblock ~32 ~7 ~23 prismarine 2  
fill ~32 ~7 ~24 ~32 ~7 ~25 prismarine 1  
fill ~32 ~7 ~27 ~35 ~7 ~27 obsidian 0  
fill ~32 ~7 ~29 ~33 ~7 ~29 prismarine 1  
fill ~32 ~7 ~30 ~32 ~7 ~31 prismarine 2  
fill ~32 ~7 ~32 ~33 ~7 ~32 obsidian 0 
setblock ~32 ~7 ~34 quartz_block 0 
setblock ~32 ~7 ~35 quartz_stairs 5 
setblock ~33 ~7 ~19 quartz_stairs 5 
setblock ~33 ~7 ~20 quartz_stairs 6 
setblock ~33 ~7 ~21 quartz_block 0  
fill ~33 ~7 ~23 ~34 ~7 ~23 obsidian 0  
fill ~33 ~7 ~24 ~33 ~7 ~25 prismarine 2 
setblock ~33 ~7 ~26 prismarine 1  
fill ~33 ~7 ~28 ~34 ~7 ~28 prismarine 1 
setblock ~33 ~7 ~30 prismarine 1  
fill ~33 ~7 ~31 ~34 ~7 ~31 obsidian 0 
setblock ~33 ~7 ~33 quartz_block 0 
setblock ~33 ~7 ~34 quartz_stairs 5 
setblock ~33 ~7 ~35 quartz_stairs 7 
setblock ~34 ~7 ~20 quartz_stairs 5 
setblock ~34 ~7 ~21 quartz_stairs 6 
setblock ~34 ~7 ~22 quartz_block 0  
fill ~34 ~7 ~24 ~34 ~7 ~25 obsidian 0 
setblock ~34 ~7 ~26 prismarine 2  
fill ~34 ~7 ~29 ~35 ~7 ~29 obsidian 0  
fill ~34 ~7 ~30 ~34 ~7 ~29 obsidian 0 
setblock ~34 ~7 ~32 quartz_block 0 
setblock ~34 ~7 ~33 quartz_stairs 5 
setblock ~34 ~7 ~34 quartz_stairs 7 
setblock ~35 ~7 ~21 quartz_stairs 5 
setblock ~35 ~7 ~22 quartz_stairs 6 
setblock ~35 ~7 ~23 quartz_block 0 
setblock ~35 ~7 ~24 sea_lantern 0  
fill ~35 ~7 ~25 ~35 ~7 ~29 obsidian 0 
setblock ~35 ~7 ~30 sea_lantern 0 
setblock ~35 ~7 ~31 quartz_block 0 
setblock ~35 ~7 ~32 quartz_stairs 5 
setblock ~35 ~7 ~33 quartz_stairs 7  
fill ~36 ~7 ~22 ~36 ~7 ~23 quartz_stairs 5  
fill ~36 ~7 ~24 ~37 ~7 ~24 quartz_stairs 6  
fill ~36 ~7 ~25 ~36 ~7 ~29 quartz_block 0  
fill ~36 ~7 ~30 ~36 ~7 ~31 quartz_stairs 5 
setblock ~36 ~7 ~32 quartz_stairs 7  
fill ~37 ~7 ~25 ~37 ~7 ~29 quartz_stairs 5 
setblock ~37 ~7 ~30 quartz_stairs 7 
setblock ~18 ~8 ~27 quartz_block 13  
fill ~19 ~8 ~25 ~19 ~12 ~25 glass 0  
fill ~19 ~8 ~26 ~19 ~12 ~26 glass 2  
fill ~19 ~8 ~27 ~19 ~12 ~27 glass 0  
fill ~19 ~8 ~28 ~19 ~12 ~28 glass 2  
fill ~19 ~8 ~29 ~19 ~12 ~29 glass 0  
fill ~20 ~8 ~23 ~20 ~12 ~23 glass 0  
fill ~20 ~8 ~24 ~20 ~12 ~24 glass 2  
fill ~20 ~8 ~30 ~20 ~12 ~30 glass 2  
fill ~20 ~8 ~31 ~20 ~12 ~31 glass 0 
setblock ~21 ~8 ~21 quartz_block 13  
fill ~21 ~8 ~22 ~21 ~12 ~22 glass 2 
setblock ~21 ~8 ~27 prismarine 1  
fill ~21 ~8 ~32 ~21 ~12 ~32 glass 2 
setblock ~21 ~8 ~33 quartz_block 13  
fill ~22 ~8 ~21 ~22 ~12 ~21 glass 0  
fill ~22 ~8 ~33 ~22 ~12 ~33 glass 0  
fill ~23 ~8 ~20 ~23 ~12 ~20 glass 2  
fill ~23 ~8 ~23 ~23 ~10 ~23 leaves 11  
fill ~23 ~8 ~34 ~23 ~12 ~34 glass 2  
fill ~24 ~8 ~20 ~24 ~12 ~20 glass 0  
fill ~24 ~8 ~26 ~24 ~9 ~26 prismarine 1  
fill ~24 ~8 ~34 ~24 ~12 ~34 glass 0  
fill ~25 ~8 ~19 ~25 ~12 ~19 glass 2  
fill ~25 ~8 ~29 ~25 ~16 ~29 leaves 11  
fill ~25 ~8 ~35 ~25 ~12 ~35 glass 2  
fill ~26 ~8 ~19 ~26 ~12 ~19 glass 0  
fill ~26 ~8 ~35 ~26 ~12 ~35 glass 0 
setblock ~27 ~8 ~18 quartz_block 13  
fill ~27 ~8 ~19 ~27 ~12 ~19 glass 2 
setblock ~27 ~8 ~21 prismarine 1  
fill ~27 ~8 ~33 ~27 ~9 ~33 prismarine 1  
fill ~27 ~8 ~35 ~27 ~12 ~35 glass 2 
setblock ~27 ~8 ~36 quartz_block 13  
fill ~28 ~8 ~19 ~28 ~12 ~19 glass 0 
setblock ~28 ~8 ~24 prismarine 1  
fill ~28 ~8 ~28 ~28 ~10 ~28 prismarine 1  
fill ~28 ~8 ~35 ~28 ~12 ~35 glass 0  
fill ~29 ~8 ~19 ~29 ~12 ~19 glass 2  
fill ~29 ~8 ~35 ~29 ~12 ~35 glass 2  
fill ~30 ~8 ~20 ~30 ~12 ~20 glass 0  
fill ~30 ~8 ~34 ~30 ~12 ~34 glass 0  
fill ~31 ~8 ~20 ~31 ~12 ~20 glass 2  
fill ~31 ~8 ~24 ~31 ~13 ~24 leaves 11  
fill ~31 ~8 ~34 ~31 ~12 ~34 glass 2  
fill ~32 ~8 ~21 ~32 ~12 ~21 glass 0  
fill ~32 ~8 ~33 ~32 ~12 ~33 glass 0 
setblock ~33 ~8 ~21 quartz_block 13  
fill ~33 ~8 ~22 ~33 ~12 ~22 glass 2  
fill ~33 ~8 ~32 ~33 ~12 ~32 glass 2 
setblock ~33 ~8 ~33 quartz_block 13  
fill ~34 ~8 ~23 ~34 ~12 ~23 glass 0  
fill ~34 ~8 ~24 ~34 ~12 ~24 glass 2  
fill ~34 ~8 ~30 ~34 ~12 ~30 glass 2  
fill ~34 ~8 ~31 ~34 ~12 ~31 glass 0  
fill ~35 ~8 ~25 ~35 ~12 ~25 glass 0  
fill ~35 ~8 ~26 ~35 ~12 ~26 glass 2  
fill ~35 ~8 ~27 ~35 ~12 ~27 glass 0  
fill ~35 ~8 ~28 ~35 ~12 ~28 glass 2  
fill ~35 ~8 ~29 ~35 ~12 ~29 glass 0 
setblock ~36 ~8 ~27 quartz_block 13  
fill ~18 ~9 ~27 ~18 ~11 ~27 quartz_block 2  
fill ~21 ~9 ~21 ~21 ~11 ~21 quartz_block 2  
fill ~21 ~9 ~33 ~21 ~11 ~33 quartz_block 2  
fill ~27 ~9 ~18 ~27 ~11 ~18 quartz_block 2 
setblock ~27 ~9 ~32 prismarine 1  
fill ~27 ~9 ~36 ~27 ~11 ~36 quartz_block 2  
fill ~33 ~9 ~21 ~33 ~11 ~21 quartz_block 2  
fill ~33 ~9 ~33 ~33 ~11 ~33 quartz_block 2  
fill ~36 ~9 ~27 ~36 ~11 ~27 quartz_block 2 
setblock ~18 ~12 ~27 quartz_block 13 
setblock ~21 ~12 ~21 quartz_block 13 
setblock ~21 ~12 ~33 quartz_block 13 
setblock ~27 ~12 ~18 quartz_block 13 
setblock ~27 ~12 ~36 quartz_block 13 
setblock ~33 ~12 ~21 quartz_block 13 
setblock ~33 ~12 ~33 quartz_block 13 
setblock ~36 ~12 ~27 quartz_block 13  
fill ~18 ~13 ~27 ~19 ~13 ~27 obsidian 0  
fill ~19 ~13 ~25 ~19 ~13 ~29 obsidian 0  
fill ~20 ~13 ~23 ~20 ~13 ~24 obsidian 0  
fill ~20 ~13 ~30 ~20 ~13 ~31 obsidian 0  
fill ~21 ~13 ~21 ~22 ~13 ~21 obsidian 0  
fill ~21 ~13 ~22 ~21 ~13 ~21 obsidian 0  
fill ~21 ~13 ~32 ~21 ~13 ~33 obsidian 0 
setblock ~22 ~13 ~33 obsidian 0  
fill ~23 ~13 ~20 ~24 ~13 ~20 obsidian 0  
fill ~23 ~13 ~34 ~24 ~13 ~34 obsidian 0  
fill ~25 ~13 ~19 ~29 ~13 ~19 obsidian 0  
fill ~25 ~13 ~35 ~29 ~13 ~35 obsidian 0 
setblock ~27 ~13 ~18 obsidian 0 
setblock ~27 ~13 ~36 obsidian 0  
fill ~30 ~13 ~20 ~31 ~13 ~20 obsidian 0  
fill ~30 ~13 ~34 ~31 ~13 ~34 obsidian 0  
fill ~32 ~13 ~21 ~33 ~13 ~21 obsidian 0  
fill ~32 ~13 ~33 ~33 ~13 ~33 obsidian 0 
setblock ~33 ~13 ~22 obsidian 0 
setblock ~33 ~13 ~32 obsidian 0  
fill ~34 ~13 ~23 ~34 ~13 ~24 obsidian 0  
fill ~34 ~13 ~30 ~34 ~13 ~31 obsidian 0  
fill ~35 ~13 ~25 ~35 ~13 ~29 obsidian 0 
setblock ~36 ~13 ~27 obsidian 0 
setblock ~18 ~14 ~27 beacon 0  
fill ~19 ~14 ~25 ~19 ~14 ~29 glass 0  
fill ~20 ~14 ~23 ~20 ~14 ~24 glass 0  
fill ~20 ~14 ~30 ~20 ~14 ~31 glass 0 
setblock ~21 ~14 ~21 beacon 0 
setblock ~21 ~14 ~22 glass 0 
setblock ~21 ~14 ~32 glass 0 
setblock ~21 ~14 ~33 beacon 0 
setblock ~22 ~14 ~21 glass 0 
setblock ~22 ~14 ~33 glass 0  
fill ~23 ~14 ~20 ~24 ~14 ~20 glass 0  
fill ~23 ~14 ~34 ~24 ~14 ~34 glass 0  
fill ~25 ~14 ~19 ~29 ~14 ~19 glass 0  
fill ~25 ~14 ~35 ~29 ~14 ~35 glass 0 
setblock ~27 ~14 ~18 beacon 0 
setblock ~27 ~14 ~36 beacon 0  
fill ~30 ~14 ~20 ~31 ~14 ~20 glass 0  
fill ~30 ~14 ~34 ~31 ~14 ~34 glass 0 
setblock ~32 ~14 ~21 glass 0 
setblock ~32 ~14 ~33 glass 0 
setblock ~33 ~14 ~21 beacon 0 
setblock ~33 ~14 ~22 glass 0 
setblock ~33 ~14 ~32 glass 0 
setblock ~33 ~14 ~33 beacon 0  
fill ~34 ~14 ~23 ~34 ~14 ~24 glass 0  
fill ~34 ~14 ~30 ~34 ~14 ~31 glass 0  
fill ~35 ~14 ~25 ~35 ~14 ~29 glass 0 
setblock ~36 ~14 ~27 beacon 0  
fill ~18 ~15 ~27 ~19 ~15 ~27 obsidian 0  
fill ~19 ~15 ~25 ~19 ~15 ~29 obsidian 0  
fill ~20 ~15 ~23 ~20 ~15 ~24 obsidian 0  
fill ~20 ~15 ~30 ~20 ~15 ~31 obsidian 0  
fill ~21 ~15 ~21 ~22 ~15 ~21 obsidian 0  
fill ~21 ~15 ~22 ~21 ~15 ~21 obsidian 0  
fill ~21 ~15 ~32 ~21 ~15 ~33 obsidian 0 
setblock ~22 ~15 ~33 obsidian 0  
fill ~23 ~15 ~20 ~24 ~15 ~20 obsidian 0  
fill ~23 ~15 ~34 ~24 ~15 ~34 obsidian 0  
fill ~25 ~15 ~19 ~29 ~15 ~19 obsidian 0  
fill ~25 ~15 ~35 ~29 ~15 ~35 obsidian 0 
setblock ~27 ~15 ~18 obsidian 0 
setblock ~27 ~15 ~36 obsidian 0  
fill ~30 ~15 ~20 ~31 ~15 ~20 obsidian 0  
fill ~30 ~15 ~34 ~31 ~15 ~34 obsidian 0  
fill ~32 ~15 ~21 ~33 ~15 ~21 obsidian 0  
fill ~32 ~15 ~33 ~33 ~15 ~33 obsidian 0 
setblock ~33 ~15 ~22 obsidian 0 
setblock ~33 ~15 ~32 obsidian 0  
fill ~34 ~15 ~23 ~34 ~15 ~24 obsidian 0  
fill ~34 ~15 ~30 ~34 ~15 ~31 obsidian 0  
fill ~35 ~15 ~25 ~35 ~15 ~29 obsidian 0 
setblock ~36 ~15 ~27 obsidian 0 
setblock ~18 ~16 ~27 quartz_block 13  
fill ~19 ~16 ~25 ~19 ~20 ~25 glass 0  
fill ~19 ~16 ~26 ~19 ~20 ~26 glass 2  
fill ~19 ~16 ~27 ~19 ~20 ~27 glass 0  
fill ~19 ~16 ~28 ~19 ~20 ~28 glass 2  
fill ~19 ~16 ~29 ~19 ~20 ~29 glass 0  
fill ~20 ~16 ~23 ~20 ~20 ~23 glass 0  
fill ~20 ~16 ~24 ~20 ~20 ~24 glass 2  
fill ~20 ~16 ~30 ~20 ~20 ~30 glass 2  
fill ~20 ~16 ~31 ~20 ~20 ~31 glass 0 
setblock ~21 ~16 ~21 quartz_block 13  
fill ~21 ~16 ~22 ~21 ~20 ~22 glass 2  
fill ~21 ~16 ~32 ~21 ~20 ~32 glass 2 
setblock ~21 ~16 ~33 quartz_block 13  
fill ~22 ~16 ~21 ~22 ~20 ~21 glass 0  
fill ~22 ~16 ~33 ~22 ~20 ~33 glass 0  
fill ~23 ~16 ~20 ~23 ~20 ~20 glass 2  
fill ~23 ~16 ~34 ~23 ~20 ~34 glass 2  
fill ~24 ~16 ~20 ~24 ~20 ~20 glass 0  
fill ~24 ~16 ~34 ~24 ~20 ~34 glass 0  
fill ~25 ~16 ~19 ~25 ~20 ~19 glass 2  
fill ~25 ~16 ~35 ~25 ~20 ~35 glass 2  
fill ~26 ~16 ~19 ~26 ~20 ~19 glass 0  
fill ~26 ~16 ~35 ~26 ~20 ~35 glass 0 
setblock ~27 ~16 ~18 quartz_block 13  
fill ~27 ~16 ~19 ~27 ~20 ~19 glass 2  
fill ~27 ~16 ~35 ~27 ~20 ~35 glass 2 
setblock ~27 ~16 ~36 quartz_block 13  
fill ~28 ~16 ~19 ~28 ~20 ~19 glass 0  
fill ~28 ~16 ~35 ~28 ~20 ~35 glass 0  
fill ~29 ~16 ~19 ~29 ~20 ~19 glass 2  
fill ~29 ~16 ~35 ~29 ~20 ~35 glass 2  
fill ~30 ~16 ~20 ~30 ~20 ~20 glass 0  
fill ~30 ~16 ~34 ~30 ~20 ~34 glass 0  
fill ~31 ~16 ~20 ~31 ~20 ~20 glass 2  
fill ~31 ~16 ~34 ~31 ~20 ~34 glass 2  
fill ~32 ~16 ~21 ~32 ~20 ~21 glass 0  
fill ~32 ~16 ~33 ~32 ~20 ~33 glass 0 
setblock ~33 ~16 ~21 quartz_block 13  
fill ~33 ~16 ~22 ~33 ~20 ~22 glass 2  
fill ~33 ~16 ~32 ~33 ~20 ~32 glass 2 
setblock ~33 ~16 ~33 quartz_block 13  
fill ~34 ~16 ~23 ~34 ~20 ~23 glass 0  
fill ~34 ~16 ~24 ~34 ~20 ~24 glass 2  
fill ~34 ~16 ~30 ~34 ~20 ~30 glass 2  
fill ~34 ~16 ~31 ~34 ~20 ~31 glass 0  
fill ~35 ~16 ~25 ~35 ~20 ~25 glass 0  
fill ~35 ~16 ~26 ~35 ~20 ~26 glass 2  
fill ~35 ~16 ~27 ~35 ~20 ~27 glass 0  
fill ~35 ~16 ~28 ~35 ~20 ~28 glass 2  
fill ~35 ~16 ~29 ~35 ~20 ~29 glass 0 
setblock ~36 ~16 ~27 quartz_block 13  
fill ~18 ~17 ~27 ~18 ~19 ~27 quartz_block 2  
fill ~21 ~17 ~21 ~21 ~19 ~21 quartz_block 2  
fill ~21 ~17 ~33 ~21 ~19 ~33 quartz_block 2 
setblock ~25 ~17 ~29 leaves 15  
fill ~27 ~17 ~18 ~27 ~19 ~18 quartz_block 2  
fill ~27 ~17 ~36 ~27 ~19 ~36 quartz_block 2  
fill ~33 ~17 ~21 ~33 ~19 ~21 quartz_block 2  
fill ~33 ~17 ~33 ~33 ~19 ~33 quartz_block 2  
fill ~36 ~17 ~27 ~36 ~19 ~27 quartz_block 2 
setblock ~18 ~20 ~27 quartz_block 13 
setblock ~21 ~20 ~21 quartz_block 13 
setblock ~21 ~20 ~33 quartz_block 13 
setblock ~27 ~20 ~18 quartz_block 13 
setblock ~27 ~20 ~36 quartz_block 13 
setblock ~33 ~20 ~21 quartz_block 13 
setblock ~33 ~20 ~33 quartz_block 13 
setblock ~36 ~20 ~27 quartz_block 13  
fill ~-35 ~21 ~26 ~-33 ~21 ~26 stone_slab 14  
fill ~-35 ~21 ~27 ~-35 ~21 ~28 stone_slab 14 
setblock ~-34 ~21 ~27 sea_lantern 0  
fill ~-34 ~21 ~28 ~-33 ~21 ~28 stone_slab 14 
setblock ~-33 ~21 ~27 stone_slab 14  
fill ~-17 ~21 ~-17 ~-15 ~21 ~-17 stone_slab 14  
fill ~-17 ~21 ~-16 ~-17 ~21 ~-15 stone_slab 14  
fill ~-17 ~21 ~69 ~-15 ~21 ~69 stone_slab 14  
fill ~-17 ~21 ~70 ~-17 ~21 ~71 stone_slab 14 
setblock ~-16 ~21 ~-16 sea_lantern 0  
fill ~-16 ~21 ~-15 ~-15 ~21 ~-15 stone_slab 14 
setblock ~-16 ~21 ~70 sea_lantern 0  
fill ~-16 ~21 ~71 ~-15 ~21 ~71 stone_slab 14 
setblock ~-15 ~21 ~-16 stone_slab 14 
setblock ~-15 ~21 ~70 stone_slab 14 
setblock ~14 ~21 ~25 quartz_stairs 6  
fill ~14 ~21 ~26 ~14 ~21 ~29 quartz_stairs 4  
fill ~15 ~21 ~21 ~16 ~21 ~21 quartz_stairs 6  
fill ~15 ~21 ~22 ~15 ~21 ~25 quartz_stairs 4  
fill ~15 ~21 ~26 ~18 ~21 ~26 quartz_block 0  
fill ~15 ~21 ~27 ~18 ~21 ~27 quartz_block 0  
fill ~15 ~21 ~28 ~18 ~21 ~28 quartz_block 0 
setblock ~15 ~21 ~29 quartz_stairs 7  
fill ~15 ~21 ~30 ~15 ~21 ~32 quartz_stairs 4 
setblock ~15 ~21 ~33 quartz_stairs 7  
fill ~16 ~21 ~19 ~17 ~21 ~19 quartz_stairs 6 
setblock ~16 ~21 ~20 quartz_stairs 4  
fill ~16 ~21 ~22 ~20 ~21 ~22 quartz_block 0  
fill ~16 ~21 ~23 ~19 ~21 ~23 quartz_block 0  
fill ~16 ~21 ~24 ~19 ~21 ~24 quartz_block 0  
fill ~16 ~21 ~25 ~18 ~21 ~25 quartz_block 0  
fill ~16 ~21 ~29 ~18 ~21 ~29 quartz_block 0  
fill ~16 ~21 ~30 ~19 ~21 ~30 quartz_block 0  
fill ~16 ~21 ~31 ~19 ~21 ~31 quartz_block 0  
fill ~16 ~21 ~32 ~20 ~21 ~32 quartz_block 0  
fill ~16 ~21 ~33 ~16 ~21 ~35 quartz_stairs 4  
fill ~17 ~21 ~17 ~19 ~21 ~17 quartz_stairs 6 
setblock ~17 ~21 ~18 quartz_stairs 4  
fill ~17 ~21 ~20 ~22 ~21 ~20 quartz_block 0  
fill ~17 ~21 ~21 ~21 ~21 ~21 quartz_block 0  
fill ~17 ~21 ~33 ~21 ~21 ~33 quartz_block 0  
fill ~17 ~21 ~34 ~22 ~21 ~34 quartz_block 0 
setblock ~17 ~21 ~35 quartz_stairs 7  
fill ~17 ~21 ~36 ~17 ~21 ~37 quartz_stairs 4  
fill ~18 ~21 ~18 ~36 ~21 ~18 quartz_block 0  
fill ~18 ~21 ~19 ~24 ~21 ~19 quartz_block 0  
fill ~18 ~21 ~35 ~24 ~21 ~35 quartz_block 0  
fill ~18 ~21 ~36 ~36 ~21 ~36 quartz_block 0  
fill ~18 ~21 ~37 ~19 ~21 ~37 quartz_stairs 7 
setblock ~19 ~21 ~16 quartz_stairs 4  
fill ~19 ~21 ~25 ~20 ~21 ~25 obsidian 0  
fill ~19 ~21 ~26 ~19 ~21 ~29 obsidian 0 
setblock ~19 ~21 ~38 quartz_stairs 4  
fill ~20 ~21 ~16 ~21 ~21 ~16 quartz_stairs 6  
fill ~20 ~21 ~17 ~34 ~21 ~17 quartz_block 0  
fill ~20 ~21 ~23 ~21 ~21 ~23 obsidian 0  
fill ~20 ~21 ~24 ~20 ~21 ~23 obsidian 0  
fill ~20 ~21 ~26 ~20 ~21 ~28 quartz_block 10  
fill ~20 ~21 ~29 ~20 ~21 ~31 obsidian 0  
fill ~20 ~21 ~37 ~34 ~21 ~37 quartz_block 0  
fill ~20 ~21 ~38 ~21 ~21 ~38 quartz_stairs 7 
setblock ~21 ~21 ~15 quartz_stairs 4  
fill ~21 ~21 ~22 ~22 ~21 ~22 obsidian 0  
fill ~21 ~21 ~24 ~21 ~21 ~25 quartz_block 10  
fill ~21 ~21 ~29 ~21 ~21 ~30 quartz_block 10  
fill ~21 ~21 ~31 ~21 ~21 ~32 obsidian 0 
setblock ~21 ~21 ~39 quartz_stairs 4  
fill ~22 ~21 ~15 ~25 ~21 ~15 quartz_stairs 6  
fill ~22 ~21 ~16 ~32 ~21 ~16 quartz_block 0  
fill ~22 ~21 ~21 ~23 ~21 ~21 obsidian 0 
setblock ~22 ~21 ~23 quartz_block 13 
setblock ~22 ~21 ~31 quartz_block 13  
fill ~22 ~21 ~32 ~22 ~21 ~33 obsidian 0  
fill ~22 ~21 ~38 ~32 ~21 ~38 quartz_block 0  
fill ~22 ~21 ~39 ~24 ~21 ~39 quartz_stairs 7  
fill ~23 ~21 ~20 ~25 ~21 ~20 obsidian 0 
setblock ~23 ~21 ~22 quartz_block 13 
setblock ~23 ~21 ~32 quartz_block 13  
fill ~23 ~21 ~33 ~23 ~21 ~34 obsidian 0  
fill ~24 ~21 ~21 ~25 ~21 ~21 quartz_block 6  
fill ~24 ~21 ~33 ~25 ~21 ~33 quartz_block 6  
fill ~24 ~21 ~34 ~25 ~21 ~34 obsidian 0 
setblock ~25 ~21 ~14 quartz_stairs 4  
fill ~25 ~21 ~19 ~29 ~21 ~19 obsidian 0  
fill ~25 ~21 ~35 ~29 ~21 ~35 obsidian 0  
fill ~25 ~21 ~39 ~25 ~21 ~40 quartz_stairs 4  
fill ~26 ~21 ~-35 ~28 ~21 ~-35 stone_slab 14  
fill ~26 ~21 ~-34 ~26 ~21 ~-33 stone_slab 14  
fill ~26 ~21 ~14 ~28 ~21 ~14 quartz_stairs 6  
fill ~26 ~21 ~15 ~28 ~21 ~15 quartz_block 0  
fill ~26 ~21 ~20 ~28 ~21 ~20 quartz_block 6  
fill ~26 ~21 ~34 ~28 ~21 ~34 quartz_block 6  
fill ~26 ~21 ~39 ~28 ~21 ~39 quartz_block 0  
fill ~26 ~21 ~40 ~28 ~21 ~40 quartz_stairs 7  
fill ~26 ~21 ~87 ~28 ~21 ~87 stone_slab 14  
fill ~26 ~21 ~88 ~26 ~21 ~89 stone_slab 14 
setblock ~27 ~21 ~-34 sea_lantern 0  
fill ~27 ~21 ~-33 ~28 ~21 ~-33 stone_slab 14 
setblock ~27 ~21 ~88 sea_lantern 0  
fill ~27 ~21 ~89 ~28 ~21 ~89 stone_slab 14 
setblock ~28 ~21 ~-34 stone_slab 14 
setblock ~28 ~21 ~88 stone_slab 14  
fill ~29 ~21 ~14 ~29 ~21 ~15 quartz_stairs 5  
fill ~29 ~21 ~20 ~31 ~21 ~20 obsidian 0  
fill ~29 ~21 ~21 ~30 ~21 ~21 quartz_block 6  
fill ~29 ~21 ~33 ~30 ~21 ~33 quartz_block 6  
fill ~29 ~21 ~34 ~31 ~21 ~34 obsidian 0  
fill ~29 ~21 ~39 ~32 ~21 ~39 quartz_stairs 7 
setblock ~29 ~21 ~40 quartz_stairs 5  
fill ~30 ~21 ~15 ~33 ~21 ~15 quartz_stairs 6  
fill ~30 ~21 ~19 ~36 ~21 ~19 quartz_block 0  
fill ~30 ~21 ~35 ~36 ~21 ~35 quartz_block 0  
summon minecraft:pig ~-11.4975585938 ~111.0 ~27.7924804688 
summon minecraft:pig ~-9.54956054688 ~111.0 ~29.2338867188 
summon minecraft:pig ~5.6943359375 ~214.0 ~-56.8037109375 
summon minecraft:pig ~4.2197265625 ~214.0 ~-55.6560058594 
summon minecraft:pig ~2.44311523438 ~214.0 ~-57.5422363281 
summon minecraft:pig ~3.08911132812 ~214.0 ~-55.447265625 
summon minecraft:pig ~5.52465820312 ~214.0 ~-57.9365234375 
summon minecraft:pig ~2.83422851562 ~214.0 ~-59.7463378906 
summon minecraft:pig ~6.572265625 ~214.0 ~-59.9250488281 
summon minecraft:pig ~6.67041015625 ~214.0 ~-56.1215820312 
summon minecraft:llama ~3.93823242188 ~214.0 ~-49.7661132812 
summon minecraft:mule ~2.3232421875 ~214.0 ~-44.6767578125 
summon minecraft:llama ~2.546875 ~214.0 ~-49.8859863281 
summon minecraft:llama ~2.580078125 ~214.0 ~-48.9189453125 
summon minecraft:donkey ~2.58349609375 ~214.0 ~-43.2458496094 
summon minecraft:donkey ~2.3232421875 ~214.0 ~-41.3425292969 
summon minecraft:donkey ~4.04248046875 ~214.0 ~-41.7795410156 
summon minecraft:llama ~5.00659179688 ~214.0 ~-48.8171386719 
summon minecraft:llama ~3.50366210938 ~214.0 ~-50.7746582031 
summon minecraft:llama ~5.63891601562 ~214.0 ~-47.8244628906 
summon minecraft:donkey ~4.6484375 ~214.0 ~-43.9602050781 
summon minecraft:llama ~3.62890625 ~214.0 ~-47.8520507812 
summon minecraft:donkey ~5.18872070312 ~214.0 ~-40.3681640625 
summon minecraft:llama ~5.68701171875 ~214.0 ~-46.7807617188 
summon minecraft:llama ~4.60034179688 ~214.0 ~-50.6916503906 
summon minecraft:mule ~5.56591796875 ~214.0 ~-42.2019042969 
summon minecraft:mule ~6.6767578125 ~214.0 ~-40.7238769531 
summon minecraft:donkey ~6.16674804688 ~214.0 ~-43.86328125 
summon minecraft:pig ~-4.39599609375 ~111.0 ~27.0346679688 
summon minecraft:pig ~-8.99145507812 ~111.0 ~27.2587890625 
summon minecraft:pig ~-8.76879882812 ~111.0 ~30.6494140625 
summon minecraft:pig ~-6.50244140625 ~111.1875 ~33.3220214844 
summon minecraft:pig ~-5.21630859375 ~111.0 ~29.5598144531 
summon minecraft:horse ~8.6982421875 ~214.0 ~-60.6767578125 
summon minecraft:horse ~11.6860351562 ~214.0 ~-60.6767578125 
summon minecraft:horse ~9.4326171875 ~214.0 ~-56.4157714844 
summon minecraft:horse ~11.5092773438 ~214.0 ~-57.8310546875 
summon minecraft:horse ~12.7131347656 ~214.0 ~-56.3232421875 
summon minecraft:horse ~12.935546875 ~214.0 ~-59.1884765625 
summon minecraft:horse ~8.67016601562 ~214.0 ~-57.9416503906 
summon minecraft:horse ~10.2766113281 ~214.0 ~-59.2673339844 
summon minecraft:horse ~10.8530273438 ~214.0 ~-56.3232421875 
summon minecraft:sheep ~12.4096679688 ~214.0 ~-53.8879394531 
summon minecraft:sheep ~13.5014648438 ~214.0 ~-53.8889160156 
summon minecraft:sheep ~13.3598632812 ~214.0 ~-54.9250488281 
summon minecraft:sheep ~15.3876953125 ~214.0 ~-53.2309570312 
summon minecraft:sheep ~15.4177246094 ~214.0 ~-54.4946289062 
summon minecraft:sheep ~12.0749511719 ~214.0 ~-52.7866210938 
summon minecraft:mooshroom ~12.4682617188 ~214.0 ~-42.4128417969 
summon minecraft:mooshroom ~8.14086914062 ~214.0 ~-40.8735351562 
summon minecraft:mooshroom ~8.6748046875 ~214.0 ~-42.9653320312 
summon minecraft:mooshroom ~8.85864257812 ~214.0 ~-44.2912597656 
summon minecraft:mooshroom ~10.8859863281 ~214.0 ~-44.7451171875 
summon minecraft:mooshroom ~9.07958984375 ~214.0 ~-41.7602539062 
summon minecraft:mooshroom ~9.70288085938 ~214.0 ~-43.0441894531 
summon minecraft:sheep ~15.21484375 ~214.0 ~-51.5417480469 
summon minecraft:sheep ~16.4643554688 ~214.0 ~-51.2119140625 
summon minecraft:sheep ~14.2490234375 ~214.0 ~-50.4733886719 
summon minecraft:sheep ~15.4675292969 ~214.0 ~-50.0751953125 
summon minecraft:painting ~14.03125 ~25.0 ~26.5 
summon minecraft:painting ~14.03125 ~26.0 ~25.5 
summon minecraft:painting ~17.03125 ~29.5 ~25.0 
summon minecraft:painting ~14.03125 ~37.5 ~26.0 
summon minecraft:painting ~14.03125 ~35.5 ~25.5 
summon minecraft:painting ~16.03125 ~42.0 ~26.5 
summon minecraft:painting ~17.03125 ~41.5 ~25.5 
summon minecraft:painting ~14.5 ~46.0 ~25.03125 
summon minecraft:painting ~14.03125 ~48.0 ~25.5 
summon minecraft:item_frame ~10.0 ~142.0 ~27.0 
summon minecraft:armor_stand ~10.5 ~141.0 ~30.5 
summon minecraft:painting ~14.03125 ~25.0 ~28.5 
summon minecraft:painting ~16.03125 ~31.0 ~27.0 
summon minecraft:painting ~16.03125 ~29.5 ~28.0 
summon minecraft:painting ~16.03125 ~43.5 ~28.0 
summon minecraft:painting ~16.03125 ~42.0 ~28.0 
summon minecraft:painting ~14.03125 ~25.5 ~29.5 
summon minecraft:painting ~14.03125 ~26.5 ~29.0 
summon minecraft:painting ~17.03125 ~31.0 ~30.0 
summon minecraft:painting ~21.0 ~30.5 ~36.96875 
summon minecraft:painting ~20.0 ~25.0 ~38.96875 
summon minecraft:painting ~21.5 ~24.0 ~39.96875 
summon minecraft:painting ~17.03125 ~26.0 ~36.5 
summon minecraft:painting ~15.03125 ~25.0 ~31.0 
summon minecraft:painting ~18.0 ~26.0 ~37.96875 
summon minecraft:painting ~14.03125 ~46.0 ~29.0 
summon minecraft:painting ~14.03125 ~37.0 ~29.0 
summon minecraft:painting ~14.03125 ~35.5 ~29.0 
summon minecraft:painting ~19.5 ~47.0 ~38.96875 
summon minecraft:painting ~14.5 ~47.5 ~29.96875 
summon minecraft:painting ~17.5 ~46.0 ~36.96875 
summon minecraft:painting ~16.03125 ~47.0 ~35.0 
summon minecraft:painting ~19.5 ~41.5 ~35.96875 
summon minecraft:painting ~19.03125 ~42.5 ~35.5 
summon minecraft:painting ~18.03125 ~42.5 ~34.0 
summon minecraft:painting ~18.03125 ~43.5 ~34.0 
summon minecraft:painting ~20.5 ~43.5 ~36.96875 
summon minecraft:painting ~19.03125 ~43.5 ~35.5 
summon minecraft:painting ~21.0 ~42.5 ~36.96875 
summon minecraft:painting ~15.03125 ~46.5 ~31.0 
summon minecraft:painting ~15.03125 ~47.5 ~30.5 
summon minecraft:painting ~15.03125 ~47.0 ~33.5 
summon minecraft:painting ~19.03125 ~32.0 ~35.5 
summon minecraft:painting ~20.5 ~32.0 ~36.96875 
summon minecraft:painting ~18.03125 ~32.0 ~34.0 
summon minecraft:painting ~15.03125 ~36.5 ~32.0 
summon minecraft:painting ~18.03125 ~40.5 ~34.0 
summon minecraft:painting ~18.03125 ~41.5 ~34.0 
summon minecraft:painting ~17.03125 ~41.5 ~29.5 
summon minecraft:painting ~17.03125 ~43.0 ~30.5 
summon minecraft:painting ~16.03125 ~35.5 ~35.0 
summon minecraft:painting ~16.03125 ~37.0 ~35.0 
summon minecraft:painting ~17.03125 ~32.5 ~32.0 
summon minecraft:painting ~17.03125 ~37.5 ~36.5 
summon minecraft:painting ~21.5 ~37.5 ~39.96875 
summon minecraft:painting ~18.5 ~37.0 ~37.96875 
summon minecraft:painting ~19.5 ~37.0 ~38.96875 
summon minecraft:painting ~14.03125 ~48.5 ~29.5 
summon minecraft:painting ~16.03125 ~48.5 ~34.5 
summon minecraft:painting ~21.03125 ~48.0 ~39.5 
summon minecraft:painting ~18.03125 ~48.0 ~37.5 
summon minecraft:item_frame ~16.0 ~135.0 ~38.0 
summon minecraft:item_frame ~21.0 ~150.0 ~30.0 
summon minecraft:item_frame ~21.0 ~151.0 ~30.0 
summon minecraft:painting ~22.0 ~26.5 ~39.96875 
summon minecraft:painting ~22.0 ~36.5 ~39.96875 
summon minecraft:painting ~22.03125 ~43.0 ~37.5 
summon minecraft:painting ~22.5 ~41.0 ~37.96875 
summon minecraft:painting ~37.96875 ~31.5 ~25.0 
summon minecraft:painting ~37.96875 ~32.5 ~25.5 
summon minecraft:painting ~26.0 ~26.0 ~40.96875 
summon minecraft:painting ~24.0 ~26.0 ~39.96875 
summon minecraft:painting ~27.0 ~29.5 ~38.96875 
summon minecraft:painting ~28.0 ~31.0 ~38.96875 
summon minecraft:painting ~24.0 ~29.5 ~37.96875 
summon minecraft:painting ~25.0 ~30.5 ~37.96875 
summon minecraft:painting ~23.5 ~37.0 ~39.96875 
summon minecraft:painting ~28.5 ~36.0 ~40.96875 
summon minecraft:painting ~25.5 ~37.0 ~40.96875 
summon minecraft:painting ~24.0 ~32.5 ~37.96875 
summon minecraft:painting ~26.5 ~32.0 ~38.96875 
summon minecraft:painting ~24.0 ~41.5 ~37.96875 
summon minecraft:painting ~25.5 ~42.0 ~37.96875 
summon minecraft:painting ~27.0 ~41.5 ~38.96875 
summon minecraft:painting ~28.0 ~43.0 ~38.96875 
summon minecraft:painting ~28.5 ~40.5 ~38.96875 
summon minecraft:painting ~24.5 ~43.0 ~37.96875 
summon minecraft:painting ~38.96875 ~30.0 ~27.0 
summon minecraft:painting ~38.96875 ~32.0 ~28.0 
summon minecraft:painting ~38.96875 ~41.5 ~28.0 
summon minecraft:painting ~38.96875 ~43.0 ~27.0 
summon minecraft:painting ~29.5 ~31.0 ~37.96875 
summon minecraft:painting ~33.0 ~24.0 ~39.96875 
summon minecraft:painting ~31.0 ~26.5 ~39.96875 
summon minecraft:painting ~29.5 ~26.0 ~40.96875 
summon minecraft:painting ~30.5 ~25.0 ~39.96875 
summon minecraft:painting ~33.0 ~26.0 ~39.96875 
summon minecraft:painting ~37.96875 ~29.5 ~30.0 
summon minecraft:painting ~37.96875 ~31.0 ~32.0 
summon minecraft:painting ~35.5 ~30.5 ~35.96875 
summon minecraft:painting ~36.96875 ~30.0 ~34.0 
summon minecraft:painting ~34.0 ~30.0 ~36.96875 
summon minecraft:painting ~34.5 ~26.0 ~38.96875 
summon minecraft:painting ~36.5 ~26.5 ~37.96875 
summon minecraft:painting ~35.0 ~24.0 ~38.96875 
summon minecraft:painting ~30.5 ~46.5 ~39.96875 
summon minecraft:painting ~31.0 ~40.5 ~37.96875 
summon minecraft:painting ~32.5 ~43.0 ~37.96875 
summon minecraft:painting ~29.0 ~37.5 ~40.96875 
summon minecraft:painting ~32.0 ~32.5 ~37.96875 
summon minecraft:painting ~31.5 ~36.5 ~39.96875 
summon minecraft:painting ~30.5 ~37.5 ~39.96875 
summon minecraft:painting ~32.5 ~35.5 ~39.96875 
summon minecraft:painting ~37.96875 ~43.0 ~30.0 
summon minecraft:painting ~34.5 ~46.5 ~38.96875 
summon minecraft:painting ~36.96875 ~43.5 ~34.0 
summon minecraft:painting ~37.5 ~43.5 ~32.96875 
summon minecraft:painting ~34.0 ~42.5 ~36.96875 
summon minecraft:painting ~33.5 ~43.5 ~36.96875 
summon minecraft:painting ~35.96875 ~43.5 ~35.5 
summon minecraft:painting ~36.96875 ~42.5 ~34.5 
summon minecraft:painting ~35.96875 ~41.5 ~35.5 
summon minecraft:painting ~35.5 ~42.5 ~35.96875 
summon minecraft:painting ~36.96875 ~32.0 ~34.5 
summon minecraft:painting ~37.96875 ~32.5 ~31.0 
summon minecraft:painting ~34.5 ~32.0 ~36.96875 
summon minecraft:painting ~35.96875 ~32.0 ~35.5 
summon minecraft:painting ~36.96875 ~37.5 ~37.5 
summon minecraft:painting ~34.5 ~37.5 ~38.96875 
summon minecraft:painting ~34.5 ~36.0 ~38.96875 
summon minecraft:painting ~36.96875 ~36.5 ~37.5 
summon minecraft:painting ~33.5 ~36.5 ~39.96875 
summon minecraft:painting ~31.0 ~48.0 ~39.96875 
summon minecraft:painting ~36.96875 ~48.0 ~37.5 
summon minecraft:painting ~35.0 ~48.0 ~38.96875 
summon minecraft:minecart ~32.4699707031 ~150.0 ~38.509765625 
summon minecraft:minecart ~31.4899902344 ~150.0 ~38.509765625 
summon minecraft:minecart ~33.5 ~150.0 ~38.509765625 
summon minecraft:painting ~38.96875 ~25.0 ~35.5 
summon minecraft:painting ~38.96875 ~26.5 ~35.0 
summon minecraft:painting ~38.96875 ~37.0 ~35.0 
summon minecraft:painting ~38.96875 ~46.5 ~35.5 
summon minecraft:painting ~38.96875 ~47.5 ~34.5 
summon minecraft:painting ~38.5 ~48.0 ~35.96875 
summon minecraft:item_frame ~38.0 ~135.0 ~38.0 
summon minecraft:item_frame ~38.0 ~135.0 ~38.0 
summon minecraft:armor_stand ~24.5 ~141.0 ~44.5 
summon minecraft:item_frame ~27.0 ~142.0 ~44.0 
summon minecraft:villager ~24.623046875 ~239.0 ~44.271484375 
summon minecraft:pig ~26.7277832031 ~111.0 ~56.8427734375 
summon minecraft:villager ~23.8623046875 ~239.0 ~45.42578125 
summon minecraft:villager ~24.55078125 ~239.0 ~45.0852050781 
summon minecraft:armor_stand ~30.5 ~141.0 ~44.5 
summon minecraft:pig ~27.6687011719 ~111.0 ~59.5498046875 
summon minecraft:pig ~26.5891113281 ~111.0 ~59.5139160156 
summon minecraft:painting ~40.96875 ~25.0 ~26.5 
summon minecraft:painting ~40.96875 ~37.0 ~26.5 
summon minecraft:painting ~40.96875 ~45.5 ~26.0 
summon minecraft:painting ~40.96875 ~46.5 ~26.0 
summon minecraft:painting ~40.96875 ~47.5 ~26.0 
summon minecraft:painting ~40.96875 ~48.5 ~26.0 
summon minecraft:painting ~40.96875 ~37.0 ~28.5 
summon minecraft:item_frame ~44.0 ~142.0 ~27.0 
summon minecraft:painting ~39.96875 ~25.0 ~31.0 
summon minecraft:painting ~40.96875 ~26.0 ~29.0 
summon minecraft:painting ~39.96875 ~36.5 ~32.0 
summon minecraft:painting ~39.96875 ~46.5 ~30.5 
summon minecraft:painting ~40.96875 ~45.5 ~29.5 
summon minecraft:painting ~40.96875 ~48.0 ~29.0 
summon minecraft:item_frame ~40.0 ~141.0 ~34.0 
summon minecraft:armor_stand ~44.5 ~141.0 ~30.5 
summon minecraft:pig ~60.1271972656 ~111.0 ~25.4094238281 
summon minecraft:pig ~59.5151367188 ~111.0 ~26.6418457031 
summon minecraft:pig ~65.1748046875 ~111.0 ~26.7758789062 
summon minecraft:pig ~59.2788085938 ~111.0 ~31.5104980469
fill ~31 ~21 ~21 ~32 ~21 ~21 obsidian 0 
setblock ~31 ~21 ~22 quartz_block 13 
setblock ~31 ~21 ~32 quartz_block 13  
fill ~31 ~21 ~33 ~32 ~21 ~33 obsidian 0  
fill ~32 ~21 ~20 ~37 ~21 ~20 quartz_block 0  
fill ~32 ~21 ~22 ~33 ~21 ~22 obsidian 0 
setblock ~32 ~21 ~23 quartz_block 13 
setblock ~32 ~21 ~31 quartz_block 13  
fill ~32 ~21 ~32 ~33 ~21 ~32 obsidian 0  
fill ~32 ~21 ~34 ~37 ~21 ~34 quartz_block 0 
setblock ~33 ~21 ~16 quartz_stairs 5  
fill ~33 ~21 ~21 ~37 ~21 ~21 quartz_block 0  
fill ~33 ~21 ~23 ~34 ~21 ~23 obsidian 0  
fill ~33 ~21 ~24 ~33 ~21 ~25 quartz_block 10  
fill ~33 ~21 ~29 ~33 ~21 ~30 quartz_block 10  
fill ~33 ~21 ~31 ~34 ~21 ~31 obsidian 0  
fill ~33 ~21 ~33 ~37 ~21 ~33 quartz_block 0  
fill ~33 ~21 ~38 ~34 ~21 ~38 quartz_stairs 7 
setblock ~33 ~21 ~39 quartz_stairs 5 
setblock ~34 ~21 ~16 quartz_stairs 6  
fill ~34 ~21 ~22 ~38 ~21 ~22 quartz_block 0  
fill ~34 ~21 ~24 ~34 ~21 ~25 obsidian 0  
fill ~34 ~21 ~26 ~34 ~21 ~28 quartz_block 10  
fill ~34 ~21 ~29 ~35 ~21 ~29 obsidian 0  
fill ~34 ~21 ~30 ~34 ~21 ~29 obsidian 0  
fill ~34 ~21 ~32 ~38 ~21 ~32 quartz_block 0  
fill ~35 ~21 ~16 ~35 ~21 ~17 quartz_stairs 5  
fill ~35 ~21 ~23 ~38 ~21 ~23 quartz_block 0  
fill ~35 ~21 ~24 ~38 ~21 ~24 quartz_block 0  
fill ~35 ~21 ~25 ~35 ~21 ~29 obsidian 0  
fill ~35 ~21 ~30 ~38 ~21 ~30 quartz_block 0  
fill ~35 ~21 ~31 ~38 ~21 ~31 quartz_block 0  
fill ~35 ~21 ~37 ~37 ~21 ~37 quartz_stairs 7 
setblock ~35 ~21 ~38 quartz_stairs 5 
setblock ~36 ~21 ~17 quartz_stairs 6  
fill ~36 ~21 ~25 ~38 ~21 ~25 quartz_block 0  
fill ~36 ~21 ~26 ~39 ~21 ~26 quartz_block 0  
fill ~36 ~21 ~27 ~39 ~21 ~27 quartz_block 0  
fill ~36 ~21 ~28 ~39 ~21 ~28 quartz_block 0  
fill ~36 ~21 ~29 ~38 ~21 ~29 quartz_block 0  
fill ~37 ~21 ~17 ~37 ~21 ~19 quartz_stairs 5  
fill ~37 ~21 ~35 ~37 ~21 ~36 quartz_stairs 5 
setblock ~38 ~21 ~19 quartz_stairs 6  
fill ~38 ~21 ~20 ~38 ~21 ~21 quartz_stairs 5  
fill ~38 ~21 ~33 ~39 ~21 ~33 quartz_stairs 7 
setblock ~38 ~21 ~34 quartz_stairs 5 
setblock ~38 ~21 ~35 quartz_stairs 7 
setblock ~39 ~21 ~21 quartz_stairs 6  
fill ~39 ~21 ~22 ~39 ~21 ~25 quartz_stairs 5  
fill ~39 ~21 ~29 ~40 ~21 ~29 quartz_stairs 7  
fill ~39 ~21 ~30 ~39 ~21 ~32 quartz_stairs 5 
setblock ~40 ~21 ~25 quartz_stairs 6  
fill ~40 ~21 ~26 ~40 ~21 ~28 quartz_stairs 5  
fill ~69 ~21 ~-17 ~71 ~21 ~-17 stone_slab 14  
fill ~69 ~21 ~-16 ~69 ~21 ~-15 stone_slab 14  
fill ~69 ~21 ~69 ~71 ~21 ~69 stone_slab 14  
fill ~69 ~21 ~70 ~69 ~21 ~71 stone_slab 14 
setblock ~70 ~21 ~-16 sea_lantern 0  
fill ~70 ~21 ~-15 ~71 ~21 ~-15 stone_slab 14 
setblock ~70 ~21 ~70 sea_lantern 0  
fill ~70 ~21 ~71 ~71 ~21 ~71 stone_slab 14 
setblock ~71 ~21 ~-16 stone_slab 14 
setblock ~71 ~21 ~70 stone_slab 14  
fill ~87 ~21 ~26 ~89 ~21 ~26 stone_slab 14  
fill ~87 ~21 ~27 ~87 ~21 ~28 stone_slab 14 
setblock ~88 ~21 ~27 sea_lantern 0  
fill ~88 ~21 ~28 ~89 ~21 ~28 stone_slab 14 
setblock ~89 ~21 ~27 stone_slab 14  
fill ~-36 ~22 ~25 ~-32 ~22 ~25 stone_slab 6  
fill ~-36 ~22 ~26 ~-36 ~24 ~26 stone_slab 6  
fill ~-36 ~22 ~27 ~-36 ~24 ~27 stone_slab 6  
fill ~-36 ~22 ~28 ~-36 ~24 ~28 stone_slab 6  
fill ~-36 ~22 ~29 ~-32 ~22 ~29 stone_slab 6  
fill ~-35 ~22 ~26 ~-33 ~22 ~26 quartz_stairs 2  
fill ~-35 ~22 ~27 ~-35 ~35 ~27 quartz_stairs 0  
fill ~-35 ~22 ~28 ~-35 ~23 ~28 quartz_stairs 0  
fill ~-34 ~22 ~27 ~-34 ~35 ~27 planks 0  
fill ~-34 ~22 ~28 ~-33 ~22 ~28 quartz_stairs 3  
fill ~-33 ~22 ~27 ~-33 ~35 ~27 quartz_stairs 1  
fill ~-32 ~22 ~26 ~-32 ~24 ~26 stone_slab 6  
fill ~-32 ~22 ~27 ~-32 ~24 ~27 stone_slab 6  
fill ~-32 ~22 ~28 ~-32 ~24 ~28 stone_slab 6  
fill ~-18 ~22 ~-18 ~-14 ~22 ~-18 stone_slab 6  
fill ~-18 ~22 ~-17 ~-18 ~24 ~-17 stone_slab 6  
fill ~-18 ~22 ~-16 ~-18 ~24 ~-16 stone_slab 6  
fill ~-18 ~22 ~-15 ~-18 ~24 ~-15 stone_slab 6  
fill ~-18 ~22 ~-14 ~-14 ~22 ~-14 stone_slab 6  
fill ~-18 ~22 ~68 ~-14 ~22 ~68 stone_slab 6  
fill ~-18 ~22 ~69 ~-18 ~24 ~69 stone_slab 6  
fill ~-18 ~22 ~70 ~-18 ~24 ~70 stone_slab 6  
fill ~-18 ~22 ~71 ~-18 ~24 ~71 stone_slab 6  
fill ~-18 ~22 ~72 ~-14 ~22 ~72 stone_slab 6  
fill ~-17 ~22 ~-17 ~-15 ~22 ~-17 quartz_stairs 2  
fill ~-17 ~22 ~-16 ~-17 ~36 ~-16 quartz_stairs 0  
fill ~-17 ~22 ~-15 ~-17 ~35 ~-15 quartz_stairs 0  
fill ~-17 ~22 ~69 ~-16 ~22 ~69 quartz_stairs 2  
fill ~-17 ~22 ~70 ~-17 ~36 ~70 quartz_stairs 0  
fill ~-17 ~22 ~71 ~-17 ~36 ~71 quartz_stairs 0  
fill ~-16 ~22 ~-16 ~-16 ~36 ~-16 quartz_block 0  
fill ~-16 ~22 ~-15 ~-15 ~22 ~-15 quartz_stairs 3  
fill ~-16 ~22 ~70 ~-16 ~36 ~70 quartz_block 0  
fill ~-16 ~22 ~71 ~-15 ~22 ~71 quartz_stairs 3  
fill ~-15 ~22 ~-16 ~-15 ~35 ~-16 quartz_stairs 1  
fill ~-15 ~22 ~69 ~-15 ~35 ~69 quartz_stairs 1  
fill ~-15 ~22 ~70 ~-15 ~35 ~70 quartz_stairs 1  
fill ~-14 ~22 ~-17 ~-14 ~24 ~-17 stone_slab 6  
fill ~-14 ~22 ~-16 ~-14 ~24 ~-16 stone_slab 6  
fill ~-14 ~22 ~-15 ~-14 ~24 ~-15 stone_slab 6  
fill ~-14 ~22 ~69 ~-14 ~24 ~69 stone_slab 6  
fill ~-14 ~22 ~70 ~-14 ~24 ~70 stone_slab 6  
fill ~-14 ~22 ~71 ~-14 ~24 ~71 stone_slab 6  
fill ~11 ~22 ~26 ~12 ~22 ~26 quartz_stairs 6 
setblock ~11 ~22 ~27 quartz_stairs 4 
setblock ~11 ~22 ~28 quartz_stairs 7  
fill ~12 ~22 ~23 ~12 ~22 ~25 quartz_stairs 4  
fill ~12 ~22 ~27 ~13 ~22 ~27 obsidian 0  
fill ~12 ~22 ~28 ~12 ~22 ~30 quartz_stairs 4 
setblock ~12 ~22 ~31 quartz_stairs 7  
fill ~13 ~22 ~19 ~13 ~22 ~22 quartz_stairs 4 
setblock ~13 ~22 ~23 quartz_stairs 6  
fill ~13 ~22 ~24 ~14 ~22 ~24 obsidian 0  
fill ~13 ~22 ~25 ~13 ~22 ~30 obsidian 0  
fill ~13 ~22 ~31 ~13 ~22 ~34 quartz_stairs 4 
setblock ~13 ~22 ~35 quartz_stairs 7  
fill ~14 ~22 ~17 ~14 ~22 ~18 quartz_stairs 4 
setblock ~14 ~22 ~19 quartz_stairs 6  
fill ~14 ~22 ~20 ~15 ~22 ~20 obsidian 0  
fill ~14 ~22 ~21 ~14 ~22 ~24 obsidian 0 
setblock ~14 ~22 ~25 quartz_block 6  
fill ~14 ~22 ~26 ~15 ~22 ~26 obsidian 0 
setblock ~14 ~22 ~27 sea_lantern 0  
fill ~14 ~22 ~28 ~15 ~22 ~28 obsidian 0 
setblock ~14 ~22 ~29 quartz_block 6  
fill ~14 ~22 ~30 ~14 ~22 ~34 obsidian 0  
fill ~14 ~22 ~35 ~14 ~22 ~36 quartz_stairs 4 
setblock ~14 ~22 ~37 quartz_stairs 7 
setblock ~15 ~22 ~16 quartz_stairs 4 
setblock ~15 ~22 ~17 quartz_stairs 6  
fill ~15 ~22 ~18 ~18 ~22 ~18 obsidian 0  
fill ~15 ~22 ~19 ~15 ~22 ~18 obsidian 0 
setblock ~15 ~22 ~21 quartz_block 10 
setblock ~15 ~22 ~22 quartz_block 6 
setblock ~15 ~22 ~23 quartz_block 10 
setblock ~15 ~22 ~24 quartz_block 6 
setblock ~15 ~22 ~25 quartz_block 10  
fill ~15 ~22 ~27 ~18 ~22 ~27 obsidian 0 
setblock ~15 ~22 ~29 quartz_block 10 
setblock ~15 ~22 ~30 quartz_block 6 
setblock ~15 ~22 ~31 quartz_block 10 
setblock ~15 ~22 ~32 quartz_block 6 
setblock ~15 ~22 ~33 quartz_block 10  
fill ~15 ~22 ~34 ~15 ~22 ~36 obsidian 0 
setblock ~15 ~22 ~37 quartz_stairs 4 
setblock ~15 ~22 ~38 quartz_stairs 7 
setblock ~16 ~22 ~15 quartz_stairs 4 
setblock ~16 ~22 ~16 quartz_stairs 6 
setblock ~16 ~22 ~17 obsidian 0 
setblock ~16 ~22 ~19 quartz_block 6 
setblock ~16 ~22 ~20 quartz_block 10 
setblock ~16 ~22 ~21 quartz_block 6 
setblock ~16 ~22 ~22 quartz_block 10 
setblock ~16 ~22 ~23 quartz_block 6 
setblock ~16 ~22 ~24 quartz_block 10 
setblock ~16 ~22 ~25 quartz_block 6 
setblock ~16 ~22 ~26 quartz_block 10 
setblock ~16 ~22 ~28 quartz_block 10 
setblock ~16 ~22 ~29 quartz_block 6 
setblock ~16 ~22 ~30 quartz_block 10 
setblock ~16 ~22 ~31 quartz_block 6 
setblock ~16 ~22 ~32 quartz_block 10 
setblock ~16 ~22 ~33 quartz_block 6 
setblock ~16 ~22 ~34 quartz_block 10 
setblock ~16 ~22 ~35 quartz_block 6  
fill ~16 ~22 ~36 ~18 ~22 ~36 obsidian 0  
fill ~16 ~22 ~37 ~16 ~22 ~36 obsidian 0 
setblock ~16 ~22 ~38 quartz_stairs 4 
setblock ~16 ~22 ~39 quartz_stairs 7 
setblock ~17 ~22 ~14 quartz_stairs 4 
setblock ~17 ~22 ~15 quartz_stairs 6  
fill ~17 ~22 ~16 ~18 ~22 ~16 obsidian 0 
setblock ~17 ~22 ~17 quartz_block 0 
setblock ~17 ~22 ~19 quartz_block 10 
setblock ~17 ~22 ~20 quartz_block 6 
setblock ~17 ~22 ~21 quartz_block 10 
setblock ~17 ~22 ~22 quartz_block 6 
setblock ~17 ~22 ~23 quartz_block 10 
setblock ~17 ~22 ~24 quartz_block 6 
setblock ~17 ~22 ~25 quartz_block 10 
setblock ~17 ~22 ~26 quartz_block 6 
setblock ~17 ~22 ~28 quartz_block 6 
setblock ~17 ~22 ~29 quartz_block 10 
setblock ~17 ~22 ~30 quartz_block 6 
setblock ~17 ~22 ~31 quartz_block 10 
setblock ~17 ~22 ~32 quartz_block 6 
setblock ~17 ~22 ~33 quartz_block 10 
setblock ~17 ~22 ~34 quartz_block 6 
setblock ~17 ~22 ~35 quartz_block 10 
setblock ~17 ~22 ~37 quartz_block 0  
fill ~17 ~22 ~38 ~18 ~22 ~38 obsidian 0  
fill ~17 ~22 ~39 ~17 ~22 ~40 quartz_stairs 4  
fill ~18 ~22 ~14 ~19 ~22 ~14 quartz_stairs 6  
fill ~18 ~22 ~15 ~20 ~22 ~15 obsidian 0 
setblock ~18 ~22 ~17 obsidian 0 
setblock ~18 ~22 ~19 quartz_block 6 
setblock ~18 ~22 ~20 quartz_block 10 
setblock ~18 ~22 ~21 quartz_block 6 
setblock ~18 ~22 ~22 quartz_block 10 
setblock ~18 ~22 ~23 quartz_block 6  
fill ~18 ~22 ~24 ~18 ~22 ~26 quartz_stairs 1  
fill ~18 ~22 ~28 ~18 ~22 ~30 quartz_stairs 1 
setblock ~18 ~22 ~31 quartz_block 6 
setblock ~18 ~22 ~32 quartz_block 10 
setblock ~18 ~22 ~33 quartz_block 6 
setblock ~18 ~22 ~34 quartz_block 10 
setblock ~18 ~22 ~35 quartz_block 6 
setblock ~18 ~22 ~37 obsidian 0  
fill ~18 ~22 ~39 ~20 ~22 ~39 obsidian 0 
setblock ~18 ~22 ~40 quartz_stairs 7 
setblock ~19 ~22 ~13 quartz_stairs 4 
setblock ~19 ~22 ~16 quartz_block 6 
setblock ~19 ~22 ~17 quartz_block 10 
setblock ~19 ~22 ~18 quartz_block 6 
setblock ~19 ~22 ~19 quartz_block 10 
setblock ~19 ~22 ~20 quartz_block 6 
setblock ~19 ~22 ~21 quartz_block 10 
setblock ~19 ~22 ~22 quartz_stairs 3 
setblock ~19 ~22 ~23 quartz_stairs 1 
setblock ~19 ~22 ~24 quartz_stairs 3 
setblock ~19 ~22 ~27 quartz_block 13 
setblock ~19 ~22 ~30 quartz_stairs 2 
setblock ~19 ~22 ~31 quartz_stairs 1 
setblock ~19 ~22 ~32 quartz_stairs 2 
setblock ~19 ~22 ~33 quartz_block 10 
setblock ~19 ~22 ~34 quartz_block 6 
setblock ~19 ~22 ~35 quartz_block 10 
setblock ~19 ~22 ~36 quartz_block 6 
setblock ~19 ~22 ~37 quartz_block 10 
setblock ~19 ~22 ~38 quartz_block 6 
setblock ~19 ~22 ~40 quartz_stairs 4  
fill ~19 ~22 ~41 ~22 ~22 ~41 quartz_stairs 7  
fill ~20 ~22 ~13 ~23 ~22 ~13 quartz_stairs 6  
fill ~20 ~22 ~14 ~24 ~22 ~14 obsidian 0 
setblock ~20 ~22 ~16 quartz_block 10 
setblock ~20 ~22 ~17 quartz_block 6 
setblock ~20 ~22 ~18 quartz_block 10 
setblock ~20 ~22 ~19 quartz_block 6 
setblock ~20 ~22 ~20 quartz_block 10 
setblock ~20 ~22 ~21 quartz_stairs 3 
setblock ~20 ~22 ~22 quartz_stairs 1 
setblock ~20 ~22 ~32 quartz_stairs 1 
setblock ~20 ~22 ~33 quartz_stairs 2 
setblock ~20 ~22 ~34 quartz_block 10 
setblock ~20 ~22 ~35 quartz_block 6 
setblock ~20 ~22 ~36 quartz_block 10 
setblock ~20 ~22 ~37 quartz_block 6 
setblock ~20 ~22 ~38 quartz_block 10  
fill ~20 ~22 ~40 ~24 ~22 ~40 obsidian 0 
setblock ~21 ~22 ~15 quartz_block 10 
setblock ~21 ~22 ~16 quartz_block 6 
setblock ~21 ~22 ~17 quartz_block 10 
setblock ~21 ~22 ~18 quartz_block 6 
setblock ~21 ~22 ~19 quartz_block 10 
setblock ~21 ~22 ~20 quartz_stairs 3 
setblock ~21 ~22 ~21 quartz_stairs 1 
setblock ~21 ~22 ~33 quartz_stairs 1 
setblock ~21 ~22 ~34 quartz_stairs 2 
setblock ~21 ~22 ~35 quartz_block 10 
setblock ~21 ~22 ~36 quartz_block 6 
setblock ~21 ~22 ~37 quartz_block 10 
setblock ~21 ~22 ~38 quartz_block 6 
setblock ~21 ~22 ~39 quartz_block 10 
setblock ~22 ~22 ~15 quartz_block 6 
setblock ~22 ~22 ~16 quartz_block 10 
setblock ~22 ~22 ~17 quartz_block 6 
setblock ~22 ~22 ~18 quartz_block 10  
fill ~22 ~22 ~19 ~22 ~22 ~20 quartz_stairs 1 
setblock ~22 ~22 ~22 beacon 0 
setblock ~22 ~22 ~32 beacon 0 
setblock ~22 ~22 ~34 quartz_stairs 1  
fill ~22 ~22 ~35 ~23 ~22 ~35 quartz_stairs 2 
setblock ~22 ~22 ~36 quartz_block 10 
setblock ~22 ~22 ~37 quartz_block 6 
setblock ~22 ~22 ~38 quartz_block 10 
setblock ~22 ~22 ~39 quartz_block 6 
setblock ~23 ~22 ~12 quartz_stairs 4 
setblock ~23 ~22 ~15 quartz_block 10 
setblock ~23 ~22 ~16 quartz_block 6 
setblock ~23 ~22 ~17 quartz_block 10 
setblock ~23 ~22 ~18 quartz_block 6 
setblock ~23 ~22 ~19 quartz_stairs 3 
setblock ~23 ~22 ~36 quartz_block 6 
setblock ~23 ~22 ~37 quartz_block 10 
setblock ~23 ~22 ~38 quartz_block 6 
setblock ~23 ~22 ~39 quartz_block 10 
setblock ~23 ~22 ~41 quartz_stairs 4  
fill ~23 ~22 ~42 ~25 ~22 ~42 quartz_stairs 7  
fill ~24 ~22 ~12 ~26 ~22 ~12 quartz_stairs 6  
fill ~24 ~22 ~13 ~30 ~22 ~13 obsidian 0 
setblock ~24 ~22 ~15 quartz_block 6 
setblock ~24 ~22 ~16 quartz_block 10 
setblock ~24 ~22 ~17 quartz_block 6  
fill ~24 ~22 ~18 ~26 ~22 ~18 quartz_stairs 3 
setblock ~24 ~22 ~19 quartz_stairs 1 
setblock ~24 ~22 ~35 quartz_stairs 1  
fill ~24 ~22 ~36 ~26 ~22 ~36 quartz_stairs 2 
setblock ~24 ~22 ~37 quartz_block 6 
setblock ~24 ~22 ~38 quartz_block 10 
setblock ~24 ~22 ~39 quartz_block 6  
fill ~24 ~22 ~41 ~30 ~22 ~41 obsidian 0  
fill ~25 ~22 ~-36 ~29 ~22 ~-36 stone_slab 6  
fill ~25 ~22 ~-35 ~25 ~24 ~-35 stone_slab 6  
fill ~25 ~22 ~-34 ~25 ~24 ~-34 stone_slab 6  
fill ~25 ~22 ~-33 ~25 ~24 ~-33 stone_slab 6  
fill ~25 ~22 ~-32 ~29 ~22 ~-32 stone_slab 6 
setblock ~25 ~22 ~14 quartz_block 6 
setblock ~25 ~22 ~15 quartz_block 10 
setblock ~25 ~22 ~16 quartz_block 6 
setblock ~25 ~22 ~17 quartz_block 10 
setblock ~25 ~22 ~37 quartz_block 10 
setblock ~25 ~22 ~38 quartz_block 6 
setblock ~25 ~22 ~39 quartz_block 10 
setblock ~25 ~22 ~40 quartz_block 6  
fill ~25 ~22 ~86 ~29 ~22 ~86 stone_slab 6  
fill ~25 ~22 ~87 ~25 ~24 ~87 stone_slab 6  
fill ~25 ~22 ~88 ~25 ~24 ~88 stone_slab 6  
fill ~25 ~22 ~89 ~25 ~24 ~89 stone_slab 6  
fill ~25 ~22 ~90 ~29 ~22 ~90 stone_slab 6  
fill ~26 ~22 ~-35 ~26 ~23 ~-35 quartz_stairs 0  
fill ~26 ~22 ~-34 ~26 ~35 ~-34 quartz_stairs 0  
fill ~26 ~22 ~-33 ~26 ~23 ~-33 quartz_stairs 0 
setblock ~26 ~22 ~11 quartz_stairs 4  
fill ~26 ~22 ~14 ~26 ~22 ~15 obsidian 0 
setblock ~26 ~22 ~16 quartz_block 10 
setblock ~26 ~22 ~17 quartz_block 6 
setblock ~26 ~22 ~37 quartz_block 6 
setblock ~26 ~22 ~38 quartz_block 10  
fill ~26 ~22 ~39 ~28 ~22 ~39 obsidian 0  
fill ~26 ~22 ~40 ~26 ~22 ~39 obsidian 0 
setblock ~26 ~22 ~42 quartz_stairs 4  
fill ~26 ~22 ~43 ~28 ~22 ~43 quartz_stairs 7  
fill ~26 ~22 ~87 ~28 ~22 ~87 quartz_stairs 2  
fill ~26 ~22 ~88 ~26 ~35 ~88 quartz_stairs 0  
fill ~26 ~22 ~89 ~27 ~22 ~89 quartz_stairs 3  
fill ~27 ~22 ~-35 ~28 ~22 ~-35 quartz_stairs 2  
fill ~27 ~22 ~-34 ~27 ~35 ~-34 planks 0  
fill ~27 ~22 ~-33 ~27 ~35 ~-33 quartz_stairs 3  
fill ~27 ~22 ~11 ~28 ~22 ~11 quartz_stairs 6  
fill ~27 ~22 ~12 ~27 ~23 ~12 obsidian 0 
setblock ~27 ~22 ~14 sea_lantern 0  
fill ~27 ~22 ~15 ~28 ~22 ~15 obsidian 0  
fill ~27 ~22 ~16 ~27 ~22 ~18 obsidian 0 
setblock ~27 ~22 ~19 quartz_block 13 
setblock ~27 ~22 ~35 quartz_block 13  
fill ~27 ~22 ~36 ~27 ~22 ~39 obsidian 0 
setblock ~27 ~22 ~40 sea_lantern 0  
fill ~27 ~22 ~42 ~27 ~23 ~42 obsidian 0  
fill ~27 ~22 ~88 ~27 ~35 ~88 planks 0  
fill ~28 ~22 ~-34 ~28 ~35 ~-34 quartz_stairs 1  
fill ~28 ~22 ~-33 ~28 ~23 ~-33 quartz_stairs 1 
setblock ~28 ~22 ~12 quartz_stairs 5 
setblock ~28 ~22 ~14 obsidian 0 
setblock ~28 ~22 ~16 quartz_block 10 
setblock ~28 ~22 ~17 quartz_block 6  
fill ~28 ~22 ~18 ~29 ~22 ~18 quartz_stairs 3  
fill ~28 ~22 ~36 ~29 ~22 ~36 quartz_stairs 2 
setblock ~28 ~22 ~37 quartz_block 6 
setblock ~28 ~22 ~38 quartz_block 10 
setblock ~28 ~22 ~40 obsidian 0 
setblock ~28 ~22 ~42 quartz_stairs 5  
fill ~28 ~22 ~88 ~28 ~35 ~88 quartz_stairs 1  
fill ~28 ~22 ~89 ~28 ~26 ~89 quartz_stairs 1  
fill ~29 ~22 ~-35 ~29 ~24 ~-35 stone_slab 6  
fill ~29 ~22 ~-34 ~29 ~24 ~-34 stone_slab 6  
fill ~29 ~22 ~-33 ~29 ~24 ~-33 stone_slab 6  
fill ~29 ~22 ~12 ~31 ~22 ~12 quartz_stairs 6 
setblock ~29 ~22 ~14 quartz_block 6 
setblock ~29 ~22 ~15 quartz_block 10 
setblock ~29 ~22 ~16 quartz_block 6 
setblock ~29 ~22 ~17 quartz_block 10 
setblock ~29 ~22 ~37 quartz_block 10 
setblock ~29 ~22 ~38 quartz_block 6 
setblock ~29 ~22 ~39 quartz_block 10 
setblock ~29 ~22 ~40 quartz_block 6  
fill ~29 ~22 ~42 ~31 ~22 ~42 quartz_stairs 7  
fill ~29 ~22 ~87 ~29 ~24 ~87 stone_slab 6  
fill ~29 ~22 ~88 ~29 ~24 ~88 stone_slab 6  
fill ~29 ~22 ~89 ~29 ~24 ~89 stone_slab 6  
fill ~30 ~22 ~14 ~34 ~22 ~14 obsidian 0 
setblock ~30 ~22 ~15 quartz_block 6 
setblock ~30 ~22 ~16 quartz_block 10 
setblock ~30 ~22 ~17 quartz_block 6  
fill ~30 ~22 ~18 ~30 ~22 ~19 quartz_stairs 0  
fill ~30 ~22 ~35 ~31 ~22 ~35 quartz_stairs 2 
setblock ~30 ~22 ~36 quartz_stairs 0 
setblock ~30 ~22 ~37 quartz_block 6 
setblock ~30 ~22 ~38 quartz_block 10 
setblock ~30 ~22 ~39 quartz_block 6  
fill ~30 ~22 ~40 ~34 ~22 ~40 obsidian 0 
setblock ~31 ~22 ~13 quartz_stairs 5 
setblock ~31 ~22 ~15 quartz_block 10 
setblock ~31 ~22 ~16 quartz_block 6 
setblock ~31 ~22 ~17 quartz_block 10 
setblock ~31 ~22 ~18 quartz_block 6 
setblock ~31 ~22 ~19 quartz_stairs 3 
setblock ~31 ~22 ~36 quartz_block 6 
setblock ~31 ~22 ~37 quartz_block 10 
setblock ~31 ~22 ~38 quartz_block 6 
setblock ~31 ~22 ~39 quartz_block 10 
setblock ~31 ~22 ~41 quartz_stairs 5  
fill ~32 ~22 ~13 ~34 ~22 ~13 quartz_stairs 6 
setblock ~32 ~22 ~15 quartz_block 6 
setblock ~32 ~22 ~16 quartz_block 10 
setblock ~32 ~22 ~17 quartz_block 6 
setblock ~32 ~22 ~18 quartz_block 10 
setblock ~32 ~22 ~19 quartz_stairs 0 
setblock ~32 ~22 ~20 quartz_stairs 3 
setblock ~32 ~22 ~22 beacon 0 
setblock ~32 ~22 ~32 beacon 0 
setblock ~32 ~22 ~34 quartz_stairs 2 
setblock ~32 ~22 ~35 quartz_stairs 0 
setblock ~32 ~22 ~36 quartz_block 10 
setblock ~32 ~22 ~37 quartz_block 6 
setblock ~32 ~22 ~38 quartz_block 10 
setblock ~32 ~22 ~39 quartz_block 6  
fill ~32 ~22 ~41 ~35 ~22 ~41 quartz_stairs 7 
setblock ~33 ~22 ~15 quartz_block 10 
setblock ~33 ~22 ~16 quartz_block 6 
setblock ~33 ~22 ~17 quartz_block 10 
setblock ~33 ~22 ~18 quartz_block 6 
setblock ~33 ~22 ~19 quartz_block 10  
fill ~33 ~22 ~20 ~33 ~22 ~21 quartz_stairs 0 
setblock ~33 ~22 ~33 quartz_stairs 2 
setblock ~33 ~22 ~34 quartz_stairs 0 
setblock ~33 ~22 ~35 quartz_block 10 
setblock ~33 ~22 ~36 quartz_block 6 
setblock ~33 ~22 ~37 quartz_block 10 
setblock ~33 ~22 ~38 quartz_block 6 
setblock ~33 ~22 ~39 quartz_block 10  
fill ~34 ~22 ~15 ~36 ~22 ~15 obsidian 0 
setblock ~34 ~22 ~16 quartz_block 10 
setblock ~34 ~22 ~17 quartz_block 6 
setblock ~34 ~22 ~18 quartz_block 10 
setblock ~34 ~22 ~19 quartz_block 6 
setblock ~34 ~22 ~20 quartz_block 10 
setblock ~34 ~22 ~21 quartz_stairs 3 
setblock ~34 ~22 ~22 quartz_stairs 0 
setblock ~34 ~22 ~32 quartz_stairs 2 
setblock ~34 ~22 ~33 quartz_stairs 0 
setblock ~34 ~22 ~34 quartz_block 10 
setblock ~34 ~22 ~35 quartz_block 6 
setblock ~34 ~22 ~36 quartz_block 10 
setblock ~34 ~22 ~37 quartz_block 6 
setblock ~34 ~22 ~38 quartz_block 10  
fill ~34 ~22 ~39 ~36 ~22 ~39 obsidian 0  
fill ~35 ~22 ~13 ~35 ~22 ~14 quartz_stairs 5 
setblock ~35 ~22 ~16 quartz_block 6 
setblock ~35 ~22 ~17 quartz_block 10 
setblock ~35 ~22 ~18 quartz_block 6 
setblock ~35 ~22 ~19 quartz_block 10 
setblock ~35 ~22 ~20 quartz_block 6 
setblock ~35 ~22 ~21 quartz_block 10 
setblock ~35 ~22 ~22 quartz_stairs 3  
fill ~35 ~22 ~23 ~35 ~22 ~24 quartz_stairs 0 
setblock ~35 ~22 ~27 quartz_block 13  
fill ~35 ~22 ~30 ~36 ~22 ~30 quartz_stairs 2  
fill ~35 ~22 ~31 ~35 ~22 ~32 quartz_stairs 0 
setblock ~35 ~22 ~33 quartz_block 10 
setblock ~35 ~22 ~34 quartz_block 6 
setblock ~35 ~22 ~35 quartz_block 10 
setblock ~35 ~22 ~36 quartz_block 6 
setblock ~35 ~22 ~37 quartz_block 10 
setblock ~35 ~22 ~38 quartz_block 6 
setblock ~35 ~22 ~40 quartz_stairs 5 
setblock ~36 ~22 ~14 quartz_stairs 6  
fill ~36 ~22 ~16 ~37 ~22 ~16 obsidian 0  
fill ~36 ~22 ~17 ~36 ~22 ~18 obsidian 0 
setblock ~36 ~22 ~19 quartz_block 6 
setblock ~36 ~22 ~20 quartz_block 10 
setblock ~36 ~22 ~21 quartz_block 6 
setblock ~36 ~22 ~22 quartz_block 10 
setblock ~36 ~22 ~23 quartz_block 6 
setblock ~36 ~22 ~24 quartz_stairs 3  
fill ~36 ~22 ~25 ~36 ~22 ~26 quartz_stairs 0  
fill ~36 ~22 ~27 ~39 ~22 ~27 obsidian 0  
fill ~36 ~22 ~28 ~36 ~22 ~29 quartz_stairs 0 
setblock ~36 ~22 ~31 quartz_block 6 
setblock ~36 ~22 ~32 quartz_block 10 
setblock ~36 ~22 ~33 quartz_block 6 
setblock ~36 ~22 ~34 quartz_block 10 
setblock ~36 ~22 ~35 quartz_block 6  
fill ~36 ~22 ~36 ~39 ~22 ~36 obsidian 0  
fill ~36 ~22 ~37 ~36 ~22 ~39 obsidian 0  
fill ~36 ~22 ~40 ~37 ~22 ~40 quartz_stairs 7  
fill ~37 ~22 ~14 ~37 ~22 ~15 quartz_stairs 5 
setblock ~37 ~22 ~17 quartz_block 0  
fill ~37 ~22 ~18 ~39 ~22 ~18 obsidian 0 
setblock ~37 ~22 ~19 quartz_block 10 
setblock ~37 ~22 ~20 quartz_block 6 
setblock ~37 ~22 ~21 quartz_block 10 
setblock ~37 ~22 ~22 quartz_block 6 
setblock ~37 ~22 ~23 quartz_block 10 
setblock ~37 ~22 ~24 quartz_block 6 
setblock ~37 ~22 ~25 quartz_block 10 
setblock ~37 ~22 ~26 quartz_block 6 
setblock ~37 ~22 ~28 quartz_block 6 
setblock ~37 ~22 ~29 quartz_block 10 
setblock ~37 ~22 ~30 quartz_block 6 
setblock ~37 ~22 ~31 quartz_block 10 
setblock ~37 ~22 ~32 quartz_block 6 
setblock ~37 ~22 ~33 quartz_block 10 
setblock ~37 ~22 ~34 quartz_block 6 
setblock ~37 ~22 ~35 quartz_block 10 
setblock ~37 ~22 ~37 quartz_block 0 
setblock ~37 ~22 ~38 obsidian 0 
setblock ~37 ~22 ~39 quartz_stairs 5 
setblock ~38 ~22 ~15 quartz_stairs 6 
setblock ~38 ~22 ~16 quartz_stairs 5 
setblock ~38 ~22 ~17 obsidian 0 
setblock ~38 ~22 ~19 quartz_block 6 
setblock ~38 ~22 ~20 quartz_block 10 
setblock ~38 ~22 ~21 quartz_block 6 
setblock ~38 ~22 ~22 quartz_block 10 
setblock ~38 ~22 ~23 quartz_block 6 
setblock ~38 ~22 ~24 quartz_block 10 
setblock ~38 ~22 ~25 quartz_block 6 
setblock ~38 ~22 ~26 quartz_block 10 
setblock ~38 ~22 ~28 quartz_block 10 
setblock ~38 ~22 ~29 quartz_block 6 
setblock ~38 ~22 ~30 quartz_block 10 
setblock ~38 ~22 ~31 quartz_block 6 
setblock ~38 ~22 ~32 quartz_block 10 
setblock ~38 ~22 ~33 quartz_block 6 
setblock ~38 ~22 ~34 quartz_block 10 
setblock ~38 ~22 ~35 quartz_block 6 
setblock ~38 ~22 ~37 obsidian 0 
setblock ~38 ~22 ~38 quartz_stairs 5 
setblock ~38 ~22 ~39 quartz_stairs 7 
setblock ~39 ~22 ~16 quartz_stairs 6 
setblock ~39 ~22 ~17 quartz_stairs 5  
fill ~39 ~22 ~19 ~39 ~22 ~20 obsidian 0 
setblock ~39 ~22 ~21 quartz_block 10 
setblock ~39 ~22 ~22 quartz_block 6 
setblock ~39 ~22 ~23 quartz_block 10 
setblock ~39 ~22 ~24 quartz_block 6 
setblock ~39 ~22 ~25 quartz_block 10  
fill ~39 ~22 ~26 ~41 ~22 ~26 obsidian 0  
fill ~39 ~22 ~28 ~41 ~22 ~28 obsidian 0 
setblock ~39 ~22 ~29 quartz_block 10 
setblock ~39 ~22 ~30 quartz_block 6 
setblock ~39 ~22 ~31 quartz_block 10 
setblock ~39 ~22 ~32 quartz_block 6 
setblock ~39 ~22 ~33 quartz_block 10  
fill ~39 ~22 ~34 ~40 ~22 ~34 obsidian 0  
fill ~39 ~22 ~35 ~39 ~22 ~34 obsidian 0 
setblock ~39 ~22 ~37 quartz_stairs 5 
setblock ~39 ~22 ~38 quartz_stairs 7 
setblock ~40 ~22 ~17 quartz_stairs 6  
fill ~40 ~22 ~18 ~40 ~22 ~19 quartz_stairs 5  
fill ~40 ~22 ~20 ~40 ~22 ~24 obsidian 0 
setblock ~40 ~22 ~25 quartz_block 6 
setblock ~40 ~22 ~27 sea_lantern 0 
setblock ~40 ~22 ~29 quartz_block 6  
fill ~40 ~22 ~30 ~41 ~22 ~30 obsidian 0  
fill ~40 ~22 ~31 ~40 ~22 ~34 obsidian 0  
fill ~40 ~22 ~35 ~40 ~22 ~36 quartz_stairs 5 
setblock ~40 ~22 ~37 quartz_stairs 7 
setblock ~41 ~22 ~19 quartz_stairs 6  
fill ~41 ~22 ~20 ~41 ~22 ~23 quartz_stairs 5  
fill ~41 ~22 ~24 ~41 ~22 ~30 obsidian 0  
fill ~41 ~22 ~31 ~41 ~22 ~34 quartz_stairs 5 
setblock ~41 ~22 ~35 quartz_stairs 7 
setblock ~42 ~22 ~23 quartz_stairs 6  
fill ~42 ~22 ~24 ~42 ~22 ~25 quartz_stairs 5  
fill ~42 ~22 ~26 ~43 ~22 ~26 quartz_stairs 6  
fill ~42 ~22 ~27 ~42 ~23 ~27 obsidian 0  
fill ~42 ~22 ~28 ~43 ~22 ~28 quartz_stairs 7  
fill ~42 ~22 ~29 ~42 ~22 ~30 quartz_stairs 5 
setblock ~42 ~22 ~31 quartz_stairs 7 
setblock ~43 ~22 ~27 quartz_stairs 5  
fill ~68 ~22 ~-18 ~72 ~22 ~-18 stone_slab 6  
fill ~68 ~22 ~-17 ~68 ~24 ~-17 stone_slab 6  
fill ~68 ~22 ~-16 ~68 ~24 ~-16 stone_slab 6  
fill ~68 ~22 ~-15 ~68 ~24 ~-15 stone_slab 6  
fill ~68 ~22 ~-14 ~72 ~22 ~-14 stone_slab 6  
fill ~68 ~22 ~68 ~72 ~22 ~68 stone_slab 6  
fill ~68 ~22 ~69 ~68 ~24 ~69 stone_slab 6  
fill ~68 ~22 ~70 ~68 ~24 ~70 stone_slab 6  
fill ~68 ~22 ~71 ~68 ~24 ~71 stone_slab 6  
fill ~68 ~22 ~72 ~72 ~22 ~72 stone_slab 6  
fill ~69 ~22 ~-17 ~71 ~22 ~-17 quartz_stairs 2  
fill ~69 ~22 ~-16 ~69 ~35 ~-16 quartz_stairs 0  
fill ~69 ~22 ~-15 ~69 ~35 ~-15 quartz_stairs 0  
fill ~69 ~22 ~69 ~69 ~22 ~70 quartz_stairs 0  
fill ~69 ~22 ~71 ~71 ~22 ~71 quartz_stairs 3  
fill ~70 ~22 ~-16 ~70 ~36 ~-16 quartz_block 0  
fill ~70 ~22 ~-15 ~71 ~22 ~-15 quartz_stairs 3  
fill ~70 ~22 ~69 ~71 ~22 ~69 quartz_stairs 2  
fill ~70 ~22 ~70 ~70 ~36 ~70 quartz_block 0  
fill ~71 ~22 ~-16 ~71 ~36 ~-16 quartz_stairs 1  
fill ~71 ~22 ~70 ~71 ~36 ~70 quartz_stairs 1  
fill ~72 ~22 ~-17 ~72 ~24 ~-17 stone_slab 6  
fill ~72 ~22 ~-16 ~72 ~24 ~-16 stone_slab 6  
fill ~72 ~22 ~-15 ~72 ~24 ~-15 stone_slab 6  
fill ~72 ~22 ~69 ~72 ~24 ~69 stone_slab 6  
fill ~72 ~22 ~70 ~72 ~24 ~70 stone_slab 6  
fill ~72 ~22 ~71 ~72 ~24 ~71 stone_slab 6  
fill ~86 ~22 ~25 ~90 ~22 ~25 stone_slab 6  
fill ~86 ~22 ~26 ~86 ~24 ~26 stone_slab 6  
fill ~86 ~22 ~27 ~86 ~24 ~27 stone_slab 6  
fill ~86 ~22 ~28 ~86 ~24 ~28 stone_slab 6  
fill ~86 ~22 ~29 ~90 ~22 ~29 stone_slab 6  
fill ~87 ~22 ~26 ~87 ~23 ~26 quartz_stairs 0  
fill ~87 ~22 ~27 ~87 ~35 ~27 quartz_stairs 0  
fill ~87 ~22 ~28 ~89 ~22 ~28 quartz_stairs 3  
fill ~88 ~22 ~26 ~89 ~22 ~26 quartz_stairs 2  
fill ~88 ~22 ~27 ~88 ~35 ~27 planks 0  
fill ~89 ~22 ~27 ~89 ~35 ~27 quartz_stairs 1  
fill ~90 ~22 ~26 ~90 ~24 ~26 stone_slab 6  
fill ~90 ~22 ~27 ~90 ~24 ~27 stone_slab 6  
fill ~90 ~22 ~28 ~90 ~24 ~28 stone_slab 6  
fill ~-37 ~23 ~25 ~-31 ~23 ~25 stone_slab 6  
fill ~-37 ~23 ~26 ~-37 ~23 ~29 stone_slab 6  
fill ~-36 ~23 ~24 ~-32 ~23 ~24 stone_slab 6  
fill ~-36 ~23 ~29 ~-31 ~23 ~29 stone_slab 6  
fill ~-36 ~23 ~30 ~-32 ~23 ~30 stone_slab 6 
setblock ~-35 ~23 ~26 quartz_stairs 0  
fill ~-34 ~23 ~26 ~-34 ~35 ~26 quartz_stairs 2  
fill ~-34 ~23 ~28 ~-33 ~23 ~28 quartz_stairs 3 
setblock ~-33 ~23 ~26 quartz_stairs 1  
fill ~-31 ~23 ~26 ~-31 ~23 ~29 stone_slab 6  
fill ~-19 ~23 ~-18 ~-13 ~23 ~-18 stone_slab 6  
fill ~-19 ~23 ~-17 ~-19 ~23 ~-14 stone_slab 6  
fill ~-19 ~23 ~68 ~-13 ~23 ~68 stone_slab 6  
fill ~-19 ~23 ~69 ~-19 ~23 ~72 stone_slab 6  
fill ~-18 ~23 ~-19 ~-14 ~23 ~-19 stone_slab 6  
fill ~-18 ~23 ~-14 ~-13 ~23 ~-14 stone_slab 6  
fill ~-18 ~23 ~-13 ~-14 ~23 ~-13 stone_slab 6  
fill ~-18 ~23 ~67 ~-14 ~23 ~67 stone_slab 6  
fill ~-18 ~23 ~72 ~-13 ~23 ~72 stone_slab 6  
fill ~-18 ~23 ~73 ~-14 ~23 ~73 stone_slab 6  
fill ~-17 ~23 ~-17 ~-17 ~24 ~-17 quartz_stairs 0  
fill ~-17 ~23 ~69 ~-16 ~23 ~69 quartz_stairs 2  
fill ~-16 ~23 ~-17 ~-15 ~23 ~-17 quartz_stairs 2  
fill ~-16 ~23 ~-15 ~-15 ~23 ~-15 quartz_stairs 3  
fill ~-16 ~23 ~71 ~-15 ~23 ~71 quartz_stairs 3  
fill ~-13 ~23 ~-17 ~-13 ~23 ~-14 stone_slab 6  
fill ~-13 ~23 ~69 ~-13 ~23 ~72 stone_slab 6  
fill ~11 ~23 ~26 ~12 ~23 ~26 stone_slab 6  
fill ~11 ~23 ~27 ~11 ~23 ~28 stone_slab 6  
fill ~12 ~23 ~23 ~13 ~23 ~23 stone_slab 6  
fill ~12 ~23 ~24 ~12 ~23 ~26 stone_slab 6  
fill ~12 ~23 ~27 ~12 ~22 ~27 obsidian 0  
fill ~12 ~23 ~28 ~12 ~23 ~31 stone_slab 6  
fill ~13 ~23 ~19 ~14 ~23 ~19 stone_slab 6  
fill ~13 ~23 ~20 ~13 ~23 ~23 stone_slab 6  
fill ~13 ~23 ~24 ~14 ~23 ~24 quartz_block 0  
fill ~13 ~23 ~25 ~13 ~27 ~25 quartz_block 0  
fill ~13 ~23 ~26 ~13 ~27 ~26 quartz_block 0  
fill ~13 ~23 ~28 ~13 ~27 ~28 quartz_block 0  
fill ~13 ~23 ~29 ~13 ~27 ~29 quartz_block 0  
fill ~13 ~23 ~30 ~14 ~23 ~30 quartz_block 0  
fill ~13 ~23 ~31 ~13 ~23 ~35 stone_slab 6  
fill ~14 ~23 ~17 ~15 ~23 ~17 stone_slab 6  
fill ~14 ~23 ~18 ~14 ~23 ~17 stone_slab 6  
fill ~14 ~23 ~20 ~15 ~23 ~20 quartz_block 0  
fill ~14 ~23 ~21 ~14 ~27 ~21 quartz_block 0  
fill ~14 ~23 ~22 ~14 ~27 ~22 quartz_block 0  
fill ~14 ~23 ~23 ~14 ~27 ~23 quartz_block 0 
setblock ~14 ~23 ~27 iron_trapdoor 3  
fill ~14 ~23 ~31 ~14 ~27 ~31 quartz_block 0  
fill ~14 ~23 ~32 ~14 ~27 ~32 quartz_block 0  
fill ~14 ~23 ~33 ~14 ~27 ~33 quartz_block 0  
fill ~14 ~23 ~34 ~15 ~23 ~34 quartz_block 0  
fill ~14 ~23 ~35 ~14 ~23 ~37 stone_slab 6 
setblock ~15 ~23 ~16 stone_slab 6  
fill ~15 ~23 ~18 ~16 ~23 ~18 quartz_block 0  
fill ~15 ~23 ~19 ~15 ~27 ~19 quartz_block 0  
fill ~15 ~23 ~21 ~15 ~25 ~21 leaves 11 
setblock ~15 ~23 ~22 quartz_stairs 7  
fill ~15 ~23 ~32 ~16 ~23 ~32 quartz_stairs 6  
fill ~15 ~23 ~33 ~15 ~25 ~33 leaves 11  
fill ~15 ~23 ~35 ~15 ~27 ~35 quartz_block 0  
fill ~15 ~23 ~36 ~16 ~23 ~36 quartz_block 0  
fill ~15 ~23 ~37 ~15 ~23 ~38 stone_slab 6  
fill ~16 ~23 ~15 ~17 ~23 ~15 stone_slab 6 
setblock ~16 ~23 ~16 obsidian 0  
fill ~16 ~23 ~17 ~16 ~27 ~17 quartz_block 0 
setblock ~16 ~23 ~20 quartz_stairs 6  
fill ~16 ~23 ~21 ~16 ~23 ~22 quartz_stairs 5 
setblock ~16 ~23 ~33 quartz_stairs 5 
setblock ~16 ~23 ~34 quartz_stairs 7  
fill ~16 ~23 ~37 ~16 ~27 ~37 quartz_block 0 
setblock ~16 ~23 ~38 obsidian 0  
fill ~16 ~23 ~39 ~17 ~23 ~39 stone_slab 6  
fill ~17 ~23 ~14 ~19 ~23 ~14 stone_slab 6  
fill ~17 ~23 ~16 ~18 ~23 ~16 quartz_block 0 
setblock ~17 ~23 ~17 sea_lantern 0  
fill ~17 ~23 ~18 ~18 ~23 ~18 glass 0  
fill ~17 ~23 ~36 ~18 ~23 ~36 glass 0 
setblock ~17 ~23 ~37 sea_lantern 0  
fill ~17 ~23 ~38 ~18 ~23 ~38 quartz_block 0  
fill ~17 ~23 ~40 ~19 ~23 ~40 stone_slab 6  
fill ~18 ~23 ~15 ~20 ~23 ~15 quartz_block 0  
fill ~18 ~23 ~17 ~18 ~24 ~17 glass 0 
setblock ~18 ~23 ~27 crafting_table 0  
fill ~18 ~23 ~37 ~18 ~24 ~37 glass 0  
fill ~18 ~23 ~39 ~20 ~23 ~39 quartz_block 0  
fill ~19 ~23 ~13 ~23 ~23 ~13 stone_slab 6  
fill ~19 ~23 ~27 ~19 ~26 ~27 quartz_block 2  
fill ~19 ~23 ~41 ~23 ~23 ~41 stone_slab 6  
fill ~20 ~23 ~14 ~24 ~23 ~14 quartz_block 0  
fill ~20 ~23 ~40 ~24 ~23 ~40 quartz_block 0  
fill ~23 ~23 ~12 ~26 ~23 ~12 stone_slab 6  
fill ~23 ~23 ~42 ~26 ~23 ~42 stone_slab 6  
fill ~24 ~23 ~-36 ~30 ~23 ~-36 stone_slab 6  
fill ~24 ~23 ~-35 ~24 ~23 ~-32 stone_slab 6  
fill ~24 ~23 ~13 ~26 ~23 ~13 quartz_block 0  
fill ~24 ~23 ~41 ~26 ~23 ~41 quartz_block 0  
fill ~24 ~23 ~86 ~30 ~23 ~86 stone_slab 6  
fill ~24 ~23 ~87 ~24 ~23 ~90 stone_slab 6  
fill ~25 ~23 ~-37 ~29 ~23 ~-37 stone_slab 6  
fill ~25 ~23 ~-32 ~30 ~23 ~-32 stone_slab 6  
fill ~25 ~23 ~-31 ~29 ~23 ~-31 stone_slab 6  
fill ~25 ~23 ~85 ~29 ~23 ~85 stone_slab 6  
fill ~25 ~23 ~90 ~30 ~23 ~90 stone_slab 6  
fill ~25 ~23 ~91 ~29 ~23 ~91 stone_slab 6  
fill ~26 ~23 ~11 ~28 ~23 ~11 stone_slab 6  
fill ~26 ~23 ~43 ~28 ~23 ~43 stone_slab 6 
setblock ~26 ~23 ~87 quartz_stairs 0  
fill ~26 ~23 ~89 ~27 ~23 ~89 quartz_stairs 3  
fill ~27 ~23 ~-35 ~28 ~23 ~-35 quartz_stairs 2 
setblock ~27 ~23 ~14 iron_trapdoor 1 
setblock ~27 ~23 ~18 crafting_table 0  
fill ~27 ~23 ~19 ~27 ~26 ~19 quartz_block 2  
fill ~27 ~23 ~35 ~27 ~26 ~35 quartz_block 2 
setblock ~27 ~23 ~36 crafting_table 0 
setblock ~27 ~23 ~40 iron_trapdoor 0  
fill ~27 ~23 ~87 ~28 ~23 ~87 quartz_stairs 2  
fill ~28 ~23 ~12 ~31 ~23 ~12 stone_slab 6  
fill ~28 ~23 ~13 ~30 ~23 ~13 quartz_block 0  
fill ~28 ~23 ~41 ~30 ~23 ~41 quartz_block 0  
fill ~28 ~23 ~42 ~31 ~23 ~42 stone_slab 6  
fill ~30 ~23 ~-35 ~30 ~23 ~-32 stone_slab 6  
fill ~30 ~23 ~14 ~34 ~23 ~14 quartz_block 0  
fill ~30 ~23 ~40 ~34 ~23 ~40 quartz_block 0  
fill ~30 ~23 ~87 ~30 ~23 ~90 stone_slab 6  
fill ~31 ~23 ~13 ~35 ~23 ~13 stone_slab 6 
setblock ~31 ~23 ~15 quartz_stairs 4  
fill ~31 ~23 ~16 ~33 ~23 ~16 quartz_stairs 7  
fill ~31 ~23 ~41 ~35 ~23 ~41 stone_slab 6  
fill ~33 ~23 ~15 ~33 ~25 ~15 leaves 15  
fill ~34 ~23 ~15 ~36 ~23 ~15 quartz_block 0 
setblock ~34 ~23 ~16 quartz_stairs 5  
fill ~34 ~23 ~39 ~36 ~23 ~39 quartz_block 0  
fill ~35 ~23 ~14 ~37 ~23 ~14 stone_slab 6  
fill ~35 ~23 ~27 ~35 ~26 ~27 quartz_block 2  
fill ~35 ~23 ~40 ~37 ~23 ~40 stone_slab 6  
fill ~36 ~23 ~16 ~37 ~23 ~16 quartz_block 0  
fill ~36 ~23 ~17 ~36 ~24 ~17 glass 0  
fill ~36 ~23 ~18 ~37 ~23 ~18 glass 0 
setblock ~36 ~23 ~27 crafting_table 0  
fill ~36 ~23 ~36 ~37 ~23 ~36 glass 0  
fill ~36 ~23 ~37 ~36 ~24 ~37 glass 0  
fill ~36 ~23 ~38 ~37 ~23 ~38 quartz_block 0  
fill ~37 ~23 ~15 ~38 ~23 ~15 stone_slab 6 
setblock ~37 ~23 ~17 sea_lantern 0 
setblock ~37 ~23 ~37 sea_lantern 0 
fill ~37 ~23 ~39 ~38 ~23 ~39 stone_slab 6 
setblock ~38 ~23 ~16 obsidian 0  
fill ~38 ~23 ~17 ~38 ~27 ~17 quartz_block 0  
fill ~38 ~23 ~18 ~39 ~23 ~18 quartz_block 0  
fill ~38 ~23 ~32 ~38 ~23 ~33 quartz_stairs 4 
setblock ~38 ~23 ~34 quartz_stairs 7  
fill ~38 ~23 ~36 ~39 ~23 ~36 quartz_block 0  
fill ~38 ~23 ~37 ~38 ~27 ~37 quartz_block 0 
setblock ~38 ~23 ~38 obsidian 0  
fill ~39 ~23 ~16 ~39 ~23 ~17 stone_slab 6  
fill ~39 ~23 ~19 ~39 ~27 ~19 quartz_block 0  
fill ~39 ~23 ~20 ~40 ~23 ~20 quartz_block 0 
setblock ~39 ~23 ~32 quartz_stairs 6  
fill ~39 ~23 ~33 ~39 ~25 ~33 leaves 11  
fill ~39 ~23 ~34 ~40 ~23 ~34 quartz_block 0  
fill ~39 ~23 ~35 ~39 ~27 ~35 quartz_block 0  
fill ~39 ~23 ~37 ~40 ~23 ~37 stone_slab 6  
fill ~39 ~23 ~38 ~39 ~23 ~37 stone_slab 6  
fill ~40 ~23 ~17 ~40 ~23 ~19 stone_slab 6  
fill ~40 ~23 ~21 ~40 ~27 ~21 quartz_block 0  
fill ~40 ~23 ~22 ~40 ~27 ~22 quartz_block 0  
fill ~40 ~23 ~23 ~40 ~27 ~23 quartz_block 0  
fill ~40 ~23 ~24 ~41 ~23 ~24 quartz_block 0 
setblock ~40 ~23 ~27 iron_trapdoor 2  
fill ~40 ~23 ~30 ~41 ~23 ~30 quartz_block 0  
fill ~40 ~23 ~31 ~40 ~27 ~31 quartz_block 0  
fill ~40 ~23 ~32 ~40 ~27 ~32 quartz_block 0  
fill ~40 ~23 ~33 ~40 ~27 ~33 quartz_block 0  
fill ~40 ~23 ~35 ~41 ~23 ~35 stone_slab 6  
fill ~40 ~23 ~36 ~40 ~23 ~35 stone_slab 6  
fill ~41 ~23 ~19 ~41 ~23 ~23 stone_slab 6  
fill ~41 ~23 ~25 ~41 ~27 ~25 quartz_block 0  
fill ~41 ~23 ~26 ~41 ~27 ~26 quartz_block 0  
fill ~41 ~23 ~28 ~41 ~27 ~28 quartz_block 0  
fill ~41 ~23 ~29 ~41 ~27 ~29 quartz_block 0  
fill ~41 ~23 ~31 ~42 ~23 ~31 stone_slab 6  
fill ~41 ~23 ~32 ~41 ~23 ~35 stone_slab 6  
fill ~42 ~23 ~23 ~42 ~23 ~26 stone_slab 6  
fill ~42 ~23 ~28 ~43 ~23 ~28 stone_slab 6  
fill ~42 ~23 ~29 ~42 ~23 ~31 stone_slab 6  
fill ~43 ~23 ~26 ~43 ~23 ~28 stone_slab 6  
fill ~67 ~23 ~-18 ~73 ~23 ~-18 stone_slab 6  
fill ~67 ~23 ~-17 ~67 ~23 ~-14 stone_slab 6  
fill ~67 ~23 ~68 ~73 ~23 ~68 stone_slab 6  
fill ~67 ~23 ~69 ~67 ~23 ~72 stone_slab 6  
fill ~68 ~23 ~-19 ~72 ~23 ~-19 stone_slab 6  
fill ~68 ~23 ~-14 ~73 ~23 ~-14 stone_slab 6  
fill ~68 ~23 ~-13 ~72 ~23 ~-13 stone_slab 6  
fill ~68 ~23 ~67 ~72 ~23 ~67 stone_slab 6  
fill ~68 ~23 ~72 ~73 ~23 ~72 stone_slab 6  
fill ~68 ~23 ~73 ~72 ~23 ~73 stone_slab 6  
fill ~69 ~23 ~-17 ~70 ~23 ~-17 quartz_stairs 2  
fill ~69 ~23 ~69 ~70 ~23 ~69 quartz_stairs 2  
fill ~69 ~23 ~70 ~69 ~35 ~70 quartz_stairs 0  
fill ~69 ~23 ~71 ~69 ~33 ~71 quartz_stairs 0  
fill ~70 ~23 ~-15 ~71 ~23 ~-15 quartz_stairs 3  
fill ~70 ~23 ~71 ~71 ~23 ~71 quartz_stairs 3  
fill ~71 ~23 ~-17 ~71 ~36 ~-17 quartz_stairs 1  
fill ~71 ~23 ~69 ~71 ~24 ~69 quartz_stairs 1  
fill ~73 ~23 ~-17 ~73 ~23 ~-14 stone_slab 6  
fill ~73 ~23 ~69 ~73 ~23 ~72 stone_slab 6  
fill ~85 ~23 ~25 ~91 ~23 ~25 stone_slab 6  
fill ~85 ~23 ~26 ~85 ~23 ~29 stone_slab 6  
fill ~86 ~23 ~24 ~90 ~23 ~24 stone_slab 6  
fill ~86 ~23 ~29 ~91 ~23 ~29 stone_slab 6  
fill ~86 ~23 ~30 ~90 ~23 ~30 stone_slab 6  
fill ~87 ~23 ~28 ~89 ~23 ~28 quartz_stairs 3  
fill ~88 ~23 ~26 ~89 ~23 ~26 quartz_stairs 2  
fill ~91 ~23 ~26 ~91 ~23 ~29 stone_slab 6  
fill ~-36 ~24 ~25 ~-32 ~24 ~25 stone_slab 6  
fill ~-36 ~24 ~29 ~-32 ~24 ~29 stone_slab 6  
fill ~-35 ~24 ~26 ~-35 ~30 ~26 quartz_stairs 2  
fill ~-35 ~24 ~28 ~-34 ~24 ~28 quartz_stairs 3  
fill ~-33 ~24 ~26 ~-33 ~26 ~26 quartz_stairs 2  
fill ~-33 ~24 ~28 ~-33 ~26 ~28 quartz_stairs 1  
fill ~-18 ~24 ~-18 ~-14 ~24 ~-18 stone_slab 6  
fill ~-18 ~24 ~-14 ~-14 ~24 ~-14 stone_slab 6  
fill ~-18 ~24 ~68 ~-14 ~24 ~68 stone_slab 6  
fill ~-18 ~24 ~72 ~-14 ~24 ~72 stone_slab 6  
fill ~-17 ~24 ~69 ~-16 ~24 ~69 quartz_stairs 2  
fill ~-16 ~24 ~-17 ~-15 ~24 ~-17 quartz_stairs 2  
fill ~-16 ~24 ~-15 ~-15 ~24 ~-15 quartz_stairs 3  
fill ~-16 ~24 ~71 ~-15 ~24 ~71 quartz_stairs 3 
setblock ~12 ~24 ~27 beacon 0  
fill ~13 ~24 ~24 ~14 ~24 ~24 quartz_block 0  
fill ~13 ~24 ~30 ~14 ~24 ~30 quartz_block 0  
fill ~14 ~24 ~20 ~15 ~24 ~20 quartz_block 0  
fill ~14 ~24 ~34 ~15 ~24 ~34 quartz_block 0  
fill ~15 ~24 ~18 ~16 ~24 ~18 quartz_block 0  
fill ~15 ~24 ~36 ~16 ~24 ~36 quartz_block 0 
setblock ~16 ~24 ~16 beacon 0 
setblock ~16 ~24 ~34 leaves 11 
setblock ~16 ~24 ~38 beacon 0  
fill ~17 ~24 ~16 ~18 ~24 ~16 quartz_block 0  
fill ~17 ~24 ~17 ~17 ~24 ~18 glass 0  
fill ~17 ~24 ~36 ~18 ~24 ~36 glass 0  
fill ~17 ~24 ~37 ~17 ~24 ~36 glass 0  
fill ~17 ~24 ~38 ~18 ~24 ~38 quartz_block 0  
fill ~18 ~24 ~15 ~20 ~24 ~15 quartz_block 0 
setblock ~18 ~24 ~18 glass 0 
setblock ~18 ~24 ~27 ender_chest 4  
fill ~18 ~24 ~39 ~20 ~24 ~39 quartz_block 0  
fill ~20 ~24 ~14 ~24 ~24 ~14 quartz_block 0  
fill ~20 ~24 ~40 ~24 ~24 ~40 quartz_block 0  
fill ~24 ~24 ~13 ~26 ~24 ~13 quartz_block 0  
fill ~24 ~24 ~41 ~26 ~24 ~41 quartz_block 0  
fill ~25 ~24 ~-36 ~29 ~24 ~-36 stone_slab 6  
fill ~25 ~24 ~-32 ~29 ~24 ~-32 stone_slab 6  
fill ~25 ~24 ~86 ~29 ~24 ~86 stone_slab 6  
fill ~25 ~24 ~90 ~29 ~24 ~90 stone_slab 6  
fill ~26 ~24 ~-35 ~28 ~24 ~-35 quartz_stairs 2  
fill ~26 ~24 ~-33 ~26 ~26 ~-33 quartz_stairs 3  
fill ~26 ~24 ~87 ~28 ~24 ~87 quartz_stairs 2  
fill ~26 ~24 ~89 ~27 ~24 ~89 quartz_stairs 3 
setblock ~27 ~24 ~12 beacon 0 
setblock ~27 ~24 ~18 ender_chest 2 
setblock ~27 ~24 ~36 ender_chest 3 
setblock ~27 ~24 ~42 beacon 0 
setblock ~28 ~24 ~-33 quartz_stairs 3  
fill ~28 ~24 ~13 ~30 ~24 ~13 quartz_block 0  
fill ~28 ~24 ~41 ~30 ~24 ~41 quartz_block 0  
fill ~30 ~24 ~14 ~34 ~24 ~14 quartz_block 0  
fill ~30 ~24 ~40 ~34 ~24 ~40 quartz_block 0  
fill ~32 ~24 ~15 ~32 ~24 ~16 leaves 15  
fill ~34 ~24 ~15 ~36 ~24 ~15 quartz_block 0 
setblock ~34 ~24 ~16 leaves 15  
fill ~34 ~24 ~39 ~36 ~24 ~39 quartz_block 0  
fill ~36 ~24 ~16 ~37 ~24 ~16 quartz_block 0  
fill ~36 ~24 ~18 ~37 ~24 ~18 glass 0 
setblock ~36 ~24 ~27 ender_chest 5  
fill ~36 ~24 ~36 ~37 ~24 ~36 glass 0  
fill ~36 ~24 ~38 ~37 ~24 ~38 quartz_block 0 
setblock ~37 ~24 ~17 glass 0 
setblock ~37 ~24 ~37 glass 0 
setblock ~38 ~24 ~16 beacon 0  
fill ~38 ~24 ~18 ~39 ~24 ~18 quartz_block 0  
fill ~38 ~24 ~32 ~39 ~24 ~32 leaves 11  
fill ~38 ~24 ~36 ~39 ~24 ~36 quartz_block 0 
setblock ~38 ~24 ~38 beacon 0  
fill ~39 ~24 ~20 ~40 ~24 ~20 quartz_block 0  
fill ~39 ~24 ~34 ~40 ~24 ~34 quartz_block 0  
fill ~40 ~24 ~24 ~41 ~24 ~24 quartz_block 0  
fill ~40 ~24 ~30 ~41 ~24 ~30 quartz_block 0 
setblock ~42 ~24 ~27 beacon 0  
fill ~68 ~24 ~-18 ~72 ~24 ~-18 stone_slab 6  
fill ~68 ~24 ~-14 ~72 ~24 ~-14 stone_slab 6  
fill ~68 ~24 ~68 ~72 ~24 ~68 stone_slab 6  
fill ~68 ~24 ~72 ~72 ~24 ~72 stone_slab 6  
fill ~69 ~24 ~-17 ~70 ~24 ~-17 quartz_stairs 2  
fill ~69 ~24 ~69 ~70 ~24 ~69 quartz_stairs 2  
fill ~70 ~24 ~-15 ~71 ~24 ~-15 quartz_stairs 3  
fill ~70 ~24 ~71 ~71 ~24 ~71 quartz_stairs 3  
fill ~86 ~24 ~25 ~90 ~24 ~25 stone_slab 6  
fill ~86 ~24 ~29 ~90 ~24 ~29 stone_slab 6  
fill ~87 ~24 ~26 ~88 ~24 ~26 quartz_stairs 2  
fill ~87 ~24 ~28 ~89 ~24 ~28 quartz_stairs 3 
setblock ~89 ~24 ~26 quartz_stairs 1  
fill ~-35 ~25 ~28 ~-34 ~25 ~28 quartz_stairs 3  
fill ~-17 ~25 ~-17 ~-15 ~25 ~-17 quartz_stairs 2  
fill ~-17 ~25 ~69 ~-16 ~25 ~69 quartz_stairs 2  
fill ~-16 ~25 ~-15 ~-15 ~25 ~-15 quartz_stairs 3  
fill ~-16 ~25 ~71 ~-15 ~25 ~71 quartz_stairs 3 
setblock ~12 ~25 ~27 obsidian 0  
fill ~13 ~25 ~24 ~14 ~25 ~24 quartz_block 0  
fill ~13 ~25 ~30 ~14 ~25 ~30 quartz_block 0  
fill ~14 ~25 ~20 ~15 ~25 ~20 quartz_block 0  
fill ~14 ~25 ~34 ~15 ~25 ~34 quartz_block 0  
fill ~15 ~25 ~18 ~16 ~25 ~18 quartz_block 0  
fill ~15 ~25 ~36 ~16 ~25 ~36 quartz_block 0 
setblock ~16 ~25 ~16 obsidian 0 
setblock ~16 ~25 ~38 obsidian 0  
fill ~17 ~25 ~16 ~18 ~25 ~16 quartz_block 0  
fill ~17 ~25 ~38 ~18 ~25 ~38 quartz_block 0  
fill ~18 ~25 ~15 ~20 ~25 ~15 quartz_block 0  
fill ~18 ~25 ~39 ~20 ~25 ~39 quartz_block 0  
fill ~20 ~25 ~14 ~24 ~25 ~14 quartz_block 0  
fill ~20 ~25 ~40 ~24 ~25 ~40 quartz_block 0  
fill ~24 ~25 ~13 ~26 ~25 ~13 quartz_block 0  
fill ~24 ~25 ~41 ~26 ~25 ~41 quartz_block 0  
fill ~26 ~25 ~-35 ~26 ~26 ~-35 quartz_stairs 0  
fill ~26 ~25 ~87 ~26 ~26 ~87 quartz_stairs 0  
fill ~26 ~25 ~89 ~27 ~25 ~89 quartz_stairs 3  
fill ~27 ~25 ~-35 ~27 ~35 ~-35 quartz_stairs 2 
setblock ~27 ~25 ~12 obsidian 0 
setblock ~27 ~25 ~42 obsidian 0  
fill ~27 ~25 ~87 ~27 ~35 ~87 quartz_stairs 2  
fill ~28 ~25 ~-35 ~28 ~32 ~-35 quartz_stairs 1  
fill ~28 ~25 ~-33 ~28 ~26 ~-33 quartz_stairs 1  
fill ~28 ~25 ~13 ~30 ~25 ~13 quartz_block 0  
fill ~28 ~25 ~41 ~30 ~25 ~41 quartz_block 0  
fill ~28 ~25 ~87 ~28 ~34 ~87 quartz_stairs 1  
fill ~30 ~25 ~14 ~34 ~25 ~14 quartz_block 0  
fill ~30 ~25 ~40 ~34 ~25 ~40 quartz_block 0  
fill ~34 ~25 ~15 ~36 ~25 ~15 quartz_block 0  
fill ~34 ~25 ~39 ~36 ~25 ~39 quartz_block 0  
fill ~36 ~25 ~16 ~37 ~25 ~16 quartz_block 0  
fill ~36 ~25 ~38 ~37 ~25 ~38 quartz_block 0 
setblock ~38 ~25 ~16 obsidian 0  
fill ~38 ~25 ~18 ~39 ~25 ~18 quartz_block 0  
fill ~38 ~25 ~36 ~39 ~25 ~36 quartz_block 0 
setblock ~38 ~25 ~38 obsidian 0  
fill ~39 ~25 ~20 ~40 ~25 ~20 quartz_block 0  
fill ~39 ~25 ~34 ~40 ~25 ~34 quartz_block 0  
fill ~40 ~25 ~24 ~41 ~25 ~24 quartz_block 0  
fill ~40 ~25 ~30 ~41 ~25 ~30 quartz_block 0 
setblock ~42 ~25 ~27 obsidian 0  
fill ~69 ~25 ~-17 ~70 ~25 ~-17 quartz_stairs 2  
fill ~69 ~25 ~69 ~71 ~25 ~69 quartz_stairs 2  
fill ~70 ~25 ~-15 ~71 ~25 ~-15 quartz_stairs 3  
fill ~70 ~25 ~71 ~70 ~36 ~71 quartz_stairs 3  
fill ~71 ~25 ~71 ~71 ~35 ~71 quartz_stairs 1  
fill ~87 ~25 ~26 ~89 ~25 ~26 quartz_stairs 2  
fill ~87 ~25 ~28 ~88 ~25 ~28 quartz_stairs 3  
fill ~89 ~25 ~28 ~89 ~26 ~28 quartz_stairs 1  
fill ~-35 ~26 ~28 ~-34 ~26 ~28 quartz_stairs 3  
fill ~-17 ~26 ~-17 ~-15 ~26 ~-17 quartz_stairs 2  
fill ~-17 ~26 ~69 ~-16 ~26 ~69 quartz_stairs 2  
fill ~-16 ~26 ~-15 ~-15 ~26 ~-15 quartz_stairs 3  
fill ~-16 ~26 ~71 ~-15 ~26 ~71 quartz_stairs 3 
setblock ~12 ~26 ~27 quartz_stairs 0  
fill ~13 ~26 ~24 ~14 ~26 ~24 quartz_block 0 
setblock ~13 ~26 ~27 quartz_stairs 5  
fill ~13 ~26 ~30 ~14 ~26 ~30 quartz_block 0  
fill ~14 ~26 ~20 ~15 ~26 ~20 quartz_block 0  
fill ~14 ~26 ~34 ~15 ~26 ~34 quartz_block 0  
fill ~15 ~26 ~18 ~16 ~26 ~18 quartz_block 0  
fill ~15 ~26 ~36 ~16 ~26 ~36 quartz_block 0 
setblock ~16 ~26 ~16 stone_slab 6 
setblock ~16 ~26 ~38 stone_slab 6  
fill ~17 ~26 ~16 ~18 ~26 ~16 quartz_block 0  
fill ~17 ~26 ~38 ~18 ~26 ~38 quartz_block 0  
fill ~18 ~26 ~15 ~20 ~26 ~15 quartz_block 0  
fill ~18 ~26 ~39 ~20 ~26 ~39 quartz_block 0  
fill ~20 ~26 ~14 ~24 ~26 ~14 quartz_block 0 
setblock ~20 ~26 ~27 wool 0  
fill ~20 ~26 ~40 ~24 ~26 ~40 quartz_block 0  
fill ~24 ~26 ~13 ~26 ~26 ~13 quartz_block 0  
fill ~24 ~26 ~41 ~26 ~26 ~41 quartz_block 0  
fill ~26 ~26 ~89 ~27 ~26 ~89 quartz_stairs 3 
setblock ~27 ~26 ~12 quartz_stairs 2 
setblock ~27 ~26 ~13 quartz_stairs 7 
setblock ~27 ~26 ~41 quartz_stairs 6 
setblock ~27 ~26 ~42 quartz_stairs 3  
fill ~28 ~26 ~13 ~30 ~26 ~13 quartz_block 0  
fill ~28 ~26 ~41 ~30 ~26 ~41 quartz_block 0  
fill ~30 ~26 ~14 ~34 ~26 ~14 quartz_block 0  
fill ~30 ~26 ~40 ~34 ~26 ~40 quartz_block 0  
fill ~34 ~26 ~15 ~36 ~26 ~15 quartz_block 0 
setblock ~34 ~26 ~27 wool 0  
fill ~34 ~26 ~39 ~36 ~26 ~39 quartz_block 0  
fill ~36 ~26 ~16 ~37 ~26 ~16 quartz_block 0  
fill ~36 ~26 ~38 ~37 ~26 ~38 quartz_block 0 
setblock ~38 ~26 ~16 stone_slab 6  
fill ~38 ~26 ~18 ~39 ~26 ~18 quartz_block 0  
fill ~38 ~26 ~36 ~39 ~26 ~36 quartz_block 0 
setblock ~38 ~26 ~38 stone_slab 6  
fill ~39 ~26 ~20 ~40 ~26 ~20 quartz_block 0  
fill ~39 ~26 ~34 ~40 ~26 ~34 quartz_block 0  
fill ~40 ~26 ~24 ~41 ~26 ~24 quartz_block 0  
fill ~40 ~26 ~30 ~41 ~26 ~30 quartz_block 0 
setblock ~41 ~26 ~27 quartz_stairs 4 
setblock ~42 ~26 ~27 quartz_stairs 1  
fill ~69 ~26 ~-17 ~70 ~26 ~-17 quartz_stairs 2  
fill ~69 ~26 ~69 ~71 ~26 ~69 quartz_stairs 2  
fill ~70 ~26 ~-15 ~71 ~26 ~-15 quartz_stairs 3  
fill ~87 ~26 ~26 ~89 ~26 ~26 quartz_stairs 2  
fill ~87 ~26 ~28 ~88 ~26 ~28 quartz_stairs 3  
fill ~-35 ~27 ~28 ~-33 ~27 ~28 quartz_stairs 3  
fill ~-33 ~27 ~26 ~-33 ~28 ~26 quartz_stairs 1  
fill ~-17 ~27 ~-17 ~-16 ~27 ~-17 quartz_stairs 2  
fill ~-17 ~27 ~69 ~-16 ~27 ~69 quartz_stairs 2  
fill ~-16 ~27 ~-15 ~-16 ~35 ~-15 quartz_stairs 3  
fill ~-16 ~27 ~71 ~-15 ~27 ~71 quartz_stairs 3  
fill ~-15 ~27 ~-17 ~-15 ~33 ~-17 quartz_stairs 1  
fill ~-15 ~27 ~-15 ~-15 ~28 ~-15 quartz_stairs 1  
fill ~13 ~27 ~24 ~14 ~27 ~24 quartz_block 0 
setblock ~13 ~27 ~27 quartz_block 0  
fill ~13 ~27 ~30 ~14 ~27 ~30 quartz_block 0  
fill ~14 ~27 ~20 ~15 ~27 ~20 quartz_block 0  
fill ~14 ~27 ~25 ~21 ~27 ~25 obsidian 0  
fill ~14 ~27 ~26 ~15 ~27 ~26 obsidian 0  
fill ~14 ~27 ~27 ~14 ~27 ~29 obsidian 0  
fill ~14 ~27 ~34 ~15 ~27 ~34 quartz_block 0  
fill ~15 ~27 ~18 ~16 ~27 ~18 quartz_block 0  
fill ~15 ~27 ~21 ~17 ~27 ~21 obsidian 0  
fill ~15 ~27 ~22 ~16 ~27 ~22 obsidian 0  
fill ~15 ~27 ~23 ~16 ~27 ~23 obsidian 0  
fill ~15 ~27 ~24 ~16 ~27 ~24 obsidian 0 
setblock ~15 ~27 ~27 sea_lantern 0  
fill ~15 ~27 ~28 ~15 ~33 ~28 obsidian 0  
fill ~15 ~27 ~29 ~21 ~27 ~29 obsidian 0  
fill ~15 ~27 ~30 ~16 ~27 ~30 obsidian 0  
fill ~15 ~27 ~31 ~16 ~27 ~31 obsidian 0  
fill ~15 ~27 ~32 ~16 ~27 ~32 obsidian 0  
fill ~15 ~27 ~33 ~17 ~27 ~33 obsidian 0  
fill ~15 ~27 ~36 ~16 ~27 ~36 quartz_block 0  
fill ~16 ~27 ~19 ~18 ~27 ~19 obsidian 0  
fill ~16 ~27 ~20 ~17 ~27 ~20 obsidian 0 
setblock ~16 ~27 ~26 quartz_stairs 7 
setblock ~16 ~27 ~27 quartz_stairs 5 
setblock ~16 ~27 ~28 quartz_stairs 6  
fill ~16 ~27 ~34 ~17 ~27 ~34 obsidian 0  
fill ~16 ~27 ~35 ~18 ~27 ~35 obsidian 0  
fill ~17 ~27 ~16 ~18 ~27 ~16 quartz_block 0  
fill ~17 ~27 ~17 ~17 ~27 ~16 quartz_block 0 
setblock ~17 ~27 ~18 obsidian 0  
fill ~17 ~27 ~22 ~17 ~27 ~24 quartz_stairs 5 
setblock ~17 ~27 ~26 quartz_stairs 5  
fill ~17 ~27 ~27 ~18 ~27 ~27 stone_slab 14 
setblock ~17 ~27 ~28 quartz_stairs 5  
fill ~17 ~27 ~30 ~17 ~27 ~31 quartz_stairs 5 
setblock ~17 ~27 ~32 quartz_stairs 6 
setblock ~17 ~27 ~36 obsidian 0  
fill ~17 ~27 ~37 ~17 ~27 ~38 quartz_block 0  
fill ~18 ~27 ~15 ~20 ~27 ~15 quartz_block 0  
fill ~18 ~27 ~17 ~21 ~27 ~17 obsidian 0 
setblock ~18 ~27 ~18 sea_lantern 0  
fill ~18 ~27 ~20 ~18 ~27 ~21 quartz_stairs 5 
setblock ~18 ~27 ~22 quartz_stairs 7  
fill ~18 ~27 ~23 ~20 ~27 ~23 stone_slab 14  
fill ~18 ~27 ~24 ~20 ~27 ~24 stone_slab 14  
fill ~18 ~27 ~26 ~20 ~27 ~26 stone_slab 14  
fill ~18 ~27 ~28 ~20 ~27 ~28 stone_slab 14  
fill ~18 ~27 ~30 ~20 ~27 ~30 stone_slab 14  
fill ~18 ~27 ~31 ~20 ~27 ~31 stone_slab 14  
fill ~18 ~27 ~32 ~18 ~27 ~33 quartz_stairs 5 
setblock ~18 ~27 ~34 quartz_stairs 6 
setblock ~18 ~27 ~36 sea_lantern 0  
fill ~18 ~27 ~37 ~21 ~27 ~37 obsidian 0  
fill ~18 ~27 ~38 ~18 ~27 ~39 quartz_block 0  
fill ~19 ~27 ~16 ~25 ~27 ~16 obsidian 0  
fill ~19 ~27 ~18 ~19 ~33 ~18 obsidian 0 
setblock ~19 ~27 ~19 quartz_stairs 5 
setblock ~19 ~27 ~20 quartz_stairs 7  
fill ~19 ~27 ~21 ~21 ~27 ~21 stone_slab 14  
fill ~19 ~27 ~22 ~20 ~27 ~22 stone_slab 14 
setblock ~19 ~27 ~27 quartz_block 13  
fill ~19 ~27 ~32 ~20 ~27 ~32 stone_slab 14  
fill ~19 ~27 ~33 ~21 ~27 ~33 stone_slab 14 
setblock ~19 ~27 ~34 quartz_stairs 5 
setblock ~19 ~27 ~35 quartz_stairs 6  
fill ~19 ~27 ~36 ~19 ~33 ~36 obsidian 0  
fill ~19 ~27 ~38 ~25 ~27 ~38 obsidian 0  
fill ~19 ~27 ~39 ~20 ~27 ~39 quartz_block 0  
fill ~20 ~27 ~14 ~24 ~27 ~14 quartz_block 0 
setblock ~20 ~27 ~18 quartz_stairs 5 
setblock ~20 ~27 ~19 quartz_stairs 7  
fill ~20 ~27 ~20 ~24 ~27 ~20 stone_slab 14  
fill ~20 ~27 ~27 ~23 ~27 ~27 obsidian 0  
fill ~20 ~27 ~34 ~24 ~27 ~34 stone_slab 14 
setblock ~20 ~27 ~35 quartz_stairs 5  
fill ~20 ~27 ~36 ~21 ~27 ~36 quartz_stairs 6  
fill ~20 ~27 ~40 ~24 ~27 ~40 quartz_block 0  
fill ~21 ~27 ~15 ~26 ~27 ~15 obsidian 0  
fill ~21 ~27 ~18 ~22 ~27 ~18 quartz_stairs 7  
fill ~21 ~27 ~19 ~24 ~27 ~19 stone_slab 14  
fill ~21 ~27 ~22 ~22 ~27 ~22 obsidian 0  
fill ~21 ~27 ~23 ~21 ~27 ~32 obsidian 0  
fill ~21 ~27 ~35 ~24 ~27 ~35 stone_slab 14  
fill ~21 ~27 ~39 ~26 ~27 ~39 obsidian 0 
setblock ~22 ~27 ~17 quartz_stairs 5  
fill ~22 ~27 ~21 ~32 ~27 ~21 obsidian 0  
fill ~22 ~27 ~23 ~26 ~27 ~23 stone_slab 14  
fill ~22 ~27 ~24 ~26 ~27 ~24 stone_slab 14  
fill ~22 ~27 ~25 ~25 ~27 ~25 stone_slab 14  
fill ~22 ~27 ~26 ~24 ~27 ~26 stone_slab 14  
fill ~22 ~27 ~28 ~24 ~27 ~28 stone_slab 14  
fill ~22 ~27 ~29 ~25 ~27 ~29 stone_slab 14  
fill ~22 ~27 ~30 ~26 ~27 ~30 stone_slab 14  
fill ~22 ~27 ~31 ~26 ~27 ~31 stone_slab 14  
fill ~22 ~27 ~32 ~22 ~27 ~33 obsidian 0 
setblock ~22 ~27 ~36 quartz_stairs 5  
fill ~22 ~27 ~37 ~24 ~27 ~37 quartz_stairs 6  
fill ~23 ~27 ~17 ~24 ~27 ~17 quartz_stairs 7  
fill ~23 ~27 ~18 ~24 ~27 ~18 stone_slab 14  
fill ~23 ~27 ~22 ~26 ~27 ~22 stone_slab 14  
fill ~23 ~27 ~32 ~26 ~27 ~32 stone_slab 14  
fill ~23 ~27 ~33 ~32 ~27 ~33 obsidian 0  
fill ~23 ~27 ~36 ~24 ~27 ~36 stone_slab 14  
fill ~24 ~27 ~13 ~30 ~27 ~13 quartz_block 0 
setblock ~24 ~27 ~27 quartz_stairs 5  
fill ~24 ~27 ~41 ~30 ~27 ~41 quartz_block 0  
fill ~25 ~27 ~14 ~29 ~27 ~14 obsidian 0  
fill ~25 ~27 ~17 ~25 ~27 ~21 obsidian 0  
fill ~25 ~27 ~34 ~25 ~27 ~40 obsidian 0  
fill ~26 ~27 ~-35 ~26 ~28 ~-35 quartz_stairs 2  
fill ~26 ~27 ~-33 ~26 ~35 ~-33 quartz_stairs 0 
setblock ~26 ~27 ~16 quartz_stairs 5 
setblock ~26 ~27 ~17 quartz_stairs 7  
fill ~26 ~27 ~18 ~28 ~27 ~18 stone_slab 14  
fill ~26 ~27 ~19 ~26 ~27 ~20 stone_slab 14  
fill ~26 ~27 ~34 ~26 ~27 ~36 stone_slab 14 
setblock ~26 ~27 ~37 quartz_stairs 6 
setblock ~26 ~27 ~38 quartz_stairs 5  
fill ~26 ~27 ~40 ~29 ~27 ~40 obsidian 0  
fill ~26 ~27 ~87 ~26 ~34 ~87 quartz_stairs 2  
fill ~26 ~27 ~89 ~26 ~35 ~89 quartz_stairs 0 
setblock ~27 ~27 ~15 sea_lantern 0 
setblock ~27 ~27 ~16 quartz_stairs 7 
setblock ~27 ~27 ~17 stone_slab 14 
setblock ~27 ~27 ~19 quartz_block 13 
setblock ~27 ~27 ~20 obsidian 0  
fill ~27 ~27 ~22 ~27 ~27 ~23 obsidian 0 
setblock ~27 ~27 ~24 quartz_stairs 7 
setblock ~27 ~27 ~30 quartz_stairs 6  
fill ~27 ~27 ~31 ~27 ~27 ~34 obsidian 0 
setblock ~27 ~27 ~35 quartz_block 13  
fill ~27 ~27 ~36 ~28 ~27 ~36 stone_slab 14  
fill ~27 ~27 ~37 ~27 ~27 ~36 stone_slab 14 
setblock ~27 ~27 ~38 quartz_stairs 6 
setblock ~27 ~27 ~39 sea_lantern 0  
fill ~27 ~27 ~89 ~28 ~27 ~89 quartz_stairs 3  
fill ~28 ~27 ~-33 ~28 ~35 ~-33 quartz_stairs 3  
fill ~28 ~27 ~15 ~33 ~27 ~15 obsidian 0 
setblock ~28 ~27 ~16 quartz_stairs 4 
setblock ~28 ~27 ~17 quartz_stairs 7  
fill ~28 ~27 ~19 ~28 ~27 ~20 stone_slab 14  
fill ~28 ~27 ~22 ~31 ~27 ~22 stone_slab 14  
fill ~28 ~27 ~23 ~32 ~27 ~23 stone_slab 14  
fill ~28 ~27 ~24 ~32 ~27 ~24 stone_slab 14  
fill ~28 ~27 ~30 ~32 ~27 ~30 stone_slab 14  
fill ~28 ~27 ~31 ~32 ~27 ~31 stone_slab 14  
fill ~28 ~27 ~32 ~31 ~27 ~32 stone_slab 14  
fill ~28 ~27 ~34 ~28 ~27 ~36 stone_slab 14 
setblock ~28 ~27 ~37 quartz_stairs 6 
setblock ~28 ~27 ~38 quartz_stairs 4  
fill ~28 ~27 ~39 ~33 ~27 ~39 obsidian 0  
fill ~29 ~27 ~16 ~35 ~27 ~16 obsidian 0  
fill ~29 ~27 ~17 ~29 ~27 ~21 obsidian 0  
fill ~29 ~27 ~25 ~32 ~27 ~25 stone_slab 14  
fill ~29 ~27 ~29 ~32 ~27 ~29 stone_slab 14  
fill ~29 ~27 ~34 ~29 ~27 ~40 obsidian 0  
fill ~30 ~27 ~14 ~34 ~27 ~14 quartz_block 0  
fill ~30 ~27 ~17 ~32 ~27 ~17 quartz_stairs 7  
fill ~30 ~27 ~18 ~31 ~27 ~18 stone_slab 14  
fill ~30 ~27 ~19 ~33 ~27 ~19 stone_slab 14  
fill ~30 ~27 ~20 ~34 ~27 ~20 stone_slab 14  
fill ~30 ~27 ~26 ~32 ~27 ~26 stone_slab 14 
setblock ~30 ~27 ~27 quartz_stairs 4  
fill ~30 ~27 ~28 ~32 ~27 ~28 stone_slab 14  
fill ~30 ~27 ~34 ~34 ~27 ~34 stone_slab 14  
fill ~30 ~27 ~35 ~33 ~27 ~35 stone_slab 14  
fill ~30 ~27 ~36 ~31 ~27 ~36 stone_slab 14  
fill ~30 ~27 ~37 ~32 ~27 ~37 quartz_stairs 6  
fill ~30 ~27 ~38 ~35 ~27 ~38 obsidian 0  
fill ~30 ~27 ~40 ~34 ~27 ~40 quartz_block 0  
fill ~31 ~27 ~27 ~34 ~27 ~27 obsidian 0 
setblock ~32 ~27 ~18 quartz_stairs 4  
fill ~32 ~27 ~22 ~33 ~27 ~22 obsidian 0  
fill ~32 ~27 ~32 ~33 ~27 ~32 obsidian 0 
setblock ~32 ~27 ~36 quartz_stairs 4  
fill ~33 ~27 ~17 ~36 ~27 ~17 obsidian 0  
fill ~33 ~27 ~18 ~34 ~27 ~18 quartz_stairs 7  
fill ~33 ~27 ~21 ~35 ~27 ~21 stone_slab 14  
fill ~33 ~27 ~23 ~33 ~27 ~32 obsidian 0  
fill ~33 ~27 ~33 ~35 ~27 ~33 stone_slab 14 
setblock ~33 ~27 ~36 quartz_stairs 6  
fill ~33 ~27 ~37 ~36 ~27 ~37 obsidian 0  
fill ~34 ~27 ~15 ~36 ~27 ~15 quartz_block 0 
setblock ~34 ~27 ~19 quartz_stairs 4  
fill ~34 ~27 ~22 ~35 ~27 ~22 stone_slab 14  
fill ~34 ~27 ~23 ~36 ~27 ~23 stone_slab 14  
fill ~34 ~27 ~24 ~36 ~27 ~24 stone_slab 14  
fill ~34 ~27 ~25 ~40 ~27 ~25 obsidian 0  
fill ~34 ~27 ~26 ~36 ~27 ~26 stone_slab 14  
fill ~34 ~27 ~28 ~36 ~27 ~28 stone_slab 14  
fill ~34 ~27 ~29 ~40 ~27 ~29 obsidian 0  
fill ~34 ~27 ~30 ~36 ~27 ~30 stone_slab 14  
fill ~34 ~27 ~31 ~36 ~27 ~31 stone_slab 14  
fill ~34 ~27 ~32 ~35 ~27 ~32 stone_slab 14 
setblock ~34 ~27 ~35 quartz_stairs 6 
setblock ~34 ~27 ~36 quartz_stairs 4  
fill ~34 ~27 ~39 ~36 ~27 ~39 quartz_block 0  
fill ~35 ~27 ~18 ~35 ~33 ~18 obsidian 0 
setblock ~35 ~27 ~19 quartz_stairs 7 
setblock ~35 ~27 ~20 quartz_stairs 4 
setblock ~35 ~27 ~27 quartz_block 13 
setblock ~35 ~27 ~34 quartz_stairs 6 
setblock ~35 ~27 ~35 quartz_stairs 4  
fill ~35 ~27 ~36 ~35 ~33 ~36 obsidian 0  
fill ~36 ~27 ~16 ~37 ~27 ~16 quartz_block 0 
setblock ~36 ~27 ~18 sea_lantern 0  
fill ~36 ~27 ~19 ~38 ~27 ~19 obsidian 0 
setblock ~36 ~27 ~20 quartz_stairs 7 
setblock ~36 ~27 ~21 quartz_stairs 4  
fill ~36 ~27 ~22 ~37 ~27 ~22 quartz_stairs 7  
fill ~36 ~27 ~27 ~37 ~27 ~27 stone_slab 14 
setblock ~36 ~27 ~32 quartz_stairs 6  
fill ~36 ~27 ~33 ~36 ~27 ~34 quartz_stairs 4  
fill ~36 ~27 ~35 ~38 ~27 ~35 obsidian 0 
setblock ~36 ~27 ~36 sea_lantern 0  
fill ~36 ~27 ~38 ~37 ~27 ~38 quartz_block 0 
setblock ~37 ~27 ~17 quartz_block 0 
setblock ~37 ~27 ~18 obsidian 0  
fill ~37 ~27 ~20 ~38 ~27 ~20 obsidian 0  
fill ~37 ~27 ~21 ~39 ~27 ~21 obsidian 0  
fill ~37 ~27 ~23 ~37 ~27 ~24 quartz_stairs 4 
setblock ~37 ~27 ~26 quartz_stairs 4 
setblock ~37 ~27 ~28 quartz_stairs 4  
fill ~37 ~27 ~30 ~37 ~27 ~32 quartz_stairs 4  
fill ~37 ~27 ~33 ~39 ~27 ~33 obsidian 0  
fill ~37 ~27 ~34 ~38 ~27 ~34 obsidian 0 
setblock ~37 ~27 ~36 obsidian 0 
setblock ~37 ~27 ~37 quartz_block 0  
fill ~38 ~27 ~18 ~39 ~27 ~18 quartz_block 0  
fill ~38 ~27 ~22 ~39 ~27 ~22 obsidian 0  
fill ~38 ~27 ~23 ~39 ~27 ~23 obsidian 0  
fill ~38 ~27 ~24 ~39 ~27 ~24 obsidian 0 
setblock ~38 ~27 ~26 quartz_stairs 7 
setblock ~38 ~27 ~27 quartz_stairs 4 
setblock ~38 ~27 ~28 quartz_stairs 6  
fill ~38 ~27 ~30 ~39 ~27 ~30 obsidian 0  
fill ~38 ~27 ~31 ~39 ~27 ~31 obsidian 0  
fill ~38 ~27 ~32 ~39 ~27 ~32 obsidian 0  
fill ~38 ~27 ~36 ~39 ~27 ~36 quartz_block 0  
fill ~39 ~27 ~20 ~40 ~27 ~20 quartz_block 0  
fill ~39 ~27 ~26 ~40 ~27 ~26 obsidian 0 
setblock ~39 ~27 ~27 sea_lantern 0  
fill ~39 ~27 ~28 ~40 ~27 ~28 obsidian 0  
fill ~39 ~27 ~34 ~40 ~27 ~34 quartz_block 0  
fill ~40 ~27 ~24 ~41 ~27 ~24 quartz_block 0 
setblock ~40 ~27 ~27 obsidian 0  
fill ~40 ~27 ~30 ~41 ~27 ~30 quartz_block 0 
setblock ~41 ~27 ~27 quartz_block 0  
fill ~69 ~27 ~-17 ~70 ~27 ~-17 quartz_stairs 2  
fill ~69 ~27 ~69 ~71 ~27 ~69 quartz_stairs 2  
fill ~70 ~27 ~-15 ~71 ~27 ~-15 quartz_stairs 3  
fill ~87 ~27 ~26 ~87 ~28 ~26 quartz_stairs 0  
fill ~87 ~27 ~28 ~87 ~28 ~28 quartz_stairs 0  
fill ~88 ~27 ~26 ~88 ~35 ~26 quartz_stairs 2  
fill ~88 ~27 ~28 ~89 ~27 ~28 quartz_stairs 3  
fill ~89 ~27 ~26 ~89 ~35 ~26 quartz_stairs 1  
fill ~-35 ~28 ~28 ~-33 ~28 ~28 quartz_stairs 3  
fill ~-17 ~28 ~-17 ~-16 ~28 ~-17 quartz_stairs 2  
fill ~-17 ~28 ~69 ~-16 ~28 ~69 quartz_stairs 2  
fill ~-16 ~28 ~71 ~-15 ~28 ~71 quartz_stairs 3  
fill ~13 ~28 ~24 ~15 ~28 ~24 stone_slab 6 
setblock ~13 ~28 ~25 quartz_stairs 1  
fill ~13 ~28 ~26 ~14 ~28 ~26 stone_slab 6 
setblock ~13 ~28 ~27 quartz_stairs 1  
fill ~13 ~28 ~28 ~14 ~28 ~28 stone_slab 6 
setblock ~13 ~28 ~29 quartz_stairs 1  
fill ~13 ~28 ~30 ~15 ~28 ~30 stone_slab 6  
fill ~14 ~28 ~20 ~16 ~28 ~20 stone_slab 6 
setblock ~14 ~28 ~21 quartz_stairs 1  
fill ~14 ~28 ~22 ~15 ~28 ~22 stone_slab 6 
setblock ~14 ~28 ~23 quartz_stairs 1 
setblock ~14 ~28 ~25 stone_slab 6 
setblock ~14 ~28 ~27 quartz_stairs 0 
setblock ~14 ~28 ~29 stone_slab 6 
setblock ~14 ~28 ~31 quartz_stairs 1  
fill ~14 ~28 ~32 ~15 ~28 ~32 stone_slab 6 
setblock ~14 ~28 ~33 quartz_stairs 1  
fill ~14 ~28 ~34 ~16 ~28 ~34 stone_slab 6  
fill ~15 ~28 ~18 ~18 ~28 ~18 stone_slab 6 
setblock ~15 ~28 ~19 quartz_stairs 1 
setblock ~15 ~28 ~21 stone_slab 6 
setblock ~15 ~28 ~23 quartz_stairs 0 
