fill ~2 ~0 ~47 ~102 ~0 ~47 stone 0  
fill ~2 ~0 ~48 ~102 ~0 ~48 stone 0  
fill ~2 ~0 ~49 ~102 ~0 ~49 stone 0  
fill ~2 ~0 ~50 ~102 ~0 ~50 stone 0  
fill ~2 ~0 ~51 ~102 ~0 ~51 stone 0  
fill ~2 ~0 ~52 ~102 ~0 ~52 stone 0  
fill ~2 ~0 ~53 ~102 ~0 ~53 stone 0  
fill ~2 ~0 ~54 ~102 ~0 ~54 stone 0  
fill ~2 ~0 ~55 ~102 ~0 ~55 stone 0  
fill ~2 ~0 ~56 ~102 ~0 ~56 stone 0  
fill ~2 ~0 ~57 ~102 ~0 ~57 stone 0  
fill ~2 ~0 ~58 ~102 ~0 ~58 stone 0  
fill ~2 ~0 ~59 ~102 ~0 ~59 stone 0  
fill ~2 ~0 ~60 ~102 ~0 ~60 stone 0  
fill ~2 ~0 ~61 ~102 ~0 ~61 stone 0  
fill ~3 ~0 ~42 ~101 ~0 ~42 stone 0  
fill ~3 ~0 ~43 ~101 ~0 ~43 stone 0  
fill ~3 ~0 ~44 ~101 ~0 ~44 stone 0  
fill ~3 ~0 ~45 ~101 ~0 ~45 stone 0  
fill ~3 ~0 ~46 ~101 ~0 ~46 stone 0  
fill ~3 ~0 ~62 ~101 ~0 ~62 stone 0  
fill ~3 ~0 ~63 ~101 ~0 ~63 stone 0  
fill ~3 ~0 ~64 ~101 ~0 ~64 stone 0  
fill ~3 ~0 ~65 ~101 ~0 ~65 stone 0  
fill ~3 ~0 ~66 ~101 ~0 ~66 stone 0  
fill ~4 ~0 ~39 ~100 ~0 ~39 stone 0  
fill ~4 ~0 ~40 ~100 ~0 ~40 stone 0  
fill ~4 ~0 ~41 ~100 ~0 ~41 stone 0  
fill ~4 ~0 ~67 ~100 ~0 ~67 stone 0  
fill ~4 ~0 ~68 ~100 ~0 ~68 stone 0  
fill ~4 ~0 ~69 ~100 ~0 ~69 stone 0  
fill ~5 ~0 ~36 ~99 ~0 ~36 stone 0  
fill ~5 ~0 ~37 ~99 ~0 ~37 stone 0  
fill ~5 ~0 ~38 ~99 ~0 ~38 stone 0  
fill ~5 ~0 ~70 ~99 ~0 ~70 stone 0  
fill ~5 ~0 ~71 ~99 ~0 ~71 stone 0  
fill ~5 ~0 ~72 ~99 ~0 ~72 stone 0  
fill ~6 ~0 ~34 ~98 ~0 ~34 stone 0  
fill ~6 ~0 ~35 ~98 ~0 ~35 stone 0  
fill ~6 ~0 ~73 ~98 ~0 ~73 stone 0  
fill ~6 ~0 ~74 ~98 ~0 ~74 stone 0  
fill ~7 ~0 ~32 ~97 ~0 ~32 stone 0  
fill ~7 ~0 ~33 ~97 ~0 ~33 stone 0  
fill ~7 ~0 ~75 ~97 ~0 ~75 stone 0  
fill ~7 ~0 ~76 ~97 ~0 ~76 stone 0  
fill ~8 ~0 ~30 ~96 ~0 ~30 stone 0  
fill ~8 ~0 ~31 ~96 ~0 ~31 stone 0  
fill ~8 ~0 ~77 ~96 ~0 ~77 stone 0  
fill ~8 ~0 ~78 ~96 ~0 ~78 stone 0  
fill ~9 ~0 ~28 ~95 ~0 ~28 stone 0  
fill ~9 ~0 ~29 ~95 ~0 ~29 stone 0  
fill ~9 ~0 ~79 ~95 ~0 ~79 stone 0  
fill ~9 ~0 ~80 ~95 ~0 ~80 stone 0  
fill ~10 ~0 ~26 ~94 ~0 ~26 stone 0  
fill ~10 ~0 ~27 ~94 ~0 ~27 stone 0  
fill ~10 ~0 ~81 ~94 ~0 ~81 stone 0  
fill ~10 ~0 ~82 ~94 ~0 ~82 stone 0  
fill ~11 ~0 ~25 ~93 ~0 ~25 stone 0  
fill ~11 ~0 ~83 ~93 ~0 ~83 stone 0  
fill ~12 ~0 ~24 ~92 ~0 ~24 stone 0  
fill ~12 ~0 ~84 ~92 ~0 ~84 stone 0  
fill ~13 ~0 ~22 ~91 ~0 ~22 stone 0  
fill ~13 ~0 ~23 ~91 ~0 ~23 stone 0  
fill ~13 ~0 ~85 ~91 ~0 ~85 stone 0  
fill ~13 ~0 ~86 ~91 ~0 ~86 stone 0  
fill ~14 ~0 ~21 ~90 ~0 ~21 stone 0  
fill ~14 ~0 ~87 ~90 ~0 ~87 stone 0  
fill ~15 ~0 ~20 ~89 ~0 ~20 stone 0  
fill ~15 ~0 ~88 ~89 ~0 ~88 stone 0  
fill ~16 ~0 ~19 ~88 ~0 ~19 stone 0  
fill ~16 ~0 ~89 ~88 ~0 ~89 stone 0  
fill ~17 ~0 ~18 ~87 ~0 ~18 stone 0  
fill ~17 ~0 ~90 ~87 ~0 ~90 stone 0  
fill ~18 ~0 ~17 ~86 ~0 ~17 stone 0  
fill ~18 ~0 ~91 ~86 ~0 ~91 stone 0  
fill ~19 ~0 ~16 ~85 ~0 ~16 stone 0  
fill ~19 ~0 ~92 ~85 ~0 ~92 stone 0  
fill ~20 ~0 ~15 ~84 ~0 ~15 stone 0  
fill ~20 ~0 ~93 ~84 ~0 ~93 stone 0  
fill ~22 ~0 ~14 ~82 ~0 ~14 stone 0  
fill ~22 ~0 ~94 ~82 ~0 ~94 stone 0  
fill ~23 ~0 ~13 ~81 ~0 ~13 stone 0  
fill ~23 ~0 ~95 ~81 ~0 ~95 stone 0  
fill ~24 ~0 ~12 ~80 ~0 ~12 stone 0  
fill ~24 ~0 ~96 ~80 ~0 ~96 stone 0  
fill ~26 ~0 ~11 ~78 ~0 ~11 stone 0  
fill ~26 ~0 ~97 ~78 ~0 ~97 stone 0  
fill ~28 ~0 ~10 ~46 ~0 ~10 stone 0  
fill ~28 ~0 ~98 ~76 ~0 ~98 stone 0  
fill ~30 ~0 ~9 ~46 ~0 ~9 stone 0  
fill ~30 ~0 ~99 ~74 ~0 ~99 stone 0  
fill ~32 ~0 ~8 ~46 ~0 ~8 stone 0  
fill ~32 ~0 ~100 ~72 ~0 ~100 stone 0  
fill ~34 ~0 ~7 ~45 ~0 ~7 stone 0  
fill ~34 ~0 ~101 ~70 ~0 ~101 stone 0  
fill ~37 ~0 ~6 ~38 ~0 ~6 stone 0  
fill ~37 ~0 ~102 ~67 ~0 ~102 stone 0  
fill ~39 ~0 ~6 ~39 ~1 ~6 dirt 0  
fill ~40 ~0 ~5 ~41 ~0 ~5 stone 0  
fill ~40 ~0 ~6 ~45 ~0 ~6 stone 0  
fill ~40 ~0 ~103 ~64 ~0 ~103 stone 0  
fill ~42 ~0 ~5 ~42 ~1 ~5 dirt 0  
fill ~43 ~0 ~5 ~45 ~0 ~5 stone 0  
fill ~45 ~0 ~4 ~48 ~0 ~4 grass 0  
fill ~45 ~0 ~104 ~59 ~0 ~104 stone 0  
fill ~46 ~0 ~5 ~50 ~0 ~5 grass 0  
fill ~46 ~0 ~6 ~48 ~0 ~6 grass 0  
fill ~46 ~0 ~7 ~52 ~0 ~7 grass 0  
fill ~47 ~0 ~8 ~54 ~0 ~8 grass 0  
fill ~47 ~0 ~9 ~53 ~0 ~9 grass 0  
fill ~47 ~0 ~10 ~47 ~0 ~4 grass 0 
setblock ~48 ~0 ~1 waterlily 0  
fill ~48 ~0 ~10 ~76 ~0 ~10 stone 0  
fill ~49 ~0 ~6 ~49 ~1 ~6 log 0  
fill ~50 ~0 ~6 ~51 ~0 ~6 grass 0  
fill ~52 ~0 ~4 ~53 ~0 ~4 tallgrass 0 
setblock ~53 ~0 ~7 tallgrass 0 
setblock ~54 ~0 ~5 light_weighted_pressure_plate 0  
fill ~54 ~0 ~9 ~74 ~0 ~9 stone 0  
fill ~55 ~0 ~5 ~56 ~0 ~5 tallgrass 0 
setblock ~56 ~0 ~4 tallgrass 0  
fill ~56 ~0 ~7 ~70 ~0 ~7 stone 0  
fill ~56 ~0 ~8 ~72 ~0 ~8 stone 0 
setblock ~57 ~0 ~2 waterlily 0  
fill ~57 ~0 ~4 ~59 ~0 ~4 stone 0  
fill ~57 ~0 ~5 ~64 ~0 ~5 stone 0  
fill ~57 ~0 ~6 ~67 ~0 ~6 stone 0 
setblock ~65 ~0 ~3 waterlily 0  
fill ~2 ~1 ~47 ~102 ~1 ~47 stone 0  
fill ~2 ~1 ~48 ~102 ~1 ~48 stone 0  
fill ~2 ~1 ~49 ~102 ~1 ~49 stone 0  
fill ~2 ~1 ~50 ~102 ~1 ~50 stone 0  
fill ~2 ~1 ~51 ~102 ~1 ~51 stone 0  
fill ~2 ~1 ~52 ~102 ~1 ~52 stone 0  
fill ~2 ~1 ~53 ~102 ~1 ~53 stone 0  
fill ~2 ~1 ~54 ~102 ~1 ~54 stone 0  
fill ~2 ~1 ~55 ~102 ~1 ~55 stone 0  
fill ~2 ~1 ~56 ~102 ~1 ~56 stone 0  
fill ~2 ~1 ~57 ~102 ~1 ~57 stone 0  
fill ~2 ~1 ~58 ~102 ~1 ~58 stone 0  
fill ~2 ~1 ~59 ~102 ~1 ~59 stone 0  
fill ~2 ~1 ~60 ~102 ~1 ~60 stone 0  
fill ~2 ~1 ~61 ~102 ~1 ~61 stone 0  
fill ~3 ~1 ~42 ~101 ~1 ~42 stone 0  
fill ~3 ~1 ~43 ~101 ~1 ~43 stone 0  
fill ~3 ~1 ~44 ~101 ~1 ~44 stone 0  
fill ~3 ~1 ~45 ~101 ~1 ~45 stone 0  
fill ~3 ~1 ~46 ~101 ~1 ~46 stone 0  
fill ~3 ~1 ~62 ~101 ~1 ~62 stone 0  
fill ~3 ~1 ~63 ~101 ~1 ~63 stone 0  
fill ~3 ~1 ~64 ~101 ~1 ~64 stone 0  
fill ~3 ~1 ~65 ~101 ~1 ~65 stone 0  
fill ~3 ~1 ~66 ~101 ~1 ~66 stone 0  
fill ~4 ~1 ~39 ~100 ~1 ~39 stone 0  
fill ~4 ~1 ~40 ~100 ~1 ~40 stone 0  
fill ~4 ~1 ~41 ~100 ~1 ~41 stone 0  
fill ~4 ~1 ~67 ~100 ~1 ~67 stone 0  
fill ~4 ~1 ~68 ~100 ~1 ~68 stone 0  
fill ~4 ~1 ~69 ~100 ~1 ~69 stone 0  
fill ~5 ~1 ~36 ~99 ~1 ~36 stone 0  
fill ~5 ~1 ~37 ~99 ~1 ~37 stone 0  
fill ~5 ~1 ~38 ~99 ~1 ~38 stone 0  
fill ~5 ~1 ~70 ~99 ~1 ~70 stone 0  
fill ~5 ~1 ~71 ~99 ~1 ~71 stone 0  
fill ~5 ~1 ~72 ~99 ~1 ~72 stone 0  
fill ~6 ~1 ~34 ~98 ~1 ~34 stone 0  
fill ~6 ~1 ~35 ~98 ~1 ~35 stone 0  
fill ~6 ~1 ~73 ~98 ~1 ~73 stone 0  
fill ~6 ~1 ~74 ~98 ~1 ~74 stone 0  
fill ~7 ~1 ~32 ~97 ~1 ~32 stone 0  
fill ~7 ~1 ~33 ~97 ~1 ~33 stone 0  
fill ~7 ~1 ~75 ~97 ~1 ~75 stone 0  
fill ~7 ~1 ~76 ~97 ~1 ~76 stone 0  
fill ~8 ~1 ~30 ~96 ~1 ~30 stone 0  
fill ~8 ~1 ~31 ~96 ~1 ~31 stone 0  
fill ~8 ~1 ~77 ~96 ~1 ~77 stone 0  
fill ~8 ~1 ~78 ~96 ~1 ~78 stone 0  
fill ~9 ~1 ~28 ~95 ~1 ~28 stone 0  
fill ~9 ~1 ~29 ~95 ~1 ~29 stone 0  
fill ~9 ~1 ~79 ~95 ~1 ~79 stone 0  
fill ~9 ~1 ~80 ~95 ~1 ~80 stone 0  
fill ~10 ~1 ~26 ~94 ~1 ~26 stone 0  
fill ~10 ~1 ~27 ~94 ~1 ~27 stone 0  
fill ~10 ~1 ~81 ~94 ~1 ~81 stone 0  
fill ~10 ~1 ~82 ~94 ~1 ~82 stone 0  
fill ~11 ~1 ~25 ~93 ~1 ~25 stone 0  
fill ~11 ~1 ~83 ~93 ~1 ~83 stone 0  
fill ~12 ~1 ~24 ~92 ~1 ~24 stone 0  
fill ~12 ~1 ~84 ~92 ~1 ~84 stone 0  
fill ~13 ~1 ~22 ~91 ~1 ~22 stone 0  
fill ~13 ~1 ~23 ~91 ~1 ~23 stone 0  
fill ~13 ~1 ~85 ~91 ~1 ~85 stone 0  
fill ~13 ~1 ~86 ~91 ~1 ~86 stone 0  
fill ~14 ~1 ~21 ~90 ~1 ~21 stone 0  
fill ~14 ~1 ~87 ~90 ~1 ~87 stone 0  
fill ~15 ~1 ~20 ~89 ~1 ~20 stone 0  
fill ~15 ~1 ~88 ~89 ~1 ~88 stone 0  
fill ~16 ~1 ~19 ~88 ~1 ~19 stone 0  
fill ~16 ~1 ~89 ~88 ~1 ~89 stone 0  
fill ~17 ~1 ~18 ~87 ~1 ~18 stone 0  
fill ~17 ~1 ~90 ~87 ~1 ~90 stone 0  
fill ~18 ~1 ~17 ~86 ~1 ~17 stone 0  
fill ~18 ~1 ~91 ~86 ~1 ~91 stone 0  
fill ~19 ~1 ~16 ~85 ~1 ~16 stone 0  
fill ~19 ~1 ~92 ~85 ~1 ~92 stone 0  
fill ~20 ~1 ~15 ~84 ~1 ~15 stone 0  
fill ~20 ~1 ~93 ~84 ~1 ~93 stone 0  
fill ~22 ~1 ~14 ~82 ~1 ~14 stone 0  
fill ~22 ~1 ~94 ~82 ~1 ~94 stone 0  
fill ~23 ~1 ~13 ~81 ~1 ~13 stone 0  
fill ~23 ~1 ~95 ~81 ~1 ~95 stone 0  
fill ~24 ~1 ~12 ~80 ~1 ~12 stone 0  
fill ~24 ~1 ~96 ~80 ~1 ~96 stone 0  
fill ~26 ~1 ~11 ~78 ~1 ~11 stone 0  
fill ~26 ~1 ~97 ~78 ~1 ~97 stone 0  
fill ~28 ~1 ~10 ~45 ~1 ~10 stone 0  
fill ~28 ~1 ~98 ~76 ~1 ~98 stone 0  
fill ~30 ~1 ~9 ~45 ~1 ~9 stone 0  
fill ~30 ~1 ~99 ~74 ~1 ~99 stone 0  
fill ~32 ~1 ~8 ~45 ~1 ~8 stone 0  
fill ~32 ~1 ~100 ~72 ~1 ~100 stone 0  
fill ~34 ~1 ~7 ~44 ~1 ~7 stone 0  
fill ~34 ~1 ~101 ~70 ~1 ~101 stone 0  
fill ~37 ~1 ~6 ~37 ~2 ~6 stone 0  
fill ~37 ~1 ~102 ~67 ~1 ~102 stone 0 
setblock ~38 ~1 ~6 dirt 0  
fill ~40 ~1 ~5 ~43 ~1 ~5 dirt 0  
fill ~40 ~1 ~6 ~44 ~1 ~6 stone 0  
fill ~40 ~1 ~103 ~64 ~1 ~103 stone 0 
setblock ~44 ~1 ~5 stone 0  
fill ~45 ~1 ~5 ~45 ~2 ~5 log 0  
fill ~45 ~1 ~6 ~45 ~2 ~6 log 0  
fill ~45 ~1 ~7 ~45 ~2 ~7 log 0  
fill ~45 ~1 ~104 ~59 ~1 ~104 stone 0  
fill ~46 ~1 ~5 ~46 ~1 ~6 tallgrass 0 
setblock ~46 ~1 ~7 red_flower 0  
fill ~46 ~1 ~8 ~46 ~2 ~8 log 0  
fill ~46 ~1 ~9 ~46 ~2 ~9 log 0  
fill ~46 ~1 ~10 ~46 ~2 ~10 log 0  
fill ~47 ~1 ~6 ~47 ~1 ~8 tallgrass 0  
fill ~47 ~1 ~10 ~76 ~1 ~10 stone 0 
setblock ~48 ~1 ~5 tallgrass 0 
setblock ~48 ~1 ~7 tallgrass 0 
setblock ~50 ~1 ~5 tallgrass 0 
setblock ~50 ~1 ~8 tallgrass 0 
setblock ~52 ~1 ~8 dropper 0  
fill ~54 ~1 ~9 ~74 ~1 ~9 stone 0  
fill ~56 ~1 ~7 ~70 ~1 ~7 stone 0  
fill ~56 ~1 ~8 ~72 ~1 ~8 stone 0  
fill ~57 ~1 ~5 ~64 ~1 ~5 stone 0  
fill ~57 ~1 ~6 ~67 ~1 ~6 stone 0  
fill ~58 ~1 ~4 ~59 ~1 ~4 stone 0  
fill ~2 ~2 ~47 ~102 ~2 ~47 stone 0  
fill ~2 ~2 ~48 ~102 ~2 ~48 stone 0  
fill ~2 ~2 ~49 ~102 ~2 ~49 stone 0  
fill ~2 ~2 ~50 ~102 ~2 ~50 stone 0  
fill ~2 ~2 ~51 ~102 ~2 ~51 stone 0  
fill ~2 ~2 ~52 ~102 ~2 ~52 stone 0  
fill ~2 ~2 ~53 ~102 ~2 ~53 stone 0  
fill ~2 ~2 ~54 ~102 ~2 ~54 stone 0  
fill ~2 ~2 ~55 ~102 ~2 ~55 stone 0  
fill ~2 ~2 ~56 ~102 ~2 ~56 stone 0  
fill ~2 ~2 ~57 ~102 ~2 ~57 stone 0  
fill ~2 ~2 ~58 ~102 ~2 ~58 stone 0  
fill ~2 ~2 ~59 ~102 ~2 ~59 stone 0  
fill ~2 ~2 ~60 ~102 ~2 ~60 stone 0  
fill ~2 ~2 ~61 ~102 ~2 ~61 stone 0  
fill ~3 ~2 ~42 ~101 ~2 ~42 stone 0  
fill ~3 ~2 ~43 ~101 ~2 ~43 stone 0  
fill ~3 ~2 ~44 ~101 ~2 ~44 stone 0  
fill ~3 ~2 ~45 ~101 ~2 ~45 stone 0  
fill ~3 ~2 ~46 ~101 ~2 ~46 stone 0  
fill ~3 ~2 ~62 ~101 ~2 ~62 stone 0  
fill ~3 ~2 ~63 ~101 ~2 ~63 stone 0  
fill ~3 ~2 ~64 ~101 ~2 ~64 stone 0  
fill ~3 ~2 ~65 ~101 ~2 ~65 stone 0  
fill ~3 ~2 ~66 ~101 ~2 ~66 stone 0  
fill ~4 ~2 ~39 ~100 ~2 ~39 stone 0  
fill ~4 ~2 ~40 ~100 ~2 ~40 stone 0  
fill ~4 ~2 ~41 ~100 ~2 ~41 stone 0  
fill ~4 ~2 ~67 ~100 ~2 ~67 stone 0  
fill ~4 ~2 ~68 ~100 ~2 ~68 stone 0  
fill ~4 ~2 ~69 ~100 ~2 ~69 stone 0  
fill ~5 ~2 ~36 ~99 ~2 ~36 stone 0  
fill ~5 ~2 ~37 ~99 ~2 ~37 stone 0  
fill ~5 ~2 ~38 ~99 ~2 ~38 stone 0  
fill ~5 ~2 ~70 ~99 ~2 ~70 stone 0  
fill ~5 ~2 ~71 ~99 ~2 ~71 stone 0  
fill ~5 ~2 ~72 ~99 ~2 ~72 stone 0  
fill ~6 ~2 ~34 ~98 ~2 ~34 stone 0  
fill ~6 ~2 ~35 ~98 ~2 ~35 stone 0  
fill ~6 ~2 ~73 ~98 ~2 ~73 stone 0  
fill ~6 ~2 ~74 ~98 ~2 ~74 stone 0  
fill ~7 ~2 ~32 ~97 ~2 ~32 stone 0  
fill ~7 ~2 ~33 ~97 ~2 ~33 stone 0  
fill ~7 ~2 ~75 ~97 ~2 ~75 stone 0  
fill ~7 ~2 ~76 ~97 ~2 ~76 stone 0  
fill ~8 ~2 ~30 ~96 ~2 ~30 stone 0  
fill ~8 ~2 ~31 ~96 ~2 ~31 stone 0  
fill ~8 ~2 ~77 ~96 ~2 ~77 stone 0  
fill ~8 ~2 ~78 ~96 ~2 ~78 stone 0  
fill ~9 ~2 ~28 ~95 ~2 ~28 stone 0  
fill ~9 ~2 ~29 ~95 ~2 ~29 stone 0  
fill ~9 ~2 ~79 ~95 ~2 ~79 stone 0  
fill ~9 ~2 ~80 ~95 ~2 ~80 stone 0  
fill ~10 ~2 ~26 ~94 ~2 ~26 stone 0  
fill ~10 ~2 ~27 ~94 ~2 ~27 stone 0  
fill ~10 ~2 ~81 ~94 ~2 ~81 stone 0  
fill ~10 ~2 ~82 ~94 ~2 ~82 stone 0  
fill ~11 ~2 ~25 ~93 ~2 ~25 stone 0  
fill ~11 ~2 ~83 ~93 ~2 ~83 stone 0  
fill ~12 ~2 ~24 ~92 ~2 ~24 stone 0  
fill ~12 ~2 ~84 ~92 ~2 ~84 stone 0  
fill ~13 ~2 ~22 ~91 ~2 ~22 stone 0  
fill ~13 ~2 ~23 ~91 ~2 ~23 stone 0  
fill ~13 ~2 ~85 ~91 ~2 ~85 stone 0  
fill ~13 ~2 ~86 ~91 ~2 ~86 stone 0  
fill ~14 ~2 ~21 ~90 ~2 ~21 stone 0  
fill ~14 ~2 ~87 ~90 ~2 ~87 stone 0  
fill ~15 ~2 ~20 ~89 ~2 ~20 stone 0  
fill ~15 ~2 ~88 ~89 ~2 ~88 stone 0  
fill ~16 ~2 ~19 ~88 ~2 ~19 stone 0  
fill ~16 ~2 ~89 ~88 ~2 ~89 stone 0  
fill ~17 ~2 ~18 ~87 ~2 ~18 stone 0  
fill ~17 ~2 ~90 ~87 ~2 ~90 stone 0  
fill ~18 ~2 ~17 ~86 ~2 ~17 stone 0  
fill ~18 ~2 ~91 ~86 ~2 ~91 stone 0  
fill ~19 ~2 ~16 ~85 ~2 ~16 stone 0  
fill ~19 ~2 ~92 ~85 ~2 ~92 stone 0  
fill ~20 ~2 ~15 ~84 ~2 ~15 stone 0  
fill ~20 ~2 ~93 ~84 ~2 ~93 stone 0  
fill ~22 ~2 ~14 ~82 ~2 ~14 stone 0  
fill ~22 ~2 ~94 ~82 ~2 ~94 stone 0  
fill ~23 ~2 ~13 ~81 ~2 ~13 stone 0  
fill ~23 ~2 ~95 ~81 ~2 ~95 stone 0  
fill ~24 ~2 ~12 ~80 ~2 ~12 stone 0  
fill ~24 ~2 ~96 ~80 ~2 ~96 stone 0  
fill ~26 ~2 ~11 ~78 ~2 ~11 stone 0  
fill ~26 ~2 ~97 ~78 ~2 ~97 stone 0  
fill ~28 ~2 ~10 ~41 ~2 ~10 stone 0  
fill ~28 ~2 ~98 ~76 ~2 ~98 stone 0  
fill ~30 ~2 ~9 ~39 ~2 ~9 stone 0  
fill ~30 ~2 ~99 ~74 ~2 ~99 stone 0  
fill ~32 ~2 ~8 ~39 ~2 ~8 stone 0  
fill ~32 ~2 ~100 ~72 ~2 ~100 stone 0  
fill ~34 ~2 ~7 ~38 ~2 ~7 stone 0  
fill ~34 ~2 ~101 ~70 ~2 ~101 stone 0  
fill ~37 ~2 ~102 ~67 ~2 ~102 stone 0  
fill ~38 ~2 ~6 ~44 ~2 ~6 grass 0  
fill ~39 ~2 ~7 ~44 ~2 ~7 grass 0  
fill ~40 ~2 ~5 ~40 ~1 ~5 dirt 0  
fill ~40 ~2 ~8 ~45 ~2 ~8 grass 0  
fill ~40 ~2 ~9 ~45 ~2 ~9 grass 0  
fill ~40 ~2 ~103 ~64 ~2 ~103 stone 0  
fill ~41 ~2 ~5 ~44 ~2 ~5 grass 0  
fill ~42 ~2 ~10 ~44 ~2 ~10 grass 0 
setblock ~45 ~2 ~10 stone 0  
fill ~45 ~2 ~104 ~59 ~2 ~104 stone 0  
fill ~47 ~2 ~10 ~76 ~2 ~10 stone 0 
setblock ~49 ~2 ~6 dropper 0  
fill ~54 ~2 ~9 ~74 ~2 ~9 stone 0 
setblock ~56 ~2 ~8 stone 5 
setblock ~57 ~2 ~7 stone 5  
fill ~57 ~2 ~8 ~72 ~2 ~8 stone 0  
fill ~58 ~2 ~5 ~64 ~2 ~5 stone 0  
fill ~58 ~2 ~6 ~67 ~2 ~6 stone 0  
fill ~58 ~2 ~7 ~70 ~2 ~7 stone 0 
setblock ~59 ~2 ~4 stone 0  
fill ~2 ~3 ~47 ~102 ~3 ~47 stone 0  
fill ~2 ~3 ~48 ~102 ~3 ~48 stone 0  
fill ~2 ~3 ~49 ~102 ~3 ~49 stone 0  
fill ~2 ~3 ~50 ~102 ~3 ~50 stone 0  
fill ~2 ~3 ~51 ~102 ~3 ~51 stone 0  
fill ~2 ~3 ~52 ~102 ~3 ~52 stone 0  
fill ~2 ~3 ~53 ~102 ~3 ~53 stone 0  
fill ~2 ~3 ~54 ~102 ~3 ~54 stone 0  
fill ~2 ~3 ~55 ~102 ~3 ~55 stone 0  
fill ~2 ~3 ~56 ~102 ~3 ~56 stone 0  
fill ~2 ~3 ~57 ~102 ~3 ~57 stone 0  
fill ~2 ~3 ~58 ~102 ~3 ~58 stone 0  
fill ~2 ~3 ~59 ~102 ~3 ~59 stone 0  
fill ~2 ~3 ~60 ~102 ~3 ~60 stone 0  
fill ~2 ~3 ~61 ~102 ~3 ~61 stone 0  
fill ~3 ~3 ~42 ~101 ~3 ~42 stone 0  
fill ~3 ~3 ~43 ~101 ~3 ~43 stone 0  
fill ~3 ~3 ~44 ~101 ~3 ~44 stone 0  
fill ~3 ~3 ~45 ~101 ~3 ~45 stone 0  
fill ~3 ~3 ~46 ~101 ~3 ~46 stone 0  
fill ~3 ~3 ~62 ~101 ~3 ~62 stone 0  
fill ~3 ~3 ~63 ~101 ~3 ~63 stone 0  
fill ~3 ~3 ~64 ~101 ~3 ~64 stone 0  
fill ~3 ~3 ~65 ~101 ~3 ~65 stone 0  
fill ~3 ~3 ~66 ~101 ~3 ~66 stone 0  
fill ~4 ~3 ~39 ~100 ~3 ~39 stone 0  
fill ~4 ~3 ~40 ~100 ~3 ~40 stone 0  
fill ~4 ~3 ~41 ~100 ~3 ~41 stone 0  
fill ~4 ~3 ~67 ~100 ~3 ~67 stone 0  
fill ~4 ~3 ~68 ~100 ~3 ~68 stone 0  
fill ~4 ~3 ~69 ~100 ~3 ~69 stone 0  
fill ~5 ~3 ~36 ~99 ~3 ~36 stone 0  
fill ~5 ~3 ~37 ~99 ~3 ~37 stone 0  
fill ~5 ~3 ~38 ~99 ~3 ~38 stone 0  
fill ~5 ~3 ~70 ~99 ~3 ~70 stone 0  
fill ~5 ~3 ~71 ~99 ~3 ~71 stone 0  
fill ~5 ~3 ~72 ~99 ~3 ~72 stone 0  
fill ~6 ~3 ~34 ~98 ~3 ~34 stone 0  
fill ~6 ~3 ~35 ~98 ~3 ~35 stone 0  
fill ~6 ~3 ~73 ~98 ~3 ~73 stone 0  
fill ~6 ~3 ~74 ~98 ~3 ~74 stone 0  
fill ~7 ~3 ~32 ~97 ~3 ~32 stone 0  
fill ~7 ~3 ~33 ~97 ~3 ~33 stone 0  
fill ~7 ~3 ~75 ~97 ~3 ~75 stone 0  
fill ~7 ~3 ~76 ~97 ~3 ~76 stone 0  
fill ~8 ~3 ~30 ~96 ~3 ~30 stone 0  
fill ~8 ~3 ~31 ~96 ~3 ~31 stone 0  
fill ~8 ~3 ~77 ~96 ~3 ~77 stone 0  
fill ~8 ~3 ~78 ~96 ~3 ~78 stone 0  
fill ~9 ~3 ~28 ~95 ~3 ~28 stone 0  
fill ~9 ~3 ~29 ~95 ~3 ~29 stone 0  
fill ~9 ~3 ~79 ~95 ~3 ~79 stone 0  
fill ~9 ~3 ~80 ~95 ~3 ~80 stone 0  
fill ~10 ~3 ~26 ~94 ~3 ~26 stone 0  
fill ~10 ~3 ~27 ~94 ~3 ~27 stone 0  
fill ~10 ~3 ~81 ~94 ~3 ~81 stone 0  
fill ~10 ~3 ~82 ~94 ~3 ~82 stone 0  
fill ~11 ~3 ~25 ~93 ~3 ~25 stone 0  
fill ~11 ~3 ~83 ~93 ~3 ~83 stone 0  
fill ~12 ~3 ~24 ~92 ~3 ~24 stone 0  
fill ~12 ~3 ~84 ~92 ~3 ~84 stone 0  
fill ~13 ~3 ~22 ~91 ~3 ~22 stone 0  
fill ~13 ~3 ~23 ~91 ~3 ~23 stone 0  
fill ~13 ~3 ~85 ~91 ~3 ~85 stone 0  
fill ~13 ~3 ~86 ~91 ~3 ~86 stone 0  
fill ~14 ~3 ~21 ~90 ~3 ~21 stone 0  
fill ~14 ~3 ~87 ~90 ~3 ~87 stone 0  
fill ~15 ~3 ~20 ~89 ~3 ~20 stone 0  
fill ~15 ~3 ~88 ~89 ~3 ~88 stone 0  
fill ~16 ~3 ~19 ~88 ~3 ~19 stone 0  
fill ~16 ~3 ~89 ~88 ~3 ~89 stone 0  
fill ~17 ~3 ~18 ~87 ~3 ~18 stone 0  
fill ~17 ~3 ~90 ~87 ~3 ~90 stone 0  
fill ~18 ~3 ~17 ~86 ~3 ~17 stone 0  
fill ~18 ~3 ~91 ~86 ~3 ~91 stone 0  
fill ~19 ~3 ~16 ~85 ~3 ~16 stone 0  
fill ~19 ~3 ~92 ~85 ~3 ~92 stone 0  
fill ~20 ~3 ~15 ~84 ~3 ~15 stone 0  
fill ~20 ~3 ~93 ~84 ~3 ~93 stone 0  
fill ~22 ~3 ~14 ~82 ~3 ~14 stone 0  
fill ~22 ~3 ~94 ~82 ~3 ~94 stone 0  
fill ~23 ~3 ~13 ~81 ~3 ~13 stone 0  
fill ~23 ~3 ~95 ~81 ~3 ~95 stone 0  
fill ~24 ~3 ~12 ~35 ~3 ~12 stone 0  
fill ~24 ~3 ~96 ~80 ~3 ~96 stone 0  
fill ~26 ~3 ~11 ~35 ~3 ~11 stone 0  
fill ~26 ~3 ~97 ~78 ~3 ~97 stone 0  
fill ~28 ~3 ~10 ~34 ~3 ~10 stone 0  
fill ~28 ~3 ~98 ~76 ~3 ~98 stone 0  
fill ~30 ~3 ~9 ~34 ~3 ~9 stone 0  
fill ~30 ~3 ~99 ~74 ~3 ~99 stone 0  
fill ~32 ~3 ~8 ~34 ~3 ~8 stone 0  
fill ~32 ~3 ~100 ~72 ~3 ~100 stone 0  
fill ~34 ~3 ~7 ~34 ~4 ~7 stone 0  
fill ~34 ~3 ~101 ~70 ~3 ~101 stone 0  
fill ~35 ~3 ~7 ~38 ~3 ~7 sand 0  
fill ~35 ~3 ~8 ~39 ~3 ~8 sand 0  
fill ~35 ~3 ~9 ~39 ~3 ~9 sand 0  
fill ~35 ~3 ~10 ~41 ~3 ~10 sand 0  
fill ~36 ~3 ~11 ~46 ~3 ~11 sand 0  
fill ~36 ~3 ~12 ~40 ~3 ~12 sand 0 
setblock ~37 ~3 ~6 sand 0  
fill ~37 ~3 ~102 ~67 ~3 ~102 stone 0 
setblock ~38 ~3 ~4 leaves 11  
fill ~40 ~3 ~5 ~40 ~4 ~5 log 3  
fill ~40 ~3 ~7 ~42 ~3 ~7 tallgrass 0  
fill ~40 ~3 ~103 ~64 ~3 ~103 stone 0 
setblock ~41 ~3 ~4 leaves 11 
setblock ~41 ~3 ~6 tallgrass 0  
fill ~41 ~3 ~12 ~80 ~3 ~12 stone 0 
setblock ~42 ~3 ~5 tallgrass 0 
setblock ~42 ~3 ~8 tallgrass 0 
setblock ~43 ~3 ~7 red_flower 3 
setblock ~43 ~3 ~8 yellow_flower 0 
setblock ~43 ~3 ~9 tallgrass 0 
setblock ~43 ~3 ~10 red_flower 0  
fill ~44 ~3 ~6 ~44 ~3 ~8 tallgrass 0  
fill ~45 ~3 ~5 ~45 ~3 ~7 dropper 0  
fill ~45 ~3 ~8 ~45 ~3 ~9 tallgrass 0  
fill ~45 ~3 ~10 ~46 ~3 ~10 sand 0  
fill ~45 ~3 ~104 ~59 ~3 ~104 stone 0  
fill ~46 ~3 ~8 ~46 ~3 ~9 dropper 0  
fill ~47 ~3 ~10 ~76 ~3 ~10 stone 0  
fill ~47 ~3 ~11 ~78 ~3 ~11 stone 0  
fill ~55 ~3 ~9 ~55 ~4 ~9 stone 0  
fill ~56 ~3 ~9 ~56 ~5 ~9 stone 5  
fill ~57 ~3 ~8 ~57 ~4 ~8 stone 5  
fill ~57 ~3 ~9 ~74 ~3 ~9 stone 0  
fill ~58 ~3 ~6 ~67 ~3 ~6 stone 0  
fill ~58 ~3 ~7 ~70 ~3 ~7 stone 0  
fill ~58 ~3 ~8 ~72 ~3 ~8 stone 0  
fill ~59 ~3 ~5 ~64 ~3 ~5 stone 0  
fill ~2 ~4 ~47 ~102 ~4 ~47 stone 0  
fill ~2 ~4 ~48 ~102 ~4 ~48 stone 0  
fill ~2 ~4 ~49 ~102 ~4 ~49 stone 0  
fill ~2 ~4 ~50 ~102 ~4 ~50 stone 0  
fill ~2 ~4 ~51 ~102 ~4 ~51 stone 0  
fill ~2 ~4 ~52 ~102 ~4 ~52 stone 0  
fill ~2 ~4 ~53 ~102 ~4 ~53 stone 0  
fill ~2 ~4 ~54 ~102 ~4 ~54 stone 0  
fill ~2 ~4 ~55 ~102 ~4 ~55 stone 0  
fill ~2 ~4 ~56 ~102 ~4 ~56 stone 0  
fill ~2 ~4 ~57 ~102 ~4 ~57 stone 0  
fill ~2 ~4 ~58 ~102 ~4 ~58 stone 0  
fill ~2 ~4 ~59 ~102 ~4 ~59 stone 0  
fill ~2 ~4 ~60 ~102 ~4 ~60 stone 0  
fill ~2 ~4 ~61 ~102 ~4 ~61 stone 0  
fill ~3 ~4 ~42 ~101 ~4 ~42 stone 0  
fill ~3 ~4 ~43 ~101 ~4 ~43 stone 0  
fill ~3 ~4 ~44 ~101 ~4 ~44 stone 0  
fill ~3 ~4 ~45 ~101 ~4 ~45 stone 0  
fill ~3 ~4 ~46 ~101 ~4 ~46 stone 0  
fill ~3 ~4 ~62 ~101 ~4 ~62 stone 0  
fill ~3 ~4 ~63 ~101 ~4 ~63 stone 0  
fill ~3 ~4 ~64 ~101 ~4 ~64 stone 0  
fill ~3 ~4 ~65 ~101 ~4 ~65 stone 0  
fill ~3 ~4 ~66 ~101 ~4 ~66 stone 0  
fill ~4 ~4 ~39 ~100 ~4 ~39 stone 0  
fill ~4 ~4 ~40 ~100 ~4 ~40 stone 0  
fill ~4 ~4 ~41 ~100 ~4 ~41 stone 0  
fill ~4 ~4 ~67 ~100 ~4 ~67 stone 0  
fill ~4 ~4 ~68 ~100 ~4 ~68 stone 0  
fill ~4 ~4 ~69 ~100 ~4 ~69 stone 0  
fill ~5 ~4 ~36 ~99 ~4 ~36 stone 0  
fill ~5 ~4 ~37 ~99 ~4 ~37 stone 0  
fill ~5 ~4 ~38 ~99 ~4 ~38 stone 0  
fill ~5 ~4 ~70 ~99 ~4 ~70 stone 0  
fill ~5 ~4 ~71 ~99 ~4 ~71 stone 0  
fill ~5 ~4 ~72 ~99 ~4 ~72 stone 0  
fill ~6 ~4 ~34 ~98 ~4 ~34 stone 0  
fill ~6 ~4 ~35 ~98 ~4 ~35 stone 0  
fill ~6 ~4 ~73 ~98 ~4 ~73 stone 0  
fill ~6 ~4 ~74 ~98 ~4 ~74 stone 0  
fill ~7 ~4 ~32 ~97 ~4 ~32 stone 0  
fill ~7 ~4 ~33 ~97 ~4 ~33 stone 0  
fill ~7 ~4 ~75 ~97 ~4 ~75 stone 0  
fill ~7 ~4 ~76 ~97 ~4 ~76 stone 0  
fill ~8 ~4 ~30 ~96 ~4 ~30 stone 0  
fill ~8 ~4 ~31 ~96 ~4 ~31 stone 0  
fill ~8 ~4 ~77 ~96 ~4 ~77 stone 0  
fill ~8 ~4 ~78 ~96 ~4 ~78 stone 0  
fill ~9 ~4 ~28 ~95 ~4 ~28 stone 0  
fill ~9 ~4 ~29 ~95 ~4 ~29 stone 0  
fill ~9 ~4 ~79 ~95 ~4 ~79 stone 0  
fill ~9 ~4 ~80 ~95 ~4 ~80 stone 0  
fill ~10 ~4 ~26 ~94 ~4 ~26 stone 0  
fill ~10 ~4 ~27 ~94 ~4 ~27 stone 0  
fill ~10 ~4 ~81 ~94 ~4 ~81 stone 0  
fill ~10 ~4 ~82 ~94 ~4 ~82 stone 0  
fill ~11 ~4 ~25 ~93 ~4 ~25 stone 0  
fill ~11 ~4 ~83 ~93 ~4 ~83 stone 0  
fill ~12 ~4 ~24 ~92 ~4 ~24 stone 0  
fill ~12 ~4 ~84 ~92 ~4 ~84 stone 0  
fill ~13 ~4 ~22 ~91 ~4 ~22 stone 0  
fill ~13 ~4 ~23 ~91 ~4 ~23 stone 0  
fill ~13 ~4 ~85 ~91 ~4 ~85 stone 0  
fill ~13 ~4 ~86 ~91 ~4 ~86 stone 0  
fill ~14 ~4 ~21 ~90 ~4 ~21 stone 0  
fill ~14 ~4 ~87 ~90 ~4 ~87 stone 0  
fill ~15 ~4 ~20 ~89 ~4 ~20 stone 0  
fill ~15 ~4 ~88 ~89 ~4 ~88 stone 0  
fill ~16 ~4 ~19 ~88 ~4 ~19 stone 0  
fill ~16 ~4 ~89 ~88 ~4 ~89 stone 0  
fill ~17 ~4 ~18 ~87 ~4 ~18 stone 0  
fill ~17 ~4 ~90 ~87 ~4 ~90 stone 0  
fill ~18 ~4 ~17 ~86 ~4 ~17 stone 0  
fill ~18 ~4 ~91 ~86 ~4 ~91 stone 0  
fill ~19 ~4 ~16 ~85 ~4 ~16 stone 0  
fill ~19 ~4 ~92 ~85 ~4 ~92 stone 0  
fill ~20 ~4 ~15 ~84 ~4 ~15 stone 0  
fill ~20 ~4 ~93 ~84 ~4 ~93 stone 0  
fill ~22 ~4 ~14 ~82 ~4 ~14 stone 0  
fill ~22 ~4 ~94 ~82 ~4 ~94 stone 0  
fill ~23 ~4 ~13 ~81 ~4 ~13 stone 0  
fill ~23 ~4 ~95 ~81 ~4 ~95 stone 0  
fill ~24 ~4 ~12 ~35 ~4 ~12 stone 0  
fill ~24 ~4 ~96 ~80 ~4 ~96 stone 0  
fill ~26 ~4 ~11 ~35 ~4 ~11 stone 0  
fill ~26 ~4 ~97 ~78 ~4 ~97 stone 0  
fill ~28 ~4 ~10 ~28 ~0 ~10 stone 0  
fill ~28 ~4 ~98 ~76 ~4 ~98 stone 0  
fill ~29 ~4 ~10 ~29 ~6 ~10 sand 0  
fill ~30 ~4 ~9 ~34 ~4 ~9 stone 0  
fill ~30 ~4 ~10 ~34 ~4 ~10 stone 0  
fill ~30 ~4 ~99 ~74 ~4 ~99 stone 0  
fill ~32 ~4 ~8 ~32 ~6 ~8 sand 0  
fill ~32 ~4 ~100 ~72 ~4 ~100 stone 0  
fill ~33 ~4 ~8 ~34 ~4 ~8 stone 0  
fill ~34 ~4 ~101 ~70 ~4 ~101 stone 0 
setblock ~37 ~4 ~8 cactus 1  
fill ~37 ~4 ~102 ~67 ~4 ~102 stone 0 
setblock ~38 ~4 ~4 leaves 15  
fill ~39 ~4 ~11 ~39 ~5 ~11 cactus 0  
fill ~40 ~4 ~103 ~64 ~4 ~103 stone 0 
setblock ~41 ~4 ~4 leaves 15  
fill ~41 ~4 ~12 ~80 ~4 ~12 stone 0  
fill ~45 ~4 ~104 ~59 ~4 ~104 stone 0  
fill ~47 ~4 ~10 ~76 ~4 ~10 stone 0  
fill ~47 ~4 ~11 ~78 ~4 ~11 stone 0  
fill ~57 ~4 ~9 ~74 ~4 ~9 stone 0  
fill ~58 ~4 ~7 ~70 ~4 ~7 stone 0  
fill ~58 ~4 ~8 ~72 ~4 ~8 stone 0  
fill ~59 ~4 ~5 ~64 ~4 ~5 stone 0  
fill ~59 ~4 ~6 ~67 ~4 ~6 stone 0  
fill ~2 ~5 ~47 ~102 ~5 ~47 stone 0  
fill ~2 ~5 ~48 ~102 ~5 ~48 stone 0  
fill ~2 ~5 ~49 ~102 ~5 ~49 stone 0  
fill ~2 ~5 ~50 ~102 ~5 ~50 stone 0  
fill ~2 ~5 ~51 ~102 ~5 ~51 stone 0  
fill ~2 ~5 ~52 ~102 ~5 ~52 stone 0  
fill ~2 ~5 ~53 ~102 ~5 ~53 stone 0  
fill ~2 ~5 ~54 ~102 ~5 ~54 stone 0  
fill ~2 ~5 ~55 ~102 ~5 ~55 stone 0  
fill ~2 ~5 ~56 ~102 ~5 ~56 stone 0  
fill ~2 ~5 ~57 ~102 ~5 ~57 stone 0  
fill ~2 ~5 ~58 ~102 ~5 ~58 stone 0  
fill ~2 ~5 ~59 ~102 ~5 ~59 stone 0  
fill ~2 ~5 ~60 ~102 ~5 ~60 stone 0  
fill ~2 ~5 ~61 ~102 ~5 ~61 stone 0  
fill ~3 ~5 ~42 ~101 ~5 ~42 stone 0  
fill ~3 ~5 ~43 ~101 ~5 ~43 stone 0  
fill ~3 ~5 ~44 ~101 ~5 ~44 stone 0  
fill ~3 ~5 ~45 ~101 ~5 ~45 stone 0  
fill ~3 ~5 ~46 ~101 ~5 ~46 stone 0  
fill ~3 ~5 ~62 ~101 ~5 ~62 stone 0  
fill ~3 ~5 ~63 ~101 ~5 ~63 stone 0  
fill ~3 ~5 ~64 ~101 ~5 ~64 stone 0  
fill ~3 ~5 ~65 ~101 ~5 ~65 stone 0  
fill ~3 ~5 ~66 ~101 ~5 ~66 stone 0  
fill ~4 ~5 ~39 ~100 ~5 ~39 stone 0  
fill ~4 ~5 ~40 ~100 ~5 ~40 stone 0  
fill ~4 ~5 ~41 ~100 ~5 ~41 stone 0  
fill ~4 ~5 ~67 ~100 ~5 ~67 stone 0  
fill ~4 ~5 ~68 ~100 ~5 ~68 stone 0  
fill ~4 ~5 ~69 ~100 ~5 ~69 stone 0  
fill ~5 ~5 ~36 ~99 ~5 ~36 stone 0  
fill ~5 ~5 ~37 ~99 ~5 ~37 stone 0  
fill ~5 ~5 ~38 ~99 ~5 ~38 stone 0  
fill ~5 ~5 ~70 ~99 ~5 ~70 stone 0  
fill ~5 ~5 ~71 ~99 ~5 ~71 stone 0  
fill ~5 ~5 ~72 ~99 ~5 ~72 stone 0  
fill ~6 ~5 ~34 ~98 ~5 ~34 stone 0  
fill ~6 ~5 ~35 ~98 ~5 ~35 stone 0  
fill ~6 ~5 ~73 ~98 ~5 ~73 stone 0  
fill ~6 ~5 ~74 ~98 ~5 ~74 stone 0  
fill ~7 ~5 ~32 ~97 ~5 ~32 stone 0  
fill ~7 ~5 ~33 ~97 ~5 ~33 stone 0  
fill ~7 ~5 ~75 ~97 ~5 ~75 stone 0  
fill ~7 ~5 ~76 ~97 ~5 ~76 stone 0  
fill ~8 ~5 ~30 ~96 ~5 ~30 stone 0  
fill ~8 ~5 ~31 ~96 ~5 ~31 stone 0  
fill ~8 ~5 ~77 ~96 ~5 ~77 stone 0  
fill ~8 ~5 ~78 ~96 ~5 ~78 stone 0  
fill ~9 ~5 ~28 ~95 ~5 ~28 stone 0  
fill ~9 ~5 ~29 ~95 ~5 ~29 stone 0  
fill ~9 ~5 ~79 ~95 ~5 ~79 stone 0  
fill ~9 ~5 ~80 ~95 ~5 ~80 stone 0  
fill ~10 ~5 ~26 ~94 ~5 ~26 stone 0  
fill ~10 ~5 ~27 ~94 ~5 ~27 stone 0  
fill ~10 ~5 ~81 ~94 ~5 ~81 stone 0  
fill ~10 ~5 ~82 ~94 ~5 ~82 stone 0  
fill ~11 ~5 ~25 ~93 ~5 ~25 stone 0  
fill ~11 ~5 ~83 ~93 ~5 ~83 stone 0  
fill ~12 ~5 ~24 ~92 ~5 ~24 stone 0  
fill ~12 ~5 ~84 ~92 ~5 ~84 stone 0  
fill ~13 ~5 ~22 ~91 ~5 ~22 stone 0  
fill ~13 ~5 ~23 ~91 ~5 ~23 stone 0  
fill ~13 ~5 ~85 ~91 ~5 ~85 stone 0  
fill ~13 ~5 ~86 ~91 ~5 ~86 stone 0  
fill ~14 ~5 ~21 ~90 ~5 ~21 stone 0  
fill ~14 ~5 ~87 ~90 ~5 ~87 stone 0  
fill ~15 ~5 ~20 ~89 ~5 ~20 stone 0  
fill ~15 ~5 ~88 ~89 ~5 ~88 stone 0  
fill ~16 ~5 ~19 ~16 ~6 ~19 dirt 0  
fill ~16 ~5 ~89 ~88 ~5 ~89 stone 0  
fill ~17 ~5 ~18 ~87 ~5 ~18 stone 0  
fill ~17 ~5 ~19 ~88 ~5 ~19 stone 0  
fill ~17 ~5 ~90 ~87 ~5 ~90 stone 0  
fill ~18 ~5 ~17 ~86 ~5 ~17 stone 0  
fill ~18 ~5 ~91 ~86 ~5 ~91 stone 0  
fill ~19 ~5 ~16 ~19 ~6 ~16 dirt 0  
fill ~19 ~5 ~92 ~85 ~5 ~92 stone 0  
fill ~20 ~5 ~15 ~20 ~6 ~15 dirt 0  
fill ~20 ~5 ~16 ~85 ~5 ~16 stone 0  
fill ~20 ~5 ~93 ~84 ~5 ~93 stone 0  
fill ~21 ~5 ~15 ~36 ~5 ~15 stone 0  
fill ~22 ~5 ~14 ~82 ~5 ~14 stone 0  
fill ~22 ~5 ~94 ~82 ~5 ~94 stone 0  
fill ~23 ~5 ~13 ~81 ~5 ~13 stone 0  
fill ~23 ~5 ~95 ~81 ~5 ~95 stone 0  
fill ~24 ~5 ~12 ~35 ~5 ~12 stone 0  
fill ~24 ~5 ~96 ~80 ~5 ~96 stone 0  
fill ~26 ~5 ~11 ~35 ~5 ~11 stone 0  
fill ~26 ~5 ~97 ~78 ~5 ~97 stone 0  
fill ~28 ~5 ~10 ~28 ~6 ~10 sand 0  
fill ~28 ~5 ~98 ~76 ~5 ~98 stone 0  
fill ~30 ~5 ~9 ~31 ~5 ~9 sand 0  
fill ~30 ~5 ~10 ~34 ~5 ~10 stone 0  
fill ~30 ~5 ~99 ~74 ~5 ~99 stone 0  
fill ~32 ~5 ~9 ~34 ~5 ~9 stone 0  
fill ~32 ~5 ~100 ~72 ~5 ~100 stone 0  
fill ~33 ~5 ~8 ~33 ~6 ~8 sand 0  
fill ~34 ~5 ~7 ~34 ~6 ~7 sand 0 
setblock ~34 ~5 ~8 stone 0  
fill ~34 ~5 ~101 ~70 ~5 ~101 stone 0 
setblock ~37 ~5 ~8 cactus 0 
setblock ~37 ~5 ~15 command_block 1  
fill ~37 ~5 ~102 ~67 ~5 ~102 stone 0  
fill ~38 ~5 ~15 ~84 ~5 ~15 stone 0  
fill ~39 ~5 ~5 ~40 ~5 ~5 leaves 15 
setblock ~40 ~5 ~4 leaves 15  
fill ~40 ~5 ~103 ~64 ~5 ~103 stone 0  
fill ~41 ~5 ~12 ~45 ~5 ~12 stone 0  
fill ~45 ~5 ~104 ~59 ~5 ~104 stone 0  
fill ~46 ~5 ~12 ~46 ~8 ~12 stone 5  
fill ~47 ~5 ~10 ~76 ~5 ~10 stone 0  
fill ~47 ~5 ~11 ~78 ~5 ~11 stone 0  
fill ~47 ~5 ~12 ~80 ~5 ~12 stone 0 
setblock ~57 ~5 ~9 stone 5  
fill ~58 ~5 ~7 ~70 ~5 ~7 stone 0  
fill ~58 ~5 ~8 ~72 ~5 ~8 stone 0  
fill ~58 ~5 ~9 ~74 ~5 ~9 stone 0  
fill ~59 ~5 ~5 ~64 ~5 ~5 stone 0  
fill ~59 ~5 ~6 ~67 ~5 ~6 stone 0  
fill ~2 ~6 ~47 ~102 ~6 ~47 stone 0  
fill ~2 ~6 ~48 ~102 ~6 ~48 stone 0  
fill ~2 ~6 ~49 ~102 ~6 ~49 stone 0  
fill ~2 ~6 ~50 ~102 ~6 ~50 stone 0  
fill ~2 ~6 ~51 ~102 ~6 ~51 stone 0  
fill ~2 ~6 ~52 ~102 ~6 ~52 stone 0  
fill ~2 ~6 ~53 ~102 ~6 ~53 stone 0  
fill ~2 ~6 ~54 ~102 ~6 ~54 stone 0  
fill ~2 ~6 ~55 ~102 ~6 ~55 stone 0  
fill ~2 ~6 ~56 ~102 ~6 ~56 stone 0  
fill ~2 ~6 ~57 ~102 ~6 ~57 stone 0  
fill ~2 ~6 ~58 ~102 ~6 ~58 stone 0  
fill ~2 ~6 ~59 ~102 ~6 ~59 stone 0  
fill ~2 ~6 ~60 ~102 ~6 ~60 stone 0  
fill ~2 ~6 ~61 ~102 ~6 ~61 stone 0  
fill ~3 ~6 ~42 ~101 ~6 ~42 stone 0  
fill ~3 ~6 ~43 ~101 ~6 ~43 stone 0  
fill ~3 ~6 ~44 ~101 ~6 ~44 stone 0  
fill ~3 ~6 ~45 ~101 ~6 ~45 stone 0  
fill ~3 ~6 ~46 ~101 ~6 ~46 stone 0  
fill ~3 ~6 ~62 ~101 ~6 ~62 stone 0  
fill ~3 ~6 ~63 ~101 ~6 ~63 stone 0  
fill ~3 ~6 ~64 ~101 ~6 ~64 stone 0  
fill ~3 ~6 ~65 ~101 ~6 ~65 stone 0  
fill ~3 ~6 ~66 ~101 ~6 ~66 stone 0  
fill ~4 ~6 ~39 ~100 ~6 ~39 stone 0  
fill ~4 ~6 ~40 ~100 ~6 ~40 stone 0  
fill ~4 ~6 ~41 ~100 ~6 ~41 stone 0  
fill ~4 ~6 ~67 ~100 ~6 ~67 stone 0  
fill ~4 ~6 ~68 ~100 ~6 ~68 stone 0  
fill ~4 ~6 ~69 ~100 ~6 ~69 stone 0  
fill ~5 ~6 ~36 ~99 ~6 ~36 stone 0  
fill ~5 ~6 ~37 ~99 ~6 ~37 stone 0  
fill ~5 ~6 ~38 ~99 ~6 ~38 stone 0  
fill ~5 ~6 ~70 ~99 ~6 ~70 stone 0  
fill ~5 ~6 ~71 ~99 ~6 ~71 stone 0  
fill ~5 ~6 ~72 ~99 ~6 ~72 stone 0  
fill ~6 ~6 ~34 ~98 ~6 ~34 stone 0  
fill ~6 ~6 ~35 ~98 ~6 ~35 stone 0  
fill ~6 ~6 ~73 ~98 ~6 ~73 stone 0  
fill ~6 ~6 ~74 ~98 ~6 ~74 stone 0  
fill ~7 ~6 ~32 ~97 ~6 ~32 stone 0  
fill ~7 ~6 ~33 ~97 ~6 ~33 stone 0  
fill ~7 ~6 ~75 ~97 ~6 ~75 stone 0  
fill ~7 ~6 ~76 ~97 ~6 ~76 stone 0  
fill ~8 ~6 ~30 ~96 ~6 ~30 stone 0  
fill ~8 ~6 ~31 ~96 ~6 ~31 stone 0  
fill ~8 ~6 ~77 ~96 ~6 ~77 stone 0  
fill ~8 ~6 ~78 ~96 ~6 ~78 stone 0  
fill ~9 ~6 ~28 ~95 ~6 ~28 stone 0  
fill ~9 ~6 ~29 ~95 ~6 ~29 stone 0  
fill ~9 ~6 ~79 ~95 ~6 ~79 stone 0  
fill ~9 ~6 ~80 ~95 ~6 ~80 stone 0  
fill ~10 ~6 ~26 ~94 ~6 ~26 stone 0  
fill ~10 ~6 ~27 ~94 ~6 ~27 stone 0  
fill ~10 ~6 ~81 ~94 ~6 ~81 stone 0  
fill ~10 ~6 ~82 ~94 ~6 ~82 stone 0  
fill ~11 ~6 ~25 ~93 ~6 ~25 stone 0  
fill ~11 ~6 ~83 ~93 ~6 ~83 stone 0  
fill ~12 ~6 ~24 ~92 ~6 ~24 stone 0  
fill ~12 ~6 ~84 ~92 ~6 ~84 stone 0  
fill ~13 ~6 ~22 ~91 ~6 ~22 stone 0  
fill ~13 ~6 ~23 ~91 ~6 ~23 stone 0  
fill ~13 ~6 ~85 ~91 ~6 ~85 stone 0  
fill ~13 ~6 ~86 ~91 ~6 ~86 stone 0  
fill ~14 ~6 ~21 ~90 ~6 ~21 stone 0  
fill ~14 ~6 ~87 ~90 ~6 ~87 stone 0 
setblock ~15 ~6 ~20 dirt 0  
fill ~15 ~6 ~88 ~89 ~6 ~88 stone 0  
fill ~16 ~6 ~20 ~89 ~6 ~20 stone 0  
fill ~16 ~6 ~89 ~88 ~6 ~89 stone 0 
setblock ~17 ~6 ~18 dirt 0  
fill ~17 ~6 ~19 ~88 ~6 ~19 stone 0  
fill ~17 ~6 ~90 ~87 ~6 ~90 stone 0 
setblock ~18 ~6 ~17 dirt 0  
fill ~18 ~6 ~18 ~87 ~6 ~18 stone 0  
fill ~18 ~6 ~91 ~86 ~6 ~91 stone 0  
fill ~19 ~6 ~17 ~86 ~6 ~17 stone 0  
fill ~19 ~6 ~92 ~85 ~6 ~92 stone 0  
fill ~20 ~6 ~16 ~30 ~6 ~16 stone 0  
fill ~20 ~6 ~93 ~84 ~6 ~93 stone 0 
setblock ~21 ~6 ~15 dirt 0 
setblock ~22 ~6 ~14 dirt 0  
fill ~22 ~6 ~15 ~29 ~6 ~15 stone 0  
fill ~22 ~6 ~94 ~82 ~6 ~94 stone 0  
fill ~23 ~6 ~13 ~27 ~6 ~13 stone 0  
fill ~23 ~6 ~14 ~28 ~6 ~14 stone 0  
fill ~23 ~6 ~95 ~81 ~6 ~95 stone 0  
fill ~24 ~6 ~12 ~27 ~6 ~12 stone 0  
fill ~24 ~6 ~96 ~80 ~6 ~96 stone 0  
fill ~26 ~6 ~11 ~27 ~6 ~11 stone 0  
fill ~26 ~6 ~97 ~78 ~6 ~97 stone 0  
fill ~28 ~6 ~11 ~29 ~6 ~11 sand 0  
fill ~28 ~6 ~12 ~33 ~6 ~12 water 0  
fill ~28 ~6 ~13 ~34 ~6 ~13 water 0  
fill ~28 ~6 ~98 ~76 ~6 ~98 stone 0  
fill ~29 ~6 ~14 ~35 ~6 ~14 water 0  
fill ~30 ~6 ~9 ~33 ~6 ~9 sand 0  
fill ~30 ~6 ~10 ~33 ~6 ~10 sand 0  
fill ~30 ~6 ~11 ~32 ~6 ~11 water 0  
fill ~30 ~6 ~15 ~34 ~6 ~15 water 0  
fill ~30 ~6 ~99 ~74 ~6 ~99 stone 0  
fill ~31 ~6 ~16 ~33 ~6 ~16 water 0  
fill ~32 ~6 ~100 ~72 ~6 ~100 stone 0 
setblock ~33 ~6 ~11 sand 0 
setblock ~34 ~6 ~8 sand 0  
fill ~34 ~6 ~9 ~34 ~6 ~10 stone 0 
setblock ~34 ~6 ~11 grass 0 
setblock ~34 ~6 ~12 sand 0  
fill ~34 ~6 ~16 ~37 ~6 ~16 sand 0  
fill ~34 ~6 ~101 ~70 ~6 ~101 stone 0  
fill ~35 ~6 ~11 ~35 ~6 ~12 stone 0 
setblock ~35 ~6 ~13 sand 0  
fill ~35 ~6 ~15 ~38 ~6 ~15 sand 0  
fill ~36 ~6 ~13 ~39 ~6 ~13 stone 0  
fill ~36 ~6 ~14 ~39 ~6 ~14 sand 0  
fill ~37 ~6 ~102 ~67 ~6 ~102 stone 0  
fill ~38 ~6 ~16 ~85 ~6 ~16 stone 0  
fill ~39 ~6 ~15 ~84 ~6 ~15 stone 0  
fill ~40 ~6 ~13 ~41 ~6 ~13 double_stone_slab 1  
fill ~40 ~6 ~14 ~82 ~6 ~14 stone 0  
fill ~40 ~6 ~103 ~64 ~6 ~103 stone 0 
setblock ~41 ~6 ~12 stone_slab 1  
fill ~42 ~6 ~12 ~44 ~6 ~12 stone 0  
fill ~42 ~6 ~13 ~81 ~6 ~13 stone 0  
fill ~45 ~6 ~12 ~45 ~7 ~12 stone 5  
fill ~45 ~6 ~104 ~59 ~6 ~104 stone 0  
fill ~47 ~6 ~10 ~76 ~6 ~10 stone 0  
fill ~47 ~6 ~11 ~78 ~6 ~11 stone 0  
fill ~47 ~6 ~12 ~80 ~6 ~12 stone 0  
fill ~56 ~6 ~9 ~74 ~6 ~9 stone 0  
fill ~57 ~6 ~8 ~72 ~6 ~8 stone 0  
fill ~58 ~6 ~7 ~70 ~6 ~7 stone 0  
fill ~59 ~6 ~5 ~64 ~6 ~5 stone 0  
fill ~59 ~6 ~6 ~67 ~6 ~6 stone 0  
fill ~2 ~7 ~47 ~102 ~7 ~47 stone 0  
fill ~2 ~7 ~48 ~102 ~7 ~48 stone 0  
fill ~2 ~7 ~49 ~102 ~7 ~49 stone 0  
fill ~2 ~7 ~50 ~102 ~7 ~50 stone 0  
fill ~2 ~7 ~51 ~102 ~7 ~51 stone 0  
fill ~2 ~7 ~52 ~102 ~7 ~52 stone 0  
fill ~2 ~7 ~53 ~102 ~7 ~53 stone 0  
fill ~2 ~7 ~54 ~102 ~7 ~54 stone 0  
fill ~2 ~7 ~55 ~102 ~7 ~55 stone 0  
fill ~2 ~7 ~56 ~102 ~7 ~56 stone 0  
fill ~2 ~7 ~57 ~102 ~7 ~57 stone 0  
fill ~2 ~7 ~58 ~102 ~7 ~58 stone 0  
fill ~2 ~7 ~59 ~102 ~7 ~59 stone 0  
fill ~2 ~7 ~60 ~102 ~7 ~60 stone 0  
fill ~2 ~7 ~61 ~102 ~7 ~61 stone 0  
fill ~3 ~7 ~42 ~101 ~7 ~42 stone 0  
fill ~3 ~7 ~43 ~101 ~7 ~43 stone 0  
fill ~3 ~7 ~44 ~101 ~7 ~44 stone 0  
fill ~3 ~7 ~45 ~101 ~7 ~45 stone 0  
fill ~3 ~7 ~46 ~101 ~7 ~46 stone 0  
fill ~3 ~7 ~62 ~101 ~7 ~62 stone 0  
fill ~3 ~7 ~63 ~101 ~7 ~63 stone 0  
fill ~3 ~7 ~64 ~101 ~7 ~64 stone 0  
fill ~3 ~7 ~65 ~101 ~7 ~65 stone 0  
fill ~3 ~7 ~66 ~101 ~7 ~66 stone 0  
fill ~4 ~7 ~39 ~100 ~7 ~39 stone 0  
fill ~4 ~7 ~40 ~100 ~7 ~40 stone 0  
fill ~4 ~7 ~41 ~100 ~7 ~41 stone 0  
fill ~4 ~7 ~67 ~100 ~7 ~67 stone 0  
fill ~4 ~7 ~68 ~100 ~7 ~68 stone 0  
fill ~4 ~7 ~69 ~100 ~7 ~69 stone 0  
fill ~5 ~7 ~36 ~99 ~7 ~36 stone 0  
fill ~5 ~7 ~37 ~99 ~7 ~37 stone 0  
fill ~5 ~7 ~38 ~99 ~7 ~38 stone 0  
fill ~5 ~7 ~70 ~99 ~7 ~70 stone 0  
fill ~5 ~7 ~71 ~99 ~7 ~71 stone 0  
fill ~5 ~7 ~72 ~99 ~7 ~72 stone 0  
fill ~6 ~7 ~34 ~98 ~7 ~34 stone 0  
fill ~6 ~7 ~35 ~98 ~7 ~35 stone 0  
fill ~6 ~7 ~73 ~98 ~7 ~73 stone 0  
fill ~6 ~7 ~74 ~98 ~7 ~74 stone 0  
fill ~7 ~7 ~32 ~97 ~7 ~32 stone 0  
fill ~7 ~7 ~33 ~97 ~7 ~33 stone 0  
fill ~7 ~7 ~75 ~97 ~7 ~75 stone 0  
fill ~7 ~7 ~76 ~97 ~7 ~76 stone 0  
fill ~8 ~7 ~30 ~96 ~7 ~30 stone 0  
fill ~8 ~7 ~31 ~96 ~7 ~31 stone 0  
fill ~8 ~7 ~77 ~96 ~7 ~77 stone 0  
fill ~8 ~7 ~78 ~96 ~7 ~78 stone 0  
fill ~9 ~7 ~28 ~95 ~7 ~28 stone 0  
fill ~9 ~7 ~29 ~95 ~7 ~29 stone 0  
fill ~9 ~7 ~79 ~95 ~7 ~79 stone 0  
fill ~9 ~7 ~80 ~95 ~7 ~80 stone 0  
fill ~10 ~7 ~26 ~94 ~7 ~26 stone 0  
fill ~10 ~7 ~27 ~94 ~7 ~27 stone 0  
fill ~10 ~7 ~81 ~94 ~7 ~81 stone 0  
fill ~10 ~7 ~82 ~94 ~7 ~82 stone 0  
fill ~11 ~7 ~25 ~93 ~7 ~25 stone 0  
fill ~11 ~7 ~83 ~93 ~7 ~83 stone 0  
fill ~12 ~7 ~24 ~18 ~7 ~24 stone 0  
fill ~12 ~7 ~84 ~92 ~7 ~84 stone 0  
fill ~13 ~7 ~22 ~14 ~7 ~22 stone 0  
fill ~13 ~7 ~23 ~17 ~7 ~23 stone 0  
fill ~13 ~7 ~85 ~91 ~7 ~85 stone 0  
fill ~13 ~7 ~86 ~91 ~7 ~86 stone 0  
fill ~14 ~7 ~21 ~14 ~9 ~21 stone 0  
fill ~14 ~7 ~87 ~90 ~7 ~87 stone 0  
fill ~15 ~7 ~20 ~18 ~7 ~20 grass 0  
fill ~15 ~7 ~21 ~19 ~7 ~21 grass 0  
fill ~15 ~7 ~22 ~22 ~7 ~22 grass 0  
fill ~15 ~7 ~88 ~89 ~7 ~88 stone 0  
fill ~16 ~7 ~19 ~18 ~7 ~19 grass 0  
fill ~16 ~7 ~89 ~88 ~7 ~89 stone 0  
fill ~17 ~7 ~18 ~19 ~7 ~18 grass 0  
fill ~17 ~7 ~90 ~87 ~7 ~90 stone 0  
fill ~18 ~7 ~17 ~19 ~7 ~17 grass 0  
fill ~18 ~7 ~23 ~22 ~7 ~23 grass 0  
fill ~18 ~7 ~91 ~86 ~7 ~91 stone 0 
setblock ~19 ~7 ~16 grass 0  
fill ~19 ~7 ~19 ~27 ~7 ~19 water 0  
fill ~19 ~7 ~20 ~24 ~7 ~20 water 0  
fill ~19 ~7 ~24 ~22 ~7 ~24 grass 0  
fill ~19 ~7 ~92 ~85 ~7 ~92 stone 0  
fill ~20 ~7 ~15 ~23 ~7 ~15 grass 0  
fill ~20 ~7 ~16 ~21 ~7 ~16 stone 0  
fill ~20 ~7 ~17 ~21 ~7 ~17 stone 0  
fill ~20 ~7 ~18 ~28 ~7 ~18 water 0  
fill ~20 ~7 ~21 ~22 ~7 ~21 water 0  
fill ~20 ~7 ~93 ~84 ~7 ~93 stone 0  
fill ~22 ~7 ~14 ~23 ~7 ~14 grass 0  
fill ~22 ~7 ~16 ~29 ~7 ~16 water 0  
fill ~22 ~7 ~17 ~29 ~7 ~17 water 0  
fill ~22 ~7 ~94 ~82 ~7 ~94 stone 0  
fill ~23 ~7 ~13 ~26 ~7 ~13 stone 0  
fill ~23 ~7 ~21 ~27 ~7 ~21 grass 0  
fill ~23 ~7 ~22 ~24 ~7 ~22 stone 0  
fill ~23 ~7 ~23 ~91 ~7 ~23 stone 0  
fill ~23 ~7 ~24 ~92 ~7 ~24 stone 0  
fill ~23 ~7 ~95 ~81 ~7 ~95 stone 0  
fill ~24 ~7 ~12 ~27 ~7 ~12 stone 0  
fill ~24 ~7 ~14 ~24 ~9 ~14 stone 0  
fill ~24 ~7 ~15 ~29 ~7 ~15 water 0  
fill ~24 ~7 ~96 ~80 ~7 ~96 stone 0  
fill ~25 ~7 ~14 ~29 ~7 ~14 water 0  
fill ~25 ~7 ~20 ~31 ~7 ~20 grass 0  
fill ~25 ~7 ~22 ~26 ~7 ~22 grass 0  
fill ~26 ~7 ~11 ~27 ~7 ~11 stone 0  
fill ~26 ~7 ~97 ~78 ~7 ~97 stone 0  
fill ~27 ~7 ~13 ~29 ~7 ~13 water 1  
fill ~27 ~7 ~22 ~91 ~7 ~22 stone 0  
fill ~28 ~7 ~19 ~33 ~7 ~19 grass 0  
fill ~28 ~7 ~21 ~90 ~7 ~21 stone 0  
fill ~28 ~7 ~98 ~76 ~7 ~98 stone 0  
fill ~29 ~7 ~18 ~35 ~7 ~18 grass 0 
setblock ~30 ~7 ~10 cactus 0  
fill ~30 ~7 ~14 ~30 ~7 ~16 water 1  
fill ~30 ~7 ~17 ~35 ~7 ~17 grass 0  
fill ~30 ~7 ~99 ~74 ~7 ~99 stone 0 
setblock ~31 ~7 ~13 waterlily 0 
setblock ~31 ~7 ~16 water 2 
setblock ~32 ~7 ~11 waterlily 0  
fill ~32 ~7 ~20 ~89 ~7 ~20 stone 0  
fill ~32 ~7 ~100 ~72 ~7 ~100 stone 0 
setblock ~33 ~7 ~15 waterlily 0  
fill ~34 ~7 ~7 ~34 ~7 ~11 stone_slab 1  
fill ~34 ~7 ~19 ~88 ~7 ~19 stone 0  
fill ~34 ~7 ~101 ~70 ~7 ~101 stone 0  
fill ~35 ~7 ~11 ~35 ~7 ~13 stone_slab 1  
fill ~36 ~7 ~13 ~39 ~7 ~13 stone_slab 1  
fill ~36 ~7 ~17 ~86 ~7 ~17 stone 0  
fill ~36 ~7 ~18 ~87 ~7 ~18 stone 0 
setblock ~37 ~7 ~15 light_weighted_pressure_plate 0  
fill ~37 ~7 ~102 ~67 ~7 ~102 stone 0  
fill ~38 ~7 ~16 ~85 ~7 ~16 stone 0  
fill ~39 ~7 ~15 ~84 ~7 ~15 stone 0  
fill ~40 ~7 ~14 ~82 ~7 ~14 stone 0  
fill ~40 ~7 ~103 ~64 ~7 ~103 stone 0  
fill ~42 ~7 ~13 ~81 ~7 ~13 stone 0 
setblock ~44 ~7 ~12 stone 0  
fill ~45 ~7 ~104 ~59 ~7 ~104 stone 0  
fill ~47 ~7 ~11 ~78 ~7 ~11 stone 0 
setblock ~47 ~7 ~12 stone 5  
fill ~48 ~7 ~10 ~76 ~7 ~10 stone 0  
fill ~48 ~7 ~12 ~80 ~7 ~12 stone 0  
fill ~54 ~7 ~9 ~74 ~7 ~9 stone 0  
fill ~57 ~7 ~8 ~72 ~7 ~8 stone 0  
fill ~58 ~7 ~6 ~67 ~7 ~6 stone 0  
fill ~58 ~7 ~7 ~70 ~7 ~7 stone 0  
fill ~59 ~7 ~4 ~59 ~31 ~4 stone 0  
fill ~59 ~7 ~5 ~64 ~7 ~5 stone 0  
fill ~2 ~8 ~47 ~102 ~8 ~47 stone 0  
fill ~2 ~8 ~48 ~102 ~8 ~48 stone 0  
fill ~2 ~8 ~49 ~102 ~8 ~49 stone 0  
fill ~2 ~8 ~50 ~102 ~8 ~50 stone 0  
fill ~2 ~8 ~51 ~102 ~8 ~51 stone 0  
fill ~2 ~8 ~52 ~102 ~8 ~52 stone 0  
fill ~2 ~8 ~53 ~102 ~8 ~53 stone 0  
fill ~2 ~8 ~54 ~102 ~8 ~54 stone 0  
fill ~2 ~8 ~55 ~102 ~8 ~55 stone 0  
fill ~2 ~8 ~56 ~102 ~8 ~56 stone 0  
fill ~2 ~8 ~57 ~102 ~8 ~57 stone 0  
fill ~2 ~8 ~58 ~102 ~8 ~58 stone 0  
fill ~2 ~8 ~59 ~102 ~8 ~59 stone 0  
fill ~2 ~8 ~60 ~102 ~8 ~60 stone 0  
fill ~2 ~8 ~61 ~102 ~8 ~61 stone 0  
fill ~3 ~8 ~42 ~101 ~8 ~42 stone 0  
fill ~3 ~8 ~43 ~101 ~8 ~43 stone 0  
fill ~3 ~8 ~44 ~101 ~8 ~44 stone 0  
fill ~3 ~8 ~45 ~101 ~8 ~45 stone 0  
fill ~3 ~8 ~46 ~101 ~8 ~46 stone 0  
fill ~3 ~8 ~62 ~101 ~8 ~62 stone 0  
fill ~3 ~8 ~63 ~101 ~8 ~63 stone 0  
fill ~3 ~8 ~64 ~101 ~8 ~64 stone 0  
fill ~3 ~8 ~65 ~101 ~8 ~65 stone 0  
fill ~3 ~8 ~66 ~101 ~8 ~66 stone 0  
fill ~4 ~8 ~39 ~100 ~8 ~39 stone 0  
fill ~4 ~8 ~40 ~100 ~8 ~40 stone 0  
fill ~4 ~8 ~41 ~100 ~8 ~41 stone 0  
fill ~4 ~8 ~67 ~100 ~8 ~67 stone 0  
fill ~4 ~8 ~68 ~100 ~8 ~68 stone 0  
fill ~4 ~8 ~69 ~100 ~8 ~69 stone 0  
fill ~5 ~8 ~36 ~99 ~8 ~36 stone 0  
fill ~5 ~8 ~37 ~99 ~8 ~37 stone 0  
fill ~5 ~8 ~38 ~99 ~8 ~38 stone 0  
fill ~5 ~8 ~70 ~99 ~8 ~70 stone 0  
fill ~5 ~8 ~71 ~99 ~8 ~71 stone 0  
fill ~5 ~8 ~72 ~99 ~8 ~72 stone 0  
fill ~6 ~8 ~34 ~98 ~8 ~34 stone 0  
fill ~6 ~8 ~35 ~98 ~8 ~35 stone 0  
fill ~6 ~8 ~73 ~98 ~8 ~73 stone 0  
fill ~6 ~8 ~74 ~98 ~8 ~74 stone 0  
fill ~7 ~8 ~32 ~97 ~8 ~32 stone 0  
fill ~7 ~8 ~33 ~97 ~8 ~33 stone 0  
fill ~7 ~8 ~75 ~97 ~8 ~75 stone 0  
fill ~7 ~8 ~76 ~97 ~8 ~76 stone 0  
fill ~8 ~8 ~30 ~96 ~8 ~30 stone 0  
fill ~8 ~8 ~31 ~96 ~8 ~31 stone 0  
fill ~8 ~8 ~77 ~96 ~8 ~77 stone 0  
fill ~8 ~8 ~78 ~96 ~8 ~78 stone 0  
fill ~9 ~8 ~28 ~95 ~8 ~28 stone 0  
fill ~9 ~8 ~29 ~95 ~8 ~29 stone 0  
fill ~9 ~8 ~79 ~95 ~8 ~79 stone 0  
fill ~9 ~8 ~80 ~95 ~8 ~80 stone 0  
fill ~10 ~8 ~26 ~94 ~8 ~26 stone 0  
fill ~10 ~8 ~27 ~94 ~8 ~27 stone 0  
fill ~10 ~8 ~81 ~94 ~8 ~81 stone 0  
fill ~10 ~8 ~82 ~94 ~8 ~82 stone 0  
fill ~11 ~8 ~25 ~93 ~8 ~25 stone 0  
fill ~11 ~8 ~83 ~93 ~8 ~83 stone 0  
fill ~12 ~8 ~24 ~16 ~8 ~24 stone 0  
fill ~12 ~8 ~84 ~92 ~8 ~84 stone 0  
fill ~13 ~8 ~22 ~14 ~8 ~22 stone 0  
fill ~13 ~8 ~23 ~17 ~8 ~23 stone 0  
fill ~13 ~8 ~85 ~91 ~8 ~85 stone 0  
fill ~13 ~8 ~86 ~91 ~8 ~86 stone 0  
fill ~14 ~8 ~87 ~90 ~8 ~87 stone 0  
fill ~15 ~8 ~88 ~89 ~8 ~88 stone 0  
fill ~16 ~8 ~19 ~17 ~8 ~19 tallgrass 0  
fill ~16 ~8 ~89 ~88 ~8 ~89 stone 0  
fill ~17 ~8 ~18 ~18 ~8 ~18 tallgrass 0 
setblock ~17 ~8 ~21 red_flower 0 
setblock ~17 ~8 ~22 tallgrass 0 
setblock ~17 ~8 ~24 command_block 1  
fill ~17 ~8 ~90 ~87 ~8 ~90 stone 0 
setblock ~18 ~8 ~17 tallgrass 0 
setblock ~18 ~8 ~19 red_flower 8 
setblock ~18 ~8 ~20 tallgrass 0 
setblock ~18 ~8 ~23 tallgrass 0  
fill ~18 ~8 ~24 ~18 ~9 ~24 stone 0  
fill ~18 ~8 ~91 ~86 ~8 ~91 stone 0  
fill ~19 ~8 ~22 ~22 ~8 ~22 tallgrass 0  
fill ~19 ~8 ~24 ~22 ~8 ~24 tallgrass 0  
fill ~19 ~8 ~92 ~85 ~8 ~92 stone 0  
fill ~20 ~8 ~16 ~21 ~8 ~16 stone 0  
fill ~20 ~8 ~17 ~21 ~8 ~17 stone 0 
setblock ~20 ~8 ~23 tallgrass 0  
fill ~20 ~8 ~93 ~84 ~8 ~93 stone 0  
fill ~22 ~8 ~15 ~23 ~8 ~15 tallgrass 0 
setblock ~22 ~8 ~20 waterlily 0 
setblock ~22 ~8 ~23 tallgrass 0  
fill ~22 ~8 ~94 ~82 ~8 ~94 stone 0  
fill ~23 ~8 ~13 ~26 ~8 ~13 stone 0 
setblock ~23 ~8 ~14 tallgrass 0  
fill ~23 ~8 ~22 ~24 ~8 ~22 stone 0  
fill ~23 ~8 ~23 ~91 ~8 ~23 stone 0  
fill ~23 ~8 ~24 ~92 ~8 ~24 stone 0  
fill ~23 ~8 ~95 ~81 ~8 ~95 stone 0  
fill ~24 ~8 ~12 ~24 ~0 ~12 stone 0 
setblock ~24 ~8 ~18 waterlily 0 
setblock ~24 ~8 ~21 red_flower 3  
fill ~24 ~8 ~96 ~80 ~8 ~96 stone 0  
fill ~25 ~8 ~12 ~25 ~9 ~12 dirt 0  
fill ~25 ~8 ~22 ~26 ~8 ~22 tallgrass 0  
fill ~26 ~8 ~11 ~27 ~8 ~11 stone 0  
fill ~26 ~8 ~12 ~27 ~8 ~12 stone 0 
setblock ~26 ~8 ~16 waterlily 0  
fill ~26 ~8 ~20 ~27 ~8 ~20 reeds 0 
setblock ~26 ~8 ~21 yellow_flower 0  
fill ~26 ~8 ~97 ~78 ~8 ~97 stone 0 
setblock ~27 ~8 ~18 waterlily 0 
setblock ~27 ~8 ~21 tallgrass 0  
fill ~27 ~8 ~22 ~91 ~8 ~22 stone 0  
fill ~28 ~8 ~19 ~28 ~10 ~19 reeds 0  
fill ~28 ~8 ~21 ~90 ~8 ~21 stone 0  
fill ~28 ~8 ~98 ~76 ~8 ~98 stone 0  
fill ~29 ~8 ~18 ~29 ~10 ~18 reeds 0 
setblock ~30 ~8 ~17 reeds 0  
fill ~30 ~8 ~18 ~31 ~8 ~18 tallgrass 0 
setblock ~30 ~8 ~19 red_flower 0 
setblock ~30 ~8 ~20 tallgrass 0  
fill ~30 ~8 ~99 ~74 ~8 ~99 stone 0 
setblock ~31 ~8 ~19 tallgrass 0 
setblock ~32 ~8 ~18 red_flower 3 
setblock ~32 ~8 ~19 yellow_flower 0  
fill ~32 ~8 ~20 ~89 ~8 ~20 stone 0  
fill ~32 ~8 ~100 ~72 ~8 ~100 stone 0 
setblock ~33 ~8 ~17 yellow_flower 0  
fill ~33 ~8 ~18 ~35 ~8 ~18 tallgrass 0  
fill ~34 ~8 ~17 ~35 ~8 ~17 tallgrass 0  
fill ~34 ~8 ~19 ~88 ~8 ~19 stone 0  
fill ~34 ~8 ~101 ~70 ~8 ~101 stone 0  
fill ~36 ~8 ~17 ~86 ~8 ~17 stone 0  
fill ~36 ~8 ~18 ~87 ~8 ~18 stone 0  
fill ~37 ~8 ~102 ~67 ~8 ~102 stone 0  
fill ~38 ~8 ~16 ~85 ~8 ~16 stone 0  
fill ~39 ~8 ~15 ~84 ~8 ~15 stone 0  
fill ~40 ~8 ~14 ~82 ~8 ~14 stone 0  
fill ~40 ~8 ~103 ~64 ~8 ~103 stone 0  
fill ~43 ~8 ~13 ~81 ~8 ~13 stone 0  
fill ~45 ~8 ~12 ~45 ~69 ~12 stone 0  
fill ~45 ~8 ~104 ~59 ~8 ~104 stone 0  
fill ~47 ~8 ~11 ~78 ~8 ~11 stone 0  
fill ~47 ~8 ~12 ~80 ~8 ~12 stone 0  
fill ~49 ~8 ~10 ~76 ~8 ~10 stone 0  
fill ~53 ~8 ~9 ~74 ~8 ~9 stone 0  
fill ~56 ~8 ~8 ~72 ~8 ~8 stone 0  
fill ~57 ~8 ~7 ~70 ~8 ~7 stone 0  
fill ~58 ~8 ~5 ~64 ~8 ~5 stone 0  
fill ~58 ~8 ~6 ~67 ~8 ~6 stone 0  
fill ~2 ~9 ~47 ~2 ~11 ~47 dirt 0  
fill ~2 ~9 ~48 ~102 ~9 ~48 stone 0  
fill ~2 ~9 ~49 ~102 ~9 ~49 stone 0  
fill ~2 ~9 ~50 ~102 ~9 ~50 stone 0  
fill ~2 ~9 ~51 ~102 ~9 ~51 stone 0  
fill ~2 ~9 ~52 ~2 ~11 ~52 dirt 0  
fill ~2 ~9 ~53 ~102 ~9 ~53 stone 0  
fill ~2 ~9 ~54 ~102 ~9 ~54 stone 0  
fill ~2 ~9 ~55 ~102 ~9 ~55 stone 0  
fill ~2 ~9 ~56 ~102 ~9 ~56 stone 0  
fill ~2 ~9 ~57 ~102 ~9 ~57 stone 0  
fill ~2 ~9 ~58 ~2 ~11 ~58 dirt 0  
fill ~2 ~9 ~59 ~102 ~9 ~59 stone 0  
fill ~2 ~9 ~60 ~102 ~9 ~60 stone 0  
fill ~2 ~9 ~61 ~102 ~9 ~61 stone 0  
fill ~3 ~9 ~42 ~101 ~9 ~42 stone 0  
fill ~3 ~9 ~43 ~101 ~9 ~43 stone 0  
fill ~3 ~9 ~44 ~101 ~9 ~44 stone 0  
fill ~3 ~9 ~45 ~101 ~9 ~45 stone 0  
fill ~3 ~9 ~46 ~101 ~9 ~46 stone 0  
fill ~3 ~9 ~47 ~102 ~9 ~47 stone 0  
fill ~3 ~9 ~52 ~102 ~9 ~52 stone 0  
fill ~3 ~9 ~58 ~102 ~9 ~58 stone 0  
fill ~3 ~9 ~62 ~101 ~9 ~62 stone 0  
fill ~3 ~9 ~63 ~3 ~11 ~63 dirt 0  
fill ~3 ~9 ~64 ~101 ~9 ~64 stone 0  
fill ~3 ~9 ~65 ~101 ~9 ~65 stone 0  
fill ~3 ~9 ~66 ~101 ~9 ~66 stone 0  
fill ~4 ~9 ~39 ~100 ~9 ~39 stone 0  
fill ~4 ~9 ~40 ~100 ~9 ~40 stone 0  
fill ~4 ~9 ~41 ~100 ~9 ~41 stone 0  
fill ~4 ~9 ~63 ~101 ~9 ~63 stone 0  
fill ~4 ~9 ~67 ~100 ~9 ~67 stone 0  
fill ~4 ~9 ~68 ~100 ~9 ~68 stone 0  
fill ~4 ~9 ~69 ~100 ~9 ~69 stone 0  
fill ~5 ~9 ~36 ~99 ~9 ~36 stone 0  
fill ~5 ~9 ~37 ~99 ~9 ~37 stone 0  
fill ~5 ~9 ~38 ~99 ~9 ~38 stone 0  
fill ~5 ~9 ~70 ~99 ~9 ~70 stone 0  
fill ~5 ~9 ~71 ~99 ~9 ~71 stone 0  
fill ~5 ~9 ~72 ~99 ~9 ~72 stone 0  
fill ~6 ~9 ~34 ~98 ~9 ~34 stone 0  
fill ~6 ~9 ~35 ~98 ~9 ~35 stone 0  
fill ~6 ~9 ~73 ~98 ~9 ~73 stone 0  
fill ~6 ~9 ~74 ~98 ~9 ~74 stone 0  
fill ~7 ~9 ~32 ~97 ~9 ~32 stone 0  
fill ~7 ~9 ~33 ~97 ~9 ~33 stone 0  
fill ~7 ~9 ~75 ~97 ~9 ~75 stone 0  
fill ~7 ~9 ~76 ~97 ~9 ~76 stone 0  
fill ~8 ~9 ~30 ~10 ~9 ~30 stone 0  
fill ~8 ~9 ~31 ~96 ~9 ~31 stone 0  
fill ~8 ~9 ~77 ~96 ~9 ~77 stone 0  
fill ~8 ~9 ~78 ~96 ~9 ~78 stone 0  
fill ~9 ~9 ~28 ~95 ~9 ~28 stone 0  
fill ~9 ~9 ~29 ~10 ~9 ~29 stone 0  
fill ~9 ~9 ~79 ~95 ~9 ~79 stone 0  
fill ~9 ~9 ~80 ~95 ~9 ~80 stone 0  
fill ~10 ~9 ~26 ~10 ~9 ~27 stone 5  
fill ~10 ~9 ~81 ~94 ~9 ~81 stone 0  
fill ~10 ~9 ~82 ~94 ~9 ~82 stone 0  
fill ~11 ~9 ~25 ~11 ~0 ~25 stone 0  
fill ~11 ~9 ~26 ~15 ~9 ~26 stone 0  
fill ~11 ~9 ~27 ~12 ~9 ~27 stone 0  
fill ~11 ~9 ~29 ~13 ~9 ~29 lava 0  
fill ~11 ~9 ~30 ~12 ~9 ~30 lava 0  
fill ~11 ~9 ~83 ~93 ~9 ~83 stone 0  
fill ~12 ~9 ~24 ~13 ~9 ~24 stone 0 
setblock ~12 ~9 ~25 lava 0  
fill ~12 ~9 ~84 ~92 ~9 ~84 stone 0  
fill ~13 ~9 ~22 ~14 ~9 ~22 stone 0  
fill ~13 ~9 ~23 ~17 ~9 ~23 stone 0  
fill ~13 ~9 ~25 ~18 ~9 ~25 stone 0  
fill ~13 ~9 ~27 ~14 ~9 ~27 lava 0  
fill ~13 ~9 ~30 ~96 ~9 ~30 stone 0  
fill ~13 ~9 ~85 ~91 ~9 ~85 stone 0  
fill ~13 ~9 ~86 ~91 ~9 ~86 stone 0 
setblock ~14 ~9 ~24 stone 5  
fill ~14 ~9 ~29 ~15 ~9 ~29 stone 0  
fill ~14 ~9 ~87 ~90 ~9 ~87 stone 0  
fill ~15 ~9 ~24 ~18 ~9 ~24 stone 0 
setblock ~15 ~9 ~27 stone 0  
fill ~15 ~9 ~88 ~89 ~9 ~88 stone 0  
fill ~16 ~9 ~26 ~16 ~9 ~27 lava 0 
setblock ~16 ~9 ~29 lava 0  
fill ~16 ~9 ~89 ~88 ~9 ~89 stone 0  
fill ~17 ~9 ~26 ~94 ~9 ~26 stone 0  
fill ~17 ~9 ~27 ~94 ~9 ~27 stone 0  
fill ~17 ~9 ~29 ~17 ~11 ~29 lava 10  
fill ~17 ~9 ~90 ~87 ~9 ~90 stone 0  
fill ~18 ~9 ~29 ~95 ~9 ~29 stone 0  
fill ~18 ~9 ~91 ~86 ~9 ~91 stone 0 
setblock ~19 ~9 ~25 stone 5  
fill ~19 ~9 ~92 ~85 ~9 ~92 stone 0  
fill ~20 ~9 ~16 ~21 ~9 ~16 stone 0  
fill ~20 ~9 ~17 ~21 ~9 ~17 stone 0  
fill ~20 ~9 ~25 ~93 ~9 ~25 stone 0  
fill ~20 ~9 ~93 ~84 ~9 ~93 stone 0  
fill ~22 ~9 ~94 ~82 ~9 ~94 stone 0  
fill ~23 ~9 ~13 ~26 ~9 ~13 stone 0  
fill ~23 ~9 ~22 ~24 ~9 ~22 stone_slab 3  
fill ~23 ~9 ~23 ~24 ~9 ~23 stone_slab 3  
fill ~23 ~9 ~24 ~92 ~9 ~24 stone 0  
fill ~23 ~9 ~95 ~81 ~9 ~95 stone 0 
setblock ~24 ~9 ~12 dirt 0  
fill ~24 ~9 ~96 ~80 ~9 ~96 stone 0  
fill ~25 ~9 ~23 ~91 ~9 ~23 stone 0 
setblock ~26 ~9 ~11 dirt 0  
fill ~26 ~9 ~12 ~27 ~9 ~12 stone 0  
fill ~26 ~9 ~20 ~27 ~9 ~20 reeds 0  
fill ~26 ~9 ~97 ~78 ~9 ~97 stone 0  
fill ~27 ~9 ~10 ~27 ~10 ~10 vine 1 
setblock ~27 ~9 ~11 stone 0  
fill ~27 ~9 ~22 ~91 ~9 ~22 stone 0  
fill ~28 ~9 ~11 ~28 ~10 ~11 vine 2  
fill ~28 ~9 ~21 ~90 ~9 ~21 stone 0  
fill ~28 ~9 ~98 ~76 ~9 ~98 stone 0  
fill ~30 ~9 ~99 ~74 ~9 ~99 stone 0  
fill ~32 ~9 ~20 ~89 ~9 ~20 stone 0  
fill ~32 ~9 ~100 ~72 ~9 ~100 stone 0  
fill ~34 ~9 ~19 ~88 ~9 ~19 stone 0  
fill ~34 ~9 ~101 ~70 ~9 ~101 stone 0  
fill ~36 ~9 ~18 ~87 ~9 ~18 stone 0  
fill ~37 ~9 ~17 ~86 ~9 ~17 stone 0  
fill ~37 ~9 ~102 ~67 ~9 ~102 stone 0  
fill ~38 ~9 ~16 ~85 ~9 ~16 stone 0  
fill ~39 ~9 ~15 ~84 ~9 ~15 stone 0  
fill ~40 ~9 ~103 ~64 ~9 ~103 stone 0  
fill ~41 ~9 ~14 ~82 ~9 ~14 stone 0  
fill ~43 ~9 ~13 ~81 ~9 ~13 stone 0 
setblock ~44 ~9 ~12 torch 4  
fill ~45 ~9 ~104 ~59 ~9 ~104 stone 0  
fill ~46 ~9 ~12 ~80 ~9 ~12 stone 0  
fill ~48 ~9 ~11 ~78 ~9 ~11 stone 0  
fill ~49 ~9 ~10 ~76 ~9 ~10 stone 0  
fill ~51 ~9 ~9 ~74 ~9 ~9 stone 0  
fill ~53 ~9 ~8 ~72 ~9 ~8 stone 0  
fill ~56 ~9 ~7 ~70 ~9 ~7 stone 0  
fill ~57 ~9 ~6 ~67 ~9 ~6 stone 0  
fill ~58 ~9 ~4 ~58 ~31 ~4 stone 0  
fill ~58 ~9 ~5 ~64 ~9 ~5 stone 0  
fill ~2 ~10 ~48 ~2 ~11 ~48 dirt 0  
fill ~2 ~10 ~49 ~2 ~11 ~49 dirt 0  
fill ~2 ~10 ~50 ~102 ~10 ~50 stone 0  
fill ~2 ~10 ~51 ~2 ~11 ~51 dirt 0  
fill ~2 ~10 ~53 ~102 ~10 ~53 stone 0  
fill ~2 ~10 ~54 ~2 ~11 ~54 dirt 0  
fill ~2 ~10 ~55 ~2 ~11 ~55 dirt 0  
fill ~2 ~10 ~56 ~2 ~11 ~56 dirt 0  
fill ~2 ~10 ~57 ~102 ~10 ~57 stone 0  
fill ~2 ~10 ~59 ~2 ~11 ~59 dirt 0  
fill ~2 ~10 ~60 ~2 ~11 ~60 dirt 0  
fill ~2 ~10 ~61 ~102 ~10 ~61 stone 0  
fill ~3 ~10 ~42 ~101 ~10 ~42 stone 0  
fill ~3 ~10 ~43 ~3 ~11 ~43 dirt 0  
fill ~3 ~10 ~44 ~3 ~11 ~44 dirt 0  
fill ~3 ~10 ~45 ~101 ~10 ~45 stone 0  
fill ~3 ~10 ~46 ~3 ~11 ~46 dirt 0  
fill ~3 ~10 ~47 ~102 ~10 ~47 stone 0  
fill ~3 ~10 ~48 ~102 ~10 ~48 stone 0  
fill ~3 ~10 ~49 ~102 ~10 ~49 stone 0  
fill ~3 ~10 ~51 ~102 ~10 ~51 stone 0  
fill ~3 ~10 ~52 ~102 ~10 ~52 stone 0  
fill ~3 ~10 ~54 ~102 ~10 ~54 stone 0  
fill ~3 ~10 ~55 ~102 ~10 ~55 stone 0  
fill ~3 ~10 ~56 ~102 ~10 ~56 stone 0  
fill ~3 ~10 ~58 ~102 ~10 ~58 stone 0  
fill ~3 ~10 ~59 ~102 ~10 ~59 stone 0  
fill ~3 ~10 ~60 ~102 ~10 ~60 stone 0  
fill ~3 ~10 ~62 ~3 ~11 ~62 dirt 0  
fill ~3 ~10 ~64 ~3 ~11 ~64 dirt 0  
fill ~3 ~10 ~65 ~101 ~10 ~65 stone 0  
fill ~3 ~10 ~66 ~3 ~11 ~66 dirt 0  
fill ~4 ~10 ~39 ~100 ~10 ~39 stone 0  
fill ~4 ~10 ~40 ~100 ~10 ~40 stone 0  
fill ~4 ~10 ~41 ~5 ~10 ~41 dirt 0  
fill ~4 ~10 ~43 ~101 ~10 ~43 stone 0  
fill ~4 ~10 ~44 ~101 ~10 ~44 stone 0  
fill ~4 ~10 ~46 ~101 ~10 ~46 stone 0  
fill ~4 ~10 ~62 ~101 ~10 ~62 stone 0  
fill ~4 ~10 ~63 ~101 ~10 ~63 stone 0  
fill ~4 ~10 ~64 ~101 ~10 ~64 stone 0  
fill ~4 ~10 ~66 ~101 ~10 ~66 stone 0  
fill ~4 ~10 ~67 ~100 ~10 ~67 stone 0  
fill ~4 ~10 ~68 ~100 ~10 ~68 stone 0  
fill ~4 ~10 ~69 ~100 ~10 ~69 stone 0  
fill ~5 ~10 ~36 ~6 ~10 ~36 stone 0  
fill ~5 ~10 ~37 ~5 ~0 ~37 stone 0  
fill ~5 ~10 ~38 ~6 ~10 ~38 stone 0  
fill ~5 ~10 ~70 ~99 ~10 ~70 stone 0  
fill ~5 ~10 ~71 ~99 ~10 ~71 stone 0  
fill ~5 ~10 ~72 ~99 ~10 ~72 stone 0  
fill ~6 ~10 ~34 ~6 ~0 ~34 stone 0  
fill ~6 ~10 ~35 ~7 ~10 ~35 stone 0  
fill ~6 ~10 ~37 ~8 ~10 ~37 lava 0  
fill ~6 ~10 ~41 ~100 ~10 ~41 stone 0  
fill ~6 ~10 ~73 ~98 ~10 ~73 stone 0  
fill ~6 ~10 ~74 ~98 ~10 ~74 stone 0  
fill ~7 ~10 ~32 ~7 ~0 ~32 stone 0  
fill ~7 ~10 ~33 ~13 ~10 ~33 stone 0  
fill ~7 ~10 ~34 ~9 ~10 ~34 stone 5 
setblock ~7 ~10 ~36 lava 0 
setblock ~7 ~10 ~38 lava 0  
fill ~7 ~10 ~75 ~97 ~10 ~75 stone 0  
fill ~7 ~10 ~76 ~97 ~10 ~76 stone 0  
fill ~8 ~10 ~31 ~8 ~0 ~31 stone 0 
setblock ~8 ~10 ~32 lava 0 
setblock ~8 ~10 ~35 stone 5  
fill ~8 ~10 ~36 ~99 ~10 ~36 stone 0  
fill ~8 ~10 ~38 ~99 ~10 ~38 stone 0  
fill ~8 ~10 ~77 ~96 ~10 ~77 stone 0  
fill ~8 ~10 ~78 ~96 ~10 ~78 stone 0  
fill ~9 ~10 ~32 ~10 ~10 ~32 stone 0 
setblock ~9 ~10 ~35 lava 0  
fill ~9 ~10 ~37 ~99 ~10 ~37 stone 0  
fill ~9 ~10 ~79 ~95 ~10 ~79 stone 0  
fill ~9 ~10 ~80 ~95 ~10 ~80 stone 0 
setblock ~10 ~10 ~34 lava 0  
fill ~10 ~10 ~35 ~98 ~10 ~35 stone 0  
fill ~10 ~10 ~81 ~94 ~10 ~81 stone 0  
fill ~10 ~10 ~82 ~94 ~10 ~82 stone 0  
fill ~11 ~10 ~28 ~11 ~11 ~28 stone 0  
fill ~11 ~10 ~32 ~12 ~10 ~32 stone 5  
fill ~11 ~10 ~34 ~98 ~10 ~34 stone 0  
fill ~11 ~10 ~83 ~93 ~10 ~83 stone 0  
fill ~12 ~10 ~84 ~92 ~10 ~84 stone 0  
fill ~13 ~10 ~25 ~13 ~0 ~25 stone 0  
fill ~13 ~10 ~31 ~96 ~10 ~31 stone 0  
fill ~13 ~10 ~32 ~14 ~10 ~32 lava 0  
fill ~13 ~10 ~85 ~91 ~10 ~85 stone 0  
fill ~13 ~10 ~86 ~91 ~10 ~86 stone 0  
fill ~14 ~10 ~30 ~96 ~10 ~30 stone 0 
setblock ~14 ~10 ~33 lava 0  
fill ~14 ~10 ~87 ~90 ~10 ~87 stone 0 
setblock ~15 ~10 ~24 stone_slab 3  
fill ~15 ~10 ~32 ~97 ~10 ~32 stone 0  
fill ~15 ~10 ~33 ~97 ~10 ~33 stone 0  
fill ~15 ~10 ~88 ~89 ~10 ~88 stone 0  
fill ~16 ~10 ~89 ~88 ~10 ~89 stone 0 
setblock ~17 ~10 ~24 light_weighted_pressure_plate 0  
fill ~17 ~10 ~90 ~87 ~10 ~90 stone 0  
fill ~18 ~10 ~28 ~95 ~10 ~28 stone 0  
fill ~18 ~10 ~29 ~95 ~10 ~29 stone 0  
fill ~18 ~10 ~91 ~86 ~10 ~91 stone 0  
fill ~19 ~10 ~27 ~94 ~10 ~27 stone 0  
fill ~19 ~10 ~92 ~85 ~10 ~92 stone 0  
fill ~20 ~10 ~16 ~21 ~10 ~16 stone_slab 3  
fill ~20 ~10 ~17 ~20 ~10 ~16 stone_slab 3  
fill ~20 ~10 ~26 ~94 ~10 ~26 stone 0  
fill ~20 ~10 ~93 ~84 ~10 ~93 stone 0 
setblock ~21 ~10 ~17 double_stone_slab 3  
fill ~21 ~10 ~25 ~93 ~10 ~25 stone 0  
fill ~22 ~10 ~94 ~82 ~10 ~94 stone 0  
fill ~23 ~10 ~13 ~26 ~10 ~13 grass 0  
fill ~23 ~10 ~95 ~81 ~10 ~95 stone 0  
fill ~24 ~10 ~12 ~27 ~10 ~12 grass 0 
setblock ~24 ~10 ~14 grass 0  
fill ~24 ~10 ~24 ~92 ~10 ~24 stone 0  
fill ~24 ~10 ~96 ~80 ~10 ~96 stone 0  
fill ~25 ~10 ~23 ~91 ~10 ~23 stone 0  
fill ~26 ~10 ~11 ~27 ~10 ~11 grass 0  
fill ~26 ~10 ~97 ~78 ~10 ~97 stone 0  
fill ~27 ~10 ~22 ~91 ~10 ~22 stone 0  
fill ~28 ~10 ~98 ~76 ~10 ~98 stone 0  
fill ~30 ~10 ~21 ~90 ~10 ~21 stone 0  
fill ~30 ~10 ~99 ~74 ~10 ~99 stone 0  
fill ~32 ~10 ~100 ~72 ~10 ~100 stone 0  
fill ~33 ~10 ~20 ~89 ~10 ~20 stone 0  
fill ~34 ~10 ~19 ~88 ~10 ~19 stone 0  
fill ~34 ~10 ~101 ~70 ~10 ~101 stone 0  
fill ~36 ~10 ~18 ~87 ~10 ~18 stone 0  
fill ~37 ~10 ~17 ~86 ~10 ~17 stone 0  
fill ~37 ~10 ~102 ~67 ~10 ~102 stone 0  
fill ~38 ~10 ~16 ~85 ~10 ~16 stone 0  
fill ~39 ~10 ~15 ~84 ~10 ~15 stone 0  
fill ~40 ~10 ~103 ~64 ~10 ~103 stone 0  
fill ~41 ~10 ~14 ~82 ~10 ~14 stone 0  
fill ~43 ~10 ~13 ~81 ~10 ~13 stone 0  
fill ~45 ~10 ~104 ~59 ~10 ~104 stone 0  
fill ~46 ~10 ~12 ~80 ~10 ~12 stone 0  
fill ~47 ~10 ~11 ~78 ~10 ~11 stone 0  
fill ~49 ~10 ~10 ~76 ~10 ~10 stone 0  
fill ~50 ~10 ~9 ~74 ~10 ~9 stone 0  
fill ~52 ~10 ~8 ~72 ~10 ~8 stone 0  
fill ~53 ~10 ~7 ~70 ~10 ~7 stone 0  
fill ~56 ~10 ~5 ~64 ~10 ~5 stone 0  
fill ~56 ~10 ~6 ~67 ~10 ~6 stone 0  
fill ~57 ~10 ~4 ~57 ~31 ~4 stone 0 
setblock ~2 ~11 ~50 dirt 0 
setblock ~2 ~11 ~53 dirt 0 
setblock ~2 ~11 ~57 dirt 0 
setblock ~2 ~11 ~61 dirt 0  
fill ~3 ~11 ~42 ~3 ~12 ~42 dirt 0 
setblock ~3 ~11 ~45 dirt 0  
fill ~3 ~11 ~47 ~102 ~11 ~47 stone 0  
fill ~3 ~11 ~48 ~102 ~11 ~48 stone 0  
fill ~3 ~11 ~49 ~102 ~11 ~49 stone 0  
fill ~3 ~11 ~50 ~102 ~11 ~50 stone 0  
fill ~3 ~11 ~51 ~102 ~11 ~51 stone 0  
fill ~3 ~11 ~52 ~102 ~11 ~52 stone 0  
fill ~3 ~11 ~53 ~102 ~11 ~53 stone 0  
fill ~3 ~11 ~54 ~102 ~11 ~54 stone 0  
fill ~3 ~11 ~55 ~102 ~11 ~55 stone 0  
fill ~3 ~11 ~56 ~102 ~11 ~56 stone 0  
fill ~3 ~11 ~57 ~102 ~11 ~57 stone 0  
fill ~3 ~11 ~58 ~102 ~11 ~58 stone 0  
fill ~3 ~11 ~59 ~102 ~11 ~59 stone 0  
fill ~3 ~11 ~60 ~102 ~11 ~60 stone 0  
fill ~3 ~11 ~61 ~102 ~11 ~61 stone 0 
setblock ~3 ~11 ~65 dirt 0  
fill ~4 ~11 ~39 ~6 ~11 ~39 stone 0  
fill ~4 ~11 ~40 ~6 ~11 ~40 stone 0  
fill ~4 ~11 ~41 ~4 ~12 ~41 dirt 0  
fill ~4 ~11 ~42 ~101 ~11 ~42 stone 0  
fill ~4 ~11 ~43 ~101 ~11 ~43 stone 0  
fill ~4 ~11 ~44 ~101 ~11 ~44 stone 0  
fill ~4 ~11 ~45 ~101 ~11 ~45 stone 0  
fill ~4 ~11 ~46 ~101 ~11 ~46 stone 0  
fill ~4 ~11 ~62 ~101 ~11 ~62 stone 0  
fill ~4 ~11 ~63 ~101 ~11 ~63 stone 0  
fill ~4 ~11 ~64 ~101 ~11 ~64 stone 0  
fill ~4 ~11 ~65 ~101 ~11 ~65 stone 0  
fill ~4 ~11 ~66 ~101 ~11 ~66 stone 0 
setblock ~4 ~11 ~67 dirt 0  
fill ~4 ~11 ~68 ~100 ~11 ~68 stone 0  
fill ~4 ~11 ~69 ~100 ~11 ~69 stone 0  
fill ~5 ~11 ~41 ~100 ~11 ~41 stone 0  
fill ~5 ~11 ~67 ~100 ~11 ~67 stone 0  
fill ~5 ~11 ~70 ~99 ~11 ~70 stone 0  
fill ~5 ~11 ~71 ~99 ~11 ~71 stone 0  
fill ~5 ~11 ~72 ~99 ~11 ~72 stone 0  
fill ~6 ~11 ~73 ~98 ~11 ~73 stone 0  
fill ~6 ~11 ~74 ~98 ~11 ~74 stone 0  
fill ~7 ~11 ~34 ~7 ~12 ~34 stone 0 
setblock ~7 ~11 ~38 lava 2  
fill ~7 ~11 ~39 ~7 ~11 ~40 stone 5  
fill ~7 ~11 ~75 ~97 ~11 ~75 stone 0  
fill ~7 ~11 ~76 ~97 ~11 ~76 stone 0 
setblock ~8 ~11 ~37 lava 2 
setblock ~8 ~11 ~38 lava 0  
fill ~8 ~11 ~39 ~9 ~11 ~39 stone 0 
setblock ~8 ~11 ~40 stone 5  
fill ~8 ~11 ~77 ~96 ~11 ~77 stone 0  
fill ~8 ~11 ~78 ~96 ~11 ~78 stone 0  
fill ~9 ~11 ~38 ~9 ~13 ~38 stone 0  
fill ~9 ~11 ~40 ~100 ~11 ~40 stone 0  
fill ~9 ~11 ~79 ~95 ~11 ~79 stone 0  
fill ~9 ~11 ~80 ~95 ~11 ~80 stone 0 
setblock ~10 ~11 ~37 stone 0  
fill ~10 ~11 ~38 ~11 ~11 ~38 lava 0  
fill ~10 ~11 ~39 ~10 ~11 ~38 lava 0  
fill ~10 ~11 ~81 ~94 ~11 ~81 stone 0  
fill ~10 ~11 ~82 ~94 ~11 ~82 stone 0 
setblock ~11 ~11 ~32 stone 0 
setblock ~11 ~11 ~36 stone 0  
fill ~11 ~11 ~37 ~12 ~11 ~37 stone 5  
fill ~11 ~11 ~39 ~100 ~11 ~39 stone 0  
fill ~11 ~11 ~83 ~93 ~11 ~83 stone 0  
fill ~12 ~11 ~34 ~13 ~11 ~34 stone 0  
fill ~12 ~11 ~35 ~13 ~11 ~35 stone 0 
setblock ~12 ~11 ~36 stone 5  
fill ~12 ~11 ~38 ~99 ~11 ~38 stone 0  
fill ~12 ~11 ~84 ~92 ~11 ~84 stone 0 
setblock ~13 ~11 ~25 stone_slab 3  
fill ~13 ~11 ~36 ~99 ~11 ~36 stone 0  
fill ~13 ~11 ~37 ~99 ~11 ~37 stone 0  
fill ~13 ~11 ~85 ~91 ~11 ~85 stone 0  
fill ~13 ~11 ~86 ~91 ~11 ~86 stone 0  
fill ~14 ~11 ~30 ~14 ~12 ~30 stone 0 
setblock ~14 ~11 ~33 lava 4 
setblock ~14 ~11 ~34 lava 2 
setblock ~14 ~11 ~35 lava 0 
setblock ~14 ~11 ~87 end_stone 0  
fill ~15 ~11 ~32 ~97 ~11 ~32 stone 0  
fill ~15 ~11 ~33 ~97 ~11 ~33 stone 0  
fill ~15 ~11 ~34 ~98 ~11 ~34 stone 0  
fill ~15 ~11 ~35 ~98 ~11 ~35 stone 0  
fill ~15 ~11 ~87 ~90 ~11 ~87 stone 0  
fill ~15 ~11 ~88 ~89 ~11 ~88 stone 0  
fill ~16 ~11 ~31 ~96 ~11 ~31 stone 0  
fill ~16 ~11 ~89 ~88 ~11 ~89 stone 0  
fill ~17 ~11 ~30 ~96 ~11 ~30 stone 0  
fill ~17 ~11 ~90 ~17 ~14 ~90 end_stone 0  
fill ~18 ~11 ~28 ~95 ~11 ~28 stone 0  
fill ~18 ~11 ~29 ~95 ~11 ~29 stone 0  
fill ~18 ~11 ~90 ~87 ~11 ~90 stone 0  
fill ~18 ~11 ~91 ~86 ~11 ~91 stone 0  
fill ~19 ~11 ~27 ~94 ~11 ~27 stone 0  
fill ~19 ~11 ~92 ~85 ~11 ~92 stone 0  
fill ~20 ~11 ~26 ~94 ~11 ~26 stone 0  
fill ~20 ~11 ~93 ~20 ~14 ~93 end_stone 0  
fill ~21 ~11 ~25 ~93 ~11 ~25 stone 0  
fill ~21 ~11 ~93 ~84 ~11 ~93 stone 0  
fill ~22 ~11 ~94 ~82 ~11 ~94 stone 0 
setblock ~23 ~11 ~13 tallgrass 0  
fill ~23 ~11 ~95 ~81 ~11 ~95 stone 0 
setblock ~24 ~11 ~12 tallgrass 0 
setblock ~24 ~11 ~14 tallgrass 0  
fill ~24 ~11 ~24 ~92 ~11 ~24 stone 0  
fill ~24 ~11 ~96 ~80 ~11 ~96 stone 0 
setblock ~25 ~11 ~13 tallgrass 0  
fill ~26 ~11 ~11 ~26 ~11 ~12 tallgrass 0  
fill ~26 ~11 ~23 ~91 ~11 ~23 stone 0  
fill ~26 ~11 ~97 ~78 ~11 ~97 stone 0 
setblock ~27 ~11 ~12 red_flower 8  
fill ~27 ~11 ~22 ~91 ~11 ~22 stone 0  
fill ~28 ~11 ~98 ~76 ~11 ~98 stone 0  
fill ~30 ~11 ~99 ~74 ~11 ~99 stone 0  
fill ~31 ~11 ~21 ~90 ~11 ~21 stone 0  
fill ~32 ~11 ~100 ~72 ~11 ~100 stone 0  
fill ~33 ~11 ~20 ~89 ~11 ~20 stone 0  
fill ~34 ~11 ~101 ~70 ~11 ~101 stone 0 
setblock ~35 ~11 ~18 torch 4  
fill ~35 ~11 ~19 ~88 ~11 ~19 stone 0  
fill ~36 ~11 ~18 ~87 ~11 ~18 stone 0  
fill ~37 ~11 ~17 ~86 ~11 ~17 stone 0  
fill ~37 ~11 ~102 ~67 ~11 ~102 stone 0  
fill ~38 ~11 ~16 ~85 ~11 ~16 stone 0  
fill ~39 ~11 ~15 ~84 ~11 ~15 stone 0  
fill ~40 ~11 ~103 ~64 ~11 ~103 stone 0  
fill ~41 ~11 ~14 ~82 ~11 ~14 stone 0  
fill ~42 ~11 ~13 ~81 ~11 ~13 stone 0  
fill ~45 ~11 ~104 ~59 ~11 ~104 stone 0  
fill ~46 ~11 ~11 ~78 ~11 ~11 stone 0  
fill ~46 ~11 ~12 ~80 ~11 ~12 stone 0  
fill ~48 ~11 ~10 ~76 ~11 ~10 stone 0  
fill ~50 ~11 ~7 ~70 ~11 ~7 stone 0  
fill ~50 ~11 ~8 ~72 ~11 ~8 stone 0  
fill ~50 ~11 ~9 ~74 ~11 ~9 stone 0  
fill ~51 ~11 ~4 ~59 ~11 ~4 stone 0  
fill ~51 ~11 ~5 ~64 ~11 ~5 stone 0  
fill ~51 ~11 ~6 ~67 ~11 ~6 stone 0  
fill ~2 ~12 ~47 ~3 ~12 ~47 grass 0  
fill ~2 ~12 ~48 ~2 ~12 ~61 grass 0  
fill ~3 ~12 ~43 ~14 ~12 ~43 grass 0  
fill ~3 ~12 ~44 ~14 ~12 ~44 grass 0  
fill ~3 ~12 ~45 ~14 ~12 ~45 grass 0  
fill ~3 ~12 ~46 ~4 ~12 ~46 grass 0  
fill ~3 ~12 ~48 ~4 ~12 ~48 water 0  
fill ~3 ~12 ~49 ~3 ~12 ~52 water 0  
fill ~3 ~12 ~53 ~3 ~12 ~66 grass 0  
fill ~4 ~12 ~40 ~4 ~0 ~40 stone 0  
fill ~4 ~12 ~42 ~5 ~12 ~42 grass 0  
fill ~4 ~12 ~47 ~6 ~12 ~47 water 0  
fill ~4 ~12 ~49 ~14 ~12 ~49 grass 0  
fill ~4 ~12 ~50 ~5 ~12 ~50 grass 0  
fill ~4 ~12 ~51 ~4 ~12 ~54 water 0  
fill ~4 ~12 ~55 ~5 ~12 ~55 grass 0  
fill ~4 ~12 ~56 ~5 ~12 ~56 grass 0  
fill ~4 ~12 ~57 ~6 ~12 ~57 grass 0 
setblock ~4 ~12 ~58 dirt 0  
fill ~4 ~12 ~59 ~6 ~12 ~59 grass 0  
fill ~4 ~12 ~60 ~11 ~12 ~60 grass 0  
fill ~4 ~12 ~61 ~11 ~12 ~61 grass 0  
fill ~4 ~12 ~62 ~11 ~12 ~62 grass 0  
fill ~4 ~12 ~63 ~14 ~12 ~63 grass 0  
fill ~4 ~12 ~64 ~14 ~12 ~64 grass 0  
fill ~4 ~12 ~65 ~14 ~12 ~65 grass 0  
fill ~4 ~12 ~66 ~14 ~12 ~66 grass 0  
fill ~4 ~12 ~67 ~14 ~12 ~67 grass 0  
fill ~4 ~12 ~68 ~100 ~12 ~68 stone 0  
fill ~4 ~12 ~69 ~100 ~12 ~69 stone 0  
fill ~5 ~12 ~41 ~5 ~11 ~41 stone 0  
fill ~5 ~12 ~46 ~7 ~12 ~46 water 0  
fill ~5 ~12 ~48 ~14 ~12 ~48 grass 0  
fill ~5 ~12 ~51 ~14 ~12 ~51 grass 0  
fill ~5 ~12 ~52 ~14 ~12 ~52 grass 0  
fill ~5 ~12 ~53 ~5 ~12 ~54 water 0  
fill ~5 ~12 ~58 ~6 ~12 ~58 grass 0  
fill ~5 ~12 ~70 ~99 ~12 ~70 stone 0  
fill ~5 ~12 ~71 ~99 ~12 ~71 stone 0  
fill ~5 ~12 ~72 ~99 ~12 ~72 stone 0  
fill ~6 ~12 ~42 ~10 ~12 ~42 stone 0 
setblock ~6 ~12 ~50 dirt 0  
fill ~6 ~12 ~53 ~14 ~12 ~53 grass 0  
fill ~6 ~12 ~54 ~6 ~12 ~56 water 0  
fill ~6 ~12 ~73 ~98 ~12 ~73 stone 0  
fill ~6 ~12 ~74 ~98 ~12 ~74 stone 0  
fill ~7 ~12 ~47 ~14 ~12 ~47 grass 0  
fill ~7 ~12 ~50 ~14 ~12 ~50 grass 0  
fill ~7 ~12 ~54 ~14 ~12 ~54 grass 0  
fill ~7 ~12 ~55 ~7 ~12 ~59 water 0  
fill ~7 ~12 ~75 ~97 ~12 ~75 stone 0  
fill ~7 ~12 ~76 ~97 ~12 ~76 stone 0  
fill ~8 ~12 ~46 ~14 ~12 ~46 grass 0  
fill ~8 ~12 ~55 ~14 ~12 ~55 grass 0  
fill ~8 ~12 ~56 ~14 ~12 ~56 grass 0  
fill ~8 ~12 ~57 ~14 ~12 ~57 grass 0  
fill ~8 ~12 ~58 ~14 ~12 ~58 grass 0  
fill ~8 ~12 ~59 ~8 ~13 ~59 water 9  
fill ~8 ~12 ~77 ~96 ~12 ~77 stone 0  
fill ~8 ~12 ~78 ~8 ~15 ~78 end_stone 0  
fill ~9 ~12 ~59 ~14 ~12 ~59 grass 0  
fill ~9 ~12 ~78 ~96 ~12 ~78 stone 0  
fill ~9 ~12 ~79 ~95 ~12 ~79 stone 0  
fill ~9 ~12 ~80 ~95 ~12 ~80 stone 0  
fill ~10 ~12 ~81 ~10 ~14 ~81 end_stone 0  
fill ~10 ~12 ~82 ~94 ~12 ~82 stone 0 
setblock ~11 ~12 ~28 stone_slab 3 
setblock ~11 ~12 ~32 stone 5 
setblock ~11 ~12 ~41 stone 0  
fill ~11 ~12 ~42 ~14 ~12 ~42 grass 0  
fill ~11 ~12 ~81 ~94 ~12 ~81 stone 0  
fill ~11 ~12 ~83 ~11 ~14 ~83 end_stone 0  
fill ~12 ~12 ~39 ~12 ~12 ~40 stone 0  
fill ~12 ~12 ~41 ~14 ~12 ~41 grass 0  
fill ~12 ~12 ~60 ~102 ~12 ~60 stone 0  
fill ~12 ~12 ~61 ~102 ~12 ~61 stone 0  
fill ~12 ~12 ~62 ~101 ~12 ~62 stone 0  
fill ~12 ~12 ~83 ~93 ~12 ~83 stone 0  
fill ~12 ~12 ~84 ~92 ~12 ~84 stone 0 
setblock ~13 ~12 ~38 stone 0  
fill ~13 ~12 ~39 ~14 ~12 ~39 grass 0  
fill ~13 ~12 ~40 ~14 ~12 ~40 grass 0  
fill ~13 ~12 ~85 ~13 ~14 ~85 end_stone 0  
fill ~13 ~12 ~86 ~13 ~14 ~86 end_stone 0  
fill ~14 ~12 ~37 ~99 ~12 ~37 stone 0  
fill ~14 ~12 ~38 ~14 ~13 ~38 grass 0  
fill ~14 ~12 ~85 ~91 ~12 ~85 stone 0  
fill ~14 ~12 ~86 ~91 ~12 ~86 stone 0 
setblock ~14 ~12 ~87 end_bricks 0  
fill ~15 ~12 ~36 ~99 ~12 ~36 stone 0  
fill ~15 ~12 ~38 ~99 ~12 ~38 stone 0  
fill ~15 ~12 ~39 ~100 ~12 ~39 stone 0  
fill ~15 ~12 ~40 ~100 ~12 ~40 stone 0  
fill ~15 ~12 ~41 ~100 ~12 ~41 stone 0  
fill ~15 ~12 ~42 ~101 ~12 ~42 stone 0  
fill ~15 ~12 ~43 ~101 ~12 ~43 stone 0  
fill ~15 ~12 ~44 ~101 ~12 ~44 stone 0  
fill ~15 ~12 ~45 ~101 ~12 ~45 stone 0  
fill ~15 ~12 ~46 ~101 ~12 ~46 stone 0  
fill ~15 ~12 ~47 ~102 ~12 ~47 stone 0  
fill ~15 ~12 ~48 ~102 ~12 ~48 stone 0  
fill ~15 ~12 ~49 ~102 ~12 ~49 stone 0  
fill ~15 ~12 ~50 ~102 ~12 ~50 stone 0  
fill ~15 ~12 ~51 ~102 ~12 ~51 stone 0  
fill ~15 ~12 ~52 ~102 ~12 ~52 stone 0  
fill ~15 ~12 ~53 ~102 ~12 ~53 stone 0  
fill ~15 ~12 ~54 ~102 ~12 ~54 stone 0  
fill ~15 ~12 ~55 ~102 ~12 ~55 stone 0  
fill ~15 ~12 ~56 ~102 ~12 ~56 stone 0  
fill ~15 ~12 ~57 ~102 ~12 ~57 stone 0  
fill ~15 ~12 ~58 ~102 ~12 ~58 stone 0  
fill ~15 ~12 ~59 ~102 ~12 ~59 stone 0  
fill ~15 ~12 ~63 ~101 ~12 ~63 stone 0  
fill ~15 ~12 ~64 ~101 ~12 ~64 stone 0  
fill ~15 ~12 ~65 ~101 ~12 ~65 stone 0  
fill ~15 ~12 ~66 ~101 ~12 ~66 stone 0  
fill ~15 ~12 ~67 ~100 ~12 ~67 stone 0  
fill ~15 ~12 ~87 ~90 ~12 ~87 stone 0  
fill ~15 ~12 ~88 ~89 ~12 ~88 stone 0  
fill ~16 ~12 ~34 ~98 ~12 ~34 stone 0  
fill ~16 ~12 ~35 ~98 ~12 ~35 stone 0  
fill ~16 ~12 ~89 ~16 ~14 ~89 end_stone 0 
setblock ~17 ~12 ~29 lava 2  
fill ~17 ~12 ~31 ~96 ~12 ~31 stone 0  
fill ~17 ~12 ~32 ~97 ~12 ~32 stone 0  
fill ~17 ~12 ~33 ~97 ~12 ~33 stone 0  
fill ~17 ~12 ~89 ~88 ~12 ~89 stone 0  
fill ~18 ~12 ~28 ~95 ~12 ~28 stone 0 
setblock ~18 ~12 ~29 lava 0  
fill ~18 ~12 ~30 ~96 ~12 ~30 stone 0  
fill ~18 ~12 ~90 ~87 ~12 ~90 stone 0 
fill ~18 ~12 ~91 ~18 ~14 ~91 end_stone 0 
setblock ~19 ~12 ~26 torch 2  
fill ~19 ~12 ~27 ~94 ~12 ~27 stone 0  
fill ~19 ~12 ~29 ~95 ~12 ~29 stone 0  
fill ~19 ~12 ~91 ~86 ~12 ~91 stone 0 
setblock ~19 ~12 ~92 end_stone 0  
fill ~20 ~12 ~26 ~94 ~12 ~26 stone 0  
fill ~20 ~12 ~92 ~85 ~12 ~92 stone 0  
fill ~21 ~12 ~93 ~21 ~14 ~93 end_stone 0  
fill ~22 ~12 ~25 ~93 ~12 ~25 stone 0  
fill ~22 ~12 ~93 ~84 ~12 ~93 stone 0  
fill ~22 ~12 ~94 ~82 ~12 ~94 stone 0  
fill ~23 ~12 ~95 ~23 ~15 ~95 end_stone 0  
fill ~24 ~12 ~24 ~92 ~12 ~24 stone 0  
fill ~24 ~12 ~95 ~81 ~12 ~95 stone 0  
fill ~24 ~12 ~96 ~80 ~12 ~96 stone 0  
fill ~26 ~12 ~23 ~91 ~12 ~23 stone 0  
fill ~26 ~12 ~97 ~78 ~12 ~97 stone 0  
fill ~27 ~12 ~22 ~91 ~12 ~22 stone 0  
fill ~28 ~12 ~98 ~76 ~12 ~98 stone 0  
fill ~30 ~12 ~99 ~74 ~12 ~99 stone 0  
fill ~31 ~12 ~21 ~90 ~12 ~21 stone 0  
fill ~32 ~12 ~100 ~72 ~12 ~100 stone 0  
fill ~33 ~12 ~20 ~89 ~12 ~20 stone 0  
fill ~34 ~12 ~101 ~70 ~12 ~101 stone 0  
fill ~35 ~12 ~19 ~88 ~12 ~19 stone 0  
fill ~36 ~12 ~18 ~87 ~12 ~18 stone 0  
fill ~37 ~12 ~17 ~86 ~12 ~17 stone 0  
fill ~37 ~12 ~102 ~67 ~12 ~102 stone 0  
fill ~38 ~12 ~16 ~85 ~12 ~16 stone 0  
fill ~39 ~12 ~15 ~84 ~12 ~15 stone 0  
fill ~40 ~12 ~14 ~82 ~12 ~14 stone 0  
fill ~40 ~12 ~103 ~64 ~12 ~103 stone 0  
fill ~42 ~12 ~13 ~81 ~12 ~13 stone 0  
fill ~43 ~12 ~12 ~80 ~12 ~12 stone 0  
fill ~45 ~12 ~104 ~59 ~12 ~104 stone 0  
fill ~46 ~12 ~10 ~76 ~12 ~10 stone 0  
fill ~46 ~12 ~11 ~78 ~12 ~11 stone 0  
fill ~48 ~12 ~9 ~74 ~12 ~9 stone 0  
fill ~49 ~12 ~4 ~59 ~12 ~4 stone 0  
fill ~49 ~12 ~8 ~72 ~12 ~8 stone 0  
fill ~50 ~12 ~5 ~64 ~12 ~5 stone 0  
fill ~50 ~12 ~6 ~67 ~12 ~6 stone 0  
fill ~50 ~12 ~7 ~70 ~12 ~7 stone 0  
fill ~2 ~13 ~47 ~2 ~13 ~49 tallgrass 0 
setblock ~2 ~13 ~50 red_flower 3 
setblock ~2 ~13 ~51 tallgrass 0  
fill ~2 ~13 ~54 ~3 ~13 ~54 tallgrass 0  
fill ~2 ~13 ~55 ~5 ~13 ~55 tallgrass 0  
fill ~2 ~13 ~56 ~5 ~13 ~56 tallgrass 0  
fill ~2 ~13 ~59 ~2 ~13 ~60 tallgrass 0 
setblock ~2 ~13 ~61 red_flower 3 
setblock ~3 ~13 ~42 grass 0 
setblock ~3 ~13 ~46 tallgrass 0 
setblock ~3 ~13 ~57 red_flower 3  
fill ~3 ~13 ~60 ~5 ~13 ~60 tallgrass 0  
fill ~3 ~13 ~61 ~5 ~13 ~61 tallgrass 0  
fill ~3 ~13 ~62 ~5 ~13 ~62 tallgrass 0  
fill ~3 ~13 ~64 ~3 ~13 ~66 tallgrass 0  
fill ~4 ~13 ~40 ~4 ~13 ~41 grass 0  
fill ~4 ~13 ~42 ~4 ~18 ~42 log 0 
setblock ~4 ~13 ~43 yellow_flower 0  
fill ~4 ~13 ~44 ~6 ~13 ~44 tallgrass 0  
fill ~4 ~13 ~45 ~7 ~13 ~45 tallgrass 0 
setblock ~4 ~13 ~57 tallgrass 0  
fill ~4 ~13 ~58 ~4 ~16 ~58 log 0 
setblock ~4 ~13 ~59 tallgrass 0  
fill ~4 ~13 ~63 ~6 ~13 ~63 tallgrass 0 
setblock ~4 ~13 ~65 tallgrass 0 
setblock ~4 ~13 ~67 tallgrass 0  
fill ~4 ~13 ~68 ~100 ~13 ~68 stone 0  
fill ~4 ~13 ~69 ~100 ~13 ~69 stone 0  
fill ~5 ~13 ~41 ~5 ~13 ~43 grass 0 
setblock ~5 ~13 ~50 tallgrass 0 
setblock ~5 ~13 ~58 tallgrass 0 
setblock ~5 ~13 ~59 red_flower 8 
setblock ~5 ~13 ~64 tallgrass 0 
setblock ~5 ~13 ~66 tallgrass 0  
fill ~5 ~13 ~67 ~6 ~13 ~67 stone 0  
fill ~5 ~13 ~70 ~5 ~15 ~70 end_stone 0  
fill ~5 ~13 ~71 ~99 ~13 ~71 stone 0  
fill ~5 ~13 ~72 ~99 ~13 ~72 stone 0  
fill ~6 ~13 ~42 ~14 ~13 ~42 grass 0  
fill ~6 ~13 ~43 ~14 ~13 ~43 grass 0  
fill ~6 ~13 ~50 ~6 ~16 ~50 log 0 
setblock ~6 ~13 ~59 tallgrass 0  
fill ~6 ~13 ~64 ~6 ~15 ~64 stone 0  
fill ~6 ~13 ~65 ~6 ~15 ~65 stone 0  
fill ~6 ~13 ~66 ~7 ~13 ~66 stone 0  
fill ~6 ~13 ~70 ~99 ~13 ~70 stone 0  
fill ~6 ~13 ~73 ~6 ~15 ~73 end_stone 0  
fill ~6 ~13 ~74 ~98 ~13 ~74 stone 0 
setblock ~7 ~13 ~34 stone 5  
fill ~7 ~13 ~44 ~14 ~13 ~44 grass 0  
fill ~7 ~13 ~48 ~11 ~13 ~48 tallgrass 0  
fill ~7 ~13 ~51 ~7 ~13 ~54 tallgrass 0  
fill ~7 ~13 ~63 ~7 ~15 ~63 stone 0  
fill ~7 ~13 ~64 ~14 ~13 ~64 grass 0  
fill ~7 ~13 ~65 ~14 ~13 ~65 grass 0  
fill ~7 ~13 ~67 ~14 ~13 ~67 grass 0  
fill ~7 ~13 ~73 ~98 ~13 ~73 stone 0  
fill ~7 ~13 ~75 ~7 ~15 ~75 end_stone 0 
setblock ~7 ~13 ~76 end_bricks 0  
fill ~8 ~13 ~47 ~10 ~13 ~47 tallgrass 0  
fill ~8 ~13 ~49 ~10 ~13 ~49 tallgrass 0  
fill ~8 ~13 ~50 ~11 ~13 ~50 tallgrass 0  
fill ~8 ~13 ~52 ~9 ~13 ~52 tallgrass 0  
fill ~8 ~13 ~53 ~9 ~13 ~53 tallgrass 0  
fill ~8 ~13 ~54 ~8 ~13 ~55 tallgrass 0  
fill ~8 ~13 ~61 ~8 ~15 ~61 stone 0  
fill ~8 ~13 ~62 ~8 ~16 ~62 stone 0  
fill ~8 ~13 ~63 ~14 ~13 ~63 grass 0  
fill ~8 ~13 ~66 ~14 ~13 ~66 grass 0  
fill ~8 ~13 ~75 ~97 ~13 ~75 stone 0  
fill ~8 ~13 ~76 ~97 ~13 ~76 stone 0  
fill ~8 ~13 ~77 ~96 ~13 ~77 stone 0 
setblock ~9 ~13 ~46 tallgrass 0  
fill ~9 ~13 ~51 ~10 ~13 ~51 tallgrass 0  
fill ~9 ~13 ~54 ~9 ~16 ~54 stone 0  
fill ~9 ~13 ~55 ~9 ~77 ~55 stone 0  
fill ~9 ~13 ~56 ~9 ~77 ~56 stone 0  
fill ~9 ~13 ~57 ~9 ~75 ~57 stone 0  
fill ~9 ~13 ~58 ~9 ~77 ~58 stone 0  
fill ~9 ~13 ~59 ~9 ~13 ~60 stone 0  
fill ~9 ~13 ~61 ~11 ~13 ~61 grass 0  
fill ~9 ~13 ~62 ~11 ~13 ~62 grass 0  
fill ~9 ~13 ~78 ~96 ~13 ~78 stone 0  
fill ~9 ~13 ~79 ~9 ~15 ~79 end_stone 0  
fill ~9 ~13 ~80 ~9 ~14 ~80 end_stone 0  
fill ~10 ~13 ~45 ~14 ~13 ~45 grass 0  
fill ~10 ~13 ~46 ~14 ~13 ~46 grass 0  
fill ~10 ~13 ~53 ~10 ~15 ~53 stone 0  
fill ~10 ~13 ~54 ~14 ~13 ~54 grass 0  
fill ~10 ~13 ~55 ~14 ~13 ~55 grass 0  
fill ~10 ~13 ~56 ~14 ~13 ~56 grass 0  
fill ~10 ~13 ~57 ~14 ~13 ~57 grass 0  
fill ~10 ~13 ~58 ~14 ~13 ~58 grass 0  
fill ~10 ~13 ~59 ~14 ~13 ~59 grass 0  
fill ~10 ~13 ~60 ~11 ~13 ~60 grass 0  
fill ~10 ~13 ~79 ~95 ~13 ~79 stone 0  
fill ~10 ~13 ~80 ~95 ~13 ~80 stone 0 
setblock ~10 ~13 ~82 end_stone 0 
setblock ~11 ~13 ~32 stone 0  
fill ~11 ~13 ~41 ~14 ~13 ~41 grass 0  
fill ~11 ~13 ~47 ~14 ~13 ~47 grass 0  
fill ~11 ~13 ~51 ~11 ~15 ~51 stone 0  
fill ~11 ~13 ~52 ~11 ~17 ~52 stone 0  
fill ~11 ~13 ~53 ~14 ~13 ~53 grass 0  
fill ~11 ~13 ~81 ~94 ~13 ~81 stone 0  
fill ~11 ~13 ~82 ~94 ~13 ~82 stone 0  
fill ~12 ~13 ~39 ~14 ~13 ~39 grass 0  
fill ~12 ~13 ~40 ~14 ~13 ~40 grass 0  
fill ~12 ~13 ~48 ~14 ~13 ~48 grass 0  
fill ~12 ~13 ~49 ~12 ~38 ~49 stone 0  
fill ~12 ~13 ~50 ~12 ~38 ~50 stone 0  
fill ~12 ~13 ~51 ~14 ~13 ~51 grass 0  
fill ~12 ~13 ~52 ~14 ~13 ~52 grass 0  
fill ~12 ~13 ~60 ~102 ~13 ~60 stone 0  
fill ~12 ~13 ~61 ~102 ~13 ~61 stone 0  
fill ~12 ~13 ~62 ~101 ~13 ~62 stone 0  
fill ~12 ~13 ~83 ~93 ~13 ~83 stone 0  
fill ~12 ~13 ~84 ~12 ~14 ~84 end_stone 0 
setblock ~13 ~13 ~38 grass 0  
fill ~13 ~13 ~49 ~14 ~13 ~49 grass 0  
fill ~13 ~13 ~50 ~14 ~13 ~50 grass 0  
fill ~13 ~13 ~84 ~92 ~13 ~84 stone 0 
setblock ~14 ~13 ~30 stone_slab 3 
setblock ~14 ~13 ~37 grass 0  
fill ~14 ~13 ~85 ~91 ~13 ~85 stone 0  
fill ~14 ~13 ~86 ~91 ~13 ~86 stone 0  
fill ~14 ~13 ~87 ~14 ~14 ~87 end_stone 0  
fill ~15 ~13 ~36 ~99 ~13 ~36 stone 0  
fill ~15 ~13 ~37 ~99 ~13 ~37 stone 0  
fill ~15 ~13 ~38 ~99 ~13 ~38 stone 0  
fill ~15 ~13 ~39 ~100 ~13 ~39 stone 0  
fill ~15 ~13 ~40 ~100 ~13 ~40 stone 0  
fill ~15 ~13 ~41 ~100 ~13 ~41 stone 0  
fill ~15 ~13 ~42 ~101 ~13 ~42 stone 0  
fill ~15 ~13 ~43 ~101 ~13 ~43 stone 0  
fill ~15 ~13 ~44 ~101 ~13 ~44 stone 0  
fill ~15 ~13 ~45 ~101 ~13 ~45 stone 0  
fill ~15 ~13 ~46 ~101 ~13 ~46 stone 0  
fill ~15 ~13 ~47 ~102 ~13 ~47 stone 0  
fill ~15 ~13 ~48 ~102 ~13 ~48 stone 0  
fill ~15 ~13 ~49 ~102 ~13 ~49 stone 0  
fill ~15 ~13 ~50 ~102 ~13 ~50 stone 0  
fill ~15 ~13 ~51 ~102 ~13 ~51 stone 0  
fill ~15 ~13 ~52 ~102 ~13 ~52 stone 0  
fill ~15 ~13 ~53 ~102 ~13 ~53 stone 0  
fill ~15 ~13 ~54 ~102 ~13 ~54 stone 0  
fill ~15 ~13 ~55 ~102 ~13 ~55 stone 0  
fill ~15 ~13 ~56 ~102 ~13 ~56 stone 0  
fill ~15 ~13 ~57 ~102 ~13 ~57 stone 0  
fill ~15 ~13 ~58 ~102 ~13 ~58 stone 0  
fill ~15 ~13 ~59 ~102 ~13 ~59 stone 0  
fill ~15 ~13 ~63 ~101 ~13 ~63 stone 0  
fill ~15 ~13 ~64 ~101 ~13 ~64 stone 0  
fill ~15 ~13 ~65 ~101 ~13 ~65 stone 0  
fill ~15 ~13 ~66 ~101 ~13 ~66 stone 0  
fill ~15 ~13 ~67 ~100 ~13 ~67 stone 0  
fill ~15 ~13 ~87 ~90 ~13 ~87 stone 0  
fill ~15 ~13 ~88 ~15 ~14 ~88 end_stone 0  
fill ~16 ~13 ~34 ~98 ~13 ~34 stone 0  
fill ~16 ~13 ~35 ~98 ~13 ~35 stone 0  
fill ~16 ~13 ~88 ~89 ~13 ~88 stone 0  
fill ~17 ~13 ~31 ~96 ~13 ~31 stone 0  
fill ~17 ~13 ~32 ~97 ~13 ~32 stone 0  
fill ~17 ~13 ~33 ~97 ~13 ~33 stone 0  
fill ~17 ~13 ~89 ~88 ~13 ~89 stone 0  
fill ~18 ~13 ~28 ~95 ~13 ~28 stone 0  
fill ~18 ~13 ~29 ~95 ~13 ~29 stone 0  
fill ~18 ~13 ~30 ~96 ~13 ~30 stone 0  
fill ~18 ~13 ~90 ~87 ~13 ~90 stone 0  
fill ~19 ~13 ~91 ~86 ~13 ~91 stone 0 
setblock ~19 ~13 ~92 end_bricks 0  
fill ~20 ~13 ~26 ~94 ~13 ~26 stone 0  
fill ~20 ~13 ~27 ~94 ~13 ~27 stone 0  
fill ~20 ~13 ~92 ~85 ~13 ~92 stone 0  
fill ~22 ~13 ~25 ~93 ~13 ~25 stone 0  
fill ~22 ~13 ~93 ~84 ~13 ~93 stone 0  
fill ~22 ~13 ~94 ~22 ~14 ~94 end_stone 0  
fill ~23 ~13 ~94 ~82 ~13 ~94 stone 0  
fill ~24 ~13 ~24 ~92 ~13 ~24 stone 0  
fill ~24 ~13 ~95 ~81 ~13 ~95 stone 0  
fill ~24 ~13 ~96 ~24 ~14 ~96 end_stone 0 
setblock ~25 ~13 ~23 torch 4  
fill ~25 ~13 ~96 ~80 ~13 ~96 stone 0  
fill ~26 ~13 ~23 ~91 ~13 ~23 stone 0  
fill ~26 ~13 ~97 ~26 ~15 ~97 end_stone 0  
fill ~27 ~13 ~22 ~91 ~13 ~22 stone 0  
fill ~27 ~13 ~97 ~78 ~13 ~97 stone 0  
fill ~28 ~13 ~98 ~76 ~13 ~98 stone 0  
fill ~30 ~13 ~21 ~90 ~13 ~21 stone 0  
fill ~30 ~13 ~99 ~74 ~13 ~99 stone 0  
fill ~32 ~13 ~20 ~89 ~13 ~20 stone 0  
fill ~32 ~13 ~100 ~72 ~13 ~100 stone 0  
fill ~34 ~13 ~19 ~88 ~13 ~19 stone 0  
fill ~34 ~13 ~101 ~70 ~13 ~101 stone 0  
fill ~36 ~13 ~17 ~86 ~13 ~17 stone 0  
fill ~36 ~13 ~18 ~87 ~13 ~18 stone 0  
fill ~37 ~13 ~102 ~67 ~13 ~102 stone 0  
fill ~38 ~13 ~15 ~84 ~13 ~15 stone 0  
fill ~38 ~13 ~16 ~85 ~13 ~16 stone 0  
fill ~40 ~13 ~5 ~64 ~13 ~5 stone 0  
fill ~40 ~13 ~14 ~82 ~13 ~14 stone 0  
fill ~40 ~13 ~103 ~64 ~13 ~103 stone 0  
fill ~41 ~13 ~13 ~81 ~13 ~13 stone 0  
fill ~42 ~13 ~12 ~80 ~13 ~12 stone 0  
fill ~43 ~13 ~11 ~78 ~13 ~11 stone 0  
fill ~44 ~13 ~6 ~67 ~13 ~6 stone 0  
fill ~44 ~13 ~10 ~76 ~13 ~10 stone 0  
fill ~45 ~13 ~4 ~59 ~13 ~4 stone 0  
fill ~45 ~13 ~7 ~70 ~13 ~7 stone 0  
fill ~45 ~13 ~8 ~72 ~13 ~8 stone 0  
fill ~45 ~13 ~9 ~74 ~13 ~9 stone 0  
fill ~45 ~13 ~104 ~59 ~13 ~104 stone 0  
fill ~2 ~14 ~56 ~6 ~14 ~56 leaves 0  
fill ~2 ~14 ~57 ~2 ~15 ~57 leaves 0  
fill ~2 ~14 ~58 ~2 ~15 ~58 leaves 0  
fill ~2 ~14 ~59 ~2 ~15 ~59 leaves 0  
fill ~3 ~14 ~57 ~5 ~14 ~57 leaves 4  
fill ~3 ~14 ~58 ~3 ~17 ~58 leaves 4  
fill ~3 ~14 ~59 ~5 ~14 ~59 leaves 4  
fill ~3 ~14 ~60 ~5 ~14 ~60 leaves 0  
fill ~4 ~14 ~49 ~7 ~14 ~49 leaves 4  
fill ~4 ~14 ~50 ~4 ~15 ~50 leaves 0  
fill ~4 ~14 ~51 ~4 ~15 ~51 leaves 0  
fill ~4 ~14 ~52 ~7 ~14 ~52 leaves 0  
fill ~4 ~14 ~68 ~100 ~14 ~68 stone 0  
fill ~4 ~14 ~69 ~100 ~14 ~69 stone 0  
fill ~5 ~14 ~48 ~5 ~15 ~48 leaves 4  
fill ~5 ~14 ~50 ~5 ~17 ~50 leaves 4  
fill ~5 ~14 ~51 ~7 ~14 ~51 leaves 4  
fill ~5 ~14 ~58 ~5 ~17 ~58 leaves 4  
fill ~5 ~14 ~67 ~100 ~14 ~67 stone 0  
fill ~5 ~14 ~71 ~5 ~15 ~71 end_stone 0  
fill ~5 ~14 ~72 ~5 ~15 ~72 end_stone 0 
setblock ~6 ~14 ~43 tallgrass 0  
fill ~6 ~14 ~48 ~7 ~14 ~48 leaves 0  
fill ~6 ~14 ~57 ~6 ~15 ~57 leaves 0  
fill ~6 ~14 ~58 ~6 ~15 ~58 leaves 0  
fill ~6 ~14 ~59 ~6 ~15 ~59 leaves 0  
fill ~6 ~14 ~66 ~6 ~15 ~66 stone 0  
fill ~6 ~14 ~70 ~99 ~14 ~70 stone 0  
fill ~6 ~14 ~71 ~99 ~14 ~71 stone 0  
fill ~6 ~14 ~72 ~99 ~14 ~72 stone 0  
fill ~6 ~14 ~74 ~6 ~15 ~74 end_stone 0 
setblock ~7 ~14 ~34 stone_slab 3  
fill ~7 ~14 ~50 ~7 ~17 ~50 leaves 4  
fill ~7 ~14 ~64 ~101 ~14 ~64 stone 0  
fill ~7 ~14 ~65 ~101 ~14 ~65 stone 0 
setblock ~7 ~14 ~66 command_block 1  
fill ~7 ~14 ~73 ~98 ~14 ~73 stone 0  
fill ~7 ~14 ~74 ~98 ~14 ~74 stone 0  
fill ~7 ~14 ~76 ~7 ~15 ~76 end_stone 0 
setblock ~8 ~14 ~43 red_flower 0  
fill ~8 ~14 ~49 ~8 ~15 ~49 leaves 0  
fill ~8 ~14 ~50 ~8 ~15 ~50 leaves 0  
fill ~8 ~14 ~51 ~8 ~15 ~51 leaves 0 
setblock ~8 ~14 ~59 water 1  
fill ~8 ~14 ~63 ~101 ~14 ~63 stone 0  
fill ~8 ~14 ~66 ~101 ~14 ~66 stone 0  
fill ~8 ~14 ~75 ~97 ~14 ~75 stone 0  
fill ~8 ~14 ~76 ~9 ~14 ~76 stone 0  
fill ~8 ~14 ~77 ~8 ~15 ~77 end_stone 0 
setblock ~9 ~14 ~38 stone_slab 3 
setblock ~9 ~14 ~59 water 0  
fill ~9 ~14 ~60 ~102 ~14 ~60 stone 0  
fill ~9 ~14 ~61 ~102 ~14 ~61 stone 0  
fill ~9 ~14 ~62 ~101 ~14 ~62 stone 0  
fill ~9 ~14 ~77 ~9 ~14 ~78 stone 0  
fill ~10 ~14 ~42 ~13 ~14 ~42 tallgrass 0  
fill ~10 ~14 ~43 ~13 ~14 ~43 tallgrass 0  
fill ~10 ~14 ~45 ~11 ~14 ~45 tallgrass 0  
fill ~10 ~14 ~46 ~11 ~14 ~46 tallgrass 0  
fill ~10 ~14 ~54 ~102 ~14 ~54 stone 0  
fill ~10 ~14 ~55 ~102 ~14 ~55 stone 0  
fill ~10 ~14 ~56 ~102 ~14 ~56 stone 0  
fill ~10 ~14 ~57 ~102 ~14 ~57 stone 0  
fill ~10 ~14 ~58 ~102 ~14 ~58 stone 0  
fill ~10 ~14 ~59 ~102 ~14 ~59 stone 0  
fill ~10 ~14 ~76 ~12 ~14 ~76 end_stone 0  
fill ~10 ~14 ~77 ~13 ~14 ~77 end_stone 0  
fill ~10 ~14 ~78 ~10 ~14 ~79 stone 0  
fill ~10 ~14 ~80 ~12 ~14 ~80 end_stone 0 
setblock ~10 ~14 ~82 end_bricks 0 
setblock ~11 ~14 ~32 stone_slab 3 
setblock ~11 ~14 ~44 tallgrass 0 
setblock ~11 ~14 ~47 tallgrass 0  
fill ~11 ~14 ~53 ~102 ~14 ~53 stone 0  
fill ~11 ~14 ~78 ~11 ~14 ~83 end_stone 0  
fill ~12 ~14 ~41 ~14 ~14 ~41 tallgrass 0 
setblock ~12 ~14 ~44 red_flower 3 
setblock ~12 ~14 ~47 red_flower 8  
fill ~12 ~14 ~51 ~102 ~14 ~51 stone 0  
fill ~12 ~14 ~52 ~102 ~14 ~52 stone 0  
fill ~12 ~14 ~78 ~13 ~14 ~78 end_bricks 0  
fill ~12 ~14 ~79 ~16 ~14 ~79 end_stone 0  
fill ~12 ~14 ~81 ~13 ~14 ~81 end_stone 0  
fill ~12 ~14 ~82 ~12 ~14 ~84 end_stone 0 
setblock ~13 ~14 ~44 tallgrass 0  
fill ~13 ~14 ~45 ~101 ~14 ~45 stone 0  
fill ~13 ~14 ~46 ~101 ~14 ~46 stone 0  
fill ~13 ~14 ~47 ~102 ~14 ~47 stone 0  
fill ~13 ~14 ~48 ~102 ~14 ~48 stone 0  
fill ~13 ~14 ~49 ~102 ~14 ~49 stone 0  
fill ~13 ~14 ~50 ~102 ~14 ~50 stone 0  
fill ~13 ~14 ~76 ~97 ~14 ~76 stone 0 
setblock ~13 ~14 ~80 end_bricks 0  
fill ~13 ~14 ~82 ~16 ~14 ~82 stone 0  
fill ~13 ~14 ~83 ~13 ~14 ~86 end_stone 0  
fill ~14 ~14 ~43 ~101 ~14 ~43 stone 0  
fill ~14 ~14 ~44 ~101 ~14 ~44 stone 0  
fill ~14 ~14 ~77 ~96 ~14 ~77 stone 0 
setblock ~14 ~14 ~78 end_stone 0  
fill ~14 ~14 ~80 ~17 ~14 ~80 end_stone 0  
fill ~14 ~14 ~81 ~15 ~14 ~81 stone 0  
fill ~14 ~14 ~83 ~16 ~14 ~83 stone 0  
fill ~14 ~14 ~84 ~16 ~14 ~84 stone 0  
fill ~14 ~14 ~85 ~14 ~14 ~87 end_stone 0  
fill ~15 ~14 ~36 ~99 ~14 ~36 stone 0  
fill ~15 ~14 ~37 ~99 ~14 ~37 stone 0 
setblock ~15 ~14 ~38 stone_slab 3  
fill ~15 ~14 ~39 ~100 ~14 ~39 stone 0  
fill ~15 ~14 ~40 ~100 ~14 ~40 stone 0  
fill ~15 ~14 ~41 ~100 ~14 ~41 stone 0  
fill ~15 ~14 ~42 ~101 ~14 ~42 stone 0  
fill ~15 ~14 ~78 ~96 ~14 ~78 stone 0  
fill ~15 ~14 ~85 ~17 ~14 ~85 stone 0  
fill ~15 ~14 ~86 ~15 ~14 ~88 end_stone 0  
fill ~16 ~14 ~34 ~98 ~14 ~34 stone 0  
fill ~16 ~14 ~35 ~98 ~14 ~35 stone 0 
setblock ~16 ~14 ~38 double_stone_slab 3  
fill ~16 ~14 ~81 ~17 ~14 ~81 end_stone 0  
fill ~16 ~14 ~86 ~19 ~14 ~86 stone 0  
fill ~16 ~14 ~87 ~20 ~14 ~87 stone 0 
setblock ~16 ~14 ~88 end_stone 0  
fill ~17 ~14 ~31 ~96 ~14 ~31 stone 0  
fill ~17 ~14 ~32 ~97 ~14 ~32 stone 0  
fill ~17 ~14 ~33 ~97 ~14 ~33 stone 0  
fill ~17 ~14 ~38 ~99 ~14 ~38 stone 0  
fill ~17 ~14 ~79 ~95 ~14 ~79 stone 0  
fill ~17 ~14 ~82 ~18 ~14 ~82 end_stone 0  
fill ~17 ~14 ~83 ~18 ~14 ~83 end_stone 0 
setblock ~17 ~14 ~84 end_bricks 0  
fill ~17 ~14 ~88 ~20 ~14 ~88 stone 0  
fill ~17 ~14 ~89 ~18 ~14 ~89 end_stone 0  
fill ~18 ~14 ~29 ~95 ~14 ~29 stone 0  
fill ~18 ~14 ~30 ~96 ~14 ~30 stone 0  
fill ~18 ~14 ~80 ~95 ~14 ~80 stone 0  
fill ~18 ~14 ~81 ~94 ~14 ~81 stone 0  
fill ~18 ~14 ~84 ~20 ~14 ~84 end_stone 0  
fill ~18 ~14 ~85 ~21 ~14 ~85 end_stone 0 
setblock ~18 ~14 ~90 end_stone 0  
fill ~19 ~14 ~28 ~95 ~14 ~28 stone 0  
fill ~19 ~14 ~82 ~94 ~14 ~82 stone 0  
fill ~19 ~14 ~83 ~93 ~14 ~83 stone 0  
fill ~19 ~14 ~89 ~20 ~14 ~89 stone 0 
setblock ~19 ~14 ~90 end_bricks 0  
fill ~19 ~14 ~91 ~22 ~14 ~91 end_stone 0  
fill ~19 ~14 ~92 ~21 ~14 ~92 end_stone 0 
setblock ~20 ~14 ~26 stone 5  
fill ~20 ~14 ~27 ~94 ~14 ~27 stone 0  
fill ~20 ~14 ~86 ~22 ~14 ~86 end_stone 0  
fill ~20 ~14 ~90 ~22 ~14 ~90 end_stone 0  
fill ~21 ~14 ~25 ~93 ~14 ~25 stone 0  
fill ~21 ~14 ~26 ~94 ~14 ~26 stone 0  
fill ~21 ~14 ~84 ~92 ~14 ~84 stone 0  
fill ~21 ~14 ~87 ~22 ~14 ~87 end_stone 0  
fill ~21 ~14 ~88 ~23 ~14 ~88 end_stone 0  
fill ~21 ~14 ~89 ~23 ~14 ~89 end_stone 0  
fill ~22 ~14 ~24 ~92 ~14 ~24 stone 0  
fill ~22 ~14 ~85 ~91 ~14 ~85 stone 0  
fill ~22 ~14 ~92 ~85 ~14 ~92 stone 0  
fill ~22 ~14 ~93 ~22 ~15 ~93 end_stone 0  
fill ~23 ~14 ~86 ~91 ~14 ~86 stone 0  
fill ~23 ~14 ~87 ~90 ~14 ~87 stone 0  
fill ~23 ~14 ~90 ~87 ~14 ~90 stone 0  
fill ~23 ~14 ~91 ~86 ~14 ~91 stone 0  
fill ~23 ~14 ~93 ~84 ~14 ~93 stone 0  
fill ~23 ~14 ~94 ~82 ~14 ~94 stone 0  
fill ~24 ~14 ~88 ~89 ~14 ~88 stone 0  
fill ~24 ~14 ~89 ~88 ~14 ~89 stone 0  
fill ~24 ~14 ~95 ~81 ~14 ~95 stone 0  
fill ~25 ~14 ~23 ~91 ~14 ~23 stone 0  
fill ~25 ~14 ~96 ~25 ~15 ~96 end_stone 0  
fill ~26 ~14 ~22 ~91 ~14 ~22 stone 0  
fill ~26 ~14 ~96 ~80 ~14 ~96 stone 0  
fill ~27 ~14 ~97 ~27 ~15 ~97 end_stone 0  
fill ~28 ~14 ~97 ~78 ~14 ~97 stone 0  
fill ~28 ~14 ~98 ~76 ~14 ~98 stone 0  
fill ~29 ~14 ~21 ~90 ~14 ~21 stone 0  
fill ~30 ~14 ~99 ~74 ~14 ~99 stone 0  
fill ~31 ~14 ~20 ~89 ~14 ~20 stone 0  
fill ~32 ~14 ~100 ~32 ~16 ~100 dirt 0  
fill ~33 ~14 ~19 ~88 ~14 ~19 stone 0  
fill ~33 ~14 ~100 ~72 ~14 ~100 stone 0  
fill ~34 ~14 ~101 ~35 ~14 ~101 stone 0  
fill ~35 ~14 ~18 ~87 ~14 ~18 stone 0  
fill ~36 ~14 ~17 ~86 ~14 ~17 stone 0  
fill ~36 ~14 ~101 ~36 ~16 ~101 dirt 0  
fill ~37 ~14 ~15 ~84 ~14 ~15 stone 0  
fill ~37 ~14 ~16 ~85 ~14 ~16 stone 0  
fill ~37 ~14 ~101 ~70 ~14 ~101 stone 0  
fill ~37 ~14 ~102 ~67 ~14 ~102 stone 0  
fill ~38 ~14 ~6 ~67 ~14 ~6 stone 0  
fill ~38 ~14 ~14 ~82 ~14 ~14 stone 0  
fill ~39 ~14 ~13 ~81 ~14 ~13 stone 0  
fill ~40 ~14 ~5 ~64 ~14 ~5 stone 0  
fill ~40 ~14 ~103 ~64 ~14 ~103 stone 0  
fill ~41 ~14 ~7 ~70 ~14 ~7 stone 0  
fill ~41 ~14 ~11 ~78 ~14 ~11 stone 0  
fill ~41 ~14 ~12 ~80 ~14 ~12 stone 0  
fill ~42 ~14 ~8 ~72 ~14 ~8 stone 0  
fill ~42 ~14 ~9 ~74 ~14 ~9 stone 0  
fill ~42 ~14 ~10 ~76 ~14 ~10 stone 0  
fill ~45 ~14 ~4 ~59 ~14 ~4 stone 0  
fill ~45 ~14 ~104 ~59 ~14 ~104 stone 0  
fill ~3 ~15 ~56 ~6 ~15 ~56 leaves 0  
fill ~3 ~15 ~57 ~5 ~15 ~57 leaves 4  
fill ~3 ~15 ~59 ~5 ~15 ~59 leaves 4  
fill ~3 ~15 ~60 ~5 ~15 ~60 leaves 0 
setblock ~4 ~15 ~48 leaves 12  
fill ~4 ~15 ~49 ~7 ~15 ~49 leaves 4  
fill ~4 ~15 ~52 ~7 ~15 ~52 leaves 0  
fill ~4 ~15 ~68 ~5 ~15 ~68 stone 0  
fill ~4 ~15 ~69 ~4 ~0 ~69 stone 0  
fill ~5 ~15 ~51 ~7 ~15 ~51 leaves 4  
fill ~5 ~15 ~67 ~7 ~15 ~67 stone 0  
fill ~5 ~15 ~69 ~10 ~15 ~69 end_stone 0  
fill ~6 ~15 ~48 ~7 ~15 ~48 leaves 0  
fill ~6 ~15 ~68 ~7 ~15 ~68 end_stone 0  
fill ~6 ~15 ~70 ~10 ~15 ~70 end_stone 0 
setblock ~6 ~15 ~71 end_bricks 0  
fill ~6 ~15 ~72 ~12 ~15 ~72 end_stone 0  
fill ~7 ~15 ~64 ~101 ~15 ~64 stone 0  
fill ~7 ~15 ~65 ~7 ~14 ~65 stone 0  
fill ~7 ~15 ~66 ~9 ~15 ~66 end_stone 0  
fill ~7 ~15 ~71 ~10 ~15 ~71 end_stone 0  
fill ~7 ~15 ~73 ~7 ~15 ~74 end_bricks 0  
fill ~8 ~15 ~63 ~101 ~15 ~63 stone 0 
setblock ~8 ~15 ~65 end_stone 0  
fill ~8 ~15 ~67 ~10 ~15 ~67 end_stone 0 
setblock ~8 ~15 ~68 end_bricks 0  
fill ~8 ~15 ~73 ~9 ~15 ~73 end_stone 0  
fill ~8 ~15 ~74 ~13 ~15 ~74 end_stone 0  
fill ~8 ~15 ~75 ~14 ~15 ~75 end_stone 0  
fill ~8 ~15 ~76 ~9 ~15 ~76 end_stone 0  
fill ~9 ~15 ~59 ~102 ~15 ~59 stone 0  
fill ~9 ~15 ~60 ~102 ~15 ~60 stone 0  
fill ~9 ~15 ~61 ~102 ~15 ~61 stone 0  
fill ~9 ~15 ~62 ~101 ~15 ~62 stone 0  
fill ~9 ~15 ~65 ~101 ~15 ~65 stone 0  
fill ~9 ~15 ~68 ~10 ~15 ~68 end_stone 0  
fill ~9 ~15 ~77 ~11 ~15 ~77 end_stone 0  
fill ~9 ~15 ~78 ~10 ~15 ~78 end_stone 0  
fill ~10 ~15 ~54 ~102 ~15 ~54 stone 0  
fill ~10 ~15 ~55 ~102 ~15 ~55 stone 0  
fill ~10 ~15 ~56 ~102 ~15 ~56 stone 0  
fill ~10 ~15 ~57 ~102 ~15 ~57 stone 0  
fill ~10 ~15 ~58 ~102 ~15 ~58 stone 0  
fill ~10 ~15 ~66 ~101 ~15 ~66 stone 0 
setblock ~10 ~15 ~73 end_bricks 0 
setblock ~10 ~15 ~76 end_bricks 0 
setblock ~10 ~15 ~79 end_stone 0  
fill ~11 ~15 ~53 ~102 ~15 ~53 stone 0  
fill ~11 ~15 ~67 ~100 ~15 ~67 stone 0  
fill ~11 ~15 ~68 ~100 ~15 ~68 stone 0  
fill ~11 ~15 ~69 ~100 ~15 ~69 stone 0  
fill ~11 ~15 ~70 ~99 ~15 ~70 stone 0  
fill ~11 ~15 ~71 ~99 ~15 ~71 stone 0  
fill ~11 ~15 ~73 ~13 ~15 ~73 end_stone 0  
fill ~11 ~15 ~76 ~15 ~15 ~76 end_stone 0  
fill ~12 ~15 ~51 ~102 ~15 ~51 stone 0  
fill ~12 ~15 ~52 ~102 ~15 ~52 stone 0  
fill ~13 ~15 ~46 ~101 ~15 ~46 stone 0  
fill ~13 ~15 ~47 ~102 ~15 ~47 stone 0  
fill ~13 ~15 ~48 ~102 ~15 ~48 stone 0  
fill ~13 ~15 ~49 ~102 ~15 ~49 stone 0  
fill ~13 ~15 ~50 ~102 ~15 ~50 stone 0  
fill ~13 ~15 ~72 ~99 ~15 ~72 stone 0 
setblock ~13 ~15 ~82 end_bricks 0  
fill ~14 ~15 ~43 ~101 ~15 ~43 stone 0  
fill ~14 ~15 ~44 ~101 ~15 ~44 stone 0  
fill ~14 ~15 ~45 ~101 ~15 ~45 stone 0  
fill ~14 ~15 ~73 ~98 ~15 ~73 stone 0  
fill ~14 ~15 ~74 ~98 ~15 ~74 stone 0  
fill ~14 ~15 ~77 ~16 ~15 ~77 end_stone 0  
fill ~14 ~15 ~81 ~15 ~15 ~81 end_stone 0  
fill ~14 ~15 ~82 ~16 ~15 ~82 end_stone 0  
fill ~14 ~15 ~83 ~16 ~15 ~83 end_stone 0  
fill ~14 ~15 ~84 ~16 ~15 ~84 end_stone 0  
fill ~15 ~15 ~39 ~16 ~15 ~39 stone 0  
fill ~15 ~15 ~40 ~100 ~15 ~40 stone 0  
fill ~15 ~15 ~41 ~100 ~15 ~41 stone 0  
fill ~15 ~15 ~42 ~101 ~15 ~42 stone 0  
fill ~15 ~15 ~75 ~97 ~15 ~75 stone 0  
fill ~15 ~15 ~78 ~17 ~15 ~78 end_stone 0 
setblock ~15 ~15 ~85 end_bricks 0  
fill ~16 ~15 ~35 ~98 ~15 ~35 stone 0  
fill ~16 ~15 ~36 ~99 ~15 ~36 stone 0  
fill ~16 ~15 ~37 ~99 ~15 ~37 stone 0  
fill ~16 ~15 ~76 ~97 ~15 ~76 stone 0  
fill ~16 ~15 ~85 ~17 ~15 ~85 end_stone 0  
fill ~16 ~15 ~86 ~19 ~15 ~86 end_stone 0  
fill ~16 ~15 ~87 ~20 ~15 ~87 end_stone 0  
fill ~17 ~15 ~32 ~97 ~15 ~32 stone 0  
fill ~17 ~15 ~33 ~97 ~15 ~33 stone 0  
fill ~17 ~15 ~34 ~98 ~15 ~34 stone 0 
setblock ~17 ~15 ~38 stone_slab 3 
setblock ~17 ~15 ~39 double_stone_slab 3  
fill ~17 ~15 ~77 ~96 ~15 ~77 stone 0  
fill ~17 ~15 ~79 ~18 ~15 ~79 end_stone 0  
fill ~17 ~15 ~88 ~20 ~15 ~88 end_stone 0  
fill ~18 ~15 ~29 ~95 ~15 ~29 stone 0  
fill ~18 ~15 ~30 ~96 ~15 ~30 stone 0  
fill ~18 ~15 ~31 ~96 ~15 ~31 stone 0  
fill ~18 ~15 ~38 ~99 ~15 ~38 stone 0  
fill ~18 ~15 ~39 ~100 ~15 ~39 stone 0  
fill ~18 ~15 ~78 ~96 ~15 ~78 stone 0  
fill ~18 ~15 ~80 ~95 ~15 ~80 stone 0  
fill ~18 ~15 ~81 ~19 ~15 ~81 end_stone 0  
fill ~19 ~15 ~28 ~95 ~15 ~28 stone 0  
fill ~19 ~15 ~79 ~95 ~15 ~79 stone 0  
fill ~19 ~15 ~82 ~20 ~15 ~82 end_stone 0  
fill ~19 ~15 ~83 ~20 ~15 ~83 end_stone 0  
fill ~19 ~15 ~89 ~20 ~15 ~89 end_stone 0  
fill ~20 ~15 ~26 ~94 ~15 ~26 stone 0  
fill ~20 ~15 ~27 ~94 ~15 ~27 stone 0  
fill ~20 ~15 ~81 ~94 ~15 ~81 stone 0  
fill ~21 ~15 ~25 ~93 ~15 ~25 stone 0  
fill ~21 ~15 ~82 ~94 ~15 ~82 stone 0  
fill ~21 ~15 ~83 ~93 ~15 ~83 stone 0  
fill ~21 ~15 ~84 ~22 ~15 ~84 end_stone 0  
fill ~22 ~15 ~24 ~92 ~15 ~24 stone 0  
fill ~22 ~15 ~85 ~23 ~15 ~85 end_stone 0  
fill ~22 ~15 ~92 ~29 ~15 ~92 end_stone 0  
fill ~23 ~15 ~23 ~91 ~15 ~23 stone 0  
fill ~23 ~15 ~84 ~92 ~15 ~84 stone 0 
setblock ~23 ~15 ~86 end_stone 0 
setblock ~23 ~15 ~87 end_bricks 0  
fill ~23 ~15 ~90 ~28 ~15 ~90 end_stone 0  
fill ~23 ~15 ~91 ~26 ~15 ~91 end_stone 0  
fill ~23 ~15 ~93 ~27 ~15 ~93 end_stone 0  
fill ~23 ~15 ~94 ~30 ~15 ~94 end_stone 0  
fill ~24 ~15 ~85 ~91 ~15 ~85 stone 0  
fill ~24 ~15 ~86 ~91 ~15 ~86 stone 0  
fill ~24 ~15 ~87 ~25 ~15 ~87 end_stone 0  
fill ~24 ~15 ~88 ~25 ~15 ~88 end_stone 0  
fill ~24 ~15 ~89 ~26 ~15 ~89 end_stone 0  
fill ~24 ~15 ~95 ~26 ~15 ~95 end_stone 0 
setblock ~24 ~15 ~96 end_bricks 0  
fill ~25 ~15 ~22 ~91 ~15 ~22 stone 0  
fill ~26 ~15 ~21 ~90 ~15 ~21 stone 0  
fill ~26 ~15 ~87 ~90 ~15 ~87 stone 0 
setblock ~26 ~15 ~88 end_bricks 0  
fill ~26 ~15 ~96 ~30 ~15 ~96 end_stone 0  
fill ~27 ~15 ~88 ~89 ~15 ~88 stone 0  
fill ~27 ~15 ~89 ~88 ~15 ~89 stone 0 
setblock ~27 ~15 ~91 end_bricks 0 
setblock ~27 ~15 ~95 end_bricks 0  
fill ~28 ~15 ~20 ~89 ~15 ~20 stone 0  
fill ~28 ~15 ~91 ~29 ~15 ~91 end_stone 0 
setblock ~28 ~15 ~93 end_bricks 0  
fill ~28 ~15 ~95 ~30 ~15 ~95 end_stone 0  
fill ~28 ~15 ~97 ~29 ~15 ~97 end_stone 0  
fill ~28 ~15 ~98 ~28 ~0 ~98 stone 0  
fill ~29 ~15 ~90 ~87 ~15 ~90 stone 0 
setblock ~29 ~15 ~93 end_stone 0  
fill ~29 ~15 ~98 ~29 ~16 ~98 dirt 0  
fill ~30 ~15 ~91 ~86 ~15 ~91 stone 0  
fill ~30 ~15 ~92 ~30 ~15 ~93 end_bricks 0  
fill ~30 ~15 ~97 ~78 ~15 ~97 stone 0  
fill ~30 ~15 ~98 ~76 ~15 ~98 stone 0  
fill ~30 ~15 ~99 ~30 ~0 ~99 stone 0  
fill ~31 ~15 ~19 ~88 ~15 ~19 stone 0  
fill ~31 ~15 ~92 ~85 ~15 ~92 stone 0  
fill ~31 ~15 ~93 ~84 ~15 ~93 stone 0  
fill ~31 ~15 ~94 ~82 ~15 ~94 stone 0  
fill ~31 ~15 ~95 ~81 ~15 ~95 stone 0  
fill ~31 ~15 ~96 ~80 ~15 ~96 stone 0  
fill ~31 ~15 ~99 ~31 ~16 ~99 dirt 0  
fill ~32 ~15 ~99 ~74 ~15 ~99 stone 0  
fill ~33 ~15 ~100 ~33 ~16 ~100 dirt 0  
fill ~34 ~15 ~7 ~70 ~15 ~7 stone 0  
fill ~34 ~15 ~18 ~87 ~15 ~18 stone 0  
fill ~34 ~15 ~100 ~72 ~15 ~100 stone 0  
fill ~34 ~15 ~101 ~34 ~0 ~101 stone 0  
fill ~35 ~15 ~17 ~86 ~15 ~17 stone 0  
fill ~35 ~15 ~101 ~35 ~16 ~101 dirt 0  
fill ~36 ~15 ~8 ~72 ~15 ~8 stone 0  
fill ~36 ~15 ~15 ~84 ~15 ~15 stone 0  
fill ~36 ~15 ~16 ~85 ~15 ~16 stone 0  
fill ~37 ~15 ~6 ~67 ~15 ~6 stone 0  
fill ~37 ~15 ~12 ~80 ~15 ~12 stone 0  
fill ~37 ~15 ~13 ~81 ~15 ~13 stone 0  
fill ~37 ~15 ~14 ~82 ~15 ~14 stone 0  
fill ~37 ~15 ~101 ~70 ~15 ~101 stone 0  
fill ~37 ~15 ~102 ~37 ~16 ~102 dirt 0  
fill ~38 ~15 ~9 ~74 ~15 ~9 stone 0  
fill ~38 ~15 ~11 ~78 ~15 ~11 stone 0 
setblock ~38 ~15 ~102 stone 0  
fill ~39 ~15 ~10 ~76 ~15 ~10 stone 0  
fill ~39 ~15 ~102 ~39 ~16 ~102 dirt 0  
fill ~40 ~15 ~5 ~64 ~15 ~5 stone 0  
fill ~40 ~15 ~102 ~67 ~15 ~102 stone 0  
fill ~40 ~15 ~103 ~64 ~15 ~103 stone 0  
fill ~45 ~15 ~4 ~59 ~15 ~4 stone 0  
fill ~45 ~15 ~104 ~59 ~15 ~104 stone 0  
fill ~2 ~16 ~40 ~6 ~16 ~40 leaves 0  
fill ~2 ~16 ~41 ~2 ~17 ~41 leaves 0  
fill ~2 ~16 ~42 ~2 ~17 ~42 leaves 0  
fill ~2 ~16 ~43 ~2 ~17 ~43 leaves 0  
fill ~2 ~16 ~44 ~6 ~16 ~44 leaves 0  
fill ~3 ~16 ~41 ~5 ~16 ~41 leaves 4  
fill ~3 ~16 ~42 ~3 ~19 ~42 leaves 4  
fill ~3 ~16 ~43 ~5 ~16 ~43 leaves 4  
fill ~3 ~16 ~57 ~4 ~16 ~57 leaves 4  
fill ~3 ~16 ~59 ~5 ~16 ~59 leaves 4  
fill ~5 ~16 ~42 ~5 ~19 ~42 leaves 4  
fill ~6 ~16 ~41 ~6 ~17 ~41 leaves 0  
fill ~6 ~16 ~42 ~6 ~17 ~42 leaves 0  
fill ~6 ~16 ~43 ~6 ~17 ~43 leaves 0  
fill ~6 ~16 ~49 ~7 ~16 ~49 leaves 4  
fill ~6 ~16 ~51 ~6 ~17 ~51 leaves 4 
setblock ~7 ~16 ~66 light_weighted_pressure_plate 0  
fill ~7 ~16 ~72 ~7 ~17 ~72 lime_glazed_terracotta 0  
fill ~7 ~16 ~76 ~7 ~17 ~76 lime_glazed_terracotta 0  
fill ~8 ~16 ~63 ~101 ~16 ~63 stone 0  
fill ~9 ~16 ~59 ~102 ~16 ~59 stone 0  
fill ~9 ~16 ~60 ~102 ~16 ~60 stone 0  
fill ~9 ~16 ~61 ~102 ~16 ~61 stone 0  
fill ~9 ~16 ~62 ~101 ~16 ~62 stone 0  
fill ~9 ~16 ~64 ~101 ~16 ~64 stone 0  
fill ~9 ~16 ~65 ~101 ~16 ~65 stone 0  
fill ~9 ~16 ~66 ~9 ~16 ~67 end_stone 0  
fill ~9 ~16 ~79 ~9 ~19 ~79 lime_glazed_terracotta 0  
fill ~10 ~16 ~54 ~102 ~16 ~54 stone 0  
fill ~10 ~16 ~55 ~102 ~16 ~55 stone 0  
fill ~10 ~16 ~56 ~102 ~16 ~56 stone 0  
fill ~10 ~16 ~57 ~102 ~16 ~57 stone 0  
fill ~10 ~16 ~58 ~102 ~16 ~58 stone 0  
fill ~10 ~16 ~66 ~101 ~16 ~66 stone 0  
fill ~10 ~16 ~67 ~10 ~16 ~68 end_stone 0 
setblock ~10 ~16 ~69 end_bricks 0  
fill ~10 ~16 ~70 ~11 ~16 ~70 end_stone 0  
fill ~10 ~16 ~71 ~11 ~16 ~71 end_stone 0  
fill ~11 ~16 ~53 ~102 ~16 ~53 stone 0  
fill ~11 ~16 ~67 ~100 ~16 ~67 stone 0  
fill ~11 ~16 ~68 ~100 ~16 ~68 stone 0 
setblock ~11 ~16 ~69 end_stone 0  
fill ~11 ~16 ~72 ~12 ~16 ~72 end_stone 0  
fill ~11 ~16 ~74 ~11 ~18 ~74 lime_glazed_terracotta 0  
fill ~12 ~16 ~51 ~102 ~16 ~51 stone 0  
fill ~12 ~16 ~52 ~102 ~16 ~52 stone 0  
fill ~12 ~16 ~69 ~100 ~16 ~69 stone 0  
fill ~12 ~16 ~70 ~99 ~16 ~70 stone 0 
setblock ~12 ~16 ~71 end_bricks 0  
fill ~13 ~16 ~46 ~101 ~16 ~46 stone 0  
fill ~13 ~16 ~47 ~102 ~16 ~47 stone 0  
fill ~13 ~16 ~48 ~102 ~16 ~48 stone 0  
fill ~13 ~16 ~49 ~102 ~16 ~49 stone 0  
fill ~13 ~16 ~50 ~102 ~16 ~50 stone 0  
fill ~13 ~16 ~71 ~99 ~16 ~71 stone 0  
fill ~13 ~16 ~72 ~99 ~16 ~72 stone 0  
fill ~14 ~16 ~43 ~101 ~16 ~43 stone 0  
fill ~14 ~16 ~44 ~101 ~16 ~44 stone 0  
fill ~14 ~16 ~45 ~101 ~16 ~45 stone 0  
fill ~14 ~16 ~73 ~98 ~16 ~73 stone 0  
fill ~14 ~16 ~74 ~98 ~16 ~74 stone 0  
fill ~15 ~16 ~39 ~16 ~16 ~39 stone 0  
fill ~15 ~16 ~40 ~16 ~16 ~40 stone 0  
fill ~15 ~16 ~41 ~16 ~16 ~41 stone 0  
fill ~15 ~16 ~42 ~101 ~16 ~42 stone 0  
fill ~15 ~16 ~75 ~97 ~16 ~75 stone 0  
fill ~15 ~16 ~77 ~15 ~17 ~77 lime_glazed_terracotta 0  
fill ~15 ~16 ~82 ~15 ~19 ~82 lime_glazed_terracotta 0  
fill ~16 ~16 ~36 ~99 ~16 ~36 stone 0  
fill ~16 ~16 ~37 ~99 ~16 ~37 stone 0  
fill ~16 ~16 ~76 ~97 ~16 ~76 stone 0  
fill ~16 ~16 ~85 ~16 ~20 ~85 lime_glazed_terracotta 0  
fill ~17 ~16 ~32 ~97 ~16 ~32 stone 0  
fill ~17 ~16 ~33 ~97 ~16 ~33 stone 0  
fill ~17 ~16 ~34 ~98 ~16 ~34 stone 0  
fill ~17 ~16 ~35 ~98 ~16 ~35 stone 0 
setblock ~17 ~16 ~40 stone_slab 3 
setblock ~17 ~16 ~41 double_stone_slab 3  
fill ~17 ~16 ~77 ~96 ~16 ~77 stone 0  
fill ~18 ~16 ~29 ~95 ~16 ~29 stone 0  
fill ~18 ~16 ~30 ~96 ~16 ~30 stone 0  
fill ~18 ~16 ~31 ~96 ~16 ~31 stone 0  
fill ~18 ~16 ~38 ~99 ~16 ~38 stone 0  
fill ~18 ~16 ~39 ~100 ~16 ~39 stone 0  
fill ~18 ~16 ~40 ~100 ~16 ~40 stone 0  
fill ~18 ~16 ~41 ~100 ~16 ~41 stone 0  
fill ~18 ~16 ~78 ~96 ~16 ~78 stone 0  
fill ~18 ~16 ~79 ~95 ~16 ~79 stone 0  
fill ~18 ~16 ~80 ~95 ~16 ~80 stone 0  
fill ~19 ~16 ~27 ~94 ~16 ~27 stone 0  
fill ~19 ~16 ~28 ~95 ~16 ~28 stone 0  
fill ~19 ~16 ~87 ~19 ~20 ~87 lime_glazed_terracotta 0  
fill ~20 ~16 ~25 ~93 ~16 ~25 stone 0  
fill ~20 ~16 ~26 ~94 ~16 ~26 stone 0  
fill ~20 ~16 ~81 ~94 ~16 ~81 stone 0  
fill ~21 ~16 ~24 ~92 ~16 ~24 stone 0  
fill ~21 ~16 ~82 ~94 ~16 ~82 stone 0  
fill ~21 ~16 ~83 ~93 ~16 ~83 stone 0  
fill ~22 ~16 ~23 ~91 ~16 ~23 stone 0  
fill ~23 ~16 ~21 ~90 ~16 ~21 stone 0  
fill ~23 ~16 ~22 ~91 ~16 ~22 stone 0  
fill ~23 ~16 ~84 ~92 ~16 ~84 stone 0  
fill ~23 ~16 ~91 ~25 ~16 ~91 end_stone 0  
fill ~23 ~16 ~92 ~25 ~16 ~92 end_stone 0 
setblock ~23 ~16 ~93 end_bricks 0  
fill ~24 ~16 ~85 ~91 ~16 ~85 stone 0  
fill ~24 ~16 ~86 ~91 ~16 ~86 stone 0 
setblock ~24 ~16 ~93 end_stone 0  
fill ~25 ~16 ~20 ~89 ~16 ~20 stone 0 
setblock ~25 ~16 ~90 end_stone 0  
fill ~26 ~16 ~87 ~90 ~16 ~87 stone 0  
fill ~27 ~16 ~19 ~88 ~16 ~19 stone 0  
fill ~27 ~16 ~88 ~89 ~16 ~88 stone 0  
fill ~27 ~16 ~89 ~88 ~16 ~89 stone 0  
fill ~28 ~16 ~10 ~76 ~16 ~10 stone 0  
fill ~28 ~16 ~96 ~28 ~16 ~97 stone 0 
setblock ~28 ~16 ~98 dirt 0  
fill ~29 ~16 ~90 ~87 ~16 ~90 stone 0  
fill ~29 ~16 ~95 ~81 ~16 ~95 stone 0  
fill ~29 ~16 ~96 ~30 ~16 ~96 end_stone 0  
fill ~29 ~16 ~97 ~29 ~16 ~96 end_stone 0  
fill ~30 ~16 ~9 ~74 ~16 ~9 stone 0  
fill ~30 ~16 ~11 ~78 ~16 ~11 stone 0  
fill ~30 ~16 ~18 ~87 ~16 ~18 stone 0  
fill ~30 ~16 ~91 ~86 ~16 ~91 stone 0  
fill ~30 ~16 ~97 ~30 ~0 ~97 stone 0  
fill ~30 ~16 ~98 ~76 ~16 ~98 stone 0 
setblock ~30 ~16 ~99 dirt 0  
fill ~31 ~16 ~12 ~80 ~16 ~12 stone 0  
fill ~31 ~16 ~92 ~85 ~16 ~92 stone 0  
fill ~31 ~16 ~93 ~84 ~16 ~93 stone 0  
fill ~31 ~16 ~94 ~82 ~16 ~94 stone 0  
fill ~31 ~16 ~96 ~80 ~16 ~96 stone 0  
fill ~31 ~16 ~97 ~37 ~16 ~97 light_gray_glazed_terracotta 0  
fill ~32 ~16 ~8 ~72 ~16 ~8 stone 0  
fill ~32 ~16 ~13 ~81 ~16 ~13 stone 0  
fill ~32 ~16 ~16 ~85 ~16 ~16 stone 0  
fill ~32 ~16 ~17 ~86 ~16 ~17 stone 0  
fill ~32 ~16 ~99 ~74 ~16 ~99 stone 0  
fill ~34 ~16 ~7 ~70 ~16 ~7 stone 0  
fill ~34 ~16 ~14 ~82 ~16 ~14 stone 0  
fill ~34 ~16 ~15 ~84 ~16 ~15 stone 0  
fill ~34 ~16 ~100 ~72 ~16 ~100 stone 0 
setblock ~34 ~16 ~101 dirt 0  
fill ~37 ~16 ~6 ~67 ~16 ~6 stone 0  
fill ~37 ~16 ~101 ~70 ~16 ~101 stone 0  
fill ~38 ~16 ~97 ~78 ~16 ~97 stone 0 
setblock ~38 ~16 ~102 dirt 0  
fill ~40 ~16 ~5 ~64 ~16 ~5 stone 0  
fill ~40 ~16 ~102 ~67 ~16 ~102 stone 0  
fill ~40 ~16 ~103 ~64 ~16 ~103 stone 0  
fill ~45 ~16 ~4 ~59 ~16 ~4 stone 0  
fill ~45 ~16 ~104 ~59 ~16 ~104 stone 0  
fill ~3 ~17 ~40 ~6 ~17 ~40 leaves 0  
fill ~3 ~17 ~41 ~5 ~17 ~41 leaves 4  
fill ~3 ~17 ~43 ~5 ~17 ~43 leaves 4  
fill ~3 ~17 ~44 ~5 ~17 ~44 leaves 0  
fill ~4 ~17 ~57 ~4 ~17 ~59 leaves 4  
fill ~6 ~17 ~49 ~6 ~14 ~49 leaves 4  
fill ~6 ~17 ~50 ~6 ~17 ~49 leaves 4  
fill ~7 ~17 ~71 ~7 ~19 ~71 lime_glazed_terracotta 0 
fill ~7 ~17 ~77 ~7 ~18 ~77 lime_glazed_terracotta 0  
fill ~9 ~17 ~59 ~102 ~17 ~59 stone 0  
fill ~9 ~17 ~60 ~102 ~17 ~60 stone 0  
fill ~9 ~17 ~61 ~102 ~17 ~61 stone 0  
fill ~9 ~17 ~62 ~101 ~17 ~62 stone 0  
fill ~9 ~17 ~63 ~101 ~17 ~63 stone 0  
fill ~9 ~17 ~64 ~101 ~17 ~64 stone 0  
fill ~10 ~17 ~54 ~102 ~17 ~54 stone 0  
fill ~10 ~17 ~55 ~102 ~17 ~55 stone 0  
fill ~10 ~17 ~56 ~102 ~17 ~56 stone 0  
fill ~10 ~17 ~57 ~102 ~17 ~57 stone 0  
fill ~10 ~17 ~58 ~102 ~17 ~58 stone 0  
fill ~10 ~17 ~65 ~101 ~17 ~65 stone 0  
fill ~10 ~17 ~66 ~101 ~17 ~66 stone 0  
fill ~11 ~17 ~53 ~102 ~17 ~53 stone 0  
fill ~11 ~17 ~67 ~100 ~17 ~67 stone 0  
fill ~11 ~17 ~68 ~100 ~17 ~68 stone 0  
fill ~12 ~17 ~51 ~102 ~17 ~51 stone 0  
fill ~12 ~17 ~52 ~102 ~17 ~52 stone 0  
fill ~12 ~17 ~69 ~100 ~17 ~69 stone 0  
fill ~12 ~17 ~70 ~99 ~17 ~70 stone 0  
fill ~13 ~17 ~46 ~101 ~17 ~46 stone 0  
fill ~13 ~17 ~47 ~102 ~17 ~47 stone 0  
fill ~13 ~17 ~48 ~102 ~17 ~48 stone 0  
fill ~13 ~17 ~49 ~102 ~17 ~49 stone 0  
fill ~13 ~17 ~50 ~102 ~17 ~50 stone 0  
fill ~13 ~17 ~71 ~99 ~17 ~71 stone 0  
fill ~13 ~17 ~72 ~99 ~17 ~72 stone 0  
fill ~14 ~17 ~42 ~15 ~17 ~42 stone 0  
fill ~14 ~17 ~43 ~101 ~17 ~43 stone 0  
fill ~14 ~17 ~44 ~101 ~17 ~44 stone 0  
fill ~14 ~17 ~45 ~101 ~17 ~45 stone 0  
fill ~14 ~17 ~73 ~98 ~17 ~73 stone 0  
fill ~14 ~17 ~74 ~98 ~17 ~74 stone 0 
setblock ~14 ~17 ~77 chorus_flower 0  
fill ~15 ~17 ~39 ~16 ~17 ~39 stone 0  
fill ~15 ~17 ~40 ~16 ~17 ~40 stone 0  
fill ~15 ~17 ~41 ~16 ~17 ~41 stone 0  
fill ~15 ~17 ~75 ~97 ~17 ~75 stone 0  
fill ~16 ~17 ~19 ~88 ~17 ~19 stone 0  
fill ~16 ~17 ~20 ~16 ~36 ~20 stone 0  
fill ~16 ~17 ~35 ~98 ~17 ~35 stone 0  
fill ~16 ~17 ~36 ~99 ~17 ~36 stone 0  
fill ~16 ~17 ~37 ~99 ~17 ~37 stone 0 
setblock ~16 ~17 ~42 double_stone_slab 3  
fill ~16 ~17 ~76 ~97 ~17 ~76 stone 0  
fill ~17 ~17 ~18 ~22 ~17 ~18 stone 0  
fill ~17 ~17 ~31 ~96 ~17 ~31 stone 0  
fill ~17 ~17 ~32 ~97 ~17 ~32 stone 0  
fill ~17 ~17 ~33 ~97 ~17 ~33 stone 0  
fill ~17 ~17 ~34 ~98 ~17 ~34 stone 0 
setblock ~17 ~17 ~42 stone_slab 3  
fill ~17 ~17 ~77 ~96 ~17 ~77 stone 0  
fill ~18 ~17 ~17 ~22 ~17 ~17 stone 0  
fill ~18 ~17 ~27 ~94 ~17 ~27 stone 0  
fill ~18 ~17 ~28 ~95 ~17 ~28 stone 0  
fill ~18 ~17 ~29 ~95 ~17 ~29 stone 0  
fill ~18 ~17 ~30 ~96 ~17 ~30 stone 0  
fill ~18 ~17 ~38 ~99 ~17 ~38 stone 0  
fill ~18 ~17 ~39 ~100 ~17 ~39 stone 0  
fill ~18 ~17 ~40 ~100 ~17 ~40 stone 0  
fill ~18 ~17 ~41 ~100 ~17 ~41 stone 0  
fill ~18 ~17 ~42 ~101 ~17 ~42 stone 0  
fill ~18 ~17 ~78 ~96 ~17 ~78 stone 0  
fill ~18 ~17 ~79 ~95 ~17 ~79 stone 0  
fill ~18 ~17 ~80 ~95 ~17 ~80 stone 0  
fill ~19 ~17 ~16 ~23 ~17 ~16 stone 0  
fill ~19 ~17 ~26 ~94 ~17 ~26 stone 0  
fill ~20 ~17 ~15 ~84 ~17 ~15 stone 0  
fill ~20 ~17 ~24 ~92 ~17 ~24 stone 0  
fill ~20 ~17 ~25 ~93 ~17 ~25 stone 0  
fill ~20 ~17 ~81 ~94 ~17 ~81 stone 0  
fill ~21 ~17 ~20 ~89 ~17 ~20 stone 0  
fill ~21 ~17 ~23 ~91 ~17 ~23 stone 0  
fill ~21 ~17 ~82 ~94 ~17 ~82 stone 0  
fill ~21 ~17 ~83 ~93 ~17 ~83 stone 0  
fill ~22 ~17 ~14 ~82 ~17 ~14 stone 0  
fill ~22 ~17 ~21 ~90 ~17 ~21 stone 0  
fill ~22 ~17 ~22 ~91 ~17 ~22 stone 0  
fill ~23 ~17 ~13 ~81 ~17 ~13 stone 0  
fill ~23 ~17 ~17 ~25 ~17 ~17 stone 5  
fill ~23 ~17 ~18 ~24 ~17 ~18 stone 5  
fill ~23 ~17 ~84 ~92 ~17 ~84 stone 0  
fill ~23 ~17 ~92 ~25 ~17 ~92 end_stone 0  
fill ~23 ~17 ~93 ~23 ~18 ~93 end_stone 0  
fill ~24 ~17 ~12 ~80 ~17 ~12 stone 0  
fill ~24 ~17 ~16 ~25 ~17 ~16 stone 5  
fill ~24 ~17 ~85 ~91 ~17 ~85 stone 0  
fill ~24 ~17 ~86 ~91 ~17 ~86 stone 0  
fill ~24 ~17 ~91 ~25 ~17 ~91 end_stone 0 
setblock ~24 ~17 ~93 end_bricks 0  
fill ~25 ~17 ~18 ~87 ~17 ~18 stone 0  
fill ~26 ~17 ~11 ~78 ~17 ~11 stone 0  
fill ~26 ~17 ~16 ~85 ~17 ~16 stone 0  
fill ~26 ~17 ~17 ~86 ~17 ~17 stone 0  
fill ~26 ~17 ~87 ~90 ~17 ~87 stone 0  
fill ~27 ~17 ~88 ~89 ~17 ~88 stone 0  
fill ~27 ~17 ~89 ~88 ~17 ~89 stone 0  
fill ~28 ~17 ~10 ~76 ~17 ~10 stone 0  
fill ~28 ~17 ~96 ~29 ~17 ~96 grass 0  
fill ~28 ~17 ~97 ~28 ~17 ~98 grass 0  
fill ~29 ~17 ~90 ~87 ~17 ~90 stone 0  
fill ~29 ~17 ~95 ~30 ~17 ~95 grass 0  
fill ~29 ~17 ~97 ~30 ~17 ~97 farmland 0 
setblock ~29 ~17 ~98 grass 0  
fill ~30 ~17 ~9 ~74 ~17 ~9 stone 0  
fill ~30 ~17 ~91 ~32 ~17 ~91 grass 0  
fill ~30 ~17 ~96 ~39 ~17 ~96 farmland 0  
fill ~30 ~17 ~98 ~39 ~17 ~98 farmland 0  
fill ~30 ~17 ~99 ~31 ~17 ~99 grass 0  
fill ~31 ~17 ~92 ~33 ~17 ~92 grass 0  
fill ~31 ~17 ~93 ~31 ~17 ~94 grass 0  
fill ~31 ~17 ~95 ~38 ~17 ~95 farmland 0  
fill ~31 ~17 ~97 ~37 ~17 ~97 water 0  
fill ~32 ~17 ~8 ~72 ~17 ~8 stone 0  
fill ~32 ~17 ~93 ~36 ~17 ~93 farmland 0  
fill ~32 ~17 ~94 ~37 ~17 ~94 farmland 0  
fill ~32 ~17 ~99 ~39 ~17 ~99 farmland 0  
fill ~32 ~17 ~100 ~33 ~17 ~100 grass 0  
fill ~33 ~17 ~91 ~86 ~17 ~91 stone 0  
fill ~34 ~17 ~7 ~70 ~17 ~7 stone 0  
