setblock ~3~0~0 minecraft:fence 0
setblock ~3~1~0 minecraft:glowstone
fill ~15~16~0 ~17~18~0 minecraft:quartz_block 0
setblock ~16~14~0 minecraft:quartz_block 0
fill ~20~18~0 ~23~18~0 minecraft:quartz_block 0
fill ~22~16~0 ~23~16~0 minecraft:quartz_block 0
fill ~23~14~0 ~23~15~0 minecraft:quartz_block 0
setblock ~23~17~0 minecraft:quartz_block 0
fill ~25~14~0 ~27~14~0 minecraft:quartz_block 0
fill ~25~18~0 ~27~18~0 minecraft:quartz_block 0
fill ~26~16~0 ~28~16~0 minecraft:quartz_block 0
setblock ~28~15~0 minecraft:quartz_block 0
setblock ~28~17~0 minecraft:quartz_block 0
fill ~30~14~0 ~32~14~0 minecraft:quartz_block 0
fill ~30~18~0 ~32~18~0 minecraft:quartz_block 0
fill ~31~16~0 ~33~16~0 minecraft:quartz_block 0
setblock ~33~15~0 minecraft:quartz_block 0
setblock ~33~17~0 minecraft:quartz_block 0
fill ~35~14~0 ~36~14~0 minecraft:quartz_block 0
fill ~37~15~0 ~37~18~0 minecraft:quartz_block 0
setblock ~39~17~0 minecraft:quartz_block 0
fill ~40~16~0 ~42~16~0 minecraft:quartz_block 0
fill ~40~18~0 ~42~18~0 minecraft:quartz_block 0
fill ~42~14~0 ~42~15~0 minecraft:quartz_block 0
setblock ~42~17~0 minecraft:quartz_block 0
setblock ~44~15~0 minecraft:quartz_block 0
fill ~44~18~0 ~46~18~0 minecraft:quartz_block 0
fill ~45~14~0 ~47~14~0 minecraft:quartz_block 0
fill ~45~16~0 ~46~16~0 minecraft:quartz_block 0
setblock ~47~17~0 minecraft:quartz_block 0
setblock ~55~0~0 minecraft:fence 0
setblock ~55~1~0 minecraft:glowstone
fill ~3~0~1 ~8~1~1 minecraft:quartz_block 0
setblock ~3~2~1 minecraft:quartz_stairs 0
fill ~4~2~1 ~7~2~1 minecraft:quartz_stairs 2
fill ~8~2~1 ~8~2~3 minecraft:quartz_stairs 1
fill ~10~13~1 ~48~13~2 minecraft:wool 15
fill ~10~14~1 ~48~19~1 minecraft:wool 15
fill ~50~0~1 ~55~1~1 minecraft:quartz_block 0
fill ~50~2~1 ~54~2~1 minecraft:quartz_stairs 2
setblock ~55~2~1 minecraft:quartz_stairs 1
fill ~3~2~2 ~7~2~2 minecraft:quartz_block 0
fill ~3~3~2 ~3~4~2 minecraft:quartz_block 0
fill ~7~3~2 ~7~4~2 minecraft:quartz_block 0
fill ~8~0~2 ~8~1~4 minecraft:quartz_block 0
fill ~10~19~2 ~48~19~2 minecraft:wool 15
fill ~11~14~2 ~14~14~2 minecraft:quartz_stairs 3
fill ~11~18~2 ~11~18~4 minecraft:fence 0
fill ~14~18~2 ~14~18~4 minecraft:fence 0
fill ~19~14~2 ~22~14~2 minecraft:quartz_stairs 3
fill ~19~18~2 ~19~18~4 minecraft:fence 0
fill ~22~18~2 ~22~18~4 minecraft:fence 0
fill ~25~0~2 ~25~0~3 minecraft:quartz_stairs 0
fill ~25~14~2 ~28~14~2 minecraft:quartz_stairs 3
fill ~25~18~2 ~25~18~4 minecraft:fence 0
fill ~26~0~2 ~27~0~2 minecraft:quartz_stairs 2
fill ~28~0~2 ~28~0~3 minecraft:quartz_stairs 1
fill ~28~18~2 ~28~18~4 minecraft:fence 0
fill ~30~0~2 ~30~0~3 minecraft:quartz_stairs 0
fill ~30~14~2 ~33~14~2 minecraft:quartz_stairs 3
fill ~30~18~2 ~30~18~4 minecraft:fence 0
fill ~31~0~2 ~33~0~2 minecraft:quartz_stairs 2
fill ~33~18~2 ~33~18~4 minecraft:fence 0
fill ~36~14~2 ~39~14~2 minecraft:quartz_stairs 3
fill ~36~18~2 ~36~18~4 minecraft:fence 0
fill ~39~18~2 ~39~18~4 minecraft:fence 0
fill ~44~14~2 ~47~14~2 minecraft:quartz_stairs 3
fill ~44~18~2 ~44~18~4 minecraft:fence 0
fill ~47~18~2 ~47~18~4 minecraft:fence 0
fill ~50~0~2 ~50~1~4 minecraft:quartz_block 0
fill ~50~2~2 ~50~2~3 minecraft:quartz_stairs 0
fill ~51~2~2 ~55~2~2 minecraft:quartz_block 0
fill ~51~3~2 ~51~5~2 minecraft:quartz_block 0
fill ~55~3~2 ~55~5~2 minecraft:quartz_block 0
setblock ~0~0~3 minecraft:fence 0
setblock ~0~1~3 minecraft:glowstone
fill ~1~0~3 ~1~1~8 minecraft:quartz_block 0
setblock ~1~2~3 minecraft:quartz_stairs 2
fill ~2~2~3 ~2~2~7 minecraft:quartz_block 0
fill ~2~3~3 ~2~4~3 minecraft:quartz_block 0
setblock ~3~2~3 minecraft:glowstone
fill ~4~2~3 ~7~2~3 minecraft:quartz_block 0
setblock ~5~14~3 minecraft:quartz_stairs 6
fill ~5~15~3 ~5~16~4 minecraft:quartz_block 0
fill ~5~17~3 ~5~20~3 minecraft:quartz_block 0
setblock ~8~14~3 minecraft:quartz_stairs 6
fill ~8~15~3 ~8~16~4 minecraft:quartz_block 0
fill ~8~17~3 ~8~20~3 minecraft:quartz_block 0
fill ~10~12~3 ~48~12~3 minecraft:wool 15
fill ~10~20~3 ~48~20~3 minecraft:glass
fill ~11~13~3 ~14~13~3 minecraft:quartz_stairs 3
fill ~19~13~3 ~22~13~3 minecraft:quartz_stairs 3
fill ~25~13~3 ~28~13~3 minecraft:quartz_stairs 3
fill ~26~0~3 ~27~0~4 minecraft:quartz_block 0
fill ~26~1~3 ~27~1~3 minecraft:quartz_stairs 2
fill ~30~13~3 ~33~13~3 minecraft:quartz_stairs 3
fill ~31~0~3 ~32~0~4 minecraft:quartz_block 0
fill ~31~1~3 ~32~1~3 minecraft:quartz_stairs 2
setblock ~33~0~3 minecraft:quartz_stairs 1
fill ~36~13~3 ~39~13~3 minecraft:quartz_stairs 3
fill ~44~13~3 ~47~13~3 minecraft:quartz_stairs 3
setblock ~50~14~3 minecraft:quartz_stairs 6
fill ~50~15~3 ~50~16~4 minecraft:quartz_block 0
fill ~50~17~3 ~50~20~3 minecraft:quartz_block 0
fill ~51~2~3 ~54~2~3 minecraft:quartz_block 0
setblock ~53~14~3 minecraft:quartz_stairs 6
fill ~53~15~3 ~53~16~4 minecraft:quartz_block 0
fill ~53~17~3 ~53~20~3 minecraft:quartz_block 0
setblock ~55~2~3 minecraft:glowstone
fill ~56~2~3 ~56~2~7 minecraft:quartz_block 0
fill ~56~3~3 ~56~5~3 minecraft:quartz_block 0
fill ~57~0~3 ~57~1~8 minecraft:quartz_block 0
setblock ~57~2~3 minecraft:quartz_stairs 2
setblock ~58~0~3 minecraft:fence 0
setblock ~58~1~3 minecraft:glowstone
fill ~1~2~4 ~1~2~7 minecraft:quartz_stairs 0
fill ~3~2~4 ~3~2~7 minecraft:quartz_block 0
setblock ~4~2~4 minecraft:glowstone
fill ~5~0~4 ~5~10~5 minecraft:quartz_block 0
fill ~5~11~4 ~8~11~4 minecraft:quartz_block 0
fill ~5~12~4 ~5~14~4 minecraft:quartz_block 0
fill ~5~17~4 ~8~17~4 minecraft:glass
setblock ~6~0~4 minecraft:wool 4
setblock ~6~1~4 minecraft:quartz_block 0
setblock ~6~2~4 minecraft:wool 4
fill ~6~3~4 ~8~3~4 minecraft:quartz_block 0
fill ~6~4~4 ~7~4~4 minecraft:wool 4
fill ~6~5~4 ~8~5~4 minecraft:quartz_block 0
fill ~6~6~4 ~7~6~4 minecraft:wool 4
fill ~6~7~4 ~8~7~4 minecraft:quartz_block 0
fill ~6~8~4 ~7~8~4 minecraft:wool 4
fill ~6~9~4 ~8~9~4 minecraft:quartz_block 0
fill ~6~10~4 ~7~10~4 minecraft:wool 4
fill ~6~12~4 ~7~12~4 minecraft:wool 4
fill ~6~13~4 ~8~13~4 minecraft:quartz_block 0
fill ~6~14~4 ~7~14~4 minecraft:wool 4
fill ~6~15~4 ~7~15~4 minecraft:quartz_block 0
fill ~6~16~4 ~7~16~4 minecraft:wool 4
fill ~7~2~4 ~8~2~4 minecraft:quartz_block 0
setblock ~8~4~4 minecraft:quartz_block 0
setblock ~8~6~4 minecraft:quartz_block 0
setblock ~8~8~4 minecraft:quartz_block 0
setblock ~8~10~4 minecraft:quartz_block 0
setblock ~8~12~4 minecraft:quartz_block 0
setblock ~8~14~4 minecraft:quartz_block 0
fill ~9~0~4 ~25~1~4 minecraft:quartz_block 0
fill ~10~2~4 ~10~7~4 minecraft:quartz_block 0
setblock ~10~8~4 minecraft:quartz_stairs 0
fill ~10~11~4 ~48~11~4 minecraft:wool 15
fill ~10~21~4 ~48~21~4 minecraft:glass
setblock ~11~8~4 minecraft:quartz_stairs 5
setblock ~11~9~4 minecraft:quartz_stairs 0
fill ~11~12~4 ~14~12~4 minecraft:quartz_stairs 3
setblock ~11~16~4 minecraft:glowstone
setblock ~11~17~4 minecraft:fence 0
setblock ~12~9~4 minecraft:glowstone
setblock ~12~10~4 minecraft:quartz_block 0
setblock ~13~8~4 minecraft:quartz_stairs 4
setblock ~13~9~4 minecraft:quartz_stairs 1
fill ~14~2~4 ~14~7~4 minecraft:quartz_block 0
setblock ~14~8~4 minecraft:glowstone
setblock ~14~16~4 minecraft:glowstone
setblock ~14~17~4 minecraft:fence 0
setblock ~15~8~4 minecraft:quartz_stairs 5
setblock ~15~9~4 minecraft:quartz_stairs 0
setblock ~16~9~4 minecraft:quartz_stairs 5
setblock ~16~10~4 minecraft:quartz_stairs 0
setblock ~17~9~4 minecraft:quartz_stairs 4
setblock ~17~10~4 minecraft:quartz_stairs 1
setblock ~18~8~4 minecraft:quartz_stairs 4
setblock ~18~9~4 minecraft:quartz_stairs 1
fill ~19~2~4 ~19~7~4 minecraft:quartz_block 0
setblock ~19~8~4 minecraft:glowstone
fill ~19~12~4 ~22~12~4 minecraft:quartz_stairs 3
setblock ~19~16~4 minecraft:glowstone
setblock ~19~17~4 minecraft:fence 0
setblock ~20~8~4 minecraft:quartz_stairs 5
setblock ~20~9~4 minecraft:quartz_stairs 0
setblock ~21~9~4 minecraft:quartz_stairs 5
setblock ~21~10~4 minecraft:quartz_stairs 0
setblock ~22~9~4 minecraft:quartz_stairs 4
setblock ~22~10~4 minecraft:quartz_stairs 1
setblock ~22~16~4 minecraft:glowstone
setblock ~22~17~4 minecraft:fence 0
setblock ~23~8~4 minecraft:quartz_stairs 4
setblock ~23~9~4 minecraft:quartz_stairs 1
fill ~24~2~4 ~24~7~4 minecraft:quartz_block 0
setblock ~24~8~4 minecraft:glowstone
setblock ~25~8~4 minecraft:quartz_stairs 5
setblock ~25~9~4 minecraft:quartz_stairs 0
fill ~25~12~4 ~28~12~4 minecraft:quartz_stairs 3
setblock ~25~16~4 minecraft:glowstone
setblock ~25~17~4 minecraft:fence 0
fill ~26~1~4 ~49~1~4 minecraft:quartz_block 0
fill ~26~2~4 ~27~2~4 minecraft:quartz_stairs 2
setblock ~26~9~4 minecraft:quartz_stairs 5
setblock ~26~10~4 minecraft:quartz_stairs 0
setblock ~27~9~4 minecraft:quartz_stairs 4
setblock ~27~10~4 minecraft:quartz_stairs 1
fill ~28~0~4 ~30~0~4 minecraft:quartz_block 0
setblock ~28~8~4 minecraft:quartz_stairs 4
setblock ~28~9~4 minecraft:quartz_stairs 1
setblock ~28~16~4 minecraft:glowstone
setblock ~28~17~4 minecraft:fence 0
fill ~29~2~4 ~29~7~4 minecraft:quartz_block 0
setblock ~29~8~4 minecraft:glowstone
setblock ~30~8~4 minecraft:quartz_stairs 5
setblock ~30~9~4 minecraft:quartz_stairs 0
fill ~30~12~4 ~33~12~4 minecraft:quartz_stairs 3
setblock ~30~16~4 minecraft:glowstone
setblock ~30~17~4 minecraft:fence 0
fill ~31~2~4 ~32~2~4 minecraft:quartz_stairs 2
setblock ~31~9~4 minecraft:quartz_stairs 5
setblock ~31~10~4 minecraft:quartz_stairs 0
setblock ~32~9~4 minecraft:quartz_stairs 4
setblock ~32~10~4 minecraft:quartz_stairs 1
fill ~33~0~4 ~49~0~4 minecraft:quartz_block 0
setblock ~33~8~4 minecraft:quartz_stairs 4
setblock ~33~9~4 minecraft:quartz_stairs 1
setblock ~33~16~4 minecraft:glowstone
setblock ~33~17~4 minecraft:fence 0
fill ~34~2~4 ~34~7~4 minecraft:quartz_block 0
setblock ~34~8~4 minecraft:glowstone
setblock ~35~8~4 minecraft:quartz_stairs 5
setblock ~35~9~4 minecraft:quartz_stairs 0
setblock ~36~9~4 minecraft:quartz_stairs 5
setblock ~36~10~4 minecraft:quartz_stairs 0
fill ~36~12~4 ~39~12~4 minecraft:quartz_stairs 3
setblock ~36~16~4 minecraft:glowstone
setblock ~36~17~4 minecraft:fence 0
setblock ~37~9~4 minecraft:quartz_stairs 4
setblock ~37~10~4 minecraft:quartz_stairs 1
setblock ~38~8~4 minecraft:quartz_stairs 4
setblock ~38~9~4 minecraft:quartz_stairs 1
fill ~39~2~4 ~39~7~4 minecraft:quartz_block 0
setblock ~39~8~4 minecraft:glowstone
setblock ~39~16~4 minecraft:glowstone
setblock ~39~17~4 minecraft:fence 0
setblock ~40~8~4 minecraft:quartz_stairs 5
setblock ~40~9~4 minecraft:quartz_stairs 0
setblock ~41~9~4 minecraft:quartz_stairs 5
setblock ~41~10~4 minecraft:quartz_stairs 0
setblock ~42~9~4 minecraft:quartz_stairs 4
setblock ~42~10~4 minecraft:quartz_stairs 1
setblock ~43~8~4 minecraft:quartz_stairs 4
setblock ~43~9~4 minecraft:quartz_stairs 1
fill ~44~2~4 ~44~7~4 minecraft:quartz_block 0
setblock ~44~8~4 minecraft:glowstone
fill ~44~12~4 ~47~12~4 minecraft:quartz_stairs 3
setblock ~44~16~4 minecraft:glowstone
setblock ~44~17~4 minecraft:fence 0
setblock ~45~8~4 minecraft:quartz_stairs 5
setblock ~45~9~4 minecraft:quartz_stairs 0
setblock ~46~9~4 minecraft:glowstone
setblock ~46~10~4 minecraft:quartz_block 0
setblock ~47~8~4 minecraft:quartz_stairs 4
setblock ~47~9~4 minecraft:quartz_stairs 1
setblock ~47~16~4 minecraft:glowstone
setblock ~47~17~4 minecraft:fence 0
fill ~48~2~4 ~48~7~4 minecraft:quartz_block 0
setblock ~48~8~4 minecraft:quartz_stairs 1
fill ~50~2~4 ~50~14~4 minecraft:quartz_block 0
fill ~50~17~4 ~53~17~4 minecraft:glass
fill ~51~3~4 ~53~3~4 minecraft:quartz_block 0
fill ~51~4~4 ~52~4~4 minecraft:wool 11
fill ~51~5~4 ~53~5~4 minecraft:quartz_block 0
fill ~51~6~4 ~52~6~4 minecraft:wool 11
fill ~51~7~4 ~53~7~4 minecraft:quartz_block 0
fill ~51~8~4 ~52~8~4 minecraft:wool 11
fill ~51~9~4 ~53~9~4 minecraft:quartz_block 0
fill ~51~10~4 ~52~10~4 minecraft:wool 11
fill ~51~11~4 ~53~11~4 minecraft:quartz_block 0
fill ~51~12~4 ~52~12~4 minecraft:wool 11
fill ~51~13~4 ~53~13~4 minecraft:quartz_block 0
fill ~51~14~4 ~52~14~4 minecraft:wool 11
fill ~51~15~4 ~52~15~4 minecraft:quartz_block 0
fill ~51~16~4 ~52~16~4 minecraft:wool 11
fill ~52~0~4 ~53~1~4 minecraft:quartz_block 0
setblock ~52~2~4 minecraft:wool 11
fill ~53~2~4 ~53~2~5 minecraft:quartz_block 0
fill ~53~4~4 ~53~4~5 minecraft:quartz_block 0
fill ~53~6~4 ~53~6~5 minecraft:quartz_block 0
fill ~53~8~4 ~53~8~5 minecraft:quartz_block 0
fill ~53~10~4 ~53~10~5 minecraft:quartz_block 0
setblock ~53~12~4 minecraft:quartz_block 0
setblock ~53~14~4 minecraft:quartz_block 0
setblock ~54~2~4 minecraft:glowstone
fill ~55~2~4 ~55~2~7 minecraft:quartz_block 0
fill ~57~2~4 ~57~2~7 minecraft:quartz_stairs 1
setblock ~3~14~5 minecraft:quartz_stairs 4
fill ~3~15~5 ~4~16~5 minecraft:quartz_block 0
fill ~3~17~5 ~3~20~5 minecraft:quartz_block 0
fill ~4~0~5 ~4~14~5 minecraft:quartz_block 0
fill ~4~17~5 ~4~17~8 minecraft:glass
fill ~5~18~5 ~8~18~5 minecraft:glass
fill ~6~0~5 ~6~10~5 minecraft:ladder 5
fill ~7~11~5 ~9~11~10 minecraft:quartz_block 0
setblock ~8~12~5 minecraft:chest 4
fill ~9~0~5 ~9~1~9 minecraft:quartz_block 0
fill ~9~2~5 ~9~10~5 minecraft:quartz_block 0
fill ~9~12~5 ~9~15~6 minecraft:quartz_block 0
setblock ~9~16~5 minecraft:quartz_block 0
fill ~9~17~5 ~9~17~8 minecraft:glass
fill ~10~10~5 ~48~10~5 minecraft:wool 15
fill ~10~22~5 ~48~22~5 minecraft:glass
fill ~14~1~5 ~14~1~13 minecraft:quartz_block 0
fill ~19~1~5 ~19~1~13 minecraft:quartz_block 0
fill ~24~1~5 ~24~1~13 minecraft:quartz_block 0
fill ~26~2~5 ~27~2~5 minecraft:quartz_block 0
fill ~26~3~5 ~27~3~5 minecraft:quartz_stairs 2
fill ~28~2~5 ~28~3~6 minecraft:fence 0
fill ~29~1~5 ~29~1~13 minecraft:quartz_block 0
fill ~30~2~5 ~30~3~6 minecraft:fence 0
fill ~31~2~5 ~32~2~5 minecraft:quartz_block 0
fill ~31~3~5 ~32~3~5 minecraft:quartz_stairs 2
fill ~34~1~5 ~34~1~13 minecraft:quartz_block 0
fill ~39~1~5 ~39~1~13 minecraft:quartz_block 0
fill ~44~1~5 ~44~1~13 minecraft:quartz_block 0
fill ~49~0~5 ~49~1~8 minecraft:quartz_block 0
fill ~49~2~5 ~49~16~5 minecraft:quartz_block 0
fill ~49~17~5 ~49~17~8 minecraft:glass
fill ~50~11~5 ~51~11~10 minecraft:quartz_block 0
setblock ~50~12~5 minecraft:chest 5
fill ~50~18~5 ~53~18~5 minecraft:glass
fill ~52~0~5 ~52~10~5 minecraft:ladder 4
fill ~53~0~5 ~54~1~5 minecraft:quartz_block 0
fill ~53~3~5 ~54~3~5 minecraft:quartz_block 0
fill ~53~5~5 ~54~5~5 minecraft:quartz_block 0
fill ~53~7~5 ~54~7~5 minecraft:quartz_block 0
fill ~53~9~5 ~54~9~5 minecraft:quartz_block 0
setblock ~54~2~5 minecraft:quartz_block 0
setblock ~54~4~5 minecraft:quartz_block 0
setblock ~54~6~5 minecraft:quartz_block 0
setblock ~54~8~5 minecraft:quartz_block 0
fill ~54~10~5 ~54~16~5 minecraft:quartz_block 0
fill ~54~17~5 ~54~17~8 minecraft:glass
setblock ~55~14~5 minecraft:quartz_stairs 5
fill ~55~15~5 ~55~20~5 minecraft:quartz_block 0
setblock ~4~0~6 minecraft:wool 4
setblock ~4~1~6 minecraft:quartz_block 0
setblock ~4~2~6 minecraft:wool 4
fill ~4~3~6 ~4~3~8 minecraft:quartz_block 0
fill ~4~4~6 ~4~4~7 minecraft:wool 4
fill ~4~5~6 ~4~5~8 minecraft:quartz_block 0
fill ~4~6~6 ~4~6~7 minecraft:wool 4
fill ~4~7~6 ~4~7~8 minecraft:quartz_block 0
fill ~4~8~6 ~4~8~7 minecraft:wool 4
fill ~4~9~6 ~4~9~8 minecraft:quartz_block 0
fill ~4~10~6 ~4~10~7 minecraft:wool 4
fill ~4~11~6 ~4~11~8 minecraft:quartz_block 0
fill ~4~12~6 ~4~12~7 minecraft:wool 4
fill ~4~13~6 ~4~13~8 minecraft:quartz_block 0
fill ~4~14~6 ~4~14~7 minecraft:wool 4
fill ~4~15~6 ~4~15~8 minecraft:quartz_block 0
fill ~4~16~6 ~4~16~7 minecraft:wool 4
fill ~5~0~6 ~5~10~6 minecraft:ladder 3
fill ~5~18~6 ~5~18~8 minecraft:glass
fill ~6~11~6 ~6~11~9 minecraft:quartz_block 0
fill ~6~18~6 ~7~18~7 minecraft:glowstone
fill ~6~19~6 ~7~19~7 minecraft:glass
fill ~8~18~6 ~8~18~8 minecraft:glass
fill ~9~2~6 ~9~2~7 minecraft:wool 4
fill ~9~3~6 ~9~3~8 minecraft:quartz_block 0
fill ~9~4~6 ~9~4~7 minecraft:wool 4
fill ~9~5~6 ~9~5~8 minecraft:quartz_block 0
fill ~9~6~6 ~9~6~7 minecraft:wool 4
fill ~9~7~6 ~9~7~8 minecraft:quartz_block 0
fill ~9~8~6 ~9~8~7 minecraft:wool 4
fill ~9~9~6 ~9~9~8 minecraft:quartz_block 0
fill ~9~10~6 ~9~10~7 minecraft:wool 4
fill ~9~16~6 ~9~16~7 minecraft:wool 4
fill ~10~10~6 ~15~11~6 minecraft:fence 0
fill ~10~23~6 ~48~23~6 minecraft:glass
fill ~16~10~6 ~17~10~8 minecraft:quartz_block 0
fill ~18~10~6 ~40~11~6 minecraft:fence 0
fill ~26~3~6 ~27~3~6 minecraft:quartz_block 0
fill ~26~4~6 ~27~4~6 minecraft:quartz_stairs 2
fill ~28~4~6 ~28~5~9 minecraft:fence 0
fill ~30~4~6 ~30~5~9 minecraft:fence 0
fill ~31~3~6 ~32~3~6 minecraft:quartz_block 0
fill ~31~4~6 ~32~4~6 minecraft:quartz_stairs 2
fill ~41~10~6 ~42~10~8 minecraft:quartz_block 0
fill ~43~10~6 ~48~11~6 minecraft:fence 0
fill ~49~2~6 ~49~2~7 minecraft:wool 11
fill ~49~3~6 ~49~3~8 minecraft:quartz_block 0
fill ~49~4~6 ~49~4~7 minecraft:wool 11
fill ~49~5~6 ~49~5~8 minecraft:quartz_block 0
fill ~49~6~6 ~49~6~7 minecraft:wool 11
fill ~49~7~6 ~49~7~8 minecraft:quartz_block 0
fill ~49~8~6 ~49~8~7 minecraft:wool 11
fill ~49~9~6 ~49~9~8 minecraft:quartz_block 0
fill ~49~10~6 ~49~10~7 minecraft:wool 11
fill ~49~11~6 ~49~11~10 minecraft:quartz_block 0
fill ~49~12~6 ~49~15~6 minecraft:quartz_block 0
fill ~49~16~6 ~49~16~7 minecraft:wool 11
fill ~50~18~6 ~50~18~8 minecraft:glass
fill ~51~18~6 ~52~18~7 minecraft:glowstone
fill ~51~19~6 ~52~19~7 minecraft:glass
fill ~52~11~6 ~52~11~9 minecraft:quartz_block 0
fill ~53~0~6 ~53~10~6 minecraft:ladder 3
fill ~53~18~6 ~53~18~8 minecraft:glass
fill ~54~0~6 ~54~1~6 minecraft:quartz_block 0
setblock ~54~2~6 minecraft:wool 11
fill ~54~3~6 ~54~3~8 minecraft:quartz_block 0
fill ~54~4~6 ~54~4~7 minecraft:wool 11
fill ~54~5~6 ~54~5~8 minecraft:quartz_block 0
fill ~54~6~6 ~54~6~7 minecraft:wool 11
fill ~54~7~6 ~54~7~8 minecraft:quartz_block 0
fill ~54~8~6 ~54~8~7 minecraft:wool 11
fill ~54~9~6 ~54~9~8 minecraft:quartz_block 0
fill ~54~10~6 ~54~10~7 minecraft:wool 11
fill ~54~11~6 ~54~11~8 minecraft:quartz_block 0
fill ~54~12~6 ~54~12~7 minecraft:wool 11
fill ~54~13~6 ~54~13~8 minecraft:quartz_block 0
fill ~54~14~6 ~54~14~7 minecraft:wool 11
fill ~54~15~6 ~54~15~8 minecraft:quartz_block 0
fill ~54~16~6 ~54~16~7 minecraft:wool 11
fill ~2~3~7 ~2~4~7 minecraft:quartz_block 0
fill ~4~2~7 ~4~2~8 minecraft:quartz_block 0
fill ~5~11~7 ~5~11~9 minecraft:quartz_block 0
setblock ~9~15~7 minecraft:quartz_block 0
fill ~10~11~7 ~10~11~10 minecraft:quartz_block 0
setblock ~10~12~7 minecraft:quartz_block 0
fill ~10~24~7 ~48~24~7 minecraft:glass
fill ~15~10~7 ~15~11~9 minecraft:fence 0
fill ~18~10~7 ~18~10~8 minecraft:quartz_block 0
fill ~19~9~7 ~19~9~8 minecraft:quartz_block 0
fill ~19~10~7 ~19~10~8 minecraft:quartz_stairs 1
fill ~20~8~7 ~20~8~8 minecraft:quartz_block 0
fill ~20~9~7 ~20~9~8 minecraft:quartz_stairs 1
fill ~21~7~7 ~21~7~8 minecraft:quartz_block 0
fill ~21~8~7 ~21~8~8 minecraft:quartz_stairs 1
fill ~22~6~7 ~22~6~8 minecraft:quartz_block 0
fill ~22~7~7 ~22~7~8 minecraft:quartz_stairs 1
fill ~23~5~7 ~23~5~8 minecraft:quartz_block 0
fill ~23~6~7 ~23~6~8 minecraft:quartz_stairs 1
fill ~24~4~7 ~27~4~8 minecraft:quartz_block 0
fill ~24~5~7 ~24~5~8 minecraft:quartz_stairs 1
fill ~31~4~7 ~34~4~8 minecraft:quartz_block 0
fill ~34~5~7 ~34~5~8 minecraft:quartz_stairs 0
fill ~35~5~7 ~35~5~8 minecraft:quartz_block 0
fill ~35~6~7 ~35~6~8 minecraft:quartz_stairs 0
fill ~36~6~7 ~36~6~8 minecraft:quartz_block 0
fill ~36~7~7 ~36~7~8 minecraft:quartz_stairs 0
fill ~37~7~7 ~37~7~8 minecraft:quartz_block 0
fill ~37~8~7 ~37~8~8 minecraft:quartz_stairs 0
fill ~38~8~7 ~38~8~8 minecraft:quartz_block 0
fill ~38~9~7 ~38~9~8 minecraft:quartz_stairs 0
fill ~39~9~7 ~39~9~8 minecraft:quartz_block 0
fill ~39~10~7 ~39~10~8 minecraft:quartz_stairs 0
fill ~40~10~7 ~40~10~8 minecraft:quartz_block 0
fill ~43~10~7 ~43~11~9 minecraft:fence 0
fill ~47~12~7 ~47~13~8 minecraft:fence 0
fill ~48~11~7 ~48~11~10 minecraft:quartz_block 0
setblock ~48~12~7 minecraft:quartz_block 0
fill ~49~15~7 ~49~15~8 minecraft:quartz_block 0
fill ~53~11~7 ~53~11~9 minecraft:quartz_block 0
fill ~56~3~7 ~56~5~7 minecraft:quartz_block 0
fill ~1~2~8 ~3~2~8 minecraft:quartz_stairs 3
fill ~2~0~8 ~4~1~8 minecraft:quartz_block 0
setblock ~3~14~8 minecraft:quartz_stairs 4
fill ~3~15~8 ~3~20~8 minecraft:quartz_block 0
setblock ~4~4~8 minecraft:quartz_block 0
setblock ~4~6~8 minecraft:quartz_block 0
setblock ~4~8~8 minecraft:quartz_block 0
setblock ~4~10~8 minecraft:quartz_block 0
setblock ~4~12~8 minecraft:quartz_block 0
setblock ~4~14~8 minecraft:quartz_block 0
setblock ~4~16~8 minecraft:quartz_block 0
setblock ~5~12~8 minecraft:chest 2
fill ~6~18~8 ~7~18~8 minecraft:glass
setblock ~8~10~8 minecraft:glowstone
setblock ~9~2~8 minecraft:quartz_block 0
setblock ~9~4~8 minecraft:quartz_block 0
setblock ~9~6~8 minecraft:quartz_block 0
setblock ~9~8~8 minecraft:quartz_block 0
setblock ~9~10~8 minecraft:quartz_block 0
setblock ~9~15~8 minecraft:quartz_stairs 7
setblock ~9~16~8 minecraft:quartz_block 0
fill ~10~12~8 ~10~12~9 minecraft:quartz_stairs 0
fill ~10~25~8 ~48~25~8 minecraft:glass
setblock ~11~12~8 minecraft:quartz_block 0
fill ~12~12~8 ~13~13~8 minecraft:fence 0
fill ~14~13~8 ~14~13~9 minecraft:fence 0
fill ~45~13~8 ~46~13~8 minecraft:fence 0
setblock ~46~12~8 minecraft:fence 0
fill ~48~12~8 ~48~12~10 minecraft:quartz_stairs 1
setblock ~49~2~8 minecraft:quartz_block 0
setblock ~49~4~8 minecraft:quartz_block 0
setblock ~49~6~8 minecraft:quartz_block 0
setblock ~49~8~8 minecraft:quartz_block 0
setblock ~49~10~8 minecraft:quartz_block 0
setblock ~49~16~8 minecraft:quartz_block 0
setblock ~50~10~8 minecraft:glowstone
fill ~51~18~8 ~52~18~8 minecraft:glass
setblock ~53~12~8 minecraft:chest 2
fill ~54~0~8 ~56~1~8 minecraft:quartz_block 0
setblock ~54~2~8 minecraft:quartz_block 0
setblock ~54~4~8 minecraft:quartz_block 0
setblock ~54~6~8 minecraft:quartz_block 0
setblock ~54~8~8 minecraft:quartz_block 0
setblock ~54~10~8 minecraft:quartz_block 0
setblock ~54~12~8 minecraft:quartz_block 0
setblock ~54~14~8 minecraft:quartz_block 0
fill ~54~16~8 ~55~16~8 minecraft:quartz_block 0
fill ~55~2~8 ~57~2~8 minecraft:quartz_stairs 3
setblock ~55~14~8 minecraft:quartz_stairs 5
setblock ~55~15~8 minecraft:quartz_block 0
fill ~55~17~8 ~55~20~8 minecraft:quartz_block 0
fill ~4~0~9 ~8~1~9 minecraft:quartz_block 0
fill ~5~2~9 ~5~10~9 minecraft:quartz_block 0
fill ~5~12~9 ~6~15~9 minecraft:quartz_block 0
setblock ~5~16~9 minecraft:quartz_block 0
fill ~5~17~9 ~8~17~9 minecraft:glass
fill ~6~2~9 ~7~2~9 minecraft:wool 4
fill ~6~3~9 ~8~3~9 minecraft:quartz_block 0
fill ~6~4~9 ~7~4~9 minecraft:wool 4
fill ~6~5~9 ~8~5~9 minecraft:quartz_block 0
fill ~6~6~9 ~7~6~9 minecraft:wool 4
fill ~6~7~9 ~8~7~9 minecraft:quartz_block 0
fill ~6~8~9 ~7~8~9 minecraft:wool 4
fill ~6~9~9 ~8~9~9 minecraft:quartz_block 0
fill ~6~10~9 ~7~10~9 minecraft:wool 4
fill ~6~16~9 ~7~16~9 minecraft:wool 4
setblock ~7~15~9 minecraft:quartz_block 0
setblock ~8~2~9 minecraft:quartz_block 0
setblock ~8~4~9 minecraft:quartz_block 0
setblock ~8~6~9 minecraft:quartz_block 0
setblock ~8~8~9 minecraft:quartz_block 0
setblock ~8~10~9 minecraft:quartz_block 0
setblock ~8~15~9 minecraft:quartz_stairs 5
setblock ~8~16~9 minecraft:quartz_block 0
fill ~9~2~9 ~49~2~9 minecraft:quartz_block 1
fill ~10~1~9 ~13~1~9 minecraft:quartz_block 0
fill ~10~26~9 ~48~26~44 minecraft:glass
fill ~11~12~9 ~13~12~9 minecraft:wool 4
setblock ~14~12~9 minecraft:fence 0
fill ~15~1~9 ~18~1~9 minecraft:quartz_block 0
fill ~15~13~9 ~15~13~10 minecraft:fence 0
fill ~16~10~9 ~20~10~9 minecraft:fence 0
fill ~16~11~9 ~19~11~9 minecraft:fence 0
fill ~19~9~9 ~21~9~9 minecraft:fence 0
fill ~20~1~9 ~23~1~9 minecraft:quartz_block 0
fill ~20~8~9 ~22~8~9 minecraft:fence 0
fill ~21~7~9 ~23~7~9 minecraft:fence 0
fill ~22~6~9 ~24~6~9 minecraft:fence 0
fill ~23~5~9 ~27~5~9 minecraft:fence 0
fill ~24~4~9 ~27~4~9 minecraft:fence 0
fill ~25~1~9 ~28~1~9 minecraft:quartz_block 0
setblock ~28~6~9 minecraft:fence 0
setblock ~28~7~9 minecraft:glowstone
fill ~30~1~9 ~33~1~9 minecraft:quartz_block 0
setblock ~30~6~9 minecraft:fence 0
setblock ~30~7~9 minecraft:glowstone
fill ~31~4~9 ~34~5~9 minecraft:fence 0
fill ~34~6~9 ~36~6~9 minecraft:fence 0
fill ~35~1~9 ~38~1~9 minecraft:quartz_block 0
setblock ~35~5~9 minecraft:fence 0
fill ~35~7~9 ~37~7~9 minecraft:fence 0
fill ~36~8~9 ~38~8~9 minecraft:fence 0
fill ~37~9~9 ~39~9~9 minecraft:fence 0
fill ~38~10~9 ~42~10~9 minecraft:fence 0
fill ~39~11~9 ~42~11~9 minecraft:fence 0
fill ~40~1~9 ~43~1~9 minecraft:quartz_block 0
fill ~44~13~9 ~45~13~9 minecraft:fence 0
fill ~45~1~9 ~54~1~9 minecraft:quartz_block 0
setblock ~45~12~9 minecraft:fence 0
fill ~46~12~9 ~47~12~9 minecraft:wool 11
fill ~50~0~9 ~54~0~9 minecraft:quartz_block 0
fill ~50~2~9 ~50~10~9 minecraft:quartz_block 0
fill ~50~15~9 ~53~15~9 minecraft:quartz_block 0
setblock ~50~16~9 minecraft:quartz_block 0
fill ~50~17~9 ~53~17~9 minecraft:glass
fill ~51~2~9 ~52~2~9 minecraft:wool 11
fill ~51~3~9 ~53~3~9 minecraft:quartz_block 0
fill ~51~4~9 ~52~4~9 minecraft:wool 11
fill ~51~5~9 ~53~5~9 minecraft:quartz_block 0
fill ~51~6~9 ~52~6~9 minecraft:wool 11
fill ~51~7~9 ~53~7~9 minecraft:quartz_block 0
fill ~51~8~9 ~52~8~9 minecraft:wool 11
fill ~51~9~9 ~53~9~9 minecraft:quartz_block 0
fill ~51~10~9 ~52~10~9 minecraft:wool 11
fill ~51~16~9 ~52~16~9 minecraft:wool 11
fill ~52~12~9 ~53~14~9 minecraft:quartz_block 0
setblock ~53~2~9 minecraft:quartz_block 0
setblock ~53~4~9 minecraft:quartz_block 0
setblock ~53~6~9 minecraft:quartz_block 0
setblock ~53~8~9 minecraft:quartz_block 0
setblock ~53~10~9 minecraft:quartz_block 0
setblock ~53~16~9 minecraft:quartz_block 0
fill ~1~13~10 ~2~13~43 minecraft:wool 15
fill ~1~14~10 ~1~19~43 minecraft:wool 15
fill ~2~19~10 ~2~19~43 minecraft:wool 15
fill ~3~12~10 ~3~12~43 minecraft:wool 15
fill ~3~20~10 ~3~20~43 minecraft:glass
fill ~4~0~10 ~4~1~45 minecraft:quartz_block 0
fill ~4~2~10 ~4~6~10 minecraft:quartz_block 0
setblock ~4~7~10 minecraft:wool 4
setblock ~4~8~10 minecraft:quartz_stairs 2
fill ~4~11~10 ~4~11~43 minecraft:wool 15
fill ~4~21~10 ~4~21~43 minecraft:glass
fill ~5~10~10 ~5~10~43 minecraft:wool 15
fill ~5~22~10 ~5~22~43 minecraft:glass
fill ~6~10~10 ~6~11~15 minecraft:fence 0
fill ~6~23~10 ~6~23~43 minecraft:glass
setblock ~7~12~10 minecraft:quartz_block 0
fill ~7~24~10 ~7~24~43 minecraft:glass
fill ~8~12~10 ~10~12~10 minecraft:quartz_stairs 2
fill ~8~25~10 ~8~25~43 minecraft:glass
fill ~9~1~10 ~9~1~49 minecraft:quartz_block 0
fill ~9~2~10 ~9~2~44 minecraft:quartz_block 1
fill ~9~26~10 ~9~26~43 minecraft:glass
fill ~10~1~10 ~13~1~13 minecraft:glass
fill ~10~3~10 ~48~4~10 minecraft:quartz_block 1
fill ~11~12~10 ~12~12~10 minecraft:quartz_block 0
fill ~13~12~10 ~14~12~10 minecraft:wool 4
fill ~15~1~10 ~18~1~13 minecraft:glass
setblock ~15~12~10 minecraft:fence 0
fill ~16~13~10 ~16~13~13 minecraft:fence 0
fill ~20~1~10 ~23~1~13 minecraft:glass
fill ~25~1~10 ~28~1~13 minecraft:glass
fill ~30~1~10 ~33~1~13 minecraft:glass
fill ~35~1~10 ~38~1~13 minecraft:glass
fill ~40~1~10 ~43~1~13 minecraft:glass
fill ~43~13~10 ~44~13~10 minecraft:fence 0
setblock ~44~12~10 minecraft:fence 0
fill ~45~1~10 ~48~1~13 minecraft:glass
setblock ~45~12~10 minecraft:wool 11
fill ~46~12~10 ~47~12~10 minecraft:quartz_block 0
fill ~49~1~10 ~49~1~49 minecraft:quartz_block 0
fill ~49~2~10 ~49~2~44 minecraft:quartz_block 1
fill ~49~12~10 ~50~12~10 minecraft:quartz_stairs 2
fill ~49~26~10 ~49~26~43 minecraft:glass
fill ~50~25~10 ~50~25~43 minecraft:glass
setblock ~51~12~10 minecraft:quartz_block 0
fill ~51~24~10 ~51~24~43 minecraft:glass
fill ~52~10~10 ~52~11~15 minecraft:fence 0
fill ~52~23~10 ~52~23~43 minecraft:glass
fill ~53~10~10 ~53~10~43 minecraft:wool 15
fill ~53~22~10 ~53~22~43 minecraft:glass
fill ~54~0~10 ~54~1~45 minecraft:quartz_block 0
fill ~54~2~10 ~54~7~10 minecraft:quartz_block 0
setblock ~54~8~10 minecraft:quartz_stairs 2
fill ~54~11~10 ~54~11~43 minecraft:wool 15
fill ~54~21~10 ~54~21~43 minecraft:glass
fill ~55~12~10 ~55~12~43 minecraft:wool 15
fill ~55~20~10 ~55~20~43 minecraft:glass
fill ~56~13~10 ~57~13~43 minecraft:wool 15
fill ~56~19~10 ~57~19~43 minecraft:wool 15
fill ~57~14~10 ~57~18~43 minecraft:wool 15
fill ~2~14~11 ~2~14~14 minecraft:quartz_stairs 1
fill ~2~18~11 ~4~18~11 minecraft:fence 0
fill ~3~13~11 ~3~13~14 minecraft:quartz_stairs 1
setblock ~4~8~11 minecraft:quartz_stairs 7
setblock ~4~9~11 minecraft:quartz_stairs 2
fill ~4~12~11 ~4~12~14 minecraft:quartz_stairs 1
setblock ~4~16~11 minecraft:glowstone
setblock ~4~17~11 minecraft:fence 0
setblock ~8~12~11 minecraft:quartz_block 0
fill ~9~12~11 ~9~12~13 minecraft:wool 4
fill ~10~3~11 ~10~4~43 minecraft:quartz_block 1
fill ~10~12~11 ~10~12~12 minecraft:quartz_block 0
fill ~11~12~11 ~12~13~11 minecraft:fence 0
setblock ~11~14~11 minecraft:glowstone
setblock ~13~12~11 minecraft:quartz_block 0
fill ~14~12~11 ~15~12~11 minecraft:wool 4
fill ~16~12~11 ~16~12~14 minecraft:fence 0
fill ~42~13~11 ~43~13~11 minecraft:fence 0
setblock ~43~12~11 minecraft:fence 0
setblock ~44~12~11 minecraft:wool 11
setblock ~45~12~11 minecraft:quartz_block 0
fill ~46~12~11 ~47~13~12 minecraft:fence 0
setblock ~47~14~11 minecraft:glowstone
fill ~48~3~11 ~48~4~43 minecraft:quartz_block 1
fill ~48~12~11 ~48~12~12 minecraft:quartz_block 0
fill ~49~12~11 ~49~12~12 minecraft:wool 11
fill ~50~12~11 ~51~13~11 minecraft:fence 0
setblock ~54~8~11 minecraft:quartz_stairs 7
setblock ~54~9~11 minecraft:quartz_stairs 2
fill ~54~12~11 ~54~12~14 minecraft:quartz_stairs 0
setblock ~54~16~11 minecraft:glowstone
fill ~54~17~11 ~54~18~11 minecraft:fence 0
fill ~55~13~11 ~55~13~14 minecraft:quartz_stairs 0
fill ~55~18~11 ~56~18~11 minecraft:fence 0
fill ~56~14~11 ~56~14~14 minecraft:quartz_stairs 0
fill ~58~14~11 ~58~14~12 minecraft:planks 2
fill ~58~15~11 ~58~18~11 minecraft:planks 2
setblock ~4~9~12 minecraft:glowstone
setblock ~4~10~12 minecraft:quartz_block 0
fill ~8~12~12 ~8~13~13 minecraft:fence 0
fill ~11~12~12 ~11~13~12 minecraft:fence 0
fill ~12~13~12 ~13~13~13 minecraft:fence 0
setblock ~12~14~12 minecraft:glowstone
setblock ~13~12~12 minecraft:fence 0
fill ~14~12~12 ~14~12~13 minecraft:quartz_block 0
fill ~15~12~12 ~15~12~13 minecraft:wool 4
fill ~42~12~12 ~42~12~14 minecraft:fence 0
fill ~42~13~12 ~42~13~13 minecraft:fence 0
fill ~43~12~12 ~43~12~13 minecraft:wool 11
fill ~44~12~12 ~44~12~13 minecraft:quartz_block 0
fill ~45~12~12 ~45~13~13 minecraft:fence 0
setblock ~46~14~12 minecraft:glowstone
fill ~50~12~12 ~50~13~12 minecraft:fence 0
setblock ~54~9~12 minecraft:glowstone
setblock ~54~10~12 minecraft:quartz_block 0
setblock ~58~18~12 minecraft:planks 2
fill ~0~14~13 ~0~17~13 minecraft:quartz_block 0
setblock ~4~8~13 minecraft:quartz_stairs 6
setblock ~4~9~13 minecraft:quartz_stairs 3
fill ~10~12~13 ~10~12~14 minecraft:wool 4
setblock ~11~12~13 minecraft:quartz_block 0
setblock ~12~12~13 minecraft:fence 0
setblock ~13~14~13 minecraft:glowstone
setblock ~45~14~13 minecraft:glowstone
fill ~46~12~13 ~46~13~13 minecraft:fence 0
setblock ~47~12~13 minecraft:quartz_block 0
setblock ~48~12~13 minecraft:wool 11
fill ~49~12~13 ~49~13~13 minecraft:fence 0
setblock ~50~13~13 minecraft:fence 0
setblock ~54~8~13 minecraft:quartz_stairs 6
setblock ~54~9~13 minecraft:quartz_stairs 3
setblock ~58~15~13 minecraft:planks 2
setblock ~58~17~13 minecraft:planks 2
fill ~0~16~14 ~0~16~16 minecraft:quartz_block 0
fill ~0~18~14 ~0~18~15 minecraft:quartz_block 0
fill ~2~18~14 ~4~18~14 minecraft:fence 0
fill ~4~2~14 ~4~5~14 minecraft:quartz_block 0
setblock ~4~6~14 minecraft:wool 4
setblock ~4~7~14 minecraft:quartz_block 0
setblock ~4~8~14 minecraft:glowstone
setblock ~4~16~14 minecraft:glowstone
setblock ~4~17~14 minecraft:fence 0
fill ~5~1~14 ~8~1~14 minecraft:quartz_block 0
fill ~8~13~14 ~9~13~14 minecraft:fence 0
setblock ~9~12~14 minecraft:fence 0
fill ~10~1~14 ~13~1~14 minecraft:quartz_block 0
fill ~11~12~14 ~11~12~15 minecraft:wool 4
fill ~12~12~14 ~13~12~14 minecraft:quartz_block 0
setblock ~14~1~14 minecraft:glowstone
fill ~14~10~14 ~16~10~14 minecraft:glass
setblock ~14~11~14 minecraft:quartz_block 0
fill ~15~1~14 ~18~1~14 minecraft:quartz_block 0
setblock ~15~11~14 minecraft:wool 4
setblock ~16~11~14 minecraft:quartz_block 0
fill ~17~10~14 ~41~10~39 minecraft:snow
fill ~17~11~14 ~18~11~14 minecraft:fence 0
setblock ~17~12~14 minecraft:fence 0
setblock ~19~1~14 minecraft:glowstone
fill ~20~1~14 ~23~1~14 minecraft:quartz_block 0
setblock ~24~1~14 minecraft:glowstone
fill ~25~1~14 ~28~1~14 minecraft:quartz_block 0
setblock ~29~1~14 minecraft:glowstone
fill ~30~1~14 ~33~1~14 minecraft:quartz_block 0
setblock ~34~1~14 minecraft:glowstone
fill ~35~1~14 ~38~1~14 minecraft:quartz_block 0
setblock ~39~1~14 minecraft:glowstone
fill ~40~1~14 ~43~1~14 minecraft:quartz_block 0
fill ~40~11~14 ~41~11~14 minecraft:fence 0
setblock ~41~12~14 minecraft:fence 0
fill ~42~10~14 ~44~10~14 minecraft:glass
setblock ~42~11~14 minecraft:quartz_block 0
setblock ~43~11~14 minecraft:wool 11
setblock ~44~1~14 minecraft:glowstone
setblock ~44~11~14 minecraft:quartz_block 0
fill ~45~1~14 ~48~1~14 minecraft:quartz_block 0
fill ~45~12~14 ~46~12~14 minecraft:quartz_block 0
setblock ~47~12~14 minecraft:wool 11
fill ~48~12~14 ~48~13~14 minecraft:fence 0
setblock ~49~13~14 minecraft:fence 0
fill ~50~1~14 ~53~1~14 minecraft:quartz_block 0
fill ~54~2~14 ~54~7~14 minecraft:quartz_block 0
setblock ~54~8~14 minecraft:glowstone
setblock ~54~16~14 minecraft:glowstone
fill ~54~17~14 ~54~18~14 minecraft:fence 0
fill ~55~18~14 ~56~18~14 minecraft:fence 0
fill ~58~16~14 ~58~16~22 minecraft:planks 2
setblock ~4~8~15 minecraft:quartz_stairs 7
setblock ~4~9~15 minecraft:quartz_stairs 2
fill ~7~10~15 ~9~11~15 minecraft:fence 0
fill ~9~13~15 ~10~13~15 minecraft:fence 0
fill ~10~1~15 ~13~1~18 minecraft:glass
setblock ~10~12~15 minecraft:fence 0
fill ~12~12~15 ~13~12~15 minecraft:wool 4
fill ~14~1~15 ~14~1~18 minecraft:quartz_block 0
fill ~14~10~15 ~14~10~16 minecraft:glass
setblock ~14~11~15 minecraft:wool 4
fill ~15~1~15 ~18~1~18 minecraft:glass
setblock ~15~10~15 minecraft:glowstone
fill ~15~11~15 ~15~11~16 minecraft:quartz_stairs 1
setblock ~16~10~15 minecraft:glass
setblock ~16~11~15 minecraft:quartz_stairs 3
fill ~19~1~15 ~19~1~18 minecraft:quartz_block 0
fill ~20~1~15 ~23~1~18 minecraft:glass
fill ~24~1~15 ~24~1~18 minecraft:quartz_block 0
fill ~25~1~15 ~28~1~18 minecraft:glass
fill ~29~1~15 ~29~1~18 minecraft:quartz_block 0
fill ~30~1~15 ~33~1~18 minecraft:glass
fill ~34~1~15 ~34~1~18 minecraft:quartz_block 0
fill ~35~1~15 ~38~1~18 minecraft:glass
fill ~39~1~15 ~39~1~18 minecraft:quartz_block 0
fill ~40~1~15 ~43~1~18 minecraft:glass
setblock ~42~10~15 minecraft:glass
setblock ~43~10~15 minecraft:glowstone
fill ~44~1~15 ~44~1~18 minecraft:quartz_block 0
fill ~44~10~15 ~44~10~16 minecraft:glass
setblock ~44~11~15 minecraft:wool 11
fill ~45~1~15 ~48~1~18 minecraft:glass
fill ~45~12~15 ~46~12~15 minecraft:wool 11
fill ~47~12~15 ~47~13~15 minecraft:fence 0
setblock ~48~13~15 minecraft:fence 0
fill ~49~10~15 ~51~11~15 minecraft:fence 0
setblock ~54~8~15 minecraft:quartz_stairs 7
setblock ~54~9~15 minecraft:quartz_stairs 2
fill ~0~14~16 ~0~15~16 minecraft:quartz_block 0
setblock ~0~17~16 minecraft:quartz_block 0
setblock ~4~9~16 minecraft:quartz_stairs 7
setblock ~4~10~16 minecraft:quartz_stairs 2
fill ~6~10~16 ~8~10~17 minecraft:quartz_block 0
fill ~9~10~16 ~9~10~20 minecraft:fence 0
fill ~9~11~16 ~9~11~19 minecraft:fence 0
fill ~10~13~16 ~13~13~16 minecraft:fence 0
fill ~11~12~16 ~14~12~16 minecraft:fence 0
setblock ~14~11~16 minecraft:quartz_block 0
setblock ~15~10~16 minecraft:glass
fill ~16~10~16 ~16~10~37 minecraft:snow
fill ~42~10~16 ~42~10~37 minecraft:snow
setblock ~43~10~16 minecraft:glass
setblock ~44~11~16 minecraft:quartz_block 0
fill ~44~12~16 ~46~12~16 minecraft:fence 0
fill ~45~13~16 ~47~13~16 minecraft:fence 0
fill ~49~10~16 ~49~10~20 minecraft:fence 0
fill ~49~11~16 ~49~11~19 minecraft:fence 0
fill ~50~10~16 ~52~10~17 minecraft:quartz_block 0
setblock ~54~9~16 minecraft:quartz_stairs 7
setblock ~54~10~16 minecraft:quartz_stairs 2
setblock ~4~9~17 minecraft:quartz_stairs 6
setblock ~4~10~17 minecraft:quartz_stairs 3
fill ~14~10~17 ~15~10~36 minecraft:snow
fill ~14~11~17 ~14~11~18 minecraft:fence 0
setblock ~14~12~17 minecraft:fence 0
fill ~43~10~17 ~44~10~36 minecraft:snow
fill ~44~11~17 ~44~11~18 minecraft:fence 0
setblock ~44~12~17 minecraft:fence 0
setblock ~54~9~17 minecraft:quartz_stairs 6
setblock ~54~10~17 minecraft:quartz_stairs 3
fill ~0~14~18 ~0~17~18 minecraft:quartz_block 0
setblock ~4~8~18 minecraft:quartz_stairs 6
setblock ~4~9~18 minecraft:quartz_stairs 3
fill ~6~10~18 ~6~11~35 minecraft:fence 0
fill ~7~10~18 ~8~10~18 minecraft:quartz_block 0
fill ~50~10~18 ~51~10~18 minecraft:quartz_block 0
fill ~52~10~18 ~52~11~35 minecraft:fence 0
setblock ~54~8~18 minecraft:quartz_stairs 6
setblock ~54~9~18 minecraft:quartz_stairs 3
fill ~0~16~19 ~0~16~20 minecraft:quartz_block 0
fill ~0~18~19 ~0~18~20 minecraft:quartz_block 0
fill ~2~14~19 ~2~14~22 minecraft:quartz_stairs 1
fill ~2~18~19 ~4~18~19 minecraft:fence 0
fill ~3~13~19 ~3~13~22 minecraft:quartz_stairs 1
fill ~4~2~19 ~4~4~19 minecraft:quartz_block 0
setblock ~4~5~19 minecraft:wool 4
fill ~4~6~19 ~4~7~19 minecraft:quartz_block 0
setblock ~4~8~19 minecraft:glowstone
fill ~4~12~19 ~4~12~22 minecraft:quartz_stairs 1
setblock ~4~16~19 minecraft:glowstone
setblock ~4~17~19 minecraft:fence 0
fill ~5~1~19 ~8~1~19 minecraft:quartz_block 0
fill ~7~9~19 ~8~9~19 minecraft:quartz_block 0
fill ~7~10~19 ~8~10~19 minecraft:quartz_stairs 3
fill ~9~9~19 ~9~9~21 minecraft:fence 0
fill ~10~1~19 ~13~1~19 minecraft:quartz_block 0
setblock ~14~1~19 minecraft:glowstone
fill ~15~1~19 ~18~1~19 minecraft:quartz_block 0
setblock ~19~1~19 minecraft:glowstone
fill ~20~1~19 ~23~1~19 minecraft:quartz_block 0
setblock ~24~1~19 minecraft:glowstone
fill ~25~1~19 ~28~1~19 minecraft:quartz_block 0
setblock ~29~1~19 minecraft:glowstone
fill ~30~1~19 ~33~1~19 minecraft:quartz_block 0
setblock ~34~1~19 minecraft:glowstone
fill ~35~1~19 ~38~1~19 minecraft:quartz_block 0
setblock ~39~1~19 minecraft:glowstone
fill ~40~1~19 ~43~1~19 minecraft:quartz_block 0
setblock ~44~1~19 minecraft:glowstone
fill ~45~1~19 ~48~1~19 minecraft:quartz_block 0
fill ~49~9~19 ~49~9~21 minecraft:fence 0
fill ~50~1~19 ~53~1~19 minecraft:quartz_block 0
fill ~50~9~19 ~51~9~19 minecraft:quartz_block 0
fill ~50~10~19 ~51~10~19 minecraft:quartz_stairs 3
fill ~54~2~19 ~54~7~19 minecraft:quartz_block 0
setblock ~54~8~19 minecraft:glowstone
fill ~54~12~19 ~54~12~22 minecraft:quartz_stairs 0
setblock ~54~16~19 minecraft:glowstone
fill ~54~17~19 ~54~18~19 minecraft:fence 0
fill ~55~13~19 ~55~13~22 minecraft:quartz_stairs 0
fill ~55~18~19 ~56~18~19 minecraft:fence 0
fill ~56~14~19 ~56~14~22 minecraft:quartz_stairs 0
setblock ~0~15~20 minecraft:stone_block_slab 6
setblock ~4~8~20 minecraft:quartz_stairs 7
setblock ~4~9~20 minecraft:quartz_stairs 2
fill ~7~8~20 ~8~8~20 minecraft:quartz_block 0
fill ~7~9~20 ~8~9~20 minecraft:quartz_stairs 3
fill ~9~8~20 ~9~8~22 minecraft:fence 0
fill ~10~1~20 ~13~1~23 minecraft:glass
fill ~14~1~20 ~14~1~23 minecraft:quartz_block 0
fill ~15~1~20 ~18~1~23 minecraft:glass
fill ~19~1~20 ~19~1~23 minecraft:quartz_block 0
fill ~20~1~20 ~23~1~23 minecraft:glass
fill ~24~1~20 ~24~1~23 minecraft:quartz_block 0
fill ~25~1~20 ~28~1~23 minecraft:glass
fill ~29~1~20 ~29~1~23 minecraft:quartz_block 0
fill ~30~1~20 ~33~1~23 minecraft:glass
fill ~34~1~20 ~34~1~23 minecraft:quartz_block 0
fill ~35~1~20 ~38~1~23 minecraft:glass
fill ~39~1~20 ~39~1~23 minecraft:quartz_block 0
fill ~40~1~20 ~43~1~23 minecraft:glass
fill ~44~1~20 ~44~1~23 minecraft:quartz_block 0
fill ~45~1~20 ~48~1~23 minecraft:glass
fill ~49~8~20 ~49~8~22 minecraft:fence 0
fill ~50~8~20 ~51~8~20 minecraft:quartz_block 0
fill ~50~9~20 ~51~9~20 minecraft:quartz_stairs 3
setblock ~54~8~20 minecraft:quartz_stairs 7
setblock ~54~9~20 minecraft:quartz_stairs 2
fill ~58~14~20 ~58~15~23 minecraft:diamond_block
fill ~58~17~20 ~58~17~24 minecraft:diamond_block
fill ~58~18~20 ~58~18~23 minecraft:diamond_block
setblock ~0~14~21 minecraft:quartz_block 0
setblock ~0~17~21 minecraft:quartz_block 0
setblock ~4~9~21 minecraft:quartz_stairs 7
setblock ~4~10~21 minecraft:quartz_stairs 2
fill ~7~7~21 ~8~7~21 minecraft:quartz_block 0
fill ~7~8~21 ~8~8~21 minecraft:quartz_stairs 3
fill ~9~7~21 ~9~7~23 minecraft:fence 0
fill ~49~7~21 ~49~7~23 minecraft:fence 0
fill ~50~7~21 ~51~7~21 minecraft:quartz_block 0
fill ~50~8~21 ~51~8~21 minecraft:quartz_stairs 3
setblock ~54~9~21 minecraft:quartz_stairs 7
setblock ~54~10~21 minecraft:quartz_stairs 2
fill ~2~18~22 ~4~18~22 minecraft:fence 0
setblock ~4~9~22 minecraft:quartz_stairs 6
setblock ~4~10~22 minecraft:quartz_stairs 3
setblock ~4~16~22 minecraft:glowstone
setblock ~4~17~22 minecraft:fence 0
fill ~7~6~22 ~8~6~22 minecraft:quartz_block 0
fill ~7~7~22 ~8~7~22 minecraft:quartz_stairs 3
fill ~9~6~22 ~9~6~24 minecraft:fence 0
fill ~49~6~22 ~49~6~24 minecraft:fence 0
fill ~50~6~22 ~51~6~22 minecraft:quartz_block 0
fill ~50~7~22 ~51~7~22 minecraft:quartz_stairs 3
setblock ~54~9~22 minecraft:quartz_stairs 6
setblock ~54~10~22 minecraft:quartz_stairs 3
setblock ~54~16~22 minecraft:glowstone
fill ~54~17~22 ~54~18~22 minecraft:fence 0
fill ~55~18~22 ~56~18~22 minecraft:fence 0
fill ~0~15~23 ~0~17~23 minecraft:quartz_block 0
fill ~2~0~23 ~3~0~23 minecraft:quartz_stairs 2
setblock ~4~8~23 minecraft:quartz_stairs 6
setblock ~4~9~23 minecraft:quartz_stairs 3
fill ~7~5~23 ~8~5~23 minecraft:quartz_block 0
fill ~7~6~23 ~8~6~23 minecraft:quartz_stairs 3
fill ~9~5~23 ~9~5~30 minecraft:fence 0
fill ~49~5~23 ~49~5~30 minecraft:fence 0
fill ~50~5~23 ~51~5~23 minecraft:quartz_block 0
fill ~50~6~23 ~51~6~23 minecraft:quartz_stairs 3
setblock ~54~8~23 minecraft:quartz_stairs 6
setblock ~54~9~23 minecraft:quartz_stairs 3
fill ~55~0~23 ~56~0~23 minecraft:quartz_stairs 2
fill ~58~16~23 ~58~16~25 minecraft:diamond_block
fill ~0~14~24 ~0~14~26 minecraft:quartz_block 0
fill ~0~16~24 ~0~16~25 minecraft:quartz_block 0
fill ~0~18~24 ~0~18~26 minecraft:quartz_block 0
fill ~2~0~24 ~2~0~29 minecraft:quartz_stairs 0
fill ~3~0~24 ~3~0~29 minecraft:quartz_block 0
setblock ~3~1~24 minecraft:quartz_stairs 2
fill ~4~2~24 ~4~3~24 minecraft:quartz_block 0
setblock ~4~4~24 minecraft:wool 4
fill ~4~5~24 ~4~7~24 minecraft:quartz_block 0
setblock ~4~8~24 minecraft:glowstone
fill ~5~1~24 ~8~1~24 minecraft:quartz_block 0
fill ~7~4~24 ~8~4~29 minecraft:quartz_block 0
fill ~7~5~24 ~8~5~24 minecraft:quartz_stairs 3
fill ~8~2~24 ~8~3~24 minecraft:quartz_block 0
fill ~9~4~24 ~9~4~29 minecraft:fence 0
fill ~10~1~24 ~13~1~24 minecraft:quartz_block 0
setblock ~14~1~24 minecraft:glowstone
fill ~15~1~24 ~18~1~24 minecraft:quartz_block 0
setblock ~19~1~24 minecraft:glowstone
fill ~20~1~24 ~23~1~24 minecraft:quartz_block 0
setblock ~24~1~24 minecraft:glowstone
fill ~25~1~24 ~28~1~24 minecraft:quartz_block 0
setblock ~25~16~24 minecraft:glowstone
fill ~25~17~24 ~25~17~28 minecraft:fence 0
setblock ~29~1~24 minecraft:glowstone
fill ~30~1~24 ~33~1~24 minecraft:quartz_block 0
setblock ~32~16~24 minecraft:glowstone
fill ~32~17~24 ~32~17~28 minecraft:fence 0
setblock ~34~1~24 minecraft:glowstone
fill ~35~1~24 ~38~1~24 minecraft:quartz_block 0
setblock ~39~1~24 minecraft:glowstone
fill ~40~1~24 ~43~1~24 minecraft:quartz_block 0
setblock ~44~1~24 minecraft:glowstone
fill ~45~1~24 ~48~1~24 minecraft:quartz_block 0
fill ~49~4~24 ~49~4~29 minecraft:fence 0
fill ~50~1~24 ~53~1~24 minecraft:quartz_block 0
fill ~50~4~24 ~51~4~29 minecraft:quartz_block 0
fill ~50~5~24 ~51~5~24 minecraft:quartz_stairs 3
fill ~54~2~24 ~54~7~24 minecraft:quartz_block 0
setblock ~54~8~24 minecraft:glowstone
fill ~55~0~24 ~55~0~29 minecraft:quartz_block 0
setblock ~55~1~24 minecraft:quartz_stairs 2
fill ~56~0~24 ~56~0~29 minecraft:quartz_stairs 1
setblock ~58~15~24 minecraft:diamond_block
fill ~2~14~25 ~2~14~28 minecraft:quartz_stairs 1
fill ~2~18~25 ~4~18~25 minecraft:fence 0
fill ~3~1~25 ~3~1~28 minecraft:quartz_stairs 0
fill ~3~13~25 ~3~13~28 minecraft:quartz_stairs 1
fill ~4~2~25 ~4~2~28 minecraft:quartz_stairs 0
setblock ~4~8~25 minecraft:quartz_stairs 7
setblock ~4~9~25 minecraft:quartz_stairs 2
fill ~4~12~25 ~4~12~28 minecraft:quartz_stairs 1
setblock ~4~16~25 minecraft:glowstone
setblock ~4~17~25 minecraft:fence 0
fill ~5~2~25 ~5~2~28 minecraft:quartz_block 0
fill ~5~3~25 ~5~3~28 minecraft:quartz_stairs 0
fill ~6~3~25 ~6~3~28 minecraft:quartz_block 0
fill ~6~4~25 ~6~4~28 minecraft:quartz_stairs 0
fill ~10~1~25 ~13~1~28 minecraft:glass
fill ~14~1~25 ~14~1~28 minecraft:quartz_block 0
fill ~15~1~25 ~18~1~28 minecraft:glass
fill ~19~1~25 ~19~1~28 minecraft:quartz_block 0
fill ~20~1~25 ~23~1~28 minecraft:glass
fill ~23~17~25 ~24~17~25 minecraft:planks 2
fill ~24~1~25 ~24~1~28 minecraft:quartz_block 0
fill ~25~1~25 ~28~1~28 minecraft:glass
fill ~26~17~25 ~31~17~25 minecraft:planks 2
fill ~28~18~25 ~29~25~25 minecraft:planks 2
fill ~29~1~25 ~29~1~28 minecraft:quartz_block 0
fill ~30~1~25 ~33~1~28 minecraft:glass
fill ~33~17~25 ~34~17~25 minecraft:planks 2
fill ~34~1~25 ~34~1~28 minecraft:quartz_block 0
fill ~35~1~25 ~38~1~28 minecraft:glass
fill ~39~1~25 ~39~1~28 minecraft:quartz_block 0
fill ~40~1~25 ~43~1~28 minecraft:glass
fill ~44~1~25 ~44~1~28 minecraft:quartz_block 0
fill ~45~1~25 ~48~1~28 minecraft:glass
fill ~52~3~25 ~52~3~28 minecraft:quartz_block 0
fill ~52~4~25 ~52~4~28 minecraft:quartz_stairs 1
fill ~53~2~25 ~53~2~28 minecraft:quartz_block 0
fill ~53~3~25 ~53~3~28 minecraft:quartz_stairs 1
fill ~54~2~25 ~54~2~28 minecraft:quartz_stairs 1
setblock ~54~8~25 minecraft:quartz_stairs 7
setblock ~54~9~25 minecraft:quartz_stairs 2
fill ~54~12~25 ~54~12~28 minecraft:quartz_stairs 0
setblock ~54~16~25 minecraft:glowstone
fill ~54~17~25 ~54~18~25 minecraft:fence 0
fill ~55~1~25 ~55~1~28 minecraft:quartz_stairs 1
fill ~55~13~25 ~55~13~28 minecraft:quartz_stairs 0
fill ~55~18~25 ~56~18~25 minecraft:fence 0
fill ~56~14~25 ~56~14~28 minecraft:quartz_stairs 0
setblock ~4~9~26 minecraft:quartz_stairs 7
setblock ~4~10~26 minecraft:quartz_stairs 2
fill ~9~6~26 ~9~6~27 minecraft:fence 0
fill ~9~7~26 ~9~7~27 minecraft:glowstone
setblock ~22~15~26 minecraft:glowstone
fill ~22~16~26 ~22~17~26 minecraft:fence 0
fill ~23~17~26 ~24~17~26 minecraft:fence 0
fill ~26~17~26 ~31~18~26 minecraft:fence 0
fill ~27~19~26 ~30~19~26 minecraft:fence 0
fill ~28~20~26 ~29~25~26 minecraft:fence 0
fill ~33~17~26 ~35~17~26 minecraft:fence 0
setblock ~35~15~26 minecraft:glowstone
setblock ~35~16~26 minecraft:fence 0
fill ~49~6~26 ~49~6~27 minecraft:fence 0
fill ~49~7~26 ~49~7~27 minecraft:glowstone
setblock ~54~9~26 minecraft:quartz_stairs 7
setblock ~54~10~26 minecraft:quartz_stairs 2
setblock ~4~9~27 minecraft:quartz_stairs 6
setblock ~4~10~27 minecraft:quartz_stairs 3
fill ~23~17~27 ~24~17~27 minecraft:planks 2
fill ~26~17~27 ~31~17~27 minecraft:planks 2
fill ~28~18~27 ~29~25~27 minecraft:planks 2
fill ~33~17~27 ~34~17~27 minecraft:planks 2
setblock ~54~9~27 minecraft:quartz_stairs 6
setblock ~54~10~27 minecraft:quartz_stairs 3
fill ~0~14~28 ~0~18~28 minecraft:quartz_block 0
fill ~2~18~28 ~4~18~28 minecraft:fence 0
setblock ~4~8~28 minecraft:quartz_stairs 6
setblock ~4~9~28 minecraft:quartz_stairs 3
setblock ~4~16~28 minecraft:glowstone
setblock ~4~17~28 minecraft:fence 0
setblock ~25~16~28 minecraft:glowstone
setblock ~32~16~28 minecraft:glowstone
setblock ~54~8~28 minecraft:quartz_stairs 6
setblock ~54~9~28 minecraft:quartz_stairs 3
setblock ~54~16~28 minecraft:glowstone
fill ~54~17~28 ~54~18~28 minecraft:fence 0
fill ~55~18~28 ~56~18~28 minecraft:fence 0
fill ~58~16~28 ~58~16~30 minecraft:diamond_block
setblock ~0~17~29 minecraft:quartz_block 0
setblock ~3~1~29 minecraft:quartz_stairs 3
fill ~4~2~29 ~4~3~29 minecraft:quartz_block 0
setblock ~4~4~29 minecraft:wool 5
fill ~4~5~29 ~4~7~29 minecraft:quartz_block 0
setblock ~4~8~29 minecraft:glowstone
fill ~5~1~29 ~8~1~29 minecraft:quartz_block 0
fill ~7~5~29 ~8~5~29 minecraft:quartz_stairs 2
fill ~8~2~29 ~8~3~29 minecraft:quartz_block 0
fill ~9~6~29 ~9~6~31 minecraft:fence 0
fill ~10~1~29 ~13~1~29 minecraft:quartz_block 0
setblock ~14~1~29 minecraft:glowstone
fill ~15~1~29 ~18~1~29 minecraft:quartz_block 0
setblock ~19~1~29 minecraft:glowstone
fill ~20~1~29 ~23~1~29 minecraft:quartz_block 0
setblock ~24~1~29 minecraft:glowstone
fill ~25~1~29 ~28~1~29 minecraft:quartz_block 0
setblock ~29~1~29 minecraft:glowstone
fill ~30~1~29 ~33~1~29 minecraft:quartz_block 0
setblock ~34~1~29 minecraft:glowstone
fill ~35~1~29 ~38~1~29 minecraft:quartz_block 0
setblock ~39~1~29 minecraft:glowstone
fill ~40~1~29 ~43~1~29 minecraft:quartz_block 0
setblock ~44~1~29 minecraft:glowstone
fill ~45~1~29 ~48~1~29 minecraft:quartz_block 0
fill ~49~6~29 ~49~6~31 minecraft:fence 0
fill ~50~1~29 ~53~1~29 minecraft:quartz_block 0
fill ~50~5~29 ~51~5~29 minecraft:quartz_stairs 2
fill ~54~2~29 ~54~7~29 minecraft:quartz_block 0
setblock ~54~8~29 minecraft:glowstone
setblock ~55~1~29 minecraft:quartz_stairs 3
fill ~58~15~29 ~58~15~33 minecraft:diamond_block
fill ~58~17~29 ~58~17~33 minecraft:diamond_block
setblock ~0~16~30 minecraft:quartz_block 0
fill ~2~0~30 ~3~0~30 minecraft:quartz_stairs 3
setblock ~4~8~30 minecraft:quartz_stairs 7
setblock ~4~9~30 minecraft:quartz_stairs 2
fill ~7~5~30 ~8~5~30 minecraft:quartz_block 0
fill ~7~6~30 ~8~6~30 minecraft:quartz_stairs 2
fill ~9~7~30 ~9~7~32 minecraft:fence 0
fill ~10~1~30 ~13~1~33 minecraft:glass
fill ~14~1~30 ~14~1~33 minecraft:quartz_block 0
fill ~15~1~30 ~18~1~33 minecraft:glass
fill ~19~1~30 ~19~1~33 minecraft:quartz_block 0
fill ~20~1~30 ~23~1~33 minecraft:glass
fill ~24~1~30 ~24~1~33 minecraft:quartz_block 0
fill ~25~1~30 ~28~1~33 minecraft:glass
fill ~29~1~30 ~29~1~33 minecraft:quartz_block 0
fill ~30~1~30 ~33~1~33 minecraft:glass
fill ~34~1~30 ~34~1~33 minecraft:quartz_block 0
fill ~35~1~30 ~38~1~33 minecraft:glass
fill ~39~1~30 ~39~1~33 minecraft:quartz_block 0
fill ~40~1~30 ~43~1~33 minecraft:glass
fill ~44~1~30 ~44~1~33 minecraft:quartz_block 0
fill ~45~1~30 ~48~1~33 minecraft:glass
fill ~49~7~30 ~49~7~32 minecraft:fence 0
fill ~50~5~30 ~51~5~30 minecraft:quartz_block 0
fill ~50~6~30 ~51~6~30 minecraft:quartz_stairs 2
setblock ~54~8~30 minecraft:quartz_stairs 7
setblock ~54~9~30 minecraft:quartz_stairs 2
fill ~55~0~30 ~56~0~30 minecraft:quartz_stairs 3
fill ~58~14~30 ~58~14~33 minecraft:diamond_block
fill ~58~18~30 ~58~18~33 minecraft:diamond_block
fill ~0~15~31 ~0~15~32 minecraft:quartz_block 0
fill ~2~14~31 ~2~14~34 minecraft:quartz_stairs 1
fill ~2~18~31 ~4~18~31 minecraft:fence 0
fill ~3~13~31 ~3~13~34 minecraft:quartz_stairs 1
setblock ~4~9~31 minecraft:quartz_stairs 7
setblock ~4~10~31 minecraft:quartz_stairs 2
fill ~4~12~31 ~4~12~34 minecraft:quartz_stairs 1
setblock ~4~16~31 minecraft:glowstone
setblock ~4~17~31 minecraft:fence 0
fill ~7~6~31 ~8~6~31 minecraft:quartz_block 0
fill ~7~7~31 ~8~7~31 minecraft:quartz_stairs 2
fill ~9~8~31 ~9~8~33 minecraft:fence 0
fill ~49~8~31 ~49~8~33 minecraft:fence 0
fill ~50~6~31 ~51~6~31 minecraft:quartz_block 0
fill ~50~7~31 ~51~7~31 minecraft:quartz_stairs 2
setblock ~54~9~31 minecraft:quartz_stairs 7
setblock ~54~10~31 minecraft:quartz_stairs 2
fill ~54~12~31 ~54~12~34 minecraft:quartz_stairs 0
setblock ~54~16~31 minecraft:glowstone
fill ~54~17~31 ~54~18~31 minecraft:fence 0
fill ~55~13~31 ~55~13~34 minecraft:quartz_stairs 0
fill ~55~18~31 ~56~18~31 minecraft:fence 0
fill ~56~14~31 ~56~14~34 minecraft:quartz_stairs 0
fill ~58~16~31 ~58~16~40 minecraft:planks 2
setblock ~0~14~32 minecraft:quartz_block 0
fill ~0~16~32 ~0~18~32 minecraft:quartz_block 0
setblock ~4~9~32 minecraft:quartz_stairs 6
setblock ~4~10~32 minecraft:quartz_stairs 3
fill ~7~7~32 ~8~7~32 minecraft:quartz_block 0
fill ~7~8~32 ~8~8~32 minecraft:quartz_stairs 2
fill ~9~9~32 ~9~9~34 minecraft:fence 0
fill ~49~9~32 ~49~9~34 minecraft:fence 0
fill ~50~7~32 ~51~7~32 minecraft:quartz_block 0
fill ~50~8~32 ~51~8~32 minecraft:quartz_stairs 2
setblock ~54~9~32 minecraft:quartz_stairs 6
setblock ~54~10~32 minecraft:quartz_stairs 3
setblock ~4~8~33 minecraft:quartz_stairs 6
setblock ~4~9~33 minecraft:quartz_stairs 3
fill ~7~8~33 ~8~8~33 minecraft:quartz_block 0
fill ~7~9~33 ~8~9~33 minecraft:quartz_stairs 2
fill ~9~10~33 ~9~10~38 minecraft:fence 0
fill ~49~10~33 ~49~10~38 minecraft:fence 0
fill ~50~8~33 ~51~8~33 minecraft:quartz_block 0
fill ~50~9~33 ~51~9~33 minecraft:quartz_stairs 2
setblock ~54~8~33 minecraft:quartz_stairs 6
setblock ~54~9~33 minecraft:quartz_stairs 3
fill ~0~14~34 ~0~17~34 minecraft:quartz_block 0
fill ~2~18~34 ~4~18~34 minecraft:fence 0
fill ~4~2~34 ~4~4~34 minecraft:quartz_block 0
setblock ~4~5~34 minecraft:wool 5
fill ~4~6~34 ~4~7~34 minecraft:quartz_block 0
setblock ~4~8~34 minecraft:glowstone
setblock ~4~16~34 minecraft:glowstone
setblock ~4~17~34 minecraft:fence 0
fill ~5~1~34 ~8~1~34 minecraft:quartz_block 0
fill ~7~9~34 ~8~9~34 minecraft:quartz_block 0
fill ~7~10~34 ~8~10~34 minecraft:quartz_stairs 2
fill ~9~11~34 ~9~11~38 minecraft:fence 0
fill ~10~1~34 ~13~1~34 minecraft:quartz_block 0
setblock ~14~1~34 minecraft:glowstone
fill ~15~1~34 ~18~1~34 minecraft:quartz_block 0
setblock ~19~1~34 minecraft:glowstone
fill ~20~1~34 ~23~1~34 minecraft:quartz_block 0
setblock ~24~1~34 minecraft:glowstone
fill ~25~1~34 ~28~1~34 minecraft:quartz_block 0
setblock ~29~1~34 minecraft:glowstone
fill ~30~1~34 ~33~1~34 minecraft:quartz_block 0
setblock ~34~1~34 minecraft:glowstone
fill ~35~1~34 ~38~1~34 minecraft:quartz_block 0
setblock ~39~1~34 minecraft:glowstone
fill ~40~1~34 ~43~1~34 minecraft:quartz_block 0
setblock ~44~1~34 minecraft:glowstone
fill ~45~1~34 ~48~1~34 minecraft:quartz_block 0
fill ~49~11~34 ~49~11~38 minecraft:fence 0
fill ~50~1~34 ~53~1~34 minecraft:quartz_block 0
fill ~50~9~34 ~51~9~34 minecraft:quartz_block 0
fill ~50~10~34 ~51~10~34 minecraft:quartz_stairs 2
fill ~54~2~34 ~54~7~34 minecraft:quartz_block 0
setblock ~54~8~34 minecraft:glowstone
setblock ~54~16~34 minecraft:glowstone
fill ~54~17~34 ~54~18~34 minecraft:fence 0
fill ~55~18~34 ~56~18~34 minecraft:fence 0
fill ~0~16~35 ~0~16~37 minecraft:quartz_block 0
fill ~0~18~35 ~0~18~36 minecraft:quartz_block 0
setblock ~4~8~35 minecraft:quartz_stairs 7
setblock ~4~9~35 minecraft:quartz_stairs 2
fill ~7~10~35 ~8~10~37 minecraft:quartz_block 0
fill ~10~1~35 ~13~1~38 minecraft:glass
fill ~14~1~35 ~14~1~38 minecraft:quartz_block 0
fill ~14~11~35 ~14~11~36 minecraft:fence 0
fill ~15~1~35 ~18~1~38 minecraft:glass
fill ~19~1~35 ~19~1~38 minecraft:quartz_block 0
fill ~20~1~35 ~23~1~38 minecraft:glass
fill ~24~1~35 ~24~1~38 minecraft:quartz_block 0
fill ~25~1~35 ~28~1~38 minecraft:glass
fill ~29~1~35 ~29~1~38 minecraft:quartz_block 0
fill ~30~1~35 ~33~1~38 minecraft:glass
fill ~34~1~35 ~34~1~38 minecraft:quartz_block 0
fill ~35~1~35 ~38~1~38 minecraft:glass
fill ~39~1~35 ~39~1~38 minecraft:quartz_block 0
fill ~40~1~35 ~43~1~38 minecraft:glass
fill ~44~1~35 ~44~1~38 minecraft:quartz_block 0
fill ~44~11~35 ~44~11~36 minecraft:fence 0
fill ~45~1~35 ~48~1~38 minecraft:glass
fill ~50~10~35 ~51~10~37 minecraft:quartz_block 0
setblock ~54~8~35 minecraft:quartz_stairs 7
setblock ~54~9~35 minecraft:quartz_stairs 2
setblock ~4~9~36 minecraft:quartz_stairs 7
setblock ~4~10~36 minecraft:quartz_stairs 2
fill ~6~10~36 ~6~10~37 minecraft:quartz_block 0
fill ~14~12~36 ~14~12~37 minecraft:fence 0
fill ~44~12~36 ~44~12~37 minecraft:fence 0
fill ~52~10~36 ~52~10~37 minecraft:quartz_block 0
setblock ~54~9~36 minecraft:quartz_stairs 7
setblock ~54~10~36 minecraft:quartz_stairs 2
fill ~0~14~37 ~0~15~37 minecraft:quartz_block 0
setblock ~0~17~37 minecraft:quartz_block 0
setblock ~4~9~37 minecraft:quartz_stairs 6
setblock ~4~10~37 minecraft:quartz_stairs 3
fill ~11~13~37 ~13~13~37 minecraft:fence 0
fill ~12~12~37 ~13~12~37 minecraft:fence 0
fill ~14~10~37 ~15~10~37 minecraft:glass
setblock ~14~11~37 minecraft:quartz_block 0
fill ~15~11~37 ~15~11~38 minecraft:quartz_stairs 1
fill ~43~10~37 ~44~10~37 minecraft:glass
fill ~43~11~37 ~43~11~38 minecraft:quartz_stairs 0
setblock ~44~11~37 minecraft:quartz_block 0
fill ~45~12~37 ~46~13~37 minecraft:fence 0
fill ~47~13~37 ~47~13~38 minecraft:fence 0
setblock ~54~9~37 minecraft:quartz_stairs 6
setblock ~54~10~37 minecraft:quartz_stairs 3
setblock ~4~8~38 minecraft:quartz_stairs 6
setblock ~4~9~38 minecraft:quartz_stairs 3
fill ~6~10~38 ~8~11~38 minecraft:fence 0
fill ~10~13~38 ~11~13~38 minecraft:fence 0
setblock ~11~12~38 minecraft:fence 0
fill ~12~12~38 ~13~12~38 minecraft:wool 5
fill ~14~10~38 ~14~10~39 minecraft:glass
setblock ~14~11~38 minecraft:wool 5
setblock ~15~10~38 minecraft:glowstone
fill ~16~10~38 ~16~10~39 minecraft:glass
setblock ~16~11~38 minecraft:quartz_stairs 2
fill ~42~10~38 ~42~10~39 minecraft:glass
setblock ~42~11~38 minecraft:quartz_stairs 2
setblock ~43~10~38 minecraft:glowstone
fill ~44~10~38 ~44~10~39 minecraft:glass
setblock ~44~11~38 minecraft:wool 2
fill ~45~12~38 ~46~12~38 minecraft:wool 2
setblock ~47~12~38 minecraft:fence 0
fill ~48~13~38 ~48~13~39 minecraft:fence 0
fill ~50~10~38 ~52~11~38 minecraft:fence 0
setblock ~54~8~38 minecraft:quartz_stairs 6
setblock ~54~9~38 minecraft:quartz_stairs 3
fill ~2~14~39 ~2~14~42 minecraft:quartz_stairs 1
fill ~2~18~39 ~4~18~39 minecraft:fence 0
fill ~3~13~39 ~3~13~42 minecraft:quartz_stairs 1
fill ~4~2~39 ~4~5~39 minecraft:quartz_block 0
setblock ~4~6~39 minecraft:wool 5
setblock ~4~7~39 minecraft:quartz_block 0
setblock ~4~8~39 minecraft:glowstone
fill ~4~12~39 ~4~12~42 minecraft:quartz_stairs 1
setblock ~4~16~39 minecraft:glowstone
setblock ~4~17~39 minecraft:fence 0
fill ~5~1~39 ~8~1~39 minecraft:quartz_block 0
fill ~6~10~39 ~6~11~43 minecraft:fence 0
fill ~9~13~39 ~10~13~39 minecraft:fence 0
fill ~10~1~39 ~13~1~39 minecraft:quartz_block 0
setblock ~10~12~39 minecraft:fence 0
setblock ~11~12~39 minecraft:wool 5
fill ~12~12~39 ~13~12~39 minecraft:quartz_block 0
setblock ~14~1~39 minecraft:glowstone
setblock ~14~11~39 minecraft:quartz_block 0
fill ~15~1~39 ~18~1~39 minecraft:quartz_block 0
setblock ~15~10~39 minecraft:glass
setblock ~15~11~39 minecraft:wool 5
setblock ~16~11~39 minecraft:quartz_block 0
fill ~16~12~39 ~17~12~39 minecraft:fence 0
fill ~17~11~39 ~18~11~39 minecraft:fence 0
setblock ~19~1~39 minecraft:glowstone
fill ~20~1~39 ~23~1~39 minecraft:quartz_block 0
setblock ~24~1~39 minecraft:glowstone
fill ~25~1~39 ~28~1~39 minecraft:quartz_block 0
setblock ~29~1~39 minecraft:glowstone
fill ~30~1~39 ~33~1~39 minecraft:quartz_block 0
setblock ~34~1~39 minecraft:glowstone
fill ~35~1~39 ~38~1~39 minecraft:quartz_block 0
setblock ~39~1~39 minecraft:glowstone
fill ~40~1~39 ~43~1~39 minecraft:quartz_block 0
fill ~40~11~39 ~41~11~39 minecraft:fence 0
fill ~41~12~39 ~42~12~39 minecraft:fence 0
setblock ~42~11~39 minecraft:quartz_block 0
fill ~42~13~39 ~42~13~42 minecraft:fence 0
setblock ~43~10~39 minecraft:glass
setblock ~43~11~39 minecraft:wool 2
setblock ~44~1~39 minecraft:glowstone
setblock ~44~11~39 minecraft:quartz_block 0
fill ~45~1~39 ~48~1~39 minecraft:quartz_block 0
fill ~45~12~39 ~46~12~39 minecraft:quartz_block 0
setblock ~47~12~39 minecraft:wool 2
setblock ~48~12~39 minecraft:fence 0
fill ~49~13~39 ~49~13~40 minecraft:fence 0
fill ~50~1~39 ~53~1~39 minecraft:quartz_block 0
fill ~52~10~39 ~52~11~43 minecraft:fence 0
fill ~54~2~39 ~54~7~39 minecraft:quartz_block 0
setblock ~54~8~39 minecraft:glowstone
fill ~54~12~39 ~54~12~42 minecraft:quartz_stairs 0
setblock ~54~16~39 minecraft:glowstone
fill ~54~17~39 ~54~18~39 minecraft:fence 0
fill ~55~13~39 ~55~13~42 minecraft:quartz_stairs 0
fill ~55~18~39 ~56~18~39 minecraft:fence 0
fill ~56~14~39 ~56~14~42 minecraft:quartz_stairs 0
fill ~0~14~40 ~0~14~41 minecraft:quartz_block 0
fill ~0~16~40 ~0~18~41 minecraft:quartz_block 0
setblock ~4~8~40 minecraft:quartz_stairs 7
setblock ~4~9~40 minecraft:quartz_stairs 2
fill ~8~13~40 ~9~13~40 minecraft:fence 0
setblock ~9~12~40 minecraft:fence 0
fill ~10~1~40 ~13~1~43 minecraft:glass
setblock ~10~12~40 minecraft:wool 5
setblock ~11~12~40 minecraft:quartz_block 0
fill ~12~12~40 ~13~13~41 minecraft:fence 0
setblock ~13~14~40 minecraft:glowstone
fill ~14~1~40 ~14~1~49 minecraft:quartz_block 0
fill ~14~12~40 ~14~12~41 minecraft:quartz_block 0
fill ~15~1~40 ~18~1~43 minecraft:glass
fill ~15~12~40 ~15~12~41 minecraft:wool 5
fill ~16~12~40 ~16~13~41 minecraft:fence 0
fill ~19~1~40 ~19~1~49 minecraft:quartz_block 0
fill ~20~1~40 ~23~1~43 minecraft:glass
fill ~24~1~40 ~24~1~49 minecraft:quartz_block 0
fill ~25~1~40 ~28~1~43 minecraft:glass
fill ~29~1~40 ~29~1~49 minecraft:quartz_block 0
fill ~30~1~40 ~33~1~43 minecraft:glass
fill ~34~1~40 ~34~1~49 minecraft:quartz_block 0
fill ~35~1~40 ~38~1~43 minecraft:glass
fill ~39~1~40 ~39~1~49 minecraft:quartz_block 0
fill ~40~1~40 ~43~1~43 minecraft:glass
fill ~42~12~40 ~42~12~41 minecraft:fence 0
fill ~43~12~40 ~43~12~41 minecraft:wool 2
fill ~44~1~40 ~44~1~49 minecraft:quartz_block 0
fill ~44~12~40 ~44~12~41 minecraft:quartz_block 0
fill ~45~1~40 ~48~1~43 minecraft:glass
fill ~45~12~40 ~46~13~41 minecraft:fence 0
setblock ~45~14~40 minecraft:glowstone
setblock ~47~12~40 minecraft:quartz_block 0
setblock ~48~12~40 minecraft:wool 2
setblock ~49~12~40 minecraft:fence 0
fill ~50~13~40 ~50~13~42 minecraft:fence 0
setblock ~54~8~40 minecraft:quartz_stairs 7
setblock ~54~9~40 minecraft:quartz_stairs 2
setblock ~58~15~40 minecraft:planks 2
setblock ~58~17~40 minecraft:planks 2
setblock ~4~9~41 minecraft:glowstone
setblock ~4~10~41 minecraft:quartz_block 0
fill ~8~12~41 ~8~13~42 minecraft:fence 0
fill ~9~12~41 ~9~12~42 minecraft:wool 5
fill ~10~12~41 ~10~12~42 minecraft:quartz_block 0
fill ~11~12~41 ~11~13~42 minecraft:fence 0
setblock ~12~14~41 minecraft:glowstone
setblock ~46~14~41 minecraft:glowstone
fill ~47~12~41 ~47~13~42 minecraft:fence 0
fill ~48~12~41 ~48~12~42 minecraft:quartz_block 0
fill ~49~12~41 ~49~12~42 minecraft:wool 2
fill ~50~12~41 ~50~12~42 minecraft:fence 0
setblock ~54~9~41 minecraft:glowstone
setblock ~54~10~41 minecraft:quartz_block 0
fill ~58~14~41 ~58~14~42 minecraft:planks 2
fill ~58~18~41 ~58~18~42 minecraft:planks 2
fill ~2~18~42 ~4~18~42 minecraft:fence 0
setblock ~4~8~42 minecraft:quartz_stairs 6
setblock ~4~9~42 minecraft:quartz_stairs 3
setblock ~4~16~42 minecraft:glowstone
setblock ~4~17~42 minecraft:fence 0
fill ~7~12~42 ~7~13~42 minecraft:fence 0
setblock ~11~14~42 minecraft:glowstone
fill ~12~12~42 ~12~13~42 minecraft:fence 0
setblock ~13~12~42 minecraft:quartz_block 0
setblock ~14~12~42 minecraft:wool 5
fill ~15~12~42 ~15~13~42 minecraft:fence 0
setblock ~16~13~42 minecraft:fence 0
fill ~43~12~42 ~43~13~42 minecraft:fence 0
setblock ~44~12~42 minecraft:wool 2
setblock ~45~12~42 minecraft:quartz_block 0
fill ~46~12~42 ~46~13~42 minecraft:fence 0
setblock ~47~14~42 minecraft:glowstone
fill ~51~12~42 ~51~13~42 minecraft:fence 0
setblock ~54~8~42 minecraft:quartz_stairs 6
setblock ~54~9~42 minecraft:quartz_stairs 3
setblock ~54~16~42 minecraft:glowstone
fill ~54~17~42 ~54~18~42 minecraft:fence 0
fill ~55~18~42 ~56~18~42 minecraft:fence 0
fill ~58~15~42 ~58~17~42 minecraft:planks 2
fill ~4~2~43 ~4~6~43 minecraft:quartz_block 0
setblock ~4~7~43 minecraft:wool 5
setblock ~4~8~43 minecraft:quartz_stairs 3
fill ~7~11~43 ~10~11~46 minecraft:quartz_block 0
setblock ~7~12~43 minecraft:quartz_block 0
fill ~8~12~43 ~10~12~43 minecraft:quartz_stairs 3
fill ~11~3~43 ~47~4~43 minecraft:quartz_block 1
fill ~11~12~43 ~12~12~43 minecraft:quartz_block 0
setblock ~13~12~43 minecraft:wool 5
fill ~14~12~43 ~14~13~43 minecraft:fence 0
setblock ~15~13~43 minecraft:fence 0
fill ~43~13~43 ~44~13~43 minecraft:fence 0
setblock ~44~12~43 minecraft:fence 0
setblock ~45~12~43 minecraft:wool 2
fill ~46~12~43 ~47~12~43 minecraft:quartz_block 0
fill ~48~11~43 ~51~11~46 minecraft:quartz_block 0
fill ~48~12~43 ~48~12~45 minecraft:quartz_stairs 1
fill ~49~12~43 ~50~12~43 minecraft:quartz_stairs 3
setblock ~51~12~43 minecraft:quartz_block 0
fill ~54~2~43 ~54~7~43 minecraft:quartz_block 0
setblock ~54~8~43 minecraft:quartz_stairs 3
fill ~5~0~44 ~9~0~44 minecraft:quartz_block 0
fill ~5~1~44 ~8~1~44 minecraft:quartz_block 0
fill ~5~2~44 ~5~16~44 minecraft:quartz_block 0
fill ~5~17~44 ~8~17~44 minecraft:glass
fill ~6~2~44 ~7~2~44 minecraft:wool 5
fill ~6~3~44 ~8~3~44 minecraft:quartz_block 0
fill ~6~4~44 ~7~4~44 minecraft:wool 5
fill ~6~5~44 ~8~5~44 minecraft:quartz_block 0
fill ~6~6~44 ~7~6~44 minecraft:wool 5
fill ~6~7~44 ~8~7~44 minecraft:quartz_block 0
fill ~6~8~44 ~7~8~44 minecraft:wool 5
fill ~6~9~44 ~8~9~44 minecraft:quartz_block 0
fill ~6~10~44 ~7~10~44 minecraft:wool 5
fill ~6~11~44 ~6~11~47 minecraft:quartz_block 0
fill ~6~12~44 ~6~15~44 minecraft:quartz_block 0
fill ~6~16~44 ~7~16~44 minecraft:wool 5
fill ~7~15~44 ~8~15~44 minecraft:quartz_block 0
setblock ~8~2~44 minecraft:quartz_block 0
setblock ~8~4~44 minecraft:quartz_block 0
setblock ~8~6~44 minecraft:quartz_block 0
setblock ~8~8~44 minecraft:quartz_block 0
setblock ~8~10~44 minecraft:quartz_block 0
setblock ~8~16~44 minecraft:quartz_block 0
fill ~10~1~44 ~13~1~44 minecraft:quartz_block 0
fill ~10~2~44 ~48~2~44 minecraft:quartz_block 1
fill ~10~12~44 ~10~12~45 minecraft:quartz_stairs 0
fill ~11~12~44 ~12~12~44 minecraft:wool 5
fill ~13~12~44 ~13~13~44 minecraft:fence 0
setblock ~14~13~44 minecraft:fence 0
fill ~15~1~44 ~18~1~44 minecraft:quartz_block 0
fill ~15~10~44 ~19~10~44 minecraft:fence 0
fill ~15~11~44 ~18~11~44 minecraft:fence 0
fill ~18~9~44 ~20~9~44 minecraft:fence 0
fill ~19~8~44 ~21~8~44 minecraft:fence 0
fill ~20~1~44 ~23~1~44 minecraft:quartz_block 0
fill ~20~7~44 ~22~7~44 minecraft:fence 0
fill ~21~6~44 ~23~6~44 minecraft:fence 0
fill ~22~5~44 ~28~5~44 minecraft:fence 0
fill ~23~4~44 ~28~4~44 minecraft:fence 0
fill ~25~1~44 ~28~1~44 minecraft:quartz_block 0
setblock ~28~6~44 minecraft:fence 0
setblock ~28~7~44 minecraft:glowstone
fill ~30~1~44 ~33~1~44 minecraft:quartz_block 0
fill ~30~4~44 ~34~5~44 minecraft:fence 0
setblock ~30~6~44 minecraft:fence 0
setblock ~30~7~44 minecraft:glowstone
fill ~35~1~44 ~38~1~44 minecraft:quartz_block 0
fill ~35~5~44 ~36~6~44 minecraft:fence 0
fill ~36~7~44 ~38~7~44 minecraft:fence 0
setblock ~37~6~44 minecraft:fence 0
fill ~37~8~44 ~39~8~44 minecraft:fence 0
fill ~38~9~44 ~40~9~44 minecraft:fence 0
fill ~39~10~44 ~43~10~44 minecraft:fence 0
fill ~40~1~44 ~43~1~44 minecraft:quartz_block 0
fill ~40~11~44 ~43~11~44 minecraft:fence 0
fill ~44~13~44 ~45~13~44 minecraft:fence 0
fill ~45~1~44 ~48~1~44 minecraft:quartz_block 0
setblock ~45~12~44 minecraft:fence 0
fill ~46~12~44 ~47~12~44 minecraft:wool 2
fill ~49~0~44 ~53~0~44 minecraft:quartz_block 0
fill ~50~1~44 ~53~1~44 minecraft:quartz_block 0
fill ~50~2~44 ~50~10~44 minecraft:quartz_block 0
fill ~50~15~44 ~53~15~44 minecraft:quartz_block 0
setblock ~50~16~44 minecraft:quartz_block 0
fill ~50~17~44 ~53~17~44 minecraft:glass
fill ~51~2~44 ~52~2~44 minecraft:wool 2
fill ~51~3~44 ~53~3~44 minecraft:quartz_block 0
fill ~51~4~44 ~52~4~44 minecraft:wool 2
fill ~51~5~44 ~53~5~44 minecraft:quartz_block 0
fill ~51~6~44 ~52~6~44 minecraft:wool 2
fill ~51~7~44 ~53~7~44 minecraft:quartz_block 0
fill ~51~8~44 ~52~8~44 minecraft:wool 2
fill ~51~9~44 ~53~9~44 minecraft:quartz_block 0
fill ~51~10~44 ~52~10~44 minecraft:wool 2
fill ~51~16~44 ~52~16~44 minecraft:wool 2
fill ~52~11~44 ~53~11~46 minecraft:quartz_block 0
fill ~52~12~44 ~53~14~44 minecraft:quartz_block 0
setblock ~53~2~44 minecraft:quartz_block 0
setblock ~53~4~44 minecraft:quartz_block 0
setblock ~53~6~44 minecraft:quartz_block 0
setblock ~53~8~44 minecraft:quartz_block 0
setblock ~53~10~44 minecraft:quartz_block 0
setblock ~53~16~44 minecraft:quartz_block 0
fill ~1~0~45 ~3~1~45 minecraft:quartz_block 0
fill ~1~2~45 ~1~2~49 minecraft:quartz_stairs 0
fill ~2~2~45 ~3~2~45 minecraft:quartz_stairs 2
setblock ~3~14~45 minecraft:quartz_stairs 4
fill ~3~15~45 ~4~16~45 minecraft:quartz_block 0
fill ~3~17~45 ~3~20~45 minecraft:quartz_block 0
fill ~4~2~45 ~4~14~45 minecraft:quartz_block 0
fill ~4~17~45 ~4~17~48 minecraft:glass
fill ~5~11~45 ~5~11~46 minecraft:quartz_block 0
setblock ~5~12~45 minecraft:chest 3
fill ~5~18~45 ~8~18~45 minecraft:glass
setblock ~8~10~45 minecraft:glowstone
fill ~9~0~45 ~9~0~49 minecraft:quartz_block 0
fill ~9~2~45 ~9~10~45 minecraft:quartz_block 0
fill ~9~15~45 ~9~15~48 minecraft:quartz_block 0
setblock ~9~16~45 minecraft:quartz_block 0
fill ~9~17~45 ~9~17~48 minecraft:glass
fill ~10~25~45 ~48~25~45 minecraft:glass
fill ~11~12~45 ~12~13~45 minecraft:fence 0
setblock ~13~13~45 minecraft:fence 0
fill ~15~10~45 ~15~11~47 minecraft:fence 0
fill ~16~10~45 ~18~10~46 minecraft:quartz_block 0
fill ~19~9~45 ~19~9~46 minecraft:quartz_block 0
fill ~20~8~45 ~20~8~46 minecraft:quartz_block 0
fill ~21~7~45 ~21~7~46 minecraft:quartz_block 0
fill ~22~6~45 ~22~6~46 minecraft:quartz_block 0
fill ~23~5~45 ~23~5~46 minecraft:quartz_block 0
fill ~24~4~45 ~27~4~46 minecraft:quartz_block 0
fill ~28~4~45 ~28~4~47 minecraft:fence 0
fill ~28~5~45 ~28~5~46 minecraft:fence 0
fill ~30~4~45 ~30~4~47 minecraft:fence 0
fill ~30~5~45 ~30~5~46 minecraft:fence 0
fill ~31~4~45 ~34~4~46 minecraft:quartz_block 0
fill ~35~5~45 ~35~5~46 minecraft:quartz_block 0
fill ~36~6~45 ~36~6~46 minecraft:quartz_block 0
fill ~37~7~45 ~37~7~46 minecraft:quartz_block 0
fill ~38~8~45 ~38~8~46 minecraft:quartz_block 0
fill ~39~9~45 ~39~9~46 minecraft:quartz_block 0
fill ~40~10~45 ~42~10~46 minecraft:quartz_block 0
fill ~43~10~45 ~43~11~47 minecraft:fence 0
fill ~45~13~45 ~47~13~45 minecraft:fence 0
fill ~46~12~45 ~47~12~45 minecraft:fence 0
fill ~49~0~45 ~49~0~49 minecraft:quartz_block 0
fill ~49~2~45 ~49~10~45 minecraft:quartz_block 0
fill ~49~15~45 ~49~15~48 minecraft:quartz_block 0
setblock ~49~16~45 minecraft:quartz_block 0
fill ~49~17~45 ~49~17~48 minecraft:glass
setblock ~50~10~45 minecraft:glowstone
fill ~50~18~45 ~53~18~45 minecraft:glass
setblock ~53~12~45 minecraft:chest 3
fill ~54~2~45 ~54~16~45 minecraft:quartz_block 0
fill ~54~17~45 ~54~17~48 minecraft:glass
fill ~55~0~45 ~57~1~45 minecraft:quartz_block 0
fill ~55~2~45 ~57~2~45 minecraft:quartz_stairs 2
setblock ~55~14~45 minecraft:quartz_stairs 5
fill ~55~15~45 ~55~20~45 minecraft:quartz_block 0
fill ~1~0~46 ~1~1~50 minecraft:quartz_block 0
fill ~2~2~46 ~3~2~49 minecraft:quartz_block 0
fill ~2~3~46 ~2~5~46 minecraft:quartz_block 0
fill ~4~3~46 ~4~3~48 minecraft:quartz_block 0
fill ~4~4~46 ~4~4~47 minecraft:wool 5
fill ~4~5~46 ~4~5~48 minecraft:quartz_block 0
fill ~4~6~46 ~4~6~47 minecraft:wool 5
fill ~4~7~46 ~4~7~48 minecraft:quartz_block 0
fill ~4~8~46 ~4~8~47 minecraft:wool 5
fill ~4~9~46 ~4~9~48 minecraft:quartz_block 0
fill ~4~10~46 ~4~10~47 minecraft:wool 5
fill ~4~11~46 ~4~11~48 minecraft:quartz_block 0
fill ~4~12~46 ~4~12~47 minecraft:wool 5
fill ~4~13~46 ~4~13~48 minecraft:quartz_block 0
fill ~4~14~46 ~4~14~47 minecraft:wool 5
fill ~4~15~46 ~4~15~48 minecraft:quartz_block 0
fill ~4~16~46 ~4~16~47 minecraft:wool 5
fill ~5~18~46 ~5~18~48 minecraft:glass
fill ~6~18~46 ~7~18~47 minecraft:glowstone
fill ~6~19~46 ~7~19~47 minecraft:glass
fill ~8~18~46 ~8~18~48 minecraft:glass
fill ~9~2~46 ~9~2~47 minecraft:wool 5
fill ~9~3~46 ~9~3~48 minecraft:quartz_block 0
fill ~9~4~46 ~9~4~47 minecraft:wool 5
fill ~9~5~46 ~9~5~48 minecraft:quartz_block 0
fill ~9~6~46 ~9~6~47 minecraft:wool 5
fill ~9~7~46 ~9~7~48 minecraft:quartz_block 0
fill ~9~8~46 ~9~8~47 minecraft:wool 5
fill ~9~9~46 ~9~9~48 minecraft:quartz_block 0
fill ~9~10~46 ~9~10~47 minecraft:wool 5
fill ~9~16~46 ~9~16~47 minecraft:wool 5
setblock ~10~12~46 minecraft:quartz_block 0
fill ~10~24~46 ~48~24~46 minecraft:glass
fill ~11~12~46 ~11~13~46 minecraft:fence 0
fill ~28~3~46 ~28~3~48 minecraft:fence 0
fill ~30~3~46 ~30~3~48 minecraft:fence 0
fill ~47~12~46 ~47~13~46 minecraft:fence 0
setblock ~48~12~46 minecraft:quartz_block 0
fill ~49~2~46 ~49~2~47 minecraft:wool 2
fill ~49~3~46 ~49~3~48 minecraft:quartz_block 0
fill ~49~4~46 ~49~4~47 minecraft:wool 2
fill ~49~5~46 ~49~5~48 minecraft:quartz_block 0
fill ~49~6~46 ~49~6~47 minecraft:wool 2
fill ~49~7~46 ~49~7~48 minecraft:quartz_block 0
fill ~49~8~46 ~49~8~47 minecraft:wool 2
fill ~49~9~46 ~49~9~48 minecraft:quartz_block 0
fill ~49~10~46 ~49~10~47 minecraft:wool 2
fill ~49~16~46 ~49~16~47 minecraft:wool 2
fill ~50~18~46 ~50~18~48 minecraft:glass
fill ~51~18~46 ~52~18~47 minecraft:glowstone
fill ~51~19~46 ~52~19~47 minecraft:glass
fill ~53~18~46 ~53~18~48 minecraft:glass
fill ~54~3~46 ~54~3~48 minecraft:quartz_block 0
fill ~54~4~46 ~54~4~47 minecraft:wool 2
fill ~54~5~46 ~54~5~48 minecraft:quartz_block 0
fill ~54~6~46 ~54~6~47 minecraft:wool 2
fill ~54~7~46 ~54~7~48 minecraft:quartz_block 0
fill ~54~8~46 ~54~8~47 minecraft:wool 2
fill ~54~9~46 ~54~9~48 minecraft:quartz_block 0
fill ~54~10~46 ~54~10~47 minecraft:wool 2
fill ~54~11~46 ~54~11~48 minecraft:quartz_block 0
fill ~54~12~46 ~54~12~47 minecraft:wool 2
fill ~54~13~46 ~54~13~48 minecraft:quartz_block 0
fill ~54~14~46 ~54~14~47 minecraft:wool 2
fill ~54~15~46 ~54~15~48 minecraft:quartz_block 0
fill ~54~16~46 ~54~16~47 minecraft:wool 2
fill ~55~2~46 ~56~2~49 minecraft:quartz_block 0
fill ~56~3~46 ~56~5~46 minecraft:quartz_block 0
fill ~57~0~46 ~57~1~50 minecraft:quartz_block 0
fill ~57~2~46 ~57~2~49 minecraft:quartz_stairs 1
setblock ~4~0~47 minecraft:wool 5
fill ~4~1~47 ~4~1~48 minecraft:quartz_block 0
setblock ~4~2~47 minecraft:wool 5
fill ~5~0~47 ~5~10~47 minecraft:ladder 2
fill ~7~11~47 ~9~11~48 minecraft:quartz_block 0
fill ~9~12~47 ~9~14~48 minecraft:quartz_block 0
fill ~10~10~47 ~14~11~47 minecraft:fence 0
fill ~10~23~47 ~48~23~47 minecraft:glass
fill ~16~10~47 ~17~10~47 minecraft:quartz_block 0
fill ~18~10~47 ~40~11~47 minecraft:fence 0
fill ~26~3~47 ~27~3~47 minecraft:quartz_block 0
fill ~28~2~47 ~28~2~48 minecraft:fence 0
fill ~30~2~47 ~30~2~48 minecraft:fence 0
fill ~31~3~47 ~32~3~47 minecraft:quartz_block 0
fill ~41~10~47 ~42~10~47 minecraft:quartz_block 0
fill ~44~10~47 ~48~11~47 minecraft:fence 0
fill ~49~11~47 ~52~11~47 minecraft:quartz_block 0
fill ~49~12~47 ~49~14~48 minecraft:quartz_block 0
fill ~53~0~47 ~53~10~47 minecraft:ladder 2
setblock ~54~0~47 minecraft:wool 2
fill ~54~1~47 ~54~1~48 minecraft:quartz_block 0
setblock ~54~2~47 minecraft:wool 2
setblock ~3~14~48 minecraft:quartz_stairs 4
fill ~3~15~48 ~3~20~48 minecraft:quartz_block 0
fill ~4~0~48 ~5~0~48 minecraft:quartz_block 0
fill ~4~2~48 ~5~2~48 minecraft:quartz_block 0
fill ~4~4~48 ~5~4~48 minecraft:quartz_block 0
fill ~4~6~48 ~5~6~48 minecraft:quartz_block 0
fill ~4~8~48 ~5~8~48 minecraft:quartz_block 0
fill ~4~10~48 ~5~10~48 minecraft:quartz_block 0
setblock ~4~12~48 minecraft:quartz_block 0
setblock ~4~14~48 minecraft:quartz_block 0
setblock ~4~16~48 minecraft:quartz_block 0
fill ~5~1~48 ~5~1~49 minecraft:quartz_block 0
fill ~5~3~48 ~5~3~49 minecraft:quartz_block 0
fill ~5~5~48 ~5~5~49 minecraft:quartz_block 0
fill ~5~7~48 ~5~7~49 minecraft:quartz_block 0
fill ~5~9~48 ~5~9~49 minecraft:quartz_block 0
fill ~6~0~48 ~6~10~48 minecraft:ladder 5
fill ~6~18~48 ~7~18~48 minecraft:glass
setblock ~8~12~48 minecraft:chest 4
setblock ~9~2~48 minecraft:quartz_block 0
setblock ~9~4~48 minecraft:quartz_block 0
setblock ~9~6~48 minecraft:quartz_block 0
setblock ~9~8~48 minecraft:quartz_block 0
setblock ~9~10~48 minecraft:quartz_block 0
setblock ~9~16~48 minecraft:quartz_block 0
fill ~10~10~48 ~48~10~48 minecraft:wool 15
fill ~10~22~48 ~48~22~48 minecraft:glass
fill ~26~2~48 ~27~2~48 minecraft:quartz_block 0
fill ~31~2~48 ~32~2~48 minecraft:quartz_block 0
setblock ~49~2~48 minecraft:quartz_block 0
setblock ~49~4~48 minecraft:quartz_block 0
setblock ~49~6~48 minecraft:quartz_block 0
setblock ~49~8~48 minecraft:quartz_block 0
fill ~49~10~48 ~49~11~48 minecraft:quartz_block 0
setblock ~49~16~48 minecraft:quartz_block 0
fill ~50~11~48 ~51~11~49 minecraft:quartz_block 0
setblock ~50~12~48 minecraft:chest 5
fill ~51~18~48 ~52~18~48 minecraft:glass
fill ~52~0~48 ~52~10~48 minecraft:ladder 4
fill ~53~0~48 ~54~0~48 minecraft:quartz_block 0
fill ~53~1~48 ~53~10~49 minecraft:quartz_block 0
setblock ~54~2~48 minecraft:quartz_block 0
setblock ~54~4~48 minecraft:quartz_block 0
setblock ~54~6~48 minecraft:quartz_block 0
setblock ~54~8~48 minecraft:quartz_block 0
setblock ~54~10~48 minecraft:quartz_block 0
setblock ~54~12~48 minecraft:quartz_block 0
setblock ~54~14~48 minecraft:quartz_block 0
fill ~54~16~48 ~55~16~48 minecraft:quartz_block 0
setblock ~55~14~48 minecraft:quartz_stairs 5
setblock ~55~15~48 minecraft:quartz_block 0
fill ~55~17~48 ~55~20~48 minecraft:quartz_block 0
setblock ~4~2~49 minecraft:glowstone
setblock ~5~0~49 minecraft:quartz_block 0
fill ~5~2~49 ~5~2~51 minecraft:quartz_block 0
setblock ~5~4~49 minecraft:quartz_block 0
setblock ~5~6~49 minecraft:quartz_block 0
setblock ~5~8~49 minecraft:quartz_block 0
fill ~5~10~49 ~5~16~49 minecraft:quartz_block 0
fill ~5~17~49 ~8~17~49 minecraft:glass
setblock ~6~0~49 minecraft:wool 5
setblock ~6~1~49 minecraft:quartz_block 0
setblock ~6~2~49 minecraft:wool 5
fill ~6~3~49 ~8~3~49 minecraft:quartz_block 0
fill ~6~4~49 ~7~4~49 minecraft:wool 5
fill ~6~5~49 ~8~5~49 minecraft:quartz_block 0
fill ~6~6~49 ~7~6~49 minecraft:wool 5
fill ~6~7~49 ~8~7~49 minecraft:quartz_block 0
fill ~6~8~49 ~7~8~49 minecraft:wool 5
fill ~6~9~49 ~8~9~49 minecraft:quartz_block 0
fill ~6~10~49 ~7~10~49 minecraft:wool 5
fill ~6~11~49 ~8~11~49 minecraft:quartz_block 0
fill ~6~12~49 ~7~12~49 minecraft:wool 5
fill ~6~13~49 ~8~13~49 minecraft:quartz_block 0
fill ~6~14~49 ~7~14~49 minecraft:wool 5
fill ~6~15~49 ~8~15~49 minecraft:quartz_block 0
fill ~6~16~49 ~7~16~49 minecraft:wool 5
fill ~8~0~49 ~8~1~52 minecraft:quartz_block 0
setblock ~8~2~49 minecraft:quartz_block 0
setblock ~8~4~49 minecraft:quartz_block 0
setblock ~8~6~49 minecraft:quartz_block 0
setblock ~8~8~49 minecraft:quartz_block 0
setblock ~8~10~49 minecraft:quartz_block 0
setblock ~8~12~49 minecraft:quartz_block 0
setblock ~8~14~49 minecraft:quartz_block 0
fill ~8~16~49 ~8~16~50 minecraft:quartz_block 0
fill ~10~0~49 ~48~0~49 minecraft:quartz_block 0
fill ~10~1~49 ~13~1~49 minecraft:quartz_block 0
fill ~10~2~49 ~10~7~49 minecraft:quartz_block 0
setblock ~10~8~49 minecraft:quartz_stairs 0
fill ~10~11~49 ~48~11~49 minecraft:wool 15
fill ~10~21~49 ~48~21~49 minecraft:glass
setblock ~11~8~49 minecraft:quartz_stairs 5
setblock ~11~9~49 minecraft:quartz_stairs 0
fill ~11~12~49 ~14~12~49 minecraft:quartz_stairs 2
setblock ~11~16~49 minecraft:glowstone
fill ~11~17~49 ~11~18~49 minecraft:fence 0
setblock ~12~9~49 minecraft:glowstone
setblock ~12~10~49 minecraft:quartz_block 0
setblock ~13~8~49 minecraft:quartz_stairs 4
setblock ~13~9~49 minecraft:quartz_stairs 1
fill ~14~2~49 ~14~7~49 minecraft:quartz_block 0
setblock ~14~8~49 minecraft:glowstone
setblock ~14~16~49 minecraft:glowstone
fill ~14~17~49 ~14~18~49 minecraft:fence 0
fill ~15~1~49 ~18~1~49 minecraft:quartz_block 0
setblock ~15~8~49 minecraft:quartz_stairs 5
setblock ~15~9~49 minecraft:quartz_stairs 0
setblock ~16~9~49 minecraft:quartz_stairs 5
setblock ~16~10~49 minecraft:quartz_stairs 0
setblock ~17~9~49 minecraft:quartz_stairs 4
setblock ~17~10~49 minecraft:quartz_stairs 1
setblock ~18~8~49 minecraft:quartz_stairs 4
setblock ~18~9~49 minecraft:quartz_stairs 1
fill ~19~2~49 ~19~7~49 minecraft:quartz_block 0
setblock ~19~8~49 minecraft:glowstone
fill ~19~12~49 ~22~12~49 minecraft:quartz_stairs 2
setblock ~19~16~49 minecraft:glowstone
fill ~19~17~49 ~19~18~49 minecraft:fence 0
fill ~20~1~49 ~23~1~49 minecraft:quartz_block 0
setblock ~20~8~49 minecraft:quartz_stairs 5
setblock ~20~9~49 minecraft:quartz_stairs 0
setblock ~21~9~49 minecraft:quartz_stairs 5
setblock ~21~10~49 minecraft:quartz_stairs 0
setblock ~22~9~49 minecraft:quartz_stairs 4
setblock ~22~10~49 minecraft:quartz_stairs 1
setblock ~22~16~49 minecraft:glowstone
fill ~22~17~49 ~22~18~49 minecraft:fence 0
setblock ~23~8~49 minecraft:quartz_stairs 4
setblock ~23~9~49 minecraft:quartz_stairs 1
fill ~24~2~49 ~24~7~49 minecraft:quartz_block 0
setblock ~24~8~49 minecraft:glowstone
fill ~25~1~49 ~28~1~49 minecraft:quartz_block 0
setblock ~25~8~49 minecraft:quartz_stairs 5
setblock ~25~9~49 minecraft:quartz_stairs 0
fill ~25~12~49 ~28~12~49 minecraft:quartz_stairs 2
setblock ~25~16~49 minecraft:glowstone
fill ~25~17~49 ~25~18~49 minecraft:fence 0
setblock ~26~9~49 minecraft:quartz_stairs 5
setblock ~26~10~49 minecraft:quartz_stairs 0
setblock ~27~9~49 minecraft:quartz_stairs 4
setblock ~27~10~49 minecraft:quartz_stairs 1
setblock ~28~8~49 minecraft:quartz_stairs 4
setblock ~28~9~49 minecraft:quartz_stairs 1
setblock ~28~16~49 minecraft:glowstone
fill ~28~17~49 ~28~18~49 minecraft:fence 0
fill ~29~2~49 ~29~7~49 minecraft:quartz_block 0
setblock ~29~8~49 minecraft:glowstone
fill ~30~1~49 ~33~1~49 minecraft:quartz_block 0
setblock ~30~8~49 minecraft:quartz_stairs 5
setblock ~30~9~49 minecraft:quartz_stairs 0
fill ~30~12~49 ~33~12~49 minecraft:quartz_stairs 2
setblock ~30~16~49 minecraft:glowstone
fill ~30~17~49 ~30~18~49 minecraft:fence 0
setblock ~31~9~49 minecraft:quartz_stairs 5
setblock ~31~10~49 minecraft:quartz_stairs 0
setblock ~32~9~49 minecraft:quartz_stairs 4
setblock ~32~10~49 minecraft:quartz_stairs 1
setblock ~33~8~49 minecraft:quartz_stairs 4
setblock ~33~9~49 minecraft:quartz_stairs 1
setblock ~33~16~49 minecraft:glowstone
fill ~33~17~49 ~33~18~49 minecraft:fence 0
fill ~34~2~49 ~34~7~49 minecraft:quartz_block 0
setblock ~34~8~49 minecraft:glowstone
fill ~35~1~49 ~38~1~49 minecraft:quartz_block 0
setblock ~35~8~49 minecraft:quartz_stairs 5
setblock ~35~9~49 minecraft:quartz_stairs 0
setblock ~36~9~49 minecraft:quartz_stairs 5
setblock ~36~10~49 minecraft:quartz_stairs 0
fill ~36~12~49 ~39~12~49 minecraft:quartz_stairs 2
setblock ~36~16~49 minecraft:glowstone
fill ~36~17~49 ~36~18~49 minecraft:fence 0
setblock ~37~9~49 minecraft:quartz_stairs 4
setblock ~37~10~49 minecraft:quartz_stairs 1
setblock ~38~8~49 minecraft:quartz_stairs 4
setblock ~38~9~49 minecraft:quartz_stairs 1
fill ~39~2~49 ~39~7~49 minecraft:quartz_block 0
setblock ~39~8~49 minecraft:glowstone
setblock ~39~16~49 minecraft:glowstone
fill ~39~17~49 ~39~18~49 minecraft:fence 0
fill ~40~1~49 ~43~1~49 minecraft:quartz_block 0
setblock ~40~8~49 minecraft:quartz_stairs 5
setblock ~40~9~49 minecraft:quartz_stairs 0
setblock ~41~9~49 minecraft:quartz_stairs 5
setblock ~41~10~49 minecraft:quartz_stairs 0
setblock ~42~9~49 minecraft:quartz_stairs 4
setblock ~42~10~49 minecraft:quartz_stairs 1
setblock ~43~8~49 minecraft:quartz_stairs 4
setblock ~43~9~49 minecraft:quartz_stairs 1
fill ~44~2~49 ~44~7~49 minecraft:quartz_block 0
setblock ~44~8~49 minecraft:glowstone
fill ~44~12~49 ~47~12~49 minecraft:quartz_stairs 2
setblock ~44~16~49 minecraft:glowstone
fill ~44~17~49 ~44~18~49 minecraft:fence 0
fill ~45~1~49 ~48~1~49 minecraft:quartz_block 0
setblock ~45~8~49 minecraft:quartz_stairs 5
setblock ~45~9~49 minecraft:quartz_stairs 0
setblock ~46~9~49 minecraft:glowstone
setblock ~46~10~49 minecraft:quartz_block 0
setblock ~47~8~49 minecraft:quartz_stairs 4
setblock ~47~9~49 minecraft:quartz_stairs 1
setblock ~47~16~49 minecraft:glowstone
fill ~47~17~49 ~47~18~49 minecraft:fence 0
fill ~48~2~49 ~48~7~49 minecraft:quartz_block 0
setblock ~48~8~49 minecraft:quartz_stairs 1
fill ~50~0~49 ~50~1~52 minecraft:quartz_block 0
fill ~50~2~49 ~50~10~49 minecraft:quartz_block 0
fill ~50~12~49 ~50~16~49 minecraft:quartz_block 0
fill ~50~17~49 ~53~17~49 minecraft:glass
fill ~51~3~49 ~52~3~49 minecraft:quartz_block 0
fill ~51~4~49 ~52~4~49 minecraft:wool 2
fill ~51~5~49 ~52~5~49 minecraft:quartz_block 0
fill ~51~6~49 ~52~6~49 minecraft:wool 2
fill ~51~7~49 ~52~7~49 minecraft:quartz_block 0
fill ~51~8~49 ~52~8~49 minecraft:wool 2
fill ~51~9~49 ~52~9~49 minecraft:quartz_block 0
fill ~51~10~49 ~52~10~49 minecraft:wool 2
fill ~51~12~49 ~52~12~49 minecraft:wool 2
fill ~51~13~49 ~53~13~49 minecraft:quartz_block 0
fill ~51~14~49 ~52~14~49 minecraft:wool 2
fill ~51~15~49 ~53~15~49 minecraft:quartz_block 0
fill ~51~16~49 ~52~16~49 minecraft:wool 2
setblock ~52~0~49 minecraft:wool 2
setblock ~52~1~49 minecraft:quartz_block 0
setblock ~52~2~49 minecraft:wool 2
fill ~52~11~49 ~53~11~49 minecraft:quartz_block 0
setblock ~53~0~49 minecraft:quartz_block 0
setblock ~53~12~49 minecraft:quartz_block 0
setblock ~53~14~49 minecraft:quartz_block 0
fill ~53~16~49 ~53~16~50 minecraft:quartz_block 0
setblock ~54~2~49 minecraft:glowstone
setblock ~0~0~50 minecraft:fence 0
setblock ~0~1~50 minecraft:glowstone
setblock ~1~2~50 minecraft:quartz_stairs 3
fill ~2~2~50 ~2~5~50 minecraft:quartz_block 0
setblock ~3~2~50 minecraft:glowstone
fill ~4~2~50 ~4~2~51 minecraft:quartz_block 0
setblock ~5~14~50 minecraft:quartz_stairs 7
fill ~5~15~50 ~5~20~50 minecraft:quartz_block 0
fill ~6~2~50 ~7~2~51 minecraft:quartz_block 0
fill ~8~2~50 ~8~2~52 minecraft:quartz_stairs 1
setblock ~8~14~50 minecraft:quartz_stairs 7
setblock ~8~15~50 minecraft:quartz_block 0
fill ~8~17~50 ~8~20~50 minecraft:quartz_block 0
fill ~10~12~50 ~48~12~50 minecraft:wool 15
fill ~10~20~50 ~48~20~50 minecraft:glass
fill ~11~13~50 ~14~13~50 minecraft:quartz_stairs 2
fill ~11~18~50 ~11~18~51 minecraft:fence 0
fill ~14~18~50 ~14~18~51 minecraft:fence 0
fill ~19~13~50 ~22~13~50 minecraft:quartz_stairs 2
fill ~19~18~50 ~19~18~51 minecraft:fence 0
fill ~22~18~50 ~22~18~51 minecraft:fence 0
fill ~25~0~50 ~25~0~51 minecraft:quartz_stairs 0
fill ~25~13~50 ~28~13~50 minecraft:quartz_stairs 2
fill ~25~18~50 ~25~18~51 minecraft:fence 0
fill ~26~0~50 ~27~0~50 minecraft:quartz_block 0
fill ~26~1~50 ~27~1~50 minecraft:quartz_stairs 3
fill ~28~0~50 ~28~0~51 minecraft:quartz_stairs 1
fill ~28~18~50 ~28~18~51 minecraft:fence 0
setblock ~30~0~50 minecraft:quartz_stairs 0
fill ~30~13~50 ~33~13~50 minecraft:quartz_stairs 2
fill ~30~18~50 ~30~18~51 minecraft:fence 0
fill ~31~0~50 ~32~0~50 minecraft:quartz_block 0
fill ~31~1~50 ~32~1~50 minecraft:quartz_stairs 3
fill ~33~0~50 ~33~0~51 minecraft:quartz_stairs 1
fill ~33~18~50 ~33~18~51 minecraft:fence 0
fill ~36~13~50 ~39~13~50 minecraft:quartz_stairs 2
fill ~36~18~50 ~36~18~51 minecraft:fence 0
fill ~39~18~50 ~39~18~51 minecraft:fence 0
fill ~44~13~50 ~47~13~50 minecraft:quartz_stairs 2
fill ~44~18~50 ~44~18~51 minecraft:fence 0
fill ~47~18~50 ~47~18~51 minecraft:fence 0
fill ~50~2~50 ~50~2~51 minecraft:quartz_stairs 0
setblock ~50~14~50 minecraft:quartz_stairs 7
fill ~50~15~50 ~50~20~50 minecraft:quartz_block 0
fill ~51~2~50 ~54~2~51 minecraft:quartz_block 0
setblock ~53~14~50 minecraft:quartz_stairs 7
setblock ~53~15~50 minecraft:quartz_block 0
fill ~53~17~50 ~53~20~50 minecraft:quartz_block 0
setblock ~55~2~50 minecraft:glowstone
fill ~56~2~50 ~56~5~50 minecraft:quartz_block 0
setblock ~57~2~50 minecraft:quartz_stairs 3
setblock ~58~0~50 minecraft:fence 0
setblock ~58~1~50 minecraft:glowstone
fill ~3~2~51 ~3~5~51 minecraft:quartz_block 0
fill ~7~3~51 ~7~5~51 minecraft:quartz_block 0
fill ~10~13~51 ~48~13~52 minecraft:wool 15
fill ~10~19~51 ~48~19~52 minecraft:wool 15
fill ~11~14~51 ~14~14~51 minecraft:quartz_stairs 2
fill ~19~14~51 ~22~14~51 minecraft:quartz_stairs 2
fill ~25~14~51 ~28~14~51 minecraft:quartz_stairs 2
fill ~26~0~51 ~27~0~51 minecraft:quartz_stairs 3
fill ~30~0~51 ~32~0~51 minecraft:quartz_stairs 3
fill ~30~14~51 ~33~14~51 minecraft:quartz_stairs 2
fill ~36~14~51 ~39~14~51 minecraft:quartz_stairs 2
fill ~44~14~51 ~47~14~51 minecraft:quartz_stairs 2
fill ~51~3~51 ~51~5~51 minecraft:quartz_block 0
fill ~55~2~51 ~55~5~51 minecraft:quartz_block 0
fill ~3~0~52 ~7~1~52 minecraft:quartz_block 0
setblock ~3~2~52 minecraft:quartz_stairs 0
fill ~4~2~52 ~7~2~52 minecraft:quartz_stairs 3
fill ~10~14~52 ~48~18~52 minecraft:wool 15
fill ~50~2~52 ~54~2~52 minecraft:quartz_stairs 3
fill ~51~0~52 ~55~1~52 minecraft:quartz_block 0
setblock ~55~2~52 minecraft:quartz_stairs 1
setblock ~3~0~53 minecraft:fence 0
setblock ~3~1~53 minecraft:glowstone
setblock ~11~16~53 minecraft:quartz_block 0
fill ~12~15~53 ~14~15~53 minecraft:quartz_block 0
setblock ~12~17~53 minecraft:quartz_block 0
setblock ~13~18~53 minecraft:quartz_block 0
setblock ~14~14~53 minecraft:quartz_block 0
setblock ~14~16~53 minecraft:quartz_block 0
fill ~16~14~53 ~16~18~53 minecraft:quartz_block 0
fill ~17~16~53 ~18~16~53 minecraft:quartz_block 0
fill ~17~18~53 ~18~18~53 minecraft:quartz_block 0
setblock ~19~17~53 minecraft:quartz_block 0
fill ~21~15~53 ~21~18~53 minecraft:quartz_block 0
fill ~22~14~53 ~23~14~53 minecraft:quartz_block 0
fill ~25~14~53 ~25~17~53 minecraft:quartz_block 0
fill ~26~16~53 ~28~16~53 minecraft:quartz_block 0
fill ~26~18~53 ~27~18~53 minecraft:quartz_block 0
fill ~28~14~53 ~28~15~53 minecraft:quartz_block 0
setblock ~28~17~53 minecraft:quartz_block 0
fill ~30~14~53 ~31~14~53 minecraft:quartz_block 0
setblock ~30~18~53 minecraft:quartz_block 0
setblock ~31~17~53 minecraft:quartz_block 0
fill ~32~15~53 ~32~16~53 minecraft:quartz_block 0
fill ~33~16~53 ~33~18~53 minecraft:quartz_block 0
fill ~35~15~53 ~35~17~53 minecraft:quartz_block 0
fill ~36~14~53 ~38~14~53 minecraft:quartz_block 0
fill ~36~16~53 ~37~16~53 minecraft:quartz_block 0
fill ~36~18~53 ~38~18~53 minecraft:quartz_block 0
fill ~40~14~53 ~40~18~53 minecraft:quartz_block 0
fill ~41~16~53 ~42~16~53 minecraft:quartz_block 0
fill ~41~18~53 ~42~18~53 minecraft:quartz_block 0
fill ~43~14~53 ~43~15~53 minecraft:quartz_block 0
setblock ~43~17~53 minecraft:quartz_block 0
fill ~45~14~53 ~46~14~53 minecraft:quartz_block 0
setblock ~45~17~53 minecraft:quartz_block 0
setblock ~46~16~53 minecraft:quartz_block 0
fill ~46~18~53 ~47~18~53 minecraft:quartz_block 0
setblock ~47~15~53 minecraft:quartz_block 0
setblock ~55~0~53 minecraft:fence 0
setblock ~55~1~53 minecraft:glowstone