fill ~62~0~3 ~65~0~4 minecraft:mycelium
fill ~61~0~4 ~61~0~5 minecraft:mycelium
fill ~66~0~4 ~70~0~4 minecraft:mycelium
setblock ~60~0~5 minecraft:mycelium
fill ~62~0~5 ~63~0~5 minecraft:mycelium
fill ~64~0~5 ~69~0~7 minecraft:stone 0
fill ~64~1~5 ~69~1~5 minecraft:mycelium
fill ~70~0~5 ~72~0~5 minecraft:mycelium
setblock ~58~0~6 minecraft:mycelium
fill ~59~0~6 ~63~0~7 minecraft:stone 0
fill ~59~1~6 ~61~1~6 minecraft:mycelium
fill ~62~1~6 ~68~1~7 minecraft:stone 0
fill ~62~2~6 ~68~2~6 minecraft:mycelium
fill ~69~1~6 ~70~1~6 minecraft:mycelium
fill ~70~0~6 ~70~0~23 minecraft:stone 0
fill ~71~0~6 ~74~0~6 minecraft:mycelium
fill ~56~0~7 ~57~0~7 minecraft:mycelium
fill ~58~0~7 ~58~0~14 minecraft:stone 0
fill ~58~1~7 ~59~1~7 minecraft:mycelium
fill ~60~1~7 ~61~1~12 minecraft:stone 0
fill ~60~2~7 ~62~2~8 minecraft:mycelium
fill ~63~2~7 ~66~2~14 minecraft:stone 0
fill ~63~3~7 ~66~3~8 minecraft:mycelium
fill ~67~2~7 ~70~2~7 minecraft:mycelium
fill ~69~1~7 ~70~1~19 minecraft:stone 0
fill ~71~0~7 ~73~0~23 minecraft:stone 0
fill ~71~1~7 ~73~1~7 minecraft:mycelium
fill ~74~0~7 ~78~0~7 minecraft:mycelium
fill ~54~0~8 ~56~0~8 minecraft:mycelium
fill ~57~0~8 ~57~0~14 minecraft:stone 0
fill ~57~1~8 ~58~1~8 minecraft:mycelium
fill ~59~0~8 ~61~0~8 minecraft:stone 0
fill ~59~1~8 ~59~1~14 minecraft:stone 0
setblock ~59~2~8 minecraft:mycelium
setblock ~62~0~8 minecraft:minecraft:sandstone
fill ~62~1~8 ~63~1~8 minecraft:stone 0
setblock ~63~0~8 minecraft:stone 0
setblock ~64~0~8 minecraft:mycelium
fill ~65~0~8 ~66~1~11 minecraft:stone 0
fill ~67~1~8 ~68~2~13 minecraft:stone 0
fill ~67~3~8 ~68~3~8 minecraft:mycelium
fill ~68~0~8 ~69~0~12 minecraft:stone 0
fill ~69~2~8 ~73~2~8 minecraft:mycelium
fill ~71~1~8 ~73~1~22 minecraft:stone 0
fill ~74~0~8 ~79~0~13 minecraft:stone 0
fill ~74~1~8 ~76~1~8 minecraft:mycelium
fill ~77~1~8 ~77~1~14 minecraft:stone 0
fill ~77~2~8 ~77~2~9 minecraft:mycelium
fill ~78~1~8 ~79~1~8 minecraft:mycelium
fill ~49~0~9 ~53~0~9 minecraft:mycelium
fill ~54~0~9 ~56~0~11 minecraft:stone 0
fill ~54~1~9 ~55~1~9 minecraft:mycelium
fill ~56~1~9 ~58~1~15 minecraft:stone 0
fill ~56~2~9 ~58~2~9 minecraft:mycelium
fill ~59~0~9 ~60~0~9 minecraft:stone 0
fill ~59~2~9 ~62~2~13 minecraft:stone 0
fill ~59~3~9 ~60~3~9 minecraft:mycelium
fill ~61~0~9 ~61~0~24 minecraft:minecraft:sandstone
fill ~61~3~9 ~68~3~14 minecraft:stone 0
fill ~61~4~9 ~68~4~9 minecraft:mycelium
fill ~62~0~9 ~62~1~11 minecraft:stone 0
setblock ~63~0~9 minecraft:mycelium
fill ~64~0~9 ~64~1~12 minecraft:stone 0
setblock ~67~0~9 minecraft:dirt 0
setblock ~69~2~9 minecraft:dirt 0
fill ~69~3~9 ~73~3~9 minecraft:mycelium
fill ~70~2~9 ~73~2~19 minecraft:stone 0
fill ~74~1~9 ~76~1~15 minecraft:stone 0
fill ~74~2~9 ~76~2~9 minecraft:mycelium
fill ~78~1~9 ~81~1~13 minecraft:stone 0
fill ~78~2~9 ~81~2~9 minecraft:mycelium
fill ~80~0~9 ~82~0~9 minecraft:stone 0
setblock ~82~1~9 minecraft:mycelium
setblock ~48~0~10 minecraft:mycelium
fill ~49~0~10 ~53~1~10 minecraft:stone 0
fill ~49~2~10 ~56~2~10 minecraft:mycelium
fill ~54~1~10 ~55~1~11 minecraft:stone 0
fill ~57~2~10 ~58~2~15 minecraft:stone 0
fill ~57~3~10 ~59~3~10 minecraft:mycelium
fill ~59~0~10 ~59~0~13 minecraft:stone 0
fill ~60~0~10 ~60~0~23 minecraft:minecraft:sandstone
fill ~60~3~10 ~60~3~14 minecraft:stone 0
fill ~60~4~10 ~62~4~10 minecraft:mycelium
fill ~63~1~10 ~63~1~13 minecraft:stone 0
fill ~63~4~10 ~67~4~15 minecraft:stone 0
fill ~63~5~10 ~67~5~11 minecraft:mycelium
fill ~67~0~10 ~67~0~11 minecraft:stone 0
fill ~68~4~10 ~72~4~10 minecraft:mycelium
fill ~69~2~10 ~69~3~13 minecraft:stone 0
fill ~70~3~10 ~72~3~18 minecraft:stone 0
fill ~73~3~10 ~81~3~10 minecraft:mycelium
fill ~74~2~10 ~81~2~17 minecraft:stone 0
fill ~80~0~10 ~81~0~62 minecraft:stone 0
fill ~82~1~10 ~83~1~12 minecraft:stone 0
fill ~82~2~10 ~83~2~10 minecraft:mycelium
fill ~83~0~10 ~83~0~12 minecraft:stone 0
setblock ~45~0~11 minecraft:mycelium
fill ~48~3~11 ~52~3~16 minecraft:stone 0
fill ~48~4~11 ~49~4~11 minecraft:mycelium
fill ~49~0~11 ~51~2~11 minecraft:stone 0
fill ~50~4~11 ~52~5~11 minecraft:stone 0
fill ~50~6~11 ~62~6~11 minecraft:mycelium
fill ~52~1~11 ~52~2~13 minecraft:stone 0
setblock ~53~0~11 minecraft:mycelium
fill ~53~2~11 ~56~2~11 minecraft:stone 0
setblock ~53~3~11 minecraft:mycelium
fill ~53~5~11 ~62~5~16 minecraft:stone 0
fill ~54~3~11 ~59~4~15 minecraft:stone 0
fill ~60~4~11 ~62~4~16 minecraft:stone 0
fill ~63~0~11 ~63~0~12 minecraft:stone 0
fill ~68~4~11 ~77~4~16 minecraft:stone 0
fill ~68~5~11 ~77~5~11 minecraft:mycelium
fill ~73~3~11 ~80~3~21 minecraft:stone 0
fill ~78~4~11 ~80~4~11 minecraft:mycelium
fill ~81~3~11 ~82~3~11 minecraft:mycelium
fill ~82~0~11 ~82~0~79 minecraft:stone 0
fill ~82~2~11 ~82~2~32 minecraft:stone 0
fill ~83~2~11 ~83~2~12 minecraft:mycelium
fill ~32~0~12 ~34~0~12 minecraft:mycelium
fill ~35~0~12 ~47~0~12 minecraft:stone 0
fill ~35~1~12 ~37~1~12 minecraft:mycelium
fill ~38~1~12 ~47~1~15 minecraft:stone 0
fill ~38~2~12 ~51~2~14 minecraft:stone 0
fill ~38~3~12 ~47~3~13 minecraft:stone 0
fill ~38~4~12 ~46~4~12 minecraft:mycelium
fill ~47~4~12 ~51~4~17 minecraft:stone 0
setblock ~47~5~12 minecraft:mycelium
fill ~48~5~12 ~52~5~17 minecraft:stone 0
fill ~48~6~12 ~50~6~12 minecraft:mycelium
fill ~49~1~12 ~51~1~14 minecraft:stone 0
fill ~50~0~12 ~52~0~13 minecraft:stone 0
fill ~51~6~12 ~61~6~17 minecraft:stone 0
fill ~51~7~12 ~61~7~12 minecraft:mycelium
setblock ~52~4~12 minecraft:dirt 0
fill ~53~1~12 ~53~4~14 minecraft:stone 0
setblock ~54~0~12 minecraft:mycelium
fill ~55~0~12 ~56~0~12 minecraft:stone 0
fill ~55~1~12 ~55~2~12 minecraft:stone 0
fill ~56~2~12 ~56~2~16 minecraft:stone 0
fill ~62~0~12 ~62~0~24 minecraft:minecraft:sandstone
fill ~62~1~12 ~62~1~13 minecraft:stone 0
fill ~62~6~12 ~71~6~12 minecraft:mycelium
fill ~63~5~12 ~71~5~15 minecraft:stone 0
fill ~65~0~12 ~65~1~12 minecraft:stone 0
fill ~66~0~12 ~67~0~13 minecraft:minecraft:sandstone
fill ~66~1~12 ~66~1~13 minecraft:stone 0
fill ~72~5~12 ~79~5~12 minecraft:mycelium
fill ~78~4~12 ~79~4~54 minecraft:stone 0
fill ~80~4~12 ~81~4~12 minecraft:mycelium
fill ~81~3~12 ~81~3~20 minecraft:stone 0
fill ~82~3~12 ~82~3~13 minecraft:mycelium
fill ~84~0~12 ~84~0~20 minecraft:stone 0
setblock ~84~1~12 minecraft:mycelium
fill ~28~0~13 ~30~0~13 minecraft:mycelium
fill ~31~0~13 ~35~0~84 minecraft:stone 0
fill ~31~1~13 ~34~1~13 minecraft:mycelium
fill ~35~1~13 ~37~1~84 minecraft:stone 0
fill ~35~2~13 ~37~2~17 minecraft:stone 0
fill ~35~3~13 ~35~4~13 minecraft:stone 0
setblock ~35~5~13 minecraft:mycelium
setblock ~36~0~13 minecraft:dirt 0
setblock ~36~3~13 minecraft:dirt 0
fill ~36~4~13 ~46~4~17 minecraft:stone 0
fill ~36~5~13 ~37~5~19 minecraft:stone 0
fill ~36~6~13 ~37~6~13 minecraft:mycelium
fill ~37~0~13 ~37~0~85 minecraft:stone 0
fill ~37~3~13 ~37~3~18 minecraft:stone 0
fill ~38~5~13 ~46~5~13 minecraft:mycelium
fill ~39~0~13 ~47~0~13 minecraft:stone 0
fill ~47~5~13 ~47~5~19 minecraft:stone 0
setblock ~47~6~13 minecraft:mycelium
fill ~48~1~13 ~48~1~14 minecraft:stone 0
fill ~48~6~13 ~50~6~18 minecraft:stone 0
fill ~48~7~13 ~51~7~13 minecraft:mycelium
fill ~49~0~13 ~49~0~14 minecraft:stone 0
fill ~52~4~13 ~52~4~16 minecraft:stone 0
fill ~52~7~13 ~59~7~18 minecraft:stone 0
fill ~52~8~13 ~59~8~13 minecraft:mycelium
setblock ~53~0~13 minecraft:stone 0
fill ~54~1~13 ~54~2~15 minecraft:stone 0
setblock ~55~0~13 minecraft:mycelium
fill ~56~0~13 ~56~0~14 minecraft:stone 0
setblock ~60~1~13 minecraft:stone 0
fill ~60~7~13 ~70~7~13 minecraft:mycelium
fill ~61~1~13 ~61~1~25 minecraft:minecraft:sandstone
fill ~62~6~13 ~70~6~15 minecraft:stone 0
fill ~63~0~13 ~64~0~25 minecraft:minecraft:sandstone
fill ~64~1~13 ~65~1~13 minecraft:stone 0
setblock ~68~0~13 minecraft:minecraft:sandstone
fill ~69~0~13 ~69~0~21 minecraft:stone 0
fill ~71~6~13 ~77~6~13 minecraft:mycelium
fill ~72~5~13 ~77~5~25 minecraft:stone 0
fill ~78~5~13 ~80~5~13 minecraft:mycelium
fill ~80~4~13 ~80~4~57 minecraft:stone 0
fill ~81~4~13 ~81~4~14 minecraft:mycelium
fill ~82~1~13 ~82~1~33 minecraft:stone 0
fill ~84~1~13 ~84~1~20 minecraft:stone 0
fill ~84~2~13 ~84~2~20 minecraft:mycelium
fill ~26~0~14 ~28~0~14 minecraft:mycelium
fill ~29~0~14 ~30~0~84 minecraft:stone 0
fill ~29~1~14 ~30~1~14 minecraft:mycelium
fill ~31~1~14 ~34~1~84 minecraft:stone 0
fill ~31~2~14 ~32~2~14 minecraft:mycelium
fill ~33~2~14 ~34~2~83 minecraft:stone 0
fill ~33~3~14 ~35~3~14 minecraft:dirt 0
fill ~33~4~14 ~35~4~15 minecraft:stone 0
fill ~33~5~14 ~35~5~14 minecraft:stone 0
fill ~33~6~14 ~34~6~14 minecraft:mycelium
fill ~35~6~14 ~43~6~14 minecraft:stone 0
fill ~35~7~14 ~46~7~14 minecraft:mycelium
fill ~36~0~14 ~36~0~84 minecraft:stone 0
fill ~36~3~14 ~36~3~80 minecraft:stone 0
fill ~38~0~14 ~43~0~84 minecraft:stone 0
fill ~38~3~14 ~39~3~17 minecraft:stone 0
fill ~38~5~14 ~46~5~17 minecraft:stone 0
setblock ~40~3~14 minecraft:dirt 0
fill ~41~3~14 ~47~3~16 minecraft:stone 0
setblock ~44~0~14 minecraft:dirt 0
setblock ~44~6~14 minecraft:dirt 0
fill ~45~0~14 ~48~0~15 minecraft:stone 0
fill ~45~6~14 ~47~6~20 minecraft:stone 0
fill ~47~7~14 ~51~7~17 minecraft:stone 0
fill ~47~8~14 ~50~8~14 minecraft:mycelium
fill ~50~0~14 ~53~0~17 minecraft:minecraft:sandstone
fill ~51~8~14 ~56~8~17 minecraft:stone 0
fill ~51~9~14 ~56~9~14 minecraft:mycelium
fill ~52~1~14 ~52~1~18 minecraft:minecraft:sandstone
fill ~52~2~14 ~52~2~15 minecraft:stone 0
fill ~55~0~14 ~55~2~14 minecraft:stone 0
fill ~57~8~14 ~58~8~14 minecraft:mycelium
fill ~59~0~14 ~59~0~22 minecraft:minecraft:sandstone
fill ~59~2~14 ~60~2~14 minecraft:stone 0
fill ~59~8~14 ~67~8~18 minecraft:stone 0
fill ~59~9~14 ~67~9~14 minecraft:mycelium
fill ~60~1~14 ~60~1~24 minecraft:minecraft:sandstone
fill ~60~7~14 ~65~7~18 minecraft:stone 0
fill ~61~2~14 ~61~2~27 minecraft:minecraft:sandstone
fill ~62~1~14 ~67~1~14 minecraft:minecraft:sandstone
setblock ~62~2~14 minecraft:stone 0
fill ~65~0~14 ~65~0~28 minecraft:minecraft:sandstone
setblock ~66~7~14 minecraft:dirt 0
fill ~67~0~14 ~67~0~15 minecraft:minecraft:sandstone
fill ~67~2~14 ~68~2~14 minecraft:stone 0
fill ~67~7~14 ~70~7~19 minecraft:stone 0
fill ~68~0~14 ~68~0~19 minecraft:stone 0
setblock ~68~1~14 minecraft:stone 0
fill ~68~8~14 ~70~8~14 minecraft:mycelium
setblock ~69~2~14 minecraft:dirt 0
fill ~69~3~14 ~69~3~16 minecraft:stone 0
fill ~71~6~14 ~72~6~24 minecraft:stone 0
fill ~71~7~14 ~72~7~14 minecraft:mycelium
fill ~73~6~14 ~78~6~14 minecraft:mycelium
fill ~74~0~14 ~77~0~14 minecraft:stone 0
fill ~78~0~14 ~78~0~20 minecraft:minecraft:sandstone
setblock ~78~1~14 minecraft:minecraft:sandstone
fill ~78~5~14 ~78~5~54 minecraft:stone 0
fill ~79~0~14 ~79~1~18 minecraft:stone 0
fill ~79~5~14 ~80~5~15 minecraft:mycelium
fill ~80~1~14 ~81~1~20 minecraft:stone 0
fill ~82~3~14 ~82~3~24 minecraft:stone 0
fill ~82~4~14 ~82~4~20 minecraft:mycelium
fill ~83~0~14 ~83~1~22 minecraft:stone 0
fill ~83~2~14 ~83~2~20 minecraft:stone 0
fill ~83~3~14 ~83~3~20 minecraft:mycelium
setblock ~85~0~14 minecraft:stone 0
fill ~85~1~14 ~85~1~20 minecraft:mycelium
fill ~18~0~15 ~20~0~15 minecraft:mycelium
fill ~21~0~15 ~28~0~18 minecraft:stone 0
fill ~21~1~15 ~25~1~15 minecraft:mycelium
fill ~26~1~15 ~30~1~82 minecraft:stone 0
fill ~26~2~15 ~28~2~15 minecraft:mycelium
fill ~29~2~15 ~32~2~78 minecraft:stone 0
fill ~29~3~15 ~29~4~15 minecraft:dirt 0
fill ~29~5~15 ~33~5~15 minecraft:stone 0
fill ~29~6~15 ~30~6~15 minecraft:mycelium
fill ~30~3~15 ~35~3~15 minecraft:stone 0
fill ~30~4~15 ~32~4~18 minecraft:stone 0
setblock ~31~6~15 minecraft:dirt 0
fill ~31~7~15 ~33~7~15 minecraft:mycelium
fill ~32~6~15 ~33~6~15 minecraft:stone 0
setblock ~34~5~15 minecraft:mycelium
fill ~34~8~15 ~36~8~15 minecraft:mycelium
fill ~35~5~15 ~35~7~17 minecraft:stone 0
fill ~36~6~15 ~40~7~15 minecraft:stone 0
fill ~37~8~15 ~40~8~20 minecraft:stone 0
fill ~37~9~15 ~38~9~15 minecraft:mycelium
fill ~38~2~15 ~45~2~15 minecraft:stone 0
fill ~39~9~15 ~40~9~20 minecraft:stone 0
fill ~39~10~15 ~45~10~15 minecraft:mycelium
fill ~40~3~15 ~40~3~17 minecraft:stone 0
fill ~41~6~15 ~43~6~15 minecraft:mycelium
setblock ~44~0~15 minecraft:stone 0
fill ~44~6~15 ~44~7~19 minecraft:stone 0
fill ~44~8~15 ~50~8~15 minecraft:stone 0
fill ~44~9~15 ~45~9~15 minecraft:stone 0
fill ~45~7~15 ~46~7~20 minecraft:stone 0
fill ~46~2~15 ~47~2~18 minecraft:minecraft:sandstone
setblock ~46~9~15 minecraft:mycelium
fill ~47~9~15 ~68~9~19 minecraft:stone 0
fill ~47~10~15 ~68~10~15 minecraft:mycelium
fill ~48~1~15 ~51~1~18 minecraft:minecraft:sandstone
fill ~48~2~15 ~51~2~15 minecraft:stone 0
fill ~49~0~15 ~49~0~17 minecraft:minecraft:sandstone
fill ~53~1~15 ~53~1~20 minecraft:minecraft:sandstone
fill ~53~2~15 ~53~4~15 minecraft:stone 0
fill ~54~0~15 ~58~0~19 minecraft:minecraft:sandstone
fill ~55~1~15 ~55~2~15 minecraft:stone 0
fill ~57~8~15 ~58~8~18 minecraft:stone 0
fill ~59~1~15 ~59~1~23 minecraft:minecraft:sandstone
setblock ~59~2~15 minecraft:stone 0
fill ~60~2~15 ~60~3~26 minecraft:minecraft:sandstone
fill ~61~3~15 ~62~3~29 minecraft:minecraft:sandstone
fill ~62~1~15 ~65~2~26 minecraft:minecraft:sandstone
fill ~63~3~15 ~65~3~15 minecraft:stone 0
fill ~66~0~15 ~66~0~29 minecraft:minecraft:sandstone
fill ~66~2~15 ~67~2~28 minecraft:minecraft:sandstone
fill ~66~3~15 ~66~3~28 minecraft:minecraft:sandstone
fill ~66~7~15 ~66~7~19 minecraft:stone 0
fill ~67~3~15 ~68~3~15 minecraft:stone 0
fill ~68~1~15 ~68~1~28 minecraft:minecraft:sandstone
fill ~68~2~15 ~69~2~15 minecraft:stone 0
fill ~68~8~15 ~70~8~21 minecraft:stone 0
fill ~69~9~15 ~70~9~15 minecraft:mycelium
fill ~71~7~15 ~71~7~26 minecraft:stone 0
setblock ~71~8~15 minecraft:mycelium
fill ~72~7~15 ~77~7~15 minecraft:mycelium
fill ~73~6~15 ~77~6~26 minecraft:stone 0
fill ~74~0~15 ~76~0~15 minecraft:stone 0
fill ~77~0~15 ~77~0~21 minecraft:minecraft:sandstone
fill ~77~1~15 ~77~1~19 minecraft:minecraft:sandstone
fill ~78~1~15 ~78~1~17 minecraft:stone 0
setblock ~78~6~15 minecraft:mycelium
fill ~81~4~15 ~81~4~24 minecraft:stone 0
fill ~81~5~15 ~81~5~24 minecraft:mycelium
setblock ~85~0~15 minecraft:dirt 0
setblock ~16~0~16 minecraft:mycelium
fill ~17~0~16 ~20~0~22 minecraft:stone 0
fill ~17~1~16 ~19~1~16 minecraft:mycelium
fill ~20~1~16 ~25~1~20 minecraft:stone 0
fill ~20~2~16 ~23~2~16 minecraft:mycelium
fill ~24~2~16 ~28~2~19 minecraft:stone 0
fill ~24~3~16 ~26~3~16 minecraft:mycelium
fill ~27~3~16 ~33~3~19 minecraft:stone 0
fill ~27~4~16 ~28~4~16 minecraft:mycelium
fill ~28~6~16 ~30~7~19 minecraft:stone 0
fill ~28~8~16 ~30~8~16 minecraft:mycelium
fill ~29~4~16 ~29~5~17 minecraft:stone 0
fill ~30~5~16 ~31~5~19 minecraft:stone 0
setblock ~31~6~16 minecraft:mycelium
fill ~31~9~16 ~34~9~16 minecraft:mycelium
fill ~32~5~16 ~33~5~16 minecraft:mycelium
fill ~33~4~16 ~33~4~20 minecraft:stone 0
fill ~33~8~16 ~36~8~19 minecraft:stone 0
setblock ~34~3~16 minecraft:mycelium
fill ~34~5~16 ~34~5~20 minecraft:stone 0
fill ~34~7~16 ~34~7~20 minecraft:stone 0
fill ~35~3~16 ~35~3~83 minecraft:stone 0
fill ~35~4~16 ~35~4~20 minecraft:stone 0
fill ~35~9~16 ~38~9~20 minecraft:stone 0
fill ~35~10~16 ~37~10~16 minecraft:mycelium
fill ~36~6~16 ~37~7~20 minecraft:stone 0
fill ~38~1~16 ~44~2~16 minecraft:stone 0
setblock ~38~6~16 minecraft:dirt 0
fill ~38~7~16 ~41~7~19 minecraft:stone 0
fill ~38~10~16 ~55~10~19 minecraft:stone 0
fill ~38~11~16 ~55~11~16 minecraft:mycelium
fill ~39~6~16 ~41~6~19 minecraft:stone 0
fill ~41~8~16 ~41~9~20 minecraft:stone 0
fill ~42~6~16 ~43~6~16 minecraft:mycelium
fill ~42~9~16 ~43~9~19 minecraft:stone 0
fill ~44~0~16 ~45~0~16 minecraft:minecraft:sandstone
setblock ~44~8~16 minecraft:mycelium
fill ~45~1~16 ~45~2~17 minecraft:minecraft:sandstone
fill ~45~8~16 ~50~8~18 minecraft:stone 0
fill ~45~9~16 ~46~9~20 minecraft:stone 0
fill ~46~0~16 ~46~0~85 minecraft:stone 0
setblock ~46~1~16 minecraft:stone 0
fill ~47~0~16 ~48~0~16 minecraft:minecraft:sandstone
fill ~47~1~16 ~47~1~17 minecraft:minecraft:sandstone
fill ~48~2~16 ~54~2~19 minecraft:minecraft:sandstone
fill ~53~3~16 ~53~3~23 minecraft:minecraft:sandstone
fill ~53~4~16 ~58~4~16 minecraft:stone 0
fill ~54~1~16 ~58~1~20 minecraft:minecraft:sandstone
fill ~54~3~16 ~58~3~16 minecraft:stone 0
setblock ~55~2~16 minecraft:stone 0
setblock ~56~10~16 minecraft:mycelium
setblock ~57~2~16 minecraft:stone 0
fill ~57~10~16 ~68~10~19 minecraft:stone 0
fill ~57~11~16 ~68~11~16 minecraft:mycelium
fill ~58~2~16 ~59~2~24 minecraft:minecraft:sandstone
fill ~59~3~16 ~59~4~27 minecraft:minecraft:sandstone
fill ~62~6~16 ~66~6~16 minecraft:stone 0
fill ~63~3~16 ~65~4~28 minecraft:minecraft:sandstone
fill ~63~5~16 ~64~5~16 minecraft:stone 0
fill ~65~5~16 ~67~5~34 minecraft:minecraft:sandstone
fill ~66~1~16 ~67~1~28 minecraft:minecraft:sandstone
fill ~66~4~16 ~67~4~30 minecraft:minecraft:sandstone
fill ~67~3~16 ~68~3~26 minecraft:minecraft:sandstone
setblock ~67~6~16 minecraft:dirt 0
fill ~68~2~16 ~68~2~28 minecraft:minecraft:sandstone
fill ~68~5~16 ~71~5~16 minecraft:stone 0
fill ~68~6~16 ~70~6~18 minecraft:stone 0
fill ~69~2~16 ~69~2~17 minecraft:stone 0
fill ~69~9~16 ~69~9~26 minecraft:stone 0
fill ~69~10~16 ~69~10~17 minecraft:mycelium
fill ~70~9~16 ~71~9~16 minecraft:mycelium
fill ~71~8~16 ~71~8~28 minecraft:stone 0
fill ~72~7~16 ~77~7~23 minecraft:stone 0
fill ~72~8~16 ~77~8~16 minecraft:mycelium
fill ~74~0~16 ~74~1~16 minecraft:stone 0
fill ~75~0~16 ~76~0~18 minecraft:minecraft:sandstone
setblock ~75~1~16 minecraft:stone 0
fill ~76~1~16 ~76~1~20 minecraft:minecraft:sandstone
fill ~78~6~16 ~78~6~38 minecraft:stone 0
fill ~78~7~16 ~78~7~28 minecraft:mycelium
fill ~79~5~16 ~79~5~55 minecraft:stone 0
fill ~79~6~16 ~79~6~28 minecraft:mycelium
fill ~80~5~16 ~80~5~17 minecraft:mycelium
fill ~85~0~16 ~85~0~20 minecraft:stone 0
setblock ~14~0~17 minecraft:mycelium
fill ~15~0~17 ~16~0~70 minecraft:stone 0
fill ~15~1~17 ~17~1~17 minecraft:mycelium
fill ~18~1~17 ~19~1~23 minecraft:stone 0
fill ~18~2~17 ~20~2~17 minecraft:mycelium
fill ~21~2~17 ~23~2~74 minecraft:stone 0
fill ~21~3~17 ~22~3~17 minecraft:mycelium
fill ~23~3~17 ~26~3~21 minecraft:stone 0
fill ~23~4~17 ~25~4~17 minecraft:mycelium
fill ~26~4~17 ~28~5~19 minecraft:stone 0
fill ~26~6~17 ~27~7~22 minecraft:stone 0
setblock ~26~8~17 minecraft:mycelium
fill ~27~8~17 ~32~8~19 minecraft:stone 0
setblock ~27~9~17 minecraft:mycelium
fill ~28~9~17 ~34~9~21 minecraft:stone 0
fill ~28~10~17 ~28~10~18 minecraft:mycelium
fill ~29~10~17 ~37~10~17 minecraft:stone 0
fill ~29~11~17 ~35~11~17 minecraft:mycelium
fill ~31~6~17 ~34~6~20 minecraft:stone 0
fill ~31~7~17 ~33~7~19 minecraft:stone 0
fill ~32~5~17 ~33~5~20 minecraft:stone 0
fill ~34~3~17 ~34~3~83 minecraft:stone 0
fill ~34~4~17 ~34~4~20 minecraft:stone 0
fill ~36~11~17 ~65~11~17 minecraft:stone 0
fill ~36~12~17 ~37~12~17 minecraft:mycelium
fill ~38~1~17 ~42~1~84 minecraft:stone 0
fill ~38~2~17 ~38~2~18 minecraft:minecraft:sandstone
fill ~38~6~17 ~38~6~20 minecraft:stone 0
fill ~38~12~17 ~58~12~17 minecraft:stone 0
fill ~38~13~17 ~58~13~17 minecraft:mycelium
fill ~39~2~17 ~43~2~17 minecraft:stone 0
fill ~41~3~17 ~43~3~17 minecraft:stone 0
fill ~42~6~17 ~43~8~18 minecraft:stone 0
fill ~43~1~17 ~44~1~17 minecraft:minecraft:sandstone
fill ~44~0~17 ~45~0~85 minecraft:stone 0
fill ~44~2~17 ~44~3~18 minecraft:minecraft:sandstone
fill ~44~8~17 ~44~9~20 minecraft:stone 0
fill ~45~3~17 ~47~3~17 minecraft:stone 0
setblock ~46~1~17 minecraft:minecraft:sandstone
fill ~47~0~17 ~48~0~81 minecraft:stone 0
fill ~48~3~17 ~52~3~20 minecraft:minecraft:sandstone
fill ~52~4~17 ~58~4~24 minecraft:minecraft:sandstone
fill ~53~5~17 ~57~5~17 minecraft:stone 0
fill ~54~3~17 ~58~3~23 minecraft:minecraft:sandstone
fill ~55~2~17 ~57~2~22 minecraft:minecraft:sandstone
fill ~56~10~17 ~56~10~19 minecraft:stone 0
fill ~58~5~17 ~58~5~30 minecraft:minecraft:sandstone
fill ~59~5~17 ~63~5~17 minecraft:stone 0
fill ~59~12~17 ~67~12~17 minecraft:mycelium
fill ~60~4~17 ~62~4~30 minecraft:minecraft:sandstone
fill ~62~6~17 ~64~6~17 minecraft:stone 0
fill ~64~5~17 ~64~5~34 minecraft:minecraft:sandstone
fill ~65~6~17 ~65~6~34 minecraft:minecraft:sandstone
fill ~66~6~17 ~67~6~17 minecraft:stone 0
setblock ~66~11~17 minecraft:dirt 0
fill ~67~0~17 ~67~0~31 minecraft:minecraft:sandstone
fill ~67~11~17 ~67~11~27 minecraft:stone 0
fill ~68~4~17 ~69~5~35 minecraft:minecraft:sandstone
setblock ~68~11~17 minecraft:mycelium
fill ~69~3~17 ~69~3~35 minecraft:minecraft:sandstone
fill ~70~4~17 ~77~4~17 minecraft:stone 0
fill ~70~5~17 ~71~5~17 minecraft:stone 0
fill ~70~9~17 ~70~9~27 minecraft:stone 0
fill ~70~10~17 ~70~10~18 minecraft:mycelium
fill ~71~9~17 ~73~9~17 minecraft:mycelium
fill ~72~8~17 ~73~8~31 minecraft:stone 0
setblock ~74~0~17 minecraft:minecraft:sandstone
fill ~74~1~17 ~74~1~55 minecraft:stone 0
fill ~74~8~17 ~77~8~17 minecraft:mycelium
fill ~75~1~17 ~75~1~18 minecraft:minecraft:sandstone
fill ~13~0~18 ~14~0~26 minecraft:stone 0
fill ~13~1~18 ~16~1~18 minecraft:mycelium
fill ~17~1~18 ~17~1~24 minecraft:stone 0
fill ~17~2~18 ~18~2~18 minecraft:mycelium
fill ~19~2~18 ~20~2~24 minecraft:stone 0
fill ~19~3~18 ~20~3~18 minecraft:mycelium
fill ~21~3~18 ~22~3~23 minecraft:stone 0
fill ~21~4~18 ~23~4~18 minecraft:mycelium
fill ~24~4~18 ~25~7~21 minecraft:stone 0
setblock ~24~8~18 minecraft:mycelium
fill ~25~8~18 ~26~8~25 minecraft:stone 0
setblock ~25~9~18 minecraft:mycelium
fill ~26~9~18 ~27~9~24 minecraft:stone 0
setblock ~26~10~18 minecraft:mycelium
fill ~27~10~18 ~27~10~24 minecraft:stone 0
setblock ~27~11~18 minecraft:mycelium
fill ~28~12~18 ~57~12~18 minecraft:stone 0
fill ~28~13~18 ~37~13~18 minecraft:mycelium
setblock ~29~4~18 minecraft:dirt 0
setblock ~29~5~18 minecraft:stone 0
fill ~29~10~18 ~31~11~22 minecraft:stone 0
setblock ~32~10~18 minecraft:dirt 0
fill ~32~11~18 ~48~11~21 minecraft:stone 0
fill ~33~10~18 ~37~10~20 minecraft:stone 0
fill ~35~2~18 ~36~2~84 minecraft:stone 0
setblock ~35~5~18 minecraft:dirt 0
fill ~35~6~18 ~35~7~20 minecraft:stone 0
fill ~36~4~18 ~39~4~18 minecraft:stone 0
setblock ~37~2~18 minecraft:minecraft:sandstone
fill ~38~3~18 ~43~3~19 minecraft:minecraft:sandstone
fill ~38~5~18 ~41~5~18 minecraft:stone 0
fill ~38~13~18 ~52~13~20 minecraft:stone 0
fill ~38~14~18 ~52~14~18 minecraft:mycelium
fill ~39~2~18 ~41~2~18 minecraft:minecraft:sandstone
fill ~40~4~18 ~43~4~20 minecraft:minecraft:sandstone
fill ~42~2~18 ~42~2~83 minecraft:stone 0
fill ~42~5~18 ~42~5~20 minecraft:minecraft:sandstone
fill ~43~1~18 ~47~1~80 minecraft:stone 0
setblock ~43~2~18 minecraft:minecraft:sandstone
fill ~43~5~18 ~46~5~18 minecraft:stone 0
fill ~44~4~18 ~48~4~18 minecraft:stone 0
fill ~45~2~18 ~45~3~18 minecraft:minecraft:sandstone
fill ~46~3~18 ~47~3~20 minecraft:minecraft:sandstone
fill ~47~7~18 ~50~7~18 minecraft:stone 0
fill ~48~5~18 ~49~5~18 minecraft:stone 0
fill ~49~0~18 ~51~0~81 minecraft:stone 0
fill ~49~4~18 ~51~4~22 minecraft:minecraft:sandstone
setblock ~49~11~18 minecraft:dirt 0
fill ~50~5~18 ~57~5~23 minecraft:minecraft:sandstone
fill ~50~11~18 ~66~11~18 minecraft:stone 0
fill ~51~6~18 ~52~6~23 minecraft:minecraft:sandstone
fill ~51~7~18 ~51~7~22 minecraft:minecraft:sandstone
setblock ~51~8~18 minecraft:dirt 0
setblock ~52~0~18 minecraft:minecraft:sandstone
fill ~52~8~18 ~56~8~19 minecraft:stone 0
fill ~53~0~18 ~53~0~83 minecraft:stone 0
fill ~53~6~18 ~57~6~18 minecraft:stone 0
setblock ~53~13~18 minecraft:mycelium
fill ~54~13~18 ~58~13~23 minecraft:dirt 0
fill ~54~14~18 ~58~14~18 minecraft:mycelium
fill ~58~6~18 ~58~6~31 minecraft:minecraft:sandstone
fill ~58~12~18 ~58~12~24 minecraft:dirt 0
fill ~59~5~18 ~63~5~31 minecraft:minecraft:sandstone
fill ~59~6~18 ~63~6~18 minecraft:stone 0
fill ~59~12~18 ~66~12~18 minecraft:stone 0
fill ~59~13~18 ~66~13~18 minecraft:mycelium
fill ~64~6~18 ~64~6~34 minecraft:minecraft:sandstone
fill ~66~6~18 ~66~6~35 minecraft:minecraft:sandstone
setblock ~67~6~18 minecraft:stone 0
fill ~67~12~18 ~68~12~19 minecraft:mycelium
fill ~68~11~18 ~68~11~28 minecraft:stone 0
fill ~69~2~18 ~69~2~35 minecraft:minecraft:sandstone
fill ~69~10~18 ~69~10~28 minecraft:stone 0
fill ~69~11~18 ~69~11~19 minecraft:mycelium
fill ~70~4~18 ~70~5~35 minecraft:minecraft:sandstone
fill ~71~4~18 ~77~4~18 minecraft:stone 0
fill ~71~5~18 ~71~5~19 minecraft:stone 0
fill ~71~9~18 ~72~9~34 minecraft:stone 0
fill ~71~10~18 ~72~10~19 minecraft:mycelium
fill ~73~9~18 ~75~9~18 minecraft:mycelium
fill ~74~0~18 ~74~0~23 minecraft:stone 0
fill ~74~2~18 ~76~2~54 minecraft:stone 0
fill ~74~8~18 ~75~8~23 minecraft:stone 0
fill ~76~8~18 ~77~8~18 minecraft:mycelium
setblock ~77~2~18 minecraft:minecraft:sandstone
fill ~78~1~18 ~78~1~19 minecraft:minecraft:sandstone
fill ~78~2~18 ~81~2~20 minecraft:stone 0
fill ~80~5~18 ~80~5~20 minecraft:stone 0
fill ~80~6~18 ~80~6~20 minecraft:mycelium
fill ~12~0~19 ~12~0~20 minecraft:mycelium
fill ~13~1~19 ~14~1~19 minecraft:mycelium
fill ~15~1~19 ~16~1~25 minecraft:stone 0
fill ~15~2~19 ~16~2~19 minecraft:mycelium
fill ~17~2~19 ~18~2~24 minecraft:stone 0
fill ~17~3~19 ~18~3~19 minecraft:mycelium
fill ~19~3~19 ~20~3~19 minecraft:stone 0
fill ~19~4~19 ~20~4~19 minecraft:mycelium
setblock ~21~0~19 minecraft:dirt 0
fill ~21~4~19 ~23~4~24 minecraft:stone 0
setblock ~21~5~19 minecraft:mycelium
fill ~22~0~19 ~28~0~82 minecraft:stone 0
fill ~22~5~19 ~23~6~25 minecraft:stone 0
setblock ~22~7~19 minecraft:mycelium
fill ~23~7~19 ~23~7~27 minecraft:stone 0
setblock ~23~8~19 minecraft:mycelium
fill ~24~8~19 ~24~8~27 minecraft:stone 0
setblock ~24~9~19 minecraft:mycelium
fill ~25~9~19 ~25~9~26 minecraft:stone 0
setblock ~25~10~19 minecraft:mycelium
fill ~26~10~19 ~26~10~25 minecraft:stone 0
setblock ~26~11~19 minecraft:mycelium
fill ~27~11~19 ~28~12~23 minecraft:stone 0
fill ~27~13~19 ~37~13~19 minecraft:stone 0
fill ~27~14~19 ~37~14~19 minecraft:mycelium
fill ~28~10~19 ~28~10~23 minecraft:stone 0
fill ~29~4~19 ~29~4~20 minecraft:minecraft:sandstone
setblock ~29~5~19 minecraft:minecraft:sandstone
fill ~29~12~19 ~53~12~20 minecraft:stone 0
fill ~30~4~19 ~31~4~19 minecraft:stone 0
setblock ~32~4~19 minecraft:dirt 0
fill ~32~10~19 ~32~10~22 minecraft:stone 0
fill ~35~5~19 ~35~5~20 minecraft:stone 0
setblock ~36~4~19 minecraft:stone 0
fill ~37~2~19 ~41~2~84 minecraft:stone 0
fill ~37~3~19 ~37~4~19 minecraft:minecraft:sandstone
fill ~38~4~19 ~39~4~20 minecraft:minecraft:sandstone
fill ~38~5~19 ~39~5~19 minecraft:stone 0
fill ~38~14~19 ~53~14~20 minecraft:stone 0
fill ~38~15~19 ~57~15~19 minecraft:mycelium
fill ~40~5~19 ~41~5~20 minecraft:minecraft:sandstone
setblock ~42~6~19 minecraft:minecraft:sandstone
fill ~42~7~19 ~43~8~19 minecraft:stone 0
fill ~43~2~19 ~46~2~80 minecraft:stone 0
fill ~43~5~19 ~43~5~20 minecraft:minecraft:sandstone
setblock ~43~6~19 minecraft:stone 0
fill ~44~3~19 ~45~4~19 minecraft:minecraft:sandstone
fill ~44~5~19 ~46~5~19 minecraft:stone 0
fill ~45~8~19 ~49~8~19 minecraft:stone 0
fill ~46~4~19 ~48~4~21 minecraft:minecraft:sandstone
setblock ~47~2~19 minecraft:minecraft:sandstone
fill ~47~7~19 ~49~7~19 minecraft:stone 0
fill ~48~1~19 ~50~1~80 minecraft:stone 0
fill ~48~5~19 ~48~6~19 minecraft:stone 0
fill ~49~5~19 ~49~5~23 minecraft:minecraft:sandstone
setblock ~49~6~19 minecraft:stone 0
fill ~49~11~19 ~57~11~19 minecraft:stone 0
fill ~50~6~19 ~50~7~22 minecraft:minecraft:sandstone
fill ~50~8~19 ~50~8~21 minecraft:minecraft:sandstone
setblock ~51~1~19 minecraft:minecraft:sandstone
setblock ~51~8~19 minecraft:stone 0
fill ~52~0~19 ~52~0~82 minecraft:stone 0
fill ~52~1~19 ~52~1~81 minecraft:stone 0
fill ~52~7~19 ~53~7~23 minecraft:minecraft:sandstone
fill ~53~6~19 ~57~6~25 minecraft:minecraft:sandstone
fill ~53~13~19 ~53~13~20 minecraft:stone 0
fill ~54~7~19 ~56~7~19 minecraft:stone 0
fill ~54~12~19 ~57~12~21 minecraft:dirt 0
fill ~54~14~19 ~57~14~23 minecraft:dirt 0
fill ~57~7~19 ~59~7~28 minecraft:minecraft:sandstone
setblock ~57~8~19 minecraft:stone 0
fill ~58~8~19 ~58~8~28 minecraft:minecraft:sandstone
fill ~58~11~19 ~58~11~23 minecraft:dirt 0
fill ~58~14~19 ~65~14~19 minecraft:mycelium
fill ~59~6~19 ~63~6~33 minecraft:minecraft:sandstone
fill ~59~8~19 ~63~8~19 minecraft:stone 0
fill ~59~11~19 ~66~11~19 minecraft:stone 0
fill ~59~12~19 ~64~13~20 minecraft:dirt 0
fill ~60~7~19 ~62~7~19 minecraft:stone 0
fill ~63~7~19 ~65~7~35 minecraft:minecraft:sandstone
fill ~64~8~19 ~64~8~35 minecraft:minecraft:sandstone
fill ~65~8~19 ~67~8~19 minecraft:stone 0
fill ~65~12~19 ~66~12~24 minecraft:stone 0
fill ~65~13~19 ~65~13~31 minecraft:stone 0
setblock ~66~13~19 minecraft:mycelium
fill ~67~6~19 ~70~6~35 minecraft:minecraft:sandstone
fill ~70~3~19 ~70~3~35 minecraft:minecraft:sandstone
fill ~70~10~19 ~70~10~36 minecraft:stone 0
setblock ~70~11~19 minecraft:mycelium
fill ~71~3~19 ~72~3~19 minecraft:stone 0
fill ~71~4~19 ~71~4~33 minecraft:minecraft:sandstone
fill ~72~4~19 ~77~4~19 minecraft:stone 0
setblock ~73~9~19 minecraft:stone 0
setblock ~73~10~19 minecraft:mycelium
fill ~74~9~19 ~76~9~19 minecraft:mycelium
fill ~75~0~19 ~75~1~56 minecraft:stone 0
fill ~76~0~19 ~76~0~23 minecraft:minecraft:sandstone
fill ~76~8~19 ~76~8~36 minecraft:stone 0
fill ~77~2~19 ~77~2~33 minecraft:stone 0
fill ~77~8~19 ~77~8~28 minecraft:mycelium
fill ~79~0~19 ~79~0~20 minecraft:minecraft:sandstone
fill ~79~1~19 ~79~1~32 minecraft:stone 0
fill ~11~0~20 ~11~0~21 minecraft:mycelium
fill ~13~1~20 ~14~1~26 minecraft:stone 0
fill ~13~2~20 ~14~2~20 minecraft:mycelium
fill ~15~2~20 ~16~2~26 minecraft:stone 0
fill ~15~3~20 ~16~3~20 minecraft:mycelium
fill ~17~3~20 ~19~3~23 minecraft:stone 0
setblock ~17~4~20 minecraft:mycelium
fill ~18~4~20 ~20~4~25 minecraft:stone 0
fill ~18~5~20 ~19~5~20 minecraft:mycelium
setblock ~20~3~20 minecraft:dirt 0
fill ~20~5~20 ~21~5~25 minecraft:stone 0
fill ~20~6~20 ~21~6~20 minecraft:mycelium
fill ~21~0~20 ~21~0~75 minecraft:stone 0
fill ~22~7~20 ~22~7~27 minecraft:stone 0
setblock ~22~8~20 minecraft:mycelium
fill ~23~8~20 ~23~8~27 minecraft:stone 0
setblock ~23~9~20 minecraft:mycelium
fill ~24~2~20 ~27~2~21 minecraft:stone 0
fill ~24~9~20 ~24~9~27 minecraft:stone 0
setblock ~24~10~20 minecraft:mycelium
fill ~25~10~20 ~25~10~26 minecraft:stone 0
setblock ~25~11~20 minecraft:mycelium
fill ~26~4~20 ~27~5~20 minecraft:stone 0
fill ~26~11~20 ~26~11~25 minecraft:stone 0
fill ~26~12~20 ~26~13~24 minecraft:stone 0
fill ~26~14~20 ~27~14~20 minecraft:mycelium
fill ~27~3~20 ~27~3~21 minecraft:stone 0
fill ~27~8~20 ~31~8~20 minecraft:stone 0
fill ~27~13~20 ~27~13~26 minecraft:stone 0
fill ~28~2~20 ~28~4~20 minecraft:minecraft:sandstone
fill ~28~5~20 ~28~7~20 minecraft:stone 0
setblock ~28~13~20 minecraft:dirt 0
fill ~28~14~20 ~37~14~23 minecraft:stone 0
fill ~28~15~20 ~39~15~20 minecraft:mycelium
setblock ~29~3~20 minecraft:stone 0
fill ~29~5~20 ~29~5~22 minecraft:dirt 0
fill ~29~6~20 ~29~7~20 minecraft:stone 0
fill ~29~13~20 ~35~13~24 minecraft:stone 0
fill ~30~3~20 ~31~3~20 minecraft:minecraft:sandstone
fill ~30~4~20 ~30~5~20 minecraft:minecraft:sandstone
fill ~30~6~20 ~30~6~24 minecraft:dirt 0
setblock ~30~7~20 minecraft:stone 0
fill ~31~4~20 ~32~4~20 minecraft:stone 0
setblock ~31~5~20 minecraft:stone 0
fill ~31~7~20 ~31~7~25 minecraft:dirt 0
fill ~32~3~20 ~33~3~77 minecraft:stone 0
fill ~32~7~20 ~33~7~20 minecraft:stone 0
fill ~32~8~20 ~34~8~28 minecraft:dirt 0
fill ~35~8~20 ~36~8~20 minecraft:stone 0
fill ~36~4~20 ~37~4~20 minecraft:minecraft:sandstone
fill ~36~5~20 ~38~5~20 minecraft:dirt 0
setblock ~36~13~20 minecraft:dirt 0
fill ~37~3~20 ~44~3~79 minecraft:stone 0
fill ~37~13~20 ~37~13~22 minecraft:stone 0
fill ~38~7~20 ~40~7~20 minecraft:stone 0
fill ~38~10~20 ~41~10~20 minecraft:stone 0
setblock ~39~5~20 minecraft:minecraft:sandstone
fill ~39~6~20 ~43~6~23 minecraft:dirt 0
fill ~40~15~20 ~40~15~26 minecraft:stone 0
fill ~40~16~20 ~56~16~20 minecraft:mycelium
fill ~41~7~20 ~43~7~25 minecraft:dirt 0
fill ~41~15~20 ~44~15~20 minecraft:dirt 0
fill ~42~8~20 ~43~9~26 minecraft:dirt 0
fill ~42~10~20 ~42~10~33 minecraft:dirt 0
fill ~43~10~20 ~55~10~20 minecraft:stone 0
fill ~44~4~20 ~45~5~20 minecraft:minecraft:sandstone
setblock ~44~6~20 minecraft:minecraft:sandstone
setblock ~44~7~20 minecraft:stone 0
setblock ~45~3~20 minecraft:minecraft:sandstone
fill ~45~8~20 ~48~8~20 minecraft:stone 0
fill ~45~15~20 ~52~15~22 minecraft:stone 0
fill ~46~5~20 ~48~5~21 minecraft:minecraft:sandstone
fill ~47~2~20 ~49~2~79 minecraft:stone 0
fill ~47~7~20 ~48~7~20 minecraft:stone 0
fill ~47~9~20 ~48~9~20 minecraft:stone 0
fill ~48~6~20 ~49~6~21 minecraft:minecraft:sandstone
fill ~49~7~20 ~49~7~21 minecraft:minecraft:sandstone
setblock ~49~8~20 minecraft:minecraft:sandstone
fill ~49~9~20 ~49~9~30 minecraft:dirt 0
fill ~49~11~20 ~52~11~21 minecraft:stone 0
setblock ~50~2~20 minecraft:minecraft:sandstone
fill ~50~9~20 ~54~9~20 minecraft:stone 0
fill ~51~1~20 ~51~1~82 minecraft:stone 0
fill ~51~2~20 ~52~2~20 minecraft:stone 0
fill ~51~8~20 ~57~8~21 minecraft:minecraft:sandstone
fill ~53~2~20 ~54~2~21 minecraft:minecraft:sandstone
fill ~53~11~20 ~57~11~21 minecraft:dirt 0
fill ~53~15~20 ~56~15~23 minecraft:dirt 0
fill ~54~0~20 ~55~0~69 minecraft:stone 0
fill ~54~7~20 ~56~7~25 minecraft:minecraft:sandstone
fill ~55~9~20 ~57~9~24 minecraft:minecraft:sandstone
fill ~56~0~20 ~58~0~20 minecraft:minecraft:sandstone
fill ~56~10~20 ~56~10~24 minecraft:minecraft:sandstone
fill ~57~10~20 ~59~10~21 minecraft:dirt 0
fill ~57~15~20 ~64~15~20 minecraft:mycelium
setblock ~58~9~20 minecraft:dirt 0
fill ~58~14~20 ~63~14~20 minecraft:dirt 0
fill ~59~8~20 ~63~8~30 minecraft:minecraft:sandstone
fill ~59~9~20 ~68~9~20 minecraft:stone 0
fill ~59~11~20 ~64~11~20 minecraft:dirt 0
fill ~60~7~20 ~62~7~34 minecraft:minecraft:sandstone
fill ~60~10~20 ~68~10~20 minecraft:stone 0
fill ~64~14~20 ~64~14~34 minecraft:stone 0
fill ~65~8~20 ~65~8~35 minecraft:minecraft:sandstone
fill ~65~11~20 ~66~11~23 minecraft:stone 0
fill ~65~14~20 ~67~14~20 minecraft:mycelium
fill ~66~7~20 ~69~7~35 minecraft:minecraft:sandstone
fill ~66~8~20 ~67~8~20 minecraft:stone 0
fill ~66~13~20 ~67~13~31 minecraft:stone 0
fill ~67~12~20 ~70~12~28 minecraft:stone 0
fill ~68~0~20 ~68~0~32 minecraft:minecraft:sandstone
fill ~68~13~20 ~70~13~20 minecraft:mycelium
fill ~69~1~20 ~69~1~35 minecraft:minecraft:sandstone
fill ~69~11~20 ~72~11~32 minecraft:stone 0
fill ~70~1~20 ~70~1~21 minecraft:stone 0
fill ~70~2~20 ~70~2~33 minecraft:minecraft:sandstone
fill ~70~7~20 ~70~7~22 minecraft:stone 0
fill ~71~2~20 ~73~2~20 minecraft:stone 0
fill ~71~3~20 ~71~3~33 minecraft:minecraft:sandstone
fill ~71~5~20 ~71~5~36 minecraft:minecraft:sandstone
fill ~71~10~20 ~72~10~35 minecraft:stone 0
fill ~71~12~20 ~72~12~20 minecraft:mycelium
setblock ~72~3~20 minecraft:stone 0
fill ~72~4~20 ~72~4~32 minecraft:minecraft:sandstone
fill ~73~4~20 ~77~4~25 minecraft:stone 0
setblock ~73~9~20 minecraft:mycelium
setblock ~73~11~20 minecraft:mycelium
fill ~74~9~20 ~74~9~26 minecraft:stone 0
fill ~74~10~20 ~74~10~23 minecraft:mycelium
fill ~75~9~20 ~76~9~21 minecraft:mycelium
fill ~77~1~20 ~78~1~32 minecraft:stone 0
fill ~10~0~21 ~10~0~22 minecraft:mycelium
fill ~12~0~21 ~12~0~26 minecraft:stone 0
setblock ~12~1~21 minecraft:mycelium
fill ~13~2~21 ~14~2~26 minecraft:stone 0
fill ~13~3~21 ~14~3~21 minecraft:mycelium
fill ~15~3~21 ~16~3~27 minecraft:stone 0
fill ~15~4~21 ~16~4~21 minecraft:mycelium
fill ~17~4~21 ~17~4~28 minecraft:stone 0
setblock ~17~5~21 minecraft:mycelium
fill ~18~5~21 ~19~5~27 minecraft:stone 0
setblock ~18~6~21 minecraft:mycelium
fill ~19~6~21 ~21~6~26 minecraft:stone 0
setblock ~19~7~21 minecraft:mycelium
fill ~20~1~21 ~22~1~74 minecraft:stone 0
fill ~20~3~21 ~20~3~25 minecraft:stone 0
fill ~20~7~21 ~21~7~26 minecraft:stone 0
fill ~20~8~21 ~21~8~21 minecraft:mycelium
fill ~22~8~21 ~22~8~27 minecraft:stone 0
setblock ~22~9~21 minecraft:mycelium
setblock ~23~1~21 minecraft:dirt 0
fill ~23~9~21 ~23~9~27 minecraft:stone 0
setblock ~23~10~21 minecraft:mycelium
fill ~24~1~21 ~25~1~81 minecraft:stone 0
fill ~24~10~21 ~24~14~27 minecraft:stone 0
fill ~24~15~21 ~27~15~21 minecraft:mycelium
fill ~25~11~21 ~25~14~26 minecraft:stone 0
fill ~26~4~21 ~30~4~21 minecraft:dirt 0
fill ~26~5~21 ~27~5~21 minecraft:stone 0
fill ~26~14~21 ~27~14~22 minecraft:stone 0
fill ~27~8~21 ~30~8~21 minecraft:stone 0
fill ~28~2~21 ~28~2~78 minecraft:stone 0
fill ~28~3~21 ~28~3~76 minecraft:stone 0
setblock ~28~5~21 minecraft:dirt 0
fill ~28~6~21 ~28~7~21 minecraft:stone 0
fill ~28~13~21 ~28~13~24 minecraft:stone 0
fill ~28~15~21 ~39~15~23 minecraft:stone 0
fill ~28~16~21 ~39~16~21 minecraft:mycelium
setblock ~29~3~21 minecraft:minecraft:sandstone
fill ~29~6~21 ~29~6~26 minecraft:dirt 0
setblock ~29~7~21 minecraft:stone 0
fill ~29~12~21 ~52~12~22 minecraft:stone 0
fill ~30~3~21 ~31~3~77 minecraft:stone 0
fill ~30~5~21 ~37~5~21 minecraft:dirt 0
fill ~30~7~21 ~30~7~26 minecraft:dirt 0
fill ~31~4~21 ~34~4~21 minecraft:minecraft:sandstone
fill ~31~6~21 ~38~6~23 minecraft:dirt 0
fill ~31~8~21 ~31~8~25 minecraft:dirt 0
fill ~32~7~21 ~40~7~24 minecraft:dirt 0
fill ~33~10~21 ~36~10~21 minecraft:stone 0
fill ~35~4~21 ~37~4~21 minecraft:dirt 0
fill ~35~8~21 ~41~9~24 minecraft:dirt 0
fill ~36~13~21 ~36~13~23 minecraft:stone 0
fill ~37~10~21 ~37~10~33 minecraft:dirt 0
fill ~38~4~21 ~40~4~78 minecraft:stone 0
setblock ~38~5~21 minecraft:stone 0
fill ~38~10~21 ~40~10~21 minecraft:stone 0
fill ~38~13~21 ~44~14~22 minecraft:stone 0
fill ~39~5~21 ~43~5~22 minecraft:dirt 0
setblock ~39~48~21 minecraft:wooden_slab 11
fill ~40~16~21 ~41~16~22 minecraft:dirt 0
fill ~40~17~21 ~46~17~22 minecraft:mycelium
fill ~41~4~21 ~44~4~21 minecraft:minecraft:sandstone
fill ~41~10~21 ~41~10~33 minecraft:dirt 0
fill ~41~15~21 ~41~15~27 minecraft:stone 0
fill ~42~15~21 ~43~15~21 minecraft:mycelium
fill ~43~10~21 ~43~10~33 minecraft:dirt 0
fill ~44~5~21 ~45~5~21 minecraft:minecraft:sandstone
fill ~44~6~21 ~46~9~21 minecraft:dirt 0
fill ~44~10~21 ~52~10~21 minecraft:stone 0
fill ~44~15~21 ~44~15~27 minecraft:stone 0
fill ~44~16~21 ~46~16~25 minecraft:dirt 0
fill ~45~3~21 ~48~3~79 minecraft:stone 0
fill ~45~4~21 ~45~4~81 minecraft:stone 0
setblock ~45~13~21 minecraft:dirt 0
fill ~45~14~21 ~52~14~22 minecraft:stone 0
fill ~46~13~21 ~52~13~22 minecraft:stone 0
setblock ~47~6~21 minecraft:minecraft:sandstone
fill ~47~7~21 ~48~9~27 minecraft:dirt 0
fill ~47~16~21 ~50~16~21 minecraft:mycelium
fill ~49~3~21 ~52~3~21 minecraft:minecraft:sandstone
fill ~49~8~21 ~49~8~30 minecraft:dirt 0
fill ~50~2~21 ~51~2~80 minecraft:stone 0
fill ~50~9~21 ~50~9~31 minecraft:dirt 0
fill ~51~9~21 ~54~9~21 minecraft:minecraft:sandstone
fill ~51~16~21 ~52~16~21 minecraft:stone 0
fill ~51~17~21 ~59~17~22 minecraft:mycelium
setblock ~52~2~21 minecraft:minecraft:sandstone
fill ~53~1~21 ~54~1~78 minecraft:stone 0
fill ~53~10~21 ~54~10~21 minecraft:dirt 0
fill ~53~12~21 ~53~12~29 minecraft:dirt 0
fill ~53~13~21 ~53~13~25 minecraft:dirt 0
fill ~53~14~21 ~53~14~23 minecraft:dirt 0
fill ~53~16~21 ~59~16~23 minecraft:dirt 0
fill ~55~1~21 ~58~1~21 minecraft:minecraft:sandstone
fill ~55~10~21 ~55~10~23 minecraft:minecraft:sandstone
fill ~56~0~21 ~56~0~68 minecraft:stone 0
fill ~57~0~21 ~58~0~21 minecraft:minecraft:sandstone
fill ~57~15~21 ~60~15~22 minecraft:dirt 0
fill ~58~9~21 ~58~9~27 minecraft:minecraft:sandstone
fill ~58~14~21 ~61~14~21 minecraft:dirt 0
fill ~59~9~21 ~61~9~21 minecraft:dirt 0
fill ~59~11~21 ~63~12~21 minecraft:dirt 0
fill ~59~13~21 ~62~13~21 minecraft:dirt 0
fill ~60~10~21 ~64~10~22 minecraft:dirt 0
fill ~60~16~21 ~60~16~22 minecraft:mycelium
fill ~61~15~21 ~67~15~21 minecraft:mycelium
fill ~62~9~21 ~63~9~21 minecraft:minecraft:sandstone
fill ~62~14~21 ~63~14~27 minecraft:stone 0
fill ~63~13~21 ~64~13~28 minecraft:stone 0
fill ~64~9~21 ~68~9~21 minecraft:stone 0
setblock ~64~11~21 minecraft:mycelium
fill ~65~10~21 ~68~10~22 minecraft:stone 0
fill ~65~14~21 ~67~14~38 minecraft:stone 0
fill ~66~8~21 ~66~8~35 minecraft:minecraft:sandstone
setblock ~67~8~21 minecraft:stone 0
fill ~68~13~21 ~70~13~34 minecraft:stone 0
fill ~68~14~21 ~70~14~21 minecraft:mycelium
fill ~71~2~21 ~71~2~32 minecraft:minecraft:sandstone
fill ~71~12~21 ~71~12~35 minecraft:stone 0
fill ~71~13~21 ~71~13~22 minecraft:mycelium
fill ~72~2~21 ~73~2~21 minecraft:stone 0
fill ~72~3~21 ~72~3~32 minecraft:minecraft:sandstone
fill ~72~12~21 ~73~12~21 minecraft:mycelium
fill ~73~9~21 ~73~11~33 minecraft:stone 0
fill ~76~1~21 ~76~1~32 minecraft:stone 0
fill ~78~0~21 ~79~0~62 minecraft:stone 0
fill ~78~2~21 ~80~2~32 minecraft:stone 0
fill ~80~1~21 ~80~1~62 minecraft:stone 0
fill ~80~5~21 ~80~5~27 minecraft:mycelium
setblock ~81~1~21 minecraft:mycelium
fill ~82~4~21 ~82~4~22 minecraft:stone 0
fill ~82~5~21 ~82~5~22 minecraft:mycelium
fill ~83~2~21 ~83~2~22 minecraft:mycelium
fill ~84~0~21 ~85~0~21 minecraft:mycelium
setblock ~9~0~22 minecraft:mycelium
fill ~11~0~22 ~11~3~27 minecraft:stone 0
fill ~11~4~22 ~14~4~22 minecraft:mycelium
fill ~12~1~22 ~12~3~28 minecraft:stone 0
fill ~13~3~22 ~14~3~25 minecraft:stone 0
fill ~15~4~22 ~16~4~28 minecraft:stone 0
setblock ~15~5~22 minecraft:mycelium
fill ~16~5~22 ~17~5~28 minecraft:stone 0
setblock ~16~6~22 minecraft:mycelium
fill ~17~6~22 ~18~6~28 minecraft:stone 0
setblock ~17~7~22 minecraft:mycelium
fill ~18~7~22 ~19~7~27 minecraft:stone 0
setblock ~18~8~22 minecraft:mycelium
fill ~19~8~22 ~21~8~27 minecraft:stone 0
fill ~19~9~22 ~20~9~22 minecraft:mycelium
fill ~21~9~22 ~22~9~28 minecraft:stone 0
setblock ~21~10~22 minecraft:mycelium
fill ~22~10~22 ~23~10~28 minecraft:stone 0
fill ~22~11~22 ~23~14~22 minecraft:stone 0
fill ~22~15~22 ~24~15~22 minecraft:mycelium
fill ~23~1~22 ~23~1~81 minecraft:stone 0
setblock ~23~3~22 minecraft:stone 0
fill ~24~2~22 ~24~3~22 minecraft:minecraft:sandstone
fill ~24~4~22 ~24~7~23 minecraft:stone 0
fill ~25~2~22 ~27~2~82 minecraft:stone 0
setblock ~25~3~22 minecraft:stone 0
fill ~25~4~22 ~27~4~23 minecraft:dirt 0
fill ~25~5~22 ~25~7~24 minecraft:stone 0
setblock ~25~15~22 minecraft:dirt 0
fill ~25~16~22 ~28~16~22 minecraft:mycelium
fill ~26~3~22 ~27~3~22 minecraft:dirt 0
fill ~26~5~22 ~27~5~25 minecraft:dirt 0
fill ~26~15~22 ~27~15~23 minecraft:stone 0
fill ~27~8~22 ~29~8~22 minecraft:stone 0
fill ~28~4~22 ~29~4~22 minecraft:stone 0
setblock ~28~5~22 minecraft:stone 0
fill ~28~6~22 ~28~6~26 minecraft:dirt 0
setblock ~28~7~22 minecraft:stone 0
fill ~28~9~22 ~30~9~22 minecraft:stone 0
fill ~29~3~22 ~29~3~76 minecraft:stone 0
fill ~29~7~22 ~29~7~28 minecraft:dirt 0
fill ~29~16~22 ~33~16~24 minecraft:stone 0
fill ~29~17~22 ~39~17~23 minecraft:mycelium
fill ~30~4~22 ~31~5~22 minecraft:dirt 0
fill ~30~8~22 ~30~8~28 minecraft:dirt 0
fill ~31~9~22 ~34~9~25 minecraft:dirt 0
fill ~32~4~22 ~37~4~76 minecraft:stone 0
fill ~32~5~22 ~36~5~22 minecraft:dirt 0
fill ~32~11~22 ~41~11~22 minecraft:stone 0
fill ~33~10~22 ~35~10~22 minecraft:stone 0
setblock ~34~16~22 minecraft:dirt 0
fill ~35~16~22 ~39~16~25 minecraft:stone 0
fill ~36~10~22 ~36~10~33 minecraft:dirt 0
fill ~37~5~22 ~37~5~75 minecraft:stone 0
setblock ~38~5~22 minecraft:dirt 0
fill ~38~10~22 ~40~10~33 minecraft:dirt 0
setblock ~39~48~22 minecraft:jungle_stairs 6
fill ~41~4~22 ~44~4~79 minecraft:stone 0
fill ~42~11~22 ~43~11~22 minecraft:dirt 0
fill ~42~15~22 ~43~15~25 minecraft:stone 0
fill ~42~16~22 ~43~16~23 minecraft:dirt 0
fill ~44~5~22 ~46~5~74 minecraft:stone 0
fill ~44~6~22 ~45~10~22 minecraft:dirt 0
fill ~44~11~22 ~46~11~24 minecraft:stone 0
fill ~45~13~22 ~45~13~27 minecraft:stone 0
fill ~46~4~22 ~47~4~79 minecraft:stone 0
fill ~46~6~22 ~46~6~23 minecraft:stone 0
fill ~46~7~22 ~46~10~27 minecraft:dirt 0
fill ~47~5~22 ~48~5~22 minecraft:minecraft:sandstone
fill ~47~6~22 ~48~6~25 minecraft:dirt 0
fill ~47~10~22 ~49~10~36 minecraft:dirt 0
setblock ~47~11~22 minecraft:dirt 0
fill ~47~16~22 ~49~16~23 minecraft:dirt 0
fill ~47~17~22 ~50~17~22 minecraft:mycelium
setblock ~48~4~22 minecraft:minecraft:sandstone
fill ~48~11~22 ~49~11~22 minecraft:stone 0
fill ~49~3~22 ~50~3~79 minecraft:stone 0
setblock ~49~6~22 minecraft:minecraft:sandstone
fill ~49~7~22 ~49~7~28 minecraft:dirt 0
fill ~50~8~22 ~51~8~29 minecraft:dirt 0
fill ~50~10~22 ~50~10~23 minecraft:mycelium
fill ~50~16~22 ~51~16~23 minecraft:stone 0
fill ~51~3~22 ~52~3~22 minecraft:minecraft:sandstone
fill ~51~9~22 ~52~10~22 minecraft:dirt 0
fill ~51~11~22 ~52~11~22 minecraft:stone 0
fill ~52~2~22 ~53~2~81 minecraft:stone 0
fill ~52~8~22 ~57~8~22 minecraft:minecraft:sandstone
fill ~52~16~22 ~52~16~23 minecraft:dirt 0
fill ~53~9~22 ~54~9~22 minecraft:minecraft:sandstone
fill ~53~10~22 ~53~11~22 minecraft:dirt 0
setblock ~54~2~22 minecraft:minecraft:sandstone
setblock ~54~10~22 minecraft:minecraft:sandstone
fill ~54~11~22 ~54~11~30 minecraft:dirt 0
fill ~54~12~22 ~54~12~29 minecraft:dirt 0
fill ~55~1~22 ~56~1~68 minecraft:stone 0
fill ~55~11~22 ~56~11~22 minecraft:minecraft:sandstone
setblock ~55~12~22 minecraft:minecraft:sandstone
fill ~56~12~22 ~57~12~24 minecraft:dirt 0
fill ~57~0~22 ~58~0~64 minecraft:stone 0
fill ~57~1~22 ~58~1~22 minecraft:minecraft:sandstone
fill ~57~10~22 ~57~10~25 minecraft:minecraft:sandstone
setblock ~57~11~22 minecraft:dirt 0
fill ~58~10~22 ~59~10~22 minecraft:dirt 0
fill ~58~14~22 ~60~14~22 minecraft:dirt 0
fill ~59~9~22 ~62~9~22 minecraft:minecraft:sandstone
fill ~59~11~22 ~62~11~22 minecraft:dirt 0
fill ~59~12~22 ~61~13~22 minecraft:dirt 0
fill ~61~14~22 ~61~15~29 minecraft:stone 0
fill ~61~16~22 ~62~16~23 minecraft:mycelium
fill ~62~12~22 ~64~12~23 minecraft:stone 0
fill ~62~13~22 ~62~13~28 minecraft:stone 0
fill ~62~15~22 ~62~15~42 minecraft:stone 0
fill ~63~11~22 ~64~11~23 minecraft:stone 0
fill ~63~15~22 ~68~15~22 minecraft:mycelium
fill ~65~9~22 ~65~9~35 minecraft:minecraft:sandstone
fill ~66~9~22 ~68~9~22 minecraft:stone 0
fill ~67~8~22 ~68~8~36 minecraft:minecraft:sandstone
fill ~68~14~22 ~68~14~39 minecraft:stone 0
fill ~69~0~22 ~69~0~34 minecraft:minecraft:sandstone
fill ~69~8~22 ~70~8~22 minecraft:stone 0
fill ~69~14~22 ~70~14~22 minecraft:mycelium
fill ~70~1~22 ~70~1~33 minecraft:minecraft:sandstone
fill ~72~2~22 ~72~2~32 minecraft:minecraft:sandstone
fill ~72~12~22 ~72~12~37 minecraft:stone 0
fill ~72~13~22 ~72~13~23 minecraft:mycelium
fill ~73~2~22 ~73~2~25 minecraft:stone 0
fill ~73~3~22 ~73~3~26 minecraft:minecraft:sandstone
setblock ~73~12~22 minecraft:mycelium
fill ~74~3~22 ~81~3~34 minecraft:stone 0
fill ~75~9~22 ~75~9~33 minecraft:stone 0
fill ~75~10~22 ~75~10~27 minecraft:mycelium
fill ~76~9~22 ~76~9~27 minecraft:mycelium
fill ~77~0~22 ~77~0~32 minecraft:stone 0
fill ~81~1~22 ~81~2~32 minecraft:stone 0
setblock ~84~0~22 minecraft:mycelium
setblock ~8~0~23 minecraft:mycelium
fill ~9~0~23 ~10~0~28 minecraft:stone 0
setblock ~9~1~23 minecraft:mycelium
fill ~10~1~23 ~10~3~31 minecraft:stone 0
fill ~10~4~23 ~12~4~23 minecraft:mycelium
fill ~13~4~23 ~14~4~30 minecraft:stone 0
fill ~13~5~23 ~14~5~23 minecraft:mycelium
fill ~15~5~23 ~15~5~30 minecraft:stone 0
setblock ~15~6~23 minecraft:mycelium
fill ~16~6~23 ~16~6~29 minecraft:stone 0
setblock ~16~7~23 minecraft:mycelium
fill ~17~0~23 ~17~0~73 minecraft:stone 0
fill ~17~7~23 ~17~7~29 minecraft:stone 0
setblock ~17~8~23 minecraft:mycelium
setblock ~18~0~23 minecraft:minecraft:sandstone
fill ~18~8~23 ~18~8~28 minecraft:stone 0
setblock ~18~9~23 minecraft:mycelium
fill ~19~0~23 ~20~0~75 minecraft:stone 0
fill ~19~9~23 ~20~9~28 minecraft:stone 0
setblock ~19~10~23 minecraft:mycelium
fill ~20~10~23 ~21~10~28 minecraft:stone 0
fill ~20~11~23 ~21~11~23 minecraft:mycelium
setblock ~22~11~23 minecraft:dirt 0
fill ~22~12~23 ~23~14~28 minecraft:stone 0
setblock ~22~15~23 minecraft:mycelium
fill ~23~3~23 ~25~3~23 minecraft:dirt 0
fill ~23~11~23 ~23~11~28 minecraft:stone 0
fill ~23~15~23 ~25~15~23 minecraft:stone 0
fill ~23~16~23 ~25~16~23 minecraft:mycelium
fill ~24~2~23 ~24~2~75 minecraft:stone 0
fill ~26~3~23 ~27~3~75 minecraft:stone 0
fill ~26~6~23 ~26~7~24 minecraft:stone 0
setblock ~26~14~23 minecraft:dirt 0
setblock ~26~16~23 minecraft:dirt 0
fill ~26~17~23 ~28~17~23 minecraft:mycelium
fill ~27~6~23 ~27~6~27 minecraft:dirt 0
fill ~27~7~23 ~27~8~23 minecraft:stone 0
fill ~27~14~23 ~27~14~28 minecraft:stone 0
setblock ~27~16~23 minecraft:stone 0
fill ~28~4~23 ~28~5~23 minecraft:dirt 0
fill ~28~7~23 ~28~8~28 minecraft:dirt 0
setblock ~28~9~23 minecraft:stone 0
setblock ~28~16~23 minecraft:dirt 0
fill ~29~4~23 ~31~4~75 minecraft:stone 0
setblock ~29~5~23 minecraft:stone 0
fill ~29~8~23 ~29~8~30 minecraft:dirt 0
fill ~29~9~23 ~30~9~27 minecraft:dirt 0
fill ~29~10~23 ~29~12~23 minecraft:stone 0
fill ~30~5~23 ~33~5~23 minecraft:dirt 0
fill ~30~10~23 ~35~10~26 minecraft:dirt 0
fill ~30~11~23 ~35~12~23 minecraft:stone 0
fill ~34~5~23 ~36~5~75 minecraft:stone 0
fill ~34~16~23 ~34~16~27 minecraft:stone 0
fill ~36~11~23 ~42~11~36 minecraft:dirt 0
fill ~36~12~23 ~47~12~23 minecraft:stone 0
fill ~37~13~23 ~37~13~48 minecraft:dirt 0
fill ~38~5~23 ~43~5~73 minecraft:stone 0
fill ~38~13~23 ~42~14~24 minecraft:stone 0
setblock ~39~47~23 minecraft:jungle_stairs 2
setblock ~39~48~23 minecraft:jungle_stairs 3
setblock ~39~49~23 minecraft:wooden_slab 3
fill ~40~16~23 ~40~16~26 minecraft:stone 0
fill ~40~17~23 ~56~17~23 minecraft:dirt 0
fill ~40~18~23 ~56~18~23 minecraft:mycelium
setblock ~41~16~23 minecraft:dirt 0
fill ~43~11~23 ~43~11~25 minecraft:stone 0
setblock ~43~13~23 minecraft:dirt 0
fill ~43~14~23 ~51~14~23 minecraft:stone 0
fill ~44~6~23 ~45~6~23 minecraft:stone 0
fill ~44~7~23 ~45~10~24 minecraft:dirt 0
setblock ~44~13~23 minecraft:stone 0
fill ~45~15~23 ~51~15~23 minecraft:stone 0
setblock ~45~19~23 minecraft:brown_mushroom
fill ~46~13~23 ~48~13~23 minecraft:stone 0
fill ~47~5~23 ~48~5~23 minecraft:dirt 0
fill ~47~11~23 ~48~11~24 minecraft:stone 0
fill ~48~4~23 ~49~4~79 minecraft:stone 0
setblock ~48~12~23 minecraft:dirt 0
fill ~49~6~23 ~50~6~26 minecraft:dirt 0
setblock ~49~11~23 minecraft:dirt 0
fill ~49~12~23 ~49~12~25 minecraft:stone 0
setblock ~49~13~23 minecraft:dirt 0
fill ~50~4~23 ~51~4~23 minecraft:minecraft:sandstone
fill ~50~7~23 ~51~7~27 minecraft:dirt 0
fill ~50~13~23 ~51~13~23 minecraft:stone 0
fill ~51~3~23 ~52~3~81 minecraft:stone 0
setblock ~51~9~23 minecraft:mycelium
fill ~52~8~23 ~52~8~24 minecraft:mycelium
fill ~52~12~23 ~52~12~29 minecraft:dirt 0
fill ~52~13~23 ~52~14~24 minecraft:dirt 0
setblock ~52~15~23 minecraft:dirt 0
fill ~53~8~23 ~57~8~23 minecraft:minecraft:sandstone
fill ~53~11~23 ~53~11~30 minecraft:dirt 0
fill ~54~2~23 ~55~2~69 minecraft:stone 0
setblock ~54~9~23 minecraft:minecraft:sandstone
fill ~54~10~23 ~54~10~40 minecraft:dirt 0
fill ~55~11~23 ~55~11~31 minecraft:dirt 0
fill ~55~12~23 ~55~12~29 minecraft:dirt 0
fill ~56~2~23 ~57~2~23 minecraft:minecraft:sandstone
fill ~56~11~23 ~57~11~23 minecraft:minecraft:sandstone
fill ~57~1~23 ~57~1~65 minecraft:stone 0
fill ~57~15~23 ~59~15~23 minecraft:dirt 0
fill ~57~17~23 ~60~17~23 minecraft:mycelium
setblock ~58~1~23 minecraft:minecraft:sandstone
fill ~58~10~23 ~65~10~23 minecraft:minecraft:sandstone
fill ~58~14~23 ~59~14~24 minecraft:dirt 0
fill ~59~0~23 ~59~0~63 minecraft:stone 0
fill ~59~9~23 ~60~9~23 minecraft:minecraft:sandstone
fill ~59~11~23 ~61~11~23 minecraft:dirt 0
fill ~59~12~23 ~60~12~24 minecraft:dirt 0
fill ~59~13~23 ~60~13~23 minecraft:dirt 0
fill ~60~14~23 ~60~16~24 minecraft:stone 0
fill ~61~12~23 ~61~13~24 minecraft:stone 0
setblock ~62~9~23 minecraft:minecraft:sandstone
fill ~63~15~23 ~67~15~27 minecraft:stone 0
fill ~63~16~23 ~68~16~23 minecraft:mycelium
fill ~64~9~23 ~64~9~35 minecraft:minecraft:sandstone
fill ~66~9~23 ~68~9~36 minecraft:minecraft:sandstone
fill ~66~10~23 ~68~10~23 minecraft:stone 0
setblock ~68~15~23 minecraft:dirt 0
fill ~69~8~23 ~69~8~36 minecraft:minecraft:sandstone
fill ~69~14~23 ~69~14~35 minecraft:stone 0
setblock ~69~15~23 minecraft:mycelium
fill ~70~7~23 ~70~7~36 minecraft:minecraft:sandstone
fill ~70~8~23 ~70~8~26 minecraft:stone 0
fill ~70~14~23 ~71~14~23 minecraft:mycelium
fill ~71~1~23 ~71~1~32 minecraft:minecraft:sandstone
fill ~71~13~23 ~71~13~35 minecraft:stone 0
fill ~72~1~23 ~73~1~24 minecraft:stone 0
setblock ~73~12~23 minecraft:dirt 0
setblock ~73~13~23 minecraft:mycelium
fill ~82~4~23 ~82~4~24 minecraft:mycelium
fill ~83~0~23 ~83~0~24 minecraft:mycelium
fill ~7~0~24 ~8~0~31 minecraft:stone 0
fill ~7~1~24 ~7~1~25 minecraft:mycelium
fill ~8~1~24 ~9~2~32 minecraft:stone 0
setblock ~8~3~24 minecraft:mycelium
fill ~9~3~24 ~9~3~33 minecraft:stone 0
fill ~9~4~24 ~10~4~24 minecraft:mycelium
fill ~11~4~24 ~12~4~31 minecraft:stone 0
fill ~11~5~24 ~12~5~24 minecraft:mycelium
fill ~13~5~24 ~14~5~31 minecraft:stone 0
fill ~13~6~24 ~14~6~24 minecraft:mycelium
fill ~15~6~24 ~15~6~30 minecraft:stone 0
setblock ~15~7~24 minecraft:mycelium
fill ~16~7~24 ~16~7~29 minecraft:stone 0
setblock ~16~8~24 minecraft:mycelium
setblock ~17~3~24 minecraft:dirt 0
fill ~17~8~24 ~17~8~29 minecraft:stone 0
setblock ~17~9~24 minecraft:mycelium
fill ~18~0~24 ~18~0~73 minecraft:stone 0
setblock ~18~1~24 minecraft:dirt 0
fill ~18~3~24 ~19~3~25 minecraft:stone 0
fill ~18~9~24 ~18~9~30 minecraft:stone 0
setblock ~18~10~24 minecraft:mycelium
fill ~19~1~24 ~19~1~74 minecraft:stone 0
fill ~19~10~24 ~19~10~30 minecraft:stone 0
setblock ~19~11~24 minecraft:mycelium
fill ~20~11~24 ~22~11~29 minecraft:stone 0
fill ~20~12~24 ~21~14~29 minecraft:stone 0
setblock ~20~15~24 minecraft:mycelium
fill ~21~3~24 ~21~3~72 minecraft:stone 0
fill ~21~15~24 ~24~15~30 minecraft:stone 0
fill ~21~16~24 ~21~16~25 minecraft:mycelium
fill ~22~3~24 ~23~3~24 minecraft:dirt 0
setblock ~22~16~24 minecraft:dirt 0
fill ~22~17~24 ~23~17~24 minecraft:mycelium
fill ~23~16~24 ~26~16~27 minecraft:stone 0
fill ~24~3~24 ~25~3~74 minecraft:stone 0
fill ~24~4~24 ~26~4~24 minecraft:dirt 0
fill ~24~5~24 ~24~7~25 minecraft:stone 0
fill ~24~17~24 ~35~17~26 minecraft:stone 0
fill ~24~18~24 ~35~18~24 minecraft:mycelium
setblock ~25~15~24 minecraft:dirt 0
fill ~26~14~24 ~26~15~28 minecraft:stone 0
fill ~27~4~24 ~28~4~74 minecraft:stone 0
fill ~27~7~24 ~27~7~29 minecraft:dirt 0
setblock ~27~8~24 minecraft:stone 0
fill ~27~11~24 ~35~11~24 minecraft:dirt 0
fill ~27~12~24 ~29~12~27 minecraft:dirt 0
fill ~27~15~24 ~27~15~25 minecraft:dirt 0
setblock ~27~16~24 minecraft:dirt 0
fill ~28~5~24 ~30~5~24 minecraft:dirt 0
fill ~28~9~24 ~28~9~34 minecraft:dirt 0
fill ~28~10~24 ~29~10~27 minecraft:dirt 0
setblock ~28~14~24 minecraft:dirt 0
fill ~28~15~24 ~29~15~27 minecraft:stone 0
fill ~28~16~24 ~28~16~25 minecraft:stone 0
fill ~29~14~24 ~37~14~24 minecraft:stone 0
fill ~30~12~24 ~34~12~24 minecraft:stone 0
setblock ~30~15~24 minecraft:dirt 0
fill ~31~5~24 ~33~5~74 minecraft:stone 0
fill ~31~6~24 ~35~6~24 minecraft:dirt 0
fill ~31~15~24 ~39~15~24 minecraft:stone 0
fill ~35~12~24 ~39~12~37 minecraft:dirt 0
fill ~36~6~24 ~36~6~73 minecraft:stone 0
fill ~36~13~24 ~36~13~27 minecraft:dirt 0
fill ~36~17~24 ~48~17~24 minecraft:dirt 0
fill ~36~18~24 ~46~18~24 minecraft:dirt 0
fill ~36~19~24 ~43~19~27 minecraft:dirt 0
fill ~36~20~24 ~38~20~24 minecraft:mycelium
fill ~37~6~24 ~42~6~24 minecraft:dirt 0
setblock ~38~47~24 minecraft:wooden_slab 11
setblock ~38~48~24 minecraft:jungle_stairs 4
fill ~39~20~24 ~41~20~27 minecraft:dirt 0
fill ~39~21~24 ~41~21~24 minecraft:mycelium
setblock ~39~46~24 minecraft:jungle_stairs 6
fill ~39~47~24 ~39~47~27 minecraft:planks 3
setblock ~39~48~24 minecraft:double_wooden_slab 3
setblock ~39~49~24 minecraft:jungle_stairs 2
fill ~40~12~24 ~46~12~24 minecraft:stone 0
setblock ~40~47~24 minecraft:wooden_slab 11
setblock ~40~48~24 minecraft:jungle_stairs 5
fill ~41~16~24 ~42~16~26 minecraft:stone 0
fill ~42~20~24 ~43~20~24 minecraft:mycelium
fill ~43~6~24 ~43~6~73 minecraft:stone 0
fill ~43~13~24 ~43~13~27 minecraft:stone 0
fill ~43~14~24 ~50~14~24 minecraft:stone 0
setblock ~43~16~24 minecraft:dirt 0
fill ~44~6~24 ~46~6~24 minecraft:dirt 0
fill ~44~13~24 ~44~13~25 minecraft:dirt 0
fill ~44~19~24 ~46~19~24 minecraft:mycelium
fill ~45~15~24 ~50~15~25 minecraft:stone 0
setblock ~46~13~24 minecraft:dirt 0
fill ~47~5~24 ~47~5~80 minecraft:stone 0
setblock ~47~12~24 minecraft:dirt 0
fill ~47~13~24 ~50~13~24 minecraft:stone 0
fill ~47~16~24 ~48~16~28 minecraft:dirt 0
fill ~47~18~24 ~49~18~24 minecraft:mycelium
fill ~48~5~24 ~50~5~24 minecraft:dirt 0
fill ~48~12~24 ~48~12~25 minecraft:stone 0
fill ~49~11~24 ~49~11~25 minecraft:stone 0
fill ~49~16~24 ~50~16~25 minecraft:stone 0
fill ~49~17~24 ~55~17~24 minecraft:stone 0
fill ~50~4~24 ~51~4~80 minecraft:stone 0
fill ~50~10~24 ~51~10~37 minecraft:dirt 0
fill ~50~11~24 ~52~11~30 minecraft:dirt 0
setblock ~50~12~24 minecraft:stone 0
fill ~50~18~24 ~55~18~24 minecraft:stone 0
fill ~50~19~24 ~56~19~24 minecraft:mycelium
fill ~51~5~24 ~57~5~24 minecraft:minecraft:sandstone
fill ~51~6~24 ~51~6~27 minecraft:dirt 0
fill ~51~9~24 ~51~9~32 minecraft:dirt 0
fill ~51~12~24 ~51~12~29 minecraft:dirt 0
fill ~51~13~24 ~51~16~24 minecraft:dirt 0
setblock ~52~6~24 minecraft:minecraft:sandstone
fill ~52~7~24 ~52~7~27 minecraft:dirt 0
fill ~52~15~24 ~59~15~24 minecraft:stone 0
fill ~52~16~24 ~53~16~27 minecraft:stone 0
fill ~53~3~24 ~54~3~80 minecraft:stone 0
setblock ~53~7~24 minecraft:minecraft:sandstone
setblock ~53~8~24 minecraft:mycelium
fill ~53~10~24 ~53~10~41 minecraft:dirt 0
fill ~53~14~24 ~57~14~26 minecraft:stone 0
fill ~54~8~24 ~57~8~24 minecraft:minecraft:sandstone
fill ~54~9~24 ~54~9~38 minecraft:dirt 0
fill ~54~13~24 ~54~13~27 minecraft:stone 0
setblock ~54~16~24 minecraft:dirt 0
fill ~55~3~24 ~58~3~24 minecraft:minecraft:sandstone
fill ~55~10~24 ~55~10~39 minecraft:dirt 0
setblock ~55~13~24 minecraft:dirt 0
fill ~55~16~24 ~59~16~24 minecraft:stone 0
fill ~56~2~24 ~57~2~67 minecraft:stone 0
fill ~56~11~24 ~56~11~44 minecraft:dirt 0
fill ~56~13~24 ~56~13~28 minecraft:stone 0
fill ~56~17~24 ~60~17~24 minecraft:dirt 0
fill ~56~18~24 ~56~18~27 minecraft:dirt 0
fill ~57~11~24 ~58~11~24 minecraft:minecraft:sandstone
fill ~57~13~24 ~59~13~24 minecraft:dirt 0
fill ~57~18~24 ~60~18~24 minecraft:mycelium
fill ~58~1~24 ~59~1~63 minecraft:stone 0
fill ~58~10~24 ~58~10~26 minecraft:minecraft:sandstone
fill ~59~9~24 ~59~9~29 minecraft:minecraft:sandstone
fill ~60~0~24 ~60~0~63 minecraft:stone 0
fill ~60~13~24 ~60~13~25 minecraft:stone 0
fill ~61~16~24 ~66~16~27 minecraft:stone 0
fill ~61~17~24 ~66~17~24 minecraft:mycelium
fill ~62~11~24 ~66~11~32 minecraft:minecraft:sandstone
fill ~62~12~24 ~63~12~31 minecraft:minecraft:sandstone
fill ~63~9~24 ~63~10~35 minecraft:minecraft:sandstone
fill ~64~10~24 ~67~10~36 minecraft:minecraft:sandstone
setblock ~64~12~24 minecraft:stone 0
fill ~67~16~24 ~69~16~24 minecraft:mycelium
fill ~68~10~24 ~68~10~27 minecraft:stone 0
fill ~68~15~24 ~68~15~33 minecraft:stone 0
setblock ~69~15~24 minecraft:dirt 0
fill ~70~0~24 ~70~0~26 minecraft:minecraft:sandstone
fill ~70~14~24 ~71~14~24 minecraft:stone 0
fill ~70~15~24 ~71~15~24 minecraft:mycelium
fill ~71~0~24 ~74~0~24 minecraft:dirt 0
fill ~72~7~24 ~74~7~26 minecraft:stone 0
setblock ~72~13~24 minecraft:stone 0
fill ~72~14~24 ~73~14~24 minecraft:mycelium
fill ~73~12~24 ~73~12~36 minecraft:stone 0
fill ~73~13~24 ~73~13~29 minecraft:dirt 0
fill ~74~8~24 ~74~8~26 minecraft:stone 0
fill ~74~10~24 ~74~10~34 minecraft:stone 0
fill ~74~11~24 ~74~11~28 minecraft:mycelium
fill ~75~7~24 ~75~7~25 minecraft:mycelium
fill ~76~0~24 ~76~0~32 minecraft:stone 0
fill ~76~7~24 ~77~7~36 minecraft:stone 0
fill ~6~0~25 ~6~0~66 minecraft:stone 0
fill ~6~1~25 ~6~1~26 minecraft:mycelium
setblock ~8~3~25 minecraft:stone 0
fill ~8~4~25 ~8~4~26 minecraft:mycelium
fill ~9~4~25 ~10~4~34 minecraft:stone 0
fill ~9~5~25 ~11~5~25 minecraft:mycelium
fill ~12~5~25 ~12~5~32 minecraft:stone 0
setblock ~12~6~25 minecraft:mycelium
fill ~13~6~25 ~14~6~31 minecraft:stone 0
setblock ~13~7~25 minecraft:mycelium
fill ~14~7~25 ~15~7~31 minecraft:stone 0
setblock ~14~8~25 minecraft:mycelium
fill ~15~8~25 ~16~8~32 minecraft:stone 0
setblock ~15~9~25 minecraft:mycelium
fill ~16~9~25 ~17~9~32 minecraft:stone 0
fill ~16~10~25 ~18~10~28 minecraft:stone 0
fill ~16~11~25 ~16~11~28 minecraft:stone 0
setblock ~16~12~25 minecraft:mycelium
setblock ~17~1~25 minecraft:dirt 0
fill ~17~2~25 ~17~3~25 minecraft:stone 0
setblock ~17~11~25 minecraft:dirt 0
fill ~17~12~25 ~19~12~31 minecraft:stone 0
setblock ~17~13~25 minecraft:dirt 0
setblock ~17~14~25 minecraft:mycelium
fill ~18~1~25 ~18~1~73 minecraft:stone 0
fill ~18~2~25 ~19~2~25 minecraft:dirt 0
fill ~18~11~25 ~19~11~31 minecraft:stone 0
fill ~18~13~25 ~19~14~32 minecraft:stone 0
fill ~18~15~25 ~19~15~25 minecraft:mycelium
fill ~20~2~25 ~20~2~73 minecraft:stone 0
fill ~20~15~25 ~20~15~33 minecraft:stone 0
setblock ~20~16~25 minecraft:mycelium
fill ~21~4~25 ~24~4~25 minecraft:dirt 0
fill ~22~3~25 ~23~3~73 minecraft:stone 0
fill ~22~16~25 ~22~16~32 minecraft:stone 0
fill ~22~17~25 ~23~17~30 minecraft:stone 0
fill ~22~18~25 ~24~18~25 minecraft:mycelium
fill ~25~4~25 ~26~4~73 minecraft:stone 0
fill ~25~5~25 ~25~5~26 minecraft:dirt 0
fill ~25~6~25 ~25~7~25 minecraft:stone 0
setblock ~25~15~25 minecraft:stone 0
fill ~25~18~25 ~34~18~25 minecraft:dirt 0
fill ~25~19~25 ~31~19~25 minecraft:mycelium
fill ~26~6~25 ~26~6~27 minecraft:dirt 0
setblock ~26~7~25 minecraft:stone 0
setblock ~26~9~25 minecraft:stone 0
fill ~26~12~25 ~26~12~27 minecraft:dirt 0
setblock ~26~13~25 minecraft:dirt 0
fill ~27~8~25 ~27~8~31 minecraft:dirt 0
fill ~27~9~25 ~27~11~27 minecraft:dirt 0
fill ~27~16~25 ~27~16~27 minecraft:stone 0
fill ~28~5~25 ~30~5~73 minecraft:stone 0
fill ~28~11~25 ~31~11~26 minecraft:dirt 0
fill ~28~13~25 ~35~13~28 minecraft:dirt 0
setblock ~28~14~25 minecraft:stone 0
fill ~29~14~25 ~29~14~69 minecraft:dirt 0
fill ~29~16~25 ~29~16~26 minecraft:stone 0
fill ~30~6~25 ~30~6~72 minecraft:stone 0
fill ~30~12~25 ~31~12~70 minecraft:dirt 0
fill ~30~14~25 ~32~15~27 minecraft:stone 0
setblock ~30~16~25 minecraft:dirt 0
fill ~31~6~25 ~32~6~25 minecraft:dirt 0
fill ~31~16~25 ~31~16~28 minecraft:stone 0
fill ~32~7~25 ~33~7~25 minecraft:dirt 0
setblock ~32~11~25 minecraft:mycelium
setblock ~32~16~25 minecraft:dirt 0
fill ~32~19~25 ~35~19~25 minecraft:dirt 0
fill ~32~20~25 ~34~20~25 minecraft:mycelium
fill ~33~6~25 ~35~6~72 minecraft:stone 0
fill ~33~11~25 ~35~11~37 minecraft:dirt 0
fill ~33~12~25 ~34~12~43 minecraft:dirt 0
fill ~33~14~25 ~33~15~25 minecraft:dirt 0
fill ~33~16~25 ~33~16~27 minecraft:stone 0
fill ~34~7~25 ~37~7~71 minecraft:stone 0
fill ~34~14~25 ~42~14~26 minecraft:stone 0
fill ~34~15~25 ~39~15~25 minecraft:stone 0
fill ~35~8~25 ~35~9~25 minecraft:dirt 0
fill ~35~18~25 ~37~18~25 minecraft:stone 0
fill ~35~20~25 ~38~20~27 minecraft:dirt 0
setblock ~35~21~25 minecraft:mycelium
fill ~36~8~25 ~36~8~69 minecraft:stone 0
fill ~36~9~25 ~41~9~31 minecraft:dirt 0
fill ~36~17~25 ~37~17~25 minecraft:stone 0
fill ~36~21~25 ~43~21~26 minecraft:dirt 0
fill ~36~22~25 ~37~22~25 minecraft:mycelium
fill ~37~6~25 ~42~6~73 minecraft:stone 0
fill ~37~8~25 ~41~8~26 minecraft:dirt 0
setblock ~37~41~25 minecraft:jungle_stairs 6
fill ~37~42~25 ~37~42~31 minecraft:jungle_stairs 0
fill ~38~7~25 ~40~7~26 minecraft:dirt 0
fill ~38~13~25 ~41~13~25 minecraft:stone 0
fill ~38~17~25 ~38~18~27 minecraft:dirt 0
fill ~38~22~25 ~41~22~28 minecraft:dirt 0
fill ~38~23~25 ~41~23~25 minecraft:mycelium
fill ~38~42~25 ~38~42~26 minecraft:jungle_stairs 5
fill ~38~43~25 ~38~43~39 minecraft:planks 3
fill ~38~44~25 ~38~44~39 minecraft:jungle_stairs 0
fill ~39~17~25 ~40~17~25 minecraft:stone 0
fill ~39~18~25 ~55~18~25 minecraft:dirt 0
fill ~39~44~25 ~39~46~26 minecraft:planks 3
setblock ~39~48~25 minecraft:wooden_slab 3
setblock ~40~12~25 minecraft:dirt 0
fill ~40~42~25 ~40~42~26 minecraft:jungle_stairs 4
fill ~40~43~25 ~40~43~39 minecraft:planks 3
fill ~40~44~25 ~40~44~39 minecraft:jungle_stairs 1
fill ~41~12~25 ~47~12~26 minecraft:stone 0
fill ~41~17~25 ~50~17~25 minecraft:dirt 0
setblock ~41~41~25 minecraft:jungle_stairs 6
fill ~41~42~25 ~41~42~40 minecraft:jungle_stairs 1
setblock ~42~13~25 minecraft:dirt 0
fill ~42~20~25 ~44~20~27 minecraft:dirt 0
fill ~42~22~25 ~43~22~25 minecraft:mycelium
fill ~43~14~25 ~43~14~26 minecraft:dirt 0
fill ~43~16~25 ~43~16~27 minecraft:stone 0
fill ~44~6~25 ~45~6~72 minecraft:stone 0
fill ~44~7~25 ~44~7~71 minecraft:stone 0
setblock ~44~8~25 minecraft:stone 0
fill ~44~9~25 ~45~10~30 minecraft:dirt 0
fill ~44~11~25 ~44~11~26 minecraft:stone 0
fill ~44~14~25 ~52~14~25 minecraft:stone 0
fill ~44~19~25 ~53~19~27 minecraft:dirt 0
setblock ~44~21~25 minecraft:mycelium
fill ~45~7~25 ~45~8~26 minecraft:dirt 0
setblock ~45~11~25 minecraft:dirt 0
fill ~45~20~25 ~53~20~25 minecraft:mycelium
setblock ~46~6~25 minecraft:dirt 0
fill ~46~11~25 ~47~11~26 minecraft:stone 0
fill ~46~13~25 ~49~13~26 minecraft:stone 0
fill ~48~5~25 ~52~5~72 minecraft:stone 0
setblock ~48~11~25 minecraft:dirt 0
fill ~50~12~25 ~50~13~25 minecraft:dirt 0
fill ~51~13~25 ~52~13~27 minecraft:stone 0
fill ~51~15~25 ~53~15~28 minecraft:stone 0
fill ~51~16~25 ~51~16~26 minecraft:stone 0
fill ~51~17~25 ~57~17~25 minecraft:stone 0
fill ~52~4~25 ~53~4~79 minecraft:stone 0
fill ~52~6~25 ~52~6~27 minecraft:dirt 0
fill ~52~8~25 ~54~8~32 minecraft:dirt 0
fill ~52~9~25 ~53~9~33 minecraft:dirt 0
fill ~52~10~25 ~52~10~40 minecraft:dirt 0
setblock ~52~46~25 minecraft:jungle_stairs 6
fill ~53~5~25 ~57~5~25 minecraft:minecraft:sandstone
fill ~53~7~25 ~53~7~30 minecraft:dirt 0
fill ~54~4~25 ~58~4~25 minecraft:minecraft:sandstone
setblock ~54~15~25 minecraft:dirt 0
fill ~54~16~25 ~54~16~28 minecraft:stone 0
fill ~54~19~25 ~55~19~25 minecraft:mycelium
fill ~55~3~25 ~56~3~68 minecraft:stone 0
fill ~55~8~25 ~57~8~25 minecraft:minecraft:sandstone
fill ~55~9~25 ~55~9~38 minecraft:dirt 0
fill ~55~13~25 ~55~13~27 minecraft:stone 0
fill ~55~15~25 ~55~15~55 minecraft:stone 0
fill ~55~16~25 ~56~16~25 minecraft:dirt 0
fill ~56~9~25 ~57~9~25 minecraft:minecraft:sandstone
fill ~56~10~25 ~56~10~41 minecraft:dirt 0
fill ~56~12~25 ~58~12~26 minecraft:stone 0
setblock ~56~15~25 minecraft:dirt 0
setblock ~56~19~25 minecraft:dirt 0
setblock ~56~20~25 minecraft:mossy_cobblestone
fill ~57~3~25 ~58~3~25 minecraft:minecraft:sandstone
fill ~57~11~25 ~57~11~33 minecraft:dirt 0
fill ~57~13~25 ~58~13~28 minecraft:stone 0
fill ~57~15~25 ~60~15~25 minecraft:stone 0
fill ~57~16~25 ~57~16~30 minecraft:stone 0
fill ~57~18~25 ~57~18~27 minecraft:dirt 0
fill ~57~19~25 ~57~19~26 minecraft:mycelium
fill ~58~2~25 ~58~2~64 minecraft:stone 0
fill ~58~11~25 ~59~11~25 minecraft:minecraft:sandstone
fill ~58~14~25 ~59~14~25 minecraft:stone 0
fill ~58~16~25 ~58~17~25 minecraft:dirt 0
fill ~58~18~25 ~59~18~25 minecraft:mycelium
setblock ~58~19~25 minecraft:stone_stairs 2
setblock ~59~2~25 minecraft:minecraft:sandstone
fill ~59~10~25 ~60~10~28 minecraft:minecraft:sandstone
fill ~59~16~25 ~60~16~25 minecraft:stone 0
fill ~59~17~25 ~65~17~25 minecraft:dirt 0
fill ~60~1~25 ~60~1~63 minecraft:stone 0
fill ~60~9~25 ~62~9~30 minecraft:minecraft:sandstone
setblock ~60~14~25 minecraft:dirt 0
fill ~60~18~25 ~60~18~26 minecraft:dirt 0
setblock ~60~19~25 minecraft:mossy_cobblestone
fill ~61~0~25 ~62~0~63 minecraft:stone 0
fill ~61~18~25 ~65~18~25 minecraft:mycelium
setblock ~62~10~25 minecraft:minecraft:sandstone
fill ~64~12~25 ~65~12~37 minecraft:minecraft:sandstone
fill ~66~12~25 ~66~12~26 minecraft:stone 0
fill ~66~17~25 ~67~17~25 minecraft:mycelium
fill ~67~16~25 ~67~16~39 minecraft:stone 0
fill ~68~16~25 ~70~16~25 minecraft:mycelium
fill ~69~15~25 ~70~15~27 minecraft:stone 0
fill ~70~14~25 ~70~14~35 minecraft:stone 0
setblock ~71~0~25 minecraft:minecraft:sandstone
fill ~71~6~25 ~71~6~36 minecraft:minecraft:sandstone
fill ~71~14~25 ~72~14~27 minecraft:dirt 0
fill ~71~15~25 ~72~15~25 minecraft:mycelium
fill ~72~0~25 ~72~1~27 minecraft:dirt 0
fill ~72~6~25 ~72~6~26 minecraft:stone 0
setblock ~72~13~25 minecraft:dirt 0
fill ~73~0~25 ~74~0~31 minecraft:stone 0
setblock ~73~1~25 minecraft:dirt 0
fill ~73~14~25 ~73~14~26 minecraft:mycelium
fill ~81~4~25 ~81~4~26 minecraft:mycelium
fill ~82~3~25 ~82~3~26 minecraft:mycelium
fill ~83~0~25 ~83~1~25 minecraft:dirt 0
fill ~83~2~25 ~83~2~27 minecraft:mycelium
fill ~4~0~26 ~4~0~27 minecraft:mycelium
fill ~5~0~26 ~5~0~59 minecraft:stone 0
setblock ~5~1~26 minecraft:mycelium
fill ~7~1~26 ~7~2~32 minecraft:stone 0
fill ~7~3~26 ~7~3~27 minecraft:mycelium
setblock ~8~3~26 minecraft:dirt 0
setblock ~9~5~26 minecraft:mycelium
fill ~10~5~26 ~11~5~32 minecraft:stone 0
fill ~10~6~26 ~11~6~26 minecraft:mycelium
fill ~12~6~26 ~12~6~32 minecraft:stone 0
setblock ~12~7~26 minecraft:mycelium
setblock ~13~3~26 minecraft:dirt 0
fill ~13~7~26 ~13~7~33 minecraft:stone 0
setblock ~13~8~26 minecraft:mycelium
fill ~14~3~26 ~14~3~29 minecraft:stone 0
fill ~14~8~26 ~14~8~34 minecraft:stone 0
setblock ~14~9~26 minecraft:mycelium
setblock ~15~1~26 minecraft:stone 0
fill ~15~9~26 ~15~10~34 minecraft:stone 0
fill ~15~11~26 ~15~11~28 minecraft:stone 0
fill ~15~12~26 ~15~12~27 minecraft:mycelium
setblock ~16~1~26 minecraft:dirt 0
fill ~16~12~26 ~16~12~35 minecraft:stone 0
fill ~16~13~26 ~16~13~27 minecraft:mycelium
fill ~17~1~26 ~17~1~72 minecraft:stone 0
fill ~17~2~26 ~18~2~26 minecraft:dirt 0
fill ~17~3~26 ~18~3~26 minecraft:stone 0
fill ~17~11~26 ~17~11~33 minecraft:stone 0
fill ~17~13~26 ~17~13~35 minecraft:stone 0
fill ~17~14~26 ~17~14~33 minecraft:stone 0
fill ~17~15~26 ~18~15~26 minecraft:mycelium
fill ~18~4~26 ~19~4~26 minecraft:stone 0
fill ~19~2~26 ~19~2~72 minecraft:stone 0
fill ~19~3~26 ~20~3~26 minecraft:dirt 0
fill ~19~15~26 ~19~15~33 minecraft:stone 0
setblock ~19~16~26 minecraft:mycelium
fill ~20~4~26 ~22~4~26 minecraft:dirt 0
setblock ~20~5~26 minecraft:stone 0
fill ~20~16~26 ~21~16~32 minecraft:stone 0
fill ~20~17~26 ~21~17~26 minecraft:mycelium
fill ~21~5~26 ~24~5~27 minecraft:dirt 0
fill ~22~6~26 ~24~6~26 minecraft:stone 0
setblock ~22~18~26 minecraft:mycelium
fill ~23~4~26 ~24~4~72 minecraft:stone 0
fill ~23~18~26 ~23~19~26 minecraft:dirt 0
fill ~23~20~26 ~33~20~26 minecraft:mycelium
fill ~24~7~26 ~25~7~26 minecraft:stone 0
fill ~24~18~26 ~28~18~29 minecraft:stone 0
fill ~24~19~26 ~29~19~26 minecraft:dirt 0
fill ~25~6~26 ~25~6~28 minecraft:dirt 0
setblock ~25~8~26 minecraft:stone 0
setblock ~25~15~26 minecraft:dirt 0
fill ~26~5~26 ~27~5~73 minecraft:stone 0
fill ~26~7~26 ~26~8~30 minecraft:dirt 0
fill ~26~9~26 ~26~9~27 minecraft:dirt 0
fill ~26~10~26 ~26~11~26 minecraft:dirt 0
fill ~26~13~26 ~26~13~27 minecraft:stone 0
fill ~27~15~26 ~27~15~29 minecraft:stone 0
setblock ~28~14~26 minecraft:dirt 0
setblock ~28~16~26 minecraft:dirt 0
setblock ~29~18~26 minecraft:dirt 0
setblock ~30~16~26 minecraft:stone 0
fill ~30~18~26 ~31~19~27 minecraft:stone 0
fill ~31~6~26 ~32~6~72 minecraft:stone 0
fill ~31~7~26 ~32~7~70 minecraft:stone 0
setblock ~31~8~26 minecraft:mycelium
setblock ~31~21~26 minecraft:red_mushroom
fill ~32~9~26 ~35~9~31 minecraft:dirt 0
fill ~32~11~26 ~32~12~38 minecraft:dirt 0
fill ~32~16~26 ~32~16~28 minecraft:stone 0
fill ~32~18~26 ~32~19~26 minecraft:dirt 0
setblock ~33~7~26 minecraft:dirt 0
fill ~33~14~26 ~33~14~28 minecraft:stone 0
setblock ~33~15~26 minecraft:dirt 0
fill ~33~18~26 ~36~18~26 minecraft:stone 0
fill ~33~19~26 ~34~19~26 minecraft:stone 0
fill ~34~15~26 ~37~15~26 minecraft:stone 0
setblock ~34~20~26 minecraft:stone 0
fill ~34~21~26 ~35~21~27 minecraft:dirt 0
setblock ~34~22~26 minecraft:mycelium
fill ~35~8~26 ~35~8~69 minecraft:stone 0
setblock ~35~16~26 minecraft:dirt 0
fill ~35~19~26 ~35~19~29 minecraft:dirt 0
fill ~35~22~26 ~37~22~28 minecraft:dirt 0
setblock ~35~23~26 minecraft:mycelium
setblock ~35~29~26 minecraft:stone_block_slab 5
setblock ~35~37~26 minecraft:jungle_stairs 6
fill ~35~38~26 ~35~38~31 minecraft:jungle_stairs 0
fill ~36~16~26 ~37~16~26 minecraft:stone 0
setblock ~36~17~26 minecraft:stone 0
fill ~36~23~26 ~43~23~39 minecraft:dirt 0
fill ~36~24~26 ~43~24~26 minecraft:mycelium
setblock ~36~38~26 minecraft:jungle_stairs 5
fill ~36~39~26 ~36~39~32 minecraft:planks 3
fill ~36~40~26 ~36~40~30 minecraft:jungle_stairs 0
fill ~37~17~26 ~37~18~27 minecraft:dirt 0
setblock ~37~40~26 minecraft:jungle_stairs 5
fill ~37~41~26 ~37~41~33 minecraft:planks 3
fill ~38~13~26 ~39~13~26 minecraft:stone 0
fill ~38~15~26 ~39~15~27 minecraft:dirt 0
fill ~38~16~26 ~38~16~27 minecraft:dirt 0
setblock ~39~16~26 minecraft:stone 0
fill ~39~17~26 ~40~18~27 minecraft:dirt 0
setblock ~39~25~26 minecraft:trapdoor 3
setblock ~40~12~26 minecraft:stone 0
setblock ~40~13~26 minecraft:dirt 0
fill ~41~7~26 ~42~7~26 minecraft:dirt 0
fill ~41~13~26 ~42~13~27 minecraft:stone 0
fill ~41~17~26 ~42~17~26 minecraft:stone 0
fill ~41~18~26 ~52~18~27 minecraft:dirt 0
setblock ~41~40~26 minecraft:jungle_stairs 4
fill ~41~41~26 ~41~41~41 minecraft:planks 3
fill ~42~15~26 ~42~15~28 minecraft:dirt 0
fill ~42~22~26 ~44~22~28 minecraft:dirt 0
setblock ~42~38~26 minecraft:jungle_stairs 4
fill ~42~39~26 ~42~39~40 minecraft:planks 3
fill ~42~40~26 ~42~40~40 minecraft:jungle_stairs 1
fill ~43~7~26 ~43~7~72 minecraft:stone 0
fill ~43~11~26 ~43~11~37 minecraft:dirt 0
fill ~43~15~26 ~43~15~27 minecraft:stone 0
fill ~43~17~26 ~51~17~27 minecraft:dirt 0
setblock ~43~29~26 minecraft:stone_block_slab 5
setblock ~43~37~26 minecraft:jungle_stairs 6
fill ~43~38~26 ~43~38~30 minecraft:jungle_stairs 1
fill ~44~8~26 ~44~8~27 minecraft:dirt 0
fill ~44~13~26 ~44~13~27 minecraft:stone 0
setblock ~44~14~26 minecraft:stone 0
fill ~44~16~26 ~44~16~27 minecraft:stone 0
fill ~44~21~26 ~46~21~26 minecraft:dirt 0
setblock ~44~23~26 minecraft:mycelium
setblock ~45~11~26 minecraft:stone 0
setblock ~45~14~26 minecraft:dirt 0
setblock ~45~15~26 minecraft:stone 0
fill ~45~16~26 ~46~16~27 minecraft:dirt 0
fill ~45~20~26 ~53~20~27 minecraft:dirt 0
fill ~45~22~26 ~46~22~26 minecraft:mycelium
fill ~46~6~26 ~48~6~72 minecraft:stone 0
fill ~46~14~26 ~52~14~28 minecraft:stone 0
fill ~46~15~26 ~46~15~27 minecraft:dirt 0
fill ~47~15~26 ~50~15~26 minecraft:stone 0
fill ~47~21~26 ~48~21~26 minecraft:mycelium
setblock ~48~11~26 minecraft:stone 0
fill ~48~12~26 ~49~12~26 minecraft:dirt 0
fill ~49~11~26 ~49~11~30 minecraft:dirt 0
fill ~49~16~26 ~49~16~30 minecraft:dirt 0
fill ~49~21~26 ~51~21~27 minecraft:dirt 0
fill ~49~22~26 ~51~22~26 minecraft:mycelium
fill ~50~12~26 ~50~13~27 minecraft:stone 0
fill ~50~16~26 ~50~16~27 minecraft:stone 0
setblock ~51~44~26 minecraft:jungle_stairs 6
fill ~51~45~26 ~51~45~28 minecraft:jungle_stairs 0
fill ~52~17~26 ~55~17~26 minecraft:stone 0
fill ~52~21~26 ~53~21~26 minecraft:mycelium
setblock ~52~46~26 minecraft:jungle_stairs 3
fill ~53~5~26 ~55~5~26 minecraft:stone 0
setblock ~53~6~26 minecraft:dirt 0
fill ~53~13~26 ~53~13~27 minecraft:stone 0
fill ~53~18~26 ~54~18~26 minecraft:stone 0
setblock ~53~44~26 minecraft:jungle_stairs 6
fill ~53~45~26 ~53~45~28 minecraft:jungle_stairs 1
fill ~54~4~26 ~55~4~72 minecraft:stone 0
fill ~54~6~26 ~57~6~26 minecraft:minecraft:sandstone
fill ~54~7~26 ~54~7~31 minecraft:dirt 0
fill ~54~15~26 ~54~15~40 minecraft:stone 0
setblock ~54~19~26 minecraft:stone 0
fill ~54~20~26 ~55~20~26 minecraft:mycelium
fill ~55~7~26 ~56~7~26 minecraft:minecraft:sandstone
fill ~55~8~26 ~55~8~32 minecraft:dirt 0
fill ~55~16~26 ~56~16~28 minecraft:stone 0
fill ~55~18~26 ~55~19~27 minecraft:dirt 0
fill ~56~4~26 ~58~4~26 minecraft:minecraft:sandstone
fill ~56~5~26 ~57~5~26 minecraft:minecraft:sandstone
fill ~56~8~26 ~57~8~26 minecraft:minecraft:sandstone
fill ~56~9~26 ~56~9~36 minecraft:dirt 0
fill ~56~15~26 ~58~15~26 minecraft:stone 0
fill ~56~17~26 ~60~17~26 minecraft:dirt 0
setblock ~56~19~26 minecraft:mycelium
fill ~57~3~26 ~57~3~68 minecraft:stone 0
setblock ~57~9~26 minecraft:minecraft:sandstone
fill ~57~10~26 ~57~10~45 minecraft:dirt 0
setblock ~58~3~26 minecraft:minecraft:sandstone
fill ~58~11~26 ~58~11~32 minecraft:dirt 0
setblock ~58~14~26 minecraft:stone 0
setblock ~58~16~26 minecraft:stone 0
fill ~58~18~26 ~59~18~27 minecraft:dirt 0
fill ~58~19~26 ~64~19~26 minecraft:mycelium
fill ~59~2~26 ~59~2~64 minecraft:stone 0
fill ~59~11~26 ~60~11~27 minecraft:minecraft:sandstone
fill ~59~12~26 ~59~12~27 minecraft:stone 0
setblock ~59~13~26 minecraft:stone 0
setblock ~59~14~26 minecraft:mycelium
setblock ~60~15~26 minecraft:dirt 0
fill ~60~16~26 ~60~16~34 minecraft:stone 0
fill ~61~1~26 ~61~1~63 minecraft:stone 0
fill ~61~17~26 ~64~17~28 minecraft:stone 0
fill ~61~18~26 ~64~18~26 minecraft:dirt 0
fill ~63~0~26 ~63~0~64 minecraft:stone 0
fill ~64~0~26 ~64~0~27 minecraft:minecraft:sandstone
fill ~65~17~26 ~67~17~26 minecraft:dirt 0
fill ~65~18~26 ~67~18~26 minecraft:mycelium
setblock ~68~16~26 minecraft:dirt 0
fill ~68~17~26 ~69~17~26 minecraft:mycelium
setblock ~69~16~26 minecraft:stone 0
fill ~70~16~26 ~71~16~26 minecraft:mycelium
fill ~71~0~26 ~71~0~28 minecraft:dirt 0
fill ~71~15~26 ~71~15~27 minecraft:dirt 0
fill ~72~5~26 ~72~5~34 minecraft:minecraft:sandstone
fill ~72~13~26 ~72~13~37 minecraft:stone 0
fill ~72~15~26 ~72~15~27 minecraft:mycelium
fill ~73~1~26 ~73~1~55 minecraft:stone 0
setblock ~73~2~26 minecraft:dirt 0
fill ~73~4~26 ~73~4~27 minecraft:minecraft:sandstone
fill ~73~5~26 ~77~5~26 minecraft:stone 0
fill ~74~4~26 ~77~4~35 minecraft:stone 0
fill ~75~7~26 ~75~7~35 minecraft:stone 0
fill ~75~8~26 ~75~8~34 minecraft:stone 0
fill ~83~0~26 ~83~0~79 minecraft:stone 0
setblock ~83~1~26 minecraft:dirt 0
fill ~3~0~27 ~3~0~28 minecraft:mycelium
fill ~5~1~27 ~6~1~29 minecraft:stone 0
fill ~5~2~27 ~5~2~28 minecraft:mycelium
fill ~6~2~27 ~6~2~51 minecraft:stone 0
fill ~6~3~27 ~6~3~28 minecraft:mycelium
fill ~8~3~27 ~8~4~41 minecraft:stone 0
setblock ~8~5~27 minecraft:mycelium
fill ~9~5~27 ~9~5~36 minecraft:stone 0
fill ~9~6~27 ~10~6~27 minecraft:mycelium
fill ~11~6~27 ~11~7~35 minecraft:stone 0
setblock ~11~8~27 minecraft:mycelium
fill ~12~0~27 ~14~0~27 minecraft:dirt 0
fill ~12~7~27 ~12~8~35 minecraft:stone 0
setblock ~12~9~27 minecraft:mycelium
fill ~13~1~27 ~15~1~27 minecraft:dirt 0
fill ~13~2~27 ~13~3~28 minecraft:stone 0
fill ~13~8~27 ~13~10~28 minecraft:stone 0
fill ~13~11~27 ~14~11~27 minecraft:mycelium
fill ~14~2~27 ~17~2~27 minecraft:dirt 0
fill ~14~9~27 ~14~10~35 minecraft:stone 0
fill ~16~1~27 ~16~1~72 minecraft:stone 0
setblock ~17~3~27 minecraft:stone 0
setblock ~17~15~27 minecraft:mycelium
fill ~18~2~27 ~18~2~71 minecraft:stone 0
fill ~18~3~27 ~19~3~27 minecraft:dirt 0
setblock ~18~4~27 minecraft:stone 0
fill ~18~15~27 ~18~15~34 minecraft:stone 0
setblock ~18~16~27 minecraft:mycelium
fill ~19~4~27 ~21~4~27 minecraft:dirt 0
setblock ~19~6~27 minecraft:stone 0
fill ~19~16~27 ~19~16~35 minecraft:stone 0
fill ~19~17~27 ~20~17~27 minecraft:mycelium
fill ~20~3~27 ~20~3~71 minecraft:stone 0
fill ~20~5~27 ~20~7~30 minecraft:dirt 0
fill ~21~6~27 ~24~6~29 minecraft:dirt 0
setblock ~21~7~27 minecraft:stone 0
fill ~21~17~27 ~21~17~28 minecraft:stone 0
setblock ~21~18~27 minecraft:mycelium
fill ~22~4~27 ~22~4~71 minecraft:stone 0
fill ~22~18~27 ~23~18~34 minecraft:stone 0
fill ~22~19~27 ~23~20~27 minecraft:dirt 0
fill ~22~21~27 ~31~21~27 minecraft:mycelium
setblock ~22~22~27 minecraft:brown_mushroom
fill ~24~7~27 ~25~7~29 minecraft:dirt 0
fill ~24~17~27 ~33~17~27 minecraft:stone 0
fill ~24~19~27 ~27~19~27 minecraft:stone 0
fill ~24~20~27 ~25~20~27 minecraft:dirt 0
fill ~25~5~27 ~25~5~73 minecraft:stone 0
fill ~25~8~27 ~25~8~33 minecraft:dirt 0
fill ~25~9~27 ~25~9~28 minecraft:dirt 0
fill ~25~10~27 ~25~14~27 minecraft:dirt 0
fill ~25~15~27 ~25~15~29 minecraft:stone 0
setblock ~26~10~27 minecraft:mycelium
setblock ~26~20~27 minecraft:stone 0
fill ~27~13~27 ~27~13~28 minecraft:dirt 0
setblock ~27~20~27 minecraft:dirt 0
fill ~28~6~27 ~29~6~72 minecraft:stone 0
fill ~28~11~27 ~30~11~27 minecraft:dirt 0
setblock ~28~14~27 minecraft:stone 0
setblock ~28~16~27 minecraft:stone 0
fill ~28~19~27 ~29~19~27 minecraft:dirt 0
setblock ~28~20~27 minecraft:stone 0
fill ~29~16~27 ~30~16~27 minecraft:dirt 0
fill ~29~18~27 ~29~18~28 minecraft:stone 0
setblock ~29~20~27 minecraft:dirt 0
fill ~30~7~27 ~30~7~70 minecraft:stone 0
setblock ~30~10~27 minecraft:dirt 0
fill ~30~20~27 ~33~20~27 minecraft:stone 0
setblock ~31~8~27 minecraft:dirt 0
setblock ~31~9~27 minecraft:mycelium
fill ~32~10~27 ~35~10~33 minecraft:dirt 0
fill ~32~18~27 ~33~19~27 minecraft:stone 0
setblock ~32~21~27 minecraft:dirt 0
setblock ~32~22~27 minecraft:cobblestone
fill ~33~7~27 ~33~7~71 minecraft:stone 0
fill ~33~15~27 ~36~15~27 minecraft:stone 0
setblock ~33~21~27 minecraft:mycelium
fill ~34~14~27 ~36~14~27 minecraft:stone 0
fill ~34~17~27 ~36~18~29 minecraft:dirt 0
fill ~34~19~27 ~34~19~30 minecraft:dirt 0
setblock ~34~20~27 minecraft:dirt 0
fill ~34~22~27 ~34~22~69 minecraft:dirt 0
setblock ~34~23~27 minecraft:mycelium
fill ~34~29~27 ~34~29~29 minecraft:stone_block_slab 5
fill ~34~36~27 ~34~36~29 minecraft:jungle_stairs 0
setblock ~35~16~27 minecraft:stone 0
fill ~35~23~27 ~35~23~67 minecraft:dirt 0
setblock ~35~24~27 minecraft:stonebrick 0
fill ~35~25~27 ~35~29~27 minecraft:log 1
setblock ~35~30~27 minecraft:stone_brick_stairs 2
setblock ~35~36~27 minecraft:jungle_stairs 5
fill ~35~37~27 ~35~37~31 minecraft:planks 3
fill ~36~16~27 ~37~16~27 minecraft:dirt 0
fill ~36~21~27 ~39~21~27 minecraft:dirt 0
fill ~36~24~27 ~36~24~28 minecraft:dirt 0
setblock ~36~25~27 minecraft:stone_brick_stairs 2
setblock ~36~27~27 minecraft:stone_stairs 4
setblock ~36~28~27 minecraft:cobblestone
fill ~36~38~27 ~37~38~28 minecraft:wood 1
fill ~37~8~27 ~38~8~69 minecraft:stone 0
fill ~37~14~27 ~40~14~27 minecraft:dirt 0
setblock ~37~15~27 minecraft:dirt 0
fill ~37~24~27 ~37~24~33 minecraft:cobblestone
fill ~37~25~27 ~37~27~27 minecraft:cobblestone
setblock ~37~28~27 minecraft:nether_brick_stairs 2
fill ~37~39~27 ~37~40~28 minecraft:wood 1
fill ~38~7~27 ~42~7~71 minecraft:stone 0
fill ~38~13~27 ~39~13~47 minecraft:dirt 0
setblock ~38~24~27 minecraft:mycelium
setblock ~38~25~27 minecraft:trapdoor 1
setblock ~38~27~27 minecraft:stone_stairs 5
setblock ~38~28~27 minecraft:double_stone_block_slab 5
fill ~38~40~27 ~38~42~28 minecraft:wood 1
fill ~39~8~27 ~41~8~27 minecraft:dirt 0
fill ~39~16~27 ~41~16~27 minecraft:dirt 0
fill ~39~24~27 ~39~25~27 minecraft:glowstone
setblock ~39~26~27 minecraft:stone_brick_stairs 2
setblock ~39~28~27 minecraft:stone_block_slab 13
setblock ~39~29~27 minecraft:stone_block_slab 5
fill ~39~42~27 ~40~42~28 minecraft:wood 1
fill ~39~43~27 ~39~44~28 minecraft:wood 1
fill ~39~45~27 ~39~46~39 minecraft:planks 3
fill ~40~12~27 ~40~12~36 minecraft:dirt 0
setblock ~40~13~27 minecraft:stone 0
fill ~40~15~27 ~40~15~28 minecraft:dirt 0
setblock ~40~24~27 minecraft:mycelium
setblock ~40~25~27 minecraft:trapdoor 1
setblock ~40~27~27 minecraft:stone_stairs 4
setblock ~40~28~27 minecraft:double_stone_block_slab 5
fill ~40~40~27 ~41~40~27 minecraft:wood 1
fill ~40~41~27 ~40~41~28 minecraft:wood 1
fill ~41~12~27 ~46~12~27 minecraft:stone 0
fill ~41~14~27 ~43~14~27 minecraft:stone 0
fill ~41~17~27 ~42~17~27 minecraft:dirt 0
fill ~41~24~27 ~41~25~27 minecraft:cobblestone
fill ~41~26~27 ~41~26~28 minecraft:mossy_cobblestone
setblock ~41~27~27 minecraft:cobblestone
setblock ~41~28~27 minecraft:nether_brick_stairs 2
fill ~41~38~27 ~42~38~28 minecraft:wood 1
fill ~41~39~27 ~41~39~28 minecraft:wood 1
fill ~42~8~27 ~43~8~69 minecraft:stone 0
fill ~42~9~27 ~43~9~30 minecraft:dirt 0
fill ~42~16~27 ~42~16~48 minecraft:stone 0
fill ~42~24~27 ~43~24~28 minecraft:dirt 0
setblock ~42~25~27 minecraft:stone_brick_stairs 2
setblock ~42~27~27 minecraft:stone_stairs 5
setblock ~42~28~27 minecraft:cobblestone
fill ~43~25~27 ~43~29~27 minecraft:log 1
setblock ~43~30~27 minecraft:stone_brick_stairs 2
setblock ~43~36~27 minecraft:jungle_stairs 4
fill ~43~37~27 ~43~37~31 minecraft:planks 3
fill ~44~11~27 ~48~11~37 minecraft:dirt 0
fill ~44~14~27 ~44~14~36 minecraft:dirt 0
fill ~44~23~27 ~44~23~28 minecraft:dirt 0
fill ~44~24~27 ~44~24~32 minecraft:mycelium
fill ~44~29~27 ~44~29~31 minecraft:stone_block_slab 5
fill ~44~36~27 ~44~36~31 minecraft:jungle_stairs 1
fill ~45~7~27 ~45~7~71 minecraft:stone 0
fill ~45~8~27 ~45~8~29 minecraft:dirt 0
setblock ~45~14~27 minecraft:stone 0
fill ~45~15~27 ~45~15~28 minecraft:dirt 0
fill ~45~21~27 ~45~22~27 minecraft:dirt 0
fill ~45~23~27 ~50~23~27 minecraft:mycelium
setblock ~46~13~27 minecraft:stone 0
fill ~46~22~27 ~54~22~28 minecraft:dirt 0
fill ~47~12~27 ~47~13~27 minecraft:dirt 0
fill ~47~15~27 ~47~15~30 minecraft:stone 0
fill ~48~12~27 ~49~13~28 minecraft:stone 0
setblock ~48~15~27 minecraft:dirt 0
fill ~49~6~27 ~50~6~71 minecraft:stone 0
fill ~49~15~27 ~50~15~27 minecraft:stone 0
fill ~49~39~27 ~49~39~28 minecraft:jungle_stairs 5
fill ~49~40~27 ~49~40~28 minecraft:jungle_stairs 0
fill ~50~29~27 ~51~29~27 minecraft:stone_block_slab 5
fill ~50~35~27 ~54~35~27 minecraft:stone_block_slab 5
setblock ~50~40~27 minecraft:jungle_stairs 5
fill ~50~41~27 ~50~41~28 minecraft:planks 3
fill ~50~42~27 ~50~42~28 minecraft:jungle_stairs 0
fill ~51~16~27 ~51~16~32 minecraft:dirt 0
fill ~51~23~27 ~53~23~32 minecraft:dirt 0
fill ~51~24~27 ~53~24~27 minecraft:mycelium
setblock ~51~28~27 minecraft:stone_block_slab 13
setblock ~51~42~27 minecraft:jungle_stairs 5
fill ~51~43~27 ~51~44~28 minecraft:planks 3
setblock ~52~17~27 minecraft:stone 0
fill ~52~21~27 ~54~21~27 minecraft:dirt 0
setblock ~52~29~27 minecraft:double_stone_block_slab 5
fill ~52~30~27 ~52~32~27 minecraft:cobblestone_wall 1
fill ~52~33~27 ~52~34~27 minecraft:cobblestone_wall 0
setblock ~52~45~27 minecraft:wooden_slab 11
fill ~52~46~27 ~52~46~28 minecraft:wooden_slab 3
fill ~53~5~27 ~53~5~71 minecraft:stone 0
fill ~53~6~27 ~53~6~69 minecraft:stone 0
fill ~53~14~27 ~53~14~46 minecraft:stone 0
fill ~53~17~27 ~54~17~37 minecraft:dirt 0
fill ~53~18~27 ~54~18~27 minecraft:dirt 0
setblock ~53~28~27 minecraft:stone_block_slab 13
fill ~53~29~27 ~54~29~27 minecraft:stone_block_slab 5
setblock ~53~42~27 minecraft:jungle_stairs 4
fill ~53~43~27 ~53~44~28 minecraft:planks 3
setblock ~54~5~27 minecraft:minecraft:sandstone
setblock ~54~6~27 minecraft:dirt 0
fill ~54~14~27 ~55~14~27 minecraft:dirt 0
fill ~54~19~27 ~54~20~27 minecraft:dirt 0
setblock ~54~23~27 minecraft:mycelium
setblock ~54~40~27 minecraft:jungle_stairs 4
fill ~54~41~27 ~54~41~28 minecraft:planks 3
fill ~54~42~27 ~54~42~28 minecraft:jungle_stairs 1
fill ~55~5~27 ~56~5~27 minecraft:stone 0
fill ~55~6~27 ~57~6~27 minecraft:minecraft:sandstone
fill ~55~7~27 ~55~7~32 minecraft:dirt 0
setblock ~55~17~27 minecraft:stone 0
setblock ~55~20~27 minecraft:dirt 0
setblock ~55~21~27 minecraft:mycelium
fill ~55~39~27 ~55~39~28 minecraft:jungle_stairs 4
fill ~55~40~27 ~55~40~28 minecraft:jungle_stairs 1
fill ~56~4~27 ~56~4~71 minecraft:stone 0
setblock ~56~7~27 minecraft:minecraft:sandstone
fill ~56~8~27 ~56~8~36 minecraft:dirt 0
fill ~56~12~27 ~56~12~30 minecraft:dirt 0
fill ~56~14~27 ~57~15~28 minecraft:stone 0
fill ~56~17~27 ~59~17~40 minecraft:dirt 0
fill ~56~19~27 ~59~19~27 minecraft:dirt 0
fill ~56~20~27 ~64~20~27 minecraft:mycelium
fill ~57~4~27 ~58~4~27 minecraft:minecraft:sandstone
setblock ~57~5~27 minecraft:minecraft:sandstone
setblock ~57~8~27 minecraft:minecraft:sandstone
fill ~57~9~27 ~57~9~38 minecraft:dirt 0
fill ~57~12~27 ~58~12~27 minecraft:stone 0
fill ~58~3~27 ~58~3~68 minecraft:stone 0
fill ~58~10~27 ~58~10~46 minecraft:dirt 0
fill ~58~14~27 ~58~14~28 minecraft:mycelium
fill ~59~13~27 ~59~13~28 minecraft:mycelium
fill ~59~16~27 ~59~16~33 minecraft:stone 0
setblock ~59~21~27 minecraft:stone_stairs 1
fill ~60~2~27 ~60~2~64 minecraft:stone 0
fill ~60~3~27 ~60~3~28 minecraft:minecraft:sandstone
fill ~60~12~27 ~61~12~27 minecraft:minecraft:sandstone
fill ~60~15~27 ~60~15~44 minecraft:stone 0
fill ~60~17~27 ~60~17~31 minecraft:stone 0
fill ~60~18~27 ~60~19~27 minecraft:stone 0
setblock ~60~21~27 minecraft:leaves 1
fill ~61~13~27 ~61~13~28 minecraft:stone 0
fill ~61~18~27 ~62~19~27 minecraft:dirt 0
fill ~62~1~27 ~62~1~64 minecraft:stone 0
fill ~62~2~27 ~65~2~28 minecraft:minecraft:sandstone
fill ~62~10~27 ~62~10~34 minecraft:minecraft:sandstone
fill ~63~1~27 ~65~1~27 minecraft:minecraft:sandstone
fill ~63~18~27 ~63~19~27 minecraft:stone 0
fill ~64~18~27 ~67~18~27 minecraft:dirt 0
setblock ~64~19~27 minecraft:dirt 0
fill ~65~17~27 ~65~17~28 minecraft:stone 0
fill ~65~19~27 ~67~19~27 minecraft:mycelium
fill ~66~12~27 ~66~12~34 minecraft:minecraft:sandstone
fill ~66~17~27 ~68~17~27 minecraft:dirt 0
setblock ~67~3~27 minecraft:minecraft:sandstone
fill ~68~16~27 ~68~16~33 minecraft:stone 0
fill ~68~18~27 ~68~18~29 minecraft:mycelium
fill ~69~9~27 ~69~9~37 minecraft:minecraft:sandstone
fill ~69~16~27 ~70~16~27 minecraft:dirt 0
fill ~69~17~27 ~70~17~28 minecraft:mycelium
setblock ~70~0~27 minecraft:dirt 0
fill ~70~8~27 ~70~8~36 minecraft:minecraft:sandstone
fill ~71~7~27 ~73~7~27 minecraft:dirt 0
fill ~71~16~27 ~71~16~30 minecraft:mycelium
fill ~72~6~27 ~73~6~27 minecraft:dirt 0
fill ~72~29~27 ~72~29~28 minecraft:wood 1
setblock ~72~30~27 minecraft:wood 1
fill ~73~2~27 ~73~2~54 minecraft:stone 0
fill ~73~3~27 ~73~3~53 minecraft:stone 0
fill ~73~5~27 ~73~5~28 minecraft:minecraft:sandstone
fill ~73~14~27 ~73~14~29 minecraft:dirt 0
fill ~73~15~27 ~73~15~30 minecraft:mycelium
fill ~74~5~27 ~77~5~35 minecraft:stone 0
fill ~74~6~27 ~77~6~34 minecraft:stone 0
fill ~74~7~27 ~74~7~29 minecraft:stone 0
setblock ~74~8~27 minecraft:mycelium
fill ~81~4~27 ~81~4~31 minecraft:stone 0
fill ~81~5~27 ~81~5~30 minecraft:mycelium
fill ~82~3~27 ~82~3~32 minecraft:stone 0
fill ~82~4~27 ~82~4~30 minecraft:mycelium
fill ~83~1~27 ~83~1~61 minecraft:stone 0
fill ~84~0~27 ~84~0~80 minecraft:stone 0
setblock ~84~1~27 minecraft:mycelium
fill ~2~0~28 ~2~0~30 minecraft:mycelium
fill ~4~0~28 ~4~0~58 minecraft:stone 0
fill ~4~1~28 ~4~1~29 minecraft:mycelium
fill ~7~3~28 ~7~3~58 minecraft:stone 0
setblock ~7~4~28 minecraft:mycelium
fill ~8~5~28 ~8~5~42 minecraft:stone 0
fill ~8~6~28 ~9~6~28 minecraft:mycelium
fill ~10~6~28 ~10~7~36 minecraft:stone 0
fill ~10~8~28 ~10~8~29 minecraft:mycelium
fill ~11~0~28 ~13~0~28 minecraft:dirt 0
fill ~11~1~28 ~11~3~29 minecraft:stone 0
fill ~11~8~28 ~11~8~42 minecraft:stone 0
fill ~11~9~28 ~11~9~29 minecraft:mycelium
fill ~12~9~28 ~12~10~40 minecraft:stone 0
setblock ~12~11~28 minecraft:mycelium
fill ~13~1~28 ~14~1~28 minecraft:dirt 0
fill ~13~11~28 ~14~11~39 minecraft:stone 0
fill ~13~12~28 ~14~12~28 minecraft:mycelium
fill ~14~0~28 ~14~0~70 minecraft:stone 0
fill ~14~2~28 ~16~2~28 minecraft:dirt 0
fill ~15~1~28 ~15~1~70 minecraft:stone 0
fill ~15~3~28 ~18~3~28 minecraft:dirt 0
setblock ~15~12~28 minecraft:stone 0
setblock ~15~13~28 minecraft:mycelium
fill ~16~13~28 ~16~13~36 minecraft:stone 0
setblock ~16~14~28 minecraft:mycelium
fill ~17~2~28 ~17~2~70 minecraft:stone 0
fill ~17~15~28 ~17~15~35 minecraft:stone 0
setblock ~17~16~28 minecraft:mycelium
fill ~18~4~28 ~20~4~28 minecraft:dirt 0
setblock ~18~5~28 minecraft:stone 0
setblock ~18~7~28 minecraft:stone 0
fill ~18~16~28 ~18~16~35 minecraft:stone 0
fill ~18~17~28 ~19~17~28 minecraft:mycelium
fill ~19~3~28 ~19~3~70 minecraft:stone 0
fill ~19~5~28 ~19~8~31 minecraft:dirt 0
fill ~20~8~28 ~24~8~33 minecraft:dirt 0
fill ~20~17~28 ~20~17~33 minecraft:stone 0
fill ~20~18~28 ~20~18~29 minecraft:mycelium
fill ~21~4~28 ~21~4~70 minecraft:stone 0
fill ~21~5~28 ~22~5~28 minecraft:dirt 0
fill ~21~7~28 ~23~7~32 minecraft:dirt 0
fill ~21~18~28 ~21~18~38 minecraft:stone 0
fill ~21~19~28 ~21~19~29 minecraft:mycelium
fill ~22~19~28 ~23~19~30 minecraft:stone 0
fill ~22~20~28 ~22~20~29 minecraft:dirt 0
fill ~22~21~28 ~24~21~28 minecraft:mycelium
fill ~23~5~28 ~24~5~70 minecraft:stone 0
fill ~23~9~28 ~23~9~30 minecraft:dirt 0
fill ~23~16~28 ~25~16~30 minecraft:stone 0
setblock ~23~20~28 minecraft:stone 0
setblock ~24~9~28 minecraft:mycelium
fill ~24~11~28 ~24~13~28 minecraft:dirt 0
fill ~24~14~28 ~25~14~28 minecraft:stone 0
fill ~24~17~28 ~30~17~28 minecraft:stone 0
setblock ~25~10~28 minecraft:mycelium
fill ~25~12~28 ~25~13~28 minecraft:dirt 0
fill ~25~19~28 ~27~19~28 minecraft:mycelium
fill ~25~22~28 ~32~22~28 minecraft:mycelium
fill ~26~6~28 ~27~6~70 minecraft:stone 0
fill ~26~9~28 ~27~9~29 minecraft:mycelium
fill ~26~13~28 ~26~13~29 minecraft:dirt 0
fill ~26~16~28 ~28~16~28 minecraft:dirt 0
setblock ~28~10~28 minecraft:mycelium
fill ~28~14~28 ~28~14~65 minecraft:dirt 0
fill ~28~15~28 ~28~15~63 minecraft:dirt 0
fill ~28~19~28 ~29~19~28 minecraft:stone 0
fill ~28~20~28 ~29~20~28 minecraft:mycelium
fill ~29~9~28 ~30~9~28 minecraft:mycelium
fill ~29~15~28 ~31~15~28 minecraft:stone 0
fill ~29~16~28 ~30~16~29 minecraft:stone 0
fill ~30~14~28 ~30~14~69 minecraft:dirt 0
fill ~30~18~28 ~33~18~31 minecraft:dirt 0
fill ~30~19~28 ~31~19~34 minecraft:dirt 0
setblock ~31~8~28 minecraft:mycelium
fill ~31~10~28 ~31~11~35 minecraft:dirt 0
fill ~31~14~28 ~32~14~28 minecraft:stone 0
fill ~31~17~28 ~33~17~31 minecraft:dirt 0
fill ~32~15~28 ~32~15~41 minecraft:dirt 0
fill ~32~19~28 ~33~19~28 minecraft:mycelium
setblock ~33~15~28 minecraft:stone 0
fill ~33~16~28 ~35~16~29 minecraft:dirt 0
fill ~33~22~28 ~33~22~66 minecraft:dirt 0
setblock ~33~23~28 minecraft:mycelium
fill ~34~14~28 ~35~14~43 minecraft:dirt 0
fill ~34~15~28 ~35~15~38 minecraft:dirt 0
fill ~34~23~28 ~34~23~67 minecraft:dirt 0
fill ~34~24~28 ~34~24~29 minecraft:mycelium
fill ~35~20~28 ~35~20~29 minecraft:mycelium
setblock ~35~24~28 minecraft:cobblestone
setblock ~35~27~28 minecraft:stone_stairs 6
setblock ~35~28~28 minecraft:cobblestone
fill ~35~29~28 ~35~34~28 minecraft:log 1
fill ~35~35~28 ~35~36~28 minecraft:wood 1
setblock ~36~13~28 minecraft:mycelium
fill ~36~19~28 ~37~19~28 minecraft:dirt 0
fill ~36~25~28 ~36~31~28 minecraft:stonebrick 0
setblock ~36~32~28 minecraft:stone_brick_stairs 1
setblock ~36~34~28 minecraft:stone_stairs 5
fill ~36~35~28 ~36~35~29 minecraft:cobblestone
setblock ~36~36~28 minecraft:log 1
setblock ~36~37~28 minecraft:wood 1
fill ~37~14~28 ~38~14~28 minecraft:mycelium
fill ~37~18~28 ~38~18~28 minecraft:dirt 0
fill ~37~20~28 ~39~20~29 minecraft:mycelium
setblock ~37~29~28 minecraft:stone_block_slab 7
setblock ~37~35~28 minecraft:stone_stairs 6
fill ~37~36~28 ~37~37~29 minecraft:cobblestone
fill ~38~19~28 ~39~19~28 minecraft:stone 0
setblock ~38~24~28 minecraft:dirt 0
setblock ~38~25~28 minecraft:stonebrick 1
setblock ~38~26~28 minecraft:stonebrick 2
fill ~38~27~28 ~40~27~28 minecraft:stonebrick 0
setblock ~38~29~28 minecraft:double_stone_block_slab 7
setblock ~38~37~28 minecraft:stone_stairs 6
fill ~38~38~28 ~38~39~29 minecraft:cobblestone
fill ~39~8~28 ~41~8~69 minecraft:stone 0
fill ~39~14~28 ~43~14~28 minecraft:dirt 0
fill ~39~15~28 ~39~16~28 minecraft:dirt 0
fill ~39~17~28 ~43~17~28 minecraft:stone 0
fill ~39~18~28 ~42~18~28 minecraft:stone 0
setblock ~39~24~28 minecraft:gravel
fill ~39~25~28 ~39~26~28 minecraft:double_stone_block_slab 5
setblock ~39~28~28 minecraft:stonebrick 0
setblock ~39~29~28 minecraft:stone_block_slab 15
setblock ~39~30~28 minecraft:stone_block_slab 7
fill ~39~39~28 ~40~39~29 minecraft:cobblestone
fill ~39~40~28 ~39~41~29 minecraft:cobblestone
setblock ~39~47~28 minecraft:double_wooden_slab 3
fill ~40~13~28 ~46~13~28 minecraft:dirt 0
fill ~40~16~28 ~41~16~33 minecraft:stone 0
fill ~40~19~28 ~42~19~28 minecraft:mycelium
fill ~40~24~28 ~41~24~28 minecraft:dirt 0
setblock ~40~25~28 minecraft:stonebrick 2
setblock ~40~26~28 minecraft:stonebrick 0
setblock ~40~29~28 minecraft:double_stone_block_slab 7
setblock ~40~37~28 minecraft:stone_stairs 6
fill ~40~38~28 ~40~38~29 minecraft:cobblestone
setblock ~40~40~28 minecraft:log 1
fill ~41~12~28 ~46~12~36 minecraft:dirt 0
setblock ~41~15~28 minecraft:dirt 0
setblock ~41~25~28 minecraft:mossy_cobblestone
setblock ~41~29~28 minecraft:stone_block_slab 7
setblock ~41~35~28 minecraft:stone_stairs 6
fill ~41~36~28 ~41~37~29 minecraft:cobblestone
setblock ~41~40~28 minecraft:wood 1
fill ~42~25~28 ~42~28~31 minecraft:stonebrick 0
fill ~42~29~28 ~42~31~28 minecraft:stonebrick 0
setblock ~42~32~28 minecraft:stone_brick_stairs 0
setblock ~42~34~28 minecraft:stone_stairs 4
fill ~42~35~28 ~42~35~29 minecraft:cobblestone
fill ~42~36~28 ~43~36~28 minecraft:wood 1
setblock ~42~37~28 minecraft:wood 1
fill ~43~15~28 ~44~16~28 minecraft:dirt 0
fill ~43~18~28 ~50~18~28 minecraft:mycelium
setblock ~43~25~28 minecraft:stone_brick_stairs 1
setblock ~43~27~28 minecraft:stone_stairs 6
setblock ~43~28~28 minecraft:cobblestone
fill ~43~29~28 ~43~32~28 minecraft:log 1
fill ~43~33~28 ~43~35~28 minecraft:wood 1
fill ~44~8~28 ~44~8~67 minecraft:stone 0
fill ~44~17~28 ~52~17~28 minecraft:dirt 0
fill ~45~14~28 ~45~14~31 minecraft:dirt 0
setblock ~45~16~28 minecraft:dirt 0
fill ~45~22~28 ~45~23~28 minecraft:dirt 0
fill ~45~24~28 ~49~24~28 minecraft:mycelium
fill ~46~7~28 ~48~7~70 minecraft:stone 0
fill ~46~8~28 ~48~9~29 minecraft:dirt 0
fill ~46~10~28 ~46~10~34 minecraft:dirt 0
fill ~46~15~28 ~46~16~42 minecraft:stone 0
fill ~46~23~28 ~50~23~29 minecraft:dirt 0
fill ~47~12~28 ~47~13~28 minecraft:stone 0
fill ~48~15~28 ~49~15~30 minecraft:stone 0
setblock ~48~28~28 minecraft:stone_block_slab 13
fill ~48~29~28 ~49~29~28 minecraft:stone_block_slab 5
fill ~48~35~28 ~49~35~28 minecraft:stone_block_slab 5
setblock ~50~7~28 minecraft:dirt 0
fill ~50~12~28 ~50~12~32 minecraft:dirt 0
setblock ~50~13~28 minecraft:stone 0
fill ~50~15~28 ~50~16~28 minecraft:dirt 0
fill ~50~24~28 ~50~24~34 minecraft:cobblestone
fill ~50~25~28 ~50~26~29 minecraft:cobblestone
setblock ~50~27~28 minecraft:stone_stairs 0
setblock ~50~28~28 minecraft:nether_brick_stairs 6
fill ~50~29~28 ~54~29~28 minecraft:double_stone_block_slab 0
fill ~50~30~28 ~51~30~28 minecraft:fence 0
fill ~50~31~28 ~51~31~28 minecraft:stone_block_slab 7
fill ~50~34~28 ~51~34~28 minecraft:stone_block_slab 8
fill ~50~35~28 ~54~35~28 minecraft:double_stone_block_slab 0
fill ~50~36~28 ~50~37~28 minecraft:cobblestone
setblock ~50~38~28 minecraft:stone_stairs 0
fill ~50~39~28 ~51~39~28 minecraft:wood 1
setblock ~50~40~28 minecraft:log 1
fill ~51~6~28 ~52~6~70 minecraft:stone 0
fill ~51~7~28 ~52~7~28 minecraft:stone 0
fill ~51~13~28 ~55~13~28 minecraft:dirt 0
fill ~51~18~28 ~51~18~56 minecraft:dirt 0
fill ~51~19~28 ~51~19~29 minecraft:mycelium
setblock ~51~24~28 minecraft:stonebrick 0
setblock ~51~25~28 minecraft:stone_brick_stairs 2
setblock ~51~27~28 minecraft:stone_stairs 5
fill ~51~28~28 ~51~28~29 minecraft:cobblestone
setblock ~51~38~28 minecraft:wood 1
setblock ~51~42~28 minecraft:wooden_slab 2
fill ~52~16~28 ~53~16~32 minecraft:dirt 0
fill ~52~18~28 ~65~18~28 minecraft:mycelium
fill ~52~24~28 ~53~24~28 minecraft:dirt 0
fill ~52~25~28 ~52~28~29 minecraft:log 1
setblock ~52~30~28 minecraft:double_stone_block_slab 0
fill ~52~31~28 ~52~33~28 minecraft:cobblestone
setblock ~52~34~28 minecraft:double_stone_block_slab 0
fill ~52~36~28 ~52~38~28 minecraft:log 1
setblock ~52~42~28 minecraft:wooden_slab 10
fill ~52~44~28 ~52~45~28 minecraft:stone_stairs 6
setblock ~53~25~28 minecraft:stone_brick_stairs 2
setblock ~53~27~28 minecraft:stone_stairs 4
fill ~53~28~28 ~53~28~29 minecraft:cobblestone
fill ~53~30~28 ~54~30~28 minecraft:fence 0
fill ~53~31~28 ~54~31~28 minecraft:stone_block_slab 7
fill ~53~34~28 ~54~34~28 minecraft:stone_block_slab 8
setblock ~53~38~28 minecraft:wood 1
setblock ~53~39~28 minecraft:log 1
setblock ~53~42~28 minecraft:wooden_slab 2
fill ~54~5~28 ~55~5~70 minecraft:stone 0
fill ~54~6~28 ~55~6~28 minecraft:stone 0
fill ~54~14~28 ~54~14~31 minecraft:stone 0
fill ~54~21~28 ~57~21~28 minecraft:dirt 0
fill ~54~23~28 ~54~23~48 minecraft:dirt 0
fill ~54~24~28 ~54~24~33 minecraft:cobblestone
fill ~54~25~28 ~54~26~29 minecraft:cobblestone
setblock ~54~27~28 minecraft:stone_stairs 1
setblock ~54~28~28 minecraft:nether_brick_stairs 6
fill ~54~36~28 ~54~37~28 minecraft:cobblestone
setblock ~54~39~28 minecraft:wood 1
setblock ~54~40~28 minecraft:log 1
setblock ~55~14~28 minecraft:dirt 0
fill ~55~17~28 ~55~17~41 minecraft:dirt 0
fill ~55~22~28 ~56~22~47 minecraft:dirt 0
fill ~55~23~28 ~56~23~28 minecraft:mycelium
fill ~55~29~28 ~56~29~28 minecraft:stone_block_slab 5
fill ~55~35~28 ~56~35~28 minecraft:stone_block_slab 5
fill ~56~5~28 ~56~6~28 minecraft:minecraft:sandstone
fill ~56~7~28 ~56~7~31 minecraft:dirt 0
setblock ~56~28~28 minecraft:stone_block_slab 13
fill ~57~4~28 ~57~4~69 minecraft:stone 0
setblock ~57~5~28 minecraft:stone 0
fill ~57~6~28 ~57~6~29 minecraft:minecraft:sandstone
fill ~57~8~28 ~57~8~35 minecraft:dirt 0
fill ~57~12~28 ~59~12~31 minecraft:dirt 0
setblock ~57~22~28 minecraft:mossy_cobblestone
fill ~58~4~28 ~59~4~28 minecraft:minecraft:sandstone
fill ~58~9~28 ~58~9~45 minecraft:dirt 0
setblock ~58~16~28 minecraft:stone 0
fill ~58~21~28 ~62~21~28 minecraft:mycelium
setblock ~58~22~28 minecraft:stone_stairs 1
fill ~59~3~28 ~59~3~65 minecraft:stone 0
fill ~59~11~28 ~59~11~32 minecraft:dirt 0
fill ~59~15~28 ~59~15~31 minecraft:stone 0
fill ~60~11~28 ~61~11~28 minecraft:minecraft:sandstone
setblock ~60~12~28 minecraft:mycelium
fill ~60~14~28 ~60~14~43 minecraft:stone 0
setblock ~60~22~28 minecraft:leaves 1
