fill ~212~64~0 ~227~65~0 minecraft:concrete 0
fill ~228~65~0 ~228~65~27 minecraft:concrete 0
fill ~207~64~1 ~212~65~1 minecraft:concrete 0
fill ~213~63~1 ~219~63~2 minecraft:concrete 0
fill ~213~65~1 ~227~65~26 minecraft:concrete 0
setblock ~219~64~1 minecraft:sea_lantern
setblock ~220~61~1 minecraft:iron_trapdoor 3
setblock ~220~64~1 minecraft:stone_button 2
fill ~221~63~1 ~227~63~2 minecraft:concrete 0
setblock ~221~64~1 minecraft:sea_lantern
fill ~228~64~1 ~233~64~1 minecraft:concrete 0
fill ~229~65~1 ~233~65~27 minecraft:concrete 0
fill ~203~64~2 ~206~65~2 minecraft:concrete 0
fill ~207~63~2 ~212~63~3 minecraft:concrete 0
fill ~207~65~2 ~212~65~27 minecraft:concrete 0
fill ~213~61~2 ~227~61~2 minecraft:concrete 0
fill ~213~62~2 ~219~62~2 minecraft:concrete 0
fill ~213~64~2 ~227~64~2 minecraft:concrete 0
setblock ~220~62~2 minecraft:iron_door 3
fill ~221~62~2 ~227~62~2 minecraft:concrete 0
fill ~228~63~2 ~233~63~3 minecraft:concrete 0
fill ~234~64~2 ~237~65~2 minecraft:concrete 0
fill ~199~64~3 ~202~65~3 minecraft:concrete 0
fill ~203~63~3 ~206~63~4 minecraft:concrete 0
fill ~203~65~3 ~206~65~29 minecraft:concrete 0
fill ~207~61~3 ~212~62~3 minecraft:concrete 0
fill ~207~64~3 ~212~64~3 minecraft:concrete 0
fill ~213~60~3 ~227~60~37 minecraft:concrete 0
fill ~218~61~3 ~218~61~5 minecraft:concrete 8
fill ~218~62~3 ~218~62~5 minecraft:concrete 14
fill ~218~63~3 ~218~63~5 minecraft:concrete 8
fill ~218~64~3 ~218~64~5 minecraft:stone_block_slab 0
fill ~219~61~3 ~221~61~3 minecraft:stone_block_slab 6
fill ~219~64~3 ~219~64~5 minecraft:stone_block_slab 8
setblock ~220~64~3 minecraft:stone_block_slab 0
setblock ~221~63~3 minecraft:stone_button 3
fill ~221~64~3 ~221~64~5 minecraft:stone_block_slab 8
fill ~222~61~3 ~222~61~5 minecraft:concrete 8
fill ~222~62~3 ~222~62~5 minecraft:concrete 14
fill ~222~63~3 ~222~63~5 minecraft:concrete 8
fill ~222~64~3 ~222~64~5 minecraft:stone_block_slab 0
fill ~228~61~3 ~233~62~3 minecraft:concrete 0
fill ~228~64~3 ~233~64~3 minecraft:concrete 0
fill ~234~63~3 ~237~63~4 minecraft:concrete 0
fill ~234~65~3 ~241~65~28 minecraft:concrete 0
fill ~237~64~3 ~241~64~3 minecraft:concrete 0
fill ~197~64~4 ~199~65~4 minecraft:concrete 0
fill ~200~63~4 ~202~63~5 minecraft:concrete 0
fill ~200~65~4 ~202~65~31 minecraft:concrete 0
fill ~203~61~4 ~206~62~4 minecraft:concrete 0
fill ~203~64~4 ~206~64~4 minecraft:concrete 0
fill ~207~60~4 ~212~60~38 minecraft:concrete 0
setblock ~220~64~4 minecraft:sea_lantern
fill ~228~60~4 ~233~60~38 minecraft:concrete 0
fill ~234~61~4 ~237~62~4 minecraft:concrete 0
fill ~234~64~4 ~237~64~4 minecraft:concrete 0
fill ~238~63~4 ~240~63~5 minecraft:concrete 0
fill ~241~64~4 ~243~64~4 minecraft:concrete 0
fill ~242~65~4 ~243~65~32 minecraft:concrete 0
fill ~194~64~5 ~196~65~5 minecraft:concrete 0
fill ~197~63~5 ~199~63~6 minecraft:concrete 0
fill ~197~65~5 ~199~65~33 minecraft:concrete 0
fill ~200~61~5 ~202~62~5 minecraft:concrete 0
fill ~200~64~5 ~202~64~5 minecraft:concrete 0
fill ~203~60~5 ~206~60~41 minecraft:concrete 0
setblock ~220~63~5 minecraft:stone_button 2
setblock ~220~64~5 minecraft:stone_block_slab 0
fill ~234~60~5 ~237~60~40 minecraft:concrete 0
fill ~238~61~5 ~240~62~5 minecraft:concrete 0
fill ~238~64~5 ~240~64~5 minecraft:concrete 0
fill ~241~63~5 ~243~63~6 minecraft:concrete 0
fill ~244~64~5 ~246~65~5 minecraft:concrete 0
fill ~192~64~6 ~194~65~6 minecraft:concrete 0
fill ~195~63~6 ~196~63~7 minecraft:concrete 0
fill ~195~65~6 ~196~65~35 minecraft:concrete 0
fill ~196~64~6 ~199~64~6 minecraft:concrete 0
fill ~197~61~6 ~199~62~6 minecraft:concrete 0
fill ~200~60~6 ~202~60~44 minecraft:concrete 0
fill ~201~61~6 ~201~61~13 minecraft:concrete 0
setblock ~209~61~6 minecraft:torch 5
fill ~219~61~6 ~219~63~6 minecraft:stained_hardened_clay 14
setblock ~219~64~6 minecraft:stone_block_slab 0
setblock ~220~61~6 minecraft:iron_door 3
fill ~220~63~6 ~221~63~6 minecraft:stained_hardened_clay 14
fill ~221~61~6 ~221~62~6 minecraft:stained_hardened_clay 14
setblock ~221~64~6 minecraft:stone_block_slab 0
setblock ~229~61~6 minecraft:torch 5
fill ~238~60~6 ~240~60~43 minecraft:concrete 0
fill ~239~61~6 ~239~61~14 minecraft:concrete 8
fill ~241~61~6 ~243~62~6 minecraft:concrete 0
fill ~241~64~6 ~243~64~6 minecraft:concrete 0
fill ~244~63~6 ~245~63~7 minecraft:concrete 0
fill ~244~65~6 ~248~65~34 minecraft:concrete 0
fill ~246~64~6 ~248~64~6 minecraft:concrete 0
fill ~190~64~7 ~191~65~7 minecraft:concrete 0
fill ~192~63~7 ~194~63~8 minecraft:concrete 0
fill ~192~65~7 ~194~65~37 minecraft:concrete 0
fill ~195~61~7 ~196~62~7 minecraft:concrete 0
fill ~195~64~7 ~196~64~7 minecraft:concrete 0
fill ~197~60~7 ~199~60~48 minecraft:concrete 0
fill ~218~61~7 ~218~63~9 minecraft:concrete 8
fill ~218~64~7 ~218~64~9 minecraft:stone_block_slab 0
setblock ~219~61~7 minecraft:red_sandstone_stairs 3
fill ~219~64~7 ~219~64~9 minecraft:stone_block_slab 8
setblock ~220~63~7 minecraft:stone_button 3
setblock ~220~64~7 minecraft:stone_block_slab 0
setblock ~221~61~7 minecraft:red_sandstone_stairs 3
setblock ~221~62~7 minecraft:wall_sign 3
fill ~221~64~7 ~221~64~9 minecraft:stone_block_slab 8
fill ~222~61~7 ~222~63~9 minecraft:concrete 8
fill ~222~64~7 ~222~64~9 minecraft:stone_block_slab 0
setblock ~236~61~7 minecraft:torch 5
fill ~241~60~7 ~243~60~45 minecraft:concrete 0
fill ~244~61~7 ~245~62~7 minecraft:concrete 0
fill ~244~64~7 ~245~64~7 minecraft:concrete 0
fill ~246~63~7 ~248~63~8 minecraft:concrete 0
fill ~249~64~7 ~250~65~7 minecraft:concrete 0
fill ~188~64~8 ~189~65~9 minecraft:concrete 0
fill ~190~63~8 ~191~63~9 minecraft:concrete 0
fill ~190~65~8 ~191~65~40 minecraft:concrete 0
fill ~193~61~8 ~194~62~8 minecraft:concrete 0
fill ~193~64~8 ~194~64~8 minecraft:concrete 0
fill ~195~60~8 ~196~60~53 minecraft:concrete 0
setblock ~215~61~8 minecraft:torch 5
setblock ~220~64~8 minecraft:sea_lantern
setblock ~226~61~8 minecraft:torch 5
fill ~244~60~8 ~245~60~49 minecraft:concrete 0
fill ~246~61~8 ~247~62~8 minecraft:concrete 0
fill ~246~64~8 ~247~64~8 minecraft:concrete 0
fill ~249~63~8 ~250~63~9 minecraft:concrete 0
fill ~249~65~8 ~252~65~38 minecraft:concrete 0
fill ~251~64~8 ~252~64~8 minecraft:concrete 0
fill ~187~64~9 ~187~65~9 minecraft:concrete 0
fill ~189~63~9 ~189~63~10 minecraft:concrete 0
fill ~191~61~9 ~192~62~9 minecraft:concrete 0
fill ~191~64~9 ~192~64~9 minecraft:concrete 0
setblock ~192~63~9 minecraft:concrete 0
fill ~193~60~9 ~194~60~59 minecraft:concrete 0
setblock ~200~61~9 minecraft:torch 5
setblock ~220~63~9 minecraft:stone_button 2
fill ~220~64~9 ~220~64~10 minecraft:stone_block_slab 0
setblock ~232~61~9 minecraft:torch 5
fill ~246~60~9 ~247~60~53 minecraft:concrete 0
fill ~248~61~9 ~249~62~9 minecraft:concrete 0
fill ~248~63~9 ~248~64~9 minecraft:concrete 0
setblock ~249~64~9 minecraft:concrete 0
fill ~251~63~9 ~251~63~10 minecraft:concrete 0
fill ~252~64~9 ~253~64~9 minecraft:concrete 0
fill ~253~65~9 ~253~65~43 minecraft:concrete 0
fill ~185~64~10 ~186~65~10 minecraft:concrete 0
fill ~187~63~10 ~188~63~10 minecraft:concrete 0
fill ~187~65~10 ~189~65~43 minecraft:concrete 0
fill ~189~61~10 ~190~62~10 minecraft:concrete 0
fill ~189~64~10 ~190~64~10 minecraft:concrete 0
setblock ~190~63~10 minecraft:concrete 0
fill ~191~60~10 ~192~60~120 minecraft:concrete 0
setblock ~206~61~10 minecraft:torch 5
fill ~219~61~10 ~219~63~10 minecraft:stained_hardened_clay 14
setblock ~219~64~10 minecraft:stone_block_slab 0
setblock ~220~61~10 minecraft:iron_door 3
fill ~220~63~10 ~221~63~10 minecraft:stained_hardened_clay 14
fill ~221~61~10 ~221~62~10 minecraft:stained_hardened_clay 14
setblock ~221~64~10 minecraft:stone_block_slab 0
fill ~248~60~10 ~249~60~59 minecraft:concrete 0
fill ~250~61~10 ~251~62~10 minecraft:concrete 0
fill ~250~63~10 ~250~64~10 minecraft:concrete 0
setblock ~251~64~10 minecraft:concrete 0
fill ~252~63~10 ~253~63~10 minecraft:concrete 0
fill ~254~64~10 ~255~65~10 minecraft:concrete 0
fill ~184~64~11 ~184~65~11 minecraft:concrete 0
fill ~185~63~11 ~186~63~12 minecraft:concrete 0
fill ~185~65~11 ~186~65~48 minecraft:concrete 0
fill ~187~61~11 ~188~62~11 minecraft:concrete 0
fill ~188~63~11 ~188~64~11 minecraft:concrete 0
fill ~189~60~11 ~190~60~119 minecraft:concrete 0
fill ~213~61~11 ~217~63~11 minecraft:concrete 8
fill ~213~64~11 ~217~64~11 minecraft:concrete 11
setblock ~218~61~11 minecraft:double_stone_block_slab 0
fill ~218~62~11 ~218~63~11 minecraft:sea_lantern
setblock ~218~64~11 minecraft:double_stone_block_slab 0
fill ~219~61~11 ~219~61~12 minecraft:carpet 8
fill ~219~64~11 ~221~64~11 minecraft:stone_block_slab 8
setblock ~220~61~11 minecraft:stone_pressure_plate 0
setblock ~220~63~11 minecraft:wall_sign 3
fill ~221~61~11 ~221~61~12 minecraft:carpet 8
setblock ~222~61~11 minecraft:double_stone_block_slab 0
fill ~222~62~11 ~222~63~11 minecraft:sea_lantern
setblock ~222~64~11 minecraft:double_stone_block_slab 0
fill ~223~61~11 ~227~63~11 minecraft:concrete 8
fill ~223~64~11 ~227~64~11 minecraft:concrete 11
setblock ~244~61~11 minecraft:torch 5
fill ~250~60~11 ~251~60~119 minecraft:concrete 0
fill ~252~61~11 ~253~62~11 minecraft:concrete 0
fill ~252~63~11 ~252~64~11 minecraft:concrete 0
fill ~254~63~11 ~255~63~12 minecraft:concrete 0
fill ~254~65~11 ~256~65~45 minecraft:concrete 0
setblock ~256~64~11 minecraft:concrete 0
fill ~182~64~12 ~183~65~12 minecraft:concrete 0
setblock ~184~63~12 minecraft:concrete 0
fill ~184~65~12 ~184~65~54 minecraft:concrete 0
fill ~186~61~12 ~186~62~12 minecraft:concrete 0
fill ~186~64~12 ~187~64~12 minecraft:concrete 0
setblock ~187~61~12 minecraft:sea_lantern
fill ~187~62~12 ~187~63~12 minecraft:concrete 0
fill ~188~60~12 ~188~60~118 minecraft:concrete 0
fill ~208~61~12 ~209~63~12 minecraft:concrete 8
fill ~208~64~12 ~211~64~12 minecraft:concrete 11
setblock ~210~61~12 minecraft:birch_door 3
fill ~210~63~12 ~211~63~12 minecraft:concrete 8
fill ~211~61~12 ~211~62~12 minecraft:concrete 8
setblock ~212~61~12 minecraft:sea_lantern
fill ~212~62~12 ~212~63~12 minecraft:double_stone_block_slab 0
setblock ~212~64~12 minecraft:sea_lantern
fill ~213~61~12 ~218~61~12 minecraft:carpet 8
fill ~213~64~12 ~218~64~12 minecraft:stone_block_slab 8
fill ~219~64~12 ~221~64~12 minecraft:stone_block_slab 14
setblock ~220~61~12 minecraft:carpet 8
fill ~222~61~12 ~227~61~12 minecraft:carpet 8
fill ~222~64~12 ~227~64~12 minecraft:stone_block_slab 8
setblock ~228~61~12 minecraft:sea_lantern
fill ~228~62~12 ~228~63~12 minecraft:double_stone_block_slab 0
setblock ~228~64~12 minecraft:sea_lantern
fill ~229~61~12 ~229~63~12 minecraft:concrete 8
fill ~229~64~12 ~232~64~12 minecraft:concrete 11
setblock ~230~61~12 minecraft:birch_door 3
fill ~230~63~12 ~232~63~12 minecraft:concrete 8
fill ~231~61~12 ~232~62~12 minecraft:concrete 8
fill ~252~60~12 ~252~60~118 minecraft:concrete 0
setblock ~253~61~12 minecraft:sea_lantern
fill ~253~62~12 ~254~62~12 minecraft:concrete 0
fill ~253~63~12 ~253~64~12 minecraft:concrete 0
setblock ~254~61~12 minecraft:concrete 0
setblock ~254~64~12 minecraft:concrete 0
setblock ~256~63~12 minecraft:concrete 0
fill ~257~64~12 ~258~65~12 minecraft:concrete 0
fill ~181~64~13 ~182~65~13 minecraft:concrete 0
fill ~183~63~13 ~183~63~14 minecraft:concrete 0
fill ~183~65~13 ~183~65~58 minecraft:concrete 0
fill ~184~61~13 ~185~62~13 minecraft:concrete 0
fill ~185~63~13 ~185~64~13 minecraft:concrete 0
fill ~186~60~13 ~187~60~117 minecraft:concrete 0
setblock ~196~61~13 minecraft:torch 5
fill ~204~61~13 ~205~63~13 minecraft:concrete 8
fill ~204~64~13 ~205~64~13 minecraft:concrete 11
setblock ~206~61~13 minecraft:sea_lantern
fill ~206~62~13 ~206~63~13 minecraft:double_stone_block_slab 0
setblock ~206~64~13 minecraft:sea_lantern
fill ~207~61~13 ~207~63~13 minecraft:concrete 8
setblock ~207~64~13 minecraft:concrete 11
fill ~208~61~13 ~209~61~13 minecraft:carpet 8
fill ~208~64~13 ~213~64~13 minecraft:stone_block_slab 8
fill ~210~61~13 ~210~61~15 minecraft:carpet 11
fill ~211~61~13 ~213~61~13 minecraft:carpet 8
fill ~214~61~13 ~217~61~14 minecraft:carpet 11
fill ~214~64~13 ~217~64~14 minecraft:stone_block_slab 14
fill ~218~61~13 ~218~61~15 minecraft:carpet 8
fill ~218~64~13 ~218~64~15 minecraft:stone_block_slab 8
fill ~219~61~13 ~221~61~14 minecraft:carpet 11
fill ~219~64~13 ~219~64~15 minecraft:stone_block_slab 14
fill ~220~64~13 ~220~64~14 minecraft:stone_block_slab2 0
fill ~221~64~13 ~221~64~15 minecraft:stone_block_slab 14
fill ~222~61~13 ~222~61~15 minecraft:carpet 8
fill ~222~64~13 ~222~64~15 minecraft:stone_block_slab 8
fill ~223~61~13 ~226~61~14 minecraft:carpet 11
fill ~223~64~13 ~226~64~14 minecraft:stone_block_slab 14
fill ~227~61~13 ~229~61~13 minecraft:carpet 8
fill ~227~64~13 ~232~64~13 minecraft:stone_block_slab 8
fill ~230~61~13 ~230~61~15 minecraft:carpet 11
fill ~231~61~13 ~232~61~13 minecraft:carpet 8
fill ~233~61~13 ~233~63~13 minecraft:concrete 8
setblock ~233~64~13 minecraft:concrete 11
setblock ~234~61~13 minecraft:sea_lantern
fill ~234~62~13 ~234~63~13 minecraft:double_stone_block_slab 0
setblock ~234~64~13 minecraft:sea_lantern
fill ~235~61~13 ~236~63~13 minecraft:concrete 8
fill ~235~64~13 ~236~64~13 minecraft:concrete 11
fill ~253~60~13 ~254~60~117 minecraft:concrete 0
fill ~255~61~13 ~256~62~13 minecraft:concrete 0
fill ~255~63~13 ~255~64~13 minecraft:concrete 0
fill ~257~63~13 ~257~63~14 minecraft:concrete 0
fill ~257~65~13 ~259~65~51 minecraft:concrete 0
fill ~258~64~13 ~259~64~13 minecraft:concrete 0
fill ~180~64~14 ~180~65~14 minecraft:concrete 0
fill ~181~63~14 ~182~63~15 minecraft:concrete 0
fill ~181~65~14 ~182~65~117 minecraft:concrete 0
fill ~183~61~14 ~183~62~14 minecraft:concrete 0
fill ~183~64~14 ~184~64~14 minecraft:concrete 0
setblock ~184~61~14 minecraft:sea_lantern
fill ~184~62~14 ~184~63~14 minecraft:concrete 0
fill ~185~60~14 ~185~60~116 minecraft:concrete 0
fill ~201~61~14 ~203~63~14 minecraft:concrete 8
fill ~201~64~14 ~203~64~14 minecraft:concrete 11
fill ~204~61~14 ~208~61~14 minecraft:carpet 8
fill ~204~64~14 ~208~64~14 minecraft:stone_block_slab 8
fill ~209~61~14 ~209~61~15 minecraft:carpet 11
fill ~209~64~14 ~213~64~14 minecraft:stone_block_slab 14
fill ~211~61~14 ~213~61~14 minecraft:carpet 11
fill ~227~61~14 ~229~61~14 minecraft:carpet 11
fill ~227~64~14 ~231~64~14 minecraft:stone_block_slab 14
fill ~231~61~14 ~231~61~15 minecraft:carpet 11
fill ~232~61~14 ~236~61~14 minecraft:carpet 8
fill ~232~64~14 ~236~64~14 minecraft:stone_block_slab 8
fill ~237~61~14 ~238~63~14 minecraft:concrete 8
fill ~237~64~14 ~239~64~14 minecraft:concrete 11
fill ~239~62~14 ~239~63~14 minecraft:concrete 8
setblock ~246~61~14 minecraft:torch 5
setblock ~250~61~14 minecraft:torch 5
fill ~255~60~14 ~255~60~116 minecraft:concrete 0
setblock ~256~61~14 minecraft:sea_lantern
fill ~256~62~14 ~257~62~14 minecraft:concrete 0
fill ~256~63~14 ~256~64~14 minecraft:concrete 0
setblock ~257~61~14 minecraft:concrete 0
setblock ~257~64~14 minecraft:concrete 0
fill ~258~63~14 ~259~63~15 minecraft:concrete 0
fill ~260~64~14 ~260~65~15 minecraft:concrete 0
fill ~104~72~15 ~142~72~15 minecraft:concrete 0
fill ~104~73~15 ~112~75~15 minecraft:stained_hardened_clay 14
fill ~104~76~15 ~142~76~15 minecraft:concrete 0
fill ~113~73~15 ~114~73~15 minecraft:concrete 0
fill ~113~74~15 ~113~75~15 minecraft:stained_hardened_clay 14
fill ~114~74~15 ~115~74~15 minecraft:concrete 0
setblock ~114~75~15 minecraft:stained_hardened_clay 14
fill ~115~73~15 ~120~73~15 minecraft:stained_hardened_clay 14
fill ~115~75~15 ~116~75~15 minecraft:concrete 0
fill ~116~74~15 ~121~74~15 minecraft:stained_hardened_clay 14
fill ~117~75~15 ~122~75~15 minecraft:stained_hardened_clay 14
fill ~121~73~15 ~142~73~15 minecraft:concrete 0
fill ~122~74~15 ~142~74~15 minecraft:concrete 0
fill ~123~75~15 ~142~75~15 minecraft:concrete 0
fill ~143~72~15 ~145~76~15 minecraft:red_nether_brick
fill ~146~72~15 ~149~76~15 minecraft:concrete 0
fill ~178~64~15 ~179~65~15 minecraft:concrete 0
setblock ~180~63~15 minecraft:concrete 0
fill ~180~65~15 ~180~65~116 minecraft:concrete 0
fill ~182~61~15 ~182~62~15 minecraft:concrete 0
setblock ~182~64~15 minecraft:concrete 0
fill ~183~60~15 ~184~60~115 minecraft:concrete 0
setblock ~184~61~15 minecraft:concrete 0
fill ~199~61~15 ~199~63~15 minecraft:concrete 8
setblock ~199~64~15 minecraft:concrete 11
setblock ~200~61~15 minecraft:sea_lantern
fill ~200~62~15 ~200~63~15 minecraft:double_stone_block_slab 0
setblock ~200~64~15 minecraft:sea_lantern
fill ~201~61~15 ~204~61~15 minecraft:carpet 8
fill ~201~64~15 ~204~64~15 minecraft:stone_block_slab 8
fill ~205~61~15 ~208~61~15 minecraft:carpet 11
fill ~211~61~15 ~212~61~15 minecraft:carpet 11
fill ~213~61~15 ~217~61~15 minecraft:carpet 8
fill ~213~64~15 ~217~64~15 minecraft:stone_block_slab 8
fill ~219~61~15 ~221~61~15 minecraft:carpet 8
setblock ~220~64~15 minecraft:stone_block_slab 14
fill ~223~61~15 ~227~61~15 minecraft:carpet 8
fill ~223~64~15 ~227~64~15 minecraft:stone_block_slab 8
fill ~228~61~15 ~229~61~15 minecraft:carpet 11
fill ~228~64~15 ~235~64~15 minecraft:stone_block_slab 14
fill ~232~61~15 ~235~61~15 minecraft:carpet 11
fill ~236~61~15 ~239~61~15 minecraft:carpet 8
fill ~236~64~15 ~239~64~15 minecraft:stone_block_slab 8
setblock ~240~61~15 minecraft:sea_lantern
fill ~240~62~15 ~240~63~15 minecraft:double_stone_block_slab 0
setblock ~240~64~15 minecraft:sea_lantern
fill ~241~61~15 ~241~63~15 minecraft:concrete 8
setblock ~241~64~15 minecraft:concrete 11
fill ~256~60~15 ~257~60~115 minecraft:concrete 0
setblock ~256~61~15 minecraft:concrete 8
fill ~258~61~15 ~258~62~15 minecraft:concrete 0
setblock ~258~64~15 minecraft:concrete 0
setblock ~260~63~15 minecraft:concrete 0
fill ~261~64~15 ~262~65~15 minecraft:concrete 0
fill ~58~72~16 ~61~72~16 minecraft:concrete 0
fill ~58~73~16 ~60~73~16 minecraft:concrete 0
fill ~58~74~16 ~59~74~16 minecraft:stained_hardened_clay 15
fill ~58~75~16 ~60~76~16 minecraft:concrete 0
fill ~60~74~16 ~63~74~16 minecraft:concrete 0
setblock ~61~73~16 minecraft:stained_hardened_clay 15
setblock ~61~75~16 minecraft:stained_hardened_clay 15
setblock ~61~76~16 minecraft:concrete 0
fill ~62~72~16 ~63~72~16 minecraft:stained_hardened_clay 15
fill ~62~73~16 ~63~73~16 minecraft:concrete 0
fill ~62~75~16 ~63~75~16 minecraft:concrete 0
fill ~62~76~16 ~63~76~16 minecraft:stained_hardened_clay 15
fill ~64~72~16 ~66~72~16 minecraft:concrete 0
fill ~64~73~16 ~64~75~16 minecraft:stained_hardened_clay 15
fill ~64~76~16 ~66~76~16 minecraft:concrete 0
fill ~65~73~16 ~65~75~16 minecraft:concrete 0
setblock ~66~73~16 minecraft:stained_hardened_clay 15
fill ~66~74~16 ~68~74~16 minecraft:concrete 0
setblock ~66~75~16 minecraft:stained_hardened_clay 15
fill ~67~72~16 ~68~72~16 minecraft:stained_hardened_clay 15
fill ~67~73~16 ~68~73~16 minecraft:concrete 0
fill ~67~75~16 ~68~75~16 minecraft:concrete 0
fill ~67~76~16 ~68~76~16 minecraft:stained_hardened_clay 15
fill ~69~72~16 ~70~72~16 minecraft:concrete 0
fill ~69~73~16 ~69~75~16 minecraft:stained_hardened_clay 15
fill ~69~76~16 ~70~76~16 minecraft:concrete 0
fill ~70~73~16 ~70~75~16 minecraft:concrete 0
fill ~71~72~16 ~71~76~16 minecraft:stained_hardened_clay 15
fill ~72~72~16 ~74~72~16 minecraft:concrete 0
setblock ~72~73~16 minecraft:stained_hardened_clay 15
fill ~72~74~16 ~72~76~16 minecraft:concrete 0
fill ~73~73~16 ~74~73~16 minecraft:concrete 0
setblock ~73~74~16 minecraft:stained_hardened_clay 15
fill ~73~75~16 ~73~76~16 minecraft:concrete 0
setblock ~74~74~16 minecraft:concrete 0
fill ~74~75~16 ~75~75~16 minecraft:stained_hardened_clay 15
setblock ~74~76~16 minecraft:concrete 0
fill ~75~72~16 ~75~74~16 minecraft:stained_hardened_clay 15
setblock ~75~76~16 minecraft:stained_hardened_clay 15
fill ~76~72~16 ~103~72~16 minecraft:concrete 0
fill ~76~73~16 ~76~76~16 minecraft:concrete 0
fill ~77~73~16 ~103~75~16 minecraft:stained_hardened_clay 14
fill ~77~76~16 ~103~76~16 minecraft:concrete 0
fill ~104~70~16 ~142~71~16 minecraft:concrete 0
fill ~104~72~16 ~142~72~16 minecraft:carpet 0
fill ~104~77~16 ~142~78~16 minecraft:concrete 0
fill ~143~70~16 ~145~71~16 minecraft:red_nether_brick
fill ~143~77~16 ~145~78~16 minecraft:red_nether_brick
fill ~146~70~16 ~149~71~16 minecraft:concrete 0
fill ~146~77~16 ~149~78~16 minecraft:concrete 0
fill ~150~72~16 ~150~76~16 minecraft:concrete 0
fill ~151~72~16 ~152~76~16 minecraft:stained_glass 14
fill ~177~64~16 ~178~65~16 minecraft:concrete 0
fill ~179~63~16 ~179~63~17 minecraft:concrete 0
fill ~179~65~16 ~179~65~115 minecraft:concrete 0
fill ~180~61~16 ~181~62~16 minecraft:concrete 0
fill ~181~63~16 ~181~64~16 minecraft:concrete 0
fill ~182~60~16 ~182~60~114 minecraft:concrete 0
setblock ~185~61~16 minecraft:concrete 0
setblock ~197~61~16 minecraft:birch_door 3
fill ~197~63~16 ~198~63~16 minecraft:concrete 8
fill ~197~64~16 ~198~64~16 minecraft:concrete 11
fill ~198~61~16 ~198~62~16 minecraft:concrete 8
fill ~199~61~16 ~201~61~16 minecraft:carpet 8
fill ~199~64~16 ~201~64~16 minecraft:stone_block_slab 8
fill ~202~61~16 ~206~61~16 minecraft:carpet 11
fill ~202~64~16 ~206~64~16 minecraft:stone_block_slab 14
fill ~207~61~16 ~213~61~16 minecraft:carpet 8
fill ~207~64~16 ~213~64~16 minecraft:stone_block_slab 8
fill ~214~61~16 ~217~63~16 minecraft:concrete 8
fill ~214~64~16 ~217~64~16 minecraft:concrete 11
setblock ~218~61~16 minecraft:double_stone_block_slab 0
fill ~218~62~16 ~218~63~16 minecraft:sea_lantern
setblock ~218~64~16 minecraft:double_stone_block_slab 0
fill ~219~61~16 ~219~61~20 minecraft:carpet 8
fill ~219~64~16 ~221~64~16 minecraft:stone_block_slab 8
fill ~220~61~16 ~220~61~26 minecraft:carpet 0
fill ~221~61~16 ~221~61~27 minecraft:carpet 8
setblock ~222~61~16 minecraft:double_stone_block_slab 0
fill ~222~62~16 ~222~63~16 minecraft:sea_lantern
setblock ~222~64~16 minecraft:double_stone_block_slab 0
fill ~223~61~16 ~226~63~16 minecraft:concrete 8
fill ~223~64~16 ~226~64~16 minecraft:concrete 11
fill ~227~61~16 ~233~61~16 minecraft:carpet 8
fill ~227~64~16 ~233~64~16 minecraft:stone_block_slab 8
fill ~234~61~16 ~238~61~16 minecraft:carpet 11
fill ~234~64~16 ~238~64~16 minecraft:stone_block_slab 14
fill ~239~61~16 ~241~61~16 minecraft:carpet 8
fill ~239~64~16 ~241~64~16 minecraft:stone_block_slab 8
fill ~242~61~16 ~242~63~16 minecraft:concrete 8
fill ~242~64~16 ~243~64~16 minecraft:concrete 11
setblock ~243~61~16 minecraft:birch_door 3
setblock ~243~63~16 minecraft:concrete 8
setblock ~255~61~16 minecraft:concrete 8
fill ~258~60~16 ~258~60~114 minecraft:concrete 0
fill ~259~61~16 ~260~62~16 minecraft:concrete 0
fill ~259~63~16 ~259~64~16 minecraft:concrete 0
setblock ~260~63~16 minecraft:carpet 0
fill ~260~65~16 ~263~65~114 minecraft:concrete 0
fill ~261~63~16 ~261~63~17 minecraft:concrete 0
fill ~262~64~16 ~263~64~17 minecraft:concrete 0
fill ~3~76~17 ~11~76~17 minecraft:concrete 8
fill ~4~75~17 ~11~75~17 minecraft:concrete 8
fill ~5~74~17 ~11~74~17 minecraft:concrete 8
fill ~6~73~17 ~11~73~17 minecraft:concrete 8
fill ~7~72~17 ~11~72~17 minecraft:concrete 8
fill ~12~72~17 ~45~73~17 minecraft:concrete 0
fill ~12~74~17 ~23~76~17 minecraft:concrete 0
fill ~24~74~17 ~44~74~17 minecraft:stained_hardened_clay 14
fill ~24~75~17 ~45~76~17 minecraft:concrete 0
setblock ~45~74~17 minecraft:concrete 0
fill ~46~72~17 ~46~76~17 minecraft:stained_hardened_clay 15
fill ~47~72~17 ~48~72~17 minecraft:concrete 0
fill ~47~73~17 ~47~76~17 minecraft:concrete 0
fill ~48~73~17 ~48~75~17 minecraft:stained_hardened_clay 15
setblock ~48~76~17 minecraft:concrete 0
setblock ~49~72~17 minecraft:stained_hardened_clay 15
fill ~49~73~17 ~49~75~17 minecraft:concrete 0
setblock ~49~76~17 minecraft:stained_hardened_clay 15
fill ~50~72~17 ~52~72~17 minecraft:concrete 0
fill ~50~73~17 ~50~75~17 minecraft:stained_hardened_clay 15
fill ~50~76~17 ~51~76~17 minecraft:concrete 0
fill ~51~73~17 ~52~73~17 minecraft:concrete 0
fill ~51~74~17 ~51~75~17 minecraft:concrete 0
fill ~52~74~17 ~53~74~17 minecraft:stained_hardened_clay 15
fill ~52~75~17 ~52~76~17 minecraft:stained_hardened_clay 15
fill ~53~72~17 ~53~73~17 minecraft:stained_hardened_clay 15
fill ~53~75~17 ~55~75~17 minecraft:concrete 0
fill ~53~76~17 ~54~76~17 minecraft:stained_hardened_clay 15
fill ~54~72~17 ~55~74~17 minecraft:concrete 0
setblock ~55~76~17 minecraft:concrete 0
fill ~56~72~17 ~56~76~17 minecraft:stained_hardened_clay 15
fill ~57~72~17 ~57~76~17 minecraft:concrete 0
fill ~58~70~17 ~103~71~17 minecraft:concrete 0
fill ~58~72~17 ~103~72~17 minecraft:carpet 0
fill ~58~77~17 ~103~78~17 minecraft:concrete 0
fill ~104~69~17 ~142~69~17 minecraft:concrete 0
fill ~104~70~17 ~142~70~17 minecraft:carpet 0
fill ~104~79~17 ~142~79~17 minecraft:concrete 0
fill ~143~69~17 ~145~69~17 minecraft:red_nether_brick
fill ~143~79~17 ~145~79~17 minecraft:red_nether_brick
setblock ~144~70~17 minecraft:torch 5
fill ~146~69~17 ~149~69~17 minecraft:concrete 0
fill ~146~79~17 ~149~79~17 minecraft:concrete 0
fill ~150~70~17 ~150~71~17 minecraft:concrete 0
fill ~150~72~17 ~150~76~29 minecraft:stained_glass 14
fill ~150~77~17 ~150~78~17 minecraft:concrete 0
fill ~151~70~17 ~152~71~17 minecraft:stained_glass 14
fill ~151~72~17 ~152~75~22 minecraft:lava 8
fill ~151~76~17 ~152~76~17 minecraft:lava 0
fill ~151~77~17 ~152~78~17 minecraft:stained_glass 14
fill ~153~72~17 ~154~76~17 minecraft:stained_glass 14
fill ~176~64~17 ~177~65~17 minecraft:concrete 0
fill ~178~63~17 ~178~63~18 minecraft:concrete 0
fill ~178~65~17 ~178~65~115 minecraft:concrete 0
fill ~179~61~17 ~179~62~17 minecraft:concrete 0
fill ~179~64~17 ~180~64~17 minecraft:concrete 0
setblock ~180~61~17 minecraft:sea_lantern
fill ~180~62~17 ~180~63~17 minecraft:concrete 0
fill ~181~60~17 ~181~60~113 minecraft:concrete 0
setblock ~186~61~17 minecraft:concrete 0
fill ~195~61~17 ~196~63~17 minecraft:concrete 8
fill ~195~64~17 ~196~64~17 minecraft:concrete 11
fill ~197~61~17 ~197~61~19 minecraft:carpet 11
fill ~197~64~17 ~199~64~17 minecraft:stone_block_slab 8
fill ~198~61~17 ~199~61~17 minecraft:carpet 8
fill ~200~61~17 ~203~61~17 minecraft:carpet 11
fill ~200~64~17 ~203~64~17 minecraft:stone_block_slab 14
fill ~204~61~17 ~207~61~17 minecraft:carpet 8
fill ~204~64~17 ~207~64~17 minecraft:stone_block_slab 8
setblock ~208~61~17 minecraft:sea_lantern
fill ~208~62~17 ~208~63~17 minecraft:double_stone_block_slab 0
setblock ~208~64~17 minecraft:sea_lantern
fill ~209~61~17 ~212~63~17 minecraft:concrete 8
fill ~209~64~17 ~212~64~17 minecraft:concrete 11
setblock ~213~61~17 minecraft:sea_lantern
fill ~213~62~17 ~213~63~17 minecraft:double_stone_block_slab 0
setblock ~213~64~17 minecraft:sea_lantern
fill ~218~61~17 ~218~63~25 minecraft:concrete 8
fill ~218~64~17 ~218~64~25 minecraft:stone_block_slab 0
fill ~219~64~17 ~219~64~26 minecraft:stone_block_slab 8
fill ~220~64~17 ~220~64~25 minecraft:stone_block_slab 14
fill ~221~64~17 ~221~64~26 minecraft:stone_block_slab 8
fill ~222~61~17 ~222~63~25 minecraft:concrete 8
fill ~222~64~17 ~222~64~25 minecraft:stone_block_slab 0
setblock ~227~61~17 minecraft:sea_lantern
fill ~227~62~17 ~227~63~17 minecraft:double_stone_block_slab 0
setblock ~227~64~17 minecraft:sea_lantern
fill ~228~61~17 ~231~63~17 minecraft:concrete 8
fill ~228~64~17 ~231~64~17 minecraft:concrete 11
setblock ~232~61~17 minecraft:sea_lantern
fill ~232~62~17 ~232~63~17 minecraft:double_stone_block_slab 0
setblock ~232~64~17 minecraft:sea_lantern
fill ~233~61~17 ~236~61~17 minecraft:carpet 8
fill ~233~64~17 ~236~64~17 minecraft:stone_block_slab 8
fill ~237~61~17 ~240~61~17 minecraft:carpet 11
fill ~237~64~17 ~240~64~17 minecraft:stone_block_slab 14
fill ~241~61~17 ~242~61~17 minecraft:carpet 8
fill ~241~64~17 ~243~64~17 minecraft:stone_block_slab 8
fill ~243~61~17 ~243~61~19 minecraft:carpet 11
fill ~244~61~17 ~245~63~17 minecraft:concrete 8
fill ~244~64~17 ~245~64~17 minecraft:concrete 11
setblock ~254~61~17 minecraft:concrete 8
fill ~259~60~17 ~259~60~113 minecraft:concrete 0
setblock ~260~61~17 minecraft:sea_lantern
fill ~260~62~17 ~261~62~17 minecraft:concrete 0
fill ~260~63~17 ~260~64~17 minecraft:concrete 0
setblock ~261~61~17 minecraft:concrete 0
setblock ~261~64~17 minecraft:concrete 0
fill ~262~63~17 ~262~63~18 minecraft:concrete 0
fill ~264~64~17 ~264~65~18 minecraft:concrete 0
fill ~2~76~18 ~2~76~28 minecraft:stained_hardened_clay 3
fill ~2~77~18 ~11~77~18 minecraft:concrete 8
fill ~3~75~18 ~3~75~20 minecraft:stained_hardened_clay 3
fill ~4~74~18 ~4~74~20 minecraft:stained_hardened_clay 3
fill ~5~73~18 ~5~73~20 minecraft:stained_hardened_clay 3
fill ~6~72~18 ~8~72~18 minecraft:stained_hardened_clay 3
fill ~9~71~18 ~11~71~18 minecraft:concrete 8
fill ~12~71~18 ~57~71~18 minecraft:concrete 0
fill ~12~72~18 ~57~72~18 minecraft:carpet 0
fill ~12~77~18 ~57~77~18 minecraft:concrete 0
setblock ~57~76~18 minecraft:netherrack
fill ~57~78~18 ~57~78~19 minecraft:concrete 0
fill ~58~69~18 ~103~69~18 minecraft:concrete 0
setblock ~58~70~18 minecraft:concrete 0
setblock ~58~71~18 minecraft:carpet 0
setblock ~58~78~18 minecraft:netherrack
fill ~58~79~18 ~103~79~18 minecraft:concrete 0
fill ~59~70~18 ~103~70~18 minecraft:carpet 0
fill ~104~68~18 ~142~68~18 minecraft:concrete 0
fill ~104~69~18 ~142~69~18 minecraft:carpet 0
setblock ~104~79~18 minecraft:netherrack
fill ~104~80~18 ~142~80~18 minecraft:concrete 0
fill ~143~68~18 ~145~68~18 minecraft:red_nether_brick
fill ~143~80~18 ~145~80~18 minecraft:red_nether_brick
fill ~146~68~18 ~149~68~18 minecraft:concrete 0
fill ~146~80~18 ~149~80~18 minecraft:concrete 0
setblock ~150~69~18 minecraft:concrete 0
fill ~150~70~18 ~150~71~28 minecraft:stained_glass 14
fill ~150~77~18 ~150~78~28 minecraft:stained_glass 14
setblock ~150~79~18 minecraft:concrete 0
fill ~151~69~18 ~152~69~18 minecraft:stained_glass 14
fill ~151~70~18 ~151~71~22 minecraft:lava 8
fill ~151~76~18 ~152~76~22 minecraft:lava 8
fill ~151~77~18 ~151~77~22 minecraft:lava 8
setblock ~151~78~18 minecraft:lava 0
fill ~151~79~18 ~152~79~18 minecraft:stained_glass 14
setblock ~152~70~18 minecraft:stained_glass 14
fill ~152~71~18 ~152~71~28 minecraft:lava 8
setblock ~152~77~18 minecraft:lava 0
setblock ~152~78~18 minecraft:stained_glass 14
fill ~153~71~18 ~154~71~18 minecraft:stained_glass 14
fill ~153~72~18 ~154~75~28 minecraft:lava 8
fill ~153~76~18 ~154~76~18 minecraft:lava 0
fill ~153~77~18 ~154~77~18 minecraft:stained_glass 14
fill ~155~72~18 ~155~72~19 minecraft:stained_glass 14
fill ~155~73~18 ~155~76~18 minecraft:stained_glass 14
fill ~175~64~18 ~176~65~18 minecraft:concrete 0
fill ~177~63~18 ~177~63~19 minecraft:concrete 0
fill ~177~65~18 ~177~65~114 minecraft:concrete 0
fill ~178~61~18 ~178~62~18 minecraft:concrete 0
setblock ~178~64~18 minecraft:concrete 0
fill ~179~60~18 ~180~60~112 minecraft:concrete 0
setblock ~187~61~18 minecraft:concrete 0
setblock ~188~61~18 minecraft:torch 5
fill ~193~61~18 ~193~63~18 minecraft:concrete 8
setblock ~193~64~18 minecraft:concrete 11
setblock ~194~61~18 minecraft:sea_lantern
fill ~194~62~18 ~194~63~18 minecraft:double_stone_block_slab 0
setblock ~194~64~18 minecraft:sea_lantern
fill ~195~61~18 ~196~61~18 minecraft:carpet 8
fill ~195~64~18 ~197~64~18 minecraft:stone_block_slab 8
fill ~198~61~18 ~201~61~18 minecraft:carpet 11
fill ~198~64~18 ~200~64~18 minecraft:stone_block_slab 14
fill ~201~64~18 ~204~64~18 minecraft:stone_block_slab 8
fill ~202~61~18 ~204~61~18 minecraft:carpet 8
fill ~205~61~18 ~207~63~18 minecraft:concrete 8
fill ~205~64~18 ~207~64~18 minecraft:concrete 11
fill ~233~61~18 ~235~63~18 minecraft:concrete 8
fill ~233~64~18 ~235~64~18 minecraft:concrete 11
fill ~236~61~18 ~239~61~18 minecraft:carpet 8
fill ~236~64~18 ~239~64~18 minecraft:stone_block_slab 8
fill ~240~61~18 ~242~61~18 minecraft:carpet 11
fill ~240~64~18 ~242~64~18 minecraft:stone_block_slab 14
fill ~243~64~18 ~245~64~18 minecraft:stone_block_slab 8
fill ~244~61~18 ~245~61~18 minecraft:carpet 8
setblock ~246~61~18 minecraft:sea_lantern
fill ~246~62~18 ~246~63~18 minecraft:double_stone_block_slab 0
setblock ~246~64~18 minecraft:sea_lantern
fill ~247~61~18 ~247~63~18 minecraft:concrete 8
setblock ~247~64~18 minecraft:concrete 11
setblock ~253~61~18 minecraft:concrete 8
setblock ~257~61~18 minecraft:torch 5
fill ~260~60~18 ~261~60~112 minecraft:concrete 0
fill ~262~61~18 ~262~62~18 minecraft:concrete 0
setblock ~262~64~18 minecraft:concrete 0
fill ~263~63~18 ~263~63~19 minecraft:concrete 0
fill ~265~64~18 ~265~65~18 minecraft:concrete 0
fill ~1~77~19 ~1~77~27 minecraft:stained_hardened_clay 3
fill ~2~78~19 ~11~78~19 minecraft:concrete 8
fill ~6~72~19 ~6~72~20 minecraft:stained_hardened_clay 3
fill ~7~71~19 ~9~71~19 minecraft:stained_hardened_clay 3
fill ~10~70~19 ~11~70~19 minecraft:concrete 8
fill ~12~70~19 ~57~70~19 minecraft:concrete 0
fill ~12~71~19 ~57~71~19 minecraft:carpet 0
fill ~12~78~19 ~56~78~19 minecraft:concrete 0
setblock ~57~77~19 minecraft:netherrack
fill ~57~79~19 ~57~79~20 minecraft:concrete 0
fill ~58~68~19 ~103~68~20 minecraft:concrete 0
setblock ~58~69~19 minecraft:concrete 0
setblock ~58~70~19 minecraft:carpet 0
fill ~58~80~19 ~103~80~20 minecraft:concrete 0
fill ~59~69~19 ~103~69~19 minecraft:carpet 0
setblock ~103~79~19 minecraft:netherrack
fill ~104~67~19 ~142~67~20 minecraft:concrete 0
fill ~104~68~19 ~142~68~20 minecraft:carpet 0
fill ~104~81~19 ~142~81~20 minecraft:concrete 0
fill ~143~67~19 ~145~67~20 minecraft:red_nether_brick
fill ~143~81~19 ~145~81~20 minecraft:red_nether_brick
fill ~146~67~19 ~149~67~20 minecraft:concrete 0
fill ~146~81~19 ~149~81~20 minecraft:concrete 0
fill ~150~68~19 ~150~68~20 minecraft:concrete 0
fill ~150~69~19 ~150~69~27 minecraft:stained_glass 14
fill ~150~79~19 ~150~79~27 minecraft:stained_glass 14
fill ~150~80~19 ~150~80~20 minecraft:concrete 0
fill ~151~68~19 ~152~68~20 minecraft:stained_glass 14
fill ~151~69~19 ~151~69~22 minecraft:lava 8
fill ~151~78~19 ~151~78~22 minecraft:lava 8
fill ~151~79~19 ~151~79~20 minecraft:lava 0
fill ~151~80~19 ~152~80~20 minecraft:stained_glass 14
setblock ~152~69~19 minecraft:stained_glass 14
fill ~152~70~19 ~152~70~27 minecraft:lava 8
fill ~152~77~19 ~152~77~27 minecraft:lava 8
setblock ~152~78~19 minecraft:lava 0
setblock ~152~79~19 minecraft:stained_glass 14
fill ~153~70~19 ~154~70~19 minecraft:stained_glass 14
fill ~153~71~19 ~154~71~27 minecraft:lava 8
fill ~153~76~19 ~154~76~27 minecraft:lava 8
fill ~153~77~19 ~154~77~19 minecraft:lava 0
fill ~153~78~19 ~154~78~19 minecraft:stained_glass 14
setblock ~155~71~19 minecraft:stained_glass 14
fill ~155~73~19 ~155~74~27 minecraft:lava 8
setblock ~155~75~19 minecraft:lava 0
fill ~155~76~19 ~155~77~19 minecraft:stained_glass 14
fill ~156~73~19 ~156~75~20 minecraft:stained_glass 14
fill ~174~64~19 ~174~65~19 minecraft:concrete 0
fill ~175~63~19 ~176~63~20 minecraft:concrete 0
fill ~175~65~19 ~176~65~62 minecraft:concrete 0
fill ~177~61~19 ~177~62~19 minecraft:concrete 0
setblock ~177~64~19 minecraft:concrete 0
fill ~178~60~19 ~178~60~111 minecraft:concrete 0
setblock ~188~61~19 minecraft:concrete 0
fill ~191~61~19 ~192~63~19 minecraft:concrete 8
fill ~191~64~19 ~192~64~19 minecraft:concrete 11
fill ~193~61~19 ~195~61~19 minecraft:carpet 8
fill ~193~64~19 ~195~64~19 minecraft:stone_block_slab 8
fill ~196~61~19 ~196~61~20 minecraft:carpet 11
fill ~196~64~19 ~198~64~19 minecraft:stone_block_slab 14
setblock ~198~61~19 minecraft:carpet 11
fill ~199~61~19 ~200~61~19 minecraft:carpet 8
fill ~199~64~19 ~201~64~19 minecraft:stone_block_slab 8
setblock ~201~61~19 minecraft:carpet 11
fill ~202~61~19 ~202~63~19 minecraft:concrete 8
setblock ~202~64~19 minecraft:concrete 11
setblock ~203~61~19 minecraft:sea_lantern
fill ~203~62~19 ~203~63~19 minecraft:double_stone_block_slab 0
setblock ~203~64~19 minecraft:sea_lantern
fill ~204~61~19 ~204~63~19 minecraft:concrete 8
setblock ~204~64~19 minecraft:concrete 11
fill ~207~61~19 ~207~61~27 minecraft:concrete 0
fill ~233~61~19 ~233~61~27 minecraft:concrete 0
fill ~236~61~19 ~236~63~19 minecraft:concrete 8
setblock ~236~64~19 minecraft:concrete 11
setblock ~237~61~19 minecraft:sea_lantern
fill ~237~62~19 ~237~63~19 minecraft:double_stone_block_slab 0
setblock ~237~64~19 minecraft:sea_lantern
fill ~238~61~19 ~238~63~19 minecraft:concrete 8
setblock ~238~64~19 minecraft:concrete 11
fill ~239~61~19 ~241~61~19 minecraft:carpet 8
fill ~239~64~19 ~241~64~19 minecraft:stone_block_slab 8
setblock ~242~61~19 minecraft:carpet 11
fill ~242~64~19 ~244~64~19 minecraft:stone_block_slab 14
fill ~244~61~19 ~244~61~20 minecraft:carpet 11
fill ~245~61~19 ~247~61~19 minecraft:carpet 8
fill ~245~64~19 ~247~64~19 minecraft:stone_block_slab 8
fill ~248~61~19 ~249~63~19 minecraft:concrete 8
fill ~248~64~19 ~249~64~19 minecraft:concrete 11
setblock ~252~61~19 minecraft:concrete 8
fill ~262~60~19 ~262~60~111 minecraft:concrete 0
fill ~263~61~19 ~263~62~19 minecraft:concrete 0
setblock ~263~64~19 minecraft:concrete 0
fill ~264~63~19 ~265~63~20 minecraft:concrete 0
fill ~264~65~19 ~266~65~111 minecraft:concrete 0
setblock ~266~64~19 minecraft:concrete 0
fill ~1~78~20 ~1~78~26 minecraft:stained_hardened_clay 3
fill ~1~79~20 ~11~79~20 minecraft:concrete 8
setblock ~3~76~20 minecraft:torch 4
fill ~7~71~20 ~8~71~20 minecraft:stained_hardened_clay 3
fill ~9~70~20 ~10~70~26 minecraft:stained_hardened_clay 3
setblock ~11~69~20 minecraft:concrete 8
setblock ~11~70~20 minecraft:torch 4
fill ~12~69~20 ~57~69~20 minecraft:concrete 0
fill ~12~70~20 ~57~70~20 minecraft:carpet 0
fill ~12~79~20 ~56~79~20 minecraft:concrete 0
setblock ~57~78~20 minecraft:netherrack
fill ~58~69~20 ~92~69~20 minecraft:carpet 0
setblock ~93~69~20 minecraft:torch 5
fill ~94~69~20 ~98~69~20 minecraft:carpet 0
setblock ~99~69~20 minecraft:torch 5
fill ~100~69~20 ~103~69~20 minecraft:carpet 0
fill ~152~69~20 ~152~69~26 minecraft:lava 8
fill ~152~78~20 ~152~78~26 minecraft:lava 8
setblock ~152~79~20 minecraft:lava 0
fill ~153~69~20 ~154~69~20 minecraft:stained_glass 14
fill ~153~70~20 ~154~70~26 minecraft:lava 8
fill ~153~77~20 ~154~77~26 minecraft:lava 8
fill ~153~78~20 ~154~78~20 minecraft:lava 0
fill ~153~79~20 ~154~79~20 minecraft:stained_glass 14
fill ~155~70~20 ~155~70~21 minecraft:stained_glass 14
fill ~155~71~20 ~155~72~26 minecraft:lava 8
fill ~155~75~20 ~155~76~26 minecraft:lava 8
fill ~155~77~20 ~155~77~21 minecraft:lava 0
fill ~155~78~20 ~155~78~21 minecraft:stained_glass 14
fill ~156~71~20 ~156~71~26 minecraft:stained_glass 14
fill ~156~72~20 ~156~72~21 minecraft:stained_glass 14
fill ~156~76~20 ~156~77~21 minecraft:stained_glass 14
fill ~173~64~20 ~173~65~21 minecraft:concrete 0
fill ~174~63~20 ~174~63~22 minecraft:concrete 0
fill ~174~65~20 ~174~65~111 minecraft:concrete 0
fill ~176~61~20 ~176~62~20 minecraft:concrete 0
setblock ~176~64~20 minecraft:concrete 0
fill ~177~60~20 ~177~60~66 minecraft:concrete 0
setblock ~189~61~20 minecraft:concrete 0
fill ~190~61~20 ~190~63~20 minecraft:concrete 8
setblock ~190~64~20 minecraft:concrete 11
fill ~191~61~20 ~193~61~20 minecraft:carpet 8
fill ~191~64~20 ~193~64~20 minecraft:stone_block_slab 8
fill ~194~61~20 ~195~61~20 minecraft:carpet 11
fill ~194~64~20 ~196~64~20 minecraft:stone_block_slab 14
fill ~197~61~20 ~199~61~20 minecraft:carpet 8
fill ~197~64~20 ~199~64~20 minecraft:stone_block_slab 8
fill ~200~61~20 ~200~63~20 minecraft:concrete 8
fill ~200~64~20 ~201~64~20 minecraft:concrete 11
setblock ~201~61~20 minecraft:birch_door 1
setblock ~201~63~20 minecraft:concrete 8
fill ~239~61~20 ~240~63~20 minecraft:concrete 8
fill ~239~64~20 ~240~64~20 minecraft:concrete 11
fill ~241~61~20 ~243~61~20 minecraft:carpet 8
fill ~241~64~20 ~243~64~20 minecraft:stone_block_slab 8
fill ~244~64~20 ~246~64~20 minecraft:stone_block_slab 14
fill ~245~61~20 ~246~61~20 minecraft:carpet 11
fill ~247~61~20 ~249~61~20 minecraft:carpet 8
fill ~247~64~20 ~249~64~20 minecraft:stone_block_slab 8
fill ~250~61~20 ~251~61~20 minecraft:concrete 8
fill ~250~62~20 ~250~63~20 minecraft:concrete 8
setblock ~250~64~20 minecraft:concrete 11
fill ~263~60~20 ~263~60~110 minecraft:concrete 0
fill ~264~61~20 ~264~62~20 minecraft:concrete 0
setblock ~264~64~20 minecraft:concrete 0
fill ~266~63~20 ~266~63~22 minecraft:concrete 0
fill ~267~64~20 ~267~65~21 minecraft:concrete 0
fill ~1~80~21 ~11~80~25 minecraft:concrete 8
fill ~2~79~21 ~2~79~25 minecraft:stained_hardened_clay 3
setblock ~3~76~21 minecraft:stained_hardened_clay 3
fill ~4~75~21 ~4~75~25 minecraft:magma
fill ~5~74~21 ~5~74~25 minecraft:magma
fill ~6~73~21 ~6~73~25 minecraft:magma
setblock ~7~72~21 minecraft:stained_hardened_clay 3
fill ~8~71~21 ~8~71~27 minecraft:stained_hardened_clay 3
fill ~11~68~21 ~11~68~25 minecraft:concrete 8
fill ~11~70~21 ~11~70~25 minecraft:stained_hardened_clay 3
fill ~12~68~21 ~57~68~25 minecraft:concrete 0
fill ~12~69~21 ~12~69~25 minecraft:stained_hardened_clay 3
fill ~12~80~21 ~57~80~25 minecraft:concrete 0
fill ~13~69~21 ~57~69~22 minecraft:carpet 0
setblock ~57~79~21 minecraft:netherrack
fill ~58~67~21 ~103~67~25 minecraft:concrete 0
fill ~58~68~21 ~103~68~22 minecraft:carpet 0
fill ~58~81~21 ~103~81~25 minecraft:concrete 0
fill ~104~66~21 ~142~66~23 minecraft:concrete 0
fill ~104~67~21 ~142~67~22 minecraft:carpet 0
fill ~104~82~21 ~142~82~25 minecraft:concrete 0
fill ~143~66~21 ~145~66~25 minecraft:red_nether_brick
fill ~143~82~21 ~145~82~25 minecraft:red_nether_brick
fill ~146~66~21 ~149~66~25 minecraft:concrete 0
fill ~146~82~21 ~149~82~25 minecraft:concrete 0
fill ~150~67~21 ~150~67~25 minecraft:concrete 0
fill ~150~68~21 ~150~68~25 minecraft:stained_glass 14
fill ~150~80~21 ~150~80~25 minecraft:stained_glass 14
fill ~150~81~21 ~150~81~25 minecraft:concrete 0
fill ~151~67~21 ~152~67~25 minecraft:stained_glass 14
fill ~151~68~21 ~152~68~22 minecraft:lava 8
fill ~151~79~21 ~152~79~22 minecraft:lava 8
fill ~151~80~21 ~152~80~22 minecraft:lava 0
fill ~151~81~21 ~152~81~25 minecraft:stained_glass 14
fill ~153~68~21 ~154~68~25 minecraft:stained_glass 14
fill ~153~69~21 ~154~69~25 minecraft:lava 8
fill ~153~78~21 ~154~78~25 minecraft:lava 8
fill ~153~79~21 ~154~79~25 minecraft:lava 0
fill ~153~80~21 ~154~80~25 minecraft:stained_glass 14
fill ~155~69~21 ~155~69~25 minecraft:stained_glass 14
fill ~155~79~21 ~155~79~25 minecraft:stained_glass 14
fill ~156~73~21 ~156~74~25 minecraft:lava 8
setblock ~156~75~21 minecraft:lava 0
fill ~157~73~21 ~157~75~25 minecraft:stained_glass 14
fill ~172~64~21 ~172~65~22 minecraft:concrete 0
fill ~175~61~21 ~175~64~21 minecraft:concrete 0
fill ~176~60~21 ~176~60~66 minecraft:concrete 0
fill ~189~61~21 ~189~63~21 minecraft:concrete 8
setblock ~189~64~21 minecraft:concrete 11
fill ~190~61~21 ~191~61~21 minecraft:carpet 8
fill ~190~64~21 ~191~64~21 minecraft:stone_block_slab 8
fill ~192~61~21 ~194~61~21 minecraft:carpet 11
fill ~192~64~21 ~194~64~21 minecraft:stone_block_slab 14
fill ~195~61~21 ~197~61~21 minecraft:carpet 8
fill ~195~64~21 ~197~64~21 minecraft:stone_block_slab 8
setblock ~198~61~21 minecraft:sea_lantern
fill ~198~62~21 ~198~63~21 minecraft:double_stone_block_slab 0
setblock ~198~64~21 minecraft:sea_lantern
fill ~199~61~21 ~199~63~21 minecraft:concrete 8
setblock ~199~64~21 minecraft:concrete 11
fill ~241~61~21 ~241~63~21 minecraft:concrete 8
setblock ~241~64~21 minecraft:concrete 11
setblock ~242~61~21 minecraft:sea_lantern
fill ~242~62~21 ~242~63~21 minecraft:double_stone_block_slab 0
setblock ~242~64~21 minecraft:sea_lantern
fill ~243~61~21 ~245~61~21 minecraft:carpet 8
fill ~243~64~21 ~245~64~21 minecraft:stone_block_slab 8
fill ~246~61~21 ~248~61~21 minecraft:carpet 11
fill ~246~64~21 ~248~64~21 minecraft:stone_block_slab 14
fill ~249~61~21 ~250~61~21 minecraft:carpet 8
fill ~249~64~21 ~250~64~21 minecraft:stone_block_slab 8
fill ~251~61~21 ~251~63~21 minecraft:concrete 8
setblock ~251~64~21 minecraft:concrete 11
fill ~264~60~21 ~264~60~109 minecraft:concrete 0
fill ~265~61~21 ~265~64~21 minecraft:concrete 0
fill ~268~64~21 ~268~65~22 minecraft:concrete 0
fill ~0~80~22 ~0~80~24 minecraft:concrete 8
fill ~3~76~22 ~3~76~24 minecraft:magma
fill ~7~72~22 ~7~72~24 minecraft:magma
fill ~155~70~22 ~155~70~24 minecraft:lava 8
fill ~155~77~22 ~155~77~24 minecraft:lava 8
fill ~155~78~22 ~155~78~24 minecraft:lava 0
fill ~156~70~22 ~156~70~24 minecraft:stained_glass 14
fill ~156~72~22 ~156~72~24 minecraft:lava 8
fill ~156~75~22 ~156~75~24 minecraft:lava 8
fill ~156~76~22 ~156~76~24 minecraft:lava 0
fill ~156~77~22 ~156~77~26 minecraft:stained_glass 14
fill ~156~78~22 ~156~78~24 minecraft:stained_glass 14
fill ~157~72~22 ~157~72~24 minecraft:stained_glass 14
fill ~157~76~22 ~157~76~24 minecraft:stained_glass 14
fill ~171~64~22 ~171~65~23 minecraft:concrete 0
fill ~173~63~22 ~173~63~23 minecraft:concrete 0
fill ~173~65~22 ~173~65~110 minecraft:concrete 0
fill ~174~61~22 ~174~62~22 minecraft:concrete 0
setblock ~174~64~22 minecraft:concrete 0
fill ~175~60~22 ~175~60~66 minecraft:concrete 0
setblock ~182~61~22 minecraft:torch 5
setblock ~187~61~22 minecraft:birch_door 3
setblock ~187~63~22 minecraft:concrete 8
setblock ~187~64~22 minecraft:concrete 11
setblock ~188~61~22 minecraft:sea_lantern
fill ~188~62~22 ~188~63~22 minecraft:double_stone_block_slab 0
setblock ~188~64~22 minecraft:sea_lantern
fill ~189~61~22 ~190~61~22 minecraft:carpet 8
fill ~189~64~22 ~190~64~22 minecraft:stone_block_slab 8
fill ~191~61~22 ~192~61~22 minecraft:carpet 11
fill ~191~64~22 ~192~64~22 minecraft:stone_block_slab 14
fill ~193~61~22 ~195~61~22 minecraft:carpet 8
fill ~193~64~22 ~195~64~22 minecraft:stone_block_slab 8
fill ~196~61~22 ~197~63~22 minecraft:concrete 8
fill ~196~64~22 ~197~64~22 minecraft:concrete 11
fill ~219~61~22 ~219~61~27 minecraft:carpet 8
fill ~243~61~22 ~244~63~22 minecraft:concrete 8
fill ~243~64~22 ~244~64~22 minecraft:concrete 11
fill ~245~61~22 ~247~61~22 minecraft:carpet 8
fill ~245~64~22 ~247~64~22 minecraft:stone_block_slab 8
fill ~248~61~22 ~249~61~22 minecraft:carpet 11
fill ~248~64~22 ~249~64~22 minecraft:stone_block_slab 14
fill ~250~61~22 ~251~61~22 minecraft:carpet 8
fill ~250~64~22 ~251~64~22 minecraft:stone_block_slab 8
setblock ~252~61~22 minecraft:sea_lantern
fill ~252~62~22 ~252~63~22 minecraft:double_stone_block_slab 0
setblock ~252~64~22 minecraft:sea_lantern
setblock ~253~61~22 minecraft:birch_door 3
setblock ~253~63~22 minecraft:concrete 8
setblock ~253~64~22 minecraft:concrete 11
fill ~265~60~22 ~265~60~108 minecraft:concrete 0
fill ~266~61~22 ~266~62~22 minecraft:concrete 0
setblock ~266~64~22 minecraft:concrete 0
fill ~267~63~22 ~267~63~23 minecraft:concrete 0
fill ~267~65~22 ~267~65~110 minecraft:concrete 0
fill ~269~64~22 ~269~65~23 minecraft:concrete 0
fill ~13~69~23 ~36~69~25 minecraft:carpet 0
setblock ~37~69~23 minecraft:torch 5
fill ~38~69~23 ~50~69~25 minecraft:carpet 0
setblock ~51~69~23 minecraft:torch 5
fill ~52~69~23 ~57~69~25 minecraft:carpet 0
fill ~58~68~23 ~66~68~25 minecraft:carpet 0
setblock ~67~68~23 minecraft:torch 5
fill ~68~68~23 ~81~68~25 minecraft:carpet 0
setblock ~82~68~23 minecraft:torch 5
fill ~83~68~23 ~103~68~25 minecraft:carpet 0
setblock ~104~67~23 minecraft:torch 5
fill ~105~67~23 ~119~67~23 minecraft:carpet 0
setblock ~120~67~23 minecraft:torch 5
fill ~121~67~23 ~129~67~25 minecraft:carpet 0
setblock ~130~67~23 minecraft:torch 5
fill ~131~67~23 ~142~67~25 minecraft:carpet 0
setblock ~144~67~23 minecraft:torch 5
fill ~151~68~23 ~151~79~23 minecraft:lava 10
setblock ~151~80~23 minecraft:lava 2
fill ~152~68~23 ~152~68~25 minecraft:lava 8
fill ~152~72~23 ~152~75~29 minecraft:lava 8
fill ~152~76~23 ~152~76~28 minecraft:lava 8
fill ~152~79~23 ~152~79~25 minecraft:lava 8
fill ~152~80~23 ~152~80~25 minecraft:lava 0
setblock ~158~74~23 minecraft:stained_glass 14
fill ~170~64~23 ~170~65~24 minecraft:concrete 0
fill ~172~63~23 ~172~63~25 minecraft:concrete 0
fill ~172~65~23 ~172~65~109 minecraft:concrete 0
fill ~173~61~23 ~173~62~23 minecraft:concrete 0
setblock ~173~64~23 minecraft:concrete 0
fill ~174~60~23 ~174~60~107 minecraft:concrete 0
fill ~186~61~23 ~186~63~23 minecraft:concrete 8
setblock ~186~64~23 minecraft:concrete 11
fill ~187~61~23 ~187~61~26 minecraft:carpet 11
fill ~187~64~23 ~189~64~23 minecraft:stone_block_slab 8
fill ~188~61~23 ~189~61~23 minecraft:carpet 8
fill ~190~61~23 ~191~61~23 minecraft:carpet 11
fill ~190~64~23 ~191~64~23 minecraft:stone_block_slab 14
fill ~192~61~23 ~193~61~23 minecraft:carpet 8
fill ~192~64~23 ~193~64~23 minecraft:stone_block_slab 8
fill ~194~61~23 ~195~63~23 minecraft:concrete 8
fill ~194~64~23 ~195~64~23 minecraft:concrete 11
fill ~245~61~23 ~246~63~23 minecraft:concrete 8
fill ~245~64~23 ~246~64~23 minecraft:concrete 11
fill ~247~61~23 ~248~61~23 minecraft:carpet 8
fill ~247~64~23 ~248~64~23 minecraft:stone_block_slab 8
fill ~249~61~23 ~250~61~23 minecraft:carpet 11
fill ~249~64~23 ~250~64~23 minecraft:stone_block_slab 14
fill ~251~61~23 ~252~61~23 minecraft:carpet 8
fill ~251~64~23 ~253~64~23 minecraft:stone_block_slab 8
fill ~253~61~23 ~253~61~26 minecraft:carpet 11
fill ~254~61~23 ~254~63~23 minecraft:concrete 8
setblock ~254~64~23 minecraft:concrete 11
setblock ~259~61~23 minecraft:torch 5
fill ~266~60~23 ~266~60~107 minecraft:concrete 0
fill ~267~61~23 ~267~62~23 minecraft:concrete 0
setblock ~267~64~23 minecraft:concrete 0
fill ~268~63~23 ~268~63~25 minecraft:concrete 0
fill ~268~65~23 ~268~65~109 minecraft:concrete 0
fill ~270~64~23 ~270~65~24 minecraft:concrete 0
fill ~37~69~24 ~37~69~25 minecraft:carpet 0
fill ~51~69~24 ~51~69~25 minecraft:carpet 0
fill ~67~68~24 ~67~68~25 minecraft:carpet 0
fill ~82~68~24 ~82~68~25 minecraft:carpet 0
fill ~104~66~24 ~116~66~25 minecraft:concrete 0
fill ~104~67~24 ~116~67~25 minecraft:carpet 0
fill ~118~66~24 ~142~66~25 minecraft:concrete 0
fill ~118~67~24 ~120~67~25 minecraft:carpet 0
fill ~130~67~24 ~130~67~25 minecraft:carpet 0
fill ~151~68~24 ~151~79~25 minecraft:lava 8
fill ~151~80~24 ~151~80~25 minecraft:lava 0
setblock ~171~63~24 minecraft:concrete 0
fill ~171~65~24 ~171~65~108 minecraft:concrete 0
fill ~172~61~24 ~172~62~24 minecraft:concrete 0
fill ~172~64~24 ~172~64~25 minecraft:concrete 0
fill ~173~60~24 ~173~60~106 minecraft:concrete 0
fill ~185~61~24 ~185~63~24 minecraft:concrete 8
setblock ~185~64~24 minecraft:concrete 11
fill ~186~61~24 ~186~61~25 minecraft:carpet 8
fill ~186~64~24 ~187~64~24 minecraft:stone_block_slab 8
fill ~188~61~24 ~190~61~24 minecraft:carpet 11
fill ~188~64~24 ~190~64~24 minecraft:stone_block_slab 14
fill ~191~61~24 ~192~61~24 minecraft:carpet 8
fill ~191~64~24 ~192~64~24 minecraft:stone_block_slab 8
setblock ~193~61~24 minecraft:sea_lantern
fill ~193~62~24 ~193~63~24 minecraft:double_stone_block_slab 0
setblock ~193~64~24 minecraft:sea_lantern
setblock ~247~61~24 minecraft:sea_lantern
fill ~247~62~24 ~247~63~24 minecraft:double_stone_block_slab 0
setblock ~247~64~24 minecraft:sea_lantern
fill ~248~61~24 ~249~61~24 minecraft:carpet 8
fill ~248~64~24 ~249~64~24 minecraft:stone_block_slab 8
fill ~250~61~24 ~252~61~24 minecraft:carpet 11
fill ~250~64~24 ~252~64~24 minecraft:stone_block_slab 14
fill ~253~64~24 ~254~64~24 minecraft:stone_block_slab 8
fill ~254~61~24 ~254~61~25 minecraft:carpet 8
fill ~255~61~24 ~255~63~24 minecraft:concrete 8
setblock ~255~64~24 minecraft:concrete 11
setblock ~263~61~24 minecraft:torch 5
fill ~267~60~24 ~267~60~106 minecraft:concrete 0
fill ~268~61~24 ~268~62~24 minecraft:concrete 0
fill ~268~64~24 ~268~64~25 minecraft:concrete 0
setblock ~269~63~24 minecraft:concrete 0
fill ~269~65~24 ~269~65~108 minecraft:concrete 0
setblock ~3~76~25 minecraft:stained_hardened_clay 3
setblock ~7~72~25 minecraft:stained_hardened_clay 3
fill ~117~66~25 ~117~66~28 minecraft:concrete 0
setblock ~117~67~25 minecraft:carpet 0
fill ~155~70~25 ~155~70~26 minecraft:stained_glass 14
fill ~155~77~25 ~155~77~26 minecraft:lava 0
fill ~155~78~25 ~155~78~26 minecraft:stained_glass 14
fill ~156~72~25 ~156~72~26 minecraft:stained_glass 14
setblock ~156~75~25 minecraft:lava 0
fill ~156~76~25 ~156~76~26 minecraft:stained_glass 14
fill ~169~64~25 ~169~65~25 minecraft:concrete 0
fill ~170~63~25 ~170~63~27 minecraft:concrete 0
fill ~170~65~25 ~170~65~107 minecraft:concrete 0
fill ~171~61~25 ~171~61~27 minecraft:concrete 0
fill ~171~62~25 ~172~62~25 minecraft:concrete 0
setblock ~172~61~25 minecraft:sea_lantern
fill ~184~61~25 ~184~63~25 minecraft:concrete 8
setblock ~184~64~25 minecraft:concrete 11
fill ~185~61~25 ~185~61~26 minecraft:carpet 8
fill ~185~64~25 ~186~64~25 minecraft:stone_block_slab 8
fill ~187~64~25 ~188~64~25 minecraft:stone_block_slab 14
setblock ~188~61~25 minecraft:carpet 11
fill ~189~61~25 ~191~61~25 minecraft:carpet 8
fill ~189~64~25 ~191~64~25 minecraft:stone_block_slab 8
fill ~192~61~25 ~192~63~25 minecraft:concrete 8
setblock ~192~64~25 minecraft:concrete 11
fill ~194~61~25 ~194~61~26 minecraft:concrete 0
fill ~246~61~25 ~246~61~26 minecraft:concrete 0
fill ~247~64~25 ~247~64~26 minecraft:stone_block_slab 8
fill ~248~61~25 ~248~63~25 minecraft:concrete 8
setblock ~248~64~25 minecraft:concrete 11
fill ~249~61~25 ~251~61~25 minecraft:carpet 8
fill ~249~64~25 ~251~64~25 minecraft:stone_block_slab 8
setblock ~252~61~25 minecraft:carpet 11
fill ~252~64~25 ~253~64~25 minecraft:stone_block_slab 14
fill ~254~64~25 ~255~64~25 minecraft:stone_block_slab 8
fill ~255~61~25 ~255~61~26 minecraft:carpet 8
fill ~256~61~25 ~256~63~25 minecraft:concrete 8
setblock ~256~64~25 minecraft:concrete 11
setblock ~268~61~25 minecraft:sea_lantern
fill ~268~62~25 ~269~62~25 minecraft:concrete 0
fill ~269~61~25 ~269~61~26 minecraft:concrete 0
fill ~270~63~25 ~270~63~27 minecraft:concrete 0
fill ~270~65~25 ~271~65~105 minecraft:concrete 0
setblock ~271~64~25 minecraft:concrete 0
fill ~1~79~26 ~11~79~26 minecraft:concrete 8
fill ~3~75~26 ~3~75~28 minecraft:stained_hardened_clay 3
setblock ~3~76~26 minecraft:torch 3
fill ~4~74~26 ~4~74~28 minecraft:stained_hardened_clay 3
fill ~5~73~26 ~5~73~28 minecraft:stained_hardened_clay 3
fill ~6~72~26 ~6~72~28 minecraft:stained_hardened_clay 3
fill ~7~71~26 ~7~71~27 minecraft:stained_hardened_clay 3
setblock ~11~69~26 minecraft:concrete 8
setblock ~11~70~26 minecraft:torch 3
fill ~12~69~26 ~57~69~26 minecraft:concrete 0
fill ~12~70~26 ~57~70~26 minecraft:carpet 0
fill ~12~79~26 ~57~79~26 minecraft:concrete 0
fill ~32~72~26 ~32~76~27 minecraft:concrete 0
fill ~33~72~26 ~58~72~26 minecraft:nether_brick_stairs 3
fill ~33~73~26 ~35~76~26 minecraft:nether_brick_stairs 3
fill ~33~77~26 ~35~77~26 minecraft:stone_block_slab 7
fill ~36~73~26 ~58~75~26 minecraft:red_nether_brick
fill ~36~76~26 ~58~76~26 minecraft:nether_brick_stairs 7
fill ~36~77~26 ~58~77~26 minecraft:netherrack
fill ~58~68~26 ~103~68~27 minecraft:concrete 0
fill ~58~69~26 ~103~69~26 minecraft:carpet 0
fill ~58~80~26 ~103~80~27 minecraft:concrete 0
setblock ~86~72~26 minecraft:torch 4
fill ~104~67~26 ~107~67~27 minecraft:concrete 0
fill ~104~68~26 ~107~68~27 minecraft:carpet 0
fill ~104~81~26 ~142~81~27 minecraft:concrete 0
fill ~108~66~26 ~116~66~26 minecraft:concrete 0
fill ~108~67~26 ~116~67~26 minecraft:carpet 0
fill ~117~67~26 ~142~67~27 minecraft:concrete 0
fill ~117~68~26 ~142~68~27 minecraft:carpet 0
fill ~143~67~26 ~145~67~27 minecraft:red_nether_brick
fill ~143~81~26 ~145~81~27 minecraft:red_nether_brick
fill ~146~67~26 ~149~67~27 minecraft:concrete 0
fill ~146~81~26 ~149~81~27 minecraft:concrete 0
fill ~150~68~26 ~150~68~27 minecraft:concrete 0
fill ~150~80~26 ~150~80~27 minecraft:concrete 0
fill ~151~68~26 ~152~68~27 minecraft:stained_glass 14
fill ~151~69~26 ~151~78~27 minecraft:lava 8
fill ~151~79~26 ~152~79~26 minecraft:lava 0
fill ~151~80~26 ~152~80~27 minecraft:stained_glass 14
fill ~153~69~26 ~154~69~26 minecraft:stained_glass 14
fill ~153~78~26 ~154~78~26 minecraft:lava 0
fill ~153~79~26 ~154~79~26 minecraft:stained_glass 14
fill ~156~73~26 ~156~75~27 minecraft:stained_glass 14
fill ~168~64~26 ~168~65~27 minecraft:concrete 0
fill ~169~63~26 ~169~63~29 minecraft:concrete 0
fill ~169~65~26 ~169~65~105 minecraft:concrete 0
fill ~171~62~26 ~171~64~26 minecraft:concrete 0
fill ~172~60~26 ~172~60~104 minecraft:concrete 0
setblock ~177~61~26 minecraft:torch 5
fill ~183~61~26 ~183~63~26 minecraft:concrete 8
setblock ~183~64~26 minecraft:concrete 11
fill ~184~61~26 ~184~61~27 minecraft:carpet 8
fill ~184~64~26 ~185~64~26 minecraft:stone_block_slab 8
fill ~186~61~26 ~186~61~27 minecraft:carpet 11
fill ~186~64~26 ~187~64~26 minecraft:stone_block_slab 14
fill ~188~61~26 ~189~61~26 minecraft:carpet 8
fill ~188~64~26 ~189~64~26 minecraft:stone_block_slab 8
fill ~190~61~26 ~191~63~26 minecraft:concrete 8
fill ~190~64~26 ~191~64~26 minecraft:concrete 11
fill ~214~61~26 ~217~63~26 minecraft:concrete 8
fill ~214~64~26 ~217~64~26 minecraft:concrete 10
setblock ~218~61~26 minecraft:double_stone_block_slab 0
fill ~218~62~26 ~218~63~26 minecraft:sea_lantern
setblock ~218~64~26 minecraft:double_stone_block_slab 0
setblock ~220~64~26 minecraft:stone_block_slab 8
setblock ~222~61~26 minecraft:double_stone_block_slab 0
fill ~222~62~26 ~222~63~26 minecraft:sea_lantern
setblock ~222~64~26 minecraft:double_stone_block_slab 0
fill ~223~61~26 ~226~63~26 minecraft:concrete 8
fill ~223~64~26 ~226~64~26 minecraft:concrete 10
fill ~248~64~26 ~248~64~27 minecraft:stone_block_slab 8
fill ~249~61~26 ~250~63~26 minecraft:concrete 8
fill ~249~64~26 ~250~64~26 minecraft:concrete 11
fill ~251~61~26 ~252~61~26 minecraft:carpet 8
fill ~251~64~26 ~252~64~26 minecraft:stone_block_slab 8
fill ~253~64~26 ~254~64~26 minecraft:stone_block_slab 14
fill ~254~61~26 ~254~61~27 minecraft:carpet 11
fill ~255~64~26 ~256~64~26 minecraft:stone_block_slab 8
fill ~256~61~26 ~256~61~27 minecraft:carpet 8
fill ~257~61~26 ~257~63~26 minecraft:concrete 8
setblock ~257~64~26 minecraft:concrete 11
fill ~268~60~26 ~268~60~104 minecraft:concrete 0
fill ~269~62~26 ~269~64~26 minecraft:concrete 0
fill ~271~63~26 ~271~63~29 minecraft:concrete 0
fill ~272~64~26 ~272~65~27 minecraft:concrete 0
fill ~2~78~27 ~11~78~27 minecraft:concrete 8
setblock ~9~71~27 minecraft:stained_hardened_clay 3
fill ~10~70~27 ~11~70~27 minecraft:concrete 8
fill ~12~70~27 ~57~70~27 minecraft:concrete 0
fill ~12~71~27 ~29~71~27 minecraft:carpet 0
fill ~12~78~27 ~57~78~27 minecraft:concrete 0
fill ~28~72~27 ~31~76~27 minecraft:concrete 0
fill ~30~71~27 ~57~71~28 minecraft:concrete 0
fill ~30~77~27 ~57~77~28 minecraft:concrete 0
setblock ~57~79~27 minecraft:concrete 0
fill ~58~69~27 ~58~69~28 minecraft:concrete 0
setblock ~58~70~27 minecraft:carpet 0
setblock ~58~72~27 minecraft:nether_brick_stairs 0
fill ~58~73~27 ~80~75~27 minecraft:red_nether_brick
setblock ~58~76~27 minecraft:nether_brick_stairs 4
fill ~58~77~27 ~97~77~27 minecraft:netherrack
fill ~59~69~27 ~103~69~27 minecraft:carpet 0
fill ~59~72~27 ~104~72~27 minecraft:nether_brick_stairs 3
fill ~59~76~27 ~101~76~27 minecraft:nether_brick_stairs 7
fill ~81~73~27 ~86~73~27 minecraft:nether_brick
fill ~81~74~27 ~81~75~27 minecraft:nether_brick
fill ~82~75~27 ~86~75~27 minecraft:nether_brick
fill ~87~73~27 ~101~75~27 minecraft:red_nether_brick
fill ~102~73~27 ~104~76~27 minecraft:nether_brick_stairs 3
fill ~102~77~27 ~104~77~27 minecraft:stone_block_slab 7
fill ~105~72~27 ~107~76~27 minecraft:concrete 0
setblock ~105~77~27 minecraft:netherrack
fill ~108~65~27 ~117~65~27 minecraft:concrete 0
fill ~108~66~27 ~108~67~28 minecraft:concrete 0
fill ~108~68~27 ~115~68~27 minecraft:carpet 0
fill ~109~67~27 ~115~67~28 minecraft:concrete 0
fill ~116~66~27 ~116~66~28 minecraft:concrete 0
setblock ~116~67~27 minecraft:carpet 0
setblock ~151~79~27 minecraft:lava 0
fill ~152~69~27 ~152~69~28 minecraft:stained_glass 14
setblock ~152~78~27 minecraft:lava 0
fill ~152~79~27 ~152~79~28 minecraft:stained_glass 14
fill ~153~70~27 ~154~70~27 minecraft:stained_glass 14
fill ~153~77~27 ~154~77~27 minecraft:lava 0
fill ~153~78~27 ~154~78~27 minecraft:stained_glass 14
fill ~155~71~27 ~155~72~27 minecraft:stained_glass 14
setblock ~155~75~27 minecraft:lava 0
fill ~155~76~27 ~155~76~28 minecraft:stained_glass 14
setblock ~155~77~27 minecraft:stained_glass 14
fill ~167~64~27 ~167~65~28 minecraft:concrete 0
fill ~170~61~27 ~170~62~27 minecraft:concrete 0
setblock ~170~64~27 minecraft:concrete 0
fill ~171~60~27 ~171~60~103 minecraft:concrete 0
setblock ~182~61~27 minecraft:sea_lantern
fill ~182~62~27 ~182~63~27 minecraft:double_stone_block_slab 0
setblock ~182~64~27 minecraft:sea_lantern
fill ~183~61~27 ~183~61~28 minecraft:carpet 8
fill ~183~64~27 ~184~64~27 minecraft:stone_block_slab 8
fill ~185~61~27 ~185~61~28 minecraft:carpet 11
fill ~185~64~27 ~186~64~27 minecraft:stone_block_slab 14
fill ~187~61~27 ~188~61~27 minecraft:carpet 8
fill ~187~64~27 ~188~64~27 minecraft:stone_block_slab 8
fill ~189~61~27 ~189~63~27 minecraft:concrete 8
setblock ~189~64~27 minecraft:concrete 11
setblock ~195~61~27 minecraft:concrete 0
fill ~210~61~27 ~210~63~27 minecraft:concrete 8
fill ~210~64~27 ~212~64~27 minecraft:concrete 10
setblock ~211~61~27 minecraft:birch_door 3
fill ~211~63~27 ~212~63~27 minecraft:concrete 8
fill ~212~61~27 ~212~62~27 minecraft:concrete 8
setblock ~213~61~27 minecraft:sea_lantern
fill ~213~62~27 ~213~63~27 minecraft:double_stone_block_slab 0
setblock ~213~64~27 minecraft:sea_lantern
fill ~213~65~27 ~214~65~27 minecraft:concrete 0
fill ~214~61~27 ~218~61~27 minecraft:carpet 8
fill ~214~64~27 ~218~64~27 minecraft:stone_block_slab 8
fill ~215~66~27 ~227~66~27 minecraft:stone_block_slab 6
fill ~219~64~27 ~221~64~27 minecraft:stone_block_slab 14
setblock ~220~61~27 minecraft:carpet 8
fill ~222~61~27 ~226~61~27 minecraft:carpet 8
fill ~222~64~27 ~226~64~27 minecraft:stone_block_slab 8
setblock ~227~61~27 minecraft:sea_lantern
fill ~227~62~27 ~227~63~27 minecraft:double_stone_block_slab 0
setblock ~227~64~27 minecraft:sea_lantern
setblock ~227~65~27 minecraft:netherrack
fill ~228~61~27 ~230~63~27 minecraft:concrete 8
fill ~228~64~27 ~230~64~27 minecraft:concrete 10
setblock ~245~61~27 minecraft:concrete 0
fill ~249~64~27 ~250~64~27 minecraft:stone_block_slab 8
fill ~251~61~27 ~251~63~27 minecraft:concrete 8
setblock ~251~64~27 minecraft:concrete 11
fill ~252~61~27 ~253~61~27 minecraft:carpet 8
fill ~252~64~27 ~253~64~27 minecraft:stone_block_slab 8
fill ~254~64~27 ~255~64~27 minecraft:stone_block_slab 14
fill ~255~61~27 ~255~61~28 minecraft:carpet 11
fill ~256~64~27 ~257~64~27 minecraft:stone_block_slab 8
fill ~257~61~27 ~257~61~28 minecraft:carpet 8
setblock ~258~61~27 minecraft:sea_lantern
fill ~258~62~27 ~258~63~27 minecraft:double_stone_block_slab 0
setblock ~258~64~27 minecraft:sea_lantern
fill ~269~60~27 ~269~60~103 minecraft:concrete 0
fill ~270~61~27 ~270~62~27 minecraft:concrete 0
setblock ~270~64~27 minecraft:concrete 0
fill ~273~64~27 ~273~65~28 minecraft:concrete 0
fill ~2~77~28 ~11~77~28 minecraft:concrete 8
fill ~7~72~28 ~8~72~28 minecraft:stained_hardened_clay 3
fill ~9~71~28 ~11~71~28 minecraft:concrete 8
fill ~12~71~28 ~29~71~28 minecraft:concrete 0
fill ~12~72~28 ~26~72~28 minecraft:carpet 0
fill ~12~77~28 ~29~77~28 minecraft:concrete 0
fill ~27~72~28 ~27~72~29 minecraft:concrete 0
fill ~27~73~28 ~27~76~28 minecraft:concrete 0
setblock ~57~78~28 minecraft:concrete 0
fill ~58~70~28 ~58~71~29 minecraft:concrete 0
fill ~58~77~28 ~107~77~29 minecraft:concrete 0
fill ~58~79~28 ~103~79~28 minecraft:concrete 0
fill ~59~69~28 ~103~69~28 minecraft:concrete 0
fill ~59~70~28 ~103~70~28 minecraft:carpet 0
fill ~59~71~28 ~107~71~29 minecraft:concrete 0
fill ~82~74~28 ~85~74~29 minecraft:concrete 8
fill ~86~74~28 ~88~74~30 minecraft:concrete 7
fill ~104~68~28 ~142~68~28 minecraft:concrete 0
fill ~104~69~28 ~115~69~28 minecraft:carpet 0
fill ~104~74~28 ~105~74~31 minecraft:concrete 7
fill ~104~80~28 ~142~80~28 minecraft:concrete 0
fill ~106~74~28 ~107~74~31 minecraft:concrete 8
fill ~108~64~28 ~117~64~28 minecraft:concrete 0
fill ~108~65~28 ~108~65~29 minecraft:concrete 0
fill ~108~72~28 ~110~72~28 minecraft:concrete 0
fill ~108~73~28 ~109~76~28 minecraft:concrete 0
fill ~109~66~28 ~115~66~28 minecraft:concrete 0
setblock ~110~73~28 minecraft:carpet 0
setblock ~110~76~28 minecraft:concrete 0
fill ~116~67~28 ~117~67~28 minecraft:concrete 0
fill ~117~65~28 ~117~65~29 minecraft:concrete 0
fill ~117~69~28 ~142~69~28 minecraft:carpet 0
fill ~143~68~28 ~145~68~28 minecraft:red_nether_brick
fill ~143~80~28 ~145~80~28 minecraft:red_nether_brick
fill ~146~68~28 ~149~68~28 minecraft:concrete 0
fill ~146~80~28 ~149~80~28 minecraft:concrete 0
setblock ~150~69~28 minecraft:concrete 0
setblock ~150~79~28 minecraft:concrete 0
setblock ~151~69~28 minecraft:stained_glass 14
fill ~151~70~28 ~151~77~28 minecraft:lava 8
setblock ~151~78~28 minecraft:lava 0
setblock ~151~79~28 minecraft:stained_glass 14
fill ~152~70~28 ~152~70~29 minecraft:stained_glass 14
setblock ~152~77~28 minecraft:lava 0
fill ~152~78~28 ~152~78~29 minecraft:stained_glass 14
fill ~153~71~28 ~154~71~28 minecraft:stained_glass 14
fill ~153~76~28 ~154~76~28 minecraft:lava 0
fill ~153~77~28 ~154~77~28 minecraft:stained_glass 14
fill ~155~72~28 ~155~75~28 minecraft:stained_glass 14
setblock ~168~63~28 minecraft:concrete 0
fill ~168~65~28 ~168~65~104 minecraft:concrete 0
fill ~169~61~28 ~169~62~28 minecraft:concrete 0
fill ~169~64~28 ~169~64~29 minecraft:concrete 0
fill ~170~60~28 ~170~60~102 minecraft:concrete 0
setblock ~172~61~28 minecraft:concrete 0
fill ~181~61~28 ~181~63~28 minecraft:concrete 8
setblock ~181~64~28 minecraft:concrete 11
fill ~182~61~28 ~182~61~29 minecraft:carpet 8
fill ~182~64~28 ~183~64~28 minecraft:stone_block_slab 8
fill ~184~61~28 ~184~61~29 minecraft:carpet 11
fill ~184~64~28 ~185~64~28 minecraft:stone_block_slab 14
fill ~186~61~28 ~187~61~28 minecraft:carpet 8
fill ~186~64~28 ~187~64~28 minecraft:stone_block_slab 8
setblock ~188~61~28 minecraft:sea_lantern
fill ~188~62~28 ~188~63~28 minecraft:double_stone_block_slab 0
setblock ~188~64~28 minecraft:sea_lantern
fill ~196~61~28 ~196~61~29 minecraft:concrete 0
fill ~207~61~28 ~207~63~28 minecraft:concrete 8
setblock ~207~64~28 minecraft:concrete 10
fill ~207~65~28 ~210~65~28 minecraft:concrete 0
setblock ~208~61~28 minecraft:sea_lantern
fill ~208~62~28 ~208~63~28 minecraft:double_stone_block_slab 0
setblock ~208~64~28 minecraft:sea_lantern
fill ~209~61~28 ~209~63~28 minecraft:concrete 8
setblock ~209~64~28 minecraft:concrete 10
fill ~210~61~28 ~210~61~29 minecraft:carpet 8
fill ~210~64~28 ~214~64~28 minecraft:stone_block_slab 8
fill ~211~61~28 ~211~61~30 minecraft:carpet 10
fill ~211~66~28 ~214~66~28 minecraft:stone_block_slab 6
fill ~212~61~28 ~214~61~28 minecraft:carpet 8
fill ~215~61~28 ~217~61~29 minecraft:carpet 10
fill ~215~64~28 ~217~64~29 minecraft:stone_block_slab 14
fill ~215~66~28 ~227~66~30 minecraft:stone_block_slab 14
fill ~218~61~28 ~218~61~30 minecraft:carpet 8
fill ~218~64~28 ~218~64~30 minecraft:stone_block_slab 8
fill ~219~61~28 ~221~61~29 minecraft:carpet 10
fill ~219~64~28 ~219~64~30 minecraft:stone_block_slab 14
fill ~220~64~28 ~220~64~29 minecraft:stone_block_slab2 0
fill ~221~64~28 ~221~64~30 minecraft:stone_block_slab 14
fill ~222~61~28 ~222~61~30 minecraft:carpet 8
fill ~222~64~28 ~222~64~30 minecraft:stone_block_slab 8
fill ~223~61~28 ~225~61~29 minecraft:carpet 10
fill ~223~64~28 ~225~64~29 minecraft:stone_block_slab 14
fill ~226~61~28 ~230~61~28 minecraft:carpet 8
fill ~226~64~28 ~230~64~28 minecraft:stone_block_slab 8
fill ~228~66~28 ~231~66~28 minecraft:stone_block_slab 6
fill ~231~61~28 ~231~63~28 minecraft:concrete 8
setblock ~231~64~28 minecraft:concrete 10
setblock ~232~61~28 minecraft:sea_lantern
fill ~232~62~28 ~232~63~28 minecraft:double_stone_block_slab 0
setblock ~232~64~28 minecraft:sea_lantern
fill ~232~65~28 ~233~65~28 minecraft:concrete 0
fill ~233~61~28 ~233~63~28 minecraft:concrete 8
setblock ~233~64~28 minecraft:concrete 10
fill ~244~61~28 ~244~61~29 minecraft:concrete 0
fill ~250~64~28 ~251~64~28 minecraft:stone_block_slab 8
setblock ~252~61~28 minecraft:sea_lantern
fill ~252~62~28 ~252~63~28 minecraft:double_stone_block_slab 0
setblock ~252~64~28 minecraft:sea_lantern
fill ~253~61~28 ~254~61~28 minecraft:carpet 8
fill ~253~64~28 ~254~64~28 minecraft:stone_block_slab 8
fill ~255~64~28 ~256~64~28 minecraft:stone_block_slab 14
fill ~256~61~28 ~256~61~29 minecraft:carpet 11
fill ~257~64~28 ~258~64~28 minecraft:stone_block_slab 8
fill ~258~61~28 ~258~61~29 minecraft:carpet 8
fill ~259~61~28 ~259~63~28 minecraft:concrete 8
setblock ~259~64~28 minecraft:concrete 11
fill ~270~60~28 ~270~60~102 minecraft:concrete 0
fill ~271~61~28 ~271~62~28 minecraft:concrete 0
fill ~271~64~28 ~271~64~29 minecraft:concrete 0
setblock ~272~63~28 minecraft:concrete 0
fill ~272~65~28 ~272~65~104 minecraft:concrete 0
fill ~3~76~29 ~11~76~29 minecraft:concrete 8
fill ~4~75~29 ~11~75~29 minecraft:concrete 8
fill ~5~74~29 ~11~74~29 minecraft:concrete 8
fill ~6~73~29 ~11~73~29 minecraft:concrete 8
fill ~7~72~29 ~11~72~29 minecraft:concrete 8
fill ~12~72~29 ~26~76~29 minecraft:concrete 0
setblock ~27~76~29 minecraft:concrete 0
fill ~58~78~29 ~103~78~29 minecraft:concrete 0
fill ~59~70~29 ~103~70~29 minecraft:concrete 0
fill ~89~74~29 ~97~74~30 minecraft:concrete 7
fill ~102~74~29 ~103~74~31 minecraft:concrete 7
fill ~104~69~29 ~142~69~29 minecraft:concrete 0
fill ~104~70~29 ~112~70~29 minecraft:carpet 0
fill ~104~79~29 ~142~79~29 minecraft:concrete 0
fill ~108~63~29 ~117~63~29 minecraft:concrete 0
fill ~108~64~29 ~108~64~30 minecraft:concrete 0
fill ~108~71~29 ~112~71~30 minecraft:concrete 0
fill ~108~73~29 ~110~73~29 minecraft:concrete 7
fill ~108~75~29 ~110~75~30 minecraft:concrete 7
fill ~108~77~29 ~110~77~30 minecraft:concrete 0
fill ~109~65~29 ~110~65~29 minecraft:concrete 0
fill ~111~65~29 ~114~65~29 minecraft:nether_brick
fill ~111~72~29 ~112~72~29 minecraft:concrete 0
fill ~111~73~29 ~112~73~29 minecraft:carpet 0
fill ~111~76~29 ~112~76~29 minecraft:concrete 0
setblock ~113~70~29 minecraft:torch 5
fill ~114~70~29 ~142~70~29 minecraft:carpet 0
fill ~115~65~29 ~116~65~29 minecraft:concrete 0
fill ~117~64~29 ~117~64~30 minecraft:concrete 0
fill ~143~69~29 ~145~69~29 minecraft:red_nether_brick
fill ~143~79~29 ~145~79~29 minecraft:red_nether_brick
setblock ~144~70~29 minecraft:torch 5
fill ~146~69~29 ~149~69~29 minecraft:concrete 0
fill ~146~79~29 ~149~79~29 minecraft:concrete 0
fill ~150~70~29 ~150~71~29 minecraft:concrete 0
fill ~150~77~29 ~150~78~29 minecraft:concrete 0
fill ~151~70~29 ~151~71~29 minecraft:stained_glass 14
fill ~151~72~29 ~151~75~29 minecraft:lava 8
fill ~151~76~29 ~152~76~29 minecraft:lava 0
fill ~151~77~29 ~152~77~29 minecraft:stained_glass 14
setblock ~151~78~29 minecraft:stained_glass 14
setblock ~152~71~29 minecraft:stained_glass 14
fill ~153~72~29 ~154~76~29 minecraft:stained_glass 14
fill ~166~64~29 ~166~65~29 minecraft:concrete 0
fill ~167~63~29 ~167~63~32 minecraft:concrete 0
fill ~167~65~29 ~167~65~56 minecraft:concrete 0
fill ~168~61~29 ~168~62~30 minecraft:concrete 0
setblock ~169~61~29 minecraft:sea_lantern
setblock ~169~62~29 minecraft:concrete 0
setblock ~173~61~29 minecraft:concrete 0
fill ~180~61~29 ~180~63~29 minecraft:concrete 8
setblock ~180~64~29 minecraft:concrete 11
fill ~181~61~29 ~181~61~30 minecraft:carpet 8
fill ~181~64~29 ~182~64~29 minecraft:stone_block_slab 8
fill ~183~61~29 ~183~61~30 minecraft:carpet 11
fill ~183~64~29 ~184~64~29 minecraft:stone_block_slab 14
fill ~185~61~29 ~186~61~29 minecraft:carpet 8
fill ~185~64~29 ~186~64~29 minecraft:stone_block_slab 8
fill ~187~61~29 ~187~63~29 minecraft:concrete 8
setblock ~187~64~29 minecraft:concrete 11
fill ~204~61~29 ~206~63~29 minecraft:concrete 8
fill ~204~64~29 ~206~64~29 minecraft:concrete 10
fill ~207~61~29 ~209~61~29 minecraft:carpet 8
fill ~207~64~29 ~210~64~29 minecraft:stone_block_slab 8
setblock ~207~65~29 minecraft:concrete 0
fill ~208~66~29 ~210~66~29 minecraft:stone_block_slab 6
fill ~211~64~29 ~214~64~29 minecraft:stone_block_slab 14
fill ~211~66~29 ~214~66~31 minecraft:stone_block_slab 14
fill ~212~61~29 ~214~61~29 minecraft:carpet 10
fill ~226~61~29 ~229~61~29 minecraft:carpet 10
fill ~226~64~29 ~229~64~29 minecraft:stone_block_slab 14
fill ~228~66~29 ~231~66~31 minecraft:stone_block_slab 14
fill ~230~61~29 ~233~61~29 minecraft:carpet 8
fill ~230~64~29 ~233~64~29 minecraft:stone_block_slab 8
fill ~232~66~29 ~234~66~29 minecraft:stone_block_slab 6
fill ~234~61~29 ~236~63~29 minecraft:concrete 8
fill ~234~64~29 ~236~64~29 minecraft:concrete 10
fill ~235~65~29 ~241~65~29 minecraft:concrete 0
fill ~251~64~29 ~252~64~29 minecraft:stone_block_slab 8
fill ~253~61~29 ~253~63~29 minecraft:concrete 8
setblock ~253~64~29 minecraft:concrete 11
fill ~254~61~29 ~255~61~29 minecraft:carpet 8
fill ~254~64~29 ~255~64~29 minecraft:stone_block_slab 8
fill ~256~64~29 ~257~64~29 minecraft:stone_block_slab 14
fill ~257~61~29 ~257~61~30 minecraft:carpet 11
fill ~258~64~29 ~259~64~29 minecraft:stone_block_slab 8
fill ~259~61~29 ~259~61~30 minecraft:carpet 8
fill ~260~61~29 ~260~63~29 minecraft:concrete 8
setblock ~260~64~29 minecraft:concrete 11
setblock ~265~61~29 minecraft:torch 5
setblock ~270~61~29 minecraft:concrete 8
setblock ~271~61~29 minecraft:sea_lantern
fill ~271~62~29 ~272~62~29 minecraft:concrete 0
fill ~272~61~29 ~272~61~30 minecraft:concrete 0
fill ~273~63~29 ~273~63~32 minecraft:concrete 0
fill ~273~65~29 ~274~65~101 minecraft:concrete 0
setblock ~274~64~29 minecraft:concrete 0
fill ~83~74~30 ~85~74~30 minecraft:concrete 8
fill ~98~74~30 ~101~74~31 minecraft:concrete 7
fill ~104~70~30 ~142~70~30 minecraft:concrete 0
fill ~104~71~30 ~107~71~30 minecraft:concrete 0
fill ~104~77~30 ~107~78~30 minecraft:concrete 0
fill ~108~62~30 ~117~62~30 minecraft:concrete 0
fill ~108~63~30 ~108~63~31 minecraft:concrete 0
fill ~108~74~30 ~111~74~31 minecraft:concrete 8
fill ~108~78~30 ~142~78~30 minecraft:concrete 0
fill ~109~64~30 ~110~64~30 minecraft:concrete 0
setblock ~111~64~30 minecraft:nether_brick
fill ~111~73~30 ~111~73~31 minecraft:concrete 7
fill ~111~75~30 ~111~75~31 minecraft:concrete 7
fill ~111~77~30 ~142~77~30 minecraft:concrete 0
fill ~112~64~30 ~113~64~30 minecraft:red_nether_brick
setblock ~112~73~30 minecraft:concrete 0
setblock ~112~75~30 minecraft:concrete 0
fill ~113~71~30 ~142~71~30 minecraft:concrete 0
fill ~113~72~30 ~113~72~31 minecraft:concrete 0
setblock ~113~73~30 minecraft:carpet 0
fill ~113~76~30 ~113~76~31 minecraft:concrete 0
setblock ~114~64~30 minecraft:nether_brick
fill ~114~72~30 ~142~72~30 minecraft:carpet 0
fill ~115~64~30 ~116~64~30 minecraft:concrete 0
fill ~117~63~30 ~117~63~31 minecraft:concrete 0
fill ~143~70~30 ~145~71~30 minecraft:red_nether_brick
fill ~143~77~30 ~145~78~30 minecraft:red_nether_brick
fill ~146~70~30 ~149~71~30 minecraft:concrete 0
fill ~146~77~30 ~149~78~30 minecraft:concrete 0
fill ~150~72~30 ~150~76~30 minecraft:concrete 0
fill ~151~72~30 ~152~76~30 minecraft:stained_glass 14
fill ~165~64~30 ~165~65~31 minecraft:concrete 0
fill ~166~63~30 ~166~63~31 minecraft:concrete 0
fill ~166~65~30 ~166~65~56 minecraft:concrete 0
fill ~168~63~30 ~168~64~30 minecraft:concrete 0
fill ~169~60~30 ~169~60~100 minecraft:concrete 0
setblock ~174~61~30 minecraft:concrete 0
fill ~179~61~30 ~179~63~30 minecraft:concrete 8
setblock ~179~64~30 minecraft:concrete 11
fill ~180~61~30 ~180~61~31 minecraft:carpet 8
fill ~180~64~30 ~181~64~30 minecraft:stone_block_slab 8
fill ~182~61~30 ~182~61~31 minecraft:carpet 11
fill ~182~64~30 ~183~64~30 minecraft:stone_block_slab 14
fill ~184~61~30 ~185~61~30 minecraft:carpet 8
fill ~184~64~30 ~185~64~30 minecraft:stone_block_slab 8
fill ~186~61~30 ~186~63~30 minecraft:concrete 8
setblock ~186~64~30 minecraft:concrete 11
setblock ~197~61~30 minecraft:concrete 0
fill ~202~61~30 ~202~63~30 minecraft:concrete 8
setblock ~202~64~30 minecraft:concrete 10
setblock ~203~61~30 minecraft:sea_lantern
fill ~203~62~30 ~203~63~30 minecraft:double_stone_block_slab 0
setblock ~203~64~30 minecraft:sea_lantern
fill ~203~65~30 ~204~65~30 minecraft:concrete 0
fill ~204~61~30 ~207~61~30 minecraft:carpet 8
fill ~204~64~30 ~207~64~30 minecraft:stone_block_slab 8
fill ~205~66~30 ~207~66~30 minecraft:stone_block_slab 6
fill ~208~61~30 ~210~61~30 minecraft:carpet 10
fill ~208~64~30 ~213~64~30 minecraft:stone_block_slab 14
fill ~208~66~30 ~210~66~32 minecraft:stone_block_slab 14
fill ~212~61~30 ~213~61~30 minecraft:carpet 10
fill ~214~61~30 ~217~61~30 minecraft:carpet 8
fill ~214~64~30 ~217~64~30 minecraft:stone_block_slab 8
fill ~219~61~30 ~221~61~30 minecraft:carpet 8
setblock ~220~64~30 minecraft:stone_block_slab 14
fill ~223~61~30 ~226~61~30 minecraft:carpet 8
fill ~223~64~30 ~226~64~30 minecraft:stone_block_slab 8
fill ~227~61~30 ~232~61~30 minecraft:carpet 10
fill ~227~64~30 ~232~64~30 minecraft:stone_block_slab 14
fill ~232~66~30 ~234~66~32 minecraft:stone_block_slab 14
fill ~233~61~30 ~236~61~30 minecraft:carpet 8
fill ~233~64~30 ~236~64~30 minecraft:stone_block_slab 8
fill ~235~66~30 ~237~66~30 minecraft:stone_block_slab 6
setblock ~237~61~30 minecraft:sea_lantern
fill ~237~62~30 ~237~63~30 minecraft:double_stone_block_slab 0
setblock ~237~64~30 minecraft:sea_lantern
setblock ~237~65~30 minecraft:netherrack
fill ~238~61~30 ~238~63~30 minecraft:concrete 8
setblock ~238~64~30 minecraft:concrete 10
fill ~238~65~30 ~241~65~30 minecraft:concrete 0
setblock ~243~61~30 minecraft:concrete 0
fill ~252~64~30 ~253~64~30 minecraft:stone_block_slab 8
fill ~254~61~30 ~254~63~30 minecraft:concrete 8
setblock ~254~64~30 minecraft:concrete 11
fill ~255~61~30 ~256~61~30 minecraft:carpet 8
fill ~255~64~30 ~256~64~30 minecraft:stone_block_slab 8
fill ~257~64~30 ~258~64~30 minecraft:stone_block_slab 14
fill ~258~61~30 ~258~61~31 minecraft:carpet 11
fill ~259~64~30 ~260~64~30 minecraft:stone_block_slab 8
fill ~260~61~30 ~260~61~31 minecraft:carpet 8
fill ~261~61~30 ~261~63~30 minecraft:concrete 8
setblock ~261~64~30 minecraft:concrete 11
setblock ~269~61~30 minecraft:concrete 8
fill ~271~60~30 ~271~60~100 minecraft:concrete 0
fill ~272~62~30 ~272~64~30 minecraft:concrete 0
fill ~274~63~30 ~274~63~31 minecraft:concrete 0
fill ~275~64~30 ~275~65~31 minecraft:concrete 0
fill ~96~74~31 ~97~74~31 minecraft:concrete 7
fill ~108~61~31 ~117~61~31 minecraft:concrete 0
fill ~108~62~31 ~108~62~32 minecraft:concrete 0
fill ~109~63~31 ~110~63~31 minecraft:concrete 0
setblock ~111~63~31 minecraft:nether_brick
fill ~112~63~31 ~113~63~31 minecraft:red_nether_brick
fill ~112~73~31 ~113~73~31 minecraft:concrete 7
setblock ~112~74~31 minecraft:concrete 8
fill ~112~75~31 ~113~75~31 minecraft:concrete 7
setblock ~113~74~31 minecraft:concrete 7
setblock ~114~63~31 minecraft:nether_brick
fill ~114~72~31 ~142~76~31 minecraft:concrete 0
fill ~115~63~31 ~116~63~31 minecraft:concrete 0
fill ~117~62~31 ~117~62~32 minecraft:concrete 0
fill ~143~72~31 ~145~76~31 minecraft:red_nether_brick
fill ~146~72~31 ~149~76~31 minecraft:concrete 0
fill ~167~61~31 ~167~62~31 minecraft:concrete 0
fill ~167~64~31 ~167~64~32 minecraft:concrete 0
fill ~168~60~31 ~168~60~99 minecraft:concrete 0
setblock ~175~61~31 minecraft:concrete 0
fill ~178~61~31 ~178~63~31 minecraft:concrete 8
setblock ~178~64~31 minecraft:concrete 11
fill ~179~61~31 ~179~61~32 minecraft:carpet 8
fill ~179~64~31 ~180~64~31 minecraft:stone_block_slab 8
fill ~181~61~31 ~181~61~32 minecraft:carpet 11
fill ~181~64~31 ~182~64~31 minecraft:stone_block_slab 14
fill ~183~61~31 ~184~61~31 minecraft:carpet 8
fill ~183~64~31 ~184~64~31 minecraft:stone_block_slab 8
fill ~185~61~31 ~185~63~31 minecraft:concrete 8
setblock ~185~64~31 minecraft:concrete 11
setblock ~186~61~31 minecraft:concrete 0
setblock ~198~61~31 minecraft:concrete 0
fill ~201~61~31 ~201~63~31 minecraft:concrete 8
setblock ~201~64~31 minecraft:concrete 10
fill ~202~61~31 ~204~61~31 minecraft:carpet 8
fill ~202~64~31 ~204~64~31 minecraft:stone_block_slab 8
fill ~203~66~31 ~205~66~31 minecraft:stone_block_slab 6
fill ~205~61~31 ~209~61~31 minecraft:carpet 10
fill ~205~64~31 ~209~64~31 minecraft:stone_block_slab 14
fill ~206~66~31 ~207~66~33 minecraft:stone_block_slab 14
fill ~210~61~31 ~214~61~31 minecraft:carpet 8
fill ~210~64~31 ~214~64~31 minecraft:stone_block_slab 8
fill ~215~61~31 ~217~63~31 minecraft:concrete 8
fill ~215~64~31 ~217~64~31 minecraft:concrete 10
setblock ~215~66~31 minecraft:stone_block_slab 14
fill ~216~67~31 ~226~67~32 minecraft:stone_block_slab 6
setblock ~218~61~31 minecraft:double_stone_block_slab 0
fill ~218~62~31 ~218~63~31 minecraft:sea_lantern
fill ~218~64~31 ~218~64~40 minecraft:double_stone_block_slab 0
fill ~219~61~31 ~219~61~41 minecraft:carpet 8
fill ~219~64~31 ~221~64~31 minecraft:stone_block_slab 8
fill ~220~61~31 ~220~61~40 minecraft:carpet 0
fill ~221~61~31 ~221~61~41 minecraft:carpet 8
setblock ~222~61~31 minecraft:double_stone_block_slab 0
fill ~222~62~31 ~222~63~31 minecraft:sea_lantern
fill ~222~64~31 ~222~64~40 minecraft:double_stone_block_slab 0
fill ~223~61~31 ~225~63~31 minecraft:concrete 8
fill ~223~64~31 ~225~64~31 minecraft:concrete 10
fill ~226~61~31 ~230~61~31 minecraft:carpet 8
fill ~226~64~31 ~230~64~31 minecraft:stone_block_slab 8
setblock ~227~66~31 minecraft:stone_block_slab 14
fill ~231~61~31 ~235~61~31 minecraft:carpet 10
fill ~231~64~31 ~235~64~31 minecraft:stone_block_slab 14
fill ~235~66~31 ~236~66~33 minecraft:stone_block_slab 14
fill ~236~61~31 ~238~61~31 minecraft:carpet 8
fill ~236~64~31 ~238~64~31 minecraft:stone_block_slab 8
fill ~237~66~31 ~239~66~31 minecraft:stone_block_slab 6
fill ~239~61~31 ~239~63~31 minecraft:concrete 8
setblock ~239~64~31 minecraft:concrete 10
setblock ~239~65~31 minecraft:netherrack
fill ~240~65~31 ~241~65~31 minecraft:concrete 0
setblock ~242~61~31 minecraft:concrete 0
setblock ~254~61~31 minecraft:concrete 0
fill ~255~61~31 ~255~63~31 minecraft:concrete 8
setblock ~255~64~31 minecraft:concrete 11
fill ~256~61~31 ~257~61~31 minecraft:carpet 8
fill ~256~64~31 ~257~64~31 minecraft:stone_block_slab 8
fill ~258~64~31 ~259~64~31 minecraft:stone_block_slab 14
fill ~259~61~31 ~259~61~32 minecraft:carpet 11
fill ~260~64~31 ~261~64~31 minecraft:stone_block_slab 8
fill ~261~61~31 ~261~61~32 minecraft:carpet 8
fill ~262~61~31 ~262~63~31 minecraft:concrete 8
setblock ~262~64~31 minecraft:concrete 11
setblock ~268~61~31 minecraft:concrete 8
fill ~272~60~31 ~272~60~99 minecraft:concrete 0
fill ~273~61~31 ~273~62~31 minecraft:concrete 0
fill ~273~64~31 ~273~64~32 minecraft:concrete 0
fill ~107~74~32 ~109~74~32 minecraft:concrete 8
fill ~108~60~32 ~117~60~32 minecraft:concrete 0
fill ~108~61~32 ~108~61~33 minecraft:concrete 0
fill ~109~62~32 ~110~62~32 minecraft:concrete 0
setblock ~111~62~32 minecraft:nether_brick
fill ~112~62~32 ~113~62~32 minecraft:red_nether_brick
setblock ~114~62~32 minecraft:nether_brick
fill ~114~73~32 ~117~75~32 minecraft:concrete 7
fill ~115~62~32 ~116~62~32 minecraft:concrete 0
fill ~117~61~32 ~117~61~33 minecraft:concrete 0
fill ~164~64~32 ~164~65~33 minecraft:concrete 0
fill ~165~63~32 ~165~63~35 minecraft:concrete 0
fill ~165~65~32 ~165~65~56 minecraft:concrete 0
fill ~166~61~32 ~166~62~33 minecraft:concrete 0
setblock ~167~61~32 minecraft:sea_lantern
setblock ~167~62~32 minecraft:concrete 0
setblock ~176~61~32 minecraft:concrete 0
fill ~177~61~32 ~177~63~32 minecraft:concrete 8
setblock ~177~64~32 minecraft:concrete 11
fill ~178~61~32 ~178~61~34 minecraft:carpet 8
fill ~178~64~32 ~179~64~32 minecraft:stone_block_slab 8
fill ~180~61~32 ~180~61~33 minecraft:carpet 11
fill ~180~64~32 ~181~64~32 minecraft:stone_block_slab 14
fill ~182~61~32 ~183~61~32 minecraft:carpet 8
fill ~182~64~32 ~183~64~32 minecraft:stone_block_slab 8
fill ~184~61~32 ~184~63~32 minecraft:concrete 8
setblock ~184~64~32 minecraft:concrete 11
setblock ~187~61~32 minecraft:concrete 0
fill ~199~61~32 ~200~63~32 minecraft:concrete 8
fill ~199~64~32 ~200~64~32 minecraft:concrete 10
fill ~200~65~32 ~201~65~32 minecraft:concrete 0
fill ~201~61~32 ~202~61~32 minecraft:carpet 8
fill ~201~64~32 ~202~64~32 minecraft:stone_block_slab 8
fill ~202~66~32 ~203~66~32 minecraft:stone_block_slab 6
fill ~203~61~32 ~206~61~32 minecraft:carpet 10
fill ~203~64~32 ~206~64~32 minecraft:stone_block_slab 14
fill ~204~66~32 ~205~66~34 minecraft:stone_block_slab 14
fill ~207~61~32 ~210~61~32 minecraft:carpet 8
fill ~207~64~32 ~210~64~32 minecraft:stone_block_slab 8
fill ~211~61~32 ~213~63~32 minecraft:concrete 8
fill ~211~64~32 ~213~64~32 minecraft:concrete 10
fill ~211~67~32 ~215~67~33 minecraft:stone_block_slab 6
setblock ~214~61~32 minecraft:sea_lantern
fill ~214~62~32 ~214~63~32 minecraft:double_stone_block_slab 0
setblock ~214~64~32 minecraft:sea_lantern
fill ~215~64~32 ~217~64~39 minecraft:stone_block_slab 8
fill ~216~65~32 ~226~66~32 minecraft:concrete 0
fill ~218~61~32 ~218~63~39 minecraft:concrete 8
fill ~219~64~32 ~219~64~40 minecraft:stone_block_slab 8
fill ~220~64~32 ~220~64~39 minecraft:stone_block_slab 14
fill ~221~64~32 ~221~64~40 minecraft:stone_block_slab 8
fill ~222~61~32 ~222~63~39 minecraft:concrete 8
fill ~223~64~32 ~225~64~39 minecraft:stone_block_slab 8
setblock ~226~61~32 minecraft:sea_lantern
fill ~226~62~32 ~226~63~32 minecraft:double_stone_block_slab 0
setblock ~226~64~32 minecraft:sea_lantern
fill ~227~61~32 ~229~63~32 minecraft:concrete 8
fill ~227~64~32 ~229~64~32 minecraft:concrete 10
fill ~227~67~32 ~231~67~33 minecraft:stone_block_slab 6
fill ~230~61~32 ~233~61~32 minecraft:carpet 8
fill ~230~64~32 ~233~64~32 minecraft:stone_block_slab 8
fill ~234~61~32 ~237~61~32 minecraft:carpet 10
fill ~234~64~32 ~237~64~32 minecraft:stone_block_slab 14
fill ~237~66~32 ~238~66~34 minecraft:stone_block_slab 14
fill ~238~61~32 ~239~61~32 minecraft:carpet 8
fill ~238~64~32 ~239~64~32 minecraft:stone_block_slab 8
fill ~239~66~32 ~240~66~32 minecraft:stone_block_slab 6
fill ~240~61~32 ~241~63~32 minecraft:concrete 8
fill ~240~64~32 ~241~64~32 minecraft:concrete 10
setblock ~241~65~32 minecraft:concrete 0
fill ~242~64~32 ~243~64~32 minecraft:stone_block_slab 8
setblock ~253~61~32 minecraft:concrete 0
fill ~256~61~32 ~256~63~32 minecraft:concrete 8
setblock ~256~64~32 minecraft:concrete 11
fill ~257~61~32 ~258~61~32 minecraft:carpet 8
fill ~257~64~32 ~258~64~32 minecraft:stone_block_slab 8
fill ~259~64~32 ~260~64~32 minecraft:stone_block_slab 14
fill ~260~61~32 ~260~61~33 minecraft:carpet 11
fill ~261~64~32 ~262~64~32 minecraft:stone_block_slab 8
fill ~262~61~32 ~262~61~34 minecraft:carpet 8
fill ~263~61~32 ~263~63~32 minecraft:concrete 8
setblock ~263~64~32 minecraft:concrete 11
setblock ~267~61~32 minecraft:concrete 8
setblock ~270~61~32 minecraft:torch 5
setblock ~273~61~32 minecraft:sea_lantern
fill ~273~62~32 ~274~62~32 minecraft:concrete 0
fill ~274~61~32 ~274~61~33 minecraft:concrete 0
fill ~275~63~32 ~275~63~35 minecraft:concrete 0
fill ~275~65~32 ~276~65~98 minecraft:concrete 0
fill ~276~64~32 ~276~64~33 minecraft:concrete 0
fill ~108~59~33 ~117~59~33 minecraft:concrete 0
fill ~108~60~33 ~108~60~34 minecraft:concrete 0
fill ~109~61~33 ~110~61~33 minecraft:concrete 0
fill ~111~61~33 ~114~61~33 minecraft:nether_brick
fill ~115~61~33 ~116~61~33 minecraft:concrete 0
fill ~117~60~33 ~117~60~34 minecraft:concrete 0
fill ~163~65~33 ~163~65~52 minecraft:concrete 0
fill ~166~63~33 ~166~64~33 minecraft:concrete 0
fill ~167~60~33 ~167~60~97 minecraft:concrete 0
setblock ~177~61~33 minecraft:sea_lantern
fill ~177~62~33 ~177~63~33 minecraft:double_stone_block_slab 0
setblock ~177~64~33 minecraft:sea_lantern
fill ~178~64~33 ~178~64~34 minecraft:stone_block_slab 8
fill ~179~61~33 ~179~61~36 minecraft:carpet 11
fill ~179~64~33 ~180~64~33 minecraft:stone_block_slab 14
fill ~181~61~33 ~182~61~33 minecraft:carpet 8
fill ~181~64~33 ~182~64~33 minecraft:stone_block_slab 8
setblock ~183~61~33 minecraft:sea_lantern
fill ~183~62~33 ~183~63~33 minecraft:double_stone_block_slab 0
setblock ~183~64~33 minecraft:sea_lantern
setblock ~188~61~33 minecraft:concrete 0
setblock ~198~61~33 minecraft:sea_lantern
fill ~198~62~33 ~198~63~33 minecraft:double_stone_block_slab 0
setblock ~198~64~33 minecraft:sea_lantern
fill ~199~61~33 ~201~61~33 minecraft:carpet 8
fill ~199~64~33 ~201~64~33 minecraft:stone_block_slab 8
fill ~200~66~33 ~201~66~33 minecraft:stone_block_slab 6
fill ~202~61~33 ~203~61~33 minecraft:carpet 10
fill ~202~64~33 ~203~64~33 minecraft:stone_block_slab 14
fill ~202~66~33 ~203~66~35 minecraft:stone_block_slab 14
fill ~204~61~33 ~207~61~33 minecraft:carpet 8
fill ~204~64~33 ~207~64~33 minecraft:stone_block_slab 8
fill ~208~61~33 ~209~63~33 minecraft:concrete 8
fill ~208~64~33 ~209~64~33 minecraft:concrete 10
setblock ~208~66~33 minecraft:stone_block_slab 14
fill ~209~67~33 ~210~67~34 minecraft:stone_block_slab 6
setblock ~210~61~33 minecraft:sea_lantern
fill ~210~62~33 ~210~63~33 minecraft:double_stone_block_slab 0
setblock ~210~64~33 minecraft:sea_lantern
fill ~211~64~33 ~214~64~40 minecraft:stone_block_slab 8
fill ~212~65~33 ~215~66~33 minecraft:concrete 0
fill ~216~67~33 ~226~67~34 minecraft:stone_block_slab 14
fill ~226~64~33 ~229~64~40 minecraft:stone_block_slab 8
fill ~227~65~33 ~230~66~33 minecraft:concrete 0
setblock ~230~61~33 minecraft:sea_lantern
fill ~230~62~33 ~230~63~33 minecraft:double_stone_block_slab 0
setblock ~230~64~33 minecraft:sea_lantern
fill ~231~61~33 ~232~63~33 minecraft:concrete 8
fill ~231~64~33 ~232~64~33 minecraft:concrete 10
fill ~232~67~33 ~233~67~34 minecraft:stone_block_slab 6
fill ~233~61~33 ~236~61~33 minecraft:carpet 8
fill ~233~64~33 ~236~64~33 minecraft:stone_block_slab 8
setblock ~234~66~33 minecraft:stone_block_slab 14
fill ~237~61~33 ~238~61~33 minecraft:carpet 10
fill ~237~64~33 ~238~64~33 minecraft:stone_block_slab 14
fill ~239~61~33 ~241~61~33 minecraft:carpet 8
fill ~239~64~33 ~241~64~33 minecraft:stone_block_slab 8
fill ~239~66~33 ~240~66~35 minecraft:stone_block_slab 14
fill ~241~66~33 ~242~66~33 minecraft:stone_block_slab 6
setblock ~242~61~33 minecraft:sea_lantern
fill ~242~62~33 ~242~63~33 minecraft:double_stone_block_slab 0
setblock ~242~64~33 minecraft:sea_lantern
setblock ~242~65~33 minecraft:netherrack
fill ~243~64~33 ~245~64~33 minecraft:stone_block_slab 8
setblock ~243~65~33 minecraft:concrete 0
setblock ~252~61~33 minecraft:concrete 0
setblock ~257~61~33 minecraft:sea_lantern
fill ~257~62~33 ~257~63~33 minecraft:double_stone_block_slab 0
setblock ~257~64~33 minecraft:sea_lantern
fill ~258~61~33 ~259~61~33 minecraft:carpet 8
fill ~258~64~33 ~259~64~33 minecraft:stone_block_slab 8
fill ~260~64~33 ~261~64~33 minecraft:stone_block_slab 14
fill ~261~61~33 ~261~61~35 minecraft:carpet 11
fill ~262~64~33 ~262~64~34 minecraft:stone_block_slab 8
setblock ~263~61~33 minecraft:sea_lantern
fill ~263~62~33 ~263~63~33 minecraft:double_stone_block_slab 0
setblock ~263~64~33 minecraft:sea_lantern
setblock ~266~61~33 minecraft:concrete 8
fill ~273~60~33 ~273~60~97 minecraft:concrete 0
fill ~274~62~33 ~274~64~33 minecraft:concrete 0
fill ~277~64~33 ~277~65~34 minecraft:concrete 0
fill ~108~58~34 ~117~58~34 minecraft:concrete 0
fill ~108~59~34 ~108~59~35 minecraft:concrete 0
fill ~109~60~34 ~116~60~34 minecraft:concrete 0
fill ~117~59~34 ~117~59~35 minecraft:concrete 0
setblock ~163~64~34 minecraft:concrete 0
fill ~164~63~34 ~164~63~37 minecraft:concrete 0
fill ~164~65~34 ~164~65~52 minecraft:concrete 0
fill ~165~61~34 ~165~62~35 minecraft:concrete 0
fill ~165~64~34 ~165~64~35 minecraft:concrete 0
fill ~166~60~34 ~166~60~96 minecraft:concrete 0
setblock ~172~61~34 minecraft:torch 5
fill ~176~61~34 ~176~63~34 minecraft:concrete 8
setblock ~176~64~34 minecraft:concrete 11
fill ~177~61~34 ~177~61~35 minecraft:carpet 8
fill ~177~64~34 ~177~64~35 minecraft:stone_block_slab 8
fill ~179~64~34 ~179~64~35 minecraft:stone_block_slab 14
fill ~180~61~34 ~181~61~34 minecraft:carpet 8
fill ~180~64~34 ~181~64~34 minecraft:stone_block_slab 8
fill ~182~61~34 ~182~63~34 minecraft:concrete 8
setblock ~182~64~34 minecraft:concrete 11
setblock ~189~61~34 minecraft:concrete 0
setblock ~196~61~34 minecraft:birch_door 3
fill ~196~63~34 ~197~63~34 minecraft:concrete 8
fill ~196~64~34 ~197~64~34 minecraft:concrete 10
fill ~197~61~34 ~197~62~34 minecraft:concrete 8
fill ~197~65~34 ~198~65~34 minecraft:concrete 0
fill ~198~61~34 ~199~61~34 minecraft:carpet 8
fill ~198~64~34 ~199~64~34 minecraft:stone_block_slab 8
fill ~199~66~34 ~200~66~34 minecraft:stone_block_slab 6
fill ~200~61~34 ~202~61~34 minecraft:carpet 10
fill ~200~64~34 ~202~64~34 minecraft:stone_block_slab 14
fill ~201~66~34 ~201~66~36 minecraft:stone_block_slab 14
fill ~203~61~34 ~204~61~34 minecraft:carpet 8
fill ~203~64~34 ~204~64~34 minecraft:stone_block_slab 8
fill ~205~61~34 ~205~63~34 minecraft:concrete 8
setblock ~205~64~34 minecraft:concrete 10
setblock ~206~61~34 minecraft:sea_lantern
fill ~206~62~34 ~206~63~34 minecraft:double_stone_block_slab 0
setblock ~206~64~34 minecraft:sea_lantern
fill ~206~67~34 ~208~67~35 minecraft:stone_block_slab 6
fill ~207~61~34 ~207~63~34 minecraft:concrete 8
setblock ~207~64~34 minecraft:concrete 10
fill ~208~64~34 ~210~64~42 minecraft:stone_block_slab 8
fill ~209~65~34 ~211~66~34 minecraft:concrete 0
setblock ~211~67~34 minecraft:stone_block_slab 6
fill ~212~67~34 ~215~67~35 minecraft:stone_block_slab 14
setblock ~220~65~34 minecraft:torch 5
setblock ~224~65~34 minecraft:torch 5
fill ~227~67~34 ~230~67~35 minecraft:stone_block_slab 14
fill ~230~64~34 ~232~64~41 minecraft:stone_block_slab 8
fill ~231~65~34 ~233~66~34 minecraft:concrete 0
setblock ~231~67~34 minecraft:stone_block_slab 6
fill ~233~61~34 ~233~63~34 minecraft:concrete 8
setblock ~233~64~34 minecraft:concrete 10
setblock ~234~61~34 minecraft:sea_lantern
fill ~234~62~34 ~234~63~34 minecraft:double_stone_block_slab 0
setblock ~234~64~34 minecraft:sea_lantern
fill ~234~67~34 ~236~67~35 minecraft:stone_block_slab 6
fill ~235~61~34 ~235~63~34 minecraft:concrete 8
setblock ~235~64~34 minecraft:concrete 10
fill ~236~61~34 ~237~61~34 minecraft:carpet 8
fill ~236~64~34 ~237~64~34 minecraft:stone_block_slab 8
fill ~238~61~34 ~240~61~34 minecraft:carpet 10
fill ~238~64~34 ~240~64~34 minecraft:stone_block_slab 14
fill ~241~61~34 ~242~61~34 minecraft:carpet 8
fill ~241~64~34 ~242~64~34 minecraft:stone_block_slab 8
fill ~241~66~34 ~241~66~36 minecraft:stone_block_slab 14
fill ~242~66~34 ~243~66~34 minecraft:stone_block_slab 6
fill ~243~61~34 ~243~63~34 minecraft:concrete 8
fill ~243~64~34 ~244~64~34 minecraft:concrete 10
setblock ~243~65~34 minecraft:netherrack
setblock ~244~63~34 minecraft:concrete 8
fill ~245~64~34 ~246~64~34 minecraft:stone_block_slab 8
setblock ~251~61~34 minecraft:concrete 0
fill ~258~61~34 ~258~63~34 minecraft:concrete 8
setblock ~258~64~34 minecraft:concrete 11
fill ~259~61~34 ~260~61~34 minecraft:carpet 8
fill ~259~64~34 ~260~64~34 minecraft:stone_block_slab 8
fill ~261~64~34 ~261~64~35 minecraft:stone_block_slab 14
fill ~263~61~34 ~263~61~35 minecraft:carpet 8
fill ~263~64~34 ~263~64~35 minecraft:stone_block_slab 8
fill ~264~61~34 ~265~61~34 minecraft:concrete 8
fill ~264~62~34 ~264~63~34 minecraft:concrete 8
setblock ~264~64~34 minecraft:concrete 11
fill ~274~60~34 ~274~60~96 minecraft:concrete 0
fill ~275~61~34 ~275~62~35 minecraft:concrete 0
fill ~275~64~34 ~275~64~35 minecraft:concrete 0
fill ~276~63~34 ~276~63~37 minecraft:concrete 0
fill ~108~57~35 ~117~57~35 minecraft:concrete 0
fill ~108~58~35 ~108~58~36 minecraft:concrete 0
fill ~109~59~35 ~110~59~35 minecraft:concrete 0
fill ~111~59~35 ~114~59~35 minecraft:nether_brick
fill ~115~59~35 ~116~59~35 minecraft:concrete 0
fill ~117~58~35 ~117~58~36 minecraft:concrete 0
fill ~162~64~35 ~162~65~36 minecraft:concrete 0
fill ~163~63~35 ~163~63~39 minecraft:concrete 0
fill ~175~61~35 ~175~63~35 minecraft:concrete 8
setblock ~175~64~35 minecraft:concrete 11
setblock ~176~61~35 minecraft:carpet 8
fill ~176~64~35 ~176~64~36 minecraft:stone_block_slab 8
fill ~178~61~35 ~178~61~36 minecraft:carpet 11
fill ~178~64~35 ~178~64~36 minecraft:stone_block_slab 14
setblock ~180~61~35 minecraft:carpet 8
fill ~180~64~35 ~180~64~36 minecraft:stone_block_slab 8
fill ~181~61~35 ~181~63~35 minecraft:concrete 8
fill ~181~64~35 ~181~64~36 minecraft:concrete 11
setblock ~190~61~35 minecraft:concrete 0
fill ~195~61~35 ~195~63~35 minecraft:concrete 8
setblock ~195~64~35 minecraft:concrete 10
fill ~196~61~35 ~196~61~38 minecraft:carpet 10
fill ~196~64~35 ~198~64~35 minecraft:stone_block_slab 8
fill ~197~61~35 ~198~61~35 minecraft:carpet 8
fill ~197~66~35 ~198~66~35 minecraft:stone_block_slab 6
fill ~199~61~35 ~200~61~35 minecraft:carpet 10
fill ~199~64~35 ~200~64~35 minecraft:stone_block_slab 14
fill ~199~66~35 ~200~66~37 minecraft:stone_block_slab 14
fill ~201~61~35 ~203~61~35 minecraft:carpet 8
fill ~201~64~35 ~203~64~35 minecraft:stone_block_slab 8
fill ~204~61~35 ~204~63~35 minecraft:concrete 8
setblock ~204~64~35 minecraft:concrete 10
fill ~204~67~35 ~205~67~36 minecraft:stone_block_slab 6
fill ~205~64~35 ~207~64~43 minecraft:stone_block_slab 8
fill ~207~65~35 ~208~66~35 minecraft:concrete 0
fill ~209~67~35 ~211~67~36 minecraft:stone_block_slab 14
setblock ~214~65~35 minecraft:torch 5
fill ~216~68~35 ~226~68~36 minecraft:stone_block_slab 6
setblock ~229~65~35 minecraft:torch 5
fill ~231~67~35 ~233~67~36 minecraft:stone_block_slab 14
fill ~233~61~35 ~233~61~38 minecraft:concrete 0
fill ~233~64~35 ~235~64~42 minecraft:stone_block_slab 8
fill ~234~65~35 ~235~66~35 minecraft:concrete 0
fill ~236~61~35 ~236~63~35 minecraft:concrete 8
setblock ~236~64~35 minecraft:concrete 10
fill ~237~61~35 ~239~61~35 minecraft:carpet 8
fill ~237~64~35 ~239~64~35 minecraft:stone_block_slab 8
fill ~237~67~35 ~238~67~36 minecraft:stone_block_slab 6
fill ~240~61~35 ~241~61~35 minecraft:carpet 10
fill ~240~64~35 ~241~64~35 minecraft:stone_block_slab 14
fill ~242~61~35 ~244~61~35 minecraft:carpet 8
fill ~242~64~35 ~244~64~35 minecraft:stone_block_slab 8
fill ~242~66~35 ~242~66~37 minecraft:stone_block_slab 14
fill ~243~66~35 ~243~66~37 minecraft:stone_block_slab 15
fill ~244~66~35 ~245~66~35 minecraft:stone_block_slab 6
fill ~245~61~35 ~245~63~35 minecraft:concrete 8
setblock ~245~64~35 minecraft:concrete 10
setblock ~245~65~35 minecraft:netherrack
fill ~246~64~35 ~247~64~35 minecraft:stone_block_slab 8
setblock ~246~65~35 minecraft:concrete 0
fill ~247~65~35 ~247~65~36 minecraft:stone_block_slab 15
fill ~248~65~35 ~248~65~37 minecraft:concrete 0
setblock ~250~61~35 minecraft:concrete 0
fill ~259~61~35 ~259~63~36 minecraft:concrete 8
fill ~259~64~35 ~259~64~36 minecraft:concrete 11
fill ~260~61~35 ~260~61~36 minecraft:carpet 8
fill ~260~64~35 ~260~64~36 minecraft:stone_block_slab 8
fill ~262~61~35 ~262~61~36 minecraft:carpet 11
fill ~262~64~35 ~262~64~36 minecraft:stone_block_slab 14
fill ~264~61~35 ~264~61~36 minecraft:carpet 8
fill ~264~64~35 ~264~64~36 minecraft:stone_block_slab 8
fill ~265~61~35 ~265~63~35 minecraft:concrete 8
setblock ~265~64~35 minecraft:concrete 11
fill ~277~63~35 ~277~63~39 minecraft:concrete 0
fill ~277~65~35 ~278~65~95 minecraft:concrete 0
fill ~278~64~35 ~278~64~36 minecraft:concrete 0
fill ~108~56~36 ~117~56~36 minecraft:concrete 0
fill ~108~57~36 ~108~57~37 minecraft:concrete 0
fill ~109~58~36 ~110~58~36 minecraft:concrete 0
setblock ~111~58~36 minecraft:nether_brick
fill ~112~58~36 ~113~58~36 minecraft:red_nether_brick
setblock ~114~58~36 minecraft:nether_brick
fill ~115~58~36 ~116~58~36 minecraft:concrete 0
fill ~117~57~36 ~117~57~37 minecraft:concrete 0
fill ~164~61~36 ~164~62~37 minecraft:concrete 0
fill ~164~64~36 ~164~64~37 minecraft:concrete 0
fill ~165~60~36 ~165~60~94 minecraft:concrete 0
setblock ~174~61~36 minecraft:birch_door 2
fill ~174~63~36 ~174~63~37 minecraft:concrete 8
fill ~174~64~36 ~174~64~37 minecraft:concrete 11
fill ~175~61~36 ~177~61~36 minecraft:carpet 11
fill ~175~64~36 ~175~64~38 minecraft:stone_block_slab 8
fill ~177~64~36 ~177~64~37 minecraft:stone_block_slab 14
fill ~179~64~36 ~179~64~37 minecraft:stone_block_slab 8
setblock ~180~61~36 minecraft:carpet 11
setblock ~181~63~36 minecraft:concrete 8
setblock ~191~61~36 minecraft:concrete 0
fill ~194~61~36 ~194~63~36 minecraft:concrete 8
setblock ~194~64~36 minecraft:concrete 10
fill ~195~61~36 ~195~61~37 minecraft:carpet 8
fill ~195~64~36 ~196~64~36 minecraft:stone_block_slab 8
setblock ~195~65~36 minecraft:concrete 0
fill ~196~66~36 ~197~66~36 minecraft:stone_block_slab 6
fill ~197~61~36 ~199~61~36 minecraft:carpet 10
fill ~197~64~36 ~199~64~36 minecraft:stone_block_slab 14
fill ~198~66~36 ~198~66~39 minecraft:stone_block_slab 14
fill ~200~61~36 ~201~61~36 minecraft:carpet 8
fill ~200~64~36 ~201~64~36 minecraft:stone_block_slab 8
setblock ~202~61~36 minecraft:sea_lantern
fill ~202~62~36 ~202~63~36 minecraft:double_stone_block_slab 0
setblock ~202~64~36 minecraft:sea_lantern
setblock ~202~66~36 minecraft:stone_block_slab 14
