fill ~193~25~11 ~196~25~12 minecraft:stone
fill ~193~28~11 ~196~28~12 minecraft:stone
fill ~189~25~12 ~192~25~14 minecraft:stone
fill ~189~28~12 ~192~28~14 minecraft:stone
fill ~185~25~13 ~188~25~15 minecraft:stone
fill ~185~28~13 ~188~28~15 minecraft:stone
fill ~189~26~13 ~189~27~13 minecraft:stone
fill ~190~26~13 ~191~26~13 minecraft:stonebrick
setblock ~190~27~13 minecraft:stonebrick
setblock ~191~27~13 minecraft:sea_lantern
fill ~192~26~13 ~192~27~13 minecraft:stone
fill ~193~25~13 ~195~25~13 minecraft:stone
fill ~193~26~13 ~193~27~13 minecraft:stonebrick
fill ~193~28~13 ~195~28~13 minecraft:stone
fill ~196~24~13 ~196~24~15 minecraft:stone_block_slab 13
fill ~196~29~13 ~196~29~15 minecraft:stone_block_slab 5
fill ~181~25~14 ~184~25~16 minecraft:stone
fill ~181~28~14 ~184~28~16 minecraft:stone
fill ~185~26~14 ~185~27~14 minecraft:stone
setblock ~186~26~14 minecraft:sea_lantern
fill ~186~27~14 ~187~27~14 minecraft:stonebrick
setblock ~187~26~14 minecraft:stonebrick
setblock ~188~26~14 minecraft:stone
setblock ~188~27~14 minecraft:sea_lantern
fill ~193~25~14 ~194~28~14 minecraft:stone
fill ~194~24~14 ~195~24~15 minecraft:stone_block_slab 13
fill ~194~29~14 ~195~29~15 minecraft:stone_block_slab 5
fill ~195~25~14 ~195~25~33 minecraft:stone_brick_stairs 2
fill ~195~28~14 ~195~28~33 minecraft:stone_brick_stairs 6
fill ~177~25~15 ~180~25~17 minecraft:stone
fill ~177~28~15 ~180~28~17 minecraft:stone
fill ~181~26~15 ~183~26~15 minecraft:stonebrick
setblock ~181~27~15 minecraft:stonebrick
setblock ~182~27~15 minecraft:sea_lantern
setblock ~183~27~15 minecraft:stonebrick
fill ~184~26~15 ~184~27~15 minecraft:stone
setblock ~189~25~15 minecraft:stone
setblock ~189~28~15 minecraft:stone
fill ~190~24~15 ~193~24~15 minecraft:stone_block_slab 13
fill ~190~29~15 ~193~29~15 minecraft:stone_block_slab 5
fill ~193~27~15 ~193~27~60 minecraft:stone
fill ~194~25~15 ~194~25~111 minecraft:stone
fill ~194~26~15 ~194~26~33 minecraft:stone_brick_stairs 2
fill ~194~27~15 ~194~27~33 minecraft:stone_brick_stairs 6
fill ~194~28~15 ~194~28~111 minecraft:stone
fill ~197~24~15 ~197~24~16 minecraft:stone
fill ~197~29~15 ~197~29~16 minecraft:stone
fill ~173~25~16 ~176~25~18 minecraft:stone
fill ~173~28~16 ~176~28~18 minecraft:stone
fill ~177~26~16 ~180~26~16 minecraft:stonebrick
setblock ~177~27~16 minecraft:stonebrick
setblock ~178~27~16 minecraft:stone
fill ~179~27~16 ~180~27~16 minecraft:stonebrick
setblock ~185~25~16 minecraft:stone
setblock ~185~28~16 minecraft:stone
fill ~186~24~16 ~192~24~16 minecraft:stone_block_slab 13
fill ~186~29~16 ~192~29~16 minecraft:stone_block_slab 5
fill ~193~24~16 ~196~24~17 minecraft:stone
fill ~193~29~16 ~196~29~17 minecraft:stone
fill ~169~25~17 ~172~25~19 minecraft:stone
fill ~169~28~17 ~172~28~19 minecraft:stone
fill ~173~26~17 ~174~26~17 minecraft:stone
setblock ~173~27~17 minecraft:stonebrick
setblock ~174~27~17 minecraft:sea_lantern
setblock ~175~26~17 minecraft:sea_lantern
setblock ~175~27~17 minecraft:stone
fill ~176~26~17 ~176~27~17 minecraft:stonebrick
setblock ~181~25~17 minecraft:stone
setblock ~181~28~17 minecraft:stone
fill ~182~24~17 ~188~24~17 minecraft:stone_block_slab 13
fill ~182~29~17 ~188~29~17 minecraft:stone_block_slab 5
fill ~189~24~17 ~192~24~18 minecraft:stone
fill ~189~29~17 ~192~29~18 minecraft:stone
fill ~197~23~17 ~197~23~18 minecraft:stone_block_slab 13
fill ~197~30~17 ~197~30~18 minecraft:stone_block_slab 5
fill ~165~25~18 ~168~25~20 minecraft:stone
fill ~165~28~18 ~168~28~20 minecraft:stone
fill ~169~26~18 ~169~27~18 minecraft:stone
setblock ~170~26~18 minecraft:sea_lantern
fill ~170~27~18 ~171~27~18 minecraft:stone_brick_stairs
setblock ~171~26~18 minecraft:stone
fill ~172~26~18 ~172~27~18 minecraft:stonebrick
setblock ~177~25~18 minecraft:stone
setblock ~177~28~18 minecraft:stone
fill ~178~24~18 ~184~24~18 minecraft:stone_block_slab 13
fill ~178~29~18 ~184~29~18 minecraft:stone_block_slab 5
fill ~185~24~18 ~188~24~19 minecraft:stone
fill ~185~29~18 ~188~29~19 minecraft:stone
fill ~193~23~18 ~196~23~19 minecraft:stone_block_slab 13
fill ~193~30~18 ~196~30~19 minecraft:stone_block_slab 5
fill ~195~24~18 ~195~24~106 minecraft:stone
fill ~195~29~18 ~195~29~106 minecraft:stone
fill ~196~24~18 ~196~24~33 minecraft:stone_brick_stairs 2
fill ~196~29~18 ~196~29~33 minecraft:stone_brick_stairs 6
fill ~161~25~19 ~164~25~21 minecraft:stone
fill ~161~28~19 ~164~28~21 minecraft:stone
fill ~165~26~19 ~165~27~19 minecraft:stone
fill ~166~26~19 ~167~26~19 minecraft:stone_brick_stairs
setblock ~166~27~19 minecraft:stone
setblock ~167~27~19 minecraft:stonebrick
setblock ~168~26~19 minecraft:stonebrick
setblock ~168~27~19 minecraft:stone
setblock ~173~25~19 minecraft:stone
setblock ~173~28~19 minecraft:stone
fill ~174~24~19 ~180~24~19 minecraft:stone_block_slab 13
fill ~174~29~19 ~180~29~19 minecraft:stone_block_slab 5
fill ~181~24~19 ~184~24~20 minecraft:stone
fill ~181~29~19 ~184~29~20 minecraft:stone
fill ~189~23~19 ~192~23~20 minecraft:stone_block_slab 13
fill ~189~30~19 ~192~30~20 minecraft:stone_block_slab 5
fill ~197~23~19 ~198~23~20 minecraft:stone
fill ~197~30~19 ~198~30~20 minecraft:stone
fill ~157~25~20 ~160~25~22 minecraft:stone
fill ~157~28~20 ~160~28~22 minecraft:stone
setblock ~161~26~20 minecraft:stonebrick
setblock ~161~27~20 minecraft:stone
fill ~162~26~20 ~163~27~20 minecraft:stone_brick_stairs
setblock ~164~26~20 minecraft:stone
setblock ~164~27~20 minecraft:stonebrick
setblock ~169~25~20 minecraft:stone
setblock ~169~28~20 minecraft:stone
fill ~170~24~20 ~176~24~20 minecraft:stone_block_slab 13
fill ~170~29~20 ~176~29~20 minecraft:stone_block_slab 5
fill ~177~24~20 ~180~24~21 minecraft:stone
fill ~177~29~20 ~180~29~21 minecraft:stone
fill ~185~23~20 ~188~23~21 minecraft:stone_block_slab 13
fill ~185~30~20 ~188~30~21 minecraft:stone_block_slab 5
fill ~193~23~20 ~196~23~21 minecraft:stone
fill ~193~30~20 ~196~30~21 minecraft:stone
fill ~153~25~21 ~156~25~23 minecraft:stone
fill ~153~28~21 ~156~28~23 minecraft:stone
fill ~157~26~21 ~157~27~21 minecraft:stone
fill ~158~26~21 ~159~26~21 minecraft:stone_brick_stairs
setblock ~158~27~21 minecraft:stone
setblock ~159~27~21 minecraft:stone_brick_stairs
setblock ~160~26~21 minecraft:stone
setblock ~160~27~21 minecraft:stonebrick
setblock ~165~25~21 minecraft:stone
setblock ~165~28~21 minecraft:stone
fill ~166~24~21 ~172~24~21 minecraft:stone_block_slab 13
fill ~166~29~21 ~172~29~21 minecraft:stone_block_slab 5
fill ~173~24~21 ~176~24~22 minecraft:stone
fill ~173~29~21 ~176~29~22 minecraft:stone
fill ~181~23~21 ~184~23~22 minecraft:stone_block_slab 13
fill ~181~30~21 ~184~30~22 minecraft:stone_block_slab 5
fill ~189~23~21 ~192~23~22 minecraft:stone
fill ~189~30~21 ~192~30~22 minecraft:stone
fill ~197~22~21 ~198~22~22 minecraft:stone_block_slab 13
fill ~197~23~21 ~197~23~33 minecraft:stone_brick_stairs 2
fill ~197~30~21 ~197~30~33 minecraft:stone_brick_stairs 6
fill ~197~31~21 ~198~31~22 minecraft:stone_block_slab 5
fill ~149~25~22 ~152~25~24 minecraft:stone
fill ~149~28~22 ~152~28~24 minecraft:stone
setblock ~153~26~22 minecraft:stonebrick
setblock ~153~27~22 minecraft:stone
fill ~154~26~22 ~155~26~22 minecraft:stone_brick_stairs
setblock ~154~27~22 minecraft:sea_lantern
fill ~155~27~22 ~156~27~22 minecraft:stone
setblock ~156~26~22 minecraft:stone
setblock ~161~25~22 minecraft:stone
setblock ~161~28~22 minecraft:stone
fill ~162~24~22 ~168~24~22 minecraft:stone_block_slab 13
fill ~162~29~22 ~168~29~22 minecraft:stone_block_slab 5
fill ~169~24~22 ~172~24~23 minecraft:stone
fill ~169~29~22 ~172~29~23 minecraft:stone
fill ~177~23~22 ~180~23~23 minecraft:stone_block_slab 13
fill ~177~30~22 ~180~30~23 minecraft:stone_block_slab 5
fill ~185~23~22 ~188~23~23 minecraft:stone
fill ~185~30~22 ~188~30~23 minecraft:stone
fill ~193~22~22 ~196~22~23 minecraft:stone_block_slab 13
fill ~193~31~22 ~196~31~23 minecraft:stone_block_slab 5
fill ~196~23~22 ~196~23~102 minecraft:stone
fill ~196~30~22 ~196~30~102 minecraft:stone
fill ~145~25~23 ~148~25~25 minecraft:stone
fill ~145~28~23 ~148~28~25 minecraft:stone
setblock ~149~26~23 minecraft:stone
setblock ~149~27~23 minecraft:stonebrick
fill ~150~26~23 ~150~27~23 minecraft:stone_brick_stairs
setblock ~151~26~23 minecraft:sea_lantern
setblock ~151~27~23 minecraft:stone_brick_stairs
fill ~152~26~23 ~152~27~23 minecraft:stone
setblock ~157~25~23 minecraft:stone
setblock ~157~28~23 minecraft:stone
fill ~158~24~23 ~164~24~23 minecraft:stone_block_slab 13
fill ~158~29~23 ~164~29~23 minecraft:stone_block_slab 5
fill ~165~24~23 ~168~24~24 minecraft:stone
fill ~165~29~23 ~168~29~24 minecraft:stone
fill ~173~23~23 ~176~23~24 minecraft:stone_block_slab 13
fill ~173~30~23 ~176~30~24 minecraft:stone_block_slab 5
fill ~181~23~23 ~184~23~24 minecraft:stone
fill ~181~30~23 ~184~30~24 minecraft:stone
fill ~189~22~23 ~192~22~24 minecraft:stone_block_slab 13
fill ~189~31~23 ~192~31~24 minecraft:stone_block_slab 5
fill ~197~22~23 ~199~22~24 minecraft:stone
fill ~197~31~23 ~199~31~24 minecraft:stone
fill ~141~25~24 ~144~25~26 minecraft:stone
fill ~141~28~24 ~144~28~26 minecraft:stone
fill ~145~26~24 ~145~27~24 minecraft:stonebrick
fill ~146~26~24 ~147~26~24 minecraft:stone
fill ~146~27~24 ~147~27~24 minecraft:stone_brick_stairs
setblock ~148~26~24 minecraft:stonebrick
setblock ~148~27~24 minecraft:sea_lantern
setblock ~153~25~24 minecraft:stone
setblock ~153~28~24 minecraft:stone
fill ~154~24~24 ~160~24~24 minecraft:stone_block_slab 13
fill ~154~29~24 ~160~29~24 minecraft:stone_block_slab 5
fill ~161~24~24 ~164~24~25 minecraft:stone
fill ~161~29~24 ~164~29~25 minecraft:stone
fill ~169~23~24 ~172~23~25 minecraft:stone_block_slab 13
fill ~169~30~24 ~172~30~25 minecraft:stone_block_slab 5
fill ~177~23~24 ~180~23~25 minecraft:stone
fill ~177~30~24 ~180~30~25 minecraft:stone
fill ~185~22~24 ~188~22~25 minecraft:stone_block_slab 13
fill ~185~31~24 ~188~31~25 minecraft:stone_block_slab 5
fill ~193~22~24 ~196~22~25 minecraft:stone
fill ~193~31~24 ~196~31~25 minecraft:stone
fill ~137~25~25 ~140~25~27 minecraft:stone
fill ~137~28~25 ~140~28~27 minecraft:stone
setblock ~141~26~25 minecraft:stone
setblock ~141~27~25 minecraft:stonebrick
fill ~142~26~25 ~143~26~25 minecraft:stone_brick_stairs
setblock ~142~27~25 minecraft:stone_brick_stairs
fill ~143~27~25 ~144~27~25 minecraft:stonebrick
setblock ~144~26~25 minecraft:stone
setblock ~149~25~25 minecraft:stone
setblock ~149~28~25 minecraft:stone
fill ~150~24~25 ~156~24~25 minecraft:stone_block_slab 13
fill ~150~29~25 ~156~29~25 minecraft:stone_block_slab 5
fill ~157~24~25 ~160~24~26 minecraft:stone
fill ~157~29~25 ~160~29~26 minecraft:stone
fill ~165~23~25 ~168~23~26 minecraft:stone_block_slab 13
fill ~165~30~25 ~168~30~26 minecraft:stone_block_slab 5
fill ~173~23~25 ~176~23~26 minecraft:stone
fill ~173~30~25 ~176~30~26 minecraft:stone
fill ~181~22~25 ~184~22~26 minecraft:stone_block_slab 13
fill ~181~31~25 ~184~31~26 minecraft:stone_block_slab 5
fill ~189~22~25 ~192~22~26 minecraft:stone
fill ~189~31~25 ~192~31~26 minecraft:stone
fill ~197~21~25 ~199~21~26 minecraft:stone_block_slab 13
fill ~197~22~25 ~197~22~99 minecraft:stone
fill ~197~31~25 ~197~31~99 minecraft:stone
fill ~197~32~25 ~199~32~26 minecraft:stone_block_slab 5
fill ~198~22~25 ~198~22~33 minecraft:stone_brick_stairs 2
fill ~198~31~25 ~198~31~33 minecraft:stone_brick_stairs 6
fill ~133~25~26 ~136~25~28 minecraft:stone
fill ~133~28~26 ~136~28~28 minecraft:stone
fill ~137~26~26 ~137~27~26 minecraft:stone
setblock ~138~26~26 minecraft:stonebrick
fill ~138~27~26 ~139~27~26 minecraft:stone_brick_stairs
setblock ~139~26~26 minecraft:sea_lantern
fill ~140~26~26 ~140~27~26 minecraft:stone
setblock ~145~25~26 minecraft:stone
setblock ~145~28~26 minecraft:stone
fill ~146~24~26 ~152~24~26 minecraft:stone_block_slab 13
fill ~146~29~26 ~152~29~26 minecraft:stone_block_slab 5
fill ~153~24~26 ~156~24~27 minecraft:stone
fill ~153~29~26 ~156~29~27 minecraft:stone
fill ~161~23~26 ~164~23~27 minecraft:stone_block_slab 13
fill ~161~30~26 ~164~30~27 minecraft:stone_block_slab 5
fill ~169~23~26 ~172~23~27 minecraft:stone
fill ~169~30~26 ~172~30~27 minecraft:stone
fill ~177~22~26 ~180~22~27 minecraft:stone_block_slab 13
fill ~177~31~26 ~180~31~27 minecraft:stone_block_slab 5
fill ~185~22~26 ~188~22~27 minecraft:stone
fill ~185~31~26 ~188~31~27 minecraft:stone
fill ~193~21~26 ~196~21~27 minecraft:stone_block_slab 13
fill ~193~32~26 ~196~32~27 minecraft:stone_block_slab 5
fill ~129~25~27 ~132~25~29 minecraft:stone
fill ~129~28~27 ~132~28~29 minecraft:stone
fill ~133~26~27 ~134~27~27 minecraft:stone
setblock ~135~26~27 minecraft:sea_lantern
fill ~135~27~27 ~136~27~27 minecraft:stone
setblock ~136~26~27 minecraft:stone
setblock ~141~25~27 minecraft:stone
setblock ~141~28~27 minecraft:stone
fill ~142~24~27 ~148~24~27 minecraft:stone_block_slab 13
fill ~142~29~27 ~148~29~27 minecraft:stone_block_slab 5
fill ~149~24~27 ~152~24~28 minecraft:stone
fill ~149~29~27 ~152~29~28 minecraft:stone
fill ~157~23~27 ~160~23~28 minecraft:stone_block_slab 13
fill ~157~30~27 ~160~30~28 minecraft:stone_block_slab 5
fill ~165~23~27 ~168~23~28 minecraft:stone
fill ~165~30~27 ~168~30~28 minecraft:stone
fill ~173~22~27 ~176~22~28 minecraft:stone_block_slab 13
fill ~173~31~27 ~176~31~28 minecraft:stone_block_slab 5
fill ~181~22~27 ~184~22~28 minecraft:stone
fill ~181~31~27 ~184~31~28 minecraft:stone
fill ~189~21~27 ~192~21~28 minecraft:stone_block_slab 13
fill ~189~32~27 ~192~32~28 minecraft:stone_block_slab 5
fill ~197~21~27 ~200~21~28 minecraft:stone
fill ~197~32~27 ~200~32~28 minecraft:stone
fill ~125~25~28 ~128~25~30 minecraft:stone
fill ~125~28~28 ~128~28~30 minecraft:stone
fill ~129~26~28 ~129~27~28 minecraft:stone
setblock ~130~26~28 minecraft:sea_lantern
fill ~130~27~28 ~131~27~28 minecraft:stonebrick
setblock ~131~26~28 minecraft:stonebrick
setblock ~132~26~28 minecraft:stone
setblock ~132~27~28 minecraft:sea_lantern
setblock ~137~25~28 minecraft:stone
setblock ~137~28~28 minecraft:stone
fill ~138~24~28 ~144~24~28 minecraft:stone_block_slab 13
fill ~138~29~28 ~144~29~28 minecraft:stone_block_slab 5
fill ~145~24~28 ~148~24~29 minecraft:stone
fill ~145~29~28 ~148~29~29 minecraft:stone
fill ~153~23~28 ~156~23~29 minecraft:stone_block_slab 13
fill ~153~30~28 ~156~30~29 minecraft:stone_block_slab 5
fill ~161~23~28 ~164~23~29 minecraft:stone
fill ~161~30~28 ~164~30~29 minecraft:stone
fill ~163~51~28 ~163~54~28 minecraft:stone 6
fill ~164~49~28 ~166~49~28 minecraft:stone 6
setblock ~164~50~28 minecraft:stone 6
fill ~164~51~28 ~166~51~28 minecraft:concrete 7
fill ~164~52~28 ~164~54~28 minecraft:concrete 7
fill ~164~55~28 ~164~56~28 minecraft:stone 6
setblock ~165~50~28 minecraft:concrete 7
fill ~165~52~28 ~165~53~28 minecraft:stone 6
fill ~165~54~28 ~166~54~28 minecraft:concrete 7
setblock ~165~55~28 minecraft:concrete 7
fill ~165~56~28 ~166~56~28 minecraft:stone 6
setblock ~166~50~28 minecraft:stone 6
fill ~166~52~28 ~166~53~28 minecraft:concrete 7
setblock ~166~55~28 minecraft:stone 6
fill ~167~51~28 ~167~54~28 minecraft:stone 6
fill ~169~22~28 ~172~22~29 minecraft:stone_block_slab 13
fill ~169~31~28 ~172~31~29 minecraft:stone_block_slab 5
fill ~177~22~28 ~180~22~29 minecraft:stone
fill ~177~31~28 ~180~31~29 minecraft:stone
fill ~185~21~28 ~188~21~29 minecraft:stone_block_slab 13
fill ~185~32~28 ~188~32~29 minecraft:stone_block_slab 5
fill ~193~21~28 ~196~21~29 minecraft:stone
fill ~193~32~28 ~196~32~29 minecraft:stone
fill ~124~25~29 ~124~25~35 minecraft:stone
fill ~124~28~29 ~124~28~35 minecraft:stone
fill ~125~26~29 ~125~27~29 minecraft:stonebrick
fill ~126~26~29 ~127~27~29 minecraft:stone_brick_stairs
fill ~128~26~29 ~128~27~29 minecraft:stone
setblock ~133~25~29 minecraft:stone
setblock ~133~28~29 minecraft:stone
fill ~134~24~29 ~140~24~29 minecraft:stone_block_slab 13
fill ~134~29~29 ~140~29~29 minecraft:stone_block_slab 5
fill ~141~24~29 ~144~24~30 minecraft:stone
fill ~141~29~29 ~144~29~30 minecraft:stone
fill ~149~23~29 ~152~23~30 minecraft:stone_block_slab 13
fill ~149~30~29 ~152~30~30 minecraft:stone_block_slab 5
fill ~157~23~29 ~160~23~30 minecraft:stone
fill ~157~30~29 ~160~30~30 minecraft:stone
fill ~165~22~29 ~168~22~30 minecraft:stone_block_slab 13
fill ~165~31~29 ~168~31~30 minecraft:stone_block_slab 5
setblock ~165~52~29 minecraft:stone_block_slab 13
fill ~173~22~29 ~176~22~30 minecraft:stone
fill ~173~31~29 ~176~31~30 minecraft:stone
fill ~181~21~29 ~184~21~30 minecraft:stone_block_slab 13
fill ~181~32~29 ~184~32~30 minecraft:stone_block_slab 5
fill ~189~21~29 ~192~21~30 minecraft:stone
fill ~189~32~29 ~192~32~30 minecraft:stone
fill ~197~20~29 ~200~20~30 minecraft:stone_block_slab 13
fill ~197~33~29 ~200~33~30 minecraft:stone_block_slab 5
fill ~198~21~29 ~198~21~95 minecraft:stone
fill ~198~32~29 ~198~32~95 minecraft:stone
fill ~199~21~29 ~199~21~33 minecraft:stone_brick_stairs 2
fill ~199~32~29 ~199~32~33 minecraft:stone_brick_stairs 6
fill ~117~25~30 ~118~25~33 minecraft:stone
fill ~117~28~30 ~118~28~33 minecraft:stone
setblock ~125~26~30 minecraft:stone
setblock ~125~27~30 minecraft:sea_lantern
setblock ~129~25~30 minecraft:stone
setblock ~129~28~30 minecraft:stone
fill ~130~24~30 ~136~24~30 minecraft:stone_block_slab 13
fill ~130~29~30 ~136~29~30 minecraft:stone_block_slab 5
fill ~137~24~30 ~140~24~31 minecraft:stone
fill ~137~29~30 ~140~29~31 minecraft:stone
fill ~145~23~30 ~148~23~31 minecraft:stone_block_slab 13
fill ~145~30~30 ~148~30~31 minecraft:stone_block_slab 5
fill ~153~23~30 ~156~23~31 minecraft:stone
fill ~153~30~30 ~156~30~31 minecraft:stone
fill ~161~22~30 ~164~22~31 minecraft:stone_block_slab 13
fill ~161~31~30 ~164~31~31 minecraft:stone_block_slab 5
fill ~165~52~30 ~165~52~31 minecraft:stone 6
setblock ~165~53~30 minecraft:stone_block_slab 5
fill ~169~22~30 ~172~22~31 minecraft:stone
fill ~169~31~30 ~172~31~31 minecraft:stone
fill ~177~21~30 ~180~21~31 minecraft:stone_block_slab 13
fill ~177~32~30 ~180~32~31 minecraft:stone_block_slab 5
fill ~185~21~30 ~188~21~31 minecraft:stone
fill ~185~32~30 ~188~32~31 minecraft:stone
fill ~193~20~30 ~196~20~31 minecraft:stone_block_slab 13
fill ~193~33~30 ~196~33~31 minecraft:stone_block_slab 5
fill ~113~25~31 ~116~25~33 minecraft:stone
fill ~113~28~31 ~116~28~33 minecraft:stone
fill ~117~26~31 ~117~27~31 minecraft:stonebrick
fill ~125~25~31 ~125~25~32 minecraft:stone
fill ~125~26~31 ~125~27~31 minecraft:stonebrick
fill ~125~28~31 ~125~28~32 minecraft:stone
fill ~126~24~31 ~132~24~31 minecraft:stone_block_slab 13
fill ~126~29~31 ~132~29~31 minecraft:stone_block_slab 5
fill ~133~24~31 ~136~24~32 minecraft:stone
fill ~133~29~31 ~136~29~32 minecraft:stone
fill ~141~23~31 ~144~23~32 minecraft:stone_block_slab 13
fill ~141~30~31 ~144~30~32 minecraft:stone_block_slab 5
fill ~149~23~31 ~152~23~32 minecraft:stone
fill ~149~30~31 ~152~30~32 minecraft:stone
fill ~157~22~31 ~160~22~32 minecraft:stone_block_slab 13
fill ~157~31~31 ~160~31~32 minecraft:stone_block_slab 5
fill ~164~34~31 ~164~34~33 minecraft:stone_block_slab 
setblock ~164~52~31 minecraft:stone 6
fill ~165~22~31 ~168~22~32 minecraft:stone
fill ~165~31~31 ~168~31~32 minecraft:stone
setblock ~165~51~31 minecraft:stone 6
fill ~165~53~31 ~165~53~33 minecraft:stone 6
fill ~166~34~31 ~166~34~33 minecraft:stone_block_slab 
setblock ~166~52~31 minecraft:stone 6
fill ~170~34~31 ~170~34~33 minecraft:stone_block_slab 
fill ~172~34~31 ~172~34~33 minecraft:stone_block_slab 
fill ~173~21~31 ~176~21~32 minecraft:stone_block_slab 13
fill ~173~32~31 ~176~32~31 minecraft:stone_block_slab 5
fill ~176~34~31 ~176~34~33 minecraft:stone_block_slab 
fill ~178~34~31 ~178~34~33 minecraft:stone_block_slab 
fill ~181~21~31 ~184~21~32 minecraft:stone
fill ~181~32~31 ~184~32~32 minecraft:stone
fill ~182~34~31 ~182~34~33 minecraft:stone_block_slab 
fill ~184~34~31 ~184~34~33 minecraft:stone_block_slab 
fill ~189~20~31 ~192~20~32 minecraft:stone_block_slab 13
fill ~189~33~31 ~192~33~32 minecraft:stone_block_slab 5
fill ~197~20~31 ~201~20~32 minecraft:stone
fill ~197~33~31 ~201~33~32 minecraft:stone
fill ~109~25~32 ~112~25~34 minecraft:stone
fill ~109~28~32 ~112~28~34 minecraft:stone
fill ~113~26~32 ~113~27~32 minecraft:stone
fill ~114~26~32 ~115~26~32 minecraft:stone_brick_stairs
setblock ~114~27~32 minecraft:stone
fill ~115~27~32 ~116~27~32 minecraft:stone_brick_stairs
setblock ~116~26~32 minecraft:sea_lantern
setblock ~118~26~32 minecraft:stone
setblock ~118~27~32 minecraft:stonebrick
fill ~119~25~32 ~119~25~34 minecraft:stone
fill ~119~28~32 ~119~28~34 minecraft:stone
fill ~124~24~32 ~128~24~32 minecraft:stone_block_slab 13
fill ~124~29~32 ~128~29~32 minecraft:stone_block_slab 5
setblock ~125~26~32 minecraft:sea_lantern
setblock ~125~27~32 minecraft:stonebrick
fill ~129~24~32 ~132~24~33 minecraft:stone
fill ~129~29~32 ~132~29~33 minecraft:stone
fill ~137~23~32 ~140~23~33 minecraft:stone_block_slab 13
fill ~137~30~32 ~140~30~33 minecraft:stone_block_slab 5
fill ~145~23~32 ~148~23~33 minecraft:stone
fill ~145~30~32 ~148~30~33 minecraft:stone
fill ~153~22~32 ~156~22~33 minecraft:stone_block_slab 13
fill ~153~31~32 ~156~31~33 minecraft:stone_block_slab 5
fill ~161~22~32 ~164~22~33 minecraft:stone
fill ~161~31~32 ~164~31~33 minecraft:stone
fill ~164~32~32 ~166~32~36 minecraft:stone
fill ~164~33~32 ~166~33~32 minecraft:stone_brick_stairs
setblock ~164~51~32 minecraft:stone 6
fill ~164~52~32 ~166~52~32 minecraft:stained_glass 15
setblock ~164~53~32 minecraft:stone 6
setblock ~164~54~32 minecraft:iron_bars
setblock ~165~50~32 minecraft:iron_trapdoor 7
setblock ~165~51~32 minecraft:sea_lantern
setblock ~165~54~32 minecraft:stone_block_slab 5
setblock ~166~51~32 minecraft:stone 6
setblock ~166~53~32 minecraft:stone 6
fill ~169~21~32 ~172~21~33 minecraft:stone_block_slab 13
fill ~169~32~32 ~169~32~33 minecraft:stone_block_slab 5
fill ~170~32~32 ~172~32~35 minecraft:stone
fill ~170~33~32 ~172~33~32 minecraft:stone_brick_stairs
fill ~173~32~32 ~175~32~32 minecraft:stone_block_slab 5
fill ~176~32~32 ~180~32~33 minecraft:stone
fill ~176~33~32 ~178~33~32 minecraft:stone_brick_stairs
fill ~177~21~32 ~180~21~33 minecraft:stone
fill ~182~33~32 ~184~33~32 minecraft:stone_brick_stairs
fill ~185~20~32 ~188~20~33 minecraft:stone_block_slab 13
fill ~185~33~32 ~188~33~32 minecraft:stone_block_slab 5
fill ~193~20~32 ~196~20~33 minecraft:stone
fill ~193~33~32 ~196~33~33 minecraft:stone
setblock ~201~34~32 minecraft:snow_layer
fill ~105~25~33 ~108~25~35 minecraft:stone
fill ~105~28~33 ~108~28~35 minecraft:stone
fill ~109~26~33 ~109~27~33 minecraft:stone
fill ~110~26~33 ~110~27~33 minecraft:stonebrick
fill ~111~26~33 ~112~26~33 minecraft:stone
setblock ~111~27~33 minecraft:sea_lantern
setblock ~112~27~33 minecraft:stone
fill ~117~24~33 ~124~24~33 minecraft:stone_block_slab 13
fill ~117~29~33 ~124~29~33 minecraft:stone_block_slab 5
fill ~119~26~33 ~119~27~33 minecraft:stonebrick
fill ~120~25~33 ~123~25~35 minecraft:stone
fill ~120~28~33 ~123~28~35 minecraft:stone
fill ~125~24~33 ~128~24~34 minecraft:stone
fill ~125~26~33 ~125~27~34 minecraft:stone
fill ~125~29~33 ~128~29~34 minecraft:stone
fill ~133~23~33 ~136~23~34 minecraft:stone_block_slab 13
fill ~133~30~33 ~136~30~34 minecraft:stone_block_slab 5
fill ~141~23~33 ~144~23~34 minecraft:stone
fill ~141~30~33 ~144~30~34 minecraft:stone
fill ~149~22~33 ~152~22~34 minecraft:stone_block_slab 13
fill ~149~31~33 ~152~31~34 minecraft:stone_block_slab 5
fill ~157~22~33 ~160~22~34 minecraft:stone
fill ~157~31~33 ~160~31~34 minecraft:stone
fill ~164~33~33 ~166~33~35 minecraft:stone
fill ~164~52~33 ~166~52~33 minecraft:stone 6
setblock ~164~53~33 minecraft:cobblestone_wall
setblock ~164~54~33 minecraft:cobblestone_wall 
setblock ~164~55~33 minecraft:iron_bars
fill ~165~21~33 ~168~21~34 minecraft:stone_block_slab 13
setblock ~165~34~33 minecraft:stone_block_slab 5
setblock ~165~51~33 minecraft:stone 6
fill ~167~32~33 ~168~32~34 minecraft:stone_block_slab 5
fill ~170~33~33 ~172~33~35 minecraft:stone
setblock ~171~34~33 minecraft:stone_block_slab 5
fill ~173~21~33 ~176~21~34 minecraft:stone
fill ~173~32~33 ~175~32~34 minecraft:stone
fill ~176~33~33 ~178~33~35 minecraft:stone
setblock ~177~34~33 minecraft:stone_block_slab 5
fill ~181~20~33 ~184~20~34 minecraft:stone_block_slab 13
fill ~181~33~33 ~181~33~34 minecraft:stone_block_slab 5
fill ~182~33~33 ~184~33~36 minecraft:stone
setblock ~183~34~33 minecraft:stone_block_slab 5
fill ~185~33~33 ~186~33~33 minecraft:stone_block_slab 5
fill ~187~33~33 ~192~33~34 minecraft:stone
fill ~187~34~33 ~187~34~39 minecraft:stone
fill ~187~35~33 ~197~35~34 minecraft:stone_block_slab 5
setblock ~188~34~33 minecraft:sea_lantern
fill ~189~20~33 ~192~20~34 minecraft:stone
fill ~189~34~33 ~190~34~33 minecraft:stone
fill ~191~34~33 ~192~34~33 minecraft:sea_lantern
fill ~193~34~33 ~194~34~33 minecraft:stone
setblock ~195~34~33 minecraft:sea_lantern
fill ~196~34~33 ~197~34~33 minecraft:stone
fill ~197~19~33 ~202~19~34 minecraft:stone_block_slab 13
fill ~198~34~33 ~202~34~34 minecraft:stone_block_slab 5
fill ~199~20~33 ~199~20~91 minecraft:stone
fill ~199~33~33 ~199~33~91 minecraft:stone
setblock ~200~20~33 minecraft:stone_brick_stairs 2
setblock ~200~33~33 minecraft:stone_brick_stairs 6
fill ~101~25~34 ~104~25~36 minecraft:stone
fill ~101~28~34 ~104~28~36 minecraft:stone
fill ~105~26~34 ~106~26~34 minecraft:stonebrick
setblock ~105~27~34 minecraft:stone
fill ~106~27~34 ~107~27~34 minecraft:stone_brick_stairs
setblock ~107~26~34 minecraft:sea_lantern
fill ~108~26~34 ~108~27~34 minecraft:stonebrick
fill ~113~24~34 ~120~24~34 minecraft:stone_block_slab 13
fill ~113~29~34 ~120~29~34 minecraft:stone_block_slab 5
setblock ~120~26~34 minecraft:stonebrick
fill ~120~27~34 ~121~27~34 minecraft:stone_brick_stairs
fill ~121~24~34 ~124~24~35 minecraft:stone
fill ~121~26~34 ~123~26~34 minecraft:stone_brick_stairs
fill ~121~29~34 ~124~29~35 minecraft:stone
setblock ~122~27~34 minecraft:sea_lantern
setblock ~123~27~34 minecraft:stonebrick
setblock ~124~26~34 minecraft:stonebrick
setblock ~124~27~34 minecraft:stone
fill ~129~23~34 ~132~23~35 minecraft:stone_block_slab 13
fill ~129~30~34 ~132~30~35 minecraft:stone_block_slab 5
fill ~137~23~34 ~140~23~35 minecraft:stone
fill ~137~30~34 ~140~30~35 minecraft:stone
fill ~145~22~34 ~148~22~35 minecraft:stone_block_slab 13
fill ~145~31~34 ~148~31~35 minecraft:stone_block_slab 5
fill ~153~22~34 ~156~22~35 minecraft:stone
fill ~153~31~34 ~156~31~35 minecraft:stone
fill ~161~21~34 ~164~21~35 minecraft:stone_block_slab 13
fill ~161~32~34 ~163~32~35 minecraft:stone_block_slab 5
setblock ~164~34~34 minecraft:stone_brick_stairs
setblock ~165~34~34 minecraft:stone
setblock ~165~52~34 minecraft:stone 6
setblock ~165~53~34 minecraft:stone_block_slab 5
setblock ~166~34~34 minecraft:stone_brick_stairs
fill ~169~21~34 ~172~21~35 minecraft:stone
fill ~169~32~34 ~169~32~35 minecraft:stone
setblock ~170~34~34 minecraft:stone_brick_stairs
setblock ~171~34~34 minecraft:stone
setblock ~172~34~34 minecraft:stone_brick_stairs
setblock ~176~32~34 minecraft:stone
setblock ~176~34~34 minecraft:stone_brick_stairs
fill ~177~20~34 ~180~20~35 minecraft:stone_block_slab 13
setblock ~177~34~34 minecraft:stone
setblock ~178~34~34 minecraft:stone_brick_stairs
fill ~179~33~34 ~180~33~35 minecraft:stone_block_slab 5
setblock ~182~34~34 minecraft:stone_brick_stairs
setblock ~183~34~34 minecraft:stone
setblock ~184~34~34 minecraft:stone_brick_stairs
fill ~185~20~34 ~188~20~35 minecraft:stone
fill ~185~33~34 ~186~33~35 minecraft:stone
fill ~193~19~34 ~196~19~35 minecraft:stone_block_slab 13
fill ~193~34~34 ~196~34~35 minecraft:stone_block_slab 5
fill ~194~26~34 ~194~27~34 minecraft:stonebrick
setblock ~195~25~34 minecraft:stonebrick
setblock ~195~28~34 minecraft:stonebrick
setblock ~196~24~34 minecraft:stonebrick
setblock ~196~29~34 minecraft:stonebrick
setblock ~197~23~34 minecraft:stonebrick
setblock ~197~30~34 minecraft:stonebrick
fill ~197~34~34 ~197~34~36 minecraft:stone
setblock ~198~22~34 minecraft:stonebrick
setblock ~198~31~34 minecraft:stonebrick
setblock ~199~21~34 minecraft:stonebrick
setblock ~199~32~34 minecraft:stonebrick
setblock ~200~20~34 minecraft:stonebrick
setblock ~200~33~34 minecraft:stonebrick
fill ~97~25~35 ~100~25~37 minecraft:stone
fill ~97~28~35 ~100~28~37 minecraft:stone
setblock ~101~26~35 minecraft:stonebrick
fill ~101~27~35 ~102~27~35 minecraft:stone
setblock ~102~26~35 minecraft:stone
fill ~103~26~35 ~104~26~35 minecraft:stonebrick
setblock ~103~27~35 minecraft:sea_lantern
setblock ~104~27~35 minecraft:stonebrick
fill ~109~24~35 ~116~24~35 minecraft:stone_block_slab 13
fill ~109~29~35 ~116~29~35 minecraft:stone_block_slab 5
fill ~117~24~35 ~120~24~36 minecraft:stone
fill ~117~29~35 ~120~29~36 minecraft:stone
fill ~125~23~35 ~128~23~36 minecraft:stone_block_slab 13
fill ~125~30~35 ~128~30~36 minecraft:stone_block_slab 5
fill ~133~23~35 ~136~23~36 minecraft:stone
fill ~133~30~35 ~136~30~36 minecraft:stone
fill ~141~22~35 ~144~22~36 minecraft:stone_block_slab 13
fill ~141~31~35 ~144~31~36 minecraft:stone_block_slab 5
fill ~149~22~35 ~152~22~36 minecraft:stone
fill ~149~31~35 ~152~31~36 minecraft:stone
fill ~157~21~35 ~160~21~36 minecraft:stone_block_slab 13
fill ~157~32~35 ~160~32~36 minecraft:stone_block_slab 5
setblock ~164~34~35 minecraft:stone_brick_stairs 1
fill ~165~21~35 ~168~21~36 minecraft:stone
setblock ~165~52~35 minecraft:stone_block_slab 13
setblock ~166~34~35 minecraft:stone_brick_stairs 1
fill ~167~32~35 ~168~32~36 minecraft:stone
setblock ~170~34~35 minecraft:stone_brick_stairs 1
setblock ~172~34~35 minecraft:stone_brick_stairs 1
fill ~173~20~35 ~176~20~36 minecraft:stone_block_slab 13
fill ~173~33~35 ~175~33~36 minecraft:stone_block_slab 5
setblock ~176~34~35 minecraft:stone_brick_stairs 1
setblock ~178~34~35 minecraft:stone_brick_stairs 1
fill ~181~20~35 ~184~20~36 minecraft:stone
fill ~181~33~35 ~181~33~36 minecraft:stone
setblock ~182~34~35 minecraft:stone_brick_stairs 1
setblock ~184~34~35 minecraft:stone_brick_stairs 1
fill ~187~33~35 ~188~33~35 minecraft:stone
fill ~187~35~35 ~197~35~36 minecraft:stone
fill ~189~19~35 ~192~19~36 minecraft:stone_block_slab 13
fill ~189~34~35 ~192~34~36 minecraft:stone_block_slab 5
setblock ~194~26~35 minecraft:stone_brick_stairs 2
setblock ~194~27~35 minecraft:stone_brick_stairs 6
setblock ~195~25~35 minecraft:stone_brick_stairs 2
setblock ~195~28~35 minecraft:stone_brick_stairs 6
fill ~196~24~35 ~196~24~36 minecraft:stone_brick_stairs 2
setblock ~196~29~35 minecraft:stone_brick_stairs 6
fill ~197~19~35 ~202~19~36 minecraft:stone
fill ~197~23~35 ~197~23~37 minecraft:stone_brick_stairs 2
fill ~197~30~35 ~197~30~36 minecraft:stone_brick_stairs 6
fill ~198~22~35 ~198~22~38 minecraft:stone_brick_stairs 2
fill ~198~31~35 ~198~31~37 minecraft:stone_brick_stairs 6
fill ~198~34~35 ~202~34~36 minecraft:stone
fill ~199~21~35 ~199~21~48 minecraft:stone_brick_stairs 2
fill ~199~32~35 ~199~32~39 minecraft:stone_brick_stairs 6
fill ~200~20~35 ~200~20~49 minecraft:stone_brick_stairs 2
fill ~200~33~35 ~200~33~49 minecraft:stone_brick_stairs 6
fill ~205~25~35 ~205~29~36 minecraft:stone
fill ~93~25~36 ~96~25~38 minecraft:stone
fill ~93~28~36 ~96~28~38 minecraft:stone
fill ~97~26~36 ~97~27~36 minecraft:stone
setblock ~98~26~36 minecraft:stonebrick
fill ~98~27~36 ~99~27~36 minecraft:stone_brick_stairs
setblock ~99~26~36 minecraft:sea_lantern
fill ~100~26~36 ~100~27~36 minecraft:stone
fill ~105~24~36 ~112~24~36 minecraft:stone_block_slab 13
fill ~105~29~36 ~112~29~36 minecraft:stone_block_slab 5
fill ~113~24~36 ~116~24~37 minecraft:stone
fill ~113~29~36 ~116~29~37 minecraft:stone
fill ~121~23~36 ~124~23~37 minecraft:stone_block_slab 13
fill ~121~30~36 ~124~30~37 minecraft:stone_block_slab 5
fill ~124~5~36 ~124~7~36 minecraft:wool 8
fill ~125~5~36 ~126~7~36 minecraft:wool 15
fill ~127~5~36 ~127~7~36 minecraft:wool 8
fill ~129~23~36 ~132~23~37 minecraft:stone
fill ~129~30~36 ~132~30~37 minecraft:stone
fill ~137~22~36 ~140~22~37 minecraft:stone_block_slab 13
fill ~137~31~36 ~140~31~37 minecraft:stone_block_slab 5
fill ~145~22~36 ~148~22~37 minecraft:stone
fill ~145~31~36 ~148~31~37 minecraft:stone
fill ~153~21~36 ~156~21~37 minecraft:stone_block_slab 13
fill ~153~32~36 ~156~32~37 minecraft:stone_block_slab 5
fill ~161~21~36 ~164~21~37 minecraft:stone
fill ~161~32~36 ~163~32~37 minecraft:stone
fill ~163~51~36 ~163~54~36 minecraft:stone 6
fill ~164~49~36 ~166~49~36 minecraft:stone 6
setblock ~164~50~36 minecraft:stone 6
fill ~164~51~36 ~166~51~36 minecraft:concrete 7
fill ~164~52~36 ~164~54~36 minecraft:concrete 7
fill ~164~55~36 ~164~56~36 minecraft:stone 6
setblock ~165~50~36 minecraft:concrete 7
fill ~165~52~36 ~165~53~36 minecraft:stone 6
fill ~165~54~36 ~166~54~36 minecraft:concrete 7
setblock ~165~55~36 minecraft:concrete 7
fill ~165~56~36 ~166~56~36 minecraft:stone 6
setblock ~166~50~36 minecraft:stone 6
fill ~166~52~36 ~166~53~36 minecraft:concrete 7
setblock ~166~55~36 minecraft:stone 6
fill ~167~51~36 ~167~54~36 minecraft:stone 6
fill ~169~20~36 ~172~20~37 minecraft:stone_block_slab 13
fill ~169~33~36 ~172~33~37 minecraft:stone_block_slab 5
setblock ~176~33~36 minecraft:stone_block_slab 5
fill ~177~20~36 ~180~20~37 minecraft:stone
fill ~177~33~36 ~180~33~37 minecraft:stone
fill ~185~19~36 ~188~19~37 minecraft:stone_block_slab 13
fill ~185~34~36 ~186~34~37 minecraft:stone_block_slab 5
fill ~188~34~36 ~188~34~37 minecraft:stone_block_slab 5
fill ~193~19~36 ~196~19~37 minecraft:stone
fill ~193~34~36 ~196~34~37 minecraft:stone
fill ~194~26~36 ~202~27~36 minecraft:stone
fill ~195~25~36 ~202~25~36 minecraft:stone
fill ~195~28~36 ~202~28~36 minecraft:stone
fill ~196~29~36 ~202~29~36 minecraft:stone
fill ~203~25~36 ~203~29~36 minecraft:stonebrick
fill ~204~25~36 ~204~29~36 minecraft:stone
fill ~205~24~36 ~205~24~37 minecraft:stone
fill ~205~30~36 ~205~30~37 minecraft:stone
fill ~206~25~36 ~207~29~36 minecraft:stone
fill ~89~25~37 ~92~25~39 minecraft:stone
fill ~89~28~37 ~92~28~39 minecraft:stone
fill ~93~26~37 ~93~27~37 minecraft:stonebrick
setblock ~94~26~37 minecraft:stone
setblock ~94~27~37 minecraft:sea_lantern
setblock ~95~26~37 minecraft:sea_lantern
fill ~95~27~37 ~96~27~37 minecraft:stonebrick
setblock ~96~26~37 minecraft:stone
fill ~101~24~37 ~108~24~37 minecraft:stone_block_slab 13
fill ~101~29~37 ~108~29~37 minecraft:stone_block_slab 5
fill ~109~24~37 ~112~24~38 minecraft:stone
fill ~109~29~37 ~112~29~38 minecraft:stone
fill ~114~4~37 ~115~4~37 minecraft:wool 7
fill ~114~8~37 ~115~8~37 minecraft:wool 7
fill ~116~4~37 ~127~4~37 minecraft:wool 8
fill ~116~8~37 ~127~8~37 minecraft:wool 8
setblock ~117~3~37 minecraft:wool 8
setblock ~117~9~37 minecraft:wool 8
fill ~117~23~37 ~120~23~38 minecraft:stone_block_slab 13
fill ~117~30~37 ~120~30~38 minecraft:stone_block_slab 5
fill ~118~3~37 ~122~3~37 minecraft:wool 15
fill ~118~9~37 ~122~9~37 minecraft:wool 15
setblock ~123~3~37 minecraft:wool 8
setblock ~123~9~37 minecraft:wool 8
fill ~124~3~37 ~126~3~37 minecraft:wool 15
fill ~124~6~37 ~124~6~39 minecraft:wool 7
fill ~124~9~37 ~126~9~37 minecraft:wool 15
fill ~125~23~37 ~128~23~38 minecraft:stone
fill ~125~30~37 ~128~30~38 minecraft:stone
setblock ~127~3~37 minecraft:wool 8
setblock ~127~9~37 minecraft:wool 8
fill ~133~22~37 ~136~22~38 minecraft:stone_block_slab 13
fill ~133~31~37 ~136~31~38 minecraft:stone_block_slab 5
fill ~141~22~37 ~144~22~38 minecraft:stone
fill ~141~31~37 ~144~31~38 minecraft:stone
fill ~149~21~37 ~152~21~38 minecraft:stone_block_slab 13
fill ~149~32~37 ~152~32~38 minecraft:stone_block_slab 5
fill ~157~21~37 ~160~21~38 minecraft:stone
fill ~157~32~37 ~160~32~38 minecraft:stone
fill ~162~38~37 ~199~38~38 minecraft:stone_block_slab 5
setblock ~164~32~37 minecraft:stone
fill ~165~20~37 ~168~20~38 minecraft:stone_block_slab 13
fill ~165~33~37 ~168~33~37 minecraft:stone_block_slab 5
fill ~173~20~37 ~176~20~38 minecraft:stone
fill ~173~33~37 ~176~33~38 minecraft:stone
fill ~174~34~37 ~175~34~37 minecraft:stone_brick_stairs
fill ~177~34~37 ~178~34~37 minecraft:stone_brick_stairs
fill ~181~19~37 ~184~19~38 minecraft:stone_block_slab 13
fill ~181~34~37 ~184~34~37 minecraft:stone_block_slab 5
fill ~187~35~37 ~187~35~38 minecraft:stone
fill ~187~36~37 ~197~36~37 minecraft:stone_block_slab 5
fill ~189~19~37 ~192~19~38 minecraft:stone
fill ~189~34~37 ~192~34~38 minecraft:stone
fill ~194~26~37 ~194~26~45 minecraft:stone_brick_stairs 2
fill ~194~27~37 ~194~27~45 minecraft:stone_brick_stairs 6
fill ~195~25~37 ~195~25~45 minecraft:stone_brick_stairs 2
fill ~195~28~37 ~195~28~45 minecraft:stone_brick_stairs 6
fill ~196~24~37 ~204~24~37 minecraft:stone
fill ~196~29~37 ~196~29~45 minecraft:stone_brick_stairs 6
fill ~197~18~37 ~203~18~38 minecraft:stone_block_slab 13
fill ~197~30~37 ~202~30~37 minecraft:stone
fill ~197~35~37 ~197~35~40 minecraft:stone
fill ~198~35~37 ~203~35~37 minecraft:stone_block_slab 5
fill ~200~19~37 ~200~19~87 minecraft:stone
fill ~200~34~37 ~200~34~87 minecraft:stone
fill ~201~19~37 ~201~19~85 minecraft:stone_brick_stairs 2
fill ~201~34~37 ~201~34~85 minecraft:stone_brick_stairs 6
setblock ~203~30~37 minecraft:stonebrick
setblock ~204~30~37 minecraft:stone
setblock ~204~31~37 minecraft:snow_layer
fill ~205~23~37 ~205~23~38 minecraft:stone
fill ~205~31~37 ~205~31~38 minecraft:stone
fill ~206~24~37 ~207~24~37 minecraft:stone
fill ~206~25~37 ~206~29~45 minecraft:sea_lantern
fill ~206~30~37 ~207~30~37 minecraft:stone
fill ~207~25~37 ~207~29~45 minecraft:air
fill ~85~25~38 ~88~25~40 minecraft:stone
fill ~85~28~38 ~88~28~40 minecraft:stone
fill ~89~26~38 ~89~27~38 minecraft:stonebrick
setblock ~90~26~38 minecraft:sea_lantern
fill ~90~27~38 ~91~27~38 minecraft:stone_brick_stairs
setblock ~91~26~38 minecraft:stone_brick_stairs
fill ~92~26~38 ~92~27~38 minecraft:stone
fill ~97~24~38 ~104~24~38 minecraft:stone_block_slab 13
fill ~97~29~38 ~104~29~38 minecraft:stone_block_slab 5
fill ~105~24~38 ~108~24~39 minecraft:stone
fill ~105~29~38 ~108~29~39 minecraft:stone
fill ~113~23~38 ~116~23~39 minecraft:stone_block_slab 13
fill ~113~30~38 ~116~30~39 minecraft:stone_block_slab 5
setblock ~119~2~38 minecraft:wool 8
setblock ~119~10~38 minecraft:wool 8
fill ~120~2~38 ~122~2~38 minecraft:wool 15
fill ~120~10~38 ~122~10~38 minecraft:wool 15
setblock ~121~1~38 minecraft:wool 8
setblock ~121~11~38 minecraft:wool 8
fill ~121~23~38 ~124~23~39 minecraft:stone
fill ~121~30~38 ~124~30~39 minecraft:stone
setblock ~122~1~38 minecraft:wool 15
setblock ~122~11~38 minecraft:wool 15
fill ~123~1~38 ~123~2~38 minecraft:wool 8
fill ~123~10~38 ~123~11~38 minecraft:wool 8
fill ~124~1~38 ~124~2~38 minecraft:wool 15
fill ~124~10~38 ~125~10~38 minecraft:wool 15
setblock ~124~11~38 minecraft:wool 15
setblock ~125~1~38 minecraft:wool 8
setblock ~125~2~38 minecraft:wool 15
setblock ~125~11~38 minecraft:wool 8
setblock ~126~2~38 minecraft:wool 8
setblock ~126~10~38 minecraft:wool 8
fill ~129~22~38 ~132~22~39 minecraft:stone_block_slab 13
fill ~129~31~38 ~132~31~39 minecraft:stone_block_slab 5
fill ~137~22~38 ~140~22~39 minecraft:stone
fill ~137~31~38 ~140~31~39 minecraft:stone
fill ~145~21~38 ~148~21~39 minecraft:stone_block_slab 13
fill ~145~32~38 ~148~32~39 minecraft:stone_block_slab 5
fill ~153~21~38 ~156~21~39 minecraft:stone
fill ~153~32~38 ~156~32~39 minecraft:stone
fill ~161~20~38 ~164~20~39 minecraft:stone_block_slab 13
fill ~161~33~38 ~161~33~39 minecraft:stone_block_slab 5
fill ~162~33~38 ~172~33~38 minecraft:stone
fill ~162~34~38 ~162~34~42 minecraft:stone
fill ~162~35~38 ~165~35~38 minecraft:stone
fill ~162~36~38 ~162~37~40 minecraft:stone
setblock ~163~34~38 minecraft:sea_lantern
fill ~163~36~38 ~164~36~38 minecraft:sea_lantern
fill ~163~37~38 ~172~37~38 minecraft:stone
fill ~164~34~38 ~171~34~38 minecraft:stone
fill ~165~36~38 ~167~36~38 minecraft:stone_brick_stairs
fill ~166~35~38 ~167~35~38 minecraft:sea_lantern
fill ~168~35~38 ~169~36~38 minecraft:stone
fill ~169~20~38 ~172~20~39 minecraft:stone
setblock ~170~35~38 minecraft:sea_lantern
setblock ~170~36~38 minecraft:stone_brick_stairs
fill ~171~35~38 ~173~35~38 minecraft:stone
setblock ~171~36~38 minecraft:stone
setblock ~172~34~38 minecraft:sea_lantern
setblock ~172~36~38 minecraft:sea_lantern
fill ~173~34~38 ~186~34~38 minecraft:stone
fill ~173~36~38 ~178~36~38 minecraft:stone
fill ~173~37~38 ~175~37~38 minecraft:stone_brick_stairs
fill ~174~35~38 ~175~35~38 minecraft:stone_brick_stairs
fill ~176~35~38 ~177~35~38 minecraft:sea_lantern
setblock ~176~37~38 minecraft:sea_lantern
fill ~177~19~38 ~180~19~39 minecraft:stone_block_slab 13
fill ~177~37~38 ~186~37~38 minecraft:stone
fill ~178~35~38 ~180~35~38 minecraft:stone
setblock ~179~36~38 minecraft:sea_lantern
fill ~180~36~38 ~181~36~38 minecraft:stone_brick_stairs
fill ~181~35~38 ~182~35~38 minecraft:sea_lantern
fill ~182~36~38 ~184~36~38 minecraft:stone
setblock ~183~35~38 minecraft:stone
fill ~184~35~38 ~185~35~38 minecraft:stone_brick_stairs
fill ~185~19~38 ~188~19~39 minecraft:stone
setblock ~185~36~38 minecraft:sea_lantern
fill ~186~35~38 ~186~36~38 minecraft:stone
fill ~187~36~38 ~192~36~38 minecraft:stone
fill ~187~37~38 ~188~37~38 minecraft:stone_brick_stairs
fill ~188~34~38 ~188~34~39 minecraft:stone
fill ~188~35~38 ~196~35~38 minecraft:stone
fill ~189~37~38 ~190~37~38 minecraft:sea_lantern
setblock ~191~37~38 minecraft:stone
fill ~192~37~38 ~194~37~38 minecraft:stone_brick_stairs
fill ~193~18~38 ~196~18~39 minecraft:stone_block_slab 13
setblock ~193~36~38 minecraft:sea_lantern
fill ~194~36~38 ~195~36~38 minecraft:stone
setblock ~195~37~38 minecraft:sea_lantern
fill ~196~24~38 ~196~24~44 minecraft:stone_brick_stairs 2
fill ~196~36~38 ~197~36~38 minecraft:stone_brick_stairs
fill ~196~37~38 ~198~37~38 minecraft:stone
fill ~197~23~38 ~204~23~38 minecraft:stone
fill ~197~30~38 ~197~30~44 minecraft:stone_brick_stairs 6
fill ~198~31~38 ~202~31~38 minecraft:stone
fill ~198~35~38 ~198~36~40 minecraft:stone
fill ~199~35~38 ~203~35~38 minecraft:stone_block_slab 5
setblock ~203~31~38 minecraft:stonebrick
setblock ~204~31~38 minecraft:stone
fill ~205~22~38 ~205~22~44 minecraft:stone
fill ~205~32~38 ~205~32~44 minecraft:stone
fill ~206~23~38 ~207~23~38 minecraft:stone
fill ~206~24~38 ~206~24~44 minecraft:sea_lantern
fill ~206~30~38 ~206~30~44 minecraft:sea_lantern
fill ~206~31~38 ~207~31~38 minecraft:stone
setblock ~206~32~38 minecraft:snow_layer
fill ~207~24~38 ~207~24~44 minecraft:air
fill ~207~30~38 ~207~30~44 minecraft:air
fill ~81~25~39 ~84~25~41 minecraft:stone
fill ~81~28~39 ~84~28~41 minecraft:stone
fill ~85~26~39 ~87~26~39 minecraft:stone_brick_stairs
setblock ~85~27~39 minecraft:stone
setblock ~86~27~39 minecraft:sea_lantern
setblock ~87~27~39 minecraft:stonebrick
setblock ~88~26~39 minecraft:stonebrick
setblock ~88~27~39 minecraft:sea_lantern
fill ~93~24~39 ~100~24~39 minecraft:stone_block_slab 13
fill ~93~29~39 ~100~29~39 minecraft:stone_block_slab 5
fill ~101~24~39 ~104~24~40 minecraft:stone
fill ~101~29~39 ~104~29~40 minecraft:stone
fill ~109~23~39 ~112~23~40 minecraft:stone_block_slab 13
fill ~109~30~39 ~112~30~40 minecraft:stone_block_slab 5
fill ~117~23~39 ~120~23~40 minecraft:stone
fill ~117~30~39 ~120~30~40 minecraft:stone
setblock ~123~6~39 minecraft:wool 7
setblock ~124~5~39 minecraft:wool 7
setblock ~124~7~39 minecraft:wool 7
setblock ~125~6~39 minecraft:wool 7
fill ~125~22~39 ~128~22~40 minecraft:stone_block_slab 13
fill ~125~31~39 ~128~31~40 minecraft:stone_block_slab 5
fill ~133~22~39 ~136~22~40 minecraft:stone
fill ~133~31~39 ~136~31~40 minecraft:stone
fill ~141~21~39 ~144~21~40 minecraft:stone_block_slab 13
fill ~141~32~39 ~144~32~40 minecraft:stone_block_slab 5
fill ~149~21~39 ~152~21~40 minecraft:stone
fill ~149~32~39 ~152~32~40 minecraft:stone
fill ~157~20~39 ~160~20~40 minecraft:stone_block_slab 13
fill ~157~33~39 ~160~33~40 minecraft:stone_block_slab 5
fill ~161~38~39 ~199~38~40 minecraft:stone
fill ~162~33~39 ~162~33~41 minecraft:stone
setblock ~162~35~39 minecraft:sea_lantern
fill ~163~33~39 ~164~33~39 minecraft:stone_block_slab 5
fill ~165~20~39 ~168~20~40 minecraft:stone
fill ~165~33~39 ~172~33~39 minecraft:stone
fill ~173~19~39 ~176~19~40 minecraft:stone_block_slab 13
fill ~173~34~39 ~180~34~39 minecraft:stone_block_slab 5
fill ~181~19~39 ~184~19~40 minecraft:stone
fill ~181~34~39 ~186~34~39 minecraft:stone
fill ~189~18~39 ~192~18~40 minecraft:stone_block_slab 13
fill ~189~35~39 ~196~35~39 minecraft:stone_block_slab 5
fill ~197~18~39 ~203~18~40 minecraft:stone
fill ~197~23~39 ~197~23~43 minecraft:stone_brick_stairs 2
fill ~198~22~39 ~204~22~43 minecraft:stone
fill ~198~31~39 ~198~31~42 minecraft:stone_brick_stairs 6
setblock ~198~37~39 minecraft:sea_lantern
fill ~199~35~39 ~203~35~40 minecraft:stone
fill ~200~32~39 ~202~32~40 minecraft:stone
fill ~203~32~39 ~203~32~43 minecraft:stonebrick
fill ~204~32~39 ~204~32~40 minecraft:stone
fill ~205~21~39 ~205~21~43 minecraft:stone
fill ~205~33~39 ~205~33~43 minecraft:stone
fill ~206~22~39 ~207~22~43 minecraft:stone
fill ~206~23~39 ~206~23~43 minecraft:sea_lantern
fill ~206~31~39 ~206~31~43 minecraft:sea_lantern
fill ~206~32~39 ~207~32~43 minecraft:stone
setblock ~206~33~39 minecraft:snow_layer
fill ~207~23~39 ~207~23~43 minecraft:air
fill ~207~31~39 ~207~31~43 minecraft:air
fill ~77~25~40 ~80~25~42 minecraft:stone
fill ~77~28~40 ~80~28~42 minecraft:stone
fill ~81~26~40 ~81~27~40 minecraft:stone
setblock ~82~26~40 minecraft:sea_lantern
fill ~82~27~40 ~83~27~40 minecraft:stone_brick_stairs
fill ~83~26~40 ~84~26~40 minecraft:stone
setblock ~84~27~40 minecraft:stone
fill ~89~24~40 ~96~24~40 minecraft:stone_block_slab 13
fill ~89~29~40 ~96~29~40 minecraft:stone_block_slab 5
fill ~97~24~40 ~100~24~41 minecraft:stone
fill ~97~29~40 ~100~29~41 minecraft:stone
fill ~105~23~40 ~108~23~41 minecraft:stone_block_slab 13
fill ~105~30~40 ~108~30~41 minecraft:stone_block_slab 5
fill ~113~23~40 ~116~23~41 minecraft:stone
fill ~113~30~40 ~116~30~41 minecraft:stone
fill ~121~22~40 ~124~22~41 minecraft:stone_block_slab 13
fill ~121~31~40 ~124~31~41 minecraft:stone_block_slab 5
fill ~123~6~40 ~125~6~44 minecraft:wool 8
fill ~124~5~40 ~124~5~44 minecraft:wool 8
fill ~124~7~40 ~124~7~44 minecraft:wool 8
fill ~129~22~40 ~132~22~41 minecraft:stone
fill ~129~31~40 ~132~31~41 minecraft:stone
fill ~137~21~40 ~140~21~41 minecraft:stone_block_slab 13
fill ~137~32~40 ~140~32~41 minecraft:stone_block_slab 5
fill ~145~21~40 ~148~21~41 minecraft:stone
fill ~145~32~40 ~148~32~41 minecraft:stone
fill ~153~20~40 ~156~20~41 minecraft:stone_block_slab 13
fill ~153~33~40 ~156~33~41 minecraft:stone_block_slab 5
fill ~161~20~40 ~164~20~41 minecraft:stone
fill ~161~33~40 ~161~33~41 minecraft:stone
fill ~162~35~40 ~162~35~42 minecraft:stone
fill ~163~33~40 ~168~33~40 minecraft:stone
fill ~169~19~40 ~172~19~41 minecraft:stone_block_slab 13
fill ~169~34~40 ~176~34~40 minecraft:stone_block_slab 5
fill ~177~19~40 ~180~19~41 minecraft:stone
fill ~177~34~40 ~184~34~40 minecraft:stone
fill ~185~18~40 ~188~18~41 minecraft:stone_block_slab 13
fill ~185~35~40 ~192~35~40 minecraft:stone_block_slab 5
fill ~193~18~40 ~196~18~41 minecraft:stone
fill ~193~35~40 ~196~35~41 minecraft:stone
fill ~198~37~40 ~198~37~42 minecraft:stone
fill ~199~32~40 ~199~32~43 minecraft:stone
fill ~76~25~41 ~76~25~47 minecraft:stone
fill ~76~28~41 ~76~28~47 minecraft:stone
fill ~77~26~41 ~77~27~41 minecraft:stonebrick
setblock ~78~26~41 minecraft:stone
setblock ~78~27~41 minecraft:sea_lantern
setblock ~79~26~41 minecraft:stonebrick
setblock ~79~27~41 minecraft:stone
setblock ~80~26~41 minecraft:stone
setblock ~80~27~41 minecraft:stonebrick
fill ~85~24~41 ~92~24~41 minecraft:stone_block_slab 13
fill ~85~29~41 ~92~29~41 minecraft:stone_block_slab 5
fill ~93~24~41 ~96~24~42 minecraft:stone
fill ~93~29~41 ~96~29~42 minecraft:stone
fill ~101~23~41 ~104~23~42 minecraft:stone_block_slab 13
fill ~101~30~41 ~104~30~42 minecraft:stone_block_slab 5
fill ~109~23~41 ~112~23~42 minecraft:stone
fill ~109~30~41 ~112~30~42 minecraft:stone
fill ~117~22~41 ~120~22~42 minecraft:stone_block_slab 13
fill ~117~31~41 ~120~31~42 minecraft:stone_block_slab 5
fill ~122~5~41 ~123~5~41 minecraft:wool 8
setblock ~122~6~41 minecraft:wool 15
fill ~123~7~41 ~123~7~43 minecraft:wool 8
fill ~124~4~41 ~124~4~43 minecraft:wool 8
fill ~124~8~41 ~124~8~43 minecraft:wool 8
fill ~125~5~41 ~125~5~42 minecraft:wool 8
fill ~125~7~41 ~125~7~43 minecraft:wool 8
fill ~125~22~41 ~128~22~42 minecraft:stone
fill ~125~31~41 ~128~31~42 minecraft:stone
setblock ~126~6~41 minecraft:wool 15
fill ~133~21~41 ~136~21~42 minecraft:stone_block_slab 13
fill ~133~32~41 ~136~32~42 minecraft:stone_block_slab 5
fill ~141~21~41 ~144~21~42 minecraft:stone
fill ~141~32~41 ~144~32~42 minecraft:stone
fill ~149~20~41 ~152~20~42 minecraft:stone_block_slab 13
fill ~149~33~41 ~152~33~42 minecraft:stone_block_slab 5
fill ~152~40~41 ~202~40~42 minecraft:stone_block_slab 5
fill ~157~20~41 ~160~20~42 minecraft:stone
fill ~157~33~41 ~160~33~42 minecraft:stone
fill ~158~34~41 ~160~34~41 minecraft:stone_brick_stairs
fill ~161~39~41 ~200~39~41 minecraft:stone_block_slab 5
setblock ~162~36~41 minecraft:sea_lantern
fill ~162~37~41 ~162~38~42 minecraft:stone
fill ~163~33~41 ~164~33~41 minecraft:stone
fill ~165~19~41 ~168~19~42 minecraft:stone_block_slab 13
fill ~165~34~41 ~172~34~41 minecraft:stone_block_slab 5
fill ~173~19~41 ~176~19~42 minecraft:stone
fill ~173~34~41 ~180~34~41 minecraft:stone
fill ~181~18~41 ~184~18~42 minecraft:stone_block_slab 13
fill ~181~35~41 ~188~35~41 minecraft:stone_block_slab 5
fill ~189~18~41 ~192~18~42 minecraft:stone
fill ~189~35~41 ~192~35~42 minecraft:stone
fill ~197~17~41 ~204~17~42 minecraft:stone_block_slab 13
setblock ~197~36~41 minecraft:stone_block_slab 5
fill ~198~36~41 ~198~36~44 minecraft:stone
fill ~198~38~41 ~198~38~42 minecraft:stone
fill ~199~36~41 ~204~36~41 minecraft:stone_block_slab 5
fill ~200~32~41 ~202~32~41 minecraft:stonebrick
fill ~201~18~41 ~201~18~83 minecraft:stone
fill ~201~35~41 ~201~35~83 minecraft:stone
fill ~202~18~41 ~202~18~81 minecraft:stone_brick_stairs 2
fill ~202~35~41 ~202~35~81 minecraft:stone_brick_stairs 6
setblock ~204~32~41 minecraft:stonebrick
setblock ~77~26~42 minecraft:sea_lantern
fill ~77~27~42 ~77~27~46 minecraft:stone
fill ~81~24~42 ~88~24~42 minecraft:stone_block_slab 13
fill ~81~29~42 ~88~29~42 minecraft:stone_block_slab 5
fill ~89~24~42 ~92~24~43 minecraft:stone
fill ~89~29~42 ~92~29~43 minecraft:stone
fill ~97~23~42 ~100~23~43 minecraft:stone_block_slab 13
fill ~97~30~42 ~100~30~43 minecraft:stone_block_slab 5
fill ~105~23~42 ~108~23~43 minecraft:stone
fill ~105~30~42 ~108~30~43 minecraft:stone
fill ~113~22~42 ~116~22~43 minecraft:stone_block_slab 13
fill ~113~31~42 ~116~31~43 minecraft:stone_block_slab 5
fill ~121~22~42 ~124~22~43 minecraft:stone
fill ~121~31~42 ~124~31~43 minecraft:stone
setblock ~122~5~42 minecraft:wool 15
setblock ~122~6~42 minecraft:wool 7
setblock ~122~7~42 minecraft:wool 15
fill ~123~4~42 ~123~5~42 minecraft:wool 8
setblock ~123~8~42 minecraft:wool 8
setblock ~125~4~42 minecraft:wool 8
setblock ~125~8~42 minecraft:wool 8
setblock ~126~5~42 minecraft:wool 15
setblock ~126~6~42 minecraft:wool 7
setblock ~126~7~42 minecraft:wool 15
fill ~129~21~42 ~132~21~43 minecraft:stone_block_slab 13
fill ~129~32~42 ~132~32~43 minecraft:stone_block_slab 5
fill ~137~21~42 ~140~21~43 minecraft:stone
fill ~137~32~42 ~140~32~43 minecraft:stone
fill ~145~20~42 ~148~20~43 minecraft:stone_block_slab 13
fill ~145~33~42 ~148~33~43 minecraft:stone_block_slab 5
fill ~153~20~42 ~156~20~43 minecraft:stone
fill ~153~33~42 ~156~33~43 minecraft:stone
fill ~153~34~42 ~153~36~42 minecraft:stone
fill ~153~37~42 ~157~37~42 minecraft:stonebrick
fill ~153~38~42 ~153~39~42 minecraft:stone
setblock ~154~34~42 minecraft:sea_lantern
fill ~154~35~42 ~154~36~42 minecraft:stone
setblock ~154~38~42 minecraft:sea_lantern
fill ~154~39~42 ~156~39~42 minecraft:stone
fill ~155~34~42 ~161~34~42 minecraft:stone
fill ~155~35~42 ~156~35~42 minecraft:stone_brick_stairs
fill ~155~36~42 ~156~36~42 minecraft:sea_lantern
fill ~155~38~42 ~156~38~42 minecraft:stone_brick_stairs
fill ~157~35~42 ~157~36~42 minecraft:stone
fill ~157~38~42 ~157~39~42 minecraft:stonebrick
setblock ~158~35~42 minecraft:sea_lantern
fill ~158~36~42 ~197~36~42 minecraft:stone
setblock ~158~37~42 minecraft:sea_lantern
fill ~158~38~42 ~161~38~42 minecraft:stone
setblock ~158~39~42 minecraft:stone
setblock ~159~35~42 minecraft:stone
fill ~159~37~42 ~161~37~42 minecraft:stone_brick_stairs
setblock ~159~39~42 minecraft:sea_lantern
setblock ~160~35~42 minecraft:sea_lantern
fill ~160~39~42 ~161~39~42 minecraft:stone
fill ~161~19~42 ~164~19~43 minecraft:stone_block_slab 13
setblock ~161~35~42 minecraft:stone
setblock ~162~39~42 minecraft:sea_lantern
fill ~163~34~42 ~176~35~42 minecraft:stone
fill ~163~37~42 ~197~38~42 minecraft:stone
fill ~163~39~42 ~170~39~42 minecraft:stone
fill ~169~19~42 ~172~19~43 minecraft:stone
setblock ~171~39~42 minecraft:sea_lantern
fill ~172~39~42 ~175~39~42 minecraft:stone
setblock ~176~39~42 minecraft:sea_lantern
fill ~177~18~42 ~180~18~43 minecraft:stone_block_slab 13
fill ~177~35~42 ~188~35~42 minecraft:stone
fill ~177~39~42 ~178~39~42 minecraft:stone
fill ~179~39~42 ~180~39~42 minecraft:sea_lantern
fill ~181~39~42 ~188~39~42 minecraft:stone
fill ~185~18~42 ~188~18~43 minecraft:stone
fill ~189~39~42 ~190~39~42 minecraft:sea_lantern
fill ~191~39~42 ~197~39~42 minecraft:stone
fill ~193~17~42 ~196~17~43 minecraft:stone_block_slab 13
setblock ~198~39~42 minecraft:sea_lantern
fill ~199~36~42 ~201~36~44 minecraft:stone
fill ~199~37~42 ~201~39~42 minecraft:stone
fill ~200~32~42 ~202~32~43 minecraft:stone
fill ~202~36~42 ~204~36~42 minecraft:stone_block_slab 5
fill ~204~32~42 ~204~32~43 minecraft:stone
fill ~207~33~42 ~207~33~43 minecraft:snow_layer
fill ~77~24~43 ~84~24~43 minecraft:stone_block_slab 13
fill ~77~25~43 ~77~25~47 minecraft:stone
fill ~77~26~43 ~77~26~44 minecraft:stone_brick_stairs 3
fill ~77~29~43 ~84~29~43 minecraft:stone_block_slab 5
fill ~85~24~43 ~88~24~44 minecraft:stone
fill ~85~29~43 ~88~29~44 minecraft:stone
fill ~93~23~43 ~96~23~44 minecraft:stone_block_slab 13
fill ~93~30~43 ~96~30~44 minecraft:stone_block_slab 5
fill ~101~23~43 ~104~23~44 minecraft:stone
fill ~101~30~43 ~104~30~44 minecraft:stone
fill ~109~22~43 ~112~22~44 minecraft:stone_block_slab 13
fill ~109~31~43 ~112~31~44 minecraft:stone_block_slab 5
fill ~117~22~43 ~120~22~44 minecraft:stone
fill ~117~31~43 ~120~31~44 minecraft:stone
fill ~122~5~43 ~123~5~43 minecraft:wool 8
setblock ~122~6~43 minecraft:wool 15
fill ~125~21~43 ~128~21~44 minecraft:stone_block_slab 13
fill ~125~32~43 ~128~32~44 minecraft:stone_block_slab 5
setblock ~126~6~43 minecraft:wool 15
fill ~133~21~43 ~136~21~44 minecraft:stone
fill ~133~32~43 ~136~32~44 minecraft:stone
fill ~141~20~43 ~144~20~44 minecraft:stone_block_slab 13
fill ~141~33~43 ~144~33~44 minecraft:stone_block_slab 5
fill ~149~20~43 ~152~20~44 minecraft:stone
fill ~149~33~43 ~152~33~44 minecraft:stone
fill ~152~40~43 ~202~40~44 minecraft:stone
setblock ~153~34~43 minecraft:sea_lantern
fill ~153~35~43 ~153~36~43 minecraft:stone
fill ~153~37~43 ~153~37~44 minecraft:stonebrick
fill ~153~38~43 ~153~38~44 minecraft:sea_lantern
fill ~153~39~43 ~153~39~46 minecraft:stone
fill ~157~19~43 ~160~19~44 minecraft:stone_block_slab 13
fill ~157~34~43 ~164~34~43 minecraft:stone_block_slab 5
fill ~165~19~43 ~168~19~44 minecraft:stone
fill ~165~34~43 ~172~34~43 minecraft:stone
fill ~173~18~43 ~176~18~44 minecraft:stone_block_slab 13
fill ~173~35~43 ~180~35~43 minecraft:stone_block_slab 5
fill ~181~18~43 ~184~18~44 minecraft:stone
fill ~181~35~43 ~188~35~43 minecraft:stone
fill ~189~17~43 ~192~17~44 minecraft:stone_block_slab 13
fill ~189~36~43 ~196~36~43 minecraft:stone_block_slab 5
fill ~197~17~43 ~204~17~44 minecraft:stone
fill ~197~36~43 ~197~36~44 minecraft:stone
fill ~201~37~43 ~201~37~48 minecraft:stone
setblock ~201~38~43 minecraft:sea_lantern
setblock ~201~39~43 minecraft:stone
fill ~202~36~43 ~204~36~44 minecraft:stone
setblock ~205~34~43 minecraft:snow_layer
fill ~76~24~44 ~80~24~44 minecraft:stone_block_slab 13
fill ~76~29~44 ~80~29~44 minecraft:stone_block_slab 5
fill ~81~24~44 ~84~24~45 minecraft:stone
fill ~81~29~44 ~84~29~45 minecraft:stone
fill ~89~23~44 ~92~23~45 minecraft:stone_block_slab 13
fill ~89~30~44 ~92~30~45 minecraft:stone_block_slab 5
fill ~97~23~44 ~100~23~45 minecraft:stone
fill ~97~30~44 ~100~30~45 minecraft:stone
fill ~105~22~44 ~108~22~45 minecraft:stone_block_slab 13
fill ~105~31~44 ~108~31~45 minecraft:stone_block_slab 5
fill ~113~22~44 ~116~22~45 minecraft:stone
fill ~113~31~44 ~116~31~45 minecraft:stone
fill ~121~21~44 ~124~21~45 minecraft:stone_block_slab 13
fill ~121~32~44 ~124~32~45 minecraft:stone_block_slab 5
fill ~129~21~44 ~132~21~45 minecraft:stone
fill ~129~32~44 ~132~32~45 minecraft:stone
fill ~137~20~44 ~140~20~45 minecraft:stone_block_slab 13
fill ~137~33~44 ~140~33~45 minecraft:stone_block_slab 5
fill ~145~20~44 ~148~20~45 minecraft:stone
fill ~145~33~44 ~148~33~45 minecraft:stone
fill ~152~34~44 ~152~34~46 minecraft:stone_brick_stairs 3
fill ~153~19~44 ~156~19~45 minecraft:stone_block_slab 13
fill ~153~34~44 ~153~36~44 minecraft:stonebrick
fill ~154~34~44 ~160~34~44 minecraft:stone_block_slab 5
fill ~161~19~44 ~164~19~45 minecraft:stone
fill ~161~34~44 ~168~34~44 minecraft:stone
fill ~169~18~44 ~172~18~45 minecraft:stone_block_slab 13
fill ~169~35~44 ~176~35~44 minecraft:stone_block_slab 5
fill ~177~18~44 ~180~18~45 minecraft:stone
fill ~177~35~44 ~184~35~44 minecraft:stone
fill ~185~17~44 ~188~17~45 minecraft:stone_block_slab 13
fill ~185~36~44 ~192~36~44 minecraft:stone_block_slab 5
fill ~193~17~44 ~196~17~45 minecraft:stone
fill ~193~36~44 ~196~36~45 minecraft:stone
fill ~197~23~44 ~207~23~44 minecraft:stone
fill ~198~22~44 ~198~22~48 minecraft:stone_brick_stairs 2
fill ~198~31~44 ~202~31~44 minecraft:stone
fill ~199~32~44 ~199~32~48 minecraft:stone_brick_stairs 6
fill ~201~38~44 ~201~38~52 minecraft:stone
fill ~201~39~44 ~201~39~45 minecraft:stonebrick
setblock ~203~31~44 minecraft:stonebrick
fill ~204~31~44 ~207~31~44 minecraft:stone
setblock ~205~33~44 minecraft:snow_layer
setblock ~207~32~44 minecraft:snow_layer
fill ~73~24~45 ~76~24~45 minecraft:stone_block_slab 13
fill ~73~25~45 ~75~25~47 minecraft:stone
fill ~73~28~45 ~75~28~47 minecraft:stone
fill ~73~29~45 ~76~29~45 minecraft:stone_block_slab 5
fill ~77~24~45 ~80~24~46 minecraft:stone
setblock ~77~26~45 minecraft:sea_lantern
fill ~77~29~45 ~80~29~46 minecraft:stone
fill ~85~23~45 ~88~23~46 minecraft:stone_block_slab 13
fill ~85~30~45 ~88~30~46 minecraft:stone_block_slab 5
fill ~93~23~45 ~96~23~46 minecraft:stone
fill ~93~30~45 ~96~30~46 minecraft:stone
fill ~101~22~45 ~104~22~46 minecraft:stone_block_slab 13
fill ~101~31~45 ~104~31~46 minecraft:stone_block_slab 5
fill ~109~22~45 ~112~22~46 minecraft:stone
fill ~109~31~45 ~112~31~46 minecraft:stone
fill ~117~21~45 ~120~21~46 minecraft:stone_block_slab 13
fill ~117~32~45 ~120~32~46 minecraft:stone_block_slab 5
fill ~123~6~45 ~125~6~45 minecraft:wool 7
setblock ~124~5~45 minecraft:wool 7
fill ~125~21~45 ~128~21~46 minecraft:stone
fill ~125~32~45 ~128~32~46 minecraft:stone
fill ~133~20~45 ~136~20~46 minecraft:stone_block_slab 13
fill ~133~33~45 ~136~33~46 minecraft:stone_block_slab 5
fill ~141~20~45 ~144~20~46 minecraft:stone
fill ~141~33~45 ~144~33~46 minecraft:stone
fill ~149~19~45 ~152~19~46 minecraft:stone_block_slab 13
fill ~149~34~45 ~151~34~46 minecraft:stone_block_slab 5
fill ~152~41~45 ~203~41~46 minecraft:stone_block_slab 5
fill ~153~34~45 ~153~34~47 minecraft:stone
fill ~153~35~45 ~153~35~46 minecraft:stone
setblock ~153~36~45 minecraft:sea_lantern
fill ~153~37~45 ~153~37~54 minecraft:stone
setblock ~153~38~45 minecraft:stone
fill ~153~40~45 ~153~40~46 minecraft:stone
fill ~154~34~45 ~156~34~45 minecraft:stone_block_slab 5
fill ~157~19~45 ~160~19~46 minecraft:stone
fill ~157~34~45 ~164~34~45 minecraft:stone
fill ~165~18~45 ~168~18~46 minecraft:stone_block_slab 13
fill ~165~35~45 ~172~35~45 minecraft:stone_block_slab 5
fill ~173~18~45 ~176~18~46 minecraft:stone
fill ~173~35~45 ~180~35~45 minecraft:stone
fill ~181~17~45 ~184~17~46 minecraft:stone_block_slab 13
fill ~181~36~45 ~188~36~45 minecraft:stone_block_slab 5
fill ~189~17~45 ~192~17~46 minecraft:stone
fill ~189~36~45 ~192~36~46 minecraft:stone
fill ~196~24~45 ~207~24~45 minecraft:stone
fill ~197~16~45 ~205~16~46 minecraft:stone_block_slab 13
fill ~197~23~45 ~197~23~48 minecraft:stone_brick_stairs 2
fill ~197~30~45 ~202~30~45 minecraft:stone
fill ~197~37~45 ~200~37~46 minecraft:stone_block_slab 5
fill ~198~31~45 ~198~31~48 minecraft:stone_brick_stairs 6
fill ~201~40~45 ~201~40~46 minecraft:stone
fill ~202~17~45 ~202~17~79 minecraft:stone
fill ~202~36~45 ~202~36~79 minecraft:stone
fill ~202~37~45 ~205~37~46 minecraft:stone_block_slab 5
fill ~203~17~45 ~203~17~58 minecraft:stone_brick_stairs 2
setblock ~203~30~45 minecraft:stonebrick
fill ~203~36~45 ~203~36~58 minecraft:stone_brick_stairs 6
fill ~204~30~45 ~207~30~45 minecraft:stone
setblock ~205~23~45 minecraft:stone
setblock ~205~31~45 minecraft:stone
fill ~69~24~46 ~72~24~46 minecraft:stone_block_slab 13
fill ~69~25~46 ~72~25~48 minecraft:stone
fill ~69~28~46 ~72~28~48 minecraft:stone
fill ~69~29~46 ~72~29~46 minecraft:stone_block_slab 5
fill ~73~24~46 ~76~24~47 minecraft:stone
fill ~73~29~46 ~76~29~47 minecraft:stone
fill ~77~26~46 ~77~26~47 minecraft:stonebrick
fill ~81~23~46 ~84~23~47 minecraft:stone_block_slab 13
fill ~81~30~46 ~84~30~47 minecraft:stone_block_slab 5
fill ~89~23~46 ~92~23~47 minecraft:stone
fill ~89~30~46 ~92~30~47 minecraft:stone
fill ~97~22~46 ~100~22~47 minecraft:stone_block_slab 13
fill ~97~31~46 ~100~31~47 minecraft:stone_block_slab 5
fill ~105~22~46 ~108~22~47 minecraft:stone
fill ~105~31~46 ~108~31~47 minecraft:stone
fill ~113~21~46 ~116~21~47 minecraft:stone_block_slab 13
fill ~113~32~46 ~116~32~47 minecraft:stone_block_slab 5
setblock ~119~2~46 minecraft:wool 8
setblock ~119~10~46 minecraft:wool 8
fill ~120~2~46 ~122~2~46 minecraft:wool 15
fill ~120~10~46 ~122~10~46 minecraft:wool 15
setblock ~121~1~46 minecraft:wool 8
setblock ~121~11~46 minecraft:wool 8
fill ~121~21~46 ~124~21~47 minecraft:stone
fill ~121~32~46 ~124~32~47 minecraft:stone
setblock ~122~1~46 minecraft:wool 15
setblock ~122~11~46 minecraft:wool 15
fill ~123~1~46 ~123~2~46 minecraft:wool 8
fill ~123~10~46 ~123~11~46 minecraft:wool 8
fill ~124~1~46 ~124~2~46 minecraft:wool 15
fill ~124~6~46 ~124~6~47 minecraft:wool 7
fill ~124~10~46 ~125~10~46 minecraft:wool 15
setblock ~124~11~46 minecraft:wool 15
setblock ~125~1~46 minecraft:wool 8
setblock ~125~2~46 minecraft:wool 15
setblock ~125~11~46 minecraft:wool 8
setblock ~126~2~46 minecraft:wool 8
setblock ~126~10~46 minecraft:wool 8
fill ~129~20~46 ~132~20~47 minecraft:stone_block_slab 13
fill ~129~33~46 ~132~33~47 minecraft:stone_block_slab 5
fill ~137~20~46 ~140~20~47 minecraft:stone
fill ~137~33~46 ~140~33~47 minecraft:stone
fill ~145~19~46 ~148~19~47 minecraft:stone_block_slab 13
fill ~145~34~46 ~148~34~46 minecraft:stone_block_slab 5
fill ~153~19~46 ~156~19~47 minecraft:stone
setblock ~153~36~46 minecraft:stone
fill ~153~38~46 ~153~38~49 minecraft:stone_brick_stairs 3
fill ~154~34~46 ~160~34~46 minecraft:stone
fill ~161~18~46 ~164~18~47 minecraft:stone_block_slab 13
fill ~161~35~46 ~168~35~46 minecraft:stone_block_slab 5
fill ~168~44~46 ~199~44~46 minecraft:stone_block_slab 5
fill ~169~18~46 ~172~18~47 minecraft:stone
fill ~169~35~46 ~176~35~46 minecraft:stone
fill ~177~17~46 ~180~17~47 minecraft:stone_block_slab 13
fill ~177~36~46 ~184~36~46 minecraft:stone_block_slab 5
fill ~184~54~46 ~193~54~47 minecraft:stone
fill ~184~55~46 ~188~56~46 minecraft:stone
fill ~184~57~46 ~184~58~46 minecraft:stone
fill ~185~17~46 ~188~17~47 minecraft:stone
fill ~185~36~46 ~188~36~47 minecraft:stone
fill ~185~57~46 ~187~57~46 minecraft:stonebrick
fill ~185~58~46 ~193~58~47 minecraft:stone
fill ~188~57~46 ~192~57~46 minecraft:stone
fill ~189~55~46 ~190~55~46 minecraft:stonebrick
fill ~189~56~46 ~193~56~46 minecraft:stone
fill ~191~55~46 ~193~55~46 minecraft:stone
fill ~193~16~46 ~196~16~47 minecraft:stone_block_slab 13
fill ~193~37~46 ~196~37~47 minecraft:stone_block_slab 5
fill ~193~57~46 ~193~57~50 minecraft:stonebrick
fill ~194~26~46 ~202~27~46 minecraft:stone
fill ~195~25~46 ~202~25~46 minecraft:stone
fill ~195~28~46 ~202~28~46 minecraft:stone
fill ~196~24~46 ~196~24~49 minecraft:stone_brick_stairs 2
fill ~196~29~46 ~202~29~46 minecraft:stone
fill ~197~30~46 ~197~30~48 minecraft:stone_brick_stairs 6
setblock ~201~39~46 minecraft:stone
fill ~203~25~46 ~203~29~46 minecraft:stonebrick
fill ~204~25~46 ~207~29~46 minecraft:stone
setblock ~205~24~46 minecraft:stone
setblock ~205~30~46 minecraft:stone
fill ~49~25~47 ~52~25~49 minecraft:stone
fill ~49~28~47 ~52~28~49 minecraft:stone
fill ~65~24~47 ~68~24~47 minecraft:stone_block_slab 13
fill ~65~25~47 ~68~25~49 minecraft:stone
fill ~65~28~47 ~68~28~49 minecraft:stone
fill ~65~29~47 ~68~29~47 minecraft:stone_block_slab 5
fill ~69~24~47 ~72~24~48 minecraft:stone
fill ~69~29~47 ~72~29~48 minecraft:stone
fill ~77~23~47 ~80~23~48 minecraft:stone_block_slab 13
setblock ~77~27~47 minecraft:sea_lantern
fill ~77~30~47 ~80~30~48 minecraft:stone_block_slab 5
fill ~85~23~47 ~88~23~48 minecraft:stone
fill ~85~30~47 ~88~30~48 minecraft:stone
fill ~93~22~47 ~96~22~48 minecraft:stone_block_slab 13
fill ~93~31~47 ~96~31~48 minecraft:stone_block_slab 5
fill ~101~22~47 ~104~22~48 minecraft:stone
fill ~101~31~47 ~104~31~48 minecraft:stone
fill ~109~21~47 ~112~21~48 minecraft:stone_block_slab 13
fill ~109~32~47 ~112~32~48 minecraft:stone_block_slab 5
fill ~114~4~47 ~115~4~47 minecraft:wool 7
fill ~114~8~47 ~115~8~47 minecraft:wool 7
fill ~116~4~47 ~127~4~47 minecraft:wool 8
fill ~116~8~47 ~127~8~47 minecraft:wool 8
setblock ~117~3~47 minecraft:wool 8
setblock ~117~9~47 minecraft:wool 8
fill ~117~21~47 ~120~21~48 minecraft:stone
fill ~117~32~47 ~120~32~48 minecraft:stone
fill ~118~3~47 ~122~3~47 minecraft:wool 15
fill ~118~9~47 ~122~9~47 minecraft:wool 15
setblock ~123~3~47 minecraft:wool 8
setblock ~123~9~47 minecraft:wool 8
fill ~124~3~47 ~125~3~47 minecraft:wool 15
fill ~124~9~47 ~126~9~47 minecraft:wool 15
fill ~125~20~47 ~128~20~48 minecraft:stone_block_slab 13
fill ~125~33~47 ~128~33~48 minecraft:stone_block_slab 5
fill ~126~3~47 ~127~3~47 minecraft:wool 8
setblock ~127~9~47 minecraft:wool 8
fill ~133~20~47 ~136~20~48 minecraft:stone
fill ~133~33~47 ~136~33~48 minecraft:stone
fill ~141~19~47 ~144~19~48 minecraft:stone_block_slab 13
fill ~141~34~47 ~146~34~47 minecraft:stone_block_slab 5
fill ~147~34~47 ~148~34~49 minecraft:stone
fill ~147~35~47 ~147~36~47 minecraft:stone
fill ~148~35~47 ~149~35~47 minecraft:stone_brick_stairs
fill ~148~36~47 ~152~36~47 minecraft:stone
fill ~149~19~47 ~152~19~48 minecraft:stone
setblock ~149~34~47 minecraft:sea_lantern
fill ~150~34~47 ~152~34~48 minecraft:stone
fill ~150~35~47 ~150~35~48 minecraft:stone
setblock ~151~35~47 minecraft:sea_lantern
setblock ~152~35~47 minecraft:stone
fill ~152~41~47 ~181~41~48 minecraft:stone
fill ~153~35~47 ~153~36~47 minecraft:stonebrick
fill ~153~39~47 ~153~40~47 minecraft:stonebrick
fill ~154~34~47 ~156~34~47 minecraft:stone
fill ~157~18~47 ~160~18~48 minecraft:stone_block_slab 13
fill ~157~35~47 ~164~35~47 minecraft:stone_block_slab 5
fill ~165~18~47 ~168~18~48 minecraft:stone
fill ~165~35~47 ~172~35~47 minecraft:stone
fill ~168~42~47 ~168~44~47 minecraft:stone
fill ~169~42~47 ~170~42~47 minecraft:stone_brick_stairs
fill ~169~43~47 ~170~43~47 minecraft:sea_lantern
fill ~169~44~47 ~199~44~48 minecraft:stone
fill ~171~42~47 ~172~42~47 minecraft:stone
setblock ~171~43~47 minecraft:stone
fill ~172~43~47 ~173~43~47 minecraft:stone_brick_stairs
fill ~173~17~47 ~176~17~48 minecraft:stone_block_slab 13
fill ~173~36~47 ~180~36~47 minecraft:stone_block_slab 5
setblock ~173~42~47 minecraft:sea_lantern
fill ~174~42~47 ~174~43~47 minecraft:stone
fill ~175~42~47 ~178~42~47 minecraft:stone_brick_stairs
setblock ~175~43~47 minecraft:stone
setblock ~176~43~47 minecraft:sea_lantern
fill ~177~43~47 ~178~43~47 minecraft:stone_brick_stairs
fill ~179~42~47 ~179~43~47 minecraft:stone
setblock ~180~42~47 minecraft:sea_lantern
fill ~180~43~47 ~183~43~47 minecraft:stone
fill ~181~17~47 ~184~17~48 minecraft:stone
fill ~181~36~47 ~184~36~48 minecraft:stone
setblock ~181~42~47 minecraft:stone
setblock ~182~41~47 minecraft:sea_lantern
fill ~182~42~47 ~183~42~47 minecraft:stone_brick_stairs
fill ~183~41~47 ~189~41~48 minecraft:stone
fill ~184~42~47 ~186~42~47 minecraft:stone
setblock ~184~43~47 minecraft:sea_lantern
fill ~184~55~47 ~184~55~48 minecraft:stone_brick_stairs 3
fill ~184~56~47 ~184~56~53 minecraft:stone
setblock ~184~57~47 minecraft:stonebrick
fill ~184~58~47 ~184~58~52 minecraft:stone
fill ~185~43~47 ~189~43~47 minecraft:stone
setblock ~186~59~47 minecraft:cobblestone_wall 
fill ~186~60~47 ~186~61~47 minecraft:cobblestone_wall
setblock ~186~62~47 minecraft:stone_block_slab 5
fill ~187~42~47 ~188~42~47 minecraft:stone_brick_stairs
fill ~187~62~47 ~188~63~50 minecraft:stone
fill ~189~16~47 ~192~16~48 minecraft:stone_block_slab 13
fill ~189~37~47 ~192~37~48 minecraft:stone_block_slab 5
fill ~189~42~47 ~195~42~47 minecraft:stone
setblock ~189~59~47 minecraft:cobblestone_wall 
fill ~189~60~47 ~189~61~47 minecraft:cobblestone_wall
setblock ~189~62~47 minecraft:stone_block_slab 5
fill ~190~41~47 ~191~41~47 minecraft:sea_lantern
fill ~190~43~47 ~192~43~47 minecraft:stone_brick_stairs
fill ~192~41~47 ~192~41~48 minecraft:stone
fill ~193~41~47 ~194~41~47 minecraft:stone_brick_stairs
setblock ~193~43~47 minecraft:stone
fill ~193~55~47 ~193~55~57 minecraft:stone
setblock ~193~56~47 minecraft:stone
fill ~194~26~47 ~194~26~55 minecraft:stone_brick_stairs 2
fill ~194~27~47 ~194~27~55 minecraft:stone_brick_stairs 6
setblock ~194~43~47 minecraft:sea_lantern
fill ~195~25~47 ~195~25~55 minecraft:stone_brick_stairs 2
fill ~195~28~47 ~195~28~55 minecraft:stone_brick_stairs 6
fill ~195~41~47 ~203~41~48 minecraft:stone
setblock ~195~43~47 minecraft:stone
fill ~196~29~47 ~196~29~49 minecraft:stone_brick_stairs 6
setblock ~196~42~47 minecraft:sea_lantern
fill ~196~43~47 ~197~43~47 minecraft:stone_brick_stairs
fill ~197~16~47 ~205~16~48 minecraft:stone
fill ~197~37~47 ~200~37~48 minecraft:stone
fill ~197~42~47 ~198~42~47 minecraft:stone
setblock ~198~43~47 minecraft:stone
setblock ~198~45~47 minecraft:snow_layer
fill ~201~39~47 ~201~40~47 minecraft:sea_lantern
fill ~202~37~47 ~205~37~48 minecraft:stone
fill ~205~25~47 ~205~29~47 minecraft:stone
fill ~45~25~48 ~48~25~50 minecraft:stone
fill ~45~28~48 ~48~28~50 minecraft:stone
fill ~49~26~48 ~50~26~48 minecraft:stonebrick
fill ~49~27~48 ~51~27~48 minecraft:stone_brick_stairs
setblock ~51~26~48 minecraft:sea_lantern
setblock ~52~26~48 minecraft:stonebrick
setblock ~52~27~48 minecraft:stone
fill ~53~25~48 ~53~25~50 minecraft:stone
fill ~53~28~48 ~53~28~50 minecraft:stone
fill ~61~24~48 ~64~24~48 minecraft:stone_block_slab 13
fill ~61~25~48 ~64~25~50 minecraft:stone
fill ~61~28~48 ~64~28~50 minecraft:stone
fill ~61~29~48 ~64~29~48 minecraft:stone_block_slab 5
fill ~65~24~48 ~68~24~49 minecraft:stone
fill ~65~29~48 ~68~29~49 minecraft:stone
fill ~73~23~48 ~76~23~49 minecraft:stone_block_slab 13
fill ~73~26~48 ~73~27~48 minecraft:stone
fill ~73~30~48 ~76~30~49 minecraft:stone_block_slab 5
fill ~74~26~48 ~75~26~48 minecraft:stone_brick_stairs
fill ~74~27~48 ~77~27~48 minecraft:stone
fill ~76~26~48 ~77~26~48 minecraft:stone
fill ~81~23~48 ~84~23~49 minecraft:stone
fill ~81~30~48 ~84~30~49 minecraft:stone
fill ~89~22~48 ~92~22~49 minecraft:stone_block_slab 13
fill ~89~31~48 ~92~31~49 minecraft:stone_block_slab 5
fill ~97~22~48 ~100~22~49 minecraft:stone
fill ~97~31~48 ~100~31~49 minecraft:stone
fill ~105~21~48 ~108~21~49 minecraft:stone_block_slab 13
fill ~105~32~48 ~108~32~49 minecraft:stone_block_slab 5
fill ~113~21~48 ~116~21~49 minecraft:stone
fill ~113~32~48 ~116~32~49 minecraft:stone
fill ~121~20~48 ~124~20~49 minecraft:stone_block_slab 13
fill ~121~33~48 ~124~33~49 minecraft:stone_block_slab 5
fill ~124~5~48 ~124~7~48 minecraft:wool 8
fill ~125~5~48 ~126~7~48 minecraft:wool 15
fill ~127~5~48 ~127~7~48 minecraft:wool 8
fill ~129~20~48 ~132~20~49 minecraft:stone
fill ~129~33~48 ~132~33~49 minecraft:stone
fill ~137~19~48 ~140~19~49 minecraft:stone_block_slab 13
fill ~137~34~48 ~140~34~49 minecraft:stone_block_slab 5
fill ~141~34~48 ~146~34~48 minecraft:stone
fill ~141~35~48 ~141~36~48 minecraft:stone
fill ~142~35~48 ~143~35~48 minecraft:sea_lantern
fill ~142~36~48 ~146~36~48 minecraft:stone
setblock ~144~35~48 minecraft:stone
fill ~145~19~48 ~148~19~49 minecraft:stone
setblock ~145~35~48 minecraft:sea_lantern
setblock ~146~35~48 minecraft:stone
fill ~147~37~48 ~152~37~49 minecraft:stone_block_slab 5
setblock ~149~34~48 minecraft:stone
fill ~153~18~48 ~156~18~49 minecraft:stone_block_slab 13
fill ~153~35~48 ~153~35~51 minecraft:stone
fill ~153~36~48 ~153~36~54 minecraft:stonebrick
fill ~153~39~48 ~153~39~49 minecraft:stone
setblock ~153~40~48 minecraft:sea_lantern
fill ~154~35~48 ~160~35~48 minecraft:stone_block_slab 5
fill ~161~18~48 ~164~18~49 minecraft:stone
fill ~161~35~48 ~168~35~48 minecraft:stone
setblock ~168~42~48 minecraft:sea_lantern
fill ~168~43~48 ~168~44~48 minecraft:stone
fill ~169~17~48 ~172~17~49 minecraft:stone_block_slab 13
fill ~169~36~48 ~176~36~48 minecraft:stone_block_slab 5
fill ~177~17~48 ~180~17~49 minecraft:stone
fill ~177~36~48 ~180~36~49 minecraft:stone
setblock ~182~41~48 minecraft:stone
fill ~184~53~48 ~193~53~49 minecraft:stone_block_slab 13
fill ~184~54~48 ~184~54~51 minecraft:stone
setblock ~184~57~48 minecraft:sea_lantern
fill ~184~59~48 ~193~59~49 minecraft:stone_block_slab 5
fill ~185~16~48 ~188~16~49 minecraft:stone_block_slab 13
fill ~185~37~48 ~188~37~49 minecraft:stone_block_slab 5
fill ~186~62~48 ~186~63~49 minecraft:stone
fill ~187~61~48 ~188~61~49 minecraft:stone
fill ~187~64~48 ~188~64~49 minecraft:stone
fill ~189~62~48 ~189~63~49 minecraft:stone
fill ~190~41~48 ~191~41~48 minecraft:stone
fill ~193~16~48 ~196~16~49 minecraft:stone
fill ~193~37~48 ~196~37~49 minecraft:stone
fill ~193~41~48 ~194~41~48 minecraft:stone
fill ~193~54~48 ~193~54~51 minecraft:stone
fill ~193~56~48 ~193~56~49 minecraft:stone_brick_stairs 2
fill ~193~58~48 ~193~58~51 minecraft:stone
fill ~198~42~48 ~198~42~49 minecraft:stone
setblock ~198~43~48 minecraft:sea_lantern
setblock ~198~45~48 minecraft:snow_layer
fill ~201~39~48 ~201~40~48 minecraft:stone
fill ~41~25~49 ~44~25~51 minecraft:stone
fill ~41~28~49 ~44~28~51 minecraft:stone
fill ~45~26~49 ~46~26~49 minecraft:stone
setblock ~45~27~49 minecraft:stone
fill ~46~27~49 ~47~27~49 minecraft:stone_brick_stairs
fill ~47~26~49 ~48~26~49 minecraft:stonebrick
setblock ~48~27~49 minecraft:stone
fill ~53~24~49 ~54~24~50 minecraft:stone_block_slab 13
fill ~53~26~49 ~53~27~49 minecraft:stonebrick
fill ~53~29~49 ~54~29~50 minecraft:stone_block_slab 5
fill ~54~25~49 ~54~25~51 minecraft:stone
fill ~54~28~49 ~54~28~51 minecraft:stone
fill ~57~24~49 ~60~24~49 minecraft:stone_block_slab 13
fill ~57~25~49 ~60~25~51 minecraft:stone
fill ~57~28~49 ~60~28~51 minecraft:stone
fill ~57~29~49 ~60~29~49 minecraft:stone_block_slab 5
fill ~61~24~49 ~64~24~50 minecraft:stone
fill ~61~29~49 ~64~29~50 minecraft:stone
fill ~69~23~49 ~72~23~50 minecraft:stone_block_slab 13
fill ~69~26~49 ~69~27~49 minecraft:stone
fill ~69~30~49 ~72~30~50 minecraft:stone_block_slab 5
fill ~70~26~49 ~71~26~49 minecraft:stone_brick_stairs
setblock ~70~27~49 minecraft:sea_lantern
setblock ~71~27~49 minecraft:stonebrick
fill ~72~26~49 ~72~27~49 minecraft:stone
fill ~77~23~49 ~80~23~50 minecraft:stone
fill ~77~30~49 ~80~30~50 minecraft:stone
fill ~85~22~49 ~88~22~50 minecraft:stone_block_slab 13
fill ~85~31~49 ~88~31~50 minecraft:stone_block_slab 5
fill ~93~22~49 ~96~22~50 minecraft:stone
fill ~93~31~49 ~96~31~50 minecraft:stone
fill ~101~21~49 ~104~21~50 minecraft:stone_block_slab 13
fill ~101~32~49 ~104~32~50 minecraft:stone_block_slab 5
fill ~109~21~49 ~112~21~50 minecraft:stone
fill ~109~32~49 ~112~32~50 minecraft:stone
fill ~117~20~49 ~120~20~50 minecraft:stone_block_slab 13
fill ~117~33~49 ~120~33~50 minecraft:stone_block_slab 5
fill ~125~20~49 ~128~20~50 minecraft:stone
fill ~125~33~49 ~128~33~50 minecraft:stone
fill ~133~19~49 ~136~19~50 minecraft:stone_block_slab 13
fill ~133~34~49 ~136~34~50 minecraft:stone_block_slab 5
fill ~141~19~49 ~144~19~50 minecraft:stone
setblock ~141~34~49 minecraft:sea_lantern
setblock ~141~35~49 minecraft:stone_brick_stairs 3
setblock ~141~36~49 minecraft:stone
fill ~141~37~49 ~146~37~50 minecraft:stone_block_slab 5
fill ~142~34~49 ~146~34~49 minecraft:stone
fill ~149~18~49 ~152~18~50 minecraft:stone_block_slab 13
fill ~149~35~49 ~152~35~50 minecraft:stone_block_slab 5
fill ~152~42~49 ~154~42~50 minecraft:stone_block_slab 5
fill ~153~40~49 ~153~41~49 minecraft:stone
fill ~154~35~49 ~156~35~49 minecraft:stone_block_slab 5
fill ~154~44~49 ~167~44~50 minecraft:stone_block_slab 5
fill ~155~42~49 ~155~42~52 minecraft:stone
fill ~155~43~49 ~158~43~49 minecraft:stone
setblock ~156~42~49 minecraft:sea_lantern
fill ~157~18~49 ~160~18~50 minecraft:stone
fill ~157~35~49 ~164~35~49 minecraft:stone
fill ~157~42~49 ~159~42~49 minecraft:stone_brick_stairs
setblock ~159~43~49 minecraft:sea_lantern
fill ~160~42~49 ~160~43~49 minecraft:stone
fill ~161~42~49 ~162~42~49 minecraft:sea_lantern
fill ~161~43~49 ~163~43~49 minecraft:stone_brick_stairs
fill ~163~42~49 ~167~42~49 minecraft:stone
setblock ~164~43~49 minecraft:stone
fill ~165~17~49 ~168~17~50 minecraft:stone_block_slab 13
fill ~165~36~49 ~172~36~49 minecraft:stone_block_slab 5
setblock ~165~43~49 minecraft:sea_lantern
fill ~166~43~49 ~167~43~49 minecraft:stone
setblock ~168~44~49 minecraft:sea_lantern
fill ~168~45~49 ~200~45~50 minecraft:stone_block_slab 5
fill ~173~17~49 ~176~17~50 minecraft:stone
fill ~173~36~49 ~176~36~50 minecraft:stone
fill ~181~16~49 ~184~16~50 minecraft:stone_block_slab 13
fill ~181~37~49 ~184~37~50 minecraft:stone_block_slab 5
setblock ~184~55~49 minecraft:stone
fill ~184~57~49 ~184~57~51 minecraft:stonebrick
fill ~189~16~49 ~192~16~50 minecraft:stone
fill ~189~37~49 ~192~37~50 minecraft:stone
fill ~197~15~49 ~206~15~50 minecraft:stone_block_slab 13
fill ~197~23~49 ~201~23~49 minecraft:stone
fill ~197~30~49 ~201~30~49 minecraft:stone
fill ~197~38~49 ~200~38~50 minecraft:stone_block_slab 5
fill ~198~22~49 ~201~22~49 minecraft:stone
fill ~198~31~49 ~201~31~49 minecraft:stone
fill ~198~43~49 ~198~44~50 minecraft:stone
fill ~199~21~49 ~201~21~49 minecraft:stone
fill ~199~32~49 ~201~32~49 minecraft:stone
fill ~199~42~49 ~204~42~50 minecraft:stone_block_slab 5
setblock ~201~39~49 minecraft:sea_lantern
fill ~201~40~49 ~201~41~49 minecraft:stone
fill ~202~21~49 ~202~23~49 minecraft:stonebrick
fill ~202~30~49 ~202~32~49 minecraft:stonebrick
fill ~202~38~49 ~206~38~50 minecraft:stone_block_slab 5
fill ~203~16~49 ~203~16~75 minecraft:stone
fill ~203~21~49 ~203~23~49 minecraft:stone
fill ~203~30~49 ~203~32~49 minecraft:stone
fill ~203~37~49 ~203~37~75 minecraft:stone
fill ~204~16~49 ~204~16~58 minecraft:stone_brick_stairs 2
fill ~204~37~49 ~204~37~58 minecraft:stone_brick_stairs 6
fill ~37~25~50 ~40~25~52 minecraft:stone
fill ~37~28~50 ~40~28~52 minecraft:stone
setblock ~41~26~50 minecraft:stonebrick
setblock ~41~27~50 minecraft:stone
setblock ~42~26~50 minecraft:stone
fill ~42~27~50 ~43~27~50 minecraft:stone_brick_stairs
setblock ~43~26~50 minecraft:sea_lantern
fill ~44~26~50 ~44~27~50 minecraft:stone
fill ~49~24~50 ~52~24~51 minecraft:stone_block_slab 13
fill ~49~29~50 ~52~29~51 minecraft:stone_block_slab 5
setblock ~54~26~50 minecraft:stonebrick
setblock ~54~27~50 minecraft:stone
fill ~55~24~50 ~56~24~50 minecraft:stone_block_slab 13
fill ~55~25~50 ~56~25~52 minecraft:stone
fill ~55~28~50 ~56~28~52 minecraft:stone
fill ~55~29~50 ~56~29~50 minecraft:stone_block_slab 5
fill ~57~24~50 ~60~24~51 minecraft:stone
fill ~57~29~50 ~60~29~51 minecraft:stone
fill ~65~23~50 ~68~23~51 minecraft:stone_block_slab 13
setblock ~65~26~50 minecraft:stonebrick
setblock ~65~27~50 minecraft:stone
fill ~65~30~50 ~68~30~51 minecraft:stone_block_slab 5
fill ~66~26~50 ~67~26~50 minecraft:stone_brick_stairs
fill ~66~27~50 ~67~27~50 minecraft:stonebrick
fill ~68~26~50 ~68~27~50 minecraft:stone
fill ~73~23~50 ~76~23~51 minecraft:stone
fill ~73~30~50 ~76~30~51 minecraft:stone
fill ~81~22~50 ~84~22~51 minecraft:stone_block_slab 13
fill ~81~31~50 ~84~31~51 minecraft:stone_block_slab 5
fill ~89~22~50 ~92~22~52 minecraft:stone
fill ~89~31~50 ~92~31~51 minecraft:stone
fill ~97~21~50 ~100~21~51 minecraft:stone_block_slab 13
fill ~97~32~50 ~100~32~51 minecraft:stone_block_slab 5
fill ~105~21~50 ~108~21~51 minecraft:stone
fill ~105~32~50 ~108~32~51 minecraft:stone
fill ~113~20~50 ~116~20~51 minecraft:stone_block_slab 13
fill ~113~33~50 ~116~33~51 minecraft:stone_block_slab 5
fill ~121~20~50 ~124~20~51 minecraft:stone
fill ~121~33~50 ~124~33~51 minecraft:stone
fill ~129~19~50 ~132~19~51 minecraft:stone_block_slab 13
fill ~129~34~50 ~132~34~51 minecraft:stone_block_slab 5
fill ~137~19~50 ~140~19~51 minecraft:stone
fill ~137~34~50 ~144~34~50 minecraft:stone
fill ~141~35~50 ~141~35~51 minecraft:stone
setblock ~141~36~50 minecraft:sea_lantern
fill ~145~18~50 ~148~18~50 minecraft:stone_block_slab 13
fill ~145~35~50 ~148~35~51 minecraft:stone_block_slab 5
fill ~147~37~50 ~152~37~51 minecraft:stone
fill ~153~18~50 ~156~18~51 minecraft:stone
fill ~153~38~50 ~153~38~54 minecraft:stone
fill ~153~39~50 ~153~40~51 minecraft:stonebrick
fill ~153~41~50 ~153~41~53 minecraft:stone
fill ~154~35~50 ~160~35~50 minecraft:stone
fill ~155~43~50 ~155~43~51 minecraft:stone
fill ~161~17~50 ~164~17~51 minecraft:stone_block_slab 13
fill ~161~36~50 ~168~36~50 minecraft:stone_block_slab 5
fill ~168~44~50 ~168~44~52 minecraft:stone
fill ~169~17~50 ~172~17~51 minecraft:stone
fill ~169~36~50 ~172~36~51 minecraft:stone
fill ~177~16~50 ~180~16~51 minecraft:stone_block_slab 13
fill ~177~37~50 ~180~37~51 minecraft:stone_block_slab 5
fill ~184~53~50 ~193~53~51 minecraft:stone
setblock ~184~55~50 minecraft:sea_lantern
fill ~184~59~50 ~193~59~51 minecraft:stone
fill ~185~16~50 ~188~16~51 minecraft:stone
fill ~185~37~50 ~188~37~51 minecraft:stone
fill ~186~60~50 ~186~61~50 minecraft:cobblestone_wall
setblock ~186~62~50 minecraft:stone_block_slab 5
fill ~189~60~50 ~189~61~50 minecraft:cobblestone_wall
setblock ~189~62~50 minecraft:stone_block_slab 5
fill ~193~15~50 ~196~15~51 minecraft:stone_block_slab 13
fill ~193~38~50 ~196~38~51 minecraft:stone_block_slab 5
setblock ~193~56~50 minecraft:sea_lantern
fill ~196~24~50 ~198~24~52 minecraft:stone
fill ~196~29~50 ~198~29~52 minecraft:stone
fill ~197~23~50 ~197~23~52 minecraft:stone_brick_stairs 2
fill ~197~30~50 ~197~30~52 minecraft:stone_brick_stairs 6
fill ~198~22~50 ~198~22~52 minecraft:stone_brick_stairs 2
fill ~198~31~50 ~198~31~52 minecraft:stone_brick_stairs 6
setblock ~198~42~50 minecraft:sea_lantern
fill ~199~21~50 ~199~21~52 minecraft:stone_brick_stairs 2
fill ~199~24~50 ~199~24~52 minecraft:stonebrick
fill ~199~29~50 ~199~29~52 minecraft:stonebrick
fill ~199~32~50 ~199~32~52 minecraft:stone_brick_stairs 6
fill ~200~20~50 ~201~20~52 minecraft:stone
fill ~200~24~50 ~201~24~50 minecraft:stone
fill ~200~29~50 ~201~29~50 minecraft:stone
fill ~200~33~50 ~201~33~52 minecraft:stone
fill ~201~39~50 ~201~40~50 minecraft:stonebrick
setblock ~201~41~50 minecraft:stone
fill ~202~20~50 ~202~20~52 minecraft:stonebrick
fill ~202~21~50 ~202~23~52 minecraft:sea_lantern
fill ~202~24~50 ~202~24~52 minecraft:stonebrick
fill ~202~29~50 ~202~29~52 minecraft:stonebrick
fill ~202~30~50 ~202~32~52 minecraft:sea_lantern
fill ~202~33~50 ~202~33~52 minecraft:stonebrick
fill ~203~20~50 ~203~20~52 minecraft:stone
fill ~203~21~50 ~203~23~52 minecraft:air
fill ~203~24~50 ~203~24~52 minecraft:stone
fill ~203~29~50 ~203~29~52 minecraft:stone
fill ~203~30~50 ~203~32~52 minecraft:air
fill ~203~33~50 ~203~33~52 minecraft:stone
fill ~33~25~51 ~36~25~53 minecraft:stone
fill ~33~28~51 ~36~28~53 minecraft:stone
setblock ~37~26~51 minecraft:stonebrick
setblock ~37~27~51 minecraft:stone
fill ~38~26~51 ~39~27~51 minecraft:stone_brick_stairs
setblock ~40~26~51 minecraft:stonebrick
setblock ~40~27~51 minecraft:stone
fill ~45~24~51 ~48~24~52 minecraft:stone_block_slab 13
fill ~45~29~51 ~48~29~52 minecraft:stone_block_slab 5
fill ~53~24~51 ~56~24~52 minecraft:stone
fill ~53~29~51 ~56~29~52 minecraft:stone
setblock ~55~26~51 minecraft:stone
setblock ~55~27~51 minecraft:stonebrick
fill ~61~23~51 ~64~23~52 minecraft:stone_block_slab 13
fill ~61~26~51 ~61~27~51 minecraft:stone
fill ~61~30~51 ~64~30~52 minecraft:stone_block_slab 5
setblock ~62~26~51 minecraft:stone_brick_stairs
setblock ~62~27~51 minecraft:stonebrick
setblock ~63~26~51 minecraft:stonebrick
setblock ~63~27~51 minecraft:stone
setblock ~64~26~51 minecraft:stone
setblock ~64~27~51 minecraft:sea_lantern
fill ~69~23~51 ~72~23~52 minecraft:stone
fill ~69~30~51 ~72~30~52 minecraft:stone
fill ~77~22~51 ~80~22~52 minecraft:stone_block_slab 13
fill ~77~31~51 ~80~31~52 minecraft:stone_block_slab 5
fill ~85~22~51 ~88~22~52 minecraft:stone
fill ~85~31~51 ~88~31~52 minecraft:stone
fill ~89~23~51 ~89~28~51 minecraft:sea_lantern
fill ~90~23~51 ~109~28~51 minecraft:stone
fill ~93~21~51 ~96~21~51 minecraft:stone_block_slab 13
fill ~93~32~51 ~96~32~52 minecraft:stone_block_slab 5
fill ~101~21~51 ~104~21~51 minecraft:stone
fill ~101~32~51 ~104~32~52 minecraft:stone
fill ~109~20~51 ~112~20~51 minecraft:stone_block_slab 13
fill ~109~21~51 ~109~21~73 minecraft:stone
fill ~109~33~51 ~112~33~52 minecraft:stone_block_slab 5
fill ~110~23~51 ~110~28~51 minecraft:sea_lantern
fill ~117~20~51 ~120~20~52 minecraft:stone
fill ~117~33~51 ~120~33~52 minecraft:stone
fill ~125~19~51 ~128~19~52 minecraft:stone_block_slab 13
fill ~125~34~51 ~128~34~52 minecraft:stone_block_slab 5
fill ~133~19~51 ~136~19~52 minecraft:stone
fill ~133~34~51 ~140~34~51 minecraft:stone
fill ~141~18~51 ~145~18~51 minecraft:stone_block_slab 13
fill ~141~36~51 ~141~37~52 minecraft:stone
fill ~142~35~51 ~144~35~52 minecraft:stone_block_slab 5
fill ~142~37~51 ~146~37~52 minecraft:stone
fill ~146~16~51 ~150~18~51 minecraft:stone
fill ~149~35~51 ~152~35~52 minecraft:stone
fill ~151~18~51 ~152~18~52 minecraft:stone
fill ~152~42~51 ~154~42~52 minecraft:stone
fill ~154~35~51 ~156~35~51 minecraft:stone
fill ~154~44~51 ~167~44~52 minecraft:stone
fill ~157~17~51 ~160~17~52 minecraft:stone_block_slab 13
fill ~157~36~51 ~164~36~51 minecraft:stone_block_slab 5
fill ~165~17~51 ~168~17~52 minecraft:stone
fill ~165~36~51 ~168~36~52 minecraft:stone
fill ~168~45~51 ~200~45~52 minecraft:stone
fill ~173~16~51 ~176~16~52 minecraft:stone_block_slab 13
fill ~173~37~51 ~176~37~52 minecraft:stone_block_slab 5
fill ~181~16~51 ~184~16~52 minecraft:stone
fill ~181~37~51 ~184~37~52 minecraft:stone
setblock ~184~55~51 minecraft:stonebrick
fill ~189~15~51 ~192~15~52 minecraft:stone_block_slab 13
fill ~189~38~51 ~192~38~52 minecraft:stone_block_slab 5
fill ~193~56~51 ~193~57~53 minecraft:stone
fill ~197~15~51 ~206~15~52 minecraft:stone
fill ~197~38~51 ~200~38~52 minecraft:stone
fill ~199~42~51 ~204~42~52 minecraft:stone
fill ~199~43~51 ~199~43~52 minecraft:stone
setblock ~199~44~51 minecraft:stone
setblock ~200~24~51 minecraft:stonebrick
setblock ~200~29~51 minecraft:stonebrick
setblock ~200~46~51 minecraft:snow_layer
fill ~201~24~51 ~201~24~52 minecraft:stone
fill ~201~29~51 ~201~29~52 minecraft:stone
fill ~201~39~51 ~201~39~56 minecraft:stone
fill ~201~40~51 ~201~40~52 minecraft:stonebrick
fill ~201~41~51 ~201~41~52 minecraft:sea_lantern
fill ~202~38~51 ~206~38~52 minecraft:stone
fill ~29~25~52 ~32~25~54 minecraft:stone
fill ~29~28~52 ~32~28~54 minecraft:stone
setblock ~33~26~52 minecraft:stonebrick
setblock ~33~27~52 minecraft:stone
fill ~34~26~52 ~34~27~52 minecraft:stone_brick_stairs
fill ~35~26~52 ~36~26~52 minecraft:stone
setblock ~35~27~52 minecraft:sea_lantern
setblock ~36~27~52 minecraft:stone
fill ~41~24~52 ~44~24~53 minecraft:stone_block_slab 13
fill ~41~29~52 ~44~29~53 minecraft:stone_block_slab 5
fill ~49~24~52 ~52~24~53 minecraft:stone
fill ~49~29~52 ~52~29~53 minecraft:stone
fill ~56~26~52 ~57~26~52 minecraft:stonebrick
setblock ~56~27~52 minecraft:stone
fill ~57~23~52 ~60~23~53 minecraft:stone_block_slab 13
setblock ~57~27~52 minecraft:sea_lantern
fill ~57~30~52 ~60~30~53 minecraft:stone_block_slab 5
fill ~58~26~52 ~59~27~52 minecraft:stone
fill ~60~26~52 ~60~27~52 minecraft:stonebrick
fill ~65~23~52 ~68~23~53 minecraft:stone
fill ~65~30~52 ~68~30~53 minecraft:stone
fill ~73~22~52 ~76~22~53 minecraft:stone_block_slab 13
fill ~73~31~52 ~76~31~53 minecraft:stone_block_slab 5
fill ~81~22~52 ~84~22~53 minecraft:stone
fill ~81~31~52 ~84~31~53 minecraft:stone
fill ~89~21~52 ~89~21~53 minecraft:stone_block_slab 13
fill ~89~23~52 ~89~27~52 minecraft:stained_glass 8
fill ~89~28~52 ~89~28~70 minecraft:sea_lantern
fill ~89~32~52 ~92~32~53 minecraft:stone_block_slab 5
fill ~90~28~52 ~90~28~71 minecraft:stone
fill ~91~29~52 ~109~29~70 minecraft:stone
fill ~93~22~52 ~109~22~52 minecraft:stone
fill ~97~32~52 ~100~32~53 minecraft:stone
fill ~105~33~52 ~108~33~53 minecraft:stone_block_slab 5
fill ~110~20~52 ~112~20~52 minecraft:stone_block_slab 13
fill ~110~22~52 ~110~22~71 minecraft:sea_lantern
fill ~110~23~52 ~110~27~52 minecraft:stained_glass 8
fill ~110~28~52 ~110~28~71 minecraft:sea_lantern
fill ~113~20~52 ~116~20~53 minecraft:stone
fill ~113~33~52 ~116~33~53 minecraft:stone
fill ~121~19~52 ~124~19~53 minecraft:stone_block_slab 13
fill ~121~34~52 ~124~34~53 minecraft:stone_block_slab 5
fill ~129~19~52 ~132~19~53 minecraft:stone
fill ~129~34~52 ~136~34~52 minecraft:stone
fill ~137~18~52 ~144~18~52 minecraft:stone_block_slab 13
fill ~137~35~52 ~140~35~53 minecraft:stone_block_slab 5
setblock ~141~35~52 minecraft:sea_lantern
fill ~145~16~52 ~145~18~52 minecraft:stone
fill ~145~35~52 ~148~35~53 minecraft:stone
fill ~146~15~52 ~150~15~52 minecraft:stone
fill ~146~18~52 ~150~18~52 minecraft:stone
fill ~147~38~52 ~152~38~53 minecraft:stone_block_slab 5
fill ~151~16~52 ~151~17~52 minecraft:stone
fill ~153~17~52 ~156~17~53 minecraft:stone_block_slab 13
fill ~153~39~52 ~153~39~53 minecraft:stone
fill ~153~40~52 ~153~40~53 minecraft:stone_brick_stairs 3
fill ~154~36~52 ~160~36~52 minecraft:stone_block_slab 5
setblock ~155~43~52 minecraft:sea_lantern
fill ~161~17~52 ~164~17~53 minecraft:stone
fill ~161~36~52 ~164~36~53 minecraft:stone
fill ~169~16~52 ~172~16~53 minecraft:stone_block_slab 13
fill ~169~37~52 ~172~37~53 minecraft:stone_block_slab 5
fill ~177~16~52 ~180~16~53 minecraft:stone
fill ~177~37~52 ~180~37~53 minecraft:stone
fill ~184~52~52 ~193~52~53 minecraft:stone_block_slab 13
fill ~184~53~52 ~184~53~57 minecraft:stone
fill ~184~54~52 ~184~54~53 minecraft:stone_brick_stairs 3
fill ~184~55~52 ~184~55~70 minecraft:stone
fill ~184~57~52 ~184~57~70 minecraft:stone
fill ~184~59~52 ~184~59~54 minecraft:stone
fill ~184~60~52 ~193~60~53 minecraft:stone_block_slab 5
fill ~185~15~52 ~188~15~53 minecraft:stone_block_slab 13
fill ~185~38~52 ~188~38~53 minecraft:stone_block_slab 5
fill ~193~15~52 ~196~15~53 minecraft:stone
fill ~193~38~52 ~196~38~53 minecraft:stone
fill ~193~53~52 ~193~53~57 minecraft:stone
fill ~193~54~52 ~193~54~53 minecraft:stonebrick
setblock ~193~58~52 minecraft:stonebrick
fill ~193~59~52 ~193~59~55 minecraft:stone
fill ~199~44~52 ~199~44~53 minecraft:stone_brick_stairs 2
setblock ~200~24~52 minecraft:stone
setblock ~200~29~52 minecraft:stone
setblock ~206~39~52 minecraft:snow_layer
fill ~25~25~53 ~28~25~55 minecraft:stone
fill ~25~28~53 ~28~28~55 minecraft:stone
setblock ~29~26~53 minecraft:stone
fill ~29~27~53 ~31~27~53 minecraft:stone_brick_stairs
setblock ~30~26~53 minecraft:stone_brick_stairs
setblock ~31~26~53 minecraft:stonebrick
setblock ~32~26~53 minecraft:sea_lantern
setblock ~32~27~53 minecraft:stonebrick
fill ~37~24~53 ~40~24~54 minecraft:stone_block_slab 13
fill ~37~29~53 ~40~29~54 minecraft:stone_block_slab 5
fill ~45~24~53 ~48~24~54 minecraft:stone
fill ~45~29~53 ~48~29~54 minecraft:stone
fill ~53~23~53 ~56~23~54 minecraft:stone_block_slab 13
fill ~53~30~53 ~56~30~54 minecraft:stone_block_slab 5
fill ~61~23~53 ~64~23~54 minecraft:stone
fill ~61~30~53 ~64~30~54 minecraft:stone
fill ~69~22~53 ~72~22~54 minecraft:stone_block_slab 13
fill ~69~31~53 ~72~31~54 minecraft:stone_block_slab 5
fill ~77~22~53 ~80~22~54 minecraft:stone
fill ~77~31~53 ~80~31~54 minecraft:stone
fill ~85~21~53 ~88~21~54 minecraft:stone_block_slab 13
fill ~85~22~53 ~88~22~69 minecraft:concrete 7
fill ~85~32~53 ~88~32~54 minecraft:stone_block_slab 5
fill ~89~22~53 ~89~22~70 minecraft:sea_lantern
fill ~89~23~53 ~89~27~69 minecraft:stained_glass_pane 8
fill ~90~22~53 ~90~22~72 minecraft:stone
fill ~91~28~53 ~109~28~53 minecraft:stone
fill ~93~32~53 ~96~32~54 minecraft:stone
fill ~101~33~53 ~104~33~54 minecraft:stone_block_slab 5
fill ~109~22~53 ~109~22~71 minecraft:stone
fill ~109~33~53 ~112~33~54 minecraft:stone
fill ~110~20~53 ~112~20~54 minecraft:stone
fill ~110~23~53 ~110~27~69 minecraft:stained_glass_pane 8
fill ~117~19~53 ~120~19~54 minecraft:stone_block_slab 13
fill ~117~34~53 ~120~34~54 minecraft:stone_block_slab 5
fill ~125~19~53 ~128~19~54 minecraft:stone
fill ~125~34~53 ~132~34~53 minecraft:stone
fill ~133~18~53 ~140~18~53 minecraft:stone_block_slab 13
fill ~133~35~53 ~136~35~54 minecraft:stone_block_slab 5
fill ~141~18~53 ~148~18~53 minecraft:stone
fill ~141~35~53 ~144~35~54 minecraft:stone
fill ~141~36~53 ~141~36~54 minecraft:stone_brick_stairs 3
fill ~141~37~53 ~141~37~54 minecraft:stone
fill ~141~38~53 ~146~38~54 minecraft:stone_block_slab 5
fill ~144~16~53 ~144~17~53 minecraft:stone
setblock ~145~15~53 minecraft:stone
fill ~146~14~53 ~150~14~53 minecraft:stone
fill ~149~17~53 ~150~17~54 minecraft:stone_block_slab 13
fill ~149~36~53 ~152~36~54 minecraft:stone_block_slab 5
setblock ~151~15~53 minecraft:stone
fill ~152~16~53 ~152~17~54 minecraft:stone
fill ~152~43~53 ~154~43~54 minecraft:stone_block_slab 5
setblock ~153~42~53 minecraft:stone
fill ~154~36~53 ~156~36~53 minecraft:stone_block_slab 5
fill ~154~45~53 ~167~45~54 minecraft:stone_block_slab 5
fill ~155~43~53 ~155~44~53 minecraft:stone
fill ~157~17~53 ~160~17~54 minecraft:stone
fill ~157~36~53 ~160~36~54 minecraft:stone
fill ~165~16~53 ~168~16~54 minecraft:stone_block_slab 13
fill ~165~37~53 ~168~37~54 minecraft:stone_block_slab 5
setblock ~168~45~53 minecraft:stone
fill ~168~46~53 ~200~46~54 minecraft:stone_block_slab 5
fill ~173~16~53 ~176~16~54 minecraft:stone
fill ~173~37~53 ~176~37~54 minecraft:stone
fill ~181~15~53 ~184~15~54 minecraft:stone_block_slab 13
fill ~181~38~53 ~184~38~54 minecraft:stone_block_slab 5
setblock ~184~58~53 minecraft:sea_lantern
fill ~189~15~53 ~192~15~54 minecraft:stone
fill ~189~38~53 ~192~38~54 minecraft:stone
setblock ~193~58~53 minecraft:sea_lantern
fill ~196~24~53 ~196~24~56 minecraft:stone_brick_stairs 2
fill ~196~29~53 ~196~29~55 minecraft:stone_brick_stairs 6
fill ~197~14~53 ~207~14~54 minecraft:stone_block_slab 13
fill ~197~23~53 ~201~23~53 minecraft:stone
fill ~197~30~53 ~201~30~53 minecraft:stone
fill ~197~39~53 ~200~39~54 minecraft:stone_block_slab 5
fill ~198~22~53 ~201~22~53 minecraft:stone
fill ~198~31~53 ~201~31~53 minecraft:stone
fill ~199~21~53 ~201~21~53 minecraft:stone
fill ~199~32~53 ~201~32~53 minecraft:stone
fill ~199~42~53 ~199~42~55 minecraft:stone
setblock ~199~43~53 minecraft:sea_lantern
fill ~199~45~53 ~199~45~54 minecraft:stone
fill ~200~20~53 ~200~20~69 minecraft:stone_brick_stairs 2
fill ~200~33~53 ~200~33~69 minecraft:stone_brick_stairs 6
fill ~200~43~53 ~205~43~54 minecraft:stone_block_slab 5
fill ~201~40~53 ~201~42~53 minecraft:stone
fill ~202~21~53 ~202~23~53 minecraft:stonebrick
fill ~202~30~53 ~202~32~53 minecraft:stonebrick
fill ~202~39~53 ~207~39~54 minecraft:stone_block_slab 5
fill ~203~21~53 ~203~23~53 minecraft:stone
fill ~203~30~53 ~203~32~53 minecraft:stone
fill ~204~15~53 ~204~15~71 minecraft:stone
fill ~204~38~53 ~204~38~71 minecraft:stone
fill ~205~15~53 ~205~15~58 minecraft:stone_brick_stairs 2
fill ~205~38~53 ~205~38~58 minecraft:stone_brick_stairs 6
fill ~21~25~54 ~24~25~56 minecraft:stone
fill ~21~28~54 ~24~28~56 minecraft:stone
fill ~25~26~54 ~26~26~54 minecraft:stonebrick
setblock ~25~27~54 minecraft:stone
fill ~26~27~54 ~28~27~54 minecraft:stonebrick
setblock ~27~26~54 minecraft:sea_lantern
setblock ~28~26~54 minecraft:stonebrick
fill ~33~24~54 ~36~24~55 minecraft:stone_block_slab 13
fill ~33~29~54 ~36~29~55 minecraft:stone_block_slab 5
fill ~41~24~54 ~44~24~55 minecraft:stone
fill ~41~29~54 ~44~29~55 minecraft:stone
fill ~49~23~54 ~52~23~55 minecraft:stone_block_slab 13
fill ~49~30~54 ~52~30~55 minecraft:stone_block_slab 5
fill ~57~23~54 ~60~23~55 minecraft:stone
fill ~57~30~54 ~60~30~55 minecraft:stone
fill ~65~22~54 ~68~22~55 minecraft:stone_block_slab 13
fill ~65~31~54 ~68~31~55 minecraft:stone_block_slab 5
fill ~73~22~54 ~76~22~55 minecraft:stone
fill ~73~31~54 ~76~31~55 minecraft:stone
fill ~81~21~54 ~84~21~55 minecraft:stone_block_slab 13
fill ~81~32~54 ~84~32~55 minecraft:stone_block_slab 5
fill ~89~21~54 ~89~21~68 minecraft:stone
fill ~89~32~54 ~92~32~55 minecraft:stone
fill ~97~33~54 ~100~33~55 minecraft:stone_block_slab 5
fill ~105~33~54 ~108~33~55 minecraft:stone
fill ~109~28~54 ~109~28~71 minecraft:stone
fill ~113~19~54 ~116~19~55 minecraft:stone_block_slab 13
fill ~113~34~54 ~116~34~55 minecraft:stone_block_slab 5
fill ~121~19~54 ~124~19~55 minecraft:stone
fill ~121~34~54 ~128~34~54 minecraft:stone
fill ~129~18~54 ~136~18~54 minecraft:stone_block_slab 13
fill ~129~35~54 ~132~35~55 minecraft:stone_block_slab 5
fill ~137~18~54 ~144~18~54 minecraft:stone
fill ~137~35~54 ~140~35~55 minecraft:stone
fill ~143~16~54 ~143~17~54 minecraft:stone
setblock ~144~15~54 minecraft:stone
setblock ~145~14~54 minecraft:stone
fill ~145~17~54 ~148~17~55 minecraft:stone_block_slab 13
fill ~145~36~54 ~148~36~55 minecraft:stone_block_slab 5
fill ~146~13~54 ~150~13~55 minecraft:stone
fill ~147~38~54 ~152~38~55 minecraft:stone
setblock ~151~14~54 minecraft:stone
setblock ~151~17~54 minecraft:stone_block_slab 13
setblock ~152~15~54 minecraft:stone
fill ~153~16~54 ~153~17~55 minecraft:stone
fill ~153~39~54 ~153~39~55 minecraft:stone_brick_stairs 3
fill ~153~40~54 ~153~40~58 minecraft:stone
setblock ~153~41~54 minecraft:sea_lantern
fill ~153~42~54 ~153~42~55 minecraft:stone_brick_stairs 3
fill ~154~17~54 ~156~17~55 minecraft:stone
fill ~154~36~54 ~156~36~55 minecraft:stone
setblock ~155~43~54 minecraft:stone_brick_stairs 3
setblock ~155~44~54 minecraft:stone
fill ~161~16~54 ~164~16~55 minecraft:stone_block_slab 13
fill ~161~37~54 ~164~37~55 minecraft:stone_block_slab 5
setblock ~168~45~54 minecraft:sea_lantern
fill ~169~16~54 ~172~16~55 minecraft:stone
fill ~169~37~54 ~172~37~55 minecraft:stone
fill ~177~15~54 ~180~15~55 minecraft:stone_block_slab 13
fill ~177~38~54 ~180~38~55 minecraft:stone_block_slab 5
fill ~184~52~54 ~193~52~54 minecraft:stone
fill ~184~54~54 ~184~54~55 minecraft:stone
fill ~184~56~54 ~184~56~57 minecraft:stone_brick_stairs 3
setblock ~184~58~54 minecraft:stone
fill ~184~60~54 ~193~60~55 minecraft:stone
fill ~185~15~54 ~188~15~55 minecraft:stone
fill ~185~38~54 ~188~38~55 minecraft:stone
setblock ~186~61~54 minecraft:stone_block_slab 5
setblock ~191~61~54 minecraft:stone_block_slab 5
fill ~193~14~54 ~196~14~55 minecraft:stone_block_slab 13
fill ~193~39~54 ~196~39~55 minecraft:stone_block_slab 5
fill ~193~54~54 ~193~54~55 minecraft:stone
fill ~193~56~54 ~193~56~55 minecraft:stone_brick_stairs 2
fill ~193~57~54 ~193~57~56 minecraft:stonebrick
fill ~193~58~54 ~193~58~57 minecraft:stone
fill ~197~23~54 ~197~23~57 minecraft:stone_brick_stairs 2
fill ~197~30~54 ~197~30~56 minecraft:stone_brick_stairs 6
fill ~198~22~54 ~198~22~58 minecraft:stone_brick_stairs 2
fill ~198~31~54 ~198~31~57 minecraft:stone_brick_stairs 6
fill ~199~21~54 ~199~21~68 minecraft:stone_brick_stairs 2
fill ~199~32~54 ~199~32~58 minecraft:stone_brick_stairs 6
fill ~199~43~54 ~199~43~55 minecraft:stone
setblock ~199~44~54 minecraft:stone
setblock ~201~40~54 minecraft:sea_lantern
setblock ~201~41~54 minecraft:stone
setblock ~201~42~54 minecraft:sea_lantern
fill ~17~25~55 ~20~25~57 minecraft:stone
fill ~17~28~55 ~20~28~57 minecraft:stone
