fill ~124~6~9 ~124~6~10 minecraft:quartz_stairs 5
setblock ~124~7~9 minecraft:quartz_stairs 5
setblock ~124~8~9 minecraft:quartz_stairs 1
setblock ~124~26~9 minecraft:quartz_stairs 5
fill ~124~27~9 ~124~28~9 minecraft:quartz_stairs 1
fill ~125~5~9 ~125~6~11 minecraft:quartz_block
fill ~125~7~9 ~126~7~9 minecraft:quartz_block
fill ~125~8~9 ~125~9~11 minecraft:quartz_block
fill ~125~25~9 ~125~26~11 minecraft:quartz_block
fill ~125~27~9 ~126~27~9 minecraft:quartz_block
fill ~125~28~9 ~125~29~11 minecraft:quartz_block
fill ~126~4~9 ~126~4~10 minecraft:quartz_stairs 5
setblock ~126~5~9 minecraft:quartz_stairs
setblock ~126~6~9 minecraft:quartz_stairs 5
setblock ~126~8~9 minecraft:quartz_stairs 1
setblock ~126~9~9 minecraft:quartz_stairs 4
setblock ~126~10~9 minecraft:quartz_stairs 1
setblock ~126~24~9 minecraft:quartz_stairs 5
setblock ~126~25~9 minecraft:quartz_stairs
setblock ~126~26~9 minecraft:quartz_stairs 5
setblock ~126~28~9 minecraft:quartz_stairs 1
setblock ~126~29~9 minecraft:quartz_stairs 4
fill ~126~30~9 ~126~30~10 minecraft:quartz_stairs 1
fill ~127~4~9 ~127~4~10 minecraft:quartz_block
setblock ~127~5~9 minecraft:quartz_stairs 7
setblock ~127~6~9 minecraft:stonebrick
setblock ~127~7~9 minecraft:stonebrick
setblock ~127~8~9 minecraft:stonebrick
setblock ~127~9~9 minecraft:quartz_stairs 3
fill ~127~10~9 ~127~10~11 minecraft:quartz_block
fill ~127~24~9 ~127~24~11 minecraft:quartz_block
setblock ~127~25~9 minecraft:quartz_stairs 7
setblock ~127~26~9 minecraft:stonebrick
setblock ~127~27~9 minecraft:stonebrick
setblock ~127~28~9 minecraft:stonebrick
setblock ~127~29~9 minecraft:quartz_stairs 3
fill ~127~30~9 ~127~30~10 minecraft:quartz_block
setblock ~128~4~9 minecraft:quartz_stairs 4
setblock ~128~5~9 minecraft:stone_brick_stairs 7
setblock ~128~6~9 minecraft:double_stone_block_slab
setblock ~128~7~9 minecraft:cobblestone_wall
setblock ~128~8~9 minecraft:double_stone_block_slab
setblock ~128~9~9 minecraft:stone_brick_stairs 3
fill ~128~10~9 ~128~10~10 minecraft:quartz_stairs
fill ~128~24~9 ~128~24~10 minecraft:quartz_stairs 4
setblock ~128~25~9 minecraft:stone_brick_stairs 7
setblock ~128~26~9 minecraft:double_stone_block_slab
setblock ~128~27~9 minecraft:cobblestone_wall
setblock ~128~28~9 minecraft:double_stone_block_slab
setblock ~128~29~9 minecraft:stone_brick_stairs 3
setblock ~128~30~9 minecraft:quartz_stairs
setblock ~129~4~9 minecraft:stone_block_slab 14
setblock ~129~5~9 minecraft:quartz_stairs 5
setblock ~129~6~9 minecraft:quartz_stairs 3
setblock ~129~7~9 minecraft:quartz_block
setblock ~129~8~9 minecraft:quartz_stairs 7
setblock ~129~9~9 minecraft:quartz_stairs 1
fill ~129~10~9 ~129~10~10 minecraft:stone_block_slab 6
fill ~129~24~9 ~129~24~10 minecraft:stone_block_slab 14
setblock ~129~25~9 minecraft:quartz_stairs 5
setblock ~129~26~9 minecraft:quartz_stairs 3
setblock ~129~27~9 minecraft:quartz_block
setblock ~129~28~9 minecraft:quartz_stairs 7
setblock ~129~29~9 minecraft:quartz_stairs 1
setblock ~129~30~9 minecraft:stone_block_slab 6
fill ~130~5~9 ~132~5~9 minecraft:quartz_stairs 3
fill ~130~6~9 ~131~6~9 minecraft:stone_brick_stairs 5
fill ~130~7~9 ~131~7~9 minecraft:cobblestone_wall
fill ~130~8~9 ~131~8~9 minecraft:stone_brick_stairs 1
fill ~130~9~9 ~132~9~9 minecraft:quartz_stairs 7
fill ~130~25~9 ~132~25~9 minecraft:quartz_stairs 3
fill ~130~26~9 ~131~26~9 minecraft:stone_brick_stairs 5
fill ~130~27~9 ~131~27~9 minecraft:cobblestone_wall
fill ~130~28~9 ~131~28~9 minecraft:stone_brick_stairs 1
fill ~130~29~9 ~132~29~9 minecraft:quartz_stairs 7
setblock ~132~6~9 minecraft:dispenser 3
setblock ~132~7~9 minecraft:quartz_block
setblock ~132~8~9 minecraft:dispenser 3
setblock ~132~26~9 minecraft:dispenser 3
setblock ~132~27~9 minecraft:quartz_block
setblock ~132~28~9 minecraft:dispenser 3
fill ~133~5~9 ~134~5~10 minecraft:quartz_block
fill ~133~6~9 ~134~6~9 minecraft:quartz_block
setblock ~133~7~9 minecraft:stone
fill ~133~8~9 ~134~9~9 minecraft:quartz_block
fill ~133~25~9 ~134~25~10 minecraft:quartz_block
fill ~133~26~9 ~134~26~9 minecraft:quartz_block
setblock ~133~27~9 minecraft:stone
fill ~133~28~9 ~134~29~9 minecraft:quartz_block
setblock ~134~7~9 minecraft:quartz_block
setblock ~134~27~9 minecraft:quartz_block
setblock ~135~5~9 minecraft:stone_brick_stairs 7
setblock ~135~6~9 minecraft:double_stone_block_slab 6
setblock ~135~7~9 minecraft:stonebrick
setblock ~135~8~9 minecraft:iron_block
setblock ~135~9~9 minecraft:stone_brick_stairs 3
setblock ~135~25~9 minecraft:stone_brick_stairs 7
setblock ~135~26~9 minecraft:iron_block
setblock ~135~27~9 minecraft:stonebrick
setblock ~135~28~9 minecraft:double_stone_block_slab 6
setblock ~135~29~9 minecraft:stone_brick_stairs 3
fill ~136~5~9 ~137~5~10 minecraft:quartz_block
fill ~136~6~9 ~137~9~9 minecraft:quartz_block
fill ~136~25~9 ~137~25~10 minecraft:quartz_block
fill ~136~26~9 ~137~29~9 minecraft:quartz_block
setblock ~138~5~9 minecraft:quartz_stairs 1
fill ~138~6~9 ~138~8~9 minecraft:cobblestone_wall
setblock ~138~9~9 minecraft:quartz_stairs 5
setblock ~138~25~9 minecraft:quartz_stairs 1
fill ~138~26~9 ~138~28~9 minecraft:cobblestone_wall
setblock ~138~29~9 minecraft:quartz_stairs 5
setblock ~139~5~9 minecraft:dispenser 3
setblock ~139~6~9 minecraft:quartz_stairs
fill ~139~7~9 ~139~8~9 minecraft:quartz_stairs 4
setblock ~139~9~9 minecraft:dispenser 3
setblock ~139~25~9 minecraft:dispenser 3
fill ~139~26~9 ~139~27~9 minecraft:quartz_stairs
setblock ~139~28~9 minecraft:quartz_stairs 4
setblock ~139~29~9 minecraft:dispenser 3
fill ~140~5~9 ~140~5~10 minecraft:quartz_block
setblock ~140~6~9 minecraft:quartz_stairs 4
fill ~140~7~9 ~140~7~10 minecraft:quartz_block
setblock ~140~8~9 minecraft:quartz_stairs
fill ~140~9~9 ~140~9~10 minecraft:quartz_block
fill ~140~25~9 ~140~25~10 minecraft:quartz_block
setblock ~140~26~9 minecraft:quartz_stairs 4
fill ~140~27~9 ~140~27~10 minecraft:quartz_block
setblock ~140~28~9 minecraft:quartz_stairs
fill ~140~29~9 ~140~29~10 minecraft:quartz_block
setblock ~109~9~10 minecraft:quartz_stairs 5
setblock ~109~10~10 minecraft:double_stone_block_slab
setblock ~109~11~10 minecraft:quartz_stairs 1
setblock ~109~23~10 minecraft:quartz_stairs 5
setblock ~109~24~10 minecraft:double_stone_block_slab
setblock ~109~25~10 minecraft:quartz_stairs 1
setblock ~110~9~10 minecraft:quartz_stairs 7
setblock ~110~10~10 minecraft:cobblestone_wall
setblock ~110~11~10 minecraft:quartz_stairs 3
setblock ~110~12~10 minecraft:quartz_stairs 1
setblock ~110~22~10 minecraft:quartz_stairs 5
setblock ~110~23~10 minecraft:quartz_stairs 7
setblock ~110~24~10 minecraft:cobblestone_wall
setblock ~110~25~10 minecraft:quartz_stairs 3
setblock ~111~9~10 minecraft:quartz_stairs 5
fill ~111~10~10 ~112~10~11 minecraft:quartz_block
setblock ~111~11~10 minecraft:quartz_stairs 1
fill ~111~12~10 ~112~12~10 minecraft:quartz_stairs 3
fill ~111~22~10 ~112~22~10 minecraft:quartz_stairs 7
setblock ~111~23~10 minecraft:quartz_stairs 5
fill ~111~24~10 ~112~24~11 minecraft:quartz_block
setblock ~111~25~10 minecraft:quartz_stairs 1
fill ~112~9~10 ~112~9~11 minecraft:quartz_block
fill ~112~11~10 ~114~11~11 minecraft:quartz_block
fill ~112~23~10 ~114~23~11 minecraft:quartz_block
fill ~112~25~10 ~112~25~11 minecraft:quartz_block
fill ~113~9~10 ~114~9~10 minecraft:stone_block_slab 14
setblock ~113~10~10 minecraft:stone_block_slab
setblock ~113~12~10 minecraft:stone_block_slab 6
setblock ~113~22~10 minecraft:stone_block_slab 6
setblock ~113~24~10 minecraft:stone_block_slab 8
fill ~113~25~10 ~114~25~10 minecraft:stone_block_slab 14
setblock ~114~8~10 minecraft:quartz_stairs 3
setblock ~114~10~10 minecraft:stone_brick_stairs
fill ~114~12~10 ~116~12~10 minecraft:quartz_stairs 3
fill ~114~22~10 ~116~22~10 minecraft:quartz_stairs 7
setblock ~114~24~10 minecraft:stone_brick_stairs 4
setblock ~114~26~10 minecraft:quartz_stairs 7
fill ~115~8~10 ~116~8~11 minecraft:quartz_block
fill ~115~9~10 ~116~9~10 minecraft:quartz_stairs
fill ~115~10~10 ~116~10~10 minecraft:dropper 3
fill ~115~11~10 ~116~11~10 minecraft:quartz_stairs 4
fill ~115~23~10 ~116~23~10 minecraft:quartz_stairs
fill ~115~24~10 ~116~24~10 minecraft:dropper 3
fill ~115~25~10 ~116~25~10 minecraft:quartz_stairs 4
fill ~115~26~10 ~116~26~11 minecraft:quartz_block
setblock ~116~6~10 minecraft:stone_block_slab 8
setblock ~116~7~10 minecraft:quartz_block
setblock ~116~27~10 minecraft:quartz_block
setblock ~116~28~10 minecraft:stone_block_slab
fill ~117~8~10 ~118~8~10 minecraft:stone_brick_stairs 3
fill ~117~9~10 ~117~11~11 minecraft:quartz_block
fill ~117~23~10 ~117~23~17 minecraft:quartz_block
fill ~117~24~10 ~118~24~10 minecraft:wool 9
fill ~117~25~10 ~117~25~11 minecraft:quartz_block
fill ~117~26~10 ~118~26~10 minecraft:stone_brick_stairs 7
setblock ~118~7~10 minecraft:cobblestone_wall
fill ~118~9~10 ~119~9~10 minecraft:quartz_stairs 7
fill ~118~10~10 ~118~10~11 minecraft:quartz_block
fill ~118~11~10 ~119~11~10 minecraft:quartz_stairs 3
fill ~118~23~10 ~119~23~10 minecraft:quartz_stairs 7
fill ~118~25~10 ~119~25~10 minecraft:quartz_stairs 3
setblock ~118~27~10 minecraft:cobblestone_wall
setblock ~119~7~10 minecraft:cobblestone_wall
fill ~119~8~10 ~124~8~11 minecraft:quartz_block
fill ~119~26~10 ~124~26~11 minecraft:quartz_block
setblock ~119~27~10 minecraft:cobblestone_wall
setblock ~120~6~10 minecraft:stone_brick_stairs 3
setblock ~120~7~10 minecraft:stone_brick_stairs 7
setblock ~120~27~10 minecraft:stone_brick_stairs 3
setblock ~120~28~10 minecraft:stone_brick_stairs 7
setblock ~121~4~10 minecraft:quartz_stairs 7
fill ~121~5~10 ~121~7~10 minecraft:double_stone_block_slab 6
setblock ~121~9~10 minecraft:quartz_block
setblock ~121~10~10 minecraft:quartz_stairs 3
setblock ~121~24~10 minecraft:quartz_stairs 7
setblock ~121~25~10 minecraft:quartz_block
fill ~121~27~10 ~121~29~10 minecraft:double_stone_block_slab 6
setblock ~121~30~10 minecraft:quartz_stairs 3
fill ~122~9~10 ~123~9~10 minecraft:furnace 3
fill ~122~10~10 ~123~10~10 minecraft:stone_block_slab
fill ~122~24~10 ~123~24~10 minecraft:stone_block_slab 8
fill ~122~25~10 ~123~25~10 minecraft:furnace 3
setblock ~123~6~10 minecraft:stonebrick
setblock ~123~28~10 minecraft:stonebrick
fill ~124~7~10 ~124~7~11 minecraft:quartz_block
setblock ~124~10~10 minecraft:quartz_stairs 3
setblock ~124~24~10 minecraft:quartz_stairs 7
fill ~124~27~10 ~124~27~11 minecraft:quartz_block
setblock ~124~28~10 minecraft:quartz_stairs 1
fill ~125~7~10 ~129~7~10 minecraft:stonebrick
fill ~125~10~10 ~126~10~11 minecraft:quartz_block
fill ~125~11~10 ~126~11~10 minecraft:stone_block_slab
fill ~125~23~10 ~126~23~10 minecraft:stone_block_slab 8
fill ~125~24~10 ~126~24~11 minecraft:quartz_block
fill ~125~27~10 ~129~27~10 minecraft:stonebrick
fill ~126~5~10 ~132~5~10 minecraft:quartz_block
fill ~126~6~10 ~130~6~10 minecraft:quartz_block
fill ~126~8~10 ~130~9~10 minecraft:quartz_block
fill ~126~25~10 ~132~25~10 minecraft:quartz_block
fill ~126~26~10 ~130~26~10 minecraft:quartz_block
fill ~126~28~10 ~130~29~10 minecraft:quartz_block
setblock ~127~11~10 minecraft:stone_brick_stairs 3
setblock ~127~23~10 minecraft:stone_brick_stairs 7
setblock ~128~4~10 minecraft:stone_brick_stairs 4
setblock ~128~30~10 minecraft:stone_brick_stairs
setblock ~129~4~10 minecraft:stone_block_slab 8
setblock ~129~30~10 minecraft:stone_block_slab
fill ~130~7~10 ~130~7~11 minecraft:quartz_block
setblock ~130~10~10 minecraft:stone_block_slab 6
setblock ~130~24~10 minecraft:stone_block_slab 14
fill ~130~27~10 ~130~27~11 minecraft:quartz_block
setblock ~131~4~10 minecraft:double_stone_block_slab 6
fill ~131~6~10 ~139~8~10 minecraft:stonebrick
fill ~131~9~10 ~139~9~10 minecraft:quartz_block
setblock ~131~10~10 minecraft:quartz_stairs 4
setblock ~131~24~10 minecraft:quartz_stairs
fill ~131~26~10 ~139~28~10 minecraft:stonebrick
fill ~131~29~10 ~139~29~10 minecraft:quartz_block
setblock ~131~30~10 minecraft:double_stone_block_slab 6
setblock ~132~4~10 minecraft:stone_block_slab 14
setblock ~132~10~10 minecraft:quartz_stairs 5
setblock ~132~24~10 minecraft:quartz_stairs 1
setblock ~132~30~10 minecraft:stone_block_slab 6
setblock ~133~4~10 minecraft:stone_brick_stairs 7
setblock ~133~10~10 minecraft:stone_block_slab 6
setblock ~133~24~10 minecraft:stone_block_slab 14
setblock ~133~30~10 minecraft:stone_brick_stairs 3
setblock ~134~4~10 minecraft:quartz_stairs 5
setblock ~134~10~10 minecraft:quartz_stairs 3
setblock ~134~24~10 minecraft:quartz_stairs 7
setblock ~134~30~10 minecraft:quartz_stairs 1
setblock ~135~4~10 minecraft:stone_block_slab 14
setblock ~135~5~10 minecraft:quartz_block
setblock ~135~10~10 minecraft:stone_block_slab 6
setblock ~135~24~10 minecraft:stone_block_slab 14
setblock ~135~25~10 minecraft:quartz_block
setblock ~135~30~10 minecraft:stone_block_slab 6
setblock ~136~4~10 minecraft:quartz_stairs 5
setblock ~136~10~10 minecraft:quartz_stairs 3
setblock ~136~24~10 minecraft:quartz_stairs 7
setblock ~136~30~10 minecraft:quartz_stairs 1
fill ~137~4~10 ~138~4~10 minecraft:stone_block_slab 14
setblock ~137~10~10 minecraft:stone_block_slab 6
setblock ~137~24~10 minecraft:stone_block_slab 14
fill ~137~30~10 ~138~30~10 minecraft:stone_block_slab 6
fill ~138~5~10 ~139~5~10 minecraft:quartz_block
fill ~138~25~10 ~139~25~10 minecraft:quartz_block
setblock ~139~10~10 minecraft:double_stone_block_slab 6
setblock ~139~24~10 minecraft:double_stone_block_slab 6
fill ~140~6~10 ~142~6~10 minecraft:quartz_block
fill ~140~8~10 ~142~8~10 minecraft:quartz_block
fill ~140~26~10 ~144~26~10 minecraft:quartz_block
fill ~140~28~10 ~143~28~10 minecraft:quartz_block
fill ~141~5~10 ~142~5~10 minecraft:quartz_stairs 7
fill ~141~7~10 ~142~7~10 minecraft:quartz_stairs 7
fill ~141~9~10 ~142~9~10 minecraft:quartz_stairs 3
fill ~141~25~10 ~144~25~10 minecraft:quartz_stairs 7
fill ~141~27~10 ~142~27~10 minecraft:quartz_stairs 3
fill ~141~29~10 ~144~29~10 minecraft:quartz_stairs 3
fill ~143~5~10 ~144~5~10 minecraft:wool 14
setblock ~143~6~10 minecraft:wool 14
fill ~143~7~10 ~144~7~10 minecraft:stone_brick_stairs 7
fill ~143~8~10 ~144~9~10 minecraft:wool 14
setblock ~143~27~10 minecraft:stone_brick_stairs 3
setblock ~144~6~10 minecraft:double_stone_block_slab
setblock ~144~27~10 minecraft:quartz_stairs 3
setblock ~144~28~10 minecraft:double_stone_block_slab
setblock ~145~5~10 minecraft:stone_brick_stairs 7
fill ~145~6~10 ~145~8~10 minecraft:stonebrick
setblock ~145~9~10 minecraft:stone_brick_stairs 3
setblock ~145~25~10 minecraft:stone_brick_stairs 7
fill ~145~26~10 ~145~28~10 minecraft:stonebrick
setblock ~145~29~10 minecraft:stone_brick_stairs 3
fill ~146~5~10 ~149~5~10 minecraft:quartz_stairs 7
fill ~146~6~10 ~149~6~10 minecraft:quartz_stairs 3
fill ~146~7~10 ~149~7~10 minecraft:quartz_block
fill ~146~8~10 ~149~8~10 minecraft:quartz_stairs 7
fill ~146~9~10 ~149~9~10 minecraft:quartz_stairs 3
fill ~146~25~10 ~149~25~10 minecraft:quartz_stairs 7
fill ~146~26~10 ~149~26~10 minecraft:quartz_stairs 3
fill ~146~27~10 ~149~27~10 minecraft:quartz_block
fill ~146~28~10 ~149~28~10 minecraft:quartz_stairs 7
fill ~146~29~10 ~149~29~10 minecraft:quartz_stairs 3
fill ~108~7~11 ~108~7~13 minecraft:stone_block_slab 14
fill ~108~8~11 ~111~9~11 minecraft:quartz_block
fill ~108~10~11 ~110~11~11 minecraft:quartz_block
fill ~108~12~11 ~109~12~12 minecraft:stone_block_slab 6
fill ~108~22~11 ~109~22~12 minecraft:stone_block_slab 14
fill ~108~23~11 ~111~23~11 minecraft:quartz_block
fill ~108~24~11 ~110~26~11 minecraft:quartz_block
fill ~108~27~11 ~108~27~13 minecraft:stone_block_slab 6
setblock ~109~7~11 minecraft:quartz_block
setblock ~109~27~11 minecraft:quartz_block
setblock ~110~6~11 minecraft:quartz_stairs 5
fill ~110~7~11 ~111~7~11 minecraft:quartz_stairs 3
fill ~110~12~11 ~111~12~11 minecraft:double_stone_block_slab 6
fill ~110~22~11 ~111~22~11 minecraft:double_stone_block_slab 6
fill ~110~27~11 ~111~27~11 minecraft:quartz_stairs 7
setblock ~110~28~11 minecraft:quartz_stairs 1
fill ~111~6~11 ~112~6~11 minecraft:double_stone_block_slab 6
setblock ~111~11~11 minecraft:quartz_block
setblock ~111~13~11 minecraft:stone_block_slab 6
setblock ~111~21~11 minecraft:stone_block_slab 14
fill ~111~25~11 ~111~26~11 minecraft:quartz_block
fill ~111~28~11 ~112~28~11 minecraft:double_stone_block_slab 6
fill ~112~7~11 ~113~7~11 minecraft:wool 9
fill ~112~8~11 ~113~8~13 minecraft:stonebrick
fill ~112~12~11 ~114~12~13 minecraft:stonebrick
fill ~112~22~11 ~114~22~13 minecraft:stonebrick
fill ~112~26~11 ~113~26~13 minecraft:stonebrick
fill ~112~27~11 ~113~27~12 minecraft:stonebrick
setblock ~113~5~11 minecraft:stone_block_slab 14
setblock ~113~6~11 minecraft:quartz_block
fill ~113~9~11 ~116~10~11 minecraft:quartz_block
fill ~113~24~11 ~124~24~11 minecraft:quartz_block
fill ~113~25~11 ~116~25~11 minecraft:quartz_block
setblock ~113~28~11 minecraft:quartz_block
setblock ~113~29~11 minecraft:stone_block_slab 6
fill ~114~6~11 ~115~6~11 minecraft:quartz_stairs 3
fill ~114~7~11 ~123~7~11 minecraft:quartz_block
setblock ~114~8~11 minecraft:quartz_block
fill ~114~26~11 ~114~27~11 minecraft:quartz_block
fill ~114~28~11 ~115~28~11 minecraft:quartz_stairs 7
fill ~115~5~11 ~116~5~12 minecraft:quartz_stairs 4
fill ~115~11~11 ~116~11~11 minecraft:quartz_block
fill ~115~12~11 ~115~12~12 minecraft:double_stone_block_slab 6
setblock ~115~13~11 minecraft:stone_block_slab 6
setblock ~115~21~11 minecraft:stone_block_slab 14
fill ~115~22~11 ~115~22~12 minecraft:double_stone_block_slab 6
fill ~115~23~11 ~116~23~11 minecraft:quartz_block
fill ~115~27~11 ~123~27~11 minecraft:quartz_block
fill ~115~29~11 ~116~29~12 minecraft:quartz_stairs
fill ~116~6~11 ~124~6~11 minecraft:quartz_block
setblock ~116~12~11 minecraft:quartz_block
setblock ~116~22~11 minecraft:quartz_block
fill ~116~28~11 ~124~28~11 minecraft:quartz_block
setblock ~117~5~11 minecraft:quartz_stairs
fill ~117~8~11 ~118~8~11 minecraft:quartz_block
setblock ~117~12~11 minecraft:stone_block_slab 6
setblock ~117~22~11 minecraft:stone_block_slab 14
fill ~117~26~11 ~118~26~11 minecraft:quartz_block
setblock ~117~29~11 minecraft:quartz_stairs 4
setblock ~118~4~11 minecraft:quartz_stairs 5
setblock ~118~5~11 minecraft:quartz_stairs 3
fill ~118~9~11 ~124~9~11 minecraft:quartz_block
fill ~118~11~11 ~121~11~17 minecraft:quartz_block
fill ~118~12~11 ~119~12~11 minecraft:quartz_stairs 3
fill ~118~22~11 ~119~22~11 minecraft:quartz_stairs 7
fill ~118~23~11 ~121~23~17 minecraft:quartz_block
fill ~118~25~11 ~124~25~11 minecraft:quartz_block
setblock ~118~29~11 minecraft:quartz_stairs 7
setblock ~118~30~11 minecraft:quartz_stairs 1
fill ~119~4~11 ~120~4~11 minecraft:quartz_stairs 6
fill ~119~5~11 ~120~5~11 minecraft:quartz_stairs 7
fill ~119~10~11 ~124~10~11 minecraft:quartz_block
fill ~119~29~11 ~120~29~11 minecraft:quartz_stairs 3
fill ~119~30~11 ~120~30~11 minecraft:quartz_stairs 2
setblock ~120~12~11 minecraft:stone_block_slab 6
setblock ~120~22~11 minecraft:stone_block_slab 14
fill ~121~4~11 ~121~5~11 minecraft:quartz_block
fill ~121~29~11 ~123~29~11 minecraft:quartz_block
setblock ~121~30~11 minecraft:quartz_block
setblock ~122~3~11 minecraft:quartz_stairs 5
fill ~122~4~11 ~123~4~11 minecraft:quartz_stairs 7
fill ~122~5~11 ~123~5~11 minecraft:quartz_block
fill ~122~11~11 ~123~11~11 minecraft:dropper 5
fill ~122~12~11 ~123~12~11 minecraft:stone_block_slab 6
fill ~122~22~11 ~123~22~11 minecraft:stone_block_slab 14
fill ~122~23~11 ~123~23~11 minecraft:dropper 5
fill ~122~30~11 ~123~30~11 minecraft:quartz_stairs 3
setblock ~122~31~11 minecraft:quartz_stairs 1
setblock ~123~3~11 minecraft:quartz_stairs 6
setblock ~123~31~11 minecraft:quartz_stairs 2
fill ~124~3~11 ~126~3~11 minecraft:quartz_block
fill ~124~4~11 ~124~4~16 minecraft:stonebrick
setblock ~124~5~11 minecraft:stonebrick
setblock ~124~11~11 minecraft:double_stone_block_slab 6
setblock ~124~23~11 minecraft:double_stone_block_slab 6
fill ~124~29~11 ~124~30~11 minecraft:stonebrick
fill ~124~31~11 ~126~31~11 minecraft:quartz_block
fill ~125~4~11 ~126~4~11 minecraft:quartz_block
fill ~125~7~11 ~126~7~11 minecraft:quartz_block
fill ~125~11~11 ~128~11~17 minecraft:quartz_block
fill ~125~23~11 ~128~23~17 minecraft:quartz_block
fill ~125~27~11 ~126~27~11 minecraft:quartz_block
fill ~125~30~11 ~126~30~11 minecraft:quartz_block
fill ~126~2~11 ~126~2~12 minecraft:stone_block_slab 14
fill ~126~5~11 ~126~6~11 minecraft:quartz_block
fill ~126~8~11 ~126~9~11 minecraft:quartz_block
fill ~126~25~11 ~130~25~11 minecraft:quartz_block
setblock ~126~26~11 minecraft:quartz_block
fill ~126~28~11 ~126~29~11 minecraft:quartz_block
fill ~126~32~11 ~126~32~12 minecraft:stone_block_slab 6
setblock ~127~4~11 minecraft:stone_brick_stairs 4
fill ~127~5~11 ~129~5~17 minecraft:stonebrick
fill ~127~6~11 ~129~8~12 minecraft:stonebrick
fill ~127~9~11 ~130~9~11 minecraft:quartz_block
fill ~127~12~11 ~127~12~13 minecraft:quartz_stairs 1
fill ~127~22~11 ~127~22~13 minecraft:quartz_stairs 5
fill ~127~26~11 ~129~29~12 minecraft:stonebrick
setblock ~127~30~11 minecraft:stone_brick_stairs
setblock ~128~4~11 minecraft:quartz_stairs 5
fill ~128~10~11 ~131~10~11 minecraft:quartz_block
setblock ~128~12~11 minecraft:double_stone_block_slab
setblock ~128~22~11 minecraft:double_stone_block_slab
fill ~128~24~11 ~131~24~11 minecraft:quartz_block
setblock ~128~30~11 minecraft:quartz_stairs 1
setblock ~129~4~11 minecraft:quartz_stairs 7
setblock ~129~11~11 minecraft:stone_brick_stairs 3
setblock ~129~23~11 minecraft:stone_brick_stairs 7
setblock ~129~30~11 minecraft:quartz_stairs 3
fill ~130~4~11 ~139~4~11 minecraft:quartz_block
fill ~130~5~11 ~130~5~12 minecraft:quartz_block
setblock ~130~6~11 minecraft:quartz_block
setblock ~130~8~11 minecraft:quartz_block
setblock ~130~26~11 minecraft:quartz_block
fill ~130~28~11 ~130~30~11 minecraft:quartz_block
fill ~131~5~11 ~141~5~11 minecraft:stonebrick
fill ~131~6~11 ~139~6~11 minecraft:cobblestone_wall
fill ~131~7~11 ~141~7~11 minecraft:stonebrick
fill ~131~8~11 ~139~8~11 minecraft:cobblestone_wall
fill ~131~9~11 ~141~9~11 minecraft:stonebrick
fill ~131~25~11 ~141~25~11 minecraft:stonebrick
fill ~131~26~11 ~139~26~11 minecraft:cobblestone_wall
fill ~131~27~11 ~141~27~11 minecraft:stonebrick
fill ~131~28~11 ~139~28~11 minecraft:cobblestone_wall
fill ~131~29~11 ~141~29~11 minecraft:stonebrick
fill ~131~30~11 ~139~30~11 minecraft:quartz_block
fill ~132~10~11 ~137~10~11 minecraft:stone_brick_stairs 3
fill ~132~24~11 ~137~24~11 minecraft:stone_brick_stairs 7
setblock ~134~3~11 minecraft:stone_block_slab 8
setblock ~134~31~11 minecraft:stone_block_slab
setblock ~136~3~11 minecraft:stone_block_slab 8
setblock ~136~31~11 minecraft:stone_block_slab
fill ~138~10~11 ~139~10~11 minecraft:quartz_block
fill ~138~24~11 ~139~24~11 minecraft:quartz_block
setblock ~140~4~11 minecraft:stone_brick_stairs 4
fill ~140~6~11 ~141~6~11 minecraft:stonebrick
fill ~140~8~11 ~141~8~11 minecraft:stonebrick
setblock ~140~10~11 minecraft:stone_brick_stairs
setblock ~140~24~11 minecraft:stone_brick_stairs 4
fill ~140~26~11 ~141~26~11 minecraft:stonebrick
fill ~140~28~11 ~141~28~11 minecraft:stonebrick
setblock ~140~30~11 minecraft:stone_brick_stairs
fill ~141~4~11 ~144~4~11 minecraft:stone_brick_stairs 7
fill ~141~10~11 ~144~10~11 minecraft:stone_brick_stairs 3
fill ~141~24~11 ~144~24~11 minecraft:stone_brick_stairs 7
fill ~141~30~11 ~144~30~11 minecraft:stone_brick_stairs 3
setblock ~142~5~11 minecraft:stone_brick_stairs 2
setblock ~142~9~11 minecraft:stone_brick_stairs 6
setblock ~142~25~11 minecraft:stone_brick_stairs 2
setblock ~142~29~11 minecraft:stone_brick_stairs 6
setblock ~143~5~11 minecraft:stone_brick_stairs
setblock ~143~9~11 minecraft:stone_brick_stairs 4
setblock ~143~25~11 minecraft:stone_brick_stairs
setblock ~143~29~11 minecraft:stone_brick_stairs 4
setblock ~145~4~11 minecraft:stonebrick
fill ~145~5~11 ~145~6~11 minecraft:stone_brick_stairs 3
setblock ~145~7~11 minecraft:stonebrick
fill ~145~8~11 ~145~9~11 minecraft:stone_brick_stairs 7
setblock ~145~10~11 minecraft:stonebrick
setblock ~145~24~11 minecraft:stonebrick
fill ~145~25~11 ~145~26~11 minecraft:stone_brick_stairs 3
setblock ~145~27~11 minecraft:stonebrick
fill ~145~28~11 ~145~29~11 minecraft:stone_brick_stairs 7
setblock ~145~30~11 minecraft:stonebrick
fill ~146~4~11 ~149~4~11 minecraft:quartz_block
fill ~146~5~11 ~146~5~12 minecraft:furnace 5
fill ~146~6~11 ~146~8~11 minecraft:furnace 5
setblock ~146~9~11 minecraft:furnace 2
fill ~146~10~11 ~149~10~11 minecraft:quartz_block
fill ~146~24~11 ~149~24~11 minecraft:quartz_block
fill ~146~25~11 ~146~25~12 minecraft:furnace 5
fill ~146~26~11 ~146~28~11 minecraft:furnace 5
setblock ~146~29~11 minecraft:furnace 2
fill ~146~30~11 ~149~30~11 minecraft:quartz_block
fill ~147~5~11 ~147~5~12 minecraft:stone
fill ~147~6~11 ~147~9~11 minecraft:stone
fill ~147~25~11 ~147~25~12 minecraft:stone
fill ~147~26~11 ~147~29~11 minecraft:stone
fill ~148~5~11 ~148~5~12 minecraft:bedrock
fill ~148~6~11 ~148~9~11 minecraft:bedrock
fill ~148~25~11 ~148~25~12 minecraft:bedrock
fill ~148~26~11 ~148~29~11 minecraft:bedrock
fill ~149~5~11 ~149~5~12 minecraft:stone_brick_stairs 7
setblock ~149~6~11 minecraft:stone_brick_stairs 7
setblock ~149~7~11 minecraft:cobblestone_wall
fill ~149~8~11 ~149~9~11 minecraft:stone_brick_stairs 3
fill ~149~25~11 ~149~25~12 minecraft:stone_brick_stairs 7
setblock ~149~26~11 minecraft:stone_brick_stairs 7
setblock ~149~27~11 minecraft:cobblestone_wall
fill ~149~28~11 ~149~29~11 minecraft:stone_brick_stairs 3
setblock ~149~31~11 minecraft:quartz_block
fill ~108~8~12 ~108~11~12 minecraft:quartz_block
fill ~108~23~12 ~108~26~12 minecraft:quartz_block
fill ~109~7~12 ~110~7~16 minecraft:double_stone_block_slab 6
fill ~109~8~12 ~111~8~13 minecraft:stonebrick
fill ~109~9~12 ~110~9~16 minecraft:wool 7
fill ~109~10~12 ~110~10~12 minecraft:furnace 2
fill ~109~11~12 ~110~11~16 minecraft:wool 7
fill ~109~23~12 ~110~23~16 minecraft:wool 7
fill ~109~24~12 ~110~24~12 minecraft:furnace 2
fill ~109~25~12 ~110~25~16 minecraft:wool 7
fill ~109~26~12 ~111~26~13 minecraft:stonebrick
fill ~109~27~12 ~110~27~16 minecraft:double_stone_block_slab 6
fill ~110~12~12 ~111~12~13 minecraft:quartz_block
fill ~110~22~12 ~111~22~13 minecraft:quartz_block
fill ~111~6~12 ~112~6~13 minecraft:stone_block_slab 14
fill ~111~7~12 ~114~7~12 minecraft:stonebrick
fill ~111~9~12 ~114~9~12 minecraft:furnace 2
fill ~111~10~12 ~129~10~12 minecraft:stonebrick
fill ~111~11~12 ~115~11~12 minecraft:stone
fill ~111~23~12 ~115~23~12 minecraft:stone
fill ~111~24~12 ~129~24~12 minecraft:stonebrick
fill ~111~25~12 ~114~25~12 minecraft:furnace 2
fill ~111~27~12 ~111~27~16 minecraft:stonebrick
fill ~111~28~12 ~112~28~13 minecraft:stone_block_slab 6
fill ~113~6~12 ~114~6~16 minecraft:stone_block_slab 6
fill ~113~13~12 ~113~13~13 minecraft:stone_block_slab 6
fill ~113~21~12 ~113~21~13 minecraft:stone_block_slab 13
fill ~113~28~12 ~114~28~16 minecraft:stone_block_slab 14
fill ~114~8~12 ~115~8~12 minecraft:stonebrick
fill ~114~26~12 ~115~26~12 minecraft:stonebrick
setblock ~114~27~12 minecraft:stonebrick
fill ~115~6~12 ~120~6~12 minecraft:stonebrick
setblock ~115~7~12 minecraft:furnace 5
fill ~115~9~12 ~121~9~12 minecraft:stonebrick
fill ~115~25~12 ~121~25~12 minecraft:stonebrick
setblock ~115~27~12 minecraft:furnace 5
fill ~115~28~12 ~120~28~12 minecraft:stonebrick
fill ~116~7~12 ~120~7~12 minecraft:iron_block
fill ~116~8~12 ~120~8~12 minecraft:cobblestone
fill ~116~11~12 ~116~11~16 minecraft:stonebrick
setblock ~116~12~12 minecraft:double_stone_block_slab 6
setblock ~116~22~12 minecraft:double_stone_block_slab 6
fill ~116~23~12 ~116~23~16 minecraft:stonebrick
fill ~116~26~12 ~120~26~12 minecraft:cobblestone
fill ~116~27~12 ~120~27~12 minecraft:iron_block
fill ~117~4~12 ~117~4~13 minecraft:stone_block_slab 14
fill ~117~5~12 ~118~5~16 minecraft:stone_block_slab 6
fill ~117~11~12 ~117~11~17 minecraft:quartz_block
fill ~117~12~12 ~120~12~13 minecraft:double_stone_block_slab
fill ~117~22~12 ~120~22~13 minecraft:double_stone_block_slab
fill ~117~29~12 ~118~29~16 minecraft:stone_block_slab 14
fill ~117~30~12 ~117~30~13 minecraft:stone_block_slab 6
fill ~119~4~12 ~119~4~13 minecraft:stone_block_slab 14
fill ~119~5~12 ~120~5~16 minecraft:stonebrick
fill ~119~29~12 ~120~29~16 minecraft:stonebrick
fill ~119~30~12 ~119~30~13 minecraft:stone_block_slab 6
setblock ~120~3~12 minecraft:stone_block_slab 8
fill ~120~4~12 ~120~4~16 minecraft:quartz_block
fill ~120~30~12 ~120~30~16 minecraft:quartz_block
setblock ~120~31~12 minecraft:stone_block_slab
setblock ~121~3~12 minecraft:quartz_stairs 7
fill ~121~4~12 ~123~4~12 minecraft:stonebrick
fill ~121~6~12 ~121~8~12 minecraft:double_wooden_slab 1
fill ~121~12~12 ~121~12~13 minecraft:stone_block_slab 6
fill ~121~22~12 ~121~22~13 minecraft:stone_block_slab 13
fill ~121~26~12 ~121~28~12 minecraft:double_wooden_slab 1
fill ~121~30~12 ~127~30~12 minecraft:stonebrick
setblock ~121~31~12 minecraft:quartz_stairs 3
fill ~122~3~12 ~123~3~12 minecraft:quartz_block
fill ~122~6~12 ~122~8~12 minecraft:log
fill ~122~11~12 ~124~11~17 minecraft:quartz_block
fill ~122~12~12 ~123~12~13 minecraft:double_stone_block_slab
fill ~122~22~12 ~123~22~13 minecraft:double_stone_block_slab
fill ~122~23~12 ~124~23~17 minecraft:quartz_block
fill ~122~26~12 ~122~28~12 minecraft:log
fill ~122~31~12 ~123~31~12 minecraft:quartz_block
fill ~123~5~12 ~124~5~12 minecraft:stone_brick_stairs 7
fill ~123~6~12 ~126~8~12 minecraft:stonebrick
fill ~123~9~12 ~124~9~12 minecraft:stone_brick_stairs 3
fill ~123~25~12 ~124~25~12 minecraft:stone_brick_stairs 7
fill ~123~26~12 ~126~28~12 minecraft:stonebrick
fill ~123~29~12 ~124~29~12 minecraft:stone_brick_stairs 3
setblock ~124~3~12 minecraft:double_stone_block_slab
setblock ~124~12~12 minecraft:stone_brick_stairs 2
setblock ~124~22~12 minecraft:stone_brick_stairs 6
setblock ~124~31~12 minecraft:double_stone_block_slab
fill ~125~3~12 ~126~3~17 minecraft:quartz_block
fill ~125~4~12 ~127~4~12 minecraft:stonebrick
fill ~125~5~12 ~126~5~12 minecraft:cobblestone_wall 
fill ~125~9~12 ~129~9~12 minecraft:stonebrick
setblock ~125~12~12 minecraft:stone_brick_stairs 1
setblock ~125~22~12 minecraft:stone_brick_stairs 5
fill ~125~25~12 ~129~25~12 minecraft:stonebrick
fill ~125~29~12 ~126~29~12 minecraft:cobblestone_wall 
fill ~125~31~12 ~126~31~17 minecraft:quartz_block
setblock ~126~12~12 minecraft:stonebrick
setblock ~126~22~12 minecraft:stonebrick
setblock ~127~3~12 minecraft:stone_block_slab 8
setblock ~127~31~12 minecraft:stone_block_slab
setblock ~128~4~12 minecraft:iron_bars
fill ~128~12~12 ~128~12~16 minecraft:quartz_block
fill ~128~22~12 ~128~22~16 minecraft:quartz_block
setblock ~128~30~12 minecraft:iron_bars
setblock ~129~4~12 minecraft:stonebrick
fill ~129~11~12 ~129~11~16 minecraft:stonebrick
setblock ~129~12~12 minecraft:cobblestone_wall
setblock ~129~22~12 minecraft:cobblestone_wall
fill ~129~23~12 ~129~23~16 minecraft:stonebrick
setblock ~129~30~12 minecraft:stonebrick
fill ~130~3~12 ~131~3~12 minecraft:quartz_stairs 7
fill ~130~4~12 ~130~4~17 minecraft:quartz_block
fill ~130~6~12 ~130~8~12 minecraft:stonebrick
fill ~130~9~12 ~130~12~12 minecraft:quartz_block
fill ~130~22~12 ~130~25~12 minecraft:quartz_block
fill ~130~26~12 ~130~28~12 minecraft:stonebrick
fill ~130~29~12 ~130~30~12 minecraft:quartz_block
fill ~130~31~12 ~131~31~12 minecraft:quartz_stairs 3
setblock ~131~4~12 minecraft:iron_bars
fill ~131~5~12 ~140~5~12 minecraft:stone_brick_stairs 7
fill ~131~6~12 ~132~6~12 minecraft:quartz_stairs 2
fill ~131~8~12 ~132~8~12 minecraft:quartz_stairs 6
fill ~131~9~12 ~140~9~12 minecraft:stone_brick_stairs 3
setblock ~131~10~12 minecraft:iron_bars
fill ~131~11~12 ~131~11~16 minecraft:quartz_block
setblock ~131~12~12 minecraft:quartz_stairs
setblock ~131~22~12 minecraft:quartz_stairs 4
fill ~131~23~12 ~131~23~16 minecraft:quartz_block
setblock ~131~24~12 minecraft:iron_bars
fill ~131~25~12 ~140~25~12 minecraft:stone_brick_stairs 7
fill ~131~26~12 ~132~26~12 minecraft:quartz_stairs 2
fill ~131~28~12 ~132~28~12 minecraft:quartz_stairs 6
fill ~131~29~12 ~140~29~12 minecraft:stone_brick_stairs 3
setblock ~131~30~12 minecraft:iron_bars
setblock ~132~3~12 minecraft:double_stone_block_slab 6
fill ~132~4~12 ~132~4~13 minecraft:wool 1
fill ~132~10~12 ~132~10~13 minecraft:wool 1
fill ~132~11~12 ~137~11~12 minecraft:stone_brick_stairs 3
fill ~132~23~12 ~137~23~12 minecraft:stone_brick_stairs 7
fill ~132~24~12 ~132~24~13 minecraft:wool 1
fill ~132~30~12 ~132~30~13 minecraft:wool 1
setblock ~132~31~12 minecraft:double_stone_block_slab 6
setblock ~133~3~12 minecraft:double_stone_block_slab
fill ~133~4~12 ~133~4~16 minecraft:stonebrick
setblock ~133~6~12 minecraft:stonebrick
setblock ~133~7~12 minecraft:stonebrick
setblock ~133~8~12 minecraft:stonebrick
fill ~133~10~12 ~133~10~16 minecraft:stonebrick
fill ~133~24~12 ~133~24~16 minecraft:stonebrick
setblock ~133~26~12 minecraft:stonebrick
setblock ~133~27~12 minecraft:stonebrick
setblock ~133~28~12 minecraft:stonebrick
fill ~133~30~12 ~133~30~16 minecraft:stonebrick
setblock ~133~31~12 minecraft:double_stone_block_slab
setblock ~134~3~12 minecraft:quartz_stairs 7
fill ~134~4~12 ~136~4~13 minecraft:wool 1
fill ~134~6~12 ~136~6~12 minecraft:quartz_stairs 2
fill ~134~8~12 ~136~8~12 minecraft:quartz_stairs 6
fill ~134~10~12 ~136~10~13 minecraft:wool 1
fill ~134~24~12 ~136~24~13 minecraft:wool 1
fill ~134~26~12 ~136~26~12 minecraft:quartz_stairs 2
fill ~134~28~12 ~136~28~12 minecraft:quartz_stairs 6
fill ~134~30~12 ~136~30~13 minecraft:wool 1
setblock ~134~31~12 minecraft:quartz_stairs 3
setblock ~135~3~12 minecraft:double_stone_block_slab
setblock ~135~31~12 minecraft:double_stone_block_slab
fill ~136~3~12 ~139~3~12 minecraft:quartz_stairs 7
fill ~136~31~12 ~139~31~12 minecraft:quartz_stairs 3
fill ~137~4~12 ~137~4~16 minecraft:stonebrick
setblock ~137~6~12 minecraft:stonebrick
setblock ~137~7~12 minecraft:stonebrick
setblock ~137~8~12 minecraft:stonebrick
fill ~137~10~12 ~137~10~16 minecraft:stonebrick
fill ~137~24~12 ~137~24~16 minecraft:stonebrick
setblock ~137~26~12 minecraft:stonebrick
setblock ~137~27~12 minecraft:stonebrick
setblock ~137~28~12 minecraft:stonebrick
fill ~137~30~12 ~137~30~16 minecraft:stonebrick
fill ~138~4~12 ~138~4~13 minecraft:wool 1
fill ~138~6~12 ~140~6~12 minecraft:quartz_stairs 2
fill ~138~8~12 ~140~8~12 minecraft:quartz_stairs 6
fill ~138~10~12 ~138~10~13 minecraft:wool 1
fill ~138~11~12 ~139~11~12 minecraft:quartz_stairs 3
fill ~138~23~12 ~139~23~12 minecraft:quartz_stairs 7
fill ~138~24~12 ~138~24~13 minecraft:wool 1
fill ~138~26~12 ~140~26~12 minecraft:quartz_stairs 2
fill ~138~28~12 ~140~28~12 minecraft:quartz_stairs 6
fill ~138~30~12 ~138~30~13 minecraft:wool 1
fill ~139~4~12 ~139~4~13 minecraft:cobblestone_wall
fill ~139~10~12 ~139~10~13 minecraft:cobblestone_wall
fill ~139~24~12 ~139~24~13 minecraft:cobblestone_wall
fill ~139~30~12 ~139~30~13 minecraft:cobblestone_wall
fill ~140~3~12 ~140~3~13 minecraft:stone_brick_stairs 4
fill ~140~4~12 ~141~4~16 minecraft:stonebrick
fill ~140~10~12 ~141~10~16 minecraft:stonebrick
fill ~140~11~12 ~140~11~13 minecraft:stone_brick_stairs
fill ~140~23~12 ~140~23~13 minecraft:stone_brick_stairs 4
fill ~140~24~12 ~141~24~16 minecraft:stonebrick
fill ~140~30~12 ~141~30~16 minecraft:stonebrick
fill ~140~31~12 ~140~31~13 minecraft:stone_brick_stairs
fill ~141~3~12 ~142~3~12 minecraft:quartz_stairs 7
fill ~141~11~12 ~142~11~12 minecraft:quartz_stairs 3
fill ~141~23~12 ~144~23~12 minecraft:quartz_stairs 7
fill ~141~31~12 ~144~31~12 minecraft:quartz_stairs 3
setblock ~142~4~12 minecraft:stone_brick_stairs 2
setblock ~142~10~12 minecraft:stone_brick_stairs 6
setblock ~142~24~12 minecraft:stone_brick_stairs 2
setblock ~142~30~12 minecraft:stone_brick_stairs 6
fill ~143~3~12 ~144~3~16 minecraft:wool 14
setblock ~143~4~12 minecraft:stone_brick_stairs
fill ~143~7~12 ~144~7~12 minecraft:quartz_block
setblock ~143~10~12 minecraft:stone_brick_stairs 4
fill ~143~11~12 ~144~11~12 minecraft:wool 14
setblock ~143~24~12 minecraft:stone_brick_stairs
fill ~143~27~12 ~144~27~12 minecraft:quartz_block
setblock ~143~30~12 minecraft:stone_brick_stairs 4
setblock ~145~3~12 minecraft:stone_brick_stairs 7
fill ~145~4~12 ~145~4~13 minecraft:stone_brick_stairs 6
setblock ~145~5~12 minecraft:stone_brick_stairs 7
fill ~145~6~12 ~145~8~12 minecraft:double_stone_block_slab
setblock ~145~9~12 minecraft:stone_brick_stairs 3
fill ~145~10~12 ~145~10~13 minecraft:stone_brick_stairs 2
setblock ~145~11~12 minecraft:stone_brick_stairs 3
setblock ~145~23~12 minecraft:stone_brick_stairs 7
fill ~145~24~12 ~145~24~13 minecraft:stone_brick_stairs 6
setblock ~145~25~12 minecraft:stone_brick_stairs 7
fill ~145~26~12 ~145~28~12 minecraft:double_stone_block_slab
setblock ~145~29~12 minecraft:stone_brick_stairs 3
fill ~145~30~12 ~145~30~13 minecraft:stone_brick_stairs 2
setblock ~145~31~12 minecraft:stone_brick_stairs 3
fill ~146~3~12 ~149~3~12 minecraft:quartz_stairs 7
fill ~146~4~12 ~146~4~16 minecraft:furnace 5
fill ~146~6~12 ~149~8~12 minecraft:stonebrick
fill ~146~9~12 ~146~10~12 minecraft:furnace 5
fill ~146~11~12 ~149~11~12 minecraft:quartz_stairs 3
fill ~146~23~12 ~149~23~12 minecraft:quartz_stairs 7
fill ~146~24~12 ~146~24~16 minecraft:furnace 5
fill ~146~26~12 ~149~28~12 minecraft:stonebrick
fill ~146~29~12 ~146~30~12 minecraft:furnace 5
fill ~146~31~12 ~149~31~12 minecraft:quartz_stairs 3
fill ~147~4~12 ~147~4~16 minecraft:stone
fill ~147~9~12 ~147~10~12 minecraft:stone
fill ~147~24~12 ~147~24~16 minecraft:stone
fill ~147~29~12 ~147~30~12 minecraft:stone
fill ~148~4~12 ~148~4~16 minecraft:bedrock
fill ~148~9~12 ~148~10~12 minecraft:bedrock
fill ~148~24~12 ~148~24~16 minecraft:bedrock
fill ~148~29~12 ~148~30~12 minecraft:bedrock
fill ~149~4~12 ~149~4~13 minecraft:stone_brick_stairs 7
fill ~149~9~12 ~149~10~12 minecraft:stone_brick_stairs 3
fill ~149~24~12 ~149~24~13 minecraft:stone_brick_stairs 7
fill ~149~29~12 ~149~30~12 minecraft:stone_brick_stairs 3
setblock ~150~6~12 minecraft:stone_brick_stairs 7
setblock ~150~7~12 minecraft:stonebrick
setblock ~150~8~12 minecraft:stone_brick_stairs 3
setblock ~150~26~12 minecraft:stone_brick_stairs 7
setblock ~150~27~12 minecraft:stonebrick
setblock ~150~28~12 minecraft:stone_brick_stairs 3
setblock ~107~7~13 minecraft:stone_block_slab 14
fill ~107~8~13 ~107~11~13 minecraft:quartz_block
setblock ~107~12~13 minecraft:double_stone_block_slab 6
setblock ~107~22~13 minecraft:double_stone_block_slab 6
fill ~107~23~13 ~107~26~13 minecraft:quartz_block
setblock ~107~27~13 minecraft:stone_block_slab 6
fill ~108~8~13 ~108~8~16 minecraft:stone
fill ~108~9~13 ~108~10~13 minecraft:stone
fill ~108~11~13 ~108~11~16 minecraft:stonebrick
fill ~108~12~13 ~109~12~13 minecraft:quartz_block
fill ~108~22~13 ~109~22~13 minecraft:quartz_block
fill ~108~23~13 ~108~23~16 minecraft:stonebrick
fill ~108~24~13 ~110~24~15 minecraft:stone
fill ~108~25~13 ~108~26~13 minecraft:stone
fill ~109~10~13 ~110~10~15 minecraft:stone
fill ~110~13~13 ~111~13~13 minecraft:stone_block_slab 6
fill ~110~21~13 ~111~21~13 minecraft:stone_block_slab 14
fill ~111~7~13 ~112~7~16 minecraft:stonebrick
fill ~111~9~13 ~113~9~13 minecraft:cobblestone_wall
fill ~111~11~13 ~115~11~14 minecraft:stonebrick
fill ~111~23~13 ~115~23~14 minecraft:stonebrick
fill ~111~25~13 ~113~25~13 minecraft:cobblestone_wall
setblock ~112~13~13 minecraft:stone_block_slab 6
setblock ~112~21~13 minecraft:stone_block_slab 13
fill ~112~27~13 ~112~27~16 minecraft:stonebrick
fill ~113~7~13 ~114~7~15 minecraft:stone_block_slab 6
fill ~113~27~13 ~114~27~15 minecraft:stone_block_slab 13
setblock ~114~8~13 minecraft:stonebrick
setblock ~114~9~13 minecraft:cobblestone_wall
setblock ~114~13~13 minecraft:stone_block_slab 6
setblock ~114~21~13 minecraft:stone_block_slab 13
setblock ~114~25~13 minecraft:cobblestone_wall
setblock ~114~26~13 minecraft:stonebrick
fill ~115~5~13 ~116~5~13 minecraft:stone_block_slab 14
fill ~115~6~13 ~116~6~16 minecraft:stonebrick
fill ~115~7~13 ~124~7~13 minecraft:stonebrick
fill ~115~12~13 ~116~12~13 minecraft:quartz_block
setblock ~115~13~13 minecraft:quartz_stairs 1
setblock ~115~21~13 minecraft:quartz_stairs 5
fill ~115~22~13 ~116~22~13 minecraft:quartz_block
fill ~115~27~13 ~124~27~13 minecraft:stonebrick
fill ~115~28~13 ~116~28~16 minecraft:stonebrick
fill ~115~29~13 ~116~29~13 minecraft:stone_block_slab 6
setblock ~116~9~13 minecraft:cobblestone_wall
setblock ~116~10~13 minecraft:furnace 5
setblock ~116~13~13 minecraft:quartz_stairs
setblock ~116~21~13 minecraft:quartz_stairs 4
setblock ~116~24~13 minecraft:furnace 5
setblock ~116~25~13 minecraft:cobblestone_wall
fill ~117~6~13 ~118~6~13 minecraft:stone_block_slab 6
fill ~117~9~13 ~120~9~13 minecraft:cobblestone_wall
fill ~117~10~13 ~120~10~13 minecraft:stone_block_slab 13
fill ~117~24~13 ~120~24~13 minecraft:stone_block_slab 6
fill ~117~25~13 ~120~25~13 minecraft:cobblestone_wall
fill ~117~28~13 ~118~28~13 minecraft:stone_block_slab 13
setblock ~120~3~13 minecraft:quartz_stairs 5
setblock ~120~31~13 minecraft:quartz_stairs 1
setblock ~121~2~13 minecraft:stone_block_slab 14
setblock ~121~3~13 minecraft:quartz_block
setblock ~121~4~13 minecraft:double_stone_block_slab
fill ~121~5~13 ~121~5~15 minecraft:spruce_stairs 5
fill ~121~6~13 ~124~6~15 minecraft:stonebrick
fill ~121~8~13 ~124~8~15 minecraft:stonebrick
fill ~121~9~13 ~121~9~15 minecraft:spruce_stairs 1
fill ~121~10~13 ~129~10~16 minecraft:stonebrick
fill ~121~24~13 ~129~24~16 minecraft:stonebrick
fill ~121~25~13 ~121~25~15 minecraft:spruce_stairs 5
fill ~121~26~13 ~124~26~15 minecraft:stonebrick
fill ~121~28~13 ~124~28~15 minecraft:stonebrick
fill ~121~29~13 ~121~29~15 minecraft:spruce_stairs 1
setblock ~121~30~13 minecraft:double_stone_block_slab
setblock ~121~31~13 minecraft:quartz_block
setblock ~121~32~13 minecraft:heavy_weighted_pressure_plate
fill ~122~3~13 ~122~4~15 minecraft:bedrock
fill ~122~5~13 ~122~5~15 minecraft:log
fill ~122~9~13 ~122~9~15 minecraft:log
fill ~122~25~13 ~122~25~15 minecraft:log
fill ~122~29~13 ~122~29~15 minecraft:log
fill ~122~30~13 ~122~31~15 minecraft:bedrock
fill ~123~2~13 ~124~2~13 minecraft:stone_block_slab 14
fill ~123~3~13 ~124~3~13 minecraft:quartz_block
setblock ~123~4~13 minecraft:double_stone_block_slab
fill ~123~5~13 ~124~5~15 minecraft:stonebrick
fill ~123~9~13 ~124~9~15 minecraft:stonebrick
fill ~123~25~13 ~124~25~15 minecraft:stonebrick
fill ~123~29~13 ~124~29~15 minecraft:stonebrick
setblock ~123~30~13 minecraft:double_stone_block_slab
fill ~123~31~13 ~124~31~13 minecraft:quartz_block
setblock ~123~32~13 minecraft:heavy_weighted_pressure_plate
setblock ~124~12~13 minecraft:stone_brick_stairs
setblock ~124~22~13 minecraft:stone_brick_stairs 4
fill ~124~30~13 ~124~30~16 minecraft:stonebrick
fill ~124~32~13 ~124~32~15 minecraft:stone_block_slab 6
fill ~125~4~13 ~126~4~13 minecraft:brick_block
fill ~125~6~13 ~129~6~13 minecraft:quartz_stairs 2
fill ~125~7~13 ~129~7~13 minecraft:double_stone_block_slab
fill ~125~8~13 ~129~8~13 minecraft:quartz_stairs 6
fill ~125~9~13 ~129~9~13 minecraft:quartz_block
setblock ~125~12~13 minecraft:stone_brick_stairs 3
setblock ~125~22~13 minecraft:stone_brick_stairs 7
fill ~125~25~13 ~129~25~13 minecraft:quartz_block
fill ~125~26~13 ~130~26~13 minecraft:quartz_stairs 2
fill ~125~27~13 ~130~27~13 minecraft:double_stone_block_slab
fill ~125~28~13 ~130~28~13 minecraft:quartz_stairs 6
fill ~125~30~13 ~126~30~13 minecraft:brick_block
setblock ~126~12~13 minecraft:stone_block_slab 14
setblock ~126~22~13 minecraft:stone_block_slab 14
fill ~127~4~13 ~127~4~16 minecraft:stonebrick
fill ~127~29~13 ~130~29~15 minecraft:stonebrick
fill ~127~30~13 ~127~30~16 minecraft:stonebrick
fill ~128~4~13 ~129~4~13 minecraft:cobblestone_wall
fill ~128~30~13 ~129~30~13 minecraft:cobblestone_wall
setblock ~129~12~13 minecraft:double_stone_block_slab
setblock ~129~22~13 minecraft:double_stone_block_slab
fill ~130~3~13 ~138~3~15 minecraft:quartz_block
fill ~130~5~13 ~130~5~15 minecraft:stonebrick
fill ~130~9~13 ~130~9~15 minecraft:stonebrick
fill ~130~10~13 ~130~10~17 minecraft:quartz_block
fill ~130~11~13 ~130~11~16 minecraft:quartz_block
setblock ~130~12~13 minecraft:stone_brick_stairs
setblock ~130~22~13 minecraft:stone_brick_stairs 4
fill ~130~23~13 ~130~24~16 minecraft:quartz_block
fill ~130~25~13 ~130~25~15 minecraft:stonebrick
fill ~130~30~13 ~130~30~17 minecraft:quartz_block
fill ~130~31~13 ~138~31~15 minecraft:quartz_block
fill ~130~32~13 ~134~32~13 minecraft:stone_block_slab 6
setblock ~131~4~13 minecraft:cobblestone_wall
fill ~131~5~13 ~132~5~13 minecraft:quartz_stairs 2
fill ~131~6~13 ~131~6~15 minecraft:stone_brick_stairs 5
fill ~131~7~13 ~141~7~13 minecraft:stonebrick
fill ~131~8~13 ~131~8~15 minecraft:stone_brick_stairs 1
fill ~131~9~13 ~132~9~13 minecraft:quartz_stairs 6
setblock ~131~10~13 minecraft:cobblestone_wall
setblock ~131~24~13 minecraft:cobblestone_wall
fill ~131~25~13 ~132~25~13 minecraft:quartz_stairs 2
fill ~131~26~13 ~131~26~15 minecraft:stone_brick_stairs 5
fill ~131~27~13 ~141~27~13 minecraft:stonebrick
fill ~131~28~13 ~131~28~15 minecraft:stone_brick_stairs 1
fill ~131~29~13 ~132~29~13 minecraft:quartz_stairs 6
setblock ~131~30~13 minecraft:cobblestone_wall
fill ~132~2~13 ~134~2~13 minecraft:stone_block_slab 14
fill ~132~6~13 ~139~6~13 minecraft:stone_brick_stairs 7
fill ~132~8~13 ~139~8~13 minecraft:stone_brick_stairs 3
fill ~132~11~13 ~137~11~15 minecraft:stone
fill ~132~23~13 ~137~23~15 minecraft:stone
fill ~132~26~13 ~139~26~13 minecraft:stone_brick_stairs 7
fill ~132~28~13 ~139~28~13 minecraft:stone_brick_stairs 3
setblock ~133~5~13 minecraft:stonebrick
setblock ~133~9~13 minecraft:stonebrick
setblock ~133~25~13 minecraft:stonebrick
setblock ~133~29~13 minecraft:stonebrick
fill ~134~5~13 ~136~5~13 minecraft:quartz_stairs 2
fill ~134~9~13 ~136~9~13 minecraft:quartz_stairs 6
fill ~134~25~13 ~136~25~13 minecraft:quartz_stairs 2
fill ~134~29~13 ~136~29~13 minecraft:quartz_stairs 6
setblock ~135~32~13 minecraft:heavy_weighted_pressure_plate
setblock ~137~5~13 minecraft:stonebrick
setblock ~137~9~13 minecraft:stonebrick
setblock ~137~25~13 minecraft:stonebrick
setblock ~137~29~13 minecraft:stonebrick
fill ~138~5~13 ~140~5~13 minecraft:quartz_stairs 2
fill ~138~9~13 ~140~9~13 minecraft:quartz_stairs 6
fill ~138~11~13 ~138~11~15 minecraft:quartz_block
fill ~138~23~13 ~138~23~15 minecraft:quartz_block
fill ~138~25~13 ~140~25~13 minecraft:quartz_stairs 2
fill ~138~29~13 ~140~29~13 minecraft:quartz_stairs 6
setblock ~139~3~13 minecraft:stone_brick_stairs 6
setblock ~139~11~13 minecraft:stone_brick_stairs 2
setblock ~139~23~13 minecraft:stone_brick_stairs 6
setblock ~139~31~13 minecraft:stone_brick_stairs 2
fill ~141~3~13 ~142~3~15 minecraft:quartz_block
fill ~141~11~13 ~142~11~13 minecraft:quartz_block
fill ~141~23~13 ~142~23~13 minecraft:quartz_block
fill ~141~31~13 ~144~31~15 minecraft:quartz_block
setblock ~142~6~13 minecraft:quartz_stairs 5
setblock ~142~7~13 minecraft:quartz_block
setblock ~142~8~13 minecraft:quartz_stairs 1
setblock ~142~26~13 minecraft:quartz_stairs 5
setblock ~142~27~13 minecraft:quartz_block
setblock ~142~28~13 minecraft:quartz_stairs 1
setblock ~143~6~13 minecraft:quartz_stairs 7
setblock ~143~8~13 minecraft:quartz_stairs 3
fill ~143~11~13 ~144~11~15 minecraft:stone
fill ~143~23~13 ~144~23~15 minecraft:stone
setblock ~143~26~13 minecraft:quartz_stairs 7
setblock ~143~28~13 minecraft:quartz_stairs 3
setblock ~144~6~13 minecraft:quartz_block
setblock ~144~8~13 minecraft:quartz_block
setblock ~144~26~13 minecraft:quartz_block
setblock ~144~28~13 minecraft:quartz_block
fill ~145~3~13 ~145~3~15 minecraft:stonebrick
fill ~145~5~13 ~145~5~15 minecraft:double_stone_block_slab
setblock ~145~6~13 minecraft:cobblestone_wall
setblock ~145~7~13 minecraft:cobblestone_wall
setblock ~145~8~13 minecraft:cobblestone_wall
fill ~145~9~13 ~145~9~15 minecraft:double_stone_block_slab
fill ~145~11~13 ~145~11~15 minecraft:stonebrick
fill ~145~23~13 ~145~23~15 minecraft:stonebrick
fill ~145~25~13 ~145~25~15 minecraft:double_stone_block_slab
setblock ~145~26~13 minecraft:cobblestone_wall
setblock ~145~27~13 minecraft:cobblestone_wall
setblock ~145~28~13 minecraft:cobblestone_wall
fill ~145~29~13 ~145~29~15 minecraft:double_stone_block_slab
fill ~145~31~13 ~145~31~15 minecraft:stonebrick
fill ~146~3~13 ~149~3~13 minecraft:quartz_stairs 6
fill ~146~5~13 ~149~5~15 minecraft:stonebrick
fill ~146~6~13 ~147~6~13 minecraft:stone_brick_stairs 2
fill ~146~8~13 ~147~8~13 minecraft:stone_brick_stairs 6
fill ~146~9~13 ~149~9~15 minecraft:stonebrick
fill ~146~10~13 ~146~10~16 minecraft:furnace 5
fill ~146~11~13 ~149~11~13 minecraft:quartz_stairs 2
fill ~146~23~13 ~149~23~13 minecraft:quartz_stairs 6
fill ~146~25~13 ~149~25~15 minecraft:stonebrick
fill ~146~26~13 ~147~26~13 minecraft:stone_brick_stairs 2
fill ~146~28~13 ~147~28~13 minecraft:stone_brick_stairs 6
fill ~146~29~13 ~149~29~15 minecraft:stonebrick
fill ~146~30~13 ~146~30~16 minecraft:furnace 5
fill ~146~31~13 ~149~31~13 minecraft:quartz_stairs 2
fill ~147~10~13 ~147~10~16 minecraft:stone
fill ~147~30~13 ~147~30~16 minecraft:stone
setblock ~148~6~13 minecraft:stone_brick_stairs
setblock ~148~8~13 minecraft:stone_brick_stairs 4
fill ~148~10~13 ~148~10~16 minecraft:bedrock
setblock ~148~26~13 minecraft:stone_brick_stairs
setblock ~148~28~13 minecraft:stone_brick_stairs 4
fill ~148~30~13 ~148~30~16 minecraft:bedrock
setblock ~149~10~13 minecraft:stone_brick_stairs 3
setblock ~149~30~13 minecraft:stone_brick_stairs 3
setblock ~150~5~13 minecraft:stone_brick_stairs 7
setblock ~150~9~13 minecraft:stone_brick_stairs 3
setblock ~150~25~13 minecraft:stone_brick_stairs 7
setblock ~150~29~13 minecraft:stone_brick_stairs 3
setblock ~106~10~14 minecraft:quartz_stairs 2
setblock ~106~24~14 minecraft:quartz_stairs 6
setblock ~107~7~14 minecraft:double_stone_block_slab 6
fill ~107~8~14 ~107~8~16 minecraft:stone_brick_stairs 1
fill ~107~9~14 ~107~9~16 minecraft:dropper 2
fill ~107~10~14 ~107~10~17 minecraft:quartz_block
fill ~107~11~14 ~107~11~16 minecraft:quartz_stairs 1
fill ~107~12~14 ~107~12~20 minecraft:quartz_block
fill ~107~13~14 ~109~13~14 minecraft:stone_block_slab 6
fill ~107~21~14 ~109~21~14 minecraft:stone_block_slab 14
fill ~107~22~14 ~107~22~20 minecraft:quartz_block
fill ~107~23~14 ~107~23~16 minecraft:quartz_stairs 5
fill ~107~24~14 ~107~24~17 minecraft:quartz_block
fill ~107~25~14 ~107~25~16 minecraft:dropper 2
fill ~107~26~14 ~107~26~16 minecraft:stone_brick_stairs 5
setblock ~107~27~14 minecraft:double_stone_block_slab 6
setblock ~108~7~14 minecraft:quartz_stairs 6
fill ~108~9~14 ~108~9~16 minecraft:stonebrick
fill ~108~10~14 ~108~10~16 minecraft:stone
fill ~108~12~14 ~110~12~17 minecraft:stonebrick
fill ~108~22~14 ~110~22~17 minecraft:stonebrick
fill ~108~25~14 ~108~25~16 minecraft:stonebrick
fill ~108~26~14 ~108~26~16 minecraft:stone
setblock ~108~27~14 minecraft:quartz_stairs 2
fill ~109~6~14 ~109~6~15 minecraft:stone_block_slab 14
fill ~109~8~14 ~110~8~16 minecraft:stonebrick
fill ~109~26~14 ~110~26~16 minecraft:stonebrick
fill ~109~28~14 ~109~28~15 minecraft:stone_block_slab 6
fill ~110~6~14 ~110~6~15 minecraft:quartz_stairs 5
fill ~110~13~14 ~111~13~15 minecraft:quartz_block
fill ~110~21~14 ~111~21~15 minecraft:quartz_block
fill ~110~28~14 ~110~28~15 minecraft:quartz_stairs 1
fill ~111~6~14 ~112~6~14 minecraft:quartz_stairs 6
fill ~111~9~14 ~114~9~14 minecraft:stonebrick
fill ~111~10~14 ~114~10~14 minecraft:stonebrick
fill ~111~12~14 ~114~12~14 minecraft:stonebrick
fill ~111~22~14 ~114~22~14 minecraft:stonebrick
fill ~111~24~14 ~114~24~14 minecraft:stonebrick
fill ~111~25~14 ~114~25~14 minecraft:stonebrick
fill ~111~28~14 ~112~28~14 minecraft:quartz_stairs 2
fill ~112~13~14 ~112~13~15 minecraft:stonebrick
setblock ~112~14~14 minecraft:stone_brick_stairs 3
setblock ~112~20~14 minecraft:stone_brick_stairs 7
fill ~112~21~14 ~112~21~15 minecraft:stonebrick
fill ~113~5~14 ~113~5~15 minecraft:stone_block_slab 14
setblock ~113~13~14 minecraft:stonebrick
fill ~113~14~14 ~113~14~16 minecraft:stonebrick
fill ~113~20~14 ~113~20~16 minecraft:stonebrick
setblock ~113~21~14 minecraft:stonebrick
fill ~113~29~14 ~113~29~15 minecraft:stone_block_slab 6
fill ~114~5~14 ~114~5~15 minecraft:quartz_stairs 5
fill ~114~13~14 ~114~13~15 minecraft:stonebrick
setblock ~114~14~14 minecraft:stone_brick_stairs 3
setblock ~114~20~14 minecraft:stone_brick_stairs 7
fill ~114~21~14 ~114~21~15 minecraft:stonebrick
fill ~114~29~14 ~114~29~15 minecraft:quartz_stairs 1
fill ~115~5~14 ~116~5~14 minecraft:quartz_stairs 6
setblock ~115~7~14 minecraft:stone_brick_stairs 5
fill ~115~8~14 ~115~9~14 minecraft:stonebrick
fill ~115~10~14 ~120~10~14 minecraft:stonebrick
fill ~115~12~14 ~115~12~19 minecraft:stonebrick
fill ~115~13~14 ~115~13~15 minecraft:quartz_block
fill ~115~21~14 ~115~21~15 minecraft:quartz_block
fill ~115~22~14 ~115~22~19 minecraft:stonebrick
fill ~115~24~14 ~120~24~14 minecraft:stonebrick
fill ~115~25~14 ~115~26~14 minecraft:stonebrick
setblock ~115~27~14 minecraft:stone_brick_stairs 1
fill ~115~29~14 ~116~29~14 minecraft:quartz_stairs 2
fill ~116~7~14 ~142~7~14 minecraft:stonebrick
fill ~116~8~14 ~120~8~14 minecraft:anvil
fill ~116~9~14 ~120~9~14 minecraft:iron_block
fill ~116~12~14 ~116~12~18 minecraft:quartz_block
setblock ~116~13~14 minecraft:double_stone_block_slab 6
setblock ~116~21~14 minecraft:double_stone_block_slab 6
fill ~116~22~14 ~116~22~18 minecraft:quartz_block
fill ~116~25~14 ~120~25~14 minecraft:iron_block
fill ~116~26~14 ~120~26~14 minecraft:anvil
fill ~116~27~14 ~142~27~14 minecraft:stonebrick
fill ~117~6~14 ~120~6~14 minecraft:double_stone_block_slab 6
fill ~117~12~14 ~123~12~14 minecraft:quartz_block
fill ~117~22~14 ~123~22~14 minecraft:quartz_block
fill ~117~28~14 ~120~28~14 minecraft:double_stone_block_slab 6
fill ~118~4~14 ~118~4~15 minecraft:quartz_stairs 4
fill ~118~30~14 ~118~30~15 minecraft:quartz_stairs
setblock ~119~4~14 minecraft:quartz_stairs 6
setblock ~119~30~14 minecraft:quartz_stairs 2
setblock ~120~3~14 minecraft:stone_brick_stairs 5
setblock ~120~31~14 minecraft:stone_brick_stairs 1
fill ~121~3~14 ~121~4~14 minecraft:bedrock
fill ~121~30~14 ~121~31~14 minecraft:bedrock
fill ~123~3~14 ~123~4~14 minecraft:bedrock
fill ~123~30~14 ~123~31~14 minecraft:bedrock
fill ~124~3~14 ~124~3~15 minecraft:quartz_block
fill ~124~12~14 ~125~12~16 minecraft:quartz_block
fill ~124~13~14 ~124~13~16 minecraft:stone_block_slab 6
fill ~124~21~14 ~124~21~16 minecraft:stone_block_slab 14
fill ~124~22~14 ~125~22~16 minecraft:quartz_block
fill ~124~31~14 ~124~31~15 minecraft:quartz_block
fill ~125~4~14 ~126~5~14 minecraft:stonebrick
fill ~125~6~14 ~129~6~14 minecraft:double_stone_block_slab
fill ~125~8~14 ~129~8~14 minecraft:double_stone_block_slab
fill ~125~9~14 ~129~9~14 minecraft:dropper 5
fill ~125~13~14 ~125~13~15 minecraft:stone_block_slab
fill ~125~21~14 ~125~21~15 minecraft:stone_block_slab 8
fill ~125~25~14 ~129~25~14 minecraft:dropper 5
fill ~125~26~14 ~130~26~14 minecraft:double_stone_block_slab
fill ~125~28~14 ~130~28~14 minecraft:double_stone_block_slab
fill ~125~29~14 ~126~30~14 minecraft:stonebrick
setblock ~126~12~14 minecraft:cobblestone_wall
setblock ~126~22~14 minecraft:cobblestone_wall
setblock ~127~3~14 minecraft:stone_brick_stairs 4
setblock ~127~12~14 minecraft:stonebrick
setblock ~127~22~14 minecraft:stonebrick
setblock ~127~31~14 minecraft:stone_brick_stairs
setblock ~128~4~14 minecraft:stonebrick
setblock ~128~13~14 minecraft:stone_block_slab 6
setblock ~128~21~14 minecraft:stone_block_slab 14
setblock ~128~30~14 minecraft:stonebrick
setblock ~129~4~14 minecraft:stonebrick
setblock ~129~12~14 minecraft:cobblestone_wall
setblock ~129~22~14 minecraft:cobblestone_wall
setblock ~129~30~14 minecraft:stonebrick
setblock ~130~12~14 minecraft:quartz_block
setblock ~130~22~14 minecraft:quartz_block
fill ~131~4~14 ~132~4~14 minecraft:stone_block_slab
fill ~131~10~14 ~132~10~14 minecraft:stone_block_slab 8
setblock ~131~12~14 minecraft:quartz_stairs
setblock ~131~22~14 minecraft:quartz_stairs 4
fill ~131~24~14 ~132~24~14 minecraft:stone_block_slab
fill ~131~30~14 ~132~30~14 minecraft:stone_block_slab 8
fill ~132~6~14 ~141~6~14 minecraft:stonebrick
fill ~132~8~14 ~141~8~14 minecraft:stonebrick
fill ~132~26~14 ~141~26~14 minecraft:stonebrick
fill ~132~28~14 ~141~28~14 minecraft:stonebrick
setblock ~133~5~14 minecraft:stonebrick
setblock ~133~9~14 minecraft:stonebrick
setblock ~133~25~14 minecraft:stonebrick
setblock ~133~29~14 minecraft:stonebrick
fill ~134~4~14 ~136~4~14 minecraft:stone_block_slab
fill ~134~10~14 ~136~10~14 minecraft:stone_block_slab 8
fill ~134~24~14 ~136~24~14 minecraft:stone_block_slab
fill ~134~30~14 ~136~30~14 minecraft:stone_block_slab 8
setblock ~135~2~14 minecraft:stone_block_slab 8
setblock ~135~32~14 minecraft:stone_block_slab
setblock ~137~2~14 minecraft:stone_block_slab 13
setblock ~137~5~14 minecraft:stonebrick
setblock ~137~9~14 minecraft:stonebrick
setblock ~137~25~14 minecraft:stonebrick
setblock ~137~29~14 minecraft:stonebrick
setblock ~137~32~14 minecraft:stone_block_slab 6
fill ~138~4~14 ~139~4~14 minecraft:stone_block_slab
fill ~138~10~14 ~139~10~14 minecraft:stone_block_slab 8
fill ~138~24~14 ~139~24~14 minecraft:stone_block_slab
fill ~138~30~14 ~139~30~14 minecraft:stone_block_slab 8
setblock ~139~3~14 minecraft:stone_brick_stairs 4
setblock ~139~11~14 minecraft:stone_brick_stairs
setblock ~139~23~14 minecraft:stone_brick_stairs 4
setblock ~139~31~14 minecraft:stone_brick_stairs
setblock ~140~3~14 minecraft:stonebrick
setblock ~140~11~14 minecraft:stonebrick
setblock ~140~23~14 minecraft:stonebrick
setblock ~140~31~14 minecraft:stonebrick
fill ~141~11~14 ~141~11~15 minecraft:quartz_block
fill ~141~23~14 ~141~23~15 minecraft:quartz_block
setblock ~142~6~14 minecraft:quartz_block
setblock ~142~8~14 minecraft:quartz_block
setblock ~142~11~14 minecraft:stone_brick_stairs
setblock ~142~23~14 minecraft:stone_brick_stairs 4
setblock ~142~26~14 minecraft:quartz_block
setblock ~142~28~14 minecraft:quartz_block
setblock ~143~5~14 minecraft:quartz_stairs 5
fill ~143~7~14 ~147~7~14 minecraft:quartz_block
setblock ~143~9~14 minecraft:quartz_stairs 1
setblock ~143~25~14 minecraft:quartz_stairs 5
fill ~143~27~14 ~147~27~14 minecraft:quartz_block
setblock ~143~29~14 minecraft:quartz_stairs 1
setblock ~144~5~14 minecraft:quartz_block
setblock ~144~9~14 minecraft:quartz_block
setblock ~144~25~14 minecraft:quartz_block
setblock ~144~29~14 minecraft:quartz_block
setblock ~145~4~14 minecraft:stonebrick
setblock ~145~6~14 minecraft:cobblestone_wall
setblock ~145~8~14 minecraft:cobblestone_wall
setblock ~145~10~14 minecraft:stonebrick
setblock ~145~24~14 minecraft:stonebrick
setblock ~145~26~14 minecraft:cobblestone_wall
setblock ~145~28~14 minecraft:cobblestone_wall
setblock ~145~30~14 minecraft:stonebrick
fill ~146~3~14 ~149~3~14 minecraft:quartz_block
fill ~146~11~14 ~149~11~14 minecraft:quartz_block
fill ~146~23~14 ~149~23~14 minecraft:quartz_block
fill ~146~31~14 ~149~31~14 minecraft:quartz_block
setblock ~149~4~14 minecraft:cobblestone_wall
setblock ~149~10~14 minecraft:cobblestone_wall
setblock ~149~24~14 minecraft:cobblestone_wall
setblock ~149~30~14 minecraft:cobblestone_wall
setblock ~150~5~14 minecraft:stonebrick
setblock ~150~9~14 minecraft:stonebrick
setblock ~150~25~14 minecraft:stonebrick
setblock ~150~29~14 minecraft:stonebrick
fill ~106~10~15 ~106~10~16 minecraft:stone_block_slab 6
fill ~106~24~15 ~106~24~16 minecraft:stone_block_slab 14
fill ~107~7~15 ~108~7~15 minecraft:quartz_stairs 7
setblock ~107~13~15 minecraft:double_stone_block_slab 6
fill ~107~14~15 ~108~14~17 minecraft:quartz_block
fill ~107~20~15 ~108~20~17 minecraft:quartz_block
setblock ~107~21~15 minecraft:double_stone_block_slab 6
fill ~107~27~15 ~108~27~15 minecraft:quartz_stairs 3
fill ~108~13~15 ~109~13~15 minecraft:quartz_block
fill ~108~21~15 ~109~21~15 minecraft:quartz_block
fill ~110~14~15 ~111~14~15 minecraft:stone_block_slab 6
setblock ~110~17~15 minecraft:dispenser 5
fill ~110~20~15 ~111~20~15 minecraft:stone_block_slab 14
fill ~111~6~15 ~112~6~15 minecraft:quartz_stairs 7
fill ~111~10~15 ~114~10~16 minecraft:stonebrick
fill ~111~11~15 ~114~11~15 minecraft:stonebrick
fill ~111~12~15 ~114~12~17 minecraft:quartz_block 
setblock ~111~15~15 minecraft:quartz_stairs 7
setblock ~111~16~15 minecraft:quartz_stairs 3
fill ~111~17~15 ~112~17~16 minecraft:double_stone_block_slab
setblock ~111~18~15 minecraft:quartz_stairs 7
setblock ~111~19~15 minecraft:quartz_stairs 3
fill ~111~22~15 ~114~22~17 minecraft:quartz_block 
fill ~111~23~15 ~114~23~15 minecraft:stonebrick
fill ~111~24~15 ~114~24~16 minecraft:stonebrick
fill ~111~28~15 ~112~28~15 minecraft:quartz_stairs 3
setblock ~112~14~15 minecraft:stone_brick_stairs 1
setblock ~112~15~15 minecraft:stone_brick_stairs 7
setblock ~112~16~15 minecraft:stone_brick_stairs 3
setblock ~112~18~15 minecraft:stone_brick_stairs 7
setblock ~112~19~15 minecraft:stone_brick_stairs 3
setblock ~112~20~15 minecraft:stone_brick_stairs 5
setblock ~113~13~15 minecraft:stonebrick
fill ~113~15~15 ~114~15~15 minecraft:quartz_stairs 7
fill ~113~16~15 ~114~16~15 minecraft:quartz_stairs 3
fill ~113~18~15 ~114~18~15 minecraft:quartz_stairs 7
fill ~113~19~15 ~114~19~15 minecraft:quartz_stairs 3
setblock ~113~21~15 minecraft:stonebrick
setblock ~114~14~15 minecraft:stone_brick_stairs
setblock ~114~20~15 minecraft:stone_brick_stairs 4
fill ~115~5~15 ~116~5~15 minecraft:quartz_stairs 7
fill ~115~7~15 ~124~7~15 minecraft:stonebrick
fill ~115~11~15 ~115~11~16 minecraft:stonebrick
fill ~115~14~15 ~116~14~15 minecraft:stone_block_slab 6
setblock ~115~15~15 minecraft:stone_brick_stairs 7
setblock ~115~16~15 minecraft:stone_brick_stairs 3
setblock ~115~18~15 minecraft:stone_brick_stairs 7
setblock ~115~19~15 minecraft:stone_brick_stairs 3
fill ~115~20~15 ~116~20~15 minecraft:stone_block_slab 14
fill ~115~23~15 ~115~23~16 minecraft:stonebrick
fill ~115~27~15 ~124~27~15 minecraft:stonebrick
fill ~115~29~15 ~116~29~15 minecraft:quartz_stairs 3
setblock ~116~9~15 minecraft:cobblestone_wall
setblock ~116~10~15 minecraft:furnace 5
fill ~116~13~15 ~116~13~20 minecraft:quartz_block
setblock ~116~15~15 minecraft:quartz_stairs 7
setblock ~116~16~15 minecraft:quartz_stairs 3
setblock ~116~18~15 minecraft:quartz_stairs 7
setblock ~116~19~15 minecraft:quartz_stairs 3
fill ~116~21~15 ~116~21~20 minecraft:quartz_block
setblock ~116~24~15 minecraft:furnace 5
setblock ~116~25~15 minecraft:cobblestone_wall
setblock ~117~4~15 minecraft:stone_block_slab 14
fill ~117~6~15 ~118~6~15 minecraft:stone_block_slab 6
fill ~117~9~15 ~120~9~15 minecraft:cobblestone_wall
fill ~117~10~15 ~120~10~15 minecraft:stone_block_slab 13
fill ~117~12~15 ~120~12~17 minecraft:double_stone_block_slab
fill ~117~13~15 ~120~13~16 minecraft:stone_block_slab
fill ~117~21~15 ~120~21~16 minecraft:stone_block_slab 8
fill ~117~22~15 ~120~22~17 minecraft:double_stone_block_slab
fill ~117~24~15 ~120~24~15 minecraft:stone_block_slab 6
fill ~117~25~15 ~120~25~15 minecraft:cobblestone_wall
fill ~117~28~15 ~118~28~15 minecraft:stone_block_slab 13
setblock ~117~30~15 minecraft:stone_block_slab 6
fill ~119~4~15 ~119~4~16 minecraft:stone_block_slab 14
fill ~119~30~15 ~119~30~16 minecraft:stone_block_slab 6
setblock ~120~3~15 minecraft:quartz_stairs 5
setblock ~120~15~15 minecraft:quartz_stairs
fill ~120~16~15 ~120~18~15 minecraft:cobblestone_wall
setblock ~120~19~15 minecraft:quartz_stairs 4
setblock ~120~31~15 minecraft:quartz_stairs 1
setblock ~121~2~15 minecraft:stone_block_slab 14
setblock ~121~3~15 minecraft:quartz_block
setblock ~121~4~15 minecraft:double_stone_block_slab
fill ~121~12~15 ~121~12~17 minecraft:stone_brick_stairs
fill ~121~22~15 ~121~22~17 minecraft:stone_brick_stairs 4
setblock ~121~30~15 minecraft:double_stone_block_slab
setblock ~121~31~15 minecraft:quartz_block
setblock ~121~32~15 minecraft:heavy_weighted_pressure_plate
fill ~122~12~15 ~122~12~16 minecraft:double_stone_block_slab 6
fill ~122~13~15 ~123~13~16 minecraft:stone_block_slab 6
fill ~122~21~15 ~123~21~16 minecraft:stone_block_slab 14
fill ~122~22~15 ~122~22~16 minecraft:double_stone_block_slab 6
fill ~123~2~15 ~124~2~15 minecraft:stone_block_slab 14
fill ~123~3~15 ~123~3~16 minecraft:quartz_block
setblock ~123~4~15 minecraft:double_stone_block_slab
fill ~123~12~15 ~123~12~16 minecraft:quartz_block
fill ~123~22~15 ~123~22~16 minecraft:quartz_block
setblock ~123~30~15 minecraft:double_stone_block_slab
fill ~123~31~15 ~123~31~16 minecraft:quartz_block
setblock ~123~32~15 minecraft:heavy_weighted_pressure_plate
fill ~124~16~15 ~124~16~16 minecraft:quartz_stairs 5
fill ~124~17~15 ~124~18~16 minecraft:quartz_stairs 1
fill ~125~4~15 ~126~4~15 minecraft:brick_block
fill ~125~5~15 ~126~5~15 minecraft:cobblestone_wall 
fill ~125~6~15 ~129~6~15 minecraft:quartz_stairs 3
fill ~125~7~15 ~129~7~15 minecraft:double_stone_block_slab
fill ~125~8~15 ~129~8~15 minecraft:quartz_stairs 7
fill ~125~9~15 ~129~9~15 minecraft:quartz_block
fill ~125~15~15 ~125~16~17 minecraft:quartz_block
fill ~125~17~15 ~126~17~15 minecraft:quartz_block
fill ~125~18~15 ~125~19~17 minecraft:quartz_block
fill ~125~25~15 ~129~25~15 minecraft:quartz_block
fill ~125~26~15 ~130~26~15 minecraft:quartz_stairs 3
fill ~125~27~15 ~130~27~15 minecraft:double_stone_block_slab
fill ~125~28~15 ~129~28~15 minecraft:quartz_stairs 7
fill ~125~29~15 ~126~29~15 minecraft:cobblestone_wall 
fill ~125~30~15 ~126~30~15 minecraft:brick_block
fill ~126~12~15 ~127~12~15 minecraft:quartz_block
fill ~126~14~15 ~126~14~16 minecraft:quartz_stairs 5
setblock ~126~15~15 minecraft:quartz_stairs
setblock ~126~16~15 minecraft:quartz_stairs 5
setblock ~126~18~15 minecraft:quartz_stairs 1
setblock ~126~19~15 minecraft:quartz_stairs 4
fill ~126~20~15 ~126~20~16 minecraft:quartz_stairs 1
fill ~126~22~15 ~127~22~15 minecraft:quartz_block
fill ~127~14~15 ~127~14~16 minecraft:quartz_block
setblock ~127~15~15 minecraft:quartz_stairs 7
setblock ~127~16~15 minecraft:stonebrick
setblock ~127~17~15 minecraft:stonebrick
setblock ~127~18~15 minecraft:stonebrick
setblock ~127~19~15 minecraft:quartz_stairs 3
fill ~127~20~15 ~127~20~16 minecraft:quartz_block
fill ~128~4~15 ~129~4~15 minecraft:cobblestone_wall
fill ~128~14~15 ~128~14~16 minecraft:quartz_stairs 4
setblock ~128~15~15 minecraft:stone_brick_stairs 7
setblock ~128~16~15 minecraft:double_stone_block_slab
setblock ~128~17~15 minecraft:cobblestone_wall
setblock ~128~18~15 minecraft:double_stone_block_slab
setblock ~128~19~15 minecraft:stone_brick_stairs 3
setblock ~128~20~15 minecraft:quartz_stairs
fill ~128~30~15 ~129~30~15 minecraft:cobblestone_wall
setblock ~129~12~15 minecraft:double_stone_block_slab
fill ~129~14~15 ~129~14~16 minecraft:stone_block_slab 14
setblock ~129~15~15 minecraft:quartz_stairs 5
setblock ~129~16~15 minecraft:quartz_stairs 3
setblock ~129~17~15 minecraft:quartz_block
setblock ~129~18~15 minecraft:quartz_stairs 7
setblock ~129~19~15 minecraft:quartz_stairs 1
setblock ~129~20~15 minecraft:stone_block_slab 6
setblock ~129~22~15 minecraft:double_stone_block_slab
setblock ~130~12~15 minecraft:stone_brick_stairs
fill ~130~15~15 ~132~15~15 minecraft:quartz_stairs 3
fill ~130~16~15 ~131~16~15 minecraft:stone_brick_stairs 5
fill ~130~17~15 ~131~17~15 minecraft:cobblestone_wall
fill ~130~18~15 ~131~18~15 minecraft:stone_brick_stairs 1
fill ~130~19~15 ~132~19~15 minecraft:quartz_stairs 7
setblock ~130~22~15 minecraft:stone_brick_stairs 4
setblock ~130~28~15 minecraft:quartz_stairs 5
fill ~130~32~15 ~134~32~15 minecraft:stone_block_slab 6
setblock ~131~4~15 minecraft:cobblestone_wall
fill ~131~5~15 ~132~5~15 minecraft:quartz_stairs 3
fill ~131~7~15 ~141~7~15 minecraft:stonebrick
fill ~131~9~15 ~132~9~15 minecraft:quartz_stairs 7
setblock ~131~10~15 minecraft:cobblestone_wall
setblock ~131~24~15 minecraft:cobblestone_wall
fill ~131~25~15 ~132~25~15 minecraft:quartz_stairs 3
fill ~131~27~15 ~141~27~15 minecraft:stonebrick
fill ~131~29~15 ~132~29~15 minecraft:quartz_stairs 7
setblock ~131~30~15 minecraft:cobblestone_wall
fill ~132~2~15 ~134~2~15 minecraft:stone_block_slab 14
fill ~132~4~15 ~132~4~16 minecraft:wool 1
fill ~132~6~15 ~139~6~15 minecraft:stone_brick_stairs 6
fill ~132~8~15 ~139~8~15 minecraft:stone_brick_stairs 2
fill ~132~10~15 ~132~10~16 minecraft:wool 1
setblock ~132~16~15 minecraft:dispenser 3
setblock ~132~17~15 minecraft:quartz_block
setblock ~132~18~15 minecraft:dispenser 3
fill ~132~24~15 ~132~24~16 minecraft:wool 1
fill ~132~26~15 ~139~26~15 minecraft:stone_brick_stairs 6
fill ~132~28~15 ~139~28~15 minecraft:stone_brick_stairs 2
fill ~132~30~15 ~132~30~16 minecraft:wool 1
setblock ~133~5~15 minecraft:stonebrick
setblock ~133~9~15 minecraft:stonebrick
fill ~133~15~15 ~134~15~16 minecraft:quartz_block
fill ~133~16~15 ~134~16~15 minecraft:quartz_block
setblock ~133~17~15 minecraft:stone
fill ~133~18~15 ~134~19~15 minecraft:quartz_block
setblock ~133~25~15 minecraft:stonebrick
setblock ~133~29~15 minecraft:stonebrick
fill ~134~4~15 ~136~4~16 minecraft:wool 1
fill ~134~5~15 ~136~5~15 minecraft:quartz_stairs 3
fill ~134~9~15 ~136~9~15 minecraft:quartz_stairs 7
fill ~134~10~15 ~136~10~16 minecraft:wool 1
setblock ~134~17~15 minecraft:quartz_block
fill ~134~24~15 ~136~24~16 minecraft:wool 1
fill ~134~25~15 ~136~25~15 minecraft:quartz_stairs 3
fill ~134~29~15 ~136~29~15 minecraft:quartz_stairs 7
fill ~134~30~15 ~136~30~16 minecraft:wool 1
setblock ~135~15~15 minecraft:stone_brick_stairs 7
setblock ~135~16~15 minecraft:iron_block
setblock ~135~17~15 minecraft:stonebrick
setblock ~135~18~15 minecraft:double_stone_block_slab 6
setblock ~135~19~15 minecraft:stone_brick_stairs 3
setblock ~135~32~15 minecraft:heavy_weighted_pressure_plate
fill ~136~15~15 ~137~15~16 minecraft:quartz_block
fill ~136~16~15 ~137~19~15 minecraft:quartz_block
setblock ~137~5~15 minecraft:stonebrick
setblock ~137~9~15 minecraft:stonebrick
setblock ~137~25~15 minecraft:stonebrick
setblock ~137~29~15 minecraft:stonebrick
fill ~138~4~15 ~138~4~16 minecraft:wool 1
fill ~138~5~15 ~140~5~15 minecraft:quartz_stairs 3
fill ~138~9~15 ~140~9~15 minecraft:quartz_stairs 7
fill ~138~10~15 ~138~10~16 minecraft:wool 1
setblock ~138~15~15 minecraft:quartz_stairs 1
fill ~138~16~15 ~138~18~15 minecraft:cobblestone_wall
setblock ~138~19~15 minecraft:quartz_stairs 5
fill ~138~24~15 ~138~24~16 minecraft:wool 1
fill ~138~25~15 ~140~25~15 minecraft:quartz_stairs 3
fill ~138~29~15 ~140~29~15 minecraft:quartz_stairs 7
fill ~138~30~15 ~138~30~16 minecraft:wool 1
setblock ~139~3~15 minecraft:stone_brick_stairs 7
fill ~139~4~15 ~139~4~16 minecraft:cobblestone_wall
fill ~139~10~15 ~139~10~16 minecraft:cobblestone_wall
setblock ~139~11~15 minecraft:stone_brick_stairs 3
setblock ~139~15~15 minecraft:dispenser 3
fill ~139~16~15 ~139~17~15 minecraft:quartz_stairs
setblock ~139~18~15 minecraft:quartz_stairs 4
setblock ~139~19~15 minecraft:dispenser 3
setblock ~139~23~15 minecraft:stone_brick_stairs 7
fill ~139~24~15 ~139~24~16 minecraft:cobblestone_wall
fill ~139~30~15 ~139~30~16 minecraft:cobblestone_wall
setblock ~139~31~15 minecraft:stone_brick_stairs 3
fill ~140~3~15 ~140~3~16 minecraft:stone_brick_stairs 4
fill ~140~11~15 ~140~11~16 minecraft:stone_brick_stairs
fill ~140~15~15 ~140~15~16 minecraft:quartz_block
setblock ~140~16~15 minecraft:quartz_stairs 4
fill ~140~17~15 ~140~17~16 minecraft:quartz_block
setblock ~140~18~15 minecraft:quartz_stairs
fill ~140~19~15 ~140~19~16 minecraft:quartz_block
fill ~140~23~15 ~140~23~16 minecraft:stone_brick_stairs 4
fill ~140~31~15 ~140~31~16 minecraft:stone_brick_stairs
setblock ~142~6~15 minecraft:quartz_stairs 5
setblock ~142~7~15 minecraft:quartz_block
setblock ~142~8~15 minecraft:quartz_stairs 1
setblock ~142~11~15 minecraft:quartz_block
setblock ~142~23~15 minecraft:quartz_block
setblock ~142~26~15 minecraft:quartz_stairs 5
setblock ~142~27~15 minecraft:quartz_block
setblock ~142~28~15 minecraft:quartz_stairs 1
setblock ~143~6~15 minecraft:quartz_stairs 6
setblock ~143~8~15 minecraft:quartz_stairs 2
setblock ~143~26~15 minecraft:quartz_stairs 6
setblock ~143~28~15 minecraft:quartz_stairs 2
setblock ~144~6~15 minecraft:quartz_block
setblock ~144~8~15 minecraft:quartz_block
setblock ~144~26~15 minecraft:quartz_block
setblock ~144~28~15 minecraft:quartz_block
fill ~145~4~15 ~145~4~16 minecraft:stone_brick_stairs 7
setblock ~145~6~15 minecraft:cobblestone_wall
setblock ~145~7~15 minecraft:cobblestone_wall
setblock ~145~8~15 minecraft:cobblestone_wall
fill ~145~10~15 ~145~10~16 minecraft:stone_brick_stairs 3
fill ~145~24~15 ~145~24~16 minecraft:stone_brick_stairs 7
setblock ~145~26~15 minecraft:cobblestone_wall
setblock ~145~27~15 minecraft:cobblestone_wall
setblock ~145~28~15 minecraft:cobblestone_wall
fill ~145~30~15 ~145~30~16 minecraft:stone_brick_stairs 3
fill ~146~3~15 ~149~3~15 minecraft:quartz_stairs 7
fill ~146~6~15 ~147~6~15 minecraft:stone_brick_stairs 3
fill ~146~8~15 ~147~8~15 minecraft:stone_brick_stairs 7
fill ~146~11~15 ~149~11~15 minecraft:quartz_stairs 3
fill ~146~23~15 ~149~23~15 minecraft:quartz_stairs 7
fill ~146~26~15 ~147~26~15 minecraft:stone_brick_stairs 3
fill ~146~28~15 ~147~28~15 minecraft:stone_brick_stairs 7
fill ~146~31~15 ~149~31~15 minecraft:quartz_stairs 3
setblock ~148~6~15 minecraft:stone_brick_stairs
setblock ~148~8~15 minecraft:stone_brick_stairs 4
setblock ~148~26~15 minecraft:stone_brick_stairs
setblock ~148~28~15 minecraft:stone_brick_stairs 4
fill ~149~4~15 ~149~4~16 minecraft:stone_brick_stairs 6
fill ~149~10~15 ~149~10~16 minecraft:stone_brick_stairs 2
fill ~149~24~15 ~149~24~16 minecraft:stone_brick_stairs 6
fill ~149~30~15 ~149~30~16 minecraft:stone_brick_stairs 2
setblock ~150~5~15 minecraft:stone_brick_stairs 6
setblock ~150~9~15 minecraft:stone_brick_stairs 2
setblock ~150~25~15 minecraft:stone_brick_stairs 6
setblock ~150~29~15 minecraft:stone_brick_stairs 2
setblock ~107~7~16 minecraft:quartz_stairs 6
fill ~107~13~16 ~107~13~22 minecraft:quartz_block
fill ~107~21~16 ~107~21~22 minecraft:quartz_block
setblock ~107~27~16 minecraft:quartz_stairs 2
setblock ~108~7~16 minecraft:double_stone_block_slab 6
fill ~108~13~16 ~108~13~22 minecraft:stonebrick
fill ~108~15~16 ~110~15~16 minecraft:quartz_stairs 7
setblock ~108~18~16 minecraft:stone
fill ~108~19~16 ~110~19~16 minecraft:quartz_stairs 3
fill ~108~21~16 ~108~21~22 minecraft:stonebrick
setblock ~108~24~16 minecraft:stone
setblock ~108~27~16 minecraft:stone_block_slab 6
fill ~109~10~16 ~110~10~16 minecraft:furnace 3
fill ~109~13~16 ~110~13~16 minecraft:cobblestone
setblock ~109~14~16 minecraft:stone_block_slab 6
setblock ~109~16~16 minecraft:anvil 3
setblock ~109~17~16 minecraft:double_stone_block_slab
setblock ~109~18~16 minecraft:quartz_stairs 7
setblock ~109~20~16 minecraft:stone_block_slab 14
fill ~109~21~16 ~110~21~16 minecraft:cobblestone
fill ~109~24~16 ~110~24~16 minecraft:furnace 3
fill ~110~6~16 ~110~6~17 minecraft:double_stone_block_slab 6
fill ~110~14~16 ~111~14~17 minecraft:quartz_block
setblock ~110~16~16 minecraft:stonebrick
setblock ~110~17~16 minecraft:furnace 5
setblock ~110~18~16 minecraft:stone_button 3
fill ~110~20~16 ~111~20~17 minecraft:quartz_block
fill ~110~28~16 ~110~28~17 minecraft:double_stone_block_slab 6
fill ~111~6~16 ~111~6~17 minecraft:quartz_stairs 4
fill ~111~8~16 ~115~9~16 minecraft:stonebrick
fill ~111~11~16 ~114~11~16 minecraft:stonebrick
fill ~111~13~16 ~114~13~16 minecraft:quartz_stairs 6
setblock ~111~15~16 minecraft:quartz_stairs 6
setblock ~111~16~16 minecraft:quartz_stairs 2
setblock ~111~18~16 minecraft:quartz_stairs 6
setblock ~111~19~16 minecraft:quartz_stairs 2
fill ~111~21~16 ~114~21~16 minecraft:quartz_stairs 2
fill ~111~23~16 ~114~23~16 minecraft:stonebrick
fill ~111~25~16 ~121~25~16 minecraft:stonebrick
fill ~111~26~16 ~115~26~16 minecraft:stonebrick
fill ~111~28~16 ~111~28~17 minecraft:quartz_stairs
setblock ~112~6~16 minecraft:double_stone_block_slab 6
setblock ~112~14~16 minecraft:stonebrick
fill ~112~15~16 ~112~16~16 minecraft:stonebrick
fill ~112~18~16 ~112~19~16 minecraft:stonebrick
setblock ~112~20~16 minecraft:stonebrick
setblock ~112~28~16 minecraft:stone_block_slab 6
fill ~113~7~16 ~114~7~16 minecraft:stonebrick
fill ~113~15~16 ~114~15~16 minecraft:quartz_stairs 6
fill ~113~16~16 ~114~16~16 minecraft:quartz_stairs 2
fill ~113~17~16 ~115~17~16 minecraft:stone_block_slab
fill ~113~18~16 ~114~18~16 minecraft:quartz_stairs 6
fill ~113~19~16 ~114~19~16 minecraft:quartz_stairs 2
fill ~113~27~16 ~114~27~16 minecraft:stonebrick
setblock ~114~14~16 minecraft:stonebrick
setblock ~114~20~16 minecraft:stonebrick
fill ~115~5~16 ~116~5~16 minecraft:stone_block_slab 14
setblock ~115~7~16 minecraft:furnace 5
fill ~115~10~16 ~120~10~16 minecraft:stonebrick
fill ~115~13~16 ~115~13~25 minecraft:stonebrick
fill ~115~14~16 ~116~14~17 minecraft:quartz_block
fill ~115~15~16 ~115~16~16 minecraft:stonebrick
fill ~115~18~16 ~115~19~16 minecraft:stonebrick
fill ~115~20~16 ~116~20~17 minecraft:quartz_block
fill ~115~21~16 ~115~21~25 minecraft:stonebrick
fill ~115~24~16 ~120~24~16 minecraft:stonebrick
setblock ~115~27~16 minecraft:furnace 5
fill ~115~29~16 ~116~29~16 minecraft:stone_block_slab 6
fill ~116~7~16 ~120~7~16 minecraft:iron_block
fill ~116~8~16 ~120~8~16 minecraft:cobblestone
fill ~116~9~16 ~121~9~16 minecraft:stonebrick
setblock ~116~15~16 minecraft:quartz_stairs 6
setblock ~116~16~16 minecraft:quartz_stairs 2
setblock ~116~17~16 minecraft:double_stone_block_slab
setblock ~116~18~16 minecraft:quartz_stairs 6
setblock ~116~19~16 minecraft:quartz_stairs 2
fill ~116~26~16 ~120~26~16 minecraft:cobblestone
fill ~116~27~16 ~120~27~16 minecraft:iron_block
fill ~117~6~16 ~120~6~16 minecraft:stonebrick
setblock ~117~15~16 minecraft:double_stone_block_slab
setblock ~117~16~16 minecraft:stone_brick_stairs 7
fill ~117~17~16 ~118~17~16 minecraft:furnace 5
setblock ~117~18~16 minecraft:stone_brick_stairs 3
setblock ~117~19~16 minecraft:double_stone_block_slab
fill ~117~28~16 ~120~28~16 minecraft:stonebrick
setblock ~118~14~16 minecraft:stone_block_slab 14
setblock ~118~15~16 minecraft:furnace 3
setblock ~118~16~16 minecraft:double_stone_block_slab 6
setblock ~118~18~16 minecraft:double_stone_block_slab 6
setblock ~118~19~16 minecraft:furnace 3
setblock ~118~20~16 minecraft:stone_block_slab 6
fill ~119~15~16 ~120~15~17 minecraft:quartz_block
fill ~119~16~16 ~119~19~17 minecraft:quartz_block
setblock ~120~3~16 minecraft:stone_block_slab 8
fill ~120~16~16 ~120~18~16 minecraft:double_stone_block_slab 6
fill ~120~19~16 ~120~19~17 minecraft:quartz_block
setblock ~120~31~16 minecraft:stone_block_slab
setblock ~121~3~16 minecraft:quartz_stairs 6
fill ~121~4~16 ~123~4~16 minecraft:stonebrick
fill ~121~6~16 ~121~8~16 minecraft:double_wooden_slab 1
fill ~121~15~16 ~122~15~16 minecraft:quartz_stairs 3
fill ~121~16~16 ~122~16~16 minecraft:stone_brick_stairs 3
setblock ~121~17~16 minecraft:stonebrick
fill ~121~18~16 ~122~18~16 minecraft:stone_brick_stairs 7
fill ~121~19~16 ~122~19~16 minecraft:quartz_stairs 7
fill ~121~26~16 ~121~28~16 minecraft:double_wooden_slab 1
fill ~121~30~16 ~123~30~16 minecraft:stonebrick
setblock ~121~31~16 minecraft:quartz_stairs 2
setblock ~122~3~16 minecraft:quartz_block
fill ~122~6~16 ~122~8~16 minecraft:log
setblock ~122~17~16 minecraft:double_stone_block_slab
fill ~122~26~16 ~122~28~16 minecraft:log
setblock ~122~31~16 minecraft:quartz_block
fill ~123~5~16 ~124~5~16 minecraft:stone_brick_stairs 6
fill ~123~6~16 ~130~8~16 minecraft:stonebrick
fill ~123~9~16 ~124~9~16 minecraft:stone_brick_stairs 2
setblock ~123~15~16 minecraft:double_stone_block_slab 6
fill ~123~16~16 ~123~18~16 minecraft:cobblestone_wall
setblock ~123~19~16 minecraft:double_stone_block_slab 6
fill ~123~25~16 ~124~25~16 minecraft:stone_brick_stairs 6
fill ~123~26~16 ~130~28~16 minecraft:stonebrick
fill ~123~29~16 ~124~29~16 minecraft:stone_brick_stairs 2
setblock ~124~3~16 minecraft:double_stone_block_slab
setblock ~124~31~16 minecraft:double_stone_block_slab
fill ~125~4~16 ~126~4~16 minecraft:stonebrick
fill ~125~9~16 ~129~9~16 minecraft:stonebrick
fill ~125~17~16 ~129~17~16 minecraft:stonebrick
fill ~125~25~16 ~129~25~16 minecraft:stonebrick
fill ~125~30~16 ~126~30~16 minecraft:stonebrick
fill ~126~2~16 ~126~2~17 minecraft:stone_block_slab 14
setblock ~126~12~16 minecraft:double_stone_block_slab 6
fill ~126~15~16 ~132~15~16 minecraft:quartz_block
fill ~126~16~16 ~130~16~16 minecraft:quartz_block
fill ~126~18~16 ~130~19~16 minecraft:quartz_block
setblock ~126~22~16 minecraft:double_stone_block_slab 6
fill ~126~32~16 ~126~32~17 minecraft:stone_block_slab 6
setblock ~127~3~16 minecraft:stone_block_slab 8
setblock ~127~12~16 minecraft:quartz_block
fill ~127~22~16 ~127~22~17 minecraft:quartz_block
fill ~127~29~16 ~129~29~17 minecraft:stonebrick
setblock ~127~31~16 minecraft:stone_block_slab
setblock ~128~4~16 minecraft:iron_bars
setblock ~128~20~16 minecraft:stone_brick_stairs
setblock ~128~30~16 minecraft:iron_bars
setblock ~129~4~16 minecraft:stonebrick
setblock ~129~12~16 minecraft:cobblestone_wall 
setblock ~129~20~16 minecraft:stone_block_slab
setblock ~129~22~16 minecraft:cobblestone_wall 
setblock ~129~30~16 minecraft:stonebrick
fill ~130~3~16 ~131~3~16 minecraft:quartz_stairs 6
fill ~130~5~16 ~130~5~18 minecraft:quartz_block
fill ~130~9~16 ~130~9~18 minecraft:quartz_block
setblock ~130~12~16 minecraft:quartz_block
setblock ~130~14~16 minecraft:stone_block_slab 14
fill ~130~17~16 ~130~17~17 minecraft:quartz_block
setblock ~130~22~16 minecraft:quartz_block
fill ~130~25~16 ~130~25~18 minecraft:quartz_block
fill ~130~29~16 ~130~29~18 minecraft:quartz_block
fill ~130~31~16 ~131~31~16 minecraft:quartz_stairs 2
setblock ~131~4~16 minecraft:iron_bars
fill ~131~5~16 ~140~5~16 minecraft:stone_brick_stairs 6
fill ~131~6~16 ~132~6~16 minecraft:quartz_stairs 3
fill ~131~8~16 ~132~8~16 minecraft:quartz_stairs 7
fill ~131~9~16 ~140~9~16 minecraft:stone_brick_stairs 2
setblock ~131~10~16 minecraft:iron_bars
setblock ~131~12~16 minecraft:quartz_stairs
setblock ~131~14~16 minecraft:quartz_stairs
fill ~131~16~16 ~139~18~16 minecraft:stonebrick
fill ~131~19~16 ~139~19~16 minecraft:quartz_block
setblock ~131~20~16 minecraft:double_stone_block_slab 6
setblock ~131~22~16 minecraft:quartz_stairs 4
setblock ~131~24~16 minecraft:iron_bars
fill ~131~25~16 ~140~25~16 minecraft:stone_brick_stairs 6
fill ~131~26~16 ~132~26~16 minecraft:quartz_stairs 3
fill ~131~28~16 ~132~28~16 minecraft:quartz_stairs 7
fill ~131~29~16 ~140~29~16 minecraft:stone_brick_stairs 2
setblock ~131~30~16 minecraft:iron_bars
setblock ~132~3~16 minecraft:double_stone_block_slab 6
fill ~132~11~16 ~137~11~16 minecraft:stone_brick_stairs 2
setblock ~132~14~16 minecraft:quartz_stairs 1
setblock ~132~20~16 minecraft:stone_block_slab 6
fill ~132~23~16 ~137~23~16 minecraft:stone_brick_stairs 6
setblock ~132~31~16 minecraft:double_stone_block_slab 6
setblock ~133~3~16 minecraft:double_stone_block_slab
setblock ~133~6~16 minecraft:stonebrick
setblock ~133~7~16 minecraft:stonebrick
setblock ~133~8~16 minecraft:stonebrick
setblock ~133~14~16 minecraft:stone_block_slab 14
setblock ~133~20~16 minecraft:stone_brick_stairs 3
setblock ~133~26~16 minecraft:stonebrick
setblock ~133~27~16 minecraft:stonebrick
setblock ~133~28~16 minecraft:stonebrick
setblock ~133~31~16 minecraft:double_stone_block_slab
setblock ~134~3~16 minecraft:quartz_stairs 6
fill ~134~6~16 ~136~6~16 minecraft:quartz_stairs 3
fill ~134~8~16 ~136~8~16 minecraft:quartz_stairs 7
setblock ~134~14~16 minecraft:quartz_stairs 7
setblock ~134~20~16 minecraft:quartz_stairs 1
fill ~134~26~16 ~136~26~16 minecraft:quartz_stairs 3
fill ~134~28~16 ~136~28~16 minecraft:quartz_stairs 7
setblock ~134~31~16 minecraft:quartz_stairs 2
setblock ~135~3~16 minecraft:double_stone_block_slab
setblock ~135~14~16 minecraft:stone_block_slab 14
setblock ~135~15~16 minecraft:quartz_block
setblock ~135~20~16 minecraft:stone_block_slab 6
setblock ~135~31~16 minecraft:double_stone_block_slab
fill ~136~3~16 ~139~3~16 minecraft:quartz_stairs 6
setblock ~136~14~16 minecraft:quartz_stairs 7
setblock ~136~20~16 minecraft:quartz_stairs 1
fill ~136~31~16 ~139~31~16 minecraft:quartz_stairs 2
setblock ~137~6~16 minecraft:stonebrick
setblock ~137~7~16 minecraft:stonebrick
setblock ~137~8~16 minecraft:stonebrick
setblock ~137~14~16 minecraft:stone_block_slab 14
fill ~137~20~16 ~138~20~16 minecraft:stone_block_slab 6
setblock ~137~26~16 minecraft:stonebrick
setblock ~137~27~16 minecraft:stonebrick
setblock ~137~28~16 minecraft:stonebrick
fill ~138~6~16 ~140~6~16 minecraft:quartz_stairs 3
fill ~138~8~16 ~140~8~16 minecraft:quartz_stairs 7
fill ~138~11~16 ~139~11~16 minecraft:quartz_stairs 2
fill ~138~15~16 ~139~15~16 minecraft:quartz_block
fill ~138~23~16 ~139~23~16 minecraft:quartz_stairs 6
fill ~138~26~16 ~140~26~16 minecraft:quartz_stairs 3
fill ~138~28~16 ~140~28~16 minecraft:quartz_stairs 7
setblock ~139~14~16 minecraft:double_stone_block_slab 6
fill ~140~16~16 ~144~16~16 minecraft:quartz_block
fill ~140~18~16 ~143~18~16 minecraft:quartz_block
fill ~141~3~16 ~142~3~16 minecraft:quartz_stairs 6
fill ~141~11~16 ~144~11~16 minecraft:quartz_stairs 2
fill ~141~15~16 ~144~15~16 minecraft:quartz_stairs 7
fill ~141~17~16 ~142~17~16 minecraft:quartz_stairs 3
fill ~141~19~16 ~144~19~16 minecraft:quartz_stairs 3
fill ~141~23~16 ~144~23~16 minecraft:quartz_stairs 6
fill ~141~31~16 ~144~31~16 minecraft:quartz_stairs 2
setblock ~142~4~16 minecraft:stone_brick_stairs 3
setblock ~142~10~16 minecraft:stone_brick_stairs 7
setblock ~142~24~16 minecraft:stone_brick_stairs 3
setblock ~142~30~16 minecraft:stone_brick_stairs 7
setblock ~143~4~16 minecraft:stone_brick_stairs
fill ~143~7~16 ~144~7~16 minecraft:quartz_block
setblock ~143~10~16 minecraft:stone_brick_stairs 4
setblock ~143~17~16 minecraft:stone_brick_stairs 3
setblock ~143~24~16 minecraft:stone_brick_stairs
fill ~143~27~16 ~144~27~16 minecraft:quartz_block
setblock ~143~30~16 minecraft:stone_brick_stairs 4
setblock ~144~17~16 minecraft:quartz_stairs 3
setblock ~144~18~16 minecraft:double_stone_block_slab
setblock ~145~3~16 minecraft:stone_brick_stairs 6
setblock ~145~5~16 minecraft:stone_brick_stairs 6
fill ~145~6~16 ~145~8~16 minecraft:double_stone_block_slab
setblock ~145~9~16 minecraft:stone_brick_stairs 2
setblock ~145~11~16 minecraft:stone_brick_stairs 2
setblock ~145~15~16 minecraft:stone_brick_stairs 7
fill ~145~16~16 ~145~18~16 minecraft:stonebrick
setblock ~145~19~16 minecraft:stone_brick_stairs 3
setblock ~145~23~16 minecraft:stone_brick_stairs 6
setblock ~145~25~16 minecraft:stone_brick_stairs 6
fill ~145~26~16 ~145~28~16 minecraft:double_stone_block_slab
setblock ~145~29~16 minecraft:stone_brick_stairs 2
setblock ~145~31~16 minecraft:stone_brick_stairs 2
fill ~146~3~16 ~149~3~16 minecraft:quartz_stairs 6
fill ~146~5~16 ~146~5~17 minecraft:furnace 5
fill ~146~6~16 ~149~8~16 minecraft:stonebrick
setblock ~146~9~16 minecraft:furnace 5
fill ~146~11~16 ~149~11~16 minecraft:quartz_stairs 2
fill ~146~15~16 ~149~15~16 minecraft:quartz_stairs 7
fill ~146~16~16 ~149~16~16 minecraft:quartz_stairs 3
fill ~146~17~16 ~149~17~16 minecraft:quartz_block
fill ~146~18~16 ~149~18~16 minecraft:quartz_stairs 7
fill ~146~19~16 ~149~19~16 minecraft:quartz_stairs 3
fill ~146~23~16 ~149~23~16 minecraft:quartz_stairs 6
fill ~146~25~16 ~146~25~17 minecraft:furnace 5
fill ~146~26~16 ~149~28~16 minecraft:stonebrick
setblock ~146~29~16 minecraft:furnace 5
fill ~146~31~16 ~149~31~16 minecraft:quartz_stairs 2
fill ~147~5~16 ~147~5~17 minecraft:stone
fill ~147~9~16 ~147~9~17 minecraft:stone
fill ~147~25~16 ~147~25~17 minecraft:stone
fill ~147~29~16 ~147~29~17 minecraft:stone
fill ~148~5~16 ~148~5~17 minecraft:bedrock
fill ~148~9~16 ~148~9~17 minecraft:bedrock
fill ~148~25~16 ~148~25~17 minecraft:bedrock
fill ~148~29~16 ~148~29~17 minecraft:bedrock
fill ~149~5~16 ~149~5~17 minecraft:stone_brick_stairs 6
fill ~149~9~16 ~149~9~17 minecraft:stone_brick_stairs 2
fill ~149~25~16 ~149~25~17 minecraft:stone_brick_stairs 6
fill ~149~29~16 ~149~29~17 minecraft:stone_brick_stairs 2
setblock ~150~6~16 minecraft:stone_brick_stairs 6
setblock ~150~7~16 minecraft:stonebrick
setblock ~150~8~16 minecraft:stone_brick_stairs 2
setblock ~150~26~16 minecraft:stone_brick_stairs 6
setblock ~150~27~16 minecraft:stonebrick
setblock ~150~28~16 minecraft:stone_brick_stairs 2
setblock ~106~10~17 minecraft:quartz_stairs 3
fill ~106~11~17 ~106~11~18 minecraft:quartz_stairs 1
fill ~106~12~17 ~106~13~18 minecraft:double_stone_block_slab
fill ~106~14~17 ~106~14~19 minecraft:quartz_stairs 5
fill ~106~15~17 ~118~15~17 minecraft:quartz_block
fill ~106~16~17 ~107~18~21 minecraft:wool 14
fill ~106~19~17 ~118~19~17 minecraft:quartz_block
fill ~106~20~17 ~106~20~19 minecraft:quartz_stairs 1
fill ~106~21~17 ~106~22~18 minecraft:double_stone_block_slab
fill ~106~23~17 ~106~23~18 minecraft:quartz_stairs 5
setblock ~106~24~17 minecraft:quartz_stairs 7
setblock ~107~7~17 minecraft:double_stone_block_slab 6
fill ~107~8~17 ~126~9~17 minecraft:quartz_block
fill ~107~11~17 ~116~11~17 minecraft:quartz_block
fill ~107~23~17 ~116~23~17 minecraft:quartz_block
fill ~107~25~17 ~129~25~17 minecraft:quartz_block
fill ~107~26~17 ~126~26~17 minecraft:quartz_block
setblock ~107~27~17 minecraft:double_stone_block_slab 6
fill ~108~7~17 ~126~7~17 minecraft:quartz_block
setblock ~108~10~17 minecraft:quartz_block
setblock ~108~16~17 minecraft:dispenser 3
fill ~108~17~17 ~118~18~17 minecraft:quartz_block
setblock ~108~24~17 minecraft:quartz_block
fill ~108~27~17 ~126~27~17 minecraft:quartz_block
fill ~109~10~17 ~110~10~17 minecraft:stonebrick
fill ~109~13~17 ~114~13~17 minecraft:stonebrick
setblock ~109~14~17 minecraft:quartz_block
fill ~109~16~17 ~118~16~17 minecraft:quartz_block
setblock ~109~20~17 minecraft:quartz_block
fill ~109~21~17 ~114~21~17 minecraft:stonebrick
fill ~109~24~17 ~110~24~17 minecraft:stonebrick
setblock ~111~10~17 minecraft:stonebrick
setblock ~111~24~17 minecraft:stonebrick
fill ~112~6~17 ~113~6~17 minecraft:double_stone_block_slab
fill ~112~10~17 ~129~10~17 minecraft:quartz_block
fill ~112~14~17 ~114~14~17 minecraft:quartz_block
fill ~112~20~17 ~114~20~17 minecraft:quartz_block
fill ~112~24~17 ~131~24~17 minecraft:quartz_block
fill ~112~28~17 ~113~28~17 minecraft:double_stone_block_slab
fill ~114~5~17 ~115~5~17 minecraft:stone_block_slab 8
fill ~114~6~17 ~126~6~17 minecraft:quartz_block
fill ~114~28~17 ~126~28~17 minecraft:quartz_block
fill ~114~29~17 ~115~29~17 minecraft:stone_block_slab
fill ~116~5~17 ~117~5~17 minecraft:double_stone_block_slab
fill ~116~29~17 ~117~29~17 minecraft:double_stone_block_slab
fill ~117~14~17 ~117~14~23 minecraft:stone_block_slab 14
fill ~117~20~17 ~117~20~23 minecraft:stone_block_slab 6
fill ~118~4~17 ~119~4~17 minecraft:stone_block_slab 8
fill ~118~5~17 ~126~5~17 minecraft:quartz_block
fill ~118~14~17 ~118~14~23 minecraft:quartz_stairs 5
fill ~118~20~17 ~118~20~23 minecraft:quartz_stairs 1
fill ~118~29~17 ~126~29~17 minecraft:quartz_block
fill ~118~30~17 ~119~30~17 minecraft:stone_block_slab
fill ~119~14~17 ~120~14~17 minecraft:quartz_stairs 6
fill ~119~20~17 ~120~20~17 minecraft:quartz_stairs 2
fill ~120~4~17 ~121~4~17 minecraft:double_stone_block_slab
fill ~120~16~17 ~124~18~17 minecraft:quartz_block
fill ~120~30~17 ~121~30~17 minecraft:double_stone_block_slab
fill ~121~14~17 ~121~15~17 minecraft:quartz_block
fill ~121~19~17 ~123~19~17 minecraft:quartz_block
setblock ~121~20~17 minecraft:quartz_block
setblock ~122~3~17 minecraft:stone_block_slab 8
fill ~122~4~17 ~126~4~17 minecraft:quartz_block
fill ~122~12~17 ~123~12~17 minecraft:stone_block_slab 6
setblock ~122~13~17 minecraft:stone_block_slab 8
fill ~122~14~17 ~123~14~17 minecraft:quartz_stairs 7
fill ~122~15~17 ~124~15~17 minecraft:quartz_block
fill ~122~20~17 ~123~20~17 minecraft:quartz_stairs 3
setblock ~122~21~17 minecraft:stone_block_slab
fill ~122~22~17 ~125~22~17 minecraft:quartz_stairs 6
fill ~122~30~17 ~126~30~17 minecraft:quartz_block
setblock ~122~31~17 minecraft:stone_block_slab
fill ~123~3~17 ~124~3~17 minecraft:stone_block_slab 14
setblock ~123~13~17 minecraft:quartz_stairs 6
setblock ~123~21~17 minecraft:quartz_stairs 2
fill ~123~31~17 ~124~31~17 minecraft:stone_block_slab 6
fill ~124~13~17 ~126~13~17 minecraft:quartz_block
fill ~124~14~17 ~124~14~22 minecraft:stonebrick
fill ~124~19~17 ~124~20~17 minecraft:stonebrick
fill ~124~21~17 ~126~21~17 minecraft:quartz_block
fill ~125~14~17 ~126~14~17 minecraft:quartz_block
fill ~125~17~17 ~126~17~17 minecraft:quartz_block
fill ~125~20~17 ~126~20~17 minecraft:quartz_block
fill ~126~15~17 ~126~16~17 minecraft:quartz_block
fill ~126~18~17 ~126~19~17 minecraft:quartz_block
fill ~126~22~17 ~126~22~18 minecraft:stone_block_slab 6
setblock ~127~4~17 minecraft:stone_brick_stairs 4
fill ~127~6~17 ~129~8~17 minecraft:stonebrick
fill ~127~9~17 ~129~9~18 minecraft:quartz_block
setblock ~127~12~17 minecraft:quartz_stairs 5
setblock ~127~14~17 minecraft:stone_brick_stairs 4
fill ~127~15~17 ~129~15~23 minecraft:stonebrick
fill ~127~16~17 ~129~19~18 minecraft:stonebrick
setblock ~127~20~17 minecraft:stone_brick_stairs
fill ~127~26~17 ~129~28~17 minecraft:stonebrick
setblock ~127~30~17 minecraft:stone_brick_stairs
setblock ~128~4~17 minecraft:quartz_stairs 5
setblock ~128~12~17 minecraft:double_stone_block_slab
setblock ~128~14~17 minecraft:quartz_stairs 5
setblock ~128~20~17 minecraft:quartz_stairs 1
setblock ~128~22~17 minecraft:double_stone_block_slab
setblock ~128~30~17 minecraft:quartz_stairs 1
setblock ~129~4~17 minecraft:quartz_stairs 6
setblock ~129~11~17 minecraft:stone_brick_stairs 2
setblock ~129~14~17 minecraft:quartz_stairs 7
setblock ~129~20~17 minecraft:quartz_stairs 3
setblock ~129~23~17 minecraft:stone_brick_stairs 6
setblock ~129~30~17 minecraft:quartz_stairs 2
fill ~130~6~17 ~130~8~18 minecraft:quartz_block
fill ~130~14~17 ~131~14~17 minecraft:quartz_block
fill ~130~15~17 ~130~15~18 minecraft:quartz_block
setblock ~130~16~17 minecraft:quartz_block
fill ~130~18~17 ~130~20~17 minecraft:quartz_block
fill ~130~26~17 ~130~28~18 minecraft:quartz_block
fill ~131~4~17 ~139~4~17 minecraft:quartz_block
fill ~131~5~17 ~141~5~17 minecraft:stonebrick
fill ~131~6~17 ~139~6~17 minecraft:cobblestone_wall
fill ~131~7~17 ~141~7~17 minecraft:stonebrick
fill ~131~8~17 ~139~8~17 minecraft:cobblestone_wall
fill ~131~9~17 ~141~9~17 minecraft:stonebrick
setblock ~131~10~17 minecraft:quartz_block
fill ~131~15~17 ~141~15~17 minecraft:stonebrick
fill ~131~16~17 ~139~16~17 minecraft:cobblestone_wall
fill ~131~17~17 ~141~17~17 minecraft:stonebrick
fill ~131~18~17 ~139~18~17 minecraft:cobblestone_wall
fill ~131~19~17 ~141~19~17 minecraft:stonebrick
fill ~131~20~17 ~139~20~17 minecraft:quartz_block
fill ~131~25~17 ~141~25~17 minecraft:stonebrick
fill ~131~26~17 ~139~26~17 minecraft:cobblestone_wall
fill ~131~27~17 ~141~27~17 minecraft:stonebrick
fill ~131~28~17 ~139~28~17 minecraft:cobblestone_wall
fill ~131~29~17 ~141~29~17 minecraft:stonebrick
fill ~131~30~17 ~139~30~17 minecraft:quartz_block
fill ~132~10~17 ~137~10~17 minecraft:stone_brick_stairs 2
fill ~132~14~17 ~137~14~17 minecraft:stone_brick_stairs 7
fill ~132~24~17 ~137~24~17 minecraft:stone_brick_stairs 6
setblock ~134~3~17 minecraft:stone_block_slab 8
setblock ~134~21~17 minecraft:stone_block_slab
setblock ~134~31~17 minecraft:stone_block_slab
setblock ~136~3~17 minecraft:stone_block_slab 8
setblock ~136~21~17 minecraft:stone_block_slab
setblock ~136~31~17 minecraft:stone_block_slab
fill ~138~10~17 ~139~10~17 minecraft:quartz_block
fill ~138~14~17 ~139~14~17 minecraft:quartz_block
fill ~138~24~17 ~139~24~17 minecraft:quartz_block
setblock ~140~4~17 minecraft:stone_brick_stairs 4
fill ~140~6~17 ~141~6~17 minecraft:stonebrick
fill ~140~8~17 ~141~8~17 minecraft:stonebrick
setblock ~140~10~17 minecraft:stone_brick_stairs
setblock ~140~14~17 minecraft:stone_brick_stairs 4
fill ~140~16~17 ~141~16~17 minecraft:stonebrick
fill ~140~18~17 ~141~18~17 minecraft:stonebrick
setblock ~140~20~17 minecraft:stone_brick_stairs
setblock ~140~24~17 minecraft:stone_brick_stairs 4
fill ~140~26~17 ~141~26~17 minecraft:stonebrick
fill ~140~28~17 ~141~28~17 minecraft:stonebrick
setblock ~140~30~17 minecraft:stone_brick_stairs
fill ~141~4~17 ~144~4~17 minecraft:stone_brick_stairs 6
fill ~141~10~17 ~144~10~17 minecraft:stone_brick_stairs 2
fill ~141~14~17 ~144~14~17 minecraft:stone_brick_stairs 7
fill ~141~20~17 ~144~20~17 minecraft:stone_brick_stairs 3
fill ~141~24~17 ~144~24~17 minecraft:stone_brick_stairs 6
fill ~141~30~17 ~144~30~17 minecraft:stone_brick_stairs 2
setblock ~142~5~17 minecraft:stone_brick_stairs 3
setblock ~142~9~17 minecraft:stone_brick_stairs 7
setblock ~142~15~17 minecraft:stone_brick_stairs 2
setblock ~142~19~17 minecraft:stone_brick_stairs 6
setblock ~142~25~17 minecraft:stone_brick_stairs 3
setblock ~142~29~17 minecraft:stone_brick_stairs 7
setblock ~143~5~17 minecraft:stone_brick_stairs
setblock ~143~9~17 minecraft:stone_brick_stairs 4
setblock ~143~15~17 minecraft:stone_brick_stairs
setblock ~143~19~17 minecraft:stone_brick_stairs 4
setblock ~143~25~17 minecraft:stone_brick_stairs
setblock ~143~29~17 minecraft:stone_brick_stairs 4
setblock ~145~4~17 minecraft:stonebrick
fill ~145~5~17 ~145~6~17 minecraft:stone_brick_stairs 2
fill ~145~7~17 ~145~7~18 minecraft:stonebrick
fill ~145~8~17 ~145~9~17 minecraft:stone_brick_stairs 6
setblock ~145~10~17 minecraft:stonebrick
setblock ~145~14~17 minecraft:stonebrick
fill ~145~15~17 ~145~16~17 minecraft:stone_brick_stairs 3
setblock ~145~17~17 minecraft:stonebrick
fill ~145~18~17 ~145~19~17 minecraft:stone_brick_stairs 7
setblock ~145~20~17 minecraft:stonebrick
setblock ~145~24~17 minecraft:stonebrick
fill ~145~25~17 ~145~26~17 minecraft:stone_brick_stairs 2
fill ~145~27~17 ~145~27~18 minecraft:stonebrick
fill ~145~28~17 ~145~29~17 minecraft:stone_brick_stairs 6
setblock ~145~30~17 minecraft:stonebrick
fill ~146~4~17 ~149~4~17 minecraft:quartz_block
fill ~146~6~17 ~146~8~17 minecraft:furnace 5
setblock ~146~9~17 minecraft:furnace 3
fill ~146~10~17 ~149~10~17 minecraft:quartz_block
fill ~146~14~17 ~149~14~17 minecraft:quartz_block
fill ~146~15~17 ~146~15~18 minecraft:furnace 5
fill ~146~16~17 ~146~18~17 minecraft:furnace 5
setblock ~146~19~17 minecraft:furnace 2
fill ~146~20~17 ~149~20~17 minecraft:quartz_block
fill ~146~24~17 ~149~24~17 minecraft:quartz_block
fill ~146~26~17 ~146~28~17 minecraft:furnace 5
setblock ~146~29~17 minecraft:furnace 3
fill ~146~30~17 ~149~30~17 minecraft:quartz_block
fill ~147~6~17 ~147~8~17 minecraft:stone
fill ~147~15~17 ~147~15~18 minecraft:stone
fill ~147~16~17 ~147~19~17 minecraft:stone
fill ~147~26~17 ~147~28~17 minecraft:stone
fill ~148~6~17 ~148~8~17 minecraft:bedrock
fill ~148~15~17 ~148~15~18 minecraft:bedrock
fill ~148~16~17 ~148~19~17 minecraft:bedrock
fill ~148~26~17 ~148~28~17 minecraft:bedrock
setblock ~149~6~17 minecraft:stone_brick_stairs 6
setblock ~149~7~17 minecraft:cobblestone_wall
setblock ~149~8~17 minecraft:stone_brick_stairs 2
fill ~149~15~17 ~149~15~18 minecraft:stone_brick_stairs 7
setblock ~149~16~17 minecraft:stone_brick_stairs 7
setblock ~149~17~17 minecraft:cobblestone_wall
fill ~149~18~17 ~149~19~17 minecraft:stone_brick_stairs 3
setblock ~149~26~17 minecraft:stone_brick_stairs 6
setblock ~149~27~17 minecraft:cobblestone_wall
setblock ~149~28~17 minecraft:stone_brick_stairs 2
setblock ~43~24~18 minecraft:cobblestone_wall
setblock ~51~24~18 minecraft:cobblestone_wall
fill ~106~15~18 ~107~15~24 minecraft:quartz_block
fill ~106~19~18 ~107~19~24 minecraft:quartz_block
fill ~107~11~18 ~115~11~18 minecraft:quartz_block
fill ~107~14~18 ~107~14~24 minecraft:quartz_block
fill ~107~20~18 ~107~20~24 minecraft:quartz_block
fill ~107~23~18 ~115~23~18 minecraft:quartz_block
fill ~108~10~18 ~111~10~18 minecraft:stone_block_slab 14
fill ~108~14~18 ~108~15~19 minecraft:stonebrick
fill ~108~16~18 ~108~20~18 minecraft:stonebrick
fill ~108~24~18 ~111~24~18 minecraft:stone_block_slab 6
fill ~109~13~18 ~110~13~22 minecraft:stonebrick
fill ~109~14~18 ~109~16~18 minecraft:stone_brick_stairs 6
fill ~109~17~18 ~109~17~19 minecraft:cobblestone_wall
fill ~109~18~18 ~109~20~18 minecraft:stone_brick_stairs 2
fill ~109~21~18 ~110~21~22 minecraft:stonebrick
fill ~110~8~18 ~111~8~18 minecraft:stone_block_slab 6
fill ~110~14~18 ~110~15~19 minecraft:stonebrick
fill ~110~16~18 ~110~20~18 minecraft:stonebrick
fill ~110~26~18 ~111~26~18 minecraft:stone_block_slab 14
fill ~111~12~18 ~114~12~18 minecraft:stonebrick
