setblock ~33 ~-3 ~102 stained_glass 4 
setblock ~34 ~-2 ~102 stained_glass 4 
setblock ~35 ~-2 ~102 stained_glass 1 
setblock ~34 ~-1 ~102 stained_glass 1 
setblock ~35 ~-1 ~101 stained_glass 1
fill ~35 ~-1 ~102 ~36 ~-1 ~102 stained_glass 14 
setblock ~35 ~-1 ~103 stained_glass 1 
setblock ~37 ~-1 ~102 stained_glass 1
fill ~35 ~0 ~102 ~40 ~0 ~102 stained_glass 14
fill ~36 ~0 ~101 ~39 ~0 ~101 stained_glass 14
fill ~36 ~0 ~103 ~39 ~0 ~103 stained_glass 14 
setblock ~36 ~1 ~102 stained_glass 1
fill ~37 ~1 ~102 ~42 ~1 ~102 stained_glass 14
fill ~38 ~1 ~101 ~40 ~1 ~101 stained_glass 14
fill ~38 ~1 ~103 ~40 ~1 ~103 stained_glass 14
fill ~43 ~1 ~100 ~44 ~1 ~100 stone_slab 13
fill ~43 ~1 ~101 ~44 ~1 ~101 stonebrick 0
fill ~43 ~1 ~102 ~44 ~1 ~102 stonebrick 0
fill ~43 ~1 ~103 ~44 ~1 ~103 stonebrick 0
fill ~43 ~1 ~104 ~44 ~1 ~104 stone_slab 13
fill ~45 ~1 ~100 ~51 ~1 ~100 stained_hardened_clay 9
fill ~45 ~1 ~101 ~52 ~1 ~101 stained_hardened_clay 9
fill ~45 ~1 ~102 ~54 ~1 ~102 stained_hardened_clay 9
fill ~45 ~1 ~103 ~52 ~1 ~103 stained_hardened_clay 9
fill ~45 ~1 ~104 ~51 ~1 ~104 stained_hardened_clay 9
fill ~48 ~1 ~99 ~51 ~1 ~99 stained_hardened_clay 9
fill ~48 ~1 ~105 ~51 ~1 ~105 stained_hardened_clay 9
fill ~54 ~1 ~100 ~54 ~1 ~104 stained_hardened_clay 9
fill ~55 ~1 ~97 ~56 ~1 ~97 planks 1
fill ~55 ~1 ~98 ~56 ~1 ~98 planks 1
fill ~55 ~1 ~99 ~56 ~1 ~99 planks 1
fill ~55 ~1 ~100 ~56 ~1 ~100 planks 1
fill ~55 ~1 ~101 ~56 ~1 ~101 planks 1
fill ~55 ~1 ~102 ~56 ~1 ~102 planks 1
fill ~55 ~1 ~103 ~56 ~1 ~103 planks 1
fill ~55 ~1 ~104 ~56 ~1 ~104 planks 1
fill ~55 ~1 ~105 ~56 ~1 ~105 planks 1
fill ~55 ~1 ~106 ~56 ~1 ~106 planks 1
fill ~55 ~1 ~107 ~56 ~1 ~107 planks 1
fill ~37 ~2 ~102 ~43 ~2 ~102 stained_glass 14
fill ~40 ~2 ~101 ~43 ~2 ~101 stained_glass 14
fill ~40 ~2 ~103 ~43 ~2 ~103 stained_glass 14 
setblock ~42 ~2 ~100 stone_brick_stairs 4 
setblock ~42 ~2 ~104 stone_brick_stairs 4
fill ~43 ~2 ~100 ~44 ~2 ~100 stonebrick 0
fill ~43 ~2 ~104 ~44 ~2 ~104 stonebrick 0
fill ~44 ~2 ~101 ~44 ~2 ~103 sea_lantern 0
fill ~45 ~2 ~99 ~53 ~2 ~99 stained_hardened_clay 9
fill ~45 ~2 ~100 ~47 ~2 ~100 stained_hardened_clay 9
fill ~45 ~2 ~104 ~47 ~2 ~104 stained_hardened_clay 9
fill ~45 ~2 ~105 ~53 ~2 ~105 stained_hardened_clay 9
fill ~48 ~2 ~98 ~49 ~2 ~98 stained_hardened_clay 9
fill ~48 ~2 ~106 ~49 ~2 ~106 stained_hardened_clay 9
fill ~50 ~2 ~100 ~53 ~2 ~100 stained_hardened_clay 9
fill ~50 ~2 ~101 ~53 ~2 ~101 stained_hardened_clay 9
fill ~50 ~2 ~102 ~53 ~2 ~102 stained_hardened_clay 9
fill ~50 ~2 ~103 ~53 ~2 ~103 stained_hardened_clay 9
fill ~50 ~2 ~104 ~53 ~2 ~104 stained_hardened_clay 9
fill ~51 ~2 ~98 ~53 ~2 ~98 stained_hardened_clay 9
fill ~51 ~2 ~106 ~53 ~2 ~106 stained_hardened_clay 9
fill ~52 ~2 ~97 ~52 ~7 ~97 stained_hardened_clay 9
fill ~52 ~2 ~107 ~52 ~7 ~107 stained_hardened_clay 9
fill ~54 ~2 ~96 ~55 ~2 ~96 planks 1
fill ~54 ~2 ~97 ~57 ~2 ~97 planks 1
fill ~54 ~2 ~98 ~57 ~2 ~98 planks 1
fill ~54 ~2 ~99 ~57 ~2 ~99 planks 1
fill ~54 ~2 ~100 ~57 ~2 ~100 planks 1
fill ~54 ~2 ~101 ~57 ~2 ~101 planks 1
fill ~54 ~2 ~102 ~57 ~2 ~102 planks 1
fill ~54 ~2 ~103 ~57 ~2 ~103 planks 1
fill ~54 ~2 ~104 ~57 ~2 ~104 planks 1
fill ~54 ~2 ~105 ~57 ~2 ~105 planks 1
fill ~54 ~2 ~106 ~57 ~2 ~106 planks 1
fill ~54 ~2 ~107 ~57 ~2 ~107 planks 1
fill ~54 ~2 ~108 ~55 ~2 ~108 planks 1
fill ~39 ~3 ~102 ~42 ~3 ~102 stained_glass 14
fill ~41 ~3 ~101 ~42 ~3 ~101 stained_glass 14
fill ~41 ~3 ~103 ~42 ~3 ~103 stained_glass 14
fill ~42 ~3 ~100 ~43 ~3 ~100 stonebrick 0
fill ~42 ~3 ~104 ~43 ~3 ~104 stonebrick 0
fill ~43 ~3 ~101 ~43 ~3 ~103 sea_lantern 0
fill ~44 ~3 ~99 ~48 ~3 ~99 stained_hardened_clay 9
fill ~44 ~3 ~105 ~48 ~3 ~105 stained_hardened_clay 9
setblock ~47 ~3 ~100 stained_hardened_clay 9
setblock ~47 ~3 ~104 stained_hardened_clay 9
fill ~48 ~3 ~98 ~51 ~3 ~98 stained_hardened_clay 9
fill ~48 ~3 ~106 ~51 ~3 ~106 stained_hardened_clay 9
fill ~50 ~3 ~99 ~51 ~3 ~99 stained_hardened_clay 9
fill ~50 ~3 ~105 ~51 ~3 ~105 stained_hardened_clay 9
fill ~53 ~3 ~97 ~53 ~4 ~97 stained_hardened_clay 9
fill ~53 ~3 ~98 ~53 ~3 ~97 stained_hardened_clay 9
fill ~53 ~3 ~106 ~53 ~3 ~107 stained_hardened_clay 9
fill ~54 ~3 ~96 ~56 ~3 ~96 planks 1
fill ~54 ~3 ~97 ~56 ~3 ~97 planks 1
fill ~54 ~3 ~98 ~56 ~3 ~98 planks 1
fill ~54 ~3 ~106 ~56 ~3 ~106 planks 1
fill ~54 ~3 ~107 ~56 ~3 ~107 planks 1
fill ~54 ~3 ~108 ~56 ~3 ~108 planks 1
fill ~56 ~3 ~99 ~56 ~5 ~99 planks 1
fill ~56 ~3 ~100 ~56 ~5 ~100 planks 1
fill ~56 ~3 ~101 ~56 ~5 ~101 planks 1
fill ~56 ~3 ~102 ~56 ~5 ~102 planks 1
fill ~56 ~3 ~103 ~56 ~5 ~103 planks 1
fill ~56 ~3 ~104 ~56 ~5 ~104 planks 1
fill ~56 ~3 ~105 ~56 ~5 ~105 planks 1
fill ~57 ~3 ~102 ~58 ~3 ~102 stained_hardened_clay 8
fill ~59 ~3 ~97 ~60 ~3 ~97 planks 1
fill ~59 ~3 ~98 ~60 ~3 ~98 planks 1
fill ~59 ~3 ~99 ~60 ~3 ~99 planks 1
fill ~59 ~3 ~100 ~60 ~3 ~100 planks 1
fill ~59 ~3 ~101 ~60 ~3 ~101 planks 1
fill ~59 ~3 ~102 ~60 ~3 ~102 planks 1
fill ~59 ~3 ~103 ~60 ~3 ~103 planks 1
fill ~59 ~3 ~104 ~60 ~3 ~104 planks 1
fill ~59 ~3 ~105 ~60 ~3 ~105 planks 1
fill ~59 ~3 ~106 ~60 ~3 ~106 planks 1
fill ~59 ~3 ~107 ~60 ~3 ~107 planks 1
setblock ~42 ~4 ~100 stone_slab 5
fill ~42 ~4 ~101 ~43 ~4 ~101 stonebrick 0
fill ~42 ~4 ~102 ~43 ~4 ~102 stonebrick 0
fill ~42 ~4 ~103 ~43 ~4 ~103 stonebrick 0
setblock ~42 ~4 ~104 stone_slab 5
setblock ~43 ~4 ~100 stained_hardened_clay 9
setblock ~43 ~4 ~104 stained_hardened_clay 9
fill ~44 ~4 ~99 ~46 ~4 ~99 stained_hardened_clay 9
fill ~44 ~4 ~105 ~46 ~4 ~105 stained_hardened_clay 9
fill ~47 ~4 ~98 ~51 ~4 ~98 stained_hardened_clay 9
fill ~47 ~4 ~106 ~51 ~4 ~106 stained_hardened_clay 9
setblock ~53 ~4 ~107 stained_hardened_clay 9
fill ~54 ~4 ~96 ~56 ~4 ~96 planks 1
fill ~54 ~4 ~97 ~56 ~4 ~97 planks 1
fill ~54 ~4 ~107 ~56 ~4 ~107 planks 1
fill ~54 ~4 ~108 ~56 ~4 ~108 planks 1
fill ~56 ~4 ~98 ~56 ~5 ~98 planks 1
fill ~56 ~4 ~106 ~56 ~5 ~106 planks 1
fill ~57 ~4 ~100 ~58 ~4 ~100 stained_hardened_clay 8
fill ~57 ~4 ~101 ~58 ~4 ~101 stained_hardened_clay 8
fill ~57 ~4 ~102 ~58 ~4 ~102 stained_hardened_clay 8
fill ~57 ~4 ~103 ~58 ~4 ~103 stained_hardened_clay 8
fill ~57 ~4 ~104 ~58 ~4 ~104 stained_hardened_clay 8
fill ~59 ~4 ~96 ~61 ~4 ~96 planks 1
fill ~59 ~4 ~97 ~61 ~4 ~97 planks 1
fill ~59 ~4 ~98 ~61 ~4 ~98 planks 1
fill ~59 ~4 ~99 ~61 ~4 ~99 planks 1
fill ~59 ~4 ~100 ~61 ~4 ~100 planks 1
fill ~59 ~4 ~101 ~61 ~4 ~101 planks 1
fill ~59 ~4 ~102 ~61 ~4 ~102 planks 1
fill ~59 ~4 ~103 ~61 ~4 ~103 planks 1
fill ~59 ~4 ~104 ~61 ~4 ~104 planks 1
fill ~59 ~4 ~105 ~61 ~4 ~105 planks 1
fill ~59 ~4 ~106 ~61 ~4 ~106 planks 1
fill ~59 ~4 ~107 ~61 ~4 ~107 planks 1
fill ~59 ~4 ~108 ~61 ~4 ~108 planks 1
fill ~64 ~4 ~99 ~64 ~6 ~99 planks 1
fill ~64 ~4 ~100 ~64 ~6 ~100 planks 1
fill ~64 ~4 ~101 ~64 ~6 ~101 planks 1
fill ~64 ~4 ~102 ~64 ~6 ~102 planks 1
fill ~64 ~4 ~103 ~64 ~6 ~103 planks 1
fill ~64 ~4 ~104 ~64 ~6 ~104 planks 1
fill ~64 ~4 ~105 ~64 ~6 ~105 planks 1
fill ~43 ~5 ~101 ~43 ~5 ~103 stained_hardened_clay 9
fill ~44 ~5 ~99 ~46 ~5 ~99 stained_hardened_clay 9
fill ~44 ~5 ~100 ~46 ~5 ~100 stained_hardened_clay 9
fill ~44 ~5 ~104 ~46 ~5 ~104 stained_hardened_clay 9
fill ~44 ~5 ~105 ~46 ~5 ~105 stained_hardened_clay 9
fill ~47 ~5 ~98 ~50 ~5 ~98 stained_hardened_clay 9
fill ~47 ~5 ~106 ~50 ~5 ~106 stained_hardened_clay 9
fill ~51 ~5 ~97 ~51 ~10 ~97 stained_hardened_clay 9
fill ~51 ~5 ~107 ~51 ~10 ~107 stained_hardened_clay 9
fill ~53 ~5 ~96 ~56 ~5 ~96 planks 1
fill ~53 ~5 ~97 ~56 ~5 ~97 planks 1
fill ~53 ~5 ~107 ~56 ~5 ~107 planks 1
fill ~53 ~5 ~108 ~56 ~5 ~108 planks 1
fill ~55 ~5 ~98 ~55 ~7 ~98 planks 1
fill ~55 ~5 ~99 ~55 ~7 ~99 planks 1
fill ~55 ~5 ~100 ~55 ~7 ~100 planks 1
fill ~55 ~5 ~101 ~55 ~7 ~101 planks 1
fill ~55 ~5 ~102 ~55 ~7 ~102 planks 1
fill ~55 ~5 ~103 ~55 ~7 ~103 planks 1
fill ~55 ~5 ~104 ~55 ~7 ~104 planks 1
fill ~55 ~5 ~105 ~55 ~7 ~105 planks 1
fill ~55 ~5 ~106 ~55 ~7 ~106 planks 1
fill ~57 ~5 ~99 ~58 ~5 ~99 stained_hardened_clay 8
fill ~57 ~5 ~100 ~58 ~5 ~100 stained_hardened_clay 8
fill ~57 ~5 ~101 ~58 ~5 ~101 stained_hardened_clay 8
fill ~57 ~5 ~102 ~58 ~5 ~102 stained_hardened_clay 8
fill ~57 ~5 ~103 ~58 ~5 ~103 stained_hardened_clay 8
fill ~57 ~5 ~104 ~58 ~5 ~104 stained_hardened_clay 8
fill ~57 ~5 ~105 ~58 ~5 ~105 stained_hardened_clay 8
fill ~59 ~5 ~96 ~61 ~5 ~96 planks 1
fill ~59 ~5 ~97 ~61 ~5 ~97 planks 1
fill ~59 ~5 ~98 ~61 ~5 ~98 planks 1
fill ~59 ~5 ~99 ~59 ~3 ~99 planks 1
fill ~59 ~5 ~100 ~59 ~3 ~100 planks 1
fill ~59 ~5 ~101 ~59 ~3 ~101 planks 1
fill ~59 ~5 ~102 ~59 ~3 ~102 planks 1
fill ~59 ~5 ~103 ~59 ~3 ~103 planks 1
fill ~59 ~5 ~104 ~59 ~3 ~104 planks 1
fill ~59 ~5 ~105 ~59 ~3 ~105 planks 1
fill ~59 ~5 ~106 ~61 ~5 ~106 planks 1
fill ~59 ~5 ~107 ~61 ~5 ~107 planks 1
fill ~59 ~5 ~108 ~61 ~5 ~108 planks 1
fill ~61 ~5 ~99 ~61 ~5 ~108 planks 1
fill ~62 ~5 ~102 ~63 ~5 ~102 stained_hardened_clay 8
fill ~64 ~5 ~96 ~65 ~5 ~96 planks 1
fill ~64 ~5 ~97 ~65 ~5 ~97 planks 1
fill ~64 ~5 ~98 ~65 ~5 ~98 planks 1
fill ~64 ~5 ~106 ~65 ~5 ~106 planks 1
fill ~64 ~5 ~107 ~65 ~5 ~107 planks 1
fill ~64 ~5 ~108 ~65 ~5 ~108 planks 1
fill ~65 ~5 ~99 ~65 ~6 ~99 planks 1
fill ~65 ~5 ~100 ~65 ~6 ~100 planks 1
fill ~65 ~5 ~101 ~65 ~6 ~101 planks 1
fill ~65 ~5 ~102 ~65 ~6 ~102 planks 1
fill ~65 ~5 ~103 ~65 ~6 ~103 planks 1
fill ~65 ~5 ~104 ~65 ~6 ~104 planks 1
fill ~65 ~5 ~105 ~65 ~6 ~105 planks 1
fill ~44 ~6 ~100 ~46 ~6 ~100 stained_hardened_clay 9
fill ~44 ~6 ~101 ~46 ~6 ~101 stained_hardened_clay 9
fill ~44 ~6 ~102 ~46 ~6 ~102 stained_hardened_clay 9
fill ~44 ~6 ~103 ~46 ~6 ~103 stained_hardened_clay 9
fill ~44 ~6 ~104 ~46 ~6 ~104 stained_hardened_clay 9
fill ~45 ~6 ~99 ~46 ~6 ~99 stained_hardened_clay 9
fill ~45 ~6 ~105 ~46 ~6 ~105 stained_hardened_clay 9
fill ~47 ~6 ~98 ~50 ~6 ~98 stained_hardened_clay 9
fill ~47 ~6 ~106 ~50 ~6 ~106 stained_hardened_clay 9
fill ~53 ~6 ~96 ~55 ~6 ~96 planks 1
fill ~53 ~6 ~97 ~55 ~6 ~97 planks 1
fill ~53 ~6 ~107 ~55 ~6 ~107 planks 1
fill ~53 ~6 ~108 ~55 ~6 ~108 planks 1
fill ~56 ~6 ~99 ~57 ~6 ~99 stained_hardened_clay 8
fill ~56 ~6 ~100 ~57 ~6 ~100 stained_hardened_clay 8
fill ~56 ~6 ~104 ~57 ~6 ~104 stained_hardened_clay 8
fill ~56 ~6 ~105 ~57 ~6 ~105 stained_hardened_clay 8
fill ~58 ~6 ~96 ~60 ~6 ~96 planks 1
fill ~58 ~6 ~97 ~60 ~6 ~97 planks 1
fill ~58 ~6 ~98 ~58 ~8 ~98 planks 1
fill ~58 ~6 ~99 ~58 ~8 ~99 planks 1
fill ~58 ~6 ~100 ~58 ~8 ~100 planks 1
fill ~58 ~6 ~101 ~58 ~8 ~101 planks 1
fill ~58 ~6 ~102 ~58 ~8 ~102 planks 1
fill ~58 ~6 ~103 ~58 ~8 ~103 planks 1
fill ~58 ~6 ~104 ~58 ~8 ~104 planks 1
fill ~58 ~6 ~105 ~58 ~8 ~105 planks 1
fill ~58 ~6 ~106 ~58 ~8 ~106 planks 1
fill ~58 ~6 ~107 ~60 ~6 ~107 planks 1
fill ~58 ~6 ~108 ~60 ~6 ~108 planks 1
fill ~60 ~6 ~98 ~60 ~8 ~98 planks 1
fill ~60 ~6 ~99 ~60 ~8 ~99 planks 1
fill ~60 ~6 ~100 ~60 ~8 ~100 planks 1
fill ~60 ~6 ~101 ~60 ~8 ~101 planks 1
fill ~60 ~6 ~102 ~60 ~8 ~102 planks 1
fill ~60 ~6 ~103 ~60 ~8 ~103 planks 1
fill ~60 ~6 ~104 ~60 ~8 ~104 planks 1
fill ~60 ~6 ~105 ~60 ~8 ~105 planks 1
fill ~60 ~6 ~106 ~60 ~8 ~106 planks 1
fill ~61 ~6 ~100 ~63 ~6 ~100 stained_hardened_clay 8
fill ~61 ~6 ~101 ~63 ~6 ~101 stained_hardened_clay 8
fill ~61 ~6 ~102 ~63 ~6 ~102 stained_hardened_clay 8
fill ~61 ~6 ~103 ~63 ~6 ~103 stained_hardened_clay 8
fill ~61 ~6 ~104 ~63 ~6 ~104 stained_hardened_clay 8
fill ~64 ~6 ~96 ~66 ~6 ~96 planks 1
fill ~64 ~6 ~97 ~66 ~6 ~97 planks 1
fill ~64 ~6 ~98 ~66 ~6 ~98 planks 1
fill ~64 ~6 ~106 ~66 ~6 ~106 planks 1
fill ~64 ~6 ~107 ~66 ~6 ~107 planks 1
fill ~64 ~6 ~108 ~66 ~6 ~108 planks 1
fill ~66 ~6 ~99 ~66 ~6 ~108 planks 1
setblock ~82 ~6 ~74 stone_brick_stairs 7
setblock ~82 ~6 ~130 stone_brick_stairs 6
setblock ~114 ~6 ~72 stone_brick_stairs 7
setblock ~114 ~6 ~132 stone_brick_stairs 6
fill ~45 ~7 ~101 ~46 ~7 ~101 stained_hardened_clay 9
fill ~45 ~7 ~102 ~46 ~7 ~102 stained_hardened_clay 9
fill ~45 ~7 ~103 ~46 ~7 ~103 stained_hardened_clay 9
fill ~46 ~7 ~99 ~49 ~7 ~99 stained_hardened_clay 9
fill ~46 ~7 ~100 ~46 ~7 ~99 stained_hardened_clay 9
fill ~46 ~7 ~104 ~46 ~7 ~105 stained_hardened_clay 9
fill ~47 ~7 ~98 ~49 ~7 ~98 stained_hardened_clay 9
fill ~47 ~7 ~105 ~49 ~7 ~105 stained_hardened_clay 9
fill ~47 ~7 ~106 ~49 ~7 ~106 stained_hardened_clay 9
fill ~50 ~7 ~97 ~50 ~9 ~97 stained_hardened_clay 9
fill ~50 ~7 ~107 ~50 ~9 ~107 stained_hardened_clay 9
fill ~53 ~7 ~96 ~55 ~7 ~96 planks 1
fill ~53 ~7 ~97 ~55 ~7 ~97 planks 1
fill ~53 ~7 ~107 ~55 ~7 ~107 planks 1
fill ~53 ~7 ~108 ~55 ~7 ~108 planks 1
fill ~56 ~7 ~98 ~57 ~7 ~98 stained_hardened_clay 8
fill ~56 ~7 ~99 ~57 ~7 ~99 stained_hardened_clay 8
fill ~56 ~7 ~105 ~57 ~7 ~105 stained_hardened_clay 8
fill ~56 ~7 ~106 ~57 ~7 ~106 stained_hardened_clay 8
fill ~58 ~7 ~96 ~60 ~7 ~96 planks 1
fill ~58 ~7 ~97 ~60 ~7 ~97 planks 1
fill ~58 ~7 ~107 ~60 ~7 ~107 planks 1
fill ~58 ~7 ~108 ~60 ~7 ~108 planks 1
fill ~61 ~7 ~99 ~62 ~7 ~99 stained_hardened_clay 8
fill ~61 ~7 ~100 ~62 ~7 ~100 stained_hardened_clay 8
fill ~61 ~7 ~104 ~62 ~7 ~104 stained_hardened_clay 8
fill ~61 ~7 ~105 ~62 ~7 ~105 stained_hardened_clay 8
fill ~63 ~7 ~96 ~66 ~7 ~96 planks 1
fill ~63 ~7 ~97 ~65 ~7 ~97 planks 1
fill ~63 ~7 ~98 ~65 ~7 ~98 planks 1
fill ~63 ~7 ~99 ~63 ~9 ~99 planks 1
fill ~63 ~7 ~100 ~63 ~9 ~100 planks 1
fill ~63 ~7 ~101 ~63 ~9 ~101 planks 1
fill ~63 ~7 ~102 ~63 ~9 ~102 planks 1
fill ~63 ~7 ~103 ~63 ~9 ~103 planks 1
fill ~63 ~7 ~104 ~63 ~9 ~104 planks 1
fill ~63 ~7 ~105 ~63 ~9 ~105 planks 1
fill ~63 ~7 ~106 ~65 ~7 ~106 planks 1
fill ~63 ~7 ~107 ~65 ~7 ~107 planks 1
fill ~63 ~7 ~108 ~66 ~7 ~108 planks 1
fill ~66 ~7 ~97 ~66 ~15 ~97 stained_hardened_clay 9
fill ~66 ~7 ~98 ~69 ~7 ~98 stained_hardened_clay 9
fill ~66 ~7 ~106 ~69 ~7 ~106 stained_hardened_clay 9
fill ~66 ~7 ~107 ~66 ~15 ~107 stained_hardened_clay 9
fill ~67 ~7 ~99 ~69 ~7 ~99 stained_hardened_clay 9
fill ~67 ~7 ~100 ~70 ~7 ~100 stained_hardened_clay 9
fill ~67 ~7 ~101 ~70 ~7 ~101 stained_hardened_clay 9
fill ~67 ~7 ~102 ~70 ~7 ~102 stained_hardened_clay 9
fill ~67 ~7 ~103 ~70 ~7 ~103 stained_hardened_clay 9
fill ~67 ~7 ~104 ~70 ~7 ~104 stained_hardened_clay 9
fill ~67 ~7 ~105 ~69 ~7 ~105 stained_hardened_clay 9
setblock ~82 ~7 ~74 stonebrick 0
setblock ~82 ~7 ~130 stonebrick 0
setblock ~114 ~7 ~72 stonebrick 0
setblock ~114 ~7 ~132 stonebrick 0
fill ~47 ~8 ~99 ~49 ~8 ~99 stained_hardened_clay 9
fill ~47 ~8 ~100 ~48 ~8 ~100 stained_hardened_clay 9
fill ~47 ~8 ~101 ~48 ~8 ~101 stained_hardened_clay 9
fill ~47 ~8 ~102 ~48 ~8 ~102 stained_hardened_clay 9
fill ~47 ~8 ~103 ~48 ~8 ~103 stained_hardened_clay 9
fill ~47 ~8 ~104 ~48 ~8 ~104 stained_hardened_clay 9
fill ~47 ~8 ~105 ~49 ~8 ~105 stained_hardened_clay 9
setblock ~49 ~8 ~98 stained_hardened_clay 9
setblock ~49 ~8 ~106 stained_hardened_clay 9
fill ~52 ~8 ~96 ~54 ~8 ~96 planks 1
fill ~52 ~8 ~97 ~54 ~8 ~97 planks 1
fill ~52 ~8 ~107 ~54 ~8 ~107 planks 1
fill ~52 ~8 ~108 ~54 ~8 ~108 planks 1
fill ~54 ~8 ~98 ~54 ~10 ~98 planks 1
fill ~54 ~8 ~99 ~54 ~10 ~99 planks 1
fill ~54 ~8 ~100 ~54 ~10 ~100 planks 1
fill ~54 ~8 ~101 ~54 ~10 ~101 planks 1
fill ~54 ~8 ~102 ~54 ~10 ~102 planks 1
fill ~54 ~8 ~103 ~54 ~10 ~103 planks 1
fill ~54 ~8 ~104 ~54 ~10 ~104 planks 1
fill ~54 ~8 ~105 ~54 ~10 ~105 planks 1
fill ~54 ~8 ~106 ~54 ~10 ~106 planks 1
fill ~55 ~8 ~99 ~57 ~8 ~99 stained_hardened_clay 8
fill ~55 ~8 ~105 ~57 ~8 ~105 stained_hardened_clay 8
fill ~58 ~8 ~96 ~60 ~8 ~96 planks 1
fill ~58 ~8 ~97 ~60 ~8 ~97 planks 1
fill ~58 ~8 ~107 ~60 ~8 ~107 planks 1
fill ~58 ~8 ~108 ~60 ~8 ~108 planks 1
fill ~61 ~8 ~99 ~62 ~8 ~99 stained_hardened_clay 8
fill ~61 ~8 ~105 ~62 ~8 ~105 stained_hardened_clay 8
fill ~63 ~8 ~96 ~65 ~8 ~96 planks 1
fill ~63 ~8 ~97 ~65 ~8 ~97 planks 1
fill ~63 ~8 ~98 ~63 ~9 ~98 planks 1
fill ~63 ~8 ~106 ~63 ~9 ~106 planks 1
fill ~63 ~8 ~107 ~65 ~8 ~107 planks 1
fill ~63 ~8 ~108 ~65 ~8 ~108 planks 1
fill ~65 ~8 ~95 ~67 ~8 ~95 prismarine 2
fill ~65 ~8 ~109 ~67 ~8 ~109 prismarine 2
fill ~66 ~8 ~96 ~67 ~8 ~96 prismarine 2
fill ~66 ~8 ~108 ~67 ~8 ~108 prismarine 2
fill ~67 ~8 ~97 ~69 ~8 ~97 stained_hardened_clay 9
fill ~67 ~8 ~98 ~71 ~8 ~98 stained_hardened_clay 9
fill ~67 ~8 ~106 ~71 ~8 ~106 stained_hardened_clay 9
fill ~67 ~8 ~107 ~69 ~8 ~107 stained_hardened_clay 9
fill ~70 ~8 ~99 ~71 ~8 ~99 stained_hardened_clay 9
fill ~70 ~8 ~100 ~71 ~8 ~100 stained_hardened_clay 9
fill ~70 ~8 ~101 ~72 ~8 ~101 stained_hardened_clay 9
fill ~70 ~8 ~102 ~72 ~8 ~102 stained_hardened_clay 9
fill ~70 ~8 ~103 ~72 ~8 ~103 stained_hardened_clay 9
fill ~70 ~8 ~104 ~71 ~8 ~104 stained_hardened_clay 9
fill ~70 ~8 ~105 ~71 ~8 ~105 stained_hardened_clay 9
setblock ~82 ~8 ~74 stone_slab 5
setblock ~82 ~8 ~130 stone_slab 5
fill ~83 ~8 ~75 ~83 ~9 ~75 stonebrick 0
fill ~83 ~8 ~129 ~83 ~9 ~129 stonebrick 0
setblock ~113 ~8 ~73 stonebrick 0
setblock ~113 ~8 ~131 stonebrick 0
setblock ~114 ~8 ~72 stone_slab 5
setblock ~114 ~8 ~132 stone_slab 5
fill ~49 ~9 ~99 ~49 ~9 ~105 stained_hardened_clay 9
fill ~50 ~9 ~98 ~51 ~9 ~98 stained_hardened_clay 9
fill ~50 ~9 ~106 ~51 ~9 ~106 stained_hardened_clay 9
fill ~52 ~9 ~96 ~54 ~9 ~96 planks 1
fill ~52 ~9 ~97 ~54 ~9 ~97 planks 1
fill ~52 ~9 ~107 ~54 ~9 ~107 planks 1
fill ~52 ~9 ~108 ~54 ~9 ~108 planks 1
fill ~55 ~9 ~99 ~56 ~9 ~99 stained_hardened_clay 8
fill ~55 ~9 ~100 ~55 ~10 ~100 stained_hardened_clay 8
fill ~55 ~9 ~104 ~55 ~10 ~104 stained_hardened_clay 8
fill ~55 ~9 ~105 ~56 ~9 ~105 stained_hardened_clay 8
fill ~57 ~9 ~96 ~59 ~9 ~96 planks 1
fill ~57 ~9 ~97 ~59 ~9 ~97 planks 1
fill ~57 ~9 ~98 ~57 ~14 ~98 planks 1
fill ~57 ~9 ~99 ~57 ~11 ~99 planks 1
fill ~57 ~9 ~100 ~57 ~9 ~108 planks 1
fill ~58 ~9 ~107 ~59 ~9 ~107 planks 1
fill ~58 ~9 ~108 ~59 ~9 ~108 planks 1
fill ~59 ~9 ~98 ~59 ~11 ~98 planks 1
fill ~59 ~9 ~99 ~59 ~11 ~99 planks 1
fill ~59 ~9 ~100 ~59 ~10 ~100 planks 1
fill ~59 ~9 ~101 ~59 ~11 ~101 planks 1
fill ~59 ~9 ~102 ~59 ~11 ~102 planks 1
fill ~59 ~9 ~103 ~59 ~11 ~103 planks 1
fill ~59 ~9 ~104 ~59 ~10 ~104 planks 1
fill ~59 ~9 ~105 ~59 ~11 ~105 planks 1
fill ~59 ~9 ~106 ~59 ~11 ~106 planks 1
fill ~60 ~9 ~99 ~62 ~9 ~99 stained_hardened_clay 8
fill ~60 ~9 ~105 ~62 ~9 ~105 stained_hardened_clay 8
fill ~61 ~9 ~98 ~62 ~9 ~98 stained_hardened_clay 8
fill ~61 ~9 ~106 ~62 ~9 ~106 stained_hardened_clay 8
fill ~63 ~9 ~96 ~65 ~9 ~96 planks 1
fill ~63 ~9 ~97 ~65 ~9 ~97 planks 1
fill ~63 ~9 ~107 ~65 ~9 ~107 planks 1
fill ~63 ~9 ~108 ~65 ~9 ~108 planks 1
fill ~64 ~9 ~95 ~65 ~9 ~95 prismarine 2
fill ~64 ~9 ~109 ~65 ~9 ~109 prismarine 2
fill ~66 ~9 ~96 ~66 ~11 ~96 sea_lantern 0
fill ~66 ~9 ~108 ~66 ~11 ~108 sea_lantern 0
fill ~67 ~9 ~95 ~68 ~9 ~95 prismarine 2
fill ~67 ~9 ~96 ~68 ~9 ~96 prismarine 2
fill ~67 ~9 ~97 ~70 ~9 ~97 stained_hardened_clay 9
fill ~67 ~9 ~107 ~70 ~9 ~107 stained_hardened_clay 9
fill ~67 ~9 ~108 ~68 ~9 ~108 prismarine 2
fill ~67 ~9 ~109 ~68 ~9 ~109 prismarine 2
fill ~70 ~9 ~98 ~72 ~9 ~98 stained_hardened_clay 9
fill ~70 ~9 ~106 ~72 ~9 ~106 stained_hardened_clay 9
fill ~72 ~9 ~99 ~72 ~11 ~99 stained_hardened_clay 9
fill ~72 ~9 ~100 ~73 ~9 ~100 stained_hardened_clay 9
fill ~72 ~9 ~101 ~73 ~9 ~101 stained_hardened_clay 9
fill ~72 ~9 ~102 ~73 ~9 ~102 stained_hardened_clay 9
fill ~72 ~9 ~103 ~73 ~9 ~103 stained_hardened_clay 9
fill ~72 ~9 ~104 ~73 ~9 ~104 stained_hardened_clay 9
fill ~72 ~9 ~105 ~72 ~11 ~105 stained_hardened_clay 9
setblock ~113 ~9 ~73 stone_slab 5
setblock ~113 ~9 ~74 stonebrick 0
setblock ~113 ~9 ~130 stonebrick 0
setblock ~113 ~9 ~131 stone_slab 5
fill ~49 ~10 ~100 ~51 ~10 ~100 stained_hardened_clay 9
fill ~49 ~10 ~101 ~51 ~10 ~101 stained_hardened_clay 9
fill ~49 ~10 ~102 ~51 ~10 ~102 stained_hardened_clay 9
fill ~49 ~10 ~103 ~51 ~10 ~103 stained_hardened_clay 9
fill ~49 ~10 ~104 ~51 ~10 ~104 stained_hardened_clay 9
fill ~50 ~10 ~98 ~51 ~10 ~98 stained_hardened_clay 9
fill ~50 ~10 ~99 ~51 ~10 ~99 stained_hardened_clay 9
fill ~50 ~10 ~105 ~51 ~10 ~105 stained_hardened_clay 9
fill ~50 ~10 ~106 ~51 ~10 ~106 stained_hardened_clay 9
fill ~52 ~10 ~96 ~54 ~10 ~96 planks 1
fill ~52 ~10 ~97 ~54 ~10 ~97 planks 1
fill ~52 ~10 ~98 ~54 ~10 ~98 planks 1
fill ~52 ~10 ~106 ~54 ~10 ~106 planks 1
fill ~52 ~10 ~107 ~54 ~10 ~107 planks 1
fill ~52 ~10 ~108 ~54 ~10 ~108 planks 1
fill ~55 ~10 ~101 ~56 ~10 ~101 stained_hardened_clay 8
fill ~55 ~10 ~102 ~56 ~10 ~102 stained_hardened_clay 8
fill ~55 ~10 ~103 ~56 ~10 ~103 stained_hardened_clay 8
fill ~56 ~10 ~100 ~57 ~10 ~100 stained_hardened_clay 8
fill ~56 ~10 ~104 ~57 ~10 ~104 stained_hardened_clay 8
fill ~57 ~10 ~96 ~59 ~10 ~96 planks 1
fill ~57 ~10 ~97 ~59 ~10 ~97 planks 1
fill ~57 ~10 ~101 ~57 ~11 ~101 planks 1
fill ~57 ~10 ~102 ~57 ~11 ~102 planks 1
fill ~57 ~10 ~103 ~57 ~11 ~103 planks 1
fill ~57 ~10 ~105 ~57 ~11 ~105 planks 1
fill ~57 ~10 ~106 ~57 ~14 ~106 planks 1
fill ~57 ~10 ~107 ~59 ~10 ~107 planks 1
fill ~57 ~10 ~108 ~59 ~10 ~108 planks 1
fill ~60 ~10 ~99 ~61 ~10 ~99 stained_hardened_clay 8
fill ~60 ~10 ~100 ~60 ~12 ~100 stained_hardened_clay 8
fill ~60 ~10 ~104 ~60 ~12 ~104 stained_hardened_clay 8
fill ~60 ~10 ~105 ~61 ~10 ~105 stained_hardened_clay 8
fill ~62 ~10 ~96 ~64 ~10 ~96 planks 1
fill ~62 ~10 ~97 ~64 ~10 ~97 planks 1
fill ~62 ~10 ~98 ~62 ~15 ~98 planks 1
fill ~62 ~10 ~99 ~62 ~12 ~99 planks 1
fill ~62 ~10 ~100 ~62 ~12 ~100 planks 1
fill ~62 ~10 ~101 ~62 ~12 ~101 planks 1
fill ~62 ~10 ~102 ~62 ~12 ~102 planks 1
fill ~62 ~10 ~103 ~62 ~12 ~103 planks 1
fill ~62 ~10 ~104 ~62 ~12 ~104 planks 1
fill ~62 ~10 ~105 ~62 ~12 ~105 planks 1
fill ~62 ~10 ~106 ~62 ~15 ~106 planks 1
fill ~62 ~10 ~107 ~64 ~10 ~107 planks 1
fill ~62 ~10 ~108 ~64 ~10 ~108 planks 1
fill ~64 ~10 ~95 ~64 ~11 ~95 prismarine 2
fill ~64 ~10 ~109 ~64 ~11 ~109 prismarine 2
setblock ~65 ~10 ~96 sea_lantern 0
fill ~65 ~10 ~97 ~65 ~14 ~97 stained_hardened_clay 9
fill ~65 ~10 ~107 ~65 ~14 ~107 stained_hardened_clay 9
setblock ~65 ~10 ~108 sea_lantern 0
fill ~67 ~10 ~96 ~67 ~11 ~96 sea_lantern 0
fill ~67 ~10 ~97 ~71 ~10 ~97 stained_hardened_clay 9
fill ~67 ~10 ~107 ~71 ~10 ~107 stained_hardened_clay 9
fill ~67 ~10 ~108 ~67 ~11 ~108 sea_lantern 0
fill ~68 ~10 ~95 ~68 ~11 ~95 prismarine 2
fill ~68 ~10 ~96 ~68 ~11 ~96 prismarine 2
fill ~68 ~10 ~108 ~68 ~11 ~108 prismarine 2
fill ~68 ~10 ~109 ~68 ~11 ~109 prismarine 2
fill ~71 ~10 ~98 ~72 ~10 ~98 stained_hardened_clay 9
fill ~71 ~10 ~106 ~72 ~10 ~106 stained_hardened_clay 9
fill ~72 ~10 ~100 ~74 ~10 ~100 stained_hardened_clay 9
fill ~72 ~10 ~101 ~75 ~10 ~101 stained_hardened_clay 9
fill ~72 ~10 ~102 ~75 ~10 ~102 stained_hardened_clay 9
fill ~72 ~10 ~103 ~75 ~10 ~103 stained_hardened_clay 9
fill ~72 ~10 ~104 ~74 ~10 ~104 stained_hardened_clay 9
fill ~73 ~10 ~99 ~74 ~10 ~99 stained_hardened_clay 9
fill ~73 ~10 ~105 ~74 ~10 ~105 stained_hardened_clay 9
setblock ~83 ~10 ~75 stone_slab 5
setblock ~83 ~10 ~129 stone_slab 5
setblock ~84 ~10 ~76 stonebrick 0
setblock ~84 ~10 ~128 stonebrick 0
setblock ~112 ~10 ~75 stonebrick 0
setblock ~112 ~10 ~129 stonebrick 0
setblock ~113 ~10 ~74 stone_slab 5
setblock ~113 ~10 ~130 stone_slab 5
fill ~51 ~11 ~96 ~53 ~11 ~96 planks 1
fill ~51 ~11 ~97 ~51 ~11 ~108 planks 1
fill ~52 ~11 ~98 ~53 ~11 ~98 planks 1
fill ~52 ~11 ~99 ~53 ~11 ~99 planks 1
fill ~52 ~11 ~100 ~53 ~11 ~100 planks 1
fill ~52 ~11 ~101 ~53 ~11 ~101 planks 1
fill ~52 ~11 ~102 ~53 ~11 ~102 planks 1
fill ~52 ~11 ~103 ~53 ~11 ~103 planks 1
fill ~52 ~11 ~104 ~53 ~11 ~104 planks 1
fill ~52 ~11 ~105 ~53 ~11 ~105 planks 1
fill ~52 ~11 ~106 ~53 ~11 ~106 planks 1
fill ~52 ~11 ~108 ~53 ~11 ~108 planks 1
fill ~53 ~11 ~97 ~53 ~12 ~97 planks 1
fill ~53 ~11 ~107 ~53 ~12 ~107 planks 1
fill ~55 ~11 ~102 ~55 ~10 ~102 stained_hardened_clay 8
fill ~56 ~11 ~96 ~59 ~11 ~96 planks 1
fill ~56 ~11 ~97 ~59 ~11 ~97 planks 1
fill ~56 ~11 ~98 ~56 ~12 ~98 planks 1
fill ~56 ~11 ~99 ~56 ~13 ~99 planks 1
fill ~56 ~11 ~100 ~57 ~11 ~100 planks 1
fill ~56 ~11 ~101 ~56 ~13 ~101 planks 1
fill ~56 ~11 ~102 ~56 ~13 ~102 planks 1
fill ~56 ~11 ~103 ~56 ~13 ~103 planks 1
fill ~56 ~11 ~104 ~57 ~11 ~104 planks 1
fill ~56 ~11 ~105 ~56 ~13 ~105 planks 1
fill ~56 ~11 ~106 ~56 ~12 ~106 planks 1
fill ~56 ~11 ~107 ~59 ~11 ~107 planks 1
fill ~56 ~11 ~108 ~59 ~11 ~108 planks 1
fill ~58 ~11 ~100 ~60 ~11 ~100 stained_hardened_clay 8
fill ~58 ~11 ~104 ~60 ~11 ~104 stained_hardened_clay 8
fill ~60 ~11 ~101 ~60 ~12 ~101 stained_hardened_clay 8
fill ~60 ~11 ~102 ~60 ~13 ~102 stained_hardened_clay 8
fill ~60 ~11 ~103 ~60 ~12 ~103 stained_hardened_clay 8
setblock ~61 ~11 ~99 stained_hardened_clay 8
setblock ~61 ~11 ~105 stained_hardened_clay 8
fill ~62 ~11 ~96 ~64 ~11 ~96 planks 1
fill ~62 ~11 ~97 ~64 ~11 ~97 planks 1
fill ~62 ~11 ~107 ~64 ~11 ~107 planks 1
fill ~62 ~11 ~108 ~64 ~11 ~108 planks 1
fill ~65 ~11 ~95 ~65 ~12 ~95 prismarine 2
fill ~65 ~11 ~96 ~65 ~12 ~96 prismarine 2
fill ~65 ~11 ~108 ~65 ~12 ~108 prismarine 2
fill ~65 ~11 ~109 ~65 ~12 ~109 prismarine 2
fill ~67 ~11 ~95 ~67 ~12 ~95 prismarine 2
fill ~67 ~11 ~97 ~71 ~11 ~97 stained_hardened_clay 9
fill ~67 ~11 ~107 ~71 ~11 ~107 stained_hardened_clay 9
fill ~67 ~11 ~109 ~67 ~12 ~109 prismarine 2
fill ~71 ~11 ~98 ~74 ~11 ~98 stained_hardened_clay 9
fill ~71 ~11 ~106 ~74 ~11 ~106 stained_hardened_clay 9
fill ~73 ~11 ~99 ~75 ~11 ~99 stained_hardened_clay 9
fill ~73 ~11 ~105 ~75 ~11 ~105 stained_hardened_clay 9
fill ~75 ~11 ~100 ~75 ~17 ~100 stained_hardened_clay 9
fill ~75 ~11 ~101 ~76 ~11 ~101 stained_hardened_clay 9
fill ~75 ~11 ~102 ~76 ~11 ~102 stained_hardened_clay 9
fill ~75 ~11 ~103 ~76 ~11 ~103 stained_hardened_clay 9
fill ~75 ~11 ~104 ~75 ~17 ~104 stained_hardened_clay 9
setblock ~84 ~11 ~76 stone_slab 5
setblock ~84 ~11 ~77 stonebrick 0
setblock ~84 ~11 ~127 stonebrick 0
setblock ~84 ~11 ~128 stone_slab 5
setblock ~111 ~11 ~76 stonebrick 0
setblock ~111 ~11 ~128 stonebrick 0
setblock ~112 ~11 ~75 stone_slab 5
setblock ~112 ~11 ~129 stone_slab 5
fill ~51 ~12 ~100 ~51 ~12 ~104 wooden_slab 1
fill ~52 ~12 ~96 ~53 ~12 ~96 planks 1
fill ~52 ~12 ~97 ~52 ~12 ~108 planks 1
fill ~53 ~12 ~98 ~53 ~12 ~108 planks 1
fill ~56 ~12 ~96 ~58 ~12 ~96 planks 1
fill ~56 ~12 ~97 ~58 ~12 ~97 planks 1
fill ~56 ~12 ~100 ~56 ~13 ~100 planks 1
fill ~56 ~12 ~104 ~56 ~13 ~104 planks 1
fill ~56 ~12 ~107 ~58 ~12 ~107 planks 1
fill ~56 ~12 ~108 ~58 ~12 ~108 planks 1
fill ~58 ~12 ~98 ~58 ~14 ~98 planks 1
fill ~58 ~12 ~99 ~58 ~14 ~99 planks 1
fill ~58 ~12 ~100 ~58 ~14 ~100 planks 1
fill ~58 ~12 ~101 ~58 ~14 ~101 planks 1
fill ~58 ~12 ~102 ~58 ~14 ~102 planks 1
fill ~58 ~12 ~103 ~58 ~14 ~103 planks 1
fill ~58 ~12 ~104 ~58 ~14 ~104 planks 1
fill ~58 ~12 ~105 ~58 ~14 ~105 planks 1
fill ~58 ~12 ~106 ~58 ~14 ~106 planks 1
setblock ~59 ~12 ~102 stained_hardened_clay 8
fill ~61 ~12 ~96 ~64 ~12 ~96 planks 1
fill ~61 ~12 ~97 ~64 ~12 ~97 planks 1
fill ~61 ~12 ~98 ~61 ~14 ~98 planks 1
fill ~61 ~12 ~99 ~61 ~14 ~99 planks 1
fill ~61 ~12 ~100 ~61 ~14 ~100 planks 1
fill ~61 ~12 ~101 ~61 ~14 ~101 planks 1
fill ~61 ~12 ~102 ~61 ~14 ~102 planks 1
fill ~61 ~12 ~103 ~61 ~14 ~103 planks 1
fill ~61 ~12 ~104 ~61 ~14 ~104 planks 1
fill ~61 ~12 ~105 ~61 ~14 ~105 planks 1
fill ~61 ~12 ~106 ~61 ~14 ~106 planks 1
fill ~61 ~12 ~107 ~64 ~12 ~107 planks 1
fill ~61 ~12 ~108 ~64 ~12 ~108 planks 1
fill ~66 ~12 ~95 ~66 ~12 ~96 prismarine 2
fill ~66 ~12 ~108 ~67 ~12 ~108 prismarine 2
fill ~66 ~12 ~109 ~66 ~12 ~108 prismarine 2
setblock ~67 ~12 ~96 prismarine 2
fill ~67 ~12 ~97 ~71 ~12 ~97 stained_hardened_clay 9
fill ~67 ~12 ~107 ~71 ~12 ~107 stained_hardened_clay 9
fill ~71 ~12 ~98 ~74 ~12 ~98 stained_hardened_clay 9
fill ~71 ~12 ~106 ~74 ~12 ~106 stained_hardened_clay 9
fill ~75 ~12 ~99 ~75 ~17 ~99 stained_hardened_clay 9
fill ~75 ~12 ~101 ~78 ~12 ~101 stained_hardened_clay 9
fill ~75 ~12 ~102 ~78 ~12 ~102 stained_hardened_clay 9
fill ~75 ~12 ~103 ~78 ~12 ~103 stained_hardened_clay 9
fill ~75 ~12 ~105 ~75 ~17 ~105 stained_hardened_clay 9
fill ~76 ~12 ~100 ~77 ~12 ~100 stained_hardened_clay 9
fill ~76 ~12 ~104 ~77 ~12 ~104 stained_hardened_clay 9
setblock ~84 ~12 ~77 stone_slab 5
setblock ~84 ~12 ~127 stone_slab 5
fill ~85 ~12 ~78 ~85 ~13 ~78 stonebrick 0
fill ~85 ~12 ~126 ~85 ~13 ~126 stonebrick 0
setblock ~101 ~12 ~99 spruce_stairs 4
fill ~101 ~12 ~100 ~102 ~12 ~100 planks 1
fill ~101 ~12 ~101 ~102 ~12 ~101 planks 1
fill ~101 ~12 ~102 ~102 ~12 ~102 planks 1
fill ~101 ~12 ~103 ~102 ~12 ~103 planks 1
fill ~101 ~12 ~104 ~102 ~12 ~104 planks 1
setblock ~101 ~12 ~105 spruce_stairs 4
setblock ~102 ~12 ~99 spruce_stairs 5
setblock ~102 ~12 ~105 spruce_stairs 5
setblock ~111 ~12 ~76 stone_slab 5
setblock ~111 ~12 ~77 stonebrick 0
setblock ~111 ~12 ~127 stonebrick 0
setblock ~111 ~12 ~128 stone_slab 5
fill ~118 ~12 ~102 ~120 ~12 ~102 stained_glass_pane 1
setblock ~56 ~13 ~98 wooden_slab 1
setblock ~56 ~13 ~106 wooden_slab 1
fill ~57 ~13 ~96 ~58 ~13 ~96 planks 1
fill ~57 ~13 ~97 ~58 ~13 ~97 planks 1
fill ~57 ~13 ~99 ~57 ~14 ~99 planks 1
fill ~57 ~13 ~100 ~57 ~14 ~100 planks 1
fill ~57 ~13 ~101 ~57 ~14 ~101 planks 1
fill ~57 ~13 ~102 ~57 ~14 ~102 planks 1
fill ~57 ~13 ~103 ~57 ~14 ~103 planks 1
fill ~57 ~13 ~104 ~57 ~14 ~104 planks 1
fill ~57 ~13 ~105 ~57 ~14 ~105 planks 1
fill ~57 ~13 ~107 ~58 ~13 ~107 planks 1
fill ~57 ~13 ~108 ~58 ~13 ~108 planks 1
fill ~61 ~13 ~96 ~63 ~13 ~96 planks 1
fill ~61 ~13 ~97 ~63 ~13 ~97 planks 1
fill ~61 ~13 ~107 ~63 ~13 ~107 planks 1
fill ~61 ~13 ~108 ~63 ~13 ~108 planks 1
fill ~64 ~13 ~97 ~64 ~14 ~97 stained_hardened_clay 9
fill ~64 ~13 ~107 ~64 ~14 ~107 stained_hardened_clay 9
fill ~67 ~13 ~97 ~71 ~13 ~97 stained_hardened_clay 9
fill ~67 ~13 ~107 ~71 ~13 ~107 stained_hardened_clay 9
setblock ~69 ~13 ~96 acacia_stairs 4
setblock ~69 ~13 ~108 acacia_stairs 4
setblock ~70 ~13 ~96 acacia_stairs 5
setblock ~70 ~13 ~108 acacia_stairs 5
fill ~71 ~13 ~98 ~74 ~13 ~98 stained_hardened_clay 9
fill ~71 ~13 ~106 ~74 ~13 ~106 stained_hardened_clay 9
setblock ~73 ~13 ~97 stone_brick_stairs 4
setblock ~73 ~13 ~107 stone_brick_stairs 4
setblock ~74 ~13 ~97 stone_brick_stairs 1
setblock ~74 ~13 ~107 stone_brick_stairs 1
fill ~75 ~13 ~97 ~75 ~13 ~98 stone_brick_stairs 0
fill ~75 ~13 ~101 ~80 ~13 ~101 stained_hardened_clay 9
fill ~75 ~13 ~102 ~80 ~13 ~102 stained_hardened_clay 9
fill ~75 ~13 ~103 ~80 ~13 ~103 stained_hardened_clay 9
fill ~75 ~13 ~106 ~75 ~13 ~107 stone_brick_stairs 0
fill ~76 ~13 ~97 ~76 ~13 ~98 stone_brick_stairs 5
fill ~76 ~13 ~99 ~77 ~13 ~99 stained_hardened_clay 9
fill ~76 ~13 ~100 ~79 ~13 ~100 stained_hardened_clay 9
fill ~76 ~13 ~104 ~79 ~13 ~104 stained_hardened_clay 9
fill ~76 ~13 ~105 ~77 ~13 ~105 stained_hardened_clay 9
fill ~76 ~13 ~106 ~76 ~13 ~107 stone_brick_stairs 5
fill ~99 ~13 ~101 ~104 ~13 ~101 stained_hardened_clay 9
fill ~99 ~13 ~102 ~106 ~13 ~102 stained_hardened_clay 9
fill ~99 ~13 ~103 ~104 ~13 ~103 stained_hardened_clay 9
fill ~100 ~13 ~100 ~103 ~13 ~100 stained_hardened_clay 9
fill ~100 ~13 ~104 ~103 ~13 ~104 stained_hardened_clay 9
setblock ~101 ~13 ~97 spruce_stairs 4
fill ~101 ~13 ~98 ~102 ~13 ~98 planks 1
fill ~101 ~13 ~99 ~102 ~13 ~99 planks 1
fill ~101 ~13 ~105 ~102 ~13 ~105 planks 1
fill ~101 ~13 ~106 ~102 ~13 ~106 planks 1
setblock ~101 ~13 ~107 spruce_stairs 4
setblock ~102 ~13 ~97 spruce_stairs 5
setblock ~102 ~13 ~107 spruce_stairs 5
setblock ~110 ~13 ~78 stonebrick 0
setblock ~110 ~13 ~126 stonebrick 0
setblock ~111 ~13 ~77 stone_slab 5
setblock ~111 ~13 ~127 stone_slab 5
fill ~117 ~13 ~102 ~118 ~13 ~102 stained_glass_pane 1
fill ~120 ~13 ~102 ~121 ~13 ~102 stained_glass_pane 1
fill ~57 ~14 ~97 ~58 ~14 ~97 planks 1
fill ~57 ~14 ~107 ~58 ~14 ~107 planks 1
fill ~61 ~14 ~96 ~63 ~14 ~96 planks 1
fill ~61 ~14 ~97 ~61 ~12 ~97 planks 1
fill ~61 ~14 ~107 ~61 ~12 ~107 planks 1
fill ~61 ~14 ~108 ~63 ~14 ~108 planks 1
fill ~62 ~14 ~99 ~62 ~15 ~99 planks 1
fill ~62 ~14 ~100 ~62 ~15 ~100 planks 1
fill ~62 ~14 ~101 ~62 ~15 ~101 planks 1
fill ~62 ~14 ~102 ~62 ~15 ~102 planks 1
fill ~62 ~14 ~103 ~62 ~15 ~103 planks 1
fill ~62 ~14 ~104 ~62 ~15 ~104 planks 1
fill ~62 ~14 ~105 ~62 ~15 ~105 planks 1
fill ~63 ~14 ~97 ~63 ~15 ~97 planks 1
fill ~63 ~14 ~98 ~63 ~15 ~98 planks 1
fill ~63 ~14 ~106 ~63 ~15 ~106 planks 1
fill ~63 ~14 ~107 ~63 ~15 ~107 planks 1
fill ~64 ~14 ~98 ~65 ~14 ~98 stained_hardened_clay 9
fill ~64 ~14 ~106 ~65 ~14 ~106 stained_hardened_clay 9
fill ~67 ~14 ~97 ~69 ~14 ~97 stained_hardened_clay 9
fill ~67 ~14 ~107 ~69 ~14 ~107 stained_hardened_clay 9
setblock ~69 ~14 ~96 acacia_stairs 0
setblock ~69 ~14 ~108 acacia_stairs 0
fill ~70 ~14 ~96 ~70 ~14 ~97 acacia_stairs 1
fill ~70 ~14 ~98 ~74 ~14 ~98 stained_hardened_clay 9
fill ~70 ~14 ~106 ~74 ~14 ~106 stained_hardened_clay 9
fill ~70 ~14 ~107 ~70 ~14 ~108 acacia_stairs 1
setblock ~73 ~14 ~97 stone_brick_stairs 1
setblock ~73 ~14 ~107 stone_brick_stairs 1
fill ~75 ~14 ~101 ~81 ~14 ~101 stained_hardened_clay 9
fill ~75 ~14 ~102 ~82 ~14 ~102 stained_hardened_clay 9
fill ~75 ~14 ~103 ~81 ~14 ~103 stained_hardened_clay 9
fill ~76 ~14 ~97 ~76 ~14 ~98 stone_brick_stairs 0
fill ~76 ~14 ~99 ~78 ~14 ~99 stained_hardened_clay 9
fill ~76 ~14 ~100 ~80 ~14 ~100 stained_hardened_clay 9
fill ~76 ~14 ~104 ~80 ~14 ~104 stained_hardened_clay 9
fill ~76 ~14 ~105 ~78 ~14 ~105 stained_hardened_clay 9
fill ~76 ~14 ~106 ~76 ~14 ~107 stone_brick_stairs 0
setblock ~85 ~14 ~78 stone_slab 5
setblock ~85 ~14 ~126 stone_slab 5
setblock ~86 ~14 ~79 stonebrick 0
setblock ~86 ~14 ~125 stonebrick 0
fill ~94 ~14 ~101 ~107 ~14 ~101 stained_hardened_clay 9
fill ~94 ~14 ~102 ~107 ~14 ~102 stained_hardened_clay 9
fill ~94 ~14 ~103 ~107 ~14 ~103 stained_hardened_clay 9
fill ~95 ~14 ~100 ~106 ~14 ~100 stained_hardened_clay 9
fill ~95 ~14 ~104 ~106 ~14 ~104 stained_hardened_clay 9
fill ~99 ~14 ~99 ~105 ~14 ~99 stained_hardened_clay 9
fill ~99 ~14 ~105 ~105 ~14 ~105 stained_hardened_clay 9
fill ~100 ~14 ~97 ~100 ~14 ~98 spruce_stairs 4
fill ~100 ~14 ~106 ~100 ~14 ~107 spruce_stairs 4
fill ~101 ~14 ~97 ~102 ~14 ~97 planks 1
fill ~101 ~14 ~98 ~102 ~14 ~98 stained_hardened_clay 9
fill ~101 ~14 ~106 ~102 ~14 ~106 stained_hardened_clay 9
fill ~101 ~14 ~107 ~102 ~14 ~107 planks 1
fill ~103 ~14 ~97 ~103 ~14 ~98 spruce_stairs 5
fill ~103 ~14 ~106 ~103 ~14 ~107 spruce_stairs 5
setblock ~109 ~14 ~79 stonebrick 0
setblock ~109 ~14 ~125 stonebrick 0
setblock ~110 ~14 ~78 stone_slab 5
setblock ~110 ~14 ~126 stone_slab 5
fill ~121 ~14 ~102 ~122 ~14 ~102 stained_glass_pane 1
fill ~61 ~15 ~100 ~61 ~15 ~104 wooden_slab 1
fill ~62 ~15 ~96 ~63 ~15 ~96 planks 1
fill ~62 ~15 ~97 ~62 ~15 ~96 planks 1
fill ~62 ~15 ~107 ~62 ~15 ~108 planks 1
fill ~63 ~15 ~99 ~63 ~15 ~108 planks 1
fill ~64 ~15 ~98 ~68 ~15 ~98 stained_hardened_clay 9
fill ~64 ~15 ~99 ~65 ~15 ~99 stained_hardened_clay 9
fill ~64 ~15 ~100 ~65 ~15 ~100 stained_hardened_clay 9
fill ~64 ~15 ~101 ~65 ~15 ~101 stained_hardened_clay 9
fill ~64 ~15 ~102 ~65 ~15 ~102 stained_hardened_clay 9
fill ~64 ~15 ~103 ~65 ~15 ~103 stained_hardened_clay 9
fill ~64 ~15 ~104 ~65 ~15 ~104 stained_hardened_clay 9
fill ~64 ~15 ~105 ~65 ~15 ~105 stained_hardened_clay 9
fill ~64 ~15 ~106 ~68 ~15 ~106 stained_hardened_clay 9
fill ~67 ~15 ~97 ~69 ~15 ~97 stained_hardened_clay 9
fill ~67 ~15 ~107 ~69 ~15 ~107 stained_hardened_clay 9
fill ~70 ~15 ~98 ~73 ~15 ~98 stained_hardened_clay 9
fill ~70 ~15 ~99 ~71 ~15 ~99 stained_hardened_clay 9
fill ~70 ~15 ~105 ~71 ~15 ~105 stained_hardened_clay 9
fill ~70 ~15 ~106 ~73 ~15 ~106 stained_hardened_clay 9
setblock ~73 ~15 ~97 stone_brick_stairs 5
setblock ~73 ~15 ~107 stone_brick_stairs 5
fill ~74 ~15 ~99 ~74 ~17 ~99 stained_hardened_clay 9
fill ~74 ~15 ~100 ~74 ~17 ~100 stained_hardened_clay 9
fill ~74 ~15 ~101 ~83 ~15 ~101 stained_hardened_clay 9
fill ~74 ~15 ~102 ~84 ~15 ~102 stained_hardened_clay 9
fill ~74 ~15 ~103 ~83 ~15 ~103 stained_hardened_clay 9
fill ~74 ~15 ~104 ~74 ~17 ~104 stained_hardened_clay 9
fill ~74 ~15 ~105 ~74 ~17 ~105 stained_hardened_clay 9
fill ~76 ~15 ~97 ~76 ~15 ~98 stone_brick_stairs 4
fill ~76 ~15 ~99 ~79 ~15 ~99 stained_hardened_clay 9
fill ~76 ~15 ~100 ~81 ~15 ~100 stained_hardened_clay 9
fill ~76 ~15 ~104 ~81 ~15 ~104 stained_hardened_clay 9
fill ~76 ~15 ~105 ~79 ~15 ~105 stained_hardened_clay 9
fill ~76 ~15 ~106 ~76 ~15 ~107 stone_brick_stairs 4
setblock ~77 ~15 ~98 double_wooden_slab 1
setblock ~77 ~15 ~106 double_wooden_slab 1
setblock ~78 ~15 ~98 wooden_slab 9
setblock ~78 ~15 ~106 wooden_slab 9
setblock ~86 ~15 ~79 stone_slab 5
setblock ~86 ~15 ~80 stonebrick 0
setblock ~86 ~15 ~124 stonebrick 0
setblock ~86 ~15 ~125 stone_slab 5
fill ~92 ~15 ~100 ~108 ~15 ~100 stained_hardened_clay 9
fill ~92 ~15 ~101 ~93 ~15 ~101 stained_hardened_clay 9
fill ~92 ~15 ~102 ~93 ~15 ~102 stained_hardened_clay 9
fill ~92 ~15 ~103 ~93 ~15 ~103 stained_hardened_clay 9
fill ~92 ~15 ~104 ~108 ~15 ~104 stained_hardened_clay 9
fill ~94 ~15 ~99 ~107 ~15 ~99 stained_hardened_clay 9
fill ~94 ~15 ~105 ~107 ~15 ~105 stained_hardened_clay 9
fill ~95 ~15 ~96 ~95 ~15 ~98 wooden_slab 13
fill ~95 ~15 ~106 ~95 ~15 ~108 wooden_slab 13
fill ~96 ~15 ~96 ~96 ~15 ~98 planks 5
fill ~96 ~15 ~106 ~96 ~15 ~108 planks 5
fill ~97 ~15 ~96 ~97 ~15 ~98 wooden_slab 13
fill ~97 ~15 ~106 ~97 ~15 ~108 wooden_slab 13
fill ~99 ~15 ~97 ~104 ~15 ~97 planks 1
fill ~99 ~15 ~98 ~101 ~15 ~98 stained_hardened_clay 9
fill ~99 ~15 ~106 ~101 ~15 ~106 stained_hardened_clay 9
fill ~99 ~15 ~107 ~104 ~15 ~107 planks 1
fill ~102 ~15 ~98 ~102 ~19 ~98 stained_hardened_clay 10
fill ~102 ~15 ~106 ~102 ~19 ~106 stained_hardened_clay 10
fill ~103 ~15 ~98 ~104 ~15 ~98 stained_hardened_clay 9
fill ~103 ~15 ~106 ~104 ~15 ~106 stained_hardened_clay 9
fill ~105 ~15 ~97 ~105 ~15 ~98 spruce_stairs 1
fill ~105 ~15 ~106 ~105 ~15 ~107 spruce_stairs 1
setblock ~108 ~15 ~80 stonebrick 0
fill ~108 ~15 ~101 ~108 ~16 ~101 stained_hardened_clay 9
fill ~108 ~15 ~102 ~108 ~15 ~104 stained_hardened_clay 9
setblock ~108 ~15 ~124 stonebrick 0
setblock ~109 ~15 ~79 stone_slab 5
setblock ~109 ~15 ~125 stone_slab 5
fill ~121 ~15 ~102 ~122 ~15 ~102 stained_glass_pane 1
fill ~63 ~16 ~97 ~63 ~16 ~107 wooden_slab 1
fill ~66 ~16 ~98 ~72 ~16 ~98 stained_hardened_clay 9
fill ~66 ~16 ~99 ~67 ~16 ~99 stained_hardened_clay 9
fill ~66 ~16 ~100 ~67 ~16 ~100 stained_hardened_clay 9
fill ~66 ~16 ~101 ~67 ~16 ~101 stained_hardened_clay 9
fill ~66 ~16 ~102 ~67 ~16 ~102 stained_hardened_clay 9
fill ~66 ~16 ~103 ~67 ~16 ~103 stained_hardened_clay 9
fill ~66 ~16 ~104 ~67 ~16 ~104 stained_hardened_clay 9
fill ~66 ~16 ~105 ~67 ~16 ~105 stained_hardened_clay 9
fill ~66 ~16 ~106 ~72 ~16 ~106 stained_hardened_clay 9
setblock ~68 ~16 ~97 stained_hardened_clay 9
setblock ~68 ~16 ~107 stained_hardened_clay 9
fill ~69 ~16 ~99 ~79 ~16 ~99 stained_hardened_clay 9
fill ~69 ~16 ~105 ~79 ~16 ~105 stained_hardened_clay 9
fill ~70 ~16 ~100 ~71 ~16 ~100 stained_hardened_clay 9
fill ~70 ~16 ~101 ~70 ~16 ~106 stained_hardened_clay 9
setblock ~71 ~16 ~104 stained_hardened_clay 9
fill ~73 ~16 ~97 ~73 ~16 ~98 stone_brick_stairs 0
fill ~73 ~16 ~106 ~73 ~16 ~107 stone_brick_stairs 0
fill ~74 ~16 ~97 ~74 ~16 ~98 stone_brick_stairs 5
fill ~74 ~16 ~101 ~85 ~16 ~101 stained_hardened_clay 9
fill ~74 ~16 ~102 ~85 ~16 ~102 stained_hardened_clay 9
fill ~74 ~16 ~103 ~85 ~16 ~103 stained_hardened_clay 9
fill ~74 ~16 ~106 ~74 ~16 ~107 stone_brick_stairs 5
fill ~75 ~16 ~97 ~75 ~16 ~98 stone_brick_stairs 4
fill ~75 ~16 ~106 ~75 ~16 ~107 stone_brick_stairs 4
fill ~76 ~16 ~97 ~76 ~16 ~98 stone_brick_stairs 1
fill ~76 ~16 ~100 ~82 ~16 ~100 stained_hardened_clay 9
fill ~76 ~16 ~104 ~82 ~16 ~104 stained_hardened_clay 9
fill ~76 ~16 ~106 ~76 ~16 ~107 stone_brick_stairs 1
setblock ~78 ~16 ~98 wooden_slab 1
setblock ~78 ~16 ~106 wooden_slab 1
setblock ~79 ~16 ~98 double_wooden_slab 1
setblock ~79 ~16 ~106 double_wooden_slab 1
setblock ~80 ~16 ~99 wooden_slab 9
setblock ~80 ~16 ~105 wooden_slab 9
setblock ~86 ~16 ~80 stone_slab 5
fill ~86 ~16 ~100 ~86 ~19 ~100 stone 6
fill ~86 ~16 ~101 ~86 ~16 ~104 stone 6
setblock ~86 ~16 ~124 stone_slab 5
fill ~87 ~16 ~81 ~87 ~17 ~81 stonebrick 0
fill ~87 ~16 ~123 ~87 ~17 ~123 stonebrick 0
fill ~88 ~16 ~101 ~91 ~16 ~101 stained_hardened_clay 9
fill ~88 ~16 ~102 ~91 ~16 ~102 stained_hardened_clay 9
fill ~88 ~16 ~103 ~91 ~16 ~103 stained_hardened_clay 9
fill ~92 ~16 ~99 ~108 ~16 ~99 stained_hardened_clay 9
fill ~92 ~16 ~100 ~93 ~16 ~100 stained_hardened_clay 9
fill ~92 ~16 ~104 ~93 ~16 ~104 stained_hardened_clay 9
fill ~92 ~16 ~105 ~108 ~16 ~105 stained_hardened_clay 9
fill ~95 ~16 ~96 ~95 ~16 ~97 planks 5
fill ~95 ~16 ~98 ~99 ~16 ~98 stained_hardened_clay 9
fill ~95 ~16 ~106 ~99 ~16 ~106 stained_hardened_clay 9
fill ~95 ~16 ~107 ~95 ~16 ~108 planks 5
setblock ~96 ~16 ~94 stone_slab 13
setblock ~96 ~16 ~95 double_stone_slab 5
fill ~96 ~16 ~96 ~96 ~16 ~97 stonebrick 0
fill ~96 ~16 ~107 ~96 ~16 ~108 stonebrick 0
setblock ~96 ~16 ~109 double_stone_slab 5
setblock ~96 ~16 ~110 stone_slab 13
fill ~97 ~16 ~96 ~97 ~16 ~97 planks 5
fill ~97 ~16 ~107 ~97 ~16 ~108 planks 5
fill ~98 ~16 ~97 ~99 ~16 ~97 planks 1
fill ~98 ~16 ~107 ~99 ~16 ~107 planks 1
setblock ~99 ~16 ~96 wooden_slab 13
setblock ~99 ~16 ~108 wooden_slab 13
setblock ~100 ~16 ~97 spruce_stairs 5
fill ~100 ~16 ~98 ~103 ~16 ~98 stained_hardened_clay 10
fill ~100 ~16 ~106 ~103 ~16 ~106 stained_hardened_clay 10
setblock ~100 ~16 ~107 spruce_stairs 5
setblock ~103 ~16 ~97 spruce_stairs 4
setblock ~103 ~16 ~107 spruce_stairs 4
fill ~104 ~16 ~97 ~107 ~16 ~97 planks 1
fill ~104 ~16 ~98 ~107 ~16 ~98 stained_hardened_clay 9
fill ~104 ~16 ~106 ~107 ~16 ~106 stained_hardened_clay 9
fill ~104 ~16 ~107 ~107 ~16 ~107 planks 1
setblock ~108 ~16 ~80 stone_slab 5
setblock ~108 ~16 ~81 stonebrick 0
setblock ~108 ~16 ~100 stained_hardened_clay 9
fill ~108 ~16 ~103 ~108 ~16 ~105 stained_hardened_clay 9
setblock ~108 ~16 ~123 stonebrick 0
setblock ~108 ~16 ~124 stone_slab 5
fill ~109 ~16 ~102 ~113 ~16 ~102 stained_hardened_clay 9
fill ~110 ~16 ~101 ~114 ~16 ~101 stained_hardened_clay 9
fill ~110 ~16 ~103 ~114 ~16 ~103 stained_hardened_clay 9
fill ~111 ~16 ~100 ~113 ~16 ~100 stained_hardened_clay 9
fill ~111 ~16 ~104 ~113 ~16 ~104 stained_hardened_clay 9
setblock ~114 ~16 ~102 planks 5
fill ~121 ~16 ~102 ~122 ~16 ~102 stained_glass_pane 1
fill ~67 ~17 ~100 ~69 ~17 ~100 stained_hardened_clay 9
fill ~67 ~17 ~101 ~69 ~17 ~101 stained_hardened_clay 9
fill ~67 ~17 ~102 ~69 ~17 ~102 stained_hardened_clay 9
fill ~67 ~17 ~103 ~69 ~17 ~103 stained_hardened_clay 9
fill ~67 ~17 ~104 ~69 ~17 ~104 stained_hardened_clay 9
setblock ~68 ~17 ~99 stained_hardened_clay 9
setblock ~68 ~17 ~105 stained_hardened_clay 9
fill ~71 ~17 ~101 ~91 ~17 ~101 stained_hardened_clay 9
fill ~71 ~17 ~102 ~91 ~17 ~102 stained_hardened_clay 9
fill ~71 ~17 ~103 ~91 ~17 ~103 stained_hardened_clay 9
fill ~72 ~17 ~100 ~85 ~17 ~100 stained_hardened_clay 9
fill ~72 ~17 ~104 ~85 ~17 ~104 stained_hardened_clay 9
setblock ~77 ~17 ~99 stained_hardened_clay 9
setblock ~77 ~17 ~105 stained_hardened_clay 9
setblock ~80 ~17 ~99 wooden_slab 1
setblock ~80 ~17 ~105 wooden_slab 1
fill ~81 ~17 ~99 ~84 ~17 ~99 double_wooden_slab 1
fill ~81 ~17 ~105 ~84 ~17 ~105 double_wooden_slab 1
fill ~85 ~17 ~99 ~91 ~17 ~99 wooden_slab 9
fill ~85 ~17 ~105 ~91 ~17 ~105 wooden_slab 9
fill ~86 ~17 ~104 ~86 ~19 ~104 stone 6
setblock ~87 ~17 ~100 wooden_slab 9
setblock ~87 ~17 ~104 wooden_slab 9
fill ~88 ~17 ~100 ~93 ~17 ~100 stained_hardened_clay 9
fill ~88 ~17 ~104 ~93 ~17 ~104 stained_hardened_clay 9
fill ~91 ~17 ~98 ~93 ~17 ~98 wooden_slab 9
fill ~91 ~17 ~106 ~93 ~17 ~106 wooden_slab 9
fill ~92 ~17 ~99 ~93 ~17 ~99 stained_hardened_clay 9
fill ~92 ~17 ~105 ~93 ~17 ~105 stained_hardened_clay 9
fill ~93 ~17 ~97 ~95 ~17 ~97 wooden_slab 9
fill ~93 ~17 ~107 ~95 ~17 ~107 wooden_slab 9
setblock ~94 ~17 ~91 stone_slab 13
fill ~94 ~17 ~92 ~95 ~17 ~92 stonebrick 0
fill ~94 ~17 ~98 ~97 ~17 ~98 stained_hardened_clay 9
fill ~94 ~17 ~106 ~97 ~17 ~106 stained_hardened_clay 9
fill ~94 ~17 ~112 ~95 ~17 ~112 stonebrick 0
setblock ~94 ~17 ~113 stone_slab 13
fill ~95 ~17 ~93 ~95 ~17 ~94 stonebrick 0
setblock ~95 ~17 ~96 wooden_slab 5
setblock ~95 ~17 ~108 wooden_slab 5
fill ~95 ~17 ~110 ~95 ~17 ~112 stonebrick 0
setblock ~96 ~17 ~94 stone_slab 5
fill ~96 ~17 ~96 ~96 ~17 ~97 planks 5
fill ~96 ~17 ~107 ~96 ~17 ~108 planks 5
setblock ~96 ~17 ~110 stone_slab 5
setblock ~97 ~17 ~96 wooden_slab 5
fill ~97 ~17 ~97 ~97 ~18 ~97 planks 1
fill ~97 ~17 ~107 ~97 ~18 ~107 planks 1
setblock ~97 ~17 ~108 wooden_slab 5
fill ~98 ~17 ~96 ~98 ~17 ~97 planks 5
fill ~98 ~17 ~98 ~106 ~17 ~98 stained_hardened_clay 10
fill ~98 ~17 ~106 ~106 ~17 ~106 stained_hardened_clay 10
fill ~98 ~17 ~107 ~98 ~17 ~108 planks 5
fill ~99 ~17 ~95 ~99 ~17 ~97 stonebrick 0
fill ~99 ~17 ~107 ~99 ~17 ~109 stonebrick 0
setblock ~100 ~17 ~95 stone_slab 13
fill ~100 ~17 ~96 ~100 ~17 ~97 planks 5
fill ~100 ~17 ~107 ~100 ~17 ~108 planks 5
setblock ~100 ~17 ~109 stone_slab 13
setblock ~106 ~17 ~97 spruce_stairs 0
setblock ~106 ~17 ~99 stained_hardened_clay 10
setblock ~106 ~17 ~105 stained_hardened_clay 10
setblock ~106 ~17 ~107 spruce_stairs 0
setblock ~107 ~17 ~82 stonebrick 0
fill ~107 ~17 ~97 ~108 ~17 ~97 planks 1
fill ~107 ~17 ~98 ~108 ~17 ~98 stained_hardened_clay 9
fill ~107 ~17 ~106 ~108 ~17 ~106 stained_hardened_clay 9
fill ~107 ~17 ~107 ~108 ~17 ~107 planks 1
setblock ~107 ~17 ~122 stonebrick 0
setblock ~108 ~17 ~81 stone_slab 5
fill ~108 ~17 ~99 ~108 ~20 ~99 stained_hardened_clay 9
fill ~108 ~17 ~105 ~108 ~20 ~105 stained_hardened_clay 9
setblock ~108 ~17 ~123 stone_slab 5
fill ~109 ~17 ~97 ~109 ~17 ~99 spruce_stairs 5
fill ~109 ~17 ~100 ~114 ~17 ~100 stained_hardened_clay 9
fill ~109 ~17 ~101 ~113 ~17 ~101 stained_hardened_clay 9
fill ~109 ~17 ~102 ~114 ~17 ~102 stained_hardened_clay 9
fill ~109 ~17 ~103 ~113 ~17 ~103 stained_hardened_clay 9
fill ~109 ~17 ~104 ~114 ~17 ~104 stained_hardened_clay 9
fill ~109 ~17 ~105 ~109 ~17 ~107 spruce_stairs 5
setblock ~114 ~17 ~101 planks 5
setblock ~114 ~17 ~103 planks 5
fill ~115 ~17 ~102 ~118 ~17 ~102 planks 5
fill ~120 ~17 ~102 ~121 ~17 ~102 stained_glass_pane 1
fill ~76 ~18 ~101 ~78 ~18 ~101 stained_hardened_clay 9
fill ~76 ~18 ~102 ~78 ~18 ~102 stained_hardened_clay 9
fill ~76 ~18 ~103 ~78 ~18 ~103 stained_hardened_clay 9
setblock ~77 ~18 ~100 stained_hardened_clay 9
setblock ~77 ~18 ~104 stained_hardened_clay 9
fill ~80 ~18 ~101 ~91 ~18 ~101 stained_hardened_clay 9
fill ~80 ~18 ~102 ~91 ~18 ~102 stained_hardened_clay 9
fill ~80 ~18 ~103 ~91 ~18 ~103 stained_hardened_clay 9
fill ~81 ~18 ~100 ~85 ~18 ~100 stained_hardened_clay 9
fill ~81 ~18 ~104 ~85 ~18 ~104 stained_hardened_clay 9
fill ~85 ~18 ~99 ~91 ~18 ~99 wooden_slab 1
fill ~85 ~18 ~105 ~91 ~18 ~105 wooden_slab 1
setblock ~87 ~18 ~81 stone_slab 5
setblock ~87 ~18 ~100 wooden_slab 1
setblock ~87 ~18 ~104 wooden_slab 1
setblock ~87 ~18 ~123 stone_slab 5
setblock ~88 ~18 ~82 stonebrick 0
fill ~88 ~18 ~100 ~92 ~18 ~100 stained_hardened_clay 9
fill ~88 ~18 ~104 ~92 ~18 ~104 stained_hardened_clay 9
setblock ~88 ~18 ~122 stonebrick 0
fill ~91 ~18 ~98 ~93 ~18 ~98 wooden_slab 1
fill ~91 ~18 ~106 ~93 ~18 ~106 wooden_slab 1
setblock ~92 ~18 ~89 stone_slab 13
fill ~92 ~18 ~99 ~93 ~18 ~99 stained_hardened_clay 9
fill ~92 ~18 ~105 ~93 ~18 ~105 stained_hardened_clay 9
setblock ~92 ~18 ~115 stone_slab 13
fill ~93 ~18 ~89 ~93 ~18 ~90 stonebrick 0
fill ~93 ~18 ~97 ~95 ~18 ~97 wooden_slab 1
fill ~93 ~18 ~107 ~95 ~18 ~107 wooden_slab 1
fill ~93 ~18 ~114 ~94 ~18 ~114 stonebrick 0
fill ~93 ~18 ~115 ~93 ~18 ~114 stonebrick 0
fill ~94 ~18 ~90 ~94 ~18 ~91 stonebrick 0
fill ~94 ~18 ~92 ~95 ~18 ~92 stone_slab 5
fill ~94 ~18 ~98 ~97 ~18 ~98 stained_hardened_clay 9
fill ~94 ~18 ~106 ~97 ~18 ~106 stained_hardened_clay 9
fill ~94 ~18 ~112 ~95 ~18 ~112 stone_slab 5
setblock ~94 ~18 ~113 stonebrick 0
setblock ~96 ~18 ~97 spruce_stairs 0
setblock ~96 ~18 ~107 spruce_stairs 0
setblock ~98 ~18 ~97 spruce_stairs 5
fill ~98 ~18 ~98 ~106 ~18 ~98 stained_hardened_clay 10
fill ~98 ~18 ~106 ~106 ~18 ~106 stained_hardened_clay 10
setblock ~98 ~18 ~107 spruce_stairs 5
fill ~99 ~18 ~95 ~100 ~18 ~95 stone_slab 5
setblock ~99 ~18 ~96 wooden_slab 5
setblock ~99 ~18 ~97 planks 5
setblock ~99 ~18 ~107 planks 5
setblock ~99 ~18 ~108 wooden_slab 5
fill ~99 ~18 ~109 ~100 ~18 ~109 stone_slab 5
fill ~100 ~18 ~93 ~101 ~18 ~93 stonebrick 0
fill ~100 ~18 ~94 ~100 ~18 ~93 stonebrick 0
fill ~100 ~18 ~110 ~100 ~18 ~111 stonebrick 0
setblock ~101 ~18 ~92 stone_slab 13
setblock ~101 ~18 ~111 stonebrick 0
setblock ~101 ~18 ~112 stone_slab 13
setblock ~106 ~18 ~83 stonebrick 0
setblock ~106 ~18 ~121 stonebrick 0
setblock ~107 ~18 ~82 stone_slab 5
fill ~107 ~18 ~97 ~108 ~18 ~97 planks 1
fill ~107 ~18 ~98 ~108 ~18 ~98 stained_hardened_clay 9
fill ~107 ~18 ~106 ~108 ~18 ~106 stained_hardened_clay 9
fill ~107 ~18 ~107 ~108 ~18 ~107 planks 1
setblock ~107 ~18 ~122 stone_slab 5
fill ~109 ~18 ~97 ~109 ~18 ~99 spruce_stairs 1
fill ~109 ~18 ~100 ~113 ~18 ~100 stained_hardened_clay 9
fill ~109 ~18 ~101 ~114 ~18 ~101 stained_hardened_clay 9
fill ~109 ~18 ~102 ~114 ~18 ~102 stained_hardened_clay 9
fill ~109 ~18 ~103 ~114 ~18 ~103 stained_hardened_clay 9
fill ~109 ~18 ~104 ~113 ~18 ~104 stained_hardened_clay 9
fill ~109 ~18 ~105 ~109 ~18 ~107 spruce_stairs 1
fill ~111 ~18 ~98 ~112 ~18 ~98 planks 2
fill ~111 ~18 ~99 ~112 ~18 ~99 stained_hardened_clay 4
fill ~111 ~18 ~105 ~112 ~18 ~105 stained_hardened_clay 4
fill ~111 ~18 ~106 ~112 ~18 ~106 planks 2
setblock ~113 ~18 ~99 stained_hardened_clay 9
setblock ~113 ~18 ~105 stained_hardened_clay 9
setblock ~114 ~18 ~100 planks 5
setblock ~114 ~18 ~104 planks 5
fill ~115 ~18 ~101 ~118 ~18 ~101 planks 5
fill ~115 ~18 ~103 ~118 ~18 ~103 planks 5
fill ~118 ~18 ~102 ~120 ~18 ~102 stained_glass_pane 1
fill ~82 ~19 ~102 ~85 ~19 ~102 stained_hardened_clay 9
fill ~83 ~19 ~101 ~84 ~19 ~101 stained_hardened_clay 9
fill ~83 ~19 ~103 ~84 ~19 ~103 stained_hardened_clay 9
fill ~86 ~19 ~101 ~86 ~19 ~104 stone 6
setblock ~88 ~19 ~82 stone_slab 5
fill ~88 ~19 ~83 ~88 ~19 ~84 stonebrick 0
fill ~88 ~19 ~101 ~91 ~19 ~101 stained_hardened_clay 9
fill ~88 ~19 ~102 ~91 ~19 ~102 stained_hardened_clay 9
fill ~88 ~19 ~103 ~91 ~19 ~103 stained_hardened_clay 9
fill ~88 ~19 ~120 ~88 ~19 ~121 stonebrick 0
setblock ~88 ~19 ~122 stone_slab 5
setblock ~89 ~19 ~84 stone_slab 13
fill ~89 ~19 ~86 ~89 ~21 ~86 stained_hardened_clay 9
fill ~89 ~19 ~118 ~89 ~21 ~118 stained_hardened_clay 9
setblock ~89 ~19 ~120 stone_slab 13
fill ~90 ~19 ~85 ~90 ~21 ~85 stained_hardened_clay 9
fill ~90 ~19 ~119 ~90 ~21 ~119 stained_hardened_clay 9
fill ~91 ~19 ~87 ~92 ~19 ~87 stonebrick 0
fill ~91 ~19 ~117 ~92 ~19 ~117 stonebrick 0
setblock ~92 ~19 ~88 stonebrick 0
setblock ~92 ~19 ~89 stone_slab 5
fill ~92 ~19 ~99 ~108 ~19 ~99 stained_hardened_clay 9
fill ~92 ~19 ~100 ~93 ~19 ~100 stained_hardened_clay 9
fill ~92 ~19 ~104 ~93 ~19 ~104 stained_hardened_clay 9
fill ~92 ~19 ~105 ~108 ~19 ~105 stained_hardened_clay 9
setblock ~92 ~19 ~115 stone_slab 5
setblock ~92 ~19 ~116 stonebrick 0
fill ~95 ~19 ~98 ~100 ~19 ~98 stained_hardened_clay 9
fill ~95 ~19 ~106 ~100 ~19 ~106 stained_hardened_clay 9
setblock ~97 ~19 ~97 spruce_stairs 4
setblock ~97 ~19 ~107 spruce_stairs 4
fill ~98 ~19 ~97 ~100 ~19 ~97 planks 1
fill ~98 ~19 ~107 ~100 ~19 ~107 planks 1
fill ~101 ~19 ~92 ~102 ~19 ~92 stonebrick 0
setblock ~101 ~19 ~93 stone_slab 5
setblock ~101 ~19 ~97 spruce_stairs 1
setblock ~101 ~19 ~98 stained_hardened_clay 10
setblock ~101 ~19 ~106 stained_hardened_clay 10
setblock ~101 ~19 ~107 spruce_stairs 1
setblock ~101 ~19 ~111 stone_slab 5
fill ~101 ~19 ~112 ~102 ~19 ~112 stonebrick 0
fill ~102 ~19 ~90 ~103 ~19 ~90 stonebrick 0
fill ~102 ~19 ~91 ~102 ~19 ~90 stonebrick 0
fill ~102 ~19 ~113 ~102 ~19 ~114 stonebrick 0
setblock ~103 ~19 ~89 stone_slab 13
fill ~103 ~19 ~98 ~105 ~19 ~98 stained_hardened_clay 10
fill ~103 ~19 ~106 ~105 ~19 ~106 stained_hardened_clay 10
setblock ~103 ~19 ~114 stonebrick 0
setblock ~103 ~19 ~115 stone_slab 13
fill ~104 ~19 ~86 ~104 ~21 ~86 stained_hardened_clay 9
fill ~104 ~19 ~118 ~104 ~21 ~118 stained_hardened_clay 9
fill ~105 ~19 ~87 ~105 ~21 ~87 stained_hardened_clay 9
setblock ~105 ~19 ~97 spruce_stairs 0
setblock ~105 ~19 ~107 spruce_stairs 0
fill ~105 ~19 ~117 ~105 ~21 ~117 stained_hardened_clay 9
setblock ~106 ~19 ~83 stone_slab 5
setblock ~106 ~19 ~84 stonebrick 0
setblock ~106 ~19 ~85 stone_slab 13
fill ~106 ~19 ~97 ~107 ~19 ~97 planks 1
fill ~106 ~19 ~98 ~107 ~19 ~98 stained_hardened_clay 9
fill ~106 ~19 ~106 ~107 ~19 ~106 stained_hardened_clay 9
fill ~106 ~19 ~107 ~107 ~19 ~107 planks 1
setblock ~106 ~19 ~119 stone_slab 13
setblock ~106 ~19 ~120 stonebrick 0
setblock ~106 ~19 ~121 stone_slab 5
fill ~109 ~19 ~100 ~114 ~19 ~100 stained_hardened_clay 9
fill ~109 ~19 ~101 ~114 ~19 ~101 stained_hardened_clay 9
fill ~109 ~19 ~102 ~115 ~19 ~102 stained_hardened_clay 9
fill ~109 ~19 ~103 ~114 ~19 ~103 stained_hardened_clay 9
fill ~109 ~19 ~104 ~114 ~19 ~104 stained_hardened_clay 9
setblock ~110 ~19 ~99 planks 2
setblock ~110 ~19 ~105 planks 2
setblock ~111 ~19 ~98 wooden_slab 2
fill ~111 ~19 ~99 ~112 ~19 ~99 sea_lantern 0
fill ~111 ~19 ~105 ~112 ~19 ~105 sea_lantern 0
setblock ~111 ~19 ~106 wooden_slab 2
setblock ~113 ~19 ~99 planks 2
setblock ~113 ~19 ~105 planks 2
fill ~115 ~19 ~101 ~115 ~18 ~101 planks 5
fill ~115 ~19 ~103 ~115 ~18 ~103 planks 5
fill ~116 ~19 ~102 ~118 ~19 ~102 planks 5
fill ~62 ~20 ~95 ~64 ~20 ~95 stained_hardened_clay 10
fill ~62 ~20 ~109 ~64 ~20 ~109 stained_hardened_clay 10
fill ~64 ~20 ~96 ~66 ~20 ~96 stained_hardened_clay 10
fill ~64 ~20 ~108 ~66 ~20 ~108 stained_hardened_clay 10
setblock ~89 ~20 ~84 stone_slab 5
setblock ~89 ~20 ~85 stonebrick 0
setblock ~89 ~20 ~119 stonebrick 0
setblock ~89 ~20 ~120 stone_slab 5
fill ~90 ~20 ~86 ~91 ~20 ~86 stonebrick 0
fill ~90 ~20 ~118 ~91 ~20 ~118 stonebrick 0
setblock ~91 ~20 ~87 stone_slab 5
fill ~91 ~20 ~97 ~95 ~20 ~97 stone 6
fill ~91 ~20 ~107 ~95 ~20 ~107 stone 6
setblock ~91 ~20 ~117 stone_slab 5
fill ~92 ~20 ~96 ~94 ~20 ~96 stone 6
fill ~92 ~20 ~98 ~95 ~20 ~98 stone 6
fill ~92 ~20 ~100 ~108 ~20 ~100 stained_hardened_clay 9
fill ~92 ~20 ~101 ~93 ~20 ~101 stained_hardened_clay 9
fill ~92 ~20 ~102 ~93 ~20 ~102 stained_hardened_clay 9
fill ~92 ~20 ~103 ~93 ~20 ~103 stained_hardened_clay 9
fill ~92 ~20 ~104 ~108 ~20 ~104 stained_hardened_clay 9
fill ~92 ~20 ~106 ~95 ~20 ~106 stone 6
fill ~92 ~20 ~108 ~94 ~20 ~108 stone 6
fill ~94 ~20 ~99 ~108 ~20 ~99 stained_hardened_clay 9
fill ~94 ~20 ~105 ~108 ~20 ~105 stained_hardened_clay 9
setblock ~99 ~20 ~97 spruce_stairs 4
fill ~99 ~20 ~98 ~104 ~20 ~98 stained_hardened_clay 9
fill ~99 ~20 ~106 ~104 ~20 ~106 stained_hardened_clay 9
setblock ~99 ~20 ~107 spruce_stairs 4
fill ~100 ~20 ~97 ~106 ~20 ~97 planks 1
fill ~100 ~20 ~107 ~106 ~20 ~107 planks 1
fill ~103 ~20 ~88 ~104 ~20 ~88 stonebrick 0
fill ~103 ~20 ~89 ~103 ~20 ~88 stonebrick 0
setblock ~103 ~20 ~90 stone_slab 5
setblock ~103 ~20 ~114 stone_slab 5
fill ~103 ~20 ~115 ~103 ~20 ~116 stonebrick 0
setblock ~104 ~20 ~87 stone_slab 13
setblock ~104 ~20 ~116 stonebrick 0
setblock ~104 ~20 ~117 stone_slab 13
setblock ~105 ~20 ~85 stonebrick 0
setblock ~105 ~20 ~86 stone_slab 13
fill ~105 ~20 ~98 ~106 ~20 ~98 planks 1
fill ~105 ~20 ~106 ~106 ~20 ~106 planks 1
setblock ~105 ~20 ~118 stone_slab 13
setblock ~105 ~20 ~119 stonebrick 0
setblock ~106 ~20 ~85 stone_slab 5
setblock ~106 ~20 ~119 stone_slab 5
fill ~107 ~20 ~97 ~107 ~20 ~98 spruce_stairs 5
fill ~107 ~20 ~106 ~107 ~20 ~107 spruce_stairs 5
fill ~108 ~20 ~102 ~115 ~20 ~102 stained_hardened_clay 9
fill ~109 ~20 ~101 ~114 ~20 ~101 stained_hardened_clay 9
fill ~109 ~20 ~103 ~114 ~20 ~103 stained_hardened_clay 9
setblock ~110 ~20 ~99 wooden_slab 2
setblock ~110 ~20 ~100 planks 2
setblock ~110 ~20 ~104 planks 2
setblock ~110 ~20 ~105 wooden_slab 2
fill ~111 ~20 ~99 ~112 ~20 ~99 sea_lantern 0
fill ~111 ~20 ~100 ~111 ~21 ~100 sea_lantern 0
fill ~111 ~20 ~104 ~111 ~21 ~104 sea_lantern 0
fill ~111 ~20 ~105 ~112 ~20 ~105 sea_lantern 0
setblock ~112 ~20 ~100 stained_glass 0
setblock ~112 ~20 ~104 stained_glass 0
setblock ~113 ~20 ~99 wooden_slab 2
setblock ~113 ~20 ~100 planks 2
setblock ~113 ~20 ~104 planks 2
setblock ~113 ~20 ~105 wooden_slab 2
fill ~61 ~21 ~95 ~62 ~21 ~95 stained_hardened_clay 10
fill ~61 ~21 ~109 ~62 ~21 ~109 stained_hardened_clay 10
fill ~66 ~21 ~96 ~67 ~21 ~96 stained_hardened_clay 10
fill ~66 ~21 ~108 ~67 ~21 ~108 stained_hardened_clay 10
fill ~84 ~21 ~96 ~88 ~21 ~96 stained_hardened_clay 10
fill ~84 ~21 ~108 ~88 ~21 ~108 stained_hardened_clay 10
fill ~91 ~21 ~95 ~94 ~21 ~95 stone 6
fill ~91 ~21 ~96 ~95 ~21 ~96 stone 6
fill ~91 ~21 ~97 ~95 ~21 ~97 stone 6
fill ~91 ~21 ~98 ~95 ~21 ~98 stone 6
fill ~91 ~21 ~106 ~95 ~21 ~106 stone 6
fill ~91 ~21 ~107 ~95 ~21 ~107 stone 6
fill ~91 ~21 ~108 ~95 ~21 ~108 stone 6
fill ~91 ~21 ~109 ~94 ~21 ~109 stone 6
fill ~93 ~21 ~99 ~95 ~21 ~99 stone 6
fill ~93 ~21 ~105 ~95 ~21 ~105 stone 6
fill ~94 ~21 ~101 ~108 ~21 ~101 stained_hardened_clay 9
fill ~94 ~21 ~102 ~108 ~21 ~102 stained_hardened_clay 9
fill ~94 ~21 ~103 ~108 ~21 ~103 stained_hardened_clay 9
fill ~95 ~21 ~100 ~108 ~21 ~100 stained_hardened_clay 9
fill ~95 ~21 ~104 ~108 ~21 ~104 stained_hardened_clay 9
fill ~98 ~21 ~99 ~105 ~21 ~99 stained_hardened_clay 9
fill ~98 ~21 ~105 ~105 ~21 ~105 stained_hardened_clay 9
fill ~100 ~21 ~97 ~100 ~21 ~98 spruce_stairs 4
fill ~100 ~21 ~106 ~100 ~21 ~107 spruce_stairs 4
fill ~101 ~21 ~97 ~103 ~21 ~97 planks 1
fill ~101 ~21 ~98 ~102 ~21 ~98 stained_hardened_clay 9
fill ~101 ~21 ~106 ~102 ~21 ~106 stained_hardened_clay 9
fill ~101 ~21 ~107 ~103 ~21 ~107 planks 1
setblock ~103 ~21 ~98 planks 1
setblock ~103 ~21 ~106 planks 1
setblock ~104 ~21 ~87 stone_slab 5
fill ~104 ~21 ~97 ~104 ~21 ~98 spruce_stairs 5
fill ~104 ~21 ~106 ~104 ~21 ~107 spruce_stairs 5
setblock ~104 ~21 ~117 stone_slab 5
setblock ~105 ~21 ~86 stone_slab 5
setblock ~105 ~21 ~118 stone_slab 5
setblock ~110 ~21 ~100 wooden_slab 2
setblock ~110 ~21 ~104 wooden_slab 2
fill ~111 ~21 ~101 ~112 ~21 ~101 planks 2
fill ~111 ~21 ~102 ~113 ~21 ~102 stained_hardened_clay 9
fill ~111 ~21 ~103 ~112 ~21 ~103 planks 2
setblock ~112 ~21 ~100 planks 2
setblock ~112 ~21 ~104 planks 2
setblock ~113 ~21 ~100 wooden_slab 2
setblock ~113 ~21 ~101 stained_hardened_clay 9
setblock ~113 ~21 ~103 stained_hardened_clay 9
setblock ~113 ~21 ~104 wooden_slab 2
fill ~61 ~22 ~95 ~61 ~23 ~95 stained_hardened_clay 10
fill ~61 ~22 ~96 ~61 ~24 ~96 stained_hardened_clay 10
fill ~61 ~22 ~108 ~61 ~24 ~108 stained_hardened_clay 10
fill ~61 ~22 ~109 ~61 ~23 ~109 stained_hardened_clay 10
fill ~67 ~22 ~96 ~67 ~25 ~96 stained_hardened_clay 10
fill ~67 ~22 ~108 ~67 ~25 ~108 stained_hardened_clay 10
fill ~82 ~22 ~96 ~84 ~22 ~96 stained_hardened_clay 10
fill ~82 ~22 ~108 ~84 ~22 ~108 stained_hardened_clay 10
fill ~88 ~22 ~96 ~90 ~22 ~96 stained_hardened_clay 10
fill ~88 ~22 ~108 ~90 ~22 ~108 stained_hardened_clay 10
setblock ~89 ~22 ~86 spruce_fence 0
setblock ~89 ~22 ~118 spruce_fence 0
fill ~90 ~22 ~95 ~94 ~22 ~95 stone 6
fill ~90 ~22 ~109 ~94 ~22 ~109 stone 6
fill ~91 ~22 ~96 ~95 ~22 ~96 stone 6
fill ~91 ~22 ~97 ~95 ~22 ~97 stone 6
fill ~91 ~22 ~98 ~95 ~22 ~98 stone 6
fill ~91 ~22 ~106 ~95 ~22 ~106 stone 6
fill ~91 ~22 ~107 ~95 ~22 ~107 stone 6
fill ~91 ~22 ~108 ~95 ~22 ~108 stone 6
fill ~92 ~22 ~94 ~94 ~22 ~94 stone 6
fill ~92 ~22 ~99 ~94 ~22 ~99 stone 6
fill ~92 ~22 ~105 ~94 ~22 ~105 stone 6
fill ~92 ~22 ~110 ~94 ~22 ~110 stone 6
fill ~99 ~22 ~101 ~104 ~22 ~101 stained_hardened_clay 9
fill ~99 ~22 ~102 ~104 ~22 ~102 stained_hardened_clay 9
fill ~99 ~22 ~103 ~104 ~22 ~103 stained_hardened_clay 9
fill ~100 ~22 ~99 ~103 ~22 ~99 stained_hardened_clay 9
fill ~100 ~22 ~100 ~103 ~22 ~100 stained_hardened_clay 9
fill ~100 ~22 ~104 ~103 ~22 ~104 stained_hardened_clay 9
fill ~100 ~22 ~105 ~103 ~22 ~105 stained_hardened_clay 9
setblock ~101 ~22 ~97 spruce_stairs 0
fill ~101 ~22 ~98 ~102 ~22 ~98 planks 1
fill ~101 ~22 ~106 ~102 ~22 ~106 planks 1
setblock ~101 ~22 ~107 spruce_stairs 0
setblock ~102 ~22 ~97 spruce_stairs 1
setblock ~102 ~22 ~107 spruce_stairs 1
setblock ~104 ~22 ~86 spruce_fence 0
setblock ~104 ~22 ~118 spruce_fence 0
fill ~111 ~22 ~101 ~112 ~22 ~101 wooden_slab 2
fill ~111 ~22 ~103 ~112 ~22 ~103 wooden_slab 2
fill ~113 ~22 ~101 ~113 ~28 ~101 stained_glass_pane 7
fill ~113 ~22 ~103 ~113 ~28 ~103 stained_glass_pane 7
fill ~59 ~23 ~96 ~61 ~23 ~96 stained_hardened_clay 10
fill ~59 ~23 ~108 ~61 ~23 ~108 stained_hardened_clay 10
fill ~62 ~23 ~95 ~62 ~24 ~95 stained_hardened_clay 10
fill ~62 ~23 ~109 ~62 ~24 ~109 stained_hardened_clay 10
fill ~64 ~23 ~95 ~64 ~24 ~95 stained_hardened_clay 10
fill ~64 ~23 ~109 ~64 ~24 ~109 stained_hardened_clay 10
fill ~67 ~23 ~95 ~70 ~23 ~95 stained_hardened_clay 10
fill ~67 ~23 ~109 ~70 ~23 ~109 stained_hardened_clay 10
setblock ~68 ~23 ~96 stained_hardened_clay 10
setblock ~68 ~23 ~108 stained_hardened_clay 10
fill ~75 ~23 ~95 ~79 ~23 ~95 stained_hardened_clay 10
fill ~75 ~23 ~109 ~79 ~23 ~109 stained_hardened_clay 10
fill ~79 ~23 ~96 ~82 ~23 ~96 stained_hardened_clay 10
fill ~79 ~23 ~108 ~82 ~23 ~108 stained_hardened_clay 10
fill ~88 ~23 ~86 ~90 ~23 ~86 wooden_slab 1
fill ~88 ~23 ~95 ~88 ~24 ~95 stained_hardened_clay 10
fill ~88 ~23 ~109 ~88 ~24 ~109 stained_hardened_clay 10
fill ~88 ~23 ~118 ~90 ~23 ~118 wooden_slab 1
setblock ~89 ~23 ~85 wooden_slab 1
setblock ~89 ~23 ~87 wooden_slab 1
fill ~89 ~23 ~95 ~95 ~23 ~95 stone 6
fill ~89 ~23 ~109 ~95 ~23 ~109 stone 6
setblock ~89 ~23 ~117 wooden_slab 1
setblock ~89 ~23 ~119 wooden_slab 1
fill ~90 ~23 ~94 ~95 ~23 ~94 stone 6
fill ~90 ~23 ~96 ~95 ~23 ~96 stone 6
fill ~90 ~23 ~97 ~95 ~23 ~97 stone 6
fill ~90 ~23 ~107 ~95 ~23 ~107 stone 6
fill ~90 ~23 ~108 ~95 ~23 ~108 stone 6
fill ~90 ~23 ~110 ~95 ~23 ~110 stone 6
fill ~93 ~23 ~98 ~95 ~23 ~98 stone 6
fill ~93 ~23 ~106 ~95 ~23 ~106 stone 6
fill ~101 ~23 ~98 ~101 ~23 ~99 spruce_stairs 0
fill ~101 ~23 ~100 ~102 ~23 ~100 planks 1
fill ~101 ~23 ~101 ~102 ~23 ~101 planks 1
fill ~101 ~23 ~102 ~101 ~23 ~104 planks 1
fill ~101 ~23 ~105 ~101 ~23 ~106 spruce_stairs 0
fill ~102 ~23 ~98 ~102 ~23 ~99 spruce_stairs 1
fill ~102 ~23 ~102 ~102 ~25 ~102 stone 6
fill ~102 ~23 ~103 ~102 ~23 ~104 planks 1
fill ~102 ~23 ~105 ~102 ~23 ~106 spruce_stairs 1
fill ~103 ~23 ~86 ~105 ~23 ~86 wooden_slab 1
fill ~103 ~23 ~118 ~105 ~23 ~118 wooden_slab 1
setblock ~104 ~23 ~85 wooden_slab 1
setblock ~104 ~23 ~87 wooden_slab 1
setblock ~104 ~23 ~117 wooden_slab 1
setblock ~104 ~23 ~119 wooden_slab 1
fill ~54 ~24 ~96 ~59 ~24 ~96 stained_hardened_clay 10
fill ~54 ~24 ~108 ~59 ~24 ~108 stained_hardened_clay 10
setblock ~62 ~24 ~96 stained_hardened_clay 10
setblock ~62 ~24 ~108 stained_hardened_clay 10
setblock ~63 ~24 ~95 stained_hardened_clay 10
setblock ~63 ~24 ~109 stained_hardened_clay 10
setblock ~64 ~24 ~96 stained_hardened_clay 10
setblock ~64 ~24 ~108 stained_hardened_clay 10
fill ~66 ~24 ~95 ~67 ~24 ~95 stained_hardened_clay 10
fill ~66 ~24 ~109 ~67 ~24 ~109 stained_hardened_clay 10
fill ~70 ~24 ~95 ~72 ~24 ~95 stained_hardened_clay 10
fill ~70 ~24 ~109 ~72 ~24 ~109 stained_hardened_clay 10
fill ~74 ~24 ~95 ~75 ~24 ~95 stained_hardened_clay 10
fill ~74 ~24 ~109 ~75 ~24 ~109 stained_hardened_clay 10
fill ~85 ~24 ~95 ~88 ~24 ~95 stained_hardened_clay 10
fill ~85 ~24 ~109 ~88 ~24 ~109 stained_hardened_clay 10
fill ~89 ~24 ~94 ~91 ~24 ~94 stone 6
fill ~89 ~24 ~95 ~96 ~24 ~95 stone 6
fill ~89 ~24 ~109 ~96 ~24 ~109 stone 6
fill ~89 ~24 ~110 ~91 ~24 ~110 stone 6
fill ~90 ~24 ~93 ~90 ~27 ~93 stone 6
fill ~90 ~24 ~96 ~95 ~24 ~96 stone 6
fill ~90 ~24 ~108 ~95 ~24 ~108 stone 6
fill ~90 ~24 ~111 ~90 ~27 ~111 stone 6
fill ~92 ~24 ~97 ~93 ~24 ~97 stone 6
fill ~92 ~24 ~107 ~93 ~24 ~107 stone 6
fill ~93 ~24 ~94 ~95 ~24 ~94 stone 6
fill ~93 ~24 ~110 ~95 ~24 ~110 stone 6
fill ~100 ~24 ~101 ~101 ~24 ~101 wooden_slab 12
fill ~100 ~24 ~102 ~100 ~24 ~103 wooden_slab 12
fill ~101 ~24 ~100 ~103 ~24 ~100 wooden_slab 12
fill ~101 ~24 ~103 ~101 ~24 ~104 wooden_slab 12
fill ~102 ~24 ~104 ~103 ~24 ~104 wooden_slab 12
fill ~103 ~24 ~101 ~104 ~24 ~101 wooden_slab 12
fill ~103 ~24 ~103 ~104 ~24 ~103 wooden_slab 12
setblock ~104 ~24 ~102 wooden_slab 12
fill ~42 ~25 ~94 ~42 ~26 ~94 stained_hardened_clay 10
fill ~42 ~25 ~95 ~46 ~25 ~95 stained_hardened_clay 10
fill ~42 ~25 ~109 ~46 ~25 ~109 stained_hardened_clay 10
fill ~42 ~25 ~110 ~42 ~26 ~110 stained_hardened_clay 10
fill ~50 ~25 ~95 ~54 ~25 ~95 stained_hardened_clay 10
fill ~50 ~25 ~109 ~54 ~25 ~109 stained_hardened_clay 10
fill ~54 ~25 ~96 ~54 ~24 ~96 stained_hardened_clay 10
fill ~54 ~25 ~108 ~54 ~24 ~108 stained_hardened_clay 10
fill ~65 ~25 ~94 ~66 ~25 ~94 stained_hardened_clay 10
fill ~65 ~25 ~110 ~66 ~25 ~110 stained_hardened_clay 10
fill ~66 ~25 ~95 ~67 ~25 ~95 stained_hardened_clay 10
fill ~66 ~25 ~109 ~67 ~25 ~109 stained_hardened_clay 10
fill ~72 ~25 ~95 ~74 ~25 ~95 stained_hardened_clay 10
fill ~72 ~25 ~109 ~74 ~25 ~109 stained_hardened_clay 10
fill ~74 ~25 ~94 ~77 ~25 ~94 stained_hardened_clay 10
fill ~74 ~25 ~110 ~77 ~25 ~110 stained_hardened_clay 10
fill ~82 ~25 ~94 ~85 ~25 ~94 stained_hardened_clay 10
fill ~82 ~25 ~110 ~85 ~25 ~110 stained_hardened_clay 10
setblock ~88 ~25 ~94 stained_hardened_clay 10
setblock ~88 ~25 ~110 stained_hardened_clay 10
fill ~89 ~25 ~93 ~89 ~28 ~93 stone 6
fill ~89 ~25 ~94 ~96 ~25 ~94 stone 6
fill ~89 ~25 ~95 ~91 ~25 ~95 stone 6
fill ~89 ~25 ~96 ~91 ~25 ~96 stone 6
fill ~89 ~25 ~108 ~91 ~25 ~108 stone 6
fill ~89 ~25 ~109 ~91 ~25 ~109 stone 6
fill ~89 ~25 ~110 ~96 ~25 ~110 stone 6
fill ~89 ~25 ~111 ~89 ~28 ~111 stone 6
setblock ~91 ~25 ~93 stone 6
setblock ~91 ~25 ~111 stone 6
fill ~93 ~25 ~93 ~96 ~25 ~93 stone 6
fill ~93 ~25 ~95 ~96 ~25 ~95 stone 6
fill ~93 ~25 ~96 ~96 ~25 ~96 stone 6
fill ~93 ~25 ~108 ~96 ~25 ~108 stone 6
fill ~93 ~25 ~109 ~96 ~25 ~109 stone 6
fill ~93 ~25 ~111 ~96 ~25 ~111 stone 6
fill ~114 ~25 ~101 ~114 ~31 ~101 stained_glass_pane 7
fill ~114 ~25 ~103 ~114 ~31 ~103 stained_glass_pane 7
fill ~40 ~26 ~94 ~43 ~26 ~94 stained_hardened_clay 10
fill ~40 ~26 ~110 ~43 ~26 ~110 stained_hardened_clay 10
fill ~46 ~26 ~95 ~50 ~26 ~95 stained_hardened_clay 10
fill ~46 ~26 ~109 ~50 ~26 ~109 stained_hardened_clay 10
setblock ~53 ~26 ~95 stained_hardened_clay 10
setblock ~53 ~26 ~109 stained_hardened_clay 10
fill ~54 ~26 ~94 ~55 ~26 ~94 stained_hardened_clay 10
fill ~54 ~26 ~110 ~55 ~26 ~110 stained_hardened_clay 10
fill ~64 ~26 ~94 ~65 ~26 ~94 stained_hardened_clay 10
fill ~64 ~26 ~110 ~65 ~26 ~110 stained_hardened_clay 10
fill ~65 ~26 ~95 ~66 ~26 ~95 stained_hardened_clay 10
fill ~65 ~26 ~109 ~66 ~26 ~109 stained_hardened_clay 10
setblock ~75 ~26 ~94 stained_hardened_clay 10
setblock ~75 ~26 ~110 stained_hardened_clay 10
fill ~77 ~26 ~94 ~82 ~26 ~94 stained_hardened_clay 10
fill ~77 ~26 ~110 ~82 ~26 ~110 stained_hardened_clay 10
fill ~88 ~26 ~92 ~88 ~29 ~92 stone 6
fill ~88 ~26 ~93 ~88 ~29 ~93 stone 6
fill ~88 ~26 ~94 ~90 ~26 ~94 stone 6
fill ~88 ~26 ~110 ~90 ~26 ~110 stone 6
fill ~88 ~26 ~111 ~88 ~29 ~111 stone 6
fill ~88 ~26 ~112 ~88 ~29 ~112 stone 6
fill ~89 ~26 ~95 ~90 ~26 ~95 stone 6
fill ~89 ~26 ~109 ~90 ~26 ~109 stone 6
fill ~93 ~26 ~94 ~97 ~26 ~94 stone 6
fill ~93 ~26 ~95 ~96 ~26 ~95 stone 6
fill ~93 ~26 ~109 ~96 ~26 ~109 stone 6
fill ~93 ~26 ~110 ~97 ~26 ~110 stone 6
fill ~94 ~26 ~92 ~96 ~26 ~92 stone 6
fill ~94 ~26 ~93 ~97 ~26 ~93 stone 6
fill ~94 ~26 ~111 ~97 ~26 ~111 stone 6
fill ~94 ~26 ~112 ~96 ~26 ~112 stone 6
fill ~17 ~27 ~93 ~21 ~27 ~93 stained_hardened_clay 10
fill ~17 ~27 ~111 ~21 ~27 ~111 stained_hardened_clay 10
fill ~23 ~27 ~92 ~27 ~27 ~92 stained_hardened_clay 10
fill ~23 ~27 ~112 ~27 ~27 ~112 stained_hardened_clay 10
fill ~35 ~27 ~93 ~40 ~27 ~93 stained_hardened_clay 10
fill ~35 ~27 ~111 ~40 ~27 ~111 stained_hardened_clay 10
fill ~43 ~27 ~94 ~44 ~27 ~94 stained_hardened_clay 10
fill ~43 ~27 ~110 ~44 ~27 ~110 stained_hardened_clay 10
fill ~47 ~27 ~92 ~51 ~27 ~92 stained_hardened_clay 10
fill ~47 ~27 ~112 ~51 ~27 ~112 stained_hardened_clay 10
fill ~55 ~27 ~93 ~56 ~27 ~93 stained_hardened_clay 10
fill ~55 ~27 ~94 ~55 ~27 ~93 stained_hardened_clay 10
fill ~55 ~27 ~110 ~55 ~27 ~111 stained_hardened_clay 10
fill ~56 ~27 ~111 ~56 ~28 ~111 stained_hardened_clay 10
fill ~61 ~27 ~93 ~63 ~27 ~93 stained_hardened_clay 10
fill ~61 ~27 ~111 ~63 ~27 ~111 stained_hardened_clay 10
fill ~62 ~27 ~94 ~63 ~27 ~94 stained_hardened_clay 10
fill ~62 ~27 ~110 ~63 ~27 ~110 stained_hardened_clay 10
fill ~66 ~27 ~92 ~69 ~27 ~92 stained_hardened_clay 10
fill ~66 ~27 ~112 ~69 ~27 ~112 stained_hardened_clay 10
fill ~75 ~27 ~93 ~75 ~28 ~93 stained_hardened_clay 10
fill ~75 ~27 ~111 ~75 ~28 ~111 stained_hardened_clay 10
fill ~79 ~27 ~93 ~79 ~28 ~93 stained_hardened_clay 10
fill ~79 ~27 ~111 ~79 ~28 ~111 stained_hardened_clay 10
fill ~82 ~27 ~93 ~85 ~27 ~93 stained_hardened_clay 10
fill ~82 ~27 ~94 ~85 ~27 ~94 stained_hardened_clay 10
fill ~82 ~27 ~110 ~85 ~27 ~110 stained_hardened_clay 10
fill ~82 ~27 ~111 ~85 ~27 ~111 stained_hardened_clay 10
fill ~87 ~27 ~91 ~87 ~30 ~91 stone 6
fill ~87 ~27 ~92 ~87 ~30 ~92 stone 6
fill ~87 ~27 ~93 ~87 ~30 ~93 stone 6
fill ~87 ~27 ~94 ~90 ~27 ~94 stone 6
fill ~87 ~27 ~110 ~90 ~27 ~110 stone 6
fill ~87 ~27 ~111 ~87 ~30 ~111 stone 6
fill ~87 ~27 ~112 ~87 ~30 ~112 stone 6
fill ~87 ~27 ~113 ~87 ~30 ~113 stone 6
fill ~89 ~27 ~92 ~89 ~28 ~92 stone 6
fill ~89 ~27 ~112 ~89 ~28 ~112 stone 6
fill ~93 ~27 ~93 ~97 ~27 ~93 stone 6
fill ~93 ~27 ~111 ~97 ~27 ~111 stone 6
fill ~94 ~27 ~94 ~97 ~27 ~94 stone 6
fill ~94 ~27 ~110 ~97 ~27 ~110 stone 6
fill ~95 ~27 ~92 ~97 ~27 ~92 stone 6
setblock ~95 ~27 ~95 stone 6
setblock ~95 ~27 ~109 stone 6
fill ~95 ~27 ~112 ~97 ~27 ~112 stone 6
fill ~14 ~28 ~92 ~15 ~28 ~92 stained_hardened_clay 10
fill ~14 ~28 ~112 ~15 ~28 ~112 stained_hardened_clay 10
fill ~15 ~28 ~93 ~17 ~28 ~93 stained_hardened_clay 10
fill ~15 ~28 ~111 ~17 ~28 ~111 stained_hardened_clay 10
fill ~21 ~28 ~93 ~22 ~28 ~93 stained_hardened_clay 10
fill ~21 ~28 ~111 ~22 ~28 ~111 stained_hardened_clay 10
fill ~22 ~28 ~92 ~23 ~28 ~92 stained_hardened_clay 10
fill ~22 ~28 ~112 ~23 ~28 ~112 stained_hardened_clay 10
fill ~27 ~28 ~92 ~31 ~28 ~92 stained_hardened_clay 10
fill ~27 ~28 ~112 ~31 ~28 ~112 stained_hardened_clay 10
fill ~31 ~28 ~93 ~35 ~28 ~93 stained_hardened_clay 10
fill ~31 ~28 ~111 ~35 ~28 ~111 stained_hardened_clay 10
fill ~38 ~28 ~92 ~38 ~29 ~92 stained_hardened_clay 10
fill ~38 ~28 ~93 ~38 ~28 ~92 stained_hardened_clay 10
fill ~38 ~28 ~111 ~38 ~28 ~112 stained_hardened_clay 10
fill ~44 ~28 ~94 ~45 ~28 ~94 stained_hardened_clay 10
fill ~44 ~28 ~110 ~45 ~28 ~110 stained_hardened_clay 10
setblock ~45 ~28 ~93 stained_hardened_clay 10
setblock ~45 ~28 ~111 stained_hardened_clay 10
fill ~46 ~28 ~92 ~47 ~28 ~92 stained_hardened_clay 10
fill ~46 ~28 ~112 ~47 ~28 ~112 stained_hardened_clay 10
fill ~51 ~28 ~92 ~52 ~28 ~92 stained_hardened_clay 10
fill ~51 ~28 ~112 ~52 ~28 ~112 stained_hardened_clay 10
fill ~53 ~28 ~92 ~55 ~28 ~92 stained_hardened_clay 0
fill ~53 ~28 ~112 ~55 ~28 ~112 stained_hardened_clay 0
fill ~54 ~28 ~91 ~58 ~28 ~91 stained_hardened_clay 0
fill ~54 ~28 ~113 ~58 ~28 ~113 stained_hardened_clay 0
fill ~56 ~28 ~92 ~57 ~28 ~92 stained_hardened_clay 10
fill ~56 ~28 ~93 ~61 ~28 ~93 stained_hardened_clay 10
fill ~56 ~28 ~112 ~57 ~28 ~112 stained_hardened_clay 10
fill ~57 ~28 ~111 ~61 ~28 ~111 stained_hardened_clay 10
fill ~58 ~28 ~92 ~58 ~31 ~92 stained_hardened_clay 0
fill ~58 ~28 ~112 ~58 ~31 ~112 stained_hardened_clay 0
fill ~65 ~28 ~92 ~66 ~28 ~92 stained_hardened_clay 10
fill ~65 ~28 ~112 ~66 ~28 ~112 stained_hardened_clay 10
setblock ~66 ~28 ~93 stained_hardened_clay 10
setblock ~66 ~28 ~111 stained_hardened_clay 10
fill ~69 ~28 ~91 ~70 ~28 ~91 stained_hardened_clay 10
fill ~69 ~28 ~92 ~69 ~28 ~91 stained_hardened_clay 10
fill ~69 ~28 ~112 ~69 ~28 ~113 stained_hardened_clay 10
fill ~70 ~28 ~113 ~70 ~30 ~113 stained_hardened_clay 10
fill ~74 ~28 ~92 ~74 ~29 ~92 stained_hardened_clay 10
fill ~74 ~28 ~93 ~74 ~28 ~92 stained_hardened_clay 10
fill ~74 ~28 ~111 ~74 ~28 ~112 stained_hardened_clay 10
fill ~79 ~28 ~92 ~79 ~29 ~92 stained_hardened_clay 10
fill ~79 ~28 ~112 ~79 ~29 ~112 stained_hardened_clay 10
fill ~84 ~28 ~92 ~84 ~29 ~92 stained_hardened_clay 10
fill ~84 ~28 ~112 ~84 ~29 ~112 stained_hardened_clay 10
fill ~85 ~28 ~92 ~89 ~28 ~92 stone 6
setblock ~85 ~28 ~93 stained_hardened_clay 10
setblock ~85 ~28 ~111 stained_hardened_clay 10
fill ~85 ~28 ~112 ~89 ~28 ~112 stone 6
fill ~86 ~28 ~91 ~86 ~31 ~91 stone 6
fill ~86 ~28 ~93 ~86 ~30 ~93 stone 6
fill ~86 ~28 ~111 ~86 ~30 ~111 stone 6
fill ~86 ~28 ~113 ~86 ~31 ~113 stone 6
fill ~87 ~28 ~94 ~88 ~28 ~94 stone 6
fill ~87 ~28 ~110 ~88 ~28 ~110 stone 6
setblock ~88 ~28 ~91 stone 6
setblock ~88 ~28 ~113 stone 6
fill ~94 ~28 ~92 ~98 ~28 ~92 stone 6
fill ~94 ~28 ~93 ~98 ~28 ~93 stone 6
fill ~94 ~28 ~111 ~98 ~28 ~111 stone 6
fill ~94 ~28 ~112 ~98 ~28 ~112 stone 6
fill ~95 ~28 ~94 ~97 ~28 ~94 stone 6
fill ~95 ~28 ~110 ~97 ~28 ~110 stone 6
fill ~96 ~28 ~91 ~97 ~28 ~91 stone 6
fill ~96 ~28 ~113 ~97 ~28 ~113 stone 6
fill ~14 ~29 ~92 ~15 ~29 ~92 stained_hardened_clay 10
fill ~14 ~29 ~112 ~15 ~29 ~112 stained_hardened_clay 10
fill ~23 ~29 ~92 ~23 ~31 ~92 stained_hardened_clay 10
fill ~23 ~29 ~112 ~23 ~31 ~112 stained_hardened_clay 10
fill ~30 ~29 ~92 ~31 ~29 ~92 stained_hardened_clay 10
fill ~30 ~29 ~112 ~31 ~29 ~112 stained_hardened_clay 10
fill ~38 ~29 ~112 ~39 ~29 ~112 stained_hardened_clay 10
setblock ~39 ~29 ~92 stained_hardened_clay 10
fill ~45 ~29 ~92 ~46 ~29 ~92 stained_hardened_clay 10
fill ~45 ~29 ~112 ~46 ~29 ~112 stained_hardened_clay 10
fill ~52 ~29 ~91 ~60 ~29 ~91 stained_hardened_clay 0
setblock ~52 ~29 ~92 stained_hardened_clay 10
setblock ~52 ~29 ~112 stained_hardened_clay 10
fill ~52 ~29 ~113 ~60 ~29 ~113 stained_hardened_clay 0
fill ~53 ~29 ~92 ~55 ~29 ~92 stained_hardened_clay 0
fill ~53 ~29 ~112 ~55 ~29 ~112 stained_hardened_clay 0
fill ~54 ~29 ~93 ~58 ~29 ~93 stained_hardened_clay 0
fill ~54 ~29 ~111 ~58 ~29 ~111 stained_hardened_clay 0
fill ~56 ~29 ~92 ~57 ~29 ~92 stained_hardened_clay 10
fill ~56 ~29 ~112 ~57 ~29 ~112 stained_hardened_clay 10
fill ~65 ~29 ~91 ~65 ~31 ~91 stained_hardened_clay 10
fill ~65 ~29 ~92 ~65 ~28 ~92 stained_hardened_clay 10
fill ~65 ~29 ~112 ~65 ~28 ~112 stained_hardened_clay 10
fill ~65 ~29 ~113 ~65 ~31 ~113 stained_hardened_clay 10
fill ~70 ~29 ~91 ~70 ~30 ~91 stained_hardened_clay 10
setblock ~74 ~29 ~112 stained_hardened_clay 10
setblock ~78 ~29 ~92 stained_hardened_clay 10
setblock ~78 ~29 ~112 stained_hardened_clay 10
fill ~83 ~29 ~91 ~83 ~30 ~91 stained_hardened_clay 10
fill ~83 ~29 ~113 ~83 ~30 ~113 stained_hardened_clay 10
fill ~85 ~29 ~90 ~85 ~31 ~90 stone 6
fill ~85 ~29 ~91 ~85 ~32 ~91 stone 6
fill ~85 ~29 ~92 ~88 ~29 ~92 stone 6
fill ~85 ~29 ~112 ~88 ~29 ~112 stone 6
fill ~85 ~29 ~113 ~85 ~32 ~113 stone 6
fill ~85 ~29 ~114 ~85 ~31 ~114 stone 6
fill ~94 ~29 ~92 ~98 ~29 ~92 stone 6
fill ~94 ~29 ~112 ~98 ~29 ~112 stone 6
fill ~95 ~29 ~91 ~98 ~29 ~91 stone 6
fill ~95 ~29 ~93 ~98 ~29 ~93 stone 6
fill ~95 ~29 ~111 ~98 ~29 ~111 stone 6
fill ~95 ~29 ~113 ~98 ~29 ~113 stone 6
setblock ~96 ~29 ~94 stone 6
setblock ~96 ~29 ~110 stone 6
fill ~115 ~29 ~101 ~115 ~32 ~101 stained_glass_pane 7
fill ~115 ~29 ~103 ~115 ~32 ~103 stained_glass_pane 7
fill ~13 ~30 ~91 ~13 ~33 ~91 stained_hardened_clay 10
fill ~13 ~30 ~92 ~14 ~30 ~92 stained_hardened_clay 10
fill ~13 ~30 ~112 ~14 ~30 ~112 stained_hardened_clay 10
fill ~13 ~30 ~113 ~13 ~33 ~113 stained_hardened_clay 10
fill ~18 ~30 ~91 ~18 ~31 ~91 stained_hardened_clay 10
fill ~18 ~30 ~113 ~18 ~31 ~113 stained_hardened_clay 10
fill ~23 ~30 ~91 ~23 ~31 ~91 stained_hardened_clay 10
fill ~23 ~30 ~113 ~23 ~31 ~113 stained_hardened_clay 10
fill ~31 ~30 ~91 ~32 ~30 ~91 stained_hardened_clay 10
fill ~31 ~30 ~113 ~32 ~30 ~113 stained_hardened_clay 10
fill ~39 ~30 ~91 ~40 ~30 ~91 stained_hardened_clay 10
fill ~39 ~30 ~113 ~40 ~30 ~113 stained_hardened_clay 10
fill ~44 ~30 ~91 ~45 ~30 ~91 stained_hardened_clay 10
fill ~44 ~30 ~113 ~45 ~30 ~113 stained_hardened_clay 10
fill ~51 ~30 ~90 ~61 ~30 ~90 stained_hardened_clay 0
fill ~51 ~30 ~91 ~61 ~30 ~91 stained_hardened_clay 0
fill ~51 ~30 ~113 ~61 ~30 ~113 stained_hardened_clay 0
fill ~51 ~30 ~114 ~61 ~30 ~114 stained_hardened_clay 0
fill ~52 ~30 ~92 ~60 ~30 ~92 stained_hardened_clay 0
fill ~52 ~30 ~93 ~60 ~30 ~93 stained_hardened_clay 0
fill ~52 ~30 ~111 ~60 ~30 ~111 stained_hardened_clay 0
fill ~52 ~30 ~112 ~60 ~30 ~112 stained_hardened_clay 0
fill ~65 ~30 ~90 ~65 ~31 ~90 stained_hardened_clay 10
fill ~65 ~30 ~114 ~65 ~31 ~114 stained_hardened_clay 10
setblock ~70 ~30 ~90 stained_hardened_clay 10
setblock ~70 ~30 ~114 stained_hardened_clay 10
fill ~73 ~30 ~91 ~73 ~31 ~91 stained_hardened_clay 10
fill ~73 ~30 ~113 ~73 ~31 ~113 stained_hardened_clay 10
setblock ~78 ~30 ~91 stained_hardened_clay 10
setblock ~78 ~30 ~113 stained_hardened_clay 10
fill ~81 ~30 ~90 ~82 ~30 ~90 stained_hardened_clay 10
fill ~81 ~30 ~91 ~83 ~30 ~91 stained_hardened_clay 10
fill ~81 ~30 ~113 ~83 ~30 ~113 stained_hardened_clay 10
fill ~81 ~30 ~114 ~82 ~30 ~114 stained_hardened_clay 10
fill ~84 ~30 ~90 ~84 ~32 ~90 stone 6
fill ~84 ~30 ~91 ~84 ~33 ~91 stone 6
fill ~84 ~30 ~113 ~84 ~33 ~113 stone 6
fill ~84 ~30 ~114 ~84 ~32 ~114 stone 6
fill ~85 ~30 ~92 ~87 ~30 ~92 stone 6
fill ~85 ~30 ~93 ~85 ~30 ~90 stone 6
fill ~85 ~30 ~111 ~85 ~30 ~114 stone 6
setblock ~86 ~30 ~90 stone 6
fill ~86 ~30 ~112 ~86 ~31 ~112 stone 6
setblock ~86 ~30 ~114 stone 6
fill ~95 ~30 ~91 ~99 ~30 ~91 stone 6
fill ~95 ~30 ~92 ~98 ~30 ~92 stone 6
fill ~95 ~30 ~93 ~98 ~30 ~93 stone 6
fill ~95 ~30 ~111 ~98 ~30 ~111 stone 6
fill ~95 ~30 ~112 ~98 ~30 ~112 stone 6
fill ~95 ~30 ~113 ~99 ~30 ~113 stone 6
fill ~97 ~30 ~90 ~98 ~30 ~90 stone 6
fill ~97 ~30 ~114 ~98 ~30 ~114 stone 6
fill ~12 ~31 ~91 ~12 ~32 ~91 stained_hardened_clay 10
fill ~12 ~31 ~113 ~12 ~32 ~113 stained_hardened_clay 10
fill ~13 ~31 ~92 ~13 ~30 ~92 stained_hardened_clay 10
fill ~13 ~31 ~112 ~13 ~30 ~112 stained_hardened_clay 10
fill ~19 ~31 ~91 ~19 ~32 ~91 stained_hardened_clay 10
fill ~19 ~31 ~113 ~19 ~32 ~113 stained_hardened_clay 10
fill ~22 ~31 ~90 ~22 ~32 ~90 stained_hardened_clay 10
fill ~22 ~31 ~91 ~22 ~31 ~90 stained_hardened_clay 10
fill ~22 ~31 ~113 ~22 ~31 ~114 stained_hardened_clay 10
setblock ~32 ~31 ~91 stained_hardened_clay 10
setblock ~32 ~31 ~113 stained_hardened_clay 10
fill ~40 ~31 ~91 ~44 ~31 ~91 stained_hardened_clay 10
fill ~40 ~31 ~113 ~44 ~31 ~113 stained_hardened_clay 10
fill ~50 ~31 ~90 ~62 ~31 ~90 stained_hardened_clay 0
fill ~50 ~31 ~91 ~62 ~31 ~91 stained_hardened_clay 0
fill ~50 ~31 ~113 ~62 ~31 ~113 stained_hardened_clay 0
fill ~50 ~31 ~114 ~62 ~31 ~114 stained_hardened_clay 0
fill ~51 ~31 ~92 ~61 ~31 ~92 stained_hardened_clay 0
fill ~51 ~31 ~112 ~61 ~31 ~112 stained_hardened_clay 0
fill ~66 ~31 ~90 ~66 ~32 ~90 stained_hardened_clay 10
fill ~66 ~31 ~114 ~66 ~32 ~114 stained_hardened_clay 10
fill ~78 ~31 ~90 ~80 ~31 ~90 stained_hardened_clay 10
fill ~78 ~31 ~114 ~80 ~31 ~114 stained_hardened_clay 10
fill ~81 ~31 ~91 ~81 ~30 ~91 stained_hardened_clay 10
fill ~81 ~31 ~113 ~81 ~30 ~113 stained_hardened_clay 10
fill ~82 ~31 ~91 ~86 ~31 ~91 stone 6
fill ~82 ~31 ~113 ~86 ~31 ~113 stone 6
fill ~83 ~31 ~90 ~83 ~33 ~90 stone 6
fill ~83 ~31 ~92 ~86 ~31 ~92 stone 6
fill ~83 ~31 ~112 ~86 ~31 ~112 stone 6
fill ~83 ~31 ~114 ~83 ~33 ~114 stone 6
fill ~85 ~31 ~88 ~90 ~31 ~88 lapis_block 0
fill ~85 ~31 ~89 ~90 ~31 ~89 lapis_block 0
fill ~85 ~31 ~115 ~90 ~31 ~115 lapis_block 0
fill ~85 ~31 ~116 ~90 ~31 ~116 lapis_block 0
fill ~95 ~31 ~91 ~99 ~31 ~91 stone 6
fill ~95 ~31 ~113 ~99 ~31 ~113 stone 6
fill ~96 ~31 ~90 ~98 ~31 ~90 stone 6
fill ~96 ~31 ~92 ~99 ~31 ~92 stone 6
fill ~96 ~31 ~93 ~97 ~31 ~93 stone 6
fill ~96 ~31 ~111 ~97 ~31 ~111 stone 6
fill ~96 ~31 ~112 ~99 ~31 ~112 stone 6
fill ~96 ~31 ~114 ~98 ~31 ~114 stone 6
fill ~114 ~31 ~100 ~114 ~33 ~100 stained_glass_pane 7
fill ~114 ~31 ~104 ~114 ~33 ~104 stained_glass_pane 7
fill ~9 ~32 ~91 ~13 ~32 ~91 stained_hardened_clay 10
fill ~9 ~32 ~113 ~13 ~32 ~113 stained_hardened_clay 10
fill ~13 ~32 ~90 ~13 ~33 ~90 stained_hardened_clay 10
fill ~13 ~32 ~114 ~13 ~33 ~114 stained_hardened_clay 10
fill ~19 ~32 ~90 ~22 ~32 ~90 stained_hardened_clay 10
fill ~19 ~32 ~114 ~22 ~32 ~114 stained_hardened_clay 10
fill ~32 ~32 ~90 ~33 ~32 ~90 stained_hardened_clay 10
fill ~32 ~32 ~114 ~33 ~32 ~114 stained_hardened_clay 10
fill ~38 ~32 ~90 ~41 ~32 ~90 stained_hardened_clay 10
fill ~38 ~32 ~114 ~41 ~32 ~114 stained_hardened_clay 10
fill ~49 ~32 ~89 ~55 ~32 ~89 stained_hardened_clay 0
fill ~49 ~32 ~115 ~55 ~32 ~115 stained_hardened_clay 0
fill ~50 ~32 ~90 ~56 ~32 ~90 stained_hardened_clay 0
fill ~50 ~32 ~91 ~56 ~32 ~91 stained_hardened_clay 0
fill ~50 ~32 ~113 ~56 ~32 ~113 stained_hardened_clay 0
fill ~50 ~32 ~114 ~56 ~32 ~114 stained_hardened_clay 0
fill ~60 ~32 ~90 ~62 ~32 ~90 stained_hardened_clay 0
fill ~60 ~32 ~91 ~62 ~32 ~91 stained_hardened_clay 0
fill ~60 ~32 ~113 ~62 ~32 ~113 stained_hardened_clay 0
fill ~60 ~32 ~114 ~62 ~32 ~114 stained_hardened_clay 0
fill ~61 ~32 ~89 ~63 ~32 ~89 stained_hardened_clay 0
fill ~61 ~32 ~115 ~63 ~32 ~115 stained_hardened_clay 0
fill ~67 ~32 ~89 ~68 ~32 ~89 stained_hardened_clay 10
fill ~67 ~32 ~90 ~67 ~32 ~89 stained_hardened_clay 10
fill ~67 ~32 ~114 ~67 ~32 ~115 stained_hardened_clay 10
fill ~68 ~32 ~115 ~68 ~33 ~115 stained_hardened_clay 10
setblock ~73 ~32 ~90 stained_hardened_clay 10
setblock ~73 ~32 ~114 stained_hardened_clay 10
fill ~75 ~32 ~90 ~78 ~32 ~90 stained_hardened_clay 10
fill ~75 ~32 ~114 ~78 ~32 ~114 stained_hardened_clay 10
fill ~81 ~32 ~88 ~82 ~32 ~88 stone 6
fill ~81 ~32 ~89 ~83 ~32 ~89 stone 6
fill ~81 ~32 ~90 ~84 ~32 ~90 stone 6
fill ~81 ~32 ~114 ~84 ~32 ~114 stone 6
fill ~81 ~32 ~115 ~83 ~32 ~115 stone 6
fill ~81 ~32 ~116 ~82 ~32 ~116 stone 6
fill ~82 ~32 ~91 ~85 ~32 ~91 stone 6
fill ~82 ~32 ~113 ~85 ~32 ~113 stone 6
fill ~83 ~32 ~92 ~84 ~32 ~92 stone 6
fill ~83 ~32 ~112 ~84 ~32 ~112 stone 6
fill ~84 ~32 ~87 ~84 ~33 ~87 lapis_block 0
fill ~84 ~32 ~88 ~85 ~32 ~88 lapis_block 0
fill ~84 ~32 ~89 ~84 ~33 ~89 lapis_block 0
fill ~84 ~32 ~115 ~84 ~33 ~115 lapis_block 0
fill ~84 ~32 ~116 ~85 ~32 ~116 lapis_block 0
fill ~84 ~32 ~117 ~84 ~33 ~117 lapis_block 0
fill ~85 ~32 ~89 ~89 ~32 ~89 planks 1
fill ~85 ~32 ~90 ~90 ~32 ~90 lapis_block 0
fill ~85 ~32 ~114 ~90 ~32 ~114 lapis_block 0
fill ~85 ~32 ~115 ~89 ~32 ~115 planks 1
fill ~90 ~32 ~88 ~92 ~32 ~88 lapis_block 0
fill ~90 ~32 ~89 ~92 ~32 ~89 lapis_block 0
fill ~90 ~32 ~115 ~92 ~32 ~115 lapis_block 0
fill ~90 ~32 ~116 ~92 ~32 ~116 lapis_block 0
fill ~95 ~32 ~90 ~99 ~32 ~90 stone 6
fill ~95 ~32 ~114 ~99 ~32 ~114 stone 6
fill ~96 ~32 ~91 ~99 ~32 ~91 stone 6
fill ~96 ~32 ~113 ~99 ~32 ~113 stone 6
fill ~97 ~32 ~89 ~99 ~32 ~89 stone 6
fill ~97 ~32 ~92 ~98 ~32 ~92 stone 6
fill ~97 ~32 ~112 ~98 ~32 ~112 stone 6
fill ~97 ~32 ~115 ~99 ~32 ~115 stone 6
fill ~115 ~32 ~100 ~115 ~38 ~100 stained_glass_pane 7
fill ~115 ~32 ~104 ~115 ~38 ~104 stained_glass_pane 7
fill ~7 ~33 ~91 ~9 ~33 ~91 stained_hardened_clay 10
fill ~7 ~33 ~113 ~9 ~33 ~113 stained_hardened_clay 10
fill ~14 ~33 ~90 ~14 ~34 ~90 stained_hardened_clay 10
fill ~14 ~33 ~114 ~14 ~34 ~114 stained_hardened_clay 10 
setblock ~33 ~33 ~90 stained_hardened_clay 10 
setblock ~33 ~33 ~114 stained_hardened_clay 10
fill ~35 ~33 ~90 ~39 ~33 ~90 stained_hardened_clay 10
fill ~35 ~33 ~114 ~39 ~33 ~114 stained_hardened_clay 10
fill ~49 ~33 ~88 ~54 ~33 ~88 stained_hardened_clay 0
fill ~49 ~33 ~89 ~55 ~33 ~89 stained_hardened_clay 0
fill ~49 ~33 ~90 ~51 ~33 ~90 stained_hardened_clay 0
fill ~49 ~33 ~114 ~51 ~33 ~114 stained_hardened_clay 0
fill ~49 ~33 ~115 ~55 ~33 ~115 stained_hardened_clay 0
fill ~49 ~33 ~116 ~54 ~33 ~116 stained_hardened_clay 0
fill ~50 ~33 ~91 ~56 ~33 ~91 stained_hardened_clay 0
fill ~50 ~33 ~113 ~56 ~33 ~113 stained_hardened_clay 0 
setblock ~52 ~33 ~90 gold_block 0 
setblock ~52 ~33 ~114 gold_block 0
fill ~53 ~33 ~90 ~55 ~33 ~90 stained_hardened_clay 0
fill ~53 ~33 ~114 ~55 ~33 ~114 stained_hardened_clay 0
fill ~60 ~33 ~91 ~62 ~33 ~91 stained_hardened_clay 0
fill ~60 ~33 ~113 ~62 ~33 ~113 stained_hardened_clay 0
fill ~61 ~33 ~89 ~63 ~33 ~89 stained_hardened_clay 0
fill ~61 ~33 ~90 ~63 ~33 ~90 stained_hardened_clay 0
fill ~61 ~33 ~114 ~63 ~33 ~114 stained_hardened_clay 0
fill ~61 ~33 ~115 ~63 ~33 ~115 stained_hardened_clay 0
fill ~62 ~33 ~88 ~63 ~33 ~88 stained_hardened_clay 0
fill ~62 ~33 ~116 ~63 ~33 ~116 stained_hardened_clay 0
fill ~68 ~33 ~89 ~69 ~33 ~89 stained_hardened_clay 10
fill ~68 ~33 ~90 ~68 ~33 ~89 stained_hardened_clay 10
setblock ~68 ~33 ~114 stained_hardened_clay 10
fill ~69 ~33 ~88 ~72 ~33 ~88 stained_hardened_clay 10
fill ~69 ~33 ~115 ~69 ~33 ~116 stained_hardened_clay 10
fill ~70 ~33 ~116 ~72 ~33 ~116 stained_hardened_clay 10
fill ~72 ~33 ~89 ~75 ~33 ~89 stained_hardened_clay 10
fill ~72 ~33 ~115 ~75 ~33 ~115 stained_hardened_clay 10
fill ~79 ~33 ~88 ~83 ~33 ~88 stone 6
fill ~79 ~33 ~116 ~83 ~33 ~116 stone 6
fill ~80 ~33 ~90 ~83 ~33 ~90 stone 6
fill ~80 ~33 ~114 ~83 ~33 ~114 stone 6
fill ~81 ~33 ~89 ~83 ~33 ~89 stone 6
fill ~81 ~33 ~115 ~83 ~33 ~115 stone 6
fill ~82 ~33 ~87 ~84 ~33 ~87 lapis_block 0
fill ~82 ~33 ~91 ~84 ~33 ~91 stone 6
fill ~82 ~33 ~113 ~84 ~33 ~113 stone 6
fill ~82 ~33 ~117 ~84 ~33 ~117 lapis_block 0
fill ~84 ~33 ~88 ~87 ~33 ~88 planks 1
fill ~84 ~33 ~90 ~86 ~33 ~90 lapis_block 0
fill ~84 ~33 ~114 ~86 ~33 ~114 lapis_block 0
fill ~84 ~33 ~116 ~87 ~33 ~116 planks 1
fill ~85 ~33 ~89 ~89 ~33 ~89 planks 1
fill ~85 ~33 ~115 ~89 ~33 ~115 planks 1
fill ~89 ~33 ~88 ~91 ~33 ~88 planks 1
fill ~89 ~33 ~116 ~91 ~33 ~116 planks 1
fill ~90 ~33 ~89 ~92 ~33 ~89 lapis_block 0
fill ~90 ~33 ~90 ~92 ~33 ~90 lapis_block 0
fill ~90 ~33 ~114 ~92 ~33 ~114 lapis_block 0
fill ~90 ~33 ~115 ~92 ~33 ~115 lapis_block 0
fill ~92 ~33 ~87 ~94 ~33 ~87 lapis_block 0
fill ~92 ~33 ~88 ~94 ~33 ~88 lapis_block 0
fill ~92 ~33 ~116 ~94 ~33 ~116 lapis_block 0
fill ~92 ~33 ~117 ~94 ~33 ~117 lapis_block 0
fill ~96 ~33 ~90 ~100 ~33 ~90 stone 6
fill ~96 ~33 ~91 ~99 ~33 ~91 stone 6
fill ~96 ~33 ~113 ~99 ~33 ~113 stone 6
fill ~96 ~33 ~114 ~100 ~33 ~114 stone 6
fill ~97 ~33 ~89 ~99 ~33 ~89 stone 6
fill ~97 ~33 ~115 ~99 ~33 ~115 stone 6
fill ~98 ~33 ~88 ~99 ~33 ~88 stone 6
fill ~98 ~33 ~116 ~99 ~33 ~116 stone 6
fill ~5 ~34 ~90 ~7 ~34 ~90 stained_hardened_clay 10
fill ~5 ~34 ~114 ~7 ~34 ~114 stained_hardened_clay 10
fill ~7 ~34 ~91 ~7 ~33 ~91 stained_hardened_clay 10
fill ~7 ~34 ~113 ~7 ~33 ~113 stained_hardened_clay 10
fill ~14 ~34 ~89 ~16 ~34 ~89 stained_hardened_clay 10
fill ~14 ~34 ~115 ~16 ~34 ~115 stained_hardened_clay 10
fill ~15 ~34 ~90 ~16 ~34 ~90 stained_hardened_clay 10
fill ~15 ~34 ~114 ~16 ~34 ~114 stained_hardened_clay 10
fill ~31 ~34 ~89 ~37 ~34 ~89 stained_hardened_clay 10
fill ~31 ~34 ~115 ~37 ~34 ~115 stained_hardened_clay 10
fill ~39 ~34 ~89 ~40 ~34 ~89 stained_hardened_clay 10
fill ~39 ~34 ~115 ~40 ~34 ~115 stained_hardened_clay 10
fill ~49 ~34 ~88 ~54 ~34 ~88 stained_hardened_clay 0
fill ~49 ~34 ~89 ~54 ~34 ~89 stained_hardened_clay 0
fill ~49 ~34 ~90 ~54 ~34 ~90 stained_hardened_clay 0
fill ~49 ~34 ~114 ~54 ~34 ~114 stained_hardened_clay 0
fill ~49 ~34 ~115 ~54 ~34 ~115 stained_hardened_clay 0
fill ~49 ~34 ~116 ~54 ~34 ~116 stained_hardened_clay 0
fill ~62 ~34 ~88 ~63 ~34 ~88 stained_hardened_clay 0
fill ~62 ~34 ~89 ~63 ~34 ~89 stained_hardened_clay 0
fill ~62 ~34 ~90 ~63 ~34 ~90 stained_hardened_clay 0
fill ~62 ~34 ~114 ~63 ~34 ~114 stained_hardened_clay 0
fill ~62 ~34 ~115 ~63 ~34 ~115 stained_hardened_clay 0
fill ~62 ~34 ~116 ~63 ~34 ~116 stained_hardened_clay 0
fill ~77 ~34 ~87 ~78 ~34 ~87 stone 6
fill ~77 ~34 ~88 ~81 ~34 ~88 stone 6
fill ~77 ~34 ~116 ~81 ~34 ~116 stone 6
fill ~77 ~34 ~117 ~78 ~34 ~117 stone 6
fill ~78 ~34 ~89 ~82 ~34 ~89 stone 6
fill ~78 ~34 ~115 ~82 ~34 ~115 stone 6
fill ~79 ~34 ~90 ~82 ~34 ~90 stone 6
fill ~79 ~34 ~114 ~82 ~34 ~114 stone 6
fill ~81 ~34 ~86 ~82 ~34 ~86 lapis_block 0
fill ~81 ~34 ~87 ~82 ~34 ~87 lapis_block 0
fill ~81 ~34 ~117 ~82 ~34 ~117 lapis_block 0
fill ~81 ~34 ~118 ~82 ~34 ~118 lapis_block 0
setblock ~82 ~34 ~88 lapis_block 0
setblock ~82 ~34 ~116 lapis_block 0
setblock ~83 ~34 ~88 planks 1
fill ~83 ~34 ~89 ~83 ~34 ~90 lapis_block 0
fill ~83 ~34 ~114 ~83 ~34 ~115 lapis_block 0
setblock ~83 ~34 ~116 planks 1
fill ~85 ~34 ~88 ~86 ~34 ~88 planks 1
fill ~85 ~34 ~116 ~86 ~34 ~116 planks 1
fill ~90 ~34 ~88 ~91 ~34 ~88 planks 1
fill ~90 ~34 ~116 ~91 ~34 ~116 planks 1
fill ~92 ~34 ~89 ~94 ~34 ~89 lapis_block 0
fill ~92 ~34 ~115 ~94 ~34 ~115 lapis_block 0
setblock ~93 ~34 ~88 planks 1
setblock ~93 ~34 ~116 planks 1
fill ~94 ~34 ~87 ~94 ~35 ~87 lapis_block 0
fill ~94 ~34 ~88 ~94 ~36 ~88 lapis_block 0
fill ~94 ~34 ~116 ~94 ~36 ~116 lapis_block 0
fill ~94 ~34 ~117 ~94 ~35 ~117 lapis_block 0
fill ~96 ~34 ~89 ~100 ~34 ~89 stone 6
fill ~96 ~34 ~115 ~100 ~34 ~115 stone 6
fill ~97 ~34 ~88 ~99 ~34 ~88 stone 6
fill ~97 ~34 ~90 ~100 ~34 ~90 stone 6
fill ~97 ~34 ~91 ~98 ~34 ~91 stone 6
fill ~97 ~34 ~113 ~98 ~34 ~113 stone 6
fill ~97 ~34 ~114 ~100 ~34 ~114 stone 6
fill ~97 ~34 ~116 ~99 ~34 ~116 stone 6
fill ~116 ~34 ~100 ~116 ~40 ~100 stained_glass_pane 7
fill ~116 ~34 ~104 ~116 ~40 ~104 stained_glass_pane 7
fill ~3 ~35 ~90 ~5 ~35 ~90 stained_hardened_clay 10
fill ~3 ~35 ~114 ~5 ~35 ~114 stained_hardened_clay 10
fill ~16 ~35 ~89 ~18 ~35 ~89 stained_hardened_clay 10
fill ~16 ~35 ~90 ~18 ~35 ~90 stained_hardened_clay 10
fill ~16 ~35 ~114 ~18 ~35 ~114 stained_hardened_clay 10
fill ~16 ~35 ~115 ~18 ~35 ~115 stained_hardened_clay 10
fill ~18 ~35 ~88 ~22 ~35 ~88 stained_hardened_clay 10
fill ~18 ~35 ~116 ~22 ~35 ~116 stained_hardened_clay 10
fill ~27 ~35 ~88 ~29 ~35 ~88 stained_hardened_clay 10
fill ~27 ~35 ~116 ~29 ~35 ~116 stained_hardened_clay 10
fill ~29 ~35 ~89 ~31 ~35 ~89 stained_hardened_clay 10
fill ~29 ~35 ~115 ~31 ~35 ~115 stained_hardened_clay 10
fill ~34 ~35 ~88 ~34 ~36 ~88 stained_hardened_clay 10
fill ~34 ~35 ~89 ~35 ~35 ~89 stained_hardened_clay 10
fill ~34 ~35 ~115 ~35 ~35 ~115 stained_hardened_clay 10
fill ~34 ~35 ~116 ~34 ~36 ~116 stained_hardened_clay 10
fill ~40 ~35 ~89 ~41 ~35 ~89 stained_hardened_clay 10
fill ~40 ~35 ~115 ~41 ~35 ~115 stained_hardened_clay 10
fill ~41 ~35 ~88 ~41 ~36 ~88 stained_hardened_clay 10
fill ~41 ~35 ~116 ~41 ~36 ~116 stained_hardened_clay 10
fill ~49 ~35 ~87 ~54 ~35 ~87 stained_hardened_clay 0
fill ~49 ~35 ~88 ~54 ~35 ~88 stained_hardened_clay 0
fill ~49 ~35 ~89 ~54 ~35 ~89 stained_hardened_clay 0
fill ~49 ~35 ~90 ~54 ~35 ~90 stained_hardened_clay 0
fill ~49 ~35 ~114 ~54 ~35 ~114 stained_hardened_clay 0
fill ~49 ~35 ~115 ~54 ~35 ~115 stained_hardened_clay 0
fill ~49 ~35 ~116 ~54 ~35 ~116 stained_hardened_clay 0
fill ~49 ~35 ~117 ~54 ~35 ~117 stained_hardened_clay 0
fill ~62 ~35 ~87 ~63 ~35 ~87 stained_hardened_clay 0
fill ~62 ~35 ~88 ~63 ~35 ~88 stained_hardened_clay 0
fill ~62 ~35 ~89 ~63 ~35 ~89 stained_hardened_clay 0
fill ~62 ~35 ~90 ~63 ~35 ~90 stained_hardened_clay 0
fill ~62 ~35 ~114 ~63 ~35 ~114 stained_hardened_clay 0
fill ~62 ~35 ~115 ~63 ~35 ~115 stained_hardened_clay 0
fill ~62 ~35 ~116 ~63 ~35 ~116 stained_hardened_clay 0
fill ~62 ~35 ~117 ~63 ~35 ~117 stained_hardened_clay 0
fill ~64 ~35 ~88 ~64 ~36 ~88 stained_hardened_clay 10
fill ~64 ~35 ~116 ~64 ~36 ~116 stained_hardened_clay 10
fill ~75 ~35 ~88 ~80 ~35 ~88 stone 6
fill ~75 ~35 ~116 ~80 ~35 ~116 stone 6
fill ~76 ~35 ~87 ~79 ~35 ~87 stone 6
fill ~76 ~35 ~89 ~80 ~35 ~89 stone 6
fill ~76 ~35 ~115 ~80 ~35 ~115 stone 6
fill ~76 ~35 ~117 ~79 ~35 ~117 stone 6
fill ~77 ~35 ~90 ~81 ~35 ~90 stone 6
fill ~77 ~35 ~114 ~81 ~35 ~114 stone 6
fill ~81 ~35 ~86 ~81 ~37 ~86 lapis_block 0
fill ~81 ~35 ~87 ~81 ~37 ~87 lapis_block 0
fill ~81 ~35 ~88 ~81 ~37 ~88 lapis_block 0
fill ~81 ~35 ~89 ~82 ~35 ~89 lapis_block 0
fill ~81 ~35 ~115 ~82 ~35 ~115 lapis_block 0
fill ~81 ~35 ~116 ~81 ~37 ~116 lapis_block 0
fill ~81 ~35 ~117 ~81 ~37 ~117 lapis_block 0
fill ~81 ~35 ~118 ~81 ~37 ~118 lapis_block 0
fill ~82 ~35 ~87 ~82 ~36 ~87 planks 1
fill ~82 ~35 ~117 ~82 ~36 ~117 planks 1
fill ~86 ~35 ~87 ~87 ~35 ~87 planks 1
fill ~86 ~35 ~117 ~87 ~35 ~117 planks 1
fill ~89 ~35 ~87 ~90 ~35 ~87 planks 1
fill ~89 ~35 ~117 ~90 ~35 ~117 planks 1
setblock ~94 ~35 ~89 lapis_block 0
setblock ~94 ~35 ~115 lapis_block 0
fill ~95 ~35 ~86 ~95 ~36 ~86 lapis_block 0
fill ~95 ~35 ~87 ~95 ~35 ~88 lapis_block 0
fill ~95 ~35 ~116 ~95 ~36 ~116 lapis_block 0
fill ~95 ~35 ~117 ~95 ~35 ~118 lapis_block 0
fill ~96 ~35 ~89 ~100 ~35 ~89 stone 6
fill ~96 ~35 ~115 ~100 ~35 ~115 stone 6
fill ~97 ~35 ~88 ~100 ~35 ~88 stone 6
fill ~97 ~35 ~90 ~100 ~35 ~90 stone 6
fill ~97 ~35 ~114 ~100 ~35 ~114 stone 6
fill ~97 ~35 ~116 ~100 ~35 ~116 stone 6
fill ~98 ~35 ~87 ~100 ~35 ~87 stone 6
fill ~98 ~35 ~117 ~100 ~35 ~117 stone 6
fill ~2 ~36 ~89 ~3 ~36 ~89 stained_hardened_clay 10
fill ~2 ~36 ~115 ~3 ~36 ~115 stained_hardened_clay 10
fill ~22 ~36 ~87 ~26 ~36 ~87 stained_hardened_clay 8
fill ~22 ~36 ~88 ~22 ~36 ~89 stained_hardened_clay 10
fill ~22 ~36 ~115 ~22 ~36 ~116 stained_hardened_clay 10
fill ~22 ~36 ~117 ~26 ~36 ~117 stained_hardened_clay 8
fill ~27 ~36 ~88 ~27 ~35 ~88 stained_hardened_clay 10
fill ~27 ~36 ~116 ~27 ~35 ~116 stained_hardened_clay 10
fill ~33 ~36 ~88 ~33 ~37 ~88 stained_hardened_clay 10
fill ~33 ~36 ~116 ~33 ~37 ~116 stained_hardened_clay 10
fill ~42 ~36 ~87 ~42 ~37 ~87 stained_hardened_clay 10
fill ~42 ~36 ~117 ~42 ~37 ~117 stained_hardened_clay 10
fill ~49 ~36 ~87 ~55 ~36 ~87 stained_hardened_clay 0
fill ~49 ~36 ~88 ~54 ~36 ~88 stained_hardened_clay 0
fill ~49 ~36 ~89 ~54 ~36 ~89 stained_hardened_clay 0
fill ~49 ~36 ~115 ~54 ~36 ~115 stained_hardened_clay 0
fill ~49 ~36 ~116 ~54 ~36 ~116 stained_hardened_clay 0
fill ~49 ~36 ~117 ~55 ~36 ~117 stained_hardened_clay 0
fill ~61 ~36 ~87 ~63 ~36 ~87 stained_hardened_clay 0
fill ~61 ~36 ~117 ~63 ~36 ~117 stained_hardened_clay 0
fill ~62 ~36 ~88 ~63 ~36 ~88 stained_hardened_clay 0
fill ~62 ~36 ~89 ~63 ~36 ~89 stained_hardened_clay 0
fill ~62 ~36 ~115 ~63 ~36 ~115 stained_hardened_clay 0
fill ~62 ~36 ~116 ~63 ~36 ~116 stained_hardened_clay 0
fill ~74 ~36 ~86 ~75 ~36 ~86 stone 6
fill ~74 ~36 ~87 ~78 ~36 ~87 stone 6
fill ~74 ~36 ~117 ~78 ~36 ~117 stone 6
fill ~74 ~36 ~118 ~75 ~36 ~118 stone 6
fill ~75 ~36 ~88 ~80 ~36 ~88 stone 6
fill ~75 ~36 ~89 ~79 ~36 ~89 stone 6
fill ~75 ~36 ~115 ~79 ~36 ~115 stone 6
fill ~75 ~36 ~116 ~80 ~36 ~116 stone 6
setblock ~78 ~36 ~90 stone 6
setblock ~78 ~36 ~114 stone 6
fill ~81 ~36 ~89 ~81 ~35 ~89 lapis_block 0
fill ~81 ~36 ~115 ~81 ~35 ~115 lapis_block 0
setblock ~83 ~36 ~87 planks 1
setblock ~83 ~36 ~117 planks 1
fill ~85 ~36 ~87 ~91 ~36 ~87 planks 1
fill ~85 ~36 ~117 ~91 ~36 ~117 planks 1
fill ~87 ~36 ~86 ~89 ~36 ~86 stained_hardened_clay 2
fill ~87 ~36 ~118 ~89 ~36 ~118 stained_hardened_clay 2
fill ~93 ~36 ~87 ~95 ~36 ~87 planks 1
fill ~93 ~36 ~117 ~95 ~36 ~117 planks 1
setblock ~95 ~36 ~88 lapis_block 0
setblock ~95 ~36 ~118 lapis_block 0
fill ~97 ~36 ~87 ~100 ~36 ~87 stone 6
fill ~97 ~36 ~88 ~100 ~36 ~88 stone 6
fill ~97 ~36 ~89 ~100 ~36 ~89 stone 6
fill ~97 ~36 ~115 ~100 ~36 ~115 stone 6
fill ~97 ~36 ~116 ~100 ~36 ~116 stone 6
fill ~97 ~36 ~117 ~100 ~36 ~117 stone 6
fill ~98 ~36 ~90 ~99 ~36 ~90 stone 6
fill ~98 ~36 ~114 ~99 ~36 ~114 stone 6
fill ~1 ~37 ~88 ~1 ~38 ~88 stained_hardened_clay 10
fill ~1 ~37 ~89 ~2 ~37 ~89 stained_hardened_clay 10
fill ~1 ~37 ~115 ~2 ~37 ~115 stained_hardened_clay 10
fill ~1 ~37 ~116 ~1 ~38 ~116 stained_hardened_clay 10
fill ~20 ~37 ~86 ~22 ~37 ~86 stained_hardened_clay 8
fill ~20 ~37 ~118 ~22 ~37 ~118 stained_hardened_clay 8
fill ~22 ~37 ~88 ~26 ~37 ~88 stained_hardened_clay 8
fill ~22 ~37 ~89 ~26 ~37 ~89 stained_hardened_clay 8
fill ~22 ~37 ~115 ~26 ~37 ~115 stained_hardened_clay 8
fill ~22 ~37 ~116 ~26 ~37 ~116 stained_hardened_clay 8
fill ~24 ~37 ~87 ~24 ~38 ~87 planks 4
fill ~24 ~37 ~117 ~24 ~38 ~117 planks 4
fill ~26 ~37 ~86 ~28 ~37 ~86 stained_hardened_clay 8
fill ~26 ~37 ~118 ~28 ~37 ~118 stained_hardened_clay 8
fill ~31 ~37 ~87 ~32 ~37 ~87 stained_hardened_clay 10
fill ~31 ~37 ~117 ~32 ~37 ~117 stained_hardened_clay 10
fill ~43 ~37 ~87 ~43 ~38 ~87 stained_hardened_clay 10
fill ~43 ~37 ~117 ~43 ~38 ~117 stained_hardened_clay 10
fill ~49 ~37 ~88 ~55 ~37 ~88 stained_hardened_clay 0
fill ~49 ~37 ~89 ~55 ~37 ~89 stained_hardened_clay 0
fill ~49 ~37 ~115 ~55 ~37 ~115 stained_hardened_clay 0
fill ~49 ~37 ~116 ~55 ~37 ~116 stained_hardened_clay 0
fill ~50 ~37 ~86 ~56 ~37 ~86 stained_hardened_clay 0
fill ~50 ~37 ~87 ~56 ~37 ~87 stained_hardened_clay 0
fill ~50 ~37 ~117 ~56 ~37 ~117 stained_hardened_clay 0
fill ~50 ~37 ~118 ~56 ~37 ~118 stained_hardened_clay 0
fill ~60 ~37 ~86 ~62 ~37 ~86 stained_hardened_clay 0
fill ~60 ~37 ~87 ~62 ~37 ~87 stained_hardened_clay 0
fill ~60 ~37 ~117 ~62 ~37 ~117 stained_hardened_clay 0
fill ~60 ~37 ~118 ~62 ~37 ~118 stained_hardened_clay 0
fill ~61 ~37 ~88 ~63 ~37 ~88 stained_hardened_clay 0
fill ~61 ~37 ~89 ~63 ~37 ~89 stained_hardened_clay 0
fill ~61 ~37 ~115 ~63 ~37 ~115 stained_hardened_clay 0
fill ~61 ~37 ~116 ~63 ~37 ~116 stained_hardened_clay 0
fill ~64 ~37 ~87 ~66 ~37 ~87 stained_hardened_clay 10
fill ~64 ~37 ~117 ~66 ~37 ~117 stained_hardened_clay 10
fill ~69 ~37 ~87 ~77 ~37 ~87 stone 6
fill ~69 ~37 ~117 ~77 ~37 ~117 stone 6
fill ~71 ~37 ~86 ~76 ~37 ~86 stone 6
fill ~71 ~37 ~118 ~76 ~37 ~118 stone 6
fill ~72 ~37 ~88 ~77 ~37 ~88 stone 6
fill ~72 ~37 ~116 ~77 ~37 ~116 stone 6
fill ~74 ~37 ~89 ~77 ~37 ~89 stone 6
fill ~74 ~37 ~115 ~77 ~37 ~115 stone 6
fill ~80 ~37 ~85 ~80 ~41 ~85 lapis_block 0
fill ~80 ~37 ~86 ~80 ~40 ~86 lapis_block 0
fill ~80 ~37 ~87 ~80 ~39 ~87 lapis_block 0
fill ~80 ~37 ~117 ~80 ~39 ~117 lapis_block 0
fill ~80 ~37 ~118 ~80 ~40 ~118 lapis_block 0
fill ~80 ~37 ~119 ~80 ~41 ~119 lapis_block 0
fill ~82 ~37 ~86 ~95 ~37 ~86 planks 1
fill ~82 ~37 ~118 ~95 ~37 ~118 planks 1
fill ~86 ~37 ~85 ~90 ~37 ~85 stained_hardened_clay 2
fill ~86 ~37 ~119 ~90 ~37 ~119 stained_hardened_clay 2
fill ~87 ~37 ~87 ~89 ~37 ~87 stained_hardened_clay 2
fill ~87 ~37 ~117 ~89 ~37 ~117 stained_hardened_clay 2
fill ~95 ~37 ~87 ~96 ~37 ~87 lapis_block 0
fill ~95 ~37 ~117 ~96 ~37 ~117 lapis_block 0
fill ~96 ~37 ~85 ~96 ~41 ~85 lapis_block 0
fill ~96 ~37 ~86 ~96 ~40 ~86 lapis_block 0
fill ~96 ~37 ~118 ~96 ~40 ~118 lapis_block 0
fill ~96 ~37 ~119 ~96 ~41 ~119 lapis_block 0
fill ~97 ~37 ~87 ~101 ~37 ~87 stone 6
fill ~97 ~37 ~117 ~101 ~37 ~117 stone 6
fill ~98 ~37 ~88 ~101 ~37 ~88 stone 6
fill ~98 ~37 ~89 ~100 ~37 ~89 stone 6
fill ~98 ~37 ~115 ~100 ~37 ~115 stone 6
fill ~98 ~37 ~116 ~101 ~37 ~116 stone 6
fill ~99 ~37 ~86 ~100 ~37 ~86 stone 6
fill ~99 ~37 ~118 ~100 ~37 ~118 stone 6
fill ~19 ~38 ~86 ~20 ~38 ~86 stained_hardened_clay 8
fill ~19 ~38 ~118 ~20 ~38 ~118 stained_hardened_clay 8
fill ~20 ~38 ~88 ~22 ~38 ~88 stained_hardened_clay 8
fill ~20 ~38 ~116 ~22 ~38 ~116 stained_hardened_clay 8
fill ~26 ~38 ~88 ~28 ~38 ~88 stained_hardened_clay 8
fill ~26 ~38 ~116 ~28 ~38 ~116 stained_hardened_clay 8
fill ~28 ~38 ~86 ~29 ~38 ~86 stained_hardened_clay 8
fill ~28 ~38 ~118 ~29 ~38 ~118 stained_hardened_clay 8
fill ~31 ~38 ~87 ~31 ~37 ~87 stained_hardened_clay 10
fill ~31 ~38 ~117 ~31 ~37 ~117 stained_hardened_clay 10
setblock ~44 ~38 ~87 stained_hardened_clay 10
setblock ~44 ~38 ~117 stained_hardened_clay 10
fill ~50 ~38 ~86 ~62 ~38 ~86 stained_hardened_clay 0
fill ~50 ~38 ~87 ~62 ~38 ~87 stained_hardened_clay 0
fill ~50 ~38 ~88 ~56 ~38 ~88 stained_hardened_clay 0
fill ~50 ~38 ~116 ~56 ~38 ~116 stained_hardened_clay 0
fill ~50 ~38 ~117 ~62 ~38 ~117 stained_hardened_clay 0
fill ~50 ~38 ~118 ~62 ~38 ~118 stained_hardened_clay 0
fill ~60 ~38 ~88 ~62 ~38 ~88 stained_hardened_clay 0
fill ~60 ~38 ~116 ~62 ~38 ~116 stained_hardened_clay 0
fill ~65 ~38 ~87 ~66 ~38 ~87 stained_hardened_clay 10
fill ~65 ~38 ~117 ~66 ~38 ~117 stained_hardened_clay 10
fill ~68 ~38 ~87 ~75 ~38 ~87 stone 6
fill ~68 ~38 ~117 ~75 ~38 ~117 stone 6
fill ~69 ~38 ~85 ~69 ~41 ~85 stone 6
fill ~69 ~38 ~86 ~73 ~38 ~86 stone 6
fill ~69 ~38 ~118 ~73 ~38 ~118 stone 6
fill ~69 ~38 ~119 ~69 ~41 ~119 stone 6
fill ~70 ~38 ~88 ~76 ~38 ~88 stone 6
fill ~70 ~38 ~116 ~76 ~38 ~116 stone 6
setblock ~75 ~38 ~89 stone 6
setblock ~75 ~38 ~115 stone 6
fill ~80 ~38 ~84 ~80 ~40 ~84 lapis_block 0
fill ~80 ~38 ~120 ~80 ~40 ~120 lapis_block 0
fill ~81 ~38 ~86 ~82 ~38 ~86 planks 1
fill ~81 ~38 ~118 ~82 ~38 ~118 planks 1
fill ~84 ~38 ~86 ~87 ~38 ~86 planks 1
fill ~84 ~38 ~118 ~87 ~38 ~118 planks 1
fill ~86 ~38 ~84 ~90 ~38 ~84 stained_hardened_clay 2
fill ~86 ~38 ~85 ~90 ~38 ~85 stained_hardened_clay 2
fill ~86 ~38 ~87 ~90 ~38 ~87 stained_hardened_clay 2
fill ~86 ~38 ~117 ~90 ~38 ~117 stained_hardened_clay 2
fill ~86 ~38 ~119 ~90 ~38 ~119 stained_hardened_clay 2
fill ~86 ~38 ~120 ~90 ~38 ~120 stained_hardened_clay 2
fill ~88 ~38 ~86 ~89 ~38 ~86 stained_hardened_clay 2
fill ~88 ~38 ~118 ~89 ~38 ~118 stained_hardened_clay 2
fill ~90 ~38 ~86 ~92 ~38 ~86 planks 1
fill ~90 ~38 ~118 ~92 ~38 ~118 planks 1
fill ~94 ~38 ~86 ~95 ~38 ~86 planks 1
fill ~94 ~38 ~118 ~95 ~38 ~118 planks 1
fill ~96 ~38 ~84 ~96 ~40 ~84 lapis_block 0
setblock ~96 ~38 ~87 lapis_block 0
setblock ~96 ~38 ~117 lapis_block 0
