fill ~2~0~0 ~67~0~23 minecraft:stonebrick 0
fill ~2~1~0 ~67~1~0 minecraft:stonebrick 0
fill ~2~12~0 ~67~12~4 minecraft:stonebrick 0
fill ~2~19~0 ~67~20~4 minecraft:stonebrick 0
fill ~2~1~1 ~2~1~23 minecraft:stonebrick 0
fill ~3~31~1 ~66~32~1 minecraft:stonebrick 0
fill ~4~1~1 ~5~1~4 minecraft:stonebrick 0
fill ~4~13~1 ~5~13~4 minecraft:stonebrick 0
fill ~4~21~1 ~5~21~4 minecraft:stonebrick 0
fill ~9~1~1 ~10~1~4 minecraft:stonebrick 0
fill ~9~13~1 ~10~13~4 minecraft:stonebrick 0
fill ~9~21~1 ~10~21~4 minecraft:stonebrick 0
fill ~14~1~1 ~15~1~4 minecraft:stonebrick 0
fill ~14~13~1 ~15~13~4 minecraft:stonebrick 0
fill ~14~21~1 ~15~21~4 minecraft:stonebrick 0
fill ~19~1~1 ~20~1~4 minecraft:stonebrick 0
fill ~19~13~1 ~20~13~4 minecraft:stonebrick 0
fill ~19~21~1 ~20~21~4 minecraft:stonebrick 0
fill ~24~1~1 ~25~1~4 minecraft:stonebrick 0
fill ~24~13~1 ~25~13~4 minecraft:stonebrick 0
fill ~24~21~1 ~25~21~4 minecraft:stonebrick 0
fill ~29~1~1 ~30~1~4 minecraft:stonebrick 0
fill ~29~13~1 ~30~13~4 minecraft:stonebrick 0
fill ~29~21~1 ~30~21~4 minecraft:stonebrick 0
fill ~34~1~1 ~35~1~4 minecraft:stonebrick 0
fill ~34~13~1 ~35~13~4 minecraft:stonebrick 0
fill ~34~21~1 ~35~21~4 minecraft:stonebrick 0
fill ~39~1~1 ~40~1~4 minecraft:stonebrick 0
fill ~39~13~1 ~40~13~4 minecraft:stonebrick 0
fill ~39~21~1 ~40~21~4 minecraft:stonebrick 0
fill ~44~1~1 ~45~1~4 minecraft:stonebrick 0
fill ~44~13~1 ~45~13~4 minecraft:stonebrick 0
fill ~44~21~1 ~45~21~4 minecraft:stonebrick 0
fill ~49~1~1 ~50~1~4 minecraft:stonebrick 0
fill ~49~13~1 ~50~13~4 minecraft:stonebrick 0
fill ~49~21~1 ~50~21~4 minecraft:stonebrick 0
fill ~54~1~1 ~55~1~4 minecraft:stonebrick 0
fill ~54~13~1 ~55~13~4 minecraft:stonebrick 0
fill ~54~21~1 ~55~21~4 minecraft:stonebrick 0
fill ~59~1~1 ~60~1~4 minecraft:stonebrick 0
fill ~59~13~1 ~60~13~4 minecraft:stonebrick 0
fill ~59~21~1 ~60~21~4 minecraft:stonebrick 0
fill ~64~1~1 ~65~1~4 minecraft:stonebrick 0
fill ~64~13~1 ~65~13~4 minecraft:stonebrick 0
fill ~64~21~1 ~65~21~4 minecraft:stonebrick 0
fill ~67~1~1 ~67~1~65 minecraft:stonebrick 0
fill ~3~1~2 ~3~1~3 minecraft:stonebrick 0
fill ~3~13~2 ~3~13~3 minecraft:stonebrick 0
fill ~3~21~2 ~3~21~3 minecraft:stonebrick 0
fill ~3~31~2 ~5~32~3 minecraft:stonebrick 0
fill ~4~2~2 ~5~11~3 minecraft:stonebrick 0
fill ~4~14~2 ~5~18~3 minecraft:stonebrick 0
fill ~4~22~2 ~5~30~3 minecraft:stonebrick 0
fill ~6~1~2 ~6~1~3 minecraft:stonebrick 0
fill ~6~13~2 ~6~13~3 minecraft:stonebrick 0
fill ~6~21~2 ~6~21~3 minecraft:stonebrick 0
fill ~6~32~2 ~66~32~5 minecraft:stonebrick 0
fill ~8~1~2 ~8~1~3 minecraft:stonebrick 0
fill ~8~13~2 ~8~13~3 minecraft:stonebrick 0
fill ~8~21~2 ~8~21~3 minecraft:stonebrick 0
fill ~9~2~2 ~10~11~3 minecraft:stonebrick 0
fill ~9~14~2 ~10~18~3 minecraft:stonebrick 0
fill ~9~22~2 ~10~31~3 minecraft:stonebrick 0
fill ~11~1~2 ~11~1~3 minecraft:stonebrick 0
fill ~11~13~2 ~11~13~3 minecraft:stonebrick 0
fill ~11~21~2 ~11~21~3 minecraft:stonebrick 0
fill ~13~1~2 ~13~1~3 minecraft:stonebrick 0
fill ~13~13~2 ~13~13~3 minecraft:stonebrick 0
fill ~13~21~2 ~13~21~3 minecraft:stonebrick 0
fill ~14~2~2 ~15~11~3 minecraft:stonebrick 0
fill ~14~14~2 ~15~18~3 minecraft:stonebrick 0
fill ~14~22~2 ~15~31~3 minecraft:stonebrick 0
fill ~16~1~2 ~16~1~3 minecraft:stonebrick 0
fill ~16~13~2 ~16~13~3 minecraft:stonebrick 0
fill ~16~21~2 ~16~21~3 minecraft:stonebrick 0
fill ~18~1~2 ~18~1~3 minecraft:stonebrick 0
fill ~18~13~2 ~18~13~3 minecraft:stonebrick 0
fill ~18~21~2 ~18~21~3 minecraft:stonebrick 0
fill ~19~2~2 ~20~11~3 minecraft:stonebrick 0
fill ~19~14~2 ~20~18~3 minecraft:stonebrick 0
fill ~19~22~2 ~20~31~3 minecraft:stonebrick 0
fill ~21~1~2 ~21~1~3 minecraft:stonebrick 0
fill ~21~13~2 ~21~13~3 minecraft:stonebrick 0
fill ~21~21~2 ~21~21~3 minecraft:stonebrick 0
fill ~23~1~2 ~23~1~3 minecraft:stonebrick 0
fill ~23~13~2 ~23~13~3 minecraft:stonebrick 0
fill ~23~21~2 ~23~21~3 minecraft:stonebrick 0
fill ~24~2~2 ~25~11~3 minecraft:stonebrick 0
fill ~24~14~2 ~25~18~3 minecraft:stonebrick 0
fill ~24~22~2 ~25~31~3 minecraft:stonebrick 0
fill ~26~1~2 ~26~1~3 minecraft:stonebrick 0
fill ~26~13~2 ~26~13~3 minecraft:stonebrick 0
fill ~26~21~2 ~26~21~3 minecraft:stonebrick 0
fill ~28~1~2 ~28~1~3 minecraft:stonebrick 0
fill ~28~13~2 ~28~13~3 minecraft:stonebrick 0
fill ~28~21~2 ~28~21~3 minecraft:stonebrick 0
fill ~29~2~2 ~30~11~3 minecraft:stonebrick 0
fill ~29~14~2 ~30~18~3 minecraft:stonebrick 0
fill ~29~22~2 ~30~31~3 minecraft:stonebrick 0
fill ~31~1~2 ~31~1~3 minecraft:stonebrick 0
fill ~31~13~2 ~31~13~3 minecraft:stonebrick 0
fill ~31~21~2 ~31~21~3 minecraft:stonebrick 0
fill ~33~1~2 ~33~1~3 minecraft:stonebrick 0
fill ~33~13~2 ~33~13~3 minecraft:stonebrick 0
fill ~33~21~2 ~33~21~3 minecraft:stonebrick 0
fill ~34~2~2 ~35~11~3 minecraft:stonebrick 0
fill ~34~14~2 ~35~18~3 minecraft:stonebrick 0
fill ~34~22~2 ~35~31~3 minecraft:stonebrick 0
fill ~36~1~2 ~36~1~3 minecraft:stonebrick 0
fill ~36~13~2 ~36~13~3 minecraft:stonebrick 0
fill ~36~21~2 ~36~21~3 minecraft:stonebrick 0
fill ~38~1~2 ~38~1~3 minecraft:stonebrick 0
fill ~38~13~2 ~38~13~3 minecraft:stonebrick 0
fill ~38~21~2 ~38~21~3 minecraft:stonebrick 0
fill ~39~2~2 ~40~11~3 minecraft:stonebrick 0
fill ~39~14~2 ~40~18~3 minecraft:stonebrick 0
fill ~39~22~2 ~40~31~3 minecraft:stonebrick 0
fill ~41~1~2 ~41~1~3 minecraft:stonebrick 0
fill ~41~13~2 ~41~13~3 minecraft:stonebrick 0
fill ~41~21~2 ~41~21~3 minecraft:stonebrick 0
fill ~43~1~2 ~43~1~3 minecraft:stonebrick 0
fill ~43~13~2 ~43~13~3 minecraft:stonebrick 0
fill ~43~21~2 ~43~21~3 minecraft:stonebrick 0
fill ~44~2~2 ~45~11~3 minecraft:stonebrick 0
fill ~44~14~2 ~45~18~3 minecraft:stonebrick 0
fill ~44~22~2 ~45~31~3 minecraft:stonebrick 0
fill ~46~1~2 ~46~1~3 minecraft:stonebrick 0
fill ~46~13~2 ~46~13~3 minecraft:stonebrick 0
fill ~46~21~2 ~46~21~3 minecraft:stonebrick 0
fill ~48~1~2 ~48~1~3 minecraft:stonebrick 0
fill ~48~13~2 ~48~13~3 minecraft:stonebrick 0
fill ~48~21~2 ~48~21~3 minecraft:stonebrick 0
fill ~49~2~2 ~50~11~3 minecraft:stonebrick 0
fill ~49~14~2 ~50~18~3 minecraft:stonebrick 0
fill ~49~22~2 ~50~31~3 minecraft:stonebrick 0
fill ~51~1~2 ~51~1~3 minecraft:stonebrick 0
fill ~51~13~2 ~51~13~3 minecraft:stonebrick 0
fill ~51~21~2 ~51~21~3 minecraft:stonebrick 0
fill ~53~1~2 ~53~1~3 minecraft:stonebrick 0
fill ~53~13~2 ~53~13~3 minecraft:stonebrick 0
fill ~53~21~2 ~53~21~3 minecraft:stonebrick 0
fill ~54~2~2 ~55~11~3 minecraft:stonebrick 0
fill ~54~14~2 ~55~18~3 minecraft:stonebrick 0
fill ~54~22~2 ~55~31~3 minecraft:stonebrick 0
fill ~56~1~2 ~56~1~3 minecraft:stonebrick 0
fill ~56~13~2 ~56~13~3 minecraft:stonebrick 0
fill ~56~21~2 ~56~21~3 minecraft:stonebrick 0
fill ~58~1~2 ~58~1~3 minecraft:stonebrick 0
fill ~58~13~2 ~58~13~3 minecraft:stonebrick 0
fill ~58~21~2 ~58~21~3 minecraft:stonebrick 0
fill ~59~2~2 ~60~11~3 minecraft:stonebrick 0
fill ~59~14~2 ~60~18~3 minecraft:stonebrick 0
fill ~59~22~2 ~60~31~3 minecraft:stonebrick 0
fill ~61~1~2 ~61~1~3 minecraft:stonebrick 0
fill ~61~13~2 ~61~13~3 minecraft:stonebrick 0
fill ~61~21~2 ~61~21~3 minecraft:stonebrick 0
fill ~63~1~2 ~63~1~3 minecraft:stonebrick 0
fill ~63~13~2 ~63~13~3 minecraft:stonebrick 0
fill ~63~21~2 ~63~21~3 minecraft:stonebrick 0
fill ~64~2~2 ~65~11~3 minecraft:stonebrick 0
fill ~64~14~2 ~65~18~3 minecraft:stonebrick 0
fill ~64~22~2 ~65~31~3 minecraft:stonebrick 0
fill ~66~1~2 ~66~1~3 minecraft:stonebrick 0
fill ~66~13~2 ~66~13~3 minecraft:stonebrick 0
fill ~66~21~2 ~66~21~3 minecraft:stonebrick 0
fill ~66~31~2 ~66~31~64 minecraft:stonebrick 0
fill ~3~31~4 ~3~32~64 minecraft:stonebrick 0
fill ~4~32~4 ~5~32~64 minecraft:stonebrick 0
fill ~2~12~5 ~6~12~65 minecraft:stonebrick 0
fill ~2~19~5 ~6~20~65 minecraft:stonebrick 0
fill ~63~12~5 ~67~12~65 minecraft:stonebrick 0
fill ~63~19~5 ~67~20~65 minecraft:stonebrick 0
fill ~4~1~6 ~5~1~9 minecraft:stonebrick 0
fill ~4~13~6 ~5~13~9 minecraft:stonebrick 0
fill ~4~21~6 ~5~21~9 minecraft:stonebrick 0
fill ~6~32~6 ~7~32~64 minecraft:stonebrick 0
fill ~8~33~6 ~61~33~9 minecraft:stonebrick 0
fill ~62~32~6 ~66~32~64 minecraft:stonebrick 0
fill ~64~1~6 ~65~1~9 minecraft:stonebrick 0
fill ~64~13~6 ~65~13~9 minecraft:stonebrick 0
fill ~64~21~6 ~65~21~9 minecraft:stonebrick 0
fill ~3~1~7 ~3~1~8 minecraft:stonebrick 0
fill ~3~13~7 ~3~13~8 minecraft:stonebrick 0
fill ~3~21~7 ~3~21~8 minecraft:stonebrick 0
fill ~4~2~7 ~5~11~8 minecraft:stonebrick 0
fill ~4~14~7 ~5~18~8 minecraft:stonebrick 0
fill ~4~22~7 ~5~31~8 minecraft:stonebrick 0
fill ~6~1~7 ~6~1~8 minecraft:stonebrick 0
fill ~6~13~7 ~6~13~8 minecraft:stonebrick 0
fill ~6~21~7 ~6~21~8 minecraft:stonebrick 0
fill ~63~1~7 ~63~1~8 minecraft:stonebrick 0
fill ~63~13~7 ~63~13~8 minecraft:stonebrick 0
fill ~63~21~7 ~63~21~8 minecraft:stonebrick 0
fill ~64~2~7 ~65~11~8 minecraft:stonebrick 0
fill ~64~14~7 ~65~18~8 minecraft:stonebrick 0
fill ~64~22~7 ~65~31~8 minecraft:stonebrick 0
fill ~66~1~7 ~66~1~8 minecraft:stonebrick 0
fill ~66~13~7 ~66~13~8 minecraft:stonebrick 0
fill ~66~21~7 ~66~21~8 minecraft:stonebrick 0
fill ~1~15~8 ~1~17~8 minecraft:wool 14
fill ~1~13~9 ~1~14~9 minecraft:wool 14
fill ~1~15~9 ~1~16~9 minecraft:gold_block
fill ~1~17~9 ~1~18~9 minecraft:wool 14
fill ~1~11~10 ~1~12~10 minecraft:wool 14
fill ~1~13~10 ~1~14~10 minecraft:gold_block
fill ~1~15~10 ~1~15~12 minecraft:wool 14
fill ~1~16~10 ~1~16~11 minecraft:wool 14
setblock ~1~17~10 minecraft:gold_block
fill ~8~33~10 ~11~33~59 minecraft:stonebrick 0
fill ~12~34~10 ~57~34~13 minecraft:stonebrick 0
fill ~58~33~10 ~61~33~59 minecraft:stonebrick 0
fill ~1~9~11 ~1~10~11 minecraft:wool 14
fill ~1~11~11 ~1~12~11 minecraft:gold_block
fill ~1~13~11 ~1~14~16 minecraft:wool 14
fill ~1~17~11 ~1~17~12 minecraft:wool 14
fill ~4~1~11 ~5~1~14 minecraft:stonebrick 0
fill ~4~13~11 ~5~13~14 minecraft:stonebrick 0
fill ~4~21~11 ~5~21~14 minecraft:stonebrick 0
fill ~64~1~11 ~65~1~14 minecraft:stonebrick 0
fill ~64~13~11 ~65~13~14 minecraft:stonebrick 0
fill ~64~21~11 ~65~21~14 minecraft:stonebrick 0
setblock ~1~8~12 minecraft:wool 14
fill ~1~9~12 ~1~10~12 minecraft:gold_block
fill ~1~11~12 ~1~12~15 minecraft:wool 14
setblock ~1~16~12 minecraft:gold_block
fill ~3~1~12 ~3~1~13 minecraft:stonebrick 0
fill ~3~13~12 ~3~13~13 minecraft:stonebrick 0
fill ~3~21~12 ~3~21~13 minecraft:stonebrick 0
fill ~4~2~12 ~5~11~13 minecraft:stonebrick 0
fill ~4~14~12 ~5~18~13 minecraft:stonebrick 0
fill ~4~22~12 ~5~31~13 minecraft:stonebrick 0
fill ~6~1~12 ~6~1~13 minecraft:stonebrick 0
fill ~6~13~12 ~6~13~13 minecraft:stonebrick 0
fill ~6~21~12 ~6~21~13 minecraft:stonebrick 0
fill ~63~1~12 ~63~1~13 minecraft:stonebrick 0
fill ~63~13~12 ~63~13~13 minecraft:stonebrick 0
fill ~63~21~12 ~63~21~13 minecraft:stonebrick 0
fill ~64~2~12 ~65~11~13 minecraft:stonebrick 0
fill ~64~14~12 ~65~18~13 minecraft:stonebrick 0
fill ~64~22~12 ~65~31~13 minecraft:stonebrick 0
fill ~66~1~12 ~66~1~13 minecraft:stonebrick 0
fill ~66~13~12 ~66~13~13 minecraft:stonebrick 0
fill ~66~21~12 ~66~21~13 minecraft:stonebrick 0
fill ~1~7~13 ~1~7~14 minecraft:wool 14
fill ~1~8~13 ~1~8~14 minecraft:gold_block
fill ~1~9~13 ~1~10~14 minecraft:wool 14
fill ~1~15~13 ~1~15~14 minecraft:gold_block
fill ~1~16~13 ~1~16~14 minecraft:glowstone
fill ~1~17~13 ~1~17~14 minecraft:gold_block
fill ~1~18~13 ~1~18~14 minecraft:wool 14
fill ~12~34~14 ~15~34~55 minecraft:stonebrick 0
fill ~16~35~14 ~53~35~17 minecraft:stonebrick 0
fill ~54~34~14 ~57~34~55 minecraft:stonebrick 0
setblock ~1~8~15 minecraft:wool 14
fill ~1~9~15 ~1~10~15 minecraft:gold_block
fill ~1~15~15 ~1~15~17 minecraft:wool 14
setblock ~1~16~15 minecraft:gold_block
fill ~1~17~15 ~1~17~16 minecraft:wool 14
fill ~28~1~15 ~41~2~15 minecraft:lapis_block
fill ~28~3~15 ~41~4~15 minecraft:glowstone
fill ~28~5~15 ~41~5~15 minecraft:lapis_block
fill ~28~6~15 ~41~7~15 minecraft:glowstone
fill ~28~8~15 ~41~8~15 minecraft:lapis_block
fill ~28~9~15 ~41~10~15 minecraft:glowstone
fill ~28~11~15 ~41~11~15 minecraft:lapis_block
fill ~28~12~15 ~41~13~15 minecraft:glowstone
fill ~28~14~15 ~41~14~15 minecraft:lapis_block
fill ~28~15~15 ~41~16~15 minecraft:glowstone
fill ~28~17~15 ~41~17~15 minecraft:lapis_block
fill ~28~18~15 ~41~19~15 minecraft:glowstone
fill ~28~20~15 ~41~20~15 minecraft:lapis_block
fill ~28~21~15 ~41~22~15 minecraft:glowstone
fill ~28~23~15 ~41~23~15 minecraft:lapis_block
fill ~28~24~15 ~41~25~15 minecraft:glowstone
fill ~28~26~15 ~41~26~15 minecraft:lapis_block
fill ~28~27~15 ~41~28~15 minecraft:glowstone
fill ~28~29~15 ~41~29~15 minecraft:lapis_block
fill ~28~30~15 ~41~31~15 minecraft:glowstone
fill ~28~32~15 ~41~32~15 minecraft:lapis_block
fill ~28~33~15 ~41~34~15 minecraft:glowstone
fill ~1~9~16 ~1~10~16 minecraft:wool 14
fill ~1~11~16 ~1~12~16 minecraft:gold_block
fill ~1~16~16 ~1~16~17 minecraft:wool 14
fill ~2~26~16 ~2~31~16 minecraft:wool 14
fill ~4~1~16 ~5~1~19 minecraft:stonebrick 0
fill ~4~13~16 ~5~13~19 minecraft:stonebrick 0
fill ~4~21~16 ~5~21~19 minecraft:stonebrick 0
fill ~25~1~16 ~27~2~16 minecraft:lapis_block
fill ~25~3~16 ~27~4~16 minecraft:glowstone
fill ~25~5~16 ~27~5~16 minecraft:lapis_block
fill ~25~6~16 ~27~7~16 minecraft:glowstone
fill ~25~8~16 ~27~8~16 minecraft:lapis_block
fill ~25~9~16 ~27~10~16 minecraft:glowstone
fill ~25~11~16 ~27~11~16 minecraft:lapis_block
fill ~25~12~16 ~27~13~16 minecraft:glowstone
fill ~25~14~16 ~27~14~16 minecraft:lapis_block
fill ~25~15~16 ~27~16~16 minecraft:glowstone
fill ~25~17~16 ~27~17~16 minecraft:lapis_block
fill ~25~18~16 ~27~19~16 minecraft:glowstone
fill ~25~20~16 ~27~20~16 minecraft:lapis_block
fill ~25~21~16 ~27~22~16 minecraft:glowstone
fill ~25~23~16 ~27~23~16 minecraft:lapis_block
fill ~25~24~16 ~27~25~16 minecraft:glowstone
fill ~25~26~16 ~27~26~16 minecraft:lapis_block
fill ~25~27~16 ~27~28~16 minecraft:glowstone
fill ~25~29~16 ~27~29~16 minecraft:lapis_block
fill ~25~30~16 ~27~31~16 minecraft:glowstone
fill ~25~32~16 ~27~32~16 minecraft:lapis_block
fill ~25~33~16 ~27~34~16 minecraft:glowstone
setblock ~28~4~16 minecraft:stonebrick 0
fill ~29~4~16 ~32~4~16 minecraft:stone_brick_stairs 3
setblock ~33~4~16 minecraft:stonebrick 0
fill ~34~4~16 ~35~4~16 minecraft:stone_block_slab 0
setblock ~36~4~16 minecraft:stonebrick 0
fill ~37~4~16 ~40~4~16 minecraft:stone_brick_stairs 3
setblock ~41~4~16 minecraft:stonebrick 0
fill ~42~1~16 ~44~2~16 minecraft:lapis_block
fill ~42~3~16 ~44~4~16 minecraft:glowstone
fill ~42~5~16 ~44~5~16 minecraft:lapis_block
fill ~42~6~16 ~44~7~16 minecraft:glowstone
fill ~42~8~16 ~44~8~16 minecraft:lapis_block
fill ~42~9~16 ~44~10~16 minecraft:glowstone
fill ~42~11~16 ~44~11~16 minecraft:lapis_block
fill ~42~12~16 ~44~13~16 minecraft:glowstone
fill ~42~14~16 ~44~14~16 minecraft:lapis_block
fill ~42~15~16 ~44~16~16 minecraft:glowstone
fill ~42~17~16 ~44~17~16 minecraft:lapis_block
fill ~42~18~16 ~44~19~16 minecraft:glowstone
fill ~42~20~16 ~44~20~16 minecraft:lapis_block
fill ~42~21~16 ~44~22~16 minecraft:glowstone
fill ~42~23~16 ~44~23~16 minecraft:lapis_block
fill ~42~24~16 ~44~25~16 minecraft:glowstone
fill ~42~26~16 ~44~26~16 minecraft:lapis_block
fill ~42~27~16 ~44~28~16 minecraft:glowstone
fill ~42~29~16 ~44~29~16 minecraft:lapis_block
fill ~42~30~16 ~44~31~16 minecraft:glowstone
fill ~42~32~16 ~44~32~16 minecraft:lapis_block
fill ~42~33~16 ~44~34~16 minecraft:glowstone
fill ~64~1~16 ~65~1~19 minecraft:stonebrick 0
fill ~64~13~16 ~65~13~19 minecraft:stonebrick 0
fill ~64~21~16 ~65~21~19 minecraft:stonebrick 0
fill ~1~11~17 ~1~12~17 minecraft:wool 14
fill ~1~13~17 ~1~14~17 minecraft:gold_block
setblock ~1~17~17 minecraft:gold_block
fill ~2~26~17 ~2~31~17 minecraft:gold_block
setblock ~2~32~17 minecraft:wool 14
fill ~3~1~17 ~3~1~18 minecraft:stonebrick 0
fill ~3~13~17 ~3~13~18 minecraft:stonebrick 0
fill ~3~21~17 ~3~21~18 minecraft:stonebrick 0
fill ~3~22~17 ~3~22~18 minecraft:glowstone
fill ~4~2~17 ~5~11~18 minecraft:stonebrick 0
fill ~4~14~17 ~5~18~18 minecraft:stonebrick 0
fill ~4~22~17 ~5~31~18 minecraft:stonebrick 0
fill ~6~1~17 ~6~1~18 minecraft:stonebrick 0
fill ~6~13~17 ~6~13~18 minecraft:stonebrick 0
fill ~6~21~17 ~6~21~18 minecraft:stonebrick 0
fill ~23~1~17 ~24~2~17 minecraft:lapis_block
fill ~23~3~17 ~24~4~17 minecraft:glowstone
fill ~23~5~17 ~24~5~17 minecraft:lapis_block
fill ~23~6~17 ~24~7~17 minecraft:glowstone
fill ~23~8~17 ~24~8~17 minecraft:lapis_block
fill ~23~9~17 ~24~10~17 minecraft:glowstone
fill ~23~11~17 ~24~11~17 minecraft:lapis_block
fill ~23~12~17 ~24~13~17 minecraft:glowstone
fill ~23~14~17 ~24~14~17 minecraft:lapis_block
fill ~23~15~17 ~24~16~17 minecraft:glowstone
fill ~23~17~17 ~24~17~17 minecraft:lapis_block
fill ~23~18~17 ~24~19~17 minecraft:glowstone
fill ~23~20~17 ~24~20~17 minecraft:lapis_block
fill ~23~21~17 ~24~22~17 minecraft:glowstone
fill ~23~23~17 ~24~23~17 minecraft:lapis_block
fill ~23~24~17 ~24~25~17 minecraft:glowstone
fill ~23~26~17 ~24~26~17 minecraft:lapis_block
fill ~23~27~17 ~24~28~17 minecraft:glowstone
fill ~23~29~17 ~24~29~17 minecraft:lapis_block
fill ~23~30~17 ~24~31~17 minecraft:glowstone
fill ~23~32~17 ~24~32~17 minecraft:lapis_block
fill ~23~33~17 ~24~34~17 minecraft:glowstone
fill ~25~4~17 ~25~4~18 minecraft:stonebrick 0
fill ~26~4~17 ~27~4~17 minecraft:stone_brick_stairs 3
setblock ~28~4~17 minecraft:stone_block_slab 5
fill ~29~3~17 ~33~3~17 minecraft:lapis_block
fill ~34~3~17 ~35~3~17 minecraft:glowstone
fill ~36~3~17 ~40~3~17 minecraft:lapis_block
setblock ~41~4~17 minecraft:stone_block_slab 5
fill ~42~4~17 ~44~4~17 minecraft:stone_brick_stairs 3
fill ~45~1~17 ~46~2~17 minecraft:lapis_block
fill ~45~3~17 ~46~4~17 minecraft:glowstone
fill ~45~5~17 ~46~5~17 minecraft:lapis_block
fill ~45~6~17 ~46~7~17 minecraft:glowstone
fill ~45~8~17 ~46~8~17 minecraft:lapis_block
fill ~45~9~17 ~46~10~17 minecraft:glowstone
fill ~45~11~17 ~46~11~17 minecraft:lapis_block
fill ~45~12~17 ~46~13~17 minecraft:glowstone
fill ~45~14~17 ~46~14~17 minecraft:lapis_block
fill ~45~15~17 ~46~16~17 minecraft:glowstone
fill ~45~17~17 ~46~17~17 minecraft:lapis_block
fill ~45~18~17 ~46~19~17 minecraft:glowstone
fill ~45~20~17 ~46~20~17 minecraft:lapis_block
fill ~45~21~17 ~46~22~17 minecraft:glowstone
fill ~45~23~17 ~46~23~17 minecraft:lapis_block
fill ~45~24~17 ~46~25~17 minecraft:glowstone
fill ~45~26~17 ~46~26~17 minecraft:lapis_block
fill ~45~27~17 ~46~28~17 minecraft:glowstone
fill ~45~29~17 ~46~29~17 minecraft:lapis_block
fill ~45~30~17 ~46~31~17 minecraft:glowstone
fill ~45~32~17 ~46~32~17 minecraft:lapis_block
fill ~45~33~17 ~46~34~17 minecraft:glowstone
fill ~63~1~17 ~63~1~18 minecraft:stonebrick 0
fill ~63~13~17 ~63~13~18 minecraft:stonebrick 0
fill ~63~21~17 ~63~21~18 minecraft:stonebrick 0
fill ~64~2~17 ~65~11~18 minecraft:stonebrick 0
fill ~64~14~17 ~65~18~18 minecraft:stonebrick 0
fill ~64~22~17 ~65~31~18 minecraft:stonebrick 0
fill ~66~1~17 ~66~1~18 minecraft:stonebrick 0
fill ~66~13~17 ~66~13~18 minecraft:stonebrick 0
fill ~66~21~17 ~66~21~18 minecraft:stonebrick 0
fill ~1~13~18 ~1~14~18 minecraft:wool 14
fill ~1~15~18 ~1~16~18 minecraft:gold_block
fill ~1~17~18 ~1~17~19 minecraft:wool 14
setblock ~1~18~18 minecraft:wool 14
fill ~2~30~18 ~2~30~22 minecraft:gold_block
setblock ~2~32~18 minecraft:gold_block
setblock ~2~33~18 minecraft:wool 14
fill ~3~33~18 ~3~33~20 minecraft:glowstone
fill ~16~35~18 ~19~35~51 minecraft:stonebrick 0
fill ~20~36~18 ~49~36~22 minecraft:stonebrick 0
fill ~22~1~18 ~22~2~29 minecraft:lapis_block
fill ~22~3~18 ~22~4~18 minecraft:glowstone
setblock ~22~5~18 minecraft:lapis_block
fill ~22~6~18 ~22~7~18 minecraft:glowstone
setblock ~22~8~18 minecraft:lapis_block
fill ~22~9~18 ~22~10~18 minecraft:glowstone
setblock ~22~11~18 minecraft:lapis_block
fill ~22~12~18 ~22~13~18 minecraft:glowstone
setblock ~22~14~18 minecraft:lapis_block
fill ~22~15~18 ~22~16~18 minecraft:glowstone
setblock ~22~17~18 minecraft:lapis_block
fill ~22~18~18 ~22~19~18 minecraft:glowstone
setblock ~22~20~18 minecraft:lapis_block
fill ~22~21~18 ~22~22~18 minecraft:glowstone
setblock ~22~23~18 minecraft:lapis_block
fill ~22~24~18 ~22~25~18 minecraft:glowstone
setblock ~22~26~18 minecraft:lapis_block
fill ~22~27~18 ~22~28~18 minecraft:glowstone
setblock ~22~29~18 minecraft:lapis_block
fill ~22~30~18 ~22~31~18 minecraft:glowstone
setblock ~22~32~18 minecraft:lapis_block
fill ~22~33~18 ~22~34~18 minecraft:glowstone
setblock ~22~35~18 minecraft:lapis_block
fill ~23~4~18 ~23~4~19 minecraft:stone_block_slab 5
setblock ~24~4~18 minecraft:stone_brick_stairs 3
fill ~26~3~18 ~29~3~18 minecraft:lapis_block
setblock ~30~3~18 minecraft:stonebrick 0
fill ~31~3~18 ~32~3~18 minecraft:stone_brick_stairs 3
setblock ~33~3~18 minecraft:stonebrick 0
fill ~34~3~18 ~35~3~18 minecraft:stone_block_slab 0
setblock ~36~3~18 minecraft:stonebrick 0
fill ~37~3~18 ~38~3~18 minecraft:stone_brick_stairs 3
setblock ~39~3~18 minecraft:stonebrick 0
fill ~40~3~18 ~43~3~18 minecraft:lapis_block
setblock ~44~4~18 minecraft:stone_block_slab 5
setblock ~45~4~18 minecraft:stone_brick_stairs 3
fill ~46~4~18 ~46~4~19 minecraft:stone_block_slab 5
fill ~47~1~18 ~47~2~18 minecraft:lapis_block
fill ~47~3~18 ~47~4~18 minecraft:glowstone
setblock ~47~5~18 minecraft:lapis_block
fill ~47~6~18 ~47~7~18 minecraft:glowstone
setblock ~47~8~18 minecraft:lapis_block
fill ~47~9~18 ~47~10~18 minecraft:glowstone
setblock ~47~11~18 minecraft:lapis_block
fill ~47~12~18 ~47~13~18 minecraft:glowstone
setblock ~47~14~18 minecraft:lapis_block
fill ~47~15~18 ~47~16~18 minecraft:glowstone
setblock ~47~17~18 minecraft:lapis_block
fill ~47~18~18 ~47~19~18 minecraft:glowstone
setblock ~47~20~18 minecraft:lapis_block
fill ~47~21~18 ~47~22~18 minecraft:glowstone
setblock ~47~23~18 minecraft:lapis_block
fill ~47~24~18 ~47~25~18 minecraft:glowstone
setblock ~47~26~18 minecraft:lapis_block
fill ~47~27~18 ~47~28~18 minecraft:glowstone
setblock ~47~29~18 minecraft:lapis_block
fill ~47~30~18 ~47~31~18 minecraft:glowstone
setblock ~47~32~18 minecraft:lapis_block
fill ~47~33~18 ~47~34~18 minecraft:glowstone
setblock ~47~35~18 minecraft:lapis_block
fill ~50~35~18 ~53~35~51 minecraft:stonebrick 0
fill ~1~15~19 ~1~16~19 minecraft:wool 14
fill ~2~29~19 ~2~29~21 minecraft:wool 14
fill ~2~32~19 ~2~32~20 minecraft:wool 14
fill ~2~33~19 ~2~33~20 minecraft:gold_block
fill ~21~1~19 ~21~2~30 minecraft:lapis_block
fill ~21~3~19 ~21~4~19 minecraft:glowstone
setblock ~21~5~19 minecraft:lapis_block
fill ~21~6~19 ~21~7~19 minecraft:glowstone
setblock ~21~8~19 minecraft:lapis_block
fill ~21~9~19 ~21~10~19 minecraft:glowstone
setblock ~21~11~19 minecraft:lapis_block
fill ~21~12~19 ~21~13~19 minecraft:glowstone
setblock ~21~14~19 minecraft:lapis_block
fill ~21~15~19 ~21~16~19 minecraft:glowstone
setblock ~21~17~19 minecraft:lapis_block
fill ~21~18~19 ~21~19~19 minecraft:glowstone
setblock ~21~20~19 minecraft:lapis_block
fill ~21~21~19 ~21~22~19 minecraft:glowstone
setblock ~21~23~19 minecraft:lapis_block
fill ~21~24~19 ~21~25~19 minecraft:glowstone
setblock ~21~26~19 minecraft:lapis_block
fill ~21~27~19 ~21~28~19 minecraft:glowstone
setblock ~21~29~19 minecraft:lapis_block
fill ~21~30~19 ~21~31~19 minecraft:glowstone
setblock ~21~32~19 minecraft:lapis_block
fill ~21~33~19 ~21~34~19 minecraft:glowstone
setblock ~21~35~19 minecraft:lapis_block
fill ~22~3~19 ~22~3~22 minecraft:lapis_block
fill ~22~4~19 ~22~4~20 minecraft:stone_block_slab 5
fill ~24~3~19 ~26~3~19 minecraft:lapis_block
setblock ~27~3~19 minecraft:stonebrick 0
fill ~28~3~19 ~29~3~19 minecraft:stone_brick_stairs 3
setblock ~30~3~19 minecraft:stone_block_slab 5
fill ~31~2~19 ~38~2~19 minecraft:lapis_block
setblock ~39~3~19 minecraft:stone_block_slab 5
fill ~40~3~19 ~41~3~19 minecraft:stone_brick_stairs 3
setblock ~42~3~19 minecraft:stonebrick 0
fill ~43~3~19 ~45~3~19 minecraft:lapis_block
fill ~47~4~19 ~47~4~20 minecraft:stone_block_slab 5
fill ~48~1~19 ~48~2~19 minecraft:lapis_block
fill ~48~3~19 ~48~4~19 minecraft:glowstone
setblock ~48~5~19 minecraft:lapis_block
fill ~48~6~19 ~48~7~19 minecraft:glowstone
setblock ~48~8~19 minecraft:lapis_block
fill ~48~9~19 ~48~10~19 minecraft:glowstone
setblock ~48~11~19 minecraft:lapis_block
fill ~48~12~19 ~48~13~19 minecraft:glowstone
setblock ~48~14~19 minecraft:lapis_block
fill ~48~15~19 ~48~16~19 minecraft:glowstone
setblock ~48~17~19 minecraft:lapis_block
fill ~48~18~19 ~48~19~19 minecraft:glowstone
setblock ~48~20~19 minecraft:lapis_block
fill ~48~21~19 ~48~22~19 minecraft:glowstone
setblock ~48~23~19 minecraft:lapis_block
fill ~48~24~19 ~48~25~19 minecraft:glowstone
setblock ~48~26~19 minecraft:lapis_block
fill ~48~27~19 ~48~28~19 minecraft:glowstone
setblock ~48~29~19 minecraft:lapis_block
fill ~48~30~19 ~48~31~19 minecraft:glowstone
setblock ~48~32~19 minecraft:lapis_block
fill ~48~33~19 ~48~34~19 minecraft:glowstone
setblock ~48~35~19 minecraft:lapis_block
fill ~20~1~20 ~20~1~30 minecraft:lapis_block
fill ~20~2~20 ~20~2~23 minecraft:lapis_block
fill ~20~3~20 ~20~4~20 minecraft:glowstone
setblock ~20~5~20 minecraft:lapis_block
fill ~20~6~20 ~20~7~20 minecraft:glowstone
setblock ~20~8~20 minecraft:lapis_block
fill ~20~9~20 ~20~10~20 minecraft:glowstone
setblock ~20~11~20 minecraft:lapis_block
fill ~20~12~20 ~20~13~20 minecraft:glowstone
setblock ~20~14~20 minecraft:lapis_block
fill ~20~15~20 ~20~16~20 minecraft:glowstone
setblock ~20~17~20 minecraft:lapis_block
fill ~20~18~20 ~20~19~20 minecraft:glowstone
setblock ~20~20~20 minecraft:lapis_block
fill ~20~21~20 ~20~22~20 minecraft:glowstone
setblock ~20~23~20 minecraft:lapis_block
fill ~20~24~20 ~20~25~20 minecraft:glowstone
setblock ~20~26~20 minecraft:lapis_block
fill ~20~27~20 ~20~28~20 minecraft:glowstone
setblock ~20~29~20 minecraft:lapis_block
fill ~20~30~20 ~20~31~20 minecraft:glowstone
setblock ~20~32~20 minecraft:lapis_block
fill ~20~33~20 ~20~34~20 minecraft:glowstone
setblock ~20~35~20 minecraft:lapis_block
fill ~21~3~20 ~21~3~24 minecraft:lapis_block
setblock ~21~4~20 minecraft:stone_block_slab 5
fill ~23~1~20 ~31~2~20 minecraft:lapis_block
fill ~23~3~20 ~24~3~20 minecraft:lapis_block
setblock ~25~3~20 minecraft:stonebrick 0
setblock ~26~3~20 minecraft:stone_brick_stairs 3
setblock ~27~3~20 minecraft:stone_block_slab 5
fill ~32~1~20 ~37~2~20 minecraft:stonebrick 0
fill ~32~3~20 ~37~3~20 minecraft:stone_block_slab 5
fill ~38~2~20 ~41~2~20 minecraft:lapis_block
setblock ~42~3~20 minecraft:stone_block_slab 5
setblock ~43~3~20 minecraft:stone_brick_stairs 3
setblock ~44~3~20 minecraft:stonebrick 0
fill ~45~3~20 ~46~3~20 minecraft:lapis_block
setblock ~48~4~20 minecraft:stone_block_slab 5
fill ~49~1~20 ~49~2~20 minecraft:lapis_block
fill ~49~3~20 ~49~4~20 minecraft:glowstone
setblock ~49~5~20 minecraft:lapis_block
fill ~49~6~20 ~49~7~20 minecraft:glowstone
setblock ~49~8~20 minecraft:lapis_block
fill ~49~9~20 ~49~10~20 minecraft:glowstone
setblock ~49~11~20 minecraft:lapis_block
fill ~49~12~20 ~49~13~20 minecraft:glowstone
setblock ~49~14~20 minecraft:lapis_block
fill ~49~15~20 ~49~16~20 minecraft:glowstone
setblock ~49~17~20 minecraft:lapis_block
fill ~49~18~20 ~49~19~20 minecraft:glowstone
setblock ~49~20~20 minecraft:lapis_block
fill ~49~21~20 ~49~22~20 minecraft:glowstone
setblock ~49~23~20 minecraft:lapis_block
fill ~49~24~20 ~49~25~20 minecraft:glowstone
setblock ~49~26~20 minecraft:lapis_block
fill ~49~27~20 ~49~28~20 minecraft:glowstone
setblock ~49~29~20 minecraft:lapis_block
fill ~49~30~20 ~49~31~20 minecraft:glowstone
setblock ~49~32~20 minecraft:lapis_block
fill ~49~33~20 ~49~34~20 minecraft:glowstone
setblock ~49~35~20 minecraft:lapis_block
fill ~2~26~21 ~2~28~21 minecraft:wool 14
setblock ~2~31~21 minecraft:wool 14
setblock ~2~32~21 minecraft:gold_block
fill ~4~1~21 ~5~1~24 minecraft:stonebrick 0
fill ~4~13~21 ~5~13~24 minecraft:stonebrick 0
fill ~4~21~21 ~5~21~24 minecraft:stonebrick 0
fill ~19~1~21 ~19~2~30 minecraft:lapis_block
fill ~19~3~21 ~19~4~21 minecraft:glowstone
setblock ~19~5~21 minecraft:lapis_block
fill ~19~6~21 ~19~7~21 minecraft:glowstone
setblock ~19~8~21 minecraft:lapis_block
fill ~19~9~21 ~19~10~21 minecraft:glowstone
setblock ~19~11~21 minecraft:lapis_block
fill ~19~12~21 ~19~13~21 minecraft:glowstone
setblock ~19~14~21 minecraft:lapis_block
fill ~19~15~21 ~19~16~21 minecraft:glowstone
setblock ~19~17~21 minecraft:lapis_block
fill ~19~18~21 ~19~19~21 minecraft:glowstone
setblock ~19~20~21 minecraft:lapis_block
fill ~19~21~21 ~19~22~21 minecraft:glowstone
setblock ~19~23~21 minecraft:lapis_block
fill ~19~24~21 ~19~25~21 minecraft:glowstone
setblock ~19~26~21 minecraft:lapis_block
fill ~19~27~21 ~19~28~21 minecraft:glowstone
setblock ~19~29~21 minecraft:lapis_block
fill ~19~30~21 ~19~31~21 minecraft:glowstone
setblock ~19~32~21 minecraft:lapis_block
fill ~19~33~21 ~19~34~21 minecraft:glowstone
fill ~20~3~21 ~20~3~27 minecraft:lapis_block
setblock ~20~4~21 minecraft:stonebrick 0
setblock ~21~4~21 minecraft:stone_brick_stairs 1
fill ~23~1~21 ~28~2~21 minecraft:lapis_block
setblock ~23~3~21 minecraft:lapis_block
fill ~24~3~21 ~24~3~22 minecraft:stone_block_slab 5
setblock ~25~3~21 minecraft:stone_brick_stairs 3
fill ~29~1~21 ~31~2~21 minecraft:stonebrick 0
fill ~29~3~21 ~31~3~21 minecraft:stone_block_slab 5
fill ~38~1~21 ~40~2~21 minecraft:stonebrick 0
fill ~38~3~21 ~40~3~21 minecraft:stone_block_slab 5
fill ~41~2~21 ~43~2~21 minecraft:lapis_block
setblock ~44~3~21 minecraft:stone_brick_stairs 3
fill ~45~3~21 ~45~3~22 minecraft:stone_block_slab 5
fill ~46~3~21 ~47~3~21 minecraft:lapis_block
setblock ~48~4~21 minecraft:stone_brick_stairs 0
setblock ~49~4~21 minecraft:stonebrick 0
fill ~50~1~21 ~50~2~22 minecraft:lapis_block
fill ~50~3~21 ~50~4~22 minecraft:glowstone
fill ~50~5~21 ~50~5~22 minecraft:lapis_block
fill ~50~6~21 ~50~7~22 minecraft:glowstone
fill ~50~8~21 ~50~8~22 minecraft:lapis_block
fill ~50~9~21 ~50~10~22 minecraft:glowstone
fill ~50~11~21 ~50~11~22 minecraft:lapis_block
fill ~50~12~21 ~50~13~22 minecraft:glowstone
fill ~50~14~21 ~50~14~22 minecraft:lapis_block
fill ~50~15~21 ~50~16~22 minecraft:glowstone
fill ~50~17~21 ~50~17~22 minecraft:lapis_block
fill ~50~18~21 ~50~19~22 minecraft:glowstone
fill ~50~20~21 ~50~20~22 minecraft:lapis_block
fill ~50~21~21 ~50~22~22 minecraft:glowstone
fill ~50~23~21 ~50~23~22 minecraft:lapis_block
fill ~50~24~21 ~50~25~22 minecraft:glowstone
fill ~50~26~21 ~50~26~22 minecraft:lapis_block
fill ~50~27~21 ~50~28~22 minecraft:glowstone
fill ~50~29~21 ~50~29~22 minecraft:lapis_block
fill ~50~30~21 ~50~31~22 minecraft:glowstone
fill ~50~32~21 ~50~32~22 minecraft:lapis_block
fill ~50~33~21 ~50~34~22 minecraft:glowstone
fill ~64~1~21 ~65~1~24 minecraft:stonebrick 0
fill ~64~13~21 ~65~13~24 minecraft:stonebrick 0
fill ~64~21~21 ~65~21~24 minecraft:stonebrick 0
fill ~2~26~22 ~2~29~22 minecraft:gold_block
setblock ~2~31~22 minecraft:gold_block
fill ~3~1~22 ~3~1~23 minecraft:stonebrick 0
fill ~3~13~22 ~3~13~23 minecraft:stonebrick 0
fill ~3~21~22 ~3~21~23 minecraft:stonebrick 0
fill ~3~22~22 ~3~22~23 minecraft:glowstone
fill ~4~2~22 ~5~11~23 minecraft:stonebrick 0
fill ~4~14~22 ~5~18~23 minecraft:stonebrick 0
fill ~4~22~22 ~5~31~23 minecraft:stonebrick 0
fill ~6~1~22 ~6~1~23 minecraft:stonebrick 0
fill ~6~13~22 ~6~13~23 minecraft:stonebrick 0
fill ~6~21~22 ~6~21~23 minecraft:stonebrick 0
fill ~16~1~22 ~18~1~27 minecraft:lapis_block
fill ~16~2~22 ~18~2~26 minecraft:lapis_block
fill ~16~3~22 ~19~4~22 minecraft:lapis_block
fill ~16~5~22 ~18~5~22 minecraft:lapis_block
fill ~16~6~22 ~18~7~22 minecraft:glowstone
fill ~16~8~22 ~18~8~22 minecraft:lapis_block
fill ~16~9~22 ~18~10~22 minecraft:glowstone
fill ~16~11~22 ~18~11~22 minecraft:lapis_block
fill ~16~12~22 ~18~13~22 minecraft:glowstone
fill ~16~14~22 ~18~14~22 minecraft:lapis_block
fill ~16~15~22 ~18~16~22 minecraft:glowstone
fill ~16~17~22 ~18~17~22 minecraft:lapis_block
fill ~16~18~22 ~18~19~22 minecraft:glowstone
fill ~16~20~22 ~18~20~22 minecraft:lapis_block
fill ~16~21~22 ~18~22~22 minecraft:glowstone
fill ~16~23~22 ~18~23~22 minecraft:lapis_block
fill ~16~24~22 ~18~25~22 minecraft:glowstone
fill ~16~26~22 ~18~26~22 minecraft:lapis_block
fill ~16~27~22 ~18~28~22 minecraft:glowstone
fill ~16~29~22 ~18~29~22 minecraft:lapis_block
fill ~16~30~22 ~18~31~22 minecraft:glowstone
fill ~16~32~22 ~18~32~22 minecraft:lapis_block
fill ~16~33~22 ~18~34~22 minecraft:glowstone
setblock ~20~4~22 minecraft:stone_brick_stairs 1
fill ~23~1~22 ~26~2~22 minecraft:lapis_block
setblock ~23~3~22 minecraft:stone_block_slab 5
fill ~27~1~22 ~28~2~22 minecraft:stonebrick 0
fill ~27~3~22 ~28~3~22 minecraft:stone_block_slab 5
fill ~41~1~22 ~42~2~22 minecraft:stonebrick 0
fill ~41~3~22 ~42~3~22 minecraft:stone_block_slab 5
fill ~43~2~22 ~44~2~22 minecraft:lapis_block
setblock ~46~3~22 minecraft:stone_block_slab 5
fill ~47~3~22 ~48~3~22 minecraft:lapis_block
setblock ~49~4~22 minecraft:stone_brick_stairs 0
fill ~63~1~22 ~63~1~23 minecraft:stonebrick 0
fill ~63~13~22 ~63~13~23 minecraft:stonebrick 0
fill ~63~21~22 ~63~21~23 minecraft:stonebrick 0
fill ~64~2~22 ~65~11~23 minecraft:stonebrick 0
fill ~64~14~22 ~65~18~23 minecraft:stonebrick 0
fill ~64~22~22 ~65~31~23 minecraft:stonebrick 0
fill ~66~1~22 ~66~1~23 minecraft:stonebrick 0
fill ~66~13~22 ~66~13~23 minecraft:stonebrick 0
fill ~66~21~22 ~66~21~23 minecraft:stonebrick 0
fill ~2~26~23 ~2~32~23 minecraft:wool 14
fill ~6~2~23 ~6~5~23 minecraft:lapis_block
fill ~6~6~23 ~7~7~23 minecraft:glowstone
fill ~6~8~23 ~7~8~23 minecraft:lapis_block
fill ~6~9~23 ~7~10~23 minecraft:glowstone
fill ~6~11~23 ~7~11~23 minecraft:lapis_block
fill ~6~14~23 ~7~14~23 minecraft:lapis_block
fill ~6~15~23 ~7~16~23 minecraft:glowstone
fill ~6~17~23 ~7~17~23 minecraft:lapis_block
fill ~6~18~23 ~7~18~23 minecraft:glowstone
fill ~6~22~23 ~7~22~23 minecraft:glowstone
fill ~6~23~23 ~7~23~23 minecraft:lapis_block
fill ~6~24~23 ~7~25~23 minecraft:glowstone
fill ~6~26~23 ~7~26~23 minecraft:lapis_block
fill ~6~27~23 ~7~28~23 minecraft:glowstone
fill ~6~29~23 ~7~29~23 minecraft:lapis_block
fill ~6~30~23 ~7~31~23 minecraft:glowstone
setblock ~7~1~23 minecraft:lapis_block
setblock ~7~2~23 minecraft:glowstone
fill ~7~3~23 ~7~5~23 minecraft:lapis_block
fill ~7~12~23 ~7~13~23 minecraft:glowstone
setblock ~7~19~23 minecraft:glowstone
setblock ~7~20~23 minecraft:lapis_block
setblock ~7~21~23 minecraft:glowstone
fill ~15~1~23 ~15~1~27 minecraft:lapis_block
fill ~15~2~23 ~15~2~26 minecraft:lapis_block
fill ~15~3~23 ~15~5~25 minecraft:lapis_block
fill ~15~6~23 ~15~7~25 minecraft:glowstone
fill ~15~8~23 ~15~8~25 minecraft:lapis_block
fill ~15~9~23 ~15~10~25 minecraft:glowstone
fill ~15~11~23 ~15~11~25 minecraft:lapis_block
fill ~15~12~23 ~15~13~25 minecraft:glowstone
fill ~15~14~23 ~15~14~25 minecraft:lapis_block
fill ~15~15~23 ~15~16~25 minecraft:glowstone
fill ~15~17~23 ~15~17~25 minecraft:lapis_block
fill ~15~18~23 ~15~19~25 minecraft:glowstone
fill ~15~20~23 ~15~20~25 minecraft:lapis_block
fill ~15~21~23 ~15~22~25 minecraft:glowstone
fill ~15~23~23 ~15~23~25 minecraft:lapis_block
fill ~15~24~23 ~15~25~25 minecraft:glowstone
fill ~15~26~23 ~15~26~25 minecraft:lapis_block
fill ~15~27~23 ~15~28~25 minecraft:glowstone
fill ~15~29~23 ~15~29~25 minecraft:lapis_block
fill ~15~30~23 ~15~31~25 minecraft:glowstone
fill ~15~32~23 ~15~32~25 minecraft:lapis_block
fill ~15~33~23 ~15~33~25 minecraft:glowstone
fill ~16~4~23 ~19~4~24 minecraft:stone_block_slab 5
fill ~17~3~23 ~19~3~24 minecraft:lapis_block
fill ~20~36~23 ~23~36~47 minecraft:stonebrick 0
setblock ~22~3~23 minecraft:stonebrick 0
fill ~23~1~23 ~25~2~23 minecraft:lapis_block
setblock ~23~3~23 minecraft:stone_brick_stairs 1
fill ~24~37~23 ~45~37~27 minecraft:stonebrick 0
fill ~26~1~23 ~26~2~23 minecraft:stonebrick 0
setblock ~26~3~23 minecraft:stone_block_slab 5
fill ~43~1~23 ~43~2~23 minecraft:stonebrick 0
setblock ~43~3~23 minecraft:stone_block_slab 5
fill ~44~2~23 ~45~2~23 minecraft:lapis_block
setblock ~46~3~23 minecraft:stone_brick_stairs 0
fill ~46~36~23 ~49~36~47 minecraft:stonebrick 0
setblock ~47~3~23 minecraft:stonebrick 0
fill ~48~3~23 ~48~3~24 minecraft:lapis_block
setblock ~49~4~23 minecraft:stone_block_slab 5
setblock ~50~4~23 minecraft:stonebrick 0
fill ~51~1~23 ~51~2~25 minecraft:lapis_block
fill ~51~3~23 ~51~4~25 minecraft:glowstone
fill ~51~5~23 ~51~5~25 minecraft:lapis_block
fill ~51~6~23 ~51~7~25 minecraft:glowstone
fill ~51~8~23 ~51~8~25 minecraft:lapis_block
fill ~51~9~23 ~51~10~25 minecraft:glowstone
fill ~51~11~23 ~51~11~25 minecraft:lapis_block
fill ~51~12~23 ~51~13~25 minecraft:glowstone
fill ~51~14~23 ~51~14~25 minecraft:lapis_block
fill ~51~15~23 ~51~16~25 minecraft:glowstone
fill ~51~17~23 ~51~17~25 minecraft:lapis_block
fill ~51~18~23 ~51~19~25 minecraft:glowstone
fill ~51~20~23 ~51~20~25 minecraft:lapis_block
fill ~51~21~23 ~51~22~25 minecraft:glowstone
fill ~51~23~23 ~51~23~25 minecraft:lapis_block
fill ~51~24~23 ~51~25~25 minecraft:glowstone
fill ~51~26~23 ~51~26~25 minecraft:lapis_block
fill ~51~27~23 ~51~28~25 minecraft:glowstone
fill ~51~29~23 ~51~29~25 minecraft:lapis_block
fill ~51~30~23 ~51~31~25 minecraft:glowstone
fill ~51~32~23 ~51~32~25 minecraft:lapis_block
fill ~51~33~23 ~51~34~25 minecraft:glowstone
fill ~2~0~24 ~25~0~65 minecraft:stonebrick 0
fill ~2~26~24 ~2~33~24 minecraft:gold_block
fill ~3~33~24 ~3~33~25 minecraft:glowstone
fill ~8~1~24 ~9~1~24 minecraft:lapis_block
fill ~8~2~24 ~8~5~24 minecraft:lapis_block
fill ~8~6~24 ~9~7~24 minecraft:glowstone
fill ~8~8~24 ~9~8~24 minecraft:lapis_block
fill ~8~9~24 ~9~10~24 minecraft:glowstone
fill ~8~11~24 ~9~11~24 minecraft:lapis_block
fill ~8~12~24 ~9~13~24 minecraft:glowstone
fill ~8~14~24 ~9~14~24 minecraft:lapis_block
fill ~8~15~24 ~9~16~24 minecraft:glowstone
fill ~8~17~24 ~9~17~24 minecraft:lapis_block
fill ~8~18~24 ~9~19~24 minecraft:glowstone
fill ~8~20~24 ~9~20~24 minecraft:lapis_block
fill ~8~21~24 ~9~22~24 minecraft:glowstone
fill ~8~23~24 ~9~23~24 minecraft:lapis_block
fill ~8~24~24 ~9~25~24 minecraft:glowstone
fill ~8~26~24 ~9~26~24 minecraft:lapis_block
fill ~8~27~24 ~9~28~24 minecraft:glowstone
fill ~8~29~24 ~9~29~24 minecraft:lapis_block
fill ~8~30~24 ~9~31~24 minecraft:glowstone
fill ~8~32~24 ~9~32~24 minecraft:lapis_block
setblock ~9~2~24 minecraft:glowstone
fill ~9~3~24 ~9~5~24 minecraft:lapis_block
setblock ~16~3~24 minecraft:lapis_block
setblock ~22~3~24 minecraft:stone_brick_stairs 1
fill ~23~1~24 ~24~2~24 minecraft:lapis_block
fill ~25~1~24 ~25~2~24 minecraft:stonebrick 0
setblock ~25~3~24 minecraft:stone_block_slab 5
setblock ~26~0~24 minecraft:glowstone
fill ~27~0~24 ~42~0~24 minecraft:stonebrick 0
setblock ~43~0~24 minecraft:glowstone
fill ~44~0~24 ~67~0~65 minecraft:stonebrick 0
fill ~44~1~24 ~44~2~24 minecraft:stonebrick 0
setblock ~44~3~24 minecraft:stone_block_slab 5
fill ~45~2~24 ~46~2~24 minecraft:lapis_block
setblock ~47~3~24 minecraft:stone_brick_stairs 0
fill ~49~3~24 ~49~3~27 minecraft:lapis_block
fill ~50~4~24 ~50~4~25 minecraft:stone_brick_stairs 0
setblock ~2~28~25 minecraft:wool 14
setblock ~2~29~25 minecraft:gold_block
setblock ~2~30~25 minecraft:wool 14
setblock ~2~32~25 minecraft:wool 14
setblock ~2~33~25 minecraft:gold_block
fill ~10~1~25 ~10~5~25 minecraft:lapis_block
fill ~10~6~25 ~10~7~25 minecraft:glowstone
setblock ~10~8~25 minecraft:lapis_block
fill ~10~9~25 ~10~10~25 minecraft:glowstone
setblock ~10~11~25 minecraft:lapis_block
fill ~10~12~25 ~10~13~25 minecraft:glowstone
setblock ~10~14~25 minecraft:lapis_block
fill ~10~15~25 ~10~16~25 minecraft:glowstone
setblock ~10~17~25 minecraft:lapis_block
fill ~10~18~25 ~10~19~25 minecraft:glowstone
setblock ~10~20~25 minecraft:lapis_block
fill ~10~21~25 ~10~22~25 minecraft:glowstone
setblock ~10~23~25 minecraft:lapis_block
fill ~10~24~25 ~10~25~25 minecraft:glowstone
setblock ~10~26~25 minecraft:lapis_block
fill ~10~27~25 ~10~28~25 minecraft:glowstone
setblock ~10~29~25 minecraft:lapis_block
fill ~10~30~25 ~10~31~25 minecraft:glowstone
setblock ~10~32~25 minecraft:lapis_block
fill ~16~3~25 ~18~3~25 minecraft:double_stone_block_slab 5
fill ~19~3~25 ~19~3~30 minecraft:lapis_block
setblock ~19~4~25 minecraft:stone_brick_stairs 1
fill ~20~2~25 ~20~2~30 minecraft:lapis_block
setblock ~21~3~25 minecraft:stonebrick 0
setblock ~22~3~25 minecraft:stone_block_slab 5
fill ~23~1~25 ~23~2~26 minecraft:lapis_block
fill ~24~1~25 ~24~2~26 minecraft:stonebrick 0
fill ~24~3~25 ~24~3~26 minecraft:stone_block_slab 5
fill ~26~0~25 ~26~0~40 minecraft:stonebrick 0
setblock ~27~0~25 minecraft:glowstone
fill ~28~0~25 ~41~0~25 minecraft:stonebrick 0
setblock ~42~0~25 minecraft:glowstone
fill ~43~0~25 ~43~0~40 minecraft:stonebrick 0
fill ~45~1~25 ~45~2~26 minecraft:stonebrick 0
fill ~45~3~25 ~45~3~26 minecraft:stone_block_slab 5
fill ~46~2~25 ~46~2~26 minecraft:lapis_block
setblock ~47~3~25 minecraft:stone_block_slab 5
setblock ~48~3~25 minecraft:stonebrick 0
setblock ~2~27~26 minecraft:wool 14
setblock ~2~28~26 minecraft:gold_block
setblock ~2~30~26 minecraft:gold_block
setblock ~2~31~26 minecraft:wool 14
setblock ~2~32~26 minecraft:gold_block
fill ~4~13~26 ~5~13~29 minecraft:stonebrick 0
fill ~4~21~26 ~5~21~29 minecraft:stonebrick 0
fill ~11~1~26 ~14~1~26 minecraft:lapis_block
setblock ~11~2~26 minecraft:glowstone
fill ~11~3~26 ~14~4~26 minecraft:lapis_block
fill ~11~5~26 ~12~5~26 minecraft:lapis_block
fill ~11~6~26 ~12~7~26 minecraft:glowstone
fill ~11~8~26 ~12~8~26 minecraft:lapis_block
fill ~11~9~26 ~12~10~26 minecraft:glowstone
fill ~11~11~26 ~12~11~26 minecraft:lapis_block
fill ~11~12~26 ~12~13~26 minecraft:glowstone
fill ~11~14~26 ~12~14~26 minecraft:lapis_block
fill ~11~15~26 ~12~16~26 minecraft:glowstone
fill ~11~17~26 ~12~17~26 minecraft:lapis_block
fill ~11~18~26 ~12~19~26 minecraft:glowstone
fill ~11~20~26 ~12~20~26 minecraft:lapis_block
fill ~11~21~26 ~12~22~26 minecraft:glowstone
fill ~11~23~26 ~12~23~26 minecraft:lapis_block
fill ~11~24~26 ~12~25~26 minecraft:glowstone
fill ~11~26~26 ~12~26~26 minecraft:lapis_block
fill ~11~27~26 ~12~28~26 minecraft:glowstone
fill ~11~29~26 ~12~29~26 minecraft:lapis_block
fill ~11~30~26 ~12~31~26 minecraft:glowstone
fill ~11~32~26 ~12~32~26 minecraft:lapis_block
fill ~12~2~26 ~14~2~27 minecraft:lapis_block
fill ~12~33~26 ~12~33~28 minecraft:glowstone
fill ~14~5~26 ~14~5~29 minecraft:lapis_block
fill ~14~6~26 ~14~7~29 minecraft:glowstone
fill ~14~8~26 ~14~8~29 minecraft:lapis_block
fill ~14~9~26 ~14~10~29 minecraft:glowstone
fill ~14~11~26 ~14~11~29 minecraft:lapis_block
fill ~14~12~26 ~14~13~29 minecraft:glowstone
fill ~14~14~26 ~14~14~31 minecraft:lapis_block
fill ~14~15~26 ~14~16~31 minecraft:glowstone
fill ~14~17~26 ~14~17~31 minecraft:lapis_block
fill ~14~18~26 ~14~19~31 minecraft:glowstone
fill ~14~20~26 ~14~20~39 minecraft:lapis_block
fill ~14~21~26 ~14~22~39 minecraft:glowstone
fill ~14~23~26 ~14~23~39 minecraft:lapis_block
fill ~14~24~26 ~14~25~39 minecraft:glowstone
fill ~14~26~26 ~14~26~39 minecraft:lapis_block
fill ~14~27~26 ~14~28~39 minecraft:glowstone
fill ~14~29~26 ~14~29~39 minecraft:lapis_block
fill ~14~30~26 ~14~31~39 minecraft:glowstone
fill ~14~32~26 ~14~32~39 minecraft:lapis_block
fill ~14~33~26 ~14~33~39 minecraft:glowstone
fill ~15~3~26 ~17~3~26 minecraft:stone_block_slab 5
fill ~18~3~26 ~18~3~30 minecraft:lapis_block
setblock ~18~4~26 minecraft:stonebrick 0
setblock ~19~4~26 minecraft:stone_block_slab 5
fill ~21~3~26 ~21~3~27 minecraft:stone_brick_stairs 1
fill ~27~0~26 ~27~0~39 minecraft:stonebrick 0
setblock ~28~0~26 minecraft:glowstone
fill ~29~0~26 ~40~0~26 minecraft:stonebrick 0
setblock ~41~0~26 minecraft:glowstone
fill ~42~0~26 ~42~0~39 minecraft:stonebrick 0
fill ~47~2~26 ~47~2~29 minecraft:lapis_block
fill ~48~3~26 ~48~3~27 minecraft:stone_brick_stairs 0
setblock ~50~4~26 minecraft:stone_block_slab 5
setblock ~51~4~26 minecraft:stonebrick 0
fill ~52~1~26 ~52~2~39 minecraft:lapis_block
fill ~52~3~26 ~52~4~39 minecraft:glowstone
fill ~52~5~26 ~52~5~39 minecraft:lapis_block
fill ~52~6~26 ~52~7~39 minecraft:glowstone
fill ~52~8~26 ~52~8~39 minecraft:lapis_block
fill ~52~9~26 ~52~10~39 minecraft:glowstone
fill ~52~11~26 ~52~11~39 minecraft:lapis_block
fill ~52~12~26 ~52~13~39 minecraft:glowstone
fill ~52~14~26 ~52~14~39 minecraft:lapis_block
fill ~52~15~26 ~52~16~39 minecraft:glowstone
fill ~52~17~26 ~52~17~39 minecraft:lapis_block
fill ~52~18~26 ~52~19~39 minecraft:glowstone
fill ~52~20~26 ~52~20~39 minecraft:lapis_block
fill ~52~21~26 ~52~22~39 minecraft:glowstone
fill ~52~23~26 ~52~23~39 minecraft:lapis_block
fill ~52~24~26 ~52~25~39 minecraft:glowstone
fill ~52~26~26 ~52~26~39 minecraft:lapis_block
fill ~52~27~26 ~52~28~39 minecraft:glowstone
fill ~52~29~26 ~52~29~39 minecraft:lapis_block
fill ~52~30~26 ~52~31~39 minecraft:glowstone
fill ~52~32~26 ~52~32~39 minecraft:lapis_block
fill ~52~33~26 ~52~34~39 minecraft:glowstone
fill ~64~1~26 ~65~1~29 minecraft:stonebrick 0
fill ~64~13~26 ~65~13~29 minecraft:stonebrick 0
fill ~64~21~26 ~65~21~29 minecraft:stonebrick 0
fill ~1~15~27 ~1~17~27 minecraft:wool 14
setblock ~2~26~27 minecraft:wool 14
setblock ~2~27~27 minecraft:gold_block
setblock ~2~31~27 minecraft:gold_block
fill ~3~13~27 ~3~13~28 minecraft:stonebrick 0
fill ~3~21~27 ~3~21~28 minecraft:stonebrick 0
fill ~3~22~27 ~3~22~28 minecraft:glowstone
fill ~4~14~27 ~5~18~28 minecraft:stonebrick 0
fill ~4~22~27 ~5~31~28 minecraft:stonebrick 0
fill ~6~13~27 ~6~13~28 minecraft:stonebrick 0
fill ~6~21~27 ~6~21~28 minecraft:stonebrick 0
fill ~12~1~27 ~14~1~28 minecraft:lapis_block
fill ~12~3~27 ~14~4~27 minecraft:lapis_block
fill ~12~5~27 ~12~5~28 minecraft:lapis_block
fill ~12~6~27 ~12~7~28 minecraft:glowstone
fill ~12~8~27 ~12~8~28 minecraft:lapis_block
fill ~12~9~27 ~12~10~28 minecraft:glowstone
fill ~12~11~27 ~12~11~28 minecraft:lapis_block
fill ~12~12~27 ~12~13~28 minecraft:glowstone
fill ~12~14~27 ~12~14~28 minecraft:lapis_block
fill ~12~15~27 ~12~16~28 minecraft:glowstone
fill ~12~17~27 ~12~17~28 minecraft:lapis_block
fill ~12~18~27 ~12~19~28 minecraft:glowstone
fill ~12~20~27 ~12~20~28 minecraft:lapis_block
fill ~12~21~27 ~12~22~28 minecraft:glowstone
fill ~12~23~27 ~12~23~28 minecraft:lapis_block
fill ~12~24~27 ~12~25~28 minecraft:glowstone
fill ~12~26~27 ~12~26~28 minecraft:lapis_block
fill ~12~27~27 ~12~28~28 minecraft:glowstone
fill ~12~29~27 ~12~29~28 minecraft:lapis_block
fill ~12~30~27 ~12~31~28 minecraft:glowstone
fill ~12~32~27 ~12~32~28 minecraft:lapis_block
fill ~15~2~27 ~17~2~27 minecraft:stonebrick 0
fill ~18~2~27 ~18~2~29 minecraft:lapis_block
fill ~18~4~27 ~18~4~30 minecraft:stone_brick_stairs 1
fill ~23~1~27 ~23~2~29 minecraft:stonebrick 0
fill ~23~3~27 ~23~3~29 minecraft:stone_block_slab 5
fill ~28~0~27 ~28~0~38 minecraft:stonebrick 0
setblock ~29~0~27 minecraft:glowstone
fill ~30~0~27 ~39~0~27 minecraft:stonebrick 0
setblock ~40~0~27 minecraft:glowstone
fill ~41~0~27 ~41~0~38 minecraft:stonebrick 0
fill ~46~1~27 ~46~2~29 minecraft:stonebrick 0
fill ~46~3~27 ~46~3~29 minecraft:stone_block_slab 5
fill ~50~3~27 ~50~3~30 minecraft:lapis_block
fill ~51~4~27 ~51~4~30 minecraft:stone_brick_stairs 0
fill ~63~1~27 ~63~1~28 minecraft:stonebrick 0
fill ~63~13~27 ~63~13~28 minecraft:stonebrick 0
fill ~63~21~27 ~63~21~28 minecraft:stonebrick 0
fill ~64~2~27 ~65~11~28 minecraft:stonebrick 0
fill ~64~14~27 ~65~18~28 minecraft:stonebrick 0
fill ~64~22~27 ~65~31~28 minecraft:stonebrick 0
fill ~66~1~27 ~66~1~28 minecraft:stonebrick 0
fill ~66~13~27 ~66~13~28 minecraft:stonebrick 0
fill ~66~21~27 ~66~21~28 minecraft:stonebrick 0
fill ~1~13~28 ~1~14~28 minecraft:wool 14
fill ~1~15~28 ~1~16~28 minecraft:gold_block
fill ~1~17~28 ~1~18~28 minecraft:wool 14
setblock ~2~26~28 minecraft:gold_block
setblock ~12~2~28 minecraft:glowstone
fill ~12~3~28 ~12~4~28 minecraft:lapis_block
fill ~13~2~28 ~14~2~28 minecraft:lapis_block
fill ~13~4~28 ~14~4~29 minecraft:lapis_block
setblock ~14~3~28 minecraft:lapis_block
fill ~15~1~28 ~17~1~29 minecraft:stonebrick 0
fill ~15~2~28 ~17~2~28 minecraft:stone_block_slab 5
fill ~18~1~28 ~18~1~30 minecraft:lapis_block
setblock ~20~3~28 minecraft:stonebrick 0
setblock ~21~3~28 minecraft:stone_block_slab 5
fill ~24~37~28 ~27~37~43 minecraft:stonebrick 0
fill ~28~38~28 ~41~38~31 minecraft:stonebrick 0
fill ~29~0~28 ~29~0~37 minecraft:stonebrick 0
setblock ~30~0~28 minecraft:glowstone
fill ~31~0~28 ~38~0~28 minecraft:stonebrick 0
setblock ~39~0~28 minecraft:glowstone
fill ~40~0~28 ~40~0~37 minecraft:stonebrick 0
fill ~42~37~28 ~45~37~43 minecraft:stonebrick 0
setblock ~48~3~28 minecraft:stone_block_slab 5
setblock ~49~3~28 minecraft:stonebrick 0
fill ~1~11~29 ~1~12~29 minecraft:wool 14
fill ~1~13~29 ~1~14~29 minecraft:gold_block
fill ~1~15~29 ~1~15~31 minecraft:wool 14
fill ~1~16~29 ~1~16~30 minecraft:wool 14
setblock ~1~17~29 minecraft:gold_block
fill ~2~26~29 ~2~32~29 minecraft:wool 14
fill ~13~1~29 ~14~1~29 minecraft:lapis_block
fill ~13~2~29 ~13~3~29 minecraft:lapis_block
setblock ~13~5~29 minecraft:lapis_block
fill ~13~6~29 ~13~7~29 minecraft:glowstone
setblock ~13~8~29 minecraft:lapis_block
fill ~13~9~29 ~13~10~29 minecraft:glowstone
setblock ~13~11~29 minecraft:lapis_block
fill ~13~12~29 ~13~13~29 minecraft:glowstone
fill ~13~14~29 ~13~14~31 minecraft:lapis_block
fill ~13~15~29 ~13~16~31 minecraft:glowstone
fill ~13~17~29 ~13~17~31 minecraft:lapis_block
fill ~13~18~29 ~13~19~31 minecraft:glowstone
fill ~13~20~29 ~13~20~36 minecraft:lapis_block
fill ~13~21~29 ~13~22~36 minecraft:glowstone
fill ~13~23~29 ~13~23~36 minecraft:lapis_block
fill ~13~24~29 ~13~25~36 minecraft:glowstone
fill ~13~26~29 ~13~26~36 minecraft:lapis_block
fill ~13~27~29 ~13~28~36 minecraft:glowstone
fill ~13~29~29 ~13~29~36 minecraft:lapis_block
fill ~13~30~29 ~13~31~36 minecraft:glowstone
fill ~13~32~29 ~13~32~36 minecraft:lapis_block
fill ~13~33~29 ~13~33~36 minecraft:glowstone
fill ~14~2~29 ~14~3~29 minecraft:glowstone
setblock ~20~3~29 minecraft:stone_brick_stairs 1
fill ~30~0~29 ~30~0~36 minecraft:stonebrick 0
setblock ~31~0~29 minecraft:glowstone
fill ~32~0~29 ~37~0~29 minecraft:stonebrick 0
setblock ~38~0~29 minecraft:glowstone
fill ~39~0~29 ~39~0~36 minecraft:stonebrick 0
fill ~48~2~29 ~48~2~36 minecraft:lapis_block
fill ~49~3~29 ~49~3~30 minecraft:stone_brick_stairs 0
fill ~1~9~30 ~1~10~30 minecraft:wool 14
fill ~1~11~30 ~1~12~30 minecraft:gold_block
fill ~1~13~30 ~1~14~35 minecraft:wool 14
fill ~1~17~30 ~1~17~31 minecraft:wool 14
fill ~2~26~30 ~2~26~33 minecraft:gold_block
fill ~2~27~30 ~2~33~30 minecraft:gold_block
fill ~3~33~30 ~3~33~33 minecraft:glowstone
setblock ~13~1~30 minecraft:lapis_block
fill ~13~2~30 ~14~2~30 minecraft:stone_brick_stairs 3
fill ~13~3~30 ~14~3~30 minecraft:stone_brick_stairs 7
fill ~13~4~30 ~14~4~30 minecraft:glowstone
fill ~13~5~30 ~14~5~30 minecraft:stone_brick_stairs 3
fill ~13~6~30 ~14~6~30 minecraft:stone_brick_stairs 7
fill ~13~7~30 ~14~7~30 minecraft:glowstone
fill ~13~8~30 ~14~8~30 minecraft:stone_brick_stairs 3
fill ~13~9~30 ~14~9~30 minecraft:stone_brick_stairs 7
fill ~13~10~30 ~14~10~30 minecraft:glowstone
fill ~13~11~30 ~14~11~30 minecraft:stone_brick_stairs 3
fill ~13~12~30 ~14~12~30 minecraft:stone_brick_stairs 7
fill ~13~13~30 ~14~13~30 minecraft:glowstone
setblock ~14~1~30 minecraft:glowstone
fill ~15~1~30 ~17~1~30 minecraft:stone_block_slab 5
setblock ~18~2~30 minecraft:glowstone
setblock ~20~3~30 minecraft:stonebrick 0
setblock ~21~3~30 minecraft:stone_brick_stairs 1
fill ~22~1~30 ~22~5~30 minecraft:stonebrick 0
fill ~31~0~30 ~31~0~35 minecraft:stonebrick 0
setblock ~32~0~30 minecraft:glowstone
fill ~33~0~30 ~36~0~30 minecraft:stonebrick 0
setblock ~37~0~30 minecraft:glowstone
fill ~38~0~30 ~38~0~35 minecraft:stonebrick 0
fill ~47~1~30 ~47~2~35 minecraft:stonebrick 0
fill ~47~3~30 ~47~3~35 minecraft:stone_block_slab 5
setblock ~1~8~31 minecraft:wool 14
fill ~1~9~31 ~1~10~31 minecraft:gold_block
fill ~1~11~31 ~1~12~34 minecraft:wool 14
setblock ~1~16~31 minecraft:gold_block
fill ~2~29~31 ~2~29~32 minecraft:wool 14
fill ~2~30~31 ~2~30~33 minecraft:gold_block
fill ~2~32~31 ~2~32~32 minecraft:wool 14
fill ~2~33~31 ~2~33~33 minecraft:gold_block
fill ~4~13~31 ~5~13~34 minecraft:stonebrick 0
fill ~4~21~31 ~5~21~34 minecraft:stonebrick 0
fill ~13~13~31 ~14~13~31 minecraft:stone_brick_stairs 7
fill ~18~4~31 ~18~4~34 minecraft:stonebrick 0
fill ~22~4~31 ~22~4~34 minecraft:nether_brick_fence
fill ~22~5~31 ~22~5~35 minecraft:stonebrick 0
setblock ~22~6~31 minecraft:stone_brick_stairs 3
fill ~31~17~31 ~38~17~31 minecraft:lapis_block
fill ~31~18~31 ~31~21~31 minecraft:lapis_block
fill ~31~22~31 ~31~37~31 minecraft:nether_brick_fence
fill ~32~0~31 ~32~0~34 minecraft:stonebrick 0
fill ~32~18~31 ~37~20~31 minecraft:glass_pane
fill ~32~21~31 ~38~21~31 minecraft:lapis_block
setblock ~33~0~31 minecraft:glowstone
fill ~34~0~31 ~35~0~31 minecraft:stonebrick 0
setblock ~36~0~31 minecraft:glowstone
fill ~37~0~31 ~37~0~34 minecraft:stonebrick 0
fill ~38~18~31 ~38~20~31 minecraft:lapis_block
fill ~38~22~31 ~38~37~31 minecraft:nether_brick_fence
fill ~49~3~31 ~50~3~31 minecraft:stonebrick 0
setblock ~51~4~31 minecraft:stonebrick 0
fill ~64~1~31 ~65~1~34 minecraft:stonebrick 0
fill ~64~13~31 ~65~13~34 minecraft:stonebrick 0
fill ~64~21~31 ~65~21~34 minecraft:stonebrick 0
fill ~1~7~32 ~1~7~33 minecraft:wool 14
fill ~1~8~32 ~1~8~33 minecraft:gold_block
fill ~1~9~32 ~1~10~33 minecraft:wool 14
fill ~1~15~32 ~1~15~33 minecraft:gold_block
fill ~1~16~32 ~1~16~33 minecraft:glowstone
fill ~1~17~32 ~1~17~33 minecraft:gold_block
fill ~1~18~32 ~1~18~33 minecraft:wool 14
fill ~3~13~32 ~3~13~33 minecraft:stonebrick 0
fill ~3~21~32 ~3~21~33 minecraft:stonebrick 0
fill ~3~22~32 ~3~22~33 minecraft:glowstone
fill ~4~14~32 ~5~18~33 minecraft:stonebrick 0
fill ~4~22~32 ~5~31~33 minecraft:stonebrick 0
fill ~6~13~32 ~6~13~33 minecraft:stonebrick 0
fill ~6~21~32 ~6~21~33 minecraft:stonebrick 0
fill ~13~19~32 ~14~19~32 minecraft:stone_brick_stairs 7
fill ~22~6~32 ~22~6~33 minecraft:stone_block_slab 5
fill ~28~38~32 ~31~38~39 minecraft:stonebrick 0
fill ~31~17~32 ~31~17~36 minecraft:lapis_block
fill ~31~18~32 ~31~20~35 minecraft:glass_pane
fill ~31~21~32 ~31~21~36 minecraft:lapis_block
fill ~32~17~32 ~37~17~35 minecraft:glass
fill ~32~21~32 ~37~21~35 minecraft:glass
fill ~33~0~32 ~33~0~33 minecraft:stonebrick 0
fill ~34~0~32 ~35~0~33 minecraft:glowstone
fill ~36~0~32 ~36~0~33 minecraft:stonebrick 0
fill ~38~17~32 ~38~17~36 minecraft:lapis_block
fill ~38~18~32 ~38~20~35 minecraft:glass_pane
fill ~38~21~32 ~38~21~36 minecraft:lapis_block
fill ~38~38~32 ~41~38~39 minecraft:stonebrick 0
fill ~49~3~32 ~49~3~33 minecraft:stone_block_slab 0
fill ~50~3~32 ~50~3~33 minecraft:glowstone
fill ~51~4~32 ~51~4~33 minecraft:stone_block_slab 0
fill ~63~1~32 ~63~1~33 minecraft:stonebrick 0
fill ~63~13~32 ~63~13~33 minecraft:stonebrick 0
fill ~63~21~32 ~63~21~33 minecraft:stonebrick 0
fill ~64~2~32 ~65~11~33 minecraft:stonebrick 0
fill ~64~14~32 ~65~18~33 minecraft:stonebrick 0
fill ~64~22~32 ~65~31~33 minecraft:stonebrick 0
fill ~66~1~32 ~66~1~33 minecraft:stonebrick 0
fill ~66~13~32 ~66~13~33 minecraft:stonebrick 0
fill ~66~21~32 ~66~21~33 minecraft:stonebrick 0
fill ~13~19~33 ~14~19~33 minecraft:stone_brick_stairs 6
setblock ~1~8~34 minecraft:wool 14
fill ~1~9~34 ~1~10~34 minecraft:gold_block
fill ~1~15~34 ~1~15~36 minecraft:wool 14
setblock ~1~16~34 minecraft:gold_block
fill ~1~17~34 ~1~17~35 minecraft:wool 14
fill ~2~26~34 ~2~32~34 minecraft:wool 14
fill ~13~13~34 ~14~13~34 minecraft:stone_brick_stairs 6
fill ~13~14~34 ~14~14~36 minecraft:lapis_block
fill ~13~15~34 ~14~16~36 minecraft:glowstone
fill ~13~17~34 ~14~17~36 minecraft:lapis_block
fill ~13~18~34 ~14~19~36 minecraft:glowstone
setblock ~22~6~34 minecraft:stone_brick_stairs 2
setblock ~33~0~34 minecraft:glowstone
fill ~34~0~34 ~35~0~65 minecraft:stonebrick 0
setblock ~36~0~34 minecraft:glowstone
fill ~49~3~34 ~50~3~34 minecraft:stonebrick 0
setblock ~51~4~34 minecraft:stonebrick 0
fill ~1~9~35 ~1~10~35 minecraft:wool 14
fill ~1~11~35 ~1~12~35 minecraft:gold_block
fill ~1~16~35 ~1~16~36 minecraft:wool 14
fill ~2~26~35 ~2~33~35 minecraft:gold_block
setblock ~3~33~35 minecraft:glowstone
fill ~13~1~35 ~13~1~36 minecraft:lapis_block
fill ~13~2~35 ~14~2~35 minecraft:stone_brick_stairs 2
fill ~13~3~35 ~14~3~35 minecraft:stone_brick_stairs 6
fill ~13~4~35 ~14~4~35 minecraft:glowstone
fill ~13~5~35 ~14~5~35 minecraft:stone_brick_stairs 2
fill ~13~6~35 ~14~6~35 minecraft:stone_brick_stairs 6
fill ~13~7~35 ~14~7~36 minecraft:glowstone
fill ~13~8~35 ~14~8~35 minecraft:stone_brick_stairs 2
fill ~13~9~35 ~14~9~35 minecraft:stone_brick_stairs 6
fill ~13~10~35 ~14~10~36 minecraft:glowstone
fill ~13~11~35 ~14~11~35 minecraft:stone_brick_stairs 2
fill ~13~12~35 ~14~12~35 minecraft:stone_brick_stairs 6
fill ~13~13~35 ~14~13~36 minecraft:glowstone
setblock ~14~1~35 minecraft:glowstone
fill ~15~1~35 ~17~1~35 minecraft:stone_block_slab 5
fill ~18~1~35 ~21~1~35 minecraft:lapis_block
setblock ~18~2~35 minecraft:glowstone
fill ~18~3~35 ~19~3~38 minecraft:lapis_block
fill ~18~4~35 ~18~4~38 minecraft:stone_brick_stairs 1
fill ~19~2~35 ~21~2~35 minecraft:lapis_block
setblock ~20~3~35 minecraft:stonebrick 0
setblock ~21~3~35 minecraft:stone_brick_stairs 1
fill ~22~1~35 ~22~4~35 minecraft:stonebrick 0
setblock ~32~0~35 minecraft:glowstone
fill ~33~0~35 ~33~0~65 minecraft:stonebrick 0
fill ~36~0~35 ~36~0~65 minecraft:stonebrick 0
setblock ~37~0~35 minecraft:glowstone
fill ~49~3~35 ~49~3~36 minecraft:stone_brick_stairs 0
fill ~50~3~35 ~50~3~38 minecraft:lapis_block
fill ~51~4~35 ~51~4~38 minecraft:stone_brick_stairs 0
fill ~1~11~36 ~1~12~36 minecraft:wool 14
fill ~1~13~36 ~1~14~36 minecraft:gold_block
setblock ~1~17~36 minecraft:gold_block
setblock ~2~30~36 minecraft:wool 14
setblock ~2~31~36 minecraft:gold_block
fill ~4~13~36 ~5~13~39 minecraft:stonebrick 0
fill ~4~21~36 ~5~21~39 minecraft:stonebrick 0
fill ~13~2~36 ~13~5~36 minecraft:lapis_block
fill ~13~6~36 ~14~6~36 minecraft:glowstone
fill ~13~8~36 ~14~8~36 minecraft:lapis_block
fill ~13~9~36 ~14~9~36 minecraft:glowstone
fill ~13~11~36 ~14~11~36 minecraft:lapis_block
fill ~13~12~36 ~14~12~36 minecraft:glowstone
fill ~14~1~36 ~14~1~39 minecraft:lapis_block
fill ~14~2~36 ~14~3~36 minecraft:glowstone
fill ~14~4~36 ~14~5~39 minecraft:lapis_block
fill ~15~1~36 ~17~1~36 minecraft:stonebrick 0
fill ~18~1~36 ~18~2~39 minecraft:lapis_block
setblock ~20~3~36 minecraft:stone_brick_stairs 1
fill ~21~2~36 ~22~2~36 minecraft:lapis_block
fill ~23~1~36 ~23~2~38 minecraft:stonebrick 0
fill ~23~3~36 ~23~3~38 minecraft:stone_block_slab 5
setblock ~31~0~36 minecraft:glowstone
fill ~31~18~36 ~31~20~36 minecraft:lapis_block
fill ~31~22~36 ~31~37~36 minecraft:nether_brick_fence
fill ~32~0~36 ~32~0~65 minecraft:stonebrick 0
fill ~32~17~36 ~37~17~36 minecraft:lapis_block
fill ~32~18~36 ~37~20~36 minecraft:glass_pane
fill ~32~21~36 ~37~21~36 minecraft:lapis_block
fill ~32~38~36 ~37~38~39 minecraft:stonebrick 0
fill ~37~0~36 ~37~0~65 minecraft:stonebrick 0
setblock ~38~0~36 minecraft:glowstone
fill ~38~18~36 ~38~20~36 minecraft:lapis_block
fill ~38~22~36 ~38~37~36 minecraft:nether_brick_fence
fill ~46~1~36 ~46~2~38 minecraft:stonebrick 0
fill ~46~3~36 ~46~3~38 minecraft:stone_block_slab 5
fill ~47~2~36 ~47~2~39 minecraft:lapis_block
fill ~64~1~36 ~65~1~39 minecraft:stonebrick 0
fill ~64~13~36 ~65~13~39 minecraft:stonebrick 0
fill ~64~21~36 ~65~21~39 minecraft:stonebrick 0
fill ~1~13~37 ~1~14~37 minecraft:wool 14
fill ~1~15~37 ~1~16~37 minecraft:gold_block
fill ~1~17~37 ~1~17~38 minecraft:wool 14
setblock ~1~18~37 minecraft:wool 14
setblock ~2~29~37 minecraft:wool 14
setblock ~2~30~37 minecraft:gold_block
fill ~3~13~37 ~3~13~38 minecraft:stonebrick 0
fill ~3~21~37 ~3~21~38 minecraft:stonebrick 0
fill ~3~22~37 ~3~22~38 minecraft:glowstone
fill ~4~14~37 ~5~18~38 minecraft:stonebrick 0
fill ~4~22~37 ~5~31~38 minecraft:stonebrick 0
fill ~6~13~37 ~6~13~38 minecraft:stonebrick 0
fill ~6~21~37 ~6~21~38 minecraft:stonebrick 0
fill ~12~1~37 ~12~1~38 minecraft:lapis_block
setblock ~12~2~37 minecraft:glowstone
fill ~12~3~37 ~12~5~38 minecraft:lapis_block
fill ~12~6~37 ~12~7~38 minecraft:glowstone
fill ~12~8~37 ~12~8~38 minecraft:lapis_block
fill ~12~9~37 ~12~10~38 minecraft:glowstone
fill ~12~11~37 ~12~11~38 minecraft:lapis_block
fill ~12~12~37 ~12~13~38 minecraft:glowstone
fill ~12~14~37 ~12~14~38 minecraft:lapis_block
fill ~12~15~37 ~12~16~38 minecraft:glowstone
fill ~12~17~37 ~12~17~38 minecraft:lapis_block
fill ~12~18~37 ~12~19~38 minecraft:glowstone
fill ~12~20~37 ~12~20~38 minecraft:lapis_block
fill ~12~21~37 ~12~22~38 minecraft:glowstone
fill ~12~23~37 ~12~23~38 minecraft:lapis_block
fill ~12~24~37 ~12~25~38 minecraft:glowstone
fill ~12~26~37 ~12~26~38 minecraft:lapis_block
fill ~12~27~37 ~12~28~38 minecraft:glowstone
fill ~12~29~37 ~12~29~38 minecraft:lapis_block
fill ~12~30~37 ~12~31~38 minecraft:glowstone
fill ~12~32~37 ~12~32~38 minecraft:lapis_block
fill ~12~33~37 ~12~33~38 minecraft:glowstone
fill ~14~2~37 ~14~3~39 minecraft:lapis_block
fill ~14~6~37 ~14~7~39 minecraft:glowstone
fill ~14~8~37 ~14~8~39 minecraft:lapis_block
fill ~14~9~37 ~14~10~39 minecraft:glowstone
fill ~14~11~37 ~14~11~39 minecraft:lapis_block
fill ~14~12~37 ~14~13~39 minecraft:glowstone
fill ~14~14~37 ~14~14~39 minecraft:lapis_block
fill ~14~15~37 ~14~16~39 minecraft:glowstone
fill ~14~17~37 ~14~17~39 minecraft:lapis_block
fill ~14~18~37 ~14~19~39 minecraft:glowstone
fill ~15~2~37 ~17~2~37 minecraft:stone_block_slab 5
setblock ~20~3~37 minecraft:stonebrick 0
setblock ~21~3~37 minecraft:stone_block_slab 5
fill ~22~2~37 ~22~2~39 minecraft:lapis_block
setblock ~30~0~37 minecraft:glowstone
fill ~31~0~37 ~31~0~65 minecraft:stonebrick 0
fill ~38~0~37 ~38~0~65 minecraft:stonebrick 0
setblock ~39~0~37 minecraft:glowstone
setblock ~48~3~37 minecraft:stone_block_slab 5
setblock ~49~3~37 minecraft:stonebrick 0
fill ~63~1~37 ~63~1~38 minecraft:stonebrick 0
fill ~63~13~37 ~63~13~38 minecraft:stonebrick 0
fill ~63~21~37 ~63~21~38 minecraft:stonebrick 0
fill ~64~2~37 ~65~11~38 minecraft:stonebrick 0
fill ~64~14~37 ~65~18~38 minecraft:stonebrick 0
fill ~64~22~37 ~65~31~38 minecraft:stonebrick 0
fill ~66~1~37 ~66~1~38 minecraft:stonebrick 0
fill ~66~13~37 ~66~13~38 minecraft:stonebrick 0
fill ~66~21~37 ~66~21~38 minecraft:stonebrick 0
fill ~1~15~38 ~1~16~38 minecraft:wool 14
fill ~2~26~38 ~2~28~38 minecraft:wool 14
fill ~2~29~38 ~2~29~39 minecraft:gold_block
fill ~2~30~38 ~2~32~38 minecraft:wool 14
setblock ~12~2~38 minecraft:lapis_block
fill ~15~2~38 ~17~2~38 minecraft:stonebrick 0
fill ~20~3~38 ~20~3~42 minecraft:lapis_block
fill ~21~3~38 ~21~3~39 minecraft:stone_brick_stairs 1
setblock ~29~0~38 minecraft:glowstone
fill ~30~0~38 ~30~0~65 minecraft:stonebrick 0
fill ~39~0~38 ~39~0~65 minecraft:stonebrick 0
setblock ~40~0~38 minecraft:glowstone
fill ~48~3~38 ~48~3~39 minecraft:stone_brick_stairs 0
fill ~49~3~38 ~49~3~41 minecraft:lapis_block
fill ~2~26~39 ~2~28~39 minecraft:gold_block
fill ~2~30~39 ~2~33~39 minecraft:gold_block
setblock ~3~33~39 minecraft:glowstone
setblock ~11~1~39 minecraft:lapis_block
setblock ~11~2~39 minecraft:glowstone
fill ~11~3~39 ~11~5~39 minecraft:lapis_block
fill ~11~6~39 ~11~7~39 minecraft:glowstone
setblock ~11~8~39 minecraft:lapis_block
fill ~11~9~39 ~11~10~39 minecraft:glowstone
setblock ~11~11~39 minecraft:lapis_block
fill ~11~12~39 ~11~13~39 minecraft:glowstone
setblock ~11~14~39 minecraft:lapis_block
fill ~11~15~39 ~11~16~39 minecraft:glowstone
setblock ~11~17~39 minecraft:lapis_block
fill ~11~18~39 ~11~19~39 minecraft:glowstone
setblock ~11~20~39 minecraft:lapis_block
fill ~11~21~39 ~11~22~39 minecraft:glowstone
setblock ~11~23~39 minecraft:lapis_block
fill ~11~24~39 ~11~25~39 minecraft:glowstone
setblock ~11~26~39 minecraft:lapis_block
fill ~11~27~39 ~11~28~39 minecraft:glowstone
setblock ~11~29~39 minecraft:lapis_block
fill ~11~30~39 ~11~31~39 minecraft:glowstone
setblock ~11~32~39 minecraft:lapis_block
fill ~15~3~39 ~17~3~39 minecraft:stone_block_slab 5
setblock ~18~3~39 minecraft:lapis_block
setblock ~18~4~39 minecraft:stonebrick 0
setblock ~19~4~39 minecraft:stone_block_slab 5
fill ~23~2~39 ~23~2~41 minecraft:lapis_block
fill ~24~1~39 ~24~2~40 minecraft:stonebrick 0
fill ~24~3~39 ~24~3~40 minecraft:stone_block_slab 5
setblock ~28~0~39 minecraft:glowstone
fill ~29~0~39 ~29~0~65 minecraft:stonebrick 0
fill ~40~0~39 ~40~0~65 minecraft:stonebrick 0
setblock ~41~0~39 minecraft:glowstone
fill ~45~1~39 ~45~2~40 minecraft:stonebrick 0
fill ~45~3~39 ~45~3~40 minecraft:stone_block_slab 5
fill ~46~2~39 ~46~2~41 minecraft:lapis_block
setblock ~50~4~39 minecraft:stone_block_slab 5
setblock ~51~4~39 minecraft:stonebrick 0
fill ~2~26~40 ~2~30~40 minecraft:wool 14
fill ~10~1~40 ~10~5~40 minecraft:lapis_block
fill ~10~6~40 ~10~7~40 minecraft:glowstone
setblock ~10~8~40 minecraft:lapis_block
fill ~10~9~40 ~10~10~40 minecraft:glowstone
setblock ~10~11~40 minecraft:lapis_block
fill ~10~12~40 ~10~13~40 minecraft:glowstone
setblock ~10~14~40 minecraft:lapis_block
fill ~10~15~40 ~10~16~40 minecraft:glowstone
setblock ~10~17~40 minecraft:lapis_block
fill ~10~18~40 ~10~19~40 minecraft:glowstone
setblock ~10~20~40 minecraft:lapis_block
fill ~10~21~40 ~10~22~40 minecraft:glowstone
setblock ~10~23~40 minecraft:lapis_block
fill ~10~24~40 ~10~25~40 minecraft:glowstone
setblock ~10~26~40 minecraft:lapis_block
fill ~10~27~40 ~10~28~40 minecraft:glowstone
setblock ~10~29~40 minecraft:lapis_block
fill ~10~30~40 ~10~31~40 minecraft:glowstone
setblock ~10~32~40 minecraft:lapis_block
fill ~15~1~40 ~15~5~42 minecraft:lapis_block
fill ~15~6~40 ~15~7~42 minecraft:glowstone
fill ~15~8~40 ~15~8~42 minecraft:lapis_block
fill ~15~9~40 ~15~10~42 minecraft:glowstone
fill ~15~11~40 ~15~11~42 minecraft:lapis_block
fill ~15~12~40 ~15~13~42 minecraft:glowstone
fill ~15~14~40 ~15~14~42 minecraft:lapis_block
fill ~15~15~40 ~15~16~42 minecraft:glowstone
fill ~15~17~40 ~15~17~42 minecraft:lapis_block
fill ~15~18~40 ~15~19~42 minecraft:glowstone
fill ~15~20~40 ~15~20~42 minecraft:lapis_block
fill ~15~21~40 ~15~22~42 minecraft:glowstone
fill ~15~23~40 ~15~23~42 minecraft:lapis_block
fill ~15~24~40 ~15~25~42 minecraft:glowstone
fill ~15~26~40 ~15~26~42 minecraft:lapis_block
fill ~15~27~40 ~15~28~42 minecraft:glowstone
fill ~15~29~40 ~15~29~42 minecraft:lapis_block
fill ~15~30~40 ~15~31~42 minecraft:glowstone
fill ~15~32~40 ~15~32~42 minecraft:lapis_block
fill ~15~33~40 ~15~33~42 minecraft:glowstone
fill ~16~3~40 ~18~3~40 minecraft:stonebrick 0
setblock ~19~4~40 minecraft:stone_brick_stairs 1
setblock ~21~3~40 minecraft:stonebrick 0
setblock ~22~3~40 minecraft:stone_block_slab 5
setblock ~27~0~40 minecraft:glowstone
fill ~28~0~40 ~28~0~65 minecraft:stonebrick 0
fill ~28~37~40 ~41~37~43 minecraft:stonebrick 0
fill ~41~0~40 ~41~0~65 minecraft:stonebrick 0
setblock ~42~0~40 minecraft:glowstone
setblock ~47~3~40 minecraft:stone_block_slab 5
setblock ~48~3~40 minecraft:stonebrick 0
fill ~50~4~40 ~50~4~41 minecraft:stone_brick_stairs 0
fill ~51~1~40 ~51~2~42 minecraft:lapis_block
fill ~51~3~40 ~51~4~42 minecraft:glowstone
fill ~51~5~40 ~51~5~42 minecraft:lapis_block
fill ~51~6~40 ~51~7~42 minecraft:glowstone
fill ~51~8~40 ~51~8~42 minecraft:lapis_block
fill ~51~9~40 ~51~10~42 minecraft:glowstone
fill ~51~11~40 ~51~11~42 minecraft:lapis_block
fill ~51~12~40 ~51~13~42 minecraft:glowstone
fill ~51~14~40 ~51~14~42 minecraft:lapis_block
fill ~51~15~40 ~51~16~42 minecraft:glowstone
fill ~51~17~40 ~51~17~42 minecraft:lapis_block
fill ~51~18~40 ~51~19~42 minecraft:glowstone
fill ~51~20~40 ~51~20~42 minecraft:lapis_block
fill ~51~21~40 ~51~22~42 minecraft:glowstone
fill ~51~23~40 ~51~23~42 minecraft:lapis_block
fill ~51~24~40 ~51~25~42 minecraft:glowstone
fill ~51~26~40 ~51~26~42 minecraft:lapis_block
fill ~51~27~40 ~51~28~42 minecraft:glowstone
fill ~51~29~40 ~51~29~42 minecraft:lapis_block
fill ~51~30~40 ~51~31~42 minecraft:glowstone
fill ~51~32~40 ~51~32~42 minecraft:lapis_block
fill ~51~33~40 ~51~34~42 minecraft:glowstone
fill ~2~26~41 ~2~31~41 minecraft:gold_block
setblock ~2~32~41 minecraft:wool 14
fill ~4~1~41 ~5~1~44 minecraft:stonebrick 0
fill ~4~13~41 ~5~13~44 minecraft:stonebrick 0
fill ~4~21~41 ~5~21~44 minecraft:stonebrick 0
fill ~8~1~41 ~9~1~41 minecraft:lapis_block
fill ~8~2~41 ~8~5~41 minecraft:lapis_block
fill ~8~6~41 ~9~7~41 minecraft:glowstone
fill ~8~8~41 ~9~8~41 minecraft:lapis_block
fill ~8~9~41 ~9~10~41 minecraft:glowstone
fill ~8~11~41 ~9~11~41 minecraft:lapis_block
fill ~8~12~41 ~9~13~41 minecraft:glowstone
fill ~8~14~41 ~9~14~41 minecraft:lapis_block
fill ~8~15~41 ~9~16~41 minecraft:glowstone
fill ~8~17~41 ~9~17~41 minecraft:lapis_block
fill ~8~18~41 ~9~19~41 minecraft:glowstone
fill ~8~20~41 ~9~20~41 minecraft:lapis_block
fill ~8~21~41 ~9~22~41 minecraft:glowstone
fill ~8~23~41 ~9~23~41 minecraft:lapis_block
fill ~8~24~41 ~9~25~41 minecraft:glowstone
fill ~8~26~41 ~9~26~41 minecraft:lapis_block
fill ~8~27~41 ~9~28~41 minecraft:glowstone
fill ~8~29~41 ~9~29~41 minecraft:lapis_block
fill ~8~30~41 ~9~31~41 minecraft:glowstone
fill ~8~32~41 ~9~32~41 minecraft:lapis_block
setblock ~9~2~41 minecraft:glowstone
fill ~9~3~41 ~9~5~41 minecraft:lapis_block
fill ~16~4~41 ~19~4~42 minecraft:stone_block_slab 5
fill ~19~3~41 ~19~3~42 minecraft:lapis_block
fill ~21~3~41 ~21~3~43 minecraft:lapis_block
setblock ~22~3~41 minecraft:stone_brick_stairs 1
fill ~24~2~41 ~24~2~42 minecraft:lapis_block
fill ~25~1~41 ~25~2~41 minecraft:stonebrick 0
setblock ~25~3~41 minecraft:stone_block_slab 5
setblock ~26~0~41 minecraft:glowstone
fill ~27~0~41 ~27~0~65 minecraft:stonebrick 0
fill ~42~0~41 ~42~0~65 minecraft:stonebrick 0
setblock ~43~0~41 minecraft:glowstone
fill ~44~1~41 ~44~2~41 minecraft:stonebrick 0
setblock ~44~3~41 minecraft:stone_block_slab 5
fill ~45~2~41 ~45~2~42 minecraft:lapis_block
setblock ~47~3~41 minecraft:stone_brick_stairs 0
fill ~48~3~41 ~48~3~43 minecraft:lapis_block
fill ~64~1~41 ~65~1~44 minecraft:stonebrick 0
fill ~64~13~41 ~65~13~44 minecraft:stonebrick 0
fill ~64~21~41 ~65~21~44 minecraft:stonebrick 0
fill ~2~1~42 ~3~1~43 minecraft:stonebrick 0
fill ~2~30~42 ~2~30~46 minecraft:gold_block
setblock ~2~32~42 minecraft:gold_block
setblock ~2~33~42 minecraft:wool 14
fill ~3~13~42 ~3~13~43 minecraft:stonebrick 0
fill ~3~21~42 ~3~21~43 minecraft:stonebrick 0
fill ~3~22~42 ~3~22~43 minecraft:glowstone
fill ~3~33~42 ~3~33~44 minecraft:glowstone
fill ~4~2~42 ~5~11~43 minecraft:stonebrick 0
fill ~4~14~42 ~5~18~43 minecraft:stonebrick 0
fill ~4~22~42 ~5~31~43 minecraft:stonebrick 0
fill ~6~1~42 ~6~1~43 minecraft:stonebrick 0
fill ~6~2~42 ~6~5~42 minecraft:lapis_block
fill ~6~6~42 ~7~7~42 minecraft:glowstone
fill ~6~8~42 ~7~8~42 minecraft:lapis_block
fill ~6~9~42 ~7~10~42 minecraft:glowstone
fill ~6~11~42 ~7~11~42 minecraft:lapis_block
fill ~6~13~42 ~6~13~43 minecraft:stonebrick 0
fill ~6~14~42 ~7~14~42 minecraft:lapis_block
fill ~6~15~42 ~7~16~42 minecraft:glowstone
fill ~6~17~42 ~7~17~42 minecraft:lapis_block
fill ~6~18~42 ~7~18~42 minecraft:glowstone
fill ~6~21~42 ~6~21~43 minecraft:stonebrick 0
fill ~6~22~42 ~7~22~42 minecraft:glowstone
fill ~6~23~42 ~7~23~42 minecraft:lapis_block
fill ~6~24~42 ~7~25~42 minecraft:glowstone
fill ~6~26~42 ~7~26~42 minecraft:lapis_block
fill ~6~27~42 ~7~28~42 minecraft:glowstone
fill ~6~29~42 ~7~29~42 minecraft:lapis_block
fill ~6~30~42 ~7~31~42 minecraft:glowstone
setblock ~7~1~42 minecraft:lapis_block
setblock ~7~2~42 minecraft:glowstone
fill ~7~3~42 ~7~5~42 minecraft:lapis_block
fill ~7~12~42 ~7~13~42 minecraft:glowstone
setblock ~7~19~42 minecraft:glowstone
setblock ~7~20~42 minecraft:lapis_block
setblock ~7~21~42 minecraft:glowstone
fill ~22~3~42 ~23~3~42 minecraft:stone_block_slab 5
fill ~25~2~42 ~25~2~43 minecraft:lapis_block
fill ~26~0~42 ~26~0~65 minecraft:stonebrick 0
fill ~26~1~42 ~26~2~42 minecraft:stonebrick 0
setblock ~26~3~42 minecraft:stone_block_slab 5
fill ~43~0~42 ~43~0~65 minecraft:stonebrick 0
fill ~43~1~42 ~43~2~42 minecraft:stonebrick 0
setblock ~43~3~42 minecraft:stone_block_slab 5
fill ~44~2~42 ~44~2~43 minecraft:lapis_block
setblock ~46~3~42 minecraft:stone_brick_stairs 0
setblock ~47~3~42 minecraft:stonebrick 0
setblock ~49~4~42 minecraft:stone_block_slab 5
setblock ~50~4~42 minecraft:stonebrick 0
fill ~63~1~42 ~63~1~43 minecraft:stonebrick 0
fill ~63~13~42 ~63~13~43 minecraft:stonebrick 0
fill ~63~21~42 ~63~21~43 minecraft:stonebrick 0
fill ~64~2~42 ~65~11~43 minecraft:stonebrick 0
fill ~64~14~42 ~65~18~43 minecraft:stonebrick 0
fill ~64~22~42 ~65~31~43 minecraft:stonebrick 0
fill ~66~1~42 ~66~1~43 minecraft:stonebrick 0
fill ~66~13~42 ~66~13~43 minecraft:stonebrick 0
fill ~66~21~42 ~66~21~43 minecraft:stonebrick 0
fill ~2~29~43 ~2~29~45 minecraft:wool 14
fill ~2~33~43 ~2~33~44 minecraft:gold_block
fill ~16~1~43 ~18~5~43 minecraft:lapis_block
fill ~16~6~43 ~18~7~43 minecraft:glowstone
fill ~16~8~43 ~18~8~43 minecraft:lapis_block
fill ~16~9~43 ~18~10~43 minecraft:glowstone
fill ~16~11~43 ~18~11~43 minecraft:lapis_block
fill ~16~12~43 ~18~13~43 minecraft:glowstone
fill ~16~14~43 ~18~14~43 minecraft:lapis_block
fill ~16~15~43 ~18~16~43 minecraft:glowstone
fill ~16~17~43 ~18~17~43 minecraft:lapis_block
fill ~16~18~43 ~18~19~43 minecraft:glowstone
fill ~16~20~43 ~18~20~43 minecraft:lapis_block
fill ~16~21~43 ~18~22~43 minecraft:glowstone
fill ~16~23~43 ~18~23~43 minecraft:lapis_block
fill ~16~24~43 ~18~25~43 minecraft:glowstone
fill ~16~26~43 ~18~26~43 minecraft:lapis_block
fill ~16~27~43 ~18~28~43 minecraft:glowstone
fill ~16~29~43 ~18~29~43 minecraft:lapis_block
fill ~16~30~43 ~18~31~43 minecraft:glowstone
fill ~16~32~43 ~18~32~43 minecraft:lapis_block
fill ~16~33~43 ~18~34~43 minecraft:glowstone
setblock ~19~4~43 minecraft:stonebrick 0
setblock ~20~4~43 minecraft:stone_brick_stairs 1
fill ~22~3~43 ~22~3~44 minecraft:lapis_block
fill ~23~3~43 ~24~3~43 minecraft:stone_block_slab 5
fill ~26~2~43 ~26~2~44 minecraft:lapis_block
fill ~27~1~43 ~28~2~43 minecraft:stonebrick 0
fill ~27~3~43 ~28~3~43 minecraft:stone_block_slab 5
fill ~41~1~43 ~42~2~43 minecraft:stonebrick 0
fill ~41~3~43 ~42~3~43 minecraft:stone_block_slab 5
fill ~43~2~43 ~43~2~44 minecraft:lapis_block
fill ~45~3~43 ~46~3~43 minecraft:stone_block_slab 5
fill ~47~3~43 ~47~3~44 minecraft:lapis_block
setblock ~49~4~43 minecraft:stone_brick_stairs 0
fill ~50~1~43 ~50~2~44 minecraft:lapis_block
fill ~50~3~43 ~50~4~44 minecraft:glowstone
fill ~50~5~43 ~50~5~44 minecraft:lapis_block
fill ~50~6~43 ~50~7~44 minecraft:glowstone
fill ~50~8~43 ~50~8~44 minecraft:lapis_block
fill ~50~9~43 ~50~10~44 minecraft:glowstone
fill ~50~11~43 ~50~11~44 minecraft:lapis_block
fill ~50~12~43 ~50~13~44 minecraft:glowstone
fill ~50~14~43 ~50~14~44 minecraft:lapis_block
fill ~50~15~43 ~50~16~44 minecraft:glowstone
fill ~50~17~43 ~50~17~44 minecraft:lapis_block
fill ~50~18~43 ~50~19~44 minecraft:glowstone
fill ~50~20~43 ~50~20~44 minecraft:lapis_block
fill ~50~21~43 ~50~22~44 minecraft:glowstone
fill ~50~23~43 ~50~23~44 minecraft:lapis_block
fill ~50~24~43 ~50~25~44 minecraft:glowstone
fill ~50~26~43 ~50~26~44 minecraft:lapis_block
fill ~50~27~43 ~50~28~44 minecraft:glowstone
fill ~50~29~43 ~50~29~44 minecraft:lapis_block
fill ~50~30~43 ~50~31~44 minecraft:glowstone
fill ~50~32~43 ~50~32~44 minecraft:lapis_block
fill ~50~33~43 ~50~34~44 minecraft:glowstone
fill ~2~1~44 ~2~1~65 minecraft:stonebrick 0
setblock ~2~32~44 minecraft:wool 14
fill ~19~1~44 ~19~5~44 minecraft:lapis_block
fill ~19~6~44 ~19~7~44 minecraft:glowstone
setblock ~19~8~44 minecraft:lapis_block
fill ~19~9~44 ~19~10~44 minecraft:glowstone
setblock ~19~11~44 minecraft:lapis_block
fill ~19~12~44 ~19~13~44 minecraft:glowstone
setblock ~19~14~44 minecraft:lapis_block
fill ~19~15~44 ~19~16~44 minecraft:glowstone
setblock ~19~17~44 minecraft:lapis_block
fill ~19~18~44 ~19~19~44 minecraft:glowstone
setblock ~19~20~44 minecraft:lapis_block
fill ~19~21~44 ~19~22~44 minecraft:glowstone
setblock ~19~23~44 minecraft:lapis_block
fill ~19~24~44 ~19~25~44 minecraft:glowstone
setblock ~19~26~44 minecraft:lapis_block
fill ~19~27~44 ~19~28~44 minecraft:glowstone
setblock ~19~29~44 minecraft:lapis_block
fill ~19~30~44 ~19~31~44 minecraft:glowstone
setblock ~19~32~44 minecraft:lapis_block
fill ~19~33~44 ~19~34~44 minecraft:glowstone
fill ~20~4~44 ~21~4~44 minecraft:stone_block_slab 5
fill ~23~3~44 ~23~3~45 minecraft:lapis_block
setblock ~24~3~44 minecraft:stone_block_slab 5
fill ~24~36~44 ~45~36~47 minecraft:stonebrick 0
setblock ~25~3~44 minecraft:stone_brick_stairs 2
fill ~27~2~44 ~28~2~44 minecraft:lapis_block
fill ~29~1~44 ~31~2~44 minecraft:stonebrick 0
fill ~29~3~44 ~31~3~44 minecraft:stone_block_slab 5
fill ~38~1~44 ~40~2~44 minecraft:stonebrick 0
fill ~38~3~44 ~40~3~44 minecraft:stone_block_slab 5
fill ~41~2~44 ~42~2~44 minecraft:lapis_block
fill ~44~3~44 ~45~3~44 minecraft:stone_block_slab 5
fill ~46~3~44 ~46~3~45 minecraft:lapis_block
setblock ~48~4~44 minecraft:stone_brick_stairs 0
setblock ~49~4~44 minecraft:stonebrick 0
fill ~2~27~45 ~2~28~45 minecraft:wool 14
setblock ~2~31~45 minecraft:wool 14
setblock ~2~32~45 minecraft:gold_block
fill ~20~1~45 ~20~5~45 minecraft:lapis_block
fill ~20~6~45 ~20~7~45 minecraft:glowstone
setblock ~20~8~45 minecraft:lapis_block
fill ~20~9~45 ~20~10~45 minecraft:glowstone
setblock ~20~11~45 minecraft:lapis_block
fill ~20~12~45 ~20~13~45 minecraft:glowstone
setblock ~20~14~45 minecraft:lapis_block
fill ~20~15~45 ~20~16~45 minecraft:glowstone
setblock ~20~17~45 minecraft:lapis_block
fill ~20~18~45 ~20~19~45 minecraft:glowstone
setblock ~20~20~45 minecraft:lapis_block
fill ~20~21~45 ~20~22~45 minecraft:glowstone
setblock ~20~23~45 minecraft:lapis_block
fill ~20~24~45 ~20~25~45 minecraft:glowstone
setblock ~20~26~45 minecraft:lapis_block
fill ~20~27~45 ~20~28~45 minecraft:glowstone
setblock ~20~29~45 minecraft:lapis_block
fill ~20~30~45 ~20~31~45 minecraft:glowstone
setblock ~20~32~45 minecraft:lapis_block
fill ~20~33~45 ~20~34~45 minecraft:glowstone
setblock ~20~35~45 minecraft:lapis_block
fill ~21~4~45 ~22~4~45 minecraft:stone_block_slab 5
fill ~24~3~45 ~24~3~46 minecraft:lapis_block
setblock ~25~3~45 minecraft:stonebrick 0
setblock ~26~3~45 minecraft:stone_brick_stairs 2
setblock ~27~3~45 minecraft:stone_block_slab 5
fill ~28~2~45 ~31~2~45 minecraft:lapis_block
fill ~32~1~45 ~37~2~45 minecraft:stonebrick 0
fill ~32~3~45 ~37~3~45 minecraft:stone_block_slab 5
fill ~38~2~45 ~41~2~45 minecraft:lapis_block
setblock ~42~3~45 minecraft:stone_brick_stairs 2
fill ~43~3~45 ~44~3~45 minecraft:stone_block_slab 5
fill ~45~3~45 ~45~3~46 minecraft:lapis_block
fill ~47~4~45 ~48~4~45 minecraft:stone_block_slab 5
fill ~49~1~45 ~49~2~45 minecraft:lapis_block
fill ~49~3~45 ~49~4~45 minecraft:glowstone
setblock ~49~5~45 minecraft:lapis_block
fill ~49~6~45 ~49~7~45 minecraft:glowstone
setblock ~49~8~45 minecraft:lapis_block
fill ~49~9~45 ~49~10~45 minecraft:glowstone
setblock ~49~11~45 minecraft:lapis_block
fill ~49~12~45 ~49~13~45 minecraft:glowstone
setblock ~49~14~45 minecraft:lapis_block
fill ~49~15~45 ~49~16~45 minecraft:glowstone
setblock ~49~17~45 minecraft:lapis_block
fill ~49~18~45 ~49~19~45 minecraft:glowstone
setblock ~49~20~45 minecraft:lapis_block
fill ~49~21~45 ~49~22~45 minecraft:glowstone
setblock ~49~23~45 minecraft:lapis_block
fill ~49~24~45 ~49~25~45 minecraft:glowstone
setblock ~49~26~45 minecraft:lapis_block
fill ~49~27~45 ~49~28~45 minecraft:glowstone
setblock ~49~29~45 minecraft:lapis_block
fill ~49~30~45 ~49~31~45 minecraft:glowstone
setblock ~49~32~45 minecraft:lapis_block
fill ~49~33~45 ~49~34~45 minecraft:glowstone
setblock ~49~35~45 minecraft:lapis_block
fill ~1~15~46 ~1~17~46 minecraft:wool 14
fill ~2~26~46 ~2~29~46 minecraft:gold_block
setblock ~2~31~46 minecraft:gold_block
fill ~4~1~46 ~5~1~49 minecraft:stonebrick 0
fill ~4~13~46 ~5~13~49 minecraft:stonebrick 0
fill ~4~21~46 ~5~21~49 minecraft:stonebrick 0
fill ~21~1~46 ~21~5~46 minecraft:lapis_block
fill ~21~6~46 ~21~7~46 minecraft:glowstone
setblock ~21~8~46 minecraft:lapis_block
fill ~21~9~46 ~21~10~46 minecraft:glowstone
setblock ~21~11~46 minecraft:lapis_block
fill ~21~12~46 ~21~13~46 minecraft:glowstone
setblock ~21~14~46 minecraft:lapis_block
fill ~21~15~46 ~21~16~46 minecraft:glowstone
setblock ~21~17~46 minecraft:lapis_block
fill ~21~18~46 ~21~19~46 minecraft:glowstone
setblock ~21~20~46 minecraft:lapis_block
fill ~21~21~46 ~21~22~46 minecraft:glowstone
setblock ~21~23~46 minecraft:lapis_block
fill ~21~24~46 ~21~25~46 minecraft:glowstone
setblock ~21~26~46 minecraft:lapis_block
fill ~21~27~46 ~21~28~46 minecraft:glowstone
setblock ~21~29~46 minecraft:lapis_block
fill ~21~30~46 ~21~31~46 minecraft:glowstone
setblock ~21~32~46 minecraft:lapis_block
fill ~21~33~46 ~21~34~46 minecraft:glowstone
setblock ~21~35~46 minecraft:lapis_block
setblock ~22~4~46 minecraft:stone_block_slab 5
setblock ~23~4~46 minecraft:stone_brick_stairs 2
fill ~25~3~46 ~26~3~46 minecraft:lapis_block
setblock ~27~3~46 minecraft:stonebrick 0
fill ~28~3~46 ~29~3~46 minecraft:stone_brick_stairs 2
setblock ~30~3~46 minecraft:stone_block_slab 5
fill ~31~2~46 ~38~2~46 minecraft:lapis_block
setblock ~39~3~46 minecraft:stone_block_slab 5
fill ~40~3~46 ~41~3~46 minecraft:stone_brick_stairs 2
setblock ~42~3~46 minecraft:stonebrick 0
fill ~43~3~46 ~44~3~46 minecraft:lapis_block
fill ~46~4~46 ~47~4~46 minecraft:stone_block_slab 5
fill ~48~1~46 ~48~2~46 minecraft:lapis_block
fill ~48~3~46 ~48~4~46 minecraft:glowstone
setblock ~48~5~46 minecraft:lapis_block
fill ~48~6~46 ~48~7~46 minecraft:glowstone
setblock ~48~8~46 minecraft:lapis_block
fill ~48~9~46 ~48~10~46 minecraft:glowstone
setblock ~48~11~46 minecraft:lapis_block
fill ~48~12~46 ~48~13~46 minecraft:glowstone
setblock ~48~14~46 minecraft:lapis_block
fill ~48~15~46 ~48~16~46 minecraft:glowstone
setblock ~48~17~46 minecraft:lapis_block
fill ~48~18~46 ~48~19~46 minecraft:glowstone
setblock ~48~20~46 minecraft:lapis_block
fill ~48~21~46 ~48~22~46 minecraft:glowstone
setblock ~48~23~46 minecraft:lapis_block
fill ~48~24~46 ~48~25~46 minecraft:glowstone
setblock ~48~26~46 minecraft:lapis_block
fill ~48~27~46 ~48~28~46 minecraft:glowstone
setblock ~48~29~46 minecraft:lapis_block
fill ~48~30~46 ~48~31~46 minecraft:glowstone
setblock ~48~32~46 minecraft:lapis_block
fill ~48~33~46 ~48~34~46 minecraft:glowstone
setblock ~48~35~46 minecraft:lapis_block
fill ~64~1~46 ~65~1~49 minecraft:stonebrick 0
fill ~64~13~46 ~65~13~49 minecraft:stonebrick 0
fill ~64~21~46 ~65~21~49 minecraft:stonebrick 0
fill ~1~13~47 ~1~14~47 minecraft:wool 14
fill ~1~15~47 ~1~16~47 minecraft:gold_block
fill ~1~17~47 ~1~18~47 minecraft:wool 14
fill ~3~1~47 ~3~1~48 minecraft:stonebrick 0
fill ~3~13~47 ~3~13~48 minecraft:stonebrick 0
fill ~3~21~47 ~3~21~48 minecraft:stonebrick 0
fill ~3~22~47 ~3~22~48 minecraft:glowstone
fill ~4~2~47 ~5~11~48 minecraft:stonebrick 0
fill ~4~14~47 ~5~18~48 minecraft:stonebrick 0
fill ~4~22~47 ~5~31~48 minecraft:stonebrick 0
fill ~6~1~47 ~6~1~48 minecraft:stonebrick 0
fill ~6~13~47 ~6~13~48 minecraft:stonebrick 0
fill ~6~21~47 ~6~21~48 minecraft:stonebrick 0
fill ~22~1~47 ~22~5~47 minecraft:lapis_block
fill ~22~6~47 ~22~7~47 minecraft:glowstone
setblock ~22~8~47 minecraft:lapis_block
fill ~22~9~47 ~22~10~47 minecraft:glowstone
setblock ~22~11~47 minecraft:lapis_block
fill ~22~12~47 ~22~13~47 minecraft:glowstone
setblock ~22~14~47 minecraft:lapis_block
fill ~22~15~47 ~22~16~47 minecraft:glowstone
setblock ~22~17~47 minecraft:lapis_block
fill ~22~18~47 ~22~19~47 minecraft:glowstone
setblock ~22~20~47 minecraft:lapis_block
fill ~22~21~47 ~22~22~47 minecraft:glowstone
setblock ~22~23~47 minecraft:lapis_block
fill ~22~24~47 ~22~25~47 minecraft:glowstone
setblock ~22~26~47 minecraft:lapis_block
fill ~22~27~47 ~22~28~47 minecraft:glowstone
setblock ~22~29~47 minecraft:lapis_block
fill ~22~30~47 ~22~31~47 minecraft:glowstone
setblock ~22~32~47 minecraft:lapis_block
fill ~22~33~47 ~22~34~47 minecraft:glowstone
setblock ~22~35~47 minecraft:lapis_block
setblock ~23~4~47 minecraft:stonebrick 0
setblock ~24~4~47 minecraft:stone_brick_stairs 2
setblock ~25~4~47 minecraft:stone_block_slab 5
fill ~26~3~47 ~29~3~47 minecraft:lapis_block
setblock ~30~3~47 minecraft:stonebrick 0
fill ~31~3~47 ~32~3~47 minecraft:stone_brick_stairs 2
setblock ~33~3~47 minecraft:stonebrick 0
fill ~34~3~47 ~35~3~47 minecraft:stone_block_slab 0
setblock ~36~3~47 minecraft:stonebrick 0
fill ~37~3~47 ~38~3~47 minecraft:stone_brick_stairs 2
setblock ~39~3~47 minecraft:stonebrick 0
fill ~40~3~47 ~43~3~47 minecraft:lapis_block
setblock ~44~4~47 minecraft:stone_block_slab 5
setblock ~45~4~47 minecraft:stone_brick_stairs 2
setblock ~46~4~47 minecraft:stone_block_slab 5
fill ~47~1~47 ~47~2~47 minecraft:lapis_block
fill ~47~3~47 ~47~4~47 minecraft:glowstone
setblock ~47~5~47 minecraft:lapis_block
fill ~47~6~47 ~47~7~47 minecraft:glowstone
setblock ~47~8~47 minecraft:lapis_block
fill ~47~9~47 ~47~10~47 minecraft:glowstone
setblock ~47~11~47 minecraft:lapis_block
fill ~47~12~47 ~47~13~47 minecraft:glowstone
setblock ~47~14~47 minecraft:lapis_block
fill ~47~15~47 ~47~16~47 minecraft:glowstone
setblock ~47~17~47 minecraft:lapis_block
fill ~47~18~47 ~47~19~47 minecraft:glowstone
setblock ~47~20~47 minecraft:lapis_block
fill ~47~21~47 ~47~22~47 minecraft:glowstone
setblock ~47~23~47 minecraft:lapis_block
fill ~47~24~47 ~47~25~47 minecraft:glowstone
setblock ~47~26~47 minecraft:lapis_block
fill ~47~27~47 ~47~28~47 minecraft:glowstone
setblock ~47~29~47 minecraft:lapis_block
fill ~47~30~47 ~47~31~47 minecraft:glowstone
setblock ~47~32~47 minecraft:lapis_block
fill ~47~33~47 ~47~34~47 minecraft:glowstone
setblock ~47~35~47 minecraft:lapis_block
fill ~63~1~47 ~63~1~48 minecraft:stonebrick 0
fill ~63~13~47 ~63~13~48 minecraft:stonebrick 0
fill ~63~21~47 ~63~21~48 minecraft:stonebrick 0
fill ~64~2~47 ~65~11~48 minecraft:stonebrick 0
fill ~64~14~47 ~65~18~48 minecraft:stonebrick 0
fill ~64~22~47 ~65~31~48 minecraft:stonebrick 0
fill ~66~1~47 ~66~1~48 minecraft:stonebrick 0
fill ~66~13~47 ~66~13~48 minecraft:stonebrick 0
fill ~66~21~47 ~66~21~48 minecraft:stonebrick 0
fill ~1~11~48 ~1~12~48 minecraft:wool 14
fill ~1~13~48 ~1~14~48 minecraft:gold_block
fill ~1~15~48 ~1~15~50 minecraft:wool 14
fill ~1~16~48 ~1~16~49 minecraft:wool 14
setblock ~1~17~48 minecraft:gold_block
fill ~20~35~48 ~49~35~51 minecraft:stonebrick 0
fill ~23~1~48 ~24~5~48 minecraft:lapis_block
fill ~23~6~48 ~24~7~48 minecraft:glowstone
fill ~23~8~48 ~24~8~48 minecraft:lapis_block
fill ~23~9~48 ~24~10~48 minecraft:glowstone
fill ~23~11~48 ~24~11~48 minecraft:lapis_block
fill ~23~12~48 ~24~13~48 minecraft:glowstone
fill ~23~14~48 ~24~14~48 minecraft:lapis_block
fill ~23~15~48 ~24~16~48 minecraft:glowstone
fill ~23~17~48 ~24~17~48 minecraft:lapis_block
fill ~23~18~48 ~24~19~48 minecraft:glowstone
fill ~23~20~48 ~24~20~48 minecraft:lapis_block
fill ~23~21~48 ~24~22~48 minecraft:glowstone
fill ~23~23~48 ~24~23~48 minecraft:lapis_block
fill ~23~24~48 ~24~25~48 minecraft:glowstone
fill ~23~26~48 ~24~26~48 minecraft:lapis_block
fill ~23~27~48 ~24~28~48 minecraft:glowstone
fill ~23~29~48 ~24~29~48 minecraft:lapis_block
fill ~23~30~48 ~24~31~48 minecraft:glowstone
fill ~23~32~48 ~24~32~48 minecraft:lapis_block
fill ~23~33~48 ~24~34~48 minecraft:glowstone
setblock ~25~4~48 minecraft:stonebrick 0
fill ~26~4~48 ~27~4~48 minecraft:stone_brick_stairs 2
setblock ~28~4~48 minecraft:stone_block_slab 5
fill ~29~3~48 ~33~3~48 minecraft:lapis_block
fill ~34~3~48 ~35~3~48 minecraft:glowstone
fill ~36~3~48 ~40~3~48 minecraft:lapis_block
setblock ~41~4~48 minecraft:stone_block_slab 5
fill ~42~4~48 ~43~4~48 minecraft:stone_brick_stairs 2
setblock ~44~4~48 minecraft:stonebrick 0
fill ~45~1~48 ~46~2~48 minecraft:lapis_block
fill ~45~3~48 ~46~4~48 minecraft:glowstone
fill ~45~5~48 ~46~5~48 minecraft:lapis_block
fill ~45~6~48 ~46~7~48 minecraft:glowstone
fill ~45~8~48 ~46~8~48 minecraft:lapis_block
fill ~45~9~48 ~46~10~48 minecraft:glowstone
fill ~45~11~48 ~46~11~48 minecraft:lapis_block
fill ~45~12~48 ~46~13~48 minecraft:glowstone
fill ~45~14~48 ~46~14~48 minecraft:lapis_block
fill ~45~15~48 ~46~16~48 minecraft:glowstone
fill ~45~17~48 ~46~17~48 minecraft:lapis_block
fill ~45~18~48 ~46~19~48 minecraft:glowstone
fill ~45~20~48 ~46~20~48 minecraft:lapis_block
fill ~45~21~48 ~46~22~48 minecraft:glowstone
fill ~45~23~48 ~46~23~48 minecraft:lapis_block
fill ~45~24~48 ~46~25~48 minecraft:glowstone
fill ~45~26~48 ~46~26~48 minecraft:lapis_block
fill ~45~27~48 ~46~28~48 minecraft:glowstone
fill ~45~29~48 ~46~29~48 minecraft:lapis_block
fill ~45~30~48 ~46~31~48 minecraft:glowstone
fill ~45~32~48 ~46~32~48 minecraft:lapis_block
fill ~45~33~48 ~46~34~48 minecraft:glowstone
fill ~1~9~49 ~1~10~49 minecraft:wool 14
fill ~1~11~49 ~1~12~49 minecraft:gold_block
fill ~1~13~49 ~1~14~54 minecraft:wool 14
fill ~1~17~49 ~1~17~50 minecraft:wool 14
fill ~25~1~49 ~27~5~49 minecraft:lapis_block
fill ~25~6~49 ~27~7~49 minecraft:glowstone
fill ~25~8~49 ~27~8~49 minecraft:lapis_block
fill ~25~9~49 ~27~10~49 minecraft:glowstone
fill ~25~11~49 ~27~11~49 minecraft:lapis_block
fill ~25~12~49 ~27~13~49 minecraft:glowstone
fill ~25~14~49 ~27~14~49 minecraft:lapis_block
fill ~25~15~49 ~27~16~49 minecraft:glowstone
fill ~25~17~49 ~27~17~49 minecraft:lapis_block
fill ~25~18~49 ~27~19~49 minecraft:glowstone
fill ~25~20~49 ~27~20~49 minecraft:lapis_block
fill ~25~21~49 ~27~22~49 minecraft:glowstone
fill ~25~23~49 ~27~23~49 minecraft:lapis_block
fill ~25~24~49 ~27~25~49 minecraft:glowstone
fill ~25~26~49 ~27~26~49 minecraft:lapis_block
fill ~25~27~49 ~27~28~49 minecraft:glowstone
fill ~25~29~49 ~27~29~49 minecraft:lapis_block
fill ~25~30~49 ~27~31~49 minecraft:glowstone
fill ~25~32~49 ~27~32~49 minecraft:lapis_block
fill ~25~33~49 ~27~34~49 minecraft:glowstone
setblock ~28~4~49 minecraft:stonebrick 0
fill ~29~4~49 ~32~4~49 minecraft:stone_brick_stairs 2
setblock ~33~4~49 minecraft:stonebrick 0
fill ~34~4~49 ~35~4~49 minecraft:stone_block_slab 0
setblock ~36~4~49 minecraft:stonebrick 0
fill ~37~4~49 ~40~4~49 minecraft:stone_brick_stairs 2
setblock ~41~4~49 minecraft:stonebrick 0
fill ~42~1~49 ~44~2~49 minecraft:lapis_block
fill ~42~3~49 ~44~4~49 minecraft:glowstone
fill ~42~5~49 ~44~5~49 minecraft:lapis_block
fill ~42~6~49 ~44~7~49 minecraft:glowstone
fill ~42~8~49 ~44~8~49 minecraft:lapis_block
fill ~42~9~49 ~44~10~49 minecraft:glowstone
fill ~42~11~49 ~44~11~49 minecraft:lapis_block
fill ~42~12~49 ~44~13~49 minecraft:glowstone
fill ~42~14~49 ~44~14~49 minecraft:lapis_block
fill ~42~15~49 ~44~16~49 minecraft:glowstone
fill ~42~17~49 ~44~17~49 minecraft:lapis_block
fill ~42~18~49 ~44~19~49 minecraft:glowstone
fill ~42~20~49 ~44~20~49 minecraft:lapis_block
fill ~42~21~49 ~44~22~49 minecraft:glowstone
fill ~42~23~49 ~44~23~49 minecraft:lapis_block
fill ~42~24~49 ~44~25~49 minecraft:glowstone
fill ~42~26~49 ~44~26~49 minecraft:lapis_block
fill ~42~27~49 ~44~28~49 minecraft:glowstone
fill ~42~29~49 ~44~29~49 minecraft:lapis_block
fill ~42~30~49 ~44~31~49 minecraft:glowstone
fill ~42~32~49 ~44~32~49 minecraft:lapis_block
fill ~42~33~49 ~44~34~49 minecraft:glowstone
setblock ~1~8~50 minecraft:wool 14
fill ~1~9~50 ~1~10~50 minecraft:gold_block
fill ~1~11~50 ~1~12~53 minecraft:wool 14
setblock ~1~16~50 minecraft:gold_block
fill ~28~1~50 ~41~2~50 minecraft:lapis_block
fill ~28~3~50 ~41~4~50 minecraft:glowstone
fill ~28~5~50 ~41~5~50 minecraft:lapis_block
fill ~28~6~50 ~41~7~50 minecraft:glowstone
fill ~28~8~50 ~41~8~50 minecraft:lapis_block
fill ~28~9~50 ~41~10~50 minecraft:glowstone
fill ~28~11~50 ~41~11~50 minecraft:lapis_block
fill ~28~12~50 ~41~13~50 minecraft:glowstone
fill ~28~14~50 ~41~14~50 minecraft:lapis_block
fill ~28~15~50 ~41~16~50 minecraft:glowstone
fill ~28~17~50 ~41~17~50 minecraft:lapis_block
fill ~28~18~50 ~41~19~50 minecraft:glowstone
fill ~28~20~50 ~41~20~50 minecraft:lapis_block
fill ~28~21~50 ~41~22~50 minecraft:glowstone
fill ~28~23~50 ~41~23~50 minecraft:lapis_block
fill ~28~24~50 ~41~25~50 minecraft:glowstone
fill ~28~26~50 ~41~26~50 minecraft:lapis_block
fill ~28~27~50 ~41~28~50 minecraft:glowstone
fill ~28~29~50 ~41~29~50 minecraft:lapis_block
fill ~28~30~50 ~41~31~50 minecraft:glowstone
fill ~28~32~50 ~41~32~50 minecraft:lapis_block
fill ~28~33~50 ~41~34~50 minecraft:glowstone
fill ~1~7~51 ~1~7~52 minecraft:wool 14
fill ~1~8~51 ~1~8~52 minecraft:gold_block
fill ~1~9~51 ~1~10~52 minecraft:wool 14
fill ~1~15~51 ~1~15~52 minecraft:gold_block
fill ~1~16~51 ~1~16~52 minecraft:glowstone
fill ~1~17~51 ~1~17~52 minecraft:gold_block
fill ~1~18~51 ~1~18~52 minecraft:wool 14
fill ~4~1~51 ~5~1~54 minecraft:stonebrick 0
fill ~4~13~51 ~5~13~54 minecraft:stonebrick 0
fill ~4~21~51 ~5~21~54 minecraft:stonebrick 0
fill ~64~1~51 ~65~1~54 minecraft:stonebrick 0
fill ~64~13~51 ~65~13~54 minecraft:stonebrick 0
fill ~64~21~51 ~65~21~54 minecraft:stonebrick 0
fill ~3~1~52 ~3~1~53 minecraft:stonebrick 0
fill ~3~13~52 ~3~13~53 minecraft:stonebrick 0
fill ~3~21~52 ~3~21~53 minecraft:stonebrick 0
fill ~4~2~52 ~5~11~53 minecraft:stonebrick 0
fill ~4~14~52 ~5~18~53 minecraft:stonebrick 0
fill ~4~22~52 ~5~31~53 minecraft:stonebrick 0
fill ~6~1~52 ~6~1~53 minecraft:stonebrick 0
fill ~6~13~52 ~6~13~53 minecraft:stonebrick 0
fill ~6~21~52 ~6~21~53 minecraft:stonebrick 0
fill ~16~34~52 ~53~34~55 minecraft:stonebrick 0
fill ~63~1~52 ~63~1~53 minecraft:stonebrick 0
fill ~63~13~52 ~63~13~53 minecraft:stonebrick 0
fill ~63~21~52 ~63~21~53 minecraft:stonebrick 0
fill ~64~2~52 ~65~11~53 minecraft:stonebrick 0
fill ~64~14~52 ~65~18~53 minecraft:stonebrick 0
fill ~64~22~52 ~65~31~53 minecraft:stonebrick 0
fill ~66~1~52 ~66~1~53 minecraft:stonebrick 0
fill ~66~13~52 ~66~13~53 minecraft:stonebrick 0
fill ~66~21~52 ~66~21~53 minecraft:stonebrick 0
setblock ~1~8~53 minecraft:wool 14
fill ~1~9~53 ~1~10~53 minecraft:gold_block
fill ~1~15~53 ~1~15~55 minecraft:wool 14
setblock ~1~16~53 minecraft:gold_block
fill ~1~17~53 ~1~17~54 minecraft:wool 14
fill ~1~9~54 ~1~10~54 minecraft:wool 14
fill ~1~11~54 ~1~12~54 minecraft:gold_block
fill ~1~16~54 ~1~16~55 minecraft:wool 14
fill ~1~11~55 ~1~12~55 minecraft:wool 14
fill ~1~13~55 ~1~14~55 minecraft:gold_block
setblock ~1~17~55 minecraft:gold_block
fill ~1~13~56 ~1~14~56 minecraft:wool 14
fill ~1~15~56 ~1~16~56 minecraft:gold_block
fill ~1~17~56 ~1~17~57 minecraft:wool 14
setblock ~1~18~56 minecraft:wool 14
fill ~4~1~56 ~5~1~59 minecraft:stonebrick 0
fill ~4~13~56 ~5~13~59 minecraft:stonebrick 0
fill ~4~21~56 ~5~21~59 minecraft:stonebrick 0
fill ~12~33~56 ~57~33~59 minecraft:stonebrick 0
fill ~64~1~56 ~65~1~59 minecraft:stonebrick 0
fill ~64~13~56 ~65~13~59 minecraft:stonebrick 0
fill ~64~21~56 ~65~21~59 minecraft:stonebrick 0
fill ~1~15~57 ~1~16~57 minecraft:wool 14
fill ~3~1~57 ~3~1~58 minecraft:stonebrick 0
fill ~3~13~57 ~3~13~58 minecraft:stonebrick 0
fill ~3~21~57 ~3~21~58 minecraft:stonebrick 0
fill ~4~2~57 ~5~11~58 minecraft:stonebrick 0
fill ~4~14~57 ~5~18~58 minecraft:stonebrick 0
fill ~4~22~57 ~5~31~58 minecraft:stonebrick 0
fill ~6~1~57 ~6~1~58 minecraft:stonebrick 0
fill ~6~13~57 ~6~13~58 minecraft:stonebrick 0
fill ~6~21~57 ~6~21~58 minecraft:stonebrick 0
fill ~63~1~57 ~63~1~58 minecraft:stonebrick 0
fill ~63~13~57 ~63~13~58 minecraft:stonebrick 0
fill ~63~21~57 ~63~21~58 minecraft:stonebrick 0
fill ~64~2~57 ~65~11~58 minecraft:stonebrick 0
fill ~64~14~57 ~65~18~58 minecraft:stonebrick 0
fill ~64~22~57 ~65~31~58 minecraft:stonebrick 0
fill ~66~1~57 ~66~1~58 minecraft:stonebrick 0
fill ~66~13~57 ~66~13~58 minecraft:stonebrick 0
fill ~66~21~57 ~66~21~58 minecraft:stonebrick 0
fill ~8~32~60 ~61~32~64 minecraft:stonebrick 0
fill ~4~1~61 ~5~1~65 minecraft:stonebrick 0
fill ~4~13~61 ~5~13~64 minecraft:stonebrick 0
fill ~4~21~61 ~5~21~64 minecraft:stonebrick 0
fill ~7~12~61 ~62~12~65 minecraft:stonebrick 0
fill ~7~19~61 ~62~20~65 minecraft:stonebrick 0
fill ~9~1~61 ~10~1~65 minecraft:stonebrick 0
fill ~9~13~61 ~10~13~64 minecraft:stonebrick 0
fill ~9~21~61 ~10~21~64 minecraft:stonebrick 0
fill ~14~1~61 ~15~1~65 minecraft:stonebrick 0
fill ~14~13~61 ~15~13~64 minecraft:stonebrick 0
fill ~14~21~61 ~15~21~64 minecraft:stonebrick 0
fill ~19~1~61 ~20~1~65 minecraft:stonebrick 0
fill ~19~13~61 ~20~13~64 minecraft:stonebrick 0
fill ~19~21~61 ~20~21~64 minecraft:stonebrick 0
fill ~24~1~61 ~25~1~65 minecraft:stonebrick 0
fill ~24~13~61 ~25~13~64 minecraft:stonebrick 0
fill ~24~21~61 ~25~21~64 minecraft:stonebrick 0
fill ~29~1~61 ~30~1~65 minecraft:stonebrick 0
fill ~29~13~61 ~30~13~64 minecraft:stonebrick 0
fill ~29~21~61 ~30~21~64 minecraft:stonebrick 0
fill ~34~1~61 ~35~1~65 minecraft:stonebrick 0
fill ~34~13~61 ~35~13~64 minecraft:stonebrick 0
fill ~34~21~61 ~35~21~64 minecraft:stonebrick 0
fill ~39~1~61 ~40~1~65 minecraft:stonebrick 0
fill ~39~13~61 ~40~13~64 minecraft:stonebrick 0
fill ~39~21~61 ~40~21~64 minecraft:stonebrick 0
fill ~44~1~61 ~45~1~65 minecraft:stonebrick 0
fill ~44~13~61 ~45~13~64 minecraft:stonebrick 0
fill ~44~21~61 ~45~21~64 minecraft:stonebrick 0
fill ~49~1~61 ~50~1~65 minecraft:stonebrick 0
fill ~49~13~61 ~50~13~64 minecraft:stonebrick 0
fill ~49~21~61 ~50~21~64 minecraft:stonebrick 0
fill ~54~1~61 ~55~1~65 minecraft:stonebrick 0
fill ~54~13~61 ~55~13~64 minecraft:stonebrick 0
fill ~54~21~61 ~55~21~64 minecraft:stonebrick 0
fill ~59~1~61 ~60~1~65 minecraft:stonebrick 0
fill ~59~13~61 ~60~13~64 minecraft:stonebrick 0
fill ~59~21~61 ~60~21~64 minecraft:stonebrick 0
fill ~64~1~61 ~65~1~65 minecraft:stonebrick 0
fill ~64~13~61 ~65~13~64 minecraft:stonebrick 0
fill ~64~21~61 ~65~21~64 minecraft:stonebrick 0
fill ~3~1~62 ~3~1~63 minecraft:stonebrick 0
fill ~3~13~62 ~3~13~63 minecraft:stonebrick 0
fill ~3~21~62 ~3~21~63 minecraft:stonebrick 0
fill ~4~2~62 ~5~11~63 minecraft:stonebrick 0
fill ~4~14~62 ~5~18~63 minecraft:stonebrick 0
fill ~4~22~62 ~5~31~63 minecraft:stonebrick 0
fill ~6~1~62 ~6~1~63 minecraft:stonebrick 0
fill ~6~13~62 ~6~13~63 minecraft:stonebrick 0
fill ~6~21~62 ~6~21~63 minecraft:stonebrick 0
fill ~8~1~62 ~8~1~63 minecraft:stonebrick 0
fill ~8~13~62 ~8~13~63 minecraft:stonebrick 0
fill ~8~21~62 ~8~21~63 minecraft:stonebrick 0
fill ~9~2~62 ~10~11~63 minecraft:stonebrick 0
fill ~9~14~62 ~10~18~63 minecraft:stonebrick 0
fill ~9~22~62 ~10~31~63 minecraft:stonebrick 0
fill ~11~1~62 ~11~1~63 minecraft:stonebrick 0
fill ~11~13~62 ~11~13~63 minecraft:stonebrick 0
fill ~11~21~62 ~11~21~63 minecraft:stonebrick 0
fill ~13~1~62 ~13~1~63 minecraft:stonebrick 0
fill ~13~13~62 ~13~13~63 minecraft:stonebrick 0
fill ~13~21~62 ~13~21~63 minecraft:stonebrick 0
fill ~14~2~62 ~15~11~63 minecraft:stonebrick 0
fill ~14~14~62 ~15~18~63 minecraft:stonebrick 0
fill ~14~22~62 ~15~31~63 minecraft:stonebrick 0
fill ~16~1~62 ~16~1~63 minecraft:stonebrick 0
fill ~16~13~62 ~16~13~63 minecraft:stonebrick 0
fill ~16~21~62 ~16~21~63 minecraft:stonebrick 0
fill ~18~1~62 ~18~1~63 minecraft:stonebrick 0
fill ~18~13~62 ~18~13~63 minecraft:stonebrick 0
fill ~18~21~62 ~18~21~63 minecraft:stonebrick 0
fill ~19~2~62 ~20~11~63 minecraft:stonebrick 0
fill ~19~14~62 ~20~18~63 minecraft:stonebrick 0
fill ~19~22~62 ~20~31~63 minecraft:stonebrick 0
fill ~21~1~62 ~21~1~63 minecraft:stonebrick 0
fill ~21~13~62 ~21~13~63 minecraft:stonebrick 0
fill ~21~21~62 ~21~21~63 minecraft:stonebrick 0
fill ~23~1~62 ~23~1~63 minecraft:stonebrick 0
fill ~23~13~62 ~23~13~63 minecraft:stonebrick 0
fill ~23~21~62 ~23~21~63 minecraft:stonebrick 0
fill ~24~2~62 ~25~11~63 minecraft:stonebrick 0
fill ~24~14~62 ~25~18~63 minecraft:stonebrick 0
fill ~24~22~62 ~25~31~63 minecraft:stonebrick 0
fill ~26~1~62 ~26~1~63 minecraft:stonebrick 0
fill ~26~13~62 ~26~13~63 minecraft:stonebrick 0
fill ~26~21~62 ~26~21~63 minecraft:stonebrick 0
fill ~28~1~62 ~28~1~63 minecraft:stonebrick 0
fill ~28~13~62 ~28~13~63 minecraft:stonebrick 0
fill ~28~21~62 ~28~21~63 minecraft:stonebrick 0
fill ~29~2~62 ~30~11~63 minecraft:stonebrick 0
fill ~29~14~62 ~30~18~63 minecraft:stonebrick 0
fill ~29~22~62 ~30~31~63 minecraft:stonebrick 0
fill ~31~1~62 ~31~1~63 minecraft:stonebrick 0
fill ~31~13~62 ~31~13~63 minecraft:stonebrick 0
fill ~31~21~62 ~31~21~63 minecraft:stonebrick 0
fill ~33~1~62 ~33~1~63 minecraft:stonebrick 0
fill ~33~13~62 ~33~13~63 minecraft:stonebrick 0
fill ~33~21~62 ~33~21~63 minecraft:stonebrick 0
fill ~34~2~62 ~35~11~63 minecraft:stonebrick 0
fill ~34~14~62 ~35~18~63 minecraft:stonebrick 0
fill ~34~22~62 ~35~31~63 minecraft:stonebrick 0
fill ~36~1~62 ~36~1~63 minecraft:stonebrick 0
fill ~36~13~62 ~36~13~63 minecraft:stonebrick 0
fill ~36~21~62 ~36~21~63 minecraft:stonebrick 0
fill ~38~1~62 ~38~1~63 minecraft:stonebrick 0
fill ~38~13~62 ~38~13~63 minecraft:stonebrick 0
fill ~38~21~62 ~38~21~63 minecraft:stonebrick 0
fill ~39~2~62 ~40~11~63 minecraft:stonebrick 0
fill ~39~14~62 ~40~18~63 minecraft:stonebrick 0
