fill ~46~31~1 ~60~31~15 minecraft:stonebrick 0
fill ~46~32~1 ~60~34~1 minecraft:stonebrick 0
fill ~50~0~1 ~56~0~1 minecraft:stone_block_slab 5
fill ~50~30~1 ~56~30~1 minecraft:stone_block_slab 13
fill ~41~31~2 ~45~31~16 minecraft:stonebrick 0
fill ~41~32~2 ~45~34~2 minecraft:stonebrick 0
fill ~46~34~2 ~65~34~15 minecraft:stonebrick 0
fill ~46~35~2 ~60~36~2 minecraft:stonebrick 0
setblock ~49~0~2 minecraft:stone_block_slab 5
setblock ~49~30~2 minecraft:stone_block_slab 13
setblock ~50~0~2 minecraft:double_stone_block_slab 5
setblock ~50~30~2 minecraft:double_stone_block_slab 5
fill ~51~0~2 ~55~0~10 minecraft:stonebrick 0
fill ~51~30~2 ~55~30~14 minecraft:stonebrick 0
setblock ~56~0~2 minecraft:double_stone_block_slab 5
setblock ~56~30~2 minecraft:double_stone_block_slab 5
setblock ~57~0~2 minecraft:stone_block_slab 5
setblock ~57~30~2 minecraft:stone_block_slab 13
fill ~61~31~2 ~65~31~16 minecraft:stonebrick 0
fill ~61~32~2 ~65~33~2 minecraft:stonebrick 0
fill ~37~31~3 ~40~31~17 minecraft:stonebrick 0
fill ~37~32~3 ~40~34~3 minecraft:stonebrick 0
fill ~41~34~3 ~45~34~16 minecraft:stonebrick 0
fill ~41~35~3 ~45~36~3 minecraft:stonebrick 0
fill ~46~36~3 ~65~36~14 minecraft:stonebrick 0
fill ~46~37~3 ~60~37~12 minecraft:stonebrick 0
setblock ~48~0~3 minecraft:stone_block_slab 5
setblock ~48~30~3 minecraft:stone_block_slab 13
fill ~49~0~3 ~50~0~11 minecraft:stonebrick 0
fill ~49~30~3 ~50~30~13 minecraft:stonebrick 0
fill ~50~29~3 ~56~29~3 minecraft:stone_brick_stairs 6
fill ~56~0~3 ~57~0~11 minecraft:stonebrick 0
fill ~56~30~3 ~57~30~13 minecraft:stonebrick 0
setblock ~58~0~3 minecraft:stone_block_slab 5
setblock ~58~30~3 minecraft:stone_block_slab 13
fill ~61~35~3 ~65~35~3 minecraft:stonebrick 0
fill ~66~31~3 ~69~31~17 minecraft:stonebrick 0
fill ~66~32~3 ~69~34~3 minecraft:stonebrick 0
fill ~35~31~4 ~36~31~19 minecraft:stonebrick 0
fill ~35~32~4 ~36~34~4 minecraft:stonebrick 0
fill ~37~34~4 ~40~34~17 minecraft:stonebrick 0
fill ~38~35~4 ~40~36~4 minecraft:stonebrick 0
fill ~41~36~4 ~45~36~15 minecraft:stonebrick 0
fill ~41~37~4 ~45~37~13 minecraft:stonebrick 0
setblock ~47~0~4 minecraft:stone_block_slab 5
setblock ~47~30~4 minecraft:stone_block_slab 13
fill ~48~0~4 ~48~0~12 minecraft:stonebrick 0
fill ~48~30~4 ~48~30~12 minecraft:stonebrick 0
setblock ~49~1~4 minecraft:stone_brick_stairs 2
setblock ~49~29~4 minecraft:stone_brick_stairs 6
setblock ~50~1~4 minecraft:stone_brick_stairs 1
setblock ~50~29~4 minecraft:stone_brick_stairs 4
setblock ~51~28~4 minecraft:stone_block_slab 13
fill ~51~29~4 ~55~29~5 minecraft:stonebrick 0
setblock ~52~28~4 minecraft:stone_brick_stairs 6
setblock ~53~27~4 minecraft:stone_brick_stairs 6
fill ~53~28~4 ~53~28~12 minecraft:stonebrick 0
setblock ~54~28~4 minecraft:stone_brick_stairs 6
setblock ~55~28~4 minecraft:stone_block_slab 13
setblock ~56~1~4 minecraft:stone_brick_stairs 0
setblock ~56~29~4 minecraft:stone_brick_stairs 5
setblock ~57~1~4 minecraft:stone_brick_stairs 2
setblock ~57~29~4 minecraft:stone_brick_stairs 6
fill ~58~0~4 ~58~0~12 minecraft:stonebrick 0
fill ~58~30~4 ~58~30~12 minecraft:stonebrick 0
setblock ~59~0~4 minecraft:stone_block_slab 5
setblock ~59~30~4 minecraft:stone_block_slab 13
fill ~61~37~4 ~65~37~13 minecraft:stonebrick 0
fill ~66~34~4 ~71~34~17 minecraft:stonebrick 0
fill ~66~35~4 ~68~36~4 minecraft:stonebrick 0
fill ~70~31~4 ~71~31~19 minecraft:stonebrick 0
fill ~70~32~4 ~71~33~4 minecraft:stonebrick 0
fill ~32~31~5 ~34~31~20 minecraft:stonebrick 0
fill ~32~32~5 ~34~34~5 minecraft:stonebrick 0
fill ~35~34~5 ~36~34~19 minecraft:stonebrick 0
fill ~35~35~5 ~37~36~5 minecraft:stonebrick 0
fill ~38~36~5 ~40~36~16 minecraft:stonebrick 0
fill ~38~37~5 ~40~37~14 minecraft:stonebrick 0
fill ~46~0~5 ~46~0~8 minecraft:stone_block_slab 5
fill ~46~30~5 ~46~30~8 minecraft:stone_block_slab 13
setblock ~47~0~5 minecraft:double_stone_block_slab 5
setblock ~47~30~5 minecraft:double_stone_block_slab 5
fill ~47~38~5 ~59~38~10 minecraft:stonebrick 0
setblock ~48~1~5 minecraft:stone_brick_stairs 2
setblock ~48~29~5 minecraft:stone_brick_stairs 6
setblock ~49~1~5 minecraft:stone_brick_stairs 0
setblock ~49~29~5 minecraft:stone_brick_stairs 4
fill ~50~1~5 ~50~1~10 minecraft:stonebrick 0
setblock ~50~2~5 minecraft:stone_block_slab 5
setblock ~50~28~5 minecraft:stone_block_slab 13
fill ~50~29~5 ~50~29~11 minecraft:stonebrick 0
setblock ~51~5~5 minecraft:stone_brick_stairs 4
fill ~51~6~5 ~51~6~11 minecraft:stonebrick 0
setblock ~51~7~5 minecraft:stone_brick_stairs 2
setblock ~51~23~5 minecraft:stone_brick_stairs 6
fill ~51~24~5 ~51~24~11 minecraft:stonebrick 0
fill ~51~25~5 ~51~28~5 minecraft:stonebrick 0
fill ~52~5~5 ~52~5~6 minecraft:stone_brick_stairs 5
setblock ~52~6~5 minecraft:beacon
fill ~52~7~5 ~52~7~11 minecraft:stonebrick 0
setblock ~52~8~5 minecraft:stone_brick_stairs 2
setblock ~52~22~5 minecraft:stone_brick_stairs 6
fill ~52~23~5 ~52~23~11 minecraft:stonebrick 0
setblock ~52~24~5 minecraft:beacon
fill ~52~25~5 ~52~27~5 minecraft:glass_pane
fill ~52~28~5 ~52~28~11 minecraft:stonebrick 0
fill ~53~6~5 ~53~6~6 minecraft:stonebrick 0
setblock ~53~7~5 minecraft:stone_brick_stairs 2
setblock ~53~23~5 minecraft:stone_brick_stairs 6
fill ~53~24~5 ~53~24~11 minecraft:stonebrick 0
fill ~53~25~5 ~53~27~5 minecraft:stonebrick 0
fill ~54~5~5 ~54~5~6 minecraft:stone_brick_stairs 4
setblock ~54~6~5 minecraft:beacon
fill ~54~7~5 ~54~7~11 minecraft:stonebrick 0
setblock ~54~8~5 minecraft:stone_brick_stairs 2
setblock ~54~22~5 minecraft:stone_brick_stairs 6
fill ~54~23~5 ~54~23~11 minecraft:stonebrick 0
setblock ~54~24~5 minecraft:beacon
fill ~54~25~5 ~54~27~5 minecraft:glass_pane
fill ~54~28~5 ~55~28~11 minecraft:stonebrick 0
setblock ~55~5~5 minecraft:stone_brick_stairs 5
fill ~55~6~5 ~55~6~11 minecraft:stonebrick 0
setblock ~55~7~5 minecraft:stone_brick_stairs 2
setblock ~55~23~5 minecraft:stone_brick_stairs 6
fill ~55~24~5 ~55~24~11 minecraft:stonebrick 0
fill ~55~25~5 ~55~27~5 minecraft:stonebrick 0
fill ~56~1~5 ~56~1~10 minecraft:stonebrick 0
setblock ~56~2~5 minecraft:stone_block_slab 5
setblock ~56~28~5 minecraft:stone_block_slab 13
fill ~56~29~5 ~56~29~11 minecraft:stonebrick 0
setblock ~57~1~5 minecraft:stone_brick_stairs 1
setblock ~57~29~5 minecraft:stone_brick_stairs 5
setblock ~58~1~5 minecraft:stone_brick_stairs 2
setblock ~58~29~5 minecraft:stone_brick_stairs 6
setblock ~59~0~5 minecraft:double_stone_block_slab 5
setblock ~59~30~5 minecraft:double_stone_block_slab 5
fill ~60~30~5 ~60~30~8 minecraft:stone_block_slab 13
fill ~66~36~5 ~71~36~16 minecraft:stonebrick 0
fill ~66~37~5 ~68~37~14 minecraft:stonebrick 0
fill ~69~35~5 ~71~35~5 minecraft:stonebrick 0
fill ~72~31~5 ~74~31~20 minecraft:stonebrick 0
fill ~72~32~5 ~74~34~5 minecraft:stonebrick 0
fill ~30~31~6 ~31~31~22 minecraft:stonebrick 0
fill ~30~32~6 ~31~34~6 minecraft:stonebrick 0
fill ~32~34~6 ~34~34~20 minecraft:stonebrick 0
fill ~32~35~6 ~34~36~6 minecraft:stonebrick 0
fill ~35~36~6 ~37~36~17 minecraft:stonebrick 0
fill ~35~37~6 ~37~37~15 minecraft:stonebrick 0
fill ~42~38~6 ~46~38~11 minecraft:stonebrick 0
fill ~47~0~6 ~47~0~10 minecraft:stonebrick 0
fill ~47~30~6 ~47~30~10 minecraft:stonebrick 0
fill ~48~1~6 ~49~1~10 minecraft:stonebrick 0
fill ~48~2~6 ~50~5~6 minecraft:stonebrick 0
fill ~48~29~6 ~48~29~10 minecraft:stone_brick_stairs 4
setblock ~49~6~6 minecraft:stone_block_slab 5
setblock ~49~28~6 minecraft:stone_block_slab 13
fill ~49~29~6 ~49~29~10 minecraft:stonebrick 0
fill ~50~6~6 ~50~6~10 minecraft:stonebrick 0
setblock ~50~7~6 minecraft:stone_block_slab 5
setblock ~50~23~6 minecraft:stone_brick_stairs 4
fill ~50~24~6 ~50~28~6 minecraft:stonebrick 0
fill ~51~1~6 ~55~1~6 minecraft:stone_block_slab 0
setblock ~51~4~6 minecraft:stone_brick_stairs 5
setblock ~51~5~6 minecraft:stonebrick 0
setblock ~51~7~6 minecraft:double_stone_block_slab 5
setblock ~51~8~6 minecraft:stone_block_slab 5
setblock ~51~22~6 minecraft:stone_block_slab 13
fill ~51~23~6 ~51~23~10 minecraft:stonebrick 0
fill ~51~25~6 ~55~27~6 minecraft:stone_block_slab 5
fill ~51~28~6 ~51~28~11 minecraft:stonebrick 0
setblock ~52~6~6 minecraft:stonebrick 0
fill ~52~8~6 ~52~22~6 minecraft:stonebrick 0
fill ~52~24~6 ~52~24~10 minecraft:stonebrick 0
fill ~53~7~6 ~53~7~10 minecraft:stonebrick 0
fill ~53~8~6 ~53~10~6 minecraft:glass_pane
setblock ~53~11~6 minecraft:beacon
fill ~53~12~6 ~53~14~6 minecraft:glass_pane
setblock ~53~15~6 minecraft:beacon
fill ~53~16~6 ~53~18~6 minecraft:glass_pane
setblock ~53~19~6 minecraft:beacon
fill ~53~20~6 ~53~22~6 minecraft:glass_pane
fill ~53~23~6 ~53~23~10 minecraft:stonebrick 0
setblock ~54~6~6 minecraft:stonebrick 0
fill ~54~8~6 ~54~22~6 minecraft:stonebrick 0
fill ~54~24~6 ~54~24~10 minecraft:stonebrick 0
setblock ~55~4~6 minecraft:stone_brick_stairs 4
fill ~55~5~6 ~58~5~6 minecraft:stonebrick 0
setblock ~55~7~6 minecraft:double_stone_block_slab 5
setblock ~55~8~6 minecraft:stone_block_slab 5
setblock ~55~22~6 minecraft:stone_block_slab 13
fill ~55~23~6 ~55~23~10 minecraft:stonebrick 0
fill ~56~2~6 ~58~4~6 minecraft:stonebrick 0
fill ~56~6~6 ~56~6~10 minecraft:stonebrick 0
setblock ~56~7~6 minecraft:stone_block_slab 5
setblock ~56~23~6 minecraft:stone_brick_stairs 5
fill ~56~24~6 ~56~28~6 minecraft:stonebrick 0
fill ~57~1~6 ~58~1~10 minecraft:stonebrick 0
setblock ~57~6~6 minecraft:stone_block_slab 5
setblock ~57~28~6 minecraft:stone_block_slab 13
fill ~57~29~6 ~57~29~10 minecraft:stonebrick 0
fill ~58~29~6 ~58~29~11 minecraft:stone_brick_stairs 5
fill ~59~0~6 ~59~0~10 minecraft:stonebrick 0
fill ~59~30~6 ~59~30~10 minecraft:stonebrick 0
fill ~60~38~6 ~64~38~11 minecraft:stonebrick 0
fill ~69~37~6 ~71~37~15 minecraft:stonebrick 0
fill ~72~34~6 ~76~34~20 minecraft:stonebrick 0
fill ~72~35~6 ~74~36~6 minecraft:stonebrick 0
fill ~75~31~6 ~76~31~22 minecraft:stonebrick 0
fill ~75~32~6 ~76~33~6 minecraft:stonebrick 0
fill ~27~0~7 ~33~0~7 minecraft:stone_block_slab 5
fill ~27~30~7 ~33~30~7 minecraft:stone_block_slab 13
fill ~28~31~7 ~29~31~23 minecraft:stonebrick 0
fill ~28~32~7 ~29~34~7 minecraft:stonebrick 0
fill ~30~34~7 ~31~34~22 minecraft:stonebrick 0
fill ~30~35~7 ~31~36~7 minecraft:stonebrick 0
fill ~32~36~7 ~34~36~19 minecraft:stonebrick 0
fill ~33~37~7 ~34~37~17 minecraft:stonebrick 0
fill ~38~38~7 ~41~38~12 minecraft:stonebrick 0
fill ~48~2~7 ~48~4~9 minecraft:stone_block_slab 13
fill ~48~5~7 ~50~5~10 minecraft:stonebrick 0
fill ~49~2~7 ~49~3~9 minecraft:lava 8
fill ~49~4~7 ~49~4~9 minecraft:lava 0
setblock ~49~6~7 minecraft:double_stone_block_slab 5
setblock ~49~28~7 minecraft:stone_brick_stairs 4
fill ~50~2~7 ~50~4~7 minecraft:stone_block_slab 13
setblock ~50~7~7 minecraft:stonebrick 0
setblock ~50~8~7 minecraft:stone_brick_stairs 0
setblock ~50~22~7 minecraft:stone_brick_stairs 4
setblock ~50~23~7 minecraft:stonebrick 0
setblock ~50~24~7 minecraft:beacon
fill ~50~25~7 ~50~27~7 minecraft:glass_pane
fill ~50~28~7 ~50~28~10 minecraft:stonebrick 0
fill ~51~1~7 ~51~1~10 minecraft:stone_block_slab 0
fill ~51~5~7 ~51~5~9 minecraft:stone_brick_stairs 5
setblock ~51~7~7 minecraft:stone_block_slab 5
fill ~51~8~7 ~51~22~7 minecraft:stonebrick 0
fill ~51~25~7 ~51~27~10 minecraft:stone_block_slab 5
setblock ~52~1~7 minecraft:stone_block_slab 5
fill ~52~6~7 ~52~6~9 minecraft:stone_brick_stairs 5
fill ~52~8~7 ~54~12~7 minecraft:stone_block_slab 13
fill ~52~13~7 ~54~22~7 minecraft:stone_block_slab 5
fill ~52~25~7 ~54~25~7 minecraft:lava 0
fill ~53~1~7 ~53~1~10 minecraft:stone_block_slab 0
fill ~53~6~7 ~53~6~9 minecraft:stone_block_slab 13
setblock ~54~1~7 minecraft:stone_block_slab 5
fill ~54~6~7 ~54~6~9 minecraft:stone_brick_stairs 4
fill ~55~1~7 ~55~1~10 minecraft:stone_block_slab 0
fill ~55~5~7 ~55~5~9 minecraft:stone_brick_stairs 4
setblock ~55~7~7 minecraft:stone_block_slab 5
fill ~55~8~7 ~55~22~7 minecraft:stonebrick 0
fill ~55~25~7 ~55~27~10 minecraft:stone_block_slab 5
fill ~56~2~7 ~56~4~7 minecraft:stone_block_slab 13
fill ~56~5~7 ~58~5~10 minecraft:stonebrick 0
setblock ~56~7~7 minecraft:stonebrick 0
setblock ~56~8~7 minecraft:stone_brick_stairs 1
setblock ~56~22~7 minecraft:stone_brick_stairs 5
setblock ~56~23~7 minecraft:stonebrick 0
setblock ~56~24~7 minecraft:beacon
fill ~56~25~7 ~56~27~7 minecraft:glass_pane
fill ~56~28~7 ~56~28~10 minecraft:stonebrick 0
fill ~57~2~7 ~57~3~9 minecraft:lava 8
fill ~57~4~7 ~57~4~9 minecraft:lava 0
setblock ~57~6~7 minecraft:double_stone_block_slab 5
setblock ~57~28~7 minecraft:stone_brick_stairs 5
fill ~58~2~7 ~58~4~9 minecraft:stone_block_slab 13
fill ~65~38~7 ~68~38~12 minecraft:stonebrick 0
fill ~72~36~7 ~76~36~19 minecraft:stonebrick 0
fill ~72~37~7 ~73~37~17 minecraft:stonebrick 0
fill ~73~0~7 ~79~0~7 minecraft:stone_block_slab 5
fill ~73~30~7 ~79~30~7 minecraft:stone_block_slab 13
fill ~75~35~7 ~76~35~7 minecraft:stonebrick 0
fill ~77~31~7 ~78~31~23 minecraft:stonebrick 0
fill ~77~32~7 ~78~34~7 minecraft:stonebrick 0
setblock ~26~0~8 minecraft:stone_block_slab 5
setblock ~26~30~8 minecraft:stone_block_slab 13
fill ~26~31~8 ~27~31~25 minecraft:stonebrick 0
fill ~26~32~8 ~27~34~8 minecraft:stonebrick 0
fill ~27~0~8 ~33~0~8 minecraft:stonebrick 0
fill ~27~30~8 ~33~30~8 minecraft:stonebrick 0
fill ~28~34~8 ~29~34~23 minecraft:stonebrick 0
fill ~28~35~8 ~29~36~8 minecraft:stonebrick 0
fill ~30~36~8 ~31~36~21 minecraft:stonebrick 0
fill ~31~37~8 ~32~37~18 minecraft:stonebrick 0
setblock ~34~0~8 minecraft:stone_block_slab 5
setblock ~34~30~8 minecraft:stone_block_slab 13
fill ~35~38~8 ~37~38~13 minecraft:stonebrick 0
setblock ~49~6~8 minecraft:stone_block_slab 5
setblock ~49~27~8 minecraft:stone_brick_stairs 4
setblock ~49~28~8 minecraft:stonebrick 0
setblock ~50~2~8 minecraft:stone_block_slab 5
setblock ~50~4~8 minecraft:double_stone_block_slab 5
setblock ~50~7~8 minecraft:stone_block_slab 5
setblock ~50~23~8 minecraft:stone_brick_stairs 4
fill ~50~24~8 ~50~27~8 minecraft:stonebrick 0
setblock ~51~7~8 minecraft:double_stone_block_slab 5
fill ~51~8~8 ~51~10~8 minecraft:glass_pane
setblock ~51~11~8 minecraft:beacon
fill ~51~12~8 ~51~14~8 minecraft:glass_pane
setblock ~51~15~8 minecraft:beacon
fill ~51~16~8 ~51~18~8 minecraft:glass_pane
setblock ~51~19~8 minecraft:beacon
fill ~51~20~8 ~51~22~8 minecraft:glass_pane
setblock ~51~39~8 minecraft:stonebrick 0
setblock ~52~1~8 minecraft:stone_block_slab 0
fill ~52~8~8 ~52~12~9 minecraft:stone_block_slab 13
fill ~52~13~8 ~52~22~9 minecraft:stone_block_slab 5
fill ~52~25~8 ~52~25~9 minecraft:lava 0
fill ~52~39~8 ~54~39~8 minecraft:glass
fill ~53~8~8 ~53~9~8 minecraft:lava 8
fill ~53~10~8 ~53~11~8 minecraft:lava 0
fill ~53~12~8 ~53~14~8 minecraft:lava 8
fill ~53~15~8 ~53~16~8 minecraft:lava 0
fill ~53~17~8 ~53~18~8 minecraft:lava 8
fill ~53~19~8 ~53~20~8 minecraft:lava 0
fill ~53~25~8 ~53~27~8 minecraft:stonebrick 0
setblock ~53~29~8 minecraft:stonebrick 0
setblock ~54~1~8 minecraft:stone_block_slab 0
fill ~54~8~8 ~54~12~9 minecraft:stone_block_slab 13
fill ~54~13~8 ~54~22~9 minecraft:stone_block_slab 5
fill ~54~25~8 ~54~25~9 minecraft:lava 0
setblock ~55~7~8 minecraft:double_stone_block_slab 5
fill ~55~8~8 ~55~10~8 minecraft:glass_pane
setblock ~55~11~8 minecraft:beacon
fill ~55~12~8 ~55~14~8 minecraft:glass_pane
setblock ~55~15~8 minecraft:beacon
fill ~55~16~8 ~55~18~8 minecraft:glass_pane
setblock ~55~19~8 minecraft:beacon
fill ~55~20~8 ~55~22~8 minecraft:glass_pane
setblock ~55~39~8 minecraft:stonebrick 0
setblock ~56~2~8 minecraft:stone_block_slab 5
setblock ~56~4~8 minecraft:double_stone_block_slab 5
setblock ~56~7~8 minecraft:stone_block_slab 5
setblock ~56~23~8 minecraft:stone_brick_stairs 5
fill ~56~24~8 ~56~27~8 minecraft:stonebrick 0
setblock ~57~6~8 minecraft:stone_block_slab 5
setblock ~57~27~8 minecraft:stone_brick_stairs 5
setblock ~57~28~8 minecraft:stonebrick 0
fill ~69~38~8 ~71~38~13 minecraft:stonebrick 0
setblock ~72~0~8 minecraft:stone_block_slab 5
setblock ~72~30~8 minecraft:stone_block_slab 13
fill ~73~0~8 ~79~0~8 minecraft:stonebrick 0
fill ~73~30~8 ~79~30~8 minecraft:stonebrick 0
fill ~74~37~8 ~75~37~18 minecraft:stonebrick 0
fill ~77~34~8 ~80~34~23 minecraft:stonebrick 0
fill ~77~35~8 ~78~36~8 minecraft:stonebrick 0
fill ~79~31~8 ~80~31~25 minecraft:stonebrick 0
fill ~79~32~8 ~80~33~8 minecraft:stonebrick 0
setblock ~80~0~8 minecraft:stone_block_slab 5
setblock ~80~30~8 minecraft:stone_block_slab 13
setblock ~25~0~9 minecraft:stone_block_slab 5
setblock ~25~30~9 minecraft:stone_block_slab 13
fill ~25~31~9 ~25~31~27 minecraft:stonebrick 0
fill ~25~32~9 ~25~34~9 minecraft:stonebrick 0
setblock ~26~0~9 minecraft:stonebrick 0
setblock ~26~30~9 minecraft:stonebrick 0
fill ~26~34~9 ~27~34~25 minecraft:stonebrick 0
setblock ~27~1~9 minecraft:stone_brick_stairs 0
setblock ~27~29~9 minecraft:stone_brick_stairs 4
fill ~27~35~9 ~27~36~9 minecraft:stonebrick 0
fill ~28~1~9 ~33~1~9 minecraft:stone_brick_stairs 2
fill ~28~29~9 ~33~29~9 minecraft:stone_brick_stairs 6
fill ~28~36~9 ~29~36~22 minecraft:stonebrick 0
fill ~29~37~9 ~30~37~19 minecraft:stonebrick 0
fill ~33~38~9 ~34~38~14 minecraft:stonebrick 0
setblock ~34~0~9 minecraft:stonebrick 0
setblock ~34~30~9 minecraft:stonebrick 0
setblock ~35~0~9 minecraft:stone_block_slab 5
setblock ~35~30~9 minecraft:stone_block_slab 13
fill ~42~0~9 ~46~0~9 minecraft:stonebrick 0
fill ~42~1~9 ~47~1~9 minecraft:stone_block_slab 13
fill ~42~30~9 ~46~30~9 minecraft:stonebrick 0
setblock ~49~6~9 minecraft:double_stone_block_slab 5
setblock ~49~28~9 minecraft:stone_brick_stairs 4
fill ~50~2~9 ~50~4~9 minecraft:stone_block_slab 13
setblock ~50~7~9 minecraft:stonebrick 0
setblock ~50~8~9 minecraft:stone_brick_stairs 0
setblock ~50~22~9 minecraft:stone_brick_stairs 4
setblock ~50~23~9 minecraft:stonebrick 0
setblock ~50~24~9 minecraft:beacon
fill ~50~25~9 ~50~27~9 minecraft:glass_pane
fill ~50~39~9 ~50~39~13 minecraft:stonebrick 0
setblock ~51~7~9 minecraft:stone_block_slab 5
fill ~51~8~9 ~51~22~9 minecraft:stonebrick 0
setblock ~51~40~9 minecraft:stonebrick 0
setblock ~52~1~9 minecraft:stone_block_slab 5
fill ~52~40~9 ~54~40~9 minecraft:glass
fill ~53~8~9 ~53~12~9 minecraft:stone_block_slab 13
fill ~53~13~9 ~53~22~9 minecraft:stone_block_slab 5
setblock ~53~25~9 minecraft:lava 0
setblock ~54~1~9 minecraft:stone_block_slab 5
setblock ~55~7~9 minecraft:stone_block_slab 5
fill ~55~8~9 ~55~22~9 minecraft:stonebrick 0
setblock ~55~40~9 minecraft:stonebrick 0
fill ~56~2~9 ~56~4~9 minecraft:stone_block_slab 13
setblock ~56~7~9 minecraft:stonebrick 0
setblock ~56~8~9 minecraft:stone_brick_stairs 1
setblock ~56~22~9 minecraft:stone_brick_stairs 5
setblock ~56~23~9 minecraft:stonebrick 0
setblock ~56~24~9 minecraft:beacon
fill ~56~25~9 ~56~27~9 minecraft:glass_pane
fill ~56~39~9 ~56~39~13 minecraft:stonebrick 0
setblock ~57~6~9 minecraft:double_stone_block_slab 5
setblock ~57~28~9 minecraft:stone_brick_stairs 5
fill ~59~1~9 ~64~1~9 minecraft:stone_block_slab 13
fill ~60~0~9 ~64~0~9 minecraft:stonebrick 0
fill ~60~30~9 ~64~30~9 minecraft:stonebrick 0
setblock ~71~0~9 minecraft:stone_block_slab 5
setblock ~71~30~9 minecraft:stone_block_slab 13
setblock ~72~0~9 minecraft:stonebrick 0
setblock ~72~30~9 minecraft:stonebrick 0
fill ~72~38~9 ~73~38~14 minecraft:stonebrick 0
fill ~73~1~9 ~79~1~9 minecraft:stone_brick_stairs 2
fill ~73~29~9 ~79~29~9 minecraft:stone_brick_stairs 6
fill ~76~37~9 ~77~37~19 minecraft:stonebrick 0
fill ~77~36~9 ~79~36~22 minecraft:stonebrick 0
setblock ~79~35~9 minecraft:stonebrick 0
setblock ~80~0~9 minecraft:stonebrick 0
setblock ~80~30~9 minecraft:stonebrick 0
setblock ~81~0~9 minecraft:stone_block_slab 5
setblock ~81~30~9 minecraft:stone_block_slab 13
fill ~81~31~9 ~81~31~27 minecraft:stonebrick 0
fill ~81~32~9 ~81~34~9 minecraft:stonebrick 0
fill ~23~31~10 ~24~31~28 minecraft:stonebrick 0
fill ~23~32~10 ~24~34~10 minecraft:stonebrick 0
setblock ~24~0~10 minecraft:stone_block_slab 5
setblock ~24~30~10 minecraft:stone_block_slab 13
setblock ~25~0~10 minecraft:stonebrick 0
setblock ~25~30~10 minecraft:stonebrick 0
fill ~25~34~10 ~25~34~27 minecraft:stonebrick 0
fill ~25~35~10 ~26~36~10 minecraft:stonebrick 0
setblock ~26~1~10 minecraft:stone_brick_stairs 0
setblock ~26~29~10 minecraft:stone_brick_stairs 4
setblock ~27~1~10 minecraft:stone_brick_stairs 2
setblock ~27~29~10 minecraft:stone_brick_stairs 6
fill ~27~36~10 ~27~36~24 minecraft:stonebrick 0
fill ~27~37~10 ~28~37~21 minecraft:stonebrick 0
fill ~28~1~10 ~32~1~11 minecraft:stonebrick 0
setblock ~28~2~10 minecraft:stone_block_slab 5
setblock ~28~28~10 minecraft:stone_block_slab 13
fill ~28~29~10 ~32~29~11 minecraft:stonebrick 0
setblock ~29~2~10 minecraft:stone_brick_stairs 2
setblock ~29~28~10 minecraft:stone_brick_stairs 6
fill ~30~2~10 ~30~2~18 minecraft:stonebrick 0
setblock ~30~3~10 minecraft:stone_brick_stairs 2
setblock ~30~27~10 minecraft:stone_brick_stairs 6
fill ~30~28~10 ~30~28~18 minecraft:stonebrick 0
setblock ~31~2~10 minecraft:stone_brick_stairs 2
setblock ~31~28~10 minecraft:stone_brick_stairs 6
fill ~31~38~10 ~32~38~16 minecraft:stonebrick 0
setblock ~32~2~10 minecraft:stone_block_slab 5
setblock ~32~28~10 minecraft:stone_block_slab 13
setblock ~33~1~10 minecraft:stone_brick_stairs 1
setblock ~33~29~10 minecraft:stone_brick_stairs 5
setblock ~34~1~10 minecraft:stone_brick_stairs 2
setblock ~34~29~10 minecraft:stone_brick_stairs 6
setblock ~35~0~10 minecraft:stonebrick 0
setblock ~35~30~10 minecraft:stonebrick 0
setblock ~36~0~10 minecraft:stone_block_slab 5
setblock ~36~30~10 minecraft:stone_block_slab 13
fill ~39~0~10 ~41~0~10 minecraft:stonebrick 0
fill ~39~1~10 ~41~1~10 minecraft:stone_block_slab 13
fill ~39~30~10 ~41~30~10 minecraft:stonebrick 0
setblock ~46~30~10 minecraft:double_stone_block_slab 5
fill ~48~2~10 ~50~4~10 minecraft:stonebrick 0
setblock ~49~6~10 minecraft:stone_block_slab 5
setblock ~49~28~10 minecraft:stone_block_slab 13
setblock ~50~7~10 minecraft:stone_block_slab 5
setblock ~50~23~10 minecraft:stone_brick_stairs 4
fill ~50~24~10 ~50~27~10 minecraft:stonebrick 0
fill ~50~40~10 ~50~40~14 minecraft:stonebrick 0
setblock ~51~4~10 minecraft:stone_brick_stairs 5
setblock ~51~5~10 minecraft:stonebrick 0
setblock ~51~7~10 minecraft:double_stone_block_slab 5
setblock ~51~8~10 minecraft:stone_block_slab 5
setblock ~51~22~10 minecraft:stone_block_slab 13
fill ~51~41~10 ~51~42~10 minecraft:stonebrick 0
setblock ~52~1~10 minecraft:stone_block_slab 0
fill ~52~5~10 ~52~5~11 minecraft:stone_brick_stairs 5
fill ~52~6~10 ~54~6~10 minecraft:stonebrick 0
fill ~52~8~10 ~52~22~10 minecraft:stonebrick 0
fill ~52~25~10 ~54~27~10 minecraft:stone_block_slab 5
fill ~52~41~10 ~54~42~10 minecraft:glass
fill ~53~8~10 ~53~10~10 minecraft:glass_pane
setblock ~53~11~10 minecraft:beacon
fill ~53~12~10 ~53~14~10 minecraft:glass_pane
setblock ~53~15~10 minecraft:beacon
fill ~53~16~10 ~53~18~10 minecraft:glass_pane
setblock ~53~19~10 minecraft:beacon
fill ~53~20~10 ~53~22~10 minecraft:glass_pane
setblock ~54~1~10 minecraft:stone_block_slab 0
fill ~54~5~10 ~54~5~11 minecraft:stone_brick_stairs 4
fill ~54~8~10 ~54~22~10 minecraft:stonebrick 0
setblock ~55~4~10 minecraft:stone_brick_stairs 4
setblock ~55~5~10 minecraft:stonebrick 0
setblock ~55~7~10 minecraft:double_stone_block_slab 5
setblock ~55~8~10 minecraft:stone_block_slab 5
setblock ~55~22~10 minecraft:stone_block_slab 13
fill ~55~41~10 ~55~42~10 minecraft:stonebrick 0
fill ~56~2~10 ~58~4~10 minecraft:stonebrick 0
setblock ~56~7~10 minecraft:stone_block_slab 5
setblock ~56~23~10 minecraft:stone_brick_stairs 5
fill ~56~24~10 ~56~27~10 minecraft:stonebrick 0
fill ~56~40~10 ~56~40~14 minecraft:stonebrick 0
setblock ~57~6~10 minecraft:stone_block_slab 5
setblock ~57~28~10 minecraft:stone_block_slab 13
fill ~59~1~10 ~59~1~13 minecraft:stone_block_slab 5
setblock ~60~30~10 minecraft:double_stone_block_slab 5
fill ~65~0~10 ~67~0~10 minecraft:stonebrick 0
fill ~65~1~10 ~67~1~10 minecraft:stone_block_slab 13
fill ~65~30~10 ~67~30~10 minecraft:stonebrick 0
setblock ~70~0~10 minecraft:stone_block_slab 5
setblock ~70~30~10 minecraft:stone_block_slab 13
setblock ~71~0~10 minecraft:stonebrick 0
setblock ~71~30~10 minecraft:stonebrick 0
setblock ~72~1~10 minecraft:stone_brick_stairs 2
setblock ~72~29~10 minecraft:stone_brick_stairs 6
setblock ~73~1~10 minecraft:stone_brick_stairs 0
setblock ~73~29~10 minecraft:stone_brick_stairs 4
fill ~74~1~10 ~78~1~11 minecraft:stonebrick 0
setblock ~74~2~10 minecraft:stone_block_slab 5
setblock ~74~28~10 minecraft:stone_block_slab 13
fill ~74~29~10 ~78~29~11 minecraft:stonebrick 0
fill ~74~38~10 ~75~38~16 minecraft:stonebrick 0
setblock ~75~2~10 minecraft:stone_brick_stairs 2
setblock ~75~28~10 minecraft:stone_brick_stairs 6
fill ~76~2~10 ~76~2~18 minecraft:stonebrick 0
setblock ~76~3~10 minecraft:stone_brick_stairs 2
setblock ~76~27~10 minecraft:stone_brick_stairs 6
fill ~76~28~10 ~76~28~18 minecraft:stonebrick 0
setblock ~77~2~10 minecraft:stone_brick_stairs 2
setblock ~77~28~10 minecraft:stone_brick_stairs 6
setblock ~78~2~10 minecraft:stone_block_slab 5
setblock ~78~28~10 minecraft:stone_block_slab 13
fill ~78~37~10 ~79~37~21 minecraft:stonebrick 0
setblock ~79~1~10 minecraft:stone_brick_stairs 1
setblock ~79~29~10 minecraft:stone_brick_stairs 5
setblock ~80~1~10 minecraft:stone_brick_stairs 2
setblock ~80~29~10 minecraft:stone_brick_stairs 6
fill ~80~35~10 ~81~36~10 minecraft:stonebrick 0
setblock ~81~0~10 minecraft:stonebrick 0
setblock ~81~30~10 minecraft:stonebrick 0
fill ~81~34~10 ~83~34~27 minecraft:stonebrick 0
setblock ~82~0~10 minecraft:stone_block_slab 5
setblock ~82~30~10 minecraft:stone_block_slab 13
fill ~82~31~10 ~83~31~28 minecraft:stonebrick 0
fill ~82~32~10 ~83~33~10 minecraft:stonebrick 0
fill ~22~31~11 ~22~31~31 minecraft:stonebrick 0
fill ~22~32~11 ~22~34~11 minecraft:stonebrick 0
fill ~23~0~11 ~23~0~17 minecraft:stone_block_slab 5
fill ~23~30~11 ~23~30~17 minecraft:stone_block_slab 13
fill ~23~34~11 ~24~34~28 minecraft:stonebrick 0
fill ~24~0~11 ~24~0~18 minecraft:stonebrick 0
fill ~24~30~11 ~24~30~18 minecraft:stonebrick 0
fill ~24~35~11 ~24~36~11 minecraft:stonebrick 0
fill ~25~1~11 ~25~1~17 minecraft:stone_brick_stairs 0
fill ~25~29~11 ~25~29~17 minecraft:stone_brick_stairs 4
fill ~25~36~11 ~26~36~25 minecraft:stonebrick 0
fill ~25~37~11 ~26~37~22 minecraft:stonebrick 0
setblock ~26~1~11 minecraft:stone_brick_stairs 2
setblock ~26~29~11 minecraft:stone_brick_stairs 6
fill ~27~1~11 ~27~1~17 minecraft:stonebrick 0
setblock ~27~2~11 minecraft:stone_block_slab 5
setblock ~27~28~11 minecraft:stone_block_slab 13
fill ~27~29~11 ~27~29~17 minecraft:stonebrick 0
fill ~28~2~11 ~29~2~17 minecraft:stonebrick 0
fill ~28~3~11 ~28~6~11 minecraft:stonebrick 0
setblock ~28~7~11 minecraft:stone_brick_stairs 2
setblock ~28~23~11 minecraft:stone_brick_stairs 6
fill ~28~24~11 ~28~24~17 minecraft:stonebrick 0
fill ~28~25~11 ~28~28~11 minecraft:stonebrick 0
fill ~29~3~11 ~29~5~11 minecraft:glass_pane
setblock ~29~6~11 minecraft:beacon
fill ~29~7~11 ~29~7~17 minecraft:stonebrick 0
setblock ~29~8~11 minecraft:stone_brick_stairs 2
setblock ~29~22~11 minecraft:stone_brick_stairs 6
fill ~29~23~11 ~29~23~17 minecraft:stonebrick 0
setblock ~29~24~11 minecraft:beacon
fill ~29~25~11 ~29~27~11 minecraft:glass_pane
fill ~29~28~11 ~29~28~17 minecraft:stonebrick 0
fill ~29~38~11 ~30~38~17 minecraft:stonebrick 0
fill ~30~3~11 ~30~6~11 minecraft:stonebrick 0
setblock ~30~7~11 minecraft:stone_brick_stairs 2
setblock ~30~23~11 minecraft:stone_brick_stairs 6
fill ~30~24~11 ~30~24~17 minecraft:stonebrick 0
fill ~30~25~11 ~30~27~11 minecraft:stonebrick 0
fill ~31~2~11 ~32~2~17 minecraft:stonebrick 0
fill ~31~3~11 ~31~5~11 minecraft:glass_pane
setblock ~31~6~11 minecraft:beacon
fill ~31~7~11 ~31~7~17 minecraft:stonebrick 0
setblock ~31~8~11 minecraft:stone_brick_stairs 2
setblock ~31~22~11 minecraft:stone_brick_stairs 6
fill ~31~23~11 ~31~23~17 minecraft:stonebrick 0
setblock ~31~24~11 minecraft:beacon
fill ~31~25~11 ~31~27~11 minecraft:glass_pane
fill ~31~28~11 ~32~28~17 minecraft:stonebrick 0
fill ~32~3~11 ~32~6~11 minecraft:stonebrick 0
setblock ~32~7~11 minecraft:stone_brick_stairs 2
setblock ~32~23~11 minecraft:stone_brick_stairs 6
fill ~32~24~11 ~32~24~17 minecraft:stonebrick 0
fill ~32~25~11 ~32~27~11 minecraft:stonebrick 0
fill ~33~1~11 ~33~1~17 minecraft:stonebrick 0
setblock ~33~2~11 minecraft:stone_block_slab 5
setblock ~33~28~11 minecraft:stone_block_slab 13
fill ~33~29~11 ~33~29~17 minecraft:stonebrick 0
setblock ~34~1~11 minecraft:stone_brick_stairs 1
setblock ~34~29~11 minecraft:stone_brick_stairs 5
setblock ~35~1~11 minecraft:stone_brick_stairs 2
setblock ~35~29~11 minecraft:stone_brick_stairs 6
fill ~36~0~11 ~38~0~11 minecraft:stonebrick 0
fill ~36~1~11 ~38~1~11 minecraft:stone_block_slab 13
fill ~36~30~11 ~38~30~11 minecraft:stonebrick 0
setblock ~47~0~11 minecraft:double_stone_block_slab 5
fill ~47~30~11 ~47~30~12 minecraft:double_stone_block_slab 5
fill ~48~1~11 ~48~1~43 minecraft:stone_block_slab 5
fill ~48~4~11 ~48~4~44 minecraft:stone_block_slab 5
setblock ~48~29~11 minecraft:stone_brick_stairs 7
setblock ~49~1~11 minecraft:stone_brick_stairs 3
fill ~49~2~11 ~49~3~43 minecraft:water 8
fill ~49~4~11 ~49~4~43 minecraft:water 0
fill ~49~5~11 ~49~5~44 minecraft:stone_block_slab 5
setblock ~49~29~11 minecraft:stone_brick_stairs 4
fill ~50~1~11 ~50~1~38 minecraft:stone_block_slab 5
fill ~50~4~11 ~50~4~43 minecraft:stone_block_slab 5
setblock ~50~28~11 minecraft:stone_block_slab 13
fill ~50~38~11 ~50~38~13 minecraft:stonebrick 0
fill ~50~41~11 ~50~42~15 minecraft:stonebrick 0
fill ~51~0~11 ~51~0~37 minecraft:stone_brick_stairs 1
setblock ~51~5~11 minecraft:stone_brick_stairs 4
setblock ~51~7~11 minecraft:stone_brick_stairs 2
setblock ~51~23~11 minecraft:stone_brick_stairs 7
fill ~51~25~11 ~51~27~11 minecraft:stonebrick 0
fill ~51~29~11 ~55~29~12 minecraft:stonebrick 0
setblock ~51~43~11 minecraft:stonebrick 0
fill ~52~0~11 ~54~0~12 minecraft:brick_block
setblock ~52~6~11 minecraft:beacon
setblock ~52~8~11 minecraft:stone_brick_stairs 2
setblock ~52~22~11 minecraft:stone_brick_stairs 7
setblock ~52~24~11 minecraft:beacon
fill ~52~25~11 ~52~27~11 minecraft:glass_pane
fill ~52~43~11 ~54~43~11 minecraft:glass
setblock ~53~6~11 minecraft:stonebrick 0
setblock ~53~7~11 minecraft:stone_brick_stairs 2
setblock ~53~23~11 minecraft:stone_brick_stairs 7
fill ~53~25~11 ~53~27~11 minecraft:stonebrick 0
setblock ~54~6~11 minecraft:beacon
setblock ~54~8~11 minecraft:stone_brick_stairs 2
setblock ~54~22~11 minecraft:stone_brick_stairs 7
setblock ~54~24~11 minecraft:beacon
fill ~54~25~11 ~54~27~11 minecraft:glass_pane
fill ~55~0~11 ~55~0~37 minecraft:stone_brick_stairs 0
setblock ~55~5~11 minecraft:stone_brick_stairs 5
setblock ~55~7~11 minecraft:stone_brick_stairs 2
setblock ~55~23~11 minecraft:stone_brick_stairs 7
fill ~55~25~11 ~55~27~11 minecraft:stonebrick 0
setblock ~55~43~11 minecraft:stonebrick 0
fill ~56~1~11 ~56~1~38 minecraft:stone_block_slab 5
fill ~56~4~11 ~56~4~43 minecraft:stone_block_slab 5
setblock ~56~28~11 minecraft:stone_block_slab 13
fill ~56~38~11 ~56~38~13 minecraft:stonebrick 0
fill ~56~41~11 ~56~42~15 minecraft:stonebrick 0
setblock ~57~1~11 minecraft:stone_brick_stairs 3
fill ~57~2~11 ~57~3~43 minecraft:water 8
fill ~57~4~11 ~57~4~43 minecraft:water 0
fill ~57~5~11 ~57~5~44 minecraft:stone_block_slab 5
setblock ~57~29~11 minecraft:stone_brick_stairs 7
fill ~58~1~11 ~58~1~43 minecraft:stone_block_slab 5
fill ~58~4~11 ~58~4~44 minecraft:stone_block_slab 5
fill ~59~0~11 ~59~0~12 minecraft:double_stone_block_slab 5
fill ~59~30~11 ~59~30~12 minecraft:double_stone_block_slab 5
setblock ~68~0~11 minecraft:stonebrick 0
fill ~68~1~11 ~70~1~11 minecraft:stone_block_slab 13
setblock ~68~30~11 minecraft:stonebrick 0
setblock ~69~0~11 minecraft:stone_block_slab 5
setblock ~69~30~11 minecraft:stone_block_slab 13
fill ~70~0~11 ~70~0~18 minecraft:stonebrick 0
fill ~70~30~11 ~70~30~18 minecraft:stonebrick 0
setblock ~71~1~11 minecraft:stone_brick_stairs 2
setblock ~71~29~11 minecraft:stone_brick_stairs 6
setblock ~72~1~11 minecraft:stone_brick_stairs 0
setblock ~72~29~11 minecraft:stone_brick_stairs 4
fill ~73~1~11 ~73~1~17 minecraft:stonebrick 0
setblock ~73~2~11 minecraft:stone_block_slab 5
setblock ~73~28~11 minecraft:stone_block_slab 13
fill ~73~29~11 ~73~29~17 minecraft:stonebrick 0
fill ~74~2~11 ~75~2~17 minecraft:stonebrick 0
fill ~74~3~11 ~74~6~11 minecraft:stonebrick 0
setblock ~74~7~11 minecraft:stone_brick_stairs 2
setblock ~74~23~11 minecraft:stone_brick_stairs 6
fill ~74~24~11 ~74~24~17 minecraft:stonebrick 0
fill ~74~25~11 ~74~28~11 minecraft:stonebrick 0
fill ~75~3~11 ~75~5~11 minecraft:glass_pane
setblock ~75~6~11 minecraft:beacon
fill ~75~7~11 ~75~7~17 minecraft:stonebrick 0
setblock ~75~8~11 minecraft:stone_brick_stairs 2
setblock ~75~22~11 minecraft:stone_brick_stairs 6
fill ~75~23~11 ~75~23~17 minecraft:stonebrick 0
setblock ~75~24~11 minecraft:beacon
fill ~75~25~11 ~75~27~11 minecraft:glass_pane
fill ~75~28~11 ~75~28~17 minecraft:stonebrick 0
fill ~76~3~11 ~76~6~11 minecraft:stonebrick 0
setblock ~76~7~11 minecraft:stone_brick_stairs 2
setblock ~76~23~11 minecraft:stone_brick_stairs 6
fill ~76~24~11 ~76~24~17 minecraft:stonebrick 0
fill ~76~25~11 ~76~27~11 minecraft:stonebrick 0
fill ~76~38~11 ~77~38~17 minecraft:stonebrick 0
fill ~77~2~11 ~78~2~17 minecraft:stonebrick 0
fill ~77~3~11 ~77~5~11 minecraft:glass_pane
setblock ~77~6~11 minecraft:beacon
fill ~77~7~11 ~77~7~17 minecraft:stonebrick 0
setblock ~77~8~11 minecraft:stone_brick_stairs 2
setblock ~77~22~11 minecraft:stone_brick_stairs 6
fill ~77~23~11 ~77~23~17 minecraft:stonebrick 0
setblock ~77~24~11 minecraft:beacon
fill ~77~25~11 ~77~27~11 minecraft:glass_pane
fill ~77~28~11 ~78~28~17 minecraft:stonebrick 0
fill ~78~3~11 ~78~6~11 minecraft:stonebrick 0
setblock ~78~7~11 minecraft:stone_brick_stairs 2
setblock ~78~23~11 minecraft:stone_brick_stairs 6
fill ~78~24~11 ~78~24~17 minecraft:stonebrick 0
fill ~78~25~11 ~78~27~11 minecraft:stonebrick 0
fill ~79~1~11 ~79~1~17 minecraft:stonebrick 0
setblock ~79~2~11 minecraft:stone_block_slab 5
setblock ~79~28~11 minecraft:stone_block_slab 13
fill ~79~29~11 ~79~29~17 minecraft:stonebrick 0
setblock ~80~1~11 minecraft:stone_brick_stairs 1
setblock ~80~29~11 minecraft:stone_brick_stairs 5
fill ~80~36~11 ~82~36~25 minecraft:stonebrick 0
fill ~80~37~11 ~81~37~22 minecraft:stonebrick 0
setblock ~81~1~11 minecraft:stone_brick_stairs 2
setblock ~81~29~11 minecraft:stone_brick_stairs 6
fill ~82~0~11 ~82~0~18 minecraft:stonebrick 0
fill ~82~30~11 ~82~30~18 minecraft:stonebrick 0
setblock ~82~35~11 minecraft:stonebrick 0
fill ~83~0~11 ~83~0~16 minecraft:stone_block_slab 5
fill ~83~30~11 ~83~30~16 minecraft:stone_block_slab 13
fill ~84~31~11 ~84~31~31 minecraft:stonebrick 0
fill ~84~32~11 ~84~34~11 minecraft:stonebrick 0
fill ~21~31~12 ~21~31~33 minecraft:stonebrick 0
fill ~21~32~12 ~21~34~12 minecraft:stonebrick 0
fill ~22~34~12 ~22~34~31 minecraft:stonebrick 0
fill ~22~35~12 ~23~36~12 minecraft:stonebrick 0
fill ~24~36~12 ~24~36~27 minecraft:stonebrick 0
fill ~24~37~12 ~24~37~24 minecraft:stonebrick 0
fill ~26~1~12 ~26~1~16 minecraft:stonebrick 0
setblock ~26~2~12 minecraft:stone_block_slab 5
setblock ~26~28~12 minecraft:stone_block_slab 13
fill ~26~29~12 ~26~29~16 minecraft:stonebrick 0
fill ~27~2~12 ~27~2~16 minecraft:stonebrick 0
fill ~27~3~12 ~27~6~12 minecraft:stonebrick 0
setblock ~27~7~12 minecraft:stone_brick_stairs 0
setblock ~27~23~12 minecraft:stone_brick_stairs 4
fill ~27~24~12 ~27~28~12 minecraft:stonebrick 0
fill ~28~3~12 ~32~5~12 minecraft:stone_block_slab 13
fill ~28~6~12 ~33~6~12 minecraft:stonebrick 0
fill ~28~7~12 ~28~7~16 minecraft:stonebrick 0
setblock ~28~8~12 minecraft:stone_block_slab 5
setblock ~28~22~12 minecraft:stone_block_slab 13
fill ~28~23~12 ~28~23~16 minecraft:stonebrick 0
fill ~28~25~12 ~32~27~12 minecraft:stone_block_slab 5
fill ~28~28~12 ~28~28~17 minecraft:stonebrick 0
fill ~28~38~12 ~28~38~18 minecraft:stonebrick 0
fill ~29~8~12 ~29~22~12 minecraft:stonebrick 0
fill ~29~24~12 ~29~24~16 minecraft:stonebrick 0
fill ~30~7~12 ~30~7~16 minecraft:stonebrick 0
fill ~30~8~12 ~30~10~12 minecraft:glass_pane
setblock ~30~11~12 minecraft:beacon
fill ~30~12~12 ~30~14~12 minecraft:glass_pane
setblock ~30~15~12 minecraft:beacon
fill ~30~16~12 ~30~18~12 minecraft:glass_pane
setblock ~30~19~12 minecraft:beacon
fill ~30~20~12 ~30~22~12 minecraft:glass_pane
fill ~30~23~12 ~30~23~16 minecraft:stonebrick 0
fill ~31~8~12 ~31~22~12 minecraft:stonebrick 0
fill ~31~24~12 ~31~24~16 minecraft:stonebrick 0
fill ~32~7~12 ~32~7~16 minecraft:stonebrick 0
setblock ~32~8~12 minecraft:stone_block_slab 5
setblock ~32~22~12 minecraft:stone_block_slab 13
fill ~32~23~12 ~32~23~16 minecraft:stonebrick 0
fill ~33~2~12 ~33~2~16 minecraft:stonebrick 0
fill ~33~3~12 ~33~5~12 minecraft:stonebrick 0
setblock ~33~7~12 minecraft:stone_brick_stairs 1
setblock ~33~23~12 minecraft:stone_brick_stairs 5
fill ~33~24~12 ~33~28~12 minecraft:stonebrick 0
fill ~34~0~12 ~36~0~12 minecraft:stonebrick 0
fill ~34~1~12 ~34~1~16 minecraft:stonebrick 0
setblock ~34~2~12 minecraft:stone_block_slab 5
setblock ~34~28~12 minecraft:stone_block_slab 13
fill ~34~29~12 ~34~29~16 minecraft:stonebrick 0
fill ~34~30~12 ~36~30~12 minecraft:stonebrick 0
fill ~35~1~12 ~35~1~17 minecraft:stone_brick_stairs 1
fill ~35~29~12 ~35~29~17 minecraft:stone_brick_stairs 5
fill ~49~0~12 ~49~1~43 minecraft:water 8
setblock ~49~29~12 minecraft:stone_brick_stairs 7
fill ~50~0~12 ~50~0~13 minecraft:stonebrick 0
setblock ~50~29~12 minecraft:stone_brick_stairs 4
fill ~50~43~12 ~50~43~16 minecraft:stonebrick 0
setblock ~51~28~12 minecraft:stone_block_slab 13
setblock ~51~44~12 minecraft:stonebrick 0
setblock ~52~28~12 minecraft:stone_brick_stairs 7
fill ~52~44~12 ~54~44~12 minecraft:glass
setblock ~53~27~12 minecraft:stone_brick_stairs 7
setblock ~54~28~12 minecraft:stone_brick_stairs 7
setblock ~55~28~12 minecraft:stone_block_slab 13
setblock ~55~44~12 minecraft:stonebrick 0
fill ~56~0~12 ~56~0~13 minecraft:stonebrick 0
setblock ~56~29~12 minecraft:stone_brick_stairs 7
fill ~56~43~12 ~56~43~16 minecraft:stonebrick 0
fill ~57~0~12 ~57~1~43 minecraft:water 8
setblock ~57~29~12 minecraft:stone_brick_stairs 5
fill ~69~0~12 ~69~0~16 minecraft:stonebrick 0
fill ~69~30~12 ~69~30~16 minecraft:stonebrick 0
setblock ~70~1~12 minecraft:stone_block_slab 13
fill ~71~0~12 ~72~0~12 minecraft:stonebrick 0
fill ~71~1~12 ~71~1~16 minecraft:stone_brick_stairs 0
fill ~71~29~12 ~71~29~16 minecraft:stone_brick_stairs 4
fill ~71~30~12 ~72~30~12 minecraft:stonebrick 0
fill ~72~1~12 ~72~1~16 minecraft:stonebrick 0
setblock ~72~2~12 minecraft:stone_block_slab 5
setblock ~72~28~12 minecraft:stone_block_slab 13
fill ~72~29~12 ~72~29~16 minecraft:stonebrick 0
fill ~73~2~12 ~73~2~16 minecraft:stonebrick 0
fill ~73~3~12 ~73~6~12 minecraft:stonebrick 0
setblock ~73~7~12 minecraft:stone_brick_stairs 0
setblock ~73~23~12 minecraft:stone_brick_stairs 4
fill ~73~24~12 ~73~28~12 minecraft:stonebrick 0
fill ~74~3~12 ~78~5~12 minecraft:stone_block_slab 13
fill ~74~6~12 ~79~6~12 minecraft:stonebrick 0
fill ~74~7~12 ~74~7~16 minecraft:stonebrick 0
setblock ~74~8~12 minecraft:stone_block_slab 5
setblock ~74~22~12 minecraft:stone_block_slab 13
fill ~74~23~12 ~74~23~16 minecraft:stonebrick 0
fill ~74~25~12 ~78~27~12 minecraft:stone_block_slab 5
fill ~74~28~12 ~74~28~17 minecraft:stonebrick 0
fill ~75~8~12 ~75~22~12 minecraft:stonebrick 0
fill ~75~24~12 ~75~24~16 minecraft:stonebrick 0
fill ~76~7~12 ~76~7~16 minecraft:stonebrick 0
fill ~76~8~12 ~76~10~12 minecraft:glass_pane
setblock ~76~11~12 minecraft:beacon
fill ~76~12~12 ~76~14~12 minecraft:glass_pane
setblock ~76~15~12 minecraft:beacon
fill ~76~16~12 ~76~18~12 minecraft:glass_pane
setblock ~76~19~12 minecraft:beacon
fill ~76~20~12 ~76~22~12 minecraft:glass_pane
fill ~76~23~12 ~76~23~16 minecraft:stonebrick 0
fill ~77~8~12 ~77~22~12 minecraft:stonebrick 0
fill ~77~24~12 ~77~24~16 minecraft:stonebrick 0
fill ~78~7~12 ~78~7~16 minecraft:stonebrick 0
setblock ~78~8~12 minecraft:stone_block_slab 5
setblock ~78~22~12 minecraft:stone_block_slab 13
fill ~78~23~12 ~78~23~16 minecraft:stonebrick 0
fill ~78~38~12 ~78~38~18 minecraft:stonebrick 0
fill ~79~2~12 ~79~2~16 minecraft:stonebrick 0
fill ~79~3~12 ~79~5~12 minecraft:stonebrick 0
setblock ~79~7~12 minecraft:stone_brick_stairs 1
setblock ~79~23~12 minecraft:stone_brick_stairs 5
fill ~79~24~12 ~79~28~12 minecraft:stonebrick 0
fill ~80~1~12 ~80~1~16 minecraft:stonebrick 0
setblock ~80~2~12 minecraft:stone_block_slab 5
setblock ~80~28~12 minecraft:stone_block_slab 13
fill ~80~29~12 ~80~29~16 minecraft:stonebrick 0
fill ~81~1~12 ~81~1~17 minecraft:stone_brick_stairs 1
fill ~81~29~12 ~81~29~17 minecraft:stone_brick_stairs 5
fill ~82~37~12 ~82~37~24 minecraft:stonebrick 0
fill ~83~35~12 ~84~36~12 minecraft:stonebrick 0
fill ~84~34~12 ~85~34~31 minecraft:stonebrick 0
fill ~85~31~12 ~85~31~33 minecraft:stonebrick 0
fill ~85~32~12 ~85~33~12 minecraft:stonebrick 0
fill ~19~31~13 ~20~31~34 minecraft:stonebrick 0
fill ~19~32~13 ~20~34~13 minecraft:stonebrick 0
fill ~21~34~13 ~21~34~33 minecraft:stonebrick 0
fill ~21~35~13 ~21~36~13 minecraft:stonebrick 0
fill ~22~36~13 ~23~36~28 minecraft:stonebrick 0
fill ~23~37~13 ~23~37~25 minecraft:stonebrick 0
setblock ~26~2~13 minecraft:stone_brick_stairs 0
setblock ~26~28~13 minecraft:stone_brick_stairs 4
fill ~26~38~13 ~27~38~19 minecraft:stonebrick 0
fill ~27~3~13 ~27~5~13 minecraft:glass_pane
setblock ~27~6~13 minecraft:beacon
setblock ~27~7~13 minecraft:stonebrick 0
setblock ~27~8~13 minecraft:stone_brick_stairs 0
setblock ~27~22~13 minecraft:stone_brick_stairs 4
setblock ~27~23~13 minecraft:stonebrick 0
setblock ~27~24~13 minecraft:beacon
fill ~27~25~13 ~27~27~13 minecraft:glass_pane
fill ~27~28~13 ~27~28~16 minecraft:stonebrick 0
fill ~28~3~13 ~28~5~16 minecraft:stone_block_slab 13
fill ~28~6~13 ~32~6~16 minecraft:stonebrick 0
fill ~28~8~13 ~28~22~13 minecraft:stonebrick 0
fill ~28~25~13 ~28~27~16 minecraft:stone_block_slab 5
fill ~29~3~13 ~31~4~13 minecraft:lava 8
fill ~29~5~13 ~31~5~13 minecraft:lava 0
fill ~29~8~13 ~31~12~13 minecraft:stone_block_slab 13
fill ~29~13~13 ~31~22~13 minecraft:stone_block_slab 5
fill ~29~25~13 ~31~25~13 minecraft:lava 0
fill ~32~0~13 ~33~0~13 minecraft:stonebrick 0
fill ~32~3~13 ~32~5~16 minecraft:stone_block_slab 13
fill ~32~8~13 ~32~22~13 minecraft:stonebrick 0
fill ~32~25~13 ~32~27~16 minecraft:stone_block_slab 5
fill ~32~30~13 ~33~30~13 minecraft:stonebrick 0
fill ~33~3~13 ~33~5~13 minecraft:glass_pane
setblock ~33~6~13 minecraft:beacon
setblock ~33~7~13 minecraft:stonebrick 0
setblock ~33~8~13 minecraft:stone_brick_stairs 1
setblock ~33~22~13 minecraft:stone_brick_stairs 5
setblock ~33~23~13 minecraft:stonebrick 0
setblock ~33~24~13 minecraft:beacon
fill ~33~25~13 ~33~27~13 minecraft:glass_pane
fill ~33~28~13 ~33~28~16 minecraft:stonebrick 0
setblock ~34~2~13 minecraft:stone_brick_stairs 1
setblock ~34~28~13 minecraft:stone_brick_stairs 5
fill ~36~0~13 ~37~0~16 minecraft:stonebrick 0
fill ~36~30~13 ~37~30~16 minecraft:stonebrick 0
setblock ~38~38~13 minecraft:stonebrick 0
setblock ~46~37~13 minecraft:stonebrick 0
setblock ~48~0~13 minecraft:double_stone_block_slab 5
setblock ~48~30~13 minecraft:double_stone_block_slab 5
fill ~50~29~13 ~55~29~13 minecraft:stone_brick_stairs 7
setblock ~50~37~13 minecraft:stonebrick 0
fill ~50~44~13 ~50~44~17 minecraft:stonebrick 0
setblock ~51~45~13 minecraft:stonebrick 0
fill ~52~0~13 ~52~0~35 minecraft:brick_block
fill ~52~45~13 ~54~45~13 minecraft:glass
setblock ~53~0~13 minecraft:glowstone
fill ~54~0~13 ~54~0~35 minecraft:brick_block
setblock ~55~45~13 minecraft:stonebrick 0
setblock ~56~29~13 minecraft:stone_brick_stairs 5
setblock ~56~37~13 minecraft:stonebrick 0
fill ~56~44~13 ~56~44~17 minecraft:stonebrick 0
setblock ~58~0~13 minecraft:double_stone_block_slab 5
setblock ~58~30~13 minecraft:double_stone_block_slab 5
setblock ~59~0~13 minecraft:stonebrick 0
setblock ~60~37~13 minecraft:stonebrick 0
setblock ~68~38~13 minecraft:stonebrick 0
setblock ~72~2~13 minecraft:stone_brick_stairs 0
setblock ~72~28~13 minecraft:stone_brick_stairs 4
fill ~73~0~13 ~74~0~13 minecraft:stonebrick 0
fill ~73~3~13 ~73~5~13 minecraft:glass_pane
setblock ~73~6~13 minecraft:beacon
setblock ~73~7~13 minecraft:stonebrick 0
setblock ~73~8~13 minecraft:stone_brick_stairs 0
setblock ~73~22~13 minecraft:stone_brick_stairs 4
setblock ~73~23~13 minecraft:stonebrick 0
setblock ~73~24~13 minecraft:beacon
fill ~73~25~13 ~73~27~13 minecraft:glass_pane
fill ~73~28~13 ~73~28~16 minecraft:stonebrick 0
fill ~73~30~13 ~74~30~13 minecraft:stonebrick 0
fill ~74~3~13 ~74~5~16 minecraft:stone_block_slab 13
fill ~74~6~13 ~78~6~16 minecraft:stonebrick 0
fill ~74~8~13 ~74~22~13 minecraft:stonebrick 0
fill ~74~25~13 ~74~27~16 minecraft:stone_block_slab 5
fill ~75~3~13 ~77~4~13 minecraft:lava 8
fill ~75~5~13 ~77~5~13 minecraft:lava 0
fill ~75~8~13 ~77~12~13 minecraft:stone_block_slab 13
fill ~75~13~13 ~77~22~13 minecraft:stone_block_slab 5
fill ~75~25~13 ~77~25~13 minecraft:lava 0
fill ~78~3~13 ~78~5~16 minecraft:stone_block_slab 13
fill ~78~8~13 ~78~22~13 minecraft:stonebrick 0
fill ~78~25~13 ~78~27~16 minecraft:stone_block_slab 5
fill ~79~3~13 ~79~5~13 minecraft:glass_pane
setblock ~79~6~13 minecraft:beacon
setblock ~79~7~13 minecraft:stonebrick 0
setblock ~79~8~13 minecraft:stone_brick_stairs 1
setblock ~79~22~13 minecraft:stone_brick_stairs 5
setblock ~79~23~13 minecraft:stonebrick 0
setblock ~79~24~13 minecraft:beacon
fill ~79~25~13 ~79~27~13 minecraft:glass_pane
fill ~79~28~13 ~79~28~16 minecraft:stonebrick 0
fill ~79~38~13 ~80~38~19 minecraft:stonebrick 0
setblock ~80~2~13 minecraft:stone_brick_stairs 1
setblock ~80~28~13 minecraft:stone_brick_stairs 5
fill ~83~36~13 ~85~36~28 minecraft:stonebrick 0
fill ~83~37~13 ~83~37~25 minecraft:stonebrick 0
setblock ~85~35~13 minecraft:stonebrick 0
fill ~86~31~13 ~87~31~34 minecraft:stonebrick 0
fill ~86~32~13 ~87~34~13 minecraft:stonebrick 0
fill ~18~31~14 ~18~31~39 minecraft:stonebrick 0
fill ~18~32~14 ~18~34~14 minecraft:stonebrick 0
fill ~19~34~14 ~20~34~34 minecraft:stonebrick 0
fill ~20~35~14 ~20~36~14 minecraft:stonebrick 0
fill ~21~36~14 ~21~36~31 minecraft:stonebrick 0
fill ~21~37~14 ~22~37~26 minecraft:stonebrick 0
fill ~25~38~14 ~25~38~21 minecraft:stonebrick 0
setblock ~26~2~14 minecraft:stonebrick 0
setblock ~26~3~14 minecraft:stone_brick_stairs 0
setblock ~26~27~14 minecraft:stone_brick_stairs 4
setblock ~26~28~14 minecraft:stonebrick 0
fill ~27~3~14 ~27~6~14 minecraft:stonebrick 0
setblock ~27~7~14 minecraft:stone_brick_stairs 0
setblock ~27~23~14 minecraft:stone_brick_stairs 4
fill ~27~24~14 ~27~27~14 minecraft:stonebrick 0
fill ~28~8~14 ~28~10~14 minecraft:glass_pane
setblock ~28~11~14 minecraft:beacon
fill ~28~12~14 ~28~14~14 minecraft:glass_pane
setblock ~28~15~14 minecraft:beacon
fill ~28~16~14 ~28~18~14 minecraft:glass_pane
setblock ~28~19~14 minecraft:beacon
fill ~28~20~14 ~28~22~14 minecraft:glass_pane
fill ~29~3~14 ~29~4~15 minecraft:lava 8
fill ~29~5~14 ~29~5~15 minecraft:lava 0
fill ~29~8~14 ~29~12~15 minecraft:stone_block_slab 13
fill ~29~13~14 ~29~22~15 minecraft:stone_block_slab 5
fill ~29~25~14 ~29~25~15 minecraft:lava 0
setblock ~30~0~14 minecraft:beacon
setblock ~30~1~14 minecraft:stonebrick 0
fill ~30~3~14 ~30~5~14 minecraft:stonebrick 0
fill ~30~8~14 ~30~9~14 minecraft:lava 8
fill ~30~10~14 ~30~11~14 minecraft:lava 0
fill ~30~12~14 ~30~14~14 minecraft:lava 8
fill ~30~15~14 ~30~16~14 minecraft:lava 0
fill ~30~17~14 ~30~18~14 minecraft:lava 8
fill ~30~19~14 ~30~20~14 minecraft:lava 0
fill ~30~25~14 ~30~27~14 minecraft:stonebrick 0
setblock ~30~29~14 minecraft:stonebrick 0
setblock ~30~30~14 minecraft:beacon
setblock ~31~0~14 minecraft:stonebrick 0
fill ~31~3~14 ~31~4~15 minecraft:lava 8
fill ~31~5~14 ~31~5~15 minecraft:lava 0
fill ~31~8~14 ~31~12~15 minecraft:stone_block_slab 13
fill ~31~13~14 ~31~22~15 minecraft:stone_block_slab 5
fill ~31~25~14 ~31~25~15 minecraft:lava 0
setblock ~31~30~14 minecraft:stonebrick 0
fill ~32~8~14 ~32~10~14 minecraft:glass_pane
setblock ~32~11~14 minecraft:beacon
fill ~32~12~14 ~32~14~14 minecraft:glass_pane
setblock ~32~15~14 minecraft:beacon
fill ~32~16~14 ~32~18~14 minecraft:glass_pane
setblock ~32~19~14 minecraft:beacon
fill ~32~20~14 ~32~22~14 minecraft:glass_pane
fill ~33~3~14 ~33~6~14 minecraft:stonebrick 0
setblock ~33~7~14 minecraft:stone_brick_stairs 1
setblock ~33~23~14 minecraft:stone_brick_stairs 5
fill ~33~24~14 ~33~27~14 minecraft:stonebrick 0
setblock ~34~2~14 minecraft:stonebrick 0
setblock ~34~3~14 minecraft:stone_brick_stairs 1
setblock ~34~27~14 minecraft:stone_brick_stairs 5
setblock ~34~28~14 minecraft:stonebrick 0
fill ~35~38~14 ~36~38~14 minecraft:stonebrick 0
fill ~41~37~14 ~42~37~14 minecraft:stonebrick 0
fill ~47~35~14 ~59~35~14 minecraft:stonebrick 0
setblock ~48~0~14 minecraft:stonebrick 0
fill ~49~30~14 ~50~30~14 minecraft:double_stone_block_slab 5
setblock ~50~0~14 minecraft:double_stone_block_slab 5
fill ~50~45~14 ~50~45~18 minecraft:stonebrick 0
fill ~51~37~14 ~51~39~14 minecraft:stonebrick 0
setblock ~51~46~14 minecraft:stonebrick 0
fill ~52~37~14 ~54~39~14 minecraft:glass
fill ~52~46~14 ~54~46~14 minecraft:glass
fill ~53~0~14 ~53~0~15 minecraft:brick_block
fill ~55~37~14 ~55~39~14 minecraft:stonebrick 0
setblock ~55~46~14 minecraft:stonebrick 0
setblock ~56~0~14 minecraft:double_stone_block_slab 5
fill ~56~30~14 ~57~30~14 minecraft:double_stone_block_slab 5
fill ~56~45~14 ~56~45~18 minecraft:stonebrick 0
setblock ~58~0~14 minecraft:stonebrick 0
fill ~64~37~14 ~65~37~14 minecraft:stonebrick 0
fill ~70~38~14 ~71~38~14 minecraft:stonebrick 0
setblock ~72~2~14 minecraft:stonebrick 0
setblock ~72~3~14 minecraft:stone_brick_stairs 0
setblock ~72~27~14 minecraft:stone_brick_stairs 4
setblock ~72~28~14 minecraft:stonebrick 0
fill ~73~3~14 ~73~6~14 minecraft:stonebrick 0
setblock ~73~7~14 minecraft:stone_brick_stairs 0
setblock ~73~23~14 minecraft:stone_brick_stairs 4
fill ~73~24~14 ~73~27~14 minecraft:stonebrick 0
fill ~74~8~14 ~74~10~14 minecraft:glass_pane
setblock ~74~11~14 minecraft:beacon
fill ~74~12~14 ~74~14~14 minecraft:glass_pane
setblock ~74~15~14 minecraft:beacon
fill ~74~16~14 ~74~18~14 minecraft:glass_pane
setblock ~74~19~14 minecraft:beacon
fill ~74~20~14 ~74~22~14 minecraft:glass_pane
setblock ~75~0~14 minecraft:stonebrick 0
fill ~75~3~14 ~75~4~15 minecraft:lava 8
fill ~75~5~14 ~75~5~15 minecraft:lava 0
fill ~75~8~14 ~75~12~15 minecraft:stone_block_slab 13
fill ~75~13~14 ~75~22~15 minecraft:stone_block_slab 5
fill ~75~25~14 ~75~25~15 minecraft:lava 0
setblock ~75~30~14 minecraft:stonebrick 0
setblock ~76~0~14 minecraft:beacon
setblock ~76~1~14 minecraft:stonebrick 0
fill ~76~3~14 ~76~5~14 minecraft:stonebrick 0
fill ~76~8~14 ~76~9~14 minecraft:lava 8
fill ~76~10~14 ~76~11~14 minecraft:lava 0
fill ~76~12~14 ~76~14~14 minecraft:lava 8
fill ~76~15~14 ~76~16~14 minecraft:lava 0
fill ~76~17~14 ~76~18~14 minecraft:lava 8
fill ~76~19~14 ~76~20~14 minecraft:lava 0
fill ~76~25~14 ~76~27~14 minecraft:stonebrick 0
setblock ~76~29~14 minecraft:stonebrick 0
setblock ~76~30~14 minecraft:beacon
fill ~77~3~14 ~77~4~15 minecraft:lava 8
fill ~77~5~14 ~77~5~15 minecraft:lava 0
fill ~77~8~14 ~77~12~15 minecraft:stone_block_slab 13
fill ~77~13~14 ~77~22~15 minecraft:stone_block_slab 5
fill ~77~25~14 ~77~25~15 minecraft:lava 0
fill ~78~8~14 ~78~10~14 minecraft:glass_pane
setblock ~78~11~14 minecraft:beacon
fill ~78~12~14 ~78~14~14 minecraft:glass_pane
setblock ~78~15~14 minecraft:beacon
fill ~78~16~14 ~78~18~14 minecraft:glass_pane
setblock ~78~19~14 minecraft:beacon
fill ~78~20~14 ~78~22~14 minecraft:glass_pane
fill ~79~3~14 ~79~6~14 minecraft:stonebrick 0
setblock ~79~7~14 minecraft:stone_brick_stairs 1
setblock ~79~23~14 minecraft:stone_brick_stairs 5
fill ~79~24~14 ~79~27~14 minecraft:stonebrick 0
setblock ~80~2~14 minecraft:stonebrick 0
setblock ~80~3~14 minecraft:stone_brick_stairs 1
setblock ~80~27~14 minecraft:stone_brick_stairs 5
setblock ~80~28~14 minecraft:stonebrick 0
fill ~81~38~14 ~81~38~21 minecraft:stonebrick 0
fill ~84~37~14 ~85~37~26 minecraft:stonebrick 0
fill ~86~34~14 ~88~34~34 minecraft:stonebrick 0
fill ~86~35~14 ~86~36~14 minecraft:stonebrick 0
fill ~88~31~14 ~88~31~39 minecraft:stonebrick 0
fill ~88~32~14 ~88~33~14 minecraft:stonebrick 0
fill ~17~31~15 ~17~31~42 minecraft:stonebrick 0
fill ~17~32~15 ~17~34~15 minecraft:stonebrick 0
fill ~18~34~15 ~18~34~39 minecraft:stonebrick 0
fill ~19~35~15 ~19~36~15 minecraft:stonebrick 0
fill ~20~36~15 ~20~36~32 minecraft:stonebrick 0
fill ~20~37~15 ~20~37~29 minecraft:stonebrick 0
fill ~23~38~15 ~24~38~21 minecraft:stonebrick 0
setblock ~26~2~15 minecraft:stone_brick_stairs 0
setblock ~26~28~15 minecraft:stone_brick_stairs 4
fill ~27~3~15 ~27~5~15 minecraft:glass_pane
setblock ~27~6~15 minecraft:beacon
setblock ~27~7~15 minecraft:stonebrick 0
setblock ~27~8~15 minecraft:stone_brick_stairs 0
setblock ~27~22~15 minecraft:stone_brick_stairs 4
setblock ~27~23~15 minecraft:stonebrick 0
setblock ~27~24~15 minecraft:beacon
fill ~27~25~15 ~27~27~15 minecraft:glass_pane
fill ~28~0~15 ~29~0~15 minecraft:stonebrick 0
fill ~28~8~15 ~28~22~15 minecraft:stonebrick 0
fill ~28~30~15 ~29~30~15 minecraft:stonebrick 0
fill ~30~3~15 ~30~4~15 minecraft:lava 8
setblock ~30~5~15 minecraft:lava 0
fill ~30~8~15 ~30~12~15 minecraft:stone_block_slab 13
fill ~30~13~15 ~30~22~15 minecraft:stone_block_slab 5
setblock ~30~25~15 minecraft:lava 0
fill ~32~8~15 ~32~22~15 minecraft:stonebrick 0
fill ~33~3~15 ~33~5~15 minecraft:glass_pane
setblock ~33~6~15 minecraft:beacon
setblock ~33~7~15 minecraft:stonebrick 0
setblock ~33~8~15 minecraft:stone_brick_stairs 1
setblock ~33~22~15 minecraft:stone_brick_stairs 5
setblock ~33~23~15 minecraft:stonebrick 0
setblock ~33~24~15 minecraft:beacon
fill ~33~25~15 ~33~27~15 minecraft:glass_pane
setblock ~33~38~15 minecraft:stonebrick 0
setblock ~34~2~15 minecraft:stone_brick_stairs 1
setblock ~34~28~15 minecraft:stone_brick_stairs 5
setblock ~38~37~15 minecraft:stonebrick 0
fill ~43~35~15 ~46~35~15 minecraft:stonebrick 0
setblock ~46~36~15 minecraft:stonebrick 0
fill ~47~32~15 ~59~33~15 minecraft:stonebrick 0
fill ~48~0~15 ~48~0~43 minecraft:stone_block_slab 5
fill ~50~0~15 ~50~0~43 minecraft:stonebrick 0
fill ~50~46~15 ~50~46~19 minecraft:stonebrick 0
fill ~51~30~15 ~55~30~15 minecraft:double_stone_block_slab 5
setblock ~51~40~15 minecraft:stonebrick 0
setblock ~51~47~15 minecraft:stonebrick 0
fill ~52~40~15 ~54~40~15 minecraft:glass
fill ~52~47~15 ~54~47~15 minecraft:glass
setblock ~55~40~15 minecraft:stonebrick 0
setblock ~55~47~15 minecraft:stonebrick 0
fill ~56~0~15 ~56~0~43 minecraft:stonebrick 0
fill ~56~46~15 ~56~46~19 minecraft:stonebrick 0
fill ~58~0~15 ~58~0~43 minecraft:stone_block_slab 5
fill ~60~35~15 ~63~36~15 minecraft:stonebrick 0
fill ~64~36~15 ~65~36~16 minecraft:stonebrick 0
setblock ~68~37~15 minecraft:stonebrick 0
setblock ~72~2~15 minecraft:stone_brick_stairs 0
setblock ~72~28~15 minecraft:stone_brick_stairs 4
fill ~73~3~15 ~73~5~15 minecraft:glass_pane
setblock ~73~6~15 minecraft:beacon
setblock ~73~7~15 minecraft:stonebrick 0
setblock ~73~8~15 minecraft:stone_brick_stairs 0
setblock ~73~22~15 minecraft:stone_brick_stairs 4
setblock ~73~23~15 minecraft:stonebrick 0
setblock ~73~24~15 minecraft:beacon
fill ~73~25~15 ~73~27~15 minecraft:glass_pane
setblock ~73~38~15 minecraft:stonebrick 0
fill ~74~8~15 ~74~22~15 minecraft:stonebrick 0
fill ~76~3~15 ~76~4~15 minecraft:lava 8
setblock ~76~5~15 minecraft:lava 0
fill ~76~8~15 ~76~12~15 minecraft:stone_block_slab 13
fill ~76~13~15 ~76~22~15 minecraft:stone_block_slab 5
setblock ~76~25~15 minecraft:lava 0
fill ~77~0~15 ~78~0~15 minecraft:stonebrick 0
fill ~77~30~15 ~78~30~15 minecraft:stonebrick 0
fill ~78~8~15 ~78~22~15 minecraft:stonebrick 0
fill ~79~3~15 ~79~5~15 minecraft:glass_pane
setblock ~79~6~15 minecraft:beacon
setblock ~79~7~15 minecraft:stonebrick 0
setblock ~79~8~15 minecraft:stone_brick_stairs 1
setblock ~79~22~15 minecraft:stone_brick_stairs 5
setblock ~79~23~15 minecraft:stonebrick 0
setblock ~79~24~15 minecraft:beacon
fill ~79~25~15 ~79~27~15 minecraft:glass_pane
setblock ~80~2~15 minecraft:stone_brick_stairs 1
setblock ~80~28~15 minecraft:stone_brick_stairs 5
fill ~82~38~15 ~83~38~21 minecraft:stonebrick 0
fill ~86~36~15 ~87~36~32 minecraft:stonebrick 0
fill ~86~37~15 ~86~37~29 minecraft:stonebrick 0
setblock ~87~35~15 minecraft:stonebrick 0
fill ~89~31~15 ~89~31~42 minecraft:stonebrick 0
fill ~89~32~15 ~89~34~15 minecraft:stonebrick 0
fill ~16~31~16 ~16~31~46 minecraft:stonebrick 0
fill ~16~32~16 ~16~34~16 minecraft:stonebrick 0
fill ~17~34~16 ~17~34~42 minecraft:stonebrick 0
fill ~18~35~16 ~18~36~16 minecraft:stonebrick 0
fill ~19~36~16 ~19~36~34 minecraft:stonebrick 0
fill ~19~37~16 ~19~37~30 minecraft:stonebrick 0
fill ~22~38~16 ~22~38~23 minecraft:stonebrick 0
setblock ~26~2~16 minecraft:stone_block_slab 5
setblock ~26~28~16 minecraft:stone_block_slab 13
setblock ~27~0~16 minecraft:stonebrick 0
fill ~27~3~16 ~27~6~16 minecraft:stonebrick 0
setblock ~27~7~16 minecraft:stone_brick_stairs 0
setblock ~27~23~16 minecraft:stone_brick_stairs 4
fill ~27~24~16 ~27~27~16 minecraft:stonebrick 0
setblock ~27~30~16 minecraft:stonebrick 0
setblock ~28~8~16 minecraft:stone_block_slab 5
setblock ~28~22~16 minecraft:stone_block_slab 13
fill ~29~3~16 ~31~5~16 minecraft:stone_block_slab 13
fill ~29~8~16 ~29~22~16 minecraft:stonebrick 0
fill ~29~25~16 ~31~27~16 minecraft:stone_block_slab 5
fill ~30~8~16 ~30~10~16 minecraft:glass_pane
setblock ~30~11~16 minecraft:beacon
fill ~30~12~16 ~30~14~16 minecraft:glass_pane
setblock ~30~15~16 minecraft:beacon
fill ~30~16~16 ~30~18~16 minecraft:glass_pane
setblock ~30~19~16 minecraft:beacon
fill ~30~20~16 ~30~22~16 minecraft:glass_pane
fill ~31~8~16 ~31~22~16 minecraft:stonebrick 0
setblock ~32~8~16 minecraft:stone_block_slab 5
setblock ~32~22~16 minecraft:stone_block_slab 13
fill ~33~3~16 ~33~6~16 minecraft:stonebrick 0
setblock ~33~7~16 minecraft:stone_brick_stairs 1
setblock ~33~23~16 minecraft:stone_brick_stairs 5
fill ~33~24~16 ~33~27~16 minecraft:stonebrick 0
setblock ~34~2~16 minecraft:stone_block_slab 5
setblock ~34~28~16 minecraft:stone_block_slab 13
fill ~35~37~16 ~36~37~16 minecraft:stonebrick 0
fill ~40~35~16 ~42~35~16 minecraft:stonebrick 0
fill ~41~36~16 ~42~36~16 minecraft:stonebrick 0
fill ~43~32~16 ~46~33~16 minecraft:stonebrick 0
setblock ~46~31~16 minecraft:stonebrick 0
setblock ~46~34~16 minecraft:stonebrick 0
fill ~50~42~16 ~51~42~16 minecraft:stonebrick 0
fill ~50~47~16 ~50~47~20 minecraft:stonebrick 0
setblock ~51~41~16 minecraft:stonebrick 0
fill ~51~48~16 ~51~48~17 minecraft:stonebrick 0
fill ~52~41~16 ~54~42~16 minecraft:glass
fill ~52~48~16 ~54~48~17 minecraft:glass
setblock ~53~0~16 minecraft:glowstone
fill ~55~41~16 ~55~42~16 minecraft:stonebrick 0
fill ~55~48~16 ~55~48~17 minecraft:stonebrick 0
setblock ~56~42~16 minecraft:stonebrick 0
fill ~56~47~16 ~56~47~20 minecraft:stonebrick 0
fill ~60~31~16 ~60~34~16 minecraft:stonebrick 0
fill ~61~32~16 ~63~34~16 minecraft:stonebrick 0
fill ~64~34~16 ~65~34~17 minecraft:stonebrick 0
fill ~64~35~16 ~66~35~16 minecraft:stonebrick 0
fill ~70~37~16 ~71~37~16 minecraft:stonebrick 0
setblock ~72~2~16 minecraft:stone_block_slab 5
setblock ~72~28~16 minecraft:stone_block_slab 13
fill ~73~3~16 ~73~6~16 minecraft:stonebrick 0
setblock ~73~7~16 minecraft:stone_brick_stairs 0
setblock ~73~23~16 minecraft:stone_brick_stairs 4
fill ~73~24~16 ~73~27~16 minecraft:stonebrick 0
setblock ~74~8~16 minecraft:stone_block_slab 5
setblock ~74~22~16 minecraft:stone_block_slab 13
fill ~75~3~16 ~77~5~16 minecraft:stone_block_slab 13
fill ~75~8~16 ~75~22~16 minecraft:stonebrick 0
fill ~75~25~16 ~77~27~16 minecraft:stone_block_slab 5
fill ~76~8~16 ~76~10~16 minecraft:glass_pane
setblock ~76~11~16 minecraft:beacon
fill ~76~12~16 ~76~14~16 minecraft:glass_pane
setblock ~76~15~16 minecraft:beacon
fill ~76~16~16 ~76~18~16 minecraft:glass_pane
setblock ~76~19~16 minecraft:beacon
fill ~76~20~16 ~76~22~16 minecraft:glass_pane
fill ~77~8~16 ~77~22~16 minecraft:stonebrick 0
setblock ~78~8~16 minecraft:stone_block_slab 5
setblock ~78~22~16 minecraft:stone_block_slab 13
setblock ~79~0~16 minecraft:stonebrick 0
fill ~79~3~16 ~79~6~16 minecraft:stonebrick 0
setblock ~79~7~16 minecraft:stone_brick_stairs 1
setblock ~79~23~16 minecraft:stone_brick_stairs 5
fill ~79~24~16 ~79~27~16 minecraft:stonebrick 0
setblock ~79~30~16 minecraft:stonebrick 0
setblock ~80~2~16 minecraft:stone_block_slab 5
setblock ~80~28~16 minecraft:stone_block_slab 13
fill ~84~38~16 ~84~38~23 minecraft:stonebrick 0
fill ~87~37~16 ~87~37~30 minecraft:stonebrick 0
fill ~88~35~16 ~88~36~16 minecraft:stonebrick 0
fill ~89~34~16 ~90~34~42 minecraft:stonebrick 0
fill ~90~31~16 ~90~31~46 minecraft:stonebrick 0
fill ~90~32~16 ~90~33~16 minecraft:stonebrick 0
fill ~15~31~17 ~15~31~89 minecraft:stonebrick 0
fill ~15~32~17 ~15~34~17 minecraft:stonebrick 0
fill ~16~34~17 ~16~34~46 minecraft:stonebrick 0
fill ~17~35~17 ~17~36~17 minecraft:stonebrick 0
fill ~18~36~17 ~18~36~36 minecraft:stonebrick 0
fill ~18~37~17 ~18~37~32 minecraft:stonebrick 0
fill ~21~38~17 ~21~38~25 minecraft:stonebrick 0
setblock ~26~0~17 minecraft:stonebrick 0
setblock ~26~1~17 minecraft:stone_brick_stairs 3
setblock ~26~29~17 minecraft:stone_brick_stairs 7
setblock ~26~30~17 minecraft:stonebrick 0
setblock ~27~2~17 minecraft:stone_block_slab 5
setblock ~27~28~17 minecraft:stone_block_slab 13
fill ~28~1~17 ~32~1~18 minecraft:stonebrick 0
fill ~28~3~17 ~28~6~17 minecraft:stonebrick 0
setblock ~28~7~17 minecraft:stone_brick_stairs 3
setblock ~28~23~17 minecraft:stone_brick_stairs 7
fill ~28~25~17 ~28~27~17 minecraft:stonebrick 0
fill ~28~29~17 ~32~29~18 minecraft:stonebrick 0
fill ~29~3~17 ~29~5~17 minecraft:glass_pane
setblock ~29~6~17 minecraft:beacon
setblock ~29~8~17 minecraft:stone_brick_stairs 3
setblock ~29~22~17 minecraft:stone_brick_stairs 7
setblock ~29~24~17 minecraft:beacon
fill ~29~25~17 ~29~27~17 minecraft:glass_pane
fill ~30~3~17 ~30~6~17 minecraft:stonebrick 0
setblock ~30~7~17 minecraft:stone_brick_stairs 3
setblock ~30~23~17 minecraft:stone_brick_stairs 7
fill ~30~25~17 ~30~27~17 minecraft:stonebrick 0
fill ~31~3~17 ~31~5~17 minecraft:glass_pane
setblock ~31~6~17 minecraft:beacon
setblock ~31~8~17 minecraft:stone_brick_stairs 3
setblock ~31~22~17 minecraft:stone_brick_stairs 7
setblock ~31~24~17 minecraft:beacon
fill ~31~25~17 ~31~27~17 minecraft:glass_pane
fill ~32~3~17 ~32~6~17 minecraft:stonebrick 0
setblock ~32~7~17 minecraft:stone_brick_stairs 3
setblock ~32~23~17 minecraft:stone_brick_stairs 7
fill ~32~25~17 ~32~27~17 minecraft:stonebrick 0
setblock ~33~2~17 minecraft:stone_block_slab 5
setblock ~33~28~17 minecraft:stone_block_slab 13
setblock ~34~1~17 minecraft:stone_brick_stairs 3
setblock ~34~29~17 minecraft:stone_brick_stairs 7
fill ~36~0~17 ~36~0~18 minecraft:stonebrick 0
fill ~36~30~17 ~36~30~18 minecraft:stonebrick 0
fill ~37~35~17 ~39~35~17 minecraft:stonebrick 0
fill ~38~36~17 ~39~36~17 minecraft:stonebrick 0
fill ~40~32~17 ~42~33~17 minecraft:stonebrick 0
fill ~41~31~17 ~42~31~17 minecraft:stonebrick 0
fill ~41~34~17 ~42~34~17 minecraft:stonebrick 0
fill ~50~48~17 ~50~48~22 minecraft:stonebrick 0
setblock ~51~43~17 minecraft:stonebrick 0
fill ~52~43~17 ~54~43~17 minecraft:glass
fill ~53~0~17 ~53~0~18 minecraft:brick_block
setblock ~55~43~17 minecraft:stonebrick 0
fill ~56~48~17 ~56~48~22 minecraft:stonebrick 0
fill ~64~31~17 ~65~33~17 minecraft:stonebrick 0
fill ~66~32~17 ~66~33~17 minecraft:stonebrick 0
fill ~67~35~17 ~69~36~17 minecraft:stonebrick 0
fill ~70~36~17 ~71~36~18 minecraft:stonebrick 0
setblock ~71~1~17 minecraft:stone_brick_stairs 3
setblock ~71~29~17 minecraft:stone_brick_stairs 7
setblock ~72~1~17 minecraft:stone_brick_stairs 0
setblock ~72~29~17 minecraft:stone_brick_stairs 4
setblock ~73~2~17 minecraft:stone_block_slab 5
setblock ~73~28~17 minecraft:stone_block_slab 13
fill ~74~1~17 ~78~1~18 minecraft:stonebrick 0
fill ~74~3~17 ~74~6~17 minecraft:stonebrick 0
setblock ~74~7~17 minecraft:stone_brick_stairs 3
setblock ~74~23~17 minecraft:stone_brick_stairs 7
fill ~74~25~17 ~74~27~17 minecraft:stonebrick 0
fill ~74~29~17 ~78~29~18 minecraft:stonebrick 0
fill ~75~3~17 ~75~5~17 minecraft:glass_pane
setblock ~75~6~17 minecraft:beacon
setblock ~75~8~17 minecraft:stone_brick_stairs 3
setblock ~75~22~17 minecraft:stone_brick_stairs 7
setblock ~75~24~17 minecraft:beacon
fill ~75~25~17 ~75~27~17 minecraft:glass_pane
fill ~76~3~17 ~76~6~17 minecraft:stonebrick 0
setblock ~76~7~17 minecraft:stone_brick_stairs 3
setblock ~76~23~17 minecraft:stone_brick_stairs 7
fill ~76~25~17 ~76~27~17 minecraft:stonebrick 0
fill ~77~3~17 ~77~5~17 minecraft:glass_pane
setblock ~77~6~17 minecraft:beacon
setblock ~77~8~17 minecraft:stone_brick_stairs 3
setblock ~77~22~17 minecraft:stone_brick_stairs 7
setblock ~77~24~17 minecraft:beacon
fill ~77~25~17 ~77~27~17 minecraft:glass_pane
fill ~78~3~17 ~78~6~17 minecraft:stonebrick 0
setblock ~78~7~17 minecraft:stone_brick_stairs 3
setblock ~78~23~17 minecraft:stone_brick_stairs 7
fill ~78~25~17 ~78~27~17 minecraft:stonebrick 0
setblock ~79~2~17 minecraft:stone_block_slab 5
setblock ~79~28~17 minecraft:stone_block_slab 13
setblock ~80~0~17 minecraft:stonebrick 0
setblock ~80~1~17 minecraft:stone_brick_stairs 3
setblock ~80~29~17 minecraft:stone_brick_stairs 7
setblock ~80~30~17 minecraft:stonebrick 0
fill ~85~38~17 ~85~38~25 minecraft:stonebrick 0
fill ~88~36~17 ~89~36~36 minecraft:stonebrick 0
fill ~88~37~17 ~88~37~32 minecraft:stonebrick 0
setblock ~89~35~17 minecraft:stonebrick 0
fill ~91~31~17 ~91~31~89 minecraft:stonebrick 0
fill ~91~32~17 ~91~34~17 minecraft:stonebrick 0
fill ~14~31~18 ~14~31~88 minecraft:stonebrick 0
fill ~14~32~18 ~14~34~18 minecraft:stonebrick 0
fill ~15~34~18 ~15~34~89 minecraft:stonebrick 0
fill ~16~35~18 ~16~36~18 minecraft:stonebrick 0
fill ~17~36~18 ~17~36~39 minecraft:stonebrick 0
fill ~17~37~18 ~17~37~34 minecraft:stonebrick 0
fill ~20~38~18 ~20~38~26 minecraft:stonebrick 0
setblock ~24~1~18 minecraft:stone_block_slab 13
fill ~25~0~18 ~25~0~19 minecraft:stonebrick 0
fill ~25~30~18 ~25~30~19 minecraft:stonebrick 0
setblock ~26~1~18 minecraft:stone_brick_stairs 0
setblock ~26~29~18 minecraft:stone_brick_stairs 4
setblock ~27~1~18 minecraft:stone_brick_stairs 3
setblock ~27~29~18 minecraft:stone_brick_stairs 7
setblock ~28~2~18 minecraft:stone_block_slab 5
setblock ~28~28~18 minecraft:stone_block_slab 13
setblock ~29~2~18 minecraft:stone_brick_stairs 3
setblock ~29~28~18 minecraft:stone_brick_stairs 7
setblock ~30~3~18 minecraft:stone_brick_stairs 3
setblock ~30~27~18 minecraft:stone_brick_stairs 7
setblock ~31~2~18 minecraft:stone_brick_stairs 3
setblock ~31~28~18 minecraft:stone_brick_stairs 7
setblock ~32~2~18 minecraft:stone_block_slab 5
setblock ~32~28~18 minecraft:stone_block_slab 13
setblock ~33~1~18 minecraft:stone_brick_stairs 3
setblock ~33~29~18 minecraft:stone_brick_stairs 7
setblock ~34~1~18 minecraft:stone_brick_stairs 1
setblock ~34~29~18 minecraft:stone_brick_stairs 5
fill ~35~0~18 ~35~0~19 minecraft:stonebrick 0
fill ~35~30~18 ~35~30~19 minecraft:stonebrick 0
fill ~35~35~18 ~36~36~18 minecraft:stonebrick 0
fill ~37~31~18 ~39~34~18 minecraft:stonebrick 0
setblock ~51~44~18 minecraft:stonebrick 0
setblock ~51~49~18 minecraft:stonebrick 0
fill ~52~44~18 ~54~44~18 minecraft:glass
fill ~52~49~18 ~54~49~18 minecraft:glass
setblock ~55~44~18 minecraft:stonebrick 0
setblock ~55~49~18 minecraft:stonebrick 0
fill ~67~31~18 ~69~34~18 minecraft:stonebrick 0
fill ~70~34~18 ~71~34~19 minecraft:stonebrick 0
fill ~70~35~18 ~71~35~18 minecraft:stonebrick 0
fill ~71~0~18 ~71~0~19 minecraft:stonebrick 0
fill ~71~30~18 ~71~30~19 minecraft:stonebrick 0
setblock ~72~1~18 minecraft:stone_brick_stairs 3
setblock ~72~29~18 minecraft:stone_brick_stairs 7
setblock ~73~1~18 minecraft:stone_brick_stairs 0
setblock ~73~29~18 minecraft:stone_brick_stairs 4
setblock ~74~2~18 minecraft:stone_block_slab 5
setblock ~74~28~18 minecraft:stone_block_slab 13
setblock ~75~2~18 minecraft:stone_brick_stairs 3
setblock ~75~28~18 minecraft:stone_brick_stairs 7
setblock ~76~3~18 minecraft:stone_brick_stairs 3
setblock ~76~27~18 minecraft:stone_brick_stairs 7
setblock ~77~2~18 minecraft:stone_brick_stairs 3
setblock ~77~28~18 minecraft:stone_brick_stairs 7
setblock ~78~2~18 minecraft:stone_block_slab 5
setblock ~78~28~18 minecraft:stone_block_slab 13
setblock ~79~1~18 minecraft:stone_brick_stairs 3
setblock ~79~29~18 minecraft:stone_brick_stairs 7
setblock ~80~1~18 minecraft:stone_brick_stairs 1
setblock ~80~29~18 minecraft:stone_brick_stairs 5
fill ~81~0~18 ~81~0~19 minecraft:stonebrick 0
fill ~81~30~18 ~81~30~19 minecraft:stonebrick 0
setblock ~82~1~18 minecraft:stone_block_slab 13
fill ~86~38~18 ~86~38~26 minecraft:stonebrick 0
fill ~89~37~18 ~89~37~34 minecraft:stonebrick 0
fill ~90~35~18 ~90~36~18 minecraft:stonebrick 0
fill ~91~34~18 ~92~34~88 minecraft:stonebrick 0
fill ~92~31~18 ~92~31~88 minecraft:stonebrick 0
fill ~92~32~18 ~92~33~18 minecraft:stonebrick 0
fill ~13~31~19 ~13~31~87 minecraft:stonebrick 0
fill ~13~32~19 ~13~34~20 minecraft:stonebrick 0
fill ~14~34~19 ~14~34~88 minecraft:stonebrick 0
fill ~15~35~19 ~15~36~19 minecraft:stonebrick 0
fill ~16~36~19 ~16~36~42 minecraft:stonebrick 0
fill ~16~37~19 ~16~37~36 minecraft:stonebrick 0
fill ~19~38~19 ~19~38~27 minecraft:stonebrick 0
setblock ~23~0~19 minecraft:stonebrick 0
setblock ~23~1~19 minecraft:stone_block_slab 13
setblock ~23~30~19 minecraft:stonebrick 0
fill ~26~0~19 ~26~0~20 minecraft:stonebrick 0
fill ~26~30~19 ~26~30~20 minecraft:stonebrick 0
setblock ~27~1~19 minecraft:stone_brick_stairs 0
setblock ~27~29~19 minecraft:stone_brick_stairs 4
fill ~28~1~19 ~32~1~19 minecraft:stone_brick_stairs 3
fill ~28~29~19 ~32~29~19 minecraft:stone_brick_stairs 7
setblock ~33~1~19 minecraft:stone_brick_stairs 1
setblock ~33~29~19 minecraft:stone_brick_stairs 5
fill ~33~35~19 ~34~35~19 minecraft:stonebrick 0
fill ~34~0~19 ~34~0~20 minecraft:stonebrick 0
fill ~34~30~19 ~34~30~20 minecraft:stonebrick 0
fill ~35~32~19 ~36~33~19 minecraft:stonebrick 0
fill ~50~49~19 ~50~49~23 minecraft:stonebrick 0
setblock ~51~45~19 minecraft:stonebrick 0
setblock ~51~50~19 minecraft:stonebrick 0
fill ~52~45~19 ~54~45~19 minecraft:glass
fill ~52~50~19 ~54~50~19 minecraft:glass
setblock ~53~0~19 minecraft:glowstone
setblock ~55~45~19 minecraft:stonebrick 0
setblock ~55~50~19 minecraft:stonebrick 0
fill ~56~49~19 ~56~49~23 minecraft:stonebrick 0
fill ~70~32~19 ~71~33~19 minecraft:stonebrick 0
fill ~72~0~19 ~72~0~20 minecraft:stonebrick 0
fill ~72~30~19 ~72~30~20 minecraft:stonebrick 0
fill ~72~35~19 ~73~35~19 minecraft:stonebrick 0
fill ~73~1~19 ~78~1~19 minecraft:stone_brick_stairs 3
fill ~73~29~19 ~78~29~19 minecraft:stone_brick_stairs 7
setblock ~79~1~19 minecraft:stone_brick_stairs 1
setblock ~79~29~19 minecraft:stone_brick_stairs 5
fill ~80~0~19 ~80~0~20 minecraft:stonebrick 0
fill ~80~30~19 ~80~30~20 minecraft:stonebrick 0
setblock ~83~0~19 minecraft:stonebrick 0
setblock ~83~1~19 minecraft:stone_block_slab 13
setblock ~83~30~19 minecraft:stonebrick 0
fill ~87~38~19 ~87~38~27 minecraft:stonebrick 0
fill ~90~36~19 ~91~36~42 minecraft:stonebrick 0
fill ~90~37~19 ~90~37~36 minecraft:stonebrick 0
setblock ~91~35~19 minecraft:stonebrick 0
fill ~93~31~19 ~93~31~87 minecraft:stonebrick 0
fill ~93~32~19 ~93~34~20 minecraft:stonebrick 0
fill ~14~35~20 ~14~36~20 minecraft:stonebrick 0
fill ~15~36~20 ~15~36~46 minecraft:stonebrick 0
fill ~15~37~20 ~15~37~38 minecraft:stonebrick 0
fill ~18~38~20 ~18~38~28 minecraft:stonebrick 0
setblock ~22~0~20 minecraft:stonebrick 0
setblock ~22~1~20 minecraft:stone_block_slab 13
setblock ~22~30~20 minecraft:stonebrick 0
setblock ~26~38~20 minecraft:stonebrick 0
fill ~27~0~20 ~33~0~20 minecraft:stonebrick 0
fill ~27~30~20 ~33~30~20 minecraft:stonebrick 0
setblock ~29~37~20 minecraft:stonebrick 0
fill ~32~35~20 ~32~36~20 minecraft:stonebrick 0
fill ~34~32~20 ~34~33~20 minecraft:stonebrick 0
fill ~50~50~20 ~50~50~24 minecraft:stonebrick 0
setblock ~51~46~20 minecraft:stonebrick 0
setblock ~51~51~20 minecraft:stonebrick 0
fill ~52~46~20 ~54~46~20 minecraft:glass
fill ~52~51~20 ~54~51~20 minecraft:glass
fill ~53~0~20 ~53~0~21 minecraft:brick_block
setblock ~55~46~20 minecraft:stonebrick 0
setblock ~55~51~20 minecraft:stonebrick 0
fill ~56~50~20 ~56~50~24 minecraft:stonebrick 0
fill ~72~32~20 ~72~33~20 minecraft:stonebrick 0
fill ~73~0~20 ~79~0~20 minecraft:stonebrick 0
fill ~73~30~20 ~79~30~20 minecraft:stonebrick 0
fill ~74~35~20 ~74~36~20 minecraft:stonebrick 0
fill ~75~36~20 ~76~36~21 minecraft:stonebrick 0
setblock ~77~37~20 minecraft:stonebrick 0
setblock ~80~38~20 minecraft:stonebrick 0
setblock ~84~0~20 minecraft:stonebrick 0
setblock ~84~1~20 minecraft:stone_block_slab 13
setblock ~84~30~20 minecraft:stonebrick 0
fill ~88~38~20 ~88~38~28 minecraft:stonebrick 0
fill ~91~37~20 ~91~37~38 minecraft:stonebrick 0
fill ~92~35~20 ~92~36~20 minecraft:stonebrick 0
fill ~12~31~21 ~12~31~85 minecraft:stonebrick 0
fill ~12~32~21 ~12~34~21 minecraft:stonebrick 0
fill ~13~34~21 ~13~34~87 minecraft:stonebrick 0
fill ~13~35~21 ~13~36~21 minecraft:stonebrick 0
fill ~14~36~21 ~14~36~86 minecraft:stonebrick 0
fill ~14~37~21 ~14~37~42 minecraft:stonebrick 0
fill ~17~38~21 ~17~38~30 minecraft:stonebrick 0
setblock ~21~0~21 minecraft:stonebrick 0
setblock ~21~1~21 minecraft:stone_block_slab 13
setblock ~21~30~21 minecraft:stonebrick 0
fill ~28~0~21 ~32~0~21 minecraft:stonebrick 0
fill ~28~30~21 ~32~30~21 minecraft:stonebrick 0
fill ~30~35~21 ~31~35~21 minecraft:stonebrick 0
fill ~32~31~21 ~33~34~21 minecraft:stonebrick 0
fill ~50~51~21 ~50~51~38 minecraft:stonebrick 0
setblock ~51~47~21 minecraft:stonebrick 0
setblock ~51~52~21 minecraft:stonebrick 0
fill ~52~47~21 ~54~47~21 minecraft:glass
fill ~52~52~21 ~54~52~21 minecraft:glass
setblock ~55~47~21 minecraft:stonebrick 0
setblock ~55~52~21 minecraft:stonebrick 0
fill ~56~51~21 ~56~51~38 minecraft:stonebrick 0
fill ~73~31~21 ~74~34~21 minecraft:stonebrick 0
fill ~74~0~21 ~78~0~21 minecraft:stonebrick 0
fill ~74~30~21 ~78~30~21 minecraft:stonebrick 0
fill ~75~34~21 ~76~34~22 minecraft:stonebrick 0
fill ~75~35~21 ~76~35~21 minecraft:stonebrick 0
setblock ~85~0~21 minecraft:stonebrick 0
setblock ~85~1~21 minecraft:stone_block_slab 13
setblock ~85~30~21 minecraft:stonebrick 0
fill ~89~38~21 ~89~38~30 minecraft:stonebrick 0
fill ~92~36~21 ~93~36~85 minecraft:stonebrick 0
fill ~92~37~21 ~92~37~42 minecraft:stonebrick 0
fill ~93~34~21 ~94~34~85 minecraft:stonebrick 0
setblock ~93~35~21 minecraft:stonebrick 0
fill ~94~31~21 ~94~31~85 minecraft:stonebrick 0
fill ~94~32~21 ~94~33~21 minecraft:stonebrick 0
fill ~11~31~22 ~11~31~84 minecraft:stonebrick 0
fill ~11~32~22 ~11~34~22 minecraft:stonebrick 0
fill ~12~34~22 ~12~34~85 minecraft:stonebrick 0
fill ~12~35~22 ~12~36~23 minecraft:stonebrick 0
fill ~13~36~22 ~13~36~85 minecraft:stonebrick 0
fill ~16~38~22 ~16~38~32 minecraft:stonebrick 0
setblock ~20~0~22 minecraft:stonebrick 0
setblock ~20~1~22 minecraft:stone_block_slab 13
setblock ~20~30~22 minecraft:stonebrick 0
setblock ~23~38~22 minecraft:stonebrick 0
setblock ~29~35~22 minecraft:stonebrick 0
fill ~31~32~22 ~31~33~22 minecraft:stonebrick 0
fill ~50~52~22 ~50~52~38 minecraft:stonebrick 0
fill ~51~48~22 ~51~48~23 minecraft:stonebrick 0
fill ~51~53~22 ~51~53~23 minecraft:stonebrick 0
fill ~52~48~22 ~54~48~23 minecraft:glass
fill ~52~53~22 ~54~53~23 minecraft:glass
setblock ~53~0~22 minecraft:glowstone
fill ~55~48~22 ~55~48~23 minecraft:stonebrick 0
fill ~55~53~22 ~55~53~23 minecraft:stonebrick 0
fill ~56~52~22 ~56~52~38 minecraft:stonebrick 0
fill ~75~32~22 ~75~33~22 minecraft:stonebrick 0
setblock ~77~35~22 minecraft:stonebrick 0
setblock ~83~38~22 minecraft:stonebrick 0
setblock ~86~0~22 minecraft:stonebrick 0
setblock ~86~1~22 minecraft:stone_block_slab 13
setblock ~86~30~22 minecraft:stonebrick 0
fill ~90~38~22 ~90~38~32 minecraft:stonebrick 0
fill ~94~35~22 ~94~36~23 minecraft:stonebrick 0
fill ~95~31~22 ~95~31~84 minecraft:stonebrick 0
fill ~95~32~22 ~95~34~22 minecraft:stonebrick 0
fill ~10~31~23 ~10~31~83 minecraft:stonebrick 0
fill ~10~32~23 ~10~34~24 minecraft:stonebrick 0
fill ~11~0~23 ~16~0~23 minecraft:stone_block_slab 5
fill ~11~30~23 ~16~30~23 minecraft:stone_block_slab 13
fill ~11~34~23 ~11~34~84 minecraft:stonebrick 0
fill ~13~37~23 ~13~37~46 minecraft:stonebrick 0
fill ~15~38~23 ~15~38~33 minecraft:stonebrick 0
setblock ~19~0~23 minecraft:stonebrick 0
setblock ~19~1~23 minecraft:stone_block_slab 13
setblock ~19~30~23 minecraft:stonebrick 0
setblock ~25~37~23 minecraft:stonebrick 0
fill ~28~35~23 ~28~36~23 minecraft:stonebrick 0
fill ~29~32~23 ~30~33~23 minecraft:stonebrick 0
setblock ~30~31~23 minecraft:stonebrick 0
setblock ~30~34~23 minecraft:stonebrick 0
fill ~50~53~23 ~50~53~38 minecraft:stonebrick 0
fill ~53~0~23 ~53~0~24 minecraft:brick_block
fill ~56~53~23 ~56~53~38 minecraft:stonebrick 0
fill ~76~31~23 ~76~34~23 minecraft:stonebrick 0
fill ~77~32~23 ~77~33~23 minecraft:stonebrick 0
fill ~78~35~23 ~78~36~23 minecraft:stonebrick 0
fill ~79~36~23 ~79~36~24 minecraft:stonebrick 0
setblock ~81~37~23 minecraft:stonebrick 0
setblock ~87~0~23 minecraft:stonebrick 0
setblock ~87~1~23 minecraft:stone_block_slab 13
setblock ~87~30~23 minecraft:stonebrick 0
fill ~89~0~23 ~95~0~23 minecraft:stone_block_slab 5
fill ~89~30~23 ~95~30~23 minecraft:stone_block_slab 13
fill ~91~38~23 ~91~38~33 minecraft:stonebrick 0
fill ~93~37~23 ~93~37~46 minecraft:stonebrick 0
fill ~95~34~23 ~96~34~83 minecraft:stonebrick 0
fill ~96~31~23 ~96~31~83 minecraft:stonebrick 0
fill ~96~32~23 ~96~33~24 minecraft:stonebrick 0
setblock ~10~0~24 minecraft:stone_block_slab 5
setblock ~10~30~24 minecraft:stone_block_slab 13
fill ~11~0~24 ~18~0~24 minecraft:stonebrick 0
fill ~11~30~24 ~18~30~24 minecraft:stonebrick 0
fill ~11~35~24 ~11~36~24 minecraft:stonebrick 0
fill ~12~36~24 ~12~36~84 minecraft:stonebrick 0
fill ~12~37~24 ~12~37~82 minecraft:stonebrick 0
setblock ~18~1~24 minecraft:stone_block_slab 13
setblock ~27~35~24 minecraft:stonebrick 0
fill ~28~31~24 ~28~34~24 minecraft:stonebrick 0
setblock ~51~49~24 minecraft:stonebrick 0
setblock ~51~54~24 minecraft:stonebrick 0
fill ~52~49~24 ~54~49~24 minecraft:glass
fill ~52~54~24 ~54~54~24 minecraft:glass
setblock ~55~49~24 minecraft:stonebrick 0
setblock ~55~54~24 minecraft:stonebrick 0
fill ~78~31~24 ~78~34~24 minecraft:stonebrick 0
fill ~79~34~24 ~80~34~25 minecraft:stonebrick 0
setblock ~79~35~24 minecraft:stonebrick 0
fill ~88~0~24 ~95~0~24 minecraft:stonebrick 0
setblock ~88~1~24 minecraft:stone_block_slab 13
fill ~88~30~24 ~95~30~24 minecraft:stonebrick 0
fill ~94~36~24 ~95~36~82 minecraft:stonebrick 0
fill ~94~37~24 ~94~37~82 minecraft:stonebrick 0
setblock ~95~35~24 minecraft:stonebrick 0
setblock ~96~0~24 minecraft:stone_block_slab 5
setblock ~96~30~24 minecraft:stone_block_slab 13
setblock ~9~0~25 minecraft:stone_block_slab 5
setblock ~9~30~25 minecraft:stone_block_slab 13
fill ~9~31~25 ~9~31~81 minecraft:stonebrick 0
fill ~9~32~25 ~9~34~25 minecraft:stonebrick 0
setblock ~10~0~25 minecraft:stonebrick 0
setblock ~10~30~25 minecraft:stonebrick 0
fill ~10~34~25 ~10~34~83 minecraft:stonebrick 0
fill ~10~35~25 ~10~36~26 minecraft:stonebrick 0
setblock ~11~1~25 minecraft:stone_brick_stairs 0
setblock ~11~29~25 minecraft:stone_brick_stairs 4
fill ~11~36~25 ~11~36~82 minecraft:stonebrick 0
fill ~11~37~25 ~11~37~81 minecraft:stonebrick 0
fill ~12~1~25 ~17~1~25 minecraft:stone_brick_stairs 2
fill ~12~29~25 ~17~29~25 minecraft:stone_brick_stairs 6
fill ~14~38~25 ~14~38~36 minecraft:stonebrick 0
fill ~18~0~25 ~19~0~25 minecraft:stonebrick 0
fill ~18~30~25 ~19~30~25 minecraft:stonebrick 0
setblock ~26~35~25 minecraft:stonebrick 0
fill ~27~32~25 ~27~33~25 minecraft:stonebrick 0
fill ~50~54~25 ~50~54~38 minecraft:stonebrick 0
fill ~51~50~25 ~51~50~39 minecraft:stonebrick 0
fill ~51~55~25 ~51~55~26 minecraft:stonebrick 0
fill ~52~50~25 ~54~50~38 minecraft:glass
fill ~52~55~25 ~54~55~26 minecraft:glass
setblock ~53~0~25 minecraft:glowstone
fill ~55~50~25 ~55~50~39 minecraft:stonebrick 0
fill ~55~55~25 ~55~55~26 minecraft:stonebrick 0
fill ~56~54~25 ~56~54~38 minecraft:stonebrick 0
fill ~79~32~25 ~79~33~25 minecraft:stonebrick 0
setblock ~80~35~25 minecraft:stonebrick 0
fill ~87~0~25 ~88~0~25 minecraft:stonebrick 0
fill ~87~30~25 ~88~30~25 minecraft:stonebrick 0
fill ~89~1~25 ~95~1~25 minecraft:stone_brick_stairs 2
fill ~89~29~25 ~95~29~25 minecraft:stone_brick_stairs 6
fill ~92~38~25 ~92~38~36 minecraft:stonebrick 0
fill ~95~37~25 ~95~37~81 minecraft:stonebrick 0
setblock ~96~0~25 minecraft:stonebrick 0
setblock ~96~30~25 minecraft:stonebrick 0
fill ~96~35~25 ~96~36~26 minecraft:stonebrick 0
setblock ~97~0~25 minecraft:stone_block_slab 5
setblock ~97~30~25 minecraft:stone_block_slab 13
fill ~97~31~25 ~97~31~81 minecraft:stonebrick 0
fill ~97~32~25 ~97~34~25 minecraft:stonebrick 0
setblock ~8~0~26 minecraft:stone_block_slab 5
setblock ~8~30~26 minecraft:stone_block_slab 13
fill ~8~31~26 ~8~31~80 minecraft:stonebrick 0
fill ~8~32~26 ~8~34~27 minecraft:stonebrick 0
setblock ~9~0~26 minecraft:stonebrick 0
setblock ~9~30~26 minecraft:stonebrick 0
fill ~9~34~26 ~9~34~81 minecraft:stonebrick 0
setblock ~10~1~26 minecraft:stone_brick_stairs 0
setblock ~10~29~26 minecraft:stone_brick_stairs 4
setblock ~11~1~26 minecraft:stone_brick_stairs 2
setblock ~11~29~26 minecraft:stone_brick_stairs 6
fill ~12~1~26 ~16~1~27 minecraft:stonebrick 0
setblock ~12~2~26 minecraft:stone_block_slab 5
setblock ~12~28~26 minecraft:stone_block_slab 13
fill ~12~29~26 ~16~29~27 minecraft:stonebrick 0
setblock ~13~2~26 minecraft:stone_brick_stairs 2
setblock ~13~28~26 minecraft:stone_brick_stairs 6
fill ~13~38~26 ~13~38~38 minecraft:stonebrick 0
fill ~14~2~26 ~14~2~34 minecraft:stonebrick 0
setblock ~14~3~26 minecraft:stone_brick_stairs 2
setblock ~14~27~26 minecraft:stone_brick_stairs 6
fill ~14~28~26 ~14~28~34 minecraft:stonebrick 0
setblock ~15~2~26 minecraft:stone_brick_stairs 2
setblock ~15~28~26 minecraft:stone_brick_stairs 6
setblock ~16~2~26 minecraft:stone_block_slab 5
setblock ~16~28~26 minecraft:stone_block_slab 13
setblock ~17~0~26 minecraft:stonebrick 0
setblock ~17~1~26 minecraft:stone_brick_stairs 1
setblock ~17~29~26 minecraft:stone_brick_stairs 5
setblock ~17~30~26 minecraft:stonebrick 0
setblock ~18~1~26 minecraft:stone_brick_stairs 2
setblock ~18~29~26 minecraft:stone_brick_stairs 6
fill ~19~0~26 ~20~0~26 minecraft:stonebrick 0
fill ~19~30~26 ~20~30~26 minecraft:stonebrick 0
fill ~25~35~26 ~25~36~26 minecraft:stonebrick 0
fill ~26~31~26 ~26~34~26 minecraft:stonebrick 0
fill ~53~0~26 ~53~0~27 minecraft:brick_block
fill ~80~31~26 ~80~34~26 minecraft:stonebrick 0
fill ~81~35~26 ~81~36~26 minecraft:stonebrick 0
fill ~82~36~26 ~82~36~27 minecraft:stonebrick 0
fill ~86~0~26 ~87~0~26 minecraft:stonebrick 0
fill ~86~30~26 ~87~30~26 minecraft:stonebrick 0
setblock ~88~1~26 minecraft:stone_brick_stairs 2
setblock ~88~29~26 minecraft:stone_brick_stairs 6
setblock ~89~0~26 minecraft:stonebrick 0
setblock ~89~1~26 minecraft:stone_brick_stairs 0
setblock ~89~29~26 minecraft:stone_brick_stairs 4
setblock ~89~30~26 minecraft:stonebrick 0
fill ~90~1~26 ~94~1~27 minecraft:stonebrick 0
setblock ~90~2~26 minecraft:stone_block_slab 5
setblock ~90~28~26 minecraft:stone_block_slab 13
fill ~90~29~26 ~94~29~27 minecraft:stonebrick 0
setblock ~91~2~26 minecraft:stone_brick_stairs 2
setblock ~91~28~26 minecraft:stone_brick_stairs 6
fill ~92~2~26 ~92~2~34 minecraft:stonebrick 0
setblock ~92~3~26 minecraft:stone_brick_stairs 2
setblock ~92~27~26 minecraft:stone_brick_stairs 6
fill ~92~28~26 ~92~28~34 minecraft:stonebrick 0
setblock ~93~2~26 minecraft:stone_brick_stairs 2
setblock ~93~28~26 minecraft:stone_brick_stairs 6
fill ~93~38~26 ~93~38~38 minecraft:stonebrick 0
setblock ~94~2~26 minecraft:stone_block_slab 5
setblock ~94~28~26 minecraft:stone_block_slab 13
setblock ~95~1~26 minecraft:stone_brick_stairs 1
setblock ~95~29~26 minecraft:stone_brick_stairs 5
setblock ~96~1~26 minecraft:stone_brick_stairs 2
setblock ~96~29~26 minecraft:stone_brick_stairs 6
setblock ~97~0~26 minecraft:stonebrick 0
setblock ~97~30~26 minecraft:stonebrick 0
fill ~97~34~26 ~98~34~80 minecraft:stonebrick 0
setblock ~98~0~26 minecraft:stone_block_slab 5
setblock ~98~30~26 minecraft:stone_block_slab 13
fill ~98~31~26 ~98~31~80 minecraft:stonebrick 0
fill ~98~32~26 ~98~33~27 minecraft:stonebrick 0
fill ~7~0~27 ~7~0~33 minecraft:stone_block_slab 5
fill ~7~30~27 ~7~30~33 minecraft:stone_block_slab 13
fill ~8~0~27 ~8~0~33 minecraft:stonebrick 0
fill ~8~30~27 ~8~30~33 minecraft:stonebrick 0
fill ~9~1~27 ~9~1~33 minecraft:stone_brick_stairs 0
fill ~9~29~27 ~9~29~33 minecraft:stone_brick_stairs 4
fill ~9~35~27 ~9~36~27 minecraft:stonebrick 0
setblock ~10~1~27 minecraft:stone_brick_stairs 2
setblock ~10~29~27 minecraft:stone_brick_stairs 6
fill ~10~36~27 ~10~36~81 minecraft:stonebrick 0
fill ~10~37~27 ~10~37~79 minecraft:stonebrick 0
fill ~11~1~27 ~11~1~33 minecraft:stonebrick 0
setblock ~11~2~27 minecraft:stone_block_slab 5
setblock ~11~28~27 minecraft:stone_block_slab 13
fill ~11~29~27 ~11~29~33 minecraft:stonebrick 0
fill ~12~2~27 ~13~2~33 minecraft:stonebrick 0
fill ~12~3~27 ~12~6~27 minecraft:stonebrick 0
setblock ~12~7~27 minecraft:stone_brick_stairs 2
setblock ~12~23~27 minecraft:stone_brick_stairs 6
fill ~12~24~27 ~12~24~33 minecraft:stonebrick 0
fill ~12~25~27 ~12~28~27 minecraft:stonebrick 0
fill ~13~3~27 ~13~5~27 minecraft:glass_pane
setblock ~13~6~27 minecraft:beacon
fill ~13~7~27 ~13~7~33 minecraft:stonebrick 0
setblock ~13~8~27 minecraft:stone_brick_stairs 2
setblock ~13~22~27 minecraft:stone_brick_stairs 6
fill ~13~23~27 ~13~23~33 minecraft:stonebrick 0
setblock ~13~24~27 minecraft:beacon
fill ~13~25~27 ~13~27~27 minecraft:glass_pane
fill ~13~28~27 ~13~28~33 minecraft:stonebrick 0
fill ~14~3~27 ~14~6~27 minecraft:stonebrick 0
setblock ~14~7~27 minecraft:stone_brick_stairs 2
setblock ~14~23~27 minecraft:stone_brick_stairs 6
fill ~14~24~27 ~14~24~33 minecraft:stonebrick 0
fill ~14~25~27 ~14~27~27 minecraft:stonebrick 0
fill ~15~2~27 ~16~2~33 minecraft:stonebrick 0
fill ~15~3~27 ~15~5~27 minecraft:glass_pane
setblock ~15~6~27 minecraft:beacon
fill ~15~7~27 ~15~7~33 minecraft:stonebrick 0
setblock ~15~8~27 minecraft:stone_brick_stairs 2
setblock ~15~22~27 minecraft:stone_brick_stairs 6
fill ~15~23~27 ~15~23~33 minecraft:stonebrick 0
setblock ~15~24~27 minecraft:beacon
fill ~15~25~27 ~15~27~27 minecraft:glass_pane
fill ~15~28~27 ~16~28~33 minecraft:stonebrick 0
setblock ~16~0~27 minecraft:stonebrick 0
fill ~16~3~27 ~16~6~27 minecraft:stonebrick 0
setblock ~16~7~27 minecraft:stone_brick_stairs 2
setblock ~16~23~27 minecraft:stone_brick_stairs 6
fill ~16~24~27 ~16~24~33 minecraft:stonebrick 0
fill ~16~25~27 ~16~27~27 minecraft:stonebrick 0
setblock ~16~30~27 minecraft:stonebrick 0
fill ~17~1~27 ~17~1~33 minecraft:stonebrick 0
setblock ~17~2~27 minecraft:stone_block_slab 5
setblock ~17~28~27 minecraft:stone_block_slab 13
fill ~17~29~27 ~17~29~33 minecraft:stonebrick 0
setblock ~18~1~27 minecraft:stone_brick_stairs 1
setblock ~18~29~27 minecraft:stone_brick_stairs 5
setblock ~19~1~27 minecraft:stone_brick_stairs 2
setblock ~19~29~27 minecraft:stone_brick_stairs 6
fill ~20~0~27 ~20~0~34 minecraft:stonebrick 0
fill ~20~30~27 ~20~30~34 minecraft:stonebrick 0
fill ~21~37~27 ~21~37~28 minecraft:stonebrick 0
setblock ~24~35~27 minecraft:stonebrick 0
fill ~25~32~27 ~25~33~27 minecraft:stonebrick 0
fill ~50~55~27 ~50~55~38 minecraft:stonebrick 0
fill ~51~56~27 ~51~56~39 minecraft:stonebrick 0
fill ~52~56~27 ~54~56~38 minecraft:glass
fill ~55~56~27 ~55~56~39 minecraft:stonebrick 0
fill ~56~55~27 ~56~55~38 minecraft:stonebrick 0
fill ~81~32~27 ~81~33~27 minecraft:stonebrick 0
setblock ~82~35~27 minecraft:stonebrick 0
fill ~85~37~27 ~85~37~28 minecraft:stonebrick 0
fill ~86~0~27 ~86~0~34 minecraft:stonebrick 0
fill ~86~30~27 ~86~30~34 minecraft:stonebrick 0
setblock ~87~1~27 minecraft:stone_brick_stairs 2
setblock ~87~29~27 minecraft:stone_brick_stairs 6
setblock ~88~1~27 minecraft:stone_brick_stairs 0
setblock ~88~29~27 minecraft:stone_brick_stairs 4
fill ~89~1~27 ~89~1~33 minecraft:stonebrick 0
setblock ~89~2~27 minecraft:stone_block_slab 5
setblock ~89~28~27 minecraft:stone_block_slab 13
fill ~89~29~27 ~89~29~33 minecraft:stonebrick 0
setblock ~90~0~27 minecraft:stonebrick 0
fill ~90~2~27 ~91~2~33 minecraft:stonebrick 0
fill ~90~3~27 ~90~6~27 minecraft:stonebrick 0
setblock ~90~7~27 minecraft:stone_brick_stairs 2
setblock ~90~23~27 minecraft:stone_brick_stairs 6
fill ~90~24~27 ~90~24~33 minecraft:stonebrick 0
fill ~90~25~27 ~90~28~27 minecraft:stonebrick 0
setblock ~90~30~27 minecraft:stonebrick 0
fill ~91~3~27 ~91~5~27 minecraft:glass_pane
setblock ~91~6~27 minecraft:beacon
fill ~91~7~27 ~91~7~33 minecraft:stonebrick 0
setblock ~91~8~27 minecraft:stone_brick_stairs 2
setblock ~91~22~27 minecraft:stone_brick_stairs 6
fill ~91~23~27 ~91~23~33 minecraft:stonebrick 0
setblock ~91~24~27 minecraft:beacon
fill ~91~25~27 ~91~27~27 minecraft:glass_pane
fill ~91~28~27 ~91~28~33 minecraft:stonebrick 0
fill ~92~3~27 ~92~6~27 minecraft:stonebrick 0
setblock ~92~7~27 minecraft:stone_brick_stairs 2
setblock ~92~23~27 minecraft:stone_brick_stairs 6
fill ~92~24~27 ~92~24~33 minecraft:stonebrick 0
fill ~92~25~27 ~92~27~27 minecraft:stonebrick 0
fill ~93~2~27 ~94~2~33 minecraft:stonebrick 0
fill ~93~3~27 ~93~5~27 minecraft:glass_pane
setblock ~93~6~27 minecraft:beacon
fill ~93~7~27 ~93~7~33 minecraft:stonebrick 0
setblock ~93~8~27 minecraft:stone_brick_stairs 2
setblock ~93~22~27 minecraft:stone_brick_stairs 6
fill ~93~23~27 ~93~23~33 minecraft:stonebrick 0
setblock ~93~24~27 minecraft:beacon
fill ~93~25~27 ~93~27~27 minecraft:glass_pane
fill ~93~28~27 ~94~28~33 minecraft:stonebrick 0
fill ~94~3~27 ~94~6~27 minecraft:stonebrick 0
setblock ~94~7~27 minecraft:stone_brick_stairs 2
setblock ~94~23~27 minecraft:stone_brick_stairs 6
fill ~94~24~27 ~94~24~33 minecraft:stonebrick 0
fill ~94~25~27 ~94~27~27 minecraft:stonebrick 0
fill ~95~1~27 ~95~1~33 minecraft:stonebrick 0
setblock ~95~2~27 minecraft:stone_block_slab 5
setblock ~95~28~27 minecraft:stone_block_slab 13
fill ~95~29~27 ~95~29~33 minecraft:stonebrick 0
setblock ~96~1~27 minecraft:stone_brick_stairs 1
setblock ~96~29~27 minecraft:stone_brick_stairs 5
fill ~96~36~27 ~97~36~79 minecraft:stonebrick 0
fill ~96~37~27 ~96~37~79 minecraft:stonebrick 0
setblock ~97~1~27 minecraft:stone_brick_stairs 2
setblock ~97~29~27 minecraft:stone_brick_stairs 6
setblock ~97~35~27 minecraft:stonebrick 0
fill ~98~0~27 ~98~0~33 minecraft:stonebrick 0
fill ~98~30~27 ~98~30~33 minecraft:stonebrick 0
fill ~99~0~27 ~99~0~33 minecraft:stone_block_slab 5
fill ~99~30~27 ~99~30~33 minecraft:stone_block_slab 13
fill ~7~31~28 ~7~31~78 minecraft:stonebrick 0
fill ~7~32~28 ~7~34~29 minecraft:stonebrick 0
fill ~8~34~28 ~8~34~80 minecraft:stonebrick 0
fill ~8~35~28 ~8~36~29 minecraft:stonebrick 0
fill ~9~36~28 ~9~36~79 minecraft:stonebrick 0
fill ~10~1~28 ~10~1~32 minecraft:stonebrick 0
setblock ~10~2~28 minecraft:stone_block_slab 5
setblock ~10~28~28 minecraft:stone_block_slab 13
fill ~10~29~28 ~10~29~32 minecraft:stonebrick 0
fill ~11~2~28 ~11~2~32 minecraft:stonebrick 0
fill ~11~3~28 ~11~6~28 minecraft:stonebrick 0
setblock ~11~7~28 minecraft:stone_brick_stairs 0
setblock ~11~23~28 minecraft:stone_brick_stairs 4
fill ~11~24~28 ~11~28~28 minecraft:stonebrick 0
fill ~12~3~28 ~16~5~28 minecraft:stone_block_slab 13
fill ~12~6~28 ~17~6~28 minecraft:stonebrick 0
fill ~12~7~28 ~12~7~32 minecraft:stonebrick 0
setblock ~12~8~28 minecraft:stone_block_slab 5
setblock ~12~22~28 minecraft:stone_block_slab 13
fill ~12~23~28 ~12~23~32 minecraft:stonebrick 0
fill ~12~25~28 ~16~27~28 minecraft:stone_block_slab 5
fill ~12~28~28 ~12~28~33 minecraft:stonebrick 0
fill ~12~38~28 ~12~38~41 minecraft:stonebrick 0
fill ~13~8~28 ~13~22~28 minecraft:stonebrick 0
fill ~13~24~28 ~13~24~32 minecraft:stonebrick 0
fill ~14~7~28 ~14~7~32 minecraft:stonebrick 0
fill ~14~8~28 ~14~10~28 minecraft:glass_pane
setblock ~14~11~28 minecraft:beacon
fill ~14~12~28 ~14~14~28 minecraft:glass_pane
setblock ~14~15~28 minecraft:beacon
fill ~14~16~28 ~14~18~28 minecraft:glass_pane
setblock ~14~19~28 minecraft:beacon
fill ~14~20~28 ~14~22~28 minecraft:glass_pane
fill ~14~23~28 ~14~23~32 minecraft:stonebrick 0
fill ~15~0~28 ~15~0~29 minecraft:stonebrick 0
fill ~15~8~28 ~15~22~28 minecraft:stonebrick 0
fill ~15~24~28 ~15~24~32 minecraft:stonebrick 0
fill ~15~30~28 ~15~30~29 minecraft:stonebrick 0
fill ~16~7~28 ~16~7~32 minecraft:stonebrick 0
setblock ~16~8~28 minecraft:stone_block_slab 5
setblock ~16~22~28 minecraft:stone_block_slab 13
fill ~16~23~28 ~16~23~32 minecraft:stonebrick 0
fill ~17~2~28 ~17~2~32 minecraft:stonebrick 0
fill ~17~3~28 ~17~5~28 minecraft:stonebrick 0
setblock ~17~7~28 minecraft:stone_brick_stairs 1
setblock ~17~23~28 minecraft:stone_brick_stairs 5
fill ~17~24~28 ~17~28~28 minecraft:stonebrick 0
fill ~18~1~28 ~18~1~32 minecraft:stonebrick 0
setblock ~18~2~28 minecraft:stone_block_slab 5
setblock ~18~28~28 minecraft:stone_block_slab 13
fill ~18~29~28 ~18~29~32 minecraft:stonebrick 0
fill ~19~1~28 ~19~1~33 minecraft:stone_brick_stairs 1
fill ~19~29~28 ~19~29~33 minecraft:stone_brick_stairs 5
fill ~21~0~28 ~21~0~32 minecraft:stonebrick 0
fill ~21~30~28 ~21~30~32 minecraft:stonebrick 0
setblock ~23~35~28 minecraft:stonebrick 0
fill ~24~32~28 ~24~33~28 minecraft:stonebrick 0
setblock ~53~0~28 minecraft:glowstone
fill ~82~32~28 ~82~34~28 minecraft:stonebrick 0
fill ~83~34~28 ~83~34~30 minecraft:stonebrick 0
setblock ~83~35~28 minecraft:stonebrick 0
fill ~85~0~28 ~85~0~32 minecraft:stonebrick 0
fill ~85~30~28 ~85~30~32 minecraft:stonebrick 0
fill ~87~1~28 ~87~1~32 minecraft:stone_brick_stairs 0
fill ~87~29~28 ~87~29~32 minecraft:stone_brick_stairs 4
fill ~88~1~28 ~88~1~32 minecraft:stonebrick 0
setblock ~88~2~28 minecraft:stone_block_slab 5
setblock ~88~28~28 minecraft:stone_block_slab 13
fill ~88~29~28 ~88~29~32 minecraft:stonebrick 0
fill ~89~2~28 ~89~2~32 minecraft:stonebrick 0
fill ~89~3~28 ~89~6~28 minecraft:stonebrick 0
setblock ~89~7~28 minecraft:stone_brick_stairs 0
setblock ~89~23~28 minecraft:stone_brick_stairs 4
fill ~89~24~28 ~89~28~28 minecraft:stonebrick 0
fill ~90~3~28 ~94~5~28 minecraft:stone_block_slab 13
fill ~90~6~28 ~95~6~28 minecraft:stonebrick 0
fill ~90~7~28 ~90~7~32 minecraft:stonebrick 0
setblock ~90~8~28 minecraft:stone_block_slab 5
setblock ~90~22~28 minecraft:stone_block_slab 13
fill ~90~23~28 ~90~23~32 minecraft:stonebrick 0
fill ~90~25~28 ~94~27~28 minecraft:stone_block_slab 5
fill ~90~28~28 ~90~28~33 minecraft:stonebrick 0
fill ~91~0~28 ~91~0~29 minecraft:stonebrick 0
fill ~91~8~28 ~91~22~28 minecraft:stonebrick 0
fill ~91~24~28 ~91~24~32 minecraft:stonebrick 0
fill ~91~30~28 ~91~30~29 minecraft:stonebrick 0
fill ~92~7~28 ~92~7~32 minecraft:stonebrick 0
fill ~92~8~28 ~92~10~28 minecraft:glass_pane
setblock ~92~11~28 minecraft:beacon
fill ~92~12~28 ~92~14~28 minecraft:glass_pane
setblock ~92~15~28 minecraft:beacon
fill ~92~16~28 ~92~18~28 minecraft:glass_pane
setblock ~92~19~28 minecraft:beacon
fill ~92~20~28 ~92~22~28 minecraft:glass_pane
fill ~92~23~28 ~92~23~32 minecraft:stonebrick 0
fill ~93~8~28 ~93~22~28 minecraft:stonebrick 0
fill ~93~24~28 ~93~24~32 minecraft:stonebrick 0
fill ~94~7~28 ~94~7~32 minecraft:stonebrick 0
setblock ~94~8~28 minecraft:stone_block_slab 5
setblock ~94~22~28 minecraft:stone_block_slab 13
fill ~94~23~28 ~94~23~32 minecraft:stonebrick 0
fill ~94~38~28 ~94~38~41 minecraft:stonebrick 0
fill ~95~2~28 ~95~2~32 minecraft:stonebrick 0
fill ~95~3~28 ~95~5~28 minecraft:stonebrick 0
setblock ~95~7~28 minecraft:stone_brick_stairs 1
setblock ~95~23~28 minecraft:stone_brick_stairs 5
fill ~95~24~28 ~95~28~28 minecraft:stonebrick 0
fill ~96~1~28 ~96~1~32 minecraft:stonebrick 0
setblock ~96~2~28 minecraft:stone_block_slab 5
setblock ~96~28~28 minecraft:stone_block_slab 13
fill ~96~29~28 ~96~29~32 minecraft:stonebrick 0
fill ~97~1~28 ~97~1~33 minecraft:stone_brick_stairs 1
fill ~97~29~28 ~97~29~33 minecraft:stone_brick_stairs 5
fill ~98~35~28 ~98~36~29 minecraft:stonebrick 0
fill ~99~31~28 ~99~31~78 minecraft:stonebrick 0
fill ~99~32~28 ~99~34~29 minecraft:stonebrick 0
fill ~9~37~29 ~9~37~77 minecraft:stonebrick 0
setblock ~10~2~29 minecraft:stone_brick_stairs 0
setblock ~10~28~29 minecraft:stone_brick_stairs 4
fill ~11~3~29 ~11~5~29 minecraft:glass_pane
setblock ~11~6~29 minecraft:beacon
setblock ~11~7~29 minecraft:stonebrick 0
setblock ~11~8~29 minecraft:stone_brick_stairs 0
setblock ~11~22~29 minecraft:stone_brick_stairs 4
setblock ~11~23~29 minecraft:stonebrick 0
setblock ~11~24~29 minecraft:beacon
fill ~11~25~29 ~11~27~29 minecraft:glass_pane
fill ~11~28~29 ~11~28~32 minecraft:stonebrick 0
fill ~11~38~29 ~11~38~46 minecraft:stonebrick 0
fill ~12~3~29 ~12~5~32 minecraft:stone_block_slab 13
fill ~12~6~29 ~16~6~32 minecraft:stonebrick 0
fill ~12~8~29 ~12~22~29 minecraft:stonebrick 0
fill ~12~25~29 ~12~27~32 minecraft:stone_block_slab 5
fill ~13~3~29 ~15~4~29 minecraft:lava 8
fill ~13~5~29 ~15~5~29 minecraft:lava 0
fill ~13~8~29 ~15~12~29 minecraft:stone_block_slab 13
fill ~13~13~29 ~15~22~29 minecraft:stone_block_slab 5
fill ~13~25~29 ~15~25~29 minecraft:lava 0
fill ~16~3~29 ~16~5~32 minecraft:stone_block_slab 13
fill ~16~8~29 ~16~22~29 minecraft:stonebrick 0
fill ~16~25~29 ~16~27~32 minecraft:stone_block_slab 5
fill ~17~3~29 ~17~5~29 minecraft:glass_pane
setblock ~17~6~29 minecraft:beacon
setblock ~17~7~29 minecraft:stonebrick 0
setblock ~17~8~29 minecraft:stone_brick_stairs 1
setblock ~17~22~29 minecraft:stone_brick_stairs 5
setblock ~17~23~29 minecraft:stonebrick 0
setblock ~17~24~29 minecraft:beacon
fill ~17~25~29 ~17~27~29 minecraft:glass_pane
fill ~17~28~29 ~17~28~32 minecraft:stonebrick 0
setblock ~18~2~29 minecraft:stone_brick_stairs 1
setblock ~18~28~29 minecraft:stone_brick_stairs 5
fill ~22~35~29 ~22~36~29 minecraft:stonebrick 0
fill ~23~31~29 ~23~34~30 minecraft:stonebrick 0
fill ~53~0~29 ~53~0~30 minecraft:brick_block
fill ~83~31~29 ~83~33~30 minecraft:stonebrick 0
fill ~84~35~29 ~84~36~29 minecraft:stonebrick 0
fill ~85~36~29 ~85~36~31 minecraft:stonebrick 0
setblock ~88~2~29 minecraft:stone_brick_stairs 0
setblock ~88~28~29 minecraft:stone_brick_stairs 4
fill ~89~3~29 ~89~5~29 minecraft:glass_pane
setblock ~89~6~29 minecraft:beacon
setblock ~89~7~29 minecraft:stonebrick 0
setblock ~89~8~29 minecraft:stone_brick_stairs 0
setblock ~89~22~29 minecraft:stone_brick_stairs 4
setblock ~89~23~29 minecraft:stonebrick 0
setblock ~89~24~29 minecraft:beacon
fill ~89~25~29 ~89~27~29 minecraft:glass_pane
fill ~89~28~29 ~89~28~32 minecraft:stonebrick 0
fill ~90~3~29 ~90~5~32 minecraft:stone_block_slab 13
fill ~90~6~29 ~94~6~32 minecraft:stonebrick 0
fill ~90~8~29 ~90~22~29 minecraft:stonebrick 0
fill ~90~25~29 ~90~27~32 minecraft:stone_block_slab 5
fill ~91~3~29 ~93~4~29 minecraft:lava 8
fill ~91~5~29 ~93~5~29 minecraft:lava 0
fill ~91~8~29 ~93~12~29 minecraft:stone_block_slab 13
fill ~91~13~29 ~93~22~29 minecraft:stone_block_slab 5
fill ~91~25~29 ~93~25~29 minecraft:lava 0
fill ~94~3~29 ~94~5~32 minecraft:stone_block_slab 13
fill ~94~8~29 ~94~22~29 minecraft:stonebrick 0
fill ~94~25~29 ~94~27~32 minecraft:stone_block_slab 5
fill ~95~3~29 ~95~5~29 minecraft:glass_pane
setblock ~95~6~29 minecraft:beacon
setblock ~95~7~29 minecraft:stonebrick 0
setblock ~95~8~29 minecraft:stone_brick_stairs 1
setblock ~95~22~29 minecraft:stone_brick_stairs 5
setblock ~95~23~29 minecraft:stonebrick 0
setblock ~95~24~29 minecraft:beacon
fill ~95~25~29 ~95~27~29 minecraft:glass_pane
fill ~95~28~29 ~95~28~32 minecraft:stonebrick 0
fill ~95~38~29 ~95~38~46 minecraft:stonebrick 0
setblock ~96~2~29 minecraft:stone_brick_stairs 1
setblock ~96~28~29 minecraft:stone_brick_stairs 5
fill ~97~37~29 ~97~37~77 minecraft:stonebrick 0
fill ~6~31~30 ~6~31~76 minecraft:stonebrick 0
fill ~6~32~30 ~6~34~31 minecraft:stonebrick 0
fill ~7~34~30 ~7~34~78 minecraft:stonebrick 0
fill ~7~35~30 ~7~36~31 minecraft:stonebrick 0
fill ~8~36~30 ~8~36~78 minecraft:stonebrick 0
setblock ~10~2~30 minecraft:stonebrick 0
setblock ~10~3~30 minecraft:stone_brick_stairs 0
setblock ~10~27~30 minecraft:stone_brick_stairs 4
setblock ~10~28~30 minecraft:stonebrick 0
