fill ~1 ~0 ~1 ~5 ~0 ~1 stone_slab 0  
fill ~1 ~0 ~2 ~1 ~0 ~5 stone_slab 0  
fill ~1 ~0 ~19 ~2 ~0 ~19 stone_slab 0  
fill ~1 ~0 ~20 ~1 ~0 ~23 stone_slab 0  
fill ~1 ~0 ~37 ~2 ~0 ~37 stone_slab 0  
fill ~1 ~0 ~38 ~1 ~0 ~41 stone_slab 0  
fill ~1 ~0 ~55 ~2 ~0 ~55 stone_slab 0  
fill ~1 ~0 ~56 ~1 ~0 ~59 stone_slab 0  
fill ~1 ~0 ~69 ~2 ~0 ~69 stone_slab 0  
fill ~1 ~0 ~70 ~1 ~0 ~73 stone_slab 0  
fill ~1 ~0 ~87 ~2 ~0 ~87 stone_slab 0  
fill ~1 ~0 ~88 ~1 ~0 ~91 stone_slab 0  
fill ~1 ~0 ~105 ~2 ~0 ~105 stone_slab 0  
fill ~1 ~0 ~106 ~1 ~0 ~109 stone_slab 0  
fill ~1 ~0 ~123 ~2 ~0 ~123 stone_slab 0  
fill ~1 ~0 ~124 ~1 ~0 ~127 stone_slab 0  
fill ~2 ~0 ~2 ~4 ~0 ~2 stained_hardened_clay 5  
fill ~2 ~0 ~3 ~2 ~2 ~3 stained_hardened_clay 5  
fill ~2 ~0 ~4 ~2 ~0 ~2 stained_hardened_clay 5  
fill ~2 ~0 ~5 ~2 ~0 ~8 stone_slab 0  
fill ~2 ~0 ~16 ~3 ~0 ~16 stone_slab 0  
fill ~2 ~0 ~17 ~2 ~0 ~19 stone_slab 0  
fill ~2 ~0 ~20 ~2 ~0 ~22 stained_hardened_clay 5  
fill ~2 ~0 ~23 ~2 ~0 ~26 stone_slab 0  
fill ~2 ~0 ~34 ~3 ~0 ~34 stone_slab 0  
fill ~2 ~0 ~35 ~2 ~0 ~37 stone_slab 0  
fill ~2 ~0 ~38 ~2 ~0 ~40 stained_hardened_clay 5  
fill ~2 ~0 ~41 ~2 ~0 ~44 stone_slab 0  
fill ~2 ~0 ~52 ~3 ~0 ~52 stone_slab 0  
fill ~2 ~0 ~53 ~2 ~0 ~55 stone_slab 0  
fill ~2 ~0 ~56 ~2 ~0 ~58 stained_hardened_clay 5  
fill ~2 ~0 ~59 ~2 ~0 ~63 stone_slab 0  
fill ~2 ~0 ~65 ~3 ~0 ~65 stone_slab 0  
fill ~2 ~0 ~66 ~2 ~0 ~69 stone_slab 0  
fill ~2 ~0 ~70 ~2 ~0 ~72 stained_hardened_clay 5  
fill ~2 ~0 ~73 ~2 ~0 ~76 stone_slab 0  
fill ~2 ~0 ~84 ~3 ~0 ~84 stone_slab 0  
fill ~2 ~0 ~85 ~2 ~0 ~87 stone_slab 0  
fill ~2 ~0 ~88 ~2 ~0 ~90 stained_hardened_clay 5  
fill ~2 ~0 ~91 ~2 ~0 ~94 stone_slab 0  
fill ~2 ~0 ~102 ~3 ~0 ~102 stone_slab 0  
fill ~2 ~0 ~103 ~2 ~0 ~105 stone_slab 0  
fill ~2 ~0 ~106 ~2 ~0 ~108 stained_hardened_clay 5  
fill ~2 ~0 ~109 ~2 ~0 ~112 stone_slab 0  
fill ~2 ~0 ~120 ~3 ~0 ~120 stone_slab 0  
fill ~2 ~0 ~121 ~2 ~0 ~123 stone_slab 0  
fill ~2 ~0 ~124 ~2 ~0 ~126 stained_hardened_clay 5  
fill ~2 ~0 ~127 ~5 ~0 ~127 stone_slab 0  
fill ~3 ~0 ~5 ~3 ~1 ~5 wool 13  
fill ~3 ~0 ~6 ~3 ~0 ~7 wool 13  
fill ~3 ~0 ~8 ~3 ~0 ~16 stone_slab 0  
fill ~3 ~0 ~17 ~3 ~0 ~19 wool 13  
fill ~3 ~0 ~23 ~3 ~1 ~23 wool 13  
fill ~3 ~0 ~24 ~3 ~0 ~25 wool 13  
fill ~3 ~0 ~26 ~3 ~0 ~34 stone_slab 0  
fill ~3 ~0 ~35 ~3 ~0 ~37 wool 13  
fill ~3 ~0 ~41 ~3 ~1 ~41 wool 13  
fill ~3 ~0 ~42 ~3 ~0 ~43 wool 13  
fill ~3 ~0 ~44 ~3 ~0 ~52 stone_slab 0  
fill ~3 ~0 ~53 ~3 ~0 ~55 wool 13  
fill ~3 ~0 ~59 ~3 ~1 ~59 wool 13  
fill ~3 ~0 ~60 ~3 ~0 ~62 wool 13  
fill ~3 ~0 ~63 ~3 ~0 ~65 stone_slab 0  
fill ~3 ~0 ~66 ~3 ~0 ~69 wool 13  
fill ~3 ~0 ~73 ~3 ~1 ~73 wool 13  
fill ~3 ~0 ~74 ~3 ~0 ~75 wool 13  
fill ~3 ~0 ~76 ~3 ~0 ~84 stone_slab 0  
fill ~3 ~0 ~85 ~3 ~0 ~87 wool 13  
fill ~3 ~0 ~91 ~3 ~1 ~91 wool 13  
fill ~3 ~0 ~92 ~3 ~0 ~93 wool 13  
fill ~3 ~0 ~94 ~3 ~0 ~102 stone_slab 0  
fill ~3 ~0 ~103 ~3 ~0 ~105 wool 13  
fill ~3 ~0 ~109 ~3 ~1 ~109 wool 13  
fill ~3 ~0 ~110 ~3 ~0 ~111 wool 13  
fill ~3 ~0 ~112 ~3 ~0 ~120 stone_slab 0  
fill ~3 ~0 ~121 ~3 ~0 ~123 wool 13  
fill ~3 ~0 ~126 ~4 ~0 ~126 stained_hardened_clay 5  
fill ~4 ~0 ~4 ~7 ~0 ~4 stained_hardened_clay 15  
fill ~4 ~0 ~5 ~4 ~1 ~5 stained_hardened_clay 15  
fill ~4 ~0 ~6 ~4 ~0 ~7 stained_hardened_clay 15  
fill ~4 ~0 ~8 ~4 ~1 ~8 stained_hardened_clay 13  
fill ~4 ~0 ~9 ~4 ~0 ~16 stained_hardened_clay 13  
fill ~4 ~0 ~17 ~4 ~0 ~25 stained_hardened_clay 15  
fill ~4 ~0 ~26 ~4 ~1 ~26 stained_hardened_clay 13  
fill ~4 ~0 ~27 ~4 ~0 ~34 stained_hardened_clay 13  
fill ~4 ~0 ~35 ~4 ~0 ~43 stained_hardened_clay 15  
fill ~4 ~0 ~44 ~4 ~1 ~44 stained_hardened_clay 13  
fill ~4 ~0 ~45 ~4 ~0 ~52 stained_hardened_clay 13  
fill ~4 ~0 ~53 ~4 ~0 ~57 stained_hardened_clay 15  
fill ~4 ~0 ~62 ~4 ~1 ~62 stained_hardened_clay 13  
fill ~4 ~0 ~63 ~4 ~1 ~63 stained_hardened_clay 13  
fill ~4 ~0 ~64 ~4 ~0 ~66 stained_hardened_clay 13  
fill ~4 ~0 ~71 ~4 ~6 ~71 stained_hardened_clay 15  
fill ~4 ~0 ~72 ~4 ~3 ~72 stained_hardened_clay 15  
fill ~4 ~0 ~73 ~4 ~1 ~73 stained_hardened_clay 15  
fill ~4 ~0 ~74 ~4 ~0 ~75 stained_hardened_clay 15  
fill ~4 ~0 ~76 ~4 ~1 ~76 stained_hardened_clay 13  
fill ~4 ~0 ~77 ~4 ~0 ~84 stained_hardened_clay 13  
fill ~4 ~0 ~85 ~4 ~0 ~93 stained_hardened_clay 15  
fill ~4 ~0 ~94 ~4 ~1 ~94 stained_hardened_clay 13  
fill ~4 ~0 ~95 ~4 ~0 ~102 stained_hardened_clay 13  
fill ~4 ~0 ~103 ~4 ~0 ~111 stained_hardened_clay 15  
fill ~4 ~0 ~112 ~4 ~1 ~112 stained_hardened_clay 13  
fill ~4 ~0 ~113 ~4 ~0 ~120 stained_hardened_clay 13  
fill ~4 ~0 ~121 ~4 ~0 ~124 stained_hardened_clay 15  
fill ~5 ~0 ~2 ~8 ~0 ~2 stone_slab 0  
fill ~5 ~0 ~3 ~7 ~0 ~3 wool 13  
fill ~5 ~0 ~8 ~5 ~1 ~8 log2 13  
fill ~5 ~0 ~9 ~6 ~0 ~9 log2 13  
fill ~5 ~0 ~10 ~6 ~0 ~10 log2 13  
fill ~5 ~0 ~11 ~6 ~0 ~11 log2 13  
fill ~5 ~0 ~12 ~6 ~0 ~12 log2 13  
fill ~5 ~0 ~13 ~6 ~0 ~13 log2 13  
fill ~5 ~0 ~14 ~6 ~0 ~14 log2 13  
fill ~5 ~0 ~15 ~6 ~0 ~15 log2 13  
fill ~5 ~0 ~16 ~5 ~1 ~16 log2 13  
fill ~5 ~0 ~26 ~5 ~1 ~26 log2 13  
fill ~5 ~0 ~27 ~6 ~0 ~27 log2 13  
fill ~5 ~0 ~28 ~6 ~0 ~28 log2 13  
fill ~5 ~0 ~29 ~6 ~0 ~29 log2 13  
fill ~5 ~0 ~30 ~6 ~0 ~30 log2 13  
fill ~5 ~0 ~31 ~6 ~0 ~31 log2 13  
fill ~5 ~0 ~32 ~6 ~0 ~32 log2 13  
fill ~5 ~0 ~33 ~6 ~0 ~33 log2 13  
fill ~5 ~0 ~34 ~5 ~1 ~34 log2 13  
fill ~5 ~0 ~44 ~5 ~1 ~44 log2 13  
fill ~5 ~0 ~45 ~6 ~0 ~45 log2 13  
fill ~5 ~0 ~46 ~6 ~0 ~46 log2 13  
fill ~5 ~0 ~47 ~6 ~0 ~47 log2 13  
fill ~5 ~0 ~48 ~6 ~0 ~48 log2 13  
fill ~5 ~0 ~49 ~6 ~0 ~49 log2 13  
fill ~5 ~0 ~50 ~6 ~0 ~50 log2 13  
fill ~5 ~0 ~51 ~6 ~0 ~51 log2 13  
fill ~5 ~0 ~52 ~5 ~1 ~52 log2 13  
fill ~5 ~0 ~58 ~5 ~5 ~58 dirt 0  
fill ~5 ~0 ~59 ~5 ~4 ~59 dirt 0  
fill ~5 ~0 ~60 ~5 ~2 ~60 dirt 0  
fill ~5 ~0 ~61 ~5 ~1 ~61 dirt 0  
fill ~5 ~0 ~62 ~5 ~1 ~62 dirt 0  
fill ~5 ~0 ~63 ~5 ~1 ~63 dirt 0  
fill ~5 ~0 ~64 ~5 ~0 ~64 dirt 0  
fill ~5 ~0 ~65 ~5 ~1 ~65 dirt 0  
fill ~5 ~0 ~66 ~5 ~1 ~66 dirt 0  
fill ~5 ~0 ~67 ~5 ~1 ~67 dirt 0  
fill ~5 ~0 ~68 ~5 ~2 ~68 dirt 0  
fill ~5 ~0 ~69 ~5 ~4 ~69 dirt 0  
fill ~5 ~0 ~70 ~5 ~5 ~70 dirt 0  
fill ~5 ~0 ~76 ~5 ~1 ~76 log2 13  
fill ~5 ~0 ~77 ~6 ~0 ~77 log2 13  
fill ~5 ~0 ~78 ~6 ~0 ~78 log2 13  
fill ~5 ~0 ~79 ~6 ~0 ~79 log2 13  
fill ~5 ~0 ~80 ~6 ~0 ~80 log2 13  
fill ~5 ~0 ~81 ~6 ~0 ~81 log2 13  
fill ~5 ~0 ~82 ~6 ~0 ~82 log2 13  
fill ~5 ~0 ~83 ~6 ~0 ~83 log2 13  
fill ~5 ~0 ~84 ~5 ~1 ~84 log2 13  
fill ~5 ~0 ~94 ~5 ~1 ~94 log2 13  
fill ~5 ~0 ~95 ~6 ~0 ~95 log2 13  
fill ~5 ~0 ~96 ~6 ~0 ~96 log2 13  
fill ~5 ~0 ~97 ~6 ~0 ~97 log2 13  
fill ~5 ~0 ~98 ~6 ~0 ~98 log2 13  
fill ~5 ~0 ~99 ~6 ~0 ~99 log2 13  
fill ~5 ~0 ~100 ~6 ~0 ~100 log2 13  
fill ~5 ~0 ~101 ~6 ~0 ~101 log2 13  
fill ~5 ~0 ~102 ~5 ~1 ~102 log2 13  
fill ~5 ~0 ~112 ~5 ~1 ~112 log2 13  
fill ~5 ~0 ~113 ~6 ~0 ~113 log2 13  
fill ~5 ~0 ~114 ~6 ~0 ~114 log2 13  
fill ~5 ~0 ~115 ~6 ~0 ~115 log2 13  
fill ~5 ~0 ~116 ~6 ~0 ~116 log2 13  
fill ~5 ~0 ~117 ~6 ~0 ~117 log2 13  
fill ~5 ~0 ~118 ~6 ~0 ~118 log2 13  
fill ~5 ~0 ~119 ~6 ~0 ~119 log2 13  
fill ~5 ~0 ~120 ~5 ~1 ~120 log2 13  
fill ~5 ~0 ~124 ~7 ~0 ~124 stained_hardened_clay 15  
fill ~5 ~0 ~125 ~7 ~0 ~125 wool 13  
fill ~5 ~0 ~126 ~8 ~0 ~126 stone_slab 0  
fill ~8 ~0 ~3 ~16 ~0 ~3 stone_slab 0  
fill ~8 ~0 ~4 ~16 ~0 ~4 stained_hardened_clay 13  
fill ~8 ~0 ~5 ~16 ~0 ~5 log2 13  
fill ~8 ~0 ~123 ~16 ~0 ~123 log2 13  
fill ~8 ~0 ~124 ~16 ~0 ~124 stained_hardened_clay 13  
fill ~8 ~0 ~125 ~16 ~0 ~125 stone_slab 0  
fill ~9 ~0 ~6 ~15 ~0 ~6 log2 13  
fill ~9 ~0 ~122 ~15 ~0 ~122 log2 13  
fill ~16 ~0 ~2 ~19 ~0 ~2 stone_slab 0  
fill ~16 ~0 ~126 ~19 ~0 ~126 stone_slab 0  
fill ~17 ~0 ~3 ~19 ~0 ~3 wool 13  
fill ~17 ~0 ~4 ~25 ~0 ~4 stained_hardened_clay 15  
fill ~17 ~0 ~124 ~25 ~0 ~124 stained_hardened_clay 15  
fill ~17 ~0 ~125 ~19 ~0 ~125 wool 13  
fill ~19 ~0 ~1 ~23 ~0 ~1 stone_slab 0  
fill ~19 ~0 ~127 ~23 ~0 ~127 stone_slab 0  
fill ~20 ~0 ~2 ~22 ~0 ~2 stained_hardened_clay 5  
fill ~20 ~0 ~126 ~22 ~0 ~126 stained_hardened_clay 5  
fill ~23 ~0 ~2 ~26 ~0 ~2 stone_slab 0  
fill ~23 ~0 ~3 ~25 ~0 ~3 wool 13  
fill ~23 ~0 ~125 ~25 ~0 ~125 wool 13  
fill ~23 ~0 ~126 ~26 ~0 ~126 stone_slab 0  
fill ~26 ~0 ~3 ~34 ~0 ~3 stone_slab 0  
fill ~26 ~0 ~4 ~34 ~0 ~4 stained_hardened_clay 13  
fill ~26 ~0 ~5 ~34 ~0 ~5 log2 13  
fill ~26 ~0 ~123 ~34 ~0 ~123 log2 13  
fill ~26 ~0 ~124 ~34 ~0 ~124 stained_hardened_clay 13  
fill ~26 ~0 ~125 ~34 ~0 ~125 stone_slab 0  
fill ~27 ~0 ~6 ~33 ~0 ~6 log2 13  
fill ~27 ~0 ~122 ~33 ~0 ~122 log2 13  
fill ~34 ~0 ~2 ~37 ~0 ~2 stone_slab 0  
fill ~34 ~0 ~126 ~37 ~0 ~126 stone_slab 0  
fill ~35 ~0 ~3 ~37 ~0 ~3 wool 13  
fill ~35 ~0 ~4 ~43 ~0 ~4 stained_hardened_clay 15  
fill ~35 ~0 ~124 ~43 ~0 ~124 stained_hardened_clay 15  
fill ~35 ~0 ~125 ~37 ~0 ~125 wool 13  
fill ~37 ~0 ~1 ~41 ~0 ~1 stone_slab 0  
fill ~37 ~0 ~127 ~41 ~0 ~127 stone_slab 0  
fill ~38 ~0 ~2 ~40 ~0 ~2 stained_hardened_clay 5  
fill ~38 ~0 ~126 ~40 ~0 ~126 stained_hardened_clay 5  
fill ~41 ~0 ~2 ~44 ~0 ~2 stone_slab 0  
fill ~41 ~0 ~3 ~43 ~0 ~3 wool 13  
fill ~41 ~0 ~125 ~43 ~0 ~125 wool 13  
fill ~41 ~0 ~126 ~44 ~0 ~126 stone_slab 0  
fill ~44 ~0 ~3 ~52 ~0 ~3 stone_slab 0  
fill ~44 ~0 ~4 ~52 ~0 ~4 stained_hardened_clay 13  
fill ~44 ~0 ~5 ~52 ~0 ~5 log2 13  
fill ~44 ~0 ~123 ~52 ~0 ~123 log2 13  
fill ~44 ~0 ~124 ~52 ~0 ~124 stained_hardened_clay 13  
fill ~44 ~0 ~125 ~52 ~0 ~125 stone_slab 0  
fill ~45 ~0 ~6 ~51 ~0 ~6 log2 13  
fill ~45 ~0 ~122 ~51 ~0 ~122 log2 13  
fill ~52 ~0 ~2 ~55 ~0 ~2 stone_slab 0  
fill ~52 ~0 ~126 ~55 ~0 ~126 stone_slab 0  
fill ~53 ~0 ~3 ~55 ~0 ~3 wool 13  
fill ~53 ~0 ~4 ~57 ~0 ~4 stained_hardened_clay 15  
fill ~53 ~0 ~124 ~57 ~0 ~124 stained_hardened_clay 15  
fill ~53 ~0 ~125 ~55 ~0 ~125 wool 13  
fill ~55 ~0 ~1 ~59 ~0 ~1 stone_slab 0  
fill ~55 ~0 ~127 ~59 ~0 ~127 stone_slab 0  
fill ~56 ~0 ~2 ~58 ~0 ~2 stained_hardened_clay 5  
fill ~56 ~0 ~126 ~58 ~0 ~126 stained_hardened_clay 5  
fill ~58 ~0 ~5 ~70 ~0 ~5 dirt 0  
fill ~58 ~0 ~123 ~70 ~0 ~123 dirt 0  
fill ~59 ~0 ~2 ~63 ~0 ~2 stone_slab 0  
fill ~59 ~0 ~3 ~62 ~0 ~3 wool 13  
fill ~59 ~0 ~125 ~62 ~0 ~125 wool 13  
fill ~59 ~0 ~126 ~63 ~0 ~126 stone_slab 0  
fill ~62 ~0 ~4 ~66 ~0 ~4 stained_hardened_clay 13  
fill ~62 ~0 ~124 ~66 ~0 ~124 stained_hardened_clay 13  
fill ~63 ~0 ~3 ~65 ~0 ~3 stone_slab 0  
fill ~63 ~0 ~125 ~65 ~0 ~125 stone_slab 0  
fill ~65 ~0 ~2 ~69 ~0 ~2 stone_slab 0  
fill ~65 ~0 ~126 ~69 ~0 ~126 stone_slab 0  
fill ~66 ~0 ~3 ~69 ~0 ~3 wool 13  
fill ~66 ~0 ~125 ~69 ~0 ~125 wool 13  
fill ~69 ~0 ~1 ~73 ~0 ~1 stone_slab 0  
fill ~69 ~0 ~127 ~73 ~0 ~127 stone_slab 0  
fill ~70 ~0 ~2 ~72 ~0 ~2 stained_hardened_clay 5  
fill ~70 ~0 ~126 ~72 ~0 ~126 stained_hardened_clay 5  
fill ~71 ~0 ~4 ~75 ~0 ~4 stained_hardened_clay 15  
fill ~71 ~0 ~124 ~75 ~0 ~124 stained_hardened_clay 15  
fill ~73 ~0 ~2 ~76 ~0 ~2 stone_slab 0  
fill ~73 ~0 ~3 ~75 ~0 ~3 wool 13  
fill ~73 ~0 ~125 ~75 ~0 ~125 wool 13  
fill ~73 ~0 ~126 ~76 ~0 ~126 stone_slab 0  
fill ~76 ~0 ~3 ~84 ~0 ~3 stone_slab 0  
fill ~76 ~0 ~4 ~84 ~0 ~4 stained_hardened_clay 13  
fill ~76 ~0 ~5 ~84 ~0 ~5 log2 13  
fill ~76 ~0 ~123 ~84 ~0 ~123 log2 13  
fill ~76 ~0 ~124 ~84 ~0 ~124 stained_hardened_clay 13  
fill ~76 ~0 ~125 ~84 ~0 ~125 stone_slab 0  
fill ~77 ~0 ~6 ~83 ~0 ~6 log2 13  
fill ~77 ~0 ~122 ~83 ~0 ~122 log2 13  
fill ~84 ~0 ~2 ~87 ~0 ~2 stone_slab 0  
fill ~84 ~0 ~126 ~87 ~0 ~126 stone_slab 0  
fill ~85 ~0 ~3 ~87 ~0 ~3 wool 13  
fill ~85 ~0 ~4 ~93 ~0 ~4 stained_hardened_clay 15  
fill ~85 ~0 ~124 ~93 ~0 ~124 stained_hardened_clay 15  
fill ~85 ~0 ~125 ~87 ~0 ~125 wool 13  
fill ~87 ~0 ~1 ~91 ~0 ~1 stone_slab 0  
fill ~87 ~0 ~127 ~91 ~0 ~127 stone_slab 0  
fill ~88 ~0 ~2 ~90 ~0 ~2 stained_hardened_clay 5  
fill ~88 ~0 ~126 ~90 ~0 ~126 stained_hardened_clay 5  
fill ~91 ~0 ~2 ~94 ~0 ~2 stone_slab 0  
fill ~91 ~0 ~3 ~93 ~0 ~3 wool 13  
fill ~91 ~0 ~125 ~93 ~0 ~125 wool 13  
fill ~91 ~0 ~126 ~94 ~0 ~126 stone_slab 0  
fill ~94 ~0 ~3 ~102 ~0 ~3 stone_slab 0  
fill ~94 ~0 ~4 ~102 ~0 ~4 stained_hardened_clay 13  
fill ~94 ~0 ~5 ~102 ~0 ~5 log2 13  
fill ~94 ~0 ~123 ~102 ~0 ~123 log2 13  
fill ~94 ~0 ~124 ~102 ~0 ~124 stained_hardened_clay 13  
fill ~94 ~0 ~125 ~102 ~0 ~125 stone_slab 0  
fill ~95 ~0 ~6 ~101 ~0 ~6 log2 13  
fill ~95 ~0 ~122 ~101 ~0 ~122 log2 13  
fill ~102 ~0 ~2 ~105 ~0 ~2 stone_slab 0  
fill ~102 ~0 ~126 ~105 ~0 ~126 stone_slab 0  
fill ~103 ~0 ~3 ~105 ~0 ~3 wool 13  
fill ~103 ~0 ~4 ~111 ~0 ~4 stained_hardened_clay 15  
fill ~103 ~0 ~124 ~111 ~0 ~124 stained_hardened_clay 15  
fill ~103 ~0 ~125 ~105 ~0 ~125 wool 13  
fill ~105 ~0 ~1 ~109 ~0 ~1 stone_slab 0  
fill ~105 ~0 ~127 ~109 ~0 ~127 stone_slab 0  
fill ~106 ~0 ~2 ~108 ~0 ~2 stained_hardened_clay 5  
fill ~106 ~0 ~126 ~108 ~0 ~126 stained_hardened_clay 5  
fill ~109 ~0 ~2 ~112 ~0 ~2 stone_slab 0  
fill ~109 ~0 ~3 ~111 ~0 ~3 wool 13  
fill ~109 ~0 ~125 ~111 ~0 ~125 wool 13  
fill ~109 ~0 ~126 ~112 ~0 ~126 stone_slab 0  
fill ~112 ~0 ~3 ~120 ~0 ~3 stone_slab 0  
fill ~112 ~0 ~4 ~120 ~0 ~4 stained_hardened_clay 13  
fill ~112 ~0 ~5 ~120 ~0 ~5 log2 13  
fill ~112 ~0 ~123 ~120 ~0 ~123 log2 13  
fill ~112 ~0 ~124 ~120 ~0 ~124 stained_hardened_clay 13  
fill ~112 ~0 ~125 ~120 ~0 ~125 stone_slab 0  
fill ~113 ~0 ~6 ~119 ~0 ~6 log2 13  
fill ~113 ~0 ~122 ~119 ~0 ~122 log2 13  
fill ~120 ~0 ~2 ~123 ~0 ~2 stone_slab 0  
fill ~120 ~0 ~126 ~123 ~0 ~126 stone_slab 0  
fill ~121 ~0 ~3 ~123 ~0 ~3 wool 13  
fill ~121 ~0 ~4 ~124 ~0 ~4 stained_hardened_clay 15  
fill ~121 ~0 ~124 ~124 ~0 ~124 stained_hardened_clay 15  
fill ~121 ~0 ~125 ~123 ~0 ~125 wool 13  
fill ~122 ~0 ~9 ~123 ~0 ~9 log2 13  
fill ~122 ~0 ~10 ~123 ~0 ~10 log2 13  
fill ~122 ~0 ~11 ~123 ~0 ~11 log2 13  
fill ~122 ~0 ~12 ~123 ~0 ~12 log2 13  
fill ~122 ~0 ~13 ~123 ~0 ~13 log2 13  
fill ~122 ~0 ~14 ~123 ~0 ~14 log2 13  
fill ~122 ~0 ~15 ~123 ~0 ~15 log2 13  
fill ~122 ~0 ~27 ~123 ~0 ~27 log2 13  
fill ~122 ~0 ~28 ~123 ~0 ~28 log2 13  
fill ~122 ~0 ~29 ~123 ~0 ~29 log2 13  
fill ~122 ~0 ~30 ~123 ~0 ~30 log2 13  
fill ~122 ~0 ~31 ~123 ~0 ~31 log2 13  
fill ~122 ~0 ~32 ~123 ~0 ~32 log2 13  
fill ~122 ~0 ~33 ~123 ~0 ~33 log2 13  
fill ~122 ~0 ~45 ~123 ~0 ~45 log2 13  
fill ~122 ~0 ~46 ~123 ~0 ~46 log2 13  
fill ~122 ~0 ~47 ~123 ~0 ~47 log2 13  
fill ~122 ~0 ~48 ~123 ~0 ~48 log2 13  
fill ~122 ~0 ~49 ~123 ~0 ~49 log2 13  
fill ~122 ~0 ~50 ~123 ~0 ~50 log2 13  
fill ~122 ~0 ~51 ~123 ~0 ~51 log2 13  
fill ~122 ~0 ~77 ~123 ~0 ~77 log2 13  
fill ~122 ~0 ~78 ~123 ~0 ~78 log2 13  
fill ~122 ~0 ~79 ~123 ~0 ~79 log2 13  
fill ~122 ~0 ~80 ~123 ~0 ~80 log2 13  
fill ~122 ~0 ~81 ~123 ~0 ~81 log2 13  
fill ~122 ~0 ~82 ~123 ~0 ~82 log2 13  
fill ~122 ~0 ~83 ~123 ~0 ~83 log2 13  
fill ~122 ~0 ~95 ~123 ~0 ~95 log2 13  
fill ~122 ~0 ~96 ~123 ~0 ~96 log2 13  
fill ~122 ~0 ~97 ~123 ~0 ~97 log2 13  
fill ~122 ~0 ~98 ~123 ~0 ~98 log2 13  
fill ~122 ~0 ~99 ~123 ~0 ~99 log2 13  
fill ~122 ~0 ~100 ~123 ~0 ~100 log2 13  
fill ~122 ~0 ~101 ~123 ~0 ~101 log2 13  
fill ~122 ~0 ~113 ~123 ~0 ~113 log2 13  
fill ~122 ~0 ~114 ~123 ~0 ~114 log2 13  
fill ~122 ~0 ~115 ~123 ~0 ~115 log2 13  
fill ~122 ~0 ~116 ~123 ~0 ~116 log2 13  
fill ~122 ~0 ~117 ~123 ~0 ~117 log2 13  
fill ~122 ~0 ~118 ~123 ~0 ~118 log2 13  
fill ~122 ~0 ~119 ~123 ~0 ~119 log2 13  
fill ~123 ~0 ~1 ~127 ~0 ~1 stone_slab 0  
fill ~123 ~0 ~8 ~123 ~1 ~8 log2 13  
fill ~123 ~0 ~16 ~123 ~1 ~16 log2 13  
fill ~123 ~0 ~26 ~123 ~1 ~26 log2 13  
fill ~123 ~0 ~34 ~123 ~1 ~34 log2 13  
fill ~123 ~0 ~44 ~123 ~1 ~44 log2 13  
fill ~123 ~0 ~52 ~123 ~1 ~52 log2 13  
fill ~123 ~0 ~58 ~123 ~5 ~58 dirt 0  
fill ~123 ~0 ~59 ~123 ~4 ~59 dirt 0  
fill ~123 ~0 ~60 ~123 ~2 ~60 dirt 0  
fill ~123 ~0 ~61 ~123 ~1 ~61 dirt 0  
fill ~123 ~0 ~62 ~123 ~1 ~62 dirt 0  
fill ~123 ~0 ~63 ~123 ~1 ~63 dirt 0  
fill ~123 ~0 ~64 ~123 ~0 ~64 dirt 0  
fill ~123 ~0 ~65 ~123 ~1 ~65 dirt 0  
fill ~123 ~0 ~66 ~123 ~1 ~66 dirt 0  
fill ~123 ~0 ~67 ~123 ~1 ~67 dirt 0  
fill ~123 ~0 ~68 ~123 ~2 ~68 dirt 0  
fill ~123 ~0 ~69 ~123 ~4 ~69 dirt 0  
fill ~123 ~0 ~70 ~123 ~5 ~70 dirt 0  
fill ~123 ~0 ~76 ~123 ~1 ~76 log2 13  
fill ~123 ~0 ~84 ~123 ~1 ~84 log2 13  
fill ~123 ~0 ~94 ~123 ~1 ~94 log2 13  
fill ~123 ~0 ~102 ~123 ~1 ~102 log2 13  
fill ~123 ~0 ~112 ~123 ~1 ~112 log2 13  
fill ~123 ~0 ~120 ~123 ~1 ~120 log2 13  
fill ~123 ~0 ~127 ~127 ~0 ~127 stone_slab 0  
fill ~124 ~0 ~2 ~126 ~0 ~2 stained_hardened_clay 5  
fill ~124 ~0 ~5 ~124 ~1 ~5 stained_hardened_clay 15  
fill ~124 ~0 ~6 ~124 ~0 ~7 stained_hardened_clay 15  
fill ~124 ~0 ~8 ~124 ~1 ~8 stained_hardened_clay 13  
fill ~124 ~0 ~9 ~124 ~0 ~16 stained_hardened_clay 13  
fill ~124 ~0 ~17 ~124 ~0 ~25 stained_hardened_clay 15  
fill ~124 ~0 ~26 ~124 ~1 ~26 stained_hardened_clay 13  
fill ~124 ~0 ~27 ~124 ~0 ~34 stained_hardened_clay 13  
fill ~124 ~0 ~35 ~124 ~0 ~43 stained_hardened_clay 15  
fill ~124 ~0 ~44 ~124 ~1 ~44 stained_hardened_clay 13  
fill ~124 ~0 ~45 ~124 ~0 ~52 stained_hardened_clay 13  
fill ~124 ~0 ~53 ~124 ~0 ~57 stained_hardened_clay 15  
fill ~124 ~0 ~62 ~124 ~1 ~62 stained_hardened_clay 13  
fill ~124 ~0 ~63 ~124 ~1 ~63 stained_hardened_clay 13  
fill ~124 ~0 ~64 ~124 ~0 ~66 stained_hardened_clay 13  
fill ~124 ~0 ~71 ~124 ~6 ~71 stained_hardened_clay 15  
fill ~124 ~0 ~72 ~124 ~3 ~72 stained_hardened_clay 15  
fill ~124 ~0 ~73 ~124 ~1 ~73 stained_hardened_clay 15  
fill ~124 ~0 ~74 ~124 ~0 ~75 stained_hardened_clay 15  
fill ~124 ~0 ~76 ~124 ~1 ~76 stained_hardened_clay 13  
fill ~124 ~0 ~77 ~124 ~0 ~84 stained_hardened_clay 13  
fill ~124 ~0 ~85 ~124 ~0 ~93 stained_hardened_clay 15  
fill ~124 ~0 ~94 ~124 ~1 ~94 stained_hardened_clay 13  
fill ~124 ~0 ~95 ~124 ~0 ~102 stained_hardened_clay 13  
fill ~124 ~0 ~103 ~124 ~0 ~111 stained_hardened_clay 15  
fill ~124 ~0 ~112 ~124 ~1 ~112 stained_hardened_clay 13  
fill ~124 ~0 ~113 ~124 ~0 ~120 stained_hardened_clay 13  
fill ~124 ~0 ~121 ~124 ~0 ~124 stained_hardened_clay 15  
fill ~124 ~0 ~126 ~126 ~0 ~126 stained_hardened_clay 5  
fill ~125 ~0 ~5 ~125 ~1 ~5 wool 13  
fill ~125 ~0 ~6 ~125 ~0 ~7 wool 13  
fill ~125 ~0 ~8 ~126 ~0 ~8 stone_slab 0  
fill ~125 ~0 ~9 ~125 ~0 ~16 stone_slab 0  
fill ~125 ~0 ~17 ~125 ~0 ~19 wool 13  
fill ~125 ~0 ~23 ~125 ~1 ~23 wool 13  
fill ~125 ~0 ~24 ~125 ~0 ~25 wool 13  
fill ~125 ~0 ~26 ~126 ~0 ~26 stone_slab 0  
fill ~125 ~0 ~27 ~125 ~0 ~34 stone_slab 0  
fill ~125 ~0 ~35 ~125 ~0 ~37 wool 13  
fill ~125 ~0 ~41 ~125 ~1 ~41 wool 13  
fill ~125 ~0 ~42 ~125 ~0 ~43 wool 13  
fill ~125 ~0 ~44 ~126 ~0 ~44 stone_slab 0  
fill ~125 ~0 ~45 ~125 ~0 ~52 stone_slab 0  
fill ~125 ~0 ~53 ~125 ~0 ~55 wool 13  
fill ~125 ~0 ~59 ~125 ~1 ~59 wool 13  
fill ~125 ~0 ~60 ~125 ~0 ~62 wool 13  
fill ~125 ~0 ~63 ~126 ~0 ~63 stone_slab 0  
fill ~125 ~0 ~64 ~125 ~0 ~65 stone_slab 0  
fill ~125 ~0 ~66 ~125 ~0 ~69 wool 13  
fill ~125 ~0 ~73 ~125 ~1 ~73 wool 13  
fill ~125 ~0 ~74 ~125 ~0 ~75 wool 13  
fill ~125 ~0 ~76 ~126 ~0 ~76 stone_slab 0  
fill ~125 ~0 ~77 ~125 ~0 ~84 stone_slab 0  
fill ~125 ~0 ~85 ~125 ~0 ~87 wool 13  
fill ~125 ~0 ~91 ~125 ~1 ~91 wool 13  
fill ~125 ~0 ~92 ~125 ~0 ~93 wool 13  
fill ~125 ~0 ~94 ~126 ~0 ~94 stone_slab 0  
fill ~125 ~0 ~95 ~125 ~0 ~102 stone_slab 0  
fill ~125 ~0 ~103 ~125 ~0 ~105 wool 13  
fill ~125 ~0 ~109 ~125 ~1 ~109 wool 13  
fill ~125 ~0 ~110 ~125 ~0 ~111 wool 13  
fill ~125 ~0 ~112 ~126 ~0 ~112 stone_slab 0  
fill ~125 ~0 ~113 ~125 ~0 ~120 stone_slab 0  
fill ~125 ~0 ~121 ~125 ~0 ~123 wool 13  
fill ~126 ~0 ~3 ~126 ~2 ~3 stained_hardened_clay 5  
fill ~126 ~0 ~4 ~126 ~0 ~2 stained_hardened_clay 5  
fill ~126 ~0 ~5 ~127 ~0 ~5 stone_slab 0  
fill ~126 ~0 ~6 ~126 ~0 ~8 stone_slab 0  
fill ~126 ~0 ~16 ~126 ~0 ~19 stone_slab 0  
fill ~126 ~0 ~20 ~126 ~0 ~22 stained_hardened_clay 5  
fill ~126 ~0 ~23 ~127 ~0 ~23 stone_slab 0  
fill ~126 ~0 ~24 ~126 ~0 ~26 stone_slab 0  
fill ~126 ~0 ~34 ~126 ~0 ~37 stone_slab 0  
fill ~126 ~0 ~38 ~126 ~0 ~40 stained_hardened_clay 5  
fill ~126 ~0 ~41 ~127 ~0 ~41 stone_slab 0  
fill ~126 ~0 ~42 ~126 ~0 ~44 stone_slab 0  
fill ~126 ~0 ~52 ~126 ~0 ~55 stone_slab 0  
fill ~126 ~0 ~56 ~126 ~0 ~58 stained_hardened_clay 5  
fill ~126 ~0 ~59 ~127 ~0 ~59 stone_slab 0  
fill ~126 ~0 ~60 ~126 ~0 ~63 stone_slab 0  
fill ~126 ~0 ~65 ~126 ~0 ~69 stone_slab 0  
fill ~126 ~0 ~70 ~126 ~0 ~72 stained_hardened_clay 5  
fill ~126 ~0 ~73 ~127 ~0 ~73 stone_slab 0  
fill ~126 ~0 ~74 ~126 ~0 ~76 stone_slab 0  
fill ~126 ~0 ~84 ~126 ~0 ~87 stone_slab 0  
fill ~126 ~0 ~88 ~126 ~0 ~90 stained_hardened_clay 5  
fill ~126 ~0 ~91 ~127 ~0 ~91 stone_slab 0  
fill ~126 ~0 ~92 ~126 ~0 ~94 stone_slab 0  
fill ~126 ~0 ~102 ~126 ~0 ~105 stone_slab 0  
fill ~126 ~0 ~106 ~126 ~0 ~108 stained_hardened_clay 5  
fill ~126 ~0 ~109 ~127 ~0 ~109 stone_slab 0  
fill ~126 ~0 ~110 ~126 ~0 ~112 stone_slab 0  
fill ~126 ~0 ~120 ~126 ~0 ~123 stone_slab 0  
fill ~126 ~0 ~124 ~126 ~0 ~126 stained_hardened_clay 5  
fill ~127 ~0 ~2 ~127 ~0 ~5 stone_slab 0  
fill ~127 ~0 ~19 ~127 ~0 ~23 stone_slab 0  
fill ~127 ~0 ~37 ~127 ~0 ~41 stone_slab 0  
fill ~127 ~0 ~55 ~127 ~0 ~59 stone_slab 0  
fill ~127 ~0 ~69 ~127 ~0 ~73 stone_slab 0  
fill ~127 ~0 ~87 ~127 ~0 ~91 stone_slab 0  
fill ~127 ~0 ~105 ~127 ~0 ~109 stone_slab 0  
fill ~127 ~0 ~123 ~127 ~0 ~127 stone_slab 0  
fill ~2 ~1 ~2 ~3 ~1 ~2 stained_hardened_clay 5  
fill ~2 ~1 ~21 ~2 ~2 ~21 stained_hardened_clay 5  
fill ~2 ~1 ~39 ~2 ~2 ~39 stained_hardened_clay 5  
fill ~2 ~1 ~57 ~2 ~2 ~57 stained_hardened_clay 5  
fill ~2 ~1 ~71 ~2 ~2 ~71 stained_hardened_clay 5  
fill ~2 ~1 ~89 ~2 ~2 ~89 stained_hardened_clay 5  
fill ~2 ~1 ~107 ~2 ~2 ~107 stained_hardened_clay 5  
fill ~2 ~1 ~125 ~3 ~1 ~125 stained_hardened_clay 5  
fill ~2 ~1 ~126 ~3 ~1 ~126 stained_hardened_clay 5  
fill ~3 ~1 ~3 ~3 ~2 ~3 stained_hardened_clay 5  
fill ~3 ~1 ~4 ~3 ~3 ~4 wool 13 
setblock ~3 ~1 ~7 log2 13  
fill ~3 ~1 ~19 ~3 ~1 ~20 wool 13  
fill ~3 ~1 ~22 ~3 ~3 ~22 wool 13 
setblock ~3 ~1 ~25 log2 13  
fill ~3 ~1 ~37 ~3 ~1 ~38 wool 13  
fill ~3 ~1 ~40 ~3 ~3 ~40 wool 13 
setblock ~3 ~1 ~43 log2 13  
fill ~3 ~1 ~55 ~3 ~1 ~56 wool 13  
fill ~3 ~1 ~58 ~3 ~3 ~58 wool 13  
fill ~3 ~1 ~69 ~3 ~1 ~70 wool 13  
fill ~3 ~1 ~72 ~3 ~3 ~72 wool 13 
setblock ~3 ~1 ~85 log2 13  
fill ~3 ~1 ~87 ~3 ~1 ~88 wool 13  
fill ~3 ~1 ~90 ~3 ~3 ~90 wool 13 
setblock ~3 ~1 ~103 log2 13  
fill ~3 ~1 ~105 ~3 ~1 ~106 wool 13  
fill ~3 ~1 ~108 ~3 ~3 ~108 wool 13 
setblock ~3 ~1 ~121 log2 13  
fill ~3 ~1 ~123 ~3 ~1 ~124 wool 13  
fill ~4 ~1 ~3 ~5 ~1 ~3 wool 13  
fill ~4 ~1 ~4 ~5 ~1 ~4 stained_hardened_clay 15  
fill ~4 ~1 ~6 ~4 ~2 ~6 stained_hardened_clay 13  
fill ~4 ~1 ~7 ~4 ~1 ~6 stained_hardened_clay 13  
fill ~4 ~1 ~14 ~4 ~1 ~15 log2 13  
fill ~4 ~1 ~16 ~4 ~1 ~18 stained_hardened_clay 13  
fill ~4 ~1 ~19 ~4 ~1 ~23 stained_hardened_clay 15  
fill ~4 ~1 ~24 ~4 ~2 ~24 stained_hardened_clay 13  
fill ~4 ~1 ~25 ~4 ~1 ~24 stained_hardened_clay 13  
fill ~4 ~1 ~32 ~4 ~1 ~33 log2 13  
fill ~4 ~1 ~34 ~4 ~1 ~36 stained_hardened_clay 13  
fill ~4 ~1 ~37 ~4 ~1 ~41 stained_hardened_clay 15  
fill ~4 ~1 ~42 ~4 ~2 ~42 stained_hardened_clay 13  
fill ~4 ~1 ~43 ~4 ~1 ~42 stained_hardened_clay 13  
fill ~4 ~1 ~50 ~4 ~1 ~51 log2 13  
fill ~4 ~1 ~52 ~4 ~1 ~54 stained_hardened_clay 13  
fill ~4 ~1 ~55 ~4 ~1 ~57 stained_hardened_clay 15  
fill ~4 ~1 ~60 ~4 ~2 ~60 stained_hardened_clay 13  
fill ~4 ~1 ~61 ~4 ~1 ~60 stained_hardened_clay 13  
fill ~4 ~1 ~65 ~4 ~1 ~68 stained_hardened_clay 13  
fill ~4 ~1 ~74 ~4 ~2 ~74 stained_hardened_clay 13  
fill ~4 ~1 ~75 ~4 ~1 ~74 stained_hardened_clay 13  
fill ~4 ~1 ~77 ~4 ~1 ~78 log2 13  
fill ~4 ~1 ~84 ~4 ~1 ~86 stained_hardened_clay 13  
fill ~4 ~1 ~87 ~4 ~1 ~91 stained_hardened_clay 15  
fill ~4 ~1 ~92 ~4 ~2 ~92 stained_hardened_clay 13  
fill ~4 ~1 ~93 ~4 ~1 ~92 stained_hardened_clay 13  
fill ~4 ~1 ~95 ~4 ~1 ~96 log2 13  
fill ~4 ~1 ~102 ~4 ~1 ~104 stained_hardened_clay 13  
fill ~4 ~1 ~105 ~4 ~1 ~109 stained_hardened_clay 15  
fill ~4 ~1 ~110 ~4 ~2 ~110 stained_hardened_clay 13  
fill ~4 ~1 ~111 ~4 ~1 ~110 stained_hardened_clay 13  
fill ~4 ~1 ~113 ~4 ~1 ~114 log2 13  
fill ~4 ~1 ~120 ~4 ~1 ~122 stained_hardened_clay 13  
fill ~4 ~1 ~123 ~4 ~1 ~124 stained_hardened_clay 15  
fill ~4 ~1 ~125 ~5 ~1 ~125 wool 13  
fill ~5 ~1 ~9 ~5 ~2 ~9 stained_hardened_clay 15  
fill ~5 ~1 ~10 ~5 ~1 ~11 stained_hardened_clay 15  
fill ~5 ~1 ~13 ~5 ~1 ~15 stained_hardened_clay 15  
fill ~5 ~1 ~27 ~5 ~2 ~27 stained_hardened_clay 15  
fill ~5 ~1 ~28 ~5 ~1 ~29 stained_hardened_clay 15  
fill ~5 ~1 ~31 ~5 ~1 ~33 stained_hardened_clay 15  
fill ~5 ~1 ~45 ~5 ~2 ~45 stained_hardened_clay 15  
fill ~5 ~1 ~46 ~5 ~1 ~47 stained_hardened_clay 15  
fill ~5 ~1 ~49 ~5 ~1 ~51 stained_hardened_clay 15  
fill ~5 ~1 ~64 ~5 ~5 ~64 stained_hardened_clay 15  
fill ~5 ~1 ~77 ~5 ~2 ~77 stained_hardened_clay 15  
fill ~5 ~1 ~78 ~5 ~1 ~79 stained_hardened_clay 15  
fill ~5 ~1 ~81 ~5 ~1 ~83 stained_hardened_clay 15  
fill ~5 ~1 ~95 ~5 ~2 ~95 stained_hardened_clay 15  
fill ~5 ~1 ~96 ~5 ~1 ~97 stained_hardened_clay 15  
fill ~5 ~1 ~99 ~5 ~1 ~101 stained_hardened_clay 15  
fill ~5 ~1 ~113 ~5 ~2 ~113 stained_hardened_clay 15  
fill ~5 ~1 ~114 ~5 ~1 ~115 stained_hardened_clay 15  
fill ~5 ~1 ~117 ~5 ~1 ~119 stained_hardened_clay 15  
fill ~5 ~1 ~124 ~5 ~0 ~124 stained_hardened_clay 15  
fill ~6 ~1 ~4 ~8 ~1 ~4 stained_hardened_clay 13  
fill ~6 ~1 ~9 ~6 ~5 ~9 log2 13  
fill ~6 ~1 ~10 ~6 ~5 ~10 log2 13  
fill ~6 ~1 ~11 ~6 ~5 ~11 log2 13  
fill ~6 ~1 ~12 ~6 ~5 ~12 log2 13  
fill ~6 ~1 ~13 ~6 ~5 ~13 log2 13  
fill ~6 ~1 ~14 ~6 ~5 ~14 log2 13  
fill ~6 ~1 ~15 ~6 ~5 ~15 log2 13  
fill ~6 ~1 ~27 ~6 ~5 ~27 log2 13  
fill ~6 ~1 ~28 ~6 ~5 ~28 log2 13  
fill ~6 ~1 ~29 ~6 ~5 ~29 log2 13  
fill ~6 ~1 ~30 ~6 ~5 ~30 log2 13  
fill ~6 ~1 ~31 ~6 ~5 ~31 log2 13  
fill ~6 ~1 ~32 ~6 ~5 ~32 log2 13  
fill ~6 ~1 ~33 ~6 ~5 ~33 log2 13  
fill ~6 ~1 ~45 ~6 ~5 ~45 log2 13  
fill ~6 ~1 ~46 ~6 ~5 ~46 log2 13  
fill ~6 ~1 ~47 ~6 ~5 ~47 log2 13  
fill ~6 ~1 ~48 ~6 ~5 ~48 log2 13  
fill ~6 ~1 ~49 ~6 ~5 ~49 log2 13  
fill ~6 ~1 ~50 ~6 ~5 ~50 log2 13  
fill ~6 ~1 ~51 ~6 ~5 ~51 log2 13  
fill ~6 ~1 ~77 ~6 ~5 ~77 log2 13  
fill ~6 ~1 ~78 ~6 ~5 ~78 log2 13  
fill ~6 ~1 ~79 ~6 ~5 ~79 log2 13  
fill ~6 ~1 ~80 ~6 ~5 ~80 log2 13  
fill ~6 ~1 ~81 ~6 ~5 ~81 log2 13  
fill ~6 ~1 ~82 ~6 ~5 ~82 log2 13  
fill ~6 ~1 ~83 ~6 ~5 ~83 log2 13  
fill ~6 ~1 ~95 ~6 ~5 ~95 log2 13  
fill ~6 ~1 ~96 ~6 ~5 ~96 log2 13  
fill ~6 ~1 ~97 ~6 ~5 ~97 log2 13  
fill ~6 ~1 ~98 ~6 ~5 ~98 log2 13  
fill ~6 ~1 ~99 ~6 ~5 ~99 log2 13  
fill ~6 ~1 ~100 ~6 ~5 ~100 log2 13  
fill ~6 ~1 ~101 ~6 ~5 ~101 log2 13  
fill ~6 ~1 ~113 ~6 ~5 ~113 log2 13  
fill ~6 ~1 ~114 ~6 ~5 ~114 log2 13  
fill ~6 ~1 ~115 ~6 ~5 ~115 log2 13  
fill ~6 ~1 ~116 ~6 ~5 ~116 log2 13  
fill ~6 ~1 ~117 ~6 ~5 ~117 log2 13  
fill ~6 ~1 ~118 ~6 ~5 ~118 log2 13  
fill ~6 ~1 ~119 ~6 ~5 ~119 log2 13  
fill ~6 ~1 ~124 ~8 ~1 ~124 stained_hardened_clay 13 
setblock ~7 ~1 ~3 log2 13 
setblock ~7 ~1 ~125 log2 13  
fill ~8 ~1 ~5 ~8 ~0 ~5 log2 13  
fill ~8 ~1 ~123 ~8 ~0 ~123 log2 13  
fill ~9 ~1 ~5 ~11 ~1 ~5 stained_hardened_clay 15  
fill ~9 ~1 ~6 ~15 ~1 ~6 log2 13  
fill ~9 ~1 ~122 ~15 ~1 ~122 log2 13  
fill ~9 ~1 ~123 ~11 ~1 ~123 stained_hardened_clay 15  
fill ~13 ~1 ~5 ~15 ~1 ~5 stained_hardened_clay 15  
fill ~13 ~1 ~123 ~15 ~1 ~123 stained_hardened_clay 15  
fill ~14 ~1 ~4 ~15 ~1 ~4 log2 13  
fill ~14 ~1 ~124 ~15 ~1 ~124 log2 13  
fill ~16 ~1 ~4 ~18 ~1 ~4 stained_hardened_clay 13 
setblock ~16 ~1 ~5 log2 13 
setblock ~16 ~1 ~123 log2 13  
fill ~16 ~1 ~124 ~18 ~1 ~124 stained_hardened_clay 13  
fill ~19 ~1 ~3 ~20 ~1 ~3 wool 13  
fill ~19 ~1 ~4 ~23 ~1 ~4 stained_hardened_clay 15  
fill ~19 ~1 ~124 ~23 ~1 ~124 stained_hardened_clay 15  
fill ~19 ~1 ~125 ~20 ~1 ~125 wool 13  
fill ~21 ~1 ~2 ~21 ~2 ~2 stained_hardened_clay 5  
fill ~21 ~1 ~126 ~21 ~2 ~126 stained_hardened_clay 5  
fill ~22 ~1 ~3 ~23 ~1 ~3 wool 13  
fill ~22 ~1 ~125 ~23 ~1 ~125 wool 13  
fill ~24 ~1 ~4 ~26 ~1 ~4 stained_hardened_clay 13  
fill ~24 ~1 ~124 ~26 ~1 ~124 stained_hardened_clay 13 
setblock ~25 ~1 ~3 log2 13 
setblock ~25 ~1 ~125 log2 13  
fill ~26 ~1 ~5 ~26 ~0 ~5 log2 13  
fill ~26 ~1 ~123 ~26 ~0 ~123 log2 13  
fill ~27 ~1 ~5 ~29 ~1 ~5 stained_hardened_clay 15  
fill ~27 ~1 ~6 ~33 ~1 ~6 log2 13  
fill ~27 ~1 ~122 ~33 ~1 ~122 log2 13  
fill ~27 ~1 ~123 ~29 ~1 ~123 stained_hardened_clay 15  
fill ~31 ~1 ~5 ~33 ~1 ~5 stained_hardened_clay 15  
fill ~31 ~1 ~123 ~33 ~1 ~123 stained_hardened_clay 15  
fill ~32 ~1 ~4 ~33 ~1 ~4 log2 13  
fill ~32 ~1 ~124 ~33 ~1 ~124 log2 13  
fill ~34 ~1 ~4 ~36 ~1 ~4 stained_hardened_clay 13 
setblock ~34 ~1 ~5 log2 13 
setblock ~34 ~1 ~123 log2 13  
fill ~34 ~1 ~124 ~36 ~1 ~124 stained_hardened_clay 13  
fill ~37 ~1 ~3 ~38 ~1 ~3 wool 13  
fill ~37 ~1 ~4 ~41 ~1 ~4 stained_hardened_clay 15  
fill ~37 ~1 ~124 ~41 ~1 ~124 stained_hardened_clay 15  
fill ~37 ~1 ~125 ~38 ~1 ~125 wool 13  
fill ~39 ~1 ~2 ~39 ~2 ~2 stained_hardened_clay 5  
fill ~39 ~1 ~126 ~39 ~2 ~126 stained_hardened_clay 5  
fill ~40 ~1 ~3 ~41 ~1 ~3 wool 13  
fill ~40 ~1 ~125 ~41 ~1 ~125 wool 13  
fill ~42 ~1 ~4 ~44 ~1 ~4 stained_hardened_clay 13  
fill ~42 ~1 ~124 ~44 ~1 ~124 stained_hardened_clay 13 
setblock ~43 ~1 ~3 log2 13 
setblock ~43 ~1 ~125 log2 13  
fill ~44 ~1 ~5 ~44 ~0 ~5 log2 13  
fill ~44 ~1 ~123 ~44 ~0 ~123 log2 13  
fill ~45 ~1 ~5 ~47 ~1 ~5 stained_hardened_clay 15  
fill ~45 ~1 ~6 ~51 ~1 ~6 log2 13  
fill ~45 ~1 ~122 ~51 ~1 ~122 log2 13  
fill ~45 ~1 ~123 ~47 ~1 ~123 stained_hardened_clay 15  
fill ~49 ~1 ~5 ~51 ~1 ~5 stained_hardened_clay 15  
fill ~49 ~1 ~123 ~51 ~1 ~123 stained_hardened_clay 15  
fill ~50 ~1 ~4 ~51 ~1 ~4 log2 13  
fill ~50 ~1 ~124 ~51 ~1 ~124 log2 13  
fill ~52 ~1 ~4 ~54 ~1 ~4 stained_hardened_clay 13 
setblock ~52 ~1 ~5 log2 13 
setblock ~52 ~1 ~123 log2 13  
fill ~52 ~1 ~124 ~54 ~1 ~124 stained_hardened_clay 13  
fill ~55 ~1 ~3 ~56 ~1 ~3 wool 13  
fill ~55 ~1 ~4 ~57 ~1 ~4 stained_hardened_clay 15  
fill ~55 ~1 ~124 ~57 ~1 ~124 stained_hardened_clay 15  
fill ~55 ~1 ~125 ~56 ~1 ~125 wool 13  
fill ~57 ~1 ~2 ~57 ~2 ~2 stained_hardened_clay 5  
fill ~57 ~1 ~126 ~57 ~2 ~126 stained_hardened_clay 5  
fill ~58 ~1 ~3 ~59 ~1 ~3 wool 13  
fill ~58 ~1 ~5 ~63 ~1 ~5 dirt 0  
fill ~58 ~1 ~123 ~63 ~1 ~123 dirt 0  
fill ~58 ~1 ~125 ~59 ~1 ~125 wool 13  
fill ~60 ~1 ~4 ~63 ~1 ~4 stained_hardened_clay 13  
fill ~60 ~1 ~124 ~63 ~1 ~124 stained_hardened_clay 13  
fill ~64 ~1 ~5 ~64 ~5 ~5 stained_hardened_clay 15  
fill ~64 ~1 ~123 ~64 ~5 ~123 stained_hardened_clay 15  
fill ~65 ~1 ~4 ~68 ~1 ~4 stained_hardened_clay 13  
fill ~65 ~1 ~5 ~70 ~1 ~5 dirt 0  
fill ~65 ~1 ~123 ~70 ~1 ~123 dirt 0  
fill ~65 ~1 ~124 ~68 ~1 ~124 stained_hardened_clay 13  
fill ~69 ~1 ~3 ~70 ~1 ~3 wool 13  
fill ~69 ~1 ~125 ~70 ~1 ~125 wool 13  
fill ~71 ~1 ~2 ~71 ~2 ~2 stained_hardened_clay 5  
fill ~71 ~1 ~4 ~73 ~1 ~4 stained_hardened_clay 15  
fill ~71 ~1 ~124 ~73 ~1 ~124 stained_hardened_clay 15  
fill ~71 ~1 ~126 ~71 ~2 ~126 stained_hardened_clay 5  
fill ~72 ~1 ~3 ~73 ~1 ~3 wool 13  
fill ~72 ~1 ~125 ~73 ~1 ~125 wool 13  
fill ~74 ~1 ~4 ~76 ~1 ~4 stained_hardened_clay 13  
fill ~74 ~1 ~124 ~76 ~1 ~124 stained_hardened_clay 13  
fill ~76 ~1 ~5 ~76 ~0 ~5 log2 13  
fill ~76 ~1 ~123 ~76 ~0 ~123 log2 13  
fill ~77 ~1 ~4 ~78 ~1 ~4 log2 13  
fill ~77 ~1 ~5 ~79 ~1 ~5 stained_hardened_clay 15  
fill ~77 ~1 ~6 ~83 ~1 ~6 log2 13  
fill ~77 ~1 ~122 ~83 ~1 ~122 log2 13  
fill ~77 ~1 ~123 ~79 ~1 ~123 stained_hardened_clay 15  
fill ~77 ~1 ~124 ~78 ~1 ~124 log2 13  
fill ~81 ~1 ~5 ~83 ~1 ~5 stained_hardened_clay 15  
fill ~81 ~1 ~123 ~83 ~1 ~123 stained_hardened_clay 15  
fill ~84 ~1 ~4 ~86 ~1 ~4 stained_hardened_clay 13 
setblock ~84 ~1 ~5 log2 13 
setblock ~84 ~1 ~123 log2 13  
fill ~84 ~1 ~124 ~86 ~1 ~124 stained_hardened_clay 13 
setblock ~85 ~1 ~3 log2 13 
setblock ~85 ~1 ~125 log2 13  
fill ~87 ~1 ~3 ~88 ~1 ~3 wool 13  
fill ~87 ~1 ~4 ~91 ~1 ~4 stained_hardened_clay 15  
fill ~87 ~1 ~124 ~91 ~1 ~124 stained_hardened_clay 15  
fill ~87 ~1 ~125 ~88 ~1 ~125 wool 13  
fill ~89 ~1 ~2 ~89 ~2 ~2 stained_hardened_clay 5  
fill ~89 ~1 ~126 ~89 ~2 ~126 stained_hardened_clay 5  
fill ~90 ~1 ~3 ~91 ~1 ~3 wool 13  
summon Zombie ~18.5 ~0.0 ~12.5 
summon Zombie ~15.5 ~0.0 ~13.5 
summon Zombie ~19.4081864835 ~0.0 ~25.0828602863 
summon Zombie ~11.9015676433 ~0.0 ~14.7021725818 
summon Skeleton ~19.5 ~0.0 ~50.5 
summon Skeleton ~18.5 ~0.0 ~48.5 
summon Spider ~5.69999998808 ~0.0 ~74.5123420079 
summon Skeleton ~10.7283342278 ~0.0 ~78.1770324291 
summon Skeleton ~15.5 ~0.0 ~78.5 
summon Spider ~10.5 ~0.0 ~84.5 
summon Skeleton ~18.7047793887 ~0.0 ~108.797420796 
summon Spider ~6.69999998808 ~4.10000002384 ~103.871995579 
summon Bat ~13.9913169995 ~0.141992345115 ~102.651511501 
summon Creeper ~11.5 ~0.0 ~94.5 
summon Spider ~11.5 ~0.0 ~96.5 
summon Creeper ~12.5 ~0.0 ~94.5 
summon Spider ~17.5 ~7.0 ~96.9023442737 
summon Zombie ~19.5 ~30.0 ~97.5 
summon Bat ~12.5872084625 ~0.826594368975 ~121.75 
summon Bat ~16.4217910804 ~2.03335455102 ~121.75 
summon Bat ~18.1937400643 ~2.31204345042 ~121.545534122 
summon Bat ~15.0691393237 ~3.32274274039 ~111.147681376 
summon Bat ~12.75 ~4.52593352999 ~124.75 
summon Creeper ~14.5 ~0.0 ~112.5 
summon Zombie ~11.5 ~0.0 ~118.5 
summon Bat ~11.3381843646 ~4.10000002384 ~119.531896763 
summon Bat ~9.83226629533 ~0.767842751297 ~121.416650637 
summon Zombie ~7.5 ~0.0 ~119.5 
summon Creeper ~6.5 ~0.0 ~120.5 
summon Creeper ~5.5 ~0.0 ~123.5 
summon Creeper ~12.5 ~0.0 ~116.5 
summon Spider ~19.5958089732 ~0.0 ~116.348708843 
summon Creeper ~10.5 ~0.0 ~113.5 
summon Skeleton ~23.5 ~0.0 ~53.5 
summon Skeleton ~24.5 ~0.0 ~50.5 
summon Creeper ~31.3324643863 ~0.0 ~93.8984320847 
summon Zombie ~34.4693814769 ~0.0 ~109.747688017 
summon Creeper ~28.28891468 ~0.0 ~98.0229237039 
summon Zombie ~22.738933953 ~0.0 ~102.828409028 
summon Skeleton ~35.8909363218 ~0.0 ~108.684320285 
summon Zombie ~35.5 ~23.0 ~107.5 
summon Creeper ~33.5 ~23.0 ~107.5 
summon Zombie ~28.5 ~30.0 ~101.5 
summon Zombie ~26.5 ~30.0 ~99.5 
summon Zombie ~25.5 ~30.0 ~101.5 
summon Skeleton ~27.7424145671 ~0.0 ~121.699999988 
summon Zombie ~30.5 ~0.0 ~111.5 
summon Spider ~23.2887897083 ~0.0 ~117.698700865 
summon Spider ~25.8353361643 ~0.0 ~114.782950608 
summon Spider ~30.2922816644 ~0.0 ~114.712963182 
summon Bat ~23.4400544889 ~4.10000002384 ~123.75 
summon Spider ~21.6473883696 ~0.0 ~117.713327035 
summon Creeper ~25.6089067236 ~0.0 ~123.026819783 
summon Bat ~25.75 ~1.03000002399 ~123.75 
summon Bat ~24.4424358377 ~2.10000002384 ~123.75 
summon Bat ~23.4495274056 ~2.07983191007 ~123.75 
summon Bat ~22.9290883519 ~0.878214368881 ~116.540330385 
summon Bat ~25.7038774409 ~1.02401707034 ~113.950562189 
summon Zombie ~30.5 ~4.0 ~124.5 
summon Creeper ~42.5 ~32.0 ~51.5 
summon Skeleton ~41.5 ~0.0 ~104.5 
summon Creeper ~40.1578553078 ~0.0 ~106.780133421 
summon Skeleton ~43.0034871768 ~0.0 ~108.373864331 
summon Skeleton ~43.5 ~0.0 ~100.5 
summon Spider ~43.019396819 ~30.0 ~99.2105523284 
summon Skeleton ~49.0592178181 ~0.0 ~118.863279974 
summon Skeleton ~48.7105335639 ~0.0 ~114.775818966 
summon Zombie ~36.5 ~7.0 ~111.5 
summon Zombie ~36.3388866676 ~0.0 ~121.08499412 
summon Zombie ~38.5 ~7.0 ~110.5 
summon Bat ~44.8722679137 ~2.99084973666 ~121.025395916 
summon Skeleton ~46.9358984749 ~0.0 ~117.558772063 
summon Skeleton ~47.2300443292 ~0.0 ~121.23535372 
summon Skeleton ~54.5 ~0.0 ~117.5 
summon Skeleton ~57.1682184449 ~0.0 ~123.257496476 
summon Skeleton ~59.3617307532 ~0.0 ~115.869950439 
summon Skeleton ~54.1225286216 ~0.0 ~119.719213397 
summon Bat ~57.9952015548 ~2.32935497144 ~121.336196831 
summon Bat ~58.875446947 ~1.00286543741 ~121.598862646 
summon Creeper ~77.5 ~0.0 ~8.5 
summon Creeper ~75.5 ~0.0 ~8.5 
summon Creeper ~80.6117543678 ~0.0 ~14.0691160475 
summon Spider ~79.3000000119 ~8.10000002384 ~90.6999999881 
summon Zombie ~80.5164816917 ~32.0 ~101.968231578 
summon Zombie ~79.6762156871 ~32.0 ~106.88527537 
summon Zombie ~79.9768173074 ~32.0 ~108.536477346 
summon Skeleton ~85.5 ~0.0 ~6.5 
summon Zombie ~90.349999994 ~7.0 ~110.349999994 
summon Zombie ~107.277907861 ~18.0 ~95.134432112  
fill ~90 ~1 ~125 ~91 ~1 ~125 wool 13  
fill ~92 ~1 ~4 ~94 ~1 ~4 stained_hardened_clay 13  
fill ~92 ~1 ~124 ~94 ~1 ~124 stained_hardened_clay 13  
fill ~94 ~1 ~5 ~94 ~0 ~5 log2 13  
fill ~94 ~1 ~123 ~94 ~0 ~123 log2 13  
fill ~95 ~1 ~4 ~96 ~1 ~4 log2 13  
fill ~95 ~1 ~5 ~97 ~1 ~5 stained_hardened_clay 15  
fill ~95 ~1 ~6 ~101 ~1 ~6 log2 13  
fill ~95 ~1 ~122 ~101 ~1 ~122 log2 13  
fill ~95 ~1 ~123 ~97 ~1 ~123 stained_hardened_clay 15  
fill ~95 ~1 ~124 ~96 ~1 ~124 log2 13  
fill ~99 ~1 ~5 ~101 ~1 ~5 stained_hardened_clay 15  
fill ~99 ~1 ~123 ~101 ~1 ~123 stained_hardened_clay 15  
fill ~102 ~1 ~4 ~104 ~1 ~4 stained_hardened_clay 13 
setblock ~102 ~1 ~5 log2 13 
setblock ~102 ~1 ~123 log2 13  
fill ~102 ~1 ~124 ~104 ~1 ~124 stained_hardened_clay 13 
setblock ~103 ~1 ~3 log2 13 
setblock ~103 ~1 ~125 log2 13  
fill ~105 ~1 ~3 ~106 ~1 ~3 wool 13  
fill ~105 ~1 ~4 ~109 ~1 ~4 stained_hardened_clay 15  
fill ~105 ~1 ~124 ~109 ~1 ~124 stained_hardened_clay 15  
fill ~105 ~1 ~125 ~106 ~1 ~125 wool 13  
fill ~107 ~1 ~2 ~107 ~2 ~2 stained_hardened_clay 5  
fill ~107 ~1 ~126 ~107 ~2 ~126 stained_hardened_clay 5  
fill ~108 ~1 ~3 ~109 ~1 ~3 wool 13  
fill ~108 ~1 ~125 ~109 ~1 ~125 wool 13  
fill ~110 ~1 ~4 ~112 ~1 ~4 stained_hardened_clay 13  
fill ~110 ~1 ~124 ~112 ~1 ~124 stained_hardened_clay 13  
fill ~112 ~1 ~5 ~112 ~0 ~5 log2 13  
fill ~112 ~1 ~123 ~112 ~0 ~123 log2 13  
fill ~113 ~1 ~4 ~114 ~1 ~4 log2 13  
fill ~113 ~1 ~5 ~115 ~1 ~5 stained_hardened_clay 15  
fill ~113 ~1 ~6 ~119 ~1 ~6 log2 13  
fill ~113 ~1 ~122 ~119 ~1 ~122 log2 13  
fill ~113 ~1 ~123 ~115 ~1 ~123 stained_hardened_clay 15  
fill ~113 ~1 ~124 ~114 ~1 ~124 log2 13  
fill ~117 ~1 ~5 ~119 ~1 ~5 stained_hardened_clay 15  
fill ~117 ~1 ~123 ~119 ~1 ~123 stained_hardened_clay 15  
fill ~120 ~1 ~4 ~122 ~1 ~4 stained_hardened_clay 13 
setblock ~120 ~1 ~5 log2 13 
setblock ~120 ~1 ~123 log2 13  
fill ~120 ~1 ~124 ~122 ~1 ~124 stained_hardened_clay 13 
setblock ~121 ~1 ~3 log2 13 
setblock ~121 ~1 ~125 log2 13  
fill ~122 ~1 ~9 ~122 ~5 ~9 log2 13  
fill ~122 ~1 ~10 ~122 ~5 ~10 log2 13  
fill ~122 ~1 ~11 ~122 ~5 ~11 log2 13  
fill ~122 ~1 ~12 ~122 ~5 ~12 log2 13  
fill ~122 ~1 ~13 ~122 ~5 ~13 log2 13  
fill ~122 ~1 ~14 ~122 ~5 ~14 log2 13  
fill ~122 ~1 ~15 ~122 ~5 ~15 log2 13  
fill ~122 ~1 ~27 ~122 ~5 ~27 log2 13  
fill ~122 ~1 ~28 ~122 ~5 ~28 log2 13  
fill ~122 ~1 ~29 ~122 ~5 ~29 log2 13  
fill ~122 ~1 ~30 ~122 ~5 ~30 log2 13  
fill ~122 ~1 ~31 ~122 ~5 ~31 log2 13  
fill ~122 ~1 ~32 ~122 ~5 ~32 log2 13  
fill ~122 ~1 ~33 ~122 ~5 ~33 log2 13  
fill ~122 ~1 ~45 ~122 ~5 ~45 log2 13  
fill ~122 ~1 ~46 ~122 ~5 ~46 log2 13  
fill ~122 ~1 ~47 ~122 ~5 ~47 log2 13  
fill ~122 ~1 ~48 ~122 ~5 ~48 log2 13  
fill ~122 ~1 ~49 ~122 ~5 ~49 log2 13  
fill ~122 ~1 ~50 ~122 ~5 ~50 log2 13  
fill ~122 ~1 ~51 ~122 ~5 ~51 log2 13  
fill ~122 ~1 ~77 ~122 ~5 ~77 log2 13  
fill ~122 ~1 ~78 ~122 ~5 ~78 log2 13  
fill ~122 ~1 ~79 ~122 ~5 ~79 log2 13  
fill ~122 ~1 ~80 ~122 ~5 ~80 log2 13  
fill ~122 ~1 ~81 ~122 ~5 ~81 log2 13  
fill ~122 ~1 ~82 ~122 ~5 ~82 log2 13  
fill ~122 ~1 ~83 ~122 ~5 ~83 log2 13  
fill ~122 ~1 ~95 ~122 ~5 ~95 log2 13  
fill ~122 ~1 ~96 ~122 ~5 ~96 log2 13  
fill ~122 ~1 ~97 ~122 ~5 ~97 log2 13  
fill ~122 ~1 ~98 ~122 ~5 ~98 log2 13  
fill ~122 ~1 ~99 ~122 ~5 ~99 log2 13  
fill ~122 ~1 ~100 ~122 ~5 ~100 log2 13  
fill ~122 ~1 ~101 ~122 ~5 ~101 log2 13  
fill ~122 ~1 ~113 ~122 ~5 ~113 log2 13  
fill ~122 ~1 ~114 ~122 ~5 ~114 log2 13  
fill ~122 ~1 ~115 ~122 ~5 ~115 log2 13  
fill ~122 ~1 ~116 ~122 ~5 ~116 log2 13  
fill ~122 ~1 ~117 ~122 ~5 ~117 log2 13  
fill ~122 ~1 ~118 ~122 ~5 ~118 log2 13  
fill ~122 ~1 ~119 ~122 ~5 ~119 log2 13  
fill ~123 ~1 ~3 ~124 ~1 ~3 wool 13  
fill ~123 ~1 ~4 ~124 ~1 ~4 stained_hardened_clay 15  
fill ~123 ~1 ~9 ~123 ~2 ~9 stained_hardened_clay 15  
fill ~123 ~1 ~10 ~123 ~1 ~11 stained_hardened_clay 15  
fill ~123 ~1 ~13 ~123 ~1 ~15 stained_hardened_clay 15  
fill ~123 ~1 ~27 ~123 ~2 ~27 stained_hardened_clay 15  
fill ~123 ~1 ~28 ~123 ~1 ~29 stained_hardened_clay 15  
fill ~123 ~1 ~31 ~123 ~1 ~33 stained_hardened_clay 15  
fill ~123 ~1 ~45 ~123 ~2 ~45 stained_hardened_clay 15  
fill ~123 ~1 ~46 ~123 ~1 ~47 stained_hardened_clay 15  
fill ~123 ~1 ~49 ~123 ~1 ~51 stained_hardened_clay 15  
fill ~123 ~1 ~64 ~123 ~5 ~64 stained_hardened_clay 15  
fill ~123 ~1 ~77 ~123 ~2 ~77 stained_hardened_clay 15  
fill ~123 ~1 ~78 ~123 ~1 ~79 stained_hardened_clay 15  
fill ~123 ~1 ~81 ~123 ~1 ~83 stained_hardened_clay 15  
fill ~123 ~1 ~95 ~123 ~2 ~95 stained_hardened_clay 15  
fill ~123 ~1 ~96 ~123 ~1 ~97 stained_hardened_clay 15  
fill ~123 ~1 ~99 ~123 ~1 ~101 stained_hardened_clay 15  
fill ~123 ~1 ~113 ~123 ~2 ~113 stained_hardened_clay 15  
fill ~123 ~1 ~114 ~123 ~1 ~115 stained_hardened_clay 15  
fill ~123 ~1 ~117 ~123 ~1 ~119 stained_hardened_clay 15  
fill ~123 ~1 ~124 ~124 ~1 ~124 stained_hardened_clay 15  
fill ~123 ~1 ~125 ~124 ~1 ~125 wool 13  
fill ~124 ~1 ~6 ~124 ~2 ~6 stained_hardened_clay 13  
fill ~124 ~1 ~7 ~124 ~1 ~6 stained_hardened_clay 13  
fill ~124 ~1 ~14 ~124 ~1 ~15 log2 13  
fill ~124 ~1 ~16 ~124 ~1 ~18 stained_hardened_clay 13  
fill ~124 ~1 ~19 ~124 ~1 ~23 stained_hardened_clay 15  
fill ~124 ~1 ~24 ~124 ~2 ~24 stained_hardened_clay 13  
fill ~124 ~1 ~25 ~124 ~1 ~24 stained_hardened_clay 13  
fill ~124 ~1 ~32 ~124 ~1 ~33 log2 13  
fill ~124 ~1 ~34 ~124 ~1 ~36 stained_hardened_clay 13  
fill ~124 ~1 ~37 ~124 ~1 ~41 stained_hardened_clay 15  
fill ~124 ~1 ~42 ~124 ~2 ~42 stained_hardened_clay 13  
fill ~124 ~1 ~43 ~124 ~1 ~42 stained_hardened_clay 13  
fill ~124 ~1 ~50 ~124 ~1 ~51 log2 13  
fill ~124 ~1 ~52 ~124 ~1 ~54 stained_hardened_clay 13  
fill ~124 ~1 ~55 ~124 ~1 ~57 stained_hardened_clay 15  
fill ~124 ~1 ~60 ~124 ~2 ~60 stained_hardened_clay 13  
fill ~124 ~1 ~61 ~124 ~1 ~60 stained_hardened_clay 13  
fill ~124 ~1 ~65 ~124 ~1 ~68 stained_hardened_clay 13  
fill ~124 ~1 ~74 ~124 ~2 ~74 stained_hardened_clay 13  
fill ~124 ~1 ~75 ~124 ~1 ~74 stained_hardened_clay 13  
fill ~124 ~1 ~77 ~124 ~1 ~78 log2 13  
fill ~124 ~1 ~84 ~124 ~1 ~86 stained_hardened_clay 13  
fill ~124 ~1 ~87 ~124 ~1 ~91 stained_hardened_clay 15  
fill ~124 ~1 ~92 ~124 ~2 ~92 stained_hardened_clay 13  
fill ~124 ~1 ~93 ~124 ~1 ~92 stained_hardened_clay 13  
fill ~124 ~1 ~95 ~124 ~1 ~96 log2 13  
fill ~124 ~1 ~102 ~124 ~1 ~104 stained_hardened_clay 13  
fill ~124 ~1 ~105 ~124 ~1 ~109 stained_hardened_clay 15  
fill ~124 ~1 ~110 ~124 ~2 ~110 stained_hardened_clay 13  
fill ~124 ~1 ~111 ~124 ~1 ~110 stained_hardened_clay 13  
fill ~124 ~1 ~113 ~124 ~1 ~114 log2 13  
fill ~124 ~1 ~120 ~124 ~1 ~122 stained_hardened_clay 13 
setblock ~124 ~1 ~123 stained_hardened_clay 15  
fill ~125 ~1 ~2 ~126 ~1 ~2 stained_hardened_clay 5  
fill ~125 ~1 ~3 ~125 ~2 ~3 stained_hardened_clay 5  
fill ~125 ~1 ~4 ~125 ~3 ~4 wool 13 
setblock ~125 ~1 ~7 log2 13  
fill ~125 ~1 ~19 ~125 ~1 ~20 wool 13  
fill ~125 ~1 ~22 ~125 ~3 ~22 wool 13 
setblock ~125 ~1 ~25 log2 13  
fill ~125 ~1 ~37 ~125 ~1 ~38 wool 13  
fill ~125 ~1 ~40 ~125 ~3 ~40 wool 13 
setblock ~125 ~1 ~43 log2 13  
fill ~125 ~1 ~55 ~125 ~1 ~56 wool 13  
fill ~125 ~1 ~58 ~125 ~3 ~58 wool 13  
fill ~125 ~1 ~69 ~125 ~1 ~70 wool 13  
fill ~125 ~1 ~72 ~125 ~3 ~72 wool 13 
setblock ~125 ~1 ~85 log2 13  
fill ~125 ~1 ~87 ~125 ~1 ~88 wool 13  
fill ~125 ~1 ~90 ~125 ~3 ~90 wool 13 
setblock ~125 ~1 ~103 log2 13  
fill ~125 ~1 ~105 ~125 ~1 ~106 wool 13  
fill ~125 ~1 ~108 ~125 ~3 ~108 wool 13 
setblock ~125 ~1 ~121 log2 13  
fill ~125 ~1 ~123 ~125 ~1 ~124 wool 13  
fill ~125 ~1 ~125 ~126 ~1 ~125 stained_hardened_clay 5  
fill ~125 ~1 ~126 ~126 ~1 ~126 stained_hardened_clay 5  
fill ~126 ~1 ~21 ~126 ~2 ~21 stained_hardened_clay 5  
fill ~126 ~1 ~39 ~126 ~2 ~39 stained_hardened_clay 5  
fill ~126 ~1 ~57 ~126 ~2 ~57 stained_hardened_clay 5  
fill ~126 ~1 ~71 ~126 ~2 ~71 stained_hardened_clay 5  
fill ~126 ~1 ~89 ~126 ~2 ~89 stained_hardened_clay 5  
fill ~126 ~1 ~107 ~126 ~2 ~107 stained_hardened_clay 5  
fill ~2 ~2 ~2 ~3 ~2 ~2 stained_hardened_clay 5  
fill ~2 ~2 ~125 ~3 ~2 ~125 stained_hardened_clay 5  
fill ~2 ~2 ~126 ~3 ~2 ~126 stained_hardened_clay 5  
fill ~3 ~2 ~20 ~3 ~3 ~20 wool 13  
fill ~3 ~2 ~38 ~3 ~3 ~38 wool 13  
fill ~3 ~2 ~56 ~3 ~3 ~56 wool 13  
fill ~3 ~2 ~70 ~3 ~3 ~70 wool 13  
fill ~3 ~2 ~88 ~3 ~3 ~88 wool 13  
fill ~3 ~2 ~106 ~3 ~3 ~106 wool 13  
fill ~3 ~2 ~124 ~3 ~3 ~124 wool 13  
fill ~4 ~2 ~3 ~4 ~3 ~3 wool 13  
fill ~4 ~2 ~4 ~4 ~3 ~4 stained_hardened_clay 15  
fill ~4 ~2 ~5 ~4 ~4 ~5 stained_hardened_clay 13  
fill ~4 ~2 ~7 ~4 ~2 ~8 log2 13  
fill ~4 ~2 ~12 ~6 ~2 ~12 log2 13  
fill ~4 ~2 ~18 ~4 ~2 ~19 stained_hardened_clay 13  
fill ~4 ~2 ~20 ~4 ~3 ~20 stained_hardened_clay 15  
fill ~4 ~2 ~21 ~4 ~6 ~21 stained_hardened_clay 15  
fill ~4 ~2 ~22 ~4 ~3 ~22 stained_hardened_clay 15  
fill ~4 ~2 ~23 ~4 ~4 ~23 stained_hardened_clay 13  
fill ~4 ~2 ~25 ~4 ~2 ~26 log2 13  
fill ~4 ~2 ~30 ~6 ~2 ~30 log2 13  
fill ~4 ~2 ~36 ~4 ~2 ~37 stained_hardened_clay 13  
fill ~4 ~2 ~38 ~4 ~3 ~38 stained_hardened_clay 15  
fill ~4 ~2 ~39 ~4 ~6 ~39 stained_hardened_clay 15  
fill ~4 ~2 ~40 ~4 ~3 ~40 stained_hardened_clay 15  
fill ~4 ~2 ~41 ~4 ~4 ~41 stained_hardened_clay 13  
fill ~4 ~2 ~43 ~4 ~2 ~44 log2 13  
fill ~4 ~2 ~48 ~6 ~2 ~48 log2 13  
fill ~4 ~2 ~54 ~4 ~2 ~55 stained_hardened_clay 13  
fill ~4 ~2 ~56 ~4 ~3 ~56 stained_hardened_clay 15  
fill ~4 ~2 ~57 ~4 ~6 ~57 stained_hardened_clay 15  
fill ~4 ~2 ~59 ~4 ~4 ~59 stained_hardened_clay 13  
fill ~4 ~2 ~68 ~4 ~2 ~69 stained_hardened_clay 13  
fill ~4 ~2 ~73 ~4 ~4 ~73 stained_hardened_clay 13  
fill ~4 ~2 ~80 ~6 ~2 ~80 log2 13  
fill ~4 ~2 ~84 ~4 ~3 ~84 log2 13  
fill ~4 ~2 ~85 ~4 ~2 ~84 log2 13  
fill ~4 ~2 ~86 ~4 ~2 ~87 stained_hardened_clay 13  
fill ~4 ~2 ~88 ~4 ~3 ~88 stained_hardened_clay 15  
fill ~4 ~2 ~89 ~4 ~6 ~89 stained_hardened_clay 15  
fill ~4 ~2 ~90 ~4 ~3 ~90 stained_hardened_clay 15  
fill ~4 ~2 ~91 ~4 ~4 ~91 stained_hardened_clay 13  
fill ~4 ~2 ~98 ~6 ~2 ~98 log2 13  
fill ~4 ~2 ~102 ~4 ~3 ~102 log2 13  
fill ~4 ~2 ~103 ~4 ~2 ~102 log2 13  
fill ~4 ~2 ~104 ~4 ~2 ~105 stained_hardened_clay 13  
fill ~4 ~2 ~106 ~4 ~3 ~106 stained_hardened_clay 15  
fill ~4 ~2 ~107 ~4 ~6 ~107 stained_hardened_clay 15  
fill ~4 ~2 ~108 ~4 ~3 ~108 stained_hardened_clay 15  
fill ~4 ~2 ~109 ~4 ~4 ~109 stained_hardened_clay 13  
fill ~4 ~2 ~116 ~6 ~2 ~116 log2 13  
fill ~4 ~2 ~120 ~4 ~3 ~120 log2 13  
fill ~4 ~2 ~121 ~4 ~2 ~120 log2 13  
fill ~4 ~2 ~122 ~4 ~2 ~123 stained_hardened_clay 13  
fill ~4 ~2 ~124 ~4 ~3 ~124 stained_hardened_clay 15  
fill ~4 ~2 ~125 ~4 ~3 ~125 wool 13  
fill ~5 ~2 ~4 ~6 ~2 ~4 stained_hardened_clay 13  
fill ~5 ~2 ~7 ~5 ~5 ~7 stained_hardened_clay 15  
fill ~5 ~2 ~8 ~5 ~2 ~7 stained_hardened_clay 15  
fill ~5 ~2 ~11 ~5 ~4 ~11 log2 13  
fill ~5 ~2 ~13 ~5 ~4 ~13 log2 13  
fill ~5 ~2 ~14 ~5 ~2 ~11 log2 13 
setblock ~5 ~2 ~15 stained_hardened_clay 15  
fill ~5 ~2 ~17 ~5 ~5 ~17 stained_hardened_clay 15  
fill ~5 ~2 ~25 ~5 ~5 ~25 stained_hardened_clay 15  
fill ~5 ~2 ~26 ~5 ~2 ~25 stained_hardened_clay 15  
fill ~5 ~2 ~29 ~5 ~4 ~29 log2 13  
fill ~5 ~2 ~31 ~5 ~4 ~31 log2 13  
fill ~5 ~2 ~32 ~5 ~2 ~29 log2 13 
setblock ~5 ~2 ~33 stained_hardened_clay 15  
fill ~5 ~2 ~35 ~5 ~5 ~35 stained_hardened_clay 15  
fill ~5 ~2 ~43 ~5 ~5 ~43 stained_hardened_clay 15  
fill ~5 ~2 ~44 ~5 ~2 ~43 stained_hardened_clay 15  
fill ~5 ~2 ~47 ~5 ~4 ~47 log2 13  
fill ~5 ~2 ~49 ~5 ~4 ~49 log2 13  
fill ~5 ~2 ~50 ~5 ~2 ~47 log2 13 
setblock ~5 ~2 ~51 stained_hardened_clay 15  
fill ~5 ~2 ~53 ~5 ~5 ~53 stained_hardened_clay 15  
fill ~5 ~2 ~61 ~5 ~5 ~61 stained_hardened_clay 15  
fill ~5 ~2 ~62 ~5 ~5 ~62 stained_hardened_clay 15  
fill ~5 ~2 ~63 ~5 ~5 ~63 stained_hardened_clay 15  
fill ~5 ~2 ~65 ~5 ~5 ~65 stained_hardened_clay 15  
fill ~5 ~2 ~66 ~5 ~5 ~66 stained_hardened_clay 15  
fill ~5 ~2 ~67 ~5 ~5 ~67 stained_hardened_clay 15  
fill ~5 ~2 ~75 ~5 ~5 ~75 stained_hardened_clay 15  
fill ~5 ~2 ~78 ~5 ~2 ~81 log2 13  
fill ~5 ~2 ~83 ~5 ~2 ~85 stained_hardened_clay 15  
fill ~5 ~2 ~93 ~5 ~5 ~93 stained_hardened_clay 15  
fill ~5 ~2 ~96 ~5 ~2 ~99 log2 13  
fill ~5 ~2 ~101 ~5 ~2 ~103 stained_hardened_clay 15  
fill ~5 ~2 ~111 ~5 ~5 ~111 stained_hardened_clay 15  
fill ~5 ~2 ~114 ~5 ~2 ~117 log2 13  
fill ~5 ~2 ~119 ~5 ~2 ~121 stained_hardened_clay 15  
fill ~5 ~2 ~124 ~6 ~2 ~124 stained_hardened_clay 13  
fill ~6 ~2 ~8 ~6 ~5 ~8 log2 13  
fill ~6 ~2 ~16 ~6 ~5 ~16 log2 13  
fill ~6 ~2 ~26 ~6 ~5 ~26 log2 13  
fill ~6 ~2 ~34 ~6 ~5 ~34 log2 13  
fill ~6 ~2 ~44 ~6 ~5 ~44 log2 13  
fill ~6 ~2 ~52 ~6 ~5 ~52 log2 13  
fill ~6 ~2 ~76 ~6 ~5 ~76 log2 13  
fill ~6 ~2 ~84 ~6 ~5 ~84 log2 13  
fill ~6 ~2 ~94 ~6 ~5 ~94 log2 13  
fill ~6 ~2 ~102 ~6 ~5 ~102 log2 13  
fill ~6 ~2 ~112 ~6 ~5 ~112 log2 13  
fill ~6 ~2 ~120 ~6 ~5 ~120 log2 13  
fill ~7 ~2 ~4 ~8 ~2 ~4 log2 13  
fill ~7 ~2 ~5 ~9 ~2 ~5 stained_hardened_clay 15  
fill ~7 ~2 ~123 ~9 ~2 ~123 stained_hardened_clay 15  
fill ~7 ~2 ~124 ~8 ~2 ~124 log2 13  
fill ~8 ~2 ~6 ~16 ~2 ~6 log2 13  
fill ~8 ~2 ~122 ~16 ~2 ~122 log2 13  
fill ~11 ~2 ~5 ~14 ~2 ~5 log2 13  
fill ~11 ~2 ~123 ~14 ~2 ~123 log2 13  
fill ~12 ~2 ~4 ~12 ~3 ~4 log2 13  
fill ~12 ~2 ~124 ~12 ~3 ~124 log2 13 
setblock ~15 ~2 ~5 stained_hardened_clay 15 
setblock ~15 ~2 ~123 stained_hardened_clay 15  
fill ~17 ~2 ~5 ~17 ~5 ~5 stained_hardened_clay 15  
fill ~17 ~2 ~123 ~17 ~5 ~123 stained_hardened_clay 15  
fill ~18 ~2 ~4 ~19 ~2 ~4 stained_hardened_clay 13  
fill ~18 ~2 ~124 ~19 ~2 ~124 stained_hardened_clay 13  
fill ~20 ~2 ~3 ~20 ~3 ~3 wool 13  
fill ~20 ~2 ~4 ~22 ~2 ~4 stained_hardened_clay 15  
fill ~20 ~2 ~124 ~22 ~2 ~124 stained_hardened_clay 15  
fill ~20 ~2 ~125 ~20 ~3 ~125 wool 13  
fill ~22 ~2 ~3 ~22 ~3 ~3 wool 13  
fill ~22 ~2 ~125 ~22 ~3 ~125 wool 13  
fill ~23 ~2 ~4 ~24 ~2 ~4 stained_hardened_clay 13  
fill ~23 ~2 ~124 ~24 ~2 ~124 stained_hardened_clay 13  
fill ~25 ~2 ~4 ~26 ~2 ~4 log2 13  
fill ~25 ~2 ~5 ~27 ~2 ~5 stained_hardened_clay 15  
fill ~25 ~2 ~123 ~27 ~2 ~123 stained_hardened_clay 15  
fill ~25 ~2 ~124 ~26 ~2 ~124 log2 13  
fill ~26 ~2 ~6 ~34 ~2 ~6 log2 13  
fill ~26 ~2 ~122 ~34 ~2 ~122 log2 13  
fill ~29 ~2 ~5 ~32 ~2 ~5 log2 13  
fill ~29 ~2 ~123 ~32 ~2 ~123 log2 13  
fill ~30 ~2 ~4 ~30 ~3 ~4 log2 13  
fill ~30 ~2 ~124 ~30 ~3 ~124 log2 13 
setblock ~33 ~2 ~5 stained_hardened_clay 15 
setblock ~33 ~2 ~123 stained_hardened_clay 15  
fill ~35 ~2 ~5 ~35 ~5 ~5 stained_hardened_clay 15  
fill ~35 ~2 ~123 ~35 ~5 ~123 stained_hardened_clay 15  
fill ~36 ~2 ~4 ~37 ~2 ~4 stained_hardened_clay 13  
fill ~36 ~2 ~124 ~37 ~2 ~124 stained_hardened_clay 13  
fill ~38 ~2 ~3 ~38 ~3 ~3 wool 13  
fill ~38 ~2 ~4 ~40 ~2 ~4 stained_hardened_clay 15  
fill ~38 ~2 ~124 ~40 ~2 ~124 stained_hardened_clay 15  
fill ~38 ~2 ~125 ~38 ~3 ~125 wool 13  
fill ~40 ~2 ~3 ~40 ~3 ~3 wool 13  
fill ~40 ~2 ~125 ~40 ~3 ~125 wool 13  
fill ~41 ~2 ~4 ~42 ~2 ~4 stained_hardened_clay 13  
fill ~41 ~2 ~124 ~42 ~2 ~124 stained_hardened_clay 13  
fill ~43 ~2 ~4 ~44 ~2 ~4 log2 13  
fill ~43 ~2 ~5 ~45 ~2 ~5 stained_hardened_clay 15  
fill ~43 ~2 ~123 ~45 ~2 ~123 stained_hardened_clay 15  
fill ~43 ~2 ~124 ~44 ~2 ~124 log2 13  
fill ~44 ~2 ~6 ~52 ~2 ~6 log2 13  
fill ~44 ~2 ~122 ~52 ~2 ~122 log2 13  
fill ~47 ~2 ~5 ~50 ~2 ~5 log2 13  
fill ~47 ~2 ~123 ~50 ~2 ~123 log2 13  
fill ~48 ~2 ~4 ~48 ~3 ~4 log2 13  
fill ~48 ~2 ~124 ~48 ~3 ~124 log2 13 
setblock ~51 ~2 ~5 stained_hardened_clay 15 
setblock ~51 ~2 ~123 stained_hardened_clay 15  
fill ~53 ~2 ~5 ~53 ~5 ~5 stained_hardened_clay 15  
fill ~53 ~2 ~123 ~53 ~5 ~123 stained_hardened_clay 15  
fill ~54 ~2 ~4 ~55 ~2 ~4 stained_hardened_clay 13  
fill ~54 ~2 ~124 ~55 ~2 ~124 stained_hardened_clay 13  
fill ~56 ~2 ~3 ~56 ~3 ~3 wool 13  
fill ~56 ~2 ~4 ~57 ~2 ~4 stained_hardened_clay 15  
fill ~56 ~2 ~124 ~57 ~2 ~124 stained_hardened_clay 15  
fill ~56 ~2 ~125 ~56 ~3 ~125 wool 13  
fill ~58 ~2 ~3 ~58 ~3 ~3 wool 13  
fill ~58 ~2 ~5 ~60 ~2 ~5 dirt 0  
fill ~58 ~2 ~123 ~60 ~2 ~123 dirt 0  
fill ~58 ~2 ~125 ~58 ~3 ~125 wool 13  
fill ~59 ~2 ~4 ~60 ~2 ~4 stained_hardened_clay 13  
fill ~59 ~2 ~124 ~60 ~2 ~124 stained_hardened_clay 13  
fill ~61 ~2 ~5 ~67 ~2 ~5 stained_hardened_clay 15  
fill ~61 ~2 ~123 ~67 ~2 ~123 stained_hardened_clay 15  
fill ~68 ~2 ~4 ~69 ~2 ~4 stained_hardened_clay 13  
fill ~68 ~2 ~5 ~70 ~2 ~5 dirt 0  
fill ~68 ~2 ~123 ~70 ~2 ~123 dirt 0  
fill ~68 ~2 ~124 ~69 ~2 ~124 stained_hardened_clay 13  
fill ~70 ~2 ~3 ~70 ~3 ~3 wool 13  
fill ~70 ~2 ~125 ~70 ~3 ~125 wool 13  
fill ~71 ~2 ~4 ~72 ~2 ~4 stained_hardened_clay 15  
fill ~71 ~2 ~124 ~72 ~2 ~124 stained_hardened_clay 15  
fill ~72 ~2 ~3 ~72 ~3 ~3 wool 13  
fill ~72 ~2 ~125 ~72 ~3 ~125 wool 13  
fill ~73 ~2 ~4 ~74 ~2 ~4 stained_hardened_clay 13  
fill ~73 ~2 ~124 ~74 ~2 ~124 stained_hardened_clay 13  
fill ~75 ~2 ~5 ~75 ~5 ~5 stained_hardened_clay 15  
fill ~75 ~2 ~123 ~75 ~5 ~123 stained_hardened_clay 15  
fill ~76 ~2 ~6 ~84 ~2 ~6 log2 13  
fill ~76 ~2 ~122 ~84 ~2 ~122 log2 13  
fill ~77 ~2 ~5 ~77 ~1 ~5 stained_hardened_clay 15  
fill ~77 ~2 ~123 ~77 ~1 ~123 stained_hardened_clay 15  
fill ~78 ~2 ~5 ~81 ~2 ~5 log2 13  
fill ~78 ~2 ~123 ~81 ~2 ~123 log2 13  
fill ~80 ~2 ~4 ~80 ~3 ~4 log2 13  
fill ~80 ~2 ~124 ~80 ~3 ~124 log2 13  
fill ~83 ~2 ~5 ~85 ~2 ~5 stained_hardened_clay 15  
fill ~83 ~2 ~123 ~85 ~2 ~123 stained_hardened_clay 15  
fill ~84 ~2 ~4 ~85 ~2 ~4 log2 13  
fill ~84 ~2 ~124 ~85 ~2 ~124 log2 13  
fill ~86 ~2 ~4 ~87 ~2 ~4 stained_hardened_clay 13  
fill ~86 ~2 ~124 ~87 ~2 ~124 stained_hardened_clay 13  
fill ~88 ~2 ~3 ~88 ~3 ~3 wool 13  
fill ~88 ~2 ~4 ~90 ~2 ~4 stained_hardened_clay 15  
fill ~88 ~2 ~124 ~90 ~2 ~124 stained_hardened_clay 15  
fill ~88 ~2 ~125 ~88 ~3 ~125 wool 13  
fill ~90 ~2 ~3 ~90 ~3 ~3 wool 13  
fill ~90 ~2 ~125 ~90 ~3 ~125 wool 13  
fill ~91 ~2 ~4 ~92 ~2 ~4 stained_hardened_clay 13  
fill ~91 ~2 ~124 ~92 ~2 ~124 stained_hardened_clay 13  
fill ~93 ~2 ~5 ~93 ~5 ~5 stained_hardened_clay 15  
fill ~93 ~2 ~123 ~93 ~5 ~123 stained_hardened_clay 15  
fill ~94 ~2 ~6 ~102 ~2 ~6 log2 13  
fill ~94 ~2 ~122 ~102 ~2 ~122 log2 13  
fill ~95 ~2 ~5 ~95 ~1 ~5 stained_hardened_clay 15  
fill ~95 ~2 ~123 ~95 ~1 ~123 stained_hardened_clay 15  
fill ~96 ~2 ~5 ~99 ~2 ~5 log2 13  
fill ~96 ~2 ~123 ~99 ~2 ~123 log2 13  
fill ~98 ~2 ~4 ~98 ~3 ~4 log2 13  
fill ~98 ~2 ~124 ~98 ~3 ~124 log2 13  
fill ~101 ~2 ~5 ~103 ~2 ~5 stained_hardened_clay 15  
fill ~101 ~2 ~123 ~103 ~2 ~123 stained_hardened_clay 15  
fill ~102 ~2 ~4 ~103 ~2 ~4 log2 13  
fill ~102 ~2 ~124 ~103 ~2 ~124 log2 13  
fill ~104 ~2 ~4 ~105 ~2 ~4 stained_hardened_clay 13  
fill ~104 ~2 ~124 ~105 ~2 ~124 stained_hardened_clay 13  
fill ~106 ~2 ~3 ~106 ~3 ~3 wool 13  
fill ~106 ~2 ~4 ~108 ~2 ~4 stained_hardened_clay 15  
fill ~106 ~2 ~124 ~108 ~2 ~124 stained_hardened_clay 15  
fill ~106 ~2 ~125 ~106 ~3 ~125 wool 13  
fill ~108 ~2 ~3 ~108 ~3 ~3 wool 13  
fill ~108 ~2 ~125 ~108 ~3 ~125 wool 13  
fill ~109 ~2 ~4 ~110 ~2 ~4 stained_hardened_clay 13  
fill ~109 ~2 ~124 ~110 ~2 ~124 stained_hardened_clay 13  
fill ~111 ~2 ~5 ~111 ~5 ~5 stained_hardened_clay 15  
fill ~111 ~2 ~123 ~111 ~5 ~123 stained_hardened_clay 15  
fill ~112 ~2 ~6 ~120 ~2 ~6 log2 13  
fill ~112 ~2 ~122 ~120 ~2 ~122 log2 13  
fill ~113 ~2 ~5 ~113 ~1 ~5 stained_hardened_clay 15  
fill ~113 ~2 ~123 ~113 ~1 ~123 stained_hardened_clay 15  
fill ~114 ~2 ~5 ~117 ~2 ~5 log2 13  
fill ~114 ~2 ~123 ~117 ~2 ~123 log2 13  
fill ~116 ~2 ~4 ~116 ~3 ~4 log2 13  
fill ~116 ~2 ~124 ~116 ~3 ~124 log2 13  
fill ~119 ~2 ~5 ~121 ~2 ~5 stained_hardened_clay 15  
fill ~119 ~2 ~123 ~121 ~2 ~123 stained_hardened_clay 15  
fill ~120 ~2 ~4 ~121 ~2 ~4 log2 13  
fill ~120 ~2 ~124 ~121 ~2 ~124 log2 13  
fill ~122 ~2 ~4 ~123 ~2 ~4 stained_hardened_clay 13  
fill ~122 ~2 ~8 ~122 ~5 ~8 log2 13  
fill ~122 ~2 ~16 ~122 ~5 ~16 log2 13  
fill ~122 ~2 ~26 ~122 ~5 ~26 log2 13  
fill ~122 ~2 ~34 ~122 ~5 ~34 log2 13  
fill ~122 ~2 ~44 ~122 ~5 ~44 log2 13  
fill ~122 ~2 ~52 ~122 ~5 ~52 log2 13  
fill ~122 ~2 ~76 ~122 ~5 ~76 log2 13  
fill ~122 ~2 ~84 ~122 ~5 ~84 log2 13  
fill ~122 ~2 ~94 ~122 ~5 ~94 log2 13  
fill ~122 ~2 ~102 ~122 ~5 ~102 log2 13  
fill ~122 ~2 ~112 ~122 ~5 ~112 log2 13  
fill ~122 ~2 ~120 ~122 ~5 ~120 log2 13  
fill ~122 ~2 ~124 ~123 ~2 ~124 stained_hardened_clay 13  
fill ~123 ~2 ~7 ~123 ~5 ~7 stained_hardened_clay 15  
fill ~123 ~2 ~8 ~123 ~2 ~7 stained_hardened_clay 15  
fill ~123 ~2 ~11 ~123 ~4 ~11 log2 13  
fill ~123 ~2 ~12 ~124 ~2 ~12 log2 13  
fill ~123 ~2 ~13 ~123 ~4 ~13 log2 13  
fill ~123 ~2 ~14 ~123 ~2 ~11 log2 13 
setblock ~123 ~2 ~15 stained_hardened_clay 15  
fill ~123 ~2 ~17 ~123 ~5 ~17 stained_hardened_clay 15  
fill ~123 ~2 ~25 ~123 ~5 ~25 stained_hardened_clay 15  
fill ~123 ~2 ~26 ~123 ~2 ~25 stained_hardened_clay 15  
fill ~123 ~2 ~29 ~123 ~4 ~29 log2 13  
fill ~123 ~2 ~30 ~124 ~2 ~30 log2 13  
fill ~123 ~2 ~31 ~123 ~4 ~31 log2 13  
fill ~123 ~2 ~32 ~123 ~2 ~29 log2 13 
setblock ~123 ~2 ~33 stained_hardened_clay 15  
fill ~123 ~2 ~35 ~123 ~5 ~35 stained_hardened_clay 15  
fill ~123 ~2 ~43 ~123 ~5 ~43 stained_hardened_clay 15  
fill ~123 ~2 ~44 ~123 ~2 ~43 stained_hardened_clay 15  
fill ~123 ~2 ~47 ~123 ~4 ~47 log2 13  
fill ~123 ~2 ~48 ~124 ~2 ~48 log2 13  
fill ~123 ~2 ~49 ~123 ~4 ~49 log2 13  
fill ~123 ~2 ~50 ~123 ~2 ~47 log2 13 
setblock ~123 ~2 ~51 stained_hardened_clay 15  
fill ~123 ~2 ~53 ~123 ~5 ~53 stained_hardened_clay 15  
fill ~123 ~2 ~61 ~123 ~5 ~61 stained_hardened_clay 15  
fill ~123 ~2 ~62 ~123 ~5 ~62 stained_hardened_clay 15  
fill ~123 ~2 ~63 ~123 ~5 ~63 stained_hardened_clay 15  
fill ~123 ~2 ~65 ~123 ~5 ~65 stained_hardened_clay 15  
fill ~123 ~2 ~66 ~123 ~5 ~66 stained_hardened_clay 15  
fill ~123 ~2 ~67 ~123 ~5 ~67 stained_hardened_clay 15  
fill ~123 ~2 ~75 ~123 ~5 ~75 stained_hardened_clay 15  
fill ~123 ~2 ~78 ~123 ~2 ~81 log2 13  
fill ~123 ~2 ~83 ~123 ~2 ~85 stained_hardened_clay 15  
fill ~123 ~2 ~93 ~123 ~5 ~93 stained_hardened_clay 15  
fill ~123 ~2 ~96 ~123 ~2 ~99 log2 13  
fill ~123 ~2 ~101 ~123 ~2 ~103 stained_hardened_clay 15  
fill ~123 ~2 ~111 ~123 ~5 ~111 stained_hardened_clay 15  
fill ~123 ~2 ~114 ~123 ~2 ~117 log2 13  
fill ~123 ~2 ~119 ~123 ~2 ~121 stained_hardened_clay 15  
fill ~124 ~2 ~3 ~124 ~3 ~3 wool 13  
fill ~124 ~2 ~4 ~124 ~3 ~4 stained_hardened_clay 15  
fill ~124 ~2 ~5 ~124 ~4 ~5 stained_hardened_clay 13  
fill ~124 ~2 ~7 ~124 ~2 ~8 log2 13  
fill ~124 ~2 ~18 ~124 ~2 ~19 stained_hardened_clay 13  
fill ~124 ~2 ~20 ~124 ~3 ~20 stained_hardened_clay 15  
fill ~124 ~2 ~21 ~124 ~6 ~21 stained_hardened_clay 15  
fill ~124 ~2 ~22 ~124 ~3 ~22 stained_hardened_clay 15  
fill ~124 ~2 ~23 ~124 ~4 ~23 stained_hardened_clay 13  
fill ~124 ~2 ~25 ~124 ~2 ~26 log2 13  
fill ~124 ~2 ~36 ~124 ~2 ~37 stained_hardened_clay 13  
fill ~124 ~2 ~38 ~124 ~3 ~38 stained_hardened_clay 15  
fill ~124 ~2 ~39 ~124 ~6 ~39 stained_hardened_clay 15  
fill ~124 ~2 ~40 ~124 ~3 ~40 stained_hardened_clay 15  
fill ~124 ~2 ~41 ~124 ~4 ~41 stained_hardened_clay 13  
fill ~124 ~2 ~43 ~124 ~2 ~44 log2 13  
fill ~124 ~2 ~54 ~124 ~2 ~55 stained_hardened_clay 13  
fill ~124 ~2 ~56 ~124 ~3 ~56 stained_hardened_clay 15  
fill ~124 ~2 ~57 ~124 ~6 ~57 stained_hardened_clay 15  
fill ~124 ~2 ~59 ~124 ~4 ~59 stained_hardened_clay 13  
fill ~124 ~2 ~68 ~124 ~2 ~69 stained_hardened_clay 13  
fill ~124 ~2 ~73 ~124 ~4 ~73 stained_hardened_clay 13  
fill ~124 ~2 ~80 ~124 ~3 ~80 log2 13  
fill ~124 ~2 ~84 ~124 ~3 ~84 log2 13  
fill ~124 ~2 ~85 ~124 ~2 ~84 log2 13  
fill ~124 ~2 ~86 ~124 ~2 ~87 stained_hardened_clay 13  
fill ~124 ~2 ~88 ~124 ~3 ~88 stained_hardened_clay 15  
fill ~124 ~2 ~89 ~124 ~6 ~89 stained_hardened_clay 15  
fill ~124 ~2 ~90 ~124 ~3 ~90 stained_hardened_clay 15  
fill ~124 ~2 ~91 ~124 ~4 ~91 stained_hardened_clay 13  
fill ~124 ~2 ~98 ~124 ~3 ~98 log2 13  
fill ~124 ~2 ~102 ~124 ~3 ~102 log2 13  
fill ~124 ~2 ~103 ~124 ~2 ~102 log2 13  
fill ~124 ~2 ~104 ~124 ~2 ~105 stained_hardened_clay 13  
fill ~124 ~2 ~106 ~124 ~3 ~106 stained_hardened_clay 15  
fill ~124 ~2 ~107 ~124 ~6 ~107 stained_hardened_clay 15  
fill ~124 ~2 ~108 ~124 ~3 ~108 stained_hardened_clay 15  
fill ~124 ~2 ~109 ~124 ~4 ~109 stained_hardened_clay 13  
fill ~124 ~2 ~116 ~124 ~3 ~116 log2 13  
fill ~124 ~2 ~120 ~124 ~3 ~120 log2 13  
fill ~124 ~2 ~121 ~124 ~2 ~120 log2 13  
fill ~124 ~2 ~122 ~124 ~2 ~123 stained_hardened_clay 13  
fill ~124 ~2 ~124 ~124 ~3 ~124 stained_hardened_clay 15  
fill ~124 ~2 ~125 ~124 ~3 ~125 wool 13  
fill ~125 ~2 ~2 ~126 ~2 ~2 stained_hardened_clay 5  
fill ~125 ~2 ~20 ~125 ~3 ~20 wool 13  
fill ~125 ~2 ~38 ~125 ~3 ~38 wool 13  
fill ~125 ~2 ~56 ~125 ~3 ~56 wool 13  
fill ~125 ~2 ~70 ~125 ~3 ~70 wool 13  
fill ~125 ~2 ~88 ~125 ~3 ~88 wool 13  
fill ~125 ~2 ~106 ~125 ~3 ~106 wool 13  
fill ~125 ~2 ~124 ~125 ~3 ~124 wool 13  
fill ~125 ~2 ~125 ~126 ~2 ~125 stained_hardened_clay 5  
fill ~125 ~2 ~126 ~126 ~2 ~126 stained_hardened_clay 5  
fill ~2 ~3 ~2 ~2 ~4 ~2 stained_hardened_clay 5  
fill ~2 ~3 ~126 ~2 ~4 ~126 stained_hardened_clay 5  
fill ~3 ~3 ~3 ~3 ~6 ~3 wool 13  
fill ~3 ~3 ~12 ~4 ~3 ~12 log2 13  
fill ~3 ~3 ~21 ~3 ~6 ~21 wool 13  
fill ~3 ~3 ~30 ~4 ~3 ~30 log2 13  
fill ~3 ~3 ~39 ~3 ~6 ~39 wool 13  
fill ~3 ~3 ~48 ~4 ~3 ~48 log2 13  
fill ~3 ~3 ~57 ~3 ~6 ~57 wool 13  
fill ~3 ~3 ~71 ~3 ~6 ~71 wool 13  
fill ~3 ~3 ~80 ~4 ~3 ~80 log2 13  
fill ~3 ~3 ~89 ~3 ~6 ~89 wool 13  
fill ~3 ~3 ~98 ~4 ~3 ~98 log2 13  
fill ~3 ~3 ~107 ~3 ~6 ~107 wool 13  
fill ~3 ~3 ~116 ~4 ~3 ~116 log2 13  
fill ~3 ~3 ~125 ~3 ~6 ~125 wool 13  
fill ~4 ~3 ~8 ~6 ~3 ~8 log2 13  
fill ~4 ~3 ~11 ~4 ~6 ~11 log2 13  
fill ~4 ~3 ~13 ~4 ~6 ~13 log2 13  
fill ~4 ~3 ~19 ~4 ~4 ~19 stained_hardened_clay 13  
fill ~4 ~3 ~26 ~6 ~3 ~26 log2 13  
fill ~4 ~3 ~29 ~4 ~6 ~29 log2 13  
fill ~4 ~3 ~31 ~4 ~6 ~31 log2 13  
fill ~4 ~3 ~37 ~4 ~4 ~37 stained_hardened_clay 13  
fill ~4 ~3 ~44 ~6 ~3 ~44 log2 13  
fill ~4 ~3 ~47 ~4 ~6 ~47 log2 13  
fill ~4 ~3 ~49 ~4 ~6 ~49 log2 13  
fill ~4 ~3 ~55 ~4 ~4 ~55 stained_hardened_clay 13  
fill ~4 ~3 ~64 ~4 ~5 ~64 log2 13  
fill ~4 ~3 ~69 ~4 ~4 ~69 stained_hardened_clay 13  
fill ~4 ~3 ~79 ~6 ~3 ~79 log2 13  
fill ~4 ~3 ~81 ~6 ~3 ~81 log2 13  
fill ~4 ~3 ~87 ~4 ~4 ~87 stained_hardened_clay 13  
fill ~4 ~3 ~97 ~6 ~3 ~97 log2 13  
fill ~4 ~3 ~99 ~6 ~3 ~99 log2 13  
fill ~4 ~3 ~105 ~4 ~4 ~105 stained_hardened_clay 13  
fill ~4 ~3 ~115 ~6 ~3 ~115 log2 13  
fill ~4 ~3 ~117 ~6 ~3 ~117 log2 13  
fill ~4 ~3 ~123 ~4 ~4 ~123 stained_hardened_clay 13  
fill ~5 ~3 ~4 ~5 ~4 ~4 stained_hardened_clay 13  
fill ~5 ~3 ~6 ~5 ~5 ~6 stained_hardened_clay 15  
fill ~5 ~3 ~12 ~5 ~4 ~12 stained_hardened_clay 15 
setblock ~5 ~3 ~16 stained_hardened_clay 15  
fill ~5 ~3 ~18 ~5 ~5 ~18 stained_hardened_clay 15  
fill ~5 ~3 ~24 ~5 ~5 ~24 stained_hardened_clay 15  
fill ~5 ~3 ~30 ~5 ~4 ~30 stained_hardened_clay 15 
setblock ~5 ~3 ~34 stained_hardened_clay 15  
fill ~5 ~3 ~36 ~5 ~5 ~36 stained_hardened_clay 15  
fill ~5 ~3 ~42 ~5 ~5 ~42 stained_hardened_clay 15  
fill ~5 ~3 ~48 ~5 ~4 ~48 stained_hardened_clay 15 
setblock ~5 ~3 ~52 stained_hardened_clay 15  
fill ~5 ~3 ~54 ~5 ~5 ~54 stained_hardened_clay 15  
fill ~5 ~3 ~60 ~5 ~5 ~60 stained_hardened_clay 15  
fill ~5 ~3 ~68 ~5 ~5 ~68 stained_hardened_clay 15  
fill ~5 ~3 ~74 ~5 ~5 ~74 stained_hardened_clay 15 
setblock ~5 ~3 ~76 stained_hardened_clay 15  
fill ~5 ~3 ~80 ~5 ~4 ~80 stained_hardened_clay 15 
setblock ~5 ~3 ~84 log2 13  
fill ~5 ~3 ~85 ~5 ~5 ~85 stained_hardened_clay 15  
fill ~5 ~3 ~86 ~5 ~5 ~86 stained_hardened_clay 15  
fill ~5 ~3 ~92 ~5 ~5 ~92 stained_hardened_clay 15 
setblock ~5 ~3 ~94 stained_hardened_clay 15  
fill ~5 ~3 ~98 ~5 ~4 ~98 stained_hardened_clay 15 
setblock ~5 ~3 ~102 log2 13  
fill ~5 ~3 ~103 ~5 ~5 ~103 stained_hardened_clay 15  
fill ~5 ~3 ~104 ~5 ~5 ~104 stained_hardened_clay 15  
fill ~5 ~3 ~110 ~5 ~5 ~110 stained_hardened_clay 15 
setblock ~5 ~3 ~112 stained_hardened_clay 15  
fill ~5 ~3 ~116 ~5 ~4 ~116 stained_hardened_clay 15 
setblock ~5 ~3 ~120 log2 13  
fill ~5 ~3 ~121 ~5 ~5 ~121 stained_hardened_clay 15  
fill ~5 ~3 ~122 ~5 ~5 ~122 stained_hardened_clay 15  
fill ~5 ~3 ~124 ~5 ~4 ~124 stained_hardened_clay 13  
fill ~6 ~3 ~5 ~7 ~3 ~5 stained_hardened_clay 15  
fill ~6 ~3 ~123 ~7 ~3 ~123 stained_hardened_clay 15  
fill ~8 ~3 ~4 ~8 ~3 ~6 log2 13  
fill ~8 ~3 ~122 ~16 ~3 ~122 log2 13  
fill ~8 ~3 ~123 ~8 ~3 ~124 log2 13  
fill ~9 ~3 ~6 ~16 ~3 ~6 log2 13  
fill ~11 ~3 ~4 ~11 ~6 ~4 log2 13  
fill ~11 ~3 ~5 ~11 ~4 ~5 log2 13  
fill ~11 ~3 ~123 ~11 ~4 ~123 log2 13  
fill ~11 ~3 ~124 ~11 ~6 ~124 log2 13  
fill ~12 ~3 ~3 ~12 ~10 ~3 log2 13  
fill ~12 ~3 ~5 ~12 ~4 ~5 stained_hardened_clay 15  
fill ~12 ~3 ~123 ~12 ~4 ~123 stained_hardened_clay 15  
fill ~12 ~3 ~125 ~12 ~10 ~125 log2 13  
fill ~13 ~3 ~4 ~13 ~6 ~4 log2 13  
fill ~13 ~3 ~5 ~13 ~4 ~5 log2 13  
fill ~13 ~3 ~123 ~13 ~4 ~123 log2 13  
fill ~13 ~3 ~124 ~13 ~6 ~124 log2 13 
setblock ~16 ~3 ~5 stained_hardened_clay 15 
setblock ~16 ~3 ~123 stained_hardened_clay 15  
fill ~18 ~3 ~5 ~18 ~5 ~5 stained_hardened_clay 15  
fill ~18 ~3 ~123 ~18 ~5 ~123 stained_hardened_clay 15  
fill ~19 ~3 ~4 ~19 ~4 ~4 stained_hardened_clay 13  
fill ~19 ~3 ~124 ~19 ~4 ~124 stained_hardened_clay 13  
fill ~20 ~3 ~4 ~22 ~3 ~4 stained_hardened_clay 15  
fill ~20 ~3 ~124 ~22 ~3 ~124 stained_hardened_clay 15  
fill ~21 ~3 ~3 ~21 ~6 ~3 wool 13  
fill ~21 ~3 ~125 ~21 ~6 ~125 wool 13  
fill ~23 ~3 ~4 ~23 ~4 ~4 stained_hardened_clay 13  
fill ~23 ~3 ~124 ~23 ~4 ~124 stained_hardened_clay 13  
fill ~24 ~3 ~5 ~25 ~3 ~5 stained_hardened_clay 15  
fill ~24 ~3 ~123 ~25 ~3 ~123 stained_hardened_clay 15  
fill ~26 ~3 ~4 ~26 ~3 ~6 log2 13  
fill ~26 ~3 ~122 ~34 ~3 ~122 log2 13  
fill ~26 ~3 ~123 ~26 ~3 ~124 log2 13  
fill ~27 ~3 ~6 ~34 ~3 ~6 log2 13  
fill ~29 ~3 ~4 ~29 ~6 ~4 log2 13  
fill ~29 ~3 ~5 ~29 ~4 ~5 log2 13  
fill ~29 ~3 ~123 ~29 ~4 ~123 log2 13  
fill ~29 ~3 ~124 ~29 ~6 ~124 log2 13  
fill ~30 ~3 ~3 ~30 ~10 ~3 log2 13  
fill ~30 ~3 ~5 ~30 ~4 ~5 stained_hardened_clay 15  
fill ~30 ~3 ~123 ~30 ~4 ~123 stained_hardened_clay 15  
fill ~30 ~3 ~125 ~30 ~10 ~125 log2 13  
fill ~31 ~3 ~4 ~31 ~6 ~4 log2 13  
fill ~31 ~3 ~5 ~31 ~4 ~5 log2 13  
fill ~31 ~3 ~123 ~31 ~4 ~123 log2 13  
fill ~31 ~3 ~124 ~31 ~6 ~124 log2 13 
setblock ~34 ~3 ~5 stained_hardened_clay 15 
setblock ~34 ~3 ~123 stained_hardened_clay 15  
fill ~36 ~3 ~5 ~36 ~5 ~5 stained_hardened_clay 15  
fill ~36 ~3 ~123 ~36 ~5 ~123 stained_hardened_clay 15  
fill ~37 ~3 ~4 ~37 ~4 ~4 stained_hardened_clay 13  
fill ~37 ~3 ~124 ~37 ~4 ~124 stained_hardened_clay 13  
fill ~38 ~3 ~4 ~40 ~3 ~4 stained_hardened_clay 15  
fill ~38 ~3 ~124 ~40 ~3 ~124 stained_hardened_clay 15  
fill ~39 ~3 ~3 ~39 ~6 ~3 wool 13  
fill ~39 ~3 ~125 ~39 ~6 ~125 wool 13  
fill ~41 ~3 ~4 ~41 ~4 ~4 stained_hardened_clay 13  
fill ~41 ~3 ~124 ~41 ~4 ~124 stained_hardened_clay 13  
fill ~42 ~3 ~5 ~43 ~3 ~5 stained_hardened_clay 15  
fill ~42 ~3 ~123 ~43 ~3 ~123 stained_hardened_clay 15  
fill ~44 ~3 ~4 ~44 ~3 ~6 log2 13  
fill ~44 ~3 ~122 ~52 ~3 ~122 log2 13  
fill ~44 ~3 ~123 ~44 ~3 ~124 log2 13  
fill ~45 ~3 ~6 ~52 ~3 ~6 log2 13  
fill ~47 ~3 ~4 ~47 ~6 ~4 log2 13  
fill ~47 ~3 ~5 ~47 ~4 ~5 log2 13  
fill ~47 ~3 ~123 ~47 ~4 ~123 log2 13  
fill ~47 ~3 ~124 ~47 ~6 ~124 log2 13  
fill ~48 ~3 ~3 ~48 ~10 ~3 log2 13  
fill ~48 ~3 ~5 ~48 ~4 ~5 stained_hardened_clay 15  
fill ~48 ~3 ~123 ~48 ~4 ~123 stained_hardened_clay 15  
fill ~48 ~3 ~125 ~48 ~10 ~125 log2 13  
fill ~49 ~3 ~4 ~49 ~6 ~4 log2 13  
fill ~49 ~3 ~5 ~49 ~4 ~5 log2 13  
fill ~49 ~3 ~123 ~49 ~4 ~123 log2 13  
fill ~49 ~3 ~124 ~49 ~6 ~124 log2 13 
setblock ~52 ~3 ~5 stained_hardened_clay 15 
setblock ~52 ~3 ~123 stained_hardened_clay 15  
fill ~54 ~3 ~5 ~54 ~5 ~5 stained_hardened_clay 15  
fill ~54 ~3 ~123 ~54 ~5 ~123 stained_hardened_clay 15  
fill ~55 ~3 ~4 ~55 ~4 ~4 stained_hardened_clay 13  
fill ~55 ~3 ~124 ~55 ~4 ~124 stained_hardened_clay 13  
fill ~56 ~3 ~4 ~57 ~3 ~4 stained_hardened_clay 15  
fill ~56 ~3 ~124 ~57 ~3 ~124 stained_hardened_clay 15  
fill ~57 ~3 ~3 ~57 ~6 ~3 wool 13  
fill ~57 ~3 ~125 ~57 ~6 ~125 wool 13   
fill ~58 ~3 ~5 ~59 ~3 ~5 dirt 0  
fill ~58 ~3 ~123 ~59 ~3 ~123 dirt 0  
fill ~59 ~3 ~4 ~59 ~4 ~4 stained_hardened_clay 13  
fill ~59 ~3 ~124 ~59 ~4 ~124 stained_hardened_clay 13  
fill ~60 ~3 ~5 ~68 ~3 ~5 stained_hardened_clay 15  
fill ~60 ~3 ~123 ~68 ~3 ~123 stained_hardened_clay 15  
fill ~64 ~3 ~4 ~64 ~5 ~4 log2 13  
fill ~64 ~3 ~124 ~64 ~5 ~124 log2 13  
fill ~69 ~3 ~4 ~69 ~4 ~4 stained_hardened_clay 13  
fill ~69 ~3 ~5 ~70 ~3 ~5 dirt 0  
fill ~69 ~3 ~123 ~70 ~3 ~123 dirt 0  
fill ~69 ~3 ~124 ~69 ~4 ~124 stained_hardened_clay 13  
fill ~71 ~3 ~3 ~71 ~6 ~3 wool 13  
fill ~71 ~3 ~4 ~72 ~3 ~4 stained_hardened_clay 15  
fill ~71 ~3 ~124 ~72 ~3 ~124 stained_hardened_clay 15  
fill ~71 ~3 ~125 ~71 ~6 ~125 wool 13  
fill ~73 ~3 ~4 ~73 ~4 ~4 stained_hardened_clay 13  
fill ~73 ~3 ~124 ~73 ~4 ~124 stained_hardened_clay 13  
fill ~74 ~3 ~5 ~74 ~5 ~5 stained_hardened_clay 15  
fill ~74 ~3 ~123 ~74 ~5 ~123 stained_hardened_clay 15 
setblock ~76 ~3 ~5 stained_hardened_clay 15  
fill ~76 ~3 ~6 ~84 ~3 ~6 log2 13  
fill ~76 ~3 ~122 ~84 ~3 ~122 log2 13 
setblock ~76 ~3 ~123 stained_hardened_clay 15  
fill ~79 ~3 ~4 ~79 ~6 ~4 log2 13  
fill ~79 ~3 ~5 ~79 ~4 ~5 log2 13  
fill ~79 ~3 ~123 ~79 ~4 ~123 log2 13  
fill ~79 ~3 ~124 ~79 ~6 ~124 log2 13  
fill ~80 ~3 ~3 ~80 ~10 ~3 log2 13  
fill ~80 ~3 ~5 ~80 ~4 ~5 stained_hardened_clay 15  
fill ~80 ~3 ~123 ~80 ~4 ~123 stained_hardened_clay 15  
fill ~80 ~3 ~125 ~80 ~10 ~125 log2 13  
fill ~81 ~3 ~4 ~81 ~6 ~4 log2 13  
fill ~81 ~3 ~5 ~81 ~4 ~5 log2 13  
fill ~81 ~3 ~123 ~81 ~4 ~123 log2 13  
fill ~81 ~3 ~124 ~81 ~6 ~124 log2 13  
fill ~84 ~3 ~4 ~84 ~2 ~4 log2 13  
fill ~84 ~3 ~5 ~84 ~3 ~4 log2 13  
fill ~84 ~3 ~123 ~84 ~3 ~124 log2 13  
fill ~85 ~3 ~5 ~86 ~3 ~5 stained_hardened_clay 15  
fill ~85 ~3 ~123 ~86 ~3 ~123 stained_hardened_clay 15  
fill ~87 ~3 ~4 ~87 ~4 ~4 stained_hardened_clay 13  
fill ~87 ~3 ~124 ~87 ~4 ~124 stained_hardened_clay 13  
fill ~88 ~3 ~4 ~90 ~3 ~4 stained_hardened_clay 15  
fill ~88 ~3 ~124 ~90 ~3 ~124 stained_hardened_clay 15  
fill ~89 ~3 ~3 ~89 ~6 ~3 wool 13  
fill ~89 ~3 ~125 ~89 ~6 ~125 wool 13  
fill ~91 ~3 ~4 ~91 ~4 ~4 stained_hardened_clay 13  
fill ~91 ~3 ~124 ~91 ~4 ~124 stained_hardened_clay 13  
fill ~92 ~3 ~5 ~92 ~5 ~5 stained_hardened_clay 15  
fill ~92 ~3 ~123 ~92 ~5 ~123 stained_hardened_clay 15 
setblock ~94 ~3 ~5 stained_hardened_clay 15  
fill ~94 ~3 ~6 ~102 ~3 ~6 log2 13  
fill ~94 ~3 ~122 ~102 ~3 ~122 log2 13 
setblock ~94 ~3 ~123 stained_hardened_clay 15  
fill ~97 ~3 ~4 ~97 ~6 ~4 log2 13  
fill ~97 ~3 ~5 ~97 ~4 ~5 log2 13  
fill ~97 ~3 ~123 ~97 ~4 ~123 log2 13  
fill ~97 ~3 ~124 ~97 ~6 ~124 log2 13  
fill ~98 ~3 ~3 ~98 ~10 ~3 log2 13  
fill ~98 ~3 ~5 ~98 ~4 ~5 stained_hardened_clay 15  
fill ~98 ~3 ~123 ~98 ~4 ~123 stained_hardened_clay 15  
fill ~98 ~3 ~125 ~98 ~10 ~125 log2 13  
fill ~99 ~3 ~4 ~99 ~6 ~4 log2 13  
fill ~99 ~3 ~5 ~99 ~4 ~5 log2 13  
fill ~99 ~3 ~123 ~99 ~4 ~123 log2 13  
fill ~99 ~3 ~124 ~99 ~6 ~124 log2 13  
fill ~102 ~3 ~4 ~102 ~2 ~4 log2 13  
fill ~102 ~3 ~5 ~102 ~3 ~4 log2 13  
fill ~102 ~3 ~123 ~102 ~3 ~124 log2 13  
fill ~103 ~3 ~5 ~104 ~3 ~5 stained_hardened_clay 15  
fill ~103 ~3 ~123 ~104 ~3 ~123 stained_hardened_clay 15  
fill ~105 ~3 ~4 ~105 ~4 ~4 stained_hardened_clay 13  
fill ~105 ~3 ~124 ~105 ~4 ~124 stained_hardened_clay 13  
fill ~106 ~3 ~4 ~108 ~3 ~4 stained_hardened_clay 15  
fill ~106 ~3 ~124 ~108 ~3 ~124 stained_hardened_clay 15  
fill ~107 ~3 ~3 ~107 ~6 ~3 wool 13  
fill ~107 ~3 ~125 ~107 ~6 ~125 wool 13  
fill ~109 ~3 ~4 ~109 ~4 ~4 stained_hardened_clay 13  
fill ~109 ~3 ~124 ~109 ~4 ~124 stained_hardened_clay 13  
fill ~110 ~3 ~5 ~110 ~5 ~5 stained_hardened_clay 15  
fill ~110 ~3 ~123 ~110 ~5 ~123 stained_hardened_clay 15 
setblock ~112 ~3 ~5 stained_hardened_clay 15  
fill ~112 ~3 ~6 ~120 ~3 ~6 log2 13  
fill ~112 ~3 ~122 ~120 ~3 ~122 log2 13 
setblock ~112 ~3 ~123 stained_hardened_clay 15  
fill ~115 ~3 ~4 ~115 ~6 ~4 log2 13  
fill ~115 ~3 ~5 ~115 ~4 ~5 log2 13  
fill ~115 ~3 ~123 ~115 ~4 ~123 log2 13  
fill ~115 ~3 ~124 ~115 ~6 ~124 log2 13  
fill ~116 ~3 ~3 ~116 ~10 ~3 log2 13  
fill ~116 ~3 ~5 ~116 ~4 ~5 stained_hardened_clay 15  
fill ~116 ~3 ~123 ~116 ~4 ~123 stained_hardened_clay 15  
fill ~116 ~3 ~125 ~116 ~10 ~125 log2 13  
fill ~117 ~3 ~4 ~117 ~6 ~4 log2 13  
fill ~117 ~3 ~5 ~117 ~4 ~5 log2 13  
fill ~117 ~3 ~123 ~117 ~4 ~123 log2 13  
fill ~117 ~3 ~124 ~117 ~6 ~124 log2 13  
fill ~120 ~3 ~4 ~120 ~2 ~4 log2 13  
fill ~120 ~3 ~5 ~120 ~3 ~4 log2 13  
fill ~120 ~3 ~123 ~120 ~3 ~124 log2 13  
fill ~121 ~3 ~5 ~122 ~3 ~5 stained_hardened_clay 15  
fill ~121 ~3 ~123 ~122 ~3 ~123 stained_hardened_clay 15  
fill ~123 ~3 ~4 ~123 ~4 ~4 stained_hardened_clay 13  
fill ~123 ~3 ~6 ~123 ~5 ~6 stained_hardened_clay 15  
fill ~123 ~3 ~8 ~124 ~3 ~8 log2 13  
fill ~123 ~3 ~12 ~123 ~4 ~12 stained_hardened_clay 15 
setblock ~123 ~3 ~16 stained_hardened_clay 15  
fill ~123 ~3 ~18 ~123 ~5 ~18 stained_hardened_clay 15  
fill ~123 ~3 ~24 ~123 ~5 ~24 stained_hardened_clay 15  
fill ~123 ~3 ~26 ~124 ~3 ~26 log2 13  
fill ~123 ~3 ~30 ~123 ~4 ~30 stained_hardened_clay 15 
setblock ~123 ~3 ~34 stained_hardened_clay 15  
fill ~123 ~3 ~36 ~123 ~5 ~36 stained_hardened_clay 15  
fill ~123 ~3 ~42 ~123 ~5 ~42 stained_hardened_clay 15  
fill ~123 ~3 ~44 ~124 ~3 ~44 log2 13  
fill ~123 ~3 ~48 ~123 ~4 ~48 stained_hardened_clay 15 
setblock ~123 ~3 ~52 stained_hardened_clay 15  
fill ~123 ~3 ~54 ~123 ~5 ~54 stained_hardened_clay 15  
fill ~123 ~3 ~60 ~123 ~5 ~60 stained_hardened_clay 15  
fill ~123 ~3 ~68 ~123 ~5 ~68 stained_hardened_clay 15  
fill ~123 ~3 ~74 ~123 ~5 ~74 stained_hardened_clay 15 
setblock ~123 ~3 ~76 stained_hardened_clay 15  
fill ~123 ~3 ~79 ~124 ~3 ~79 log2 13  
fill ~123 ~3 ~80 ~123 ~4 ~80 stained_hardened_clay 15  
fill ~123 ~3 ~81 ~124 ~3 ~81 log2 13 
setblock ~123 ~3 ~84 log2 13  
fill ~123 ~3 ~85 ~123 ~5 ~85 stained_hardened_clay 15  
fill ~123 ~3 ~86 ~123 ~5 ~86 stained_hardened_clay 15  
fill ~123 ~3 ~92 ~123 ~5 ~92 stained_hardened_clay 15 
setblock ~123 ~3 ~94 stained_hardened_clay 15  
fill ~123 ~3 ~97 ~124 ~3 ~97 log2 13  
fill ~123 ~3 ~98 ~123 ~4 ~98 stained_hardened_clay 15  
fill ~123 ~3 ~99 ~124 ~3 ~99 log2 13 
setblock ~123 ~3 ~102 log2 13  
fill ~123 ~3 ~103 ~123 ~5 ~103 stained_hardened_clay 15  
fill ~123 ~3 ~104 ~123 ~5 ~104 stained_hardened_clay 15  
fill ~123 ~3 ~110 ~123 ~5 ~110 stained_hardened_clay 15 
setblock ~123 ~3 ~112 stained_hardened_clay 15  
fill ~123 ~3 ~115 ~124 ~3 ~115 log2 13  
fill ~123 ~3 ~116 ~123 ~4 ~116 stained_hardened_clay 15  
fill ~123 ~3 ~117 ~124 ~3 ~117 log2 13 
setblock ~123 ~3 ~120 log2 13  
fill ~123 ~3 ~121 ~123 ~5 ~121 stained_hardened_clay 15  
fill ~123 ~3 ~122 ~123 ~5 ~122 stained_hardened_clay 15  
fill ~123 ~3 ~124 ~123 ~4 ~124 stained_hardened_clay 13  
fill ~124 ~3 ~11 ~124 ~6 ~11 log2 13  
fill ~124 ~3 ~12 ~125 ~3 ~12 log2 13  
fill ~124 ~3 ~13 ~124 ~6 ~13 log2 13  
fill ~124 ~3 ~19 ~124 ~4 ~19 stained_hardened_clay 13  
fill ~124 ~3 ~29 ~124 ~6 ~29 log2 13  
fill ~124 ~3 ~30 ~125 ~3 ~30 log2 13  
fill ~124 ~3 ~31 ~124 ~6 ~31 log2 13  
fill ~124 ~3 ~37 ~124 ~4 ~37 stained_hardened_clay 13  
fill ~124 ~3 ~47 ~124 ~6 ~47 log2 13  
fill ~124 ~3 ~48 ~125 ~3 ~48 log2 13  
fill ~124 ~3 ~49 ~124 ~6 ~49 log2 13  
fill ~124 ~3 ~55 ~124 ~4 ~55 stained_hardened_clay 13  
fill ~124 ~3 ~64 ~124 ~5 ~64 log2 13  
fill ~124 ~3 ~69 ~124 ~4 ~69 stained_hardened_clay 13  
fill ~124 ~3 ~87 ~124 ~4 ~87 stained_hardened_clay 13  
fill ~124 ~3 ~105 ~124 ~4 ~105 stained_hardened_clay 13  
fill ~124 ~3 ~123 ~124 ~4 ~123 stained_hardened_clay 13  
fill ~125 ~3 ~3 ~125 ~6 ~3 wool 13  
fill ~125 ~3 ~21 ~125 ~6 ~21 wool 13  
fill ~125 ~3 ~39 ~125 ~6 ~39 wool 13  
fill ~125 ~3 ~57 ~125 ~6 ~57 wool 13  
fill ~125 ~3 ~71 ~125 ~6 ~71 wool 13  
fill ~125 ~3 ~80 ~125 ~10 ~80 log2 13  
fill ~125 ~3 ~89 ~125 ~6 ~89 wool 13  
fill ~125 ~3 ~98 ~125 ~10 ~98 log2 13  
fill ~125 ~3 ~107 ~125 ~6 ~107 wool 13  
fill ~125 ~3 ~116 ~125 ~10 ~116 log2 13  
fill ~125 ~3 ~125 ~125 ~6 ~125 wool 13  
fill ~126 ~3 ~2 ~126 ~4 ~2 stained_hardened_clay 5  
fill ~126 ~3 ~126 ~126 ~4 ~126 stained_hardened_clay 5  
fill ~3 ~4 ~11 ~3 ~7 ~11 log2 13  
fill ~3 ~4 ~12 ~3 ~10 ~12 log2 13  
fill ~3 ~4 ~13 ~3 ~7 ~13 log2 13  
fill ~3 ~4 ~29 ~3 ~7 ~29 log2 13  
fill ~3 ~4 ~30 ~3 ~10 ~30 log2 13  
fill ~3 ~4 ~31 ~3 ~7 ~31 log2 13  
fill ~3 ~4 ~47 ~3 ~7 ~47 log2 13  
fill ~3 ~4 ~48 ~3 ~10 ~48 log2 13  
fill ~3 ~4 ~49 ~3 ~7 ~49 log2 13  
fill ~3 ~4 ~79 ~6 ~4 ~79 log2 13  
fill ~3 ~4 ~80 ~3 ~10 ~80 log2 13  
fill ~3 ~4 ~81 ~6 ~4 ~81 log2 13  
fill ~3 ~4 ~97 ~6 ~4 ~97 log2 13  
fill ~3 ~4 ~98 ~3 ~10 ~98 log2 13  
fill ~3 ~4 ~99 ~6 ~4 ~99 log2 13  
fill ~3 ~4 ~115 ~6 ~4 ~115 log2 13  
fill ~3 ~4 ~116 ~3 ~10 ~116 log2 13  
fill ~3 ~4 ~117 ~6 ~4 ~117 log2 13  
fill ~4 ~4 ~4 ~4 ~6 ~4 stained_hardened_clay 13  
fill ~4 ~4 ~20 ~4 ~6 ~20 stained_hardened_clay 13  
fill ~4 ~4 ~22 ~4 ~6 ~22 stained_hardened_clay 13  
fill ~4 ~4 ~38 ~4 ~6 ~38 stained_hardened_clay 13  
fill ~4 ~4 ~40 ~4 ~6 ~40 stained_hardened_clay 13  
fill ~4 ~4 ~56 ~4 ~6 ~56 stained_hardened_clay 13  
fill ~4 ~4 ~58 ~4 ~6 ~58 stained_hardened_clay 13  
fill ~4 ~4 ~63 ~4 ~6 ~63 log2 13  
fill ~4 ~4 ~65 ~4 ~6 ~65 log2 13  
fill ~4 ~4 ~70 ~4 ~6 ~70 stained_hardened_clay 13  
fill ~4 ~4 ~72 ~4 ~6 ~72 stained_hardened_clay 13  
fill ~4 ~4 ~88 ~4 ~6 ~88 stained_hardened_clay 13  
fill ~4 ~4 ~90 ~4 ~6 ~90 stained_hardened_clay 13  
fill ~4 ~4 ~106 ~4 ~6 ~106 stained_hardened_clay 13  
fill ~4 ~4 ~108 ~4 ~6 ~108 stained_hardened_clay 13  
fill ~4 ~4 ~124 ~4 ~6 ~124 stained_hardened_clay 13  
fill ~5 ~4 ~8 ~5 ~4 ~9 stained_hardened_clay 15 
setblock ~5 ~4 ~15 stained_hardened_clay 15  
fill ~5 ~4 ~26 ~5 ~4 ~27 stained_hardened_clay 15 
setblock ~5 ~4 ~33 stained_hardened_clay 15  
fill ~5 ~4 ~44 ~5 ~4 ~45 stained_hardened_clay 15 
setblock ~5 ~4 ~51 stained_hardened_clay 15 
setblock ~5 ~4 ~77 stained_hardened_clay 15  
fill ~5 ~4 ~83 ~5 ~4 ~86 stained_hardened_clay 15 
setblock ~5 ~4 ~95 stained_hardened_clay 15  
fill ~5 ~4 ~101 ~5 ~4 ~104 stained_hardened_clay 15 
setblock ~5 ~4 ~113 stained_hardened_clay 15  
fill ~5 ~4 ~119 ~5 ~4 ~122 stained_hardened_clay 15  
fill ~6 ~4 ~5 ~9 ~4 ~5 stained_hardened_clay 15  
fill ~6 ~4 ~123 ~9 ~4 ~123 stained_hardened_clay 15  
fill ~8 ~4 ~6 ~16 ~4 ~6 log2 13  
fill ~8 ~4 ~122 ~16 ~4 ~122 log2 13  
fill ~11 ~4 ~3 ~11 ~7 ~3 log2 13  
fill ~11 ~4 ~125 ~11 ~7 ~125 log2 13  
fill ~13 ~4 ~3 ~13 ~7 ~3 log2 13  
fill ~13 ~4 ~125 ~13 ~7 ~125 log2 13 
setblock ~15 ~4 ~5 stained_hardened_clay 15 
setblock ~15 ~4 ~123 stained_hardened_clay 15  
fill ~20 ~4 ~4 ~20 ~6 ~4 stained_hardened_clay 13  
fill ~20 ~4 ~124 ~20 ~6 ~124 stained_hardened_clay 13  
fill ~21 ~4 ~4 ~21 ~6 ~4 stained_hardened_clay 15  
fill ~21 ~4 ~124 ~21 ~6 ~124 stained_hardened_clay 15  
fill ~22 ~4 ~4 ~22 ~6 ~4 stained_hardened_clay 13  
fill ~22 ~4 ~124 ~22 ~6 ~124 stained_hardened_clay 13  
fill ~24 ~4 ~5 ~27 ~4 ~5 stained_hardened_clay 15  
fill ~24 ~4 ~123 ~27 ~4 ~123 stained_hardened_clay 15  
fill ~26 ~4 ~6 ~34 ~4 ~6 log2 13  
fill ~26 ~4 ~122 ~34 ~4 ~122 log2 13  
fill ~29 ~4 ~3 ~29 ~7 ~3 log2 13  
fill ~29 ~4 ~125 ~29 ~7 ~125 log2 13  
fill ~31 ~4 ~3 ~31 ~7 ~3 log2 13  
fill ~31 ~4 ~125 ~31 ~7 ~125 log2 13 
setblock ~33 ~4 ~5 stained_hardened_clay 15 
setblock ~33 ~4 ~123 stained_hardened_clay 15  
fill ~38 ~4 ~4 ~38 ~6 ~4 stained_hardened_clay 13  
fill ~38 ~4 ~124 ~38 ~6 ~124 stained_hardened_clay 13  
fill ~39 ~4 ~4 ~39 ~6 ~4 stained_hardened_clay 15  
fill ~39 ~4 ~124 ~39 ~6 ~124 stained_hardened_clay 15  
fill ~40 ~4 ~4 ~40 ~6 ~4 stained_hardened_clay 13  
fill ~40 ~4 ~124 ~40 ~6 ~124 stained_hardened_clay 13  
fill ~42 ~4 ~5 ~45 ~4 ~5 stained_hardened_clay 15  
fill ~42 ~4 ~123 ~45 ~4 ~123 stained_hardened_clay 15  
fill ~44 ~4 ~6 ~52 ~4 ~6 log2 13  
fill ~44 ~4 ~122 ~52 ~4 ~122 log2 13  
fill ~47 ~4 ~3 ~47 ~7 ~3 log2 13  
fill ~47 ~4 ~125 ~47 ~7 ~125 log2 13  
fill ~49 ~4 ~3 ~49 ~7 ~3 log2 13  
fill ~49 ~4 ~125 ~49 ~7 ~125 log2 13 
setblock ~51 ~4 ~5 stained_hardened_clay 15 
setblock ~51 ~4 ~123 stained_hardened_clay 15  
fill ~56 ~4 ~4 ~56 ~6 ~4 stained_hardened_clay 13  
fill ~56 ~4 ~124 ~56 ~6 ~124 stained_hardened_clay 13  
fill ~57 ~4 ~4 ~57 ~6 ~4 stained_hardened_clay 15  
fill ~57 ~4 ~124 ~57 ~6 ~124 stained_hardened_clay 15  
fill ~58 ~4 ~4 ~58 ~6 ~4 stained_hardened_clay 13  
fill ~58 ~4 ~5 ~59 ~4 ~5 dirt 0  
fill ~58 ~4 ~123 ~59 ~4 ~123 dirt 0  
fill ~58 ~4 ~124 ~58 ~6 ~124 stained_hardened_clay 13  
fill ~60 ~4 ~5 ~68 ~4 ~5 stained_hardened_clay 15  
fill ~60 ~4 ~123 ~68 ~4 ~123 stained_hardened_clay 15  
fill ~63 ~4 ~4 ~63 ~6 ~4 log2 13  
fill ~63 ~4 ~124 ~63 ~6 ~124 log2 13  
fill ~65 ~4 ~4 ~65 ~6 ~4 log2 13  
fill ~65 ~4 ~124 ~65 ~6 ~124 log2 13  
fill ~69 ~4 ~5 ~70 ~4 ~5 dirt 0  
fill ~69 ~4 ~123 ~70 ~4 ~123 dirt 0  
fill ~70 ~4 ~4 ~70 ~6 ~4 stained_hardened_clay 13  
fill ~70 ~4 ~124 ~70 ~6 ~124 stained_hardened_clay 13  
fill ~71 ~4 ~4 ~71 ~6 ~4 stained_hardened_clay 15  
fill ~71 ~4 ~124 ~71 ~6 ~124 stained_hardened_clay 15  
fill ~72 ~4 ~4 ~72 ~6 ~4 stained_hardened_clay 13  
fill ~72 ~4 ~124 ~72 ~6 ~124 stained_hardened_clay 13  
fill ~76 ~4 ~6 ~84 ~4 ~6 log2 13  
fill ~76 ~4 ~122 ~84 ~4 ~122 log2 13 
setblock ~77 ~4 ~5 stained_hardened_clay 15 
setblock ~77 ~4 ~123 stained_hardened_clay 15  
fill ~79 ~4 ~3 ~79 ~7 ~3 log2 13  
fill ~79 ~4 ~125 ~79 ~7 ~125 log2 13  
fill ~81 ~4 ~3 ~81 ~7 ~3 log2 13  
fill ~81 ~4 ~125 ~81 ~7 ~125 log2 13  
fill ~83 ~4 ~5 ~86 ~4 ~5 stained_hardened_clay 15  
fill ~83 ~4 ~123 ~86 ~4 ~123 stained_hardened_clay 15  
fill ~88 ~4 ~4 ~88 ~6 ~4 stained_hardened_clay 13  
fill ~88 ~4 ~124 ~88 ~6 ~124 stained_hardened_clay 13  
fill ~89 ~4 ~4 ~89 ~6 ~4 stained_hardened_clay 15  
fill ~89 ~4 ~124 ~89 ~6 ~124 stained_hardened_clay 15  
fill ~90 ~4 ~4 ~90 ~6 ~4 stained_hardened_clay 13  
fill ~90 ~4 ~124 ~90 ~6 ~124 stained_hardened_clay 13  
fill ~94 ~4 ~6 ~102 ~4 ~6 log2 13  
fill ~94 ~4 ~122 ~102 ~4 ~122 log2 13 
setblock ~95 ~4 ~5 stained_hardened_clay 15 
setblock ~95 ~4 ~123 stained_hardened_clay 15  
fill ~97 ~4 ~3 ~97 ~7 ~3 log2 13  
fill ~97 ~4 ~125 ~97 ~7 ~125 log2 13  
fill ~99 ~4 ~3 ~99 ~7 ~3 log2 13  
fill ~99 ~4 ~125 ~99 ~7 ~125 log2 13  
fill ~101 ~4 ~5 ~104 ~4 ~5 stained_hardened_clay 15  
fill ~101 ~4 ~123 ~104 ~4 ~123 stained_hardened_clay 15  
fill ~106 ~4 ~4 ~106 ~6 ~4 stained_hardened_clay 13  
fill ~106 ~4 ~124 ~106 ~6 ~124 stained_hardened_clay 13  
fill ~107 ~4 ~4 ~107 ~6 ~4 stained_hardened_clay 15  
fill ~107 ~4 ~124 ~107 ~6 ~124 stained_hardened_clay 15  
fill ~108 ~4 ~4 ~108 ~6 ~4 stained_hardened_clay 13  
fill ~108 ~4 ~124 ~108 ~6 ~124 stained_hardened_clay 13  
fill ~112 ~4 ~6 ~120 ~4 ~6 log2 13  
fill ~112 ~4 ~122 ~120 ~4 ~122 log2 13 
setblock ~113 ~4 ~5 stained_hardened_clay 15 
setblock ~113 ~4 ~123 stained_hardened_clay 15  
fill ~115 ~4 ~3 ~115 ~7 ~3 log2 13  
fill ~115 ~4 ~125 ~115 ~7 ~125 log2 13  
fill ~117 ~4 ~3 ~117 ~7 ~3 log2 13  
fill ~117 ~4 ~125 ~117 ~7 ~125 log2 13  
fill ~119 ~4 ~5 ~122 ~4 ~5 stained_hardened_clay 15  
fill ~119 ~4 ~123 ~122 ~4 ~123 stained_hardened_clay 15  
fill ~123 ~4 ~8 ~123 ~4 ~9 stained_hardened_clay 15 
setblock ~123 ~4 ~15 stained_hardened_clay 15  
fill ~123 ~4 ~26 ~123 ~4 ~27 stained_hardened_clay 15 
setblock ~123 ~4 ~33 stained_hardened_clay 15  
fill ~123 ~4 ~44 ~123 ~4 ~45 stained_hardened_clay 15 
setblock ~123 ~4 ~51 stained_hardened_clay 15 
setblock ~123 ~4 ~77 stained_hardened_clay 15  
fill ~123 ~4 ~79 ~125 ~4 ~79 log2 13  
fill ~123 ~4 ~81 ~125 ~4 ~81 log2 13  
fill ~123 ~4 ~83 ~123 ~4 ~86 stained_hardened_clay 15 
setblock ~123 ~4 ~95 stained_hardened_clay 15  
fill ~123 ~4 ~97 ~125 ~4 ~97 log2 13  
fill ~123 ~4 ~99 ~125 ~4 ~99 log2 13  
fill ~123 ~4 ~101 ~123 ~4 ~104 stained_hardened_clay 15 
setblock ~123 ~4 ~113 stained_hardened_clay 15  
fill ~123 ~4 ~115 ~125 ~4 ~115 log2 13  
fill ~123 ~4 ~117 ~125 ~4 ~117 log2 13  
fill ~123 ~4 ~119 ~123 ~4 ~122 stained_hardened_clay 15  
fill ~124 ~4 ~4 ~124 ~6 ~4 stained_hardened_clay 13  
fill ~124 ~4 ~20 ~124 ~6 ~20 stained_hardened_clay 13  
fill ~124 ~4 ~22 ~124 ~6 ~22 stained_hardened_clay 13  
fill ~124 ~4 ~38 ~124 ~6 ~38 stained_hardened_clay 13  
fill ~124 ~4 ~40 ~124 ~6 ~40 stained_hardened_clay 13  
fill ~124 ~4 ~56 ~124 ~6 ~56 stained_hardened_clay 13  
fill ~124 ~4 ~58 ~124 ~6 ~58 stained_hardened_clay 13  
fill ~124 ~4 ~63 ~124 ~6 ~63 log2 13  
fill ~124 ~4 ~65 ~124 ~6 ~65 log2 13  
fill ~124 ~4 ~70 ~124 ~6 ~70 stained_hardened_clay 13  
fill ~124 ~4 ~72 ~124 ~6 ~72 stained_hardened_clay 13  
fill ~124 ~4 ~88 ~124 ~6 ~88 stained_hardened_clay 13  
fill ~124 ~4 ~90 ~124 ~6 ~90 stained_hardened_clay 13  
fill ~124 ~4 ~106 ~124 ~6 ~106 stained_hardened_clay 13  
fill ~124 ~4 ~108 ~124 ~6 ~108 stained_hardened_clay 13  
fill ~124 ~4 ~124 ~124 ~6 ~124 stained_hardened_clay 13  
fill ~125 ~4 ~11 ~125 ~7 ~11 log2 13  
fill ~125 ~4 ~12 ~125 ~10 ~12 log2 13  
fill ~125 ~4 ~13 ~125 ~7 ~13 log2 13  
fill ~125 ~4 ~29 ~125 ~7 ~29 log2 13  
fill ~125 ~4 ~30 ~125 ~10 ~30 log2 13  
fill ~125 ~4 ~31 ~125 ~7 ~31 log2 13  
fill ~125 ~4 ~47 ~125 ~7 ~47 log2 13  
fill ~125 ~4 ~48 ~125 ~10 ~48 log2 13  
fill ~125 ~4 ~49 ~125 ~7 ~49 log2 13  
fill ~2 ~5 ~12 ~2 ~8 ~12 log2 13  
fill ~2 ~5 ~30 ~2 ~8 ~30 log2 13  
fill ~2 ~5 ~48 ~2 ~8 ~48 log2 13  
fill ~2 ~5 ~80 ~2 ~8 ~80 log2 13  
fill ~2 ~5 ~98 ~2 ~8 ~98 log2 13  
fill ~2 ~5 ~116 ~2 ~8 ~116 log2 13  
fill ~3 ~5 ~8 ~6 ~5 ~8 log2 13  
fill ~3 ~5 ~16 ~6 ~5 ~16 log2 13  
fill ~3 ~5 ~26 ~6 ~5 ~26 log2 13  
fill ~3 ~5 ~34 ~6 ~5 ~34 log2 13  
fill ~3 ~5 ~44 ~6 ~5 ~44 log2 13  
fill ~3 ~5 ~52 ~6 ~5 ~52 log2 13  
fill ~3 ~5 ~60 ~4 ~5 ~60 log2 13  
fill ~3 ~5 ~64 ~3 ~10 ~64 log2 13  
fill ~3 ~5 ~68 ~4 ~5 ~68 log2 13  
fill ~3 ~5 ~76 ~6 ~5 ~76 log2 13  
fill ~3 ~5 ~79 ~4 ~5 ~79 log2 13  
fill ~3 ~5 ~81 ~4 ~5 ~81 log2 13  
fill ~3 ~5 ~84 ~6 ~5 ~84 log2 13  
fill ~3 ~5 ~94 ~6 ~5 ~94 log2 13  
fill ~3 ~5 ~97 ~4 ~5 ~97 log2 13  
fill ~3 ~5 ~99 ~4 ~5 ~99 log2 13  
fill ~3 ~5 ~102 ~6 ~5 ~102 log2 13  
fill ~3 ~5 ~112 ~6 ~5 ~112 log2 13  
fill ~3 ~5 ~115 ~4 ~5 ~115 log2 13  
fill ~3 ~5 ~117 ~4 ~5 ~117 log2 13  
fill ~3 ~5 ~120 ~6 ~5 ~120 log2 13  
fill ~5 ~5 ~5 ~7 ~5 ~5 stained_hardened_clay 15 
setblock ~5 ~5 ~10 log2 13 
setblock ~5 ~5 ~11 stained_hardened_clay 15 
setblock ~5 ~5 ~12 log2 13 
setblock ~5 ~5 ~13 stained_hardened_clay 15 
setblock ~5 ~5 ~14 log2 13 
setblock ~5 ~5 ~19 stained_hardened_clay 15 
setblock ~5 ~5 ~23 stained_hardened_clay 15 
setblock ~5 ~5 ~28 log2 13 
setblock ~5 ~5 ~29 stained_hardened_clay 15 
setblock ~5 ~5 ~30 log2 13 
setblock ~5 ~5 ~31 stained_hardened_clay 15 
setblock ~5 ~5 ~32 log2 13 
setblock ~5 ~5 ~37 stained_hardened_clay 15 
setblock ~5 ~5 ~41 stained_hardened_clay 15 
setblock ~5 ~5 ~46 log2 13 
setblock ~5 ~5 ~47 stained_hardened_clay 15 
setblock ~5 ~5 ~48 log2 13 
setblock ~5 ~5 ~49 stained_hardened_clay 15 
setblock ~5 ~5 ~50 log2 13 
setblock ~5 ~5 ~55 stained_hardened_clay 15  
fill ~5 ~5 ~56 ~5 ~5 ~58 dirt 0 
setblock ~5 ~5 ~59 stained_hardened_clay 15 
setblock ~5 ~5 ~69 stained_hardened_clay 15  
fill ~5 ~5 ~71 ~5 ~5 ~72 dirt 0 
setblock ~5 ~5 ~73 stained_hardened_clay 15 
setblock ~5 ~5 ~78 log2 13 
setblock ~5 ~5 ~79 stained_hardened_clay 15 
setblock ~5 ~5 ~80 log2 13 
setblock ~5 ~5 ~81 stained_hardened_clay 15 
setblock ~5 ~5 ~82 log2 13 
setblock ~5 ~5 ~87 stained_hardened_clay 15 
setblock ~5 ~5 ~91 stained_hardened_clay 15 
setblock ~5 ~5 ~96 log2 13 
setblock ~5 ~5 ~97 stained_hardened_clay 15 
setblock ~5 ~5 ~98 log2 13 
setblock ~5 ~5 ~99 stained_hardened_clay 15 
setblock ~5 ~5 ~100 log2 13 
setblock ~5 ~5 ~105 stained_hardened_clay 15 
setblock ~5 ~5 ~109 stained_hardened_clay 15 
setblock ~5 ~5 ~114 log2 13 
setblock ~5 ~5 ~115 stained_hardened_clay 15 
setblock ~5 ~5 ~116 log2 13 
setblock ~5 ~5 ~117 stained_hardened_clay 15 
setblock ~5 ~5 ~118 log2 13  
fill ~5 ~5 ~123 ~7 ~5 ~123 stained_hardened_clay 15  
fill ~6 ~5 ~58 ~123 ~5 ~58 dirt 0  
fill ~6 ~5 ~59 ~122 ~5 ~59 dirt 0  
fill ~6 ~5 ~60 ~122 ~5 ~60 dirt 0  
fill ~6 ~5 ~61 ~122 ~5 ~61 dirt 0  
fill ~6 ~5 ~62 ~121 ~5 ~62 dirt 0  
fill ~6 ~5 ~63 ~122 ~5 ~63 dirt 0  
fill ~6 ~5 ~64 ~122 ~5 ~64 dirt 0  
fill ~6 ~5 ~65 ~122 ~5 ~65 dirt 0  
fill ~6 ~5 ~67 ~122 ~5 ~67 dirt 0  
fill ~6 ~5 ~68 ~122 ~5 ~68 dirt 0  
fill ~6 ~5 ~69 ~122 ~5 ~69 dirt 0  
fill ~6 ~5 ~70 ~123 ~5 ~70 dirt 0  
fill ~7 ~5 ~7 ~121 ~5 ~7 dirt 0  
fill ~7 ~5 ~8 ~121 ~5 ~8 dirt 0  
fill ~7 ~5 ~9 ~121 ~5 ~9 dirt 0  
fill ~7 ~5 ~10 ~121 ~5 ~10 dirt 0  
fill ~7 ~5 ~11 ~121 ~5 ~11 dirt 0  
fill ~7 ~5 ~12 ~121 ~5 ~12 dirt 0  
fill ~7 ~5 ~13 ~121 ~5 ~13 dirt 0  
fill ~7 ~5 ~14 ~121 ~5 ~14 dirt 0  
fill ~7 ~5 ~15 ~121 ~5 ~15 dirt 0  
fill ~7 ~5 ~16 ~121 ~5 ~16 dirt 0  
fill ~7 ~5 ~17 ~121 ~5 ~17 dirt 0  
fill ~7 ~5 ~18 ~121 ~5 ~18 dirt 0  
fill ~7 ~5 ~19 ~121 ~5 ~19 dirt 0  
fill ~7 ~5 ~20 ~121 ~5 ~20 dirt 0  
fill ~7 ~5 ~21 ~121 ~5 ~21 dirt 0  
fill ~7 ~5 ~22 ~121 ~5 ~22 dirt 0  
fill ~7 ~5 ~23 ~121 ~5 ~23 dirt 0  
fill ~7 ~5 ~24 ~121 ~5 ~24 dirt 0  
fill ~7 ~5 ~25 ~121 ~5 ~25 dirt 0  
fill ~7 ~5 ~26 ~121 ~5 ~26 dirt 0  
fill ~7 ~5 ~27 ~121 ~5 ~27 dirt 0  
fill ~7 ~5 ~28 ~121 ~5 ~28 dirt 0  
fill ~7 ~5 ~29 ~121 ~5 ~29 dirt 0  
fill ~7 ~5 ~30 ~121 ~5 ~30 dirt 0  
fill ~7 ~5 ~31 ~121 ~5 ~31 dirt 0  
fill ~7 ~5 ~32 ~121 ~5 ~32 dirt 0  
fill ~7 ~5 ~33 ~121 ~5 ~33 dirt 0  
fill ~7 ~5 ~34 ~121 ~5 ~34 dirt 0  
fill ~7 ~5 ~35 ~121 ~5 ~35 dirt 0  
fill ~7 ~5 ~36 ~121 ~5 ~36 dirt 0  
fill ~7 ~5 ~37 ~121 ~5 ~37 dirt 0  
fill ~7 ~5 ~38 ~121 ~5 ~38 dirt 0  
fill ~7 ~5 ~39 ~121 ~5 ~39 dirt 0  
fill ~7 ~5 ~40 ~121 ~5 ~40 dirt 0  
fill ~7 ~5 ~41 ~121 ~5 ~41 dirt 0  
fill ~7 ~5 ~42 ~121 ~5 ~42 dirt 0  
fill ~7 ~5 ~43 ~121 ~5 ~43 dirt 0  
fill ~7 ~5 ~44 ~121 ~5 ~44 dirt 0  
fill ~7 ~5 ~45 ~121 ~5 ~45 dirt 0  
fill ~7 ~5 ~46 ~121 ~5 ~46 dirt 0  
fill ~7 ~5 ~47 ~121 ~5 ~47 dirt 0  
fill ~7 ~5 ~48 ~121 ~5 ~48 dirt 0  
fill ~7 ~5 ~49 ~121 ~5 ~49 dirt 0  
fill ~7 ~5 ~50 ~121 ~5 ~50 dirt 0  
fill ~7 ~5 ~51 ~121 ~5 ~51 dirt 0  
fill ~7 ~5 ~52 ~121 ~5 ~52 dirt 0  
fill ~7 ~5 ~53 ~121 ~5 ~53 dirt 0  
fill ~7 ~5 ~54 ~121 ~5 ~54 dirt 0  
fill ~7 ~5 ~55 ~121 ~5 ~55 dirt 0  
fill ~7 ~5 ~56 ~121 ~5 ~56 dirt 0  
fill ~7 ~5 ~57 ~121 ~5 ~57 dirt 0  
fill ~7 ~5 ~66 ~122 ~5 ~66 dirt 0  
fill ~7 ~5 ~71 ~121 ~5 ~71 dirt 0  
fill ~7 ~5 ~72 ~121 ~5 ~72 dirt 0  
fill ~7 ~5 ~73 ~121 ~5 ~73 dirt 0  
fill ~7 ~5 ~74 ~121 ~5 ~74 dirt 0  
fill ~7 ~5 ~75 ~121 ~5 ~75 dirt 0  
fill ~7 ~5 ~76 ~121 ~5 ~76 dirt 0  
fill ~7 ~5 ~77 ~121 ~5 ~77 dirt 0  
fill ~7 ~5 ~78 ~121 ~5 ~78 dirt 0  
fill ~7 ~5 ~79 ~121 ~5 ~79 dirt 0  
fill ~7 ~5 ~80 ~121 ~5 ~80 dirt 0  
fill ~7 ~5 ~81 ~121 ~5 ~81 dirt 0  
fill ~7 ~5 ~82 ~121 ~5 ~82 dirt 0  
fill ~7 ~5 ~83 ~121 ~5 ~83 dirt 0  
fill ~7 ~5 ~84 ~121 ~5 ~84 dirt 0  
fill ~7 ~5 ~85 ~121 ~5 ~85 dirt 0  
fill ~7 ~5 ~86 ~121 ~5 ~86 dirt 0  
fill ~7 ~5 ~87 ~121 ~5 ~87 dirt 0  
fill ~7 ~5 ~88 ~121 ~5 ~88 dirt 0  
fill ~7 ~5 ~89 ~121 ~5 ~89 dirt 0  
fill ~7 ~5 ~90 ~121 ~5 ~90 dirt 0  
fill ~7 ~5 ~91 ~121 ~5 ~91 dirt 0  
fill ~7 ~5 ~92 ~121 ~5 ~92 dirt 0  
fill ~7 ~5 ~93 ~121 ~5 ~93 dirt 0  
fill ~7 ~5 ~94 ~121 ~5 ~94 dirt 0  
fill ~7 ~5 ~95 ~121 ~5 ~95 dirt 0  
fill ~7 ~5 ~96 ~121 ~5 ~96 dirt 0  
fill ~7 ~5 ~97 ~121 ~5 ~97 dirt 0  
fill ~7 ~5 ~98 ~121 ~5 ~98 dirt 0  
fill ~7 ~5 ~99 ~121 ~5 ~99 dirt 0  
fill ~7 ~5 ~100 ~121 ~5 ~100 dirt 0  
fill ~7 ~5 ~101 ~121 ~5 ~101 dirt 0  
fill ~7 ~5 ~102 ~121 ~5 ~102 dirt 0  
fill ~7 ~5 ~103 ~121 ~5 ~103 dirt 0  
fill ~7 ~5 ~104 ~121 ~5 ~104 dirt 0  
fill ~7 ~5 ~105 ~121 ~5 ~105 dirt 0  
fill ~7 ~5 ~106 ~121 ~5 ~106 dirt 0  
fill ~7 ~5 ~107 ~121 ~5 ~107 dirt 0  
fill ~7 ~5 ~108 ~121 ~5 ~108 dirt 0  
fill ~7 ~5 ~109 ~121 ~5 ~109 dirt 0  
fill ~7 ~5 ~110 ~121 ~5 ~110 dirt 0  
fill ~7 ~5 ~111 ~121 ~5 ~111 dirt 0  
fill ~7 ~5 ~112 ~121 ~5 ~112 dirt 0  
fill ~7 ~5 ~113 ~121 ~5 ~113 dirt 0  
fill ~7 ~5 ~114 ~121 ~5 ~114 dirt 0  
fill ~7 ~5 ~115 ~121 ~5 ~115 dirt 0  
fill ~7 ~5 ~116 ~121 ~5 ~116 dirt 0  
fill ~7 ~5 ~117 ~121 ~5 ~117 dirt 0  
fill ~7 ~5 ~118 ~121 ~5 ~118 dirt 0  
fill ~7 ~5 ~119 ~121 ~5 ~119 dirt 0  
fill ~7 ~5 ~120 ~121 ~5 ~120 dirt 0  
fill ~7 ~5 ~121 ~121 ~5 ~121 dirt 0  
fill ~8 ~5 ~3 ~8 ~7 ~3 log2 13  
fill ~8 ~5 ~4 ~8 ~5 ~6 log2 13  
fill ~8 ~5 ~122 ~16 ~5 ~122 log2 13  
fill ~8 ~5 ~123 ~8 ~5 ~125 log2 13  
fill ~9 ~5 ~6 ~16 ~5 ~6 log2 13 
setblock ~10 ~5 ~5 log2 13 
setblock ~10 ~5 ~123 log2 13 
setblock ~11 ~5 ~5 stained_hardened_clay 15 
setblock ~11 ~5 ~123 stained_hardened_clay 15  
fill ~12 ~5 ~2 ~12 ~8 ~2 log2 13 
setblock ~12 ~5 ~5 log2 13 
setblock ~12 ~5 ~123 log2 13  
fill ~12 ~5 ~126 ~12 ~8 ~126 log2 13 
setblock ~13 ~5 ~5 stained_hardened_clay 15 
setblock ~13 ~5 ~123 stained_hardened_clay 15 
setblock ~14 ~5 ~5 log2 13 
setblock ~14 ~5 ~123 log2 13  
fill ~16 ~5 ~3 ~16 ~7 ~3 log2 13  
fill ~16 ~5 ~4 ~16 ~5 ~6 log2 13  
fill ~16 ~5 ~123 ~16 ~5 ~125 log2 13 
setblock ~19 ~5 ~5 stained_hardened_clay 15 
setblock ~19 ~5 ~123 stained_hardened_clay 15  
fill ~23 ~5 ~5 ~25 ~5 ~5 stained_hardened_clay 15  
fill ~23 ~5 ~123 ~25 ~5 ~123 stained_hardened_clay 15  
fill ~26 ~5 ~3 ~26 ~7 ~3 log2 13  
fill ~26 ~5 ~4 ~26 ~5 ~6 log2 13  
fill ~26 ~5 ~122 ~34 ~5 ~122 log2 13  
fill ~26 ~5 ~123 ~26 ~5 ~125 log2 13  
fill ~27 ~5 ~6 ~34 ~5 ~6 log2 13 
setblock ~28 ~5 ~5 log2 13 
setblock ~28 ~5 ~123 log2 13 
setblock ~29 ~5 ~5 stained_hardened_clay 15 
setblock ~29 ~5 ~123 stained_hardened_clay 15  
fill ~30 ~5 ~2 ~30 ~8 ~2 log2 13 
setblock ~30 ~5 ~5 log2 13 
setblock ~30 ~5 ~123 log2 13  
fill ~30 ~5 ~126 ~30 ~8 ~126 log2 13 
setblock ~31 ~5 ~5 stained_hardened_clay 15 
setblock ~31 ~5 ~123 stained_hardened_clay 15 
setblock ~32 ~5 ~5 log2 13 
setblock ~32 ~5 ~123 log2 13  
fill ~34 ~5 ~3 ~34 ~7 ~3 log2 13  
fill ~34 ~5 ~4 ~34 ~5 ~6 log2 13  
fill ~34 ~5 ~123 ~34 ~5 ~125 log2 13 
setblock ~37 ~5 ~5 stained_hardened_clay 15 
setblock ~37 ~5 ~123 stained_hardened_clay 15  
fill ~41 ~5 ~5 ~43 ~5 ~5 stained_hardened_clay 15  
fill ~41 ~5 ~123 ~43 ~5 ~123 stained_hardened_clay 15  
fill ~44 ~5 ~3 ~44 ~7 ~3 log2 13  
fill ~44 ~5 ~4 ~44 ~5 ~6 log2 13  
fill ~44 ~5 ~122 ~52 ~5 ~122 log2 13  
fill ~44 ~5 ~123 ~44 ~5 ~125 log2 13  
fill ~45 ~5 ~6 ~52 ~5 ~6 log2 13 
setblock ~46 ~5 ~5 log2 13 
setblock ~46 ~5 ~123 log2 13 
setblock ~47 ~5 ~5 stained_hardened_clay 15 
setblock ~47 ~5 ~123 stained_hardened_clay 15  
fill ~48 ~5 ~2 ~48 ~8 ~2 log2 13 
setblock ~48 ~5 ~5 log2 13 
setblock ~48 ~5 ~123 log2 13  
fill ~48 ~5 ~126 ~48 ~8 ~126 log2 13 
setblock ~49 ~5 ~5 stained_hardened_clay 15 
setblock ~49 ~5 ~123 stained_hardened_clay 15 
setblock ~50 ~5 ~5 log2 13 
setblock ~50 ~5 ~123 log2 13  
fill ~52 ~5 ~3 ~52 ~7 ~3 log2 13  
fill ~52 ~5 ~4 ~52 ~5 ~6 log2 13  
fill ~52 ~5 ~123 ~52 ~5 ~125 log2 13 
setblock ~55 ~5 ~5 stained_hardened_clay 15 
setblock ~55 ~5 ~123 stained_hardened_clay 15  
fill ~56 ~5 ~5 ~58 ~5 ~5 dirt 0  
fill ~56 ~5 ~123 ~58 ~5 ~123 dirt 0  
fill ~58 ~5 ~6 ~61 ~5 ~6 dirt 0  
fill ~58 ~5 ~122 ~65 ~5 ~122 dirt 0  
fill ~59 ~5 ~5 ~69 ~5 ~5 stained_hardened_clay 15  
fill ~59 ~5 ~123 ~69 ~5 ~123 stained_hardened_clay 15  
fill ~60 ~5 ~3 ~60 ~7 ~3 log2 13  
fill ~60 ~5 ~4 ~60 ~5 ~3 log2 13  
fill ~60 ~5 ~124 ~60 ~5 ~125 log2 13  
fill ~63 ~5 ~6 ~70 ~5 ~6 dirt 0  
fill ~64 ~5 ~3 ~64 ~10 ~3 log2 13  
fill ~64 ~5 ~125 ~64 ~10 ~125 log2 13  
fill ~67 ~5 ~122 ~70 ~5 ~122 dirt 0  
fill ~68 ~5 ~3 ~68 ~7 ~3 log2 13  
fill ~68 ~5 ~4 ~68 ~5 ~3 log2 13  
fill ~68 ~5 ~124 ~68 ~5 ~125 log2 13  
fill ~70 ~5 ~5 ~72 ~5 ~5 dirt 0  
fill ~70 ~5 ~123 ~72 ~5 ~123 dirt 0 
setblock ~73 ~5 ~5 stained_hardened_clay 15 
setblock ~73 ~5 ~123 stained_hardened_clay 15  
fill ~76 ~5 ~3 ~76 ~7 ~3 log2 13  
fill ~76 ~5 ~4 ~76 ~5 ~6 log2 13  
fill ~76 ~5 ~122 ~84 ~5 ~122 log2 13  
fill ~76 ~5 ~123 ~76 ~5 ~125 log2 13  
fill ~77 ~5 ~6 ~84 ~5 ~6 log2 13 
setblock ~78 ~5 ~5 log2 13 
setblock ~78 ~5 ~123 log2 13 
setblock ~79 ~5 ~5 stained_hardened_clay 15 
setblock ~79 ~5 ~123 stained_hardened_clay 15  
fill ~80 ~5 ~2 ~80 ~8 ~2 log2 13 
setblock ~80 ~5 ~5 log2 13 
setblock ~80 ~5 ~123 log2 13  
fill ~80 ~5 ~126 ~80 ~8 ~126 log2 13 
setblock ~81 ~5 ~5 stained_hardened_clay 15 
setblock ~81 ~5 ~123 stained_hardened_clay 15 
setblock ~82 ~5 ~5 log2 13 
setblock ~82 ~5 ~123 log2 13  
fill ~84 ~5 ~3 ~84 ~7 ~3 log2 13  
fill ~84 ~5 ~4 ~84 ~5 ~6 log2 13  
fill ~84 ~5 ~123 ~84 ~5 ~125 log2 13  
fill ~85 ~5 ~5 ~87 ~5 ~5 stained_hardened_clay 15  
fill ~85 ~5 ~123 ~87 ~5 ~123 stained_hardened_clay 15 
setblock ~91 ~5 ~5 stained_hardened_clay 15 
setblock ~91 ~5 ~123 stained_hardened_clay 15  
fill ~94 ~5 ~3 ~94 ~7 ~3 log2 13  
fill ~94 ~5 ~4 ~94 ~5 ~6 log2 13  
fill ~94 ~5 ~122 ~102 ~5 ~122 log2 13  
fill ~94 ~5 ~123 ~94 ~5 ~125 log2 13  
fill ~95 ~5 ~6 ~102 ~5 ~6 log2 13 
setblock ~96 ~5 ~5 log2 13 
setblock ~96 ~5 ~123 log2 13 
setblock ~97 ~5 ~5 stained_hardened_clay 15 
setblock ~97 ~5 ~123 stained_hardened_clay 15  
fill ~98 ~5 ~2 ~98 ~8 ~2 log2 13 
setblock ~98 ~5 ~5 log2 13 
setblock ~98 ~5 ~123 log2 13  
fill ~98 ~5 ~126 ~98 ~8 ~126 log2 13 
setblock ~99 ~5 ~5 stained_hardened_clay 15 
setblock ~99 ~5 ~123 stained_hardened_clay 15 
setblock ~100 ~5 ~5 log2 13 
setblock ~100 ~5 ~123 log2 13  
fill ~102 ~5 ~3 ~102 ~7 ~3 log2 13  
fill ~102 ~5 ~4 ~102 ~5 ~6 log2 13  
fill ~102 ~5 ~123 ~102 ~5 ~125 log2 13  
fill ~103 ~5 ~5 ~105 ~5 ~5 stained_hardened_clay 15  
fill ~103 ~5 ~123 ~105 ~5 ~123 stained_hardened_clay 15 
setblock ~109 ~5 ~5 stained_hardened_clay 15 
setblock ~109 ~5 ~123 stained_hardened_clay 15  
fill ~112 ~5 ~3 ~112 ~7 ~3 log2 13  
fill ~112 ~5 ~4 ~112 ~5 ~6 log2 13  
fill ~112 ~5 ~122 ~120 ~5 ~122 log2 13  
fill ~112 ~5 ~123 ~112 ~5 ~125 log2 13  
fill ~113 ~5 ~6 ~120 ~5 ~6 log2 13 
setblock ~114 ~5 ~5 log2 13 
setblock ~114 ~5 ~123 log2 13 
setblock ~115 ~5 ~5 stained_hardened_clay 15 
setblock ~115 ~5 ~123 stained_hardened_clay 15  
fill ~116 ~5 ~2 ~116 ~8 ~2 log2 13 
setblock ~116 ~5 ~5 log2 13 
setblock ~116 ~5 ~123 log2 13  
fill ~116 ~5 ~126 ~116 ~8 ~126 log2 13 
setblock ~117 ~5 ~5 stained_hardened_clay 15 
setblock ~117 ~5 ~123 stained_hardened_clay 15 
setblock ~118 ~5 ~5 log2 13 
setblock ~118 ~5 ~123 log2 13  
fill ~120 ~5 ~3 ~120 ~7 ~3 log2 13  
fill ~120 ~5 ~4 ~120 ~5 ~6 log2 13  
fill ~120 ~5 ~123 ~120 ~5 ~125 log2 13  
fill ~121 ~5 ~5 ~123 ~5 ~5 stained_hardened_clay 15  
fill ~121 ~5 ~123 ~123 ~5 ~123 stained_hardened_clay 15  
fill ~123 ~5 ~8 ~125 ~5 ~8 log2 13 
setblock ~123 ~5 ~10 log2 13 
setblock ~123 ~5 ~11 stained_hardened_clay 15 
setblock ~123 ~5 ~12 log2 13 
setblock ~123 ~5 ~13 stained_hardened_clay 15 
setblock ~123 ~5 ~14 log2 13  
fill ~123 ~5 ~16 ~125 ~5 ~16 log2 13 
setblock ~123 ~5 ~19 stained_hardened_clay 15 
setblock ~123 ~5 ~23 stained_hardened_clay 15  
fill ~123 ~5 ~26 ~125 ~5 ~26 log2 13 
setblock ~123 ~5 ~28 log2 13 
setblock ~123 ~5 ~29 stained_hardened_clay 15 
setblock ~123 ~5 ~30 log2 13 
setblock ~123 ~5 ~31 stained_hardened_clay 15 
setblock ~123 ~5 ~32 log2 13  
fill ~123 ~5 ~34 ~125 ~5 ~34 log2 13 
setblock ~123 ~5 ~37 stained_hardened_clay 15 
setblock ~123 ~5 ~41 stained_hardened_clay 15  
fill ~123 ~5 ~44 ~125 ~5 ~44 log2 13 
setblock ~123 ~5 ~46 log2 13 
setblock ~123 ~5 ~47 stained_hardened_clay 15 
setblock ~123 ~5 ~48 log2 13 
setblock ~123 ~5 ~49 stained_hardened_clay 15 
setblock ~123 ~5 ~50 log2 13  
fill ~123 ~5 ~52 ~125 ~5 ~52 log2 13 
setblock ~123 ~5 ~55 stained_hardened_clay 15  
fill ~123 ~5 ~56 ~123 ~5 ~58 dirt 0 
setblock ~123 ~5 ~59 stained_hardened_clay 15 
setblock ~123 ~5 ~69 stained_hardened_clay 15  
fill ~123 ~5 ~71 ~123 ~5 ~72 dirt 0 
setblock ~123 ~5 ~73 stained_hardened_clay 15  
fill ~123 ~5 ~76 ~125 ~5 ~76 log2 13 
setblock ~123 ~5 ~78 log2 13 
setblock ~123 ~5 ~79 stained_hardened_clay 15 
setblock ~123 ~5 ~80 log2 13 
setblock ~123 ~5 ~81 stained_hardened_clay 15 
setblock ~123 ~5 ~82 log2 13  
fill ~123 ~5 ~84 ~125 ~5 ~84 log2 13 
setblock ~123 ~5 ~87 stained_hardened_clay 15 
setblock ~123 ~5 ~91 stained_hardened_clay 15   
fill ~123 ~5 ~94 ~125 ~5 ~94 log2 13 
setblock ~123 ~5 ~96 log2 13 
setblock ~123 ~5 ~97 stained_hardened_clay 15 
setblock ~123 ~5 ~98 log2 13 
setblock ~123 ~5 ~99 stained_hardened_clay 15 
setblock ~123 ~5 ~100 log2 13  
fill ~123 ~5 ~102 ~125 ~5 ~102 log2 13 
setblock ~123 ~5 ~105 stained_hardened_clay 15 
setblock ~123 ~5 ~109 stained_hardened_clay 15  
fill ~123 ~5 ~112 ~125 ~5 ~112 log2 13 
setblock ~123 ~5 ~114 log2 13 
setblock ~123 ~5 ~115 stained_hardened_clay 15 
setblock ~123 ~5 ~116 log2 13 
setblock ~123 ~5 ~117 stained_hardened_clay 15 
setblock ~123 ~5 ~118 log2 13  
fill ~123 ~5 ~120 ~125 ~5 ~120 log2 13  
fill ~124 ~5 ~60 ~125 ~5 ~60 log2 13  
fill ~124 ~5 ~68 ~125 ~5 ~68 log2 13  
fill ~124 ~5 ~79 ~125 ~5 ~79 log2 13  
