setblock ~4~83~1 minecraft:quartz_block
fill ~4~84~1 ~4~86~6 minecraft:quartz_block
setblock ~4~87~1 minecraft:quartz_block
setblock ~3~84~2 minecraft:quartz_block
fill ~3~85~2 ~3~85~5 minecraft:quartz_block
setblock ~3~86~2 minecraft:quartz_block
setblock ~4~81~2 minecraft:quartz_block
fill ~4~82~2 ~4~83~5 minecraft:quartz_block
fill ~4~87~2 ~4~88~11 minecraft:quartz_block
setblock ~4~89~2 minecraft:quartz_block
setblock ~5~84~2 minecraft:quartz_block
fill ~5~85~2 ~5~85~5 minecraft:quartz_block
setblock ~5~86~2 minecraft:quartz_block
setblock ~2~84~3 minecraft:quartz_block
fill ~2~85~3 ~2~85~4 minecraft:bone_block
setblock ~2~86~3 minecraft:quartz_block
setblock ~3~81~3 minecraft:quartz_block
fill ~3~82~3 ~3~84~4 minecraft:quartz_block
fill ~3~86~3 ~3~87~7 minecraft:quartz_block
setblock ~3~88~3 minecraft:quartz_block
setblock ~4~79~3 minecraft:quartz_block
fill ~4~80~3 ~4~81~5 minecraft:quartz_block
fill ~4~89~3 ~4~90~12 minecraft:quartz_block
setblock ~4~91~3 minecraft:quartz_block
setblock ~5~81~3 minecraft:quartz_block
fill ~5~82~3 ~5~84~4 minecraft:quartz_block
fill ~5~86~3 ~5~87~7 minecraft:quartz_block
setblock ~5~88~3 minecraft:quartz_block
setblock ~6~84~3 minecraft:quartz_block
fill ~6~85~3 ~6~85~4 minecraft:bone_block
setblock ~6~86~3 minecraft:quartz_block
setblock ~2~84~4 minecraft:quartz_block
fill ~2~86~4 ~2~87~4 minecraft:bone_block
setblock ~2~88~4 minecraft:quartz_block
setblock ~3~79~4 minecraft:quartz_block
fill ~3~80~4 ~3~81~4 minecraft:quartz_block
fill ~3~88~4 ~3~90~11 minecraft:quartz_block
setblock ~3~91~4 minecraft:stone_block_slab
setblock ~4~78~4 minecraft:quartz_block
fill ~4~79~4 ~4~79~6 minecraft:quartz_block
fill ~4~91~4 ~4~91~14 minecraft:quartz_block
setblock ~4~92~4 minecraft:stone_block_slab
setblock ~5~79~4 minecraft:quartz_block
fill ~5~80~4 ~5~81~4 minecraft:quartz_block
fill ~5~88~4 ~5~90~11 minecraft:quartz_block
setblock ~5~91~4 minecraft:stone_block_slab
setblock ~6~84~4 minecraft:quartz_block
fill ~6~86~4 ~6~87~4 minecraft:bone_block
setblock ~6~88~4 minecraft:quartz_block
setblock ~2~86~5 minecraft:quartz_block
fill ~2~87~5 ~2~89~6 minecraft:bone_block
setblock ~2~90~5 minecraft:stone_block_slab
setblock ~3~78~5 minecraft:quartz_block
setblock ~3~79~5 minecraft:quartz_block
setblock ~3~80~5 minecraft:quartz_block
setblock ~3~83~5 minecraft:quartz_block
setblock ~3~84~5 minecraft:quartz_block
fill ~3~91~5 ~3~91~14 minecraft:quartz_block
setblock ~4~77~5 minecraft:quartz_block
fill ~4~78~5 ~4~78~6 minecraft:quartz_block
fill ~4~92~5 ~4~92~15 minecraft:quartz_block
setblock ~5~78~5 minecraft:quartz_block
setblock ~5~79~5 minecraft:quartz_block
setblock ~5~80~5 minecraft:quartz_block
setblock ~5~83~5 minecraft:quartz_block
setblock ~5~84~5 minecraft:quartz_block
fill ~5~91~5 ~5~91~14 minecraft:quartz_block
setblock ~6~86~5 minecraft:quartz_block
fill ~6~87~5 ~6~89~6 minecraft:bone_block
setblock ~6~90~5 minecraft:stone_block_slab
fill ~2~90~6 ~2~90~11 minecraft:bone_block
setblock ~3~85~6 minecraft:quartz_block
setblock ~4~76~6 minecraft:stone_block_slab
setblock ~4~77~6 minecraft:quartz_block
setblock ~4~80~6 minecraft:quartz_block
setblock ~4~82~6 minecraft:quartz_block
setblock ~4~83~6 minecraft:quartz_block
setblock ~5~85~6 minecraft:quartz_block
fill ~6~90~6 ~6~90~12 minecraft:bone_block
setblock ~2~87~7 minecraft:stone_block_slab
fill ~2~88~7 ~2~89~8 minecraft:bone_block
setblock ~2~91~7 minecraft:stone_block_slab
setblock ~3~92~7 minecraft:stone_block_slab
setblock ~4~77~7 minecraft:quartz_block
setblock ~4~84~7 minecraft:stone_block_slab
fill ~4~85~7 ~4~86~8 minecraft:quartz_block
setblock ~4~93~7 minecraft:stone_block_slab
setblock ~5~92~7 minecraft:stone_block_slab
setblock ~6~87~7 minecraft:stone_block_slab
fill ~6~88~7 ~6~89~7 minecraft:bone_block
setblock ~6~91~7 minecraft:stone_block_slab
fill ~2~91~8 ~2~91~11 minecraft:bone_block
setblock ~3~86~8 minecraft:stone_block_slab
fill ~3~87~8 ~3~87~11 minecraft:quartz_block
fill ~3~92~8 ~3~92~15 minecraft:quartz_block
fill ~4~93~8 ~4~93~15 minecraft:quartz_block
setblock ~5~86~8 minecraft:stone_block_slab
fill ~5~87~8 ~5~87~11 minecraft:quartz_block
fill ~5~92~8 ~5~92~15 minecraft:quartz_block
setblock ~6~88~8 minecraft:quartz_block
fill ~6~89~8 ~6~89~9 minecraft:bone_block
fill ~6~91~8 ~6~91~14 minecraft:bone_block
setblock ~2~88~9 minecraft:stone_block_slab
setblock ~2~89~9 minecraft:bone_block
setblock ~4~32~9 minecraft:stonebrick
fill ~4~33~9 ~4~33~10 minecraft:stonebrick
setblock ~4~34~9 minecraft:stonebrick
setblock ~4~35~9 minecraft:stonebrick
setblock ~4~36~9 minecraft:stone
setblock ~4~37~9 minecraft:stonebrick
setblock ~4~38~9 minecraft:stonebrick
fill ~4~39~9 ~4~40~9 minecraft:stone
setblock ~4~41~9 minecraft:stonebrick
setblock ~4~42~9 minecraft:stonebrick
setblock ~4~43~9 minecraft:stone
setblock ~4~44~9 minecraft:stonebrick
setblock ~4~85~9 minecraft:stone_block_slab
fill ~4~86~9 ~4~86~11 minecraft:quartz_block
setblock ~6~88~9 minecraft:stone_block_slab
setblock ~2~89~10 minecraft:stone_block_slab
setblock ~2~92~10 minecraft:quartz_block
setblock ~3~32~10 minecraft:stonebrick
fill ~3~33~10 ~3~33~11 minecraft:stone
setblock ~3~34~10 minecraft:cobblestone
setblock ~3~35~10 minecraft:stonebrick
setblock ~3~36~10 minecraft:stonebrick
fill ~3~37~10 ~3~38~11 minecraft:stone
setblock ~3~39~10 minecraft:stone
setblock ~3~40~10 minecraft:stonebrick
setblock ~3~41~10 minecraft:stonebrick
fill ~3~42~10 ~3~43~10 minecraft:stone
setblock ~3~44~10 minecraft:stonebrick
setblock ~3~86~10 minecraft:stone_block_slab
setblock ~3~93~10 minecraft:quartz_block
setblock ~4~26~10 minecraft:stonebrick
setblock ~4~27~10 minecraft:stonebrick
setblock ~4~28~10 minecraft:stonebrick
setblock ~4~29~10 minecraft:stone
setblock ~4~30~10 minecraft:stonebrick
fill ~4~31~10 ~4~32~10 minecraft:stonebrick
fill ~4~34~10 ~5~34~10 minecraft:stone
setblock ~4~35~10 minecraft:cobblestone
fill ~4~36~10 ~4~36~11 minecraft:stonebrick
fill ~4~37~10 ~4~37~11 minecraft:cobblestone
setblock ~4~38~10 minecraft:stonebrick
setblock ~4~39~10 minecraft:cobblestone
fill ~4~40~10 ~5~40~10 minecraft:stone
setblock ~4~41~10 minecraft:stone
setblock ~4~42~10 minecraft:stonebrick
fill ~4~43~10 ~5~43~10 minecraft:cobblestone
setblock ~4~44~10 minecraft:stonebrick
setblock ~4~45~10 minecraft:cobblestone
setblock ~4~46~10 minecraft:stone
setblock ~4~47~10 minecraft:stonebrick
fill ~4~48~10 ~4~48~11 minecraft:cobblestone
setblock ~4~49~10 minecraft:stonebrick
fill ~4~50~10 ~4~51~10 minecraft:stonebrick
setblock ~4~52~10 minecraft:stone
fill ~4~53~10 ~4~53~11 minecraft:stonebrick
fill ~4~54~10 ~4~54~13 minecraft:cobblestone
setblock ~4~55~10 minecraft:cobblestone
setblock ~4~56~10 minecraft:stonebrick
setblock ~4~57~10 minecraft:stonebrick
setblock ~4~69~10 minecraft:stonebrick
setblock ~4~70~10 minecraft:stone
fill ~4~71~10 ~4~71~11 minecraft:cobblestone
setblock ~4~72~10 minecraft:stonebrick
fill ~4~73~10 ~4~74~10 minecraft:stonebrick
setblock ~4~75~10 minecraft:stone
setblock ~4~76~10 minecraft:stonebrick
setblock ~4~77~10 minecraft:stonebrick
setblock ~4~78~10 minecraft:stonebrick
setblock ~4~79~10 minecraft:stonebrick
fill ~4~85~10 ~4~85~12 minecraft:quartz_block
setblock ~4~94~10 minecraft:quartz_block
setblock ~5~32~10 minecraft:stonebrick
setblock ~5~33~10 minecraft:stonebrick
setblock ~5~35~10 minecraft:stone
fill ~5~36~10 ~5~36~11 minecraft:stonebrick
fill ~5~37~10 ~5~38~10 minecraft:stonebrick
setblock ~5~39~10 minecraft:stone
setblock ~5~41~10 minecraft:stonebrick
setblock ~5~42~10 minecraft:stone
setblock ~5~44~10 minecraft:stonebrick
setblock ~5~86~10 minecraft:stone_block_slab
setblock ~5~93~10 minecraft:quartz_block
setblock ~6~89~10 minecraft:stone_block_slab
setblock ~6~92~10 minecraft:quartz_block
fill ~1~86~11 ~1~88~11 minecraft:stone
fill ~2~85~11 ~3~85~11 minecraft:quartz_block
fill ~2~86~11 ~3~86~11 minecraft:quartz_block
fill ~2~87~11 ~2~88~11 minecraft:quartz_block
setblock ~2~89~11 minecraft:bone_block
setblock ~2~92~11 minecraft:quartz_block
setblock ~2~93~11 minecraft:stone_block_slab
setblock ~3~26~11 minecraft:stonebrick
fill ~3~27~11 ~4~27~11 minecraft:stonebrick
setblock ~3~28~11 minecraft:stonebrick
setblock ~3~29~11 minecraft:stone
fill ~3~30~11 ~3~30~13 minecraft:stonebrick
fill ~3~31~11 ~4~31~11 minecraft:stone
setblock ~3~32~11 minecraft:stonebrick
fill ~3~34~11 ~3~35~11 minecraft:stone
setblock ~3~36~11 minecraft:stonebrick
fill ~3~39~11 ~3~40~11 minecraft:stonebrick
fill ~3~41~11 ~3~41~12 minecraft:stone
setblock ~3~42~11 minecraft:cobblestone
setblock ~3~43~11 minecraft:stone
setblock ~3~44~11 minecraft:cobblestone
fill ~3~45~11 ~4~45~11 minecraft:stonebrick
fill ~3~46~11 ~3~46~12 minecraft:stone
fill ~3~47~11 ~3~47~12 minecraft:stonebrick
setblock ~3~48~11 minecraft:stonebrick
setblock ~3~49~11 minecraft:cobblestone
fill ~3~50~11 ~3~51~11 minecraft:stone
setblock ~3~52~11 minecraft:stonebrick
setblock ~3~53~11 minecraft:stonebrick
setblock ~3~54~11 minecraft:stonebrick
fill ~3~55~11 ~4~55~11 minecraft:stone
setblock ~3~56~11 minecraft:cobblestone
setblock ~3~57~11 minecraft:stonebrick
setblock ~3~69~11 minecraft:stonebrick
fill ~3~70~11 ~3~70~12 minecraft:stonebrick
fill ~3~71~11 ~3~72~11 minecraft:stonebrick
setblock ~3~73~11 minecraft:cobblestone
fill ~3~74~11 ~4~74~11 minecraft:stonebrick
fill ~3~75~11 ~3~76~11 minecraft:stonebrick
setblock ~3~77~11 minecraft:stonebrick
setblock ~3~78~11 minecraft:cobblestone
setblock ~3~79~11 minecraft:stonebrick
fill ~3~93~11 ~3~93~21 minecraft:quartz_block
setblock ~3~94~11 minecraft:stone_block_slab
fill ~4~19~11 ~4~20~11 minecraft:stonebrick
fill ~4~21~11 ~4~22~11 minecraft:stonebrick
fill ~4~23~11 ~4~26~11 minecraft:stone
fill ~4~28~11 ~4~29~11 minecraft:stonebrick
fill ~4~30~11 ~4~30~12 minecraft:stone
setblock ~4~32~11 minecraft:stonebrick
setblock ~4~33~11 minecraft:cobblestone
setblock ~4~34~11 minecraft:stonebrick
fill ~4~35~11 ~5~35~11 minecraft:stonebrick
fill ~4~38~11 ~4~39~11 minecraft:stone
fill ~4~40~11 ~5~40~11 minecraft:cobblestone
setblock ~4~41~11 minecraft:stonebrick
setblock ~4~42~11 minecraft:stone
fill ~4~43~11 ~4~43~12 minecraft:cobblestone
fill ~4~44~11 ~5~44~11 minecraft:stonebrick
setblock ~4~46~11 minecraft:stonebrick
fill ~4~47~11 ~4~47~13 minecraft:cobblestone
setblock ~4~49~11 minecraft:stonebrick
fill ~4~50~11 ~5~50~11 minecraft:cobblestone
setblock ~4~51~11 minecraft:cobblestone
setblock ~4~52~11 minecraft:stonebrick
fill ~4~56~11 ~4~56~12 minecraft:stonebrick
fill ~4~57~11 ~4~58~11 minecraft:stonebrick
fill ~4~59~11 ~4~59~12 minecraft:stonebrick
setblock ~4~60~11 minecraft:stonebrick
fill ~4~61~11 ~4~62~11 minecraft:stone
setblock ~4~63~11 minecraft:cobblestone
setblock ~4~64~11 minecraft:stonebrick
setblock ~4~65~11 minecraft:stone
fill ~4~66~11 ~4~67~12 minecraft:stonebrick
setblock ~4~68~11 minecraft:stonebrick
fill ~4~69~11 ~4~69~12 minecraft:stonebrick
setblock ~4~70~11 minecraft:stonebrick
setblock ~4~72~11 minecraft:stonebrick
setblock ~4~73~11 minecraft:stonebrick
setblock ~4~75~11 minecraft:cobblestone
setblock ~4~76~11 minecraft:stone
setblock ~4~77~11 minecraft:cobblestone
setblock ~4~78~11 minecraft:stonebrick
setblock ~4~79~11 minecraft:stonebrick
fill ~4~80~11 ~4~80~12 minecraft:cobblestone
setblock ~4~81~11 minecraft:stonebrick
setblock ~4~84~11 minecraft:quartz_block
fill ~4~94~11 ~4~94~15 minecraft:quartz_block
setblock ~4~95~11 minecraft:stone_block_slab
setblock ~5~26~11 minecraft:stonebrick
setblock ~5~27~11 minecraft:stonebrick
setblock ~5~28~11 minecraft:stonebrick
fill ~5~29~11 ~5~29~13 minecraft:stonebrick
setblock ~5~30~11 minecraft:stonebrick
setblock ~5~31~11 minecraft:cobblestone
setblock ~5~32~11 minecraft:stone
setblock ~5~33~11 minecraft:stonebrick
setblock ~5~34~11 minecraft:stone
setblock ~5~37~11 minecraft:stonebrick
setblock ~5~38~11 minecraft:stonebrick
setblock ~5~39~11 minecraft:cobblestone
setblock ~5~41~11 minecraft:stone
fill ~5~42~11 ~5~42~12 minecraft:stonebrick
setblock ~5~43~11 minecraft:stonebrick
setblock ~5~45~11 minecraft:stonebrick
setblock ~5~46~11 minecraft:cobblestone
setblock ~5~47~11 minecraft:stone
setblock ~5~48~11 minecraft:cobblestone
setblock ~5~49~11 minecraft:stonebrick
setblock ~5~51~11 minecraft:stonebrick
fill ~5~52~11 ~5~52~12 minecraft:stonebrick
fill ~5~53~11 ~5~53~12 minecraft:stonebrick
setblock ~5~54~11 minecraft:cobblestone
setblock ~5~55~11 minecraft:stonebrick
setblock ~5~56~11 minecraft:cobblestone
setblock ~5~57~11 minecraft:stonebrick
setblock ~5~69~11 minecraft:stonebrick
setblock ~5~70~11 minecraft:stone
setblock ~5~71~11 minecraft:cobblestone
fill ~5~72~11 ~5~72~12 minecraft:stonebrick
fill ~5~73~11 ~5~75~11 minecraft:stone
setblock ~5~76~11 minecraft:stonebrick
setblock ~5~77~11 minecraft:stonebrick
setblock ~5~78~11 minecraft:cobblestone
setblock ~5~79~11 minecraft:stonebrick
fill ~5~85~11 ~6~85~11 minecraft:quartz_block
fill ~5~86~11 ~6~86~11 minecraft:quartz_block
fill ~5~93~11 ~5~93~21 minecraft:quartz_block
setblock ~5~94~11 minecraft:stone_block_slab
setblock ~6~87~11 minecraft:quartz_block
fill ~6~88~11 ~6~89~11 minecraft:bone_block
fill ~6~92~11 ~6~92~15 minecraft:bone_block
setblock ~6~93~11 minecraft:stone_block_slab
fill ~7~86~11 ~7~88~11 minecraft:stone
fill ~1~84~12 ~1~85~12 minecraft:stone
fill ~1~89~12 ~1~90~12 minecraft:stone
setblock ~2~32~12 minecraft:stonebrick
setblock ~2~33~12 minecraft:cobblestone
fill ~2~34~12 ~3~34~12 minecraft:stonebrick
fill ~2~35~12 ~3~35~12 minecraft:stonebrick
setblock ~2~36~12 minecraft:stonebrick
fill ~2~37~12 ~2~38~12 minecraft:stonebrick
fill ~2~39~12 ~2~39~13 minecraft:stonebrick
fill ~2~40~12 ~2~41~12 minecraft:cobblestone
fill ~2~42~12 ~2~43~12 minecraft:stonebrick
setblock ~2~44~12 minecraft:stonebrick
setblock ~2~83~12 minecraft:stone_block_slab
fill ~2~84~12 ~6~84~12 minecraft:quartz_block
fill ~2~85~12 ~3~85~12 minecraft:quartz_block
fill ~2~86~12 ~2~88~12 minecraft:stone
fill ~2~89~12 ~3~90~12 minecraft:quartz_block
fill ~2~91~12 ~2~91~14 minecraft:quartz_block
fill ~2~92~12 ~2~92~15 minecraft:bone_block
setblock ~2~93~12 minecraft:quartz_block
setblock ~3~19~12 minecraft:stonebrick
fill ~3~20~12 ~3~20~13 minecraft:cobblestone
fill ~3~21~12 ~3~21~13 minecraft:stonebrick
setblock ~3~22~12 minecraft:stonebrick
setblock ~3~23~12 minecraft:cobblestone
setblock ~3~24~12 minecraft:stonebrick
fill ~3~25~12 ~4~25~12 minecraft:stonebrick
fill ~3~26~12 ~3~27~12 minecraft:stonebrick
setblock ~3~28~12 minecraft:stonebrick
setblock ~3~29~12 minecraft:stonebrick
setblock ~3~31~12 minecraft:stone
fill ~3~32~12 ~3~32~13 minecraft:stonebrick
setblock ~3~33~12 minecraft:stonebrick
fill ~3~36~12 ~4~36~12 minecraft:stone
fill ~3~37~12 ~3~37~13 minecraft:stonebrick
setblock ~3~38~12 minecraft:cobblestone
fill ~3~39~12 ~3~39~13 minecraft:stonebrick
fill ~3~40~12 ~3~40~13 minecraft:stonebrick
fill ~3~42~12 ~3~42~13 minecraft:stonebrick
fill ~3~43~12 ~3~43~13 minecraft:cobblestone
fill ~3~44~12 ~3~45~12 minecraft:stone
setblock ~3~48~12 minecraft:cobblestone
setblock ~3~49~12 minecraft:stonebrick
fill ~3~50~12 ~3~51~12 minecraft:cobblestone
setblock ~3~52~12 minecraft:stone
setblock ~3~53~12 minecraft:cobblestone
setblock ~3~54~12 minecraft:stonebrick
fill ~3~55~12 ~3~56~13 minecraft:stonebrick
fill ~3~57~12 ~4~57~12 minecraft:stone
setblock ~3~58~12 minecraft:stonebrick
setblock ~3~59~12 minecraft:stonebrick
fill ~3~60~12 ~5~60~12 minecraft:stone
setblock ~3~61~12 minecraft:stone
setblock ~3~62~12 minecraft:cobblestone
setblock ~3~63~12 minecraft:stonebrick
fill ~3~64~12 ~3~64~13 minecraft:stonebrick
fill ~3~65~12 ~3~65~13 minecraft:stonebrick
fill ~3~66~12 ~3~67~12 minecraft:stonebrick
setblock ~3~68~12 minecraft:stone
fill ~3~69~12 ~3~69~13 minecraft:stonebrick
fill ~3~71~12 ~4~71~12 minecraft:stonebrick
setblock ~3~72~12 minecraft:stonebrick
setblock ~3~73~12 minecraft:stone
fill ~3~74~12 ~3~74~13 minecraft:cobblestone
fill ~3~75~12 ~3~76~12 minecraft:stone
setblock ~3~77~12 minecraft:cobblestone
setblock ~3~78~12 minecraft:stonebrick
fill ~3~79~12 ~3~79~13 minecraft:stonebrick
setblock ~3~80~12 minecraft:stonebrick
setblock ~3~81~12 minecraft:stonebrick
setblock ~3~86~12 minecraft:concrete
setblock ~3~87~12 minecraft:concrete
fill ~3~88~12 ~4~88~12 minecraft:concrete
fill ~3~94~12 ~3~94~20 minecraft:quartz_block
setblock ~4~14~12 minecraft:stonebrick
setblock ~4~15~12 minecraft:stonebrick
setblock ~4~16~12 minecraft:cobblestone
setblock ~4~17~12 minecraft:stonebrick
setblock ~4~18~12 minecraft:stonebrick
setblock ~4~19~12 minecraft:cobblestone
setblock ~4~20~12 minecraft:stone
setblock ~4~21~12 minecraft:cobblestone
fill ~4~22~12 ~4~24~12 minecraft:stonebrick
fill ~4~26~12 ~4~27~12 minecraft:stone
fill ~4~28~12 ~5~28~12 minecraft:cobblestone
setblock ~4~29~12 minecraft:stonebrick
fill ~4~31~12 ~4~31~13 minecraft:stonebrick
fill ~4~32~12 ~5~32~12 minecraft:stonebrick
setblock ~4~33~12 minecraft:stonebrick
setblock ~4~34~12 minecraft:cobblestone
fill ~4~35~12 ~4~35~13 minecraft:stonebrick
fill ~4~37~12 ~5~37~12 minecraft:stone
setblock ~4~38~12 minecraft:stonebrick
fill ~4~39~12 ~4~39~13 minecraft:stone
fill ~4~40~12 ~5~40~12 minecraft:stonebrick
fill ~4~41~12 ~5~41~12 minecraft:stonebrick
setblock ~4~42~12 minecraft:stonebrick
fill ~4~44~12 ~5~44~12 minecraft:cobblestone
setblock ~4~45~12 minecraft:stonebrick
setblock ~4~46~12 minecraft:cobblestone
fill ~4~48~12 ~5~48~12 minecraft:stone
fill ~4~49~12 ~4~49~13 minecraft:stonebrick
fill ~4~50~12 ~5~50~12 minecraft:stonebrick
fill ~4~51~12 ~4~51~13 minecraft:stone
fill ~4~52~12 ~4~52~15 minecraft:stonebrick
setblock ~4~53~12 minecraft:stone
setblock ~4~55~12 minecraft:stone
setblock ~4~58~12 minecraft:stonebrick
setblock ~4~61~12 minecraft:stonebrick
fill ~4~62~12 ~4~63~12 minecraft:stone
setblock ~4~64~12 minecraft:cobblestone
setblock ~4~65~12 minecraft:stonebrick
fill ~4~68~12 ~4~68~13 minecraft:stonebrick
setblock ~4~70~12 minecraft:stone
fill ~4~72~12 ~4~72~13 minecraft:stonebrick
fill ~4~73~12 ~5~73~12 minecraft:stonebrick
setblock ~4~74~12 minecraft:stonebrick
fill ~4~75~12 ~4~76~12 minecraft:stonebrick
fill ~4~77~12 ~5~77~12 minecraft:stone
setblock ~4~78~12 minecraft:cobblestone
setblock ~4~79~12 minecraft:stonebrick
setblock ~4~81~12 minecraft:stonebrick
setblock ~4~82~12 minecraft:stone
fill ~4~83~12 ~4~83~13 minecraft:stonebrick
fill ~4~86~12 ~5~86~12 minecraft:concrete
setblock ~4~87~12 minecraft:concrete
fill ~4~95~12 ~4~95~15 minecraft:quartz_block
fill ~5~19~12 ~5~20~12 minecraft:stonebrick
setblock ~5~21~12 minecraft:stone
setblock ~5~22~12 minecraft:stonebrick
setblock ~5~23~12 minecraft:stone
setblock ~5~24~12 minecraft:stonebrick
setblock ~5~25~12 minecraft:cobblestone
setblock ~5~26~12 minecraft:stonebrick
setblock ~5~27~12 minecraft:stonebrick
fill ~5~30~12 ~5~30~13 minecraft:stonebrick
setblock ~5~31~12 minecraft:stonebrick
setblock ~5~33~12 minecraft:stonebrick
fill ~5~34~12 ~5~34~13 minecraft:stonebrick
setblock ~5~35~12 minecraft:cobblestone
fill ~5~36~12 ~5~36~13 minecraft:stonebrick
setblock ~5~38~12 minecraft:stone
fill ~5~39~12 ~6~39~12 minecraft:stonebrick
setblock ~5~43~12 minecraft:stonebrick
fill ~5~45~12 ~5~45~13 minecraft:cobblestone
setblock ~5~46~12 minecraft:stonebrick
setblock ~5~47~12 minecraft:cobblestone
fill ~5~49~12 ~5~49~13 minecraft:stonebrick
setblock ~5~51~12 minecraft:stonebrick
setblock ~5~54~12 minecraft:stone
setblock ~5~55~12 minecraft:cobblestone
fill ~5~56~12 ~5~56~13 minecraft:stone
setblock ~5~57~12 minecraft:stonebrick
setblock ~5~58~12 minecraft:stone
fill ~5~59~12 ~5~59~13 minecraft:stonebrick
setblock ~5~61~12 minecraft:stonebrick
setblock ~5~62~12 minecraft:cobblestone
setblock ~5~63~12 minecraft:stonebrick
setblock ~5~64~12 minecraft:stone
fill ~5~65~12 ~5~66~12 minecraft:stonebrick
fill ~5~67~12 ~5~67~13 minecraft:cobblestone
setblock ~5~68~12 minecraft:stonebrick
setblock ~5~69~12 minecraft:stone
fill ~5~70~12 ~5~71~12 minecraft:stonebrick
setblock ~5~74~12 minecraft:cobblestone
setblock ~5~75~12 minecraft:stone
fill ~5~76~12 ~5~76~13 minecraft:cobblestone
setblock ~5~78~12 minecraft:stonebrick
fill ~5~79~12 ~5~80~12 minecraft:cobblestone
setblock ~5~81~12 minecraft:stonebrick
fill ~5~85~12 ~6~85~12 minecraft:quartz_block
setblock ~5~87~12 minecraft:concrete
setblock ~5~88~12 minecraft:concrete
fill ~5~89~12 ~5~90~12 minecraft:quartz_block
fill ~5~94~12 ~5~94~20 minecraft:quartz_block
setblock ~6~32~12 minecraft:stonebrick
setblock ~6~33~12 minecraft:cobblestone
setblock ~6~34~12 minecraft:stone
setblock ~6~35~12 minecraft:stonebrick
fill ~6~36~12 ~6~37~12 minecraft:stonebrick
fill ~6~38~12 ~6~38~13 minecraft:stonebrick
fill ~6~40~12 ~6~41~12 minecraft:cobblestone
setblock ~6~42~12 minecraft:stonebrick
fill ~6~43~12 ~6~43~13 minecraft:stonebrick
setblock ~6~44~12 minecraft:stonebrick
setblock ~6~83~12 minecraft:stone_block_slab
fill ~6~86~12 ~6~88~12 minecraft:stone
setblock ~6~89~12 minecraft:bone_block
fill ~6~93~12 ~6~93~20 minecraft:bone_block
fill ~7~84~12 ~7~85~12 minecraft:stone
fill ~7~89~12 ~7~90~12 minecraft:stone
fill ~1~83~13 ~1~83~14 minecraft:stone
fill ~1~91~13 ~1~91~14 minecraft:stone
setblock ~2~19~13 minecraft:stonebrick
setblock ~2~20~13 minecraft:cobblestone
setblock ~2~21~13 minecraft:stonebrick
fill ~2~22~13 ~2~22~14 minecraft:stonebrick
fill ~2~23~13 ~2~23~14 minecraft:stonebrick
setblock ~2~24~13 minecraft:cobblestone
setblock ~2~25~13 minecraft:stone
setblock ~2~26~13 minecraft:stonebrick
fill ~2~27~13 ~2~27~14 minecraft:stonebrick
fill ~2~28~13 ~2~29~13 minecraft:cobblestone
fill ~2~30~13 ~2~30~14 minecraft:stone
setblock ~2~31~13 minecraft:cobblestone
fill ~2~32~13 ~2~33~13 minecraft:stone
setblock ~2~34~13 minecraft:stonebrick
setblock ~2~35~13 minecraft:stonebrick
fill ~2~36~13 ~3~36~13 minecraft:stone
fill ~2~37~13 ~2~38~13 minecraft:stone
setblock ~2~40~13 minecraft:stonebrick
setblock ~2~41~13 minecraft:stonebrick
setblock ~2~42~13 minecraft:cobblestone
setblock ~2~43~13 minecraft:stone
setblock ~2~44~13 minecraft:stonebrick
fill ~2~45~13 ~4~45~13 minecraft:stonebrick
setblock ~2~46~13 minecraft:stonebrick
setblock ~2~47~13 minecraft:cobblestone
setblock ~2~48~13 minecraft:stonebrick
fill ~2~49~13 ~2~51~13 minecraft:cobblestone
setblock ~2~52~13 minecraft:stonebrick
fill ~2~53~13 ~2~53~14 minecraft:stonebrick
setblock ~2~54~13 minecraft:stone
setblock ~2~55~13 minecraft:cobblestone
setblock ~2~56~13 minecraft:stonebrick
setblock ~2~57~13 minecraft:stonebrick
setblock ~2~69~13 minecraft:stonebrick
setblock ~2~70~13 minecraft:stonebrick
fill ~2~71~13 ~2~72~13 minecraft:stonebrick
setblock ~2~73~13 minecraft:cobblestone
setblock ~2~74~13 minecraft:stone
setblock ~2~75~13 minecraft:cobblestone
fill ~2~76~13 ~3~76~13 minecraft:stonebrick
setblock ~2~77~13 minecraft:stone
setblock ~2~78~13 minecraft:stonebrick
setblock ~2~79~13 minecraft:stonebrick
fill ~2~83~13 ~2~83~14 minecraft:quartz_block
fill ~2~84~13 ~2~84~14 minecraft:stone
setblock ~2~85~13 minecraft:stone
fill ~2~86~13 ~2~88~19 minecraft:stained_glass
fill ~2~89~13 ~2~90~13 minecraft:stone
fill ~2~93~13 ~2~93~20 minecraft:bone_block
setblock ~2~94~13 minecraft:stone_block_slab
setblock ~3~14~13 minecraft:stonebrick
setblock ~3~15~13 minecraft:stone
setblock ~3~16~13 minecraft:stonebrick
fill ~3~17~13 ~3~17~14 minecraft:stone
fill ~3~18~13 ~3~19~13 minecraft:stonebrick
fill ~3~22~13 ~4~22~13 minecraft:cobblestone
setblock ~3~23~13 minecraft:stone
fill ~3~24~13 ~3~25~13 minecraft:stonebrick
fill ~3~26~13 ~3~27~13 minecraft:cobblestone
setblock ~3~28~13 minecraft:stonebrick
setblock ~3~29~13 minecraft:stonebrick
setblock ~3~31~13 minecraft:stonebrick
setblock ~3~33~13 minecraft:cobblestone
fill ~3~34~13 ~3~35~13 minecraft:stonebrick
setblock ~3~38~13 minecraft:stonebrick
setblock ~3~41~13 minecraft:stonebrick
setblock ~3~44~13 minecraft:cobblestone
setblock ~3~46~13 minecraft:cobblestone
setblock ~3~47~13 minecraft:stonebrick
setblock ~3~48~13 minecraft:stonebrick
fill ~3~49~13 ~3~50~13 minecraft:stone
setblock ~3~51~13 minecraft:cobblestone
setblock ~3~52~13 minecraft:stonebrick
setblock ~3~53~13 minecraft:stonebrick
setblock ~3~54~13 minecraft:stonebrick
setblock ~3~57~13 minecraft:stonebrick
fill ~3~58~13 ~3~59~13 minecraft:cobblestone
fill ~3~60~13 ~5~60~13 minecraft:stonebrick
setblock ~3~61~13 minecraft:stonebrick
fill ~3~62~13 ~4~63~13 minecraft:stonebrick
setblock ~3~66~13 minecraft:stone
fill ~3~67~13 ~3~68~13 minecraft:stonebrick
fill ~3~70~13 ~3~71~13 minecraft:stonebrick
setblock ~3~72~13 minecraft:cobblestone
fill ~3~73~13 ~4~73~13 minecraft:stonebrick
setblock ~3~75~13 minecraft:stonebrick
setblock ~3~77~13 minecraft:stonebrick
fill ~3~78~13 ~3~78~14 minecraft:stone
fill ~3~80~13 ~4~80~13 minecraft:stonebrick
setblock ~3~81~13 minecraft:stonebrick
setblock ~3~82~13 minecraft:stonebrick
setblock ~3~83~13 minecraft:cobblestone
fill ~3~84~13 ~5~84~13 minecraft:quartz_block
setblock ~3~85~13 minecraft:concrete
fill ~3~86~13 ~3~88~19 minecraft:stained_glass
setblock ~3~89~13 minecraft:concrete
fill ~3~90~13 ~5~90~13 minecraft:quartz_block
setblock ~3~95~13 minecraft:stone_block_slab
setblock ~4~10~13 minecraft:stonebrick
setblock ~4~11~13 minecraft:stone
fill ~4~12~13 ~4~12~14 minecraft:stonebrick
setblock ~4~13~13 minecraft:stonebrick
setblock ~4~14~13 minecraft:stone
fill ~4~15~13 ~4~15~14 minecraft:stonebrick
setblock ~4~16~13 minecraft:stone
fill ~4~17~13 ~5~17~13 minecraft:stonebrick
setblock ~4~18~13 minecraft:cobblestone
setblock ~4~19~13 minecraft:stone
fill ~4~20~13 ~5~20~13 minecraft:cobblestone
setblock ~4~21~13 minecraft:stonebrick
setblock ~4~23~13 minecraft:stonebrick
fill ~4~24~13 ~6~24~13 minecraft:stonebrick
fill ~4~25~13 ~4~25~14 minecraft:stonebrick
setblock ~4~26~13 minecraft:stonebrick
fill ~4~27~13 ~4~27~14 minecraft:stonebrick
setblock ~4~28~13 minecraft:cobblestone
setblock ~4~29~13 minecraft:stone
setblock ~4~30~13 minecraft:stonebrick
setblock ~4~32~13 minecraft:stone
fill ~4~33~13 ~4~33~14 minecraft:stonebrick
setblock ~4~34~13 minecraft:stonebrick
setblock ~4~36~13 minecraft:stonebrick
fill ~4~37~13 ~5~38~13 minecraft:stonebrick
setblock ~4~40~13 minecraft:cobblestone
fill ~4~41~13 ~4~42~13 minecraft:stonebrick
fill ~4~43~13 ~5~43~13 minecraft:stonebrick
fill ~4~44~13 ~4~44~14 minecraft:stone
fill ~4~46~13 ~6~46~13 minecraft:stonebrick
fill ~4~48~13 ~5~48~13 minecraft:stonebrick
setblock ~4~50~13 minecraft:stonebrick
setblock ~4~53~13 minecraft:cobblestone
fill ~4~55~13 ~4~57~13 minecraft:cobblestone
setblock ~4~58~13 minecraft:stone
setblock ~4~59~13 minecraft:stonebrick
setblock ~4~61~13 minecraft:stonebrick
setblock ~4~64~13 minecraft:stonebrick
fill ~4~65~13 ~4~65~14 minecraft:stonebrick
setblock ~4~66~13 minecraft:cobblestone
setblock ~4~67~13 minecraft:stonebrick
setblock ~4~69~13 minecraft:stone
fill ~4~70~13 ~4~70~14 minecraft:stonebrick
setblock ~4~71~13 minecraft:cobblestone
setblock ~4~74~13 minecraft:stone
setblock ~4~75~13 minecraft:cobblestone
setblock ~4~76~13 minecraft:stonebrick
setblock ~4~77~13 minecraft:stonebrick
setblock ~4~78~13 minecraft:stonebrick
setblock ~4~79~13 minecraft:stonebrick
fill ~4~81~13 ~5~81~13 minecraft:stonebrick
setblock ~4~82~13 minecraft:stonebrick
setblock ~4~85~13 minecraft:concrete
fill ~4~86~13 ~4~86~19 minecraft:stained_glass
fill ~4~87~13 ~4~88~15 minecraft:stained_glass
setblock ~4~89~13 minecraft:concrete
setblock ~4~96~13 minecraft:stone_block_slab
setblock ~5~14~13 minecraft:stonebrick
setblock ~5~15~13 minecraft:stone
setblock ~5~16~13 minecraft:stonebrick
fill ~5~18~13 ~5~19~13 minecraft:stonebrick
setblock ~5~21~13 minecraft:cobblestone
setblock ~5~22~13 minecraft:stone
setblock ~5~23~13 minecraft:stonebrick
fill ~5~25~13 ~5~26~13 minecraft:stonebrick
fill ~5~27~13 ~6~27~13 minecraft:stone
setblock ~5~28~13 minecraft:stonebrick
fill ~5~31~13 ~6~31~13 minecraft:cobblestone
setblock ~5~32~13 minecraft:stonebrick
fill ~5~33~13 ~6~33~13 minecraft:stonebrick
setblock ~5~35~13 minecraft:stonebrick
setblock ~5~39~13 minecraft:stonebrick
setblock ~5~40~13 minecraft:stonebrick
setblock ~5~41~13 minecraft:stone
setblock ~5~42~13 minecraft:stonebrick
setblock ~5~44~13 minecraft:stonebrick
setblock ~5~47~13 minecraft:stonebrick
setblock ~5~50~13 minecraft:cobblestone
setblock ~5~51~13 minecraft:stone
setblock ~5~52~13 minecraft:cobblestone
setblock ~5~53~13 minecraft:stonebrick
setblock ~5~54~13 minecraft:cobblestone
setblock ~5~55~13 minecraft:stone
fill ~5~57~13 ~5~58~13 minecraft:cobblestone
setblock ~5~61~13 minecraft:stone
setblock ~5~62~13 minecraft:stonebrick
setblock ~5~63~13 minecraft:stonebrick
fill ~5~64~13 ~5~65~13 minecraft:cobblestone
setblock ~5~66~13 minecraft:stonebrick
setblock ~5~68~13 minecraft:stonebrick
setblock ~5~69~13 minecraft:stonebrick
setblock ~5~70~13 minecraft:stone
setblock ~5~71~13 minecraft:stonebrick
fill ~5~72~13 ~5~72~14 minecraft:stonebrick
setblock ~5~73~13 minecraft:stonebrick
setblock ~5~74~13 minecraft:stonebrick
setblock ~5~75~13 minecraft:stonebrick
setblock ~5~77~13 minecraft:stonebrick
fill ~5~78~13 ~5~80~13 minecraft:stonebrick
fill ~5~82~13 ~5~82~14 minecraft:cobblestone
fill ~5~83~13 ~5~83~14 minecraft:stone
setblock ~5~85~13 minecraft:concrete
fill ~5~86~13 ~5~88~19 minecraft:stained_glass
setblock ~5~89~13 minecraft:concrete
setblock ~5~95~13 minecraft:stone_block_slab
fill ~6~19~13 ~6~19~14 minecraft:stonebrick
setblock ~6~20~13 minecraft:stonebrick
fill ~6~21~13 ~6~22~13 minecraft:stonebrick
setblock ~6~23~13 minecraft:cobblestone
setblock ~6~25~13 minecraft:cobblestone
setblock ~6~26~13 minecraft:stonebrick
setblock ~6~28~13 minecraft:stone
setblock ~6~29~13 minecraft:stonebrick
setblock ~6~30~13 minecraft:stonebrick
setblock ~6~32~13 minecraft:stonebrick
setblock ~6~34~13 minecraft:stonebrick
setblock ~6~35~13 minecraft:stonebrick
setblock ~6~36~13 minecraft:stone
setblock ~6~37~13 minecraft:stonebrick
setblock ~6~39~13 minecraft:cobblestone
setblock ~6~40~13 minecraft:stonebrick
setblock ~6~41~13 minecraft:cobblestone
setblock ~6~42~13 minecraft:stonebrick
setblock ~6~44~13 minecraft:stonebrick
setblock ~6~45~13 minecraft:stonebrick
fill ~6~47~13 ~6~48~13 minecraft:cobblestone
fill ~6~49~13 ~6~49~14 minecraft:stonebrick
setblock ~6~50~13 minecraft:stonebrick
setblock ~6~51~13 minecraft:stonebrick
setblock ~6~52~13 minecraft:stone
fill ~6~53~13 ~6~54~13 minecraft:stonebrick
setblock ~6~55~13 minecraft:stonebrick
setblock ~6~56~13 minecraft:stonebrick
setblock ~6~57~13 minecraft:stonebrick
setblock ~6~69~13 minecraft:stonebrick
fill ~6~70~13 ~6~70~14 minecraft:stonebrick
setblock ~6~71~13 minecraft:stonebrick
setblock ~6~72~13 minecraft:cobblestone
fill ~6~73~13 ~6~75~13 minecraft:stone
setblock ~6~76~13 minecraft:stonebrick
setblock ~6~77~13 minecraft:stone
setblock ~6~78~13 minecraft:cobblestone
setblock ~6~79~13 minecraft:stonebrick
fill ~6~83~13 ~6~83~14 minecraft:quartz_block
fill ~6~84~13 ~6~84~14 minecraft:stone
setblock ~6~85~13 minecraft:stone
fill ~6~86~13 ~6~88~19 minecraft:stained_glass
fill ~6~89~13 ~6~90~13 minecraft:stone
setblock ~6~94~13 minecraft:stone_block_slab
fill ~7~83~13 ~7~83~14 minecraft:stone
fill ~7~91~13 ~7~91~14 minecraft:stone
setblock ~2~18~14 minecraft:stonebrick
setblock ~2~19~14 minecraft:stone
setblock ~2~20~14 minecraft:stonebrick
setblock ~2~21~14 minecraft:stonebrick
setblock ~2~24~14 minecraft:stonebrick
setblock ~2~25~14 minecraft:cobblestone
setblock ~2~26~14 minecraft:stonebrick
setblock ~2~28~14 minecraft:stonebrick
setblock ~2~29~14 minecraft:stone
setblock ~2~31~14 minecraft:stonebrick
setblock ~2~32~14 minecraft:stonebrick
setblock ~2~33~14 minecraft:stonebrick
setblock ~2~34~14 minecraft:stonebrick
setblock ~2~42~14 minecraft:stonebrick
setblock ~2~43~14 minecraft:stonebrick
setblock ~2~44~14 minecraft:stonebrick
setblock ~2~45~14 minecraft:stone
setblock ~2~46~14 minecraft:stonebrick
setblock ~2~47~14 minecraft:stone
fill ~2~48~14 ~2~49~14 minecraft:stonebrick
fill ~2~50~14 ~2~51~14 minecraft:stonebrick
setblock ~2~52~14 minecraft:stonebrick
fill ~2~54~14 ~2~55~14 minecraft:stonebrick
setblock ~2~56~14 minecraft:cobblestone
setblock ~2~57~14 minecraft:stonebrick
setblock ~2~58~14 minecraft:cobblestone
setblock ~2~59~14 minecraft:stonebrick
setblock ~2~60~14 minecraft:stone
setblock ~2~61~14 minecraft:stonebrick
setblock ~2~62~14 minecraft:stone
fill ~2~63~14 ~2~64~14 minecraft:stonebrick
setblock ~2~65~14 minecraft:stonebrick
setblock ~2~66~14 minecraft:cobblestone
fill ~2~67~14 ~2~67~15 minecraft:stonebrick
setblock ~2~68~14 minecraft:stonebrick
fill ~2~69~14 ~3~69~14 minecraft:stone
setblock ~2~70~14 minecraft:stonebrick
fill ~2~71~14 ~3~71~14 minecraft:cobblestone
setblock ~2~72~14 minecraft:stone
fill ~2~73~14 ~3~73~14 minecraft:stonebrick
setblock ~2~74~14 minecraft:cobblestone
setblock ~2~75~14 minecraft:stonebrick
setblock ~2~76~14 minecraft:stonebrick
fill ~2~77~14 ~3~77~14 minecraft:stonebrick
fill ~2~78~14 ~2~79~14 minecraft:stone
setblock ~2~80~14 minecraft:stonebrick
setblock ~2~81~14 minecraft:stonebrick
setblock ~2~82~14 minecraft:quartz_block
fill ~2~85~14 ~2~85~18 minecraft:stained_glass
fill ~2~89~14 ~2~89~18 minecraft:stained_glass
setblock ~2~90~14 minecraft:stone
fill ~2~94~14 ~2~94~18 minecraft:bone_block
setblock ~3~10~14 minecraft:stonebrick
setblock ~3~11~14 minecraft:stonebrick
fill ~3~12~14 ~3~13~14 minecraft:stonebrick
fill ~3~14~14 ~5~14~14 minecraft:stonebrick
setblock ~3~15~14 minecraft:stonebrick
setblock ~3~16~14 minecraft:stonebrick
setblock ~3~18~14 minecraft:stonebrick
fill ~3~19~14 ~3~20~14 minecraft:stained_hardened_clay
fill ~3~21~14 ~3~21~17 minecraft:stained_hardened_clay
setblock ~3~22~14 minecraft:stained_hardened_clay
setblock ~3~23~14 minecraft:stained_hardened_clay
setblock ~3~24~14 minecraft:stained_hardened_clay
fill ~3~25~14 ~3~25~15 minecraft:stained_hardened_clay
fill ~3~26~14 ~3~27~14 minecraft:stained_hardened_clay
fill ~3~28~14 ~3~28~15 minecraft:stained_hardened_clay
fill ~3~29~14 ~3~29~15 minecraft:stained_hardened_clay
fill ~3~30~14 ~3~31~14 minecraft:stained_hardened_clay
setblock ~3~32~14 minecraft:stained_hardened_clay
fill ~3~33~14 ~3~33~15 minecraft:stained_hardened_clay
fill ~3~34~14 ~3~36~14 minecraft:stained_hardened_clay
fill ~3~37~14 ~3~37~15 minecraft:stained_hardened_clay
fill ~3~38~14 ~3~38~15 minecraft:stained_hardened_clay
fill ~3~39~14 ~3~40~15 minecraft:stained_hardened_clay
setblock ~3~41~14 minecraft:stained_hardened_clay
setblock ~3~42~14 minecraft:stained_hardened_clay
fill ~3~43~14 ~3~44~14 minecraft:stained_hardened_clay
fill ~3~45~14 ~3~48~14 minecraft:stained_hardened_clay
fill ~3~49~14 ~3~49~15 minecraft:stained_hardened_clay
fill ~3~50~14 ~3~51~14 minecraft:stained_hardened_clay
setblock ~3~52~14 minecraft:stained_hardened_clay
setblock ~3~53~14 minecraft:stained_hardened_clay
setblock ~3~54~14 minecraft:stained_hardened_clay
fill ~3~55~14 ~3~56~14 minecraft:stained_hardened_clay
fill ~3~57~14 ~3~57~15 minecraft:stained_hardened_clay
fill ~3~58~14 ~3~59~15 minecraft:stained_hardened_clay
fill ~3~60~14 ~3~64~14 minecraft:stained_hardened_clay
fill ~3~65~14 ~3~66~14 minecraft:stained_hardened_clay
fill ~3~67~14 ~3~67~15 minecraft:stained_hardened_clay
fill ~3~68~14 ~5~68~14 minecraft:stonebrick
setblock ~3~70~14 minecraft:stone
setblock ~3~72~14 minecraft:stonebrick
fill ~3~74~14 ~3~75~14 minecraft:stone
setblock ~3~76~14 minecraft:stonebrick
setblock ~3~79~14 minecraft:stone
setblock ~3~80~14 minecraft:cobblestone
fill ~3~81~14 ~3~83~14 minecraft:stonebrick
setblock ~3~84~14 minecraft:concrete
fill ~3~85~14 ~3~85~18 minecraft:stained_glass
fill ~3~89~14 ~3~89~18 minecraft:stained_glass
setblock ~3~90~14 minecraft:concrete
fill ~3~95~14 ~3~95~18 minecraft:quartz_block
fill ~3~112~14 ~5~112~14 minecraft:concrete
fill ~3~113~14 ~3~114~14 minecraft:concrete
setblock ~4~7~14 minecraft:stonebrick
setblock ~4~8~14 minecraft:stonebrick
setblock ~4~9~14 minecraft:stonebrick
setblock ~4~10~14 minecraft:stone
setblock ~4~11~14 minecraft:stonebrick
setblock ~4~13~14 minecraft:stone
setblock ~4~16~14 minecraft:stonebrick
setblock ~4~17~14 minecraft:stonebrick
setblock ~4~18~14 minecraft:stonebrick
setblock ~4~19~14 minecraft:cobblestone
setblock ~4~20~14 minecraft:stonebrick
fill ~4~21~14 ~4~21~15 minecraft:cobblestone
fill ~4~22~14 ~4~22~15 minecraft:stonebrick
setblock ~4~23~14 minecraft:stone
setblock ~4~24~14 minecraft:stonebrick
fill ~4~26~14 ~4~26~15 minecraft:stonebrick
setblock ~4~28~14 minecraft:stone
setblock ~4~29~14 minecraft:stonebrick
setblock ~4~30~14 minecraft:stone
setblock ~4~31~14 minecraft:cobblestone
setblock ~4~32~14 minecraft:stonebrick
setblock ~4~34~14 minecraft:stonebrick
fill ~4~35~14 ~4~36~14 minecraft:cobblestone
setblock ~4~37~14 minecraft:stonebrick
fill ~4~38~14 ~4~38~15 minecraft:stonebrick
setblock ~4~39~14 minecraft:stonebrick
fill ~4~40~14 ~4~41~14 minecraft:stone
setblock ~4~42~14 minecraft:stonebrick
setblock ~4~43~14 minecraft:stonebrick
setblock ~4~45~14 minecraft:stonebrick
setblock ~4~46~14 minecraft:stonebrick
fill ~4~47~14 ~4~47~15 minecraft:stonebrick
setblock ~4~48~14 minecraft:stone
setblock ~4~49~14 minecraft:stonebrick
setblock ~4~50~14 minecraft:stone
fill ~4~51~14 ~4~51~15 minecraft:cobblestone
fill ~4~53~14 ~4~54~14 minecraft:stonebrick
setblock ~4~55~14 minecraft:stonebrick
setblock ~4~56~14 minecraft:stonebrick
setblock ~4~57~14 minecraft:cobblestone
fill ~4~58~14 ~4~59~14 minecraft:stonebrick
setblock ~4~60~14 minecraft:stone
fill ~4~61~14 ~4~61~15 minecraft:cobblestone
setblock ~4~62~14 minecraft:cobblestone
setblock ~4~63~14 minecraft:stonebrick
setblock ~4~64~14 minecraft:stonebrick
setblock ~4~66~14 minecraft:stonebrick
setblock ~4~67~14 minecraft:stone
setblock ~4~69~14 minecraft:stonebrick
fill ~4~71~14 ~4~71~15 minecraft:stonebrick
setblock ~4~72~14 minecraft:cobblestone
fill ~4~73~14 ~4~73~15 minecraft:stonebrick
fill ~4~74~14 ~6~74~14 minecraft:stonebrick
fill ~4~75~14 ~5~75~14 minecraft:stonebrick
setblock ~4~76~14 minecraft:cobblestone
setblock ~4~77~14 minecraft:stone
fill ~4~78~14 ~6~78~14 minecraft:stonebrick
setblock ~4~79~14 minecraft:stonebrick
fill ~4~80~14 ~4~80~15 minecraft:stone
setblock ~4~81~14 minecraft:cobblestone
fill ~4~82~14 ~4~82~15 minecraft:stonebrick
setblock ~4~83~14 minecraft:stonebrick
fill ~4~84~14 ~5~84~14 minecraft:concrete
fill ~4~85~14 ~4~85~18 minecraft:stained_glass
fill ~4~89~14 ~4~89~18 minecraft:stained_glass
fill ~4~90~14 ~5~90~14 minecraft:concrete
setblock ~4~96~14 minecraft:quartz_block
setblock ~4~113~14 minecraft:stained_glass
fill ~4~114~14 ~5~114~15 minecraft:concrete
setblock ~5~10~14 minecraft:stonebrick
fill ~5~11~14 ~5~13~14 minecraft:stonebrick
setblock ~5~15~14 minecraft:cobblestone
setblock ~5~16~14 minecraft:stonebrick
fill ~5~17~14 ~5~18~14 minecraft:stonebrick
fill ~5~19~14 ~5~19~16 minecraft:stained_hardened_clay
fill ~5~20~14 ~5~21~14 minecraft:stained_hardened_clay
fill ~5~22~14 ~5~22~15 minecraft:stained_hardened_clay
fill ~5~23~14 ~5~23~15 minecraft:stained_hardened_clay
setblock ~5~24~14 minecraft:stained_hardened_clay
setblock ~5~25~14 minecraft:stained_hardened_clay
setblock ~5~26~14 minecraft:stained_hardened_clay
fill ~5~27~14 ~5~28~14 minecraft:stained_hardened_clay
fill ~5~29~14 ~5~29~15 minecraft:stained_hardened_clay
setblock ~5~30~14 minecraft:stained_hardened_clay
fill ~5~31~14 ~5~31~15 minecraft:stained_hardened_clay
setblock ~5~32~14 minecraft:stained_hardened_clay
fill ~5~33~14 ~5~33~15 minecraft:stained_hardened_clay
setblock ~5~34~14 minecraft:stained_hardened_clay
fill ~5~35~14 ~5~36~14 minecraft:stained_hardened_clay
fill ~5~37~14 ~5~38~15 minecraft:stained_hardened_clay
fill ~5~39~14 ~5~39~15 minecraft:stained_hardened_clay
fill ~5~40~14 ~5~41~14 minecraft:stained_hardened_clay
fill ~5~42~14 ~5~46~14 minecraft:stained_hardened_clay
setblock ~5~47~14 minecraft:stained_hardened_clay
fill ~5~48~14 ~5~48~15 minecraft:stained_hardened_clay
setblock ~5~49~14 minecraft:stained_hardened_clay
fill ~5~50~14 ~5~53~14 minecraft:stained_hardened_clay
fill ~5~54~14 ~5~55~15 minecraft:stained_hardened_clay
setblock ~5~56~14 minecraft:stained_hardened_clay
setblock ~5~57~14 minecraft:stained_hardened_clay
setblock ~5~58~14 minecraft:stained_hardened_clay
setblock ~5~59~14 minecraft:stained_hardened_clay
fill ~5~60~14 ~5~60~15 minecraft:stained_hardened_clay
setblock ~5~61~14 minecraft:stained_hardened_clay
setblock ~5~62~14 minecraft:stained_hardened_clay
setblock ~5~63~14 minecraft:stained_hardened_clay
setblock ~5~64~14 minecraft:stained_hardened_clay
fill ~5~65~14 ~5~66~14 minecraft:stained_hardened_clay
fill ~5~67~14 ~5~67~16 minecraft:stained_hardened_clay
setblock ~5~69~14 minecraft:cobblestone
setblock ~5~70~14 minecraft:stonebrick
setblock ~5~71~14 minecraft:stone
fill ~5~73~14 ~6~73~14 minecraft:stonebrick
setblock ~5~76~14 minecraft:stonebrick
fill ~5~77~14 ~6~77~14 minecraft:stonebrick
setblock ~5~79~14 minecraft:stonebrick
setblock ~5~80~14 minecraft:cobblestone
setblock ~5~81~14 minecraft:stonebrick
fill ~5~85~14 ~5~85~18 minecraft:stained_glass
fill ~5~89~14 ~5~89~18 minecraft:stained_glass
fill ~5~95~14 ~5~95~18 minecraft:quartz_block
setblock ~5~113~14 minecraft:concrete
setblock ~6~18~14 minecraft:stonebrick
setblock ~6~20~14 minecraft:stone
setblock ~6~21~14 minecraft:cobblestone
setblock ~6~22~14 minecraft:stonebrick
setblock ~6~23~14 minecraft:stonebrick
setblock ~6~24~14 minecraft:stonebrick
setblock ~6~25~14 minecraft:stonebrick
fill ~6~26~14 ~6~27~14 minecraft:stone
fill ~6~28~14 ~6~29~14 minecraft:stonebrick
setblock ~6~30~14 minecraft:stonebrick
fill ~6~31~14 ~6~32~14 minecraft:stone
setblock ~6~33~14 minecraft:stonebrick
setblock ~6~34~14 minecraft:stonebrick
setblock ~6~42~14 minecraft:stonebrick
setblock ~6~43~14 minecraft:stonebrick
setblock ~6~44~14 minecraft:stonebrick
setblock ~6~45~14 minecraft:stonebrick
setblock ~6~46~14 minecraft:cobblestone
setblock ~6~47~14 minecraft:stonebrick
setblock ~6~48~14 minecraft:cobblestone
setblock ~6~50~14 minecraft:stonebrick
fill ~6~51~14 ~6~52~14 minecraft:stonebrick
fill ~6~53~14 ~6~55~14 minecraft:cobblestone
setblock ~6~56~14 minecraft:stonebrick
setblock ~6~57~14 minecraft:stonebrick
fill ~6~58~14 ~6~60~14 minecraft:stone
fill ~6~61~14 ~6~62~15 minecraft:stonebrick
setblock ~6~63~14 minecraft:stonebrick
setblock ~6~64~14 minecraft:stonebrick
setblock ~6~65~14 minecraft:cobblestone
fill ~6~66~14 ~6~66~15 minecraft:stonebrick
fill ~6~67~14 ~6~68~14 minecraft:cobblestone
setblock ~6~69~14 minecraft:stonebrick
fill ~6~71~14 ~6~72~14 minecraft:stonebrick
setblock ~6~75~14 minecraft:stone
setblock ~6~76~14 minecraft:cobblestone
setblock ~6~79~14 minecraft:cobblestone
setblock ~6~80~14 minecraft:stonebrick
setblock ~6~81~14 minecraft:stonebrick
setblock ~6~82~14 minecraft:quartz_block
fill ~6~85~14 ~6~85~18 minecraft:stained_glass
fill ~6~89~14 ~6~89~18 minecraft:stained_glass
setblock ~6~90~14 minecraft:stone
fill ~6~94~14 ~6~94~18 minecraft:bone_block
fill ~1~82~15 ~1~82~17 minecraft:stone
fill ~1~92~15 ~1~92~17 minecraft:stone
setblock ~2~14~15 minecraft:stonebrick
setblock ~2~15~15 minecraft:stonebrick
setblock ~2~16~15 minecraft:cobblestone
setblock ~2~17~15 minecraft:stonebrick
setblock ~2~18~15 minecraft:stonebrick
fill ~2~19~15 ~2~20~15 minecraft:stonebrick
setblock ~2~21~15 minecraft:stonebrick
setblock ~2~57~15 minecraft:stonebrick
setblock ~2~58~15 minecraft:stonebrick
setblock ~2~59~15 minecraft:cobblestone
setblock ~2~60~15 minecraft:stonebrick
fill ~2~61~15 ~2~62~15 minecraft:stonebrick
fill ~2~63~15 ~2~64~15 minecraft:stone
setblock ~2~65~15 minecraft:stonebrick
setblock ~2~66~15 minecraft:stonebrick
fill ~2~68~15 ~2~69~15 minecraft:stonebrick
setblock ~2~70~15 minecraft:stonebrick
setblock ~2~77~15 minecraft:stonebrick
setblock ~2~78~15 minecraft:stonebrick
fill ~2~79~15 ~2~80~15 minecraft:stonebrick
fill ~2~81~15 ~3~81~15 minecraft:stonebrick
setblock ~2~82~15 minecraft:stonebrick
fill ~2~83~15 ~2~83~17 minecraft:stone
fill ~2~84~15 ~2~84~17 minecraft:stained_glass
fill ~2~90~15 ~2~90~17 minecraft:stained_glass
fill ~2~91~15 ~2~91~17 minecraft:stone
fill ~2~112~15 ~2~112~17 minecraft:concrete
fill ~2~113~15 ~2~114~15 minecraft:concrete
setblock ~3~7~15 minecraft:stone_block_slab
setblock ~3~8~15 minecraft:cobblestone
fill ~3~9~15 ~3~9~16 minecraft:stonebrick
setblock ~3~10~15 minecraft:cobblestone
fill ~3~11~15 ~3~12~15 minecraft:stone
fill ~3~13~15 ~4~13~15 minecraft:stonebrick
fill ~3~14~15 ~3~15~15 minecraft:stone
setblock ~3~16~15 minecraft:stained_hardened_clay
fill ~3~17~15 ~3~18~16 minecraft:stained_hardened_clay
fill ~3~19~15 ~3~20~15 minecraft:stained_hardened_clay
setblock ~3~22~15 minecraft:stained_hardened_clay
setblock ~3~23~15 minecraft:stained_hardened_clay
setblock ~3~24~15 minecraft:stained_hardened_clay
setblock ~3~26~15 minecraft:stained_hardened_clay
setblock ~3~27~15 minecraft:stained_hardened_clay
setblock ~3~30~15 minecraft:stained_hardened_clay
fill ~3~31~15 ~3~32~15 minecraft:stained_hardened_clay
setblock ~3~34~15 minecraft:stained_hardened_clay
setblock ~3~35~15 minecraft:stained_hardened_clay
setblock ~3~36~15 minecraft:stained_hardened_clay
setblock ~3~41~15 minecraft:stained_hardened_clay
setblock ~3~42~15 minecraft:stained_hardened_clay
fill ~3~43~15 ~3~44~15 minecraft:stained_hardened_clay
fill ~3~45~15 ~3~46~15 minecraft:stained_hardened_clay
setblock ~3~47~15 minecraft:stained_hardened_clay
setblock ~3~48~15 minecraft:stained_hardened_clay
fill ~3~50~15 ~3~51~15 minecraft:stained_hardened_clay
setblock ~3~52~15 minecraft:stained_hardened_clay
setblock ~3~53~15 minecraft:stained_hardened_clay
setblock ~3~54~15 minecraft:stained_hardened_clay
setblock ~3~55~15 minecraft:stained_hardened_clay
setblock ~3~56~15 minecraft:stained_hardened_clay
setblock ~3~60~15 minecraft:stained_hardened_clay
setblock ~3~61~15 minecraft:stained_hardened_clay
setblock ~3~62~15 minecraft:stained_hardened_clay
setblock ~3~63~15 minecraft:stained_hardened_clay
fill ~3~64~15 ~3~65~16 minecraft:stained_hardened_clay
setblock ~3~66~15 minecraft:stained_hardened_clay
setblock ~3~68~15 minecraft:stained_hardened_clay
fill ~3~69~15 ~3~70~15 minecraft:stained_hardened_clay
fill ~3~71~15 ~3~72~15 minecraft:stained_hardened_clay
setblock ~3~73~15 minecraft:stained_hardened_clay
setblock ~3~74~15 minecraft:stained_hardened_clay
setblock ~3~75~15 minecraft:stained_hardened_clay
fill ~3~76~15 ~3~77~15 minecraft:stained_hardened_clay
setblock ~3~78~15 minecraft:stained_hardened_clay
setblock ~3~79~15 minecraft:stained_hardened_clay
setblock ~3~80~15 minecraft:stained_hardened_clay
setblock ~3~82~15 minecraft:stonebrick
fill ~3~83~15 ~3~83~17 minecraft:concrete
fill ~3~84~15 ~3~84~17 minecraft:stained_glass
fill ~3~90~15 ~3~90~17 minecraft:stained_glass
fill ~3~91~15 ~5~91~16 minecraft:concrete
setblock ~3~96~15 minecraft:stone_block_slab
fill ~3~111~15 ~5~111~17 minecraft:concrete
fill ~3~112~15 ~5~112~17 minecraft:gold_block
setblock ~3~113~15 minecraft:gold_block
fill ~3~114~15 ~3~114~18 minecraft:concrete
fill ~3~115~15 ~5~115~15 minecraft:concrete
setblock ~4~3~15 minecraft:stonebrick
setblock ~4~4~15 minecraft:stonebrick
setblock ~4~5~15 minecraft:stonebrick
setblock ~4~6~15 minecraft:stonebrick
setblock ~4~7~15 minecraft:stonebrick
fill ~4~8~15 ~4~8~16 minecraft:stonebrick
setblock ~4~9~15 minecraft:cobblestone
fill ~4~10~15 ~5~10~15 minecraft:stonebrick
fill ~4~11~15 ~4~11~16 minecraft:stonebrick
fill ~4~12~15 ~4~12~16 minecraft:stonebrick
setblock ~4~14~15 minecraft:stonebrick
setblock ~4~15~15 minecraft:cobblestone
setblock ~4~16~15 minecraft:stonebrick
fill ~4~17~15 ~4~18~15 minecraft:stonebrick
setblock ~4~19~15 minecraft:stonebrick
setblock ~4~20~15 minecraft:stonebrick
setblock ~4~23~15 minecraft:stonebrick
setblock ~4~24~15 minecraft:stone
setblock ~4~25~15 minecraft:cobblestone
setblock ~4~27~15 minecraft:stone
setblock ~4~28~15 minecraft:cobblestone
setblock ~4~29~15 minecraft:stonebrick
setblock ~4~30~15 minecraft:cobblestone
setblock ~4~31~15 minecraft:stone
setblock ~4~32~15 minecraft:stonebrick
setblock ~4~33~15 minecraft:stonebrick
setblock ~4~34~15 minecraft:cobblestone
setblock ~4~35~15 minecraft:stonebrick
setblock ~4~36~15 minecraft:stonebrick
setblock ~4~37~15 minecraft:stone
setblock ~4~39~15 minecraft:cobblestone
setblock ~4~40~15 minecraft:stonebrick
setblock ~4~41~15 minecraft:stonebrick
fill ~4~42~15 ~4~43~15 minecraft:stone
setblock ~4~44~15 minecraft:cobblestone
setblock ~4~45~15 minecraft:stone
setblock ~4~46~15 minecraft:cobblestone
setblock ~4~48~15 minecraft:stonebrick
fill ~4~49~15 ~4~50~15 minecraft:cobblestone
setblock ~4~53~15 minecraft:stonebrick
fill ~4~54~15 ~4~55~15 minecraft:stone
setblock ~4~56~15 minecraft:stonebrick
setblock ~4~57~15 minecraft:stonebrick
setblock ~4~58~15 minecraft:stone
setblock ~4~59~15 minecraft:stonebrick
setblock ~4~60~15 minecraft:cobblestone
setblock ~4~62~15 minecraft:stonebrick
fill ~4~63~15 ~4~64~15 minecraft:cobblestone
fill ~4~65~15 ~4~66~15 minecraft:stone
fill ~4~67~15 ~4~68~15 minecraft:stonebrick
setblock ~4~69~15 minecraft:stonebrick
setblock ~4~70~15 minecraft:cobblestone
setblock ~4~72~15 minecraft:stonebrick
setblock ~4~74~15 minecraft:stonebrick
setblock ~4~75~15 minecraft:cobblestone
setblock ~4~76~15 minecraft:stonebrick
setblock ~4~77~15 minecraft:stonebrick
fill ~4~78~15 ~4~79~15 minecraft:stone
setblock ~4~81~15 minecraft:stonebrick
setblock ~4~83~15 minecraft:concrete
fill ~4~84~15 ~4~84~17 minecraft:stained_glass
fill ~4~90~15 ~4~90~17 minecraft:stained_glass
fill ~4~96~15 ~4~100~17 minecraft:nether_brick
fill ~4~101~15 ~4~110~15 minecraft:nether_brick
setblock ~4~113~15 minecraft:sea_lantern
setblock ~5~7~15 minecraft:stone_block_slab
fill ~5~8~15 ~5~9~15 minecraft:stone
setblock ~5~11~15 minecraft:stonebrick
fill ~5~12~15 ~5~14~15 minecraft:cobblestone
setblock ~5~15~15 minecraft:stone
fill ~5~16~15 ~5~16~17 minecraft:stained_hardened_clay
fill ~5~17~15 ~5~18~15 minecraft:stained_hardened_clay
fill ~5~20~15 ~5~20~17 minecraft:stained_hardened_clay
setblock ~5~21~15 minecraft:stained_hardened_clay
fill ~5~24~15 ~5~25~15 minecraft:stained_hardened_clay
setblock ~5~26~15 minecraft:stained_hardened_clay
fill ~5~27~15 ~5~28~15 minecraft:stained_hardened_clay
setblock ~5~30~15 minecraft:stained_hardened_clay
setblock ~5~32~15 minecraft:stained_hardened_clay
setblock ~5~34~15 minecraft:stained_hardened_clay
setblock ~5~35~15 minecraft:stained_hardened_clay
setblock ~5~36~15 minecraft:stained_hardened_clay
setblock ~5~40~15 minecraft:stained_hardened_clay
setblock ~5~41~15 minecraft:stained_hardened_clay
setblock ~5~42~15 minecraft:stained_hardened_clay
setblock ~5~43~15 minecraft:stained_hardened_clay
setblock ~5~44~15 minecraft:stained_hardened_clay
setblock ~5~45~15 minecraft:stained_hardened_clay
setblock ~5~46~15 minecraft:stained_hardened_clay
setblock ~5~47~15 minecraft:stained_hardened_clay
setblock ~5~49~15 minecraft:stained_hardened_clay
setblock ~5~50~15 minecraft:stained_hardened_clay
setblock ~5~51~15 minecraft:stained_hardened_clay
setblock ~5~52~15 minecraft:stained_hardened_clay
setblock ~5~53~15 minecraft:stained_hardened_clay
setblock ~5~56~15 minecraft:stained_hardened_clay
setblock ~5~57~15 minecraft:stained_hardened_clay
setblock ~5~58~15 minecraft:stained_hardened_clay
fill ~5~59~15 ~5~59~16 minecraft:stained_hardened_clay
fill ~5~61~15 ~5~61~16 minecraft:stained_hardened_clay
setblock ~5~62~15 minecraft:stained_hardened_clay
setblock ~5~63~15 minecraft:stained_hardened_clay
fill ~5~64~15 ~5~64~17 minecraft:stained_hardened_clay
setblock ~5~65~15 minecraft:stained_hardened_clay
setblock ~5~66~15 minecraft:stained_hardened_clay
fill ~5~68~15 ~5~70~16 minecraft:stained_hardened_clay
fill ~5~71~15 ~5~72~15 minecraft:stained_hardened_clay
setblock ~5~73~15 minecraft:stained_hardened_clay
setblock ~5~74~15 minecraft:stained_hardened_clay
setblock ~5~75~15 minecraft:stained_hardened_clay
setblock ~5~76~15 minecraft:stained_hardened_clay
fill ~5~77~15 ~5~77~17 minecraft:stained_hardened_clay
fill ~5~78~15 ~5~80~15 minecraft:stained_hardened_clay
setblock ~5~81~15 minecraft:stonebrick
setblock ~5~82~15 minecraft:stonebrick
fill ~5~83~15 ~5~83~17 minecraft:concrete
fill ~5~84~15 ~5~84~17 minecraft:stained_glass
fill ~5~90~15 ~5~90~17 minecraft:stained_glass
setblock ~5~96~15 minecraft:stone_block_slab
setblock ~5~113~15 minecraft:gold_block
setblock ~6~14~15 minecraft:stonebrick
fill ~6~15~15 ~6~16~15 minecraft:stonebrick
setblock ~6~17~15 minecraft:cobblestone
fill ~6~18~15 ~6~19~15 minecraft:stone
setblock ~6~20~15 minecraft:cobblestone
setblock ~6~21~15 minecraft:stonebrick
setblock ~6~57~15 minecraft:stonebrick
setblock ~6~58~15 minecraft:stonebrick
setblock ~6~59~15 minecraft:stonebrick
setblock ~6~60~15 minecraft:cobblestone
setblock ~6~63~15 minecraft:stonebrick
fill ~6~64~15 ~6~65~15 minecraft:stone
fill ~6~67~15 ~6~68~15 minecraft:stone
setblock ~6~69~15 minecraft:cobblestone
setblock ~6~70~15 minecraft:stonebrick
setblock ~6~77~15 minecraft:stonebrick
setblock ~6~78~15 minecraft:stonebrick
setblock ~6~79~15 minecraft:stone
setblock ~6~80~15 minecraft:stonebrick
setblock ~6~81~15 minecraft:stone
setblock ~6~82~15 minecraft:stonebrick
fill ~6~83~15 ~6~83~17 minecraft:stone
fill ~6~84~15 ~6~84~17 minecraft:stained_glass
fill ~6~90~15 ~6~90~17 minecraft:stained_glass
fill ~6~91~15 ~6~91~17 minecraft:stone
fill ~6~112~15 ~6~112~17 minecraft:concrete
fill ~6~113~15 ~6~114~15 minecraft:concrete
fill ~7~82~15 ~7~82~17 minecraft:stone
fill ~7~92~15 ~7~92~17 minecraft:stone
setblock ~2~8~16 minecraft:stonebrick
fill ~2~9~16 ~2~10~16 minecraft:stonebrick
setblock ~2~11~16 minecraft:cobblestone
fill ~2~12~16 ~3~12~16 minecraft:stonebrick
setblock ~2~13~16 minecraft:cobblestone
setblock ~2~14~16 minecraft:stonebrick
fill ~2~15~16 ~2~15~17 minecraft:cobblestone
setblock ~2~81~16 minecraft:stonebrick
fill ~2~82~16 ~3~82~16 minecraft:stonebrick
fill ~2~92~16 ~3~92~16 minecraft:nether_brick
setblock ~2~113~16 minecraft:stained_glass
fill ~2~114~16 ~2~114~17 minecraft:concrete
setblock ~3~3~16 minecraft:stonebrick
fill ~3~4~16 ~4~4~16 minecraft:stonebrick
setblock ~3~5~16 minecraft:stone
fill ~3~6~16 ~4~6~16 minecraft:cobblestone
setblock ~3~7~16 minecraft:stonebrick
setblock ~3~8~16 minecraft:stonebrick
fill ~3~10~16 ~3~11~16 minecraft:stonebrick
fill ~3~13~16 ~3~13~17 minecraft:stone
setblock ~3~14~16 minecraft:stonebrick
fill ~3~19~16 ~3~19~18 minecraft:stained_hardened_clay
setblock ~3~20~16 minecraft:stained_hardened_clay
setblock ~3~57~16 minecraft:stained_hardened_clay
fill ~3~58~16 ~3~59~16 minecraft:stained_hardened_clay
fill ~3~60~16 ~3~60~17 minecraft:stained_hardened_clay
fill ~3~61~16 ~3~62~16 minecraft:stained_hardened_clay
setblock ~3~63~16 minecraft:stained_hardened_clay
setblock ~3~66~16 minecraft:stained_hardened_clay
setblock ~3~67~16 minecraft:stained_hardened_clay
fill ~3~68~16 ~3~69~16 minecraft:stained_hardened_clay
setblock ~3~70~16 minecraft:stained_hardened_clay
setblock ~3~77~16 minecraft:stained_hardened_clay
fill ~3~78~16 ~3~81~16 minecraft:stained_hardened_clay
fill ~3~96~16 ~3~110~16 minecraft:nether_brick
setblock ~3~113~16 minecraft:sea_lantern
fill ~3~115~16 ~3~115~17 minecraft:concrete
setblock ~4~0~16 minecraft:stone
setblock ~4~1~16 minecraft:stonebrick
fill ~4~2~16 ~4~3~16 minecraft:stone
fill ~4~5~16 ~5~5~16 minecraft:stonebrick
setblock ~4~7~16 minecraft:stone
fill ~4~9~16 ~5~9~16 minecraft:stone
setblock ~4~10~16 minecraft:stonebrick
fill ~4~13~16 ~6~13~16 minecraft:stonebrick
setblock ~4~14~16 minecraft:stonebrick
setblock ~4~15~16 minecraft:stone
fill ~4~16~16 ~4~16~18 minecraft:stonebrick
setblock ~4~17~16 minecraft:stonebrick
setblock ~4~18~16 minecraft:cobblestone
setblock ~4~19~16 minecraft:stone
fill ~4~78~16 ~5~78~16 minecraft:stained_hardened_clay
setblock ~4~79~16 minecraft:stonebrick
setblock ~4~80~16 minecraft:stonebrick
setblock ~4~81~16 minecraft:stonebrick
setblock ~4~82~16 minecraft:stonebrick
fill ~4~83~16 ~4~83~17 minecraft:concrete
setblock ~4~87~16 minecraft:sea_lantern
fill ~4~88~16 ~4~88~19 minecraft:stained_glass
fill ~4~92~16 ~4~95~16 minecraft:stonebrick
fill ~4~101~16 ~4~110~16 minecraft:stonebrick
setblock ~4~113~16 minecraft:gold_block
setblock ~4~114~16 minecraft:sea_lantern
setblock ~4~115~16 minecraft:stained_glass
setblock ~5~3~16 minecraft:stonebrick
setblock ~5~4~16 minecraft:stonebrick
setblock ~5~6~16 minecraft:stonebrick
setblock ~5~7~16 minecraft:stonebrick
setblock ~5~8~16 minecraft:cobblestone
setblock ~5~10~16 minecraft:stonebrick
setblock ~5~11~16 minecraft:cobblestone
setblock ~5~12~16 minecraft:stonebrick
setblock ~5~14~16 minecraft:stone
setblock ~5~15~16 minecraft:stonebrick
fill ~5~17~16 ~5~17~17 minecraft:stained_hardened_clay
setblock ~5~18~16 minecraft:stained_hardened_clay
fill ~5~21~16 ~5~21~17 minecraft:stained_hardened_clay
fill ~5~57~16 ~5~58~16 minecraft:stained_hardened_clay
fill ~5~60~16 ~5~60~17 minecraft:stained_hardened_clay
fill ~5~62~16 ~5~62~17 minecraft:stained_hardened_clay
setblock ~5~63~16 minecraft:stained_hardened_clay
fill ~5~65~16 ~5~66~16 minecraft:stained_hardened_clay
setblock ~5~79~16 minecraft:stained_hardened_clay
fill ~5~80~16 ~5~80~17 minecraft:stained_hardened_clay
setblock ~5~81~16 minecraft:stonebrick
fill ~5~82~16 ~5~82~18 minecraft:stonebrick
fill ~5~92~16 ~6~92~16 minecraft:nether_brick
fill ~5~96~16 ~5~110~16 minecraft:nether_brick
setblock ~5~113~16 minecraft:sea_lantern
fill ~5~114~16 ~6~114~17 minecraft:concrete
fill ~5~115~16 ~5~115~17 minecraft:concrete
setblock ~6~8~16 minecraft:stonebrick
fill ~6~9~16 ~6~10~16 minecraft:stonebrick
setblock ~6~11~16 minecraft:stonebrick
setblock ~6~12~16 minecraft:stone
fill ~6~14~16 ~6~15~16 minecraft:stonebrick
setblock ~6~81~16 minecraft:stonebrick
setblock ~6~113~16 minecraft:stained_glass
setblock ~2~14~17 minecraft:stonebrick
setblock ~2~16~17 minecraft:stonebrick
setblock ~2~17~17 minecraft:stonebrick
setblock ~2~18~17 minecraft:stone
setblock ~2~19~17 minecraft:stonebrick
setblock ~2~20~17 minecraft:stonebrick
setblock ~2~21~17 minecraft:stonebrick
setblock ~2~57~17 minecraft:stonebrick
setblock ~2~58~17 minecraft:stonebrick
setblock ~2~59~17 minecraft:stonebrick
fill ~2~60~17 ~2~60~18 minecraft:stone
setblock ~2~61~17 minecraft:stonebrick
fill ~2~62~17 ~2~62~18 minecraft:cobblestone
setblock ~2~63~17 minecraft:cobblestone
fill ~2~64~17 ~2~64~18 minecraft:stonebrick
setblock ~2~65~17 minecraft:stonebrick
fill ~2~66~17 ~2~66~18 minecraft:stonebrick
setblock ~2~67~17 minecraft:stonebrick
fill ~2~68~17 ~2~69~17 minecraft:stonebrick
setblock ~2~70~17 minecraft:stonebrick
setblock ~2~77~17 minecraft:stonebrick
fill ~2~78~17 ~2~79~17 minecraft:stone
fill ~2~80~17 ~2~82~17 minecraft:cobblestone
fill ~2~92~17 ~2~92~21 minecraft:bone_block
setblock ~2~113~17 minecraft:concrete
setblock ~3~7~17 minecraft:stone_block_slab
fill ~3~8~17 ~4~8~17 minecraft:stonebrick
setblock ~3~9~17 minecraft:stonebrick
setblock ~3~10~17 minecraft:stonebrick
setblock ~3~11~17 minecraft:stonebrick
fill ~3~12~17 ~5~12~17 minecraft:cobblestone
setblock ~3~14~17 minecraft:stonebrick
fill ~3~15~17 ~4~15~17 minecraft:stonebrick
setblock ~3~16~17 minecraft:stained_hardened_clay
fill ~3~17~17 ~3~18~17 minecraft:stained_hardened_clay
setblock ~3~20~17 minecraft:stained_hardened_clay
fill ~3~22~17 ~3~23~17 minecraft:stained_hardened_clay
setblock ~3~24~17 minecraft:stained_hardened_clay
setblock ~3~25~17 minecraft:stained_hardened_clay
setblock ~3~26~17 minecraft:stained_hardened_clay
fill ~3~27~17 ~3~27~18 minecraft:stained_hardened_clay
fill ~3~28~17 ~3~29~17 minecraft:stained_hardened_clay
fill ~3~30~17 ~3~30~18 minecraft:stained_hardened_clay
fill ~3~31~17 ~3~32~18 minecraft:stained_hardened_clay
setblock ~3~33~17 minecraft:stained_hardened_clay
fill ~3~34~17 ~3~35~17 minecraft:stained_hardened_clay
setblock ~3~36~17 minecraft:stained_hardened_clay
fill ~3~37~17 ~3~37~18 minecraft:stained_hardened_clay
fill ~3~38~17 ~3~39~17 minecraft:stained_hardened_clay
setblock ~3~40~17 minecraft:stained_hardened_clay
fill ~3~41~17 ~3~42~17 minecraft:stained_hardened_clay
fill ~3~43~17 ~3~44~18 minecraft:stained_hardened_clay
fill ~3~45~17 ~3~46~18 minecraft:stained_hardened_clay
setblock ~3~47~17 minecraft:stained_hardened_clay
setblock ~3~48~17 minecraft:stained_hardened_clay
fill ~3~49~17 ~3~50~18 minecraft:stained_hardened_clay
fill ~3~51~17 ~3~51~18 minecraft:stained_hardened_clay
fill ~3~52~17 ~3~53~17 minecraft:stained_hardened_clay
setblock ~3~54~17 minecraft:stained_hardened_clay
fill ~3~55~17 ~3~56~17 minecraft:stained_hardened_clay
fill ~3~57~17 ~3~58~17 minecraft:stained_hardened_clay
fill ~3~59~17 ~3~59~18 minecraft:stained_hardened_clay
fill ~3~61~17 ~3~61~18 minecraft:stained_hardened_clay
fill ~3~62~17 ~3~63~17 minecraft:stained_hardened_clay
setblock ~3~64~17 minecraft:stained_hardened_clay
setblock ~3~65~17 minecraft:stained_hardened_clay
setblock ~3~66~17 minecraft:stained_hardened_clay
setblock ~3~67~17 minecraft:stained_hardened_clay
fill ~3~68~17 ~3~70~17 minecraft:stained_hardened_clay
fill ~3~71~17 ~3~75~17 minecraft:stained_hardened_clay
setblock ~3~76~17 minecraft:stained_hardened_clay
fill ~3~77~17 ~3~78~17 minecraft:stained_hardened_clay
fill ~3~79~17 ~3~80~17 minecraft:stained_hardened_clay
setblock ~3~81~17 minecraft:stonebrick
setblock ~3~82~17 minecraft:stonebrick
fill ~3~91~17 ~4~91~17 minecraft:concrete
fill ~3~92~17 ~5~92~24 minecraft:quartz_block
setblock ~3~96~17 minecraft:stone_block_slab
setblock ~3~113~17 minecraft:gold_block
setblock ~4~3~17 minecraft:stonebrick
fill ~4~4~17 ~4~6~17 minecraft:stone
setblock ~4~7~17 minecraft:stonebrick
fill ~4~9~17 ~4~10~17 minecraft:cobblestone
setblock ~4~11~17 minecraft:stone
fill ~4~13~17 ~5~13~17 minecraft:stonebrick
setblock ~4~14~17 minecraft:stone
setblock ~4~17~17 minecraft:stonebrick
setblock ~4~18~17 minecraft:stonebrick
setblock ~4~19~17 minecraft:stonebrick
setblock ~4~20~17 minecraft:stonebrick
setblock ~4~21~17 minecraft:stonebrick
fill ~4~22~17 ~4~23~17 minecraft:stonebrick
setblock ~4~24~17 minecraft:stonebrick
fill ~4~25~17 ~4~26~17 minecraft:stonebrick
setblock ~4~27~17 minecraft:stonebrick
setblock ~4~28~17 minecraft:stonebrick
fill ~4~29~17 ~4~29~18 minecraft:stonebrick
setblock ~4~30~17 minecraft:stone
fill ~4~31~17 ~4~32~17 minecraft:stonebrick
fill ~4~33~17 ~4~33~18 minecraft:stonebrick
fill ~4~34~17 ~4~34~19 minecraft:stonebrick
setblock ~4~35~17 minecraft:stonebrick
setblock ~4~36~17 minecraft:stonebrick
setblock ~4~37~17 minecraft:stonebrick
fill ~4~38~17 ~4~39~17 minecraft:stonebrick
fill ~4~40~17 ~4~42~17 minecraft:cobblestone
setblock ~4~43~17 minecraft:stone
setblock ~4~44~17 minecraft:stonebrick
fill ~4~45~17 ~4~46~17 minecraft:cobblestone
setblock ~4~47~17 minecraft:stonebrick
setblock ~4~48~17 minecraft:stone
fill ~4~49~17 ~4~49~20 minecraft:stonebrick
setblock ~4~50~17 minecraft:stonebrick
setblock ~4~51~17 minecraft:stonebrick
setblock ~4~52~17 minecraft:stone
setblock ~4~53~17 minecraft:stonebrick
setblock ~4~54~17 minecraft:cobblestone
setblock ~4~55~17 minecraft:stonebrick
fill ~4~56~17 ~4~56~18 minecraft:cobblestone
fill ~4~57~17 ~4~58~17 minecraft:stone
setblock ~4~59~17 minecraft:stonebrick
setblock ~4~60~17 minecraft:stonebrick
setblock ~4~61~17 minecraft:stonebrick
setblock ~4~62~17 minecraft:stonebrick
setblock ~4~63~17 minecraft:stonebrick
setblock ~4~64~17 minecraft:cobblestone
setblock ~4~65~17 minecraft:stonebrick
setblock ~4~66~17 minecraft:stonebrick
setblock ~4~67~17 minecraft:stonebrick
setblock ~4~68~17 minecraft:cobblestone
setblock ~4~69~17 minecraft:stonebrick
fill ~4~70~17 ~4~72~17 minecraft:stone
fill ~4~73~17 ~4~74~17 minecraft:cobblestone
setblock ~4~75~17 minecraft:stonebrick
fill ~4~76~17 ~4~77~17 minecraft:cobblestone
setblock ~4~78~17 minecraft:stone
setblock ~4~79~17 minecraft:cobblestone
setblock ~4~80~17 minecraft:stone
fill ~4~81~17 ~4~81~18 minecraft:stonebrick
setblock ~4~82~17 minecraft:stonebrick
fill ~4~87~17 ~4~87~19 minecraft:stained_glass
fill ~4~93~17 ~4~93~24 minecraft:quartz_block
fill ~4~94~17 ~4~94~21 minecraft:quartz_block
fill ~4~95~17 ~4~95~20 minecraft:quartz_block
fill ~4~101~17 ~4~110~17 minecraft:nether_brick
setblock ~4~113~17 minecraft:sea_lantern
fill ~4~114~17 ~4~114~18 minecraft:concrete
setblock ~4~115~17 minecraft:concrete
setblock ~5~7~17 minecraft:stone_block_slab
setblock ~5~8~17 minecraft:stone
setblock ~5~9~17 minecraft:stonebrick
setblock ~5~10~17 minecraft:cobblestone
setblock ~5~11~17 minecraft:stonebrick
setblock ~5~14~17 minecraft:stonebrick
fill ~5~15~17 ~6~15~17 minecraft:stonebrick
setblock ~5~18~17 minecraft:stained_hardened_clay
setblock ~5~19~17 minecraft:stained_hardened_clay
fill ~5~22~17 ~5~22~18 minecraft:stained_hardened_clay
fill ~5~23~17 ~5~24~17 minecraft:stained_hardened_clay
setblock ~5~25~17 minecraft:stained_hardened_clay
setblock ~5~26~17 minecraft:stained_hardened_clay
setblock ~5~27~17 minecraft:stained_hardened_clay
fill ~5~28~17 ~5~29~18 minecraft:stained_hardened_clay
fill ~5~30~17 ~5~30~18 minecraft:stained_hardened_clay
fill ~5~31~17 ~5~31~18 minecraft:stained_hardened_clay
fill ~5~32~17 ~5~32~18 minecraft:stained_hardened_clay
fill ~5~33~17 ~5~37~17 minecraft:stained_hardened_clay
setblock ~5~38~17 minecraft:stained_hardened_clay
setblock ~5~39~17 minecraft:stained_hardened_clay
setblock ~5~40~17 minecraft:stained_hardened_clay
setblock ~5~41~17 minecraft:stained_hardened_clay
setblock ~5~42~17 minecraft:stained_hardened_clay
fill ~5~43~17 ~5~43~18 minecraft:stained_hardened_clay
setblock ~5~44~17 minecraft:stained_hardened_clay
fill ~5~45~17 ~5~46~17 minecraft:stained_hardened_clay
fill ~5~47~17 ~5~47~18 minecraft:stained_hardened_clay
fill ~5~48~17 ~5~48~18 minecraft:stained_hardened_clay
setblock ~5~49~17 minecraft:stained_hardened_clay
fill ~5~50~17 ~5~51~18 minecraft:stained_hardened_clay
setblock ~5~52~17 minecraft:stained_hardened_clay
fill ~5~53~17 ~5~53~18 minecraft:stained_hardened_clay
setblock ~5~54~17 minecraft:stained_hardened_clay
setblock ~5~55~17 minecraft:stained_hardened_clay
setblock ~5~56~17 minecraft:stained_hardened_clay
setblock ~5~57~17 minecraft:stained_hardened_clay
fill ~5~58~17 ~5~59~17 minecraft:stained_hardened_clay
setblock ~5~61~17 minecraft:stained_hardened_clay
fill ~5~63~17 ~5~63~18 minecraft:stained_hardened_clay
fill ~5~65~17 ~5~66~17 minecraft:stained_hardened_clay
fill ~5~67~17 ~5~68~17 minecraft:stained_hardened_clay
setblock ~5~69~17 minecraft:stained_hardened_clay
setblock ~5~70~17 minecraft:stained_hardened_clay
fill ~5~71~17 ~5~73~17 minecraft:stained_hardened_clay
fill ~5~74~17 ~5~76~17 minecraft:stained_hardened_clay
setblock ~5~78~17 minecraft:stained_hardened_clay
setblock ~5~79~17 minecraft:stained_hardened_clay
fill ~5~81~17 ~6~81~17 minecraft:cobblestone
setblock ~5~91~17 minecraft:concrete
setblock ~5~96~17 minecraft:stone_block_slab
setblock ~5~113~17 minecraft:gold_block
setblock ~6~14~17 minecraft:stonebrick
setblock ~6~16~17 minecraft:cobblestone
setblock ~6~17~17 minecraft:stone
setblock ~6~18~17 minecraft:stonebrick
setblock ~6~19~17 minecraft:cobblestone
fill ~6~20~17 ~6~20~18 minecraft:stonebrick
setblock ~6~21~17 minecraft:stonebrick
setblock ~6~57~17 minecraft:stonebrick
fill ~6~58~17 ~6~59~17 minecraft:cobblestone
setblock ~6~60~17 minecraft:stonebrick
fill ~6~61~17 ~6~61~18 minecraft:stone
fill ~6~62~17 ~6~63~17 minecraft:cobblestone
setblock ~6~64~17 minecraft:stonebrick
setblock ~6~65~17 minecraft:cobblestone
setblock ~6~66~17 minecraft:stone
setblock ~6~67~17 minecraft:cobblestone
fill ~6~68~17 ~6~69~17 minecraft:stonebrick
setblock ~6~70~17 minecraft:stonebrick
setblock ~6~77~17 minecraft:stonebrick
setblock ~6~78~17 minecraft:stonebrick
setblock ~6~79~17 minecraft:stonebrick
setblock ~6~80~17 minecraft:stone
setblock ~6~82~17 minecraft:stone
fill ~6~92~17 ~6~92~21 minecraft:bone_block
setblock ~6~113~17 minecraft:concrete
fill ~1~83~18 ~1~83~19 minecraft:stone
fill ~1~91~18 ~1~91~19 minecraft:stone
setblock ~2~18~18 minecraft:stonebrick
fill ~2~19~18 ~2~20~18 minecraft:stonebrick
fill ~2~21~18 ~2~21~19 minecraft:stonebrick
fill ~2~22~18 ~2~23~18 minecraft:cobblestone
fill ~2~24~18 ~2~24~19 minecraft:stonebrick
fill ~2~25~18 ~2~26~18 minecraft:cobblestone
setblock ~2~27~18 minecraft:stonebrick
setblock ~2~28~18 minecraft:stone
fill ~2~29~18 ~2~29~19 minecraft:stonebrick
fill ~2~30~18 ~2~31~18 minecraft:stonebrick
setblock ~2~32~18 minecraft:cobblestone
fill ~2~33~18 ~2~33~20 minecraft:stonebrick
setblock ~2~34~18 minecraft:stonebrick
setblock ~2~42~18 minecraft:stonebrick
setblock ~2~43~18 minecraft:cobblestone
fill ~2~44~18 ~2~45~18 minecraft:stonebrick
setblock ~2~46~18 minecraft:cobblestone
setblock ~2~47~18 minecraft:stonebrick
fill ~2~48~18 ~2~48~19 minecraft:stonebrick
setblock ~2~49~18 minecraft:cobblestone
setblock ~2~50~18 minecraft:stonebrick
fill ~2~51~18 ~2~52~18 minecraft:cobblestone
fill ~2~53~18 ~2~53~19 minecraft:stonebrick
setblock ~2~54~18 minecraft:stonebrick
fill ~2~55~18 ~2~56~18 minecraft:stonebrick
fill ~2~57~18 ~2~59~18 minecraft:stone
setblock ~2~61~18 minecraft:stonebrick
setblock ~2~63~18 minecraft:stonebrick
setblock ~2~65~18 minecraft:cobblestone
setblock ~2~67~18 minecraft:stonebrick
fill ~2~68~18 ~3~68~18 minecraft:stone
setblock ~2~69~18 minecraft:stone
fill ~2~70~18 ~3~70~18 minecraft:cobblestone
setblock ~2~71~18 minecraft:stonebrick
fill ~2~72~18 ~2~73~18 minecraft:stone
setblock ~2~74~18 minecraft:stonebrick
setblock ~2~75~18 minecraft:stonebrick
fill ~2~76~18 ~2~78~18 minecraft:stonebrick
setblock ~2~79~18 minecraft:stonebrick
setblock ~2~80~18 minecraft:stonebrick
setblock ~2~81~18 minecraft:stonebrick
setblock ~2~82~18 minecraft:quartz_block
fill ~2~83~18 ~2~83~19 minecraft:quartz_block
fill ~2~84~18 ~2~84~19 minecraft:stone
fill ~2~90~18 ~2~90~19 minecraft:stone
fill ~2~91~18 ~6~91~18 minecraft:quartz_block
setblock ~3~10~18 minecraft:stonebrick
setblock ~3~11~18 minecraft:stone
fill ~3~12~18 ~3~13~18 minecraft:stonebrick
setblock ~3~14~18 minecraft:stonebrick
setblock ~3~15~18 minecraft:stonebrick
fill ~3~16~18 ~3~16~19 minecraft:stonebrick
setblock ~3~17~18 minecraft:stonebrick
fill ~3~18~18 ~5~18~18 minecraft:cobblestone
fill ~3~20~18 ~3~21~18 minecraft:stained_hardened_clay
setblock ~3~22~18 minecraft:stained_hardened_clay
fill ~3~23~18 ~3~24~18 minecraft:stained_hardened_clay
setblock ~3~25~18 minecraft:stained_hardened_clay
setblock ~3~26~18 minecraft:stained_hardened_clay
setblock ~3~28~18 minecraft:stained_hardened_clay
setblock ~3~29~18 minecraft:stained_hardened_clay
setblock ~3~33~18 minecraft:stained_hardened_clay
fill ~3~34~18 ~3~35~18 minecraft:stained_hardened_clay
setblock ~3~36~18 minecraft:stained_hardened_clay
setblock ~3~38~18 minecraft:stained_hardened_clay
fill ~3~39~18 ~3~40~18 minecraft:stained_hardened_clay
fill ~3~41~18 ~3~42~18 minecraft:stained_hardened_clay
setblock ~3~47~18 minecraft:stained_hardened_clay
setblock ~3~48~18 minecraft:stained_hardened_clay
setblock ~3~52~18 minecraft:stained_hardened_clay
fill ~3~53~18 ~3~54~18 minecraft:stained_hardened_clay
fill ~3~55~18 ~3~56~18 minecraft:stained_hardened_clay
fill ~3~57~18 ~3~58~18 minecraft:stained_hardened_clay
setblock ~3~60~18 minecraft:stained_hardened_clay
setblock ~3~62~18 minecraft:stained_hardened_clay
setblock ~3~63~18 minecraft:stained_hardened_clay
fill ~3~64~18 ~3~65~18 minecraft:stained_hardened_clay
setblock ~3~66~18 minecraft:stained_hardened_clay
setblock ~3~67~18 minecraft:stained_hardened_clay
fill ~3~69~18 ~4~69~18 minecraft:cobblestone
fill ~3~71~18 ~3~71~19 minecraft:stonebrick
fill ~3~72~18 ~3~73~18 minecraft:stonebrick
setblock ~3~74~18 minecraft:stonebrick
fill ~3~75~18 ~4~75~18 minecraft:stone
fill ~3~76~18 ~3~76~19 minecraft:stonebrick
setblock ~3~77~18 minecraft:stonebrick
fill ~3~78~18 ~3~79~19 minecraft:stonebrick
fill ~3~80~18 ~3~81~18 minecraft:stonebrick
fill ~3~82~18 ~4~83~18 minecraft:stone
fill ~3~84~18 ~5~84~18 minecraft:concrete
setblock ~3~90~18 minecraft:concrete
fill ~3~112~18 ~5~112~18 minecraft:concrete
setblock ~3~113~18 minecraft:concrete
setblock ~4~7~18 minecraft:stonebrick
setblock ~4~8~18 minecraft:stonebrick
setblock ~4~9~18 minecraft:stonebrick
setblock ~4~10~18 minecraft:cobblestone
setblock ~4~11~18 minecraft:stonebrick
fill ~4~12~18 ~4~12~19 minecraft:stonebrick
setblock ~4~13~18 minecraft:stone
fill ~4~14~18 ~5~14~18 minecraft:cobblestone
setblock ~4~15~18 minecraft:stone
setblock ~4~17~18 minecraft:stonebrick
setblock ~4~19~18 minecraft:stone
fill ~4~20~18 ~4~23~18 minecraft:cobblestone
fill ~4~24~18 ~4~25~18 minecraft:stonebrick
setblock ~4~26~18 minecraft:stonebrick
setblock ~4~27~18 minecraft:cobblestone
setblock ~4~28~18 minecraft:stone
fill ~4~30~18 ~4~31~18 minecraft:cobblestone
setblock ~4~32~18 minecraft:stonebrick
setblock ~4~35~18 minecraft:stonebrick
fill ~4~36~18 ~4~37~18 minecraft:stone
setblock ~4~38~18 minecraft:stonebrick
setblock ~4~39~18 minecraft:stone
fill ~4~40~18 ~4~40~19 minecraft:stonebrick
fill ~4~41~18 ~4~42~18 minecraft:cobblestone
setblock ~4~43~18 minecraft:stonebrick
fill ~4~44~18 ~4~44~20 minecraft:stone
setblock ~4~45~18 minecraft:stonebrick
setblock ~4~46~18 minecraft:stonebrick
setblock ~4~47~18 minecraft:cobblestone
fill ~4~48~18 ~4~48~19 minecraft:stonebrick
setblock ~4~50~18 minecraft:stonebrick
setblock ~4~51~18 minecraft:stonebrick
setblock ~4~52~18 minecraft:cobblestone
setblock ~4~53~18 minecraft:stonebrick
setblock ~4~54~18 minecraft:stonebrick
setblock ~4~55~18 minecraft:stonebrick
setblock ~4~57~18 minecraft:cobblestone
setblock ~4~58~18 minecraft:stonebrick
setblock ~4~59~18 minecraft:stone
fill ~4~60~18 ~4~60~19 minecraft:cobblestone
setblock ~4~61~18 minecraft:stonebrick
fill ~4~62~18 ~4~63~18 minecraft:stonebrick
setblock ~4~64~18 minecraft:stonebrick
fill ~4~65~18 ~4~65~19 minecraft:cobblestone
setblock ~4~66~18 minecraft:stonebrick
setblock ~4~67~18 minecraft:cobblestone
fill ~4~68~18 ~4~68~19 minecraft:stonebrick
setblock ~4~70~18 minecraft:stonebrick
fill ~4~71~18 ~6~71~18 minecraft:stonebrick
setblock ~4~72~18 minecraft:stone
setblock ~4~73~18 minecraft:stonebrick
setblock ~4~74~18 minecraft:stonebrick
setblock ~4~76~18 minecraft:stonebrick
setblock ~4~77~18 minecraft:stone
fill ~4~78~18 ~4~79~18 minecraft:stonebrick
fill ~4~80~18 ~6~80~18 minecraft:stonebrick
setblock ~4~90~18 minecraft:concrete
setblock ~4~96~18 minecraft:quartz_block
setblock ~4~113~18 minecraft:stained_glass
setblock ~5~10~18 minecraft:stonebrick
setblock ~5~11~18 minecraft:cobblestone
fill ~5~12~18 ~5~13~18 minecraft:stonebrick
setblock ~5~15~18 minecraft:stonebrick
setblock ~5~16~18 minecraft:stone
setblock ~5~17~18 minecraft:cobblestone
setblock ~5~19~18 minecraft:stained_hardened_clay
setblock ~5~20~18 minecraft:stained_hardened_clay
setblock ~5~21~18 minecraft:stained_hardened_clay
fill ~5~23~18 ~5~24~18 minecraft:stained_hardened_clay
fill ~5~25~18 ~5~27~18 minecraft:stained_hardened_clay
setblock ~5~33~18 minecraft:stained_hardened_clay
fill ~5~34~18 ~5~35~18 minecraft:stained_hardened_clay
setblock ~5~36~18 minecraft:stained_hardened_clay
setblock ~5~37~18 minecraft:stained_hardened_clay
setblock ~5~38~18 minecraft:stained_hardened_clay
setblock ~5~39~18 minecraft:stained_hardened_clay
setblock ~5~40~18 minecraft:stained_hardened_clay
setblock ~5~41~18 minecraft:stained_hardened_clay
setblock ~5~42~18 minecraft:stained_hardened_clay
setblock ~5~44~18 minecraft:stained_hardened_clay
setblock ~5~45~18 minecraft:stained_hardened_clay
setblock ~5~46~18 minecraft:stained_hardened_clay
setblock ~5~49~18 minecraft:stained_hardened_clay
setblock ~5~52~18 minecraft:stained_hardened_clay
setblock ~5~54~18 minecraft:stained_hardened_clay
fill ~5~55~18 ~5~56~18 minecraft:stained_hardened_clay
setblock ~5~57~18 minecraft:stained_hardened_clay
setblock ~5~58~18 minecraft:stained_hardened_clay
fill ~5~59~18 ~5~60~18 minecraft:stained_hardened_clay
fill ~5~61~18 ~5~62~18 minecraft:stained_hardened_clay
fill ~5~64~18 ~5~65~18 minecraft:stained_hardened_clay
setblock ~5~66~18 minecraft:stained_hardened_clay
setblock ~5~67~18 minecraft:stained_hardened_clay
fill ~5~68~18 ~5~69~18 minecraft:stone
fill ~5~70~18 ~6~70~18 minecraft:stonebrick
setblock ~5~72~18 minecraft:stonebrick
fill ~5~73~18 ~5~73~19 minecraft:stone
fill ~5~74~18 ~6~74~18 minecraft:stonebrick
fill ~5~75~18 ~5~75~19 minecraft:stonebrick
fill ~5~76~18 ~5~76~19 minecraft:cobblestone
fill ~5~77~18 ~5~77~20 minecraft:stonebrick
fill ~5~78~18 ~6~78~18 minecraft:cobblestone
setblock ~5~79~18 minecraft:stonebrick
setblock ~5~81~18 minecraft:stone
setblock ~5~83~18 minecraft:stone
setblock ~5~90~18 minecraft:concrete
fill ~5~113~18 ~5~114~18 minecraft:concrete
setblock ~6~18~18 minecraft:stonebrick
setblock ~6~19~18 minecraft:stonebrick
fill ~6~21~18 ~6~21~19 minecraft:stonebrick
setblock ~6~22~18 minecraft:stonebrick
fill ~6~23~18 ~6~24~18 minecraft:stone
setblock ~6~25~18 minecraft:stonebrick
fill ~6~26~18 ~6~27~18 minecraft:cobblestone
setblock ~6~28~18 minecraft:stonebrick
setblock ~6~29~18 minecraft:cobblestone
setblock ~6~30~18 minecraft:stonebrick
setblock ~6~31~18 minecraft:stonebrick
fill ~6~32~18 ~6~32~19 minecraft:stonebrick
setblock ~6~33~18 minecraft:stonebrick
setblock ~6~34~18 minecraft:stonebrick
setblock ~6~42~18 minecraft:stonebrick
setblock ~6~43~18 minecraft:stone
fill ~6~44~18 ~6~46~18 minecraft:cobblestone
fill ~6~47~18 ~6~47~19 minecraft:stonebrick
fill ~6~48~18 ~6~49~18 minecraft:stonebrick
setblock ~6~50~18 minecraft:stone
setblock ~6~51~18 minecraft:stonebrick
setblock ~6~52~18 minecraft:stonebrick
setblock ~6~53~18 minecraft:cobblestone
fill ~6~54~18 ~6~54~19 minecraft:stonebrick
setblock ~6~55~18 minecraft:stonebrick
setblock ~6~56~18 minecraft:stonebrick
setblock ~6~57~18 minecraft:stonebrick
setblock ~6~58~18 minecraft:stonebrick
fill ~6~59~18 ~6~60~18 minecraft:stone
fill ~6~62~18 ~6~63~18 minecraft:stonebrick
setblock ~6~64~18 minecraft:stone
setblock ~6~65~18 minecraft:stonebrick
setblock ~6~66~18 minecraft:cobblestone
setblock ~6~67~18 minecraft:stonebrick
setblock ~6~68~18 minecraft:cobblestone
setblock ~6~69~18 minecraft:stonebrick
fill ~6~72~18 ~6~73~18 minecraft:stonebrick
setblock ~6~75~18 minecraft:stonebrick
setblock ~6~76~18 minecraft:stone
setblock ~6~77~18 minecraft:stonebrick
setblock ~6~79~18 minecraft:stonebrick
setblock ~6~81~18 minecraft:stonebrick
setblock ~6~82~18 minecraft:quartz_block
fill ~6~83~18 ~6~83~19 minecraft:quartz_block
fill ~6~84~18 ~6~84~19 minecraft:stone
fill ~6~90~18 ~6~90~19 minecraft:stone
fill ~7~83~18 ~7~83~19 minecraft:stone
fill ~7~91~18 ~7~91~19 minecraft:stone
setblock ~2~19~19 minecraft:cobblestone
setblock ~2~20~19 minecraft:stonebrick
setblock ~2~22~19 minecraft:stone
setblock ~2~23~19 minecraft:stonebrick
setblock ~2~25~19 minecraft:stonebrick
setblock ~2~26~19 minecraft:cobblestone
setblock ~2~27~19 minecraft:stone
fill ~2~28~19 ~3~28~19 minecraft:stonebrick
fill ~2~30~19 ~3~30~19 minecraft:stonebrick
setblock ~2~31~19 minecraft:stonebrick
setblock ~2~32~19 minecraft:stonebrick
setblock ~2~34~19 minecraft:stonebrick
setblock ~2~35~19 minecraft:cobblestone
setblock ~2~36~19 minecraft:stonebrick
setblock ~2~37~19 minecraft:stone
fill ~2~38~19 ~3~38~19 minecraft:cobblestone
fill ~2~39~19 ~3~39~19 minecraft:stonebrick
setblock ~2~40~19 minecraft:stonebrick
setblock ~2~41~19 minecraft:stone
setblock ~2~42~19 minecraft:stonebrick
fill ~2~43~19 ~3~43~19 minecraft:stone
fill ~2~44~19 ~3~44~19 minecraft:stonebrick
setblock ~2~45~19 minecraft:cobblestone
setblock ~2~46~19 minecraft:stonebrick
setblock ~2~47~19 minecraft:stonebrick
setblock ~2~49~19 minecraft:stonebrick
fill ~2~50~19 ~2~52~19 minecraft:stone
setblock ~2~54~19 minecraft:stonebrick
setblock ~2~55~19 minecraft:stonebrick
setblock ~2~56~19 minecraft:stonebrick
setblock ~2~57~19 minecraft:stonebrick
setblock ~2~69~19 minecraft:stonebrick
setblock ~2~70~19 minecraft:stonebrick
setblock ~2~71~19 minecraft:cobblestone
setblock ~2~72~19 minecraft:stonebrick
fill ~2~73~19 ~2~74~19 minecraft:stonebrick
setblock ~2~75~19 minecraft:stone
fill ~2~76~19 ~2~77~19 minecraft:stonebrick
setblock ~2~78~19 minecraft:cobblestone
setblock ~2~79~19 minecraft:stonebrick
setblock ~2~85~19 minecraft:stone
setblock ~2~89~19 minecraft:stone
fill ~2~91~19 ~2~91~24 minecraft:bone_block
setblock ~2~94~19 minecraft:stone_block_slab
setblock ~3~14~19 minecraft:stonebrick
setblock ~3~15~19 minecraft:stonebrick
fill ~3~17~19 ~4~17~19 minecraft:cobblestone
setblock ~3~18~19 minecraft:stone
fill ~3~19~19 ~4~19~19 minecraft:stonebrick
fill ~3~20~19 ~4~20~19 minecraft:stonebrick
fill ~3~21~19 ~3~21~20 minecraft:cobblestone
fill ~3~22~19 ~4~22~19 minecraft:stonebrick
fill ~3~23~19 ~3~23~20 minecraft:cobblestone
fill ~3~24~19 ~3~24~20 minecraft:stonebrick
setblock ~3~25~19 minecraft:stone
setblock ~3~26~19 minecraft:stonebrick
setblock ~3~27~19 minecraft:cobblestone
setblock ~3~29~19 minecraft:cobblestone
fill ~3~31~19 ~3~32~20 minecraft:stonebrick
fill ~3~33~19 ~3~33~20 minecraft:stone
setblock ~3~34~19 minecraft:stonebrick
setblock ~3~35~19 minecraft:stone
fill ~3~36~19 ~4~37~19 minecraft:stonebrick
fill ~3~40~19 ~3~40~20 minecraft:stonebrick
setblock ~3~41~19 minecraft:cobblestone
setblock ~3~42~19 minecraft:stone
fill ~3~45~19 ~3~45~20 minecraft:stone
setblock ~3~46~19 minecraft:stonebrick
fill ~3~47~19 ~4~47~19 minecraft:stonebrick
setblock ~3~48~19 minecraft:stone
fill ~3~49~19 ~3~50~19 minecraft:stonebrick
setblock ~3~51~19 minecraft:cobblestone
setblock ~3~52~19 minecraft:stonebrick
fill ~3~53~19 ~3~53~20 minecraft:stonebrick
setblock ~3~54~19 minecraft:stone
setblock ~3~55~19 minecraft:stonebrick
setblock ~3~56~19 minecraft:stone
fill ~3~57~19 ~5~57~19 minecraft:stonebrick
fill ~3~58~19 ~3~58~20 minecraft:cobblestone
fill ~3~59~19 ~4~59~19 minecraft:cobblestone
fill ~3~60~19 ~3~61~19 minecraft:stonebrick
setblock ~3~62~19 minecraft:cobblestone
fill ~3~63~19 ~5~63~19 minecraft:stonebrick
fill ~3~64~19 ~3~64~20 minecraft:cobblestone
setblock ~3~65~19 minecraft:cobblestone
fill ~3~66~19 ~3~67~19 minecraft:stonebrick
fill ~3~68~19 ~3~68~20 minecraft:stonebrick
fill ~3~69~19 ~3~70~19 minecraft:stone
setblock ~3~72~19 minecraft:stone
setblock ~3~73~19 minecraft:stonebrick
setblock ~3~74~19 minecraft:stonebrick
setblock ~3~75~19 minecraft:stonebrick
fill ~3~77~19 ~4~77~19 minecraft:stonebrick
fill ~3~80~19 ~3~80~20 minecraft:stonebrick
setblock ~3~81~19 minecraft:stone
setblock ~3~82~19 minecraft:stonebrick
setblock ~3~83~19 minecraft:stonebrick
fill ~3~84~19 ~5~84~20 minecraft:quartz_block
setblock ~3~85~19 minecraft:concrete
setblock ~3~89~19 minecraft:concrete
fill ~3~90~19 ~5~90~28 minecraft:quartz_block
fill ~3~91~19 ~5~91~27 minecraft:quartz_block
setblock ~3~95~19 minecraft:stone_block_slab
setblock ~4~10~19 minecraft:stonebrick
setblock ~4~11~19 minecraft:stone
setblock ~4~13~19 minecraft:stonebrick
setblock ~4~14~19 minecraft:stone
fill ~4~15~19 ~4~16~19 minecraft:stonebrick
setblock ~4~18~19 minecraft:stonebrick
setblock ~4~21~19 minecraft:stonebrick
setblock ~4~23~19 minecraft:stonebrick
setblock ~4~24~19 minecraft:cobblestone
setblock ~4~25~19 minecraft:stonebrick
setblock ~4~26~19 minecraft:cobblestone
fill ~4~27~19 ~5~27~19 minecraft:stone
fill ~4~28~19 ~4~28~20 minecraft:stonebrick
fill ~4~29~19 ~6~29~19 minecraft:stone
fill ~4~30~19 ~5~30~19 minecraft:stonebrick
fill ~4~31~19 ~4~32~19 minecraft:stonebrick
fill ~4~33~19 ~5~33~19 minecraft:stonebrick
fill ~4~35~19 ~5~35~19 minecraft:stonebrick
setblock ~4~38~19 minecraft:stonebrick
setblock ~4~39~19 minecraft:stonebrick
setblock ~4~41~19 minecraft:stonebrick
fill ~4~42~19 ~4~43~19 minecraft:stonebrick
setblock ~4~45~19 minecraft:stonebrick
setblock ~4~46~19 minecraft:stonebrick
setblock ~4~50~19 minecraft:stone
setblock ~4~51~19 minecraft:stonebrick
setblock ~4~52~19 minecraft:stonebrick
setblock ~4~53~19 minecraft:cobblestone
fill ~4~54~19 ~5~55~19 minecraft:stonebrick
setblock ~4~56~19 minecraft:stonebrick
fill ~4~58~19 ~4~58~20 minecraft:stonebrick
setblock ~4~61~19 minecraft:stonebrick
setblock ~4~62~19 minecraft:stonebrick
setblock ~4~64~19 minecraft:stonebrick
fill ~4~66~19 ~5~66~19 minecraft:stone
fill ~4~67~19 ~4~67~20 minecraft:stonebrick
fill ~4~69~19 ~4~70~19 minecraft:stonebrick
fill ~4~71~19 ~5~71~19 minecraft:stonebrick
fill ~4~72~19 ~4~72~20 minecraft:stonebrick
setblock ~4~73~19 minecraft:stonebrick
setblock ~4~74~19 minecraft:stonebrick
setblock ~4~75~19 minecraft:stonebrick
setblock ~4~76~19 minecraft:stone
setblock ~4~78~19 minecraft:stonebrick
fill ~4~79~19 ~4~80~19 minecraft:stonebrick
fill ~4~81~19 ~5~81~19 minecraft:cobblestone
setblock ~4~82~19 minecraft:cobblestone
fill ~4~83~19 ~4~83~20 minecraft:stone
fill ~4~85~19 ~5~85~19 minecraft:concrete
setblock ~4~89~19 minecraft:concrete
setblock ~4~96~19 minecraft:stone_block_slab
setblock ~5~14~19 minecraft:stonebrick
setblock ~5~15~19 minecraft:stonebrick
setblock ~5~16~19 minecraft:stonebrick
setblock ~5~17~19 minecraft:stonebrick
fill ~5~18~19 ~5~19~19 minecraft:cobblestone
fill ~5~20~19 ~6~20~19 minecraft:stonebrick
setblock ~5~21~19 minecraft:stonebrick
setblock ~5~22~19 minecraft:stonebrick
setblock ~5~23~19 minecraft:cobblestone
setblock ~5~24~19 minecraft:stonebrick
fill ~5~25~19 ~5~25~20 minecraft:stonebrick
setblock ~5~26~19 minecraft:stonebrick
fill ~5~28~19 ~6~28~19 minecraft:stonebrick
setblock ~5~31~19 minecraft:stonebrick
setblock ~5~32~19 minecraft:cobblestone
setblock ~5~34~19 minecraft:cobblestone
setblock ~5~36~19 minecraft:stone
fill ~5~37~19 ~5~37~20 minecraft:stonebrick
fill ~5~38~19 ~6~38~19 minecraft:cobblestone
fill ~5~39~19 ~5~40~19 minecraft:stonebrick
fill ~5~41~19 ~5~41~20 minecraft:stonebrick
fill ~5~42~19 ~5~43~19 minecraft:stonebrick
setblock ~5~44~19 minecraft:cobblestone
fill ~5~45~19 ~5~47~19 minecraft:stone
setblock ~5~48~19 minecraft:stonebrick
fill ~5~49~19 ~6~49~19 minecraft:stonebrick
fill ~5~50~19 ~5~50~20 minecraft:stonebrick
setblock ~5~51~19 minecraft:cobblestone
fill ~5~52~19 ~6~52~19 minecraft:stone
setblock ~5~53~19 minecraft:stone
setblock ~5~56~19 minecraft:stonebrick
setblock ~5~58~19 minecraft:stonebrick
fill ~5~59~19 ~5~59~20 minecraft:stonebrick
fill ~5~60~19 ~5~61~19 minecraft:stone
setblock ~5~62~19 minecraft:cobblestone
setblock ~5~64~19 minecraft:stone
setblock ~5~65~19 minecraft:stonebrick
fill ~5~67~19 ~5~67~20 minecraft:stone
fill ~5~68~19 ~5~68~20 minecraft:stonebrick
fill ~5~69~19 ~5~69~20 minecraft:stonebrick
fill ~5~70~19 ~6~70~19 minecraft:stonebrick
setblock ~5~72~19 minecraft:stone
setblock ~5~74~19 minecraft:cobblestone
fill ~5~78~19 ~5~79~19 minecraft:stone
setblock ~5~80~19 minecraft:stonebrick
setblock ~5~82~19 minecraft:stonebrick
setblock ~5~83~19 minecraft:stonebrick
setblock ~5~89~19 minecraft:concrete
setblock ~5~95~19 minecraft:stone_block_slab
setblock ~6~19~19 minecraft:stonebrick
setblock ~6~22~19 minecraft:stone
setblock ~6~23~19 minecraft:stonebrick
setblock ~6~24~19 minecraft:cobblestone
fill ~6~25~19 ~6~26~19 minecraft:stone
setblock ~6~27~19 minecraft:stonebrick
setblock ~6~30~19 minecraft:stone
setblock ~6~31~19 minecraft:cobblestone
setblock ~6~33~19 minecraft:cobblestone
setblock ~6~34~19 minecraft:stonebrick
setblock ~6~35~19 minecraft:stonebrick
setblock ~6~36~19 minecraft:stonebrick
fill ~6~37~19 ~6~37~20 minecraft:stonebrick
setblock ~6~39~19 minecraft:stone
setblock ~6~40~19 minecraft:cobblestone
fill ~6~41~19 ~6~42~20 minecraft:stonebrick
setblock ~6~43~19 minecraft:stonebrick
setblock ~6~44~19 minecraft:stone
setblock ~6~45~19 minecraft:stonebrick
setblock ~6~46~19 minecraft:stone
setblock ~6~48~19 minecraft:cobblestone
setblock ~6~50~19 minecraft:stonebrick
setblock ~6~51~19 minecraft:stone
setblock ~6~53~19 minecraft:stonebrick
setblock ~6~55~19 minecraft:stone
setblock ~6~56~19 minecraft:cobblestone
setblock ~6~57~19 minecraft:stonebrick
setblock ~6~69~19 minecraft:stonebrick
setblock ~6~71~19 minecraft:stonebrick
setblock ~6~72~19 minecraft:stonebrick
setblock ~6~73~19 minecraft:cobblestone
fill ~6~74~19 ~6~75~19 minecraft:stonebrick
setblock ~6~76~19 minecraft:stonebrick
setblock ~6~77~19 minecraft:cobblestone
setblock ~6~78~19 minecraft:stonebrick
setblock ~6~79~19 minecraft:stonebrick
setblock ~6~85~19 minecraft:stone
setblock ~6~89~19 minecraft:stone
fill ~6~91~19 ~6~91~24 minecraft:bone_block
setblock ~6~94~19 minecraft:stone_block_slab
fill ~1~84~20 ~1~85~20 minecraft:stone
fill ~1~89~20 ~1~90~20 minecraft:stone
setblock ~2~32~20 minecraft:stonebrick
fill ~2~34~20 ~3~34~20 minecraft:stonebrick
setblock ~2~35~20 minecraft:stonebrick
fill ~2~36~20 ~2~39~20 minecraft:stonebrick
setblock ~2~40~20 minecraft:cobblestone
setblock ~2~41~20 minecraft:stonebrick
setblock ~2~42~20 minecraft:cobblestone
fill ~2~43~20 ~3~43~20 minecraft:stonebrick
setblock ~2~44~20 minecraft:stonebrick
setblock ~2~83~20 minecraft:stone_block_slab
fill ~2~84~20 ~2~85~20 minecraft:quartz_block
fill ~2~86~20 ~2~88~20 minecraft:stone
fill ~2~89~20 ~5~89~20 minecraft:quartz_block
setblock ~2~90~20 minecraft:quartz_block
setblock ~3~19~20 minecraft:stonebrick
setblock ~3~20~20 minecraft:stone
setblock ~3~22~20 minecraft:cobblestone
setblock ~3~25~20 minecraft:stonebrick
setblock ~3~26~20 minecraft:stonebrick
fill ~3~27~20 ~3~27~21 minecraft:stonebrick
setblock ~3~28~20 minecraft:stone
setblock ~3~29~20 minecraft:stonebrick
setblock ~3~30~20 minecraft:stone
setblock ~3~35~20 minecraft:stonebrick
fill ~3~36~20 ~4~36~20 minecraft:stonebrick
fill ~3~37~20 ~3~38~21 minecraft:cobblestone
setblock ~3~39~20 minecraft:stone
fill ~3~41~20 ~4~41~20 minecraft:stonebrick
fill ~3~42~20 ~3~42~22 minecraft:stonebrick
setblock ~3~44~20 minecraft:stonebrick
setblock ~3~46~20 minecraft:stone
fill ~3~47~20 ~3~49~20 minecraft:stonebrick
setblock ~3~50~20 minecraft:cobblestone
setblock ~3~51~20 minecraft:stone
setblock ~3~52~20 minecraft:stonebrick
fill ~3~54~20 ~4~55~20 minecraft:stonebrick
setblock ~3~56~20 minecraft:stonebrick
setblock ~3~57~20 minecraft:stonebrick
setblock ~3~59~20 minecraft:stonebrick
setblock ~3~60~20 minecraft:stonebrick
setblock ~3~61~20 minecraft:cobblestone
setblock ~3~62~20 minecraft:stone
setblock ~3~63~20 minecraft:stonebrick
setblock ~3~65~20 minecraft:stonebrick
fill ~3~66~20 ~4~66~20 minecraft:stone
setblock ~3~67~20 minecraft:cobblestone
setblock ~3~69~20 minecraft:stonebrick
setblock ~3~70~20 minecraft:cobblestone
fill ~3~71~20 ~3~71~21 minecraft:stonebrick
setblock ~3~72~20 minecraft:stonebrick
setblock ~3~73~20 minecraft:cobblestone
setblock ~3~74~20 minecraft:stonebrick
setblock ~3~75~20 minecraft:stonebrick
fill ~3~76~20 ~3~77~20 minecraft:stone
fill ~3~78~20 ~3~78~21 minecraft:stonebrick
setblock ~3~79~20 minecraft:stonebrick
setblock ~3~81~20 minecraft:stonebrick
fill ~3~85~20 ~6~85~20 minecraft:quartz_block
fill ~3~86~20 ~4~86~20 minecraft:concrete
setblock ~3~87~20 minecraft:concrete
setblock ~3~88~20 minecraft:concrete
setblock ~4~14~20 minecraft:stonebrick
setblock ~4~15~20 minecraft:stone
setblock ~4~16~20 minecraft:stonebrick
setblock ~4~17~20 minecraft:cobblestone
setblock ~4~18~20 minecraft:stonebrick
setblock ~4~19~20 minecraft:stonebrick
fill ~4~20~20 ~4~20~21 minecraft:stonebrick
fill ~4~21~20 ~5~21~20 minecraft:cobblestone
setblock ~4~22~20 minecraft:stonebrick
setblock ~4~23~20 minecraft:stonebrick
fill ~4~24~20 ~5~24~20 minecraft:stonebrick
setblock ~4~25~20 minecraft:stonebrick
fill ~4~26~20 ~4~27~20 minecraft:stonebrick
fill ~4~29~20 ~5~29~20 minecraft:stone
fill ~4~30~20 ~4~30~22 minecraft:stonebrick
setblock ~4~31~20 minecraft:stone
setblock ~4~32~20 minecraft:stonebrick
fill ~4~33~20 ~4~33~23 minecraft:cobblestone
fill ~4~34~20 ~5~34~20 minecraft:stonebrick
setblock ~4~35~20 minecraft:cobblestone
setblock ~4~37~20 minecraft:stone
setblock ~4~38~20 minecraft:stonebrick
setblock ~4~39~20 minecraft:stonebrick
setblock ~4~40~20 minecraft:stone
fill ~4~42~20 ~4~43~20 minecraft:stonebrick
setblock ~4~45~20 minecraft:stone
setblock ~4~46~20 minecraft:cobblestone
setblock ~4~47~20 minecraft:stonebrick
setblock ~4~48~20 minecraft:cobblestone
setblock ~4~50~20 minecraft:stonebrick
setblock ~4~51~20 minecraft:stonebrick
fill ~4~52~20 ~4~52~21 minecraft:stonebrick
fill ~4~53~20 ~5~53~20 minecraft:stonebrick
setblock ~4~56~20 minecraft:stone
fill ~4~57~20 ~5~57~20 minecraft:stonebrick
fill ~4~59~20 ~4~59~21 minecraft:cobblestone
fill ~4~60~20 ~5~60~20 minecraft:stonebrick
fill ~4~61~20 ~5~61~20 minecraft:stonebrick
fill ~4~62~20 ~5~62~20 minecraft:stonebrick
fill ~4~63~20 ~4~63~21 minecraft:cobblestone
fill ~4~64~20 ~5~64~20 minecraft:stonebrick
fill ~4~65~20 ~4~65~21 minecraft:stonebrick
fill ~4~68~20 ~4~69~20 minecraft:stone
fill ~4~70~20 ~4~71~20 minecraft:stonebrick
fill ~4~73~20 ~4~73~21 minecraft:stonebrick
fill ~4~74~20 ~4~75~20 minecraft:stonebrick
setblock ~4~76~20 minecraft:stonebrick
fill ~4~77~20 ~4~78~20 minecraft:stone
setblock ~4~79~20 minecraft:stonebrick
fill ~4~80~20 ~4~81~20 minecraft:stonebrick
setblock ~4~82~20 minecraft:stonebrick
setblock ~4~87~20 minecraft:concrete
setblock ~4~88~20 minecraft:concrete
setblock ~5~19~20 minecraft:stonebrick
setblock ~5~20~20 minecraft:stonebrick
setblock ~5~22~20 minecraft:cobblestone
setblock ~5~23~20 minecraft:stonebrick
setblock ~5~26~20 minecraft:stonebrick
setblock ~5~27~20 minecraft:cobblestone
setblock ~5~28~20 minecraft:stonebrick
setblock ~5~30~20 minecraft:stone
setblock ~5~31~20 minecraft:stonebrick
fill ~5~32~20 ~5~33~20 minecraft:stonebrick
fill ~5~35~20 ~5~35~22 minecraft:stonebrick
setblock ~5~36~20 minecraft:stonebrick
fill ~5~38~20 ~5~39~20 minecraft:stonebrick
setblock ~5~40~20 minecraft:stonebrick
fill ~5~42~20 ~5~43~20 minecraft:stonebrick
fill ~5~44~20 ~5~44~21 minecraft:stonebrick
fill ~5~45~20 ~5~46~20 minecraft:stonebrick
fill ~5~47~20 ~5~47~21 minecraft:stone
setblock ~5~48~20 minecraft:stonebrick
setblock ~5~49~20 minecraft:cobblestone
fill ~5~51~20 ~5~51~21 minecraft:stonebrick
setblock ~5~52~20 minecraft:stone
setblock ~5~54~20 minecraft:cobblestone
setblock ~5~55~20 minecraft:stonebrick
setblock ~5~56~20 minecraft:cobblestone
setblock ~5~58~20 minecraft:stonebrick
setblock ~5~63~20 minecraft:stonebrick
setblock ~5~65~20 minecraft:stone
setblock ~5~66~20 minecraft:stonebrick
fill ~5~70~20 ~5~70~21 minecraft:stone
setblock ~5~71~20 minecraft:stonebrick
setblock ~5~72~20 minecraft:stonebrick
setblock ~5~73~20 minecraft:stonebrick
setblock ~5~74~20 minecraft:stonebrick
fill ~5~75~20 ~5~76~20 minecraft:stone
fill ~5~78~20 ~5~78~21 minecraft:stonebrick
setblock ~5~79~20 minecraft:stonebrick
setblock ~5~80~20 minecraft:cobblestone
setblock ~5~81~20 minecraft:stonebrick
fill ~5~86~20 ~5~88~20 minecraft:concrete
setblock ~6~32~20 minecraft:stonebrick
fill ~6~33~20 ~6~34~20 minecraft:stonebrick
setblock ~6~35~20 minecraft:stone
setblock ~6~36~20 minecraft:stonebrick
setblock ~6~38~20 minecraft:stone
setblock ~6~39~20 minecraft:stonebrick
setblock ~6~40~20 minecraft:stone
setblock ~6~43~20 minecraft:stone
setblock ~6~44~20 minecraft:stonebrick
setblock ~6~83~20 minecraft:stone_block_slab
setblock ~6~84~20 minecraft:quartz_block
fill ~6~86~20 ~6~88~20 minecraft:stone
fill ~6~89~20 ~6~90~21 minecraft:bone_block
fill ~7~84~20 ~7~85~20 minecraft:stone
fill ~7~89~20 ~7~90~20 minecraft:stone
fill ~1~86~21 ~1~88~21 minecraft:stone
fill ~2~85~21 ~3~85~21 minecraft:quartz_block
fill ~2~86~21 ~6~88~21 minecraft:quartz_block
fill ~2~89~21 ~2~90~21 minecraft:bone_block
setblock ~2~93~21 minecraft:stone_block_slab
setblock ~3~26~21 minecraft:stonebrick
setblock ~3~28~21 minecraft:cobblestone
fill ~3~29~21 ~4~29~21 minecraft:stone
setblock ~3~30~21 minecraft:cobblestone
setblock ~3~31~21 minecraft:stonebrick
setblock ~3~32~21 minecraft:stonebrick
setblock ~3~33~21 minecraft:stonebrick
setblock ~3~34~21 minecraft:stonebrick
setblock ~3~35~21 minecraft:cobblestone
fill ~3~36~21 ~4~36~21 minecraft:stonebrick
setblock ~3~39~21 minecraft:stonebrick
setblock ~3~40~21 minecraft:stonebrick
setblock ~3~41~21 minecraft:cobblestone
setblock ~3~43~21 minecraft:stonebrick
fill ~3~44~21 ~4~44~21 minecraft:stonebrick
fill ~3~45~21 ~3~46~21 minecraft:stonebrick
setblock ~3~47~21 minecraft:stonebrick
fill ~3~48~21 ~3~49~21 minecraft:stone
setblock ~3~50~21 minecraft:stonebrick
fill ~3~51~21 ~3~52~21 minecraft:stonebrick
setblock ~3~53~21 minecraft:stonebrick
setblock ~3~54~21 minecraft:cobblestone
setblock ~3~55~21 minecraft:stonebrick
setblock ~3~56~21 minecraft:cobblestone
setblock ~3~57~21 minecraft:stonebrick
setblock ~3~69~21 minecraft:stonebrick
setblock ~3~70~21 minecraft:stonebrick
fill ~3~72~21 ~5~72~21 minecraft:stonebrick
setblock ~3~73~21 minecraft:stone
setblock ~3~74~21 minecraft:stonebrick
setblock ~3~75~21 minecraft:cobblestone
setblock ~3~76~21 minecraft:stonebrick
setblock ~3~77~21 minecraft:stonebrick
setblock ~3~79~21 minecraft:stonebrick
fill ~3~89~21 ~5~89~28 minecraft:quartz_block
setblock ~3~94~21 minecraft:stone_block_slab
setblock ~4~19~21 minecraft:stonebrick
setblock ~4~21~21 minecraft:stonebrick
fill ~4~22~21 ~4~23~21 minecraft:stone
fill ~4~24~21 ~4~26~21 minecraft:stonebrick
fill ~4~27~21 ~5~27~21 minecraft:stone
setblock ~4~28~21 minecraft:stone
fill ~4~31~21 ~4~31~22 minecraft:stonebrick
setblock ~4~32~21 minecraft:stonebrick
setblock ~4~34~21 minecraft:stonebrick
setblock ~4~35~21 minecraft:stone
setblock ~4~37~21 minecraft:stonebrick
fill ~4~38~21 ~4~38~23 minecraft:stonebrick
setblock ~4~39~21 minecraft:stonebrick
setblock ~4~40~21 minecraft:cobblestone
setblock ~4~41~21 minecraft:stonebrick
fill ~4~42~21 ~5~42~21 minecraft:cobblestone
setblock ~4~43~21 minecraft:stonebrick
setblock ~4~45~21 minecraft:cobblestone
fill ~4~46~21 ~5~46~21 minecraft:stonebrick
setblock ~4~47~21 minecraft:stonebrick
setblock ~4~48~21 minecraft:stonebrick
setblock ~4~49~21 minecraft:stone
fill ~4~50~21 ~5~50~21 minecraft:stonebrick
setblock ~4~51~21 minecraft:cobblestone
setblock ~4~53~21 minecraft:stonebrick
setblock ~4~54~21 minecraft:stonebrick
fill ~4~55~21 ~4~55~22 minecraft:cobblestone
setblock ~4~56~21 minecraft:stonebrick
setblock ~4~57~21 minecraft:stone
setblock ~4~58~21 minecraft:stonebrick
setblock ~4~60~21 minecraft:cobblestone
setblock ~4~61~21 minecraft:stone
setblock ~4~62~21 minecraft:stonebrick
setblock ~4~64~21 minecraft:stonebrick
setblock ~4~66~21 minecraft:stonebrick
setblock ~4~67~21 minecraft:cobblestone
setblock ~4~68~21 minecraft:stonebrick
setblock ~4~69~21 minecraft:stonebrick
fill ~4~70~21 ~4~71~21 minecraft:cobblestone
setblock ~4~74~21 minecraft:stonebrick
setblock ~4~75~21 minecraft:stonebrick
setblock ~4~76~21 minecraft:stone
setblock ~4~77~21 minecraft:stonebrick
setblock ~4~78~21 minecraft:stonebrick
setblock ~4~79~21 minecraft:stone
setblock ~4~80~21 minecraft:stonebrick
setblock ~4~81~21 minecraft:stonebrick
setblock ~4~84~21 minecraft:quartz_block
fill ~4~85~21 ~4~85~22 minecraft:quartz_block
setblock ~4~95~21 minecraft:stone_block_slab
setblock ~5~26~21 minecraft:stonebrick
setblock ~5~28~21 minecraft:stonebrick
setblock ~5~29~21 minecraft:stonebrick
setblock ~5~30~21 minecraft:cobblestone
setblock ~5~31~21 minecraft:stonebrick
setblock ~5~32~21 minecraft:stonebrick
fill ~5~33~21 ~5~34~21 minecraft:stonebrick
setblock ~5~36~21 minecraft:stonebrick
fill ~5~37~21 ~5~37~22 minecraft:stone
fill ~5~38~21 ~5~39~21 minecraft:stone
setblock ~5~40~21 minecraft:stonebrick
fill ~5~41~21 ~5~41~22 minecraft:stonebrick
setblock ~5~43~21 minecraft:stonebrick
setblock ~5~45~21 minecraft:stonebrick
setblock ~5~48~21 minecraft:stonebrick
setblock ~5~49~21 minecraft:stonebrick
setblock ~5~52~21 minecraft:stonebrick
setblock ~5~53~21 minecraft:cobblestone
setblock ~5~54~21 minecraft:stonebrick
setblock ~5~55~21 minecraft:stonebrick
setblock ~5~56~21 minecraft:stone
setblock ~5~57~21 minecraft:stonebrick
setblock ~5~69~21 minecraft:stonebrick
setblock ~5~71~21 minecraft:stonebrick
setblock ~5~73~21 minecraft:stonebrick
setblock ~5~74~21 minecraft:stone
setblock ~5~75~21 minecraft:cobblestone
setblock ~5~76~21 minecraft:stonebrick
setblock ~5~77~21 minecraft:stone
setblock ~5~79~21 minecraft:stonebrick
fill ~5~85~21 ~6~85~21 minecraft:quartz_block
setblock ~5~94~21 minecraft:stone_block_slab
setblock ~6~93~21 minecraft:stone_block_slab
fill ~7~86~21 ~7~88~21 minecraft:stone
setblock ~2~89~22 minecraft:stone_block_slab
fill ~2~90~22 ~2~90~26 minecraft:bone_block
setblock ~2~92~22 minecraft:quartz_block
setblock ~3~32~22 minecraft:stonebrick
setblock ~3~33~22 minecraft:cobblestone
