setblock ~1~20~7 minecraft:end_rod 4
setblock ~2~20~7 minecraft:end_rod 5
setblock ~3~20~7 minecraft:end_rod 4
setblock ~4~20~7 minecraft:end_rod 5
setblock ~5~20~7 minecraft:end_rod 4
setblock ~6~20~7 minecraft:end_rod 5
setblock ~7~20~7 minecraft:end_rod 4
setblock ~8~20~7 minecraft:end_rod 5
setblock ~9~20~7 minecraft:end_rod 4
setblock ~10~20~7 minecraft:end_rod 5
setblock ~11~20~7 minecraft:end_rod 4
setblock ~12~20~7 minecraft:end_rod 5
setblock ~13~20~7 minecraft:end_rod 4
setblock ~14~20~7 minecraft:end_rod 5
setblock ~15~20~7 minecraft:end_rod 4
setblock ~16~20~7 minecraft:end_rod 5
setblock ~17~20~7 minecraft:end_rod 4
setblock ~18~20~7 minecraft:end_rod 5
setblock ~19~20~7 minecraft:end_rod 4
setblock ~20~20~7 minecraft:end_rod 5
setblock ~21~20~7 minecraft:end_rod 4
setblock ~22~20~7 minecraft:end_rod 5
setblock ~23~20~7 minecraft:end_rod 4
setblock ~24~20~7 minecraft:end_rod 5
fill ~25~20~7 ~28~20~7 minecraft:wool 0
setblock ~26~20~8 minecraft:wool 0
fill ~27~21~8 ~28~21~8 minecraft:wool 0
fill ~29~20~8 ~30~20~8 minecraft:wool 0
setblock ~3~20~9 minecraft:end_rod 4
setblock ~4~20~9 minecraft:end_rod 5
setblock ~5~20~9 minecraft:end_rod 4
setblock ~6~20~9 minecraft:end_rod 5
setblock ~7~20~9 minecraft:end_rod 4
setblock ~8~20~9 minecraft:end_rod 5
setblock ~9~20~9 minecraft:end_rod 4
setblock ~10~20~9 minecraft:end_rod 5
setblock ~11~20~9 minecraft:end_rod 4
setblock ~12~20~9 minecraft:end_rod 5
setblock ~13~20~9 minecraft:end_rod 4
setblock ~14~20~9 minecraft:end_rod 5
setblock ~15~20~9 minecraft:end_rod 4
setblock ~16~20~9 minecraft:end_rod 5
setblock ~17~20~9 minecraft:end_rod 4
setblock ~18~20~9 minecraft:end_rod 5
setblock ~19~20~9 minecraft:end_rod 4
setblock ~20~20~9 minecraft:end_rod 5
setblock ~21~20~9 minecraft:end_rod 4
setblock ~22~20~9 minecraft:end_rod 5
setblock ~23~20~9 minecraft:end_rod 4
setblock ~24~20~9 minecraft:end_rod 5
setblock ~25~20~9 minecraft:end_rod 4
setblock ~26~20~9 minecraft:end_rod 5
fill ~27~20~9 ~27~20~10 minecraft:wool 0
fill ~28~21~9 ~30~21~9 minecraft:wool 0
fill ~31~20~9 ~33~20~9 minecraft:wool 0
setblock ~28~21~10 minecraft:wool 0
fill ~29~22~10 ~30~22~10 minecraft:wool 0
fill ~31~21~10 ~33~21~10 minecraft:wool 0
fill ~34~20~10 ~35~20~10 minecraft:wool 0
setblock ~6~20~11 minecraft:end_rod 4
setblock ~7~20~11 minecraft:end_rod 5
setblock ~8~20~11 minecraft:end_rod 4
setblock ~9~20~11 minecraft:end_rod 5
setblock ~10~20~11 minecraft:end_rod 4
setblock ~11~20~11 minecraft:end_rod 5
setblock ~12~20~11 minecraft:end_rod 4
setblock ~13~20~11 minecraft:end_rod 5
setblock ~14~20~11 minecraft:end_rod 4
setblock ~15~20~11 minecraft:end_rod 5
setblock ~16~20~11 minecraft:end_rod 4
setblock ~17~20~11 minecraft:end_rod 5
setblock ~18~20~11 minecraft:end_rod 4
setblock ~19~20~11 minecraft:end_rod 5
setblock ~20~20~11 minecraft:end_rod 4
setblock ~21~20~11 minecraft:end_rod 5
setblock ~22~20~11 minecraft:end_rod 4
setblock ~23~20~11 minecraft:end_rod 5
setblock ~24~20~11 minecraft:end_rod 4
setblock ~25~20~11 minecraft:end_rod 5
setblock ~26~20~11 minecraft:end_rod 4
setblock ~27~20~11 minecraft:end_rod 5
fill ~28~20~11 ~28~20~12 minecraft:wool 0
fill ~29~21~11 ~29~21~12 minecraft:wool 0
fill ~30~22~11 ~32~22~12 minecraft:wool 0
fill ~32~21~11 ~35~21~12 minecraft:wool 0
fill ~36~20~11 ~41~20~11 minecraft:wool 0
fill ~30~23~12 ~31~23~12 minecraft:wool 0
fill ~33~22~12 ~33~22~13 minecraft:wool 0
fill ~36~21~12 ~41~21~12 minecraft:wool 0
fill ~42~20~12 ~43~20~12 minecraft:wool 0
setblock ~9~20~13 minecraft:end_rod 4
setblock ~10~20~13 minecraft:end_rod 5
setblock ~11~20~13 minecraft:end_rod 4
setblock ~12~20~13 minecraft:end_rod 5
setblock ~13~20~13 minecraft:end_rod 4
setblock ~14~20~13 minecraft:end_rod 5
setblock ~15~20~13 minecraft:end_rod 4
setblock ~16~20~13 minecraft:end_rod 5
setblock ~17~20~13 minecraft:end_rod 4
setblock ~18~20~13 minecraft:end_rod 5
setblock ~19~20~13 minecraft:end_rod 4
setblock ~20~20~13 minecraft:end_rod 5
setblock ~21~20~13 minecraft:end_rod 4
setblock ~22~20~13 minecraft:end_rod 5
setblock ~23~20~13 minecraft:end_rod 4
setblock ~24~20~13 minecraft:end_rod 5
setblock ~25~20~13 minecraft:end_rod 4
setblock ~26~20~13 minecraft:end_rod 5
setblock ~27~20~13 minecraft:end_rod 4
setblock ~28~20~13 minecraft:end_rod 5
setblock ~29~20~13 minecraft:wool 0
setblock ~30~21~13 minecraft:wool 0
fill ~31~22~13 ~32~22~13 minecraft:wool 0
setblock ~32~23~13 minecraft:wool 0
fill ~34~22~13 ~41~22~13 minecraft:wool 0
fill ~42~21~13 ~43~21~13 minecraft:wool 0
fill ~44~20~13 ~48~20~13 minecraft:wool 0
setblock ~30~20~14 minecraft:wool 0
setblock ~31~21~14 minecraft:wool 0
setblock ~32~22~14 minecraft:wool 0
setblock ~33~23~14 minecraft:wool 0
fill ~34~22~14 ~37~22~14 minecraft:wool 0
fill ~38~23~14 ~41~23~14 minecraft:wool 0
fill ~42~22~14 ~43~22~14 minecraft:wool 0
fill ~44~21~14 ~48~21~14 minecraft:wool 0
setblock ~49~20~14 minecraft:wool 0
setblock ~11~20~15 minecraft:end_rod 4
setblock ~12~20~15 minecraft:end_rod 5
setblock ~13~20~15 minecraft:end_rod 4
setblock ~14~20~15 minecraft:end_rod 5
setblock ~15~20~15 minecraft:end_rod 4
setblock ~16~20~15 minecraft:end_rod 5
setblock ~17~20~15 minecraft:end_rod 4
setblock ~18~20~15 minecraft:end_rod 5
setblock ~19~20~15 minecraft:end_rod 4
setblock ~20~20~15 minecraft:end_rod 5
setblock ~21~20~15 minecraft:end_rod 4
setblock ~22~20~15 minecraft:end_rod 5
setblock ~23~20~15 minecraft:end_rod 4
setblock ~24~20~15 minecraft:end_rod 5
setblock ~25~20~15 minecraft:end_rod 4
setblock ~26~20~15 minecraft:end_rod 5
setblock ~27~20~15 minecraft:end_rod 4
setblock ~28~20~15 minecraft:end_rod 5
setblock ~29~20~15 minecraft:end_rod 4
setblock ~30~20~15 minecraft:end_rod 5
setblock ~31~20~15 minecraft:wool 0
fill ~32~21~15 ~32~21~19 minecraft:wool 0
setblock ~33~22~15 minecraft:wool 0
fill ~34~23~15 ~37~23~15 minecraft:wool 0
fill ~36~24~15 ~40~24~15 minecraft:wool 0
fill ~41~23~15 ~43~23~15 minecraft:wool 0
fill ~44~22~15 ~48~22~15 minecraft:wool 0
setblock ~49~21~15 minecraft:wool 0
fill ~50~20~15 ~51~20~15 minecraft:wool 0
fill ~30~20~16 ~30~20~18 minecraft:wool 0
fill ~31~21~16 ~31~21~18 minecraft:wool 0
fill ~33~21~16 ~33~21~19 minecraft:wool 0
fill ~34~22~16 ~35~22~16 minecraft:wool 0
setblock ~36~23~16 minecraft:wool 0
fill ~37~24~16 ~41~24~16 minecraft:wool 0
fill ~42~23~16 ~46~23~16 minecraft:wool 0
fill ~47~22~16 ~49~22~16 minecraft:wool 0
fill ~50~21~16 ~51~21~16 minecraft:wool 0
setblock ~52~20~16 minecraft:wool 0
setblock ~14~20~17 minecraft:end_rod 4
setblock ~15~20~17 minecraft:end_rod 5
setblock ~16~20~17 minecraft:end_rod 4
setblock ~17~20~17 minecraft:end_rod 5
setblock ~18~20~17 minecraft:end_rod 4
setblock ~19~20~17 minecraft:end_rod 5
setblock ~20~20~17 minecraft:end_rod 4
setblock ~21~20~17 minecraft:end_rod 5
setblock ~22~20~17 minecraft:end_rod 4
setblock ~23~20~17 minecraft:end_rod 5
setblock ~24~20~17 minecraft:end_rod 4
setblock ~25~20~17 minecraft:end_rod 5
setblock ~26~20~17 minecraft:end_rod 4
setblock ~27~20~17 minecraft:end_rod 5
setblock ~28~20~17 minecraft:end_rod 4
setblock ~29~20~17 minecraft:end_rod 5
fill ~34~21~17 ~35~21~20 minecraft:wool 0
setblock ~36~22~17 minecraft:wool 0
setblock ~37~23~17 minecraft:wool 0
fill ~38~24~17 ~45~24~17 minecraft:wool 0
fill ~46~23~17 ~48~23~17 minecraft:wool 0
fill ~49~22~17 ~50~22~17 minecraft:wool 0
fill ~51~21~17 ~52~21~17 minecraft:wool 0
fill ~53~20~17 ~53~20~21 minecraft:wool 0
fill ~36~21~18 ~36~21~22 minecraft:wool 0
setblock ~37~22~18 minecraft:wool 0
setblock ~38~23~18 minecraft:wool 0
fill ~39~24~18 ~47~24~18 minecraft:wool 0
fill ~48~23~18 ~49~23~18 minecraft:wool 0
fill ~50~22~18 ~51~22~19 minecraft:wool 0
fill ~52~21~18 ~52~21~21 minecraft:wool 0
setblock ~17~20~19 minecraft:end_rod 4
setblock ~18~20~19 minecraft:end_rod 5
setblock ~19~20~19 minecraft:end_rod 4
setblock ~20~20~19 minecraft:end_rod 5
setblock ~21~20~19 minecraft:end_rod 4
setblock ~22~20~19 minecraft:end_rod 5
setblock ~23~20~19 minecraft:end_rod 4
setblock ~24~20~19 minecraft:end_rod 5
setblock ~25~20~19 minecraft:end_rod 4
setblock ~26~20~19 minecraft:end_rod 5
setblock ~27~20~19 minecraft:end_rod 4
setblock ~28~20~19 minecraft:end_rod 5
setblock ~29~20~19 minecraft:end_rod 4
setblock ~30~20~19 minecraft:end_rod 5
setblock ~31~20~19 minecraft:wool 0
fill ~37~21~19 ~37~21~23 minecraft:wool 0
setblock ~38~22~19 minecraft:wool 0
fill ~39~23~19 ~42~23~19 minecraft:wool 0
fill ~43~24~19 ~48~24~19 minecraft:wool 0
fill ~49~23~19 ~49~23~21 minecraft:wool 0
fill ~32~20~20 ~33~20~20 minecraft:wool 0
fill ~38~21~20 ~38~21~24 minecraft:wool 0
fill ~39~22~20 ~42~22~20 minecraft:wool 0
setblock ~43~23~20 minecraft:wool 0
fill ~44~24~20 ~48~24~20 minecraft:wool 0
setblock ~50~23~20 minecraft:wool 0
fill ~51~22~20 ~51~22~21 minecraft:wool 0
setblock ~20~20~21 minecraft:end_rod 4
setblock ~21~20~21 minecraft:end_rod 5
setblock ~22~20~21 minecraft:end_rod 4
setblock ~23~20~21 minecraft:end_rod 5
setblock ~24~20~21 minecraft:end_rod 4
setblock ~25~20~21 minecraft:end_rod 5
setblock ~26~20~21 minecraft:end_rod 4
setblock ~27~20~21 minecraft:end_rod 5
setblock ~28~20~21 minecraft:end_rod 4
setblock ~29~20~21 minecraft:end_rod 5
setblock ~30~20~21 minecraft:end_rod 4
setblock ~31~20~21 minecraft:end_rod 5
setblock ~32~20~21 minecraft:end_rod 4
setblock ~33~20~21 minecraft:end_rod 5
setblock ~34~20~21 minecraft:wool 0
setblock ~35~21~21 minecraft:wool 0
fill ~39~21~21 ~42~21~23 minecraft:wool 0
setblock ~43~22~21 minecraft:wool 0
setblock ~44~23~21 minecraft:wool 0
fill ~45~24~21 ~48~24~21 minecraft:wool 0
fill ~50~22~21 ~50~22~22 minecraft:wool 0
setblock ~35~20~22 minecraft:wool 0
setblock ~43~21~22 minecraft:wool 0
setblock ~44~22~22 minecraft:wool 0
fill ~45~23~22 ~48~23~22 minecraft:wool 0
setblock ~49~22~22 minecraft:wool 0
setblock ~51~21~22 minecraft:wool 0
setblock ~52~20~22 minecraft:wool 0
setblock ~24~20~23 minecraft:end_rod 4
setblock ~25~20~23 minecraft:end_rod 5
setblock ~26~20~23 minecraft:end_rod 4
setblock ~27~20~23 minecraft:end_rod 5
setblock ~28~20~23 minecraft:end_rod 4
setblock ~29~20~23 minecraft:end_rod 5
setblock ~30~20~23 minecraft:end_rod 4
setblock ~31~20~23 minecraft:end_rod 5
setblock ~32~20~23 minecraft:end_rod 4
setblock ~33~20~23 minecraft:end_rod 5
setblock ~34~20~23 minecraft:end_rod 4
setblock ~35~20~23 minecraft:end_rod 5
setblock ~36~20~23 minecraft:wool 0
fill ~43~22~23 ~43~22~24 minecraft:wool 0
fill ~44~23~23 ~46~23~23 minecraft:wool 0
fill ~47~22~23 ~48~22~23 minecraft:wool 0
fill ~49~21~23 ~50~21~23 minecraft:wool 0
setblock ~51~20~23 minecraft:wool 0
setblock ~37~20~24 minecraft:wool 0
fill ~39~22~24 ~42~22~24 minecraft:wool 0
fill ~44~22~24 ~47~22~24 minecraft:wool 0
setblock ~48~21~24 minecraft:wool 0
fill ~49~20~24 ~50~20~24 minecraft:wool 0
setblock ~30~20~25 minecraft:end_rod 4
setblock ~31~20~25 minecraft:end_rod 5
setblock ~32~20~25 minecraft:end_rod 4
setblock ~33~20~25 minecraft:end_rod 5
setblock ~34~20~25 minecraft:end_rod 4
setblock ~35~20~25 minecraft:end_rod 5
setblock ~36~20~25 minecraft:end_rod 4
setblock ~37~20~25 minecraft:end_rod 5
setblock ~38~20~25 minecraft:wool 0
fill ~39~21~25 ~47~21~25 minecraft:wool 0
fill ~48~19~25 ~48~20~25 minecraft:wool 0
setblock ~38~19~26 minecraft:wool 0
fill ~39~20~26 ~47~20~26 minecraft:wool 0
setblock ~47~19~26 minecraft:wool 0
fill ~39~19~27 ~46~19~27 minecraft:wool 0
setblock ~40~19~28 minecraft:wool 0
fill ~41~18~28 ~43~18~28 minecraft:wool 0
setblock ~44~19~28 minecraft:wool 0
fill ~27~8~29 ~34~8~42 minecraft:stained_glass 6
fill ~27~9~29 ~43~17~29 minecraft:stained_glass 6
fill ~35~18~29 ~53~18~29 minecraft:stained_glass 6
fill ~44~10~29 ~53~17~29 minecraft:stained_glass 6
fill ~44~19~29 ~53~19~42 minecraft:stained_glass 6
fill ~27~1~30 ~31~1~30 minecraft:stained_glass 6
fill ~27~9~30 ~27~17~42 minecraft:stained_glass 6
fill ~28~2~30 ~32~3~30 minecraft:stained_glass 6
fill ~28~17~30 ~34~17~42 minecraft:stained_glass 6
fill ~29~4~30 ~33~7~30 minecraft:stained_glass 6
fill ~35~9~30 ~43~9~42 minecraft:stained_glass 6
fill ~35~18~30 ~43~18~42 minecraft:stained_glass 6
fill ~44~10~30 ~47~10~42 minecraft:stained_glass 6
fill ~46~3~30 ~50~3~30 minecraft:stained_glass 6
fill ~47~4~30 ~51~5~30 minecraft:stained_glass 6
fill ~48~6~30 ~52~9~30 minecraft:stained_glass 6
fill ~53~10~30 ~53~18~42 minecraft:stained_glass 6
fill ~27~1~31 ~30~1~34 minecraft:stained_glass 6
fill ~28~2~31 ~28~3~34 minecraft:stained_glass 6
fill ~29~4~31 ~29~7~34 minecraft:stained_glass 6
setblock ~31~1~31 minecraft:stained_glass 15
fill ~32~2~31 ~32~3~34 minecraft:stained_glass 6
fill ~33~4~31 ~33~7~34 minecraft:stained_glass 6
fill ~46~3~31 ~49~3~34 minecraft:stained_glass 6
fill ~47~4~31 ~47~5~34 minecraft:stained_glass 6
fill ~48~6~31 ~48~9~34 minecraft:stained_glass 6
setblock ~50~3~31 minecraft:stained_glass 15
fill ~51~4~31 ~51~5~34 minecraft:stained_glass 6
fill ~52~6~31 ~52~9~34 minecraft:stained_glass 6
fill ~54~15~31 ~62~15~40 minecraft:stained_glass 6
fill ~54~16~31 ~62~23~31 minecraft:stained_glass 6
setblock ~31~1~32 minecraft:stained_glass 6
setblock ~50~3~32 minecraft:stained_glass 6
fill ~54~20~32 ~54~23~40 minecraft:stained_glass 6
fill ~54~24~32 ~62~24~32 minecraft:concrete 4
fill ~54~25~32 ~54~26~32 minecraft:concrete 4
fill ~55~23~32 ~62~23~40 minecraft:stained_glass 6
setblock ~55~25~32 minecraft:concrete 14
fill ~56~25~32 ~56~26~32 minecraft:concrete 4
setblock ~57~25~32 minecraft:concrete 5
setblock ~58~25~32 minecraft:concrete 3
setblock ~58~26~32 minecraft:concrete 4
setblock ~59~25~32 minecraft:concrete 4
setblock ~60~25~32 minecraft:concrete 14
setblock ~60~26~32 minecraft:concrete 4
fill ~61~25~32 ~62~25~32 minecraft:concrete 4
fill ~62~16~32 ~62~17~40 minecraft:stained_glass 6
fill ~62~18~32 ~62~20~33 minecraft:stained_glass 6
setblock ~62~21~32 minecraft:tinted_glass
fill ~62~22~32 ~62~22~40 minecraft:stained_glass 6
setblock ~62~26~32 minecraft:concrete 4
fill ~21~23~33 ~22~23~33 minecraft:stained_glass 6
fill ~22~21~33 ~24~21~33 minecraft:stained_glass 6
fill ~24~19~33 ~26~19~33 minecraft:stained_glass 6
fill ~26~20~33 ~26~20~36 minecraft:stained_glass 6
setblock ~31~1~33 minecraft:stained_glass 15
setblock ~50~3~33 minecraft:stained_glass 15
fill ~54~24~33 ~54~24~39 minecraft:concrete 4
setblock ~54~25~33 minecraft:concrete 5
setblock ~62~21~33 minecraft:stained_glass 0
fill ~62~24~33 ~62~24~39 minecraft:concrete 4
setblock ~62~25~33 minecraft:concrete 5
fill ~22~21~34 ~22~23~34 minecraft:stained_glass 6
fill ~24~19~34 ~24~19~35 minecraft:stained_glass 6
fill ~24~21~34 ~24~21~35 minecraft:stained_glass 6
fill ~26~17~34 ~26~17~36 minecraft:stained_glass 6
fill ~29~2~34 ~31~3~34 minecraft:stained_glass 6
fill ~30~4~34 ~32~7~34 minecraft:stained_glass 6
setblock ~31~1~34 minecraft:stained_glass 6
fill ~48~4~34 ~50~5~34 minecraft:stained_glass 6
fill ~49~6~34 ~51~9~34 minecraft:stained_glass 6
setblock ~50~3~34 minecraft:stained_glass 6
fill ~54~25~34 ~54~26~34 minecraft:concrete 4
setblock ~62~18~34 minecraft:stained_glass 14
fill ~62~19~34 ~62~20~40 minecraft:stained_glass 6
fill ~62~21~34 ~62~21~37 minecraft:stained_glass 6
fill ~62~25~34 ~62~26~34 minecraft:concrete 4
setblock ~24~20~35 minecraft:stained_glass 6
fill ~48~10~35 ~52~10~36 minecraft:stained_glass 6
setblock ~54~25~35 minecraft:concrete 3
fill ~62~18~35 ~62~18~36 minecraft:stained_glass 6
setblock ~62~25~35 minecraft:concrete 11
fill ~26~18~36 ~26~19~36 minecraft:stained_glass 6
setblock ~54~25~36 minecraft:concrete 14
setblock ~62~25~36 minecraft:concrete 4
fill ~27~1~37 ~31~1~37 minecraft:stained_glass 6
fill ~28~2~37 ~32~3~37 minecraft:stained_glass 6
fill ~29~4~37 ~33~7~37 minecraft:stained_glass 6
fill ~46~3~37 ~50~3~37 minecraft:stained_glass 6
fill ~47~4~37 ~51~5~37 minecraft:stained_glass 6
fill ~48~6~37 ~52~9~37 minecraft:stained_glass 6
fill ~54~25~37 ~54~26~37 minecraft:concrete 4
setblock ~62~18~37 minecraft:stained_glass 14
setblock ~62~25~37 minecraft:concrete 3
setblock ~62~26~37 minecraft:concrete 4
fill ~27~1~38 ~30~1~41 minecraft:stained_glass 6
fill ~28~2~38 ~28~3~41 minecraft:stained_glass 6
fill ~29~4~38 ~29~7~41 minecraft:stained_glass 6
setblock ~31~1~38 minecraft:stained_glass 15
fill ~32~2~38 ~32~3~41 minecraft:stained_glass 6
fill ~33~4~38 ~33~7~41 minecraft:stained_glass 6
fill ~46~3~38 ~49~3~41 minecraft:stained_glass 6
fill ~47~4~38 ~47~5~41 minecraft:stained_glass 6
fill ~48~6~38 ~48~9~41 minecraft:stained_glass 6
setblock ~50~3~38 minecraft:stained_glass 15
fill ~51~4~38 ~51~5~41 minecraft:stained_glass 6
fill ~52~6~38 ~52~9~41 minecraft:stained_glass 6
setblock ~54~25~38 minecraft:concrete 2
fill ~62~18~38 ~62~18~40 minecraft:stained_glass 6
setblock ~62~21~38 minecraft:stained_glass 0
fill ~62~25~38 ~62~25~39 minecraft:concrete 4
setblock ~31~1~39 minecraft:stained_glass 6
setblock ~50~3~39 minecraft:stained_glass 6
setblock ~54~25~39 minecraft:concrete 3
setblock ~54~26~39 minecraft:concrete 4
fill ~55~24~39 ~61~24~39 minecraft:concrete 4
setblock ~55~25~39 minecraft:concrete 4
setblock ~56~25~39 minecraft:concrete 5
setblock ~56~26~39 minecraft:concrete 4
setblock ~57~25~39 minecraft:concrete 4
setblock ~58~25~39 minecraft:concrete 2
setblock ~58~26~39 minecraft:concrete 4
setblock ~59~25~39 minecraft:concrete 14
fill ~60~25~39 ~60~26~39 minecraft:concrete 4
setblock ~61~25~39 minecraft:concrete 2
setblock ~62~21~39 minecraft:tinted_glass
setblock ~62~26~39 minecraft:concrete 4
setblock ~31~1~40 minecraft:stained_glass 15
setblock ~50~3~40 minecraft:stained_glass 15
fill ~54~16~40 ~61~19~40 minecraft:stained_glass 6
fill ~55~20~40 ~61~22~40 minecraft:stained_glass 6
setblock ~62~21~40 minecraft:stained_glass 6
fill ~29~2~41 ~31~3~41 minecraft:stained_glass 6
fill ~30~4~41 ~32~7~41 minecraft:stained_glass 6
setblock ~31~1~41 minecraft:stained_glass 6
fill ~48~4~41 ~50~5~41 minecraft:stained_glass 6
fill ~49~6~41 ~51~9~41 minecraft:stained_glass 6
setblock ~50~3~41 minecraft:stained_glass 6
fill ~28~9~42 ~34~16~42 minecraft:stained_glass 6
fill ~35~10~42 ~43~17~42 minecraft:stained_glass 6
fill ~44~11~42 ~52~18~42 minecraft:stained_glass 6
fill ~48~10~42 ~52~10~42 minecraft:stained_glass 6
fill ~40~19~43 ~40~19~44 minecraft:wool 0
fill ~41~18~43 ~43~18~43 minecraft:wool 0
fill ~44~19~43 ~44~19~44 minecraft:wool 0
setblock ~39~19~44 minecraft:wool 0
fill ~41~19~44 ~43~19~44 minecraft:wool 0
fill ~45~19~44 ~46~19~44 minecraft:wool 0
setblock ~38~19~45 minecraft:wool 0
fill ~39~20~45 ~47~20~45 minecraft:wool 0
setblock ~47~19~45 minecraft:wool 0
setblock ~30~20~46 minecraft:end_rod 4
setblock ~31~20~46 minecraft:end_rod 5
setblock ~32~20~46 minecraft:end_rod 4
setblock ~33~20~46 minecraft:end_rod 5
setblock ~34~20~46 minecraft:end_rod 4
setblock ~35~20~46 minecraft:end_rod 5
setblock ~36~20~46 minecraft:end_rod 4
setblock ~37~20~46 minecraft:end_rod 5
setblock ~38~20~46 minecraft:wool 0
fill ~39~21~46 ~47~21~46 minecraft:wool 0
fill ~48~19~46 ~48~20~46 minecraft:wool 0
setblock ~37~20~47 minecraft:wool 0
fill ~38~21~47 ~38~21~51 minecraft:wool 0
fill ~39~22~47 ~47~22~47 minecraft:wool 0
setblock ~48~21~47 minecraft:wool 0
fill ~49~20~47 ~50~20~47 minecraft:wool 0
setblock ~24~20~48 minecraft:end_rod 4
setblock ~25~20~48 minecraft:end_rod 5
setblock ~26~20~48 minecraft:end_rod 4
setblock ~27~20~48 minecraft:end_rod 5
setblock ~28~20~48 minecraft:end_rod 4
setblock ~29~20~48 minecraft:end_rod 5
setblock ~30~20~48 minecraft:end_rod 4
setblock ~31~20~48 minecraft:end_rod 5
setblock ~32~20~48 minecraft:end_rod 4
setblock ~33~20~48 minecraft:end_rod 5
setblock ~34~20~48 minecraft:end_rod 4
setblock ~35~20~48 minecraft:end_rod 5
setblock ~36~20~48 minecraft:wool 0
fill ~37~21~48 ~37~21~52 minecraft:wool 0
fill ~39~21~48 ~42~21~50 minecraft:wool 0
setblock ~43~22~48 minecraft:wool 0
fill ~44~23~48 ~46~23~48 minecraft:wool 0
fill ~47~22~48 ~48~22~48 minecraft:wool 0
fill ~49~21~48 ~50~21~48 minecraft:wool 0
setblock ~51~20~48 minecraft:wool 0
setblock ~35~20~49 minecraft:wool 0
fill ~36~21~49 ~36~21~53 minecraft:wool 0
setblock ~43~21~49 minecraft:wool 0
setblock ~44~22~49 minecraft:wool 0
fill ~45~23~49 ~48~23~49 minecraft:wool 0
fill ~49~22~49 ~50~22~49 minecraft:wool 0
setblock ~51~21~49 minecraft:wool 0
setblock ~52~20~49 minecraft:wool 0
setblock ~20~20~50 minecraft:end_rod 4
setblock ~21~20~50 minecraft:end_rod 5
setblock ~22~20~50 minecraft:end_rod 4
setblock ~23~20~50 minecraft:end_rod 5
setblock ~24~20~50 minecraft:end_rod 4
setblock ~25~20~50 minecraft:end_rod 5
setblock ~26~20~50 minecraft:end_rod 4
setblock ~27~20~50 minecraft:end_rod 5
setblock ~28~20~50 minecraft:end_rod 4
setblock ~29~20~50 minecraft:end_rod 5
setblock ~30~20~50 minecraft:end_rod 4
setblock ~31~20~50 minecraft:end_rod 5
setblock ~32~20~50 minecraft:end_rod 4
setblock ~33~20~50 minecraft:end_rod 5
setblock ~34~20~50 minecraft:wool 0
fill ~35~21~50 ~35~21~54 minecraft:wool 0
setblock ~43~22~50 minecraft:wool 0
setblock ~44~23~50 minecraft:wool 0
fill ~45~24~50 ~48~24~52 minecraft:wool 0
fill ~49~23~50 ~49~23~53 minecraft:wool 0
fill ~50~22~50 ~51~22~50 minecraft:wool 0
fill ~52~21~50 ~52~21~54 minecraft:wool 0
fill ~53~20~50 ~53~20~54 minecraft:wool 0
fill ~32~20~51 ~33~20~51 minecraft:wool 0
fill ~34~21~51 ~34~21~54 minecraft:wool 0
fill ~39~22~51 ~42~22~51 minecraft:wool 0
setblock ~43~23~51 minecraft:wool 0
fill ~44~24~51 ~44~24~54 minecraft:wool 0
setblock ~50~23~51 minecraft:wool 0
fill ~51~22~51 ~51~22~53 minecraft:wool 0
setblock ~17~20~52 minecraft:end_rod 4
setblock ~18~20~52 minecraft:end_rod 5
setblock ~19~20~52 minecraft:end_rod 4
setblock ~20~20~52 minecraft:end_rod 5
setblock ~21~20~52 minecraft:end_rod 4
setblock ~22~20~52 minecraft:end_rod 5
setblock ~23~20~52 minecraft:end_rod 4
setblock ~24~20~52 minecraft:end_rod 5
setblock ~25~20~52 minecraft:end_rod 4
setblock ~26~20~52 minecraft:end_rod 5
setblock ~27~20~52 minecraft:end_rod 4
setblock ~28~20~52 minecraft:end_rod 5
setblock ~29~20~52 minecraft:end_rod 4
setblock ~30~20~52 minecraft:end_rod 5
setblock ~31~20~52 minecraft:wool 0
fill ~32~21~52 ~33~21~55 minecraft:wool 0
setblock ~38~22~52 minecraft:wool 0
fill ~39~23~52 ~42~23~52 minecraft:wool 0
fill ~43~24~52 ~43~24~54 minecraft:wool 0
fill ~50~22~52 ~50~22~54 minecraft:wool 0
fill ~30~20~53 ~30~20~55 minecraft:wool 0
fill ~31~21~53 ~31~21~55 minecraft:wool 0
setblock ~37~22~53 minecraft:wool 0
setblock ~38~23~53 minecraft:wool 0
fill ~39~24~53 ~42~24~54 minecraft:wool 0
fill ~45~24~53 ~47~24~53 minecraft:wool 0
fill ~48~23~53 ~48~23~54 minecraft:wool 0
setblock ~14~20~54 minecraft:end_rod 4
setblock ~15~20~54 minecraft:end_rod 5
setblock ~16~20~54 minecraft:end_rod 4
setblock ~17~20~54 minecraft:end_rod 5
setblock ~18~20~54 minecraft:end_rod 4
setblock ~19~20~54 minecraft:end_rod 5
setblock ~20~20~54 minecraft:end_rod 4
setblock ~21~20~54 minecraft:end_rod 5
setblock ~22~20~54 minecraft:end_rod 4
setblock ~23~20~54 minecraft:end_rod 5
setblock ~24~20~54 minecraft:end_rod 4
setblock ~25~20~54 minecraft:end_rod 5
setblock ~26~20~54 minecraft:end_rod 4
setblock ~27~20~54 minecraft:end_rod 5
setblock ~28~20~54 minecraft:end_rod 4
setblock ~29~20~54 minecraft:end_rod 5
setblock ~36~22~54 minecraft:wool 0
setblock ~37~23~54 minecraft:wool 0
fill ~38~24~54 ~38~24~56 minecraft:wool 0
setblock ~45~24~54 minecraft:wool 0
fill ~46~23~54 ~47~23~54 minecraft:wool 0
fill ~49~22~54 ~49~22~55 minecraft:wool 0
fill ~51~21~54 ~51~21~55 minecraft:wool 0
fill ~34~22~55 ~35~22~55 minecraft:wool 0
fill ~36~23~55 ~36~23~56 minecraft:wool 0
fill ~37~24~55 ~37~24~56 minecraft:wool 0
fill ~39~24~55 ~41~24~55 minecraft:wool 0
fill ~42~23~55 ~46~23~55 minecraft:wool 0
fill ~47~22~55 ~48~22~56 minecraft:wool 0
setblock ~50~21~55 minecraft:wool 0
setblock ~52~20~55 minecraft:wool 0
setblock ~11~20~56 minecraft:end_rod 4
setblock ~12~20~56 minecraft:end_rod 5
setblock ~13~20~56 minecraft:end_rod 4
setblock ~14~20~56 minecraft:end_rod 5
setblock ~15~20~56 minecraft:end_rod 4
setblock ~16~20~56 minecraft:end_rod 5
setblock ~17~20~56 minecraft:end_rod 4
setblock ~18~20~56 minecraft:end_rod 5
setblock ~19~20~56 minecraft:end_rod 4
setblock ~20~20~56 minecraft:end_rod 5
setblock ~21~20~56 minecraft:end_rod 4
setblock ~22~20~56 minecraft:end_rod 5
setblock ~23~20~56 minecraft:end_rod 4
setblock ~24~20~56 minecraft:end_rod 5
setblock ~25~20~56 minecraft:end_rod 4
setblock ~26~20~56 minecraft:end_rod 5
setblock ~27~20~56 minecraft:end_rod 4
setblock ~28~20~56 minecraft:end_rod 5
setblock ~29~20~56 minecraft:end_rod 4
setblock ~30~20~56 minecraft:end_rod 5
setblock ~31~20~56 minecraft:wool 0
setblock ~32~21~56 minecraft:wool 0
setblock ~33~22~56 minecraft:wool 0
fill ~34~23~56 ~35~23~56 minecraft:wool 0
setblock ~36~24~56 minecraft:wool 0
setblock ~37~23~56 minecraft:wool 0
fill ~39~24~56 ~40~24~56 minecraft:wool 0
fill ~41~23~56 ~43~23~56 minecraft:wool 0
fill ~44~22~56 ~46~22~56 minecraft:wool 0
setblock ~49~21~56 minecraft:wool 0
fill ~50~20~56 ~51~20~56 minecraft:wool 0
setblock ~30~20~57 minecraft:wool 0
setblock ~31~21~57 minecraft:wool 0
fill ~32~22~57 ~32~22~60 minecraft:wool 0
setblock ~33~23~57 minecraft:wool 0
fill ~34~22~57 ~37~22~58 minecraft:wool 0
fill ~38~23~57 ~41~23~57 minecraft:wool 0
fill ~42~22~57 ~43~22~57 minecraft:wool 0
fill ~44~21~57 ~48~21~57 minecraft:wool 0
setblock ~49~20~57 minecraft:wool 0
setblock ~9~20~58 minecraft:end_rod 4
setblock ~10~20~58 minecraft:end_rod 5
setblock ~11~20~58 minecraft:end_rod 4
setblock ~12~20~58 minecraft:end_rod 5
setblock ~13~20~58 minecraft:end_rod 4
setblock ~14~20~58 minecraft:end_rod 5
setblock ~15~20~58 minecraft:end_rod 4
setblock ~16~20~58 minecraft:end_rod 5
setblock ~17~20~58 minecraft:end_rod 4
setblock ~18~20~58 minecraft:end_rod 5
setblock ~19~20~58 minecraft:end_rod 4
setblock ~20~20~58 minecraft:end_rod 5
setblock ~21~20~58 minecraft:end_rod 4
setblock ~22~20~58 minecraft:end_rod 5
setblock ~23~20~58 minecraft:end_rod 4
setblock ~24~20~58 minecraft:end_rod 5
setblock ~25~20~58 minecraft:end_rod 4
setblock ~26~20~58 minecraft:end_rod 5
setblock ~27~20~58 minecraft:end_rod 4
setblock ~28~20~58 minecraft:end_rod 5
setblock ~29~20~58 minecraft:wool 0
setblock ~30~21~58 minecraft:wool 0
fill ~31~22~58 ~31~22~60 minecraft:wool 0
setblock ~32~23~58 minecraft:wool 0
fill ~33~22~58 ~33~22~59 minecraft:wool 0
fill ~38~22~58 ~41~22~58 minecraft:wool 0
fill ~42~21~58 ~43~21~58 minecraft:wool 0
fill ~44~20~58 ~48~20~58 minecraft:wool 0
fill ~28~20~59 ~28~20~60 minecraft:wool 0
fill ~29~21~59 ~29~21~60 minecraft:wool 0
fill ~30~22~59 ~30~22~61 minecraft:wool 0
fill ~30~23~59 ~31~23~59 minecraft:wool 0
fill ~32~21~59 ~41~21~59 minecraft:wool 0
fill ~42~20~59 ~43~20~59 minecraft:wool 0
setblock ~6~20~60 minecraft:end_rod 4
setblock ~7~20~60 minecraft:end_rod 5
setblock ~8~20~60 minecraft:end_rod 4
setblock ~9~20~60 minecraft:end_rod 5
setblock ~10~20~60 minecraft:end_rod 4
setblock ~11~20~60 minecraft:end_rod 5
setblock ~12~20~60 minecraft:end_rod 4
setblock ~13~20~60 minecraft:end_rod 5
setblock ~14~20~60 minecraft:end_rod 4
setblock ~15~20~60 minecraft:end_rod 5
setblock ~16~20~60 minecraft:end_rod 4
setblock ~17~20~60 minecraft:end_rod 5
setblock ~18~20~60 minecraft:end_rod 4
setblock ~19~20~60 minecraft:end_rod 5
setblock ~20~20~60 minecraft:end_rod 4
setblock ~21~20~60 minecraft:end_rod 5
setblock ~22~20~60 minecraft:end_rod 4
setblock ~23~20~60 minecraft:end_rod 5
setblock ~24~20~60 minecraft:end_rod 4
setblock ~25~20~60 minecraft:end_rod 5
setblock ~26~20~60 minecraft:end_rod 4
setblock ~27~20~60 minecraft:end_rod 5
fill ~32~21~60 ~35~21~60 minecraft:wool 0
fill ~36~20~60 ~41~20~60 minecraft:wool 0
fill ~27~20~61 ~27~20~62 minecraft:wool 0
fill ~28~21~61 ~28~21~63 minecraft:wool 0
setblock ~29~22~61 minecraft:wool 0
fill ~31~21~61 ~33~21~61 minecraft:wool 0
fill ~34~20~61 ~35~20~61 minecraft:wool 0
setblock ~3~20~62 minecraft:end_rod 4
setblock ~4~20~62 minecraft:end_rod 5
setblock ~5~20~62 minecraft:end_rod 4
setblock ~6~20~62 minecraft:end_rod 5
setblock ~7~20~62 minecraft:end_rod 4
setblock ~8~20~62 minecraft:end_rod 5
setblock ~9~20~62 minecraft:end_rod 4
setblock ~10~20~62 minecraft:end_rod 5
setblock ~11~20~62 minecraft:end_rod 4
setblock ~12~20~62 minecraft:end_rod 5
setblock ~13~20~62 minecraft:end_rod 4
setblock ~14~20~62 minecraft:end_rod 5
setblock ~15~20~62 minecraft:end_rod 4
setblock ~16~20~62 minecraft:end_rod 5
setblock ~17~20~62 minecraft:end_rod 4
setblock ~18~20~62 minecraft:end_rod 5
setblock ~19~20~62 minecraft:end_rod 4
setblock ~20~20~62 minecraft:end_rod 5
setblock ~21~20~62 minecraft:end_rod 4
setblock ~22~20~62 minecraft:end_rod 5
setblock ~23~20~62 minecraft:end_rod 4
setblock ~24~20~62 minecraft:end_rod 5
setblock ~25~20~62 minecraft:end_rod 4
setblock ~26~20~62 minecraft:end_rod 5
fill ~29~21~62 ~30~21~62 minecraft:wool 0
fill ~31~20~62 ~33~20~62 minecraft:wool 0
fill ~26~20~63 ~26~20~64 minecraft:wool 0
setblock ~27~21~63 minecraft:wool 0
fill ~29~20~63 ~30~20~63 minecraft:wool 0
setblock ~1~20~64 minecraft:end_rod 4
setblock ~2~20~64 minecraft:end_rod 5
setblock ~3~20~64 minecraft:end_rod 4
setblock ~4~20~64 minecraft:end_rod 5
setblock ~5~20~64 minecraft:end_rod 4
setblock ~6~20~64 minecraft:end_rod 5
setblock ~7~20~64 minecraft:end_rod 4
setblock ~8~20~64 minecraft:end_rod 5
setblock ~9~20~64 minecraft:end_rod 4
setblock ~10~20~64 minecraft:end_rod 5
setblock ~11~20~64 minecraft:end_rod 4
setblock ~12~20~64 minecraft:end_rod 5
setblock ~13~20~64 minecraft:end_rod 4
setblock ~14~20~64 minecraft:end_rod 5
setblock ~15~20~64 minecraft:end_rod 4
setblock ~16~20~64 minecraft:end_rod 5
setblock ~17~20~64 minecraft:end_rod 4
setblock ~18~20~64 minecraft:end_rod 5
setblock ~19~20~64 minecraft:end_rod 4
setblock ~20~20~64 minecraft:end_rod 5
setblock ~21~20~64 minecraft:end_rod 4
setblock ~22~20~64 minecraft:end_rod 5
setblock ~23~20~64 minecraft:end_rod 4
setblock ~24~20~64 minecraft:end_rod 5
setblock ~25~20~64 minecraft:wool 0
fill ~27~20~64 ~28~20~64 minecraft:wool 0