fill ~3~0~0 ~31~0~11 minecraft:stonebrick 0
fill ~3~1~0 ~31~1~0 minecraft:stonebrick 0
fill ~3~10~0 ~5~10~0 minecraft:stone_brick_stairs 6
fill ~3~11~0 ~3~13~0 minecraft:stonebrick 0
setblock ~3~14~0 minecraft:redstone_torch 5
fill ~4~11~0 ~4~11~1 minecraft:stonebrick 3
fill ~4~12~0 ~4~13~0 minecraft:stonebrick 3
fill ~5~11~0 ~7~11~2 minecraft:stonebrick 0
fill ~5~12~0 ~7~12~0 minecraft:stonebrick 0
setblock ~6~13~0 minecraft:stonebrick 0
fill ~7~10~0 ~8~10~0 minecraft:stone_brick_stairs 6
fill ~8~12~0 ~8~13~0 minecraft:stonebrick 3
fill ~9~10~0 ~9~10~3 minecraft:stone_brick_stairs 5
fill ~9~11~0 ~9~13~0 minecraft:stonebrick 0
setblock ~9~14~0 minecraft:redstone_torch 5
fill ~25~10~0 ~25~10~3 minecraft:stone_brick_stairs 4
fill ~25~11~0 ~25~13~0 minecraft:stonebrick 0
setblock ~25~14~0 minecraft:redstone_torch 5
fill ~26~10~0 ~27~10~0 minecraft:stone_brick_stairs 6
fill ~26~11~0 ~26~11~1 minecraft:stonebrick 3
fill ~26~12~0 ~26~13~0 minecraft:stonebrick 3
fill ~27~11~0 ~29~11~2 minecraft:stonebrick 0
fill ~27~12~0 ~29~12~0 minecraft:stonebrick 0
setblock ~28~13~0 minecraft:stonebrick 0
fill ~29~10~0 ~31~10~0 minecraft:stone_brick_stairs 6
fill ~30~11~0 ~30~11~1 minecraft:stonebrick 3
fill ~30~12~0 ~30~13~0 minecraft:stonebrick 3
fill ~31~11~0 ~31~13~0 minecraft:stonebrick 0
setblock ~31~14~0 minecraft:redstone_torch 5
fill ~32~0~0 ~32~0~24 minecraft:dirt 0
fill ~32~1~0 ~32~1~10 minecraft:grass
fill ~3~1~1 ~3~1~28 minecraft:stonebrick 0
fill ~3~10~1 ~3~10~2 minecraft:stone_brick_stairs 4
fill ~3~11~1 ~3~13~1 minecraft:stonebrick 3
fill ~4~1~1 ~4~10~1 minecraft:stonebrick 3
fill ~5~1~1 ~7~1~28 minecraft:stonebrick 0
fill ~5~2~1 ~7~3~27 minecraft:stonebrick 0
fill ~5~4~1 ~7~7~5 minecraft:stonebrick 0
fill ~5~8~1 ~7~8~1 minecraft:stonebrick 0
fill ~5~9~1 ~5~10~1 minecraft:stonebrick 0
setblock ~6~10~1 minecraft:iron_bars
fill ~7~9~1 ~7~10~1 minecraft:stonebrick 0
fill ~8~1~1 ~8~10~1 minecraft:stonebrick 3
fill ~9~1~1 ~25~2~5 minecraft:stonebrick 0
fill ~9~11~1 ~9~13~1 minecraft:stonebrick 3
fill ~25~11~1 ~25~13~1 minecraft:stonebrick 3
fill ~26~1~1 ~26~10~1 minecraft:stonebrick 3
fill ~27~1~1 ~29~1~28 minecraft:stonebrick 0
fill ~27~2~1 ~29~3~27 minecraft:stonebrick 0
fill ~27~4~1 ~29~7~5 minecraft:stonebrick 0
fill ~27~8~1 ~29~8~1 minecraft:stonebrick 0
fill ~27~9~1 ~27~10~1 minecraft:stonebrick 0
setblock ~28~10~1 minecraft:iron_bars
fill ~29~9~1 ~29~10~1 minecraft:stonebrick 0
fill ~30~1~1 ~30~10~1 minecraft:stonebrick 3
fill ~31~1~1 ~31~1~28 minecraft:stonebrick 0
fill ~31~10~1 ~31~10~2 minecraft:stone_brick_stairs 5
fill ~31~11~1 ~31~13~1 minecraft:stonebrick 3
fill ~3~11~2 ~4~11~4 minecraft:stonebrick 0
fill ~3~12~2 ~3~12~4 minecraft:stonebrick 0
fill ~4~1~2 ~4~8~4 minecraft:stonebrick 0
fill ~4~9~2 ~4~10~2 minecraft:stonebrick 0
fill ~8~1~2 ~8~7~26 minecraft:stonebrick 0
fill ~8~8~2 ~8~11~3 minecraft:stonebrick 0
fill ~9~3~2 ~26~3~5 minecraft:stonebrick 0
fill ~9~11~2 ~9~12~4 minecraft:stonebrick 0
fill ~25~11~2 ~26~11~4 minecraft:stonebrick 0
fill ~25~12~2 ~25~12~4 minecraft:stonebrick 0
fill ~26~1~2 ~26~2~26 minecraft:stonebrick 0
fill ~26~4~2 ~26~7~26 minecraft:stonebrick 0
fill ~26~8~2 ~26~10~3 minecraft:stonebrick 0
fill ~30~1~2 ~30~8~4 minecraft:stonebrick 0
fill ~30~9~2 ~30~11~2 minecraft:stonebrick 0
fill ~31~11~2 ~31~12~4 minecraft:stonebrick 0
setblock ~3~13~3 minecraft:stonebrick 0
setblock ~4~10~3 minecraft:iron_bars
fill ~5~11~3 ~5~11~6 minecraft:stonebrick 0
fill ~6~8~3 ~6~11~3 minecraft:ladder 2
fill ~7~11~3 ~7~11~6 minecraft:stonebrick 0
fill ~9~4~3 ~25~4~5 minecraft:stonebrick 0
fill ~9~5~3 ~10~7~5 minecraft:stonebrick 0
fill ~9~8~3 ~10~8~3 minecraft:fence 0
setblock ~9~13~3 minecraft:stonebrick 0
fill ~24~5~3 ~25~7~5 minecraft:stonebrick 0
fill ~24~8~3 ~25~8~3 minecraft:fence 0
setblock ~25~13~3 minecraft:stonebrick 0
fill ~27~11~3 ~27~11~6 minecraft:stonebrick 0
fill ~28~8~3 ~28~11~3 minecraft:ladder 2
fill ~29~11~3 ~30~11~4 minecraft:stonebrick 0
setblock ~30~10~3 minecraft:iron_bars
setblock ~31~13~3 minecraft:stonebrick 0
fill ~3~10~4 ~3~10~6 minecraft:stone_brick_stairs 4
fill ~4~9~4 ~4~10~4 minecraft:stonebrick 0
fill ~6~8~4 ~6~11~5 minecraft:stonebrick 0
fill ~7~16~4 ~27~16~4 minecraft:stone_brick_stairs 2
setblock ~8~11~4 minecraft:stonebrick 0
setblock ~10~8~4 minecraft:fence 0
fill ~11~5~4 ~23~5~5 minecraft:stonebrick 0
setblock ~24~8~4 minecraft:fence 0
fill ~28~8~4 ~28~11~5 minecraft:stonebrick 0
fill ~30~9~4 ~30~10~4 minecraft:stonebrick 0
fill ~31~10~4 ~31~10~6 minecraft:stone_brick_stairs 5
fill ~3~11~5 ~4~11~5 minecraft:stonebrick 3
fill ~3~12~5 ~3~13~5 minecraft:stonebrick 3
fill ~4~1~5 ~4~10~5 minecraft:stonebrick 3
fill ~5~8~5 ~5~10~5 minecraft:stonebrick 0
fill ~7~16~5 ~7~16~24 minecraft:stone_brick_stairs 0
fill ~8~8~5 ~8~15~5 minecraft:stonebrick 3
fill ~8~16~5 ~26~16~7 minecraft:stonebrick 0
fill ~8~17~5 ~8~17~22 minecraft:stone_brick_stairs 0
fill ~9~12~5 ~10~13~5 minecraft:stonebrick 3
fill ~9~17~5 ~25~17~5 minecraft:stone_brick_stairs 2
fill ~10~8~5 ~10~11~5 minecraft:stonebrick 3
fill ~10~14~5 ~10~15~5 minecraft:stonebrick 3
fill ~11~6~5 ~23~7~5 minecraft:stonebrick 0
fill ~12~8~5 ~12~15~5 minecraft:stonebrick 3
fill ~14~8~5 ~14~15~5 minecraft:stonebrick 3
fill ~16~8~5 ~16~15~5 minecraft:stonebrick 3
fill ~18~8~5 ~18~15~5 minecraft:stonebrick 3
fill ~20~8~5 ~20~15~5 minecraft:stonebrick 3
fill ~22~8~5 ~22~15~5 minecraft:stonebrick 3
fill ~24~8~5 ~24~15~5 minecraft:stonebrick 3
fill ~25~12~5 ~26~13~5 minecraft:stonebrick 3
fill ~26~8~5 ~26~11~5 minecraft:stonebrick 3
fill ~26~14~5 ~26~15~5 minecraft:stonebrick 3
fill ~26~17~5 ~26~17~22 minecraft:stone_brick_stairs 1
fill ~27~16~5 ~27~16~24 minecraft:stone_brick_stairs 1
fill ~29~8~5 ~29~11~5 minecraft:stonebrick 0
fill ~30~1~5 ~30~11~5 minecraft:stonebrick 3
fill ~31~11~5 ~31~13~5 minecraft:stonebrick 3
fill ~3~11~6 ~3~13~6 minecraft:stonebrick 0
setblock ~3~14~6 minecraft:redstone_torch 5
fill ~4~1~6 ~4~2~22 minecraft:stonebrick 0
fill ~4~10~6 ~6~10~6 minecraft:stone_brick_stairs 7
fill ~4~11~6 ~4~13~6 minecraft:stonebrick 3
fill ~5~12~6 ~7~12~6 minecraft:stonebrick 0
fill ~6~4~6 ~7~4~27 minecraft:stonebrick 0
fill ~6~5~6 ~7~7~7 minecraft:stonebrick 0
fill ~6~8~6 ~6~8~7 minecraft:fence 0
setblock ~6~11~6 minecraft:stonebrick 0
setblock ~6~13~6 minecraft:stonebrick 0
fill ~8~12~6 ~8~13~7 minecraft:stonebrick 3
fill ~9~1~6 ~12~2~6 minecraft:bookshelf
fill ~9~7~6 ~25~7~11 minecraft:stonebrick 0
fill ~9~17~6 ~25~17~7 minecraft:stonebrick 0
fill ~9~18~6 ~24~18~6 minecraft:stone_brick_stairs 2
fill ~22~1~6 ~25~2~6 minecraft:bookshelf
fill ~25~18~6 ~25~18~22 minecraft:stone_brick_stairs 1
fill ~26~3~6 ~26~3~26 minecraft:stonebrick 0
fill ~26~12~6 ~26~13~7 minecraft:stonebrick 3
fill ~27~4~6 ~28~4~27 minecraft:stonebrick 0
fill ~27~5~6 ~28~7~7 minecraft:stonebrick 0
fill ~27~12~6 ~29~12~6 minecraft:stonebrick 0
fill ~28~8~6 ~28~8~7 minecraft:fence 0
fill ~28~10~6 ~30~10~6 minecraft:stone_brick_stairs 7
fill ~28~11~6 ~29~11~6 minecraft:stonebrick 0
setblock ~28~13~6 minecraft:stonebrick 0
fill ~30~1~6 ~30~2~22 minecraft:stonebrick 0
fill ~30~11~6 ~30~13~6 minecraft:stonebrick 3
fill ~31~11~6 ~31~13~6 minecraft:stonebrick 0
setblock ~31~14~6 minecraft:redstone_torch 5
setblock ~7~8~7 minecraft:fence 0
fill ~8~8~7 ~8~11~7 minecraft:stonebrick 3
fill ~8~14~7 ~8~15~7 minecraft:stonebrick 3
fill ~9~1~7 ~9~2~9 minecraft:bookshelf
fill ~9~18~7 ~9~18~22 minecraft:stone_brick_stairs 0
fill ~10~18~7 ~24~18~8 minecraft:stonebrick 0
fill ~10~19~7 ~10~19~20 minecraft:stone_brick_stairs 0
fill ~11~19~7 ~23~19~7 minecraft:stone_brick_stairs 2
fill ~24~19~7 ~24~19~21 minecraft:stone_brick_stairs 1
fill ~25~1~7 ~25~2~9 minecraft:bookshelf
fill ~26~8~7 ~26~11~7 minecraft:stonebrick 3
fill ~26~14~7 ~26~15~7 minecraft:stonebrick 3
setblock ~27~8~7 minecraft:fence 0
fill ~7~5~8 ~7~5~27 minecraft:stonebrick 0
fill ~8~16~8 ~10~16~23 minecraft:stonebrick 0
fill ~9~17~8 ~12~17~8 minecraft:stonebrick 0
fill ~11~19~8 ~23~19~9 minecraft:stonebrick 0
fill ~11~20~8 ~11~20~19 minecraft:stone_brick_stairs 0
fill ~12~20~8 ~22~20~8 minecraft:stone_brick_stairs 2
fill ~15~1~8 ~16~4~9 minecraft:bookshelf
fill ~15~5~8 ~16~6~9 minecraft:planks 0
fill ~18~1~8 ~19~4~9 minecraft:bookshelf
fill ~18~5~8 ~19~6~9 minecraft:planks 0
fill ~22~17~8 ~25~17~8 minecraft:stonebrick 0
fill ~23~20~8 ~23~20~19 minecraft:stone_brick_stairs 1
fill ~24~16~8 ~26~16~23 minecraft:stonebrick 0
fill ~27~5~8 ~27~5~27 minecraft:stonebrick 0
fill ~8~8~9 ~8~15~9 minecraft:stonebrick 3
fill ~9~17~9 ~11~17~9 minecraft:stonebrick 0
fill ~10~18~9 ~13~18~9 minecraft:stonebrick 0
fill ~12~8~9 ~22~8~9 minecraft:carpet 14
fill ~12~20~9 ~22~20~10 minecraft:stonebrick 0
fill ~12~21~9 ~21~21~9 minecraft:stone_brick_stairs 2
fill ~21~18~9 ~24~18~9 minecraft:stonebrick 0
fill ~22~21~9 ~22~21~18 minecraft:stone_brick_stairs 1
fill ~23~17~9 ~25~17~9 minecraft:stonebrick 0
fill ~26~8~9 ~26~15~9 minecraft:stonebrick 3
fill ~9~17~10 ~10~17~22 minecraft:stonebrick 0
fill ~10~18~10 ~12~18~10 minecraft:stonebrick 0
fill ~11~19~10 ~14~19~10 minecraft:stonebrick 0
fill ~12~8~10 ~12~8~19 minecraft:carpet 14
fill ~12~21~10 ~12~21~19 minecraft:stone_brick_stairs 0
fill ~13~8~10 ~21~8~10 minecraft:carpet 1
fill ~13~21~10 ~21~21~11 minecraft:stonebrick 0
fill ~13~22~10 ~13~22~17 minecraft:stone_brick_stairs 0
fill ~14~22~10 ~21~22~10 minecraft:stone_brick_stairs 2
fill ~20~19~10 ~23~19~10 minecraft:stonebrick 0
fill ~22~8~10 ~22~8~19 minecraft:carpet 14
fill ~22~18~10 ~24~18~10 minecraft:stonebrick 0
fill ~24~17~10 ~25~17~22 minecraft:stonebrick 0
fill ~8~8~11 ~8~15~11 minecraft:stonebrick 3
fill ~10~18~11 ~11~18~21 minecraft:stonebrick 0
fill ~11~19~11 ~13~19~11 minecraft:stonebrick 0
fill ~12~20~11 ~15~20~11 minecraft:stonebrick 0
fill ~13~8~11 ~13~8~18 minecraft:carpet 1
setblock ~14~8~11 minecraft:fence 0
setblock ~14~9~11 minecraft:torch 5
fill ~14~22~11 ~20~22~13 minecraft:stonebrick 0
fill ~14~23~11 ~14~23~16 minecraft:stone_brick_stairs 0
setblock ~15~4~11 minecraft:torch 4
fill ~15~8~11 ~19~8~11 minecraft:carpet 4
fill ~15~23~11 ~20~23~11 minecraft:stone_brick_stairs 2
setblock ~19~4~11 minecraft:torch 4
fill ~19~20~11 ~22~20~11 minecraft:stonebrick 0
setblock ~20~8~11 minecraft:fence 0
setblock ~20~9~11 minecraft:torch 5
fill ~21~8~11 ~21~8~18 minecraft:carpet 1
fill ~21~19~11 ~23~19~11 minecraft:stonebrick 0
fill ~21~22~11 ~21~22~17 minecraft:stone_brick_stairs 1
fill ~23~18~11 ~24~18~21 minecraft:stonebrick 0
fill ~26~8~11 ~27~8~11 minecraft:stonebrick 3
fill ~26~9~11 ~26~15~11 minecraft:stonebrick 3
fill ~27~6~11 ~28~6~11 minecraft:stonebrick 0
setblock ~27~7~11 minecraft:stonebrick 0
fill ~28~5~11 ~29~5~11 minecraft:stonebrick 0
setblock ~28~7~11 minecraft:stonebrick 3
setblock ~28~8~11 minecraft:redstone_torch 1
fill ~29~4~11 ~30~4~11 minecraft:stonebrick 0
setblock ~29~6~11 minecraft:stonebrick 3
fill ~30~3~11 ~30~3~17 minecraft:stonebrick 0
setblock ~30~5~11 minecraft:stonebrick 3
setblock ~30~6~11 minecraft:redstone_torch 1
fill ~31~2~11 ~32~2~11 minecraft:stone_brick_stairs 2
setblock ~31~4~11 minecraft:redstone_torch 1
fill ~32~1~11 ~32~1~17 minecraft:stonebrick 0
fill ~3~0~12 ~14~0~28 minecraft:stonebrick 0
fill ~9~7~12 ~13~7~23 minecraft:stonebrick 0
fill ~11~1~12 ~12~6~13 minecraft:bookshelf
fill ~11~19~12 ~12~19~20 minecraft:stonebrick 0
fill ~12~20~12 ~14~20~12 minecraft:stonebrick 0
fill ~13~21~12 ~15~21~12 minecraft:stonebrick 0
fill ~14~1~12 ~14~7~12 minecraft:ladder 4
setblock ~14~8~12 minecraft:trapdoor 1
setblock ~15~0~12 minecraft:quartz_block 2
setblock ~15~1~12 minecraft:quartz_block 1
fill ~15~2~12 ~15~6~12 minecraft:quartz_block 2
fill ~15~7~12 ~19~7~12 minecraft:gold_block
fill ~15~8~12 ~19~8~12 minecraft:stonebrick 0
setblock ~15~9~12 minecraft:torch 5
fill ~15~23~12 ~19~23~13 minecraft:stonebrick 0
fill ~15~24~12 ~15~24~15 minecraft:stone_brick_stairs 0
fill ~16~0~12 ~18~0~28 minecraft:stonebrick 0
fill ~16~1~12 ~16~4~13 minecraft:bookshelf
setblock ~16~5~12 minecraft:quartz_stairs 5
setblock ~16~6~12 minecraft:quartz_block 1
fill ~16~24~12 ~19~24~12 minecraft:stone_brick_stairs 2
setblock ~17~5~12 minecraft:stone_block_slab 14
fill ~17~6~12 ~17~6~16 minecraft:quartz_block 0
fill ~17~21~12 ~17~21~13 minecraft:stonebrick 0
fill ~18~1~12 ~18~4~13 minecraft:bookshelf
setblock ~18~5~12 minecraft:quartz_stairs 4
setblock ~18~6~12 minecraft:quartz_block 1
setblock ~19~0~12 minecraft:quartz_block 2
setblock ~19~1~12 minecraft:quartz_block 1
fill ~19~2~12 ~19~6~12 minecraft:quartz_block 2
setblock ~19~9~12 minecraft:torch 5
fill ~19~21~12 ~21~21~12 minecraft:stonebrick 0
fill ~20~0~12 ~31~0~28 minecraft:stonebrick 0
fill ~20~1~12 ~20~7~12 minecraft:ladder 5
setblock ~20~8~12 minecraft:trapdoor 0
fill ~20~20~12 ~22~20~12 minecraft:stonebrick 0
fill ~20~23~12 ~20~23~17 minecraft:stone_brick_stairs 1
fill ~21~7~12 ~25~7~23 minecraft:stonebrick 0
fill ~22~1~12 ~23~6~13 minecraft:bookshelf
fill ~22~19~12 ~23~19~20 minecraft:stonebrick 0
fill ~27~6~12 ~27~6~17 minecraft:stonebrick 0
fill ~27~7~12 ~27~7~16 minecraft:stone_brick_stairs 1
fill ~28~5~12 ~28~5~17 minecraft:stonebrick 0
fill ~28~6~12 ~28~6~16 minecraft:stone_brick_stairs 1
fill ~29~4~12 ~29~4~17 minecraft:stonebrick 0
fill ~29~5~12 ~29~5~16 minecraft:stone_brick_stairs 1
fill ~30~4~12 ~30~4~16 minecraft:stone_brick_stairs 1
fill ~31~2~12 ~31~2~16 minecraft:stonebrick 0
fill ~31~3~12 ~31~3~16 minecraft:stone_brick_stairs 1
fill ~32~2~12 ~32~2~16 minecraft:stone_brick_stairs 1
fill ~8~8~13 ~8~15~13 minecraft:stonebrick 3
fill ~12~20~13 ~13~20~19 minecraft:stonebrick 0
fill ~13~21~13 ~14~21~18 minecraft:stonebrick 0
fill ~14~7~13 ~14~7~15 minecraft:stonebrick 0
setblock ~14~8~13 minecraft:fence 0
fill ~15~0~13 ~15~0~15 minecraft:stonebrick 0
fill ~15~1~13 ~15~4~13 minecraft:bookshelf
setblock ~15~5~13 minecraft:quartz_stairs 7
setblock ~15~6~13 minecraft:quartz_block 1
fill ~15~7~13 ~15~7~16 minecraft:gold_block
fill ~15~8~13 ~15~8~16 minecraft:stonebrick 0
setblock ~16~5~13 minecraft:bookshelf
fill ~16~6~13 ~16~6~15 minecraft:quartz_block 0
fill ~16~7~13 ~18~8~15 minecraft:iron_block
fill ~16~9~13 ~16~11~13 minecraft:double_stone_block_slab 0
fill ~16~12~13 ~18~12~13 minecraft:stone_block_slab 0
fill ~16~20~13 ~16~20~14 minecraft:stone_brick_stairs 4
fill ~16~21~13 ~16~21~15 minecraft:stonebrick 0
fill ~16~24~13 ~18~24~13 minecraft:stonebrick 0
setblock ~16~25~13 minecraft:stonebrick 0
setblock ~16~26~13 minecraft:cobblestone_wall 0
fill ~17~9~13 ~17~10~13 minecraft:iron_bars
setblock ~17~11~13 minecraft:glass_pane
fill ~17~20~13 ~18~20~13 minecraft:stone_brick_stairs 6
setblock ~17~25~13 minecraft:stone_brick_stairs 2
setblock ~18~5~13 minecraft:bookshelf
fill ~18~6~13 ~18~6~15 minecraft:quartz_block 0
fill ~18~9~13 ~18~11~13 minecraft:double_stone_block_slab 0
fill ~18~21~13 ~18~21~15 minecraft:stonebrick 0
setblock ~18~25~13 minecraft:stonebrick 0
setblock ~18~26~13 minecraft:cobblestone_wall 0
fill ~19~0~13 ~19~0~15 minecraft:stonebrick 0
fill ~19~1~13 ~19~4~13 minecraft:bookshelf
setblock ~19~5~13 minecraft:quartz_stairs 7
setblock ~19~6~13 minecraft:quartz_block 1
fill ~19~7~13 ~19~7~16 minecraft:gold_block
fill ~19~8~13 ~19~8~16 minecraft:stonebrick 0
fill ~19~24~13 ~19~24~16 minecraft:stone_brick_stairs 1
fill ~20~7~13 ~20~7~15 minecraft:stonebrick 0
setblock ~20~8~13 minecraft:fence 0
fill ~20~21~13 ~21~21~18 minecraft:stonebrick 0
fill ~21~20~13 ~22~20~19 minecraft:stonebrick 0
fill ~26~8~13 ~26~15~13 minecraft:stonebrick 3
setblock ~14~8~14 minecraft:carpet 4
fill ~14~22~14 ~16~22~17 minecraft:stonebrick 0
setblock ~15~5~14 minecraft:stone_block_slab 14
setblock ~15~6~14 minecraft:quartz_block 0
setblock ~15~21~14 minecraft:stonebrick 0
fill ~15~23~14 ~16~23~16 minecraft:stonebrick 0
fill ~16~9~14 ~16~10~14 minecraft:iron_bars
setblock ~16~11~14 minecraft:glass_pane
fill ~16~12~14 ~16~12~15 minecraft:stone_block_slab 0
fill ~16~24~14 ~16~24~15 minecraft:stonebrick 0
setblock ~16~25~14 minecraft:stone_brick_stairs 0
setblock ~17~9~14 minecraft:beacon
setblock ~17~11~14 minecraft:stained_glass 14
fill ~17~20~14 ~17~25~14 minecraft:stained_glass 14
fill ~18~9~14 ~18~10~14 minecraft:iron_bars
setblock ~18~11~14 minecraft:glass_pane
fill ~18~12~14 ~18~12~15 minecraft:stone_block_slab 0
fill ~18~20~14 ~18~20~15 minecraft:stone_brick_stairs 5
fill ~18~22~14 ~20~22~17 minecraft:stonebrick 0
fill ~18~23~14 ~19~23~16 minecraft:stonebrick 0
fill ~18~24~14 ~18~24~15 minecraft:stonebrick 0
setblock ~18~25~14 minecraft:stone_brick_stairs 1
setblock ~19~5~14 minecraft:stone_block_slab 14
setblock ~19~6~14 minecraft:quartz_block 0
setblock ~19~21~14 minecraft:stonebrick 0
setblock ~20~8~14 minecraft:carpet 4
fill ~8~8~15 ~8~15~15 minecraft:stonebrick 3
fill ~11~1~15 ~12~4~16 minecraft:bookshelf
fill ~11~5~15 ~12~6~16 minecraft:planks 0
setblock ~14~8~15 minecraft:fence 0
fill ~15~1~15 ~16~4~15 minecraft:bookshelf
setblock ~15~5~15 minecraft:quartz_stairs 6
setblock ~15~6~15 minecraft:quartz_block 1
setblock ~16~5~15 minecraft:bookshelf
fill ~16~9~15 ~16~11~15 minecraft:double_stone_block_slab 0
fill ~16~20~15 ~17~20~15 minecraft:stone_brick_stairs 7
setblock ~16~25~15 minecraft:stonebrick 0
setblock ~16~26~15 minecraft:cobblestone_wall 0
fill ~17~9~15 ~17~10~15 minecraft:iron_bars
setblock ~17~11~15 minecraft:glass_pane
setblock ~17~12~15 minecraft:stone_block_slab 0
fill ~17~21~15 ~17~21~18 minecraft:stonebrick 0
fill ~17~22~15 ~17~22~17 minecraft:stonebrick 0
fill ~17~23~15 ~17~23~16 minecraft:stonebrick 0
setblock ~17~24~15 minecraft:stonebrick 0
setblock ~17~25~15 minecraft:stone_brick_stairs 3
fill ~18~1~15 ~19~4~15 minecraft:bookshelf
setblock ~18~5~15 minecraft:bookshelf
fill ~18~9~15 ~18~11~15 minecraft:double_stone_block_slab 0
setblock ~18~25~15 minecraft:stonebrick 0
setblock ~18~26~15 minecraft:cobblestone_wall 0
setblock ~19~5~15 minecraft:quartz_stairs 6
setblock ~19~6~15 minecraft:quartz_block 1
setblock ~20~8~15 minecraft:fence 0
fill ~22~1~15 ~23~6~16 minecraft:bookshelf
fill ~26~8~15 ~26~15~15 minecraft:stonebrick 3
fill ~14~1~16 ~14~7~16 minecraft:ladder 4
setblock ~14~8~16 minecraft:trapdoor 1
fill ~14~20~16 ~14~20~19 minecraft:stonebrick 0
setblock ~15~0~16 minecraft:quartz_block 2
setblock ~15~1~16 minecraft:quartz_block 1
fill ~15~2~16 ~15~6~16 minecraft:quartz_block 2
setblock ~15~9~16 minecraft:torch 5
fill ~15~21~16 ~15~21~18 minecraft:stonebrick 0
fill ~15~24~16 ~18~24~16 minecraft:stone_brick_stairs 3
fill ~16~1~16 ~16~4~16 minecraft:bookshelf
fill ~16~5~16 ~18~5~16 minecraft:stone_block_slab 14
setblock ~16~6~16 minecraft:quartz_block 1
fill ~16~7~16 ~18~7~16 minecraft:gold_block
fill ~16~8~16 ~18~8~16 minecraft:stonebrick 0
fill ~18~1~16 ~18~4~16 minecraft:bookshelf
setblock ~18~6~16 minecraft:quartz_block 1
setblock ~19~0~16 minecraft:quartz_block 2
setblock ~19~1~16 minecraft:quartz_block 1
fill ~19~2~16 ~19~6~16 minecraft:quartz_block 2
setblock ~19~9~16 minecraft:torch 5
fill ~19~21~16 ~19~21~18 minecraft:stonebrick 0
fill ~20~1~16 ~20~7~16 minecraft:ladder 5
setblock ~20~8~16 minecraft:trapdoor 0
fill ~20~20~16 ~20~20~19 minecraft:stonebrick 0
fill ~8~8~17 ~8~15~17 minecraft:stonebrick 3
fill ~13~19~17 ~13~19~20 minecraft:stonebrick 0
fill ~14~7~17 ~20~7~23 minecraft:stonebrick 0
setblock ~14~8~17 minecraft:fence 0
setblock ~14~9~17 minecraft:torch 5
fill ~14~23~17 ~19~23~17 minecraft:stone_brick_stairs 3
fill ~15~0~17 ~15~0~28 minecraft:stonebrick 0
setblock ~15~4~17 minecraft:torch 3
fill ~15~8~17 ~19~8~17 minecraft:carpet 4
fill ~15~20~17 ~15~20~19 minecraft:stonebrick 0
fill ~16~21~17 ~16~21~18 minecraft:stonebrick 0
fill ~18~21~17 ~18~21~18 minecraft:stonebrick 0
fill ~19~0~17 ~19~0~28 minecraft:stonebrick 0
setblock ~19~4~17 minecraft:torch 3
fill ~19~20~17 ~19~20~19 minecraft:stonebrick 0
setblock ~20~8~17 minecraft:fence 0
setblock ~20~9~17 minecraft:torch 5
fill ~21~19~17 ~21~19~20 minecraft:stonebrick 0
fill ~26~8~17 ~27~8~17 minecraft:stonebrick 3
fill ~26~9~17 ~26~15~17 minecraft:stonebrick 3
setblock ~27~7~17 minecraft:stonebrick 0
setblock ~28~6~17 minecraft:stonebrick 0
setblock ~28~7~17 minecraft:stonebrick 3
setblock ~28~8~17 minecraft:redstone_torch 1
setblock ~29~5~17 minecraft:stonebrick 0
setblock ~29~6~17 minecraft:stonebrick 3
setblock ~30~4~17 minecraft:stonebrick 0
setblock ~30~5~17 minecraft:stonebrick 3
setblock ~30~6~17 minecraft:redstone_torch 1
fill ~31~2~17 ~32~2~17 minecraft:stone_brick_stairs 3
setblock ~31~4~17 minecraft:redstone_torch 1
fill ~12~18~18 ~12~18~21 minecraft:stonebrick 0
fill ~13~22~18 ~21~22~18 minecraft:stone_brick_stairs 3
fill ~14~8~18 ~20~8~18 minecraft:carpet 1
fill ~14~19~18 ~14~19~20 minecraft:stonebrick 0
fill ~16~20~18 ~18~20~19 minecraft:stonebrick 0
fill ~20~19~18 ~20~19~20 minecraft:stonebrick 0
fill ~22~18~18 ~22~18~21 minecraft:stonebrick 0
fill ~32~1~18 ~32~1~24 minecraft:grass
fill ~8~8~19 ~8~15~19 minecraft:stonebrick 3
fill ~9~1~19 ~9~2~22 minecraft:bookshelf
fill ~11~17~19 ~11~17~22 minecraft:stonebrick 0
fill ~13~8~19 ~21~8~19 minecraft:carpet 14
fill ~13~18~19 ~13~18~21 minecraft:stonebrick 0
fill ~13~21~19 ~22~21~19 minecraft:stone_brick_stairs 3
fill ~15~1~19 ~16~6~20 minecraft:bookshelf
fill ~15~19~19 ~19~19~20 minecraft:stonebrick 0
fill ~19~1~19 ~19~4~20 minecraft:bookshelf
fill ~19~5~19 ~19~6~20 minecraft:planks 0
fill ~21~18~19 ~21~18~21 minecraft:stonebrick 0
fill ~23~17~19 ~23~17~22 minecraft:stonebrick 0
fill ~25~1~19 ~25~2~22 minecraft:bookshelf
fill ~26~8~19 ~26~15~19 minecraft:stonebrick 3
fill ~11~20~20 ~23~20~20 minecraft:stone_brick_stairs 3
fill ~12~17~20 ~12~17~22 minecraft:stonebrick 0
fill ~14~18~20 ~20~18~21 minecraft:stonebrick 0
fill ~22~17~20 ~22~17~22 minecraft:stonebrick 0
fill ~6~5~21 ~6~7~27 minecraft:stonebrick 0
fill ~6~8~21 ~7~8~21 minecraft:fence 0
fill ~7~6~21 ~7~7~27 minecraft:stonebrick 0
fill ~8~8~21 ~8~15~21 minecraft:stonebrick 3
fill ~10~19~21 ~23~19~21 minecraft:stone_brick_stairs 3
fill ~11~16~21 ~23~16~23 minecraft:stonebrick 0
fill ~13~17~21 ~21~17~22 minecraft:stonebrick 0
fill ~26~8~21 ~26~15~21 minecraft:stonebrick 3
fill ~27~6~21 ~28~7~27 minecraft:stonebrick 0
fill ~27~8~21 ~28~8~21 minecraft:fence 0
fill ~28~5~21 ~28~5~27 minecraft:stonebrick 0
fill ~3~10~22 ~6~10~22 minecraft:stone_brick_stairs 6
fill ~3~11~22 ~3~13~22 minecraft:stonebrick 0
setblock ~3~14~22 minecraft:redstone_torch 5
fill ~4~11~22 ~4~11~23 minecraft:stonebrick 3
fill ~4~12~22 ~4~13~22 minecraft:stonebrick 3
fill ~5~11~22 ~7~11~24 minecraft:stonebrick 0
fill ~5~12~22 ~7~12~22 minecraft:stonebrick 0
setblock ~6~8~22 minecraft:fence 0
setblock ~6~13~22 minecraft:stonebrick 0
fill ~8~12~22 ~8~13~23 minecraft:stonebrick 3
fill ~10~1~22 ~12~2~22 minecraft:bookshelf
fill ~10~18~22 ~24~18~22 minecraft:stone_brick_stairs 3
fill ~22~1~22 ~24~2~22 minecraft:bookshelf
fill ~26~12~22 ~26~13~23 minecraft:stonebrick 3
fill ~27~11~22 ~29~11~24 minecraft:stonebrick 0
fill ~27~12~22 ~29~12~22 minecraft:stonebrick 0
setblock ~28~8~22 minecraft:fence 0
fill ~28~10~22 ~31~10~22 minecraft:stone_brick_stairs 6
setblock ~28~13~22 minecraft:stonebrick 0
fill ~30~11~22 ~30~11~23 minecraft:stonebrick 3
fill ~30~12~22 ~30~13~22 minecraft:stonebrick 3
fill ~31~11~22 ~31~13~22 minecraft:stonebrick 0
setblock ~31~14~22 minecraft:redstone_torch 5
fill ~3~10~23 ~3~10~24 minecraft:stone_brick_stairs 4
fill ~3~11~23 ~3~13~23 minecraft:stonebrick 3
fill ~4~1~23 ~4~10~23 minecraft:stonebrick 3
fill ~5~4~23 ~5~7~27 minecraft:stonebrick 0
fill ~5~8~23 ~6~10~23 minecraft:stonebrick 0
fill ~8~8~23 ~8~11~23 minecraft:stonebrick 3
fill ~8~14~23 ~8~15~23 minecraft:stonebrick 3
fill ~8~17~23 ~26~17~23 minecraft:stone_brick_stairs 3
fill ~9~1~23 ~25~1~28 minecraft:stonebrick 0
fill ~9~2~23 ~25~2~27 minecraft:stonebrick 0
fill ~9~3~23 ~25~3~26 minecraft:stonebrick 0
fill ~9~4~23 ~25~4~25 minecraft:stonebrick 0
fill ~9~5~23 ~25~5~24 minecraft:stonebrick 0
fill ~9~6~23 ~25~6~23 minecraft:stonebrick 0
fill ~9~12~23 ~10~13~23 minecraft:stonebrick 3
fill ~10~8~23 ~10~11~23 minecraft:stonebrick 3
fill ~10~14~23 ~10~15~23 minecraft:stonebrick 3
fill ~12~8~23 ~12~15~23 minecraft:stonebrick 3
fill ~14~8~23 ~14~15~23 minecraft:stonebrick 3
fill ~16~8~23 ~16~15~23 minecraft:stonebrick 3
fill ~18~8~23 ~18~15~23 minecraft:stonebrick 3
fill ~20~8~23 ~20~15~23 minecraft:stonebrick 3
fill ~22~8~23 ~22~15~23 minecraft:stonebrick 3
fill ~24~8~23 ~24~15~23 minecraft:stonebrick 3
fill ~25~12~23 ~25~13~23 minecraft:stonebrick 3
fill ~26~8~23 ~26~11~23 minecraft:stonebrick 3
fill ~26~14~23 ~26~15~23 minecraft:stonebrick 3
fill ~28~8~23 ~29~10~23 minecraft:stonebrick 0
fill ~29~4~23 ~29~7~27 minecraft:stonebrick 0
fill ~30~1~23 ~30~10~23 minecraft:stonebrick 3
fill ~31~10~23 ~31~10~24 minecraft:stone_brick_stairs 5
fill ~31~11~23 ~31~13~23 minecraft:stonebrick 3
fill ~3~11~24 ~4~11~26 minecraft:stonebrick 0
fill ~3~12~24 ~3~12~26 minecraft:stonebrick 0
fill ~4~1~24 ~4~8~26 minecraft:stonebrick 0
fill ~4~9~24 ~4~10~24 minecraft:stonebrick 0
fill ~8~11~24 ~9~11~26 minecraft:stonebrick 0
fill ~8~16~24 ~26~16~24 minecraft:stone_brick_stairs 3
fill ~9~6~24 ~10~7~25 minecraft:stonebrick 0
fill ~9~12~24 ~9~12~26 minecraft:stonebrick 0
fill ~10~8~24 ~10~8~25 minecraft:fence 0
fill ~24~6~24 ~25~7~25 minecraft:stonebrick 0
fill ~24~8~24 ~24~8~25 minecraft:fence 0
fill ~25~11~24 ~26~11~26 minecraft:stonebrick 0
fill ~25~12~24 ~25~12~26 minecraft:stonebrick 0
fill ~28~8~24 ~28~10~24 minecraft:stonebrick 0
fill ~30~1~24 ~30~8~26 minecraft:stonebrick 0
fill ~30~9~24 ~30~11~24 minecraft:stonebrick 0
fill ~31~11~24 ~31~12~26 minecraft:stonebrick 0
setblock ~3~13~25 minecraft:stonebrick 0
setblock ~4~10~25 minecraft:iron_bars
fill ~5~11~25 ~5~11~28 minecraft:stonebrick 0
fill ~6~8~25 ~6~11~25 minecraft:ladder 4
fill ~7~8~25 ~8~10~25 minecraft:stonebrick 0
fill ~7~11~25 ~7~11~28 minecraft:stonebrick 0
fill ~9~5~25 ~10~5~25 minecraft:stonebrick 0
setblock ~9~8~25 minecraft:fence 0
fill ~9~10~25 ~9~10~27 minecraft:stone_brick_stairs 5
setblock ~9~13~25 minecraft:stonebrick 0
fill ~24~5~25 ~25~5~25 minecraft:stonebrick 0
setblock ~25~8~25 minecraft:fence 0
fill ~25~10~25 ~25~10~27 minecraft:stone_brick_stairs 4
setblock ~25~13~25 minecraft:stonebrick 0
fill ~26~8~25 ~26~10~26 minecraft:stonebrick 0
fill ~27~11~25 ~27~11~28 minecraft:stonebrick 0
fill ~28~8~25 ~28~11~25 minecraft:ladder 3
fill ~29~11~25 ~30~11~26 minecraft:stonebrick 0
setblock ~30~10~25 minecraft:iron_bars
setblock ~31~13~25 minecraft:stonebrick 0
setblock ~32~0~25 minecraft:grass
fill ~3~10~26 ~3~10~28 minecraft:stone_brick_stairs 4
fill ~4~9~26 ~4~10~26 minecraft:stonebrick 0
fill ~6~11~26 ~6~11~28 minecraft:stonebrick 0
fill ~8~8~26 ~8~10~26 minecraft:stonebrick 0
fill ~28~11~26 ~28~11~28 minecraft:stonebrick 0
fill ~30~9~26 ~30~10~26 minecraft:stonebrick 0
fill ~31~10~26 ~31~10~28 minecraft:stone_brick_stairs 5
fill ~3~11~27 ~4~11~27 minecraft:stonebrick 3
fill ~3~12~27 ~3~13~27 minecraft:stonebrick 3
fill ~4~1~27 ~4~10~27 minecraft:stonebrick 3
fill ~5~8~27 ~7~8~27 minecraft:stonebrick 0
fill ~5~9~27 ~5~10~27 minecraft:stonebrick 0
setblock ~6~10~27 minecraft:iron_bars
fill ~7~9~27 ~7~10~27 minecraft:stonebrick 0
fill ~8~1~27 ~8~11~27 minecraft:stonebrick 3
fill ~9~11~27 ~9~13~27 minecraft:stonebrick 3
fill ~25~11~27 ~26~11~27 minecraft:stonebrick 3
fill ~25~12~27 ~25~13~27 minecraft:stonebrick 3
fill ~26~1~27 ~26~10~27 minecraft:stonebrick 3
fill ~27~8~27 ~29~8~27 minecraft:stonebrick 0
fill ~27~9~27 ~27~10~27 minecraft:stonebrick 0
setblock ~28~10~27 minecraft:iron_bars
fill ~29~9~27 ~29~11~27 minecraft:stonebrick 0
fill ~30~1~27 ~30~11~27 minecraft:stonebrick 3
fill ~31~11~27 ~31~13~27 minecraft:stonebrick 3
fill ~3~11~28 ~3~13~28 minecraft:stonebrick 0
setblock ~3~14~28 minecraft:redstone_torch 5
setblock ~4~1~28 minecraft:stonebrick 0
fill ~4~10~28 ~5~10~28 minecraft:stone_brick_stairs 7
fill ~4~11~28 ~4~13~28 minecraft:stonebrick 3
fill ~5~12~28 ~7~12~28 minecraft:stonebrick 0
setblock ~6~13~28 minecraft:stonebrick 0
fill ~7~10~28 ~9~10~28 minecraft:stone_brick_stairs 7
setblock ~8~1~28 minecraft:stonebrick 0
fill ~8~11~28 ~8~13~28 minecraft:stonebrick 3
fill ~9~11~28 ~9~13~28 minecraft:stonebrick 0
setblock ~9~14~28 minecraft:redstone_torch 5
fill ~25~10~28 ~27~10~28 minecraft:stone_brick_stairs 7
fill ~25~11~28 ~25~13~28 minecraft:stonebrick 0
setblock ~25~14~28 minecraft:redstone_torch 5
setblock ~26~1~28 minecraft:stonebrick 0
fill ~26~11~28 ~26~13~28 minecraft:stonebrick 3
fill ~27~12~28 ~29~12~28 minecraft:stonebrick 0
setblock ~28~13~28 minecraft:stonebrick 0
fill ~29~10~28 ~30~10~28 minecraft:stone_brick_stairs 7
setblock ~29~11~28 minecraft:stonebrick 0
setblock ~30~1~28 minecraft:stonebrick 0
fill ~30~11~28 ~30~13~28 minecraft:stonebrick 3
fill ~31~11~28 ~31~13~28 minecraft:stonebrick 0
setblock ~31~14~28 minecraft:redstone_torch 5