fill ~1 ~0 ~20 ~2 ~0 ~20 cobblestone 0  
fill ~2 ~0 ~17 ~2 ~17 ~17 cobblestone 0  
fill ~2 ~0 ~18 ~2 ~9 ~18 cobblestone 0  
fill ~2 ~0 ~19 ~2 ~17 ~19 cobblestone 0  
fill ~2 ~0 ~21 ~2 ~17 ~21 cobblestone 0  
fill ~2 ~0 ~22 ~2 ~9 ~22 cobblestone 0  
fill ~2 ~0 ~23 ~2 ~17 ~23 cobblestone 0  
fill ~2 ~0 ~25 ~3 ~0 ~25 cobblestone 0  
fill ~3 ~0 ~15 ~3 ~17 ~15 cobblestone 0  
fill ~3 ~0 ~16 ~3 ~17 ~16 cobblestone 0  
fill ~3 ~0 ~24 ~3 ~17 ~24 cobblestone 0  
fill ~4 ~0 ~14 ~4 ~17 ~14 cobblestone 0  
fill ~4 ~0 ~26 ~4 ~17 ~26 cobblestone 0  
fill ~5 ~0 ~13 ~5 ~9 ~13 cobblestone 0  
fill ~5 ~0 ~27 ~5 ~9 ~27 cobblestone 0  
fill ~6 ~0 ~12 ~6 ~17 ~12 cobblestone 0  
fill ~6 ~0 ~28 ~6 ~17 ~28 cobblestone 0  
fill ~7 ~0 ~11 ~8 ~0 ~11 cobblestone 0  
fill ~7 ~0 ~29 ~8 ~0 ~29 cobblestone 0  
fill ~7 ~0 ~30 ~7 ~15 ~30 cobblestone 0  
fill ~9 ~0 ~2 ~14 ~0 ~2 cobblestone 0  
fill ~9 ~0 ~5 ~12 ~0 ~5 cobblestone 0  
fill ~9 ~0 ~10 ~11 ~0 ~10 cobblestone 0  
fill ~9 ~0 ~30 ~11 ~0 ~30 cobblestone 0  
fill ~9 ~0 ~35 ~12 ~0 ~35 cobblestone 0  
fill ~9 ~0 ~38 ~14 ~0 ~38 cobblestone 0  
fill ~10 ~0 ~1 ~10 ~1 ~1 cobblestone 0  
fill ~10 ~0 ~3 ~13 ~0 ~3 cobblestone 0  
fill ~10 ~0 ~4 ~15 ~0 ~4 cobblestone 0  
fill ~10 ~0 ~36 ~15 ~0 ~36 cobblestone 0  
fill ~10 ~0 ~37 ~13 ~0 ~37 cobblestone 0  
fill ~10 ~0 ~39 ~10 ~1 ~39 cobblestone 0  
fill ~12 ~0 ~6 ~12 ~21 ~6 cobblestone 0  
fill ~12 ~0 ~7 ~12 ~21 ~7 cobblestone 0  
fill ~12 ~0 ~8 ~12 ~21 ~8 cobblestone 0  
fill ~12 ~0 ~9 ~12 ~22 ~9 cobblestone 0  
fill ~12 ~0 ~31 ~12 ~22 ~31 cobblestone 0  
fill ~12 ~0 ~32 ~12 ~21 ~32 cobblestone 0  
fill ~12 ~0 ~33 ~12 ~21 ~33 cobblestone 0  
fill ~12 ~0 ~34 ~12 ~21 ~34 cobblestone 0  
fill ~13 ~0 ~1 ~13 ~1 ~1 cobblestone 0  
fill ~13 ~0 ~39 ~13 ~1 ~39 cobblestone 0  
fill ~16 ~0 ~3 ~16 ~17 ~3 cobblestone 0  
fill ~16 ~0 ~37 ~16 ~17 ~37 cobblestone 0  
fill ~17 ~0 ~4 ~19 ~0 ~4 cobblestone 0  
fill ~17 ~0 ~36 ~19 ~0 ~36 cobblestone 0  
fill ~20 ~0 ~3 ~20 ~17 ~3 cobblestone 0  
fill ~20 ~0 ~37 ~20 ~17 ~37 cobblestone 0  
fill ~21 ~0 ~4 ~28 ~0 ~4 cobblestone 0  
fill ~21 ~0 ~36 ~28 ~0 ~36 cobblestone 0  
fill ~22 ~0 ~2 ~27 ~0 ~2 cobblestone 0  
fill ~22 ~0 ~38 ~27 ~0 ~38 cobblestone 0  
fill ~23 ~0 ~1 ~23 ~1 ~1 cobblestone 0  
fill ~23 ~0 ~3 ~26 ~0 ~3 cobblestone 0  
fill ~23 ~0 ~37 ~26 ~0 ~37 cobblestone 0  
fill ~23 ~0 ~39 ~23 ~1 ~39 cobblestone 0  
fill ~26 ~0 ~1 ~26 ~1 ~1 cobblestone 0  
fill ~26 ~0 ~39 ~26 ~1 ~39 cobblestone 0  
fill ~29 ~0 ~3 ~29 ~17 ~3 cobblestone 0  
fill ~29 ~0 ~37 ~29 ~17 ~37 cobblestone 0  
fill ~30 ~0 ~4 ~32 ~0 ~4 cobblestone 0  
fill ~30 ~0 ~36 ~32 ~0 ~36 cobblestone 0  
fill ~33 ~0 ~3 ~33 ~17 ~3 cobblestone 0  
fill ~33 ~0 ~37 ~33 ~17 ~37 cobblestone 0  
fill ~34 ~0 ~4 ~41 ~0 ~4 cobblestone 0  
fill ~34 ~0 ~36 ~41 ~0 ~36 cobblestone 0  
fill ~35 ~0 ~2 ~40 ~0 ~2 cobblestone 0  
fill ~35 ~0 ~38 ~40 ~0 ~38 cobblestone 0  
fill ~36 ~0 ~1 ~36 ~1 ~1 cobblestone 0  
fill ~36 ~0 ~3 ~39 ~0 ~3 cobblestone 0  
fill ~36 ~0 ~37 ~39 ~0 ~37 cobblestone 0  
fill ~36 ~0 ~39 ~36 ~1 ~39 cobblestone 0  
fill ~39 ~0 ~1 ~39 ~1 ~1 cobblestone 0  
fill ~39 ~0 ~39 ~39 ~1 ~39 cobblestone 0  
fill ~42 ~0 ~3 ~42 ~17 ~3 cobblestone 0  
fill ~42 ~0 ~37 ~42 ~17 ~37 cobblestone 0  
fill ~43 ~0 ~4 ~45 ~0 ~4 cobblestone 0  
fill ~43 ~0 ~36 ~45 ~0 ~36 cobblestone 0  
fill ~46 ~0 ~3 ~46 ~17 ~3 cobblestone 0  
fill ~46 ~0 ~37 ~46 ~17 ~37 cobblestone 0  
fill ~47 ~0 ~4 ~54 ~0 ~4 cobblestone 0  
fill ~47 ~0 ~36 ~54 ~0 ~36 cobblestone 0  
fill ~48 ~0 ~2 ~53 ~0 ~2 cobblestone 0  
fill ~48 ~0 ~38 ~53 ~0 ~38 cobblestone 0  
fill ~49 ~0 ~1 ~49 ~1 ~1 cobblestone 0  
fill ~49 ~0 ~3 ~52 ~0 ~3 cobblestone 0  
fill ~49 ~0 ~37 ~52 ~0 ~37 cobblestone 0  
fill ~49 ~0 ~39 ~49 ~1 ~39 cobblestone 0  
fill ~52 ~0 ~1 ~52 ~1 ~1 cobblestone 0  
fill ~52 ~0 ~39 ~52 ~1 ~39 cobblestone 0  
fill ~53 ~0 ~5 ~53 ~0 ~5 cobblestone 0  
fill ~53 ~0 ~6 ~53 ~0 ~6 cobblestone 0  
fill ~53 ~0 ~8 ~54 ~0 ~8 cobblestone 0  
fill ~53 ~0 ~9 ~54 ~0 ~9 cobblestone 0  
fill ~53 ~0 ~10 ~58 ~0 ~10 cobblestone 0  
fill ~54 ~0 ~5 ~54 ~0 ~7 stone_stairs 1  
fill ~54 ~0 ~11 ~58 ~0 ~11 cobblestone 0  
fill ~55 ~0 ~3 ~55 ~17 ~3 cobblestone 0  
fill ~55 ~0 ~9 ~58 ~0 ~9 stone_slab 3  
fill ~55 ~0 ~12 ~58 ~0 ~12 cobblestone 0  
fill ~55 ~0 ~37 ~55 ~17 ~37 cobblestone 0  
fill ~56 ~0 ~4 ~57 ~0 ~4 cobblestone 0  
fill ~56 ~0 ~36 ~58 ~0 ~36 cobblestone 0  
fill ~57 ~0 ~1 ~57 ~2 ~1 cobblestone 0  
fill ~57 ~0 ~2 ~57 ~2 ~2 cobblestone 0  
fill ~57 ~0 ~3 ~57 ~2 ~3 cobblestone 0  
fill ~59 ~0 ~9 ~61 ~0 ~9 stone_stairs 2  
fill ~59 ~0 ~37 ~59 ~17 ~37 cobblestone 0  
fill ~60 ~0 ~10 ~60 ~0 ~10 cobblestone 0  
fill ~60 ~0 ~36 ~63 ~0 ~36 cobblestone 0  
fill ~61 ~0 ~4 ~63 ~0 ~4 cobblestone 0  
fill ~61 ~0 ~17 ~62 ~0 ~17 cobblestone 0  
fill ~61 ~0 ~23 ~61 ~7 ~23 cobblestone 0  
fill ~61 ~0 ~38 ~66 ~0 ~38 cobblestone 0  
fill ~62 ~0 ~1 ~62 ~2 ~1 cobblestone 0  
fill ~62 ~0 ~2 ~66 ~0 ~2 cobblestone 0  
fill ~62 ~0 ~3 ~65 ~0 ~3 cobblestone 0  
fill ~62 ~0 ~5 ~62 ~10 ~5 cobblestone 0  
fill ~62 ~0 ~6 ~65 ~0 ~6 cobblestone 0  
fill ~62 ~0 ~7 ~64 ~0 ~7 cobblestone 0  
fill ~62 ~0 ~8 ~64 ~0 ~8 cobblestone 0  
fill ~62 ~0 ~9 ~64 ~0 ~9 cobblestone 0  
fill ~62 ~0 ~10 ~62 ~6 ~10 cobblestone 0  
fill ~62 ~0 ~11 ~64 ~0 ~11 cobblestone 0  
fill ~62 ~0 ~12 ~64 ~0 ~12 cobblestone 0  
fill ~62 ~0 ~16 ~64 ~0 ~16 cobblestone 0  
fill ~62 ~0 ~20 ~65 ~0 ~20 cobblestone 0  
fill ~62 ~0 ~24 ~62 ~10 ~24 cobblestone 0  
fill ~62 ~0 ~37 ~65 ~0 ~37 cobblestone 0  
fill ~62 ~0 ~39 ~62 ~1 ~39 cobblestone 0  
fill ~63 ~0 ~13 ~64 ~0 ~13 cobblestone 0  
fill ~63 ~0 ~14 ~64 ~0 ~14 cobblestone 0  
fill ~63 ~0 ~15 ~64 ~0 ~15 cobblestone 0  
fill ~63 ~0 ~25 ~64 ~0 ~25 cobblestone 0  
fill ~63 ~0 ~26 ~64 ~0 ~26 cobblestone 0  
fill ~63 ~0 ~27 ~64 ~0 ~27 cobblestone 0  
fill ~63 ~0 ~28 ~64 ~0 ~28 cobblestone 0  
fill ~63 ~0 ~29 ~64 ~0 ~29 cobblestone 0  
fill ~63 ~0 ~31 ~64 ~0 ~31 cobblestone 0  
fill ~63 ~0 ~32 ~64 ~0 ~32 cobblestone 0  
fill ~63 ~0 ~33 ~64 ~0 ~33 cobblestone 0  
fill ~63 ~0 ~34 ~65 ~0 ~34 cobblestone 0  
fill ~64 ~0 ~5 ~66 ~0 ~5 cobblestone 0  
fill ~64 ~0 ~10 ~65 ~0 ~10 cobblestone 0  
fill ~64 ~0 ~17 ~65 ~0 ~17 cobblestone 0  
fill ~64 ~0 ~18 ~65 ~0 ~18 cobblestone 0  
fill ~64 ~0 ~19 ~65 ~0 ~19 cobblestone 0  
fill ~64 ~0 ~24 ~64 ~0 ~24 cobblestone 0  
fill ~64 ~0 ~30 ~65 ~0 ~30 cobblestone 0  
fill ~64 ~0 ~35 ~66 ~0 ~35 cobblestone 0  
fill ~65 ~0 ~1 ~65 ~1 ~1 cobblestone 0  
fill ~65 ~0 ~4 ~65 ~1 ~4 cobblestone 0 
setblock ~65 ~0 ~16 stone_slab 3  
fill ~65 ~0 ~21 ~65 ~0 ~21 cobblestone 0  
fill ~65 ~0 ~22 ~65 ~0 ~22 cobblestone 0  
fill ~65 ~0 ~23 ~65 ~0 ~23 cobblestone 0 
setblock ~65 ~0 ~24 stone_slab 3  
fill ~65 ~0 ~36 ~65 ~1 ~36 cobblestone 0  
fill ~65 ~0 ~39 ~65 ~1 ~39 cobblestone 0  
fill ~66 ~0 ~17 ~66 ~0 ~23 stone_slab 3  
fill ~1 ~1 ~20 ~2 ~1 ~20 cobblestone 0  
fill ~2 ~1 ~25 ~3 ~1 ~25 cobblestone 0  
fill ~3 ~1 ~17 ~17 ~1 ~17 iron_block 0  
fill ~3 ~1 ~18 ~17 ~1 ~18 iron_block 0  
fill ~3 ~1 ~19 ~17 ~1 ~19 iron_block 0  
fill ~3 ~1 ~20 ~7 ~1 ~20 iron_block 0  
fill ~3 ~1 ~21 ~17 ~1 ~21 iron_block 0  
fill ~3 ~1 ~22 ~17 ~1 ~22 iron_block 0  
fill ~3 ~1 ~23 ~17 ~1 ~23 iron_block 0  
fill ~4 ~1 ~15 ~17 ~1 ~15 iron_block 0  
fill ~4 ~1 ~16 ~17 ~1 ~16 iron_block 0  
fill ~4 ~1 ~24 ~17 ~1 ~24 iron_block 0  
fill ~4 ~1 ~25 ~17 ~1 ~25 iron_block 0  
fill ~5 ~1 ~14 ~17 ~1 ~14 iron_block 0  
fill ~5 ~1 ~26 ~17 ~1 ~26 iron_block 0  
fill ~6 ~1 ~13 ~17 ~1 ~13 iron_block 0  
fill ~6 ~1 ~27 ~17 ~1 ~27 iron_block 0  
fill ~7 ~1 ~11 ~8 ~1 ~11 cobblestone 0  
fill ~7 ~1 ~12 ~17 ~1 ~12 iron_block 0  
fill ~7 ~1 ~28 ~17 ~1 ~28 iron_block 0  
fill ~7 ~1 ~29 ~8 ~1 ~29 cobblestone 0  
fill ~8 ~1 ~20 ~59 ~1 ~20 diamond_block 0  
fill ~9 ~1 ~2 ~14 ~1 ~2 cobblestone 0  
fill ~9 ~1 ~5 ~12 ~1 ~5 cobblestone 0  
fill ~9 ~1 ~10 ~11 ~1 ~10 cobblestone 0  
fill ~9 ~1 ~11 ~17 ~1 ~11 iron_block 0  
fill ~9 ~1 ~29 ~17 ~1 ~29 iron_block 0  
fill ~9 ~1 ~30 ~11 ~1 ~30 cobblestone 0  
fill ~9 ~1 ~35 ~12 ~1 ~35 cobblestone 0  
fill ~9 ~1 ~38 ~14 ~1 ~38 cobblestone 0  
fill ~10 ~1 ~3 ~13 ~1 ~3 cobblestone 0  
fill ~10 ~1 ~4 ~15 ~1 ~4 cobblestone 0  
fill ~10 ~1 ~36 ~15 ~1 ~36 cobblestone 0  
fill ~10 ~1 ~37 ~13 ~1 ~37 cobblestone 0  
fill ~12 ~1 ~10 ~17 ~1 ~10 iron_block 0  
fill ~12 ~1 ~30 ~17 ~1 ~30 iron_block 0  
fill ~13 ~1 ~5 ~17 ~1 ~5 iron_block 0  
fill ~13 ~1 ~6 ~17 ~1 ~6 iron_block 0  
fill ~13 ~1 ~7 ~17 ~1 ~7 iron_block 0  
fill ~13 ~1 ~8 ~17 ~1 ~8 iron_block 0  
fill ~13 ~1 ~9 ~17 ~1 ~9 iron_block 0  
fill ~13 ~1 ~31 ~17 ~1 ~31 iron_block 0  
fill ~13 ~1 ~32 ~17 ~1 ~32 iron_block 0  
fill ~13 ~1 ~33 ~17 ~1 ~33 iron_block 0  
fill ~13 ~1 ~34 ~17 ~1 ~34 iron_block 0  
fill ~13 ~1 ~35 ~17 ~1 ~35 iron_block 0  
fill ~17 ~1 ~4 ~19 ~1 ~4 cobblestone 0  
fill ~17 ~1 ~36 ~19 ~1 ~36 cobblestone 0  
fill ~18 ~1 ~5 ~18 ~1 ~35 diamond_block 0  
fill ~19 ~1 ~5 ~30 ~1 ~5 iron_block 0  
fill ~19 ~1 ~6 ~30 ~1 ~6 iron_block 0  
fill ~19 ~1 ~7 ~30 ~1 ~7 iron_block 0  
fill ~19 ~1 ~8 ~30 ~1 ~8 iron_block 0  
fill ~19 ~1 ~9 ~30 ~1 ~9 iron_block 0  
fill ~19 ~1 ~10 ~30 ~1 ~10 iron_block 0  
fill ~19 ~1 ~11 ~30 ~1 ~11 iron_block 0  
fill ~19 ~1 ~12 ~30 ~1 ~12 iron_block 0  
fill ~19 ~1 ~13 ~30 ~1 ~13 iron_block 0  
fill ~19 ~1 ~14 ~30 ~1 ~14 iron_block 0  
fill ~19 ~1 ~15 ~30 ~1 ~15 iron_block 0  
fill ~19 ~1 ~16 ~30 ~1 ~16 iron_block 0  
fill ~19 ~1 ~17 ~30 ~1 ~17 iron_block 0  
fill ~19 ~1 ~18 ~30 ~1 ~18 iron_block 0  
fill ~19 ~1 ~19 ~30 ~1 ~19 iron_block 0  
fill ~19 ~1 ~21 ~30 ~1 ~21 iron_block 0  
fill ~19 ~1 ~22 ~30 ~1 ~22 iron_block 0  
fill ~19 ~1 ~23 ~30 ~1 ~23 iron_block 0  
fill ~19 ~1 ~24 ~30 ~1 ~24 iron_block 0  
fill ~19 ~1 ~25 ~30 ~1 ~25 iron_block 0  
fill ~19 ~1 ~26 ~30 ~1 ~26 iron_block 0  
fill ~19 ~1 ~27 ~30 ~1 ~27 iron_block 0  
fill ~19 ~1 ~28 ~30 ~1 ~28 iron_block 0  
fill ~19 ~1 ~29 ~30 ~1 ~29 iron_block 0  
fill ~19 ~1 ~30 ~30 ~1 ~30 iron_block 0  
fill ~19 ~1 ~31 ~30 ~1 ~31 iron_block 0  
fill ~19 ~1 ~32 ~30 ~1 ~32 iron_block 0  
fill ~19 ~1 ~33 ~30 ~1 ~33 iron_block 0  
fill ~19 ~1 ~34 ~30 ~1 ~34 iron_block 0  
fill ~19 ~1 ~35 ~30 ~1 ~35 iron_block 0  
fill ~21 ~1 ~4 ~28 ~1 ~4 cobblestone 0  
fill ~21 ~1 ~36 ~28 ~1 ~36 cobblestone 0  
fill ~22 ~1 ~2 ~27 ~1 ~2 cobblestone 0  
fill ~22 ~1 ~38 ~27 ~1 ~38 cobblestone 0  
fill ~23 ~1 ~3 ~26 ~1 ~3 cobblestone 0  
fill ~23 ~1 ~37 ~26 ~1 ~37 cobblestone 0  
fill ~30 ~1 ~4 ~32 ~1 ~4 cobblestone 0  
fill ~30 ~1 ~36 ~32 ~1 ~36 cobblestone 0  
fill ~31 ~1 ~5 ~31 ~1 ~35 diamond_block 0  
fill ~32 ~1 ~5 ~52 ~1 ~5 iron_block 0  
fill ~32 ~1 ~6 ~52 ~1 ~6 iron_block 0  
fill ~32 ~1 ~7 ~52 ~1 ~7 iron_block 0  
fill ~32 ~1 ~8 ~43 ~1 ~8 iron_block 0  
fill ~32 ~1 ~9 ~43 ~1 ~9 iron_block 0  
fill ~32 ~1 ~10 ~43 ~1 ~10 iron_block 0  
fill ~32 ~1 ~11 ~43 ~1 ~11 iron_block 0  
fill ~32 ~1 ~12 ~43 ~1 ~12 iron_block 0  
fill ~32 ~1 ~13 ~43 ~1 ~13 iron_block 0  
fill ~32 ~1 ~14 ~43 ~1 ~14 iron_block 0  
fill ~32 ~1 ~15 ~43 ~1 ~15 iron_block 0  
fill ~32 ~1 ~16 ~43 ~1 ~16 iron_block 0  
fill ~32 ~1 ~17 ~43 ~1 ~17 iron_block 0  
fill ~32 ~1 ~18 ~43 ~1 ~18 iron_block 0  
fill ~32 ~1 ~19 ~43 ~1 ~19 iron_block 0  
fill ~32 ~1 ~21 ~43 ~1 ~21 iron_block 0  
fill ~32 ~1 ~22 ~43 ~1 ~22 iron_block 0  
fill ~32 ~1 ~23 ~43 ~1 ~23 iron_block 0  
fill ~32 ~1 ~24 ~43 ~1 ~24 iron_block 0  
fill ~32 ~1 ~25 ~43 ~1 ~25 iron_block 0  
fill ~32 ~1 ~26 ~43 ~1 ~26 iron_block 0  
fill ~32 ~1 ~27 ~43 ~1 ~27 iron_block 0  
fill ~32 ~1 ~28 ~43 ~1 ~28 iron_block 0  
fill ~32 ~1 ~29 ~43 ~1 ~29 iron_block 0  
fill ~32 ~1 ~30 ~43 ~1 ~30 iron_block 0  
fill ~32 ~1 ~31 ~43 ~1 ~31 iron_block 0  
fill ~32 ~1 ~32 ~43 ~1 ~32 iron_block 0  
fill ~32 ~1 ~33 ~43 ~1 ~33 iron_block 0  
fill ~32 ~1 ~34 ~43 ~1 ~34 iron_block 0  
fill ~32 ~1 ~35 ~43 ~1 ~35 iron_block 0  
fill ~34 ~1 ~4 ~41 ~1 ~4 cobblestone 0  
fill ~34 ~1 ~36 ~41 ~1 ~36 cobblestone 0  
fill ~35 ~1 ~2 ~40 ~1 ~2 cobblestone 0  
fill ~35 ~1 ~38 ~40 ~1 ~38 cobblestone 0  
fill ~36 ~1 ~3 ~39 ~1 ~3 cobblestone 0  
fill ~36 ~1 ~37 ~39 ~1 ~37 cobblestone 0  
fill ~43 ~1 ~4 ~45 ~1 ~4 cobblestone 0  
fill ~43 ~1 ~36 ~45 ~1 ~36 cobblestone 0  
fill ~44 ~1 ~8 ~44 ~1 ~35 diamond_block 0  
fill ~45 ~1 ~8 ~52 ~1 ~8 iron_block 0  
fill ~45 ~1 ~9 ~52 ~1 ~9 iron_block 0  
fill ~45 ~1 ~10 ~52 ~1 ~10 iron_block 0  
fill ~45 ~1 ~11 ~53 ~1 ~11 iron_block 0  
fill ~45 ~1 ~12 ~53 ~1 ~12 iron_block 0  
fill ~45 ~1 ~13 ~53 ~1 ~13 iron_block 0  
fill ~45 ~1 ~14 ~53 ~1 ~14 iron_block 0  
fill ~45 ~1 ~15 ~53 ~1 ~15 iron_block 0  
fill ~45 ~1 ~16 ~53 ~1 ~16 iron_block 0  
fill ~45 ~1 ~17 ~53 ~1 ~17 iron_block 0  
fill ~45 ~1 ~18 ~59 ~1 ~18 iron_block 0  
fill ~45 ~1 ~19 ~59 ~1 ~19 iron_block 0  
fill ~45 ~1 ~21 ~59 ~1 ~21 iron_block 0  
fill ~45 ~1 ~22 ~59 ~1 ~22 iron_block 0  
fill ~45 ~1 ~23 ~58 ~1 ~23 iron_block 0  
fill ~45 ~1 ~24 ~58 ~1 ~24 iron_block 0  
fill ~45 ~1 ~25 ~57 ~1 ~25 iron_block 0  
fill ~45 ~1 ~26 ~57 ~1 ~26 iron_block 0  
fill ~45 ~1 ~27 ~57 ~1 ~27 iron_block 0  
fill ~45 ~1 ~28 ~57 ~1 ~28 iron_block 0  
fill ~45 ~1 ~29 ~57 ~1 ~29 iron_block 0  
fill ~45 ~1 ~30 ~61 ~1 ~30 iron_block 0  
fill ~45 ~1 ~31 ~61 ~1 ~31 iron_block 0  
fill ~45 ~1 ~32 ~61 ~1 ~32 iron_block 0  
fill ~45 ~1 ~33 ~61 ~1 ~33 iron_block 0  
fill ~45 ~1 ~34 ~61 ~1 ~34 iron_block 0  
fill ~45 ~1 ~35 ~61 ~1 ~35 iron_block 0  
fill ~47 ~1 ~4 ~54 ~1 ~4 cobblestone 0  
fill ~47 ~1 ~36 ~54 ~1 ~36 cobblestone 0  
fill ~48 ~1 ~2 ~53 ~1 ~2 cobblestone 0  
fill ~48 ~1 ~38 ~53 ~1 ~38 cobblestone 0  
fill ~49 ~1 ~3 ~52 ~1 ~3 cobblestone 0  
fill ~49 ~1 ~37 ~52 ~1 ~37 cobblestone 0  
fill ~53 ~1 ~5 ~53 ~1 ~7 stone_stairs 1  
fill ~53 ~1 ~8 ~54 ~1 ~8 cobblestone 0  
fill ~53 ~1 ~9 ~54 ~1 ~9 cobblestone 0  
fill ~53 ~1 ~10 ~54 ~1 ~10 cobblestone 0  
fill ~54 ~1 ~11 ~54 ~8 ~11 cobblestone 0  
fill ~54 ~1 ~12 ~59 ~1 ~12 cobblestone 0  
fill ~54 ~1 ~13 ~54 ~2 ~13 cobblestone 0  
fill ~54 ~1 ~14 ~54 ~8 ~14 cobblestone 0  
fill ~54 ~1 ~15 ~54 ~8 ~15 cobblestone 0  
fill ~54 ~1 ~16 ~54 ~8 ~16 cobblestone 0  
fill ~54 ~1 ~17 ~54 ~8 ~17 cobblestone 0  
fill ~55 ~1 ~11 ~57 ~1 ~11 stone_slab 3  
fill ~55 ~1 ~13 ~58 ~1 ~13 iron_block 0  
fill ~55 ~1 ~14 ~58 ~1 ~14 iron_block 0  
fill ~55 ~1 ~15 ~58 ~1 ~15 iron_block 0  
fill ~55 ~1 ~16 ~58 ~1 ~16 iron_block 0  
fill ~55 ~1 ~17 ~58 ~1 ~17 iron_block 0 
setblock ~55 ~1 ~36 iron_block 0  
fill ~56 ~1 ~4 ~57 ~1 ~4 cobblestone 0  
fill ~56 ~1 ~36 ~58 ~1 ~36 cobblestone 0  
fill ~58 ~1 ~10 ~58 ~10 ~10 cobblestone 0  
fill ~58 ~1 ~11 ~59 ~1 ~11 cobblestone 0  
fill ~59 ~1 ~10 ~61 ~1 ~10 stone_stairs 2  
fill ~59 ~1 ~13 ~59 ~3 ~13 cobblestone 0  
fill ~59 ~1 ~14 ~59 ~4 ~14 cobblestone 0  
fill ~59 ~1 ~15 ~59 ~5 ~15 cobblestone 0  
fill ~59 ~1 ~16 ~59 ~6 ~16 cobblestone 0  
fill ~59 ~1 ~17 ~59 ~7 ~17 cobblestone 0 
setblock ~59 ~1 ~36 iron_block 0  
fill ~60 ~1 ~18 ~63 ~1 ~18 cobblestone 0  
fill ~60 ~1 ~19 ~63 ~1 ~19 cobblestone 0  
fill ~60 ~1 ~20 ~63 ~1 ~20 cobblestone 0  
fill ~60 ~1 ~21 ~63 ~1 ~21 cobblestone 0  
fill ~60 ~1 ~22 ~63 ~1 ~22 cobblestone 0  
fill ~60 ~1 ~36 ~63 ~1 ~36 cobblestone 0  
fill ~61 ~1 ~4 ~63 ~1 ~4 cobblestone 0  
fill ~61 ~1 ~17 ~63 ~1 ~17 cobblestone 0  
fill ~61 ~1 ~38 ~66 ~1 ~38 cobblestone 0  
fill ~62 ~1 ~2 ~66 ~1 ~2 cobblestone 0  
fill ~62 ~1 ~3 ~65 ~1 ~3 cobblestone 0  
fill ~62 ~1 ~6 ~63 ~1 ~6 cobblestone 0  
fill ~62 ~1 ~7 ~63 ~1 ~7 cobblestone 0  
fill ~62 ~1 ~8 ~63 ~1 ~8 cobblestone 0  
fill ~62 ~1 ~9 ~63 ~1 ~9 cobblestone 0  
fill ~62 ~1 ~11 ~63 ~1 ~11 cobblestone 0  
fill ~62 ~1 ~12 ~63 ~1 ~12 cobblestone 0  
fill ~62 ~1 ~16 ~62 ~10 ~16 cobblestone 0  
fill ~62 ~1 ~23 ~63 ~1 ~23 cobblestone 0  
fill ~62 ~1 ~37 ~65 ~1 ~37 cobblestone 0  
fill ~63 ~1 ~13 ~63 ~2 ~13 cobblestone 0  
fill ~63 ~1 ~14 ~63 ~11 ~14 cobblestone 0  
fill ~63 ~1 ~15 ~63 ~19 ~15 cobblestone 0 
setblock ~63 ~1 ~16 stone_slab 3 
setblock ~63 ~1 ~24 stone_slab 3  
fill ~63 ~1 ~25 ~63 ~19 ~25 cobblestone 0  
fill ~63 ~1 ~26 ~63 ~11 ~26 cobblestone 0  
fill ~63 ~1 ~27 ~63 ~2 ~27 cobblestone 0  
fill ~63 ~1 ~28 ~63 ~2 ~28 cobblestone 0  
fill ~63 ~1 ~29 ~63 ~19 ~29 cobblestone 0  
fill ~63 ~1 ~31 ~63 ~8 ~31 cobblestone 0  
fill ~63 ~1 ~32 ~63 ~2 ~32 cobblestone 0  
fill ~63 ~1 ~33 ~63 ~2 ~33 cobblestone 0  
fill ~63 ~1 ~34 ~63 ~19 ~34 cobblestone 0  
fill ~64 ~1 ~5 ~66 ~1 ~5 cobblestone 0  
fill ~64 ~1 ~6 ~64 ~1 ~9 stone_stairs 1  
fill ~64 ~1 ~10 ~64 ~19 ~10 cobblestone 0  
fill ~64 ~1 ~11 ~64 ~1 ~15 stone_stairs 1  
fill ~64 ~1 ~17 ~64 ~1 ~23 stone_slab 3  
fill ~64 ~1 ~25 ~64 ~1 ~29 stone_stairs 1  
fill ~64 ~1 ~30 ~64 ~19 ~30 cobblestone 0  
fill ~64 ~1 ~31 ~64 ~1 ~34 stone_stairs 1  
fill ~64 ~1 ~35 ~66 ~1 ~35 cobblestone 0 
setblock ~65 ~1 ~6 cobblestone 0 
setblock ~65 ~1 ~10 stone_stairs 1 
setblock ~65 ~1 ~30 stone_stairs 1 
setblock ~65 ~1 ~34 cobblestone 0  
fill ~1 ~2 ~20 ~2 ~2 ~20 cobblestone 0  
fill ~2 ~2 ~25 ~3 ~2 ~25 cobblestone 0  
fill ~7 ~2 ~11 ~8 ~2 ~11 cobblestone 0  
fill ~7 ~2 ~19 ~7 ~15 ~19 cobblestone 0  
fill ~7 ~2 ~20 ~7 ~15 ~20 cobblestone 0  
fill ~7 ~2 ~21 ~7 ~15 ~21 cobblestone 0  
fill ~7 ~2 ~29 ~8 ~2 ~29 cobblestone 0  
fill ~8 ~2 ~17 ~8 ~7 ~17 cobblestone 0 
setblock ~8 ~2 ~18 snow 0 
setblock ~8 ~2 ~22 snow 0  
fill ~8 ~2 ~23 ~8 ~7 ~23 cobblestone 0 
setblock ~9 ~2 ~2 stone_stairs 0 
setblock ~9 ~2 ~5 stone_stairs 0  
fill ~9 ~2 ~10 ~11 ~2 ~10 cobblestone 0  
fill ~9 ~2 ~15 ~9 ~7 ~15 cobblestone 0  
fill ~9 ~2 ~25 ~9 ~7 ~25 cobblestone 0  
fill ~9 ~2 ~30 ~11 ~2 ~30 cobblestone 0 
setblock ~9 ~2 ~35 stone_stairs 0 
setblock ~9 ~2 ~38 stone_stairs 0 
setblock ~10 ~2 ~1 stone_stairs 2  
fill ~10 ~2 ~2 ~10 ~19 ~2 cobblestone 0  
fill ~10 ~2 ~3 ~12 ~2 ~3 cobblestone 0  
fill ~10 ~2 ~4 ~15 ~2 ~4 cobblestone 0  
fill ~10 ~2 ~5 ~12 ~2 ~5 cobblestone 0 
setblock ~10 ~2 ~14 snow 0 
setblock ~10 ~2 ~26 snow 0  
fill ~10 ~2 ~35 ~12 ~2 ~35 cobblestone 0  
fill ~10 ~2 ~36 ~15 ~2 ~36 cobblestone 0  
fill ~10 ~2 ~37 ~12 ~2 ~37 cobblestone 0  
fill ~10 ~2 ~38 ~10 ~19 ~38 cobblestone 0 
setblock ~10 ~2 ~39 stone_stairs 3  
fill ~11 ~2 ~2 ~12 ~2 ~2 stone_stairs 2  
fill ~11 ~2 ~13 ~11 ~15 ~13 cobblestone 0  
fill ~11 ~2 ~27 ~11 ~15 ~27 cobblestone 0  
fill ~11 ~2 ~38 ~12 ~2 ~38 stone_stairs 3 
setblock ~13 ~2 ~1 stone_stairs 2  
fill ~13 ~2 ~2 ~13 ~19 ~2 cobblestone 0 
setblock ~13 ~2 ~3 stone_stairs 1  
fill ~13 ~2 ~7 ~14 ~2 ~7 cobblestone 0  
fill ~13 ~2 ~13 ~13 ~15 ~13 cobblestone 0  
fill ~13 ~2 ~14 ~13 ~3 ~14 nether_brick_fence 0  
fill ~13 ~2 ~26 ~13 ~3 ~26 nether_brick_fence 0  
fill ~13 ~2 ~27 ~13 ~15 ~27 cobblestone 0  
fill ~13 ~2 ~32 ~14 ~2 ~32 cobblestone 0 
setblock ~13 ~2 ~37 stone_stairs 1  
fill ~13 ~2 ~38 ~13 ~19 ~38 cobblestone 0 
setblock ~13 ~2 ~39 stone_stairs 3 
setblock ~14 ~2 ~2 stone_stairs 1  
fill ~14 ~2 ~8 ~14 ~12 ~8 cobblestone 0  
fill ~14 ~2 ~11 ~14 ~12 ~11 cobblestone 0  
fill ~14 ~2 ~12 ~15 ~2 ~12 snow 0  
fill ~14 ~2 ~13 ~15 ~2 ~13 snow 0  
fill ~14 ~2 ~19 ~16 ~2 ~19 cobblestone 0  
fill ~14 ~2 ~20 ~18 ~2 ~20 cobblestone 0  
fill ~14 ~2 ~21 ~16 ~2 ~21 cobblestone 0  
fill ~14 ~2 ~27 ~15 ~2 ~27 snow 0  
fill ~14 ~2 ~28 ~15 ~2 ~28 snow 0  
fill ~14 ~2 ~29 ~14 ~10 ~29 cobblestone 0  
fill ~14 ~2 ~33 ~15 ~2 ~33 snow 0  
fill ~14 ~2 ~34 ~15 ~2 ~34 snow 0 
setblock ~14 ~2 ~38 stone_stairs 1  
fill ~15 ~2 ~6 ~15 ~2 ~7 snow 0 
setblock ~15 ~2 ~11 torch 4 
setblock ~15 ~2 ~29 torch 3  
fill ~16 ~2 ~5 ~16 ~9 ~5 cobblestone 0  
fill ~16 ~2 ~35 ~16 ~9 ~35 cobblestone 0  
fill ~17 ~2 ~4 ~19 ~2 ~4 cobblestone 0  
fill ~17 ~2 ~17 ~18 ~2 ~17 stone_slab 3  
fill ~17 ~2 ~18 ~17 ~2 ~19 stone_slab 3  
fill ~17 ~2 ~21 ~19 ~2 ~21 stone_slab 3  
fill ~17 ~2 ~36 ~19 ~2 ~36 cobblestone 0  
fill ~18 ~2 ~6 ~18 ~3 ~6 cobblestone 0 
setblock ~18 ~2 ~7 stone_stairs 3  
fill ~18 ~2 ~18 ~18 ~3 ~18 snow 0 
setblock ~18 ~2 ~19 stone_slab 3 
setblock ~18 ~2 ~33 stone_stairs 2  
fill ~18 ~2 ~34 ~18 ~3 ~34 cobblestone 0 
setblock ~19 ~2 ~17 stone_stairs 2 
setblock ~19 ~2 ~18 stone_slab 3 
setblock ~19 ~2 ~19 stone_stairs 3 
setblock ~19 ~2 ~20 stone_stairs 1  
fill ~20 ~2 ~5 ~20 ~9 ~5 cobblestone 0  
fill ~20 ~2 ~35 ~20 ~9 ~35 cobblestone 0  
fill ~21 ~2 ~4 ~28 ~2 ~4 cobblestone 0  
fill ~21 ~2 ~6 ~22 ~2 ~6 snow 0  
fill ~21 ~2 ~7 ~22 ~2 ~7 snow 0  
fill ~21 ~2 ~11 ~22 ~2 ~11 torch 4  
fill ~21 ~2 ~12 ~22 ~2 ~12 snow 0  
fill ~21 ~2 ~13 ~22 ~2 ~13 snow 0  
fill ~21 ~2 ~27 ~22 ~2 ~27 snow 0  
fill ~21 ~2 ~28 ~22 ~2 ~28 snow 0  
fill ~21 ~2 ~29 ~22 ~2 ~29 torch 3  
fill ~21 ~2 ~33 ~22 ~2 ~33 snow 0  
fill ~21 ~2 ~34 ~22 ~2 ~34 snow 0  
fill ~21 ~2 ~36 ~28 ~2 ~36 cobblestone 0 
setblock ~22 ~2 ~2 stone_stairs 0 
setblock ~22 ~2 ~38 stone_stairs 0 
setblock ~23 ~2 ~1 stone_stairs 2  
fill ~23 ~2 ~2 ~23 ~18 ~2 cobblestone 0 
setblock ~23 ~2 ~3 stone_stairs 0  
fill ~23 ~2 ~5 ~23 ~9 ~5 cobblestone 0  
fill ~23 ~2 ~6 ~23 ~3 ~6 nether_brick_fence 0  
fill ~23 ~2 ~34 ~23 ~3 ~34 nether_brick_fence 0  
fill ~23 ~2 ~35 ~23 ~9 ~35 cobblestone 0  
fill ~23 ~2 ~37 ~25 ~2 ~37 cobblestone 0  
fill ~23 ~2 ~38 ~23 ~18 ~38 cobblestone 0 
setblock ~23 ~2 ~39 stone_stairs 3  
fill ~24 ~2 ~2 ~25 ~2 ~2 stone_stairs 2  
fill ~24 ~2 ~3 ~25 ~2 ~3 cobblestone 0  
fill ~24 ~2 ~38 ~25 ~2 ~38 stone_stairs 3 
setblock ~26 ~2 ~1 stone_stairs 2  
fill ~26 ~2 ~2 ~26 ~18 ~2 cobblestone 0 
setblock ~26 ~2 ~3 stone_stairs 1  
fill ~26 ~2 ~5 ~26 ~9 ~5 cobblestone 0  
fill ~26 ~2 ~6 ~26 ~3 ~6 nether_brick_fence 0  
fill ~26 ~2 ~34 ~26 ~3 ~34 nether_brick_fence 0  
fill ~26 ~2 ~35 ~26 ~9 ~35 cobblestone 0 
setblock ~26 ~2 ~37 stone_stairs 1  
fill ~26 ~2 ~38 ~26 ~18 ~38 cobblestone 0 
setblock ~26 ~2 ~39 stone_stairs 3 
setblock ~27 ~2 ~2 stone_stairs 1  
fill ~27 ~2 ~6 ~28 ~2 ~6 snow 0  
fill ~27 ~2 ~7 ~28 ~2 ~7 snow 0  
fill ~27 ~2 ~11 ~28 ~2 ~11 torch 4  
fill ~27 ~2 ~12 ~28 ~2 ~12 snow 0  
fill ~27 ~2 ~13 ~28 ~2 ~13 snow 0  
fill ~27 ~2 ~27 ~28 ~2 ~27 snow 0  
fill ~27 ~2 ~28 ~28 ~2 ~28 snow 0  
fill ~27 ~2 ~29 ~28 ~2 ~29 torch 3  
fill ~27 ~2 ~33 ~28 ~2 ~33 snow 0  
fill ~27 ~2 ~34 ~28 ~2 ~34 snow 0 
setblock ~27 ~2 ~38 stone_stairs 1  
fill ~29 ~2 ~5 ~29 ~9 ~5 cobblestone 0  
fill ~29 ~2 ~35 ~29 ~9 ~35 cobblestone 0  
fill ~30 ~2 ~4 ~32 ~2 ~4 cobblestone 0  
fill ~30 ~2 ~36 ~32 ~2 ~36 cobblestone 0  
fill ~31 ~2 ~6 ~31 ~3 ~6 cobblestone 0 
setblock ~31 ~2 ~7 stone_stairs 3 
setblock ~31 ~2 ~33 stone_stairs 2  
fill ~31 ~2 ~34 ~31 ~3 ~34 cobblestone 0  
fill ~33 ~2 ~5 ~33 ~9 ~5 cobblestone 0  
fill ~33 ~2 ~35 ~33 ~9 ~35 cobblestone 0  
fill ~34 ~2 ~4 ~41 ~2 ~4 cobblestone 0  
fill ~34 ~2 ~6 ~35 ~2 ~6 snow 0  
fill ~34 ~2 ~7 ~35 ~2 ~7 snow 0  
fill ~34 ~2 ~11 ~35 ~2 ~11 torch 4  
fill ~34 ~2 ~12 ~35 ~2 ~12 snow 0  
fill ~34 ~2 ~13 ~35 ~2 ~13 snow 0  
fill ~34 ~2 ~27 ~35 ~2 ~27 snow 0  
fill ~34 ~2 ~28 ~35 ~2 ~28 snow 0  
fill ~34 ~2 ~29 ~35 ~2 ~29 torch 3  
fill ~34 ~2 ~33 ~35 ~2 ~33 snow 0  
fill ~34 ~2 ~34 ~35 ~2 ~34 snow 0  
fill ~34 ~2 ~36 ~41 ~2 ~36 cobblestone 0 
setblock ~35 ~2 ~2 stone_stairs 0 
setblock ~35 ~2 ~38 stone_stairs 0 
setblock ~36 ~2 ~1 stone_stairs 2  
fill ~36 ~2 ~2 ~36 ~18 ~2 cobblestone 0 
setblock ~36 ~2 ~3 stone_stairs 0  
fill ~36 ~2 ~5 ~36 ~9 ~5 cobblestone 0  
fill ~36 ~2 ~6 ~36 ~3 ~6 nether_brick_fence 0  
fill ~36 ~2 ~34 ~36 ~3 ~34 nether_brick_fence 0  
fill ~36 ~2 ~35 ~36 ~9 ~35 cobblestone 0  
fill ~36 ~2 ~37 ~38 ~2 ~37 cobblestone 0  
fill ~36 ~2 ~38 ~36 ~18 ~38 cobblestone 0 
setblock ~36 ~2 ~39 stone_stairs 3  
fill ~37 ~2 ~2 ~38 ~2 ~2 stone_stairs 2  
fill ~37 ~2 ~3 ~38 ~2 ~3 cobblestone 0  
fill ~37 ~2 ~38 ~38 ~2 ~38 stone_stairs 3 
setblock ~39 ~2 ~1 stone_stairs 2  
fill ~39 ~2 ~2 ~39 ~18 ~2 cobblestone 0 
setblock ~39 ~2 ~3 stone_stairs 1  
fill ~39 ~2 ~5 ~39 ~9 ~5 cobblestone 0  
fill ~39 ~2 ~6 ~39 ~3 ~6 nether_brick_fence 0  
fill ~39 ~2 ~34 ~39 ~3 ~34 nether_brick_fence 0  
fill ~39 ~2 ~35 ~39 ~9 ~35 cobblestone 0 
setblock ~39 ~2 ~37 stone_stairs 1  
fill ~39 ~2 ~38 ~39 ~18 ~38 cobblestone 0 
setblock ~39 ~2 ~39 stone_stairs 3 
setblock ~40 ~2 ~2 stone_stairs 1  
fill ~40 ~2 ~6 ~41 ~2 ~6 snow 0  
fill ~40 ~2 ~7 ~41 ~2 ~7 snow 0  
fill ~40 ~2 ~11 ~41 ~2 ~11 torch 4  
fill ~40 ~2 ~12 ~41 ~2 ~12 snow 0  
fill ~40 ~2 ~13 ~41 ~2 ~13 snow 0  
fill ~40 ~2 ~27 ~41 ~2 ~27 snow 0  
fill ~40 ~2 ~28 ~41 ~2 ~28 snow 0  
fill ~40 ~2 ~29 ~41 ~2 ~29 torch 3  
fill ~40 ~2 ~33 ~41 ~2 ~33 snow 0  
fill ~40 ~2 ~34 ~41 ~2 ~34 snow 0 
setblock ~40 ~2 ~38 stone_stairs 1  
fill ~42 ~2 ~5 ~42 ~9 ~5 cobblestone 0  
fill ~42 ~2 ~35 ~42 ~9 ~35 cobblestone 0  
fill ~43 ~2 ~4 ~45 ~2 ~4 cobblestone 0  
fill ~43 ~2 ~36 ~45 ~2 ~36 cobblestone 0  
fill ~44 ~2 ~6 ~44 ~3 ~6 cobblestone 0 
setblock ~44 ~2 ~7 stone_stairs 3 
setblock ~44 ~2 ~33 stone_stairs 2  
fill ~44 ~2 ~34 ~44 ~3 ~34 cobblestone 0  
fill ~46 ~2 ~5 ~46 ~9 ~5 cobblestone 0  
fill ~46 ~2 ~35 ~46 ~9 ~35 cobblestone 0  
fill ~47 ~2 ~4 ~54 ~2 ~4 cobblestone 0  
fill ~47 ~2 ~6 ~48 ~2 ~6 snow 0  
fill ~47 ~2 ~7 ~48 ~2 ~7 snow 0  
fill ~47 ~2 ~11 ~48 ~2 ~11 torch 4  
fill ~47 ~2 ~12 ~48 ~2 ~12 snow 0  
fill ~47 ~2 ~13 ~48 ~2 ~13 snow 0  
fill ~47 ~2 ~27 ~48 ~2 ~27 snow 0  
fill ~47 ~2 ~28 ~48 ~2 ~28 snow 0  
fill ~47 ~2 ~29 ~48 ~2 ~29 torch 3  
fill ~47 ~2 ~33 ~48 ~2 ~33 snow 0  
fill ~47 ~2 ~34 ~48 ~2 ~34 snow 0  
fill ~47 ~2 ~36 ~54 ~2 ~36 cobblestone 0 
setblock ~48 ~2 ~2 stone_stairs 0  
fill ~48 ~2 ~15 ~48 ~3 ~15 nether_brick_fence 0  
fill ~48 ~2 ~25 ~48 ~3 ~25 nether_brick_fence 0 
setblock ~48 ~2 ~38 stone_stairs 0 
setblock ~49 ~2 ~1 stone_stairs 2  
fill ~49 ~2 ~2 ~49 ~18 ~2 cobblestone 0 
setblock ~49 ~2 ~3 stone_stairs 0  
fill ~49 ~2 ~5 ~49 ~9 ~5 cobblestone 0  
fill ~49 ~2 ~6 ~49 ~9 ~6 cobblestone 0  
fill ~49 ~2 ~7 ~49 ~9 ~7 cobblestone 0  
fill ~49 ~2 ~8 ~49 ~10 ~8 cobblestone 0  
fill ~49 ~2 ~11 ~49 ~13 ~11 cobblestone 0  
fill ~49 ~2 ~12 ~50 ~2 ~12 cobblestone 0  
fill ~49 ~2 ~13 ~49 ~14 ~13 cobblestone 0  
fill ~49 ~2 ~14 ~49 ~9 ~14 cobblestone 0  
fill ~49 ~2 ~15 ~49 ~9 ~15 cobblestone 0  
fill ~49 ~2 ~16 ~49 ~10 ~16 cobblestone 0  
fill ~49 ~2 ~17 ~49 ~4 ~17 obsidian 0  
fill ~49 ~2 ~23 ~49 ~4 ~23 obsidian 0  
fill ~49 ~2 ~24 ~49 ~10 ~24 cobblestone 0  
fill ~49 ~2 ~25 ~49 ~9 ~25 cobblestone 0  
fill ~49 ~2 ~26 ~49 ~9 ~26 cobblestone 0  
fill ~49 ~2 ~27 ~49 ~14 ~27 cobblestone 0  
fill ~49 ~2 ~28 ~50 ~2 ~28 cobblestone 0  
fill ~49 ~2 ~29 ~49 ~13 ~29 cobblestone 0  
fill ~49 ~2 ~32 ~49 ~10 ~32 cobblestone 0  
fill ~49 ~2 ~33 ~49 ~9 ~33 cobblestone 0  
fill ~49 ~2 ~34 ~49 ~9 ~34 cobblestone 0  
fill ~49 ~2 ~35 ~49 ~9 ~35 cobblestone 0 
setblock ~49 ~2 ~37 stone_stairs 0  
fill ~49 ~2 ~38 ~49 ~18 ~38 cobblestone 0 
setblock ~49 ~2 ~39 stone_stairs 3  
fill ~50 ~2 ~2 ~51 ~2 ~2 stone_stairs 2  
fill ~50 ~2 ~3 ~51 ~2 ~3 cobblestone 0  
fill ~50 ~2 ~17 ~50 ~7 ~17 cobblestone 0  
fill ~50 ~2 ~23 ~50 ~8 ~23 cobblestone 0  
fill ~50 ~2 ~37 ~51 ~2 ~37 cobblestone 0  
fill ~50 ~2 ~38 ~51 ~2 ~38 stone_stairs 3  
fill ~51 ~2 ~17 ~51 ~4 ~17 obsidian 0  
fill ~51 ~2 ~23 ~51 ~4 ~23 obsidian 0 
setblock ~52 ~2 ~1 stone_stairs 2  
fill ~52 ~2 ~2 ~52 ~18 ~2 cobblestone 0 
setblock ~52 ~2 ~3 stone_stairs 1  
fill ~52 ~2 ~12 ~54 ~2 ~12 cobblestone 0  
fill ~52 ~2 ~17 ~52 ~7 ~17 cobblestone 0  
fill ~52 ~2 ~23 ~52 ~8 ~23 cobblestone 0  
fill ~52 ~2 ~28 ~54 ~2 ~28 cobblestone 0 
setblock ~52 ~2 ~37 stone_stairs 1  
fill ~52 ~2 ~38 ~52 ~18 ~38 cobblestone 0 
setblock ~52 ~2 ~39 stone_stairs 3 
setblock ~53 ~2 ~2 stone_stairs 1  
fill ~53 ~2 ~8 ~54 ~2 ~8 cobblestone 0  
fill ~53 ~2 ~9 ~54 ~2 ~9 cobblestone 0  
fill ~53 ~2 ~10 ~54 ~2 ~10 cobblestone 0  
fill ~53 ~2 ~11 ~53 ~7 ~11 cobblestone 0  
fill ~53 ~2 ~13 ~53 ~7 ~13 cobblestone 0  
fill ~53 ~2 ~14 ~53 ~7 ~14 cobblestone 0  
fill ~53 ~2 ~15 ~53 ~7 ~15 cobblestone 0  
fill ~53 ~2 ~16 ~53 ~7 ~16 cobblestone 0  
fill ~53 ~2 ~17 ~53 ~4 ~17 obsidian 0  
fill ~53 ~2 ~23 ~53 ~4 ~23 obsidian 0  
fill ~53 ~2 ~24 ~54 ~2 ~24 cobblestone 0  
fill ~53 ~2 ~25 ~54 ~2 ~25 cobblestone 0  
fill ~53 ~2 ~26 ~54 ~2 ~26 cobblestone 0  
fill ~53 ~2 ~27 ~54 ~2 ~27 cobblestone 0  
fill ~53 ~2 ~29 ~54 ~2 ~29 cobblestone 0  
fill ~53 ~2 ~30 ~54 ~2 ~30 cobblestone 0  
fill ~53 ~2 ~31 ~54 ~2 ~31 cobblestone 0  
fill ~53 ~2 ~32 ~54 ~2 ~32 cobblestone 0 
setblock ~53 ~2 ~38 stone_stairs 1  
fill ~54 ~2 ~23 ~54 ~8 ~23 cobblestone 0  
fill ~56 ~2 ~4 ~57 ~2 ~4 cobblestone 0  
fill ~56 ~2 ~36 ~58 ~2 ~36 cobblestone 0  
fill ~58 ~2 ~11 ~58 ~10 ~11 cobblestone 0  
fill ~58 ~2 ~12 ~59 ~2 ~12 cobblestone 0  
fill ~58 ~2 ~13 ~58 ~10 ~13 cobblestone 0  
fill ~58 ~2 ~14 ~58 ~10 ~14 cobblestone 0  
fill ~58 ~2 ~15 ~58 ~10 ~15 cobblestone 0  
fill ~58 ~2 ~25 ~59 ~2 ~25 cobblestone 0  
fill ~58 ~2 ~26 ~58 ~10 ~26 cobblestone 0  
fill ~58 ~2 ~27 ~58 ~10 ~27 cobblestone 0  
fill ~58 ~2 ~28 ~58 ~10 ~28 cobblestone 0  
fill ~58 ~2 ~29 ~58 ~10 ~29 cobblestone 0  
fill ~58 ~2 ~30 ~58 ~10 ~30 cobblestone 0  
fill ~59 ~2 ~11 ~61 ~2 ~11 stone_stairs 2  
fill ~59 ~2 ~18 ~60 ~2 ~18 cobblestone 0  
fill ~59 ~2 ~22 ~60 ~2 ~22 cobblestone 0  
fill ~59 ~2 ~23 ~59 ~7 ~23 cobblestone 0  
fill ~59 ~2 ~24 ~59 ~6 ~24 cobblestone 0  
fill ~59 ~2 ~29 ~61 ~2 ~29 stone_stairs 3  
fill ~60 ~2 ~36 ~64 ~2 ~36 cobblestone 0  
fill ~61 ~2 ~4 ~64 ~2 ~4 cobblestone 0  
fill ~61 ~2 ~17 ~61 ~7 ~17 cobblestone 0 
setblock ~61 ~2 ~38 stone_stairs 0  
fill ~62 ~2 ~2 ~62 ~19 ~2 cobblestone 0  
fill ~62 ~2 ~3 ~64 ~2 ~3 cobblestone 0  
fill ~62 ~2 ~6 ~63 ~2 ~6 cobblestone 0  
fill ~62 ~2 ~7 ~63 ~2 ~7 cobblestone 0  
fill ~62 ~2 ~8 ~63 ~2 ~8 cobblestone 0  
fill ~62 ~2 ~9 ~63 ~2 ~9 cobblestone 0  
fill ~62 ~2 ~11 ~63 ~2 ~11 cobblestone 0  
fill ~62 ~2 ~12 ~63 ~2 ~12 cobblestone 0  
fill ~62 ~2 ~13 ~62 ~10 ~13 cobblestone 0  
fill ~62 ~2 ~27 ~62 ~10 ~27 cobblestone 0  
fill ~62 ~2 ~28 ~62 ~10 ~28 cobblestone 0  
fill ~62 ~2 ~29 ~62 ~6 ~29 cobblestone 0  
fill ~62 ~2 ~30 ~62 ~6 ~30 cobblestone 0  
fill ~62 ~2 ~31 ~62 ~10 ~31 cobblestone 0  
fill ~62 ~2 ~32 ~62 ~10 ~32 cobblestone 0  
fill ~62 ~2 ~33 ~62 ~6 ~33 cobblestone 0  
fill ~62 ~2 ~34 ~62 ~6 ~34 cobblestone 0  
fill ~62 ~2 ~35 ~62 ~10 ~35 cobblestone 0 
setblock ~62 ~2 ~37 stone_stairs 0  
fill ~62 ~2 ~38 ~62 ~19 ~38 cobblestone 0 
setblock ~62 ~2 ~39 stone_stairs 3  
fill ~63 ~2 ~2 ~64 ~2 ~2 stone_stairs 2  
fill ~63 ~2 ~37 ~64 ~2 ~37 cobblestone 0  
fill ~63 ~2 ~38 ~64 ~2 ~38 stone_stairs 3  
fill ~64 ~2 ~5 ~65 ~2 ~5 cobblestone 0  
fill ~64 ~2 ~35 ~65 ~2 ~35 cobblestone 0 
setblock ~65 ~2 ~1 stone_stairs 2  
fill ~65 ~2 ~2 ~65 ~19 ~2 cobblestone 0  
fill ~65 ~2 ~3 ~65 ~2 ~4 stone_stairs 1 
setblock ~65 ~2 ~6 stone_stairs 3 
setblock ~65 ~2 ~34 stone_stairs 2  
fill ~65 ~2 ~36 ~65 ~2 ~37 stone_stairs 1  
fill ~65 ~2 ~38 ~65 ~19 ~38 cobblestone 0 
setblock ~65 ~2 ~39 stone_stairs 3 
setblock ~66 ~2 ~2 stone_stairs 1 
setblock ~66 ~2 ~5 stone_stairs 1 
setblock ~66 ~2 ~35 stone_stairs 1 
setblock ~66 ~2 ~38 stone_stairs 1  
fill ~1 ~3 ~20 ~2 ~3 ~20 cobblestone 0  
fill ~2 ~3 ~25 ~3 ~3 ~25 cobblestone 0  
fill ~7 ~3 ~11 ~8 ~3 ~11 cobblestone 0  
fill ~7 ~3 ~29 ~8 ~3 ~29 cobblestone 0  
fill ~8 ~3 ~18 ~8 ~19 ~18 obsidian 0  
fill ~8 ~3 ~22 ~8 ~19 ~22 obsidian 0  
fill ~9 ~3 ~10 ~11 ~3 ~10 cobblestone 0  
fill ~9 ~3 ~30 ~11 ~3 ~30 cobblestone 0  
fill ~10 ~3 ~5 ~12 ~3 ~5 cobblestone 0  
fill ~10 ~3 ~14 ~10 ~19 ~14 obsidian 0  
fill ~10 ~3 ~26 ~10 ~19 ~26 obsidian 0  
fill ~10 ~3 ~35 ~12 ~3 ~35 cobblestone 0  
fill ~11 ~3 ~3 ~12 ~3 ~3 cobblestone 0  
fill ~11 ~3 ~4 ~15 ~3 ~4 cobblestone 0  
fill ~11 ~3 ~36 ~15 ~3 ~36 cobblestone 0  
fill ~11 ~3 ~37 ~12 ~3 ~37 cobblestone 0  
fill ~13 ~3 ~7 ~14 ~3 ~7 cobblestone 0  
fill ~13 ~3 ~32 ~14 ~3 ~32 cobblestone 0  
fill ~14 ~3 ~12 ~15 ~3 ~12 obsidian 0  
fill ~14 ~3 ~13 ~15 ~3 ~13 obsidian 0  
fill ~14 ~3 ~19 ~16 ~3 ~19 cobblestone 0  
fill ~14 ~3 ~20 ~17 ~3 ~20 cobblestone 0  
fill ~14 ~3 ~21 ~16 ~3 ~21 cobblestone 0  
fill ~14 ~3 ~27 ~15 ~3 ~27 obsidian 0  
fill ~14 ~3 ~28 ~15 ~3 ~28 obsidian 0  
fill ~14 ~3 ~33 ~15 ~3 ~33 obsidian 0  
fill ~14 ~3 ~34 ~15 ~3 ~34 obsidian 0  
fill ~15 ~3 ~6 ~15 ~9 ~6 obsidian 0  
fill ~15 ~3 ~7 ~15 ~9 ~7 obsidian 0 
setblock ~16 ~3 ~18 torch 4 
setblock ~16 ~3 ~22 torch 3  
fill ~17 ~3 ~4 ~19 ~3 ~4 cobblestone 0  
fill ~17 ~3 ~36 ~19 ~3 ~36 cobblestone 0 
setblock ~18 ~3 ~20 stone_stairs 1
fill ~21 ~3 ~4 ~28 ~3 ~4 cobblestone 0  
fill ~21 ~3 ~6 ~22 ~3 ~6 obsidian 0  
fill ~21 ~3 ~7 ~22 ~3 ~7 obsidian 0  
fill ~21 ~3 ~12 ~22 ~3 ~12 obsidian 0  
fill ~21 ~3 ~13 ~22 ~3 ~13 obsidian 0  
fill ~21 ~3 ~27 ~22 ~3 ~27 obsidian 0  
fill ~21 ~3 ~28 ~22 ~3 ~28 obsidian 0  
fill ~21 ~3 ~33 ~22 ~3 ~33 obsidian 0  
fill ~21 ~3 ~34 ~22 ~3 ~34 obsidian 0  
fill ~21 ~3 ~36 ~28 ~3 ~36 cobblestone 0  
fill ~24 ~3 ~3 ~25 ~3 ~3 cobblestone 0  
fill ~24 ~3 ~37 ~25 ~3 ~37 cobblestone 0  
fill ~27 ~3 ~6 ~28 ~3 ~6 obsidian 0  
fill ~27 ~3 ~7 ~28 ~3 ~7 obsidian 0  
fill ~27 ~3 ~12 ~28 ~3 ~12 obsidian 0  
fill ~27 ~3 ~13 ~28 ~3 ~13 obsidian 0  
fill ~27 ~3 ~27 ~28 ~3 ~27 obsidian 0  
fill ~27 ~3 ~28 ~28 ~3 ~28 obsidian 0  
fill ~27 ~3 ~33 ~28 ~3 ~33 obsidian 0  
fill ~27 ~3 ~34 ~28 ~3 ~34 obsidian 0  
fill ~30 ~3 ~4 ~32 ~3 ~4 cobblestone 0  
fill ~30 ~3 ~36 ~32 ~3 ~36 cobblestone 0  
fill ~34 ~3 ~4 ~41 ~3 ~4 cobblestone 0  
fill ~34 ~3 ~6 ~35 ~3 ~6 obsidian 0  
fill ~34 ~3 ~7 ~35 ~3 ~7 obsidian 0  
fill ~34 ~3 ~12 ~35 ~3 ~12 obsidian 0  
fill ~34 ~3 ~13 ~35 ~3 ~13 obsidian 0  
fill ~34 ~3 ~27 ~35 ~3 ~27 obsidian 0  
fill ~34 ~3 ~28 ~35 ~3 ~28 obsidian 0  
fill ~34 ~3 ~33 ~35 ~3 ~33 obsidian 0  
fill ~34 ~3 ~34 ~35 ~3 ~34 obsidian 0  
fill ~34 ~3 ~36 ~41 ~3 ~36 cobblestone 0  
fill ~37 ~3 ~3 ~38 ~3 ~3 cobblestone 0  
fill ~37 ~3 ~37 ~38 ~3 ~37 cobblestone 0  
fill ~40 ~3 ~6 ~41 ~3 ~6 obsidian 0  
fill ~40 ~3 ~7 ~41 ~3 ~7 obsidian 0  
fill ~40 ~3 ~12 ~41 ~3 ~12 obsidian 0  
fill ~40 ~3 ~13 ~41 ~3 ~13 obsidian 0  
fill ~40 ~3 ~27 ~41 ~3 ~27 obsidian 0  
fill ~40 ~3 ~28 ~41 ~3 ~28 obsidian 0  
fill ~40 ~3 ~33 ~41 ~3 ~33 obsidian 0  
fill ~40 ~3 ~34 ~41 ~3 ~34 obsidian 0  
fill ~43 ~3 ~4 ~45 ~3 ~4 cobblestone 0  
fill ~43 ~3 ~36 ~45 ~3 ~36 cobblestone 0  
fill ~47 ~3 ~4 ~54 ~3 ~4 cobblestone 0  
fill ~47 ~3 ~6 ~48 ~3 ~6 obsidian 0  
fill ~47 ~3 ~7 ~48 ~3 ~7 obsidian 0  
fill ~47 ~3 ~12 ~48 ~3 ~12 obsidian 0  
fill ~47 ~3 ~13 ~48 ~3 ~13 obsidian 0  
fill ~47 ~3 ~27 ~48 ~3 ~27 obsidian 0  
fill ~47 ~3 ~28 ~48 ~3 ~28 obsidian 0  
fill ~47 ~3 ~33 ~48 ~3 ~33 obsidian 0  
fill ~47 ~3 ~34 ~48 ~3 ~34 obsidian 0  
fill ~47 ~3 ~36 ~54 ~3 ~36 cobblestone 0  
fill ~49 ~3 ~12 ~50 ~3 ~12 cobblestone 0  
fill ~49 ~3 ~28 ~50 ~3 ~28 cobblestone 0  
fill ~50 ~3 ~3 ~51 ~3 ~3 cobblestone 0  
fill ~50 ~3 ~37 ~51 ~3 ~37 cobblestone 0  
fill ~52 ~3 ~12 ~53 ~3 ~12 cobblestone 0  
fill ~52 ~3 ~28 ~53 ~3 ~28 cobblestone 0  
fill ~53 ~3 ~8 ~54 ~3 ~8 cobblestone 0  
fill ~53 ~3 ~24 ~54 ~3 ~24 cobblestone 0  
fill ~53 ~3 ~25 ~54 ~3 ~25 cobblestone 0  
fill ~53 ~3 ~26 ~54 ~3 ~26 cobblestone 0  
fill ~53 ~3 ~27 ~53 ~8 ~27 cobblestone 0  
fill ~53 ~3 ~29 ~54 ~3 ~29 cobblestone 0  
fill ~53 ~3 ~32 ~54 ~3 ~32 cobblestone 0  
fill ~54 ~3 ~9 ~54 ~7 ~9 cobblestone 0  
fill ~54 ~3 ~10 ~54 ~8 ~10 cobblestone 0  
fill ~54 ~3 ~30 ~54 ~8 ~30 cobblestone 0  
fill ~54 ~3 ~31 ~54 ~8 ~31 cobblestone 0  
fill ~56 ~3 ~4 ~57 ~3 ~4 cobblestone 0  
fill ~56 ~3 ~36 ~58 ~3 ~36 cobblestone 0  
fill ~57 ~3 ~1 ~57 ~3 ~3 stone_brick_stairs 0 
setblock ~58 ~3 ~4 stone_stairs 5  
fill ~58 ~3 ~12 ~58 ~10 ~12 cobblestone 0  
fill ~58 ~3 ~25 ~58 ~10 ~25 cobblestone 0  
fill ~59 ~3 ~12 ~61 ~3 ~12 stone_stairs 2  
fill ~59 ~3 ~18 ~60 ~3 ~18 cobblestone 0  
fill ~59 ~3 ~22 ~60 ~3 ~22 cobblestone 0  
fill ~59 ~3 ~28 ~61 ~3 ~28 stone_stairs 3 
setblock ~60 ~3 ~4 stone_stairs 4  
fill ~60 ~3 ~36 ~64 ~3 ~36 cobblestone 0 
setblock ~61 ~3 ~2 stonebrick 0 
setblock ~61 ~3 ~3 stone_brick_stairs 1  
fill ~61 ~3 ~4 ~64 ~3 ~4 cobblestone 0 
setblock ~62 ~3 ~1 stone_brick_stairs 1  
fill ~62 ~3 ~3 ~64 ~3 ~3 cobblestone 0  
fill ~62 ~3 ~6 ~63 ~3 ~6 cobblestone 0  
fill ~62 ~3 ~7 ~62 ~6 ~7 cobblestone 0  
fill ~62 ~3 ~8 ~62 ~10 ~8 cobblestone 0  
fill ~62 ~3 ~9 ~63 ~3 ~9 cobblestone 0  
fill ~62 ~3 ~11 ~63 ~3 ~11 cobblestone 0  
fill ~62 ~3 ~12 ~62 ~10 ~12 cobblestone 0  
fill ~63 ~3 ~37 ~64 ~3 ~37 cobblestone 0  
fill ~64 ~3 ~5 ~65 ~3 ~5 cobblestone 0  
fill ~64 ~3 ~35 ~65 ~3 ~35 cobblestone 0  
fill ~1 ~4 ~20 ~2 ~4 ~20 cobblestone 0  
fill ~2 ~4 ~25 ~3 ~4 ~25 cobblestone 0  
fill ~7 ~4 ~11 ~8 ~4 ~11 cobblestone 0  
fill ~7 ~4 ~29 ~8 ~4 ~29 cobblestone 0  
fill ~9 ~4 ~10 ~11 ~4 ~10 cobblestone 0  
fill ~9 ~4 ~30 ~11 ~4 ~30 cobblestone 0  
fill ~10 ~4 ~5 ~12 ~4 ~5 cobblestone 0  
fill ~10 ~4 ~35 ~12 ~4 ~35 cobblestone 0  
fill ~11 ~4 ~3 ~12 ~4 ~3 cobblestone 0  
fill ~11 ~4 ~4 ~15 ~4 ~4 cobblestone 0  
fill ~11 ~4 ~36 ~15 ~4 ~36 cobblestone 0  
fill ~11 ~4 ~37 ~12 ~4 ~37 cobblestone 0  
fill ~13 ~4 ~7 ~14 ~4 ~7 cobblestone 0 
setblock ~13 ~4 ~14 torch 5 
setblock ~13 ~4 ~19 torch 2 
setblock ~13 ~4 ~21 torch 2 
setblock ~13 ~4 ~26 torch 5  
fill ~13 ~4 ~32 ~14 ~4 ~32 cobblestone 0  
fill ~14 ~4 ~12 ~15 ~4 ~12 obsidian 0  
fill ~14 ~4 ~13 ~15 ~4 ~13 obsidian 0  
fill ~14 ~4 ~19 ~16 ~4 ~19 cobblestone 0  
fill ~14 ~4 ~20 ~16 ~4 ~20 cobblestone 0  
fill ~14 ~4 ~21 ~16 ~4 ~21 cobblestone 0  
fill ~14 ~4 ~27 ~15 ~4 ~27 obsidian 0  
fill ~14 ~4 ~28 ~15 ~4 ~28 obsidian 0  
fill ~14 ~4 ~33 ~15 ~4 ~33 obsidian 0  
fill ~14 ~4 ~34 ~15 ~4 ~34 obsidian 0  
fill ~17 ~4 ~4 ~19 ~4 ~4 cobblestone 0 
setblock ~17 ~4 ~20 stone_stairs 1  
fill ~17 ~4 ~36 ~19 ~4 ~36 cobblestone 0 
setblock ~18 ~4 ~6 stone_slab 3 
setblock ~18 ~4 ~34 stone_slab 3  
fill ~21 ~4 ~4 ~28 ~4 ~4 cobblestone 0  
fill ~21 ~4 ~6 ~22 ~4 ~6 obsidian 0  
fill ~21 ~4 ~7 ~22 ~4 ~7 obsidian 0  
fill ~21 ~4 ~12 ~22 ~4 ~12 obsidian 0  
fill ~21 ~4 ~13 ~22 ~4 ~13 obsidian 0  
fill ~21 ~4 ~27 ~22 ~4 ~27 obsidian 0  
fill ~21 ~4 ~28 ~22 ~4 ~28 obsidian 0  
fill ~21 ~4 ~33 ~22 ~4 ~33 obsidian 0  
fill ~21 ~4 ~34 ~22 ~4 ~34 obsidian 0  
fill ~21 ~4 ~36 ~28 ~4 ~36 cobblestone 0 
setblock ~23 ~4 ~6 torch 5 
setblock ~23 ~4 ~34 torch 5  
fill ~24 ~4 ~3 ~25 ~4 ~3 cobblestone 0  
fill ~24 ~4 ~37 ~25 ~4 ~37 cobblestone 0 
setblock ~26 ~4 ~6 torch 5 
setblock ~26 ~4 ~34 torch 5  
fill ~27 ~4 ~6 ~28 ~4 ~6 obsidian 0  
fill ~27 ~4 ~7 ~28 ~4 ~7 obsidian 0  
fill ~27 ~4 ~12 ~28 ~4 ~12 obsidian 0  
fill ~27 ~4 ~13 ~28 ~4 ~13 obsidian 0  
fill ~27 ~4 ~27 ~28 ~4 ~27 obsidian 0  
fill ~27 ~4 ~28 ~28 ~4 ~28 obsidian 0  
fill ~27 ~4 ~33 ~28 ~4 ~33 obsidian 0  
fill ~27 ~4 ~34 ~28 ~4 ~34 obsidian 0  
fill ~30 ~4 ~4 ~32 ~4 ~4 cobblestone 0  
fill ~30 ~4 ~36 ~32 ~4 ~36 cobblestone 0 
setblock ~31 ~4 ~6 stone_slab 3 
setblock ~31 ~4 ~34 stone_slab 3  
fill ~34 ~4 ~4 ~41 ~4 ~4 cobblestone 0  
fill ~34 ~4 ~6 ~35 ~4 ~6 obsidian 0  
fill ~34 ~4 ~7 ~35 ~4 ~7 obsidian 0  
fill ~34 ~4 ~12 ~35 ~4 ~12 obsidian 0  
fill ~34 ~4 ~13 ~35 ~4 ~13 obsidian 0  
fill ~34 ~4 ~27 ~35 ~4 ~27 obsidian 0  
fill ~34 ~4 ~28 ~35 ~4 ~28 obsidian 0  
fill ~34 ~4 ~33 ~35 ~4 ~33 obsidian 0  
fill ~34 ~4 ~34 ~35 ~4 ~34 obsidian 0  
fill ~34 ~4 ~36 ~41 ~4 ~36 cobblestone 0 
setblock ~36 ~4 ~6 torch 5 
setblock ~36 ~4 ~34 torch 5  
fill ~37 ~4 ~3 ~38 ~4 ~3 cobblestone 0  
fill ~37 ~4 ~37 ~38 ~4 ~37 cobblestone 0 
setblock ~39 ~4 ~6 torch 5 
setblock ~39 ~4 ~34 torch 5  
fill ~40 ~4 ~6 ~41 ~4 ~6 obsidian 0  
fill ~40 ~4 ~7 ~41 ~4 ~7 obsidian 0  
fill ~40 ~4 ~12 ~41 ~4 ~12 obsidian 0  
fill ~40 ~4 ~13 ~41 ~4 ~13 obsidian 0  
fill ~40 ~4 ~27 ~41 ~4 ~27 obsidian 0  
fill ~40 ~4 ~28 ~41 ~4 ~28 obsidian 0  
fill ~40 ~4 ~33 ~41 ~4 ~33 obsidian 0  
fill ~40 ~4 ~34 ~41 ~4 ~34 obsidian 0  
fill ~43 ~4 ~4 ~45 ~4 ~4 cobblestone 0  
fill ~43 ~4 ~36 ~45 ~4 ~36 cobblestone 0 
setblock ~44 ~4 ~6 stone_slab 3 
setblock ~44 ~4 ~34 stone_slab 3  
fill ~47 ~4 ~4 ~54 ~4 ~4 cobblestone 0  
fill ~47 ~4 ~6 ~48 ~4 ~6 obsidian 0  
fill ~47 ~4 ~7 ~48 ~4 ~7 obsidian 0  
fill ~47 ~4 ~12 ~48 ~4 ~12 obsidian 0  
fill ~47 ~4 ~13 ~48 ~4 ~13 obsidian 0  
fill ~47 ~4 ~27 ~48 ~4 ~27 obsidian 0  
fill ~47 ~4 ~28 ~48 ~4 ~28 obsidian 0  
fill ~47 ~4 ~33 ~48 ~4 ~33 obsidian 0  
fill ~47 ~4 ~34 ~48 ~4 ~34 obsidian 0  
fill ~47 ~4 ~36 ~54 ~4 ~36 cobblestone 0 
setblock ~48 ~4 ~15 torch 5 
setblock ~48 ~4 ~25 torch 5  
fill ~49 ~4 ~12 ~50 ~4 ~12 cobblestone 0  
fill ~49 ~4 ~28 ~50 ~4 ~28 cobblestone 0  
fill ~50 ~4 ~3 ~51 ~4 ~3 cobblestone 0 
setblock ~50 ~4 ~14 torch 1  
fill ~50 ~4 ~37 ~51 ~4 ~37 cobblestone 0  
fill ~52 ~4 ~12 ~53 ~4 ~12 cobblestone 0 
setblock ~52 ~4 ~14 torch 2  
fill ~52 ~4 ~28 ~53 ~4 ~28 cobblestone 0  
fill ~53 ~4 ~7 ~54 ~4 ~7 torch 4  
fill ~53 ~4 ~8 ~54 ~4 ~8 cobblestone 0  
fill ~53 ~4 ~24 ~54 ~4 ~24 cobblestone 0  
fill ~53 ~4 ~25 ~54 ~4 ~25 cobblestone 0  
fill ~53 ~4 ~26 ~54 ~4 ~26 cobblestone 0  
fill ~53 ~4 ~29 ~54 ~4 ~29 cobblestone 0  
fill ~53 ~4 ~32 ~54 ~4 ~32 cobblestone 0  
fill ~53 ~4 ~33 ~54 ~4 ~33 torch 3  
fill ~56 ~4 ~4 ~58 ~4 ~4 cobblestone 0  
fill ~56 ~4 ~36 ~58 ~4 ~36 cobblestone 0 
setblock ~57 ~4 ~15 torch 2 
setblock ~57 ~4 ~25 torch 2  
fill ~58 ~4 ~1 ~58 ~4 ~3 stone_brick_stairs 0 
setblock ~58 ~4 ~16 torch 3 
setblock ~58 ~4 ~24 torch 4  
fill ~59 ~4 ~13 ~61 ~4 ~13 stone_stairs 2  
fill ~59 ~4 ~18 ~60 ~4 ~18 cobblestone 0  
fill ~59 ~4 ~22 ~60 ~4 ~22 cobblestone 0  
fill ~59 ~4 ~27 ~61 ~4 ~27 stone_stairs 3 
setblock ~60 ~4 ~2 stonebrick 0 
setblock ~60 ~4 ~3 stone_brick_stairs 1  
fill ~60 ~4 ~4 ~64 ~4 ~4 cobblestone 0  
fill ~60 ~4 ~36 ~64 ~4 ~36 cobblestone 0 
setblock ~61 ~4 ~1 stone_brick_stairs 1  
fill ~62 ~4 ~6 ~63 ~4 ~6 cobblestone 0  
fill ~62 ~4 ~9 ~63 ~4 ~9 cobblestone 0  
fill ~62 ~4 ~11 ~63 ~4 ~11 cobblestone 0  
fill ~63 ~4 ~3 ~64 ~4 ~3 cobblestone 0 
setblock ~63 ~4 ~30 cobblestone 0  
fill ~63 ~4 ~37 ~64 ~4 ~37 cobblestone 0  
fill ~64 ~4 ~5 ~65 ~4 ~5 cobblestone 0  
fill ~64 ~4 ~35 ~65 ~4 ~35 cobblestone 0  
fill ~1 ~5 ~20 ~2 ~5 ~20 cobblestone 0  
fill ~2 ~5 ~25 ~3 ~5 ~25 cobblestone 0 
setblock ~3 ~5 ~20 torch 1  
fill ~7 ~5 ~11 ~8 ~5 ~11 cobblestone 0 
setblock ~7 ~5 ~12 torch 3 
setblock ~7 ~5 ~28 torch 4  
fill ~7 ~5 ~29 ~8 ~5 ~29 cobblestone 0 
setblock ~8 ~5 ~16 obsidian 0 
setblock ~8 ~5 ~24 obsidian 0  
fill ~9 ~5 ~10 ~11 ~5 ~10 cobblestone 0  
fill ~9 ~5 ~30 ~11 ~5 ~30 cobblestone 0  
fill ~10 ~5 ~5 ~12 ~5 ~5 cobblestone 0  
fill ~10 ~5 ~35 ~12 ~5 ~35 cobblestone 0  
fill ~11 ~5 ~3 ~12 ~5 ~3 cobblestone 0  
fill ~11 ~5 ~4 ~15 ~5 ~4 cobblestone 0  
fill ~11 ~5 ~36 ~15 ~5 ~36 cobblestone 0  
fill ~11 ~5 ~37 ~12 ~5 ~37 cobblestone 0 
setblock ~12 ~5 ~13 obsidian 0 
setblock ~12 ~5 ~27 obsidian 0  
fill ~13 ~5 ~7 ~14 ~5 ~7 cobblestone 0  
fill ~13 ~5 ~32 ~14 ~5 ~32 cobblestone 0 
setblock ~14 ~5 ~9 stone_stairs 7 
setblock ~14 ~5 ~10 stone_stairs 6  
fill ~14 ~5 ~12 ~15 ~5 ~12 obsidian 0  
fill ~14 ~5 ~13 ~15 ~5 ~13 obsidian 0 
setblock ~14 ~5 ~19 stone_slab 3  
fill ~14 ~5 ~20 ~14 ~7 ~20 snow 0 
setblock ~14 ~5 ~21 stone_slab 3  
fill ~14 ~5 ~27 ~15 ~5 ~27 obsidian 0  
fill ~14 ~5 ~28 ~15 ~5 ~28 obsidian 0 
setblock ~14 ~5 ~30 stone_stairs 7 
setblock ~14 ~5 ~31 stone_stairs 6  
fill ~14 ~5 ~33 ~15 ~5 ~33 obsidian 0  
fill ~14 ~5 ~34 ~15 ~5 ~34 obsidian 0 
setblock ~15 ~5 ~19 stone_stairs 2 
setblock ~15 ~5 ~20 stone_slab 3 
setblock ~15 ~5 ~21 stone_stairs 3  
fill ~17 ~5 ~4 ~17 ~17 ~4 cobblestone 0  
fill ~17 ~5 ~36 ~17 ~17 ~36 cobblestone 0  
fill ~18 ~5 ~4 ~18 ~8 ~4 glass_pane 0  
fill ~18 ~5 ~36 ~18 ~8 ~36 glass_pane 0  
fill ~19 ~5 ~4 ~19 ~17 ~4 cobblestone 0  
fill ~19 ~5 ~36 ~19 ~17 ~36 cobblestone 0  
fill ~21 ~5 ~4 ~28 ~5 ~4 cobblestone 0  
fill ~21 ~5 ~6 ~22 ~5 ~6 obsidian 0  
fill ~21 ~5 ~7 ~22 ~5 ~7 obsidian 0  
fill ~21 ~5 ~12 ~22 ~5 ~12 obsidian 0  
fill ~21 ~5 ~13 ~22 ~5 ~13 obsidian 0  
fill ~21 ~5 ~27 ~22 ~5 ~27 obsidian 0  
fill ~21 ~5 ~28 ~22 ~5 ~28 obsidian 0  
fill ~21 ~5 ~33 ~22 ~5 ~33 obsidian 0  
fill ~21 ~5 ~34 ~22 ~5 ~34 obsidian 0  
fill ~21 ~5 ~36 ~28 ~5 ~36 cobblestone 0  
fill ~24 ~5 ~3 ~25 ~5 ~3 cobblestone 0  
fill ~24 ~5 ~37 ~25 ~5 ~37 cobblestone 0  
fill ~27 ~5 ~6 ~28 ~5 ~6 obsidian 0  
fill ~27 ~5 ~7 ~28 ~5 ~7 obsidian 0  
fill ~27 ~5 ~12 ~28 ~5 ~12 obsidian 0  
fill ~27 ~5 ~13 ~28 ~5 ~13 obsidian 0  
fill ~27 ~5 ~27 ~28 ~5 ~27 obsidian 0  
fill ~27 ~5 ~28 ~28 ~5 ~28 obsidian 0  
fill ~27 ~5 ~33 ~28 ~5 ~33 obsidian 0  
fill ~27 ~5 ~34 ~28 ~5 ~34 obsidian 0  
fill ~30 ~5 ~4 ~30 ~17 ~4 cobblestone 0  
fill ~30 ~5 ~36 ~30 ~17 ~36 cobblestone 0  
fill ~31 ~5 ~4 ~31 ~8 ~4 glass_pane 0  
fill ~31 ~5 ~36 ~31 ~8 ~36 glass_pane 0  
fill ~32 ~5 ~4 ~32 ~17 ~4 cobblestone 0  
fill ~32 ~5 ~36 ~32 ~17 ~36 cobblestone 0  
fill ~34 ~5 ~4 ~41 ~5 ~4 cobblestone 0  
fill ~34 ~5 ~6 ~35 ~5 ~6 obsidian 0  
fill ~34 ~5 ~7 ~35 ~5 ~7 obsidian 0  
fill ~34 ~5 ~12 ~35 ~5 ~12 obsidian 0  
fill ~34 ~5 ~13 ~35 ~5 ~13 obsidian 0  
fill ~34 ~5 ~27 ~35 ~5 ~27 obsidian 0  
fill ~34 ~5 ~28 ~35 ~5 ~28 obsidian 0  
fill ~34 ~5 ~33 ~35 ~5 ~33 obsidian 0  
fill ~34 ~5 ~34 ~35 ~5 ~34 obsidian 0  
fill ~34 ~5 ~36 ~41 ~5 ~36 cobblestone 0  
fill ~37 ~5 ~3 ~38 ~5 ~3 cobblestone 0  
fill ~37 ~5 ~37 ~38 ~5 ~37 cobblestone 0  
fill ~40 ~5 ~6 ~41 ~5 ~6 obsidian 0  
fill ~40 ~5 ~7 ~41 ~5 ~7 obsidian 0  
fill ~40 ~5 ~12 ~41 ~5 ~12 obsidian 0  
fill ~40 ~5 ~13 ~41 ~5 ~13 obsidian 0  
fill ~40 ~5 ~27 ~41 ~5 ~27 obsidian 0  
fill ~40 ~5 ~28 ~41 ~5 ~28 obsidian 0  
fill ~40 ~5 ~33 ~41 ~5 ~33 obsidian 0  
fill ~40 ~5 ~34 ~41 ~5 ~34 obsidian 0  
fill ~43 ~5 ~4 ~43 ~17 ~4 cobblestone 0  
fill ~43 ~5 ~36 ~43 ~17 ~36 cobblestone 0  
fill ~44 ~5 ~4 ~44 ~8 ~4 glass_pane 0  
fill ~44 ~5 ~36 ~44 ~8 ~36 glass_pane 0  
fill ~45 ~5 ~4 ~45 ~17 ~4 cobblestone 0  
fill ~45 ~5 ~36 ~45 ~17 ~36 cobblestone 0  
fill ~47 ~5 ~4 ~54 ~5 ~4 cobblestone 0  
fill ~47 ~5 ~6 ~48 ~5 ~6 obsidian 0  
fill ~47 ~5 ~7 ~48 ~5 ~7 obsidian 0  
fill ~47 ~5 ~12 ~48 ~5 ~12 obsidian 0  
fill ~47 ~5 ~13 ~48 ~5 ~13 obsidian 0  
fill ~47 ~5 ~27 ~48 ~5 ~27 obsidian 0  
fill ~47 ~5 ~28 ~48 ~5 ~28 obsidian 0  
fill ~47 ~5 ~33 ~48 ~5 ~33 obsidian 0  
fill ~47 ~5 ~34 ~48 ~5 ~34 obsidian 0  
fill ~47 ~5 ~36 ~54 ~5 ~36 cobblestone 0 
setblock ~49 ~5 ~9 stone_stairs 7 
setblock ~49 ~5 ~10 stone_stairs 6  
fill ~49 ~5 ~12 ~50 ~5 ~12 cobblestone 0 
setblock ~49 ~5 ~17 cobblestone 0 
setblock ~49 ~5 ~23 cobblestone 0  
fill ~49 ~5 ~28 ~50 ~5 ~28 cobblestone 0 
setblock ~49 ~5 ~30 stone_stairs 7 
setblock ~49 ~5 ~31 stone_stairs 6  
fill ~50 ~5 ~3 ~51 ~5 ~3 cobblestone 0  
fill ~50 ~5 ~37 ~51 ~5 ~37 cobblestone 0 
setblock ~51 ~5 ~12 obsidian 0  
fill ~51 ~5 ~17 ~51 ~7 ~17 cobblestone 0  
fill ~51 ~5 ~23 ~51 ~8 ~23 cobblestone 0 
setblock ~51 ~5 ~28 obsidian 0  
fill ~52 ~5 ~12 ~53 ~5 ~12 cobblestone 0  
fill ~52 ~5 ~28 ~53 ~5 ~28 cobblestone 0  
fill ~53 ~5 ~8 ~54 ~5 ~8 cobblestone 0  
fill ~53 ~5 ~17 ~53 ~6 ~17 cobblestone 0  
fill ~53 ~5 ~23 ~53 ~8 ~23 cobblestone 0  
fill ~53 ~5 ~24 ~54 ~5 ~24 cobblestone 0  
fill ~53 ~5 ~25 ~54 ~5 ~25 cobblestone 0  
fill ~53 ~5 ~26 ~54 ~5 ~26 cobblestone 0  
fill ~53 ~5 ~29 ~54 ~5 ~29 cobblestone 0  
fill ~53 ~5 ~32 ~54 ~5 ~32 cobblestone 0  
fill ~56 ~5 ~4 ~58 ~5 ~4 cobblestone 0  
fill ~56 ~5 ~36 ~58 ~5 ~36 cobblestone 0  
fill ~59 ~5 ~1 ~60 ~5 ~1 stone_slab 5  
fill ~59 ~5 ~2 ~59 ~5 ~1 stone_slab 5  
fill ~59 ~5 ~3 ~59 ~17 ~3 cobblestone 0  
fill ~59 ~5 ~14 ~61 ~5 ~14 stone_stairs 2  
fill ~59 ~5 ~18 ~60 ~5 ~18 cobblestone 0  
fill ~59 ~5 ~22 ~60 ~5 ~22 cobblestone 0  
fill ~59 ~5 ~26 ~61 ~5 ~26 stone_stairs 3  
fill ~60 ~5 ~4 ~64 ~5 ~4 cobblestone 0  
fill ~60 ~5 ~36 ~64 ~5 ~36 cobblestone 0 
setblock ~61 ~5 ~18 torch 1  
fill ~62 ~5 ~6 ~63 ~5 ~6 cobblestone 0  
fill ~62 ~5 ~9 ~63 ~5 ~9 cobblestone 0  
fill ~62 ~5 ~11 ~63 ~5 ~11 cobblestone 0  
fill ~62 ~5 ~14 ~62 ~6 ~14 cobblestone 0 
setblock ~62 ~5 ~23 torch 1  
fill ~62 ~5 ~26 ~62 ~6 ~26 cobblestone 0  
fill ~63 ~5 ~3 ~64 ~5 ~3 cobblestone 0  
fill ~63 ~5 ~37 ~64 ~5 ~37 cobblestone 0  
fill ~64 ~5 ~5 ~65 ~5 ~5 cobblestone 0  
fill ~64 ~5 ~35 ~65 ~5 ~35 cobblestone 0  
fill ~1 ~6 ~20 ~2 ~6 ~20 cobblestone 0  
fill ~2 ~6 ~25 ~3 ~6 ~25 cobblestone 0  
fill ~3 ~6 ~17 ~7 ~6 ~17 iron_block 0  
fill ~3 ~6 ~18 ~7 ~6 ~18 iron_block 0  
fill ~3 ~6 ~19 ~6 ~6 ~19 iron_block 0  
fill ~3 ~6 ~20 ~6 ~6 ~20 iron_block 0  
fill ~3 ~6 ~21 ~6 ~6 ~21 iron_block 0  
fill ~3 ~6 ~22 ~7 ~6 ~22 iron_block 0  
fill ~3 ~6 ~23 ~7 ~6 ~23 iron_block 0  
fill ~4 ~6 ~15 ~7 ~6 ~15 iron_block 0  
fill ~4 ~6 ~16 ~7 ~6 ~16 iron_block 0  
fill ~4 ~6 ~24 ~7 ~6 ~24 iron_block 0  
fill ~4 ~6 ~25 ~7 ~6 ~25 iron_block 0  
fill ~5 ~6 ~14 ~7 ~6 ~14 iron_block 0  
fill ~5 ~6 ~26 ~7 ~6 ~26 iron_block 0  
fill ~6 ~6 ~13 ~7 ~6 ~13 iron_block 0  
fill ~6 ~6 ~27 ~7 ~6 ~27 iron_block 0  
fill ~7 ~6 ~11 ~8 ~6 ~11 cobblestone 0 
setblock ~7 ~6 ~12 iron_block 0 
setblock ~7 ~6 ~28 iron_block 0  
fill ~7 ~6 ~29 ~8 ~6 ~29 cobblestone 0  
fill ~8 ~6 ~16 ~8 ~7 ~16 cobblestone 0  
fill ~8 ~6 ~24 ~8 ~7 ~24 cobblestone 0  
fill ~9 ~6 ~10 ~11 ~6 ~10 cobblestone 0  
fill ~9 ~6 ~30 ~11 ~6 ~30 cobblestone 0  
fill ~10 ~6 ~5 ~12 ~6 ~5 cobblestone 0  
fill ~10 ~6 ~35 ~12 ~6 ~35 cobblestone 0  
fill ~11 ~6 ~3 ~12 ~6 ~3 cobblestone 0  
fill ~11 ~6 ~4 ~15 ~6 ~4 cobblestone 0  
fill ~11 ~6 ~36 ~15 ~6 ~36 cobblestone 0  
fill ~11 ~6 ~37 ~12 ~6 ~37 cobblestone 0  
fill ~12 ~6 ~13 ~12 ~15 ~13 cobblestone 0  
fill ~12 ~6 ~27 ~12 ~15 ~27 cobblestone 0  
fill ~13 ~6 ~7 ~14 ~6 ~7 cobblestone 0  
fill ~13 ~6 ~32 ~14 ~6 ~32 cobblestone 0  
fill ~14 ~6 ~9 ~14 ~6 ~10 obsidian 0  
fill ~14 ~6 ~12 ~15 ~6 ~12 obsidian 0  
fill ~14 ~6 ~13 ~15 ~6 ~13 obsidian 0  
fill ~14 ~6 ~27 ~15 ~6 ~27 obsidian 0  
fill ~14 ~6 ~28 ~15 ~6 ~28 obsidian 0  
fill ~14 ~6 ~30 ~14 ~6 ~31 obsidian 0  
fill ~14 ~6 ~33 ~15 ~6 ~33 obsidian 0  
fill ~14 ~6 ~34 ~15 ~6 ~34 obsidian 0  
fill ~21 ~6 ~4 ~28 ~6 ~4 cobblestone 0  
fill ~21 ~6 ~6 ~22 ~6 ~6 obsidian 0  
fill ~21 ~6 ~7 ~22 ~6 ~7 obsidian 0  
fill ~21 ~6 ~12 ~22 ~6 ~12 obsidian 0  
fill ~21 ~6 ~13 ~22 ~6 ~13 obsidian 0  
fill ~21 ~6 ~27 ~22 ~6 ~27 obsidian 0  
fill ~21 ~6 ~28 ~22 ~6 ~28 obsidian 0  
fill ~21 ~6 ~33 ~22 ~6 ~33 obsidian 0  
fill ~21 ~6 ~34 ~22 ~6 ~34 obsidian 0  
fill ~21 ~6 ~36 ~28 ~6 ~36 cobblestone 0  
fill ~24 ~6 ~3 ~25 ~6 ~3 cobblestone 0  
fill ~24 ~6 ~37 ~25 ~6 ~37 cobblestone 0  
fill ~27 ~6 ~6 ~28 ~6 ~6 obsidian 0  
fill ~27 ~6 ~7 ~28 ~6 ~7 obsidian 0  
fill ~27 ~6 ~12 ~28 ~6 ~12 obsidian 0  
fill ~27 ~6 ~13 ~28 ~6 ~13 obsidian 0  
fill ~27 ~6 ~27 ~28 ~6 ~27 obsidian 0  
fill ~27 ~6 ~28 ~28 ~6 ~28 obsidian 0  
fill ~27 ~6 ~33 ~28 ~6 ~33 obsidian 0  
fill ~27 ~6 ~34 ~28 ~6 ~34 obsidian 0  
fill ~34 ~6 ~4 ~41 ~6 ~4 cobblestone 0  
fill ~34 ~6 ~6 ~35 ~6 ~6 obsidian 0  
fill ~34 ~6 ~7 ~35 ~6 ~7 obsidian 0  
fill ~34 ~6 ~12 ~35 ~6 ~12 obsidian 0  
fill ~34 ~6 ~13 ~35 ~6 ~13 obsidian 0  
fill ~34 ~6 ~27 ~35 ~6 ~27 obsidian 0  
fill ~34 ~6 ~28 ~35 ~6 ~28 obsidian 0  
fill ~34 ~6 ~33 ~35 ~6 ~33 obsidian 0  
fill ~34 ~6 ~34 ~35 ~6 ~34 obsidian 0  
fill ~34 ~6 ~36 ~41 ~6 ~36 cobblestone 0  
fill ~37 ~6 ~3 ~38 ~6 ~3 cobblestone 0  
fill ~37 ~6 ~37 ~38 ~6 ~37 cobblestone 0  
fill ~40 ~6 ~6 ~41 ~6 ~6 obsidian 0  
fill ~40 ~6 ~7 ~41 ~6 ~7 obsidian 0  
fill ~40 ~6 ~12 ~41 ~6 ~12 obsidian 0  
fill ~40 ~6 ~13 ~41 ~6 ~13 obsidian 0  
fill ~40 ~6 ~27 ~41 ~6 ~27 obsidian 0  
fill ~40 ~6 ~28 ~41 ~6 ~28 obsidian 0  
fill ~40 ~6 ~33 ~41 ~6 ~33 obsidian 0  
fill ~40 ~6 ~34 ~41 ~6 ~34 obsidian 0  
fill ~47 ~6 ~4 ~54 ~6 ~4 cobblestone 0  
fill ~47 ~6 ~6 ~48 ~6 ~6 obsidian 0  
fill ~47 ~6 ~7 ~48 ~6 ~7 obsidian 0  
fill ~47 ~6 ~12 ~48 ~6 ~12 obsidian 0  
fill ~47 ~6 ~13 ~48 ~6 ~13 obsidian 0  
fill ~47 ~6 ~27 ~48 ~6 ~27 obsidian 0  
fill ~47 ~6 ~28 ~48 ~6 ~28 obsidian 0  
fill ~47 ~6 ~33 ~48 ~6 ~33 obsidian 0  
fill ~47 ~6 ~34 ~48 ~6 ~34 obsidian 0  
fill ~47 ~6 ~36 ~54 ~6 ~36 cobblestone 0  
fill ~49 ~6 ~9 ~49 ~6 ~10 obsidian 0  
fill ~49 ~6 ~12 ~53 ~6 ~12 cobblestone 0 
setblock ~49 ~6 ~17 obsidian 0  
fill ~49 ~6 ~18 ~54 ~6 ~18 stone_stairs 7  
fill ~49 ~6 ~22 ~54 ~6 ~22 stone_stairs 6 
setblock ~49 ~6 ~23 obsidian 0  
fill ~49 ~6 ~28 ~53 ~6 ~28 cobblestone 0  
fill ~49 ~6 ~30 ~49 ~6 ~31 obsidian 0  
fill ~50 ~6 ~3 ~51 ~6 ~3 cobblestone 0  
fill ~50 ~6 ~37 ~51 ~6 ~37 cobblestone 0 
setblock ~51 ~6 ~27 torch 4  
fill ~53 ~6 ~5 ~54 ~6 ~5 stone_stairs 7  
fill ~53 ~6 ~7 ~54 ~6 ~7 stone_stairs 6  
fill ~53 ~6 ~8 ~54 ~6 ~8 cobblestone 0 
setblock ~53 ~6 ~9 stone_stairs 7 
setblock ~53 ~6 ~10 stone_stairs 6  
fill ~53 ~6 ~24 ~54 ~6 ~24 cobblestone 0  
fill ~53 ~6 ~25 ~54 ~6 ~25 cobblestone 0  
fill ~53 ~6 ~26 ~54 ~6 ~26 cobblestone 0  
fill ~53 ~6 ~29 ~54 ~6 ~29 cobblestone 0 
setblock ~53 ~6 ~30 stone_stairs 7 
setblock ~53 ~6 ~31 stone_stairs 6  
fill ~53 ~6 ~32 ~54 ~6 ~32 cobblestone 0  
fill ~53 ~6 ~33 ~54 ~6 ~33 stone_stairs 7  
fill ~53 ~6 ~35 ~54 ~6 ~35 stone_stairs 6 
setblock ~54 ~6 ~12 stone_stairs 7 
setblock ~54 ~6 ~13 stone_stairs 6 
setblock ~54 ~6 ~27 stone_stairs 7 
setblock ~54 ~6 ~28 stone_stairs 6  
fill ~56 ~6 ~4 ~58 ~6 ~4 cobblestone 0  
fill ~56 ~6 ~36 ~58 ~6 ~36 cobblestone 0  
fill ~59 ~6 ~15 ~61 ~6 ~15 stone_stairs 2  
fill ~59 ~6 ~18 ~60 ~6 ~18 cobblestone 0  
fill ~59 ~6 ~19 ~60 ~6 ~19 stone_stairs 7  
fill ~59 ~6 ~21 ~60 ~6 ~21 stone_stairs 6  
fill ~59 ~6 ~22 ~60 ~6 ~22 cobblestone 0  
fill ~59 ~6 ~25 ~61 ~6 ~25 stone_stairs 3  
fill ~60 ~6 ~4 ~64 ~6 ~4 cobblestone 0  
fill ~60 ~6 ~36 ~64 ~6 ~36 cobblestone 0 
setblock ~61 ~6 ~18 stone_stairs 7 
setblock ~61 ~6 ~22 stone_stairs 6  
fill ~62 ~6 ~6 ~63 ~6 ~6 cobblestone 0  
fill ~62 ~6 ~9 ~63 ~6 ~9 cobblestone 0  
fill ~62 ~6 ~11 ~63 ~6 ~11 cobblestone 0 
setblock ~62 ~6 ~15 cobblestone 0 
setblock ~62 ~6 ~17 stone_stairs 7 
setblock ~62 ~6 ~23 stone_stairs 6 
setblock ~62 ~6 ~25 cobblestone 0  
fill ~63 ~6 ~3 ~64 ~6 ~3 cobblestone 0 
setblock ~63 ~6 ~16 stone_stairs 7 
setblock ~63 ~6 ~24 stone_stairs 6  
fill ~63 ~6 ~37 ~64 ~6 ~37 cobblestone 0  
fill ~64 ~6 ~5 ~65 ~6 ~5 cobblestone 0  
fill ~64 ~6 ~35 ~65 ~6 ~35 cobblestone 0  
fill ~1 ~7 ~20 ~2 ~7 ~20 cobblestone 0  
fill ~2 ~7 ~25 ~3 ~7 ~25 cobblestone 0  
fill ~7 ~7 ~11 ~8 ~7 ~11 cobblestone 0  
fill ~7 ~7 ~29 ~8 ~7 ~29 cobblestone 0  
fill ~8 ~7 ~12 ~8 ~7 ~15 stone_stairs 0  
fill ~8 ~7 ~25 ~8 ~7 ~28 stone_stairs 0  
fill ~9 ~7 ~10 ~11 ~7 ~10 cobblestone 0  
fill ~9 ~7 ~30 ~11 ~7 ~30 cobblestone 0  
fill ~10 ~7 ~5 ~12 ~7 ~5 cobblestone 0  
fill ~10 ~7 ~35 ~12 ~7 ~35 cobblestone 0  
fill ~11 ~7 ~3 ~12 ~7 ~3 cobblestone 0  
fill ~11 ~7 ~4 ~15 ~7 ~4 cobblestone 0  
fill ~11 ~7 ~36 ~15 ~7 ~36 cobblestone 0  
fill ~11 ~7 ~37 ~12 ~7 ~37 cobblestone 0  
fill ~13 ~7 ~7 ~14 ~7 ~7 cobblestone 0  
fill ~13 ~7 ~32 ~14 ~7 ~32 cobblestone 0  
fill ~14 ~7 ~9 ~14 ~12 ~9 cobblestone 0  
fill ~14 ~7 ~10 ~14 ~12 ~10 cobblestone 0  
fill ~14 ~7 ~12 ~15 ~7 ~12 obsidian 0  
fill ~14 ~7 ~13 ~15 ~7 ~13 obsidian 0  
fill ~14 ~7 ~27 ~15 ~7 ~27 obsidian 0  
fill ~14 ~7 ~28 ~15 ~7 ~28 obsidian 0  
fill ~14 ~7 ~30 ~14 ~11 ~30 cobblestone 0  
fill ~14 ~7 ~31 ~14 ~11 ~31 cobblestone 0  
fill ~14 ~7 ~33 ~15 ~7 ~33 obsidian 0  
fill ~14 ~7 ~34 ~15 ~7 ~34 obsidian 0  
fill ~21 ~7 ~4 ~28 ~7 ~4 cobblestone 0  
fill ~21 ~7 ~6 ~22 ~7 ~6 obsidian 0  
fill ~21 ~7 ~7 ~22 ~7 ~7 obsidian 0  
fill ~21 ~7 ~12 ~22 ~7 ~12 obsidian 0  
fill ~21 ~7 ~13 ~22 ~7 ~13 obsidian 0  
fill ~21 ~7 ~27 ~22 ~7 ~27 obsidian 0  
fill ~21 ~7 ~28 ~22 ~7 ~28 obsidian 0  
fill ~21 ~7 ~33 ~22 ~7 ~33 obsidian 0  
fill ~21 ~7 ~34 ~22 ~7 ~34 obsidian 0  
fill ~21 ~7 ~36 ~28 ~7 ~36 cobblestone 0  
fill ~24 ~7 ~3 ~25 ~7 ~3 cobblestone 0  
fill ~24 ~7 ~37 ~25 ~7 ~37 cobblestone 0  
fill ~27 ~7 ~6 ~28 ~7 ~6 obsidian 0  
fill ~27 ~7 ~7 ~28 ~7 ~7 obsidian 0  
fill ~27 ~7 ~12 ~28 ~7 ~12 obsidian 0  
fill ~27 ~7 ~13 ~28 ~7 ~13 obsidian 0  
fill ~27 ~7 ~27 ~28 ~7 ~27 obsidian 0  
fill ~27 ~7 ~28 ~28 ~7 ~28 obsidian 0  
fill ~27 ~7 ~33 ~28 ~7 ~33 obsidian 0  
fill ~27 ~7 ~34 ~28 ~7 ~34 obsidian 0  
fill ~34 ~7 ~4 ~41 ~7 ~4 cobblestone 0  
fill ~34 ~7 ~6 ~35 ~7 ~6 obsidian 0  
fill ~34 ~7 ~7 ~35 ~7 ~7 obsidian 0  
fill ~34 ~7 ~12 ~35 ~7 ~12 obsidian 0  
fill ~34 ~7 ~13 ~35 ~7 ~13 obsidian 0  
fill ~34 ~7 ~27 ~35 ~7 ~27 obsidian 0  
fill ~34 ~7 ~28 ~35 ~7 ~28 obsidian 0  
fill ~34 ~7 ~33 ~35 ~7 ~33 obsidian 0  
fill ~34 ~7 ~34 ~35 ~7 ~34 obsidian 0  
fill ~34 ~7 ~36 ~41 ~7 ~36 cobblestone 0  
fill ~37 ~7 ~3 ~38 ~7 ~3 cobblestone 0  
fill ~37 ~7 ~37 ~38 ~7 ~37 cobblestone 0  
fill ~40 ~7 ~6 ~41 ~7 ~6 obsidian 0  
fill ~40 ~7 ~7 ~41 ~7 ~7 obsidian 0  
fill ~40 ~7 ~12 ~41 ~7 ~12 obsidian 0  
fill ~40 ~7 ~13 ~41 ~7 ~13 obsidian 0  
fill ~40 ~7 ~27 ~41 ~7 ~27 obsidian 0  
fill ~40 ~7 ~28 ~41 ~7 ~28 obsidian 0  
fill ~40 ~7 ~33 ~41 ~7 ~33 obsidian 0  
fill ~40 ~7 ~34 ~41 ~7 ~34 obsidian 0  
fill ~47 ~7 ~4 ~54 ~7 ~4 cobblestone 0  
fill ~47 ~7 ~6 ~48 ~7 ~6 obsidian 0  
fill ~47 ~7 ~7 ~48 ~7 ~7 obsidian 0  
fill ~47 ~7 ~12 ~48 ~7 ~12 obsidian 0  
fill ~47 ~7 ~13 ~48 ~7 ~13 obsidian 0  
fill ~47 ~7 ~27 ~48 ~7 ~27 obsidian 0  
fill ~47 ~7 ~28 ~48 ~7 ~28 obsidian 0  
fill ~47 ~7 ~33 ~48 ~7 ~33 obsidian 0  
fill ~47 ~7 ~34 ~48 ~7 ~34 obsidian 0  
fill ~47 ~7 ~36 ~54 ~7 ~36 cobblestone 0  
fill ~49 ~7 ~9 ~49 ~13 ~9 cobblestone 0  
fill ~49 ~7 ~10 ~49 ~13 ~10 cobblestone 0  
fill ~49 ~7 ~12 ~52 ~7 ~12 cobblestone 0  
fill ~49 ~7 ~17 ~49 ~9 ~17 cobblestone 0 
setblock ~49 ~7 ~18 obsidian 0  
fill ~49 ~7 ~19 ~54 ~7 ~19 stone_stairs 7  
fill ~49 ~7 ~20 ~54 ~7 ~20 stone_slab 11  
fill ~49 ~7 ~21 ~54 ~7 ~21 stone_stairs 6 
setblock ~49 ~7 ~22 obsidian 0  
fill ~49 ~7 ~23 ~49 ~9 ~23 cobblestone 0  
fill ~49 ~7 ~28 ~54 ~7 ~28 cobblestone 0  
fill ~49 ~7 ~30 ~49 ~13 ~30 cobblestone 0  
fill ~49 ~7 ~31 ~49 ~13 ~31 cobblestone 0  
fill ~50 ~7 ~3 ~51 ~7 ~3 cobblestone 0  
fill ~50 ~7 ~18 ~54 ~7 ~18 cobblestone 0  
fill ~50 ~7 ~22 ~54 ~7 ~22 cobblestone 0  
fill ~50 ~7 ~37 ~51 ~7 ~37 cobblestone 0  
fill ~53 ~7 ~5 ~54 ~7 ~5 cobblestone 0  
fill ~53 ~7 ~6 ~54 ~7 ~6 cobblestone 0  
fill ~53 ~7 ~7 ~54 ~7 ~7 cobblestone 0  
fill ~53 ~7 ~8 ~54 ~7 ~8 cobblestone 0  
fill ~53 ~7 ~9 ~53 ~7 ~11 cobblestone 0  
fill ~53 ~7 ~24 ~54 ~7 ~24 cobblestone 0  
fill ~53 ~7 ~25 ~54 ~7 ~25 cobblestone 0  
fill ~53 ~7 ~26 ~54 ~7 ~26 cobblestone 0  
fill ~53 ~7 ~29 ~54 ~7 ~29 cobblestone 0  
fill ~53 ~7 ~30 ~53 ~8 ~30 cobblestone 0  
fill ~53 ~7 ~31 ~53 ~8 ~31 cobblestone 0  
fill ~53 ~7 ~32 ~54 ~7 ~32 cobblestone 0  
fill ~53 ~7 ~33 ~54 ~7 ~33 cobblestone 0  
fill ~53 ~7 ~34 ~54 ~7 ~34 cobblestone 0  
fill ~53 ~7 ~35 ~54 ~7 ~35 cobblestone 0  
fill ~54 ~7 ~12 ~54 ~8 ~12 cobblestone 0  
fill ~54 ~7 ~13 ~54 ~8 ~13 cobblestone 0  
fill ~54 ~7 ~27 ~54 ~8 ~27 cobblestone 0  
fill ~56 ~7 ~4 ~58 ~7 ~4 cobblestone 0  
fill ~56 ~7 ~36 ~58 ~7 ~36 cobblestone 0 
setblock ~58 ~7 ~16 stone_stairs 7 
setblock ~58 ~7 ~24 stone_stairs 6  
fill ~59 ~7 ~16 ~61 ~7 ~16 stone_stairs 2  
fill ~59 ~7 ~18 ~61 ~7 ~18 cobblestone 0  
fill ~59 ~7 ~19 ~60 ~7 ~19 cobblestone 0  
fill ~59 ~7 ~20 ~60 ~7 ~20 cobblestone 0  
fill ~59 ~7 ~21 ~60 ~7 ~21 cobblestone 0  
fill ~59 ~7 ~22 ~61 ~7 ~22 cobblestone 0  
fill ~59 ~7 ~24 ~61 ~7 ~24 stone_stairs 3  
fill ~60 ~7 ~4 ~64 ~7 ~4 cobblestone 0  
fill ~60 ~7 ~36 ~64 ~7 ~36 cobblestone 0  
fill ~61 ~7 ~8 ~61 ~7 ~9 torch 2  
fill ~61 ~7 ~12 ~61 ~7 ~13 torch 2 
setblock ~61 ~7 ~19 stone_stairs 7 
setblock ~61 ~7 ~20 stone_slab 11 
setblock ~61 ~7 ~21 stone_stairs 6  
fill ~61 ~7 ~27 ~61 ~7 ~28 torch 2  
fill ~61 ~7 ~31 ~61 ~7 ~32 torch 2  
fill ~62 ~7 ~6 ~62 ~7 ~7 stone_slab 3  
fill ~62 ~7 ~9 ~63 ~7 ~9 cobblestone 0  
fill ~62 ~7 ~17 ~62 ~10 ~17 cobblestone 0 
setblock ~62 ~7 ~18 stone_stairs 7 
setblock ~62 ~7 ~22 stone_stairs 6  
fill ~62 ~7 ~23 ~62 ~10 ~23 cobblestone 0  
fill ~62 ~7 ~33 ~62 ~7 ~34 stone_slab 3  
fill ~63 ~7 ~3 ~64 ~7 ~3 cobblestone 0  
fill ~63 ~7 ~6 ~63 ~19 ~6 cobblestone 0 
setblock ~63 ~7 ~7 stone_stairs 7 
setblock ~63 ~7 ~8 stone_stairs 6  
fill ~63 ~7 ~10 ~63 ~19 ~10 cobblestone 0  
fill ~63 ~7 ~11 ~63 ~19 ~11 cobblestone 0 
setblock ~63 ~7 ~12 stone_stairs 7 
setblock ~63 ~7 ~13 stone_stairs 6  
fill ~63 ~7 ~16 ~63 ~8 ~16 cobblestone 0 
setblock ~63 ~7 ~17 stone_stairs 7 
setblock ~63 ~7 ~23 stone_stairs 6  
fill ~63 ~7 ~24 ~63 ~8 ~24 cobblestone 0 
setblock ~63 ~7 ~27 stone_stairs 7 
setblock ~63 ~7 ~28 stone_stairs 6  
fill ~63 ~7 ~30 ~63 ~19 ~30 cobblestone 0 
setblock ~63 ~7 ~32 stone_stairs 7 
setblock ~63 ~7 ~33 stone_stairs 6  
fill ~63 ~7 ~37 ~64 ~7 ~37 cobblestone 0  
fill ~64 ~7 ~5 ~65 ~7 ~5 cobblestone 0  
fill ~64 ~7 ~35 ~65 ~7 ~35 cobblestone 0  
fill ~1 ~8 ~20 ~2 ~8 ~20 cobblestone 0  
fill ~2 ~8 ~25 ~3 ~8 ~25 cobblestone 0  
fill ~7 ~8 ~11 ~8 ~8 ~11 cobblestone 0  
fill ~7 ~8 ~29 ~8 ~8 ~29 cobblestone 0  
fill ~8 ~8 ~16 ~8 ~11 ~16 obsidian 0  
fill ~8 ~8 ~24 ~8 ~11 ~24 obsidian 0  
fill ~9 ~8 ~10 ~11 ~8 ~10 cobblestone 0  
fill ~9 ~8 ~11 ~9 ~8 ~14 stone_stairs 0  
fill ~9 ~8 ~26 ~9 ~8 ~29 stone_stairs 0  
fill ~9 ~8 ~30 ~11 ~8 ~30 cobblestone 0  
fill ~10 ~8 ~5 ~12 ~8 ~5 cobblestone 0  
fill ~10 ~8 ~35 ~12 ~8 ~35 cobblestone 0  
fill ~11 ~8 ~3 ~12 ~8 ~3 cobblestone 0  
fill ~11 ~8 ~4 ~15 ~8 ~4 cobblestone 0  
fill ~11 ~8 ~36 ~15 ~8 ~36 cobblestone 0  
fill ~11 ~8 ~37 ~12 ~8 ~37 cobblestone 0  
fill ~13 ~8 ~7 ~14 ~8 ~7 cobblestone 0  
fill ~13 ~8 ~32 ~14 ~8 ~32 cobblestone 0  
fill ~14 ~8 ~12 ~15 ~8 ~12 obsidian 0  
fill ~14 ~8 ~13 ~15 ~8 ~13 obsidian 0  
fill ~14 ~8 ~27 ~15 ~8 ~27 obsidian 0  
fill ~14 ~8 ~28 ~15 ~8 ~28 obsidian 0  
fill ~14 ~8 ~33 ~15 ~8 ~33 obsidian 0  
fill ~14 ~8 ~34 ~15 ~8 ~34 obsidian 0  
fill ~21 ~8 ~4 ~28 ~8 ~4 cobblestone 0  
fill ~21 ~8 ~6 ~22 ~8 ~6 obsidian 0  
fill ~21 ~8 ~7 ~22 ~8 ~7 obsidian 0  
fill ~21 ~8 ~12 ~22 ~8 ~12 obsidian 0  
fill ~21 ~8 ~13 ~22 ~8 ~13 obsidian 0  
fill ~21 ~8 ~27 ~22 ~8 ~27 obsidian 0  
fill ~21 ~8 ~28 ~22 ~8 ~28 obsidian 0  
fill ~21 ~8 ~33 ~22 ~8 ~33 obsidian 0  
fill ~21 ~8 ~34 ~22 ~8 ~34 obsidian 0  
fill ~21 ~8 ~36 ~28 ~8 ~36 cobblestone 0  
fill ~24 ~8 ~3 ~25 ~8 ~3 cobblestone 0  
fill ~24 ~8 ~37 ~25 ~8 ~37 cobblestone 0  
fill ~27 ~8 ~6 ~28 ~8 ~6 obsidian 0  
fill ~27 ~8 ~7 ~28 ~8 ~7 obsidian 0  
fill ~27 ~8 ~12 ~28 ~8 ~12 obsidian 0  
fill ~27 ~8 ~13 ~28 ~8 ~13 obsidian 0  
fill ~27 ~8 ~27 ~28 ~8 ~27 obsidian 0  
fill ~27 ~8 ~28 ~28 ~8 ~28 obsidian 0  
fill ~27 ~8 ~33 ~28 ~8 ~33 obsidian 0  
fill ~27 ~8 ~34 ~28 ~8 ~34 obsidian 0  
fill ~34 ~8 ~4 ~41 ~8 ~4 cobblestone 0  
fill ~34 ~8 ~6 ~35 ~8 ~6 obsidian 0  
fill ~34 ~8 ~7 ~35 ~8 ~7 obsidian 0  
fill ~34 ~8 ~12 ~35 ~8 ~12 obsidian 0  
fill ~34 ~8 ~13 ~35 ~8 ~13 obsidian 0  
fill ~34 ~8 ~27 ~35 ~8 ~27 obsidian 0  
fill ~34 ~8 ~28 ~35 ~8 ~28 obsidian 0  
fill ~34 ~8 ~33 ~35 ~8 ~33 obsidian 0  
fill ~34 ~8 ~34 ~35 ~8 ~34 obsidian 0  
fill ~34 ~8 ~36 ~41 ~8 ~36 cobblestone 0  
fill ~37 ~8 ~3 ~38 ~8 ~3 cobblestone 0  
fill ~37 ~8 ~37 ~38 ~8 ~37 cobblestone 0  
fill ~40 ~8 ~6 ~41 ~8 ~6 obsidian 0  
fill ~40 ~8 ~7 ~41 ~8 ~7 obsidian 0  
fill ~40 ~8 ~12 ~41 ~8 ~12 obsidian 0  
fill ~40 ~8 ~13 ~41 ~8 ~13 obsidian 0  
fill ~40 ~8 ~27 ~41 ~8 ~27 obsidian 0  
fill ~40 ~8 ~28 ~41 ~8 ~28 obsidian 0  
fill ~40 ~8 ~33 ~41 ~8 ~33 obsidian 0  
fill ~40 ~8 ~34 ~41 ~8 ~34 obsidian 0  
fill ~47 ~8 ~4 ~58 ~8 ~4 cobblestone 0  
fill ~47 ~8 ~6 ~48 ~8 ~6 obsidian 0  
fill ~47 ~8 ~7 ~48 ~8 ~7 obsidian 0  
fill ~47 ~8 ~12 ~48 ~8 ~12 obsidian 0  
fill ~47 ~8 ~13 ~48 ~8 ~13 obsidian 0  
fill ~47 ~8 ~27 ~48 ~8 ~27 obsidian 0  
fill ~47 ~8 ~28 ~48 ~8 ~28 obsidian 0  
fill ~47 ~8 ~33 ~48 ~8 ~33 obsidian 0  
fill ~47 ~8 ~34 ~48 ~8 ~34 obsidian 0  
fill ~47 ~8 ~36 ~58 ~8 ~36 cobblestone 0  
fill ~49 ~8 ~12 ~49 ~20 ~12 cobblestone 0  
fill ~49 ~8 ~18 ~49 ~9 ~18 cobblestone 0  
fill ~49 ~8 ~19 ~59 ~8 ~19 cobblestone 0 
setblock ~49 ~8 ~20 obsidian 0  
fill ~49 ~8 ~21 ~58 ~8 ~21 cobblestone 0  
fill ~49 ~8 ~22 ~58 ~8 ~22 cobblestone 0  
fill ~49 ~8 ~28 ~58 ~8 ~28 cobblestone 0  
fill ~50 ~8 ~3 ~51 ~8 ~3 cobblestone 0  
fill ~50 ~8 ~5 ~58 ~8 ~5 cobblestone 0  
fill ~50 ~8 ~6 ~58 ~8 ~6 cobblestone 0  
fill ~50 ~8 ~7 ~58 ~8 ~7 cobblestone 0  
fill ~50 ~8 ~8 ~52 ~8 ~8 cobblestone 0  
fill ~50 ~8 ~9 ~52 ~8 ~9 cobblestone 0  
fill ~50 ~8 ~10 ~58 ~8 ~10 cobblestone 0  
fill ~50 ~8 ~11 ~52 ~8 ~11 cobblestone 0  
fill ~50 ~8 ~13 ~52 ~8 ~13 cobblestone 0  
fill ~50 ~8 ~14 ~52 ~8 ~14 cobblestone 0  
fill ~50 ~8 ~15 ~52 ~8 ~15 cobblestone 0  
fill ~50 ~8 ~16 ~52 ~8 ~16 cobblestone 0  
fill ~50 ~8 ~20 ~59 ~8 ~20 cobblestone 0  
fill ~50 ~8 ~24 ~58 ~8 ~24 cobblestone 0  
fill ~50 ~8 ~25 ~58 ~8 ~25 cobblestone 0  
fill ~50 ~8 ~26 ~58 ~8 ~26 cobblestone 0  
fill ~50 ~8 ~27 ~58 ~8 ~27 cobblestone 0
fill ~50 ~8 ~29 ~58 ~8 ~29 cobblestone 0  
fill ~50 ~8 ~30 ~58 ~8 ~30 cobblestone 0  
fill ~50 ~8 ~31 ~58 ~8 ~31 cobblestone 0  
fill ~50 ~8 ~32 ~58 ~8 ~32 cobblestone 0  
fill ~50 ~8 ~33 ~58 ~8 ~33 cobblestone 0  
fill ~50 ~8 ~34 ~58 ~8 ~34 cobblestone 0  
fill ~50 ~8 ~35 ~58 ~8 ~35 cobblestone 0  
fill ~50 ~8 ~37 ~51 ~8 ~37 cobblestone 0  
fill ~54 ~8 ~18 ~59 ~8 ~18 cobblestone 0  
fill ~55 ~8 ~8 ~58 ~8 ~8 cobblestone 0  
fill ~55 ~8 ~9 ~58 ~8 ~9 cobblestone 0  
fill ~55 ~8 ~11 ~58 ~8 ~11 cobblestone 0  
fill ~55 ~8 ~12 ~58 ~8 ~12 cobblestone 0  
fill ~55 ~8 ~13 ~58 ~8 ~13 cobblestone 0  
fill ~55 ~8 ~14 ~58 ~8 ~14 cobblestone 0  
fill ~55 ~8 ~15 ~58 ~8 ~15 cobblestone 0  
fill ~55 ~8 ~16 ~58 ~8 ~16 cobblestone 0  
fill ~55 ~8 ~17 ~58 ~8 ~17 cobblestone 0  
fill ~55 ~8 ~23 ~58 ~8 ~23 cobblestone 0  
fill ~59 ~8 ~17 ~61 ~8 ~17 stone_stairs 2  
fill ~59 ~8 ~23 ~61 ~8 ~23 stone_stairs 3  
fill ~60 ~8 ~4 ~64 ~8 ~4 cobblestone 0  
fill ~60 ~8 ~36 ~64 ~8 ~36 cobblestone 0  
fill ~61 ~8 ~18 ~62 ~8 ~18 cobblestone 0  
fill ~61 ~8 ~19 ~62 ~8 ~19 cobblestone 0  
fill ~61 ~8 ~20 ~62 ~8 ~20 cobblestone 0  
fill ~61 ~8 ~21 ~62 ~8 ~21 cobblestone 0  
fill ~62 ~8 ~9 ~63 ~8 ~9 cobblestone 0  
fill ~62 ~8 ~22 ~62 ~10 ~22 cobblestone 0  
fill ~63 ~8 ~3 ~64 ~8 ~3 cobblestone 0  
fill ~63 ~8 ~7 ~63 ~11 ~7 cobblestone 0  
fill ~63 ~8 ~8 ~63 ~8 ~6 cobblestone 0  
fill ~63 ~8 ~12 ~63 ~8 ~17 cobblestone 0 
setblock ~63 ~8 ~18 stone_stairs 7  
fill ~63 ~8 ~19 ~63 ~8 ~21 stone_slab 11 
setblock ~63 ~8 ~22 stone_stairs 6 
setblock ~63 ~8 ~23 cobblestone 0  
fill ~63 ~8 ~27 ~63 ~9 ~27 cobblestone 0  
fill ~63 ~8 ~28 ~63 ~8 ~23 cobblestone 0  
fill ~63 ~8 ~32 ~63 ~8 ~34 cobblestone 0  
fill ~63 ~8 ~37 ~64 ~8 ~37 cobblestone 0  
fill ~64 ~8 ~5 ~65 ~8 ~5 cobblestone 0  
fill ~64 ~8 ~35 ~65 ~8 ~35 cobblestone 0  
fill ~1 ~9 ~20 ~2 ~9 ~20 cobblestone 0  
fill ~2 ~9 ~25 ~3 ~9 ~25 cobblestone 0 
setblock ~3 ~9 ~18 torch 1 
setblock ~3 ~9 ~22 torch 1  
fill ~7 ~9 ~11 ~8 ~9 ~11 cobblestone 0  
fill ~7 ~9 ~29 ~8 ~9 ~29 cobblestone 0  
fill ~9 ~9 ~10 ~11 ~9 ~10 cobblestone 0  
fill ~9 ~9 ~30 ~11 ~9 ~30 cobblestone 0  
fill ~10 ~9 ~5 ~12 ~9 ~5 cobblestone 0  
fill ~10 ~9 ~11 ~10 ~9 ~13 stone_stairs 0  
fill ~10 ~9 ~27 ~10 ~9 ~29 stone_stairs 0  
fill ~10 ~9 ~35 ~12 ~9 ~35 cobblestone 0  
fill ~11 ~9 ~3 ~12 ~9 ~3 cobblestone 0  
fill ~11 ~9 ~4 ~15 ~9 ~4 cobblestone 0  
fill ~11 ~9 ~36 ~15 ~9 ~36 cobblestone 0  
fill ~11 ~9 ~37 ~12 ~9 ~37 cobblestone 0  
fill ~13 ~9 ~7 ~14 ~9 ~7 cobblestone 0  
fill ~13 ~9 ~32 ~14 ~9 ~32 cobblestone 0  
fill ~14 ~9 ~12 ~15 ~9 ~12 obsidian 0  
fill ~14 ~9 ~13 ~15 ~9 ~13 obsidian 0  
fill ~14 ~9 ~27 ~15 ~9 ~27 obsidian 0  
fill ~14 ~9 ~28 ~15 ~9 ~28 obsidian 0  
fill ~14 ~9 ~33 ~15 ~9 ~33 obsidian 0  
fill ~14 ~9 ~34 ~15 ~9 ~34 obsidian 0  
fill ~18 ~9 ~4 ~18 ~11 ~4 cobblestone 0  
fill ~18 ~9 ~36 ~18 ~11 ~36 cobblestone 0  
fill ~21 ~9 ~4 ~28 ~9 ~4 cobblestone 0  
fill ~21 ~9 ~6 ~22 ~9 ~6 obsidian 0  
fill ~21 ~9 ~7 ~22 ~9 ~7 obsidian 0  
fill ~21 ~9 ~12 ~22 ~9 ~12 obsidian 0  
fill ~21 ~9 ~13 ~22 ~9 ~13 obsidian 0  
fill ~21 ~9 ~27 ~22 ~9 ~27 obsidian 0  
fill ~21 ~9 ~28 ~22 ~9 ~28 obsidian 0  
fill ~21 ~9 ~33 ~22 ~9 ~33 obsidian 0  
fill ~21 ~9 ~34 ~22 ~9 ~34 obsidian 0  
fill ~21 ~9 ~36 ~28 ~9 ~36 cobblestone 0  
fill ~24 ~9 ~3 ~25 ~9 ~3 cobblestone 0  
fill ~24 ~9 ~37 ~25 ~9 ~37 cobblestone 0  
fill ~27 ~9 ~6 ~28 ~9 ~6 obsidian 0  
fill ~27 ~9 ~7 ~28 ~9 ~7 obsidian 0  
fill ~27 ~9 ~12 ~28 ~9 ~12 obsidian 0  
fill ~27 ~9 ~13 ~28 ~9 ~13 obsidian 0  
fill ~27 ~9 ~27 ~28 ~9 ~27 obsidian 0  
fill ~27 ~9 ~28 ~28 ~9 ~28 obsidian 0  
fill ~27 ~9 ~33 ~28 ~9 ~33 obsidian 0  
fill ~27 ~9 ~34 ~28 ~9 ~34 obsidian 0  
fill ~31 ~9 ~4 ~31 ~11 ~4 cobblestone 0  
fill ~31 ~9 ~36 ~31 ~11 ~36 cobblestone 0  
fill ~34 ~9 ~4 ~41 ~9 ~4 cobblestone 0  
fill ~34 ~9 ~6 ~35 ~9 ~6 obsidian 0  
fill ~34 ~9 ~7 ~35 ~9 ~7 obsidian 0  
fill ~34 ~9 ~12 ~35 ~9 ~12 obsidian 0  
fill ~34 ~9 ~13 ~35 ~9 ~13 obsidian 0  
fill ~34 ~9 ~27 ~35 ~9 ~27 obsidian 0  
fill ~34 ~9 ~28 ~35 ~9 ~28 obsidian 0  
fill ~34 ~9 ~33 ~35 ~9 ~33 obsidian 0  
fill ~34 ~9 ~34 ~35 ~9 ~34 obsidian 0  
fill ~34 ~9 ~36 ~41 ~9 ~36 cobblestone 0  
fill ~37 ~9 ~3 ~38 ~9 ~3 cobblestone 0  
fill ~37 ~9 ~37 ~38 ~9 ~37 cobblestone 0  
fill ~40 ~9 ~6 ~41 ~9 ~6 obsidian 0  
fill ~40 ~9 ~7 ~41 ~9 ~7 obsidian 0  
fill ~40 ~9 ~12 ~41 ~9 ~12 obsidian 0  
fill ~40 ~9 ~13 ~41 ~9 ~13 obsidian 0  
fill ~40 ~9 ~27 ~41 ~9 ~27 obsidian 0  
fill ~40 ~9 ~28 ~41 ~9 ~28 obsidian 0  
fill ~40 ~9 ~33 ~41 ~9 ~33 obsidian 0  
fill ~40 ~9 ~34 ~41 ~9 ~34 obsidian 0  
fill ~44 ~9 ~4 ~44 ~11 ~4 cobblestone 0  
fill ~44 ~9 ~36 ~44 ~11 ~36 cobblestone 0  
fill ~47 ~9 ~4 ~54 ~9 ~4 cobblestone 0  
fill ~47 ~9 ~6 ~48 ~9 ~6 obsidian 0  
fill ~47 ~9 ~7 ~48 ~9 ~7 obsidian 0  
fill ~47 ~9 ~12 ~48 ~9 ~12 obsidian 0  
fill ~47 ~9 ~13 ~48 ~9 ~13 obsidian 0  
fill ~47 ~9 ~27 ~48 ~9 ~27 obsidian 0  
fill ~47 ~9 ~28 ~48 ~9 ~28 obsidian 0  
fill ~47 ~9 ~33 ~48 ~9 ~33 obsidian 0  
fill ~47 ~9 ~34 ~48 ~9 ~34 obsidian 0  
fill ~47 ~9 ~36 ~54 ~9 ~36 cobblestone 0  
fill ~49 ~9 ~19 ~49 ~8 ~19 cobblestone 0  
fill ~49 ~9 ~20 ~49 ~10 ~20 cobblestone 0  
fill ~49 ~9 ~21 ~49 ~8 ~21 cobblestone 0  
fill ~49 ~9 ~22 ~49 ~8 ~22 cobblestone 0  
fill ~49 ~9 ~28 ~49 ~20 ~28 cobblestone 0  
fill ~50 ~9 ~3 ~51 ~9 ~3 cobblestone 0  
fill ~50 ~9 ~10 ~57 ~9 ~10 iron_block 0  
fill ~50 ~9 ~11 ~57 ~9 ~11 iron_block 0  
fill ~50 ~9 ~12 ~57 ~9 ~12 iron_block 0  
fill ~50 ~9 ~13 ~52 ~9 ~13 iron_block 0  
fill ~50 ~9 ~14 ~57 ~9 ~14 iron_block 0  
fill ~50 ~9 ~15 ~57 ~9 ~15 iron_block 0  
fill ~50 ~9 ~16 ~57 ~9 ~16 iron_block 0  
fill ~50 ~9 ~17 ~57 ~9 ~17 iron_block 0  
fill ~50 ~9 ~18 ~57 ~9 ~18 iron_block 0  
fill ~50 ~9 ~19 ~62 ~9 ~19 iron_block 0  
fill ~50 ~9 ~20 ~62 ~9 ~20 iron_block 0  
fill ~50 ~9 ~21 ~62 ~9 ~21 iron_block 0  
fill ~50 ~9 ~22 ~57 ~9 ~22 iron_block 0  
fill ~50 ~9 ~23 ~57 ~9 ~23 iron_block 0  
fill ~50 ~9 ~24 ~57 ~9 ~24 iron_block 0  
fill ~50 ~9 ~25 ~57 ~9 ~25 iron_block 0  
fill ~50 ~9 ~26 ~57 ~9 ~26 iron_block 0  
fill ~50 ~9 ~27 ~57 ~9 ~27 iron_block 0  
fill ~50 ~9 ~28 ~57 ~9 ~28 iron_block 0  
fill ~50 ~9 ~29 ~57 ~9 ~29 iron_block 0  
fill ~50 ~9 ~30 ~57 ~9 ~30 iron_block 0  
fill ~50 ~9 ~37 ~51 ~9 ~37 cobblestone 0  
fill ~54 ~9 ~13 ~57 ~9 ~13 iron_block 0  
fill ~56 ~9 ~4 ~58 ~9 ~4 cobblestone 0  
fill ~56 ~9 ~36 ~58 ~9 ~36 cobblestone 0  
fill ~58 ~9 ~5 ~58 ~12 ~5 cobblestone 0  
fill ~58 ~9 ~6 ~58 ~12 ~6 cobblestone 0  
fill ~58 ~9 ~7 ~58 ~12 ~7 cobblestone 0  
fill ~58 ~9 ~8 ~58 ~12 ~8 cobblestone 0  
fill ~58 ~9 ~9 ~58 ~11 ~9 cobblestone 0  
fill ~58 ~9 ~16 ~58 ~10 ~16 cobblestone 0  
fill ~58 ~9 ~17 ~58 ~10 ~17 cobblestone 0  
fill ~58 ~9 ~18 ~58 ~10 ~18 cobblestone 0  
fill ~58 ~9 ~22 ~58 ~10 ~22 cobblestone 0  
fill ~58 ~9 ~23 ~58 ~10 ~23 cobblestone 0  
fill ~58 ~9 ~24 ~58 ~10 ~24 cobblestone 0  
fill ~58 ~9 ~31 ~58 ~11 ~31 cobblestone 0  
fill ~58 ~9 ~32 ~58 ~12 ~32 cobblestone 0  
fill ~58 ~9 ~33 ~58 ~12 ~33 cobblestone 0  
fill ~58 ~9 ~34 ~58 ~12 ~34 cobblestone 0  
fill ~58 ~9 ~35 ~58 ~12 ~35 cobblestone 0  
fill ~59 ~9 ~18 ~61 ~9 ~18 stone_stairs 2  
fill ~59 ~9 ~22 ~61 ~9 ~22 stone_stairs 3  
fill ~60 ~9 ~4 ~64 ~9 ~4 cobblestone 0  
fill ~60 ~9 ~36 ~64 ~9 ~36 cobblestone 0  
fill ~62 ~9 ~9 ~62 ~10 ~9 cobblestone 0  
fill ~62 ~9 ~18 ~64 ~9 ~18 cobblestone 0  
fill ~63 ~9 ~3 ~64 ~9 ~3 cobblestone 0  
fill ~63 ~9 ~19 ~64 ~9 ~19 cobblestone 0  
fill ~63 ~9 ~20 ~64 ~9 ~20 cobblestone 0  
fill ~63 ~9 ~21 ~64 ~9 ~21 cobblestone 0  
fill ~63 ~9 ~22 ~64 ~9 ~22 cobblestone 0  
fill ~63 ~9 ~33 ~64 ~9 ~33 cobblestone 0  
fill ~63 ~9 ~37 ~64 ~9 ~37 cobblestone 0  
fill ~64 ~9 ~5 ~65 ~9 ~5 cobblestone 0  
fill ~64 ~9 ~6 ~64 ~9 ~37 cobblestone 0  
fill ~65 ~9 ~35 ~65 ~19 ~35 cobblestone 0  
fill ~1 ~10 ~20 ~2 ~10 ~20 cobblestone 0  
fill ~2 ~10 ~18 ~2 ~15 ~18 glass_pane 0  
fill ~2 ~10 ~22 ~2 ~15 ~22 glass_pane 0  
fill ~2 ~10 ~25 ~3 ~10 ~25 cobblestone 0  
fill ~5 ~10 ~13 ~6 ~10 ~13 glass_pane 0  
fill ~5 ~10 ~14 ~5 ~15 ~14 glass_pane 0  
fill ~5 ~10 ~26 ~5 ~15 ~26 glass_pane 0  
fill ~5 ~10 ~27 ~6 ~10 ~27 glass_pane 0  
fill ~7 ~10 ~11 ~8 ~10 ~11 cobblestone 0  
fill ~7 ~10 ~29 ~8 ~10 ~29 cobblestone 0 
setblock ~8 ~10 ~12 torch 3 
setblock ~8 ~10 ~28 torch 4  
fill ~9 ~10 ~10 ~9 ~17 ~10 cobblestone 0  
fill ~9 ~10 ~30 ~9 ~17 ~30 cobblestone 0  
fill ~10 ~10 ~5 ~12 ~10 ~5 cobblestone 0  
fill ~10 ~10 ~10 ~10 ~15 ~10 glass_pane 0  
fill ~10 ~10 ~30 ~10 ~15 ~30 glass_pane 0  
fill ~10 ~10 ~35 ~12 ~10 ~35 cobblestone 0  
fill ~11 ~10 ~3 ~12 ~10 ~3 cobblestone 0  
fill ~11 ~10 ~4 ~15 ~10 ~4 cobblestone 0  
fill ~11 ~10 ~10 ~11 ~17 ~10 cobblestone 0  
fill ~11 ~10 ~11 ~11 ~10 ~12 stone_stairs 0  
fill ~11 ~10 ~28 ~11 ~10 ~29 stone_stairs 0  
fill ~11 ~10 ~30 ~11 ~17 ~30 cobblestone 0  
fill ~11 ~10 ~36 ~15 ~10 ~36 cobblestone 0  
fill ~11 ~10 ~37 ~12 ~10 ~37 cobblestone 0  
fill ~13 ~10 ~7 ~15 ~10 ~7 cobblestone 0  
fill ~13 ~10 ~32 ~14 ~10 ~32 cobblestone 0  
fill ~14 ~10 ~12 ~14 ~3 ~12 obsidian 0  
fill ~14 ~10 ~13 ~15 ~10 ~13 obsidian 0  
fill ~14 ~10 ~27 ~15 ~10 ~27 obsidian 0  
fill ~15 ~10 ~6 ~15 ~12 ~6 cobblestone 0 
setblock ~15 ~10 ~8 stone_stairs 7 
setblock ~15 ~10 ~11 stone_stairs 6 
setblock ~15 ~10 ~12 cobblestone 0 
setblock ~15 ~10 ~28 cobblestone 0 
setblock ~15 ~10 ~29 stone_stairs 7 
setblock ~15 ~10 ~32 stone_stairs 6  
fill ~15 ~10 ~33 ~15 ~12 ~33 cobblestone 0  
fill ~15 ~10 ~34 ~15 ~12 ~34 cobblestone 0 
setblock ~16 ~10 ~5 obsidian 0  
fill ~16 ~10 ~6 ~16 ~10 ~7 stone_stairs 5  
fill ~16 ~10 ~12 ~16 ~10 ~13 stone_stairs 5  
fill ~16 ~10 ~27 ~16 ~10 ~28 stone_stairs 5  
fill ~16 ~10 ~33 ~16 ~10 ~34 stone_stairs 5 
setblock ~16 ~10 ~35 obsidian 0 
setblock ~17 ~10 ~5 stone_stairs 7 
setblock ~17 ~10 ~35 stone_stairs 6 
setblock ~19 ~10 ~5 stone_stairs 7 
setblock ~19 ~10 ~35 stone_stairs 6 
setblock ~20 ~10 ~5 obsidian 0  
fill ~20 ~10 ~6 ~20 ~10 ~7 stone_stairs 4  
fill ~20 ~10 ~12 ~20 ~10 ~13 stone_stairs 4  
fill ~20 ~10 ~27 ~20 ~10 ~28 stone_stairs 4  
fill ~20 ~10 ~33 ~20 ~10 ~34 stone_stairs 4 
setblock ~20 ~10 ~35 obsidian 0  
fill ~21 ~10 ~4 ~28 ~10 ~4 cobblestone 0  
fill ~21 ~10 ~6 ~22 ~10 ~6 cobblestone 0  
fill ~21 ~10 ~7 ~22 ~10 ~7 cobblestone 0  
fill ~21 ~10 ~8 ~22 ~10 ~8 stone_stairs 7  
fill ~21 ~10 ~11 ~22 ~10 ~11 stone_stairs 6  
fill ~21 ~10 ~12 ~22 ~10 ~12 cobblestone 0  
fill ~21 ~10 ~13 ~22 ~10 ~13 obsidian 0  
fill ~21 ~10 ~27 ~22 ~10 ~27 obsidian 0  
fill ~21 ~10 ~28 ~22 ~10 ~28 cobblestone 0  
fill ~21 ~10 ~29 ~22 ~10 ~29 stone_stairs 7  
fill ~21 ~10 ~32 ~22 ~10 ~32 stone_stairs 6  
fill ~21 ~10 ~33 ~22 ~10 ~33 cobblestone 0  
fill ~21 ~10 ~34 ~22 ~10 ~34 cobblestone 0  
fill ~21 ~10 ~36 ~28 ~10 ~36 cobblestone 0 
setblock ~23 ~10 ~5 obsidian 0  
fill ~23 ~10 ~6 ~23 ~10 ~7 stone_stairs 5  
fill ~23 ~10 ~12 ~23 ~10 ~13 stone_stairs 5  
fill ~23 ~10 ~27 ~23 ~10 ~28 stone_stairs 5  
fill ~23 ~10 ~33 ~23 ~10 ~34 stone_stairs 5 
setblock ~23 ~10 ~35 obsidian 0  
fill ~24 ~10 ~3 ~25 ~10 ~3 cobblestone 0  
fill ~24 ~10 ~5 ~25 ~10 ~5 stone_stairs 7  
fill ~24 ~10 ~35 ~25 ~10 ~35 stone_stairs 6  
fill ~24 ~10 ~37 ~25 ~10 ~37 cobblestone 0 
setblock ~26 ~10 ~5 obsidian 0  
fill ~26 ~10 ~6 ~26 ~10 ~7 stone_stairs 4  
fill ~26 ~10 ~12 ~26 ~10 ~13 stone_stairs 4  
fill ~26 ~10 ~27 ~26 ~10 ~28 stone_stairs 4  
fill ~26 ~10 ~33 ~26 ~10 ~34 stone_stairs 4 
setblock ~26 ~10 ~35 obsidian 0  
fill ~27 ~10 ~6 ~28 ~10 ~6 cobblestone 0  
fill ~27 ~10 ~7 ~28 ~10 ~7 cobblestone 0  
fill ~27 ~10 ~8 ~28 ~10 ~8 stone_stairs 7  
fill ~27 ~10 ~11 ~28 ~10 ~11 stone_stairs 6  
fill ~27 ~10 ~12 ~28 ~10 ~12 cobblestone 0  
fill ~27 ~10 ~13 ~28 ~10 ~13 obsidian 0  
fill ~27 ~10 ~27 ~28 ~10 ~27 obsidian 0  
fill ~27 ~10 ~28 ~28 ~10 ~28 cobblestone 0  
fill ~27 ~10 ~29 ~28 ~10 ~29 stone_stairs 7  
fill ~27 ~10 ~32 ~28 ~10 ~32 stone_stairs 6  
fill ~27 ~10 ~33 ~28 ~10 ~33 cobblestone 0  
fill ~27 ~10 ~34 ~28 ~10 ~34 cobblestone 0 
setblock ~29 ~10 ~5 obsidian 0  
fill ~29 ~10 ~6 ~29 ~10 ~7 stone_stairs 5  
fill ~29 ~10 ~12 ~29 ~10 ~13 stone_stairs 5  
fill ~29 ~10 ~27 ~29 ~10 ~28 stone_stairs 5  
fill ~29 ~10 ~33 ~29 ~10 ~34 stone_stairs 5 
setblock ~29 ~10 ~35 obsidian 0 
setblock ~30 ~10 ~5 stone_stairs 7 
setblock ~30 ~10 ~35 stone_stairs 6 
setblock ~32 ~10 ~5 stone_stairs 7 
setblock ~32 ~10 ~35 stone_stairs 6 
setblock ~33 ~10 ~5 obsidian 0  
fill ~33 ~10 ~6 ~33 ~10 ~7 stone_stairs 4  
fill ~33 ~10 ~12 ~33 ~10 ~13 stone_stairs 4  
fill ~33 ~10 ~27 ~33 ~10 ~28 stone_stairs 4  
fill ~33 ~10 ~33 ~33 ~10 ~34 stone_stairs 4 
setblock ~33 ~10 ~35 obsidian 0  
fill ~34 ~10 ~4 ~41 ~10 ~4 cobblestone 0  
fill ~34 ~10 ~6 ~35 ~10 ~6 cobblestone 0  
fill ~34 ~10 ~7 ~35 ~10 ~7 cobblestone 0  
fill ~34 ~10 ~8 ~35 ~10 ~8 stone_stairs 7  
fill ~34 ~10 ~11 ~35 ~10 ~11 stone_stairs 6  
fill ~34 ~10 ~12 ~35 ~10 ~12 cobblestone 0  
fill ~34 ~10 ~13 ~35 ~10 ~13 obsidian 0  
fill ~34 ~10 ~27 ~35 ~10 ~27 obsidian 0  
fill ~34 ~10 ~28 ~35 ~10 ~28 cobblestone 0  
fill ~34 ~10 ~29 ~35 ~10 ~29 stone_stairs 7  
fill ~34 ~10 ~32 ~35 ~10 ~32 stone_stairs 6  
fill ~34 ~10 ~33 ~35 ~10 ~33 cobblestone 0  
fill ~34 ~10 ~34 ~35 ~10 ~34 cobblestone 0  
fill ~34 ~10 ~36 ~41 ~10 ~36 cobblestone 0 
setblock ~36 ~10 ~5 obsidian 0  
fill ~36 ~10 ~6 ~36 ~10 ~7 stone_stairs 5  
fill ~36 ~10 ~12 ~36 ~10 ~13 stone_stairs 5  
fill ~36 ~10 ~27 ~36 ~10 ~28 stone_stairs 5  
fill ~36 ~10 ~33 ~36 ~10 ~34 stone_stairs 5 
setblock ~36 ~10 ~35 obsidian 0  
fill ~37 ~10 ~3 ~38 ~10 ~3 cobblestone 0  
fill ~37 ~10 ~5 ~38 ~10 ~5 stone_stairs 7  
fill ~37 ~10 ~35 ~38 ~10 ~35 stone_stairs 6  
fill ~37 ~10 ~37 ~38 ~10 ~37 cobblestone 0 
setblock ~39 ~10 ~5 obsidian 0  
fill ~39 ~10 ~6 ~39 ~10 ~7 stone_stairs 4  
fill ~39 ~10 ~12 ~39 ~10 ~13 stone_stairs 4  
fill ~39 ~10 ~27 ~39 ~10 ~28 stone_stairs 4  
fill ~39 ~10 ~33 ~39 ~10 ~34 stone_stairs 4 
setblock ~39 ~10 ~35 obsidian 0  
fill ~40 ~10 ~6 ~41 ~10 ~6 cobblestone 0  
fill ~40 ~10 ~7 ~41 ~10 ~7 cobblestone 0  
fill ~40 ~10 ~8 ~41 ~10 ~8 stone_stairs 7  
fill ~40 ~10 ~11 ~41 ~10 ~11 stone_stairs 6  
fill ~40 ~10 ~12 ~41 ~10 ~12 cobblestone 0  
fill ~40 ~10 ~13 ~41 ~10 ~13 obsidian 0  
fill ~40 ~10 ~27 ~41 ~10 ~27 obsidian 0  
fill ~40 ~10 ~28 ~41 ~10 ~28 cobblestone 0  
fill ~40 ~10 ~29 ~41 ~10 ~29 stone_stairs 7  
fill ~40 ~10 ~32 ~41 ~10 ~32 stone_stairs 6  
fill ~40 ~10 ~33 ~41 ~10 ~33 cobblestone 0  
fill ~40 ~10 ~34 ~41 ~10 ~34 cobblestone 0 
setblock ~42 ~10 ~5 obsidian 0  
fill ~42 ~10 ~6 ~42 ~10 ~7 stone_stairs 5  
fill ~42 ~10 ~12 ~42 ~10 ~13 stone_stairs 5  
fill ~42 ~10 ~27 ~42 ~10 ~28 stone_stairs 5  
fill ~42 ~10 ~33 ~42 ~10 ~34 stone_stairs 5 
setblock ~42 ~10 ~35 obsidian 0 
setblock ~43 ~10 ~5 stone_stairs 7 
setblock ~43 ~10 ~35 stone_stairs 6 
setblock ~45 ~10 ~5 stone_stairs 7 
setblock ~45 ~10 ~35 stone_stairs 6 
setblock ~46 ~10 ~5 obsidian 0  
fill ~46 ~10 ~6 ~46 ~10 ~7 stone_stairs 4  
fill ~46 ~10 ~12 ~46 ~10 ~13 stone_stairs 4  
fill ~46 ~10 ~27 ~46 ~10 ~28 stone_stairs 4  
fill ~46 ~10 ~33 ~46 ~10 ~34 stone_stairs 4 
setblock ~46 ~10 ~35 obsidian 0  
fill ~47 ~10 ~4 ~54 ~10 ~4 cobblestone 0  
fill ~47 ~10 ~6 ~48 ~10 ~6 cobblestone 0  
fill ~47 ~10 ~7 ~48 ~10 ~7 cobblestone 0  
fill ~47 ~10 ~8 ~48 ~10 ~8 stone_stairs 7  
fill ~47 ~10 ~11 ~48 ~10 ~11 stone_stairs 6  
fill ~47 ~10 ~12 ~49 ~10 ~12 cobblestone 0  
fill ~47 ~10 ~13 ~48 ~10 ~13 obsidian 0  
fill ~47 ~10 ~27 ~48 ~10 ~27 obsidian 0  
fill ~47 ~10 ~28 ~49 ~10 ~28 cobblestone 0  
fill ~47 ~10 ~29 ~48 ~10 ~29 stone_stairs 7  
fill ~47 ~10 ~32 ~48 ~10 ~32 stone_stairs 6  
fill ~47 ~10 ~33 ~48 ~10 ~33 cobblestone 0  
fill ~47 ~10 ~34 ~48 ~10 ~34 cobblestone 0  
fill ~47 ~10 ~36 ~54 ~10 ~36 cobblestone 0  
fill ~48 ~10 ~5 ~48 ~11 ~5 cobblestone 0  
fill ~49 ~10 ~14 ~49 ~10 ~15 stone_slab 3  
fill ~49 ~10 ~17 ~49 ~10 ~19 stone_slab 3  
fill ~49 ~10 ~21 ~49 ~10 ~23 stone_slab 3  
fill ~49 ~10 ~25 ~49 ~10 ~26 stone_slab 3  
fill ~50 ~10 ~3 ~51 ~10 ~3 cobblestone 0  
fill ~50 ~10 ~9 ~54 ~10 ~9 cobblestone 0  
fill ~50 ~10 ~31 ~54 ~10 ~31 cobblestone 0  
fill ~50 ~10 ~37 ~51 ~10 ~37 cobblestone 0  
fill ~53 ~10 ~13 ~54 ~10 ~13 cobblestone 0  
fill ~53 ~10 ~14 ~54 ~10 ~14 cobblestone 0  
fill ~53 ~10 ~15 ~54 ~10 ~15 cobblestone 0  
fill ~53 ~10 ~16 ~54 ~10 ~16 cobblestone 0  
fill ~53 ~10 ~17 ~54 ~10 ~17 cobblestone 0  
fill ~53 ~10 ~18 ~54 ~10 ~18 cobblestone 0  
fill ~53 ~10 ~19 ~54 ~10 ~19 cobblestone 0  
fill ~53 ~10 ~20 ~54 ~10 ~20 cobblestone 0  
fill ~53 ~10 ~21 ~54 ~10 ~21 cobblestone 0  
fill ~53 ~10 ~22 ~54 ~10 ~22 cobblestone 0  
fill ~53 ~10 ~23 ~54 ~10 ~23 cobblestone 0  
fill ~53 ~10 ~24 ~54 ~10 ~24 cobblestone 0  
fill ~53 ~10 ~25 ~54 ~10 ~25 cobblestone 0  
fill ~53 ~10 ~26 ~54 ~10 ~26 cobblestone 0  
fill ~53 ~10 ~27 ~54 ~10 ~27 cobblestone 0  
fill ~55 ~10 ~9 ~57 ~10 ~9 stone_stairs 3  
fill ~55 ~10 ~31 ~57 ~10 ~31 stone_stairs 2  
fill ~56 ~10 ~4 ~58 ~10 ~4 cobblestone 0  
fill ~56 ~10 ~36 ~58 ~10 ~36 cobblestone 0  
fill ~60 ~10 ~4 ~64 ~10 ~4 cobblestone 0  
fill ~60 ~10 ~36 ~64 ~10 ~36 cobblestone 0 
setblock ~62 ~10 ~6 stone_stairs 7 
setblock ~62 ~10 ~7 stone_stairs 6 
setblock ~62 ~10 ~10 stone_stairs 7 
setblock ~62 ~10 ~11 stone_stairs 6 
setblock ~62 ~10 ~14 stone_stairs 7 
setblock ~62 ~10 ~15 stone_stairs 6  
fill ~62 ~10 ~18 ~62 ~8 ~18 cobblestone 0  
fill ~62 ~10 ~19 ~62 ~10 ~24 cobblestone 0 
setblock ~62 ~10 ~25 stone_stairs 7 
setblock ~62 ~10 ~26 stone_stairs 6 
setblock ~62 ~10 ~29 stone_stairs 7 
setblock ~62 ~10 ~30 stone_stairs 6 
setblock ~62 ~10 ~33 stone_stairs 7 
setblock ~62 ~10 ~34 stone_stairs 6  
fill ~63 ~10 ~3 ~64 ~10 ~3 cobblestone 0  
fill ~63 ~10 ~33 ~63 ~11 ~33 cobblestone 0  
fill ~63 ~10 ~37 ~64 ~10 ~37 cobblestone 0  
fill ~64 ~10 ~5 ~65 ~10 ~5 cobblestone 0  
fill ~64 ~10 ~6 ~64 ~10 ~9 stone_stairs 1  
fill ~64 ~10 ~11 ~64 ~10 ~14 stone_stairs 1  
fill ~64 ~10 ~15 ~64 ~19 ~15 cobblestone 0  
fill ~64 ~10 ~16 ~64 ~10 ~24 stone_stairs 1  
fill ~64 ~10 ~25 ~64 ~19 ~25 cobblestone 0  
fill ~64 ~10 ~26 ~64 ~10 ~29 stone_stairs 1  
fill ~64 ~10 ~31 ~64 ~10 ~34 stone_stairs 1  
fill ~64 ~10 ~35 ~64 ~19 ~35 cobblestone 0  
fill ~1 ~11 ~20 ~2 ~11 ~20 cobblestone 0  
fill ~2 ~11 ~25 ~3 ~11 ~25 cobblestone 0  
fill ~5 ~11 ~13 ~6 ~11 ~13 glass_pane 0  
fill ~5 ~11 ~27 ~6 ~11 ~27 glass_pane 0  
fill ~7 ~11 ~11 ~8 ~11 ~11 cobblestone 0  
fill ~7 ~11 ~29 ~8 ~11 ~29 cobblestone 0 
setblock ~8 ~11 ~17 stone_stairs 6 
setblock ~8 ~11 ~20 torch 1 
setblock ~8 ~11 ~23 stone_stairs 7 
setblock ~9 ~11 ~15 stone_stairs 7 
setblock ~9 ~11 ~25 stone_stairs 6  
fill ~10 ~11 ~5 ~12 ~11 ~5 cobblestone 0  
fill ~10 ~11 ~35 ~12 ~11 ~35 cobblestone 0  
fill ~11 ~11 ~3 ~12 ~11 ~3 cobblestone 0  
fill ~11 ~11 ~4 ~15 ~11 ~4 cobblestone 0  
fill ~11 ~11 ~36 ~15 ~11 ~36 cobblestone 0  
fill ~11 ~11 ~37 ~12 ~11 ~37 cobblestone 0  
fill ~12 ~11 ~10 ~12 ~11 ~12 stone_stairs 0  
fill ~12 ~11 ~28 ~12 ~11 ~30 stone_stairs 0  
fill ~13 ~11 ~7 ~15 ~11 ~7 cobblestone 0  
fill ~13 ~11 ~28 ~13 ~11 ~31 cobblestone 0  
fill ~14 ~11 ~12 ~14 ~12 ~12 cobblestone 0  
fill ~14 ~11 ~13 ~16 ~11 ~13 obsidian 0  
fill ~14 ~11 ~27 ~16 ~11 ~27 obsidian 0 
setblock ~15 ~11 ~8 obsidian 0 
setblock ~15 ~11 ~9 stone_stairs 7 
setblock ~15 ~11 ~10 stone_stairs 6  
fill ~15 ~11 ~11 ~15 ~11 ~13 obsidian 0  
fill ~15 ~11 ~28 ~16 ~11 ~28 obsidian 0  
fill ~15 ~11 ~29 ~15 ~11 ~27 obsidian 0 
setblock ~15 ~11 ~30 stone_stairs 7 
setblock ~15 ~11 ~31 stone_stairs 6 
setblock ~15 ~11 ~32 obsidian 0  
fill ~16 ~11 ~6 ~16 ~11 ~7 obsidian 0 
setblock ~16 ~11 ~12 obsidian 0  
fill ~16 ~11 ~33 ~16 ~11 ~34 obsidian 0 
setblock ~17 ~11 ~5 obsidian 0  
fill ~17 ~11 ~6 ~17 ~11 ~7 stone_stairs 5  
fill ~17 ~11 ~12 ~17 ~11 ~13 stone_stairs 5  
fill ~17 ~11 ~27 ~17 ~11 ~28 stone_stairs 5  
fill ~17 ~11 ~33 ~17 ~11 ~34 stone_stairs 5 
setblock ~17 ~11 ~35 obsidian 0 
setblock ~18 ~11 ~5 stone_stairs 7 
setblock ~18 ~11 ~35 stone_stairs 6 
setblock ~19 ~11 ~5 obsidian 0  
fill ~19 ~11 ~6 ~19 ~11 ~7 stone_stairs 4  
fill ~19 ~11 ~12 ~19 ~11 ~13 stone_stairs 4  
fill ~19 ~11 ~27 ~19 ~11 ~28 stone_stairs 4  
fill ~19 ~11 ~33 ~19 ~11 ~34 stone_stairs 4 
setblock ~19 ~11 ~35 obsidian 0  
fill ~20 ~11 ~6 ~20 ~11 ~7 obsidian 0  
fill ~20 ~11 ~12 ~23 ~11 ~12 obsidian 0  
fill ~20 ~11 ~13 ~23 ~11 ~13 obsidian 0  
fill ~20 ~11 ~27 ~23 ~11 ~27 obsidian 0  
fill ~20 ~11 ~28 ~23 ~11 ~28 obsidian 0  
fill ~20 ~11 ~33 ~20 ~11 ~34 obsidian 0  
fill ~21 ~11 ~4 ~28 ~11 ~4 cobblestone 0  
fill ~21 ~11 ~6 ~22 ~11 ~6 cobblestone 0  
fill ~21 ~11 ~7 ~22 ~11 ~7 cobblestone 0  
fill ~21 ~11 ~8 ~22 ~11 ~8 obsidian 0  
fill ~21 ~11 ~9 ~22 ~11 ~9 stone_stairs 7  
fill ~21 ~11 ~10 ~22 ~11 ~10 stone_stairs 6  
fill ~21 ~11 ~11 ~22 ~11 ~11 obsidian 0  
fill ~21 ~11 ~29 ~22 ~11 ~29 obsidian 0  
fill ~21 ~11 ~30 ~22 ~11 ~30 stone_stairs 7  
fill ~21 ~11 ~31 ~22 ~11 ~31 stone_stairs 6  
fill ~21 ~11 ~32 ~22 ~11 ~32 obsidian 0  
fill ~21 ~11 ~33 ~22 ~11 ~33 cobblestone 0  
fill ~21 ~11 ~34 ~22 ~11 ~34 cobblestone 0  
fill ~21 ~11 ~36 ~28 ~11 ~36 cobblestone 0  
fill ~23 ~11 ~6 ~23 ~11 ~7 obsidian 0  
fill ~23 ~11 ~33 ~23 ~11 ~34 obsidian 0  
fill ~24 ~11 ~3 ~25 ~11 ~3 cobblestone 0  
fill ~24 ~11 ~5 ~25 ~11 ~5 obsidian 0  
fill ~24 ~11 ~6 ~24 ~11 ~7 stone_stairs 5  
fill ~24 ~11 ~12 ~24 ~11 ~13 stone_stairs 5  
fill ~24 ~11 ~27 ~24 ~11 ~28 stone_stairs 5  
fill ~24 ~11 ~33 ~24 ~11 ~34 stone_stairs 5  
fill ~24 ~11 ~35 ~25 ~11 ~35 obsidian 0  
fill ~24 ~11 ~37 ~25 ~11 ~37 cobblestone 0  
fill ~25 ~11 ~6 ~25 ~11 ~7 stone_stairs 4  
fill ~25 ~11 ~12 ~25 ~11 ~13 stone_stairs 4  
fill ~25 ~11 ~27 ~25 ~11 ~28 stone_stairs 4  
fill ~25 ~11 ~33 ~25 ~11 ~34 stone_stairs 4  
fill ~26 ~11 ~6 ~26 ~11 ~7 obsidian 0  
fill ~26 ~11 ~12 ~29 ~11 ~12 obsidian 0  
fill ~26 ~11 ~13 ~29 ~11 ~13 obsidian 0  
fill ~26 ~11 ~27 ~29 ~11 ~27 obsidian 0  
fill ~26 ~11 ~28 ~29 ~11 ~28 obsidian 0  
fill ~26 ~11 ~33 ~26 ~11 ~34 obsidian 0  
fill ~27 ~11 ~6 ~28 ~11 ~6 cobblestone 0  
fill ~27 ~11 ~7 ~28 ~11 ~7 cobblestone 0  
fill ~27 ~11 ~8 ~28 ~11 ~8 obsidian 0  
fill ~27 ~11 ~9 ~28 ~11 ~9 stone_stairs 7  
fill ~27 ~11 ~10 ~28 ~11 ~10 stone_stairs 6  
fill ~27 ~11 ~11 ~28 ~11 ~11 obsidian 0  
fill ~27 ~11 ~29 ~28 ~11 ~29 obsidian 0  
fill ~27 ~11 ~30 ~28 ~11 ~30 stone_stairs 7  
fill ~27 ~11 ~31 ~28 ~11 ~31 stone_stairs 6  
fill ~27 ~11 ~32 ~28 ~11 ~32 obsidian 0  
fill ~27 ~11 ~33 ~28 ~11 ~33 cobblestone 0  
fill ~27 ~11 ~34 ~28 ~11 ~34 cobblestone 0  
fill ~29 ~11 ~6 ~29 ~11 ~7 obsidian 0  
fill ~29 ~11 ~33 ~29 ~11 ~34 obsidian 0 
setblock ~30 ~11 ~5 obsidian 0  
fill ~30 ~11 ~6 ~30 ~11 ~7 stone_stairs 5  
fill ~30 ~11 ~12 ~30 ~11 ~13 stone_stairs 5  
fill ~30 ~11 ~27 ~30 ~11 ~28 stone_stairs 5  
fill ~30 ~11 ~33 ~30 ~11 ~34 stone_stairs 5 
setblock ~30 ~11 ~35 obsidian 0 
setblock ~31 ~11 ~5 stone_stairs 7 
setblock ~31 ~11 ~35 stone_stairs 6 
setblock ~32 ~11 ~5 obsidian 0  
fill ~32 ~11 ~6 ~32 ~11 ~7 stone_stairs 4  
fill ~32 ~11 ~12 ~32 ~11 ~13 stone_stairs 4  
fill ~32 ~11 ~27 ~32 ~11 ~28 stone_stairs 4  
fill ~32 ~11 ~33 ~32 ~11 ~34 stone_stairs 4 
setblock ~32 ~11 ~35 obsidian 0  
fill ~33 ~11 ~6 ~33 ~11 ~7 obsidian 0  
fill ~33 ~11 ~12 ~36 ~11 ~12 obsidian 0  
fill ~33 ~11 ~13 ~36 ~11 ~13 obsidian 0  
fill ~33 ~11 ~27 ~36 ~11 ~27 obsidian 0  
fill ~33 ~11 ~28 ~36 ~11 ~28 obsidian 0  
fill ~33 ~11 ~33 ~33 ~11 ~34 obsidian 0  
fill ~34 ~11 ~4 ~41 ~11 ~4 cobblestone 0  
fill ~34 ~11 ~6 ~35 ~11 ~6 cobblestone 0  
fill ~34 ~11 ~7 ~35 ~11 ~7 cobblestone 0  
fill ~34 ~11 ~8 ~35 ~11 ~8 obsidian 0  
fill ~34 ~11 ~9 ~35 ~11 ~9 stone_stairs 7  
fill ~34 ~11 ~10 ~35 ~11 ~10 stone_stairs 6  
fill ~34 ~11 ~11 ~35 ~11 ~11 obsidian 0  
fill ~34 ~11 ~29 ~35 ~11 ~29 obsidian 0  
fill ~34 ~11 ~30 ~35 ~11 ~30 stone_stairs 7  
fill ~34 ~11 ~31 ~35 ~11 ~31 stone_stairs 6  
fill ~34 ~11 ~32 ~35 ~11 ~32 obsidian 0  
fill ~34 ~11 ~33 ~35 ~11 ~33 cobblestone 0  
fill ~34 ~11 ~34 ~35 ~11 ~34 cobblestone 0  
fill ~34 ~11 ~36 ~41 ~11 ~36 cobblestone 0  
fill ~36 ~11 ~6 ~36 ~11 ~7 obsidian 0  
fill ~36 ~11 ~33 ~36 ~11 ~34 obsidian 0  
fill ~37 ~11 ~3 ~38 ~11 ~3 cobblestone 0  
fill ~37 ~11 ~5 ~38 ~11 ~5 obsidian 0  
fill ~37 ~11 ~6 ~37 ~11 ~7 stone_stairs 5  
fill ~37 ~11 ~12 ~37 ~11 ~13 stone_stairs 5  
fill ~37 ~11 ~27 ~37 ~11 ~28 stone_stairs 5  
fill ~37 ~11 ~33 ~37 ~11 ~34 stone_stairs 5  
fill ~37 ~11 ~35 ~38 ~11 ~35 obsidian 0  
fill ~37 ~11 ~37 ~38 ~11 ~37 cobblestone 0  
fill ~38 ~11 ~6 ~38 ~11 ~7 stone_stairs 4  
fill ~38 ~11 ~12 ~38 ~11 ~13 stone_stairs 4  
fill ~38 ~11 ~27 ~38 ~11 ~28 stone_stairs 4  
fill ~38 ~11 ~33 ~38 ~11 ~34 stone_stairs 4  
fill ~39 ~11 ~6 ~39 ~11 ~7 obsidian 0  
fill ~39 ~11 ~12 ~42 ~11 ~12 obsidian 0  
fill ~39 ~11 ~13 ~42 ~11 ~13 obsidian 0  
fill ~39 ~11 ~27 ~42 ~11 ~27 obsidian 0  
fill ~39 ~11 ~28 ~42 ~11 ~28 obsidian 0  
fill ~39 ~11 ~33 ~39 ~11 ~34 obsidian 0  
fill ~40 ~11 ~6 ~41 ~11 ~6 cobblestone 0  
fill ~40 ~11 ~7 ~41 ~11 ~7 cobblestone 0  
fill ~40 ~11 ~8 ~41 ~11 ~8 obsidian 0  
fill ~40 ~11 ~9 ~41 ~11 ~9 stone_stairs 7  
fill ~40 ~11 ~10 ~41 ~11 ~10 stone_stairs 6  
fill ~40 ~11 ~11 ~41 ~11 ~11 obsidian 0  
fill ~40 ~11 ~29 ~41 ~11 ~29 obsidian 0  
fill ~40 ~11 ~30 ~41 ~11 ~30 stone_stairs 7  
fill ~40 ~11 ~31 ~41 ~11 ~31 stone_stairs 6  
fill ~40 ~11 ~32 ~41 ~11 ~32 obsidian 0  
fill ~40 ~11 ~33 ~41 ~11 ~33 cobblestone 0  
fill ~40 ~11 ~34 ~41 ~11 ~34 cobblestone 0  
fill ~42 ~11 ~6 ~42 ~11 ~7 obsidian 0  
fill ~42 ~11 ~33 ~42 ~11 ~34 obsidian 0 
setblock ~43 ~11 ~5 obsidian 0  
fill ~43 ~11 ~6 ~43 ~11 ~7 stone_stairs 5  
fill ~43 ~11 ~12 ~43 ~11 ~13 stone_stairs 5  
fill ~43 ~11 ~27 ~43 ~11 ~28 stone_stairs 5  
fill ~43 ~11 ~33 ~43 ~11 ~34 stone_stairs 5 
setblock ~43 ~11 ~35 obsidian 0 
setblock ~44 ~11 ~5 stone_stairs 7 
setblock ~44 ~11 ~35 stone_stairs 6 
setblock ~45 ~11 ~5 obsidian 0  
fill ~45 ~11 ~6 ~45 ~11 ~7 stone_stairs 4  
fill ~45 ~11 ~12 ~45 ~11 ~13 stone_stairs 4  
fill ~45 ~11 ~27 ~45 ~11 ~28 stone_stairs 4  
fill ~45 ~11 ~33 ~45 ~11 ~34 stone_stairs 4 
setblock ~45 ~11 ~35 obsidian 0  
fill ~46 ~11 ~6 ~46 ~11 ~7 obsidian 0  
fill ~46 ~11 ~12 ~46 ~11 ~13 obsidian 0  
fill ~46 ~11 ~27 ~48 ~11 ~27 obsidian 0  
fill ~46 ~11 ~28 ~46 ~11 ~27 obsidian 0  
fill ~46 ~11 ~33 ~46 ~11 ~34 obsidian 0  
fill ~47 ~11 ~4 ~54 ~11 ~4 cobblestone 0  
fill ~47 ~11 ~6 ~48 ~11 ~6 cobblestone 0  
fill ~47 ~11 ~7 ~48 ~11 ~7 cobblestone 0  
fill ~47 ~11 ~8 ~48 ~11 ~8 obsidian 0  
fill ~47 ~11 ~9 ~48 ~11 ~9 stone_stairs 7  
fill ~47 ~11 ~10 ~48 ~11 ~10 stone_stairs 6  
fill ~47 ~11 ~11 ~48 ~11 ~11 obsidian 0  
fill ~47 ~11 ~13 ~48 ~11 ~13 obsidian 0  
fill ~47 ~11 ~29 ~48 ~11 ~29 obsidian 0  
fill ~47 ~11 ~30 ~48 ~11 ~30 stone_stairs 7  
fill ~47 ~11 ~31 ~48 ~11 ~31 stone_stairs 6  
fill ~47 ~11 ~32 ~48 ~11 ~32 obsidian 0  
fill ~47 ~11 ~33 ~48 ~11 ~33 cobblestone 0  
fill ~47 ~11 ~34 ~48 ~11 ~34 cobblestone 0  
fill ~47 ~11 ~36 ~54 ~11 ~36 cobblestone 0  
fill ~48 ~11 ~12 ~48 ~12 ~12 cobblestone 0  
fill ~48 ~11 ~28 ~48 ~12 ~28 cobblestone 0  
fill ~49 ~11 ~16 ~49 ~12 ~16 obsidian 0  
fill ~49 ~11 ~20 ~49 ~12 ~20 obsidian 0  
fill ~49 ~11 ~24 ~49 ~12 ~24 obsidian 0  
fill ~50 ~11 ~3 ~51 ~11 ~3 cobblestone 0  
fill ~50 ~11 ~9 ~51 ~11 ~9 cobblestone 0  
fill ~50 ~11 ~31 ~51 ~11 ~31 cobblestone 0  
fill ~50 ~11 ~37 ~51 ~11 ~37 cobblestone 0  
fill ~52 ~11 ~8 ~54 ~11 ~8 cobblestone 0  
fill ~52 ~11 ~32 ~54 ~11 ~32 cobblestone 0  
fill ~53 ~11 ~13 ~54 ~11 ~13 cobblestone 0  
fill ~53 ~11 ~14 ~54 ~11 ~14 cobblestone 0  
fill ~53 ~11 ~15 ~53 ~14 ~15 cobblestone 0  
fill ~53 ~11 ~16 ~53 ~14 ~16 cobblestone 0  
fill ~53 ~11 ~19 ~53 ~14 ~19 cobblestone 0  
fill ~53 ~11 ~20 ~53 ~14 ~20 cobblestone 0  
fill ~53 ~11 ~21 ~53 ~14 ~21 cobblestone 0  
fill ~53 ~11 ~24 ~53 ~14 ~24 cobblestone 0  
fill ~53 ~11 ~25 ~53 ~14 ~25 cobblestone 0  
fill ~53 ~11 ~26 ~54 ~11 ~26 cobblestone 0  
fill ~53 ~11 ~27 ~54 ~11 ~27 cobblestone 0  
fill ~54 ~11 ~9 ~54 ~20 ~9 cobblestone 0  
fill ~54 ~11 ~17 ~54 ~16 ~17 cobblestone 0  
fill ~54 ~11 ~18 ~54 ~16 ~18 cobblestone 0  
fill ~54 ~11 ~22 ~54 ~16 ~22 cobblestone 0  
fill ~54 ~11 ~23 ~54 ~16 ~23 cobblestone 0  
fill ~54 ~11 ~31 ~54 ~20 ~31 cobblestone 0  
fill ~55 ~11 ~4 ~55 ~11 ~7 iron_block 0  
fill ~55 ~11 ~8 ~57 ~11 ~8 stone_stairs 3  
fill ~55 ~11 ~32 ~57 ~11 ~32 stone_stairs 2  
fill ~55 ~11 ~33 ~57 ~11 ~33 iron_block 0  
fill ~55 ~11 ~34 ~57 ~11 ~34 iron_block 0  
fill ~55 ~11 ~35 ~57 ~11 ~35 iron_block 0  
fill ~55 ~11 ~36 ~55 ~11 ~33 iron_block 0  
fill ~56 ~11 ~4 ~58 ~11 ~4 cobblestone 0  
fill ~56 ~11 ~5 ~57 ~11 ~5 iron_block 0  
fill ~56 ~11 ~6 ~57 ~11 ~6 iron_block 0  
fill ~56 ~11 ~7 ~57 ~11 ~7 iron_block 0  
fill ~56 ~11 ~36 ~58 ~11 ~36 cobblestone 0 
setblock ~58 ~11 ~10 stone_stairs 3 
setblock ~58 ~11 ~30 stone_stairs 2  
fill ~60 ~11 ~4 ~64 ~11 ~4 cobblestone 0  
fill ~60 ~11 ~36 ~64 ~11 ~36 cobblestone 0  
fill ~62 ~11 ~5 ~62 ~11 ~35 stone_stairs 0  
fill ~63 ~11 ~3 ~64 ~11 ~3 cobblestone 0  
fill ~63 ~11 ~5 ~65 ~11 ~5 cobblestone 0  
fill ~63 ~11 ~8 ~63 ~19 ~8 cobblestone 0  
fill ~63 ~11 ~9 ~63 ~11 ~3 cobblestone 0  
fill ~63 ~11 ~12 ~63 ~11 ~37 cobblestone 0  
fill ~64 ~11 ~37 ~64 ~30 ~37 cobblestone 0  
fill ~1 ~12 ~20 ~2 ~12 ~20 cobblestone 0  
fill ~2 ~12 ~25 ~3 ~12 ~25 cobblestone 0  
fill ~5 ~12 ~13 ~6 ~12 ~13 glass_pane 0  
fill ~5 ~12 ~27 ~6 ~12 ~27 glass_pane 0  
fill ~7 ~12 ~11 ~8 ~12 ~11 cobblestone 0  
fill ~7 ~12 ~29 ~8 ~12 ~29 cobblestone 0  
fill ~8 ~12 ~16 ~8 ~15 ~16 cobblestone 0  
fill ~8 ~12 ~17 ~8 ~15 ~17 cobblestone 0  
fill ~8 ~12 ~23 ~8 ~15 ~23 cobblestone 0  
fill ~8 ~12 ~24 ~8 ~15 ~24 cobblestone 0  
fill ~9 ~12 ~15 ~9 ~15 ~15 cobblestone 0  
fill ~9 ~12 ~25 ~9 ~15 ~25 cobblestone 0  
fill ~10 ~12 ~5 ~12 ~12 ~5 cobblestone 0  
fill ~10 ~12 ~35 ~12 ~12 ~35 cobblestone 0  
fill ~11 ~12 ~3 ~12 ~12 ~3 cobblestone 0  
fill ~11 ~12 ~4 ~13 ~12 ~4 cobblestone 0  
fill ~11 ~12 ~36 ~13 ~12 ~36 cobblestone 0  
fill ~11 ~12 ~37 ~12 ~12 ~37 cobblestone 0  
fill ~13 ~12 ~5 ~15 ~12 ~5 stone_stairs 2  
fill ~13 ~12 ~6 ~13 ~12 ~12 stone_stairs 0  
fill ~13 ~12 ~28 ~13 ~12 ~35 stone_stairs 0  
fill ~14 ~12 ~4 ~14 ~15 ~4 glass_pane 0  
fill ~14 ~12 ~13 ~15 ~12 ~13 obsidian 0  
fill ~14 ~12 ~27 ~15 ~12 ~27 obsidian 0  
fill ~14 ~12 ~35 ~15 ~12 ~35 stone_stairs 3  
fill ~14 ~12 ~36 ~14 ~15 ~36 glass_pane 0  
fill ~15 ~12 ~4 ~15 ~17 ~4 cobblestone 0  
fill ~15 ~12 ~7 ~16 ~12 ~7 cobblestone 0  
fill ~15 ~12 ~8 ~15 ~12 ~6 cobblestone 0  
fill ~15 ~12 ~9 ~15 ~12 ~10 obsidian 0  
fill ~15 ~12 ~11 ~15 ~12 ~12 cobblestone 0  
fill ~15 ~12 ~28 ~16 ~12 ~28 cobblestone 0  
fill ~15 ~12 ~29 ~15 ~12 ~28 cobblestone 0  
fill ~15 ~12 ~30 ~15 ~12 ~31 obsidian 0 
setblock ~15 ~12 ~32 cobblestone 0  
fill ~15 ~12 ~36 ~15 ~17 ~36 cobblestone 0 
setblock ~16 ~12 ~4 stone_slab 3 
setblock ~16 ~12 ~5 diamond_block 0 
setblock ~16 ~12 ~6 cobblestone 0 
setblock ~16 ~12 ~8 glowstone 0 
setblock ~16 ~12 ~11 glowstone 0  
fill ~16 ~12 ~12 ~16 ~12 ~13 cobblestone 0  
fill ~16 ~12 ~27 ~16 ~13 ~27 cobblestone 0 
setblock ~16 ~12 ~29 glowstone 0 
setblock ~16 ~12 ~32 glowstone 0  
fill ~16 ~12 ~33 ~16 ~12 ~34 cobblestone 0 
setblock ~16 ~12 ~35 diamond_block 0  
fill ~17 ~12 ~5 ~19 ~12 ~5 stone_stairs 2  
fill ~17 ~12 ~6 ~17 ~12 ~7 obsidian 0  
fill ~17 ~12 ~12 ~17 ~12 ~13 obsidian 0  
fill ~17 ~12 ~27 ~17 ~12 ~28 obsidian 0  
fill ~17 ~12 ~33 ~17 ~12 ~34 obsidian 0  
fill ~17 ~12 ~35 ~19 ~12 ~35 stone_stairs 3  
fill ~18 ~12 ~4 ~18 ~15 ~4 glass_pane 0  
fill ~18 ~12 ~6 ~18 ~12 ~7 cobblestone 0  
fill ~18 ~12 ~12 ~18 ~12 ~13 cobblestone 0  
fill ~18 ~12 ~27 ~18 ~13 ~27 cobblestone 0  
fill ~18 ~12 ~28 ~18 ~12 ~27 cobblestone 0  
fill ~18 ~12 ~33 ~18 ~12 ~34 cobblestone 0  
fill ~18 ~12 ~36 ~18 ~15 ~36 glass_pane 0  
fill ~19 ~12 ~6 ~19 ~12 ~7 obsidian 0  
fill ~19 ~12 ~12 ~19 ~12 ~13 obsidian 0  
fill ~19 ~12 ~27 ~19 ~12 ~28 obsidian 0  
fill ~19 ~12 ~33 ~19 ~12 ~34 obsidian 0 
setblock ~20 ~12 ~4 stone_slab 3 
setblock ~20 ~12 ~5 diamond_block 0  
fill ~20 ~12 ~6 ~23 ~12 ~6 cobblestone 0  
fill ~20 ~12 ~7 ~23 ~12 ~7 cobblestone 0   

KittysCommands:  
setblock ~20 ~12 ~8 glowstone 0 
setblock ~20 ~12 ~11 glowstone 0  
fill ~20 ~12 ~12 ~23 ~12 ~12 cobblestone 0  
fill ~20 ~12 ~13 ~20 ~13 ~13 cobblestone 0  
fill ~20 ~12 ~27 ~20 ~13 ~27 cobblestone 0  
fill ~20 ~12 ~28 ~23 ~12 ~28 cobblestone 0 
setblock ~20 ~12 ~29 glowstone 0 
setblock ~20 ~12 ~32 glowstone 0  
fill ~20 ~12 ~33 ~23 ~12 ~33 cobblestone 0  
fill ~20 ~12 ~34 ~23 ~12 ~34 cobblestone 0 
setblock ~20 ~12 ~35 diamond_block 0  
fill ~21 ~12 ~4 ~21 ~17 ~4 cobblestone 0  
fill ~21 ~12 ~5 ~22 ~12 ~5 stone_stairs 2  
fill ~21 ~12 ~8 ~22 ~12 ~8 cobblestone 0  
fill ~21 ~12 ~9 ~22 ~12 ~9 obsidian 0  
fill ~21 ~12 ~10 ~22 ~12 ~10 obsidian 0  
fill ~21 ~12 ~11 ~22 ~12 ~11 cobblestone 0  
fill ~21 ~12 ~13 ~22 ~12 ~13 obsidian 0  
fill ~21 ~12 ~27 ~22 ~12 ~27 obsidian 0  
fill ~21 ~12 ~29 ~22 ~12 ~29 cobblestone 0  
fill ~21 ~12 ~30 ~22 ~12 ~30 obsidian 0  
fill ~21 ~12 ~31 ~22 ~12 ~31 obsidian 0  
fill ~21 ~12 ~32 ~22 ~12 ~32 cobblestone 0  
fill ~21 ~12 ~35 ~22 ~12 ~35 stone_stairs 3  
fill ~21 ~12 ~36 ~21 ~17 ~36 cobblestone 0  
fill ~22 ~12 ~4 ~22 ~15 ~4 glass_pane 0  
fill ~22 ~12 ~36 ~22 ~15 ~36 glass_pane 0  
fill ~23 ~12 ~4 ~26 ~12 ~4 cobblestone 0 
setblock ~23 ~12 ~5 diamond_block 0 
setblock ~23 ~12 ~8 glowstone 0 
setblock ~23 ~12 ~11 glowstone 0  
fill ~23 ~12 ~13 ~23 ~13 ~13 cobblestone 0  
fill ~23 ~12 ~27 ~23 ~13 ~27 cobblestone 0 
setblock ~23 ~12 ~29 glowstone 0 
setblock ~23 ~12 ~32 glowstone 0 
setblock ~23 ~12 ~35 diamond_block 0  
fill ~23 ~12 ~36 ~26 ~12 ~36 cobblestone 0  
fill ~24 ~12 ~3 ~25 ~12 ~3 cobblestone 0  
fill ~24 ~12 ~5 ~25 ~12 ~5 stone_stairs 2  
fill ~24 ~12 ~6 ~25 ~12 ~6 obsidian 0  
fill ~24 ~12 ~7 ~25 ~12 ~7 obsidian 0  
fill ~24 ~12 ~12 ~25 ~12 ~12 obsidian 0  
fill ~24 ~12 ~13 ~25 ~12 ~13 obsidian 0  
fill ~24 ~12 ~27 ~25 ~12 ~27 obsidian 0  
fill ~24 ~12 ~28 ~25 ~12 ~28 obsidian 0  
fill ~24 ~12 ~33 ~25 ~12 ~33 obsidian 0  
fill ~24 ~12 ~34 ~25 ~12 ~34 obsidian 0  
fill ~24 ~12 ~35 ~25 ~12 ~35 stone_stairs 3  
fill ~24 ~12 ~37 ~25 ~12 ~37 cobblestone 0 
setblock ~26 ~12 ~5 diamond_block 0  
fill ~26 ~12 ~6 ~29 ~12 ~6 cobblestone 0  
fill ~26 ~12 ~7 ~29 ~12 ~7 cobblestone 0 
setblock ~26 ~12 ~8 glowstone 0 
setblock ~26 ~12 ~11 glowstone 0  
fill ~26 ~12 ~12 ~29 ~12 ~12 cobblestone 0  
fill ~26 ~12 ~13 ~26 ~13 ~13 cobblestone 0  
fill ~26 ~12 ~27 ~26 ~13 ~27 cobblestone 0  
fill ~26 ~12 ~28 ~29 ~12 ~28 cobblestone 0 
setblock ~26 ~12 ~29 glowstone 0 
setblock ~26 ~12 ~32 glowstone 0  
fill ~26 ~12 ~33 ~29 ~12 ~33 cobblestone 0  
fill ~26 ~12 ~34 ~29 ~12 ~34 cobblestone 0 
setblock ~26 ~12 ~35 diamond_block 0  
fill ~27 ~12 ~4 ~27 ~15 ~4 glass_pane 0  
fill ~27 ~12 ~5 ~28 ~12 ~5 stone_stairs 2  
fill ~27 ~12 ~8 ~28 ~12 ~8 cobblestone 0  
fill ~27 ~12 ~9 ~28 ~12 ~9 obsidian 0  
fill ~27 ~12 ~10 ~28 ~12 ~10 obsidian 0  
fill ~27 ~12 ~11 ~28 ~12 ~11 cobblestone 0  
fill ~27 ~12 ~13 ~28 ~12 ~13 obsidian 0  
fill ~27 ~12 ~27 ~28 ~12 ~27 obsidian 0  
fill ~27 ~12 ~29 ~28 ~12 ~29 cobblestone 0  
fill ~27 ~12 ~30 ~28 ~12 ~30 obsidian 0  
fill ~27 ~12 ~31 ~28 ~12 ~31 obsidian 0  
fill ~27 ~12 ~32 ~28 ~12 ~32 cobblestone 0  
fill ~27 ~12 ~35 ~28 ~12 ~35 stone_stairs 3  
fill ~27 ~12 ~36 ~27 ~15 ~36 glass_pane 0  
fill ~28 ~12 ~4 ~28 ~17 ~4 cobblestone 0  
fill ~28 ~12 ~36 ~28 ~17 ~36 cobblestone 0 
setblock ~29 ~12 ~4 stone_slab 3 
setblock ~29 ~12 ~5 diamond_block 0 
setblock ~29 ~12 ~8 glowstone 0 
setblock ~29 ~12 ~11 glowstone 0  
fill ~29 ~12 ~13 ~29 ~13 ~13 cobblestone 0  
fill ~29 ~12 ~27 ~29 ~13 ~27 cobblestone 0 
setblock ~29 ~12 ~29 glowstone 0 
setblock ~29 ~12 ~32 glowstone 0 
setblock ~29 ~12 ~35 diamond_block 0  
fill ~30 ~12 ~5 ~32 ~12 ~5 stone_stairs 2  
fill ~30 ~12 ~6 ~30 ~12 ~7 obsidian 0  
fill ~30 ~12 ~12 ~30 ~12 ~13 obsidian 0  
fill ~30 ~12 ~27 ~30 ~12 ~28 obsidian 0  
fill ~30 ~12 ~33 ~30 ~12 ~34 obsidian 0  
fill ~30 ~12 ~35 ~32 ~12 ~35 stone_stairs 3  
fill ~31 ~12 ~4 ~31 ~15 ~4 glass_pane 0  
fill ~31 ~12 ~6 ~31 ~12 ~7 cobblestone 0  
fill ~31 ~12 ~12 ~31 ~12 ~13 cobblestone 0  
fill ~31 ~12 ~27 ~31 ~13 ~27 cobblestone 0  
fill ~31 ~12 ~28 ~31 ~12 ~27 cobblestone 0  
fill ~31 ~12 ~33 ~31 ~12 ~34 cobblestone 0  
fill ~31 ~12 ~36 ~31 ~15 ~36 glass_pane 0  
fill ~32 ~12 ~6 ~32 ~12 ~7 obsidian 0  
fill ~32 ~12 ~12 ~32 ~12 ~13 obsidian 0  
fill ~32 ~12 ~27 ~32 ~12 ~28 obsidian 0  
fill ~32 ~12 ~33 ~32 ~12 ~34 obsidian 0 
setblock ~33 ~12 ~4 stone_slab 3 
setblock ~33 ~12 ~5 diamond_block 0  
fill ~33 ~12 ~6 ~36 ~12 ~6 cobblestone 0  
fill ~33 ~12 ~7 ~36 ~12 ~7 cobblestone 0 
setblock ~33 ~12 ~8 glowstone 0 
setblock ~33 ~12 ~11 glowstone 0  
fill ~33 ~12 ~12 ~36 ~12 ~12 cobblestone 0  
fill ~33 ~12 ~13 ~33 ~13 ~13 cobblestone 0  
fill ~33 ~12 ~27 ~33 ~13 ~27 cobblestone 0  
