    
fill ~2 ~0 ~19 ~2 ~0 ~20 stone_brick_stairs  
fill ~2 ~0 ~36 ~2 ~0 ~37 stone_brick_stairs 
setblock ~3 ~0 ~7 stone_brick_stairs 0 
setblock ~3 ~0 ~9 stone_brick_stairs 0  
fill ~3 ~0 ~18 ~4 ~0 ~18 stone_brick_stairs  
fill ~3 ~0 ~19 ~4 ~0 ~19 stonebrick  
fill ~3 ~0 ~20 ~4 ~0 ~20 stonebrick 
setblock ~3 ~0 ~21 stone_brick_stairs 3  
fill ~3 ~0 ~22 ~3 ~2 ~22 cobblestone_wall  
fill ~3 ~0 ~24 ~3 ~2 ~24 cobblestone_wall  
fill ~3 ~0 ~26 ~3 ~2 ~26 cobblestone_wall  
fill ~3 ~0 ~28 ~3 ~2 ~28 cobblestone_wall  
fill ~3 ~0 ~30 ~3 ~2 ~30 cobblestone_wall  
fill ~3 ~0 ~32 ~3 ~2 ~32 cobblestone_wall  
fill ~3 ~0 ~34 ~3 ~2 ~34 cobblestone_wall 
setblock ~3 ~0 ~35 stone_brick_stairs 2  
fill ~3 ~0 ~36 ~4 ~0 ~36 stonebrick  
fill ~3 ~0 ~37 ~4 ~0 ~37 stonebrick  
fill ~3 ~0 ~38 ~4 ~0 ~38 stone_brick_stairs 
setblock ~4 ~0 ~6 stone_brick_stairs 2  
fill ~4 ~0 ~7 ~5 ~0 ~7 stonebrick 
setblock ~4 ~0 ~8 stone_brick_stairs 0  
fill ~4 ~0 ~9 ~5 ~0 ~9 stonebrick 
setblock ~4 ~0 ~10 stone_brick_stairs 3  
fill ~4 ~0 ~21 ~4 ~3 ~21 stone  
fill ~4 ~0 ~22 ~4 ~3 ~22 stone  
fill ~4 ~0 ~23 ~4 ~3 ~23 stone  
fill ~4 ~0 ~24 ~4 ~3 ~24 stone  
fill ~4 ~0 ~25 ~4 ~3 ~25 stone  
fill ~4 ~0 ~26 ~4 ~3 ~26 stone  
fill ~4 ~0 ~27 ~4 ~3 ~27 stone  
fill ~4 ~0 ~28 ~4 ~3 ~28 stone  
fill ~4 ~0 ~29 ~4 ~3 ~29 stone  
fill ~4 ~0 ~30 ~4 ~3 ~30 stone  
fill ~4 ~0 ~31 ~4 ~3 ~31 stone  
fill ~4 ~0 ~32 ~4 ~3 ~32 stone  
fill ~4 ~0 ~33 ~4 ~3 ~33 stone  
fill ~4 ~0 ~34 ~4 ~3 ~34 stone  
fill ~4 ~0 ~35 ~4 ~3 ~35 stone  
fill ~5 ~0 ~5 ~5 ~0 ~11 stonebrick 
setblock ~5 ~0 ~19 stonebrick 0  
fill ~5 ~0 ~20 ~8 ~0 ~20 stone  
fill ~5 ~0 ~36 ~13 ~0 ~36 stone 
setblock ~5 ~0 ~37 stone_brick_stairs 1  
fill ~6 ~0 ~4 ~12 ~0 ~4 stonebrick  
fill ~6 ~0 ~5 ~6 ~5 ~5 stonebrick  
fill ~6 ~0 ~6 ~6 ~20 ~6 stonebrick  
fill ~6 ~0 ~10 ~6 ~20 ~10 stonebrick  
fill ~6 ~0 ~11 ~6 ~5 ~11 stonebrick  
fill ~6 ~0 ~12 ~12 ~0 ~12 stonebrick  
fill ~6 ~0 ~19 ~6 ~2 ~19 cobblestone_wall  
fill ~6 ~0 ~37 ~6 ~2 ~37 cobblestone_wall 
setblock ~7 ~0 ~3 stone_brick_stairs 0  
fill ~7 ~0 ~5 ~7 ~20 ~5 stonebrick  
fill ~7 ~0 ~11 ~7 ~20 ~11 stonebrick 
setblock ~7 ~0 ~13 stone_brick_stairs 0  
fill ~7 ~0 ~14 ~7 ~0 ~18 stone_slab 
setblock ~7 ~0 ~19 stone_brick_stairs 0 
setblock ~8 ~0 ~2 stone_brick_stairs 2  
fill ~8 ~0 ~3 ~8 ~3 ~3 stonebrick  
fill ~8 ~0 ~13 ~8 ~0 ~19 stonebrick  
fill ~8 ~0 ~37 ~8 ~2 ~37 cobblestone_wall 
setblock ~9 ~0 ~3 stone_brick_stairs 2  
fill ~9 ~0 ~13 ~9 ~7 ~13 cobblestone  
fill ~9 ~0 ~14 ~9 ~4 ~14 cobblestone  
fill ~9 ~0 ~15 ~9 ~4 ~15 cobblestone  
fill ~9 ~0 ~16 ~9 ~3 ~16 cobblestone  
fill ~9 ~0 ~17 ~9 ~4 ~17 cobblestone  
fill ~9 ~0 ~18 ~9 ~4 ~18 cobblestone  
fill ~9 ~0 ~19 ~9 ~7 ~19 cobblestone  
fill ~9 ~0 ~20 ~9 ~8 ~20 cobblestone 
setblock ~10 ~0 ~2 stone_brick_stairs 2  
fill ~10 ~0 ~3 ~10 ~3 ~3 stonebrick  
fill ~10 ~0 ~13 ~10 ~0 ~19 stonebrick  
fill ~10 ~0 ~20 ~14 ~0 ~20 stone  
fill ~10 ~0 ~37 ~10 ~2 ~37 cobblestone_wall 
setblock ~11 ~0 ~3 stone_brick_stairs 1  
fill ~11 ~0 ~5 ~11 ~20 ~5 stonebrick  
fill ~11 ~0 ~11 ~11 ~20 ~11 stonebrick 
setblock ~11 ~0 ~13 stone_brick_stairs 1  
fill ~11 ~0 ~14 ~11 ~0 ~18 stone_slab 
setblock ~11 ~0 ~19 stone_brick_stairs 1  
fill ~12 ~0 ~5 ~12 ~5 ~5 stonebrick  
fill ~12 ~0 ~6 ~13 ~0 ~6 stonebrick  
fill ~12 ~0 ~8 ~24 ~0 ~8 stonebrick  
fill ~12 ~0 ~10 ~13 ~0 ~10 stonebrick  
fill ~12 ~0 ~11 ~12 ~5 ~11 stonebrick  
fill ~12 ~0 ~19 ~12 ~2 ~19 cobblestone_wall  
fill ~12 ~0 ~23 ~13 ~0 ~23 log  
fill ~12 ~0 ~37 ~12 ~2 ~37 cobblestone_wall 
setblock ~13 ~0 ~5 stonebrick 0  
fill ~13 ~0 ~7 ~14 ~0 ~7 stonebrick  
fill ~13 ~0 ~9 ~14 ~0 ~9 stonebrick 
setblock ~13 ~0 ~11 stonebrick 0 
setblock ~13 ~0 ~19 stone_brick_stairs 0  
fill ~13 ~0 ~24 ~13 ~1 ~24 log  
fill ~13 ~0 ~25 ~13 ~1 ~25 log 
setblock ~13 ~0 ~37 stone_brick_stairs 0 
setblock ~14 ~0 ~6 stone_brick_stairs 2 
setblock ~14 ~0 ~10 stone_brick_stairs 3  
fill ~14 ~0 ~18 ~15 ~0 ~18 stone_brick_stairs  
fill ~14 ~0 ~19 ~15 ~0 ~19 stonebrick  
fill ~14 ~0 ~21 ~14 ~3 ~21 stone  
fill ~14 ~0 ~22 ~14 ~3 ~22 stone 
setblock ~14 ~0 ~23 stone_brick_stairs 3 
setblock ~14 ~0 ~25 stone_brick_stairs 2  
fill ~14 ~0 ~26 ~14 ~3 ~26 stone  
fill ~14 ~0 ~27 ~14 ~3 ~27 stone  
fill ~14 ~0 ~28 ~14 ~3 ~28 stone  
fill ~14 ~0 ~29 ~14 ~3 ~29 stone  
fill ~14 ~0 ~30 ~14 ~3 ~30 stone  
fill ~14 ~0 ~31 ~14 ~2 ~31 stonebrick  
fill ~14 ~0 ~32 ~14 ~3 ~32 stone  
fill ~14 ~0 ~33 ~14 ~3 ~33 stone  
fill ~14 ~0 ~34 ~14 ~3 ~34 stone  
fill ~14 ~0 ~35 ~14 ~3 ~35 stone  
fill ~14 ~0 ~36 ~15 ~0 ~36 stonebrick  
fill ~14 ~0 ~37 ~15 ~0 ~37 stonebrick  
fill ~14 ~0 ~38 ~15 ~0 ~38 stone_brick_stairs 
setblock ~15 ~0 ~7 stone_brick_stairs 1 
setblock ~15 ~0 ~9 stone_brick_stairs 1  
fill ~15 ~0 ~20 ~15 ~2 ~20 stonebrick 
setblock ~15 ~0 ~21 stone_brick_stairs 3  
fill ~15 ~0 ~22 ~15 ~1 ~22 cobblestone_wall  
fill ~15 ~0 ~26 ~15 ~1 ~26 cobblestone_wall  
fill ~15 ~0 ~28 ~15 ~2 ~28 cobblestone_wall 
setblock ~15 ~0 ~29 stone_brick_stairs 2  
fill ~15 ~0 ~30 ~15 ~2 ~30 stonebrick  
fill ~15 ~0 ~31 ~35 ~0 ~31 stone  
fill ~15 ~0 ~34 ~15 ~2 ~34 cobblestone_wall 
setblock ~15 ~0 ~35 stone_brick_stairs 2  
fill ~16 ~0 ~7 ~16 ~3 ~7 log  
fill ~16 ~0 ~9 ~16 ~3 ~9 log  
fill ~16 ~0 ~19 ~16 ~0 ~20 stone_brick_stairs 
setblock ~16 ~0 ~30 stone_brick_stairs 1  
fill ~16 ~0 ~32 ~16 ~2 ~32 cobblestone_wall  
fill ~16 ~0 ~36 ~16 ~0 ~37 stone_brick_stairs  
fill ~17 ~0 ~7 ~18 ~0 ~7 stone_slab  
fill ~17 ~0 ~9 ~18 ~0 ~9 stone_slab  
fill ~17 ~0 ~30 ~17 ~2 ~30 cobblestone_wall  
fill ~18 ~0 ~32 ~18 ~2 ~32 cobblestone_wall  
fill ~19 ~0 ~7 ~19 ~3 ~7 log  
fill ~19 ~0 ~9 ~19 ~3 ~9 log  
fill ~19 ~0 ~30 ~19 ~2 ~30 cobblestone_wall  
fill ~20 ~0 ~7 ~21 ~0 ~7 stone_slab  
fill ~20 ~0 ~9 ~21 ~0 ~9 stone_slab  
fill ~20 ~0 ~32 ~20 ~2 ~32 cobblestone_wall  
fill ~21 ~0 ~30 ~21 ~2 ~30 cobblestone_wall  
fill ~22 ~0 ~7 ~22 ~3 ~7 log  
fill ~22 ~0 ~9 ~22 ~3 ~9 log  
fill ~22 ~0 ~32 ~22 ~2 ~32 cobblestone_wall 
setblock ~23 ~0 ~7 stone_slab 5 
setblock ~23 ~0 ~9 stone_slab 5  
fill ~23 ~0 ~30 ~23 ~2 ~30 cobblestone_wall 
setblock ~24 ~0 ~7 stone_brick_stairs 0 
setblock ~24 ~0 ~9 stone_brick_stairs 0  
fill ~24 ~0 ~16 ~24 ~0 ~17 stone_brick_stairs  
fill ~24 ~0 ~32 ~24 ~2 ~32 cobblestone_wall  
fill ~25 ~0 ~6 ~26 ~0 ~6 stone_brick_stairs  
fill ~25 ~0 ~7 ~26 ~0 ~7 stonebrick  
fill ~25 ~0 ~8 ~26 ~0 ~8 stonebrick 
setblock ~25 ~0 ~9 stone_brick_stairs 3  
fill ~25 ~0 ~10 ~25 ~3 ~10 cobblestone_wall  
fill ~25 ~0 ~14 ~25 ~3 ~14 cobblestone_wall 
setblock ~25 ~0 ~15 stone_brick_stairs 2  
fill ~25 ~0 ~16 ~26 ~0 ~16 stonebrick  
fill ~25 ~0 ~17 ~26 ~0 ~17 stonebrick  
fill ~25 ~0 ~18 ~26 ~0 ~18 stone_brick_stairs  
fill ~25 ~0 ~30 ~25 ~2 ~30 cobblestone_wall  
fill ~26 ~0 ~9 ~26 ~6 ~9 stonebrick  
fill ~26 ~0 ~10 ~26 ~5 ~10 stonebrick  
fill ~26 ~0 ~14 ~26 ~5 ~14 stonebrick  
fill ~26 ~0 ~15 ~26 ~6 ~15 stonebrick  
fill ~26 ~0 ~32 ~26 ~2 ~32 cobblestone_wall 
setblock ~27 ~0 ~7 stone_brick_stairs 1  
fill ~27 ~0 ~8 ~31 ~0 ~8 stonebrick  
fill ~27 ~0 ~9 ~27 ~3 ~9 stonebrick  
fill ~27 ~0 ~10 ~30 ~0 ~10 stone_slab  
fill ~27 ~0 ~14 ~30 ~0 ~14 stone_slab  
fill ~27 ~0 ~15 ~27 ~3 ~15 stonebrick  
fill ~27 ~0 ~16 ~31 ~0 ~16 stonebrick 
setblock ~27 ~0 ~17 stone_brick_stairs 1  
fill ~27 ~0 ~28 ~27 ~0 ~29 stone_brick_stairs  
fill ~27 ~0 ~30 ~27 ~2 ~30 cobblestone_wall  
fill ~27 ~0 ~35 ~27 ~0 ~36 stone_brick_stairs 
setblock ~28 ~0 ~7 stone_slab 13  
fill ~28 ~0 ~9 ~29 ~0 ~9 stonebrick  
fill ~28 ~0 ~15 ~29 ~0 ~15 stonebrick  
fill ~28 ~0 ~27 ~29 ~0 ~27 stone_brick_stairs  
fill ~28 ~0 ~28 ~29 ~0 ~28 stonebrick  
fill ~28 ~0 ~29 ~28 ~0 ~29 stonebrick 
setblock ~28 ~0 ~30 stone_brick_stairs 3  
fill ~28 ~0 ~33 ~28 ~2 ~33 cobblestone_wall 
setblock ~28 ~0 ~34 stone_brick_stairs 2  
fill ~28 ~0 ~35 ~28 ~0 ~36 stonebrick  
fill ~28 ~0 ~37 ~29 ~0 ~37 stone_brick_stairs 
setblock ~29 ~0 ~7 stone_brick_stairs 2  
fill ~29 ~0 ~12 ~30 ~0 ~12 stone_slab  
fill ~29 ~0 ~29 ~35 ~0 ~29 stone  
fill ~29 ~0 ~30 ~35 ~0 ~30 stone  
fill ~29 ~0 ~32 ~35 ~0 ~32 stone  
fill ~29 ~0 ~33 ~35 ~0 ~33 stone  
fill ~29 ~0 ~34 ~35 ~0 ~34 stone  
fill ~29 ~0 ~35 ~35 ~0 ~35 stone 
setblock ~29 ~0 ~36 stonebrick 0 
setblock ~30 ~0 ~7 stone_slab 13  
fill ~30 ~0 ~9 ~30 ~3 ~9 stonebrick 
setblock ~30 ~0 ~11 stone_slab 5 
setblock ~30 ~0 ~13 stone_slab 5  
fill ~30 ~0 ~15 ~30 ~3 ~15 stonebrick  
fill ~30 ~0 ~19 ~30 ~2 ~19 cobblestone_wall  
fill ~30 ~0 ~21 ~30 ~2 ~21 cobblestone_wall  
fill ~30 ~0 ~23 ~30 ~2 ~23 cobblestone_wall  
fill ~30 ~0 ~25 ~30 ~2 ~25 cobblestone_wall  
fill ~30 ~0 ~27 ~30 ~2 ~27 cobblestone_wall 
setblock ~30 ~0 ~28 stone_brick_stairs 1 
setblock ~30 ~0 ~36 stone_brick_stairs 1 
setblock ~31 ~0 ~7 stone_brick_stairs 0  
fill ~31 ~0 ~9 ~31 ~5 ~9 stonebrick  
fill ~31 ~0 ~10 ~31 ~5 ~10 stonebrick 
setblock ~31 ~0 ~11 stone_brick_stairs 0 
setblock ~31 ~0 ~12 stonebrick 0 
setblock ~31 ~0 ~13 stone_brick_stairs 0  
fill ~31 ~0 ~14 ~31 ~5 ~14 stonebrick  
fill ~31 ~0 ~15 ~31 ~5 ~15 stonebrick  
fill ~31 ~0 ~17 ~31 ~3 ~17 stone  
fill ~31 ~0 ~18 ~31 ~3 ~18 stone  
fill ~31 ~0 ~19 ~31 ~3 ~19 stone  
fill ~31 ~0 ~20 ~31 ~3 ~20 stone  
fill ~31 ~0 ~21 ~31 ~3 ~21 stone  
fill ~31 ~0 ~22 ~31 ~3 ~22 stone  
fill ~31 ~0 ~23 ~31 ~3 ~23 stone  
fill ~31 ~0 ~24 ~31 ~3 ~24 stone  
fill ~31 ~0 ~25 ~31 ~3 ~25 stone  
fill ~31 ~0 ~26 ~31 ~3 ~26 stone  
fill ~31 ~0 ~27 ~31 ~3 ~27 stone  
fill ~31 ~0 ~28 ~31 ~3 ~28 stone  
fill ~31 ~0 ~36 ~31 ~2 ~36 cobblestone_wall  
fill ~32 ~0 ~6 ~33 ~0 ~6 stone_brick_stairs  
fill ~32 ~0 ~7 ~33 ~0 ~7 stonebrick  
fill ~32 ~0 ~8 ~33 ~0 ~8 stonebrick  
fill ~32 ~0 ~9 ~33 ~0 ~9 stone_brick_stairs 
setblock ~32 ~0 ~10 stonebrick 3  
fill ~32 ~0 ~11 ~38 ~0 ~11 dropper  
fill ~32 ~0 ~12 ~38 ~0 ~12 dropper  
fill ~32 ~0 ~13 ~38 ~0 ~13 dropper 
setblock ~32 ~0 ~14 stonebrick 3  
fill ~32 ~0 ~15 ~33 ~0 ~15 stone_brick_stairs  
fill ~32 ~0 ~16 ~33 ~0 ~16 stonebrick  
fill ~32 ~0 ~17 ~33 ~0 ~17 stonebrick  
fill ~32 ~0 ~18 ~33 ~0 ~18 stone_brick_stairs  
fill ~32 ~0 ~19 ~32 ~2 ~19 cobblestone_wall  
fill ~32 ~0 ~21 ~32 ~2 ~21 cobblestone_wall  
fill ~32 ~0 ~23 ~32 ~2 ~23 cobblestone_wall  
fill ~32 ~0 ~25 ~32 ~2 ~25 cobblestone_wall 
setblock ~32 ~0 ~26 stone_brick_stairs 2  
fill ~32 ~0 ~27 ~32 ~2 ~27 stonebrick  
fill ~32 ~0 ~28 ~32 ~2 ~28 stonebrick  
fill ~33 ~0 ~10 ~38 ~0 ~10 dropper  
fill ~33 ~0 ~14 ~38 ~0 ~14 dropper  
fill ~33 ~0 ~27 ~33 ~0 ~28 stone_brick_stairs  
fill ~33 ~0 ~36 ~33 ~2 ~36 cobblestone_wall  
fill ~34 ~0 ~7 ~34 ~0 ~8 stone_brick_stairs  
fill ~34 ~0 ~9 ~39 ~0 ~9 dropper  
fill ~34 ~0 ~15 ~39 ~0 ~15 dropper  
fill ~34 ~0 ~16 ~34 ~0 ~17 stone_brick_stairs 
setblock ~34 ~0 ~28 stone_brick_stairs 0 
setblock ~34 ~0 ~36 stone_brick_stairs 0 
setblock ~35 ~0 ~8 stone_slab 5 
setblock ~35 ~0 ~16 stone_slab 5  
fill ~35 ~0 ~27 ~36 ~0 ~27 stone_brick_stairs  
fill ~35 ~0 ~28 ~36 ~0 ~28 stonebrick  
fill ~35 ~0 ~36 ~36 ~0 ~36 stonebrick  
fill ~35 ~0 ~37 ~36 ~0 ~37 stone_brick_stairs 
setblock ~36 ~0 ~8 double_stone_slab 5 
setblock ~36 ~0 ~16 double_stone_slab 5 
setblock ~36 ~0 ~29 stonebrick 0 
setblock ~36 ~0 ~30 stone_brick_stairs 3  
fill ~36 ~0 ~31 ~36 ~2 ~31 cobblestone_wall  
fill ~36 ~0 ~33 ~36 ~2 ~33 cobblestone_wall 
setblock ~36 ~0 ~34 stone_brick_stairs 2 
setblock ~36 ~0 ~35 stonebrick 0 
setblock ~37 ~0 ~8 stone_slab 5 
setblock ~37 ~0 ~16 stone_slab 5  
fill ~37 ~0 ~28 ~37 ~0 ~29 stone_brick_stairs  
fill ~37 ~0 ~35 ~37 ~0 ~36 stone_brick_stairs 
setblock ~38 ~0 ~8 double_stone_slab 5 
setblock ~38 ~0 ~16 double_stone_slab 5 
setblock ~39 ~0 ~8 stone_brick_stairs 0 
setblock ~39 ~0 ~16 stone_brick_stairs 0 
setblock ~40 ~0 ~8 stone_slab 5 
setblock ~40 ~0 ~16 stone_slab 5  
fill ~3 ~1 ~19 ~4 ~1 ~19 stonebrick  
fill ~3 ~1 ~20 ~4 ~1 ~20 stonebrick  
fill ~3 ~1 ~36 ~4 ~1 ~36 stonebrick  
fill ~3 ~1 ~37 ~4 ~1 ~37 stonebrick  
fill ~4 ~1 ~7 ~5 ~1 ~7 stonebrick  
fill ~4 ~1 ~9 ~5 ~1 ~9 stonebrick  
fill ~5 ~1 ~5 ~5 ~3 ~5 cobblestone_wall  
fill ~5 ~1 ~6 ~5 ~3 ~6 stonebrick 
setblock ~5 ~1 ~8 iron_bars 0  
fill ~5 ~1 ~10 ~5 ~3 ~10 stonebrick  
fill ~5 ~1 ~11 ~5 ~3 ~11 cobblestone_wall  
fill ~5 ~1 ~20 ~8 ~1 ~20 stone  
fill ~5 ~1 ~36 ~13 ~1 ~36 stone  
fill ~6 ~1 ~4 ~6 ~3 ~4 cobblestone_wall  
fill ~6 ~1 ~12 ~6 ~3 ~12 cobblestone_wall  
fill ~7 ~1 ~4 ~8 ~1 ~4 stonebrick  
fill ~7 ~1 ~12 ~8 ~1 ~12 stonebrick 
setblock ~7 ~1 ~13 stone_brick_stairs 4 
setblock ~7 ~1 ~19 stone_brick_stairs 4  
fill ~8 ~1 ~13 ~8 ~6 ~13 stonebrick 
setblock ~8 ~1 ~14 stone_slab 5  
fill ~8 ~1 ~16 ~8 ~2 ~16 cobblestone_wall 
setblock ~8 ~1 ~18 stone_slab 5  
fill ~8 ~1 ~19 ~8 ~6 ~19 stonebrick 
setblock ~9 ~1 ~4 iron_bars 0 
setblock ~9 ~1 ~12 iron_bars 0  
fill ~10 ~1 ~4 ~11 ~1 ~4 stonebrick  
fill ~10 ~1 ~12 ~11 ~1 ~12 stonebrick  
fill ~10 ~1 ~13 ~10 ~6 ~13 stonebrick 
setblock ~10 ~1 ~14 stone_slab 5  
fill ~10 ~1 ~16 ~10 ~2 ~16 cobblestone_wall 
setblock ~10 ~1 ~18 stone_slab 5  
fill ~10 ~1 ~19 ~10 ~6 ~19 stonebrick  
fill ~10 ~1 ~20 ~14 ~1 ~20 stone 
setblock ~11 ~1 ~13 stone_brick_stairs 5 
setblock ~11 ~1 ~19 stone_brick_stairs 5  
fill ~12 ~1 ~4 ~12 ~3 ~4 cobblestone_wall  
fill ~12 ~1 ~6 ~13 ~1 ~6 stonebrick  
fill ~12 ~1 ~8 ~16 ~1 ~8 stonebrick  
fill ~12 ~1 ~10 ~13 ~1 ~10 stonebrick  
fill ~12 ~1 ~12 ~12 ~3 ~12 cobblestone_wall  
fill ~13 ~1 ~5 ~13 ~3 ~5 cobblestone_wall  
fill ~13 ~1 ~7 ~14 ~1 ~7 stonebrick  
fill ~13 ~1 ~9 ~14 ~1 ~9 stonebrick  
fill ~13 ~1 ~11 ~13 ~3 ~11 cobblestone_wall 
setblock ~13 ~1 ~23 log 1  
fill ~14 ~1 ~19 ~15 ~1 ~19 stonebrick 
setblock ~14 ~1 ~23 stone_brick_stairs 7 
setblock ~14 ~1 ~25 stone_brick_stairs 6  
fill ~14 ~1 ~36 ~15 ~1 ~36 stonebrick  
fill ~14 ~1 ~37 ~15 ~1 ~37 stonebrick  
fill ~15 ~1 ~31 ~35 ~1 ~31 stone 
setblock ~17 ~1 ~8 stone_brick_stairs 1 
setblock ~18 ~1 ~8 stone_brick_stairs 0  
fill ~19 ~1 ~8 ~19 ~4 ~8 stonebrick 
setblock ~20 ~1 ~8 stone_brick_stairs 1 
setblock ~21 ~1 ~8 stone_brick_stairs 0  
fill ~22 ~1 ~8 ~22 ~4 ~8 stonebrick 
setblock ~23 ~1 ~8 stone_brick_stairs 1 
setblock ~24 ~1 ~8 stone_brick_stairs 0  
fill ~25 ~1 ~7 ~26 ~1 ~7 stonebrick  
fill ~25 ~1 ~8 ~26 ~1 ~8 stonebrick  
fill ~25 ~1 ~16 ~26 ~1 ~16 stonebrick  
fill ~25 ~1 ~17 ~26 ~1 ~17 stonebrick 
setblock ~27 ~1 ~7 stone_slab 5  
fill ~27 ~1 ~8 ~31 ~1 ~8 stonebrick  
fill ~27 ~1 ~16 ~31 ~1 ~16 stonebrick  
fill ~28 ~1 ~28 ~29 ~1 ~28 stonebrick  
fill ~28 ~1 ~29 ~28 ~2 ~29 stonebrick  
fill ~28 ~1 ~35 ~28 ~2 ~35 stonebrick  
fill ~28 ~1 ~36 ~29 ~1 ~36 stonebrick 
setblock ~29 ~1 ~7 stone_brick_stairs 6  
fill ~29 ~1 ~29 ~35 ~1 ~29 stone  
fill ~29 ~1 ~30 ~35 ~1 ~30 stone  
fill ~29 ~1 ~32 ~35 ~1 ~32 stone  
fill ~29 ~1 ~33 ~35 ~1 ~33 stone  
fill ~29 ~1 ~34 ~35 ~1 ~34 stone  
fill ~29 ~1 ~35 ~35 ~1 ~35 stone 
setblock ~31 ~1 ~7 stone_slab 5  
fill ~32 ~1 ~7 ~33 ~1 ~7 stonebrick  
fill ~32 ~1 ~8 ~33 ~1 ~8 stonebrick  
fill ~32 ~1 ~10 ~32 ~4 ~10 cobblestone_wall  
fill ~32 ~1 ~14 ~32 ~4 ~14 cobblestone_wall  
fill ~32 ~1 ~16 ~33 ~1 ~16 stonebrick  
fill ~32 ~1 ~17 ~33 ~1 ~17 stonebrick  
fill ~35 ~1 ~28 ~36 ~1 ~28 stonebrick  
fill ~35 ~1 ~36 ~36 ~1 ~36 stonebrick  
fill ~36 ~1 ~8 ~37 ~1 ~8 web  
fill ~36 ~1 ~16 ~37 ~1 ~16 web  
fill ~36 ~1 ~29 ~36 ~2 ~29 stonebrick  
fill ~36 ~1 ~35 ~36 ~2 ~35 stonebrick  
fill ~3 ~2 ~19 ~4 ~2 ~19 stonebrick  
fill ~3 ~2 ~20 ~4 ~2 ~20 stonebrick  
fill ~3 ~2 ~36 ~4 ~2 ~36 stonebrick  
fill ~3 ~2 ~37 ~4 ~2 ~37 stonebrick  
fill ~4 ~2 ~7 ~5 ~2 ~7 stonebrick 
setblock ~4 ~2 ~8 stone_brick_stairs 4  
fill ~4 ~2 ~9 ~5 ~2 ~9 stonebrick  
fill ~5 ~2 ~8 ~5 ~4 ~8 stonebrick  
fill ~5 ~2 ~20 ~8 ~2 ~20 stone  
fill ~5 ~2 ~36 ~13 ~2 ~36 stone  
fill ~7 ~2 ~4 ~11 ~2 ~4 stonebrick  
fill ~7 ~2 ~12 ~11 ~2 ~12 stonebrick 
setblock ~9 ~2 ~3 stone_brick_stairs 6  
fill ~10 ~2 ~20 ~14 ~2 ~20 stone  
fill ~12 ~2 ~6 ~13 ~2 ~6 stonebrick  
fill ~12 ~2 ~8 ~24 ~2 ~8 stonebrick  
fill ~12 ~2 ~10 ~13 ~2 ~10 stonebrick  
fill ~13 ~2 ~7 ~14 ~2 ~7 stonebrick  
fill ~13 ~2 ~9 ~14 ~2 ~9 stonebrick  
fill ~14 ~2 ~19 ~15 ~2 ~19 stonebrick  
fill ~14 ~2 ~23 ~14 ~3 ~23 stone  
fill ~14 ~2 ~24 ~14 ~3 ~24 stone  
fill ~14 ~2 ~25 ~14 ~3 ~25 stone  
fill ~14 ~2 ~36 ~15 ~2 ~36 stonebrick  
fill ~14 ~2 ~37 ~15 ~2 ~37 stonebrick 
setblock ~15 ~2 ~22 stone_brick_stairs 3 
setblock ~15 ~2 ~26 stone_brick_stairs 2  
fill ~15 ~2 ~31 ~35 ~2 ~31 stone  
fill ~25 ~2 ~7 ~26 ~2 ~7 stonebrick  
fill ~25 ~2 ~8 ~26 ~2 ~8 stonebrick  
fill ~25 ~2 ~16 ~26 ~2 ~16 stonebrick  
fill ~25 ~2 ~17 ~26 ~2 ~17 stonebrick  
fill ~27 ~2 ~8 ~27 ~4 ~8 stone_brick_stairs  
fill ~27 ~2 ~16 ~31 ~2 ~16 stonebrick  
fill ~28 ~2 ~8 ~30 ~2 ~8 stonebrick  
fill ~28 ~2 ~28 ~29 ~2 ~28 stonebrick  
fill ~28 ~2 ~36 ~29 ~2 ~36 stonebrick  
fill ~29 ~2 ~7 ~29 ~4 ~7 cobblestone_wall  
fill ~29 ~2 ~29 ~35 ~2 ~29 stone  
fill ~29 ~2 ~30 ~35 ~2 ~30 stone  
fill ~29 ~2 ~32 ~35 ~2 ~32 stone  
fill ~29 ~2 ~33 ~35 ~2 ~33 stone  
fill ~29 ~2 ~34 ~35 ~2 ~34 stone  
fill ~29 ~2 ~35 ~35 ~2 ~35 stone  
fill ~30 ~2 ~12 ~30 ~5 ~12 fence  
fill ~31 ~2 ~8 ~31 ~4 ~8 stone_brick_stairs  
fill ~32 ~2 ~7 ~33 ~2 ~7 stonebrick  
fill ~32 ~2 ~8 ~33 ~2 ~8 stonebrick  
fill ~32 ~2 ~16 ~33 ~2 ~16 stonebrick  
fill ~32 ~2 ~17 ~33 ~2 ~17 stonebrick  
fill ~35 ~2 ~8 ~36 ~2 ~8 web  
fill ~35 ~2 ~16 ~36 ~2 ~16 web  
fill ~35 ~2 ~28 ~36 ~2 ~28 stonebrick  
fill ~35 ~2 ~36 ~36 ~2 ~36 stonebrick  
fill ~2 ~3 ~19 ~2 ~3 ~20 stone_brick_stairs  
fill ~2 ~3 ~36 ~2 ~3 ~37 stone_brick_stairs 
setblock ~3 ~3 ~7 stone_button 2 
setblock ~3 ~3 ~9 stone_button 2  
fill ~3 ~3 ~18 ~4 ~3 ~18 stone_brick_stairs  
fill ~3 ~3 ~19 ~4 ~3 ~19 stonebrick  
fill ~3 ~3 ~20 ~3 ~3 ~19 stonebrick 
setblock ~3 ~3 ~21 stone_brick_stairs 7 
setblock ~3 ~3 ~22 double_stone_slab 5 
setblock ~3 ~3 ~23 stone_slab 13 
setblock ~3 ~3 ~24 double_stone_slab 5 
setblock ~3 ~3 ~25 stone_slab 13 
setblock ~3 ~3 ~26 double_stone_slab 5 
setblock ~3 ~3 ~27 stone_slab 13 
setblock ~3 ~3 ~28 double_stone_slab 5 
setblock ~3 ~3 ~29 stone_slab 13 
setblock ~3 ~3 ~30 double_stone_slab 5 
setblock ~3 ~3 ~31 stone_slab 13 
setblock ~3 ~3 ~32 double_stone_slab 5 
setblock ~3 ~3 ~33 stone_slab 13 
setblock ~3 ~3 ~34 double_stone_slab 5 
setblock ~3 ~3 ~35 stone_brick_stairs 6  
fill ~3 ~3 ~36 ~3 ~3 ~37 stonebrick  
fill ~3 ~3 ~38 ~4 ~3 ~38 stone_brick_stairs  
fill ~4 ~3 ~7 ~5 ~3 ~7 stonebrick 
setblock ~4 ~3 ~8 stone_brick_stairs 0  
fill ~4 ~3 ~9 ~5 ~3 ~9 stonebrick  
fill ~4 ~3 ~20 ~8 ~3 ~20 stone  
fill ~4 ~3 ~36 ~14 ~3 ~36 stone 
setblock ~4 ~3 ~37 stonebrick 0 
setblock ~5 ~3 ~19 stone_brick_stairs 5  
fill ~5 ~3 ~21 ~14 ~3 ~21 stone  
fill ~5 ~3 ~22 ~14 ~3 ~22 stone  
fill ~5 ~3 ~23 ~14 ~3 ~23 stone  
fill ~5 ~3 ~24 ~10 ~3 ~24 stone  
fill ~5 ~3 ~25 ~14 ~3 ~25 stone  
fill ~5 ~3 ~26 ~14 ~3 ~26 stone  
fill ~5 ~3 ~27 ~14 ~3 ~27 stone  
fill ~5 ~3 ~28 ~14 ~3 ~28 stone  
fill ~5 ~3 ~29 ~14 ~3 ~29 stone  
fill ~5 ~3 ~30 ~14 ~3 ~30 stone  
fill ~5 ~3 ~31 ~29 ~3 ~31 stone  
fill ~5 ~3 ~32 ~14 ~3 ~32 stone  
fill ~5 ~3 ~33 ~14 ~3 ~33 stone  
fill ~5 ~3 ~34 ~14 ~3 ~34 stone  
fill ~5 ~3 ~35 ~14 ~3 ~35 stone 
setblock ~5 ~3 ~37 stone_brick_stairs 5 
setblock ~6 ~3 ~19 double_stone_slab 5 
setblock ~6 ~3 ~37 double_stone_slab 5  
fill ~7 ~3 ~4 ~11 ~3 ~4 stonebrick  
fill ~7 ~3 ~12 ~11 ~3 ~12 stonebrick 
setblock ~7 ~3 ~19 stone_slab 13 
setblock ~7 ~3 ~37 stone_slab 13 
setblock ~8 ~3 ~2 stone_button 4 
setblock ~8 ~3 ~16 stonebrick 0 
setblock ~8 ~3 ~37 double_stone_slab 5 
setblock ~9 ~3 ~3 stone_brick_stairs 2 
setblock ~9 ~3 ~37 stone_slab 13 
setblock ~10 ~3 ~16 stonebrick 0  
fill ~10 ~3 ~20 ~14 ~3 ~20 stone 
setblock ~10 ~3 ~37 double_stone_slab 5 
setblock ~11 ~3 ~19 stone_slab 13 
setblock ~11 ~3 ~37 stone_slab 13  
fill ~12 ~3 ~6 ~13 ~3 ~6 stonebrick  
fill ~12 ~3 ~8 ~24 ~3 ~8 stonebrick  
fill ~12 ~3 ~10 ~13 ~3 ~10 stonebrick 
setblock ~12 ~3 ~19 double_stone_slab 5  
fill ~12 ~3 ~24 ~14 ~3 ~24 stone 
setblock ~12 ~3 ~37 double_stone_slab 5  
fill ~13 ~3 ~7 ~14 ~3 ~7 stonebrick  
fill ~13 ~3 ~9 ~14 ~3 ~9 stonebrick 
setblock ~13 ~3 ~19 stone_brick_stairs 4 
setblock ~13 ~3 ~37 stone_brick_stairs 4  
fill ~14 ~3 ~18 ~15 ~3 ~18 stone_brick_stairs  
fill ~14 ~3 ~19 ~15 ~3 ~19 stonebrick  
fill ~14 ~3 ~37 ~15 ~3 ~37 stonebrick  
fill ~14 ~3 ~38 ~15 ~3 ~38 stone_brick_stairs 
setblock ~15 ~3 ~7 oak_stairs 4 
setblock ~15 ~3 ~9 oak_stairs 4 
setblock ~15 ~3 ~20 stonebrick 0 
setblock ~15 ~3 ~21 stone_brick_stairs 7 
setblock ~15 ~3 ~22 double_stone_slab 5 
setblock ~15 ~3 ~23 stone_slab 13 
setblock ~15 ~3 ~24 double_stone_slab 5 
setblock ~15 ~3 ~25 stone_slab 13 
setblock ~15 ~3 ~26 double_stone_slab 5 
setblock ~15 ~3 ~27 stone_slab 13 
setblock ~15 ~3 ~28 double_stone_slab 5 
setblock ~15 ~3 ~29 stone_brick_stairs 6 
setblock ~15 ~3 ~30 stonebrick 0  
fill ~15 ~3 ~32 ~15 ~3 ~33 stone_slab 
setblock ~15 ~3 ~34 double_stone_slab 5 
setblock ~15 ~3 ~35 stone_brick_stairs 6 
setblock ~15 ~3 ~36 stonebrick 0 
setblock ~16 ~3 ~6 oak_stairs 6 
setblock ~16 ~3 ~10 oak_stairs 7  
fill ~16 ~3 ~19 ~16 ~3 ~20 stone_brick_stairs 
setblock ~16 ~3 ~30 stone_brick_stairs 5 
setblock ~16 ~3 ~32 double_stone_slab 5  
fill ~16 ~3 ~36 ~16 ~3 ~37 stone_brick_stairs 
setblock ~17 ~3 ~7 oak_stairs 5 
setblock ~17 ~3 ~9 oak_stairs 5 
setblock ~17 ~3 ~30 double_stone_slab 5 
setblock ~17 ~3 ~32 stone_slab 13 
setblock ~18 ~3 ~7 oak_stairs 4 
setblock ~18 ~3 ~9 oak_stairs 4 
setblock ~18 ~3 ~30 stone_slab 13 
setblock ~18 ~3 ~32 double_stone_slab 5 
setblock ~19 ~3 ~6 oak_stairs 6 
setblock ~19 ~3 ~10 oak_stairs 7 
setblock ~19 ~3 ~30 double_stone_slab 5 
setblock ~19 ~3 ~32 stone_slab 13 
setblock ~20 ~3 ~7 oak_stairs 5 
setblock ~20 ~3 ~9 oak_stairs 5 
setblock ~20 ~3 ~30 stone_slab 13 
setblock ~20 ~3 ~32 double_stone_slab 5 
setblock ~21 ~3 ~7 oak_stairs 4 
setblock ~21 ~3 ~9 oak_stairs 4 
setblock ~21 ~3 ~30 double_stone_slab 5 
setblock ~21 ~3 ~32 stone_slab 13 
setblock ~22 ~3 ~6 oak_stairs 6 
setblock ~22 ~3 ~10 oak_stairs 7 
setblock ~22 ~3 ~30 stone_slab 13 
setblock ~22 ~3 ~32 double_stone_slab 5 
setblock ~23 ~3 ~7 oak_stairs 5 
setblock ~23 ~3 ~9 oak_stairs 5 
setblock ~23 ~3 ~30 double_stone_slab 5 
setblock ~23 ~3 ~32 stone_slab 13 
setblock ~24 ~3 ~7 oak_stairs 4 
setblock ~24 ~3 ~9 oak_stairs 4 
setblock ~24 ~3 ~30 stone_slab 13 
setblock ~24 ~3 ~32 double_stone_slab 5  
fill ~25 ~3 ~7 ~26 ~3 ~7 stonebrick  
fill ~25 ~3 ~8 ~26 ~3 ~8 stonebrick  
fill ~25 ~3 ~16 ~26 ~3 ~16 stonebrick  
fill ~25 ~3 ~17 ~26 ~3 ~17 stonebrick 
setblock ~25 ~3 ~30 double_stone_slab 5 
setblock ~25 ~3 ~32 stone_slab 13 
setblock ~26 ~3 ~11 stone_brick_stairs 7 
setblock ~26 ~3 ~13 stone_brick_stairs 6 
setblock ~26 ~3 ~30 stone_slab 13 
setblock ~26 ~3 ~32 double_stone_slab 5 
setblock ~27 ~3 ~10 torch 3 
setblock ~27 ~3 ~14 torch 4  
fill ~27 ~3 ~16 ~31 ~3 ~16 stonebrick  
fill ~27 ~3 ~28 ~27 ~3 ~29 stone_brick_stairs 
setblock ~27 ~3 ~30 double_stone_slab 5  
fill ~27 ~3 ~32 ~28 ~3 ~32 stone_slab  
fill ~27 ~3 ~35 ~27 ~3 ~36 stone_brick_stairs 
setblock ~28 ~3 ~7 cobblestone_wall 0  
fill ~28 ~3 ~8 ~30 ~3 ~8 stonebrick 
setblock ~28 ~3 ~9 stone_brick_stairs 5  
fill ~28 ~3 ~15 ~29 ~3 ~15 stone_brick_stairs  
fill ~28 ~3 ~27 ~29 ~3 ~27 stone_brick_stairs  
fill ~28 ~3 ~28 ~29 ~3 ~28 stonebrick  
fill ~28 ~3 ~29 ~28 ~3 ~28 stonebrick 
setblock ~28 ~3 ~30 stone_brick_stairs 7 
setblock ~28 ~3 ~33 double_stone_slab 5 
setblock ~28 ~3 ~34 stone_slab 13  
fill ~28 ~3 ~35 ~28 ~3 ~36 stonebrick  
fill ~28 ~3 ~37 ~29 ~3 ~37 stone_brick_stairs 
setblock ~29 ~3 ~9 stone_brick_stairs 4  
fill ~29 ~3 ~29 ~35 ~3 ~29 stone  
fill ~29 ~3 ~30 ~29 ~0 ~30 stone  
fill ~29 ~3 ~32 ~29 ~0 ~32 stone  
fill ~29 ~3 ~33 ~29 ~0 ~33 stone  
fill ~29 ~3 ~34 ~29 ~0 ~34 stone  
fill ~29 ~3 ~35 ~35 ~3 ~35 stone 
setblock ~29 ~3 ~36 stonebrick 0 
setblock ~30 ~3 ~7 cobblestone_wall 0  
fill ~30 ~3 ~10 ~30 ~3 ~14 fence  
fill ~30 ~3 ~17 ~30 ~3 ~18 stone_slab 
setblock ~30 ~3 ~19 double_stone_slab 5 
setblock ~30 ~3 ~20 stone_slab 13 
setblock ~30 ~3 ~21 double_stone_slab 5 
setblock ~30 ~3 ~22 stone_slab 13 
setblock ~30 ~3 ~23 double_stone_slab 5 
setblock ~30 ~3 ~24 stone_slab 13 
setblock ~30 ~3 ~25 double_stone_slab 5 
setblock ~30 ~3 ~26 stone_slab 13  
fill ~30 ~3 ~27 ~30 ~3 ~28 double_stone_slab  
fill ~30 ~3 ~30 ~34 ~3 ~30 stonebrick  
fill ~30 ~3 ~31 ~30 ~6 ~31 stonebrick  
fill ~30 ~3 ~32 ~30 ~5 ~32 stonebrick  
fill ~30 ~3 ~33 ~30 ~6 ~33 stonebrick  
fill ~30 ~3 ~34 ~34 ~3 ~34 stonebrick 
setblock ~30 ~3 ~36 stone_brick_stairs 5  
fill ~31 ~3 ~31 ~33 ~3 ~31 stone_slab  
fill ~31 ~3 ~32 ~33 ~3 ~32 stone_slab  
fill ~31 ~3 ~33 ~33 ~3 ~33 stone_slab 
setblock ~31 ~3 ~36 double_stone_slab 5  
fill ~32 ~3 ~7 ~33 ~3 ~7 stonebrick  
fill ~32 ~3 ~8 ~33 ~3 ~8 stonebrick 
setblock ~32 ~3 ~9 torch 1 
setblock ~32 ~3 ~15 torch 1  
fill ~32 ~3 ~16 ~33 ~3 ~16 stonebrick  
fill ~32 ~3 ~17 ~33 ~3 ~17 stonebrick 
setblock ~32 ~3 ~18 stone_slab 13 
setblock ~32 ~3 ~19 double_stone_slab 5 
setblock ~32 ~3 ~20 stone_slab 13 
setblock ~32 ~3 ~21 double_stone_slab 5 
setblock ~32 ~3 ~22 stone_slab 13 
setblock ~32 ~3 ~23 double_stone_slab 5 
setblock ~32 ~3 ~24 stone_slab 13 
setblock ~32 ~3 ~25 double_stone_slab 5 
setblock ~32 ~3 ~26 stone_brick_stairs 6  
fill ~32 ~3 ~27 ~32 ~3 ~28 stonebrick 
setblock ~32 ~3 ~36 stone_slab 13  
fill ~33 ~3 ~27 ~33 ~3 ~28 stone_brick_stairs 
setblock ~33 ~3 ~36 double_stone_slab 5  
fill ~34 ~3 ~8 ~35 ~3 ~8 web  
fill ~34 ~3 ~16 ~35 ~3 ~16 web 
setblock ~34 ~3 ~28 stone_brick_stairs 4  
fill ~34 ~3 ~31 ~34 ~6 ~31 stonebrick  
fill ~34 ~3 ~32 ~34 ~5 ~32 stonebrick  
fill ~34 ~3 ~33 ~34 ~6 ~33 stonebrick 
setblock ~34 ~3 ~36 stone_brick_stairs 4  
fill ~35 ~3 ~27 ~36 ~3 ~27 stone_brick_stairs  
fill ~35 ~3 ~28 ~36 ~3 ~28 stonebrick  
fill ~35 ~3 ~30 ~35 ~3 ~35 stone  
fill ~35 ~3 ~36 ~36 ~3 ~36 stonebrick  
fill ~35 ~3 ~37 ~36 ~3 ~37 stone_brick_stairs 
setblock ~36 ~3 ~29 stonebrick 0 
setblock ~36 ~3 ~30 stone_brick_stairs 7 
setblock ~36 ~3 ~31 double_stone_slab 5 
setblock ~36 ~3 ~32 stone_slab 13 
setblock ~36 ~3 ~33 double_stone_slab 5 
setblock ~36 ~3 ~34 stone_brick_stairs 6 
setblock ~36 ~3 ~35 stonebrick 0  
fill ~37 ~3 ~28 ~37 ~3 ~29 stone_brick_stairs  
fill ~37 ~3 ~35 ~37 ~3 ~36 stone_brick_stairs 
setblock ~2 ~4 ~18 stone_slab 5  
fill ~2 ~4 ~19 ~2 ~4 ~25 stone_brick_stairs 
setblock ~2 ~4 ~27 stone_brick_stairs 3 
setblock ~2 ~4 ~28 stonebrick 0  
fill ~2 ~4 ~29 ~2 ~4 ~37 stone_brick_stairs 
setblock ~2 ~4 ~38 stone_slab 5  
fill ~3 ~4 ~18 ~7 ~4 ~18 stone_brick_stairs  
fill ~3 ~4 ~37 ~3 ~6 ~37 cobblestone_wall  
fill ~3 ~4 ~38 ~8 ~4 ~38 stone_brick_stairs 
setblock ~4 ~4 ~7 stone_brick_stairs 0 
setblock ~4 ~4 ~9 stone_brick_stairs 0  
fill ~4 ~4 ~20 ~4 ~6 ~20 cobblestone  
fill ~4 ~4 ~24 ~4 ~6 ~24 cobblestone  
fill ~4 ~4 ~28 ~4 ~6 ~28 cobblestone 
setblock ~4 ~4 ~29 stone_slab 13 
setblock ~4 ~4 ~30 cobblestone_wall 0 
setblock ~4 ~4 ~31 stone_slab 13  
fill ~4 ~4 ~32 ~4 ~6 ~32 cobblestone 
setblock ~4 ~4 ~33 stone_stairs 2 
setblock ~4 ~4 ~34 stone_stairs 7 
setblock ~5 ~4 ~5 stone_brick_stairs 2 
setblock ~5 ~4 ~6 stone_brick_stairs 0  
fill ~5 ~4 ~7 ~5 ~5 ~7 stonebrick  
fill ~5 ~4 ~9 ~5 ~5 ~9 stonebrick 
setblock ~5 ~4 ~10 stone_brick_stairs 0 
setblock ~5 ~4 ~11 stone_brick_stairs 3  
fill ~5 ~4 ~21 ~10 ~4 ~21 planks 
setblock ~5 ~4 ~22 dark_oak_door 0  
fill ~5 ~4 ~23 ~5 ~5 ~23 planks  
fill ~5 ~4 ~24 ~5 ~5 ~24 planks  
fill ~5 ~4 ~25 ~5 ~4 ~23 planks 
setblock ~5 ~4 ~26 oak_stairs 0  
fill ~5 ~4 ~27 ~5 ~4 ~30 planks  
fill ~5 ~4 ~31 ~5 ~5 ~31 log 
setblock ~6 ~4 ~4 stone_brick_stairs 0 
setblock ~6 ~4 ~12 stone_brick_stairs 0  
fill ~6 ~4 ~20 ~7 ~4 ~20 stone_slab 
setblock ~6 ~4 ~31 oak_stairs 1 
setblock ~7 ~4 ~4 stone_brick_stairs 2 
setblock ~7 ~4 ~12 stone_brick_stairs 3 
setblock ~8 ~4 ~3 stone_brick_stairs 2  
fill ~8 ~4 ~4 ~10 ~4 ~4 stonebrick  
fill ~8 ~4 ~12 ~10 ~4 ~12 stonebrick 
setblock ~8 ~4 ~14 stone_brick_stairs 7 
setblock ~8 ~4 ~15 stone_brick_stairs 6  
fill ~8 ~4 ~16 ~8 ~5 ~16 stone_slab 
setblock ~8 ~4 ~17 stone_brick_stairs 7 
setblock ~8 ~4 ~18 stone_brick_stairs 6  
fill ~8 ~4 ~20 ~8 ~6 ~20 stonebrick 
setblock ~8 ~4 ~31 oak_stairs 0 
setblock ~9 ~4 ~16 stonebrick 3  
fill ~9 ~4 ~31 ~13 ~4 ~31 planks  
fill ~9 ~4 ~32 ~9 ~6 ~32 log 
setblock ~9 ~4 ~33 stone_stairs 2 
setblock ~9 ~4 ~34 stone_stairs 7 
setblock ~9 ~4 ~38 stonebrick 0 
setblock ~10 ~4 ~3 stone_brick_stairs 2 
setblock ~10 ~4 ~14 stone_brick_stairs 7 
setblock ~10 ~4 ~15 stone_brick_stairs 6  
fill ~10 ~4 ~16 ~10 ~5 ~16 stone_slab 
setblock ~10 ~4 ~17 stone_brick_stairs 7 
setblock ~10 ~4 ~18 stonebrick 0  
fill ~10 ~4 ~20 ~10 ~6 ~20 stonebrick 
setblock ~10 ~4 ~32 stone_stairs 0  
fill ~10 ~4 ~38 ~15 ~4 ~38 stone_brick_stairs 
setblock ~11 ~4 ~4 stone_brick_stairs 2 
setblock ~11 ~4 ~12 stone_brick_stairs 3  
fill ~11 ~4 ~18 ~15 ~4 ~18 stone_brick_stairs 
setblock ~11 ~4 ~21 oak_stairs 1  
fill ~11 ~4 ~22 ~12 ~4 ~22 log 
setblock ~11 ~4 ~32 stone_stairs 1 
setblock ~12 ~4 ~4 stone_brick_stairs 1  
fill ~12 ~4 ~6 ~12 ~20 ~6 stonebrick  
fill ~12 ~4 ~8 ~24 ~4 ~8 stonebrick  
fill ~12 ~4 ~10 ~12 ~20 ~10 stonebrick 
setblock ~12 ~4 ~12 stone_brick_stairs 1 
setblock ~12 ~4 ~21 oak_stairs 0 
setblock ~12 ~4 ~32 stone_stairs 0 
setblock ~13 ~4 ~5 stone_brick_stairs 2 
setblock ~13 ~4 ~6 stone_brick_stairs 1  
fill ~13 ~4 ~7 ~24 ~4 ~7 wool  
fill ~13 ~4 ~9 ~13 ~5 ~9 stonebrick 
setblock ~13 ~4 ~10 stone_brick_stairs 1 
setblock ~13 ~4 ~11 stone_brick_stairs 3  
fill ~13 ~4 ~20 ~13 ~5 ~20 fence  
fill ~13 ~4 ~21 ~13 ~5 ~21 planks 
setblock ~13 ~4 ~22 dropper 0  
fill ~13 ~4 ~23 ~13 ~5 ~23 planks  
fill ~13 ~4 ~24 ~13 ~5 ~24 planks  
fill ~13 ~4 ~25 ~13 ~5 ~25 planks  
fill ~13 ~4 ~26 ~13 ~5 ~26 planks  
fill ~13 ~4 ~27 ~13 ~5 ~27 planks  
fill ~13 ~4 ~28 ~13 ~5 ~28 planks  
fill ~13 ~4 ~29 ~13 ~5 ~29 planks 
setblock ~13 ~4 ~30 spruce_door 2 
setblock ~13 ~4 ~32 stone_stairs 1  
fill ~14 ~4 ~6 ~15 ~4 ~6 stone_slab  
fill ~14 ~4 ~9 ~24 ~4 ~9 wool  
fill ~14 ~4 ~10 ~15 ~4 ~10 stone_slab  
fill ~14 ~4 ~20 ~14 ~6 ~20 cobblestone  
fill ~14 ~4 ~21 ~14 ~5 ~21 fence  
fill ~14 ~4 ~23 ~14 ~5 ~23 fence  
fill ~14 ~4 ~24 ~14 ~6 ~24 cobblestone  
fill ~14 ~4 ~25 ~14 ~4 ~27 grass  
fill ~14 ~4 ~28 ~14 ~7 ~28 cobblestone  
fill ~14 ~4 ~31 ~29 ~4 ~31 stone  
fill ~14 ~4 ~32 ~14 ~7 ~32 cobblestone 
setblock ~14 ~4 ~33 stone_stairs 2 
setblock ~14 ~4 ~34 stone_stairs 7  
fill ~15 ~4 ~25 ~15 ~4 ~27 trapdoor  
fill ~15 ~4 ~37 ~15 ~6 ~37 cobblestone_wall 
setblock ~16 ~4 ~6 double_stone_slab 5 
setblock ~16 ~4 ~10 double_stone_slab 5  
fill ~16 ~4 ~19 ~16 ~4 ~28 stone_brick_stairs 
setblock ~16 ~4 ~29 stonebrick 0 
setblock ~16 ~4 ~33 stonebrick 0  
fill ~16 ~4 ~34 ~16 ~4 ~37 stone_brick_stairs 
setblock ~16 ~4 ~38 stone_slab 5  
fill ~17 ~4 ~6 ~18 ~4 ~6 stone_slab  
fill ~17 ~4 ~10 ~18 ~4 ~10 stone_slab  
fill ~17 ~4 ~29 ~20 ~4 ~29 stone_brick_stairs  
fill ~17 ~4 ~30 ~17 ~7 ~30 stonebrick  
fill ~17 ~4 ~32 ~17 ~7 ~32 stonebrick  
fill ~17 ~4 ~33 ~20 ~4 ~33 stone_brick_stairs 
setblock ~19 ~4 ~6 double_stone_slab 5 
setblock ~19 ~4 ~10 double_stone_slab 5  
fill ~20 ~4 ~6 ~21 ~4 ~6 stone_slab  
fill ~20 ~4 ~10 ~21 ~4 ~10 stone_slab  
fill ~21 ~4 ~29 ~21 ~4 ~30 stonebrick  
fill ~21 ~4 ~32 ~21 ~7 ~32 stonebrick  
fill ~21 ~4 ~33 ~21 ~4 ~32 stonebrick 
setblock ~22 ~4 ~6 double_stone_slab 5 
setblock ~22 ~4 ~10 double_stone_slab 5  
fill ~22 ~4 ~29 ~25 ~4 ~29 stone_brick_stairs  
fill ~22 ~4 ~33 ~26 ~4 ~33 stone_brick_stairs  
fill ~23 ~4 ~6 ~24 ~4 ~6 stone_slab  
fill ~23 ~4 ~10 ~24 ~4 ~10 stone_slab  
fill ~25 ~4 ~7 ~26 ~4 ~7 stonebrick  
fill ~25 ~4 ~8 ~26 ~4 ~8 stonebrick 
setblock ~25 ~4 ~10 stone_brick_stairs 2 
setblock ~25 ~4 ~12 stone_slab 13 
setblock ~25 ~4 ~14 stone_brick_stairs 3  
fill ~25 ~4 ~16 ~26 ~4 ~16 stonebrick  
fill ~25 ~4 ~17 ~26 ~4 ~17 stonebrick  
fill ~25 ~4 ~30 ~25 ~7 ~30 stonebrick  
fill ~25 ~4 ~32 ~25 ~7 ~32 stonebrick  
fill ~26 ~4 ~11 ~26 ~5 ~11 stonebrick  
fill ~26 ~4 ~12 ~26 ~5 ~12 stonebrick  
fill ~26 ~4 ~13 ~26 ~5 ~13 stonebrick 
setblock ~26 ~4 ~29 stonebrick 0  

KittysCommands:   
fill ~27 ~4 ~9 ~31 ~4 ~9 stonebrick  
fill ~27 ~4 ~10 ~29 ~4 ~10 stone_brick_stairs  
fill ~27 ~4 ~14 ~29 ~4 ~14 stone_brick_stairs  
fill ~27 ~4 ~15 ~31 ~4 ~15 stonebrick  
fill ~27 ~4 ~16 ~31 ~4 ~16 stonebrick 
setblock ~27 ~4 ~27 stone_slab 5 
setblock ~27 ~4 ~28 stone_brick_stairs 3 
setblock ~27 ~4 ~29 stone_slab 5 
setblock ~27 ~4 ~33 stone_slab 5  
fill ~27 ~4 ~34 ~27 ~4 ~36 stone_brick_stairs 
setblock ~27 ~4 ~37 stone_slab 5 
setblock ~28 ~4 ~8 stone_brick_stairs 2 
setblock ~28 ~4 ~27 stone_brick_stairs 1  
fill ~28 ~4 ~37 ~31 ~4 ~37 stone_brick_stairs 
setblock ~29 ~4 ~8 stonebrick 0  
fill ~29 ~4 ~17 ~29 ~4 ~26 stone_brick_stairs 
setblock ~29 ~4 ~27 stonebrick 0  
fill ~29 ~4 ~29 ~29 ~17 ~29 log  
fill ~29 ~4 ~30 ~31 ~4 ~30 stonebrick  
fill ~29 ~4 ~32 ~29 ~8 ~32 stonebrick  
fill ~29 ~4 ~33 ~29 ~5 ~33 stonebrick  
fill ~29 ~4 ~35 ~29 ~17 ~35 log 
setblock ~30 ~4 ~8 stone_brick_stairs 2 
setblock ~30 ~4 ~10 stonebrick 0 
setblock ~30 ~4 ~11 fence 5 
setblock ~30 ~4 ~13 fence 5 
setblock ~30 ~4 ~14 stonebrick 0  
fill ~30 ~4 ~19 ~30 ~6 ~19 stonebrick  
fill ~30 ~4 ~22 ~30 ~6 ~22 stonebrick  
fill ~30 ~4 ~25 ~30 ~6 ~25 stonebrick  
fill ~30 ~4 ~28 ~30 ~6 ~28 stonebrick  
fill ~30 ~4 ~34 ~34 ~4 ~34 stonebrick 
setblock ~31 ~4 ~11 stone_brick_stairs 7 
setblock ~31 ~4 ~13 stone_brick_stairs 6  
fill ~31 ~4 ~17 ~31 ~7 ~17 stonebrick  
fill ~31 ~4 ~18 ~32 ~4 ~18 stonebrick  
fill ~31 ~4 ~19 ~31 ~7 ~19 stonebrick  
fill ~31 ~4 ~20 ~31 ~7 ~20 stonebrick  
fill ~31 ~4 ~21 ~31 ~4 ~30 stonebrick  
fill ~31 ~4 ~35 ~31 ~5 ~35 stonebrick  
fill ~32 ~4 ~7 ~33 ~4 ~7 stonebrick  
fill ~32 ~4 ~8 ~33 ~4 ~8 stonebrick 
setblock ~32 ~4 ~9 stone_brick_stairs 7 
setblock ~32 ~4 ~15 stone_brick_stairs 6  
fill ~32 ~4 ~16 ~33 ~4 ~16 stonebrick  
fill ~32 ~4 ~17 ~33 ~4 ~17 stonebrick  
fill ~32 ~4 ~19 ~32 ~6 ~19 stonebrick  
fill ~32 ~4 ~22 ~32 ~6 ~22 stonebrick  
fill ~32 ~4 ~25 ~32 ~6 ~25 stonebrick  
fill ~32 ~4 ~28 ~32 ~6 ~28 stonebrick 
setblock ~32 ~4 ~37 stonebrick 0 
setblock ~33 ~4 ~6 stone_brick_stairs 2  
fill ~33 ~4 ~18 ~33 ~4 ~26 stone_brick_stairs 
setblock ~33 ~4 ~27 stonebrick 0  
fill ~33 ~4 ~29 ~33 ~5 ~29 stonebrick  
fill ~33 ~4 ~30 ~34 ~4 ~30 stonebrick  
fill ~33 ~4 ~35 ~33 ~5 ~35 stonebrick  
fill ~33 ~4 ~37 ~36 ~4 ~37 stone_brick_stairs 
setblock ~34 ~4 ~8 stone_brick_stairs 1 
setblock ~34 ~4 ~16 stone_brick_stairs 1  
fill ~34 ~4 ~27 ~36 ~4 ~27 stone_brick_stairs  
fill ~35 ~4 ~29 ~35 ~17 ~29 log  
fill ~35 ~4 ~31 ~35 ~5 ~31 stonebrick  
fill ~35 ~4 ~33 ~35 ~5 ~33 stonebrick  
fill ~35 ~4 ~35 ~35 ~17 ~35 log 
setblock ~36 ~4 ~31 stone_brick_stairs 1 
setblock ~36 ~4 ~33 stone_brick_stairs 1 
setblock ~37 ~4 ~27 stone_slab 5  
fill ~37 ~4 ~28 ~37 ~4 ~31 stone_brick_stairs 
setblock ~37 ~4 ~32 stonebrick 0  
fill ~37 ~4 ~33 ~37 ~4 ~36 stone_brick_stairs 
setblock ~37 ~4 ~37 stone_slab 5 
setblock ~4 ~5 ~29 cobblestone_wall 0 
setblock ~4 ~5 ~30 stone_slab 5 
setblock ~4 ~5 ~31 cobblestone_wall 0 
setblock ~4 ~5 ~34 stone_stairs 2 
setblock ~4 ~5 ~35 stone_stairs 7 
setblock ~5 ~5 ~6 stone_slab 5 
setblock ~5 ~5 ~8 stone_slab 5 
setblock ~5 ~5 ~10 stone_slab 5  
fill ~5 ~5 ~21 ~5 ~4 ~21 planks 
setblock ~5 ~5 ~22 dark_oak_door 8  
fill ~5 ~5 ~25 ~5 ~5 ~27 oak_stairs  
fill ~5 ~5 ~28 ~5 ~5 ~30 planks  
fill ~6 ~5 ~8 ~6 ~8 ~8 stone  
fill ~6 ~5 ~20 ~7 ~5 ~20 flower_pot  
fill ~6 ~5 ~21 ~7 ~5 ~21 glass_pane 
setblock ~6 ~5 ~31 oak_stairs 5 
setblock ~7 ~5 ~4 stone_slab 5 
setblock ~7 ~5 ~12 stone_slab 5  
fill ~8 ~5 ~4 ~8 ~0 ~4 stonebrick  
fill ~8 ~5 ~12 ~8 ~6 ~12 stonebrick  
fill ~8 ~5 ~21 ~10 ~5 ~21 planks 
setblock ~8 ~5 ~31 oak_stairs 4 
setblock ~9 ~5 ~4 stone_slab 5  
fill ~9 ~5 ~5 ~9 ~8 ~5 stone  
fill ~9 ~5 ~11 ~9 ~8 ~11 stone 
setblock ~9 ~5 ~12 stone_slab 5  
fill ~9 ~5 ~14 ~9 ~7 ~14 stone  
fill ~9 ~5 ~15 ~9 ~7 ~15 stone  
fill ~9 ~5 ~16 ~9 ~7 ~16 stone  
fill ~9 ~5 ~17 ~9 ~7 ~17 stone  
fill ~9 ~5 ~18 ~9 ~7 ~18 stone  
fill ~9 ~5 ~31 ~13 ~5 ~31 planks 
setblock ~9 ~5 ~34 stone_stairs 2 
setblock ~9 ~5 ~35 stone_stairs 7 
setblock ~10 ~5 ~4 stonebrick 0 
setblock ~10 ~5 ~12 stonebrick 0 
setblock ~11 ~5 ~4 stone_slab 5 
setblock ~11 ~5 ~12 stone_slab 5  
fill ~11 ~5 ~21 ~12 ~5 ~21 fence  
fill ~11 ~5 ~22 ~12 ~5 ~22 log  
fill ~12 ~5 ~8 ~12 ~6 ~8 stonebrick 
setblock ~13 ~5 ~6 stone_slab 5  
fill ~13 ~5 ~7 ~13 ~6 ~7 wool 
setblock ~13 ~5 ~10 stone_slab 5 
setblock ~13 ~5 ~22 dropper 8 
setblock ~13 ~5 ~30 spruce_door 8  
fill ~14 ~5 ~7 ~15 ~5 ~7 glass_pane  
fill ~14 ~5 ~9 ~15 ~5 ~9 glass_pane  
fill ~14 ~5 ~25 ~14 ~5 ~27 flower_pot 
setblock ~14 ~5 ~29 torch 1  
fill ~14 ~5 ~31 ~18 ~5 ~31 stone 
setblock ~14 ~5 ~34 stone_stairs 2 
setblock ~14 ~5 ~35 stone_stairs 7  
fill ~16 ~5 ~6 ~16 ~6 ~6 cobblestone_wall  
fill ~16 ~5 ~7 ~16 ~6 ~7 wool  
fill ~16 ~5 ~9 ~16 ~6 ~9 wool  
fill ~16 ~5 ~10 ~16 ~6 ~10 cobblestone_wall  
fill ~17 ~5 ~7 ~18 ~5 ~7 glass_pane  
fill ~17 ~5 ~9 ~18 ~5 ~9 glass_pane  
fill ~19 ~5 ~6 ~19 ~6 ~6 cobblestone_wall  
fill ~19 ~5 ~7 ~19 ~6 ~7 wool  
fill ~19 ~5 ~9 ~19 ~6 ~9 wool  
fill ~19 ~5 ~10 ~19 ~6 ~10 cobblestone_wall  
fill ~19 ~5 ~31 ~19 ~6 ~31 iron_bars  
fill ~20 ~5 ~7 ~21 ~5 ~7 glass_pane  
fill ~20 ~5 ~9 ~21 ~5 ~9 glass_pane  
fill ~20 ~5 ~31 ~22 ~5 ~31 stone  
fill ~21 ~5 ~30 ~21 ~7 ~30 stonebrick  
fill ~22 ~5 ~6 ~22 ~6 ~6 cobblestone_wall  
fill ~22 ~5 ~7 ~22 ~6 ~7 wool  
fill ~22 ~5 ~9 ~22 ~6 ~9 wool  
fill ~22 ~5 ~10 ~22 ~6 ~10 cobblestone_wall  
fill ~23 ~5 ~7 ~24 ~5 ~7 glass_pane  
fill ~23 ~5 ~9 ~24 ~5 ~9 glass_pane  
fill ~23 ~5 ~31 ~23 ~6 ~31 iron_bars  
fill ~24 ~5 ~16 ~24 ~5 ~17 stone_brick_stairs  
fill ~24 ~5 ~31 ~26 ~5 ~31 stone  
fill ~25 ~5 ~6 ~26 ~5 ~6 stone_brick_stairs 
setblock ~25 ~5 ~7 wool 0 
setblock ~25 ~5 ~9 stone_brick_stairs 7 
setblock ~25 ~5 ~10 stone_brick_stairs 6  
fill ~25 ~5 ~11 ~25 ~6 ~11 stone_brick_stairs 
setblock ~25 ~5 ~12 stone_slab 5  
fill ~25 ~5 ~13 ~25 ~6 ~13 stone_brick_stairs 
setblock ~25 ~5 ~14 stone_brick_stairs 7 
setblock ~25 ~5 ~15 stone_brick_stairs 6  
fill ~25 ~5 ~16 ~26 ~5 ~16 stonebrick  
fill ~25 ~5 ~17 ~26 ~5 ~17 stonebrick  
fill ~25 ~5 ~18 ~26 ~5 ~18 stone_brick_stairs  
fill ~26 ~5 ~7 ~26 ~10 ~7 stonebrick  
fill ~26 ~5 ~8 ~26 ~10 ~8 stonebrick 
setblock ~27 ~5 ~7 stone_brick_stairs 5  
fill ~27 ~5 ~8 ~28 ~5 ~8 stonebrick  
fill ~27 ~5 ~9 ~31 ~5 ~9 stonebrick  
fill ~27 ~5 ~11 ~29 ~5 ~11 stone_brick_stairs  
fill ~27 ~5 ~13 ~29 ~5 ~13 stone_brick_stairs  
fill ~27 ~5 ~15 ~32 ~5 ~15 stonebrick  
fill ~27 ~5 ~16 ~31 ~5 ~16 stonebrick 
setblock ~27 ~5 ~17 stone_brick_stairs 5  
fill ~27 ~5 ~31 ~27 ~6 ~31 iron_bars  
fill ~28 ~5 ~31 ~29 ~5 ~31 stone 
setblock ~29 ~5 ~8 stone_brick_stairs 6  
fill ~29 ~5 ~30 ~34 ~5 ~30 stonebrick  
fill ~30 ~5 ~8 ~31 ~5 ~8 stonebrick  
fill ~30 ~5 ~11 ~31 ~5 ~11 stonebrick  
fill ~30 ~5 ~13 ~31 ~5 ~13 stonebrick  
fill ~30 ~5 ~34 ~34 ~5 ~34 stonebrick 
setblock ~31 ~5 ~7 stone_brick_stairs 4 
setblock ~31 ~5 ~12 stonebrick 0  
fill ~31 ~5 ~18 ~32 ~5 ~18 stonebrick 
setblock ~31 ~5 ~21 stone_brick_stairs 2  
fill ~31 ~5 ~22 ~31 ~7 ~22 stonebrick 
setblock ~31 ~5 ~23 stone_brick_stairs 3 
setblock ~31 ~5 ~24 stone_brick_stairs 2  
fill ~31 ~5 ~25 ~31 ~7 ~25 stonebrick 
setblock ~31 ~5 ~26 stone_brick_stairs 3  
fill ~31 ~5 ~27 ~31 ~7 ~27 stonebrick  
fill ~31 ~5 ~28 ~31 ~7 ~28 stonebrick  
fill ~31 ~5 ~29 ~31 ~7 ~29 stonebrick  
fill ~32 ~5 ~6 ~33 ~5 ~6 stone_brick_stairs  
fill ~32 ~5 ~7 ~33 ~5 ~7 stonebrick  
fill ~32 ~5 ~8 ~33 ~5 ~8 stonebrick  
fill ~32 ~5 ~9 ~32 ~5 ~10 double_stone_slab  
fill ~32 ~5 ~11 ~32 ~5 ~13 stone_slab 
setblock ~32 ~5 ~14 double_stone_slab 5  
fill ~32 ~5 ~16 ~33 ~5 ~16 stonebrick  
fill ~32 ~5 ~17 ~33 ~5 ~17 stonebrick 
setblock ~32 ~5 ~35 stone_slab 13 
setblock ~33 ~5 ~9 stone_brick_stairs 7 
setblock ~33 ~5 ~10 stone_slab 13 
setblock ~33 ~5 ~14 stone_slab 13 
setblock ~33 ~5 ~15 stone_brick_stairs 6 
setblock ~33 ~5 ~18 stone_brick_stairs 7  
fill ~34 ~5 ~7 ~34 ~5 ~8 stone_brick_stairs  
fill ~34 ~5 ~16 ~34 ~5 ~17 stone_brick_stairs 
setblock ~35 ~5 ~32 stone_slab 13 
setblock ~3 ~6 ~20 stone_stairs 4 
setblock ~3 ~6 ~24 stone_stairs 4 
setblock ~3 ~6 ~28 stone_stairs 4 
setblock ~3 ~6 ~32 stone_stairs 4 
setblock ~3 ~6 ~36 stone_slab 11 
setblock ~4 ~6 ~19 stone_stairs 6 
setblock ~4 ~6 ~21 stone_stairs 7 
setblock ~4 ~6 ~23 stone_stairs 6 
setblock ~4 ~6 ~25 stone_stairs 7 
setblock ~4 ~6 ~27 stone_stairs 6 
setblock ~4 ~6 ~29 stone_stairs 7 
setblock ~4 ~6 ~31 stone_stairs 6 
setblock ~4 ~6 ~33 stone_stairs 7  
fill ~4 ~6 ~34 ~4 ~6 ~35 stone_stairs 
setblock ~4 ~6 ~36 double_stone_slab 3 
setblock ~4 ~6 ~37 stone_slab 11 
setblock ~5 ~6 ~7 stone_brick_stairs 3 
setblock ~5 ~6 ~9 stone_brick_stairs 2 
setblock ~5 ~6 ~20 stone_stairs 5  
fill ~5 ~6 ~21 ~5 ~6 ~31 log  
fill ~5 ~6 ~32 ~5 ~6 ~33 stone_slab  
fill ~6 ~6 ~5 ~6 ~19 ~5 cobblestone_wall  
fill ~6 ~6 ~7 ~6 ~7 ~7 stone  
fill ~6 ~6 ~9 ~6 ~7 ~9 stone  
fill ~6 ~6 ~11 ~6 ~19 ~11 cobblestone_wall  
fill ~6 ~6 ~21 ~12 ~6 ~21 log  
fill ~6 ~6 ~31 ~12 ~6 ~31 log  
fill ~6 ~6 ~33 ~8 ~6 ~33 stone_slab 
setblock ~8 ~6 ~4 stone_brick_stairs 1  
fill ~8 ~6 ~5 ~8 ~7 ~5 stone  
fill ~8 ~6 ~11 ~8 ~7 ~11 stone 
setblock ~8 ~6 ~14 stone_brick_stairs 7 
setblock ~8 ~6 ~18 stone_brick_stairs 6  
fill ~9 ~6 ~12 ~9 ~7 ~12 cobblestone 
setblock ~9 ~6 ~33 stone_stairs 7  
fill ~9 ~6 ~34 ~9 ~6 ~35 stone_stairs 
setblock ~9 ~6 ~36 double_stone_slab 3 
setblock ~9 ~6 ~37 stone_slab 11 
setblock ~10 ~6 ~4 stone_brick_stairs 0  
fill ~10 ~6 ~5 ~10 ~7 ~5 stone  
fill ~10 ~6 ~11 ~10 ~7 ~11 stone 
setblock ~10 ~6 ~12 stone_brick_stairs 0 
setblock ~10 ~6 ~14 stone_brick_stairs 7 
setblock ~10 ~6 ~18 stone_brick_stairs 6  
fill ~10 ~6 ~33 ~13 ~6 ~33 stone_slab  
fill ~12 ~6 ~5 ~12 ~9 ~5 cobblestone_wall  
fill ~12 ~6 ~7 ~12 ~7 ~7 stone  
fill ~12 ~6 ~9 ~12 ~7 ~9 stone  
fill ~12 ~6 ~11 ~12 ~9 ~11 cobblestone_wall 
setblock ~12 ~6 ~30 stonebrick 0  
fill ~13 ~6 ~8 ~24 ~6 ~8 stonebrick 
setblock ~13 ~6 ~9 stone_brick_stairs 2 
setblock ~13 ~6 ~20 stone_stairs 4  
fill ~13 ~6 ~21 ~13 ~6 ~31 log  
fill ~14 ~6 ~6 ~15 ~6 ~6 dropper  
fill ~14 ~6 ~7 ~24 ~6 ~7 wool  
fill ~14 ~6 ~9 ~24 ~6 ~9 wool  
fill ~14 ~6 ~10 ~15 ~6 ~10 dropper 
setblock ~14 ~6 ~19 stone_stairs 6 
setblock ~14 ~6 ~21 stone_stairs 7 
setblock ~14 ~6 ~23 stone_stairs 6 
setblock ~14 ~6 ~25 stone_stairs 7 
setblock ~14 ~6 ~27 stone_stairs 6 
setblock ~14 ~6 ~29 stone_stairs 7 
setblock ~14 ~6 ~30 stone_stairs 6  
fill ~14 ~6 ~31 ~18 ~6 ~31 stone 
setblock ~14 ~6 ~33 stone_stairs 7  
fill ~14 ~6 ~34 ~14 ~6 ~35 stone_stairs 
setblock ~14 ~6 ~36 double_stone_slab 3 
setblock ~14 ~6 ~37 stone_slab 11 
setblock ~15 ~6 ~20 stone_stairs 5 
setblock ~15 ~6 ~24 stone_stairs 5 
setblock ~15 ~6 ~28 stone_stairs 5 
setblock ~15 ~6 ~32 stone_stairs 5 
setblock ~15 ~6 ~36 stone_slab 11  
fill ~17 ~6 ~6 ~18 ~6 ~6 dropper  
fill ~17 ~6 ~10 ~18 ~6 ~10 dropper  
fill ~20 ~6 ~6 ~21 ~6 ~6 dropper  
fill ~20 ~6 ~10 ~21 ~6 ~10 dropper  
fill ~20 ~6 ~31 ~22 ~6 ~31 stone  
fill ~23 ~6 ~6 ~24 ~6 ~6 dropper  
fill ~23 ~6 ~10 ~24 ~6 ~10 dropper  
fill ~24 ~6 ~16 ~24 ~6 ~17 stone_brick_stairs  
fill ~24 ~6 ~18 ~24 ~7 ~18 stone_slab  
fill ~24 ~6 ~31 ~26 ~6 ~31 stone  
fill ~25 ~6 ~6 ~26 ~6 ~6 stone_brick_stairs  
fill ~25 ~6 ~7 ~25 ~10 ~7 stonebrick  
fill ~25 ~6 ~8 ~25 ~10 ~8 stonebrick  
fill ~25 ~6 ~9 ~25 ~6 ~11 stone_brick_stairs  
fill ~25 ~6 ~12 ~25 ~7 ~12 stonebrick  
fill ~25 ~6 ~14 ~26 ~6 ~14 stone_brick_stairs  
fill ~25 ~6 ~15 ~25 ~6 ~13 stone_brick_stairs  
fill ~25 ~6 ~16 ~26 ~6 ~16 stonebrick  
fill ~25 ~6 ~17 ~26 ~6 ~17 stonebrick  
fill ~25 ~6 ~18 ~26 ~6 ~18 stone_brick_stairs 
setblock ~26 ~6 ~10 stone_brick_stairs 3  
fill ~27 ~6 ~7 ~28 ~6 ~7 stone_brick_stairs  
fill ~27 ~6 ~8 ~27 ~5 ~8 stonebrick  
fill ~27 ~6 ~9 ~31 ~6 ~9 cobblestone  
fill ~27 ~6 ~10 ~27 ~10 ~10 cobblestone  
fill ~27 ~6 ~11 ~27 ~10 ~11 cobblestone  
fill ~27 ~6 ~12 ~30 ~6 ~12 stone_slab  
fill ~27 ~6 ~13 ~27 ~10 ~13 cobblestone  
fill ~27 ~6 ~14 ~27 ~10 ~14 cobblestone  
fill ~27 ~6 ~15 ~31 ~6 ~15 cobblestone  
fill ~27 ~6 ~16 ~27 ~0 ~16 stonebrick  
fill ~27 ~6 ~17 ~28 ~6 ~17 stone_brick_stairs 
setblock ~28 ~6 ~8 stone_brick_stairs 1 
setblock ~28 ~6 ~16 stone_brick_stairs 1  
fill ~28 ~6 ~31 ~29 ~6 ~31 stone  
fill ~29 ~6 ~7 ~29 ~7 ~7 stonebrick 
setblock ~29 ~6 ~8 stone_slab 5  
fill ~29 ~6 ~17 ~29 ~7 ~17 stonebrick 
setblock ~29 ~6 ~19 stone_slab 13 
setblock ~29 ~6 ~22 stone_slab 13 
setblock ~29 ~6 ~25 stone_slab 13 
setblock ~29 ~6 ~28 stone_slab 13  
fill ~29 ~6 ~30 ~31 ~6 ~30 stonebrick 
setblock ~29 ~6 ~33 stone_brick_stairs 0 
setblock ~29 ~6 ~34 stone_slab 5  
fill ~30 ~6 ~7 ~31 ~6 ~7 stone_brick_stairs  
fill ~30 ~6 ~8 ~30 ~6 ~7 stone_brick_stairs  
fill ~30 ~6 ~14 ~30 ~9 ~14 stone  
fill ~30 ~6 ~16 ~30 ~6 ~17 stone_brick_stairs 
setblock ~30 ~6 ~29 stone_slab 5  
fill ~30 ~6 ~32 ~30 ~8 ~32 stonebrick  
fill ~30 ~6 ~34 ~31 ~6 ~34 stonebrick 
setblock ~30 ~6 ~35 stone_slab 5 
setblock ~31 ~6 ~8 stonebrick 0  
fill ~31 ~6 ~10 ~31 ~6 ~15 cobblestone  
fill ~31 ~6 ~16 ~31 ~7 ~16 stonebrick  
fill ~31 ~6 ~18 ~31 ~7 ~18 stonebrick 
setblock ~31 ~6 ~21 stone_brick_stairs 6  
fill ~31 ~6 ~23 ~31 ~7 ~23 stonebrick  
fill ~31 ~6 ~24 ~31 ~7 ~24 stonebrick 
setblock ~31 ~6 ~26 stone_brick_stairs 7 
setblock ~31 ~6 ~35 stone_brick_stairs 3  
fill ~32 ~6 ~6 ~33 ~6 ~6 stone_brick_stairs  
fill ~32 ~6 ~7 ~33 ~6 ~7 stonebrick  
fill ~32 ~6 ~8 ~33 ~6 ~8 stonebrick 
setblock ~32 ~6 ~9 stonebrick 0  
fill ~32 ~6 ~10 ~32 ~6 ~11 stone_slab 
setblock ~32 ~6 ~12 double_stone_slab 5  
fill ~32 ~6 ~13 ~32 ~6 ~14 stone_slab 
setblock ~32 ~6 ~15 stonebrick 0  
fill ~32 ~6 ~16 ~33 ~6 ~16 stonebrick  
fill ~32 ~6 ~17 ~33 ~6 ~17 stonebrick  
fill ~32 ~6 ~18 ~33 ~6 ~18 stone_brick_stairs  
fill ~32 ~6 ~29 ~32 ~7 ~29 stonebrick  
fill ~32 ~6 ~30 ~32 ~7 ~30 stonebrick  
fill ~32 ~6 ~34 ~32 ~8 ~34 stonebrick  
fill ~32 ~6 ~35 ~32 ~8 ~35 cobblestone_wall  
fill ~33 ~6 ~9 ~33 ~6 ~11 stone_brick_stairs  
fill ~33 ~6 ~12 ~33 ~7 ~12 stonebrick  
fill ~33 ~6 ~13 ~33 ~6 ~15 stone_brick_stairs 
setblock ~33 ~6 ~19 stone_slab 13 
setblock ~33 ~6 ~22 stone_slab 13 
setblock ~33 ~6 ~25 stone_slab 13 
setblock ~33 ~6 ~28 stone_slab 13 
setblock ~33 ~6 ~29 stone_brick_stairs 2  
fill ~33 ~6 ~30 ~34 ~6 ~30 stonebrick  
fill ~33 ~6 ~34 ~34 ~6 ~34 stonebrick 
setblock ~33 ~6 ~35 stone_brick_stairs 3  
fill ~34 ~6 ~6 ~34 ~7 ~6 stone_slab  
fill ~34 ~6 ~7 ~34 ~6 ~8 stone_brick_stairs  
fill ~34 ~6 ~16 ~34 ~6 ~17 stone_brick_stairs  
fill ~34 ~6 ~18 ~34 ~7 ~18 stone_slab 
setblock ~34 ~6 ~29 stone_slab 5  
fill ~34 ~6 ~32 ~34 ~8 ~32 stonebrick 
setblock ~34 ~6 ~35 stone_slab 5 
setblock ~35 ~6 ~30 stone_slab 5 
setblock ~35 ~6 ~31 stone_brick_stairs 1  
fill ~35 ~6 ~32 ~35 ~8 ~32 cobblestone_wall 
setblock ~35 ~6 ~33 stone_brick_stairs 1 
setblock ~35 ~6 ~34 stone_slab 5  
fill ~3 ~7 ~19 ~3 ~11 ~19 log 
setblock ~3 ~7 ~20 stone_brick_stairs 0 
setblock ~3 ~7 ~24 stone_brick_stairs 0 
setblock ~3 ~7 ~28 stone_brick_stairs 0 
setblock ~3 ~7 ~32 stone_brick_stairs 0 
setblock ~3 ~7 ~36 stone_brick_stairs 0  
fill ~3 ~7 ~37 ~3 ~11 ~37 log 
setblock ~4 ~7 ~19 stone_brick_stairs 2  
fill ~4 ~7 ~20 ~4 ~7 ~35 log 
setblock ~4 ~7 ~36 stonebrick 0 
setblock ~4 ~7 ~37 stone_brick_stairs 3 
setblock ~5 ~7 ~7 stone_brick_stairs 7 
setblock ~5 ~7 ~9 stone_brick_stairs 6  
fill ~5 ~7 ~20 ~8 ~7 ~20 log  
fill ~5 ~7 ~32 ~14 ~7 ~32 cobblestone  
fill ~5 ~7 ~34 ~13 ~7 ~34 stone_slab  
fill ~5 ~7 ~35 ~13 ~7 ~35 stone_slab  
fill ~5 ~7 ~36 ~13 ~7 ~36 log 
setblock ~7 ~7 ~12 stone_slab 13 
setblock ~7 ~7 ~13 stone_brick_stairs 4 
setblock ~7 ~7 ~14 stone_slab 13 
setblock ~7 ~7 ~18 stone_slab 13 
setblock ~7 ~7 ~19 stone_brick_stairs 4 
setblock ~8 ~7 ~4 stone_brick_stairs 5 
setblock ~8 ~7 ~12 stone_brick_stairs 5  
fill ~8 ~7 ~13 ~8 ~7 ~14 stonebrick 
setblock ~8 ~7 ~15 double_stone_slab 5 
setblock ~8 ~7 ~16 stone_slab 13 
setblock ~8 ~7 ~17 double_stone_slab 5  
fill ~8 ~7 ~18 ~8 ~7 ~19 stonebrick 
setblock ~9 ~7 ~37 stone_brick_stairs 3 
setblock ~10 ~7 ~4 stone_brick_stairs 4 
setblock ~10 ~7 ~12 stone_brick_stairs 4  
fill ~10 ~7 ~13 ~10 ~7 ~15 stonebrick 
setblock ~10 ~7 ~16 stone_slab 13  
fill ~10 ~7 ~17 ~10 ~7 ~19 stonebrick  
fill ~10 ~7 ~20 ~13 ~7 ~20 log 
setblock ~11 ~7 ~12 stone_slab 13 
setblock ~11 ~7 ~13 stone_brick_stairs 5 
setblock ~11 ~7 ~14 stone_slab 13 
setblock ~11 ~7 ~18 stone_slab 13 
setblock ~11 ~7 ~19 stone_brick_stairs 5  
fill ~12 ~7 ~8 ~12 ~8 ~8 stone  
fill ~13 ~7 ~5 ~15 ~7 ~5 dropper  
fill ~13 ~7 ~6 ~15 ~7 ~6 activator_rail 
setblock ~13 ~7 ~7 stone_brick_stairs 7 
setblock ~13 ~7 ~9 stone_brick_stairs 6  
fill ~14 ~7 ~10 ~15 ~7 ~10 activator_rail  
fill ~14 ~7 ~11 ~15 ~7 ~11 dropper 
setblock ~14 ~7 ~19 stone_brick_stairs 2  
fill ~14 ~7 ~20 ~14 ~7 ~27 log  
fill ~14 ~7 ~29 ~14 ~7 ~30 log  
fill ~14 ~7 ~31 ~29 ~7 ~31 stone  
fill ~14 ~7 ~33 ~14 ~7 ~36 log 
setblock ~14 ~7 ~37 stone_brick_stairs 3  
fill ~15 ~7 ~19 ~15 ~12 ~19 log 
setblock ~15 ~7 ~20 stone_brick_stairs 1  
fill ~15 ~7 ~24 ~15 ~10 ~24 log  
fill ~15 ~7 ~28 ~15 ~10 ~28 log  
fill ~15 ~7 ~32 ~15 ~10 ~32 log 
setblock ~15 ~7 ~36 stone_brick_stairs 1  
fill ~15 ~7 ~37 ~15 ~12 ~37 log 
setblock ~16 ~7 ~5 stone_slab 3 
setblock ~16 ~7 ~6 cobblestone 0 
setblock ~16 ~7 ~10 cobblestone 0 
setblock ~16 ~7 ~11 stone_slab 3 
setblock ~16 ~7 ~30 stone_brick_stairs 4 
setblock ~16 ~7 ~32 stone_brick_stairs 4  
fill ~17 ~7 ~5 ~18 ~7 ~5 dropper  
fill ~17 ~7 ~6 ~18 ~7 ~6 activator_rail  
fill ~17 ~7 ~10 ~18 ~7 ~10 activator_rail  
fill ~17 ~7 ~11 ~18 ~7 ~11 dropper 
setblock ~17 ~7 ~29 stone_brick_stairs 6 
setblock ~17 ~7 ~33 stone_brick_stairs 7 
setblock ~18 ~7 ~30 stone_brick_stairs 5 
setblock ~18 ~7 ~32 stone_brick_stairs 5 
setblock ~19 ~7 ~5 stone_slab 3 
setblock ~19 ~7 ~6 cobblestone 0 
setblock ~19 ~7 ~10 cobblestone 0 
setblock ~19 ~7 ~11 stone_slab 3  
fill ~20 ~7 ~5 ~21 ~7 ~5 dropper  
fill ~20 ~7 ~6 ~21 ~7 ~6 activator_rail  
fill ~20 ~7 ~10 ~21 ~7 ~10 activator_rail  
fill ~20 ~7 ~11 ~21 ~7 ~11 dropper 
setblock ~20 ~7 ~30 stone_brick_stairs 4 
setblock ~20 ~7 ~32 stone_brick_stairs 4 
setblock ~21 ~7 ~29 stone_brick_stairs 6 
setblock ~21 ~7 ~33 stone_brick_stairs 7 
setblock ~22 ~7 ~5 stone_slab 3 
setblock ~22 ~7 ~6 cobblestone 0 
setblock ~22 ~7 ~10 cobblestone 0 
setblock ~22 ~7 ~11 stone_slab 3 
setblock ~22 ~7 ~30 stone_brick_stairs 5 
setblock ~22 ~7 ~32 stone_brick_stairs 5  
fill ~23 ~7 ~5 ~24 ~7 ~5 dropper  
fill ~23 ~7 ~6 ~24 ~7 ~6 activator_rail  
fill ~23 ~7 ~10 ~24 ~7 ~10 activator_rail  
fill ~23 ~7 ~11 ~24 ~7 ~11 dropper 
setblock ~24 ~7 ~7 stone_brick_stairs 7  
fill ~24 ~7 ~8 ~24 ~7 ~9 stone_brick_stairs  
fill ~24 ~7 ~16 ~24 ~7 ~17 stone_brick_stairs 
setblock ~24 ~7 ~30 stone_brick_stairs 4 
setblock ~24 ~7 ~32 stone_brick_stairs 4  
fill ~25 ~7 ~6 ~26 ~7 ~6 stone_brick_stairs  
fill ~25 ~7 ~9 ~25 ~7 ~11 stone_brick_stairs  
fill ~25 ~7 ~13 ~25 ~7 ~15 stone_brick_stairs  
fill ~25 ~7 ~16 ~26 ~7 ~16 stonebrick  
fill ~25 ~7 ~17 ~26 ~7 ~17 stonebrick  
fill ~25 ~7 ~18 ~26 ~7 ~18 stone_brick_stairs 
setblock ~25 ~7 ~29 stone_brick_stairs 6 
setblock ~25 ~7 ~33 stone_brick_stairs 7 
setblock ~26 ~7 ~9 stone_brick_stairs 3 
setblock ~26 ~7 ~15 stone_brick_stairs 2 
setblock ~26 ~7 ~30 stone_brick_stairs 5 
setblock ~26 ~7 ~32 stone_brick_stairs 5  
fill ~27 ~7 ~7 ~28 ~7 ~7 stone_brick_stairs 
setblock ~27 ~7 ~8 stone_brick_stairs 1  
fill ~27 ~7 ~9 ~31 ~7 ~9 cobblestone  
fill ~27 ~7 ~12 ~27 ~10 ~12 cobblestone  
fill ~27 ~7 ~15 ~31 ~7 ~15 cobblestone 
setblock ~27 ~7 ~16 stone_brick_stairs 1  
fill ~27 ~7 ~17 ~28 ~7 ~17 stone_brick_stairs 
setblock ~28 ~7 ~30 stone_brick_stairs 4 
setblock ~28 ~7 ~32 stone_brick_stairs 4 
setblock ~29 ~7 ~19 stone_brick_stairs 4 
setblock ~29 ~7 ~22 stone_brick_stairs 4 
setblock ~29 ~7 ~25 stone_brick_stairs 4 
setblock ~29 ~7 ~28 stone_brick_stairs 4  
fill ~29 ~7 ~30 ~31 ~7 ~30 stonebrick 
setblock ~29 ~7 ~33 stone_brick_stairs 7  
fill ~30 ~7 ~7 ~31 ~7 ~7 stone_brick_stairs  
fill ~30 ~7 ~10 ~30 ~8 ~10 piston  
fill ~30 ~7 ~11 ~30 ~8 ~11 piston  
fill ~30 ~7 ~13 ~30 ~9 ~13 stone  
fill ~30 ~7 ~16 ~30 ~7 ~17 stonebrick 
setblock ~30 ~7 ~18 stone_brick_stairs 6 
setblock ~30 ~7 ~19 stonebrick 0 
setblock ~30 ~7 ~20 stone_brick_stairs 7 
setblock ~30 ~7 ~21 stone_brick_stairs 6 
setblock ~30 ~7 ~22 stonebrick 0 
setblock ~30 ~7 ~23 stone_brick_stairs 7 
setblock ~30 ~7 ~24 stone_brick_stairs 6 
setblock ~30 ~7 ~25 stonebrick 0 
setblock ~30 ~7 ~26 stone_brick_stairs 7 
setblock ~30 ~7 ~27 stone_brick_stairs 6  
fill ~30 ~7 ~28 ~30 ~7 ~30 stonebrick 
setblock ~30 ~7 ~31 stone_brick_stairs 2 
setblock ~30 ~7 ~33 stone_brick_stairs 3  
fill ~30 ~7 ~34 ~30 ~17 ~34 stonebrick 
setblock ~31 ~7 ~8 stone_brick_stairs 0  
fill ~31 ~7 ~10 ~31 ~7 ~11 dark_oak_door  
fill ~31 ~7 ~12 ~31 ~10 ~12 cobblestone 
setblock ~31 ~7 ~13 stone_stairs 3 
setblock ~31 ~7 ~14 stone_stairs 2 
setblock ~31 ~7 ~21 stonebrick 0 
setblock ~31 ~7 ~26 stonebrick 0 
setblock ~31 ~7 ~34 stone_brick_stairs 0  
fill ~32 ~7 ~6 ~33 ~7 ~6 stone_brick_stairs  
fill ~32 ~7 ~7 ~33 ~7 ~7 stonebrick  
fill ~32 ~7 ~8 ~33 ~7 ~8 stonebrick 
setblock ~32 ~7 ~9 stone_brick_stairs 3  
fill ~32 ~7 ~12 ~32 ~8 ~12 cobblestone_wall 
setblock ~32 ~7 ~15 stone_brick_stairs 2  
fill ~32 ~7 ~16 ~33 ~7 ~16 stonebrick  
fill ~32 ~7 ~17 ~33 ~7 ~17 stonebrick  
fill ~32 ~7 ~18 ~33 ~7 ~18 stone_brick_stairs 
setblock ~32 ~7 ~19 stonebrick 0 
setblock ~32 ~7 ~20 stone_brick_stairs 7 
setblock ~32 ~7 ~21 stone_brick_stairs 6 
setblock ~32 ~7 ~22 stonebrick 0 
setblock ~32 ~7 ~23 stone_brick_stairs 7 
setblock ~32 ~7 ~24 stone_brick_stairs 6 
setblock ~32 ~7 ~25 stonebrick 0 
setblock ~32 ~7 ~26 stone_brick_stairs 7 
setblock ~32 ~7 ~27 stone_brick_stairs 6 
setblock ~32 ~7 ~28 stonebrick 0  
fill ~33 ~7 ~9 ~33 ~7 ~11 stone_brick_stairs  
fill ~33 ~7 ~13 ~33 ~7 ~15 stone_brick_stairs 
setblock ~33 ~7 ~19 stone_brick_stairs 5 
setblock ~33 ~7 ~22 stone_brick_stairs 5 
setblock ~33 ~7 ~25 stone_brick_stairs 5 
setblock ~33 ~7 ~28 stone_brick_stairs 5 
setblock ~33 ~7 ~30 stone_brick_stairs 1 
setblock ~33 ~7 ~34 stone_brick_stairs 1  
fill ~34 ~7 ~7 ~34 ~7 ~8 stone_brick_stairs  
fill ~34 ~7 ~16 ~34 ~7 ~17 stone_brick_stairs  
fill ~34 ~7 ~30 ~34 ~17 ~30 stonebrick 
setblock ~34 ~7 ~31 stone_brick_stairs 2 
setblock ~34 ~7 ~33 stone_brick_stairs 3  
fill ~34 ~7 ~34 ~34 ~17 ~34 stonebrick 
setblock ~3 ~8 ~20 stone_brick_stairs 4 
setblock ~3 ~8 ~24 stone_brick_stairs 4 
setblock ~3 ~8 ~28 stone_brick_stairs 4 
setblock ~3 ~8 ~32 stone_brick_stairs 4 
setblock ~3 ~8 ~36 stone_brick_stairs 4 
setblock ~4 ~8 ~19 stone_brick_stairs 6  
fill ~4 ~8 ~20 ~4 ~10 ~20 wool  
fill ~4 ~8 ~21 ~4 ~10 ~21 wool  
fill ~4 ~8 ~22 ~4 ~10 ~22 wool  
fill ~4 ~8 ~23 ~4 ~10 ~23 wool  
fill ~4 ~8 ~24 ~4 ~10 ~24 wool  
fill ~4 ~8 ~25 ~4 ~10 ~25 wool  
fill ~4 ~8 ~26 ~4 ~10 ~26 wool  
fill ~4 ~8 ~27 ~4 ~10 ~27 wool  
fill ~4 ~8 ~28 ~4 ~10 ~28 wool  
fill ~4 ~8 ~29 ~4 ~10 ~29 wool  
fill ~4 ~8 ~30 ~4 ~10 ~30 wool  
fill ~4 ~8 ~31 ~4 ~10 ~31 wool  
fill ~4 ~8 ~32 ~4 ~10 ~32 wool  
fill ~4 ~8 ~33 ~4 ~10 ~33 wool  
fill ~4 ~8 ~34 ~4 ~10 ~34 wool  
fill ~4 ~8 ~35 ~4 ~10 ~35 wool  
fill ~4 ~8 ~36 ~4 ~10 ~36 wool 
setblock ~4 ~8 ~37 stone_brick_stairs 7 
setblock ~5 ~8 ~6 stone_slab 13  
fill ~5 ~8 ~7 ~5 ~10 ~7 stonebrick 
setblock ~5 ~8 ~8 stone_slab 13  
fill ~5 ~8 ~9 ~5 ~10 ~9 stonebrick 
setblock ~5 ~8 ~10 stone_slab 13 
setblock ~5 ~8 ~20 wool 8 
setblock ~5 ~8 ~36 wool 8  
fill ~6 ~8 ~20 ~7 ~8 ~20 wool  
fill ~6 ~8 ~36 ~7 ~8 ~36 wool  
fill ~6 ~8 ~37 ~7 ~8 ~37 stone_stairs 
setblock ~7 ~8 ~4 stone_slab 13  
fill ~7 ~8 ~12 ~7 ~11 ~12 stone_slab 
setblock ~7 ~8 ~14 stone_brick_stairs 2 
setblock ~7 ~8 ~15 stone_slab 5 
setblock ~7 ~8 ~16 stone_slab 13 
setblock ~7 ~8 ~17 stone_slab 5 
setblock ~7 ~8 ~18 stone_brick_stairs 3  
fill ~8 ~8 ~4 ~8 ~10 ~4 stonebrick  
fill ~8 ~8 ~12 ~8 ~10 ~12 stonebrick  
fill ~8 ~8 ~13 ~8 ~8 ~19 stone_brick_stairs 
setblock ~8 ~8 ~20 wool 8 
setblock ~8 ~8 ~36 wool 8 
setblock ~9 ~8 ~4 stone_slab 13 
setblock ~9 ~8 ~12 stone_slab 13  
fill ~9 ~8 ~13 ~9 ~8 ~19 stonebrick  
fill ~9 ~8 ~36 ~9 ~10 ~36 wool 
setblock ~9 ~8 ~37 stone_brick_stairs 7  
fill ~10 ~8 ~4 ~10 ~10 ~4 stonebrick  
fill ~10 ~8 ~12 ~10 ~10 ~12 stonebrick  
fill ~10 ~8 ~13 ~10 ~8 ~19 stone_brick_stairs 
setblock ~10 ~8 ~20 wool 8 
setblock ~10 ~8 ~36 wool 8 
setblock ~11 ~8 ~4 stone_slab 13  
fill ~11 ~8 ~12 ~11 ~11 ~12 stone_slab 
setblock ~11 ~8 ~14 stone_brick_stairs 2 
setblock ~11 ~8 ~15 stone_slab 5 
setblock ~11 ~8 ~16 stone_slab 13 
setblock ~11 ~8 ~17 stone_slab 5 
setblock ~11 ~8 ~18 stone_brick_stairs 3  
fill ~11 ~8 ~19 ~12 ~8 ~19 stone_stairs  
fill ~11 ~8 ~20 ~12 ~8 ~20 wool  
fill ~11 ~8 ~36 ~12 ~8 ~36 wool 
setblock ~13 ~8 ~6 stone_slab 13  
fill ~13 ~8 ~7 ~13 ~10 ~7 stonebrick 
setblock ~13 ~8 ~8 stone_slab 13  
fill ~13 ~8 ~9 ~13 ~10 ~9 stonebrick 
setblock ~13 ~8 ~10 stone_slab 13 
setblock ~13 ~8 ~20 wool 8 
setblock ~13 ~8 ~36 wool 8  
fill ~14 ~8 ~7 ~15 ~8 ~7 spruce_stairs  
fill ~14 ~8 ~9 ~15 ~8 ~9 spruce_stairs 
setblock ~14 ~8 ~19 stone_brick_stairs 6  
fill ~14 ~8 ~20 ~14 ~10 ~20 wool 
setblock ~14 ~8 ~21 wool 8 
setblock ~14 ~8 ~22 wool 0 
setblock ~14 ~8 ~23 wool 8  
fill ~14 ~8 ~24 ~14 ~10 ~24 wool  
fill ~14 ~8 ~25 ~14 ~8 ~24 wool 
setblock ~14 ~8 ~26 wool 8  
fill ~14 ~8 ~27 ~14 ~8 ~28 wool 
setblock ~14 ~8 ~29 stone_slab 13 
setblock ~14 ~8 ~30 wool 0  
fill ~14 ~8 ~31 ~14 ~3 ~31 stone  
fill ~14 ~8 ~32 ~14 ~10 ~32 wool 
setblock ~14 ~8 ~33 wool 8 
setblock ~14 ~8 ~34 wool 0 
setblock ~14 ~8 ~35 wool 8  
fill ~14 ~8 ~36 ~14 ~10 ~36 wool 
setblock ~14 ~8 ~37 stone_brick_stairs 7 
setblock ~15 ~8 ~20 stone_brick_stairs 5 
setblock ~15 ~8 ~26 stone_brick_stairs 5  
fill ~15 ~8 ~30 ~28 ~8 ~30 stone_brick_stairs  
fill ~15 ~8 ~31 ~29 ~8 ~31 stonebrick 
setblock ~15 ~8 ~36 stone_brick_stairs 5 
setblock ~16 ~8 ~7 stone_stairs 2 
setblock ~16 ~8 ~9 stone_stairs 3 
setblock ~16 ~8 ~29 stone_slab 13  
fill ~16 ~8 ~32 ~28 ~8 ~32 stone_brick_stairs 
setblock ~16 ~8 ~33 stone_slab 13  
fill ~17 ~8 ~7 ~18 ~8 ~7 spruce_stairs  
fill ~17 ~8 ~9 ~18 ~8 ~9 spruce_stairs 
setblock ~17 ~8 ~29 stonebrick 0 
setblock ~17 ~8 ~33 stonebrick 0 
setblock ~18 ~8 ~29 stone_slab 13 
setblock ~18 ~8 ~33 stone_slab 13 
setblock ~19 ~8 ~7 stone_stairs 2 
setblock ~19 ~8 ~9 stone_stairs 3  
fill ~20 ~8 ~7 ~21 ~8 ~7 spruce_stairs  
fill ~20 ~8 ~9 ~21 ~8 ~9 spruce_stairs 
setblock ~20 ~8 ~29 stone_slab 13 
setblock ~20 ~8 ~33 stone_slab 13 
setblock ~21 ~8 ~29 stonebrick 0 
setblock ~21 ~8 ~33 stonebrick 0 
setblock ~22 ~8 ~7 stone_stairs 2 
setblock ~22 ~8 ~9 stone_stairs 3 
setblock ~22 ~8 ~29 stone_slab 13 
setblock ~22 ~8 ~33 stone_slab 13  
fill ~23 ~8 ~7 ~24 ~8 ~7 spruce_stairs  
fill ~23 ~8 ~9 ~24 ~8 ~9 spruce_stairs 
setblock ~24 ~8 ~29 stone_slab 13 
setblock ~24 ~8 ~33 stone_slab 13  
fill ~25 ~8 ~16 ~26 ~8 ~16 stonebrick  
fill ~25 ~8 ~17 ~26 ~8 ~17 stonebrick 
setblock ~25 ~8 ~29 stonebrick 0 
setblock ~25 ~8 ~33 stonebrick 0 
setblock ~26 ~8 ~9 stone_brick_stairs 7 
setblock ~26 ~8 ~15 stone_brick_stairs 6 
setblock ~26 ~8 ~29 stone_slab 13 
setblock ~26 ~8 ~33 stone_slab 13 
setblock ~27 ~8 ~8 stone_brick_stairs 5  
fill ~27 ~8 ~9 ~28 ~8 ~9 cobblestone  
fill ~27 ~8 ~15 ~31 ~8 ~15 cobblestone 
setblock ~27 ~8 ~16 stone_brick_stairs 5  
fill ~28 ~8 ~10 ~29 ~8 ~10 stone 
setblock ~28 ~8 ~29 stone_slab 13 
setblock ~28 ~8 ~33 stone_slab 13 
setblock ~29 ~8 ~16 stone_slab 5 
setblock ~29 ~8 ~17 double_stone_slab 5 
setblock ~29 ~8 ~18 stone_slab 5 
setblock ~29 ~8 ~19 double_stone_slab 5 
setblock ~29 ~8 ~20 stone_slab 5 
setblock ~29 ~8 ~21 double_stone_slab 5 
setblock ~29 ~8 ~22 stone_slab 5 
setblock ~29 ~8 ~23 double_stone_slab 5 
setblock ~29 ~8 ~24 stone_slab 5 
setblock ~29 ~8 ~25 double_stone_slab 5 
setblock ~29 ~8 ~26 stone_slab 5 
setblock ~29 ~8 ~27 double_stone_slab 5 
setblock ~29 ~8 ~28 stone_slab 5  
fill ~29 ~8 ~30 ~30 ~8 ~30 stonebrick  
fill ~29 ~8 ~33 ~29 ~9 ~33 stonebrick  
fill ~30 ~8 ~9 ~31 ~8 ~9 cobblestone 
setblock ~30 ~8 ~31 stone_brick_stairs 6 
setblock ~30 ~8 ~33 stone_brick_stairs 7 
setblock ~31 ~8 ~8 stone_brick_stairs 4 
setblock ~31 ~8 ~10 dark_oak_door 9 
setblock ~31 ~8 ~11 dark_oak_door 8 
setblock ~31 ~8 ~30 iron_door 1 
setblock ~31 ~8 ~34 stone_brick_stairs 4  
fill ~32 ~8 ~7 ~33 ~8 ~7 stonebrick  
fill ~32 ~8 ~8 ~33 ~8 ~8 stonebrick 
setblock ~32 ~8 ~9 stone_brick_stairs 7 
setblock ~32 ~8 ~15 stone_brick_stairs 6  
fill ~32 ~8 ~16 ~33 ~8 ~16 stonebrick  
fill ~32 ~8 ~17 ~33 ~8 ~17 stonebrick  
fill ~32 ~8 ~30 ~32 ~10 ~30 stonebrick 
setblock ~33 ~8 ~18 stone_slab 5 
setblock ~33 ~8 ~19 double_stone_slab 5 
setblock ~33 ~8 ~20 stone_slab 5 
setblock ~33 ~8 ~21 double_stone_slab 5 
setblock ~33 ~8 ~22 stone_slab 5 
setblock ~33 ~8 ~23 double_stone_slab 5 
setblock ~33 ~8 ~24 stone_slab 5 
setblock ~33 ~8 ~25 double_stone_slab 5 
setblock ~33 ~8 ~26 stone_slab 5 
setblock ~33 ~8 ~27 double_stone_slab 5 
setblock ~33 ~8 ~28 stone_slab 5 
setblock ~33 ~8 ~29 double_stone_slab 5 
setblock ~33 ~8 ~30 stone_brick_stairs 5 
setblock ~33 ~8 ~34 stone_brick_stairs 5 
setblock ~34 ~8 ~31 stone_brick_stairs 6 
setblock ~34 ~8 ~33 stone_brick_stairs 7 
setblock ~3 ~9 ~20 stone_brick_stairs 0 
setblock ~3 ~9 ~24 stone_brick_stairs 0 
setblock ~3 ~9 ~28 stone_brick_stairs 0 
setblock ~3 ~9 ~32 stone_brick_stairs 0 
setblock ~3 ~9 ~36 stone_brick_stairs 0 
setblock ~4 ~9 ~7 torch 2 
setblock ~4 ~9 ~9 torch 2 
setblock ~4 ~9 ~19 stone_brick_stairs 2 
setblock ~4 ~9 ~37 stone_brick_stairs 3  
fill ~5 ~9 ~8 ~5 ~12 ~8 stonebrick 
setblock ~5 ~9 ~19 trapdoor 12 
setblock ~5 ~9 ~20 wool 0 
setblock ~5 ~9 ~36 wool 0 
setblock ~6 ~9 ~20 glass_pane 0  
fill ~6 ~9 ~36 ~7 ~9 ~36 glass_pane  
fill ~6 ~9 ~37 ~7 ~9 ~37 flower_pot 
setblock ~7 ~9 ~13 double_stone_slab 5 
setblock ~7 ~9 ~14 stone_slab 5 
setblock ~7 ~9 ~15 double_stone_slab 5 
setblock ~7 ~9 ~16 stone_slab 5 
setblock ~7 ~9 ~17 double_stone_slab 5 
setblock ~7 ~9 ~18 stone_slab 5 
setblock ~7 ~9 ~19 double_stone_slab 5  
fill ~7 ~9 ~20 ~8 ~9 ~20 wool 
setblock ~8 ~9 ~36 wool 0  
fill ~9 ~9 ~4 ~9 ~12 ~4 stonebrick 
setblock ~9 ~9 ~12 iron_door 3 
setblock ~9 ~9 ~20 wooden_door 1 
setblock ~9 ~9 ~37 stone_brick_stairs 3 
setblock ~10 ~9 ~20 wool 0 
setblock ~10 ~9 ~36 wool 0 
setblock ~10 ~9 ~37 trapdoor 13 
setblock ~11 ~9 ~13 double_stone_slab 5 
setblock ~11 ~9 ~14 stone_slab 5 
setblock ~11 ~9 ~15 double_stone_slab 5 
setblock ~11 ~9 ~16 stone_slab 5 
setblock ~11 ~9 ~17 double_stone_slab 5 
setblock ~11 ~9 ~18 stone_slab 5 
setblock ~11 ~9 ~19 double_stone_slab 5  
fill ~11 ~9 ~20 ~12 ~9 ~20 glass_pane  
fill ~11 ~9 ~36 ~12 ~9 ~36 glass_pane 
setblock ~12 ~9 ~19 flower_pot 0  
fill ~13 ~9 ~8 ~13 ~12 ~8 stonebrick 
setblock ~13 ~9 ~20 wool 0 
setblock ~13 ~9 ~36 wool 0 
setblock ~13 ~9 ~37 trapdoor 13  
fill ~14 ~9 ~8 ~15 ~9 ~8 log 
setblock ~14 ~9 ~9 torch 1 
setblock ~14 ~9 ~19 stone_brick_stairs 2 
setblock ~14 ~9 ~21 wool 0 
setblock ~14 ~9 ~22 glass_pane 0 
setblock ~14 ~9 ~23 wool 0 
setblock ~14 ~9 ~25 wool 8 
setblock ~14 ~9 ~26 glass_pane 0 
setblock ~14 ~9 ~27 wool 8  
fill ~14 ~9 ~28 ~14 ~10 ~28 wool  
fill ~14 ~9 ~29 ~14 ~10 ~29 wool 
setblock ~14 ~9 ~30 spruce_door 2  
fill ~14 ~9 ~31 ~14 ~10 ~31 wool 
setblock ~14 ~9 ~33 wool 0 
setblock ~14 ~9 ~34 glass_pane 0 
setblock ~14 ~9 ~35 wool 0 
setblock ~14 ~9 ~37 stone_brick_stairs 3 
setblock ~15 ~9 ~20 stone_brick_stairs 1 
setblock ~15 ~9 ~21 fence 0 
setblock ~15 ~9 ~23 fence 0 
setblock ~15 ~9 ~25 trapdoor 15 
setblock ~15 ~9 ~26 flower_pot 0 
setblock ~15 ~9 ~27 trapdoor 15 
setblock ~15 ~9 ~29 double_stone_slab 5 
setblock ~15 ~9 ~33 double_stone_slab 5 
setblock ~15 ~9 ~35 fence 0 
setblock ~15 ~9 ~36 stone_brick_stairs 1 
setblock ~16 ~9 ~8 cobblestone 0 
setblock ~16 ~9 ~24 cobblestone_wall 0 
setblock ~16 ~9 ~28 cobblestone_wall 0 
setblock ~16 ~9 ~29 stone_slab 5  

KittysCommands:  
setblock ~16 ~9 ~33 stone_slab 5  
fill ~17 ~9 ~8 ~18 ~9 ~8 log 
setblock ~17 ~9 ~29 double_stone_slab 5 
setblock ~17 ~9 ~33 double_stone_slab 5 
setblock ~18 ~9 ~29 stone_slab 5 
setblock ~18 ~9 ~33 stone_slab 5 
setblock ~19 ~9 ~8 cobblestone 0 
setblock ~19 ~9 ~29 double_stone_slab 5 
setblock ~19 ~9 ~33 double_stone_slab 5  
fill ~20 ~9 ~8 ~21 ~9 ~8 log 
setblock ~20 ~9 ~29 stone_slab 5 
setblock ~20 ~9 ~33 stone_slab 5 
setblock ~21 ~9 ~29 double_stone_slab 5 
setblock ~21 ~9 ~33 double_stone_slab 5 
setblock ~22 ~9 ~8 cobblestone 0 
setblock ~22 ~9 ~29 stone_slab 5 
setblock ~22 ~9 ~33 stone_slab 5  
fill ~23 ~9 ~8 ~24 ~9 ~8 log 
setblock ~23 ~9 ~29 double_stone_slab 5 
setblock ~23 ~9 ~33 double_stone_slab 5 
setblock ~24 ~9 ~29 stone_slab 5 
setblock ~24 ~9 ~33 stone_slab 5  
fill ~25 ~9 ~16 ~26 ~9 ~16 stonebrick  
fill ~25 ~9 ~17 ~26 ~9 ~17 stonebrick 
setblock ~25 ~9 ~29 double_stone_slab 5 
setblock ~25 ~9 ~33 double_stone_slab 5 
setblock ~26 ~9 ~9 stone_brick_stairs 3 
setblock ~26 ~9 ~12 stone_brick_stairs 0 
setblock ~26 ~9 ~15 stone_brick_stairs 2 
setblock ~26 ~9 ~29 stone_slab 5 
setblock ~26 ~9 ~33 stone_slab 5 
setblock ~27 ~9 ~8 stone_brick_stairs 1  
fill ~27 ~9 ~9 ~27 ~10 ~9 cobblestone  
fill ~27 ~9 ~15 ~27 ~10 ~15 cobblestone 
setblock ~27 ~9 ~16 stone_brick_stairs 1 
setblock ~27 ~9 ~29 double_stone_slab 5 
setblock ~27 ~9 ~33 double_stone_slab 5 
setblock ~28 ~9 ~9 stone_stairs 5  
fill ~28 ~9 ~10 ~30 ~9 ~10 stone  
fill ~28 ~9 ~14 ~30 ~9 ~14 stone 
setblock ~28 ~9 ~15 stone_stairs 5 
setblock ~28 ~9 ~29 stone_slab 5 
setblock ~28 ~9 ~33 stone_slab 5 
setblock ~29 ~9 ~30 stone_brick_stairs 7 
setblock ~29 ~9 ~31 stone_slab 13 
setblock ~29 ~9 ~32 stone_brick_stairs 0 
setblock ~29 ~9 ~34 stone_brick_stairs 6 
setblock ~30 ~9 ~9 stone_stairs 4 
setblock ~30 ~9 ~11 stone 0 
setblock ~30 ~9 ~15 stone_stairs 4 
setblock ~30 ~9 ~29 torch 4  
fill ~30 ~9 ~30 ~30 ~17 ~30 stonebrick  
fill ~30 ~9 ~31 ~30 ~10 ~31 stonebrick  
fill ~30 ~9 ~32 ~30 ~10 ~32 stonebrick  
fill ~30 ~9 ~33 ~30 ~10 ~33 stonebrick 
setblock ~30 ~9 ~35 stone_brick_stairs 5 
setblock ~31 ~9 ~8 stone_brick_stairs 0  
fill ~31 ~9 ~9 ~31 ~10 ~9 cobblestone 
setblock ~31 ~9 ~10 stone_stairs 3 
setblock ~31 ~9 ~11 stone_stairs 2 
setblock ~31 ~9 ~13 stone_stairs 7 
setblock ~31 ~9 ~14 stone_stairs 6  
fill ~31 ~9 ~15 ~31 ~10 ~15 cobblestone 
setblock ~31 ~9 ~16 stone_brick_stairs 0 
setblock ~31 ~9 ~30 iron_door 8  
fill ~31 ~9 ~34 ~34 ~9 ~34 stonebrick 
setblock ~31 ~9 ~35 stone_slab 13  
fill ~32 ~9 ~7 ~33 ~9 ~7 stonebrick  
fill ~32 ~9 ~8 ~33 ~9 ~8 stonebrick 
setblock ~32 ~9 ~9 stone_brick_stairs 3 
setblock ~32 ~9 ~12 stone_brick_stairs 1 
setblock ~32 ~9 ~15 stone_brick_stairs 2  
fill ~32 ~9 ~16 ~33 ~9 ~16 stonebrick  
fill ~32 ~9 ~17 ~33 ~9 ~17 stonebrick 
setblock ~32 ~9 ~29 wooden_button 4 
setblock ~32 ~9 ~35 stone_brick_stairs 3 
setblock ~33 ~9 ~29 stone_brick_stairs 5  
fill ~33 ~9 ~30 ~33 ~10 ~30 stonebrick 
setblock ~33 ~9 ~35 stone_slab 13 
setblock ~34 ~9 ~29 stone_brick_stairs 4  
fill ~34 ~9 ~31 ~34 ~10 ~31 stonebrick  
fill ~34 ~9 ~32 ~34 ~10 ~32 stonebrick  
fill ~34 ~9 ~33 ~34 ~10 ~33 stonebrick 
setblock ~34 ~9 ~35 stone_brick_stairs 4 
setblock ~35 ~9 ~30 stone_brick_stairs 7 
setblock ~35 ~9 ~31 stone_slab 13 
setblock ~35 ~9 ~32 stone_brick_stairs 1 
setblock ~35 ~9 ~33 stone_slab 13 
setblock ~35 ~9 ~34 stone_brick_stairs 6 
setblock ~3 ~10 ~20 stone_brick_stairs 4 
setblock ~3 ~10 ~24 stone_brick_stairs 4 
setblock ~3 ~10 ~28 stone_brick_stairs 4 
setblock ~3 ~10 ~32 stone_brick_stairs 4 
setblock ~3 ~10 ~36 stone_brick_stairs 4 
setblock ~4 ~10 ~7 stone_slab 13  
fill ~4 ~10 ~8 ~4 ~11 ~8 stone_slab 
setblock ~4 ~10 ~9 stone_slab 13 
setblock ~4 ~10 ~19 stone_brick_stairs 6 
setblock ~4 ~10 ~37 stone_brick_stairs 7  
fill ~5 ~10 ~6 ~5 ~11 ~6 stone_slab  
fill ~5 ~10 ~10 ~5 ~11 ~10 stone_slab 
setblock ~5 ~10 ~20 wool 8 
setblock ~5 ~10 ~36 wool 8  
fill ~6 ~10 ~20 ~7 ~10 ~20 wool  
fill ~6 ~10 ~36 ~7 ~10 ~36 wool  
fill ~7 ~10 ~4 ~7 ~11 ~4 stone_slab 
setblock ~7 ~10 ~19 spruce_stairs 6 
setblock ~7 ~10 ~37 spruce_stairs 7 
setblock ~8 ~10 ~3 stone_slab 13 
setblock ~8 ~10 ~13 stone_slab 13 
setblock ~8 ~10 ~19 torch 4 
setblock ~8 ~10 ~20 wool 8 
setblock ~8 ~10 ~36 wool 8  
fill ~9 ~10 ~3 ~9 ~11 ~3 stone_slab 
setblock ~9 ~10 ~12 iron_door 8 
setblock ~9 ~10 ~20 wooden_door 8 
setblock ~9 ~10 ~37 stone_brick_stairs 7 
setblock ~10 ~10 ~3 stone_slab 13 
setblock ~10 ~10 ~13 stone_slab 13 
setblock ~10 ~10 ~19 torch 4 
setblock ~10 ~10 ~20 wool 8 
setblock ~10 ~10 ~36 wool 8  
fill ~11 ~10 ~4 ~11 ~11 ~4 stone_slab 
setblock ~11 ~10 ~19 spruce_stairs 6  
fill ~11 ~10 ~20 ~12 ~10 ~20 wool  
fill ~11 ~10 ~36 ~12 ~10 ~36 wool 
setblock ~11 ~10 ~37 spruce_stairs 7 
setblock ~12 ~10 ~5 stonebrick 0 
setblock ~12 ~10 ~11 stonebrick 0  
fill ~13 ~10 ~6 ~13 ~11 ~6 stone_slab  
fill ~13 ~10 ~10 ~13 ~11 ~10 stone_slab 
setblock ~13 ~10 ~20 wool 8 
setblock ~13 ~10 ~36 wool 8 
setblock ~14 ~10 ~7 stone_slab 13  
fill ~14 ~10 ~8 ~24 ~10 ~8 fence 
setblock ~14 ~10 ~9 stone_slab 13 
setblock ~14 ~10 ~19 stone_brick_stairs 6 
setblock ~14 ~10 ~21 wool 8 
setblock ~14 ~10 ~22 wool 0 
setblock ~14 ~10 ~23 wool 8 
setblock ~14 ~10 ~25 wool 0 
setblock ~14 ~10 ~26 wool 8 
setblock ~14 ~10 ~27 wool 0 
setblock ~14 ~10 ~30 spruce_door 9 
setblock ~14 ~10 ~33 wool 8 
setblock ~14 ~10 ~34 wool 0 
setblock ~14 ~10 ~35 wool 8 
setblock ~14 ~10 ~37 stone_brick_stairs 7 
setblock ~15 ~10 ~20 stone_brick_stairs 5 
setblock ~15 ~10 ~21 stone_slab 4 
setblock ~15 ~10 ~22 stone_slab 12 
setblock ~15 ~10 ~23 stone_slab 4 
setblock ~15 ~10 ~29 torch 1 
setblock ~15 ~10 ~31 torch 1 
setblock ~15 ~10 ~33 stone_slab 4 
setblock ~15 ~10 ~34 stone_slab 12 
setblock ~15 ~10 ~35 stone_slab 4 
setblock ~15 ~10 ~36 stone_brick_stairs 5 
setblock ~16 ~10 ~24 stone_brick_stairs 1 
setblock ~16 ~10 ~28 stone_brick_stairs 1 
setblock ~24 ~10 ~7 stone_brick_stairs 0 
setblock ~24 ~10 ~9 stone_brick_stairs 0 
setblock ~24 ~10 ~17 stone_brick_stairs 0 
setblock ~25 ~10 ~6 stone_brick_stairs 2  
fill ~25 ~10 ~16 ~26 ~10 ~16 stonebrick  
fill ~25 ~10 ~17 ~26 ~10 ~17 stonebrick 
setblock ~25 ~10 ~18 stone_brick_stairs 3 
setblock ~26 ~10 ~9 stone_brick_stairs 7 
setblock ~26 ~10 ~11 stone_slab 13 
setblock ~26 ~10 ~12 stone_brick_stairs 4 
setblock ~26 ~10 ~13 stone_slab 13 
setblock ~26 ~10 ~15 stone_brick_stairs 6 
setblock ~27 ~10 ~8 stone_brick_stairs 5 
setblock ~27 ~10 ~16 stone_brick_stairs 5  
fill ~28 ~10 ~8 ~30 ~10 ~8 stone_slab  
fill ~28 ~10 ~9 ~31 ~10 ~9 cobblestone  
fill ~28 ~10 ~10 ~31 ~10 ~10 cobblestone  
fill ~28 ~10 ~11 ~31 ~10 ~11 cobblestone  
fill ~28 ~10 ~12 ~28 ~10 ~15 cobblestone  
fill ~28 ~10 ~16 ~30 ~10 ~16 stone_slab  
fill ~29 ~10 ~13 ~31 ~10 ~13 cobblestone  
fill ~29 ~10 ~14 ~31 ~10 ~14 cobblestone  
fill ~29 ~10 ~15 ~31 ~10 ~15 cobblestone  
fill ~29 ~10 ~30 ~29 ~13 ~30 cobblestone_wall  
fill ~29 ~10 ~34 ~29 ~13 ~34 cobblestone_wall 
setblock ~30 ~10 ~12 cobblestone 0 
setblock ~30 ~10 ~29 stone_slab 13  
fill ~30 ~10 ~35 ~30 ~13 ~35 cobblestone_wall 
setblock ~31 ~10 ~8 stone_brick_stairs 4 
setblock ~31 ~10 ~16 stone_brick_stairs 4 
setblock ~31 ~10 ~29 stone_brick_stairs 1 
setblock ~31 ~10 ~30 stonebrick 0  
fill ~31 ~10 ~31 ~33 ~10 ~31 glowstone  
fill ~31 ~10 ~32 ~31 ~14 ~32 glowstone  
fill ~31 ~10 ~33 ~33 ~10 ~33 glowstone  
fill ~31 ~10 ~34 ~34 ~10 ~34 stonebrick  
fill ~32 ~10 ~7 ~33 ~10 ~7 stonebrick  
fill ~32 ~10 ~8 ~33 ~10 ~8 stonebrick 
setblock ~32 ~10 ~9 stone_brick_stairs 7 
setblock ~32 ~10 ~11 stone_slab 13 
setblock ~32 ~10 ~12 stone_brick_stairs 5 
setblock ~32 ~10 ~13 stone_slab 13 
setblock ~32 ~10 ~15 stone_brick_stairs 6  
fill ~32 ~10 ~16 ~33 ~10 ~16 stonebrick  
fill ~32 ~10 ~17 ~33 ~10 ~17 stonebrick 
setblock ~32 ~10 ~29 stone_slab 5 
setblock ~32 ~10 ~35 stone_slab 5 
setblock ~33 ~10 ~6 stone_brick_stairs 2 
setblock ~33 ~10 ~18 stone_brick_stairs 3  
fill ~33 ~10 ~32 ~33 ~14 ~32 glowstone 
setblock ~34 ~10 ~7 stone_brick_stairs 1 
setblock ~34 ~10 ~17 stone_brick_stairs 1  
fill ~34 ~10 ~29 ~34 ~13 ~29 cobblestone_wall  
fill ~34 ~10 ~35 ~34 ~13 ~35 cobblestone_wall  
fill ~35 ~10 ~30 ~35 ~13 ~30 cobblestone_wall 
setblock ~35 ~10 ~32 stone_slab 5  
fill ~35 ~10 ~34 ~35 ~13 ~34 cobblestone_wall 
setblock ~2 ~11 ~19 spruce_stairs 4 
setblock ~2 ~11 ~37 spruce_stairs 4 
setblock ~3 ~11 ~18 spruce_stairs 6  
fill ~3 ~11 ~20 ~3 ~11 ~36 log 
setblock ~3 ~11 ~38 spruce_stairs 7 
setblock ~4 ~11 ~7 stone_brick_stairs 6 
setblock ~4 ~11 ~9 stone_brick_stairs 7  
fill ~4 ~11 ~19 ~14 ~11 ~19 log  
fill ~4 ~11 ~37 ~14 ~11 ~37 log  
fill ~5 ~11 ~7 ~5 ~17 ~7 stonebrick  
fill ~5 ~11 ~9 ~5 ~17 ~9 stonebrick 
setblock ~7 ~11 ~18 spruce_stairs 6 
setblock ~7 ~11 ~38 spruce_stairs 7 
setblock ~8 ~11 ~3 stone_brick_stairs 4  
fill ~8 ~11 ~4 ~8 ~17 ~4 stonebrick  
fill ~8 ~11 ~12 ~8 ~17 ~12 stonebrick 
setblock ~8 ~11 ~13 stone_brick_stairs 4  
fill ~9 ~11 ~12 ~9 ~12 ~12 stonebrick 
setblock ~9 ~11 ~13 stone_slab 5 
setblock ~10 ~11 ~3 stone_brick_stairs 5  
fill ~10 ~11 ~4 ~10 ~17 ~4 stonebrick  
fill ~10 ~11 ~12 ~10 ~17 ~12 stonebrick 
setblock ~10 ~11 ~13 stone_brick_stairs 5 
setblock ~11 ~11 ~18 spruce_stairs 6 
setblock ~11 ~11 ~38 spruce_stairs 7  
fill ~12 ~11 ~5 ~12 ~19 ~5 cobblestone_wall  
fill ~12 ~11 ~11 ~12 ~19 ~11 cobblestone_wall  
fill ~13 ~11 ~7 ~13 ~17 ~7 stonebrick  
fill ~13 ~11 ~9 ~13 ~17 ~9 stonebrick 
setblock ~14 ~11 ~7 stone_brick_stairs 6 
setblock ~14 ~11 ~8 stone_slab 5 
setblock ~14 ~11 ~9 stone_brick_stairs 7 
setblock ~15 ~11 ~18 spruce_stairs 6 
setblock ~15 ~11 ~20 stonebrick 0  
fill ~15 ~11 ~21 ~15 ~11 ~23 log 
setblock ~15 ~11 ~24 stonebrick 0  
fill ~15 ~11 ~25 ~15 ~11 ~27 log 
setblock ~15 ~11 ~28 stonebrick 0  
fill ~15 ~11 ~29 ~15 ~11 ~31 log 
setblock ~15 ~11 ~32 stonebrick 0  
fill ~15 ~11 ~33 ~15 ~11 ~35 log 
setblock ~15 ~11 ~36 stonebrick 0 
setblock ~15 ~11 ~38 spruce_stairs 7 
setblock ~16 ~11 ~18 cobblestone_wall 0 
setblock ~16 ~11 ~20 stone_brick_stairs 5 
setblock ~16 ~11 ~24 stone_brick_stairs 5 
setblock ~16 ~11 ~28 stone_brick_stairs 5 
setblock ~16 ~11 ~32 stone_brick_stairs 5 
setblock ~16 ~11 ~36 stone_brick_stairs 5 
setblock ~16 ~11 ~38 cobblestone_wall 0  
fill ~24 ~11 ~7 ~24 ~11 ~9 stone_brick_stairs  
fill ~24 ~11 ~15 ~25 ~11 ~15 stone_brick_stairs  
fill ~24 ~11 ~16 ~24 ~11 ~17 stone_brick_stairs  
fill ~25 ~11 ~6 ~26 ~11 ~6 stone_brick_stairs  
fill ~25 ~11 ~7 ~26 ~11 ~7 stonebrick  
fill ~25 ~11 ~8 ~26 ~11 ~8 stonebrick 
setblock ~25 ~11 ~9 stone_brick_stairs 7  
fill ~25 ~11 ~10 ~25 ~11 ~14 stone_brick_stairs  
fill ~25 ~11 ~16 ~26 ~11 ~16 stonebrick  
fill ~25 ~11 ~17 ~26 ~11 ~17 stonebrick  
fill ~25 ~11 ~18 ~26 ~11 ~18 stone_brick_stairs  
fill ~26 ~11 ~9 ~26 ~11 ~17 stonebrick  
fill ~27 ~11 ~6 ~27 ~11 ~7 stone_brick_stairs  
fill ~27 ~11 ~8 ~31 ~11 ~8 stone_slab  
fill ~27 ~11 ~16 ~31 ~11 ~16 stone_slab  
fill ~27 ~11 ~17 ~27 ~11 ~18 stone_brick_stairs  
fill ~28 ~11 ~7 ~30 ~11 ~7 stone_brick_stairs  
fill ~28 ~11 ~17 ~30 ~11 ~17 stone_brick_stairs  
fill ~30 ~11 ~29 ~30 ~13 ~29 cobblestone_wall 
setblock ~30 ~11 ~31 stone_brick_stairs 3 
setblock ~30 ~11 ~33 stone_brick_stairs 2  
fill ~31 ~11 ~6 ~31 ~11 ~7 stone_brick_stairs  
fill ~31 ~11 ~17 ~31 ~11 ~18 stone_brick_stairs 
setblock ~31 ~11 ~30 stone_brick_stairs 1  
fill ~31 ~11 ~31 ~33 ~11 ~31 glowstone  
fill ~31 ~11 ~33 ~33 ~11 ~33 glowstone 
setblock ~31 ~11 ~34 stone_brick_stairs 1  
fill ~32 ~11 ~6 ~33 ~11 ~6 stone_brick_stairs  
fill ~32 ~11 ~7 ~33 ~11 ~7 stonebrick  
fill ~32 ~11 ~8 ~33 ~11 ~8 stonebrick  
fill ~32 ~11 ~9 ~32 ~11 ~17 stonebrick  
fill ~32 ~11 ~18 ~33 ~11 ~18 stone_brick_stairs  
fill ~33 ~11 ~9 ~34 ~11 ~9 stone_brick_stairs  
fill ~33 ~11 ~10 ~33 ~11 ~14 stone_brick_stairs  
fill ~33 ~11 ~15 ~34 ~11 ~15 stone_brick_stairs  
fill ~33 ~11 ~16 ~33 ~11 ~17 stonebrick 
setblock ~33 ~11 ~30 stone_brick_stairs 0 
setblock ~33 ~11 ~34 stone_brick_stairs 0  
fill ~34 ~11 ~7 ~34 ~11 ~8 stone_brick_stairs  
fill ~34 ~11 ~16 ~34 ~11 ~17 stone_brick_stairs 
setblock ~34 ~11 ~31 stone_brick_stairs 3 
setblock ~34 ~11 ~33 stone_brick_stairs 2 
setblock ~2 ~12 ~19 spruce_stairs 0  
fill ~2 ~12 ~20 ~2 ~12 ~36 dropper 
setblock ~2 ~12 ~37 spruce_stairs 0 
setblock ~3 ~12 ~18 spruce_stairs 2  
fill ~3 ~12 ~19 ~3 ~15 ~19 stonebrick  
fill ~3 ~12 ~20 ~3 ~12 ~36 stonebrick  
fill ~3 ~12 ~37 ~3 ~15 ~37 stonebrick 
setblock ~3 ~12 ~38 spruce_stairs 3 
setblock ~4 ~12 ~7 cobblestone_wall 0 
setblock ~4 ~12 ~9 cobblestone_wall 0 
setblock ~4 ~12 ~18 spruce_stairs 5  
fill ~4 ~12 ~19 ~14 ~12 ~19 wool  
fill ~4 ~12 ~37 ~14 ~12 ~37 wool 
setblock ~4 ~12 ~38 spruce_stairs 5 
setblock ~5 ~12 ~18 fence 0 
setblock ~5 ~12 ~38 fence 0 
setblock ~6 ~12 ~18 spruce_stairs 4 
setblock ~6 ~12 ~38 spruce_stairs 4 
setblock ~7 ~12 ~18 spruce_stairs 2 
setblock ~7 ~12 ~38 spruce_stairs 3 
setblock ~8 ~12 ~3 cobblestone_wall 0 
setblock ~8 ~12 ~13 cobblestone_wall 0 
setblock ~8 ~12 ~18 spruce_stairs 5 
setblock ~8 ~12 ~38 spruce_stairs 5 
setblock ~9 ~12 ~18 fence 0 
setblock ~9 ~12 ~38 fence 0 
setblock ~10 ~12 ~3 cobblestone_wall 0 
setblock ~10 ~12 ~13 cobblestone_wall 0 
setblock ~10 ~12 ~18 spruce_stairs 4 
setblock ~10 ~12 ~38 spruce_stairs 4 
setblock ~11 ~12 ~18 spruce_stairs 2 
setblock ~11 ~12 ~38 spruce_stairs 3 
setblock ~12 ~12 ~18 spruce_stairs 5 
setblock ~12 ~12 ~38 spruce_stairs 5 
setblock ~13 ~12 ~18 fence 0 
setblock ~13 ~12 ~38 fence 0 
setblock ~14 ~12 ~7 cobblestone_wall 0 
setblock ~14 ~12 ~9 cobblestone_wall 0 
setblock ~14 ~12 ~18 spruce_stairs 4  
fill ~14 ~12 ~20 ~14 ~12 ~36 cobblestone 
setblock ~14 ~12 ~38 spruce_stairs 4 
setblock ~15 ~12 ~18 spruce_stairs 1  
fill ~15 ~12 ~20 ~15 ~12 ~36 stonebrick 
setblock ~15 ~12 ~38 spruce_stairs 1 
setblock ~16 ~12 ~18 stone_slab 5 
setblock ~16 ~12 ~19 stone_brick_stairs 7 
setblock ~16 ~12 ~20 stonebrick 0  
fill ~16 ~12 ~21 ~16 ~13 ~21 stone_brick_stairs 
setblock ~16 ~12 ~22 stonebrick 0  
fill ~16 ~12 ~23 ~16 ~13 ~23 stone_brick_stairs 
setblock ~16 ~12 ~24 stonebrick 0  
fill ~16 ~12 ~25 ~16 ~13 ~25 stone_brick_stairs 
setblock ~16 ~12 ~26 stonebrick 0  
fill ~16 ~12 ~27 ~16 ~13 ~27 stone_brick_stairs 
setblock ~16 ~12 ~28 stonebrick 0  
fill ~16 ~12 ~29 ~16 ~13 ~29 stone_brick_stairs 
setblock ~16 ~12 ~30 stonebrick 0  
fill ~16 ~12 ~31 ~16 ~13 ~31 stone_brick_stairs 
setblock ~16 ~12 ~32 stonebrick 0  
fill ~16 ~12 ~33 ~16 ~13 ~33 stone_brick_stairs 
setblock ~16 ~12 ~34 stonebrick 0  
fill ~16 ~12 ~35 ~16 ~13 ~35 stone_brick_stairs 
setblock ~16 ~12 ~36 stonebrick 0 
setblock ~16 ~12 ~37 stone_brick_stairs 6 
setblock ~16 ~12 ~38 stone_slab 5 
setblock ~17 ~12 ~24 stone_brick_stairs 5 
setblock ~17 ~12 ~28 stone_brick_stairs 5 
setblock ~17 ~12 ~32 stone_brick_stairs 5  
fill ~23 ~12 ~7 ~23 ~13 ~7 double_stone_slab  
fill ~23 ~12 ~8 ~23 ~13 ~8 stone_slab  
fill ~23 ~12 ~9 ~23 ~13 ~9 double_stone_slab  
fill ~23 ~12 ~15 ~23 ~13 ~15 double_stone_slab  
fill ~23 ~12 ~16 ~23 ~13 ~16 stone_slab  
fill ~23 ~12 ~17 ~23 ~13 ~17 double_stone_slab  
fill ~24 ~12 ~6 ~24 ~13 ~6 stone_slab  
fill ~24 ~12 ~7 ~24 ~12 ~9 stone  
fill ~24 ~12 ~10 ~24 ~13 ~10 stone_slab  
fill ~24 ~12 ~11 ~24 ~13 ~11 double_stone_slab  
fill ~24 ~12 ~12 ~24 ~13 ~12 stone_slab  
fill ~24 ~12 ~13 ~24 ~13 ~13 double_stone_slab  
fill ~24 ~12 ~14 ~24 ~13 ~14 stone_slab  
fill ~24 ~12 ~15 ~24 ~12 ~17 stone  
fill ~24 ~12 ~18 ~24 ~13 ~18 stone_slab  
fill ~25 ~12 ~5 ~25 ~13 ~5 double_stone_slab  
fill ~25 ~12 ~6 ~27 ~12 ~6 stone  
fill ~25 ~12 ~7 ~27 ~12 ~7 stone_slab  
fill ~25 ~12 ~8 ~33 ~12 ~8 stone_slab  
fill ~25 ~12 ~9 ~33 ~12 ~9 stone_slab  
fill ~25 ~12 ~10 ~25 ~12 ~14 stone  
fill ~25 ~12 ~15 ~33 ~12 ~15 stone_slab  
fill ~25 ~12 ~16 ~33 ~12 ~16 stone_slab  
fill ~25 ~12 ~17 ~27 ~12 ~17 stone_slab  
fill ~25 ~12 ~18 ~27 ~12 ~18 stone  
fill ~25 ~12 ~19 ~25 ~13 ~19 double_stone_slab  
fill ~26 ~12 ~5 ~26 ~13 ~5 stone_slab  
fill ~26 ~12 ~10 ~32 ~12 ~10 stone_slab  
fill ~26 ~12 ~11 ~32 ~12 ~11 stone_slab  
fill ~26 ~12 ~12 ~32 ~12 ~12 stone_slab  
fill ~26 ~12 ~13 ~32 ~12 ~13 stone_slab  
fill ~26 ~12 ~14 ~32 ~12 ~14 stone_slab  
fill ~26 ~12 ~19 ~26 ~13 ~19 stone_slab  
fill ~27 ~12 ~5 ~27 ~13 ~5 double_stone_slab  
fill ~27 ~12 ~19 ~27 ~13 ~19 double_stone_slab  
fill ~28 ~12 ~6 ~28 ~13 ~6 stone_slab  
fill ~28 ~12 ~7 ~30 ~12 ~7 stone  
fill ~28 ~12 ~17 ~30 ~12 ~17 stone  
fill ~28 ~12 ~18 ~28 ~13 ~18 stone_slab  
fill ~29 ~12 ~6 ~29 ~13 ~6 double_stone_slab  
fill ~29 ~12 ~18 ~29 ~13 ~18 double_stone_slab  
fill ~30 ~12 ~6 ~30 ~13 ~6 stone_slab  
fill ~30 ~12 ~18 ~30 ~13 ~18 stone_slab  
fill ~30 ~12 ~31 ~30 ~13 ~31 stone_brick_stairs  
fill ~30 ~12 ~33 ~30 ~13 ~33 stone_brick_stairs  
fill ~31 ~12 ~5 ~31 ~13 ~5 double_stone_slab  
fill ~31 ~12 ~6 ~33 ~12 ~6 stone  
fill ~31 ~12 ~7 ~33 ~12 ~7 stone_slab  
fill ~31 ~12 ~17 ~33 ~12 ~17 stone_slab  
fill ~31 ~12 ~18 ~33 ~12 ~18 stone  
fill ~31 ~12 ~19 ~31 ~13 ~19 double_stone_slab  
fill ~31 ~12 ~30 ~31 ~13 ~30 stone_brick_stairs  
fill ~31 ~12 ~31 ~33 ~12 ~31 glowstone  
fill ~31 ~12 ~33 ~33 ~12 ~33 glowstone  
fill ~31 ~12 ~34 ~31 ~13 ~34 stone_brick_stairs  
fill ~32 ~12 ~5 ~32 ~13 ~5 stone_slab  
fill ~32 ~12 ~19 ~32 ~13 ~19 stone_slab  
fill ~33 ~12 ~5 ~33 ~13 ~5 double_stone_slab  
fill ~33 ~12 ~10 ~33 ~12 ~14 stone  
fill ~33 ~12 ~19 ~33 ~13 ~19 double_stone_slab  
fill ~33 ~12 ~30 ~33 ~13 ~30 stone_brick_stairs  
fill ~33 ~12 ~34 ~33 ~13 ~34 stone_brick_stairs  
fill ~34 ~12 ~6 ~34 ~13 ~6 stone_slab  
fill ~34 ~12 ~7 ~34 ~12 ~9 stone  
fill ~34 ~12 ~10 ~34 ~13 ~10 stone_slab  
fill ~34 ~12 ~11 ~34 ~13 ~11 double_stone_slab  
fill ~34 ~12 ~12 ~34 ~13 ~12 stone_slab  
fill ~34 ~12 ~13 ~34 ~13 ~13 double_stone_slab  
fill ~34 ~12 ~14 ~34 ~13 ~14 stone_slab  
fill ~34 ~12 ~15 ~34 ~12 ~17 stone  
fill ~34 ~12 ~18 ~34 ~13 ~18 stone_slab  
fill ~34 ~12 ~31 ~34 ~13 ~31 stone_brick_stairs  
fill ~34 ~12 ~33 ~34 ~13 ~33 stone_brick_stairs  
fill ~35 ~12 ~7 ~35 ~13 ~7 double_stone_slab  
fill ~35 ~12 ~8 ~35 ~13 ~8 stone_slab  
fill ~35 ~12 ~9 ~35 ~13 ~9 double_stone_slab  
fill ~35 ~12 ~15 ~35 ~13 ~15 double_stone_slab  
fill ~35 ~12 ~16 ~35 ~13 ~16 stone_slab  
fill ~35 ~12 ~17 ~35 ~13 ~17 double_stone_slab  
fill ~2 ~13 ~18 ~3 ~13 ~18 stone_brick_stairs  
fill ~2 ~13 ~19 ~2 ~15 ~19 stonebrick  
fill ~2 ~13 ~20 ~2 ~14 ~20 stone_slab 
setblock ~2 ~13 ~21 stone_brick_stairs 0  
fill ~2 ~13 ~22 ~2 ~14 ~22 stone_slab 
setblock ~2 ~13 ~23 stone_brick_stairs 0  
fill ~2 ~13 ~24 ~2 ~14 ~24 stone_slab 
setblock ~2 ~13 ~25 stone_brick_stairs 0 
setblock ~2 ~13 ~26 stone_slab 5 
setblock ~2 ~13 ~27 stone_brick_stairs 0  
fill ~2 ~13 ~28 ~2 ~14 ~28 stone_slab 
setblock ~2 ~13 ~29 stone_brick_stairs 0 
setblock ~2 ~13 ~30 stone_slab 5 
setblock ~2 ~13 ~31 stone_brick_stairs 0  
fill ~2 ~13 ~32 ~2 ~14 ~32 stone_slab 
setblock ~2 ~13 ~33 stone_brick_stairs 0  
fill ~2 ~13 ~34 ~2 ~14 ~34 stone_slab 
setblock ~2 ~13 ~35 stone_brick_stairs 0  
fill ~2 ~13 ~36 ~2 ~14 ~36 stone_slab  
fill ~2 ~13 ~37 ~2 ~15 ~37 stonebrick  
fill ~2 ~13 ~38 ~3 ~13 ~38 stone_brick_stairs  
fill ~3 ~13 ~20 ~3 ~14 ~20 sandstone  
fill ~3 ~13 ~21 ~3 ~14 ~21 sandstone  
fill ~3 ~13 ~22 ~3 ~16 ~22 sandstone  
fill ~3 ~13 ~23 ~3 ~14 ~23 sandstone  
fill ~3 ~13 ~24 ~3 ~14 ~24 sandstone  
fill ~3 ~13 ~25 ~3 ~14 ~25 sandstone  
fill ~3 ~13 ~26 ~3 ~18 ~26 sandstone  
fill ~3 ~13 ~27 ~3 ~14 ~27 sandstone  
fill ~3 ~13 ~28 ~3 ~15 ~28 sandstone  
fill ~3 ~13 ~29 ~3 ~14 ~29 sandstone  
fill ~3 ~13 ~30 ~3 ~18 ~30 sandstone  
fill ~3 ~13 ~31 ~3 ~14 ~31 sandstone  
fill ~3 ~13 ~32 ~3 ~14 ~32 sandstone  
fill ~3 ~13 ~33 ~3 ~14 ~33 sandstone  
fill ~3 ~13 ~34 ~3 ~16 ~34 sandstone  
fill ~3 ~13 ~35 ~3 ~14 ~35 sandstone  
fill ~3 ~13 ~36 ~3 ~14 ~36 sandstone  
fill ~4 ~13 ~18 ~7 ~13 ~18 brick_stairs  
fill ~4 ~13 ~38 ~7 ~13 ~38 brick_stairs 
setblock ~5 ~13 ~8 stone_brick_stairs 4 
setblock ~8 ~13 ~17 stone_slab 5  
fill ~8 ~13 ~18 ~8 ~13 ~19 stonebrick  
fill ~8 ~13 ~37 ~8 ~14 ~37 stonebrick  
fill ~8 ~13 ~38 ~8 ~13 ~37 stonebrick 
setblock ~8 ~13 ~39 stone_slab 5 
setblock ~9 ~13 ~4 stone_brick_stairs 6 
setblock ~9 ~13 ~12 stone_brick_stairs 7  
fill ~9 ~13 ~18 ~12 ~13 ~18 brick_stairs  
fill ~9 ~13 ~38 ~12 ~13 ~38 brick_stairs 
setblock ~13 ~13 ~8 stone_brick_stairs 5  
fill ~13 ~13 ~18 ~14 ~13 ~18 stone_brick_stairs  
fill ~13 ~13 ~19 ~14 ~13 ~19 stonebrick  
fill ~13 ~13 ~20 ~13 ~14 ~20 sandstone  
fill ~13 ~13 ~21 ~13 ~13 ~23 iron_bars  
fill ~13 ~13 ~24 ~13 ~14 ~24 sandstone  
fill ~13 ~13 ~25 ~13 ~13 ~27 iron_bars 
setblock ~13 ~13 ~28 sandstone 0  
fill ~13 ~13 ~29 ~13 ~13 ~31 iron_bars  
fill ~13 ~13 ~32 ~13 ~14 ~32 sandstone  
fill ~13 ~13 ~33 ~13 ~13 ~35 iron_bars  
fill ~13 ~13 ~36 ~13 ~14 ~36 sandstone  
fill ~13 ~13 ~37 ~14 ~13 ~37 stonebrick  
fill ~13 ~13 ~38 ~14 ~13 ~38 stone_brick_stairs  
fill ~14 ~13 ~20 ~16 ~13 ~20 dropper  
fill ~14 ~13 ~21 ~17 ~13 ~21 stone_brick_stairs  
fill ~14 ~13 ~23 ~17 ~13 ~23 stone_brick_stairs  
fill ~14 ~13 ~24 ~16 ~13 ~24 stone_slab  
fill ~14 ~13 ~25 ~17 ~13 ~25 stone_brick_stairs  
fill ~14 ~13 ~27 ~17 ~13 ~27 stone_brick_stairs  
fill ~14 ~13 ~28 ~16 ~13 ~28 stone_slab  
fill ~14 ~13 ~29 ~17 ~13 ~29 stone_brick_stairs  
fill ~14 ~13 ~31 ~17 ~13 ~31 stone_brick_stairs  
fill ~14 ~13 ~32 ~16 ~13 ~32 stone_slab  
fill ~14 ~13 ~33 ~17 ~13 ~33 stone_brick_stairs  
fill ~14 ~13 ~35 ~17 ~13 ~35 stone_brick_stairs  
fill ~14 ~13 ~36 ~16 ~13 ~36 dropper 
setblock ~15 ~13 ~19 stone_brick_stairs 5 
setblock ~15 ~13 ~37 stone_brick_stairs 5 
setblock ~16 ~13 ~19 stone_brick_stairs 6 
setblock ~16 ~13 ~37 stone_brick_stairs 7 
setblock ~17 ~13 ~20 stone_brick_stairs 5 
setblock ~17 ~13 ~24 stone_brick_stairs 1 
setblock ~17 ~13 ~28 stone_brick_stairs 1 
setblock ~17 ~13 ~32 stone_brick_stairs 1 
setblock ~17 ~13 ~36 stone_brick_stairs 5  
fill ~31 ~13 ~31 ~33 ~13 ~31 glowstone  
fill ~31 ~13 ~33 ~33 ~13 ~33 glowstone 
setblock ~2 ~14 ~21 stone_slab 5 
setblock ~2 ~14 ~23 stone_slab 5 
setblock ~2 ~14 ~25 stone_slab 5 
setblock ~2 ~14 ~26 double_stone_slab 5 
setblock ~2 ~14 ~27 stone_slab 5 
setblock ~2 ~14 ~29 stone_slab 5 
setblock ~2 ~14 ~30 double_stone_slab 5 
setblock ~2 ~14 ~31 stone_slab 5 
setblock ~2 ~14 ~33 stone_slab 5 
setblock ~2 ~14 ~35 stone_slab 5  
fill ~4 ~14 ~19 ~7 ~14 ~19 brick_stairs  
fill ~4 ~14 ~37 ~7 ~14 ~37 brick_stairs  
fill ~5 ~14 ~8 ~5 ~15 ~8 iron_bars  
fill ~6 ~14 ~8 ~6 ~15 ~8 glowstone 
setblock ~8 ~14 ~18 cobblestone_wall 0 
setblock ~8 ~14 ~19 stonebrick 0 
setblock ~8 ~14 ~38 cobblestone_wall 0  
fill ~9 ~14 ~4 ~9 ~15 ~4 iron_bars  
fill ~9 ~14 ~5 ~9 ~15 ~5 glowstone  
fill ~9 ~14 ~11 ~9 ~15 ~11 glowstone  
fill ~9 ~14 ~12 ~9 ~15 ~12 iron_bars  
fill ~9 ~14 ~19 ~12 ~14 ~19 brick_stairs  
fill ~9 ~14 ~37 ~12 ~14 ~37 brick_stairs  
fill ~12 ~14 ~8 ~12 ~15 ~8 glowstone  
fill ~13 ~14 ~8 ~13 ~15 ~8 iron_bars  
fill ~13 ~14 ~19 ~14 ~14 ~19 stonebrick 
setblock ~13 ~14 ~21 sandstone 0 
setblock ~13 ~14 ~23 sandstone 0 
setblock ~13 ~14 ~25 sandstone 0 
setblock ~13 ~14 ~27 sandstone 0 
setblock ~13 ~14 ~28 sandstone 1 
setblock ~13 ~14 ~29 sandstone 0 
setblock ~13 ~14 ~31 sandstone 0 
setblock ~13 ~14 ~33 sandstone 0 
setblock ~13 ~14 ~35 sandstone 0  
fill ~13 ~14 ~37 ~14 ~14 ~37 stonebrick  
fill ~14 ~14 ~21 ~16 ~14 ~21 spruce_stairs  
fill ~14 ~14 ~22 ~16 ~14 ~22 planks  
fill ~14 ~14 ~23 ~16 ~14 ~23 spruce_stairs  
fill ~14 ~14 ~25 ~16 ~14 ~25 spruce_stairs  
fill ~14 ~14 ~26 ~16 ~14 ~26 planks  
fill ~14 ~14 ~27 ~16 ~14 ~27 spruce_stairs  
fill ~14 ~14 ~29 ~16 ~14 ~29 spruce_stairs  
fill ~14 ~14 ~30 ~16 ~14 ~30 planks  
fill ~14 ~14 ~31 ~16 ~14 ~31 spruce_stairs  
fill ~14 ~14 ~33 ~16 ~14 ~33 spruce_stairs  
fill ~14 ~14 ~34 ~16 ~14 ~34 planks  
fill ~14 ~14 ~35 ~16 ~14 ~35 spruce_stairs 
setblock ~15 ~14 ~19 stone_slab 5 
setblock ~15 ~14 ~37 stone_slab 5 
setblock ~17 ~14 ~21 stone_brick_stairs 2 
setblock ~17 ~14 ~22 stone_brick_stairs 5 
setblock ~17 ~14 ~23 stone_brick_stairs 3 
setblock ~17 ~14 ~25 stone_brick_stairs 2 
setblock ~17 ~14 ~26 stone_brick_stairs 5 
setblock ~17 ~14 ~27 stone_brick_stairs 3 
setblock ~17 ~14 ~29 stone_brick_stairs 2 
setblock ~17 ~14 ~30 stone_brick_stairs 5 
setblock ~17 ~14 ~31 stone_brick_stairs 3 
setblock ~17 ~14 ~33 stone_brick_stairs 2 
setblock ~17 ~14 ~34 stone_brick_stairs 5 
setblock ~17 ~14 ~35 stone_brick_stairs 3 
setblock ~23 ~14 ~7 cobblestone_wall 0 
setblock ~23 ~14 ~17 cobblestone_wall 0 
setblock ~25 ~14 ~5 cobblestone_wall 0 
setblock ~25 ~14 ~19 cobblestone_wall 0  
fill ~29 ~14 ~30 ~29 ~15 ~30 stone_slab  
fill ~29 ~14 ~31 ~29 ~15 ~31 stone_slab  
fill ~29 ~14 ~33 ~29 ~15 ~33 stone_slab  
fill ~29 ~14 ~34 ~29 ~15 ~34 stone_slab  
fill ~30 ~14 ~29 ~30 ~15 ~29 stone_slab  
fill ~30 ~14 ~31 ~30 ~17 ~31 stonebrick  
fill ~30 ~14 ~32 ~30 ~17 ~32 stonebrick  
fill ~30 ~14 ~33 ~30 ~17 ~33 stonebrick  
fill ~30 ~14 ~35 ~30 ~15 ~35 stone_slab  
fill ~31 ~14 ~29 ~31 ~15 ~29 stone_slab  
fill ~31 ~14 ~30 ~34 ~14 ~30 stonebrick  
fill ~31 ~14 ~31 ~33 ~14 ~31 glowstone  
fill ~31 ~14 ~33 ~33 ~14 ~33 glowstone  
fill ~31 ~14 ~34 ~34 ~14 ~34 stonebrick  
fill ~31 ~14 ~35 ~31 ~15 ~35 stone_slab 
setblock ~33 ~14 ~5 cobblestone_wall 0 
setblock ~33 ~14 ~19 cobblestone_wall 0  
fill ~33 ~14 ~29 ~33 ~15 ~29 stone_slab  
fill ~33 ~14 ~35 ~33 ~15 ~35 stone_slab  
fill ~34 ~14 ~29 ~34 ~15 ~29 stone_slab  
fill ~34 ~14 ~31 ~34 ~17 ~31 stonebrick  
fill ~34 ~14 ~32 ~34 ~17 ~32 stonebrick  
fill ~34 ~14 ~33 ~34 ~17 ~33 stonebrick  
fill ~34 ~14 ~35 ~34 ~15 ~35 stone_slab 
setblock ~35 ~14 ~7 cobblestone_wall 0 
setblock ~35 ~14 ~17 cobblestone_wall 0  
fill ~35 ~14 ~30 ~35 ~15 ~30 stone_slab  
fill ~35 ~14 ~31 ~35 ~15 ~31 stone_slab  
fill ~35 ~14 ~33 ~35 ~15 ~33 stone_slab  
fill ~35 ~14 ~34 ~35 ~15 ~34 stone_slab  
fill ~2 ~15 ~18 ~3 ~15 ~18 stone_brick_stairs 
setblock ~2 ~15 ~20 stone_brick_stairs 7 
setblock ~2 ~15 ~21 stone_brick_stairs 6  
fill ~2 ~15 ~26 ~2 ~16 ~26 cobblestone_wall  
fill ~2 ~15 ~30 ~2 ~16 ~30 cobblestone_wall 
setblock ~2 ~15 ~35 stone_brick_stairs 7 
setblock ~2 ~15 ~36 stone_brick_stairs 6  
fill ~2 ~15 ~38 ~3 ~15 ~38 stone_brick_stairs  
fill ~3 ~15 ~20 ~3 ~15 ~21 stonebrick 
setblock ~3 ~15 ~23 sandstone_stairs 3 
setblock ~3 ~15 ~25 sandstone_stairs 2 
setblock ~3 ~15 ~27 sandstone 1 
setblock ~3 ~15 ~29 sandstone 1 
setblock ~3 ~15 ~31 sandstone_stairs 3 
setblock ~3 ~15 ~33 sandstone_stairs 2  
fill ~3 ~15 ~35 ~3 ~17 ~35 stonebrick  
fill ~3 ~15 ~36 ~3 ~15 ~35 stonebrick  
fill ~4 ~15 ~20 ~7 ~15 ~20 brick_stairs  
fill ~4 ~15 ~23 ~4 ~16 ~23 cobblestone  
fill ~4 ~15 ~24 ~4 ~16 ~24 cobblestone  
fill ~4 ~15 ~25 ~4 ~16 ~25 cobblestone  
fill ~4 ~15 ~26 ~4 ~16 ~26 cobblestone  
fill ~4 ~15 ~27 ~4 ~20 ~27 cobblestone  
fill ~4 ~15 ~28 ~4 ~20 ~28 cobblestone  
fill ~4 ~15 ~29 ~4 ~20 ~29 cobblestone  
fill ~4 ~15 ~30 ~4 ~16 ~30 cobblestone  
fill ~4 ~15 ~31 ~4 ~16 ~31 cobblestone  
fill ~4 ~15 ~32 ~4 ~16 ~32 cobblestone  
fill ~4 ~15 ~33 ~4 ~16 ~33 cobblestone  
fill ~4 ~15 ~36 ~7 ~15 ~36 brick_stairs 
setblock ~8 ~15 ~19 cobblestone_wall 0 
setblock ~8 ~15 ~20 stonebrick 0 
setblock ~8 ~15 ~36 stonebrick 0 
setblock ~8 ~15 ~37 cobblestone_wall 0  
fill ~9 ~15 ~20 ~12 ~15 ~20 brick_stairs  
fill ~9 ~15 ~36 ~12 ~15 ~36 brick_stairs  
fill ~12 ~15 ~23 ~12 ~16 ~23 cobblestone  
fill ~12 ~15 ~24 ~12 ~16 ~24 cobblestone  
fill ~12 ~15 ~25 ~12 ~16 ~25 cobblestone  
fill ~12 ~15 ~27 ~12 ~20 ~27 cobblestone  
fill ~12 ~15 ~28 ~12 ~20 ~28 cobblestone  
fill ~12 ~15 ~29 ~12 ~20 ~29 cobblestone  
fill ~12 ~15 ~31 ~12 ~16 ~31 cobblestone  
fill ~12 ~15 ~32 ~12 ~16 ~32 cobblestone  
fill ~12 ~15 ~33 ~12 ~16 ~33 cobblestone  
fill ~13 ~15 ~18 ~14 ~15 ~18 stone_brick_stairs  
fill ~13 ~15 ~19 ~14 ~15 ~19 stonebrick  
fill ~13 ~15 ~20 ~13 ~15 ~21 stonebrick  
fill ~13 ~15 ~22 ~13 ~16 ~22 sandstone 
setblock ~13 ~15 ~23 sandstone_stairs 3 
setblock ~13 ~15 ~25 sandstone_stairs 2  
fill ~13 ~15 ~26 ~13 ~18 ~26 sandstone 
setblock ~13 ~15 ~27 sandstone 1 
setblock ~13 ~15 ~28 sandstone 0 
setblock ~13 ~15 ~29 sandstone 1  
fill ~13 ~15 ~30 ~13 ~18 ~30 sandstone 
setblock ~13 ~15 ~31 sandstone_stairs 3 
setblock ~13 ~15 ~33 sandstone_stairs 2  
fill ~13 ~15 ~34 ~13 ~16 ~34 sandstone  
fill ~13 ~15 ~35 ~13 ~17 ~35 stonebrick  
fill ~13 ~15 ~36 ~13 ~15 ~37 stonebrick  
fill ~13 ~15 ~38 ~14 ~15 ~38 stone_brick_stairs 
setblock ~14 ~15 ~20 stone_brick_stairs 7 
setblock ~14 ~15 ~21 stone_brick_stairs 6  
fill ~14 ~15 ~22 ~15 ~15 ~22 dropper 
setblock ~14 ~15 ~26 activator_rail 0 
setblock ~14 ~15 ~30 activator_rail 0  
fill ~14 ~15 ~34 ~15 ~15 ~34 dropper 
setblock ~14 ~15 ~35 stone_brick_stairs 7 
setblock ~14 ~15 ~36 stone_brick_stairs 6 
setblock ~14 ~15 ~37 stonebrick 0 
setblock ~15 ~15 ~26 dropper 0 
setblock ~15 ~15 ~30 dropper 0 
setblock ~16 ~15 ~22 spruce_stairs 0 
setblock ~16 ~15 ~26 spruce_stairs 0 
setblock ~16 ~15 ~30 spruce_stairs 0 
setblock ~16 ~15 ~34 spruce_stairs 0 
setblock ~17 ~15 ~22 stonebrick 0 
setblock ~17 ~15 ~26 stonebrick 0 
setblock ~17 ~15 ~30 stonebrick 0 
setblock ~17 ~15 ~34 stonebrick 0 
setblock ~28 ~15 ~29 cobblestone_wall 0 
setblock ~28 ~15 ~35 cobblestone_wall 0 
setblock ~29 ~15 ~28 cobblestone_wall 0 
setblock ~29 ~15 ~32 stone_brick_stairs 4 
setblock ~29 ~15 ~36 cobblestone_wall 0  
fill ~31 ~15 ~30 ~34 ~15 ~30 stonebrick  
fill ~31 ~15 ~34 ~34 ~15 ~34 stonebrick 
setblock ~32 ~15 ~29 stone_brick_stairs 6 
setblock ~32 ~15 ~35 stone_brick_stairs 7 
setblock ~35 ~15 ~28 cobblestone_wall 0 
setblock ~35 ~15 ~32 stone_brick_stairs 5 
setblock ~35 ~15 ~36 cobblestone_wall 0 
setblock ~36 ~15 ~29 cobblestone_wall 0 
setblock ~36 ~15 ~35 cobblestone_wall 0 
setblock ~2 ~16 ~19 cobblestone_wall 0  
fill ~2 ~16 ~20 ~3 ~16 ~20 stone_slab  
fill ~2 ~16 ~21 ~3 ~16 ~21 stonebrick  
fill ~2 ~16 ~35 ~2 ~17 ~35 stonebrick  
fill ~2 ~16 ~36 ~3 ~16 ~36 stone_slab 
setblock ~2 ~16 ~37 cobblestone_wall 0 
setblock ~3 ~16 ~23 sandstone 0 
setblock ~3 ~16 ~24 stone_slab 9  
fill ~3 ~16 ~25 ~3 ~18 ~25 sandstone 
setblock ~3 ~16 ~27 sandstone_stairs 3 
setblock ~3 ~16 ~29 sandstone_stairs 2  
fill ~3 ~16 ~31 ~3 ~18 ~31 sandstone 
setblock ~3 ~16 ~32 stone_slab 9 
setblock ~3 ~16 ~33 sandstone 0  
fill ~4 ~16 ~21 ~7 ~16 ~21 stone_brick_stairs  
fill ~4 ~16 ~35 ~7 ~16 ~35 stone_brick_stairs 
setblock ~5 ~16 ~8 stone_brick_stairs 0 
setblock ~8 ~16 ~20 cobblestone_wall 0 
setblock ~8 ~16 ~21 stonebrick 0 
setblock ~8 ~16 ~35 stonebrick 0 
setblock ~8 ~16 ~36 cobblestone_wall 0 
setblock ~9 ~16 ~4 stone_brick_stairs 2 
setblock ~9 ~16 ~12 stone_brick_stairs 3  
fill ~9 ~16 ~21 ~12 ~16 ~21 stone_brick_stairs  
fill ~9 ~16 ~35 ~12 ~16 ~35 stone_brick_stairs 
setblock ~13 ~16 ~8 stone_brick_stairs 1  
fill ~13 ~16 ~20 ~14 ~16 ~20 stone_slab  
fill ~13 ~16 ~21 ~14 ~16 ~21 stonebrick 
setblock ~13 ~16 ~23 sandstone 0 
setblock ~13 ~16 ~24 stone_slab 9  
fill ~13 ~16 ~25 ~13 ~18 ~25 sandstone 
setblock ~13 ~16 ~27 sandstone_stairs 3 
setblock ~13 ~16 ~29 sandstone_stairs 2  
fill ~13 ~16 ~31 ~13 ~18 ~31 sandstone 
setblock ~13 ~16 ~32 stone_slab 9 
setblock ~13 ~16 ~33 sandstone 0  
fill ~13 ~16 ~36 ~14 ~16 ~36 stone_slab 
setblock ~14 ~16 ~19 cobblestone_wall 0 
setblock ~14 ~16 ~26 cobblestone_wall 0 
setblock ~14 ~16 ~30 cobblestone_wall 0  
fill ~14 ~16 ~35 ~14 ~17 ~35 stonebrick 
setblock ~14 ~16 ~37 cobblestone_wall 0 
setblock ~17 ~16 ~22 cobblestone_wall 0 
setblock ~17 ~16 ~26 cobblestone_wall 0 
setblock ~17 ~16 ~30 cobblestone_wall 0 
setblock ~17 ~16 ~34 cobblestone_wall 0 
setblock ~28 ~16 ~29 stone_brick_stairs 0 
setblock ~28 ~16 ~35 stone_brick_stairs 0 
setblock ~29 ~16 ~28 stone_brick_stairs 2  
fill ~29 ~16 ~32 ~29 ~17 ~32 stonebrick 
setblock ~29 ~16 ~36 stone_brick_stairs 3  
fill ~31 ~16 ~30 ~34 ~16 ~30 stonebrick  
fill ~31 ~16 ~34 ~34 ~16 ~34 stonebrick  
fill ~32 ~16 ~29 ~32 ~17 ~29 stonebrick  
fill ~32 ~16 ~35 ~32 ~17 ~35 stonebrick  

KittysCommands:  
setblock ~35 ~16 ~28 stone_brick_stairs 2  
fill ~35 ~16 ~32 ~35 ~17 ~32 stonebrick 
setblock ~35 ~16 ~36 stone_brick_stairs 3 
setblock ~36 ~16 ~29 stone_brick_stairs 1 
setblock ~36 ~16 ~35 stone_brick_stairs 1  
fill ~2 ~17 ~20 ~3 ~17 ~20 stone_brick_stairs  
fill ~2 ~17 ~21 ~3 ~17 ~21 stonebrick 
setblock ~2 ~17 ~22 stone_brick_stairs 7 
setblock ~2 ~17 ~23 stone_brick_stairs 6 
setblock ~2 ~17 ~24 stone_slab 13 
setblock ~2 ~17 ~26 stone_brick_stairs 2 
setblock ~2 ~17 ~30 stone_brick_stairs 3 
setblock ~2 ~17 ~32 stone_slab 13 
setblock ~2 ~17 ~33 stone_brick_stairs 7 
setblock ~2 ~17 ~34 stone_brick_stairs 6  
fill ~2 ~17 ~36 ~3 ~17 ~36 stone_brick_stairs  
fill ~3 ~17 ~22 ~3 ~17 ~23 stonebrick  
fill ~3 ~17 ~24 ~3 ~18 ~24 sandstone 
setblock ~3 ~17 ~27 double_stone_slab 1 
setblock ~3 ~17 ~29 double_stone_slab 1  
fill ~3 ~17 ~32 ~3 ~18 ~32 sandstone  
fill ~3 ~17 ~33 ~3 ~19 ~33 stonebrick  
fill ~3 ~17 ~34 ~3 ~17 ~33 stonebrick 
setblock ~4 ~17 ~7 cobblestone_wall 0 
setblock ~4 ~17 ~9 cobblestone_wall 0  
fill ~4 ~17 ~22 ~7 ~17 ~22 brick_stairs  
fill ~4 ~17 ~34 ~7 ~17 ~34 brick_stairs  
fill ~5 ~17 ~8 ~5 ~20 ~8 stonebrick 
setblock ~8 ~17 ~3 cobblestone_wall 0 
setblock ~8 ~17 ~13 cobblestone_wall 0 
setblock ~8 ~17 ~21 cobblestone_wall 0 
setblock ~8 ~17 ~22 stonebrick 0 
setblock ~8 ~17 ~34 stonebrick 0 
setblock ~8 ~17 ~35 cobblestone_wall 0  
fill ~9 ~17 ~4 ~9 ~20 ~4 stonebrick  
fill ~9 ~17 ~12 ~9 ~20 ~12 stonebrick  
fill ~9 ~17 ~22 ~12 ~17 ~22 brick_stairs  
fill ~9 ~17 ~34 ~12 ~17 ~34 brick_stairs 
setblock ~10 ~17 ~3 cobblestone_wall 0 
setblock ~10 ~17 ~13 cobblestone_wall 0  
fill ~13 ~17 ~8 ~13 ~20 ~8 stonebrick  
fill ~13 ~17 ~20 ~14 ~17 ~20 stone_brick_stairs  
fill ~13 ~17 ~21 ~14 ~17 ~21 stonebrick  
fill ~13 ~17 ~22 ~13 ~17 ~23 stonebrick  
fill ~13 ~17 ~24 ~13 ~18 ~24 sandstone 
setblock ~13 ~17 ~27 double_stone_slab 1 
setblock ~13 ~17 ~29 double_stone_slab 1  
fill ~13 ~17 ~32 ~13 ~18 ~32 sandstone  
fill ~13 ~17 ~33 ~13 ~19 ~33 stonebrick  
fill ~13 ~17 ~34 ~13 ~17 ~33 stonebrick  
fill ~13 ~17 ~36 ~14 ~17 ~36 stone_brick_stairs 
setblock ~14 ~17 ~7 cobblestone_wall 0 
setblock ~14 ~17 ~9 cobblestone_wall 0 
setblock ~14 ~17 ~22 stone_brick_stairs 7 
setblock ~14 ~17 ~23 stone_brick_stairs 6 
setblock ~14 ~17 ~24 stone_slab 13 
setblock ~14 ~17 ~26 stone_brick_stairs 2 
setblock ~14 ~17 ~30 stone_brick_stairs 3 
setblock ~14 ~17 ~32 stone_slab 13 
setblock ~14 ~17 ~33 stone_brick_stairs 7 
setblock ~14 ~17 ~34 stone_brick_stairs 6 
setblock ~28 ~17 ~29 stone_brick_stairs 4 
setblock ~28 ~17 ~32 stone_brick_stairs 4 
setblock ~28 ~17 ~35 stone_brick_stairs 4 
setblock ~29 ~17 ~28 stone_brick_stairs 6 
setblock ~29 ~17 ~30 stone_brick_stairs 7 
setblock ~29 ~17 ~31 stone_brick_stairs 6 
setblock ~29 ~17 ~33 stone_brick_stairs 7 
setblock ~29 ~17 ~34 stone_brick_stairs 6 
setblock ~29 ~17 ~36 stone_brick_stairs 7 
setblock ~30 ~17 ~29 stone_brick_stairs 5 
setblock ~30 ~17 ~35 stone_brick_stairs 5 
setblock ~31 ~17 ~29 stone_brick_stairs 4  
fill ~31 ~17 ~30 ~34 ~17 ~30 stonebrick  
fill ~31 ~17 ~34 ~34 ~17 ~34 stonebrick 
setblock ~31 ~17 ~35 stone_brick_stairs 4 
setblock ~32 ~17 ~28 stone_brick_stairs 6 
setblock ~32 ~17 ~36 stone_brick_stairs 7 
setblock ~33 ~17 ~29 stone_brick_stairs 5 
setblock ~33 ~17 ~35 stone_brick_stairs 5 
setblock ~34 ~17 ~29 stone_brick_stairs 4 
setblock ~34 ~17 ~35 stone_brick_stairs 4 
setblock ~35 ~17 ~28 stone_brick_stairs 6 
setblock ~35 ~17 ~30 stone_brick_stairs 7 
setblock ~35 ~17 ~31 stone_brick_stairs 6 
setblock ~35 ~17 ~33 stone_brick_stairs 7 
setblock ~35 ~17 ~34 stone_brick_stairs 6 
setblock ~35 ~17 ~36 stone_brick_stairs 7 
setblock ~36 ~17 ~29 stone_brick_stairs 5 
setblock ~36 ~17 ~32 stone_brick_stairs 5 
setblock ~36 ~17 ~35 stone_brick_stairs 5 
setblock ~2 ~18 ~21 cobblestone_wall 0  
fill ~2 ~18 ~22 ~3 ~18 ~22 stone_slab  
fill ~2 ~18 ~23 ~3 ~18 ~23 stonebrick 
setblock ~2 ~18 ~26 stone_brick_stairs 6 
setblock ~2 ~18 ~30 stone_brick_stairs 7  
fill ~2 ~18 ~33 ~2 ~19 ~33 stonebrick  
fill ~2 ~18 ~34 ~3 ~18 ~34 stone_slab 
setblock ~2 ~18 ~35 cobblestone_wall 0 
setblock ~3 ~18 ~27 sandstone_stairs 3 
setblock ~3 ~18 ~29 sandstone_stairs 2 
setblock ~4 ~18 ~7 stone_brick_stairs 0 
setblock ~4 ~18 ~9 stone_brick_stairs 0 
setblock ~4 ~18 ~23 brick_stairs 2  
fill ~4 ~18 ~24 ~7 ~18 ~24 iron_bars  
fill ~4 ~18 ~25 ~7 ~18 ~25 iron_bars  
fill ~4 ~18 ~31 ~7 ~18 ~31 iron_bars  
fill ~4 ~18 ~32 ~7 ~18 ~32 iron_bars 
setblock ~4 ~18 ~33 brick_stairs 3  
fill ~5 ~18 ~7 ~5 ~20 ~7 stonebrick  
fill ~5 ~18 ~9 ~5 ~20 ~9 stonebrick 
setblock ~5 ~18 ~23 stone_stairs 1 
setblock ~5 ~18 ~33 stone_stairs 1 
