setblock ~23~16~3 minecraft:leaves 0
fill ~23~17~3 ~23~18~3 minecraft:leaves 0
setblock ~23~19~3 minecraft:leaves 0
fill ~23~23~3 ~23~24~3 minecraft:leaves 0
setblock ~21~10~4 minecraft:leaves 0
fill ~22~11~4 ~22~12~4 minecraft:leaves 0
setblock ~23~13~4 minecraft:leaves 0
setblock ~23~14~4 minecraft:leaves 0
setblock ~23~15~4 minecraft:leaves 0
setblock ~23~20~4 minecraft:leaves 0
setblock ~23~21~4 minecraft:leaves 0
setblock ~23~22~4 minecraft:leaves 0
fill ~23~24~4 ~25~24~4 minecraft:grass
setblock ~23~25~4 minecraft:leaves 0
fill ~24~23~4 ~24~23~18 minecraft:dirt 0
setblock ~25~25~4 minecraft:tallgrass 0
fill ~9~39~5 ~10~39~5 minecraft:grass
setblock ~10~40~5 minecraft:tallgrass 0
setblock ~22~24~5 minecraft:grass
setblock ~22~35~5 minecraft:nether_brick_stairs 4
setblock ~22~37~5 minecraft:nether_brick_stairs 6
setblock ~22~38~5 minecraft:cobblestone_wall 0
fill ~22~39~5 ~22~39~6 minecraft:nether_brick_stairs 0
fill ~22~43~5 ~25~43~5 minecraft:nether_brick_stairs 6
setblock ~22~52~5 minecraft:nether_brick_stairs 4
setblock ~22~55~5 minecraft:stone_block_slab 15
setblock ~22~56~5 minecraft:cobblestone_wall 0
fill ~22~57~5 ~22~57~6 minecraft:nether_brick_stairs 0
setblock ~23~23~5 minecraft:dirt 0
fill ~23~24~5 ~25~24~5 minecraft:stone 0
fill ~23~25~5 ~25~25~6 minecraft:grass
fill ~23~34~5 ~25~34~5 minecraft:nether_brick_stairs 6
setblock ~23~35~5 minecraft:stone_stairs 6
setblock ~23~39~5 minecraft:nether_brick_stairs 5
setblock ~23~40~5 minecraft:nether_brick_stairs 0
fill ~23~52~5 ~25~52~5 minecraft:nether_brick_stairs 6
setblock ~23~57~5 minecraft:nether_brick_stairs 5
setblock ~23~58~5 minecraft:nether_brick_stairs 0
fill ~24~21~5 ~24~22~5 minecraft:dirt 0
fill ~24~26~5 ~25~26~5 minecraft:leaves 0
setblock ~24~35~5 minecraft:stone_stairs 2
setblock ~24~40~5 minecraft:nether_brick_stairs 6
fill ~24~41~5 ~24~41~6 minecraft:stone_block_slab 7
setblock ~24~58~5 minecraft:nether_brick_stairs 6
fill ~24~59~5 ~24~59~6 minecraft:stone_block_slab 7
fill ~25~22~5 ~25~23~5 minecraft:dirt 0
setblock ~25~35~5 minecraft:stone_stairs 6
setblock ~25~39~5 minecraft:nether_brick_stairs 4
setblock ~25~40~5 minecraft:nether_brick_stairs 1
setblock ~25~57~5 minecraft:nether_brick_stairs 4
setblock ~25~58~5 minecraft:nether_brick_stairs 1
setblock ~26~23~5 minecraft:dirt 0
setblock ~26~24~5 minecraft:grass
setblock ~26~25~5 minecraft:leaves 0
setblock ~26~35~5 minecraft:nether_brick_stairs 5
setblock ~26~37~5 minecraft:nether_brick_stairs 6
setblock ~26~38~5 minecraft:cobblestone_wall 0
fill ~26~39~5 ~26~39~6 minecraft:nether_brick_stairs 1
setblock ~26~43~5 minecraft:nether_brick_stairs 5
setblock ~26~52~5 minecraft:nether_brick_stairs 5
setblock ~26~55~5 minecraft:stone_block_slab 15
setblock ~26~56~5 minecraft:cobblestone_wall 0
fill ~26~57~5 ~26~57~6 minecraft:nether_brick_stairs 1
fill ~27~22~5 ~27~23~5 minecraft:leaves 0
setblock ~27~24~5 minecraft:leaves 0
fill ~28~19~5 ~28~21~5 minecraft:leaves 0
setblock ~29~18~5 minecraft:leaves 0
fill ~7~39~6 ~8~39~6 minecraft:grass
setblock ~8~40~6 minecraft:double_plant 2
fill ~9~38~6 ~10~39~6 minecraft:dirt 0
fill ~9~40~6 ~10~40~7 minecraft:grass
setblock ~10~41~6 minecraft:tallgrass 2
setblock ~11~39~6 minecraft:grass
setblock ~11~40~6 minecraft:leaves 0
setblock ~12~39~6 minecraft:leaves 0
fill ~20~24~6 ~21~24~6 minecraft:grass
fill ~20~43~6 ~21~43~6 minecraft:nether_brick_stairs 6
setblock ~20~52~6 minecraft:nether_brick_stairs 4
setblock ~21~25~6 minecraft:tallgrass 0
setblock ~21~34~6 minecraft:nether_brick_stairs 4
fill ~21~52~6 ~22~52~6 minecraft:nether_brick_stairs 6
fill ~22~22~6 ~22~23~6 minecraft:dirt 0
fill ~22~24~6 ~23~24~6 minecraft:stone 0
setblock ~22~25~6 minecraft:grass
setblock ~22~26~6 minecraft:double_plant 3
setblock ~22~34~6 minecraft:nether_brick_stairs 6
fill ~22~35~6 ~22~38~6 minecraft:stonebrick 0
setblock ~22~43~6 minecraft:nether_brick_stairs 4
setblock ~22~44~6 minecraft:stone_stairs 6
setblock ~22~49~6 minecraft:stone_brick_stairs 4
setblock ~22~53~6 minecraft:nether_brick_stairs 6
fill ~23~21~6 ~25~22~6 minecraft:stone 0
setblock ~23~23~6 minecraft:stone 0
setblock ~23~34~6 minecraft:nether_brick_stairs 4
fill ~23~35~6 ~25~35~6 minecraft:stone_stairs 3
fill ~23~36~6 ~25~36~6 minecraft:iron_bars
fill ~23~38~6 ~25~38~6 minecraft:iron_bars
fill ~23~39~6 ~24~39~6 minecraft:iron_bars
setblock ~23~40~6 minecraft:stone_brick_stairs 0
fill ~23~42~6 ~25~42~6 minecraft:stone_stairs 6
fill ~23~43~6 ~25~43~16 minecraft:planks 1
setblock ~23~44~6 minecraft:stone 6
setblock ~23~45~6 minecraft:stone_brick_stairs 1
setblock ~23~46~6 minecraft:stone_brick_stairs 5
setblock ~23~47~6 minecraft:stone_brick_stairs 0
setblock ~23~49~6 minecraft:stone_brick_stairs 6
setblock ~23~50~6 minecraft:stone_brick_stairs 2
setblock ~23~51~6 minecraft:stone_block_slab 5
setblock ~23~52~6 minecraft:stonebrick 0
setblock ~23~53~6 minecraft:stone 6
fill ~23~54~6 ~23~57~6 minecraft:stonebrick 0
setblock ~23~58~6 minecraft:stone_brick_stairs 0
setblock ~23~66~6 minecraft:nether_brick_stairs 0
fill ~24~18~6 ~24~20~6 minecraft:stone 0
fill ~24~24~6 ~24~24~16 minecraft:dirt 0
setblock ~24~34~6 minecraft:double_stone_block_slab 3
fill ~24~37~6 ~25~37~6 minecraft:iron_bars
setblock ~24~40~6 minecraft:iron_bars
setblock ~24~44~6 minecraft:stone_brick_stairs 2
fill ~24~45~6 ~24~46~6 minecraft:cobblestone_wall 0
setblock ~24~47~6 minecraft:stone_brick_stairs 6
setblock ~24~48~6 minecraft:cobblestone_wall 0
setblock ~24~49~6 minecraft:stonebrick 3
setblock ~24~50~6 minecraft:cobblestone_wall 0
setblock ~24~51~6 minecraft:stone_block_slab 13
fill ~24~52~6 ~24~52~16 minecraft:planks 1
setblock ~24~53~6 minecraft:stone_brick_stairs 2
fill ~24~54~6 ~24~56~6 minecraft:iron_bars
setblock ~24~57~6 minecraft:stone_brick_stairs 6
setblock ~24~58~6 minecraft:stonebrick 0
fill ~24~66~6 ~25~66~6 minecraft:nether_brick_stairs 2
fill ~25~19~6 ~25~20~6 minecraft:stone 0
fill ~25~23~6 ~26~24~6 minecraft:stone 0
setblock ~25~26~6 minecraft:tallgrass 0
setblock ~25~34~6 minecraft:nether_brick_stairs 5
setblock ~25~40~6 minecraft:stone_brick_stairs 1
setblock ~25~44~6 minecraft:stone 6
setblock ~25~45~6 minecraft:stone_brick_stairs 0
setblock ~25~46~6 minecraft:stone_brick_stairs 4
setblock ~25~47~6 minecraft:stone_brick_stairs 1
setblock ~25~49~6 minecraft:stone_brick_stairs 6
setblock ~25~50~6 minecraft:stone_brick_stairs 2
setblock ~25~51~6 minecraft:stone_block_slab 5
setblock ~25~52~6 minecraft:stonebrick 0
setblock ~25~53~6 minecraft:stone 6
fill ~25~54~6 ~25~57~6 minecraft:stonebrick 0
setblock ~25~58~6 minecraft:stone_brick_stairs 1
setblock ~26~21~6 minecraft:cobblestone
fill ~26~22~6 ~26~22~7 minecraft:stone 0
setblock ~26~25~6 minecraft:grass
setblock ~26~34~6 minecraft:nether_brick_stairs 6
fill ~26~35~6 ~26~38~6 minecraft:stonebrick 0
fill ~26~43~6 ~27~43~6 minecraft:nether_brick_stairs 6
setblock ~26~44~6 minecraft:stone_stairs 6
setblock ~26~49~6 minecraft:stone_brick_stairs 5
fill ~26~52~6 ~28~52~6 minecraft:nether_brick_stairs 6
setblock ~26~53~6 minecraft:nether_brick_stairs 6
setblock ~27~23~6 minecraft:dirt 0
fill ~27~24~6 ~28~24~6 minecraft:grass
setblock ~27~34~6 minecraft:nether_brick_stairs 5
setblock ~28~25~6 minecraft:tallgrass 0
setblock ~28~43~6 minecraft:nether_brick_stairs 5
setblock ~30~18~6 minecraft:leaves 0
fill ~39~46~6 ~39~46~7 minecraft:stone_block_slab 7
setblock ~40~46~6 minecraft:nether_brick_stairs 6
setblock ~40~47~6 minecraft:nether_brick_stairs 2
fill ~41~46~6 ~41~46~7 minecraft:stone_block_slab 7
fill ~4~33~7 ~4~35~7 minecraft:leaves 0
setblock ~4~36~7 minecraft:leaves 0
setblock ~6~39~7 minecraft:grass
setblock ~6~40~7 minecraft:tallgrass 0
fill ~7~38~7 ~7~39~7 minecraft:dirt 0
fill ~7~40~7 ~8~40~7 minecraft:grass
setblock ~7~41~7 minecraft:tallgrass 0
fill ~8~37~7 ~8~38~7 minecraft:stone 0
setblock ~8~39~7 minecraft:dirt 0
setblock ~8~42~7 minecraft:stone_block_slab 15
setblock ~8~43~7 minecraft:nether_brick_fence
setblock ~8~44~7 minecraft:nether_brick_stairs 6
setblock ~8~45~7 minecraft:nether_brick_stairs 0
setblock ~8~47~7 minecraft:nether_brick_stairs 6
fill ~8~48~7 ~8~49~7 minecraft:nether_brick
setblock ~8~50~7 minecraft:nether_brick_stairs 2
fill ~8~63~7 ~9~63~7 minecraft:nether_brick_stairs 2
setblock ~9~36~7 minecraft:stone 0
setblock ~9~37~7 minecraft:dirt 0
fill ~9~38~7 ~10~39~7 minecraft:stone 0
setblock ~9~45~7 minecraft:nether_brick_stairs 6
setblock ~10~31~7 minecraft:leaves 0
setblock ~10~34~7 minecraft:leaves 0
setblock ~10~35~7 minecraft:leaves 0
setblock ~10~37~7 minecraft:stone 0
setblock ~10~42~7 minecraft:stone_block_slab 15
setblock ~10~43~7 minecraft:nether_brick_fence
setblock ~10~44~7 minecraft:nether_brick_stairs 6
setblock ~10~45~7 minecraft:nether_brick_stairs 1
setblock ~10~47~7 minecraft:nether_brick_stairs 6
fill ~10~48~7 ~10~49~7 minecraft:nether_brick
setblock ~10~50~7 minecraft:nether_brick_stairs 2
setblock ~10~63~7 minecraft:nether_brick_stairs 1
setblock ~11~32~7 minecraft:leaves 0
setblock ~11~33~7 minecraft:leaves 0
setblock ~11~35~7 minecraft:trapdoor 3
setblock ~11~36~7 minecraft:leaves 0
fill ~11~37~7 ~11~39~7 minecraft:dirt 0
setblock ~11~40~7 minecraft:grass
setblock ~11~41~7 minecraft:leaves 0
fill ~12~37~7 ~12~38~7 minecraft:leaves 0
setblock ~12~39~7 minecraft:grass
setblock ~12~40~7 minecraft:tallgrass 0
fill ~19~24~7 ~19~24~8 minecraft:grass
setblock ~19~43~7 minecraft:nether_brick_stairs 6
fill ~19~52~7 ~19~52~8 minecraft:nether_brick_stairs 4
fill ~20~23~7 ~23~23~14 minecraft:dirt 0
fill ~20~24~7 ~21~24~7 minecraft:stone 0
fill ~20~25~7 ~21~25~7 minecraft:grass
setblock ~20~34~7 minecraft:nether_brick_stairs 4
setblock ~20~43~7 minecraft:nether_brick_stairs 4
setblock ~20~52~7 minecraft:nether_brick_stairs 6
fill ~21~21~7 ~21~22~7 minecraft:dirt 0
setblock ~21~26~7 minecraft:web
setblock ~21~31~7 minecraft:trapdoor 3
setblock ~21~34~7 minecraft:nether_brick_stairs 6
setblock ~21~35~7 minecraft:stonebrick 0
setblock ~21~36~7 minecraft:stone_block_slab 7
setblock ~21~38~7 minecraft:stone_brick_stairs 6
setblock ~21~39~7 minecraft:stone_brick_stairs 2
setblock ~21~40~7 minecraft:stone_brick_stairs 0
setblock ~21~41~7 minecraft:stone_brick_stairs 4
setblock ~21~42~7 minecraft:stone_brick_stairs 6
fill ~21~43~7 ~22~43~15 minecraft:planks 1
setblock ~21~44~7 minecraft:stonebrick 0
setblock ~21~45~7 minecraft:stone_brick_stairs 0
setblock ~21~46~7 minecraft:stone_brick_stairs 4
setblock ~21~47~7 minecraft:stone_block_slab 7
setblock ~21~49~7 minecraft:stone_brick_stairs 6
setblock ~21~50~7 minecraft:cobblestone_wall 0
setblock ~21~51~7 minecraft:stonebrick 0
fill ~21~52~7 ~23~52~15 minecraft:planks 1
setblock ~21~53~7 minecraft:stonebrick 0
setblock ~21~54~7 minecraft:stone_block_slab 7
setblock ~21~55~7 minecraft:stone_block_slab 13
setblock ~21~56~7 minecraft:cobblestone_wall 0
setblock ~21~57~7 minecraft:stone_brick_stairs 0
setblock ~21~58~7 minecraft:stone_brick_stairs 4
setblock ~21~59~7 minecraft:stone_brick_stairs 2
setblock ~21~66~7 minecraft:nether_brick_stairs 0
fill ~22~20~7 ~23~20~7 minecraft:stone 0
fill ~22~21~7 ~22~22~7 minecraft:stone 0
fill ~22~24~7 ~23~24~14 minecraft:dirt 0
fill ~22~25~7 ~22~25~8 minecraft:dirt 0
setblock ~22~26~7 minecraft:stone_brick_stairs 2
setblock ~22~28~7 minecraft:stone_block_slab 15
setblock ~22~31~7 minecraft:nether_brick_stairs 6
fill ~22~32~7 ~22~33~7 minecraft:nether_brick
fill ~22~34~7 ~26~34~15 minecraft:planks 1
fill ~22~39~7 ~22~40~7 minecraft:stonebrick 0
setblock ~22~41~7 minecraft:stonebrick 3
fill ~22~42~7 ~26~42~7 minecraft:stonebrick 0
fill ~22~44~7 ~22~51~7 minecraft:nether_brick
fill ~22~53~7 ~22~60~7 minecraft:nether_brick
setblock ~22~61~7 minecraft:nether_brick_stairs 2
setblock ~22~64~7 minecraft:stone_brick_stairs 6
setblock ~22~65~7 minecraft:cobblestone_wall 0
fill ~22~66~7 ~23~66~7 minecraft:nether_brick_stairs 2
fill ~23~18~7 ~23~19~7 minecraft:stone 0
fill ~23~21~7 ~25~21~7 minecraft:stonebrick 0
fill ~23~22~7 ~25~22~14 minecraft:dirt 0
fill ~23~25~7 ~25~25~7 minecraft:stone 6
setblock ~23~26~7 minecraft:stone_stairs 6
setblock ~23~27~7 minecraft:cobblestone_wall 0
setblock ~23~28~7 minecraft:nether_brick_fence
setblock ~23~29~7 minecraft:nether_brick_stairs 0
setblock ~23~33~7 minecraft:stone_brick_stairs 6
setblock ~23~40~7 minecraft:stonebrick 0
setblock ~23~41~7 minecraft:stone_brick_stairs 2
setblock ~23~51~7 minecraft:wooden_slab 9
setblock ~23~58~7 minecraft:stonebrick 0
setblock ~23~59~7 minecraft:stonebrick 3
setblock ~23~60~7 minecraft:stone_brick_stairs 1
setblock ~23~61~7 minecraft:nether_brick_stairs 6
setblock ~23~62~7 minecraft:stone_brick_stairs 4
fill ~23~63~7 ~23~65~7 minecraft:stonebrick 0
fill ~24~16~7 ~24~17~7 minecraft:stone 0
fill ~24~19~7 ~25~19~7 minecraft:stone_block_slab 15
setblock ~24~29~7 minecraft:stone_block_slab 15
setblock ~24~33~7 minecraft:stone_block_slab 11
setblock ~24~41~7 minecraft:stonebrick 0
setblock ~24~59~7 minecraft:nether_brick_stairs 2
setblock ~24~60~7 minecraft:nether_brick_stairs 6
setblock ~24~61~7 minecraft:cobblestone_wall 0
setblock ~24~62~7 minecraft:stone_brick_stairs 2
fill ~24~63~7 ~24~64~7 minecraft:iron_bars
setblock ~24~65~7 minecraft:stone_brick_stairs 6
fill ~24~66~7 ~24~67~7 minecraft:nether_brick
setblock ~24~68~7 minecraft:nether_brick_stairs 2
fill ~25~17~7 ~25~18~7 minecraft:stone 0
setblock ~25~20~7 minecraft:skull 1
fill ~25~23~7 ~26~23~16 minecraft:dirt 0
fill ~25~24~7 ~26~24~15 minecraft:dirt 0
setblock ~25~26~7 minecraft:stone_stairs 6
setblock ~25~27~7 minecraft:cobblestone_wall 0
setblock ~25~28~7 minecraft:nether_brick_fence
setblock ~25~29~7 minecraft:nether_brick_stairs 1
setblock ~25~33~7 minecraft:stone_brick_stairs 6
fill ~25~40~7 ~26~40~7 minecraft:stonebrick 0
setblock ~25~41~7 minecraft:stone_brick_stairs 2
setblock ~25~51~7 minecraft:wooden_slab 9
fill ~25~52~7 ~27~52~15 minecraft:planks 1
setblock ~25~58~7 minecraft:stonebrick 0
setblock ~25~59~7 minecraft:stonebrick 3
setblock ~25~60~7 minecraft:stone_brick_stairs 0
setblock ~25~61~7 minecraft:nether_brick_stairs 6
setblock ~25~62~7 minecraft:stone_brick_stairs 5
fill ~25~63~7 ~25~65~7 minecraft:stonebrick 0
setblock ~25~66~7 minecraft:nether_brick_stairs 1
fill ~26~18~7 ~26~18~8 minecraft:stone 0
fill ~26~19~7 ~26~21~7 minecraft:stone 0
fill ~26~25~7 ~26~25~8 minecraft:dirt 0
setblock ~26~26~7 minecraft:stone_brick_stairs 2
setblock ~26~28~7 minecraft:stone_block_slab 15
setblock ~26~31~7 minecraft:nether_brick_stairs 6
fill ~26~32~7 ~26~33~7 minecraft:nether_brick
setblock ~26~39~7 minecraft:stonebrick 0
setblock ~26~41~7 minecraft:stonebrick 3
fill ~26~43~7 ~27~43~15 minecraft:planks 1
fill ~26~44~7 ~26~51~7 minecraft:nether_brick
fill ~26~53~7 ~26~60~7 minecraft:nether_brick
setblock ~26~61~7 minecraft:nether_brick_stairs 2
setblock ~26~64~7 minecraft:stone_brick_stairs 6
setblock ~26~65~7 minecraft:cobblestone_wall 0
fill ~26~66~7 ~27~66~7 minecraft:nether_brick_stairs 2
setblock ~27~22~7 minecraft:dirt 0
fill ~27~23~7 ~27~24~7 minecraft:stone 0
fill ~27~25~7 ~28~25~7 minecraft:grass
setblock ~27~26~7 minecraft:tallgrass 2
setblock ~27~31~7 minecraft:trapdoor 3
setblock ~27~34~7 minecraft:nether_brick_stairs 6
setblock ~27~35~7 minecraft:stonebrick 0
setblock ~27~36~7 minecraft:stone_block_slab 7
setblock ~27~38~7 minecraft:stone_brick_stairs 6
setblock ~27~39~7 minecraft:stone_brick_stairs 2
setblock ~27~40~7 minecraft:stone_brick_stairs 1
setblock ~27~41~7 minecraft:stone_brick_stairs 5
setblock ~27~42~7 minecraft:stone_brick_stairs 6
setblock ~27~44~7 minecraft:stonebrick 0
setblock ~27~45~7 minecraft:stone_brick_stairs 1
setblock ~27~46~7 minecraft:stone_brick_stairs 5
setblock ~27~47~7 minecraft:stone_block_slab 7
setblock ~27~49~7 minecraft:stone_brick_stairs 6
setblock ~27~50~7 minecraft:cobblestone_wall 0
setblock ~27~51~7 minecraft:stonebrick 0
setblock ~27~53~7 minecraft:stonebrick 0
setblock ~27~54~7 minecraft:stone_block_slab 7
setblock ~27~55~7 minecraft:stone_block_slab 13
setblock ~27~56~7 minecraft:cobblestone_wall 0
setblock ~27~57~7 minecraft:stone_brick_stairs 1
setblock ~27~58~7 minecraft:stone_brick_stairs 5
setblock ~27~59~7 minecraft:stone_brick_stairs 2
fill ~28~23~7 ~28~23~13 minecraft:dirt 0
fill ~28~24~7 ~28~24~8 minecraft:stone 0
setblock ~28~34~7 minecraft:nether_brick_stairs 5
fill ~28~43~7 ~29~43~7 minecraft:nether_brick_stairs 6
setblock ~28~52~7 minecraft:nether_brick_stairs 5
fill ~29~24~7 ~29~24~8 minecraft:grass
setblock ~29~52~7 minecraft:nether_brick_stairs 6
setblock ~30~19~7 minecraft:leaves 0
setblock ~30~20~7 minecraft:leaves 0
setblock ~30~21~7 minecraft:leaves 0
fill ~37~46~7 ~38~46~7 minecraft:stone_block_slab 7
setblock ~40~47~7 minecraft:nether_brick_stairs 7
setblock ~40~48~7 minecraft:nether_brick_stairs 2
fill ~42~46~7 ~43~46~7 minecraft:stone_block_slab 7
setblock ~4~37~8 minecraft:leaves 0
setblock ~4~38~8 minecraft:leaves 0
setblock ~4~39~8 minecraft:leaves 0
setblock ~5~39~8 minecraft:grass
setblock ~5~40~8 minecraft:leaves 0
fill ~6~37~8 ~6~39~8 minecraft:dirt 0
setblock ~6~40~8 minecraft:grass
setblock ~6~41~8 minecraft:double_plant 3
fill ~6~63~8 ~7~63~8 minecraft:nether_brick_stairs 2
fill ~7~36~8 ~8~36~8 minecraft:stone 0
fill ~7~37~8 ~7~39~8 minecraft:stone 0
fill ~7~40~8 ~8~40~8 minecraft:nether_brick
setblock ~7~41~8 minecraft:cobblestone_wall 0
setblock ~7~45~8 minecraft:stone_block_slab 7
setblock ~7~46~8 minecraft:stone_block_slab 13
setblock ~7~47~8 minecraft:stone_block_slab 5
setblock ~7~53~8 minecraft:stone_block_slab 11
fill ~7~54~8 ~7~55~8 minecraft:cobblestone_wall 0
setblock ~7~56~8 minecraft:stone_block_slab 3
setblock ~7~57~8 minecraft:nether_brick_stairs 4
setblock ~7~58~8 minecraft:stonebrick 0
setblock ~7~59~8 minecraft:stone_brick_stairs 0
fill ~8~35~8 ~10~35~8 minecraft:stone 0
fill ~8~39~8 ~11~39~8 minecraft:stone 0
setblock ~8~41~8 minecraft:nether_brick_stairs 6
fill ~8~42~8 ~8~44~8 minecraft:stonebrick 0
setblock ~8~45~8 minecraft:stone 6
setblock ~8~46~8 minecraft:stonebrick 0
setblock ~8~47~8 minecraft:nether_brick
setblock ~8~48~8 minecraft:nether_brick_stairs 3
setblock ~8~50~8 minecraft:nether_brick_stairs 7
setblock ~8~51~8 minecraft:stone_block_slab 7
setblock ~8~52~8 minecraft:stone_brick_stairs 4
setblock ~8~53~8 minecraft:stone_stairs 6
fill ~8~54~8 ~8~55~8 minecraft:stonebrick 0
setblock ~8~56~8 minecraft:stone_stairs 2
setblock ~8~57~8 minecraft:stone_stairs 6
setblock ~8~58~8 minecraft:stone_brick_stairs 2
fill ~8~59~8 ~10~59~8 minecraft:cobblestone_wall 0
setblock ~8~63~8 minecraft:nether_brick_stairs 0
fill ~9~33~8 ~9~33~13 minecraft:stone 0
fill ~9~34~8 ~10~34~8 minecraft:stone 0
setblock ~9~40~8 minecraft:dirt 0
setblock ~9~41~8 minecraft:stone_stairs 2
fill ~9~42~8 ~9~43~8 minecraft:iron_bars
setblock ~9~44~8 minecraft:stone_stairs 6
setblock ~9~45~8 minecraft:stone_stairs 3
fill ~9~51~8 ~9~52~8 minecraft:stonebrick 0
setblock ~9~53~8 minecraft:stone_stairs 2
setblock ~9~56~8 minecraft:stone_stairs 6
setblock ~9~57~8 minecraft:stone_stairs 2
setblock ~9~58~8 minecraft:stone_brick_stairs 6
fill ~9~63~8 ~9~64~8 minecraft:nether_brick
setblock ~9~65~8 minecraft:nether_brick_stairs 2
fill ~10~36~8 ~11~36~8 minecraft:stone 0
setblock ~10~38~8 minecraft:web
fill ~10~40~8 ~11~40~8 minecraft:nether_brick
setblock ~10~41~8 minecraft:nether_brick_stairs 6
fill ~10~42~8 ~10~44~8 minecraft:stonebrick 0
setblock ~10~45~8 minecraft:stone 6
setblock ~10~46~8 minecraft:stonebrick 0
setblock ~10~47~8 minecraft:nether_brick
setblock ~10~48~8 minecraft:nether_brick_stairs 3
setblock ~10~50~8 minecraft:nether_brick_stairs 7
setblock ~10~51~8 minecraft:stone_block_slab 7
setblock ~10~52~8 minecraft:stone_brick_stairs 5
setblock ~10~53~8 minecraft:stone_stairs 6
fill ~10~54~8 ~10~55~8 minecraft:stonebrick 0
setblock ~10~56~8 minecraft:stone_stairs 2
setblock ~10~57~8 minecraft:stone_stairs 6
setblock ~10~58~8 minecraft:stone_brick_stairs 2
fill ~10~63~8 ~11~63~8 minecraft:nether_brick_stairs 2
setblock ~11~34~8 minecraft:trapdoor 3
setblock ~11~35~8 minecraft:glowstone
fill ~11~37~8 ~12~37~8 minecraft:stone 0
setblock ~11~38~8 minecraft:stone 0
setblock ~11~41~8 minecraft:cobblestone_wall 0
setblock ~11~45~8 minecraft:stone_block_slab 7
setblock ~11~46~8 minecraft:stone_block_slab 13
setblock ~11~47~8 minecraft:stone_block_slab 5
setblock ~11~53~8 minecraft:stone_block_slab 11
fill ~11~54~8 ~11~55~8 minecraft:cobblestone_wall 0
setblock ~11~56~8 minecraft:stone_block_slab 3
setblock ~11~57~8 minecraft:nether_brick_stairs 5
setblock ~11~58~8 minecraft:stonebrick 0
setblock ~11~59~8 minecraft:stone_brick_stairs 1
setblock ~12~35~8 minecraft:trapdoor 0
fill ~12~38~8 ~12~39~8 minecraft:dirt 0
setblock ~12~40~8 minecraft:grass
setblock ~12~41~8 minecraft:leaves 0
fill ~12~63~8 ~12~63~9 minecraft:nether_brick_stairs 1
setblock ~13~39~8 minecraft:grass
setblock ~13~40~8 minecraft:leaves 0
setblock ~14~39~8 minecraft:leaves 0
setblock ~19~25~8 minecraft:double_plant 2
fill ~19~34~8 ~19~34~9 minecraft:nether_brick_stairs 4
fill ~19~43~8 ~19~43~9 minecraft:nether_brick_stairs 4
setblock ~20~21~8 minecraft:trapdoor 1
fill ~20~22~8 ~22~22~8 minecraft:dirt 0
setblock ~20~24~8 minecraft:stone 0
setblock ~20~25~8 minecraft:grass
setblock ~20~26~8 minecraft:tallgrass 2
setblock ~20~31~8 minecraft:trapdoor 1
setblock ~20~34~8 minecraft:nether_brick_stairs 6
setblock ~20~35~8 minecraft:stonebrick 0
setblock ~20~36~8 minecraft:stone_block_slab 7
setblock ~20~38~8 minecraft:stone_brick_stairs 4
setblock ~20~39~8 minecraft:stone_brick_stairs 0
setblock ~20~40~8 minecraft:stone_brick_stairs 2
setblock ~20~41~8 minecraft:stone_brick_stairs 6
setblock ~20~42~8 minecraft:stone_brick_stairs 4
fill ~20~43~8 ~20~43~14 minecraft:planks 1
setblock ~20~44~8 minecraft:stonebrick 0
setblock ~20~45~8 minecraft:stone_brick_stairs 2
setblock ~20~46~8 minecraft:stone_brick_stairs 6
setblock ~20~47~8 minecraft:stone_block_slab 7
setblock ~20~49~8 minecraft:stone_brick_stairs 4
setblock ~20~50~8 minecraft:cobblestone_wall 0
setblock ~20~51~8 minecraft:stonebrick 0
fill ~20~52~8 ~20~52~14 minecraft:planks 1
setblock ~20~53~8 minecraft:stonebrick 0
setblock ~20~54~8 minecraft:stone_block_slab 7
setblock ~20~55~8 minecraft:stone_block_slab 13
setblock ~20~56~8 minecraft:cobblestone_wall 0
setblock ~20~57~8 minecraft:stone_brick_stairs 2
setblock ~20~58~8 minecraft:stone_brick_stairs 6
setblock ~20~59~8 minecraft:stone_brick_stairs 0
fill ~20~66~8 ~20~66~9 minecraft:nether_brick_stairs 0
fill ~21~19~8 ~22~19~8 minecraft:stone 0
setblock ~21~20~8 minecraft:stone 0
setblock ~21~21~8 minecraft:glowstone
fill ~21~24~8 ~21~24~14 minecraft:dirt 0
setblock ~21~25~8 minecraft:glowstone
setblock ~21~26~8 minecraft:stone_block_slab 13
setblock ~21~27~8 minecraft:cobblestone_wall 0
setblock ~21~28~8 minecraft:stone_block_slab 7
setblock ~21~30~8 minecraft:stone_block_slab 15
setblock ~21~31~8 minecraft:glowstone
setblock ~21~32~8 minecraft:stone_block_slab 13
setblock ~21~33~8 minecraft:cobblestone_wall 0
setblock ~21~34~8 minecraft:stonebrick 0
fill ~21~42~8 ~22~42~8 minecraft:double_wooden_slab 1
setblock ~21~51~8 minecraft:double_wooden_slab 1
setblock ~21~59~8 minecraft:stonebrick 0
setblock ~21~60~8 minecraft:stone_block_slab 5
setblock ~21~61~8 minecraft:stone_block_slab 15
fill ~21~62~8 ~21~65~8 minecraft:nether_brick
setblock ~21~66~8 minecraft:nether_brick_stairs 2
fill ~22~17~8 ~23~17~8 minecraft:stone 0
setblock ~22~18~8 minecraft:stone 0
setblock ~22~20~8 minecraft:web
fill ~22~21~8 ~22~21~9 minecraft:stonebrick 0
setblock ~22~26~8 minecraft:stone 6
fill ~22~27~8 ~22~32~8 minecraft:stonebrick 0
setblock ~22~33~8 minecraft:stone_block_slab 13
fill ~22~51~8 ~22~51~9 minecraft:wooden_slab 9
fill ~22~59~8 ~22~61~8 minecraft:nether_brick
fill ~22~62~8 ~22~65~8 minecraft:stonebrick 0
fill ~22~66~8 ~23~66~8 minecraft:nether_brick
setblock ~22~67~8 minecraft:nether_brick_stairs 2
setblock ~23~16~8 minecraft:stone 0
setblock ~23~18~8 minecraft:redstone_torch 5
setblock ~23~21~8 minecraft:stonebrick 2
fill ~23~25~8 ~25~25~8 minecraft:nether_brick
setblock ~23~26~8 minecraft:stone_stairs 7
setblock ~23~29~8 minecraft:stonebrick 0
setblock ~23~30~8 minecraft:stone_brick_stairs 6
fill ~23~31~8 ~23~33~8 minecraft:stonebrick 0
fill ~23~42~8 ~25~42~8 minecraft:wooden_slab 9
fill ~23~61~8 ~23~61~14 minecraft:planks 1
fill ~23~62~8 ~25~62~8 minecraft:stone_brick_stairs 7
setblock ~23~63~8 minecraft:flower_pot 0
setblock ~23~67~8 minecraft:nether_brick_stairs 0
fill ~24~14~8 ~24~15~14 minecraft:stone 0
setblock ~24~16~8 minecraft:stonebrick 0
setblock ~24~17~8 minecraft:cauldron 6
fill ~24~21~8 ~26~21~8 minecraft:stonebrick 0
setblock ~24~30~8 minecraft:stone_stairs 2
fill ~24~31~8 ~24~32~8 minecraft:iron_bars
setblock ~24~33~8 minecraft:stone_stairs 6
setblock ~24~61~8 minecraft:stonebrick 0
setblock ~24~63~8 minecraft:wooden_pressure_plate 0
fill ~24~67~8 ~24~69~8 minecraft:nether_brick
setblock ~24~70~8 minecraft:nether_brick_stairs 2
fill ~25~15~8 ~25~15~14 minecraft:stone 0
setblock ~25~16~8 minecraft:stone 0
setblock ~25~17~8 minecraft:enchanting_table
setblock ~25~26~8 minecraft:stone_stairs 7
fill ~25~29~8 ~26~29~8 minecraft:stonebrick 0
setblock ~25~30~8 minecraft:stone_brick_stairs 6
fill ~25~31~8 ~26~32~8 minecraft:stonebrick 0
setblock ~25~33~8 minecraft:stonebrick 0
fill ~25~61~8 ~25~61~14 minecraft:planks 1
setblock ~25~63~8 minecraft:brewing_stand 0
fill ~25~66~8 ~26~66~8 minecraft:nether_brick
setblock ~25~67~8 minecraft:nether_brick_stairs 1
setblock ~26~15~8 minecraft:trapdoor 3
fill ~26~17~8 ~26~17~9 minecraft:stone 0
setblock ~26~19~8 minecraft:web
fill ~26~22~8 ~26~22~14 minecraft:dirt 0
setblock ~26~26~8 minecraft:stone 6
fill ~26~27~8 ~26~28~8 minecraft:stonebrick 0
setblock ~26~30~8 minecraft:stonebrick 0
setblock ~26~33~8 minecraft:stone_block_slab 13
fill ~26~42~8 ~27~42~8 minecraft:double_wooden_slab 1
fill ~26~51~8 ~26~51~9 minecraft:wooden_slab 9
fill ~26~59~8 ~26~61~8 minecraft:nether_brick
fill ~26~62~8 ~26~65~8 minecraft:stonebrick 0
setblock ~26~67~8 minecraft:nether_brick_stairs 2
fill ~27~19~8 ~27~19~9 minecraft:stone 0
fill ~27~20~8 ~27~22~8 minecraft:stone 0
fill ~27~23~8 ~27~24~14 minecraft:dirt 0
setblock ~27~25~8 minecraft:glowstone
setblock ~27~26~8 minecraft:stone_block_slab 13
setblock ~27~27~8 minecraft:cobblestone_wall 0
setblock ~27~28~8 minecraft:stone_block_slab 7
setblock ~27~30~8 minecraft:stone_block_slab 15
setblock ~27~31~8 minecraft:glowstone
setblock ~27~32~8 minecraft:stone_block_slab 13
setblock ~27~33~8 minecraft:cobblestone_wall 0
setblock ~27~34~8 minecraft:stonebrick 0
setblock ~27~51~8 minecraft:double_wooden_slab 1
setblock ~27~59~8 minecraft:stonebrick 0
setblock ~27~60~8 minecraft:stone_block_slab 5
setblock ~27~61~8 minecraft:stone_block_slab 15
fill ~27~62~8 ~27~65~8 minecraft:nether_brick
setblock ~27~66~8 minecraft:nether_brick_stairs 1
fill ~28~21~8 ~28~22~14 minecraft:stone 0
setblock ~28~25~8 minecraft:grass
setblock ~28~26~8 minecraft:double_plant 2
setblock ~28~31~8 minecraft:trapdoor 0
setblock ~28~34~8 minecraft:nether_brick_stairs 6
setblock ~28~35~8 minecraft:stonebrick 0
setblock ~28~36~8 minecraft:stone_block_slab 7
setblock ~28~38~8 minecraft:stone_brick_stairs 5
setblock ~28~39~8 minecraft:stone_brick_stairs 1
setblock ~28~40~8 minecraft:stone_brick_stairs 2
setblock ~28~41~8 minecraft:stone_brick_stairs 6
setblock ~28~42~8 minecraft:stone_brick_stairs 5
fill ~28~43~8 ~28~43~14 minecraft:planks 1
setblock ~28~44~8 minecraft:stonebrick 0
setblock ~28~45~8 minecraft:stone_brick_stairs 2
setblock ~28~46~8 minecraft:stone_brick_stairs 6
setblock ~28~47~8 minecraft:stone_block_slab 7
setblock ~28~49~8 minecraft:stone_brick_stairs 5
setblock ~28~50~8 minecraft:cobblestone_wall 0
setblock ~28~51~8 minecraft:stonebrick 0
fill ~28~52~8 ~28~52~14 minecraft:planks 1
setblock ~28~53~8 minecraft:stonebrick 0
setblock ~28~54~8 minecraft:stone_block_slab 7
setblock ~28~55~8 minecraft:stone_block_slab 13
setblock ~28~56~8 minecraft:cobblestone_wall 0
setblock ~28~57~8 minecraft:stone_brick_stairs 2
setblock ~28~58~8 minecraft:stone_brick_stairs 6
setblock ~28~59~8 minecraft:stone_brick_stairs 1
setblock ~28~66~8 minecraft:nether_brick_stairs 2
setblock ~29~25~8 minecraft:web
fill ~29~34~8 ~29~34~9 minecraft:nether_brick_stairs 5
fill ~29~43~8 ~29~43~9 minecraft:nether_brick_stairs 5
fill ~29~52~8 ~29~52~9 minecraft:nether_brick_stairs 5
fill ~29~53~8 ~30~53~8 minecraft:iron_bars
setblock ~30~22~8 minecraft:leaves 0
fill ~30~23~8 ~30~24~8 minecraft:leaves 0
fill ~30~52~8 ~31~52~8 minecraft:iron_bars
fill ~31~51~8 ~32~51~8 minecraft:iron_bars
fill ~32~50~8 ~33~50~8 minecraft:iron_bars
fill ~33~49~8 ~34~49~8 minecraft:iron_bars
fill ~34~48~8 ~35~48~8 minecraft:iron_bars
fill ~35~47~8 ~36~47~8 minecraft:iron_bars
setblock ~36~46~8 minecraft:double_stone_block_slab 7
setblock ~37~46~8 minecraft:stone_block_slab 7
setblock ~38~49~8 minecraft:stained_glass_pane 12
fill ~39~49~8 ~39~50~8 minecraft:stained_glass 12
setblock ~39~51~8 minecraft:stained_glass_pane 1
setblock ~40~47~8 minecraft:stained_glass 14
setblock ~40~48~8 minecraft:nether_brick_stairs 7
setblock ~40~49~8 minecraft:nether_brick_stairs 2
fill ~40~50~8 ~40~50~9 minecraft:stained_glass 1
setblock ~40~51~8 minecraft:stained_glass 1
setblock ~40~52~8 minecraft:stained_glass_pane 14
setblock ~41~47~8 minecraft:stained_glass_pane 14
fill ~41~50~8 ~41~50~9 minecraft:stained_glass 12
fill ~43~46~8 ~44~46~8 minecraft:stone_block_slab 7
fill ~4~39~9 ~4~39~10 minecraft:grass
setblock ~4~40~9 minecraft:double_plant 3
fill ~5~38~9 ~5~39~9 minecraft:dirt 0
fill ~5~40~9 ~5~40~13 minecraft:grass
fill ~5~41~9 ~5~41~10 minecraft:leaves 0
fill ~6~36~9 ~6~36~10 minecraft:stone 0
fill ~6~37~9 ~6~38~9 minecraft:stone 0
setblock ~6~39~9 minecraft:dirt 0
fill ~6~40~9 ~6~40~10 minecraft:nether_brick
setblock ~6~41~9 minecraft:cobblestone_wall 0
setblock ~6~45~9 minecraft:stone_block_slab 7
setblock ~6~46~9 minecraft:stone_block_slab 13
setblock ~6~47~9 minecraft:stone_block_slab 5
setblock ~6~53~9 minecraft:stone_block_slab 11
fill ~6~54~9 ~6~55~9 minecraft:cobblestone_wall 0
setblock ~6~56~9 minecraft:stone_block_slab 3
setblock ~6~57~9 minecraft:nether_brick_stairs 6
setblock ~6~58~9 minecraft:stonebrick 0
setblock ~6~59~9 minecraft:stone_brick_stairs 2
fill ~6~63~9 ~6~63~10 minecraft:nether_brick_stairs 0
fill ~7~34~9 ~8~34~9 minecraft:stone 0
setblock ~7~35~9 minecraft:stone 0
setblock ~7~38~9 minecraft:web
setblock ~7~39~9 minecraft:stone 0
setblock ~7~40~9 minecraft:dirt 0
setblock ~7~41~9 minecraft:stonebrick 0
setblock ~7~42~9 minecraft:stone_block_slab 5
setblock ~7~43~9 minecraft:stone_block_slab 13
setblock ~7~44~9 minecraft:cobblestone_wall 0
setblock ~7~45~9 minecraft:stonebrick 0
fill ~7~46~9 ~7~47~9 minecraft:cobblestone_wall 0
setblock ~7~48~9 minecraft:cobblestone_wall 0
setblock ~7~49~9 minecraft:glowstone
setblock ~7~50~9 minecraft:cobblestone_wall 0
fill ~7~51~9 ~7~63~9 minecraft:nether_brick
setblock ~7~64~9 minecraft:stone_block_slab 7
setblock ~8~30~9 minecraft:trapdoor 3
setblock ~8~32~9 minecraft:cobblestone
fill ~8~33~9 ~8~33~13 minecraft:stone 0
setblock ~8~35~9 minecraft:furnace 3
fill ~8~39~9 ~10~39~13 minecraft:wooden_slab 9
fill ~8~40~9 ~10~40~10 minecraft:double_wooden_slab 1
fill ~8~41~9 ~10~41~9 minecraft:bookshelf
fill ~8~57~9 ~10~57~13 minecraft:stone_block_slab 13fill ~8~58~9 ~10~58~13 minecraft:stonebrick 0
setblock ~8~59~9 minecraft:nether_brick_stairs 5
setblock ~8~61~9 minecraft:stone_brick_stairs 5
setblock ~8~62~9 minecraft:stone_brick_stairs 0
setblock ~8~64~9 minecraft:nether_brick
setblock ~8~65~9 minecraft:nether_brick_stairs 2
fill ~9~30~9 ~9~32~12 minecraft:stone 0
fill ~9~34~9 ~10~34~10 minecraft:wooden_slab 9
setblock ~9~35~9 minecraft:nether_brick_stairs 5
setblock ~9~50~9 minecraft:stone_brick_stairs 6
setblock ~9~51~9 minecraft:stone_brick_stairs 3
setblock ~9~59~9 minecraft:stone_block_slab 15
setblock ~9~62~9 minecraft:stone_brick_stairs 6
fill ~9~65~9 ~9~66~9 minecraft:nether_brick
setblock ~9~67~9 minecraft:nether_brick_stairs 2
fill ~10~32~9 ~10~32~13 minecraft:stone 0
setblock ~10~33~9 minecraft:stone 0
setblock ~10~35~9 minecraft:nether_brick_stairs 4
setblock ~10~59~9 minecraft:nether_brick_stairs 4
setblock ~10~60~9 minecraft:flower_pot 0
setblock ~10~61~9 minecraft:stone_brick_stairs 4
setblock ~10~62~9 minecraft:stone_brick_stairs 1
setblock ~10~64~9 minecraft:nether_brick
setblock ~10~65~9 minecraft:nether_brick_stairs 2
setblock ~11~33~9 minecraft:cobblestone
fill ~11~34~9 ~11~35~9 minecraft:stone 0
setblock ~11~36~9 minecraft:skull 1
setblock ~11~38~9 minecraft:web
setblock ~11~39~9 minecraft:stone 0
setblock ~11~40~9 minecraft:dirt 0
setblock ~11~41~9 minecraft:stonebrick 0
setblock ~11~42~9 minecraft:stone_block_slab 5
setblock ~11~43~9 minecraft:stone_block_slab 13
setblock ~11~44~9 minecraft:cobblestone_wall 0
setblock ~11~45~9 minecraft:stonebrick 0
fill ~11~46~9 ~11~47~9 minecraft:cobblestone_wall 0
setblock ~11~48~9 minecraft:cobblestone_wall 0
setblock ~11~49~9 minecraft:glowstone
setblock ~11~50~9 minecraft:cobblestone_wall 0
fill ~11~51~9 ~11~63~9 minecraft:nether_brick
setblock ~11~64~9 minecraft:stone_block_slab 7
fill ~12~36~9 ~12~38~9 minecraft:stone 0
fill ~12~39~9 ~13~39~9 minecraft:dirt 0
fill ~12~40~9 ~12~40~10 minecraft:nether_brick
setblock ~12~41~9 minecraft:cobblestone_wall 0
setblock ~12~45~9 minecraft:stone_block_slab 7
setblock ~12~46~9 minecraft:stone_block_slab 13
setblock ~12~47~9 minecraft:stone_block_slab 5
setblock ~12~53~9 minecraft:stone_block_slab 11
fill ~12~54~9 ~12~55~9 minecraft:cobblestone_wall 0
setblock ~12~56~9 minecraft:stone_block_slab 3
setblock ~12~57~9 minecraft:nether_brick_stairs 6
setblock ~12~58~9 minecraft:stonebrick 0
setblock ~12~59~9 minecraft:stone_brick_stairs 2
setblock ~13~38~9 minecraft:dirt 0
fill ~13~40~9 ~13~40~10 minecraft:grass
setblock ~13~41~9 minecraft:double_plant 2
setblock ~14~39~9 minecraft:grass
setblock ~14~40~9 minecraft:web
setblock ~15~39~9 minecraft:leaves 0
setblock ~18~24~9 minecraft:grass
setblock ~18~25~9 minecraft:tallgrass 2
setblock ~18~43~9 minecraft:nether_brick_stairs 6
fill ~18~52~9 ~18~52~12 minecraft:nether_brick_stairs 4
setblock ~18~55~9 minecraft:stone_block_slab 15
setblock ~18~56~9 minecraft:cobblestone_wall 0
fill ~18~57~9 ~19~57~9 minecraft:nether_brick_stairs 2
setblock ~19~22~9 minecraft:cobblestone
setblock ~19~23~9 minecraft:dirt 0
fill ~19~24~9 ~19~24~10 minecraft:stone 0
fill ~19~25~9 ~19~25~13 minecraft:grass
fill ~19~35~9 ~19~38~9 minecraft:stonebrick 0
setblock ~19~39~9 minecraft:nether_brick_stairs 2
setblock ~19~44~9 minecraft:stone_stairs 4
setblock ~19~49~9 minecraft:stone_brick_stairs 6
setblock ~19~52~9 minecraft:nether_brick_stairs 6
setblock ~19~53~9 minecraft:nether_brick_stairs 4
fill ~20~20~9 ~20~22~13 minecraft:stone 0
fill ~20~24~9 ~20~24~13 minecraft:dirt 0
fill ~20~25~9 ~21~25~9 minecraft:dirt 0
setblock ~20~26~9 minecraft:stone_brick_stairs 0
setblock ~20~28~9 minecraft:stone_block_slab 15
setblock ~20~31~9 minecraft:nether_brick_stairs 4
fill ~20~32~9 ~20~33~9 minecraft:nether_brick
fill ~20~34~9 ~21~34~13 minecraft:planks 1
fill ~20~39~9 ~20~40~9 minecraft:stonebrick 0
setblock ~20~41~9 minecraft:stonebrick 3
fill ~20~42~9 ~20~42~13 minecraft:stonebrick 0
fill ~20~44~9 ~20~51~9 minecraft:nether_brick
fill ~20~53~9 ~20~60~9 minecraft:nether_brick
setblock ~20~61~9 minecraft:nether_brick_stairs 0
setblock ~20~64~9 minecraft:stone_brick_stairs 4
setblock ~20~65~9 minecraft:cobblestone_wall 0
fill ~21~17~9 ~21~17~13 minecraft:stone 0
fill ~21~18~9 ~21~19~9 minecraft:stone 0
setblock ~21~20~9 minecraft:web
setblock ~21~21~9 minecraft:stonebrick 2
fill ~21~22~9 ~22~22~13 minecraft:dirt 0
setblock ~21~26~9 minecraft:stone 6
fill ~21~27~9 ~21~32~9 minecraft:stonebrick 0
setblock ~21~33~9 minecraft:stone_block_slab 13
setblock ~21~42~9 minecraft:double_wooden_slab 1
setblock ~21~51~9 minecraft:wooden_slab 9
fill ~21~59~9 ~21~61~9 minecraft:nether_brick
fill ~21~62~9 ~21~65~9 minecraft:stonebrick 0
fill ~21~66~9 ~21~66~10 minecraft:nether_brick
setblock ~21~67~9 minecraft:nether_brick_stairs 0
setblock ~22~15~9 minecraft:cobblestone
setblock ~22~16~9 minecraft:stone 0
setblock ~22~17~9 minecraft:nether_brick
setblock ~22~18~9 minecraft:brewing_stand 0
setblock ~22~25~9 minecraft:nether_brick
setblock ~22~29~9 minecraft:cobblestone_wall 0
setblock ~22~30~9 minecraft:redstone_torch 5
fill ~22~33~9 ~26~33~13 minecraft:wooden_slab 9
fill ~22~42~9 ~23~42~9 minecraft:wooden_slab 9
fill ~22~61~9 ~22~61~13 minecraft:planks 1
setblock ~22~67~9 minecraft:nether_brick
setblock ~22~68~9 minecraft:stone_block_slab 7
fill ~23~13~9 ~25~13~11 minecraft:stone 0
fill ~23~14~9 ~23~15~13 minecraft:stone 0
setblock ~23~16~9 minecraft:stonebrick 0
setblock ~23~21~9 minecraft:stonebrick 1
fill ~23~25~9 ~25~25~13 minecraft:obsidian
setblock ~23~68~9 minecraft:nether_brick
setblock ~23~69~9 minecraft:nether_brick_stairs 2
setblock ~24~9~9 minecraft:cobblestone_wall 0
setblock ~24~10~9 minecraft:stone 0
setblock ~24~11~9 minecraft:cobblestone
fill ~24~12~9 ~25~12~12 minecraft:stone 0
setblock ~24~16~9 minecraft:stonebrick 1
fill ~24~21~9 ~24~21~13 minecraft:stonebrick 0
fill ~24~61~9 ~24~61~13 minecraft:planks 1
fill ~24~69~9 ~24~72~9 minecraft:nether_brick
setblock ~24~73~9 minecraft:nether_brick_stairs 2
fill ~25~14~9 ~25~14~13 minecraft:stone 0
setblock ~25~16~9 minecraft:stonebrick 0
setblock ~25~21~9 minecraft:stonebrick 2
fill ~25~42~9 ~26~42~9 minecraft:wooden_slab 9
setblock ~25~67~9 minecraft:web
setblock ~25~68~9 minecraft:nether_brick
setblock ~25~69~9 minecraft:nether_brick_stairs 2
setblock ~26~14~9 minecraft:cobblestone
setblock ~26~15~9 minecraft:glowstone
setblock ~26~16~9 minecraft:stone 0
fill ~26~21~9 ~27~21~10 minecraft:stonebrick 0
setblock ~26~25~9 minecraft:nether_brick
setblock ~26~29~9 minecraft:cobblestone_wall 0
setblock ~26~30~9 minecraft:redstone_torch 5
fill ~26~61~9 ~26~61~13 minecraft:planks 1
fill ~26~62~9 ~26~65~9 minecraft:bookshelf
fill ~26~66~9 ~27~66~9 minecraft:nether_brick
setblock ~26~67~9 minecraft:nether_brick
setblock ~26~68~9 minecraft:stone_block_slab 7
setblock ~27~15~9 minecraft:trapdoor 1
fill ~27~17~9 ~27~17~10 minecraft:stone 0
setblock ~27~18~9 minecraft:stone 0
setblock ~27~20~9 minecraft:web
fill ~27~22~9 ~27~22~13 minecraft:dirt 0
fill ~27~25~9 ~28~25~9 minecraft:dirt 0
setblock ~27~26~9 minecraft:stone 6
fill ~27~27~9 ~27~32~9 minecraft:stonebrick 0
setblock ~27~33~9 minecraft:stone_block_slab 13
fill ~27~34~9 ~28~34~13 minecraft:planks 1
setblock ~27~42~9 minecraft:double_wooden_slab 1
setblock ~27~51~9 minecraft:wooden_slab 9
fill ~27~59~9 ~28~60~9 minecraft:nether_brick
setblock ~27~61~9 minecraft:nether_brick
fill ~27~62~9 ~27~65~9 minecraft:stonebrick 0
setblock ~27~67~9 minecraft:nether_brick_stairs 1
fill ~28~20~9 ~28~20~14 minecraft:stone 0
fill ~28~24~9 ~28~24~13 minecraft:dirt 0
setblock ~28~26~9 minecraft:stone_brick_stairs 1
setblock ~28~28~9 minecraft:stone_block_slab 15
setblock ~28~31~9 minecraft:nether_brick_stairs 5
fill ~28~32~9 ~28~33~9 minecraft:nether_brick
fill ~28~39~9 ~28~40~9 minecraft:stonebrick 0
setblock ~28~41~9 minecraft:stonebrick 3
setblock ~28~42~9 minecraft:stonebrick 0
fill ~28~44~9 ~28~51~9 minecraft:nether_brick
fill ~28~53~9 ~28~58~9 minecraft:nether_brick
setblock ~28~61~9 minecraft:nether_brick_stairs 1
setblock ~28~64~9 minecraft:stone_brick_stairs 5
setblock ~28~65~9 minecraft:cobblestone_wall 0
setblock ~28~66~9 minecraft:nether_brick_stairs 1
fill ~29~22~9 ~29~22~10 minecraft:dirt 0
setblock ~29~23~9 minecraft:dirt 0
fill ~29~24~9 ~29~24~10 minecraft:stone 0
fill ~29~25~9 ~29~25~13 minecraft:grass
setblock ~29~26~9 minecraft:tallgrass 2
fill ~29~35~9 ~29~38~9 minecraft:stonebrick 0
fill ~29~39~9 ~30~39~9 minecraft:nether_brick_stairs 2
setblock ~29~44~9 minecraft:stone_stairs 5
setblock ~29~53~9 minecraft:nether_brick_stairs 5
fill ~29~57~9 ~30~57~9 minecraft:nether_brick_stairs 2
setblock ~30~24~9 minecraft:grass
setblock ~30~25~9 minecraft:leaves 0
setblock ~30~35~9 minecraft:nether_brick_stairs 6
setblock ~30~37~9 minecraft:nether_brick_stairs 5
setblock ~30~38~9 minecraft:cobblestone_wall 0
setblock ~30~52~9 minecraft:nether_brick_stairs 6
setblock ~30~55~9 minecraft:stone_block_slab 15
setblock ~30~56~9 minecraft:cobblestone_wall 0
fill ~36~46~9 ~36~46~10 minecraft:stone_block_slab 7
fill ~38~48~9 ~39~48~9 minecraft:stained_glass 12
fill ~38~49~9 ~39~49~9 minecraft:stained_glass 1
fill ~38~50~9 ~38~50~11 minecraft:stained_glass 1
setblock ~39~44~9 minecraft:stained_glass_pane 14
setblock ~39~45~9 minecraft:stained_glass 1
setblock ~39~46~9 minecraft:stained_glass 12
fill ~39~47~9 ~39~47~10 minecraft:stained_glass 14
setblock ~39~50~9 minecraft:stained_glass 12
fill ~39~51~9 ~41~51~9 minecraft:stained_glass 14
fill ~39~52~9 ~40~52~9 minecraft:stained_glass 1
setblock ~39~53~9 minecraft:stained_glass 1
setblock ~39~54~9 minecraft:stained_glass_pane 1
setblock ~40~42~9 minecraft:stained_glass_pane 1
setblock ~40~43~9 minecraft:stained_glass_pane 4
setblock ~40~44~9 minecraft:stained_glass 1
setblock ~40~45~9 minecraft:stained_glass 12
fill ~40~46~9 ~40~48~9 minecraft:stained_glass 1
fill ~40~49~9 ~42~49~9 minecraft:stained_glass 12
setblock ~40~53~9 minecraft:stained_glass 14
fill ~40~54~9 ~40~54~11 minecraft:stained_glass 1
setblock ~41~45~9 minecraft:stained_glass_pane 14
setblock ~41~46~9 minecraft:stained_glass 12
fill ~41~47~9 ~41~47~11 minecraft:stained_glass 1
setblock ~41~48~9 minecraft:stained_glass 1
setblock ~41~52~9 minecraft:stained_glass 12
setblock ~42~47~9 minecraft:stained_glass_pane 1
setblock ~42~48~9 minecraft:stained_glass 14
fill ~42~50~9 ~42~50~10 minecraft:stained_glass 12
setblock ~42~51~9 minecraft:stained_glass_pane 4
fill ~44~46~9 ~44~46~10 minecraft:stone_block_slab 7
fill ~3~38~10 ~3~39~10 minecraft:leaves 0
setblock ~4~37~10 minecraft:leaves 0
fill ~4~38~10 ~4~38~12 minecraft:dirt 0
setblock ~4~40~10 minecraft:tallgrass 0
fill ~5~37~10 ~5~38~13 minecraft:stone 0
setblock ~5~39~10 minecraft:dirt 0
setblock ~5~42~10 minecraft:stone_block_slab 15
setblock ~5~43~10 minecraft:nether_brick_fence
setblock ~5~44~10 minecraft:nether_brick_stairs 4
setblock ~5~45~10 minecraft:nether_brick_stairs 2
setblock ~5~47~10 minecraft:nether_brick_stairs 4
fill ~5~48~10 ~5~49~10 minecraft:nether_brick
setblock ~5~50~10 minecraft:nether_brick_stairs 0
setblock ~5~63~10 minecraft:nether_brick_stairs 2
setblock ~6~35~10 minecraft:cobblestone
setblock ~6~37~10 minecraft:cobblestone_wall 0
setblock ~6~38~10 minecraft:redstone_torch 5
fill ~6~39~10 ~6~39~13 minecraft:stone 0
setblock ~6~41~10 minecraft:nether_brick_stairs 4
fill ~6~42~10 ~6~44~10 minecraft:stonebrick 0
setblock ~6~45~10 minecraft:stone 6
setblock ~6~46~10 minecraft:stonebrick 0
setblock ~6~47~10 minecraft:nether_brick
setblock ~6~48~10 minecraft:nether_brick_stairs 1
setblock ~6~50~10 minecraft:nether_brick_stairs 5
setblock ~6~51~10 minecraft:stone_block_slab 7
setblock ~6~52~10 minecraft:stone_brick_stairs 6
setblock ~6~53~10 minecraft:stone_stairs 4
fill ~6~54~10 ~6~55~10 minecraft:stonebrick 0
setblock ~6~56~10 minecraft:stone_stairs 0
setblock ~6~57~10 minecraft:stone_stairs 4
setblock ~6~58~10 minecraft:stone_brick_stairs 0
fill ~6~59~10 ~6~59~12 minecraft:cobblestone_wall 0
setblock ~7~30~10 minecraft:trapdoor 1
fill ~7~33~10 ~7~33~12 minecraft:stone 0
setblock ~7~34~10 minecraft:stone 0
setblock ~7~35~10 minecraft:crafting_table
fill ~7~39~10 ~7~39~12 minecraft:wooden_slab 9
fill ~7~40~10 ~7~40~12 minecraft:double_wooden_slab 1
fill ~7~41~10 ~7~41~12 minecraft:bookshelf
fill ~7~57~10 ~7~57~12 minecraft:stone_block_slab 13
fill ~7~58~10 ~7~58~12 minecraft:stonebrick 0
setblock ~7~59~10 minecraft:nether_brick_stairs 7
setblock ~7~61~10 minecraft:stone_brick_stairs 7
setblock ~7~62~10 minecraft:stone_brick_stairs 2
setblock ~7~64~10 minecraft:nether_brick
setblock ~7~65~10 minecraft:nether_brick_stairs 0
setblock ~8~29~10 minecraft:trapdoor 1
setblock ~8~30~10 minecraft:glowstone
fill ~8~31~10 ~8~32~11 minecraft:stone 0
setblock ~8~34~10 minecraft:double_wooden_slab 1
fill ~8~65~10 ~8~66~10 minecraft:nether_brick
setblock ~8~67~10 minecraft:stone_block_slab 7
fill ~9~28~10 ~9~29~12 minecraft:stone 0
setblock ~9~49~10 minecraft:stone_brick_stairs 6
setblock ~9~50~10 minecraft:stone_brick_stairs 3
setblock ~9~67~10 minecraft:nether_brick
setblock ~9~68~10 minecraft:stained_glass 15
setblock ~9~69~10 minecraft:nether_brick_stairs 6
setblock ~9~70~10 minecraft:nether_brick_stairs 2
setblock ~10~30~10 minecraft:cobblestone
fill ~10~31~10 ~10~31~12 minecraft:stone 0
fill ~10~33~10 ~12~33~10 minecraft:nether_brick
setblock ~10~35~10 minecraft:redstone_wire 0
fill ~10~65~10 ~10~66~10 minecraft:nether_brick
setblock ~10~67~10 minecraft:stone_block_slab 7
fill ~11~32~10 ~11~32~12 minecraft:stone 0
fill ~11~34~10 ~11~34~12 minecraft:planks 1
fill ~11~39~10 ~11~39~12 minecraft:wooden_slab 9
fill ~11~40~10 ~11~40~12 minecraft:double_wooden_slab 1
setblock ~11~41~10 minecraft:bookshelf
fill ~11~57~10 ~11~57~12 minecraft:stone_block_slab 13
fill ~11~58~10 ~11~58~12 minecraft:stonebrick 0
setblock ~11~59~10 minecraft:nether_brick_stairs 7
setblock ~11~61~10 minecraft:stone_brick_stairs 7
setblock ~11~62~10 minecraft:stone_brick_stairs 2
setblock ~11~64~10 minecraft:nether_brick
setblock ~11~65~10 minecraft:nether_brick_stairs 1
fill ~12~34~10 ~14~34~10 minecraft:nether_brick
fill ~12~35~10 ~12~37~10 minecraft:nether_brick
fill ~12~38~10 ~12~38~14 minecraft:stone 0
fill ~12~39~10 ~12~39~13 minecraft:stone 0
setblock ~12~41~10 minecraft:nether_brick_stairs 5
fill ~12~42~10 ~12~44~10 minecraft:stonebrick 0
setblock ~12~45~10 minecraft:stone 6
setblock ~12~46~10 minecraft:stonebrick 0
setblock ~12~47~10 minecraft:nether_brick
setblock ~12~48~10 minecraft:nether_brick_stairs 0
setblock ~12~50~10 minecraft:nether_brick_stairs 4
setblock ~12~51~10 minecraft:stone_block_slab 7
setblock ~12~52~10 minecraft:stone_brick_stairs 6
setblock ~12~53~10 minecraft:stone_stairs 5
fill ~12~54~10 ~12~55~10 minecraft:stonebrick 0
setblock ~12~56~10 minecraft:stone_stairs 1
setblock ~12~57~10 minecraft:stone_stairs 5
setblock ~12~58~10 minecraft:stone_brick_stairs 1
fill ~12~59~10 ~12~59~12 minecraft:cobblestone_wall 0
setblock ~12~63~10 minecraft:nether_brick_stairs 2
setblock ~13~33~10 minecraft:nether_brick_stairs 5
fill ~13~35~10 ~18~35~10 minecraft:nether_brick_fence
setblock ~13~37~10 minecraft:nether_brick_stairs 5
setblock ~13~38~10 minecraft:nether_brick
setblock ~13~39~10 minecraft:nether_brick_stairs 5
setblock ~13~42~10 minecraft:stone_block_slab 15
setblock ~13~43~10 minecraft:nether_brick_fence
setblock ~13~44~10 minecraft:nether_brick_stairs 5
setblock ~13~45~10 minecraft:nether_brick_stairs 2
setblock ~13~47~10 minecraft:nether_brick_stairs 5
fill ~13~48~10 ~13~49~10 minecraft:nether_brick
setblock ~13~50~10 minecraft:nether_brick_stairs 1
fill ~13~63~10 ~13~63~11 minecraft:nether_brick_stairs 1
setblock ~14~33~10 minecraft:stone_block_slab 15
setblock ~14~36~10 minecraft:redstone_torch 5
setblock ~14~38~10 minecraft:nether_brick_stairs 5
setblock ~14~39~10 minecraft:stone_block_slab 7
setblock ~15~34~10 minecraft:double_stone_block_slab 7
fill ~15~39~10 ~16~39~10 minecraft:double_stone_block_slab 7
setblock ~15~40~10 minecraft:leaves 0
setblock ~16~34~10 minecraft:stone_block_slab 15
fill ~17~24~10 ~17~24~12 minecraft:grass
setblock ~17~34~10 minecraft:double_stone_block_slab 7
setblock ~17~38~10 minecraft:nether_brick_stairs 4
fill ~17~39~10 ~17~39~12 minecraft:stone_block_slab 7
fill ~18~23~10 ~18~23~12 minecraft:dirt 0
fill ~18~24~10 ~18~24~12 minecraft:stone 0
fill ~18~25~10 ~18~25~12 minecraft:grass
setblock ~18~33~10 minecraft:stone_block_slab 15
fill ~18~34~10 ~19~34~10 minecraft:nether_brick
setblock ~18~37~10 minecraft:nether_brick_stairs 4
setblock ~18~38~10 minecraft:nether_brick_stairs 1
fill ~18~43~10 ~18~43~13 minecraft:nether_brick_stairs 4
setblock ~18~57~10 minecraft:nether_brick_stairs 7
setblock ~18~58~10 minecraft:nether_brick_stairs 2
fill ~19~20~10 ~19~20~11 minecraft:stone 0
setblock ~19~21~10 minecraft:stone 0
setblock ~19~22~10 minecraft:dirt 0
setblock ~19~23~10 minecraft:stone 0
setblock ~19~26~10 minecraft:tallgrass 0
setblock ~19~33~10 minecraft:nether_brick_stairs 4
fill ~19~35~10 ~19~36~10 minecraft:nether_brick
setblock ~19~37~10 minecraft:nether_brick_stairs 1
fill ~19~39~10 ~19~39~11 minecraft:iron_bars
setblock ~19~40~10 minecraft:nether_brick_stairs 2
fill ~19~42~10 ~19~42~12 minecraft:stone_stairs 4
fill ~19~43~10 ~19~43~12 minecraft:planks 1
setblock ~19~44~10 minecraft:stone 6
setblock ~19~45~10 minecraft:stone_brick_stairs 3
setblock ~19~46~10 minecraft:stone_brick_stairs 7
setblock ~19~47~10 minecraft:stone_brick_stairs 2
setblock ~19~49~10 minecraft:stone_brick_stairs 4
setblock ~19~50~10 minecraft:stone_brick_stairs 0
setblock ~19~51~10 minecraft:stone_block_slab 5
setblock ~19~52~10 minecraft:stonebrick 0
setblock ~19~53~10 minecraft:stone 6
fill ~19~54~10 ~19~57~10 minecraft:stonebrick 0
setblock ~19~58~10 minecraft:stone_brick_stairs 2
fill ~19~66~10 ~19~66~11 minecraft:nether_brick_stairs 0
fill ~20~18~10 ~20~19~12 minecraft:stone 0
fill ~20~25~10 ~20~25~12 minecraft:stone 6
setblock ~20~26~10 minecraft:stone_stairs 4
setblock ~20~27~10 minecraft:cobblestone_wall 0
setblock ~20~28~10 minecraft:nether_brick_fence
setblock ~20~29~10 minecraft:nether_brick_stairs 2
setblock ~20~32~10 minecraft:nether_brick_stairs 4
setblock ~20~33~10 minecraft:nether_brick
setblock ~20~40~10 minecraft:stonebrick 0
setblock ~20~41~10 minecraft:stone_brick_stairs 0
setblock ~20~51~10 minecraft:wooden_slab 9
setblock ~20~58~10 minecraft:stonebrick 0
setblock ~20~59~10 minecraft:stonebrick 3
setblock ~20~60~10 minecraft:stone_brick_stairs 3
setblock ~20~61~10 minecraft:nether_brick_stairs 4
setblock ~20~62~10 minecraft:stone_brick_stairs 6
fill ~20~63~10 ~20~65~10 minecraft:stonebrick 0
setblock ~20~66~10 minecraft:nether_brick_stairs 2
fill ~21~16~10 ~21~16~12 minecraft:stone 0
setblock ~21~18~10 minecraft:stone_block_slab 15
setblock ~21~19~10 minecraft:chest 5
fill ~21~21~10 ~21~21~13 minecraft:stonebrick 0
fill ~21~25~10 ~21~25~12 minecraft:nether_brick
setblock ~21~26~10 minecraft:stone_stairs 5
setblock ~21~29~10 minecraft:stonebrick 0
setblock ~21~30~10 minecraft:stone_brick_stairs 4
fill ~21~31~10 ~21~31~13 minecraft:stonebrick 0
fill ~21~32~10 ~21~33~12 minecraft:stonebrick 0
fill ~21~42~10 ~22~42~10 minecraft:wooden_slab 9
setblock ~21~61~10 minecraft:planks 1
fill ~21~62~10 ~21~62~12 minecraft:stone_brick_stairs 5
setblock ~21~67~10 minecraft:nether_brick_stairs 2
fill ~22~13~10 ~22~15~11 minecraft:stone 0
fill ~22~16~10 ~22~16~12 minecraft:stonebrick 0
setblock ~22~17~10 minecraft:stone_block_slab 15
setblock ~22~21~10 minecraft:stonebrick 2
fill ~22~25~10 ~22~25~12 minecraft:obsidian
setblock ~22~68~10 minecraft:nether_brick
setblock ~22~69~10 minecraft:nether_brick_stairs 0
setblock ~23~7~10 minecraft:stone_block_slab 13
fill ~23~8~10 ~23~10~10 minecraft:cobblestone_wall 0
setblock ~23~11~10 minecraft:stonebrick 0
fill ~23~12~10 ~23~12~13 minecraft:stone 0
setblock ~23~16~10 minecraft:stonebrick 2
fill ~23~21~10 ~23~21~14 minecraft:stonebrick 0
setblock ~23~69~10 minecraft:web
setblock ~23~70~10 minecraft:glowstone
fill ~23~71~10 ~25~72~10 minecraft:nether_brick
fill ~24~4~10 ~24~4~11 minecraft:stone 0
fill ~24~5~10 ~24~6~10 minecraft:stone 0
fill ~24~7~10 ~24~7~12 minecraft:stonebrick 0
setblock ~24~11~10 minecraft:stonebrick 2
fill ~24~16~10 ~24~16~12 minecraft:stonebrick 0
setblock ~24~42~10 minecraft:trapdoor 3
setblock ~24~51~10 minecraft:trapdoor 3
setblock ~24~70~10 minecraft:nether_brick
fill ~24~73~10 ~24~75~12 minecraft:nether_brick
setblock ~24~76~10 minecraft:nether_brick_stairs 2
setblock ~25~7~10 minecraft:stone_block_slab 13
fill ~25~8~10 ~25~10~10 minecraft:cobblestone_wall 0
setblock ~25~11~10 minecraft:stonebrick 1
setblock ~25~16~10 minecraft:stonebrick 1
fill ~25~21~10 ~25~21~13 minecraft:stonebrick 0
setblock ~25~70~10 minecraft:glowstone
fill ~26~13~10 ~26~15~12 minecraft:stone 0
fill ~26~16~10 ~26~16~12 minecraft:stonebrick 0
setblock ~26~17~10 minecraft:redstone_wire 0
fill ~26~25~10 ~26~25~12 minecraft:obsidian
fill ~26~42~10 ~27~42~10 minecraft:wooden_slab 9
setblock ~26~68~10 minecraft:nether_brick
setblock ~26~69~10 minecraft:nether_brick_stairs 1
fill ~27~16~10 ~27~16~12 minecraft:stone 0
setblock ~27~18~10 minecraft:flower_pot 0
fill ~27~25~10 ~27~25~12 minecraft:nether_brick
setblock ~27~26~10 minecraft:stone_stairs 4
setblock ~27~29~10 minecraft:stonebrick 0
setblock ~27~30~10 minecraft:stone_brick_stairs 5
fill ~27~31~10 ~27~33~10 minecraft:stonebrick 0
setblock ~27~61~10 minecraft:planks 1
setblock ~27~62~10 minecraft:stone_brick_stairs 4
setblock ~27~63~10 minecraft:skull 1
setblock ~27~66~10 minecraft:nether_brick
setblock ~27~67~10 minecraft:nether_brick_stairs 2
setblock ~28~17~10 minecraft:stonebrick 0
setblock ~28~18~10 minecraft:cobblestone
setblock ~28~19~10 minecraft:stonebrick 0
fill ~28~25~10 ~28~25~12 minecraft:stone 6
setblock ~28~26~10 minecraft:stone_stairs 5
setblock ~28~27~10 minecraft:cobblestone_wall 0
setblock ~28~28~10 minecraft:nether_brick_fence
setblock ~28~29~10 minecraft:nether_brick_stairs 2
setblock ~28~33~10 minecraft:stone_brick_stairs 5
setblock ~28~40~10 minecraft:nether_brick_stairs 4
setblock ~28~41~10 minecraft:double_stone_block_slab 7
setblock ~28~42~10 minecraft:nether_brick_stairs 0
setblock ~28~51~10 minecraft:wooden_slab 9
setblock ~28~58~10 minecraft:stonebrick 0
setblock ~28~59~10 minecraft:stonebrick 3
setblock ~28~60~10 minecraft:stone_brick_stairs 3
setblock ~28~61~10 minecraft:nether_brick_stairs 5
setblock ~28~62~10 minecraft:stone_brick_stairs 6
fill ~28~63~10 ~28~65~10 minecraft:stonebrick 0
setblock ~28~66~10 minecraft:nether_brick_stairs 2
setblock ~29~21~10 minecraft:dirt 0
setblock ~29~23~10 minecraft:stone 0
setblock ~29~34~10 minecraft:nether_brick_stairs 6
fill ~29~35~10 ~29~35~12 minecraft:stone_stairs 0
fill ~29~36~10 ~29~36~12 minecraft:iron_bars
fill ~29~37~10 ~29~38~10 minecraft:iron_bars
setblock ~29~40~10 minecraft:stone_brick_stairs 2
fill ~29~42~10 ~29~42~12 minecraft:nether_brick_stairs 5
fill ~29~43~10 ~29~45~10 minecraft:double_stone_block_slab 7
setblock ~29~46~10 minecraft:nether_brick_stairs 3
setblock ~29~47~10 minecraft:stone_brick_stairs 7
setblock ~29~48~10 minecraft:stone_brick_stairs 1
setblock ~29~50~10 minecraft:stone_block_slab 13
setblock ~29~51~10 minecraft:stone_brick_stairs 1
setblock ~29~52~10 minecraft:stonebrick 0
setblock ~29~53~10 minecraft:stone 6
fill ~29~54~10 ~29~57~10 minecraft:stonebrick 0
setblock ~29~58~10 minecraft:stone_brick_stairs 2
fill ~29~66~10 ~29~66~12 minecraft:nether_brick_stairs 1
fill ~30~23~10 ~30~23~12 minecraft:dirt 0
fill ~30~24~10 ~30~24~12 minecraft:stone 0
fill ~30~25~10 ~30~25~12 minecraft:grass
setblock ~30~26~10 minecraft:leaves 0
fill ~30~34~10 ~30~34~12 minecraft:nether_brick_stairs 5
setblock ~30~35~10 minecraft:stone_stairs 5
setblock ~30~39~10 minecraft:nether_brick_stairs 7
setblock ~30~40~10 minecraft:nether_brick_stairs 2
setblock ~30~44~10 minecraft:nether_brick_stairs 5
setblock ~30~45~10 minecraft:double_stone_block_slab 7
fill ~30~52~10 ~30~52~13 minecraft:nether_brick_stairs 5
setblock ~30~57~10 minecraft:nether_brick_stairs 7
setblock ~30~58~10 minecraft:nether_brick_stairs 2
fill ~31~24~10 ~31~24~12 minecraft:grass
setblock ~31~45~10 minecraft:nether_brick_stairs 5
fill ~32~45~10 ~33~45~10 minecraft:stone_block_slab 15
fill ~33~46~10 ~35~46~10 minecraft:stone_block_slab 7
setblock ~37~49~10 minecraft:stained_glass_pane 4
fill ~37~50~10 ~37~50~11 minecraft:stained_glass 14
setblock ~37~51~10 minecraft:stained_glass_pane 12
setblock ~38~45~10 minecraft:stained_glass_pane 12
setblock ~38~46~10 minecraft:stained_glass 12
setblock ~38~47~10 minecraft:stained_glass 14
fill ~38~48~10 ~38~49~10 minecraft:stained_glass 12
fill ~38~51~10 ~39~51~10 minecraft:stained_glass 14
setblock ~38~52~10 minecraft:stained_glass 14
setblock ~38~53~10 minecraft:stained_glass_pane 1
setblock ~39~41~10 minecraft:stained_glass_pane 14
fill ~39~42~10 ~39~42~11 minecraft:stained_glass 12
fill ~39~43~10 ~41~43~10 minecraft:stained_glass 14
setblock ~39~44~10 minecraft:stained_glass 12
fill ~39~45~10 ~39~46~10 minecraft:stained_glass 14
fill ~39~48~10 ~40~49~10 minecraft:stained_glass 1
fill ~39~52~10 ~39~53~10 minecraft:stained_glass 12
setblock ~39~54~10 minecraft:stained_glass 14
setblock ~40~38~10 minecraft:stained_glass_pane 14
setblock ~40~39~10 minecraft:stained_glass 12
setblock ~40~40~10 minecraft:stained_glass 1
setblock ~40~41~10 minecraft:stained_glass 12
setblock ~40~42~10 minecraft:stained_glass 14
setblock ~40~46~10 minecraft:stained_glass 14
setblock ~40~47~10 minecraft:stained_glass 12
fill ~40~50~10 ~41~50~10 minecraft:stained_glass 14
fill ~40~51~10 ~42~51~10 minecraft:stained_glass 1
setblock ~40~52~10 minecraft:stained_glass 14
setblock ~40~53~10 minecraft:stained_glass 12
fill ~40~55~10 ~41~55~10 minecraft:stained_glass 12
fill ~40~56~10 ~40~56~11 minecraft:stained_glass 14
setblock ~40~57~10 minecraft:stained_glass_pane 1
setblock ~41~42~10 minecraft:stained_glass_pane 4
setblock ~41~44~10 minecraft:stained_glass 1
setblock ~41~45~10 minecraft:stained_glass 14
fill ~41~46~10 ~42~46~10 minecraft:stained_glass 1
setblock ~41~48~10 minecraft:stained_glass 12
fill ~41~49~10 ~42~49~10 minecraft:stained_glass 1
fill ~41~52~10 ~42~52~10 minecraft:stained_glass 1
fill ~41~53~10 ~41~54~11 minecraft:stained_glass 1
setblock ~42~44~10 minecraft:stained_glass_pane 1
fill ~42~45~10 ~42~45~11 minecraft:stained_glass 1
fill ~42~47~10 ~42~47~11 minecraft:stained_glass 1
setblock ~42~48~10 minecraft:stained_glass 1
setblock ~42~53~10 minecraft:stained_glass 12
setblock ~43~47~10 minecraft:stained_glass_pane 12
setblock ~43~48~10 minecraft:stained_glass_pane 1
setblock ~43~49~10 minecraft:stained_glass 12
fill ~43~50~10 ~43~50~12 minecraft:stained_glass 1
setblock ~43~51~10 minecraft:stained_glass_pane 4
fill ~3~39~11 ~3~39~12 minecraft:grass
setblock ~3~40~11 minecraft:leaves 0
setblock ~4~36~11 minecraft:leaves 0
setblock ~4~37~11 minecraft:dirt 0
fill ~4~39~11 ~4~39~12 minecraft:dirt 0
fill ~4~40~11 ~4~40~12 minecraft:grass
setblock ~4~41~11 minecraft:leaves 0
fill ~5~35~11 ~5~36~11 minecraft:stone 0
fill ~5~39~11 ~5~39~12 minecraft:stone 0
setblock ~5~45~11 minecraft:nether_brick_stairs 4
fill ~5~63~11 ~5~63~12 minecraft:nether_brick_stairs 0
fill ~6~33~11 ~6~34~11 minecraft:stone 0
setblock ~6~35~11 minecraft:cauldron 4
setblock ~6~36~11 minecraft:tripwire_hook 3
fill ~6~37~11 ~6~37~12 minecraft:nether_brick_stairs 5
setblock ~6~40~11 minecraft:dirt 0
setblock ~6~41~11 minecraft:stone_stairs 0
fill ~6~42~11 ~6~43~11 minecraft:iron_bars
setblock ~6~44~11 minecraft:stone_stairs 4
setblock ~6~45~11 minecraft:stone_stairs 1
setblock ~6~51~11 minecraft:stone_brick_stairs 4
setblock ~6~52~11 minecraft:stonebrick 0
setblock ~6~53~11 minecraft:stone_stairs 0
setblock ~6~56~11 minecraft:stone_stairs 4
setblock ~6~57~11 minecraft:stone_stairs 0
setblock ~6~58~11 minecraft:stone_brick_stairs 4
fill ~6~63~11 ~6~64~11 minecraft:nether_brick
setblock ~6~65~11 minecraft:nether_brick_stairs 0
fill ~7~31~11 ~7~32~11 minecraft:stone 0
fill ~7~34~11 ~8~34~12 minecraft:wooden_slab 9
setblock ~7~50~11 minecraft:stone_brick_stairs 4
setblock ~7~51~11 minecraft:stone_brick_stairs 1
setblock ~7~59~11 minecraft:stone_block_slab 15
setblock ~7~62~11 minecraft:stone_brick_stairs 4
fill ~7~65~11 ~7~66~11 minecraft:nether_brick
setblock ~7~67~11 minecraft:nether_brick_stairs 0
fill ~8~29~11 ~8~30~11 minecraft:stone 0
setblock ~8~35~11 minecraft:redstone_wire 0
fill ~8~40~11 ~8~40~13 minecraft:double_wooden_slab 1
setblock ~8~49~11 minecraft:stone_brick_stairs 4
setblock ~8~50~11 minecraft:stone_brick_stairs 1
setblock ~8~67~11 minecraft:nether_brick
setblock ~8~68~11 minecraft:stained_glass 15
setblock ~8~69~11 minecraft:nether_brick_stairs 4
setblock ~8~70~11 minecraft:nether_brick_stairs 0
fill ~9~24~11 ~9~25~11 minecraft:stone 0
setblock ~9~26~11 minecraft:cobblestone
fill ~9~27~11 ~10~27~11 minecraft:stone 0
setblock ~9~34~11 minecraft:planks 1
setblock ~9~40~11 minecraft:planks 1
setblock ~9~48~11 minecraft:stone_block_slab 13
setblock ~9~49~11 minecraft:stonebrick 0
fill ~9~67~11 ~9~68~11 minecraft:glowstone
setblock ~9~69~11 minecraft:nether_brick
setblock ~9~70~11 minecraft:glowstone
fill ~9~71~11 ~9~73~11 minecraft:nether_brick
fill ~10~28~11 ~10~30~11 minecraft:stone 0
fill ~10~33~11 ~12~33~11 minecraft:stone 0
fill ~10~34~11 ~10~34~13 minecraft:wooden_slab 9
fill ~10~40~11 ~10~40~13 minecraft:double_wooden_slab 1
setblock ~10~49~11 minecraft:stone_brick_stairs 5
setblock ~10~50~11 minecraft:stone_brick_stairs 0
setblock ~10~67~11 minecraft:nether_brick
setblock ~10~68~11 minecraft:stained_glass 15
setblock ~10~69~11 minecraft:nether_brick_stairs 5
setblock ~10~70~11 minecraft:nether_brick_stairs 1
fill ~11~29~11 ~11~31~11 minecraft:stone 0
setblock ~11~41~11 minecraft:oak_stairs 4
setblock ~11~51~11 minecraft:stone_brick_stairs 0
setblock ~11~59~11 minecraft:stone_block_slab 15
setblock ~11~62~11 minecraft:stone_brick_stairs 5
fill ~11~65~11 ~11~66~11 minecraft:nether_brick
setblock ~11~67~11 minecraft:nether_brick_stairs 1
setblock ~12~32~11 minecraft:cobblestone
setblock ~12~34~11 minecraft:double_stone_block_slab 5
setblock ~12~35~11 minecraft:spruce_door 0
setblock ~12~37~11 minecraft:nether_brick_stairs 5
setblock ~12~40~11 minecraft:dirt 0
setblock ~12~41~11 minecraft:stone_stairs 1
fill ~12~42~11 ~12~43~11 minecraft:iron_bars
setblock ~12~44~11 minecraft:stone_stairs 5
setblock ~12~45~11 minecraft:stone_stairs 0
setblock ~12~51~11 minecraft:stone_brick_stairs 5
setblock ~12~52~11 minecraft:stonebrick 0
setblock ~12~53~11 minecraft:stone_stairs 1
setblock ~12~56~11 minecraft:stone_stairs 5
setblock ~12~57~11 minecraft:stone_stairs 1
setblock ~12~58~11 minecraft:stone_brick_stairs 5
fill ~12~63~11 ~12~64~11 minecraft:nether_brick
setblock ~12~65~11 minecraft:nether_brick_stairs 1
fill ~13~34~11 ~19~34~11 minecraft:stone_block_slab 13
setblock ~13~38~11 minecraft:nether_brick_stairs 5
setblock ~13~39~11 minecraft:nether_brick
setblock ~13~40~11 minecraft:stone_stairs 1
setblock ~13~45~11 minecraft:nether_brick_stairs 5
setblock ~14~39~11 minecraft:double_stone_block_slab 7
setblock ~14~40~11 minecraft:leaves 0
setblock ~18~22~11 minecraft:dirt 0
setblock ~18~58~11 minecraft:nether_brick_stairs 4
fill ~18~59~11 ~19~59~11 minecraft:stone_block_slab 7
setblock ~19~19~11 minecraft:stone 0
setblock ~19~21~11 minecraft:dirt 0
fill ~19~22~11 ~19~22~13 minecraft:stone 0
fill ~19~23~11 ~19~24~11 minecraft:dirt 0
setblock ~19~37~11 minecraft:stone_block_slab 15
fill ~19~38~11 ~19~38~12 minecraft:iron_bars
setblock ~19~40~11 minecraft:iron_bars
setblock ~19~41~11 minecraft:stone_block_slab 7
setblock ~19~44~11 minecraft:stone_brick_stairs 0
fill ~19~45~11 ~19~46~11 minecraft:cobblestone_wall 0
setblock ~19~47~11 minecraft:stone_brick_stairs 4
setblock ~19~48~11 minecraft:cobblestone_wall 0
setblock ~19~49~11 minecraft:stonebrick 3
setblock ~19~50~11 minecraft:cobblestone_wall 0
setblock ~19~51~11 minecraft:stone_block_slab 13
setblock ~19~52~11 minecraft:planks 1
setblock ~19~53~11 minecraft:stone_brick_stairs 0
setblock ~19~54~11 minecraft:iron_bars
setblock ~19~56~11 minecraft:iron_bars
fill ~19~57~11 ~19~58~11 minecraft:stone_brick_stairs 4
setblock ~20~17~11 minecraft:cobblestone
setblock ~20~29~11 minecraft:stone_block_slab 15
setblock ~20~30~11 minecraft:nether_brick_stairs 0
setblock ~20~33~11 minecraft:nether_brick_stairs 4
setblock ~20~41~11 minecraft:stonebrick 0
setblock ~20~59~11 minecraft:nether_brick_stairs 0
setblock ~20~60~11 minecraft:nether_brick_stairs 4
setblock ~20~61~11 minecraft:cobblestone_wall 0
setblock ~20~62~11 minecraft:stone_brick_stairs 0
fill ~20~63~11 ~20~64~11 minecraft:iron_bars
setblock ~20~65~11 minecraft:stone_brick_stairs 4
fill ~20~66~11 ~20~67~11 minecraft:nether_brick
setblock ~20~68~11 minecraft:nether_brick_stairs 0
setblock ~21~15~11 minecraft:stone 0
setblock ~21~30~11 minecraft:stonebrick 0
fill ~21~42~11 ~21~42~12 minecraft:wooden_slab 9
setblock ~21~61~11 minecraft:stonebrick 0
fill ~21~67~11 ~21~69~11 minecraft:nether_brick
setblock ~21~70~11 minecraft:nether_brick_stairs 0
setblock ~22~10~11 minecraft:cobblestone_wall 0
fill ~22~11~11 ~22~12~11 minecraft:stone 0
setblock ~22~17~11 minecraft:nether_brick
setblock ~22~18~11 minecraft:brewing_stand 0
fill ~22~21~11 ~22~21~13 minecraft:stonebrick 0
fill ~22~69~11 ~22~72~11 minecraft:nether_brick
setblock ~22~73~11 minecraft:nether_brick_stairs 0
setblock ~23~5~11 minecraft:trapdoor 1
setblock ~23~6~11 minecraft:stone_brick_stairs 4
setblock ~23~7~11 minecraft:stonebrick 2
setblock ~23~11~11 minecraft:stonebrick 2
fill ~23~16~11 ~23~16~13 minecraft:stonebrick 0
setblock ~23~17~11 minecraft:redstone_wire 0
setblock ~23~42~11 minecraft:trapdoor 1
setblock ~23~51~11 minecraft:trapdoor 1
fill ~23~70~11 ~23~75~11 minecraft:nether_brick
setblock ~23~76~11 minecraft:nether_brick_stairs 0
fill ~24~2~11 ~24~3~11 minecraft:stone 0
setblock ~24~5~11 minecraft:glowstone
fill ~24~6~11 ~25~6~11 minecraft:stone 0
fill ~24~11~11 ~25~11~11 minecraft:stonebrick 0
setblock ~24~41~11 minecraft:trapdoor 3
setblock ~24~42~11 minecraft:glowstone
setblock ~24~50~11 minecraft:trapdoor 2
setblock ~24~51~11 minecraft:glowstone
fill ~24~76~11 ~24~80~11 minecraft:nether_brick
setblock ~25~5~11 minecraft:trapdoor 1
setblock ~25~7~11 minecraft:stonebrick 1
fill ~25~16~11 ~25~16~12 minecraft:stonebrick 0
setblock ~25~42~11 minecraft:trapdoor 0
setblock ~25~51~11 minecraft:trapdoor 0
fill ~25~70~11 ~26~72~11 minecraft:nether_brick
fill ~25~73~11 ~25~75~11 minecraft:nether_brick
setblock ~25~76~11 minecraft:nether_brick_stairs 1
setblock ~26~9~11 minecraft:cobblestone_wall 0
fill ~26~10~11 ~26~12~11 minecraft:stone 0
setblock ~26~21~11 minecraft:stonebrick 2
fill ~26~69~11 ~27~69~11 minecraft:nether_brick
setblock ~26~73~11 minecraft:nether_brick_stairs 1
setblock ~27~14~11 minecraft:cobblestone
fill ~27~15~11 ~27~15~12 minecraft:stone 0
setblock ~27~17~11 minecraft:nether_brick_stairs 0
fill ~27~19~11 ~27~19~12 minecraft:stone_block_slab 15
setblock ~27~20~11 minecraft:skull 1
fill ~27~21~11 ~27~21~13 minecraft:stonebrick 0
setblock ~27~30~11 minecraft:stone_stairs 1
fill ~27~31~11 ~27~32~11 minecraft:iron_bars
setblock ~27~33~11 minecraft:stone_stairs 5
fill ~27~42~11 ~27~42~12 minecraft:wooden_slab 9
setblock ~27~61~11 minecraft:stonebrick 0
setblock ~27~62~11 minecraft:enchanting_table
setblock ~27~66~11 minecraft:web
fill ~27~67~11 ~28~67~11 minecraft:nether_brick
setblock ~27~68~11 minecraft:nether_brick
setblock ~27~70~11 minecraft:nether_brick_stairs 1
setblock ~28~16~11 minecraft:stone_brick_stairs 5
setblock ~28~17~11 minecraft:stone_brick_stairs 1
setblock ~28~18~11 minecraft:iron_bars
setblock ~28~19~11 minecraft:stone_brick_stairs 5
setblock ~28~29~11 minecraft:stone_block_slab 15
setblock ~28~33~11 minecraft:stone_block_slab 11
setblock ~28~41~11 minecraft:stonebrick 0
setblock ~28~42~11 minecraft:stone_block_slab 7
setblock ~28~59~11 minecraft:nether_brick_stairs 1
setblock ~28~60~11 minecraft:nether_brick_stairs 5
setblock ~28~61~11 minecraft:cobblestone_wall 0
setblock ~28~62~11 minecraft:stone_brick_stairs 1
fill ~28~63~11 ~28~64~11 minecraft:iron_bars
setblock ~28~65~11 minecraft:stone_brick_stairs 5
setblock ~28~66~11 minecraft:nether_brick
setblock ~28~68~11 minecraft:nether_brick_stairs 1
fill ~29~20~11 ~29~22~12 minecraft:stone 0
fill ~29~23~11 ~29~24~11 minecraft:dirt 0
setblock ~29~34~11 minecraft:double_stone_block_slab 3
fill ~29~38~11 ~29~39~12 minecraft:iron_bars
setblock ~29~40~11 minecraft:iron_bars
fill ~29~41~11 ~30~41~11 minecraft:stone_block_slab 7
setblock ~29~43~11 minecraft:nether_brick_stairs 5
setblock ~29~44~11 minecraft:stone_brick_stairs 1
setblock ~29~45~11 minecraft:stone_brick_stairs 5
setblock ~29~46~11 minecraft:stone_block_slab 7
setblock ~29~47~11 minecraft:stone_block_slab 13
setblock ~29~48~11 minecraft:stone_brick_stairs 5
setblock ~29~49~11 minecraft:cobblestone_wall 0
setblock ~29~50~11 minecraft:stone_block_slab 5
setblock ~29~51~11 minecraft:stone_brick_stairs 5
setblock ~29~52~11 minecraft:planks 1
setblock ~29~53~11 minecraft:stone_brick_stairs 1
fill ~29~54~11 ~29~55~11 minecraft:iron_bars
fill ~29~57~11 ~29~58~11 minecraft:stone_brick_stairs 5
fill ~29~59~11 ~30~59~11 minecraft:stone_block_slab 7
setblock ~30~21~11 minecraft:stone 0
setblock ~30~22~11 minecraft:dirt 0
setblock ~30~35~11 minecraft:stone_stairs 1
setblock ~30~40~11 minecraft:nether_brick_stairs 5
setblock ~30~58~11 minecraft:nether_brick_stairs 5
fill ~31~19~11 ~31~20~11 minecraft:leaves 0
setblock ~31~21~11 minecraft:leaves 0
setblock ~31~23~11 minecraft:dirt 0
setblock ~31~25~11 minecraft:leaves 0
setblock ~31~45~11 minecraft:stone_block_slab 15
setblock ~35~46~11 minecraft:nether_brick_stairs 4
setblock ~35~47~11 minecraft:nether_brick_stairs 0
setblock ~36~47~11 minecraft:nether_brick_stairs 5
setblock ~36~48~11 minecraft:nether_brick_stairs 0
setblock ~37~48~11 minecraft:nether_brick_stairs 5
setblock ~37~49~11 minecraft:nether_brick_stairs 0
setblock ~37~51~11 minecraft:stained_glass 12
setblock ~38~43~11 minecraft:stained_glass_pane 4
setblock ~38~44~11 minecraft:stained_glass 14
fill ~38~45~11 ~38~47~12 minecraft:stained_glass 1
fill ~38~48~11 ~38~48~13 minecraft:stained_glass 14
setblock ~38~49~11 minecraft:stained_glass 1
fill ~38~51~11 ~39~51~11 minecraft:stained_glass 1
fill ~38~52~11 ~38~52~12 minecraft:stained_glass 12
fill ~38~53~11 ~40~53~11 minecraft:stained_glass 1
setblock ~38~54~11 minecraft:stained_glass_pane 4
setblock ~39~39~11 minecraft:stained_glass_pane 1
fill ~39~40~11 ~40~40~11 minecraft:stained_glass 12
setblock ~39~41~11 minecraft:stained_glass 12
setblock ~39~43~11 minecraft:stained_glass 1
setblock ~39~46~11 minecraft:stained_glass 12
setblock ~39~47~11 minecraft:stained_glass 1
fill ~39~48~11 ~39~49~11 minecraft:stained_glass 12
setblock ~39~52~11 minecraft:stained_glass 1
fill ~39~54~11 ~39~55~11 minecraft:stained_glass 1
setblock ~39~56~11 minecraft:stained_glass_pane 4
setblock ~40~35~11 minecraft:stained_glass_pane 4
setblock ~40~36~11 minecraft:stained_glass 14
setblock ~40~37~11 minecraft:stained_glass 1
setblock ~40~38~11 minecraft:stained_glass 12
setblock ~40~39~11 minecraft:stained_glass 1
fill ~40~41~11 ~40~41~12 minecraft:stained_glass 1
fill ~40~46~11 ~40~46~12 minecraft:stained_glass 1
fill ~40~47~11 ~40~51~11 minecraft:glowstone
setblock ~40~52~11 minecraft:stained_glass 12
setblock ~40~55~11 minecraft:stained_glass 12
setblock ~40~57~11 minecraft:stained_glass 1
setblock ~40~58~11 minecraft:stained_glass 12
setblock ~40~59~11 minecraft:stained_glass_pane 4
setblock ~41~41~11 minecraft:stained_glass_pane 12
fill ~41~42~11 ~41~43~11 minecraft:stained_glass 1
fill ~41~46~11 ~41~46~12 minecraft:stained_glass 12
setblock ~41~48~11 minecraft:stained_glass 1
fill ~41~49~11 ~42~49~11 minecraft:stained_glass 12
fill ~41~50~11 ~42~50~12 minecraft:stained_glass 14
fill ~41~51~11 ~41~52~11 minecraft:stained_glass 14
setblock ~41~55~11 minecraft:stained_glass 1
setblock ~41~56~11 minecraft:stained_glass 12
setblock ~41~57~11 minecraft:stained_glass 14
setblock ~41~58~11 minecraft:stained_glass_pane 12
setblock ~42~43~11 minecraft:stained_glass_pane 1
setblock ~42~44~11 minecraft:stained_glass 12
fill ~42~46~11 ~42~46~12 minecraft:stained_glass 14
fill ~42~48~11 ~42~48~13 minecraft:stained_glass 12
fill ~42~51~11 ~43~51~11 minecraft:stained_glass 1
fill ~42~52~11 ~42~52~12 minecraft:stained_glass 1
setblock ~42~53~11 minecraft:stained_glass 14
setblock ~42~54~11 minecraft:stained_glass 1
setblock ~42~55~11 minecraft:stained_glass_pane 14
setblock ~43~46~11 minecraft:stained_glass_pane 12
setblock ~43~47~11 minecraft:stained_glass 1
setblock ~43~48~11 minecraft:nether_brick_stairs 4
setblock ~43~49~11 minecraft:nether_brick_stairs 1
setblock ~43~52~11 minecraft:stained_glass_pane 1
setblock ~44~47~11 minecraft:nether_brick_stairs 4
setblock ~44~48~11 minecraft:nether_brick_stairs 1
setblock ~4~41~12 minecraft:tallgrass 0
setblock ~5~35~12 minecraft:leaves 0
setblock ~5~36~12 minecraft:stone 0
setblock ~5~42~12 minecraft:stone_block_slab 15
setblock ~5~43~12 minecraft:nether_brick_fence
setblock ~5~44~12 minecraft:nether_brick_stairs 4
setblock ~5~45~12 minecraft:nether_brick_stairs 3
setblock ~5~47~12 minecraft:nether_brick_stairs 4
fill ~5~48~12 ~5~49~12 minecraft:nether_brick
setblock ~5~50~12 minecraft:nether_brick_stairs 0
fill ~6~34~12 ~6~35~12 minecraft:stone 0
setblock ~6~36~12 minecraft:brewing_stand 0
setblock ~6~38~12 minecraft:flower_pot 0
fill ~6~40~12 ~6~40~13 minecraft:nether_brick
setblock ~6~41~12 minecraft:nether_brick_stairs 4
fill ~6~42~12 ~6~44~12 minecraft:stonebrick 0
setblock ~6~45~12 minecraft:stone 6
setblock ~6~46~12 minecraft:stonebrick 0
setblock ~6~47~12 minecraft:nether_brick
setblock ~6~48~12 minecraft:nether_brick_stairs 1
setblock ~6~50~12 minecraft:nether_brick_stairs 5
setblock ~6~51~12 minecraft:stone_block_slab 7
setblock ~6~52~12 minecraft:stone_brick_stairs 7
setblock ~6~53~12 minecraft:stone_stairs 4
fill ~6~54~12 ~6~55~12 minecraft:stonebrick 0
setblock ~6~56~12 minecraft:stone_stairs 0
setblock ~6~57~12 minecraft:stone_stairs 4
setblock ~6~58~12 minecraft:stone_brick_stairs 0
setblock ~6~63~12 minecraft:nether_brick_stairs 3
setblock ~7~59~12 minecraft:nether_brick_stairs 6
setblock ~7~60~12 minecraft:redstone_torch 5
setblock ~7~61~12 minecraft:stone_brick_stairs 6
setblock ~7~62~12 minecraft:stone_brick_stairs 3
setblock ~7~64~12 minecraft:nether_brick
setblock ~7~65~12 minecraft:nether_brick_stairs 0
setblock ~8~31~12 minecraft:cobblestone
fill ~8~32~12 ~8~32~13 minecraft:stone 0
fill ~8~65~12 ~8~66~12 minecraft:nether_brick
setblock ~8~67~12 minecraft:stone_block_slab 7
fill ~9~34~12 ~9~34~13 minecraft:wooden_slab 9
fill ~9~40~12 ~9~40~13 minecraft:double_wooden_slab 1
setblock ~9~49~12 minecraft:stone_brick_stairs 7
setblock ~9~50~12 minecraft:stone_brick_stairs 2
setblock ~9~67~12 minecraft:nether_brick
setblock ~9~68~12 minecraft:stained_glass 15
setblock ~9~69~12 minecraft:nether_brick_stairs 7
setblock ~9~70~12 minecraft:nether_brick_stairs 3
fill ~10~29~12 ~10~30~12 minecraft:stone 0
fill ~10~33~12 ~10~33~13 minecraft:stone 0
fill ~10~65~12 ~10~66~12 minecraft:nether_brick
setblock ~10~67~12 minecraft:stone_block_slab 7
setblock ~11~31~12 minecraft:cobblestone
fill ~11~33~12 ~12~33~12 minecraft:nether_brick
setblock ~11~59~12 minecraft:nether_brick_stairs 6
setblock ~11~60~12 minecraft:skull 1
setblock ~11~61~12 minecraft:stone_brick_stairs 6
setblock ~11~62~12 minecraft:stone_brick_stairs 3
setblock ~11~64~12 minecraft:nether_brick
setblock ~11~65~12 minecraft:nether_brick_stairs 1
fill ~12~34~12 ~14~34~12 minecraft:nether_brick
fill ~12~35~12 ~12~37~12 minecraft:nether_brick
fill ~12~40~12 ~12~40~13 minecraft:nether_brick
setblock ~12~41~12 minecraft:nether_brick_stairs 5
fill ~12~42~12 ~12~44~12 minecraft:stonebrick 0
setblock ~12~45~12 minecraft:stone 6
setblock ~12~46~12 minecraft:stonebrick 0
setblock ~12~47~12 minecraft:nether_brick
setblock ~12~48~12 minecraft:nether_brick_stairs 0
setblock ~12~50~12 minecraft:nether_brick_stairs 4
setblock ~12~51~12 minecraft:stone_block_slab 7
setblock ~12~52~12 minecraft:stone_brick_stairs 7
setblock ~12~53~12 minecraft:stone_stairs 5
fill ~12~54~12 ~12~55~12 minecraft:stonebrick 0
setblock ~12~56~12 minecraft:stone_stairs 1
setblock ~12~57~12 minecraft:stone_stairs 5
setblock ~12~58~12 minecraft:stone_brick_stairs 1
fill ~12~63~12 ~12~63~13 minecraft:nether_brick_stairs 1
setblock ~13~33~12 minecraft:nether_brick_stairs 5
fill ~13~35~12 ~18~35~12 minecraft:nether_brick_fence
setblock ~13~37~12 minecraft:nether_brick_stairs 5
setblock ~13~38~12 minecraft:nether_brick
setblock ~13~39~12 minecraft:nether_brick_stairs 5
fill ~13~40~12 ~13~40~13 minecraft:grass
fill ~13~41~12 ~13~41~13 minecraft:leaves 0
setblock ~13~42~12 minecraft:stone_block_slab 15
setblock ~13~43~12 minecraft:nether_brick_fence
setblock ~13~44~12 minecraft:nether_brick_stairs 5
setblock ~13~45~12 minecraft:nether_brick_stairs 3
setblock ~13~47~12 minecraft:nether_brick_stairs 5
fill ~13~48~12 ~13~49~12 minecraft:nether_brick
setblock ~13~50~12 minecraft:nether_brick_stairs 1
setblock ~13~63~12 minecraft:nether_brick_stairs 3
setblock ~14~33~12 minecraft:stone_block_slab 15
setblock ~14~38~12 minecraft:nether_brick_stairs 5
setblock ~14~39~12 minecraft:stone_block_slab 7
setblock ~15~34~12 minecraft:double_stone_block_slab 7
fill ~15~39~12 ~16~39~12 minecraft:double_stone_block_slab 7
setblock ~16~34~12 minecraft:stone_block_slab 15
setblock ~17~25~12 minecraft:tallgrass 0
setblock ~17~34~12 minecraft:double_stone_block_slab 7
setblock ~17~36~12 minecraft:redstone_torch 5
setblock ~17~38~12 minecraft:nether_brick_stairs 4
setblock ~18~26~12 minecraft:tallgrass 2
setblock ~18~33~12 minecraft:stone_block_slab 15
fill ~18~34~12 ~19~34~12 minecraft:nether_brick
setblock ~18~37~12 minecraft:nether_brick_stairs 4
setblock ~18~38~12 minecraft:nether_brick_stairs 1
setblock ~18~57~12 minecraft:nether_brick_stairs 6
setblock ~18~58~12 minecraft:nether_brick_stairs 3
setblock ~19~21~12 minecraft:stone 0
fill ~19~23~12 ~19~24~12 minecraft:stone 0
setblock ~19~33~12 minecraft:nether_brick_stairs 4
fill ~19~35~12 ~19~36~12 minecraft:nether_brick
setblock ~19~37~12 minecraft:nether_brick_stairs 1
setblock ~19~40~12 minecraft:nether_brick_stairs 3
setblock ~19~44~12 minecraft:stone 6
setblock ~19~45~12 minecraft:stone_brick_stairs 2
setblock ~19~46~12 minecraft:stone_brick_stairs 6
setblock ~19~47~12 minecraft:stone_brick_stairs 3
setblock ~19~49~12 minecraft:stone_brick_stairs 4
setblock ~19~50~12 minecraft:stone_brick_stairs 0
setblock ~19~51~12 minecraft:stone_block_slab 5
setblock ~19~52~12 minecraft:stonebrick 0
setblock ~19~53~12 minecraft:stone 6
fill ~19~54~12 ~19~57~12 minecraft:stonebrick 0
setblock ~19~58~12 minecraft:stone_brick_stairs 3
setblock ~19~66~12 minecraft:nether_brick_stairs 3
setblock ~20~26~12 minecraft:stone_stairs 4
setblock ~20~27~12 minecraft:cobblestone_wall 0
setblock ~20~28~12 minecraft:nether_brick_fence
setblock ~20~29~12 minecraft:nether_brick_stairs 3
setblock ~20~32~12 minecraft:nether_brick_stairs 4
fill ~20~33~12 ~20~33~13 minecraft:nether_brick
fill ~20~40~12 ~20~40~13 minecraft:stonebrick 0
setblock ~20~41~12 minecraft:stone_brick_stairs 0
setblock ~20~51~12 minecraft:wooden_slab 9
setblock ~20~58~12 minecraft:stonebrick 0
setblock ~20~59~12 minecraft:stonebrick 3
setblock ~20~60~12 minecraft:stone_brick_stairs 2
setblock ~20~61~12 minecraft:nether_brick_stairs 4
setblock ~20~62~12 minecraft:stone_brick_stairs 7
fill ~20~63~12 ~20~65~12 minecraft:stonebrick 0
fill ~20~66~12 ~20~66~13 minecraft:nether_brick_stairs 0
setblock ~21~18~12 minecraft:chest 5
setblock ~21~19~12 minecraft:stone_block_slab 15
setblock ~21~20~12 minecraft:flower_pot 0
setblock ~21~26~12 minecraft:stone_stairs 5
fill ~21~29~12 ~21~29~13 minecraft:stonebrick 0
setblock ~21~30~12 minecraft:stone_brick_stairs 4
setblock ~21~61~12 minecraft:planks 1
setblock ~21~63~12 minecraft:skull 1
fill ~21~66~12 ~21~66~13 minecraft:nether_brick
setblock ~21~67~12 minecraft:nether_brick_stairs 3
fill ~22~14~12 ~22~15~12 minecraft:stone 0
fill ~22~42~12 ~22~42~13 minecraft:wooden_slab 9
setblock ~22~67~12 minecraft:web
setblock ~22~68~12 minecraft:nether_brick
setblock ~22~69~12 minecraft:nether_brick_stairs 0
setblock ~23~7~12 minecraft:stone_block_slab 13
fill ~23~8~12 ~23~10~12 minecraft:cobblestone_wall 0
fill ~23~11~12 ~24~11~12 minecraft:stonebrick 0
setblock ~23~13~12 minecraft:cobblestone
setblock ~23~70~12 minecraft:glowstone
fill ~23~71~12 ~25~72~12 minecraft:nether_brick
fill ~24~5~12 ~24~6~12 minecraft:stone 0
fill ~24~13~12 ~25~13~13 minecraft:stone 0
setblock ~24~42~12 minecraft:trapdoor 2
setblock ~24~51~12 minecraft:trapdoor 2
fill ~24~70~12 ~24~70~13 minecraft:nether_brick
setblock ~24~76~12 minecraft:nether_brick_stairs 3
setblock ~25~7~12 minecraft:stone_block_slab 13
fill ~25~8~12 ~25~10~12 minecraft:cobblestone_wall 0
setblock ~25~11~12 minecraft:stonebrick 1
setblock ~25~17~12 minecraft:redstone_wire 0
setblock ~25~70~12 minecraft:glowstone
setblock ~26~12~12 minecraft:stone 0
setblock ~26~17~12 minecraft:trapdoor 1
fill ~26~21~12 ~26~21~13 minecraft:stonebrick 1
fill ~26~42~12 ~26~42~13 minecraft:wooden_slab 9
setblock ~26~68~12 minecraft:nether_brick
setblock ~26~69~12 minecraft:nether_brick_stairs 1
setblock ~27~17~12 minecraft:soul_sand
setblock ~27~18~12 minecraft:nether_wart 3
setblock ~27~26~12 minecraft:stone_stairs 4
fill ~27~29~12 ~27~29~13 minecraft:stonebrick 0
setblock ~27~30~12 minecraft:stone_brick_stairs 5
fill ~27~31~12 ~27~31~13 minecraft:stonebrick 0
fill ~27~32~12 ~27~33~12 minecraft:stonebrick 0
setblock ~27~61~12 minecraft:planks 1
setblock ~27~62~12 minecraft:stone_brick_stairs 4
setblock ~27~63~12 minecraft:skull 1
setblock ~27~65~12 minecraft:web
fill ~27~66~12 ~27~66~13 minecraft:nether_brick
setblock ~27~67~12 minecraft:nether_brick_stairs 3
setblock ~28~17~12 minecraft:stonebrick 0
setblock ~28~18~12 minecraft:cobblestone
setblock ~28~19~12 minecraft:stonebrick 0
setblock ~28~26~12 minecraft:stone_stairs 5
setblock ~28~27~12 minecraft:cobblestone_wall 0
setblock ~28~28~12 minecraft:nether_brick_fence
setblock ~28~29~12 minecraft:nether_brick_stairs 3
setblock ~28~33~12 minecraft:stone_brick_stairs 5
setblock ~28~40~12 minecraft:nether_brick_stairs 4
setblock ~28~41~12 minecraft:double_stone_block_slab 7
setblock ~28~42~12 minecraft:nether_brick_stairs 0
setblock ~28~51~12 minecraft:wooden_slab 9
setblock ~28~58~12 minecraft:stonebrick 0
setblock ~28~59~12 minecraft:stonebrick 3
setblock ~28~60~12 minecraft:stone_brick_stairs 2
setblock ~28~61~12 minecraft:nether_brick_stairs 5
setblock ~28~62~12 minecraft:stone_brick_stairs 7
fill ~28~63~12 ~28~65~12 minecraft:stonebrick 0
setblock ~28~66~12 minecraft:nether_brick_stairs 3
fill ~29~23~12 ~29~24~13 minecraft:stone 0
setblock ~29~26~12 minecraft:tallgrass 0
setblock ~29~34~12 minecraft:nether_brick_stairs 7
setblock ~29~37~12 minecraft:iron_bars
setblock ~29~40~12 minecraft:stone_brick_stairs 3
fill ~29~43~12 ~29~45~12 minecraft:double_stone_block_slab 7
setblock ~29~46~12 minecraft:nether_brick_stairs 2
setblock ~29~47~12 minecraft:stone_brick_stairs 6
setblock ~29~48~12 minecraft:stone_brick_stairs 1
setblock ~29~50~12 minecraft:stone_block_slab 13
setblock ~29~51~12 minecraft:stone_brick_stairs 1
setblock ~29~52~12 minecraft:stonebrick 0
setblock ~29~53~12 minecraft:stone 6
fill ~29~54~12 ~29~57~12 minecraft:stonebrick 0
setblock ~29~58~12 minecraft:stone_brick_stairs 3
setblock ~30~35~12 minecraft:stone_stairs 5
setblock ~30~39~12 minecraft:nether_brick_stairs 6
setblock ~30~40~12 minecraft:nether_brick_stairs 3
setblock ~30~44~12 minecraft:nether_brick_stairs 5
setblock ~30~45~12 minecraft:double_stone_block_slab 7
setblock ~30~57~12 minecraft:nether_brick_stairs 6
setblock ~30~58~12 minecraft:nether_brick_stairs 3
setblock ~31~45~12 minecraft:nether_brick_stairs 5
fill ~32~22~12 ~32~24~12 minecraft:leaves 0
fill ~32~45~12 ~33~45~12 minecraft:stone_block_slab 15
fill ~33~46~12 ~36~46~12 minecraft:stone_block_slab 7
setblock ~37~49~12 minecraft:stained_glass 1
fill ~37~50~12 ~38~50~12 minecraft:stained_glass 12
setblock ~38~49~12 minecraft:stained_glass 12
setblock ~38~51~12 minecraft:stained_glass 12
setblock ~38~53~12 minecraft:stained_glass_pane 14
setblock ~39~41~12 minecraft:stained_glass_pane 4
setblock ~39~42~12 minecraft:stained_glass_pane 12
setblock ~39~43~12 minecraft:stained_glass 14
fill ~39~44~12 ~40~44~12 minecraft:stained_glass 1
setblock ~39~45~12 minecraft:stained_glass 1
fill ~39~46~12 ~39~49~12 minecraft:stained_glass 14
setblock ~39~51~12 minecraft:stained_glass 1
setblock ~39~52~12 minecraft:stained_glass 12
fill ~39~53~12 ~40~53~12 minecraft:stained_glass 1
setblock ~39~54~12 minecraft:stained_glass 12
setblock ~39~55~12 minecraft:stained_glass_pane 1
setblock ~40~40~12 minecraft:stained_glass_pane 14
setblock ~40~42~12 minecraft:stained_glass 14
setblock ~40~43~12 minecraft:stained_glass 12
setblock ~40~45~12 minecraft:stained_glass 14
fill ~40~47~12 ~40~49~13 minecraft:stained_glass 14
fill ~40~51~12 ~40~51~13 minecraft:stained_glass 14
setblock ~40~52~12 minecraft:stained_glass 1
setblock ~40~54~12 minecraft:stained_glass 14
setblock ~40~55~12 minecraft:stained_glass 1
setblock ~40~56~12 minecraft:stained_glass_pane 14
setblock ~41~43~12 minecraft:stained_glass_pane 1
fill ~41~44~12 ~41~45~12 minecraft:stained_glass 12
fill ~41~47~12 ~42~47~12 minecraft:stained_glass 12
fill ~41~48~12 ~41~48~13 minecraft:stained_glass 12
fill ~41~49~12 ~41~49~13 minecraft:stained_glass 14
setblock ~41~52~12 minecraft:stained_glass 14
setblock ~41~53~12 minecraft:stained_glass 12
setblock ~41~54~12 minecraft:stained_glass 1
setblock ~42~45~12 minecraft:stained_glass_pane 1
setblock ~42~49~12 minecraft:stained_glass 12
setblock ~42~51~12 minecraft:stained_glass 1
setblock ~42~53~12 minecraft:stained_glass_pane 1
setblock ~43~49~12 minecraft:stained_glass 14
setblock ~43~51~12 minecraft:stained_glass_pane 14
fill ~44~46~12 ~44~46~14 minecraft:stone_block_slab 7
setblock ~4~39~13 minecraft:grass
setblock ~5~36~13 minecraft:leaves 0
setblock ~5~39~13 minecraft:dirt 0
fill ~6~35~13 ~7~35~13 minecraft:stone 0
fill ~6~36~13 ~6~38~13 minecraft:stone 0
setblock ~6~41~13 minecraft:cobblestone_wall 0
setblock ~6~45~13 minecraft:stone_block_slab 7
setblock ~6~46~13 minecraft:stone_block_slab 13
setblock ~6~47~13 minecraft:stone_block_slab 5
setblock ~6~53~13 minecraft:stone_block_slab 11
fill ~6~54~13 ~6~55~13 minecraft:cobblestone_wall 0
setblock ~6~56~13 minecraft:stone_block_slab 3
setblock ~6~57~13 minecraft:nether_brick_stairs 7
setblock ~6~58~13 minecraft:stonebrick 0
setblock ~6~59~13 minecraft:stone_brick_stairs 3
setblock ~6~63~13 minecraft:nether_brick_stairs 0
setblock ~7~34~13 minecraft:stone 0
setblock ~7~36~13 minecraft:brewing_stand 0
fill ~7~39~13 ~7~39~14 minecraft:stone 0
setblock ~7~40~13 minecraft:dirt 0
setblock ~7~41~13 minecraft:stonebrick 0
setblock ~7~42~13 minecraft:stone_block_slab 5
setblock ~7~43~13 minecraft:stone_block_slab 13
setblock ~7~44~13 minecraft:cobblestone_wall 0
setblock ~7~45~13 minecraft:stonebrick 0
fill ~7~46~13 ~7~47~13 minecraft:cobblestone_wall 0
setblock ~7~48~13 minecraft:cobblestone_wall 0
setblock ~7~49~13 minecraft:glowstone
setblock ~7~50~13 minecraft:cobblestone_wall 0
fill ~7~51~13 ~7~63~13 minecraft:nether_brick
setblock ~7~64~13 minecraft:stone_block_slab 7
setblock ~8~34~13 minecraft:wooden_slab 9
fill ~8~41~13 ~10~41~13 minecraft:bookshelf
setblock ~8~59~13 minecraft:nether_brick_stairs 5
setblock ~8~61~13 minecraft:stone_brick_stairs 5
setblock ~8~62~13 minecraft:stone_brick_stairs 0
setblock ~8~64~13 minecraft:nether_brick
setblock ~8~65~13 minecraft:nether_brick_stairs 3
fill ~9~31~13 ~9~32~13 minecraft:stone 0
setblock ~9~50~13 minecraft:stone_brick_stairs 7
setblock ~9~51~13 minecraft:stone_brick_stairs 2
setblock ~9~59~13 minecraft:enchanting_table
setblock ~9~62~13 minecraft:stone_brick_stairs 7
fill ~9~65~13 ~9~66~13 minecraft:nether_brick
setblock ~9~67~13 minecraft:nether_brick_stairs 3
setblock ~10~35~13 minecraft:redstone_wire 0
setblock ~10~59~13 minecraft:nether_brick_stairs 4
setblock ~10~61~13 minecraft:stone_brick_stairs 4
setblock ~10~62~13 minecraft:stone_brick_stairs 1
setblock ~10~64~13 minecraft:nether_brick
setblock ~10~65~13 minecraft:nether_brick_stairs 3
setblock ~11~32~13 minecraft:trapdoor 2
setblock ~11~33~13 minecraft:glowstone
fill ~11~34~13 ~11~35~13 minecraft:stone 0
setblock ~11~37~13 minecraft:cobblestone_wall 0
setblock ~11~38~13 minecraft:redstone_torch 5
fill ~11~39~13 ~11~39~14 minecraft:stone 0
setblock ~11~40~13 minecraft:dirt 0
setblock ~11~41~13 minecraft:stonebrick 0
setblock ~11~42~13 minecraft:stone_block_slab 5
setblock ~11~43~13 minecraft:stone_block_slab 13
setblock ~11~44~13 minecraft:cobblestone_wall 0
setblock ~11~45~13 minecraft:stonebrick 0
fill ~11~46~13 ~11~47~13 minecraft:cobblestone_wall 0
setblock ~11~48~13 minecraft:cobblestone_wall 0
setblock ~11~49~13 minecraft:glowstone
setblock ~11~50~13 minecraft:cobblestone_wall 0
fill ~11~51~13 ~11~63~13 minecraft:nether_brick
setblock ~11~64~13 minecraft:stone_block_slab 7
setblock ~12~33~13 minecraft:trapdoor 0
fill ~12~35~13 ~12~37~13 minecraft:stone 0
setblock ~12~41~13 minecraft:cobblestone_wall 0
setblock ~12~45~13 minecraft:stone_block_slab 7
setblock ~12~46~13 minecraft:stone_block_slab 13
setblock ~12~47~13 minecraft:stone_block_slab 5
setblock ~12~53~13 minecraft:stone_block_slab 11
fill ~12~54~13 ~12~55~13 minecraft:cobblestone_wall 0
setblock ~12~56~13 minecraft:stone_block_slab 3
setblock ~12~57~13 minecraft:nether_brick_stairs 7
setblock ~12~58~13 minecraft:stonebrick 0
setblock ~12~59~13 minecraft:stone_brick_stairs 3
fill ~13~35~13 ~13~36~13 minecraft:leaves 0
setblock ~13~37~13 minecraft:stone 0
fill ~13~38~13 ~13~39~13 minecraft:dirt 0
setblock ~14~39~13 minecraft:grass
setblock ~14~40~13 minecraft:double_plant 3
setblock ~18~24~13 minecraft:grass
setblock ~18~52~13 minecraft:nether_brick_stairs 7
setblock ~18~55~13 minecraft:stone_block_slab 15
setblock ~18~56~13 minecraft:cobblestone_wall 0
fill ~18~57~13 ~19~57~13 minecraft:nether_brick_stairs 3
setblock ~19~23~13 minecraft:dirt 0
setblock ~19~24~13 minecraft:stone 0
setblock ~19~26~13 minecraft:double_plant 3
fill ~19~34~13 ~19~34~14 minecraft:nether_brick_stairs 4
fill ~19~35~13 ~19~38~13 minecraft:stonebrick 0
setblock ~19~39~13 minecraft:nether_brick_stairs 3
setblock ~19~43~13 minecraft:nether_brick_stairs 7
setblock ~19~44~13 minecraft:stone_stairs 4
setblock ~19~49~13 minecraft:stone_brick_stairs 7
fill ~19~52~13 ~19~52~14 minecraft:nether_brick_stairs 4
setblock ~19~53~13 minecraft:nether_brick_stairs 4
fill ~20~25~13 ~21~25~13 minecraft:dirt 0
setblock ~20~26~13 minecraft:stone_brick_stairs 0
setblock ~20~28~13 minecraft:stone_block_slab 15
setblock ~20~31~13 minecraft:nether_brick_stairs 4
setblock ~20~32~13 minecraft:nether_brick
setblock ~20~39~13 minecraft:stonebrick 0
setblock ~20~41~13 minecraft:stonebrick 3
fill ~20~44~13 ~20~51~13 minecraft:nether_brick
fill ~20~53~13 ~20~60~13 minecraft:nether_brick
setblock ~20~61~13 minecraft:nether_brick_stairs 0
setblock ~20~64~13 minecraft:stone_brick_stairs 4
setblock ~20~65~13 minecraft:cobblestone_wall 0
fill ~21~18~13 ~21~19~13 minecraft:stone 0
setblock ~21~20~13 minecraft:web
setblock ~21~26~13 minecraft:stone 6
fill ~21~27~13 ~21~28~13 minecraft:stonebrick 0
setblock ~21~30~13 minecraft:stonebrick 0
setblock ~21~32~13 minecraft:double_stone_block_slab 5
setblock ~21~33~13 minecraft:stone_block_slab 13
fill ~21~42~13 ~21~42~14 minecraft:double_wooden_slab 1
fill ~21~51~13 ~22~51~13 minecraft:wooden_slab 9
fill ~21~59~13 ~21~61~13 minecraft:nether_brick
fill ~21~62~13 ~21~65~13 minecraft:stonebrick 0
setblock ~21~67~13 minecraft:nether_brick_stairs 0
setblock ~22~15~13 minecraft:cobblestone
fill ~22~16~13 ~22~17~13 minecraft:stone 0
setblock ~22~18~13 minecraft:flower_pot 0
setblock ~22~25~13 minecraft:nether_brick
setblock ~22~29~13 minecraft:cobblestone_wall 0
setblock ~22~30~13 minecraft:redstone_torch 5
setblock ~22~67~13 minecraft:nether_brick
setblock ~22~68~13 minecraft:stone_block_slab 7
setblock ~23~13~13 minecraft:stone 0
setblock ~23~17~13 minecraft:anvil 1
fill ~23~42~13 ~23~42~14 minecraft:wooden_slab 9
setblock ~23~68~13 minecraft:nether_brick
setblock ~23~69~13 minecraft:nether_brick_stairs 3
setblock ~24~8~13 minecraft:cobblestone_wall 0
fill ~24~9~13 ~24~10~13 minecraft:stone 0
setblock ~24~11~13 minecraft:cobblestone
setblock ~24~12~13 minecraft:stone 0
setblock ~24~16~13 minecraft:stonebrick 1
setblock ~24~68~13 minecraft:web
fill ~24~69~13 ~24~69~14 minecraft:nether_brick
fill ~24~71~13 ~24~72~13 minecraft:nether_brick
setblock ~24~73~13 minecraft:nether_brick_stairs 3
setblock ~25~16~13 minecraft:stonebrick 2
setblock ~25~17~13 minecraft:web
fill ~25~42~13 ~25~42~14 minecraft:wooden_slab 9
setblock ~25~68~13 minecraft:nether_brick
setblock ~25~69~13 minecraft:nether_brick_stairs 3
setblock ~26~14~13 minecraft:cobblestone
fill ~26~15~13 ~26~16~13 minecraft:stone 0
setblock ~26~17~13 minecraft:nether_brick
setblock ~26~25~13 minecraft:nether_brick
setblock ~26~29~13 minecraft:cobblestone_wall 0
setblock ~26~30~13 minecraft:redstone_torch 5
fill ~26~51~13 ~27~51~13 minecraft:wooden_slab 9
setblock ~26~62~13 minecraft:chest 4
setblock ~26~67~13 minecraft:nether_brick
setblock ~26~68~13 minecraft:stone_block_slab 7
fill ~27~17~13 ~27~18~13 minecraft:stone 0
fill ~27~19~13 ~27~20~13 minecraft:web
fill ~27~25~13 ~28~25~13 minecraft:dirt 0
setblock ~27~26~13 minecraft:stone 6
fill ~27~27~13 ~27~28~13 minecraft:stonebrick 0
setblock ~27~30~13 minecraft:stonebrick 0
setblock ~27~32~13 minecraft:double_stone_block_slab 5
setblock ~27~33~13 minecraft:stone_block_slab 13
fill ~27~42~13 ~27~42~14 minecraft:double_wooden_slab 1
fill ~27~59~13 ~28~60~13 minecraft:nether_brick
setblock ~27~61~13 minecraft:nether_brick
fill ~27~62~13 ~27~65~13 minecraft:stonebrick 0
setblock ~27~67~13 minecraft:nether_brick_stairs 1
setblock ~28~19~13 minecraft:stone 0
setblock ~28~26~13 minecraft:stone_brick_stairs 1
setblock ~28~28~13 minecraft:stone_block_slab 15
setblock ~28~31~13 minecraft:nether_brick_stairs 5
fill ~28~32~13 ~28~33~13 minecraft:nether_brick
fill ~28~39~13 ~28~40~13 minecraft:stonebrick 0
setblock ~28~41~13 minecraft:stonebrick 3
setblock ~28~42~13 minecraft:stonebrick 0
fill ~28~44~13 ~28~51~13 minecraft:nether_brick
fill ~28~53~13 ~28~58~13 minecraft:nether_brick
setblock ~28~61~13 minecraft:nether_brick_stairs 1
setblock ~28~64~13 minecraft:stone_brick_stairs 5
setblock ~28~65~13 minecraft:cobblestone_wall 0
fill ~28~66~13 ~28~66~14 minecraft:nether_brick_stairs 1
setblock ~29~16~13 minecraft:leaves 0
setblock ~29~17~13 minecraft:leaves 0
setblock ~29~18~13 minecraft:leaves 0
setblock ~29~22~13 minecraft:stone 0
setblock ~29~34~13 minecraft:nether_brick_stairs 5
fill ~29~35~13 ~29~38~13 minecraft:stonebrick 0
fill ~29~39~13 ~30~39~13 minecraft:nether_brick_stairs 3
fill ~29~43~13 ~29~43~14 minecraft:nether_brick_stairs 5
setblock ~29~44~13 minecraft:stone_stairs 5
setblock ~29~52~13 minecraft:nether_brick_stairs 7
setblock ~29~53~13 minecraft:nether_brick_stairs 5
fill ~29~57~13 ~30~57~13 minecraft:nether_brick_stairs 3
setblock ~30~24~13 minecraft:grass
setblock ~30~25~13 minecraft:double_plant 3
setblock ~30~35~13 minecraft:nether_brick_stairs 7
setblock ~30~37~13 minecraft:nether_brick_stairs 5
setblock ~30~38~13 minecraft:cobblestone_wall 0
setblock ~30~55~13 minecraft:stone_block_slab 15
setblock ~30~56~13 minecraft:cobblestone_wall 0
setblock ~36~46~13 minecraft:stone_block_slab 7
setblock ~37~50~13 minecraft:stained_glass_pane 1
fill ~38~49~13 ~38~50~13 minecraft:stained_glass 1
fill ~39~46~13 ~40~46~13 minecraft:stained_glass 12
setblock ~39~47~13 minecraft:stained_glass 12
fill ~39~48~13 ~39~52~13 minecraft:stained_glass 14
setblock ~39~53~13 minecraft:stained_glass_pane 4
setblock ~40~43~13 minecraft:stained_glass_pane 1
setblock ~40~44~13 minecraft:stained_glass 14
setblock ~40~45~13 minecraft:stained_glass 12
fill ~40~50~13 ~41~50~13 minecraft:stained_glass 1
fill ~40~52~13 ~40~53~13 minecraft:stained_glass 14
setblock ~40~54~13 minecraft:stained_glass_pane 12
setblock ~41~46~13 minecraft:stained_glass_pane 12
setblock ~41~47~13 minecraft:stained_glass 14
setblock ~41~51~13 minecraft:stained_glass 1
setblock ~41~52~13 minecraft:stained_glass 12
setblock ~41~53~13 minecraft:stained_glass_pane 12
setblock ~42~49~13 minecraft:stained_glass 14
setblock ~42~50~13 minecraft:stained_glass 12
fill ~42~51~13 ~42~52~13 minecraft:stained_glass_pane 1
fill ~5~37~14 ~5~38~14 minecraft:leaves 0
setblock ~5~39~14 minecraft:grass
setblock ~6~35~14 minecraft:trapdoor 1
fill ~6~37~14 ~6~39~14 minecraft:dirt 0
setblock ~6~40~14 minecraft:grass
setblock ~6~41~14 minecraft:web
fill ~6~63~14 ~8~63~14 minecraft:nether_brick_stairs 3
setblock ~7~34~14 minecraft:trapdoor 2
setblock ~7~35~14 minecraft:glowstone
fill ~7~36~14 ~8~36~14 minecraft:stone 0
fill ~7~37~14 ~7~38~14 minecraft:stone 0
fill ~7~40~14 ~8~40~14 minecraft:nether_brick
setblock ~7~41~14 minecraft:cobblestone_wall 0
setblock ~7~45~14 minecraft:stone_block_slab 7
setblock ~7~46~14 minecraft:stone_block_slab 13
setblock ~7~47~14 minecraft:stone_block_slab 5
setblock ~7~53~14 minecraft:stone_block_slab 11
fill ~7~54~14 ~7~55~14 minecraft:cobblestone_wall 0
setblock ~7~56~14 minecraft:stone_block_slab 3
setblock ~7~57~14 minecraft:nether_brick_stairs 4
setblock ~7~58~14 minecraft:stonebrick 0
setblock ~7~59~14 minecraft:stone_brick_stairs 0
fill ~8~34~14 ~10~34~14 minecraft:stone 0
setblock ~8~35~14 minecraft:stone 0
fill ~8~37~14 ~9~37~14 minecraft:stone_block_slab 15
setblock ~8~38~14 minecraft:skull 1
fill ~8~39~14 ~10~39~15 minecraft:stone 0
setblock ~8~41~14 minecraft:nether_brick_stairs 7
fill ~8~42~14 ~8~44~14 minecraft:stonebrick 0
setblock ~8~45~14 minecraft:stone 6
setblock ~8~46~14 minecraft:stonebrick 0
setblock ~8~47~14 minecraft:nether_brick
setblock ~8~48~14 minecraft:nether_brick_stairs 2
setblock ~8~50~14 minecraft:nether_brick_stairs 6
setblock ~8~51~14 minecraft:stone_block_slab 7
setblock ~8~52~14 minecraft:stone_brick_stairs 4
setblock ~8~53~14 minecraft:stone_stairs 7
fill ~8~54~14 ~8~55~14 minecraft:stonebrick 0
setblock ~8~56~14 minecraft:stone_stairs 3
setblock ~8~57~14 minecraft:stone_stairs 7
setblock ~8~58~14 minecraft:stone_brick_stairs 3
fill ~8~59~14 ~10~59~14 minecraft:cobblestone_wall 0
setblock ~9~33~14 minecraft:cobblestone
setblock ~9~35~14 minecraft:enchanting_table
setblock ~9~40~14 minecraft:dirt 0
setblock ~9~41~14 minecraft:stone_stairs 3
fill ~9~42~14 ~9~43~14 minecraft:iron_bars
setblock ~9~44~14 minecraft:stone_stairs 7
setblock ~9~45~14 minecraft:stone_stairs 2
setblock ~9~51~14 minecraft:stone_brick_stairs 7
setblock ~9~52~14 minecraft:stonebrick 0
setblock ~9~53~14 minecraft:stone_stairs 3
setblock ~9~56~14 minecraft:stone_stairs 7
setblock ~9~57~14 minecraft:stone_stairs 3
setblock ~9~58~14 minecraft:stone_brick_stairs 7
fill ~9~63~14 ~9~64~14 minecraft:nether_brick
setblock ~9~65~14 minecraft:nether_brick_stairs 3
fill ~10~35~14 ~11~35~14 minecraft:stone 0
setblock ~10~38~14 minecraft:web
fill ~10~40~14 ~11~40~14 minecraft:nether_brick
setblock ~10~41~14 minecraft:nether_brick_stairs 7
fill ~10~42~14 ~10~44~14 minecraft:stonebrick 0
setblock ~10~45~14 minecraft:stone 6
setblock ~10~46~14 minecraft:stonebrick 0
setblock ~10~47~14 minecraft:nether_brick
setblock ~10~48~14 minecraft:nether_brick_stairs 2
setblock ~10~50~14 minecraft:nether_brick_stairs 6
setblock ~10~51~14 minecraft:stone_block_slab 7
setblock ~10~52~14 minecraft:stone_brick_stairs 5
setblock ~10~53~14 minecraft:stone_stairs 7
fill ~10~54~14 ~10~55~14 minecraft:stonebrick 0
setblock ~10~56~14 minecraft:stone_stairs 3
setblock ~10~57~14 minecraft:stone_stairs 7
setblock ~10~58~14 minecraft:stone_brick_stairs 3
setblock ~10~63~14 minecraft:nether_brick_stairs 1
setblock ~11~33~14 minecraft:trapdoor 2
fill ~11~36~14 ~11~38~14 minecraft:stone 0
setblock ~11~41~14 minecraft:cobblestone_wall 0
setblock ~11~45~14 minecraft:stone_block_slab 7
setblock ~11~46~14 minecraft:stone_block_slab 13
setblock ~11~47~14 minecraft:stone_block_slab 5
setblock ~11~53~14 minecraft:stone_block_slab 11
fill ~11~54~14 ~11~55~14 minecraft:cobblestone_wall 0
setblock ~11~56~14 minecraft:stone_block_slab 3
setblock ~11~57~14 minecraft:nether_brick_stairs 5
setblock ~11~58~14 minecraft:stonebrick 0
setblock ~11~59~14 minecraft:stone_brick_stairs 1
fill ~11~63~14 ~12~63~14 minecraft:nether_brick_stairs 3
setblock ~12~39~14 minecraft:dirt 0
setblock ~12~40~14 minecraft:grass
setblock ~12~41~14 minecraft:tallgrass 0
setblock ~13~34~14 minecraft:leaves 0
