fill ~0 ~0 ~4 ~5 ~0 ~4 coal_block 0  
fill ~0 ~0 ~5 ~5 ~0 ~5 coal_block 0  
fill ~0 ~0 ~6 ~5 ~0 ~6 coal_block 0  
fill ~0 ~0 ~7 ~5 ~0 ~7 coal_block 0  
fill ~0 ~0 ~8 ~5 ~0 ~8 coal_block 0  
fill ~0 ~0 ~9 ~5 ~0 ~9 coal_block 0  
fill ~0 ~0 ~10 ~5 ~0 ~10 coal_block 0  
fill ~0 ~0 ~11 ~5 ~0 ~11 coal_block 0  
fill ~22 ~0 ~12 ~23 ~0 ~12 coal_block 0  
fill ~22 ~0 ~13 ~23 ~0 ~13 coal_block 0  
fill ~22 ~0 ~14 ~23 ~0 ~14 coal_block 0  
fill ~22 ~0 ~15 ~23 ~0 ~15 coal_block 0  
fill ~22 ~0 ~16 ~23 ~0 ~16 coal_block 0  
fill ~22 ~0 ~17 ~23 ~0 ~17 coal_block 0  
fill ~22 ~0 ~18 ~23 ~0 ~18 coal_block 0  
fill ~22 ~0 ~19 ~23 ~0 ~19 coal_block 0 
setblock ~31 ~0 ~-5 wool 14  
fill ~-1 ~1 ~4 ~5 ~1 ~4 coal_block 0  
fill ~-1 ~1 ~5 ~5 ~1 ~5 coal_block 0  
fill ~-1 ~1 ~6 ~5 ~1 ~6 coal_block 0  
fill ~-1 ~1 ~7 ~5 ~1 ~7 coal_block 0  
fill ~-1 ~1 ~8 ~5 ~1 ~8 coal_block 0  
fill ~-1 ~1 ~9 ~5 ~1 ~9 coal_block 0  
fill ~-1 ~1 ~10 ~5 ~1 ~10 coal_block 0  
fill ~-1 ~1 ~11 ~5 ~1 ~11 coal_block 0  
fill ~21 ~1 ~12 ~24 ~1 ~12 coal_block 0  
fill ~21 ~1 ~13 ~24 ~1 ~13 coal_block 0  
fill ~21 ~1 ~14 ~24 ~1 ~14 coal_block 0  
fill ~21 ~1 ~15 ~24 ~1 ~15 coal_block 0  
fill ~21 ~1 ~16 ~24 ~1 ~16 coal_block 0  
fill ~21 ~1 ~17 ~24 ~1 ~17 coal_block 0  
fill ~21 ~1 ~18 ~24 ~1 ~18 coal_block 0  
fill ~21 ~1 ~19 ~24 ~1 ~19 coal_block 0  
fill ~-3 ~2 ~4 ~4 ~2 ~4 coal_block 0  
fill ~-3 ~2 ~5 ~4 ~2 ~5 coal_block 0  
fill ~-3 ~2 ~6 ~4 ~2 ~6 coal_block 0  
fill ~-3 ~2 ~7 ~4 ~2 ~7 coal_block 0  
fill ~-3 ~2 ~8 ~4 ~2 ~8 coal_block 0  
fill ~-3 ~2 ~9 ~4 ~2 ~9 coal_block 0  
fill ~-3 ~2 ~10 ~4 ~2 ~10 coal_block 0  
fill ~-3 ~2 ~11 ~4 ~2 ~11 coal_block 0  
fill ~21 ~2 ~12 ~25 ~2 ~12 coal_block 0  
fill ~21 ~2 ~13 ~25 ~2 ~13 coal_block 0  
fill ~21 ~2 ~14 ~25 ~2 ~14 coal_block 0  
fill ~21 ~2 ~16 ~25 ~2 ~16 coal_block 0  
fill ~21 ~2 ~17 ~25 ~2 ~17 coal_block 0  
fill ~21 ~2 ~18 ~25 ~2 ~18 coal_block 0  
fill ~21 ~2 ~19 ~25 ~2 ~19 coal_block 0  
fill ~22 ~2 ~15 ~25 ~2 ~15 coal_block 0  
fill ~-5 ~3 ~4 ~1 ~3 ~4 coal_block 0  
fill ~-5 ~3 ~5 ~1 ~3 ~5 coal_block 0  
fill ~-5 ~3 ~6 ~1 ~3 ~6 coal_block 0  
fill ~-5 ~3 ~7 ~1 ~3 ~7 coal_block 0  
fill ~-5 ~3 ~8 ~1 ~3 ~8 coal_block 0  
fill ~-5 ~3 ~9 ~1 ~3 ~9 coal_block 0  
fill ~-5 ~3 ~10 ~1 ~3 ~10 coal_block 0  
fill ~-5 ~3 ~11 ~1 ~3 ~11 coal_block 0  
fill ~20 ~3 ~12 ~26 ~3 ~12 coal_block 0  
fill ~20 ~3 ~13 ~26 ~3 ~13 coal_block 0  
fill ~20 ~3 ~14 ~26 ~3 ~14 coal_block 0  
fill ~20 ~3 ~15 ~26 ~3 ~15 coal_block 0  
fill ~20 ~3 ~16 ~26 ~3 ~16 coal_block 0  
fill ~20 ~3 ~17 ~26 ~3 ~17 coal_block 0  
fill ~20 ~3 ~18 ~26 ~3 ~18 coal_block 0  
fill ~20 ~3 ~19 ~26 ~3 ~19 coal_block 0  
fill ~-5 ~4 ~4 ~-1 ~4 ~4 coal_block 0  
fill ~-5 ~4 ~5 ~-1 ~4 ~5 coal_block 0  
fill ~-5 ~4 ~6 ~-1 ~4 ~6 coal_block 0  
fill ~-5 ~4 ~7 ~-1 ~4 ~7 coal_block 0  
fill ~-5 ~4 ~8 ~-1 ~4 ~8 coal_block 0  
fill ~-5 ~4 ~9 ~-1 ~4 ~9 coal_block 0  
fill ~-5 ~4 ~10 ~-1 ~4 ~10 coal_block 0  
fill ~-5 ~4 ~11 ~-1 ~4 ~11 coal_block 0  
fill ~0 ~4 ~4 ~1 ~4 ~4 lapis_block 0  
fill ~0 ~4 ~5 ~1 ~4 ~5 lapis_block 0  
fill ~0 ~4 ~6 ~1 ~4 ~6 lapis_block 0  
fill ~0 ~4 ~7 ~1 ~4 ~7 lapis_block 0  
fill ~0 ~4 ~8 ~1 ~4 ~8 lapis_block 0  
fill ~0 ~4 ~9 ~1 ~4 ~9 lapis_block 0  
fill ~0 ~4 ~10 ~1 ~4 ~10 lapis_block 0  
fill ~0 ~4 ~11 ~1 ~4 ~11 lapis_block 0  
fill ~18 ~4 ~12 ~20 ~4 ~12 lapis_block 0  
fill ~18 ~4 ~13 ~20 ~4 ~13 lapis_block 0  
fill ~18 ~4 ~14 ~20 ~4 ~14 lapis_block 0  
fill ~18 ~4 ~15 ~20 ~4 ~15 lapis_block 0  
fill ~18 ~4 ~16 ~20 ~4 ~16 lapis_block 0  
fill ~18 ~4 ~17 ~20 ~4 ~17 lapis_block 0  
fill ~18 ~4 ~18 ~20 ~4 ~18 lapis_block 0  
fill ~18 ~4 ~19 ~20 ~4 ~19 lapis_block 0  
fill ~21 ~4 ~12 ~27 ~4 ~12 coal_block 0  
fill ~21 ~4 ~13 ~27 ~4 ~13 coal_block 0  
fill ~21 ~4 ~14 ~27 ~4 ~14 coal_block 0  
fill ~21 ~4 ~15 ~27 ~4 ~15 coal_block 0  
fill ~21 ~4 ~16 ~27 ~4 ~16 coal_block 0  
fill ~21 ~4 ~17 ~27 ~4 ~17 coal_block 0  
fill ~21 ~4 ~18 ~27 ~4 ~18 coal_block 0  
fill ~21 ~4 ~19 ~27 ~4 ~19 coal_block 0  
fill ~-4 ~5 ~4 ~-3 ~5 ~4 coal_block 0  
fill ~-4 ~5 ~5 ~-3 ~5 ~5 coal_block 0  
fill ~-4 ~5 ~6 ~-3 ~5 ~6 coal_block 0  
fill ~-4 ~5 ~7 ~-3 ~5 ~7 coal_block 0  
fill ~-4 ~5 ~8 ~-3 ~5 ~8 coal_block 0  
fill ~-4 ~5 ~9 ~-3 ~5 ~9 coal_block 0  
fill ~-4 ~5 ~10 ~-3 ~5 ~10 coal_block 0  
fill ~-4 ~5 ~11 ~-3 ~5 ~11 coal_block 0  
fill ~-2 ~5 ~4 ~1 ~5 ~4 lapis_block 0  
fill ~-2 ~5 ~5 ~1 ~5 ~5 lapis_block 0  
fill ~-2 ~5 ~6 ~1 ~5 ~6 lapis_block 0  
fill ~-2 ~5 ~7 ~1 ~5 ~7 lapis_block 0  
fill ~-2 ~5 ~8 ~1 ~5 ~8 lapis_block 0  
fill ~-2 ~5 ~9 ~1 ~5 ~9 lapis_block 0  
fill ~-2 ~5 ~10 ~1 ~5 ~10 lapis_block 0  
fill ~-2 ~5 ~11 ~1 ~5 ~11 lapis_block 0  
fill ~18 ~5 ~12 ~22 ~5 ~12 lapis_block 0  
fill ~18 ~5 ~13 ~22 ~5 ~13 lapis_block 0  
fill ~18 ~5 ~14 ~22 ~5 ~14 lapis_block 0  
fill ~18 ~5 ~15 ~22 ~5 ~15 lapis_block 0  
fill ~18 ~5 ~16 ~22 ~5 ~16 lapis_block 0  
fill ~18 ~5 ~17 ~22 ~5 ~17 lapis_block 0  
fill ~18 ~5 ~18 ~22 ~5 ~18 lapis_block 0  
fill ~18 ~5 ~19 ~22 ~5 ~19 lapis_block 0  
fill ~23 ~5 ~12 ~28 ~5 ~12 coal_block 0  
fill ~23 ~5 ~13 ~28 ~5 ~13 coal_block 0  
fill ~23 ~5 ~14 ~28 ~5 ~14 coal_block 0  
fill ~23 ~5 ~15 ~28 ~5 ~15 coal_block 0  
fill ~23 ~5 ~16 ~28 ~5 ~16 coal_block 0  
fill ~23 ~5 ~17 ~28 ~5 ~17 coal_block 0  
fill ~23 ~5 ~18 ~28 ~5 ~18 coal_block 0  
fill ~23 ~5 ~19 ~28 ~5 ~19 coal_block 0  
fill ~-3 ~6 ~4 ~2 ~6 ~4 lapis_block 0  
fill ~-3 ~6 ~5 ~2 ~6 ~5 lapis_block 0  
fill ~-3 ~6 ~6 ~2 ~6 ~6 lapis_block 0  
fill ~-3 ~6 ~7 ~2 ~6 ~7 lapis_block 0  
fill ~-3 ~6 ~8 ~2 ~6 ~8 lapis_block 0  
fill ~-3 ~6 ~9 ~2 ~6 ~9 lapis_block 0  
fill ~-3 ~6 ~10 ~2 ~6 ~10 lapis_block 0  
fill ~-3 ~6 ~11 ~2 ~6 ~11 lapis_block 0  
fill ~17 ~6 ~12 ~23 ~6 ~12 lapis_block 0  
fill ~17 ~6 ~13 ~23 ~6 ~13 lapis_block 0  
fill ~17 ~6 ~14 ~23 ~6 ~14 lapis_block 0  
fill ~17 ~6 ~15 ~23 ~6 ~15 lapis_block 0  
fill ~17 ~6 ~16 ~23 ~6 ~16 lapis_block 0  
fill ~17 ~6 ~17 ~23 ~6 ~17 lapis_block 0  
fill ~17 ~6 ~18 ~23 ~6 ~18 lapis_block 0  
fill ~17 ~6 ~19 ~23 ~6 ~19 lapis_block 0  
fill ~24 ~6 ~12 ~29 ~6 ~12 coal_block 0  
fill ~24 ~6 ~13 ~29 ~6 ~13 coal_block 0  
fill ~24 ~6 ~14 ~29 ~6 ~14 coal_block 0  
fill ~24 ~6 ~15 ~29 ~6 ~15 coal_block 0  
fill ~24 ~6 ~16 ~29 ~6 ~16 coal_block 0  
fill ~24 ~6 ~17 ~29 ~6 ~17 coal_block 0  
fill ~24 ~6 ~18 ~29 ~6 ~18 coal_block 0  
fill ~24 ~6 ~19 ~29 ~6 ~19 coal_block 0  
fill ~-4 ~7 ~4 ~3 ~7 ~4 lapis_block 0  
fill ~-4 ~7 ~5 ~3 ~7 ~5 lapis_block 0  
fill ~-4 ~7 ~6 ~3 ~7 ~6 lapis_block 0  
fill ~-4 ~7 ~7 ~3 ~7 ~7 lapis_block 0  
fill ~-4 ~7 ~8 ~3 ~7 ~8 lapis_block 0  
fill ~-4 ~7 ~9 ~3 ~7 ~9 lapis_block 0  
fill ~-4 ~7 ~10 ~3 ~7 ~10 lapis_block 0  
fill ~-4 ~7 ~11 ~3 ~7 ~11 lapis_block 0  
fill ~17 ~7 ~12 ~24 ~7 ~12 lapis_block 0  
fill ~17 ~7 ~13 ~24 ~7 ~13 lapis_block 0  
fill ~17 ~7 ~14 ~24 ~7 ~14 lapis_block 0  
fill ~17 ~7 ~15 ~24 ~7 ~15 lapis_block 0  
fill ~17 ~7 ~16 ~24 ~7 ~16 lapis_block 0  
fill ~17 ~7 ~17 ~24 ~7 ~17 lapis_block 0  
fill ~17 ~7 ~18 ~24 ~7 ~18 lapis_block 0  
fill ~17 ~7 ~19 ~24 ~7 ~19 lapis_block 0  
fill ~26 ~7 ~12 ~29 ~7 ~12 coal_block 0  
fill ~26 ~7 ~13 ~29 ~7 ~13 coal_block 0  
fill ~26 ~7 ~14 ~29 ~7 ~14 coal_block 0  
fill ~26 ~7 ~15 ~29 ~7 ~15 coal_block 0  
fill ~26 ~7 ~16 ~29 ~7 ~16 coal_block 0  
fill ~26 ~7 ~17 ~29 ~7 ~17 coal_block 0  
fill ~26 ~7 ~18 ~29 ~7 ~18 coal_block 0  
fill ~26 ~7 ~19 ~29 ~7 ~19 coal_block 0  
fill ~-5 ~8 ~4 ~3 ~8 ~4 lapis_block 0  
fill ~-5 ~8 ~5 ~3 ~8 ~5 lapis_block 0  
fill ~-5 ~8 ~6 ~3 ~8 ~6 lapis_block 0  
fill ~-5 ~8 ~7 ~3 ~8 ~7 lapis_block 0  
fill ~-5 ~8 ~8 ~3 ~8 ~8 lapis_block 0  
fill ~-5 ~8 ~9 ~3 ~8 ~9 lapis_block 0  
fill ~-5 ~8 ~10 ~3 ~8 ~10 lapis_block 0  
fill ~-5 ~8 ~11 ~3 ~8 ~11 lapis_block 0  
fill ~16 ~8 ~12 ~25 ~8 ~12 lapis_block 0  
fill ~16 ~8 ~13 ~25 ~8 ~13 lapis_block 0  
fill ~16 ~8 ~14 ~25 ~8 ~14 lapis_block 0  
fill ~16 ~8 ~15 ~25 ~8 ~15 lapis_block 0  
fill ~16 ~8 ~16 ~25 ~8 ~16 lapis_block 0  
fill ~16 ~8 ~17 ~25 ~8 ~17 lapis_block 0  
fill ~16 ~8 ~18 ~25 ~8 ~18 lapis_block 0  
fill ~16 ~8 ~19 ~25 ~8 ~19 lapis_block 0  
fill ~28 ~8 ~12 ~30 ~8 ~12 coal_block 0  
fill ~28 ~8 ~13 ~30 ~8 ~13 coal_block 0  
fill ~28 ~8 ~14 ~30 ~8 ~14 coal_block 0  
fill ~28 ~8 ~15 ~30 ~8 ~15 coal_block 0  
fill ~28 ~8 ~16 ~30 ~8 ~16 coal_block 0  
fill ~28 ~8 ~17 ~30 ~8 ~17 coal_block 0  
fill ~28 ~8 ~18 ~30 ~8 ~18 coal_block 0  
fill ~28 ~8 ~19 ~30 ~8 ~19 coal_block 0  
fill ~-5 ~9 ~4 ~4 ~9 ~4 lapis_block 0  
fill ~-5 ~9 ~5 ~4 ~9 ~5 lapis_block 0  
fill ~-5 ~9 ~6 ~4 ~9 ~6 lapis_block 0  
fill ~-5 ~9 ~7 ~4 ~9 ~7 lapis_block 0  
fill ~-5 ~9 ~8 ~4 ~9 ~8 lapis_block 0  
fill ~-5 ~9 ~9 ~4 ~9 ~9 lapis_block 0  
fill ~-5 ~9 ~10 ~4 ~9 ~10 lapis_block 0  
fill ~-5 ~9 ~11 ~4 ~9 ~11 lapis_block 0  
fill ~16 ~9 ~12 ~24 ~9 ~12 lapis_block 0  
fill ~16 ~9 ~13 ~24 ~9 ~13 lapis_block 0  
fill ~16 ~9 ~14 ~24 ~9 ~14 lapis_block 0  
fill ~16 ~9 ~15 ~24 ~9 ~15 lapis_block 0  
fill ~16 ~9 ~16 ~24 ~9 ~16 lapis_block 0  
fill ~16 ~9 ~17 ~24 ~9 ~17 lapis_block 0  
fill ~16 ~9 ~18 ~24 ~9 ~18 lapis_block 0  
fill ~16 ~9 ~19 ~24 ~9 ~19 lapis_block 0  
fill ~29 ~9 ~12 ~30 ~9 ~12 coal_block 0  
fill ~29 ~9 ~13 ~30 ~9 ~13 coal_block 0  
fill ~29 ~9 ~14 ~30 ~9 ~14 coal_block 0  
fill ~29 ~9 ~15 ~30 ~9 ~15 coal_block 0  
fill ~29 ~9 ~16 ~30 ~9 ~16 coal_block 0  
fill ~29 ~9 ~17 ~30 ~9 ~17 coal_block 0  
fill ~29 ~9 ~18 ~30 ~9 ~18 coal_block 0  
fill ~29 ~9 ~19 ~30 ~9 ~19 coal_block 0  
fill ~-4 ~10 ~4 ~4 ~10 ~4 lapis_block 0  
fill ~-4 ~10 ~5 ~4 ~10 ~5 lapis_block 0  
fill ~-4 ~10 ~6 ~4 ~10 ~6 lapis_block 0  
fill ~-4 ~10 ~7 ~4 ~10 ~7 lapis_block 0  
fill ~-4 ~10 ~8 ~4 ~10 ~8 lapis_block 0  
fill ~-4 ~10 ~9 ~4 ~10 ~9 lapis_block 0  
fill ~-4 ~10 ~10 ~4 ~10 ~10 lapis_block 0  
fill ~-4 ~10 ~11 ~4 ~10 ~11 lapis_block 0  
fill ~15 ~10 ~12 ~23 ~10 ~12 lapis_block 0  
fill ~15 ~10 ~13 ~23 ~10 ~13 lapis_block 0  
fill ~15 ~10 ~14 ~23 ~10 ~14 lapis_block 0  
fill ~15 ~10 ~15 ~23 ~10 ~15 lapis_block 0  
fill ~15 ~10 ~16 ~23 ~10 ~16 lapis_block 0  
fill ~15 ~10 ~17 ~23 ~10 ~17 lapis_block 0  
fill ~15 ~10 ~18 ~23 ~10 ~18 lapis_block 0  
fill ~15 ~10 ~19 ~23 ~10 ~19 lapis_block 0  
fill ~-3 ~11 ~4 ~5 ~11 ~4 lapis_block 0  
fill ~-3 ~11 ~5 ~5 ~11 ~5 lapis_block 0  
fill ~-3 ~11 ~6 ~5 ~11 ~6 lapis_block 0  
fill ~-3 ~11 ~7 ~5 ~11 ~7 lapis_block 0  
fill ~-3 ~11 ~8 ~5 ~11 ~8 lapis_block 0  
fill ~-3 ~11 ~9 ~5 ~11 ~9 lapis_block 0  
fill ~-3 ~11 ~10 ~5 ~11 ~10 lapis_block 0  
fill ~-3 ~11 ~11 ~5 ~11 ~11 lapis_block 0  
fill ~15 ~11 ~12 ~23 ~11 ~12 lapis_block 0  
fill ~15 ~11 ~13 ~23 ~11 ~13 lapis_block 0  
fill ~15 ~11 ~14 ~23 ~11 ~14 lapis_block 0  
fill ~15 ~11 ~15 ~23 ~11 ~15 lapis_block 0  
fill ~15 ~11 ~16 ~23 ~11 ~16 lapis_block 0  
fill ~15 ~11 ~17 ~23 ~11 ~17 lapis_block 0  
fill ~15 ~11 ~18 ~23 ~11 ~18 lapis_block 0  
fill ~15 ~11 ~19 ~23 ~11 ~19 lapis_block 0  
fill ~-3 ~12 ~4 ~6 ~12 ~4 lapis_block 0  
fill ~-3 ~12 ~5 ~6 ~12 ~5 lapis_block 0  
fill ~-3 ~12 ~6 ~6 ~12 ~6 lapis_block 0  
fill ~-3 ~12 ~7 ~6 ~12 ~7 lapis_block 0  
fill ~-3 ~12 ~8 ~6 ~12 ~8 lapis_block 0  
fill ~-3 ~12 ~9 ~6 ~12 ~9 lapis_block 0  
fill ~-3 ~12 ~10 ~6 ~12 ~10 lapis_block 0  
fill ~-3 ~12 ~11 ~6 ~12 ~11 lapis_block 0  
fill ~14 ~12 ~12 ~22 ~12 ~12 lapis_block 0  
fill ~14 ~12 ~13 ~22 ~12 ~13 lapis_block 0  
fill ~14 ~12 ~14 ~22 ~12 ~14 lapis_block 0  
fill ~14 ~12 ~15 ~22 ~12 ~15 lapis_block 0  
fill ~14 ~12 ~16 ~21 ~12 ~16 lapis_block 0  
fill ~14 ~12 ~17 ~22 ~12 ~17 lapis_block 0  
fill ~14 ~12 ~18 ~22 ~12 ~18 lapis_block 0  
fill ~14 ~12 ~19 ~22 ~12 ~19 lapis_block 0 
setblock ~22 ~12 ~16 wool 3  
fill ~-2 ~13 ~4 ~6 ~13 ~4 lapis_block 0  
fill ~-2 ~13 ~5 ~6 ~13 ~5 lapis_block 0  
fill ~-2 ~13 ~6 ~6 ~13 ~6 lapis_block 0  
fill ~-2 ~13 ~7 ~6 ~13 ~7 lapis_block 0  
fill ~-2 ~13 ~8 ~6 ~13 ~8 lapis_block 0  
fill ~-2 ~13 ~9 ~6 ~13 ~9 lapis_block 0  
fill ~-2 ~13 ~10 ~6 ~13 ~10 lapis_block 0  
fill ~-2 ~13 ~11 ~6 ~13 ~11 lapis_block 0  
fill ~14 ~13 ~12 ~22 ~13 ~12 lapis_block 0  
fill ~14 ~13 ~13 ~22 ~13 ~13 lapis_block 0  
fill ~14 ~13 ~14 ~21 ~13 ~14 lapis_block 0  
fill ~14 ~13 ~15 ~21 ~13 ~15 lapis_block 0  
fill ~14 ~13 ~16 ~21 ~13 ~16 lapis_block 0  
fill ~14 ~13 ~17 ~21 ~13 ~17 lapis_block 0  
fill ~14 ~13 ~18 ~22 ~13 ~18 lapis_block 0  
fill ~14 ~13 ~19 ~22 ~13 ~19 lapis_block 0 
setblock ~22 ~13 ~14 wool 3  
fill ~22 ~13 ~15 ~22 ~13 ~16 stained_hardened_clay 5 
setblock ~22 ~13 ~17 wool 11  
fill ~-2 ~14 ~4 ~7 ~14 ~4 lapis_block 0  
fill ~-2 ~14 ~5 ~7 ~14 ~5 lapis_block 0  
fill ~-2 ~14 ~6 ~7 ~14 ~6 lapis_block 0  
fill ~-2 ~14 ~7 ~7 ~14 ~7 lapis_block 0  
fill ~-2 ~14 ~8 ~7 ~14 ~8 lapis_block 0  
fill ~-2 ~14 ~9 ~7 ~14 ~9 lapis_block 0  
fill ~-2 ~14 ~10 ~7 ~14 ~10 lapis_block 0  
fill ~-2 ~14 ~11 ~7 ~14 ~11 lapis_block 0  
fill ~13 ~14 ~12 ~21 ~14 ~12 lapis_block 0  
fill ~13 ~14 ~13 ~20 ~14 ~13 lapis_block 0  
fill ~13 ~14 ~14 ~20 ~14 ~14 lapis_block 0  
fill ~13 ~14 ~15 ~20 ~14 ~15 lapis_block 0  
fill ~13 ~14 ~16 ~20 ~14 ~16 lapis_block 0  
fill ~13 ~14 ~17 ~21 ~14 ~17 lapis_block 0  
fill ~13 ~14 ~18 ~21 ~14 ~18 lapis_block 0  
fill ~13 ~14 ~19 ~21 ~14 ~19 lapis_block 0 
setblock ~21 ~14 ~13 wool 3  
fill ~21 ~14 ~14 ~21 ~15 ~14 stained_hardened_clay 5  
fill ~21 ~14 ~15 ~21 ~15 ~15 stained_hardened_clay 5 
setblock ~21 ~14 ~16 wool 11  
fill ~-1 ~15 ~4 ~7 ~15 ~4 lapis_block 0  
fill ~-1 ~15 ~5 ~7 ~15 ~5 lapis_block 0  
fill ~-1 ~15 ~6 ~7 ~15 ~6 lapis_block 0  
fill ~-1 ~15 ~7 ~7 ~15 ~7 lapis_block 0  
fill ~-1 ~15 ~8 ~7 ~15 ~8 lapis_block 0  
fill ~-1 ~15 ~9 ~7 ~15 ~9 lapis_block 0  
fill ~-1 ~15 ~10 ~7 ~15 ~10 lapis_block 0  
fill ~-1 ~15 ~11 ~7 ~15 ~11 lapis_block 0  
fill ~13 ~15 ~12 ~21 ~15 ~12 lapis_block 0  
fill ~13 ~15 ~13 ~20 ~15 ~13 lapis_block 0  
fill ~13 ~15 ~14 ~20 ~15 ~14 lapis_block 0  
fill ~13 ~15 ~15 ~20 ~15 ~15 lapis_block 0  
fill ~13 ~15 ~16 ~20 ~15 ~16 lapis_block 0  
fill ~13 ~15 ~17 ~20 ~15 ~17 lapis_block 0  
fill ~13 ~15 ~18 ~21 ~15 ~18 lapis_block 0  
fill ~13 ~15 ~19 ~21 ~15 ~19 lapis_block 0 
setblock ~21 ~15 ~13 wool 11 
setblock ~21 ~15 ~16 stained_hardened_clay 5 
setblock ~21 ~15 ~17 wool 3  
fill ~0 ~16 ~4 ~8 ~16 ~4 lapis_block 0  
fill ~0 ~16 ~5 ~8 ~16 ~5 lapis_block 0  
fill ~0 ~16 ~6 ~8 ~16 ~6 lapis_block 0  
fill ~0 ~16 ~7 ~8 ~16 ~7 lapis_block 0  
fill ~0 ~16 ~8 ~8 ~16 ~8 lapis_block 0  
fill ~0 ~16 ~9 ~8 ~16 ~9 lapis_block 0  
fill ~0 ~16 ~10 ~8 ~16 ~10 lapis_block 0  
fill ~0 ~16 ~11 ~8 ~16 ~11 lapis_block 0  
fill ~12 ~16 ~12 ~20 ~16 ~12 lapis_block 0  
fill ~12 ~16 ~13 ~19 ~16 ~13 lapis_block 0  
fill ~12 ~16 ~14 ~19 ~16 ~14 lapis_block 0  
fill ~12 ~16 ~15 ~19 ~16 ~15 lapis_block 0  
fill ~12 ~16 ~16 ~19 ~16 ~16 lapis_block 0  
fill ~12 ~16 ~17 ~19 ~16 ~17 lapis_block 0  
fill ~12 ~16 ~18 ~19 ~16 ~18 lapis_block 0  
fill ~12 ~16 ~19 ~20 ~16 ~19 lapis_block 0 
setblock ~20 ~16 ~13 wool 11  
fill ~20 ~16 ~14 ~20 ~17 ~14 stained_hardened_clay 5  
fill ~20 ~16 ~15 ~20 ~17 ~15 stained_hardened_clay 5  
fill ~20 ~16 ~16 ~20 ~17 ~16 stained_hardened_clay 5  
fill ~20 ~16 ~17 ~20 ~17 ~17 stained_hardened_clay 5 
setblock ~20 ~16 ~18 wool 3  
fill ~0 ~17 ~4 ~8 ~17 ~4 lapis_block 0  
fill ~0 ~17 ~5 ~8 ~17 ~5 lapis_block 0  
fill ~0 ~17 ~6 ~8 ~17 ~6 lapis_block 0  
fill ~0 ~17 ~7 ~8 ~17 ~7 lapis_block 0  
fill ~0 ~17 ~8 ~8 ~17 ~8 lapis_block 0  
fill ~0 ~17 ~9 ~8 ~17 ~9 lapis_block 0  
fill ~0 ~17 ~10 ~8 ~17 ~10 lapis_block 0  
fill ~0 ~17 ~11 ~8 ~17 ~11 lapis_block 0  
fill ~11 ~17 ~12 ~19 ~17 ~12 lapis_block 0  
fill ~11 ~17 ~13 ~19 ~17 ~13 lapis_block 0  
fill ~11 ~17 ~14 ~19 ~17 ~14 lapis_block 0  
fill ~11 ~17 ~15 ~19 ~17 ~15 lapis_block 0  
fill ~11 ~17 ~16 ~19 ~17 ~16 lapis_block 0  
fill ~11 ~17 ~17 ~19 ~17 ~17 lapis_block 0  
fill ~11 ~17 ~18 ~19 ~17 ~18 lapis_block 0  
fill ~11 ~17 ~19 ~20 ~17 ~19 lapis_block 0 
setblock ~20 ~17 ~12 wool 11 
setblock ~20 ~17 ~13 stained_hardened_clay 5 
setblock ~20 ~17 ~18 wool 11  
fill ~1 ~18 ~4 ~9 ~18 ~4 lapis_block 0  
fill ~1 ~18 ~5 ~9 ~18 ~5 lapis_block 0  
fill ~1 ~18 ~6 ~9 ~18 ~6 lapis_block 0  
fill ~1 ~18 ~7 ~9 ~18 ~7 lapis_block 0  
fill ~1 ~18 ~8 ~9 ~18 ~8 lapis_block 0  
fill ~1 ~18 ~9 ~9 ~18 ~9 lapis_block 0  
fill ~1 ~18 ~10 ~9 ~18 ~10 lapis_block 0  
fill ~1 ~18 ~11 ~9 ~18 ~11 lapis_block 0  
fill ~10 ~18 ~12 ~19 ~18 ~12 lapis_block 0  
fill ~10 ~18 ~13 ~18 ~18 ~13 lapis_block 0  
fill ~10 ~18 ~14 ~18 ~18 ~14 lapis_block 0  
fill ~10 ~18 ~15 ~18 ~18 ~15 lapis_block 0  
fill ~10 ~18 ~16 ~18 ~18 ~16 lapis_block 0  
fill ~10 ~18 ~17 ~18 ~18 ~17 lapis_block 0  
fill ~10 ~18 ~18 ~19 ~18 ~18 lapis_block 0  
fill ~10 ~18 ~19 ~19 ~18 ~19 lapis_block 0 
setblock ~19 ~18 ~13 wool 11  
fill ~19 ~18 ~14 ~19 ~18 ~16 stained_hardened_clay 5 
setblock ~19 ~18 ~17 wool 3  
fill ~2 ~19 ~4 ~9 ~19 ~4 lapis_block 0  
fill ~2 ~19 ~5 ~9 ~19 ~5 lapis_block 0  
fill ~2 ~19 ~6 ~9 ~19 ~6 lapis_block 0  
fill ~2 ~19 ~7 ~9 ~19 ~7 lapis_block 0  
fill ~2 ~19 ~8 ~9 ~19 ~8 lapis_block 0  
fill ~2 ~19 ~9 ~9 ~19 ~9 lapis_block 0  
fill ~2 ~19 ~10 ~9 ~19 ~10 lapis_block 0  
fill ~2 ~19 ~11 ~9 ~19 ~11 lapis_block 0  
fill ~9 ~19 ~12 ~18 ~19 ~12 lapis_block 0  
fill ~9 ~19 ~13 ~17 ~19 ~13 lapis_block 0  
fill ~9 ~19 ~14 ~17 ~19 ~14 lapis_block 0  
fill ~9 ~19 ~15 ~17 ~19 ~15 lapis_block 0  
fill ~9 ~19 ~16 ~17 ~19 ~16 lapis_block 0  
fill ~9 ~19 ~17 ~18 ~19 ~17 lapis_block 0  
fill ~9 ~19 ~18 ~18 ~19 ~18 lapis_block 0  
fill ~9 ~19 ~19 ~18 ~19 ~19 lapis_block 0 
setblock ~18 ~19 ~13 wool 11  
fill ~18 ~19 ~14 ~18 ~19 ~15 stained_hardened_clay 5 
setblock ~18 ~19 ~16 wool 11  
fill ~3 ~20 ~4 ~10 ~20 ~4 lapis_block 0  
fill ~3 ~20 ~5 ~10 ~20 ~5 lapis_block 0  
fill ~3 ~20 ~6 ~10 ~20 ~6 lapis_block 0  
fill ~3 ~20 ~7 ~10 ~20 ~7 lapis_block 0  
fill ~3 ~20 ~8 ~10 ~20 ~8 lapis_block 0  
fill ~3 ~20 ~9 ~10 ~20 ~9 lapis_block 0  
fill ~3 ~20 ~10 ~10 ~20 ~10 lapis_block 0  
fill ~3 ~20 ~11 ~10 ~20 ~11 lapis_block 0  
fill ~8 ~20 ~12 ~18 ~20 ~12 lapis_block 0  
fill ~8 ~20 ~13 ~18 ~20 ~13 lapis_block 0  
fill ~8 ~20 ~14 ~17 ~20 ~14 lapis_block 0  
fill ~8 ~20 ~15 ~17 ~20 ~15 lapis_block 0  
fill ~8 ~20 ~16 ~18 ~20 ~16 lapis_block 0  
fill ~8 ~20 ~17 ~18 ~20 ~17 lapis_block 0  
fill ~8 ~20 ~18 ~18 ~20 ~18 lapis_block 0  
fill ~8 ~20 ~19 ~18 ~20 ~19 lapis_block 0 
setblock ~18 ~20 ~14 wool 11 
setblock ~18 ~20 ~15 wool 3  
fill ~4 ~21 ~4 ~10 ~21 ~4 lapis_block 0  
fill ~4 ~21 ~5 ~10 ~21 ~5 lapis_block 0  
fill ~4 ~21 ~6 ~10 ~21 ~6 lapis_block 0  
fill ~4 ~21 ~7 ~10 ~21 ~7 lapis_block 0  
fill ~4 ~21 ~8 ~10 ~21 ~8 lapis_block 0  
fill ~4 ~21 ~9 ~10 ~21 ~9 lapis_block 0  
fill ~4 ~21 ~10 ~10 ~21 ~10 lapis_block 0  
fill ~4 ~21 ~11 ~10 ~21 ~11 lapis_block 0  
fill ~7 ~21 ~12 ~17 ~21 ~12 lapis_block 0  
fill ~7 ~21 ~13 ~17 ~21 ~13 lapis_block 0  
fill ~7 ~21 ~14 ~17 ~21 ~14 lapis_block 0  
fill ~7 ~21 ~15 ~17 ~21 ~15 lapis_block 0  
fill ~7 ~21 ~16 ~17 ~21 ~16 lapis_block 0  
fill ~7 ~21 ~17 ~17 ~21 ~17 lapis_block 0  
fill ~7 ~21 ~18 ~17 ~21 ~18 lapis_block 0  
fill ~8 ~21 ~19 ~17 ~21 ~19 lapis_block 0  
fill ~5 ~22 ~4 ~11 ~22 ~4 lapis_block 0  
fill ~5 ~22 ~5 ~11 ~22 ~5 lapis_block 0  
fill ~5 ~22 ~6 ~11 ~22 ~6 lapis_block 0  
fill ~5 ~22 ~7 ~11 ~22 ~7 lapis_block 0  
fill ~5 ~22 ~8 ~11 ~22 ~8 lapis_block 0  
fill ~5 ~22 ~9 ~11 ~22 ~9 lapis_block 0  
fill ~5 ~22 ~10 ~11 ~22 ~10 lapis_block 0  
fill ~5 ~22 ~11 ~11 ~22 ~11 lapis_block 0  
fill ~6 ~22 ~12 ~17 ~22 ~12 lapis_block 0  
fill ~6 ~22 ~13 ~17 ~22 ~13 lapis_block 0  
fill ~6 ~22 ~14 ~17 ~22 ~14 lapis_block 0  
fill ~6 ~22 ~15 ~17 ~22 ~15 lapis_block 0  
fill ~6 ~22 ~16 ~17 ~22 ~16 lapis_block 0  
fill ~6 ~22 ~17 ~17 ~22 ~17 lapis_block 0  
fill ~6 ~22 ~18 ~17 ~22 ~18 lapis_block 0  
fill ~7 ~22 ~19 ~17 ~22 ~19 lapis_block 0  
fill ~6 ~23 ~4 ~12 ~23 ~4 lapis_block 0  
fill ~6 ~23 ~5 ~12 ~23 ~5 lapis_block 0  
fill ~6 ~23 ~6 ~12 ~23 ~6 lapis_block 0  
fill ~6 ~23 ~7 ~12 ~23 ~7 lapis_block 0  
fill ~6 ~23 ~8 ~12 ~23 ~8 lapis_block 0  
fill ~6 ~23 ~9 ~12 ~23 ~9 lapis_block 0  
fill ~6 ~23 ~10 ~12 ~23 ~10 lapis_block 0  
fill ~6 ~23 ~11 ~12 ~23 ~11 lapis_block 0  
fill ~6 ~23 ~12 ~16 ~23 ~12 lapis_block 0  
fill ~6 ~23 ~13 ~16 ~23 ~13 lapis_block 0  
fill ~6 ~23 ~14 ~16 ~23 ~14 lapis_block 0  
fill ~6 ~23 ~15 ~16 ~23 ~15 lapis_block 0  
fill ~6 ~23 ~16 ~16 ~23 ~16 lapis_block 0  
fill ~6 ~23 ~17 ~16 ~23 ~17 lapis_block 0  
fill ~6 ~23 ~18 ~16 ~23 ~18 lapis_block 0  
fill ~6 ~23 ~19 ~16 ~23 ~19 lapis_block 0  
fill ~6 ~24 ~4 ~12 ~24 ~4 lapis_block 0  
fill ~6 ~24 ~5 ~12 ~24 ~5 lapis_block 0  
fill ~6 ~24 ~6 ~12 ~24 ~6 lapis_block 0  
fill ~6 ~24 ~7 ~12 ~24 ~7 lapis_block 0  
fill ~6 ~24 ~8 ~12 ~24 ~8 lapis_block 0  
fill ~6 ~24 ~9 ~12 ~24 ~9 lapis_block 0  
fill ~6 ~24 ~10 ~12 ~24 ~10 lapis_block 0  
fill ~6 ~24 ~11 ~12 ~24 ~11 lapis_block 0  
fill ~6 ~24 ~12 ~16 ~24 ~12 lapis_block 0  
fill ~6 ~24 ~13 ~16 ~24 ~13 lapis_block 0  
fill ~6 ~24 ~14 ~16 ~24 ~14 lapis_block 0  
fill ~6 ~24 ~15 ~16 ~24 ~15 lapis_block 0  
fill ~6 ~24 ~16 ~16 ~24 ~16 lapis_block 0  
fill ~6 ~24 ~17 ~16 ~24 ~17 lapis_block 0  
fill ~6 ~24 ~18 ~16 ~24 ~18 lapis_block 0  
fill ~6 ~24 ~19 ~16 ~24 ~19 lapis_block 0 
setblock ~18 ~24 ~8 nether_wart_block 0  
fill ~6 ~25 ~4 ~11 ~25 ~4 lapis_block 0  
fill ~6 ~25 ~5 ~12 ~25 ~5 lapis_block 0  
fill ~6 ~25 ~6 ~13 ~25 ~6 lapis_block 0  
fill ~6 ~25 ~7 ~13 ~25 ~7 lapis_block 0  
fill ~6 ~25 ~8 ~13 ~25 ~8 lapis_block 0  
fill ~6 ~25 ~9 ~13 ~25 ~9 lapis_block 0  
fill ~6 ~25 ~10 ~13 ~25 ~10 lapis_block 0  
fill ~6 ~25 ~11 ~13 ~25 ~11 lapis_block 0  
fill ~6 ~25 ~12 ~15 ~25 ~12 lapis_block 0  
fill ~6 ~25 ~13 ~15 ~25 ~13 lapis_block 0  
fill ~6 ~25 ~14 ~15 ~25 ~14 lapis_block 0  
fill ~6 ~25 ~15 ~15 ~25 ~15 lapis_block 0  
fill ~6 ~25 ~16 ~15 ~25 ~16 lapis_block 0  
fill ~6 ~25 ~17 ~15 ~25 ~17 lapis_block 0  
fill ~6 ~25 ~18 ~15 ~25 ~18 lapis_block 0  
fill ~6 ~25 ~19 ~15 ~25 ~19 lapis_block 0  
fill ~12 ~25 ~4 ~13 ~25 ~4 prismarine 0  
fill ~13 ~25 ~5 ~13 ~47 ~5 prismarine 0  
fill ~6 ~26 ~4 ~11 ~26 ~4 lapis_block 0  
fill ~6 ~26 ~5 ~11 ~26 ~5 lapis_block 0  
fill ~6 ~26 ~6 ~11 ~26 ~6 lapis_block 0  
fill ~6 ~26 ~7 ~11 ~26 ~7 lapis_block 0  
fill ~6 ~26 ~8 ~11 ~26 ~8 lapis_block 0  
fill ~6 ~26 ~9 ~11 ~26 ~9 lapis_block 0  
fill ~6 ~26 ~10 ~11 ~26 ~10 lapis_block 0  
fill ~6 ~26 ~11 ~11 ~26 ~11 lapis_block 0  
fill ~6 ~26 ~12 ~7 ~26 ~12 lapis_block 0  
fill ~6 ~26 ~13 ~7 ~26 ~13 lapis_block 0  
fill ~6 ~26 ~14 ~7 ~26 ~14 lapis_block 0  
fill ~6 ~26 ~15 ~7 ~26 ~15 lapis_block 0  
fill ~6 ~26 ~16 ~7 ~26 ~16 lapis_block 0  
fill ~6 ~26 ~17 ~7 ~26 ~17 lapis_block 0  
fill ~6 ~26 ~18 ~7 ~26 ~18 lapis_block 0  
fill ~6 ~26 ~19 ~14 ~26 ~19 lapis_block 0  
fill ~8 ~26 ~12 ~8 ~47 ~12 prismarine 0  
fill ~8 ~26 ~13 ~8 ~47 ~13 prismarine 0  
fill ~8 ~26 ~14 ~8 ~47 ~14 prismarine 0  
fill ~8 ~26 ~15 ~8 ~47 ~15 prismarine 0  
fill ~8 ~26 ~16 ~8 ~47 ~16 prismarine 0  
fill ~8 ~26 ~17 ~8 ~47 ~17 prismarine 0  
fill ~8 ~26 ~18 ~8 ~47 ~18 prismarine 0  
fill ~9 ~26 ~12 ~14 ~26 ~12 lapis_block 0  
fill ~9 ~26 ~13 ~14 ~26 ~13 lapis_block 0  
fill ~9 ~26 ~14 ~14 ~26 ~14 lapis_block 0  
fill ~9 ~26 ~15 ~14 ~26 ~15 lapis_block 0  
fill ~9 ~26 ~16 ~14 ~26 ~16 lapis_block 0  
fill ~9 ~26 ~17 ~14 ~26 ~17 lapis_block 0  
fill ~9 ~26 ~18 ~14 ~26 ~18 lapis_block 0  
fill ~12 ~26 ~4 ~13 ~26 ~4 prismarine 0  
fill ~12 ~26 ~5 ~12 ~47 ~5 prismarine 0  
fill ~12 ~26 ~6 ~12 ~47 ~6 prismarine 0  
fill ~12 ~26 ~7 ~12 ~47 ~7 prismarine 0  
fill ~12 ~26 ~8 ~12 ~47 ~8 prismarine 0  
fill ~12 ~26 ~9 ~12 ~47 ~9 prismarine 0  
fill ~12 ~26 ~10 ~12 ~47 ~10 prismarine 0  
fill ~12 ~26 ~11 ~12 ~47 ~11 prismarine 0  
fill ~13 ~26 ~6 ~13 ~26 ~19 lapis_block 0 
setblock ~18 ~26 ~8 nether_wart_block 0  
fill ~7 ~27 ~4 ~9 ~27 ~4 lapis_block 0  
fill ~7 ~27 ~5 ~10 ~27 ~5 lapis_block 0  
fill ~7 ~27 ~6 ~10 ~27 ~6 lapis_block 0  
fill ~7 ~27 ~7 ~10 ~27 ~7 lapis_block 0  
fill ~7 ~27 ~8 ~10 ~27 ~8 lapis_block 0  
fill ~7 ~27 ~9 ~10 ~27 ~9 lapis_block 0  
fill ~7 ~27 ~10 ~10 ~27 ~10 lapis_block 0  
fill ~7 ~27 ~11 ~10 ~27 ~11 lapis_block 0  
fill ~7 ~27 ~12 ~7 ~27 ~19 lapis_block 0  
fill ~8 ~27 ~19 ~14 ~27 ~19 lapis_block 0  
fill ~9 ~27 ~12 ~9 ~47 ~12 prismarine 0  
fill ~9 ~27 ~13 ~9 ~47 ~13 prismarine 0  
fill ~9 ~27 ~14 ~9 ~47 ~14 prismarine 0  
fill ~9 ~27 ~15 ~9 ~47 ~15 prismarine 0  
fill ~9 ~27 ~16 ~9 ~47 ~16 prismarine 0  
fill ~9 ~27 ~17 ~9 ~47 ~17 prismarine 0  
fill ~9 ~27 ~18 ~9 ~47 ~18 prismarine 0  
fill ~10 ~27 ~4 ~14 ~27 ~4 prismarine 0  
fill ~10 ~27 ~12 ~14 ~27 ~12 lapis_block 0  
fill ~10 ~27 ~13 ~14 ~27 ~13 lapis_block 0  
fill ~10 ~27 ~14 ~14 ~27 ~14 lapis_block 0  
fill ~10 ~27 ~15 ~14 ~27 ~15 lapis_block 0  
fill ~10 ~27 ~16 ~14 ~27 ~16 lapis_block 0  
fill ~10 ~27 ~17 ~14 ~27 ~17 lapis_block 0  
fill ~10 ~27 ~18 ~14 ~27 ~18 lapis_block 0  
fill ~11 ~27 ~5 ~11 ~47 ~5 prismarine 0  
fill ~11 ~27 ~6 ~11 ~47 ~6 prismarine 0  
fill ~11 ~27 ~7 ~11 ~47 ~7 prismarine 0  
fill ~11 ~27 ~8 ~11 ~47 ~8 prismarine 0  
fill ~11 ~27 ~9 ~11 ~47 ~9 prismarine 0  
fill ~11 ~27 ~10 ~11 ~47 ~10 prismarine 0  
fill ~11 ~27 ~11 ~11 ~47 ~11 prismarine 0  
fill ~13 ~27 ~6 ~14 ~27 ~6 prismarine 0  
fill ~13 ~27 ~7 ~14 ~27 ~7 prismarine 0  
fill ~13 ~27 ~8 ~13 ~47 ~8 prismarine 0  
fill ~13 ~27 ~9 ~13 ~47 ~9 prismarine 0  
fill ~13 ~27 ~10 ~13 ~47 ~10 prismarine 0  
fill ~13 ~27 ~11 ~13 ~40 ~11 prismarine 0  
fill ~14 ~27 ~5 ~14 ~30 ~5 prismarine 0  
fill ~14 ~27 ~8 ~14 ~27 ~19 lapis_block 0 
setblock ~29 ~27 ~18 nether_wart_block 0  
fill ~7 ~28 ~4 ~14 ~28 ~4 prismarine 0  
fill ~7 ~28 ~5 ~14 ~28 ~5 prismarine 0  
fill ~7 ~28 ~6 ~14 ~28 ~6 prismarine 0  
fill ~7 ~28 ~7 ~14 ~28 ~7 prismarine 0  
fill ~7 ~28 ~8 ~14 ~28 ~8 prismarine 0  
fill ~7 ~28 ~9 ~14 ~28 ~9 prismarine 0  
fill ~7 ~28 ~10 ~14 ~28 ~10 prismarine 0  
fill ~7 ~28 ~11 ~14 ~28 ~11 prismarine 0  
fill ~7 ~28 ~12 ~7 ~47 ~12 prismarine 0  
fill ~7 ~28 ~13 ~7 ~47 ~13 prismarine 0  
fill ~7 ~28 ~14 ~7 ~47 ~14 prismarine 0  
fill ~7 ~28 ~15 ~7 ~47 ~15 prismarine 0  
fill ~7 ~28 ~16 ~7 ~47 ~16 prismarine 0  
fill ~7 ~28 ~17 ~7 ~47 ~17 prismarine 0  
fill ~7 ~28 ~18 ~7 ~47 ~18 prismarine 0  
fill ~7 ~28 ~19 ~14 ~28 ~19 prismarine 0  
fill ~10 ~28 ~12 ~14 ~28 ~12 prismarine 0  
fill ~10 ~28 ~13 ~14 ~28 ~13 prismarine 0  
fill ~10 ~28 ~14 ~14 ~28 ~14 prismarine 0  
fill ~10 ~28 ~15 ~14 ~28 ~15 prismarine 0  
fill ~10 ~28 ~16 ~14 ~28 ~16 prismarine 0  
fill ~10 ~28 ~17 ~14 ~28 ~17 prismarine 0  
fill ~10 ~28 ~18 ~14 ~28 ~18 prismarine 0  
fill ~29 ~28 ~29 ~29 ~29 ~29 stained_hardened_clay 14  
fill ~7 ~29 ~4 ~11 ~29 ~4 prismarine 0  
fill ~7 ~29 ~5 ~14 ~29 ~5 prismarine 0  
fill ~7 ~29 ~6 ~14 ~29 ~6 prismarine 0  
fill ~7 ~29 ~7 ~13 ~29 ~7 prismarine 0  
fill ~7 ~29 ~8 ~14 ~29 ~8 prismarine 0  
fill ~7 ~29 ~9 ~14 ~29 ~9 prismarine 0  
fill ~7 ~29 ~10 ~14 ~29 ~10 prismarine 0  
fill ~7 ~29 ~11 ~14 ~29 ~11 prismarine 0  
fill ~7 ~29 ~19 ~14 ~29 ~19 prismarine 0  
fill ~10 ~29 ~12 ~14 ~29 ~12 prismarine 0  
fill ~10 ~29 ~13 ~14 ~29 ~13 prismarine 0  
fill ~10 ~29 ~14 ~14 ~29 ~14 prismarine 0  
fill ~10 ~29 ~15 ~14 ~29 ~15 prismarine 0  
fill ~10 ~29 ~16 ~14 ~29 ~16 prismarine 0  
fill ~10 ~29 ~17 ~14 ~29 ~17 prismarine 0  
fill ~10 ~29 ~18 ~14 ~29 ~18 prismarine 0  
fill ~12 ~29 ~4 ~12 ~31 ~4 stained_hardened_clay 9  
fill ~13 ~29 ~4 ~14 ~29 ~4 prismarine 0  
fill ~14 ~29 ~7 ~14 ~30 ~7 stained_hardened_clay 9 
setblock ~18 ~29 ~8 nether_wart_block 0  
fill ~28 ~29 ~29 ~28 ~30 ~29 stained_hardened_clay 14  
fill ~7 ~30 ~4 ~11 ~30 ~4 prismarine 0  
fill ~7 ~30 ~5 ~14 ~30 ~5 prismarine 0  
fill ~7 ~30 ~6 ~13 ~30 ~6 prismarine 0  
fill ~7 ~30 ~7 ~13 ~30 ~7 prismarine 0  
fill ~7 ~30 ~8 ~14 ~30 ~8 prismarine 0  
fill ~7 ~30 ~9 ~14 ~30 ~9 prismarine 0  
fill ~7 ~30 ~10 ~14 ~30 ~10 prismarine 0  
fill ~7 ~30 ~11 ~14 ~30 ~11 prismarine 0  
fill ~7 ~30 ~19 ~14 ~30 ~19 prismarine 0  
fill ~10 ~30 ~12 ~14 ~30 ~12 prismarine 0  
fill ~10 ~30 ~13 ~14 ~30 ~13 prismarine 0  
fill ~10 ~30 ~14 ~14 ~30 ~14 prismarine 0  
fill ~10 ~30 ~15 ~14 ~30 ~15 prismarine 0  
fill ~10 ~30 ~16 ~14 ~30 ~16 prismarine 0  
fill ~10 ~30 ~17 ~14 ~30 ~17 prismarine 0  
fill ~10 ~30 ~18 ~14 ~30 ~18 prismarine 0  
fill ~13 ~30 ~4 ~14 ~30 ~4 stained_hardened_clay 9  
fill ~14 ~30 ~6 ~14 ~33 ~6 stained_hardened_clay 9  
fill ~28 ~30 ~28 ~28 ~31 ~28 stained_hardened_clay 14 
setblock ~29 ~30 ~18 nether_wart_block 0  
fill ~7 ~31 ~4 ~11 ~31 ~4 prismarine 0  
fill ~7 ~31 ~5 ~13 ~31 ~5 prismarine 0  
fill ~7 ~31 ~6 ~13 ~31 ~6 prismarine 0  
fill ~7 ~31 ~7 ~14 ~31 ~7 prismarine 0  
fill ~7 ~31 ~8 ~14 ~31 ~8 prismarine 0  
fill ~7 ~31 ~9 ~14 ~31 ~9 prismarine 0  
fill ~7 ~31 ~10 ~14 ~31 ~10 prismarine 0  
fill ~7 ~31 ~11 ~14 ~31 ~11 prismarine 0  
fill ~7 ~31 ~19 ~13 ~31 ~19 prismarine 0  
fill ~10 ~31 ~12 ~14 ~31 ~12 prismarine 0  
fill ~10 ~31 ~13 ~14 ~31 ~13 prismarine 0  
fill ~10 ~31 ~14 ~14 ~31 ~14 prismarine 0  
fill ~10 ~31 ~15 ~14 ~31 ~15 prismarine 0  
fill ~10 ~31 ~16 ~14 ~31 ~16 prismarine 0  
fill ~10 ~31 ~17 ~14 ~31 ~17 prismarine 0  
fill ~10 ~31 ~18 ~14 ~31 ~18 prismarine 0  
fill ~13 ~31 ~4 ~14 ~31 ~4 stained_hardened_clay 9  
fill ~14 ~31 ~5 ~14 ~34 ~5 stained_hardened_clay 9  
fill ~14 ~31 ~19 ~14 ~35 ~19 stained_hardened_clay 7  
fill ~18 ~31 ~8 ~18 ~32 ~8 nether_wart_block 0 
setblock ~19 ~31 ~12 nether_wart_block 0  
fill ~29 ~31 ~28 ~29 ~32 ~28 stained_hardened_clay 14  
fill ~7 ~32 ~4 ~13 ~32 ~4 prismarine 0  
fill ~7 ~32 ~5 ~13 ~32 ~5 prismarine 0  
fill ~7 ~32 ~6 ~13 ~32 ~6 prismarine 0  
fill ~7 ~32 ~7 ~14 ~32 ~7 prismarine 0  
fill ~7 ~32 ~8 ~13 ~32 ~8 prismarine 0  
fill ~7 ~32 ~9 ~14 ~32 ~9 prismarine 0  
fill ~7 ~32 ~10 ~14 ~32 ~10 prismarine 0  
fill ~7 ~32 ~11 ~14 ~32 ~11 prismarine 0  
fill ~7 ~32 ~19 ~12 ~32 ~19 prismarine 0  
fill ~10 ~32 ~12 ~14 ~32 ~12 prismarine 0  
fill ~10 ~32 ~13 ~14 ~32 ~13 prismarine 0  
fill ~10 ~32 ~14 ~14 ~32 ~14 prismarine 0  
fill ~10 ~32 ~15 ~14 ~32 ~15 prismarine 0  
fill ~10 ~32 ~16 ~14 ~32 ~16 prismarine 0  
fill ~10 ~32 ~17 ~14 ~32 ~17 prismarine 0  
fill ~10 ~32 ~18 ~14 ~32 ~18 prismarine 0  
fill ~13 ~32 ~19 ~13 ~34 ~19 stained_hardened_clay 7 
setblock ~14 ~32 ~4 stained_hardened_clay 9  
fill ~14 ~32 ~8 ~14 ~35 ~8 stained_hardened_clay 9 
setblock ~29 ~32 ~18 stained_hardened_clay 8  
fill ~29 ~32 ~29 ~29 ~33 ~29 stained_hardened_clay 8  
fill ~7 ~33 ~4 ~13 ~33 ~4 prismarine 0  
fill ~7 ~33 ~5 ~13 ~33 ~5 prismarine 0  
fill ~7 ~33 ~6 ~13 ~33 ~6 prismarine 0  
fill ~7 ~33 ~7 ~14 ~33 ~7 prismarine 0  
fill ~7 ~33 ~8 ~13 ~33 ~8 prismarine 0  
fill ~7 ~33 ~9 ~14 ~33 ~9 prismarine 0  
fill ~7 ~33 ~10 ~14 ~33 ~10 prismarine 0  
fill ~7 ~33 ~11 ~14 ~33 ~11 prismarine 0  
fill ~7 ~33 ~19 ~12 ~33 ~19 prismarine 0  
fill ~10 ~33 ~12 ~14 ~33 ~12 prismarine 0  
fill ~10 ~33 ~13 ~14 ~33 ~13 prismarine 0  
fill ~10 ~33 ~14 ~14 ~33 ~14 prismarine 0  
fill ~10 ~33 ~15 ~14 ~33 ~15 prismarine 0  
fill ~10 ~33 ~16 ~14 ~33 ~16 prismarine 0  
fill ~10 ~33 ~17 ~14 ~33 ~17 prismarine 0  
fill ~10 ~33 ~18 ~14 ~33 ~18 prismarine 0  
fill ~14 ~33 ~4 ~14 ~34 ~4 stained_hardened_clay 7  
fill ~19 ~33 ~12 ~19 ~34 ~12 nether_wart_block 0  
fill ~28 ~33 ~28 ~28 ~34 ~28 stained_hardened_clay 14  
fill ~28 ~33 ~29 ~28 ~33 ~28 stained_hardened_clay 14  
fill ~29 ~33 ~18 ~29 ~33 ~19 stained_hardened_clay 14  
fill ~7 ~34 ~4 ~13 ~34 ~4 prismarine 0  
fill ~7 ~34 ~5 ~13 ~34 ~5 prismarine 0  
fill ~7 ~34 ~6 ~14 ~34 ~6 prismarine 0  
fill ~7 ~34 ~7 ~14 ~34 ~7 prismarine 0  
fill ~7 ~34 ~8 ~13 ~34 ~8 prismarine 0  
fill ~7 ~34 ~9 ~14 ~34 ~9 prismarine 0  
fill ~7 ~34 ~10 ~14 ~34 ~10 prismarine 0  
fill ~7 ~34 ~11 ~14 ~34 ~11 prismarine 0  
fill ~7 ~34 ~19 ~12 ~34 ~19 prismarine 0  
fill ~10 ~34 ~12 ~14 ~34 ~12 prismarine 0  
fill ~10 ~34 ~13 ~14 ~34 ~13 prismarine 0  
fill ~10 ~34 ~14 ~14 ~34 ~14 prismarine 0  
fill ~10 ~34 ~15 ~14 ~34 ~15 prismarine 0  
fill ~10 ~34 ~16 ~14 ~34 ~16 prismarine 0  
fill ~10 ~34 ~17 ~14 ~34 ~17 prismarine 0  
fill ~10 ~34 ~18 ~13 ~34 ~18 prismarine 0  
fill ~14 ~34 ~18 ~14 ~38 ~18 stained_hardened_clay 7  
fill ~18 ~34 ~8 ~18 ~35 ~8 nether_wart_block 0 
setblock ~18 ~34 ~15 nether_wart_block 0 
setblock ~19 ~34 ~11 nether_wart_block 0 
setblock ~28 ~34 ~19 stained_hardened_clay 8   

KittysCommands:  
setblock ~29 ~34 ~19 stained_hardened_clay 14 
setblock ~29 ~34 ~28 stained_hardened_clay 14  
fill ~7 ~35 ~4 ~14 ~35 ~4 prismarine 0  
fill ~7 ~35 ~5 ~13 ~35 ~5 prismarine 0  
fill ~7 ~35 ~6 ~14 ~35 ~6 prismarine 0  
fill ~7 ~35 ~7 ~14 ~35 ~7 prismarine 0  
fill ~7 ~35 ~8 ~13 ~35 ~8 prismarine 0  
fill ~7 ~35 ~9 ~14 ~35 ~9 prismarine 0  
fill ~7 ~35 ~10 ~14 ~35 ~10 prismarine 0  
fill ~7 ~35 ~11 ~14 ~35 ~11 prismarine 0  
fill ~7 ~35 ~19 ~13 ~35 ~19 prismarine 0  
fill ~10 ~35 ~12 ~14 ~35 ~12 prismarine 0  
fill ~10 ~35 ~13 ~14 ~35 ~13 prismarine 0  
fill ~10 ~35 ~14 ~14 ~35 ~14 prismarine 0  
fill ~10 ~35 ~15 ~14 ~35 ~15 prismarine 0  
fill ~10 ~35 ~16 ~14 ~35 ~16 prismarine 0  
fill ~10 ~35 ~17 ~13 ~35 ~17 prismarine 0  
fill ~10 ~35 ~18 ~13 ~35 ~18 prismarine 0  
fill ~14 ~35 ~5 ~14 ~37 ~5 stained_hardened_clay 7  
fill ~14 ~35 ~17 ~14 ~37 ~17 stained_hardened_clay 7 
setblock ~28 ~35 ~18 stained_hardened_clay 8 
setblock ~28 ~35 ~19 stained_hardened_clay 14  
fill ~28 ~35 ~29 ~29 ~35 ~29 stained_hardened_clay 14 
setblock ~29 ~35 ~28 stained_hardened_clay 8  
fill ~7 ~36 ~4 ~13 ~36 ~4 prismarine 0  
fill ~7 ~36 ~5 ~13 ~36 ~5 prismarine 0  
fill ~7 ~36 ~6 ~13 ~36 ~6 prismarine 0  
fill ~7 ~36 ~7 ~14 ~36 ~7 prismarine 0  
fill ~7 ~36 ~8 ~14 ~36 ~8 prismarine 0  
fill ~7 ~36 ~9 ~13 ~36 ~9 prismarine 0  
fill ~7 ~36 ~10 ~14 ~36 ~10 prismarine 0  
fill ~7 ~36 ~11 ~14 ~36 ~11 prismarine 0  
fill ~7 ~36 ~19 ~13 ~36 ~19 prismarine 0  
fill ~10 ~36 ~12 ~14 ~36 ~12 prismarine 0  
fill ~10 ~36 ~13 ~14 ~36 ~13 prismarine 0  
fill ~10 ~36 ~14 ~14 ~36 ~14 prismarine 0  
fill ~10 ~36 ~15 ~14 ~36 ~15 prismarine 0  
fill ~10 ~36 ~16 ~13 ~36 ~16 prismarine 0  
fill ~10 ~36 ~17 ~13 ~36 ~17 prismarine 0  
fill ~10 ~36 ~18 ~13 ~36 ~18 prismarine 0  
fill ~14 ~36 ~4 ~14 ~37 ~4 stained_hardened_clay 7 
setblock ~14 ~36 ~6 stained_hardened_clay 7  
fill ~14 ~36 ~9 ~14 ~38 ~9 stained_hardened_clay 9 
setblock ~14 ~36 ~16 stained_hardened_clay 7  
fill ~14 ~36 ~19 ~14 ~39 ~19 stained_hardened_clay 9  
fill ~18 ~36 ~15 ~18 ~42 ~15 nether_wart_block 0  
fill ~19 ~36 ~12 ~19 ~37 ~12 nether_wart_block 0 
setblock ~20 ~36 ~-5 nether_wart_block 0  
fill ~27 ~36 ~28 ~27 ~42 ~28 nether_wart_block 0  
fill ~28 ~36 ~18 ~29 ~36 ~18 stained_hardened_clay 14  
fill ~28 ~36 ~28 ~28 ~37 ~28 stained_hardened_clay 14  
fill ~28 ~36 ~29 ~28 ~35 ~29 stained_hardened_clay 14 
setblock ~29 ~36 ~19 stained_hardened_clay 8  
fill ~7 ~37 ~4 ~13 ~37 ~4 prismarine 0  
fill ~7 ~37 ~5 ~13 ~37 ~5 prismarine 0  
fill ~7 ~37 ~6 ~14 ~37 ~6 prismarine 0  
fill ~7 ~37 ~7 ~14 ~37 ~7 prismarine 0  
fill ~7 ~37 ~8 ~14 ~37 ~8 prismarine 0  
fill ~7 ~37 ~9 ~13 ~37 ~9 prismarine 0  
fill ~7 ~37 ~10 ~14 ~37 ~10 prismarine 0  
fill ~7 ~37 ~11 ~14 ~37 ~11 prismarine 0  
fill ~7 ~37 ~19 ~12 ~37 ~19 prismarine 0  
fill ~10 ~37 ~12 ~14 ~37 ~12 prismarine 0  
fill ~10 ~37 ~13 ~14 ~37 ~13 prismarine 0  
fill ~10 ~37 ~14 ~14 ~37 ~14 prismarine 0  
fill ~10 ~37 ~15 ~14 ~37 ~15 prismarine 0  
fill ~10 ~37 ~16 ~14 ~37 ~16 prismarine 0  
fill ~10 ~37 ~17 ~13 ~37 ~17 prismarine 0  
fill ~10 ~37 ~18 ~13 ~37 ~18 prismarine 0  
fill ~13 ~37 ~19 ~13 ~39 ~19 stained_hardened_clay 9  
fill ~19 ~37 ~11 ~19 ~39 ~11 nether_wart_block 0  
fill ~28 ~37 ~19 ~29 ~37 ~19 stained_hardened_clay 14  
fill ~7 ~38 ~4 ~14 ~38 ~4 prismarine 0  
fill ~7 ~38 ~5 ~14 ~38 ~5 prismarine 0  
fill ~7 ~38 ~6 ~14 ~38 ~6 prismarine 0  
fill ~7 ~38 ~7 ~14 ~38 ~7 prismarine 0  
fill ~7 ~38 ~8 ~14 ~38 ~8 prismarine 0  
fill ~7 ~38 ~9 ~13 ~38 ~9 prismarine 0  
fill ~7 ~38 ~10 ~14 ~38 ~10 prismarine 0  
fill ~7 ~38 ~11 ~14 ~38 ~11 prismarine 0  
fill ~7 ~38 ~19 ~11 ~38 ~19 prismarine 0  
fill ~10 ~38 ~12 ~14 ~38 ~12 prismarine 0  
fill ~10 ~38 ~13 ~14 ~38 ~13 prismarine 0  
fill ~10 ~38 ~14 ~14 ~38 ~14 prismarine 0  
fill ~10 ~38 ~15 ~14 ~38 ~15 prismarine 0  
fill ~10 ~38 ~16 ~14 ~38 ~16 prismarine 0  
fill ~10 ~38 ~17 ~14 ~38 ~17 prismarine 0  
fill ~10 ~38 ~18 ~13 ~38 ~18 prismarine 0  
fill ~12 ~38 ~19 ~12 ~39 ~19 stained_hardened_clay 9  
fill ~15 ~38 ~10 ~17 ~38 ~10 stained_hardened_clay 5  
fill ~15 ~38 ~11 ~17 ~38 ~11 stained_hardened_clay 5  
fill ~15 ~38 ~12 ~17 ~38 ~12 stained_hardened_clay 5  
fill ~15 ~38 ~13 ~17 ~38 ~13 stained_hardened_clay 5  
fill ~18 ~38 ~8 ~18 ~42 ~8 nether_wart_block 0  
fill ~20 ~38 ~-5 ~20 ~40 ~-5 nether_wart_block 0 
setblock ~22 ~38 ~-5 nether_wart_block 0  
fill ~28 ~38 ~18 ~28 ~41 ~18 nether_wart_block 0  
fill ~28 ~38 ~19 ~28 ~37 ~19 stained_hardened_clay 14 
setblock ~28 ~38 ~28 stained_hardened_clay 8  
fill ~29 ~38 ~29 ~29 ~41 ~29 nether_wart_block 0 
setblock ~31 ~38 ~22 nether_wart_block 0  
fill ~7 ~39 ~4 ~14 ~39 ~4 prismarine 0  
fill ~7 ~39 ~5 ~14 ~39 ~5 prismarine 0  
fill ~7 ~39 ~6 ~14 ~39 ~6 prismarine 0  
fill ~7 ~39 ~7 ~14 ~39 ~7 prismarine 0  
fill ~7 ~39 ~8 ~14 ~39 ~8 prismarine 0  
fill ~7 ~39 ~9 ~14 ~39 ~9 prismarine 0  
fill ~7 ~39 ~10 ~14 ~39 ~10 prismarine 0  
fill ~7 ~39 ~11 ~14 ~39 ~11 prismarine 0  
fill ~7 ~39 ~19 ~11 ~39 ~19 prismarine 0  
fill ~10 ~39 ~12 ~14 ~39 ~12 prismarine 0  
fill ~10 ~39 ~13 ~14 ~39 ~13 prismarine 0  
fill ~10 ~39 ~14 ~14 ~39 ~14 prismarine 0  
fill ~10 ~39 ~15 ~14 ~39 ~15 prismarine 0  
fill ~10 ~39 ~16 ~14 ~39 ~16 prismarine 0  
fill ~10 ~39 ~17 ~14 ~39 ~17 prismarine 0  
fill ~10 ~39 ~18 ~13 ~39 ~18 prismarine 0  
fill ~14 ~39 ~18 ~14 ~40 ~18 stained_hardened_clay 9  
fill ~15 ~39 ~9 ~17 ~39 ~9 stained_hardened_clay 13  
fill ~15 ~39 ~10 ~18 ~39 ~10 stained_hardened_clay 13  
fill ~15 ~39 ~11 ~18 ~39 ~11 stained_hardened_clay 13  
fill ~15 ~39 ~12 ~18 ~39 ~12 stained_hardened_clay 13  
fill ~15 ~39 ~13 ~18 ~39 ~13 stained_hardened_clay 13  
fill ~15 ~39 ~14 ~17 ~39 ~14 stained_hardened_clay 13  
fill ~19 ~39 ~9 ~19 ~41 ~9 nether_wart_block 0  
fill ~19 ~39 ~12 ~19 ~40 ~12 nether_wart_block 0 
setblock ~27 ~39 ~29 stained_hardened_clay 8 
setblock ~28 ~39 ~28 stained_hardened_clay 14 
setblock ~29 ~39 ~18 stained_hardened_clay 14  
fill ~7 ~40 ~-4 ~14 ~40 ~-4 prismarine 0  
fill ~7 ~40 ~-3 ~14 ~40 ~-3 prismarine 0  
fill ~7 ~40 ~-2 ~14 ~40 ~-2 prismarine 0  
fill ~7 ~40 ~-1 ~14 ~40 ~-1 prismarine 0  
fill ~7 ~40 ~0 ~14 ~40 ~0 prismarine 0  
fill ~7 ~40 ~1 ~14 ~40 ~1 prismarine 0  
fill ~7 ~40 ~2 ~14 ~40 ~2 prismarine 0  
fill ~7 ~40 ~3 ~14 ~40 ~3 prismarine 0  
fill ~7 ~40 ~4 ~14 ~40 ~4 prismarine 0  
fill ~7 ~40 ~5 ~14 ~40 ~5 prismarine 0  
fill ~7 ~40 ~6 ~14 ~40 ~6 prismarine 0  
fill ~7 ~40 ~7 ~14 ~40 ~7 prismarine 0  
fill ~7 ~40 ~8 ~14 ~40 ~8 prismarine 0  
fill ~7 ~40 ~9 ~13 ~40 ~9 prismarine 0  
fill ~7 ~40 ~10 ~13 ~40 ~10 prismarine 0  
fill ~7 ~40 ~11 ~13 ~40 ~11 prismarine 0  
fill ~7 ~40 ~19 ~13 ~40 ~19 prismarine 0  
fill ~7 ~40 ~20 ~14 ~40 ~20 prismarine 0  
fill ~7 ~40 ~21 ~14 ~40 ~21 prismarine 0  
fill ~7 ~40 ~22 ~14 ~40 ~22 prismarine 0  
fill ~7 ~40 ~23 ~14 ~40 ~23 prismarine 0  
fill ~7 ~40 ~24 ~14 ~40 ~24 prismarine 0  
fill ~7 ~40 ~25 ~14 ~40 ~25 prismarine 0  
fill ~7 ~40 ~26 ~14 ~40 ~26 prismarine 0  
fill ~7 ~40 ~27 ~14 ~40 ~27 prismarine 0  
fill ~10 ~40 ~12 ~13 ~40 ~12 prismarine 0  
fill ~10 ~40 ~13 ~13 ~40 ~13 prismarine 0  
fill ~10 ~40 ~14 ~13 ~40 ~14 prismarine 0  
fill ~10 ~40 ~15 ~14 ~40 ~15 prismarine 0  
fill ~10 ~40 ~16 ~14 ~40 ~16 prismarine 0  
fill ~10 ~40 ~17 ~14 ~40 ~17 prismarine 0  
fill ~10 ~40 ~18 ~13 ~40 ~18 prismarine 0  
fill ~14 ~40 ~9 ~14 ~47 ~9 stained_hardened_clay 13  
fill ~14 ~40 ~10 ~14 ~47 ~10 coal_block 0  
fill ~14 ~40 ~11 ~14 ~40 ~13 coal_block 0  
fill ~14 ~40 ~14 ~14 ~47 ~14 stained_hardened_clay 13  
fill ~14 ~40 ~19 ~14 ~42 ~19 stained_hardened_clay 7  
fill ~15 ~40 ~-4 ~24 ~40 ~-4 stained_hardened_clay 5  
fill ~15 ~40 ~-3 ~24 ~40 ~-3 stained_hardened_clay 5  
fill ~15 ~40 ~-2 ~18 ~40 ~-2 stained_hardened_clay 5  
fill ~15 ~40 ~-1 ~18 ~40 ~-1 stained_hardened_clay 5  
fill ~15 ~40 ~0 ~18 ~40 ~0 stained_hardened_clay 5  
fill ~15 ~40 ~1 ~18 ~40 ~1 stained_hardened_clay 5  
fill ~15 ~40 ~2 ~30 ~40 ~2 stained_hardened_clay 5  
fill ~15 ~40 ~3 ~20 ~40 ~3 stained_hardened_clay 13  
fill ~15 ~40 ~8 ~17 ~40 ~8 stained_hardened_clay 13  
fill ~15 ~40 ~9 ~15 ~47 ~9 coal_block 0  
fill ~15 ~40 ~14 ~15 ~47 ~14 coal_block 0  
fill ~15 ~40 ~15 ~17 ~40 ~15 stained_hardened_clay 13  
fill ~15 ~40 ~20 ~18 ~40 ~20 stained_hardened_clay 5  
fill ~15 ~40 ~21 ~30 ~40 ~21 stained_hardened_clay 5  
fill ~15 ~40 ~22 ~18 ~40 ~22 stained_hardened_clay 5  
fill ~15 ~40 ~23 ~18 ~40 ~23 stained_hardened_clay 5  
fill ~15 ~40 ~24 ~18 ~40 ~24 stained_hardened_clay 5  
fill ~15 ~40 ~25 ~18 ~40 ~25 stained_hardened_clay 5  
fill ~15 ~40 ~26 ~24 ~40 ~26 stained_hardened_clay 5  
fill ~15 ~40 ~27 ~24 ~40 ~27 stained_hardened_clay 5  
fill ~16 ~40 ~11 ~18 ~40 ~11 nether_wart_block 0 
setblock ~16 ~40 ~14 stone_slab 7  
fill ~17 ~40 ~9 ~17 ~40 ~10 stone_slab 7 
setblock ~17 ~40 ~12 stone_slab 7 
setblock ~17 ~40 ~13 nether_wart_block 0  
fill ~18 ~40 ~9 ~18 ~42 ~9 stained_hardened_clay 13  
fill ~18 ~40 ~10 ~18 ~40 ~9 stained_hardened_clay 13 
setblock ~18 ~40 ~12 nether_wart_block 0  
fill ~18 ~40 ~13 ~18 ~40 ~14 stained_hardened_clay 13  
fill ~19 ~40 ~-2 ~20 ~40 ~-2 stained_hardened_clay 13  
fill ~19 ~40 ~-1 ~20 ~40 ~-1 stained_hardened_clay 13  
fill ~19 ~40 ~0 ~20 ~40 ~0 stained_hardened_clay 13  
fill ~19 ~40 ~1 ~20 ~40 ~1 stained_hardened_clay 13  
fill ~19 ~40 ~20 ~24 ~40 ~20 stained_hardened_clay 13  
fill ~19 ~40 ~22 ~20 ~40 ~22 stained_hardened_clay 13  
fill ~19 ~40 ~23 ~20 ~40 ~23 stained_hardened_clay 13  
fill ~19 ~40 ~24 ~20 ~40 ~24 stained_hardened_clay 13  
fill ~19 ~40 ~25 ~20 ~40 ~25 stained_hardened_clay 13  
fill ~21 ~40 ~-2 ~30 ~40 ~-2 stained_hardened_clay 5  
fill ~21 ~40 ~-1 ~30 ~40 ~-1 stained_hardened_clay 5  
fill ~21 ~40 ~0 ~24 ~40 ~0 stained_hardened_clay 5  
fill ~21 ~40 ~1 ~24 ~40 ~1 stained_hardened_clay 5  
fill ~21 ~40 ~3 ~24 ~40 ~3 stained_hardened_clay 5  
fill ~21 ~40 ~22 ~24 ~40 ~22 stained_hardened_clay 5  
fill ~21 ~40 ~23 ~24 ~40 ~23 stained_hardened_clay 5  
fill ~21 ~40 ~24 ~30 ~40 ~24 stained_hardened_clay 5  
fill ~21 ~40 ~25 ~29 ~40 ~25 stained_hardened_clay 5  
fill ~22 ~40 ~-5 ~22 ~41 ~-5 nether_wart_block 0  
fill ~25 ~40 ~-4 ~30 ~40 ~-4 stained_hardened_clay 13  
fill ~25 ~40 ~-3 ~30 ~40 ~-3 stained_hardened_clay 13  
fill ~25 ~40 ~0 ~30 ~40 ~0 stained_hardened_clay 13  
fill ~25 ~40 ~1 ~30 ~40 ~1 stained_hardened_clay 13  
fill ~25 ~40 ~3 ~26 ~40 ~3 stained_hardened_clay 13  
fill ~25 ~40 ~20 ~30 ~40 ~20 stained_hardened_clay 5  
fill ~25 ~40 ~22 ~30 ~40 ~22 stained_hardened_clay 13  
fill ~25 ~40 ~23 ~30 ~40 ~23 stained_hardened_clay 13  
fill ~25 ~40 ~26 ~30 ~40 ~26 stained_hardened_clay 13  
fill ~25 ~40 ~27 ~30 ~40 ~27 stained_hardened_clay 13  
fill ~27 ~40 ~3 ~28 ~40 ~3 stained_hardened_clay 5  
fill ~28 ~40 ~19 ~29 ~40 ~19 stained_hardened_clay 14  
fill ~28 ~40 ~29 ~28 ~41 ~29 stained_hardened_clay 14  
fill ~29 ~40 ~3 ~30 ~40 ~3 stained_hardened_clay 13  
fill ~29 ~40 ~18 ~29 ~42 ~18 nether_wart_block 0 
setblock ~30 ~40 ~25 nether_wart_block 0  
fill ~31 ~40 ~22 ~31 ~42 ~22 nether_wart_block 0  
fill ~7 ~41 ~-4 ~14 ~41 ~-4 prismarine 0  
fill ~7 ~41 ~-3 ~14 ~41 ~-3 prismarine 0  
fill ~7 ~41 ~-2 ~14 ~41 ~-2 prismarine 0  
fill ~7 ~41 ~-1 ~14 ~41 ~-1 prismarine 0  
fill ~7 ~41 ~0 ~14 ~41 ~0 prismarine 0  
fill ~7 ~41 ~1 ~14 ~41 ~1 prismarine 0  
fill ~7 ~41 ~2 ~14 ~41 ~2 prismarine 0  
fill ~7 ~41 ~3 ~14 ~41 ~3 prismarine 0  
fill ~7 ~41 ~4 ~14 ~41 ~4 prismarine 0  
fill ~7 ~41 ~5 ~14 ~41 ~5 prismarine 0  
fill ~7 ~41 ~6 ~14 ~41 ~6 prismarine 0  
fill ~7 ~41 ~7 ~14 ~41 ~7 prismarine 0  
fill ~7 ~41 ~8 ~14 ~41 ~8 prismarine 0  
fill ~7 ~41 ~9 ~13 ~41 ~9 prismarine 0  
fill ~7 ~41 ~10 ~13 ~41 ~10 prismarine 0  
fill ~7 ~41 ~11 ~12 ~41 ~11 prismarine 0  
fill ~7 ~41 ~19 ~13 ~41 ~19 prismarine 0  
fill ~7 ~41 ~20 ~14 ~41 ~20 prismarine 0  
fill ~7 ~41 ~21 ~14 ~41 ~21 prismarine 0  
fill ~7 ~41 ~22 ~14 ~41 ~22 prismarine 0  
fill ~7 ~41 ~23 ~14 ~41 ~23 prismarine 0  
fill ~7 ~41 ~24 ~14 ~41 ~24 prismarine 0  
fill ~7 ~41 ~25 ~14 ~41 ~25 prismarine 0  
fill ~7 ~41 ~26 ~14 ~41 ~26 prismarine 0  
fill ~7 ~41 ~27 ~14 ~41 ~27 prismarine 0  
fill ~10 ~41 ~12 ~12 ~41 ~12 prismarine 0  
fill ~10 ~41 ~13 ~13 ~41 ~13 prismarine 0  
fill ~10 ~41 ~14 ~13 ~41 ~14 prismarine 0  
fill ~10 ~41 ~15 ~14 ~41 ~15 prismarine 0  
fill ~10 ~41 ~16 ~14 ~41 ~16 prismarine 0  
fill ~10 ~41 ~17 ~14 ~41 ~17 prismarine 0  
fill ~10 ~41 ~18 ~14 ~41 ~18 prismarine 0  
fill ~13 ~41 ~11 ~13 ~47 ~11 coal_block 0  
fill ~13 ~41 ~12 ~13 ~47 ~12 coal_block 0  
fill ~14 ~41 ~13 ~14 ~47 ~13 coal_block 0  
fill ~15 ~41 ~-4 ~19 ~41 ~-4 stained_hardened_clay 5  
fill ~15 ~41 ~-3 ~19 ~41 ~-3 stained_hardened_clay 5  
fill ~15 ~41 ~-2 ~30 ~41 ~-2 stained_hardened_clay 5  
fill ~15 ~41 ~-1 ~30 ~41 ~-1 stained_hardened_clay 5  
fill ~15 ~41 ~0 ~29 ~41 ~0 stained_hardened_clay 5  
fill ~15 ~41 ~1 ~29 ~41 ~1 stained_hardened_clay 5  
fill ~15 ~41 ~2 ~30 ~41 ~2 stained_hardened_clay 5  
fill ~15 ~41 ~3 ~20 ~41 ~3 stained_hardened_clay 13  
fill ~15 ~41 ~8 ~17 ~41 ~8 stained_hardened_clay 13  
fill ~15 ~41 ~15 ~17 ~41 ~15 stained_hardened_clay 13  
fill ~15 ~41 ~20 ~18 ~41 ~20 stained_hardened_clay 5  
fill ~15 ~41 ~21 ~29 ~41 ~21 stained_hardened_clay 5  
fill ~15 ~41 ~22 ~29 ~41 ~22 stained_hardened_clay 5  
fill ~15 ~41 ~23 ~29 ~41 ~23 stained_hardened_clay 5  
fill ~15 ~41 ~24 ~30 ~41 ~24 stained_hardened_clay 5  
fill ~15 ~41 ~25 ~30 ~41 ~25 stained_hardened_clay 5  
fill ~15 ~41 ~26 ~29 ~41 ~26 stained_hardened_clay 5  
fill ~15 ~41 ~27 ~29 ~41 ~27 stained_hardened_clay 5  
fill ~18 ~41 ~14 ~18 ~42 ~14 stained_hardened_clay 13  
fill ~19 ~41 ~20 ~24 ~41 ~20 stained_hardened_clay 13  
fill ~20 ~41 ~-4 ~20 ~41 ~-3 nether_wart_block 0  
fill ~21 ~41 ~-4 ~29 ~41 ~-4 stained_hardened_clay 5  
fill ~21 ~41 ~-3 ~29 ~41 ~-3 stained_hardened_clay 5  
fill ~21 ~41 ~3 ~30 ~41 ~3 stained_hardened_clay 5  
fill ~23 ~41 ~-5 ~23 ~42 ~-5 nether_wart_block 0  
fill ~25 ~41 ~20 ~30 ~41 ~20 stained_hardened_clay 5  
fill ~28 ~41 ~19 ~28 ~42 ~19 stained_hardened_clay 14 
setblock ~28 ~41 ~28 stained_hardened_clay 14  
fill ~30 ~41 ~-4 ~30 ~43 ~-4 stained_hardened_clay 13  
fill ~30 ~41 ~-3 ~30 ~43 ~-3 stained_hardened_clay 13  
fill ~30 ~41 ~0 ~30 ~43 ~0 stained_hardened_clay 13  
fill ~30 ~41 ~1 ~30 ~43 ~1 stained_hardened_clay 13  
fill ~30 ~41 ~21 ~30 ~42 ~21 stained_hardened_clay 14  
fill ~30 ~41 ~22 ~30 ~43 ~22 stained_hardened_clay 13  
fill ~30 ~41 ~23 ~30 ~43 ~23 stained_hardened_clay 13 
setblock ~30 ~41 ~26 stained_hardened_clay 13 
setblock ~30 ~41 ~27 nether_wart_block 0  
fill ~7 ~42 ~-4 ~14 ~42 ~-4 prismarine 0  
fill ~7 ~42 ~-3 ~14 ~42 ~-3 prismarine 0  
fill ~7 ~42 ~-2 ~14 ~42 ~-2 prismarine 0  
fill ~7 ~42 ~-1 ~14 ~42 ~-1 prismarine 0  
fill ~7 ~42 ~0 ~14 ~42 ~0 prismarine 0  
fill ~7 ~42 ~1 ~14 ~42 ~1 prismarine 0  
fill ~7 ~42 ~2 ~14 ~42 ~2 prismarine 0  
fill ~7 ~42 ~3 ~14 ~42 ~3 prismarine 0  
fill ~7 ~42 ~4 ~14 ~42 ~4 prismarine 0  
fill ~7 ~42 ~5 ~14 ~42 ~5 prismarine 0  
fill ~7 ~42 ~6 ~14 ~42 ~6 prismarine 0  
fill ~7 ~42 ~7 ~14 ~42 ~7 prismarine 0  
fill ~7 ~42 ~8 ~14 ~42 ~8 prismarine 0  
fill ~7 ~42 ~9 ~13 ~42 ~9 prismarine 0  
fill ~7 ~42 ~10 ~13 ~42 ~10 prismarine 0  
fill ~7 ~42 ~11 ~12 ~42 ~11 prismarine 0  
fill ~7 ~42 ~19 ~13 ~42 ~19 prismarine 0  
fill ~7 ~42 ~20 ~14 ~42 ~20 prismarine 0  
fill ~7 ~42 ~21 ~14 ~42 ~21 prismarine 0  
fill ~7 ~42 ~22 ~14 ~42 ~22 prismarine 0  
fill ~7 ~42 ~23 ~14 ~42 ~23 prismarine 0  
fill ~7 ~42 ~24 ~14 ~42 ~24 prismarine 0  
fill ~7 ~42 ~25 ~14 ~42 ~25 prismarine 0  
fill ~7 ~42 ~26 ~14 ~42 ~26 prismarine 0  
fill ~7 ~42 ~27 ~14 ~42 ~27 prismarine 0  
fill ~10 ~42 ~12 ~12 ~42 ~12 prismarine 0  
fill ~10 ~42 ~13 ~13 ~42 ~13 prismarine 0  
fill ~10 ~42 ~14 ~13 ~42 ~14 prismarine 0  
fill ~10 ~42 ~15 ~14 ~42 ~15 prismarine 0  
fill ~10 ~42 ~16 ~14 ~42 ~16 prismarine 0  
fill ~10 ~42 ~17 ~14 ~42 ~17 prismarine 0  
fill ~10 ~42 ~18 ~14 ~42 ~18 prismarine 0  
fill ~15 ~42 ~-4 ~17 ~42 ~-4 stained_hardened_clay 5  
fill ~15 ~42 ~-3 ~18 ~42 ~-3 stained_hardened_clay 5  
fill ~15 ~42 ~-2 ~19 ~42 ~-2 stained_hardened_clay 5  
fill ~15 ~42 ~-1 ~30 ~42 ~-1 stained_hardened_clay 5  
fill ~15 ~42 ~0 ~29 ~42 ~0 stained_hardened_clay 5  
fill ~15 ~42 ~1 ~29 ~42 ~1 stained_hardened_clay 5  
fill ~15 ~42 ~2 ~30 ~42 ~2 stained_hardened_clay 5  
fill ~15 ~42 ~3 ~22 ~42 ~3 stained_hardened_clay 5  
fill ~15 ~42 ~8 ~17 ~42 ~8 stained_hardened_clay 13  
fill ~15 ~42 ~15 ~17 ~42 ~15 stained_hardened_clay 13  
fill ~15 ~42 ~20 ~28 ~42 ~20 stained_hardened_clay 5  
fill ~15 ~42 ~21 ~29 ~42 ~21 stained_hardened_clay 5  
fill ~15 ~42 ~22 ~29 ~42 ~22 stained_hardened_clay 5  
fill ~15 ~42 ~23 ~29 ~42 ~23 stained_hardened_clay 5  
fill ~15 ~42 ~24 ~30 ~42 ~24 stained_hardened_clay 5  
fill ~15 ~42 ~25 ~29 ~42 ~25 stained_hardened_clay 5  
fill ~15 ~42 ~26 ~29 ~42 ~26 stained_hardened_clay 5  
fill ~15 ~42 ~27 ~29 ~42 ~27 stained_hardened_clay 5 
setblock ~18 ~42 ~-4 stained_hardened_clay 9 
setblock ~19 ~42 ~-3 stained_hardened_clay 15 
setblock ~20 ~42 ~-2 stained_hardened_clay 15  
fill ~21 ~42 ~-3 ~21 ~42 ~-2 stained_hardened_clay 14 
setblock ~22 ~42 ~-4 stained_hardened_clay 9  
fill ~22 ~42 ~-3 ~29 ~42 ~-3 stained_hardened_clay 5  
fill ~22 ~42 ~-2 ~30 ~42 ~-2 stained_hardened_clay 5 
setblock ~23 ~42 ~-4 stained_hardened_clay 5  
fill ~23 ~42 ~3 ~28 ~42 ~3 stained_hardened_clay 13 
setblock ~24 ~42 ~-4 stained_hardened_clay 9  
fill ~25 ~42 ~-4 ~29 ~42 ~-4 stained_hardened_clay 5  
fill ~27 ~42 ~19 ~27 ~43 ~19 stained_hardened_clay 14  
fill ~28 ~42 ~28 ~29 ~42 ~28 nether_wart_block 0  
fill ~28 ~42 ~29 ~28 ~43 ~29 nether_wart_block 0  
fill ~29 ~42 ~3 ~30 ~42 ~3 stained_hardened_clay 5  
fill ~29 ~42 ~19 ~29 ~43 ~19 nether_wart_block 0  
fill ~29 ~42 ~20 ~29 ~43 ~20 stained_hardened_clay 14 
setblock ~29 ~42 ~29 stained_hardened_clay 14  
fill ~30 ~42 ~20 ~30 ~43 ~20 stained_hardened_clay 5  
fill ~30 ~42 ~25 ~30 ~42 ~26 stained_hardened_clay 14  
fill ~30 ~42 ~27 ~30 ~43 ~27 stained_hardened_clay 13  
fill ~7 ~43 ~-4 ~14 ~43 ~-4 prismarine 0  
fill ~7 ~43 ~-3 ~14 ~43 ~-3 prismarine 0  
fill ~7 ~43 ~-2 ~14 ~43 ~-2 prismarine 0  
fill ~7 ~43 ~-1 ~14 ~43 ~-1 prismarine 0  
fill ~7 ~43 ~0 ~14 ~43 ~0 prismarine 0  
fill ~7 ~43 ~1 ~14 ~43 ~1 prismarine 0  
fill ~7 ~43 ~2 ~14 ~43 ~2 prismarine 0  
fill ~7 ~43 ~3 ~14 ~43 ~3 prismarine 0  
fill ~7 ~43 ~4 ~14 ~43 ~4 prismarine 0  
fill ~7 ~43 ~5 ~14 ~43 ~5 prismarine 0  
fill ~7 ~43 ~6 ~14 ~43 ~6 prismarine 0  
fill ~7 ~43 ~7 ~14 ~43 ~7 prismarine 0  
fill ~7 ~43 ~8 ~14 ~43 ~8 prismarine 0  
fill ~7 ~43 ~9 ~13 ~43 ~9 prismarine 0  
fill ~7 ~43 ~10 ~13 ~43 ~10 prismarine 0  
fill ~7 ~43 ~11 ~12 ~43 ~11 prismarine 0  
fill ~7 ~43 ~19 ~14 ~43 ~19 prismarine 0  
fill ~7 ~43 ~20 ~14 ~43 ~20 prismarine 0  
fill ~7 ~43 ~21 ~14 ~43 ~21 prismarine 0  
fill ~7 ~43 ~22 ~14 ~43 ~22 prismarine 0  
fill ~7 ~43 ~23 ~14 ~43 ~23 prismarine 0  
fill ~7 ~43 ~24 ~14 ~43 ~24 prismarine 0  
fill ~7 ~43 ~25 ~14 ~43 ~25 prismarine 0  
fill ~7 ~43 ~26 ~14 ~43 ~26 prismarine 0  
fill ~7 ~43 ~27 ~14 ~43 ~27 prismarine 0  
fill ~10 ~43 ~12 ~12 ~43 ~12 prismarine 0  
fill ~10 ~43 ~13 ~13 ~43 ~13 prismarine 0  
fill ~10 ~43 ~14 ~13 ~43 ~14 prismarine 0  
fill ~10 ~43 ~15 ~14 ~43 ~15 prismarine 0  
fill ~10 ~43 ~16 ~14 ~43 ~16 prismarine 0  
fill ~10 ~43 ~17 ~14 ~43 ~17 prismarine 0  
fill ~10 ~43 ~18 ~14 ~43 ~18 prismarine 0  
fill ~15 ~43 ~-4 ~18 ~43 ~-4 stained_hardened_clay 5  
fill ~15 ~43 ~-3 ~19 ~43 ~-3 stained_hardened_clay 5  
fill ~15 ~43 ~-2 ~19 ~43 ~-2 stained_hardened_clay 5  
fill ~15 ~43 ~-1 ~30 ~43 ~-1 stained_hardened_clay 5  
fill ~15 ~43 ~0 ~29 ~43 ~0 stained_hardened_clay 5  
fill ~15 ~43 ~1 ~29 ~43 ~1 stained_hardened_clay 5  
fill ~15 ~43 ~2 ~30 ~43 ~2 stained_hardened_clay 5  
fill ~15 ~43 ~3 ~22 ~43 ~3 stained_hardened_clay 5  
fill ~15 ~43 ~7 ~16 ~43 ~7 stained_hardened_clay 5  
fill ~15 ~43 ~8 ~17 ~43 ~8 stained_hardened_clay 13  
fill ~15 ~43 ~15 ~17 ~43 ~15 stained_hardened_clay 13  
fill ~15 ~43 ~16 ~15 ~62 ~16 stained_hardened_clay 5  
fill ~15 ~43 ~20 ~28 ~43 ~20 stained_hardened_clay 5  
fill ~15 ~43 ~21 ~30 ~43 ~21 stained_hardened_clay 5  
fill ~15 ~43 ~22 ~29 ~43 ~22 stained_hardened_clay 5  
fill ~15 ~43 ~23 ~29 ~43 ~23 stained_hardened_clay 5  
fill ~15 ~43 ~24 ~30 ~43 ~24 stained_hardened_clay 5  
fill ~15 ~43 ~25 ~30 ~43 ~25 stained_hardened_clay 5  
fill ~15 ~43 ~26 ~29 ~43 ~26 stained_hardened_clay 5  
fill ~15 ~43 ~27 ~29 ~43 ~27 stained_hardened_clay 5 
setblock ~17 ~43 ~14 nether_wart_block 0 
setblock ~18 ~43 ~9 nether_wart_block 0 
setblock ~19 ~43 ~-4 stained_hardened_clay 13  
fill ~20 ~43 ~-2 ~23 ~43 ~-2 bone_block 4 
setblock ~23 ~43 ~-4 nether_wart_block 0  
fill ~23 ~43 ~3 ~28 ~43 ~3 stained_hardened_clay 13 
setblock ~24 ~43 ~-3 stained_hardened_clay 14  
fill ~24 ~43 ~-2 ~30 ~43 ~-2 stained_hardened_clay 5 
setblock ~25 ~43 ~-4 stained_hardened_clay 13  
fill ~25 ~43 ~-3 ~29 ~43 ~-3 stained_hardened_clay 5  
fill ~26 ~43 ~-4 ~29 ~43 ~-4 stained_hardened_clay 5  
fill ~28 ~43 ~18 ~28 ~44 ~18 nether_wart_block 0  
fill ~28 ~43 ~19 ~28 ~44 ~19 nether_wart_block 0 
setblock ~28 ~43 ~28 stained_hardened_clay 14  
fill ~29 ~43 ~3 ~30 ~43 ~3 stained_hardened_clay 5 
setblock ~29 ~43 ~28 nether_wart_block 0 
setblock ~30 ~43 ~26 stained_hardened_clay 14 
setblock ~31 ~43 ~21 nether_wart_block 0  
fill ~7 ~44 ~-4 ~14 ~44 ~-4 prismarine 0  
fill ~7 ~44 ~-3 ~14 ~44 ~-3 prismarine 0  
fill ~7 ~44 ~-2 ~14 ~44 ~-2 prismarine 0  
fill ~7 ~44 ~-1 ~14 ~44 ~-1 prismarine 0  
fill ~7 ~44 ~0 ~14 ~44 ~0 prismarine 0  
fill ~7 ~44 ~1 ~14 ~44 ~1 prismarine 0  
fill ~7 ~44 ~2 ~14 ~44 ~2 prismarine 0  
fill ~7 ~44 ~3 ~14 ~44 ~3 prismarine 0  
fill ~7 ~44 ~4 ~14 ~44 ~4 prismarine 0  
fill ~7 ~44 ~5 ~14 ~44 ~5 prismarine 0  
fill ~7 ~44 ~6 ~14 ~44 ~6 prismarine 0  
fill ~7 ~44 ~7 ~14 ~44 ~7 prismarine 0  
fill ~7 ~44 ~8 ~14 ~44 ~8 prismarine 0  
fill ~7 ~44 ~9 ~13 ~44 ~9 prismarine 0  
fill ~7 ~44 ~10 ~13 ~44 ~10 prismarine 0  
fill ~7 ~44 ~11 ~12 ~44 ~11 prismarine 0  
fill ~7 ~44 ~19 ~14 ~44 ~19 prismarine 0  
fill ~7 ~44 ~20 ~14 ~44 ~20 prismarine 0  
fill ~7 ~44 ~21 ~14 ~44 ~21 prismarine 0  
fill ~7 ~44 ~22 ~14 ~44 ~22 prismarine 0  
fill ~7 ~44 ~23 ~14 ~44 ~23 prismarine 0  
fill ~7 ~44 ~24 ~14 ~44 ~24 prismarine 0  
fill ~7 ~44 ~25 ~14 ~44 ~25 prismarine 0  
fill ~7 ~44 ~26 ~14 ~44 ~26 prismarine 0  
fill ~7 ~44 ~27 ~14 ~44 ~27 prismarine 0  
fill ~10 ~44 ~12 ~12 ~44 ~12 prismarine 0  
fill ~10 ~44 ~13 ~13 ~44 ~13 prismarine 0  
fill ~10 ~44 ~14 ~13 ~44 ~14 prismarine 0  
fill ~10 ~44 ~15 ~14 ~44 ~15 prismarine 0  
fill ~10 ~44 ~16 ~14 ~44 ~16 prismarine 0  
fill ~10 ~44 ~17 ~14 ~44 ~17 prismarine 0  
fill ~10 ~44 ~18 ~14 ~44 ~18 prismarine 0  
fill ~15 ~44 ~-4 ~17 ~44 ~-4 stained_hardened_clay 5  
fill ~15 ~44 ~-3 ~19 ~44 ~-3 stained_hardened_clay 5  
fill ~15 ~44 ~-2 ~20 ~44 ~-2 stained_hardened_clay 5  
fill ~15 ~44 ~-1 ~29 ~44 ~-1 stained_hardened_clay 5  
fill ~15 ~44 ~0 ~30 ~44 ~0 stained_hardened_clay 5  
fill ~15 ~44 ~1 ~30 ~44 ~1 stained_hardened_clay 5  
fill ~15 ~44 ~2 ~29 ~44 ~2 stained_hardened_clay 5  
fill ~15 ~44 ~3 ~29 ~44 ~3 stained_hardened_clay 5  
fill ~15 ~44 ~6 ~15 ~60 ~6 stained_hardened_clay 5  
fill ~15 ~44 ~7 ~17 ~44 ~7 stained_hardened_clay 5  
fill ~15 ~44 ~8 ~17 ~44 ~8 stained_hardened_clay 13  
fill ~15 ~44 ~15 ~17 ~44 ~15 stained_hardened_clay 13  
fill ~15 ~44 ~17 ~15 ~62 ~17 stained_hardened_clay 5  
fill ~15 ~44 ~20 ~22 ~44 ~20 stained_hardened_clay 5  
fill ~15 ~44 ~21 ~30 ~44 ~21 stained_hardened_clay 5  
fill ~15 ~44 ~22 ~29 ~44 ~22 stained_hardened_clay 5  
fill ~15 ~44 ~23 ~30 ~44 ~23 stained_hardened_clay 5  
fill ~15 ~44 ~24 ~29 ~44 ~24 stained_hardened_clay 5  
fill ~15 ~44 ~25 ~29 ~44 ~25 stained_hardened_clay 5  
fill ~15 ~44 ~26 ~30 ~44 ~26 stained_hardened_clay 5  
fill ~15 ~44 ~27 ~29 ~44 ~27 stained_hardened_clay 5  
fill ~16 ~44 ~16 ~17 ~44 ~16 stained_hardened_clay 5 
setblock ~18 ~44 ~-4 stained_hardened_clay 13  
fill ~19 ~44 ~-4 ~20 ~44 ~-4 stained_hardened_clay 5 
setblock ~20 ~44 ~-3 stained_hardened_clay 15 
setblock ~21 ~44 ~-2 bone_block 4 
setblock ~22 ~44 ~-3 stained_hardened_clay 14  
fill ~22 ~44 ~-2 ~29 ~44 ~-2 stained_hardened_clay 5  
fill ~23 ~44 ~-4 ~24 ~44 ~-4 stained_hardened_clay 13  
fill ~23 ~44 ~-3 ~30 ~44 ~-3 stained_hardened_clay 5  
fill ~23 ~44 ~20 ~28 ~44 ~20 stained_hardened_clay 13 
setblock ~25 ~44 ~-4 stained_hardened_clay 5 
setblock ~26 ~44 ~-4 stained_hardened_clay 9  
fill ~27 ~44 ~-4 ~30 ~44 ~-4 stained_hardened_clay 5 
setblock ~27 ~44 ~19 nether_wart_block 0 
setblock ~29 ~44 ~19 stained_hardened_clay 14  
fill ~29 ~44 ~20 ~29 ~46 ~20 stained_hardened_clay 5 
setblock ~29 ~44 ~28 stained_hardened_clay 14  
fill ~30 ~44 ~-2 ~30 ~47 ~-2 stained_hardened_clay 13  
fill ~30 ~44 ~-1 ~30 ~47 ~-1 stained_hardened_clay 13  
fill ~30 ~44 ~2 ~30 ~47 ~2 stained_hardened_clay 13  
fill ~30 ~44 ~3 ~30 ~47 ~3 stained_hardened_clay 13 
setblock ~30 ~44 ~20 stained_hardened_clay 14  
fill ~30 ~44 ~22 ~30 ~45 ~22 stained_hardened_clay 8  
fill ~30 ~44 ~24 ~30 ~47 ~24 stained_hardened_clay 13 
setblock ~30 ~44 ~25 stained_hardened_clay 14  
fill ~30 ~44 ~27 ~30 ~45 ~27 nether_wart_block 0  
fill ~7 ~45 ~-4 ~14 ~45 ~-4 prismarine 0  
fill ~7 ~45 ~-3 ~14 ~45 ~-3 prismarine 0  
fill ~7 ~45 ~-2 ~14 ~45 ~-2 prismarine 0  
fill ~7 ~45 ~-1 ~14 ~45 ~-1 prismarine 0  
fill ~7 ~45 ~0 ~14 ~45 ~0 prismarine 0  
fill ~7 ~45 ~1 ~14 ~45 ~1 prismarine 0  
fill ~7 ~45 ~2 ~14 ~45 ~2 prismarine 0  
fill ~7 ~45 ~3 ~14 ~45 ~3 prismarine 0  
fill ~7 ~45 ~4 ~14 ~45 ~4 prismarine 0  
fill ~7 ~45 ~5 ~14 ~45 ~5 prismarine 0  
fill ~7 ~45 ~6 ~14 ~45 ~6 prismarine 0  
fill ~7 ~45 ~7 ~14 ~45 ~7 prismarine 0  
fill ~7 ~45 ~8 ~14 ~45 ~8 prismarine 0  
fill ~7 ~45 ~9 ~13 ~45 ~9 prismarine 0  
fill ~7 ~45 ~10 ~13 ~45 ~10 prismarine 0  
fill ~7 ~45 ~11 ~12 ~45 ~11 prismarine 0  
fill ~7 ~45 ~19 ~14 ~45 ~19 prismarine 0  
fill ~7 ~45 ~20 ~14 ~45 ~20 prismarine 0  
fill ~7 ~45 ~21 ~14 ~45 ~21 prismarine 0  
fill ~7 ~45 ~22 ~14 ~45 ~22 prismarine 0  
fill ~7 ~45 ~23 ~14 ~45 ~23 prismarine 0  
fill ~7 ~45 ~24 ~14 ~45 ~24 prismarine 0  
fill ~7 ~45 ~25 ~14 ~45 ~25 prismarine 0  
fill ~7 ~45 ~26 ~14 ~45 ~26 prismarine 0  
fill ~7 ~45 ~27 ~14 ~45 ~27 prismarine 0  
fill ~10 ~45 ~12 ~12 ~45 ~12 prismarine 0  
fill ~10 ~45 ~13 ~13 ~45 ~13 prismarine 0  
fill ~10 ~45 ~14 ~13 ~45 ~14 prismarine 0  
fill ~10 ~45 ~15 ~14 ~45 ~15 prismarine 0  
fill ~10 ~45 ~16 ~14 ~45 ~16 prismarine 0  
fill ~10 ~45 ~17 ~14 ~45 ~17 prismarine 0  
fill ~10 ~45 ~18 ~14 ~45 ~18 prismarine 0  
fill ~15 ~45 ~-4 ~18 ~45 ~-4 stained_hardened_clay 5  
fill ~15 ~45 ~-3 ~30 ~45 ~-3 stained_hardened_clay 5  
fill ~15 ~45 ~-2 ~29 ~45 ~-2 stained_hardened_clay 5  
fill ~15 ~45 ~-1 ~29 ~45 ~-1 stained_hardened_clay 5  
fill ~15 ~45 ~0 ~30 ~45 ~0 stained_hardened_clay 5  
fill ~15 ~45 ~1 ~30 ~45 ~1 stained_hardened_clay 5  
fill ~15 ~45 ~2 ~29 ~45 ~2 stained_hardened_clay 5  
fill ~15 ~45 ~3 ~29 ~45 ~3 stained_hardened_clay 5  
fill ~15 ~45 ~5 ~15 ~59 ~5 stained_hardened_clay 5  
fill ~15 ~45 ~7 ~17 ~45 ~7 stained_hardened_clay 5  
fill ~15 ~45 ~8 ~17 ~45 ~8 stained_hardened_clay 13  
fill ~15 ~45 ~15 ~17 ~45 ~15 stained_hardened_clay 13  
fill ~15 ~45 ~18 ~15 ~62 ~18 stained_hardened_clay 5  
fill ~15 ~45 ~20 ~22 ~45 ~20 stained_hardened_clay 5  
fill ~15 ~45 ~21 ~29 ~45 ~21 stained_hardened_clay 5  
fill ~15 ~45 ~22 ~29 ~45 ~22 stained_hardened_clay 5  
fill ~15 ~45 ~23 ~30 ~45 ~23 stained_hardened_clay 5  
fill ~15 ~45 ~24 ~29 ~45 ~24 stained_hardened_clay 5  
fill ~15 ~45 ~25 ~29 ~45 ~25 stained_hardened_clay 5  
fill ~15 ~45 ~26 ~29 ~45 ~26 stained_hardened_clay 5  
fill ~15 ~45 ~27 ~28 ~45 ~27 stained_hardened_clay 5  
fill ~16 ~45 ~6 ~16 ~49 ~6 stained_hardened_clay 5  
fill ~16 ~45 ~16 ~17 ~45 ~16 stained_hardened_clay 5  
fill ~16 ~45 ~17 ~16 ~62 ~17 stained_hardened_clay 5  
fill ~18 ~45 ~9 ~18 ~49 ~9 stained_hardened_clay 13  
fill ~18 ~45 ~14 ~18 ~49 ~14 stained_hardened_clay 13 
setblock ~19 ~45 ~-4 stained_hardened_clay 9  
fill ~20 ~45 ~-4 ~20 ~47 ~-4 stained_hardened_clay 5 
setblock ~21 ~45 ~-4 stained_hardened_clay 9 
setblock ~22 ~45 ~-4 stained_hardened_clay 5  
fill ~23 ~45 ~-4 ~23 ~44 ~-4 stained_hardened_clay 13  
fill ~23 ~45 ~20 ~28 ~45 ~20 stained_hardened_clay 13  
fill ~24 ~45 ~-4 ~25 ~45 ~-4 stained_hardened_clay 8  
fill ~26 ~45 ~-4 ~30 ~45 ~-4 stained_hardened_clay 5 
setblock ~27 ~45 ~19 stained_hardened_clay 14  
fill ~29 ~45 ~27 ~29 ~46 ~27 nether_wart_block 0  
fill ~30 ~45 ~20 ~30 ~47 ~20 stained_hardened_clay 13 
setblock ~30 ~45 ~21 stained_hardened_clay 14  
fill ~30 ~45 ~25 ~30 ~47 ~25 stained_hardened_clay 13 
setblock ~30 ~45 ~26 stained_hardened_clay 8  
fill ~7 ~46 ~-4 ~14 ~46 ~-4 prismarine 0  
fill ~7 ~46 ~-3 ~14 ~46 ~-3 prismarine 0  
fill ~7 ~46 ~-2 ~14 ~46 ~-2 prismarine 0  
fill ~7 ~46 ~-1 ~14 ~46 ~-1 prismarine 0  
fill ~7 ~46 ~0 ~14 ~46 ~0 prismarine 0  
fill ~7 ~46 ~1 ~14 ~46 ~1 prismarine 0  
fill ~7 ~46 ~2 ~14 ~46 ~2 prismarine 0  
fill ~7 ~46 ~3 ~14 ~46 ~3 prismarine 0  
fill ~7 ~46 ~4 ~14 ~46 ~4 prismarine 0  
fill ~7 ~46 ~5 ~14 ~46 ~5 prismarine 0  
fill ~7 ~46 ~6 ~14 ~46 ~6 prismarine 0  
fill ~7 ~46 ~7 ~14 ~46 ~7 prismarine 0  
fill ~7 ~46 ~8 ~13 ~46 ~8 prismarine 0  
fill ~7 ~46 ~9 ~13 ~46 ~9 prismarine 0  
fill ~7 ~46 ~10 ~13 ~46 ~10 prismarine 0  
fill ~7 ~46 ~11 ~12 ~46 ~11 prismarine 0  
fill ~7 ~46 ~19 ~14 ~46 ~19 prismarine 0  
fill ~7 ~46 ~20 ~14 ~46 ~20 prismarine 0  
fill ~7 ~46 ~21 ~14 ~46 ~21 prismarine 0  
fill ~7 ~46 ~22 ~14 ~46 ~22 prismarine 0  
fill ~7 ~46 ~23 ~14 ~46 ~23 prismarine 0  
fill ~7 ~46 ~24 ~14 ~46 ~24 prismarine 0  
fill ~7 ~46 ~25 ~14 ~46 ~25 prismarine 0  
fill ~7 ~46 ~26 ~14 ~46 ~26 prismarine 0  
fill ~7 ~46 ~27 ~14 ~46 ~27 prismarine 0  
fill ~10 ~46 ~12 ~12 ~46 ~12 prismarine 0  
fill ~10 ~46 ~13 ~13 ~46 ~13 prismarine 0  
fill ~10 ~46 ~14 ~13 ~46 ~14 prismarine 0  
fill ~10 ~46 ~15 ~13 ~46 ~15 prismarine 0  
fill ~10 ~46 ~16 ~14 ~46 ~16 prismarine 0  
fill ~10 ~46 ~17 ~14 ~46 ~17 prismarine 0  
fill ~10 ~46 ~18 ~14 ~46 ~18 prismarine 0  
fill ~14 ~46 ~8 ~14 ~62 ~8 stained_hardened_clay 5  
fill ~14 ~46 ~15 ~14 ~62 ~15 stained_hardened_clay 5  
fill ~15 ~46 ~-4 ~20 ~46 ~-4 stained_hardened_clay 5  
fill ~15 ~46 ~-3 ~21 ~46 ~-3 stained_hardened_clay 5  
fill ~15 ~46 ~-2 ~29 ~46 ~-2 stained_hardened_clay 5  
fill ~15 ~46 ~-1 ~29 ~46 ~-1 stained_hardened_clay 5  
fill ~15 ~46 ~0 ~30 ~46 ~0 stained_hardened_clay 5  
fill ~15 ~46 ~1 ~30 ~46 ~1 stained_hardened_clay 5  
fill ~15 ~46 ~2 ~29 ~46 ~2 stained_hardened_clay 5  
fill ~15 ~46 ~3 ~18 ~46 ~3 stained_hardened_clay 5  
fill ~15 ~46 ~7 ~18 ~46 ~7 stained_hardened_clay 5  
fill ~15 ~46 ~8 ~17 ~46 ~8 stained_hardened_clay 13  
fill ~15 ~46 ~15 ~17 ~46 ~15 stained_hardened_clay 13  
fill ~15 ~46 ~20 ~20 ~46 ~20 stained_hardened_clay 13  
fill ~15 ~46 ~21 ~29 ~46 ~21 stained_hardened_clay 5  
fill ~15 ~46 ~22 ~30 ~46 ~22 stained_hardened_clay 5  
fill ~15 ~46 ~23 ~30 ~46 ~23 stained_hardened_clay 5  
fill ~15 ~46 ~24 ~29 ~46 ~24 stained_hardened_clay 5  
fill ~15 ~46 ~25 ~29 ~46 ~25 stained_hardened_clay 5  
fill ~15 ~46 ~26 ~30 ~46 ~26 stained_hardened_clay 5  
fill ~15 ~46 ~27 ~28 ~46 ~27 stained_hardened_clay 5  
fill ~16 ~46 ~5 ~16 ~59 ~5 stained_hardened_clay 5  
fill ~16 ~46 ~16 ~18 ~46 ~16 stained_hardened_clay 5  
fill ~16 ~46 ~18 ~16 ~62 ~18 stained_hardened_clay 5  
fill ~19 ~46 ~3 ~24 ~46 ~3 stained_hardened_clay 13 
setblock ~21 ~46 ~-4 stained_hardened_clay 8  
fill ~21 ~46 ~20 ~29 ~46 ~20 stained_hardened_clay 5  
fill ~22 ~46 ~-3 ~25 ~46 ~-3 bone_block 4  
fill ~25 ~46 ~3 ~29 ~46 ~3 stained_hardened_clay 5 
setblock ~26 ~46 ~-4 stained_hardened_clay 13  
fill ~26 ~46 ~-3 ~30 ~46 ~-3 stained_hardened_clay 5  
fill ~27 ~46 ~-4 ~30 ~46 ~-4 stained_hardened_clay 5 
setblock ~30 ~46 ~21 stained_hardened_clay 8 
setblock ~30 ~46 ~27 stained_hardened_clay 8  
fill ~7 ~47 ~-4 ~14 ~47 ~-4 prismarine 0   
fill ~7 ~47 ~-3 ~14 ~47 ~-3 prismarine 0  
fill ~7 ~47 ~-2 ~14 ~47 ~-2 prismarine 0  
fill ~7 ~47 ~-1 ~14 ~47 ~-1 prismarine 0  
fill ~7 ~47 ~0 ~14 ~47 ~0 prismarine 0  
fill ~7 ~47 ~1 ~14 ~47 ~1 prismarine 0  
fill ~7 ~47 ~2 ~14 ~47 ~2 prismarine 0  
fill ~7 ~47 ~3 ~14 ~47 ~3 prismarine 0  
fill ~7 ~47 ~4 ~14 ~47 ~4 prismarine 0  
fill ~7 ~47 ~5 ~14 ~47 ~5 prismarine 0  
fill ~7 ~47 ~6 ~14 ~47 ~6 prismarine 0  
fill ~7 ~47 ~7 ~14 ~47 ~7 prismarine 0  
fill ~7 ~47 ~8 ~13 ~47 ~8 prismarine 0  
fill ~7 ~47 ~9 ~13 ~47 ~9 prismarine 0  
fill ~7 ~47 ~10 ~13 ~47 ~10 prismarine 0  
fill ~7 ~47 ~11 ~12 ~47 ~11 prismarine 0  
fill ~7 ~47 ~19 ~14 ~47 ~19 prismarine 0  
fill ~7 ~47 ~20 ~14 ~47 ~20 prismarine 0  
fill ~7 ~47 ~21 ~14 ~47 ~21 prismarine 0  
fill ~7 ~47 ~22 ~14 ~47 ~22 prismarine 0  
fill ~7 ~47 ~23 ~14 ~47 ~23 prismarine 0  
fill ~7 ~47 ~24 ~14 ~47 ~24 prismarine 0  
fill ~7 ~47 ~25 ~14 ~47 ~25 prismarine 0  
fill ~7 ~47 ~26 ~14 ~47 ~26 prismarine 0  
fill ~7 ~47 ~27 ~14 ~47 ~27 prismarine 0  
fill ~10 ~47 ~12 ~12 ~47 ~12 prismarine 0  
fill ~10 ~47 ~13 ~13 ~47 ~13 prismarine 0  
fill ~10 ~47 ~14 ~13 ~47 ~14 prismarine 0  
fill ~10 ~47 ~15 ~13 ~47 ~15 prismarine 0  
fill ~10 ~47 ~16 ~14 ~47 ~16 prismarine 0  
fill ~10 ~47 ~17 ~14 ~47 ~17 prismarine 0  
fill ~10 ~47 ~18 ~14 ~47 ~18 prismarine 0  
fill ~15 ~47 ~-4 ~20 ~47 ~-4 stained_hardened_clay 5  
fill ~15 ~47 ~-3 ~20 ~47 ~-3 stained_hardened_clay 5  
fill ~15 ~47 ~-2 ~16 ~47 ~-2 stained_hardened_clay 5  
fill ~15 ~47 ~-1 ~16 ~47 ~-1 stained_hardened_clay 5  
fill ~15 ~47 ~0 ~28 ~47 ~0 stained_hardened_clay 5  
fill ~15 ~47 ~1 ~28 ~47 ~1 stained_hardened_clay 5  
fill ~15 ~47 ~2 ~16 ~47 ~2 stained_hardened_clay 5  
fill ~15 ~47 ~3 ~18 ~47 ~3 stained_hardened_clay 5  
fill ~15 ~47 ~7 ~18 ~47 ~7 stained_hardened_clay 5  
fill ~15 ~47 ~8 ~18 ~47 ~8 stained_hardened_clay 13  
fill ~15 ~47 ~15 ~18 ~47 ~15 stained_hardened_clay 13  
fill ~15 ~47 ~20 ~20 ~47 ~20 stained_hardened_clay 13  
fill ~15 ~47 ~21 ~16 ~47 ~21 stained_hardened_clay 5  
fill ~15 ~47 ~22 ~28 ~47 ~22 stained_hardened_clay 5  
fill ~15 ~47 ~23 ~28 ~47 ~23 stained_hardened_clay 5  
fill ~15 ~47 ~24 ~16 ~47 ~24 stained_hardened_clay 5  
fill ~15 ~47 ~25 ~16 ~47 ~25 stained_hardened_clay 5  
fill ~15 ~47 ~26 ~24 ~47 ~26 stained_hardened_clay 5  
fill ~15 ~47 ~27 ~24 ~47 ~27 stained_hardened_clay 5  
fill ~16 ~47 ~16 ~18 ~47 ~16 stained_hardened_clay 5  
fill ~17 ~47 ~-2 ~20 ~47 ~-2 stained_hardened_clay 13  
fill ~17 ~47 ~-1 ~20 ~47 ~-1 stained_hardened_clay 13  
fill ~17 ~47 ~2 ~18 ~47 ~2 stained_hardened_clay 13  
fill ~17 ~47 ~5 ~17 ~49 ~5 stained_hardened_clay 5  
fill ~17 ~47 ~6 ~18 ~47 ~6 stained_hardened_clay 5  
fill ~17 ~47 ~17 ~18 ~47 ~17 stained_hardened_clay 5  
fill ~17 ~47 ~18 ~17 ~62 ~18 stained_hardened_clay 5  
fill ~17 ~47 ~21 ~18 ~47 ~21 stained_hardened_clay 13  
fill ~17 ~47 ~24 ~20 ~47 ~24 stained_hardened_clay 13  
fill ~17 ~47 ~25 ~20 ~47 ~25 stained_hardened_clay 13  
fill ~19 ~47 ~2 ~24 ~47 ~2 stained_hardened_clay 5  
fill ~19 ~47 ~3 ~24 ~47 ~3 stained_hardened_clay 13  
fill ~19 ~47 ~21 ~24 ~47 ~21 stained_hardened_clay 5 
setblock ~21 ~47 ~-3 stained_hardened_clay 13 
setblock ~21 ~47 ~-2 stained_hardened_clay 9 
setblock ~21 ~47 ~-1 stained_hardened_clay 5  
fill ~21 ~47 ~20 ~24 ~47 ~20 stained_hardened_clay 5  
fill ~21 ~47 ~24 ~29 ~47 ~24 stained_hardened_clay 5  
fill ~21 ~47 ~25 ~29 ~47 ~25 stained_hardened_clay 5 
setblock ~22 ~47 ~-2 stained_hardened_clay 13 
setblock ~22 ~47 ~-1 stained_hardened_clay 9 
setblock ~23 ~47 ~-2 stained_hardened_clay 9  
fill ~23 ~47 ~-1 ~29 ~47 ~-1 stained_hardened_clay 5  
fill ~24 ~47 ~-2 ~29 ~47 ~-2 stained_hardened_clay 5  
fill ~25 ~47 ~2 ~26 ~47 ~2 stained_hardened_clay 13  
fill ~25 ~47 ~3 ~29 ~47 ~3 stained_hardened_clay 5  
fill ~25 ~47 ~20 ~26 ~47 ~20 stained_hardened_clay 13  
fill ~25 ~47 ~21 ~26 ~47 ~21 stained_hardened_clay 13  
fill ~25 ~47 ~26 ~28 ~47 ~26 stained_hardened_clay 13  
fill ~25 ~47 ~27 ~28 ~47 ~27 stained_hardened_clay 13  
fill ~26 ~47 ~-3 ~28 ~47 ~-3 stained_hardened_clay 13  
fill ~27 ~47 ~-4 ~28 ~47 ~-4 stained_hardened_clay 13  
fill ~27 ~47 ~2 ~28 ~47 ~2 stained_hardened_clay 5  
fill ~27 ~47 ~20 ~28 ~47 ~20 stained_hardened_clay 5  
fill ~27 ~47 ~21 ~28 ~47 ~21 stained_hardened_clay 5  
fill ~29 ~47 ~-4 ~30 ~47 ~-4 stained_hardened_clay 5  
fill ~29 ~47 ~-3 ~30 ~47 ~-3 stained_hardened_clay 5  
fill ~29 ~47 ~0 ~30 ~47 ~0 stained_hardened_clay 13  
fill ~29 ~47 ~1 ~30 ~47 ~1 stained_hardened_clay 13  
fill ~29 ~47 ~2 ~29 ~47 ~0 stained_hardened_clay 13  
fill ~29 ~47 ~20 ~29 ~47 ~23 stained_hardened_clay 13  
fill ~29 ~47 ~26 ~30 ~47 ~26 stained_hardened_clay 5  
fill ~29 ~47 ~27 ~30 ~47 ~27 stained_hardened_clay 5  
fill ~30 ~47 ~21 ~30 ~47 ~25 stained_hardened_clay 13  
fill ~3 ~48 ~4 ~4 ~48 ~4 stained_hardened_clay 13  
fill ~3 ~48 ~5 ~3 ~63 ~5 stained_hardened_clay 13  
fill ~3 ~48 ~6 ~3 ~53 ~6 stained_hardened_clay 13  
fill ~3 ~48 ~7 ~3 ~53 ~7 stained_hardened_clay 13  
fill ~3 ~48 ~8 ~3 ~49 ~8 stained_hardened_clay 13  
fill ~3 ~48 ~9 ~3 ~49 ~9 stained_hardened_clay 13  
fill ~3 ~48 ~10 ~3 ~59 ~10 stained_hardened_clay 13  
fill ~3 ~48 ~11 ~3 ~59 ~11 stained_hardened_clay 13  
fill ~3 ~48 ~12 ~3 ~51 ~12 stained_hardened_clay 13  
fill ~3 ~48 ~13 ~3 ~51 ~13 stained_hardened_clay 13  
fill ~3 ~48 ~14 ~3 ~51 ~14 stained_hardened_clay 13  
fill ~3 ~48 ~15 ~3 ~51 ~15 stained_hardened_clay 13  
fill ~3 ~48 ~16 ~3 ~49 ~16 stained_hardened_clay 13  
fill ~3 ~48 ~17 ~3 ~49 ~17 stained_hardened_clay 13  
fill ~3 ~48 ~18 ~3 ~63 ~18 stained_hardened_clay 13  
fill ~3 ~48 ~19 ~4 ~48 ~19 stained_hardened_clay 13  
fill ~4 ~48 ~5 ~18 ~48 ~5 stained_hardened_clay 5  
fill ~4 ~48 ~6 ~18 ~48 ~6 stained_hardened_clay 5  
fill ~4 ~48 ~7 ~18 ~48 ~7 stained_hardened_clay 5  
fill ~4 ~48 ~8 ~17 ~48 ~8 stained_hardened_clay 5  
fill ~4 ~48 ~9 ~15 ~48 ~9 stained_hardened_clay 5  
fill ~4 ~48 ~10 ~14 ~48 ~10 stained_hardened_clay 5  
fill ~4 ~48 ~11 ~13 ~48 ~11 stained_hardened_clay 5  
fill ~4 ~48 ~12 ~13 ~48 ~12 stained_hardened_clay 5  
fill ~4 ~48 ~13 ~14 ~48 ~13 stained_hardened_clay 5  
fill ~4 ~48 ~14 ~15 ~48 ~14 stained_hardened_clay 5  
fill ~4 ~48 ~15 ~17 ~48 ~15 stained_hardened_clay 5  
fill ~4 ~48 ~16 ~18 ~48 ~16 stained_hardened_clay 5  
fill ~4 ~48 ~17 ~18 ~48 ~17 stained_hardened_clay 5  
fill ~4 ~48 ~18 ~18 ~48 ~18 stained_hardened_clay 5  
fill ~5 ~48 ~4 ~18 ~48 ~4 stained_hardened_clay 5  
fill ~5 ~48 ~19 ~18 ~48 ~19 stained_hardened_clay 5  
fill ~14 ~48 ~11 ~16 ~48 ~11 coal_block 0  
fill ~14 ~48 ~12 ~16 ~48 ~12 coal_block 0  
fill ~15 ~48 ~10 ~16 ~48 ~10 coal_block 0  
fill ~15 ~48 ~13 ~16 ~48 ~13 coal_block 0  
fill ~16 ~48 ~9 ~17 ~48 ~9 coal_block 0  
fill ~16 ~48 ~14 ~17 ~48 ~14 coal_block 0 
setblock ~17 ~48 ~10 stone_slab 15  
fill ~17 ~48 ~12 ~17 ~48 ~13 stone_slab 15 
setblock ~18 ~48 ~15 stained_hardened_clay 13  
fill ~3 ~49 ~4 ~4 ~49 ~4 stained_hardened_clay 13  
fill ~3 ~49 ~19 ~4 ~49 ~19 stained_hardened_clay 13  
fill ~4 ~49 ~5 ~18 ~49 ~5 stained_hardened_clay 5  
fill ~4 ~49 ~6 ~16 ~49 ~6 stained_hardened_clay 5  
fill ~4 ~49 ~7 ~16 ~49 ~7 stained_hardened_clay 5  
fill ~4 ~49 ~8 ~18 ~49 ~8 stained_hardened_clay 5  
fill ~4 ~49 ~9 ~17 ~49 ~9 stained_hardened_clay 5  
fill ~4 ~49 ~10 ~17 ~49 ~10 stained_hardened_clay 5  
fill ~4 ~49 ~11 ~17 ~49 ~11 stained_hardened_clay 5  
fill ~4 ~49 ~12 ~17 ~49 ~12 stained_hardened_clay 5  
fill ~4 ~49 ~13 ~17 ~49 ~13 stained_hardened_clay 5  
fill ~4 ~49 ~14 ~17 ~49 ~14 stained_hardened_clay 5  
fill ~4 ~49 ~15 ~18 ~49 ~15 stained_hardened_clay 5  
fill ~4 ~49 ~16 ~18 ~49 ~16 stained_hardened_clay 5  
fill ~4 ~49 ~17 ~18 ~49 ~17 stained_hardened_clay 5  
fill ~4 ~49 ~18 ~18 ~49 ~18 stained_hardened_clay 5  
fill ~5 ~49 ~4 ~18 ~49 ~4 stained_hardened_clay 5  
fill ~5 ~49 ~19 ~18 ~49 ~19 stained_hardened_clay 5  
fill ~17 ~49 ~6 ~17 ~49 ~7 nether_wart_block 0  
fill ~18 ~49 ~10 ~18 ~50 ~10 stained_hardened_clay 13  
fill ~18 ~49 ~11 ~18 ~50 ~11 stained_hardened_clay 13  
fill ~18 ~49 ~12 ~18 ~50 ~12 stained_hardened_clay 13  
fill ~18 ~49 ~13 ~18 ~50 ~13 stained_hardened_clay 13  
fill ~3 ~50 ~4 ~10 ~50 ~4 stained_hardened_clay 13  
fill ~3 ~50 ~8 ~16 ~50 ~8 stained_hardened_clay 5  
fill ~3 ~50 ~9 ~18 ~50 ~9 stained_hardened_clay 5  
fill ~3 ~50 ~16 ~18 ~50 ~16 stained_hardened_clay 5  
fill ~3 ~50 ~17 ~18 ~50 ~17 stained_hardened_clay 5  
fill ~3 ~50 ~19 ~10 ~50 ~19 stained_hardened_clay 13  
fill ~4 ~50 ~5 ~16 ~50 ~5 stained_hardened_clay 5  
fill ~4 ~50 ~6 ~15 ~50 ~6 stained_hardened_clay 5  
fill ~4 ~50 ~7 ~15 ~50 ~7 stained_hardened_clay 5  
fill ~4 ~50 ~10 ~17 ~50 ~10 stained_hardened_clay 5  
fill ~4 ~50 ~11 ~17 ~50 ~11 stained_hardened_clay 5  
fill ~4 ~50 ~12 ~17 ~50 ~12 stained_hardened_clay 5  
fill ~4 ~50 ~13 ~17 ~50 ~13 stained_hardened_clay 5  
fill ~4 ~50 ~14 ~18 ~50 ~14 stained_hardened_clay 5  
fill ~4 ~50 ~15 ~18 ~50 ~15 stained_hardened_clay 5  
fill ~4 ~50 ~18 ~18 ~50 ~18 stained_hardened_clay 5  
fill ~11 ~50 ~4 ~18 ~50 ~4 stained_hardened_clay 5  
fill ~11 ~50 ~19 ~18 ~50 ~19 stained_hardened_clay 5  
fill ~16 ~50 ~6 ~16 ~51 ~6 stained_hardened_clay 8  
fill ~16 ~50 ~7 ~16 ~50 ~6 stained_hardened_clay 8  
fill ~17 ~50 ~5 ~17 ~52 ~5 nether_wart_block 0 
setblock ~17 ~50 ~8 nether_wart_block 0  
fill ~3 ~51 ~4 ~10 ~51 ~4 stained_hardened_clay 13  
fill ~3 ~51 ~8 ~18 ~51 ~8 stained_hardened_clay 5  
fill ~3 ~51 ~9 ~18 ~51 ~9 stained_hardened_clay 5  
fill ~3 ~51 ~16 ~18 ~51 ~16 stained_hardened_clay 5  
fill ~3 ~51 ~17 ~18 ~51 ~17 stained_hardened_clay 5  
fill ~3 ~51 ~19 ~10 ~51 ~19 stained_hardened_clay 13  
fill ~4 ~51 ~5 ~16 ~51 ~5 stained_hardened_clay 5  
fill ~4 ~51 ~6 ~15 ~51 ~6 stained_hardened_clay 5  
fill ~4 ~51 ~7 ~16 ~51 ~7 stained_hardened_clay 5  
fill ~4 ~51 ~10 ~18 ~51 ~10 stained_hardened_clay 5  
fill ~4 ~51 ~11 ~18 ~51 ~11 stained_hardened_clay 5  
fill ~4 ~51 ~12 ~18 ~51 ~12 stained_hardened_clay 5  
fill ~4 ~51 ~13 ~18 ~51 ~13 stained_hardened_clay 5  
fill ~4 ~51 ~14 ~18 ~51 ~14 stained_hardened_clay 5  
fill ~4 ~51 ~15 ~18 ~51 ~15 stained_hardened_clay 5  
fill ~4 ~51 ~18 ~18 ~51 ~18 stained_hardened_clay 5  
fill ~11 ~51 ~4 ~18 ~51 ~4 stained_hardened_clay 5  
fill ~11 ~51 ~19 ~18 ~51 ~19 stained_hardened_clay 5 
setblock ~16 ~51 ~3 nether_wart_block 0  
fill ~17 ~51 ~7 ~17 ~52 ~7 nether_wart_block 0  
fill ~3 ~52 ~4 ~14 ~52 ~4 stained_hardened_clay 13  
fill ~3 ~52 ~8 ~3 ~57 ~8 stained_hardened_clay 13  
fill ~3 ~52 ~9 ~3 ~57 ~9 stained_hardened_clay 13  
fill ~3 ~52 ~12 ~17 ~52 ~12 stained_hardened_clay 5  
fill ~3 ~52 ~13 ~17 ~52 ~13 stained_hardened_clay 5  
fill ~3 ~52 ~14 ~18 ~52 ~14 stained_hardened_clay 5  
fill ~3 ~52 ~15 ~18 ~52 ~15 stained_hardened_clay 5  
fill ~3 ~52 ~16 ~18 ~52 ~16 stained_hardened_clay 5  
fill ~3 ~52 ~17 ~18 ~52 ~17 stained_hardened_clay 5  
fill ~3 ~52 ~19 ~14 ~52 ~19 stained_hardened_clay 13  
fill ~4 ~52 ~5 ~16 ~52 ~5 stained_hardened_clay 5  
fill ~4 ~52 ~6 ~18 ~52 ~6 stained_hardened_clay 5  
fill ~4 ~52 ~7 ~16 ~52 ~7 stained_hardened_clay 5  
fill ~4 ~52 ~8 ~18 ~52 ~8 stained_hardened_clay 5  
fill ~4 ~52 ~9 ~18 ~52 ~9 stained_hardened_clay 5  
fill ~4 ~52 ~10 ~17 ~52 ~10 stained_hardened_clay 5  
fill ~4 ~52 ~11 ~17 ~52 ~11 stained_hardened_clay 5  
fill ~4 ~52 ~18 ~18 ~52 ~18 stained_hardened_clay 5  
fill ~15 ~52 ~4 ~18 ~52 ~4 stained_hardened_clay 5  
fill ~15 ~52 ~19 ~18 ~52 ~19 stained_hardened_clay 5  
fill ~18 ~52 ~10 ~18 ~53 ~10 stained_hardened_clay 13  
fill ~18 ~52 ~11 ~18 ~53 ~11 stained_hardened_clay 13  
fill ~18 ~52 ~12 ~18 ~53 ~12 stained_hardened_clay 13  
fill ~18 ~52 ~13 ~18 ~53 ~13 stained_hardened_clay 13  
fill ~3 ~53 ~4 ~14 ~53 ~4 stained_hardened_clay 13  
fill ~3 ~53 ~12 ~17 ~53 ~12 stained_hardened_clay 5  
fill ~3 ~53 ~13 ~17 ~53 ~13 stained_hardened_clay 5  
fill ~3 ~53 ~14 ~18 ~53 ~14 stained_hardened_clay 5  
fill ~3 ~53 ~15 ~18 ~53 ~15 stained_hardened_clay 5  
fill ~3 ~53 ~16 ~18 ~53 ~16 stained_hardened_clay 5  
fill ~3 ~53 ~17 ~18 ~53 ~17 stained_hardened_clay 5  
fill ~3 ~53 ~19 ~14 ~53 ~19 stained_hardened_clay 13  
fill ~4 ~53 ~5 ~18 ~53 ~5 stained_hardened_clay 5  
fill ~4 ~53 ~6 ~18 ~53 ~6 stained_hardened_clay 5  
fill ~4 ~53 ~7 ~18 ~53 ~7 stained_hardened_clay 5  
fill ~4 ~53 ~8 ~18 ~53 ~8 stained_hardened_clay 5  
fill ~4 ~53 ~9 ~18 ~53 ~9 stained_hardened_clay 5  
fill ~4 ~53 ~10 ~17 ~53 ~10 stained_hardened_clay 5  
fill ~4 ~53 ~11 ~17 ~53 ~11 stained_hardened_clay 5  
fill ~4 ~53 ~18 ~18 ~53 ~18 stained_hardened_clay 5  
fill ~15 ~53 ~4 ~18 ~53 ~4 stained_hardened_clay 5  
fill ~15 ~53 ~19 ~18 ~53 ~19 stained_hardened_clay 5  
fill ~3 ~54 ~4 ~14 ~54 ~4 stained_hardened_clay 13  
fill ~3 ~54 ~6 ~17 ~54 ~6 stained_hardened_clay 5  
fill ~3 ~54 ~7 ~16 ~54 ~7 stained_hardened_clay 5  
fill ~3 ~54 ~12 ~3 ~63 ~12 stained_hardened_clay 13  
fill ~3 ~54 ~13 ~3 ~63 ~13 stained_hardened_clay 13  
fill ~3 ~54 ~14 ~17 ~54 ~14 stained_hardened_clay 5  
fill ~3 ~54 ~15 ~16 ~54 ~15 stained_hardened_clay 5  
fill ~3 ~54 ~16 ~16 ~54 ~16 stained_hardened_clay 5  
fill ~3 ~54 ~17 ~17 ~54 ~17 stained_hardened_clay 5  
fill ~3 ~54 ~19 ~14 ~54 ~19 stained_hardened_clay 13  
fill ~4 ~54 ~5 ~18 ~54 ~5 stained_hardened_clay 5  
fill ~4 ~54 ~8 ~16 ~54 ~8 stained_hardened_clay 5  
fill ~4 ~54 ~9 ~17 ~54 ~9 stained_hardened_clay 5  
fill ~4 ~54 ~10 ~18 ~54 ~10 stained_hardened_clay 5  
fill ~4 ~54 ~11 ~18 ~54 ~11 stained_hardened_clay 5  
fill ~4 ~54 ~12 ~18 ~54 ~12 stained_hardened_clay 5  
fill ~4 ~54 ~13 ~18 ~54 ~13 stained_hardened_clay 5  
fill ~4 ~54 ~18 ~18 ~54 ~18 stained_hardened_clay 5  
fill ~15 ~54 ~4 ~18 ~54 ~4 stained_hardened_clay 5  
fill ~15 ~54 ~19 ~18 ~54 ~19 stained_hardened_clay 5 
setblock ~16 ~54 ~3 nether_wart_block 0  
fill ~17 ~54 ~7 ~17 ~54 ~8 glowstone 0  
fill ~17 ~54 ~15 ~17 ~54 ~16 glowstone 0  
fill ~18 ~54 ~6 ~18 ~55 ~6 coal_block 0  
fill ~18 ~54 ~7 ~18 ~54 ~8 stained_glass 14  
fill ~18 ~54 ~9 ~18 ~55 ~9 coal_block 0  
fill ~18 ~54 ~14 ~18 ~55 ~14 coal_block 0  
fill ~18 ~54 ~15 ~18 ~54 ~16 stained_glass 14  
fill ~18 ~54 ~17 ~18 ~55 ~17 coal_block 0  
fill ~3 ~55 ~4 ~14 ~55 ~4 stained_hardened_clay 13  
fill ~3 ~55 ~6 ~17 ~55 ~6 stained_hardened_clay 5  
fill ~3 ~55 ~7 ~17 ~55 ~7 stained_hardened_clay 5  
fill ~3 ~55 ~14 ~17 ~55 ~14 stained_hardened_clay 5  
fill ~3 ~55 ~15 ~17 ~55 ~15 stained_hardened_clay 5  
fill ~3 ~55 ~16 ~17 ~55 ~16 stained_hardened_clay 5  
fill ~3 ~55 ~17 ~17 ~55 ~17 stained_hardened_clay 5  
fill ~3 ~55 ~19 ~14 ~55 ~19 stained_hardened_clay 13  
fill ~4 ~55 ~5 ~18 ~55 ~5 stained_hardened_clay 5  
fill ~4 ~55 ~8 ~17 ~55 ~8 stained_hardened_clay 5  
fill ~4 ~55 ~9 ~17 ~55 ~9 stained_hardened_clay 5  
fill ~4 ~55 ~10 ~18 ~55 ~10 stained_hardened_clay 5  
fill ~4 ~55 ~11 ~16 ~55 ~11 stained_hardened_clay 5  
fill ~4 ~55 ~12 ~18 ~55 ~12 stained_hardened_clay 5  
fill ~4 ~55 ~13 ~18 ~55 ~13 stained_hardened_clay 5  
fill ~4 ~55 ~18 ~18 ~55 ~18 stained_hardened_clay 5  
fill ~15 ~55 ~4 ~18 ~55 ~4 stained_hardened_clay 5  
fill ~15 ~55 ~19 ~18 ~55 ~19 stained_hardened_clay 5 
setblock ~17 ~55 ~11 stained_hardened_clay 8  
fill ~18 ~55 ~7 ~18 ~55 ~9 coal_block 0  
fill ~18 ~55 ~15 ~18 ~55 ~17 coal_block 0  
fill ~3 ~56 ~4 ~14 ~56 ~4 stained_hardened_clay 13  
fill ~3 ~56 ~6 ~18 ~56 ~6 stained_hardened_clay 5  
fill ~3 ~56 ~7 ~18 ~56 ~7 stained_hardened_clay 5  
fill ~3 ~56 ~14 ~3 ~63 ~14 stained_hardened_clay 13  
fill ~3 ~56 ~15 ~3 ~63 ~15 stained_hardened_clay 13  
fill ~3 ~56 ~16 ~18 ~56 ~16 stained_hardened_clay 5  
fill ~3 ~56 ~17 ~18 ~56 ~17 stained_hardened_clay 5  
fill ~3 ~56 ~19 ~14 ~56 ~19 stained_hardened_clay 13  
fill ~4 ~56 ~5 ~18 ~56 ~5 stained_hardened_clay 5  
fill ~4 ~56 ~8 ~18 ~56 ~8 stained_hardened_clay 5  
fill ~4 ~56 ~9 ~18 ~56 ~9 stained_hardened_clay 5  
fill ~4 ~56 ~10 ~18 ~56 ~10 stained_hardened_clay 5  
fill ~4 ~56 ~11 ~18 ~56 ~11 stained_hardened_clay 5  
fill ~4 ~56 ~12 ~16 ~56 ~12 stained_hardened_clay 5  
fill ~4 ~56 ~13 ~16 ~56 ~13 stained_hardened_clay 5  
fill ~4 ~56 ~14 ~16 ~56 ~14 stained_hardened_clay 5  
fill ~4 ~56 ~15 ~18 ~56 ~15 stained_hardened_clay 5  
fill ~4 ~56 ~18 ~18 ~56 ~18 stained_hardened_clay 5  
fill ~15 ~56 ~4 ~18 ~56 ~4 stained_hardened_clay 5  
fill ~15 ~56 ~19 ~18 ~56 ~19 stained_hardened_clay 5  
fill ~16 ~56 ~3 ~16 ~59 ~3 nether_wart_block 0  
fill ~17 ~56 ~12 ~17 ~56 ~14 nether_wart_block 0 
setblock ~18 ~56 ~14 stained_hardened_clay 5  
fill ~3 ~57 ~4 ~14 ~57 ~4 stained_hardened_clay 13  
fill ~3 ~57 ~6 ~18 ~57 ~6 stained_hardened_clay 5  
fill ~3 ~57 ~7 ~18 ~57 ~7 stained_hardened_clay 5  
fill ~3 ~57 ~16 ~18 ~57 ~16 stained_hardened_clay 5  
fill ~3 ~57 ~17 ~18 ~57 ~17 stained_hardened_clay 5  
fill ~3 ~57 ~19 ~14 ~57 ~19 stained_hardened_clay 13  
fill ~4 ~57 ~5 ~18 ~57 ~5 stained_hardened_clay 5  
fill ~4 ~57 ~8 ~18 ~57 ~8 stained_hardened_clay 5  
fill ~4 ~57 ~9 ~18 ~57 ~9 stained_hardened_clay 5  
fill ~4 ~57 ~10 ~18 ~57 ~10 stained_hardened_clay 5  
fill ~4 ~57 ~11 ~18 ~57 ~11 stained_hardened_clay 5  
fill ~4 ~57 ~12 ~18 ~57 ~12 stained_hardened_clay 5  
fill ~4 ~57 ~13 ~16 ~57 ~13 stained_hardened_clay 5  
fill ~4 ~57 ~14 ~15 ~57 ~14 stained_hardened_clay 5  
fill ~4 ~57 ~15 ~16 ~57 ~15 stained_hardened_clay 5  
fill ~4 ~57 ~18 ~18 ~57 ~18 stained_hardened_clay 5  
fill ~15 ~57 ~4 ~18 ~57 ~4 stained_hardened_clay 5  
fill ~15 ~57 ~19 ~18 ~57 ~19 stained_hardened_clay 5 
setblock ~16 ~57 ~14 stained_hardened_clay 8 
setblock ~17 ~57 ~13 nether_wart_block 0 
setblock ~17 ~57 ~15 nether_wart_block 0  
fill ~3 ~58 ~4 ~18 ~58 ~4 stained_hardened_clay 13  
fill ~3 ~58 ~6 ~18 ~58 ~6 stained_hardened_clay 5  
fill ~3 ~58 ~7 ~18 ~58 ~7 stained_hardened_clay 5  
fill ~3 ~58 ~8 ~18 ~58 ~8 stained_hardened_clay 5  
fill ~3 ~58 ~9 ~18 ~58 ~9 stained_hardened_clay 5  
fill ~3 ~58 ~16 ~3 ~63 ~16 stained_hardened_clay 13  
fill ~3 ~58 ~17 ~3 ~63 ~17 stained_hardened_clay 13  
fill ~3 ~58 ~19 ~18 ~58 ~19 stained_hardened_clay 13  
fill ~4 ~58 ~5 ~18 ~58 ~5 stained_hardened_clay 5  
fill ~4 ~58 ~10 ~18 ~58 ~10 stained_hardened_clay 5  
fill ~4 ~58 ~11 ~18 ~58 ~11 stained_hardened_clay 5  
fill ~4 ~58 ~12 ~18 ~58 ~12 stained_hardened_clay 5  
fill ~4 ~58 ~13 ~18 ~58 ~13 stained_hardened_clay 5  
fill ~4 ~58 ~14 ~16 ~58 ~14 stained_hardened_clay 5  
fill ~4 ~58 ~15 ~15 ~58 ~15 stained_hardened_clay 5  
fill ~4 ~58 ~16 ~16 ~58 ~16 stained_hardened_clay 5  
fill ~4 ~58 ~17 ~18 ~58 ~17 stained_hardened_clay 5  
fill ~4 ~58 ~18 ~17 ~58 ~18 stained_hardened_clay 5 
setblock ~16 ~58 ~15 stained_hardened_clay 8 
setblock ~17 ~58 ~14 nether_wart_block 0 
setblock ~17 ~58 ~16 nether_wart_block 0  
fill ~18 ~58 ~14 ~18 ~59 ~14 stained_hardened_clay 5  
fill ~18 ~58 ~18 ~18 ~63 ~18 stained_hardened_clay 13  
fill ~19 ~58 ~6 ~19 ~60 ~6 nether_wart_block 0  
fill ~3 ~59 ~4 ~18 ~59 ~4 stained_hardened_clay 13  
fill ~3 ~59 ~6 ~18 ~59 ~6 stained_hardened_clay 5  
fill ~3 ~59 ~7 ~18 ~59 ~7 stained_hardened_clay 5  
fill ~3 ~59 ~8 ~18 ~59 ~8 stained_hardened_clay 5  
fill ~3 ~59 ~9 ~18 ~59 ~9 stained_hardened_clay 5  
fill ~3 ~59 ~19 ~18 ~59 ~19 stained_hardened_clay 13  
fill ~4 ~59 ~5 ~18 ~59 ~5 stained_hardened_clay 5  
fill ~4 ~59 ~10 ~18 ~59 ~10 stained_hardened_clay 5  
fill ~4 ~59 ~11 ~18 ~59 ~11 stained_hardened_clay 5  
fill ~4 ~59 ~12 ~18 ~59 ~12 stained_hardened_clay 5  
fill ~4 ~59 ~13 ~18 ~59 ~13 stained_hardened_clay 5  
fill ~4 ~59 ~14 ~18 ~59 ~14 stained_hardened_clay 5  
fill ~4 ~59 ~15 ~18 ~59 ~15 stained_hardened_clay 5  
fill ~4 ~59 ~16 ~18 ~59 ~16 stained_hardened_clay 5  
fill ~4 ~59 ~17 ~16 ~59 ~17 stained_hardened_clay 5  
fill ~4 ~59 ~18 ~17 ~59 ~18 stained_hardened_clay 5 
setblock ~17 ~59 ~17 nether_wart_block 0  
fill ~3 ~60 ~4 ~15 ~60 ~4 stained_hardened_clay 13  
fill ~3 ~60 ~6 ~3 ~63 ~6 stained_hardened_clay 13  
fill ~3 ~60 ~7 ~3 ~63 ~7 stained_hardened_clay 13  
fill ~3 ~60 ~8 ~18 ~60 ~8 stained_hardened_clay 5  
fill ~3 ~60 ~9 ~18 ~60 ~9 stained_hardened_clay 5  
fill ~3 ~60 ~10 ~18 ~60 ~10 stained_hardened_clay 5  
fill ~3 ~60 ~11 ~18 ~60 ~11 stained_hardened_clay 5  
fill ~3 ~60 ~19 ~18 ~60 ~19 stained_hardened_clay 13  
fill ~4 ~60 ~5 ~14 ~60 ~5 stained_hardened_clay 5  
fill ~4 ~60 ~6 ~16 ~60 ~6 stained_hardened_clay 5  
fill ~4 ~60 ~7 ~16 ~60 ~7 stained_hardened_clay 5  
fill ~4 ~60 ~12 ~17 ~60 ~12 stained_hardened_clay 5  
fill ~4 ~60 ~13 ~17 ~60 ~13 stained_hardened_clay 5  
fill ~4 ~60 ~14 ~17 ~60 ~14 stained_hardened_clay 5  
fill ~4 ~60 ~15 ~17 ~60 ~15 stained_hardened_clay 5  
fill ~4 ~60 ~16 ~17 ~60 ~16 stained_hardened_clay 5  
fill ~4 ~60 ~17 ~17 ~60 ~17 stained_hardened_clay 5  
fill ~4 ~60 ~18 ~17 ~60 ~18 stained_hardened_clay 5  
fill ~15 ~60 ~5 ~17 ~60 ~5 bone_block 0 
setblock ~16 ~60 ~4 nether_wart_block 0  
fill ~17 ~60 ~6 ~17 ~60 ~7 bone_block 0  
fill ~18 ~60 ~5 ~18 ~60 ~7 stained_hardened_clay 13  
fill ~18 ~60 ~12 ~18 ~63 ~12 stained_hardened_clay 13  
fill ~18 ~60 ~13 ~18 ~63 ~13 stained_hardened_clay 13  
fill ~18 ~60 ~14 ~18 ~63 ~14 stained_hardened_clay 13  
fill ~18 ~60 ~15 ~18 ~63 ~15 stained_hardened_clay 13  
fill ~18 ~60 ~16 ~18 ~63 ~16 stained_hardened_clay 13  
fill ~18 ~60 ~17 ~18 ~63 ~17 stained_hardened_clay 13  
fill ~3 ~61 ~4 ~14 ~61 ~4 stained_hardened_clay 13  
fill ~3 ~61 ~8 ~15 ~61 ~8 stained_hardened_clay 5  
fill ~3 ~61 ~9 ~18 ~61 ~9 stained_hardened_clay 5  
fill ~3 ~61 ~10 ~18 ~61 ~10 stained_hardened_clay 5  
fill ~3 ~61 ~11 ~18 ~61 ~11 stained_hardened_clay 5  
fill ~3 ~61 ~19 ~18 ~61 ~19 stained_hardened_clay 13  
fill ~4 ~61 ~5 ~13 ~61 ~5 stained_hardened_clay 5  
fill ~4 ~61 ~6 ~14 ~61 ~6 stained_hardened_clay 5  
fill ~4 ~61 ~7 ~15 ~61 ~7 stained_hardened_clay 5  
fill ~4 ~61 ~12 ~17 ~61 ~12 stained_hardened_clay 5  
fill ~4 ~61 ~13 ~17 ~61 ~13 stained_hardened_clay 5  
fill ~4 ~61 ~14 ~17 ~61 ~14 stained_hardened_clay 5  
fill ~4 ~61 ~15 ~17 ~61 ~15 stained_hardened_clay 5  
fill ~4 ~61 ~16 ~17 ~61 ~16 stained_hardened_clay 5  
fill ~4 ~61 ~17 ~17 ~61 ~17 stained_hardened_clay 5  
fill ~4 ~61 ~18 ~17 ~61 ~18 stained_hardened_clay 5 
setblock ~14 ~61 ~5 bone_block 0  
fill ~15 ~61 ~5 ~16 ~61 ~5 nether_wart_block 0  
fill ~15 ~61 ~6 ~16 ~61 ~6 stained_hardened_clay 14  
fill ~16 ~61 ~7 ~16 ~61 ~8 stained_hardened_clay 14 
setblock ~17 ~61 ~7 nether_wart_block 0 
setblock ~17 ~61 ~8 bone_block 0 
setblock ~18 ~61 ~6 nether_wart_block 0 
setblock ~18 ~61 ~7 stained_hardened_clay 13 
setblock ~18 ~61 ~8 stained_hardened_clay 5  
fill ~3 ~62 ~4 ~14 ~62 ~4 stained_hardened_clay 13  
fill ~3 ~62 ~8 ~3 ~63 ~8 stained_hardened_clay 13  
fill ~3 ~62 ~9 ~3 ~63 ~9 stained_hardened_clay 13  
fill ~3 ~62 ~10 ~3 ~63 ~10 stained_hardened_clay 13  
fill ~3 ~62 ~11 ~3 ~63 ~11 stained_hardened_clay 13  
fill ~3 ~62 ~19 ~18 ~62 ~19 stained_hardened_clay 13  
fill ~4 ~62 ~5 ~13 ~62 ~5 stained_hardened_clay 5  
fill ~4 ~62 ~6 ~13 ~62 ~6 stained_hardened_clay 5  
fill ~4 ~62 ~7 ~13 ~62 ~7 stained_hardened_clay 5  
fill ~4 ~62 ~8 ~15 ~62 ~8 stained_hardened_clay 5  
fill ~4 ~62 ~9 ~17 ~62 ~9 stained_hardened_clay 5  
fill ~4 ~62 ~10 ~17 ~62 ~10 stained_hardened_clay 5  
fill ~4 ~62 ~11 ~17 ~62 ~11 stained_hardened_clay 5  
fill ~4 ~62 ~12 ~17 ~62 ~12 stained_hardened_clay 5  
fill ~4 ~62 ~13 ~17 ~62 ~13 stained_hardened_clay 5  
fill ~4 ~62 ~14 ~17 ~62 ~14 stained_hardened_clay 5  
fill ~4 ~62 ~15 ~17 ~62 ~15 stained_hardened_clay 5  
fill ~4 ~62 ~16 ~17 ~62 ~16 stained_hardened_clay 5  
fill ~4 ~62 ~17 ~17 ~62 ~17 stained_hardened_clay 5  
fill ~4 ~62 ~18 ~17 ~62 ~18 stained_hardened_clay 5  
fill ~14 ~62 ~6 ~14 ~62 ~7 stained_hardened_clay 14 
setblock ~15 ~62 ~7 stained_hardened_clay 14 
setblock ~16 ~62 ~8 stained_hardened_clay 14  
fill ~18 ~62 ~8 ~18 ~62 ~19 stained_hardened_clay 13 
setblock ~-5 ~63 ~29 wool 11  
fill ~3 ~63 ~4 ~13 ~63 ~4 stained_hardened_clay 13  
fill ~3 ~63 ~19 ~18 ~63 ~19 stained_hardened_clay 13  
fill ~4 ~63 ~5 ~13 ~63 ~5 stained_hardened_clay 13  
fill ~4 ~63 ~6 ~13 ~63 ~6 stained_hardened_clay 13  
fill ~4 ~63 ~7 ~13 ~63 ~7 stained_hardened_clay 13  
fill ~4 ~63 ~8 ~17 ~63 ~8 stained_hardened_clay 13  
fill ~4 ~63 ~9 ~18 ~63 ~9 stained_hardened_clay 13  
fill ~4 ~63 ~10 ~18 ~63 ~10 stained_hardened_clay 13  
fill ~4 ~63 ~11 ~18 ~63 ~11 stained_hardened_clay 13  
fill ~4 ~63 ~12 ~18 ~63 ~12 stained_hardened_clay 13  
fill ~4 ~63 ~13 ~18 ~63 ~13 stained_hardened_clay 13  
fill ~4 ~63 ~14 ~18 ~63 ~14 stained_hardened_clay 13  
fill ~4 ~63 ~15 ~18 ~63 ~15 stained_hardened_clay 13  
fill ~4 ~63 ~16 ~18 ~63 ~16 stained_hardened_clay 13  
fill ~4 ~63 ~17 ~18 ~63 ~17 stained_hardened_clay 13  
fill ~4 ~63 ~18 ~18 ~63 ~18 stained_hardened_clay 13 
setblock ~15 ~63 ~7 stained_hardened_clay 13    