fill ~1 ~0 ~8 ~1 ~34 ~8 log 1  
fill ~1 ~0 ~9 ~1 ~3 ~9 log 1  
fill ~1 ~0 ~10 ~1 ~3 ~10 log 1  
fill ~1 ~0 ~11 ~1 ~3 ~11 log 1  
fill ~1 ~0 ~12 ~1 ~3 ~12 log 1  
fill ~1 ~0 ~13 ~1 ~3 ~13 log 1  
fill ~1 ~0 ~14 ~1 ~34 ~14 log 1  
fill ~1 ~0 ~15 ~1 ~3 ~15 log 1  
fill ~1 ~0 ~16 ~1 ~3 ~16 log 1  
fill ~1 ~0 ~17 ~1 ~3 ~17 log 1  
fill ~1 ~0 ~18 ~1 ~3 ~18 log 1  
fill ~1 ~0 ~19 ~1 ~3 ~19 log 1  
fill ~1 ~0 ~20 ~1 ~34 ~20 log 1  
fill ~1 ~0 ~21 ~1 ~3 ~21 log 1  
fill ~1 ~0 ~22 ~1 ~3 ~22 log 1  
fill ~1 ~0 ~23 ~1 ~3 ~23 log 1  
fill ~1 ~0 ~24 ~1 ~3 ~24 log 1  
fill ~1 ~0 ~25 ~1 ~3 ~25 log 1  
fill ~1 ~0 ~26 ~1 ~3 ~26 log 1  
fill ~1 ~0 ~27 ~1 ~3 ~27 log 1  
fill ~1 ~0 ~28 ~1 ~3 ~28 log 1  
fill ~1 ~0 ~29 ~1 ~34 ~29 log 1  
fill ~1 ~0 ~30 ~1 ~3 ~30 log 1  
fill ~1 ~0 ~31 ~1 ~3 ~31 log 1  
fill ~1 ~0 ~32 ~1 ~3 ~32 log 1  
fill ~1 ~0 ~33 ~1 ~3 ~33 log 1  
fill ~1 ~0 ~34 ~1 ~3 ~34 log 1  
fill ~1 ~0 ~35 ~1 ~34 ~35 log 1  
fill ~1 ~0 ~36 ~1 ~3 ~36 log 1  
fill ~1 ~0 ~37 ~1 ~3 ~37 log 1  
fill ~1 ~0 ~38 ~1 ~3 ~38 log 1  
fill ~1 ~0 ~39 ~1 ~3 ~39 log 1  
fill ~1 ~0 ~40 ~1 ~3 ~40 log 1  
fill ~1 ~0 ~41 ~1 ~35 ~41 log 1  
fill ~1 ~0 ~42 ~1 ~1 ~42 log 1  
fill ~1 ~0 ~43 ~1 ~1 ~43 log 1  
fill ~1 ~0 ~44 ~1 ~1 ~44 log 1  
fill ~1 ~0 ~45 ~1 ~1 ~45 log 1  
fill ~1 ~0 ~46 ~1 ~1 ~46 log 1  
fill ~1 ~0 ~47 ~1 ~3 ~47 log 1  
fill ~1 ~0 ~48 ~1 ~1 ~48 log 1  
fill ~1 ~0 ~49 ~1 ~1 ~49 log 1  
fill ~1 ~0 ~50 ~1 ~1 ~50 log 1  
fill ~1 ~0 ~51 ~1 ~1 ~51 log 1  
fill ~1 ~0 ~52 ~1 ~1 ~52 log 1  
fill ~1 ~0 ~53 ~1 ~2 ~53 log 1  
fill ~1 ~0 ~54 ~1 ~1 ~54 planks 5  
fill ~1 ~0 ~55 ~1 ~1 ~55 planks 5  
fill ~1 ~0 ~56 ~1 ~1 ~56 planks 5  
fill ~1 ~0 ~57 ~1 ~1 ~57 planks 5  
fill ~1 ~0 ~58 ~1 ~1 ~58 planks 5  
fill ~1 ~0 ~59 ~1 ~1 ~59 planks 5  
fill ~1 ~0 ~60 ~1 ~1 ~60 planks 5  
fill ~1 ~0 ~61 ~1 ~1 ~61 planks 5  
fill ~1 ~0 ~62 ~1 ~1 ~62 planks 5  
fill ~1 ~0 ~63 ~1 ~1 ~63 planks 5  
fill ~1 ~0 ~64 ~1 ~1 ~64 planks 5  
fill ~1 ~0 ~65 ~1 ~2 ~65 log 1  
fill ~1 ~0 ~66 ~1 ~1 ~66 log 1  
fill ~1 ~0 ~67 ~1 ~1 ~67 log 1  
fill ~1 ~0 ~68 ~1 ~1 ~68 log 1  
fill ~1 ~0 ~69 ~1 ~1 ~69 log 1  
fill ~1 ~0 ~70 ~1 ~1 ~70 log 1  
fill ~1 ~0 ~71 ~1 ~3 ~71 log 1  
fill ~1 ~0 ~72 ~1 ~1 ~72 log 1  
fill ~1 ~0 ~73 ~1 ~1 ~73 log 1  
fill ~1 ~0 ~74 ~1 ~1 ~74 log 1  
fill ~1 ~0 ~75 ~1 ~1 ~75 log 1  
fill ~1 ~0 ~76 ~1 ~1 ~76 log 1  
fill ~1 ~0 ~77 ~1 ~35 ~77 log 1  
fill ~1 ~0 ~78 ~1 ~3 ~78 log 1  
fill ~1 ~0 ~79 ~1 ~3 ~79 log 1  
fill ~1 ~0 ~80 ~1 ~3 ~80 log 1  
fill ~1 ~0 ~81 ~1 ~3 ~81 log 1  
fill ~1 ~0 ~82 ~1 ~3 ~82 log 1  
fill ~1 ~0 ~83 ~1 ~34 ~83 log 1  
fill ~1 ~0 ~84 ~1 ~3 ~84 log 1  
fill ~1 ~0 ~85 ~1 ~3 ~85 log 1  
fill ~1 ~0 ~86 ~1 ~3 ~86 log 1  
fill ~1 ~0 ~87 ~1 ~3 ~87 log 1  
fill ~1 ~0 ~88 ~1 ~3 ~88 log 1  
fill ~1 ~0 ~89 ~1 ~34 ~89 log 1  
fill ~1 ~0 ~90 ~1 ~3 ~90 log 1  
fill ~1 ~0 ~91 ~1 ~3 ~91 log 1  
fill ~1 ~0 ~92 ~1 ~3 ~92 log 1  
fill ~1 ~0 ~93 ~1 ~3 ~93 log 1  
fill ~1 ~0 ~94 ~1 ~3 ~94 log 1  
fill ~1 ~0 ~95 ~1 ~3 ~95 log 1  
fill ~1 ~0 ~96 ~1 ~3 ~96 log 1  
fill ~1 ~0 ~97 ~1 ~3 ~97 log 1  
fill ~1 ~0 ~98 ~1 ~34 ~98 log 1  
fill ~1 ~0 ~99 ~1 ~3 ~99 log 1  
fill ~1 ~0 ~100 ~1 ~3 ~100 log 1  
fill ~1 ~0 ~101 ~1 ~3 ~101 log 1  
fill ~1 ~0 ~102 ~1 ~3 ~102 log 1  
fill ~1 ~0 ~103 ~1 ~3 ~103 log 1  
fill ~1 ~0 ~104 ~1 ~34 ~104 log 1  
fill ~1 ~0 ~105 ~1 ~3 ~105 log 1  
fill ~1 ~0 ~106 ~1 ~3 ~106 log 1  
fill ~1 ~0 ~107 ~1 ~3 ~107 log 1  
fill ~1 ~0 ~108 ~1 ~3 ~108 log 1  
fill ~1 ~0 ~109 ~1 ~3 ~109 log 1  
fill ~1 ~0 ~110 ~2 ~0 ~110 log 1  
fill ~2 ~0 ~7 ~2 ~22 ~7 log 1  
fill ~2 ~0 ~9 ~118 ~0 ~9 stonebrick 0  
fill ~2 ~0 ~10 ~118 ~0 ~10 stonebrick 0  
fill ~2 ~0 ~11 ~118 ~0 ~11 stonebrick 0  
fill ~2 ~0 ~12 ~118 ~0 ~12 stonebrick 0  
fill ~2 ~0 ~13 ~118 ~0 ~13 stonebrick 0  
fill ~2 ~0 ~14 ~118 ~0 ~14 stonebrick 0  
fill ~2 ~0 ~15 ~118 ~0 ~15 stonebrick 0  
fill ~2 ~0 ~16 ~118 ~0 ~16 stonebrick 0  
fill ~2 ~0 ~17 ~118 ~0 ~17 stonebrick 0  
fill ~2 ~0 ~18 ~118 ~0 ~18 stonebrick 0  
fill ~2 ~0 ~19 ~118 ~0 ~19 stonebrick 0  
fill ~2 ~0 ~20 ~118 ~0 ~20 stonebrick 0  
fill ~2 ~0 ~21 ~118 ~0 ~21 stonebrick 0  
fill ~2 ~0 ~22 ~118 ~0 ~22 stonebrick 0  
fill ~2 ~0 ~23 ~118 ~0 ~23 stonebrick 0  
fill ~2 ~0 ~24 ~118 ~0 ~24 stonebrick 0  
fill ~2 ~0 ~25 ~118 ~0 ~25 stonebrick 0  
fill ~2 ~0 ~26 ~118 ~0 ~26 stonebrick 0  
fill ~2 ~0 ~27 ~118 ~0 ~27 stonebrick 0  
fill ~2 ~0 ~28 ~118 ~0 ~28 stonebrick 0  
fill ~2 ~0 ~29 ~118 ~0 ~29 stonebrick 0  
fill ~2 ~0 ~30 ~118 ~0 ~30 stonebrick 0  
fill ~2 ~0 ~31 ~118 ~0 ~31 stonebrick 0  
fill ~2 ~0 ~32 ~118 ~0 ~32 stonebrick 0  
fill ~2 ~0 ~33 ~118 ~0 ~33 stonebrick 0  
fill ~2 ~0 ~34 ~118 ~0 ~34 stonebrick 0  
fill ~2 ~0 ~35 ~118 ~0 ~35 stonebrick 0  
fill ~2 ~0 ~36 ~118 ~0 ~36 stonebrick 0  
fill ~2 ~0 ~37 ~118 ~0 ~37 stonebrick 0  
fill ~2 ~0 ~38 ~118 ~0 ~38 stonebrick 0  
fill ~2 ~0 ~39 ~118 ~0 ~39 stonebrick 0  
fill ~2 ~0 ~40 ~118 ~0 ~40 stonebrick 0  
fill ~2 ~0 ~41 ~118 ~0 ~41 stonebrick 0  
fill ~2 ~0 ~42 ~118 ~0 ~42 stonebrick 0  
fill ~2 ~0 ~43 ~118 ~0 ~43 stonebrick 0  
fill ~2 ~0 ~44 ~118 ~0 ~44 stonebrick 0  
fill ~2 ~0 ~45 ~118 ~0 ~45 stonebrick 0  
fill ~2 ~0 ~46 ~118 ~0 ~46 stonebrick 0  
fill ~2 ~0 ~47 ~118 ~0 ~47 stonebrick 0  
fill ~2 ~0 ~48 ~118 ~0 ~48 stonebrick 0  
fill ~2 ~0 ~49 ~118 ~0 ~49 stonebrick 0  
fill ~2 ~0 ~50 ~118 ~0 ~50 stonebrick 0  
fill ~2 ~0 ~51 ~118 ~0 ~51 stonebrick 0  
fill ~2 ~0 ~52 ~118 ~0 ~52 stonebrick 0  
fill ~2 ~0 ~53 ~118 ~0 ~53 stonebrick 0  
fill ~2 ~0 ~54 ~118 ~0 ~54 stonebrick 0  
fill ~2 ~0 ~55 ~118 ~0 ~55 stonebrick 0  
fill ~2 ~0 ~56 ~118 ~0 ~56 stonebrick 0  
fill ~2 ~0 ~57 ~118 ~0 ~57 stonebrick 0  
fill ~2 ~0 ~58 ~118 ~0 ~58 stonebrick 0  
fill ~2 ~0 ~59 ~118 ~0 ~59 stonebrick 0  
fill ~2 ~0 ~60 ~118 ~0 ~60 stonebrick 0  
fill ~2 ~0 ~61 ~118 ~0 ~61 stonebrick 0  
fill ~2 ~0 ~62 ~118 ~0 ~62 stonebrick 0  
fill ~2 ~0 ~63 ~118 ~0 ~63 stonebrick 0  
fill ~2 ~0 ~64 ~118 ~0 ~64 stonebrick 0  
fill ~2 ~0 ~65 ~118 ~0 ~65 stonebrick 0  
fill ~2 ~0 ~66 ~118 ~0 ~66 stonebrick 0  
fill ~2 ~0 ~67 ~118 ~0 ~67 stonebrick 0  
fill ~2 ~0 ~68 ~118 ~0 ~68 stonebrick 0  
fill ~2 ~0 ~69 ~118 ~0 ~69 stonebrick 0  
fill ~2 ~0 ~70 ~118 ~0 ~70 stonebrick 0  
fill ~2 ~0 ~71 ~118 ~0 ~71 stonebrick 0  
fill ~2 ~0 ~72 ~118 ~0 ~72 stonebrick 0  
fill ~2 ~0 ~73 ~118 ~0 ~73 stonebrick 0  
fill ~2 ~0 ~74 ~118 ~0 ~74 stonebrick 0  
fill ~2 ~0 ~75 ~118 ~0 ~75 stonebrick 0  
fill ~2 ~0 ~76 ~118 ~0 ~76 stonebrick 0  
fill ~2 ~0 ~77 ~118 ~0 ~77 stonebrick 0  
fill ~2 ~0 ~78 ~118 ~0 ~78 stonebrick 0  
fill ~2 ~0 ~79 ~118 ~0 ~79 stonebrick 0  
fill ~2 ~0 ~80 ~118 ~0 ~80 stonebrick 0  
fill ~2 ~0 ~81 ~118 ~0 ~81 stonebrick 0  
fill ~2 ~0 ~82 ~118 ~0 ~82 stonebrick 0  
fill ~2 ~0 ~83 ~118 ~0 ~83 stonebrick 0  
fill ~2 ~0 ~84 ~118 ~0 ~84 stonebrick 0  
fill ~2 ~0 ~85 ~118 ~0 ~85 stonebrick 0  
fill ~2 ~0 ~86 ~118 ~0 ~86 stonebrick 0  
fill ~2 ~0 ~87 ~118 ~0 ~87 stonebrick 0  
fill ~2 ~0 ~88 ~118 ~0 ~88 stonebrick 0  
fill ~2 ~0 ~89 ~118 ~0 ~89 stonebrick 0  
fill ~2 ~0 ~90 ~118 ~0 ~90 stonebrick 0  
fill ~2 ~0 ~91 ~118 ~0 ~91 stonebrick 0  
fill ~2 ~0 ~92 ~118 ~0 ~92 stonebrick 0  
fill ~2 ~0 ~93 ~118 ~0 ~93 stonebrick 0  
fill ~2 ~0 ~94 ~118 ~0 ~94 stonebrick 0  
fill ~2 ~0 ~95 ~118 ~0 ~95 stonebrick 0  
fill ~2 ~0 ~96 ~118 ~0 ~96 stonebrick 0  
fill ~2 ~0 ~97 ~118 ~0 ~97 stonebrick 0  
fill ~2 ~0 ~98 ~118 ~0 ~98 stonebrick 0  
fill ~2 ~0 ~99 ~118 ~0 ~99 stonebrick 0  
fill ~2 ~0 ~100 ~118 ~0 ~100 stonebrick 0  
fill ~2 ~0 ~101 ~118 ~0 ~101 stonebrick 0  
fill ~2 ~0 ~102 ~118 ~0 ~102 stonebrick 0  
fill ~2 ~0 ~103 ~118 ~0 ~103 stonebrick 0  
fill ~2 ~0 ~104 ~118 ~0 ~104 stonebrick 0  
fill ~2 ~0 ~105 ~118 ~0 ~105 stonebrick 0  
fill ~2 ~0 ~106 ~118 ~0 ~106 stonebrick 0  
fill ~2 ~0 ~107 ~118 ~0 ~107 stonebrick 0  
fill ~2 ~0 ~108 ~118 ~0 ~108 stonebrick 0  
fill ~2 ~0 ~109 ~118 ~0 ~109 stonebrick 0  
fill ~2 ~0 ~111 ~2 ~22 ~111 log 1  
fill ~3 ~0 ~5 ~3 ~22 ~5 log 1  
fill ~3 ~0 ~6 ~3 ~22 ~6 log 1  
fill ~3 ~0 ~112 ~3 ~22 ~112 log 1  
fill ~3 ~0 ~113 ~3 ~22 ~113 log 1  
fill ~4 ~0 ~4 ~4 ~22 ~4 log 1  
fill ~4 ~0 ~114 ~4 ~22 ~114 log 1  
fill ~5 ~0 ~3 ~5 ~22 ~3 log 1  
fill ~5 ~0 ~115 ~5 ~22 ~115 log 1  
fill ~6 ~0 ~2 ~7 ~0 ~2 log 1  
fill ~6 ~0 ~116 ~7 ~0 ~116 log 1  
fill ~8 ~0 ~1 ~9 ~0 ~1 log 1  
fill ~8 ~0 ~117 ~8 ~22 ~117 log 1  
fill ~9 ~0 ~0 ~54 ~0 ~0 log 1  
fill ~9 ~0 ~118 ~54 ~0 ~118 log 1  
fill ~10 ~0 ~1 ~110 ~0 ~1 stonebrick 0  
fill ~10 ~0 ~2 ~110 ~0 ~2 stonebrick 0  
fill ~10 ~0 ~3 ~110 ~0 ~3 stonebrick 0  
fill ~10 ~0 ~4 ~110 ~0 ~4 stonebrick 0  
fill ~10 ~0 ~5 ~110 ~0 ~5 stonebrick 0  
fill ~10 ~0 ~6 ~110 ~0 ~6 stonebrick 0  
fill ~10 ~0 ~7 ~110 ~0 ~7 stonebrick 0  
fill ~10 ~0 ~8 ~110 ~0 ~8 stonebrick 0  
fill ~10 ~0 ~110 ~110 ~0 ~110 stonebrick 0  
fill ~10 ~0 ~111 ~110 ~0 ~111 stonebrick 0  
fill ~10 ~0 ~112 ~110 ~0 ~112 stonebrick 0  
fill ~10 ~0 ~113 ~110 ~0 ~113 stonebrick 0  
fill ~10 ~0 ~114 ~110 ~0 ~114 stonebrick 0  
fill ~10 ~0 ~115 ~110 ~0 ~115 stonebrick 0  
fill ~10 ~0 ~116 ~110 ~0 ~116 stonebrick 0  
fill ~10 ~0 ~117 ~110 ~0 ~117 stonebrick 0  
fill ~55 ~0 ~0 ~65 ~0 ~0 planks 5  
fill ~55 ~0 ~118 ~65 ~0 ~118 planks 5  
fill ~66 ~0 ~0 ~111 ~0 ~0 log 1  
fill ~66 ~0 ~118 ~111 ~0 ~118 log 1  
fill ~111 ~0 ~117 ~112 ~0 ~117 log 1  
fill ~112 ~0 ~1 ~112 ~22 ~1 log 1  
fill ~113 ~0 ~2 ~114 ~0 ~2 log 1  
fill ~113 ~0 ~116 ~114 ~0 ~116 log 1  
fill ~115 ~0 ~3 ~115 ~22 ~3 log 1  
fill ~115 ~0 ~115 ~115 ~22 ~115 log 1  
fill ~116 ~0 ~4 ~116 ~22 ~4 log 1  
fill ~116 ~0 ~114 ~116 ~22 ~114 log 1  
fill ~117 ~0 ~5 ~117 ~22 ~5 log 1  
fill ~117 ~0 ~6 ~117 ~22 ~6 log 1  
fill ~117 ~0 ~112 ~117 ~22 ~112 log 1  
fill ~117 ~0 ~113 ~117 ~22 ~113 log 1  
fill ~118 ~0 ~7 ~118 ~22 ~7 log 1  
fill ~118 ~0 ~8 ~119 ~0 ~8 log 1  
fill ~118 ~0 ~111 ~118 ~22 ~111 log 1  
fill ~119 ~0 ~9 ~119 ~3 ~9 log 1  
fill ~119 ~0 ~10 ~119 ~3 ~10 log 1  
fill ~119 ~0 ~11 ~119 ~3 ~11 log 1  
fill ~119 ~0 ~12 ~119 ~3 ~12 log 1  
fill ~119 ~0 ~13 ~119 ~3 ~13 log 1  
fill ~119 ~0 ~14 ~119 ~34 ~14 log 1  
fill ~119 ~0 ~15 ~119 ~3 ~15 log 1  
fill ~119 ~0 ~16 ~119 ~3 ~16 log 1  
fill ~119 ~0 ~17 ~119 ~3 ~17 log 1  
fill ~119 ~0 ~18 ~119 ~3 ~18 log 1  
fill ~119 ~0 ~19 ~119 ~3 ~19 log 1  
fill ~119 ~0 ~20 ~119 ~34 ~20 log 1  
fill ~119 ~0 ~21 ~119 ~3 ~21 log 1  
fill ~119 ~0 ~22 ~119 ~3 ~22 log 1  
fill ~119 ~0 ~23 ~119 ~3 ~23 log 1  
fill ~119 ~0 ~24 ~119 ~3 ~24 log 1  
fill ~119 ~0 ~25 ~119 ~3 ~25 log 1  
fill ~119 ~0 ~26 ~119 ~3 ~26 log 1  
fill ~119 ~0 ~27 ~119 ~3 ~27 log 1  
fill ~119 ~0 ~28 ~119 ~3 ~28 log 1  
fill ~119 ~0 ~29 ~119 ~34 ~29 log 1  
fill ~119 ~0 ~30 ~119 ~3 ~30 log 1  
fill ~119 ~0 ~31 ~119 ~3 ~31 log 1  
fill ~119 ~0 ~32 ~119 ~3 ~32 log 1  
fill ~119 ~0 ~33 ~119 ~3 ~33 log 1  
fill ~119 ~0 ~34 ~119 ~3 ~34 log 1  
fill ~119 ~0 ~35 ~119 ~34 ~35 log 1  
fill ~119 ~0 ~36 ~119 ~3 ~36 log 1  
fill ~119 ~0 ~37 ~119 ~3 ~37 log 1  
fill ~119 ~0 ~38 ~119 ~3 ~38 log 1  
fill ~119 ~0 ~39 ~119 ~3 ~39 log 1  
fill ~119 ~0 ~40 ~119 ~3 ~40 log 1  
fill ~119 ~0 ~41 ~119 ~35 ~41 log 1  
fill ~119 ~0 ~42 ~119 ~1 ~42 log 1  
fill ~119 ~0 ~43 ~119 ~1 ~43 log 1  
fill ~119 ~0 ~44 ~119 ~1 ~44 log 1  
fill ~119 ~0 ~45 ~119 ~1 ~45 log 1  
fill ~119 ~0 ~46 ~119 ~1 ~46 log 1  
fill ~119 ~0 ~47 ~119 ~3 ~47 log 1  
fill ~119 ~0 ~48 ~119 ~1 ~48 log 1  
fill ~119 ~0 ~49 ~119 ~1 ~49 log 1  
fill ~119 ~0 ~50 ~119 ~1 ~50 log 1  
fill ~119 ~0 ~51 ~119 ~1 ~51 log 1  
fill ~119 ~0 ~52 ~119 ~1 ~52 log 1  
fill ~119 ~0 ~53 ~119 ~2 ~53 log 1  
fill ~119 ~0 ~54 ~119 ~1 ~54 planks 5  
fill ~119 ~0 ~55 ~119 ~1 ~55 planks 5  
fill ~119 ~0 ~56 ~119 ~1 ~56 planks 5  
fill ~119 ~0 ~57 ~119 ~1 ~57 planks 5  
fill ~119 ~0 ~58 ~119 ~1 ~58 planks 5  
fill ~119 ~0 ~59 ~119 ~1 ~59 planks 5  
fill ~119 ~0 ~60 ~119 ~1 ~60 planks 5  
fill ~119 ~0 ~61 ~119 ~1 ~61 planks 5  
fill ~119 ~0 ~62 ~119 ~1 ~62 planks 5  
fill ~119 ~0 ~63 ~119 ~1 ~63 planks 5  
fill ~119 ~0 ~64 ~119 ~1 ~64 planks 5  
fill ~119 ~0 ~65 ~119 ~2 ~65 log 1  
fill ~119 ~0 ~66 ~119 ~1 ~66 log 1  
fill ~119 ~0 ~67 ~119 ~1 ~67 log 1  
fill ~119 ~0 ~68 ~119 ~1 ~68 log 1  
fill ~119 ~0 ~69 ~119 ~1 ~69 log 1  
fill ~119 ~0 ~70 ~119 ~1 ~70 log 1  
fill ~119 ~0 ~71 ~119 ~3 ~71 log 1  
fill ~119 ~0 ~72 ~119 ~1 ~72 log 1  
fill ~119 ~0 ~73 ~119 ~1 ~73 log 1  
fill ~119 ~0 ~74 ~119 ~1 ~74 log 1  
fill ~119 ~0 ~75 ~119 ~1 ~75 log 1  
fill ~119 ~0 ~76 ~119 ~1 ~76 log 1  
fill ~119 ~0 ~77 ~119 ~35 ~77 log 1  
fill ~119 ~0 ~78 ~119 ~3 ~78 log 1  
fill ~119 ~0 ~79 ~119 ~3 ~79 log 1  
fill ~119 ~0 ~80 ~119 ~3 ~80 log 1  
fill ~119 ~0 ~81 ~119 ~3 ~81 log 1  
fill ~119 ~0 ~82 ~119 ~3 ~82 log 1  
fill ~119 ~0 ~83 ~119 ~34 ~83 log 1  
fill ~119 ~0 ~84 ~119 ~3 ~84 log 1  
fill ~119 ~0 ~85 ~119 ~3 ~85 log 1  
fill ~119 ~0 ~86 ~119 ~3 ~86 log 1  
fill ~119 ~0 ~87 ~119 ~3 ~87 log 1  
fill ~119 ~0 ~88 ~119 ~3 ~88 log 1  
fill ~119 ~0 ~89 ~119 ~34 ~89 log 1  
fill ~119 ~0 ~90 ~119 ~3 ~90 log 1  
fill ~119 ~0 ~91 ~119 ~3 ~91 log 1  
fill ~119 ~0 ~92 ~119 ~3 ~92 log 1  
fill ~119 ~0 ~93 ~119 ~3 ~93 log 1  
fill ~119 ~0 ~94 ~119 ~3 ~94 log 1  
fill ~119 ~0 ~95 ~119 ~3 ~95 log 1  
fill ~119 ~0 ~96 ~119 ~3 ~96 log 1  
fill ~119 ~0 ~97 ~119 ~3 ~97 log 1  
fill ~119 ~0 ~98 ~119 ~34 ~98 log 1  
fill ~119 ~0 ~99 ~119 ~3 ~99 log 1  
fill ~119 ~0 ~100 ~119 ~3 ~100 log 1  
fill ~119 ~0 ~101 ~119 ~3 ~101 log 1  
fill ~119 ~0 ~102 ~119 ~3 ~102 log 1  
fill ~119 ~0 ~103 ~119 ~3 ~103 log 1  
fill ~119 ~0 ~104 ~119 ~34 ~104 log 1  
fill ~119 ~0 ~105 ~119 ~3 ~105 log 1  
fill ~119 ~0 ~106 ~119 ~3 ~106 log 1  
fill ~119 ~0 ~107 ~119 ~3 ~107 log 1  
fill ~119 ~0 ~108 ~119 ~3 ~108 log 1  
fill ~119 ~0 ~109 ~119 ~3 ~109 log 1  
fill ~119 ~0 ~110 ~119 ~34 ~110 log 1  
fill ~1 ~1 ~110 ~2 ~1 ~110 log 1  
fill ~2 ~1 ~9 ~118 ~1 ~9 stonebrick 0  
fill ~2 ~1 ~10 ~118 ~1 ~10 stonebrick 0  
fill ~2 ~1 ~11 ~118 ~1 ~11 stonebrick 0  
fill ~2 ~1 ~12 ~118 ~1 ~12 stonebrick 0  
fill ~2 ~1 ~13 ~118 ~1 ~13 stonebrick 0  
fill ~2 ~1 ~14 ~118 ~1 ~14 stonebrick 0  
fill ~2 ~1 ~15 ~118 ~1 ~15 stonebrick 0  
fill ~2 ~1 ~16 ~118 ~1 ~16 stonebrick 0  
fill ~2 ~1 ~17 ~118 ~1 ~17 stonebrick 0  
fill ~2 ~1 ~18 ~118 ~1 ~18 stonebrick 0  
fill ~2 ~1 ~19 ~118 ~1 ~19 stonebrick 0  
fill ~2 ~1 ~20 ~118 ~1 ~20 stonebrick 0  
fill ~2 ~1 ~21 ~118 ~1 ~21 stonebrick 0  
fill ~2 ~1 ~22 ~118 ~1 ~22 stonebrick 0  
fill ~2 ~1 ~23 ~118 ~1 ~23 stonebrick 0  
fill ~2 ~1 ~24 ~118 ~1 ~24 stonebrick 0  
fill ~2 ~1 ~25 ~118 ~1 ~25 stonebrick 0  
fill ~2 ~1 ~26 ~118 ~1 ~26 stonebrick 0  
fill ~2 ~1 ~27 ~118 ~1 ~27 stonebrick 0  
fill ~2 ~1 ~28 ~118 ~1 ~28 stonebrick 0  
fill ~2 ~1 ~29 ~118 ~1 ~29 stonebrick 0  
fill ~2 ~1 ~30 ~118 ~1 ~30 stonebrick 0  
fill ~2 ~1 ~31 ~118 ~1 ~31 stonebrick 0  
fill ~2 ~1 ~32 ~118 ~1 ~32 stonebrick 0  
fill ~2 ~1 ~33 ~118 ~1 ~33 stonebrick 0  
fill ~2 ~1 ~34 ~118 ~1 ~34 stonebrick 0  
fill ~2 ~1 ~35 ~118 ~1 ~35 stonebrick 0  
fill ~2 ~1 ~36 ~118 ~1 ~36 stonebrick 0  
fill ~2 ~1 ~37 ~118 ~1 ~37 stonebrick 0  
fill ~2 ~1 ~38 ~118 ~1 ~38 stonebrick 0  
fill ~2 ~1 ~39 ~118 ~1 ~39 stonebrick 0  
fill ~2 ~1 ~40 ~118 ~1 ~40 stonebrick 0  
fill ~2 ~1 ~41 ~118 ~1 ~41 stonebrick 0  
fill ~2 ~1 ~42 ~118 ~1 ~42 stonebrick 0  
fill ~2 ~1 ~43 ~118 ~1 ~43 stonebrick 0  
fill ~2 ~1 ~44 ~118 ~1 ~44 stonebrick 0  
fill ~2 ~1 ~45 ~118 ~1 ~45 stonebrick 0  
fill ~2 ~1 ~46 ~118 ~1 ~46 stonebrick 0  
fill ~2 ~1 ~47 ~118 ~1 ~47 stonebrick 0  
fill ~2 ~1 ~48 ~118 ~1 ~48 stonebrick 0  
fill ~2 ~1 ~49 ~118 ~1 ~49 stonebrick 0  
fill ~2 ~1 ~50 ~118 ~1 ~50 stonebrick 0  
fill ~2 ~1 ~51 ~118 ~1 ~51 stonebrick 0  
fill ~2 ~1 ~52 ~118 ~1 ~52 stonebrick 0  
fill ~2 ~1 ~53 ~118 ~1 ~53 stonebrick 0  
fill ~2 ~1 ~54 ~118 ~1 ~54 stonebrick 0  
fill ~2 ~1 ~55 ~2 ~1 ~63 planks 5  
fill ~2 ~1 ~64 ~118 ~1 ~64 stonebrick 0  
fill ~2 ~1 ~65 ~118 ~1 ~65 stonebrick 0  
fill ~2 ~1 ~66 ~118 ~1 ~66 stonebrick 0  
fill ~2 ~1 ~67 ~118 ~1 ~67 stonebrick 0  
fill ~2 ~1 ~68 ~118 ~1 ~68 stonebrick 0  
fill ~2 ~1 ~69 ~118 ~1 ~69 stonebrick 0  
fill ~2 ~1 ~70 ~118 ~1 ~70 stonebrick 0  
fill ~2 ~1 ~71 ~118 ~1 ~71 stonebrick 0  
fill ~2 ~1 ~72 ~118 ~1 ~72 stonebrick 0  
fill ~2 ~1 ~73 ~118 ~1 ~73 stonebrick 0  
fill ~2 ~1 ~74 ~118 ~1 ~74 stonebrick 0  
fill ~2 ~1 ~75 ~118 ~1 ~75 stonebrick 0  
fill ~2 ~1 ~76 ~118 ~1 ~76 stonebrick 0  
fill ~2 ~1 ~77 ~118 ~1 ~77 stonebrick 0  
fill ~2 ~1 ~78 ~118 ~1 ~78 stonebrick 0  
fill ~2 ~1 ~79 ~118 ~1 ~79 stonebrick 0  
fill ~2 ~1 ~80 ~118 ~1 ~80 stonebrick 0  
fill ~2 ~1 ~81 ~118 ~1 ~81 stonebrick 0  
fill ~2 ~1 ~82 ~118 ~1 ~82 stonebrick 0  
fill ~2 ~1 ~83 ~118 ~1 ~83 stonebrick 0  
fill ~2 ~1 ~84 ~118 ~1 ~84 stonebrick 0  
fill ~2 ~1 ~85 ~118 ~1 ~85 stonebrick 0  
fill ~2 ~1 ~86 ~118 ~1 ~86 stonebrick 0  
fill ~2 ~1 ~87 ~118 ~1 ~87 stonebrick 0  
fill ~2 ~1 ~88 ~118 ~1 ~88 stonebrick 0  
fill ~2 ~1 ~89 ~118 ~1 ~89 stonebrick 0  
fill ~2 ~1 ~90 ~118 ~1 ~90 stonebrick 0  
fill ~2 ~1 ~91 ~118 ~1 ~91 stonebrick 0  
fill ~2 ~1 ~92 ~118 ~1 ~92 stonebrick 0  
fill ~2 ~1 ~93 ~118 ~1 ~93 stonebrick 0  
fill ~2 ~1 ~94 ~118 ~1 ~94 stonebrick 0  
fill ~2 ~1 ~95 ~118 ~1 ~95 stonebrick 0  
fill ~2 ~1 ~96 ~118 ~1 ~96 stonebrick 0  
fill ~2 ~1 ~97 ~118 ~1 ~97 stonebrick 0  
fill ~2 ~1 ~98 ~118 ~1 ~98 stonebrick 0  
fill ~2 ~1 ~99 ~118 ~1 ~99 stonebrick 0  
fill ~2 ~1 ~100 ~118 ~1 ~100 stonebrick 0  
fill ~2 ~1 ~101 ~118 ~1 ~101 stonebrick 0  
fill ~2 ~1 ~102 ~118 ~1 ~102 stonebrick 0  
fill ~2 ~1 ~103 ~118 ~1 ~103 stonebrick 0  
fill ~2 ~1 ~104 ~118 ~1 ~104 stonebrick 0  
fill ~2 ~1 ~105 ~118 ~1 ~105 stonebrick 0  
fill ~2 ~1 ~106 ~118 ~1 ~106 stonebrick 0  
fill ~2 ~1 ~107 ~118 ~1 ~107 stonebrick 0  
fill ~2 ~1 ~108 ~118 ~1 ~108 stonebrick 0  
fill ~2 ~1 ~109 ~118 ~1 ~109 stonebrick 0  
fill ~3 ~1 ~55 ~117 ~1 ~55 stonebrick 0  
fill ~3 ~1 ~56 ~117 ~1 ~56 stonebrick 0  
fill ~3 ~1 ~57 ~3 ~1 ~61 planks 5  
fill ~3 ~1 ~62 ~117 ~1 ~62 stonebrick 0  
fill ~3 ~1 ~63 ~117 ~1 ~63 stonebrick 0  
fill ~4 ~1 ~57 ~116 ~1 ~57 stonebrick 0  
fill ~4 ~1 ~58 ~116 ~1 ~58 stonebrick 0  
fill ~4 ~1 ~59 ~116 ~1 ~59 stonebrick 0  
fill ~4 ~1 ~60 ~116 ~1 ~60 stonebrick 0  
fill ~4 ~1 ~61 ~116 ~1 ~61 stonebrick 0  
fill ~6 ~1 ~2 ~7 ~1 ~2 log 1  
fill ~6 ~1 ~116 ~7 ~1 ~116 log 1  
fill ~8 ~1 ~1 ~9 ~1 ~1 log 1  
fill ~9 ~1 ~0 ~54 ~1 ~0 log 1  
fill ~9 ~1 ~118 ~54 ~1 ~118 log 1  
fill ~10 ~1 ~1 ~55 ~1 ~1 stonebrick 0  
fill ~10 ~1 ~2 ~57 ~1 ~2 stonebrick 0  
fill ~10 ~1 ~3 ~110 ~1 ~3 stonebrick 0  
fill ~10 ~1 ~4 ~110 ~1 ~4 stonebrick 0  
fill ~10 ~1 ~5 ~110 ~1 ~5 stonebrick 0  
fill ~10 ~1 ~6 ~110 ~1 ~6 stonebrick 0  
fill ~10 ~1 ~7 ~110 ~1 ~7 stonebrick 0  
fill ~10 ~1 ~8 ~110 ~1 ~8 stonebrick 0  
fill ~10 ~1 ~110 ~110 ~1 ~110 stonebrick 0  
fill ~10 ~1 ~111 ~110 ~1 ~111 stonebrick 0  
fill ~10 ~1 ~112 ~110 ~1 ~112 stonebrick 0  
fill ~10 ~1 ~113 ~110 ~1 ~113 stonebrick 0  
fill ~10 ~1 ~114 ~110 ~1 ~114 stonebrick 0  
fill ~10 ~1 ~115 ~110 ~1 ~115 stonebrick 0  
fill ~10 ~1 ~116 ~57 ~1 ~116 stonebrick 0  
fill ~10 ~1 ~117 ~55 ~1 ~117 stonebrick 0  
fill ~55 ~1 ~0 ~65 ~1 ~0 planks 5  
fill ~55 ~1 ~118 ~65 ~1 ~118 planks 5  
fill ~56 ~1 ~1 ~64 ~1 ~1 planks 5  
fill ~56 ~1 ~117 ~64 ~1 ~117 planks 5  
fill ~58 ~1 ~2 ~62 ~1 ~2 planks 5  
fill ~58 ~1 ~116 ~62 ~1 ~116 planks 5  
fill ~63 ~1 ~2 ~110 ~1 ~2 stonebrick 0  
fill ~63 ~1 ~116 ~110 ~1 ~116 stonebrick 0  
fill ~65 ~1 ~1 ~110 ~1 ~1 stonebrick 0  
fill ~65 ~1 ~117 ~110 ~1 ~117 stonebrick 0  
fill ~66 ~1 ~0 ~111 ~1 ~0 log 1  
fill ~66 ~1 ~118 ~111 ~1 ~118 log 1  
fill ~111 ~1 ~117 ~112 ~1 ~117 log 1  
fill ~113 ~1 ~2 ~114 ~1 ~2 log 1  
fill ~113 ~1 ~116 ~114 ~1 ~116 log 1  
fill ~117 ~1 ~57 ~119 ~1 ~57 planks 5  
fill ~117 ~1 ~58 ~119 ~1 ~58 planks 5  
fill ~117 ~1 ~59 ~119 ~1 ~59 planks 5  
fill ~117 ~1 ~60 ~119 ~1 ~60 planks 5  
fill ~117 ~1 ~61 ~119 ~1 ~61 planks 5  
fill ~118 ~1 ~8 ~119 ~1 ~8 log 1  
fill ~118 ~1 ~55 ~118 ~1 ~63 planks 5 
setblock ~1 ~2 ~42 dark_oak_stairs 7  
fill ~1 ~2 ~43 ~1 ~2 ~45 dark_oak_stairs 4 
setblock ~1 ~2 ~46 dark_oak_stairs 6 
setblock ~1 ~2 ~48 dark_oak_stairs 7  
fill ~1 ~2 ~49 ~1 ~2 ~51 dark_oak_stairs 4 
setblock ~1 ~2 ~52 dark_oak_stairs 6 
setblock ~1 ~2 ~54 dark_oak_stairs 3 
setblock ~1 ~2 ~66 dark_oak_stairs 7  
fill ~1 ~2 ~67 ~1 ~2 ~69 dark_oak_stairs 4 
setblock ~1 ~2 ~70 dark_oak_stairs 6 
setblock ~1 ~2 ~72 dark_oak_stairs 7  
fill ~1 ~2 ~73 ~1 ~2 ~75 dark_oak_stairs 4 
setblock ~1 ~2 ~76 dark_oak_stairs 6  
fill ~1 ~2 ~110 ~2 ~2 ~110 log 1  
fill ~2 ~2 ~9 ~118 ~2 ~9 stonebrick 0  
fill ~2 ~2 ~10 ~118 ~2 ~10 stonebrick 0  
fill ~2 ~2 ~11 ~118 ~2 ~11 stonebrick 0  
fill ~2 ~2 ~12 ~118 ~2 ~12 stonebrick 0  
fill ~2 ~2 ~13 ~118 ~2 ~13 stonebrick 0  
fill ~2 ~2 ~14 ~118 ~2 ~14 stonebrick 0  
fill ~2 ~2 ~15 ~118 ~2 ~15 stonebrick 0  
fill ~2 ~2 ~16 ~118 ~2 ~16 stonebrick 0  
fill ~2 ~2 ~17 ~118 ~2 ~17 stonebrick 0  
fill ~2 ~2 ~18 ~118 ~2 ~18 stonebrick 0  
fill ~2 ~2 ~19 ~118 ~2 ~19 stonebrick 0  
fill ~2 ~2 ~20 ~118 ~2 ~20 stonebrick 0  
fill ~2 ~2 ~21 ~118 ~2 ~21 stonebrick 0  
fill ~2 ~2 ~22 ~118 ~2 ~22 stonebrick 0  
fill ~2 ~2 ~23 ~118 ~2 ~23 stonebrick 0  
fill ~2 ~2 ~24 ~118 ~2 ~24 stonebrick 0  
fill ~2 ~2 ~25 ~118 ~2 ~25 stonebrick 0  
fill ~2 ~2 ~26 ~118 ~2 ~26 stonebrick 0  
fill ~2 ~2 ~27 ~118 ~2 ~27 stonebrick 0  
fill ~2 ~2 ~28 ~118 ~2 ~28 stonebrick 0  
fill ~2 ~2 ~29 ~118 ~2 ~29 stonebrick 0  
fill ~2 ~2 ~30 ~118 ~2 ~30 stonebrick 0  
fill ~2 ~2 ~31 ~118 ~2 ~31 stonebrick 0  
fill ~2 ~2 ~32 ~118 ~2 ~32 stonebrick 0  
fill ~2 ~2 ~33 ~118 ~2 ~33 stonebrick 0  
fill ~2 ~2 ~34 ~118 ~2 ~34 stonebrick 0  
fill ~2 ~2 ~35 ~118 ~2 ~35 stonebrick 0  
fill ~2 ~2 ~36 ~118 ~2 ~36 stonebrick 0  
fill ~2 ~2 ~37 ~118 ~2 ~37 stonebrick 0  
fill ~2 ~2 ~38 ~118 ~2 ~38 stonebrick 0  
fill ~2 ~2 ~39 ~118 ~2 ~39 stonebrick 0  
fill ~2 ~2 ~40 ~118 ~2 ~40 stonebrick 0  
fill ~2 ~2 ~41 ~118 ~2 ~41 stonebrick 0  
fill ~2 ~2 ~42 ~118 ~2 ~42 stonebrick 0  
fill ~2 ~2 ~43 ~118 ~2 ~43 stonebrick 0  
fill ~2 ~2 ~44 ~118 ~2 ~44 stonebrick 0  
fill ~2 ~2 ~45 ~118 ~2 ~45 stonebrick 0  
fill ~2 ~2 ~46 ~118 ~2 ~46 stonebrick 0  
fill ~2 ~2 ~47 ~118 ~2 ~47 stonebrick 0  
fill ~2 ~2 ~48 ~118 ~2 ~48 stonebrick 0  
fill ~2 ~2 ~49 ~118 ~2 ~49 stonebrick 0  
fill ~2 ~2 ~50 ~118 ~2 ~50 stonebrick 0  
fill ~2 ~2 ~51 ~118 ~2 ~51 stonebrick 0  
fill ~2 ~2 ~52 ~118 ~2 ~52 stonebrick 0 
setblock ~2 ~2 ~53 dark_oak_stairs 3 
setblock ~2 ~2 ~54 dropper 5 
setblock ~2 ~2 ~64 dropper 5  
fill ~2 ~2 ~65 ~3 ~2 ~65 dark_oak_stairs 2  
fill ~2 ~2 ~66 ~118 ~2 ~66 stonebrick 0  
fill ~2 ~2 ~67 ~15 ~2 ~67 stonebrick 0  
fill ~2 ~2 ~68 ~118 ~2 ~68 stonebrick 0  
fill ~2 ~2 ~69 ~118 ~2 ~69 stonebrick 0  
fill ~2 ~2 ~70 ~118 ~2 ~70 stonebrick 0  
fill ~2 ~2 ~71 ~118 ~2 ~71 stonebrick 0  
fill ~2 ~2 ~72 ~118 ~2 ~72 stonebrick 0  
fill ~2 ~2 ~73 ~118 ~2 ~73 stonebrick 0  
fill ~2 ~2 ~74 ~118 ~2 ~74 stonebrick 0  
fill ~2 ~2 ~75 ~118 ~2 ~75 stonebrick 0  
fill ~2 ~2 ~76 ~118 ~2 ~76 stonebrick 0  
fill ~2 ~2 ~77 ~118 ~2 ~77 stonebrick 0  
fill ~2 ~2 ~78 ~118 ~2 ~78 stonebrick 0  
fill ~2 ~2 ~79 ~118 ~2 ~79 stonebrick 0  
fill ~2 ~2 ~80 ~118 ~2 ~80 stonebrick 0  
fill ~2 ~2 ~81 ~118 ~2 ~81 stonebrick 0  
fill ~2 ~2 ~82 ~118 ~2 ~82 stonebrick 0  
fill ~2 ~2 ~83 ~118 ~2 ~83 stonebrick 0  
fill ~2 ~2 ~84 ~118 ~2 ~84 stonebrick 0  
fill ~2 ~2 ~85 ~118 ~2 ~85 stonebrick 0  
fill ~2 ~2 ~86 ~118 ~2 ~86 stonebrick 0  
fill ~2 ~2 ~87 ~118 ~2 ~87 stonebrick 0  
fill ~2 ~2 ~88 ~118 ~2 ~88 stonebrick 0  
fill ~2 ~2 ~89 ~118 ~2 ~89 stonebrick 0  
fill ~2 ~2 ~90 ~118 ~2 ~90 stonebrick 0  
fill ~2 ~2 ~91 ~118 ~2 ~91 stonebrick 0  
fill ~2 ~2 ~92 ~118 ~2 ~92 stonebrick 0  
fill ~2 ~2 ~93 ~118 ~2 ~93 stonebrick 0  
fill ~2 ~2 ~94 ~118 ~2 ~94 stonebrick 0  
fill ~2 ~2 ~95 ~118 ~2 ~95 stonebrick 0  
fill ~2 ~2 ~96 ~118 ~2 ~96 stonebrick 0  
fill ~2 ~2 ~97 ~118 ~2 ~97 stonebrick 0  
fill ~2 ~2 ~98 ~118 ~2 ~98 stonebrick 0  
fill ~2 ~2 ~99 ~118 ~2 ~99 stonebrick 0  
fill ~2 ~2 ~100 ~118 ~2 ~100 stonebrick 0  
fill ~2 ~2 ~101 ~118 ~2 ~101 stonebrick 0  
fill ~2 ~2 ~102 ~118 ~2 ~102 stonebrick 0  
fill ~2 ~2 ~103 ~118 ~2 ~103 stonebrick 0  
fill ~2 ~2 ~104 ~118 ~2 ~104 stonebrick 0  
fill ~2 ~2 ~105 ~118 ~2 ~105 stonebrick 0  
fill ~2 ~2 ~106 ~118 ~2 ~106 stonebrick 0  
fill ~2 ~2 ~107 ~118 ~2 ~107 stonebrick 0  
fill ~2 ~2 ~108 ~118 ~2 ~108 stonebrick 0  
fill ~2 ~2 ~109 ~118 ~2 ~109 stonebrick 0 
setblock ~3 ~2 ~53 dark_oak_stairs 0 
setblock ~3 ~2 ~54 dark_oak_stairs 3  
fill ~3 ~2 ~55 ~3 ~2 ~56 dropper 5  
fill ~3 ~2 ~62 ~3 ~2 ~63 dropper 5 
setblock ~3 ~2 ~64 dark_oak_stairs 0  
fill ~4 ~2 ~53 ~116 ~2 ~53 stonebrick 0  
fill ~4 ~2 ~54 ~4 ~2 ~55 dark_oak_stairs 0 
setblock ~4 ~2 ~56 dark_oak_stairs 3  
fill ~4 ~2 ~57 ~4 ~2 ~61 dropper 5  
fill ~4 ~2 ~62 ~4 ~2 ~63 dark_oak_stairs 0 
setblock ~4 ~2 ~64 dark_oak_stairs 2  
fill ~4 ~2 ~65 ~116 ~2 ~65 stonebrick 0  
fill ~5 ~2 ~54 ~115 ~2 ~54 stonebrick 0  
fill ~5 ~2 ~55 ~115 ~2 ~55 stonebrick 0  
fill ~5 ~2 ~56 ~5 ~2 ~57 dark_oak_stairs 0 
setblock ~5 ~2 ~58 dark_oak_stairs 3 
setblock ~5 ~2 ~59 dropper 5  
fill ~5 ~2 ~60 ~5 ~2 ~61 dark_oak_stairs 0 
setblock ~5 ~2 ~62 dark_oak_stairs 2  
fill ~5 ~2 ~63 ~15 ~2 ~63 stonebrick 0  
fill ~5 ~2 ~64 ~115 ~2 ~64 stonebrick 0  
fill ~6 ~2 ~2 ~7 ~2 ~2 log 1  
fill ~6 ~2 ~56 ~114 ~2 ~56 stonebrick 0  
fill ~6 ~2 ~57 ~114 ~2 ~57 stonebrick 0  
fill ~6 ~2 ~58 ~6 ~2 ~59 dark_oak_stairs 0 
setblock ~6 ~2 ~60 dark_oak_stairs 2  
fill ~6 ~2 ~61 ~114 ~2 ~61 stonebrick 0  
fill ~6 ~2 ~62 ~114 ~2 ~62 stonebrick 0  
fill ~6 ~2 ~116 ~7 ~2 ~116 log 1  
fill ~7 ~2 ~58 ~113 ~2 ~58 stonebrick 0  
fill ~7 ~2 ~59 ~113 ~2 ~59 stonebrick 0  
fill ~7 ~2 ~60 ~113 ~2 ~60 stonebrick 0  
fill ~8 ~2 ~1 ~9 ~2 ~1 log 1  
fill ~9 ~2 ~0 ~42 ~2 ~0 log 1  
fill ~9 ~2 ~118 ~42 ~2 ~118 log 1  
fill ~10 ~2 ~1 ~53 ~2 ~1 stonebrick 0  
fill ~10 ~2 ~2 ~53 ~2 ~2 stonebrick 0  
fill ~10 ~2 ~3 ~54 ~2 ~3 stonebrick 0  
fill ~10 ~2 ~4 ~56 ~2 ~4 stonebrick 0  
fill ~10 ~2 ~5 ~58 ~2 ~5 stonebrick 0  
fill ~10 ~2 ~6 ~110 ~2 ~6 stonebrick 0  
fill ~10 ~2 ~7 ~110 ~2 ~7 stonebrick 0  
fill ~10 ~2 ~8 ~110 ~2 ~8 stonebrick 0  
fill ~10 ~2 ~110 ~110 ~2 ~110 stonebrick 0  
fill ~10 ~2 ~111 ~110 ~2 ~111 stonebrick 0  
fill ~10 ~2 ~112 ~110 ~2 ~112 stonebrick 0  
fill ~10 ~2 ~113 ~58 ~2 ~113 stonebrick 0  
fill ~10 ~2 ~114 ~56 ~2 ~114 stonebrick 0  
fill ~10 ~2 ~115 ~54 ~2 ~115 stonebrick 0  
fill ~10 ~2 ~116 ~53 ~2 ~116 stonebrick 0  
fill ~10 ~2 ~117 ~53 ~2 ~117 stonebrick 0 
setblock ~16 ~2 ~63 redstone_block 0 
setblock ~16 ~2 ~67 redstone_block 0  
fill ~17 ~2 ~63 ~21 ~2 ~63 stonebrick 0  
fill ~17 ~2 ~67 ~21 ~2 ~67 stonebrick 0 
setblock ~22 ~2 ~63 redstone_block 0 
setblock ~22 ~2 ~67 redstone_block 0  
fill ~23 ~2 ~63 ~27 ~2 ~63 stonebrick 0  
fill ~23 ~2 ~67 ~27 ~2 ~67 stonebrick 0 
setblock ~28 ~2 ~63 redstone_block 0 
setblock ~28 ~2 ~67 redstone_block 0  
fill ~29 ~2 ~63 ~115 ~2 ~63 stonebrick 0  
fill ~29 ~2 ~67 ~118 ~2 ~67 stonebrick 0 
setblock ~43 ~2 ~0 dark_oak_stairs 5 
setblock ~43 ~2 ~118 dark_oak_stairs 5  
fill ~44 ~2 ~0 ~46 ~2 ~0 dark_oak_stairs 6  
fill ~44 ~2 ~118 ~46 ~2 ~118 dark_oak_stairs 7 
setblock ~47 ~2 ~0 dark_oak_stairs 4 
setblock ~47 ~2 ~118 dark_oak_stairs 4  
fill ~48 ~2 ~0 ~48 ~3 ~0 log 1  
fill ~48 ~2 ~118 ~48 ~3 ~118 log 1 
setblock ~49 ~2 ~0 dark_oak_stairs 5 
setblock ~49 ~2 ~118 dark_oak_stairs 5  
fill ~50 ~2 ~0 ~52 ~2 ~0 dark_oak_stairs 6  
fill ~50 ~2 ~118 ~52 ~2 ~118 dark_oak_stairs 7 
setblock ~53 ~2 ~0 dark_oak_stairs 4 
setblock ~53 ~2 ~118 dark_oak_stairs 4 
setblock ~54 ~2 ~0 log 1  
fill ~54 ~2 ~1 ~54 ~2 ~2 dark_oak_stairs 1 
setblock ~54 ~2 ~116 dark_oak_stairs 3 
setblock ~54 ~2 ~117 dark_oak_stairs 1 
setblock ~54 ~2 ~118 log 1 
setblock ~55 ~2 ~1 dropper 5 
setblock ~55 ~2 ~2 dark_oak_stairs 2 
setblock ~55 ~2 ~3 dark_oak_stairs 1  
fill ~55 ~2 ~115 ~56 ~2 ~115 dark_oak_stairs 3 
setblock ~55 ~2 ~116 dark_oak_stairs 1 
setblock ~55 ~2 ~117 dropper 5 
setblock ~55 ~2 ~118 dark_oak_stairs 1  
fill ~56 ~2 ~2 ~57 ~2 ~2 dropper 5  
fill ~56 ~2 ~3 ~57 ~2 ~3 dark_oak_stairs 2  
fill ~56 ~2 ~116 ~57 ~2 ~116 dropper 5 
setblock ~57 ~2 ~4 dark_oak_stairs 1  
fill ~57 ~2 ~114 ~58 ~2 ~114 dark_oak_stairs 3 
setblock ~57 ~2 ~115 dark_oak_stairs 1  
fill ~58 ~2 ~3 ~62 ~2 ~3 dropper 5  
fill ~58 ~2 ~4 ~59 ~2 ~4 dark_oak_stairs 2  
fill ~58 ~2 ~115 ~62 ~2 ~115 dropper 5 
setblock ~59 ~2 ~5 dark_oak_stairs 1  
fill ~59 ~2 ~113 ~60 ~2 ~113 dark_oak_stairs 3 
setblock ~59 ~2 ~114 dark_oak_stairs 1 
setblock ~60 ~2 ~4 dropper 5  
fill ~60 ~2 ~5 ~61 ~2 ~5 dark_oak_stairs 2 
setblock ~60 ~2 ~114 dropper 5 
setblock ~61 ~2 ~4 dark_oak_stairs 0 
setblock ~61 ~2 ~113 dark_oak_stairs 0  
fill ~61 ~2 ~114 ~62 ~2 ~114 dark_oak_stairs 3  
fill ~62 ~2 ~4 ~63 ~2 ~4 dark_oak_stairs 2  
fill ~62 ~2 ~5 ~110 ~2 ~5 stonebrick 0  
fill ~62 ~2 ~113 ~110 ~2 ~113 stonebrick 0  
fill ~63 ~2 ~2 ~64 ~2 ~2 dropper 5 
setblock ~63 ~2 ~3 dark_oak_stairs 0 
setblock ~63 ~2 ~114 dark_oak_stairs 0  
fill ~63 ~2 ~115 ~64 ~2 ~115 dark_oak_stairs 3  
fill ~63 ~2 ~116 ~64 ~2 ~116 dropper 5  
fill ~64 ~2 ~3 ~65 ~2 ~3 dark_oak_stairs 2  
fill ~64 ~2 ~4 ~110 ~2 ~4 stonebrick 0  
fill ~64 ~2 ~114 ~110 ~2 ~114 stonebrick 0 
setblock ~65 ~2 ~0 dark_oak_stairs 0 
setblock ~65 ~2 ~1 dropper 5 
setblock ~65 ~2 ~2 dark_oak_stairs 0 
setblock ~65 ~2 ~115 dark_oak_stairs 0 
setblock ~65 ~2 ~116 dark_oak_stairs 3 
setblock ~65 ~2 ~117 dropper 5  
fill ~66 ~2 ~0 ~66 ~0 ~0 log 1 
setblock ~66 ~2 ~1 dark_oak_stairs 0 
setblock ~66 ~2 ~2 dark_oak_stairs 2  
fill ~66 ~2 ~3 ~110 ~2 ~3 stonebrick 0  
fill ~66 ~2 ~115 ~110 ~2 ~115 stonebrick 0  
fill ~66 ~2 ~116 ~66 ~2 ~117 dark_oak_stairs 0  
fill ~66 ~2 ~118 ~66 ~0 ~118 log 1 
setblock ~67 ~2 ~0 dark_oak_stairs 5  
fill ~67 ~2 ~1 ~110 ~2 ~1 stonebrick 0  
fill ~67 ~2 ~2 ~110 ~2 ~2 stonebrick 0  
fill ~67 ~2 ~116 ~110 ~2 ~116 stonebrick 0  
fill ~67 ~2 ~117 ~110 ~2 ~117 stonebrick 0 
setblock ~67 ~2 ~118 dark_oak_stairs 5  
fill ~68 ~2 ~0 ~70 ~2 ~0 dark_oak_stairs 6  
fill ~68 ~2 ~118 ~70 ~2 ~118 dark_oak_stairs 7 
setblock ~71 ~2 ~0 dark_oak_stairs 4 
setblock ~71 ~2 ~118 dark_oak_stairs 4  
fill ~72 ~2 ~0 ~72 ~3 ~0 log 1  
fill ~72 ~2 ~118 ~72 ~3 ~118 log 1 
setblock ~73 ~2 ~0 dark_oak_stairs 5 
setblock ~73 ~2 ~118 dark_oak_stairs 5  
fill ~74 ~2 ~0 ~76 ~2 ~0 dark_oak_stairs 6  
fill ~74 ~2 ~118 ~76 ~2 ~118 dark_oak_stairs 7 
setblock ~77 ~2 ~0 dark_oak_stairs 4 
setblock ~77 ~2 ~118 dark_oak_stairs 4  
fill ~78 ~2 ~0 ~111 ~2 ~0 log 1  
fill ~78 ~2 ~118 ~111 ~2 ~118 log 1  
fill ~111 ~2 ~117 ~112 ~2 ~117 log 1  
fill ~113 ~2 ~2 ~114 ~2 ~2 log 1  
fill ~113 ~2 ~116 ~114 ~2 ~116 log 1 
setblock ~114 ~2 ~58 dark_oak_stairs 3  
fill ~114 ~2 ~59 ~114 ~2 ~60 dark_oak_stairs 1 
setblock ~115 ~2 ~56 dark_oak_stairs 3  
fill ~115 ~2 ~57 ~115 ~2 ~58 dark_oak_stairs 1  
fill ~115 ~2 ~59 ~116 ~2 ~59 dropper 5 
setblock ~115 ~2 ~60 dark_oak_stairs 2  
fill ~115 ~2 ~61 ~115 ~2 ~62 dark_oak_stairs 1 
setblock ~116 ~2 ~54 dark_oak_stairs 3  
fill ~116 ~2 ~55 ~116 ~2 ~56 dark_oak_stairs 1  
fill ~116 ~2 ~57 ~116 ~2 ~61 dropper 5 
setblock ~116 ~2 ~62 dark_oak_stairs 2  
fill ~116 ~2 ~63 ~116 ~2 ~64 dark_oak_stairs 1  
fill ~117 ~2 ~53 ~118 ~2 ~53 dark_oak_stairs 3 
setblock ~117 ~2 ~54 dark_oak_stairs 1  
fill ~117 ~2 ~55 ~117 ~2 ~56 dropper 5  
fill ~117 ~2 ~62 ~117 ~2 ~63 dropper 5 
setblock ~117 ~2 ~64 dark_oak_stairs 2 
setblock ~117 ~2 ~65 dark_oak_stairs 1  
fill ~118 ~2 ~8 ~119 ~2 ~8 log 1 
setblock ~118 ~2 ~54 dropper 5 
setblock ~118 ~2 ~64 dropper 5 
setblock ~118 ~2 ~65 dark_oak_stairs 2 
setblock ~119 ~2 ~42 dark_oak_stairs 7  
fill ~119 ~2 ~43 ~119 ~2 ~45 dark_oak_stairs 5 
setblock ~119 ~2 ~46 dark_oak_stairs 6 
setblock ~119 ~2 ~48 dark_oak_stairs 7  
fill ~119 ~2 ~49 ~119 ~2 ~51 dark_oak_stairs 5 
setblock ~119 ~2 ~52 dark_oak_stairs 6 
setblock ~119 ~2 ~64 dark_oak_stairs 2 
setblock ~119 ~2 ~66 dark_oak_stairs 7  
fill ~119 ~2 ~67 ~119 ~2 ~69 dark_oak_stairs 5 
setblock ~119 ~2 ~70 dark_oak_stairs 6 
setblock ~119 ~2 ~72 dark_oak_stairs 7  
fill ~119 ~2 ~73 ~119 ~2 ~75 dark_oak_stairs 5 
setblock ~119 ~2 ~76 dark_oak_stairs 6 
setblock ~1 ~3 ~42 dark_oak_stairs 3  
fill ~1 ~3 ~43 ~1 ~3 ~45 dark_oak_stairs 0 
setblock ~1 ~3 ~46 dark_oak_stairs 2 KittysCommands:  

KittysCommands:  
setblock ~1 ~3 ~48 dark_oak_stairs 3  
fill ~1 ~3 ~49 ~1 ~3 ~50 dark_oak_stairs 0  
fill ~1 ~3 ~51 ~2 ~3 ~51 dark_oak_stairs 3  
fill ~1 ~3 ~52 ~3 ~3 ~52 dropper 5 
setblock ~1 ~3 ~53 cobblestone_wall 0 
setblock ~1 ~3 ~65 cobblestone_wall 0  
fill ~1 ~3 ~66 ~3 ~3 ~66 dropper 5  
fill ~1 ~3 ~67 ~1 ~3 ~69 dark_oak_stairs 0 
setblock ~1 ~3 ~70 dark_oak_stairs 2 
setblock ~1 ~3 ~72 dark_oak_stairs 3  
fill ~1 ~3 ~73 ~1 ~3 ~75 dark_oak_stairs 0 
setblock ~1 ~3 ~76 dark_oak_stairs 2  
fill ~1 ~3 ~110 ~2 ~3 ~110 log 1  
fill ~2 ~3 ~9 ~50 ~3 ~9 stonebrick 0  
fill ~2 ~3 ~10 ~50 ~3 ~10 stonebrick 0  
fill ~2 ~3 ~11 ~52 ~3 ~11 stonebrick 0  
fill ~2 ~3 ~12 ~52 ~3 ~12 stonebrick 0  
fill ~2 ~3 ~13 ~52 ~3 ~13 stonebrick 0  
fill ~2 ~3 ~14 ~50 ~3 ~14 stonebrick 0  
fill ~2 ~3 ~15 ~51 ~3 ~15 stonebrick 0  
fill ~2 ~3 ~16 ~50 ~3 ~16 stonebrick 0  
fill ~2 ~3 ~17 ~52 ~3 ~17 stonebrick 0  
fill ~2 ~3 ~18 ~52 ~3 ~18 stonebrick 0  
fill ~2 ~3 ~19 ~52 ~3 ~19 stonebrick 0  
fill ~2 ~3 ~20 ~50 ~3 ~20 stonebrick 0  
fill ~2 ~3 ~21 ~51 ~3 ~21 stonebrick 0  
fill ~2 ~3 ~22 ~50 ~3 ~22 stonebrick 0  
fill ~2 ~3 ~23 ~52 ~3 ~23 stonebrick 0  
fill ~2 ~3 ~24 ~52 ~3 ~24 stonebrick 0  
fill ~2 ~3 ~25 ~52 ~3 ~25 stonebrick 0  
fill ~2 ~3 ~26 ~50 ~3 ~26 stonebrick 0  
fill ~2 ~3 ~27 ~51 ~3 ~27 stonebrick 0  
fill ~2 ~3 ~28 ~50 ~3 ~28 stonebrick 0  
fill ~2 ~3 ~29 ~52 ~3 ~29 stonebrick 0  
fill ~2 ~3 ~30 ~52 ~3 ~30 stonebrick 0  
fill ~2 ~3 ~31 ~52 ~3 ~31 stonebrick 0  
fill ~2 ~3 ~32 ~50 ~3 ~32 stonebrick 0  
fill ~2 ~3 ~33 ~39 ~3 ~33 stonebrick 0  
fill ~2 ~3 ~34 ~34 ~3 ~34 stonebrick 0  
fill ~2 ~3 ~35 ~39 ~3 ~35 stonebrick 0  
fill ~2 ~3 ~36 ~37 ~3 ~36 stonebrick 0  
fill ~2 ~3 ~37 ~36 ~3 ~37 stonebrick 0  
fill ~2 ~3 ~38 ~36 ~3 ~38 stonebrick 0  
fill ~2 ~3 ~39 ~33 ~3 ~39 stonebrick 0  
fill ~2 ~3 ~40 ~33 ~3 ~40 stonebrick 0  
fill ~2 ~3 ~41 ~35 ~3 ~41 stonebrick 0  
fill ~2 ~3 ~42 ~2 ~3 ~50 planks 1 
setblock ~2 ~3 ~67 dark_oak_stairs 2  
fill ~2 ~3 ~68 ~9 ~3 ~68 planks 1  
fill ~2 ~3 ~69 ~8 ~3 ~69 planks 1  
fill ~2 ~3 ~70 ~8 ~3 ~70 planks 1  
fill ~2 ~3 ~71 ~6 ~3 ~71 planks 1  
fill ~2 ~3 ~72 ~6 ~3 ~72 planks 1  
fill ~2 ~3 ~73 ~5 ~3 ~73 planks 1  
fill ~2 ~3 ~74 ~3 ~3 ~74 planks 1  
fill ~2 ~3 ~75 ~35 ~3 ~75 stonebrick 0  
fill ~2 ~3 ~76 ~35 ~3 ~76 stonebrick 0  
fill ~2 ~3 ~77 ~35 ~3 ~77 stonebrick 0  
fill ~2 ~3 ~78 ~33 ~3 ~78 stonebrick 0  
fill ~2 ~3 ~79 ~33 ~3 ~79 stonebrick 0  
fill ~2 ~3 ~80 ~36 ~3 ~80 stonebrick 0  
fill ~2 ~3 ~81 ~36 ~3 ~81 stonebrick 0  
fill ~2 ~3 ~82 ~37 ~3 ~82 stonebrick 0  
fill ~2 ~3 ~83 ~39 ~3 ~83 stonebrick 0  
fill ~2 ~3 ~84 ~34 ~3 ~84 stonebrick 0  
fill ~2 ~3 ~85 ~39 ~3 ~85 stonebrick 0  
fill ~2 ~3 ~86 ~50 ~3 ~86 stonebrick 0  
fill ~2 ~3 ~87 ~52 ~3 ~87 stonebrick 0  
fill ~2 ~3 ~88 ~52 ~3 ~88 stonebrick 0  
fill ~2 ~3 ~89 ~52 ~3 ~89 stonebrick 0  
fill ~2 ~3 ~90 ~50 ~3 ~90 stonebrick 0  
fill ~2 ~3 ~91 ~51 ~3 ~91 stonebrick 0  
fill ~2 ~3 ~92 ~50 ~3 ~92 stonebrick 0  
fill ~2 ~3 ~93 ~52 ~3 ~93 stonebrick 0  
fill ~2 ~3 ~94 ~52 ~3 ~94 stonebrick 0  
fill ~2 ~3 ~95 ~52 ~3 ~95 stonebrick 0  
fill ~2 ~3 ~96 ~50 ~3 ~96 stonebrick 0  
fill ~2 ~3 ~97 ~51 ~3 ~97 stonebrick 0  
fill ~2 ~3 ~98 ~50 ~3 ~98 stonebrick 0  
fill ~2 ~3 ~99 ~52 ~3 ~99 stonebrick 0  
fill ~2 ~3 ~100 ~52 ~3 ~100 stonebrick 0  
fill ~2 ~3 ~101 ~52 ~3 ~101 stonebrick 0  
fill ~2 ~3 ~102 ~50 ~3 ~102 stonebrick 0  
fill ~2 ~3 ~103 ~51 ~3 ~103 stonebrick 0  
fill ~2 ~3 ~104 ~50 ~3 ~104 stonebrick 0  
fill ~2 ~3 ~105 ~52 ~3 ~105 stonebrick 0  
fill ~2 ~3 ~106 ~52 ~3 ~106 stonebrick 0  
fill ~2 ~3 ~107 ~52 ~3 ~107 stonebrick 0  
fill ~2 ~3 ~108 ~50 ~3 ~108 stonebrick 0  
fill ~2 ~3 ~109 ~50 ~3 ~109 stonebrick 0  
fill ~3 ~3 ~42 ~35 ~3 ~42 stonebrick 0  
fill ~3 ~3 ~43 ~35 ~3 ~43 stonebrick 0  
fill ~3 ~3 ~44 ~3 ~3 ~50 planks 1 
setblock ~3 ~3 ~51 dark_oak_stairs 0 
setblock ~3 ~3 ~67 dark_oak_stairs 0  
fill ~4 ~3 ~44 ~35 ~3 ~44 stonebrick 0  
fill ~4 ~3 ~45 ~5 ~3 ~45 planks 1  
fill ~4 ~3 ~46 ~6 ~3 ~46 planks 1  
fill ~4 ~3 ~47 ~6 ~3 ~47 planks 1  
fill ~4 ~3 ~48 ~7 ~3 ~48 planks 1  
fill ~4 ~3 ~49 ~7 ~3 ~49 planks 1  
fill ~4 ~3 ~50 ~8 ~3 ~50 planks 1  
fill ~4 ~3 ~51 ~9 ~3 ~51 planks 1 
setblock ~4 ~3 ~52 dark_oak_stairs 3 
setblock ~4 ~3 ~53 dropper 5 
setblock ~4 ~3 ~65 dropper 5  
fill ~4 ~3 ~66 ~5 ~3 ~66 dark_oak_stairs 2  
fill ~4 ~3 ~67 ~9 ~3 ~67 planks 1  
fill ~4 ~3 ~74 ~35 ~3 ~74 stonebrick 0  
fill ~5 ~3 ~52 ~5 ~3 ~53 dark_oak_stairs 0  
fill ~5 ~3 ~54 ~5 ~3 ~55 dropper 5  
fill ~5 ~3 ~63 ~5 ~3 ~64 dropper 5 
setblock ~5 ~3 ~65 dark_oak_stairs 0  
fill ~6 ~3 ~2 ~7 ~3 ~2 log 1  
fill ~6 ~3 ~45 ~35 ~3 ~45 stonebrick 0  
fill ~6 ~3 ~52 ~9 ~3 ~52 planks 1  
fill ~6 ~3 ~53 ~9 ~3 ~53 planks 1 
setblock ~6 ~3 ~54 dark_oak_stairs 3 
setblock ~6 ~3 ~55 dark_oak_stairs 0  
fill ~6 ~3 ~56 ~6 ~3 ~57 dropper 5  
fill ~6 ~3 ~61 ~6 ~3 ~62 dropper 5 
setblock ~6 ~3 ~63 dark_oak_stairs 0 
setblock ~6 ~3 ~64 dark_oak_stairs 2  
fill ~6 ~3 ~65 ~9 ~3 ~65 planks 1  
fill ~6 ~3 ~66 ~9 ~3 ~66 planks 1  
fill ~6 ~3 ~73 ~35 ~3 ~73 stonebrick 0  
fill ~6 ~3 ~116 ~7 ~3 ~116 log 1  
fill ~7 ~3 ~46 ~33 ~3 ~46 stonebrick 0  
fill ~7 ~3 ~47 ~33 ~3 ~47 stonebrick 0  
fill ~7 ~3 ~54 ~9 ~3 ~54 planks 1  
fill ~7 ~3 ~55 ~9 ~3 ~55 planks 1 
setblock ~7 ~3 ~56 dark_oak_stairs 3 
setblock ~7 ~3 ~57 dark_oak_stairs 0  
fill ~7 ~3 ~58 ~7 ~3 ~60 dropper 5 
setblock ~7 ~3 ~61 dark_oak_stairs 0 
setblock ~7 ~3 ~62 dark_oak_stairs 2  
fill ~7 ~3 ~63 ~9 ~3 ~63 planks 1  
fill ~7 ~3 ~64 ~9 ~3 ~64 planks 1  
fill ~7 ~3 ~71 ~7 ~3 ~109 stonebrick 0  
fill ~8 ~3 ~1 ~9 ~3 ~1 log 1  
fill ~8 ~3 ~48 ~35 ~3 ~48 stonebrick 0  
fill ~8 ~3 ~49 ~35 ~3 ~49 stonebrick 0  
fill ~8 ~3 ~56 ~8 ~3 ~57 planks 1 
setblock ~8 ~3 ~58 dark_oak_stairs 3 
setblock ~8 ~3 ~59 dark_oak_stairs 0 
setblock ~8 ~3 ~60 dark_oak_stairs 2  
fill ~8 ~3 ~61 ~8 ~3 ~71 planks 1  
fill ~9 ~3 ~0 ~42 ~3 ~0 log 1 
setblock ~9 ~3 ~50 stonebrick 0  
fill ~9 ~3 ~56 ~9 ~3 ~61 stonebrick 0 
setblock ~9 ~3 ~62 planks 1  
fill ~9 ~3 ~69 ~35 ~3 ~69 stonebrick 0  
fill ~9 ~3 ~70 ~35 ~3 ~70 stonebrick 0  
fill ~9 ~3 ~71 ~33 ~3 ~71 stonebrick 0  
fill ~9 ~3 ~72 ~33 ~3 ~72 stonebrick 0  
fill ~9 ~3 ~118 ~42 ~3 ~118 log 1  
fill ~10 ~3 ~1 ~44 ~3 ~1 stonebrick 0  
fill ~10 ~3 ~2 ~44 ~3 ~2 stonebrick 0  
fill ~10 ~3 ~3 ~45 ~3 ~3 stonebrick 0  
fill ~10 ~3 ~4 ~45 ~3 ~4 stonebrick 0  
fill ~10 ~3 ~5 ~46 ~3 ~5 stonebrick 0  
fill ~10 ~3 ~6 ~48 ~3 ~6 stonebrick 0  
fill ~10 ~3 ~7 ~46 ~3 ~7 stonebrick 0  
fill ~10 ~3 ~8 ~50 ~3 ~8 stonebrick 0 
setblock ~10 ~3 ~50 redstone_block 0 
setblock ~10 ~3 ~51 lit_redstone_lamp 0  
fill ~10 ~3 ~52 ~10 ~3 ~54 log 9 
setblock ~10 ~3 ~55 lit_redstone_lamp 0 
setblock ~10 ~3 ~56 redstone_block 0  
fill ~10 ~3 ~57 ~35 ~3 ~57 stonebrick 0  
fill ~10 ~3 ~58 ~35 ~3 ~58 stonebrick 0  
fill ~10 ~3 ~59 ~34 ~3 ~59 stonebrick 0  
fill ~10 ~3 ~60 ~35 ~3 ~60 stonebrick 0  
fill ~10 ~3 ~61 ~35 ~3 ~61 stonebrick 0 
setblock ~10 ~3 ~62 redstone_block 0 
setblock ~10 ~3 ~63 lit_redstone_lamp 0  
fill ~10 ~3 ~64 ~10 ~3 ~66 log 9 
setblock ~10 ~3 ~67 lit_redstone_lamp 0 
setblock ~10 ~3 ~68 redstone_block 0  
fill ~10 ~3 ~110 ~51 ~3 ~110 stonebrick 0  
fill ~10 ~3 ~111 ~50 ~3 ~111 stonebrick 0  
fill ~10 ~3 ~112 ~48 ~3 ~112 stonebrick 0  
fill ~10 ~3 ~113 ~46 ~3 ~113 stonebrick 0  
fill ~10 ~3 ~114 ~45 ~3 ~114 stonebrick 0  
fill ~10 ~3 ~115 ~45 ~3 ~115 stonebrick 0  
fill ~10 ~3 ~116 ~44 ~3 ~116 stonebrick 0  
fill ~10 ~3 ~117 ~42 ~3 ~117 stonebrick 0 
setblock ~11 ~3 ~50 dropper 0  
fill ~11 ~3 ~51 ~15 ~3 ~51 stonebrick 0  
fill ~11 ~3 ~52 ~11 ~3 ~53 dark_oak_stairs 1  
fill ~11 ~3 ~54 ~14 ~3 ~54 dark_oak_stairs 2  
fill ~11 ~3 ~55 ~15 ~3 ~55 stonebrick 0 
setblock ~11 ~3 ~56 dark_oak_stairs 6 
setblock ~11 ~3 ~62 dropper 0  
fill ~11 ~3 ~63 ~15 ~3 ~63 stonebrick 0  
fill ~11 ~3 ~64 ~11 ~3 ~65 dark_oak_stairs 1  
fill ~11 ~3 ~66 ~14 ~3 ~66 dark_oak_stairs 2  
fill ~11 ~3 ~67 ~15 ~3 ~67 stonebrick 0 
setblock ~11 ~3 ~68 dark_oak_stairs 6  
fill ~12 ~3 ~50 ~14 ~3 ~50 stonebrick 0  
fill ~12 ~3 ~52 ~15 ~3 ~52 dark_oak_stairs 3  
fill ~12 ~3 ~53 ~14 ~3 ~53 dropper 9  
fill ~12 ~3 ~56 ~14 ~3 ~56 stonebrick 0  
fill ~12 ~3 ~62 ~14 ~3 ~62 stonebrick 0  
fill ~12 ~3 ~64 ~15 ~3 ~64 dark_oak_stairs 3  
fill ~12 ~3 ~65 ~14 ~3 ~65 dropper 9  
fill ~12 ~3 ~68 ~14 ~3 ~68 stonebrick 0 
setblock ~15 ~3 ~50 dark_oak_stairs 7  
fill ~15 ~3 ~53 ~15 ~3 ~54 dark_oak_stairs 0 
setblock ~15 ~3 ~56 dropper 0 
setblock ~15 ~3 ~62 dark_oak_stairs 7  
fill ~15 ~3 ~65 ~15 ~3 ~66 dark_oak_stairs 0 
setblock ~15 ~3 ~68 dropper 0 
setblock ~16 ~3 ~50 stonebrick 0 
setblock ~16 ~3 ~51 redstone_lamp 0  
fill ~16 ~3 ~52 ~16 ~3 ~54 log 9 
setblock ~16 ~3 ~55 redstone_lamp 0 
setblock ~16 ~3 ~56 stonebrick 0 
setblock ~16 ~3 ~62 stonebrick 0 
setblock ~16 ~3 ~63 lit_redstone_lamp 0  
fill ~16 ~3 ~64 ~16 ~3 ~66 log 9 
setblock ~16 ~3 ~67 lit_redstone_lamp 0 
setblock ~16 ~3 ~68 stonebrick 0 
setblock ~17 ~3 ~50 dropper 0  
fill ~17 ~3 ~51 ~21 ~3 ~51 stonebrick 0  
fill ~17 ~3 ~52 ~17 ~3 ~53 dark_oak_stairs 1  
fill ~17 ~3 ~54 ~20 ~3 ~54 dark_oak_stairs 2  
fill ~17 ~3 ~55 ~21 ~3 ~55 stonebrick 0 
setblock ~17 ~3 ~56 dark_oak_stairs 6 
setblock ~17 ~3 ~62 dropper 0  
fill ~17 ~3 ~63 ~21 ~3 ~63 stonebrick 0  
fill ~17 ~3 ~64 ~17 ~3 ~65 dark_oak_stairs 1  
fill ~17 ~3 ~66 ~20 ~3 ~66 dark_oak_stairs 2  
fill ~17 ~3 ~67 ~21 ~3 ~67 stonebrick 0 
setblock ~17 ~3 ~68 dark_oak_stairs 6  
fill ~18 ~3 ~50 ~20 ~3 ~50 stonebrick 0  
fill ~18 ~3 ~52 ~21 ~3 ~52 dark_oak_stairs 3  
fill ~18 ~3 ~53 ~20 ~3 ~53 dropper 9  
fill ~18 ~3 ~56 ~20 ~3 ~56 stonebrick 0  
fill ~18 ~3 ~62 ~20 ~3 ~62 stonebrick 0  
fill ~18 ~3 ~64 ~21 ~3 ~64 dark_oak_stairs 3  
fill ~18 ~3 ~65 ~20 ~3 ~65 dropper 9  
fill ~18 ~3 ~68 ~20 ~3 ~68 stonebrick 0 
setblock ~21 ~3 ~50 dark_oak_stairs 7  
fill ~21 ~3 ~53 ~21 ~3 ~54 dark_oak_stairs 0 
setblock ~21 ~3 ~56 dropper 0 
setblock ~21 ~3 ~62 dark_oak_stairs 7  
fill ~21 ~3 ~65 ~21 ~3 ~66 dark_oak_stairs 0 
setblock ~21 ~3 ~68 dropper 0 
setblock ~22 ~3 ~50 stonebrick 0 
setblock ~22 ~3 ~51 redstone_lamp 0  
fill ~22 ~3 ~52 ~22 ~3 ~54 log 9 
setblock ~22 ~3 ~55 redstone_lamp 0 
setblock ~22 ~3 ~56 stonebrick 0 
setblock ~22 ~3 ~62 stonebrick 0 
setblock ~22 ~3 ~63 lit_redstone_lamp 0  
fill ~22 ~3 ~64 ~22 ~3 ~66 log 9 
setblock ~22 ~3 ~67 lit_redstone_lamp 0 
setblock ~22 ~3 ~68 stonebrick 0 
setblock ~23 ~3 ~50 dropper 0  
fill ~23 ~3 ~51 ~27 ~3 ~51 stonebrick 0  
fill ~23 ~3 ~52 ~23 ~3 ~53 dark_oak_stairs 1  
fill ~23 ~3 ~54 ~26 ~3 ~54 dark_oak_stairs 2  
fill ~23 ~3 ~55 ~27 ~3 ~55 stonebrick 0 
setblock ~23 ~3 ~56 dark_oak_stairs 6 
setblock ~23 ~3 ~62 dropper 0  
fill ~23 ~3 ~63 ~27 ~3 ~63 stonebrick 0  
fill ~23 ~3 ~64 ~23 ~3 ~65 dark_oak_stairs 1  
fill ~23 ~3 ~66 ~26 ~3 ~66 dark_oak_stairs 2  
fill ~23 ~3 ~67 ~27 ~3 ~67 stonebrick 0 
setblock ~23 ~3 ~68 dark_oak_stairs 6  
fill ~24 ~3 ~50 ~26 ~3 ~50 stonebrick 0  
fill ~24 ~3 ~52 ~27 ~3 ~52 dark_oak_stairs 3  
fill ~24 ~3 ~53 ~26 ~3 ~53 dropper 9  
fill ~24 ~3 ~56 ~26 ~3 ~56 stonebrick 0  
fill ~24 ~3 ~62 ~26 ~3 ~62 stonebrick 0  
fill ~24 ~3 ~64 ~27 ~3 ~64 dark_oak_stairs 3  
fill ~24 ~3 ~65 ~26 ~3 ~65 dropper 9  
fill ~24 ~3 ~68 ~26 ~3 ~68 stonebrick 0 
setblock ~27 ~3 ~50 dark_oak_stairs 7  
fill ~27 ~3 ~53 ~27 ~3 ~54 dark_oak_stairs 0 
setblock ~27 ~3 ~56 dropper 0 
setblock ~27 ~3 ~62 dark_oak_stairs 7  
fill ~27 ~3 ~65 ~27 ~3 ~66 dark_oak_stairs 0 
setblock ~27 ~3 ~68 dropper 0 
setblock ~28 ~3 ~50 stonebrick 0 
setblock ~28 ~3 ~51 redstone_lamp 0  
fill ~28 ~3 ~52 ~28 ~3 ~54 log 9 
setblock ~28 ~3 ~55 redstone_lamp 0 
setblock ~28 ~3 ~56 stonebrick 0 
setblock ~28 ~3 ~62 stonebrick 0 
setblock ~28 ~3 ~63 lit_redstone_lamp 0  
fill ~28 ~3 ~64 ~28 ~3 ~66 log 9 
setblock ~28 ~3 ~67 lit_redstone_lamp 0 
setblock ~28 ~3 ~68 stonebrick 0 
setblock ~29 ~3 ~50 dropper 0  
fill ~29 ~3 ~51 ~33 ~3 ~51 stonebrick 0  
fill ~29 ~3 ~52 ~29 ~3 ~53 dark_oak_stairs 1  
fill ~29 ~3 ~54 ~32 ~3 ~54 dark_oak_stairs 2  
fill ~29 ~3 ~55 ~33 ~3 ~55 stonebrick 0 
setblock ~29 ~3 ~56 dark_oak_stairs 6 
setblock ~29 ~3 ~62 dropper 0  
fill ~29 ~3 ~63 ~33 ~3 ~63 stonebrick 0  
fill ~29 ~3 ~64 ~29 ~3 ~65 dark_oak_stairs 1  
fill ~29 ~3 ~66 ~32 ~3 ~66 dark_oak_stairs 2  
fill ~29 ~3 ~67 ~33 ~3 ~67 stonebrick 0 
setblock ~29 ~3 ~68 dark_oak_stairs 6  
fill ~30 ~3 ~50 ~32 ~3 ~50 stonebrick 0  
fill ~30 ~3 ~52 ~33 ~3 ~52 dark_oak_stairs 3  
fill ~30 ~3 ~53 ~32 ~3 ~53 dropper 9  
fill ~30 ~3 ~56 ~32 ~3 ~56 stonebrick 0  
fill ~30 ~3 ~62 ~32 ~3 ~62 stonebrick 0  
fill ~30 ~3 ~64 ~33 ~3 ~64 dark_oak_stairs 3  
fill ~30 ~3 ~65 ~32 ~3 ~65 dropper 9  
fill ~30 ~3 ~68 ~32 ~3 ~68 stonebrick 0 
setblock ~33 ~3 ~50 dark_oak_stairs 7  
fill ~33 ~3 ~53 ~33 ~3 ~54 dark_oak_stairs 0 
setblock ~33 ~3 ~56 dropper 0 
setblock ~33 ~3 ~62 dark_oak_stairs 7  
fill ~33 ~3 ~65 ~33 ~3 ~66 dark_oak_stairs 0 
setblock ~33 ~3 ~68 dropper 0  
fill ~34 ~3 ~39 ~34 ~3 ~40 redstone_block 0  
fill ~34 ~3 ~46 ~34 ~3 ~47 redstone_block 0  
fill ~34 ~3 ~50 ~35 ~3 ~50 stonebrick 0  
fill ~34 ~3 ~51 ~35 ~3 ~51 dropper 9  
fill ~34 ~3 ~52 ~35 ~3 ~52 dropper 0  
fill ~34 ~3 ~53 ~36 ~3 ~53 dropper 0  
fill ~34 ~3 ~54 ~35 ~3 ~54 dropper 0  
fill ~34 ~3 ~55 ~35 ~3 ~55 dropper 9 
setblock ~34 ~3 ~56 stonebrick 0 
setblock ~34 ~3 ~62 stonebrick 0  
fill ~34 ~3 ~63 ~35 ~3 ~63 dropper 9  
fill ~34 ~3 ~64 ~35 ~3 ~64 dropper 0  
fill ~34 ~3 ~65 ~36 ~3 ~65 dropper 0  
fill ~34 ~3 ~66 ~35 ~3 ~66 dropper 0  
fill ~34 ~3 ~67 ~35 ~3 ~67 dropper 9  
fill ~34 ~3 ~68 ~35 ~3 ~68 stonebrick 0  
fill ~34 ~3 ~71 ~34 ~3 ~72 redstone_block 0  
fill ~34 ~3 ~78 ~34 ~3 ~79 redstone_block 0 
setblock ~35 ~3 ~34 redstone_block 0 
setblock ~35 ~3 ~39 stonebrick 0 
setblock ~35 ~3 ~40 dropper 0  
fill ~35 ~3 ~46 ~36 ~3 ~46 dropper 0  
fill ~35 ~3 ~47 ~36 ~3 ~47 dropper 0  
fill ~35 ~3 ~56 ~36 ~3 ~56 dropper 0 
setblock ~35 ~3 ~59 stone_slab 8  
fill ~35 ~3 ~62 ~36 ~3 ~62 dropper 0  
fill ~35 ~3 ~71 ~36 ~3 ~71 dropper 0  
fill ~35 ~3 ~72 ~36 ~3 ~72 dropper 0 
setblock ~35 ~3 ~78 dropper 0 
setblock ~35 ~3 ~79 stonebrick 0 
setblock ~35 ~3 ~84 redstone_block 0  
fill ~36 ~3 ~34 ~40 ~3 ~34 stonebrick 0  
fill ~36 ~3 ~39 ~39 ~3 ~39 dropper 0 
setblock ~36 ~3 ~40 dropper 9  
fill ~36 ~3 ~41 ~36 ~3 ~51 dropper 0 
setblock ~36 ~3 ~52 dropper 9 
setblock ~36 ~3 ~54 dropper 9 
setblock ~36 ~3 ~55 dropper 0  
fill ~36 ~3 ~57 ~39 ~3 ~57 dropper 0  
fill ~36 ~3 ~58 ~39 ~3 ~58 dropper 0  
fill ~36 ~3 ~59 ~43 ~3 ~59 dropper 0  
fill ~36 ~3 ~60 ~39 ~3 ~60 dropper 0  
fill ~36 ~3 ~61 ~39 ~3 ~61 dropper 0 
setblock ~36 ~3 ~63 dropper 0 
setblock ~36 ~3 ~64 dropper 9 
setblock ~36 ~3 ~66 dropper 9  
fill ~36 ~3 ~67 ~38 ~3 ~67 dropper 0  
fill ~36 ~3 ~68 ~38 ~3 ~68 dropper 0  
fill ~36 ~3 ~69 ~37 ~3 ~69 dropper 0  
fill ~36 ~3 ~70 ~37 ~3 ~70 dropper 0  
fill ~36 ~3 ~73 ~37 ~3 ~73 dropper 0  
fill ~36 ~3 ~74 ~37 ~3 ~74 dropper 0  
fill ~36 ~3 ~75 ~37 ~3 ~75 dropper 0  
fill ~36 ~3 ~76 ~36 ~3 ~77 dropper 0 
setblock ~36 ~3 ~78 dropper 9  
fill ~36 ~3 ~79 ~39 ~3 ~79 dropper 0  
fill ~36 ~3 ~84 ~40 ~3 ~84 stonebrick 0  
fill ~37 ~3 ~37 ~38 ~3 ~37 dropper 9  
fill ~37 ~3 ~38 ~38 ~3 ~38 dropper 0  
fill ~37 ~3 ~40 ~39 ~3 ~40 dropper 0  
fill ~37 ~3 ~41 ~37 ~3 ~42 dropper 9  
fill ~37 ~3 ~43 ~37 ~3 ~45 dropper 0  
fill ~37 ~3 ~46 ~37 ~3 ~47 dropper 9  
fill ~37 ~3 ~48 ~37 ~3 ~52 dropper 0 
setblock ~37 ~3 ~53 dropper 9  
fill ~37 ~3 ~54 ~39 ~3 ~54 dropper 0  
fill ~37 ~3 ~55 ~37 ~3 ~56 dropper 9  
fill ~37 ~3 ~62 ~37 ~3 ~63 dropper 9  
fill ~37 ~3 ~64 ~39 ~3 ~64 dropper 0 
setblock ~37 ~3 ~65 dropper 9 
setblock ~37 ~3 ~66 dropper 0  
fill ~37 ~3 ~71 ~37 ~3 ~72 dropper 9  
fill ~37 ~3 ~76 ~37 ~3 ~77 dropper 9  
fill ~37 ~3 ~78 ~39 ~3 ~78 dropper 0  
fill ~37 ~3 ~80 ~38 ~3 ~80 dropper 0  
fill ~37 ~3 ~81 ~38 ~3 ~81 dropper 9 
setblock ~38 ~3 ~36 dropper 9  
fill ~38 ~3 ~41 ~38 ~3 ~42 dropper 0  
fill ~38 ~3 ~43 ~38 ~3 ~45 dropper 9  
fill ~38 ~3 ~46 ~40 ~3 ~46 dropper 0  
fill ~38 ~3 ~47 ~40 ~3 ~47 dropper 0  
fill ~38 ~3 ~48 ~38 ~3 ~49 dropper 9  
fill ~38 ~3 ~50 ~38 ~3 ~51 dropper 0 
setblock ~38 ~3 ~52 dropper 9 
setblock ~38 ~3 ~53 dropper 0  
fill ~38 ~3 ~55 ~40 ~3 ~55 dropper 0  
fill ~38 ~3 ~56 ~40 ~3 ~56 dropper 0  
fill ~38 ~3 ~62 ~40 ~3 ~62 dropper 0  
fill ~38 ~3 ~63 ~40 ~3 ~63 dropper 0 
setblock ~38 ~3 ~65 dropper 0 
setblock ~38 ~3 ~66 dropper 9  
fill ~38 ~3 ~69 ~38 ~3 ~70 dropper 9  
fill ~38 ~3 ~71 ~40 ~3 ~71 dropper 0  
fill ~38 ~3 ~72 ~40 ~3 ~72 dropper 0  
fill ~38 ~3 ~73 ~38 ~3 ~75 dropper 9  
fill ~38 ~3 ~76 ~38 ~3 ~80 dropper 0 
setblock ~38 ~3 ~82 dropper 9  
fill ~39 ~3 ~36 ~41 ~3 ~36 dropper 0  
fill ~39 ~3 ~37 ~43 ~3 ~37 dropper 0 
setblock ~39 ~3 ~38 dropper 9  
fill ~39 ~3 ~41 ~39 ~3 ~42 dropper 9  
fill ~39 ~3 ~43 ~41 ~3 ~43 dropper 0  
fill ~39 ~3 ~44 ~40 ~3 ~44 dropper 0  
fill ~39 ~3 ~45 ~40 ~3 ~45 dropper 0  
fill ~39 ~3 ~48 ~40 ~3 ~48 dropper 0  
fill ~39 ~3 ~49 ~40 ~3 ~49 dropper 0  
fill ~39 ~3 ~50 ~39 ~3 ~51 dropper 9  
fill ~39 ~3 ~52 ~42 ~3 ~52 dropper 0 
setblock ~39 ~3 ~53 dropper 9 
setblock ~39 ~3 ~65 dropper 9  
fill ~39 ~3 ~66 ~42 ~3 ~66 dropper 0  
fill ~39 ~3 ~67 ~39 ~3 ~68 dropper 9  
fill ~39 ~3 ~69 ~40 ~3 ~69 dropper 0  
fill ~39 ~3 ~70 ~40 ~3 ~70 dropper 0  
fill ~39 ~3 ~73 ~40 ~3 ~73 dropper 0  
fill ~39 ~3 ~74 ~40 ~3 ~74 dropper 0  
fill ~39 ~3 ~75 ~41 ~3 ~75 dropper 0  
fill ~39 ~3 ~76 ~39 ~3 ~77 dropper 9 
setblock ~39 ~3 ~80 dropper 9  
fill ~39 ~3 ~81 ~43 ~3 ~81 dropper 0  
fill ~39 ~3 ~82 ~41 ~3 ~82 dropper 0  
fill ~40 ~3 ~33 ~41 ~3 ~33 redstone_block 0 
setblock ~40 ~3 ~35 dropper 0  
fill ~40 ~3 ~38 ~41 ~3 ~38 dropper 0  
fill ~40 ~3 ~39 ~41 ~3 ~39 dropper 9  
fill ~40 ~3 ~40 ~40 ~3 ~39 dropper 9  
fill ~40 ~3 ~41 ~42 ~3 ~41 dropper 0  
fill ~40 ~3 ~42 ~41 ~3 ~42 dropper 0  
fill ~40 ~3 ~50 ~41 ~3 ~50 dropper 0  
fill ~40 ~3 ~51 ~41 ~3 ~51 dropper 0 
setblock ~40 ~3 ~53 dropper 0  
fill ~40 ~3 ~54 ~41 ~3 ~54 dropper 9 
setblock ~40 ~3 ~57 stonebrick 0 
setblock ~40 ~3 ~58 dark_oak_stairs 3 
setblock ~40 ~3 ~60 dark_oak_stairs 2 
setblock ~40 ~3 ~61 stonebrick 0  
fill ~40 ~3 ~64 ~41 ~3 ~64 dropper 9 
setblock ~40 ~3 ~65 dropper 0  
fill ~40 ~3 ~67 ~41 ~3 ~67 dropper 0  
fill ~40 ~3 ~68 ~41 ~3 ~68 dropper 0  
fill ~40 ~3 ~76 ~41 ~3 ~76 dropper 0  
fill ~40 ~3 ~77 ~42 ~3 ~77 dropper 0  
fill ~40 ~3 ~78 ~40 ~3 ~79 dropper 9  
fill ~40 ~3 ~80 ~41 ~3 ~80 dropper 0 
setblock ~40 ~3 ~83 dropper 0  
fill ~40 ~3 ~85 ~41 ~3 ~85 redstone_block 0 
setblock ~41 ~3 ~34 dropper 0 
setblock ~41 ~3 ~35 dropper 9  
fill ~41 ~3 ~40 ~44 ~3 ~40 dropper 0  
fill ~41 ~3 ~44 ~46 ~3 ~44 stonebrick 0  
fill ~41 ~3 ~45 ~45 ~3 ~45 stonebrick 0  
fill ~41 ~3 ~46 ~44 ~3 ~46 stonebrick 0  
fill ~41 ~3 ~47 ~44 ~3 ~47 stonebrick 0  
fill ~41 ~3 ~48 ~44 ~3 ~48 stonebrick 0  
fill ~41 ~3 ~49 ~44 ~3 ~49 stonebrick 0 
setblock ~41 ~3 ~53 dark_oak_stairs 1 
setblock ~41 ~3 ~55 dark_oak_stairs 1  
fill ~41 ~3 ~56 ~44 ~3 ~56 stonebrick 0 
setblock ~41 ~3 ~57 dark_oak_stairs 3 
setblock ~41 ~3 ~58 dark_oak_stairs 1 
setblock ~41 ~3 ~60 dark_oak_stairs 1 
setblock ~41 ~3 ~61 dark_oak_stairs 2  
fill ~41 ~3 ~62 ~44 ~3 ~62 stonebrick 0 
setblock ~41 ~3 ~63 dark_oak_stairs 1 
setblock ~41 ~3 ~65 dark_oak_stairs 1  
fill ~41 ~3 ~69 ~44 ~3 ~69 stonebrick 0  
fill ~41 ~3 ~70 ~44 ~3 ~70 stonebrick 0  
fill ~41 ~3 ~71 ~44 ~3 ~71 stonebrick 0  
fill ~41 ~3 ~72 ~44 ~3 ~72 stonebrick 0  
fill ~41 ~3 ~73 ~45 ~3 ~73 stonebrick 0  
fill ~41 ~3 ~74 ~53 ~3 ~74 stonebrick 0  
fill ~41 ~3 ~78 ~44 ~3 ~78 dropper 0 
setblock ~41 ~3 ~79 dropper 9 
setblock ~41 ~3 ~83 dropper 9 
setblock ~41 ~3 ~84 dropper 0  
fill ~42 ~3 ~33 ~46 ~3 ~33 stonebrick 0  
fill ~42 ~3 ~34 ~46 ~3 ~34 stonebrick 0  
fill ~42 ~3 ~35 ~52 ~3 ~35 dropper 0  
fill ~42 ~3 ~36 ~43 ~3 ~36 dropper 9  
fill ~42 ~3 ~38 ~43 ~3 ~38 dropper 9  
fill ~42 ~3 ~39 ~54 ~3 ~39 dropper 0  
fill ~42 ~3 ~42 ~53 ~3 ~42 stonebrick 0  
fill ~42 ~3 ~43 ~53 ~3 ~43 stonebrick 0  
fill ~42 ~3 ~50 ~45 ~3 ~50 stonebrick 0  
fill ~42 ~3 ~51 ~47 ~3 ~51 stonebrick 0  
fill ~42 ~3 ~53 ~46 ~3 ~53 dark_oak_stairs 3  
fill ~42 ~3 ~54 ~47 ~3 ~54 dropper 0  
fill ~42 ~3 ~55 ~48 ~3 ~55 dark_oak_stairs 2 
setblock ~42 ~3 ~57 dark_oak_stairs 0  
fill ~42 ~3 ~58 ~43 ~3 ~58 dropper 0  
fill ~42 ~3 ~60 ~43 ~3 ~60 dropper 0 
setblock ~42 ~3 ~61 dark_oak_stairs 0  
fill ~42 ~3 ~63 ~47 ~3 ~63 dark_oak_stairs 3  
fill ~42 ~3 ~64 ~47 ~3 ~64 dropper 0  
fill ~42 ~3 ~65 ~46 ~3 ~65 dark_oak_stairs 2  
fill ~42 ~3 ~67 ~47 ~3 ~67 stonebrick 0  
fill ~42 ~3 ~68 ~45 ~3 ~68 stonebrick 0  
fill ~42 ~3 ~75 ~53 ~3 ~75 stonebrick 0  
fill ~42 ~3 ~76 ~53 ~3 ~76 stonebrick 0  
fill ~42 ~3 ~79 ~54 ~3 ~79 dropper 0  
fill ~42 ~3 ~80 ~43 ~3 ~80 dropper 9  
fill ~42 ~3 ~82 ~43 ~3 ~82 dropper 9  
fill ~42 ~3 ~83 ~52 ~3 ~83 dropper 0  
fill ~42 ~3 ~84 ~46 ~3 ~84 stonebrick 0  
fill ~42 ~3 ~85 ~46 ~3 ~85 stonebrick 0 
setblock ~43 ~3 ~0 dark_oak_stairs 1  
fill ~43 ~3 ~41 ~52 ~3 ~41 stonebrick 0  
fill ~43 ~3 ~52 ~45 ~3 ~52 stonebrick 0 
setblock ~43 ~3 ~57 stonebrick 0 
setblock ~43 ~3 ~61 stonebrick 0  
fill ~43 ~3 ~66 ~45 ~3 ~66 stonebrick 0  
fill ~43 ~3 ~77 ~52 ~3 ~77 stonebrick 0  
fill ~43 ~3 ~117 ~51 ~3 ~117 planks 1 
setblock ~43 ~3 ~118 dark_oak_stairs 1  
fill ~44 ~3 ~0 ~46 ~3 ~0 dark_oak_stairs 2  
fill ~44 ~3 ~36 ~46 ~3 ~36 dropper 0  
fill ~44 ~3 ~37 ~46 ~3 ~37 dropper 9  
fill ~44 ~3 ~38 ~50 ~3 ~38 dropper 0  
fill ~44 ~3 ~57 ~45 ~3 ~57 bookshelf 0 
setblock ~44 ~3 ~58 dark_oak_stairs 1 
setblock ~44 ~3 ~59 glowstone 0 
setblock ~44 ~3 ~60 dark_oak_stairs 1  
fill ~44 ~3 ~61 ~45 ~3 ~61 bookshelf 0  
fill ~44 ~3 ~80 ~50 ~3 ~80 dropper 0  
fill ~44 ~3 ~81 ~46 ~3 ~81 dropper 9  
fill ~44 ~3 ~82 ~46 ~3 ~82 dropper 0  
fill ~44 ~3 ~118 ~46 ~3 ~118 dark_oak_stairs 3  
fill ~45 ~3 ~1 ~51 ~3 ~1 planks 1  
fill ~45 ~3 ~2 ~51 ~3 ~2 planks 1  
fill ~45 ~3 ~40 ~50 ~3 ~40 stonebrick 0  
fill ~45 ~3 ~46 ~45 ~3 ~49 obsidian 0 
setblock ~45 ~3 ~56 redstone_block 0 
setblock ~45 ~3 ~58 dark_oak_stairs 2 
setblock ~45 ~3 ~59 dark_oak_stairs 1 
setblock ~45 ~3 ~60 dark_oak_stairs 3 
setblock ~45 ~3 ~62 redstone_block 0  
fill ~45 ~3 ~69 ~45 ~3 ~72 dropper 0  
fill ~45 ~3 ~78 ~50 ~3 ~78 stonebrick 0  
fill ~45 ~3 ~116 ~51 ~3 ~116 planks 1  
fill ~46 ~3 ~3 ~52 ~3 ~3 planks 1  
fill ~46 ~3 ~4 ~52 ~3 ~4 planks 1  
fill ~46 ~3 ~45 ~46 ~3 ~46 dark_oak_stairs 1  
fill ~46 ~3 ~47 ~50 ~3 ~47 stone_slab 8  
fill ~46 ~3 ~48 ~49 ~3 ~48 stone_slab 8 
setblock ~46 ~3 ~49 dark_oak_stairs 1  
fill ~46 ~3 ~50 ~47 ~3 ~50 dark_oak_stairs 2 
setblock ~46 ~3 ~52 dropper 0  
fill ~46 ~3 ~56 ~74 ~3 ~56 stonebrick 0  
fill ~46 ~3 ~57 ~74 ~3 ~57 stonebrick 0  
fill ~46 ~3 ~58 ~46 ~5 ~58 bookshelf 0  
fill ~46 ~3 ~59 ~46 ~6 ~59 bookshelf 0  
fill ~46 ~3 ~60 ~46 ~5 ~60 bookshelf 0  
fill ~46 ~3 ~61 ~74 ~3 ~61 stonebrick 0  
fill ~46 ~3 ~62 ~74 ~3 ~62 stonebrick 0 
setblock ~46 ~3 ~66 dropper 0  
fill ~46 ~3 ~68 ~47 ~3 ~68 dark_oak_stairs 3 
setblock ~46 ~3 ~69 dark_oak_stairs 1  
fill ~46 ~3 ~70 ~46 ~3 ~71 stone_slab 8  
fill ~46 ~3 ~72 ~46 ~3 ~73 dark_oak_stairs 1  
fill ~46 ~3 ~114 ~52 ~3 ~114 planks 1  
fill ~46 ~3 ~115 ~52 ~3 ~115 planks 1 
setblock ~47 ~3 ~0 dark_oak_stairs 0  
fill ~47 ~3 ~5 ~54 ~3 ~5 planks 1  
fill ~47 ~3 ~33 ~48 ~3 ~33 redstone_block 0  
fill ~47 ~3 ~34 ~48 ~3 ~34 dropper 0  
fill ~47 ~3 ~36 ~48 ~3 ~36 dropper 9  
fill ~47 ~3 ~37 ~48 ~3 ~37 dropper 0  
fill ~47 ~3 ~44 ~51 ~3 ~44 obsidian 0 
setblock ~47 ~3 ~45 dark_oak_stairs 3 
setblock ~47 ~3 ~46 dropper 0 
setblock ~47 ~3 ~49 dropper 0  
fill ~47 ~3 ~52 ~48 ~3 ~52 dark_oak_stairs 3 
setblock ~47 ~3 ~53 dark_oak_stairs 1  
fill ~47 ~3 ~58 ~73 ~3 ~58 stonebrick 0  
fill ~47 ~3 ~59 ~73 ~3 ~59 stonebrick 0  
fill ~47 ~3 ~60 ~73 ~3 ~60 stonebrick 0 
setblock ~47 ~3 ~65 dark_oak_stairs 1  
fill ~47 ~3 ~66 ~48 ~3 ~66 dark_oak_stairs 2 
setblock ~47 ~3 ~69 dropper 0  
fill ~47 ~3 ~70 ~47 ~3 ~71 end_portal 0 
setblock ~47 ~3 ~72 dropper 0 
setblock ~47 ~3 ~73 dark_oak_stairs 2  
fill ~47 ~3 ~81 ~48 ~3 ~81 dropper 0  
fill ~47 ~3 ~82 ~48 ~3 ~82 dropper 9  
fill ~47 ~3 ~84 ~48 ~3 ~84 dropper 0  
fill ~47 ~3 ~85 ~48 ~3 ~85 redstone_block 0  
fill ~47 ~3 ~113 ~54 ~3 ~113 planks 1 
setblock ~47 ~3 ~118 dark_oak_stairs 0  
fill ~48 ~3 ~7 ~58 ~3 ~7 planks 1  
fill ~48 ~3 ~45 ~49 ~3 ~45 stone_slab 8  
fill ~48 ~3 ~46 ~49 ~3 ~46 stone_slab 8 
setblock ~48 ~3 ~49 stone_slab 8  
fill ~48 ~3 ~50 ~48 ~7 ~50 log 1 
setblock ~48 ~3 ~51 dropper 0  
fill ~48 ~3 ~53 ~50 ~3 ~53 dropper 0 
setblock ~48 ~3 ~54 dark_oak_stairs 0 
setblock ~48 ~3 ~63 dark_oak_stairs 0  
fill ~48 ~3 ~64 ~51 ~3 ~64 dark_oak_stairs 3  
fill ~48 ~3 ~65 ~50 ~3 ~65 dropper 0 
setblock ~48 ~3 ~67 dropper 0  
fill ~48 ~3 ~68 ~48 ~7 ~68 log 1  
fill ~48 ~3 ~69 ~48 ~3 ~70 stone_slab 8  
fill ~48 ~3 ~71 ~48 ~3 ~72 end_portal 0  
fill ~48 ~3 ~73 ~49 ~3 ~73 stone_slab 8 
setblock ~49 ~3 ~0 dark_oak_stairs 1  
fill ~49 ~3 ~6 ~56 ~3 ~6 planks 1  
fill ~49 ~3 ~33 ~51 ~3 ~33 stonebrick 0  
fill ~49 ~3 ~34 ~51 ~3 ~34 stonebrick 0  
fill ~49 ~3 ~36 ~53 ~3 ~36 dropper 0  
fill ~49 ~3 ~37 ~50 ~3 ~37 dropper 9  
fill ~49 ~3 ~49 ~50 ~3 ~49 dropper 0 
setblock ~49 ~3 ~50 dark_oak_stairs 0 
setblock ~49 ~3 ~51 dark_oak_stairs 3 
setblock ~49 ~3 ~52 dark_oak_stairs 1  
fill ~49 ~3 ~54 ~50 ~3 ~54 dark_oak_stairs 2 
setblock ~49 ~3 ~55 dropper 0 
setblock ~49 ~3 ~63 dropper 0 
setblock ~49 ~3 ~66 dark_oak_stairs 1 
setblock ~49 ~3 ~67 dark_oak_stairs 3 
setblock ~49 ~3 ~68 dark_oak_stairs 0  
fill ~49 ~3 ~69 ~50 ~3 ~69 dropper 0 
setblock ~49 ~3 ~70 end_portal 0  
fill ~49 ~3 ~71 ~50 ~3 ~71 stone_slab 8 
setblock ~49 ~3 ~72 end_portal 0  
fill ~49 ~3 ~81 ~50 ~3 ~81 dropper 9  
fill ~49 ~3 ~82 ~53 ~3 ~82 dropper 0  
fill ~49 ~3 ~84 ~51 ~3 ~84 stonebrick 0  
fill ~49 ~3 ~85 ~51 ~3 ~85 stonebrick 0  
fill ~49 ~3 ~112 ~56 ~3 ~112 planks 1 
setblock ~49 ~3 ~118 dark_oak_stairs 1  
fill ~50 ~3 ~0 ~52 ~3 ~0 dark_oak_stairs 2 
setblock ~50 ~3 ~45 dark_oak_stairs 3 
setblock ~50 ~3 ~46 dropper 0 
setblock ~50 ~3 ~48 dropper 0 
setblock ~50 ~3 ~50 dark_oak_stairs 2  
fill ~50 ~3 ~51 ~52 ~3 ~51 dropper 0  
fill ~50 ~3 ~52 ~51 ~3 ~52 dropper 0  
fill ~50 ~3 ~55 ~70 ~3 ~55 stonebrick 0  
fill ~50 ~3 ~63 ~70 ~3 ~63 stonebrick 0  
fill ~50 ~3 ~66 ~51 ~3 ~66 dropper 0  
fill ~50 ~3 ~67 ~52 ~3 ~67 dropper 0 
setblock ~50 ~3 ~68 dark_oak_stairs 3 
setblock ~50 ~3 ~70 dropper 0 
setblock ~50 ~3 ~72 dropper 0 
setblock ~50 ~3 ~73 dark_oak_stairs 2  
fill ~50 ~3 ~118 ~51 ~3 ~118 dark_oak_stairs 3  
fill ~51 ~3 ~8 ~57 ~3 ~8 planks 1 
setblock ~51 ~3 ~9 redstone_block 0 
setblock ~51 ~3 ~10 dark_oak_stairs 5 
setblock ~51 ~3 ~14 dropper 0 
setblock ~51 ~3 ~16 dark_oak_stairs 5 
setblock ~51 ~3 ~20 dropper 0 
setblock ~51 ~3 ~22 dark_oak_stairs 5 
setblock ~51 ~3 ~26 dropper 0 
setblock ~51 ~3 ~28 dark_oak_stairs 5 
setblock ~51 ~3 ~32 dropper 0  
fill ~51 ~3 ~37 ~52 ~3 ~37 dropper 0  
fill ~51 ~3 ~38 ~52 ~3 ~38 dropper 9  
fill ~51 ~3 ~40 ~53 ~3 ~40 dropper 0  
fill ~51 ~3 ~45 ~51 ~3 ~46 dark_oak_stairs 0  
fill ~51 ~3 ~47 ~51 ~7 ~47 log 1 
setblock ~51 ~3 ~48 dark_oak_stairs 2 
setblock ~51 ~3 ~49 dark_oak_stairs 0  
fill ~51 ~3 ~50 ~53 ~3 ~50 dropper 0 
setblock ~51 ~3 ~53 dark_oak_stairs 2 
setblock ~51 ~3 ~54 dark_oak_stairs 0 
setblock ~51 ~3 ~65 dark_oak_stairs 0  
fill ~51 ~3 ~68 ~53 ~3 ~68 dropper 0 
setblock ~51 ~3 ~69 dark_oak_stairs 0 
setblock ~51 ~3 ~70 dark_oak_stairs 3  
fill ~51 ~3 ~71 ~51 ~7 ~71 log 1  
fill ~51 ~3 ~72 ~51 ~3 ~73 dark_oak_stairs 0  
fill ~51 ~3 ~78 ~53 ~3 ~78 dropper 0  
fill ~51 ~3 ~80 ~52 ~3 ~80 dropper 9  
fill ~51 ~3 ~81 ~52 ~3 ~81 dropper 0 
setblock ~51 ~3 ~86 dark_oak_stairs 5 
setblock ~51 ~3 ~90 dropper 0 
setblock ~51 ~3 ~92 dark_oak_stairs 5 
setblock ~51 ~3 ~96 dropper 0 
setblock ~51 ~3 ~98 dark_oak_stairs 5 
setblock ~51 ~3 ~102 dropper 0 
setblock ~51 ~3 ~104 dark_oak_stairs 5 
setblock ~51 ~3 ~108 dropper 0 
setblock ~51 ~3 ~109 redstone_block 0  
fill ~51 ~3 ~111 ~58 ~3 ~111 planks 1 
setblock ~52 ~3 ~1 dark_oak_stairs 1 
setblock ~52 ~3 ~2 dark_oak_stairs 2 
setblock ~52 ~3 ~9 lit_redstone_lamp 0 
setblock ~52 ~3 ~10 stonebrick 0 
setblock ~52 ~3 ~14 stonebrick 0 
setblock ~52 ~3 ~15 redstone_lamp 0 
setblock ~52 ~3 ~16 stonebrick 0 
setblock ~52 ~3 ~20 stonebrick 0 
setblock ~52 ~3 ~21 redstone_lamp 0 
setblock ~52 ~3 ~22 stonebrick 0 
setblock ~52 ~3 ~26 stonebrick 0 
setblock ~52 ~3 ~27 redstone_lamp 0 
setblock ~52 ~3 ~28 stonebrick 0 
setblock ~52 ~3 ~32 stonebrick 0  
fill ~52 ~3 ~33 ~52 ~3 ~34 dropper 9  
fill ~52 ~3 ~44 ~53 ~3 ~44 stonebrick 0  
fill ~52 ~3 ~45 ~52 ~8 ~45 stonebrick 0  
fill ~52 ~3 ~46 ~52 ~3 ~41 stonebrick 0 
setblock ~52 ~3 ~47 dropper 0 
setblock ~52 ~3 ~48 dark_oak_stairs 0  
fill ~52 ~3 ~49 ~54 ~3 ~49 dropper 0 
setblock ~52 ~3 ~52 dark_oak_stairs 2 
setblock ~52 ~3 ~53 dark_oak_stairs 0 
setblock ~52 ~3 ~54 dropper 0 
setblock ~52 ~3 ~64 dropper 0 
setblock ~52 ~3 ~65 dark_oak_stairs 3 
setblock ~52 ~3 ~66 dark_oak_stairs 0  
fill ~52 ~3 ~69 ~54 ~3 ~69 dropper 0 
setblock ~52 ~3 ~70 dark_oak_stairs 1 
setblock ~52 ~3 ~71 dropper 0  
fill ~52 ~3 ~72 ~52 ~3 ~77 stonebrick 0  
fill ~52 ~3 ~84 ~52 ~3 ~85 dropper 9 
setblock ~52 ~3 ~86 stonebrick 0 
setblock ~52 ~3 ~90 stonebrick 0 
setblock ~52 ~3 ~91 redstone_lamp 0 
setblock ~52 ~3 ~92 stonebrick 0 
setblock ~52 ~3 ~96 stonebrick 0 
setblock ~52 ~3 ~97 redstone_lamp 0 
setblock ~52 ~3 ~98 stonebrick 0 
setblock ~52 ~3 ~102 stonebrick 0 
setblock ~52 ~3 ~103 redstone_lamp 0 
setblock ~52 ~3 ~104 stonebrick 0 
setblock ~52 ~3 ~108 stonebrick 0 
setblock ~52 ~3 ~109 lit_redstone_lamp 0  
fill ~52 ~3 ~110 ~56 ~3 ~110 planks 1 
setblock ~52 ~3 ~116 dark_oak_stairs 3  
fill ~52 ~3 ~117 ~52 ~3 ~118 dark_oak_stairs 1  
fill ~53 ~3 ~0 ~53 ~3 ~2 dropper 5  
fill ~53 ~3 ~3 ~53 ~3 ~4 dark_oak_stairs 1  
fill ~53 ~3 ~9 ~55 ~3 ~9 log 9  
fill ~53 ~3 ~10 ~53 ~3 ~13 dark_oak_stairs 1  
fill ~53 ~3 ~14 ~54 ~3 ~14 dark_oak_stairs 2  
fill ~53 ~3 ~15 ~55 ~3 ~15 log 9  
fill ~53 ~3 ~16 ~53 ~3 ~19 dark_oak_stairs 1  
fill ~53 ~3 ~20 ~54 ~3 ~20 dark_oak_stairs 2  
fill ~53 ~3 ~21 ~55 ~3 ~21 log 9  
fill ~53 ~3 ~22 ~53 ~3 ~25 dark_oak_stairs 1  
fill ~53 ~3 ~26 ~54 ~3 ~26 dark_oak_stairs 2  
fill ~53 ~3 ~27 ~55 ~3 ~27 log 9  
fill ~53 ~3 ~28 ~53 ~3 ~31 dark_oak_stairs 1  
fill ~53 ~3 ~32 ~54 ~3 ~32 dark_oak_stairs 2  
fill ~53 ~3 ~33 ~55 ~3 ~33 dropper 0  
fill ~53 ~3 ~34 ~55 ~3 ~34 dropper 0 
setblock ~53 ~3 ~35 dropper 9 
setblock ~53 ~3 ~37 dropper 9 
setblock ~53 ~3 ~38 dropper 0 
setblock ~53 ~3 ~41 dropper 0 
setblock ~53 ~3 ~45 dropper 0  
fill ~53 ~3 ~46 ~53 ~3 ~47 dark_oak_stairs 1 
setblock ~53 ~3 ~48 dark_oak_stairs 3 
setblock ~53 ~3 ~51 dark_oak_stairs 2 
setblock ~53 ~3 ~52 dark_oak_stairs 0  
fill ~53 ~3 ~53 ~53 ~3 ~65 stonebrick 0 
setblock ~53 ~3 ~66 dark_oak_stairs 3 
setblock ~53 ~3 ~67 dark_oak_stairs 0 
setblock ~53 ~3 ~70 dark_oak_stairs 2  
fill ~53 ~3 ~71 ~53 ~3 ~72 dark_oak_stairs 1 
setblock ~53 ~3 ~73 dropper 0 
setblock ~53 ~3 ~77 dropper 0 
setblock ~53 ~3 ~80 dropper 0 
setblock ~53 ~3 ~81 dropper 9 
setblock ~53 ~3 ~83 dropper 9  
fill ~53 ~3 ~84 ~55 ~3 ~84 dropper 0  
fill ~53 ~3 ~85 ~55 ~3 ~85 dropper 0  
fill ~53 ~3 ~86 ~53 ~3 ~89 dark_oak_stairs 1  
fill ~53 ~3 ~90 ~54 ~3 ~90 dark_oak_stairs 2  
fill ~53 ~3 ~91 ~55 ~3 ~91 log 9  
fill ~53 ~3 ~92 ~53 ~3 ~95 dark_oak_stairs 1  
fill ~53 ~3 ~96 ~54 ~3 ~96 dark_oak_stairs 2  
fill ~53 ~3 ~97 ~55 ~3 ~97 log 9  
fill ~53 ~3 ~98 ~53 ~3 ~101 dark_oak_stairs 1  
fill ~53 ~3 ~102 ~54 ~3 ~102 dark_oak_stairs 2  
fill ~53 ~3 ~103 ~55 ~3 ~103 log 9  
fill ~53 ~3 ~104 ~53 ~3 ~107 dark_oak_stairs 1  
fill ~53 ~3 ~108 ~54 ~3 ~108 dark_oak_stairs 2  
fill ~53 ~3 ~109 ~55 ~3 ~109 log 9  
fill ~53 ~3 ~114 ~54 ~3 ~114 dark_oak_stairs 3 
setblock ~53 ~3 ~115 dark_oak_stairs 1  
fill ~53 ~3 ~116 ~53 ~3 ~118 dropper 5 
setblock ~54 ~3 ~0 cobblestone_wall 0 
setblock ~54 ~3 ~3 dropper 5 
setblock ~54 ~3 ~4 dark_oak_stairs 2  
fill ~54 ~3 ~10 ~55 ~3 ~10 dark_oak_stairs 3  
fill ~54 ~3 ~11 ~54 ~3 ~13 dropper 9  
fill ~54 ~3 ~16 ~55 ~3 ~16 dark_oak_stairs 3  
fill ~54 ~3 ~17 ~54 ~3 ~19 dropper 9
fill ~54 ~3 ~22 ~55 ~3 ~22 dark_oak_stairs 3  
fill ~54 ~3 ~23 ~54 ~3 ~25 dropper 9  
fill ~54 ~3 ~28 ~55 ~3 ~28 dark_oak_stairs 3  
fill ~54 ~3 ~29 ~54 ~3 ~31 dropper 9 
setblock ~54 ~3 ~35 dropper 0 
setblock ~54 ~3 ~36 dropper 9  
fill ~54 ~3 ~37 ~66 ~3 ~37 dropper 0 
setblock ~54 ~3 ~38 dropper 9 
setblock ~54 ~3 ~40 dark_oak_stairs 3  
fill ~54 ~3 ~41 ~54 ~3 ~45 dark_oak_stairs 1 
setblock ~54 ~3 ~46 dark_oak_stairs 3  
fill ~54 ~3 ~47 ~54 ~3 ~49 dropper 0 
setblock ~54 ~3 ~50 dark_oak_stairs 2 
setblock ~54 ~3 ~51 dark_oak_stairs 0  
fill ~54 ~3 ~52 ~66 ~3 ~52 stonebrick 0 
setblock ~54 ~3 ~53 redstone_block 0  
fill ~54 ~3 ~54 ~67 ~3 ~54 stonebrick 0  
fill ~54 ~3 ~64 ~67 ~3 ~64 stonebrick 0 
setblock ~54 ~3 ~65 redstone_block 0  
fill ~54 ~3 ~66 ~66 ~3 ~66 stonebrick 0 
setblock ~54 ~3 ~67 dark_oak_stairs 3 
setblock ~54 ~3 ~68 dark_oak_stairs 0  
fill ~54 ~3 ~70 ~54 ~3 ~71 dropper 0 
setblock ~54 ~3 ~72 dark_oak_stairs 2  
fill ~54 ~3 ~73 ~54 ~3 ~77 dark_oak_stairs 1 
setblock ~54 ~3 ~78 dark_oak_stairs 2 
setblock ~54 ~3 ~80 dropper 9  
fill ~54 ~3 ~81 ~60 ~3 ~81 dropper 0 
setblock ~54 ~3 ~82 dropper 9 
setblock ~54 ~3 ~83 dropper 0  
fill ~54 ~3 ~86 ~55 ~3 ~86 dark_oak_stairs 3  
fill ~54 ~3 ~87 ~54 ~3 ~89 dropper 9  
fill ~54 ~3 ~92 ~55 ~3 ~92 dark_oak_stairs 3  
fill ~54 ~3 ~93 ~54 ~3 ~95 dropper 9  
fill ~54 ~3 ~98 ~55 ~3 ~98 dark_oak_stairs 3  
fill ~54 ~3 ~99 ~54 ~3 ~101 dropper 9  
fill ~54 ~3 ~104 ~55 ~3 ~104 dark_oak_stairs 3  
fill ~54 ~3 ~105 ~54 ~3 ~107 dropper 9 
setblock ~54 ~3 ~115 dropper 5 
setblock ~54 ~3 ~118 cobblestone_wall 0  
fill ~55 ~3 ~4 ~56 ~3 ~4 dropper 5 
setblock ~55 ~3 ~5 dark_oak_stairs 1  
fill ~55 ~3 ~11 ~55 ~3 ~14 dark_oak_stairs 0  
fill ~55 ~3 ~17 ~55 ~3 ~20 dark_oak_stairs 0  
fill ~55 ~3 ~23 ~55 ~3 ~26 dark_oak_stairs 0  
fill ~55 ~3 ~29 ~55 ~3 ~32 dark_oak_stairs 0 
setblock ~55 ~3 ~35 dropper 9 
setblock ~55 ~3 ~36 dropper 0  
fill ~55 ~3 ~38 ~65 ~3 ~38 dropper 0  
fill ~55 ~3 ~39 ~55 ~3 ~40 dropper 9  
fill ~55 ~3 ~41 ~55 ~3 ~46 dropper 0  
fill ~55 ~3 ~47 ~55 ~3 ~50 dark_oak_stairs 0 
setblock ~55 ~3 ~51 dropper 0  
fill ~55 ~3 ~53 ~65 ~3 ~53 stonebrick 0  
fill ~55 ~3 ~65 ~65 ~3 ~65 stonebrick 0 
setblock ~55 ~3 ~67 dropper 0 
setblock ~55 ~3 ~68 dark_oak_stairs 3  
fill ~55 ~3 ~69 ~55 ~3 ~70 dark_oak_stairs 0 
setblock ~55 ~3 ~71 dark_oak_stairs 3  
fill ~55 ~3 ~72 ~55 ~3 ~77 dropper 0  
fill ~55 ~3 ~78 ~55 ~3 ~79 dropper 9  
fill ~55 ~3 ~80 ~65 ~3 ~80 dropper 0 
setblock ~55 ~3 ~82 dropper 0 
setblock ~55 ~3 ~83 dropper 9  
fill ~55 ~3 ~87 ~55 ~3 ~90 dark_oak_stairs 0  
fill ~55 ~3 ~93 ~55 ~3 ~96 dark_oak_stairs 0  
fill ~55 ~3 ~99 ~55 ~3 ~102 dark_oak_stairs 0  
fill ~55 ~3 ~105 ~55 ~3 ~108 dark_oak_stairs 0 
setblock ~55 ~3 ~113 dark_oak_stairs 1  
fill ~55 ~3 ~114 ~56 ~3 ~114 dropper 5 
setblock ~56 ~3 ~5 dark_oak_stairs 2 
setblock ~56 ~3 ~9 lit_redstone_lamp 0  
fill ~56 ~3 ~10 ~56 ~3 ~14 stonebrick 0 
setblock ~56 ~3 ~15 redstone_lamp 0  
fill ~56 ~3 ~16 ~56 ~3 ~20 stonebrick 0 
setblock ~56 ~3 ~21 redstone_lamp 0  
fill ~56 ~3 ~22 ~56 ~3 ~26 stonebrick 0 
setblock ~56 ~3 ~27 redstone_lamp 0  
fill ~56 ~3 ~28 ~56 ~3 ~32 stonebrick 0  
fill ~56 ~3 ~33 ~56 ~3 ~34 dropper 9  
fill ~56 ~3 ~35 ~64 ~3 ~35 dropper 0  
fill ~56 ~3 ~36 ~57 ~3 ~36 dropper 9  
fill ~56 ~3 ~39 ~57 ~3 ~39 dropper 0 
setblock ~56 ~3 ~40 dark_oak_stairs 3  
fill ~56 ~3 ~41 ~56 ~3 ~46 dark_oak_stairs 0 
setblock ~56 ~3 ~47 dark_oak_stairs 2 
setblock ~56 ~3 ~48 dropper 0  
fill ~56 ~3 ~49 ~64 ~3 ~49 stonebrick 0  
fill ~56 ~3 ~50 ~64 ~3 ~50 stonebrick 0  
fill ~56 ~3 ~51 ~64 ~3 ~51 stonebrick 0  
fill ~56 ~3 ~67 ~64 ~3 ~67 stonebrick 0  
fill ~56 ~3 ~68 ~64 ~3 ~68 stonebrick 0  
fill ~56 ~3 ~69 ~64 ~3 ~69 stonebrick 0 
setblock ~56 ~3 ~70 dropper 0  
fill ~56 ~3 ~71 ~56 ~3 ~77 dark_oak_stairs 0 
setblock ~56 ~3 ~78 dark_oak_stairs 2  
fill ~56 ~3 ~79 ~57 ~3 ~79 dropper 0  
fill ~56 ~3 ~82 ~57 ~3 ~82 dropper 9  
fill ~56 ~3 ~83 ~64 ~3 ~83 dropper 0  
fill ~56 ~3 ~84 ~56 ~3 ~85 dropper 9  
fill ~56 ~3 ~86 ~56 ~3 ~90 stonebrick 0 
setblock ~56 ~3 ~91 redstone_lamp 0  
fill ~56 ~3 ~92 ~56 ~3 ~96 stonebrick 0 
setblock ~56 ~3 ~97 redstone_lamp 0  
fill ~56 ~3 ~98 ~56 ~3 ~102 stonebrick 0 
setblock ~56 ~3 ~103 redstone_lamp 0  
fill ~56 ~3 ~104 ~56 ~3 ~108 stonebrick 0 
setblock ~56 ~3 ~109 lit_redstone_lamp 0 
setblock ~56 ~3 ~113 dark_oak_stairs 3  
fill ~57 ~3 ~5 ~58 ~3 ~5 dropper 5 
setblock ~57 ~3 ~6 dark_oak_stairs 1 
setblock ~57 ~3 ~9 redstone_block 0 
setblock ~57 ~3 ~10 dropper 0  
fill ~57 ~3 ~11 ~64 ~3 ~11 stonebrick 0  
fill ~57 ~3 ~12 ~64 ~3 ~12 stonebrick 0  
fill ~57 ~3 ~13 ~64 ~3 ~13 stonebrick 0 
setblock ~57 ~3 ~14 dark_oak_stairs 4  
fill ~57 ~3 ~15 ~63 ~3 ~15 stonebrick 0 
setblock ~57 ~3 ~16 dropper 0  
fill ~57 ~3 ~17 ~64 ~3 ~17 stonebrick 0  
fill ~57 ~3 ~18 ~64 ~3 ~18 stonebrick 0  
fill ~57 ~3 ~19 ~64 ~3 ~19 stonebrick 0 
setblock ~57 ~3 ~20 dark_oak_stairs 4  
fill ~57 ~3 ~21 ~63 ~3 ~21 stonebrick 0 
setblock ~57 ~3 ~22 dropper 0  
fill ~57 ~3 ~23 ~64 ~3 ~23 stonebrick 0  
fill ~57 ~3 ~24 ~64 ~3 ~24 stonebrick 0  
fill ~57 ~3 ~25 ~64 ~3 ~25 stonebrick 0 
setblock ~57 ~3 ~26 dark_oak_stairs 4  
fill ~57 ~3 ~27 ~63 ~3 ~27 stonebrick 0 
setblock ~57 ~3 ~28 dropper 0  
fill ~57 ~3 ~29 ~64 ~3 ~29 stonebrick 0  
fill ~57 ~3 ~30 ~64 ~3 ~30 stonebrick 0  
fill ~57 ~3 ~31 ~64 ~3 ~31 stonebrick 0 
setblock ~57 ~3 ~32 dark_oak_stairs 4  
fill ~57 ~3 ~33 ~63 ~3 ~33 stonebrick 0 
setblock ~57 ~3 ~34 dropper 0  
fill ~57 ~3 ~40 ~57 ~3 ~43 stonebrick 0 
setblock ~57 ~3 ~44 redstone_block 0  
fill ~57 ~3 ~45 ~58 ~3 ~45 stonebrick 0  
fill ~57 ~3 ~46 ~63 ~3 ~46 stonebrick 0  
fill ~57 ~3 ~47 ~63 ~3 ~47 stonebrick 0  
fill ~57 ~3 ~48 ~63 ~3 ~48 stonebrick 0  
fill ~57 ~3 ~70 ~63 ~3 ~70 stonebrick 0  
fill ~57 ~3 ~71 ~63 ~3 ~71 stonebrick 0  
fill ~57 ~3 ~72 ~63 ~3 ~72 stonebrick 0  
fill ~57 ~3 ~73 ~58 ~3 ~73 stonebrick 0 
setblock ~57 ~3 ~74 redstone_block 0  
fill ~57 ~3 ~75 ~57 ~3 ~78 stonebrick 0 
setblock ~57 ~3 ~84 dropper 0  
fill ~57 ~3 ~85 ~63 ~3 ~85 stonebrick 0 
setblock ~57 ~3 ~86 dropper 0  
fill ~57 ~3 ~87 ~64 ~3 ~87 stonebrick 0  
fill ~57 ~3 ~88 ~64 ~3 ~88 stonebrick 0  
fill ~57 ~3 ~89 ~64 ~3 ~89 stonebrick 0 
setblock ~57 ~3 ~90 dark_oak_stairs 4  
fill ~57 ~3 ~91 ~63 ~3 ~91 stonebrick 0 
setblock ~57 ~3 ~92 dropper 0  
fill ~57 ~3 ~93 ~64 ~3 ~93 stonebrick 0  
fill ~57 ~3 ~94 ~64 ~3 ~94 stonebrick 0  
fill ~57 ~3 ~95 ~64 ~3 ~95 stonebrick 0 
setblock ~57 ~3 ~96 dark_oak_stairs 4  
fill ~57 ~3 ~97 ~63 ~3 ~97 stonebrick 0 
setblock ~57 ~3 ~98 dropper 0  
fill ~57 ~3 ~99 ~64 ~3 ~99 stonebrick 0  
fill ~57 ~3 ~100 ~64 ~3 ~100 stonebrick 0  
fill ~57 ~3 ~101 ~64 ~3 ~101 stonebrick 0 
setblock ~57 ~3 ~102 dark_oak_stairs 4  
fill ~57 ~3 ~103 ~63 ~3 ~103 stonebrick 0 
setblock ~57 ~3 ~104 dropper 0  
fill ~57 ~3 ~105 ~64 ~3 ~105 stonebrick 0  
fill ~57 ~3 ~106 ~64 ~3 ~106 stonebrick 0  
fill ~57 ~3 ~107 ~64 ~3 ~107 stonebrick 0 
setblock ~57 ~3 ~108 dark_oak_stairs 4 
setblock ~57 ~3 ~109 redstone_block 0  
fill ~57 ~3 ~110 ~62 ~3 ~110 stonebrick 0 
setblock ~57 ~3 ~112 dark_oak_stairs 1  
fill ~57 ~3 ~113 ~58 ~3 ~113 dropper 5 
setblock ~58 ~3 ~6 dark_oak_stairs 2  
fill ~58 ~3 ~8 ~63 ~3 ~8 stonebrick 0  
fill ~58 ~3 ~9 ~62 ~3 ~9 stonebrick 0  
fill ~58 ~3 ~10 ~62 ~3 ~10 stonebrick 0  
fill ~58 ~3 ~14 ~62 ~3 ~14 stonebrick 0  
fill ~58 ~3 ~16 ~62 ~3 ~16 stonebrick 0  
fill ~58 ~3 ~20 ~62 ~3 ~20 stonebrick 0  
fill ~58 ~3 ~22 ~62 ~3 ~22 stonebrick 0  
fill ~58 ~3 ~26 ~62 ~3 ~26 stonebrick 0  
fill ~58 ~3 ~28 ~62 ~3 ~28 stonebrick 0  
fill ~58 ~3 ~32 ~62 ~3 ~32 stonebrick 0  
fill ~58 ~3 ~34 ~59 ~3 ~34 stonebrick 0  
fill ~58 ~3 ~36 ~62 ~3 ~36 dropper 0 
setblock ~58 ~3 ~39 stonebrick 0 
setblock ~58 ~3 ~40 dark_oak_stairs 1 
setblock ~58 ~3 ~41 dark_oak_stairs 2 
setblock ~58 ~3 ~42 stonebrick 0  
fill ~58 ~3 ~43 ~58 ~4 ~43 bookshelf 0  
fill ~58 ~3 ~44 ~58 ~5 ~44 bookshelf 0  
fill ~58 ~3 ~74 ~58 ~5 ~74 bookshelf 0  
fill ~58 ~3 ~75 ~58 ~4 ~75 bookshelf 0 
setblock ~58 ~3 ~76 stonebrick 0 
setblock ~58 ~3 ~77 dark_oak_stairs 3 
setblock ~58 ~3 ~78 dark_oak_stairs 1 
setblock ~58 ~3 ~79 stonebrick 0  
fill ~58 ~3 ~82 ~59 ~3 ~82 dropper 0  
fill ~58 ~3 ~84 ~59 ~3 ~84 stonebrick 0  
fill ~58 ~3 ~86 ~62 ~3 ~86 stonebrick 0  
fill ~58 ~3 ~90 ~62 ~3 ~90 stonebrick 0  
fill ~58 ~3 ~92 ~62 ~3 ~92 stonebrick 0  
fill ~58 ~3 ~96 ~62 ~3 ~96 stonebrick 0  
fill ~58 ~3 ~98 ~62 ~3 ~98 stonebrick 0  
fill ~58 ~3 ~102 ~62 ~3 ~102 stonebrick 0  
fill ~58 ~3 ~104 ~62 ~3 ~104 stonebrick 0  
fill ~58 ~3 ~108 ~62 ~3 ~108 stonebrick 0  
fill ~58 ~3 ~109 ~62 ~3 ~109 stonebrick 0 
setblock ~58 ~3 ~112 dark_oak_stairs 3  
fill ~59 ~3 ~6 ~61 ~3 ~6 dropper 5 
setblock ~59 ~3 ~7 dark_oak_stairs 1 
setblock ~59 ~3 ~39 dark_oak_stairs 1 
setblock ~59 ~3 ~40 dark_oak_stairs 3  
fill ~59 ~3 ~41 ~61 ~3 ~41 dropper 0  
fill ~59 ~3 ~42 ~61 ~3 ~42 dropper 0 
setblock ~59 ~3 ~43 dark_oak_stairs 3 
setblock ~59 ~3 ~44 dark_oak_stairs 0  
fill ~59 ~3 ~45 ~61 ~3 ~45 bookshelf 0  
fill ~59 ~3 ~73 ~61 ~3 ~73 bookshelf 0 
setblock ~59 ~3 ~74 dark_oak_stairs 0 
setblock ~59 ~3 ~75 dark_oak_stairs 2  
fill ~59 ~3 ~76 ~61 ~3 ~76 dropper 0  
fill ~59 ~3 ~77 ~61 ~3 ~77 dropper 0 
setblock ~59 ~3 ~78 dark_oak_stairs 2 
setblock ~59 ~3 ~79 dark_oak_stairs 1 
setblock ~59 ~3 ~111 dark_oak_stairs 1  
fill ~59 ~3 ~112 ~61 ~3 ~112 dropper 5 
setblock ~60 ~3 ~7 dark_oak_stairs 2 
setblock ~60 ~3 ~34 stone_slab 8  
fill ~60 ~3 ~39 ~60 ~3 ~42 dropper 0 
setblock ~60 ~3 ~43 glowstone 0 
setblock ~60 ~3 ~44 dark_oak_stairs 3 
setblock ~60 ~3 ~74 dark_oak_stairs 2 
setblock ~60 ~3 ~75 glowstone 0  
fill ~60 ~3 ~78 ~60 ~3 ~81 dropper 0 
setblock ~60 ~3 ~82 dropper 9 
setblock ~60 ~3 ~84 stone_slab 8 
setblock ~60 ~3 ~111 dark_oak_stairs 3 
setblock ~61 ~3 ~7 dark_oak_stairs 0  
fill ~61 ~3 ~34 ~62 ~3 ~34 stonebrick 0 
setblock ~61 ~3 ~39 dark_oak_stairs 0 
setblock ~61 ~3 ~40 dark_oak_stairs 3 
setblock ~61 ~3 ~43 dark_oak_stairs 3 
setblock ~61 ~3 ~44 dark_oak_stairs 1 
setblock ~61 ~3 ~74 dark_oak_stairs 1 
setblock ~61 ~3 ~75 dark_oak_stairs 2 
setblock ~61 ~3 ~78 dark_oak_stairs 2 
setblock ~61 ~3 ~79 dark_oak_stairs 0  
fill ~61 ~3 ~81 ~62 ~3 ~81 dropper 9  
fill ~61 ~3 ~82 ~62 ~3 ~82 dropper 0  
fill ~61 ~3 ~84 ~62 ~3 ~84 stonebrick 0 
setblock ~61 ~3 ~111 dark_oak_stairs 0  
fill ~62 ~3 ~5 ~63 ~3 ~5 dropper 5 
setblock ~62 ~3 ~6 dark_oak_stairs 2  
fill ~62 ~3 ~7 ~69 ~3 ~7 planks 1 
setblock ~62 ~3 ~39 stonebrick 0 
setblock ~62 ~3 ~40 dark_oak_stairs 0 
setblock ~62 ~3 ~41 dark_oak_stairs 2  
fill ~62 ~3 ~42 ~63 ~3 ~42 stonebrick 0  
fill ~62 ~3 ~43 ~62 ~4 ~43 bookshelf 0  
fill ~62 ~3 ~44 ~62 ~5 ~44 bookshelf 0  
fill ~62 ~3 ~45 ~63 ~3 ~45 stonebrick 0  
fill ~62 ~3 ~73 ~63 ~3 ~73 stonebrick 0  
fill ~62 ~3 ~74 ~62 ~5 ~74 bookshelf 0  
fill ~62 ~3 ~75 ~62 ~4 ~75 bookshelf 0  
fill ~62 ~3 ~76 ~63 ~3 ~76 stonebrick 0 
setblock ~62 ~3 ~77 dark_oak_stairs 3 
setblock ~62 ~3 ~78 dark_oak_stairs 0 
setblock ~62 ~3 ~79 stonebrick 0  
fill ~62 ~3 ~111 ~72 ~3 ~111 planks 1 
setblock ~62 ~3 ~112 dark_oak_stairs 3  
fill ~62 ~3 ~113 ~63 ~3 ~113 dropper 5 
setblock ~63 ~3 ~6 dark_oak_stairs 0 
setblock ~63 ~3 ~9 redstone_block 0 
setblock ~63 ~3 ~10 dark_oak_stairs 5 
setblock ~63 ~3 ~14 dropper 0 
setblock ~63 ~3 ~16 dark_oak_stairs 5 
setblock ~63 ~3 ~20 dropper 0 
setblock ~63 ~3 ~22 dark_oak_stairs 5 
setblock ~63 ~3 ~26 dropper 0 
setblock ~63 ~3 ~28 dark_oak_stairs 5 
setblock ~63 ~3 ~32 dropper 0 
setblock ~63 ~3 ~34 dropper 0  
fill ~63 ~3 ~36 ~64 ~3 ~36 dropper 9  
fill ~63 ~3 ~39 ~64 ~3 ~39 dropper 0  
fill ~63 ~3 ~40 ~63 ~3 ~43 stonebrick 0 
setblock ~63 ~3 ~44 redstone_block 0 
setblock ~63 ~3 ~74 redstone_block 0 
setblock ~63 ~3 ~75 stonebrick 0  
fill ~63 ~3 ~77 ~63 ~3 ~78 stonebrick 0  
fill ~63 ~3 ~79 ~64 ~3 ~79 dropper 0  
fill ~63 ~3 ~81 ~66 ~3 ~81 dropper 0  
fill ~63 ~3 ~82 ~64 ~3 ~82 dropper 9 
setblock ~63 ~3 ~84 dropper 0 
setblock ~63 ~3 ~86 dark_oak_stairs 5 
setblock ~63 ~3 ~90 dropper 0 
setblock ~63 ~3 ~92 dark_oak_stairs 5 
setblock ~63 ~3 ~96 dropper 0 
setblock ~63 ~3 ~98 dark_oak_stairs 5 
setblock ~63 ~3 ~102 dropper 0 
setblock ~63 ~3 ~104 dark_oak_stairs 5 
setblock ~63 ~3 ~108 dropper 0 
setblock ~63 ~3 ~109 redstone_block 0  
fill ~63 ~3 ~110 ~69 ~3 ~110 planks 1 
setblock ~63 ~3 ~112 dark_oak_stairs 0  
fill ~64 ~3 ~4 ~65 ~3 ~4 dropper 5 
setblock ~64 ~3 ~5 dark_oak_stairs 2  
fill ~64 ~3 ~6 ~71 ~3 ~6 planks 1  
fill ~64 ~3 ~8 ~68 ~3 ~8 planks 1 
setblock ~64 ~3 ~9 lit_redstone_lamp 0 
setblock ~64 ~3 ~10 stonebrick 0 
setblock ~64 ~3 ~14 stonebrick 0 
setblock ~64 ~3 ~15 redstone_lamp 0 
setblock ~64 ~3 ~16 stonebrick 0 
setblock ~64 ~3 ~20 stonebrick 0 
setblock ~64 ~3 ~21 redstone_lamp 0 
setblock ~64 ~3 ~22 stonebrick 0 
setblock ~64 ~3 ~26 stonebrick 0 
setblock ~64 ~3 ~27 redstone_lamp 0 
setblock ~64 ~3 ~28 stonebrick 0 
setblock ~64 ~3 ~32 stonebrick 0  
fill ~64 ~3 ~33 ~64 ~3 ~34 dropper 9 
setblock ~64 ~3 ~40 dark_oak_stairs 3  
fill ~64 ~3 ~41 ~64 ~3 ~47 dark_oak_stairs 1 
setblock ~64 ~3 ~48 dropper 0 
setblock ~64 ~3 ~70 dropper 0 
setblock ~64 ~3 ~71 dark_oak_stairs 3  
fill ~64 ~3 ~72 ~64 ~3 ~77 dark_oak_stairs 1 
setblock ~64 ~3 ~78 dark_oak_stairs 2  
fill ~64 ~3 ~84 ~64 ~3 ~85 dropper 9 
setblock ~64 ~3 ~86 stonebrick 0 
setblock ~64 ~3 ~90 stonebrick 0 
setblock ~64 ~3 ~91 redstone_lamp 0 
setblock ~64 ~3 ~92 stonebrick 0 
setblock ~64 ~3 ~96 stonebrick 0 
setblock ~64 ~3 ~97 redstone_lamp 0 
setblock ~64 ~3 ~98 stonebrick 0 
setblock ~64 ~3 ~102 stonebrick 0 
setblock ~64 ~3 ~103 redstone_lamp 0 
setblock ~64 ~3 ~104 stonebrick 0 
setblock ~64 ~3 ~108 stonebrick 0 
setblock ~64 ~3 ~109 lit_redstone_lamp 0  
fill ~64 ~3 ~112 ~71 ~3 ~112 planks 1 
setblock ~64 ~3 ~113 dark_oak_stairs 3  
fill ~64 ~3 ~114 ~65 ~3 ~114 dropper 5 
setblock ~65 ~3 ~5 dark_oak_stairs 0  
fill ~65 ~3 ~9 ~67 ~3 ~9 log 9  
fill ~65 ~3 ~10 ~65 ~3 ~13 dark_oak_stairs 1  
fill ~65 ~3 ~14 ~66 ~3 ~14 dark_oak_stairs 2  
fill ~65 ~3 ~15 ~67 ~3 ~15 log 9  
fill ~65 ~3 ~16 ~65 ~3 ~19 dark_oak_stairs 1  
fill ~65 ~3 ~20 ~66 ~3 ~20 dark_oak_stairs 2  
fill ~65 ~3 ~21 ~67 ~3 ~21 log 9  
fill ~65 ~3 ~22 ~65 ~3 ~25 dark_oak_stairs 1  
fill ~65 ~3 ~26 ~66 ~3 ~26 dark_oak_stairs 2  
fill ~65 ~3 ~27 ~67 ~3 ~27 log 9  
fill ~65 ~3 ~28 ~65 ~3 ~31 dark_oak_stairs 1  
fill ~65 ~3 ~32 ~66 ~3 ~32 dark_oak_stairs 2  
fill ~65 ~3 ~33 ~67 ~3 ~33 dropper 0  
fill ~65 ~3 ~34 ~67 ~3 ~34 dropper 0 
setblock ~65 ~3 ~35 dropper 9 
setblock ~65 ~3 ~36 dropper 0  
fill ~65 ~3 ~39 ~65 ~3 ~40 dropper 9  
fill ~65 ~3 ~41 ~65 ~3 ~46 dropper 0 
setblock ~65 ~3 ~47 dark_oak_stairs 2  
fill ~65 ~3 ~48 ~65 ~3 ~49 dark_oak_stairs 1 
setblock ~65 ~3 ~50 dark_oak_stairs 2 
setblock ~65 ~3 ~51 dropper 0 
setblock ~65 ~3 ~67 dropper 0  
fill ~65 ~3 ~68 ~65 ~3 ~71 dark_oak_stairs 1  
fill ~65 ~3 ~72 ~65 ~3 ~77 dropper 0  
fill ~65 ~3 ~78 ~65 ~3 ~79 dropper 9 
setblock ~65 ~3 ~82 dropper 0 
setblock ~65 ~3 ~83 dropper 9  
fill ~65 ~3 ~84 ~67 ~3 ~84 dropper 0  
fill ~65 ~3 ~85 ~67 ~3 ~85 dropper 0  
fill ~65 ~3 ~86 ~65 ~3 ~89 dark_oak_stairs 1  
fill ~65 ~3 ~90 ~66 ~3 ~90 dark_oak_stairs 2  
fill ~65 ~3 ~91 ~67 ~3 ~91 log 9  
fill ~65 ~3 ~92 ~65 ~3 ~95 dark_oak_stairs 1  
fill ~65 ~3 ~96 ~66 ~3 ~96 dark_oak_stairs 2  
fill ~65 ~3 ~97 ~67 ~3 ~97 log 9  
fill ~65 ~3 ~98 ~65 ~3 ~101 dark_oak_stairs 1  
fill ~65 ~3 ~102 ~66 ~3 ~102 dark_oak_stairs 2  
fill ~65 ~3 ~103 ~67 ~3 ~103 log 9  
fill ~65 ~3 ~104 ~65 ~3 ~107 dark_oak_stairs 1  
fill ~65 ~3 ~108 ~66 ~3 ~108 dark_oak_stairs 2  
fill ~65 ~3 ~109 ~67 ~3 ~109 log 9 
setblock ~65 ~3 ~113 dark_oak_stairs 0 
setblock ~66 ~3 ~0 cobblestone_wall 0 
setblock ~66 ~3 ~3 dropper 5  
fill ~66 ~3 ~4 ~67 ~3 ~4 dark_oak_stairs 2  
fill ~66 ~3 ~5 ~73 ~3 ~5 planks 1  
fill ~66 ~3 ~10 ~67 ~3 ~10 dark_oak_stairs 3  
fill ~66 ~3 ~11 ~66 ~3 ~13 dropper 9  
fill ~66 ~3 ~16 ~67 ~3 ~16 dark_oak_stairs 3  
fill ~66 ~3 ~17 ~66 ~3 ~19 dropper 9  
fill ~66 ~3 ~22 ~67 ~3 ~22 dark_oak_stairs 3  
fill ~66 ~3 ~23 ~66 ~3 ~25 dropper 9  
fill ~66 ~3 ~28 ~67 ~3 ~28 dark_oak_stairs 3  
fill ~66 ~3 ~29 ~66 ~3 ~31 dropper 9 
setblock ~66 ~3 ~35 dropper 0 
setblock ~66 ~3 ~36 dropper 9 
setblock ~66 ~3 ~38 dropper 9  
fill ~66 ~3 ~39 ~78 ~3 ~39 dropper 0 
setblock ~66 ~3 ~40 dark_oak_stairs 3  
fill ~66 ~3 ~41 ~66 ~3 ~45 dark_oak_stairs 0 
setblock ~66 ~3 ~46 dark_oak_stairs 3  
fill ~66 ~3 ~47 ~66 ~3 ~49 dropper 0 
setblock ~66 ~3 ~50 dark_oak_stairs 1 
setblock ~66 ~3 ~51 dark_oak_stairs 2 
setblock ~66 ~3 ~53 redstone_block 0 
setblock ~66 ~3 ~65 redstone_block 0 
setblock ~66 ~3 ~67 dark_oak_stairs 1 
setblock ~66 ~3 ~68 dark_oak_stairs 3  
fill ~66 ~3 ~69 ~68 ~3 ~69 dropper 0  
fill ~66 ~3 ~70 ~66 ~3 ~71 dropper 0 
setblock ~66 ~3 ~72 dark_oak_stairs 2  
fill ~66 ~3 ~73 ~66 ~3 ~77 dark_oak_stairs 0 
setblock ~66 ~3 ~78 dark_oak_stairs 2  
fill ~66 ~3 ~79 ~78 ~3 ~79 dropper 0 
setblock ~66 ~3 ~80 dropper 9 
setblock ~66 ~3 ~82 dropper 9 
setblock ~66 ~3 ~83 dropper 0  
fill ~66 ~3 ~86 ~67 ~3 ~86 dark_oak_stairs 3  
fill ~66 ~3 ~87 ~66 ~3 ~89 dropper 9  
fill ~66 ~3 ~92 ~67 ~3 ~92 dark_oak_stairs 3  
fill ~66 ~3 ~93 ~66 ~3 ~95 dropper 9  
fill ~66 ~3 ~98 ~67 ~3 ~98 dark_oak_stairs 3  
fill ~66 ~3 ~99 ~66 ~3 ~101 dropper 9  
fill ~66 ~3 ~104 ~67 ~3 ~104 dark_oak_stairs 3  
fill ~66 ~3 ~105 ~66 ~3 ~107 dropper 9  
fill ~66 ~3 ~113 ~73 ~3 ~113 planks 1 
setblock ~66 ~3 ~114 dark_oak_stairs 3 
setblock ~66 ~3 ~115 dropper 5 
setblock ~66 ~3 ~118 cobblestone_wall 0  
fill ~67 ~3 ~0 ~67 ~3 ~2 dropper 5 
setblock ~67 ~3 ~3 dark_oak_stairs 0  
fill ~67 ~3 ~11 ~67 ~3 ~14 dark_oak_stairs 0  
fill ~67 ~3 ~17 ~67 ~3 ~20 dark_oak_stairs 0  
fill ~67 ~3 ~23 ~67 ~3 ~26 dark_oak_stairs 0  
fill ~67 ~3 ~29 ~67 ~3 ~32 dark_oak_stairs 0 
setblock ~67 ~3 ~35 dropper 9  
fill ~67 ~3 ~36 ~71 ~3 ~36 dropper 0 
setblock ~67 ~3 ~37 dropper 9 
setblock ~67 ~3 ~38 dropper 0  
fill ~67 ~3 ~40 ~69 ~3 ~40 dropper 0  
fill ~67 ~3 ~41 ~67 ~3 ~38 dropper 0  
fill ~67 ~3 ~42 ~78 ~3 ~42 stonebrick 0  
fill ~67 ~3 ~43 ~78 ~3 ~43 stonebrick 0  
fill ~67 ~3 ~44 ~79 ~3 ~44 stonebrick 0 
setblock ~67 ~3 ~45 dropper 0  
fill ~67 ~3 ~46 ~67 ~3 ~47 dark_oak_stairs 0 
setblock ~67 ~3 ~48 dark_oak_stairs 3  
fill ~67 ~3 ~49 ~68 ~3 ~49 dropper 0  
fill ~67 ~3 ~50 ~69 ~3 ~50 dropper 0 
setblock ~67 ~3 ~51 dark_oak_stairs 1 
setblock ~67 ~3 ~52 dark_oak_stairs 2 
setblock ~67 ~3 ~53 stonebrick 0 
setblock ~67 ~3 ~65 stonebrick 0 
setblock ~67 ~3 ~66 dark_oak_stairs 1 
setblock ~67 ~3 ~67 dark_oak_stairs 3  
fill ~67 ~3 ~68 ~69 ~3 ~68 dropper 0 
setblock ~67 ~3 ~70 dark_oak_stairs 2  
fill ~67 ~3 ~71 ~67 ~3 ~72 dark_oak_stairs 0 
setblock ~67 ~3 ~73 dropper 0  
fill ~67 ~3 ~74 ~68 ~3 ~74 stonebrick 0  
fill ~67 ~3 ~75 ~78 ~3 ~75 stonebrick 0  
fill ~67 ~3 ~76 ~78 ~3 ~76 stonebrick 0  
fill ~67 ~3 ~77 ~67 ~3 ~80 dropper 0 
setblock ~67 ~3 ~81 dropper 9  
fill ~67 ~3 ~82 ~71 ~3 ~82 dropper 0 
setblock ~67 ~3 ~83 dropper 9  
fill ~67 ~3 ~87 ~67 ~3 ~90 dark_oak_stairs 0  
fill ~67 ~3 ~93 ~67 ~3 ~96 dark_oak_stairs 0  
fill ~67 ~3 ~99 ~67 ~3 ~102 dark_oak_stairs 0  
fill ~67 ~3 ~105 ~67 ~3 ~108 dark_oak_stairs 0  
fill ~67 ~3 ~114 ~67 ~3 ~115 dark_oak_stairs 0  
fill ~67 ~3 ~116 ~67 ~3 ~118 dropper 5  
fill ~68 ~3 ~0 ~68 ~3 ~1 dark_oak_stairs 0 
setblock ~68 ~3 ~2 dark_oak_stairs 2  
fill ~68 ~3 ~3 ~74 ~3 ~3 planks 1  
fill ~68 ~3 ~4 ~74 ~3 ~4 planks 1 
setblock ~68 ~3 ~9 lit_redstone_lamp 0  
fill ~68 ~3 ~10 ~68 ~3 ~14 stonebrick 0 
setblock ~68 ~3 ~15 redstone_lamp 0  
fill ~68 ~3 ~16 ~68 ~3 ~20 stonebrick 0 
setblock ~68 ~3 ~21 redstone_lamp 0  
fill ~68 ~3 ~22 ~68 ~3 ~26 stonebrick 0 
setblock ~68 ~3 ~27 redstone_lamp 0  
fill ~68 ~3 ~28 ~68 ~3 ~32 stonebrick 0  
fill ~68 ~3 ~33 ~68 ~3 ~34 dropper 9  
fill ~68 ~3 ~35 ~78 ~3 ~35 dropper 0  
fill ~68 ~3 ~37 ~69 ~3 ~37 dropper 0  
fill ~68 ~3 ~38 ~69 ~3 ~38 dropper 9  
fill ~68 ~3 ~41 ~77 ~3 ~41 stonebrick 0  
fill ~68 ~3 ~45 ~68 ~8 ~45 stonebrick 0  
fill ~68 ~3 ~46 ~68 ~3 ~41 stonebrick 0 
setblock ~68 ~3 ~47 dropper 0 
setblock ~68 ~3 ~48 dark_oak_stairs 0  
fill ~68 ~3 ~51 ~70 ~3 ~51 dropper 0 
setblock ~68 ~3 ~52 dark_oak_stairs 1 
setblock ~68 ~3 ~53 dark_oak_stairs 2 
setblock ~68 ~3 ~54 dropper 0 
setblock ~68 ~3 ~64 dropper 0 
setblock ~68 ~3 ~65 dark_oak_stairs 1 
setblock ~68 ~3 ~66 dark_oak_stairs 3  
fill ~68 ~3 ~67 ~70 ~3 ~67 dropper 0 
setblock ~68 ~3 ~70 dark_oak_stairs 1 
setblock ~68 ~3 ~71 dropper 0  
fill ~68 ~3 ~72 ~68 ~3 ~77 stonebrick 0  
fill ~68 ~3 ~78 ~69 ~3 ~78 dropper 0  
fill ~68 ~3 ~80 ~69 ~3 ~80 dropper 9  
fill ~68 ~3 ~81 ~69 ~3 ~81 dropper 0  
fill ~68 ~3 ~83 ~78 ~3 ~83 dropper 0  
fill ~68 ~3 ~84 ~68 ~3 ~85 dropper 9  
fill ~68 ~3 ~86 ~68 ~3 ~90 stonebrick 0 
setblock ~68 ~3 ~91 redstone_lamp 0  
fill ~68 ~3 ~92 ~68 ~3 ~96 stonebrick 0 
setblock ~68 ~3 ~97 redstone_lamp 0  
fill ~68 ~3 ~98 ~68 ~3 ~102 stonebrick 0 
setblock ~68 ~3 ~103 redstone_lamp 0  
fill ~68 ~3 ~104 ~68 ~3 ~108 stonebrick 0 
setblock ~68 ~3 ~109 lit_redstone_lamp 0  
fill ~68 ~3 ~114 ~74 ~3 ~114 planks 1  
fill ~68 ~3 ~115 ~74 ~3 ~115 planks 1 
setblock ~68 ~3 ~116 dark_oak_stairs 3 
setblock ~68 ~3 ~117 dark_oak_stairs 0  
fill ~68 ~3 ~118 ~70 ~3 ~118 dark_oak_stairs 3  
fill ~69 ~3 ~0 ~70 ~3 ~0 dark_oak_stairs 2  
fill ~69 ~3 ~1 ~77 ~3 ~1 planks 1  
fill ~69 ~3 ~2 ~75 ~3 ~2 planks 1  
fill ~69 ~3 ~8 ~110 ~3 ~8 stonebrick 0 
setblock ~69 ~3 ~9 redstone_block 0 
setblock ~69 ~3 ~10 dropper 0  
fill ~69 ~3 ~11 ~118 ~3 ~11 stonebrick 0  
fill ~69 ~3 ~12 ~118 ~3 ~12 stonebrick 0  
fill ~69 ~3 ~13 ~118 ~3 ~13 stonebrick 0 
setblock ~69 ~3 ~14 dark_oak_stairs 4  
fill ~69 ~3 ~15 ~118 ~3 ~15 stonebrick 0 
setblock ~69 ~3 ~16 dropper 0  
fill ~69 ~3 ~17 ~118 ~3 ~17 stonebrick 0  
fill ~69 ~3 ~18 ~118 ~3 ~18 stonebrick 0  
fill ~69 ~3 ~19 ~118 ~3 ~19 stonebrick 0 
setblock ~69 ~3 ~20 dark_oak_stairs 4  
fill ~69 ~3 ~21 ~118 ~3 ~21 stonebrick 0 
setblock ~69 ~3 ~22 dropper 0  
fill ~69 ~3 ~23 ~118 ~3 ~23 stonebrick 0  
fill ~69 ~3 ~24 ~118 ~3 ~24 stonebrick 0  
fill ~69 ~3 ~25 ~118 ~3 ~25 stonebrick 0 
setblock ~69 ~3 ~26 dark_oak_stairs 4  
fill ~69 ~3 ~27 ~118 ~3 ~27 stonebrick 0 
setblock ~69 ~3 ~28 dropper 0  
fill ~69 ~3 ~29 ~118 ~3 ~29 stonebrick 0  
fill ~69 ~3 ~30 ~118 ~3 ~30 stonebrick 0  
fill ~69 ~3 ~31 ~118 ~3 ~31 stonebrick 0 
setblock ~69 ~3 ~32 dark_oak_stairs 4  
fill ~69 ~3 ~33 ~71 ~3 ~33 stonebrick 0  
fill ~69 ~3 ~34 ~71 ~3 ~34 stonebrick 0  
fill ~69 ~3 ~45 ~69 ~3 ~46 dark_oak_stairs 1  
fill ~69 ~3 ~47 ~69 ~7 ~47 log 1 
setblock ~69 ~3 ~48 dark_oak_stairs 2 
setblock ~69 ~3 ~49 dark_oak_stairs 1  
fill ~69 ~3 ~52 ~70 ~3 ~52 dropper 0 
setblock ~69 ~3 ~53 dark_oak_stairs 1  
fill ~69 ~3 ~54 ~72 ~3 ~54 dark_oak_stairs 2 
setblock ~69 ~3 ~64 dark_oak_stairs 1 
setblock ~69 ~3 ~65 dark_oak_stairs 3  
fill ~69 ~3 ~66 ~70 ~3 ~66 dropper 0 
setblock ~69 ~3 ~69 dark_oak_stairs 1 
setblock ~69 ~3 ~70 dark_oak_stairs 3  
fill ~69 ~3 ~71 ~69 ~7 ~71 log 1  
fill ~69 ~3 ~72 ~69 ~3 ~73 dark_oak_stairs 1  
fill ~69 ~3 ~74 ~73 ~3 ~74 obsidian 0  
fill ~69 ~3 ~77 ~77 ~3 ~77 stonebrick 0  
fill ~69 ~3 ~84 ~71 ~3 ~84 stonebrick 0  
fill ~69 ~3 ~85 ~71 ~3 ~85 stonebrick 0 
setblock ~69 ~3 ~86 dropper 0  
fill ~69 ~3 ~87 ~118 ~3 ~87 stonebrick 0  
fill ~69 ~3 ~88 ~118 ~3 ~88 stonebrick 0  
fill ~69 ~3 ~89 ~118 ~3 ~89 stonebrick 0 
setblock ~69 ~3 ~90 dark_oak_stairs 4  
fill ~69 ~3 ~91 ~118 ~3 ~91 stonebrick 0 
setblock ~69 ~3 ~92 dropper 0  
fill ~69 ~3 ~93 ~118 ~3 ~93 stonebrick 0  
fill ~69 ~3 ~94 ~118 ~3 ~94 stonebrick 0  
fill ~69 ~3 ~95 ~118 ~3 ~95 stonebrick 0 
setblock ~69 ~3 ~96 dark_oak_stairs 4  
fill ~69 ~3 ~97 ~118 ~3 ~97 stonebrick 0 
setblock ~69 ~3 ~98 dropper 0  
fill ~69 ~3 ~99 ~118 ~3 ~99 stonebrick 0  
fill ~69 ~3 ~100 ~118 ~3 ~100 stonebrick 0  
fill ~69 ~3 ~101 ~118 ~3 ~101 stonebrick 0 
setblock ~69 ~3 ~102 dark_oak_stairs 4  
fill ~69 ~3 ~103 ~118 ~3 ~103 stonebrick 0 
setblock ~69 ~3 ~104 dropper 0  
fill ~69 ~3 ~105 ~118 ~3 ~105 stonebrick 0  
fill ~69 ~3 ~106 ~118 ~3 ~106 stonebrick 0  
fill ~69 ~3 ~107 ~118 ~3 ~107 stonebrick 0 
setblock ~69 ~3 ~108 dark_oak_stairs 4 
setblock ~69 ~3 ~109 redstone_block 0  
fill ~69 ~3 ~116 ~75 ~3 ~116 planks 1  
fill ~69 ~3 ~117 ~75 ~3 ~117 planks 1  
fill ~70 ~3 ~7 ~110 ~3 ~7 stonebrick 0  
fill ~70 ~3 ~9 ~118 ~3 ~9 stonebrick 0  
fill ~70 ~3 ~10 ~118 ~3 ~10 stonebrick 0  
fill ~70 ~3 ~14 ~118 ~3 ~14 stonebrick 0  
fill ~70 ~3 ~16 ~118 ~3 ~16 stonebrick 0  
fill ~70 ~3 ~20 ~118 ~3 ~20 stonebrick 0  
fill ~70 ~3 ~22 ~118 ~3 ~22 stonebrick 0  
fill ~70 ~3 ~26 ~118 ~3 ~26 stonebrick 0  
fill ~70 ~3 ~28 ~118 ~3 ~28 stonebrick 0  
fill ~70 ~3 ~32 ~118 ~3 ~32 stonebrick 0  
fill ~70 ~3 ~37 ~71 ~3 ~37 dropper 9  
fill ~70 ~3 ~38 ~76 ~3 ~38 dropper 0  
fill ~70 ~3 ~40 ~75 ~3 ~40 stonebrick 0 
setblock ~70 ~3 ~45 dark_oak_stairs 3 
setblock ~70 ~3 ~46 dropper 0  
fill ~70 ~3 ~47 ~71 ~3 ~47 stone_slab 8  
fill ~70 ~3 ~48 ~70 ~3 ~49 dropper 0 
setblock ~70 ~3 ~50 dark_oak_stairs 2  
fill ~70 ~3 ~53 ~72 ~3 ~53 dropper 0  
fill ~70 ~3 ~64 ~71 ~3 ~64 dark_oak_stairs 3  
fill ~70 ~3 ~65 ~72 ~3 ~65 dropper 0 
setblock ~70 ~3 ~68 dark_oak_stairs 3  
fill ~70 ~3 ~69 ~71 ~3 ~69 dropper 0  
fill ~70 ~3 ~70 ~70 ~3 ~69 dropper 0  
fill ~70 ~3 ~71 ~74 ~3 ~71 stone_slab 8 
setblock ~70 ~3 ~72 dropper 0 
setblock ~70 ~3 ~73 dark_oak_stairs 2  
fill ~70 ~3 ~78 ~75 ~3 ~78 stonebrick 0  
fill ~70 ~3 ~80 ~76 ~3 ~80 dropper 0  
fill ~70 ~3 ~81 ~71 ~3 ~81 dropper 9  
fill ~70 ~3 ~86 ~118 ~3 ~86 stonebrick 0  
fill ~70 ~3 ~90 ~118 ~3 ~90 stonebrick 0  
fill ~70 ~3 ~92 ~118 ~3 ~92 stonebrick 0  
fill ~70 ~3 ~96 ~118 ~3 ~96 stonebrick 0  
fill ~70 ~3 ~98 ~118 ~3 ~98 stonebrick 0  
fill ~70 ~3 ~102 ~118 ~3 ~102 stonebrick 0  
fill ~70 ~3 ~104 ~118 ~3 ~104 stonebrick 0  
fill ~70 ~3 ~108 ~118 ~3 ~108 stonebrick 0  
fill ~70 ~3 ~109 ~118 ~3 ~109 stonebrick 0  
fill ~70 ~3 ~110 ~110 ~3 ~110 stonebrick 0 
setblock ~71 ~3 ~0 dark_oak_stairs 0  
fill ~71 ~3 ~45 ~72 ~3 ~45 stone_slab 8  
fill ~71 ~3 ~46 ~72 ~3 ~46 end_portal 0 
setblock ~71 ~3 ~48 end_portal 0 
setblock ~71 ~3 ~49 dropper 0 
setblock ~71 ~3 ~50 dark_oak_stairs 1 
setblock ~71 ~3 ~51 dark_oak_stairs 2 
setblock ~71 ~3 ~52 dark_oak_stairs 0 
setblock ~71 ~3 ~55 dropper 0 
setblock ~71 ~3 ~63 dropper 0 
setblock ~71 ~3 ~66 dark_oak_stairs 0 
setblock ~71 ~3 ~67 dark_oak_stairs 2 
setblock ~71 ~3 ~68 dark_oak_stairs 1  
fill ~71 ~3 ~70 ~74 ~3 ~70 stone_slab 8  
fill ~71 ~3 ~72 ~72 ~3 ~72 stone_slab 8  
fill ~71 ~3 ~73 ~72 ~3 ~73 stone_slab 8 
setblock ~71 ~3 ~118 dark_oak_stairs 0  
fill ~72 ~3 ~6 ~110 ~3 ~6 stonebrick 0  
fill ~72 ~3 ~33 ~73 ~3 ~33 redstone_block 0  
fill ~72 ~3 ~34 ~73 ~3 ~34 dropper 0  
fill ~72 ~3 ~36 ~73 ~3 ~36 dropper 9  
fill ~72 ~3 ~37 ~73 ~3 ~37 dropper 0  
fill ~72 ~3 ~47 ~73 ~3 ~47 end_portal 0  
fill ~72 ~3 ~48 ~72 ~3 ~49 stone_slab 8  
fill ~72 ~3 ~50 ~72 ~7 ~50 log 1 
setblock ~72 ~3 ~51 dropper 0  
fill ~72 ~3 ~52 ~73 ~3 ~52 dark_oak_stairs 3 
setblock ~72 ~3 ~55 dark_oak_stairs 1  
fill ~72 ~3 ~63 ~78 ~3 ~63 dark_oak_stairs 3 
setblock ~72 ~3 ~64 dark_oak_stairs 1  
fill ~72 ~3 ~66 ~73 ~3 ~66 dark_oak_stairs 2 
setblock ~72 ~3 ~67 dropper 0  
fill ~72 ~3 ~68 ~72 ~7 ~68 log 1 
setblock ~72 ~3 ~69 stone_slab 8  
fill ~72 ~3 ~81 ~73 ~3 ~81 dropper 0  
fill ~72 ~3 ~82 ~73 ~3 ~82 dropper 9  
fill ~72 ~3 ~84 ~73 ~3 ~84 dropper 0  
fill ~72 ~3 ~85 ~73 ~3 ~85 redstone_block 0  
fill ~72 ~3 ~112 ~110 ~3 ~112 stonebrick 0 
setblock ~73 ~3 ~0 dark_oak_stairs 1 
setblock ~73 ~3 ~45 dark_oak_stairs 3 
setblock ~73 ~3 ~46 dropper 0 
setblock ~73 ~3 ~48 end_portal 0 
setblock ~73 ~3 ~49 dropper 0  
fill ~73 ~3 ~50 ~74 ~3 ~50 dark_oak_stairs 2  
fill ~73 ~3 ~51 ~78 ~3 ~51 stonebrick 0 
setblock ~73 ~3 ~53 dark_oak_stairs 0  
fill ~73 ~3 ~54 ~78 ~3 ~54 dropper 0  
fill ~73 ~3 ~55 ~78 ~3 ~55 dark_oak_stairs 2  
fill ~73 ~3 ~64 ~78 ~3 ~64 dropper 0 
setblock ~73 ~3 ~65 dark_oak_stairs 0  
fill ~73 ~3 ~67 ~78 ~3 ~67 stonebrick 0  
fill ~73 ~3 ~68 ~74 ~3 ~68 dark_oak_stairs 3 
setblock ~73 ~3 ~69 dropper 0 
setblock ~73 ~3 ~72 dropper 0 
setblock ~73 ~3 ~73 dark_oak_stairs 2 
setblock ~73 ~3 ~118 dark_oak_stairs 1  
fill ~74 ~3 ~0 ~76 ~3 ~0 dark_oak_stairs 2  
fill ~74 ~3 ~5 ~110 ~3 ~5 stonebrick 0  
fill ~74 ~3 ~33 ~78 ~3 ~33 stonebrick 0  
fill ~74 ~3 ~34 ~78 ~3 ~34 stonebrick 0  
fill ~74 ~3 ~36 ~76 ~3 ~36 dropper 0  
fill ~74 ~3 ~37 ~76 ~3 ~37 dropper 9  
fill ~74 ~3 ~45 ~74 ~3 ~46 dark_oak_stairs 0  
fill ~74 ~3 ~47 ~74 ~3 ~48 stone_slab 8 
setblock ~74 ~3 ~49 dark_oak_stairs 0 
setblock ~74 ~3 ~52 dropper 0  
fill ~74 ~3 ~53 ~78 ~3 ~53 dark_oak_stairs 3  
fill ~74 ~3 ~58 ~74 ~5 ~58 bookshelf 0  
fill ~74 ~3 ~59 ~74 ~6 ~59 bookshelf 0  
fill ~74 ~3 ~60 ~74 ~5 ~60 bookshelf 0  
fill ~74 ~3 ~65 ~78 ~3 ~65 dark_oak_stairs 2 
setblock ~74 ~3 ~66 dropper 0 
setblock ~74 ~3 ~69 dark_oak_stairs 0  
fill ~74 ~3 ~72 ~74 ~3 ~73 dark_oak_stairs 0  
fill ~74 ~3 ~74 ~79 ~3 ~74 stonebrick 0  
fill ~74 ~3 ~81 ~76 ~3 ~81 dropper 9  
fill ~74 ~3 ~82 ~76 ~3 ~82 dropper 0  
fill ~74 ~3 ~84 ~78 ~3 ~84 stonebrick 0  
fill ~74 ~3 ~85 ~78 ~3 ~85 stonebrick 0  
fill ~74 ~3 ~111 ~110 ~3 ~111 stonebrick 0  
fill ~74 ~3 ~113 ~110 ~3 ~113 stonebrick 0  
fill ~74 ~3 ~118 ~76 ~3 ~118 dark_oak_stairs 3  
fill ~75 ~3 ~3 ~110 ~3 ~3 stonebrick 0  
fill ~75 ~3 ~4 ~110 ~3 ~4 stonebrick 0  
fill ~75 ~3 ~45 ~79 ~3 ~45 stonebrick 0  
fill ~75 ~3 ~46 ~75 ~3 ~49 dropper 0  
fill ~75 ~3 ~50 ~78 ~3 ~50 stonebrick 0  
fill ~75 ~3 ~52 ~77 ~3 ~52 stonebrick 0 
setblock ~75 ~3 ~56 redstone_block 0  
fill ~75 ~3 ~57 ~76 ~3 ~57 bookshelf 0 
setblock ~75 ~3 ~58 dark_oak_stairs 2 
setblock ~75 ~3 ~59 dark_oak_stairs 0 
setblock ~75 ~3 ~60 dark_oak_stairs 3  
fill ~75 ~3 ~61 ~76 ~3 ~61 bookshelf 0 
setblock ~75 ~3 ~62 redstone_block 0  
fill ~75 ~3 ~66 ~77 ~3 ~66 stonebrick 0  
fill ~75 ~3 ~68 ~78 ~3 ~68 stonebrick 0  
fill ~75 ~3 ~69 ~75 ~3 ~72 obsidian 0  
fill ~75 ~3 ~73 ~79 ~3 ~73 stonebrick 0  
fill ~75 ~3 ~114 ~110 ~3 ~114 stonebrick 0  
fill ~75 ~3 ~115 ~110 ~3 ~115 stonebrick 0  
fill ~76 ~3 ~2 ~110 ~3 ~2 stonebrick 0  
fill ~76 ~3 ~40 ~79 ~3 ~40 dropper 0  
fill ~76 ~3 ~46 ~79 ~3 ~46 stonebrick 0  
fill ~76 ~3 ~47 ~79 ~3 ~47 stonebrick 0  
fill ~76 ~3 ~48 ~79 ~3 ~48 stonebrick 0  
fill ~76 ~3 ~49 ~79 ~3 ~49 stonebrick 0  
fill ~76 ~3 ~56 ~79 ~3 ~56 stonebrick 0 
setblock ~76 ~3 ~58 dark_oak_stairs 0 
setblock ~76 ~3 ~59 glowstone 0 
setblock ~76 ~3 ~60 dark_oak_stairs 0  
fill ~76 ~3 ~62 ~79 ~3 ~62 stonebrick 0  
fill ~76 ~3 ~69 ~79 ~3 ~69 stonebrick 0  
fill ~76 ~3 ~70 ~79 ~3 ~70 stonebrick 0  
fill ~76 ~3 ~71 ~79 ~3 ~71 stonebrick 0  
fill ~76 ~3 ~72 ~79 ~3 ~72 stonebrick 0  
fill ~76 ~3 ~78 ~79 ~3 ~78 dropper 0  
fill ~76 ~3 ~116 ~110 ~3 ~116 stonebrick 0  
fill ~76 ~3 ~117 ~110 ~3 ~117 stonebrick 0 
setblock ~77 ~3 ~0 dark_oak_stairs 0  
fill ~77 ~3 ~36 ~78 ~3 ~36 dropper 9  
fill ~77 ~3 ~37 ~81 ~3 ~37 dropper 0  
fill ~77 ~3 ~38 ~78 ~3 ~38 dropper 9 
setblock ~77 ~3 ~57 stonebrick 0  
fill ~77 ~3 ~58 ~78 ~3 ~58 dropper 0  
fill ~77 ~3 ~59 ~82 ~3 ~59 dropper 0  
fill ~77 ~3 ~60 ~78 ~3 ~60 dropper 0 
setblock ~77 ~3 ~61 stonebrick 0  
fill ~77 ~3 ~80 ~78 ~3 ~80 dropper 9  
fill ~77 ~3 ~81 ~81 ~3 ~81 dropper 0  
fill ~77 ~3 ~82 ~78 ~3 ~82 dropper 9 
setblock ~77 ~3 ~118 dark_oak_stairs 0  
fill ~78 ~3 ~0 ~111 ~3 ~0 log 1  
fill ~78 ~3 ~1 ~110 ~3 ~1 stonebrick 0  
fill ~78 ~3 ~41 ~80 ~3 ~41 dropper 0  
fill ~78 ~3 ~52 ~81 ~3 ~52 dropper 0 
setblock ~78 ~3 ~57 dark_oak_stairs 1 
setblock ~78 ~3 ~61 dark_oak_stairs 1  
fill ~78 ~3 ~66 ~81 ~3 ~66 dropper 0  
fill ~78 ~3 ~77 ~80 ~3 ~77 dropper 0  
fill ~78 ~3 ~118 ~111 ~3 ~118 log 1  
fill ~79 ~3 ~33 ~80 ~3 ~33 redstone_block 0 
setblock ~79 ~3 ~34 dropper 0 
setblock ~79 ~3 ~35 dropper 9  
fill ~79 ~3 ~36 ~81 ~3 ~36 dropper 0  
fill ~79 ~3 ~38 ~80 ~3 ~38 dropper 0  
fill ~79 ~3 ~39 ~80 ~3 ~39 dropper 9  
fill ~79 ~3 ~42 ~80 ~3 ~42 dropper 0  
fill ~79 ~3 ~43 ~81 ~3 ~43 dropper 0  
fill ~79 ~3 ~50 ~80 ~3 ~50 dropper 0  
fill ~79 ~3 ~51 ~80 ~3 ~51 dropper 0   

KittysCommands:  
setblock ~79 ~3 ~53 dark_oak_stairs 0  
fill ~79 ~3 ~54 ~80 ~3 ~54 dropper 9 
setblock ~79 ~3 ~55 dark_oak_stairs 0 
setblock ~79 ~3 ~57 dark_oak_stairs 3 
setblock ~79 ~3 ~58 dark_oak_stairs 0 
setblock ~79 ~3 ~60 dark_oak_stairs 0 
setblock ~79 ~3 ~61 dark_oak_stairs 2 
setblock ~79 ~3 ~63 dark_oak_stairs 0  
fill ~79 ~3 ~64 ~80 ~3 ~64 dropper 9 
setblock ~79 ~3 ~65 dark_oak_stairs 0  
fill ~79 ~3 ~67 ~80 ~3 ~67 dropper 0  
fill ~79 ~3 ~68 ~80 ~3 ~68 dropper 0  
fill ~79 ~3 ~75 ~81 ~3 ~75 dropper 0  
fill ~79 ~3 ~76 ~80 ~3 ~76 dropper 0  
fill ~79 ~3 ~79 ~80 ~3 ~79 dropper 9  
fill ~79 ~3 ~80 ~80 ~3 ~80 dropper 0  
fill ~79 ~3 ~82 ~81 ~3 ~82 dropper 0 
setblock ~79 ~3 ~83 dropper 9 
setblock ~79 ~3 ~84 dropper 0  
fill ~79 ~3 ~85 ~80 ~3 ~85 redstone_block 0  
fill ~80 ~3 ~34 ~84 ~3 ~34 stonebrick 0 
setblock ~80 ~3 ~35 dropper 0 
setblock ~80 ~3 ~40 dropper 9  
fill ~80 ~3 ~44 ~81 ~3 ~44 dropper 0  
fill ~80 ~3 ~45 ~81 ~3 ~45 dropper 0  
fill ~80 ~3 ~46 ~82 ~3 ~46 dropper 0  
fill ~80 ~3 ~47 ~82 ~3 ~47 dropper 0  
fill ~80 ~3 ~48 ~81 ~3 ~48 dropper 0  
fill ~80 ~3 ~49 ~81 ~3 ~49 dropper 0 
setblock ~80 ~3 ~53 dropper 0  
fill ~80 ~3 ~55 ~82 ~3 ~55 dropper 0  
fill ~80 ~3 ~56 ~82 ~3 ~56 dropper 0 
setblock ~80 ~3 ~57 stonebrick 0 
setblock ~80 ~3 ~58 dark_oak_stairs 3 
setblock ~80 ~3 ~60 dark_oak_stairs 2 
setblock ~80 ~3 ~61 stonebrick 0  
fill ~80 ~3 ~62 ~82 ~3 ~62 dropper 0  
fill ~80 ~3 ~63 ~82 ~3 ~63 dropper 0 
setblock ~80 ~3 ~65 dropper 0  
fill ~80 ~3 ~69 ~81 ~3 ~69 dropper 0  
fill ~80 ~3 ~70 ~81 ~3 ~70 dropper 0  
fill ~80 ~3 ~71 ~82 ~3 ~71 dropper 0  
fill ~80 ~3 ~72 ~82 ~3 ~72 dropper 0  
fill ~80 ~3 ~73 ~81 ~3 ~73 dropper 0  
fill ~80 ~3 ~74 ~81 ~3 ~74 dropper 0 
setblock ~80 ~3 ~78 dropper 9 
setblock ~80 ~3 ~83 dropper 0  
fill ~80 ~3 ~84 ~84 ~3 ~84 stonebrick 0  
fill ~81 ~3 ~33 ~118 ~3 ~33 stonebrick 0  
fill ~81 ~3 ~35 ~118 ~3 ~35 stonebrick 0 
setblock ~81 ~3 ~38 dropper 9  
fill ~81 ~3 ~39 ~84 ~3 ~39 dropper 0  
fill ~81 ~3 ~40 ~83 ~3 ~40 dropper 0  
fill ~81 ~3 ~41 ~81 ~3 ~42 dropper 9  
fill ~81 ~3 ~50 ~81 ~3 ~51 dropper 9 
setblock ~81 ~3 ~53 dropper 9  
fill ~81 ~3 ~54 ~83 ~3 ~54 dropper 0  
fill ~81 ~3 ~57 ~84 ~3 ~57 dropper 0  
fill ~81 ~3 ~58 ~84 ~3 ~58 dropper 0  
fill ~81 ~3 ~60 ~81 ~3 ~64 dropper 0 
setblock ~81 ~3 ~65 dropper 9  
fill ~81 ~3 ~67 ~81 ~3 ~68 dropper 9  
fill ~81 ~3 ~76 ~81 ~3 ~77 dropper 9  
fill ~81 ~3 ~78 ~83 ~3 ~78 dropper 0  
fill ~81 ~3 ~79 ~84 ~3 ~79 dropper 0 
setblock ~81 ~3 ~80 dropper 9  
fill ~81 ~3 ~83 ~118 ~3 ~83 stonebrick 0  
fill ~81 ~3 ~85 ~118 ~3 ~85 stonebrick 0  
fill ~82 ~3 ~36 ~82 ~3 ~37 dropper 9  
fill ~82 ~3 ~38 ~83 ~3 ~38 dropper 0  
fill ~82 ~3 ~41 ~82 ~3 ~42 dropper 0  
fill ~82 ~3 ~43 ~82 ~3 ~45 dropper 9  
fill ~82 ~3 ~48 ~82 ~3 ~49 dropper 9  
fill ~82 ~3 ~50 ~84 ~3 ~50 dropper 0  
fill ~82 ~3 ~51 ~84 ~3 ~51 dropper 0 
setblock ~82 ~3 ~52 dropper 9 
setblock ~82 ~3 ~53 dropper 0  
fill ~82 ~3 ~60 ~82 ~3 ~61 dropper 9  
fill ~82 ~3 ~64 ~83 ~3 ~64 dropper 0  
fill ~82 ~3 ~65 ~82 ~3 ~62 dropper 0 
setblock ~82 ~3 ~66 dropper 9  
fill ~82 ~3 ~67 ~84 ~3 ~67 dropper 0  
fill ~82 ~3 ~68 ~84 ~3 ~68 dropper 0  
fill ~82 ~3 ~69 ~82 ~3 ~70 dropper 9  
fill ~82 ~3 ~73 ~82 ~3 ~75 dropper 9  
fill ~82 ~3 ~76 ~82 ~3 ~80 dropper 0  
fill ~82 ~3 ~81 ~83 ~3 ~81 dropper 9  
fill ~82 ~3 ~82 ~82 ~3 ~81 dropper 9  
fill ~83 ~3 ~36 ~118 ~3 ~36 stonebrick 0 
setblock ~83 ~3 ~37 dropper 9  
fill ~83 ~3 ~41 ~83 ~3 ~42 dropper 9  
fill ~83 ~3 ~43 ~84 ~3 ~43 dropper 0  
fill ~83 ~3 ~44 ~84 ~3 ~44 dropper 0  
fill ~83 ~3 ~45 ~84 ~3 ~45 dropper 0  
fill ~83 ~3 ~46 ~83 ~3 ~47 dropper 9  
fill ~83 ~3 ~48 ~84 ~3 ~48 dropper 0  
fill ~83 ~3 ~49 ~84 ~3 ~49 dropper 0 
setblock ~83 ~3 ~52 dropper 0 
setblock ~83 ~3 ~53 dropper 9  
fill ~83 ~3 ~55 ~83 ~3 ~56 dropper 9 
setblock ~83 ~3 ~59 dropper 9  
fill ~83 ~3 ~60 ~84 ~3 ~60 dropper 0  
fill ~83 ~3 ~61 ~84 ~3 ~61 dropper 0  
fill ~83 ~3 ~62 ~83 ~3 ~63 dropper 9 
setblock ~83 ~3 ~65 dropper 9 
setblock ~83 ~3 ~66 dropper 0  
fill ~83 ~3 ~69 ~84 ~3 ~69 dropper 0  
fill ~83 ~3 ~70 ~84 ~3 ~70 dropper 0  
fill ~83 ~3 ~71 ~83 ~3 ~72 dropper 9  
fill ~83 ~3 ~73 ~84 ~3 ~73 dropper 0  
fill ~83 ~3 ~74 ~84 ~3 ~74 dropper 0  
fill ~83 ~3 ~75 ~84 ~3 ~75 dropper 0  
fill ~83 ~3 ~76 ~83 ~3 ~77 dropper 9 
setblock ~83 ~3 ~80 dropper 0  
fill ~83 ~3 ~82 ~118 ~3 ~82 stonebrick 0  
fill ~84 ~3 ~37 ~118 ~3 ~37 stonebrick 0  
fill ~84 ~3 ~38 ~118 ~3 ~38 stonebrick 0 
setblock ~84 ~3 ~40 dropper 9  
fill ~84 ~3 ~41 ~84 ~3 ~51 dropper 0 
setblock ~84 ~3 ~52 dropper 9  
fill ~84 ~3 ~53 ~86 ~3 ~53 dropper 0 
setblock ~84 ~3 ~54 dropper 9  
fill ~84 ~3 ~55 ~84 ~3 ~63 dropper 0 
setblock ~84 ~3 ~64 dropper 9  
