setblock ~13~68~1 minecraft:purpur_stairs 6
setblock ~13~66~2 minecraft:purpur_stairs 6
fill ~13~67~2 ~13~67~3 minecraft:purpur_block 0
setblock ~13~68~2 minecraft:purpur_stairs 3
fill ~9~54~3 ~9~54~9 minecraft:purpur_stairs 0
setblock ~10~54~3 minecraft:purpur_stairs 5
setblock ~10~55~3 minecraft:purpur_block 0
setblock ~10~56~3 minecraft:purpur_stairs 0
setblock ~11~56~3 minecraft:purpur_stairs 5
fill ~11~57~3 ~11~58~3 minecraft:purpur_block 0
setblock ~11~59~3 minecraft:purpur_stairs 0
setblock ~12~59~3 minecraft:purpur_stairs 5
fill ~12~60~3 ~12~62~3 minecraft:purpur_block 0
setblock ~12~63~3 minecraft:purpur_stairs 0
setblock ~13~63~3 minecraft:purpur_stairs 6
fill ~13~64~3 ~13~66~3 minecraft:purpur_block 0
setblock ~14~59~3 minecraft:purpur_stairs 4
fill ~14~60~3 ~14~62~3 minecraft:purpur_block 0
setblock ~14~63~3 minecraft:purpur_stairs 1
setblock ~15~56~3 minecraft:purpur_stairs 4
fill ~15~57~3 ~15~58~3 minecraft:purpur_block 0
setblock ~15~59~3 minecraft:purpur_stairs 1
setblock ~16~54~3 minecraft:purpur_stairs 4
setblock ~16~55~3 minecraft:purpur_block 0
setblock ~16~56~3 minecraft:purpur_stairs 1
fill ~17~54~3 ~17~54~8 minecraft:purpur_stairs 1
fill ~10~54~4 ~10~54~5 minecraft:nether_brick_stairs 5
fill ~10~55~4 ~10~55~9 minecraft:nether_brick
fill ~10~56~4 ~10~56~10 minecraft:nether_brick_stairs 0
fill ~11~5~4 ~15~5~4 minecraft:stone_block_slab2 1
setblock ~11~50~4 minecraft:cobblestone_wall 0
setblock ~11~51~4 minecraft:torch 5
setblock ~11~56~4 minecraft:nether_brick_stairs 5
fill ~11~57~4 ~11~58~5 minecraft:nether_brick
fill ~11~59~4 ~11~59~5 minecraft:nether_brick_stairs 0
fill ~12~49~4 ~12~49~5 minecraft:purpur_stairs 4
fill ~12~50~4 ~12~50~22 minecraft:stonebrick 0
fill ~12~51~4 ~12~59~4 minecraft:stonebrick 0
fill ~12~60~4 ~12~62~11 minecraft:nether_brick
fill ~12~63~4 ~12~63~12 minecraft:nether_brick_stairs 0
setblock ~13~0~4 minecraft:purpur_stairs 2
setblock ~13~47~4 minecraft:wooden_button 2
setblock ~13~48~4 minecraft:purpur_stairs 6
setblock ~13~49~4 minecraft:purpur_stairs 2
setblock ~13~50~4 minecraft:stone_brick_stairs 6
setblock ~13~51~4 minecraft:stone_brick_stairs 2
fill ~13~52~4 ~13~55~4 minecraft:stained_glass_pane 10
setblock ~13~56~4 minecraft:stone_brick_stairs 6
fill ~13~57~4 ~14~59~4 minecraft:stonebrick 0
fill ~13~60~4 ~13~62~4 minecraft:stonebrick 0
fill ~13~64~4 ~13~64~8 minecraft:nether_brick
fill ~13~65~4 ~13~65~5 minecraft:nether_brick
fill ~13~66~4 ~13~66~5 minecraft:purpur_block 0
setblock ~13~67~4 minecraft:purpur_stairs 3
fill ~14~49~4 ~14~49~5 minecraft:purpur_stairs 5
fill ~14~50~4 ~14~50~22 minecraft:stonebrick 0
fill ~14~51~4 ~14~56~4 minecraft:stonebrick 0
fill ~14~60~4 ~14~62~11 minecraft:nether_brick
fill ~14~63~4 ~14~63~12 minecraft:nether_brick_stairs 1
setblock ~15~50~4 minecraft:cobblestone_wall 0
setblock ~15~51~4 minecraft:torch 5
setblock ~15~56~4 minecraft:nether_brick_stairs 4
fill ~15~57~4 ~15~58~5 minecraft:nether_brick
fill ~15~59~4 ~15~59~5 minecraft:nether_brick_stairs 1
fill ~16~54~4 ~16~54~5 minecraft:nether_brick_stairs 4
fill ~16~55~4 ~16~55~9 minecraft:nether_brick
fill ~16~56~4 ~16~56~9 minecraft:nether_brick_stairs 1
fill ~9~5~5 ~10~5~5 minecraft:stone_block_slab2 1
setblock ~10~57~5 minecraft:purpur_stairs 4
setblock ~10~58~5 minecraft:purpur_stairs 2
setblock ~11~0~5 minecraft:stone_block_slab2 1
setblock ~11~4~5 minecraft:stone_block_slab 13
setblock ~11~9~5 minecraft:stone_block_slab2 1
fill ~11~10~5 ~11~11~5 minecraft:cobblestone_wall 0
fill ~11~12~5 ~11~12~6 minecraft:purpur_stairs 0
setblock ~11~47~5 minecraft:wooden_button 2
setblock ~11~49~5 minecraft:purpur_stairs 6
fill ~11~50~5 ~11~50~7 minecraft:stonebrick 0
fill ~11~51~5 ~11~56~5 minecraft:stonebrick 0
setblock ~12~0~5 minecraft:purpur_stairs 2
setblock ~12~4~5 minecraft:stone_brick_stairs 6
setblock ~12~12~5 minecraft:stone_block_slab2 1
setblock ~12~13~5 minecraft:stone_block_slab2 1
setblock ~12~47~5 minecraft:purpur_stairs 4
setblock ~12~48~5 minecraft:purpur_stairs 0
fill ~13~0~5 ~13~0~21 minecraft:stonebrick 0
setblock ~13~1~5 minecraft:stone_brick_stairs 2
setblock ~13~3~5 minecraft:stone_brick_stairs 6
setblock ~13~4~5 minecraft:stonebrick 0
setblock ~13~13~5 minecraft:double_stone_block_slab2 1
setblock ~13~46~5 minecraft:purpur_stairs 6
fill ~13~47~5 ~13~49~5 minecraft:purpur_block 0
fill ~13~50~5 ~13~50~21 minecraft:stonebrick 0
setblock ~14~0~5 minecraft:purpur_stairs 2
setblock ~14~4~5 minecraft:stone_brick_stairs 6
setblock ~14~12~5 minecraft:stone_block_slab2 1
setblock ~14~13~5 minecraft:stone_block_slab2 1
setblock ~14~47~5 minecraft:purpur_stairs 5
setblock ~14~48~5 minecraft:purpur_stairs 1
setblock ~15~0~5 minecraft:stone_block_slab2 1
setblock ~15~4~5 minecraft:stone_block_slab 13
setblock ~15~9~5 minecraft:stone_block_slab2 1
fill ~15~10~5 ~15~11~5 minecraft:cobblestone_wall 0
fill ~15~12~5 ~15~12~6 minecraft:purpur_stairs 1
setblock ~15~47~5 minecraft:wooden_button 2
setblock ~15~49~5 minecraft:purpur_stairs 6
fill ~15~50~5 ~15~50~7 minecraft:stonebrick 0
fill ~15~51~5 ~15~56~5 minecraft:stonebrick 0
fill ~16~5~5 ~17~5~5 minecraft:stone_block_slab2 1
setblock ~16~57~5 minecraft:purpur_stairs 5
setblock ~16~58~5 minecraft:purpur_stairs 2
setblock ~8~5~6 minecraft:stone_block_slab2 1
setblock ~9~0~6 minecraft:stone_block_slab2 1
setblock ~9~1~6 minecraft:stone_brick_stairs 6
setblock ~9~2~6 minecraft:cobblestone_wall 0
setblock ~9~3~6 minecraft:stone_brick_stairs 2
setblock ~9~4~6 minecraft:stone_block_slab 13
setblock ~10~0~6 minecraft:stone_brick_stairs 6
setblock ~10~1~6 minecraft:stone_brick_stairs 2
setblock ~10~3~6 minecraft:stone_brick_stairs 6
fill ~10~4~6 ~11~4~6 minecraft:stonebrick 0
setblock ~10~47~6 minecraft:wooden_button 4
fill ~10~49~6 ~10~49~9 minecraft:purpur_stairs 4
fill ~10~50~6 ~10~54~6 minecraft:log 1
setblock ~10~58~6 minecraft:purpur_stairs 7
setblock ~10~59~6 minecraft:purpur_block 0
setblock ~10~60~6 minecraft:purpur_stairs 2
fill ~11~0~6 ~12~0~20 minecraft:stonebrick 0
setblock ~11~1~6 minecraft:stone_brick_stairs 6
setblock ~11~2~6 minecraft:cobblestone_wall 0
setblock ~11~3~6 minecraft:stone_brick_stairs 2
setblock ~11~8~6 minecraft:stone_brick_stairs 4
setblock ~11~46~6 minecraft:purpur_stairs 6
fill ~11~47~6 ~11~49~6 minecraft:purpur_block 0
setblock ~11~51~6 minecraft:stone_brick_stairs 5
fill ~11~56~6 ~11~56~10 minecraft:stonebrick 0
fill ~11~57~6 ~11~58~6 minecraft:stained_glass_pane 10
setblock ~11~59~6 minecraft:nether_brick
setblock ~11~60~6 minecraft:nether_brick_stairs 2
setblock ~12~1~6 minecraft:cobblestone_wall 0
setblock ~12~2~6 minecraft:stone_brick_stairs 2
setblock ~12~3~6 minecraft:stone_brick_stairs 6
fill ~12~4~6 ~14~4~12 minecraft:stone 6
setblock ~12~5~6 minecraft:stone_brick_stairs 2
setblock ~12~6~6 minecraft:stone_brick_stairs 6
fill ~12~7~6 ~12~12~6 minecraft:stonebrick 0
setblock ~12~13~6 minecraft:stone_block_slab 5
fill ~12~48~6 ~14~49~7 minecraft:stonebrick 0
fill ~13~1~6 ~13~3~6 minecraft:stone 6
setblock ~13~5~6 minecraft:stone_brick_stairs 6
setblock ~13~6~6 minecraft:stone_brick_stairs 2
fill ~13~7~6 ~13~11~6 minecraft:stained_glass_pane 2
setblock ~13~12~6 minecraft:stone_brick_stairs 6
setblock ~13~13~6 minecraft:double_stone_block_slab 5
setblock ~13~43~6 minecraft:purpur_stairs 6
fill ~13~44~6 ~13~45~6 minecraft:purpur_block 0
setblock ~13~46~6 minecraft:purpur_stairs 3
fill ~13~65~6 ~13~65~8 minecraft:purpur_block 0
setblock ~13~66~6 minecraft:purpur_stairs 3
fill ~14~0~6 ~15~0~20 minecraft:stonebrick 0
setblock ~14~1~6 minecraft:cobblestone_wall 0
setblock ~14~2~6 minecraft:stone_brick_stairs 2
setblock ~14~3~6 minecraft:stone_brick_stairs 6
setblock ~14~5~6 minecraft:stone_brick_stairs 2
setblock ~14~6~6 minecraft:stone_brick_stairs 6
fill ~14~7~6 ~14~12~6 minecraft:stonebrick 0
setblock ~14~13~6 minecraft:stone_block_slab 5
setblock ~15~1~6 minecraft:stone_brick_stairs 6
setblock ~15~2~6 minecraft:cobblestone_wall 0
setblock ~15~3~6 minecraft:stone_brick_stairs 2
fill ~15~4~6 ~16~4~6 minecraft:stonebrick 0
setblock ~15~8~6 minecraft:stone_brick_stairs 5
setblock ~15~46~6 minecraft:purpur_stairs 6
fill ~15~47~6 ~15~49~6 minecraft:purpur_block 0
setblock ~15~51~6 minecraft:stone_brick_stairs 4
fill ~15~56~6 ~15~56~10 minecraft:stonebrick 0
fill ~15~57~6 ~15~58~8 minecraft:stained_glass_pane 10
setblock ~15~59~6 minecraft:nether_brick
setblock ~15~60~6 minecraft:nether_brick_stairs 2
setblock ~16~0~6 minecraft:stone_brick_stairs 6
setblock ~16~1~6 minecraft:stone_brick_stairs 2
setblock ~16~3~6 minecraft:stone_brick_stairs 6
setblock ~16~47~6 minecraft:wooden_button 5
fill ~16~49~6 ~16~49~9 minecraft:purpur_stairs 5
fill ~16~50~6 ~16~54~6 minecraft:log 1
setblock ~16~58~6 minecraft:purpur_stairs 7
setblock ~16~59~6 minecraft:purpur_block 0
setblock ~16~60~6 minecraft:purpur_stairs 2
setblock ~17~0~6 minecraft:stone_block_slab2 1
setblock ~17~1~6 minecraft:stone_brick_stairs 6
setblock ~17~2~6 minecraft:cobblestone_wall 0
setblock ~17~3~6 minecraft:stone_brick_stairs 2
setblock ~17~4~6 minecraft:stone_block_slab 13
setblock ~18~5~6 minecraft:stone_block_slab2 1
setblock ~7~0~7 minecraft:cobblestone_wall 0
fill ~7~1~7 ~7~3~7 minecraft:cobblestone_wall 0
setblock ~7~4~7 minecraft:cobblestone_wall 0
setblock ~7~5~7 minecraft:stone_block_slab2 1
setblock ~8~0~7 minecraft:stone_block_slab2 1
setblock ~8~4~7 minecraft:stone_brick_stairs 4
fill ~9~0~7 ~10~0~19 minecraft:stonebrick 0
setblock ~9~1~7 minecraft:stone_brick_stairs 0
setblock ~9~3~7 minecraft:stone_brick_stairs 4
fill ~9~4~7 ~9~4~8 minecraft:stonebrick 0
setblock ~9~62~7 minecraft:purpur_stairs 4
setblock ~10~1~7 minecraft:stone 6
setblock ~10~2~7 minecraft:glowstone
fill ~10~3~7 ~11~4~7 minecraft:stone 6
setblock ~10~5~7 minecraft:stone_brick_stairs 0
setblock ~10~7~7 minecraft:stone_brick_stairs 4
setblock ~10~8~7 minecraft:cobblestone_wall 0
setblock ~10~9~7 minecraft:stone_brick_stairs 0
setblock ~10~11~7 minecraft:stone_brick_stairs 4
setblock ~10~12~7 minecraft:cobblestone_wall 0
setblock ~10~13~7 minecraft:stone_brick_stairs 0
setblock ~10~50~7 minecraft:stone_brick_stairs 4
setblock ~10~54~7 minecraft:stone_brick_stairs 7
setblock ~10~60~7 minecraft:purpur_stairs 4
setblock ~10~61~7 minecraft:purpur_block 0
setblock ~10~62~7 minecraft:purpur_stairs 1
setblock ~11~1~7 minecraft:glowstone
setblock ~11~2~7 minecraft:purpur_block 0
fill ~11~5~7 ~11~13~7 minecraft:stonebrick 0
setblock ~11~35~7 minecraft:stone_block_slab 15
setblock ~11~36~7 minecraft:cobblestone_wall 0
fill ~11~37~7 ~11~37~8 minecraft:nether_brick_stairs 0
setblock ~11~44~7 minecraft:purpur_stairs 6
setblock ~11~45~7 minecraft:purpur_block 0
setblock ~11~46~7 minecraft:purpur_stairs 3
fill ~11~49~7 ~11~49~9 minecraft:stonebrick 0
fill ~11~51~7 ~11~55~7 minecraft:stonebrick 0
fill ~11~58~7 ~11~58~8 minecraft:stained_glass_pane 10
setblock ~11~59~7 minecraft:stained_glass_pane 10
setblock ~11~60~7 minecraft:nether_brick
setblock ~11~61~7 minecraft:purpur_stairs 1
fill ~12~1~7 ~14~1~7 minecraft:cobblestone
setblock ~12~12~7 minecraft:stone_brick_stairs 5
fill ~12~13~7 ~12~15~7 minecraft:stonebrick 0
setblock ~12~16~7 minecraft:stone_brick_stairs 4
setblock ~12~17~7 minecraft:cobblestone_wall 0
setblock ~12~18~7 minecraft:stone_brick_stairs 0
setblock ~12~19~7 minecraft:stone_brick_stairs 4
setblock ~12~20~7 minecraft:stone_brick_stairs 0
setblock ~12~23~7 minecraft:stone_block_slab 15
setblock ~12~33~7 minecraft:nether_brick_stairs 4
setblock ~12~37~7 minecraft:stone_block_slab 15
setblock ~12~38~7 minecraft:stone_block_slab 7
fill ~12~41~7 ~12~42~8 minecraft:stonebrick 0
fill ~12~43~7 ~12~47~7 minecraft:stonebrick 0
setblock ~13~13~7 minecraft:stone_brick_stairs 7
setblock ~13~14~7 minecraft:stone_brick_stairs 2
setblock ~13~15~7 minecraft:stone_brick_stairs 6
setblock ~13~16~7 minecraft:stone_brick_stairs 2
setblock ~13~18~7 minecraft:stone_brick_stairs 6
setblock ~13~19~7 minecraft:stone_brick_stairs 2
setblock ~13~20~7 minecraft:stone_brick_stairs 6
setblock ~13~21~7 minecraft:stone_brick_stairs 2
setblock ~13~24~7 minecraft:stone_block_slab 7
setblock ~13~33~7 minecraft:nether_brick_stairs 6
setblock ~13~38~7 minecraft:double_stone_block_slab 7
setblock ~13~41~7 minecraft:stone_brick_stairs 6
setblock ~13~42~7 minecraft:stone_brick_stairs 2
setblock ~13~43~7 minecraft:purpur_block 0
fill ~13~44~7 ~14~47~7 minecraft:stonebrick 0
setblock ~14~12~7 minecraft:stone_brick_stairs 4
fill ~14~13~7 ~15~13~7 minecraft:stonebrick 0
fill ~14~14~7 ~14~14~8 minecraft:stonebrick 0
setblock ~14~15~7 minecraft:stonebrick 0
setblock ~14~16~7 minecraft:stone_brick_stairs 5
setblock ~14~17~7 minecraft:cobblestone_wall 0
setblock ~14~18~7 minecraft:stone_brick_stairs 1
setblock ~14~19~7 minecraft:stone_brick_stairs 5
setblock ~14~20~7 minecraft:stone_brick_stairs 1
setblock ~14~23~7 minecraft:stone_block_slab 15
setblock ~14~33~7 minecraft:nether_brick_stairs 5
setblock ~14~37~7 minecraft:stone_block_slab 15
setblock ~14~38~7 minecraft:stone_block_slab 7
fill ~14~41~7 ~14~42~8 minecraft:stonebrick 0
setblock ~14~43~7 minecraft:stonebrick 0
setblock ~15~1~7 minecraft:stone 6
setblock ~15~2~7 minecraft:purpur_block 0
fill ~15~3~7 ~16~4~7 minecraft:stone 6
fill ~15~5~7 ~15~12~7 minecraft:stonebrick 0
setblock ~15~35~7 minecraft:stone_block_slab 15
setblock ~15~36~7 minecraft:cobblestone_wall 0
fill ~15~37~7 ~15~37~8 minecraft:nether_brick_stairs 1
setblock ~15~44~7 minecraft:purpur_stairs 6
setblock ~15~45~7 minecraft:purpur_block 0
setblock ~15~46~7 minecraft:purpur_stairs 3
fill ~15~49~7 ~15~49~9 minecraft:stonebrick 0
fill ~15~51~7 ~15~55~7 minecraft:stonebrick 0
setblock ~15~59~7 minecraft:stained_glass_pane 10
setblock ~15~60~7 minecraft:nether_brick
setblock ~15~61~7 minecraft:purpur_stairs 0
fill ~16~0~7 ~17~0~19 minecraft:stonebrick 0
setblock ~16~2~7 minecraft:glowstone
setblock ~16~5~7 minecraft:stone_brick_stairs 1
setblock ~16~7~7 minecraft:stone_brick_stairs 5
setblock ~16~8~7 minecraft:cobblestone_wall 0
setblock ~16~9~7 minecraft:stone_brick_stairs 1
setblock ~16~11~7 minecraft:stone_brick_stairs 5
setblock ~16~12~7 minecraft:cobblestone_wall 0
setblock ~16~13~7 minecraft:stone_brick_stairs 1
setblock ~16~50~7 minecraft:stone_brick_stairs 5
setblock ~16~54~7 minecraft:stone_brick_stairs 7
setblock ~16~60~7 minecraft:purpur_stairs 5
setblock ~16~61~7 minecraft:purpur_block 0
setblock ~16~62~7 minecraft:purpur_stairs 0
setblock ~17~1~7 minecraft:stone_brick_stairs 1
setblock ~17~3~7 minecraft:stone_brick_stairs 5
fill ~17~4~7 ~17~4~8 minecraft:stonebrick 0
setblock ~17~62~7 minecraft:purpur_stairs 5
setblock ~18~0~7 minecraft:stone_block_slab2 1
setblock ~18~4~7 minecraft:stone_brick_stairs 5
setblock ~19~0~7 minecraft:cobblestone_wall 0
fill ~19~1~7 ~19~3~7 minecraft:cobblestone_wall 0
setblock ~19~4~7 minecraft:cobblestone_wall 0
setblock ~19~5~7 minecraft:stone_block_slab2 1
setblock ~6~5~8 minecraft:stone_block_slab2 1
setblock ~7~0~8 minecraft:stone_block_slab2 1
setblock ~7~4~8 minecraft:stone_brick_stairs 6
fill ~8~0~8 ~8~0~18 minecraft:stonebrick 0
fill ~8~4~8 ~8~4~9 minecraft:stonebrick 0
setblock ~9~1~8 minecraft:stone_brick_stairs 7
setblock ~9~2~8 minecraft:cobblestone_wall 0
setblock ~9~3~8 minecraft:stone_brick_stairs 3
setblock ~9~5~8 minecraft:stone_brick_stairs 4
fill ~9~6~8 ~9~6~9 minecraft:stonebrick 0
setblock ~9~7~8 minecraft:stone_brick_stairs 2
setblock ~9~9~8 minecraft:stone_brick_stairs 6
setblock ~9~10~8 minecraft:cobblestone_wall 0
setblock ~9~11~8 minecraft:stone_brick_stairs 2
setblock ~9~13~8 minecraft:stone_brick_stairs 6
fill ~10~1~8 ~11~1~8 minecraft:cobblestone
setblock ~10~2~8 minecraft:purpur_block 0
fill ~10~3~8 ~10~4~8 minecraft:stone 6
fill ~10~5~8 ~10~16~8 minecraft:nether_brick
setblock ~10~17~8 minecraft:nether_brick_stairs 2
setblock ~10~23~8 minecraft:stone_block_slab 7
setblock ~10~41~8 minecraft:stone_brick_stairs 4
fill ~10~42~8 ~10~44~9 minecraft:stonebrick 0
setblock ~10~45~8 minecraft:stone_brick_stairs 0
setblock ~10~47~8 minecraft:stone_brick_stairs 4
setblock ~10~48~8 minecraft:stone_brick_stairs 0
setblock ~10~58~8 minecraft:purpur_stairs 6
setblock ~10~59~8 minecraft:purpur_block 0
setblock ~10~60~8 minecraft:purpur_stairs 3
fill ~11~4~8 ~11~4~19 minecraft:stone 6
fill ~11~14~8 ~13~14~8 minecraft:stonebrick 0
fill ~11~15~8 ~11~22~8 minecraft:stonebrick 0
setblock ~11~23~8 minecraft:nether_brick_stairs 2
setblock ~11~28~8 minecraft:purpur_stairs 0
setblock ~11~39~8 minecraft:stone_brick_stairs 6
setblock ~11~40~8 minecraft:cobblestone_wall 0
setblock ~11~41~8 minecraft:stone_brick_stairs 2
setblock ~11~42~8 minecraft:stone_brick_stairs 6
fill ~11~43~8 ~11~48~8 minecraft:stonebrick 0
setblock ~11~50~8 minecraft:stone_brick_stairs 0
fill ~11~51~8 ~11~53~8 minecraft:stained_glass_pane 10
setblock ~11~54~8 minecraft:stone_brick_stairs 4
fill ~11~55~8 ~11~55~9 minecraft:stonebrick 0
setblock ~11~57~8 minecraft:stained_glass_pane 10
setblock ~11~59~8 minecraft:nether_brick
setblock ~11~60~8 minecraft:nether_brick_stairs 3
setblock ~12~15~8 minecraft:stone_brick_stairs 7
fill ~12~16~8 ~12~21~8 minecraft:stained_glass 10
setblock ~12~22~8 minecraft:stone_brick_stairs 2
setblock ~12~28~8 minecraft:purpur_stairs 5
setblock ~12~31~8 minecraft:stone_brick_stairs 4
setblock ~12~32~8 minecraft:stone_brick_stairs 0
fill ~12~33~8 ~14~33~8 minecraft:stonebrick 0
fill ~12~34~8 ~12~37~8 minecraft:stonebrick 0
setblock ~12~38~8 minecraft:stone_block_slab 5
setblock ~12~43~8 minecraft:cobblestone_wall 0
setblock ~12~44~8 minecraft:stone_brick_stairs 0
fill ~13~15~8 ~13~16~8 minecraft:stone 6
setblock ~13~17~8 minecraft:glowstone
fill ~13~18~8 ~13~23~8 minecraft:stone 6
setblock ~13~24~8 minecraft:stone_brick_stairs 2
setblock ~13~26~8 minecraft:cobblestone_wall 0
setblock ~13~27~8 minecraft:torch 5
setblock ~13~28~8 minecraft:stone_block_slab2 1
setblock ~13~29~8 minecraft:stone_block_slab2 1
setblock ~13~30~8 minecraft:stone_brick_stairs 6
fill ~13~31~8 ~13~32~8 minecraft:stone 6
fill ~13~34~8 ~13~36~8 minecraft:stained_glass_pane 2
setblock ~13~37~8 minecraft:stone_brick_stairs 6
setblock ~13~38~8 minecraft:stone_block_slab 13
setblock ~13~40~8 minecraft:stone_brick_stairs 6
setblock ~13~41~8 minecraft:cobblestone_wall 0
setblock ~13~42~8 minecraft:stone_brick_stairs 3
setblock ~13~43~8 minecraft:glowstone
setblock ~13~44~8 minecraft:stone_brick_stairs 7
setblock ~13~46~8 minecraft:torch 3
setblock ~14~15~8 minecraft:stone_brick_stairs 7
fill ~14~16~8 ~14~21~8 minecraft:stained_glass 10
setblock ~14~22~8 minecraft:stone_brick_stairs 2
setblock ~14~28~8 minecraft:purpur_stairs 4
setblock ~14~31~8 minecraft:stone_brick_stairs 5
setblock ~14~32~8 minecraft:stone_brick_stairs 1
fill ~14~34~8 ~14~37~8 minecraft:stonebrick 0
setblock ~14~38~8 minecraft:stone_block_slab 5
setblock ~14~43~8 minecraft:cobblestone_wall 0
setblock ~14~44~8 minecraft:stone_brick_stairs 1
fill ~15~1~8 ~16~1~8 minecraft:cobblestone
fill ~15~4~8 ~16~4~19 minecraft:stone 6
fill ~15~14~8 ~15~22~8 minecraft:stonebrick 0
setblock ~15~23~8 minecraft:nether_brick_stairs 2
setblock ~15~28~8 minecraft:purpur_stairs 1
setblock ~15~39~8 minecraft:stone_brick_stairs 6
setblock ~15~40~8 minecraft:cobblestone_wall 0
setblock ~15~41~8 minecraft:stone_brick_stairs 2
setblock ~15~42~8 minecraft:stone_brick_stairs 6
fill ~15~43~8 ~16~44~8 minecraft:stonebrick 0
fill ~15~45~8 ~15~48~8 minecraft:stonebrick 0
setblock ~15~50~8 minecraft:stone_brick_stairs 1
fill ~15~51~8 ~15~53~8 minecraft:stained_glass_pane 10
setblock ~15~54~8 minecraft:stone_brick_stairs 5
fill ~15~55~8 ~15~55~9 minecraft:stonebrick 0
setblock ~15~59~8 minecraft:nether_brick
setblock ~15~60~8 minecraft:nether_brick_stairs 3
setblock ~16~2~8 minecraft:purpur_block 0
setblock ~16~3~8 minecraft:stone 6
fill ~16~5~8 ~16~16~8 minecraft:nether_brick
setblock ~16~17~8 minecraft:nether_brick_stairs 2
setblock ~16~23~8 minecraft:stone_block_slab 7
setblock ~16~41~8 minecraft:stone_brick_stairs 5
fill ~16~42~8 ~16~42~9 minecraft:stonebrick 0
setblock ~16~45~8 minecraft:stone_brick_stairs 1
setblock ~16~47~8 minecraft:stone_brick_stairs 5
setblock ~16~48~8 minecraft:stone_brick_stairs 1
setblock ~16~58~8 minecraft:purpur_stairs 6
setblock ~16~59~8 minecraft:purpur_block 0
setblock ~16~60~8 minecraft:purpur_stairs 3
setblock ~17~1~8 minecraft:stone_brick_stairs 7
setblock ~17~2~8 minecraft:cobblestone_wall 0
setblock ~17~3~8 minecraft:stone_brick_stairs 3
setblock ~17~5~8 minecraft:stone_brick_stairs 5
fill ~17~6~8 ~17~6~9 minecraft:stonebrick 0
setblock ~17~7~8 minecraft:stone_brick_stairs 2
setblock ~17~9~8 minecraft:stone_brick_stairs 6
setblock ~17~10~8 minecraft:cobblestone_wall 0
setblock ~17~11~8 minecraft:stone_brick_stairs 2
setblock ~17~13~8 minecraft:stone_brick_stairs 6
fill ~18~0~8 ~18~0~18 minecraft:stonebrick 0
fill ~18~4~8 ~18~4~9 minecraft:stonebrick 0
setblock ~19~0~8 minecraft:stone_block_slab2 1
setblock ~19~4~8 minecraft:stone_brick_stairs 6
setblock ~20~5~8 minecraft:stone_block_slab2 1
setblock ~26~0~8 minecraft:purpur_stairs 2
setblock ~26~5~8 minecraft:purpur_stairs 6
fill ~3~54~9 ~8~54~9 minecraft:purpur_stairs 2
fill ~5~5~9 ~5~5~10 minecraft:stone_block_slab2 1
setblock ~6~0~9 minecraft:stone_block_slab2 1
setblock ~6~1~9 minecraft:stone_brick_stairs 4
setblock ~6~2~9 minecraft:cobblestone_wall 0
setblock ~6~3~9 minecraft:stone_brick_stairs 0
setblock ~6~4~9 minecraft:stone_block_slab 13
fill ~7~0~9 ~7~0~17 minecraft:stonebrick 0
setblock ~7~1~9 minecraft:stone_brick_stairs 2
setblock ~7~3~9 minecraft:stone_brick_stairs 6
setblock ~7~4~9 minecraft:stonebrick 0
setblock ~8~1~9 minecraft:stone_brick_stairs 5
setblock ~8~2~9 minecraft:cobblestone_wall 0
setblock ~8~3~9 minecraft:stone_brick_stairs 1
setblock ~8~5~9 minecraft:stone_brick_stairs 6
setblock ~8~6~9 minecraft:stonebrick 0
setblock ~8~7~9 minecraft:stone_brick_stairs 0
setblock ~8~9~9 minecraft:stone_brick_stairs 4
setblock ~8~10~9 minecraft:cobblestone_wall 0
setblock ~8~11~9 minecraft:stone_brick_stairs 0
setblock ~8~13~9 minecraft:stone_brick_stairs 4
setblock ~9~1~9 minecraft:cobblestone
setblock ~9~2~9 minecraft:purpur_block 0
fill ~9~3~9 ~9~4~9 minecraft:stone 6
setblock ~9~5~9 minecraft:stonebrick 0
fill ~9~7~9 ~9~9~9 minecraft:stonebrick 0
setblock ~9~10~9 minecraft:glowstone
fill ~9~11~9 ~9~14~9 minecraft:stonebrick 0
setblock ~9~15~9 minecraft:cobblestone_wall 0
setblock ~9~16~9 minecraft:stone_block_slab 5
setblock ~9~17~9 minecraft:stone_block_slab 13
fill ~9~18~9 ~9~20~9 minecraft:purpur_block 2
setblock ~9~21~9 minecraft:stone_block_slab 5
setblock ~9~22~9 minecraft:stone_block_slab 15
setblock ~9~28~9 minecraft:stone_block_slab2 1
setblock ~9~42~9 minecraft:stone_block_slab 13
setblock ~9~43~9 minecraft:glowstone
setblock ~9~44~9 minecraft:stone_block_slab 5
fill ~10~4~9 ~10~4~19 minecraft:stone 6
fill ~10~14~9 ~10~18~9 minecraft:stonebrick 0
setblock ~10~19~9 minecraft:stone_brick_stairs 2
setblock ~10~21~9 minecraft:stone_brick_stairs 6
setblock ~10~22~9 minecraft:stone_brick_stairs 2
setblock ~10~24~9 minecraft:stone_brick_stairs 6
setblock ~10~25~9 minecraft:cobblestone_wall 0
setblock ~10~26~9 minecraft:stone_brick_stairs 2
setblock ~10~28~9 minecraft:purpur_stairs 6
setblock ~10~32~9 minecraft:stone_brick_stairs 4
setblock ~10~33~9 minecraft:cobblestone_wall 0
setblock ~10~34~9 minecraft:stone_brick_stairs 0
setblock ~10~36~9 minecraft:stone_brick_stairs 4
setblock ~10~37~9 minecraft:cobblestone_wall 0
setblock ~10~38~9 minecraft:stone_brick_stairs 0
setblock ~10~40~9 minecraft:stone_brick_stairs 4
setblock ~10~41~9 minecraft:stonebrick 0
setblock ~10~45~9 minecraft:stonebrick 0
setblock ~10~46~9 minecraft:stone_brick_stairs 0
setblock ~10~50~9 minecraft:stone_brick_stairs 4
setblock ~10~51~9 minecraft:flower_pot 0
setblock ~10~54~9 minecraft:stone_brick_stairs 6
setblock ~10~57~9 minecraft:purpur_stairs 4
setblock ~10~58~9 minecraft:purpur_stairs 3
fill ~11~19~9 ~11~24~9 minecraft:stonebrick 0
setblock ~11~25~9 minecraft:stone_brick_stairs 2
setblock ~11~28~9 minecraft:purpur_stairs 2
setblock ~11~30~9 minecraft:stone_brick_stairs 4
setblock ~11~31~9 minecraft:cobblestone_wall 0
fill ~11~32~9 ~15~32~9 minecraft:stonebrick 0
fill ~11~33~9 ~11~40~9 minecraft:stonebrick 0
setblock ~11~46~9 minecraft:stone_brick_stairs 7
fill ~11~47~9 ~11~48~9 minecraft:stonebrick 0
fill ~11~50~9 ~11~50~17 minecraft:stonebrick 0
fill ~11~51~9 ~11~54~9 minecraft:stonebrick 0
fill ~11~57~9 ~11~58~10 minecraft:nether_brick
fill ~11~59~9 ~11~59~11 minecraft:nether_brick_stairs 0
fill ~12~23~9 ~15~23~9 minecraft:stonebrick 0
setblock ~12~24~9 minecraft:stone_brick_stairs 2
setblock ~12~25~9 minecraft:stone_brick_stairs 6
setblock ~12~26~9 minecraft:stone_brick_stairs 2
setblock ~12~27~9 minecraft:stone_brick_stairs 6
fill ~12~28~9 ~12~31~9 minecraft:stonebrick 0
setblock ~12~37~9 minecraft:stone_brick_stairs 5
fill ~12~38~9 ~15~40~9 minecraft:stonebrick 0
setblock ~13~24~9 minecraft:stonebrick 0
fill ~13~25~9 ~13~29~9 minecraft:stone 6
fill ~13~30~9 ~14~31~9 minecraft:stonebrick 0
setblock ~13~37~9 minecraft:torch 3
fill ~13~64~9 ~13~64~11 minecraft:purpur_block 0
setblock ~13~65~9 minecraft:purpur_stairs 3
setblock ~14~24~9 minecraft:stone_brick_stairs 2
setblock ~14~25~9 minecraft:stone_brick_stairs 6
setblock ~14~26~9 minecraft:stone_brick_stairs 2
setblock ~14~27~9 minecraft:stone_brick_stairs 6
fill ~14~28~9 ~14~29~9 minecraft:stonebrick 0
setblock ~14~37~9 minecraft:stone_brick_stairs 4
fill ~15~19~9 ~15~22~9 minecraft:stonebrick 0
fill ~15~24~9 ~15~24~10 minecraft:stonebrick 0
setblock ~15~25~9 minecraft:stone_brick_stairs 2
setblock ~15~28~9 minecraft:purpur_stairs 2
setblock ~15~30~9 minecraft:stone_brick_stairs 5
setblock ~15~31~9 minecraft:cobblestone_wall 0
fill ~15~33~9 ~15~37~9 minecraft:stonebrick 0
setblock ~15~46~9 minecraft:stone_brick_stairs 7
fill ~15~47~9 ~15~48~9 minecraft:stonebrick 0
fill ~15~50~9 ~15~50~17 minecraft:stonebrick 0
fill ~15~51~9 ~15~54~9 minecraft:stonebrick 0
fill ~15~57~9 ~15~58~10 minecraft:nether_brick
fill ~15~59~9 ~15~59~10 minecraft:nether_brick_stairs 1
fill ~16~14~9 ~17~14~9 minecraft:stonebrick 0
fill ~16~15~9 ~16~18~9 minecraft:stonebrick 0
setblock ~16~19~9 minecraft:stone_brick_stairs 2
setblock ~16~21~9 minecraft:stone_brick_stairs 6
setblock ~16~22~9 minecraft:stone_brick_stairs 2
setblock ~16~24~9 minecraft:stone_brick_stairs 6
setblock ~16~25~9 minecraft:cobblestone_wall 0
setblock ~16~26~9 minecraft:stone_brick_stairs 2
setblock ~16~28~9 minecraft:purpur_stairs 6
setblock ~16~32~9 minecraft:stone_brick_stairs 5
setblock ~16~33~9 minecraft:cobblestone_wall 0
setblock ~16~34~9 minecraft:stone_brick_stairs 1
setblock ~16~36~9 minecraft:stone_brick_stairs 5
setblock ~16~37~9 minecraft:cobblestone_wall 0
setblock ~16~38~9 minecraft:stone_brick_stairs 1
setblock ~16~40~9 minecraft:stone_brick_stairs 5
setblock ~16~41~9 minecraft:stonebrick 0
fill ~16~43~9 ~16~45~9 minecraft:stonebrick 0
setblock ~16~46~9 minecraft:stone_brick_stairs 1
setblock ~16~50~9 minecraft:stone_brick_stairs 5
setblock ~16~51~9 minecraft:flower_pot 0
setblock ~16~54~9 minecraft:stone_brick_stairs 6
setblock ~16~57~9 minecraft:purpur_stairs 5
setblock ~16~58~9 minecraft:purpur_stairs 3
setblock ~17~1~9 minecraft:cobblestone
setblock ~17~2~9 minecraft:purpur_block 0
fill ~17~3~9 ~17~4~9 minecraft:stone 6
setblock ~17~5~9 minecraft:stonebrick 0
fill ~17~7~9 ~17~9~9 minecraft:stonebrick 0
setblock ~17~10~9 minecraft:glowstone
fill ~17~11~9 ~17~13~9 minecraft:stonebrick 0
setblock ~17~15~9 minecraft:cobblestone_wall 0
setblock ~17~16~9 minecraft:stone_block_slab 5
setblock ~17~17~9 minecraft:stone_block_slab 13
fill ~17~18~9 ~17~20~9 minecraft:purpur_block 2
setblock ~17~21~9 minecraft:stone_block_slab 5
setblock ~17~22~9 minecraft:stone_block_slab 15
setblock ~17~28~9 minecraft:stone_block_slab2 1
setblock ~17~42~9 minecraft:stone_block_slab 13
setblock ~17~43~9 minecraft:glowstone
setblock ~17~44~9 minecraft:stone_block_slab 5
fill ~17~54~9 ~23~54~9 minecraft:purpur_stairs 2
setblock ~18~1~9 minecraft:stone_brick_stairs 4
setblock ~18~2~9 minecraft:cobblestone_wall 0
setblock ~18~3~9 minecraft:stone_brick_stairs 0
setblock ~18~5~9 minecraft:stone_brick_stairs 6
setblock ~18~6~9 minecraft:stonebrick 0
setblock ~18~7~9 minecraft:stone_brick_stairs 1
setblock ~18~9~9 minecraft:stone_brick_stairs 5
setblock ~18~10~9 minecraft:cobblestone_wall 0
setblock ~18~11~9 minecraft:stone_brick_stairs 1
setblock ~18~13~9 minecraft:stone_brick_stairs 5
fill ~19~0~9 ~19~0~17 minecraft:stonebrick 0
setblock ~19~1~9 minecraft:stone_brick_stairs 2
setblock ~19~3~9 minecraft:stone_brick_stairs 6
setblock ~19~4~9 minecraft:stonebrick 0
setblock ~20~0~9 minecraft:stone_block_slab2 1
setblock ~20~1~9 minecraft:stone_brick_stairs 5
setblock ~20~2~9 minecraft:cobblestone_wall 0
setblock ~20~3~9 minecraft:stone_brick_stairs 1
setblock ~20~4~9 minecraft:stone_block_slab 13
fill ~21~5~9 ~21~5~10 minecraft:stone_block_slab2 1
fill ~25~0~9 ~25~0~10 minecraft:purpur_stairs 0
setblock ~25~5~9 minecraft:purpur_stairs 4
setblock ~26~0~9 minecraft:purpur_stairs 4
fill ~26~1~9 ~26~5~9 minecraft:log 1
setblock ~26~6~9 minecraft:fire 0
setblock ~27~0~9 minecraft:purpur_stairs 1
setblock ~27~5~9 minecraft:purpur_stairs 5
setblock ~3~54~10 minecraft:purpur_stairs 7
setblock ~3~55~10 minecraft:purpur_block 0
setblock ~3~56~10 minecraft:purpur_stairs 2
fill ~4~54~10 ~5~54~10 minecraft:nether_brick_stairs 7
fill ~4~55~10 ~9~55~10 minecraft:nether_brick
fill ~4~56~10 ~9~56~10 minecraft:nether_brick_stairs 2
setblock ~6~0~10 minecraft:stone_brick_stairs 4
setblock ~6~1~10 minecraft:stone_brick_stairs 0
setblock ~6~3~10 minecraft:stone_brick_stairs 4
fill ~6~4~10 ~6~4~11 minecraft:stonebrick 0
setblock ~6~47~10 minecraft:wooden_button 2
fill ~6~49~10 ~9~49~10 minecraft:purpur_stairs 6
fill ~6~50~10 ~6~54~10 minecraft:log 1
setblock ~7~2~10 minecraft:glowstone
fill ~7~3~10 ~8~4~10 minecraft:stone 6
setblock ~7~5~10 minecraft:stone_brick_stairs 2
setblock ~7~7~10 minecraft:stone_brick_stairs 6
setblock ~7~8~10 minecraft:cobblestone_wall 0
setblock ~7~9~10 minecraft:stone_brick_stairs 2
setblock ~7~11~10 minecraft:stone_brick_stairs 6
setblock ~7~12~10 minecraft:cobblestone_wall 0
setblock ~7~13~10 minecraft:stone_brick_stairs 2
setblock ~7~50~10 minecraft:stone_brick_stairs 6
setblock ~7~51~10 minecraft:flower_pot 0
setblock ~7~54~10 minecraft:stone_brick_stairs 5
fill ~8~1~10 ~8~1~11 minecraft:cobblestone
setblock ~8~2~10 minecraft:purpur_block 0
fill ~8~5~10 ~8~16~10 minecraft:nether_brick
setblock ~8~17~10 minecraft:nether_brick_stairs 0
setblock ~8~23~10 minecraft:stone_block_slab 7
setblock ~8~41~10 minecraft:stone_brick_stairs 6
fill ~8~42~10 ~9~44~10 minecraft:stonebrick 0
setblock ~8~45~10 minecraft:stone_brick_stairs 2
setblock ~8~47~10 minecraft:stone_brick_stairs 6
setblock ~8~48~10 minecraft:stone_brick_stairs 2
fill ~9~4~10 ~9~4~17 minecraft:stone 6
fill ~9~14~10 ~9~18~10 minecraft:stonebrick 0
setblock ~9~19~10 minecraft:stone_brick_stairs 0
setblock ~9~21~10 minecraft:stone_brick_stairs 4
setblock ~9~22~10 minecraft:stone_brick_stairs 0
setblock ~9~24~10 minecraft:stone_brick_stairs 4
setblock ~9~25~10 minecraft:cobblestone_wall 0
setblock ~9~26~10 minecraft:stone_brick_stairs 0
setblock ~9~28~10 minecraft:purpur_stairs 4
setblock ~9~32~10 minecraft:stone_brick_stairs 6
setblock ~9~33~10 minecraft:cobblestone_wall 0
setblock ~9~34~10 minecraft:stone_brick_stairs 2
setblock ~9~36~10 minecraft:stone_brick_stairs 6
setblock ~9~37~10 minecraft:cobblestone_wall 0
setblock ~9~38~10 minecraft:stone_brick_stairs 2
setblock ~9~40~10 minecraft:stone_brick_stairs 6
setblock ~9~41~10 minecraft:stonebrick 0
setblock ~9~45~10 minecraft:stonebrick 0
setblock ~9~46~10 minecraft:stone_brick_stairs 2
setblock ~9~50~10 minecraft:stone_brick_stairs 6
setblock ~9~54~10 minecraft:stone_brick_stairs 4
setblock ~10~20~10 minecraft:stained_glass 10
setblock ~10~21~10 minecraft:stone_block_slab 13
fill ~10~22~10 ~10~55~10 minecraft:purpur_block 2
fill ~11~23~10 ~11~30~10 minecraft:stonebrick 0
setblock ~11~31~10 minecraft:monster_egg 2
setblock ~11~32~10 minecraft:stonebrick 0
setblock ~11~55~10 minecraft:stone_brick_stairs 7
setblock ~15~23~10 minecraft:stonebrick 0
fill ~15~25~10 ~15~32~10 minecraft:stonebrick 0
setblock ~15~55~10 minecraft:stone_brick_stairs 7
setblock ~16~20~10 minecraft:stained_glass 10
setblock ~16~21~10 minecraft:stone_block_slab 13
fill ~16~22~10 ~16~55~10 minecraft:purpur_block 2
fill ~16~56~10 ~22~56~10 minecraft:nether_brick_stairs 2
fill ~17~4~10 ~19~4~16 minecraft:stone 6
fill ~17~14~10 ~17~18~10 minecraft:stonebrick 0
setblock ~17~19~10 minecraft:stone_brick_stairs 1
setblock ~17~21~10 minecraft:stone_brick_stairs 5
setblock ~17~22~10 minecraft:stone_brick_stairs 1
setblock ~17~24~10 minecraft:stone_brick_stairs 5
setblock ~17~25~10 minecraft:cobblestone_wall 0
setblock ~17~26~10 minecraft:stone_brick_stairs 1
setblock ~17~28~10 minecraft:purpur_stairs 5
setblock ~17~32~10 minecraft:stone_brick_stairs 6
setblock ~17~33~10 minecraft:cobblestone_wall 0
setblock ~17~34~10 minecraft:stone_brick_stairs 2
setblock ~17~36~10 minecraft:stone_brick_stairs 6
setblock ~17~37~10 minecraft:cobblestone_wall 0
setblock ~17~38~10 minecraft:stone_brick_stairs 2
setblock ~17~40~10 minecraft:stone_brick_stairs 6
fill ~17~41~10 ~17~45~10 minecraft:stonebrick 0
setblock ~17~46~10 minecraft:stone_brick_stairs 2
fill ~17~49~10 ~20~49~10 minecraft:purpur_stairs 6
setblock ~17~50~10 minecraft:stone_brick_stairs 6
setblock ~17~51~10 minecraft:flower_pot 0
setblock ~17~54~10 minecraft:stone_brick_stairs 5
fill ~17~55~10 ~22~55~10 minecraft:nether_brick
fill ~18~1~10 ~18~1~11 minecraft:cobblestone
setblock ~18~2~10 minecraft:purpur_block 0
fill ~18~3~10 ~19~3~10 minecraft:stone 6
fill ~18~5~10 ~18~16~10 minecraft:nether_brick
setblock ~18~17~10 minecraft:nether_brick_stairs 1
setblock ~18~23~10 minecraft:stone_block_slab 7
setblock ~18~41~10 minecraft:stone_brick_stairs 6
fill ~18~42~10 ~18~44~10 minecraft:stonebrick 0
setblock ~18~45~10 minecraft:stone_brick_stairs 2
setblock ~18~47~10 minecraft:stone_brick_stairs 6
setblock ~18~48~10 minecraft:stone_brick_stairs 2
setblock ~19~1~10 minecraft:stone 6
setblock ~19~2~10 minecraft:glowstone
setblock ~19~5~10 minecraft:stone_brick_stairs 2
setblock ~19~7~10 minecraft:stone_brick_stairs 6
setblock ~19~8~10 minecraft:cobblestone_wall 0
setblock ~19~9~10 minecraft:stone_brick_stairs 2
setblock ~19~11~10 minecraft:stone_brick_stairs 6
setblock ~19~12~10 minecraft:cobblestone_wall 0
setblock ~19~13~10 minecraft:stone_brick_stairs 2
setblock ~19~50~10 minecraft:stone_brick_stairs 6
setblock ~19~54~10 minecraft:stone_brick_stairs 4
setblock ~20~0~10 minecraft:stone_brick_stairs 5
setblock ~20~1~10 minecraft:stone_brick_stairs 1
setblock ~20~3~10 minecraft:stone_brick_stairs 5
fill ~20~4~10 ~20~4~11 minecraft:stonebrick 0
setblock ~20~47~10 minecraft:wooden_button 2
fill ~20~50~10 ~20~54~10 minecraft:log 1
fill ~21~54~10 ~22~54~10 minecraft:nether_brick_stairs 7
setblock ~23~54~10 minecraft:purpur_stairs 7
setblock ~23~55~10 minecraft:purpur_block 0
setblock ~23~56~10 minecraft:purpur_stairs 2
setblock ~25~1~10 minecraft:purpur_stairs 4
setblock ~25~2~10 minecraft:purpur_stairs 1
setblock ~25~56~10 minecraft:trapdoor 3
setblock ~26~0~10 minecraft:purpur_block 2
setblock ~26~1~10 minecraft:purpur_stairs 1
setblock ~26~5~10 minecraft:purpur_stairs 7
setblock ~27~0~10 minecraft:purpur_stairs 5
setblock ~27~51~10 minecraft:trapdoor 3
setblock ~27~56~10 minecraft:cobblestone_wall 0
setblock ~31~56~10 minecraft:trapdoor 3
setblock ~3~56~11 minecraft:purpur_stairs 7
fill ~3~57~11 ~3~58~11 minecraft:purpur_block 0
setblock ~3~59~11 minecraft:purpur_stairs 2
fill ~4~5~11 ~4~5~15 minecraft:stone_block_slab2 1
setblock ~4~50~11 minecraft:cobblestone_wall 0
setblock ~4~51~11 minecraft:torch 5
setblock ~4~56~11 minecraft:nether_brick_stairs 7
fill ~4~57~11 ~10~58~11 minecraft:nether_brick
fill ~4~59~11 ~10~59~11 minecraft:nether_brick_stairs 2
setblock ~5~0~11 minecraft:stone_block_slab2 1
setblock ~5~4~11 minecraft:stone_block_slab 13
setblock ~5~9~11 minecraft:stone_block_slab2 1
fill ~5~10~11 ~5~11~11 minecraft:cobblestone_wall 0
fill ~5~12~11 ~6~12~11 minecraft:purpur_stairs 2
setblock ~5~47~11 minecraft:wooden_button 4
setblock ~5~49~11 minecraft:purpur_stairs 4
fill ~5~50~11 ~7~50~15 minecraft:stonebrick 0
fill ~5~51~11 ~5~56~11 minecraft:stonebrick 0
fill ~6~0~11 ~6~0~15 minecraft:stonebrick 0
setblock ~6~1~11 minecraft:stone_brick_stairs 4
setblock ~6~2~11 minecraft:cobblestone_wall 0
setblock ~6~3~11 minecraft:stone_brick_stairs 0
setblock ~6~8~11 minecraft:stone_brick_stairs 6
setblock ~6~46~11 minecraft:purpur_stairs 4
fill ~6~47~11 ~6~49~11 minecraft:purpur_block 0
setblock ~6~51~11 minecraft:stone_brick_stairs 7
fill ~6~56~11 ~10~56~11 minecraft:stonebrick 0
setblock ~7~1~11 minecraft:stone 6
setblock ~7~2~11 minecraft:purpur_block 0
fill ~7~3~11 ~7~4~11 minecraft:stone 6
fill ~7~5~11 ~7~13~11 minecraft:stonebrick 0
setblock ~7~35~11 minecraft:stone_block_slab 15
setblock ~7~36~11 minecraft:cobblestone_wall 0
fill ~7~37~11 ~8~37~11 minecraft:nether_brick_stairs 2
setblock ~7~44~11 minecraft:purpur_stairs 4
setblock ~7~45~11 minecraft:purpur_block 0
setblock ~7~46~11 minecraft:purpur_stairs 1
fill ~7~49~11 ~9~49~11 minecraft:stonebrick 0
fill ~7~51~11 ~7~55~11 minecraft:stonebrick 0
fill ~8~4~11 ~8~4~16 minecraft:stone 6
fill ~8~14~11 ~8~14~15 minecraft:stonebrick 0
fill ~8~15~11 ~8~22~11 minecraft:stonebrick 0
setblock ~8~23~11 minecraft:nether_brick_stairs 0
setblock ~8~28~11 minecraft:purpur_stairs 2
setblock ~8~39~11 minecraft:stone_brick_stairs 4
setblock ~8~40~11 minecraft:cobblestone_wall 0
setblock ~8~41~11 minecraft:stone_brick_stairs 0
setblock ~8~42~11 minecraft:stone_brick_stairs 4
fill ~8~43~11 ~8~48~11 minecraft:stonebrick 0
setblock ~8~50~11 minecraft:stone_brick_stairs 2
fill ~8~51~11 ~8~53~11 minecraft:stained_glass_pane 10
setblock ~8~54~11 minecraft:stone_brick_stairs 6
fill ~8~55~11 ~9~55~11 minecraft:stonebrick 0
fill ~9~19~11 ~9~24~11 minecraft:stonebrick 0
setblock ~9~25~11 minecraft:stone_brick_stairs 0
setblock ~9~28~11 minecraft:purpur_stairs 0
setblock ~9~30~11 minecraft:stone_brick_stairs 6
setblock ~9~31~11 minecraft:cobblestone_wall 0
fill ~9~32~11 ~10~32~11 minecraft:stonebrick 0
fill ~9~33~11 ~9~40~11 minecraft:stonebrick 0
setblock ~9~46~11 minecraft:stone_brick_stairs 5
fill ~9~47~11 ~9~48~11 minecraft:stonebrick 0
fill ~9~50~11 ~10~50~15 minecraft:stonebrick 0
fill ~9~51~11 ~9~54~11 minecraft:stonebrick 0
fill ~10~23~11 ~10~31~11 minecraft:stonebrick 0
setblock ~10~55~11 minecraft:stone_brick_stairs 5
fill ~15~59~11 ~22~59~11 minecraft:nether_brick_stairs 2
fill ~16~23~11 ~17~24~11 minecraft:stonebrick 0
fill ~16~25~11 ~16~30~11 minecraft:stonebrick 0
setblock ~16~31~11 minecraft:monster_egg 2
fill ~16~32~11 ~17~32~11 minecraft:stonebrick 0
fill ~16~50~11 ~17~50~15 minecraft:stonebrick 0
setblock ~16~55~11 minecraft:stone_brick_stairs 4
fill ~16~56~11 ~21~56~11 minecraft:stonebrick 0
fill ~16~57~11 ~22~58~11 minecraft:nether_brick
fill ~17~19~11 ~18~22~11 minecraft:stonebrick 0
setblock ~17~25~11 minecraft:stone_brick_stairs 1
setblock ~17~28~11 minecraft:purpur_stairs 1
setblock ~17~30~11 minecraft:stone_brick_stairs 6
setblock ~17~31~11 minecraft:cobblestone_wall 0
fill ~17~33~11 ~17~40~11 minecraft:stonebrick 0
setblock ~17~46~11 minecraft:stone_brick_stairs 4
fill ~17~47~11 ~18~49~11 minecraft:stonebrick 0
fill ~17~51~11 ~17~55~11 minecraft:stonebrick 0
fill ~18~14~11 ~18~14~15 minecraft:stonebrick 0
fill ~18~15~11 ~18~18~11 minecraft:stonebrick 0
setblock ~18~23~11 minecraft:nether_brick_stairs 1
setblock ~18~28~11 minecraft:purpur_stairs 2
fill ~18~37~11 ~19~37~11 minecraft:nether_brick_stairs 2
setblock ~18~39~11 minecraft:stone_brick_stairs 5
setblock ~18~40~11 minecraft:cobblestone_wall 0
setblock ~18~41~11 minecraft:stone_brick_stairs 1
setblock ~18~42~11 minecraft:stone_brick_stairs 5
fill ~18~43~11 ~18~46~11 minecraft:stonebrick 0
setblock ~18~50~11 minecraft:stone_brick_stairs 2
fill ~18~51~11 ~18~53~11 minecraft:stained_glass_pane 10
setblock ~18~54~11 minecraft:stone_brick_stairs 6
fill ~18~55~11 ~19~55~11 minecraft:stonebrick 0
setblock ~19~1~11 minecraft:glowstone
setblock ~19~2~11 minecraft:purpur_block 0
setblock ~19~3~11 minecraft:stone 6
fill ~19~5~11 ~19~13~11 minecraft:stonebrick 0
setblock ~19~35~11 minecraft:stone_block_slab 15
setblock ~19~36~11 minecraft:cobblestone_wall 0
setblock ~19~44~11 minecraft:purpur_stairs 5
setblock ~19~45~11 minecraft:purpur_block 0
setblock ~19~46~11 minecraft:purpur_stairs 0
fill ~19~49~11 ~19~50~15 minecraft:stonebrick 0
fill ~19~51~11 ~19~54~11 minecraft:stonebrick 0
fill ~20~0~11 ~20~0~15 minecraft:stonebrick 0
setblock ~20~1~11 minecraft:stone_brick_stairs 5
setblock ~20~2~11 minecraft:cobblestone_wall 0
setblock ~20~3~11 minecraft:stone_brick_stairs 1
setblock ~20~5~11 minecraft:stone_brick_stairs 1
setblock ~20~6~11 minecraft:stone_brick_stairs 5
setblock ~20~7~11 minecraft:fire 0
setblock ~20~8~11 minecraft:stone_brick_stairs 6
fill ~20~12~11 ~21~12~11 minecraft:purpur_stairs 2
setblock ~20~46~11 minecraft:purpur_stairs 5
fill ~20~47~11 ~20~49~11 minecraft:purpur_block 0
fill ~20~50~11 ~21~50~15 minecraft:stonebrick 0
setblock ~20~51~11 minecraft:stone_brick_stairs 7
setblock ~21~0~11 minecraft:stone_block_slab2 1
setblock ~21~4~11 minecraft:stone_block_slab 13
setblock ~21~9~11 minecraft:stone_block_slab2 1
fill ~21~10~11 ~21~11~11 minecraft:cobblestone_wall 0
setblock ~21~47~11 minecraft:wooden_button 5
setblock ~21~49~11 minecraft:purpur_stairs 5
fill ~21~51~11 ~21~55~11 minecraft:stonebrick 0
setblock ~22~4~11 minecraft:purpur_stairs 4
setblock ~22~5~11 minecraft:stone_block_slab2 1
setblock ~22~56~11 minecraft:nether_brick_stairs 7
setblock ~23~3~11 minecraft:purpur_stairs 4
setblock ~23~4~11 minecraft:purpur_stairs 1
setblock ~23~56~11 minecraft:purpur_stairs 7
fill ~23~57~11 ~23~58~11 minecraft:purpur_block 0
setblock ~23~59~11 minecraft:purpur_stairs 2
setblock ~24~2~11 minecraft:purpur_stairs 4
setblock ~24~3~11 minecraft:purpur_stairs 1
fill ~24~50~11 ~24~52~11 minecraft:quartz_block 0
fill ~25~0~11 ~25~0~15 minecraft:stone_stairs 4
fill ~25~1~11 ~25~1~15 minecraft:stone_stairs 1
setblock ~25~49~11 minecraft:quartz_block 0
setblock ~25~53~11 minecraft:quartz_block 0
setblock ~25~56~11 minecraft:log 1
fill ~26~0~11 ~26~0~15 minecraft:stone_stairs 1
fill ~26~48~11 ~28~48~11 minecraft:quartz_block 0
fill ~26~54~11 ~28~54~11 minecraft:quartz_block 0
fill ~27~51~11 ~27~51~15 minecraft:log 1
setblock ~27~56~11 minecraft:cobblestone_wall 0
setblock ~27~57~11 minecraft:cobblestone_wall 0
fill ~28~26~11 ~30~26~11 minecraft:stone_block_slab2 1
fill ~29~27~11 ~29~29~11 minecraft:fence 5
setblock ~29~49~11 minecraft:quartz_block 0
setblock ~29~53~11 minecraft:quartz_block 0
fill ~30~50~11 ~30~52~11 minecraft:quartz_block 0
setblock ~31~56~11 minecraft:log 1
setblock ~3~59~12 minecraft:purpur_stairs 7
fill ~3~60~12 ~3~62~12 minecraft:purpur_block 0
setblock ~3~63~12 minecraft:purpur_stairs 2
fill ~4~49~12 ~5~49~12 minecraft:purpur_stairs 6
fill ~4~50~12 ~4~59~12 minecraft:stonebrick 0
fill ~4~60~12 ~11~62~12 minecraft:nether_brick
fill ~4~63~12 ~11~63~12 minecraft:nether_brick_stairs 2
setblock ~5~0~12 minecraft:purpur_stairs 0
setblock ~5~4~12 minecraft:stone_brick_stairs 4
setblock ~5~12~12 minecraft:stone_block_slab2 1
setblock ~5~13~12 minecraft:stone_block_slab2 1
setblock ~5~47~12 minecraft:purpur_stairs 6
setblock ~5~48~12 minecraft:purpur_stairs 2
setblock ~6~1~12 minecraft:cobblestone_wall 0
setblock ~6~2~12 minecraft:stone_brick_stairs 0
setblock ~6~3~12 minecraft:stone_brick_stairs 4
fill ~6~4~12 ~7~4~14 minecraft:stone 6
setblock ~6~5~12 minecraft:stone_brick_stairs 0
setblock ~6~6~12 minecraft:stone_brick_stairs 4
fill ~6~7~12 ~6~12~12 minecraft:stonebrick 0
setblock ~6~13~12 minecraft:stone_block_slab 5
fill ~6~48~12 ~7~48~14 minecraft:stonebrick 0
fill ~7~1~12 ~7~1~14 minecraft:cobblestone
setblock ~7~12~12 minecraft:stone_brick_stairs 7
fill ~7~13~12 ~7~15~12 minecraft:stonebrick 0
setblock ~7~16~12 minecraft:stone_brick_stairs 6
setblock ~7~17~12 minecraft:cobblestone_wall 0
setblock ~7~18~12 minecraft:stone_brick_stairs 2
setblock ~7~19~12 minecraft:stone_brick_stairs 6
setblock ~7~20~12 minecraft:stone_brick_stairs 2
setblock ~7~23~12 minecraft:stone_block_slab 15
setblock ~7~33~12 minecraft:nether_brick_stairs 6
setblock ~7~37~12 minecraft:stone_block_slab 15
setblock ~7~38~12 minecraft:stone_block_slab 7
fill ~7~41~12 ~8~42~12 minecraft:stonebrick 0
fill ~7~43~12 ~7~47~12 minecraft:stonebrick 0
fill ~7~49~12 ~7~49~15 minecraft:stonebrick 0
setblock ~8~15~12 minecraft:stone_brick_stairs 5
fill ~8~16~12 ~8~21~12 minecraft:stained_glass 10
setblock ~8~22~12 minecraft:stone_brick_stairs 0
setblock ~8~28~12 minecraft:purpur_stairs 7
setblock ~8~31~12 minecraft:stone_brick_stairs 6
setblock ~8~32~12 minecraft:stone_brick_stairs 2
fill ~8~33~12 ~8~33~14 minecraft:stonebrick 0
fill ~8~34~12 ~8~37~12 minecraft:stonebrick 0
setblock ~8~38~12 minecraft:stone_block_slab 5
setblock ~8~43~12 minecraft:cobblestone_wall 0
setblock ~8~44~12 minecraft:stone_brick_stairs 2
fill ~8~50~12 ~8~50~14 minecraft:stonebrick 0
fill ~9~23~12 ~9~23~15 minecraft:stonebrick 0
setblock ~9~24~12 minecraft:stone_brick_stairs 0
setblock ~9~25~12 minecraft:stone_brick_stairs 4
setblock ~9~26~12 minecraft:stone_brick_stairs 0
setblock ~9~27~12 minecraft:stone_brick_stairs 4
fill ~9~28~12 ~9~32~12 minecraft:stonebrick 0
setblock ~9~37~12 minecraft:stone_brick_stairs 7
fill ~9~38~12 ~9~40~15 minecraft:stonebrick 0
setblock ~13~64~12 minecraft:purpur_stairs 3
fill ~15~60~12 ~22~62~12 minecraft:nether_brick
fill ~15~63~12 ~22~63~12 minecraft:nether_brick_stairs 2
fill ~17~23~12 ~17~23~15 minecraft:stonebrick 0
setblock ~17~24~12 minecraft:stone_brick_stairs 1
setblock ~17~25~12 minecraft:stone_brick_stairs 5
setblock ~17~26~12 minecraft:stone_brick_stairs 1
setblock ~17~27~12 minecraft:stone_brick_stairs 5
fill ~17~28~12 ~17~32~12 minecraft:stonebrick 0
setblock ~17~37~12 minecraft:stone_brick_stairs 7
fill ~17~38~12 ~17~40~15 minecraft:stonebrick 0
setblock ~18~15~12 minecraft:stone_brick_stairs 4
fill ~18~16~12 ~18~21~12 minecraft:stained_glass 10
setblock ~18~22~12 minecraft:stone_brick_stairs 1
setblock ~18~28~12 minecraft:purpur_stairs 7
setblock ~18~31~12 minecraft:stone_brick_stairs 6
setblock ~18~32~12 minecraft:stone_brick_stairs 2
fill ~18~33~12 ~18~33~14 minecraft:stonebrick 0
fill ~18~34~12 ~18~37~12 minecraft:stonebrick 0
setblock ~18~38~12 minecraft:stone_block_slab 5
fill ~18~41~12 ~19~41~12 minecraft:stonebrick 0
setblock ~18~42~12 minecraft:stone_brick_stairs 6
setblock ~18~43~12 minecraft:cobblestone_wall 0
setblock ~18~44~12 minecraft:stone_brick_stairs 2
fill ~18~50~12 ~18~50~14 minecraft:stonebrick 0
fill ~19~1~12 ~19~1~14 minecraft:cobblestone
setblock ~19~12~12 minecraft:stone_brick_stairs 7
fill ~19~13~12 ~19~15~12 minecraft:stonebrick 0
setblock ~19~16~12 minecraft:stone_brick_stairs 6
setblock ~19~17~12 minecraft:cobblestone_wall 0
setblock ~19~18~12 minecraft:stone_brick_stairs 2
setblock ~19~19~12 minecraft:stone_brick_stairs 6
setblock ~19~20~12 minecraft:stone_brick_stairs 2
setblock ~19~23~12 minecraft:stone_block_slab 15
setblock ~19~33~12 minecraft:nether_brick_stairs 6
setblock ~19~37~12 minecraft:stone_block_slab 15
setblock ~19~38~12 minecraft:stone_block_slab 7
fill ~19~42~12 ~19~48~12 minecraft:stonebrick 0
setblock ~20~1~12 minecraft:cobblestone_wall 0
setblock ~20~2~12 minecraft:stone_brick_stairs 1
setblock ~20~3~12 minecraft:stone_brick_stairs 5
fill ~20~4~12 ~20~4~14 minecraft:stone 6
setblock ~20~8~12 minecraft:stone_brick_stairs 7
fill ~20~9~12 ~20~12~12 minecraft:stonebrick 0
setblock ~20~13~12 minecraft:stone_block_slab 5
fill ~20~48~12 ~20~49~14 minecraft:stonebrick 0
setblock ~21~0~12 minecraft:purpur_stairs 1
setblock ~21~4~12 minecraft:stone_brick_stairs 5
setblock ~21~12~12 minecraft:stone_block_slab2 1
setblock ~21~13~12 minecraft:stone_block_slab2 1
setblock ~21~47~12 minecraft:purpur_stairs 6
setblock ~21~48~12 minecraft:purpur_stairs 2
fill ~21~49~12 ~22~49~12 minecraft:purpur_stairs 6
setblock ~21~51~12 minecraft:cobblestone_wall 0
setblock ~21~56~12 minecraft:barrier
fill ~22~3~12 ~22~3~14 minecraft:stone_stairs 4
fill ~22~4~12 ~22~4~14 minecraft:stone_stairs 1
setblock ~22~50~12 minecraft:stonebrick 0
fill ~22~56~12 ~22~59~12 minecraft:stonebrick 0
fill ~23~2~12 ~23~2~14 minecraft:stone_stairs 4
fill ~23~3~12 ~23~3~14 minecraft:stone_stairs 1
fill ~23~56~12 ~32~56~12 minecraft:log 1
setblock ~23~59~12 minecraft:purpur_stairs 7
fill ~23~60~12 ~23~62~12 minecraft:purpur_block 0
setblock ~23~63~12 minecraft:purpur_stairs 2
fill ~24~1~12 ~24~1~14 minecraft:stone_stairs 4
fill ~24~2~12 ~24~2~14 minecraft:stone_stairs 1
fill ~24~51~12 ~26~51~12 minecraft:fence 5
fill ~25~49~12 ~29~50~12 minecraft:fence 5
fill ~25~52~12 ~29~53~12 minecraft:fence 5
setblock ~25~57~12 minecraft:log 1
setblock ~25~58~12 minecraft:trapdoor 2
fill ~27~26~12 ~27~26~14 minecraft:stone_block_slab2 1
setblock ~27~48~12 minecraft:fence 5
setblock ~27~54~12 minecraft:fence 5
fill ~27~57~12 ~27~57~14 minecraft:cobblestone_wall 0
fill ~28~26~12 ~30~26~14 minecraft:planks 5
setblock ~28~27~12 minecraft:glowstone
fill ~28~51~12 ~30~51~12 minecraft:fence 5
setblock ~29~27~12 minecraft:chest 2
fill ~29~29~12 ~29~32~12 minecraft:fence 5
setblock ~30~27~12 minecraft:emerald_ore
fill ~31~26~12 ~31~26~14 minecraft:stone_block_slab2 1
setblock ~31~53~12 minecraft:fence 5
fill ~31~54~12 ~31~55~12 minecraft:log 1
setblock ~31~57~12 minecraft:log 1
setblock ~31~58~12 minecraft:trapdoor 0
setblock ~33~56~12 minecraft:trapdoor 0
setblock ~1~68~13 minecraft:purpur_stairs 4
setblock ~2~66~13 minecraft:purpur_stairs 4
fill ~2~67~13 ~3~67~13 minecraft:purpur_block 0
setblock ~2~68~13 minecraft:purpur_stairs 1
setblock ~3~63~13 minecraft:purpur_stairs 4
fill ~3~64~13 ~3~66~13 minecraft:purpur_block 0
setblock ~4~0~13 minecraft:purpur_stairs 0
setblock ~4~47~13 minecraft:wooden_button 4
setblock ~4~48~13 minecraft:purpur_stairs 4
setblock ~4~49~13 minecraft:purpur_stairs 0
setblock ~4~50~13 minecraft:stone_brick_stairs 4
setblock ~4~51~13 minecraft:stone_brick_stairs 0
fill ~4~52~13 ~4~55~13 minecraft:stained_glass_pane 10
setblock ~4~56~13 minecraft:stone_brick_stairs 4
fill ~4~57~13 ~4~59~14 minecraft:stonebrick 0
fill ~4~60~13 ~4~62~13 minecraft:stonebrick 0
fill ~4~64~13 ~8~64~13 minecraft:nether_brick
fill ~4~65~13 ~5~65~13 minecraft:nether_brick
fill ~4~66~13 ~5~66~13 minecraft:purpur_block 0
setblock ~4~67~13 minecraft:purpur_stairs 1
setblock ~5~0~13 minecraft:stonebrick 0
setblock ~5~1~13 minecraft:stone_brick_stairs 0
setblock ~5~3~13 minecraft:stone_brick_stairs 4
setblock ~5~4~13 minecraft:stonebrick 0
setblock ~5~13~13 minecraft:double_stone_block_slab2 1
setblock ~5~46~13 minecraft:purpur_stairs 4
fill ~5~47~13 ~5~49~13 minecraft:purpur_block 0
fill ~6~1~13 ~6~3~13 minecraft:stone 6
setblock ~6~5~13 minecraft:stone_brick_stairs 4
setblock ~6~6~13 minecraft:stone_brick_stairs 0
fill ~6~7~13 ~6~11~13 minecraft:stained_glass_pane 2
setblock ~6~12~13 minecraft:stone_brick_stairs 4
setblock ~6~13~13 minecraft:double_stone_block_slab 5
setblock ~6~43~13 minecraft:purpur_stairs 4
fill ~6~44~13 ~6~45~13 minecraft:purpur_block 0
setblock ~6~46~13 minecraft:purpur_stairs 1
fill ~6~65~13 ~8~65~13 minecraft:purpur_block 0
setblock ~6~66~13 minecraft:purpur_stairs 1
setblock ~7~13~13 minecraft:stone_brick_stairs 5
setblock ~7~14~13 minecraft:stone_brick_stairs 0
setblock ~7~15~13 minecraft:stone_brick_stairs 4
setblock ~7~16~13 minecraft:stone_brick_stairs 0
setblock ~7~18~13 minecraft:stone_brick_stairs 4
setblock ~7~19~13 minecraft:stone_brick_stairs 0
setblock ~7~20~13 minecraft:stone_brick_stairs 4
setblock ~7~21~13 minecraft:stone_brick_stairs 0
setblock ~7~24~13 minecraft:stone_block_slab 7
setblock ~7~33~13 minecraft:nether_brick_stairs 4
setblock ~7~38~13 minecraft:double_stone_block_slab 7
setblock ~7~41~13 minecraft:stone_brick_stairs 4
setblock ~7~42~13 minecraft:stone_brick_stairs 0
setblock ~7~43~13 minecraft:purpur_block 0
fill ~7~44~13 ~7~47~14 minecraft:stonebrick 0
fill ~8~15~13 ~8~16~13 minecraft:stone 6
setblock ~8~17~13 minecraft:glowstone
fill ~8~18~13 ~8~23~13 minecraft:stone 6
setblock ~8~24~13 minecraft:stone_brick_stairs 0
setblock ~8~26~13 minecraft:cobblestone_wall 0
setblock ~8~27~13 minecraft:torch 5
setblock ~8~28~13 minecraft:stone_block_slab2 1
setblock ~8~29~13 minecraft:stone_block_slab2 1
setblock ~8~30~13 minecraft:stone_brick_stairs 4
fill ~8~31~13 ~8~32~13 minecraft:stone 6
fill ~8~34~13 ~8~36~13 minecraft:stained_glass_pane 2
setblock ~8~37~13 minecraft:stone_brick_stairs 4
setblock ~8~38~13 minecraft:stone_block_slab 13
setblock ~8~40~13 minecraft:stone_brick_stairs 4
setblock ~8~41~13 minecraft:cobblestone_wall 0
setblock ~8~42~13 minecraft:stone_brick_stairs 1
setblock ~8~43~13 minecraft:glowstone
setblock ~8~44~13 minecraft:stone_brick_stairs 5
setblock ~8~46~13 minecraft:torch 1
setblock ~9~24~13 minecraft:stonebrick 0
fill ~9~25~13 ~9~29~13 minecraft:stone 6
fill ~9~30~13 ~9~32~14 minecraft:stonebrick 0
setblock ~9~37~13 minecraft:torch 1
fill ~9~64~13 ~11~64~13 minecraft:purpur_block 0
setblock ~9~65~13 minecraft:purpur_stairs 1
fill ~12~4~13 ~12~4~20 minecraft:stone 6
setblock ~12~64~13 minecraft:purpur_stairs 1
setblock ~13~4~13 minecraft:glowstone
setblock ~13~58~13 minecraft:glowstone
fill ~13~59~13 ~13~62~13 minecraft:nether_brick_fence
setblock ~13~63~13 minecraft:glowstone
fill ~13~64~13 ~13~65~13 minecraft:nether_brick
fill ~13~66~13 ~13~67~13 minecraft:nether_brick_fence
setblock ~13~68~13 minecraft:glowstone
fill ~14~4~13 ~14~4~20 minecraft:stone 6
setblock ~14~64~13 minecraft:purpur_stairs 0
fill ~15~64~13 ~17~64~13 minecraft:purpur_block 0
setblock ~17~24~13 minecraft:stonebrick 0
fill ~17~25~13 ~17~29~13 minecraft:stone 6
fill ~17~30~13 ~17~32~14 minecraft:stonebrick 0
setblock ~17~37~13 minecraft:torch 2
setblock ~17~65~13 minecraft:purpur_stairs 0
fill ~18~15~13 ~18~16~13 minecraft:stone 6
setblock ~18~17~13 minecraft:glowstone
fill ~18~18~13 ~18~23~13 minecraft:stone 6
setblock ~18~24~13 minecraft:stone_brick_stairs 1
setblock ~18~26~13 minecraft:cobblestone_wall 0
setblock ~18~27~13 minecraft:torch 5
setblock ~18~28~13 minecraft:stone_block_slab2 1
setblock ~18~29~13 minecraft:stone_block_slab2 1
setblock ~18~30~13 minecraft:stone_brick_stairs 5
fill ~18~31~13 ~18~32~13 minecraft:stone 6
fill ~18~34~13 ~18~36~13 minecraft:stained_glass_pane 2
setblock ~18~37~13 minecraft:stone_brick_stairs 5
setblock ~18~38~13 minecraft:stone_block_slab 13
setblock ~18~40~13 minecraft:stone_brick_stairs 5
setblock ~18~41~13 minecraft:cobblestone_wall 0
setblock ~18~42~13 minecraft:stone_brick_stairs 0
setblock ~18~43~13 minecraft:glowstone
setblock ~18~44~13 minecraft:stone_brick_stairs 4
fill ~18~64~13 ~22~64~13 minecraft:nether_brick
fill ~18~65~13 ~20~65~13 minecraft:purpur_block 0
setblock ~19~13~13 minecraft:stone_brick_stairs 4
setblock ~19~14~13 minecraft:stone_brick_stairs 1
setblock ~19~15~13 minecraft:stone_brick_stairs 5
setblock ~19~16~13 minecraft:stone_brick_stairs 1
setblock ~19~18~13 minecraft:stone_brick_stairs 5
setblock ~19~19~13 minecraft:stone_brick_stairs 1
setblock ~19~20~13 minecraft:stone_brick_stairs 5
setblock ~19~21~13 minecraft:stone_brick_stairs 1
setblock ~19~24~13 minecraft:stone_block_slab 7
setblock ~19~33~13 minecraft:nether_brick_stairs 5
setblock ~19~38~13 minecraft:double_stone_block_slab 7
setblock ~19~41~13 minecraft:stone_brick_stairs 5
setblock ~19~42~13 minecraft:stone_brick_stairs 1
setblock ~19~43~13 minecraft:purpur_block 0
fill ~19~44~13 ~19~48~14 minecraft:stonebrick 0
fill ~20~1~13 ~20~3~13 minecraft:stone 6
setblock ~20~9~13 minecraft:stone_brick_stairs 5
fill ~20~10~13 ~20~11~13 minecraft:stained_glass_pane 2
setblock ~20~12~13 minecraft:stone_brick_stairs 5
setblock ~20~13~13 minecraft:double_stone_block_slab 5
setblock ~20~43~13 minecraft:purpur_stairs 5
fill ~20~44~13 ~20~45~13 minecraft:purpur_block 0
setblock ~20~46~13 minecraft:purpur_stairs 0
setblock ~20~66~13 minecraft:purpur_stairs 0
setblock ~21~0~13 minecraft:stonebrick 0
setblock ~21~1~13 minecraft:stone_brick_stairs 1
setblock ~21~3~13 minecraft:stone_brick_stairs 5
setblock ~21~4~13 minecraft:stonebrick 0
setblock ~21~13~13 minecraft:double_stone_block_slab2 1
setblock ~21~46~13 minecraft:purpur_stairs 5
fill ~21~47~13 ~21~49~13 minecraft:purpur_block 0
setblock ~21~51~13 minecraft:dark_oak_fence_gate 3
fill ~21~65~13 ~22~65~13 minecraft:nether_brick
fill ~21~66~13 ~23~66~13 minecraft:purpur_block 0
setblock ~22~0~13 minecraft:purpur_stairs 1
setblock ~22~47~13 minecraft:wooden_button 5
setblock ~22~48~13 minecraft:purpur_stairs 5
setblock ~22~49~13 minecraft:purpur_stairs 1
setblock ~22~50~13 minecraft:stone_brick_stairs 5
fill ~22~57~13 ~22~59~14 minecraft:stonebrick 0
fill ~22~60~13 ~22~62~13 minecraft:stonebrick 0
setblock ~22~67~13 minecraft:purpur_stairs 0
setblock ~23~63~13 minecraft:purpur_stairs 5
fill ~23~64~13 ~23~65~13 minecraft:purpur_block 0
fill ~23~67~13 ~24~67~13 minecraft:purpur_block 0
setblock ~24~66~13 minecraft:purpur_stairs 5
setblock ~24~68~13 minecraft:purpur_stairs 0
setblock ~25~56~13 minecraft:log 1
setblock ~25~68~13 minecraft:purpur_stairs 5
fill ~27~27~13 ~27~29~13 minecraft:fence 5
fill ~27~52~13 ~27~54~13 minecraft:cobblestone_wall 0
setblock ~27~55~13 minecraft:cobblestone_wall 0
setblock ~27~56~13 minecraft:cobblestone_wall 0
fill ~28~27~13 ~28~27~14 minecraft:log 0
fill ~28~29~13 ~28~32~13 minecraft:fence 5
setblock ~29~27~13 minecraft:magma
fill ~29~32~13 ~30~32~13 minecraft:fence 5
fill ~29~33~13 ~29~49~13 minecraft:fence 5
setblock ~30~27~13 minecraft:furnace 3
fill ~30~29~13 ~31~29~13 minecraft:fence 5
fill ~30~30~13 ~30~31~13 minecraft:fence 5
fill ~31~27~13 ~31~28~13 minecraft:fence 5
setblock ~31~56~13 minecraft:log 1
setblock ~3~59~14 minecraft:purpur_stairs 6
fill ~3~60~14 ~3~62~14 minecraft:purpur_block 0
setblock ~3~63~14 minecraft:purpur_stairs 3
fill ~4~49~14 ~5~49~14 minecraft:purpur_stairs 7
fill ~4~50~14 ~4~56~14 minecraft:stonebrick 0
fill ~4~60~14 ~11~62~14 minecraft:nether_brick
fill ~4~63~14 ~12~63~14 minecraft:nether_brick_stairs 3
setblock ~5~0~14 minecraft:purpur_stairs 0
setblock ~5~4~14 minecraft:stone_brick_stairs 4
setblock ~5~12~14 minecraft:stone_block_slab2 1
setblock ~5~13~14 minecraft:stone_block_slab2 1
setblock ~5~47~14 minecraft:purpur_stairs 7
setblock ~5~48~14 minecraft:purpur_stairs 3
setblock ~6~1~14 minecraft:cobblestone_wall 0
setblock ~6~2~14 minecraft:stone_brick_stairs 0
setblock ~6~3~14 minecraft:stone_brick_stairs 4
setblock ~6~5~14 minecraft:stone_brick_stairs 0
setblock ~6~6~14 minecraft:stone_brick_stairs 4
fill ~6~7~14 ~6~12~14 minecraft:stonebrick 0
setblock ~6~13~14 minecraft:stone_block_slab 5
setblock ~6~49~14 minecraft:stonebrick 0
setblock ~7~12~14 minecraft:stone_brick_stairs 6
fill ~7~13~14 ~7~13~15 minecraft:stonebrick 0
fill ~7~14~14 ~7~15~14 minecraft:stonebrick 0
setblock ~7~16~14 minecraft:stone_brick_stairs 7
setblock ~7~17~14 minecraft:cobblestone_wall 0
setblock ~7~18~14 minecraft:stone_brick_stairs 3
setblock ~7~19~14 minecraft:stone_brick_stairs 7
setblock ~7~20~14 minecraft:stone_brick_stairs 3
setblock ~7~23~14 minecraft:stone_block_slab 15
setblock ~7~33~14 minecraft:nether_brick_stairs 7
setblock ~7~37~14 minecraft:stone_block_slab 15
setblock ~7~38~14 minecraft:stone_block_slab 7
fill ~7~41~14 ~8~42~14 minecraft:stonebrick 0
setblock ~7~43~14 minecraft:stonebrick 0
setblock ~8~15~14 minecraft:stone_brick_stairs 5
fill ~8~16~14 ~8~21~14 minecraft:stained_glass 10
setblock ~8~22~14 minecraft:stone_brick_stairs 0
setblock ~8~28~14 minecraft:purpur_stairs 6
setblock ~8~31~14 minecraft:stone_brick_stairs 7
setblock ~8~32~14 minecraft:stone_brick_stairs 3
fill ~8~34~14 ~8~37~14 minecraft:stonebrick 0
setblock ~8~38~14 minecraft:stone_block_slab 5
setblock ~8~43~14 minecraft:cobblestone_wall 0
setblock ~8~44~14 minecraft:stone_brick_stairs 3
setblock ~9~24~14 minecraft:stone_brick_stairs 0
setblock ~9~25~14 minecraft:stone_brick_stairs 4
setblock ~9~26~14 minecraft:stone_brick_stairs 0
setblock ~9~27~14 minecraft:stone_brick_stairs 4
fill ~9~28~14 ~9~29~14 minecraft:stonebrick 0
setblock ~9~37~14 minecraft:stone_brick_stairs 6
fill ~13~4~14 ~13~4~19 minecraft:stone 6
setblock ~13~64~14 minecraft:purpur_stairs 2
fill ~14~63~14 ~14~63~22 minecraft:nether_brick_stairs 1
fill ~15~60~14 ~22~62~14 minecraft:nether_brick
fill ~15~63~14 ~22~63~14 minecraft:nether_brick_stairs 3
setblock ~17~24~14 minecraft:stone_brick_stairs 1
setblock ~17~25~14 minecraft:stone_brick_stairs 5
setblock ~17~26~14 minecraft:stone_brick_stairs 1
setblock ~17~27~14 minecraft:stone_brick_stairs 5
fill ~17~28~14 ~17~29~14 minecraft:stonebrick 0
setblock ~17~37~14 minecraft:stone_brick_stairs 6
setblock ~18~15~14 minecraft:stone_brick_stairs 4
fill ~18~16~14 ~18~21~14 minecraft:stained_glass 10
setblock ~18~22~14 minecraft:stone_brick_stairs 1
setblock ~18~28~14 minecraft:purpur_stairs 6
setblock ~18~31~14 minecraft:stone_brick_stairs 7
setblock ~18~32~14 minecraft:stone_brick_stairs 3
fill ~18~34~14 ~18~37~14 minecraft:stonebrick 0
setblock ~18~38~14 minecraft:stone_block_slab 5
fill ~18~41~14 ~19~41~14 minecraft:stonebrick 0
setblock ~18~42~14 minecraft:stone_brick_stairs 7
setblock ~18~43~14 minecraft:cobblestone_wall 0
setblock ~18~44~14 minecraft:stone_brick_stairs 3
setblock ~19~12~14 minecraft:stone_brick_stairs 6
fill ~19~13~14 ~19~13~15 minecraft:stonebrick 0
fill ~19~14~14 ~19~15~14 minecraft:stonebrick 0
setblock ~19~16~14 minecraft:stone_brick_stairs 7
setblock ~19~17~14 minecraft:cobblestone_wall 0
setblock ~19~18~14 minecraft:stone_brick_stairs 3
setblock ~19~19~14 minecraft:stone_brick_stairs 7
setblock ~19~20~14 minecraft:stone_brick_stairs 3
setblock ~19~23~14 minecraft:stone_block_slab 15
setblock ~19~33~14 minecraft:nether_brick_stairs 7
setblock ~19~37~14 minecraft:stone_block_slab 15
setblock ~19~38~14 minecraft:stone_block_slab 7
fill ~19~42~14 ~19~43~14 minecraft:stonebrick 0
setblock ~20~1~14 minecraft:cobblestone_wall 0
setblock ~20~2~14 minecraft:stone_brick_stairs 1
setblock ~20~3~14 minecraft:stone_brick_stairs 5
setblock ~20~8~14 minecraft:stone_brick_stairs 6
fill ~20~9~14 ~20~12~14 minecraft:stonebrick 0
setblock ~20~13~14 minecraft:stone_block_slab 5
setblock ~21~0~14 minecraft:purpur_stairs 1
setblock ~21~4~14 minecraft:stone_brick_stairs 5
setblock ~21~12~14 minecraft:stone_block_slab2 1
setblock ~21~13~14 minecraft:stone_block_slab2 1
setblock ~21~47~14 minecraft:purpur_stairs 7
setblock ~21~48~14 minecraft:purpur_stairs 3
fill ~21~49~14 ~22~49~14 minecraft:purpur_stairs 7
setblock ~21~51~14 minecraft:cobblestone_wall 0
setblock ~21~56~14 minecraft:barrier
setblock ~22~50~14 minecraft:stonebrick 0
setblock ~22~56~14 minecraft:stonebrick 0
fill ~23~56~14 ~32~56~14 minecraft:log 1
setblock ~23~59~14 minecraft:purpur_stairs 6
fill ~23~60~14 ~23~62~14 minecraft:purpur_block 0
setblock ~23~63~14 minecraft:purpur_stairs 3
fill ~24~51~14 ~26~51~14 minecraft:fence 5
fill ~25~49~14 ~29~50~14 minecraft:fence 5
fill ~25~52~14 ~29~53~14 minecraft:fence 5
setblock ~25~57~14 minecraft:log 1
setblock ~25~58~14 minecraft:trapdoor 2
setblock ~27~48~14 minecraft:fence 5
setblock ~27~54~14 minecraft:fence 5
fill ~28~51~14 ~30~51~14 minecraft:fence 5
setblock ~29~27~14 minecraft:crafting_table
fill ~29~29~14 ~29~29~15 minecraft:fence 5
fill ~29~30~14 ~29~32~14 minecraft:fence 5
setblock ~30~27~14 minecraft:diamond_ore
setblock ~31~54~14 minecraft:fence 5
setblock ~31~55~14 minecraft:log 1
setblock ~31~57~14 minecraft:log 1
setblock ~31~58~14 minecraft:trapdoor 0
setblock ~33~56~14 minecraft:trapdoor 0
setblock ~3~56~15 minecraft:purpur_stairs 6
fill ~3~57~15 ~3~58~15 minecraft:purpur_block 0
setblock ~3~59~15 minecraft:purpur_stairs 3
setblock ~4~50~15 minecraft:cobblestone_wall 0
setblock ~4~51~15 minecraft:torch 5
setblock ~4~56~15 minecraft:nether_brick_stairs 6
fill ~4~57~15 ~10~58~15 minecraft:nether_brick
fill ~4~59~15 ~11~59~15 minecraft:nether_brick_stairs 3
setblock ~5~0~15 minecraft:stone_block_slab2 1
setblock ~5~4~15 minecraft:stone_block_slab 13
setblock ~5~9~15 minecraft:stone_block_slab2 1
fill ~5~10~15 ~5~11~15 minecraft:cobblestone_wall 0
fill ~5~12~15 ~6~12~15 minecraft:purpur_stairs 3
setblock ~5~47~15 minecraft:wooden_button 4
setblock ~5~49~15 minecraft:purpur_stairs 4
fill ~5~51~15 ~5~56~15 minecraft:stonebrick 0
setblock ~6~1~15 minecraft:stone_brick_stairs 4
setblock ~6~2~15 minecraft:cobblestone_wall 0
setblock ~6~3~15 minecraft:stone_brick_stairs 0
fill ~6~4~15 ~6~4~16 minecraft:stonebrick 0
setblock ~6~8~15 minecraft:stone_brick_stairs 7
setblock ~6~46~15 minecraft:purpur_stairs 4
fill ~6~47~15 ~6~49~15 minecraft:purpur_block 0
setblock ~6~51~15 minecraft:stone_brick_stairs 6
fill ~6~56~15 ~10~56~15 minecraft:stonebrick 0
setblock ~7~1~15 minecraft:glowstone
setblock ~7~2~15 minecraft:purpur_block 0
fill ~7~3~15 ~7~4~16 minecraft:stone 6
fill ~7~5~15 ~7~12~15 minecraft:stonebrick 0
setblock ~7~35~15 minecraft:stone_block_slab 15
setblock ~7~36~15 minecraft:cobblestone_wall 0
fill ~7~37~15 ~8~37~15 minecraft:nether_brick_stairs 3
setblock ~7~44~15 minecraft:purpur_stairs 4
setblock ~7~45~15 minecraft:purpur_block 0
setblock ~7~46~15 minecraft:purpur_stairs 1
fill ~7~51~15 ~7~55~15 minecraft:stonebrick 0
fill ~8~1~15 ~8~1~16 minecraft:cobblestone
fill ~8~15~15 ~8~22~15 minecraft:stonebrick 0
setblock ~8~23~15 minecraft:nether_brick_stairs 0
setblock ~8~28~15 minecraft:purpur_stairs 3
setblock ~8~39~15 minecraft:stone_brick_stairs 4
setblock ~8~40~15 minecraft:cobblestone_wall 0
setblock ~8~41~15 minecraft:stone_brick_stairs 0
setblock ~8~42~15 minecraft:stone_brick_stairs 4
fill ~8~43~15 ~8~44~16 minecraft:stonebrick 0
fill ~8~45~15 ~8~49~15 minecraft:stonebrick 0
setblock ~8~50~15 minecraft:stone_brick_stairs 3
fill ~8~51~15 ~8~53~15 minecraft:stained_glass_pane 10
setblock ~8~54~15 minecraft:stone_brick_stairs 7
fill ~8~55~15 ~9~55~15 minecraft:stonebrick 0
fill ~9~19~15 ~9~22~15 minecraft:stonebrick 0
fill ~9~24~15 ~10~24~15 minecraft:stonebrick 0
setblock ~9~25~15 minecraft:stone_brick_stairs 0
setblock ~9~28~15 minecraft:purpur_stairs 0
setblock ~9~30~15 minecraft:stone_brick_stairs 7
setblock ~9~31~15 minecraft:cobblestone_wall 0
fill ~9~32~15 ~10~32~15 minecraft:stonebrick 0
fill ~9~33~15 ~9~37~15 minecraft:stonebrick 0
setblock ~9~46~15 minecraft:stone_brick_stairs 5
fill ~9~47~15 ~9~49~15 minecraft:stonebrick 0
fill ~9~51~15 ~9~54~15 minecraft:stonebrick 0
setblock ~10~23~15 minecraft:stonebrick 0
fill ~10~25~15 ~10~30~15 minecraft:stonebrick 0
setblock ~10~31~15 minecraft:monster_egg 2
setblock ~10~55~15 minecraft:stone_brick_stairs 5
fill ~12~60~15 ~12~62~22 minecraft:nether_brick
fill ~12~63~15 ~12~63~22 minecraft:nether_brick_stairs 0
fill ~13~64~15 ~13~64~17 minecraft:purpur_block 0
fill ~14~60~15 ~14~62~22 minecraft:nether_brick
fill ~15~59~15 ~15~59~17 minecraft:nether_brick_stairs 1
fill ~16~23~15 ~16~32~15 minecraft:stonebrick 0
setblock ~16~55~15 minecraft:stone_brick_stairs 4
fill ~16~56~15 ~21~56~15 minecraft:stonebrick 0
fill ~16~57~15 ~22~58~15 minecraft:nether_brick
fill ~16~59~15 ~22~59~15 minecraft:nether_brick_stairs 3
fill ~17~19~15 ~18~22~15 minecraft:stonebrick 0
setblock ~17~24~15 minecraft:stonebrick 0
setblock ~17~25~15 minecraft:stone_brick_stairs 1
setblock ~17~28~15 minecraft:purpur_stairs 1
setblock ~17~30~15 minecraft:stone_brick_stairs 7
setblock ~17~31~15 minecraft:cobblestone_wall 0
fill ~17~32~15 ~17~37~15 minecraft:stonebrick 0
setblock ~17~46~15 minecraft:stone_brick_stairs 4
fill ~17~47~15 ~18~49~15 minecraft:stonebrick 0
fill ~17~51~15 ~17~55~15 minecraft:stonebrick 0
fill ~18~1~15 ~18~1~16 minecraft:cobblestone
fill ~18~15~15 ~18~18~15 minecraft:stonebrick 0
setblock ~18~23~15 minecraft:nether_brick_stairs 1
setblock ~18~28~15 minecraft:purpur_stairs 3
fill ~18~37~15 ~19~37~15 minecraft:nether_brick_stairs 3
setblock ~18~39~15 minecraft:stone_brick_stairs 5
setblock ~18~40~15 minecraft:cobblestone_wall 0
setblock ~18~41~15 minecraft:stone_brick_stairs 1
setblock ~18~42~15 minecraft:stone_brick_stairs 5
fill ~18~43~15 ~18~44~16 minecraft:stonebrick 0
fill ~18~45~15 ~18~46~15 minecraft:stonebrick 0
setblock ~18~50~15 minecraft:stone_brick_stairs 3
fill ~18~51~15 ~18~53~15 minecraft:stained_glass_pane 10
setblock ~18~54~15 minecraft:stone_brick_stairs 7
fill ~18~55~15 ~19~55~15 minecraft:stonebrick 0
setblock ~19~1~15 minecraft:stone 6
setblock ~19~2~15 minecraft:purpur_block 0
fill ~19~3~15 ~19~3~16 minecraft:stone 6
fill ~19~5~15 ~19~12~15 minecraft:stonebrick 0
setblock ~19~35~15 minecraft:stone_block_slab 15
setblock ~19~36~15 minecraft:cobblestone_wall 0
setblock ~19~44~15 minecraft:purpur_stairs 5
setblock ~19~45~15 minecraft:purpur_block 0
setblock ~19~46~15 minecraft:purpur_stairs 0
fill ~19~51~15 ~19~54~15 minecraft:stonebrick 0
setblock ~20~1~15 minecraft:stone_brick_stairs 5
setblock ~20~2~15 minecraft:cobblestone_wall 0
setblock ~20~3~15 minecraft:stone_brick_stairs 1
fill ~20~4~15 ~20~4~16 minecraft:stonebrick 0
setblock ~20~5~15 minecraft:stone_brick_stairs 1
setblock ~20~6~15 minecraft:stone_brick_stairs 5
setblock ~20~7~15 minecraft:fire 0
setblock ~20~8~15 minecraft:stone_brick_stairs 7
fill ~20~12~15 ~21~12~15 minecraft:purpur_stairs 3
setblock ~20~46~15 minecraft:purpur_stairs 5
fill ~20~47~15 ~20~49~15 minecraft:purpur_block 0
setblock ~20~51~15 minecraft:stone_brick_stairs 6
setblock ~21~0~15 minecraft:stone_block_slab2 1
setblock ~21~4~15 minecraft:stone_block_slab 13
setblock ~21~9~15 minecraft:stone_block_slab2 1
fill ~21~10~15 ~21~11~15 minecraft:cobblestone_wall 0
setblock ~21~47~15 minecraft:wooden_button 5
setblock ~21~49~15 minecraft:purpur_stairs 5
fill ~21~51~15 ~21~55~15 minecraft:stonebrick 0
setblock ~22~4~15 minecraft:purpur_stairs 4
setblock ~22~5~15 minecraft:stone_block_slab2 1
setblock ~22~56~15 minecraft:nether_brick_stairs 6
setblock ~23~3~15 minecraft:purpur_stairs 4
setblock ~23~4~15 minecraft:purpur_stairs 1
setblock ~23~56~15 minecraft:purpur_stairs 6
fill ~23~57~15 ~23~58~15 minecraft:purpur_block 0
setblock ~23~59~15 minecraft:purpur_stairs 3
setblock ~24~2~15 minecraft:purpur_stairs 4
setblock ~24~3~15 minecraft:purpur_stairs 1
fill ~24~50~15 ~24~52~15 minecraft:quartz_block 0
setblock ~25~49~15 minecraft:quartz_block 0
setblock ~25~53~15 minecraft:quartz_block 0
setblock ~25~56~15 minecraft:log 1
fill ~26~48~15 ~28~48~15 minecraft:quartz_block 0
fill ~26~54~15 ~28~54~15 minecraft:quartz_block 0
setblock ~27~56~15 minecraft:cobblestone_wall 0
setblock ~27~57~15 minecraft:cobblestone_wall 0
fill ~28~26~15 ~30~26~15 minecraft:stone_block_slab2 1
fill ~29~27~15 ~29~28~15 minecraft:fence 5
setblock ~29~49~15 minecraft:quartz_block 0
setblock ~29~53~15 minecraft:quartz_block 0
fill ~30~50~15 ~30~52~15 minecraft:quartz_block 0
setblock ~31~56~15 minecraft:log 1
setblock ~3~54~16 minecraft:purpur_stairs 6
setblock ~3~55~16 minecraft:purpur_block 0
setblock ~3~56~16 minecraft:purpur_stairs 3
fill ~4~54~16 ~5~54~16 minecraft:nether_brick_stairs 6
fill ~4~55~16 ~9~55~16 minecraft:nether_brick
fill ~4~56~16 ~10~56~16 minecraft:nether_brick_stairs 3
fill ~5~5~16 ~5~5~17 minecraft:stone_block_slab2 1
setblock ~6~0~16 minecraft:stone_brick_stairs 4
setblock ~6~1~16 minecraft:stone_brick_stairs 0
setblock ~6~3~16 minecraft:stone_brick_stairs 4
setblock ~6~47~16 minecraft:wooden_button 3
fill ~6~49~16 ~9~49~16 minecraft:purpur_stairs 7
fill ~6~50~16 ~6~54~16 minecraft:log 1
setblock ~7~1~16 minecraft:stone 6
setblock ~7~2~16 minecraft:glowstone
setblock ~7~5~16 minecraft:stone_brick_stairs 3
setblock ~7~7~16 minecraft:stone_brick_stairs 7
setblock ~7~8~16 minecraft:cobblestone_wall 0
setblock ~7~9~16 minecraft:stone_brick_stairs 3
setblock ~7~11~16 minecraft:stone_brick_stairs 7
setblock ~7~12~16 minecraft:cobblestone_wall 0
setblock ~7~13~16 minecraft:stone_brick_stairs 3
setblock ~7~50~16 minecraft:stone_brick_stairs 7
setblock ~7~51~16 minecraft:flower_pot 0
setblock ~8~2~16 minecraft:purpur_block 0
setblock ~8~3~16 minecraft:stone 6
fill ~8~5~16 ~8~16~16 minecraft:nether_brick
setblock ~8~17~16 minecraft:nether_brick_stairs 0
setblock ~8~23~16 minecraft:stone_block_slab 7
setblock ~8~41~16 minecraft:stone_brick_stairs 7
fill ~8~42~16 ~9~42~16 minecraft:stonebrick 0
setblock ~8~45~16 minecraft:stone_brick_stairs 3
setblock ~8~47~16 minecraft:stone_brick_stairs 7
setblock ~8~48~16 minecraft:stone_brick_stairs 3
fill ~9~14~16 ~9~14~17 minecraft:stonebrick 0
fill ~9~15~16 ~9~18~16 minecraft:stonebrick 0
setblock ~9~19~16 minecraft:stone_brick_stairs 0
setblock ~9~21~16 minecraft:stone_brick_stairs 4
setblock ~9~22~16 minecraft:stone_brick_stairs 0
setblock ~9~24~16 minecraft:stone_brick_stairs 4
setblock ~9~25~16 minecraft:cobblestone_wall 0
setblock ~9~26~16 minecraft:stone_brick_stairs 0
setblock ~9~28~16 minecraft:purpur_stairs 4
setblock ~9~32~16 minecraft:stone_brick_stairs 7
setblock ~9~33~16 minecraft:cobblestone_wall 0
setblock ~9~34~16 minecraft:stone_brick_stairs 3
setblock ~9~36~16 minecraft:stone_brick_stairs 7
setblock ~9~37~16 minecraft:cobblestone_wall 0
setblock ~9~38~16 minecraft:stone_brick_stairs 3
setblock ~9~40~16 minecraft:stone_brick_stairs 7
setblock ~9~41~16 minecraft:stonebrick 0
fill ~9~43~16 ~9~45~16 minecraft:stonebrick 0
setblock ~9~46~16 minecraft:stone_brick_stairs 3
setblock ~9~50~16 minecraft:stone_brick_stairs 7
setblock ~10~20~16 minecraft:stained_glass 10
setblock ~10~21~16 minecraft:stone_block_slab 13
fill ~10~22~16 ~10~55~16 minecraft:purpur_block 2
fill ~11~23~16 ~11~24~17 minecraft:stonebrick 0
fill ~11~25~16 ~11~32~16 minecraft:stonebrick 0
setblock ~11~55~16 minecraft:stone_brick_stairs 6
fill ~11~56~16 ~11~56~21 minecraft:stonebrick 0
fill ~11~57~16 ~11~58~17 minecraft:nether_brick
fill ~11~59~16 ~11~59~17 minecraft:nether_brick_stairs 0
fill ~15~23~16 ~15~24~17 minecraft:stonebrick 0
fill ~15~25~16 ~15~30~16 minecraft:stonebrick 0
setblock ~15~31~16 minecraft:monster_egg 2
fill ~15~32~16 ~15~32~17 minecraft:stonebrick 0
setblock ~15~55~16 minecraft:stone_brick_stairs 6
fill ~15~56~16 ~15~56~21 minecraft:stonebrick 0
fill ~15~57~16 ~15~58~17 minecraft:nether_brick
setblock ~16~20~16 minecraft:stained_glass 10
setblock ~16~21~16 minecraft:stone_block_slab 13
fill ~16~22~16 ~16~55~16 minecraft:purpur_block 2
fill ~16~56~16 ~16~56~22 minecraft:nether_brick_stairs 1
fill ~17~14~16 ~17~14~17 minecraft:stonebrick 0
fill ~17~15~16 ~17~18~16 minecraft:stonebrick 0
setblock ~17~19~16 minecraft:stone_brick_stairs 1
setblock ~17~21~16 minecraft:stone_brick_stairs 5
setblock ~17~22~16 minecraft:stone_brick_stairs 1
setblock ~17~24~16 minecraft:stone_brick_stairs 5
setblock ~17~25~16 minecraft:cobblestone_wall 0
setblock ~17~26~16 minecraft:stone_brick_stairs 1
setblock ~17~28~16 minecraft:purpur_stairs 5
setblock ~17~32~16 minecraft:stone_brick_stairs 7
setblock ~17~33~16 minecraft:cobblestone_wall 0
setblock ~17~34~16 minecraft:stone_brick_stairs 3
setblock ~17~36~16 minecraft:stone_brick_stairs 7
setblock ~17~37~16 minecraft:cobblestone_wall 0
setblock ~17~38~16 minecraft:stone_brick_stairs 3
setblock ~17~40~16 minecraft:stone_brick_stairs 7
fill ~17~41~16 ~17~45~16 minecraft:stonebrick 0
setblock ~17~46~16 minecraft:stone_brick_stairs 3
fill ~17~49~16 ~20~49~16 minecraft:purpur_stairs 7
setblock ~17~50~16 minecraft:stone_brick_stairs 7
setblock ~17~51~16 minecraft:flower_pot 0
setblock ~17~54~16 minecraft:stone_brick_stairs 5
fill ~17~55~16 ~22~55~16 minecraft:nether_brick
fill ~17~56~16 ~22~56~16 minecraft:nether_brick_stairs 3
setblock ~18~2~16 minecraft:purpur_block 0
setblock ~18~3~16 minecraft:stone 6
fill ~18~5~16 ~18~16~16 minecraft:nether_brick
setblock ~18~17~16 minecraft:nether_brick_stairs 1
setblock ~18~23~16 minecraft:stone_block_slab 7
setblock ~18~41~16 minecraft:stone_brick_stairs 7
setblock ~18~42~16 minecraft:stonebrick 0
setblock ~18~45~16 minecraft:stone_brick_stairs 3
setblock ~18~47~16 minecraft:stone_brick_stairs 7
setblock ~18~48~16 minecraft:stone_brick_stairs 3
setblock ~19~2~16 minecraft:glowstone
setblock ~19~5~16 minecraft:stone_brick_stairs 3
setblock ~19~7~16 minecraft:stone_brick_stairs 7
setblock ~19~8~16 minecraft:cobblestone_wall 0
setblock ~19~9~16 minecraft:stone_brick_stairs 3
setblock ~19~11~16 minecraft:stone_brick_stairs 7
setblock ~19~12~16 minecraft:cobblestone_wall 0
setblock ~19~13~16 minecraft:stone_brick_stairs 3
setblock ~19~50~16 minecraft:stone_brick_stairs 7
setblock ~19~54~16 minecraft:stone_brick_stairs 4
setblock ~20~0~16 minecraft:stone_brick_stairs 5
setblock ~20~1~16 minecraft:stone_brick_stairs 1
setblock ~20~3~16 minecraft:stone_brick_stairs 5
setblock ~20~47~16 minecraft:wooden_button 3
fill ~20~50~16 ~20~54~16 minecraft:log 1
fill ~21~5~16 ~21~5~17 minecraft:stone_block_slab2 1
fill ~21~54~16 ~22~54~16 minecraft:nether_brick_stairs 6
setblock ~23~54~16 minecraft:purpur_stairs 6
setblock ~23~55~16 minecraft:purpur_block 0
setblock ~23~56~16 minecraft:purpur_stairs 3
fill ~25~0~16 ~25~0~17 minecraft:purpur_stairs 0
setblock ~25~1~16 minecraft:purpur_stairs 4
setblock ~25~2~16 minecraft:purpur_stairs 1
setblock ~25~56~16 minecraft:trapdoor 2
setblock ~26~0~16 minecraft:purpur_block 2
setblock ~26~1~16 minecraft:purpur_stairs 1
setblock ~26~5~16 minecraft:purpur_stairs 6
setblock ~27~0~16 minecraft:purpur_stairs 5
setblock ~27~51~16 minecraft:trapdoor 2
setblock ~27~56~16 minecraft:cobblestone_wall 0
setblock ~31~56~16 minecraft:trapdoor 2
fill ~3~54~17 ~9~54~17 minecraft:purpur_stairs 3
setblock ~6~0~17 minecraft:stone_block_slab2 1
setblock ~6~1~17 minecraft:stone_brick_stairs 4
setblock ~6~2~17 minecraft:cobblestone_wall 0
setblock ~6~3~17 minecraft:stone_brick_stairs 0
setblock ~6~4~17 minecraft:stone_block_slab 13
setblock ~7~1~17 minecraft:stone_brick_stairs 3
setblock ~7~3~17 minecraft:stone_brick_stairs 7
fill ~7~4~17 ~8~4~17 minecraft:stonebrick 0
setblock ~8~1~17 minecraft:stone_brick_stairs 5
setblock ~8~2~17 minecraft:cobblestone_wall 0
setblock ~8~3~17 minecraft:stone_brick_stairs 1
setblock ~8~5~17 minecraft:stone_brick_stairs 7
fill ~8~6~17 ~9~6~17 minecraft:stonebrick 0
setblock ~8~7~17 minecraft:stone_brick_stairs 0
setblock ~8~9~17 minecraft:stone_brick_stairs 4
setblock ~8~10~17 minecraft:cobblestone_wall 0
setblock ~8~11~17 minecraft:stone_brick_stairs 0
setblock ~8~13~17 minecraft:stone_brick_stairs 4
setblock ~9~1~17 minecraft:cobblestone
setblock ~9~2~17 minecraft:purpur_block 0
setblock ~9~3~17 minecraft:stone 6
setblock ~9~5~17 minecraft:stonebrick 0
fill ~9~7~17 ~9~9~17 minecraft:stonebrick 0
setblock ~9~10~17 minecraft:glowstone
fill ~9~11~17 ~9~13~17 minecraft:stonebrick 0
setblock ~9~15~17 minecraft:cobblestone_wall 0
setblock ~9~16~17 minecraft:stone_block_slab 5
setblock ~9~17~17 minecraft:stone_block_slab 13
fill ~9~18~17 ~9~20~17 minecraft:purpur_block 2
setblock ~9~21~17 minecraft:stone_block_slab 5
setblock ~9~22~17 minecraft:stone_block_slab 15
setblock ~9~28~17 minecraft:stone_block_slab2 1
setblock ~9~42~17 minecraft:stone_block_slab 13
setblock ~9~43~17 minecraft:glowstone
setblock ~9~44~17 minecraft:stone_block_slab 5
fill ~10~14~17 ~10~18~17 minecraft:stonebrick 0
setblock ~10~19~17 minecraft:stone_brick_stairs 3
setblock ~10~21~17 minecraft:stone_brick_stairs 7
setblock ~10~22~17 minecraft:stone_brick_stairs 3
setblock ~10~24~17 minecraft:stone_brick_stairs 7
setblock ~10~25~17 minecraft:cobblestone_wall 0
setblock ~10~26~17 minecraft:stone_brick_stairs 3
setblock ~10~28~17 minecraft:purpur_stairs 7
setblock ~10~32~17 minecraft:stone_brick_stairs 4
setblock ~10~33~17 minecraft:cobblestone_wall 0
setblock ~10~34~17 minecraft:stone_brick_stairs 0
setblock ~10~36~17 minecraft:stone_brick_stairs 4
setblock ~10~37~17 minecraft:cobblestone_wall 0
setblock ~10~38~17 minecraft:stone_brick_stairs 0
setblock ~10~40~17 minecraft:stone_brick_stairs 4
fill ~10~41~17 ~10~45~17 minecraft:stonebrick 0
setblock ~10~46~17 minecraft:stone_brick_stairs 0
fill ~10~49~17 ~10~49~20 minecraft:purpur_stairs 4
setblock ~10~50~17 minecraft:stone_brick_stairs 4
setblock ~10~51~17 minecraft:flower_pot 0
fill ~10~55~17 ~10~55~22 minecraft:nether_brick
fill ~10~56~17 ~10~56~22 minecraft:nether_brick_stairs 0
setblock ~10~57~17 minecraft:purpur_stairs 4
setblock ~10~58~17 minecraft:purpur_stairs 2
fill ~11~19~17 ~11~22~18 minecraft:stonebrick 0
setblock ~11~25~17 minecraft:stone_brick_stairs 3
setblock ~11~28~17 minecraft:purpur_stairs 3
setblock ~11~30~17 minecraft:stone_brick_stairs 4
setblock ~11~31~17 minecraft:cobblestone_wall 0
fill ~11~32~17 ~14~32~17 minecraft:stonebrick 0
fill ~11~33~17 ~11~40~17 minecraft:stonebrick 0
setblock ~11~46~17 minecraft:stone_brick_stairs 6
fill ~11~47~17 ~11~49~18 minecraft:stonebrick 0
fill ~11~51~17 ~11~55~17 minecraft:stonebrick 0
fill ~12~23~17 ~14~23~17 minecraft:stonebrick 0
setblock ~12~24~17 minecraft:stone_brick_stairs 3
setblock ~12~25~17 minecraft:stone_brick_stairs 7
setblock ~12~26~17 minecraft:stone_brick_stairs 3
setblock ~12~27~17 minecraft:stone_brick_stairs 7
fill ~12~28~17 ~12~31~17 minecraft:stonebrick 0
setblock ~12~37~17 minecraft:stone_brick_stairs 5
fill ~12~38~17 ~15~40~17 minecraft:stonebrick 0
setblock ~13~24~17 minecraft:stonebrick 0
fill ~13~25~17 ~13~29~17 minecraft:stone 6
fill ~13~30~17 ~14~31~17 minecraft:stonebrick 0
setblock ~13~37~17 minecraft:torch 4
setblock ~13~65~17 minecraft:purpur_stairs 2
setblock ~14~24~17 minecraft:stone_brick_stairs 3
setblock ~14~25~17 minecraft:stone_brick_stairs 7
setblock ~14~26~17 minecraft:stone_brick_stairs 3
setblock ~14~27~17 minecraft:stone_brick_stairs 7
fill ~14~28~17 ~14~29~17 minecraft:stonebrick 0
setblock ~14~37~17 minecraft:stone_brick_stairs 4
fill ~14~55~17 ~14~55~19 minecraft:stone_brick_stairs 4
fill ~15~19~17 ~15~22~18 minecraft:stonebrick 0
setblock ~15~25~17 minecraft:stone_brick_stairs 3
setblock ~15~28~17 minecraft:purpur_stairs 3
setblock ~15~30~17 minecraft:stone_brick_stairs 5
setblock ~15~31~17 minecraft:cobblestone_wall 0
fill ~15~33~17 ~15~37~17 minecraft:stonebrick 0
setblock ~15~46~17 minecraft:stone_brick_stairs 6
fill ~15~47~17 ~15~49~18 minecraft:stonebrick 0
fill ~15~51~17 ~15~55~17 minecraft:stonebrick 0
fill ~16~14~17 ~16~17~17 minecraft:stonebrick 0
setblock ~16~18~17 minecraft:double_stone_block_slab 5
setblock ~16~19~17 minecraft:stone_brick_stairs 3
setblock ~16~21~17 minecraft:stone_brick_stairs 7
setblock ~16~22~17 minecraft:stone_brick_stairs 3
setblock ~16~24~17 minecraft:stone_brick_stairs 7
setblock ~16~25~17 minecraft:cobblestone_wall 0
setblock ~16~26~17 minecraft:stone_brick_stairs 3
setblock ~16~28~17 minecraft:purpur_stairs 7
setblock ~16~32~17 minecraft:stone_brick_stairs 5
setblock ~16~33~17 minecraft:cobblestone_wall 0
setblock ~16~34~17 minecraft:stone_brick_stairs 1
setblock ~16~36~17 minecraft:stone_brick_stairs 5
setblock ~16~37~17 minecraft:cobblestone_wall 0
setblock ~16~38~17 minecraft:stone_brick_stairs 1
setblock ~16~40~17 minecraft:stone_brick_stairs 5
fill ~16~41~17 ~16~45~17 minecraft:stonebrick 0
setblock ~16~46~17 minecraft:stone_brick_stairs 1
fill ~16~49~17 ~16~49~20 minecraft:purpur_stairs 5
setblock ~16~50~17 minecraft:stone_brick_stairs 5
setblock ~16~54~17 minecraft:stone_brick_stairs 7
fill ~16~55~17 ~16~55~22 minecraft:nether_brick
setblock ~16~57~17 minecraft:purpur_stairs 5
setblock ~16~58~17 minecraft:purpur_stairs 2
setblock ~17~1~17 minecraft:cobblestone
setblock ~17~2~17 minecraft:purpur_block 0
fill ~17~3~17 ~17~4~17 minecraft:stone 6
fill ~17~5~17 ~17~9~17 minecraft:stonebrick 0
setblock ~17~10~17 minecraft:glowstone
fill ~17~11~17 ~17~13~17 minecraft:stonebrick 0
setblock ~17~15~17 minecraft:cobblestone_wall 0
setblock ~17~16~17 minecraft:stone_block_slab 5
setblock ~17~17~17 minecraft:stone_block_slab 13
fill ~17~18~17 ~17~20~17 minecraft:purpur_block 2
setblock ~17~21~17 minecraft:stone_block_slab 5
setblock ~17~22~17 minecraft:stone_block_slab 15
setblock ~17~28~17 minecraft:stone_block_slab2 1
setblock ~17~42~17 minecraft:stone_block_slab 13
setblock ~17~43~17 minecraft:glowstone
setblock ~17~44~17 minecraft:stone_block_slab 5
fill ~17~54~17 ~17~54~23 minecraft:purpur_stairs 1
setblock ~18~1~17 minecraft:stone_brick_stairs 4
setblock ~18~2~17 minecraft:cobblestone_wall 0
setblock ~18~3~17 minecraft:stone_brick_stairs 0
fill ~18~4~17 ~19~4~17 minecraft:stonebrick 0
setblock ~18~5~17 minecraft:stone_brick_stairs 7
setblock ~18~6~17 minecraft:stonebrick 0
setblock ~18~7~17 minecraft:stone_brick_stairs 1
setblock ~18~9~17 minecraft:stone_brick_stairs 5
setblock ~18~10~17 minecraft:cobblestone_wall 0
setblock ~18~11~17 minecraft:stone_brick_stairs 1
setblock ~18~13~17 minecraft:stone_brick_stairs 5
fill ~18~54~17 ~23~54~17 minecraft:purpur_stairs 3
setblock ~19~1~17 minecraft:stone_brick_stairs 3
setblock ~19~3~17 minecraft:stone_brick_stairs 7
setblock ~20~0~17 minecraft:stone_block_slab2 1
setblock ~20~1~17 minecraft:stone_brick_stairs 5
setblock ~20~2~17 minecraft:cobblestone_wall 0
setblock ~20~3~17 minecraft:stone_brick_stairs 1
setblock ~20~4~17 minecraft:stone_block_slab 13
setblock ~25~5~17 minecraft:purpur_stairs 4
setblock ~26~0~17 minecraft:purpur_stairs 4
fill ~26~1~17 ~26~5~17 minecraft:log 1
setblock ~26~6~17 minecraft:fire 0
setblock ~27~0~17 minecraft:purpur_stairs 1
setblock ~27~5~17 minecraft:purpur_stairs 5
setblock ~6~5~18 minecraft:stone_block_slab2 1
setblock ~7~0~18 minecraft:stone_block_slab2 1
setblock ~7~4~18 minecraft:stone_brick_stairs 7
fill ~8~4~18 ~9~4~18 minecraft:stonebrick 0
setblock ~9~1~18 minecraft:stone_brick_stairs 6
setblock ~9~2~18 minecraft:cobblestone_wall 0
setblock ~9~3~18 minecraft:stone_brick_stairs 2
setblock ~9~5~18 minecraft:stone_brick_stairs 4
setblock ~9~6~18 minecraft:stonebrick 0
setblock ~9~7~18 minecraft:stone_brick_stairs 3
setblock ~9~9~18 minecraft:stone_brick_stairs 7
setblock ~9~10~18 minecraft:cobblestone_wall 0
setblock ~9~11~18 minecraft:stone_brick_stairs 3
setblock ~9~13~18 minecraft:stone_brick_stairs 7
fill ~9~54~18 ~9~54~23 minecraft:purpur_stairs 0
fill ~10~1~18 ~11~1~18 minecraft:cobblestone
setblock ~10~2~18 minecraft:purpur_block 0
fill ~10~3~18 ~10~3~19 minecraft:stone 6
fill ~10~5~18 ~10~16~18 minecraft:nether_brick
setblock ~10~17~18 minecraft:nether_brick_stairs 3
setblock ~10~23~18 minecraft:stone_block_slab 7
setblock ~10~41~18 minecraft:stone_brick_stairs 4
fill ~10~42~18 ~10~44~18 minecraft:stonebrick 0
setblock ~10~45~18 minecraft:stone_brick_stairs 0
setblock ~10~47~18 minecraft:stone_brick_stairs 4
setblock ~10~48~18 minecraft:stone_brick_stairs 0
setblock ~10~58~18 minecraft:purpur_stairs 7
setblock ~10~59~18 minecraft:purpur_block 0
setblock ~10~60~18 minecraft:purpur_stairs 2
fill ~11~14~18 ~15~14~18 minecraft:stonebrick 0
fill ~11~15~18 ~11~18~18 minecraft:stonebrick 0
setblock ~11~23~18 minecraft:nether_brick_stairs 3
setblock ~11~28~18 minecraft:purpur_stairs 0
fill ~11~37~18 ~11~37~19 minecraft:nether_brick_stairs 0
setblock ~11~39~18 minecraft:stone_brick_stairs 7
setblock ~11~40~18 minecraft:cobblestone_wall 0
setblock ~11~41~18 minecraft:stone_brick_stairs 3
setblock ~11~42~18 minecraft:stone_brick_stairs 7
fill ~11~43~18 ~11~46~18 minecraft:stonebrick 0
setblock ~11~50~18 minecraft:stone_brick_stairs 0
fill ~11~51~18 ~11~53~18 minecraft:stained_glass_pane 10
setblock ~11~54~18 minecraft:stone_brick_stairs 4
fill ~11~55~18 ~11~55~19 minecraft:stonebrick 0
fill ~11~57~18 ~11~58~20 minecraft:stained_glass_pane 10
setblock ~11~59~18 minecraft:nether_brick
setblock ~11~60~18 minecraft:nether_brick_stairs 2
setblock ~12~15~18 minecraft:stone_brick_stairs 6
fill ~12~16~18 ~12~21~18 minecraft:stained_glass 10
setblock ~12~22~18 minecraft:stone_brick_stairs 3
setblock ~12~28~18 minecraft:purpur_stairs 5
setblock ~12~31~18 minecraft:stone_brick_stairs 4
setblock ~12~32~18 minecraft:stone_brick_stairs 0
fill ~12~33~18 ~14~33~18 minecraft:stonebrick 0
fill ~12~34~18 ~12~37~18 minecraft:stonebrick 0
setblock ~12~38~18 minecraft:stone_block_slab 5
fill ~12~41~18 ~12~42~19 minecraft:stonebrick 0
setblock ~12~43~18 minecraft:cobblestone_wall 0
setblock ~12~44~18 minecraft:stone_brick_stairs 0
fill ~13~15~18 ~13~16~18 minecraft:stone 6
setblock ~13~17~18 minecraft:glowstone
fill ~13~18~18 ~13~23~18 minecraft:stone 6
setblock ~13~24~18 minecraft:stone_brick_stairs 3
setblock ~13~26~18 minecraft:cobblestone_wall 0
setblock ~13~27~18 minecraft:torch 5
setblock ~13~28~18 minecraft:stone_block_slab2 1
setblock ~13~29~18 minecraft:stone_block_slab2 1
setblock ~13~30~18 minecraft:stone_brick_stairs 7
fill ~13~31~18 ~13~32~18 minecraft:stone 6
fill ~13~34~18 ~13~36~18 minecraft:stained_glass_pane 2
setblock ~13~37~18 minecraft:stone_brick_stairs 7
setblock ~13~38~18 minecraft:stone_block_slab 13
setblock ~13~40~18 minecraft:stone_brick_stairs 7
setblock ~13~41~18 minecraft:cobblestone_wall 0
setblock ~13~42~18 minecraft:stone_brick_stairs 2
setblock ~13~43~18 minecraft:glowstone
setblock ~13~44~18 minecraft:stone_brick_stairs 6
setblock ~13~46~18 minecraft:torch 4
fill ~13~64~18 ~13~64~22 minecraft:nether_brick
fill ~13~65~18 ~13~65~20 minecraft:purpur_block 0
setblock ~14~15~18 minecraft:stone_brick_stairs 6
fill ~14~16~18 ~14~21~18 minecraft:stained_glass 10
setblock ~14~22~18 minecraft:stone_brick_stairs 3
setblock ~14~28~18 minecraft:purpur_stairs 4
setblock ~14~31~18 minecraft:stone_brick_stairs 5
setblock ~14~32~18 minecraft:stone_brick_stairs 1
fill ~14~34~18 ~14~37~18 minecraft:stonebrick 0
setblock ~14~38~18 minecraft:stone_block_slab 5
fill ~14~41~18 ~14~42~19 minecraft:stonebrick 0
setblock ~14~43~18 minecraft:cobblestone_wall 0
setblock ~14~44~18 minecraft:stone_brick_stairs 1
fill ~15~1~18 ~16~1~18 minecraft:cobblestone
fill ~15~15~18 ~15~18~18 minecraft:stonebrick 0
setblock ~15~23~18 minecraft:nether_brick_stairs 3
setblock ~15~28~18 minecraft:purpur_stairs 1
fill ~15~37~18 ~15~37~19 minecraft:nether_brick_stairs 1
setblock ~15~39~18 minecraft:stone_brick_stairs 7
setblock ~15~40~18 minecraft:cobblestone_wall 0
setblock ~15~41~18 minecraft:stone_brick_stairs 3
setblock ~15~42~18 minecraft:stone_brick_stairs 7
fill ~15~43~18 ~16~44~18 minecraft:stonebrick 0
fill ~15~45~18 ~15~46~18 minecraft:stonebrick 0
setblock ~15~50~18 minecraft:stone_brick_stairs 1
fill ~15~51~18 ~15~53~18 minecraft:stained_glass_pane 10
setblock ~15~54~18 minecraft:stone_brick_stairs 5
fill ~15~55~18 ~15~55~19 minecraft:stonebrick 0
fill ~15~57~18 ~15~58~20 minecraft:stained_glass_pane 10
setblock ~15~59~18 minecraft:nether_brick
setblock ~15~60~18 minecraft:nether_brick_stairs 2
setblock ~16~2~18 minecraft:purpur_block 0
fill ~16~3~18 ~16~3~19 minecraft:stone 6
fill ~16~5~18 ~16~16~18 minecraft:nether_brick
setblock ~16~17~18 minecraft:nether_brick_stairs 3
setblock ~16~23~18 minecraft:stone_block_slab 7
setblock ~16~41~18 minecraft:stone_brick_stairs 5
setblock ~16~42~18 minecraft:stonebrick 0
setblock ~16~45~18 minecraft:stone_brick_stairs 1
setblock ~16~47~18 minecraft:stone_brick_stairs 5
setblock ~16~48~18 minecraft:stone_brick_stairs 1
setblock ~16~58~18 minecraft:purpur_stairs 7
setblock ~16~59~18 minecraft:purpur_block 0
setblock ~16~60~18 minecraft:purpur_stairs 2
setblock ~17~1~18 minecraft:stone_brick_stairs 6
setblock ~17~2~18 minecraft:cobblestone_wall 0
setblock ~17~3~18 minecraft:stone_brick_stairs 2
fill ~17~4~18 ~18~4~18 minecraft:stonebrick 0
setblock ~17~5~18 minecraft:stone_brick_stairs 5
setblock ~17~6~18 minecraft:stonebrick 0
setblock ~17~7~18 minecraft:stone_brick_stairs 3
setblock ~17~9~18 minecraft:stone_brick_stairs 7
setblock ~17~10~18 minecraft:cobblestone_wall 0
setblock ~17~11~18 minecraft:stone_brick_stairs 3
setblock ~17~13~18 minecraft:stone_brick_stairs 7
setblock ~19~0~18 minecraft:stone_block_slab2 1
setblock ~19~4~18 minecraft:stone_brick_stairs 7
setblock ~20~5~18 minecraft:stone_block_slab2 1
setblock ~26~0~18 minecraft:purpur_stairs 3
setblock ~26~5~18 minecraft:purpur_stairs 7
setblock ~7~0~19 minecraft:cobblestone_wall 0
fill ~7~1~19 ~7~3~19 minecraft:cobblestone_wall 0
setblock ~7~4~19 minecraft:cobblestone_wall 0
setblock ~7~5~19 minecraft:stone_block_slab2 1
setblock ~8~0~19 minecraft:stone_block_slab2 1
setblock ~8~4~19 minecraft:stone_brick_stairs 4
setblock ~9~1~19 minecraft:stone_brick_stairs 0
setblock ~9~3~19 minecraft:stone_brick_stairs 4
setblock ~9~4~19 minecraft:stonebrick 0
setblock ~9~62~19 minecraft:purpur_stairs 4
setblock ~10~2~19 minecraft:glowstone
setblock ~10~5~19 minecraft:stone_brick_stairs 0
setblock ~10~7~19 minecraft:stone_brick_stairs 4
setblock ~10~8~19 minecraft:cobblestone_wall 0
setblock ~10~9~19 minecraft:stone_brick_stairs 0
setblock ~10~11~19 minecraft:stone_brick_stairs 4
setblock ~10~12~19 minecraft:cobblestone_wall 0
setblock ~10~13~19 minecraft:stone_brick_stairs 0
setblock ~10~50~19 minecraft:stone_brick_stairs 4
setblock ~10~60~19 minecraft:purpur_stairs 4
setblock ~10~61~19 minecraft:purpur_block 0
setblock ~10~62~19 minecraft:purpur_stairs 1
setblock ~11~1~19 minecraft:stone 6
setblock ~11~2~19 minecraft:purpur_block 0
setblock ~11~3~19 minecraft:stone 6
fill ~11~5~19 ~11~13~19 minecraft:stonebrick 0
setblock ~11~35~19 minecraft:stone_block_slab 15
setblock ~11~36~19 minecraft:cobblestone_wall 0
setblock ~11~44~19 minecraft:purpur_stairs 7
setblock ~11~45~19 minecraft:purpur_block 0
setblock ~11~46~19 minecraft:purpur_stairs 2
fill ~11~49~19 ~15~49~19 minecraft:stonebrick 0
fill ~11~50~19 ~11~50~21 minecraft:stonebrick 0
fill ~11~51~19 ~11~54~19 minecraft:stonebrick 0
setblock ~11~59~19 minecraft:stained_glass_pane 10
setblock ~11~60~19 minecraft:nether_brick
setblock ~11~61~19 minecraft:purpur_stairs 1
fill ~12~1~19 ~14~1~19 minecraft:cobblestone
setblock ~12~12~19 minecraft:stone_brick_stairs 5
fill ~12~13~19 ~12~15~19 minecraft:stonebrick 0
setblock ~12~16~19 minecraft:stone_brick_stairs 4
setblock ~12~17~19 minecraft:cobblestone_wall 0
setblock ~12~18~19 minecraft:stone_brick_stairs 0
setblock ~12~19~19 minecraft:stone_brick_stairs 4
setblock ~12~20~19 minecraft:stone_brick_stairs 0
setblock ~12~23~19 minecraft:stone_block_slab 15
setblock ~12~33~19 minecraft:nether_brick_stairs 4
setblock ~12~37~19 minecraft:stone_block_slab 15
setblock ~12~38~19 minecraft:stone_block_slab 7
fill ~12~43~19 ~12~48~19 minecraft:stonebrick 0
setblock ~13~13~19 minecraft:stone_brick_stairs 6
setblock ~13~14~19 minecraft:stone_brick_stairs 3
setblock ~13~15~19 minecraft:stone_brick_stairs 7
setblock ~13~16~19 minecraft:stone_brick_stairs 3
setblock ~13~18~19 minecraft:stone_brick_stairs 7
setblock ~13~19~19 minecraft:stone_brick_stairs 3
setblock ~13~20~19 minecraft:stone_brick_stairs 7
setblock ~13~21~19 minecraft:stone_brick_stairs 3
setblock ~13~24~19 minecraft:stone_block_slab 7
setblock ~13~33~19 minecraft:nether_brick_stairs 7
setblock ~13~38~19 minecraft:double_stone_block_slab 7
setblock ~13~41~19 minecraft:stone_brick_stairs 7
setblock ~13~42~19 minecraft:stone_brick_stairs 3
setblock ~13~43~19 minecraft:purpur_block 0
fill ~13~44~19 ~14~48~19 minecraft:stonebrick 0
setblock ~14~12~19 minecraft:stone_brick_stairs 4
fill ~14~13~19 ~15~13~19 minecraft:stonebrick 0
fill ~14~14~19 ~14~15~19 minecraft:stonebrick 0
setblock ~14~16~19 minecraft:stone_brick_stairs 5
setblock ~14~17~19 minecraft:cobblestone_wall 0
setblock ~14~18~19 minecraft:stone_brick_stairs 1
setblock ~14~19~19 minecraft:stone_brick_stairs 5
setblock ~14~20~19 minecraft:stone_brick_stairs 1
setblock ~14~23~19 minecraft:stone_block_slab 15
setblock ~14~33~19 minecraft:nether_brick_stairs 5
setblock ~14~37~19 minecraft:stone_block_slab 15
setblock ~14~38~19 minecraft:stone_block_slab 7
setblock ~14~43~19 minecraft:stonebrick 0
setblock ~15~1~19 minecraft:glowstone
setblock ~15~2~19 minecraft:purpur_block 0
setblock ~15~3~19 minecraft:stone 6
fill ~15~5~19 ~15~12~19 minecraft:stonebrick 0
setblock ~15~35~19 minecraft:stone_block_slab 15
setblock ~15~36~19 minecraft:cobblestone_wall 0
setblock ~15~44~19 minecraft:purpur_stairs 7
setblock ~15~45~19 minecraft:purpur_block 0
setblock ~15~46~19 minecraft:purpur_stairs 2
fill ~15~50~19 ~15~50~21 minecraft:stonebrick 0
fill ~15~51~19 ~15~54~19 minecraft:stonebrick 0
setblock ~15~59~19 minecraft:stained_glass_pane 10
setblock ~15~60~19 minecraft:nether_brick
setblock ~15~61~19 minecraft:purpur_stairs 0
setblock ~16~1~19 minecraft:stone 6
setblock ~16~2~19 minecraft:glowstone
setblock ~16~5~19 minecraft:stone_brick_stairs 1
setblock ~16~7~19 minecraft:stone_brick_stairs 5
setblock ~16~8~19 minecraft:cobblestone_wall 0
setblock ~16~9~19 minecraft:stone_brick_stairs 1
setblock ~16~11~19 minecraft:stone_brick_stairs 5
setblock ~16~12~19 minecraft:cobblestone_wall 0
setblock ~16~13~19 minecraft:stone_brick_stairs 1
setblock ~16~50~19 minecraft:stone_brick_stairs 5
setblock ~16~51~19 minecraft:flower_pot 0
setblock ~16~54~19 minecraft:stone_brick_stairs 6
setblock ~16~60~19 minecraft:purpur_stairs 5
setblock ~16~61~19 minecraft:purpur_block 0
setblock ~16~62~19 minecraft:purpur_stairs 0
setblock ~17~1~19 minecraft:stone_brick_stairs 1
setblock ~17~3~19 minecraft:stone_brick_stairs 5
setblock ~17~4~19 minecraft:stonebrick 0
setblock ~17~62~19 minecraft:purpur_stairs 5
setblock ~18~0~19 minecraft:stone_block_slab2 1
setblock ~18~4~19 minecraft:stone_brick_stairs 5
setblock ~19~0~19 minecraft:cobblestone_wall 0
fill ~19~1~19 ~19~3~19 minecraft:cobblestone_wall 0
setblock ~19~4~19 minecraft:cobblestone_wall 0
setblock ~19~5~19 minecraft:stone_block_slab2 1
setblock ~8~5~20 minecraft:stone_block_slab2 1
setblock ~9~0~20 minecraft:stone_block_slab2 1
setblock ~9~1~20 minecraft:stone_brick_stairs 7
setblock ~9~2~20 minecraft:cobblestone_wall 0
setblock ~9~3~20 minecraft:stone_brick_stairs 3
setblock ~9~4~20 minecraft:stone_block_slab 13
setblock ~10~0~20 minecraft:stone_brick_stairs 7
setblock ~10~1~20 minecraft:stone_brick_stairs 3
setblock ~10~3~20 minecraft:stone_brick_stairs 7
fill ~10~4~20 ~11~4~20 minecraft:stonebrick 0
setblock ~10~47~20 minecraft:wooden_button 4
fill ~10~50~20 ~10~54~20 minecraft:log 1
setblock ~10~58~20 minecraft:purpur_stairs 6
setblock ~10~59~20 minecraft:purpur_block 0
setblock ~10~60~20 minecraft:purpur_stairs 3
setblock ~11~1~20 minecraft:stone_brick_stairs 7
setblock ~11~2~20 minecraft:cobblestone_wall 0
setblock ~11~3~20 minecraft:stone_brick_stairs 3
setblock ~11~8~20 minecraft:stone_brick_stairs 4
fill ~11~12~20 ~11~12~21 minecraft:purpur_stairs 0
setblock ~11~46~20 minecraft:purpur_stairs 7
fill ~11~47~20 ~11~49~20 minecraft:purpur_block 0
setblock ~11~51~20 minecraft:stone_brick_stairs 5
setblock ~11~59~20 minecraft:nether_brick
setblock ~11~60~20 minecraft:nether_brick_stairs 3
setblock ~12~1~20 minecraft:cobblestone_wall 0
setblock ~12~2~20 minecraft:stone_brick_stairs 3
setblock ~12~3~20 minecraft:stone_brick_stairs 7
setblock ~12~5~20 minecraft:stone_brick_stairs 3
setblock ~12~6~20 minecraft:stone_brick_stairs 7
fill ~12~7~20 ~12~12~20 minecraft:stonebrick 0
setblock ~12~13~20 minecraft:stone_block_slab 5
fill ~12~48~20 ~14~49~20 minecraft:stonebrick 0
fill ~13~1~20 ~13~3~20 minecraft:stone 6
fill ~13~4~20 ~13~4~21 minecraft:stonebrick 0
setblock ~13~5~20 minecraft:stone_brick_stairs 7
setblock ~13~6~20 minecraft:stone_brick_stairs 3
fill ~13~7~20 ~13~11~20 minecraft:stained_glass_pane 2
setblock ~13~12~20 minecraft:stone_brick_stairs 7
setblock ~13~13~20 minecraft:double_stone_block_slab 5
setblock ~13~43~20 minecraft:purpur_stairs 7
fill ~13~44~20 ~13~45~20 minecraft:purpur_block 0
setblock ~13~46~20 minecraft:purpur_stairs 2
setblock ~13~66~20 minecraft:purpur_stairs 2
setblock ~14~1~20 minecraft:cobblestone_wall 0
setblock ~14~2~20 minecraft:stone_brick_stairs 3
setblock ~14~3~20 minecraft:stone_brick_stairs 7
setblock ~14~5~20 minecraft:stone_brick_stairs 3
setblock ~14~6~20 minecraft:stone_brick_stairs 7
fill ~14~7~20 ~14~12~20 minecraft:stonebrick 0
setblock ~14~13~20 minecraft:stone_block_slab 5
setblock ~15~1~20 minecraft:stone_brick_stairs 7
setblock ~15~2~20 minecraft:cobblestone_wall 0
