fill ~1~0~1 ~17~0~17 minecraft:dirt 0
fill ~1~1~1 ~0~1~2 minecraft:grass
fill ~1~1~1 ~17~1~15 minecraft:dirt 0
fill ~1~2~1 ~3~2~2 minecraft:grass
fill ~4~2~1 ~17~2~15 minecraft:dirt 0
fill ~4~3~1 ~7~3~3 minecraft:grass
fill ~8~3~1 ~17~3~15 minecraft:dirt 0
fill ~8~4~1 ~13~4~5 minecraft:grass
fill ~14~4~1 ~17~4~15 minecraft:dirt 0
fill ~14~5~1 ~21~5~15 minecraft:grass
fill ~15~6~1 ~19~6~2 minecraft:tallgrass 0
fill ~18~0~1 ~84~0~2 minecraft:stone 0
fill ~18~1~1 ~79~1~4 minecraft:stone 0
fill ~18~2~1 ~76~2~4 minecraft:stone 0
fill ~18~3~1 ~72~3~2 minecraft:stone 0
fill ~18~4~1 ~67~4~5 minecraft:stone 0
setblock ~22~5~1 minecraft:wool 0
fill ~23~5~1 ~27~5~1 minecraft:wool 15
fill ~28~5~1 ~29~5~1 minecraft:wool 0
fill ~30~5~1 ~68~5~1 minecraft:grass
fill ~31~23~1 ~51~23~1 minecraft:quartz_stairs 6
fill ~47~6~1 ~49~6~1 minecraft:tallgrass 0
setblock ~50~6~1 minecraft:yellow_flower
fill ~52~23~1 ~52~23~14 minecraft:quartz_stairs 5
fill ~58~6~1 ~61~6~1 minecraft:tallgrass 0
setblock ~63~6~1 minecraft:tallgrass 0
fill ~66~6~1 ~68~6~1 minecraft:tallgrass 0
fill ~68~4~1 ~68~4~2 minecraft:dirt 0
fill ~69~4~1 ~72~4~2 minecraft:grass
fill ~69~5~1 ~70~5~1 minecraft:tallgrass 0
fill ~73~3~1 ~76~3~2 minecraft:grass
fill ~77~2~1 ~80~2~2 minecraft:grass
setblock ~78~3~1 minecraft:tallgrass 0
fill ~80~1~1 ~80~1~2 minecraft:dirt 0
setblock ~80~3~1 minecraft:tallgrass 0
fill ~81~1~1 ~84~1~2 minecraft:grass
fill ~85~0~1 ~85~0~2 minecraft:grass
setblock ~2~3~2 minecraft:tallgrass 0
setblock ~14~6~2 minecraft:tallgrass 0
fill ~22~5~2 ~22~5~15 minecraft:grass
fill ~23~5~2 ~23~5~3 minecraft:wool 0
fill ~24~5~2 ~29~5~3 minecraft:wool 15
fill ~30~5~2 ~31~5~2 minecraft:wool 0
fill ~31~23~2 ~31~23~14 minecraft:quartz_stairs 4
fill ~32~5~2 ~51~5~2 minecraft:quartz_block 0
setblock ~32~6~2 minecraft:quartz_block 1
fill ~32~7~2 ~32~19~2 minecraft:quartz_block 2
fill ~32~20~2 ~32~21~2 minecraft:quartz_block 1
fill ~32~22~2 ~51~22~17 minecraft:quartz_block 0
fill ~32~23~2 ~51~23~4 minecraft:quartz_block 0
fill ~32~24~2 ~51~24~2 minecraft:quartz_block 0
setblock ~32~25~2 minecraft:wool 7
fill ~33~6~2 ~37~6~2 minecraft:anvil 1
setblock ~33~20~2 minecraft:quartz_stairs 5
fill ~33~21~2 ~50~21~2 minecraft:quartz_block 2
fill ~33~25~2 ~37~25~2 minecraft:anvil 3
fill ~34~20~2 ~36~20~2 minecraft:stone_block_slab 14
setblock ~37~20~2 minecraft:quartz_stairs 4
setblock ~38~6~2 minecraft:quartz_block 1
fill ~38~7~2 ~38~19~2 minecraft:quartz_block 2
setblock ~38~20~2 minecraft:quartz_block 1
setblock ~38~25~2 minecraft:wool 7
fill ~39~6~2 ~44~6~2 minecraft:anvil 1
setblock ~39~20~2 minecraft:quartz_stairs 5
fill ~39~25~2 ~44~25~2 minecraft:anvil 3
fill ~40~20~2 ~43~20~2 minecraft:stone_block_slab 14
setblock ~44~20~2 minecraft:quartz_stairs 4
setblock ~45~6~2 minecraft:quartz_block 1
fill ~45~7~2 ~45~19~2 minecraft:quartz_block 2
setblock ~45~20~2 minecraft:quartz_block 1
setblock ~45~25~2 minecraft:wool 7
fill ~46~6~2 ~50~6~2 minecraft:anvil 1
setblock ~46~20~2 minecraft:quartz_stairs 5
fill ~46~25~2 ~50~25~2 minecraft:anvil 3
fill ~47~20~2 ~49~20~2 minecraft:stone_block_slab 14
setblock ~50~20~2 minecraft:quartz_stairs 4
setblock ~51~6~2 minecraft:quartz_block 1
fill ~51~7~2 ~51~19~2 minecraft:quartz_block 2
fill ~51~20~2 ~51~21~2 minecraft:quartz_block 1
setblock ~51~25~2 minecraft:wool 7
fill ~52~5~2 ~57~5~2 minecraft:wool 0
fill ~58~5~2 ~68~5~2 minecraft:grass
fill ~60~6~2 ~61~6~2 minecraft:tallgrass 0
setblock ~67~6~2 minecraft:tallgrass 0
setblock ~69~5~2 minecraft:red_flower 3
fill ~0~1~3 ~0~1~54 minecraft:dirt 0
fill ~0~2~3 ~2~2~6 minecraft:grass
fill ~1~3~3 ~1~3~5 minecraft:tallgrass 0
fill ~3~2~3 ~3~2~54 minecraft:dirt 0
fill ~3~3~3 ~3~3~13 minecraft:grass
fill ~15~6~3 ~18~6~3 minecraft:tallgrass 0
fill ~18~0~3 ~80~0~3 minecraft:stone 0
fill ~18~3~3 ~71~3~5 minecraft:stone 0
fill ~30~5~3 ~57~5~6 minecraft:wool 15
setblock ~32~20~3 minecraft:quartz_stairs 7
fill ~32~21~3 ~32~21~15 minecraft:quartz_block 2
fill ~32~24~3 ~32~24~16 minecraft:quartz_block 0
fill ~32~25~3 ~32~25~6 minecraft:anvil 2
fill ~33~24~3 ~33~24~17 minecraft:quartz_stairs 1
fill ~34~24~3 ~49~24~3 minecraft:quartz_stairs 3
setblock ~39~6~3 minecraft:stone_button 2
setblock ~43~6~3 minecraft:stone_button 2
fill ~50~24~3 ~50~24~17 minecraft:quartz_stairs 0
setblock ~51~20~3 minecraft:quartz_stairs 7
fill ~51~21~3 ~51~21~15 minecraft:quartz_block 2
fill ~51~24~3 ~51~24~16 minecraft:quartz_block 0
fill ~51~25~3 ~51~25~6 minecraft:anvil 0
fill ~58~5~3 ~68~5~3 minecraft:wool 0
fill ~68~4~3 ~72~4~3 minecraft:wool 0
fill ~72~3~3 ~76~3~3 minecraft:wool 0
fill ~77~2~3 ~80~2~3 minecraft:wool 0
fill ~80~1~3 ~84~1~3 minecraft:wool 0
fill ~81~0~3 ~85~0~3 minecraft:wool 0
fill ~0~3~4 ~0~3~5 minecraft:tallgrass 0
fill ~4~3~4 ~6~3~7 minecraft:grass
fill ~7~3~4 ~7~3~15 minecraft:dirt 0
fill ~7~4~4 ~7~4~15 minecraft:grass
setblock ~14~6~4 minecraft:tallgrass 0
setblock ~16~6~4 minecraft:tallgrass 0
fill ~18~0~4 ~79~0~6 minecraft:stone 0
setblock ~19~6~4 minecraft:red_flower 0
fill ~23~5~4 ~23~5~15 minecraft:grass
setblock ~24~5~4 minecraft:wool 0
fill ~25~5~4 ~29~5~4 minecraft:wool 15
fill ~32~20~4 ~32~20~5 minecraft:stone_block_slab 14
setblock ~38~6~4 minecraft:quartz_stairs 4
fill ~38~7~4 ~39~7~4 minecraft:stone_block_slab 6
setblock ~39~6~4 minecraft:coal_block
fill ~40~6~4 ~41~6~4 minecraft:stone_block_slab 6
setblock ~40~7~4 minecraft:stone_block_slab 14
fill ~40~8~4 ~40~8~6 minecraft:glass_pane
fill ~41~7~4 ~42~7~4 minecraft:wall_sign 2
setblock ~42~6~4 minecraft:stone_block_slab 14
setblock ~43~6~4 minecraft:coal_block
setblock ~43~7~4 minecraft:stone_block_slab 6
fill ~51~20~4 ~51~20~5 minecraft:stone_block_slab 14
fill ~58~5~4 ~68~5~6 minecraft:wool 15
fill ~68~4~4 ~72~4~6 minecraft:wool 15
fill ~73~3~4 ~76~3~6 minecraft:wool 15
fill ~77~2~4 ~80~2~6 minecraft:wool 15
setblock ~80~0~4 minecraft:wool 0
fill ~80~1~4 ~84~1~6 minecraft:wool 15
fill ~81~0~4 ~85~0~6 minecraft:wool 15
fill ~2~3~5 ~2~3~6 minecraft:tallgrass 0
setblock ~12~5~5 minecraft:tallgrass 0
setblock ~17~6~5 minecraft:tallgrass 0
fill ~18~1~5 ~40~2~5 minecraft:stone 0
fill ~24~5~5 ~24~5~15 minecraft:grass
fill ~25~5~5 ~26~5~5 minecraft:wool 0
fill ~27~5~5 ~29~5~5 minecraft:wool 15
fill ~32~23~5 ~34~23~20 minecraft:quartz_block 0
fill ~35~24~5 ~48~24~7 minecraft:clay
setblock ~38~6~5 minecraft:wooden_slab 11
setblock ~38~7~5 minecraft:double_wooden_slab 3
setblock ~39~6~5 minecraft:double_stone_block_slab 6
fill ~40~6~5 ~42~6~5 minecraft:wooden_slab 11
fill ~40~7~5 ~42~7~5 minecraft:double_wooden_slab 3
fill ~41~2~5 ~42~2~6 minecraft:stone_block_slab 8
setblock ~42~8~5 minecraft:lever 6
fill ~43~1~5 ~79~1~5 minecraft:stone 0
fill ~43~2~5 ~76~2~5 minecraft:stone 0
setblock ~43~7~5 minecraft:ladder 5
fill ~49~23~5 ~51~23~20 minecraft:quartz_block 0
fill ~80~0~5 ~80~0~7 minecraft:wool 15
fill ~8~4~6 ~12~4~10 minecraft:grass
fill ~13~4~6 ~13~4~15 minecraft:dirt 0
fill ~13~5~6 ~13~5~15 minecraft:grass
fill ~18~1~6 ~37~4~6 minecraft:stone 0
setblock ~24~6~6 minecraft:tallgrass 0
fill ~25~5~6 ~26~5~15 minecraft:grass
fill ~27~5~6 ~28~5~6 minecraft:wool 0
setblock ~29~5~6 minecraft:wool 15
setblock ~32~20~6 minecraft:quartz_stairs 6
fill ~38~1~6 ~39~4~6 minecraft:stained_hardened_clay 14
setblock ~38~6~6 minecraft:quartz_stairs 4
fill ~38~7~6 ~39~7~6 minecraft:stone_block_slab 6
setblock ~39~6~6 minecraft:coal_block
fill ~40~1~6 ~40~3~6 minecraft:stone 0
fill ~40~6~6 ~41~6~6 minecraft:stone_block_slab 6
setblock ~40~7~6 minecraft:stone_block_slab 14
fill ~41~1~6 ~42~1~6 minecraft:flower_pot 0
fill ~41~3~6 ~43~3~6 minecraft:stone 0
fill ~41~4~6 ~45~4~6 minecraft:stained_hardened_clay 14
fill ~41~7~6 ~42~7~6 minecraft:wall_sign 3
setblock ~42~6~6 minecraft:stone_block_slab 14
fill ~43~1~6 ~43~2~6 minecraft:stone 0
setblock ~43~6~6 minecraft:coal_block
setblock ~43~7~6 minecraft:stone_block_slab 6
fill ~44~1~6 ~45~3~6 minecraft:stained_hardened_clay 14
fill ~46~1~6 ~79~1~6 minecraft:stone 0
fill ~46~2~6 ~76~2~6 minecraft:stone 0
fill ~46~3~6 ~71~3~6 minecraft:stone 0
fill ~46~4~6 ~67~4~6 minecraft:stone 0
setblock ~51~20~6 minecraft:quartz_stairs 6
fill ~0~2~7 ~1~2~9 minecraft:grass
fill ~2~2~7 ~2~2~54 minecraft:dirt 0
fill ~2~3~7 ~2~3~14 minecraft:grass
fill ~8~5~7 ~11~5~7 minecraft:tallgrass 0
fill ~18~0~7 ~37~0~7 minecraft:stone 0
fill ~18~1~7 ~36~4~7 minecraft:stone 0
setblock ~26~6~7 minecraft:tallgrass 0
fill ~27~5~7 ~28~5~15 minecraft:grass
fill ~29~5~7 ~31~5~7 minecraft:wool 0
fill ~32~5~7 ~32~5~58 minecraft:quartz_block 0
setblock ~32~6~7 minecraft:quartz_block 1
fill ~32~7~7 ~32~19~7 minecraft:quartz_block 2
setblock ~32~20~7 minecraft:quartz_block 1
setblock ~32~25~7 minecraft:wool 7
fill ~33~5~7 ~50~5~7 minecraft:wool 0
fill ~37~1~7 ~37~4~20 minecraft:stained_hardened_clay 14
fill ~38~0~7 ~39~0~19 minecraft:stained_hardened_clay 11
setblock ~39~3~7 minecraft:torch 3
setblock ~39~6~7 minecraft:stone_button 3
fill ~40~0~7 ~40~0~19 minecraft:stone_block_slab 7
fill ~41~0~7 ~42~0~20 minecraft:double_wooden_slab 4
fill ~43~0~7 ~43~0~19 minecraft:stone_block_slab 7
setblock ~43~6~7 minecraft:stone_button 3
fill ~44~0~7 ~45~0~19 minecraft:stained_hardened_clay 11
setblock ~44~3~7 minecraft:torch 3
fill ~45~1~7 ~45~1~18 minecraft:stone_block_slab 6
fill ~46~0~7 ~79~0~7 minecraft:stone 0
fill ~46~1~7 ~46~4~19 minecraft:stained_hardened_clay 14
fill ~47~1~7 ~79~1~7 minecraft:stone 0
fill ~47~2~7 ~76~2~15 minecraft:stone 0
fill ~47~3~7 ~71~3~15 minecraft:stone 0
fill ~47~4~7 ~67~4~15 minecraft:stone 0
fill ~51~5~7 ~51~5~58 minecraft:quartz_block 0
setblock ~51~6~7 minecraft:quartz_block 1
fill ~51~7~7 ~51~19~7 minecraft:quartz_block 2
setblock ~51~20~7 minecraft:quartz_block 1
setblock ~51~25~7 minecraft:wool 7
fill ~52~5~7 ~68~5~7 minecraft:wool 0
fill ~68~4~7 ~72~4~7 minecraft:wool 0
fill ~73~3~7 ~76~3~7 minecraft:wool 0
fill ~77~2~7 ~80~2~7 minecraft:wool 0
setblock ~80~1~7 minecraft:wool 15
fill ~81~0~7 ~85~0~7 minecraft:wool 0
fill ~81~1~7 ~84~1~7 minecraft:wool 0
fill ~4~3~8 ~5~3~10 minecraft:grass
fill ~6~3~8 ~6~3~15 minecraft:dirt 0
fill ~6~4~8 ~6~4~15 minecraft:grass
fill ~6~5~8 ~9~5~8 minecraft:tallgrass 0
setblock ~11~5~8 minecraft:tallgrass 0
fill ~18~0~8 ~18~0~17 minecraft:dirt 0
fill ~18~1~8 ~18~4~15 minecraft:dirt 0
fill ~19~0~8 ~37~0~15 minecraft:stone 0
fill ~19~1~8 ~36~4~15 minecraft:stone 0
fill ~23~6~8 ~24~6~11 minecraft:tallgrass 0
fill ~29~5~8 ~31~5~15 minecraft:grass
fill ~32~6~8 ~32~6~9 minecraft:anvil 0
setblock ~32~20~8 minecraft:quartz_stairs 7
fill ~32~25~8 ~32~25~9 minecraft:anvil 2
fill ~33~5~8 ~50~5~43 minecraft:quartz_block 0
fill ~35~24~8 ~37~24~19 minecraft:clay
fill ~38~25~8 ~45~25~10 minecraft:clay
fill ~46~0~8 ~78~0~12 minecraft:stone 0
fill ~46~24~8 ~48~24~19 minecraft:clay
fill ~47~1~8 ~78~1~15 minecraft:stone 0
fill ~51~6~8 ~51~6~9 minecraft:anvil 0
setblock ~51~20~8 minecraft:quartz_stairs 7
fill ~51~25~8 ~51~25~9 minecraft:anvil 0
fill ~52~5~8 ~68~5~15 minecraft:grass
setblock ~61~6~8 minecraft:red_flower 8
fill ~62~6~8 ~63~6~10 minecraft:tallgrass 0
setblock ~64~6~8 minecraft:red_flower 0
fill ~68~4~8 ~68~4~11 minecraft:dirt 0
fill ~69~4~8 ~72~4~10 minecraft:grass
fill ~72~3~8 ~72~3~15 minecraft:stone 0
fill ~73~3~8 ~76~3~9 minecraft:grass
fill ~78~2~8 ~80~2~10 minecraft:grass
fill ~79~0~8 ~84~0~24 minecraft:dirt 0
fill ~79~1~8 ~80~1~10 minecraft:dirt 0
fill ~81~1~8 ~84~1~8 minecraft:grass
setblock ~85~0~8 minecraft:grass
fill ~2~4~9 ~4~4~9 minecraft:tallgrass 0
fill ~8~5~9 ~9~5~9 minecraft:tallgrass 0
setblock ~22~6~9 minecraft:tallgrass 0
setblock ~25~6~9 minecraft:yellow_flower
fill ~26~6~9 ~27~6~9 minecraft:tallgrass 0
setblock ~32~20~9 minecraft:quartz_stairs 6
setblock ~51~20~9 minecraft:quartz_stairs 6
setblock ~55~6~9 minecraft:tallgrass 0
setblock ~57~6~9 minecraft:tallgrass 0
fill ~59~6~9 ~61~6~9 minecraft:tallgrass 0
fill ~64~6~9 ~64~6~13 minecraft:tallgrass 0
setblock ~77~2~9 minecraft:grass
fill ~81~1~9 ~81~1~10 minecraft:dirt 0
fill ~81~2~9 ~81~2~12 minecraft:grass
fill ~82~1~9 ~85~1~10 minecraft:grass
fill ~85~0~9 ~85~0~24 minecraft:dirt 0
fill ~0~2~10 ~0~2~12 minecraft:grass
fill ~1~2~10 ~1~2~53 minecraft:dirt 0
fill ~1~3~10 ~1~3~16 minecraft:grass
fill ~1~4~10 ~2~4~10 minecraft:tallgrass 0
setblock ~6~5~10 minecraft:red_flower 0
setblock ~8~5~10 minecraft:tallgrass 0
setblock ~9~5~10 minecraft:yellow_flower
fill ~25~6~10 ~26~6~11 minecraft:tallgrass 0
setblock ~32~6~10 minecraft:quartz_block 1
fill ~32~7~10 ~32~19~10 minecraft:quartz_block 2
setblock ~32~20~10 minecraft:quartz_block 1
setblock ~32~25~10 minecraft:wool 7
setblock ~38~3~10 minecraft:torch 1
setblock ~45~3~10 minecraft:torch 2
setblock ~51~6~10 minecraft:quartz_block 1
fill ~51~7~10 ~51~19~10 minecraft:quartz_block 2
setblock ~51~20~10 minecraft:quartz_block 1
setblock ~51~25~10 minecraft:wool 7
fill ~53~6~10 ~54~6~13 minecraft:tallgrass 0
fill ~60~6~10 ~61~6~10 minecraft:tallgrass 0
setblock ~66~6~10 minecraft:tallgrass 0
setblock ~68~6~10 minecraft:red_flower 0
fill ~73~3~10 ~73~3~15 minecraft:stone 0
fill ~73~4~10 ~73~4~14 minecraft:grass
fill ~74~3~10 ~77~3~11 minecraft:grass
fill ~77~2~10 ~77~2~15 minecraft:stone 0
setblock ~77~4~10 minecraft:tallgrass 0
setblock ~82~2~10 minecraft:tallgrass 0
fill ~85~2~10 ~85~2~13 minecraft:tallgrass 0
setblock ~1~4~11 minecraft:yellow_flower
setblock ~2~4~11 minecraft:tallgrass 0
fill ~4~3~11 ~4~3~12 minecraft:grass
fill ~5~3~11 ~5~3~15 minecraft:dirt 0
fill ~5~4~11 ~5~4~15 minecraft:grass
setblock ~7~5~11 minecraft:tallgrass 0
fill ~8~4~11 ~11~4~12 minecraft:grass
fill ~9~5~11 ~10~5~11 minecraft:tallgrass 0
fill ~12~4~11 ~12~4~15 minecraft:dirt 0
fill ~12~5~11 ~12~5~15 minecraft:grass
fill ~32~6~11 ~32~6~14 minecraft:anvil 0
setblock ~32~20~11 minecraft:quartz_stairs 7
fill ~32~25~11 ~32~25~14 minecraft:anvil 2
fill ~38~25~11 ~40~25~19 minecraft:clay
fill ~41~26~11 ~42~26~49 minecraft:clay
fill ~43~25~11 ~45~25~19 minecraft:clay
fill ~51~6~11 ~51~6~14 minecraft:anvil 0
setblock ~51~20~11 minecraft:quartz_stairs 7
fill ~51~25~11 ~51~25~14 minecraft:anvil 0
fill ~55~6~11 ~55~6~13 minecraft:tallgrass 0
setblock ~56~6~11 minecraft:red_flower 0
setblock ~60~6~11 minecraft:tallgrass 0
fill ~63~6~11 ~63~6~12 minecraft:tallgrass 0
setblock ~69~4~11 minecraft:dirt 0
fill ~69~5~11 ~69~5~15 minecraft:grass
setblock ~69~6~11 minecraft:tallgrass 0
fill ~70~4~11 ~72~4~12 minecraft:grass
setblock ~73~5~11 minecraft:tallgrass 0
fill ~74~4~11 ~75~4~11 minecraft:tallgrass 0
setblock ~76~4~11 minecraft:yellow_flower
fill ~78~2~11 ~78~2~15 minecraft:stone 0
fill ~78~3~11 ~78~3~13 minecraft:grass
fill ~79~1~11 ~81~1~15 minecraft:stone 0
fill ~79~2~11 ~80~2~11 minecraft:grass
setblock ~82~1~11 minecraft:dirt 0
fill ~82~2~11 ~82~2~13 minecraft:grass
fill ~83~1~11 ~85~1~11 minecraft:grass
setblock ~0~3~12 minecraft:tallgrass 0
fill ~1~4~12 ~1~4~13 minecraft:tallgrass 0
setblock ~2~4~12 minecraft:red_flower 0
setblock ~3~4~12 minecraft:tallgrass 0
setblock ~6~5~12 minecraft:tallgrass 0
setblock ~10~5~12 minecraft:tallgrass 0
setblock ~22~6~12 minecraft:tallgrass 0
setblock ~24~6~12 minecraft:tallgrass 0
fill ~32~20~12 ~32~20~13 minecraft:stone_block_slab 14
fill ~51~20~12 ~51~20~13 minecraft:stone_block_slab 14
setblock ~52~6~12 minecraft:tallgrass 0
fill ~56~6~12 ~57~6~12 minecraft:tallgrass 0
fill ~67~6~12 ~68~6~14 minecraft:tallgrass 0
fill ~68~4~12 ~69~4~15 minecraft:stone 0
fill ~74~3~12 ~75~3~15 minecraft:stone 0
fill ~74~4~12 ~75~4~15 minecraft:grass
fill ~74~5~12 ~75~5~13 minecraft:tallgrass 0
fill ~76~3~12 ~77~3~12 minecraft:grass
fill ~79~2~12 ~80~2~15 minecraft:stone 0
fill ~79~3~12 ~80~3~13 minecraft:grass
fill ~82~1~12 ~82~1~52 minecraft:stone 0
setblock ~83~1~12 minecraft:dirt 0
fill ~83~2~12 ~83~2~15 minecraft:grass
setblock ~83~3~12 minecraft:tallgrass 0
fill ~84~1~12 ~85~1~12 minecraft:grass
fill ~0~2~13 ~0~2~51 minecraft:dirt 0
fill ~0~3~13 ~0~3~19 minecraft:grass
setblock ~2~4~13 minecraft:tallgrass 0
fill ~4~3~13 ~4~3~51 minecraft:dirt 0
fill ~4~4~13 ~4~4~51 minecraft:grass
fill ~8~4~13 ~10~4~13 minecraft:grass
fill ~11~4~13 ~11~4~15 minecraft:dirt 0
fill ~11~5~13 ~11~5~15 minecraft:grass
fill ~46~0~13 ~67~0~15 minecraft:stone 0
setblock ~56~6~13 minecraft:red_flower 8
setblock ~59~6~13 minecraft:tallgrass 0
setblock ~62~6~13 minecraft:tallgrass 0
setblock ~66~6~13 minecraft:red_flower 8
fill ~68~0~13 ~68~0~17 minecraft:dirt 0
fill ~69~0~13 ~70~0~17 minecraft:stone 0
fill ~69~6~13 ~70~6~14 minecraft:tallgrass 0
fill ~70~4~13 ~70~4~15 minecraft:stone 0
fill ~70~5~13 ~70~5~15 minecraft:grass
fill ~71~0~13 ~78~0~17 minecraft:dirt 0
fill ~71~4~13 ~72~4~13 minecraft:grass
fill ~76~3~13 ~77~3~15 minecraft:stone 0
fill ~76~4~13 ~77~4~15 minecraft:grass
setblock ~76~5~13 minecraft:tallgrass 0
fill ~81~2~13 ~81~2~52 minecraft:stone 0
fill ~81~3~13 ~81~3~15 minecraft:grass
fill ~83~1~13 ~84~1~52 minecraft:stone 0
fill ~84~2~13 ~84~2~17 minecraft:grass
setblock ~84~3~13 minecraft:tallgrass 0
setblock ~85~1~13 minecraft:grass
fill ~3~3~14 ~3~3~51 minecraft:dirt 0
fill ~3~4~14 ~3~4~51 minecraft:grass
fill ~8~4~14 ~9~4~14 minecraft:grass
fill ~10~4~14 ~10~4~15 minecraft:dirt 0
fill ~10~5~14 ~10~5~15 minecraft:grass
setblock ~21~6~14 minecraft:tallgrass 0
setblock ~32~20~14 minecraft:quartz_stairs 6
setblock ~51~20~14 minecraft:quartz_stairs 6
setblock ~53~6~14 minecraft:red_flower 3
setblock ~54~6~14 minecraft:tallgrass 0
setblock ~56~6~14 minecraft:tallgrass 0
setblock ~66~6~14 minecraft:tallgrass 0
fill ~71~4~14 ~71~4~15 minecraft:stone 0
fill ~71~5~14 ~71~5~15 minecraft:grass
setblock ~72~4~14 minecraft:grass
setblock ~73~5~14 minecraft:yellow_flower
setblock ~75~5~14 minecraft:tallgrass 0
fill ~78~3~14 ~79~3~15 minecraft:stone 0
fill ~78~4~14 ~79~4~15 minecraft:grass
setblock ~80~3~14 minecraft:grass
fill ~82~2~14 ~82~2~52 minecraft:stone 0
fill ~82~3~14 ~82~3~17 minecraft:grass
fill ~83~3~14 ~84~3~14 minecraft:red_flower 0
setblock ~85~1~14 minecraft:dirt 0
fill ~85~2~14 ~85~2~19 minecraft:grass
fill ~85~3~14 ~85~3~16 minecraft:tallgrass 0
fill ~2~3~15 ~2~3~30 minecraft:dirt 0
fill ~2~4~15 ~2~4~30 minecraft:grass
fill ~4~23~15 ~4~23~53 minecraft:quartz_stairs 4
fill ~5~23~15 ~31~23~15 minecraft:quartz_stairs 6
setblock ~8~4~15 minecraft:grass
setblock ~8~12~15 minecraft:quartz_stairs 6
setblock ~8~13~15 minecraft:stone_block_slab 6
setblock ~9~4~15 minecraft:dirt 0
setblock ~9~5~15 minecraft:grass
fill ~9~13~15 ~10~13~15 minecraft:stone_block_slab 14
setblock ~11~12~15 minecraft:quartz_stairs 6
setblock ~11~13~15 minecraft:stone_block_slab 6
setblock ~14~12~15 minecraft:quartz_stairs 6
setblock ~14~13~15 minecraft:quartz_stairs 0
fill ~15~13~15 ~16~13~15 minecraft:stone_block_slab 14
setblock ~17~12~15 minecraft:quartz_stairs 6
setblock ~17~13~15 minecraft:quartz_stairs 1
setblock ~20~12~15 minecraft:quartz_stairs 6
setblock ~20~13~15 minecraft:stone_block_slab 6
fill ~21~13~15 ~22~13~15 minecraft:stone_block_slab 14
setblock ~23~12~15 minecraft:quartz_stairs 6
setblock ~23~13~15 minecraft:stone_block_slab 6
setblock ~26~12~15 minecraft:quartz_stairs 6
setblock ~26~13~15 minecraft:quartz_stairs 0
fill ~27~13~15 ~28~13~15 minecraft:stone_block_slab 14
setblock ~29~12~15 minecraft:quartz_stairs 6
setblock ~29~13~15 minecraft:quartz_stairs 1
setblock ~32~6~15 minecraft:quartz_block 1
fill ~32~7~15 ~32~19~15 minecraft:quartz_block 2
setblock ~32~20~15 minecraft:quartz_block 1
fill ~32~25~15 ~32~25~16 minecraft:wool 7
fill ~33~21~15 ~50~21~17 minecraft:quartz_block 2
setblock ~34~12~15 minecraft:quartz_stairs 6
setblock ~34~13~15 minecraft:quartz_stairs 0
fill ~35~13~15 ~36~13~15 minecraft:stone_block_slab 14
setblock ~37~12~15 minecraft:quartz_stairs 6
setblock ~37~13~15 minecraft:quartz_stairs 1
setblock ~39~6~15 minecraft:quartz_block 1
fill ~39~7~15 ~39~9~15 minecraft:quartz_block 2
setblock ~39~10~15 minecraft:quartz_block 1
setblock ~39~11~15 minecraft:quartz_stairs 6
fill ~39~12~15 ~40~12~15 minecraft:quartz_block 2
setblock ~39~13~15 minecraft:stone_block_slab 6
setblock ~40~10~15 minecraft:quartz_stairs 6
setblock ~40~11~15 minecraft:quartz_block 2
setblock ~40~13~15 minecraft:quartz_stairs 0
fill ~41~11~15 ~42~11~15 minecraft:quartz_stairs 6
fill ~41~13~15 ~41~13~17 minecraft:quartz_stairs 5
fill ~41~14~15 ~42~14~15 minecraft:stone_block_slab 6
fill ~42~13~15 ~42~13~17 minecraft:quartz_stairs 4
setblock ~43~10~15 minecraft:quartz_stairs 6
fill ~43~11~15 ~43~12~15 minecraft:quartz_block 2
setblock ~43~13~15 minecraft:quartz_stairs 1
setblock ~44~6~15 minecraft:quartz_block 1
fill ~44~7~15 ~44~9~15 minecraft:quartz_block 2
setblock ~44~10~15 minecraft:quartz_block 1
setblock ~44~11~15 minecraft:quartz_stairs 6
setblock ~44~12~15 minecraft:quartz_block 2
setblock ~44~13~15 minecraft:stone_block_slab 6
setblock ~46~12~15 minecraft:quartz_stairs 6
setblock ~46~13~15 minecraft:quartz_stairs 0
fill ~47~13~15 ~48~13~15 minecraft:stone_block_slab 14
setblock ~49~12~15 minecraft:quartz_stairs 6
setblock ~49~13~15 minecraft:quartz_stairs 1
setblock ~51~6~15 minecraft:quartz_block 1
fill ~51~7~15 ~51~19~15 minecraft:quartz_block 2
setblock ~51~20~15 minecraft:quartz_block 1
fill ~51~25~15 ~51~25~16 minecraft:wool 7
fill ~52~23~15 ~78~23~15 minecraft:quartz_stairs 6
setblock ~54~12~15 minecraft:quartz_stairs 6
setblock ~54~13~15 minecraft:stone_block_slab 6
fill ~55~13~15 ~56~13~15 minecraft:stone_block_slab 14
setblock ~57~12~15 minecraft:quartz_stairs 6
setblock ~57~13~15 minecraft:stone_block_slab 6
setblock ~60~12~15 minecraft:quartz_stairs 6
setblock ~60~13~15 minecraft:quartz_stairs 0
fill ~61~13~15 ~62~13~15 minecraft:stone_block_slab 14
setblock ~63~12~15 minecraft:quartz_stairs 6
setblock ~63~13~15 minecraft:quartz_stairs 1
setblock ~66~12~15 minecraft:quartz_stairs 6
setblock ~66~13~15 minecraft:stone_block_slab 6
fill ~67~13~15 ~68~13~15 minecraft:stone_block_slab 14
setblock ~68~6~15 minecraft:tallgrass 0
setblock ~69~12~15 minecraft:quartz_stairs 6
setblock ~69~13~15 minecraft:stone_block_slab 6
setblock ~70~6~15 minecraft:tallgrass 0
fill ~72~4~15 ~73~4~15 minecraft:stone 0
fill ~72~5~15 ~73~5~15 minecraft:grass
setblock ~72~12~15 minecraft:quartz_stairs 6
setblock ~72~13~15 minecraft:quartz_stairs 0
fill ~73~13~15 ~74~13~15 minecraft:stone_block_slab 14
setblock ~75~12~15 minecraft:quartz_stairs 6
setblock ~75~13~15 minecraft:quartz_stairs 1
fill ~79~23~15 ~79~23~53 minecraft:quartz_stairs 5
fill ~80~3~15 ~80~3~52 minecraft:stone 0
fill ~80~4~15 ~80~4~52 minecraft:grass
setblock ~83~3~15 minecraft:tallgrass 0
setblock ~84~3~15 minecraft:yellow_flower
fill ~85~1~15 ~85~1~52 minecraft:stone 0
fill ~1~1~16 ~4~1~55 minecraft:dirt 0
fill ~4~2~16 ~4~2~53 minecraft:dirt 0
fill ~5~1~16 ~35~4~17 minecraft:quartz_block 0
fill ~5~5~16 ~31~5~17 minecraft:quartz_block 0
fill ~5~6~16 ~5~6~17 minecraft:quartz_block 1
fill ~5~7~16 ~5~19~17 minecraft:quartz_block 2
fill ~5~20~16 ~5~20~17 minecraft:quartz_block 1
fill ~5~21~16 ~5~21~51 minecraft:quartz_block 2
fill ~5~22~16 ~31~23~17 minecraft:quartz_block 0
fill ~5~24~16 ~31~24~16 minecraft:quartz_block 0
fill ~5~25~16 ~7~25~16 minecraft:wool 7
fill ~6~6~16 ~40~6~16 minecraft:quartz_block 0
fill ~6~7~16 ~8~14~17 minecraft:quartz_block 0
fill ~6~15~16 ~77~15~16 minecraft:quartz_block 0
fill ~6~16~16 ~8~20~16 minecraft:quartz_block 0
fill ~6~21~16 ~32~21~17 minecraft:quartz_block 2
fill ~8~25~16 ~11~25~16 minecraft:anvil 3
fill ~9~7~16 ~10~12~16 minecraft:glass_pane
fill ~9~13~16 ~40~14~16 minecraft:quartz_block 0
fill ~9~16~16 ~10~19~16 minecraft:glass_pane
fill ~9~20~16 ~77~20~16 minecraft:quartz_block 0
fill ~11~7~16 ~14~12~16 minecraft:quartz_block 0
fill ~11~16~16 ~14~19~16 minecraft:quartz_block 0
fill ~12~25~16 ~13~25~16 minecraft:wool 7
fill ~14~25~16 ~17~25~16 minecraft:anvil 3
fill ~15~7~16 ~16~12~16 minecraft:glass_pane
fill ~15~16~16 ~16~19~16 minecraft:glass_pane
fill ~17~7~16 ~20~12~16 minecraft:quartz_block 0
fill ~17~16~16 ~20~19~16 minecraft:quartz_block 0
fill ~18~25~16 ~19~25~16 minecraft:wool 7
fill ~19~0~16 ~37~0~17 minecraft:dirt 0
fill ~20~25~16 ~23~25~16 minecraft:anvil 3
fill ~21~7~16 ~22~12~16 minecraft:glass_pane
fill ~21~16~16 ~22~19~16 minecraft:glass_pane
fill ~23~7~16 ~26~12~16 minecraft:quartz_block 0
fill ~23~16~16 ~26~19~16 minecraft:quartz_block 0
fill ~24~25~16 ~25~25~16 minecraft:wool 7
fill ~26~25~16 ~29~25~16 minecraft:anvil 3
fill ~27~7~16 ~28~12~16 minecraft:glass_pane
fill ~27~16~16 ~28~19~16 minecraft:glass_pane
fill ~29~7~16 ~34~12~16 minecraft:quartz_block 0
fill ~29~16~16 ~35~19~16 minecraft:quartz_block 0
fill ~30~25~16 ~31~25~16 minecraft:wool 7
fill ~35~7~16 ~36~12~16 minecraft:glass_pane
fill ~36~1~16 ~36~4~28 minecraft:stained_hardened_clay 14
fill ~36~16~16 ~37~19~16 minecraft:glass_pane
fill ~37~7~16 ~40~12~16 minecraft:quartz_block 0
fill ~38~16~16 ~40~19~16 minecraft:quartz_block 0
fill ~41~10~16 ~42~10~17 minecraft:quartz_block 2
fill ~41~11~16 ~46~11~16 minecraft:quartz_block 0
fill ~41~12~16 ~42~12~16 minecraft:glass_pane
fill ~41~14~16 ~77~14~17 minecraft:quartz_block 0
fill ~41~16~16 ~42~19~16 minecraft:glass_pane
fill ~43~6~16 ~77~6~16 minecraft:quartz_block 0
fill ~43~7~16 ~46~10~16 minecraft:quartz_block 0
fill ~43~12~16 ~46~13~16 minecraft:quartz_block 0
fill ~43~16~16 ~45~19~16 minecraft:quartz_block 0
fill ~46~0~16 ~67~0~17 minecraft:dirt 0
fill ~46~16~16 ~47~19~16 minecraft:glass_pane
fill ~47~1~16 ~78~4~16 minecraft:quartz_block 0
fill ~47~7~16 ~48~12~16 minecraft:glass_pane
fill ~47~13~16 ~77~13~17 minecraft:quartz_block 0
fill ~48~16~16 ~54~19~16 minecraft:quartz_block 0
fill ~49~7~16 ~54~12~16 minecraft:quartz_block 0
fill ~51~21~16 ~77~21~17 minecraft:quartz_block 2
fill ~52~5~16 ~78~5~17 minecraft:quartz_block 0
fill ~52~22~16 ~78~23~17 minecraft:quartz_block 0
fill ~52~24~16 ~78~24~16 minecraft:quartz_block 0
fill ~52~25~16 ~53~25~16 minecraft:wool 7
fill ~54~25~16 ~57~25~16 minecraft:anvil 3
fill ~55~7~16 ~56~12~16 minecraft:glass_pane
fill ~55~16~16 ~56~19~16 minecraft:glass_pane
fill ~57~7~16 ~60~12~16 minecraft:quartz_block 0
fill ~57~16~16 ~60~19~16 minecraft:quartz_block 0
fill ~58~25~16 ~59~25~16 minecraft:wool 7
fill ~60~25~16 ~63~25~16 minecraft:anvil 3
fill ~61~7~16 ~62~12~16 minecraft:glass_pane
fill ~61~16~16 ~62~19~16 minecraft:glass_pane
fill ~63~7~16 ~66~12~16 minecraft:quartz_block 0
fill ~63~16~16 ~66~19~16 minecraft:quartz_block 0
fill ~64~25~16 ~65~25~16 minecraft:wool 7
fill ~66~25~16 ~69~25~16 minecraft:anvil 3
fill ~67~7~16 ~68~12~16 minecraft:glass_pane
fill ~67~16~16 ~68~19~16 minecraft:glass_pane
fill ~69~7~16 ~72~12~16 minecraft:quartz_block 0
fill ~69~16~16 ~72~19~16 minecraft:quartz_block 0
fill ~70~25~16 ~71~25~16 minecraft:wool 7
fill ~72~25~16 ~75~25~16 minecraft:anvil 3
fill ~73~7~16 ~74~12~16 minecraft:glass_pane
fill ~73~16~16 ~74~19~16 minecraft:glass_pane
fill ~75~7~16 ~77~12~16 minecraft:quartz_block 0
fill ~75~16~16 ~77~19~16 minecraft:quartz_block 0
fill ~76~25~16 ~78~25~16 minecraft:wool 7
fill ~78~6~16 ~78~6~17 minecraft:quartz_block 1
fill ~78~7~16 ~78~19~17 minecraft:quartz_block 2
fill ~78~20~16 ~78~21~17 minecraft:quartz_block 1
fill ~79~1~16 ~79~1~56 minecraft:dirt 0
fill ~79~2~16 ~79~2~54 minecraft:dirt 0
fill ~79~3~16 ~79~3~51 minecraft:dirt 0
fill ~79~4~16 ~79~4~51 minecraft:grass
fill ~80~1~16 ~81~1~52 minecraft:stone 0
fill ~80~2~16 ~80~2~52 minecraft:stone 0
fill ~81~3~16 ~81~3~52 minecraft:stone 0
fill ~81~4~16 ~81~4~53 minecraft:grass
fill ~83~2~16 ~83~2~52 minecraft:stone 0
fill ~83~3~16 ~83~3~19 minecraft:grass
setblock ~84~3~16 minecraft:tallgrass 0
fill ~1~3~17 ~1~3~26 minecraft:dirt 0
fill ~1~4~17 ~1~4~26 minecraft:grass
fill ~5~24~17 ~5~24~52 minecraft:quartz_block 0
setblock ~5~25~17 minecraft:wool 7
fill ~6~6~17 ~13~6~17 minecraft:quartz_block 0
fill ~6~15~17 ~7~20~17 minecraft:quartz_block 0
fill ~6~24~17 ~32~24~17 minecraft:quartz_stairs 3
fill ~8~15~17 ~8~18~17 minecraft:hay_block 0
fill ~8~19~17 ~11~19~17 minecraft:hay_block 0
fill ~8~20~17 ~39~20~17 minecraft:quartz_block 0
fill ~9~13~17 ~13~14~17 minecraft:quartz_block 0
fill ~9~15~17 ~10~15~17 minecraft:stained_hardened_clay 4
fill ~11~7~17 ~13~12~17 minecraft:quartz_block 0
fill ~11~15~17 ~11~18~17 minecraft:hay_block 0
fill ~12~15~17 ~13~19~17 minecraft:quartz_block 0
fill ~14~6~17 ~14~12~17 minecraft:wool 4
fill ~14~13~17 ~23~13~17 minecraft:sandstone 2
fill ~14~14~17 ~40~14~23 minecraft:quartz_block 0
fill ~14~15~17 ~14~19~17 minecraft:sandstone 2
fill ~15~6~17 ~16~6~17 minecraft:sandstone 2
fill ~15~12~17 ~17~12~17 minecraft:wool 4
fill ~15~15~17 ~16~15~17 minecraft:quartz_block 0
fill ~15~19~17 ~17~19~17 minecraft:sandstone 2
fill ~17~6~17 ~17~11~17 minecraft:wool 4
fill ~17~15~17 ~17~18~17 minecraft:sandstone 2
fill ~18~6~17 ~19~12~17 minecraft:sandstone 2
fill ~18~15~17 ~19~19~17 minecraft:quartz_block 0
fill ~20~6~17 ~20~12~17 minecraft:wool 4
fill ~20~15~17 ~20~19~17 minecraft:sandstone 2
fill ~21~6~17 ~22~6~17 minecraft:sandstone 2
fill ~21~12~17 ~23~12~17 minecraft:wool 4
fill ~21~15~17 ~22~15~17 minecraft:quartz_block 0
fill ~21~19~17 ~23~19~17 minecraft:sandstone 2
fill ~23~6~17 ~23~11~17 minecraft:wool 4
fill ~23~15~17 ~23~18~17 minecraft:sandstone 2
fill ~24~6~17 ~40~6~17 minecraft:quartz_block 0
fill ~24~7~17 ~25~13~17 minecraft:quartz_block 0
fill ~24~15~17 ~33~15~17 minecraft:quartz_block 0
fill ~24~16~17 ~26~19~17 minecraft:quartz_block 0
fill ~26~7~17 ~26~13~17 minecraft:wool 14
fill ~27~13~17 ~29~13~17 minecraft:wool 14
fill ~29~7~17 ~29~12~17 minecraft:wool 14
fill ~29~16~17 ~33~19~17 minecraft:quartz_block 0
fill ~30~7~17 ~33~13~17 minecraft:quartz_block 0
fill ~34~7~17 ~34~12~17 minecraft:wool 14
fill ~34~13~17 ~40~13~17 minecraft:quartz_block 0
fill ~34~15~17 ~34~19~17 minecraft:wool 3
fill ~35~11~17 ~37~12~17 minecraft:wool 14
fill ~35~15~17 ~35~19~17 minecraft:diamond_block
fill ~36~15~17 ~37~15~17 minecraft:wool 3
fill ~36~19~17 ~38~19~17 minecraft:diamond_block
fill ~37~7~17 ~37~10~17 minecraft:wool 14
setblock ~38~3~17 minecraft:torch 1
fill ~38~7~17 ~40~12~17 minecraft:quartz_block 0
fill ~38~15~17 ~38~18~17 minecraft:diamond_block
fill ~39~15~17 ~39~19~17 minecraft:quartz_block 0
fill ~40~15~17 ~40~18~17 minecraft:quartz_block 2
fill ~40~19~17 ~43~19~17 minecraft:quartz_block 2
fill ~40~20~17 ~43~20~17 minecraft:wool 3
fill ~41~11~17 ~45~11~17 minecraft:quartz_block 0
fill ~41~15~17 ~42~15~17 minecraft:wool 3
fill ~43~6~17 ~59~6~17 minecraft:quartz_block 0
fill ~43~7~17 ~45~10~17 minecraft:quartz_block 0
fill ~43~12~17 ~45~13~17 minecraft:quartz_block 0
fill ~43~15~17 ~43~18~17 minecraft:quartz_block 2
fill ~44~15~17 ~45~20~17 minecraft:quartz_block 0
setblock ~45~3~17 minecraft:torch 2
fill ~46~7~17 ~46~12~17 minecraft:wool 14
setblock ~46~13~17 minecraft:quartz_block 0
fill ~46~15~17 ~47~15~17 minecraft:wool 3
fill ~46~20~17 ~60~20~17 minecraft:quartz_block 0
fill ~47~1~17 ~59~4~17 minecraft:quartz_block 0
fill ~47~11~17 ~49~12~17 minecraft:wool 14
fill ~48~15~17 ~48~19~17 minecraft:quartz_block 0
fill ~49~7~17 ~49~10~17 minecraft:wool 14
fill ~49~15~17 ~49~19~17 minecraft:wool 3
fill ~50~7~17 ~54~12~17 minecraft:quartz_block 0
fill ~50~15~17 ~60~15~17 minecraft:quartz_block 0
fill ~50~16~17 ~54~19~17 minecraft:quartz_block 0
fill ~51~24~17 ~77~24~17 minecraft:quartz_stairs 3
fill ~57~7~17 ~59~12~17 minecraft:quartz_block 0
fill ~57~16~17 ~59~19~17 minecraft:quartz_block 0
fill ~60~1~17 ~62~3~17 minecraft:bookshelf
fill ~60~4~17 ~61~4~17 minecraft:bookshelf
setblock ~60~6~17 minecraft:quartz_block 1
fill ~60~7~17 ~60~11~17 minecraft:quartz_block 2
setblock ~60~12~17 minecraft:quartz_block 1
fill ~60~16~17 ~60~19~18 minecraft:wool 6
fill ~61~6~17 ~62~6~17 minecraft:quartz_block 0
fill ~61~15~17 ~63~15~17 minecraft:wool 6
fill ~61~20~17 ~69~20~17 minecraft:wool 6
fill ~62~4~17 ~78~4~17 minecraft:quartz_block 0
fill ~63~1~17 ~63~3~17 minecraft:quartz_block 0
setblock ~63~6~17 minecraft:quartz_block 1
fill ~63~7~17 ~63~11~17 minecraft:quartz_block 2
setblock ~63~12~17 minecraft:quartz_block 1
fill ~63~16~17 ~66~19~17 minecraft:wool 6
fill ~64~1~17 ~65~3~17 minecraft:bookshelf
fill ~64~6~17 ~65~12~17 minecraft:quartz_block 0
fill ~64~15~17 ~65~15~17 minecraft:planks 1
fill ~66~1~17 ~66~3~17 minecraft:quartz_block 0
setblock ~66~6~17 minecraft:quartz_block 1
fill ~66~7~17 ~66~11~17 minecraft:quartz_block 2
setblock ~66~12~17 minecraft:quartz_block 1
fill ~66~15~17 ~69~15~17 minecraft:wool 6
fill ~67~1~17 ~68~3~17 minecraft:bookshelf
fill ~67~6~17 ~68~6~17 minecraft:quartz_block 0
fill ~69~1~17 ~69~3~17 minecraft:quartz_block 0
setblock ~69~6~17 minecraft:quartz_block 1
fill ~69~7~17 ~69~11~17 minecraft:quartz_block 2
setblock ~69~12~17 minecraft:quartz_block 1
fill ~69~16~17 ~69~19~17 minecraft:wool 6
fill ~70~1~17 ~71~3~17 minecraft:bookshelf
fill ~70~6~17 ~71~12~17 minecraft:quartz_block 0
fill ~70~15~17 ~70~20~17 minecraft:quartz_block 0
fill ~71~15~17 ~75~15~17 minecraft:wool 6
fill ~71~16~17 ~72~20~17 minecraft:wool 6
fill ~72~1~17 ~72~3~17 minecraft:quartz_block 0
setblock ~72~6~17 minecraft:quartz_block 1
fill ~72~7~17 ~72~11~17 minecraft:quartz_block 2
setblock ~72~12~17 minecraft:quartz_block 1
fill ~73~1~17 ~75~3~17 minecraft:bookshelf
fill ~73~6~17 ~74~6~17 minecraft:quartz_block 0
fill ~73~20~17 ~75~20~17 minecraft:wool 6
setblock ~75~6~17 minecraft:quartz_block 1
fill ~75~7~17 ~75~11~17 minecraft:quartz_block 2
setblock ~75~12~17 minecraft:quartz_block 1
fill ~75~16~17 ~75~19~17 minecraft:wool 6
fill ~76~1~17 ~78~3~17 minecraft:quartz_block 0
fill ~76~6~17 ~77~12~17 minecraft:quartz_block 0
fill ~76~15~17 ~77~20~17 minecraft:quartz_block 0
fill ~78~24~17 ~78~24~52 minecraft:quartz_block 0
setblock ~78~25~17 minecraft:wool 7
fill ~0~0~18 ~7~0~27 minecraft:dirt 0
fill ~1~5~18 ~1~5~22 minecraft:tallgrass 0
setblock ~4~5~18 minecraft:tallgrass 0
fill ~5~1~18 ~7~1~49 minecraft:quartz_block 0
fill ~5~2~18 ~7~4~29 minecraft:quartz_block 0
fill ~5~5~18 ~5~5~21 minecraft:quartz_stairs 0
setblock ~5~12~18 minecraft:quartz_stairs 4
setblock ~5~13~18 minecraft:quartz_stairs 2
setblock ~5~20~18 minecraft:quartz_stairs 7
fill ~5~22~18 ~5~23~52 minecraft:quartz_block 0
fill ~5~25~18 ~5~25~21 minecraft:anvil 2
fill ~6~5~18 ~31~5~21 minecraft:quartz_block 0
fill ~6~6~18 ~7~6~31 minecraft:quartz_block 0
fill ~6~7~18 ~7~14~18 minecraft:quartz_block 0
fill ~6~15~18 ~6~15~51 minecraft:quartz_block 0
fill ~6~16~18 ~6~21~18 minecraft:quartz_block 0
fill ~6~23~18 ~31~23~20 minecraft:quartz_block 0
fill ~6~24~18 ~6~24~31 minecraft:quartz_stairs 1
fill ~7~15~18 ~7~18~18 minecraft:hay_block 0
fill ~7~19~18 ~7~19~21 minecraft:hay_block 0
fill ~7~20~18 ~8~21~18 minecraft:quartz_block 0
fill ~8~0~18 ~23~0~28 minecraft:quartz_block 0
fill ~8~1~18 ~23~1~18 minecraft:rail 1
fill ~8~4~18 ~8~4~26 minecraft:quartz_stairs 5
fill ~8~6~18 ~8~6~26 minecraft:quartz_stairs 5
fill ~8~13~18 ~8~13~27 minecraft:quartz_stairs 5
fill ~8~14~18 ~13~14~32 minecraft:quartz_block 0
fill ~8~15~18 ~10~15~18 minecraft:quartz_stairs 7
fill ~9~4~18 ~23~4~18 minecraft:quartz_stairs 7
fill ~9~6~18 ~11~6~18 minecraft:quartz_stairs 7
fill ~9~13~18 ~11~13~18 minecraft:quartz_stairs 7
fill ~9~20~18 ~10~20~18 minecraft:quartz_stairs 7
fill ~9~21~18 ~77~21~23 minecraft:quartz_block 0
fill ~11~15~18 ~11~15~19 minecraft:quartz_stairs 4
setblock ~11~20~18 minecraft:quartz_block 0
fill ~12~6~18 ~12~13~18 minecraft:quartz_block 0
fill ~12~15~18 ~12~20~22 minecraft:stained_hardened_clay 4
fill ~13~6~18 ~13~13~18 minecraft:sandstone 2
fill ~13~15~18 ~13~20~22 minecraft:quartz_block 0
setblock ~14~13~18 minecraft:quartz_block 0
setblock ~14~20~18 minecraft:quartz_block 0
fill ~15~13~18 ~22~13~18 minecraft:quartz_stairs 7
fill ~15~20~18 ~22~20~18 minecraft:quartz_stairs 7
fill ~18~18~18 ~19~18~18 minecraft:torch 3
fill ~19~2~18 ~21~2~18 minecraft:stone_block_slab 14
fill ~19~3~18 ~21~3~18 minecraft:flower_pot 0
setblock ~23~13~18 minecraft:quartz_block 0
fill ~23~20~18 ~25~20~18 minecraft:quartz_block 0
fill ~24~0~18 ~25~0~18 minecraft:dirt 0
fill ~24~1~18 ~25~4~18 minecraft:quartz_block 0
fill ~24~6~18 ~24~13~18 minecraft:sandstone 2
fill ~24~15~18 ~25~19~18 minecraft:quartz_block 0
fill ~25~6~18 ~25~13~18 minecraft:quartz_block 0
fill ~26~0~18 ~30~0~28 minecraft:quartz_block 0
fill ~26~15~18 ~31~15~18 minecraft:planks 1
fill ~26~16~18 ~26~17~18 minecraft:planks 1
setblock ~27~6~18 minecraft:spruce_stairs 5
setblock ~28~3~18 minecraft:torch 3
setblock ~28~6~18 minecraft:wooden_slab 9
setblock ~29~6~18 minecraft:spruce_stairs 4
fill ~29~16~18 ~31~17~18 minecraft:planks 1
setblock ~29~19~18 minecraft:torch 3
fill ~30~1~18 ~30~1~29 minecraft:quartz_block 0
fill ~30~2~18 ~30~3~28 minecraft:quartz_block 0
fill ~30~4~18 ~30~4~23 minecraft:quartz_block 0
fill ~31~0~18 ~35~0~22 minecraft:grass
fill ~32~6~18 ~32~13~18 minecraft:quartz_block 0
fill ~32~15~18 ~32~20~18 minecraft:quartz_block 0
fill ~33~15~18 ~33~20~18 minecraft:wool 3
fill ~34~20~18 ~38~20~18 minecraft:quartz_stairs 7
fill ~36~0~18 ~37~0~20 minecraft:dirt 0
fill ~38~6~18 ~39~6~18 minecraft:quartz_block 1
fill ~38~7~18 ~39~12~18 minecraft:quartz_block 2
fill ~38~13~18 ~39~13~18 minecraft:quartz_block 1
fill ~39~15~18 ~39~20~22 minecraft:wool 3
setblock ~40~9~18 minecraft:torch 3
fill ~40~15~18 ~40~15~20 minecraft:planks 2
fill ~41~14~18 ~51~14~29 minecraft:quartz_block 0
setblock ~43~9~18 minecraft:torch 3
setblock ~43~15~18 minecraft:planks 2
setblock ~43~16~18 minecraft:flower_pot 0
fill ~44~6~18 ~45~6~18 minecraft:quartz_block 1
fill ~44~7~18 ~45~12~18 minecraft:quartz_block 2
fill ~44~13~18 ~45~13~18 minecraft:quartz_block 1
fill ~44~15~18 ~44~19~22 minecraft:wool 3
fill ~44~20~18 ~44~20~20 minecraft:wool 3
fill ~45~15~18 ~45~15~19 minecraft:planks 2
fill ~45~20~18 ~45~20~24 minecraft:quartz_stairs 5
fill ~46~0~18 ~47~0~20 minecraft:dirt 0
fill ~46~20~18 ~48~20~18 minecraft:quartz_stairs 7
fill ~47~1~18 ~47~4~27 minecraft:stained_hardened_clay 14
fill ~48~0~18 ~53~0~27 minecraft:grass
fill ~49~20~18 ~49~20~23 minecraft:quartz_stairs 4
fill ~50~15~18 ~50~19~24 minecraft:wool 3
fill ~50~20~18 ~51~20~23 minecraft:quartz_block 0
fill ~51~10~18 ~51~13~20 minecraft:quartz_block 0
fill ~51~15~18 ~51~19~28 minecraft:quartz_block 0
fill ~52~5~18 ~59~5~21 minecraft:quartz_block 0
fill ~52~20~18 ~52~20~27 minecraft:quartz_stairs 5
fill ~52~23~18 ~78~23~20 minecraft:quartz_block 0
setblock ~53~17~18 minecraft:torch 3
fill ~53~20~18 ~57~20~18 minecraft:quartz_stairs 7
fill ~54~0~18 ~54~0~23 minecraft:dirt 0
fill ~54~1~18 ~54~1~23 minecraft:quartz_block 0
fill ~55~0~18 ~57~0~25 minecraft:grass
fill ~58~0~18 ~59~0~21 minecraft:dirt 0
fill ~58~1~18 ~58~1~28 minecraft:quartz_block 0
fill ~58~10~18 ~58~12~30 minecraft:quartz_block 0
fill ~58~13~18 ~60~14~18 minecraft:quartz_block 0
fill ~58~15~18 ~59~20~18 minecraft:quartz_block 0
fill ~59~1~18 ~59~4~20 minecraft:bookshelf
setblock ~59~6~18 minecraft:quartz_block 1
fill ~59~7~18 ~59~11~18 minecraft:quartz_block 2
setblock ~59~12~18 minecraft:quartz_block 1
fill ~60~0~18 ~78~0~28 minecraft:quartz_block 0
fill ~60~4~18 ~60~4~20 minecraft:quartz_stairs 5
fill ~60~5~18 ~75~5~20 minecraft:planks 3
fill ~60~6~18 ~60~12~18 minecraft:wool 13
setblock ~60~15~18 minecraft:wool 6
setblock ~60~20~18 minecraft:wool 6
fill ~61~4~18 ~75~4~18 minecraft:quartz_stairs 7
fill ~61~12~18 ~63~12~18 minecraft:wool 13
fill ~61~13~18 ~74~13~18 minecraft:quartz_stairs 7
fill ~61~14~18 ~77~14~20 minecraft:quartz_block 0
setblock ~61~20~18 minecraft:quartz_block 0
fill ~62~20~18 ~68~20~18 minecraft:quartz_stairs 7
setblock ~63~2~18 minecraft:torch 3
fill ~63~6~18 ~63~11~18 minecraft:wool 13
fill ~64~15~18 ~65~15~18 minecraft:chest 3
fill ~64~16~18 ~65~16~18 minecraft:spruce_stairs 7
fill ~64~17~18 ~65~17~18 minecraft:planks 1
setblock ~66~1~18 minecraft:spruce_stairs 7
setblock ~66~2~18 minecraft:torch 3
fill ~66~6~18 ~66~12~18 minecraft:wool 13
fill ~67~12~18 ~69~12~18 minecraft:wool 13
setblock ~69~1~18 minecraft:spruce_stairs 1
setblock ~69~2~18 minecraft:torch 3
fill ~69~6~18 ~69~11~18 minecraft:wool 13
setblock ~69~20~18 minecraft:quartz_block 0
fill ~70~1~18 ~70~1~19 minecraft:spruce_stairs 4
fill ~70~15~18 ~70~20~23 minecraft:wool 6
fill ~71~1~18 ~71~1~19 minecraft:spruce_stairs 5
setblock ~71~20~18 minecraft:quartz_block 0
setblock ~72~1~18 minecraft:spruce_stairs 0
setblock ~72~2~18 minecraft:torch 3
fill ~72~6~18 ~72~12~18 minecraft:wool 13
fill ~72~20~18 ~74~20~18 minecraft:quartz_stairs 7
fill ~73~12~18 ~75~12~18 minecraft:wool 13
setblock ~73~15~18 minecraft:spruce_stairs 3
fill ~75~6~18 ~75~11~18 minecraft:wool 13
fill ~75~13~18 ~77~13~18 minecraft:quartz_block 0
setblock ~75~20~18 minecraft:quartz_block 0
fill ~76~1~18 ~76~3~20 minecraft:bookshelf
fill ~76~4~18 ~78~4~52 minecraft:quartz_block 0
fill ~76~5~18 ~77~5~52 minecraft:quartz_block 0
setblock ~76~6~18 minecraft:quartz_block 1
fill ~76~7~18 ~76~11~18 minecraft:quartz_block 2
setblock ~76~12~18 minecraft:quartz_block 1
fill ~76~15~18 ~76~20~18 minecraft:wool 6
fill ~77~1~18 ~78~3~51 minecraft:quartz_block 0
fill ~77~6~18 ~77~6~51 minecraft:quartz_block 0
fill ~77~7~18 ~77~12~18 minecraft:quartz_block 0
fill ~77~15~18 ~77~15~51 minecraft:quartz_block 0
fill ~77~16~18 ~77~20~18 minecraft:quartz_block 0
fill ~77~24~18 ~77~24~28 minecraft:quartz_stairs 0
fill ~78~5~18 ~78~5~21 minecraft:quartz_stairs 1
setblock ~78~12~18 minecraft:quartz_stairs 5
setblock ~78~13~18 minecraft:quartz_stairs 2
setblock ~78~20~18 minecraft:quartz_stairs 7
fill ~78~21~18 ~78~21~51 minecraft:quartz_block 2
fill ~78~22~18 ~78~22~52 minecraft:quartz_block 0
fill ~78~25~18 ~78~25~21 minecraft:anvil 0
fill ~82~3~18 ~82~3~52 minecraft:stone 0
fill ~82~4~18 ~82~4~53 minecraft:grass
fill ~84~2~18 ~84~2~21 minecraft:stone 0
fill ~84~3~18 ~84~3~22 minecraft:grass
setblock ~3~5~19 minecraft:red_flower 0
fill ~5~13~19 ~5~13~20 minecraft:stone_block_slab 14
fill ~5~20~19 ~5~20~20 minecraft:stone_block_slab 14
fill ~6~7~19 ~6~12~20 minecraft:glass_pane
fill ~6~13~19 ~7~14~32 minecraft:quartz_block 0
fill ~6~16~19 ~6~19~20 minecraft:glass_pane
fill ~6~20~19 ~7~21~39 minecraft:quartz_block 0
fill ~7~15~19 ~7~15~20 minecraft:stained_hardened_clay 4
fill ~7~26~19 ~7~26~50 minecraft:quartz_stairs 4
setblock ~8~15~19 minecraft:quartz_stairs 5
fill ~8~20~19 ~8~20~26 minecraft:quartz_stairs 5
fill ~8~21~19 ~8~21~51 minecraft:quartz_block 0
fill ~8~26~19 ~40~26~19 minecraft:quartz_stairs 6
fill ~9~19~19 ~10~19~19 minecraft:web
fill ~11~13~19 ~11~13~27 minecraft:quartz_stairs 4
fill ~11~20~19 ~11~20~26 minecraft:quartz_stairs 4
fill ~12~10~19 ~12~13~28 minecraft:quartz_block 0
fill ~13~10~19 ~13~13~27 minecraft:sandstone 2
fill ~14~13~19 ~14~13~26 minecraft:quartz_stairs 5
fill ~14~20~19 ~14~20~24 minecraft:quartz_stairs 5
fill ~23~4~19 ~23~4~26 minecraft:quartz_stairs 4
fill ~23~13~19 ~23~13~26 minecraft:quartz_stairs 4
fill ~23~20~19 ~23~20~24 minecraft:quartz_stairs 4
fill ~24~0~19 ~25~0~20 minecraft:quartz_block 0
fill ~24~4~19 ~25~4~30 minecraft:quartz_block 0
fill ~24~10~19 ~24~13~27 minecraft:sandstone 2
fill ~24~19~19 ~25~20~28 minecraft:quartz_block 0
fill ~25~10~19 ~25~12~30 minecraft:quartz_block 0
fill ~25~13~19 ~25~13~29 minecraft:quartz_block 0
fill ~26~15~19 ~31~15~19 minecraft:wooden_button 3
setblock ~28~6~19 minecraft:spruce_stairs 2
fill ~28~10~19 ~29~10~20 minecraft:glowstone
fill ~28~11~19 ~29~13~20 minecraft:iron_bars
fill ~30~16~19 ~30~17~19 minecraft:wooden_button 3
fill ~32~9~19 ~32~12~29 minecraft:quartz_block 0
fill ~32~13~19 ~32~13~28 minecraft:quartz_block 0
fill ~32~19~19 ~32~20~28 minecraft:quartz_block 0
setblock ~33~9~19 minecraft:torch 1
fill ~33~19~19 ~33~19~24 minecraft:wool 3
fill ~33~20~19 ~33~20~25 minecraft:quartz_block 0
fill ~34~20~19 ~34~20~24 minecraft:quartz_stairs 5
fill ~36~15~19 ~37~15~19 minecraft:wooden_slab 2
setblock ~38~15~19 minecraft:double_wooden_slab 2
setblock ~38~16~19 minecraft:flower_pot 0
fill ~38~20~19 ~38~20~23 minecraft:quartz_stairs 4
fill ~40~16~19 ~40~16~20 minecraft:flower_pot 0
setblock ~41~15~19 minecraft:wooden_button 5
setblock ~43~15~19 minecraft:chest 4
fill ~43~26~19 ~76~26~19 minecraft:quartz_stairs 6
setblock ~45~1~19 minecraft:double_stone_block_slab 6
setblock ~45~2~19 minecraft:quartz_stairs 2
setblock ~45~16~19 minecraft:flower_pot 0
fill ~47~15~19 ~48~15~19 minecraft:wooden_slab 2
setblock ~49~15~19 minecraft:double_wooden_slab 2
setblock ~49~16~19 minecraft:flower_pot 0
setblock ~55~1~19 minecraft:torch 5
fill ~57~20~19 ~57~20~26 minecraft:quartz_stairs 4
fill ~58~13~19 ~59~14~29 minecraft:quartz_block 0
fill ~58~15~19 ~58~20~28 minecraft:quartz_block 0
fill ~59~10~19 ~59~12~20 minecraft:quartz_block 0
fill ~59~15~19 ~59~20~20 minecraft:wool 6
fill ~60~10~19 ~60~10~20 minecraft:quartz_stairs 5
fill ~60~13~19 ~60~13~31 minecraft:quartz_stairs 5
fill ~60~14~19 ~60~14~21 minecraft:quartz_block 0
fill ~60~20~19 ~60~20~20 minecraft:quartz_block 0
fill ~61~20~19 ~61~20~26 minecraft:quartz_stairs 5
fill ~69~20~19 ~69~20~24 minecraft:quartz_stairs 4
setblock ~70~2~19 minecraft:flower_pot 0
fill ~71~15~19 ~71~16~20 minecraft:planks 1
fill ~71~20~19 ~71~20~21 minecraft:quartz_stairs 5
fill ~72~15~19 ~72~15~20 minecraft:wooden_button 5
fill ~75~4~19 ~75~4~27 minecraft:quartz_stairs 4
fill ~75~12~19 ~75~12~21 minecraft:wool 13
fill ~75~13~19 ~75~13~48 minecraft:quartz_stairs 4
fill ~75~20~19 ~75~20~20 minecraft:quartz_stairs 4
fill ~76~6~19 ~76~6~20 minecraft:quartz_block 0
fill ~76~13~19 ~77~13~32 minecraft:quartz_block 0
setblock ~76~20~19 minecraft:wool 6
fill ~77~7~19 ~77~12~20 minecraft:glass_pane
fill ~77~16~19 ~77~19~20 minecraft:glass_pane
fill ~77~20~19 ~77~20~51 minecraft:quartz_block 0
fill ~78~13~19 ~78~13~20 minecraft:stone_block_slab 14
fill ~78~20~19 ~78~20~20 minecraft:stone_block_slab 14
fill ~0~3~20 ~0~3~24 minecraft:dirt 0
fill ~0~4~20 ~0~4~24 minecraft:grass
setblock ~0~5~20 minecraft:red_flower 0
fill ~2~5~20 ~3~5~21 minecraft:tallgrass 0
fill ~8~2~20 ~8~2~24 minecraft:stone_block_slab 14
fill ~8~3~20 ~8~3~24 minecraft:flower_pot 0
setblock ~8~15~20 minecraft:quartz_stairs 6
setblock ~8~19~20 minecraft:web
setblock ~8~22~20 minecraft:torch 5
fill ~8~24~20 ~8~25~24 minecraft:quartz_block 0
fill ~8~26~20 ~40~26~49 minecraft:clay
setblock ~9~1~20 minecraft:torch 5
fill ~9~19~20 ~10~19~20 minecraft:glowstone
fill ~9~20~20 ~10~20~20 minecraft:iron_bars
fill ~9~24~20 ~10~25~20 minecraft:glass_pane
setblock ~10~22~20 minecraft:quartz_block 0
fill ~11~4~20 ~11~4~24 minecraft:quartz_stairs 4
fill ~11~15~20 ~11~15~21 minecraft:cauldron 6
fill ~11~16~20 ~11~16~21 minecraft:tripwire_hook 1
setblock ~11~19~20 minecraft:web
fill ~11~24~20 ~14~25~20 minecraft:quartz_block 0
setblock ~12~1~20 minecraft:quartz_stairs 0
fill ~12~4~20 ~21~4~20 minecraft:quartz_stairs 6
fill ~13~1~20 ~19~1~20 minecraft:rail 1
fill ~15~22~20 ~16~22~20 minecraft:quartz_block 0
fill ~15~24~20 ~16~25~20 minecraft:glass_pane
fill ~16~2~20 ~17~2~20 minecraft:stone_block_slab 14
fill ~16~3~20 ~17~3~20 minecraft:flower_pot 0
fill ~17~24~20 ~20~25~20 minecraft:quartz_block 0
fill ~18~6~20 ~19~6~20 minecraft:oak_stairs 3
fill ~18~15~20 ~19~15~20 minecraft:spruce_stairs 3
setblock ~20~1~20 minecraft:quartz_stairs 1
fill ~21~24~20 ~22~25~20 minecraft:glass_pane
fill ~23~24~20 ~24~25~21 minecraft:quartz_block 0
fill ~24~6~20 ~24~9~21 minecraft:sandstone 2
fill ~25~6~20 ~25~9~25 minecraft:quartz_block 0
setblock ~25~24~20 minecraft:wooden_door 1
fill ~26~24~20 ~26~25~23 minecraft:quartz_block 0
fill ~27~24~20 ~28~25~20 minecraft:glass_pane
fill ~29~24~20 ~54~25~20 minecraft:quartz_block 0
fill ~32~6~20 ~32~8~29 minecraft:quartz_block 0
fill ~35~23~20 ~48~23~20 minecraft:quartz_block 0
fill ~36~15~20 ~36~15~22 minecraft:wooden_slab 2
setblock ~36~19~20 minecraft:web
fill ~38~0~20 ~40~0~20 minecraft:double_wooden_slab 4
fill ~38~15~20 ~38~15~21 minecraft:bed 3
setblock ~40~17~20 minecraft:torch 4
fill ~43~0~20 ~44~0~20 minecraft:double_wooden_slab 4
setblock ~43~15~20 minecraft:planks 2
setblock ~43~16~20 minecraft:flower_pot 0
setblock ~43~17~20 minecraft:torch 4
fill ~43~26~20 ~75~26~49 minecraft:clay
setblock ~45~0~20 minecraft:dirt 0
setblock ~45~1~20 minecraft:quartz_stairs 1
setblock ~45~15~20 minecraft:chest 5
fill ~46~1~20 ~46~1~21 minecraft:quartz_block 0
fill ~46~2~20 ~46~4~20 minecraft:stained_hardened_clay 14
fill ~47~15~20 ~47~15~22 minecraft:wooden_slab 2
setblock ~47~19~20 minecraft:web
fill ~49~15~20 ~49~15~21 minecraft:bed 3
setblock ~50~9~20 minecraft:torch 2
fill ~51~6~20 ~57~9~20 minecraft:quartz_block 0
fill ~52~10~20 ~57~12~20 minecraft:quartz_block 0
fill ~52~13~20 ~57~13~20 minecraft:anvil 1
fill ~55~22~20 ~56~22~21 minecraft:torch 5
fill ~55~24~20 ~56~25~20 minecraft:glass_pane
fill ~57~24~20 ~60~25~20 minecraft:quartz_block 0
fill ~61~24~20 ~62~25~20 minecraft:glass_pane
fill ~63~24~20 ~66~25~20 minecraft:quartz_block 0
setblock ~64~15~20 minecraft:spruce_stairs 2
fill ~67~15~20 ~67~17~20 minecraft:nether_brick_fence
fill ~67~18~20 ~69~18~22 minecraft:wool 0
setblock ~67~19~20 minecraft:nether_brick_fence
fill ~67~24~20 ~68~25~20 minecraft:glass_pane
setblock ~68~15~20 minecraft:wool 0
setblock ~69~1~20 minecraft:spruce_stairs 1
fill ~69~15~20 ~69~17~20 minecraft:nether_brick_fence
setblock ~69~19~20 minecraft:nether_brick_fence
fill ~69~24~20 ~72~25~20 minecraft:quartz_block 0
fill ~70~1~20 ~71~1~20 minecraft:spruce_stairs 7
setblock ~72~1~20 minecraft:spruce_stairs 0
setblock ~73~18~20 minecraft:glowstone
setblock ~73~19~20 minecraft:web
setblock ~73~20~20 minecraft:iron_bars
fill ~73~24~20 ~74~25~20 minecraft:glass_pane
fill ~74~15~20 ~74~15~21 minecraft:iron_bars
fill ~74~16~20 ~74~16~22 minecraft:quartz_block 2
setblock ~75~15~20 minecraft:quartz_block 2
setblock ~75~16~20 minecraft:quartz_block 1
fill ~75~24~20 ~75~25~24 minecraft:quartz_block 0
fill ~76~26~20 ~76~26~50 minecraft:quartz_stairs 5
fill ~82~5~20 ~82~5~23 minecraft:tallgrass 0
fill ~83~3~20 ~83~3~32 minecraft:stone 0
fill ~83~4~20 ~83~4~32 minecraft:grass
setblock ~83~5~20 minecraft:red_flower 3
fill ~85~2~20 ~85~2~33 minecraft:stone 0
fill ~85~3~20 ~85~3~33 minecraft:grass
fill ~0~5~21 ~0~5~22 minecraft:tallgrass 0
setblock ~5~12~21 minecraft:quartz_stairs 4
setblock ~5~13~21 minecraft:quartz_stairs 3
setblock ~5~20~21 minecraft:quartz_stairs 6
fill ~6~7~21 ~7~12~24 minecraft:quartz_block 0
fill ~6~16~21 ~6~19~24 minecraft:quartz_block 0
fill ~6~23~21 ~8~23~52 minecraft:quartz_block 0
fill ~7~15~21 ~7~18~21 minecraft:hay_block 0
setblock ~8~9~21 minecraft:torch 1
fill ~8~15~21 ~8~15~24 minecraft:furnace 5
fill ~8~16~21 ~8~16~24 minecraft:trapdoor 0
setblock ~8~22~21 minecraft:quartz_block 0
fill ~9~19~21 ~10~19~21 minecraft:web
fill ~9~22~21 ~10~22~21 minecraft:torch 5
fill ~11~2~21 ~11~2~22 minecraft:stone_block_slab 14
fill ~11~3~21 ~11~3~22 minecraft:flower_pot 0
fill ~11~6~21 ~11~6~24 minecraft:quartz_stairs 4
setblock ~11~9~21 minecraft:torch 2
fill ~11~22~21 ~11~25~21 minecraft:quartz_block 0
fill ~12~1~21 ~20~4~21 minecraft:quartz_block 0
fill ~12~6~21 ~12~9~24 minecraft:quartz_block 0
fill ~13~6~21 ~13~9~24 minecraft:sandstone 2
fill ~14~22~21 ~14~25~21 minecraft:quartz_block 0
fill ~15~22~21 ~16~22~21 minecraft:torch 5
fill ~17~6~21 ~17~6~24 minecraft:oak_stairs 1
fill ~17~15~21 ~17~15~23 minecraft:spruce_stairs 1
fill ~17~22~21 ~17~25~21 minecraft:quartz_block 0
fill ~18~6~21 ~19~6~24 minecraft:fence 0
fill ~18~7~21 ~19~7~24 minecraft:wooden_pressure_plate 0
fill ~18~15~21 ~19~15~23 minecraft:fence 0
fill ~18~16~21 ~19~16~23 minecraft:wooden_pressure_plate 0
fill ~20~6~21 ~20~6~24 minecraft:oak_stairs 0
fill ~20~15~21 ~20~15~23 minecraft:spruce_stairs 0
fill ~20~22~21 ~20~25~21 minecraft:quartz_block 0
fill ~21~1~21 ~21~1~22 minecraft:quartz_stairs 5
fill ~21~2~21 ~21~2~22 minecraft:flower_pot 0
fill ~21~4~21 ~21~4~22 minecraft:quartz_stairs 5
fill ~21~22~21 ~22~22~21 minecraft:torch 5
fill ~23~1~21 ~23~1~22 minecraft:quartz_stairs 4
setblock ~23~2~21 minecraft:stone_block_slab 14
setblock ~23~3~21 minecraft:flower_pot 0
setblock ~23~6~21 minecraft:quartz_block 2
setblock ~23~7~21 minecraft:quartz_block 1
setblock ~23~18~21 minecraft:torch 2
fill ~23~22~21 ~23~23~21 minecraft:quartz_block 0
fill ~24~0~21 ~25~0~27 minecraft:dirt 0
fill ~24~1~21 ~25~3~29 minecraft:quartz_block 0
fill ~24~15~21 ~25~18~28 minecraft:quartz_block 0
fill ~24~23~21 ~26~23~21 minecraft:quartz_block 0
fill ~25~22~21 ~25~22~22 minecraft:quartz_block 0
fill ~27~22~21 ~28~22~21 minecraft:torch 5
setblock ~28~15~21 minecraft:spruce_stairs 3
fill ~29~22~21 ~29~25~23 minecraft:quartz_block 0
setblock ~30~15~21 minecraft:spruce_stairs 3
fill ~32~15~21 ~32~18~28 minecraft:quartz_block 0
setblock ~32~22~21 minecraft:torch 5
setblock ~33~6~21 minecraft:quartz_block 1
fill ~33~7~21 ~33~12~21 minecraft:quartz_block 2
setblock ~33~13~21 minecraft:quartz_block 1
fill ~33~15~21 ~33~18~24 minecraft:wool 3
setblock ~35~19~21 minecraft:web
fill ~36~0~21 ~36~0~29 minecraft:dirt 0
setblock ~36~18~21 minecraft:web
setblock ~36~19~21 minecraft:glowstone
setblock ~36~20~21 minecraft:iron_bars
fill ~37~0~21 ~46~0~27 minecraft:quartz_block 0
setblock ~37~19~21 minecraft:web
fill ~40~15~21 ~40~20~21 minecraft:wool 3
fill ~41~19~21 ~43~20~21 minecraft:wool 3
setblock ~41~22~21 minecraft:torch 5
fill ~43~15~21 ~43~18~21 minecraft:wool 3
setblock ~44~20~21 minecraft:quartz_block 0
setblock ~45~1~21 minecraft:quartz_stairs 2
fill ~45~15~21 ~45~15~22 minecraft:planks 2
setblock ~46~19~21 minecraft:web
setblock ~46~22~21 minecraft:torch 5
fill ~47~0~21 ~47~0~29 minecraft:dirt 0
setblock ~47~18~21 minecraft:web
setblock ~47~19~21 minecraft:glowstone
setblock ~47~20~21 minecraft:iron_bars
setblock ~48~19~21 minecraft:web
fill ~51~6~21 ~51~6~23 minecraft:quartz_stairs 0
setblock ~51~10~21 minecraft:stone_block_slab 14
fill ~51~11~21 ~51~12~29 minecraft:quartz_block 0
fill ~51~13~21 ~51~13~28 minecraft:quartz_block 0
fill ~52~6~21 ~58~6~23 minecraft:quartz_block 0
fill ~52~12~21 ~57~12~23 minecraft:quartz_block 0
fill ~54~22~21 ~54~25~21 minecraft:quartz_block 0
fill ~57~22~21 ~57~25~21 minecraft:quartz_block 0
fill ~58~7~21 ~58~9~30 minecraft:quartz_block 0
fill ~59~1~21 ~59~4~21 minecraft:quartz_block 0
setblock ~59~6~21 minecraft:quartz_block 1
fill ~59~7~21 ~59~11~21 minecraft:quartz_block 2
setblock ~59~12~21 minecraft:quartz_block 1
fill ~59~15~21 ~59~20~24 minecraft:quartz_block 0
setblock ~60~1~21 minecraft:quartz_block 2
setblock ~60~2~21 minecraft:quartz_block 1
setblock ~60~3~21 minecraft:quartz_block 2
setblock ~60~4~21 minecraft:quartz_block 1
setblock ~60~5~21 minecraft:quartz_block 0
setblock ~60~6~21 minecraft:quartz_block 2
setblock ~60~7~21 minecraft:quartz_block 1
setblock ~60~10~21 minecraft:quartz_stairs 7
fill ~60~23~21 ~60~25~21 minecraft:quartz_block 0
setblock ~61~3~21 minecraft:torch 1
fill ~61~5~21 ~75~5~49 minecraft:planks 3
fill ~61~14~21 ~74~14~21 minecraft:quartz_block 0
setblock ~61~15~21 minecraft:quartz_block 2
setblock ~61~16~21 minecraft:quartz_block 1
fill ~61~22~21 ~62~22~21 minecraft:torch 5
fill ~63~22~21 ~63~25~21 minecraft:quartz_block 0
setblock ~64~1~21 minecraft:spruce_stairs 3
setblock ~65~19~21 minecraft:web
fill ~66~22~21 ~66~25~21 minecraft:quartz_block 0
fill ~67~22~21 ~68~22~21 minecraft:torch 5
setblock ~68~15~21 minecraft:bed 3
setblock ~69~15~21 minecraft:wool 0
fill ~69~22~21 ~69~25~21 minecraft:quartz_block 0
fill ~72~22~21 ~72~25~21 minecraft:quartz_block 0
setblock ~73~15~21 minecraft:iron_bars
setblock ~73~16~21 minecraft:quartz_block 2
fill ~73~22~21 ~74~22~21 minecraft:torch 5
setblock ~74~20~21 minecraft:stone_block_slab 14
setblock ~75~2~21 minecraft:torch 2
fill ~75~6~21 ~75~11~21 minecraft:wool 13
setblock ~75~14~21 minecraft:netherrack
setblock ~75~15~21 minecraft:fire 15
setblock ~75~16~21 minecraft:quartz_block 2
setblock ~75~20~21 minecraft:quartz_block 0
fill ~75~23~21 ~78~23~52 minecraft:quartz_block 0
fill ~76~1~21 ~76~3~21 minecraft:quartz_block 0
setblock ~76~6~21 minecraft:quartz_block 1
fill ~76~7~21 ~76~11~21 minecraft:quartz_block 2
setblock ~76~12~21 minecraft:quartz_block 1
fill ~76~14~21 ~77~14~51 minecraft:quartz_block 0
setblock ~76~15~21 minecraft:double_stone_block_slab 6
fill ~77~7~21 ~77~12~24 minecraft:quartz_block 0
fill ~77~16~21 ~77~19~24 minecraft:quartz_block 0
setblock ~78~12~21 minecraft:quartz_stairs 5
setblock ~78~13~21 minecraft:quartz_stairs 3
setblock ~78~20~21 minecraft:quartz_stairs 6
setblock ~79~5~21 minecraft:red_flower 3
fill ~81~5~21 ~81~5~23 minecraft:tallgrass 0
fill ~83~5~21 ~83~5~23 minecraft:tallgrass 0
fill ~2~5~22 ~2~5~25 minecraft:tallgrass 0
setblock ~4~5~22 minecraft:red_flower 0
fill ~5~5~22 ~22~5~23 minecraft:quartz_block 0
fill ~5~6~22 ~5~6~23 minecraft:quartz_block 1
fill ~5~7~22 ~5~19~23 minecraft:quartz_block 2
fill ~5~20~22 ~5~20~23 minecraft:quartz_block 1
fill ~5~25~22 ~5~25~23 minecraft:wool 7
fill ~7~15~22 ~7~19~23 minecraft:stained_hardened_clay 4
fill ~9~22~22 ~10~25~22 minecraft:quartz_block 0
setblock ~11~15~22 minecraft:quartz_stairs 6
fill ~12~1~22 ~12~4~22 minecraft:quartz_block 0
fill ~13~1~22 ~20~1~22 minecraft:quartz_stairs 7
fill ~13~4~22 ~13~4~23 minecraft:quartz_stairs 5
setblock ~14~2~22 minecraft:flower_pot 0
fill ~14~4~22 ~20~4~22 minecraft:quartz_stairs 7
setblock ~14~6~22 minecraft:jungle_stairs 7
fill ~14~7~22 ~14~7~23 minecraft:planks 3
setblock ~14~18~22 minecraft:torch 1
fill ~15~7~22 ~15~7~23 minecraft:stone_button 5
fill ~15~22~22 ~16~25~22 minecraft:quartz_block 0
fill ~16~2~22 ~18~2~22 minecraft:brewing_stand 0
fill ~17~10~22 ~20~10~22 minecraft:iron_bars
fill ~17~11~22 ~20~11~22 minecraft:glowstone
setblock ~18~3~22 minecraft:torch 3
setblock ~20~2~22 minecraft:flower_pot 0
fill ~21~22~22 ~22~25~22 minecraft:quartz_block 0
fill ~22~15~22 ~22~15~23 minecraft:wooden_button 4
setblock ~23~2~22 minecraft:flower_pot 0
fill ~23~5~22 ~23~5~23 minecraft:quartz_block 2
fill ~23~6~22 ~23~6~23 minecraft:iron_bars
fill ~23~7~22 ~23~7~23 minecraft:quartz_block 2
fill ~23~15~22 ~23~15~23 minecraft:planks 1
fill ~24~5~22 ~24~5~23 minecraft:netherrack
fill ~24~6~22 ~24~6~23 minecraft:fire 15
fill ~24~7~22 ~24~9~25 minecraft:sandstone 2
fill ~24~23~22 ~24~25~26 minecraft:quartz_block 0
fill ~25~5~22 ~31~5~23 minecraft:quartz_block 0
setblock ~25~23~22 minecraft:quartz_stairs 3
fill ~26~6~22 ~26~13~23 minecraft:quartz_block 0
fill ~26~23~22 ~26~23~23 minecraft:quartz_block 0
fill ~27~9~22 ~31~13~23 minecraft:quartz_block 0
setblock ~27~15~22 minecraft:spruce_stairs 5
setblock ~27~16~22 minecraft:flower_pot 0
fill ~28~6~22 ~31~8~23 minecraft:quartz_block 0
fill ~28~15~22 ~30~15~22 minecraft:spruce_stairs 6
setblock ~28~16~22 minecraft:rail 1
setblock ~28~18~22 minecraft:torch 4
setblock ~29~3~22 minecraft:torch 2
setblock ~30~16~22 minecraft:rail 1
setblock ~30~18~22 minecraft:torch 4
setblock ~31~15~22 minecraft:spruce_stairs 4
setblock ~31~16~22 minecraft:flower_pot 0
setblock ~36~19~22 minecraft:web
setblock ~37~15~22 minecraft:wooden_slab 2
setblock ~38~15~22 minecraft:double_wooden_slab 2
setblock ~38~16~22 minecraft:flower_pot 0
fill ~40~20~22 ~40~20~26 minecraft:quartz_stairs 5
fill ~41~11~22 ~42~11~25 minecraft:web
fill ~41~12~22 ~42~12~22 minecraft:glowstone
fill ~41~20~22 ~43~20~22 minecraft:quartz_stairs 7
fill ~44~20~22 ~44~20~27 minecraft:wool 3
setblock ~45~16~22 minecraft:flower_pot 0
setblock ~47~19~22 minecraft:web
setblock ~48~15~22 minecraft:wooden_slab 2
setblock ~49~15~22 minecraft:double_wooden_slab 2
setblock ~49~16~22 minecraft:flower_pot 0
fill ~52~5~22 ~58~5~24 minecraft:quartz_block 0
setblock ~52~17~22 minecraft:torch 1
fill ~55~22~22 ~56~25~22 minecraft:quartz_block 0
setblock ~57~17~22 minecraft:torch 2
fill ~58~0~22 ~58~0~27 minecraft:dirt 0
fill ~59~0~22 ~59~0~23 minecraft:netherrack
fill ~59~1~22 ~59~1~23 minecraft:fire 15
fill ~59~2~22 ~59~4~24 minecraft:quartz_block 0
fill ~59~5~22 ~59~5~23 minecraft:netherrack
fill ~59~6~22 ~59~6~23 minecraft:fire 15
fill ~59~7~22 ~59~12~23 minecraft:quartz_block 0
fill ~60~1~22 ~60~1~23 minecraft:iron_bars
fill ~60~2~22 ~60~2~23 minecraft:quartz_block 2
fill ~60~3~22 ~60~4~23 minecraft:quartz_stairs 5
fill ~60~5~22 ~60~5~23 minecraft:quartz_block 2
fill ~60~6~22 ~60~6~23 minecraft:iron_bars
fill ~60~7~22 ~60~7~23 minecraft:quartz_block 2
fill ~60~14~22 ~60~14~23 minecraft:netherrack
fill ~60~15~22 ~60~15~23 minecraft:fire 15
fill ~60~16~22 ~60~16~23 minecraft:quartz_block 0
setblock ~61~14~22 minecraft:double_stone_block_slab 6
fill ~61~15~22 ~61~15~23 minecraft:iron_bars
fill ~61~16~22 ~61~16~23 minecraft:quartz_block 2
fill ~61~22~22 ~62~25~22 minecraft:quartz_block 0
fill ~62~1~22 ~62~1~23 minecraft:wooden_slab 1
fill ~62~14~22 ~73~14~51 minecraft:quartz_block 0
fill ~64~1~22 ~64~1~23 minecraft:spruce_stairs 0
setblock ~64~19~22 minecraft:web
setblock ~65~18~22 minecraft:web
setblock ~65~19~22 minecraft:glowstone
setblock ~65~20~22 minecraft:iron_bars
setblock ~66~19~22 minecraft:web
fill ~67~15~22 ~67~17~22 minecraft:nether_brick_fence
setblock ~67~19~22 minecraft:nether_brick_fence
fill ~67~22~22 ~68~25~22 minecraft:quartz_block 0
setblock ~68~15~22 minecraft:wool 0
fill ~69~15~22 ~69~17~22 minecraft:nether_brick_fence
setblock ~69~19~22 minecraft:nether_brick_fence
setblock ~71~20~22 minecraft:quartz_block 0
fill ~72~20~22 ~73~20~22 minecraft:quartz_stairs 6
setblock ~73~15~22 minecraft:quartz_block 2
setblock ~73~16~22 minecraft:quartz_block 1
fill ~73~22~22 ~74~25~22 minecraft:quartz_block 0
setblock ~74~14~22 minecraft:netherrack
setblock ~74~15~22 minecraft:fire 15
setblock ~74~20~22 minecraft:quartz_block 0
fill ~75~14~22 ~75~14~51 minecraft:quartz_block 0
setblock ~75~15~22 minecraft:double_stone_block_slab 6
fill ~76~1~22 ~76~3~23 minecraft:bookshelf
fill ~76~6~22 ~76~12~23 minecraft:quartz_block 0
fill ~76~15~22 ~76~15~29 minecraft:quartz_block 0
fill ~76~16~22 ~76~20~24 minecraft:quartz_block 0
fill ~78~5~22 ~78~5~23 minecraft:quartz_block 0
fill ~78~6~22 ~78~6~23 minecraft:quartz_block 1
fill ~78~7~22 ~78~19~23 minecraft:quartz_block 2
fill ~78~20~22 ~78~20~23 minecraft:quartz_block 1
fill ~78~25~22 ~78~25~23 minecraft:wool 7
fill ~80~5~22 ~80~5~23 minecraft:tallgrass 0
setblock ~84~2~22 minecraft:dirt 0
setblock ~1~5~23 minecraft:double_plant 2
setblock ~3~5~23 minecraft:tallgrass 0
fill ~12~4~23 ~12~4~25 minecraft:quartz_block 0
fill ~12~19~23 ~12~19~27 minecraft:stained_hardened_clay 4
fill ~12~20~23 ~12~20~24 minecraft:stained_hardened_clay 4
fill ~13~19~23 ~13~20~26 minecraft:quartz_block 0
setblock ~14~6~23 minecraft:jungle_stairs 6
setblock ~14~22~23 minecraft:torch 5
fill ~17~10~23 ~17~10~25 minecraft:iron_bars
fill ~17~11~23 ~17~11~25 minecraft:glowstone
fill ~18~9~23 ~19~9~24 minecraft:iron_bars
fill ~18~10~23 ~19~10~24 minecraft:iron_block
fill ~18~11~23 ~19~13~24 minecraft:iron_bars
fill ~20~10~23 ~20~10~25 minecraft:iron_bars
fill ~20~11~23 ~20~11~25 minecraft:glowstone
fill ~23~1~23 ~23~1~25 minecraft:cauldron 6
fill ~23~2~23 ~23~2~25 minecraft:tripwire_hook 1
fill ~24~22~23 ~24~22~26 minecraft:quartz_block 0
setblock ~25~22~23 minecraft:quartz_stairs 3
fill ~26~18~23 ~31~20~23 minecraft:quartz_block 0
fill ~26~22~23 ~28~22~23 minecraft:quartz_block 0
fill ~27~15~23 ~31~17~23 minecraft:quartz_block 0
fill ~27~23~23 ~28~25~23 minecraft:quartz_block 0
fill ~30~22~23 ~32~25~23 minecraft:quartz_block 0
fill ~31~0~23 ~31~0~27 minecraft:dirt 0
fill ~31~1~23 ~31~1~29 minecraft:quartz_block 0
fill ~31~2~23 ~31~4~28 minecraft:quartz_block 0
fill ~32~0~23 ~35~0~27 minecraft:grass
setblock ~33~9~23 minecraft:torch 1
fill ~39~1~23 ~39~1~25 minecraft:dark_oak_stairs 1
fill ~39~19~23 ~39~20~27 minecraft:wool 3
fill ~40~11~23 ~40~11~24 minecraft:web
fill ~40~12~23 ~40~12~24 minecraft:glowstone
fill ~41~1~23 ~42~1~23 minecraft:wooden_slab 5
fill ~41~10~23 ~42~10~24 minecraft:web
fill ~41~12~23 ~42~13~24 minecraft:iron_bars
fill ~43~11~23 ~43~11~24 minecraft:web
fill ~43~12~23 ~43~12~24 minecraft:glowstone
fill ~43~20~23 ~43~20~26 minecraft:quartz_stairs 4
fill ~44~1~23 ~44~1~24 minecraft:dark_oak_stairs 0
fill ~44~19~23 ~44~19~27 minecraft:wool 3
setblock ~51~10~23 minecraft:stone_block_slab 14
setblock ~57~9~23 minecraft:torch 2
fill ~61~14~23 ~61~14~51 minecraft:quartz_block 0
fill ~64~15~23 ~65~15~23 minecraft:carpet 6
setblock ~65~19~23 minecraft:web
setblock ~69~15~23 minecraft:chest 4
fill ~71~19~23 ~71~20~23 minecraft:wool 6
setblock ~72~20~23 minecraft:wool 6
setblock ~74~1~23 minecraft:spruce_stairs 0
fill ~74~14~23 ~74~14~51 minecraft:quartz_block 0
setblock ~74~15~23 minecraft:double_stone_block_slab 6
setblock ~79~5~23 minecraft:yellow_flower
fill ~84~2~23 ~84~2~52 minecraft:stone 0
fill ~84~3~23 ~84~3~28 minecraft:stone 0
fill ~84~4~23 ~84~4~28 minecraft:grass
setblock ~0~5~24 minecraft:yellow_flower
fill ~5~5~24 ~5~5~27 minecraft:quartz_stairs 0
setblock ~5~12~24 minecraft:quartz_stairs 4
setblock ~5~13~24 minecraft:stone_block_slab 6
setblock ~5~20~24 minecraft:quartz_stairs 7
fill ~5~25~24 ~5~25~27 minecraft:anvil 2
fill ~6~5~24 ~27~5~25 minecraft:quartz_block 0
fill ~7~15~24 ~7~18~24 minecraft:hay_block 0
fill ~7~19~24 ~7~19~27 minecraft:hay_block 0
setblock ~8~9~24 minecraft:torch 1
fill ~9~19~24 ~10~19~24 minecraft:web
fill ~9~21~24 ~27~21~24 minecraft:quartz_block 0
fill ~9~22~24 ~9~25~24 minecraft:quartz_block 0
setblock ~10~4~24 minecraft:quartz_stairs 6
setblock ~11~2~24 minecraft:stone_block_slab 14
setblock ~11~3~24 minecraft:flower_pot 0
setblock ~11~9~24 minecraft:torch 2
fill ~12~1~24 ~12~3~25 minecraft:quartz_block 0
fill ~13~1~24 ~15~1~24 minecraft:quartz_stairs 6
setblock ~13~2~24 minecraft:flower_pot 0
fill ~13~4~24 ~15~4~24 minecraft:quartz_stairs 6
fill ~14~14~24 ~25~14~31 minecraft:quartz_block 0
setblock ~15~2~24 minecraft:flower_pot 0
setblock ~18~1~24 minecraft:quartz_stairs 4
fill ~18~2~24 ~18~2~25 minecraft:flower_pot 0
fill ~18~15~24 ~19~15~24 minecraft:spruce_stairs 2
setblock ~19~1~24 minecraft:quartz_stairs 6
setblock ~20~1~24 minecraft:quartz_stairs 5
setblock ~23~3~24 minecraft:torch 2
setblock ~23~6~24 minecraft:quartz_block 2
setblock ~23~7~24 minecraft:quartz_block 1
fill ~24~6~24 ~24~6~25 minecraft:sandstone 2
setblock ~26~13~24 minecraft:quartz_stairs 4
setblock ~26~14~24 minecraft:quartz_stairs 1
setblock ~26~24~24 minecraft:torch 3
setblock ~27~12~24 minecraft:quartz_stairs 4
setblock ~27~13~24 minecraft:quartz_stairs 1
setblock ~28~5~24 minecraft:quartz_stairs 1
setblock ~28~11~24 minecraft:quartz_stairs 4
setblock ~28~12~24 minecraft:quartz_stairs 1
setblock ~28~20~24 minecraft:quartz_stairs 4
setblock ~28~21~24 minecraft:quartz_stairs 1
setblock ~29~4~24 minecraft:quartz_stairs 1
setblock ~29~6~24 minecraft:torch 3
setblock ~29~10~24 minecraft:quartz_stairs 4
setblock ~29~11~24 minecraft:quartz_stairs 1
setblock ~29~15~24 minecraft:torch 3
setblock ~29~19~24 minecraft:quartz_stairs 4
setblock ~29~20~24 minecraft:quartz_stairs 1
setblock ~30~9~24 minecraft:quartz_stairs 4
setblock ~30~10~24 minecraft:quartz_stairs 1
setblock ~30~18~24 minecraft:quartz_stairs 4
setblock ~30~19~24 minecraft:quartz_stairs 1
fill ~31~5~24 ~31~5~56 minecraft:quartz_block 0
fill ~31~6~24 ~31~9~26 minecraft:quartz_block 0
fill ~31~18~24 ~31~18~28 minecraft:quartz_block 0
fill ~32~14~24 ~40~14~29 minecraft:quartz_block 0
fill ~32~21~24 ~77~21~29 minecraft:quartz_block 0
fill ~32~22~24 ~32~25~26 minecraft:quartz_block 0
fill ~35~20~24 ~38~20~24 minecraft:quartz_stairs 6
setblock ~37~3~24 minecraft:torch 1
setblock ~46~3~24 minecraft:torch 2
fill ~46~20~24 ~49~20~24 minecraft:quartz_stairs 6
setblock ~49~15~24 minecraft:hopper 5
fill ~49~16~24 ~49~17~24 minecraft:leaves 0
setblock ~50~20~24 minecraft:wool 3
fill ~51~6~24 ~54~6~29 minecraft:quartz_block 0
fill ~51~7~24 ~51~10~29 minecraft:quartz_block 0
fill ~51~20~24 ~51~20~28 minecraft:quartz_block 0
fill ~52~7~24 ~54~7~24 minecraft:quartz_stairs 2
fill ~52~12~24 ~54~12~24 minecraft:quartz_stairs 7
fill ~52~13~24 ~54~13~24 minecraft:quartz_stairs 2
fill ~54~0~24 ~54~0~25 minecraft:grass
fill ~55~6~24 ~57~6~24 minecraft:quartz_stairs 3
fill ~55~11~24 ~57~11~24 minecraft:quartz_stairs 6
fill ~55~12~24 ~57~12~24 minecraft:quartz_stairs 3
fill ~58~6~24 ~58~6~30 minecraft:quartz_block 0
fill ~59~0~24 ~59~0~27 minecraft:dirt 0
setblock ~59~1~24 minecraft:quartz_block 0
fill ~59~5~24 ~60~5~24 minecraft:quartz_block 0
setblock ~59~6~24 minecraft:quartz_block 1
fill ~59~7~24 ~59~11~24 minecraft:quartz_block 2
setblock ~59~12~24 minecraft:quartz_block 1
setblock ~60~1~24 minecraft:quartz_block 2
setblock ~60~2~24 minecraft:quartz_block 1
setblock ~60~3~24 minecraft:quartz_block 2
setblock ~60~4~24 minecraft:quartz_block 1
setblock ~60~6~24 minecraft:quartz_block 2
setblock ~60~7~24 minecraft:quartz_block 1
setblock ~60~10~24 minecraft:quartz_stairs 6
fill ~60~14~24 ~60~14~51 minecraft:quartz_block 0
setblock ~61~3~24 minecraft:torch 1
setblock ~61~15~24 minecraft:quartz_block 2
setblock ~61~16~24 minecraft:quartz_block 1
fill ~63~15~24 ~63~15~25 minecraft:carpet 6
setblock ~64~1~24 minecraft:spruce_stairs 2
fill ~64~15~24 ~65~15~25 minecraft:carpet 0
fill ~66~15~24 ~66~15~25 minecraft:carpet 6
fill ~67~9~24 ~68~9~24 minecraft:iron_bars
fill ~67~10~24 ~68~10~24 minecraft:glowstone
fill ~70~1~24 ~71~1~24 minecraft:wooden_slab 1
fill ~70~19~24 ~70~20~25 minecraft:wool 6
setblock ~71~20~24 minecraft:quartz_block 0
fill ~72~20~24 ~74~20~24 minecraft:quartz_stairs 7
fill ~74~15~24 ~75~15~24 minecraft:quartz_block 0
fill ~74~16~24 ~74~19~24 minecraft:glass_pane
fill ~74~22~24 ~74~25~24 minecraft:quartz_block 0
setblock ~75~2~24 minecraft:torch 2
fill ~75~6~24 ~75~12~24 minecraft:wool 13
setblock ~75~20~24 minecraft:quartz_block 0
fill ~76~1~24 ~76~3~24 minecraft:quartz_block 0
setblock ~76~6~24 minecraft:quartz_block 1
fill ~76~7~24 ~76~11~24 minecraft:quartz_block 2
setblock ~76~12~24 minecraft:quartz_block 1
fill ~78~5~24 ~78~5~27 minecraft:quartz_stairs 1
setblock ~78~12~24 minecraft:quartz_stairs 5
setblock ~78~13~24 minecraft:stone_block_slab 6
setblock ~78~20~24 minecraft:quartz_stairs 7
fill ~78~25~24 ~78~25~27 minecraft:anvil 0
setblock ~84~5~24 minecraft:tallgrass 0
fill ~0~3~25 ~0~3~42 minecraft:grass
fill ~0~4~25 ~0~4~26 minecraft:tallgrass 0
fill ~5~13~25 ~5~13~26 minecraft:stone_block_slab 14
fill ~5~20~25 ~5~20~26 minecraft:stone_block_slab 14
fill ~6~7~25 ~6~12~26 minecraft:glass_pane
fill ~6~16~25 ~6~19~26 minecraft:glass_pane
fill ~7~15~25 ~7~15~26 minecraft:stained_hardened_clay 4
fill ~8~1~25 ~8~1~27 minecraft:double_stone_block_slab 6
fill ~8~2~25 ~8~2~27 minecraft:flower_pot 0
setblock ~8~15~25 minecraft:quartz_stairs 7
setblock ~8~19~25 minecraft:web
fill ~8~22~25 ~8~22~26 minecraft:quartz_block 0
fill ~8~24~25 ~8~25~26 minecraft:glass_pane
fill ~9~19~25 ~10~19~25 minecraft:glowstone
fill ~9~20~25 ~10~20~25 minecraft:iron_bars
fill ~9~21~25 ~26~21~51 minecraft:quartz_block 0
fill ~9~22~25 ~9~22~26 minecraft:torch 5
fill ~10~4~25 ~10~4~27 minecraft:quartz_stairs 4
fill ~10~22~25 ~10~25~26 minecraft:quartz_block 0
fill ~11~1~25 ~11~4~25 minecraft:quartz_block 0
setblock ~11~19~25 minecraft:web
fill ~12~15~25 ~12~18~26 minecraft:stained_hardened_clay 4
fill ~12~20~25 ~12~20~29 minecraft:quartz_block 0
fill ~13~1~25 ~14~4~25 minecraft:quartz_block 0
fill ~13~15~25 ~13~18~26 minecraft:quartz_block 0
fill ~13~27~25 ~70~27~44 minecraft:clay
fill ~14~20~25 ~14~20~26 minecraft:quartz_block 0
fill ~15~1~25 ~15~1~26 minecraft:quartz_stairs 5
setblock ~15~3~25 minecraft:torch 1
fill ~15~4~25 ~15~4~26 minecraft:quartz_stairs 5
setblock ~15~20~25 minecraft:quartz_stairs 6
setblock ~16~20~25 minecraft:quartz_stairs 5
setblock ~18~1~25 minecraft:quartz_stairs 7
fill ~18~6~25 ~19~6~25 minecraft:oak_stairs 2
fill ~18~10~25 ~19~10~25 minecraft:iron_bars
fill ~18~11~25 ~19~11~25 minecraft:glowstone
setblock ~19~1~25 minecraft:cauldron 0
setblock ~20~1~25 minecraft:quartz_stairs 7
setblock ~21~20~25 minecraft:quartz_stairs 4
setblock ~22~20~25 minecraft:quartz_stairs 6
fill ~23~20~25 ~23~20~29 minecraft:quartz_block 0
setblock ~26~3~25 minecraft:torch 1
fill ~26~14~25 ~26~14~30 minecraft:quartz_block 0
setblock ~27~1~25 minecraft:quartz_stairs 0
setblock ~27~6~25 minecraft:quartz_stairs 0
setblock ~27~14~25 minecraft:quartz_stairs 5
setblock ~27~15~25 minecraft:quartz_stairs 0
fill ~27~21~25 ~27~22~25 minecraft:quartz_stairs 5
fill ~28~1~25 ~29~1~25 minecraft:quartz_block 0
setblock ~28~2~25 minecraft:quartz_stairs 0
setblock ~28~7~25 minecraft:quartz_stairs 0
setblock ~28~9~25 minecraft:torch 4
setblock ~28~15~25 minecraft:quartz_stairs 5
setblock ~28~16~25 minecraft:quartz_stairs 0
setblock ~28~19~25 minecraft:torch 4
fill ~29~2~25 ~29~2~28 minecraft:quartz_block 0
setblock ~29~3~25 minecraft:quartz_stairs 0
setblock ~29~8~25 minecraft:quartz_stairs 0
setblock ~29~16~25 minecraft:quartz_stairs 5
setblock ~29~17~25 minecraft:quartz_stairs 0
setblock ~30~9~25 minecraft:quartz_stairs 0
setblock ~30~17~25 minecraft:quartz_stairs 5
setblock ~30~18~25 minecraft:quartz_stairs 0
setblock ~33~6~25 minecraft:quartz_block 1
fill ~33~7~25 ~33~12~25 minecraft:quartz_block 2
setblock ~33~13~25 minecraft:quartz_block 1
fill ~33~15~25 ~33~19~25 minecraft:quartz_block 0
fill ~34~15~25 ~36~20~25 minecraft:wool 3
fill ~37~18~25 ~39~18~25 minecraft:wool 3
fill ~37~19~25 ~38~20~25 minecraft:wool 3
fill ~38~15~25 ~39~17~25 minecraft:wool 3
fill ~40~1~25 ~44~1~25 minecraft:dark_oak_stairs 2
setblock ~40~17~25 minecraft:torch 1
fill ~41~12~25 ~42~12~25 minecraft:glowstone
setblock ~43~17~25 minecraft:torch 2
fill ~44~15~25 ~45~18~25 minecraft:wool 3
fill ~45~19~25 ~49~20~25 minecraft:wool 3
fill ~46~18~25 ~49~18~25 minecraft:wool 3
fill ~47~15~25 ~49~17~25 minecraft:wool 3
setblock ~50~6~25 minecraft:quartz_block 1
fill ~50~7~25 ~50~12~25 minecraft:quartz_block 2
setblock ~50~13~25 minecraft:quartz_block 1
fill ~50~15~25 ~50~20~25 minecraft:quartz_block 0
fill ~52~5~25 ~54~5~27 minecraft:quartz_block 0
fill ~52~7~25 ~54~7~29 minecraft:quartz_block 0
fill ~52~8~25 ~54~8~25 minecraft:quartz_stairs 2
fill ~52~13~25 ~54~13~25 minecraft:quartz_stairs 7
fill ~52~14~25 ~54~14~25 minecraft:quartz_stairs 2
fill ~55~5~25 ~57~5~25 minecraft:quartz_stairs 3
fill ~55~10~25 ~57~10~25 minecraft:quartz_stairs 6
fill ~55~11~25 ~57~11~25 minecraft:quartz_stairs 3
fill ~58~5~25 ~58~5~43 minecraft:quartz_block 0
fill ~59~1~25 ~59~4~27 minecraft:bookshelf
fill ~59~5~25 ~60~5~26 minecraft:planks 3
fill ~59~10~25 ~59~12~26 minecraft:quartz_block 0
fill ~59~15~25 ~59~20~26 minecraft:wool 6
fill ~60~4~25 ~60~4~27 minecraft:quartz_stairs 5
fill ~60~10~25 ~60~10~26 minecraft:quartz_stairs 5
fill ~60~20~25 ~60~20~26 minecraft:quartz_block 0
fill ~66~9~25 ~66~9~26 minecraft:iron_bars
fill ~66~10~25 ~66~10~26 minecraft:glowstone
fill ~67~8~25 ~68~12~26 minecraft:web
fill ~67~13~25 ~68~13~26 minecraft:iron_bars
fill ~67~20~25 ~68~20~25 minecraft:quartz_stairs 6
fill ~69~9~25 ~69~9~26 minecraft:iron_bars
fill ~69~10~25 ~69~10~26 minecraft:glowstone
setblock ~69~20~25 minecraft:quartz_block 0
fill ~71~20~25 ~71~20~26 minecraft:quartz_stairs 5
fill ~73~15~25 ~73~15~26 minecraft:carpet 6
fill ~73~22~25 ~73~25~26 minecraft:quartz_block 0
setblock ~74~1~25 minecraft:spruce_stairs 0
fill ~74~15~25 ~74~15~28 minecraft:quartz_block 0
fill ~74~22~25 ~74~22~26 minecraft:torch 5
fill ~75~12~25 ~75~12~27 minecraft:wool 13
setblock ~75~15~25 minecraft:water 0
fill ~75~20~25 ~75~20~26 minecraft:quartz_stairs 4
fill ~75~24~25 ~75~25~26 minecraft:glass_pane
fill ~76~1~25 ~76~3~27 minecraft:bookshelf
fill ~76~6~25 ~76~6~26 minecraft:quartz_block 0
fill ~76~20~25 ~76~20~51 minecraft:quartz_block 0
fill ~77~7~25 ~77~12~26 minecraft:glass_pane
fill ~77~16~25 ~77~19~26 minecraft:glass_pane
fill ~78~13~25 ~78~13~26 minecraft:stone_block_slab 14
fill ~78~20~25 ~78~20~26 minecraft:stone_block_slab 14
fill ~79~0~25 ~82~0~28 minecraft:dirt 0
fill ~83~0~25 ~85~0~52 minecraft:stone 0
setblock ~3~5~26 minecraft:tallgrass 0
fill ~6~5~26 ~12~5~39 minecraft:quartz_block 0
setblock ~8~15~26 minecraft:quartz_stairs 5
setblock ~8~16~26 minecraft:brewing_stand 0
fill ~9~19~26 ~10~19~26 minecraft:web
setblock ~11~1~26 minecraft:wooden_door 2
fill ~11~3~26 ~11~4~28 minecraft:quartz_block 0
setblock ~12~3~26 minecraft:torch 3
fill ~13~1~26 ~13~4~27 minecraft:chest 4
fill ~13~5~26 ~13~5~27 minecraft:quartz_stairs 5
fill ~14~1~26 ~14~1~29 minecraft:quartz_block 0
fill ~14~2~26 ~14~5~28 minecraft:quartz_block 0
fill ~14~15~26 ~15~19~26 minecraft:quartz_block 0
setblock ~15~2~26 minecraft:flower_pot 0
fill ~15~5~26 ~30~5~43 minecraft:quartz_block 0
fill ~15~20~26 ~16~20~29 minecraft:quartz_block 0
setblock ~17~20~26 minecraft:quartz_stairs 5
setblock ~20~20~26 minecraft:quartz_stairs 4
fill ~21~20~26 ~22~20~28 minecraft:quartz_block 0
fill ~22~15~26 ~23~19~28 minecraft:quartz_block 0
setblock ~23~1~26 minecraft:quartz_stairs 4
setblock ~23~2~26 minecraft:stone_block_slab 14
setblock ~23~3~26 minecraft:flower_pot 0
fill ~25~22~26 ~31~25~26 minecraft:quartz_block 0
fill ~26~15~26 ~31~17~28 minecraft:quartz_block 0
fill ~26~18~26 ~30~20~28 minecraft:quartz_block 0
fill ~27~14~26 ~31~14~29 minecraft:quartz_block 0
fill ~27~21~26 ~31~21~51 minecraft:quartz_block 0
fill ~28~6~26 ~30~13~26 minecraft:quartz_block 0
fill ~29~1~26 ~29~1~29 minecraft:quartz_block 0
fill ~29~3~26 ~29~4~28 minecraft:quartz_block 0
fill ~30~4~26 ~30~4~28 minecraft:quartz_block 0
fill ~31~10~26 ~31~13~26 minecraft:quartz_block 0
fill ~31~19~26 ~31~20~28 minecraft:quartz_block 0
fill ~33~15~26 ~33~20~27 minecraft:wool 3
fill ~34~15~26 ~34~15~27 minecraft:water 0
setblock ~34~16~26 minecraft:tripwire_hook 0
setblock ~35~1~26 minecraft:torch 5
fill ~35~15~26 ~35~15~27 minecraft:quartz_stairs 1
fill ~36~15~26 ~36~15~27 minecraft:carpet 9
setblock ~36~17~26 minecraft:torch 3
setblock ~37~22~26 minecraft:torch 5
setblock ~38~15~26 minecraft:cauldron 6
setblock ~38~16~26 minecraft:tripwire_hook 1
fill ~39~15~26 ~39~18~27 minecraft:wool 3
fill ~40~15~26 ~40~16~26 minecraft:planks 2
setblock ~41~15~26 minecraft:wooden_button 5
fill ~43~15~26 ~43~15~27 minecraft:planks 2
setblock ~43~16~26 minecraft:flower_pot 0
fill ~44~15~26 ~44~18~27 minecraft:wool 3
setblock ~45~15~26 minecraft:cauldron 6
setblock ~45~16~26 minecraft:tripwire_hook 3
setblock ~46~22~26 minecraft:torch 5
fill ~47~15~26 ~47~15~27 minecraft:carpet 9
setblock ~47~17~26 minecraft:torch 3
fill ~48~15~26 ~48~15~27 minecraft:quartz_stairs 0
setblock ~49~15~26 minecraft:water 1
setblock ~49~16~26 minecraft:tripwire_hook 0
fill ~50~15~26 ~50~20~27 minecraft:wool 3
fill ~52~8~26 ~54~8~29 minecraft:quartz_block 0
fill ~52~9~26 ~54~9~26 minecraft:quartz_stairs 2
fill ~52~14~26 ~54~14~29 minecraft:quartz_block 0
fill ~54~0~26 ~57~0~29 minecraft:dirt 0
fill ~54~1~26 ~57~1~28 minecraft:quartz_block 0
fill ~54~2~26 ~58~2~27 minecraft:quartz_block 0
fill ~54~3~26 ~58~3~26 minecraft:quartz_block 0
fill ~54~4~26 ~54~4~27 minecraft:quartz_block 0
fill ~55~4~26 ~57~4~26 minecraft:quartz_stairs 3
fill ~55~9~26 ~57~9~26 minecraft:quartz_stairs 6
fill ~55~10~26 ~57~10~26 minecraft:quartz_stairs 3
fill ~55~14~26 ~57~14~26 minecraft:quartz_stairs 6
fill ~55~15~26 ~57~15~26 minecraft:anvil 3
fill ~58~4~26 ~58~4~30 minecraft:quartz_block 0
fill ~64~15~26 ~65~15~26 minecraft:carpet 6
setblock ~64~22~26 minecraft:torch 5
setblock ~67~20~26 minecraft:quartz_stairs 4
fill ~68~15~26 ~69~20~26 minecraft:wool 6
fill ~70~15~26 ~70~20~28 minecraft:quartz_block 0
setblock ~71~15~26 minecraft:carpet 6
setblock ~75~15~26 minecraft:water 1
setblock ~82~5~26 minecraft:tallgrass 0
setblock ~0~4~27 minecraft:yellow_flower
fill ~1~3~27 ~1~3~39 minecraft:grass
setblock ~2~5~27 minecraft:tallgrass 0
setblock ~5~12~27 minecraft:quartz_stairs 4
setblock ~5~13~27 minecraft:stone_block_slab 6
setblock ~5~20~27 minecraft:quartz_stairs 6
fill ~6~7~27 ~7~12~30 minecraft:quartz_block 0
fill ~6~16~27 ~6~19~30 minecraft:quartz_block 0
fill ~7~15~27 ~7~18~27 minecraft:hay_block 0
fill ~8~4~27 ~9~4~27 minecraft:quartz_stairs 6
fill ~8~6~27 ~9~6~27 minecraft:quartz_stairs 6
setblock ~8~15~27 minecraft:quartz_stairs 6
fill ~8~20~27 ~8~20~29 minecraft:quartz_block 0
fill ~8~24~27 ~9~25~27 minecraft:quartz_block 0
setblock ~9~9~27 minecraft:torch 4
fill ~9~13~27 ~10~13~27 minecraft:quartz_stairs 6
fill ~9~20~27 ~10~20~27 minecraft:quartz_stairs 6
fill ~9~22~27 ~9~23~27 minecraft:quartz_block 0
setblock ~10~1~27 minecraft:torch 5
setblock ~11~1~27 minecraft:wooden_door 2
fill ~11~20~27 ~11~20~29 minecraft:quartz_block 0
setblock ~12~3~27 minecraft:torch 4
fill ~12~6~27 ~12~9~28 minecraft:quartz_block 0
fill ~12~18~27 ~12~18~28 minecraft:stained_hardened_clay 4
fill ~13~6~27 ~13~9~27 minecraft:sandstone 2
fill ~13~15~27 ~14~15~27 minecraft:stone_pressure_plate 0
setblock ~14~13~27 minecraft:quartz_block 0
fill ~15~1~27 ~17~1~27 minecraft:quartz_stairs 6
fill ~15~4~27 ~23~4~27 minecraft:quartz_stairs 6
fill ~15~13~27 ~22~13~27 minecraft:quartz_stairs 6
fill ~15~15~27 ~16~19~28 minecraft:quartz_block 0
fill ~16~2~27 ~17~2~27 minecraft:stone_block_slab 14
fill ~16~3~27 ~17~3~27 minecraft:flower_pot 0
setblock ~17~18~27 minecraft:torch 4
fill ~17~20~27 ~17~20~29 minecraft:quartz_block 0
fill ~18~1~27 ~20~1~27 minecraft:furnace 2
fill ~18~2~27 ~20~2~27 minecraft:trapdoor 3
setblock ~18~3~27 minecraft:quartz_stairs 0
fill ~18~20~27 ~19~20~27 minecraft:quartz_stairs 6
setblock ~19~3~27 minecraft:quartz_stairs 2
setblock ~20~3~27 minecraft:quartz_stairs 1
setblock ~20~18~27 minecraft:torch 4
fill ~20~20~27 ~20~20~29 minecraft:quartz_block 0
fill ~21~1~27 ~23~1~27 minecraft:quartz_stairs 6
fill ~21~15~27 ~21~19~28 minecraft:quartz_block 0
fill ~22~2~27 ~23~2~27 minecraft:flower_pot 0
setblock ~23~13~27 minecraft:quartz_block 0
fill ~24~6~27 ~24~9~27 minecraft:sandstone 2
fill ~25~6~27 ~25~9~30 minecraft:quartz_block 0
fill ~28~6~27 ~28~13~28 minecraft:quartz_block 0
setblock ~33~9~27 minecraft:torch 1
fill ~34~16~27 ~34~17~27 minecraft:water 9
setblock ~34~18~27 minecraft:water 1
fill ~35~16~27 ~35~18~27 minecraft:stained_glass_pane 8
setblock ~38~15~27 minecraft:hopper 5
setblock ~38~16~27 minecraft:stone_button 4
setblock ~39~3~27 minecraft:torch 4
fill ~40~20~27 ~43~20~27 minecraft:quartz_stairs 6
setblock ~44~3~27 minecraft:torch 4
setblock ~45~15~27 minecraft:hopper 4
setblock ~45~16~27 minecraft:stone_button 5
fill ~48~16~27 ~48~18~27 minecraft:stained_glass_pane 8
setblock ~49~1~27 minecraft:torch 5
fill ~49~15~27 ~49~17~27 minecraft:water 9
setblock ~49~18~27 minecraft:water 1
setblock ~50~9~27 minecraft:torch 2
fill ~52~9~27 ~57~9~29 minecraft:quartz_block 0
setblock ~53~17~27 minecraft:torch 4
fill ~53~20~27 ~57~20~27 minecraft:quartz_stairs 6
setblock ~54~3~27 minecraft:stained_hardened_clay 3
fill ~55~3~27 ~57~3~27 minecraft:quartz_stairs 3
fill ~55~8~27 ~57~8~27 minecraft:quartz_stairs 6
fill ~55~14~27 ~57~14~29 minecraft:quartz_block 0
setblock ~56~17~27 minecraft:torch 4
setblock ~57~22~27 minecraft:torch 5
fill ~58~3~27 ~58~3~29 minecraft:stained_hardened_clay 3
fill ~59~5~27 ~59~5~32 minecraft:quartz_block 0
setblock ~59~6~27 minecraft:quartz_block 1
fill ~59~7~27 ~59~11~27 minecraft:quartz_block 2
setblock ~59~12~27 minecraft:quartz_block 1
fill ~59~15~27 ~59~20~29 minecraft:quartz_block 0
fill ~60~5~27 ~60~5~42 minecraft:planks 3
setblock ~60~10~27 minecraft:quartz_stairs 7
fill ~60~15~27 ~60~20~27 minecraft:wool 6
setblock ~61~2~27 minecraft:torch 4
fill ~61~4~27 ~74~4~27 minecraft:quartz_stairs 6
setblock ~61~20~27 minecraft:quartz_block 0
fill ~62~20~27 ~66~20~27 minecraft:quartz_stairs 6
setblock ~64~2~27 minecraft:torch 4
fill ~67~9~27 ~68~9~27 minecraft:iron_bars
fill ~67~10~27 ~68~10~27 minecraft:glowstone
setblock ~67~20~27 minecraft:quartz_block 0
setblock ~68~2~27 minecraft:torch 4
fill ~68~18~27 ~69~18~28 minecraft:wool 6
fill ~68~19~27 ~68~20~27 minecraft:wool 6
fill ~69~1~27 ~72~1~27 minecraft:spruce_stairs 2
fill ~69~15~27 ~69~17~28 minecraft:wool 6
setblock ~71~15~27 minecraft:hopper 0
setblock ~71~16~27 minecraft:stone_button 2
fill ~71~20~27 ~71~20~28 minecraft:quartz_block 0
fill ~72~20~27 ~74~20~27 minecraft:quartz_stairs 6
setblock ~73~2~27 minecraft:torch 4
fill ~74~16~27 ~74~19~27 minecraft:glass_pane
fill ~74~22~27 ~74~22~29 minecraft:quartz_block 0
fill ~74~23~27 ~74~25~27 minecraft:quartz_block 0
fill ~75~6~27 ~75~11~27 minecraft:wool 13
fill ~75~15~27 ~75~18~27 minecraft:water 9
setblock ~75~19~27 minecraft:water 1
fill ~75~20~27 ~75~20~28 minecraft:quartz_block 0
fill ~75~24~27 ~75~25~29 minecraft:quartz_block 0
setblock ~76~6~27 minecraft:quartz_block 1
fill ~76~7~27 ~76~11~27 minecraft:quartz_block 2
setblock ~76~12~27 minecraft:quartz_block 1
fill ~76~16~27 ~77~19~29 minecraft:quartz_block 0
fill ~77~7~27 ~77~12~30 minecraft:quartz_block 0
setblock ~78~12~27 minecraft:quartz_stairs 5
setblock ~78~13~27 minecraft:stone_block_slab 6
setblock ~78~20~27 minecraft:quartz_stairs 6
fill ~85~4~27 ~85~4~31 minecraft:tallgrass 0
fill ~0~0~28 ~4~0~56 minecraft:dirt 0
fill ~5~0~28 ~7~0~29 minecraft:quartz_block 0
fill ~5~5~28 ~5~5~30 minecraft:quartz_block 0
fill ~5~6~28 ~5~6~30 minecraft:quartz_block 1
fill ~5~7~28 ~5~11~30 minecraft:quartz_block 2
fill ~5~12~28 ~5~19~29 minecraft:quartz_block 2
fill ~5~20~28 ~5~20~29 minecraft:quartz_block 1
fill ~5~25~28 ~5~25~29 minecraft:wool 7
fill ~7~15~28 ~7~19~29 minecraft:quartz_block 0
fill ~8~1~28 ~8~1~29 minecraft:quartz_block 0
fill ~8~2~28 ~8~4~28 minecraft:quartz_block 0
fill ~8~6~28 ~9~13~28 minecraft:quartz_block 0
fill ~8~15~28 ~9~19~28 minecraft:stained_hardened_clay 4
setblock ~8~22~28 minecraft:torch 5
fill ~8~24~28 ~8~25~30 minecraft:quartz_block 0
fill ~9~4~28 ~10~4~29 minecraft:quartz_block 0
fill ~9~20~28 ~10~20~29 minecraft:quartz_block 0
fill ~10~10~28 ~11~13~29 minecraft:quartz_block 0
fill ~10~19~28 ~11~19~28 minecraft:stained_hardened_clay 4
fill ~11~1~28 ~13~1~29 minecraft:quartz_block 0
fill ~11~2~28 ~13~2~28 minecraft:quartz_block 0
fill ~12~3~28 ~13~4~28 minecraft:quartz_block 0
fill ~12~15~28 ~12~17~28 minecraft:stained_hardened_clay 4
setblock ~12~19~28 minecraft:quartz_block 0
fill ~13~5~28 ~13~5~52 minecraft:quartz_block 0
fill ~13~6~28 ~13~13~29 minecraft:quartz_block 0
fill ~13~15~28 ~14~15~28 minecraft:iron_door 1
fill ~13~17~28 ~14~17~28 minecraft:quartz_block 0
fill ~14~6~28 ~19~13~28 minecraft:sandstone 2
fill ~15~1~28 ~23~1~29 minecraft:quartz_block 0
fill ~15~2~28 ~23~4~28 minecraft:quartz_block 0
fill ~17~15~28 ~17~19~28 minecraft:quartz_block 0
fill ~18~19~28 ~20~19~28 minecraft:quartz_block 0
fill ~18~20~28 ~19~20~29 minecraft:quartz_block 0
fill ~20~10~28 ~23~13~28 minecraft:sandstone 2
fill ~20~15~28 ~20~18~28 minecraft:quartz_block 0
fill ~22~6~28 ~23~9~28 minecraft:sandstone 2
fill ~24~0~28 ~25~0~29 minecraft:quartz_block 0
fill ~24~6~28 ~24~13~31 minecraft:quartz_block 0
fill ~25~22~28 ~73~22~29 minecraft:quartz_block 0
fill ~26~1~28 ~26~1~29 minecraft:quartz_block 0
fill ~26~2~28 ~26~4~28 minecraft:quartz_block 0
fill ~26~6~28 ~27~13~28 minecraft:quartz_block 0
fill ~27~4~28 ~28~4~29 minecraft:quartz_block 0
fill ~29~6~28 ~31~12~29 minecraft:quartz_block 0
fill ~29~13~28 ~31~13~28 minecraft:quartz_block 0
fill ~31~0~28 ~31~0~29 minecraft:quartz_block 0
fill ~32~0~28 ~35~0~28 minecraft:dirt 0
fill ~32~1~28 ~33~3~28 minecraft:noteblock
fill ~32~4~28 ~35~4~28 minecraft:quartz_block 0
fill ~33~15~28 ~33~17~28 minecraft:quartz_block 0
setblock ~33~18~28 minecraft:wool 3
fill ~33~19~28 ~33~20~28 minecraft:quartz_block 0
fill ~34~1~28 ~35~1~29 minecraft:quartz_block 0
fill ~34~2~28 ~35~3~28 minecraft:quartz_block 0
fill ~34~15~28 ~38~17~28 minecraft:wool 3
setblock ~34~18~28 minecraft:water 0
fill ~34~19~28 ~38~20~28 minecraft:wool 3
fill ~35~18~28 ~38~18~28 minecraft:wool 3
fill ~37~0~28 ~40~0~29 minecraft:dirt 0
fill ~37~1~28 ~40~4~28 minecraft:stained_hardened_clay 14
fill ~39~15~28 ~39~20~28 minecraft:quartz_block 0
fill ~40~15~28 ~40~20~28 minecraft:wool 3
fill ~41~0~28 ~42~0~28 minecraft:quartz_block 0
fill ~41~4~28 ~47~4~28 minecraft:stained_hardened_clay 14
fill ~41~19~28 ~43~20~28 minecraft:wool 3
fill ~43~0~28 ~46~0~29 minecraft:dirt 0
fill ~43~1~28 ~46~3~28 minecraft:stained_hardened_clay 14
fill ~43~15~28 ~43~18~28 minecraft:wool 3
fill ~44~15~28 ~44~20~28 minecraft:quartz_block 0
fill ~45~15~28 ~49~17~28 minecraft:wool 3
fill ~45~18~28 ~48~20~28 minecraft:wool 3
fill ~47~1~28 ~47~2~28 minecraft:stained_hardened_clay 2
setblock ~47~3~28 minecraft:stained_hardened_clay 14
fill ~48~0~28 ~53~0~28 minecraft:dirt 0
fill ~48~1~28 ~49~1~29 minecraft:quartz_block 0
fill ~48~2~28 ~49~4~28 minecraft:quartz_block 0
setblock ~49~18~28 minecraft:water 0
fill ~49~19~28 ~49~20~28 minecraft:wool 3
fill ~50~1~28 ~51~3~28 minecraft:noteblock
fill ~50~4~28 ~53~4~28 minecraft:quartz_block 0
fill ~50~15~28 ~50~17~28 minecraft:quartz_block 0
setblock ~50~18~28 minecraft:wool 3
fill ~50~19~28 ~50~20~28 minecraft:quartz_block 0
fill ~52~1~28 ~53~1~28 minecraft:quartz_block 0
fill ~52~2~28 ~52~3~28 minecraft:quartz_block 0
fill ~52~5~28 ~53~5~54 minecraft:quartz_block 0
fill ~52~15~28 ~53~20~28 minecraft:quartz_block 0
fill ~53~2~28 ~53~3~28 minecraft:stained_hardened_clay 3
fill ~54~2~28 ~57~2~28 minecraft:quartz_stairs 3
fill ~54~5~28 ~54~5~30 minecraft:quartz_stairs 5
fill ~54~19~28 ~57~20~28 minecraft:quartz_block 0
fill ~55~7~28 ~57~7~28 minecraft:quartz_stairs 6
fill ~55~8~28 ~57~8~29 minecraft:quartz_block 0
fill ~56~15~28 ~57~18~28 minecraft:quartz_block 0
fill ~58~0~28 ~59~0~29 minecraft:quartz_block 0
fill ~58~2~28 ~58~2~29 minecraft:stained_hardened_clay 3
fill ~59~1~28 ~59~4~29 minecraft:quartz_block 0
fill ~59~6~28 ~59~12~31 minecraft:quartz_block 0
fill ~60~1~28 ~60~4~28 minecraft:bookshelf
fill ~60~15~28 ~60~20~28 minecraft:quartz_block 0
fill ~61~1~28 ~61~2~28 minecraft:quartz_block 2
setblock ~61~3~28 minecraft:quartz_block 1
fill ~61~4~28 ~66~4~28 minecraft:quartz_block 0
fill ~61~15~28 ~65~20~28 minecraft:wool 6
fill ~64~1~28 ~64~2~28 minecraft:quartz_block 2
setblock ~64~3~28 minecraft:quartz_block 1
fill ~65~1~28 ~67~2~28 minecraft:bookshelf
fill ~65~3~28 ~66~3~28 minecraft:bookshelf
fill ~66~19~28 ~67~20~28 minecraft:wool 6
setblock ~67~3~28 minecraft:chest 2
setblock ~67~4~28 minecraft:quartz_stairs 2
fill ~68~1~28 ~68~1~29 minecraft:quartz_block 0
fill ~68~2~28 ~68~4~28 minecraft:quartz_block 0
fill ~68~15~28 ~68~17~28 minecraft:wool 6
fill ~68~19~28 ~68~20~28 minecraft:quartz_block 0
fill ~69~1~28 ~72~3~28 minecraft:bookshelf
fill ~69~4~28 ~75~4~28 minecraft:quartz_block 0
fill ~69~19~28 ~69~20~28 minecraft:wool 6
fill ~71~15~28 ~71~19~28 minecraft:quartz_block 0
fill ~72~19~28 ~74~20~28 minecraft:quartz_block 0
fill ~73~1~28 ~73~1~29 minecraft:quartz_block 0
fill ~73~2~28 ~73~3~28 minecraft:quartz_block 0
fill ~74~1~28 ~75~3~28 minecraft:bookshelf
fill ~74~16~28 ~75~18~28 minecraft:quartz_block 0
setblock ~75~15~28 minecraft:quartz_block 0
setblock ~75~19~28 minecraft:water 0
fill ~76~1~28 ~76~1~39 minecraft:quartz_block 0
fill ~76~2~28 ~76~3~29 minecraft:quartz_block 0
fill ~76~6~28 ~76~12~29 minecraft:quartz_block 0
fill ~78~5~28 ~78~5~30 minecraft:quartz_block 0
fill ~78~6~28 ~78~6~30 minecraft:quartz_block 1
fill ~78~7~28 ~78~11~30 minecraft:quartz_block 2
fill ~78~12~28 ~78~19~29 minecraft:quartz_block 2
fill ~78~20~28 ~78~20~29 minecraft:quartz_block 1
fill ~78~25~28 ~78~25~29 minecraft:wool 7
setblock ~84~5~28 minecraft:red_flower 3
setblock ~8~0~29 minecraft:quartz_block 0
fill ~8~2~29 ~8~4~29 minecraft:stained_hardened_clay 3
fill ~8~6~29 ~8~13~29 minecraft:quartz_block 0
fill ~8~15~29 ~9~15~29 minecraft:quartz_block 1
fill ~8~16~29 ~9~19~29 minecraft:sandstone 2
fill ~9~0~29 ~10~0~38 minecraft:sandstone 0
setblock ~9~6~29 minecraft:quartz_block 1
fill ~9~7~29 ~9~11~29 minecraft:quartz_block 2
setblock ~9~12~29 minecraft:quartz_block 1
setblock ~9~13~29 minecraft:quartz_block 0
fill ~10~19~29 ~12~19~29 minecraft:sandstone 2
fill ~11~0~29 ~23~0~29 minecraft:quartz_block 0
fill ~11~2~29 ~23~4~29 minecraft:stained_hardened_clay 3
setblock ~12~6~29 minecraft:quartz_block 1
fill ~12~7~29 ~12~11~29 minecraft:quartz_block 2
setblock ~12~12~29 minecraft:quartz_block 1
setblock ~12~13~29 minecraft:quartz_block 0
setblock ~12~15~29 minecraft:quartz_block 1
fill ~12~16~29 ~12~18~29 minecraft:sandstone 2
fill ~13~15~29 ~14~15~29 minecraft:chest 2
fill ~13~16~29 ~14~16~29 minecraft:sandstone_stairs 6
fill ~13~17~29 ~13~19~29 minecraft:sandstone 0
fill ~13~20~29 ~14~20~29 minecraft:quartz_block 0
fill ~14~5~29 ~14~5~51 minecraft:quartz_block 0
fill ~14~6~29 ~18~13~29 minecraft:quartz_block 0
fill ~14~17~29 ~15~18~29 minecraft:sandstone 2
fill ~14~19~29 ~16~19~29 minecraft:sandstone 0
fill ~15~15~29 ~17~15~29 minecraft:quartz_block 1
fill ~15~16~29 ~16~16~29 minecraft:sandstone 0
fill ~16~17~29 ~16~18~29 minecraft:sandstone 0
fill ~17~16~29 ~17~19~29 minecraft:sandstone 2
fill ~18~19~29 ~23~19~29 minecraft:sandstone 2
setblock ~19~6~29 minecraft:quartz_block 1
fill ~19~7~29 ~19~11~29 minecraft:quartz_block 2
setblock ~19~12~29 minecraft:quartz_block 1
fill ~19~13~29 ~23~13~29 minecraft:quartz_block 0
fill ~20~10~29 ~21~12~29 minecraft:quartz_block 0
fill ~20~15~29 ~23~15~29 minecraft:quartz_block 1
fill ~20~16~29 ~20~18~29 minecraft:sandstone 2
fill ~21~16~29 ~22~16~30 minecraft:planks 1
fill ~21~17~29 ~23~18~29 minecraft:sandstone 2
setblock ~21~20~29 minecraft:sandstone 2
setblock ~22~6~29 minecraft:quartz_block 1
fill ~22~7~29 ~22~11~29 minecraft:quartz_block 2
setblock ~22~12~29 minecraft:quartz_block 1
setblock ~22~20~29 minecraft:quartz_block 0
fill ~23~6~29 ~23~12~29 minecraft:quartz_block 0
setblock ~23~16~29 minecraft:sandstone 2
fill ~24~15~29 ~24~20~29 minecraft:quartz_block 0
fill ~25~15~29 ~40~20~29 minecraft:stained_hardened_clay 4
setblock ~26~0~29 minecraft:quartz_block 0
fill ~26~2~29 ~26~4~29 minecraft:stained_hardened_clay 3
fill ~26~6~29 ~26~12~29 minecraft:quartz_block 0
fill ~26~13~29 ~57~13~29 minecraft:quartz_block 1
fill ~27~0~29 ~28~0~37 minecraft:sandstone 0
fill ~27~6~29 ~28~6~29 minecraft:quartz_block 1
fill ~27~7~29 ~28~11~29 minecraft:quartz_block 2
fill ~27~12~29 ~28~12~29 minecraft:quartz_block 1
fill ~29~0~29 ~30~0~29 minecraft:quartz_block 0
fill ~29~2~29 ~31~4~29 minecraft:stained_hardened_clay 3
fill ~32~0~29 ~33~0~37 minecraft:sandstone 0
fill ~32~4~29 ~33~4~29 minecraft:quartz_block 0
setblock ~33~6~29 minecraft:quartz_block 1
fill ~33~7~29 ~33~11~29 minecraft:quartz_block 2
setblock ~33~12~29 minecraft:quartz_block 1
fill ~34~0~29 ~35~0~29 minecraft:dirt 0
fill ~34~2~29 ~34~4~29 minecraft:stained_hardened_clay 3
fill ~35~2~29 ~36~4~29 minecraft:quartz_block 0
fill ~36~1~29 ~36~1~30 minecraft:quartz_block 1
fill ~37~1~29 ~40~1~29 minecraft:quartz_block 0
fill ~37~2~29 ~40~3~29 minecraft:stained_hardened_clay 3
fill ~37~4~29 ~42~4~29 minecraft:quartz_block 0
fill ~38~6~29 ~39~6~29 minecraft:quartz_block 1
fill ~38~7~29 ~39~11~29 minecraft:quartz_block 2
fill ~38~12~29 ~39~12~29 minecraft:quartz_block 1
fill ~41~0~29 ~42~0~38 minecraft:sandstone 0
fill ~41~19~29 ~58~20~29 minecraft:stained_hardened_clay 4
fill ~43~1~29 ~47~1~29 minecraft:quartz_block 0
fill ~43~2~29 ~46~4~29 minecraft:stained_hardened_clay 3
fill ~43~15~29 ~53~18~29 minecraft:stained_hardened_clay 4
fill ~44~6~29 ~45~6~29 minecraft:quartz_block 1
fill ~44~7~29 ~45~11~29 minecraft:quartz_block 2
fill ~44~12~29 ~45~12~29 minecraft:quartz_block 1
fill ~47~2~29 ~48~4~29 minecraft:quartz_block 0
fill ~48~0~29 ~49~0~29 minecraft:dirt 0
fill ~49~2~29 ~49~4~29 minecraft:stained_hardened_clay 3
fill ~50~0~29 ~51~0~37 minecraft:sandstone 0
fill ~50~4~29 ~52~4~29 minecraft:quartz_block 0
setblock ~50~6~29 minecraft:quartz_block 1
fill ~50~7~29 ~50~11~29 minecraft:quartz_block 2
setblock ~50~12~29 minecraft:quartz_block 1
fill ~52~0~29 ~53~0~29 minecraft:dirt 0
setblock ~52~1~29 minecraft:quartz_block 0
fill ~52~2~29 ~52~3~29 minecraft:stained_hardened_clay 3
fill ~52~10~29 ~57~10~29 minecraft:anvil 1
fill ~53~1~29 ~57~1~29 minecraft:quartz_stairs 3
fill ~53~4~29 ~53~4~30 minecraft:quartz_stairs 5
fill ~55~6~29 ~57~6~29 minecraft:quartz_stairs 6
fill ~55~7~29 ~57~7~29 minecraft:quartz_block 0
fill ~56~15~29 ~58~18~29 minecraft:stained_hardened_clay 4
setblock ~58~1~29 minecraft:stained_hardened_clay 3
fill ~58~23~29 ~74~25~29 minecraft:quartz_block 0
fill ~60~0~29 ~61~1~29 minecraft:quartz_block 0
fill ~60~2~29 ~61~4~29 minecraft:stained_hardened_clay 3
fill ~60~15~29 ~65~19~29 minecraft:gold_block
fill ~60~20~29 ~69~20~29 minecraft:quartz_block 0
fill ~62~0~29 ~63~0~38 minecraft:sandstone 0
fill ~62~4~29 ~63~4~29 minecraft:quartz_block 0
fill ~64~0~29 ~78~0~29 minecraft:quartz_block 0
fill ~64~1~29 ~67~1~29 minecraft:quartz_block 0
fill ~64~2~29 ~75~4~29 minecraft:stained_hardened_clay 3
fill ~66~19~29 ~75~19~29 minecraft:gold_block
fill ~68~15~29 ~68~18~29 minecraft:gold_block
fill ~69~1~29 ~72~1~29 minecraft:quartz_block 0
fill ~69~15~29 ~70~16~29 minecraft:planks 1
fill ~69~17~29 ~71~18~29 minecraft:gold_block
fill ~70~20~29 ~75~20~29 minecraft:gold_block
fill ~71~15~29 ~71~16~29 minecraft:gold_block
fill ~74~1~29 ~75~1~29 minecraft:quartz_block 0
fill ~74~15~29 ~75~18~29 minecraft:gold_block
setblock ~77~24~29 minecraft:quartz_stairs 3
fill ~79~0~29 ~80~0~38 minecraft:stone 0
fill ~81~0~29 ~82~0~29 minecraft:wool 0
setblock ~83~5~29 minecraft:tallgrass 0
fill ~84~3~29 ~84~3~42 minecraft:grass
fill ~84~4~29 ~84~4~31 minecraft:tallgrass 0
fill ~5~0~30 ~7~0~54 minecraft:dirt 0
fill ~5~2~30 ~6~4~49 minecraft:quartz_block 0
setblock ~5~12~30 minecraft:quartz_block 1
fill ~5~13~30 ~5~13~32 minecraft:quartz_stairs 4
setblock ~5~20~30 minecraft:quartz_stairs 7
fill ~5~25~30 ~5~25~37 minecraft:anvil 2
fill ~7~2~30 ~7~4~37 minecraft:stained_hardened_clay 3
fill ~7~15~30 ~7~19~31 minecraft:sand 0
fill ~8~0~30 ~8~0~37 minecraft:sandstone 0
fill ~8~4~30 ~23~4~30 minecraft:quartz_stairs 7
fill ~8~9~30 ~8~9~31 minecraft:torch 1
setblock ~8~13~30 minecraft:quartz_block 0
fill ~8~20~30 ~8~20~36 minecraft:quartz_stairs 5
fill ~9~13~30 ~22~13~30 minecraft:quartz_stairs 7
setblock ~9~18~30 minecraft:torch 3
fill ~9~20~30 ~23~20~30 minecraft:quartz_stairs 7
fill ~9~22~30 ~9~25~30 minecraft:quartz_block 0
fill ~11~0~30 ~26~0~37 minecraft:sandstone 0
setblock ~12~3~30 minecraft:torch 3
setblock ~12~18~30 minecraft:torch 3
fill ~13~9~30 ~14~9~30 minecraft:torch 3
fill ~13~15~30 ~16~15~30 minecraft:planks 1
setblock ~14~16~30 minecraft:flower_pot 0
setblock ~16~16~30 minecraft:torch 5
fill ~17~9~30 ~18~9~30 minecraft:torch 3
setblock ~17~18~30 minecraft:torch 3
setblock ~18~3~30 minecraft:torch 3
fill ~18~28~30 ~65~28~39 minecraft:clay
setblock ~20~18~30 minecraft:torch 3
fill ~21~15~30 ~22~15~30 minecraft:planks 1
fill ~23~9~30 ~23~9~31 minecraft:torch 2
setblock ~23~13~30 minecraft:quartz_block 0
fill ~24~1~30 ~25~1~30 minecraft:quartz_block 1
fill ~24~2~30 ~25~2~30 minecraft:quartz_block 2
fill ~24~3~30 ~25~3~30 minecraft:quartz_block 1
fill ~24~15~30 ~24~15~32 minecraft:quartz_block 1
fill ~24~16~30 ~24~19~32 minecraft:sandstone 2
fill ~24~20~30 ~24~20~37 minecraft:quartz_block 0
setblock ~24~22~30 minecraft:torch 5
fill ~25~13~30 ~25~13~37 minecraft:quartz_block 1
fill ~25~15~30 ~25~20~32 minecraft:stained_hardened_clay 4
fill ~25~22~30 ~25~22~38 minecraft:quartz_block 0
fill ~26~4~30 ~34~4~30 minecraft:quartz_stairs 7
fill ~26~20~30 ~48~20~30 minecraft:quartz_stairs 7
fill ~27~14~30 ~56~14~30 minecraft:quartz_stairs 7
fill ~29~0~30 ~31~0~37 minecraft:sandstone 0
fill ~29~15~30 ~30~15~30 minecraft:spruce_stairs 3
setblock ~30~3~30 minecraft:torch 3
fill ~30~6~30 ~31~6~30 minecraft:nether_brick_stairs 3
setblock ~31~17~30 minecraft:torch 3
setblock ~32~15~30 minecraft:spruce_stairs 7
setblock ~32~16~30 minecraft:flower_pot 0
fill ~32~21~30 ~58~21~48 minecraft:quartz_block 0
fill ~34~0~30 ~40~0~37 minecraft:sandstone 0
fill ~34~15~30 ~35~15~30 minecraft:spruce_stairs 3
setblock ~35~1~30 minecraft:quartz_block 1
fill ~35~2~30 ~36~2~30 minecraft:quartz_block 2
fill ~35~3~30 ~36~3~30 minecraft:quartz_block 1
fill ~35~4~30 ~36~4~30 minecraft:quartz_block 0
fill ~37~4~30 ~46~4~30 minecraft:quartz_stairs 7
setblock ~38~15~30 minecraft:spruce_stairs 7
setblock ~38~16~30 minecraft:flower_pot 0
setblock ~39~3~30 minecraft:torch 3
setblock ~39~17~30 minecraft:torch 3
fill ~43~0~30 ~49~0~37 minecraft:sandstone 0
setblock ~44~3~30 minecraft:torch 3
setblock ~44~15~30 minecraft:spruce_stairs 7
setblock ~44~16~30 minecraft:flower_pot 0
setblock ~44~17~30 minecraft:torch 3
fill ~46~15~30 ~47~15~30 minecraft:spruce_stairs 3
