fill ~11~0~1 ~19~0~0 minecraft:grass
fill ~8~0~1 ~13~0~1 minecraft:grass
fill ~14~0~1 ~16~0~29 minecraft:dirt 0
fill ~14~1~1 ~16~1~2 minecraft:grass
fill ~17~0~1 ~33~0~1 minecraft:grass
fill ~6~0~2 ~11~0~2 minecraft:grass
fill ~12~0~2 ~13~0~36 minecraft:dirt 0
fill ~12~1~2 ~13~1~2 minecraft:grass
fill ~17~0~2 ~34~0~21 minecraft:dirt 0
fill ~17~1~2 ~34~1~2 minecraft:grass
fill ~37~0~2 ~37~0~5 minecraft:polished_blackstone_bricks
setblock ~37~1~2 minecraft:polished_blackstone_brick_wall 0
setblock ~37~2~2 minecraft:nether_brick_fence
setblock ~37~3~2 minecraft:soul_lantern 0
fill ~43~0~2 ~43~0~5 minecraft:polished_blackstone_bricks
setblock ~43~1~2 minecraft:polished_blackstone_brick_wall 0
setblock ~43~2~2 minecraft:nether_brick_fence
setblock ~43~3~2 minecraft:soul_lantern 0
fill ~44~0~2 ~53~0~2 minecraft:grass
fill ~5~0~3 ~8~0~3 minecraft:grass
fill ~9~0~3 ~11~0~45 minecraft:dirt 0
fill ~9~1~3 ~12~1~3 minecraft:grass
fill ~13~1~3 ~33~1~21 minecraft:dirt 0
fill ~13~2~3 ~33~2~3 minecraft:grass
setblock ~34~1~3 minecraft:grass
fill ~35~0~3 ~36~0~3 minecraft:grass
setblock ~37~1~3 minecraft:polished_blackstone_brick_wall 0
setblock ~43~1~3 minecraft:polished_blackstone_brick_wall 0
fill ~44~0~3 ~45~0~3 minecraft:grass
fill ~46~0~3 ~52~0~20 minecraft:dirt 0
fill ~46~1~3 ~52~1~3 minecraft:grass
fill ~53~0~3 ~60~0~3 minecraft:grass
fill ~66~0~3 ~70~0~3 minecraft:grass
fill ~4~0~4 ~5~0~4 minecraft:grass
fill ~6~0~4 ~8~0~45 minecraft:dirt 0
fill ~6~1~4 ~8~1~4 minecraft:grass
fill ~9~1~4 ~12~1~28 minecraft:dirt 0
fill ~9~2~4 ~23~2~4 minecraft:grass
fill ~24~2~4 ~25~2~29 minecraft:dirt 0
fill ~24~3~4 ~25~3~5 minecraft:grass
fill ~26~2~4 ~35~2~4 minecraft:grass
fill ~34~1~4 ~35~1~21 minecraft:dirt 0
fill ~35~0~4 ~36~0~21 minecraft:dirt 0
fill ~36~1~4 ~36~1~5 minecraft:grass
fill ~37~1~4 ~37~1~6 minecraft:polished_blackstone_bricks
setblock ~37~2~4 minecraft:polished_blackstone_brick_wall 0
setblock ~37~3~4 minecraft:nether_brick_fence
fill ~38~0~4 ~42~0~4 minecraft:polished_blackstone_brick_stairs 2
fill ~43~1~4 ~43~1~6 minecraft:polished_blackstone_bricks
setblock ~43~2~4 minecraft:polished_blackstone_brick_wall 0
setblock ~43~3~4 minecraft:nether_brick_fence
fill ~44~0~4 ~45~0~15 minecraft:dirt 0
fill ~44~1~4 ~45~1~4 minecraft:grass
fill ~46~1~4 ~51~1~20 minecraft:dirt 0
fill ~46~2~4 ~51~2~4 minecraft:grass
fill ~52~1~4 ~52~1~5 minecraft:grass
fill ~53~0~4 ~56~0~4 minecraft:grass
fill ~57~0~4 ~59~0~30 minecraft:dirt 0
fill ~57~1~4 ~59~1~5 minecraft:grass
fill ~60~0~4 ~66~0~4 minecraft:grass
fill ~67~0~4 ~69~0~27 minecraft:dirt 0
fill ~67~1~4 ~69~1~5 minecraft:grass
fill ~70~0~4 ~71~0~4 minecraft:grass
fill ~3~0~5 ~4~0~5 minecraft:grass
fill ~5~0~5 ~5~0~55 minecraft:dirt 0
fill ~5~1~5 ~7~1~5 minecraft:grass
fill ~8~1~5 ~8~1~29 minecraft:dirt 0
fill ~8~2~5 ~11~2~5 minecraft:grass
fill ~12~2~5 ~23~2~26 minecraft:dirt 0
fill ~12~3~5 ~23~3~5 minecraft:grass
fill ~26~2~5 ~33~2~14 minecraft:dirt 0
fill ~26~3~5 ~33~3~5 minecraft:grass
fill ~34~2~5 ~35~2~5 minecraft:grass
setblock ~37~2~5 minecraft:polished_blackstone_brick_wall 0
fill ~38~0~5 ~42~0~5 minecraft:polished_blackstone_bricks
setblock ~43~2~5 minecraft:polished_blackstone_brick_wall 0
setblock ~44~1~5 minecraft:grass
fill ~45~1~5 ~45~1~16 minecraft:dirt 0
fill ~45~2~5 ~46~2~5 minecraft:grass
fill ~47~2~5 ~50~2~21 minecraft:dirt 0
fill ~47~3~5 ~50~3~5 minecraft:grass
setblock ~51~2~5 minecraft:grass
fill ~53~0~5 ~56~0~24 minecraft:dirt 0
fill ~53~1~5 ~56~1~5 minecraft:grass
fill ~60~0~5 ~66~0~30 minecraft:dirt 0
fill ~60~1~5 ~66~1~5 minecraft:grass
fill ~70~0~5 ~70~0~27 minecraft:dirt 0
fill ~70~1~5 ~70~1~7 minecraft:grass
fill ~71~0~5 ~72~0~6 minecraft:grass
fill ~2~0~6 ~3~0~6 minecraft:grass
fill ~4~0~6 ~4~0~42 minecraft:dirt 0
fill ~4~1~6 ~5~1~6 minecraft:grass
fill ~6~1~6 ~7~1~31 minecraft:dirt 0
fill ~6~2~6 ~9~2~6 minecraft:grass
fill ~10~2~6 ~11~2~25 minecraft:dirt 0
fill ~10~3~6 ~19~3~6 minecraft:grass
fill ~20~3~6 ~33~3~14 minecraft:dirt 0
fill ~20~4~6 ~28~4~7 minecraft:grass
fill ~29~4~6 ~35~4~6 minecraft:polished_blackstone_bricks
setblock ~29~5~6 minecraft:polished_blackstone_bricks
setblock ~29~6~6 minecraft:polished_blackstone_brick_wall 0
setblock ~29~7~6 minecraft:nether_brick_fence
fill ~30~5~6 ~32~5~6 minecraft:polished_blackstone_brick_wall 0
setblock ~33~5~6 minecraft:polished_blackstone_bricks
setblock ~33~6~6 minecraft:polished_blackstone_brick_wall 0
setblock ~33~7~6 minecraft:nether_brick_fence
setblock ~33~8~6 minecraft:soul_lantern 0
fill ~34~2~6 ~35~2~21 minecraft:dirt 0
fill ~34~3~6 ~37~3~6 minecraft:polished_blackstone_bricks
setblock ~34~5~6 minecraft:polished_blackstone_brick_wall 0
setblock ~35~5~6 minecraft:polished_blackstone_brick_wall 0
setblock ~35~6~6 minecraft:nether_brick_fence
fill ~36~1~6 ~36~1~21 minecraft:dirt 0
fill ~36~2~6 ~37~2~6 minecraft:polished_blackstone_bricks
setblock ~36~4~6 minecraft:polished_blackstone_brick_wall 0
fill ~37~0~6 ~43~0~15 minecraft:dirt 0
setblock ~37~4~6 minecraft:polished_blackstone_brick_wall 0
setblock ~37~5~6 minecraft:nether_brick_fence
setblock ~37~6~6 minecraft:soul_lantern 0
fill ~38~1~6 ~42~1~6 minecraft:polished_blackstone_brick_stairs 2
fill ~43~2~6 ~44~3~6 minecraft:polished_blackstone_bricks
setblock ~43~4~6 minecraft:polished_blackstone_brick_wall 0
setblock ~43~5~6 minecraft:nether_brick_fence
setblock ~43~6~6 minecraft:soul_lantern 0
fill ~44~1~6 ~44~1~7 minecraft:dirt 0
setblock ~44~4~6 minecraft:polished_blackstone_brick_wall 0
fill ~45~2~6 ~46~2~21 minecraft:dirt 0
fill ~45~3~6 ~46~4~6 minecraft:polished_blackstone_bricks
setblock ~45~5~6 minecraft:polished_blackstone_brick_wall 0
setblock ~45~6~6 minecraft:nether_brick_fence
setblock ~46~5~6 minecraft:polished_blackstone_brick_wall 0
fill ~47~3~6 ~50~3~16 minecraft:dirt 0
fill ~47~4~6 ~51~4~6 minecraft:polished_blackstone_bricks
setblock ~47~5~6 minecraft:polished_blackstone_bricks
setblock ~47~6~6 minecraft:polished_blackstone_brick_wall 0
setblock ~47~7~6 minecraft:nether_brick_fence
setblock ~47~8~6 minecraft:soul_lantern 0
fill ~48~5~6 ~50~5~6 minecraft:polished_blackstone_brick_wall 0
fill ~51~2~6 ~51~2~23 minecraft:dirt 0
setblock ~51~3~6 minecraft:polished_blackstone_bricks
setblock ~51~5~6 minecraft:polished_blackstone_bricks
setblock ~51~6~6 minecraft:polished_blackstone_brick_wall 0
setblock ~51~7~6 minecraft:nether_brick_fence
fill ~52~1~6 ~68~1~25 minecraft:dirt 0
fill ~52~2~6 ~68~2~6 minecraft:grass
setblock ~69~1~6 minecraft:grass
fill ~2~0~7 ~2~0~8 minecraft:grass
fill ~3~0~7 ~3~0~42 minecraft:dirt 0
fill ~3~1~7 ~4~1~7 minecraft:grass
fill ~5~1~7 ~5~1~30 minecraft:dirt 0
fill ~5~2~7 ~7~2~7 minecraft:grass
fill ~8~2~7 ~9~2~23 minecraft:dirt 0
fill ~8~3~7 ~11~3~7 minecraft:grass
fill ~12~3~7 ~19~3~24 minecraft:dirt 0
fill ~12~4~7 ~19~4~7 minecraft:grass
fill ~29~4~7 ~29~4~13 minecraft:polished_blackstone_bricks
fill ~29~5~7 ~29~5~9 minecraft:polished_blackstone_brick_wall 0
fill ~30~4~7 ~32~4~13 minecraft:quartz_bricks
fill ~33~4~7 ~33~4~9 minecraft:polished_blackstone_brick_stairs 1
fill ~34~3~7 ~34~3~9 minecraft:polished_blackstone
fill ~35~3~7 ~35~3~9 minecraft:polished_blackstone_brick_stairs 1
fill ~36~2~7 ~36~2~9 minecraft:polished_blackstone
fill ~37~1~7 ~37~1~21 minecraft:dirt 0
fill ~37~2~7 ~37~2~9 minecraft:polished_blackstone_brick_stairs 1
fill ~38~1~7 ~42~1~9 minecraft:quartz_bricks
fill ~43~1~7 ~43~1~20 minecraft:dirt 0
fill ~43~2~7 ~43~2~9 minecraft:polished_blackstone_brick_stairs 0
fill ~44~2~7 ~44~2~9 minecraft:polished_blackstone
fill ~45~3~7 ~45~3~9 minecraft:polished_blackstone_brick_stairs 0
fill ~46~3~7 ~46~3~9 minecraft:polished_blackstone
fill ~47~4~7 ~47~4~9 minecraft:polished_blackstone_brick_stairs 0
fill ~48~4~7 ~50~4~13 minecraft:quartz_bricks
fill ~51~3~7 ~51~3~23 minecraft:dirt 0
fill ~51~4~7 ~51~4~13 minecraft:polished_blackstone_bricks
fill ~51~5~7 ~51~5~9 minecraft:polished_blackstone_brick_wall 0
fill ~52~2~7 ~63~2~25 minecraft:dirt 0
fill ~52~3~7 ~63~3~8 minecraft:grass
fill ~64~2~7 ~69~2~7 minecraft:grass
fill ~69~1~7 ~69~1~26 minecraft:dirt 0
fill ~71~0~7 ~71~0~27 minecraft:dirt 0
fill ~71~1~7 ~71~1~8 minecraft:grass
fill ~72~0~7 ~73~0~7 minecraft:grass
fill ~1~0~8 ~1~0~10 minecraft:grass
fill ~3~1~8 ~3~1~9 minecraft:grass
fill ~4~1~8 ~4~1~30 minecraft:dirt 0
fill ~4~2~8 ~5~2~8 minecraft:grass
fill ~6~2~8 ~7~2~22 minecraft:dirt 0
fill ~6~3~8 ~6~3~10 minecraft:grass
fill ~7~3~8 ~7~3~21 minecraft:dirt 0
fill ~7~4~8 ~7~4~9 minecraft:grass
setblock ~8~3~8 minecraft:grass
fill ~9~3~8 ~11~3~22 minecraft:dirt 0
fill ~9~4~8 ~15~4~8 minecraft:grass
fill ~16~4~8 ~25~4~14 minecraft:dirt 0
fill ~16~5~8 ~25~5~9 minecraft:grass
fill ~26~4~8 ~28~4~11 minecraft:grass
fill ~64~2~8 ~66~2~25 minecraft:dirt 0
fill ~64~3~8 ~66~3~8 minecraft:grass
fill ~67~2~8 ~70~2~8 minecraft:grass
fill ~70~1~8 ~70~1~13 minecraft:dirt 0
fill ~72~0~8 ~72~0~14 minecraft:dirt 0
fill ~72~1~8 ~72~1~14 minecraft:grass
fill ~73~0~8 ~74~0~9 minecraft:grass
fill ~2~0~9 ~2~0~42 minecraft:dirt 0
fill ~2~1~9 ~2~1~42 minecraft:grass
fill ~4~2~9 ~4~2~10 minecraft:grass
fill ~5~2~9 ~5~2~15 minecraft:dirt 0
fill ~5~3~9 ~5~3~11 minecraft:grass
fill ~8~3~9 ~8~3~21 minecraft:dirt 0
fill ~8~4~9 ~13~4~9 minecraft:grass
fill ~14~4~9 ~15~4~25 minecraft:dirt 0
fill ~14~5~9 ~15~5~10 minecraft:grass
fill ~44~1~9 ~44~1~16 minecraft:dirt 0
fill ~52~3~9 ~64~3~13 minecraft:dirt 0
fill ~52~4~9 ~64~4~9 minecraft:grass
fill ~65~3~9 ~68~3~9 minecraft:grass
fill ~67~2~9 ~68~2~15 minecraft:dirt 0
fill ~69~2~9 ~71~2~9 minecraft:grass
fill ~71~1~9 ~71~1~13 minecraft:dirt 0
fill ~0~0~10 ~0~0~42 minecraft:grass
fill ~3~1~10 ~3~1~15 minecraft:dirt 0
fill ~3~2~10 ~3~2~15 minecraft:grass
fill ~7~4~10 ~8~4~12 minecraft:dirt 0
fill ~7~5~10 ~8~5~12 minecraft:grass
fill ~9~4~10 ~12~4~10 minecraft:grass
fill ~13~4~10 ~13~4~23 minecraft:dirt 0
fill ~13~5~10 ~13~5~11 minecraft:grass
fill ~16~5~10 ~17~5~10 minecraft:grass
fill ~18~5~10 ~23~5~26 minecraft:dirt 0
fill ~18~6~10 ~23~6~11 minecraft:grass
fill ~24~5~10 ~25~5~10 minecraft:grass
setblock ~29~5~10 minecraft:polished_blackstone_bricks
setblock ~29~6~10 minecraft:polished_blackstone_brick_wall 0
setblock ~29~7~10 minecraft:nether_brick_fence
setblock ~29~8~10 minecraft:soul_lantern 0
fill ~33~4~10 ~34~6~10 minecraft:polished_blackstone_bricks
setblock ~33~7~10 minecraft:polished_blackstone_brick_wall 0
setblock ~33~8~10 minecraft:nether_brick_fence
setblock ~33~9~10 minecraft:soul_lantern 0
fill ~34~3~10 ~34~3~15 minecraft:dirt 0
setblock ~34~7~10 minecraft:polished_blackstone_brick_wall 0
setblock ~35~3~10 minecraft:polished_blackstone_bricks
setblock ~35~4~10 minecraft:polished_blackstone_brick_stairs 2
setblock ~35~5~10 minecraft:polished_blackstone_brick_stairs 6
fill ~35~6~10 ~37~7~10 minecraft:polished_blackstone_bricks
setblock ~35~8~10 minecraft:polished_blackstone_brick_wall 0
setblock ~35~9~10 minecraft:nether_brick_fence
fill ~36~2~10 ~36~2~16 minecraft:dirt 0
setblock ~36~3~10 minecraft:polished_blackstone_brick_stairs 2
setblock ~36~4~10 minecraft:polished_blackstone_brick_stairs 6
setblock ~36~5~10 minecraft:polished_blackstone_bricks
setblock ~36~8~10 minecraft:polished_blackstone_brick_wall 0
fill ~37~2~10 ~43~2~10 minecraft:polished_blackstone_bricks
setblock ~37~3~10 minecraft:polished_blackstone_bricks
setblock ~37~4~10 minecraft:polished_blackstone_brick_stairs 2
setblock ~37~5~10 minecraft:polished_blackstone_brick_stairs 6
setblock ~37~8~10 minecraft:polished_blackstone_bricks
setblock ~37~9~10 minecraft:polished_blackstone_brick_wall 0
setblock ~37~10~10 minecraft:nether_brick_fence
setblock ~37~11~10 minecraft:soul_lantern 0
fill ~38~1~10 ~42~1~20 minecraft:dirt 0
setblock ~38~3~10 minecraft:polished_blackstone_brick_stairs 2
setblock ~38~4~10 minecraft:polished_blackstone_brick_stairs 6
setblock ~38~5~10 minecraft:polished_blackstone_bricks
fill ~38~6~10 ~42~6~10 minecraft:polished_blackstone_brick_stairs 2
fill ~38~7~10 ~42~7~10 minecraft:polished_blackstone_brick_stairs 6
fill ~38~8~10 ~42~8~10 minecraft:polished_blackstone_brick_wall 0
setblock ~39~3~10 minecraft:polished_blackstone_bricks
setblock ~39~4~10 minecraft:polished_blackstone_brick_stairs 2
setblock ~39~5~10 minecraft:polished_blackstone_brick_stairs 6
setblock ~40~3~10 minecraft:polished_blackstone_brick_stairs 2
setblock ~40~4~10 minecraft:polished_blackstone_brick_stairs 6
setblock ~40~5~10 minecraft:polished_blackstone_bricks
setblock ~41~3~10 minecraft:polished_blackstone_bricks
setblock ~41~4~10 minecraft:polished_blackstone_brick_stairs 2
setblock ~41~5~10 minecraft:polished_blackstone_brick_stairs 6
setblock ~42~3~10 minecraft:polished_blackstone_brick_stairs 2
setblock ~42~4~10 minecraft:polished_blackstone_brick_stairs 6
setblock ~42~5~10 minecraft:polished_blackstone_bricks
setblock ~43~3~10 minecraft:polished_blackstone_bricks
setblock ~43~4~10 minecraft:polished_blackstone_brick_stairs 2
setblock ~43~5~10 minecraft:polished_blackstone_brick_stairs 6
fill ~43~6~10 ~47~6~10 minecraft:polished_blackstone_bricks
fill ~43~7~10 ~45~7~10 minecraft:polished_blackstone_bricks
setblock ~43~8~10 minecraft:polished_blackstone_bricks
setblock ~43~9~10 minecraft:polished_blackstone_brick_wall 0
setblock ~43~10~10 minecraft:nether_brick_fence
setblock ~43~11~10 minecraft:soul_lantern 0
fill ~44~2~10 ~44~2~21 minecraft:dirt 0
setblock ~44~3~10 minecraft:polished_blackstone_brick_stairs 2
setblock ~44~4~10 minecraft:polished_blackstone_brick_stairs 6
setblock ~44~5~10 minecraft:polished_blackstone_bricks
setblock ~44~8~10 minecraft:polished_blackstone_brick_wall 0
setblock ~45~3~10 minecraft:polished_blackstone_bricks
setblock ~45~4~10 minecraft:polished_blackstone_brick_stairs 2
setblock ~45~5~10 minecraft:polished_blackstone_brick_stairs 6
setblock ~45~8~10 minecraft:polished_blackstone_brick_wall 0
setblock ~45~9~10 minecraft:nether_brick_fence
fill ~46~3~10 ~46~3~21 minecraft:dirt 0
fill ~46~4~10 ~47~5~10 minecraft:polished_blackstone_bricks
setblock ~46~7~10 minecraft:polished_blackstone_brick_wall 0
setblock ~47~7~10 minecraft:polished_blackstone_brick_wall 0
setblock ~47~8~10 minecraft:nether_brick_fence
setblock ~47~9~10 minecraft:soul_lantern 0
setblock ~51~5~10 minecraft:polished_blackstone_bricks
setblock ~51~6~10 minecraft:polished_blackstone_brick_wall 0
setblock ~51~7~10 minecraft:nether_brick_fence
setblock ~51~8~10 minecraft:soul_lantern 0
fill ~52~4~10 ~56~4~10 minecraft:grass
fill ~57~4~10 ~59~4~14 minecraft:dirt 0
fill ~57~5~10 ~59~5~14 minecraft:grass
fill ~60~4~10 ~65~4~10 minecraft:grass
fill ~65~3~10 ~65~3~13 minecraft:dirt 0
fill ~66~3~10 ~69~3~11 minecraft:grass
fill ~69~2~10 ~69~2~13 minecraft:dirt 0
fill ~70~2~10 ~71~2~13 minecraft:grass
fill ~73~0~10 ~73~0~12 minecraft:dirt 0
fill ~73~1~10 ~73~1~12 minecraft:grass
fill ~74~0~10 ~74~0~13 minecraft:grass
setblock ~1~0~11 minecraft:dirt 0
setblock ~1~1~11 minecraft:grass
fill ~4~2~11 ~4~2~13 minecraft:dirt 0
fill ~4~3~11 ~4~3~13 minecraft:grass
fill ~6~3~11 ~6~3~21 minecraft:dirt 0
fill ~6~4~11 ~6~4~21 minecraft:grass
fill ~9~4~11 ~9~4~12 minecraft:dirt 0
fill ~9~5~11 ~9~5~12 minecraft:grass
fill ~10~4~11 ~10~4~14 minecraft:grass
fill ~11~4~11 ~12~4~22 minecraft:dirt 0
fill ~11~5~11 ~12~5~11 minecraft:grass
fill ~14~5~11 ~17~5~23 minecraft:dirt 0
fill ~14~6~11 ~17~6~11 minecraft:grass
fill ~24~5~11 ~24~5~28 minecraft:dirt 0
fill ~24~6~11 ~24~6~12 minecraft:grass
fill ~25~5~11 ~25~5~12 minecraft:grass
fill ~29~5~11 ~29~5~13 minecraft:polished_blackstone_brick_wall 0
fill ~33~4~11 ~47~4~15 minecraft:dirt 0
fill ~33~5~11 ~33~5~13 minecraft:polished_blackstone_brick_stairs 0
fill ~34~5~11 ~34~5~13 minecraft:polished_blackstone
fill ~35~3~11 ~40~3~16 minecraft:dirt 0
fill ~35~5~11 ~37~5~21 minecraft:dirt 0
fill ~35~6~11 ~35~6~13 minecraft:polished_blackstone_brick_stairs 0
fill ~36~6~11 ~36~6~13 minecraft:polished_blackstone
fill ~37~2~11 ~43~2~21 minecraft:dirt 0
fill ~37~6~11 ~37~6~21 minecraft:dirt 0
fill ~37~7~11 ~37~7~13 minecraft:polished_blackstone_brick_stairs 0
fill ~38~5~11 ~43~5~11 minecraft:grass
fill ~38~7~11 ~42~7~13 minecraft:quartz_bricks
fill ~42~3~11 ~45~3~21 minecraft:dirt 0
fill ~43~7~11 ~43~7~13 minecraft:polished_blackstone_brick_stairs 1
fill ~44~5~11 ~45~5~21 minecraft:dirt 0
fill ~44~6~11 ~44~6~13 minecraft:polished_blackstone
fill ~45~6~11 ~45~6~13 minecraft:polished_blackstone_brick_stairs 1
fill ~46~5~11 ~46~5~13 minecraft:polished_blackstone
fill ~47~5~11 ~47~5~13 minecraft:polished_blackstone_brick_stairs 1
fill ~51~5~11 ~51~5~13 minecraft:polished_blackstone_brick_wall 0
fill ~52~4~11 ~55~4~12 minecraft:grass
fill ~56~4~11 ~56~4~29 minecraft:dirt 0
fill ~56~5~11 ~56~5~29 minecraft:grass
fill ~60~4~11 ~60~4~14 minecraft:dirt 0
fill ~60~5~11 ~60~5~14 minecraft:grass
fill ~61~4~11 ~65~4~13 minecraft:grass
fill ~1~0~12 ~1~0~23 minecraft:grass
fill ~5~3~12 ~5~3~13 minecraft:dirt 0
fill ~5~4~12 ~5~4~13 minecraft:grass
setblock ~5~5~12 minecraft:red_flower 2
setblock ~10~5~12 minecraft:red_flower 0
fill ~11~5~12 ~11~5~15 minecraft:grass
setblock ~11~6~12 minecraft:tallgrass 0
fill ~12~5~12 ~13~5~20 minecraft:dirt 0
fill ~12~6~12 ~14~6~13 minecraft:grass
fill ~12~7~12 ~14~7~12 minecraft:tallgrass 0
fill ~15~6~12 ~23~6~20 minecraft:dirt 0
fill ~15~7~12 ~23~7~12 minecraft:grass
setblock ~15~8~12 minecraft:tallgrass 0
fill ~26~4~12 ~26~4~28 minecraft:dirt 0
fill ~26~5~12 ~26~5~13 minecraft:grass
fill ~27~4~12 ~28~4~12 minecraft:grass
fill ~38~5~12 ~42~6~21 minecraft:dirt 0
fill ~41~3~12 ~41~3~21 minecraft:dirt 0
setblock ~43~5~12 minecraft:grass
setblock ~61~5~12 minecraft:red_flower 0
fill ~62~5~12 ~65~5~12 minecraft:tallgrass 0
setblock ~66~3~12 minecraft:dirt 0
setblock ~66~4~12 minecraft:grass
setblock ~66~5~12 minecraft:red_flower 0
fill ~67~3~12 ~69~3~13 minecraft:grass
fill ~6~5~13 ~6~5~14 minecraft:tallgrass 0
fill ~7~4~13 ~9~4~13 minecraft:grass
setblock ~7~5~13 minecraft:red_flower 2
setblock ~8~5~13 minecraft:tallgrass 0
setblock ~9~5~13 minecraft:red_flower 0
fill ~10~5~13 ~10~5~14 minecraft:red_flower 2
setblock ~11~6~13 minecraft:red_flower 1
setblock ~12~7~13 minecraft:red_flower 9
fill ~13~7~13 ~13~7~14 minecraft:red_flower 2
fill ~15~7~13 ~23~7~14 minecraft:dirt 0
fill ~15~8~13 ~23~8~13 minecraft:grass
setblock ~15~9~13 minecraft:red_flower 1
fill ~23~9~13 ~23~9~14 minecraft:red_flower 3
fill ~24~6~13 ~24~6~28 minecraft:dirt 0
fill ~24~7~13 ~24~7~14 minecraft:grass
fill ~25~5~13 ~25~5~28 minecraft:dirt 0
fill ~25~6~13 ~25~6~14 minecraft:grass
fill ~27~4~13 ~27~4~28 minecraft:dirt 0
fill ~27~5~13 ~27~5~14 minecraft:grass
setblock ~28~4~13 minecraft:grass
fill ~43~5~13 ~43~5~14 minecraft:dirt 0
fill ~52~4~13 ~54~4~13 minecraft:grass
fill ~55~4~13 ~55~4~29 minecraft:dirt 0
fill ~55~5~13 ~55~5~16 minecraft:grass
setblock ~61~5~13 minecraft:red_flower 2
setblock ~62~5~13 minecraft:red_flower 10
setblock ~63~5~13 minecraft:red_flower 1
setblock ~65~5~13 minecraft:red_flower 1
fill ~66~3~13 ~66~3~25 minecraft:grass
setblock ~66~4~13 minecraft:red_flower 2
setblock ~67~4~13 minecraft:red_flower 10
setblock ~68~4~13 minecraft:red_flower 9
fill ~73~0~13 ~73~0~19 minecraft:grass
fill ~4~2~14 ~4~2~30 minecraft:grass
fill ~5~3~14 ~5~3~15 minecraft:grass
fill ~7~4~14 ~7~4~21 minecraft:grass
setblock ~7~5~14 minecraft:red_flower 10
fill ~8~4~14 ~9~4~16 minecraft:dirt 0
fill ~8~5~14 ~9~5~16 minecraft:grass
setblock ~9~6~14 minecraft:tallgrass 0
setblock ~11~6~14 minecraft:red_flower 2
fill ~12~6~14 ~13~6~15 minecraft:grass
setblock ~12~7~14 minecraft:red_flower 3
fill ~14~6~14 ~14~6~20 minecraft:dirt 0
fill ~14~7~14 ~14~7~20 minecraft:grass
setblock ~14~8~14 minecraft:red_flower 10
setblock ~15~8~14 minecraft:grass
setblock ~15~9~14 minecraft:tallgrass 0
fill ~16~8~14 ~22~8~15 minecraft:dirt 0
fill ~16~9~14 ~22~9~14 minecraft:grass
setblock ~16~10~14 minecraft:yellow_flower
setblock ~17~10~14 minecraft:tallgrass 0
setblock ~21~10~14 minecraft:red_flower 0
setblock ~22~10~14 minecraft:tallgrass 0
fill ~23~8~14 ~23~8~16 minecraft:grass
fill ~26~5~14 ~26~5~28 minecraft:dirt 0
fill ~26~6~14 ~26~6~15 minecraft:grass
fill ~28~4~14 ~32~4~21 minecraft:dirt 0
setblock ~28~5~14 minecraft:grass
fill ~29~5~14 ~33~9~14 minecraft:polished_blackstone_bricks
fill ~29~10~14 ~29~12~14 minecraft:polished_blackstone_bricks
setblock ~29~13~14 minecraft:polished_blackstone_brick_wall 0
setblock ~29~14~14 minecraft:nether_brick_fence
setblock ~29~15~14 minecraft:soul_lantern 0
setblock ~30~10~14 minecraft:polished_blackstone_brick_stairs 2
fill ~30~11~14 ~32~11~14 minecraft:polished_blackstone_brick_stairs 6
fill ~30~12~14 ~32~12~14 minecraft:polished_blackstone_brick_wall 0
setblock ~31~10~14 minecraft:polished_blackstone_bricks
setblock ~32~10~14 minecraft:polished_blackstone_brick_stairs 2
fill ~33~10~14 ~37~10~14 minecraft:polished_blackstone_bricks
fill ~33~11~14 ~35~11~14 minecraft:polished_blackstone_bricks
setblock ~33~12~14 minecraft:polished_blackstone_bricks
setblock ~33~13~14 minecraft:polished_blackstone_brick_wall 0
setblock ~33~14~14 minecraft:nether_brick_fence
setblock ~33~15~14 minecraft:soul_lantern 0
fill ~34~5~14 ~34~5~21 minecraft:dirt 0
fill ~34~6~14 ~35~9~14 minecraft:polished_blackstone_bricks
setblock ~34~12~14 minecraft:polished_blackstone_brick_wall 0
setblock ~35~12~14 minecraft:polished_blackstone_brick_wall 0
setblock ~35~13~14 minecraft:nether_brick_fence
fill ~36~6~14 ~36~6~21 minecraft:dirt 0
fill ~36~7~14 ~37~9~14 minecraft:polished_blackstone_bricks
setblock ~36~11~14 minecraft:polished_blackstone_brick_wall 0
setblock ~37~11~14 minecraft:polished_blackstone_brick_wall 0
setblock ~37~12~14 minecraft:nether_brick_fence
setblock ~37~13~14 minecraft:soul_lantern 0
fill ~38~7~14 ~42~7~21 minecraft:dirt 0
fill ~38~8~14 ~42~8~14 minecraft:polished_blackstone_brick_stairs 2
fill ~43~6~14 ~51~9~14 minecraft:polished_blackstone_bricks
fill ~43~10~14 ~47~10~14 minecraft:polished_blackstone_bricks
setblock ~43~11~14 minecraft:polished_blackstone_brick_wall 0
setblock ~43~12~14 minecraft:nether_brick_fence
setblock ~43~13~14 minecraft:soul_lantern 0
setblock ~44~11~14 minecraft:polished_blackstone_brick_wall 0
fill ~45~11~14 ~47~11~14 minecraft:polished_blackstone_bricks
setblock ~45~12~14 minecraft:polished_blackstone_brick_wall 0
setblock ~45~13~14 minecraft:nether_brick_fence
fill ~46~5~14 ~46~5~21 minecraft:dirt 0
setblock ~46~12~14 minecraft:polished_blackstone_brick_wall 0
fill ~47~5~14 ~51~5~14 minecraft:polished_blackstone_bricks
setblock ~47~12~14 minecraft:polished_blackstone_bricks
setblock ~47~13~14 minecraft:polished_blackstone_brick_wall 0
setblock ~47~14~14 minecraft:nether_brick_fence
setblock ~47~15~14 minecraft:soul_lantern 0
fill ~48~4~14 ~54~4~15 minecraft:dirt 0
setblock ~48~10~14 minecraft:polished_blackstone_brick_stairs 2
fill ~48~11~14 ~50~11~14 minecraft:polished_blackstone_brick_stairs 6
fill ~48~12~14 ~50~12~14 minecraft:polished_blackstone_brick_wall 0
setblock ~49~10~14 minecraft:polished_blackstone_bricks
setblock ~50~10~14 minecraft:polished_blackstone_brick_stairs 2
fill ~51~10~14 ~51~12~14 minecraft:polished_blackstone_bricks
setblock ~51~13~14 minecraft:polished_blackstone_brick_wall 0
setblock ~51~14~14 minecraft:nether_brick_fence
setblock ~51~15~14 minecraft:soul_lantern 0
fill ~52~3~14 ~60~3~14 minecraft:dirt 0
fill ~52~5~14 ~52~5~26 minecraft:dirt 0
fill ~52~6~14 ~52~6~20 minecraft:grass
setblock ~52~7~14 minecraft:red_flower 9
fill ~53~5~14 ~54~5~14 minecraft:grass
setblock ~53~6~14 minecraft:red_flower 2
fill ~54~6~14 ~56~6~14 minecraft:tallgrass 0
fill ~61~3~14 ~65~3~16 minecraft:grass
fill ~61~4~14 ~62~4~14 minecraft:tallgrass 0
setblock ~63~4~14 minecraft:red_flower 3
fill ~64~4~14 ~64~4~16 minecraft:tallgrass 0
setblock ~65~4~14 minecraft:red_flower 3
setblock ~66~4~14 minecraft:red_flower 1
fill ~67~3~14 ~68~3~15 minecraft:grass
setblock ~67~4~14 minecraft:red_flower 9
setblock ~68~4~14 minecraft:tallgrass 0
fill ~69~2~14 ~69~2~19 minecraft:grass
setblock ~69~3~14 minecraft:tallgrass 0
fill ~70~1~14 ~71~1~18 minecraft:grass
setblock ~74~0~14 minecraft:red_flower 2
setblock ~5~4~15 minecraft:tallgrass 0
fill ~6~5~15 ~7~5~15 minecraft:red_flower 2
setblock ~8~6~15 minecraft:red_flower 10
fill ~10~4~15 ~10~4~21 minecraft:dirt 0
fill ~10~5~15 ~10~5~21 minecraft:grass
setblock ~10~6~15 minecraft:tallgrass 0
setblock ~11~6~15 minecraft:red_flower 3
fill ~12~7~15 ~13~7~15 minecraft:red_flower 10
fill ~15~7~15 ~15~7~20 minecraft:grass
setblock ~15~8~15 minecraft:yellow_flower
fill ~16~4~15 ~24~4~25 minecraft:dirt 0
fill ~16~7~15 ~24~7~18 minecraft:dirt 0
fill ~16~9~15 ~18~9~15 minecraft:grass
setblock ~16~10~15 minecraft:tallgrass 0
setblock ~17~10~15 minecraft:red_flower 0
fill ~18~10~15 ~18~10~18 minecraft:tallgrass 0
fill ~19~9~15 ~20~9~16 minecraft:dirt 0
fill ~19~10~15 ~20~10~16 minecraft:grass
setblock ~19~11~15 minecraft:red_flower 3
fill ~20~3~15 ~24~3~28 minecraft:dirt 0
setblock ~20~11~15 minecraft:red_flower 1
fill ~21~9~15 ~22~9~20 minecraft:grass
setblock ~21~10~15 minecraft:red_flower 3
setblock ~23~9~15 minecraft:red_flower 1
fill ~24~8~15 ~24~8~17 minecraft:grass
fill ~25~3~15 ~26~3~16 minecraft:coal_ore
fill ~25~4~15 ~25~4~16 minecraft:coal_ore
fill ~25~6~15 ~25~6~28 minecraft:dirt 0
setblock ~25~7~15 minecraft:grass
setblock ~26~2~15 minecraft:coal_ore
fill ~27~2~15 ~33~3~21 minecraft:dirt 0
fill ~27~5~15 ~33~5~19 minecraft:dirt 0
fill ~27~6~15 ~28~6~15 minecraft:grass
fill ~29~6~15 ~35~6~19 minecraft:dirt 0
fill ~29~7~15 ~29~9~15 minecraft:polished_blackstone_bricks
setblock ~29~10~15 minecraft:polished_blackstone_brick_stairs 0
fill ~29~11~15 ~29~11~22 minecraft:polished_blackstone_brick_stairs 4
fill ~29~12~15 ~29~12~16 minecraft:polished_blackstone_brick_wall 0
fill ~30~7~15 ~37~7~21 minecraft:dirt 0
fill ~30~8~15 ~35~8~21 minecraft:dirt 0
fill ~30~9~15 ~33~10~17 minecraft:dirt 0
fill ~30~11~15 ~32~11~22 minecraft:quartz_bricks
fill ~33~11~15 ~33~11~17 minecraft:polished_blackstone_brick_stairs 1
fill ~34~9~15 ~34~9~17 minecraft:grass
fill ~34~10~15 ~34~10~17 minecraft:polished_blackstone_slab 0
fill ~35~9~15 ~35~9~17 minecraft:dirt 0
fill ~35~10~15 ~35~10~17 minecraft:polished_blackstone_brick_stairs 1
setblock ~36~8~15 minecraft:polished_blackstone_brick_stairs 1
setblock ~36~9~15 minecraft:polished_blackstone_double_slab 0
fill ~37~8~15 ~37~8~21 minecraft:dirt 0
fill ~37~9~15 ~37~9~17 minecraft:polished_blackstone_brick_stairs 1
fill ~38~8~15 ~42~8~17 minecraft:quartz_bricks
fill ~43~5~15 ~43~8~17 minecraft:polished_blackstone_bricks
fill ~43~9~15 ~43~9~17 minecraft:polished_blackstone_brick_stairs 0
fill ~44~6~15 ~50~7~21 minecraft:dirt 0
fill ~44~8~15 ~44~8~17 minecraft:grass
fill ~44~9~15 ~44~9~17 minecraft:polished_blackstone_slab 0
fill ~45~8~15 ~50~8~21 minecraft:dirt 0
fill ~45~9~15 ~45~9~17 minecraft:dirt 0
fill ~45~10~15 ~45~10~17 minecraft:polished_blackstone_brick_stairs 0
fill ~46~9~15 ~46~9~17 minecraft:grass
fill ~46~10~15 ~46~10~17 minecraft:polished_blackstone_slab 0
fill ~47~5~15 ~51~5~15 minecraft:dirt 0
fill ~47~9~15 ~50~9~21 minecraft:dirt 0
fill ~47~10~15 ~50~10~15 minecraft:dirt 0
fill ~47~11~15 ~47~11~17 minecraft:polished_blackstone_brick_stairs 0
fill ~48~11~15 ~50~11~22 minecraft:quartz_bricks
fill ~51~6~15 ~51~9~20 minecraft:polished_blackstone_bricks
setblock ~51~10~15 minecraft:polished_blackstone_brick_stairs 1
fill ~51~11~15 ~51~11~22 minecraft:polished_blackstone_brick_stairs 5
fill ~51~12~15 ~51~12~16 minecraft:polished_blackstone_brick_wall 0
fill ~52~3~15 ~59~3~26 minecraft:dirt 0
fill ~52~7~15 ~53~7~15 minecraft:tallgrass 0
fill ~53~5~15 ~53~5~24 minecraft:dirt 0
fill ~53~6~15 ~53~6~19 minecraft:grass
setblock ~54~5~15 minecraft:grass
fill ~54~6~15 ~55~6~15 minecraft:tallgrass 0
setblock ~56~6~15 minecraft:red_flower 2
fill ~57~4~15 ~59~4~19 minecraft:grass
setblock ~57~5~15 minecraft:yellow_flower
setblock ~58~5~15 minecraft:tallgrass 0
fill ~59~5~15 ~59~5~16 minecraft:red_flower 3
fill ~60~3~15 ~60~3~17 minecraft:grass
setblock ~60~4~15 minecraft:red_flower 0
setblock ~63~4~15 minecraft:yellow_flower
setblock ~65~4~15 minecraft:red_flower 0
setblock ~66~4~15 minecraft:red_flower 9
setblock ~67~4~15 minecraft:red_flower 1
setblock ~68~4~15 minecraft:red_flower 3
setblock ~69~3~15 minecraft:yellow_flower
setblock ~71~2~15 minecraft:yellow_flower
fill ~72~0~15 ~72~0~17 minecraft:grass
fill ~72~1~15 ~72~1~17 minecraft:tallgrass 0
fill ~3~1~16 ~3~1~19 minecraft:grass
fill ~5~2~16 ~5~2~30 minecraft:grass
setblock ~7~5~16 minecraft:red_flower 0
setblock ~8~6~16 minecraft:tallgrass 0
fill ~9~6~16 ~9~6~17 minecraft:red_flower 1
setblock ~10~6~16 minecraft:yellow_flower
fill ~11~5~16 ~11~5~19 minecraft:dirt 0
fill ~11~6~16 ~12~6~19 minecraft:grass
setblock ~11~7~16 minecraft:tallgrass 0
setblock ~12~7~16 minecraft:red_flower 2
fill ~13~6~16 ~13~6~19 minecraft:dirt 0
fill ~13~7~16 ~13~7~19 minecraft:grass
fill ~13~8~16 ~15~8~16 minecraft:tallgrass 0
fill ~16~8~16 ~16~8~18 minecraft:grass
setblock ~16~9~16 minecraft:red_flower 1
fill ~17~8~16 ~22~8~17 minecraft:dirt 0
fill ~17~9~16 ~18~9~17 minecraft:grass
setblock ~17~10~16 minecraft:yellow_flower
fill ~19~11~16 ~20~11~16 minecraft:tallgrass 0
fill ~21~10~16 ~21~10~20 minecraft:tallgrass 0
fill ~22~10~16 ~22~10~17 minecraft:red_flower 2
setblock ~24~9~16 minecraft:red_flower 10
fill ~25~7~16 ~25~7~28 minecraft:dirt 0
fill ~25~8~16 ~25~8~17 minecraft:grass
setblock ~25~9~16 minecraft:red_flower 9
fill ~26~2~16 ~26~2~22 minecraft:dirt 0
fill ~26~6~16 ~28~6~26 minecraft:dirt 0
fill ~26~7~16 ~28~7~16 minecraft:grass
fill ~29~7~16 ~29~7~23 minecraft:dirt 0
fill ~29~8~16 ~29~10~16 minecraft:polished_blackstone_bricks
fill ~33~4~16 ~42~4~21 minecraft:dirt 0
fill ~34~3~16 ~34~3~18 minecraft:ice
fill ~36~8~16 ~36~8~17 minecraft:grass
fill ~36~9~16 ~36~9~17 minecraft:polished_blackstone_slab 0
fill ~37~0~16 ~40~0~21 minecraft:dirt 0
fill ~43~4~16 ~43~4~17 minecraft:polished_blackstone_bricks
fill ~44~4~16 ~50~4~16 minecraft:dirt 0
fill ~45~0~16 ~45~0~20 minecraft:dirt 0
fill ~47~5~16 ~50~5~21 minecraft:dirt 0
setblock ~47~10~16 minecraft:quartz_bricks
fill ~48~10~16 ~50~10~21 minecraft:dirt 0
fill ~51~4~16 ~51~5~17 minecraft:polished_blackstone_bricks
setblock ~51~10~16 minecraft:polished_blackstone_bricks
fill ~52~4~16 ~54~4~26 minecraft:dirt 0
fill ~52~7~16 ~52~7~17 minecraft:tallgrass 0
setblock ~53~7~16 minecraft:red_flower 9
fill ~54~5~16 ~54~5~24 minecraft:dirt 0
fill ~54~6~16 ~54~6~20 minecraft:grass
setblock ~54~7~16 minecraft:red_flower 2
setblock ~55~6~16 minecraft:red_flower 2
setblock ~56~6~16 minecraft:tallgrass 0
fill ~57~5~16 ~57~5~17 minecraft:tallgrass 0
setblock ~58~5~16 minecraft:red_flower 1
setblock ~60~4~16 minecraft:tallgrass 0
fill ~61~4~16 ~62~4~16 minecraft:red_flower 9
setblock ~63~4~16 minecraft:red_flower 3
fill ~65~4~16 ~66~4~17 minecraft:tallgrass 0
fill ~67~2~16 ~67~2~25 minecraft:dirt 0
fill ~67~3~16 ~67~3~25 minecraft:grass
setblock ~67~4~16 minecraft:red_flower 9
fill ~68~2~16 ~68~2~17 minecraft:grass
setblock ~68~3~16 minecraft:red_flower 9
setblock ~69~3~16 minecraft:red_flower 10
setblock ~70~2~16 minecraft:red_flower 2
setblock ~71~2~16 minecraft:tallgrass 0
setblock ~74~0~16 minecraft:red_flower 0
fill ~6~5~17 ~7~5~17 minecraft:red_flower 10
fill ~8~4~17 ~8~4~21 minecraft:grass
setblock ~8~5~17 minecraft:tallgrass 0
fill ~9~4~17 ~9~4~20 minecraft:dirt 0
fill ~9~5~17 ~9~5~20 minecraft:grass
setblock ~10~6~17 minecraft:red_flower 1
setblock ~11~7~17 minecraft:red_flower 9
fill ~12~7~17 ~12~7~18 minecraft:tallgrass 0
setblock ~13~8~17 minecraft:tallgrass 0
setblock ~15~8~17 minecraft:red_flower 0
setblock ~16~9~17 minecraft:red_flower 0
setblock ~17~10~17 minecraft:red_flower 1
fill ~19~9~17 ~20~9~18 minecraft:grass
setblock ~19~10~17 minecraft:red_flower 10
fill ~20~10~17 ~20~10~18 minecraft:red_flower 2
fill ~23~8~17 ~23~8~23 minecraft:dirt 0
fill ~23~9~17 ~23~9~23 minecraft:grass
fill ~23~10~17 ~23~10~18 minecraft:red_flower 2
fill ~25~3~17 ~26~3~29 minecraft:dirt 0
fill ~25~4~17 ~25~4~28 minecraft:dirt 0
setblock ~25~9~17 minecraft:tallgrass 0
fill ~26~7~17 ~26~7~28 minecraft:dirt 0
fill ~26~8~17 ~26~8~18 minecraft:grass
setblock ~26~9~17 minecraft:red_flower 0
setblock ~27~7~17 minecraft:grass
fill ~28~7~17 ~28~7~26 minecraft:dirt 0
fill ~28~8~17 ~28~8~22 minecraft:grass
setblock ~28~9~17 minecraft:tallgrass 0
fill ~29~8~17 ~29~8~23 minecraft:dirt 0
fill ~29~9~17 ~29~9~23 minecraft:polished_blackstone_bricks
setblock ~29~10~17 minecraft:polished_blackstone_brick_stairs 0
setblock ~29~12~17 minecraft:polished_blackstone_bricks
setblock ~29~13~17 minecraft:polished_blackstone_brick_wall 0
setblock ~29~14~17 minecraft:nether_brick_fence
setblock ~35~3~17 minecraft:dirt 0
setblock ~36~2~17 minecraft:grass
fill ~36~3~17 ~37~3~19 minecraft:ice
fill ~38~3~17 ~40~3~21 minecraft:dirt 0
fill ~41~0~17 ~42~0~20 minecraft:dirt 0
fill ~44~4~17 ~49~4~20 minecraft:dirt 0
fill ~45~1~17 ~45~1~18 minecraft:gravel
fill ~47~3~17 ~49~3~21 minecraft:dirt 0
fill ~47~10~17 ~47~10~18 minecraft:dirt 0
setblock ~50~3~17 minecraft:grass
setblock ~50~4~17 minecraft:tallgrass 0
setblock ~51~10~17 minecraft:polished_blackstone_brick_stairs 1
setblock ~51~12~17 minecraft:polished_blackstone_bricks
setblock ~51~13~17 minecraft:polished_blackstone_brick_wall 0
setblock ~51~14~17 minecraft:nether_brick_fence
setblock ~53~7~17 minecraft:red_flower 1
setblock ~54~7~17 minecraft:tallgrass 0
fill ~55~5~17 ~55~5~24 minecraft:dirt 0
fill ~55~6~17 ~55~6~24 minecraft:grass
setblock ~55~7~17 minecraft:red_flower 1
setblock ~56~6~17 minecraft:red_flower 9
setblock ~58~5~17 minecraft:tallgrass 0
setblock ~59~5~17 minecraft:yellow_flower
setblock ~61~3~17 minecraft:grass
setblock ~61~4~17 minecraft:tallgrass 0
fill ~62~3~17 ~64~3~21 minecraft:dirt 0
fill ~62~4~17 ~64~4~21 minecraft:grass
fill ~62~5~17 ~63~5~17 minecraft:tallgrass 0
setblock ~64~5~17 minecraft:red_flower 0
setblock ~65~3~17 minecraft:grass
fill ~67~4~17 ~67~4~18 minecraft:tallgrass 0
fill ~68~3~17 ~69~3~17 minecraft:red_flower 3
setblock ~73~1~17 minecraft:red_flower 9
setblock ~74~0~17 minecraft:tallgrass 0
setblock ~6~5~18 minecraft:tallgrass 0
setblock ~7~5~18 minecraft:red_flower 3
setblock ~8~5~18 minecraft:red_flower 1
fill ~10~6~18 ~10~6~20 minecraft:tallgrass 0
fill ~11~7~18 ~11~7~19 minecraft:tallgrass 0
setblock ~13~8~18 minecraft:red_flower 9
fill ~14~8~18 ~14~8~19 minecraft:red_flower 1
setblock ~16~9~18 minecraft:red_flower 2
fill ~17~8~18 ~17~8~19 minecraft:grass
setblock ~17~9~18 minecraft:red_flower 0
fill ~18~8~18 ~22~8~18 minecraft:dirt 0
setblock ~18~9~18 minecraft:grass
setblock ~19~10~18 minecraft:tallgrass 0
setblock ~22~10~18 minecraft:red_flower 10
fill ~24~8~18 ~25~8~24 minecraft:dirt 0
fill ~24~9~18 ~25~9~24 minecraft:grass
fill ~24~10~18 ~25~10~18 minecraft:tallgrass 0
setblock ~26~9~18 minecraft:red_flower 3
fill ~27~7~18 ~27~7~28 minecraft:dirt 0
fill ~27~8~18 ~27~8~21 minecraft:grass
setblock ~27~9~18 minecraft:yellow_flower
setblock ~28~9~18 minecraft:red_flower 10
setblock ~29~10~18 minecraft:polished_blackstone_bricks
fill ~29~12~18 ~29~12~19 minecraft:polished_blackstone_brick_wall 0
fill ~30~9~18 ~32~10~21 minecraft:dirt 0
fill ~33~9~18 ~45~9~18 minecraft:polished_blackstone_bricks
fill ~33~10~18 ~35~10~18 minecraft:polished_blackstone_bricks
fill ~33~11~18 ~34~13~18 minecraft:polished_blackstone_bricks
setblock ~33~14~18 minecraft:polished_blackstone_brick_wall 0
setblock ~33~15~18 minecraft:nether_brick_fence
setblock ~33~16~18 minecraft:soul_lantern 0
setblock ~34~14~18 minecraft:polished_blackstone_brick_wall 0
fill ~35~3~18 ~35~3~19 minecraft:ice
setblock ~35~11~18 minecraft:polished_blackstone_brick_stairs 2
setblock ~35~12~18 minecraft:polished_blackstone_brick_stairs 6
fill ~35~13~18 ~37~14~18 minecraft:polished_blackstone_bricks
setblock ~35~15~18 minecraft:polished_blackstone_brick_wall 0
setblock ~35~16~18 minecraft:nether_brick_fence
setblock ~36~2~18 minecraft:water 0
fill ~36~8~18 ~36~8~21 minecraft:dirt 0
fill ~36~10~18 ~38~10~18 minecraft:polished_blackstone_brick_stairs 2
setblock ~36~11~18 minecraft:polished_blackstone_brick_stairs 6
setblock ~36~12~18 minecraft:polished_blackstone_bricks
setblock ~36~15~18 minecraft:polished_blackstone_brick_wall 0
setblock ~37~11~18 minecraft:polished_blackstone_brick_stairs 2
setblock ~37~12~18 minecraft:polished_blackstone_brick_stairs 6
setblock ~37~15~18 minecraft:polished_blackstone_bricks
setblock ~37~16~18 minecraft:polished_blackstone_brick_wall 0
setblock ~37~17~18 minecraft:nether_brick_fence
setblock ~37~18~18 minecraft:soul_lantern 0
fill ~38~8~18 ~44~8~21 minecraft:dirt 0
setblock ~38~11~18 minecraft:polished_blackstone_brick_stairs 6
setblock ~38~12~18 minecraft:polished_blackstone_bricks
fill ~38~13~18 ~42~13~18 minecraft:polished_blackstone_brick_stairs 2
fill ~38~14~18 ~42~14~18 minecraft:polished_blackstone_brick_stairs 6
fill ~38~15~18 ~42~15~18 minecraft:polished_blackstone_brick_wall 0
setblock ~39~10~18 minecraft:polished_blackstone_bricks
setblock ~39~11~18 minecraft:polished_blackstone_brick_stairs 2
setblock ~39~12~18 minecraft:polished_blackstone_brick_stairs 6
setblock ~40~10~18 minecraft:polished_blackstone_brick_stairs 2
setblock ~40~11~18 minecraft:polished_blackstone_brick_stairs 6
setblock ~40~12~18 minecraft:polished_blackstone_bricks
setblock ~41~10~18 minecraft:polished_blackstone_bricks
setblock ~41~11~18 minecraft:polished_blackstone_brick_stairs 2
setblock ~41~12~18 minecraft:polished_blackstone_brick_stairs 6
setblock ~42~10~18 minecraft:polished_blackstone_brick_stairs 2
setblock ~42~11~18 minecraft:polished_blackstone_brick_stairs 6
setblock ~42~12~18 minecraft:polished_blackstone_bricks
fill ~43~0~18 ~44~0~20 minecraft:dirt 0
fill ~43~4~18 ~43~7~21 minecraft:dirt 0
setblock ~43~10~18 minecraft:polished_blackstone_bricks
setblock ~43~11~18 minecraft:polished_blackstone_brick_stairs 2
setblock ~43~12~18 minecraft:polished_blackstone_brick_stairs 6
fill ~43~13~18 ~47~13~18 minecraft:polished_blackstone_bricks
fill ~43~14~18 ~45~14~18 minecraft:polished_blackstone_bricks
setblock ~43~15~18 minecraft:polished_blackstone_bricks
setblock ~43~16~18 minecraft:polished_blackstone_brick_wall 0
setblock ~43~17~18 minecraft:nether_brick_fence
setblock ~43~18~18 minecraft:soul_lantern 0
setblock ~44~1~18 minecraft:gravel
setblock ~44~10~18 minecraft:polished_blackstone_brick_stairs 2
setblock ~44~11~18 minecraft:polished_blackstone_brick_stairs 6
setblock ~44~12~18 minecraft:polished_blackstone_bricks
setblock ~44~15~18 minecraft:polished_blackstone_brick_wall 0
fill ~45~10~18 ~46~10~18 minecraft:polished_blackstone_bricks
setblock ~45~11~18 minecraft:polished_blackstone_brick_stairs 2
setblock ~45~12~18 minecraft:polished_blackstone_brick_stairs 6
setblock ~45~15~18 minecraft:polished_blackstone_brick_wall 0
setblock ~45~16~18 minecraft:nether_brick_fence
fill ~46~9~18 ~46~9~21 minecraft:dirt 0
fill ~46~11~18 ~47~12~18 minecraft:polished_blackstone_bricks
setblock ~46~14~18 minecraft:polished_blackstone_brick_wall 0
setblock ~47~14~18 minecraft:polished_blackstone_brick_wall 0
setblock ~47~15~18 minecraft:nether_brick_fence
setblock ~47~16~18 minecraft:soul_lantern 0
fill ~50~3~18 ~50~4~22 minecraft:dirt 0
fill ~51~4~18 ~51~4~23 minecraft:dirt 0
fill ~51~5~18 ~51~5~20 minecraft:polished_blackstone_bricks
setblock ~51~10~18 minecraft:polished_blackstone_bricks
fill ~51~12~18 ~51~12~19 minecraft:polished_blackstone_brick_wall 0
setblock ~52~7~18 minecraft:red_flower 1
setblock ~53~7~18 minecraft:red_flower 2
setblock ~54~7~18 minecraft:red_flower 1
setblock ~55~7~18 minecraft:red_flower 10
setblock ~56~6~18 minecraft:red_flower 3
setblock ~57~5~18 minecraft:red_flower 0
setblock ~59~5~18 minecraft:red_flower 0
fill ~60~3~18 ~61~3~28 minecraft:dirt 0
fill ~60~4~18 ~61~4~23 minecraft:grass
fill ~60~5~18 ~61~5~19 minecraft:tallgrass 0
setblock ~62~5~18 minecraft:red_flower 10
fill ~63~5~18 ~65~5~18 minecraft:tallgrass 0
fill ~65~3~18 ~65~3~20 minecraft:dirt 0
fill ~65~4~18 ~65~4~20 minecraft:grass
setblock ~66~4~18 minecraft:red_flower 10
fill ~68~2~18 ~68~2~25 minecraft:dirt 0
fill ~68~3~18 ~68~3~25 minecraft:grass
setblock ~69~3~18 minecraft:red_flower 9
fill ~72~0~18 ~72~0~27 minecraft:dirt 0
fill ~72~1~18 ~72~1~20 minecraft:grass
setblock ~72~2~18 minecraft:red_flower 3
setblock ~73~1~18 minecraft:tallgrass 0
fill ~74~0~18 ~74~0~25 minecraft:grass
setblock ~75~0~18 minecraft:red_flower 0
setblock ~6~5~19 minecraft:red_flower 1
fill ~7~5~19 ~8~5~19 minecraft:tallgrass 0
setblock ~9~6~19 minecraft:red_flower 2
setblock ~13~8~19 minecraft:red_flower 3
setblock ~15~8~19 minecraft:red_flower 2
fill ~16~7~19 ~16~7~21 minecraft:grass
setblock ~16~8~19 minecraft:tallgrass 0
fill ~17~7~19 ~24~7~19 minecraft:dirt 0
setblock ~17~9~19 minecraft:red_flower 9
fill ~18~8~19 ~20~8~20 minecraft:grass
setblock ~18~9~19 minecraft:red_flower 3
setblock ~19~9~19 minecraft:red_flower 10
setblock ~20~9~19 minecraft:tallgrass 0
fill ~21~8~19 ~22~8~20 minecraft:dirt 0
fill ~24~10~19 ~24~10~21 minecraft:tallgrass 0
setblock ~25~10~19 minecraft:red_flower 9
fill ~26~8~19 ~26~8~23 minecraft:dirt 0
fill ~26~9~19 ~26~9~23 minecraft:grass
setblock ~26~10~19 minecraft:tallgrass 0
setblock ~27~9~19 minecraft:red_flower 10
fill ~28~9~19 ~28~9~20 minecraft:tallgrass 0
setblock ~29~10~19 minecraft:polished_blackstone_brick_stairs 0
fill ~33~9~19 ~45~9~21 minecraft:dirt 0
fill ~33~10~19 ~47~10~21 minecraft:grass
fill ~33~12~19 ~33~12~21 minecraft:polished_blackstone_brick_stairs 0
fill ~34~3~19 ~34~3~21 minecraft:dirt 0
fill ~34~12~19 ~34~12~21 minecraft:polished_blackstone_slab 0
fill ~35~13~19 ~35~13~21 minecraft:polished_blackstone_brick_stairs 0
fill ~36~2~19 ~36~2~21 minecraft:dirt 0
fill ~36~13~19 ~36~13~21 minecraft:polished_blackstone_slab 0
fill ~37~14~19 ~37~14~21 minecraft:polished_blackstone_brick_stairs 0
fill ~38~14~19 ~42~14~74 minecraft:quartz_bricks
fill ~43~14~19 ~43~14~21 minecraft:polished_blackstone_brick_stairs 1
fill ~44~1~19 ~45~1~20 minecraft:dirt 0
fill ~44~13~19 ~44~13~21 minecraft:polished_blackstone_slab 0
fill ~45~13~19 ~45~13~21 minecraft:polished_blackstone_brick_stairs 1
fill ~46~12~19 ~46~12~21 minecraft:polished_blackstone_slab 0
fill ~47~12~19 ~47~12~21 minecraft:polished_blackstone_brick_stairs 1
setblock ~51~10~19 minecraft:polished_blackstone_brick_stairs 1
setblock ~53~7~19 minecraft:red_flower 1
setblock ~54~7~19 minecraft:red_flower 9
setblock ~55~7~19 minecraft:red_flower 1
setblock ~56~6~19 minecraft:red_flower 10
setblock ~58~5~19 minecraft:red_flower 3
setblock ~59~5~19 minecraft:red_flower 2
fill ~62~5~19 ~62~5~21 minecraft:tallgrass 0
setblock ~63~5~19 minecraft:red_flower 2
fill ~64~5~19 ~65~5~19 minecraft:tallgrass 0
setblock ~66~4~19 minecraft:tallgrass 0
setblock ~67~4~19 minecraft:red_flower 1
setblock ~68~4~19 minecraft:red_flower 0
setblock ~69~3~19 minecraft:tallgrass 0
fill ~70~1~19 ~70~1~26 minecraft:dirt 0
fill ~70~2~19 ~70~2~20 minecraft:grass
setblock ~70~3~19 minecraft:yellow_flower
setblock ~71~1~19 minecraft:grass
setblock ~72~2~19 minecraft:red_flower 10
setblock ~73~1~19 minecraft:red_flower 9
setblock ~74~1~19 minecraft:red_flower 2
fill ~75~0~19 ~75~0~20 minecraft:tallgrass 0
fill ~3~1~20 ~3~1~21 minecraft:dirt 0
fill ~3~2~20 ~3~2~21 minecraft:grass
setblock ~6~5~20 minecraft:tallgrass 0
setblock ~7~5~20 minecraft:red_flower 3
setblock ~8~5~20 minecraft:red_flower 9
setblock ~9~6~20 minecraft:red_flower 1
fill ~11~5~20 ~11~5~22 minecraft:grass
setblock ~11~6~20 minecraft:red_flower 9
fill ~12~6~20 ~13~6~20 minecraft:grass
setblock ~12~7~20 minecraft:tallgrass 0
setblock ~13~7~20 minecraft:red_flower 0
fill ~14~8~20 ~15~8~20 minecraft:tallgrass 0
fill ~16~8~20 ~17~8~20 minecraft:red_flower 10
fill ~17~7~20 ~17~7~22 minecraft:grass
fill ~18~7~20 ~24~7~20 minecraft:dirt 0
setblock ~18~9~20 minecraft:tallgrass 0
setblock ~19~9~20 minecraft:red_flower 9
setblock ~20~9~20 minecraft:red_flower 1
setblock ~22~10~20 minecraft:red_flower 1
setblock ~23~10~20 minecraft:red_flower 10
setblock ~25~10~20 minecraft:red_flower 0
setblock ~26~10~20 minecraft:red_flower 2
fill ~27~5~20 ~31~5~21 minecraft:dirt 0
setblock ~27~9~20 minecraft:tallgrass 0
fill ~29~6~20 ~31~6~21 minecraft:dirt 0
setblock ~29~10~20 minecraft:polished_blackstone_bricks
setblock ~29~12~20 minecraft:polished_blackstone_bricks
setblock ~29~13~20 minecraft:polished_blackstone_brick_wall 0
setblock ~29~14~20 minecraft:nether_brick_fence
fill ~32~5~20 ~33~5~20 minecraft:grass
fill ~34~6~20 ~35~6~21 minecraft:dirt 0
fill ~35~3~20 ~35~3~21 minecraft:dirt 0
setblock ~36~3~20 minecraft:ice
fill ~37~3~20 ~37~3~21 minecraft:dirt 0
setblock ~51~10~20 minecraft:polished_blackstone_bricks
setblock ~51~12~20 minecraft:polished_blackstone_bricks
setblock ~51~13~20 minecraft:polished_blackstone_brick_wall 0
setblock ~51~14~20 minecraft:nether_brick_fence
setblock ~52~7~20 minecraft:tallgrass 0
fill ~53~6~20 ~53~6~23 minecraft:dirt 0
fill ~53~7~20 ~53~7~21 minecraft:grass
setblock ~53~8~20 minecraft:red_flower 2
fill ~54~7~20 ~55~7~20 minecraft:tallgrass 0
setblock ~56~6~20 minecraft:red_flower 1
fill ~57~4~20 ~57~4~29 minecraft:dirt 0
fill ~57~5~20 ~57~5~29 minecraft:grass
setblock ~57~6~20 minecraft:red_flower 2
fill ~58~4~20 ~59~4~21 minecraft:grass
setblock ~59~5~20 minecraft:tallgrass 0
setblock ~60~5~20 minecraft:red_flower 3
fill ~61~5~20 ~61~5~22 minecraft:tallgrass 0
setblock ~63~5~20 minecraft:red_flower 10
setblock ~64~5~20 minecraft:yellow_flower
setblock ~65~5~20 minecraft:tallgrass 0
setblock ~66~4~20 minecraft:red_flower 10
setblock ~67~4~20 minecraft:red_flower 9
setblock ~68~4~20 minecraft:red_flower 3
fill ~69~2~20 ~69~2~25 minecraft:dirt 0
fill ~69~3~20 ~69~3~25 minecraft:grass
fill ~71~1~20 ~71~1~26 minecraft:dirt 0
fill ~71~2~20 ~71~2~26 minecraft:grass
setblock ~71~3~20 minecraft:red_flower 10
fill ~73~0~20 ~73~0~22 minecraft:dirt 0
fill ~73~1~20 ~73~1~22 minecraft:grass
fill ~73~2~20 ~73~2~21 minecraft:tallgrass 0
setblock ~6~5~21 minecraft:red_flower 9
setblock ~7~5~21 minecraft:tallgrass 0
setblock ~8~5~21 minecraft:red_flower 2
fill ~9~4~21 ~9~4~22 minecraft:grass
setblock ~11~6~21 minecraft:red_flower 10
fill ~12~5~21 ~12~5~22 minecraft:grass
setblock ~12~6~21 minecraft:tallgrass 0
setblock ~13~5~21 minecraft:dirt 0
fill ~13~6~21 ~15~6~21 minecraft:grass
fill ~14~7~21 ~14~7~22 minecraft:red_flower 2
setblock ~15~7~21 minecraft:tallgrass 0
fill ~16~6~21 ~23~6~21 minecraft:dirt 0
fill ~16~8~21 ~17~8~21 minecraft:red_flower 0
fill ~18~7~21 ~18~7~24 minecraft:grass
fill ~19~7~21 ~24~7~21 minecraft:dirt 0
fill ~19~8~21 ~21~8~21 minecraft:grass
setblock ~19~9~21 minecraft:red_flower 2
fill ~21~9~21 ~21~9~22 minecraft:tallgrass 0
fill ~22~8~21 ~22~8~22 minecraft:dirt 0
fill ~22~9~21 ~22~9~22 minecraft:grass
fill ~22~10~21 ~23~10~22 minecraft:tallgrass 0
fill ~25~10~21 ~26~10~21 minecraft:red_flower 9
setblock ~29~10~21 minecraft:polished_blackstone_brick_stairs 0
fill ~29~12~21 ~29~12~22 minecraft:polished_blackstone_brick_wall 0
setblock ~29~23~21 minecraft:polished_blackstone_brick_stairs 0
fill ~30~23~21 ~34~23~21 minecraft:polished_blackstone_brick_stairs 2
setblock ~31~20~21 minecraft:soul_lantern 0
setblock ~31~21~21 minecraft:nether_brick_fence
setblock ~31~22~21 minecraft:polished_blackstone_brick_wall 0
setblock ~32~5~21 minecraft:grass
fill ~33~5~21 ~33~6~21 minecraft:dirt 0
setblock ~33~20~21 minecraft:soul_lantern 0
setblock ~33~21~21 minecraft:nether_brick_fence
setblock ~33~22~21 minecraft:polished_blackstone_brick_wall 0
fill ~35~23~21 ~35~23~22 minecraft:polished_blackstone_brick_stairs 1
setblock ~36~3~21 minecraft:dirt 0
fill ~36~32~21 ~36~32~24 minecraft:smooth_quartz_stairs 4
setblock ~36~33~21 minecraft:polished_blackstone_brick_wall 0
setblock ~36~34~21 minecraft:nether_brick_fence
setblock ~36~35~21 minecraft:soul_lantern 0
fill ~37~32~21 ~44~32~21 minecraft:smooth_quartz_stairs 6
fill ~37~33~21 ~43~33~21 minecraft:polished_blackstone_brick_wall 0
fill ~38~1~21 ~40~1~21 minecraft:dirt 0
setblock ~41~0~21 minecraft:dirt 0
fill ~41~1~21 ~42~1~80 minecraft:quartz_bricks
fill ~44~4~21 ~48~4~21 minecraft:dirt 0
setblock ~44~33~21 minecraft:polished_blackstone_brick_wall 0
setblock ~44~34~21 minecraft:nether_brick_fence
setblock ~44~35~21 minecraft:soul_lantern 0
setblock ~45~1~21 minecraft:dirt 0
fill ~45~23~21 ~45~23~22 minecraft:polished_blackstone_brick_stairs 0
fill ~46~23~21 ~50~23~21 minecraft:polished_blackstone_brick_stairs 2
setblock ~47~20~21 minecraft:soul_lantern 0
setblock ~47~21~21 minecraft:nether_brick_fence
setblock ~47~22~21 minecraft:polished_blackstone_brick_wall 0
fill ~49~4~21 ~49~4~22 minecraft:quartz_bricks
setblock ~49~20~21 minecraft:soul_lantern 0
setblock ~49~21~21 minecraft:nether_brick_fence
setblock ~49~22~21 minecraft:polished_blackstone_brick_wall 0
fill ~51~0~21 ~52~0~24 minecraft:dirt 0
fill ~51~1~21 ~51~1~24 minecraft:dirt 0
fill ~51~5~21 ~51~6~23 minecraft:dirt 0
fill ~51~7~21 ~51~9~22 minecraft:polished_blackstone_bricks
setblock ~51~10~21 minecraft:polished_blackstone_brick_stairs 1
fill ~51~12~21 ~51~12~22 minecraft:polished_blackstone_brick_wall 0
setblock ~51~23~21 minecraft:polished_blackstone_brick_stairs 1
fill ~52~6~21 ~52~6~24 minecraft:dirt 0
setblock ~52~7~21 minecraft:grass
fill ~53~8~21 ~54~8~21 minecraft:tallgrass 0
fill ~54~6~21 ~54~6~23 minecraft:dirt 0
fill ~54~7~21 ~54~7~23 minecraft:grass
setblock ~56~6~21 minecraft:red_flower 3
setblock ~57~6~21 minecraft:red_flower 9
setblock ~58~5~21 minecraft:tallgrass 0
setblock ~59~5~21 minecraft:red_flower 0
setblock ~63~5~21 minecraft:red_flower 9
setblock ~64~5~21 minecraft:red_flower 10
fill ~65~3~21 ~65~3~26 minecraft:grass
setblock ~65~4~21 minecraft:red_flower 1
setblock ~67~4~21 minecraft:red_flower 3
fill ~68~4~21 ~70~4~21 minecraft:tallgrass 0
fill ~70~2~21 ~70~2~25 minecraft:dirt 0
fill ~70~3~21 ~70~3~25 minecraft:grass
fill ~71~3~21 ~71~3~22 minecraft:tallgrass 0
fill ~72~1~21 ~72~1~22 minecraft:dirt 0
fill ~72~2~21 ~72~2~22 minecraft:grass
fill ~74~1~21 ~74~1~22 minecraft:tallgrass 0
setblock ~75~0~21 minecraft:red_flower 0
fill ~3~1~22 ~3~1~24 minecraft:grass
fill ~6~3~22 ~8~3~22 minecraft:grass
setblock ~6~4~22 minecraft:red_flower 9
fill ~7~4~22 ~7~4~23 minecraft:tallgrass 0
setblock ~8~4~22 minecraft:red_flower 10
setblock ~9~5~22 minecraft:tallgrass 0
fill ~10~4~22 ~10~4~23 minecraft:grass
setblock ~11~6~22 minecraft:red_flower 2
setblock ~12~6~22 minecraft:red_flower 10
fill ~13~1~22 ~30~1~22 minecraft:dirt 0
fill ~13~5~22 ~13~5~23 minecraft:grass
setblock ~13~6~22 minecraft:red_flower 9
fill ~14~6~22 ~16~6~23 minecraft:grass
setblock ~15~7~22 minecraft:red_flower 0
fill ~16~7~22 ~16~7~24 minecraft:tallgrass 0
fill ~17~0~22 ~32~0~23 minecraft:dirt 0
fill ~17~6~22 ~23~6~22 minecraft:dirt 0
setblock ~17~8~22 minecraft:red_flower 2
setblock ~18~8~22 minecraft:tallgrass 0
fill ~19~7~22 ~19~7~25 minecraft:grass
fill ~20~7~22 ~24~7~23 minecraft:dirt 0
fill ~20~8~22 ~21~8~23 minecraft:grass
fill ~20~9~22 ~20~9~23 minecraft:tallgrass 0
setblock ~25~10~22 minecraft:red_flower 10
setblock ~26~10~22 minecraft:red_flower 0
fill ~27~2~22 ~30~3~22 minecraft:dirt 0
fill ~27~5~22 ~30~5~22 minecraft:dirt 0
setblock ~27~8~22 minecraft:dirt 0
setblock ~27~9~22 minecraft:grass
setblock ~27~10~22 minecraft:red_flower 9
fill ~28~4~22 ~30~4~22 minecraft:dirt 0
setblock ~28~9~22 minecraft:tallgrass 0
setblock ~28~23~22 minecraft:polished_blackstone_brick_stairs 2
fill ~29~6~22 ~30~6~22 minecraft:dirt 0
setblock ~29~10~22 minecraft:polished_blackstone_bricks
fill ~29~23~22 ~34~23~22 minecraft:polished_blackstone_bricks
fill ~30~7~22 ~30~10~22 minecraft:dirt 0
setblock ~30~20~22 minecraft:nether_brick_fence
fill ~30~21~22 ~30~22~22 minecraft:polished_blackstone_brick_wall 0
setblock ~30~24~22 minecraft:polished_blackstone_brick_wall 0
setblock ~30~25~22 minecraft:nether_brick_fence
fill ~31~1~22 ~40~1~28 minecraft:quartz_bricks
fill ~31~2~22 ~49~3~22 minecraft:quartz_bricks
fill ~31~4~22 ~48~10~22 minecraft:quartz_bricks
fill ~31~12~22 ~49~13~22 minecraft:quartz_bricks
fill ~31~14~22 ~37~14~43 minecraft:quartz_bricks
fill ~31~15~22 ~34~15~28 minecraft:quartz_bricks
fill ~31~16~22 ~31~16~28 minecraft:quartz_bricks
fill ~31~17~22 ~31~22~22 minecraft:quartz_bricks
fill ~31~24~22 ~33~24~22 minecraft:polished_blackstone_bricks
setblock ~31~25~22 minecraft:polished_blackstone_brick_stairs 0
setblock ~32~16~22 minecraft:smooth_quartz_stairs 6
fill ~32~17~22 ~32~21~22 minecraft:stained_glass_pane 3
fill ~32~22~22 ~33~22~22 minecraft:quartz_bricks
fill ~32~25~22 ~32~25~23 minecraft:polished_blackstone_bricks
setblock ~32~26~22 minecraft:polished_blackstone_brick_stairs 2
fill ~33~0~22 ~34~0~22 minecraft:water 7
fill ~33~11~22 ~47~11~22 minecraft:quartz_bricks
fill ~33~16~22 ~33~16~27 minecraft:quartz_bricks
fill ~33~17~22 ~33~21~22 minecraft:quartz_bricks
setblock ~33~25~22 minecraft:polished_blackstone_brick_stairs 1
setblock ~34~16~22 minecraft:smooth_quartz_stairs 1
setblock ~34~20~22 minecraft:nether_brick_fence
fill ~34~21~22 ~34~22~22 minecraft:polished_blackstone_brick_wall 0
setblock ~34~24~22 minecraft:polished_blackstone_brick_wall 0
setblock ~34~25~22 minecraft:nether_brick_fence
setblock ~35~15~22 minecraft:smooth_quartz_stairs 1
fill ~36~0~22 ~37~0~22 minecraft:water 7
setblock ~36~23~22 minecraft:polished_blackstone_brick_stairs 2
fill ~36~33~22 ~36~33~23 minecraft:polished_blackstone_brick_wall 0
fill ~37~31~22 ~38~31~23 minecraft:stone_block_slab 14
fill ~37~32~22 ~43~32~34 minecraft:quartz_bricks
fill ~39~31~22 ~41~31~22 minecraft:smooth_quartz_stairs 6
fill ~42~31~22 ~43~31~23 minecraft:stone_block_slab 14
setblock ~43~0~22 minecraft:water 7
fill ~43~1~22 ~50~1~28 minecraft:quartz_bricks
fill ~43~14~22 ~49~14~74 minecraft:quartz_bricks
setblock ~44~23~22 minecraft:polished_blackstone_brick_stairs 2
fill ~44~32~22 ~44~32~24 minecraft:smooth_quartz_stairs 5
fill ~44~33~22 ~44~33~23 minecraft:polished_blackstone_brick_wall 0
setblock ~45~15~22 minecraft:smooth_quartz_stairs 0
fill ~46~0~22 ~47~0~22 minecraft:water 7
fill ~46~15~22 ~49~15~28 minecraft:quartz_bricks
setblock ~46~16~22 minecraft:smooth_quartz_stairs 0
setblock ~46~20~22 minecraft:nether_brick_fence
fill ~46~21~22 ~46~22~22 minecraft:polished_blackstone_brick_wall 0
fill ~46~23~22 ~51~23~22 minecraft:polished_blackstone_bricks
setblock ~46~24~22 minecraft:polished_blackstone_brick_wall 0
setblock ~46~25~22 minecraft:nether_brick_fence
fill ~47~16~22 ~47~16~27 minecraft:quartz_bricks
fill ~47~17~22 ~47~22~22 minecraft:quartz_bricks
fill ~47~24~22 ~49~24~22 minecraft:polished_blackstone_bricks
setblock ~47~25~22 minecraft:polished_blackstone_brick_stairs 0
setblock ~48~16~22 minecraft:smooth_quartz_stairs 6
fill ~48~17~22 ~48~21~22 minecraft:stained_glass_pane 3
fill ~48~22~22 ~49~22~22 minecraft:quartz_bricks
fill ~48~25~22 ~48~25~23 minecraft:polished_blackstone_bricks
setblock ~48~26~22 minecraft:polished_blackstone_brick_stairs 2
fill ~49~5~22 ~49~10~22 minecraft:quartz_bricks
fill ~49~16~22 ~49~16~28 minecraft:quartz_bricks
fill ~49~17~22 ~49~21~22 minecraft:quartz_bricks
setblock ~49~25~22 minecraft:polished_blackstone_brick_stairs 1
setblock ~50~2~22 minecraft:dirt 0
fill ~50~5~22 ~50~10~22 minecraft:dirt 0
setblock ~50~20~22 minecraft:nether_brick_fence
fill ~50~21~22 ~50~22~22 minecraft:polished_blackstone_brick_wall 0
setblock ~50~24~22 minecraft:polished_blackstone_brick_wall 0
setblock ~50~25~22 minecraft:nether_brick_fence
fill ~51~10~22 ~51~10~23 minecraft:polished_blackstone_bricks
fill ~52~7~22 ~53~7~23 minecraft:dirt 0
setblock ~52~8~22 minecraft:smooth_quartz_stairs 2
setblock ~52~23~22 minecraft:polished_blackstone_brick_stairs 2
fill ~53~8~22 ~53~8~28 minecraft:smooth_quartz_stairs 1
setblock ~54~8~22 minecraft:red_flower 1
setblock ~55~7~22 minecraft:yellow_flower
setblock ~56~6~22 minecraft:red_flower 1
setblock ~57~6~22 minecraft:yellow_flower
fill ~58~4~22 ~58~4~29 minecraft:dirt 0
fill ~58~5~22 ~58~5~29 minecraft:grass
setblock ~58~6~22 minecraft:red_flower 2
setblock ~59~4~22 minecraft:grass
fill ~62~3~22 ~63~3~22 minecraft:dirt 0
fill ~62~4~22 ~63~4~22 minecraft:grass
setblock ~62~5~22 minecraft:red_flower 9
setblock ~63~5~22 minecraft:red_flower 3
fill ~64~3~22 ~64~3~29 minecraft:grass
setblock ~65~4~22 minecraft:red_flower 9
setblock ~66~4~22 minecraft:tallgrass 0
setblock ~67~4~22 minecraft:red_flower 9
setblock ~68~4~22 minecraft:red_flower 10
setblock ~69~4~22 minecraft:red_flower 9
setblock ~70~4~22 minecraft:red_flower 10
setblock ~72~3~22 minecraft:tallgrass 0
setblock ~75~0~22 minecraft:red_flower 1
setblock ~5~3~23 minecraft:tallgrass 0
fill ~6~2~23 ~6~2~31 minecraft:grass
setblock ~6~3~23 minecraft:red_flower 3
setblock ~7~2~23 minecraft:dirt 0
fill ~7~3~23 ~9~3~23 minecraft:grass
setblock ~8~4~23 minecraft:red_flower 3
fill ~10~3~23 ~11~3~23 minecraft:dirt 0
fill ~10~5~23 ~11~5~23 minecraft:tallgrass 0
fill ~11~4~23 ~12~4~24 minecraft:grass
fill ~13~1~23 ~25~1~23 minecraft:dirt 0
setblock ~13~6~23 minecraft:red_flower 10
setblock ~14~7~23 minecraft:red_flower 0
fill ~17~6~23 ~17~6~25 minecraft:grass
setblock ~17~7~23 minecraft:tallgrass 0
fill ~18~6~23 ~23~6~24 minecraft:dirt 0
fill ~22~8~23 ~22~8~26 minecraft:grass
setblock ~22~9~23 minecraft:tallgrass 0
fill ~23~10~23 ~25~10~23 minecraft:tallgrass 0
fill ~26~1~23 ~27~1~24 minecraft:coal_ore
fill ~26~2~23 ~27~2~23 minecraft:coal_ore
fill ~27~3~23 ~29~3~23 minecraft:dirt 0
fill ~27~5~23 ~29~5~23 minecraft:dirt 0
fill ~27~8~23 ~27~8~26 minecraft:grass
fill ~28~1~23 ~29~2~23 minecraft:dirt 0
fill ~28~4~23 ~29~4~23 minecraft:dirt 0
fill ~28~8~23 ~28~8~24 minecraft:dirt 0
fill ~28~9~23 ~28~9~30 minecraft:polished_blackstone_bricks
setblock ~28~10~23 minecraft:polished_blackstone_bricks
setblock ~28~11~23 minecraft:polished_blackstone_brick_wall 0
setblock ~28~12~23 minecraft:nether_brick_fence
fill ~28~23~23 ~28~23~28 minecraft:polished_blackstone_brick_stairs 0
setblock ~29~6~23 minecraft:dirt 0
setblock ~29~10~23 minecraft:polished_blackstone_brick_stairs 2
fill ~29~11~23 ~29~12~23 minecraft:polished_blackstone_bricks
setblock ~29~13~23 minecraft:polished_blackstone_brick_wall 0
setblock ~29~14~23 minecraft:nether_brick_fence
setblock ~29~15~23 minecraft:soul_lantern 0
setblock ~29~20~23 minecraft:nether_brick_fence
fill ~29~21~23 ~29~22~23 minecraft:polished_blackstone_brick_wall 0
fill ~29~23~23 ~30~23~23 minecraft:polished_blackstone_bricks
setblock ~29~24~23 minecraft:polished_blackstone_brick_wall 0
setblock ~29~25~23 minecraft:nether_brick_fence
fill ~30~1~23 ~30~1~76 minecraft:quartz_bricks
fill ~30~2~23 ~30~22~23 minecraft:quartz_bricks
setblock ~30~24~23 minecraft:polished_blackstone_bricks
fill ~30~25~23 ~30~26~23 minecraft:polished_blackstone_brick_wall 0
setblock ~30~27~23 minecraft:nether_brick_fence
fill ~31~2~23 ~32~2~23 minecraft:spruce_stairs 7
fill ~31~3~23 ~32~6~23 minecraft:chest 3
fill ~31~7~23 ~32~7~23 minecraft:spruce_stairs 3
fill ~31~8~23 ~49~8~23 minecraft:smooth_quartz_stairs 3
fill ~31~9~23 ~49~9~23 minecraft:smooth_quartz_stairs 7
fill ~31~10~23 ~50~10~39 minecraft:quartz_bricks
fill ~31~11~23 ~31~13~33 minecraft:quartz_bricks
fill ~31~23~23 ~32~23~23 minecraft:smooth_quartz_stairs 7
fill ~31~24~23 ~33~24~27 minecraft:quartz_bricks
fill ~31~25~23 ~31~27~23 minecraft:polished_blackstone_bricks
setblock ~31~28~23 minecraft:polished_blackstone_brick_stairs 0
fill ~32~16~23 ~32~16~30 minecraft:quartz_bricks
fill ~32~26~23 ~33~27~23 minecraft:polished_blackstone_bricks
fill ~32~28~23 ~32~29~27 minecraft:polished_blackstone_bricks
setblock ~32~30~23 minecraft:polished_blackstone_brick_stairs 2
fill ~33~0~23 ~34~0~23 minecraft:water 6
fill ~33~2~23 ~33~7~23 minecraft:stripped_spruce_log 0
setblock ~33~13~23 minecraft:soul_lantern 0
setblock ~33~23~23 minecraft:smooth_quartz_stairs 4
setblock ~33~25~23 minecraft:polished_blackstone_bricks
setblock ~33~28~23 minecraft:polished_blackstone_brick_stairs 1
fill ~34~2~23 ~35~2~23 minecraft:spruce_stairs 7
fill ~34~3~23 ~35~6~23 minecraft:chest 3
fill ~34~7~23 ~35~7~23 minecraft:spruce_stairs 3
fill ~34~16~23 ~34~16~27 minecraft:quartz_bricks
fill ~34~17~23 ~34~22~23 minecraft:quartz_bricks
fill ~34~23~23 ~35~23~23 minecraft:polished_blackstone_bricks
setblock ~34~24~23 minecraft:polished_blackstone_bricks
fill ~34~25~23 ~34~26~23 minecraft:polished_blackstone_brick_wall 0
setblock ~34~27~23 minecraft:nether_brick_fence
setblock ~35~0~23 minecraft:water 7
fill ~35~15~23 ~37~15~23 minecraft:smooth_quartz_stairs 2
setblock ~35~20~23 minecraft:nether_brick_fence
fill ~35~21~23 ~35~22~23 minecraft:polished_blackstone_brick_wall 0
setblock ~35~24~23 minecraft:polished_blackstone_brick_wall 0
setblock ~35~25~23 minecraft:nether_brick_fence
fill ~36~0~23 ~37~0~23 minecraft:water 6
fill ~36~2~23 ~36~7~23 minecraft:stripped_spruce_log 0
setblock ~36~23~23 minecraft:polished_blackstone_brick_stairs 1
fill ~37~2~23 ~38~2~23 minecraft:spruce_stairs 7
fill ~37~3~23 ~38~6~23 minecraft:chest 3
fill ~37~7~23 ~38~7~23 minecraft:spruce_stairs 3
setblock ~38~0~23 minecraft:water 7
fill ~39~2~23 ~39~7~23 minecraft:stripped_spruce_log 0
fill ~39~31~23 ~39~31~24 minecraft:smooth_quartz_stairs 4
setblock ~40~2~23 minecraft:spruce_stairs 7
fill ~40~3~23 ~40~6~23 minecraft:crafting_table
setblock ~40~7~23 minecraft:spruce_stairs 3
setblock ~40~30~23 minecraft:stone_block_slab 14
fill ~40~31~23 ~40~31~73 minecraft:quartz_bricks
fill ~41~2~23 ~41~7~23 minecraft:stripped_spruce_log 0
fill ~41~31~23 ~41~31~24 minecraft:smooth_quartz_stairs 5
setblock ~42~0~23 minecraft:water 7
fill ~42~2~23 ~43~2~23 minecraft:spruce_stairs 7
fill ~42~3~23 ~43~6~23 minecraft:chest 3
fill ~42~7~23 ~43~7~23 minecraft:spruce_stairs 3
setblock ~43~0~23 minecraft:water 6
fill ~43~15~23 ~45~15~23 minecraft:smooth_quartz_stairs 2
fill ~44~0~23 ~45~0~23 minecraft:water 7
fill ~44~2~23 ~44~7~23 minecraft:stripped_spruce_log 0
setblock ~44~23~23 minecraft:polished_blackstone_brick_stairs 0
fill ~45~2~23 ~46~2~23 minecraft:spruce_stairs 7
fill ~45~3~23 ~46~6~23 minecraft:chest 3
fill ~45~7~23 ~46~7~23 minecraft:spruce_stairs 3
setblock ~45~20~23 minecraft:nether_brick_fence
fill ~45~21~23 ~45~22~23 minecraft:polished_blackstone_brick_wall 0
fill ~45~23~23 ~46~23~23 minecraft:polished_blackstone_bricks
setblock ~45~24~23 minecraft:polished_blackstone_brick_wall 0
setblock ~45~25~23 minecraft:nether_brick_fence
fill ~46~0~23 ~47~0~23 minecraft:water 6
fill ~46~16~23 ~46~16~27 minecraft:quartz_bricks
fill ~46~17~23 ~46~22~23 minecraft:quartz_bricks
setblock ~46~24~23 minecraft:polished_blackstone_bricks
fill ~46~25~23 ~46~26~23 minecraft:polished_blackstone_brick_wall 0
setblock ~46~27~23 minecraft:nether_brick_fence
fill ~47~2~23 ~47~7~23 minecraft:stripped_spruce_log 0
fill ~47~23~23 ~48~23~23 minecraft:smooth_quartz_stairs 7
fill ~47~24~23 ~49~24~27 minecraft:quartz_bricks
fill ~47~25~23 ~47~27~23 minecraft:polished_blackstone_bricks
setblock ~47~28~23 minecraft:polished_blackstone_brick_stairs 0
setblock ~48~0~23 minecraft:water 7
fill ~48~2~23 ~49~2~23 minecraft:spruce_stairs 7
fill ~48~3~23 ~49~6~23 minecraft:chest 3
fill ~48~7~23 ~49~7~23 minecraft:spruce_stairs 3
fill ~48~16~23 ~48~16~30 minecraft:quartz_bricks
fill ~48~26~23 ~49~27~23 minecraft:polished_blackstone_bricks
fill ~48~28~23 ~48~29~27 minecraft:polished_blackstone_bricks
setblock ~48~30~23 minecraft:polished_blackstone_brick_stairs 2
fill ~49~11~23 ~50~13~23 minecraft:quartz_bricks
setblock ~49~23~23 minecraft:smooth_quartz_stairs 4
setblock ~49~25~23 minecraft:polished_blackstone_bricks
setblock ~49~28~23 minecraft:polished_blackstone_brick_stairs 1
fill ~50~2~23 ~50~9~23 minecraft:quartz_bricks
fill ~50~14~23 ~50~16~27 minecraft:quartz_bricks
fill ~50~17~23 ~50~22~23 minecraft:quartz_bricks
fill ~50~23~23 ~51~23~23 minecraft:polished_blackstone_bricks
setblock ~50~24~23 minecraft:polished_blackstone_bricks
fill ~50~25~23 ~50~26~23 minecraft:polished_blackstone_brick_wall 0
setblock ~50~27~23 minecraft:nether_brick_fence
fill ~51~7~23 ~51~8~26 minecraft:quartz_bricks
fill ~51~9~23 ~52~9~23 minecraft:polished_blackstone_bricks
fill ~51~11~23 ~51~12~23 minecraft:polished_blackstone_bricks
setblock ~51~13~23 minecraft:polished_blackstone_brick_wall 0
setblock ~51~14~23 minecraft:nether_brick_fence
setblock ~51~15~23 minecraft:soul_lantern 0
setblock ~51~20~23 minecraft:nether_brick_fence
fill ~51~21~23 ~51~22~23 minecraft:polished_blackstone_brick_wall 0
setblock ~51~24~23 minecraft:polished_blackstone_brick_wall 0
setblock ~51~25~23 minecraft:nether_brick_fence
fill ~52~8~23 ~52~8~30 minecraft:quartz_bricks
setblock ~52~10~23 minecraft:polished_blackstone_bricks
setblock ~52~11~23 minecraft:polished_blackstone_brick_wall 0
setblock ~52~12~23 minecraft:nether_brick_fence
fill ~52~23~23 ~52~23~28 minecraft:polished_blackstone_brick_stairs 1
setblock ~54~8~23 minecraft:red_flower 0
fill ~56~6~23 ~56~6~24 minecraft:red_flower 2
fill ~58~6~23 ~58~6~24 minecraft:red_flower 0
fill ~59~4~23 ~59~4~29 minecraft:dirt 0
fill ~59~5~23 ~59~5~29 minecraft:grass
setblock ~59~6~23 minecraft:yellow_flower
setblock ~60~5~23 minecraft:red_flower 2
setblock ~61~5~23 minecraft:red_flower 3
fill ~62~3~23 ~62~3~29 minecraft:dirt 0
fill ~62~4~23 ~62~4~27 minecraft:grass
setblock ~62~5~23 minecraft:red_flower 10
fill ~63~3~23 ~63~3~25 minecraft:grass
setblock ~64~4~23 minecraft:red_flower 10
fill ~65~4~23 ~66~4~23 minecraft:red_flower 1
fill ~68~4~23 ~69~4~23 minecraft:red_flower 0
setblock ~71~3~23 minecraft:red_flower 10
fill ~72~1~23 ~72~1~27 minecraft:grass
setblock ~72~2~23 minecraft:tallgrass 0
fill ~73~0~23 ~73~0~28 minecraft:grass
setblock ~73~1~23 minecraft:tallgrass 0
setblock ~74~1~23 minecraft:red_flower 1
setblock ~75~0~23 minecraft:red_flower 9
setblock ~76~0~23 minecraft:tallgrass 0
fill ~1~0~24 ~1~0~25 minecraft:dirt 0
fill ~1~1~24 ~1~1~25 minecraft:grass
setblock ~5~3~24 minecraft:yellow_flower
setblock ~6~3~24 minecraft:red_flower 0
fill ~7~2~24 ~8~2~29 minecraft:grass
setblock ~8~3~24 minecraft:red_flower 0
setblock ~9~2~24 minecraft:dirt 0
fill ~9~3~24 ~10~3~24 minecraft:grass
setblock ~9~4~24 minecraft:red_flower 10
setblock ~10~4~24 minecraft:red_flower 2
setblock ~11~3~24 minecraft:dirt 0
setblock ~12~5~24 minecraft:yellow_flower
fill ~13~1~24 ~24~1~29 minecraft:dirt 0
fill ~13~4~24 ~13~4~25 minecraft:grass
setblock ~13~5~24 minecraft:red_flower 1
fill ~14~5~24 ~15~5~25 minecraft:grass
setblock ~14~6~24 minecraft:tallgrass 0
setblock ~15~6~24 minecraft:red_flower 0
fill ~16~5~24 ~17~5~24 minecraft:dirt 0
setblock ~16~6~24 minecraft:grass
fill ~17~0~24 ~24~0~25 minecraft:dirt 0
fill ~20~7~24 ~20~7~28 minecraft:grass
setblock ~20~8~24 minecraft:red_flower 3
fill ~21~7~24 ~24~7~25 minecraft:dirt 0
fill ~21~8~24 ~21~8~25 minecraft:grass
fill ~21~9~24 ~21~9~25 minecraft:tallgrass 0
fill ~23~8~24 ~23~8~27 minecraft:grass
setblock ~23~9~24 minecraft:tallgrass 0
fill ~24~10~24 ~25~10~24 minecraft:tallgrass 0
fill ~25~0~24 ~26~0~25 minecraft:coal_ore
fill ~25~1~24 ~25~1~25 minecraft:coal_ore
setblock ~26~2~24 minecraft:coal_ore
fill ~26~8~24 ~26~8~28 minecraft:grass
setblock ~26~9~24 minecraft:red_flower 9
fill ~27~0~24 ~32~0~24 minecraft:dirt 0
fill ~27~2~24 ~28~3~26 minecraft:dirt 0
fill ~27~5~24 ~28~5~26 minecraft:dirt 0
fill ~27~9~24 ~27~9~25 minecraft:red_flower 1
fill ~28~1~24 ~28~1~26 minecraft:dirt 0
fill ~28~4~24 ~28~4~26 minecraft:dirt 0
fill ~28~10~24 ~28~10~29 minecraft:polished_blackstone_brick_stairs 0
setblock ~28~20~24 minecraft:soul_lantern 0
setblock ~28~21~24 minecraft:nether_brick_fence
setblock ~28~22~24 minecraft:polished_blackstone_brick_wall 0
fill ~29~1~24 ~29~1~76 minecraft:quartz_bricks
fill ~29~2~24 ~29~15~26 minecraft:quartz_bricks
fill ~29~16~24 ~30~16~24 minecraft:quartz_bricks
fill ~29~17~24 ~29~22~24 minecraft:quartz_bricks
fill ~29~23~24 ~29~23~27 minecraft:polished_blackstone_bricks
fill ~29~24~24 ~29~24~26 minecraft:polished_blackstone_bricks
setblock ~29~25~24 minecraft:polished_blackstone_brick_stairs 2
fill ~30~2~24 ~30~2~25 minecraft:spruce_stairs 5
fill ~30~3~24 ~30~6~25 minecraft:chest 5
fill ~30~7~24 ~30~7~25 minecraft:spruce_stairs 1
fill ~30~8~24 ~30~8~26 minecraft:smooth_quartz_stairs 1
setblock ~30~9~24 minecraft:smooth_quartz_stairs 7
fill ~30~10~24 ~30~10~76 minecraft:quartz_bricks
fill ~30~13~24 ~30~15~27 minecraft:quartz_bricks
setblock ~30~23~24 minecraft:smooth_quartz_stairs 7
fill ~30~24~24 ~30~24~26 minecraft:quartz_bricks
fill ~30~25~24 ~30~27~26 minecraft:polished_blackstone_bricks
setblock ~30~28~24 minecraft:polished_blackstone_brick_stairs 2
fill ~31~2~24 ~33~2~24 minecraft:carpet 7
setblock ~31~9~24 minecraft:smooth_quartz_stairs 5
setblock ~31~23~24 minecraft:smooth_quartz_stairs 5
fill ~31~28~24 ~31~30~26 minecraft:polished_blackstone_bricks
setblock ~31~31~24 minecraft:polished_blackstone_brick_wall 0
setblock ~32~22~24 minecraft:soul_lantern 0
fill ~32~23~24 ~32~23~26 minecraft:nether_brick_fence
fill ~32~30~24 ~33~30~26 minecraft:polished_blackstone_bricks
fill ~32~31~24 ~32~32~26 minecraft:polished_blackstone_bricks
setblock ~32~33~24 minecraft:polished_blackstone_brick_stairs 2
fill ~33~0~24 ~34~0~24 minecraft:water 5
setblock ~33~5~24 minecraft:soul_lantern 0
setblock ~33~6~24 minecraft:fence 0
setblock ~33~7~24 minecraft:dark_oak_trapdoor 2
setblock ~33~23~24 minecraft:smooth_quartz_stairs 7
fill ~33~28~24 ~33~29~26 minecraft:polished_blackstone_bricks
setblock ~33~31~24 minecraft:smooth_quartz_stairs 0
fill ~34~2~24 ~46~2~24 minecraft:carpet 13
fill ~34~23~24 ~34~23~25 minecraft:smooth_quartz_stairs 4
fill ~34~24~24 ~34~24~36 minecraft:quartz_bricks
fill ~34~25~24 ~34~27~25 minecraft:polished_blackstone_bricks
setblock ~34~28~24 minecraft:polished_blackstone_brick_stairs 2
setblock ~34~31~24 minecraft:smooth_quartz_stairs 5
setblock ~34~32~24 minecraft:smooth_quartz_stairs 0
setblock ~35~0~24 minecraft:water 6
fill ~35~15~24 ~36~15~34 minecraft:quartz_bricks
fill ~35~16~24 ~35~22~28 minecraft:quartz_bricks
fill ~35~23~24 ~35~23~25 minecraft:polished_blackstone_bricks
setblock ~35~24~24 minecraft:polished_blackstone_bricks
setblock ~35~25~24 minecraft:polished_blackstone_brick_stairs 2
setblock ~35~32~24 minecraft:smooth_quartz_stairs 5
setblock ~35~33~24 minecraft:quartz_bricks
setblock ~35~34~24 minecraft:smooth_quartz_stairs 0
fill ~36~0~24 ~37~0~24 minecraft:water 5
setblock ~36~5~24 minecraft:soul_lantern 0
setblock ~36~6~24 minecraft:fence 0
setblock ~36~7~24 minecraft:dark_oak_trapdoor 2
fill ~36~16~24 ~36~22~24 minecraft:polished_blackstone_brick_wall 0
fill ~36~23~24 ~44~23~24 minecraft:polished_blackstone_brick_stairs 2
setblock ~36~33~24 minecraft:polished_blackstone_brick_wall 0
setblock ~36~34~24 minecraft:smooth_quartz_stairs 5
fill ~36~35~24 ~36~36~24 minecraft:quartz_bricks
setblock ~36~37~24 minecraft:smooth_quartz_stairs 0
setblock ~37~15~24 minecraft:smooth_quartz_stairs 1
setblock ~37~31~24 minecraft:smooth_quartz_stairs 4
setblock ~37~37~24 minecraft:smooth_quartz_stairs 5
fill ~37~38~24 ~37~39~24 minecraft:quartz_bricks
setblock ~37~40~24 minecraft:smooth_quartz_stairs 0
setblock ~38~0~24 minecraft:water 6
setblock ~38~20~24 minecraft:soul_lantern 0
setblock ~38~21~24 minecraft:nether_brick_fence
setblock ~38~22~24 minecraft:polished_blackstone_brick_wall 0
setblock ~38~31~24 minecraft:smooth_quartz_stairs 6
fill ~38~33~24 ~38~33~25 minecraft:stained_glass_pane 3
setblock ~38~34~24 minecraft:iron_bars
fill ~38~35~24 ~38~35~25 minecraft:stained_glass_pane 3
setblock ~38~40~24 minecraft:smooth_quartz_stairs 5
fill ~38~41~24 ~38~42~24 minecraft:quartz_bricks
setblock ~38~43~24 minecraft:smooth_quartz_stairs 0
setblock ~39~0~24 minecraft:water 7
setblock ~39~5~24 minecraft:soul_lantern 0
setblock ~39~6~24 minecraft:fence 0
setblock ~39~7~24 minecraft:dark_oak_trapdoor 2
fill ~39~15~24 ~39~15~25 minecraft:stained_glass_pane 3
fill ~39~16~24 ~39~17~24 minecraft:iron_bars
fill ~39~18~24 ~39~18~25 minecraft:stained_glass_pane 3
setblock ~39~43~24 minecraft:smooth_quartz_stairs 5
fill ~39~44~24 ~39~45~24 minecraft:quartz_bricks
setblock ~39~46~24 minecraft:smooth_quartz_stairs 0
setblock ~40~30~24 minecraft:smooth_quartz_stairs 6
fill ~40~33~24 ~40~33~25 minecraft:stained_glass_pane 3
setblock ~40~34~24 minecraft:iron_bars
fill ~40~35~24 ~40~35~25 minecraft:stained_glass_pane 3
setblock ~40~46~24 minecraft:smooth_quartz_stairs 6
fill ~40~47~24 ~40~48~24 minecraft:quartz_bricks
setblock ~40~49~24 minecraft:smooth_quartz_stairs 2
setblock ~41~0~24 minecraft:water 7
setblock ~41~5~24 minecraft:soul_lantern 0
setblock ~41~6~24 minecraft:fence 0
setblock ~41~7~24 minecraft:dark_oak_trapdoor 2
fill ~41~15~24 ~41~15~25 minecraft:stained_glass_pane 3
fill ~41~16~24 ~41~17~24 minecraft:iron_bars
fill ~41~18~24 ~41~18~25 minecraft:stained_glass_pane 3
setblock ~41~43~24 minecraft:smooth_quartz_stairs 4
fill ~41~44~24 ~41~45~24 minecraft:quartz_bricks
setblock ~41~46~24 minecraft:smooth_quartz_stairs 1
setblock ~42~0~24 minecraft:water 6
setblock ~42~20~24 minecraft:soul_lantern 0
setblock ~42~21~24 minecraft:nether_brick_fence
setblock ~42~22~24 minecraft:polished_blackstone_brick_wall 0
setblock ~42~31~24 minecraft:smooth_quartz_stairs 6
setblock ~42~40~24 minecraft:smooth_quartz_stairs 4
fill ~42~41~24 ~42~42~24 minecraft:quartz_bricks
setblock ~42~43~24 minecraft:smooth_quartz_stairs 1
setblock ~43~0~24 minecraft:water 5
setblock ~43~15~24 minecraft:smooth_quartz_stairs 0
setblock ~43~31~24 minecraft:smooth_quartz_stairs 5
setblock ~43~37~24 minecraft:smooth_quartz_stairs 4
fill ~43~38~24 ~43~39~24 minecraft:quartz_bricks
setblock ~43~40~24 minecraft:smooth_quartz_stairs 1
fill ~44~0~24 ~45~0~24 minecraft:water 6
setblock ~44~5~24 minecraft:soul_lantern 0
setblock ~44~6~24 minecraft:fence 0
setblock ~44~7~24 minecraft:dark_oak_trapdoor 2
fill ~44~15~24 ~45~15~34 minecraft:quartz_bricks
fill ~44~16~24 ~44~22~24 minecraft:polished_blackstone_brick_wall 0
setblock ~44~33~24 minecraft:polished_blackstone_brick_wall 0
setblock ~44~34~24 minecraft:smooth_quartz_stairs 4
fill ~44~35~24 ~44~36~24 minecraft:quartz_bricks
setblock ~44~37~24 minecraft:smooth_quartz_stairs 1
fill ~45~16~24 ~45~22~28 minecraft:quartz_bricks
fill ~45~23~24 ~45~23~25 minecraft:polished_blackstone_bricks
setblock ~45~24~24 minecraft:polished_blackstone_bricks
setblock ~45~25~24 minecraft:polished_blackstone_brick_stairs 2
setblock ~45~32~24 minecraft:smooth_quartz_stairs 4
setblock ~45~33~24 minecraft:quartz_bricks
setblock ~45~34~24 minecraft:smooth_quartz_stairs 1
fill ~46~0~24 ~47~0~24 minecraft:water 5
setblock ~46~23~24 minecraft:smooth_quartz_stairs 7
fill ~46~24~24 ~46~24~35 minecraft:quartz_bricks
fill ~46~25~24 ~46~27~25 minecraft:polished_blackstone_bricks
setblock ~46~28~24 minecraft:polished_blackstone_brick_stairs 2
setblock ~46~31~24 minecraft:smooth_quartz_stairs 4
setblock ~46~32~24 minecraft:smooth_quartz_stairs 1
fill ~47~2~24 ~49~2~24 minecraft:carpet 7
setblock ~47~5~24 minecraft:soul_lantern 0
setblock ~47~6~24 minecraft:fence 0
setblock ~47~7~24 minecraft:dark_oak_trapdoor 2
setblock ~47~23~24 minecraft:smooth_quartz_stairs 5
fill ~47~28~24 ~47~30~26 minecraft:polished_blackstone_bricks
setblock ~47~31~24 minecraft:smooth_quartz_stairs 1
setblock ~48~0~24 minecraft:water 6
setblock ~48~22~24 minecraft:soul_lantern 0
fill ~48~23~24 ~48~23~26 minecraft:nether_brick_fence
fill ~48~30~24 ~49~30~26 minecraft:polished_blackstone_bricks
fill ~48~31~24 ~48~32~26 minecraft:polished_blackstone_bricks
setblock ~48~33~24 minecraft:polished_blackstone_brick_stairs 2
setblock ~49~0~24 minecraft:water 7
setblock ~49~9~24 minecraft:smooth_quartz_stairs 4
fill ~49~11~24 ~49~13~33 minecraft:quartz_bricks
setblock ~49~23~24 minecraft:smooth_quartz_stairs 7
fill ~49~28~24 ~49~29~26 minecraft:polished_blackstone_bricks
setblock ~49~31~24 minecraft:polished_blackstone_brick_wall 0
fill ~50~2~24 ~50~2~25 minecraft:spruce_stairs 4
fill ~50~3~24 ~50~6~25 minecraft:chest 4
fill ~50~7~24 ~50~7~25 minecraft:spruce_stairs 0
fill ~50~8~24 ~50~8~26 minecraft:smooth_quartz_stairs 0
setblock ~50~9~24 minecraft:smooth_quartz_stairs 7
fill ~50~13~24 ~51~13~26 minecraft:quartz_bricks
fill ~50~23~24 ~50~23~25 minecraft:smooth_quartz_stairs 4
fill ~50~24~24 ~50~24~26 minecraft:quartz_bricks
fill ~50~25~24 ~50~27~26 minecraft:polished_blackstone_bricks
setblock ~50~28~24 minecraft:polished_blackstone_brick_stairs 2
fill ~51~2~24 ~51~6~26 minecraft:quartz_bricks
fill ~51~9~24 ~51~12~26 minecraft:quartz_bricks
fill ~51~14~24 ~51~15~26 minecraft:quartz_bricks
fill ~51~16~24 ~51~22~24 minecraft:quartz_bricks
fill ~51~23~24 ~51~23~27 minecraft:polished_blackstone_bricks
fill ~51~24~24 ~51~24~26 minecraft:polished_blackstone_bricks
setblock ~51~25~24 minecraft:polished_blackstone_brick_stairs 2
fill ~52~7~24 ~52~7~30 minecraft:quartz_bricks
fill ~52~9~24 ~52~9~30 minecraft:polished_blackstone_bricks
fill ~52~10~24 ~52~10~29 minecraft:polished_blackstone_brick_stairs 1
setblock ~52~20~24 minecraft:soul_lantern 0
setblock ~52~21~24 minecraft:nether_brick_fence
setblock ~52~22~24 minecraft:polished_blackstone_brick_wall 0
fill ~53~6~24 ~54~6~24 minecraft:grass
setblock ~53~7~24 minecraft:red_flower 2
setblock ~54~7~24 minecraft:red_flower 3
setblock ~55~7~24 minecraft:red_flower 10
setblock ~57~6~24 minecraft:red_flower 2
fill ~59~6~24 ~59~6~25 minecraft:red_flower 9
fill ~60~4~24 ~60~4~29 minecraft:dirt 0
fill ~60~5~24 ~60~5~29 minecraft:grass
setblock ~60~6~24 minecraft:red_flower 3
fill ~61~4~24 ~61~4~25 minecraft:grass
setblock ~61~5~24 minecraft:tallgrass 0
setblock ~63~4~24 minecraft:tallgrass 0
setblock ~64~4~24 minecraft:red_flower 2
setblock ~65~4~24 minecraft:red_flower 10
setblock ~66~4~24 minecraft:red_flower 1
setblock ~67~4~24 minecraft:tallgrass 0
setblock ~69~4~24 minecraft:red_flower 2
fill ~70~4~24 ~70~4~25 minecraft:red_flower 10
fill ~71~3~24 ~71~3~25 minecraft:tallgrass 0
setblock ~73~1~24 minecraft:red_flower 1
setblock ~75~0~24 minecraft:tallgrass 0
setblock ~76~0~24 minecraft:red_flower 1
fill ~3~1~25 ~3~1~26 minecraft:dirt 0
fill ~3~2~25 ~3~2~26 minecraft:grass
setblock ~6~3~25 minecraft:tallgrass 0
setblock ~7~3~25 minecraft:yellow_flower
setblock ~8~3~25 minecraft:red_flower 9
fill ~9~2~25 ~9~2~29 minecraft:grass
fill ~9~3~25 ~9~3~29 minecraft:tallgrass 0
fill ~10~3~25 ~12~3~25 minecraft:grass
setblock ~10~4~25 minecraft:red_flower 3
fill ~11~4~25 ~12~4~25 minecraft:tallgrass 0
fill ~13~3~25 ~19~3~25 minecraft:dirt 0
setblock ~13~5~25 minecraft:red_flower 9
setblock ~15~6~25 minecraft:yellow_flower
setblock ~16~5~25 minecraft:grass
setblock ~16~6~25 minecraft:tallgrass 0
setblock ~17~5~25 minecraft:dirt 0
fill ~17~7~25 ~18~7~25 minecraft:tallgrass 0
fill ~18~6~25 ~18~6~26 minecraft:grass
fill ~19~6~25 ~23~6~25 minecraft:dirt 0
setblock ~22~9~25 minecraft:tallgrass 0
fill ~24~8~25 ~24~8~28 minecraft:grass
setblock ~24~9~25 minecraft:yellow_flower
setblock ~25~8~25 minecraft:dirt 0
setblock ~25~9~25 minecraft:grass
setblock ~25~10~25 minecraft:tallgrass 0
setblock ~26~1~25 minecraft:coal_ore
fill ~26~2~25 ~26~2~29 minecraft:dirt 0
setblock ~26~9~25 minecraft:tallgrass 0
fill ~27~0~25 ~28~0~28 minecraft:dirt 0
fill ~27~1~25 ~27~1~28 minecraft:dirt 0
fill ~28~8~25 ~28~8~30 minecraft:quartz_bricks
setblock ~29~16~25 minecraft:smooth_quartz_stairs 4
fill ~29~17~25 ~29~21~25 minecraft:stained_glass_pane 3
fill ~29~22~25 ~29~22~26 minecraft:quartz_bricks
setblock ~29~25~25 minecraft:polished_blackstone_bricks
setblock ~29~26~25 minecraft:polished_blackstone_brick_stairs 0
setblock ~30~0~25 minecraft:water 7
fill ~30~9~25 ~30~9~26 minecraft:smooth_quartz_stairs 5
fill ~30~16~25 ~30~16~27 minecraft:quartz_bricks
fill ~30~23~25 ~30~23~26 minecraft:smooth_quartz_stairs 5
fill ~30~28~25 ~30~29~25 minecraft:polished_blackstone_bricks
setblock ~30~30~25 minecraft:polished_blackstone_brick_stairs 0
setblock ~31~0~25 minecraft:water 6
fill ~31~2~25 ~31~2~27 minecraft:carpet 7
setblock ~31~22~25 minecraft:soul_lantern 0
setblock ~31~23~25 minecraft:nether_brick_fence
fill ~31~31~25 ~31~32~25 minecraft:polished_blackstone_bricks
setblock ~31~33~25 minecraft:polished_blackstone_brick_stairs 0
setblock ~32~0~25 minecraft:water 5
fill ~32~2~25 ~32~2~28 minecraft:carpet 14
setblock ~32~21~25 minecraft:soul_lantern 0
setblock ~32~22~25 minecraft:nether_brick_fence
fill ~32~33~25 ~32~34~25 minecraft:polished_blackstone_bricks
fill ~32~35~25 ~32~37~25 minecraft:polished_blackstone_brick_wall 0
fill ~32~38~25 ~32~41~25 minecraft:nether_brick_fence
fill ~33~0~25 ~34~0~25 minecraft:water 4
fill ~33~2~25 ~47~2~25 minecraft:carpet 7
setblock ~33~22~25 minecraft:soul_lantern 0
setblock ~33~23~25 minecraft:nether_brick_fence
fill ~33~31~25 ~33~32~25 minecraft:polished_blackstone_bricks
setblock ~33~33~25 minecraft:polished_blackstone_brick_stairs 1
setblock ~34~8~25 minecraft:soul_lantern 0
fill ~34~9~25 ~34~9~27 minecraft:nether_brick_fence
fill ~34~28~25 ~34~29~25 minecraft:polished_blackstone_bricks
setblock ~34~30~25 minecraft:polished_blackstone_brick_stairs 1
fill ~34~31~25 ~39~31~60 minecraft:quartz_bricks
fill ~34~32~25 ~34~32~27 minecraft:polished_blackstone_brick_stairs 0
setblock ~35~0~25 minecraft:water 5
fill ~35~24~25 ~45~24~30 minecraft:quartz_bricks
fill ~35~25~25 ~37~25~25 minecraft:quartz_bricks
fill ~35~26~25 ~36~30~25 minecraft:quartz_bricks
fill ~35~32~25 ~36~32~34 minecraft:quartz_bricks
fill ~35~33~25 ~35~33~29 minecraft:polished_blackstone_bricks
fill ~35~34~25 ~35~34~29 minecraft:polished_blackstone_brick_stairs 0
fill ~36~0~25 ~37~0~25 minecraft:water 4
fill ~36~16~25 ~36~22~25 minecraft:quartz_bricks
fill ~36~23~25 ~44~23~25 minecraft:polished_blackstone_bricks
fill ~36~33~25 ~37~34~25 minecraft:quartz_bricks
fill ~36~35~25 ~36~36~28 minecraft:polished_blackstone_bricks
fill ~36~37~25 ~36~37~28 minecraft:polished_blackstone_brick_stairs 0
fill ~37~15~25 ~38~15~25 minecraft:quartz_bricks
fill ~37~16~25 ~37~21~25 minecraft:stained_glass_pane 3
fill ~37~22~25 ~44~22~25 minecraft:quartz_bricks
fill ~37~26~25 ~37~29~25 minecraft:stained_glass_pane 3
setblock ~37~30~25 minecraft:quartz_bricks
fill ~37~35~25 ~37~37~25 minecraft:quartz_bricks
fill ~37~38~25 ~37~39~28 minecraft:polished_blackstone_bricks
fill ~37~40~25 ~37~40~27 minecraft:polished_blackstone_brick_stairs 0
setblock ~38~0~25 minecraft:water 5
fill ~38~16~25 ~38~21~25 minecraft:quartz_bricks
fill ~38~25~25 ~38~30~25 minecraft:stained_glass 3
setblock ~38~34~25 minecraft:stained_glass_pane 3
fill ~38~36~25 ~40~36~25 minecraft:stained_glass_pane 3
fill ~38~37~25 ~38~40~25 minecraft:quartz_bricks
fill ~38~41~25 ~38~42~27 minecraft:polished_blackstone_bricks
fill ~38~43~25 ~38~43~27 minecraft:polished_blackstone_brick_stairs 0
setblock ~39~0~25 minecraft:water 6
fill ~39~16~25 ~39~17~25 minecraft:stained_glass_pane 3
fill ~39~19~25 ~41~19~25 minecraft:stained_glass_pane 3
fill ~39~20~25 ~39~21~25 minecraft:quartz_bricks
fill ~39~25~25 ~41~25~25 minecraft:quartz_bricks
fill ~39~26~25 ~39~29~25 minecraft:stained_glass_pane 3
fill ~39~30~25 ~41~30~25 minecraft:quartz_bricks
setblock ~39~37~25 minecraft:stained_glass_pane 3
fill ~39~38~25 ~42~40~25 minecraft:quartz_bricks
fill ~39~41~25 ~39~43~28 minecraft:quartz_bricks
fill ~39~44~25 ~39~45~27 minecraft:polished_blackstone_bricks
fill ~39~46~25 ~39~46~27 minecraft:polished_blackstone_brick_stairs 0
setblock ~40~0~25 minecraft:water 7
setblock ~40~8~25 minecraft:soul_lantern 0
fill ~40~9~25 ~40~9~27 minecraft:nether_brick_fence
setblock ~40~20~25 minecraft:stained_glass_pane 3
fill ~40~21~25 ~42~21~25 minecraft:quartz_bricks
fill ~40~26~25 ~40~29~25 minecraft:quartz_bricks
setblock ~40~34~25 minecraft:stained_glass_pane 3
fill ~40~37~25 ~41~37~25 minecraft:quartz_bricks
fill ~40~41~25 ~40~43~25 minecraft:stained_glass_pane 3
fill ~40~44~25 ~40~46~27 minecraft:quartz_bricks
fill ~40~47~25 ~40~48~27 minecraft:polished_blackstone_bricks
setblock ~40~49~25 minecraft:polished_blackstone_brick_wall 0
setblock ~41~0~25 minecraft:water 6
fill ~41~16~25 ~41~17~25 minecraft:stained_glass_pane 3
fill ~41~20~25 ~42~20~25 minecraft:quartz_bricks
fill ~41~26~25 ~41~29~25 minecraft:stained_glass_pane 3
fill ~41~31~25 ~46~31~60 minecraft:quartz_bricks
fill ~41~33~25 ~44~33~25 minecraft:quartz_bricks
fill ~41~34~25 ~41~36~25 minecraft:quartz_bricks
fill ~41~41~25 ~41~43~28 minecraft:quartz_bricks
fill ~41~44~25 ~41~45~27 minecraft:polished_blackstone_bricks
fill ~41~46~25 ~41~46~27 minecraft:polished_blackstone_brick_stairs 1
setblock ~42~0~25 minecraft:water 5
fill ~42~15~25 ~43~15~25 minecraft:quartz_bricks
fill ~42~16~25 ~42~19~25 minecraft:quartz_bricks
fill ~42~25~25 ~42~30~25 minecraft:stained_glass 3
fill ~42~34~25 ~42~37~25 minecraft:stained_glass_pane 3
fill ~42~41~25 ~42~42~27 minecraft:polished_blackstone_bricks
fill ~42~43~25 ~42~43~27 minecraft:polished_blackstone_brick_stairs 1
setblock ~43~0~25 minecraft:water 4
fill ~43~16~25 ~43~21~25 minecraft:stained_glass_pane 3
fill ~43~25~25 ~45~25~25 minecraft:quartz_bricks
fill ~43~26~25 ~43~29~25 minecraft:stained_glass_pane 3
fill ~43~30~25 ~45~30~25 minecraft:quartz_bricks
fill ~43~34~25 ~44~34~25 minecraft:quartz_bricks
fill ~43~35~25 ~43~37~25 minecraft:quartz_bricks
fill ~43~38~25 ~43~39~28 minecraft:polished_blackstone_bricks
fill ~43~40~25 ~43~40~27 minecraft:polished_blackstone_brick_stairs 1
fill ~44~0~25 ~45~0~25 minecraft:water 5
fill ~44~16~25 ~44~21~25 minecraft:quartz_bricks
fill ~44~26~25 ~45~29~25 minecraft:quartz_bricks
fill ~44~32~25 ~45~32~34 minecraft:quartz_bricks
fill ~44~35~25 ~44~36~28 minecraft:polished_blackstone_bricks
fill ~44~37~25 ~44~37~28 minecraft:polished_blackstone_brick_stairs 1
fill ~45~33~25 ~45~33~28 minecraft:polished_blackstone_bricks
fill ~45~34~25 ~45~34~27 minecraft:polished_blackstone_brick_stairs 1
fill ~46~0~25 ~47~0~25 minecraft:water 4
fill ~46~23~25 ~46~23~26 minecraft:smooth_quartz_stairs 5
fill ~46~28~25 ~46~29~25 minecraft:polished_blackstone_bricks
setblock ~46~30~25 minecraft:polished_blackstone_brick_stairs 0
fill ~46~32~25 ~46~32~27 minecraft:polished_blackstone_brick_stairs 1
setblock ~47~8~25 minecraft:soul_lantern 0
fill ~47~9~25 ~47~9~27 minecraft:nether_brick_fence
setblock ~47~22~25 minecraft:soul_lantern 0
setblock ~47~23~25 minecraft:nether_brick_fence
fill ~47~31~25 ~47~31~26 minecraft:polished_blackstone_bricks
setblock ~47~32~25 minecraft:polished_blackstone_bricks
setblock ~47~33~25 minecraft:polished_blackstone_brick_stairs 0
setblock ~48~0~25 minecraft:water 5
fill ~48~2~25 ~48~2~28 minecraft:carpet 14
setblock ~48~21~25 minecraft:soul_lantern 0
setblock ~48~22~25 minecraft:nether_brick_fence
fill ~48~33~25 ~48~34~25 minecraft:polished_blackstone_bricks
fill ~48~35~25 ~48~37~25 minecraft:polished_blackstone_brick_wall 0
fill ~48~38~25 ~48~41~25 minecraft:nether_brick_fence
setblock ~49~0~25 minecraft:water 6
fill ~49~2~25 ~49~2~27 minecraft:carpet 7
setblock ~49~22~25 minecraft:soul_lantern 0
setblock ~49~23~25 minecraft:nether_brick_fence
fill ~49~31~25 ~49~32~25 minecraft:polished_blackstone_bricks
setblock ~49~33~25 minecraft:polished_blackstone_brick_stairs 1
setblock ~50~0~25 minecraft:water 7
fill ~50~9~25 ~50~9~26 minecraft:smooth_quartz_stairs 4
fill ~50~28~25 ~50~29~25 minecraft:polished_blackstone_bricks
setblock ~50~30~25 minecraft:polished_blackstone_brick_stairs 1
fill ~51~1~25 ~51~1~68 minecraft:quartz_bricks
setblock ~51~16~25 minecraft:smooth_quartz_stairs 5
fill ~51~17~25 ~51~21~25 minecraft:stained_glass_pane 3
fill ~51~22~25 ~51~22~26 minecraft:quartz_bricks
setblock ~51~25~25 minecraft:polished_blackstone_bricks
setblock ~51~26~25 minecraft:polished_blackstone_brick_stairs 1
fill ~52~0~25 ~53~0~26 minecraft:coal_ore
fill ~52~6~25 ~52~6~30 minecraft:quartz_bricks
fill ~53~5~25 ~55~5~29 minecraft:grass
fill ~53~6~25 ~53~6~26 minecraft:tallgrass 0
fill ~54~0~25 ~56~0~29 minecraft:dirt 0
setblock ~54~6~25 minecraft:red_flower 10
fill ~55~6~25 ~56~6~26 minecraft:tallgrass 0
fill ~57~6~25 ~58~6~25 minecraft:red_flower 9
setblock ~60~6~25 minecraft:red_flower 2
setblock ~62~5~25 minecraft:red_flower 10
setblock ~63~4~25 minecraft:red_flower 3
setblock ~65~4~25 minecraft:red_flower 2
setblock ~66~4~25 minecraft:yellow_flower
setblock ~67~4~25 minecraft:red_flower 2
setblock ~68~4~25 minecraft:red_flower 1
setblock ~69~4~25 minecraft:tallgrass 0
setblock ~72~2~25 minecraft:tallgrass 0
setblock ~73~1~25 minecraft:red_flower 2
setblock ~74~1~25 minecraft:red_flower 9
setblock ~75~0~25 minecraft:red_flower 2
fill ~1~0~26 ~1~0~30 minecraft:grass
setblock ~5~3~26 minecraft:red_flower 10
fill ~7~3~26 ~7~3~27 minecraft:tallgrass 0
setblock ~8~3~26 minecraft:red_flower 10
fill ~10~2~26 ~10~2~28 minecraft:grass
fill ~10~3~26 ~10~3~27 minecraft:tallgrass 0
setblock ~11~2~26 minecraft:dirt 0
fill ~11~3~26 ~14~3~26 minecraft:grass
setblock ~12~4~26 minecraft:red_flower 10
fill ~13~4~26 ~14~4~26 minecraft:red_flower 9
fill ~15~3~26 ~19~3~27 minecraft:dirt 0
fill ~15~4~26 ~16~4~27 minecraft:grass
setblock ~15~5~26 minecraft:red_flower 1
setblock ~16~5~26 minecraft:tallgrass 0
fill ~17~0~26 ~23~0~29 minecraft:dirt 0
fill ~17~4~26 ~24~4~27 minecraft:dirt 0
fill ~17~5~26 ~17~5~27 minecraft:grass
setblock ~17~6~26 minecraft:tallgrass 0
fill ~19~6~26 ~19~6~28 minecraft:grass
setblock ~19~7~26 minecraft:red_flower 9
fill ~20~6~26 ~23~6~28 minecraft:dirt 0
setblock ~20~8~26 minecraft:red_flower 0
fill ~21~7~26 ~21~7~28 minecraft:grass
setblock ~21~8~26 minecraft:yellow_flower
fill ~22~7~26 ~24~7~26 minecraft:dirt 0
fill ~23~9~26 ~23~9~27 minecraft:yellow_flower
fill ~24~0~26 ~25~0~26 minecraft:coal_ore
setblock ~24~9~26 minecraft:red_flower 0
fill ~25~1~26 ~26~1~29 minecraft:dirt 0
fill ~25~8~26 ~25~8~28 minecraft:grass
setblock ~25~9~26 minecraft:tallgrass 0
fill ~26~0~26 ~26~0~29 minecraft:dirt 0
setblock ~26~9~26 minecraft:red_flower 10
setblock ~27~9~26 minecraft:red_flower 2
setblock ~28~20~26 minecraft:soul_lantern 0
setblock ~28~21~26 minecraft:nether_brick_fence
setblock ~28~22~26 minecraft:polished_blackstone_brick_wall 0
setblock ~29~0~26 minecraft:water 7
fill ~29~16~26 ~29~21~26 minecraft:quartz_bricks
setblock ~29~25~26 minecraft:polished_blackstone_brick_stairs 3
setblock ~30~0~26 minecraft:water 6
fill ~30~2~26 ~30~7~26 minecraft:stripped_spruce_log 0
setblock ~30~11~26 minecraft:soul_lantern 0
setblock ~30~28~26 minecraft:polished_blackstone_brick_stairs 3
setblock ~31~0~26 minecraft:water 5
setblock ~31~5~26 minecraft:soul_lantern 0
setblock ~31~6~26 minecraft:fence 0
setblock ~31~7~26 minecraft:dark_oak_trapdoor 0
setblock ~31~23~26 minecraft:smooth_quartz_stairs 6
setblock ~31~31~26 minecraft:polished_blackstone_brick_wall 0
setblock ~32~0~26 minecraft:water 4
setblock ~32~22~26 minecraft:soul_lantern 0
setblock ~32~33~26 minecraft:polished_blackstone_brick_stairs 3
fill ~33~0~26 ~34~0~26 minecraft:water 3
fill ~33~2~26 ~47~2~26 minecraft:carpet 14
setblock ~33~8~26 minecraft:soul_lantern 0
setblock ~33~9~26 minecraft:nether_brick_fence
fill ~33~23~26 ~34~23~26 minecraft:smooth_quartz_stairs 6
setblock ~33~31~26 minecraft:smooth_quartz_stairs 0
setblock ~34~7~26 minecraft:soul_lantern 0
setblock ~34~8~26 minecraft:nether_brick_fence
fill ~34~25~26 ~34~30~27 minecraft:quartz_bricks
setblock ~35~0~26 minecraft:water 4
setblock ~35~8~26 minecraft:soul_lantern 0
setblock ~35~9~26 minecraft:nether_brick_fence
fill ~35~23~26 ~45~23~60 minecraft:quartz_bricks
fill ~35~30~26 ~36~30~26 minecraft:smooth_quartz_stairs 7
fill ~36~0~26 ~37~0~26 minecraft:water 3
fill ~36~16~26 ~36~16~27 minecraft:stone_block_slab4 1
fill ~36~17~26 ~36~17~27 minecraft:soul_lantern 0
setblock ~36~21~26 minecraft:smooth_quartz_stairs 7
fill ~36~22~26 ~37~22~28 minecraft:quartz_bricks
fill ~36~33~26 ~36~34~30 minecraft:quartz_bricks
fill ~37~15~26 ~37~15~27 minecraft:smooth_quartz_stairs 1
fill ~37~21~26 ~37~21~27 minecraft:stone_block_slab 14
setblock ~37~30~26 minecraft:smooth_quartz_stairs 5
fill ~37~35~26 ~37~35~29 minecraft:smooth_quartz_stairs 5
fill ~37~36~26 ~37~37~31 minecraft:quartz_bricks
setblock ~38~0~26 minecraft:water 4
fill ~38~22~26 ~38~22~32 minecraft:smooth_quartz_stairs 5
fill ~38~38~26 ~38~38~32 minecraft:smooth_quartz_stairs 5
fill ~38~39~26 ~42~39~73 minecraft:quartz_bricks
fill ~38~40~26 ~42~40~33 minecraft:quartz_bricks
setblock ~39~0~26 minecraft:water 5
setblock ~39~8~26 minecraft:soul_lantern 0
setblock ~39~9~26 minecraft:nether_brick_fence
fill ~39~22~26 ~41~22~26 minecraft:smooth_quartz_stairs 7
setblock ~39~30~26 minecraft:smooth_quartz_stairs 4
fill ~39~38~26 ~41~38~26 minecraft:smooth_quartz_stairs 7
setblock ~40~0~26 minecraft:water 6
setblock ~40~7~26 minecraft:soul_lantern 0
setblock ~40~8~26 minecraft:nether_brick_fence
setblock ~40~29~26 minecraft:smooth_quartz_stairs 7
setblock ~40~30~26 minecraft:smooth_quartz_stairs 3
setblock ~40~49~26 minecraft:polished_blackstone_double_slab 0
setblock ~40~50~26 minecraft:polished_blackstone_brick_wall 0
fill ~40~51~26 ~40~52~26 minecraft:nether_brick_fence
setblock ~41~0~26 minecraft:water 5
setblock ~41~8~26 minecraft:soul_lantern 0
setblock ~41~9~26 minecraft:nether_brick_fence
setblock ~41~30~26 minecraft:smooth_quartz_stairs 5
setblock ~42~0~26 minecraft:water 4
fill ~42~22~26 ~42~22~31 minecraft:smooth_quartz_stairs 4
fill ~42~38~26 ~42~38~30 minecraft:smooth_quartz_stairs 4
setblock ~43~0~26 minecraft:water 3
fill ~43~15~26 ~43~15~27 minecraft:smooth_quartz_stairs 0
fill ~43~21~26 ~43~21~27 minecraft:stone_block_slab 14
fill ~43~22~26 ~44~22~28 minecraft:quartz_bricks
setblock ~43~30~26 minecraft:smooth_quartz_stairs 4
fill ~43~35~26 ~43~35~29 minecraft:smooth_quartz_stairs 4
fill ~43~36~26 ~43~37~30 minecraft:quartz_bricks
fill ~44~0~26 ~45~0~26 minecraft:water 4
fill ~44~16~26 ~44~16~27 minecraft:stone_block_slab4 1
fill ~44~17~26 ~44~17~27 minecraft:soul_lantern 0
setblock ~44~21~26 minecraft:smooth_quartz_stairs 7
setblock ~44~30~26 minecraft:smooth_quartz_stairs 7
fill ~44~33~26 ~44~34~30 minecraft:quartz_bricks
fill ~45~30~26 ~45~30~28 minecraft:smooth_quartz_stairs 4
fill ~46~0~26 ~47~0~26 minecraft:water 3
setblock ~46~8~26 minecraft:soul_lantern 0
setblock ~46~9~26 minecraft:nether_brick_fence
fill ~46~25~26 ~46~30~27 minecraft:quartz_bricks
setblock ~47~7~26 minecraft:soul_lantern 0
setblock ~47~8~26 minecraft:nether_brick_fence
setblock ~47~23~26 minecraft:smooth_quartz_stairs 6
setblock ~48~0~26 minecraft:water 4
setblock ~48~8~26 minecraft:soul_lantern 0
setblock ~48~9~26 minecraft:nether_brick_fence
setblock ~48~22~26 minecraft:soul_lantern 0
setblock ~48~33~26 minecraft:polished_blackstone_brick_stairs 3
setblock ~49~0~26 minecraft:water 5
setblock ~49~5~26 minecraft:soul_lantern 0
setblock ~49~6~26 minecraft:fence 0
setblock ~49~7~26 minecraft:dark_oak_trapdoor 1
setblock ~49~23~26 minecraft:smooth_quartz_stairs 4
fill ~49~31~26 ~49~31~33 minecraft:smooth_quartz_stairs 1
setblock ~50~0~26 minecraft:water 6
fill ~50~2~26 ~50~7~26 minecraft:stripped_spruce_log 0
setblock ~50~11~26 minecraft:soul_lantern 0
setblock ~50~23~26 minecraft:smooth_quartz_stairs 6
setblock ~50~28~26 minecraft:polished_blackstone_brick_stairs 3
fill ~51~0~26 ~51~0~27 minecraft:coal_ore
fill ~51~16~26 ~51~21~26 minecraft:quartz_bricks
setblock ~51~25~26 minecraft:polished_blackstone_brick_stairs 3
setblock ~52~1~26 minecraft:grass
setblock ~52~20~26 minecraft:soul_lantern 0
setblock ~52~21~26 minecraft:nether_brick_fence
setblock ~52~22~26 minecraft:polished_blackstone_brick_wall 0
fill ~53~1~26 ~68~1~26 minecraft:dirt 0
fill ~53~2~26 ~65~2~26 minecraft:dirt 0
setblock ~54~6~26 minecraft:tallgrass 0
fill ~57~6~26 ~58~6~27 minecraft:tallgrass 0
setblock ~59~6~26 minecraft:red_flower 10
setblock ~60~6~26 minecraft:red_flower 3
fill ~61~4~26 ~61~4~29 minecraft:dirt 0
fill ~61~5~26 ~61~5~29 minecraft:grass
fill ~61~6~26 ~61~6~27 minecraft:tallgrass 0
fill ~63~3~26 ~63~3~29 minecraft:dirt 0
fill ~63~4~26 ~63~4~29 minecraft:grass
fill ~64~4~26 ~65~4~26 minecraft:tallgrass 0
fill ~66~2~26 ~70~2~26 minecraft:grass
setblock ~66~3~26 minecraft:red_flower 3
setblock ~67~3~26 minecraft:tallgrass 0
setblock ~68~3~26 minecraft:red_flower 0
setblock ~69~3~26 minecraft:red_flower 2
fill ~70~3~26 ~71~3~26 minecraft:yellow_flower
setblock ~73~1~26 minecraft:red_flower 0
setblock ~74~0~26 minecraft:tallgrass 0
setblock ~75~0~26 minecraft:red_flower 9
setblock ~3~1~27 minecraft:grass
setblock ~5~3~27 minecraft:red_flower 2
fill ~6~3~27 ~6~3~30 minecraft:tallgrass 0
fill ~8~3~27 ~8~3~29 minecraft:tallgrass 0
fill ~11~2~27 ~12~2~28 minecraft:grass
setblock ~11~3~27 minecraft:red_flower 3
fill ~12~3~27 ~12~3~28 minecraft:tallgrass 0
fill ~13~2~27 ~23~2~28 minecraft:dirt 0
fill ~13~3~27 ~14~3~28 minecraft:grass
fill ~13~4~27 ~14~4~27 minecraft:tallgrass 0
setblock ~15~5~27 minecraft:yellow_flower
fill ~17~6~27 ~18~6~27 minecraft:red_flower 3
fill ~18~5~27 ~18~5~28 minecraft:grass
fill ~19~5~27 ~23~5~28 minecraft:dirt 0
fill ~20~8~27 ~21~8~28 minecraft:tallgrass 0
fill ~22~7~27 ~22~7~28 minecraft:grass
setblock ~22~8~27 minecraft:red_flower 1
fill ~23~7~27 ~24~7~27 minecraft:dirt 0
fill ~24~0~27 ~25~0~29 minecraft:dirt 0
fill ~24~9~27 ~24~9~28 minecraft:tallgrass 0
setblock ~25~9~27 minecraft:red_flower 3
fill ~26~6~27 ~27~6~28 minecraft:dirt 0
setblock ~26~9~27 minecraft:tallgrass 0
fill ~27~2~27 ~27~3~28 minecraft:dirt 0
fill ~27~5~27 ~27~5~28 minecraft:dirt 0
fill ~27~8~27 ~27~8~28 minecraft:smooth_quartz_stairs 0
fill ~28~1~27 ~28~1~70 minecraft:quartz_bricks
fill ~28~2~27 ~28~2~42 minecraft:quartz_bricks
fill ~28~3~27 ~28~7~30 minecraft:quartz_bricks
setblock ~29~0~27 minecraft:water 6
fill ~29~2~27 ~29~2~29 minecraft:spruce_stairs 5
fill ~29~3~27 ~29~3~29 minecraft:blast_furnace 5
fill ~29~4~27 ~29~7~27 minecraft:blast_furnace 5
fill ~29~8~27 ~29~8~29 minecraft:smooth_quartz_stairs 1
fill ~29~9~27 ~29~9~29 minecraft:smooth_quartz_stairs 5
fill ~29~10~27 ~29~10~76 minecraft:quartz_bricks
fill ~29~11~27 ~29~11~31 minecraft:polished_blackstone_bricks
fill ~29~12~27 ~29~12~31 minecraft:polished_blackstone_brick_stairs 0
setblock ~29~20~27 minecraft:nether_brick_fence
fill ~29~21~27 ~29~22~27 minecraft:polished_blackstone_brick_wall 0
setblock ~29~24~27 minecraft:polished_blackstone_brick_wall 0
setblock ~29~25~27 minecraft:nether_brick_fence
setblock ~30~0~27 minecraft:water 5
fill ~30~2~27 ~30~2~29 minecraft:carpet 7
setblock ~30~9~27 minecraft:smooth_quartz_stairs 7
fill ~30~17~27 ~30~22~27 minecraft:quartz_bricks
fill ~30~23~27 ~30~23~28 minecraft:polished_blackstone_bricks
setblock ~30~24~27 minecraft:polished_blackstone_bricks
fill ~30~25~27 ~30~26~27 minecraft:polished_blackstone_brick_wall 0
setblock ~30~27~27 minecraft:nether_brick_fence
fill ~30~31~27 ~33~31~27 minecraft:smooth_quartz_stairs 2
setblock ~31~0~27 minecraft:water 4
setblock ~31~23~27 minecraft:smooth_quartz_stairs 5
fill ~31~25~27 ~32~27~27 minecraft:polished_blackstone_bricks
setblock ~31~28~27 minecraft:polished_blackstone_brick_stairs 0
setblock ~32~0~27 minecraft:water 3
setblock ~32~23~27 minecraft:smooth_quartz_stairs 6
setblock ~32~30~27 minecraft:polished_blackstone_brick_stairs 3
fill ~33~0~27 ~34~0~27 minecraft:water 2
fill ~33~2~27 ~39~2~27 minecraft:carpet 7
setblock ~33~23~27 minecraft:smooth_quartz_stairs 4
fill ~33~25~27 ~33~30~27 minecraft:quartz_bricks
setblock ~34~8~27 minecraft:soul_lantern 0
setblock ~34~22~27 minecraft:stone_block_slab4 1
fill ~34~23~27 ~34~23~60 minecraft:quartz_bricks
setblock ~35~0~27 minecraft:water 3
setblock ~35~30~27 minecraft:smooth_quartz_stairs 5
fill ~36~0~27 ~37~0~27 minecraft:water 2
setblock ~36~21~27 minecraft:smooth_quartz_stairs 6
fill ~36~56~27 ~36~56~28 minecraft:smooth_quartz_stairs 0
fill ~37~48~27 ~38~48~27 minecraft:polished_blackstone_slab 0
setblock ~37~56~27 minecraft:smooth_quartz_stairs 5
setblock ~37~57~27 minecraft:quartz_bricks
setblock ~37~58~27 minecraft:smooth_quartz_stairs 0
setblock ~38~0~27 minecraft:water 3
setblock ~38~58~27 minecraft:smooth_quartz_stairs 5
setblock ~38~59~27 minecraft:quartz_bricks
setblock ~38~60~27 minecraft:smooth_quartz_stairs 0
setblock ~39~0~27 minecraft:water 4
setblock ~39~48~27 minecraft:polished_blackstone_brick_stairs 0
setblock ~39~60~27 minecraft:smooth_quartz_stairs 5
fill ~39~61~27 ~39~62~27 minecraft:quartz_bricks
setblock ~39~63~27 minecraft:smooth_quartz_stairs 0
setblock ~40~0~27 minecraft:water 5
