setblock ~16 ~1 ~44 chest 4  
setblock ~17 ~3 ~42 furnace 2  
setblock ~17 ~2 ~42 furnace 2  
fill ~-5 ~-1 ~-5 ~20 ~-1 ~-5 grass 0  
fill ~-5 ~-1 ~-4 ~20 ~-1 ~-4 grass 0  
fill ~-5 ~-1 ~-3 ~20 ~-1 ~-3 grass 0  
fill ~-5 ~-1 ~-2 ~20 ~-1 ~-2 grass 0  
fill ~-5 ~-1 ~-1 ~20 ~-1 ~-1 grass 0  
fill ~-5 ~-1 ~0 ~20 ~-1 ~0 grass 0  
fill ~-5 ~-1 ~1 ~6 ~-1 ~1 grass 0  
fill ~-5 ~-1 ~2 ~6 ~-1 ~2 grass 0  
fill ~-5 ~-1 ~3 ~6 ~-1 ~3 grass 0  
fill ~-5 ~-1 ~4 ~6 ~-1 ~4 grass 0  
fill ~-5 ~-1 ~5 ~6 ~-1 ~5 grass 0  
fill ~-5 ~-1 ~6 ~5 ~-1 ~6 grass 0  
fill ~-5 ~-1 ~7 ~5 ~-1 ~7 grass 0  
fill ~-5 ~-1 ~8 ~5 ~-1 ~8 grass 0  
fill ~-5 ~-1 ~9 ~5 ~-1 ~9 grass 0  
fill ~-5 ~-1 ~10 ~-1 ~-1 ~10 grass 0  
fill ~-5 ~-1 ~11 ~-1 ~-1 ~11 grass 0  
fill ~-5 ~-1 ~12 ~-1 ~-1 ~12 grass 0  
fill ~-5 ~-1 ~13 ~-1 ~-1 ~13 grass 0  
fill ~-5 ~-1 ~14 ~-1 ~-1 ~14 grass 0  
fill ~-5 ~-1 ~15 ~-1 ~-1 ~15 grass 0  
fill ~-5 ~-1 ~16 ~-1 ~-1 ~16 grass 0  
fill ~-5 ~-1 ~17 ~-1 ~-1 ~17 grass 0  
fill ~-5 ~-1 ~18 ~-1 ~-1 ~18 grass 0  
fill ~-5 ~-1 ~19 ~5 ~-1 ~19 grass 0  
fill ~-5 ~-1 ~20 ~5 ~-1 ~20 grass 0  
fill ~-5 ~-1 ~21 ~5 ~-1 ~21 grass 0  
fill ~-5 ~-1 ~22 ~5 ~-1 ~22 dirt 0  
fill ~-5 ~-1 ~23 ~5 ~-1 ~23 dirt 0  
fill ~-5 ~-1 ~24 ~5 ~-1 ~24 dirt 0  
fill ~-5 ~-1 ~25 ~5 ~-1 ~25 dirt 0  
fill ~-5 ~-1 ~26 ~5 ~-1 ~26 dirt 0  
fill ~-5 ~-1 ~27 ~5 ~-1 ~27 dirt 0  
fill ~-5 ~-1 ~28 ~5 ~-1 ~28 dirt 0  
fill ~-5 ~-1 ~29 ~-1 ~-1 ~29 grass 0  
fill ~-5 ~-1 ~30 ~-1 ~-1 ~30 grass 0  
fill ~-5 ~-1 ~31 ~5 ~-1 ~31 grass 0  
fill ~-5 ~-1 ~32 ~5 ~-1 ~32 grass 0  
fill ~-5 ~-1 ~33 ~5 ~-1 ~33 grass 0  
fill ~-5 ~-1 ~34 ~5 ~-1 ~34 grass 0  
fill ~-5 ~-1 ~35 ~-3 ~-1 ~35 grass 0  
fill ~-5 ~-1 ~36 ~-4 ~-1 ~36 grass 0  
fill ~-5 ~-1 ~37 ~-4 ~-1 ~37 grass 0  
fill ~-5 ~-1 ~38 ~-4 ~-1 ~38 grass 0  
fill ~-5 ~-1 ~39 ~-3 ~-1 ~39 grass 0  
fill ~-5 ~-1 ~40 ~10 ~-1 ~40 grass 0  
fill ~-5 ~-1 ~41 ~10 ~-1 ~41 grass 0  
fill ~-5 ~-1 ~42 ~10 ~-1 ~42 grass 0  
fill ~-5 ~-1 ~43 ~10 ~-1 ~43 grass 0  
fill ~-5 ~-1 ~44 ~10 ~-1 ~44 grass 0  
fill ~-5 ~-1 ~45 ~10 ~-1 ~45 grass 0  
fill ~-5 ~-1 ~46 ~33 ~-1 ~46 grass 0  
fill ~-5 ~-1 ~47 ~33 ~-1 ~47 grass 0  
fill ~-5 ~-1 ~48 ~33 ~-1 ~48 grass 0  
fill ~-5 ~-1 ~49 ~33 ~-1 ~49 grass 0  
fill ~-3 ~-1 ~36 ~5 ~-1 ~36 dirt 0  
fill ~-3 ~-1 ~37 ~5 ~-1 ~37 dirt 0  
fill ~-3 ~-1 ~38 ~5 ~-1 ~38 dirt 0  
fill ~-2 ~-1 ~35 ~1 ~-1 ~35 dirt 0  
fill ~-2 ~-1 ~39 ~2 ~-1 ~39 dirt 0  
fill ~0 ~-1 ~10 ~5 ~-1 ~10 dirt 0  
fill ~0 ~-1 ~11 ~5 ~-1 ~11 dirt 0  
fill ~0 ~-1 ~12 ~5 ~-1 ~12 dirt 0  
fill ~0 ~-1 ~13 ~5 ~-1 ~13 dirt 0  
fill ~0 ~-1 ~14 ~5 ~-1 ~14 dirt 0  
fill ~0 ~-1 ~15 ~5 ~-1 ~15 dirt 0  
fill ~0 ~-1 ~16 ~5 ~-1 ~16 dirt 0  
fill ~0 ~-1 ~17 ~5 ~-1 ~17 dirt 0  
fill ~0 ~-1 ~18 ~5 ~-1 ~18 dirt 0  
fill ~0 ~-1 ~29 ~5 ~-1 ~29 dirt 0  
fill ~0 ~-1 ~30 ~5 ~-1 ~30 dirt 0  
fill ~2 ~-1 ~35 ~5 ~-1 ~35 grass 0  
fill ~3 ~-1 ~39 ~10 ~-1 ~39 grass 0  
fill ~6 ~-1 ~6 ~43 ~-1 ~6 gravel 0  
fill ~6 ~-1 ~7 ~43 ~-1 ~7 gravel 0  
fill ~6 ~-1 ~8 ~61 ~-1 ~8 gravel 0  
fill ~6 ~-1 ~9 ~8 ~-1 ~9 gravel 0  
fill ~6 ~-1 ~10 ~8 ~-1 ~10 gravel 0  
fill ~6 ~-1 ~11 ~8 ~-1 ~11 gravel 0  
fill ~6 ~-1 ~12 ~8 ~-1 ~12 gravel 0  
fill ~6 ~-1 ~13 ~8 ~-1 ~13 gravel 0  
fill ~6 ~-1 ~14 ~8 ~-1 ~14 gravel 0  
fill ~6 ~-1 ~15 ~8 ~-1 ~15 gravel 0  
fill ~6 ~-1 ~16 ~8 ~-1 ~16 gravel 0  
fill ~6 ~-1 ~17 ~8 ~-1 ~17 gravel 0  
fill ~6 ~-1 ~18 ~8 ~-1 ~18 gravel 0  
fill ~6 ~-1 ~19 ~8 ~-1 ~19 gravel 0  
fill ~6 ~-1 ~20 ~18 ~-1 ~20 gravel 0  
fill ~6 ~-1 ~21 ~18 ~-1 ~21 gravel 0  
fill ~6 ~-1 ~22 ~18 ~-1 ~22 gravel 0  
fill ~6 ~-1 ~23 ~8 ~-1 ~23 gravel 0  
fill ~6 ~-1 ~24 ~8 ~-1 ~24 gravel 0  
fill ~6 ~-1 ~25 ~8 ~-1 ~25 gravel 0  
fill ~6 ~-1 ~26 ~8 ~-1 ~26 gravel 0  
fill ~6 ~-1 ~27 ~8 ~-1 ~27 gravel 0  
fill ~6 ~-1 ~28 ~8 ~-1 ~28 gravel 0  
fill ~6 ~-1 ~29 ~8 ~-1 ~29 gravel 0  
fill ~6 ~-1 ~30 ~8 ~-1 ~30 gravel 0  
fill ~6 ~-1 ~31 ~8 ~-1 ~31 gravel 0  
fill ~6 ~-1 ~32 ~8 ~-1 ~32 gravel 0  
fill ~6 ~-1 ~33 ~8 ~-1 ~33 gravel 0  
fill ~6 ~-1 ~34 ~8 ~-1 ~34 gravel 0  
fill ~6 ~-1 ~35 ~8 ~-1 ~35 gravel 0  
fill ~6 ~-1 ~36 ~43 ~-1 ~36 gravel 0  
fill ~6 ~-1 ~37 ~43 ~-1 ~37 gravel 0  
fill ~6 ~-1 ~38 ~43 ~-1 ~38 gravel 0  
fill ~7 ~-1 ~1 ~10 ~-1 ~1 dirt 0  
fill ~7 ~-1 ~2 ~10 ~-1 ~2 dirt 0  
fill ~7 ~-1 ~3 ~10 ~-1 ~3 dirt 0  
fill ~7 ~-1 ~4 ~10 ~-1 ~4 dirt 0  
fill ~7 ~-1 ~5 ~10 ~-1 ~5 dirt 0  
fill ~9 ~-1 ~9 ~20 ~-1 ~9 grass 0  
fill ~9 ~-1 ~10 ~20 ~-1 ~10 grass 0  
fill ~9 ~-1 ~11 ~20 ~-1 ~11 grass 0  
fill ~9 ~-1 ~12 ~15 ~-1 ~12 grass 0  
fill ~9 ~-1 ~13 ~15 ~-1 ~13 grass 0  
fill ~9 ~-1 ~14 ~15 ~-1 ~14 grass 0  
fill ~9 ~-1 ~15 ~15 ~-1 ~15 grass 0  
fill ~9 ~-1 ~16 ~20 ~-1 ~16 grass 0  
fill ~9 ~-1 ~17 ~20 ~-1 ~17 grass 0  
fill ~9 ~-1 ~18 ~18 ~-1 ~18 grass 0  
fill ~9 ~-1 ~19 ~18 ~-1 ~19 grass 0  
fill ~9 ~-1 ~23 ~11 ~-1 ~23 grass 0  
fill ~9 ~-1 ~24 ~11 ~-1 ~24 grass 0  
fill ~9 ~-1 ~25 ~11 ~-1 ~25 grass 0  
fill ~9 ~-1 ~26 ~11 ~-1 ~26 grass 0  
fill ~9 ~-1 ~27 ~11 ~-1 ~27 grass 0  
fill ~9 ~-1 ~28 ~40 ~-1 ~28 grass 0  
fill ~9 ~-1 ~29 ~40 ~-1 ~29 grass 0  
fill ~9 ~-1 ~30 ~21 ~-1 ~30 grass 0  
fill ~9 ~-1 ~31 ~21 ~-1 ~31 grass 0  
fill ~9 ~-1 ~32 ~21 ~-1 ~32 grass 0  
fill ~9 ~-1 ~33 ~21 ~-1 ~33 grass 0  
fill ~9 ~-1 ~34 ~21 ~-1 ~34 grass 0  
fill ~9 ~-1 ~35 ~21 ~-1 ~35 grass 0  
fill ~11 ~-1 ~1 ~12 ~-1 ~1 grass 0  
fill ~11 ~-1 ~2 ~12 ~-1 ~2 grass 0  
fill ~11 ~-1 ~3 ~12 ~-1 ~3 grass 0  
fill ~11 ~-1 ~4 ~12 ~-1 ~4 grass 0  
fill ~11 ~-1 ~5 ~12 ~-1 ~5 grass 0  
fill ~11 ~-1 ~39 ~20 ~-1 ~39 dirt 0  
fill ~11 ~-1 ~40 ~20 ~-1 ~40 dirt 0  
fill ~11 ~-1 ~41 ~20 ~-1 ~41 dirt 0  
fill ~11 ~-1 ~42 ~20 ~-1 ~42 dirt 0  
fill ~11 ~-1 ~43 ~20 ~-1 ~43 dirt 0  
fill ~11 ~-1 ~44 ~20 ~-1 ~44 dirt 0  
fill ~11 ~-1 ~45 ~20 ~-1 ~45 dirt 0  
fill ~12 ~-1 ~23 ~16 ~-1 ~23 dirt 0  
fill ~12 ~-1 ~24 ~16 ~-1 ~24 dirt 0  
fill ~12 ~-1 ~25 ~16 ~-1 ~25 dirt 0  
fill ~12 ~-1 ~26 ~16 ~-1 ~26 dirt 0  
fill ~12 ~-1 ~27 ~16 ~-1 ~27 dirt 0  
fill ~13 ~-1 ~1 ~17 ~-1 ~1 dirt 0  
fill ~13 ~-1 ~2 ~17 ~-1 ~2 dirt 0  
fill ~13 ~-1 ~3 ~17 ~-1 ~3 dirt 0  
fill ~13 ~-1 ~4 ~17 ~-1 ~4 dirt 0  
fill ~13 ~-1 ~5 ~17 ~-1 ~5 dirt 0  
fill ~16 ~-1 ~12 ~20 ~-1 ~12 dirt 0  
fill ~16 ~-1 ~13 ~20 ~-1 ~13 dirt 0  
fill ~16 ~-1 ~14 ~20 ~-1 ~14 dirt 0  
fill ~16 ~-1 ~15 ~20 ~-1 ~15 dirt 0  
fill ~17 ~-1 ~23 ~18 ~-1 ~23 grass 0  
fill ~17 ~-1 ~24 ~35 ~-1 ~24 grass 0  
fill ~17 ~-1 ~25 ~35 ~-1 ~25 grass 0  
fill ~17 ~-1 ~26 ~35 ~-1 ~26 grass 0  
fill ~17 ~-1 ~27 ~40 ~-1 ~27 grass 0  
fill ~18 ~-1 ~1 ~20 ~-1 ~1 grass 0  
fill ~18 ~-1 ~2 ~20 ~-1 ~2 grass 0  
fill ~18 ~-1 ~3 ~20 ~-1 ~3 grass 0  
fill ~18 ~-1 ~4 ~20 ~-1 ~4 grass 0  
fill ~18 ~-1 ~5 ~20 ~-1 ~5 grass 0  
fill ~19 ~-1 ~18 ~24 ~-1 ~18 dirt 0  
fill ~19 ~-1 ~19 ~20 ~-1 ~19 dirt 0  
fill ~19 ~-1 ~20 ~19 ~-1 ~20 dirt 0  
fill ~19 ~-1 ~21 ~19 ~-1 ~21 dirt 0  
fill ~19 ~-1 ~22 ~20 ~-1 ~22 dirt 0  
fill ~19 ~-1 ~23 ~24 ~-1 ~23 dirt 0  
fill ~20 ~-1 ~20 ~20 ~1 ~20 cobblestone 0  
fill ~20 ~-1 ~21 ~20 ~1 ~21 cobblestone 0  
fill ~21 ~-1 ~-5 ~27 ~-1 ~-5 dirt 0  
fill ~21 ~-1 ~-4 ~27 ~-1 ~-4 dirt 0  
fill ~21 ~-1 ~-3 ~27 ~-1 ~-3 dirt 0  
fill ~21 ~-1 ~-2 ~27 ~-1 ~-2 dirt 0  
fill ~21 ~-1 ~-1 ~27 ~-1 ~-1 dirt 0  
fill ~21 ~-1 ~0 ~29 ~-1 ~0 dirt 0  
fill ~21 ~-1 ~1 ~29 ~-1 ~1 dirt 0  
fill ~21 ~-1 ~2 ~29 ~-1 ~2 dirt 0  
fill ~21 ~-1 ~3 ~29 ~-1 ~3 dirt 0  
fill ~21 ~-1 ~4 ~29 ~-1 ~4 dirt 0  
fill ~21 ~-1 ~5 ~29 ~-1 ~5 dirt 0  
fill ~21 ~-1 ~9 ~23 ~-1 ~9 gravel 0  
fill ~21 ~-1 ~10 ~23 ~-1 ~10 gravel 0  
fill ~21 ~-1 ~11 ~23 ~-1 ~11 gravel 0  
fill ~21 ~-1 ~12 ~23 ~-1 ~12 gravel 0  
fill ~21 ~-1 ~13 ~23 ~-1 ~13 gravel 0  
fill ~21 ~-1 ~14 ~23 ~-1 ~14 gravel 0  
fill ~21 ~-1 ~15 ~23 ~-1 ~15 gravel 0  
fill ~21 ~-1 ~16 ~23 ~-1 ~16 gravel 0  
fill ~21 ~-1 ~17 ~23 ~-1 ~17 gravel 0  
fill ~21 ~-1 ~19 ~22 ~-1 ~19 cobblestone 0  
fill ~21 ~-1 ~20 ~22 ~-1 ~20 water 8  
fill ~21 ~-1 ~21 ~22 ~-1 ~21 water 8  
fill ~21 ~-1 ~22 ~22 ~-1 ~22 cobblestone 0  
fill ~21 ~-1 ~39 ~31 ~-1 ~39 grass 0  
fill ~21 ~-1 ~40 ~31 ~-1 ~40 grass 0  
fill ~21 ~-1 ~41 ~31 ~-1 ~41 grass 0  
fill ~21 ~-1 ~42 ~31 ~-1 ~42 grass 0  
fill ~21 ~-1 ~43 ~31 ~-1 ~43 grass 0  
fill ~21 ~-1 ~44 ~31 ~-1 ~44 grass 0  
fill ~21 ~-1 ~45 ~33 ~-1 ~45 grass 0  
fill ~22 ~-1 ~30 ~30 ~-1 ~30 dirt 0  
fill ~22 ~-1 ~31 ~30 ~-1 ~31 dirt 0  
fill ~22 ~-1 ~32 ~30 ~-1 ~32 dirt 0  
fill ~22 ~-1 ~33 ~30 ~-1 ~33 dirt 0  
fill ~22 ~-1 ~34 ~30 ~-1 ~34 dirt 0  
fill ~22 ~-1 ~35 ~30 ~-1 ~35 dirt 0  
fill ~23 ~-1 ~19 ~24 ~-1 ~19 dirt 0  
fill ~23 ~-1 ~20 ~23 ~1 ~20 cobblestone 0  
fill ~23 ~-1 ~21 ~23 ~1 ~21 cobblestone 0  
fill ~23 ~-1 ~22 ~24 ~-1 ~22 dirt 0  
fill ~24 ~-1 ~9 ~25 ~-1 ~9 grass 0  
fill ~24 ~-1 ~10 ~25 ~-1 ~10 grass 0  
fill ~24 ~-1 ~11 ~25 ~-1 ~11 grass 0  
fill ~24 ~-1 ~12 ~25 ~-1 ~12 grass 0  
fill ~24 ~-1 ~13 ~25 ~-1 ~13 grass 0  
fill ~24 ~-1 ~14 ~25 ~-1 ~14 grass 0  
fill ~24 ~-1 ~15 ~27 ~-1 ~15 grass 0  
fill ~24 ~-1 ~16 ~27 ~-1 ~16 grass 0  
fill ~24 ~-1 ~17 ~27 ~-1 ~17 grass 0  
fill ~24 ~-1 ~20 ~24 ~-1 ~20 dirt 0  
fill ~24 ~-1 ~21 ~24 ~-1 ~21 dirt 0  
fill ~25 ~-1 ~18 ~27 ~-1 ~18 grass 0  
fill ~25 ~-1 ~19 ~27 ~-1 ~19 grass 0  
fill ~25 ~-1 ~20 ~40 ~-1 ~20 grass 0  
fill ~25 ~-1 ~21 ~40 ~-1 ~21 grass 0  
fill ~25 ~-1 ~22 ~35 ~-1 ~22 grass 0  
fill ~25 ~-1 ~23 ~35 ~-1 ~23 grass 0  
fill ~26 ~-1 ~9 ~34 ~-1 ~9 dirt 0  
fill ~26 ~-1 ~10 ~34 ~-1 ~10 dirt 0  
fill ~26 ~-1 ~11 ~34 ~-1 ~11 dirt 0  
fill ~26 ~-1 ~12 ~34 ~-1 ~12 dirt 0  
fill ~26 ~-1 ~13 ~34 ~-1 ~13 dirt 0  
fill ~26 ~-1 ~14 ~34 ~-1 ~14 dirt 0  
fill ~28 ~-1 ~-5 ~40 ~-1 ~-5 grass 0  
fill ~28 ~-1 ~-4 ~40 ~-1 ~-4 grass 0  
fill ~28 ~-1 ~-3 ~40 ~-1 ~-3 grass 0  
fill ~28 ~-1 ~-2 ~31 ~-1 ~-2 grass 0  
fill ~28 ~-1 ~-1 ~31 ~-1 ~-1 grass 0  
fill ~28 ~-1 ~15 ~34 ~-1 ~15 dirt 0  
fill ~28 ~-1 ~16 ~34 ~-1 ~16 dirt 0  
fill ~28 ~-1 ~17 ~34 ~-1 ~17 dirt 0  
fill ~28 ~-1 ~18 ~34 ~-1 ~18 dirt 0  
fill ~28 ~-1 ~19 ~34 ~-1 ~19 dirt 0  
fill ~30 ~-1 ~0 ~31 ~-1 ~0 grass 0  
fill ~30 ~-1 ~1 ~31 ~-1 ~1 grass 0  
fill ~30 ~-1 ~2 ~31 ~-1 ~2 grass 0  
fill ~30 ~-1 ~3 ~31 ~-1 ~3 grass 0  
fill ~30 ~-1 ~4 ~31 ~-1 ~4 grass 0  
fill ~30 ~-1 ~5 ~40 ~-1 ~5 grass 0  
fill ~31 ~-1 ~30 ~40 ~-1 ~30 grass 0  
fill ~31 ~-1 ~31 ~40 ~-1 ~31 grass 0  
fill ~31 ~-1 ~32 ~40 ~-1 ~32 grass 0  
fill ~31 ~-1 ~33 ~40 ~-1 ~33 grass 0  
fill ~31 ~-1 ~34 ~40 ~-1 ~34 grass 0  
fill ~31 ~-1 ~35 ~40 ~-1 ~35 grass 0  
fill ~32 ~-1 ~-2 ~40 ~-1 ~-2 dirt 0  
fill ~32 ~-1 ~-1 ~32 ~-1 ~-1 dirt 0  
fill ~32 ~-1 ~0 ~32 ~-1 ~0 dirt 0  
fill ~32 ~-1 ~1 ~40 ~-1 ~1 dirt 0  
fill ~32 ~-1 ~2 ~32 ~-1 ~2 dirt 0  
fill ~32 ~-1 ~3 ~32 ~-1 ~3 dirt 0  
fill ~32 ~-1 ~4 ~40 ~-1 ~4 dirt 0  
fill ~32 ~-1 ~39 ~40 ~-1 ~39 dirt 0  
fill ~32 ~-1 ~40 ~40 ~-1 ~40 dirt 0  
fill ~32 ~-1 ~41 ~40 ~-1 ~41 dirt 0  
fill ~32 ~-1 ~42 ~40 ~-1 ~42 dirt 0  
fill ~32 ~-1 ~43 ~40 ~-1 ~43 dirt 0  
fill ~32 ~-1 ~44 ~40 ~-1 ~44 dirt 0  
fill ~33 ~-1 ~-1 ~37 ~-1 ~-1 grass 0  
fill ~33 ~-1 ~0 ~38 ~-1 ~0 grass 0  
fill ~33 ~-1 ~2 ~39 ~-1 ~2 grass 0  
fill ~33 ~-1 ~3 ~39 ~-1 ~3 grass 0  
fill ~34 ~-1 ~45 ~40 ~-1 ~45 dirt 0  
fill ~34 ~-1 ~46 ~40 ~-1 ~46 dirt 0  
fill ~34 ~-1 ~47 ~40 ~-1 ~47 dirt 0  
fill ~34 ~-1 ~48 ~40 ~-1 ~48 dirt 0  
fill ~34 ~-1 ~49 ~40 ~-1 ~49 dirt 0  
fill ~35 ~-1 ~9 ~40 ~-1 ~9 grass 0  
fill ~35 ~-1 ~10 ~40 ~-1 ~10 grass 0  
fill ~35 ~-1 ~11 ~35 ~-1 ~35 grass 0  
fill ~36 ~-1 ~11 ~36 ~-1 ~11 dirt 0  
fill ~36 ~-1 ~12 ~36 ~-1 ~12 dirt 0  
fill ~36 ~-1 ~13 ~36 ~-1 ~13 dirt 0  
fill ~36 ~-1 ~14 ~40 ~-1 ~14 dirt 0  
fill ~36 ~-1 ~15 ~40 ~-1 ~15 grass 0  
fill ~36 ~-1 ~16 ~40 ~-1 ~16 grass 0  
fill ~36 ~-1 ~17 ~40 ~-1 ~17 grass 0  
fill ~36 ~-1 ~18 ~40 ~-1 ~18 grass 0  
fill ~36 ~-1 ~19 ~40 ~-1 ~19 grass 0  
fill ~36 ~-1 ~22 ~40 ~-1 ~22 dirt 0  
fill ~36 ~-1 ~23 ~40 ~-1 ~23 dirt 0  
fill ~36 ~-1 ~24 ~40 ~-1 ~24 dirt 0  
fill ~36 ~-1 ~25 ~40 ~-1 ~25 dirt 0  
fill ~36 ~-1 ~26 ~40 ~-1 ~26 dirt 0  
fill ~37 ~-1 ~13 ~37 ~-1 ~13 sand 0  
fill ~38 ~-1 ~-1 ~38 ~-1 ~-1 dirt 0 
setblock ~39 ~-1 ~-1 grass 0  
fill ~39 ~-1 ~0 ~40 ~-1 ~0 dirt 0  
fill ~40 ~-1 ~-1 ~40 ~-1 ~-1 dirt 0  
fill ~40 ~-1 ~2 ~40 ~-1 ~2 dirt 0  
fill ~40 ~-1 ~3 ~40 ~-1 ~3 dirt 0  
fill ~40 ~-1 ~11 ~40 ~-1 ~11 dirt 0  
fill ~40 ~-1 ~12 ~40 ~-1 ~12 dirt 0  
fill ~40 ~-1 ~13 ~40 ~-1 ~13 dirt 0  
fill ~41 ~-1 ~-5 ~43 ~-1 ~-5 gravel 0  
fill ~41 ~-1 ~-4 ~43 ~-1 ~-4 gravel 0  
fill ~41 ~-1 ~-3 ~43 ~-1 ~-3 gravel 0  
fill ~41 ~-1 ~-2 ~43 ~-1 ~-2 gravel 0  
fill ~41 ~-1 ~-1 ~43 ~-1 ~-1 gravel 0  
fill ~41 ~-1 ~0 ~43 ~-1 ~0 gravel 0  
fill ~41 ~-1 ~1 ~43 ~-1 ~1 gravel 0  
fill ~41 ~-1 ~2 ~43 ~-1 ~2 gravel 0  
fill ~41 ~-1 ~3 ~43 ~-1 ~3 gravel 0  
fill ~41 ~-1 ~4 ~43 ~-1 ~4 gravel 0  
fill ~41 ~-1 ~5 ~43 ~-1 ~5 gravel 0  
fill ~41 ~-1 ~9 ~61 ~-1 ~9 gravel 0  
fill ~41 ~-1 ~10 ~61 ~-1 ~10 gravel 0  
fill ~41 ~-1 ~11 ~43 ~-1 ~11 gravel 0  
fill ~41 ~-1 ~13 ~43 ~-1 ~13 gravel 0  
fill ~41 ~-1 ~14 ~43 ~-1 ~14 gravel 0  
fill ~41 ~-1 ~15 ~43 ~-1 ~15 gravel 0  
fill ~41 ~-1 ~16 ~43 ~-1 ~16 gravel 0  
fill ~41 ~-1 ~17 ~43 ~-1 ~17 gravel 0  
fill ~41 ~-1 ~18 ~43 ~-1 ~18 gravel 0  
fill ~41 ~-1 ~19 ~43 ~-1 ~19 gravel 0  
fill ~41 ~-1 ~20 ~43 ~-1 ~20 gravel 0  
fill ~41 ~-1 ~21 ~43 ~-1 ~21 gravel 0  
fill ~41 ~-1 ~22 ~43 ~-1 ~22 gravel 0  
fill ~41 ~-1 ~23 ~43 ~-1 ~23 gravel 0  
fill ~41 ~-1 ~24 ~43 ~-1 ~24 gravel 0  
fill ~41 ~-1 ~25 ~43 ~-1 ~25 gravel 0  
fill ~41 ~-1 ~26 ~43 ~-1 ~26 gravel 0  
fill ~41 ~-1 ~27 ~43 ~-1 ~27 gravel 0  
fill ~41 ~-1 ~28 ~43 ~-1 ~28 gravel 0  
fill ~41 ~-1 ~29 ~43 ~-1 ~29 gravel 0  
fill ~41 ~-1 ~30 ~43 ~-1 ~30 gravel 0  
fill ~41 ~-1 ~31 ~43 ~-1 ~31 gravel 0  
fill ~41 ~-1 ~32 ~43 ~-1 ~32 gravel 0  
fill ~41 ~-1 ~33 ~43 ~-1 ~33 gravel 0  
fill ~41 ~-1 ~34 ~43 ~-1 ~34 gravel 0  
fill ~41 ~-1 ~35 ~43 ~-1 ~35 gravel 0  
fill ~41 ~-1 ~39 ~61 ~-1 ~39 grass 0  
fill ~41 ~-1 ~40 ~61 ~-1 ~40 grass 0  
fill ~41 ~-1 ~41 ~61 ~-1 ~41 grass 0  
fill ~41 ~-1 ~42 ~61 ~-1 ~42 grass 0  
fill ~41 ~-1 ~43 ~61 ~-1 ~43 grass 0  
fill ~41 ~-1 ~44 ~61 ~-1 ~44 grass 0  
fill ~41 ~-1 ~45 ~61 ~-1 ~45 grass 0  
fill ~41 ~-1 ~46 ~61 ~-1 ~46 grass 0  
fill ~41 ~-1 ~47 ~61 ~-1 ~47 grass 0  
fill ~41 ~-1 ~48 ~61 ~-1 ~48 grass 0  
fill ~41 ~-1 ~49 ~61 ~-1 ~49 grass 0  
fill ~42 ~-1 ~12 ~43 ~-1 ~12 gravel 0  
fill ~44 ~-1 ~-5 ~61 ~-1 ~-5 grass 0  
fill ~44 ~-1 ~-4 ~61 ~-1 ~-4 grass 0  
fill ~44 ~-1 ~-3 ~61 ~-1 ~-3 grass 0  
fill ~44 ~-1 ~-2 ~61 ~-1 ~-2 grass 0  
fill ~44 ~-1 ~-1 ~61 ~-1 ~-1 grass 0  
fill ~44 ~-1 ~0 ~61 ~-1 ~0 grass 0  
fill ~44 ~-1 ~1 ~61 ~-1 ~1 grass 0  
fill ~44 ~-1 ~2 ~61 ~-1 ~2 grass 0  
fill ~44 ~-1 ~3 ~47 ~-1 ~3 dirt 0  
fill ~44 ~-1 ~4 ~47 ~-1 ~4 dirt 0  
fill ~44 ~-1 ~5 ~47 ~-1 ~5 dirt 0  
fill ~44 ~-1 ~6 ~47 ~-1 ~6 dirt 0  
fill ~44 ~-1 ~7 ~47 ~-1 ~7 dirt 0  
fill ~44 ~-1 ~11 ~46 ~-1 ~11 grass 0  
fill ~44 ~-1 ~12 ~46 ~-1 ~12 grass 0  
fill ~44 ~-1 ~13 ~46 ~-1 ~13 grass 0  
fill ~44 ~-1 ~14 ~46 ~-1 ~14 grass 0  
fill ~44 ~-1 ~15 ~46 ~-1 ~15 grass 0  
fill ~44 ~-1 ~16 ~46 ~-1 ~16 grass 0  
fill ~44 ~-1 ~17 ~46 ~-1 ~17 grass 0  
fill ~44 ~-1 ~18 ~51 ~-1 ~18 grass 0  
fill ~44 ~-1 ~19 ~51 ~-1 ~19 grass 0  
fill ~44 ~-1 ~20 ~61 ~-1 ~20 grass 0  
fill ~44 ~-1 ~21 ~61 ~-1 ~21 grass 0  
fill ~44 ~-1 ~22 ~61 ~-1 ~22 grass 0  
fill ~44 ~-1 ~23 ~61 ~-1 ~23 grass 0  
fill ~44 ~-1 ~24 ~61 ~-1 ~24 grass 0  
fill ~44 ~-1 ~25 ~61 ~-1 ~25 grass 0  
fill ~44 ~-1 ~26 ~61 ~-1 ~26 grass 0  
fill ~44 ~-1 ~27 ~49 ~-1 ~27 dirt 0  
fill ~44 ~-1 ~28 ~49 ~-1 ~28 dirt 0  
fill ~44 ~-1 ~29 ~54 ~-1 ~29 dirt 0  
fill ~44 ~-1 ~30 ~54 ~-1 ~30 dirt 0  
fill ~44 ~-1 ~31 ~54 ~-1 ~31 dirt 0  
fill ~44 ~-1 ~32 ~54 ~-1 ~32 dirt 0  
fill ~44 ~-1 ~33 ~54 ~-1 ~33 dirt 0  
fill ~44 ~-1 ~34 ~54 ~-1 ~34 dirt 0  
fill ~44 ~-1 ~35 ~54 ~-1 ~35 dirt 0  
fill ~44 ~-1 ~36 ~61 ~-1 ~36 grass 0  
fill ~44 ~-1 ~37 ~61 ~-1 ~37 grass 0  
fill ~44 ~-1 ~38 ~61 ~-1 ~38 grass 0  
fill ~47 ~-1 ~11 ~57 ~-1 ~11 dirt 0  
fill ~47 ~-1 ~12 ~57 ~-1 ~12 dirt 0  
fill ~47 ~-1 ~13 ~57 ~-1 ~13 dirt 0  
fill ~47 ~-1 ~14 ~57 ~-1 ~14 dirt 0  
fill ~47 ~-1 ~15 ~57 ~-1 ~15 dirt 0  
fill ~47 ~-1 ~16 ~57 ~-1 ~16 dirt 0  
fill ~47 ~-1 ~17 ~51 ~-1 ~17 dirt 0  
fill ~48 ~-1 ~3 ~53 ~-1 ~3 grass 0  
fill ~48 ~-1 ~4 ~53 ~-1 ~4 grass 0  
fill ~48 ~-1 ~5 ~53 ~-1 ~5 grass 0  
fill ~48 ~-1 ~6 ~53 ~-1 ~6 grass 0  
fill ~48 ~-1 ~7 ~53 ~-1 ~7 grass 0  
fill ~50 ~-1 ~27 ~61 ~-1 ~27 grass 0  
fill ~50 ~-1 ~28 ~61 ~-1 ~28 grass 0 
setblock ~52 ~-1 ~17 planks 0  
fill ~52 ~-1 ~18 ~57 ~-1 ~18 dirt 0  
fill ~52 ~-1 ~19 ~57 ~-1 ~19 dirt 0  
fill ~53 ~-1 ~17 ~57 ~-1 ~17 dirt 0  
fill ~54 ~-1 ~3 ~58 ~-1 ~3 dirt 0  
fill ~54 ~-1 ~4 ~58 ~-1 ~4 dirt 0  
fill ~54 ~-1 ~5 ~58 ~-1 ~5 dirt 0  
fill ~54 ~-1 ~6 ~58 ~-1 ~6 dirt 0  
fill ~54 ~-1 ~7 ~58 ~-1 ~7 dirt 0  
fill ~55 ~-1 ~29 ~61 ~-1 ~29 grass 0  
fill ~55 ~-1 ~30 ~61 ~-1 ~30 grass 0  
fill ~55 ~-1 ~31 ~61 ~-1 ~31 grass 0  
fill ~55 ~-1 ~32 ~61 ~-1 ~32 grass 0  
fill ~55 ~-1 ~33 ~61 ~-1 ~33 grass 0  
fill ~55 ~-1 ~34 ~61 ~-1 ~34 grass 0  
fill ~55 ~-1 ~35 ~61 ~-1 ~35 grass 0  
fill ~58 ~-1 ~11 ~60 ~-1 ~11 gravel 0  
fill ~58 ~-1 ~12 ~60 ~-1 ~12 gravel 0  
fill ~58 ~-1 ~13 ~60 ~-1 ~13 gravel 0  
fill ~58 ~-1 ~14 ~60 ~-1 ~14 gravel 0  
fill ~58 ~-1 ~15 ~60 ~-1 ~15 gravel 0  
fill ~58 ~-1 ~16 ~60 ~-1 ~16 gravel 0  
fill ~58 ~-1 ~17 ~60 ~-1 ~17 gravel 0  
fill ~58 ~-1 ~18 ~60 ~-1 ~18 gravel 0  
fill ~58 ~-1 ~19 ~60 ~-1 ~19 gravel 0  
fill ~59 ~-1 ~3 ~61 ~-1 ~3 grass 0  
fill ~59 ~-1 ~4 ~61 ~-1 ~4 grass 0  
fill ~59 ~-1 ~5 ~61 ~-1 ~5 grass 0  
fill ~59 ~-1 ~6 ~61 ~-1 ~6 grass 0  
fill ~59 ~-1 ~7 ~61 ~-1 ~7 grass 0  
fill ~61 ~-1 ~11 ~61 ~-1 ~11 grass 0  
fill ~61 ~-1 ~12 ~61 ~-1 ~12 grass 0  
fill ~61 ~-1 ~13 ~61 ~-1 ~13 grass 0  
fill ~61 ~-1 ~14 ~61 ~-1 ~14 grass 0  
fill ~61 ~-1 ~15 ~61 ~-1 ~15 grass 0  
fill ~61 ~-1 ~16 ~61 ~-1 ~16 grass 0  
fill ~61 ~-1 ~17 ~61 ~-1 ~17 grass 0  
fill ~61 ~-1 ~18 ~61 ~-1 ~18 grass 0  
fill ~61 ~-1 ~19 ~61 ~-1 ~19 grass 0  
fill ~-5 ~0 ~22 ~5 ~0 ~22 cobblestone 0  
fill ~-5 ~0 ~23 ~-5 ~3 ~23 cobblestone 0  
fill ~-5 ~0 ~24 ~-5 ~3 ~24 cobblestone 0  
fill ~-5 ~0 ~25 ~-5 ~3 ~25 cobblestone 0  
fill ~-5 ~0 ~26 ~-5 ~3 ~26 cobblestone 0  
fill ~-5 ~0 ~27 ~-5 ~3 ~27 cobblestone 0  
fill ~-5 ~0 ~28 ~0 ~0 ~28 cobblestone 0  
fill ~-4 ~0 ~23 ~4 ~0 ~23 planks 0  
fill ~-4 ~0 ~24 ~4 ~0 ~24 planks 0  
fill ~-4 ~0 ~25 ~4 ~0 ~25 planks 0  
fill ~-4 ~0 ~26 ~4 ~0 ~26 planks 0  
fill ~-4 ~0 ~27 ~4 ~0 ~27 planks 0  
fill ~-3 ~0 ~36 ~5 ~0 ~36 cobblestone 0  
fill ~-3 ~0 ~37 ~5 ~0 ~37 cobblestone 0  
fill ~-3 ~0 ~38 ~5 ~0 ~38 cobblestone 0  
fill ~-2 ~0 ~35 ~1 ~0 ~35 cobblestone 0  
fill ~-2 ~0 ~39 ~2 ~0 ~39 cobblestone 0  
fill ~0 ~0 ~10 ~5 ~0 ~10 cobblestone 0  
fill ~0 ~0 ~11 ~5 ~0 ~11 cobblestone 0  
fill ~0 ~0 ~12 ~5 ~0 ~12 cobblestone 0  
fill ~0 ~0 ~13 ~5 ~0 ~13 cobblestone 0  
fill ~0 ~0 ~14 ~5 ~0 ~14 cobblestone 0  
fill ~0 ~0 ~15 ~5 ~0 ~15 cobblestone 0  
fill ~0 ~0 ~16 ~5 ~0 ~16 cobblestone 0  
fill ~0 ~0 ~17 ~5 ~0 ~17 cobblestone 0  
fill ~0 ~0 ~18 ~5 ~0 ~18 cobblestone 0  
fill ~0 ~0 ~29 ~0 ~1 ~29 cobblestone 0  
fill ~0 ~0 ~30 ~5 ~0 ~30 cobblestone 0  
fill ~1 ~0 ~28 ~4 ~0 ~28 planks 0  
fill ~1 ~0 ~29 ~4 ~0 ~29 planks 0  
fill ~5 ~0 ~5 ~6 ~0 ~5 fence 0  
fill ~5 ~0 ~6 ~5 ~0 ~9 fence 0  
fill ~5 ~0 ~19 ~5 ~0 ~21 fence 0  
fill ~5 ~0 ~23 ~5 ~1 ~23 cobblestone 0  
fill ~5 ~0 ~24 ~5 ~1 ~24 cobblestone 0  
fill ~5 ~0 ~25 ~5 ~1 ~25 cobblestone 0  
fill ~5 ~0 ~26 ~5 ~1 ~26 cobblestone 0  
fill ~5 ~0 ~27 ~5 ~1 ~27 cobblestone 0  
fill ~5 ~0 ~28 ~5 ~0 ~30 cobblestone 0  
fill ~5 ~0 ~31 ~5 ~0 ~35 fence 0  
fill ~5 ~0 ~39 ~10 ~0 ~39 fence 0 
setblock ~6 ~0 ~12 stone_stairs 1 
setblock ~6 ~0 ~28 stone_stairs 1 
setblock ~6 ~0 ~37 stone_stairs 1  
fill ~7 ~0 ~1 ~10 ~0 ~1 cobblestone 0  
fill ~7 ~0 ~2 ~10 ~0 ~2 cobblestone 0  
fill ~7 ~0 ~3 ~10 ~0 ~3 cobblestone 0  
fill ~7 ~0 ~4 ~10 ~0 ~4 cobblestone 0  
fill ~7 ~0 ~5 ~10 ~0 ~5 cobblestone 0 
setblock ~9 ~0 ~6 stone_stairs 3  
fill ~11 ~0 ~5 ~12 ~0 ~5 fence 0  
fill ~11 ~0 ~39 ~20 ~0 ~39 cobblestone 0  
fill ~11 ~0 ~40 ~20 ~0 ~40 cobblestone 0  
fill ~11 ~0 ~41 ~20 ~0 ~41 cobblestone 0  
fill ~11 ~0 ~42 ~20 ~0 ~42 cobblestone 0  
fill ~11 ~0 ~43 ~20 ~0 ~43 cobblestone 0  
fill ~11 ~0 ~44 ~20 ~0 ~44 cobblestone 0  
fill ~11 ~0 ~45 ~20 ~0 ~45 cobblestone 0  
fill ~12 ~0 ~23 ~16 ~0 ~23 cobblestone 0  
fill ~12 ~0 ~24 ~16 ~0 ~24 cobblestone 0  
fill ~12 ~0 ~25 ~16 ~0 ~25 cobblestone 0  
fill ~12 ~0 ~26 ~16 ~0 ~26 cobblestone 0  
fill ~12 ~0 ~27 ~16 ~0 ~27 cobblestone 0  
fill ~13 ~0 ~1 ~17 ~0 ~1 cobblestone 0  
fill ~13 ~0 ~2 ~17 ~0 ~2 cobblestone 0  
fill ~13 ~0 ~3 ~17 ~0 ~3 cobblestone 0  
fill ~13 ~0 ~4 ~17 ~0 ~4 cobblestone 0  
fill ~13 ~0 ~5 ~17 ~0 ~5 cobblestone 0 
setblock ~14 ~0 ~22 stone_stairs 2 
setblock ~15 ~0 ~6 stone_stairs 3  
fill ~16 ~0 ~12 ~20 ~0 ~12 cobblestone 0  
fill ~16 ~0 ~13 ~20 ~0 ~13 cobblestone 0  
fill ~16 ~0 ~14 ~20 ~0 ~14 cobblestone 0  
fill ~16 ~0 ~15 ~20 ~0 ~15 cobblestone 0  
fill ~17 ~0 ~38 ~19 ~0 ~38 stone_stairs 2  
fill ~18 ~0 ~5 ~20 ~0 ~5 fence 0  
fill ~19 ~0 ~18 ~24 ~0 ~18 gravel 0  
fill ~19 ~0 ~19 ~19 ~0 ~23 gravel 0  
fill ~20 ~0 ~19 ~23 ~0 ~19 cobblestone 0  
fill ~20 ~0 ~22 ~23 ~0 ~22 cobblestone 0  
fill ~20 ~0 ~23 ~24 ~0 ~23 gravel 0  
fill ~21 ~0 ~-5 ~27 ~0 ~-5 grass 0  
fill ~21 ~0 ~-4 ~27 ~0 ~-4 grass 0  
fill ~21 ~0 ~-3 ~27 ~0 ~-3 grass 0  
fill ~21 ~0 ~-2 ~27 ~0 ~-2 grass 0  
fill ~21 ~0 ~-1 ~22 ~0 ~-1 grass 0  
fill ~21 ~0 ~0 ~29 ~0 ~0 cobblestone 0  
fill ~21 ~0 ~1 ~21 ~1 ~1 cobblestone 0  
fill ~21 ~0 ~2 ~21 ~1 ~2 cobblestone 0  
fill ~21 ~0 ~3 ~21 ~1 ~3 cobblestone 0  
fill ~21 ~0 ~4 ~21 ~1 ~4 cobblestone 0  
fill ~21 ~0 ~5 ~29 ~0 ~5 cobblestone 0 
setblock ~21 ~0 ~13 stone_stairs 1  
fill ~21 ~0 ~20 ~22 ~0 ~20 water 8  
fill ~21 ~0 ~21 ~22 ~0 ~21 water 8  
fill ~21 ~0 ~39 ~31 ~0 ~39 fence 0  
fill ~22 ~0 ~1 ~28 ~0 ~1 planks 0  
fill ~22 ~0 ~2 ~24 ~0 ~2 double_stone_slab 0  
fill ~22 ~0 ~3 ~24 ~0 ~3 double_stone_slab 0  
fill ~22 ~0 ~4 ~24 ~0 ~4 double_stone_slab 0  
fill ~22 ~0 ~30 ~30 ~0 ~30 cobblestone 0  
fill ~22 ~0 ~31 ~26 ~0 ~31 cobblestone 0  
fill ~22 ~0 ~32 ~30 ~0 ~32 cobblestone 0  
fill ~22 ~0 ~33 ~30 ~0 ~33 cobblestone 0  
fill ~22 ~0 ~34 ~30 ~0 ~34 cobblestone 0  
fill ~22 ~0 ~35 ~30 ~0 ~35 cobblestone 0 
setblock ~23 ~0 ~-1 cobblestone 0  
fill ~24 ~0 ~-1 ~27 ~0 ~-1 grass 0  
fill ~24 ~0 ~19 ~24 ~0 ~23 gravel 0  
fill ~25 ~0 ~2 ~28 ~0 ~2 planks 0  
fill ~25 ~0 ~3 ~28 ~0 ~3 planks 0  
fill ~25 ~0 ~4 ~28 ~0 ~4 planks 0  
fill ~26 ~0 ~9 ~34 ~0 ~9 cobblestone 0  
fill ~26 ~0 ~10 ~26 ~1 ~10 cobblestone 0  
fill ~26 ~0 ~11 ~26 ~1 ~11 cobblestone 0  
fill ~26 ~0 ~12 ~26 ~1 ~12 cobblestone 0  
fill ~26 ~0 ~13 ~26 ~1 ~13 cobblestone 0  
fill ~26 ~0 ~14 ~34 ~0 ~14 cobblestone 0 
setblock ~27 ~0 ~6 stone_stairs 3  
fill ~27 ~0 ~10 ~30 ~0 ~10 planks 0  
fill ~27 ~0 ~11 ~30 ~0 ~11 planks 0  
fill ~27 ~0 ~12 ~30 ~0 ~12 planks 0  
fill ~27 ~0 ~13 ~33 ~0 ~13 planks 0 
setblock ~27 ~0 ~31 grass 0 
setblock ~28 ~0 ~8 stone_stairs 2  
fill ~28 ~0 ~15 ~31 ~0 ~15 grass 0  
fill ~28 ~0 ~16 ~34 ~0 ~16 grass 0  
fill ~28 ~0 ~17 ~34 ~0 ~17 grass 0  
fill ~28 ~0 ~18 ~34 ~0 ~18 grass 0  
fill ~28 ~0 ~19 ~34 ~0 ~19 grass 0  
fill ~28 ~0 ~31 ~30 ~0 ~31 cobblestone 0 
setblock ~28 ~0 ~36 stone_stairs 3  
fill ~29 ~0 ~1 ~29 ~1 ~1 cobblestone 0  
fill ~29 ~0 ~2 ~29 ~1 ~2 cobblestone 0  
fill ~29 ~0 ~3 ~29 ~1 ~3 cobblestone 0  
fill ~29 ~0 ~4 ~29 ~1 ~4 cobblestone 0  
fill ~30 ~0 ~5 ~40 ~0 ~5 fence 0  
fill ~31 ~0 ~10 ~33 ~0 ~10 double_stone_slab 0  
fill ~31 ~0 ~11 ~33 ~0 ~11 double_stone_slab 0  
fill ~31 ~0 ~12 ~33 ~0 ~12 double_stone_slab 0  
fill ~32 ~0 ~-2 ~40 ~0 ~-2 log 0  
fill ~32 ~0 ~-1 ~32 ~0 ~4 log 0 
setblock ~32 ~0 ~15 cobblestone 0  
fill ~32 ~0 ~39 ~40 ~0 ~39 cobblestone 0  
fill ~32 ~0 ~40 ~32 ~1 ~40 cobblestone 0  
fill ~32 ~0 ~41 ~32 ~1 ~41 cobblestone 0  
fill ~32 ~0 ~42 ~32 ~1 ~42 cobblestone 0  
fill ~32 ~0 ~43 ~32 ~1 ~43 cobblestone 0  
fill ~32 ~0 ~44 ~40 ~0 ~44 cobblestone 0  
fill ~33 ~0 ~-1 ~37 ~0 ~-1 farmland 7  
fill ~33 ~0 ~0 ~38 ~0 ~0 farmland 7  
fill ~33 ~0 ~1 ~39 ~0 ~1 water 0  
fill ~33 ~0 ~2 ~39 ~0 ~2 farmland 7  
fill ~33 ~0 ~3 ~39 ~0 ~3 farmland 7  
fill ~33 ~0 ~4 ~40 ~0 ~4 log 0  
fill ~33 ~0 ~15 ~34 ~0 ~15 grass 0  
fill ~33 ~0 ~40 ~36 ~0 ~40 planks 0  
fill ~33 ~0 ~41 ~36 ~0 ~41 planks 0  
fill ~33 ~0 ~42 ~36 ~0 ~42 planks 0  
fill ~33 ~0 ~43 ~39 ~0 ~43 planks 0  
fill ~34 ~0 ~10 ~34 ~1 ~10 cobblestone 0  
fill ~34 ~0 ~11 ~34 ~1 ~11 cobblestone 0  
fill ~34 ~0 ~12 ~34 ~1 ~12 cobblestone 0  
fill ~34 ~0 ~13 ~34 ~1 ~13 cobblestone 0 
setblock ~34 ~0 ~38 stone_stairs 2  
fill ~34 ~0 ~45 ~37 ~0 ~45 grass 0  
fill ~34 ~0 ~46 ~40 ~0 ~46 grass 0  
fill ~34 ~0 ~47 ~40 ~0 ~47 grass 0  
fill ~34 ~0 ~48 ~40 ~0 ~48 grass 0  
fill ~34 ~0 ~49 ~40 ~0 ~49 grass 0  
fill ~36 ~0 ~11 ~40 ~0 ~11 cobblestone 0  
fill ~36 ~0 ~12 ~40 ~0 ~12 cobblestone 0  
fill ~36 ~0 ~13 ~40 ~0 ~13 cobblestone 0  
fill ~36 ~0 ~14 ~40 ~0 ~14 cobblestone 0  
fill ~36 ~0 ~22 ~40 ~0 ~22 cobblestone 0  
fill ~36 ~0 ~23 ~40 ~0 ~23 cobblestone 0  
fill ~36 ~0 ~24 ~40 ~0 ~24 cobblestone 0  
fill ~36 ~0 ~25 ~40 ~0 ~25 cobblestone 0  
fill ~36 ~0 ~26 ~40 ~0 ~26 cobblestone 0  
fill ~37 ~0 ~40 ~39 ~0 ~40 double_stone_slab 0  
fill ~37 ~0 ~41 ~39 ~0 ~41 double_stone_slab 0  
fill ~37 ~0 ~42 ~39 ~0 ~42 double_stone_slab 0 
setblock ~38 ~0 ~-1 grass 0 
setblock ~38 ~0 ~45 cobblestone 0 
setblock ~39 ~0 ~-1 farmland 7 
setblock ~39 ~0 ~0 grass 0  
fill ~39 ~0 ~45 ~40 ~0 ~45 grass 0  
fill ~40 ~0 ~-5 ~40 ~0 ~-3 fence 0  
fill ~40 ~0 ~-1 ~40 ~0 ~4 log 0  
fill ~40 ~0 ~40 ~40 ~1 ~40 cobblestone 0  
fill ~40 ~0 ~41 ~40 ~1 ~41 cobblestone 0  
fill ~40 ~0 ~42 ~40 ~1 ~42 cobblestone 0  
fill ~40 ~0 ~43 ~40 ~1 ~43 cobblestone 0 
setblock ~41 ~0 ~12 stone_stairs 1 
setblock ~41 ~0 ~24 stone_stairs 1  
fill ~41 ~0 ~39 ~44 ~0 ~39 fence 0 
setblock ~43 ~0 ~29 stone_stairs 0  
fill ~44 ~0 ~-5 ~44 ~0 ~2 fence 0  
fill ~44 ~0 ~3 ~47 ~0 ~3 cobblestone 0  
fill ~44 ~0 ~4 ~47 ~0 ~4 cobblestone 0  
fill ~44 ~0 ~5 ~47 ~0 ~5 cobblestone 0  
fill ~44 ~0 ~6 ~47 ~0 ~6 cobblestone 0  
fill ~44 ~0 ~7 ~47 ~0 ~7 cobblestone 0  
fill ~44 ~0 ~11 ~46 ~0 ~11 fence 0  
fill ~44 ~0 ~12 ~44 ~0 ~26 fence 0  
fill ~44 ~0 ~27 ~49 ~0 ~27 cobblestone 0  
fill ~44 ~0 ~28 ~44 ~1 ~28 cobblestone 0  
fill ~44 ~0 ~29 ~44 ~0 ~35 cobblestone 0  
fill ~44 ~0 ~36 ~44 ~0 ~39 fence 0 
setblock ~45 ~0 ~8 stone_stairs 3  
fill ~45 ~0 ~28 ~48 ~0 ~28 planks 0  
fill ~45 ~0 ~29 ~48 ~0 ~29 planks 0  
fill ~45 ~0 ~30 ~53 ~0 ~30 planks 0  
fill ~45 ~0 ~31 ~53 ~0 ~31 planks 0  
fill ~45 ~0 ~32 ~53 ~0 ~32 planks 0  
fill ~45 ~0 ~33 ~53 ~0 ~33 planks 0  
fill ~45 ~0 ~34 ~53 ~0 ~34 planks 0  
fill ~45 ~0 ~35 ~54 ~0 ~35 cobblestone 0  
fill ~47 ~0 ~11 ~51 ~0 ~11 grass 0  
fill ~47 ~0 ~12 ~51 ~0 ~12 grass 0  
fill ~47 ~0 ~13 ~51 ~0 ~13 grass 0  
fill ~47 ~0 ~14 ~51 ~0 ~14 grass 0  
fill ~47 ~0 ~15 ~51 ~0 ~15 grass 0  
fill ~47 ~0 ~16 ~51 ~0 ~16 grass 0  
fill ~47 ~0 ~17 ~51 ~0 ~17 grass 0  
fill ~48 ~0 ~7 ~53 ~0 ~7 fence 0  
fill ~49 ~0 ~28 ~49 ~1 ~28 cobblestone 0  
fill ~49 ~0 ~29 ~54 ~0 ~29 cobblestone 0  
fill ~52 ~0 ~11 ~57 ~0 ~11 cobblestone 0  
fill ~52 ~0 ~12 ~52 ~1 ~12 cobblestone 0  
fill ~52 ~0 ~13 ~52 ~0 ~19 cobblestone 0  
fill ~53 ~0 ~12 ~53 ~0 ~18 planks 0  
fill ~53 ~0 ~19 ~57 ~0 ~19 cobblestone 0  
fill ~54 ~0 ~3 ~58 ~0 ~3 cobblestone 0  
fill ~54 ~0 ~4 ~58 ~0 ~4 cobblestone 0  
fill ~54 ~0 ~5 ~58 ~0 ~5 cobblestone 0  
fill ~54 ~0 ~6 ~58 ~0 ~6 cobblestone 0  
fill ~54 ~0 ~7 ~58 ~0 ~7 cobblestone 0  
fill ~54 ~0 ~12 ~56 ~0 ~12 double_stone_slab 0  
fill ~54 ~0 ~13 ~56 ~0 ~13 double_stone_slab 0  
fill ~54 ~0 ~14 ~56 ~0 ~14 double_stone_slab 0  
fill ~54 ~0 ~15 ~56 ~0 ~15 planks 0  
fill ~54 ~0 ~16 ~56 ~0 ~16 planks 0  
fill ~54 ~0 ~17 ~56 ~0 ~17 planks 0  
fill ~54 ~0 ~18 ~56 ~0 ~18 planks 0  
fill ~54 ~0 ~30 ~54 ~3 ~30 cobblestone 0  
fill ~54 ~0 ~31 ~54 ~3 ~31 cobblestone 0  
fill ~54 ~0 ~32 ~54 ~3 ~32 cobblestone 0  
fill ~54 ~0 ~33 ~54 ~3 ~33 cobblestone 0  
fill ~54 ~0 ~34 ~54 ~3 ~34 cobblestone 0 
setblock ~56 ~0 ~8 stone_stairs 3  
fill ~57 ~0 ~12 ~57 ~1 ~12 cobblestone 0  
fill ~57 ~0 ~13 ~57 ~1 ~13 cobblestone 0  
fill ~57 ~0 ~14 ~57 ~1 ~14 cobblestone 0  
fill ~57 ~0 ~15 ~57 ~1 ~15 cobblestone 0  
fill ~57 ~0 ~16 ~57 ~1 ~16 cobblestone 0  
fill ~57 ~0 ~17 ~57 ~0 ~19 cobblestone 0  
fill ~57 ~0 ~20 ~61 ~0 ~20 fence 0 
setblock ~58 ~0 ~17 stone_stairs 1  
fill ~59 ~0 ~7 ~61 ~0 ~7 fence 0  
fill ~61 ~0 ~11 ~61 ~0 ~11 fence 0  
fill ~61 ~0 ~12 ~61 ~0 ~20 fence 0  
fill ~-5 ~1 ~22 ~5 ~1 ~22 cobblestone 0  
fill ~-5 ~1 ~28 ~0 ~1 ~28 cobblestone 0  
fill ~-3 ~1 ~36 ~-1 ~1 ~36 cobblestone 0  
fill ~-3 ~1 ~37 ~-1 ~1 ~37 cobblestone 0  
fill ~-3 ~1 ~38 ~-1 ~1 ~38 cobblestone 0  
fill ~-2 ~1 ~35 ~4 ~1 ~35 cobblestone 0  
fill ~-2 ~1 ~39 ~4 ~1 ~39 cobblestone 0  
fill ~0 ~1 ~10 ~5 ~1 ~10 cobblestone 0  
fill ~0 ~1 ~11 ~0 ~0 ~11 cobblestone 0  
fill ~0 ~1 ~12 ~0 ~0 ~12 cobblestone 0  
fill ~0 ~1 ~13 ~0 ~0 ~13 cobblestone 0  
fill ~0 ~1 ~14 ~0 ~0 ~14 cobblestone 0  
fill ~0 ~1 ~15 ~0 ~0 ~15 cobblestone 0  
fill ~0 ~1 ~16 ~0 ~0 ~16 cobblestone 0  
fill ~0 ~1 ~17 ~0 ~0 ~17 cobblestone 0  
fill ~0 ~1 ~18 ~5 ~1 ~18 cobblestone 0  
fill ~0 ~1 ~30 ~5 ~1 ~30 cobblestone 0 
setblock ~0 ~1 ~36 stone_stairs 1 
setblock ~0 ~1 ~38 stone_stairs 1  
fill ~1 ~1 ~13 ~1 ~1 ~16 oak_stairs 1 
setblock ~1 ~1 ~17 planks 0 
setblock ~2 ~1 ~14 fence 0 
setblock ~2 ~1 ~16 fence 0 
setblock ~2 ~1 ~17 oak_stairs 2  
fill ~2 ~1 ~36 ~2 ~9 ~36 ladder 3 
setblock ~4 ~1 ~17 crafting_table 0 
setblock ~5 ~1 ~11 cobblestone 0 
setblock ~5 ~1 ~12 wooden_door 2  
fill ~5 ~1 ~13 ~5 ~1 ~18 cobblestone 0 
setblock ~5 ~1 ~28 wooden_door 2 
setblock ~5 ~1 ~29 cobblestone 0  
fill ~5 ~1 ~36 ~5 ~10 ~36 cobblestone 0 
setblock ~5 ~1 ~37 wooden_door 2  
fill ~5 ~1 ~38 ~5 ~10 ~38 cobblestone 0  
fill ~7 ~1 ~1 ~7 ~3 ~1 log 0  
fill ~7 ~1 ~2 ~7 ~3 ~2 planks 0  
fill ~7 ~1 ~3 ~7 ~1 ~4 planks 0  
fill ~7 ~1 ~5 ~7 ~3 ~5 log 0  
fill ~8 ~1 ~1 ~9 ~1 ~1 planks 0  
fill ~8 ~1 ~5 ~8 ~3 ~5 planks 0 
setblock ~9 ~1 ~5 wooden_door 3  
fill ~10 ~1 ~1 ~10 ~3 ~1 log 0  
fill ~10 ~1 ~2 ~10 ~3 ~2 planks 0  
fill ~10 ~1 ~3 ~10 ~1 ~4 planks 0  
fill ~10 ~1 ~5 ~10 ~3 ~5 log 0  
fill ~11 ~1 ~39 ~11 ~4 ~39 log 0  
fill ~11 ~1 ~40 ~11 ~3 ~40 planks 0  
fill ~11 ~1 ~41 ~11 ~1 ~44 planks 0  
fill ~11 ~1 ~45 ~11 ~4 ~45 log 0  
fill ~12 ~1 ~23 ~12 ~3 ~23 cobblestone 0  
fill ~12 ~1 ~24 ~12 ~3 ~24 planks 0  
fill ~12 ~1 ~25 ~12 ~1 ~26 planks 0  
fill ~12 ~1 ~27 ~12 ~3 ~27 cobblestone 0  
fill ~12 ~1 ~39 ~13 ~1 ~39 planks 0 
setblock ~12 ~1 ~43 oak_stairs 1  
fill ~12 ~1 ~44 ~12 ~1 ~45 planks 0  
fill ~13 ~1 ~1 ~13 ~3 ~1 cobblestone 0  
fill ~13 ~1 ~2 ~13 ~3 ~2 planks 0  
fill ~13 ~1 ~3 ~13 ~1 ~4 planks 0  
fill ~13 ~1 ~5 ~13 ~3 ~5 cobblestone 0  
fill ~13 ~1 ~23 ~13 ~3 ~23 planks 0  
fill ~13 ~1 ~27 ~15 ~1 ~27 planks 0 
setblock ~13 ~1 ~43 fence 0 
setblock ~13 ~1 ~44 oak_stairs 2  
fill ~13 ~1 ~45 ~16 ~1 ~45 planks 0  
fill ~14 ~1 ~1 ~16 ~1 ~1 planks 0  
fill ~14 ~1 ~2 ~14 ~4 ~2 ladder 3  
fill ~14 ~1 ~5 ~14 ~3 ~5 planks 0 
setblock ~14 ~1 ~23 wooden_door 1  
fill ~14 ~1 ~39 ~14 ~4 ~39 log 0 
setblock ~14 ~1 ~40 wooden_door 2  
fill ~14 ~1 ~41 ~14 ~3 ~41 planks 0 
setblock ~15 ~1 ~5 wooden_door 3  
fill ~15 ~1 ~23 ~15 ~3 ~23 planks 0  
fill ~15 ~1 ~26 ~15 ~3 ~26 ladder 2  
fill ~15 ~1 ~42 ~16 ~1 ~42 planks 0  
fill ~16 ~1 ~5 ~16 ~3 ~5 planks 0  
fill ~16 ~1 ~12 ~16 ~3 ~12 log 0  
fill ~16 ~1 ~13 ~16 ~3 ~13 planks 0  
fill ~16 ~1 ~14 ~16 ~3 ~14 planks 0  
fill ~16 ~1 ~15 ~16 ~3 ~15 log 0  
fill ~16 ~1 ~23 ~16 ~3 ~23 cobblestone 0  
fill ~16 ~1 ~24 ~16 ~3 ~24 planks 0  
fill ~16 ~1 ~25 ~16 ~1 ~26 planks 0  
fill ~16 ~1 ~27 ~16 ~3 ~27 cobblestone 0  
fill ~16 ~1 ~39 ~16 ~3 ~39 fence 0 
setblock ~16 ~1 ~41 anvil 3  
fill ~17 ~1 ~1 ~17 ~3 ~1 cobblestone 0  
fill ~17 ~1 ~2 ~17 ~3 ~2 planks 0  
fill ~17 ~1 ~3 ~17 ~1 ~4 planks 0  
fill ~17 ~1 ~5 ~17 ~3 ~5 cobblestone 0  
fill ~17 ~1 ~12 ~19 ~1 ~12 planks 0  
fill ~17 ~1 ~15 ~19 ~1 ~15 planks 0  
fill ~17 ~1 ~42 ~17 ~1 ~45 cobblestone 0  
fill ~18 ~1 ~43 ~20 ~1 ~43 cobblestone 0  
fill ~18 ~1 ~44 ~19 ~1 ~44 lava 0  
fill ~18 ~1 ~45 ~20 ~1 ~45 cobblestone 0 
setblock ~19 ~1 ~40 double_stone_slab 0  
fill ~20 ~1 ~12 ~20 ~3 ~12 log 0 
setblock ~20 ~1 ~13 wooden_door 2  
summon Villager ~23.7196946732 ~0.0 ~11.1962537224 
summon Villager ~40.9250000119 ~0.0 ~-2.50067884967 
summon Villager ~28.5000015632 ~1.5 ~12.9250000119 
summon Villager ~37.7029108414 ~1.0 ~13.3160209288 
summon Bat ~52.6254299953 ~2.10000002384 ~29.8625000007 
summon Bat ~53.75 ~4.10000002384 ~33.2669581976 
summon Bat ~46.25 ~4.10000002384 ~28.5577213795 
summon Bat ~49.4027025068 ~3.10000002384 ~30.25 
summon Bat ~46.4015012824 ~2.10000002384 ~27.8125 
summon Bat ~45.25 ~3.10000002384 ~28.25  
fill ~20 ~1 ~14 ~20 ~3 ~14 planks 0  
fill ~20 ~1 ~15 ~20 ~3 ~15 log 0  
fill ~20 ~1 ~19 ~23 ~1 ~19 cobblestone 0  
fill ~20 ~1 ~22 ~23 ~1 ~22 cobblestone 0  
fill ~20 ~1 ~39 ~20 ~3 ~39 fence 0 
setblock ~20 ~1 ~44 cobblestone 0  
fill ~21 ~1 ~-5 ~27 ~1 ~-5 fence 0  
fill ~21 ~1 ~-4 ~21 ~1 ~-1 fence 0  
fill ~21 ~1 ~0 ~22 ~1 ~0 cobblestone 0  
fill ~21 ~1 ~5 ~26 ~1 ~5 cobblestone 0  
fill ~21 ~1 ~20 ~22 ~1 ~20 water 0  
fill ~21 ~1 ~21 ~22 ~1 ~21 water 0  
fill ~22 ~1 ~30 ~30 ~1 ~30 cobblestone 0  
fill ~22 ~1 ~31 ~22 ~0 ~31 cobblestone 0  
fill ~22 ~1 ~32 ~22 ~0 ~32 cobblestone 0  
fill ~22 ~1 ~33 ~22 ~0 ~33 cobblestone 0  
fill ~22 ~1 ~34 ~22 ~0 ~34 cobblestone 0  
fill ~22 ~1 ~35 ~27 ~1 ~35 cobblestone 0 
setblock ~23 ~1 ~0 wooden_door 1  
fill ~23 ~1 ~3 ~23 ~1 ~4 double_stone_slab 0 
setblock ~23 ~1 ~31 planks 0 
setblock ~23 ~1 ~32 oak_stairs 1 
setblock ~23 ~1 ~34 crafting_table 0  
fill ~24 ~1 ~0 ~29 ~1 ~0 cobblestone 0  
fill ~24 ~1 ~31 ~27 ~1 ~31 oak_stairs 3 
setblock ~24 ~1 ~32 fence 0  
fill ~26 ~1 ~9 ~27 ~1 ~9 cobblestone 0  
fill ~26 ~1 ~14 ~31 ~1 ~14 cobblestone 0 
setblock ~26 ~1 ~32 fence 0  
fill ~27 ~1 ~-4 ~27 ~1 ~-1 fence 0 
setblock ~27 ~1 ~1 oak_stairs 3 
setblock ~27 ~1 ~2 fence 0 
setblock ~27 ~1 ~5 wooden_door 3 
setblock ~27 ~1 ~12 oak_stairs 1  
fill ~27 ~1 ~13 ~27 ~0 ~13 planks 0 
setblock ~28 ~1 ~1 planks 0 
setblock ~28 ~1 ~2 oak_stairs 0  
fill ~28 ~1 ~5 ~29 ~1 ~5 cobblestone 0 
setblock ~28 ~1 ~9 wooden_door 1 
setblock ~28 ~1 ~12 fence 0 
setblock ~28 ~1 ~13 oak_stairs 2  
fill ~28 ~1 ~15 ~28 ~1 ~19 fence 0 
setblock ~28 ~1 ~35 wooden_door 7  
fill ~29 ~1 ~9 ~34 ~1 ~9 cobblestone 0  
fill ~29 ~1 ~19 ~34 ~1 ~19 fence 0  
fill ~29 ~1 ~35 ~30 ~1 ~35 cobblestone 0  
fill ~30 ~1 ~31 ~30 ~1 ~35 cobblestone 0  
fill ~32 ~1 ~10 ~32 ~1 ~11 double_stone_slab 0 
setblock ~32 ~1 ~14 wooden_door 3  
fill ~32 ~1 ~39 ~33 ~1 ~39 cobblestone 0  
fill ~32 ~1 ~44 ~37 ~1 ~44 cobblestone 0  
fill ~33 ~1 ~-1 ~37 ~1 ~-1 wheat 7  
fill ~33 ~1 ~0 ~38 ~1 ~0 wheat 7  
fill ~33 ~1 ~2 ~39 ~1 ~2 wheat 7  
fill ~33 ~1 ~3 ~39 ~1 ~3 wheat 7  
fill ~33 ~1 ~14 ~34 ~1 ~14 cobblestone 0 
setblock ~33 ~1 ~42 oak_stairs 1  
fill ~33 ~1 ~43 ~33 ~0 ~43 planks 0  
fill ~34 ~1 ~15 ~34 ~1 ~19 fence 0 
setblock ~34 ~1 ~39 wooden_door 1 
setblock ~34 ~1 ~42 fence 0 
setblock ~34 ~1 ~43 oak_stairs 2  
fill ~34 ~1 ~45 ~34 ~1 ~49 fence 0  
fill ~35 ~1 ~39 ~40 ~1 ~39 cobblestone 0  
fill ~35 ~1 ~49 ~40 ~1 ~49 fence 0  
fill ~36 ~1 ~11 ~36 ~3 ~11 log 0  
fill ~36 ~1 ~12 ~36 ~3 ~12 planks 0  
fill ~36 ~1 ~13 ~36 ~3 ~13 planks 0  
fill ~36 ~1 ~14 ~36 ~3 ~14 log 0  
fill ~36 ~1 ~22 ~36 ~3 ~22 cobblestone 0  
fill ~36 ~1 ~23 ~36 ~3 ~23 planks 0  
fill ~36 ~1 ~24 ~36 ~1 ~25 planks 0  
fill ~36 ~1 ~26 ~36 ~3 ~26 cobblestone 0  
fill ~37 ~1 ~11 ~39 ~1 ~11 planks 0  
fill ~37 ~1 ~14 ~39 ~1 ~14 planks 0  
fill ~37 ~1 ~22 ~39 ~1 ~22 planks 0  
fill ~37 ~1 ~26 ~39 ~1 ~26 planks 0  
fill ~38 ~1 ~40 ~38 ~1 ~41 double_stone_slab 0 
setblock ~38 ~1 ~44 wooden_door 3 
setblock ~39 ~1 ~-1 wheat 7  
fill ~39 ~1 ~44 ~40 ~1 ~44 cobblestone 0  
fill ~40 ~1 ~11 ~40 ~3 ~11 log 0 
setblock ~40 ~1 ~12 wooden_door 2  
fill ~40 ~1 ~13 ~40 ~3 ~13 planks 0  
fill ~40 ~1 ~14 ~40 ~3 ~14 log 0  
fill ~40 ~1 ~22 ~40 ~3 ~22 cobblestone 0  
fill ~40 ~1 ~23 ~40 ~3 ~23 planks 0 
setblock ~40 ~1 ~24 wooden_door 2  
fill ~40 ~1 ~25 ~40 ~3 ~25 planks 0  
fill ~40 ~1 ~26 ~40 ~3 ~26 cobblestone 0  
fill ~40 ~1 ~45 ~40 ~1 ~49 fence 0  
fill ~44 ~1 ~3 ~44 ~3 ~3 log 0  
fill ~44 ~1 ~4 ~44 ~3 ~4 planks 0  
fill ~44 ~1 ~5 ~44 ~1 ~6 planks 0  
fill ~44 ~1 ~7 ~44 ~3 ~7 log 0  
fill ~44 ~1 ~27 ~49 ~1 ~27 cobblestone 0 
setblock ~44 ~1 ~29 wooden_door 0  
fill ~44 ~1 ~30 ~44 ~1 ~35 cobblestone 0  
fill ~45 ~1 ~3 ~46 ~1 ~3 planks 0 
setblock ~45 ~1 ~7 wooden_door 3  
fill ~45 ~1 ~35 ~54 ~1 ~35 cobblestone 0  
fill ~46 ~1 ~7 ~46 ~3 ~7 planks 0  
fill ~47 ~1 ~3 ~47 ~3 ~3 log 0  
fill ~47 ~1 ~4 ~47 ~3 ~4 planks 0  
fill ~47 ~1 ~5 ~47 ~1 ~6 planks 0  
fill ~47 ~1 ~7 ~47 ~3 ~7 log 0  
fill ~47 ~1 ~11 ~51 ~1 ~11 fence 0  
fill ~47 ~1 ~12 ~47 ~1 ~17 fence 0  
fill ~48 ~1 ~17 ~51 ~1 ~17 fence 0  
fill ~49 ~1 ~29 ~54 ~1 ~29 cobblestone 0  
fill ~52 ~1 ~11 ~57 ~1 ~11 cobblestone 0 
setblock ~52 ~1 ~13 wooden_door 0  
fill ~52 ~1 ~14 ~52 ~1 ~19 cobblestone 0 
setblock ~53 ~1 ~17 oak_stairs 1 
setblock ~53 ~1 ~18 planks 0  
fill ~53 ~1 ~19 ~57 ~1 ~19 cobblestone 0  
fill ~54 ~1 ~3 ~54 ~3 ~3 cobblestone 0  
fill ~54 ~1 ~4 ~54 ~3 ~4 planks 0  
fill ~54 ~1 ~5 ~54 ~1 ~6 planks 0  
fill ~54 ~1 ~7 ~54 ~3 ~7 cobblestone 0 
setblock ~54 ~1 ~17 fence 0 
setblock ~54 ~1 ~18 oak_stairs 2  
fill ~55 ~1 ~3 ~57 ~1 ~3 planks 0  
fill ~55 ~1 ~7 ~55 ~3 ~7 planks 0  
fill ~55 ~1 ~13 ~56 ~1 ~13 double_stone_slab 0 
setblock ~56 ~1 ~7 wooden_door 3  
fill ~57 ~1 ~4 ~57 ~4 ~4 ladder 3  
fill ~57 ~1 ~7 ~57 ~3 ~7 planks 0 
setblock ~57 ~1 ~17 wooden_door 2 
setblock ~57 ~1 ~18 cobblestone 0  
fill ~58 ~1 ~3 ~58 ~3 ~3 cobblestone 0  
fill ~58 ~1 ~4 ~58 ~3 ~4 planks 0  
fill ~58 ~1 ~5 ~58 ~1 ~6 planks 0  
fill ~58 ~1 ~7 ~58 ~3 ~7 cobblestone 0  
fill ~-5 ~2 ~22 ~-5 ~3 ~22 cobblestone 0  
fill ~-5 ~2 ~28 ~-5 ~3 ~28 cobblestone 0 
setblock ~-4 ~2 ~22 log 0 
setblock ~-4 ~2 ~28 log 0  
fill ~-3 ~2 ~22 ~-2 ~2 ~22 glass_pane 0  
fill ~-3 ~2 ~28 ~-2 ~2 ~28 glass_pane 0  
fill ~-3 ~2 ~36 ~-3 ~4 ~36 cobblestone 0  
fill ~-3 ~2 ~37 ~-3 ~0 ~37 cobblestone 0  
fill ~-3 ~2 ~38 ~-3 ~4 ~38 cobblestone 0  
fill ~-2 ~2 ~35 ~2 ~2 ~35 cobblestone 0 
setblock ~-2 ~2 ~36 stone_stairs 3 
setblock ~-2 ~2 ~38 stone_stairs 2  
fill ~-2 ~2 ~39 ~2 ~2 ~39 cobblestone 0 
setblock ~-1 ~2 ~22 log 0 
setblock ~-1 ~2 ~28 log 0  
fill ~0 ~2 ~10 ~0 ~5 ~10 cobblestone 0  
fill ~0 ~2 ~11 ~0 ~5 ~11 planks 0  
fill ~0 ~2 ~12 ~0 ~2 ~13 glass_pane 0  
fill ~0 ~2 ~14 ~0 ~5 ~14 planks 0  
fill ~0 ~2 ~15 ~0 ~2 ~16 glass_pane 0  
fill ~0 ~2 ~17 ~0 ~5 ~17 planks 0  
fill ~0 ~2 ~18 ~0 ~5 ~18 cobblestone 0  
fill ~0 ~2 ~22 ~0 ~4 ~22 planks 0  
fill ~0 ~2 ~28 ~0 ~4 ~28 planks 0  
fill ~0 ~2 ~29 ~0 ~3 ~29 planks 0  
fill ~0 ~2 ~30 ~0 ~3 ~30 cobblestone 0  
fill ~1 ~2 ~10 ~1 ~4 ~10 planks 0  
fill ~1 ~2 ~18 ~1 ~4 ~18 planks 0 
setblock ~1 ~2 ~22 log 0 
setblock ~1 ~2 ~30 log 0  
fill ~2 ~2 ~10 ~3 ~2 ~10 glass_pane 0 
setblock ~2 ~2 ~14 wooden_pressure_plate 0 
setblock ~2 ~2 ~16 wooden_pressure_plate 0  
fill ~2 ~2 ~18 ~3 ~2 ~18 glass_pane 0  
fill ~2 ~2 ~22 ~3 ~2 ~22 glass_pane 0  
fill ~2 ~2 ~30 ~3 ~2 ~30 glass_pane 0  
fill ~3 ~2 ~35 ~3 ~3 ~35 glass_pane 0  
fill ~3 ~2 ~39 ~3 ~3 ~39 glass_pane 0  
fill ~4 ~2 ~10 ~4 ~4 ~10 planks 0  
fill ~4 ~2 ~18 ~4 ~4 ~18 planks 0 
setblock ~4 ~2 ~22 log 0 
setblock ~4 ~2 ~30 log 0  
fill ~4 ~2 ~35 ~4 ~10 ~35 cobblestone 0  
fill ~4 ~2 ~39 ~4 ~10 ~39 cobblestone 0  
fill ~5 ~2 ~10 ~5 ~5 ~10 cobblestone 0  
fill ~5 ~2 ~11 ~5 ~5 ~11 planks 0 
setblock ~5 ~2 ~12 wooden_door 8  
fill ~5 ~2 ~13 ~5 ~5 ~13 planks 0  
fill ~5 ~2 ~14 ~5 ~3 ~14 glass_pane 0  
fill ~5 ~2 ~15 ~5 ~3 ~15 glass_pane 0  
fill ~5 ~2 ~16 ~5 ~3 ~16 glass_pane 0  
fill ~5 ~2 ~17 ~5 ~5 ~17 planks 0  
fill ~5 ~2 ~18 ~5 ~5 ~18 cobblestone 0  
fill ~5 ~2 ~22 ~5 ~3 ~22 cobblestone 0  
fill ~5 ~2 ~23 ~5 ~3 ~23 planks 0 
setblock ~5 ~2 ~24 log 0 
setblock ~5 ~2 ~25 glass_pane 0 
setblock ~5 ~2 ~26 log 0  
fill ~5 ~2 ~27 ~5 ~3 ~27 planks 0 
setblock ~5 ~2 ~28 wooden_door 8  
fill ~5 ~2 ~29 ~5 ~3 ~29 planks 0  
fill ~5 ~2 ~30 ~5 ~3 ~30 cobblestone 0 
setblock ~5 ~2 ~37 wooden_door 8 
setblock ~7 ~2 ~3 glass_pane 0  
fill ~7 ~2 ~4 ~7 ~3 ~4 planks 0  
fill ~8 ~2 ~1 ~9 ~2 ~1 planks 0 
setblock ~9 ~2 ~5 wooden_door 8 
setblock ~10 ~2 ~3 glass_pane 0  
fill ~10 ~2 ~4 ~10 ~3 ~4 planks 0 
setblock ~11 ~2 ~41 glass_pane 0  
fill ~11 ~2 ~42 ~11 ~3 ~42 planks 0 
setblock ~11 ~2 ~43 glass_pane 0  
fill ~11 ~2 ~44 ~11 ~3 ~44 planks 0 
setblock ~12 ~2 ~25 glass_pane 0  
fill ~12 ~2 ~26 ~12 ~3 ~26 planks 0  
fill ~12 ~2 ~39 ~13 ~2 ~39 planks 0  
fill ~12 ~2 ~45 ~12 ~3 ~45 planks 0 
setblock ~13 ~2 ~3 glass_pane 0  
fill ~13 ~2 ~4 ~13 ~3 ~4 planks 0  
fill ~13 ~2 ~27 ~13 ~3 ~27 planks 0 
setblock ~13 ~2 ~43 wooden_pressure_plate 0 
setblock ~13 ~2 ~45 glass_pane 0  
fill ~14 ~2 ~1 ~14 ~3 ~1 planks 0 
setblock ~14 ~2 ~23 wooden_door 8 
setblock ~14 ~2 ~27 glass_pane 0 
setblock ~14 ~2 ~40 wooden_door 8  
fill ~14 ~2 ~45 ~14 ~3 ~45 planks 0 
setblock ~15 ~2 ~1 glass_pane 0 
setblock ~15 ~2 ~5 wooden_door 8  
fill ~15 ~2 ~27 ~15 ~3 ~27 planks 0  
fill ~15 ~2 ~42 ~16 ~2 ~42 planks 0 
setblock ~15 ~2 ~45 glass_pane 0  
fill ~16 ~2 ~1 ~16 ~3 ~1 planks 0 
setblock ~16 ~2 ~25 glass_pane 0  
fill ~16 ~2 ~26 ~16 ~3 ~26 planks 0  
fill ~16 ~2 ~45 ~16 ~3 ~45 planks 0 
setblock ~17 ~2 ~3 glass_pane 0  
fill ~17 ~2 ~4 ~17 ~3 ~4 planks 0  
fill ~17 ~2 ~12 ~17 ~3 ~12 planks 0  
fill ~17 ~2 ~15 ~17 ~3 ~15 planks 0  
fill ~17 ~2 ~43 ~17 ~4 ~43 cobblestone 0  
fill ~17 ~2 ~44 ~17 ~4 ~44 cobblestone 0  
fill ~17 ~2 ~45 ~20 ~2 ~45 cobblestone 0 
setblock ~18 ~2 ~12 glass_pane 0 
setblock ~18 ~2 ~15 glass_pane 0  
fill ~19 ~2 ~12 ~19 ~3 ~12 planks 0  
fill ~19 ~2 ~15 ~19 ~3 ~15 planks 0 
setblock ~20 ~2 ~13 wooden_door 8  
fill ~20 ~2 ~19 ~20 ~3 ~19 fence 0  
fill ~20 ~2 ~22 ~20 ~3 ~22 fence 0  
fill ~20 ~2 ~43 ~20 ~2 ~44 iron_bars 0  
fill ~21 ~2 ~0 ~21 ~3 ~0 cobblestone 0 
setblock ~21 ~2 ~1 log 0  
fill ~21 ~2 ~2 ~21 ~2 ~3 glass_pane 0 
setblock ~21 ~2 ~4 log 0  
fill ~21 ~2 ~5 ~21 ~3 ~5 cobblestone 0  
fill ~22 ~2 ~0 ~22 ~3 ~0 planks 0  
fill ~22 ~2 ~5 ~23 ~2 ~5 planks 0  
fill ~22 ~2 ~30 ~22 ~5 ~30 cobblestone 0  
fill ~22 ~2 ~31 ~22 ~4 ~31 planks 0  
fill ~22 ~2 ~32 ~22 ~3 ~32 glass_pane 0  
fill ~22 ~2 ~33 ~22 ~3 ~33 glass_pane 0  
fill ~22 ~2 ~34 ~22 ~4 ~34 planks 0  
fill ~22 ~2 ~35 ~22 ~5 ~35 cobblestone 0 
setblock ~23 ~2 ~0 wooden_door 8  
fill ~23 ~2 ~19 ~23 ~3 ~19 fence 0  
fill ~23 ~2 ~22 ~23 ~3 ~22 fence 0  
fill ~23 ~2 ~30 ~23 ~5 ~30 planks 0  
fill ~23 ~2 ~35 ~23 ~5 ~35 planks 0  
fill ~24 ~2 ~0 ~25 ~2 ~0 planks 0 
setblock ~24 ~2 ~5 glass_pane 0  
fill ~24 ~2 ~30 ~25 ~2 ~30 glass_pane 0 
setblock ~24 ~2 ~32 wooden_pressure_plate 0  
fill ~24 ~2 ~35 ~26 ~2 ~35 glass_pane 0  
fill ~25 ~2 ~5 ~26 ~2 ~5 planks 0  
fill ~26 ~2 ~0 ~27 ~2 ~0 glass_pane 0  
fill ~26 ~2 ~9 ~26 ~3 ~9 cobblestone 0 
setblock ~26 ~2 ~10 log 0  
fill ~26 ~2 ~11 ~26 ~2 ~12 glass_pane 0 
setblock ~26 ~2 ~13 log 0  
fill ~26 ~2 ~14 ~26 ~3 ~14 cobblestone 0  
fill ~26 ~2 ~30 ~26 ~5 ~30 planks 0 
setblock ~26 ~2 ~32 wooden_pressure_plate 0 
setblock ~27 ~2 ~2 wooden_pressure_plate 0 
setblock ~27 ~2 ~5 wooden_door 8  
fill ~27 ~2 ~9 ~27 ~3 ~9 planks 0  
fill ~27 ~2 ~14 ~27 ~3 ~14 planks 0  
fill ~27 ~2 ~30 ~28 ~2 ~30 glass_pane 0  
fill ~27 ~2 ~35 ~27 ~5 ~35 planks 0  
fill ~28 ~2 ~0 ~28 ~3 ~0 planks 0  
fill ~28 ~2 ~5 ~28 ~3 ~5 planks 0 
setblock ~28 ~2 ~9 wooden_door 8 
setblock ~28 ~2 ~12 wooden_pressure_plate 1  
fill ~28 ~2 ~14 ~29 ~2 ~14 glass_pane 0 
setblock ~28 ~2 ~35 wooden_door 8  
fill ~29 ~2 ~0 ~29 ~3 ~0 cobblestone 0 
setblock ~29 ~2 ~1 log 0  
fill ~29 ~2 ~2 ~29 ~2 ~3 glass_pane 0 
setblock ~29 ~2 ~4 log 0  
fill ~29 ~2 ~5 ~29 ~3 ~5 cobblestone 0  
fill ~29 ~2 ~9 ~30 ~2 ~9 planks 0  
fill ~29 ~2 ~30 ~29 ~5 ~30 planks 0  
fill ~29 ~2 ~35 ~29 ~5 ~35 planks 0  
fill ~30 ~2 ~14 ~31 ~2 ~14 planks 0  
fill ~30 ~2 ~30 ~30 ~5 ~30 cobblestone 0  
fill ~30 ~2 ~31 ~30 ~4 ~31 planks 0  
fill ~30 ~2 ~32 ~30 ~3 ~32 glass_pane 0  
fill ~30 ~2 ~33 ~30 ~3 ~33 glass_pane 0  
fill ~30 ~2 ~34 ~30 ~4 ~34 planks 0  
fill ~30 ~2 ~35 ~30 ~5 ~35 cobblestone 0 
setblock ~31 ~2 ~9 glass_pane 0  
fill ~32 ~2 ~9 ~33 ~2 ~9 planks 0 
setblock ~32 ~2 ~14 wooden_door 8  
fill ~32 ~2 ~39 ~32 ~3 ~39 cobblestone 0 
setblock ~32 ~2 ~40 log 0  
fill ~32 ~2 ~41 ~32 ~2 ~42 glass_pane 0 
setblock ~32 ~2 ~43 log 0  
fill ~32 ~2 ~44 ~32 ~3 ~44 cobblestone 0  
fill ~33 ~2 ~14 ~33 ~3 ~14 planks 0  
fill ~33 ~2 ~39 ~33 ~3 ~39 planks 0  
fill ~33 ~2 ~44 ~33 ~3 ~44 planks 0  
fill ~34 ~2 ~9 ~34 ~3 ~9 cobblestone 0 
setblock ~34 ~2 ~10 log 0  
fill ~34 ~2 ~11 ~34 ~2 ~12 glass_pane 0 
setblock ~34 ~2 ~13 log 0  
fill ~34 ~2 ~14 ~34 ~3 ~14 cobblestone 0 
setblock ~34 ~2 ~39 wooden_door 8 
setblock ~34 ~2 ~42 wooden_pressure_plate 0  
fill ~34 ~2 ~44 ~35 ~2 ~44 glass_pane 0  
fill ~35 ~2 ~39 ~36 ~2 ~39 planks 0 
setblock ~36 ~2 ~24 glass_pane 0  
fill ~36 ~2 ~25 ~36 ~3 ~25 planks 0  
fill ~36 ~2 ~44 ~37 ~2 ~44 planks 0  
fill ~37 ~2 ~11 ~37 ~3 ~11 planks 0  
fill ~37 ~2 ~14 ~37 ~3 ~14 planks 0  
fill ~37 ~2 ~22 ~37 ~3 ~22 planks 0  
fill ~37 ~2 ~26 ~37 ~3 ~26 planks 0 
setblock ~37 ~2 ~39 glass_pane 0 
setblock ~38 ~2 ~11 glass_pane 0 
setblock ~38 ~2 ~14 glass_pane 0 
setblock ~38 ~2 ~22 glass_pane 0 
setblock ~38 ~2 ~26 glass_pane 0  
fill ~38 ~2 ~39 ~39 ~2 ~39 planks 0 
setblock ~38 ~2 ~44 wooden_door 8  
fill ~39 ~2 ~11 ~39 ~3 ~11 planks 0  
fill ~39 ~2 ~14 ~39 ~3 ~14 planks 0  
fill ~39 ~2 ~22 ~39 ~3 ~22 planks 0  
fill ~39 ~2 ~26 ~39 ~3 ~26 planks 0  
fill ~39 ~2 ~44 ~39 ~3 ~44 planks 0 
setblock ~40 ~2 ~12 wooden_door 8 
setblock ~40 ~2 ~24 wooden_door 8  
fill ~40 ~2 ~39 ~40 ~3 ~39 cobblestone 0 
setblock ~40 ~2 ~40 log 0  
fill ~40 ~2 ~41 ~40 ~2 ~42 glass_pane 0 
setblock ~40 ~2 ~43 log 0  
fill ~40 ~2 ~44 ~40 ~3 ~44 cobblestone 0 
setblock ~44 ~2 ~5 glass_pane 0  
fill ~44 ~2 ~6 ~44 ~3 ~6 planks 0  
fill ~44 ~2 ~27 ~44 ~3 ~27 cobblestone 0  
fill ~44 ~2 ~28 ~44 ~3 ~28 planks 0 
setblock ~44 ~2 ~29 wooden_door 8  
fill ~44 ~2 ~30 ~44 ~3 ~30 planks 0 
setblock ~44 ~2 ~31 log 0 
setblock ~44 ~2 ~32 glass_pane 0 
setblock ~44 ~2 ~33 log 0  
fill ~44 ~2 ~34 ~44 ~3 ~34 planks 0  
fill ~44 ~2 ~35 ~44 ~3 ~35 cobblestone 0  
fill ~45 ~2 ~3 ~46 ~2 ~3 planks 0 
setblock ~45 ~2 ~7 wooden_door 8 
setblock ~45 ~2 ~27 log 0 
setblock ~45 ~2 ~35 log 0  
fill ~46 ~2 ~27 ~47 ~2 ~27 glass_pane 0  
fill ~46 ~2 ~35 ~47 ~2 ~35 glass_pane 0 
setblock ~47 ~2 ~5 glass_pane 0  
fill ~47 ~2 ~6 ~47 ~3 ~6 planks 0 
setblock ~48 ~2 ~27 log 0 
setblock ~48 ~2 ~35 log 0  
fill ~49 ~2 ~27 ~49 ~3 ~27 cobblestone 0  
fill ~49 ~2 ~28 ~49 ~3 ~28 planks 0  
fill ~49 ~2 ~29 ~49 ~4 ~29 planks 0 
setblock ~49 ~2 ~35 planks 0 
setblock ~50 ~2 ~29 log 0 
setblock ~50 ~2 ~35 log 0  
fill ~51 ~2 ~29 ~52 ~2 ~29 glass_pane 0  
fill ~51 ~2 ~35 ~52 ~2 ~35 glass_pane 0  
fill ~52 ~2 ~11 ~52 ~3 ~11 cobblestone 0  
fill ~52 ~2 ~12 ~52 ~3 ~12 planks 0 
setblock ~52 ~2 ~13 wooden_door 8  
fill ~52 ~2 ~14 ~52 ~3 ~14 planks 0  
fill ~52 ~2 ~15 ~52 ~3 ~15 planks 0  
fill ~52 ~2 ~16 ~52 ~2 ~17 glass_pane 0  
fill ~52 ~2 ~18 ~52 ~3 ~18 planks 0  
fill ~52 ~2 ~19 ~52 ~3 ~19 cobblestone 0 
setblock ~53 ~2 ~11 log 0 
setblock ~53 ~2 ~19 log 0 
setblock ~53 ~2 ~29 log 0 
setblock ~53 ~2 ~35 log 0 
setblock ~54 ~2 ~5 glass_pane 0  
fill ~54 ~2 ~6 ~54 ~3 ~6 planks 0  
fill ~54 ~2 ~11 ~55 ~2 ~11 glass_pane 0 
setblock ~54 ~2 ~17 wooden_pressure_plate 0  
fill ~54 ~2 ~19 ~55 ~2 ~19 glass_pane 0  
fill ~54 ~2 ~29 ~54 ~3 ~29 cobblestone 0  
fill ~54 ~2 ~35 ~54 ~3 ~35 cobblestone 0  
fill ~55 ~2 ~3 ~55 ~3 ~3 planks 0 
setblock ~56 ~2 ~3 glass_pane 0 
setblock ~56 ~2 ~7 wooden_door 8 
setblock ~56 ~2 ~11 log 0 
setblock ~56 ~2 ~19 log 0  
fill ~57 ~2 ~3 ~57 ~3 ~3 planks 0  
fill ~57 ~2 ~11 ~57 ~3 ~11 cobblestone 0  
fill ~57 ~2 ~12 ~57 ~3 ~12 planks 0  
fill ~57 ~2 ~13 ~57 ~3 ~13 planks 0 
setblock ~57 ~2 ~14 glass_pane 0  
fill ~57 ~2 ~15 ~57 ~3 ~15 planks 0  
fill ~57 ~2 ~16 ~57 ~3 ~16 planks 0 
setblock ~57 ~2 ~17 wooden_door 8  
fill ~57 ~2 ~18 ~57 ~3 ~18 planks 0  
fill ~57 ~2 ~19 ~57 ~3 ~19 cobblestone 0 
setblock ~58 ~2 ~5 glass_pane 0  
fill ~58 ~2 ~6 ~58 ~3 ~6 planks 0  
fill ~-4 ~3 ~22 ~4 ~3 ~22 planks 0  
fill ~-4 ~3 ~28 ~-1 ~3 ~28 cobblestone 0 
setblock ~-3 ~3 ~37 glass_pane 0  
fill ~-2 ~3 ~35 ~-2 ~4 ~35 cobblestone 0  
fill ~-2 ~3 ~39 ~-2 ~4 ~39 cobblestone 0 
setblock ~-1 ~3 ~35 glass_pane 0 
setblock ~-1 ~3 ~39 glass_pane 0  
fill ~0 ~3 ~12 ~0 ~5 ~12 planks 0  
fill ~0 ~3 ~13 ~0 ~5 ~13 planks 0  
fill ~0 ~3 ~15 ~0 ~5 ~15 planks 0  
fill ~0 ~3 ~16 ~0 ~5 ~16 planks 0  
fill ~0 ~3 ~35 ~2 ~3 ~35 cobblestone 0  
fill ~0 ~3 ~39 ~2 ~3 ~39 cobblestone 0  
fill ~1 ~3 ~11 ~1 ~3 ~17 bookshelf 0  
fill ~1 ~3 ~30 ~5 ~3 ~30 cobblestone 0  
fill ~2 ~3 ~10 ~3 ~3 ~10 glass_pane 0  
fill ~2 ~3 ~18 ~3 ~3 ~18 glass_pane 0 
setblock ~4 ~3 ~12 torch 2 
setblock ~4 ~3 ~37 torch 2  
fill ~5 ~3 ~12 ~5 ~5 ~12 planks 0  
fill ~5 ~3 ~24 ~5 ~3 ~29 planks 0  
fill ~5 ~3 ~37 ~5 ~5 ~37 cobblestone 0  
fill ~6 ~3 ~22 ~6 ~3 ~30 oak_stairs 1 
setblock ~7 ~3 ~3 planks 0  
fill ~8 ~3 ~1 ~9 ~3 ~1 planks 0 
setblock ~9 ~3 ~4 torch 4 
setblock ~9 ~3 ~5 planks 0 
setblock ~10 ~3 ~3 planks 0 
setblock ~11 ~3 ~41 planks 0 
setblock ~11 ~3 ~43 planks 0 
setblock ~12 ~3 ~25 planks 0  
fill ~12 ~3 ~39 ~13 ~3 ~39 planks 0 
setblock ~13 ~3 ~3 planks 0 
setblock ~13 ~3 ~40 torch 2 
setblock ~13 ~3 ~45 planks 0 
setblock ~14 ~3 ~23 planks 0 
setblock ~14 ~3 ~27 planks 0 
setblock ~14 ~3 ~40 planks 0 
setblock ~15 ~3 ~1 planks 0 
setblock ~15 ~3 ~5 planks 0  
fill ~15 ~3 ~42 ~16 ~3 ~42 planks 0 
setblock ~15 ~3 ~45 planks 0 
setblock ~16 ~3 ~25 planks 0 
setblock ~17 ~3 ~3 planks 0  
fill ~17 ~3 ~45 ~20 ~3 ~45 cobblestone 0 
setblock ~18 ~3 ~12 planks 0 
setblock ~18 ~3 ~15 planks 0  
fill ~18 ~3 ~43 ~20 ~3 ~43 cobblestone 0  
fill ~18 ~3 ~44 ~20 ~3 ~44 cobblestone 0 
setblock ~20 ~3 ~13 planks 0  
fill ~21 ~3 ~-1 ~29 ~3 ~-1 oak_stairs 2  
fill ~21 ~3 ~1 ~21 ~3 ~5 cobblestone 0  
fill ~21 ~3 ~6 ~29 ~3 ~6 oak_stairs 3  
fill ~22 ~3 ~5 ~28 ~3 ~5 planks 0  
fill ~23 ~3 ~0 ~28 ~3 ~0 planks 0 
setblock ~23 ~3 ~1 torch 3  
fill ~23 ~3 ~31 ~29 ~3 ~31 bookshelf 0  
fill ~24 ~3 ~30 ~29 ~3 ~30 planks 0  
fill ~24 ~3 ~35 ~26 ~3 ~35 glass_pane 0  
fill ~26 ~3 ~8 ~34 ~3 ~8 oak_stairs 2  
fill ~26 ~3 ~10 ~26 ~3 ~14 cobblestone 0  
fill ~26 ~3 ~15 ~34 ~3 ~15 oak_stairs 3 
setblock ~27 ~3 ~4 torch 4  
fill ~28 ~3 ~9 ~33 ~3 ~9 planks 0 
setblock ~28 ~3 ~10 torch 3  
fill ~28 ~3 ~14 ~33 ~3 ~14 planks 0 
setblock ~28 ~3 ~34 torch 4  
fill ~28 ~3 ~35 ~28 ~5 ~35 planks 0  
fill ~29 ~3 ~1 ~29 ~3 ~5 cobblestone 0 
setblock ~32 ~3 ~13 torch 4  
fill ~32 ~3 ~38 ~40 ~3 ~38 oak_stairs 2  
fill ~32 ~3 ~40 ~32 ~3 ~44 cobblestone 0  
fill ~32 ~3 ~45 ~40 ~3 ~45 oak_stairs 3  
fill ~34 ~3 ~10 ~34 ~3 ~14 cobblestone 0  
fill ~34 ~3 ~39 ~39 ~3 ~39 planks 0 
setblock ~34 ~3 ~40 torch 3  
fill ~34 ~3 ~44 ~39 ~3 ~44 planks 0 
setblock ~36 ~3 ~24 planks 0 
setblock ~38 ~3 ~11 planks 0 
setblock ~38 ~3 ~14 planks 0 
setblock ~38 ~3 ~22 planks 0 
setblock ~38 ~3 ~26 planks 0 
setblock ~38 ~3 ~43 torch 4 
setblock ~39 ~3 ~12 torch 2 
setblock ~39 ~3 ~24 torch 2 
setblock ~40 ~3 ~12 planks 0 
setblock ~40 ~3 ~24 planks 0  
fill ~40 ~3 ~40 ~40 ~3 ~44 cobblestone 0  
fill ~43 ~3 ~27 ~43 ~3 ~35 oak_stairs 0 
setblock ~44 ~3 ~5 planks 0 
setblock ~44 ~3 ~29 planks 0  
fill ~44 ~3 ~31 ~44 ~3 ~34 planks 0  
fill ~45 ~3 ~3 ~46 ~3 ~3 planks 0 
setblock ~45 ~3 ~7 planks 0  
fill ~45 ~3 ~27 ~49 ~3 ~27 cobblestone 0  
fill ~45 ~3 ~35 ~54 ~3 ~35 cobblestone 0 
setblock ~47 ~3 ~5 planks 0  
fill ~50 ~3 ~29 ~54 ~3 ~29 cobblestone 0  
fill ~51 ~3 ~11 ~51 ~3 ~19 oak_stairs 0 
setblock ~52 ~3 ~13 planks 0  
fill ~52 ~3 ~16 ~52 ~3 ~18 planks 0  
fill ~53 ~3 ~11 ~57 ~3 ~11 cobblestone 0 
setblock ~53 ~3 ~13 torch 1  
fill ~53 ~3 ~19 ~57 ~3 ~19 cobblestone 0 
setblock ~54 ~3 ~5 planks 0 
setblock ~56 ~3 ~3 planks 0 
setblock ~56 ~3 ~6 torch 4 
setblock ~56 ~3 ~7 planks 0 
setblock ~56 ~3 ~17 torch 2 
setblock ~57 ~3 ~14 planks 0 
setblock ~57 ~3 ~17 planks 0 
setblock ~58 ~3 ~5 planks 0  
fill ~58 ~3 ~11 ~58 ~3 ~19 oak_stairs 1  
fill ~-5 ~4 ~22 ~-1 ~4 ~22 oak_stairs 2  
fill ~-5 ~4 ~23 ~4 ~4 ~23 planks 0  
fill ~-5 ~4 ~24 ~-5 ~5 ~24 planks 0  
fill ~-5 ~4 ~25 ~-5 ~6 ~25 planks 0  
fill ~-5 ~4 ~26 ~-5 ~5 ~26 planks 0  
fill ~-5 ~4 ~27 ~1 ~4 ~27 planks 0  
fill ~-5 ~4 ~28 ~-1 ~4 ~28 oak_stairs 3 
setblock ~-3 ~4 ~37 cobblestone 0  
fill ~-1 ~4 ~35 ~5 ~4 ~35 cobblestone 0  
fill ~-1 ~4 ~39 ~5 ~4 ~39 cobblestone 0  
fill ~0 ~4 ~29 ~0 ~4 ~30 oak_stairs 0 
setblock ~0 ~4 ~37 torch 2  
fill ~1 ~4 ~11 ~1 ~4 ~18 planks 0  
fill ~1 ~4 ~22 ~4 ~4 ~22 planks 0  
fill ~1 ~4 ~28 ~1 ~4 ~30 planks 0  
fill ~1 ~4 ~36 ~1 ~10 ~36 cobblestone 0  
fill ~1 ~4 ~37 ~5 ~4 ~37 cobblestone 0  
fill ~1 ~4 ~38 ~5 ~4 ~38 cobblestone 0  
fill ~2 ~4 ~10 ~4 ~4 ~10 planks 0  
fill ~2 ~4 ~18 ~4 ~4 ~18 planks 0  
fill ~2 ~4 ~30 ~4 ~4 ~30 planks 0  
fill ~3 ~4 ~36 ~5 ~4 ~36 cobblestone 0  
fill ~4 ~4 ~11 ~4 ~4 ~18 planks 0  
fill ~4 ~4 ~24 ~4 ~4 ~30 planks 0  
fill ~5 ~4 ~14 ~5 ~5 ~14 planks 0  
fill ~5 ~4 ~15 ~5 ~5 ~15 planks 0  
fill ~5 ~4 ~16 ~5 ~5 ~16 planks 0  
fill ~5 ~4 ~22 ~5 ~4 ~30 oak_stairs 1  
fill ~7 ~4 ~2 ~7 ~4 ~4 log 0  
fill ~8 ~4 ~1 ~9 ~4 ~1 log 0  
fill ~8 ~4 ~5 ~9 ~4 ~5 log 0  
fill ~10 ~4 ~2 ~10 ~4 ~4 log 0  
fill ~11 ~4 ~40 ~20 ~4 ~40 cobblestone 0  
fill ~11 ~4 ~41 ~20 ~4 ~41 cobblestone 0  
fill ~11 ~4 ~42 ~20 ~4 ~42 cobblestone 0  
fill ~11 ~4 ~43 ~20 ~4 ~43 cobblestone 0  
fill ~11 ~4 ~44 ~20 ~4 ~44 cobblestone 0  
fill ~12 ~4 ~23 ~16 ~4 ~23 log 0  
fill ~12 ~4 ~24 ~12 ~4 ~27 log 0  
fill ~12 ~4 ~39 ~13 ~4 ~39 cobblestone 0  
fill ~12 ~4 ~45 ~20 ~4 ~45 cobblestone 0  
fill ~13 ~4 ~1 ~17 ~4 ~1 log 0  
fill ~13 ~4 ~2 ~13 ~4 ~5 log 0  
fill ~13 ~4 ~24 ~15 ~4 ~24 planks 0  
fill ~13 ~4 ~25 ~15 ~4 ~25 planks 0  
fill ~13 ~4 ~26 ~14 ~4 ~26 planks 0  
fill ~13 ~4 ~27 ~16 ~4 ~27 log 0  
fill ~14 ~4 ~3 ~16 ~4 ~3 planks 0  
fill ~14 ~4 ~4 ~16 ~4 ~4 planks 0  
fill ~14 ~4 ~5 ~17 ~4 ~5 log 0  
fill ~15 ~4 ~2 ~16 ~4 ~2 planks 0  
fill ~15 ~4 ~39 ~20 ~4 ~39 cobblestone 0  
fill ~16 ~4 ~13 ~16 ~4 ~14 log 0  
fill ~16 ~4 ~24 ~16 ~4 ~27 log 0  
fill ~17 ~4 ~2 ~17 ~4 ~5 log 0  
fill ~17 ~4 ~12 ~19 ~4 ~12 log 0  
fill ~17 ~4 ~15 ~19 ~4 ~15 log 0  
fill ~20 ~4 ~13 ~20 ~4 ~14 log 0  
fill ~20 ~4 ~19 ~23 ~4 ~19 cobblestone 0  
fill ~20 ~4 ~20 ~23 ~4 ~20 cobblestone 0  
fill ~20 ~4 ~21 ~23 ~4 ~21 cobblestone 0  
fill ~20 ~4 ~22 ~23 ~4 ~22 cobblestone 0  
fill ~21 ~4 ~0 ~29 ~4 ~0 oak_stairs 2  
fill ~21 ~4 ~1 ~29 ~4 ~1 planks 0  
fill ~21 ~4 ~2 ~21 ~5 ~2 planks 0  
fill ~21 ~4 ~3 ~21 ~5 ~3 planks 0  
fill ~21 ~4 ~4 ~29 ~4 ~4 planks 0  
fill ~21 ~4 ~5 ~29 ~4 ~5 oak_stairs 3  
fill ~22 ~4 ~32 ~22 ~4 ~34 planks 0  
fill ~23 ~4 ~31 ~30 ~4 ~31 planks 0  
fill ~23 ~4 ~34 ~30 ~4 ~34 planks 0  
fill ~24 ~4 ~30 ~29 ~4 ~30 planks 0  
fill ~24 ~4 ~35 ~29 ~4 ~35 planks 0  
fill ~26 ~4 ~9 ~34 ~4 ~9 oak_stairs 2  
fill ~26 ~4 ~10 ~34 ~4 ~10 planks 0  
fill ~26 ~4 ~11 ~26 ~5 ~11 planks 0  
fill ~26 ~4 ~12 ~26 ~5 ~12 planks 0  
fill ~26 ~4 ~13 ~34 ~4 ~13 planks 0  
fill ~26 ~4 ~14 ~34 ~4 ~14 oak_stairs 3  
fill ~29 ~4 ~2 ~29 ~5 ~2 planks 0  
fill ~29 ~4 ~3 ~29 ~5 ~3 planks 0  
fill ~30 ~4 ~32 ~30 ~4 ~34 planks 0  
fill ~32 ~4 ~39 ~40 ~4 ~39 oak_stairs 2  
fill ~32 ~4 ~40 ~40 ~4 ~40 planks 0  
fill ~32 ~4 ~41 ~32 ~5 ~41 planks 0  
fill ~32 ~4 ~42 ~32 ~5 ~42 planks 0  
fill ~32 ~4 ~43 ~40 ~4 ~43 planks 0  
fill ~32 ~4 ~44 ~40 ~4 ~44 oak_stairs 3  
fill ~34 ~4 ~11 ~34 ~5 ~11 planks 0  
fill ~34 ~4 ~12 ~34 ~5 ~12 planks 0  
fill ~36 ~4 ~12 ~36 ~4 ~13 log 0  
fill ~36 ~4 ~22 ~40 ~4 ~22 log 0  
fill ~36 ~4 ~23 ~36 ~4 ~26 log 0  
fill ~37 ~4 ~11 ~39 ~4 ~11 log 0  
fill ~37 ~4 ~14 ~39 ~4 ~14 log 0  
fill ~37 ~4 ~23 ~39 ~4 ~23 planks 0  
fill ~37 ~4 ~24 ~39 ~4 ~24 planks 0  
fill ~37 ~4 ~25 ~39 ~4 ~25 planks 0  
fill ~37 ~4 ~26 ~40 ~4 ~26 log 0  
fill ~40 ~4 ~12 ~40 ~4 ~13 log 0  
fill ~40 ~4 ~23 ~40 ~4 ~26 log 0  
fill ~40 ~4 ~41 ~40 ~5 ~41 planks 0  
fill ~40 ~4 ~42 ~40 ~5 ~42 planks 0  
fill ~44 ~4 ~4 ~44 ~4 ~6 log 0  
fill ~44 ~4 ~27 ~44 ~4 ~35 oak_stairs 0  
fill ~45 ~4 ~3 ~46 ~4 ~3 log 0  
fill ~45 ~4 ~7 ~46 ~4 ~7 log 0  
fill ~45 ~4 ~27 ~48 ~4 ~27 planks 0  
fill ~45 ~4 ~28 ~45 ~4 ~35 planks 0  
fill ~46 ~4 ~34 ~54 ~4 ~34 planks 0  
fill ~46 ~4 ~35 ~49 ~4 ~35 planks 0  
fill ~47 ~4 ~4 ~47 ~4 ~6 log 0  
fill ~48 ~4 ~28 ~48 ~4 ~30 planks 0  
fill ~49 ~4 ~27 ~49 ~4 ~28 oak_stairs 1  
fill ~49 ~4 ~30 ~54 ~4 ~30 planks 0  
fill ~50 ~4 ~29 ~54 ~4 ~29 oak_stairs 2  
fill ~50 ~4 ~35 ~54 ~4 ~35 oak_stairs 3  
fill ~52 ~4 ~11 ~52 ~4 ~19 oak_stairs 0  
fill ~53 ~4 ~11 ~56 ~4 ~11 planks 0  
fill ~53 ~4 ~12 ~53 ~4 ~19 planks 0  
fill ~54 ~4 ~3 ~58 ~4 ~3 log 0  
fill ~54 ~4 ~4 ~54 ~4 ~7 log 0  
fill ~54 ~4 ~19 ~56 ~4 ~19 planks 0 
setblock ~54 ~4 ~31 log 0 
setblock ~54 ~4 ~32 glass_pane 0 
setblock ~54 ~4 ~33 log 0  
fill ~55 ~4 ~4 ~56 ~4 ~4 planks 0  
fill ~55 ~4 ~5 ~57 ~4 ~5 planks 0  
fill ~55 ~4 ~6 ~57 ~4 ~6 planks 0  
fill ~55 ~4 ~7 ~58 ~4 ~7 log 0  
fill ~56 ~4 ~12 ~56 ~4 ~19 planks 0  
fill ~57 ~4 ~11 ~57 ~4 ~19 oak_stairs 1  
fill ~58 ~4 ~4 ~58 ~4 ~7 log 0  
fill ~-5 ~5 ~23 ~0 ~5 ~23 oak_stairs 2  
fill ~-5 ~5 ~27 ~0 ~5 ~27 oak_stairs 3  
fill ~-4 ~5 ~24 ~3 ~5 ~24 planks 0  
fill ~-4 ~5 ~26 ~3 ~5 ~26 planks 0  
fill ~-2 ~5 ~36 ~1 ~5 ~36 cobblestone 0  
fill ~-2 ~5 ~37 ~1 ~5 ~37 cobblestone 0  
fill ~-2 ~5 ~38 ~1 ~5 ~38 cobblestone 0  
fill ~-1 ~5 ~10 ~-1 ~5 ~18 oak_stairs 0  
fill ~1 ~5 ~10 ~5 ~5 ~10 cobblestone 0  
fill ~1 ~5 ~11 ~1 ~5 ~18 cobblestone 0 
setblock ~1 ~5 ~22 oak_stairs 0  
fill ~1 ~5 ~23 ~3 ~5 ~23 planks 0  
fill ~1 ~5 ~27 ~3 ~5 ~27 planks 0  
fill ~1 ~5 ~28 ~1 ~5 ~30 oak_stairs 0  
fill ~2 ~5 ~12 ~4 ~5 ~12 cobblestone 0  
fill ~2 ~5 ~13 ~4 ~5 ~13 cobblestone 0  
fill ~2 ~5 ~14 ~4 ~5 ~14 cobblestone 0  
fill ~2 ~5 ~15 ~4 ~5 ~15 cobblestone 0  
fill ~2 ~5 ~16 ~4 ~5 ~16 cobblestone 0  
fill ~2 ~5 ~17 ~4 ~5 ~17 cobblestone 0  
fill ~2 ~5 ~18 ~5 ~5 ~18 cobblestone 0  
fill ~2 ~5 ~22 ~3 ~5 ~22 planks 0  
fill ~2 ~5 ~25 ~3 ~5 ~25 planks 0  
fill ~2 ~5 ~28 ~3 ~5 ~28 planks 0  
fill ~2 ~5 ~29 ~3 ~5 ~29 planks 0  
fill ~2 ~5 ~30 ~3 ~5 ~30 planks 0  
fill ~2 ~5 ~35 ~4 ~5 ~35 cobblestone 0  
fill ~2 ~5 ~39 ~4 ~5 ~39 cobblestone 0  
fill ~3 ~5 ~11 ~4 ~5 ~11 cobblestone 0  
fill ~4 ~5 ~22 ~4 ~5 ~30 oak_stairs 1  
fill ~6 ~5 ~10 ~6 ~5 ~18 oak_stairs 1  
fill ~8 ~5 ~2 ~9 ~5 ~2 log 0  
fill ~8 ~5 ~3 ~9 ~5 ~3 log 0  
fill ~8 ~5 ~4 ~9 ~5 ~4 log 0  
fill ~11 ~5 ~39 ~20 ~5 ~39 stone_slab 0  
fill ~11 ~5 ~40 ~11 ~5 ~45 stone_slab 0  
fill ~12 ~5 ~23 ~16 ~5 ~23 fence 0  
fill ~12 ~5 ~24 ~12 ~5 ~27 fence 0  
fill ~12 ~5 ~45 ~20 ~5 ~45 stone_slab 0  
fill ~13 ~5 ~1 ~17 ~5 ~1 fence 0  
fill ~13 ~5 ~2 ~13 ~5 ~5 fence 0  
fill ~13 ~5 ~27 ~16 ~5 ~27 fence 0  
fill ~14 ~5 ~5 ~17 ~5 ~5 fence 0  
fill ~16 ~5 ~24 ~16 ~5 ~27 fence 0  
fill ~17 ~5 ~2 ~17 ~5 ~5 fence 0  
fill ~17 ~5 ~13 ~19 ~5 ~13 log 0  
fill ~17 ~5 ~14 ~19 ~5 ~14 log 0  
fill ~20 ~5 ~40 ~20 ~5 ~45 stone_slab 0  
fill ~21 ~5 ~1 ~29 ~5 ~1 oak_stairs 2  
fill ~21 ~5 ~4 ~29 ~5 ~4 oak_stairs 3  
fill ~22 ~5 ~2 ~29 ~5 ~2 planks 0  
fill ~22 ~5 ~3 ~29 ~5 ~3 planks 0  
fill ~22 ~5 ~29 ~30 ~5 ~29 oak_stairs 2  
fill ~22 ~5 ~31 ~30 ~5 ~31 cobblestone 0  
fill ~22 ~5 ~32 ~30 ~5 ~32 cobblestone 0  
fill ~22 ~5 ~33 ~30 ~5 ~33 cobblestone 0  
fill ~22 ~5 ~34 ~30 ~5 ~34 cobblestone 0  
fill ~22 ~5 ~36 ~30 ~5 ~36 oak_stairs 3  
fill ~24 ~5 ~30 ~29 ~5 ~30 planks 0  
fill ~24 ~5 ~35 ~29 ~5 ~35 planks 0  
fill ~26 ~5 ~10 ~34 ~5 ~10 oak_stairs 2  
fill ~26 ~5 ~13 ~34 ~5 ~13 oak_stairs 3  
fill ~27 ~5 ~11 ~34 ~5 ~11 planks 0  
fill ~27 ~5 ~12 ~34 ~5 ~12 planks 0  
fill ~32 ~5 ~40 ~40 ~5 ~40 oak_stairs 2  
fill ~32 ~5 ~43 ~40 ~5 ~43 oak_stairs 3  
fill ~33 ~5 ~41 ~40 ~5 ~41 planks 0  
fill ~33 ~5 ~42 ~40 ~5 ~42 planks 0  
fill ~37 ~5 ~12 ~39 ~5 ~12 log 0  
fill ~37 ~5 ~13 ~39 ~5 ~13 log 0  
fill ~45 ~5 ~4 ~46 ~5 ~4 log 0  
fill ~45 ~5 ~5 ~46 ~5 ~5 log 0  
fill ~45 ~5 ~6 ~46 ~5 ~6 log 0  
fill ~45 ~5 ~27 ~45 ~5 ~35 oak_stairs 0  
fill ~46 ~5 ~27 ~47 ~5 ~27 planks 0  
fill ~46 ~5 ~28 ~47 ~5 ~28 planks 0  
fill ~46 ~5 ~29 ~47 ~5 ~29 planks 0  
fill ~46 ~5 ~30 ~48 ~5 ~30 planks 0  
fill ~46 ~5 ~31 ~54 ~5 ~31 planks 0  
fill ~46 ~5 ~33 ~54 ~5 ~33 planks 0  
fill ~46 ~5 ~34 ~48 ~5 ~34 planks 0  
fill ~46 ~5 ~35 ~47 ~5 ~35 planks 0  
fill ~48 ~5 ~27 ~48 ~5 ~29 oak_stairs 1 
setblock ~48 ~5 ~35 oak_stairs 1  
fill ~49 ~5 ~30 ~54 ~5 ~30 oak_stairs 2  
fill ~49 ~5 ~34 ~54 ~5 ~34 oak_stairs 3  
fill ~53 ~5 ~11 ~53 ~5 ~19 oak_stairs 0  
fill ~54 ~5 ~3 ~58 ~5 ~3 fence 0  
fill ~54 ~5 ~4 ~54 ~5 ~7 fence 0  
fill ~54 ~5 ~11 ~55 ~5 ~11 planks 0  
fill ~54 ~5 ~12 ~55 ~5 ~12 planks 0  
fill ~54 ~5 ~13 ~55 ~5 ~13 planks 0  
fill ~54 ~5 ~14 ~55 ~5 ~14 planks 0  
fill ~54 ~5 ~15 ~55 ~5 ~15 planks 0  
fill ~54 ~5 ~16 ~55 ~5 ~16 planks 0  
fill ~54 ~5 ~17 ~55 ~5 ~17 planks 0  
fill ~54 ~5 ~18 ~55 ~5 ~18 planks 0  
fill ~54 ~5 ~19 ~55 ~5 ~19 planks 0  
fill ~54 ~5 ~32 ~54 ~6 ~32 planks 0  
fill ~55 ~5 ~7 ~58 ~5 ~7 fence 0  
fill ~56 ~5 ~11 ~56 ~5 ~19 oak_stairs 1  
fill ~58 ~5 ~4 ~58 ~5 ~7 fence 0  
fill ~-5 ~6 ~24 ~1 ~6 ~24 oak_stairs 2  
fill ~-5 ~6 ~26 ~1 ~6 ~26 oak_stairs 3  
fill ~-4 ~6 ~25 ~2 ~6 ~25 planks 0  
fill ~0 ~6 ~10 ~0 ~6 ~18 oak_stairs 0  
fill ~1 ~6 ~10 ~4 ~6 ~10 planks 0  
fill ~1 ~6 ~11 ~1 ~6 ~18 planks 0  
fill ~1 ~6 ~37 ~1 ~7 ~37 glass_pane 0  
fill ~1 ~6 ~38 ~1 ~10 ~38 cobblestone 0  
fill ~2 ~6 ~18 ~4 ~6 ~18 planks 0  
fill ~2 ~6 ~22 ~2 ~6 ~23 oak_stairs 0 
setblock ~2 ~6 ~24 planks 0 
setblock ~2 ~6 ~26 planks 0  
fill ~2 ~6 ~27 ~2 ~6 ~30 oak_stairs 0  
fill ~2 ~6 ~35 ~2 ~10 ~35 cobblestone 0  
fill ~2 ~6 ~39 ~2 ~10 ~39 cobblestone 0  
fill ~3 ~6 ~22 ~3 ~6 ~30 oak_stairs 1  
fill ~3 ~6 ~35 ~3 ~7 ~35 glass_pane 0  
fill ~3 ~6 ~39 ~3 ~7 ~39 glass_pane 0  
fill ~4 ~6 ~11 ~4 ~6 ~18 planks 0  
fill ~5 ~6 ~10 ~5 ~6 ~18 oak_stairs 1  
fill ~5 ~6 ~37 ~5 ~7 ~37 glass_pane 0  
fill ~21 ~6 ~2 ~29 ~6 ~2 oak_stairs 2  
fill ~21 ~6 ~3 ~29 ~6 ~3 oak_stairs 3  
fill ~22 ~6 ~30 ~30 ~6 ~30 oak_stairs 2  
fill ~22 ~6 ~31 ~30 ~6 ~31 cobblestone 0  
fill ~22 ~6 ~32 ~22 ~7 ~32 cobblestone 0  
fill ~22 ~6 ~33 ~22 ~7 ~33 cobblestone 0  
fill ~22 ~6 ~34 ~30 ~6 ~34 cobblestone 0  
fill ~22 ~6 ~35 ~30 ~6 ~35 oak_stairs 3  
fill ~26 ~6 ~11 ~34 ~6 ~11 oak_stairs 2  
fill ~26 ~6 ~12 ~34 ~6 ~12 oak_stairs 3  
fill ~30 ~6 ~32 ~30 ~7 ~32 cobblestone 0  
fill ~30 ~6 ~33 ~30 ~7 ~33 cobblestone 0  
fill ~32 ~6 ~41 ~40 ~6 ~41 oak_stairs 2  
fill ~32 ~6 ~42 ~40 ~6 ~42 oak_stairs 3  
fill ~46 ~6 ~27 ~46 ~6 ~35 oak_stairs 0  
fill ~47 ~6 ~27 ~47 ~6 ~30 oak_stairs 1  
fill ~47 ~6 ~31 ~47 ~6 ~33 planks 0  
fill ~47 ~6 ~34 ~47 ~6 ~35 oak_stairs 1  
fill ~48 ~6 ~31 ~54 ~6 ~31 oak_stairs 2  
fill ~48 ~6 ~32 ~54 ~6 ~32 planks 0  
fill ~48 ~6 ~33 ~54 ~6 ~33 oak_stairs 3  
fill ~54 ~6 ~11 ~54 ~6 ~19 oak_stairs 0  
fill ~55 ~6 ~11 ~55 ~6 ~19 oak_stairs 1  
fill ~1 ~7 ~10 ~1 ~7 ~18 oak_stairs 0  
fill ~2 ~7 ~10 ~3 ~7 ~10 planks 0 
setblock ~2 ~7 ~17 torch 4  
fill ~2 ~7 ~18 ~3 ~7 ~18 planks 0  
fill ~4 ~7 ~10 ~4 ~7 ~18 oak_stairs 1  
fill ~22 ~7 ~31 ~30 ~7 ~31 oak_stairs 2  
fill ~22 ~7 ~34 ~30 ~7 ~34 oak_stairs 3 
setblock ~23 ~7 ~32 torch 1  
fill ~1 ~8 ~37 ~1 ~11 ~37 cobblestone 0  
fill ~2 ~8 ~10 ~2 ~8 ~18 oak_stairs 0 
setblock ~2 ~8 ~37 torch 1  
fill ~3 ~8 ~10 ~3 ~8 ~18 oak_stairs 1  
fill ~3 ~8 ~35 ~3 ~11 ~35 cobblestone 0  
fill ~3 ~8 ~39 ~3 ~11 ~39 cobblestone 0  
fill ~5 ~8 ~37 ~5 ~11 ~37 cobblestone 0  
fill ~22 ~8 ~32 ~30 ~8 ~32 oak_stairs 2  
fill ~22 ~8 ~33 ~30 ~8 ~33 oak_stairs 3 
setblock ~1 ~9 ~35 cobblestone 0 
setblock ~1 ~9 ~39 cobblestone 0  
fill ~2 ~9 ~37 ~5 ~9 ~37 cobblestone 0  
fill ~2 ~9 ~38 ~5 ~9 ~38 cobblestone 0  
fill ~3 ~9 ~36 ~5 ~9 ~36 cobblestone 0 
setblock ~5 ~9 ~35 cobblestone 0 
setblock ~5 ~9 ~39 cobblestone 0    