setblock ~15 ~11 ~11 chest 4
setblock ~15 ~11 ~16 chest 2
setblock ~14 ~11 ~16 chest 2
setblock ~10 ~4 ~25 hopper 4
setblock ~10 ~4 ~31 hopper 4
setblock ~13 ~16 ~28 hopper 8
setblock ~10 ~4 ~24 hopper 4
setblock ~10 ~4 ~32 hopper 4
setblock ~14 ~11 ~34 hopper 5
setblock ~14 ~11 ~38 hopper 3
setblock ~12 ~8 ~37 hopper 0
setblock ~11 ~8 ~49 hopper 0
setblock ~11 ~8 ~53 hopper 0
setblock ~17 ~4 ~59 hopper 3
setblock ~17 ~12 ~60 chest 5
setblock ~17 ~12 ~59 chest 5
setblock ~17 ~11 ~59 chest 5
setblock ~17 ~11 ~60 chest 5
setblock ~17 ~4 ~55 hopper 2
setblock ~17 ~10 ~59 chest 5
setblock ~17 ~10 ~60 chest 5
setblock ~25 ~11 ~11 hopper 3
setblock ~26 ~11 ~18 hopper 4
setblock ~30 ~4 ~24 hopper 5
setblock ~20 ~10 ~24 hopper 2
setblock ~26 ~11 ~22 hopper 4
setblock ~20 ~19 ~28 hopper 0
setblock ~27 ~16 ~28 hopper 8
setblock ~30 ~4 ~25 hopper 5
setblock ~30 ~4 ~31 hopper 5
setblock ~20 ~10 ~32 hopper 3
setblock ~30 ~4 ~32 hopper 5
setblock ~26 ~11 ~34 hopper 4
setblock ~23 ~4 ~38 furnace 4
setblock ~23 ~4 ~39 furnace 4
setblock ~26 ~11 ~38 hopper 4
setblock ~28 ~8 ~37 hopper 0
setblock ~28 ~9 ~48 hopper 8
setblock ~29 ~11 ~52 hopper 4
setblock ~23 ~4 ~55 hopper 2
setblock ~23 ~4 ~59 hopper 3
setblock ~27 ~12 ~61 trapped_chest 5
setblock ~20 ~10 ~57 hopper 0
setblock ~26 ~11 ~61 chest 2
setblock ~26 ~12 ~61 chest 2
setblock ~27 ~11 ~61 chest 2
setblock ~27 ~11 ~60 trapped_chest 3
setblock ~28 ~9 ~54 hopper 8
setblock ~28 ~11 ~61 trapped_chest 2
fill ~2 ~0 ~14 ~2 ~0 ~18 stone_brick_stairs 0 
setblock ~2 ~0 ~26 stone_brick_stairs 2  
fill ~2 ~0 ~27 ~2 ~0 ~29 stone_brick_stairs 0 
setblock ~2 ~0 ~30 stone_brick_stairs 3 
setblock ~3 ~0 ~3 stone_brick_stairs 0  
fill ~3 ~0 ~4 ~4 ~0 ~4 stonebrick 0 
setblock ~3 ~0 ~5 stone_brick_stairs 0 
setblock ~3 ~0 ~13 stone_brick_stairs 2  
fill ~3 ~0 ~14 ~6 ~0 ~14 stonebrick 0  
fill ~3 ~0 ~15 ~6 ~0 ~15 stonebrick 0  
fill ~3 ~0 ~16 ~6 ~0 ~16 stonebrick 0  
fill ~3 ~0 ~17 ~6 ~0 ~17 stonebrick 0  
fill ~3 ~0 ~18 ~6 ~0 ~18 stonebrick 0 
setblock ~3 ~0 ~19 stone_brick_stairs 3  
fill ~3 ~0 ~26 ~6 ~0 ~26 stonebrick 0  
fill ~3 ~0 ~27 ~6 ~0 ~27 stonebrick 0  
fill ~3 ~0 ~28 ~6 ~0 ~28 stonebrick 0  
fill ~3 ~0 ~29 ~6 ~0 ~29 stonebrick 0  
fill ~3 ~0 ~30 ~6 ~0 ~30 stonebrick 0 
setblock ~3 ~0 ~37 stone_brick_stairs 0  
fill ~3 ~0 ~38 ~4 ~0 ~38 stonebrick 0 
setblock ~3 ~0 ~39 stone_brick_stairs 0 
setblock ~3 ~0 ~63 stone_brick_stairs 0  
fill ~3 ~0 ~64 ~4 ~0 ~64 stonebrick 0 
setblock ~3 ~0 ~65 stone_brick_stairs 0 
setblock ~4 ~0 ~2 stone_brick_stairs 2  
fill ~4 ~0 ~3 ~4 ~3 ~3 stonebrick 0  
fill ~4 ~0 ~5 ~4 ~3 ~5 stonebrick 0 
setblock ~4 ~0 ~6 stone_brick_stairs 0 
setblock ~4 ~0 ~12 stone_brick_stairs 0  
fill ~4 ~0 ~13 ~6 ~0 ~13 stonebrick 0  
fill ~4 ~0 ~19 ~6 ~0 ~19 stonebrick 0 
setblock ~4 ~0 ~20 stone_brick_stairs 0 
setblock ~4 ~0 ~36 stone_brick_stairs 0  
fill ~4 ~0 ~37 ~4 ~3 ~37 stonebrick 0  
fill ~4 ~0 ~39 ~4 ~3 ~39 stonebrick 0 
setblock ~4 ~0 ~40 stone_brick_stairs 0 
setblock ~4 ~0 ~62 stone_brick_stairs 0  
fill ~4 ~0 ~63 ~4 ~3 ~63 stonebrick 0  
fill ~4 ~0 ~65 ~4 ~3 ~65 stonebrick 0 
setblock ~4 ~0 ~66 stone_brick_stairs 3 
setblock ~5 ~0 ~1 stone_brick_stairs 2  
fill ~5 ~0 ~2 ~7 ~0 ~2 stonebrick 0  
fill ~5 ~0 ~6 ~7 ~0 ~6 stonebrick 0 
setblock ~5 ~0 ~7 stone_brick_stairs 0 
setblock ~5 ~0 ~11 stone_brick_stairs 0  
fill ~5 ~0 ~12 ~6 ~0 ~12 stonebrick 0  
fill ~5 ~0 ~20 ~6 ~0 ~20 stonebrick 0 
setblock ~5 ~0 ~21 stone_brick_stairs 0 
setblock ~5 ~0 ~25 stone_brick_stairs 0 
setblock ~5 ~0 ~31 stone_brick_stairs 0 
setblock ~5 ~0 ~35 stone_brick_stairs 0  
fill ~5 ~0 ~36 ~7 ~0 ~36 stonebrick 0  
fill ~5 ~0 ~40 ~7 ~0 ~40 stonebrick 0 
setblock ~5 ~0 ~41 stone_brick_stairs 3 
setblock ~5 ~0 ~61 stone_brick_stairs 2  
fill ~5 ~0 ~62 ~7 ~0 ~62 stonebrick 0  
fill ~5 ~0 ~66 ~7 ~0 ~66 stonebrick 0 
setblock ~5 ~0 ~67 stone_brick_stairs 3 
setblock ~6 ~0 ~1 stonebrick 0  
fill ~6 ~0 ~7 ~6 ~3 ~7 stonebrick 0  
fill ~6 ~0 ~8 ~6 ~0 ~10 stone_slab 6  
fill ~6 ~0 ~11 ~6 ~3 ~11 stonebrick 0  
fill ~6 ~0 ~21 ~6 ~3 ~21 stonebrick 0  
fill ~6 ~0 ~22 ~6 ~0 ~24 stone_slab 6  
fill ~6 ~0 ~25 ~6 ~3 ~25 stonebrick 0  
fill ~6 ~0 ~31 ~6 ~3 ~31 stonebrick 0  
fill ~6 ~0 ~32 ~6 ~0 ~34 stone_slab 6  
fill ~6 ~0 ~35 ~6 ~3 ~35 stonebrick 0  
fill ~6 ~0 ~41 ~6 ~3 ~41 stonebrick 0 
setblock ~6 ~0 ~42 stone_brick_stairs 0 
setblock ~6 ~0 ~44 stone_brick_stairs 0 
setblock ~6 ~0 ~46 stone_brick_stairs 0 
setblock ~6 ~0 ~48 stone_brick_stairs 0 
setblock ~6 ~0 ~50 stone_brick_stairs 0 
setblock ~6 ~0 ~52 stone_brick_stairs 0 
setblock ~6 ~0 ~54 stone_brick_stairs 0 
setblock ~6 ~0 ~56 stone_brick_stairs 0 
setblock ~6 ~0 ~58 stone_brick_stairs 0 
setblock ~6 ~0 ~60 stone_brick_stairs 0  
fill ~6 ~0 ~61 ~7 ~0 ~61 stonebrick 0 
setblock ~6 ~0 ~67 stonebrick 0 
setblock ~7 ~0 ~1 stone_brick_stairs 2  
fill ~7 ~0 ~8 ~7 ~0 ~10 brick_block 0  
fill ~7 ~0 ~22 ~7 ~0 ~24 brick_block 0  
fill ~7 ~0 ~32 ~7 ~0 ~34 brick_block 0  
fill ~7 ~0 ~42 ~7 ~3 ~42 stonebrick 0  
fill ~7 ~0 ~43 ~7 ~3 ~43 stonebrick 0  
fill ~7 ~0 ~44 ~7 ~3 ~44 stonebrick 0  
fill ~7 ~0 ~45 ~7 ~3 ~45 stonebrick 0  
fill ~7 ~0 ~46 ~7 ~3 ~46 stonebrick 0  
fill ~7 ~0 ~47 ~7 ~3 ~47 stonebrick 0  
fill ~7 ~0 ~48 ~7 ~3 ~48 stonebrick 0  
fill ~7 ~0 ~49 ~7 ~3 ~49 stonebrick 0  
fill ~7 ~0 ~50 ~7 ~3 ~50 stonebrick 0  
fill ~7 ~0 ~51 ~7 ~3 ~51 stonebrick 0  
fill ~7 ~0 ~52 ~7 ~3 ~52 stonebrick 0  
fill ~7 ~0 ~53 ~7 ~3 ~53 stonebrick 0  
fill ~7 ~0 ~54 ~7 ~3 ~54 stonebrick 0  
fill ~7 ~0 ~55 ~7 ~3 ~55 stonebrick 0  
fill ~7 ~0 ~56 ~7 ~3 ~56 stonebrick 0  
fill ~7 ~0 ~57 ~7 ~3 ~57 stonebrick 0  
fill ~7 ~0 ~58 ~7 ~3 ~58 stonebrick 0  
fill ~7 ~0 ~59 ~7 ~3 ~59 stonebrick 0  
fill ~7 ~0 ~60 ~7 ~3 ~60 stonebrick 0 
setblock ~7 ~0 ~67 stone_brick_stairs 3 
setblock ~8 ~0 ~2 stone_brick_stairs 2  
fill ~8 ~0 ~3 ~8 ~3 ~3 stonebrick 0  
fill ~8 ~0 ~4 ~9 ~0 ~4 stonebrick 0  
fill ~8 ~0 ~5 ~8 ~3 ~5 stonebrick 0  
fill ~8 ~0 ~37 ~8 ~3 ~37 stonebrick 0  
fill ~8 ~0 ~38 ~8 ~3 ~38 stonebrick 0  
fill ~8 ~0 ~39 ~8 ~3 ~39 stonebrick 0  
fill ~8 ~0 ~63 ~8 ~3 ~63 stonebrick 0  
fill ~8 ~0 ~64 ~9 ~0 ~64 stonebrick 0  
fill ~8 ~0 ~65 ~8 ~3 ~65 stonebrick 0 
setblock ~8 ~0 ~66 stone_brick_stairs 3 
setblock ~9 ~0 ~3 stone_brick_stairs 2 
setblock ~9 ~0 ~65 stone_brick_stairs 3  
fill ~10 ~0 ~4 ~12 ~0 ~4 stone_slab 6  
fill ~10 ~0 ~5 ~12 ~0 ~5 brick_block 0  
fill ~10 ~0 ~63 ~12 ~0 ~63 brick_block 0  
fill ~10 ~0 ~64 ~12 ~0 ~64 stone_slab 6 
setblock ~13 ~0 ~3 stone_brick_stairs 2  
fill ~13 ~0 ~4 ~13 ~3 ~4 stonebrick 0  
fill ~13 ~0 ~64 ~13 ~3 ~64 stonebrick 0 
setblock ~13 ~0 ~65 stone_brick_stairs 3  
fill ~14 ~0 ~4 ~16 ~0 ~4 stone_slab 6  
fill ~14 ~0 ~5 ~16 ~0 ~5 brick_block 0  
fill ~14 ~0 ~63 ~16 ~0 ~63 brick_block 0  
fill ~14 ~0 ~64 ~16 ~0 ~64 stone_slab 6 
setblock ~17 ~0 ~3 stone_brick_stairs 2  
fill ~17 ~0 ~4 ~17 ~3 ~4 stonebrick 0  
fill ~17 ~0 ~64 ~17 ~3 ~64 stonebrick 0 
setblock ~17 ~0 ~65 stone_brick_stairs 3  
fill ~18 ~0 ~0 ~18 ~0 ~3 stonebrick 0  
fill ~18 ~0 ~64 ~18 ~2 ~64 cobblestone 0  
fill ~18 ~0 ~65 ~22 ~0 ~65 stonebrick 0  
fill ~18 ~0 ~66 ~22 ~0 ~66 stonebrick 0  
fill ~18 ~0 ~67 ~22 ~0 ~67 stonebrick 0  
fill ~18 ~0 ~68 ~18 ~0 ~65 stonebrick 0  
fill ~19 ~0 ~0 ~21 ~0 ~0 stone_brick_stairs 2  
fill ~19 ~0 ~1 ~22 ~0 ~1 stonebrick 0  
fill ~19 ~0 ~2 ~19 ~1 ~2 stonebrick 0  
fill ~19 ~0 ~64 ~19 ~3 ~64 stonebrick 0  
fill ~19 ~0 ~68 ~21 ~0 ~68 stone_brick_stairs 3  
fill ~20 ~0 ~64 ~20 ~2 ~64 cobblestone 0  
fill ~21 ~0 ~50 ~21 ~2 ~50 stone 0  
fill ~21 ~0 ~64 ~21 ~3 ~64 stonebrick 0 
setblock ~22 ~0 ~0 stonebrick 0  
fill ~22 ~0 ~2 ~22 ~2 ~2 stonebrick 0  
fill ~22 ~0 ~3 ~22 ~3 ~3 stonebrick 0  
fill ~22 ~0 ~49 ~22 ~2 ~49 stone 0  
fill ~22 ~0 ~51 ~22 ~2 ~51 stone 0  
fill ~22 ~0 ~64 ~22 ~2 ~64 cobblestone 0 
setblock ~22 ~0 ~68 stonebrick 0 
setblock ~23 ~0 ~3 stone_brick_stairs 2  
fill ~23 ~0 ~4 ~23 ~3 ~4 stonebrick 0  
fill ~23 ~0 ~50 ~23 ~4 ~50 stone 0  
fill ~23 ~0 ~64 ~23 ~3 ~64 stonebrick 0 
setblock ~23 ~0 ~65 stone_brick_stairs 3  
fill ~24 ~0 ~4 ~26 ~0 ~4 stone_slab 6  
fill ~24 ~0 ~5 ~26 ~0 ~5 brick_block 0 
setblock ~24 ~0 ~46 stonebrick 0  
fill ~24 ~0 ~47 ~24 ~0 ~48 redstone_wire 0 
setblock ~24 ~0 ~49 stonebrick 0 
setblock ~24 ~0 ~50 redstone_torch 3  
fill ~24 ~0 ~63 ~26 ~0 ~63 brick_block 0  
fill ~24 ~0 ~64 ~26 ~0 ~64 stone_slab 6 
setblock ~27 ~0 ~3 stone_brick_stairs 2  
fill ~27 ~0 ~4 ~27 ~3 ~4 stonebrick 0  
fill ~27 ~0 ~64 ~27 ~3 ~64 stonebrick 0 
setblock ~27 ~0 ~65 stone_brick_stairs 3  
fill ~28 ~0 ~4 ~30 ~0 ~4 stone_slab 6  
fill ~28 ~0 ~5 ~30 ~0 ~5 brick_block 0  
fill ~28 ~0 ~63 ~30 ~0 ~63 brick_block 0  
fill ~28 ~0 ~64 ~30 ~0 ~64 stone_slab 6 
setblock ~31 ~0 ~3 stone_brick_stairs 2  
fill ~31 ~0 ~4 ~32 ~0 ~4 stonebrick 0 
setblock ~31 ~0 ~9 stone_brick_stairs 2  
fill ~31 ~0 ~10 ~37 ~0 ~10 stonebrick 0  
fill ~31 ~0 ~11 ~31 ~3 ~11 stonebrick 0  
fill ~31 ~0 ~12 ~31 ~2 ~12 stonebrick 0  
fill ~31 ~0 ~13 ~31 ~2 ~13 stonebrick 0  
fill ~31 ~0 ~14 ~31 ~2 ~14 stonebrick 0  
fill ~31 ~0 ~15 ~31 ~3 ~15 stonebrick 0  
fill ~31 ~0 ~16 ~37 ~0 ~16 stonebrick 0  
fill ~31 ~0 ~64 ~32 ~0 ~64 stonebrick 0 
setblock ~31 ~0 ~65 stone_brick_stairs 3 
setblock ~32 ~0 ~2 stone_brick_stairs 2  
fill ~32 ~0 ~3 ~32 ~3 ~3 stonebrick 0  
fill ~32 ~0 ~5 ~32 ~3 ~5 stonebrick 0 
setblock ~32 ~0 ~9 stonebrick 0  
fill ~32 ~0 ~37 ~32 ~3 ~37 stonebrick 0  
fill ~32 ~0 ~38 ~32 ~3 ~38 stonebrick 0  
fill ~32 ~0 ~39 ~32 ~3 ~39 stonebrick 0  
fill ~32 ~0 ~63 ~32 ~3 ~63 stonebrick 0  
fill ~32 ~0 ~65 ~32 ~3 ~65 stonebrick 0 
setblock ~32 ~0 ~66 stone_brick_stairs 3 
setblock ~33 ~0 ~1 stone_brick_stairs 2  
fill ~33 ~0 ~2 ~35 ~0 ~2 stonebrick 0  
fill ~33 ~0 ~6 ~35 ~0 ~6 stonebrick 0 
setblock ~33 ~0 ~9 stone_brick_stairs 2  
fill ~33 ~0 ~18 ~33 ~2 ~18 brick_block 0  
fill ~33 ~0 ~19 ~33 ~0 ~20 brick_block 0  
fill ~33 ~0 ~22 ~33 ~2 ~22 brick_block 0  
fill ~33 ~0 ~23 ~33 ~0 ~24 brick_block 0  
fill ~33 ~0 ~32 ~33 ~2 ~32 brick_block 0  
fill ~33 ~0 ~33 ~33 ~0 ~34 brick_block 0  
fill ~33 ~0 ~35 ~34 ~0 ~35 stonebrick 0  
fill ~33 ~0 ~36 ~35 ~0 ~36 stonebrick 0  
fill ~33 ~0 ~40 ~35 ~0 ~40 stonebrick 0  
fill ~33 ~0 ~41 ~34 ~0 ~41 stonebrick 0  
fill ~33 ~0 ~42 ~33 ~3 ~42 stonebrick 0  
fill ~33 ~0 ~43 ~33 ~3 ~43 stonebrick 0  
fill ~33 ~0 ~44 ~33 ~2 ~44 stonebrick 0  
fill ~33 ~0 ~45 ~33 ~2 ~45 stonebrick 0  
fill ~33 ~0 ~46 ~33 ~2 ~46 stonebrick 0  
fill ~33 ~0 ~47 ~33 ~3 ~47 stonebrick 0  
fill ~33 ~0 ~48 ~33 ~3 ~48 stonebrick 0  
fill ~33 ~0 ~49 ~33 ~3 ~49 stonebrick 0  
fill ~33 ~0 ~50 ~33 ~2 ~50 stonebrick 0  
fill ~33 ~0 ~51 ~33 ~2 ~51 stonebrick 0  
fill ~33 ~0 ~52 ~33 ~2 ~52 stonebrick 0  
fill ~33 ~0 ~53 ~33 ~3 ~53 stonebrick 0  
fill ~33 ~0 ~54 ~33 ~3 ~54 stonebrick 0  
fill ~33 ~0 ~55 ~33 ~3 ~55 stonebrick 0  
fill ~33 ~0 ~56 ~33 ~2 ~56 stonebrick 0  
fill ~33 ~0 ~57 ~33 ~2 ~57 stonebrick 0  
fill ~33 ~0 ~58 ~33 ~2 ~58 stonebrick 0  
fill ~33 ~0 ~59 ~33 ~1 ~59 stonebrick 0  
fill ~33 ~0 ~60 ~33 ~3 ~60 stonebrick 0  
fill ~33 ~0 ~62 ~35 ~0 ~62 stonebrick 0  
fill ~33 ~0 ~66 ~35 ~0 ~66 stonebrick 0 
setblock ~33 ~0 ~67 stone_brick_stairs 3 
setblock ~34 ~0 ~1 stonebrick 0  
fill ~34 ~0 ~7 ~34 ~3 ~7 stonebrick 0  
fill ~34 ~0 ~8 ~34 ~2 ~8 cobblestone 0  
fill ~34 ~0 ~9 ~34 ~3 ~9 stonebrick 0  
fill ~34 ~0 ~17 ~34 ~3 ~17 stonebrick 0  
fill ~34 ~0 ~18 ~34 ~0 ~20 stone_slab 6  
fill ~34 ~0 ~21 ~34 ~3 ~21 stonebrick 0  
fill ~34 ~0 ~22 ~34 ~0 ~24 stone_slab 6  
fill ~34 ~0 ~25 ~34 ~3 ~25 stonebrick 0  
fill ~34 ~0 ~31 ~34 ~3 ~31 stonebrick 0  
fill ~34 ~0 ~32 ~34 ~0 ~34 stone_slab 6 
setblock ~34 ~0 ~42 stone_brick_stairs 1 
setblock ~34 ~0 ~44 stone_brick_stairs 1 
setblock ~34 ~0 ~46 stone_brick_stairs 1 
setblock ~34 ~0 ~48 stone_brick_stairs 1 
setblock ~34 ~0 ~50 stone_brick_stairs 1 
setblock ~34 ~0 ~52 stone_brick_stairs 1 
setblock ~34 ~0 ~54 stone_brick_stairs 1 
setblock ~34 ~0 ~56 stone_brick_stairs 1 
setblock ~34 ~0 ~58 stone_brick_stairs 1 
setblock ~34 ~0 ~60 stone_brick_stairs 1  
fill ~34 ~0 ~61 ~34 ~3 ~61 stonebrick 0 
setblock ~34 ~0 ~67 stonebrick 0 
setblock ~35 ~0 ~1 stone_brick_stairs 2 
setblock ~35 ~0 ~7 stone_brick_stairs 3 
setblock ~35 ~0 ~9 stone_brick_stairs 1 
setblock ~35 ~0 ~17 stone_brick_stairs 1 
setblock ~35 ~0 ~21 stone_brick_stairs 1 
setblock ~35 ~0 ~25 stone_brick_stairs 1  
fill ~35 ~0 ~26 ~37 ~0 ~26 stonebrick 0  
fill ~35 ~0 ~30 ~37 ~0 ~30 stonebrick 0 
setblock ~35 ~0 ~31 stone_brick_stairs 1 
setblock ~35 ~0 ~35 stone_brick_stairs 1 
setblock ~35 ~0 ~41 stone_brick_stairs 3  
fill ~35 ~0 ~42 ~35 ~1 ~42 leaves 12  
fill ~35 ~0 ~43 ~35 ~1 ~43 leaves 12  
fill ~35 ~0 ~44 ~35 ~0 ~55 leaves 8  
fill ~35 ~0 ~56 ~35 ~1 ~56 leaves 12  
fill ~35 ~0 ~57 ~35 ~2 ~57 leaves 12  
fill ~35 ~0 ~58 ~35 ~2 ~58 leaves 12  
fill ~35 ~0 ~59 ~35 ~2 ~59 leaves 12  
fill ~35 ~0 ~60 ~35 ~2 ~60 leaves 12 
setblock ~35 ~0 ~61 stone_brick_stairs 2 
setblock ~35 ~0 ~67 stone_brick_stairs 3 
setblock ~36 ~0 ~2 stone_brick_stairs 1  
fill ~36 ~0 ~3 ~36 ~3 ~3 stonebrick 0  
fill ~36 ~0 ~4 ~37 ~0 ~4 stonebrick 0  
fill ~36 ~0 ~5 ~36 ~3 ~5 stonebrick 0 
setblock ~36 ~0 ~6 stone_brick_stairs 1 
setblock ~36 ~0 ~9 stone_brick_stairs 2 
setblock ~36 ~0 ~17 stone_brick_stairs 3 
setblock ~36 ~0 ~36 stone_brick_stairs 1  
fill ~36 ~0 ~37 ~36 ~3 ~37 stonebrick 0  
fill ~36 ~0 ~38 ~37 ~0 ~38 stonebrick 0  
fill ~36 ~0 ~39 ~36 ~3 ~39 stonebrick 0 
setblock ~36 ~0 ~40 stone_brick_stairs 1 
setblock ~36 ~0 ~62 stone_brick_stairs 1  
fill ~36 ~0 ~63 ~36 ~3 ~63 stonebrick 0  
fill ~36 ~0 ~64 ~37 ~0 ~64 stonebrick 0  
fill ~36 ~0 ~65 ~36 ~3 ~65 stonebrick 0 
setblock ~36 ~0 ~66 stone_slab 5 
setblock ~37 ~0 ~3 stone_brick_stairs 1 
setblock ~37 ~0 ~5 stone_brick_stairs 1 
setblock ~37 ~0 ~9 cobblestone 0  
fill ~37 ~0 ~11 ~37 ~0 ~16 stonebrick 0 
setblock ~37 ~0 ~17 cobblestone 0  
fill ~37 ~0 ~27 ~37 ~0 ~30 stonebrick 0 
setblock ~37 ~0 ~37 stone_brick_stairs 1 
setblock ~37 ~0 ~39 stone_brick_stairs 1 
setblock ~37 ~0 ~63 stone_brick_stairs 1 
setblock ~37 ~0 ~65 stone_brick_stairs 1  
fill ~38 ~0 ~9 ~38 ~4 ~9 stonebrick 0 
setblock ~38 ~0 ~10 cobblestone 0  
fill ~38 ~0 ~11 ~38 ~0 ~12 stone_brick_stairs 1 
setblock ~38 ~0 ~13 cobblestone 0  
fill ~38 ~0 ~14 ~38 ~0 ~15 stone_brick_stairs 1 
setblock ~38 ~0 ~16 cobblestone 0  
fill ~38 ~0 ~17 ~38 ~4 ~17 stonebrick 0 
setblock ~38 ~0 ~26 stone_brick_stairs 2  
fill ~38 ~0 ~27 ~38 ~0 ~29 stone_brick_stairs 1 
setblock ~38 ~0 ~30 stone_brick_stairs 3  
fill ~1 ~1 ~61 ~1 ~2 ~61 leaves 2  
fill ~1 ~1 ~62 ~1 ~2 ~62 leaves 2  
fill ~1 ~1 ~63 ~1 ~2 ~63 leaves 2  
fill ~1 ~1 ~64 ~1 ~2 ~64 leaves 2  
fill ~1 ~1 ~65 ~1 ~1 ~61 leaves 2  
fill ~3 ~1 ~14 ~6 ~1 ~14 stonebrick 0  
fill ~3 ~1 ~15 ~6 ~1 ~15 stonebrick 0  
fill ~3 ~1 ~16 ~6 ~1 ~16 stonebrick 0  
fill ~3 ~1 ~17 ~6 ~1 ~17 stonebrick 0  
fill ~3 ~1 ~18 ~6 ~1 ~18 stonebrick 0  
fill ~3 ~1 ~26 ~6 ~1 ~26 stonebrick 0  
fill ~3 ~1 ~27 ~3 ~1 ~29 stone_brick_stairs 0  
fill ~3 ~1 ~30 ~6 ~1 ~30 stonebrick 0  
fill ~4 ~1 ~4 ~4 ~2 ~4 glass_pane 0  
fill ~4 ~1 ~13 ~6 ~1 ~13 stonebrick 0  
fill ~4 ~1 ~19 ~6 ~1 ~19 stonebrick 0  
fill ~4 ~1 ~27 ~6 ~1 ~27 stonebrick 0  
fill ~4 ~1 ~28 ~6 ~1 ~28 stonebrick 0  
fill ~4 ~1 ~29 ~6 ~1 ~29 stonebrick 0  
fill ~4 ~1 ~38 ~4 ~2 ~38 glass_pane 0  
fill ~4 ~1 ~64 ~4 ~2 ~64 glass_pane 0  
fill ~5 ~1 ~2 ~5 ~3 ~2 stonebrick 0  
fill ~5 ~1 ~6 ~7 ~1 ~6 stonebrick 0  
fill ~5 ~1 ~12 ~6 ~1 ~12 stonebrick 0  
fill ~5 ~1 ~20 ~6 ~1 ~20 stonebrick 0  
fill ~5 ~1 ~36 ~7 ~1 ~36 stonebrick 0  
fill ~5 ~1 ~40 ~7 ~1 ~40 stonebrick 0  
fill ~5 ~1 ~62 ~7 ~1 ~62 stonebrick 0  
fill ~5 ~1 ~66 ~5 ~3 ~66 stonebrick 0  
fill ~6 ~1 ~2 ~6 ~2 ~2 glass_pane 0  
fill ~6 ~1 ~61 ~7 ~1 ~61 stonebrick 0  
fill ~6 ~1 ~66 ~6 ~2 ~66 glass_pane 0  
fill ~7 ~1 ~2 ~7 ~3 ~2 stonebrick 0 
setblock ~7 ~1 ~8 brick_stairs 3  
fill ~7 ~1 ~9 ~7 ~2 ~9 brick_block 0 
setblock ~7 ~1 ~10 brick_stairs 2 
setblock ~7 ~1 ~22 brick_stairs 3  
fill ~7 ~1 ~23 ~7 ~2 ~23 brick_block 0 
setblock ~7 ~1 ~24 brick_stairs 2 
setblock ~7 ~1 ~32 brick_stairs 3  
fill ~7 ~1 ~33 ~7 ~2 ~33 brick_block 0 
setblock ~7 ~1 ~34 brick_stairs 2  
fill ~7 ~1 ~66 ~7 ~3 ~66 stonebrick 0  
fill ~8 ~1 ~4 ~9 ~1 ~4 stonebrick 0  
fill ~8 ~1 ~8 ~8 ~2 ~8 wool 15  
fill ~8 ~1 ~10 ~8 ~2 ~10 wool 15  
fill ~8 ~1 ~22 ~8 ~2 ~22 wool 15  
fill ~8 ~1 ~24 ~8 ~2 ~24 wool 15  
fill ~8 ~1 ~32 ~8 ~2 ~32 wool 15  
fill ~8 ~1 ~34 ~8 ~2 ~34 wool 15  
fill ~8 ~1 ~64 ~9 ~1 ~64 stonebrick 0  
fill ~10 ~1 ~5 ~10 ~2 ~5 brick_block 0  
fill ~10 ~1 ~63 ~10 ~2 ~63 brick_block 0  
fill ~11 ~1 ~5 ~11 ~2 ~5 glass_pane 0  
fill ~11 ~1 ~63 ~11 ~2 ~63 glass_pane 0  
fill ~12 ~1 ~5 ~12 ~2 ~5 brick_block 0  
fill ~12 ~1 ~63 ~12 ~2 ~63 brick_block 0  
fill ~14 ~1 ~5 ~14 ~2 ~5 brick_block 0  
fill ~14 ~1 ~63 ~14 ~2 ~63 brick_block 0  
fill ~15 ~1 ~5 ~15 ~2 ~5 glass_pane 0 
setblock ~15 ~1 ~52 brick_block 0  
fill ~15 ~1 ~63 ~15 ~2 ~63 glass_pane 0  
fill ~16 ~1 ~5 ~16 ~2 ~5 brick_block 0  
fill ~16 ~1 ~63 ~16 ~2 ~63 brick_block 0 
setblock ~18 ~1 ~0 stone_slab 6  
fill ~18 ~1 ~1 ~18 ~1 ~3 stonebrick 0  
fill ~18 ~1 ~65 ~22 ~1 ~65 stonebrick 0  
fill ~18 ~1 ~66 ~22 ~1 ~66 stonebrick 0  
fill ~18 ~1 ~67 ~18 ~1 ~65 stonebrick 0 
setblock ~18 ~1 ~68 stone_slab 6  
fill ~19 ~1 ~1 ~21 ~1 ~1 stone_brick_stairs 2  
fill ~19 ~1 ~67 ~21 ~1 ~67 stone_brick_stairs 3  
fill ~20 ~1 ~2 ~22 ~1 ~2 stonebrick 0 
setblock ~22 ~1 ~0 stone_slab 6 
setblock ~22 ~1 ~1 stonebrick 0 
setblock ~22 ~1 ~67 stonebrick 0 
setblock ~22 ~1 ~68 stone_slab 6 
setblock ~23 ~1 ~46 stonebrick 0  
fill ~24 ~1 ~5 ~24 ~2 ~5 brick_block 0 
setblock ~24 ~1 ~46 redstone_wire 0 
setblock ~24 ~1 ~50 stonebrick 0  
fill ~24 ~1 ~62 ~24 ~2 ~62 wool 15 
setblock ~24 ~1 ~63 brick_stairs 1  
fill ~25 ~1 ~5 ~25 ~2 ~5 glass_pane 0  
fill ~25 ~1 ~63 ~25 ~2 ~63 brick_block 0  
fill ~26 ~1 ~5 ~26 ~2 ~5 brick_block 0  
fill ~26 ~1 ~62 ~26 ~2 ~62 wool 15 
setblock ~26 ~1 ~63 brick_stairs 0  
fill ~28 ~1 ~5 ~28 ~2 ~5 brick_block 0  
fill ~28 ~1 ~62 ~28 ~2 ~62 wool 15 
setblock ~28 ~1 ~63 brick_stairs 1  
fill ~29 ~1 ~5 ~29 ~2 ~5 glass_pane 0  
fill ~29 ~1 ~63 ~29 ~2 ~63 brick_block 0  
fill ~30 ~1 ~5 ~30 ~2 ~5 brick_block 0  
fill ~30 ~1 ~62 ~30 ~2 ~62 wool 15 
setblock ~30 ~1 ~63 brick_stairs 0  
fill ~31 ~1 ~4 ~32 ~1 ~4 stonebrick 0  
fill ~31 ~1 ~10 ~37 ~1 ~10 stonebrick 0  
fill ~31 ~1 ~16 ~37 ~1 ~16 stonebrick 0  
fill ~31 ~1 ~64 ~32 ~1 ~64 stonebrick 0  
fill ~33 ~1 ~2 ~33 ~3 ~2 stonebrick 0  
fill ~33 ~1 ~6 ~35 ~1 ~6 stonebrick 0  
fill ~33 ~1 ~19 ~33 ~2 ~19 glass_pane 0  
fill ~33 ~1 ~20 ~33 ~2 ~20 brick_block 0  
fill ~33 ~1 ~23 ~33 ~2 ~23 glass_pane 0  
fill ~33 ~1 ~24 ~33 ~2 ~24 brick_block 0  
fill ~33 ~1 ~33 ~33 ~2 ~33 glass_pane 0  
fill ~33 ~1 ~34 ~33 ~2 ~34 brick_block 0  
fill ~33 ~1 ~35 ~34 ~1 ~35 stonebrick 0  
fill ~33 ~1 ~36 ~35 ~1 ~36 stonebrick 0  
fill ~33 ~1 ~40 ~35 ~1 ~40 stonebrick 0  
fill ~33 ~1 ~41 ~34 ~1 ~41 stonebrick 0  
fill ~33 ~1 ~62 ~35 ~1 ~62 stonebrick 0  
fill ~33 ~1 ~66 ~33 ~3 ~66 stonebrick 0  
fill ~34 ~1 ~2 ~34 ~2 ~2 glass_pane 0  
fill ~34 ~1 ~66 ~34 ~2 ~66 glass_pane 0  
fill ~35 ~1 ~2 ~35 ~3 ~2 stonebrick 0  
fill ~35 ~1 ~26 ~37 ~1 ~26 stonebrick 0  
fill ~35 ~1 ~30 ~37 ~1 ~30 stonebrick 0  
fill ~35 ~1 ~44 ~35 ~2 ~44 leaves 12  
fill ~35 ~1 ~45 ~35 ~2 ~45 leaves 12  
fill ~35 ~1 ~46 ~35 ~2 ~46 leaves 12  
fill ~35 ~1 ~47 ~35 ~2 ~47 leaves 8  
fill ~35 ~1 ~48 ~35 ~2 ~48 leaves 8  
fill ~35 ~1 ~49 ~35 ~2 ~49 leaves 8  
fill ~35 ~1 ~50 ~35 ~2 ~50 leaves 8  
fill ~35 ~1 ~51 ~35 ~2 ~51 leaves 8  
fill ~35 ~1 ~52 ~35 ~2 ~52 leaves 8  
fill ~35 ~1 ~53 ~35 ~2 ~53 leaves 8  
fill ~35 ~1 ~54 ~35 ~2 ~54 leaves 8  
fill ~35 ~1 ~55 ~35 ~2 ~55 leaves 8  
fill ~35 ~1 ~66 ~35 ~3 ~66 stonebrick 0  
fill ~36 ~1 ~4 ~36 ~2 ~4 glass_pane 0  
fill ~36 ~1 ~38 ~36 ~2 ~38 glass_pane 0  
fill ~36 ~1 ~64 ~36 ~2 ~64 glass_pane 0 
setblock ~37 ~1 ~9 stone_brick_stairs 2  
fill ~37 ~1 ~11 ~37 ~2 ~11 glass_pane 0  
fill ~37 ~1 ~12 ~37 ~2 ~12 glass_pane 0  
fill ~37 ~1 ~13 ~37 ~3 ~13 stonebrick 0  
fill ~37 ~1 ~14 ~37 ~2 ~14 glass_pane 0  
fill ~37 ~1 ~15 ~37 ~2 ~15 glass_pane 0 
setblock ~37 ~1 ~17 stone_brick_stairs 3  
fill ~37 ~1 ~27 ~37 ~1 ~29 stone_brick_stairs 1 
setblock ~38 ~1 ~10 stone_brick_stairs 1 
setblock ~38 ~1 ~13 stone_brick_stairs 1 
setblock ~38 ~1 ~16 stone_brick_stairs 1 
setblock ~2 ~2 ~14 stone_brick_stairs 4 
setblock ~2 ~2 ~18 stone_brick_stairs 4 
setblock ~3 ~2 ~13 stone_brick_stairs 6  
fill ~3 ~2 ~14 ~6 ~2 ~14 stonebrick 0  
fill ~3 ~2 ~15 ~6 ~2 ~15 stonebrick 0  
fill ~3 ~2 ~16 ~6 ~2 ~16 stonebrick 0  
fill ~3 ~2 ~17 ~6 ~2 ~17 stonebrick 0  
fill ~3 ~2 ~18 ~6 ~2 ~18 stonebrick 0 
setblock ~3 ~2 ~19 stone_brick_stairs 7 
setblock ~4 ~2 ~12 stone_brick_stairs 4  
fill ~4 ~2 ~13 ~6 ~2 ~13 stonebrick 0  
fill ~4 ~2 ~19 ~6 ~2 ~19 stonebrick 0 
setblock ~4 ~2 ~20 stone_brick_stairs 4  
fill ~4 ~2 ~26 ~6 ~2 ~26 stonebrick 0  
fill ~4 ~2 ~27 ~4 ~2 ~29 stone_brick_stairs 0  
fill ~4 ~2 ~30 ~6 ~2 ~30 stonebrick 0  
fill ~5 ~2 ~6 ~7 ~2 ~6 stonebrick 0 
setblock ~5 ~2 ~7 stone_brick_stairs 4 
setblock ~5 ~2 ~11 stone_brick_stairs 4  
fill ~5 ~2 ~12 ~6 ~2 ~12 stonebrick 0  
fill ~5 ~2 ~20 ~6 ~2 ~20 stonebrick 0 
setblock ~5 ~2 ~21 stone_brick_stairs 4 
setblock ~5 ~2 ~25 stone_brick_stairs 4  
fill ~5 ~2 ~27 ~6 ~2 ~27 stonebrick 0  
fill ~5 ~2 ~28 ~6 ~2 ~28 stonebrick 0  
fill ~5 ~2 ~29 ~6 ~2 ~29 stonebrick 0 
setblock ~5 ~2 ~31 stone_brick_stairs 4 
setblock ~5 ~2 ~35 stone_brick_stairs 4  
fill ~5 ~2 ~36 ~7 ~2 ~36 stonebrick 0  
fill ~5 ~2 ~40 ~7 ~2 ~40 stonebrick 0  
fill ~5 ~2 ~62 ~7 ~2 ~62 stonebrick 0 
setblock ~6 ~2 ~22 stone_brick_stairs 7 
setblock ~6 ~2 ~24 stone_brick_stairs 6 
setblock ~6 ~2 ~32 stone_brick_stairs 7 
setblock ~6 ~2 ~34 stone_brick_stairs 6 
setblock ~6 ~2 ~43 quartz_stairs 4 
setblock ~6 ~2 ~47 quartz_stairs 4 
setblock ~6 ~2 ~49 quartz_stairs 4 
setblock ~6 ~2 ~53 quartz_stairs 4 
setblock ~6 ~2 ~55 quartz_stairs 4 
setblock ~6 ~2 ~59 quartz_stairs 4  
fill ~6 ~2 ~61 ~7 ~2 ~61 stonebrick 0 
setblock ~7 ~2 ~8 brick_stairs 7 
setblock ~7 ~2 ~10 brick_stairs 6 
setblock ~7 ~2 ~22 brick_stairs 7 
setblock ~7 ~2 ~24 brick_stairs 6 
setblock ~7 ~2 ~32 brick_stairs 7 
setblock ~7 ~2 ~34 brick_stairs 6  
fill ~8 ~2 ~4 ~9 ~2 ~4 stonebrick 0  
fill ~8 ~2 ~64 ~9 ~2 ~64 stonebrick 0 
setblock ~9 ~2 ~3 stone_brick_stairs 6 
setblock ~9 ~2 ~65 stone_brick_stairs 7 
setblock ~10 ~2 ~4 stone_brick_stairs 5 
setblock ~10 ~2 ~64 stone_brick_stairs 5 
setblock ~12 ~2 ~4 stone_brick_stairs 4 
setblock ~12 ~2 ~64 stone_brick_stairs 4 
setblock ~13 ~2 ~3 stone_brick_stairs 6 
setblock ~13 ~2 ~65 stone_brick_stairs 7 
setblock ~14 ~2 ~4 stone_brick_stairs 5 
setblock ~14 ~2 ~64 stone_brick_stairs 5 
setblock ~15 ~2 ~52 redstone_torch 5 
setblock ~16 ~2 ~4 stone_brick_stairs 4 
setblock ~16 ~2 ~64 stone_brick_stairs 4 
setblock ~17 ~2 ~3 stone_brick_stairs 6 
setblock ~17 ~2 ~65 stone_brick_stairs 7 
setblock ~18 ~2 ~1 stone_slab 6  
fill ~18 ~2 ~2 ~18 ~2 ~3 stonebrick 0  
fill ~18 ~2 ~65 ~22 ~2 ~65 stonebrick 0  
fill ~18 ~2 ~66 ~18 ~2 ~65 stonebrick 0 
setblock ~18 ~2 ~67 stone_slab 6  
fill ~19 ~2 ~2 ~21 ~2 ~2 stone_brick_stairs 2  
fill ~19 ~2 ~3 ~22 ~2 ~3 stonebrick 0  
fill ~19 ~2 ~66 ~21 ~2 ~66 stone_brick_stairs 3 
setblock ~22 ~2 ~1 stone_slab 6 
setblock ~22 ~2 ~66 stonebrick 0 
setblock ~22 ~2 ~67 stone_slab 6 
setblock ~23 ~2 ~3 stone_brick_stairs 6 
setblock ~23 ~2 ~46 redstone_wire 0 
setblock ~23 ~2 ~47 stonebrick 0 
setblock ~23 ~2 ~65 stone_brick_stairs 7 
setblock ~24 ~2 ~4 stone_brick_stairs 5 
setblock ~24 ~2 ~50 unlit_redstone_torch 5 
setblock ~24 ~2 ~63 brick_stairs 5 
setblock ~24 ~2 ~64 stone_brick_stairs 5 
setblock ~26 ~2 ~4 stone_brick_stairs 4 
setblock ~26 ~2 ~63 brick_stairs 4 
setblock ~26 ~2 ~64 stone_brick_stairs 4 
setblock ~27 ~2 ~3 stone_brick_stairs 6 
setblock ~27 ~2 ~65 stone_brick_stairs 7 
setblock ~28 ~2 ~4 stone_brick_stairs 5 
setblock ~28 ~2 ~63 brick_stairs 5 
setblock ~28 ~2 ~64 stone_brick_stairs 5 
setblock ~30 ~2 ~4 stone_brick_stairs 4 
setblock ~30 ~2 ~63 brick_stairs 4 
setblock ~30 ~2 ~64 stone_brick_stairs 4 
setblock ~31 ~2 ~3 stone_brick_stairs 6  
fill ~31 ~2 ~4 ~32 ~2 ~4 stonebrick 0  
fill ~31 ~2 ~10 ~37 ~2 ~10 stonebrick 0  
fill ~31 ~2 ~16 ~37 ~2 ~16 stonebrick 0  
fill ~31 ~2 ~64 ~32 ~2 ~64 stonebrick 0 
setblock ~31 ~2 ~65 stone_brick_stairs 7  
fill ~33 ~2 ~6 ~35 ~2 ~6 stonebrick 0 
setblock ~33 ~2 ~28 glowstone 0  
fill ~33 ~2 ~35 ~34 ~2 ~35 stonebrick 0  
fill ~33 ~2 ~36 ~35 ~2 ~36 stonebrick 0  
fill ~33 ~2 ~40 ~35 ~2 ~40 stonebrick 0  
fill ~33 ~2 ~41 ~34 ~2 ~41 stonebrick 0 
setblock ~33 ~2 ~59 brick_block 0  
fill ~33 ~2 ~62 ~35 ~2 ~62 stonebrick 0 
setblock ~34 ~2 ~18 stone_brick_stairs 7 
setblock ~34 ~2 ~20 stone_brick_stairs 6 
setblock ~34 ~2 ~22 stone_brick_stairs 7 
setblock ~34 ~2 ~24 stone_brick_stairs 6 
setblock ~34 ~2 ~32 stone_brick_stairs 7 
setblock ~34 ~2 ~34 stone_brick_stairs 6 
setblock ~34 ~2 ~43 quartz_stairs 5 
setblock ~34 ~2 ~47 quartz_stairs 5 
setblock ~34 ~2 ~49 quartz_stairs 5 
setblock ~34 ~2 ~53 quartz_stairs 5 
setblock ~34 ~2 ~55 quartz_stairs 5 
setblock ~34 ~2 ~59 quartz_stairs 5 
setblock ~35 ~2 ~17 stone_brick_stairs 5 
setblock ~35 ~2 ~21 stone_brick_stairs 5 
setblock ~35 ~2 ~25 stone_brick_stairs 5  
fill ~35 ~2 ~26 ~36 ~2 ~26 stonebrick 0  
fill ~35 ~2 ~30 ~36 ~2 ~30 stonebrick 0 
setblock ~35 ~2 ~31 stone_brick_stairs 5 
setblock ~35 ~2 ~35 stone_brick_stairs 5  
fill ~35 ~2 ~42 ~35 ~2 ~43 leaves 8 
setblock ~35 ~2 ~56 leaves 8  
fill ~36 ~2 ~27 ~36 ~2 ~29 stone_brick_stairs 1 
setblock ~37 ~2 ~26 stone_slab 6 
setblock ~37 ~2 ~30 stone_slab 6  
fill ~2 ~3 ~14 ~23 ~3 ~14 stonebrick 0 
setblock ~2 ~3 ~15 stone_brick_stairs 4  
fill ~2 ~3 ~16 ~25 ~3 ~16 stonebrick 0 
setblock ~2 ~3 ~17 stone_brick_stairs 4  
fill ~2 ~3 ~18 ~25 ~3 ~18 stonebrick 0  
fill ~3 ~3 ~3 ~3 ~3 ~5 stone_brick_stairs 4  
fill ~3 ~3 ~13 ~23 ~3 ~13 stonebrick 0  
fill ~3 ~3 ~15 ~24 ~3 ~15 stonebrick 0  
fill ~3 ~3 ~17 ~25 ~3 ~17 stonebrick 0  
fill ~3 ~3 ~19 ~25 ~3 ~19 stonebrick 0  
fill ~3 ~3 ~37 ~3 ~3 ~39 stone_brick_stairs 4  
fill ~3 ~3 ~63 ~3 ~3 ~65 stone_brick_stairs 4 
setblock ~4 ~3 ~2 stone_slab 13 
setblock ~4 ~3 ~4 stonebrick 0 
setblock ~4 ~3 ~6 stone_slab 13  
fill ~4 ~3 ~12 ~23 ~3 ~12 stonebrick 0  
fill ~4 ~3 ~20 ~25 ~3 ~20 stonebrick 0 
setblock ~4 ~3 ~36 stone_slab 13 
setblock ~4 ~3 ~38 stonebrick 0 
setblock ~4 ~3 ~40 stone_slab 13 
setblock ~4 ~3 ~62 stone_slab 13 
setblock ~4 ~3 ~64 stonebrick 0 
setblock ~4 ~3 ~66 stone_slab 13  
fill ~5 ~3 ~1 ~7 ~3 ~1 stone_brick_stairs 6  
fill ~5 ~3 ~6 ~32 ~3 ~6 stonebrick 0  
fill ~5 ~3 ~7 ~5 ~5 ~7 stonebrick 0 
setblock ~5 ~3 ~8 stone_brick_stairs 4  
fill ~5 ~3 ~9 ~25 ~3 ~9 stonebrick 0 
setblock ~5 ~3 ~10 stone_brick_stairs 4  
fill ~5 ~3 ~11 ~5 ~4 ~11 stonebrick 0  
fill ~5 ~3 ~21 ~5 ~4 ~21 stonebrick 0 
setblock ~5 ~3 ~22 stone_brick_stairs 4  
fill ~5 ~3 ~23 ~10 ~3 ~23 stonebrick 0 
setblock ~5 ~3 ~24 stone_brick_stairs 4  
fill ~5 ~3 ~25 ~5 ~4 ~25 stonebrick 0  
fill ~5 ~3 ~26 ~10 ~3 ~26 stonebrick 0  
fill ~5 ~3 ~27 ~5 ~3 ~29 stone_brick_stairs 0  
fill ~5 ~3 ~30 ~9 ~3 ~30 stonebrick 0  
fill ~5 ~3 ~31 ~5 ~4 ~31 stonebrick 0 
setblock ~5 ~3 ~32 stone_brick_stairs 4  
fill ~5 ~3 ~33 ~10 ~3 ~33 stonebrick 0 
setblock ~5 ~3 ~34 stone_brick_stairs 4  
fill ~5 ~3 ~35 ~5 ~5 ~35 stonebrick 0  
fill ~5 ~3 ~36 ~9 ~3 ~36 stonebrick 0  
fill ~5 ~3 ~40 ~10 ~3 ~40 stonebrick 0 
setblock ~5 ~3 ~41 stone_brick_stairs 7 
setblock ~5 ~3 ~61 stone_brick_stairs 6  
fill ~5 ~3 ~62 ~35 ~3 ~62 stonebrick 0  
fill ~5 ~3 ~63 ~7 ~3 ~63 dropper 8  
fill ~5 ~3 ~64 ~7 ~3 ~64 dropper 8  
fill ~5 ~3 ~65 ~7 ~3 ~65 dropper 8  
fill ~5 ~3 ~67 ~7 ~3 ~67 stone_brick_stairs 7 
setblock ~6 ~3 ~2 stonebrick 0  
fill ~6 ~3 ~4 ~32 ~3 ~4 stonebrick 0  
fill ~6 ~3 ~5 ~32 ~3 ~5 stonebrick 0  
fill ~6 ~3 ~8 ~25 ~3 ~8 stonebrick 0  
fill ~6 ~3 ~10 ~25 ~3 ~10 stonebrick 0  
fill ~6 ~3 ~22 ~14 ~3 ~22 stonebrick 0  
fill ~6 ~3 ~24 ~9 ~3 ~24 stonebrick 0  
fill ~6 ~3 ~27 ~10 ~3 ~27 stonebrick 0  
fill ~6 ~3 ~28 ~9 ~3 ~28 stonebrick 0  
fill ~6 ~3 ~29 ~10 ~3 ~29 stonebrick 0  
fill ~6 ~3 ~32 ~9 ~3 ~32 stonebrick 0  
fill ~6 ~3 ~34 ~10 ~3 ~34 stonebrick 0 
setblock ~6 ~3 ~42 brick_stairs 4  
fill ~6 ~3 ~43 ~6 ~6 ~43 quartz_block 2  
fill ~6 ~3 ~44 ~6 ~3 ~46 brick_stairs 4  
fill ~6 ~3 ~47 ~6 ~6 ~47 quartz_block 2 
setblock ~6 ~3 ~48 brick_stairs 4  
fill ~6 ~3 ~49 ~6 ~6 ~49 quartz_block 2  
fill ~6 ~3 ~50 ~6 ~3 ~52 brick_stairs 4  
fill ~6 ~3 ~53 ~6 ~6 ~53 quartz_block 2 
setblock ~6 ~3 ~54 brick_stairs 4  
fill ~6 ~3 ~55 ~6 ~6 ~55 quartz_block 2  
fill ~6 ~3 ~56 ~6 ~3 ~58 brick_stairs 4  
fill ~6 ~3 ~59 ~6 ~6 ~59 quartz_block 2 
setblock ~6 ~3 ~60 brick_stairs 4  
fill ~6 ~3 ~61 ~34 ~3 ~61 stonebrick 0 
setblock ~6 ~3 ~66 stonebrick 0 
setblock ~7 ~3 ~3 stonebrick 0  
fill ~7 ~3 ~7 ~32 ~3 ~7 stonebrick 0  
fill ~7 ~3 ~11 ~24 ~3 ~11 stonebrick 0  
fill ~7 ~3 ~21 ~25 ~3 ~21 stonebrick 0  
fill ~7 ~3 ~25 ~9 ~3 ~25 stonebrick 0  
fill ~7 ~3 ~31 ~9 ~3 ~31 stonebrick 0  
fill ~7 ~3 ~35 ~9 ~3 ~35 stonebrick 0  
fill ~7 ~3 ~41 ~10 ~3 ~41 stonebrick 0 
setblock ~8 ~3 ~2 stone_slab 13  
fill ~8 ~3 ~42 ~8 ~3 ~60 stone 0  
fill ~8 ~3 ~64 ~32 ~3 ~64 stonebrick 0 
setblock ~8 ~3 ~66 stone_slab 13  
fill ~9 ~3 ~3 ~9 ~5 ~3 stonebrick 0  
fill ~9 ~3 ~37 ~9 ~3 ~41 stonebrick 0  
fill ~9 ~3 ~42 ~9 ~3 ~59 wool 13  
fill ~9 ~3 ~60 ~15 ~3 ~60 stone 0  
fill ~9 ~3 ~63 ~32 ~3 ~63 stonebrick 0  
fill ~9 ~3 ~65 ~9 ~5 ~65 stonebrick 0 
setblock ~10 ~3 ~3 stone_brick_stairs 6 
setblock ~10 ~3 ~24 stone_slab 8 
setblock ~10 ~3 ~25 stone_slab 14 
setblock ~10 ~3 ~28 stone_slab 8  
fill ~10 ~3 ~30 ~10 ~9 ~30 brick_block 0 
setblock ~10 ~3 ~31 stone_slab 14 
setblock ~10 ~3 ~32 stone_slab 8 
setblock ~10 ~3 ~35 stone_slab 14 
setblock ~10 ~3 ~36 stone_slab 8 
setblock ~10 ~3 ~37 stone_slab 14 
setblock ~10 ~3 ~38 stone_slab 8 
setblock ~10 ~3 ~39 stone_slab 14  
fill ~10 ~3 ~42 ~15 ~3 ~42 stone 0  
fill ~10 ~3 ~43 ~14 ~3 ~43 wool 13  
fill ~10 ~3 ~44 ~14 ~3 ~44 wool 13  
fill ~10 ~3 ~45 ~14 ~3 ~45 wool 13  
fill ~10 ~3 ~46 ~14 ~3 ~46 wool 13  
fill ~10 ~3 ~47 ~14 ~3 ~47 wool 13  
fill ~10 ~3 ~48 ~14 ~3 ~48 wool 13  
fill ~10 ~3 ~49 ~14 ~3 ~49 wool 13  
fill ~10 ~3 ~50 ~14 ~3 ~50 wool 13  
fill ~10 ~3 ~51 ~14 ~3 ~51 wool 13  
fill ~10 ~3 ~52 ~14 ~3 ~52 wool 13  
fill ~10 ~3 ~53 ~14 ~3 ~53 wool 13  
fill ~10 ~3 ~54 ~14 ~3 ~54 wool 13  
fill ~10 ~3 ~55 ~14 ~3 ~55 wool 13  
fill ~10 ~3 ~56 ~14 ~3 ~56 wool 13  
fill ~10 ~3 ~57 ~14 ~3 ~57 wool 13  
fill ~10 ~3 ~58 ~14 ~3 ~58 wool 13  
fill ~10 ~3 ~59 ~14 ~3 ~59 wool 13 
setblock ~10 ~3 ~65 stone_brick_stairs 7 
setblock ~11 ~3 ~3 stonebrick 0 
setblock ~11 ~3 ~23 stone_slab 8 
setblock ~11 ~3 ~24 stone_slab 14 
setblock ~11 ~3 ~25 stone_slab 8 
setblock ~11 ~3 ~26 stone_slab 14 
setblock ~11 ~3 ~27 stone_slab 8 
setblock ~11 ~3 ~28 stone_slab 14 
setblock ~11 ~3 ~29 stone_slab 8 
setblock ~11 ~3 ~30 stone_slab 14  
setblock ~11 ~3 ~31 stone_slab 8 
setblock ~11 ~3 ~32 stone_slab 14 
setblock ~11 ~3 ~33 stone_slab 8 
setblock ~11 ~3 ~34 stone_slab 14 
setblock ~11 ~3 ~35 stone_slab 8 
setblock ~11 ~3 ~36 stone_slab 14 
setblock ~11 ~3 ~37 stone_slab 8 
setblock ~11 ~3 ~38 stone_slab 14 
setblock ~11 ~3 ~39 stone_slab 8 
setblock ~11 ~3 ~40 stone_slab 14 
setblock ~11 ~3 ~41 stone_slab 8 
setblock ~11 ~3 ~65 stonebrick 0 
setblock ~12 ~3 ~3 stone_brick_stairs 6 
setblock ~12 ~3 ~23 quartz_block 0 
setblock ~12 ~3 ~24 stone_slab 8 
setblock ~12 ~3 ~25 stone_slab 14 
setblock ~12 ~3 ~26 stone_slab 8  
fill ~12 ~3 ~27 ~13 ~3 ~27 wool 14  
fill ~12 ~3 ~28 ~13 ~3 ~28 wool 14  
fill ~12 ~3 ~29 ~13 ~3 ~29 wool 14 
setblock ~12 ~3 ~30 stone_slab 8 
setblock ~12 ~3 ~31 stone_slab 14 
setblock ~12 ~3 ~32 stone_slab 8 
setblock ~12 ~3 ~33 quartz_block 0 
setblock ~12 ~3 ~34 stone_slab 8  
fill ~12 ~3 ~35 ~12 ~3 ~39 wool 14 
setblock ~12 ~3 ~40 stone_slab 8 
setblock ~12 ~3 ~41 stone_slab 14 
setblock ~12 ~3 ~65 stone_brick_stairs 7  
fill ~13 ~3 ~3 ~13 ~4 ~3 stonebrick 0 
setblock ~13 ~3 ~23 stone_slab 8 
setblock ~13 ~3 ~24 stone_slab 14 
setblock ~13 ~3 ~25 stone_slab 8 
setblock ~13 ~3 ~26 stone_slab 14 
setblock ~13 ~3 ~30 stone_slab 14 
setblock ~13 ~3 ~31 stone_slab 8 
setblock ~13 ~3 ~32 stone_slab 14 
setblock ~13 ~3 ~33 stone_slab 8 
setblock ~13 ~3 ~34 stone_slab 14 
setblock ~13 ~3 ~35 stone_slab 8 
setblock ~13 ~3 ~36 stone_slab 14 
setblock ~13 ~3 ~37 stone_slab 8 
setblock ~13 ~3 ~38 stone_slab 14 
setblock ~13 ~3 ~39 stone_slab 8 
setblock ~13 ~3 ~40 stone_slab 14 
setblock ~13 ~3 ~41 stone_slab 8  
fill ~13 ~3 ~65 ~13 ~4 ~65 stonebrick 0 
setblock ~14 ~3 ~3 stone_brick_stairs 6  
fill ~14 ~3 ~23 ~25 ~3 ~23 stonebrick 0 
setblock ~14 ~3 ~24 stone_slab 8 
setblock ~14 ~3 ~25 stone_slab 14 
setblock ~14 ~3 ~26 stone_slab 8 
setblock ~14 ~3 ~27 stone_slab 14 
setblock ~14 ~3 ~28 stone_slab 8 
setblock ~14 ~3 ~29 stone_slab 14 
setblock ~14 ~3 ~30 stone_slab 8 
setblock ~14 ~3 ~31 stone_slab 14 
setblock ~14 ~3 ~32 stone_slab 8  
fill ~14 ~3 ~33 ~18 ~3 ~33 stonebrick 0  
fill ~14 ~3 ~34 ~17 ~3 ~34 stonebrick 0 
setblock ~14 ~3 ~35 stone_slab 14 
setblock ~14 ~3 ~36 stone_slab 8 
setblock ~14 ~3 ~37 stone_slab 14 
setblock ~14 ~3 ~38 stone_slab 8 
setblock ~14 ~3 ~39 stone_slab 14  
fill ~14 ~3 ~40 ~16 ~3 ~40 stonebrick 0  
fill ~14 ~3 ~41 ~17 ~3 ~41 stonebrick 0 
setblock ~14 ~3 ~65 stone_brick_stairs 7 
setblock ~15 ~3 ~3 stonebrick 0  
fill ~15 ~3 ~22 ~17 ~3 ~22 netherrack 0 
setblock ~15 ~3 ~24 stone_slab 14 
setblock ~15 ~3 ~25 stone_slab 8  
fill ~15 ~3 ~26 ~18 ~3 ~26 stonebrick 0  
fill ~15 ~3 ~27 ~25 ~3 ~27 stonebrick 0  
fill ~15 ~3 ~28 ~25 ~3 ~28 stonebrick 0  
fill ~15 ~3 ~29 ~25 ~3 ~29 stonebrick 0  
fill ~15 ~3 ~30 ~18 ~3 ~30 stonebrick 0 
setblock ~15 ~3 ~31 stone_slab 8 
setblock ~15 ~3 ~32 stone_slab 14  
fill ~15 ~3 ~35 ~16 ~3 ~35 stonebrick 0  
fill ~15 ~3 ~36 ~16 ~3 ~36 stonebrick 0  
fill ~15 ~3 ~37 ~16 ~3 ~37 stonebrick 0  
fill ~15 ~3 ~38 ~16 ~3 ~38 stonebrick 0  
fill ~15 ~3 ~39 ~16 ~3 ~39 stonebrick 0  
fill ~15 ~3 ~43 ~15 ~3 ~51 stone 0 
setblock ~15 ~3 ~52 wool 0  
fill ~15 ~3 ~53 ~15 ~3 ~60 stone 0 
setblock ~15 ~3 ~65 stonebrick 0 
setblock ~16 ~3 ~3 stone_brick_stairs 6 
setblock ~16 ~3 ~24 stone_slab 8 
setblock ~16 ~3 ~25 stone_slab 14 
setblock ~16 ~3 ~31 stone_slab 14 
setblock ~16 ~3 ~32 stone_slab 8 
setblock ~16 ~3 ~42 stonebrick 0 
setblock ~16 ~3 ~43 stone_slab 8 
setblock ~16 ~3 ~44 stone_slab 14 
setblock ~16 ~3 ~45 stone_slab 8  
fill ~16 ~3 ~46 ~16 ~3 ~55 stonebrick 0 
setblock ~16 ~3 ~56 stone_slab 8 
setblock ~16 ~3 ~57 stone_slab 14 
setblock ~16 ~3 ~58 stone_slab 8  
fill ~16 ~3 ~59 ~16 ~3 ~64 stonebrick 0 
setblock ~16 ~3 ~65 stone_brick_stairs 7  
fill ~17 ~3 ~3 ~18 ~3 ~3 stonebrick 0 
setblock ~17 ~3 ~24 stone_slab 14 
setblock ~17 ~3 ~25 stone_slab 8 
setblock ~17 ~3 ~31 stone_slab 8 
setblock ~17 ~3 ~32 stone_slab 14  
fill ~17 ~3 ~35 ~17 ~3 ~40 stone_slab 9 
setblock ~17 ~3 ~42 stone_slab 8 
setblock ~17 ~3 ~43 stone_slab 14 
setblock ~17 ~3 ~44 stone_slab 8 
setblock ~17 ~3 ~45 stone_slab 14 
setblock ~17 ~3 ~46 stone_slab 8  
fill ~17 ~3 ~47 ~18 ~3 ~47 stonebrick 0  
fill ~17 ~3 ~48 ~19 ~3 ~48 stonebrick 0  
fill ~17 ~3 ~49 ~17 ~3 ~53 stonebrick 0 
setblock ~17 ~3 ~54 stone_slab 14 
setblock ~17 ~3 ~55 stone_slab 8 
setblock ~17 ~3 ~56 stone_slab 14 
setblock ~17 ~3 ~57 stone_slab 8 
setblock ~17 ~3 ~58 stone_slab 14 
setblock ~17 ~3 ~59 stone_slab 8 
setblock ~17 ~3 ~60 stonebrick 0  
fill ~17 ~3 ~65 ~18 ~3 ~65 stonebrick 0 
setblock ~18 ~3 ~2 stone_slab 6  
fill ~18 ~3 ~22 ~25 ~3 ~22 stonebrick 0 
setblock ~18 ~3 ~24 stone_slab 8 
setblock ~18 ~3 ~25 stone_slab 14 
setblock ~18 ~3 ~31 stone_slab 14 
setblock ~18 ~3 ~32 stone_slab 8  
fill ~18 ~3 ~34 ~22 ~3 ~34 stone_slab 9  
fill ~18 ~3 ~35 ~22 ~3 ~35 stone_slab 14  
fill ~18 ~3 ~36 ~22 ~3 ~36 stone_slab 14  
fill ~18 ~3 ~37 ~22 ~3 ~37 stone_slab 14  
fill ~18 ~3 ~38 ~22 ~3 ~38 stone_slab 14  
fill ~18 ~3 ~39 ~22 ~3 ~39 stone_slab 14  
fill ~18 ~3 ~40 ~23 ~3 ~40 stone_slab 9 
setblock ~18 ~3 ~41 double_stone_slab 1 
setblock ~18 ~3 ~42 stone_slab 14 
setblock ~18 ~3 ~43 stone_slab 8 
setblock ~18 ~3 ~44 stone_slab 14 
setblock ~18 ~3 ~45 stone_slab 8 
setblock ~18 ~3 ~46 stone_slab 14  
fill ~18 ~3 ~49 ~18 ~3 ~50 double_stone_slab 0  
fill ~18 ~3 ~51 ~20 ~3 ~51 stone_slab 8  
fill ~18 ~3 ~52 ~22 ~3 ~52 stone_slab 8  
fill ~18 ~3 ~53 ~19 ~3 ~53 stone 0 
setblock ~18 ~3 ~54 stone_slab 8 
setblock ~18 ~3 ~55 stone_slab 14 
setblock ~18 ~3 ~56 stone_slab 8 
setblock ~18 ~3 ~57 stone_slab 14 
setblock ~18 ~3 ~58 stone_slab 8 
setblock ~18 ~3 ~59 stone_slab 14 
setblock ~18 ~3 ~60 stone_slab 8 
setblock ~18 ~3 ~66 stone_slab 6  
fill ~19 ~3 ~3 ~21 ~3 ~3 stone_brick_stairs 2 
setblock ~19 ~3 ~24 stone_slab 14 
setblock ~19 ~3 ~25 stone_slab 8 
setblock ~19 ~3 ~26 stone_slab 14 
setblock ~19 ~3 ~30 stone_slab 14 
setblock ~19 ~3 ~31 stone_slab 8 
setblock ~19 ~3 ~32 stone_slab 14 
setblock ~19 ~3 ~33 stone_slab 8 
setblock ~19 ~3 ~41 stone_slab 14 
setblock ~19 ~3 ~42 stone_slab 8 
setblock ~19 ~3 ~43 wool 14  
fill ~19 ~3 ~44 ~21 ~3 ~44 wool 4 
setblock ~19 ~3 ~45 wool 14 
setblock ~19 ~3 ~46 stone_slab 8 
setblock ~19 ~3 ~47 stone_slab 14  
fill ~19 ~3 ~49 ~20 ~3 ~49 stone_slab 8  
fill ~19 ~3 ~50 ~20 ~3 ~50 stone_slab 8 
setblock ~19 ~3 ~54 stone_slab 14 
setblock ~19 ~3 ~55 stone_slab 8  
fill ~19 ~3 ~56 ~21 ~3 ~56 wool 11  
fill ~19 ~3 ~57 ~21 ~3 ~57 wool 11  
fill ~19 ~3 ~58 ~21 ~3 ~58 wool 11 
setblock ~19 ~3 ~59 stone_slab 8 
setblock ~19 ~3 ~60 stone_slab 14  
fill ~19 ~3 ~65 ~21 ~3 ~65 stone_brick_stairs 3 
setblock ~20 ~3 ~24 stone_slab 8 
setblock ~20 ~3 ~25 stone_slab 14 
setblock ~20 ~3 ~26 stone_slab 8 
setblock ~20 ~3 ~30 stone_slab 8 
setblock ~20 ~3 ~31 stone_slab 14 
setblock ~20 ~3 ~32 stone_slab 8 
setblock ~20 ~3 ~33 quartz_block 0 
setblock ~20 ~3 ~41 stone_slab 8 
setblock ~20 ~3 ~42 stone_slab 14 
setblock ~20 ~3 ~43 wool 4 
setblock ~20 ~3 ~45 wool 4 
setblock ~20 ~3 ~46 stone_slab 14  
fill ~20 ~3 ~47 ~20 ~3 ~52 stone_slab 8 
setblock ~20 ~3 ~53 stone_slab 14 
setblock ~20 ~3 ~54 stone_slab 8 
setblock ~20 ~3 ~55 stone_slab 14 
setblock ~20 ~3 ~59 stone_slab 14 
setblock ~20 ~3 ~60 stone_slab 8 
setblock ~21 ~3 ~24 stone_slab 14 
setblock ~21 ~3 ~25 stone_slab 8 
setblock ~21 ~3 ~26 stone_slab 14 
setblock ~21 ~3 ~30 stone_slab 14 
setblock ~21 ~3 ~31 stone_slab 8 
setblock ~21 ~3 ~32 stone_slab 14 
setblock ~21 ~3 ~33 stone_slab 8 
setblock ~21 ~3 ~41 stone_slab 14 
setblock ~21 ~3 ~42 stone_slab 8 
setblock ~21 ~3 ~43 wool 14 
setblock ~21 ~3 ~45 wool 14 
setblock ~21 ~3 ~46 stone_slab 8 
setblock ~21 ~3 ~47 stone_slab 14  
fill ~21 ~3 ~48 ~23 ~3 ~48 stonebrick 0  
fill ~21 ~3 ~49 ~22 ~3 ~49 double_stone_slab 0  
fill ~21 ~3 ~50 ~21 ~3 ~51 double_stone_slab 0  
fill ~21 ~3 ~53 ~22 ~3 ~53 stone 0 
setblock ~21 ~3 ~54 stone_slab 14 
setblock ~21 ~3 ~55 stone_slab 8 
setblock ~21 ~3 ~59 stone_slab 8 
setblock ~21 ~3 ~60 stone_slab 14 
setblock ~22 ~3 ~2 stone_slab 6 
setblock ~22 ~3 ~24 stone_slab 8 
setblock ~22 ~3 ~25 stone_slab 14  
fill ~22 ~3 ~26 ~25 ~3 ~26 stonebrick 0  
fill ~22 ~3 ~30 ~25 ~3 ~30 stonebrick 0 
setblock ~22 ~3 ~31 stone_slab 14 
setblock ~22 ~3 ~32 stone_slab 8  
fill ~22 ~3 ~33 ~25 ~3 ~33 stonebrick 0  
fill ~22 ~3 ~41 ~26 ~3 ~41 stonebrick 0 
setblock ~22 ~3 ~42 stone_slab 14 
setblock ~22 ~3 ~43 stone_slab 8 
setblock ~22 ~3 ~44 stone_slab 14 
setblock ~22 ~3 ~45 stone_slab 8 
setblock ~22 ~3 ~46 stone_slab 14 
setblock ~22 ~3 ~47 stonebrick 0 
setblock ~22 ~3 ~51 double_stone_slab 0 
setblock ~22 ~3 ~54 stone_slab 8 
setblock ~22 ~3 ~55 stone_slab 14 
setblock ~22 ~3 ~56 stone_slab 8 
setblock ~22 ~3 ~57 stone_slab 14 
setblock ~22 ~3 ~58 stone_slab 8 
setblock ~22 ~3 ~59 stone_slab 14 
setblock ~22 ~3 ~60 stone_slab 8  
fill ~22 ~3 ~65 ~23 ~3 ~65 stonebrick 0 
setblock ~22 ~3 ~66 stone_slab 6  
fill ~23 ~3 ~3 ~23 ~4 ~3 stonebrick 0 
setblock ~23 ~3 ~24 stone_slab 14 
setblock ~23 ~3 ~25 stone_slab 8 
setblock ~23 ~3 ~31 stone_slab 8 
setblock ~23 ~3 ~32 stone_slab 14  
fill ~23 ~3 ~34 ~26 ~3 ~34 stonebrick 0  
fill ~23 ~3 ~35 ~23 ~3 ~40 stone_slab 9 
setblock ~23 ~3 ~42 stone_slab 8 
setblock ~23 ~3 ~43 stone_slab 14 
setblock ~23 ~3 ~44 stone_slab 8 
setblock ~23 ~3 ~45 stone_slab 14 
setblock ~23 ~3 ~46 stone_slab 8 
setblock ~23 ~3 ~47 redstone_wire 0 
setblock ~23 ~3 ~49 stonebrick 0  
fill ~23 ~3 ~51 ~23 ~3 ~53 stonebrick 0 
setblock ~23 ~3 ~54 stone_slab 14 
setblock ~23 ~3 ~55 stone_slab 8 
setblock ~23 ~3 ~56 stone_slab 14 
setblock ~23 ~3 ~57 stone_slab 8 
setblock ~23 ~3 ~58 stone_slab 14 
setblock ~23 ~3 ~59 stone_slab 8  
fill ~23 ~3 ~60 ~24 ~3 ~60 stonebrick 0 
setblock ~24 ~3 ~3 stone_brick_stairs 6 
setblock ~24 ~3 ~12 stone_slab 8 
setblock ~24 ~3 ~13 quartz_block 0 
setblock ~24 ~3 ~14 stone_slab 8 
setblock ~24 ~3 ~24 stone_slab 8 
setblock ~24 ~3 ~25 stone_slab 14 
setblock ~24 ~3 ~31 stone_slab 14 
setblock ~24 ~3 ~32 stone_slab 8  
fill ~24 ~3 ~35 ~25 ~3 ~35 stonebrick 0  
fill ~24 ~3 ~36 ~25 ~3 ~36 stonebrick 0  
fill ~24 ~3 ~37 ~25 ~3 ~37 stonebrick 0  
fill ~24 ~3 ~38 ~25 ~3 ~38 stonebrick 0  
fill ~24 ~3 ~39 ~25 ~3 ~39 stonebrick 0  
fill ~24 ~3 ~40 ~26 ~3 ~40 stonebrick 0 
setblock ~24 ~3 ~42 stonebrick 0 
setblock ~24 ~3 ~43 stone_slab 8 
setblock ~24 ~3 ~44 stone_slab 14 
setblock ~24 ~3 ~45 stone_slab 8 
setblock ~24 ~3 ~46 stonebrick 0  
fill ~24 ~3 ~47 ~24 ~3 ~49 quartz_block 0 
setblock ~24 ~3 ~50 sticky_piston 5  
fill ~24 ~3 ~51 ~24 ~3 ~54 quartz_block 0 
setblock ~24 ~3 ~55 stonebrick 0 
setblock ~24 ~3 ~56 stone_slab 8 
setblock ~24 ~3 ~57 stone_slab 14 
setblock ~24 ~3 ~58 stone_slab 8 
setblock ~24 ~3 ~59 stonebrick 0 
setblock ~24 ~3 ~65 stone_brick_stairs 7 
setblock ~25 ~3 ~3 stonebrick 0 
setblock ~25 ~3 ~11 stone_slab 8 
setblock ~25 ~3 ~12 stone_slab 14 
setblock ~25 ~3 ~13 stone_slab 8 
setblock ~25 ~3 ~14 stone_slab 14 
setblock ~25 ~3 ~15 stone_slab 8 
setblock ~25 ~3 ~24 stone_slab 14 
setblock ~25 ~3 ~25 double_stone_slab 0 
setblock ~25 ~3 ~31 double_stone_slab 0 
setblock ~25 ~3 ~32 stone_slab 14  
fill ~25 ~3 ~42 ~31 ~3 ~42 dropper 9  
fill ~25 ~3 ~43 ~25 ~3 ~59 dropper 9 
setblock ~25 ~3 ~60 activator_rail 0 
setblock ~25 ~3 ~65 stonebrick 0 
setblock ~26 ~3 ~3 stone_brick_stairs 6 
setblock ~26 ~3 ~8 stone_slab 8 
setblock ~26 ~3 ~9 stone_slab 14 
setblock ~26 ~3 ~10 stone_slab 8 
setblock ~26 ~3 ~11 stonebrick 0 
setblock ~26 ~3 ~12 stone_slab 8 
setblock ~26 ~3 ~13 quartz_block 0 
setblock ~26 ~3 ~14 stone_slab 8 
setblock ~26 ~3 ~15 stonebrick 0 
setblock ~26 ~3 ~16 stone_slab 8 
setblock ~26 ~3 ~17 stone_slab 14 
setblock ~26 ~3 ~18 stone_slab 8 
setblock ~26 ~3 ~19 stone_slab 14 
setblock ~26 ~3 ~20 stone_slab 8 
setblock ~26 ~3 ~21 stone_slab 14 
setblock ~26 ~3 ~22 stone_slab 8  
fill ~26 ~3 ~23 ~26 ~16 ~23 brick_block 0 
setblock ~26 ~3 ~24 stone_slab 8 
setblock ~26 ~3 ~25 stone_slab 14 
setblock ~26 ~3 ~26 stone_slab 8 
setblock ~26 ~3 ~27 stone_slab 14 
setblock ~26 ~3 ~28 stone_slab 8 
setblock ~26 ~3 ~29 stone_slab 14 
setblock ~26 ~3 ~30 stone_slab 8 
setblock ~26 ~3 ~31 stone_slab 14 
setblock ~26 ~3 ~32 stone_slab 8  
fill ~26 ~3 ~33 ~26 ~15 ~33 brick_block 0 
setblock ~26 ~3 ~35 stone_slab 14 
setblock ~26 ~3 ~36 stone_slab 8 
setblock ~26 ~3 ~37 stone_slab 14 
setblock ~26 ~3 ~38 stone_slab 8 
setblock ~26 ~3 ~39 stone_slab 14  
fill ~26 ~3 ~43 ~30 ~3 ~43 stone 0  
fill ~26 ~3 ~44 ~30 ~3 ~44 stone 0  
fill ~26 ~3 ~45 ~30 ~3 ~45 stone 0  
fill ~26 ~3 ~46 ~30 ~3 ~46 stone 0  
fill ~26 ~3 ~47 ~30 ~3 ~47 stone 0  
fill ~26 ~3 ~48 ~30 ~3 ~48 stone 0  
fill ~26 ~3 ~49 ~30 ~3 ~49 stone 0  
fill ~26 ~3 ~50 ~30 ~3 ~50 stone 0  
fill ~26 ~3 ~51 ~30 ~3 ~51 stone 0  
fill ~26 ~3 ~52 ~30 ~3 ~52 stone 0  
fill ~26 ~3 ~53 ~30 ~3 ~53 stone 0  
fill ~26 ~3 ~54 ~30 ~3 ~54 stone 0  
fill ~26 ~3 ~55 ~30 ~3 ~55 stone 0  
fill ~26 ~3 ~56 ~30 ~3 ~56 stone 0  
fill ~26 ~3 ~57 ~30 ~3 ~57 stone 0  
fill ~26 ~3 ~58 ~30 ~3 ~58 stone 0  
fill ~26 ~3 ~59 ~30 ~3 ~59 stone 0  
fill ~26 ~3 ~60 ~28 ~3 ~60 dropper 9 
setblock ~26 ~3 ~65 stone_brick_stairs 7  
fill ~27 ~3 ~3 ~27 ~4 ~3 stonebrick 0 
setblock ~27 ~3 ~8 stone_slab 14 
setblock ~27 ~3 ~9 stone_slab 8 
setblock ~27 ~3 ~10 stone_slab 14 
setblock ~27 ~3 ~11 stone_slab 8 
setblock ~27 ~3 ~12 stone_slab 14 
setblock ~27 ~3 ~13 stone_slab 8 
setblock ~27 ~3 ~14 stone_slab 14 
setblock ~27 ~3 ~15 stone_slab 8 
setblock ~27 ~3 ~16 stone_slab 14 
setblock ~27 ~3 ~17 stone_slab 8 
setblock ~27 ~3 ~18 stone_slab 14 
setblock ~27 ~3 ~19 stone_slab 8 
setblock ~27 ~3 ~20 stone_slab 14 
setblock ~27 ~3 ~21 stone_slab 8 
setblock ~27 ~3 ~22 stone_slab 14 
setblock ~27 ~3 ~23 double_stone_slab 0 
setblock ~27 ~3 ~24 stone_slab 14 
setblock ~27 ~3 ~25 stone_slab 8 
setblock ~27 ~3 ~26 stone_slab 14  
fill ~27 ~3 ~27 ~28 ~3 ~27 wool 14  
fill ~27 ~3 ~28 ~28 ~3 ~28 wool 14  
fill ~27 ~3 ~29 ~28 ~3 ~29 wool 14 
setblock ~27 ~3 ~30 stone_slab 14 
setblock ~27 ~3 ~31 stone_slab 8 
setblock ~27 ~3 ~32 stone_slab 14 
setblock ~27 ~3 ~33 double_stone_slab 0 
setblock ~27 ~3 ~34 stone_slab 14 
setblock ~27 ~3 ~35 stone_slab 8 
setblock ~27 ~3 ~36 stone_slab 14 
setblock ~27 ~3 ~37 stone_slab 8 
setblock ~27 ~3 ~38 stone_slab 14 
setblock ~27 ~3 ~39 stone_slab 8 
setblock ~27 ~3 ~40 stone_slab 14 
setblock ~27 ~3 ~41 stone_slab 8  
fill ~27 ~3 ~65 ~27 ~4 ~65 stonebrick 0 
setblock ~28 ~3 ~3 stone_brick_stairs 6 
setblock ~28 ~3 ~8 stone_slab 8 
setblock ~28 ~3 ~9 stone_slab 14 
setblock ~28 ~3 ~10 stone_slab 8 
setblock ~28 ~3 ~11 stone_slab 14 
setblock ~28 ~3 ~12 stone_slab 8 
setblock ~28 ~3 ~13 stone_slab 14 
setblock ~28 ~3 ~14 stone_slab 8 
setblock ~28 ~3 ~15 stone_slab 14 
setblock ~28 ~3 ~16 stone_slab 8  
fill ~28 ~3 ~17 ~28 ~3 ~21 wool 14 
setblock ~28 ~3 ~22 stone_slab 8 
setblock ~28 ~3 ~23 quartz_block 0 
setblock ~28 ~3 ~24 stone_slab 8 
setblock ~28 ~3 ~25 stone_slab 14 
setblock ~28 ~3 ~26 stone_slab 8 
setblock ~28 ~3 ~30 stone_slab 8 
setblock ~28 ~3 ~31 stone_slab 14 
setblock ~28 ~3 ~32 stone_slab 8 
setblock ~28 ~3 ~33 quartz_block 0 
setblock ~28 ~3 ~34 stone_slab 8  
fill ~28 ~3 ~35 ~28 ~3 ~39 wool 14 
setblock ~28 ~3 ~40 stone_slab 8 
setblock ~28 ~3 ~41 stone_slab 14 
setblock ~28 ~3 ~65 stone_brick_stairs 7 
setblock ~29 ~3 ~3 stonebrick 0 
setblock ~29 ~3 ~8 stone_slab 14 
setblock ~29 ~3 ~9 stone_slab 8 
setblock ~29 ~3 ~10 stone_slab 14 
setblock ~29 ~3 ~11 stone_slab 8 
setblock ~29 ~3 ~12 stone_slab 14 
setblock ~29 ~3 ~13 stone_slab 8 
setblock ~29 ~3 ~14 stone_slab 14 
setblock ~29 ~3 ~15 stone_slab 8 
setblock ~29 ~3 ~16 stone_slab 14 
setblock ~29 ~3 ~17 stone_slab 8 
setblock ~29 ~3 ~18 stone_slab 14 
setblock ~29 ~3 ~19 stone_slab 8 
setblock ~29 ~3 ~20 stone_slab 14 
setblock ~29 ~3 ~21 stone_slab 8 
setblock ~29 ~3 ~22 stone_slab 14 
setblock ~29 ~3 ~23 double_stone_slab 0 
setblock ~29 ~3 ~24 stone_slab 14 
setblock ~29 ~3 ~25 stone_slab 8 
setblock ~29 ~3 ~26 stone_slab 14 
setblock ~29 ~3 ~27 stone_slab 8 
setblock ~29 ~3 ~28 stone_slab 14 
setblock ~29 ~3 ~29 stone_slab 8 
setblock ~29 ~3 ~30 stone_slab 14 
setblock ~29 ~3 ~31 stone_slab 8 
setblock ~29 ~3 ~32 stone_slab 14 
setblock ~29 ~3 ~33 double_stone_slab 0 
setblock ~29 ~3 ~34 stone_slab 14 
setblock ~29 ~3 ~35 stone_slab 8 
setblock ~29 ~3 ~36 stone_slab 14 
setblock ~29 ~3 ~37 stone_slab 8 
setblock ~29 ~3 ~38 stone_slab 14 
setblock ~29 ~3 ~39 stone_slab 8 
setblock ~29 ~3 ~40 stone_slab 14 
setblock ~29 ~3 ~41 stone_slab 8 
setblock ~29 ~3 ~60 stonebrick 0 
setblock ~29 ~3 ~65 stonebrick 0 
setblock ~30 ~3 ~3 stone_brick_stairs 6  
fill ~30 ~3 ~8 ~33 ~3 ~8 dropper 8  
fill ~30 ~3 ~9 ~33 ~3 ~9 dropper 8 
setblock ~30 ~3 ~10 stone_slab 8 
setblock ~30 ~3 ~11 stone_slab 14 
setblock ~30 ~3 ~12 stone_slab 8 
setblock ~30 ~3 ~13 stone_slab 14 
setblock ~30 ~3 ~14 stone_slab 8 
setblock ~30 ~3 ~15 stone_slab 14 
setblock ~30 ~3 ~16 stone_slab 8  
fill ~30 ~3 ~17 ~30 ~4 ~17 stone_slab 14 
setblock ~30 ~3 ~18 stone_slab 8 
setblock ~30 ~3 ~19 stone_slab 14 
setblock ~30 ~3 ~20 stone_slab 8 
setblock ~30 ~3 ~21 stone_slab 14 
setblock ~30 ~3 ~22 stone_slab 8  
fill ~30 ~3 ~23 ~30 ~17 ~23 brick_block 0 
setblock ~30 ~3 ~24 double_stone_slab 0 
setblock ~30 ~3 ~25 stone_slab 14  
fill ~30 ~3 ~26 ~30 ~9 ~26 brick_block 0  
fill ~30 ~3 ~27 ~30 ~6 ~27 quartz_block 0 
setblock ~30 ~3 ~28 double_stone_slab 0  
fill ~30 ~3 ~29 ~30 ~6 ~29 quartz_block 0  
fill ~30 ~3 ~30 ~30 ~9 ~30 brick_block 0 
setblock ~30 ~3 ~31 stone_slab 14 
setblock ~30 ~3 ~32 double_stone_slab 0  
fill ~30 ~3 ~33 ~30 ~14 ~33 brick_block 0  
fill ~30 ~3 ~34 ~34 ~3 ~34 stonebrick 0 
setblock ~30 ~3 ~35 stone_slab 14 
setblock ~30 ~3 ~36 stone_slab 8 
setblock ~30 ~3 ~37 stone_slab 14 
setblock ~30 ~3 ~38 stone_slab 8 
setblock ~30 ~3 ~39 stone_slab 14  
fill ~30 ~3 ~40 ~35 ~3 ~40 stonebrick 0  
fill ~30 ~3 ~41 ~34 ~3 ~41 stonebrick 0  
fill ~30 ~3 ~60 ~31 ~3 ~60 dropper 9 
setblock ~30 ~3 ~65 stone_brick_stairs 7  
fill ~31 ~3 ~3 ~31 ~5 ~3 stonebrick 0  
fill ~31 ~3 ~10 ~32 ~3 ~10 stonebrick 0 
setblock ~31 ~3 ~12 double_stone_slab 6 
setblock ~31 ~3 ~13 double_stone_slab 0 
setblock ~31 ~3 ~14 double_stone_slab 6  
fill ~31 ~3 ~16 ~37 ~3 ~16 stonebrick 0  
fill ~31 ~3 ~17 ~35 ~3 ~17 stonebrick 0  
fill ~31 ~3 ~18 ~34 ~3 ~18 stonebrick 0  
fill ~31 ~3 ~19 ~35 ~3 ~19 stonebrick 0  
fill ~31 ~3 ~20 ~34 ~3 ~20 stonebrick 0  
fill ~31 ~3 ~21 ~35 ~3 ~21 stonebrick 0  
fill ~31 ~3 ~22 ~34 ~3 ~22 stonebrick 0  
fill ~31 ~3 ~24 ~31 ~4 ~24 brick_block 0  
fill ~31 ~3 ~25 ~31 ~4 ~25 brick_block 0  
fill ~31 ~3 ~26 ~35 ~3 ~26 stonebrick 0  
fill ~31 ~3 ~27 ~34 ~3 ~27 stonebrick 0  
fill ~31 ~3 ~28 ~34 ~3 ~28 stonebrick 0  
fill ~31 ~3 ~29 ~34 ~3 ~29 stonebrick 0  
fill ~31 ~3 ~30 ~35 ~3 ~30 stonebrick 0  
fill ~31 ~3 ~31 ~35 ~3 ~31 stonebrick 0  
fill ~31 ~3 ~32 ~34 ~3 ~32 stonebrick 0  
fill ~31 ~3 ~33 ~35 ~3 ~33 stonebrick 0  
fill ~31 ~3 ~35 ~31 ~3 ~41 stonebrick 0  
fill ~31 ~3 ~43 ~31 ~3 ~60 dropper 9  
fill ~31 ~3 ~65 ~31 ~5 ~65 stonebrick 0 
setblock ~32 ~3 ~2 stone_slab 13  
fill ~32 ~3 ~11 ~36 ~3 ~11 dropper 8  
fill ~32 ~3 ~12 ~36 ~3 ~12 dropper 8  
fill ~32 ~3 ~13 ~36 ~3 ~13 dropper 8  
fill ~32 ~3 ~14 ~36 ~3 ~14 dropper 8  
fill ~32 ~3 ~15 ~36 ~3 ~15 dropper 8  
fill ~32 ~3 ~24 ~34 ~3 ~24 stonebrick 0  
fill ~32 ~3 ~25 ~35 ~3 ~25 stonebrick 0 
setblock ~32 ~3 ~35 quartz_block 10  
fill ~32 ~3 ~36 ~32 ~16 ~36 brick_block 0 
setblock ~32 ~3 ~42 quartz_block 0 
setblock ~32 ~3 ~43 stonebrick 0  
fill ~32 ~3 ~44 ~33 ~3 ~44 quartz_block 0  
fill ~32 ~3 ~45 ~33 ~3 ~45 quartz_block 0  
fill ~32 ~3 ~46 ~33 ~3 ~46 quartz_block 0 
setblock ~32 ~3 ~47 stonebrick 0 
setblock ~32 ~3 ~48 quartz_block 0 
setblock ~32 ~3 ~49 stonebrick 0  
fill ~32 ~3 ~50 ~33 ~3 ~50 quartz_block 0  
fill ~32 ~3 ~51 ~33 ~3 ~51 quartz_block 0  
fill ~32 ~3 ~52 ~33 ~3 ~52 quartz_block 0 
setblock ~32 ~3 ~53 stonebrick 0 
setblock ~32 ~3 ~54 quartz_block 0 
setblock ~32 ~3 ~55 stonebrick 0  
fill ~32 ~3 ~56 ~33 ~3 ~56 quartz_block 0  
fill ~32 ~3 ~57 ~33 ~3 ~57 quartz_block 0  
fill ~32 ~3 ~58 ~33 ~3 ~58 quartz_block 0  
fill ~32 ~3 ~59 ~33 ~3 ~59 stonebrick 0  
fill ~32 ~3 ~60 ~32 ~3 ~59 stonebrick 0 
setblock ~32 ~3 ~66 stone_slab 13  
fill ~33 ~3 ~1 ~35 ~3 ~1 stone_brick_stairs 6  
fill ~33 ~3 ~3 ~35 ~3 ~3 dropper 8  
fill ~33 ~3 ~4 ~35 ~3 ~4 dropper 8  
fill ~33 ~3 ~5 ~35 ~3 ~5 dropper 8  
fill ~33 ~3 ~6 ~33 ~3 ~9 dropper 8 
setblock ~33 ~3 ~10 activator_rail 0  
fill ~33 ~3 ~23 ~35 ~3 ~23 stonebrick 0  
fill ~33 ~3 ~35 ~35 ~3 ~35 stonebrick 0  
fill ~33 ~3 ~36 ~35 ~3 ~36 stonebrick 0  
fill ~33 ~3 ~37 ~35 ~3 ~37 dropper 8  
fill ~33 ~3 ~38 ~35 ~3 ~38 dropper 8  
fill ~33 ~3 ~39 ~35 ~3 ~39 dropper 8  
fill ~33 ~3 ~63 ~35 ~3 ~63 dropper 8  
fill ~33 ~3 ~64 ~35 ~3 ~64 dropper 8  
fill ~33 ~3 ~65 ~35 ~3 ~65 dropper 8  
fill ~33 ~3 ~67 ~35 ~3 ~67 stone_brick_stairs 7 
setblock ~34 ~3 ~2 stonebrick 0  
fill ~34 ~3 ~6 ~35 ~3 ~6 stonebrick 0 
setblock ~34 ~3 ~8 stonebrick 0  
fill ~34 ~3 ~10 ~37 ~3 ~10 stonebrick 0 
setblock ~34 ~3 ~42 brick_stairs 5  
fill ~34 ~3 ~43 ~34 ~6 ~43 quartz_block 2  
fill ~34 ~3 ~44 ~34 ~3 ~46 brick_stairs 5  
fill ~34 ~3 ~47 ~34 ~6 ~47 quartz_block 2 
setblock ~34 ~3 ~48 brick_stairs 5  
fill ~34 ~3 ~49 ~34 ~6 ~49 quartz_block 2  
fill ~34 ~3 ~50 ~34 ~3 ~52 brick_stairs 5  
fill ~34 ~3 ~53 ~34 ~6 ~53 quartz_block 2 
setblock ~34 ~3 ~54 brick_stairs 5  
fill ~34 ~3 ~55 ~34 ~6 ~55 quartz_block 2  
fill ~34 ~3 ~56 ~34 ~3 ~58 brick_stairs 5  
fill ~34 ~3 ~59 ~34 ~6 ~59 quartz_block 2 
setblock ~34 ~3 ~60 brick_stairs 5 
setblock ~34 ~3 ~66 stonebrick 0 
setblock ~35 ~3 ~7 spruce_stairs 7 
setblock ~35 ~3 ~18 stone_brick_stairs 5 
setblock ~35 ~3 ~20 stone_brick_stairs 5 
setblock ~35 ~3 ~22 stone_brick_stairs 5 
setblock ~35 ~3 ~24 stone_brick_stairs 5  
fill ~35 ~3 ~27 ~35 ~3 ~29 stone_brick_stairs 1 
setblock ~35 ~3 ~32 stone_brick_stairs 5 
setblock ~35 ~3 ~34 stone_brick_stairs 5 
setblock ~35 ~3 ~41 stone_slab 13 
setblock ~35 ~3 ~61 stone_brick_stairs 6 
setblock ~36 ~3 ~2 stone_slab 13 
setblock ~36 ~3 ~4 stonebrick 0 
setblock ~36 ~3 ~6 stone_slab 13 
setblock ~36 ~3 ~9 spruce_stairs 6 
setblock ~36 ~3 ~17 spruce_stairs 7 
setblock ~36 ~3 ~26 stone_slab 6 
setblock ~36 ~3 ~30 stone_slab 6 
setblock ~36 ~3 ~36 stone_slab 13 
setblock ~36 ~3 ~38 stonebrick 0 
setblock ~36 ~3 ~40 stone_slab 13 
setblock ~36 ~3 ~62 stone_slab 13 
setblock ~36 ~3 ~64 stonebrick 0 
setblock ~36 ~3 ~66 stone_slab 13  
fill ~37 ~3 ~3 ~37 ~3 ~5 stone_brick_stairs 5  
fill ~37 ~3 ~11 ~37 ~3 ~16 stonebrick 0  
fill ~37 ~3 ~37 ~37 ~3 ~39 stone_brick_stairs 5  
fill ~37 ~3 ~63 ~37 ~3 ~65 stone_brick_stairs 5  
fill ~38 ~3 ~11 ~38 ~3 ~12 spruce_stairs 5 
setblock ~38 ~3 ~13 spruce_stairs 1  
fill ~38 ~3 ~14 ~38 ~3 ~15 spruce_stairs 5  
fill ~2 ~4 ~3 ~2 ~4 ~5 trapdoor 14  
fill ~2 ~4 ~14 ~2 ~3 ~14 stonebrick 0  
fill ~2 ~4 ~15 ~2 ~4 ~17 fence 0  
fill ~2 ~4 ~18 ~2 ~3 ~18 stonebrick 0  
fill ~2 ~4 ~37 ~2 ~4 ~39 trapdoor 14  
fill ~2 ~4 ~63 ~2 ~4 ~65 trapdoor 14 
setblock ~3 ~4 ~2 spruce_stairs 6  
fill ~3 ~4 ~3 ~3 ~4 ~5 grass 0 
setblock ~3 ~4 ~6 spruce_stairs 7  
fill ~3 ~4 ~13 ~3 ~3 ~13 stonebrick 0  
fill ~3 ~4 ~19 ~3 ~3 ~19 stonebrick 0 
setblock ~3 ~4 ~36 spruce_stairs 6  
fill ~3 ~4 ~37 ~3 ~4 ~39 grass 0 
setblock ~3 ~4 ~40 spruce_stairs 7 
setblock ~3 ~4 ~62 spruce_stairs 6  
fill ~3 ~4 ~63 ~3 ~4 ~65 grass 0 
setblock ~3 ~4 ~66 spruce_stairs 7 
setblock ~4 ~4 ~1 spruce_stairs 4 
setblock ~4 ~4 ~2 planks 1  
fill ~4 ~4 ~3 ~4 ~9 ~3 brick_block 0  
fill ~4 ~4 ~4 ~4 ~4 ~5 brick_block 0 
setblock ~4 ~4 ~6 planks 1 
setblock ~4 ~4 ~7 spruce_stairs 4  
fill ~4 ~4 ~12 ~4 ~3 ~12 stonebrick 0  
fill ~4 ~4 ~20 ~4 ~3 ~20 stonebrick 0 
setblock ~4 ~4 ~35 spruce_stairs 4 
setblock ~4 ~4 ~36 planks 1  
fill ~4 ~4 ~37 ~4 ~9 ~37 brick_block 0  
fill ~4 ~4 ~38 ~4 ~4 ~39 brick_block 0 
setblock ~4 ~4 ~40 planks 1 
setblock ~4 ~4 ~41 spruce_stairs 4 
setblock ~4 ~4 ~61 spruce_stairs 4 
setblock ~4 ~4 ~62 planks 1  
fill ~4 ~4 ~63 ~4 ~9 ~63 brick_block 0  
fill ~4 ~4 ~64 ~4 ~4 ~65 brick_block 0 
setblock ~4 ~4 ~66 planks 1 
setblock ~4 ~4 ~67 spruce_stairs 4  
fill ~5 ~4 ~0 ~7 ~4 ~0 trapdoor 12  
fill ~5 ~4 ~1 ~7 ~4 ~1 grass 0  
fill ~5 ~4 ~2 ~7 ~4 ~2 brick_block 0  
fill ~5 ~4 ~6 ~5 ~9 ~6 brick_block 0  
fill ~5 ~4 ~8 ~5 ~4 ~10 fence 0  
fill ~5 ~4 ~22 ~5 ~4 ~24 fence 0  
fill ~5 ~4 ~32 ~5 ~4 ~34 fence 0  
fill ~5 ~4 ~36 ~5 ~9 ~36 brick_block 0  
fill ~5 ~4 ~40 ~7 ~4 ~40 brick_block 0 
setblock ~5 ~4 ~41 grass 0 
setblock ~5 ~4 ~42 trapdoor 13 
setblock ~5 ~4 ~60 trapdoor 12 
setblock ~5 ~4 ~61 grass 0  
fill ~5 ~4 ~62 ~8 ~4 ~62 brick_block 0  
fill ~5 ~4 ~66 ~7 ~4 ~66 brick_block 0  
fill ~5 ~4 ~67 ~7 ~4 ~67 grass 0  
fill ~5 ~4 ~68 ~7 ~4 ~68 trapdoor 13 
setblock ~6 ~4 ~6 wooden_door 3 
setblock ~6 ~4 ~36 wooden_door 1  
fill ~6 ~4 ~41 ~6 ~14 ~41 quartz_block 2  
fill ~6 ~4 ~61 ~6 ~14 ~61 quartz_block 2  
fill ~7 ~4 ~6 ~8 ~4 ~6 brick_block 0  
fill ~7 ~4 ~36 ~8 ~4 ~36 brick_block 0  
fill ~7 ~4 ~41 ~7 ~15 ~41 brick_block 0  
fill ~7 ~4 ~42 ~7 ~14 ~42 brick_block 0  
fill ~7 ~4 ~43 ~7 ~14 ~43 brick_block 0  
fill ~7 ~4 ~44 ~7 ~7 ~44 glass 0  
fill ~7 ~4 ~45 ~7 ~7 ~45 glass 0  
fill ~7 ~4 ~46 ~7 ~7 ~46 glass 0  
fill ~7 ~4 ~47 ~7 ~14 ~47 brick_block 0  
fill ~7 ~4 ~48 ~7 ~15 ~48 brick_block 0  
fill ~7 ~4 ~49 ~7 ~19 ~49 brick_block 0  
fill ~7 ~4 ~50 ~7 ~7 ~50 glass 0  
fill ~7 ~4 ~51 ~7 ~7 ~51 glass 0  
fill ~7 ~4 ~52 ~7 ~7 ~52 glass 0  
fill ~7 ~4 ~53 ~7 ~19 ~53 brick_block 0  
fill ~7 ~4 ~54 ~7 ~15 ~54 brick_block 0  
fill ~7 ~4 ~55 ~7 ~14 ~55 brick_block 0  
fill ~7 ~4 ~56 ~7 ~7 ~56 glass 0  
fill ~7 ~4 ~57 ~7 ~7 ~57 glass 0  
fill ~7 ~4 ~58 ~7 ~7 ~58 glass 0  
fill ~7 ~4 ~59 ~7 ~14 ~59 brick_block 0  
fill ~7 ~4 ~60 ~7 ~14 ~60 brick_block 0  
fill ~7 ~4 ~61 ~17 ~4 ~61 brick_block 0 
setblock ~8 ~4 ~1 spruce_stairs 5 
setblock ~8 ~4 ~2 planks 1  
fill ~8 ~4 ~3 ~8 ~9 ~3 brick_block 0  
fill ~8 ~4 ~5 ~8 ~9 ~5 brick_block 0  
fill ~8 ~4 ~7 ~8 ~14 ~7 quartz_block 2  
fill ~8 ~4 ~8 ~8 ~4 ~10 brick_stairs 4  
fill ~8 ~4 ~11 ~8 ~7 ~11 quartz_block 0  
fill ~8 ~4 ~12 ~8 ~4 ~14 brick_stairs 4  
fill ~8 ~4 ~15 ~8 ~7 ~15 quartz_block 0  
fill ~8 ~4 ~16 ~8 ~4 ~18 brick_stairs 4  
fill ~8 ~4 ~19 ~8 ~7 ~19 quartz_block 0  
fill ~8 ~4 ~20 ~8 ~4 ~22 brick_stairs 4  
fill ~8 ~4 ~23 ~8 ~6 ~23 quartz_block 0  
fill ~8 ~4 ~24 ~9 ~4 ~24 brick_block 0  
fill ~8 ~4 ~25 ~8 ~6 ~25 stonebrick 0  
fill ~8 ~4 ~31 ~8 ~6 ~31 stonebrick 0  
fill ~8 ~4 ~32 ~9 ~4 ~32 brick_block 0  
fill ~8 ~4 ~35 ~8 ~14 ~35 quartz_block 2  
fill ~8 ~4 ~37 ~8 ~16 ~37 brick_block 0  
fill ~8 ~4 ~38 ~8 ~9 ~38 brick_block 0  
fill ~8 ~4 ~39 ~8 ~16 ~39 brick_block 0  
fill ~8 ~4 ~42 ~9 ~4 ~42 bookshelf 0  
fill ~8 ~4 ~43 ~8 ~7 ~43 bookshelf 0  
fill ~8 ~4 ~47 ~8 ~7 ~47 bookshelf 0  
fill ~8 ~4 ~48 ~8 ~7 ~48 bookshelf 0  
fill ~8 ~4 ~49 ~8 ~7 ~49 bookshelf 0  
fill ~8 ~4 ~53 ~8 ~7 ~53 bookshelf 0  
fill ~8 ~4 ~54 ~8 ~7 ~54 bookshelf 0  
fill ~8 ~4 ~55 ~8 ~7 ~55 bookshelf 0  
fill ~8 ~4 ~59 ~8 ~7 ~59 bookshelf 0  
fill ~8 ~4 ~60 ~11 ~4 ~60 bookshelf 0  
fill ~8 ~4 ~63 ~8 ~9 ~63 brick_block 0 
setblock ~8 ~4 ~64 wooden_door 4  
fill ~8 ~4 ~65 ~8 ~9 ~65 brick_block 0 
setblock ~8 ~4 ~66 planks 1 
setblock ~8 ~4 ~67 spruce_stairs 5 
setblock ~9 ~4 ~2 spruce_stairs 6  
fill ~9 ~4 ~6 ~9 ~14 ~6 quartz_block 2  
fill ~9 ~4 ~7 ~32 ~4 ~7 brick_block 0  
fill ~9 ~4 ~8 ~9 ~4 ~25 brick_block 0  
fill ~9 ~4 ~26 ~9 ~6 ~26 stonebrick 0  
fill ~9 ~4 ~30 ~9 ~6 ~30 stonebrick 0  
fill ~9 ~4 ~31 ~9 ~15 ~31 brick_block 0  
fill ~9 ~4 ~33 ~10 ~4 ~33 brick_block 0  
fill ~9 ~4 ~34 ~9 ~14 ~34 brick_block 0  
fill ~9 ~4 ~35 ~9 ~4 ~39 stone 0  
fill ~9 ~4 ~40 ~9 ~7 ~40 brick_block 0  
fill ~9 ~4 ~62 ~9 ~14 ~62 quartz_block 2 
setblock ~9 ~4 ~66 spruce_stairs 7  
fill ~10 ~4 ~3 ~12 ~4 ~3 fence 0  
fill ~10 ~4 ~8 ~10 ~4 ~10 spruce_stairs 5  
fill ~10 ~4 ~11 ~10 ~8 ~11 brick_block 0  
fill ~10 ~4 ~12 ~10 ~4 ~14 spruce_stairs 5  
fill ~10 ~4 ~15 ~10 ~8 ~15 brick_block 0  
fill ~10 ~4 ~16 ~10 ~4 ~18 spruce_stairs 5  
fill ~10 ~4 ~19 ~10 ~8 ~19 brick_block 0  
fill ~10 ~4 ~20 ~10 ~4 ~22 spruce_stairs 5  
fill ~10 ~4 ~23 ~10 ~11 ~23 brick_block 0  
fill ~10 ~4 ~26 ~10 ~9 ~26 brick_block 0  
fill ~10 ~4 ~27 ~10 ~6 ~27 quartz_block 0 
setblock ~10 ~4 ~28 iron_door 0  
fill ~10 ~4 ~29 ~10 ~6 ~29 quartz_block 0 
setblock ~10 ~4 ~34 brick_stairs 1 
setblock ~10 ~4 ~36 oak_stairs 5 
setblock ~10 ~4 ~37 dropper 8 
setblock ~10 ~4 ~38 oak_stairs 5 
setblock ~10 ~4 ~40 brick_stairs 1  
fill ~10 ~4 ~41 ~10 ~9 ~41 brick_block 0  
fill ~10 ~4 ~65 ~12 ~4 ~65 fence 0  
fill ~11 ~4 ~6 ~11 ~6 ~6 quartz_block 0 
setblock ~11 ~4 ~28 stone_pressure_plate 0  
fill ~11 ~4 ~62 ~11 ~6 ~62 quartz_block 0  
fill ~12 ~4 ~6 ~14 ~4 ~6 brick_stairs 6  
fill ~12 ~4 ~62 ~14 ~4 ~62 brick_stairs 7  
fill ~14 ~4 ~3 ~16 ~4 ~3 fence 0  
fill ~14 ~4 ~21 ~18 ~4 ~21 brick_stairs 6  
fill ~14 ~4 ~22 ~14 ~8 ~22 brick_block 0  
fill ~14 ~4 ~23 ~18 ~4 ~23 brick_block 0  
fill ~14 ~4 ~33 ~18 ~4 ~33 brick_block 0 
setblock ~14 ~4 ~34 brick_stairs 0 
setblock ~14 ~4 ~36 oak_stairs 4 
setblock ~14 ~4 ~37 dropper 8 
setblock ~14 ~4 ~38 oak_stairs 4 
setblock ~14 ~4 ~40 brick_stairs 0  
fill ~14 ~4 ~41 ~15 ~4 ~41 brick_block 0 
setblock ~14 ~4 ~42 trapdoor 6  
fill ~14 ~4 ~65 ~16 ~4 ~65 fence 0  
fill ~15 ~4 ~6 ~15 ~6 ~6 quartz_block 0  
fill ~15 ~4 ~26 ~18 ~4 ~26 brick_block 0  
fill ~15 ~4 ~27 ~15 ~4 ~29 spruce_stairs 0  
fill ~15 ~4 ~30 ~18 ~4 ~30 brick_block 0  
fill ~15 ~4 ~34 ~17 ~4 ~34 brick_block 0  
fill ~15 ~4 ~35 ~17 ~4 ~35 stone 0  
fill ~15 ~4 ~36 ~16 ~4 ~36 stone 0  
fill ~15 ~4 ~37 ~16 ~4 ~37 stone 0  
fill ~15 ~4 ~38 ~16 ~4 ~38 stone 0  
fill ~15 ~4 ~39 ~16 ~4 ~39 stone 0  
fill ~15 ~4 ~40 ~15 ~7 ~40 brick_block 0 
setblock ~15 ~4 ~42 activator_rail 2 
setblock ~15 ~4 ~43 trapdoor 5  
fill ~15 ~4 ~47 ~15 ~7 ~47 bookshelf 0  
fill ~15 ~4 ~48 ~15 ~7 ~48 bookshelf 0 
setblock ~15 ~4 ~49 jukebox 0  
fill ~15 ~4 ~50 ~15 ~4 ~51 spruce_stairs 0 
setblock ~15 ~4 ~52 piston_head 1  
fill ~15 ~4 ~53 ~15 ~4 ~54 spruce_stairs 0  
fill ~15 ~4 ~59 ~15 ~7 ~59 bookshelf 0  
fill ~15 ~4 ~60 ~15 ~7 ~60 bookshelf 0  
fill ~15 ~4 ~62 ~15 ~6 ~62 quartz_block 0  
fill ~16 ~4 ~27 ~17 ~4 ~27 planks 1  
fill ~16 ~4 ~28 ~17 ~4 ~28 planks 1  
fill ~16 ~4 ~29 ~17 ~4 ~29 planks 1  
fill ~16 ~4 ~40 ~16 ~4 ~41 stone 0  
fill ~16 ~4 ~42 ~16 ~9 ~42 brick_block 0  
fill ~16 ~4 ~46 ~16 ~9 ~46 brick_block 0  
fill ~16 ~4 ~47 ~18 ~4 ~47 brick_block 0  
fill ~16 ~4 ~48 ~16 ~9 ~48 brick_block 0  
fill ~16 ~4 ~49 ~16 ~9 ~49 brick_block 0  
fill ~16 ~4 ~50 ~16 ~9 ~50 brick_block 0  
fill ~16 ~4 ~51 ~16 ~9 ~51 brick_block 0  
fill ~16 ~4 ~52 ~16 ~5 ~52 brick_block 0  
fill ~16 ~4 ~53 ~16 ~9 ~53 brick_block 0  
fill ~16 ~4 ~54 ~18 ~4 ~54 brick_block 0  
fill ~16 ~4 ~55 ~16 ~9 ~55 brick_block 0  
fill ~16 ~4 ~59 ~16 ~12 ~59 brick_block 0  
fill ~16 ~4 ~60 ~18 ~4 ~60 brick_block 0 
setblock ~16 ~4 ~62 brick_block 0  
fill ~17 ~4 ~3 ~17 ~3 ~3 stonebrick 0  
fill ~17 ~4 ~36 ~17 ~4 ~38 activator_rail 0 
setblock ~17 ~4 ~39 cauldron 6  
fill ~17 ~4 ~40 ~17 ~7 ~40 brick_block 0  
fill ~17 ~4 ~41 ~18 ~4 ~41 brick_block 0 
setblock ~17 ~4 ~42 jukebox 0  
fill ~17 ~4 ~46 ~18 ~4 ~46 oak_stairs 6 
setblock ~17 ~4 ~48 stone 0  
fill ~17 ~4 ~49 ~17 ~4 ~50 double_stone_slab 6  
fill ~17 ~4 ~51 ~17 ~4 ~53 stone 0  
fill ~17 ~4 ~62 ~17 ~6 ~62 stonebrick 0  
fill ~17 ~4 ~65 ~17 ~3 ~65 stonebrick 0 
setblock ~18 ~4 ~3 stone_slab 6  
fill ~18 ~4 ~6 ~18 ~6 ~6 quartz_block 0  
fill ~18 ~4 ~22 ~18 ~8 ~22 brick_block 0 
setblock ~18 ~4 ~35 iron_door 0  
fill ~18 ~4 ~36 ~18 ~4 ~38 trapdoor 15 
setblock ~18 ~4 ~48 double_stone_slab 6 
setblock ~18 ~4 ~51 quartz_stairs 3 
setblock ~18 ~4 ~52 cauldron 6  
fill ~18 ~4 ~53 ~23 ~4 ~53 stone 0  
fill ~18 ~4 ~59 ~18 ~6 ~59 brick_block 0  
fill ~18 ~4 ~61 ~18 ~6 ~61 stonebrick 0 
setblock ~18 ~4 ~65 stone_slab 6  
fill ~19 ~4 ~6 ~21 ~4 ~6 brick_stairs 6
fill ~19 ~4 ~27 ~21 ~4 ~27 brick_block 0  
fill ~19 ~4 ~29 ~21 ~4 ~29 brick_block 0 
setblock ~19 ~4 ~48 stone 0  
fill ~19 ~4 ~49 ~19 ~4 ~51 quartz_stairs 1 
setblock ~19 ~4 ~54 birch_stairs 5  
fill ~19 ~4 ~60 ~19 ~7 ~60 quartz_block 0 
setblock ~20 ~4 ~36 spruce_stairs 6 
setblock ~20 ~4 ~37 dropper 9 
setblock ~20 ~4 ~38 spruce_stairs 7 
setblock ~20 ~4 ~48 wooden_door 1 
setblock ~20 ~4 ~54 dropper 0 
setblock ~20 ~4 ~59 stone_pressure_plate 0 
setblock ~20 ~4 ~60 iron_door 3  
fill ~21 ~4 ~48 ~22 ~4 ~48 stone 0 
setblock ~21 ~4 ~50 quartz_stairs 0 
setblock ~21 ~4 ~54 birch_stairs 4  
fill ~21 ~4 ~60 ~21 ~7 ~60 quartz_block 0 
setblock ~22 ~4 ~3 stone_slab 6  
fill ~22 ~4 ~6 ~22 ~6 ~6 quartz_block 0  
fill ~22 ~4 ~23 ~26 ~4 ~23 brick_block 0  
fill ~22 ~4 ~26 ~25 ~4 ~26 brick_block 0  
fill ~22 ~4 ~30 ~25 ~4 ~30 brick_block 0  
fill ~22 ~4 ~33 ~26 ~4 ~33 brick_block 0  
fill ~22 ~4 ~35 ~22 ~4 ~37 trapdoor 14  
fill ~22 ~4 ~41 ~23 ~4 ~41 brick_block 0  
fill ~22 ~4 ~46 ~23 ~4 ~46 oak_stairs 6  
fill ~22 ~4 ~47 ~22 ~9 ~47 brick_block 0  
fill ~22 ~4 ~49 ~22 ~5 ~49 double_stone_slab 6 
setblock ~22 ~4 ~51 quartz_stairs 3  
fill ~22 ~4 ~54 ~24 ~4 ~54 brick_block 0  
fill ~22 ~4 ~59 ~22 ~6 ~59 brick_block 0  
fill ~22 ~4 ~60 ~24 ~4 ~60 brick_block 0  
fill ~22 ~4 ~61 ~22 ~6 ~61 stonebrick 0 
setblock ~22 ~4 ~65 stone_slab 6  
fill ~23 ~4 ~11 ~23 ~8 ~11 brick_block 0  
fill ~23 ~4 ~15 ~23 ~8 ~15 brick_block 0  
fill ~23 ~4 ~22 ~24 ~4 ~22 brick_block 0  
fill ~23 ~4 ~27 ~24 ~4 ~27 planks 1  
fill ~23 ~4 ~28 ~24 ~4 ~28 planks 1  
fill ~23 ~4 ~29 ~24 ~4 ~29 planks 1  
fill ~23 ~4 ~34 ~25 ~4 ~34 brick_block 0  
fill ~23 ~4 ~35 ~23 ~4 ~36 activator_rail 0 
setblock ~23 ~4 ~37 crafting_table 0  
fill ~23 ~4 ~40 ~23 ~7 ~40 brick_block 0 
setblock ~23 ~4 ~42 jukebox 0 
setblock ~23 ~4 ~48 redstone_wire 0 
setblock ~23 ~4 ~49 stone 0  
fill ~23 ~4 ~51 ~23 ~4 ~53 stone 0  
fill ~23 ~4 ~61 ~33 ~4 ~61 brick_block 0  
fill ~23 ~4 ~62 ~23 ~6 ~62 stonebrick 0 
setblock ~23 ~4 ~65 stonebrick 0  
fill ~24 ~4 ~3 ~26 ~4 ~3 fence 0  
fill ~24 ~4 ~8 ~25 ~4 ~8 stone 0  
fill ~24 ~4 ~9 ~25 ~4 ~9 stone 0  
fill ~24 ~4 ~10 ~25 ~4 ~10 stone 0  
fill ~24 ~4 ~11 ~25 ~4 ~11 brick_stairs 7  
fill ~24 ~4 ~15 ~25 ~4 ~15 brick_stairs 6  
fill ~24 ~4 ~16 ~25 ~4 ~16 stone 0  
fill ~24 ~4 ~17 ~25 ~4 ~17 stone 0  
fill ~24 ~4 ~18 ~25 ~4 ~18 stone 0  
fill ~24 ~4 ~19 ~25 ~4 ~19 stone 0  
fill ~24 ~4 ~20 ~25 ~4 ~20 stone 0  
fill ~24 ~4 ~21 ~25 ~4 ~21 stone 0  
fill ~24 ~4 ~35 ~25 ~4 ~35 stone 0  
fill ~24 ~4 ~36 ~25 ~4 ~36 stone 0  
fill ~24 ~4 ~37 ~25 ~4 ~37 stone 0  
fill ~24 ~4 ~38 ~25 ~4 ~38 stone 0  
fill ~24 ~4 ~39 ~25 ~4 ~39 stone 0  
fill ~24 ~4 ~40 ~24 ~4 ~41 stone 0  
fill ~24 ~4 ~42 ~24 ~9 ~42 brick_block 0  
fill ~24 ~4 ~46 ~24 ~9 ~46 brick_block 0  
fill ~24 ~4 ~47 ~24 ~9 ~47 brick_block 0  
fill ~24 ~4 ~48 ~24 ~7 ~48 brick_block 0  
fill ~24 ~4 ~49 ~24 ~4 ~55 brick_block 0  
fill ~24 ~4 ~59 ~24 ~9 ~59 brick_block 0 
setblock ~24 ~4 ~62 brick_block 0  
fill ~24 ~4 ~65 ~26 ~4 ~65 fence 0  
fill ~25 ~4 ~6 ~25 ~6 ~6 quartz_block 0 
setblock ~25 ~4 ~22 stone 0  
fill ~25 ~4 ~27 ~25 ~4 ~29 spruce_stairs 1  
fill ~25 ~4 ~40 ~25 ~9 ~40 brick_block 0  
fill ~25 ~4 ~41 ~26 ~4 ~41 brick_block 0 
setblock ~25 ~4 ~46 wooden_door 2 
setblock ~25 ~4 ~49 wooden_door 2 
setblock ~25 ~4 ~52 wooden_door 2 
setblock ~25 ~4 ~55 wooden_door 2  
fill ~25 ~4 ~60 ~25 ~7 ~60 wool 14  
fill ~25 ~4 ~62 ~25 ~6 ~62 quartz_block 0  
fill ~26 ~4 ~6 ~28 ~4 ~6 brick_stairs 6 
setblock ~26 ~4 ~8 jungle_stairs 7 
setblock ~26 ~4 ~9 dropper 0 
setblock ~26 ~4 ~10 jungle_stairs 6  
fill ~26 ~4 ~11 ~26 ~8 ~11 brick_block 0  
fill ~26 ~4 ~15 ~26 ~8 ~15 brick_block 0 
setblock ~26 ~4 ~34 brick_stairs 1 
setblock ~26 ~4 ~36 sandstone_stairs 7 
setblock ~26 ~4 ~37 stone_slab 9 
setblock ~26 ~4 ~38 sandstone_stairs 6 
setblock ~26 ~4 ~40 brick_stairs 1 
setblock ~26 ~4 ~46 sandstone_stairs 1 
setblock ~26 ~4 ~49 sandstone_stairs 1 
setblock ~26 ~4 ~52 sandstone_stairs 1 
setblock ~26 ~4 ~55 sandstone_stairs 1  
fill ~26 ~4 ~60 ~28 ~4 ~60 brick_stairs 6  
fill ~26 ~4 ~62 ~28 ~4 ~62 brick_stairs 7  
fill ~27 ~4 ~45 ~29 ~4 ~45 dropper 9  
fill ~27 ~4 ~46 ~27 ~4 ~56 dropper 9  
fill ~28 ~4 ~3 ~30 ~4 ~3 fence 0 
setblock ~28 ~4 ~43 wooden_door 3 
setblock ~28 ~4 ~44 sandstone_stairs 3 
setblock ~28 ~4 ~46 spruce_stairs 6 
setblock ~28 ~4 ~47 spruce_stairs 7  
fill ~28 ~4 ~48 ~29 ~4 ~48 dropper 9  
fill ~28 ~4 ~49 ~29 ~4 ~49 dropper 9 
setblock ~28 ~4 ~50 spruce_stairs 6 
setblock ~28 ~4 ~51 spruce_stairs 7  
fill ~28 ~4 ~52 ~29 ~4 ~52 dropper 9  
fill ~28 ~4 ~53 ~29 ~4 ~53 dropper 9 
setblock ~28 ~4 ~54 spruce_stairs 6 
setblock ~28 ~4 ~55 spruce_stairs 7  
fill ~28 ~4 ~56 ~29 ~4 ~56 dropper 9 
setblock ~28 ~4 ~57 sandstone_stairs 2 
setblock ~28 ~4 ~58 wooden_door 1  
fill ~28 ~4 ~65 ~30 ~4 ~65 fence 0  
fill ~29 ~4 ~6 ~29 ~6 ~6 quartz_block 0  
fill ~29 ~4 ~8 ~29 ~4 ~9 oak_stairs 0 
setblock ~29 ~4 ~28 stone_pressure_plate 0  
fill ~29 ~4 ~46 ~29 ~4 ~56 dropper 9  
fill ~29 ~4 ~60 ~29 ~7 ~60 wool 14  
fill ~29 ~4 ~62 ~29 ~6 ~62 quartz_block 0  
fill ~30 ~4 ~8 ~30 ~4 ~9 activator_rail 0 
setblock ~30 ~4 ~10 quartz_stairs 7 
setblock ~30 ~4 ~11 quartz_stairs 6 
setblock ~30 ~4 ~16 quartz_stairs 7 
setblock ~30 ~4 ~18 stone_slab 14 
setblock ~30 ~4 ~19 quartz_stairs 6 
setblock ~30 ~4 ~28 iron_door 2 
setblock ~30 ~4 ~34 brick_stairs 0 
setblock ~30 ~4 ~36 sandstone_stairs 7 
setblock ~30 ~4 ~37 stone_slab 9 
setblock ~30 ~4 ~38 sandstone_stairs 6 
setblock ~30 ~4 ~40 brick_stairs 0  
fill ~30 ~4 ~41 ~33 ~4 ~41 brick_block 0 
setblock ~30 ~4 ~46 sandstone_stairs 0 
setblock ~30 ~4 ~49 sandstone_stairs 0 
setblock ~30 ~4 ~52 sandstone_stairs 0 
setblock ~30 ~4 ~55 sandstone_stairs 0 
setblock ~31 ~4 ~2 spruce_stairs 6  
fill ~31 ~4 ~6 ~31 ~14 ~6 quartz_block 2  
fill ~31 ~4 ~10 ~32 ~4 ~10 brick_block 0  
fill ~31 ~4 ~11 ~31 ~17 ~11 brick_block 0  
fill ~31 ~4 ~15 ~31 ~17 ~15 brick_block 0  
fill ~31 ~4 ~16 ~32 ~4 ~16 brick_block 0  
fill ~31 ~4 ~17 ~31 ~15 ~17 brick_block 0  
fill ~31 ~4 ~18 ~31 ~15 ~18 brick_block 0  
fill ~31 ~4 ~19 ~31 ~17 ~19 brick_block 0  
fill ~31 ~4 ~20 ~31 ~4 ~25 brick_block 0  
fill ~31 ~4 ~26 ~31 ~6 ~26 stonebrick 0  
fill ~31 ~4 ~30 ~31 ~6 ~30 stonebrick 0  
fill ~31 ~4 ~31 ~31 ~15 ~31 brick_block 0  
fill ~31 ~4 ~32 ~32 ~4 ~32 brick_block 0  
fill ~31 ~4 ~33 ~31 ~14 ~33 brick_block 0  
fill ~31 ~4 ~34 ~31 ~14 ~34 brick_block 0  
fill ~31 ~4 ~35 ~31 ~4 ~39 stone 0  
fill ~31 ~4 ~40 ~35 ~4 ~40 brick_block 0 
setblock ~31 ~4 ~46 wooden_door 0 
setblock ~31 ~4 ~49 wooden_door 0 
setblock ~31 ~4 ~52 wooden_door 0 
setblock ~31 ~4 ~55 wooden_door 0  
fill ~31 ~4 ~62 ~31 ~14 ~62 quartz_block 2 
setblock ~31 ~4 ~66 spruce_stairs 7 
setblock ~32 ~4 ~1 spruce_stairs 4 
setblock ~32 ~4 ~2 activator_rail 0  
fill ~32 ~4 ~3 ~32 ~9 ~3 brick_block 0 
setblock ~32 ~4 ~4 wooden_door 2  
fill ~32 ~4 ~5 ~32 ~9 ~5 brick_block 0  
fill ~32 ~4 ~6 ~32 ~6 ~6 brick_block 0  
fill ~32 ~4 ~17 ~32 ~14 ~17 quartz_block 2  
fill ~32 ~4 ~19 ~32 ~6 ~19 quartz_block 0  
fill ~32 ~4 ~20 ~32 ~4 ~22 brick_stairs 5  
fill ~32 ~4 ~23 ~32 ~6 ~23 quartz_block 0 
setblock ~32 ~4 ~24 brick_block 0  
fill ~32 ~4 ~25 ~32 ~6 ~25 stonebrick 0  
fill ~32 ~4 ~31 ~32 ~6 ~31 stonebrick 0  
fill ~32 ~4 ~35 ~32 ~14 ~35 quartz_block 2  
fill ~32 ~4 ~37 ~32 ~9 ~37 brick_block 0  
fill ~32 ~4 ~38 ~32 ~9 ~38 brick_block 0  
fill ~32 ~4 ~39 ~32 ~16 ~39 brick_block 0  
fill ~32 ~4 ~42 ~33 ~4 ~42 brick_block 0  
fill ~32 ~4 ~43 ~32 ~7 ~43 wool 14  
fill ~32 ~4 ~47 ~32 ~7 ~47 wool 14  
fill ~32 ~4 ~49 ~32 ~7 ~49 wool 14  
fill ~32 ~4 ~53 ~32 ~7 ~53 wool 14  
fill ~32 ~4 ~55 ~32 ~7 ~55 wool 14  
fill ~32 ~4 ~59 ~32 ~7 ~59 wool 14  
fill ~32 ~4 ~60 ~33 ~4 ~60 brick_block 0  
fill ~32 ~4 ~62 ~35 ~4 ~62 brick_block 0  
fill ~32 ~4 ~63 ~32 ~9 ~63 brick_block 0 
setblock ~32 ~4 ~64 wooden_door 2  
fill ~32 ~4 ~65 ~32 ~9 ~65 brick_block 0 
setblock ~32 ~4 ~66 activator_rail 0 
setblock ~32 ~4 ~67 spruce_stairs 4  
fill ~33 ~4 ~0 ~35 ~4 ~0 trapdoor 12  
fill ~33 ~4 ~1 ~35 ~4 ~1 grass 0  
fill ~33 ~4 ~2 ~35 ~4 ~2 brick_block 0 
setblock ~33 ~4 ~6 wooden_door 3  
fill ~33 ~4 ~16 ~34 ~4 ~16 wooden_door 1  
fill ~33 ~4 ~36 ~33 ~9 ~36 brick_block 0  
fill ~33 ~4 ~43 ~33 ~14 ~43 brick_block 0  
fill ~33 ~4 ~44 ~33 ~7 ~44 glass 0  
fill ~33 ~4 ~45 ~33 ~7 ~45 glass 0  
fill ~33 ~4 ~46 ~33 ~7 ~46 glass 0  
fill ~33 ~4 ~47 ~33 ~14 ~47 brick_block 0  
fill ~33 ~4 ~48 ~33 ~15 ~48 brick_block 0  
fill ~33 ~4 ~49 ~33 ~19 ~49 brick_block 0  
fill ~33 ~4 ~50 ~33 ~7 ~50 glass 0  
fill ~33 ~4 ~51 ~33 ~7 ~51 glass 0  
fill ~33 ~4 ~52 ~33 ~7 ~52 glass 0  
fill ~33 ~4 ~53 ~33 ~19 ~53 brick_block 0  
fill ~33 ~4 ~54 ~33 ~15 ~54 brick_block 0  
fill ~33 ~4 ~55 ~33 ~14 ~55 brick_block 0  
fill ~33 ~4 ~56 ~33 ~7 ~56 glass 0  
fill ~33 ~4 ~57 ~33 ~7 ~57 glass 0  
fill ~33 ~4 ~58 ~33 ~7 ~58 glass 0  
fill ~33 ~4 ~59 ~33 ~14 ~59 brick_block 0  
fill ~33 ~4 ~66 ~35 ~4 ~66 brick_block 0  
fill ~33 ~4 ~67 ~35 ~4 ~67 grass 0  
fill ~33 ~4 ~68 ~35 ~4 ~68 trapdoor 13  
fill ~34 ~4 ~6 ~35 ~4 ~6 brick_block 0  
fill ~34 ~4 ~7 ~34 ~15 ~7 brick_block 0  
fill ~34 ~4 ~8 ~34 ~4 ~10 brick_block 0 
setblock ~34 ~4 ~36 wooden_door 3  
fill ~34 ~4 ~41 ~34 ~14 ~41 quartz_block 2  
fill ~34 ~4 ~61 ~34 ~14 ~61 quartz_block 2 
setblock ~35 ~4 ~7 planks 1 
setblock ~35 ~4 ~9 spruce_stairs 4  
fill ~35 ~4 ~10 ~37 ~4 ~10 brick_block 0  
fill ~35 ~4 ~16 ~37 ~4 ~16 brick_block 0  
fill ~35 ~4 ~17 ~35 ~5 ~17 stonebrick 0  
fill ~35 ~4 ~18 ~35 ~4 ~20 fence 0 
setblock ~35 ~4 ~21 stonebrick 0  
fill ~35 ~4 ~22 ~35 ~4 ~24 fence 0 
setblock ~35 ~4 ~25 stonebrick 0 
setblock ~35 ~4 ~26 stone_slab 6 
setblock ~35 ~4 ~30 stone_slab 6 
setblock ~35 ~4 ~31 stonebrick 0  
fill ~35 ~4 ~32 ~35 ~4 ~34 fence 0  
fill ~35 ~4 ~35 ~35 ~5 ~35 stonebrick 0  
fill ~35 ~4 ~36 ~35 ~9 ~36 brick_block 0 
setblock ~35 ~4 ~41 grass 0 
setblock ~35 ~4 ~42 trapdoor 13 
setblock ~35 ~4 ~60 trapdoor 12 
setblock ~35 ~4 ~61 grass 0 
setblock ~36 ~4 ~1 spruce_stairs 5 
setblock ~36 ~4 ~2 planks 1  
fill ~36 ~4 ~3 ~36 ~9 ~3 brick_block 0  
fill ~36 ~4 ~4 ~36 ~4 ~5 brick_block 0 
setblock ~36 ~4 ~6 planks 1 
setblock ~36 ~4 ~7 spruce_stairs 5 
setblock ~36 ~4 ~8 trapdoor 12 
setblock ~36 ~4 ~9 grass 0 
setblock ~36 ~4 ~17 grass 0 
setblock ~36 ~4 ~18 trapdoor 13 
setblock ~36 ~4 ~35 spruce_stairs 5 
setblock ~36 ~4 ~36 planks 1  
fill ~36 ~4 ~37 ~36 ~9 ~37 brick_block 0  
fill ~36 ~4 ~38 ~36 ~4 ~39 brick_block 0 
setblock ~36 ~4 ~40 planks 1 
setblock ~36 ~4 ~41 spruce_stairs 5 
setblock ~36 ~4 ~61 spruce_stairs 5 
setblock ~36 ~4 ~62 activator_rail 0  
fill ~36 ~4 ~63 ~36 ~9 ~63 brick_block 0  
fill ~36 ~4 ~64 ~36 ~4 ~65 brick_block 0 
setblock ~36 ~4 ~66 planks 1 
setblock ~36 ~4 ~67 spruce_stairs 5 
setblock ~37 ~4 ~2 spruce_stairs 6  
fill ~37 ~4 ~3 ~37 ~4 ~5 grass 0 
setblock ~37 ~4 ~6 spruce_stairs 7 
setblock ~37 ~4 ~9 spruce_stairs 5  
fill ~37 ~4 ~11 ~37 ~4 ~16 brick_block 0 
setblock ~37 ~4 ~17 spruce_stairs 5 
setblock ~37 ~4 ~36 spruce_stairs 6  
fill ~37 ~4 ~37 ~37 ~4 ~39 grass 0 
setblock ~37 ~4 ~40 spruce_stairs 7 
setblock ~37 ~4 ~62 spruce_stairs 6  
fill ~37 ~4 ~63 ~37 ~4 ~65 grass 0 
setblock ~37 ~4 ~66 spruce_stairs 7  
fill ~38 ~4 ~3 ~38 ~4 ~5 trapdoor 15 
setblock ~38 ~4 ~10 spruce_stairs 6  
fill ~38 ~4 ~11 ~38 ~4 ~12 grass 0 
setblock ~38 ~4 ~13 planks 1  
fill ~38 ~4 ~14 ~38 ~4 ~15 grass 0 
setblock ~38 ~4 ~16 spruce_stairs 7  
fill ~38 ~4 ~37 ~38 ~4 ~39 trapdoor 15  
fill ~38 ~4 ~63 ~38 ~4 ~65 trapdoor 15  
fill ~39 ~4 ~11 ~39 ~4 ~12 trapdoor 15  
fill ~39 ~4 ~14 ~39 ~4 ~15 trapdoor 15 
setblock ~3 ~5 ~2 dropper 0 
setblock ~3 ~5 ~3 wool 0 
setblock ~3 ~5 ~5 wool 0 
setblock ~3 ~5 ~6 dropper 0 
setblock ~3 ~5 ~36 dropper 0 
setblock ~3 ~5 ~37 yellow_flower 0 
setblock ~3 ~5 ~39 yellow_flower 0 
setblock ~3 ~5 ~40 dropper 0 
setblock ~3 ~5 ~62 dropper 0 
setblock ~3 ~5 ~63 wool 0 
setblock ~3 ~5 ~65 wool 0 
setblock ~3 ~5 ~66 dropper 0 
setblock ~4 ~5 ~1 dropper 0 
setblock ~4 ~5 ~2 fence 0  
fill ~4 ~5 ~4 ~4 ~6 ~4 glass_pane 0  
fill ~4 ~5 ~5 ~4 ~9 ~5 brick_block 0 
setblock ~4 ~5 ~6 fence 0 
setblock ~4 ~5 ~7 dropper 0 
setblock ~4 ~5 ~35 dropper 0 
setblock ~4 ~5 ~36 fence 0  
fill ~4 ~5 ~38 ~4 ~6 ~38 glass_pane 0  
fill ~4 ~5 ~39 ~4 ~9 ~39 brick_block 0 
setblock ~4 ~5 ~40 fence 0 
setblock ~4 ~5 ~41 dropper 0 
setblock ~4 ~5 ~61 dropper 0 
setblock ~4 ~5 ~62 fence 0  
fill ~4 ~5 ~64 ~4 ~6 ~64 glass_pane 0  
fill ~4 ~5 ~65 ~4 ~9 ~65 brick_block 0 
setblock ~4 ~5 ~66 fence 0 
setblock ~4 ~5 ~67 dropper 0 
setblock ~5 ~5 ~1 wool 0  
fill ~5 ~5 ~2 ~5 ~9 ~2 brick_block 0  
fill ~5 ~5 ~40 ~7 ~5 ~40 brick_block 0  
fill ~5 ~5 ~62 ~8 ~5 ~62 brick_block 0  
fill ~5 ~5 ~66 ~5 ~9 ~66 brick_block 0 
setblock ~5 ~5 ~67 wool 0  
fill ~6 ~5 ~2 ~6 ~6 ~2 glass_pane 0 
setblock ~6 ~5 ~6 wooden_door 8 
setblock ~6 ~5 ~36 wooden_door 8  
fill ~6 ~5 ~66 ~6 ~6 ~66 glass_pane 0 
setblock ~7 ~5 ~1 yellow_flower 0  
fill ~7 ~5 ~2 ~7 ~9 ~2 brick_block 0  
fill ~7 ~5 ~6 ~8 ~5 ~6 brick_block 0  
fill ~7 ~5 ~36 ~8 ~5 ~36 brick_block 0  
fill ~7 ~5 ~61 ~11 ~5 ~61 brick_block 0  
fill ~7 ~5 ~66 ~7 ~9 ~66 brick_block 0 
setblock ~7 ~5 ~67 yellow_flower 0 
setblock ~8 ~5 ~1 dropper 0 
setblock ~8 ~5 ~2 fence 0 
setblock ~8 ~5 ~24 brick_stairs 4 
setblock ~8 ~5 ~32 brick_stairs 4  
fill ~8 ~5 ~42 ~9 ~5 ~42 bookshelf 0  
fill ~8 ~5 ~60 ~11 ~5 ~60 bookshelf 0 
setblock ~8 ~5 ~64 wooden_door 8 
setblock ~8 ~5 ~66 fence 0 
setblock ~8 ~5 ~67 dropper 0 
setblock ~9 ~5 ~2 dropper 0  
fill ~9 ~5 ~7 ~11 ~5 ~7 brick_block 0  
fill ~9 ~5 ~8 ~9 ~7 ~8 glass 0  
fill ~9 ~5 ~9 ~9 ~7 ~9 glass 0  
fill ~9 ~5 ~10 ~9 ~7 ~10 glass 0  
fill ~9 ~5 ~11 ~9 ~14 ~11 brick_block 0  
fill ~9 ~5 ~12 ~9 ~7 ~12 glass 0  
fill ~9 ~5 ~13 ~9 ~7 ~13 glass 0  
fill ~9 ~5 ~14 ~9 ~7 ~14 glass 0  
fill ~9 ~5 ~15 ~9 ~14 ~15 brick_block 0  
fill ~9 ~5 ~16 ~9 ~7 ~16 glass 0  
fill ~9 ~5 ~17 ~9 ~7 ~17 glass 0  
fill ~9 ~5 ~18 ~9 ~7 ~18 glass 0  
fill ~9 ~5 ~19 ~9 ~17 ~19 brick_block 0  
fill ~9 ~5 ~20 ~9 ~7 ~20 glass 0  
fill ~9 ~5 ~21 ~9 ~7 ~21 glass 0  
fill ~9 ~5 ~22 ~9 ~7 ~22 glass 0  
fill ~9 ~5 ~23 ~9 ~11 ~23 brick_block 0  
fill ~9 ~5 ~24 ~9 ~15 ~24 brick_block 0  
fill ~9 ~5 ~25 ~9 ~15 ~25 brick_block 0 
setblock ~9 ~5 ~29 stone_button 2  
fill ~9 ~5 ~32 ~9 ~14 ~32 brick_block 0  
fill ~9 ~5 ~33 ~10 ~5 ~33 brick_block 0 
setblock ~9 ~5 ~35 wool 0 
setblock ~9 ~5 ~36 wool 13 
setblock ~9 ~5 ~37 wool 0 
setblock ~9 ~5 ~38 wool 13 
setblock ~9 ~5 ~39 wool 0 
setblock ~9 ~5 ~66 dropper 0  
fill ~10 ~5 ~24 ~10 ~5 ~25 leaves 8 
setblock ~10 ~5 ~28 iron_door 8  
fill ~10 ~5 ~31 ~10 ~5 ~32 leaves 8 
setblock ~10 ~5 ~36 flower_pot 2 
setblock ~10 ~5 ~37 stone_pressure_plate 0 
setblock ~10 ~5 ~38 flower_pot 11  
fill ~12 ~5 ~7 ~14 ~5 ~7 glass 0  
fill ~12 ~5 ~61 ~14 ~5 ~61 glass 0  
fill ~14 ~5 ~23 ~14 ~17 ~23 brick_block 0  
fill ~14 ~5 ~33 ~14 ~15 ~33 brick_block 0 
setblock ~14 ~5 ~36 flower_pot 11 
setblock ~14 ~5 ~37 stone_pressure_plate 0 
setblock ~14 ~5 ~38 flower_pot 1  
fill ~14 ~5 ~41 ~15 ~5 ~41 brick_block 0  
fill ~15 ~5 ~7 ~18 ~5 ~7 brick_block 0 
setblock ~15 ~5 ~23 brick_stairs 3 
setblock ~15 ~5 ~26 stone_slab 6 
setblock ~15 ~5 ~30 stone_slab 6 
setblock ~15 ~5 ~33 brick_stairs 2  
fill ~15 ~5 ~34 ~17 ~5 ~34 brick_block 0 
setblock ~15 ~5 ~35 wool 0 
setblock ~15 ~5 ~36 wool 13 
setblock ~15 ~5 ~37 wool 0 
setblock ~15 ~5 ~38 wool 13 
setblock ~15 ~5 ~39 wool 0 
setblock ~15 ~5 ~42 fence 0 
setblock ~15 ~5 ~52 fence 0  
fill ~15 ~5 ~61 ~17 ~5 ~61 brick_block 0  
fill ~16 ~5 ~23 ~18 ~5 ~23 brick_block 0  
fill ~16 ~5 ~26 ~18 ~5 ~26 brick_block 0  
fill ~16 ~5 ~27 ~16 ~5 ~29 spruce_stairs 0  
fill ~16 ~5 ~30 ~18 ~5 ~30 brick_block 0  
fill ~16 ~5 ~33 ~18 ~5 ~33 brick_block 0  
fill ~16 ~5 ~35 ~16 ~7 ~35 wool 4  
fill ~16 ~5 ~36 ~16 ~7 ~36 wool 0  
fill ~16 ~5 ~37 ~16 ~7 ~37 wool 4  
fill ~16 ~5 ~38 ~16 ~7 ~38 wool 0  
fill ~16 ~5 ~39 ~16 ~7 ~39 wool 4  
fill ~16 ~5 ~40 ~16 ~7 ~40 wool 0  
fill ~16 ~5 ~47 ~18 ~5 ~47 brick_block 0  
fill ~16 ~5 ~54 ~18 ~5 ~54 brick_block 0  
fill ~16 ~5 ~60 ~18 ~5 ~60 brick_block 0 
setblock ~16 ~5 ~62 brick_stairs 7  
fill ~17 ~5 ~27 ~18 ~5 ~27 planks 1  
fill ~17 ~5 ~28 ~18 ~5 ~28 planks 1  
fill ~17 ~5 ~29 ~18 ~5 ~29 planks 1 
setblock ~17 ~5 ~35 stone 0  
fill ~17 ~5 ~36 ~17 ~5 ~38 stone_pressure_plate 0 
setblock ~17 ~5 ~39 tripwire_hook 3  
fill ~17 ~5 ~41 ~18 ~5 ~41 brick_block 0  
fill ~17 ~5 ~48 ~17 ~7 ~48 wool 9  
fill ~17 ~5 ~49 ~17 ~7 ~49 wool 9  
fill ~17 ~5 ~50 ~17 ~7 ~50 wool 3  
fill ~17 ~5 ~51 ~17 ~7 ~51 wool 3  
fill ~17 ~5 ~52 ~17 ~7 ~52 wool 9  
fill ~17 ~5 ~53 ~17 ~5 ~52 wool 9  
fill ~17 ~5 ~55 ~17 ~6 ~55 leaves 8  
fill ~17 ~5 ~59 ~17 ~6 ~59 leaves 8 
setblock ~18 ~5 ~35 iron_door 8  
fill ~18 ~5 ~48 ~18 ~7 ~48 wool 3  
fill ~18 ~5 ~53 ~18 ~7 ~53 wool 3  
fill ~19 ~5 ~7 ~21 ~5 ~7 glass 0  
fill ~19 ~5 ~27 ~19 ~6 ~27 brick_block 0  
fill ~19 ~5 ~29 ~19 ~6 ~29 brick_block 0  
fill ~19 ~5 ~48 ~19 ~7 ~48 wool 9  
fill ~19 ~5 ~53 ~21 ~5 ~53 wool 9 
setblock ~19 ~5 ~54 flower_pot 11  
fill ~20 ~5 ~28 ~20 ~6 ~28 glowstone 0 
setblock ~20 ~5 ~37 flower_pot 1 
setblock ~20 ~5 ~48 wooden_door 8 
setblock ~20 ~5 ~60 iron_door 8  
fill ~21 ~5 ~27 ~21 ~6 ~27 brick_block 0  
fill ~21 ~5 ~29 ~21 ~6 ~29 brick_block 0  
fill ~21 ~5 ~48 ~21 ~7 ~48 wool 9 
setblock ~21 ~5 ~49 lever 2 
setblock ~21 ~5 ~54 flower_pot 11 
setblock ~21 ~5 ~61 stone_button 3  
fill ~22 ~5 ~7 ~25 ~5 ~7 brick_block 0  
fill ~22 ~5 ~23 ~24 ~5 ~23 brick_block 0  
fill ~22 ~5 ~26 ~24 ~5 ~26 brick_block 0  
fill ~22 ~5 ~27 ~23 ~5 ~27 planks 1  
fill ~22 ~5 ~28 ~23 ~5 ~28 planks 1  
fill ~22 ~5 ~29 ~23 ~5 ~29 planks 1  
fill ~22 ~5 ~30 ~24 ~5 ~30 brick_block 0  
fill ~22 ~5 ~33 ~24 ~5 ~33 brick_block 0  
fill ~22 ~5 ~41 ~23 ~5 ~41 brick_block 0  
fill ~22 ~5 ~48 ~22 ~7 ~48 wool 3  
fill ~22 ~5 ~53 ~22 ~7 ~53 wool 3  
fill ~22 ~5 ~54 ~24 ~5 ~54 brick_block 0  
fill ~22 ~5 ~60 ~24 ~5 ~60 brick_block 0  
fill ~23 ~5 ~22 ~24 ~5 ~22 brick_block 0  
fill ~23 ~5 ~34 ~25 ~5 ~34 brick_block 0  
fill ~23 ~5 ~35 ~23 ~5 ~36 stone_pressure_plate 0  
fill ~23 ~5 ~47 ~23 ~9 ~47 brick_block 0 
setblock ~23 ~5 ~49 redstone_wire 0  
fill ~23 ~5 ~50 ~23 ~7 ~50 wool 3  
fill ~23 ~5 ~51 ~23 ~7 ~51 wool 3  
fill ~23 ~5 ~52 ~23 ~7 ~52 wool 9  
fill ~23 ~5 ~53 ~23 ~7 ~53 wool 9  
fill ~23 ~5 ~55 ~23 ~6 ~55 leaves 8  
fill ~23 ~5 ~59 ~23 ~6 ~59 leaves 8  
fill ~23 ~5 ~61 ~25 ~5 ~61 brick_block 0  
fill ~24 ~5 ~8 ~25 ~5 ~8 wool 0  
fill ~24 ~5 ~9 ~24 ~8 ~9 wool 14  
fill ~24 ~5 ~10 ~25 ~5 ~10 wool 0  
fill ~24 ~5 ~16 ~25 ~5 ~16 wool 0  
fill ~24 ~5 ~17 ~24 ~8 ~17 wool 14  
fill ~24 ~5 ~18 ~24 ~9 ~18 wool 0  
fill ~24 ~5 ~19 ~24 ~8 ~19 wool 14  
fill ~24 ~5 ~20 ~24 ~9 ~20 wool 0  
fill ~24 ~5 ~21 ~24 ~8 ~21 wool 14  
fill ~24 ~5 ~27 ~24 ~5 ~29 spruce_stairs 1  
fill ~24 ~5 ~35 ~24 ~7 ~35 wool 4  
fill ~24 ~5 ~36 ~24 ~7 ~36 wool 0  
fill ~24 ~5 ~37 ~24 ~7 ~37 wool 4  
fill ~24 ~5 ~38 ~24 ~7 ~38 wool 0  
fill ~24 ~5 ~39 ~24 ~7 ~39 wool 4  
fill ~24 ~5 ~40 ~24 ~7 ~40 wool 0 
setblock ~24 ~5 ~49 brick_stairs 1  
fill ~24 ~5 ~50 ~24 ~9 ~50 brick_block 0  
fill ~24 ~5 ~51 ~24 ~9 ~51 brick_block 0  
fill ~24 ~5 ~52 ~24 ~9 ~52 brick_block 0 
setblock ~24 ~5 ~53 brick_stairs 1  
fill ~24 ~5 ~55 ~24 ~9 ~55 brick_block 0 
setblock ~24 ~5 ~62 brick_stairs 7  
fill ~25 ~5 ~9 ~25 ~6 ~9 wool 11  
fill ~25 ~5 ~17 ~25 ~6 ~17 wool 11  
fill ~25 ~5 ~18 ~25 ~6 ~18 wool 11  
fill ~25 ~5 ~19 ~25 ~6 ~19 wool 0  
fill ~25 ~5 ~20 ~25 ~6 ~20 wool 11  
fill ~25 ~5 ~21 ~25 ~6 ~21 wool 11  
fill ~25 ~5 ~22 ~25 ~6 ~22 wool 0 
setblock ~25 ~5 ~23 brick_stairs 3 
setblock ~25 ~5 ~26 stone_slab 6 
setblock ~25 ~5 ~30 stone_slab 6 
setblock ~25 ~5 ~33 brick_stairs 2  
fill ~25 ~5 ~35 ~25 ~6 ~35 wool 0  
fill ~25 ~5 ~36 ~25 ~6 ~36 wool 14  
fill ~25 ~5 ~37 ~25 ~6 ~37 wool 0  
fill ~25 ~5 ~38 ~25 ~6 ~38 wool 14  
fill ~25 ~5 ~39 ~25 ~6 ~39 wool 0  
fill ~25 ~5 ~41 ~26 ~5 ~41 brick_block 0 
setblock ~25 ~5 ~46 wooden_door 8 
setblock ~25 ~5 ~49 wooden_door 8 
setblock ~25 ~5 ~52 wooden_door 8 
setblock ~25 ~5 ~55 wooden_door 8  
fill ~26 ~5 ~7 ~28 ~5 ~7 glass 0 
setblock ~26 ~5 ~8 flower_pot 1 
setblock ~26 ~5 ~10 flower_pot 1 
setblock ~26 ~5 ~36 flower_pot 1 
setblock ~26 ~5 ~38 flower_pot 11 
setblock ~26 ~5 ~60 flower_pot 11  
fill ~26 ~5 ~61 ~28 ~5 ~61 glass 0 
setblock ~27 ~5 ~46 heavy_weighted_pressure_plate 0 
setblock ~27 ~5 ~49 heavy_weighted_pressure_plate 0 
setblock ~27 ~5 ~52 heavy_weighted_pressure_plate 0 
setblock ~27 ~5 ~55 heavy_weighted_pressure_plate 0 
setblock ~28 ~5 ~43 wooden_door 8 
setblock ~28 ~5 ~45 heavy_weighted_pressure_plate 0 
setblock ~28 ~5 ~50 flower_pot 1 
setblock ~28 ~5 ~51 flower_pot 2 
setblock ~28 ~5 ~56 heavy_weighted_pressure_plate 0 
setblock ~28 ~5 ~58 wooden_door 8 
setblock ~28 ~5 ~60 flower_pot 1  
fill ~29 ~5 ~7 ~32 ~5 ~7 brick_block 0 
setblock ~29 ~5 ~46 heavy_weighted_pressure_plate 0 
setblock ~29 ~5 ~49 heavy_weighted_pressure_plate 0 
setblock ~29 ~5 ~52 heavy_weighted_pressure_plate 0 
setblock ~29 ~5 ~55 heavy_weighted_pressure_plate 0  
fill ~29 ~5 ~61 ~33 ~5 ~61 brick_block 0  
fill ~30 ~5 ~8 ~30 ~5 ~9 oak_stairs 0  
fill ~30 ~5 ~10 ~30 ~5 ~11 stone_pressure_plate 0  
fill ~30 ~5 ~16 ~30 ~5 ~19 leaves 8  
fill ~30 ~5 ~24 ~30 ~5 ~25 leaves 8 
setblock ~30 ~5 ~28 iron_door 8  
fill ~30 ~5 ~31 ~30 ~5 ~32 leaves 12 
setblock ~30 ~5 ~36 flower_pot 11 
setblock ~30 ~5 ~38 flower_pot 1  
fill ~30 ~5 ~41 ~33 ~5 ~41 brick_block 0 
setblock ~31 ~5 ~2 dropper 0  
fill ~31 ~5 ~10 ~32 ~5 ~10 brick_block 0  
fill ~31 ~5 ~16 ~32 ~5 ~16 brick_block 0  
fill ~31 ~5 ~20 ~31 ~7 ~20 glass 0  
fill ~31 ~5 ~21 ~31 ~7 ~21 glass 0  
fill ~31 ~5 ~22 ~31 ~7 ~22 glass 0  
fill ~31 ~5 ~23 ~31 ~17 ~23 brick_block 0 
setblock ~31 ~5 ~25 redstone_wire 0 
setblock ~31 ~5 ~27 stone_button 1  
fill ~31 ~5 ~32 ~31 ~14 ~32 brick_block 0  
fill ~31 ~5 ~35 ~31 ~6 ~35 wool 0  
fill ~31 ~5 ~36 ~31 ~6 ~36 wool 14  
fill ~31 ~5 ~37 ~31 ~6 ~37 wool 0  
fill ~31 ~5 ~38 ~31 ~6 ~38 wool 14  
fill ~31 ~5 ~39 ~31 ~6 ~39 wool 0  
fill ~31 ~5 ~40 ~35 ~5 ~40 brick_block 0 
setblock ~31 ~5 ~46 wooden_door 8 
setblock ~31 ~5 ~49 wooden_door 8 
setblock ~31 ~5 ~52 wooden_door 8 
setblock ~31 ~5 ~55 wooden_door 8 
setblock ~31 ~5 ~66 dropper 0 
setblock ~32 ~5 ~1 dropper 0 
setblock ~32 ~5 ~2 fence 0 
setblock ~32 ~5 ~4 wooden_door 8 
setblock ~32 ~5 ~24 brick_stairs 5 
setblock ~32 ~5 ~32 brick_stairs 5  
fill ~32 ~5 ~42 ~33 ~5 ~42 brick_block 0  
fill ~32 ~5 ~60 ~33 ~5 ~60 brick_block 0  
fill ~32 ~5 ~62 ~35 ~5 ~62 brick_block 0 
setblock ~32 ~5 ~64 wooden_door 8 
setblock ~32 ~5 ~67 dropper 0 
setblock ~33 ~5 ~1 red_flower 0  
fill ~33 ~5 ~2 ~33 ~9 ~2 brick_block 0 
setblock ~33 ~5 ~6 wooden_door 8 
setblock ~33 ~5 ~16 wooden_door 9  
fill ~33 ~5 ~66 ~33 ~9 ~66 brick_block 0 
setblock ~33 ~5 ~67 yellow_flower 0  
fill ~34 ~5 ~2 ~34 ~6 ~2 glass_pane 0  
fill ~34 ~5 ~6 ~35 ~5 ~6 brick_block 0  
fill ~34 ~5 ~8 ~34 ~6 ~8 glass_pane 0  
fill ~34 ~5 ~9 ~34 ~15 ~9 brick_block 0  
fill ~34 ~5 ~10 ~35 ~5 ~10 brick_block 0 
setblock ~34 ~5 ~16 wooden_door 8 
setblock ~34 ~5 ~36 wooden_door 8  
fill ~34 ~5 ~66 ~34 ~6 ~66 glass_pane 0 
setblock ~35 ~5 ~1 red_flower 0  
fill ~35 ~5 ~2 ~35 ~9 ~2 brick_block 0  
fill ~35 ~5 ~7 ~36 ~5 ~7 dropper 0 
setblock ~35 ~5 ~9 dropper 0  
fill ~35 ~5 ~16 ~35 ~10 ~16 brick_block 0 
setblock ~35 ~5 ~61 red_flower 0  
fill ~35 ~5 ~66 ~35 ~9 ~66 brick_block 0 
setblock ~35 ~5 ~67 yellow_flower 0 
setblock ~36 ~5 ~1 dropper 0 
setblock ~36 ~5 ~2 fence 0  
fill ~36 ~5 ~4 ~36 ~6 ~4 glass_pane 0  
fill ~36 ~5 ~5 ~36 ~9 ~5 brick_block 0 
setblock ~36 ~5 ~6 fence 0 
setblock ~36 ~5 ~9 red_flower 0  
fill ~36 ~5 ~10 ~36 ~6 ~10 glass_pane 0  
fill ~36 ~5 ~16 ~36 ~6 ~16 glass_pane 0 
setblock ~36 ~5 ~17 yellow_flower 0 
setblock ~36 ~5 ~35 dropper 0 
setblock ~36 ~5 ~36 fence 0  
fill ~36 ~5 ~38 ~36 ~6 ~38 glass_pane 0  
fill ~36 ~5 ~39 ~36 ~9 ~39 brick_block 0 
setblock ~36 ~5 ~40 fence 0 
setblock ~36 ~5 ~41 dropper 0 
setblock ~36 ~5 ~61 dropper 0 
setblock ~36 ~5 ~62 fence 0  
fill ~36 ~5 ~64 ~36 ~6 ~64 glass_pane 0  
fill ~36 ~5 ~65 ~36 ~9 ~65 brick_block 0 
setblock ~36 ~5 ~66 fence 0 
setblock ~36 ~5 ~67 dropper 0 
setblock ~37 ~5 ~2 dropper 0 
setblock ~37 ~5 ~3 yellow_flower 0 
setblock ~37 ~5 ~5 wool 0 
setblock ~37 ~5 ~6 dropper 0 
setblock ~37 ~5 ~9 dropper 0  
fill ~37 ~5 ~10 ~37 ~10 ~10 brick_block 0  
fill ~37 ~5 ~11 ~37 ~6 ~11 glass_pane 0  
fill ~37 ~5 ~12 ~37 ~6 ~12 glass_pane 0  
fill ~37 ~5 ~13 ~37 ~7 ~13 brick_block 0  
fill ~37 ~5 ~14 ~37 ~6 ~14 glass_pane 0  
fill ~37 ~5 ~15 ~37 ~6 ~15 glass_pane 0  
fill ~37 ~5 ~16 ~37 ~10 ~16 brick_block 0 
setblock ~37 ~5 ~17 dropper 0 
setblock ~37 ~5 ~36 dropper 0 
setblock ~37 ~5 ~37 wool 0 
setblock ~37 ~5 ~39 wool 0 
setblock ~37 ~5 ~40 dropper 0 
setblock ~37 ~5 ~62 dropper 0 
setblock ~37 ~5 ~63 red_flower 0 
setblock ~37 ~5 ~65 wool 0 
setblock ~37 ~5 ~66 dropper 0  
fill ~38 ~5 ~9 ~38 ~10 ~9 brick_block 0 
setblock ~38 ~5 ~10 dropper 0 
setblock ~38 ~5 ~11 wool 0 
setblock ~38 ~5 ~12 yellow_flower 0 
setblock ~38 ~5 ~13 dropper 0 
setblock ~38 ~5 ~14 red_flower 0 
setblock ~38 ~5 ~15 yellow_flower 0 
setblock ~38 ~5 ~16 dropper 0  
fill ~38 ~5 ~17 ~38 ~10 ~17 brick_block 0  
fill ~5 ~6 ~40 ~7 ~6 ~40 brick_block 0  
fill ~5 ~6 ~62 ~8 ~6 ~62 brick_block 0  
fill ~6 ~6 ~6 ~8 ~6 ~6 brick_block 0  
fill ~6 ~6 ~36 ~8 ~6 ~36 brick_block 0  
fill ~7 ~6 ~61 ~11 ~6 ~61 brick_block 0  
fill ~8 ~6 ~4 ~8 ~7 ~4 brick_block 0 
setblock ~8 ~6 ~24 leaves 8 
setblock ~8 ~6 ~32 leaves 8  
fill ~8 ~6 ~42 ~9 ~6 ~42 bookshelf 0  
fill ~8 ~6 ~60 ~11 ~6 ~60 bookshelf 0  
fill ~8 ~6 ~64 ~8 ~7 ~64 brick_block 0  
fill ~9 ~6 ~7 ~11 ~6 ~7 brick_block 0  
fill ~9 ~6 ~33 ~10 ~6 ~33 brick_block 0 
setblock ~9 ~6 ~35 wool 13 
setblock ~9 ~6 ~36 wool 0 
setblock ~9 ~6 ~37 wool 13 
setblock ~9 ~6 ~38 wool 0 
setblock ~9 ~6 ~39 wool 13 
setblock ~10 ~6 ~28 quartz_block 0 
setblock ~11 ~6 ~26 tripwire_hook 3 
setblock ~11 ~6 ~30 tripwire_hook 3  
fill ~12 ~6 ~7 ~14 ~6 ~7 glass 0  
fill ~12 ~6 ~61 ~14 ~6 ~61 glass 0  
fill ~14 ~6 ~41 ~14 ~9 ~41 brick_block 0  
fill ~15 ~6 ~7 ~18 ~6 ~7 brick_block 0  
fill ~15 ~6 ~21 ~17 ~6 ~21 brick_stairs 6  
fill ~15 ~6 ~22 ~18 ~6 ~22 brick_block 0  
fill ~15 ~6 ~34 ~17 ~6 ~34 brick_block 0 
setblock ~15 ~6 ~35 wool 13 
setblock ~15 ~6 ~36 wool 0 
setblock ~15 ~6 ~37 wool 13 
setblock ~15 ~6 ~38 wool 0 
setblock ~15 ~6 ~39 wool 13 
setblock ~15 ~6 ~41 lever 9 
setblock ~15 ~6 ~42 lit_redstone_lamp 0 
setblock ~15 ~6 ~52 lit_redstone_lamp 0  
fill ~15 ~6 ~61 ~17 ~6 ~61 brick_block 0  
fill ~16 ~6 ~23 ~18 ~6 ~23 brick_block 0 
setblock ~16 ~6 ~26 stone_slab 6 
setblock ~16 ~6 ~30 stone_slab 6  
fill ~16 ~6 ~33 ~18 ~6 ~33 brick_block 0  
fill ~16 ~6 ~47 ~18 ~6 ~47 brick_block 0 
setblock ~16 ~6 ~52 lever 12  
fill ~16 ~6 ~54 ~18 ~6 ~54 brick_block 0  
fill ~16 ~6 ~60 ~18 ~6 ~60 brick_block 0 
setblock ~16 ~6 ~62 leaves 8  
fill ~17 ~6 ~26 ~18 ~6 ~26 brick_block 0  
fill ~17 ~6 ~27 ~17 ~6 ~29 spruce_stairs 0  
fill ~17 ~6 ~30 ~18 ~6 ~30 brick_block 0 
setblock ~17 ~6 ~35 dispenser 5  
fill ~17 ~6 ~36 ~17 ~6 ~39 activator_rail 0  
fill ~17 ~6 ~41 ~18 ~6 ~41 brick_block 0  
fill ~18 ~6 ~27 ~18 ~6 ~29 planks 1  
fill ~18 ~6 ~36 ~18 ~6 ~39 stone_button 1  
fill ~19 ~6 ~7 ~21 ~6 ~7 glass 0 
setblock ~19 ~6 ~23 brick_stairs 5 
setblock ~19 ~6 ~26 brick_stairs 5  
fill ~19 ~6 ~28 ~19 ~7 ~28 planks 1 
setblock ~19 ~6 ~30 brick_stairs 5 
setblock ~19 ~6 ~33 brick_stairs 5  
fill ~19 ~6 ~36 ~19 ~6 ~38 dropper 8 
setblock ~19 ~6 ~41 brick_stairs 5  
fill ~19 ~6 ~53 ~21 ~6 ~53 wool 9 
setblock ~20 ~6 ~35 dropper 8 
setblock ~20 ~6 ~39 dropper 8  
fill ~20 ~6 ~48 ~20 ~7 ~48 wool 9  
fill ~20 ~6 ~60 ~20 ~7 ~60 quartz_block 0 
setblock ~21 ~6 ~23 brick_stairs 4 
setblock ~21 ~6 ~26 brick_stairs 4  
fill ~21 ~6 ~28 ~22 ~6 ~28 planks 1 
setblock ~21 ~6 ~30 brick_stairs 4 
setblock ~21 ~6 ~33 brick_stairs 4  
fill ~21 ~6 ~36 ~21 ~6 ~38 dropper 8 
setblock ~21 ~6 ~41 brick_stairs 4  
fill ~22 ~6 ~7 ~25 ~6 ~7 brick_block 0  
fill ~22 ~6 ~23 ~24 ~6 ~23 brick_block 0  
fill ~22 ~6 ~26 ~23 ~6 ~26 brick_block 0  
fill ~22 ~6 ~27 ~22 ~5 ~27 planks 1  
fill ~22 ~6 ~29 ~22 ~5 ~29 planks 1  
fill ~22 ~6 ~30 ~23 ~6 ~30 brick_block 0  
fill ~22 ~6 ~33 ~24 ~6 ~33 brick_block 0  
fill ~22 ~6 ~41 ~23 ~6 ~41 brick_block 0  
fill ~22 ~6 ~54 ~24 ~6 ~54 brick_block 0  
fill ~22 ~6 ~60 ~24 ~6 ~60 brick_block 0  
fill ~23 ~6 ~22 ~24 ~6 ~22 brick_block 0  
fill ~23 ~6 ~27 ~23 ~6 ~29 spruce_stairs 1  
fill ~23 ~6 ~34 ~25 ~6 ~34 brick_block 0  
fill ~23 ~6 ~35 ~23 ~6 ~37 dropper 8 
setblock ~23 ~6 ~38 stone_stairs 2 
setblock ~23 ~6 ~39 stone_stairs 3  
fill ~23 ~6 ~48 ~23 ~7 ~48 wool 9  
fill ~23 ~6 ~49 ~23 ~7 ~49 wool 9  
fill ~23 ~6 ~61 ~25 ~6 ~61 brick_block 0  
fill ~24 ~6 ~8 ~25 ~6 ~8 wool 0  
fill ~24 ~6 ~10 ~25 ~6 ~10 wool 0  
fill ~24 ~6 ~16 ~25 ~6 ~16 wool 0 
setblock ~24 ~6 ~26 stone_slab 6 
setblock ~24 ~6 ~30 stone_slab 6 
setblock ~24 ~6 ~62 leaves 8  
fill ~25 ~6 ~41 ~26 ~6 ~41 brick_block 0  
fill ~26 ~6 ~7 ~28 ~6 ~7 glass 0  
fill ~26 ~6 ~61 ~28 ~6 ~61 glass 0  
fill ~29 ~6 ~7 ~32 ~6 ~7 brick_block 0 
setblock ~29 ~6 ~26 tripwire_hook 1 
setblock ~29 ~6 ~30 tripwire_hook 1  
fill ~29 ~6 ~61 ~33 ~6 ~61 brick_block 0 
setblock ~30 ~6 ~28 quartz_block 0  
fill ~30 ~6 ~41 ~33 ~6 ~41 brick_block 0  
fill ~31 ~6 ~8 ~31 ~6 ~9 oak_stairs 0  
fill ~31 ~6 ~10 ~35 ~6 ~10 brick_block 0 
setblock ~31 ~6 ~12 brick_stairs 7 
setblock ~31 ~6 ~14 brick_stairs 6  
fill ~31 ~6 ~16 ~35 ~6 ~16 brick_block 0  
fill ~31 ~6 ~24 ~31 ~15 ~24 brick_block 0  
fill ~31 ~6 ~25 ~31 ~15 ~25 brick_block 0  
fill ~31 ~6 ~40 ~35 ~6 ~40 brick_block 0  
fill ~32 ~6 ~4 ~32 ~7 ~4 brick_block 0 
setblock ~32 ~6 ~24 leaves 8 
setblock ~32 ~6 ~32 leaves 8  
fill ~32 ~6 ~42 ~33 ~6 ~42 brick_block 0  
fill ~32 ~6 ~60 ~33 ~6 ~60 brick_block 0  
fill ~32 ~6 ~62 ~35 ~6 ~62 brick_block 0  
fill ~32 ~6 ~64 ~32 ~7 ~64 brick_block 0  
fill ~33 ~6 ~6 ~35 ~6 ~6 brick_block 0  
fill ~34 ~6 ~36 ~34 ~7 ~36 brick_block 0 
setblock ~4 ~7 ~4 brick_block 0 
setblock ~4 ~7 ~38 brick_block 0 
setblock ~4 ~7 ~64 brick_block 0  
fill ~5 ~7 ~40 ~7 ~7 ~40 brick_block 0  
fill ~5 ~7 ~62 ~8 ~7 ~62 brick_block 0 
setblock ~6 ~7 ~2 brick_block 0  
fill ~6 ~7 ~6 ~8 ~7 ~6 brick_block 0  
fill ~6 ~7 ~36 ~8 ~7 ~36 brick_block 0 
setblock ~6 ~7 ~43 quartz_stairs 2 
setblock ~6 ~7 ~44 quartz_stairs 7 
setblock ~6 ~7 ~46 quartz_stairs 6 
setblock ~6 ~7 ~47 quartz_stairs 3 
setblock ~6 ~7 ~49 quartz_stairs 2 
setblock ~6 ~7 ~50 quartz_stairs 7 
setblock ~6 ~7 ~52 quartz_stairs 6 
setblock ~6 ~7 ~53 quartz_stairs 3 
setblock ~6 ~7 ~55 quartz_stairs 2 
setblock ~6 ~7 ~56 quartz_stairs 7 
setblock ~6 ~7 ~58 quartz_stairs 6 
setblock ~6 ~7 ~59 quartz_stairs 3 
setblock ~6 ~7 ~66 brick_block 0  
fill ~7 ~7 ~61 ~11 ~7 ~61 brick_block 0 
setblock ~8 ~7 ~8 quartz_stairs 7 
setblock ~8 ~7 ~10 quartz_stairs 6 
setblock ~8 ~7 ~12 quartz_stairs 7 
setblock ~8 ~7 ~14 quartz_stairs 6 
setblock ~8 ~7 ~16 quartz_stairs 7 
setblock ~8 ~7 ~18 quartz_stairs 6 
setblock ~8 ~7 ~20 quartz_stairs 7 
setblock ~8 ~7 ~22 quartz_stairs 6 
setblock ~8 ~7 ~23 quartz_stairs 3 
setblock ~8 ~7 ~25 stone_brick_stairs 2 
setblock ~8 ~7 ~26 stone_brick_stairs 7 
setblock ~8 ~7 ~30 stone_brick_stairs 6 
setblock ~8 ~7 ~31 stone_brick_stairs 3  
fill ~8 ~7 ~42 ~9 ~7 ~42 bookshelf 0  
fill ~8 ~7 ~44 ~8 ~7 ~46 fence_gate 1  
fill ~8 ~7 ~50 ~8 ~7 ~52 fence_gate 1  
fill ~8 ~7 ~56 ~8 ~7 ~58 fence_gate 1  
fill ~8 ~7 ~60 ~11 ~7 ~60 bookshelf 0  
fill ~9 ~7 ~7 ~11 ~7 ~7 brick_block 0 
setblock ~9 ~7 ~26 stone_brick_stairs 2 
setblock ~9 ~7 ~27 stone_brick_stairs 7 
setblock ~9 ~7 ~29 stone_brick_stairs 6 
setblock ~9 ~7 ~30 stone_brick_stairs 3  
fill ~9 ~7 ~33 ~10 ~7 ~33 brick_block 0 
setblock ~9 ~7 ~35 wool 0 
setblock ~9 ~7 ~36 wool 13 
setblock ~9 ~7 ~37 wool 0 
setblock ~9 ~7 ~38 wool 13 
setblock ~9 ~7 ~39 wool 0  
fill ~10 ~7 ~27 ~10 ~7 ~29 quartz_stairs 5  
setblock ~11 ~7 ~6 quartz_stairs 0 
setblock ~11 ~7 ~23 brick_stairs 5 
setblock ~11 ~7 ~33 brick_stairs 5 
setblock ~11 ~7 ~41 brick_stairs 5 
setblock ~11 ~7 ~49 glowstone 0 
setblock ~11 ~7 ~53 glowstone 0 
setblock ~11 ~7 ~62 quartz_stairs 0 
setblock ~12 ~7 ~6 quartz_stairs 5  
fill ~12 ~7 ~7 ~14 ~7 ~7 glass 0 
setblock ~12 ~7 ~37 glowstone 0  
fill ~12 ~7 ~60 ~14 ~7 ~60 fence_gate 0  
fill ~12 ~7 ~61 ~14 ~7 ~61 glass 0 
setblock ~12 ~7 ~62 quartz_stairs 5 
setblock ~13 ~7 ~23 brick_stairs 4 
setblock ~13 ~7 ~33 brick_stairs 4 
setblock ~13 ~7 ~41 brick_stairs 4 
setblock ~14 ~7 ~6 quartz_stairs 4 
setblock ~14 ~7 ~62 quartz_stairs 4 
setblock ~15 ~7 ~6 quartz_stairs 1  
fill ~15 ~7 ~7 ~18 ~7 ~7 brick_block 0  
fill ~15 ~7 ~21 ~17 ~7 ~21 brick_block 0  
fill ~15 ~7 ~22 ~18 ~7 ~22 brick_block 0  
fill ~15 ~7 ~34 ~17 ~7 ~34 brick_block 0 
setblock ~15 ~7 ~35 wool 0 
setblock ~15 ~7 ~36 wool 13 
setblock ~15 ~7 ~37 wool 0 
setblock ~15 ~7 ~38 wool 13 
setblock ~15 ~7 ~39 wool 0 
setblock ~15 ~7 ~41 brick_block 0  
fill ~15 ~7 ~61 ~17 ~7 ~61 brick_block 0 
setblock ~15 ~7 ~62 quartz_stairs 1  
fill ~16 ~7 ~23 ~24 ~7 ~23 brick_block 0  
fill ~16 ~7 ~33 ~24 ~7 ~33 brick_block 0 
setblock ~16 ~7 ~43 brick_stairs 7 
setblock ~16 ~7 ~45 brick_stairs 6  
fill ~16 ~7 ~47 ~18 ~7 ~47 brick_block 0  
fill ~16 ~7 ~52 ~16 ~9 ~52 brick_block 0  
fill ~16 ~7 ~54 ~18 ~7 ~54 brick_block 0 
setblock ~16 ~7 ~56 brick_stairs 7 
setblock ~16 ~7 ~58 brick_stairs 6  
fill ~16 ~7 ~60 ~18 ~7 ~60 brick_block 0 
setblock ~17 ~7 ~26 stone_slab 6 
setblock ~17 ~7 ~30 stone_slab 6  
fill ~17 ~7 ~35 ~17 ~8 ~35 stone_slab 6  
fill ~17 ~7 ~36 ~17 ~7 ~39 dropper 0  
fill ~17 ~7 ~41 ~23 ~7 ~41 brick_block 0 
setblock ~17 ~7 ~62 stone_brick_stairs 0 
setblock ~18 ~7 ~6 quartz_stairs 0  
fill ~18 ~7 ~24 ~18 ~7 ~25 spruce_stairs 4 
setblock ~18 ~7 ~26 double_stone_slab 6  
fill ~18 ~7 ~27 ~18 ~7 ~29 spruce_stairs 0 
setblock ~18 ~7 ~30 double_stone_slab 6  
fill ~18 ~7 ~31 ~18 ~7 ~32 spruce_stairs 4  
fill ~18 ~7 ~34 ~22 ~7 ~34 stone_slab 14  
fill ~18 ~7 ~35 ~19 ~7 ~35 stone_slab 14  
fill ~18 ~7 ~36 ~18 ~7 ~40 stone_slab 14  
fill ~18 ~7 ~49 ~19 ~7 ~49 activator_rail 2  
fill ~18 ~7 ~50 ~22 ~7 ~50 activator_rail 2  
fill ~18 ~7 ~51 ~22 ~7 ~51 activator_rail 2  
fill ~18 ~7 ~52 ~19 ~7 ~52 activator_rail 2 
setblock ~18 ~7 ~59 brick_stairs 0 
setblock ~18 ~7 ~61 stone_brick_stairs 0 
setblock ~18 ~7 ~62 stone_brick_stairs 5 
setblock ~19 ~7 ~6 quartz_stairs 5  
fill ~19 ~7 ~7 ~21 ~7 ~7 glass 0  
fill ~19 ~7 ~24 ~21 ~7 ~24 planks 1  
fill ~19 ~7 ~25 ~21 ~7 ~25 planks 1  
fill ~19 ~7 ~26 ~21 ~7 ~26 planks 1  
fill ~19 ~7 ~27 ~21 ~7 ~27 planks 1  
fill ~19 ~7 ~29 ~21 ~7 ~29 planks 1  
fill ~19 ~7 ~30 ~21 ~7 ~30 planks 1  
fill ~19 ~7 ~31 ~21 ~7 ~31 planks 1  
fill ~19 ~7 ~32 ~21 ~7 ~32 planks 1  
fill ~19 ~7 ~36 ~19 ~7 ~38 bookshelf 0  
fill ~19 ~7 ~39 ~19 ~7 ~40 stone_slab 14 
setblock ~19 ~7 ~47 brick_stairs 5  
fill ~19 ~7 ~53 ~21 ~7 ~53 wool 9 
setblock ~19 ~7 ~54 brick_stairs 5 
setblock ~19 ~7 ~59 brick_stairs 5 
setblock ~19 ~7 ~61 stone_brick_stairs 5  
fill ~20 ~7 ~28 ~21 ~7 ~28 planks 1 
setblock ~20 ~7 ~35 oak_stairs 6  
fill ~20 ~7 ~36 ~20 ~7 ~38 lit_redstone_lamp 0 
setblock ~20 ~7 ~39 oak_stairs 7  
fill ~20 ~7 ~40 ~22 ~7 ~40 stone_slab 14 
setblock ~20 ~7 ~49 lit_redstone_lamp 0 
setblock ~20 ~7 ~52 lit_redstone_lamp 0 
setblock ~21 ~7 ~6 quartz_stairs 4  
fill ~21 ~7 ~35 ~22 ~7 ~35 stone_slab 14  
fill ~21 ~7 ~36 ~21 ~7 ~38 bookshelf 0  
fill ~21 ~7 ~39 ~22 ~7 ~39 stone_slab 14 
setblock ~21 ~7 ~47 brick_stairs 4  
fill ~21 ~7 ~49 ~22 ~7 ~49 activator_rail 2  
fill ~21 ~7 ~52 ~22 ~7 ~52 activator_rail 2 
setblock ~21 ~7 ~54 brick_stairs 4 
setblock ~21 ~7 ~59 brick_stairs 4 
setblock ~21 ~7 ~61 stone_brick_stairs 4 
setblock ~22 ~7 ~6 quartz_stairs 1  
fill ~22 ~7 ~7 ~25 ~7 ~7 brick_block 0  
fill ~22 ~7 ~24 ~22 ~7 ~25 spruce_stairs 5 
setblock ~22 ~7 ~26 double_stone_slab 6  
fill ~22 ~7 ~27 ~22 ~7 ~29 spruce_stairs 1 
setblock ~22 ~7 ~30 double_stone_slab 6  
fill ~22 ~7 ~31 ~22 ~7 ~32 spruce_stairs 5  
fill ~22 ~7 ~36 ~22 ~7 ~40 stone_slab 14  
fill ~22 ~7 ~54 ~24 ~7 ~54 brick_block 0 
setblock ~22 ~7 ~59 brick_stairs 1  
fill ~22 ~7 ~60 ~24 ~7 ~60 brick_block 0 
setblock ~22 ~7 ~61 stone_brick_stairs 1 
setblock ~22 ~7 ~62 stone_brick_stairs 4 
setblock ~23 ~7 ~12 brick_stairs 7 
setblock ~23 ~7 ~14 brick_stairs 6  
fill ~23 ~7 ~22 ~24 ~7 ~22 brick_block 0 
setblock ~23 ~7 ~26 stone_slab 6 
setblock ~23 ~7 ~30 stone_slab 6  
fill ~23 ~7 ~34 ~25 ~7 ~34 brick_block 0  
fill ~23 ~7 ~35 ~23 ~7 ~37 bookshelf 0  
fill ~23 ~7 ~38 ~23 ~7 ~39 cobblestone 0  
fill ~23 ~7 ~61 ~25 ~7 ~61 brick_block 0 
setblock ~23 ~7 ~62 stone_brick_stairs 1  
fill ~24 ~7 ~8 ~24 ~9 ~8 wool 0  
fill ~24 ~7 ~10 ~24 ~9 ~10 wool 0  
fill ~24 ~7 ~11 ~25 ~7 ~11 brick_stairs 3  
fill ~24 ~7 ~15 ~25 ~7 ~15 brick_stairs 2  
fill ~24 ~7 ~16 ~24 ~9 ~16 wool 0 
setblock ~24 ~7 ~43 brick_stairs 7 
setblock ~24 ~7 ~45 brick_stairs 6 
setblock ~24 ~7 ~56 brick_stairs 7 
setblock ~24 ~7 ~58 brick_stairs 6 
setblock ~25 ~7 ~6 quartz_stairs 0  
fill ~25 ~7 ~8 ~25 ~8 ~8 wool 11  
fill ~25 ~7 ~9 ~25 ~8 ~9 wool 0  
fill ~25 ~7 ~10 ~25 ~8 ~10 wool 11  
fill ~25 ~7 ~16 ~25 ~9 ~16 wool 11  
fill ~25 ~7 ~17 ~25 ~8 ~17 wool 0  
fill ~25 ~7 ~18 ~25 ~8 ~18 wool 0  
fill ~25 ~7 ~19 ~25 ~9 ~19 wool 11  
fill ~25 ~7 ~20 ~25 ~8 ~20 wool 0  
fill ~25 ~7 ~21 ~25 ~8 ~21 wool 0  
fill ~25 ~7 ~22 ~25 ~9 ~22 wool 11  
fill ~25 ~7 ~35 ~25 ~8 ~35 wool 14  
fill ~25 ~7 ~36 ~25 ~8 ~36 wool 0  
fill ~25 ~7 ~37 ~25 ~8 ~37 wool 14  
fill ~25 ~7 ~38 ~25 ~8 ~38 wool 0  
fill ~25 ~7 ~39 ~25 ~8 ~39 wool 14  
fill ~25 ~7 ~41 ~26 ~7 ~41 brick_block 0 
setblock ~25 ~7 ~62 quartz_stairs 0 
setblock ~26 ~7 ~6 quartz_stairs 5  
fill ~26 ~7 ~7 ~28 ~7 ~7 glass 0 
setblock ~26 ~7 ~12 brick_stairs 7 
