setblock ~32 ~13 ~-11 furnace 3  
setblock ~33 ~15 ~-10 furnace 3  
setblock ~31 ~13 ~-12 furnace 3  
setblock ~32 ~15 ~-11 furnace 3  
setblock ~31 ~15 ~-11 furnace 3  
setblock ~30 ~13 ~-13 furnace 3  
setblock ~29 ~13 ~-14 furnace 3  
setblock ~28 ~13 ~-15 furnace 3  
setblock ~27 ~13 ~-16 furnace 3  
setblock ~26 ~13 ~-17 furnace 3  
setblock ~25 ~13 ~-17 furnace 3  
setblock ~24 ~13 ~-17 furnace 3  
setblock ~23 ~13 ~-17 furnace 3  
setblock ~22 ~13 ~-17 furnace 3  
setblock ~21 ~13 ~-17 furnace 3  
setblock ~34 ~14 ~-9 furnace 3  
setblock ~33 ~14 ~-11 furnace 3  
setblock ~32 ~14 ~-12 furnace 3  
setblock ~31 ~14 ~-13 furnace 3  
setblock ~30 ~14 ~-14 furnace 3  
setblock ~29 ~14 ~-15 furnace 3  
setblock ~28 ~14 ~-16 furnace 3  
setblock ~27 ~14 ~-16 furnace 3  
setblock ~26 ~14 ~-16 furnace 3  
setblock ~25 ~14 ~-16 furnace 3  
setblock ~24 ~14 ~-16 furnace 3  
setblock ~23 ~14 ~-16 furnace 3  
setblock ~22 ~14 ~-16 furnace 3  
setblock ~21 ~14 ~-16 furnace 3  
setblock ~34 ~13 ~-9 furnace 3  
setblock ~33 ~13 ~-10 furnace 3  
setblock ~34 ~15 ~-9 furnace 3  
setblock ~28 ~42 ~23 command_block 1  
setblock ~28 ~42 ~22 command_block 1  
setblock ~25 ~35 ~29 command_block 5  
setblock ~25 ~35 ~30 command_block 5  
setblock ~34 ~42 ~22 furnace 4  
setblock ~33 ~43 ~22 furnace 5  
setblock ~34 ~44 ~22 furnace 4  
setblock ~28 ~42 ~25 command_block 1  
setblock ~28 ~42 ~24 command_block 1  
setblock ~33 ~43 ~37 furnace 5  
setblock ~34 ~44 ~37 furnace 4  
setblock ~34 ~42 ~37 furnace 4  
setblock ~28 ~42 ~34 command_block 1  
setblock ~28 ~42 ~35 command_block 1  
setblock ~28 ~42 ~36 command_block 1  
setblock ~28 ~42 ~37 command_block 1  
setblock ~31 ~15 ~70 furnace 2  
setblock ~21 ~9 ~75 furnace 2  
setblock ~32 ~15 ~70 furnace 2  
setblock ~22 ~9 ~75 furnace 2  
setblock ~23 ~9 ~75 furnace 2  
setblock ~29 ~13 ~73 furnace 2  
setblock ~33 ~13 ~69 furnace 2  
setblock ~24 ~9 ~75 furnace 2  
setblock ~33 ~11 ~68 furnace 2  
setblock ~29 ~11 ~72 furnace 2  
setblock ~25 ~9 ~75 furnace 2  
setblock ~26 ~9 ~75 furnace 2  
setblock ~34 ~9 ~67 furnace 2  
setblock ~30 ~9 ~71 furnace 2  
setblock ~29 ~7 ~74 furnace 2  
setblock ~21 ~10 ~75 furnace 2  
setblock ~22 ~10 ~75 furnace 2  
setblock ~23 ~10 ~75 furnace 2  
setblock ~24 ~10 ~75 furnace 2  
setblock ~33 ~12 ~68 furnace 2  
setblock ~29 ~12 ~72 furnace 2  
setblock ~30 ~14 ~73 furnace 2  
setblock ~25 ~10 ~75 furnace 2  
setblock ~26 ~10 ~75 furnace 2  
setblock ~34 ~10 ~67 furnace 2  
setblock ~30 ~10 ~71 furnace 2  
setblock ~32 ~8 ~70 furnace 2  
setblock ~28 ~8 ~74 furnace 2  
setblock ~21 ~13 ~76 furnace 2  
setblock ~21 ~11 ~75 furnace 2  
setblock ~22 ~13 ~76 furnace 2  
setblock ~22 ~11 ~75 furnace 2  
setblock ~23 ~13 ~76 furnace 2  
setblock ~23 ~11 ~75 furnace 2  
setblock ~24 ~13 ~76 furnace 2  
setblock ~33 ~15 ~69 furnace 2  
setblock ~24 ~11 ~75 furnace 2  
setblock ~25 ~13 ~76 furnace 2  
setblock ~25 ~11 ~75 furnace 2  
setblock ~30 ~13 ~72 furnace 2  
setblock ~26 ~13 ~76 furnace 2  
setblock ~34 ~13 ~68 furnace 2  
setblock ~26 ~11 ~75 furnace 2  
setblock ~34 ~11 ~67 furnace 2  
setblock ~30 ~11 ~71 furnace 2  
setblock ~27 ~9 ~74 furnace 2  
setblock ~31 ~9 ~70 furnace 2  
setblock ~33 ~7 ~69 furnace 2  
setblock ~30 ~7 ~73 furnace 2  
setblock ~21 ~12 ~75 furnace 2  
setblock ~22 ~12 ~75 furnace 2  
setblock ~23 ~12 ~75 furnace 2  
setblock ~24 ~12 ~75 furnace 2  
setblock ~25 ~12 ~75 furnace 2  
setblock ~34 ~14 ~68 furnace 2  
setblock ~30 ~12 ~71 furnace 2  
setblock ~26 ~12 ~75 furnace 2  
setblock ~34 ~12 ~67 furnace 2  
setblock ~31 ~14 ~72 furnace 2  
setblock ~27 ~10 ~74 furnace 2  
setblock ~31 ~10 ~70 furnace 2  
setblock ~33 ~8 ~69 furnace 2  
setblock ~29 ~8 ~73 furnace 2  
setblock ~34 ~15 ~68 furnace 2  
setblock ~31 ~13 ~71 furnace 2  
setblock ~27 ~13 ~75 furnace 2  
setblock ~27 ~11 ~74 furnace 2  
setblock ~31 ~11 ~70 furnace 2  
setblock ~32 ~9 ~69 furnace 2  
setblock ~28 ~9 ~73 furnace 2  
setblock ~34 ~7 ~68 furnace 2  
setblock ~31 ~7 ~72 furnace 2  
setblock ~21 ~14 ~75 furnace 2  
setblock ~22 ~14 ~75 furnace 2  
setblock ~23 ~14 ~75 furnace 2  
setblock ~24 ~14 ~75 furnace 2  
setblock ~25 ~14 ~75 furnace 2  
setblock ~26 ~14 ~75 furnace 2  
setblock ~27 ~14 ~75 furnace 2  
setblock ~27 ~12 ~74 furnace 2  
setblock ~31 ~12 ~70 furnace 2  
setblock ~28 ~14 ~75 furnace 2  
setblock ~32 ~14 ~71 furnace 2  
setblock ~32 ~10 ~69 furnace 2  
setblock ~28 ~10 ~73 furnace 2  
setblock ~34 ~8 ~68 furnace 2  
setblock ~30 ~8 ~72 furnace 2  
setblock ~28 ~13 ~74 furnace 2  
setblock ~32 ~13 ~70 furnace 2  
setblock ~32 ~11 ~69 furnace 2  
setblock ~28 ~11 ~73 furnace 2  
setblock ~33 ~9 ~68 furnace 2  
setblock ~29 ~9 ~72 furnace 2  
setblock ~28 ~7 ~75 furnace 2  
setblock ~32 ~7 ~71 furnace 2  
setblock ~21 ~8 ~75 furnace 2  
setblock ~22 ~8 ~75 furnace 2  
setblock ~32 ~12 ~69 furnace 2  
setblock ~28 ~12 ~73 furnace 2  
setblock ~29 ~14 ~74 furnace 2  
setblock ~33 ~14 ~70 furnace 2  
setblock ~23 ~8 ~75 furnace 2  
setblock ~24 ~8 ~75 furnace 2  
setblock ~33 ~10 ~68 furnace 2  
setblock ~29 ~10 ~72 furnace 2  
setblock ~25 ~8 ~75 furnace 2  
setblock ~26 ~8 ~75 furnace 2  
setblock ~27 ~8 ~75 furnace 2  
setblock ~31 ~8 ~71 furnace 2  
setblock ~41 ~13 ~-2 furnace 3  
setblock ~41 ~14 ~-2 furnace 3  
setblock ~40 ~13 ~-3 furnace 3  
setblock ~42 ~16 ~-2 furnace 3  
setblock ~41 ~15 ~-2 furnace 3  
setblock ~40 ~14 ~-3 furnace 3  
setblock ~40 ~15 ~-3 furnace 3  
setblock ~39 ~13 ~-4 furnace 3  
setblock ~41 ~16 ~-3 furnace 3  
setblock ~39 ~14 ~-4 furnace 3  
setblock ~40 ~16 ~-3 furnace 3  
setblock ~38 ~13 ~-5 furnace 3  
setblock ~38 ~14 ~-5 furnace 3  
setblock ~39 ~15 ~-5 furnace 3  
setblock ~37 ~13 ~-6 furnace 3  
setblock ~37 ~14 ~-6 furnace 3  
setblock ~38 ~15 ~-6 furnace 3  
setblock ~36 ~13 ~-7 furnace 3  
setblock ~36 ~14 ~-7 furnace 3  
setblock ~37 ~15 ~-7 furnace 3  
setblock ~35 ~13 ~-8 furnace 3  
setblock ~35 ~14 ~-8 furnace 3  
setblock ~36 ~15 ~-8 furnace 3  
setblock ~35 ~15 ~-9 furnace 3  
setblock ~50 ~16 ~7 furnace 3  
setblock ~49 ~14 ~6 furnace 3  
setblock ~49 ~16 ~6 furnace 3  
setblock ~48 ~14 ~5 furnace 3  
setblock ~48 ~16 ~5 furnace 3  
setblock ~47 ~14 ~4 furnace 3  
setblock ~46 ~14 ~3 furnace 3  
setblock ~47 ~16 ~4 furnace 3  
setblock ~46 ~16 ~3 furnace 3  
setblock ~45 ~14 ~2 furnace 3  
setblock ~44 ~14 ~1 furnace 3  
setblock ~45 ~16 ~1 furnace 3  
setblock ~43 ~14 ~0 furnace 3  
setblock ~44 ~16 ~0 furnace 3  
setblock ~42 ~14 ~-1 furnace 3  
setblock ~43 ~16 ~-1 furnace 3  
setblock ~50 ~13 ~7 furnace 3  
setblock ~50 ~15 ~7 furnace 3  
setblock ~49 ~13 ~6 furnace 3  
setblock ~49 ~15 ~6 furnace 3  
setblock ~48 ~13 ~5 furnace 3  
setblock ~50 ~17 ~6 furnace 3  
setblock ~48 ~15 ~5 furnace 3  
setblock ~47 ~13 ~4 furnace 3  
setblock ~49 ~17 ~5 furnace 3  
setblock ~46 ~13 ~3 furnace 3  
setblock ~47 ~15 ~4 furnace 3  
setblock ~48 ~17 ~4 furnace 3  
setblock ~46 ~15 ~3 furnace 3  
setblock ~45 ~13 ~2 furnace 3  
setblock ~47 ~17 ~3 furnace 3  
setblock ~44 ~13 ~1 furnace 3  
setblock ~45 ~15 ~2 furnace 3  
setblock ~43 ~13 ~0 furnace 3  
setblock ~44 ~15 ~1 furnace 3  
setblock ~42 ~13 ~-1 furnace 3  
setblock ~43 ~15 ~0 furnace 3  
setblock ~42 ~15 ~-1 furnace 3  
setblock ~50 ~14 ~7 furnace 3  
setblock ~50 ~7 ~30 furnace 2  
setblock ~48 ~7 ~30 furnace 2  
setblock ~46 ~7 ~30 furnace 2  
setblock ~50 ~11 ~28 chest 3  
setblock ~48 ~11 ~28 chest 3  
setblock ~46 ~11 ~28 chest 3  
setblock ~50 ~6 ~30 furnace 2  
setblock ~48 ~6 ~30 furnace 2  
setblock ~46 ~6 ~30 furnace 2  
setblock ~50 ~12 ~28 chest 3  
setblock ~48 ~12 ~28 chest 3  
setblock ~46 ~12 ~28 chest 3  
setblock ~35 ~43 ~23 furnace 2  
setblock ~35 ~18 ~26 chest 5  
setblock ~50 ~7 ~32 furnace 3  
setblock ~35 ~43 ~36 furnace 3  
setblock ~45 ~6 ~31 furnace 4  
setblock ~46 ~6 ~32 furnace 3  
setblock ~47 ~6 ~31 furnace 4  
setblock ~48 ~6 ~32 furnace 3  
setblock ~49 ~6 ~31 furnace 5  
setblock ~50 ~6 ~32 furnace 3  
setblock ~45 ~7 ~31 furnace 4  
setblock ~46 ~7 ~32 furnace 3  
setblock ~47 ~7 ~31 furnace 4  
setblock ~48 ~7 ~32 furnace 3  
setblock ~49 ~7 ~31 furnace 5  
setblock ~48 ~17 ~55 furnace 2  
setblock ~48 ~15 ~54 furnace 2  
setblock ~40 ~15 ~62 furnace 2  
setblock ~44 ~15 ~58 furnace 2  
setblock ~49 ~13 ~53 furnace 2  
setblock ~41 ~13 ~61 furnace 2  
setblock ~45 ~13 ~57 furnace 2  
setblock ~41 ~11 ~60 furnace 2  
setblock ~49 ~11 ~52 furnace 2  
setblock ~45 ~11 ~56 furnace 2  
setblock ~42 ~9 ~59 furnace 2  
setblock ~50 ~9 ~51 furnace 2  
setblock ~46 ~9 ~55 furnace 2  
setblock ~40 ~7 ~62 furnace 2  
setblock ~48 ~7 ~54 furnace 2  
setblock ~44 ~7 ~58 furnace 2  
setblock ~49 ~5 ~53 furnace 2  
setblock ~48 ~16 ~54 furnace 2  
setblock ~40 ~16 ~62 furnace 2  
setblock ~41 ~16 ~62 furnace 2  
setblock ~45 ~16 ~58 furnace 2  
setblock ~49 ~14 ~53 furnace 2  
setblock ~41 ~14 ~61 furnace 2  
setblock ~45 ~14 ~57 furnace 2  
setblock ~41 ~12 ~60 furnace 2  
setblock ~49 ~12 ~52 furnace 2  
setblock ~45 ~12 ~56 furnace 2  
setblock ~42 ~10 ~59 furnace 2  
setblock ~50 ~10 ~51 furnace 2  
setblock ~46 ~10 ~55 furnace 2  
setblock ~40 ~8 ~62 furnace 2  
setblock ~48 ~8 ~54 furnace 2  
setblock ~44 ~8 ~58 furnace 2  
setblock ~41 ~6 ~61 furnace 2  
setblock ~49 ~6 ~53 furnace 2  
setblock ~45 ~6 ~57 furnace 2  
setblock ~49 ~15 ~53 furnace 2  
setblock ~41 ~15 ~61 furnace 2  
setblock ~45 ~15 ~57 furnace 2  
setblock ~50 ~13 ~52 furnace 2  
setblock ~46 ~13 ~56 furnace 2  
setblock ~42 ~13 ~60 furnace 2  
setblock ~42 ~11 ~59 furnace 2  
setblock ~50 ~11 ~51 furnace 2  
setblock ~46 ~11 ~55 furnace 2  
setblock ~43 ~9 ~58 furnace 2  
setblock ~39 ~9 ~62 furnace 2  
setblock ~47 ~9 ~54 furnace 2  
setblock ~41 ~7 ~61 furnace 2  
setblock ~49 ~7 ~53 furnace 2  
setblock ~45 ~7 ~57 furnace 2  
setblock ~50 ~5 ~52 furnace 2  
setblock ~46 ~5 ~56 furnace 2  
setblock ~49 ~16 ~53 furnace 2  
setblock ~42 ~16 ~61 furnace 2  
setblock ~50 ~14 ~52 furnace 2  
setblock ~46 ~14 ~56 furnace 2  
setblock ~42 ~14 ~60 furnace 2  
setblock ~42 ~12 ~59 furnace 2  
setblock ~50 ~12 ~51 furnace 2  
setblock ~46 ~12 ~55 furnace 2  
setblock ~43 ~10 ~58 furnace 2  
setblock ~39 ~10 ~62 furnace 2  
setblock ~47 ~10 ~54 furnace 2  
setblock ~41 ~8 ~61 furnace 2  
setblock ~49 ~8 ~53 furnace 2  
setblock ~45 ~8 ~57 furnace 2  
setblock ~42 ~6 ~60 furnace 2  
setblock ~50 ~6 ~52 furnace 2  
setblock ~46 ~6 ~56 furnace 2  
setblock ~49 ~17 ~53 furnace 2  
setblock ~50 ~17 ~53 furnace 2  
setblock ~50 ~15 ~52 furnace 2  
setblock ~46 ~15 ~56 furnace 2  
setblock ~42 ~15 ~60 furnace 2  
setblock ~47 ~13 ~55 furnace 2  
setblock ~43 ~13 ~59 furnace 2  
setblock ~43 ~11 ~58 furnace 2  
setblock ~39 ~11 ~62 furnace 2  
setblock ~47 ~11 ~54 furnace 2  
setblock ~40 ~9 ~61 furnace 2  
setblock ~48 ~9 ~53 furnace 2  
setblock ~44 ~9 ~57 furnace 2  
setblock ~42 ~7 ~60 furnace 2  
setblock ~50 ~7 ~52 furnace 2  
setblock ~46 ~7 ~56 furnace 2  
setblock ~47 ~5 ~55 furnace 2  
setblock ~50 ~16 ~52 furnace 2  
setblock ~46 ~16 ~56 furnace 2  
setblock ~43 ~16 ~60 furnace 2  
setblock ~47 ~14 ~55 furnace 2  
setblock ~43 ~14 ~59 furnace 2  
setblock ~43 ~12 ~58 furnace 2  
setblock ~39 ~12 ~62 furnace 2  
setblock ~47 ~12 ~54 furnace 2  
setblock ~40 ~10 ~61 furnace 2  
setblock ~48 ~10 ~53 furnace 2  
setblock ~44 ~10 ~57 furnace 2  
setblock ~42 ~8 ~60 furnace 2  
setblock ~50 ~8 ~52 furnace 2  
setblock ~46 ~8 ~56 furnace 2  
setblock ~43 ~6 ~59 furnace 2  
setblock ~47 ~6 ~55 furnace 2  
setblock ~46 ~17 ~56 furnace 2  
setblock ~47 ~17 ~56 furnace 2  
setblock ~47 ~15 ~55 furnace 2  
setblock ~43 ~15 ~59 furnace 2  
setblock ~48 ~13 ~54 furnace 2  
setblock ~40 ~13 ~62 furnace 2  
setblock ~44 ~13 ~58 furnace 2  
setblock ~40 ~11 ~61 furnace 2  
setblock ~48 ~11 ~53 furnace 2  
setblock ~44 ~11 ~57 furnace 2  
setblock ~41 ~9 ~60 furnace 2  
setblock ~49 ~9 ~52 furnace 2  
setblock ~45 ~9 ~56 furnace 2  
setblock ~43 ~7 ~59 furnace 2  
setblock ~47 ~7 ~55 furnace 2  
setblock ~48 ~5 ~54 furnace 2  
setblock ~47 ~16 ~55 furnace 2  
setblock ~44 ~16 ~59 furnace 2  
setblock ~48 ~14 ~54 furnace 2  
setblock ~40 ~14 ~62 furnace 2  
setblock ~44 ~14 ~58 furnace 2  
setblock ~40 ~12 ~61 furnace 2  
setblock ~48 ~12 ~53 furnace 2  
setblock ~44 ~12 ~57 furnace 2  
setblock ~41 ~10 ~60 furnace 2  
setblock ~49 ~10 ~52 furnace 2  
setblock ~45 ~10 ~56 furnace 2  
setblock ~43 ~8 ~59 furnace 2  
setblock ~47 ~8 ~55 furnace 2  
setblock ~40 ~6 ~62 furnace 2  
setblock ~48 ~6 ~54 furnace 2  
setblock ~44 ~6 ~58 furnace 2  
setblock ~39 ~15 ~64 furnace 2  
setblock ~38 ~15 ~65 furnace 2  
setblock ~37 ~15 ~66 furnace 2  
setblock ~36 ~15 ~67 furnace 2  
setblock ~35 ~15 ~68 furnace 2  
setblock ~38 ~13 ~64 furnace 2  
setblock ~37 ~13 ~65 furnace 2  
setblock ~36 ~13 ~66 furnace 2  
setblock ~35 ~13 ~67 furnace 2  
setblock ~39 ~13 ~63 furnace 2  
setblock ~38 ~11 ~63 furnace 2  
setblock ~36 ~11 ~65 furnace 2  
setblock ~35 ~11 ~66 furnace 2  
setblock ~37 ~11 ~64 furnace 2  
setblock ~37 ~9 ~64 furnace 2  
setblock ~35 ~9 ~66 furnace 2  
setblock ~36 ~9 ~65 furnace 2  
setblock ~38 ~9 ~63 furnace 2  
setblock ~35 ~7 ~67 furnace 2  
setblock ~37 ~7 ~65 furnace 2  
setblock ~39 ~7 ~63 furnace 2  
setblock ~36 ~7 ~66 furnace 2  
setblock ~38 ~7 ~64 furnace 2  
setblock ~38 ~14 ~64 furnace 2  
setblock ~37 ~14 ~65 furnace 2  
setblock ~36 ~14 ~66 furnace 2  
setblock ~35 ~14 ~67 furnace 2  
setblock ~39 ~14 ~63 furnace 2  
setblock ~38 ~12 ~63 furnace 2  
setblock ~36 ~12 ~65 furnace 2  
setblock ~37 ~12 ~64 furnace 2  
setblock ~35 ~12 ~66 furnace 2  
setblock ~37 ~10 ~64 furnace 2  
setblock ~35 ~10 ~66 furnace 2  
setblock ~38 ~10 ~63 furnace 2  
setblock ~36 ~10 ~65 furnace 2  
setblock ~35 ~8 ~67 furnace 2  
setblock ~37 ~8 ~65 furnace 2  
setblock ~39 ~8 ~63 furnace 2  
setblock ~36 ~8 ~66 furnace 2  
setblock ~38 ~8 ~64 furnace 2  
setblock ~63 ~5 ~9 furnace 3  
setblock ~62 ~5 ~9 furnace 3  
setblock ~61 ~5 ~9 furnace 3  
setblock ~60 ~5 ~9 furnace 3  
setblock ~59 ~5 ~9 furnace 3  
setblock ~66 ~15 ~10 furnace 3  
setblock ~65 ~15 ~10 furnace 3  
setblock ~64 ~15 ~10 furnace 3  
setblock ~66 ~17 ~9 furnace 3  
setblock ~65 ~17 ~9 furnace 3  
setblock ~64 ~17 ~9 furnace 3  
setblock ~52 ~7 ~8 furnace 3  
setblock ~51 ~7 ~8 furnace 3  
setblock ~52 ~9 ~9 furnace 3  
setblock ~51 ~9 ~9 furnace 3  
setblock ~58 ~15 ~8 furnace 3  
setblock ~57 ~15 ~8 furnace 3  
setblock ~56 ~15 ~8 furnace 3  
setblock ~58 ~17 ~7 furnace 3  
setblock ~55 ~15 ~8 furnace 3  
setblock ~57 ~17 ~7 furnace 3  
setblock ~54 ~15 ~8 furnace 3  
setblock ~56 ~17 ~7 furnace 3  
setblock ~53 ~15 ~8 furnace 3  
setblock ~55 ~17 ~7 furnace 3  
setblock ~52 ~15 ~8 furnace 3  
setblock ~54 ~17 ~7 furnace 3  
setblock ~51 ~15 ~8 furnace 3  
setblock ~53 ~17 ~7 furnace 3  
setblock ~52 ~17 ~7 furnace 3  
setblock ~51 ~17 ~7 furnace 3  
setblock ~66 ~4 ~9 furnace 3  
setblock ~66 ~6 ~10 furnace 3  
setblock ~65 ~4 ~9 furnace 3  
setblock ~65 ~6 ~10 furnace 3  
setblock ~64 ~4 ~9 furnace 3  
setblock ~64 ~6 ~10 furnace 3  
setblock ~58 ~6 ~8 furnace 3  
setblock ~57 ~6 ~8 furnace 3  
setblock ~56 ~6 ~8 furnace 3  
setblock ~55 ~6 ~8 furnace 3  
setblock ~54 ~6 ~8 furnace 3  
setblock ~53 ~6 ~8 furnace 3  
setblock ~62 ~16 ~9 furnace 3  
setblock ~52 ~6 ~8 furnace 3  
setblock ~51 ~6 ~8 furnace 3  
setblock ~60 ~16 ~9 furnace 3  
setblock ~51 ~12 ~9 furnace 3  
setblock ~52 ~14 ~8 furnace 3  
setblock ~51 ~14 ~8 furnace 3  
setblock ~66 ~5 ~10 furnace 3  
setblock ~65 ~5 ~10 furnace 3  
setblock ~64 ~5 ~10 furnace 3  
setblock ~58 ~5 ~8 furnace 3  
setblock ~57 ~5 ~8 furnace 3  
setblock ~56 ~5 ~8 furnace 3  
setblock ~55 ~5 ~8 furnace 3  
setblock ~54 ~5 ~8 furnace 3  
setblock ~53 ~5 ~8 furnace 3  
setblock ~62 ~15 ~9 furnace 3  
setblock ~52 ~5 ~8 furnace 3  
setblock ~63 ~17 ~8 furnace 3  
setblock ~51 ~5 ~8 furnace 3  
setblock ~60 ~15 ~9 furnace 3  
setblock ~62 ~17 ~8 furnace 3  
setblock ~61 ~17 ~8 furnace 3  
setblock ~60 ~17 ~8 furnace 3  
setblock ~52 ~11 ~9 furnace 3  
setblock ~59 ~17 ~8 furnace 3  
setblock ~51 ~11 ~9 furnace 3  
setblock ~52 ~13 ~8 furnace 3  
setblock ~51 ~13 ~8 furnace 3  
setblock ~63 ~6 ~9 furnace 3  
setblock ~62 ~6 ~9 furnace 3  
setblock ~61 ~6 ~9 furnace 3  
setblock ~60 ~6 ~9 furnace 3  
setblock ~59 ~6 ~9 furnace 3  
setblock ~52 ~8 ~8 furnace 3  
setblock ~51 ~8 ~8 furnace 3  
setblock ~52 ~10 ~9 furnace 3  
setblock ~51 ~10 ~9 furnace 3  
setblock ~58 ~16 ~8 furnace 3  
setblock ~57 ~16 ~8 furnace 3  
setblock ~56 ~16 ~8 furnace 3  
setblock ~55 ~16 ~8 furnace 3  
setblock ~54 ~16 ~8 furnace 3  
setblock ~53 ~16 ~8 furnace 3  
setblock ~52 ~16 ~8 furnace 3  
setblock ~51 ~16 ~8 furnace 3  
setblock ~52 ~11 ~28 chest 3  
setblock ~52 ~12 ~28 chest 3  
setblock ~51 ~7 ~31 furnace 5  
setblock ~51 ~6 ~31 furnace 5  
setblock ~51 ~12 ~50 furnace 2  
setblock ~59 ~17 ~51 furnace 2  
setblock ~60 ~17 ~51 furnace 2  
setblock ~60 ~16 ~50 furnace 2  
setblock ~61 ~17 ~51 furnace 2  
setblock ~60 ~15 ~50 furnace 2  
setblock ~62 ~17 ~51 furnace 2  
setblock ~62 ~16 ~50 furnace 2  
setblock ~64 ~17 ~50 furnace 2  
setblock ~63 ~17 ~51 furnace 2  
setblock ~62 ~15 ~50 furnace 2  
setblock ~64 ~16 ~49 furnace 2  
setblock ~65 ~17 ~50 furnace 2  
setblock ~64 ~15 ~49 furnace 2  
setblock ~65 ~16 ~49 furnace 2  
setblock ~66 ~17 ~50 furnace 2  
setblock ~65 ~15 ~49 furnace 2  
setblock ~66 ~16 ~49 furnace 2  
setblock ~66 ~15 ~49 furnace 2  
setblock ~76 ~11 ~8 furnace 3  
setblock ~70 ~9 ~11 furnace 3  
setblock ~80 ~13 ~5 furnace 3  
setblock ~79 ~13 ~5 furnace 3  
setblock ~74 ~13 ~9 furnace 3  
setblock ~73 ~13 ~9 furnace 3  
setblock ~77 ~15 ~6 furnace 3  
setblock ~72 ~15 ~10 furnace 3  
setblock ~76 ~15 ~6 furnace 3  
setblock ~69 ~15 ~10 furnace 3  
setblock ~68 ~15 ~10 furnace 3  
setblock ~67 ~15 ~10 furnace 3  
setblock ~78 ~6 ~6 furnace 3  
setblock ~77 ~6 ~6 furnace 3  
setblock ~72 ~6 ~10 furnace 3  
setblock ~76 ~6 ~6 furnace 3  
setblock ~77 ~8 ~7 furnace 3  
setblock ~76 ~8 ~7 furnace 3  
setblock ~77 ~10 ~8 furnace 3  
setblock ~71 ~8 ~11 furnace 3  
setblock ~69 ~4 ~9 furnace 3  
setblock ~81 ~12 ~5 furnace 3  
setblock ~76 ~10 ~8 furnace 3  
setblock ~70 ~8 ~11 furnace 3  
setblock ~69 ~6 ~10 furnace 3  
setblock ~68 ~4 ~9 furnace 3  
setblock ~68 ~6 ~10 furnace 3  
setblock ~67 ~4 ~9 furnace 3  
setblock ~75 ~12 ~9 furnace 3  
setblock ~67 ~6 ~10 furnace 3  
setblock ~78 ~14 ~6 furnace 3  
setblock ~72 ~14 ~10 furnace 3  
setblock ~72 ~5 ~10 furnace 3  
setblock ~77 ~7 ~7 furnace 3  
setblock ~76 ~7 ~7 furnace 3  
setblock ~77 ~9 ~8 furnace 3  
setblock ~71 ~7 ~11 furnace 3  
setblock ~81 ~11 ~5 furnace 3  
setblock ~76 ~9 ~8 furnace 3  
setblock ~70 ~7 ~11 furnace 3  
setblock ~69 ~5 ~10 furnace 3  
setblock ~68 ~5 ~10 furnace 3  
setblock ~75 ~11 ~9 furnace 3  
setblock ~67 ~5 ~10 furnace 3  
setblock ~82 ~13 ~2 furnace 3  
setblock ~78 ~13 ~6 furnace 3  
setblock ~72 ~13 ~10 furnace 3  
setblock ~71 ~15 ~11 furnace 3  
setblock ~70 ~15 ~11 furnace 3  
setblock ~72 ~4 ~10 furnace 3  
setblock ~71 ~4 ~10 furnace 3  
setblock ~81 ~8 ~4 furnace 3  
setblock ~71 ~6 ~11 furnace 3  
setblock ~70 ~4 ~10 furnace 3  
setblock ~81 ~10 ~5 furnace 3  
setblock ~70 ~6 ~11 furnace 3  
setblock ~75 ~8 ~8 furnace 3  
setblock ~80 ~12 ~6 furnace 3  
setblock ~79 ~12 ~6 furnace 3  
setblock ~74 ~12 ~10 furnace 3  
setblock ~73 ~12 ~10 furnace 3  
setblock ~77 ~14 ~7 furnace 3  
setblock ~76 ~14 ~7 furnace 3  
setblock ~71 ~14 ~11 furnace 3  
setblock ~70 ~14 ~11 furnace 3  
setblock ~74 ~16 ~8 furnace 3  
setblock ~73 ~16 ~8 furnace 3  
setblock ~81 ~7 ~4 furnace 3  
setblock ~71 ~5 ~11 furnace 3  
setblock ~81 ~9 ~5 furnace 3  
setblock ~80 ~7 ~4 furnace 3  
setblock ~70 ~5 ~11 furnace 3  
setblock ~75 ~7 ~8 furnace 3  
setblock ~79 ~7 ~4 furnace 3  
setblock ~75 ~9 ~9 furnace 3  
setblock ~80 ~11 ~6 furnace 3  
setblock ~79 ~11 ~6 furnace 3  
setblock ~73 ~11 ~10 furnace 3  
setblock ~77 ~13 ~7 furnace 3  
setblock ~76 ~13 ~7 furnace 3  
setblock ~71 ~13 ~11 furnace 3  
setblock ~70 ~13 ~11 furnace 3  
setblock ~75 ~15 ~8 furnace 3  
setblock ~69 ~17 ~9 furnace 3  
setblock ~68 ~17 ~9 furnace 3  
setblock ~67 ~17 ~9 furnace 3  
setblock ~75 ~6 ~8 furnace 3  
setblock ~80 ~8 ~5 furnace 3  
setblock ~80 ~10 ~6 furnace 3  
setblock ~79 ~8 ~5 furnace 3  
setblock ~74 ~8 ~9 furnace 3  
setblock ~79 ~10 ~6 furnace 3  
setblock ~73 ~8 ~9 furnace 3  
setblock ~82 ~12 ~3 furnace 3  
setblock ~78 ~12 ~7 furnace 3  
setblock ~72 ~12 ~11 furnace 3  
setblock ~80 ~14 ~4 furnace 3  
setblock ~75 ~14 ~8 furnace 3  
setblock ~79 ~14 ~4 furnace 3  
setblock ~75 ~5 ~8 furnace 3  
setblock ~74 ~5 ~8 furnace 3  
setblock ~80 ~9 ~6 furnace 3  
setblock ~74 ~7 ~9 furnace 3  
setblock ~79 ~9 ~6 furnace 3  
setblock ~73 ~7 ~9 furnace 3  
setblock ~73 ~9 ~10 furnace 3  
setblock ~78 ~11 ~7 furnace 3  
setblock ~72 ~11 ~11 furnace 3  
setblock ~81 ~13 ~4 furnace 3  
setblock ~70 ~11 ~11 furnace 3  
setblock ~75 ~13 ~8 furnace 3  
setblock ~74 ~15 ~9 furnace 3  
setblock ~73 ~15 ~9 furnace 3  
setblock ~74 ~6 ~9 furnace 3  
setblock ~73 ~6 ~9 furnace 3  
setblock ~82 ~8 ~2 furnace 3  
setblock ~78 ~8 ~6 furnace 3  
setblock ~78 ~10 ~7 furnace 3  
setblock ~72 ~8 ~10 furnace 3  
setblock ~77 ~12 ~8 furnace 3  
setblock ~76 ~12 ~8 furnace 3  
setblock ~70 ~10 ~11 furnace 3  
setblock ~71 ~12 ~12 furnace 3  
setblock ~74 ~14 ~9 furnace 3  
setblock ~73 ~14 ~9 furnace 3  
setblock ~72 ~16 ~10 furnace 3  
setblock ~73 ~5 ~9 furnace 3  
setblock ~78 ~7 ~6 furnace 3  
setblock ~82 ~9 ~3 furnace 3  
setblock ~78 ~9 ~7 furnace 3  
setblock ~72 ~7 ~10 furnace 3  
setblock ~72 ~9 ~11 furnace 3  
setblock ~77 ~11 ~8 furnace 3  
setblock ~82 ~16 ~19 furnace 5  
setblock ~82 ~9 ~28 chest 3  
setblock ~80 ~9 ~28 chest 3  
setblock ~78 ~9 ~28 chest 3  
setblock ~76 ~9 ~28 chest 3  
setblock ~82 ~16 ~40 furnace 5  
setblock ~76 ~9 ~31 chest 2  
setblock ~78 ~9 ~31 chest 2  
setblock ~80 ~9 ~31 chest 2  
setblock ~82 ~9 ~31 chest 2  
setblock ~71 ~12 ~47 furnace 2  
setblock ~71 ~10 ~47 furnace 2  
setblock ~78 ~10 ~52 furnace 2  
setblock ~81 ~12 ~54 furnace 2  
setblock ~81 ~13 ~55 furnace 2  
setblock ~81 ~11 ~54 furnace 2  
setblock ~81 ~10 ~54 furnace 2  
setblock ~81 ~9 ~54 furnace 2  
setblock ~82 ~12 ~56 furnace 2  
setblock ~82 ~13 ~57 furnace 2  
setblock ~82 ~9 ~56 furnace 2  
setblock ~82 ~8 ~57 furnace 2  
setblock ~67 ~17 ~50 furnace 2  
setblock ~67 ~16 ~49 furnace 2  
setblock ~68 ~17 ~50 furnace 2  
setblock ~67 ~15 ~49 furnace 2  
setblock ~68 ~16 ~49 furnace 2  
setblock ~69 ~17 ~50 furnace 2  
setblock ~68 ~15 ~49 furnace 2  
setblock ~69 ~16 ~49 furnace 2  
setblock ~69 ~15 ~49 furnace 2  
setblock ~98 ~8 ~7 furnace 3  
setblock ~91 ~10 ~12 chest 5  
setblock ~88 ~10 ~12 chest 2  
setblock ~91 ~10 ~8 chest 5  
setblock ~87 ~10 ~12 chest 2  
setblock ~93 ~12 ~5 furnace 3  
setblock ~92 ~12 ~5 furnace 3  
setblock ~89 ~8 ~3 furnace 3  
setblock ~91 ~12 ~5 furnace 3  
setblock ~86 ~10 ~8 hopper 4  
setblock ~88 ~8 ~3 furnace 3  
setblock ~89 ~10 ~4 furnace 3  
setblock ~90 ~12 ~5 furnace 3  
setblock ~85 ~10 ~8 chest 4  
setblock ~88 ~10 ~4 furnace 3  
setblock ~87 ~8 ~3 furnace 3  
setblock ~87 ~10 ~4 furnace 3  
setblock ~86 ~8 ~3 furnace 3  
setblock ~86 ~10 ~4 furnace 3  
setblock ~93 ~11 ~5 furnace 3  
setblock ~89 ~9 ~4 furnace 3  
setblock ~90 ~11 ~5 furnace 3  
setblock ~88 ~9 ~4 furnace 3  
setblock ~87 ~9 ~4 furnace 3  
setblock ~86 ~9 ~4 furnace 3  
setblock ~85 ~13 ~2 furnace 3  
setblock ~84 ~13 ~2 furnace 3  
setblock ~83 ~13 ~2 furnace 3  
setblock ~91 ~10 ~13 trapped_chest 5  
setblock ~91 ~10 ~9 trapped_chest 5  
setblock ~96 ~12 ~6 furnace 3  
setblock ~93 ~8 ~4 furnace 3  
setblock ~94 ~12 ~6 furnace 3  
setblock ~92 ~8 ~4 furnace 3  
setblock ~93 ~10 ~5 furnace 3  
setblock ~91 ~8 ~4 furnace 3  
setblock ~90 ~8 ~4 furnace 3  
setblock ~90 ~10 ~5 furnace 3  
setblock ~97 ~11 ~6 furnace 3  
setblock ~93 ~9 ~5 furnace 3  
setblock ~92 ~9 ~5 furnace 3  
setblock ~91 ~9 ~5 furnace 3  
setblock ~90 ~9 ~5 furnace 3  
setblock ~89 ~13 ~3 furnace 3  
setblock ~88 ~13 ~3 furnace 3  
setblock ~87 ~13 ~3 furnace 3  
setblock ~86 ~13 ~3 furnace 3  
setblock ~91 ~10 ~14 trapped_chest 5  
setblock ~98 ~12 ~7 furnace 3  
setblock ~97 ~10 ~6 furnace 3  
setblock ~91 ~10 ~10 trapped_chest 5  
setblock ~85 ~12 ~3 furnace 3  
setblock ~93 ~13 ~4 furnace 3  
setblock ~92 ~13 ~4 furnace 3  
setblock ~91 ~13 ~4 furnace 3  
setblock ~90 ~13 ~4 furnace 3  
setblock ~94 ~8 ~6 furnace 3  
setblock ~91 ~10 ~11 chest 5  
setblock ~91 ~10 ~7 chest 5  
setblock ~86 ~10 ~7 chest 5  
setblock ~85 ~10 ~7 hopper 5  
setblock ~89 ~12 ~4 furnace 3  
setblock ~88 ~12 ~4 furnace 3  
setblock ~87 ~12 ~4 furnace 3  
setblock ~85 ~8 ~2 furnace 3  
setblock ~86 ~12 ~4 furnace 3  
setblock ~84 ~8 ~2 furnace 3  
setblock ~83 ~8 ~2 furnace 3  
setblock ~88 ~11 ~12 chest 2  
setblock ~89 ~11 ~4 furnace 3  
setblock ~88 ~11 ~4 furnace 3  
setblock ~87 ~11 ~4 furnace 3  
setblock ~86 ~11 ~4 furnace 3  
setblock ~85 ~9 ~3 furnace 3  
setblock ~92 ~6 ~18 command_block 5  
setblock ~92 ~6 ~16 command_block 5  
setblock ~92 ~10 ~18 command_block 1  
setblock ~92 ~10 ~16 command_block 2  
setblock ~83 ~16 ~19 furnace 5  
setblock ~96 ~17 ~30 furnace 4  
setblock ~97 ~17 ~28 furnace 2  
setblock ~96 ~17 ~28 furnace 4  
setblock ~84 ~2 ~29 hopper 3  
setblock ~97 ~18 ~29 furnace 5  
setblock ~96 ~18 ~29 furnace 4  
setblock ~89 ~17 ~27 furnace 4  
setblock ~90 ~17 ~25 furnace 2  
setblock ~89 ~17 ~25 furnace 4  
setblock ~83 ~16 ~40 furnace 5  
setblock ~92 ~10 ~41 command_block 1  
setblock ~92 ~10 ~43 command_block 1  
setblock ~91 ~10 ~46 chest 5  
setblock ~92 ~6 ~41 command_block 5  
setblock ~92 ~6 ~43 command_block 5  
setblock ~89 ~17 ~31 furnace 4  
setblock ~90 ~17 ~31 furnace 2  
setblock ~89 ~17 ~33 furnace 4  
setblock ~85 ~8 ~49 hopper 5  
setblock ~85 ~8 ~50 chest 4  
setblock ~86 ~8 ~49 chest 5  
setblock ~88 ~8 ~47 chest 3  
setblock ~86 ~8 ~50 hopper 4  
setblock ~89 ~8 ~47 chest 3  
setblock ~91 ~10 ~47 chest 5  
setblock ~85 ~12 ~56 furnace 2  
setblock ~86 ~12 ~55 furnace 2  
setblock ~87 ~12 ~55 furnace 2  
setblock ~86 ~10 ~55 furnace 2  
setblock ~88 ~12 ~55 furnace 2  
setblock ~83 ~8 ~57 furnace 2  
setblock ~87 ~10 ~55 furnace 2  
setblock ~89 ~12 ~55 furnace 2  
setblock ~84 ~8 ~57 furnace 2  
setblock ~88 ~10 ~55 furnace 2  
setblock ~85 ~8 ~57 furnace 2  
setblock ~86 ~8 ~56 furnace 2  
setblock ~89 ~10 ~55 furnace 2  
setblock ~87 ~8 ~56 furnace 2  
setblock ~88 ~8 ~56 furnace 2  
setblock ~89 ~8 ~56 furnace 2  
setblock ~88 ~9 ~47 chest 3  
setblock ~83 ~13 ~57 furnace 2  
setblock ~84 ~13 ~57 furnace 2  
setblock ~85 ~13 ~57 furnace 2  
setblock ~86 ~13 ~56 furnace 2  
setblock ~86 ~11 ~55 furnace 2  
setblock ~87 ~13 ~56 furnace 2  
setblock ~87 ~11 ~55 furnace 2  
setblock ~88 ~13 ~56 furnace 2  
setblock ~85 ~9 ~56 furnace 2  
setblock ~86 ~9 ~55 furnace 2  
setblock ~88 ~11 ~55 furnace 2  
setblock ~89 ~13 ~56 furnace 2  
setblock ~87 ~9 ~55 furnace 2  
setblock ~89 ~11 ~55 furnace 2  
setblock ~90 ~11 ~54 furnace 2  
setblock ~88 ~9 ~55 furnace 2  
setblock ~89 ~9 ~55 furnace 2  
setblock ~108 ~12 ~9 furnace 3  
setblock ~107 ~12 ~9 furnace 3  
setblock ~106 ~12 ~9 furnace 3  
setblock ~109 ~11 ~9 furnace 3  
setblock ~106 ~11 ~9 furnace 3  
setblock ~107 ~10 ~13 trapped_chest 5  
setblock ~112 ~12 ~10 furnace 3  
setblock ~109 ~8 ~8 furnace 3  
setblock ~110 ~12 ~10 furnace 3  
setblock ~108 ~8 ~8 furnace 3  
setblock ~109 ~10 ~9 furnace 3  
setblock ~107 ~8 ~8 furnace 3  
setblock ~106 ~8 ~8 furnace 3  
setblock ~106 ~10 ~9 furnace 3  
setblock ~102 ~8 ~8 furnace 3  
setblock ~113 ~11 ~10 furnace 3  
setblock ~109 ~9 ~9 furnace 3  
setblock ~108 ~9 ~9 furnace 3  
setblock ~107 ~9 ~9 furnace 3  
setblock ~106 ~9 ~9 furnace 3  
setblock ~114 ~12 ~11 furnace 3  
setblock ~113 ~10 ~10 furnace 3  
setblock ~107 ~10 ~14 trapped_chest 5  
setblock ~100 ~12 ~7 furnace 3  
setblock ~109 ~13 ~8 furnace 3  
setblock ~108 ~13 ~8 furnace 3  
setblock ~107 ~13 ~8 furnace 3  
setblock ~106 ~13 ~8 furnace 3  
setblock ~101 ~11 ~7 furnace 3  
setblock ~110 ~8 ~10 furnace 3  
setblock ~107 ~10 ~11 chest 5  
setblock ~104 ~12 ~8 furnace 3  
setblock ~101 ~10 ~7 furnace 3  
setblock ~102 ~12 ~8 furnace 3  
setblock ~114 ~8 ~11 furnace 3  
setblock ~107 ~10 ~12 chest 5  
setblock ~109 ~12 ~9 furnace 3  
setblock ~111 ~17 ~30 furnace 4  
setblock ~110 ~17 ~26 furnace 5  
setblock ~109 ~17 ~26 furnace 5  
setblock ~111 ~16 ~30 furnace 4  
setblock ~112 ~16 ~28 furnace 2  
setblock ~111 ~16 ~28 furnace 4  
setblock ~107 ~10 ~17 trapped_chest 5  
setblock ~107 ~10 ~15 chest 5  
setblock ~114 ~11 ~26 chest 3  
setblock ~113 ~11 ~26 chest 3  
setblock ~112 ~17 ~29 furnace 4  
setblock ~111 ~17 ~29 furnace 4  
setblock ~108 ~6 ~22 command_block 5  
setblock ~108 ~6 ~20 command_block 5  
setblock ~110 ~16 ~27 furnace 5  
setblock ~108 ~10 ~22 command_block 1  
setblock ~108 ~10 ~20 command_block 2  
setblock ~107 ~10 ~18 trapped_chest 5  
setblock ~107 ~10 ~16 chest 5  
setblock ~109 ~17 ~33 furnace 5  
setblock ~110 ~17 ~33 furnace 5  
setblock ~110 ~16 ~32 furnace 5  
setblock ~110 ~16 ~34 furnace 5  
setblock ~108 ~10 ~37 command_block 1  
setblock ~108 ~10 ~39 command_block 1  
setblock ~108 ~6 ~37 command_block 5  
setblock ~108 ~6 ~39 command_block 5  
setblock ~113 ~11 ~33 chest 2  
setblock ~114 ~11 ~33 chest 2  
setblock ~111 ~9 ~49 furnace 2  
setblock ~117 ~11 ~11 furnace 3  
setblock ~118 ~8 ~12 furnace 3  
setblock ~120 ~12 ~12 furnace 3  
setblock ~117 ~10 ~11 furnace 3  
setblock ~118 ~12 ~12 furnace 3  
setblock ~116 ~12 ~11 furnace 3  
setblock ~118 ~11 ~28 trapped_chest 4  
setblock ~118 ~11 ~27 trapped_chest 4  
setblock ~118 ~11 ~26 chest 3  
setblock ~117 ~11 ~26 chest 3  
setblock ~116 ~11 ~26 trapped_chest 3  
setblock ~115 ~11 ~26 trapped_chest 3  
setblock ~124 ~10 ~26 command_block 1  
setblock ~127 ~7 ~24 chest 3  
setblock ~116 ~11 ~33 trapped_chest 2  
setblock ~118 ~11 ~31 trapped_chest 4  
setblock ~117 ~11 ~33 chest 2  
setblock ~118 ~11 ~32 trapped_chest 4  
setblock ~118 ~11 ~33 chest 2  
setblock ~124 ~10 ~33 command_block 1  
setblock ~124 ~6 ~33 command_block 5  
setblock ~128 ~7 ~35 chest 2  
setblock ~115 ~11 ~33 trapped_chest 2  
setblock ~145 ~12 ~18 furnace 3  
setblock ~139 ~10 ~21 chest 5  
setblock ~144 ~12 ~18 furnace 3  
setblock ~141 ~10 ~19 chest 3  
setblock ~143 ~12 ~18 furnace 3  
setblock ~140 ~10 ~19 chest 3  
setblock ~139 ~10 ~19 trapped_chest 5  
setblock ~142 ~12 ~18 furnace 3  
setblock ~141 ~10 ~17 furnace 3  
setblock ~140 ~10 ~17 furnace 3  
setblock ~139 ~10 ~17 furnace 3  
setblock ~138 ~10 ~17 furnace 3  
setblock ~145 ~11 ~22 chest 5  
setblock ~141 ~11 ~22 chest 2  
setblock ~145 ~11 ~18 furnace 3  
setblock ~139 ~9 ~21 chest 5  
setblock ~144 ~11 ~18 furnace 3  
setblock ~141 ~9 ~19 chest 3  
setblock ~139 ~11 ~22 chest 5  
setblock ~143 ~11 ~18 furnace 3  
setblock ~140 ~9 ~19 chest 3  
setblock ~139 ~9 ~19 trapped_chest 5  
setblock ~142 ~11 ~18 furnace 3  
setblock ~141 ~9 ~17 furnace 3  
setblock ~139 ~11 ~20 trapped_chest 5  
setblock ~140 ~9 ~17 furnace 3  
setblock ~139 ~9 ~17 furnace 3  
setblock ~138 ~9 ~17 furnace 3  
setblock ~137 ~11 ~16 furnace 3  
setblock ~145 ~10 ~18 furnace 3  
setblock ~141 ~10 ~22 chest 2  
setblock ~144 ~10 ~18 furnace 3  
setblock ~139 ~10 ~22 chest 5  
setblock ~143 ~10 ~18 furnace 3  
setblock ~142 ~10 ~18 furnace 3  
setblock ~139 ~10 ~20 trapped_chest 5  
setblock ~141 ~12 ~17 furnace 3  
setblock ~140 ~12 ~17 furnace 3  
setblock ~139 ~12 ~17 furnace 3  
setblock ~137 ~10 ~16 furnace 3  
setblock ~138 ~12 ~17 furnace 3  
setblock ~145 ~11 ~23 chest 5  
setblock ~145 ~9 ~18 furnace 3  
setblock ~141 ~9 ~22 chest 2  
summon ArmorStand ~46.5 ~7.0 ~31.5 {  Rotation:[-180.0,0.0],Pose:{Head:[3.07628846169f,4.50973701477f,0.0f],Body:[0.0f,-4.0079460144f,0.0f]}}}
summon ArmorStand ~48.5 ~7.0 ~31.5 {  Rotation:[-180.0,0.0],Pose:{Head:[3.07628846169f,4.50973701477f,0.0f],Body:[0.0f,-4.0079460144f,0.0f]}}}
summon ArmorStand ~50.5 ~11.0 ~31.5 {  Rotation:[-180.0,0.0],Pose:{Head:[1.36432433128f,-0.21005821228f,0.0f],Body:[0.0f,3.08906555176f,0.0f]}}}
summon ArmorStand ~48.5 ~11.0 ~31.5 {  Rotation:[-180.0,0.0],Pose:{Head:[4.79443979263f,-2.42496395111f,0.0f],Body:[0.0f,-2.18516469002f,0.0f]}}}
summon ArmorStand ~46.5 ~11.0 ~31.5 {  Rotation:[-180.0,0.0],Pose:{Head:[2.52356529236f,-6.05063533783f,0.0f],Body:[0.0f,0.820303440094f,0.0f]}}}
summon ArmorStand ~52.5 ~11.0 ~31.5 {  Rotation:[180.0,0.0],Pose:{Head:[1.52614212036f,6.59328269958f,0.0f],Body:[0.0f,-4.22077465057f,0.0f]}}}
summon Chicken ~77.3244751169 ~13.0 ~25.7247003895 
summon Chicken ~77.825000003 ~13.0 ~25.7905423977 
summon Chicken ~79.7044859069 ~13.0 ~27.174999997 
summon Chicken ~82.5691853331 ~13.0 ~26.1515166431 
summon Chicken ~78.0693408969 ~13.0 ~25.2893227931 
summon Chicken ~77.825000003 ~13.0 ~27.174999997 
summon Chicken ~77.825000003 ~13.0 ~26.2518149276 
summon Chicken ~81.8080994584 ~13.0 ~26.1515824724 
summon Pig ~80.131980926 ~13.0 ~25.4499999881 
summon Chicken ~77.3776787804 ~13.0 ~25.200000003 
summon Chicken ~79.1732877098 ~13.0 ~27.174999997 
summon Pig ~77.4120200332 ~13.0 ~28.4499999881 
summon Pig ~78.982592385 ~13.0 ~26.0315773614 
summon Pig ~78.959400281 ~13.0 ~28.0749999881 
summon Chicken ~78.5030813422 ~13.0 ~25.200000003 
summon Chicken ~78.6612960894 ~13.0 ~27.174999997 
summon Pig ~79.9238768248 ~13.0 ~28.4209369037 
summon Pig ~80.9833403457 ~13.0 ~28.0749999881 
summon Chicken ~78.3487886278 ~13.0 ~26.7475824323 
summon Chicken ~80.2443986254 ~13.0 ~29.7058288729 
summon Chicken ~79.3898217126 ~13.0 ~30.1362534249 
summon Cow ~80.9426212529 ~13.0 ~29.1022127805 
summon Chicken ~79.2455810104 ~13.0 ~28.7282905651 
summon Chicken ~81.4987941969 ~13.0 ~25.200000003 
summon Chicken ~78.7689024314 ~13.0 ~28.9558426814 
summon Pig ~81.9546596619 ~13.0 ~28.9050707867 
summon Chicken ~79.1849874576 ~13.0 ~25.200000003 
summon Item ~78.7516855344 ~13.0 ~26.379852403 
summon Pig ~80.1405847855 ~13.0 ~30.3911407088 
summon Item ~77.9732165891 ~13.0 ~27.25 
summon Item ~82.3240089508 ~13.0 ~26.4515738242 
summon Item ~79.4447239816 ~13.0 ~30.5759248038 
summon Item ~76.125 ~13.0 ~30.3411077111 
summon Cow ~76.5006160481 ~13.0 ~28.962592649 
summon Item ~78.5362348787 ~13.0 ~25.125 
summon Cow ~76.4993247335 ~13.0 ~29.9512620188 
summon Pig ~82.9676474425 ~13.0 ~30.8253830432 
summon Pig ~81.6879548015 ~13.0 ~30.7816906473 
summon Cow ~78.0749999881 ~13.0 ~33.5909530336 
summon Pig ~78.0749999881 ~13.0 ~34.5500000119 
summon Pig ~78.1750000119 ~13.0 ~32.6492957186 
summon Cow ~79.0969298568 ~13.0 ~34.1868978353 
summon Pig ~79.7349914795 ~13.0 ~33.0749999881 
summon Chicken ~77.825000003 ~13.0 ~31.8855572136 
summon Cow ~81.8116953938 ~13.0 ~33.0749999881 
summon Cow ~82.5386251769 ~13.0 ~31.7957857484 
summon Item ~82.8303653353 ~13.0 ~32.25 
summon Item ~77.75 ~13.0 ~31.0557361725 
summon Pig ~78.0749999881 ~13.0 ~31.1174328119 
summon Pig ~79.0569242448 ~13.0 ~31.4611635049 
summon Chicken ~84.799999997 ~13.0 ~25.4620362427 
summon Chicken ~84.5294183889 ~13.0 ~25.8702628908 
summon Pig ~84.5483969173 ~13.0 ~28.0749999881 
summon Chicken ~83.9866393715 ~13.0 ~27.174999997 
summon Chicken ~84.3118734018 ~13.0 ~26.2990221729 
summon Pig ~84.5500000119 ~13.0 ~29.0174002618 
summon Chicken ~84.799999997 ~13.0 ~27.174999997 
summon Chicken ~84.5730760102 ~13.0 ~26.7199675042 
summon Chicken ~83.7962786992 ~13.0 ~25.2332771636 
summon Chicken ~83.3113901772 ~13.0 ~26.356836196 
summon Chicken ~83.7788999986 ~13.0 ~26.6760261246 
summon Item ~83.7578780297 ~13.0 ~25.8761673097 
summon Item ~84.2168337529 ~13.0 ~25.125 
summon Item ~84.6019517921 ~13.0 ~26.5719047965 
summon Cow ~84.5500000119 ~13.0 ~34.5006999366 
summon Cow ~84.5500000119 ~13.0 ~33.5279280012 
summon Chicken ~84.799999997 ~13.0 ~32.174999997 
summon Pig ~83.9031455288 ~13.0 ~31.2099724111 
summon Cow ~83.5863758839 ~13.0 ~34.4980497864  
setblock ~144 ~9 ~18 furnace 3  
setblock ~139 ~9 ~22 chest 5  
setblock ~143 ~9 ~18 furnace 3  
setblock ~142 ~9 ~18 furnace 3  
setblock ~139 ~9 ~20 trapped_chest 5  
setblock ~139 ~11 ~21 chest 5  
setblock ~141 ~11 ~19 chest 3  
setblock ~140 ~11 ~19 chest 3  
setblock ~139 ~11 ~19 trapped_chest 5  
setblock ~141 ~11 ~17 furnace 3  
setblock ~140 ~11 ~17 furnace 3  
setblock ~139 ~11 ~17 furnace 3  
setblock ~138 ~11 ~17 furnace 3  
setblock ~140 ~10 ~40 chest 2  
setblock ~141 ~10 ~40 chest 2  
setblock ~139 ~10 ~42 furnace 2  
setblock ~139 ~11 ~37 chest 5  
setblock ~139 ~11 ~38 chest 5  
setblock ~139 ~11 ~39 trapped_chest 5  
setblock ~139 ~9 ~37 chest 5  
setblock ~139 ~11 ~40 trapped_chest 5  
setblock ~139 ~9 ~38 chest 5  
setblock ~140 ~11 ~40 chest 2  
setblock ~139 ~9 ~39 trapped_chest 5  
setblock ~141 ~11 ~40 chest 2  
setblock ~139 ~9 ~40 trapped_chest 5  
setblock ~139 ~11 ~42 furnace 2  
setblock ~140 ~9 ~40 chest 2  
setblock ~141 ~9 ~40 chest 2  
setblock ~139 ~10 ~37 chest 5  
setblock ~139 ~10 ~38 chest 5  
setblock ~139 ~10 ~39 trapped_chest 5  
setblock ~139 ~10 ~40 trapped_chest 5  
setblock ~165 ~11 ~23 furnace 3  
setblock ~163 ~12 ~36 furnace 2  
setblock ~164 ~12 ~36 furnace 3  
setblock ~165 ~12 ~36 furnace 3  
setblock ~165 ~10 ~36 furnace 3  
setblock ~164 ~11 ~36 furnace 3  
setblock ~165 ~11 ~36 furnace 3  
setblock ~165 ~9 ~36 furnace 3 
setblock ~9 ~0 ~21 stonebrick 0  
fill ~9 ~0 ~22 ~9 ~0 ~23 stone 6 
setblock ~9 ~0 ~24 stonebrick 0 
setblock ~9 ~0 ~35 stonebrick 0  
fill ~9 ~0 ~36 ~9 ~0 ~37 stone 6 
setblock ~9 ~0 ~38 stonebrick 0  
fill ~10 ~0 ~22 ~19 ~0 ~22 cobblestone 0  
fill ~10 ~0 ~23 ~19 ~0 ~23 cobblestone 0  
fill ~10 ~0 ~24 ~20 ~0 ~24 stone 6  
fill ~10 ~0 ~35 ~20 ~0 ~35 stone 6  
fill ~10 ~0 ~36 ~19 ~0 ~36 cobblestone 0  
fill ~10 ~0 ~37 ~19 ~0 ~37 cobblestone 0  
fill ~23 ~0 ~20 ~23 ~0 ~23 stone 4  
fill ~23 ~0 ~36 ~23 ~0 ~39 stone 4  
fill ~86 ~0 ~29 ~86 ~0 ~30 stone_stairs 4  
fill ~87 ~0 ~29 ~87 ~0 ~30 glass 0 
setblock ~10 ~1 ~17 stonebrick 0  
fill ~10 ~1 ~18 ~10 ~1 ~20 stone 6  
fill ~10 ~1 ~21 ~19 ~1 ~21 stonebrick 0  
fill ~10 ~1 ~24 ~19 ~1 ~24 stonebrick 0  
fill ~10 ~1 ~35 ~19 ~1 ~35 stonebrick 0  
fill ~10 ~1 ~38 ~19 ~1 ~38 stonebrick 0  
fill ~10 ~1 ~39 ~10 ~1 ~41 stone 6 
setblock ~10 ~1 ~42 stonebrick 0  
fill ~11 ~1 ~18 ~19 ~1 ~18 cobblestone 0  
fill ~11 ~1 ~19 ~19 ~1 ~19 cobblestone 0  
fill ~11 ~1 ~20 ~19 ~1 ~20 cobblestone 0  
fill ~11 ~1 ~39 ~19 ~1 ~39 cobblestone 0  
fill ~11 ~1 ~40 ~19 ~1 ~40 cobblestone 0  
fill ~11 ~1 ~41 ~19 ~1 ~41 cobblestone 0  
fill ~20 ~1 ~22 ~20 ~13 ~22 stone 6  
fill ~20 ~1 ~23 ~20 ~13 ~23 stone 6  
fill ~20 ~1 ~24 ~34 ~1 ~24 stone 6  
fill ~20 ~1 ~35 ~34 ~1 ~35 stone 6  
fill ~20 ~1 ~36 ~20 ~13 ~36 stone 6  
fill ~20 ~1 ~37 ~20 ~13 ~37 stone 6  
fill ~23 ~1 ~16 ~23 ~1 ~19 stone 4  
fill ~23 ~1 ~40 ~23 ~1 ~43 stone 4  
fill ~84 ~1 ~29 ~84 ~1 ~30 stone_slab 11 
setblock ~85 ~1 ~28 stone_slab 11 
setblock ~85 ~1 ~29 glass 0 
setblock ~85 ~1 ~30 stone_slab 3 
setblock ~85 ~1 ~31 stone_slab 11  
fill ~86 ~1 ~28 ~87 ~1 ~28 glass 0  
fill ~86 ~1 ~31 ~87 ~1 ~31 glass 0  
fill ~88 ~1 ~29 ~88 ~2 ~29 glass 0  
fill ~88 ~1 ~30 ~88 ~2 ~30 glass 0  
fill ~-14 ~2 ~20 ~-11 ~2 ~20 stone_slab 8  
fill ~-14 ~2 ~39 ~-11 ~2 ~39 stone_slab 8  
fill ~-10 ~2 ~19 ~-6 ~2 ~19 coal_block 0  
fill ~-10 ~2 ~20 ~-6 ~2 ~20 coal_block 0  
fill ~-10 ~2 ~21 ~-6 ~2 ~21 coal_block 0  
fill ~-10 ~2 ~38 ~-6 ~2 ~38 coal_block 0  
fill ~-10 ~2 ~39 ~-6 ~2 ~39 coal_block 0  
fill ~-10 ~2 ~40 ~-6 ~2 ~40 coal_block 0  
fill ~-7 ~2 ~17 ~-7 ~2 ~18 cobblestone_wall 0  
fill ~-7 ~2 ~22 ~-7 ~2 ~23 cobblestone_wall 0  
fill ~-7 ~2 ~36 ~-7 ~2 ~37 cobblestone_wall 0  
fill ~-7 ~2 ~41 ~-7 ~2 ~42 cobblestone_wall 0 
setblock ~-5 ~2 ~20 nether_brick_stairs 5 
setblock ~-5 ~2 ~39 nether_brick_stairs 5 
setblock ~-4 ~2 ~20 stone_slab 14 
setblock ~-4 ~2 ~39 stone_slab 14  
fill ~-3 ~2 ~20 ~0 ~2 ~20 iron_block 0  
fill ~-3 ~2 ~39 ~0 ~2 ~39 iron_block 0 
setblock ~1 ~2 ~20 stone_stairs 5 
setblock ~1 ~2 ~39 stone_stairs 5  
fill ~11 ~2 ~13 ~19 ~2 ~13 stonebrick 0  
fill ~11 ~2 ~14 ~11 ~2 ~16 stone 6  
fill ~11 ~2 ~17 ~19 ~2 ~17 stonebrick 0  
fill ~11 ~2 ~42 ~19 ~2 ~42 stonebrick 0  
fill ~11 ~2 ~43 ~11 ~2 ~45 stone 6  
fill ~11 ~2 ~46 ~19 ~2 ~46 stonebrick 0 
setblock ~12 ~2 ~9 stonebrick 0  
fill ~12 ~2 ~10 ~12 ~2 ~12 stone 6  
fill ~12 ~2 ~14 ~19 ~2 ~14 cobblestone 0  
fill ~12 ~2 ~15 ~19 ~2 ~15 cobblestone 0  
fill ~12 ~2 ~16 ~19 ~2 ~16 cobblestone 0  
fill ~12 ~2 ~25 ~34 ~2 ~25 stone 6  
fill ~12 ~2 ~26 ~34 ~2 ~26 stone 6  
fill ~12 ~2 ~27 ~34 ~2 ~27 stone 6  
fill ~12 ~2 ~32 ~34 ~2 ~32 stone 6  
fill ~12 ~2 ~33 ~34 ~2 ~33 stone 6  
fill ~12 ~2 ~34 ~34 ~2 ~34 stone 6  
fill ~12 ~2 ~43 ~19 ~2 ~43 cobblestone 0  
fill ~12 ~2 ~44 ~19 ~2 ~44 cobblestone 0  
fill ~12 ~2 ~45 ~19 ~2 ~45 cobblestone 0  
fill ~12 ~2 ~47 ~12 ~2 ~49 stone 6 
setblock ~12 ~2 ~50 stonebrick 0  
fill ~13 ~2 ~10 ~19 ~2 ~10 cobblestone 0  
fill ~13 ~2 ~11 ~19 ~2 ~11 cobblestone 0  
fill ~13 ~2 ~12 ~19 ~2 ~12 cobblestone 0  
fill ~13 ~2 ~47 ~19 ~2 ~47 cobblestone 0  
fill ~13 ~2 ~48 ~19 ~2 ~48 cobblestone 0  
fill ~13 ~2 ~49 ~19 ~2 ~49 cobblestone 0  
fill ~18 ~2 ~28 ~34 ~2 ~28 stone 6  
fill ~18 ~2 ~29 ~34 ~2 ~29 stone 6  
fill ~18 ~2 ~30 ~34 ~2 ~30 stone 6  
fill ~18 ~2 ~31 ~34 ~2 ~31 stone 6  
fill ~20 ~2 ~18 ~20 ~23 ~18 stone 6  
fill ~20 ~2 ~19 ~20 ~23 ~19 stone 6  
fill ~20 ~2 ~20 ~20 ~14 ~20 stone 6  
fill ~20 ~2 ~21 ~20 ~13 ~21 stone 6  
fill ~20 ~2 ~24 ~20 ~13 ~24 stone 6  
fill ~20 ~2 ~35 ~20 ~13 ~35 stone 6  
fill ~20 ~2 ~38 ~20 ~13 ~38 stone 6  
fill ~20 ~2 ~39 ~20 ~14 ~39 stone 6  
fill ~20 ~2 ~40 ~20 ~23 ~40 stone 6  
fill ~20 ~2 ~41 ~20 ~23 ~41 stone 6  
fill ~23 ~2 ~12 ~23 ~2 ~15 stone 4  
fill ~23 ~2 ~44 ~23 ~2 ~47 stone 4  
fill ~35 ~2 ~24 ~48 ~2 ~24 stone 6  
fill ~35 ~2 ~35 ~48 ~2 ~35 stone 6  
fill ~63 ~2 ~23 ~74 ~2 ~23 stone 6  
fill ~63 ~2 ~36 ~74 ~2 ~36 stone 6  
fill ~64 ~2 ~12 ~69 ~2 ~12 stone_slab 8  
fill ~64 ~2 ~13 ~72 ~2 ~13 stone 6  
fill ~64 ~2 ~14 ~72 ~2 ~14 stone 6  
fill ~64 ~2 ~15 ~74 ~2 ~15 stone 6  
fill ~64 ~2 ~16 ~74 ~2 ~16 stone 6  
fill ~64 ~2 ~17 ~74 ~2 ~17 stone 6  
fill ~64 ~2 ~18 ~74 ~2 ~18 stone 6  
fill ~64 ~2 ~19 ~74 ~2 ~19 stone 6  
fill ~64 ~2 ~20 ~74 ~2 ~20 stone 6  
fill ~64 ~2 ~21 ~74 ~2 ~21 stone 6  
fill ~64 ~2 ~22 ~74 ~2 ~22 stone 6  
fill ~64 ~2 ~37 ~74 ~2 ~37 stone 6  
fill ~64 ~2 ~38 ~74 ~2 ~38 stone 6  
fill ~64 ~2 ~39 ~74 ~2 ~39 stone 6  
fill ~64 ~2 ~40 ~74 ~2 ~40 stone 6  
fill ~64 ~2 ~41 ~74 ~2 ~41 stone 6  
fill ~64 ~2 ~42 ~74 ~2 ~42 stone 6  
fill ~64 ~2 ~43 ~74 ~2 ~43 stone 6  
fill ~64 ~2 ~44 ~74 ~2 ~44 stone 6  
fill ~64 ~2 ~45 ~72 ~2 ~45 stone 6  
fill ~64 ~2 ~46 ~72 ~2 ~46 stone 6  
fill ~64 ~2 ~47 ~69 ~2 ~47 stone_slab 8  
fill ~73 ~2 ~14 ~75 ~2 ~14 stone_slab 8  
fill ~73 ~2 ~45 ~75 ~2 ~45 stone_slab 8  
fill ~75 ~2 ~15 ~75 ~2 ~23 stone_slab 8  
fill ~75 ~2 ~36 ~75 ~2 ~45 stone_slab 8  
fill ~83 ~2 ~29 ~83 ~2 ~30 stone_stairs 4 
setblock ~84 ~2 ~28 stone_stairs 6 
setblock ~84 ~2 ~30 dispenser 2 
setblock ~84 ~2 ~31 stone_stairs 7  
fill ~85 ~2 ~28 ~87 ~2 ~28 glass 0 
setblock ~85 ~2 ~29 redstone_lamp 0 
setblock ~85 ~2 ~30 ladder 3  
fill ~85 ~2 ~31 ~87 ~2 ~31 glass 0 
setblock ~86 ~2 ~29 lever 1 
setblock ~88 ~2 ~28 stone_stairs 5 
setblock ~88 ~2 ~31 stone_stairs 5  
fill ~89 ~2 ~29 ~102 ~2 ~29 stone_slab 8  
fill ~89 ~2 ~30 ~91 ~2 ~30 stone_slab 8  
fill ~93 ~2 ~30 ~101 ~2 ~30 stone_slab 8  
fill ~-16 ~3 ~19 ~-16 ~3 ~21 cobblestone 0  
fill ~-16 ~3 ~38 ~-16 ~3 ~40 cobblestone 0  
fill ~-15 ~3 ~19 ~-11 ~3 ~19 coal_block 0  
fill ~-15 ~3 ~20 ~-11 ~3 ~20 coal_block 0  
fill ~-15 ~3 ~21 ~-11 ~3 ~21 coal_block 0  
fill ~-15 ~3 ~38 ~-11 ~3 ~38 coal_block 0  
fill ~-15 ~3 ~39 ~-11 ~3 ~39 coal_block 0  
fill ~-15 ~3 ~40 ~-11 ~3 ~40 coal_block 0  
fill ~-14 ~3 ~18 ~-11 ~3 ~18 stone_slab 0  
fill ~-14 ~3 ~22 ~-11 ~3 ~22 stone_slab 0  
fill ~-14 ~3 ~37 ~-11 ~3 ~37 stone_slab 0  
fill ~-14 ~3 ~41 ~-11 ~3 ~41 stone_slab 0  
fill ~-10 ~3 ~17 ~-6 ~3 ~17 coal_block 0  
fill ~-10 ~3 ~18 ~-6 ~3 ~18 coal_block 0  
fill ~-10 ~3 ~19 ~5 ~3 ~19 stonebrick 0  
fill ~-10 ~3 ~20 ~5 ~3 ~20 stonebrick 0  
fill ~-10 ~3 ~21 ~5 ~3 ~21 stonebrick 0  
fill ~-10 ~3 ~22 ~-6 ~3 ~22 coal_block 0  
fill ~-10 ~3 ~23 ~-6 ~3 ~23 coal_block 0  
fill ~-10 ~3 ~36 ~-6 ~3 ~36 coal_block 0  
fill ~-10 ~3 ~37 ~-6 ~3 ~37 coal_block 0  
fill ~-10 ~3 ~38 ~5 ~3 ~38 stonebrick 0  
fill ~-10 ~3 ~39 ~5 ~3 ~39 stonebrick 0  
fill ~-10 ~3 ~40 ~5 ~3 ~40 stonebrick 0  
fill ~-10 ~3 ~41 ~-6 ~3 ~41 coal_block 0  
fill ~-10 ~3 ~42 ~-6 ~3 ~42 coal_block 0 
setblock ~-7 ~3 ~16 cobblestone_wall 0 
setblock ~-7 ~3 ~24 cobblestone_wall 0 
setblock ~-7 ~3 ~35 cobblestone_wall 0 
setblock ~-7 ~3 ~43 cobblestone_wall 0 
setblock ~-5 ~3 ~18 nether_brick_stairs 1 
setblock ~-5 ~3 ~22 nether_brick_stairs 1 
setblock ~-5 ~3 ~37 nether_brick_stairs 1 
setblock ~-5 ~3 ~41 nether_brick_stairs 1 
setblock ~-4 ~3 ~18 stone_slab 6 
setblock ~-4 ~3 ~22 stone_slab 6 
setblock ~-4 ~3 ~37 stone_slab 6 
setblock ~-4 ~3 ~41 stone_slab 6  
fill ~6 ~3 ~19 ~6 ~3 ~21 cobblestone 0  
fill ~6 ~3 ~38 ~6 ~3 ~40 cobblestone 0  
fill ~7 ~3 ~19 ~8 ~3 ~19 stonebrick 0  
fill ~7 ~3 ~20 ~8 ~3 ~20 stonebrick 0  
fill ~7 ~3 ~21 ~8 ~3 ~21 stonebrick 0  
fill ~7 ~3 ~38 ~8 ~3 ~38 stonebrick 0  
fill ~7 ~3 ~39 ~8 ~3 ~39 stonebrick 0  
fill ~7 ~3 ~40 ~8 ~3 ~40 stonebrick 0  
fill ~9 ~3 ~18 ~10 ~3 ~18 nether_brick_fence 0  
fill ~9 ~3 ~19 ~10 ~3 ~19 stonebrick 3  
fill ~9 ~3 ~20 ~10 ~3 ~20 stonebrick 3  
fill ~9 ~3 ~21 ~10 ~3 ~21 stonebrick 3  
fill ~9 ~3 ~22 ~10 ~3 ~22 nether_brick_fence 0  
fill ~9 ~3 ~37 ~10 ~3 ~37 nether_brick_fence 0  
fill ~9 ~3 ~38 ~10 ~3 ~38 stonebrick 3  
fill ~9 ~3 ~39 ~10 ~3 ~39 stonebrick 3  
fill ~9 ~3 ~40 ~10 ~3 ~40 stonebrick 3  
fill ~9 ~3 ~41 ~10 ~3 ~41 nether_brick_fence 0  
fill ~11 ~3 ~19 ~11 ~3 ~21 stonebrick 0  
fill ~11 ~3 ~38 ~11 ~3 ~40 stonebrick 0  
fill ~12 ~3 ~19 ~12 ~3 ~21 cobblestone 0  
fill ~12 ~3 ~28 ~17 ~3 ~28 stone 6  
fill ~12 ~3 ~31 ~17 ~3 ~31 stone 6  
fill ~12 ~3 ~38 ~12 ~3 ~40 cobblestone 0 
setblock ~13 ~3 ~5 stonebrick 0  
fill ~13 ~3 ~6 ~13 ~3 ~8 stone 6  
fill ~13 ~3 ~9 ~19 ~3 ~9 stonebrick 0  
fill ~13 ~3 ~19 ~15 ~3 ~19 stonebrick 0  
fill ~13 ~3 ~20 ~15 ~3 ~20 stonebrick 0  
fill ~13 ~3 ~21 ~15 ~3 ~21 stonebrick 0  
fill ~13 ~3 ~38 ~15 ~3 ~38 stonebrick 0  
fill ~13 ~3 ~39 ~15 ~3 ~39 stonebrick 0  
fill ~13 ~3 ~40 ~15 ~3 ~40 stonebrick 0  
fill ~13 ~3 ~50 ~19 ~3 ~50 stonebrick 0  
fill ~13 ~3 ~51 ~13 ~3 ~53 stone 6 
setblock ~13 ~3 ~54 stonebrick 0  
fill ~14 ~3 ~6 ~19 ~3 ~6 cobblestone 0  
fill ~14 ~3 ~7 ~19 ~3 ~7 cobblestone 0  
fill ~14 ~3 ~8 ~19 ~3 ~8 cobblestone 0  
fill ~14 ~3 ~51 ~19 ~3 ~51 cobblestone 0  
fill ~14 ~3 ~52 ~19 ~3 ~52 cobblestone 0  
fill ~14 ~3 ~53 ~19 ~3 ~53 cobblestone 0 
setblock ~16 ~3 ~18 cobblestone_wall 0  
fill ~16 ~3 ~19 ~16 ~3 ~21 stone 5 
setblock ~16 ~3 ~22 cobblestone_wall 0 
setblock ~16 ~3 ~37 cobblestone_wall 0  
fill ~16 ~3 ~38 ~16 ~3 ~40 stone 5 
setblock ~16 ~3 ~41 cobblestone_wall 0  
fill ~17 ~3 ~19 ~18 ~3 ~19 stonebrick 0  
fill ~17 ~3 ~20 ~18 ~3 ~20 stonebrick 0  
fill ~17 ~3 ~21 ~18 ~3 ~21 stonebrick 0  
fill ~17 ~3 ~29 ~17 ~3 ~30 stone_brick_stairs 4  
fill ~17 ~3 ~38 ~18 ~3 ~38 stonebrick 0  
fill ~17 ~3 ~39 ~18 ~3 ~39 stonebrick 0  
fill ~17 ~3 ~40 ~18 ~3 ~40 stonebrick 0  
fill ~18 ~3 ~29 ~19 ~3 ~29 stonebrick 0  
fill ~18 ~3 ~30 ~19 ~3 ~30 stonebrick 0  
fill ~19 ~3 ~19 ~19 ~3 ~21 stonebrick 3  
fill ~19 ~3 ~38 ~19 ~3 ~40 stonebrick 3  
fill ~20 ~3 ~10 ~20 ~21 ~10 stone 6  
fill ~20 ~3 ~11 ~20 ~21 ~11 stone 6  
fill ~20 ~3 ~12 ~20 ~22 ~12 stone 6  
fill ~20 ~3 ~13 ~20 ~22 ~13 stone 6  
fill ~20 ~3 ~14 ~20 ~22 ~14 stone 6  
fill ~20 ~3 ~15 ~20 ~22 ~15 stone 6  
fill ~20 ~3 ~16 ~20 ~23 ~16 stone 6  
fill ~20 ~3 ~17 ~20 ~23 ~17 stone 6  
fill ~20 ~3 ~25 ~20 ~14 ~25 stone 6  
fill ~20 ~3 ~26 ~20 ~10 ~26 stone 6  
fill ~20 ~3 ~27 ~20 ~10 ~27 stone 6  
fill ~20 ~3 ~28 ~20 ~10 ~28 stone 6  
fill ~20 ~3 ~31 ~20 ~10 ~31 stone 6  
fill ~20 ~3 ~32 ~20 ~10 ~32 stone 6  
fill ~20 ~3 ~33 ~20 ~10 ~33 stone 6  
fill ~20 ~3 ~34 ~20 ~14 ~34 stone 6  
fill ~20 ~3 ~42 ~20 ~23 ~42 stone 6  
fill ~20 ~3 ~43 ~20 ~23 ~43 stone 6  
fill ~20 ~3 ~44 ~20 ~22 ~44 stone 6  
fill ~20 ~3 ~45 ~20 ~22 ~45 stone 6  
fill ~20 ~3 ~46 ~20 ~22 ~46 stone 6  
fill ~20 ~3 ~47 ~20 ~22 ~47 stone 6  
fill ~20 ~3 ~48 ~20 ~21 ~48 stone 6  
fill ~20 ~3 ~49 ~20 ~21 ~49 stone 6  
fill ~23 ~3 ~8 ~23 ~3 ~11 stone 4  
fill ~23 ~3 ~48 ~23 ~3 ~51 stone 4  
fill ~35 ~3 ~25 ~48 ~3 ~25 stone 6  
fill ~35 ~3 ~26 ~48 ~3 ~26 stone 6  
fill ~35 ~3 ~27 ~48 ~3 ~27 stone 6  
fill ~35 ~3 ~28 ~48 ~3 ~28 stone 6  
fill ~35 ~3 ~29 ~48 ~3 ~29 stone 6  
fill ~35 ~3 ~30 ~48 ~3 ~30 stone 6  
fill ~35 ~3 ~31 ~48 ~3 ~31 stone 6  
fill ~35 ~3 ~32 ~48 ~3 ~32 stone 6  
fill ~35 ~3 ~33 ~48 ~3 ~33 stone 6  
fill ~35 ~3 ~34 ~48 ~3 ~34 stone 6  
fill ~49 ~3 ~24 ~63 ~3 ~24 stone 6  
fill ~49 ~3 ~35 ~63 ~3 ~35 stone 6  
fill ~51 ~3 ~53 ~58 ~3 ~53 stone 6  
fill ~59 ~3 ~52 ~63 ~3 ~52 stone 6  
fill ~63 ~3 ~23 ~63 ~6 ~23 end_stone 0  
fill ~63 ~3 ~36 ~63 ~6 ~36 end_stone 0  
fill ~64 ~3 ~8 ~69 ~3 ~8 stone 6  
fill ~64 ~3 ~9 ~72 ~3 ~9 stone 6  
fill ~64 ~3 ~10 ~75 ~3 ~10 stone 6  
fill ~64 ~3 ~11 ~75 ~3 ~11 stone 6  
fill ~64 ~3 ~12 ~69 ~3 ~12 end_stone 0  
fill ~64 ~3 ~13 ~72 ~3 ~13 end_stone 0  
fill ~64 ~3 ~14 ~72 ~3 ~14 end_stone 0  
fill ~64 ~3 ~15 ~75 ~3 ~15 end_stone 0  
fill ~64 ~3 ~16 ~75 ~3 ~16 end_stone 0  
fill ~64 ~3 ~17 ~75 ~3 ~17 end_stone 0  
fill ~64 ~3 ~18 ~75 ~3 ~18 end_stone 0  
fill ~64 ~3 ~19 ~75 ~3 ~19 end_stone 0  
fill ~64 ~3 ~20 ~75 ~3 ~20 end_stone 0  
fill ~64 ~3 ~21 ~75 ~3 ~21 end_stone 0  
fill ~64 ~3 ~22 ~75 ~3 ~22 end_stone 0  
fill ~64 ~3 ~23 ~85 ~3 ~23 stone 6  
fill ~64 ~3 ~36 ~85 ~3 ~36 stone 6  
fill ~64 ~3 ~37 ~75 ~3 ~37 end_stone 0  
fill ~64 ~3 ~38 ~75 ~3 ~38 end_stone 0  
fill ~64 ~3 ~39 ~75 ~3 ~39 end_stone 0  
fill ~64 ~3 ~40 ~70 ~3 ~40 quartz_block 0  
fill ~64 ~3 ~41 ~70 ~3 ~41 quartz_block 0  
fill ~64 ~3 ~42 ~75 ~3 ~42 end_stone 0  
fill ~64 ~3 ~43 ~75 ~3 ~43 end_stone 0  
fill ~64 ~3 ~44 ~75 ~3 ~44 end_stone 0  
fill ~64 ~3 ~45 ~72 ~3 ~45 end_stone 0  
fill ~64 ~3 ~46 ~72 ~3 ~46 end_stone 0  
fill ~64 ~3 ~47 ~69 ~3 ~47 end_stone 0  
fill ~64 ~3 ~48 ~75 ~3 ~48 stone 6  
fill ~64 ~3 ~49 ~75 ~3 ~49 stone 6  
fill ~64 ~3 ~50 ~72 ~3 ~50 stone 6  
fill ~64 ~3 ~51 ~69 ~3 ~51 stone 6  
fill ~70 ~3 ~12 ~75 ~3 ~12 stone 6  
fill ~70 ~3 ~47 ~75 ~3 ~47 stone 6  
fill ~71 ~3 ~40 ~75 ~3 ~40 end_stone 0  
fill ~71 ~3 ~41 ~75 ~3 ~41 end_stone 0  
fill ~73 ~3 ~9 ~75 ~3 ~9 stone_slab 8  
fill ~73 ~3 ~13 ~75 ~3 ~13 stone 6  
fill ~73 ~3 ~14 ~75 ~3 ~14 stone 6  
fill ~73 ~3 ~45 ~75 ~3 ~45 stone 6  
fill ~73 ~3 ~46 ~75 ~3 ~46 stone 6  
fill ~73 ~3 ~50 ~75 ~3 ~50 stone_slab 8 
setblock ~76 ~3 ~14 stone_slab 8  
fill ~76 ~3 ~15 ~78 ~3 ~15 stone 6  
fill ~76 ~3 ~16 ~78 ~3 ~16 stone 6  
fill ~76 ~3 ~17 ~81 ~3 ~17 stone 6  
fill ~76 ~3 ~18 ~81 ~3 ~18 stone 6  
fill ~76 ~3 ~19 ~81 ~3 ~19 stone 6  
fill ~76 ~3 ~20 ~81 ~3 ~20 stone 6  
fill ~76 ~3 ~21 ~81 ~3 ~21 stone 6  
fill ~76 ~3 ~22 ~85 ~3 ~22 stone 6  
fill ~76 ~3 ~37 ~85 ~3 ~37 stone 6  
fill ~76 ~3 ~38 ~81 ~3 ~38 stone 6  
fill ~76 ~3 ~39 ~81 ~3 ~39 stone 6  
fill ~76 ~3 ~40 ~81 ~3 ~40 stone 6  
fill ~76 ~3 ~41 ~81 ~3 ~41 stone 6  
fill ~76 ~3 ~42 ~81 ~3 ~42 stone 6  
fill ~76 ~3 ~43 ~78 ~3 ~43 stone 6  
fill ~76 ~3 ~44 ~78 ~3 ~44 stone 6 
setblock ~76 ~3 ~45 stone_slab 8  
fill ~79 ~3 ~16 ~81 ~3 ~16 stone_slab 8  
fill ~79 ~3 ~43 ~81 ~3 ~43 stone_slab 8  
fill ~83 ~3 ~24 ~93 ~3 ~24 stone 6  
fill ~83 ~3 ~25 ~89 ~3 ~25 stone 6  
fill ~83 ~3 ~26 ~103 ~3 ~26 stone 6  
fill ~83 ~3 ~27 ~90 ~3 ~27 stone 6  
fill ~83 ~3 ~28 ~86 ~3 ~28 stone 6  
fill ~83 ~3 ~29 ~85 ~3 ~29 stone 6  
fill ~83 ~3 ~30 ~84 ~3 ~30 stone 6  
fill ~83 ~3 ~31 ~86 ~3 ~31 stone 6  
fill ~83 ~3 ~32 ~90 ~3 ~32 stone 6  
fill ~83 ~3 ~33 ~103 ~3 ~33 stone 6  
fill ~83 ~3 ~34 ~89 ~3 ~34 stone 6  
fill ~83 ~3 ~35 ~93 ~3 ~35 stone 6  
fill ~85 ~3 ~30 ~85 ~4 ~30 ladder 5  
fill ~86 ~3 ~23 ~89 ~3 ~23 stone_slab 8 
setblock ~86 ~3 ~29 double_stone_slab 5 
setblock ~86 ~3 ~30 stone_slab 13  
fill ~86 ~3 ~36 ~89 ~3 ~36 stone_slab 8 
setblock ~87 ~3 ~28 redstone_block 0  
fill ~87 ~3 ~29 ~87 ~3 ~30 sticky_piston 9 
setblock ~87 ~3 ~31 redstone_block 0  
fill ~88 ~3 ~28 ~103 ~3 ~28 stone 6  
fill ~88 ~3 ~29 ~92 ~3 ~29 end_stone 0  
fill ~88 ~3 ~30 ~91 ~3 ~30 end_stone 0  
fill ~88 ~3 ~31 ~103 ~3 ~31 stone 6 
setblock ~90 ~3 ~25 dispenser 8 
setblock ~90 ~3 ~34 dispenser 8 
setblock ~91 ~3 ~25 stone 6 
setblock ~91 ~3 ~27 dispenser 8 
setblock ~91 ~3 ~32 dispenser 8 
setblock ~91 ~3 ~34 stone 6 
setblock ~92 ~3 ~25 dispenser 8  
fill ~92 ~3 ~27 ~92 ~4 ~27 stone 6 
setblock ~92 ~3 ~30 dispenser 0  
fill ~92 ~3 ~32 ~92 ~4 ~32 stone 6 
setblock ~92 ~3 ~34 dispenser 8 
setblock ~93 ~3 ~25 stone 6 
setblock ~93 ~3 ~27 dispenser 8  
fill ~93 ~3 ~29 ~93 ~3 ~30 sticky_piston 9 
setblock ~93 ~3 ~32 dispenser 8 
setblock ~93 ~3 ~34 stone 6  
fill ~94 ~3 ~25 ~97 ~3 ~25 stone_slab 8  
fill ~94 ~3 ~27 ~103 ~3 ~27 stone 6  
fill ~94 ~3 ~29 ~94 ~3 ~30 redstone_block 0  
fill ~94 ~3 ~32 ~100 ~3 ~32 stone 6  
fill ~94 ~3 ~34 ~97 ~3 ~34 stone_slab 8  
fill ~95 ~3 ~29 ~102 ~3 ~29 end_stone 0  
fill ~95 ~3 ~30 ~101 ~3 ~30 end_stone 0 
setblock ~101 ~3 ~32 dispenser 0 
setblock ~102 ~3 ~30 dispenser 0  
fill ~102 ~3 ~32 ~103 ~3 ~32 stone 6  
fill ~103 ~3 ~29 ~103 ~3 ~30 stone_stairs 5  
fill ~104 ~3 ~29 ~120 ~3 ~29 stone_slab 8  
fill ~104 ~3 ~30 ~120 ~3 ~30 stone_slab 8 
setblock ~-16 ~4 ~18 cobblestone 0 
setblock ~-16 ~4 ~22 cobblestone 0 
setblock ~-16 ~4 ~37 cobblestone 0 
setblock ~-16 ~4 ~41 cobblestone 0  
fill ~-15 ~4 ~18 ~-11 ~4 ~18 coal_block 0  
fill ~-15 ~4 ~22 ~-11 ~4 ~22 coal_block 0  
fill ~-15 ~4 ~37 ~-11 ~4 ~37 coal_block 0  
fill ~-15 ~4 ~41 ~-11 ~4 ~41 coal_block 0  
fill ~-14 ~4 ~17 ~-11 ~4 ~17 stone_slab 0  
fill ~-14 ~4 ~23 ~-11 ~4 ~23 stone_slab 0  
fill ~-14 ~4 ~36 ~-11 ~4 ~36 stone_slab 0  
fill ~-14 ~4 ~42 ~-11 ~4 ~42 stone_slab 0  
fill ~-11 ~4 ~20 ~-11 ~6 ~20 stonebrick 3  
fill ~-11 ~4 ~39 ~-11 ~6 ~39 stonebrick 3  
fill ~-10 ~4 ~16 ~-6 ~4 ~16 coal_block 0  
fill ~-10 ~4 ~17 ~-6 ~4 ~17 coal_block 0  
fill ~-10 ~4 ~18 ~5 ~4 ~18 stonebrick 0  
fill ~-10 ~4 ~19 ~-10 ~10 ~19 glowstone 0  
fill ~-10 ~4 ~20 ~-10 ~6 ~20 glowstone 0  
fill ~-10 ~4 ~21 ~-10 ~10 ~21 glowstone 0  
fill ~-10 ~4 ~22 ~5 ~4 ~22 stonebrick 0  
fill ~-10 ~4 ~23 ~-6 ~4 ~23 coal_block 0  
fill ~-10 ~4 ~24 ~-6 ~4 ~24 coal_block 0  
fill ~-10 ~4 ~35 ~-6 ~4 ~35 coal_block 0  
fill ~-10 ~4 ~36 ~-6 ~4 ~36 coal_block 0  
fill ~-10 ~4 ~37 ~5 ~4 ~37 stonebrick 0  
fill ~-10 ~4 ~38 ~-10 ~10 ~38 glowstone 0  
fill ~-10 ~4 ~39 ~-10 ~6 ~39 glowstone 0  
fill ~-10 ~4 ~40 ~-10 ~10 ~40 glowstone 0  
fill ~-10 ~4 ~41 ~5 ~4 ~41 stonebrick 0  
fill ~-10 ~4 ~42 ~-6 ~4 ~42 coal_block 0  
fill ~-10 ~4 ~43 ~-6 ~4 ~43 coal_block 0  
fill ~-7 ~4 ~25 ~-7 ~5 ~25 cobblestone_wall 0  
fill ~-7 ~4 ~34 ~-7 ~5 ~34 cobblestone_wall 0 
setblock ~-5 ~4 ~17 nether_brick_stairs 1 
setblock ~-5 ~4 ~23 nether_brick_stairs 1 
setblock ~-5 ~4 ~36 nether_brick_stairs 1 
setblock ~-5 ~4 ~42 nether_brick_stairs 1 
setblock ~-4 ~4 ~17 stone_slab 6 
setblock ~-4 ~4 ~23 stone_slab 6 
setblock ~-4 ~4 ~36 stone_slab 6 
setblock ~-4 ~4 ~42 stone_slab 6  
fill ~-3 ~4 ~17 ~0 ~4 ~17 iron_block 0  
fill ~-3 ~4 ~23 ~0 ~4 ~23 iron_block 0  
fill ~-3 ~4 ~36 ~0 ~4 ~36 iron_block 0  
fill ~-3 ~4 ~42 ~0 ~4 ~42 iron_block 0 
setblock ~1 ~4 ~17 stone_stairs 6 
setblock ~1 ~4 ~23 stone_stairs 7 
setblock ~1 ~4 ~36 stone_stairs 6 
setblock ~1 ~4 ~42 stone_stairs 7 
setblock ~6 ~4 ~18 cobblestone 0 
setblock ~6 ~4 ~22 cobblestone 0 
setblock ~6 ~4 ~37 cobblestone 0 
setblock ~6 ~4 ~41 cobblestone 0  
fill ~7 ~4 ~18 ~8 ~4 ~18 stonebrick 0  
fill ~7 ~4 ~22 ~8 ~4 ~22 stonebrick 0  
fill ~7 ~4 ~37 ~8 ~4 ~37 stonebrick 0  
fill ~7 ~4 ~41 ~8 ~4 ~41 stonebrick 0  
fill ~9 ~4 ~17 ~10 ~4 ~17 nether_brick_fence 0  
fill ~9 ~4 ~18 ~10 ~4 ~18 stonebrick 3  
fill ~9 ~4 ~22 ~10 ~4 ~22 stonebrick 3  
fill ~9 ~4 ~23 ~10 ~4 ~23 nether_brick_fence 0  
fill ~9 ~4 ~36 ~10 ~4 ~36 nether_brick_fence 0  
fill ~9 ~4 ~37 ~10 ~4 ~37 stonebrick 3  
fill ~9 ~4 ~41 ~10 ~4 ~41 stonebrick 3  
fill ~9 ~4 ~42 ~10 ~4 ~42 nether_brick_fence 0 
setblock ~11 ~4 ~18 stonebrick 0 
setblock ~11 ~4 ~22 stonebrick 0  
fill ~11 ~4 ~29 ~11 ~4 ~30 stone_brick_stairs 4 
setblock ~11 ~4 ~37 stonebrick 0 
setblock ~11 ~4 ~41 stonebrick 0 
setblock ~12 ~4 ~18 cobblestone 0 
setblock ~12 ~4 ~22 cobblestone 0  
fill ~12 ~4 ~29 ~19 ~4 ~29 stonebrick 0  
fill ~12 ~4 ~30 ~19 ~4 ~30 stonebrick 0 
setblock ~12 ~4 ~37 cobblestone 0 
setblock ~12 ~4 ~41 cobblestone 0  
fill ~13 ~4 ~18 ~15 ~4 ~18 stonebrick 0  
fill ~13 ~4 ~22 ~15 ~4 ~22 stonebrick 0  
fill ~13 ~4 ~37 ~15 ~4 ~37 stonebrick 0  
fill ~13 ~4 ~41 ~15 ~4 ~41 stonebrick 0 
setblock ~14 ~4 ~1 stonebrick 0  
fill ~14 ~4 ~2 ~14 ~4 ~4 stone 6  
fill ~14 ~4 ~5 ~19 ~4 ~5 stonebrick 0  
fill ~14 ~4 ~38 ~14 ~4 ~40 stone 6  
fill ~14 ~4 ~54 ~19 ~4 ~54 stonebrick 0  
fill ~14 ~4 ~55 ~14 ~4 ~57 stone 6 
setblock ~14 ~4 ~58 stonebrick 0  
fill ~15 ~4 ~2 ~19 ~4 ~2 cobblestone 0  
fill ~15 ~4 ~3 ~19 ~4 ~3 cobblestone 0  
fill ~15 ~4 ~4 ~19 ~4 ~4 cobblestone 0  
fill ~15 ~4 ~55 ~19 ~4 ~55 cobblestone 0  
fill ~15 ~4 ~56 ~19 ~4 ~56 cobblestone 0  
fill ~15 ~4 ~57 ~19 ~4 ~57 cobblestone 0 
setblock ~16 ~4 ~17 cobblestone_wall 0 
setblock ~16 ~4 ~18 stone 5 
setblock ~16 ~4 ~22 stone 5 
setblock ~16 ~4 ~23 cobblestone_wall 0 
setblock ~16 ~4 ~36 cobblestone_wall 0 
setblock ~16 ~4 ~37 stone 5 
setblock ~16 ~4 ~41 stone 5 
setblock ~16 ~4 ~42 cobblestone_wall 0  
fill ~17 ~4 ~18 ~18 ~4 ~18 stonebrick 0  
fill ~17 ~4 ~22 ~18 ~4 ~22 stonebrick 0  
fill ~17 ~4 ~37 ~18 ~4 ~37 stonebrick 0  
fill ~17 ~4 ~41 ~18 ~4 ~41 stonebrick 0 
setblock ~19 ~4 ~17 stone_brick_stairs 6 
setblock ~19 ~4 ~18 stonebrick 3 
setblock ~19 ~4 ~22 stonebrick 3 
setblock ~19 ~4 ~23 stone_brick_stairs 7 
setblock ~19 ~4 ~36 stone_brick_stairs 6 
setblock ~19 ~4 ~37 stonebrick 3 
setblock ~19 ~4 ~41 stonebrick 3 
setblock ~19 ~4 ~42 stone_brick_stairs 7  
fill ~20 ~4 ~6 ~20 ~20 ~6 stone 6  
fill ~20 ~4 ~7 ~20 ~20 ~7 stone 6  
fill ~20 ~4 ~8 ~20 ~21 ~8 stone 6  
fill ~20 ~4 ~9 ~20 ~21 ~9 stone 6  
fill ~20 ~4 ~50 ~20 ~21 ~50 stone 6  
fill ~20 ~4 ~51 ~20 ~21 ~51 stone 6  
fill ~20 ~4 ~52 ~20 ~20 ~52 stone 6  
fill ~20 ~4 ~53 ~20 ~20 ~53 stone 6  
fill ~23 ~4 ~4 ~23 ~4 ~7 stone 4  
fill ~23 ~4 ~52 ~23 ~4 ~55 stone 4 
setblock ~47 ~4 ~1 stone 4 
setblock ~47 ~4 ~58 stone 4 
setblock ~48 ~4 ~2 stone 4 
setblock ~48 ~4 ~57 stone 4 
setblock ~49 ~4 ~3 stone 4  
fill ~49 ~4 ~25 ~63 ~4 ~25 stone 6  
fill ~49 ~4 ~26 ~63 ~4 ~26 stone 6  
fill ~49 ~4 ~27 ~63 ~4 ~27 stone 6  
fill ~49 ~4 ~28 ~63 ~4 ~28 stone 6  
fill ~49 ~4 ~29 ~63 ~4 ~29 stone 6  
fill ~49 ~4 ~30 ~63 ~4 ~30 stone 6  
fill ~49 ~4 ~31 ~63 ~4 ~31 stone 6  
fill ~49 ~4 ~32 ~63 ~4 ~32 stone 6  
fill ~49 ~4 ~33 ~63 ~4 ~33 stone 6  
fill ~49 ~4 ~34 ~63 ~4 ~34 stone 6 
setblock ~49 ~4 ~56 stone 4 
setblock ~50 ~4 ~4 stone 4 
setblock ~50 ~4 ~55 stone 4  
fill ~51 ~4 ~5 ~58 ~4 ~5 stone 4  
fill ~51 ~4 ~52 ~58 ~4 ~52 furnace 2  
fill ~51 ~4 ~53 ~58 ~4 ~53 end_stone 0  
fill ~51 ~4 ~54 ~58 ~4 ~54 stone 4  
fill ~59 ~4 ~6 ~63 ~4 ~6 stone 4  
fill ~59 ~4 ~51 ~63 ~4 ~51 furnace 2  
fill ~59 ~4 ~52 ~63 ~4 ~52 end_stone 0  
fill ~59 ~4 ~53 ~63 ~4 ~53 stone 4  
fill ~63 ~4 ~24 ~63 ~7 ~24 stone 6  
fill ~63 ~4 ~35 ~63 ~7 ~35 stone 6  
fill ~64 ~4 ~7 ~69 ~4 ~7 stone 4  
fill ~64 ~4 ~8 ~69 ~4 ~8 end_stone 0  
fill ~64 ~4 ~10 ~69 ~4 ~10 end_stone 0  
fill ~64 ~4 ~11 ~75 ~4 ~11 end_stone 0  
fill ~64 ~4 ~23 ~64 ~7 ~23 stone 6  
fill ~64 ~4 ~28 ~64 ~4 ~31 stone_stairs 5  
fill ~64 ~4 ~36 ~64 ~7 ~36 stone 6  
fill ~64 ~4 ~39 ~70 ~4 ~39 quartz_stairs 3  
fill ~64 ~4 ~42 ~70 ~4 ~42 quartz_stairs 2  
fill ~64 ~4 ~48 ~75 ~4 ~48 end_stone 0  
fill ~64 ~4 ~49 ~69 ~4 ~49 end_stone 0  
fill ~64 ~4 ~50 ~69 ~4 ~50 furnace 2  
fill ~64 ~4 ~51 ~69 ~4 ~51 end_stone 0  
fill ~64 ~4 ~52 ~69 ~4 ~52 stone 4  
fill ~65 ~4 ~23 ~65 ~6 ~23 end_stone 0 
setblock ~65 ~4 ~24 stone_brick_stairs 7 
setblock ~65 ~4 ~35 stone_brick_stairs 6  
fill ~65 ~4 ~36 ~65 ~6 ~36 end_stone 0  
fill ~66 ~4 ~23 ~67 ~4 ~23 stone 6  
fill ~66 ~4 ~36 ~67 ~4 ~36 stone 6  
fill ~68 ~4 ~23 ~68 ~7 ~23 end_stone 0 
setblock ~68 ~4 ~24 stone_brick_stairs 7 
setblock ~68 ~4 ~35 stone_brick_stairs 6  
fill ~68 ~4 ~36 ~68 ~7 ~36 end_stone 0  
fill ~69 ~4 ~23 ~70 ~4 ~23 stone 6  
fill ~69 ~4 ~36 ~70 ~4 ~36 stone 6  
fill ~70 ~4 ~8 ~72 ~4 ~8 stone 4  
fill ~70 ~4 ~9 ~74 ~4 ~9 end_stone 0  
fill ~70 ~4 ~12 ~75 ~4 ~12 end_stone 0  
fill ~70 ~4 ~47 ~75 ~4 ~47 end_stone 0  
fill ~70 ~4 ~49 ~72 ~4 ~49 furnace 2  
fill ~70 ~4 ~50 ~74 ~4 ~50 end_stone 0  
fill ~70 ~4 ~51 ~72 ~4 ~51 stone 4  
fill ~71 ~4 ~23 ~71 ~12 ~23 end_stone 0 
setblock ~71 ~4 ~24 stone_brick_stairs 7 
setblock ~71 ~4 ~35 stone_brick_stairs 6  
fill ~71 ~4 ~36 ~71 ~8 ~36 end_stone 0  
fill ~71 ~4 ~39 ~72 ~4 ~39 stone 6  
fill ~71 ~4 ~40 ~71 ~4 ~41 quartz_stairs 0  
fill ~71 ~4 ~42 ~72 ~4 ~42 stone 6  
fill ~72 ~4 ~23 ~73 ~4 ~23 stone 6  
fill ~72 ~4 ~36 ~73 ~4 ~36 stone 6  
fill ~73 ~4 ~7 ~75 ~4 ~7 stone 6  
fill ~73 ~4 ~8 ~75 ~4 ~8 stone 6  
fill ~73 ~4 ~10 ~75 ~4 ~10 end_stone 0  
fill ~73 ~4 ~13 ~75 ~4 ~13 end_stone 0  
fill ~73 ~4 ~14 ~75 ~4 ~14 end_stone 0  
fill ~73 ~4 ~45 ~75 ~4 ~45 end_stone 0  
fill ~73 ~4 ~46 ~75 ~4 ~46 end_stone 0  
fill ~73 ~4 ~49 ~75 ~4 ~49 end_stone 0  
fill ~73 ~4 ~51 ~75 ~4 ~51 stone 6  
fill ~73 ~4 ~52 ~75 ~4 ~52 stone 6  
fill ~74 ~4 ~23 ~74 ~8 ~23 end_stone 0 
setblock ~74 ~4 ~24 stone_brick_stairs 7 
setblock ~74 ~4 ~35 stone_brick_stairs 6 
setblock ~74 ~4 ~36 end_stone 0 
setblock ~75 ~4 ~9 stone 6  
fill ~75 ~4 ~23 ~76 ~4 ~23 stone 6  
fill ~75 ~4 ~34 ~76 ~4 ~34 stonebrick 0  
fill ~75 ~4 ~35 ~76 ~4 ~35 stonebrick 0  
fill ~75 ~4 ~36 ~76 ~4 ~36 quartz_block 0  
fill ~75 ~4 ~37 ~76 ~4 ~37 quartz_block 0  
fill ~75 ~4 ~38 ~76 ~4 ~38 quartz_block 0  
fill ~75 ~4 ~39 ~76 ~4 ~39 sticky_piston 1 
setblock ~75 ~4 ~50 stone 6 
setblock ~76 ~4 ~9 stone_slab 8  
fill ~76 ~4 ~10 ~78 ~4 ~10 stone 6  
fill ~76 ~4 ~11 ~78 ~4 ~11 stone 6  
fill ~76 ~4 ~12 ~81 ~4 ~12 stone 6  
fill ~76 ~4 ~13 ~81 ~4 ~13 stone 6  
fill ~76 ~4 ~14 ~81 ~4 ~14 stone 6  
fill ~76 ~4 ~15 ~78 ~4 ~15 end_stone 0  
fill ~76 ~4 ~16 ~78 ~4 ~16 end_stone 0  
fill ~76 ~4 ~17 ~81 ~4 ~17 end_stone 0  
fill ~76 ~4 ~18 ~81 ~4 ~18 end_stone 0  
fill ~76 ~4 ~19 ~81 ~4 ~19 end_stone 0  
fill ~76 ~4 ~20 ~81 ~4 ~20 end_stone 0  
fill ~76 ~4 ~21 ~81 ~4 ~21 end_stone 0  
fill ~76 ~4 ~22 ~85 ~4 ~22 end_stone 0  
fill ~76 ~4 ~40 ~81 ~4 ~40 end_stone 0  
fill ~76 ~4 ~41 ~81 ~4 ~41 end_stone 0  
fill ~76 ~4 ~42 ~81 ~4 ~42 end_stone 0  
fill ~76 ~4 ~43 ~78 ~4 ~43 end_stone 0  
fill ~76 ~4 ~44 ~78 ~4 ~44 end_stone 0  
fill ~76 ~4 ~45 ~81 ~4 ~45 stone 6  
fill ~76 ~4 ~46 ~81 ~4 ~46 stone 6  
fill ~76 ~4 ~47 ~81 ~4 ~47 stone 6  
fill ~76 ~4 ~48 ~78 ~4 ~48 stone 6  
fill ~76 ~4 ~49 ~78 ~4 ~49 stone 6 
setblock ~76 ~4 ~50 stone_slab 8  
fill ~77 ~4 ~23 ~77 ~17 ~23 end_stone 0 
setblock ~77 ~4 ~24 stone_brick_stairs 7 
setblock ~77 ~4 ~35 stone_brick_stairs 6  
fill ~77 ~4 ~36 ~77 ~4 ~44 end_stone 0  
fill ~78 ~4 ~23 ~79 ~4 ~23 stone 6  
fill ~78 ~4 ~36 ~79 ~4 ~36 stone 6  
fill ~78 ~4 ~37 ~85 ~4 ~37 end_stone 0  
fill ~78 ~4 ~38 ~81 ~4 ~38 end_stone 0  
fill ~78 ~4 ~39 ~81 ~4 ~39 end_stone 0  
fill ~79 ~4 ~11 ~81 ~4 ~11 stone_slab 8  
fill ~79 ~4 ~15 ~81 ~4 ~15 stone 6  
fill ~79 ~4 ~16 ~81 ~4 ~16 stone 6  
fill ~79 ~4 ~43 ~81 ~4 ~43 stone 6  
fill ~79 ~4 ~44 ~81 ~4 ~44 stone 6  
fill ~79 ~4 ~48 ~81 ~4 ~48 stone_slab 8  
fill ~80 ~4 ~23 ~80 ~8 ~23 end_stone 0 
setblock ~80 ~4 ~24 stone_brick_stairs 7 
setblock ~80 ~4 ~35 stone_brick_stairs 6  
fill ~80 ~4 ~36 ~80 ~8 ~36 end_stone 0  
fill ~81 ~4 ~23 ~83 ~4 ~23 stone 6  
fill ~81 ~4 ~36 ~82 ~4 ~36 stone 6 
setblock ~82 ~4 ~16 stone_slab 8  
fill ~82 ~4 ~17 ~85 ~4 ~17 stone 6  
fill ~82 ~4 ~18 ~85 ~4 ~18 stone 6  
fill ~82 ~4 ~19 ~93 ~4 ~19 stone 6  
fill ~82 ~4 ~20 ~93 ~4 ~20 stone 6  
fill ~82 ~4 ~21 ~101 ~4 ~21 stone 6 
setblock ~82 ~4 ~27 stone_stairs 4  
fill ~82 ~4 ~29 ~82 ~4 ~30 stone_stairs 4 
setblock ~82 ~4 ~32 stone_stairs 4  
fill ~82 ~4 ~38 ~101 ~4 ~38 stone 6  
fill ~82 ~4 ~39 ~93 ~4 ~39 stone 6  
fill ~82 ~4 ~40 ~93 ~4 ~40 stone 6  
fill ~82 ~4 ~41 ~85 ~4 ~41 stone 6  
fill ~82 ~4 ~42 ~85 ~4 ~42 stone 6 
setblock ~82 ~4 ~43 stone_slab 8  
fill ~83 ~4 ~24 ~83 ~7 ~24 stone 6  
fill ~83 ~4 ~25 ~83 ~10 ~25 stone 6  
fill ~83 ~4 ~26 ~83 ~8 ~26 stone 6  
fill ~83 ~4 ~27 ~90 ~4 ~27 stone 6  
fill ~83 ~4 ~28 ~92 ~4 ~28 stone 6  
fill ~83 ~4 ~29 ~86 ~4 ~29 stone 6  
fill ~83 ~4 ~30 ~84 ~4 ~30 stone 6  
fill ~83 ~4 ~31 ~92 ~4 ~31 stone 6  
fill ~83 ~4 ~32 ~90 ~4 ~32 stone 6  
fill ~83 ~4 ~33 ~83 ~8 ~33 stone 6  
fill ~83 ~4 ~34 ~83 ~7 ~34 stone 6  
fill ~83 ~4 ~35 ~83 ~7 ~35 stone 6  
fill ~83 ~4 ~36 ~89 ~4 ~36 end_stone 0  
fill ~84 ~4 ~23 ~89 ~4 ~23 end_stone 0  
fill ~84 ~4 ~24 ~93 ~4 ~24 end_stone 0  
fill ~84 ~4 ~25 ~89 ~4 ~25 end_stone 0  
fill ~84 ~4 ~26 ~98 ~4 ~26 end_stone 0  
fill ~84 ~4 ~33 ~98 ~4 ~33 end_stone 0  
fill ~84 ~4 ~34 ~89 ~4 ~34 end_stone 0  
fill ~84 ~4 ~35 ~93 ~4 ~35 end_stone 0  
fill ~86 ~4 ~18 ~89 ~4 ~18 stone_slab 8  
fill ~86 ~4 ~22 ~101 ~4 ~22 stone 6 
setblock ~86 ~4 ~30 stone 6  
fill ~86 ~4 ~37 ~95 ~4 ~37 stone 6  
fill ~86 ~4 ~41 ~89 ~4 ~41 stone_slab 8  
fill ~87 ~4 ~29 ~87 ~4 ~30 piston_head 9  
fill ~88 ~4 ~29 ~92 ~4 ~29 stone 6  
fill ~88 ~4 ~30 ~92 ~4 ~30 stone 6  
fill ~90 ~4 ~23 ~109 ~4 ~23 stone 6 
setblock ~90 ~4 ~25 redstone_block 0 
setblock ~90 ~4 ~34 redstone_block 0  
fill ~90 ~4 ~36 ~109 ~4 ~36 stone 6 
setblock ~91 ~4 ~25 end_stone 0 
setblock ~91 ~4 ~27 redstone_block 0 
setblock ~91 ~4 ~32 redstone_block 0 
setblock ~91 ~4 ~34 end_stone 0 
setblock ~92 ~4 ~25 redstone_block 0 
setblock ~92 ~4 ~34 redstone_block 0  
fill ~93 ~4 ~25 ~97 ~4 ~25 end_stone 0 
setblock ~93 ~4 ~27 redstone_block 0  
fill ~93 ~4 ~28 ~98 ~4 ~28 end_stone 0  
fill ~93 ~4 ~29 ~93 ~4 ~30 piston_head 9  
fill ~93 ~4 ~31 ~98 ~4 ~31 end_stone 0 
setblock ~93 ~4 ~32 redstone_block 0  
fill ~93 ~4 ~34 ~97 ~4 ~34 end_stone 0  
fill ~94 ~4 ~20 ~97 ~4 ~20 stone_slab 8  
fill ~94 ~4 ~24 ~98 ~4 ~24 stone 6  
fill ~94 ~4 ~27 ~96 ~4 ~27 end_stone 0  
fill ~94 ~4 ~29 ~102 ~4 ~29 quartz_block 0  
fill ~94 ~4 ~30 ~102 ~4 ~30 quartz_block 0  
fill ~94 ~4 ~32 ~98 ~4 ~32 end_stone 0 
setblock ~94 ~4 ~35 stone 6  
fill ~94 ~4 ~39 ~97 ~4 ~39 stone_slab 8 
setblock ~95 ~4 ~35 dispenser 8  
fill ~96 ~4 ~35 ~109 ~4 ~35 stone 6 
setblock ~96 ~4 ~37 dispenser 8  
fill ~97 ~4 ~27 ~100 ~4 ~27 quartz_block 0  
fill ~97 ~4 ~37 ~99 ~4 ~37 stone 6  
fill ~98 ~4 ~25 ~117 ~4 ~25 stone 6  
fill ~98 ~4 ~34 ~117 ~4 ~34 stone 6 
setblock ~99 ~4 ~24 dispenser 0  
fill ~99 ~4 ~26 ~100 ~4 ~26 quartz_block 0  
fill ~99 ~4 ~28 ~100 ~4 ~28 quartz_block 0  
fill ~99 ~4 ~31 ~100 ~4 ~31 quartz_block 0  
fill ~99 ~4 ~32 ~100 ~4 ~32 quartz_block 0  
fill ~99 ~4 ~33 ~100 ~4 ~33 quartz_block 0  
fill ~100 ~4 ~24 ~109 ~4 ~24 stone 6 
setblock ~100 ~4 ~37 dispenser 0  
fill ~101 ~4 ~26 ~103 ~4 ~26 end_stone 0  
fill ~101 ~4 ~27 ~103 ~4 ~27 end_stone 0  
fill ~101 ~4 ~28 ~103 ~4 ~28 end_stone 0  
fill ~101 ~4 ~31 ~103 ~4 ~31 end_stone 0  
fill ~101 ~4 ~32 ~103 ~4 ~32 end_stone 0  
fill ~101 ~4 ~33 ~103 ~4 ~33 end_stone 0 
setblock ~101 ~4 ~37 stone 6 
setblock ~101 ~4 ~40 stone 6  
fill ~102 ~4 ~22 ~105 ~4 ~22 stone_slab 8  
fill ~102 ~4 ~37 ~105 ~4 ~37 stone_slab 8  
fill ~103 ~4 ~29 ~103 ~4 ~30 redstone_block 0  
fill ~104 ~4 ~26 ~117 ~4 ~26 stone 6  
fill ~104 ~4 ~27 ~121 ~4 ~27 stone 6  
fill ~104 ~4 ~28 ~121 ~4 ~28 stone 6  
fill ~104 ~4 ~29 ~105 ~4 ~29 sticky_piston 9  
fill ~104 ~4 ~30 ~105 ~4 ~30 sticky_piston 9  
fill ~104 ~4 ~31 ~121 ~4 ~31 stone 6  
fill ~104 ~4 ~32 ~121 ~4 ~32 stone 6  
fill ~104 ~4 ~33 ~117 ~4 ~33 stone 6  
fill ~106 ~4 ~29 ~106 ~4 ~30 redstone_block 0   
fill ~107 ~4 ~29 ~117 ~4 ~29 end_stone 0  
fill ~107 ~4 ~30 ~117 ~4 ~30 end_stone 0  
fill ~110 ~4 ~24 ~113 ~4 ~24 stone_slab 8  
fill ~110 ~4 ~35 ~113 ~4 ~35 stone_slab 8  
fill ~118 ~4 ~26 ~121 ~4 ~26 stone_slab 8  
fill ~118 ~4 ~29 ~118 ~4 ~30 redstone_block 0  
fill ~118 ~4 ~33 ~121 ~4 ~33 stone_slab 8  
fill ~119 ~4 ~29 ~120 ~4 ~29 sticky_piston 9  
fill ~119 ~4 ~30 ~120 ~4 ~30 sticky_piston 9  
fill ~121 ~4 ~29 ~121 ~4 ~30 stone_stairs 5  
fill ~122 ~4 ~29 ~138 ~4 ~29 stone_slab 8  
fill ~122 ~4 ~30 ~138 ~4 ~30 stone_slab 8 
setblock ~-16 ~5 ~17 cobblestone 0 
setblock ~-16 ~5 ~23 cobblestone 0 
setblock ~-16 ~5 ~36 cobblestone 0 
setblock ~-16 ~5 ~42 cobblestone 0  
fill ~-15 ~5 ~17 ~-11 ~5 ~17 coal_block 0  
fill ~-15 ~5 ~23 ~-11 ~5 ~23 coal_block 0  
fill ~-15 ~5 ~36 ~-11 ~5 ~36 coal_block 0  
fill ~-15 ~5 ~42 ~-11 ~5 ~42 coal_block 0  
fill ~-14 ~5 ~16 ~-11 ~5 ~16 stone_slab 0  
fill ~-14 ~5 ~24 ~-11 ~5 ~24 stone_slab 0  
fill ~-14 ~5 ~35 ~-11 ~5 ~35 stone_slab 0  
fill ~-14 ~5 ~43 ~-11 ~5 ~43 stone_slab 0  
fill ~-10 ~5 ~16 ~-6 ~5 ~16 coal_block 0  
fill ~-10 ~5 ~17 ~5 ~5 ~17 stonebrick 0  
fill ~-10 ~5 ~18 ~-10 ~9 ~18 glowstone 0  
fill ~-10 ~5 ~22 ~-10 ~9 ~22 glowstone 0  
fill ~-10 ~5 ~23 ~5 ~5 ~23 stonebrick 0  
fill ~-10 ~5 ~24 ~-6 ~5 ~24 coal_block 0  
fill ~-10 ~5 ~35 ~-6 ~5 ~35 coal_block 0  
fill ~-10 ~5 ~36 ~5 ~5 ~36 stonebrick 0  
fill ~-10 ~5 ~37 ~-10 ~9 ~37 glowstone 0  
fill ~-10 ~5 ~41 ~-10 ~9 ~41 glowstone 0  
fill ~-10 ~5 ~42 ~5 ~5 ~42 stonebrick 0  
fill ~-10 ~5 ~43 ~-6 ~5 ~43 coal_block 0  
fill ~-9 ~5 ~9 ~-6 ~5 ~9 stone_slab 8  
fill ~-9 ~5 ~50 ~-6 ~5 ~50 stone_slab 8  
fill ~-5 ~5 ~8 ~-1 ~5 ~8 coal_block 0  
fill ~-5 ~5 ~9 ~-1 ~5 ~9 coal_block 0  
fill ~-5 ~5 ~10 ~-1 ~5 ~10 coal_block 0 
setblock ~-5 ~5 ~16 nether_brick_stairs 1 
setblock ~-5 ~5 ~24 nether_brick_stairs 1 
setblock ~-5 ~5 ~35 nether_brick_stairs 1 
setblock ~-5 ~5 ~43 nether_brick_stairs 1  
fill ~-5 ~5 ~49 ~-1 ~5 ~49 coal_block 0  
fill ~-5 ~5 ~50 ~-1 ~5 ~50 coal_block 0  
fill ~-5 ~5 ~51 ~-1 ~5 ~51 coal_block 0 
setblock ~-4 ~5 ~16 stone_slab 6 
setblock ~-4 ~5 ~24 stone_slab 6 
setblock ~-4 ~5 ~35 stone_slab 6 
setblock ~-4 ~5 ~43 stone_slab 6  
fill ~-2 ~5 ~6 ~-2 ~5 ~7 cobblestone_wall 0  
fill ~-2 ~5 ~11 ~-2 ~5 ~12 cobblestone_wall 0  
fill ~-2 ~5 ~47 ~-2 ~5 ~48 cobblestone_wall 0  
fill ~-2 ~5 ~52 ~-2 ~5 ~53 cobblestone_wall 0 
setblock ~0 ~5 ~9 nether_brick_stairs 5 
setblock ~0 ~5 ~50 nether_brick_stairs 5 
setblock ~1 ~5 ~9 stone_slab 14 
setblock ~1 ~5 ~50 stone_slab 14  
fill ~2 ~5 ~9 ~3 ~5 ~9 iron_block 0  
fill ~2 ~5 ~50 ~3 ~5 ~50 iron_block 0 
setblock ~4 ~5 ~9 stone_stairs 5 
setblock ~4 ~5 ~50 stone_stairs 5  
fill ~5 ~5 ~29 ~5 ~5 ~30 stone_brick_stairs 4 
setblock ~6 ~5 ~17 cobblestone 0 
setblock ~6 ~5 ~23 cobblestone 0  
fill ~6 ~5 ~29 ~19 ~5 ~29 stonebrick 0  
fill ~6 ~5 ~30 ~19 ~5 ~30 stonebrick 0 
setblock ~6 ~5 ~36 cobblestone 0 
setblock ~6 ~5 ~42 cobblestone 0  
fill ~7 ~5 ~17 ~8 ~5 ~17 stonebrick 0  
fill ~7 ~5 ~23 ~8 ~5 ~23 stonebrick 0  
fill ~7 ~5 ~36 ~8 ~5 ~36 stonebrick 0  
fill ~7 ~5 ~42 ~8 ~5 ~42 stonebrick 0  
fill ~9 ~5 ~16 ~10 ~5 ~16 nether_brick_fence 0  
fill ~9 ~5 ~17 ~10 ~5 ~17 stonebrick 3  
fill ~9 ~5 ~23 ~10 ~5 ~23 stonebrick 3  
fill ~9 ~5 ~24 ~10 ~5 ~24 nether_brick_fence 0  
fill ~9 ~5 ~35 ~10 ~5 ~35 nether_brick_fence 0  
fill ~9 ~5 ~36 ~10 ~5 ~36 stonebrick 3  
fill ~9 ~5 ~42 ~10 ~5 ~42 stonebrick 3  
fill ~9 ~5 ~43 ~10 ~5 ~43 nether_brick_fence 0 
setblock ~11 ~5 ~17 stonebrick 0 
setblock ~11 ~5 ~23 stonebrick 0 
setblock ~11 ~5 ~36 stonebrick 0 
setblock ~11 ~5 ~42 stonebrick 0 
setblock ~12 ~5 ~17 cobblestone 0 
setblock ~12 ~5 ~23 cobblestone 0 
setblock ~12 ~5 ~36 cobblestone 0 
setblock ~12 ~5 ~42 cobblestone 0  
fill ~13 ~5 ~17 ~15 ~5 ~17 stonebrick 0  
fill ~13 ~5 ~23 ~15 ~5 ~23 stonebrick 0  
fill ~13 ~5 ~36 ~15 ~5 ~36 stonebrick 0  
fill ~13 ~5 ~42 ~15 ~5 ~42 stonebrick 0 
setblock ~15 ~5 ~-3 stonebrick 0  
fill ~15 ~5 ~-2 ~15 ~5 ~0 stone 6  
fill ~15 ~5 ~1 ~19 ~5 ~1 stonebrick 0  
fill ~15 ~5 ~2 ~15 ~5 ~4 stone 6  
fill ~15 ~5 ~37 ~15 ~5 ~41 stone 6  
fill ~15 ~5 ~55 ~20 ~5 ~55 stone 6  
fill ~15 ~5 ~56 ~15 ~5 ~57 stone 6  
fill ~15 ~5 ~58 ~19 ~5 ~58 stonebrick 0  
fill ~15 ~5 ~59 ~15 ~5 ~61 stone 6 
setblock ~15 ~5 ~62 stonebrick 0  
fill ~16 ~5 ~-2 ~19 ~5 ~-2 cobblestone 0  
fill ~16 ~5 ~-1 ~19 ~5 ~-1 cobblestone 0  
fill ~16 ~5 ~0 ~19 ~5 ~0 cobblestone 0  
fill ~16 ~5 ~2 ~19 ~5 ~2 end_stone 0  
fill ~16 ~5 ~3 ~19 ~5 ~3 end_stone 0  
fill ~16 ~5 ~4 ~20 ~5 ~4 stone 6 
setblock ~16 ~5 ~16 cobblestone_wall 0 
setblock ~16 ~5 ~17 stone 5 
setblock ~16 ~5 ~23 stone 5 
setblock ~16 ~5 ~24 cobblestone_wall 0 
setblock ~16 ~5 ~35 cobblestone_wall 0 
setblock ~16 ~5 ~36 stone 5 
setblock ~16 ~5 ~42 stone 5 
setblock ~16 ~5 ~43 cobblestone_wall 0  
fill ~16 ~5 ~56 ~19 ~5 ~56 end_stone 0  
fill ~16 ~5 ~57 ~19 ~5 ~57 end_stone 0  
fill ~16 ~5 ~59 ~19 ~5 ~59 cobblestone 0  
fill ~16 ~5 ~60 ~19 ~5 ~60 cobblestone 0  
fill ~16 ~5 ~61 ~19 ~5 ~61 cobblestone 0  
fill ~17 ~5 ~17 ~18 ~5 ~17 stonebrick 0  
fill ~17 ~5 ~23 ~18 ~5 ~23 stonebrick 0  
fill ~17 ~5 ~36 ~18 ~5 ~36 stonebrick 0  
fill ~17 ~5 ~42 ~18 ~5 ~42 stonebrick 0 
setblock ~19 ~5 ~17 stonebrick 3 
setblock ~19 ~5 ~23 stonebrick 3 
setblock ~19 ~5 ~36 stonebrick 3 
setblock ~19 ~5 ~42 stonebrick 3  
fill ~20 ~5 ~2 ~20 ~19 ~2 stone 6  
fill ~20 ~5 ~3 ~20 ~19 ~3 stone 6  
fill ~20 ~5 ~5 ~20 ~20 ~5 stone 6  
fill ~20 ~5 ~54 ~20 ~20 ~54 stone 6  
fill ~20 ~5 ~56 ~20 ~19 ~56 stone 6  
fill ~20 ~5 ~57 ~20 ~19 ~57 stone 6  
fill ~23 ~5 ~0 ~23 ~5 ~3 stone 4  
fill ~23 ~5 ~56 ~23 ~5 ~59 stone 4  
fill ~35 ~5 ~68 ~36 ~5 ~68 stone 6  
fill ~35 ~5 ~69 ~35 ~5 ~68 stone 6  
fill ~36 ~5 ~67 ~37 ~5 ~67 stone 6  
fill ~37 ~5 ~66 ~38 ~5 ~66 stone 6  
fill ~38 ~5 ~65 ~39 ~5 ~65 stone 6  
fill ~40 ~5 ~64 ~40 ~8 ~64 stone 6 
setblock ~41 ~5 ~-5 stone 4 
setblock ~41 ~5 ~64 stone 4 
setblock ~42 ~5 ~-4 stone 4 
setblock ~42 ~5 ~63 stone 4 
setblock ~43 ~5 ~-3 stone 4 
setblock ~43 ~5 ~62 stone 4 
setblock ~44 ~5 ~-2 stone 4 
setblock ~44 ~5 ~61 stone 4 
setblock ~45 ~5 ~-1 stone 4 
setblock ~45 ~5 ~60 stone 4 
setblock ~46 ~5 ~0 stone 4  
fill ~46 ~5 ~1 ~46 ~8 ~1 stone 6 
setblock ~46 ~5 ~31 sticky_piston 1  
fill ~46 ~5 ~57 ~46 ~8 ~57 end_stone 0  
fill ~46 ~5 ~58 ~46 ~8 ~58 stone 6 
setblock ~46 ~5 ~59 stone 4 
setblock ~47 ~5 ~1 nether_brick_fence 0  
fill ~47 ~5 ~2 ~47 ~8 ~2 stone 6  
fill ~47 ~5 ~56 ~47 ~8 ~56 end_stone 0  
fill ~47 ~5 ~57 ~47 ~8 ~57 stone 6 
setblock ~47 ~5 ~58 nether_brick_fence 0  
fill ~48 ~5 ~3 ~48 ~8 ~3 stone 6 
setblock ~48 ~5 ~31 sticky_piston 1  
fill ~48 ~5 ~55 ~48 ~8 ~55 end_stone 0  
fill ~48 ~5 ~56 ~48 ~8 ~56 stone 6  
fill ~49 ~5 ~4 ~49 ~8 ~4 stone 6  
fill ~49 ~5 ~54 ~49 ~8 ~54 end_stone 0  
fill ~49 ~5 ~55 ~49 ~8 ~55 stone 6  
fill ~50 ~5 ~5 ~50 ~8 ~5 stone 6 
setblock ~50 ~5 ~31 sticky_piston 1  
fill ~50 ~5 ~53 ~50 ~8 ~53 end_stone 0  
fill ~50 ~5 ~54 ~50 ~8 ~54 stone 6  
fill ~51 ~5 ~6 ~52 ~5 ~6 stone 6  
fill ~51 ~5 ~7 ~58 ~5 ~7 end_stone 0  
fill ~51 ~5 ~51 ~58 ~5 ~51 furnace 2  
fill ~51 ~5 ~52 ~58 ~5 ~52 end_stone 0  
fill ~51 ~5 ~53 ~52 ~5 ~53 stone 6  
fill ~53 ~5 ~6 ~53 ~8 ~6 stonebrick 0  
fill ~53 ~5 ~53 ~53 ~8 ~53 stonebrick 0  
fill ~54 ~5 ~6 ~58 ~5 ~6 stone 6  
fill ~54 ~5 ~53 ~58 ~5 ~53 stone 6  
fill ~56 ~5 ~27 ~56 ~7 ~27 stone 6  
fill ~56 ~5 ~28 ~56 ~8 ~28 stone 6  
fill ~56 ~5 ~31 ~56 ~8 ~31 stone 6  
fill ~56 ~5 ~32 ~56 ~7 ~32 stone 6  
fill ~57 ~5 ~26 ~63 ~5 ~26 stone 6  
fill ~57 ~5 ~33 ~63 ~5 ~33 stone 6  
fill ~59 ~5 ~7 ~63 ~5 ~7 stone 6  
fill ~59 ~5 ~8 ~63 ~5 ~8 end_stone 0  
fill ~59 ~5 ~50 ~63 ~5 ~50 furnace 2  
fill ~59 ~5 ~51 ~63 ~5 ~51 end_stone 0  
fill ~59 ~5 ~52 ~63 ~5 ~52 stone 6  
fill ~63 ~5 ~25 ~63 ~7 ~25 stone 6  
fill ~63 ~5 ~27 ~63 ~7 ~27 stone 6  
fill ~63 ~5 ~28 ~64 ~5 ~28 glass 0  
fill ~63 ~5 ~29 ~64 ~5 ~29 glass 0  
fill ~63 ~5 ~30 ~64 ~5 ~30 glass 0  
fill ~63 ~5 ~31 ~64 ~5 ~31 glass 0  
fill ~63 ~5 ~32 ~63 ~7 ~32 stone 6  
fill ~63 ~5 ~34 ~63 ~7 ~34 stone 6  
fill ~64 ~5 ~8 ~68 ~5 ~8 stone 6  
fill ~64 ~5 ~9 ~69 ~5 ~9 end_stone 0 
setblock ~64 ~5 ~27 stone_stairs 6 
setblock ~64 ~5 ~32 stone_stairs 7  
fill ~64 ~5 ~38 ~70 ~5 ~38 stone 6  
fill ~64 ~5 ~43 ~70 ~5 ~43 stone 6  
fill ~64 ~5 ~49 ~69 ~5 ~49 furnace 2  
fill ~64 ~5 ~50 ~69 ~5 ~50 end_stone 0  
fill ~64 ~5 ~51 ~68 ~5 ~51 stone 6  
fill ~65 ~5 ~24 ~65 ~7 ~24 stone 4  
fill ~65 ~5 ~35 ~65 ~7 ~35 stone 4  
fill ~66 ~5 ~23 ~67 ~5 ~23 stone 6  
fill ~66 ~5 ~36 ~67 ~5 ~36 stone 6  
fill ~68 ~5 ~24 ~68 ~7 ~24 stone 4  
fill ~68 ~5 ~35 ~68 ~7 ~35 stone 4  
fill ~69 ~5 ~8 ~69 ~8 ~8 stonebrick 0  
fill ~69 ~5 ~23 ~70 ~5 ~23 stone 6  
fill ~69 ~5 ~36 ~70 ~5 ~36 stone 6  
fill ~69 ~5 ~51 ~69 ~8 ~51 stonebrick 0 
setblock ~70 ~5 ~8 cobblestone_wall 0  
fill ~70 ~5 ~9 ~71 ~5 ~9 stone 6  
fill ~70 ~5 ~10 ~71 ~5 ~10 end_stone 0  
fill ~70 ~5 ~48 ~71 ~5 ~48 furnace 2  
fill ~70 ~5 ~49 ~71 ~5 ~49 end_stone 0  
fill ~70 ~5 ~50 ~71 ~5 ~50 stone 6 
setblock ~70 ~5 ~51 cobblestone_wall 0  
fill ~71 ~5 ~24 ~71 ~7 ~24 stone 4  
fill ~71 ~5 ~35 ~71 ~7 ~35 stone 4  
fill ~71 ~5 ~39 ~72 ~5 ~39 stone 6  
fill ~71 ~5 ~42 ~72 ~5 ~42 stone 6 
setblock ~72 ~5 ~7 stone 4  
fill ~72 ~5 ~8 ~72 ~8 ~8 stone 6  
fill ~72 ~5 ~9 ~72 ~8 ~9 end_stone 0  
fill ~72 ~5 ~23 ~73 ~5 ~23 stone 6  
fill ~72 ~5 ~36 ~74 ~5 ~36 stone 6  
fill ~72 ~5 ~40 ~72 ~5 ~41 quartz_stairs 0  
fill ~72 ~5 ~49 ~72 ~8 ~49 furnace 2  
fill ~72 ~5 ~50 ~72 ~8 ~50 end_stone 0  
fill ~72 ~5 ~51 ~72 ~8 ~51 stone 6 
setblock ~72 ~5 ~52 stone 4  
fill ~73 ~5 ~6 ~75 ~5 ~6 stone 4  
fill ~73 ~5 ~7 ~73 ~8 ~7 stone 6  
fill ~73 ~5 ~8 ~73 ~8 ~8 end_stone 0  
fill ~73 ~5 ~40 ~84 ~5 ~40 quartz_block 0  
fill ~73 ~5 ~41 ~84 ~5 ~41 quartz_block 0  
fill ~73 ~5 ~51 ~75 ~5 ~51 furnace 2  
fill ~73 ~5 ~52 ~75 ~5 ~52 end_stone 0  
fill ~73 ~5 ~53 ~75 ~5 ~53 stone 4  
fill ~74 ~5 ~7 ~75 ~5 ~7 end_stone 0  
fill ~74 ~5 ~24 ~74 ~7 ~24 stone 4  
fill ~74 ~5 ~34 ~74 ~6 ~34 stonebrick 0  
fill ~74 ~5 ~35 ~74 ~7 ~35 stone 4  
fill ~74 ~5 ~37 ~74 ~12 ~37 stone 6  
fill ~74 ~5 ~38 ~74 ~11 ~38 stone 6  
fill ~74 ~5 ~39 ~74 ~5 ~36 stone 6 
setblock ~75 ~5 ~9 end_stone 0  
fill ~75 ~5 ~23 ~76 ~5 ~23 stone 6  
fill ~75 ~5 ~34 ~76 ~5 ~34 iron_door 1  
fill ~75 ~5 ~35 ~76 ~5 ~35 stone_pressure_plate 0  
fill ~75 ~5 ~38 ~76 ~5 ~38 quartz_stairs 2  
fill ~75 ~5 ~39 ~76 ~5 ~39 stone_brick_stairs 3 
setblock ~75 ~5 ~50 end_stone 0  
fill ~76 ~5 ~5 ~78 ~5 ~5 stone 6  
fill ~76 ~5 ~6 ~81 ~5 ~6 stone 6  
fill ~76 ~5 ~7 ~81 ~5 ~7 stone 6  
fill ~76 ~5 ~8 ~81 ~5 ~8 stone 6  
fill ~76 ~5 ~9 ~81 ~5 ~9 stone 6  
fill ~76 ~5 ~10 ~78 ~5 ~10 end_stone 0  
fill ~76 ~5 ~11 ~78 ~5 ~11 end_stone 0  
fill ~76 ~5 ~12 ~81 ~5 ~12 end_stone 0  
fill ~76 ~5 ~13 ~81 ~5 ~13 end_stone 0  
fill ~76 ~5 ~14 ~81 ~5 ~14 end_stone 0  
fill ~76 ~5 ~45 ~81 ~5 ~45 end_stone 0  
fill ~76 ~5 ~46 ~81 ~5 ~46 end_stone 0  
fill ~76 ~5 ~47 ~81 ~5 ~47 end_stone 0  
fill ~76 ~5 ~48 ~78 ~5 ~48 end_stone 0  
fill ~76 ~5 ~49 ~78 ~5 ~49 end_stone 0  
fill ~76 ~5 ~50 ~81 ~5 ~50 stone 6  
fill ~76 ~5 ~51 ~81 ~5 ~51 stone 6  
fill ~76 ~5 ~52 ~81 ~5 ~52 stone 6  
fill ~76 ~5 ~53 ~81 ~5 ~53 stone 6  
fill ~76 ~5 ~54 ~78 ~5 ~54 stone 6  
fill ~77 ~5 ~24 ~77 ~7 ~24 stone 4  
fill ~77 ~5 ~34 ~77 ~6 ~34 stonebrick 0  
fill ~77 ~5 ~35 ~77 ~7 ~35 stone 4  
fill ~77 ~5 ~36 ~79 ~5 ~36 stone 6  
fill ~77 ~5 ~37 ~77 ~7 ~37 stone 6  
fill ~77 ~5 ~38 ~77 ~7 ~38 stone 6  
fill ~77 ~5 ~39 ~77 ~5 ~36 stone 6  
fill ~78 ~5 ~23 ~79 ~5 ~23 stone 6  
fill ~78 ~5 ~42 ~79 ~5 ~42 quartz_block 0  
fill ~78 ~5 ~43 ~79 ~5 ~43 quartz_block 0  
fill ~78 ~5 ~44 ~79 ~5 ~44 quartz_block 0  
fill ~79 ~5 ~5 ~81 ~5 ~5 stone_slab 8  
fill ~79 ~5 ~10 ~81 ~5 ~10 stone 6  
fill ~79 ~5 ~11 ~81 ~5 ~11 stone 6  
fill ~79 ~5 ~15 ~81 ~5 ~15 end_stone 0  
fill ~79 ~5 ~16 ~81 ~5 ~16 end_stone 0  
fill ~79 ~5 ~48 ~81 ~5 ~48 stone 6  
fill ~79 ~5 ~49 ~81 ~5 ~49 stone 6  
fill ~79 ~5 ~54 ~81 ~5 ~54 stone_slab 8  
fill ~80 ~5 ~24 ~80 ~7 ~24 stone 4  
fill ~80 ~5 ~35 ~80 ~7 ~35 stone 4  
fill ~80 ~5 ~43 ~81 ~5 ~43 end_stone 0  
fill ~80 ~5 ~44 ~81 ~5 ~44 end_stone 0  
fill ~81 ~5 ~23 ~83 ~5 ~23 stone 6  
fill ~81 ~5 ~36 ~82 ~5 ~36 stone 6 
setblock ~82 ~5 ~11 stone_slab 8  
fill ~82 ~5 ~12 ~85 ~5 ~12 stone 6  
fill ~82 ~5 ~13 ~85 ~5 ~13 stone 6  
fill ~82 ~5 ~14 ~93 ~5 ~14 stone 6  
fill ~82 ~5 ~15 ~93 ~5 ~15 stone 6  
fill ~82 ~5 ~16 ~101 ~5 ~16 stone 6  
fill ~82 ~5 ~17 ~85 ~5 ~17 end_stone 0  
fill ~82 ~5 ~18 ~89 ~5 ~18 end_stone 0  
fill ~82 ~5 ~19 ~93 ~5 ~19 end_stone 0  
fill ~82 ~5 ~20 ~97 ~5 ~20 end_stone 0  
fill ~82 ~5 ~21 ~98 ~5 ~21 end_stone 0 
setblock ~82 ~5 ~28 stone_stairs 6  
fill ~82 ~5 ~29 ~82 ~6 ~29 glass 0  
fill ~82 ~5 ~30 ~82 ~6 ~30 glass 0 
setblock ~82 ~5 ~31 stone_stairs 7  
fill ~82 ~5 ~38 ~96 ~5 ~38 end_stone 0  
fill ~82 ~5 ~39 ~97 ~5 ~39 end_stone 0  
fill ~82 ~5 ~42 ~85 ~5 ~42 end_stone 0  
fill ~82 ~5 ~43 ~101 ~5 ~43 stone 6  
fill ~82 ~5 ~44 ~93 ~5 ~44 stone 6  
fill ~82 ~5 ~45 ~93 ~5 ~45 stone 6  
fill ~82 ~5 ~46 ~85 ~5 ~46 stone 6  
fill ~82 ~5 ~47 ~85 ~5 ~47 stone 6 
setblock ~82 ~5 ~48 stone_slab 8  
fill ~83 ~5 ~28 ~87 ~5 ~28 stone 6  
fill ~83 ~5 ~31 ~87 ~5 ~31 stone 6  
fill ~83 ~5 ~36 ~83 ~8 ~36 end_stone 0  
fill ~84 ~5 ~25 ~84 ~6 ~25 sticky_piston 11  
fill ~84 ~5 ~26 ~84 ~6 ~26 piston_head 11  
fill ~84 ~5 ~32 ~84 ~6 ~32 stonebrick 3  
fill ~84 ~5 ~33 ~84 ~6 ~33 piston_head 10  
fill ~84 ~5 ~34 ~84 ~6 ~34 sticky_piston 10  
fill ~85 ~5 ~26 ~86 ~5 ~26 stone 6  
fill ~85 ~5 ~33 ~86 ~5 ~33 stone 6  
fill ~85 ~5 ~40 ~93 ~5 ~40 end_stone 0  
fill ~85 ~5 ~41 ~89 ~5 ~41 end_stone 0  
fill ~86 ~5 ~13 ~89 ~5 ~13 stone_slab 8  
fill ~86 ~5 ~17 ~101 ~5 ~17 stone 6  
fill ~86 ~5 ~22 ~98 ~5 ~22 end_stone 0  
fill ~86 ~5 ~37 ~95 ~5 ~37 end_stone 0  
fill ~86 ~5 ~42 ~101 ~5 ~42 stone 6  
fill ~86 ~5 ~46 ~89 ~5 ~46 stone_slab 8  
fill ~87 ~5 ~25 ~87 ~6 ~25 sticky_piston 11  
fill ~87 ~5 ~26 ~87 ~6 ~26 piston_head 11  
fill ~87 ~5 ~29 ~87 ~5 ~30 stonebrick 3  
fill ~87 ~5 ~32 ~87 ~6 ~32 stonebrick 3  
fill ~87 ~5 ~33 ~87 ~6 ~33 piston_head 10  
fill ~87 ~5 ~34 ~87 ~6 ~34 sticky_piston 10  
fill ~88 ~5 ~26 ~92 ~5 ~26 stone 6  
fill ~88 ~5 ~33 ~92 ~5 ~33 stone 6  
fill ~90 ~5 ~18 ~109 ~5 ~18 stone 6  
fill ~90 ~5 ~23 ~98 ~5 ~23 end_stone 0  
fill ~90 ~5 ~36 ~98 ~5 ~36 end_stone 0  
fill ~90 ~5 ~41 ~109 ~5 ~41 stone 6  
fill ~91 ~5 ~27 ~91 ~7 ~27 stone 6  
fill ~91 ~5 ~32 ~91 ~8 ~32 stone 6  
fill ~93 ~5 ~27 ~93 ~6 ~27 stone 6  
fill ~93 ~5 ~28 ~93 ~6 ~28 stone 6  
fill ~93 ~5 ~30 ~93 ~6 ~30 stonebrick 3  
fill ~93 ~5 ~31 ~93 ~6 ~31 stone 6  
fill ~93 ~5 ~32 ~93 ~6 ~32 stone 6  
fill ~94 ~5 ~15 ~97 ~5 ~15 stone_slab 8  
fill ~94 ~5 ~19 ~109 ~5 ~19 stone 6  
fill ~94 ~5 ~24 ~97 ~5 ~24 end_stone 0 
setblock ~94 ~5 ~27 redstone_block 0  
fill ~94 ~5 ~28 ~98 ~5 ~28 quartz_stairs 3  
fill ~94 ~5 ~31 ~98 ~5 ~31 quartz_stairs 2 
setblock ~94 ~5 ~35 end_stone 0  
fill ~94 ~5 ~40 ~100 ~5 ~40 stone 6  
fill ~94 ~5 ~44 ~97 ~5 ~44 stone_slab 8 
setblock ~95 ~5 ~27 end_stone 0 
setblock ~95 ~5 ~35 redstone_block 0 
setblock ~96 ~5 ~27 redstone_block 0 
setblock ~96 ~5 ~32 redstone_block 0  
fill ~96 ~5 ~35 ~97 ~5 ~35 end_stone 0 
setblock ~96 ~5 ~37 redstone_block 0  
fill ~97 ~5 ~25 ~97 ~5 ~26 end_stone 0 
setblock ~97 ~5 ~27 sticky_piston 13 
setblock ~97 ~5 ~32 sticky_piston 13  
fill ~97 ~5 ~37 ~98 ~5 ~37 end_stone 0 
setblock ~97 ~5 ~38 quartz_block 0  
fill ~98 ~5 ~20 ~117 ~5 ~20 stone 6  
fill ~98 ~5 ~24 ~98 ~7 ~24 stone 6  
fill ~98 ~5 ~25 ~98 ~7 ~25 stone 6  
fill ~98 ~5 ~26 ~98 ~7 ~26 stone 6 
setblock ~98 ~5 ~27 piston_head 13 
setblock ~98 ~5 ~32 piston_head 13  
fill ~98 ~5 ~33 ~98 ~12 ~33 stone 6  
fill ~98 ~5 ~34 ~98 ~7 ~34 stone 6  
fill ~98 ~5 ~35 ~98 ~7 ~35 stone 6 
setblock ~98 ~5 ~38 end_stone 0  
fill ~98 ~5 ~39 ~117 ~5 ~39 stone 6  
fill ~99 ~5 ~21 ~100 ~5 ~21 quartz_block 0  
fill ~99 ~5 ~22 ~100 ~5 ~22 quartz_block 0  
fill ~99 ~5 ~23 ~100 ~5 ~23 quartz_block 0  
fill ~99 ~5 ~24 ~100 ~5 ~24 quartz_stairs 3  
fill ~99 ~5 ~35 ~100 ~5 ~35 quartz_stairs 2  
fill ~99 ~5 ~36 ~100 ~5 ~36 quartz_block 0  
fill ~99 ~5 ~37 ~100 ~5 ~37 quartz_block 0  
fill ~99 ~5 ~38 ~100 ~5 ~38 quartz_block 0  
fill ~101 ~5 ~21 ~101 ~5 ~23 end_stone 0  
fill ~101 ~5 ~24 ~101 ~7 ~24 stone 6  
fill ~101 ~5 ~25 ~101 ~7 ~25 stone 6  
fill ~101 ~5 ~26 ~101 ~7 ~26 stone 6 
setblock ~101 ~5 ~27 piston_head 12  
fill ~101 ~5 ~28 ~102 ~5 ~28 quartz_stairs 3  
fill ~101 ~5 ~31 ~102 ~5 ~31 quartz_stairs 2 
setblock ~101 ~5 ~32 piston_head 12  
fill ~101 ~5 ~33 ~101 ~7 ~33 stone 6  
fill ~101 ~5 ~34 ~101 ~7 ~34 stone 6  
fill ~101 ~5 ~35 ~101 ~7 ~35 stone 6  
fill ~101 ~5 ~36 ~109 ~5 ~36 end_stone 0  
fill ~101 ~5 ~37 ~105 ~5 ~37 end_stone 0  
fill ~101 ~5 ~38 ~101 ~5 ~36 end_stone 0  
fill ~101 ~5 ~40 ~101 ~6 ~40 end_stone 0  
fill ~102 ~5 ~17 ~105 ~5 ~17 stone_slab 8  
fill ~102 ~5 ~21 ~117 ~5 ~21 stone 6  
fill ~102 ~5 ~22 ~105 ~5 ~22 end_stone 0  
fill ~102 ~5 ~23 ~109 ~5 ~23 end_stone 0  
fill ~102 ~5 ~24 ~107 ~5 ~24 end_stone 0  
fill ~102 ~5 ~25 ~107 ~5 ~25 end_stone 0  
fill ~102 ~5 ~26 ~107 ~5 ~26 end_stone 0 
setblock ~102 ~5 ~27 sticky_piston 12 
setblock ~102 ~5 ~32 sticky_piston 12  
fill ~102 ~5 ~33 ~107 ~5 ~33 end_stone 0  
fill ~102 ~5 ~34 ~107 ~5 ~34 end_stone 0  
fill ~102 ~5 ~35 ~107 ~5 ~35 end_stone 0  
fill ~102 ~5 ~38 ~117 ~5 ~38 stone 6  
fill ~102 ~5 ~40 ~109 ~5 ~40 stone 6  
fill ~102 ~5 ~42 ~105 ~5 ~42 stone_slab 8 
setblock ~103 ~5 ~27 redstone_block 0  
fill ~103 ~5 ~28 ~103 ~8 ~28 quartz_block 0  
fill ~103 ~5 ~29 ~103 ~5 ~30 quartz_stairs 0  
fill ~103 ~5 ~31 ~103 ~8 ~31 quartz_block 0 
setblock ~103 ~5 ~32 redstone_block 0  
fill ~104 ~5 ~27 ~107 ~5 ~27 end_stone 0  
fill ~104 ~5 ~28 ~107 ~5 ~28 end_stone 0  
fill ~104 ~5 ~29 ~105 ~5 ~29 piston_head 9  
fill ~104 ~5 ~30 ~105 ~5 ~30 piston_head 9  
fill ~104 ~5 ~31 ~107 ~5 ~31 end_stone 0  
fill ~104 ~5 ~32 ~107 ~5 ~32 end_stone 0  
fill ~106 ~5 ~22 ~125 ~5 ~22 stone 6  
fill ~106 ~5 ~29 ~118 ~5 ~29 quartz_block 0  
fill ~106 ~5 ~30 ~118 ~5 ~30 quartz_block 0  
fill ~106 ~5 ~37 ~125 ~5 ~37 stone 6  
fill ~108 ~5 ~24 ~109 ~5 ~24 quartz_block 0  
fill ~108 ~5 ~25 ~109 ~5 ~25 quartz_block 0  
fill ~108 ~5 ~26 ~109 ~5 ~26 quartz_block 0  
fill ~108 ~5 ~27 ~109 ~5 ~27 quartz_block 0  
fill ~108 ~5 ~28 ~109 ~5 ~28 quartz_block 0  
fill ~108 ~5 ~31 ~109 ~5 ~31 quartz_block 0  
fill ~108 ~5 ~32 ~109 ~5 ~32 quartz_block 0  
fill ~108 ~5 ~33 ~109 ~5 ~33 quartz_block 0  
fill ~108 ~5 ~34 ~109 ~5 ~34 quartz_block 0  
fill ~108 ~5 ~35 ~109 ~5 ~35 quartz_block 0  
fill ~110 ~5 ~19 ~113 ~5 ~19 stone_slab 8  
fill ~110 ~5 ~23 ~125 ~5 ~23 stone 6  
fill ~110 ~5 ~24 ~113 ~5 ~24 end_stone 0  
fill ~110 ~5 ~25 ~114 ~5 ~25 end_stone 0  
fill ~110 ~5 ~26 ~114 ~5 ~26 end_stone 0  
fill ~110 ~5 ~27 ~114 ~5 ~27 end_stone 0  
fill ~110 ~5 ~28 ~114 ~5 ~28 end_stone 0  
fill ~110 ~5 ~31 ~114 ~5 ~31 end_stone 0  
fill ~110 ~5 ~32 ~114 ~5 ~32 end_stone 0  
fill ~110 ~5 ~33 ~114 ~5 ~33 end_stone 0  
fill ~110 ~5 ~34 ~114 ~5 ~34 end_stone 0  
fill ~110 ~5 ~35 ~113 ~5 ~35 end_stone 0  
fill ~110 ~5 ~36 ~125 ~5 ~36 stone 6  
fill ~110 ~5 ~40 ~113 ~5 ~40 stone_slab 8  
fill ~114 ~5 ~24 ~133 ~5 ~24 stone 6  
fill ~114 ~5 ~35 ~133 ~5 ~35 stone 6  
fill ~115 ~5 ~25 ~116 ~5 ~25 quartz_block 0  
fill ~115 ~5 ~26 ~116 ~5 ~26 quartz_block 0  
fill ~115 ~5 ~27 ~116 ~5 ~27 quartz_block 0  
fill ~115 ~5 ~28 ~116 ~5 ~28 quartz_block 0  
fill ~115 ~5 ~31 ~116 ~5 ~31 quartz_block 0  
fill ~115 ~5 ~32 ~116 ~5 ~32 quartz_block 0  
fill ~115 ~5 ~33 ~116 ~5 ~33 quartz_block 0  
fill ~115 ~5 ~34 ~116 ~5 ~34 quartz_block 0  
fill ~117 ~5 ~25 ~117 ~5 ~28 end_stone 0  
fill ~117 ~5 ~31 ~121 ~5 ~31 end_stone 0  
fill ~117 ~5 ~32 ~121 ~5 ~32 end_stone 0  
fill ~117 ~5 ~33 ~121 ~5 ~33 end_stone 0  
fill ~117 ~5 ~34 ~117 ~5 ~31 end_stone 0  
fill ~118 ~5 ~21 ~121 ~5 ~21 stone_slab 8  
fill ~118 ~5 ~25 ~124 ~5 ~25 stone 6  
fill ~118 ~5 ~26 ~121 ~5 ~26 end_stone 0  
fill ~118 ~5 ~27 ~121 ~5 ~27 end_stone 0  
fill ~118 ~5 ~28 ~121 ~5 ~28 end_stone 0  
fill ~118 ~5 ~34 ~124 ~5 ~34 stone 6  
fill ~118 ~5 ~38 ~121 ~5 ~38 stone_slab 8  
fill ~119 ~5 ~29 ~120 ~5 ~29 piston_head 9  
fill ~119 ~5 ~30 ~120 ~5 ~30 piston_head 9  
fill ~121 ~5 ~29 ~121 ~5 ~30 redstone_block 0  
fill ~122 ~5 ~26 ~139 ~5 ~26 stone 6  
fill ~122 ~5 ~27 ~125 ~5 ~27 stone 6  
fill ~122 ~5 ~28 ~139 ~5 ~28 stone 6  
fill ~122 ~5 ~29 ~123 ~5 ~29 sticky_piston 9  
fill ~122 ~5 ~30 ~123 ~5 ~30 sticky_piston 9  
fill ~122 ~5 ~31 ~139 ~5 ~31 stone 6  
fill ~122 ~5 ~32 ~125 ~5 ~32 stone 6  
fill ~122 ~5 ~33 ~139 ~5 ~33 stone 6  
fill ~124 ~5 ~29 ~124 ~5 ~30 redstone_block 0 
setblock ~125 ~5 ~25 dispenser 0  
fill ~125 ~5 ~29 ~134 ~5 ~29 end_stone 0  
fill ~125 ~5 ~30 ~134 ~5 ~30 end_stone 0 
setblock ~125 ~5 ~34 dispenser 0  
fill ~126 ~5 ~23 ~129 ~5 ~23 stone_slab 8 
setblock ~126 ~5 ~25 stone 6 
setblock ~126 ~5 ~27 dispenser 0 
setblock ~126 ~5 ~32 dispenser 0 
setblock ~126 ~5 ~34 stone 6  
fill ~126 ~5 ~36 ~129 ~5 ~36 stone_slab 8 
setblock ~127 ~5 ~25 dispenser 0 
setblock ~127 ~5 ~27 stone 6 
setblock ~127 ~5 ~32 stone 6 
setblock ~127 ~5 ~34 dispenser 0 
setblock ~128 ~5 ~25 stone 6 
setblock ~128 ~5 ~27 dispenser 0 
setblock ~128 ~5 ~32 dispenser 0 
setblock ~128 ~5 ~34 stone 6 
setblock ~129 ~5 ~25 dispenser 0 
setblock ~129 ~5 ~27 stone 6 
setblock ~129 ~5 ~32 stone 6 
setblock ~129 ~5 ~34 dispenser 0 
setblock ~130 ~5 ~25 stone 6 
setblock ~130 ~5 ~27 dispenser 0 
setblock ~130 ~5 ~32 dispenser 0 
setblock ~130 ~5 ~34 stone 6 
setblock ~131 ~5 ~25 dispenser 0 
setblock ~131 ~5 ~27 stone 6 
setblock ~131 ~5 ~32 stone 6 
setblock ~131 ~5 ~34 dispenser 0  
fill ~132 ~5 ~25 ~133 ~5 ~25 stone 6 
setblock ~132 ~5 ~27 dispenser 0 
setblock ~132 ~5 ~32 dispenser 0  
fill ~132 ~5 ~34 ~133 ~5 ~34 stone 6 
setblock ~133 ~5 ~27 stone 6 
setblock ~133 ~5 ~32 stone 6  
fill ~134 ~5 ~25 ~137 ~5 ~25 stone_slab 8 
setblock ~134 ~5 ~27 dispenser 0 
setblock ~134 ~5 ~32 dispenser 0  
fill ~134 ~5 ~34 ~137 ~5 ~34 stone_slab 8  
fill ~135 ~5 ~27 ~139 ~5 ~27 stone 6  
fill ~135 ~5 ~29 ~135 ~5 ~30 redstone_block 0  
fill ~135 ~5 ~32 ~139 ~5 ~32 stone 6  
fill ~136 ~5 ~29 ~137 ~5 ~29 sticky_piston 9  
fill ~136 ~5 ~30 ~137 ~5 ~30 sticky_piston 9  
fill ~138 ~5 ~29 ~138 ~5 ~30 redstone_block 0  
fill ~139 ~5 ~29 ~139 ~5 ~30 stone_stairs 5  
fill ~140 ~5 ~29 ~156 ~5 ~29 stone_slab 8  
fill ~140 ~5 ~30 ~156 ~5 ~30 stone_slab 8  
fill ~-16 ~6 ~16 ~-16 ~8 ~16 cobblestone 0  
fill ~-16 ~6 ~24 ~-16 ~8 ~24 cobblestone 0  
fill ~-16 ~6 ~35 ~-16 ~8 ~35 cobblestone 0  
fill ~-16 ~6 ~43 ~-16 ~8 ~43 cobblestone 0  
fill ~-15 ~6 ~16 ~-11 ~6 ~16 coal_block 0  
fill ~-15 ~6 ~24 ~-11 ~6 ~24 coal_block 0  
fill ~-15 ~6 ~35 ~-11 ~6 ~35 coal_block 0  
fill ~-15 ~6 ~43 ~-11 ~6 ~43 coal_block 0  
fill ~-14 ~6 ~25 ~-11 ~6 ~25 stone_slab 0  
fill ~-14 ~6 ~34 ~-11 ~6 ~34 stone_slab 0  
fill ~-11 ~6 ~8 ~-11 ~6 ~10 cobblestone 0  
fill ~-11 ~6 ~49 ~-11 ~6 ~51 cobblestone 0  
fill ~-10 ~6 ~8 ~-6 ~6 ~8 coal_block 0  
fill ~-10 ~6 ~9 ~-6 ~6 ~9 coal_block 0  
fill ~-10 ~6 ~10 ~-6 ~6 ~10 coal_block 0  
fill ~-10 ~6 ~16 ~5 ~6 ~16 stonebrick 0  
fill ~-10 ~6 ~17 ~-10 ~8 ~17 glowstone 0  
fill ~-10 ~6 ~23 ~-10 ~8 ~23 glowstone 0  
fill ~-10 ~6 ~24 ~5 ~6 ~24 stonebrick 0  
fill ~-10 ~6 ~25 ~-6 ~6 ~25 coal_block 0  
fill ~-10 ~6 ~34 ~-6 ~6 ~34 coal_block 0  
fill ~-10 ~6 ~35 ~5 ~6 ~35 stonebrick 0  
fill ~-10 ~6 ~36 ~-10 ~8 ~36 glowstone 0  
fill ~-10 ~6 ~42 ~-10 ~8 ~42 glowstone 0  
fill ~-10 ~6 ~43 ~5 ~6 ~43 stonebrick 0  
fill ~-10 ~6 ~49 ~-6 ~6 ~49 coal_block 0  
fill ~-10 ~6 ~50 ~-6 ~6 ~50 coal_block 0  
fill ~-10 ~6 ~51 ~-6 ~6 ~51 coal_block 0  
fill ~-9 ~6 ~7 ~-6 ~6 ~7 stone_slab 0  
fill ~-9 ~6 ~11 ~-6 ~6 ~11 stone_slab 0  
fill ~-9 ~6 ~48 ~-6 ~6 ~48 stone_slab 0  
fill ~-9 ~6 ~52 ~-6 ~6 ~52 stone_slab 0  
fill ~-5 ~6 ~6 ~-1 ~6 ~6 coal_block 0  
fill ~-5 ~6 ~7 ~-1 ~6 ~7 coal_block 0  
fill ~-5 ~6 ~8 ~8 ~6 ~8 stonebrick 0  
fill ~-5 ~6 ~9 ~8 ~6 ~9 stonebrick 0  
fill ~-5 ~6 ~10 ~8 ~6 ~10 stonebrick 0  
fill ~-5 ~6 ~11 ~-1 ~6 ~11 coal_block 0  
fill ~-5 ~6 ~12 ~-1 ~6 ~12 coal_block 0  
fill ~-5 ~6 ~25 ~-5 ~8 ~25 nether_brick_stairs 1  
fill ~-5 ~6 ~34 ~-5 ~8 ~34 nether_brick_stairs 1  
fill ~-5 ~6 ~47 ~-1 ~6 ~47 coal_block 0  
fill ~-5 ~6 ~48 ~-1 ~6 ~48 coal_block 0  
fill ~-5 ~6 ~49 ~8 ~6 ~49 stonebrick 0  
fill ~-5 ~6 ~50 ~8 ~6 ~50 stonebrick 0  
fill ~-5 ~6 ~51 ~8 ~6 ~51 stonebrick 0  
fill ~-5 ~6 ~52 ~-1 ~6 ~52 coal_block 0  
fill ~-5 ~6 ~53 ~-1 ~6 ~53 coal_block 0  
fill ~-4 ~6 ~25 ~-4 ~8 ~25 stone_slab 6  
fill ~-4 ~6 ~34 ~-4 ~8 ~34 stone_slab 6 
setblock ~-2 ~6 ~5 cobblestone_wall 0 
setblock ~-2 ~6 ~13 cobblestone_wall 0 
setblock ~-2 ~6 ~46 cobblestone_wall 0 
setblock ~-2 ~6 ~54 cobblestone_wall 0  
fill ~-1 ~6 ~29 ~-1 ~6 ~30 stone_brick_stairs 4 
setblock ~0 ~6 ~7 nether_brick_stairs 1 
setblock ~0 ~6 ~11 nether_brick_stairs 1  
fill ~0 ~6 ~29 ~19 ~6 ~29 stonebrick 0  
fill ~0 ~6 ~30 ~19 ~6 ~30 stonebrick 0 
setblock ~0 ~6 ~48 nether_brick_stairs 1 
setblock ~0 ~6 ~52 nether_brick_stairs 1 
setblock ~1 ~6 ~7 stone_slab 6 
setblock ~1 ~6 ~11 stone_slab 6 
setblock ~1 ~6 ~48 stone_slab 6 
setblock ~1 ~6 ~52 stone_slab 6  
fill ~6 ~6 ~16 ~6 ~8 ~16 cobblestone 0  
fill ~6 ~6 ~24 ~6 ~8 ~24 cobblestone 0  
fill ~6 ~6 ~35 ~6 ~8 ~35 cobblestone 0  
fill ~6 ~6 ~43 ~6 ~8 ~43 cobblestone 0  
fill ~7 ~6 ~16 ~8 ~6 ~16 stonebrick 0  
fill ~7 ~6 ~24 ~8 ~6 ~24 stonebrick 0  
fill ~7 ~6 ~35 ~8 ~6 ~35 stonebrick 0  
fill ~7 ~6 ~43 ~8 ~6 ~43 stonebrick 0  
fill ~9 ~6 ~8 ~9 ~6 ~10 cobblestone 0  
fill ~9 ~6 ~16 ~10 ~6 ~16 stonebrick 3  
fill ~9 ~6 ~24 ~10 ~6 ~24 stonebrick 3  
fill ~9 ~6 ~25 ~10 ~6 ~25 nether_brick_fence 0  
fill ~9 ~6 ~34 ~10 ~6 ~34 nether_brick_fence 0  
fill ~9 ~6 ~35 ~10 ~6 ~35 stonebrick 3  
fill ~9 ~6 ~43 ~10 ~6 ~43 stonebrick 3  
fill ~9 ~6 ~49 ~9 ~6 ~51 cobblestone 0  
fill ~10 ~6 ~8 ~11 ~6 ~8 stonebrick 0  
fill ~10 ~6 ~9 ~11 ~6 ~9 stonebrick 0  
fill ~10 ~6 ~10 ~11 ~6 ~10 stonebrick 0  
fill ~10 ~6 ~49 ~11 ~6 ~49 stonebrick 0  
fill ~10 ~6 ~50 ~11 ~6 ~50 stonebrick 0  
fill ~10 ~6 ~51 ~11 ~6 ~51 stonebrick 0  
fill ~11 ~6 ~16 ~11 ~8 ~16 stonebrick 0  
fill ~11 ~6 ~24 ~11 ~8 ~24 stonebrick 0  
fill ~11 ~6 ~35 ~11 ~8 ~35 stonebrick 0  
fill ~11 ~6 ~43 ~11 ~8 ~43 stonebrick 0  
fill ~12 ~6 ~7 ~13 ~6 ~7 nether_brick_fence 0  
fill ~12 ~6 ~8 ~13 ~6 ~8 stonebrick 3  
fill ~12 ~6 ~9 ~13 ~6 ~9 stonebrick 3  
fill ~12 ~6 ~10 ~13 ~6 ~10 stonebrick 3  
fill ~12 ~6 ~11 ~13 ~6 ~11 nether_brick_fence 0  
fill ~12 ~6 ~16 ~12 ~8 ~16 cobblestone 0  
fill ~12 ~6 ~24 ~12 ~8 ~24 cobblestone 0  
fill ~12 ~6 ~35 ~12 ~8 ~35 cobblestone 0  
fill ~12 ~6 ~43 ~12 ~8 ~43 cobblestone 0  
fill ~12 ~6 ~48 ~13 ~6 ~48 nether_brick_fence 0  
fill ~12 ~6 ~49 ~13 ~6 ~49 stonebrick 3  
fill ~12 ~6 ~50 ~13 ~6 ~50 stonebrick 3  
fill ~12 ~6 ~51 ~13 ~6 ~51 stonebrick 3  
fill ~12 ~6 ~52 ~13 ~6 ~52 nether_brick_fence 0  
fill ~13 ~6 ~16 ~15 ~6 ~16 stonebrick 0  
fill ~13 ~6 ~24 ~15 ~6 ~24 stonebrick 0  
fill ~13 ~6 ~35 ~15 ~6 ~35 stonebrick 0  
fill ~13 ~6 ~43 ~15 ~6 ~43 stonebrick 0  
fill ~14 ~6 ~8 ~14 ~6 ~10 stonebrick 0  
fill ~14 ~6 ~49 ~14 ~6 ~51 stonebrick 0 
setblock ~15 ~6 ~2 stone_brick_stairs 0 
setblock ~15 ~6 ~3 nether_brick_stairs 0 
setblock ~15 ~6 ~4 stone_brick_stairs 0  
fill ~15 ~6 ~8 ~15 ~6 ~10 cobblestone 0  
fill ~15 ~6 ~49 ~15 ~6 ~51 cobblestone 0 
setblock ~15 ~6 ~55 stone_brick_stairs 0 
setblock ~15 ~6 ~56 nether_brick_stairs 0 
setblock ~15 ~6 ~57 stone_brick_stairs 0  
fill ~16 ~6 ~-7 ~19 ~6 ~-7 stonebrick 0  
fill ~16 ~6 ~-6 ~16 ~6 ~-4 stone 6  
fill ~16 ~6 ~-3 ~19 ~6 ~-3 stonebrick 0  
fill ~16 ~6 ~-2 ~16 ~6 ~-1 stone 6 
setblock ~16 ~6 ~0 nether_brick 0 
setblock ~16 ~6 ~1 stone 6  
fill ~16 ~6 ~2 ~19 ~6 ~2 end_stone 0  
fill ~16 ~6 ~3 ~19 ~6 ~3 end_stone 0  
fill ~16 ~6 ~4 ~20 ~6 ~4 stone 6 
setblock ~16 ~6 ~7 cobblestone_wall 0  
fill ~16 ~6 ~8 ~16 ~6 ~10 stone 5 
setblock ~16 ~6 ~11 cobblestone_wall 0  
fill ~16 ~6 ~16 ~16 ~8 ~16 stone 5  
fill ~16 ~6 ~24 ~16 ~8 ~24 stone 5  
fill ~16 ~6 ~35 ~16 ~8 ~35 stone 5  
fill ~16 ~6 ~36 ~17 ~6 ~36 stone 6  
fill ~16 ~6 ~37 ~17 ~6 ~37 stone 6  
fill ~16 ~6 ~38 ~17 ~6 ~38 stone 6  
fill ~16 ~6 ~39 ~17 ~6 ~39 stone 6  
fill ~16 ~6 ~40 ~17 ~6 ~40 stone 6  
fill ~16 ~6 ~41 ~17 ~6 ~41 stone 6  
fill ~16 ~6 ~42 ~17 ~6 ~42 stone 6  
fill ~16 ~6 ~43 ~16 ~8 ~43 stone 5 
setblock ~16 ~6 ~48 cobblestone_wall 0  
fill ~16 ~6 ~49 ~16 ~6 ~51 stone 5 
setblock ~16 ~6 ~52 cobblestone_wall 0  
fill ~16 ~6 ~55 ~20 ~6 ~55 stone 6  
fill ~16 ~6 ~56 ~19 ~6 ~56 end_stone 0  
fill ~16 ~6 ~57 ~19 ~6 ~57 end_stone 0 
setblock ~16 ~6 ~58 stone 6 
setblock ~16 ~6 ~59 nether_brick 0  
fill ~16 ~6 ~60 ~16 ~7 ~60 stone 6  
fill ~16 ~6 ~61 ~16 ~6 ~60 stone 6  
fill ~16 ~6 ~62 ~19 ~6 ~62 stonebrick 0  
fill ~16 ~6 ~63 ~16 ~6 ~65 stone 6  
fill ~16 ~6 ~66 ~19 ~6 ~66 stonebrick 0  
fill ~17 ~6 ~-11 ~19 ~6 ~-11 stonebrick 0  
fill ~17 ~6 ~-10 ~17 ~6 ~-8 stone 6  
fill ~17 ~6 ~-6 ~19 ~6 ~-6 cobblestone 0  
fill ~17 ~6 ~-5 ~19 ~6 ~-5 cobblestone 0  
fill ~17 ~6 ~-4 ~19 ~6 ~-4 cobblestone 0  
fill ~17 ~6 ~-2 ~19 ~6 ~-2 end_stone 0  
fill ~17 ~6 ~-1 ~19 ~6 ~-1 end_stone 0  
fill ~17 ~6 ~0 ~19 ~6 ~0 end_stone 0  
fill ~17 ~6 ~1 ~19 ~6 ~1 end_stone 0  
fill ~17 ~6 ~8 ~18 ~6 ~8 stonebrick 0  
fill ~17 ~6 ~9 ~18 ~6 ~9 stonebrick 0  
fill ~17 ~6 ~10 ~18 ~6 ~10 stonebrick 0  
fill ~17 ~6 ~16 ~18 ~6 ~16 stonebrick 0  
fill ~17 ~6 ~24 ~18 ~6 ~24 stonebrick 0  
fill ~17 ~6 ~35 ~18 ~6 ~35 stonebrick 0  
fill ~17 ~6 ~43 ~18 ~6 ~43 stonebrick 0  
fill ~17 ~6 ~49 ~18 ~6 ~49 stonebrick 0  
fill ~17 ~6 ~50 ~18 ~6 ~50 stonebrick 0  
fill ~17 ~6 ~51 ~18 ~6 ~51 stonebrick 0  
fill ~17 ~6 ~58 ~19 ~6 ~58 end_stone 0  
fill ~17 ~6 ~59 ~19 ~6 ~59 end_stone 0  
fill ~17 ~6 ~60 ~19 ~6 ~60 end_stone 0  
fill ~17 ~6 ~61 ~19 ~6 ~61 end_stone 0  
fill ~17 ~6 ~63 ~19 ~6 ~63 cobblestone 0  
fill ~17 ~6 ~64 ~19 ~6 ~64 cobblestone 0  
fill ~17 ~6 ~65 ~19 ~6 ~65 cobblestone 0  
fill ~17 ~6 ~67 ~17 ~6 ~69 stone 6  
fill ~17 ~6 ~70 ~19 ~6 ~70 stonebrick 0  
fill ~18 ~6 ~-10 ~19 ~6 ~-10 cobblestone 0  
fill ~18 ~6 ~-9 ~19 ~6 ~-9 cobblestone 0  
fill ~18 ~6 ~-8 ~19 ~6 ~-8 cobblestone 0  
fill ~18 ~6 ~67 ~19 ~6 ~67 cobblestone 0  
fill ~18 ~6 ~68 ~19 ~6 ~68 cobblestone 0  
fill ~18 ~6 ~69 ~19 ~6 ~69 cobblestone 0  
fill ~19 ~6 ~8 ~19 ~6 ~10 stonebrick 3  
fill ~19 ~6 ~16 ~19 ~8 ~16 stonebrick 3  
fill ~19 ~6 ~24 ~19 ~8 ~24 stonebrick 3  
fill ~19 ~6 ~35 ~19 ~8 ~35 stonebrick 3  
fill ~19 ~6 ~43 ~19 ~8 ~43 stonebrick 3  
fill ~19 ~6 ~49 ~19 ~6 ~51 stonebrick 3  
fill ~20 ~6 ~-2 ~20 ~18 ~-2 stone 6  
fill ~20 ~6 ~-1 ~20 ~18 ~-1 stone 6  
fill ~20 ~6 ~0 ~20 ~19 ~0 stone 6  
fill ~20 ~6 ~1 ~20 ~19 ~1 stone 6  
fill ~20 ~6 ~58 ~20 ~19 ~58 stone 6  
fill ~20 ~6 ~59 ~20 ~19 ~59 stone 6  
fill ~20 ~6 ~60 ~20 ~18 ~60 stone 6  
fill ~20 ~6 ~61 ~20 ~18 ~61 stone 6  
fill ~23 ~6 ~-4 ~23 ~6 ~-1 stone 4  
fill ~23 ~6 ~60 ~23 ~6 ~63 stone 4 
setblock ~28 ~6 ~76 stone 6 
setblock ~29 ~6 ~75 stone 6 
setblock ~30 ~6 ~74 stone 6 
setblock ~31 ~6 ~73 stone 6 
setblock ~32 ~6 ~72 stone 6 
setblock ~33 ~6 ~71 stone 6  
fill ~34 ~6 ~70 ~34 ~8 ~70 stone 6 
setblock ~35 ~6 ~-11 stone 4 
setblock ~35 ~6 ~70 stone 4 
setblock ~36 ~6 ~-10 stone 4 
setblock ~36 ~6 ~69 stone 4 
setblock ~37 ~6 ~-9 stone 4 
setblock ~37 ~6 ~68 stone 4 
setblock ~38 ~6 ~-8 stone 4 
setblock ~38 ~6 ~67 stone 4 
setblock ~39 ~6 ~-7 stone 4 
setblock ~39 ~6 ~66 stone 4 
setblock ~40 ~6 ~-6 stone 4  
fill ~40 ~6 ~-5 ~40 ~8 ~-5 stone 6  
fill ~40 ~6 ~63 ~40 ~8 ~63 end_stone 0 
setblock ~40 ~6 ~65 stone 4 
setblock ~41 ~6 ~-5 nether_brick_fence 0  
fill ~41 ~6 ~-4 ~41 ~8 ~-4 stone 6  
fill ~41 ~6 ~62 ~41 ~8 ~62 end_stone 0  
fill ~41 ~6 ~63 ~41 ~8 ~63 stone 6 
setblock ~41 ~6 ~64 nether_brick_fence 0  
fill ~42 ~6 ~-3 ~42 ~8 ~-3 stone 6  
fill ~42 ~6 ~61 ~42 ~8 ~61 end_stone 0  
fill ~42 ~6 ~62 ~42 ~8 ~62 stone 6  
fill ~43 ~6 ~-2 ~43 ~8 ~-2 stone 6  
fill ~43 ~6 ~60 ~43 ~8 ~60 end_stone 0  
fill ~43 ~6 ~61 ~43 ~8 ~61 stone 6  
fill ~44 ~6 ~-1 ~44 ~8 ~-1 stone 6   
fill ~44 ~6 ~59 ~44 ~8 ~59 end_stone 0  
fill ~44 ~6 ~60 ~44 ~8 ~60 stone 6  
fill ~45 ~6 ~0 ~45 ~8 ~0 stone 6  
fill ~45 ~6 ~58 ~45 ~8 ~58 end_stone 0  
fill ~45 ~6 ~59 ~45 ~8 ~59 stone 6 
setblock ~46 ~6 ~31 slime 0 
setblock ~48 ~6 ~31 slime 0 
setblock ~50 ~6 ~31 slime 0  
fill ~51 ~6 ~6 ~52 ~6 ~6 stone 6  
fill ~51 ~6 ~7 ~58 ~6 ~7 end_stone 0  
fill ~51 ~6 ~51 ~58 ~6 ~51 furnace 2  
fill ~51 ~6 ~52 ~58 ~6 ~52 end_stone 0  
fill ~51 ~6 ~53 ~52 ~6 ~53 stone 6  
