setblock ~10 ~0 ~28 stained_hardened_clay 11  
fill ~12 ~0 ~28 ~12 ~1 ~28 stained_hardened_clay 11  
fill ~12 ~0 ~29 ~12 ~0 ~28 stained_hardened_clay 11  
fill ~13 ~0 ~30 ~13 ~0 ~31 stained_hardened_clay 11  
fill ~14 ~0 ~23 ~16 ~0 ~23 stained_hardened_clay 11  
fill ~14 ~0 ~24 ~18 ~0 ~24 stained_hardened_clay 11  
fill ~14 ~0 ~31 ~14 ~0 ~32 stained_hardened_clay 11  
fill ~15 ~0 ~25 ~18 ~0 ~25 stained_hardened_clay 11  
fill ~15 ~0 ~26 ~19 ~0 ~26 stained_hardened_clay 11  
fill ~15 ~0 ~27 ~27 ~0 ~27 stained_hardened_clay 11  
fill ~16 ~0 ~28 ~23 ~0 ~28 stained_hardened_clay 11  
fill ~16 ~0 ~31 ~16 ~1 ~31 stained_hardened_clay 11  
fill ~16 ~0 ~32 ~16 ~0 ~33 stained_hardened_clay 11  
fill ~17 ~0 ~29 ~32 ~0 ~29 stained_hardened_clay 11  
fill ~17 ~0 ~30 ~30 ~0 ~30 stained_hardened_clay 11  
fill ~17 ~0 ~33 ~17 ~0 ~34 stained_hardened_clay 11  
fill ~18 ~0 ~31 ~29 ~0 ~31 stained_hardened_clay 11 
setblock ~18 ~0 ~35 stained_hardened_clay 11  
fill ~19 ~0 ~32 ~27 ~0 ~32 stained_hardened_clay 11  
fill ~19 ~0 ~33 ~20 ~0 ~33 stained_hardened_clay 11 
setblock ~19 ~0 ~36 stained_hardened_clay 11 
setblock ~20 ~0 ~34 stained_hardened_clay 11 
setblock ~21 ~0 ~26 stained_hardened_clay 11  
fill ~21 ~0 ~35 ~22 ~0 ~35 stained_hardened_clay 11  
fill ~22 ~0 ~33 ~26 ~0 ~33 stained_hardened_clay 11  
fill ~23 ~0 ~36 ~25 ~0 ~36 stained_hardened_clay 11  
fill ~26 ~0 ~1 ~33 ~0 ~1 wool 7  
fill ~26 ~0 ~2 ~33 ~0 ~2 wool 7  
fill ~26 ~0 ~3 ~33 ~0 ~3 wool 7  
fill ~26 ~0 ~35 ~27 ~0 ~35 stained_hardened_clay 11  
fill ~27 ~0 ~0 ~32 ~0 ~0 wool 7  
fill ~27 ~0 ~4 ~32 ~0 ~4 wool 7  
fill ~28 ~0 ~-1 ~32 ~0 ~-1 wool 7  
fill ~28 ~0 ~26 ~29 ~0 ~26 stained_hardened_clay 11  
fill ~28 ~0 ~28 ~30 ~0 ~28 stained_hardened_clay 11 
setblock ~28 ~0 ~34 stained_hardened_clay 11 
setblock ~29 ~0 ~33 stained_hardened_clay 11 
setblock ~30 ~0 ~25 stained_hardened_clay 11 
setblock ~31 ~0 ~27 stained_hardened_clay 11  
fill ~32 ~0 ~26 ~35 ~0 ~26 stained_hardened_clay 11  
fill ~32 ~0 ~28 ~34 ~0 ~28 stained_hardened_clay 11  
fill ~35 ~0 ~27 ~36 ~0 ~27 stained_hardened_clay 11 
setblock ~37 ~0 ~28 stained_hardened_clay 11  
fill ~38 ~0 ~29 ~38 ~0 ~30 stained_hardened_clay 11  
fill ~39 ~0 ~30 ~39 ~0 ~33 stained_hardened_clay 11  
fill ~44 ~0 ~23 ~50 ~0 ~23 wool 7  
fill ~44 ~0 ~24 ~51 ~0 ~24 wool 7  
fill ~44 ~0 ~25 ~51 ~0 ~25 wool 7  
fill ~45 ~0 ~22 ~47 ~0 ~22 wool 7  
fill ~45 ~0 ~26 ~51 ~0 ~26 wool 7  
fill ~48 ~0 ~27 ~50 ~0 ~27 wool 7  
fill ~9 ~1 ~24 ~9 ~2 ~24 stained_hardened_clay 11  
fill ~9 ~1 ~27 ~9 ~1 ~28 stained_hardened_clay 11  
fill ~11 ~1 ~24 ~11 ~2 ~24 stained_hardened_clay 11  
fill ~11 ~1 ~25 ~11 ~2 ~25 stained_hardened_clay 11  
fill ~11 ~1 ~26 ~12 ~1 ~26 stained_hardened_clay 11  
fill ~12 ~1 ~23 ~15 ~1 ~23 stained_hardened_clay 11 
setblock ~12 ~1 ~27 stained_hardened_clay 11  
fill ~13 ~1 ~24 ~17 ~1 ~24 stained_hardened_clay 11  
fill ~14 ~1 ~25 ~18 ~1 ~25 stained_hardened_clay 11  
fill ~14 ~1 ~26 ~19 ~1 ~26 stained_hardened_clay 11  
fill ~14 ~1 ~29 ~15 ~1 ~29 stained_hardened_clay 11  
fill ~15 ~1 ~27 ~21 ~1 ~27 stained_hardened_clay 11  
fill ~15 ~1 ~28 ~22 ~1 ~28 stained_hardened_clay 11  
fill ~15 ~1 ~30 ~16 ~1 ~30 stained_hardened_clay 11  
fill ~15 ~1 ~31 ~15 ~1 ~23 stained_hardened_clay 11  
fill ~17 ~1 ~23 ~17 ~2 ~23 stained_hardened_clay 11  
fill ~17 ~1 ~29 ~23 ~1 ~29 stained_hardened_clay 11  
fill ~18 ~1 ~30 ~21 ~1 ~30 stained_hardened_clay 11  
fill ~19 ~1 ~31 ~25 ~1 ~31 stained_hardened_clay 11  
fill ~19 ~1 ~32 ~19 ~0 ~32 stained_hardened_clay 11 
setblock ~23 ~1 ~32 stained_hardened_clay 11  
fill ~24 ~1 ~30 ~25 ~1 ~30 stained_hardened_clay 11  
fill ~25 ~1 ~2 ~30 ~1 ~2 wool 7  
fill ~25 ~1 ~3 ~31 ~1 ~3 wool 7  
fill ~25 ~1 ~32 ~26 ~1 ~32 stained_hardened_clay 11  
fill ~26 ~1 ~0 ~33 ~1 ~0 wool 7  
fill ~26 ~1 ~1 ~33 ~1 ~1 wool 7  
fill ~26 ~1 ~4 ~29 ~1 ~4 wool 7 
setblock ~27 ~1 ~5 stained_hardened_clay 9 
setblock ~27 ~1 ~31 stained_hardened_clay 11  
fill ~28 ~1 ~-1 ~32 ~1 ~-1 wool 7  
fill ~28 ~1 ~5 ~29 ~1 ~5 wool 7  
fill ~28 ~1 ~29 ~28 ~1 ~30 stained_hardened_clay 11 
setblock ~29 ~1 ~30 stained_hardened_clay 11  
fill ~30 ~1 ~4 ~30 ~3 ~4 stained_hardened_clay 9  
fill ~30 ~1 ~5 ~30 ~1 ~4 stained_hardened_clay 9 
setblock ~30 ~1 ~29 stained_hardened_clay 11  
fill ~31 ~1 ~2 ~31 ~2 ~2 snow 0  
fill ~31 ~1 ~4 ~32 ~1 ~4 wool 7 
setblock ~32 ~1 ~2 wool 7  
fill ~32 ~1 ~3 ~32 ~3 ~3 stained_hardened_clay 9  
fill ~33 ~1 ~2 ~33 ~2 ~2 stained_hardened_clay 9  
fill ~33 ~1 ~3 ~33 ~2 ~3 wool 7  
fill ~43 ~1 ~23 ~51 ~1 ~23 wool 7  
fill ~43 ~1 ~24 ~52 ~1 ~24 wool 7  
fill ~43 ~1 ~25 ~52 ~1 ~25 wool 7  
fill ~44 ~1 ~22 ~44 ~3 ~22 stained_hardened_clay 9  
fill ~44 ~1 ~26 ~52 ~1 ~26 wool 7  
fill ~45 ~1 ~22 ~49 ~1 ~22 wool 7  
fill ~46 ~1 ~27 ~51 ~1 ~27 wool 7  
fill ~8 ~2 ~22 ~8 ~3 ~22 stained_hardened_clay 11  
fill ~8 ~2 ~23 ~9 ~2 ~23 stained_hardened_clay 11  
fill ~8 ~2 ~25 ~8 ~3 ~25 stained_hardened_clay 11  
fill ~8 ~2 ~26 ~9 ~2 ~26 stained_hardened_clay 11  
fill ~11 ~2 ~22 ~11 ~3 ~22 stained_hardened_clay 11  
fill ~13 ~2 ~22 ~17 ~2 ~22 stained_hardened_clay 11  
fill ~13 ~2 ~23 ~17 ~2 ~23 stained_hardened_clay 11  
fill ~13 ~2 ~24 ~16 ~2 ~24 stained_hardened_clay 11  
fill ~13 ~2 ~25 ~17 ~2 ~25 stained_hardened_clay 11  
fill ~13 ~2 ~28 ~21 ~2 ~28 stained_hardened_clay 11  
fill ~14 ~2 ~26 ~19 ~2 ~26 stained_hardened_clay 11  
fill ~14 ~2 ~27 ~19 ~2 ~27 stained_hardened_clay 11  
fill ~15 ~2 ~19 ~16 ~2 ~19 stained_hardened_clay 11 
setblock ~15 ~2 ~29 stained_hardened_clay 11  
fill ~17 ~2 ~29 ~20 ~2 ~29 stained_hardened_clay 11  
fill ~18 ~2 ~30 ~19 ~2 ~30 stained_hardened_clay 11  
fill ~20 ~2 ~25 ~21 ~2 ~25 stained_hardened_clay 11  
fill ~20 ~2 ~31 ~21 ~2 ~31 stained_hardened_clay 11 
setblock ~21 ~2 ~26 stained_hardened_clay 11  
fill ~25 ~2 ~1 ~32 ~2 ~1 wool 7  
fill ~25 ~2 ~2 ~25 ~4 ~2 stained_hardened_clay 9  
fill ~25 ~2 ~3 ~25 ~4 ~3 stained_hardened_clay 9  
fill ~25 ~2 ~4 ~32 ~2 ~4 stained_hardened_clay 9  
fill ~26 ~2 ~0 ~32 ~2 ~0 wool 7  
fill ~26 ~2 ~2 ~30 ~2 ~2 wool 7  
fill ~26 ~2 ~3 ~28 ~2 ~3 wool 7  
fill ~26 ~2 ~5 ~26 ~3 ~5 stained_hardened_clay 9  
fill ~27 ~2 ~-1 ~31 ~2 ~-1 wool 7 
setblock ~27 ~2 ~5 wool 7  
fill ~28 ~2 ~5 ~29 ~2 ~5 stained_hardened_clay 9  
fill ~29 ~2 ~3 ~29 ~3 ~3 stained_hardened_clay 9 
setblock ~30 ~2 ~3 snow 0  
fill ~31 ~2 ~3 ~31 ~4 ~3 stained_hardened_clay 9 
setblock ~32 ~2 ~2 snow 0 
setblock ~33 ~2 ~1 stained_hardened_clay 9  
fill ~43 ~2 ~23 ~45 ~2 ~23 stained_hardened_clay 9  
fill ~43 ~2 ~24 ~43 ~4 ~24 stained_hardened_clay 9  
fill ~43 ~2 ~25 ~52 ~2 ~25 wool 7  
fill ~44 ~2 ~24 ~52 ~2 ~24 wool 7  
fill ~44 ~2 ~26 ~52 ~2 ~26 wool 7  
fill ~45 ~2 ~22 ~45 ~6 ~22 stained_hardened_clay 9  
fill ~45 ~2 ~27 ~51 ~2 ~27 wool 7  
fill ~46 ~2 ~22 ~49 ~2 ~22 wool 7  
fill ~46 ~2 ~23 ~51 ~2 ~23 wool 7  
fill ~6 ~3 ~16 ~6 ~4 ~16 stained_hardened_clay 11  
fill ~6 ~3 ~17 ~6 ~3 ~16 stained_hardened_clay 11  
fill ~7 ~3 ~20 ~8 ~3 ~20 stained_hardened_clay 11 
setblock ~7 ~3 ~25 stained_hardened_clay 11 
setblock ~8 ~3 ~21 stained_hardened_clay 11 
setblock ~8 ~3 ~24 stained_hardened_clay 11  
fill ~8 ~3 ~26 ~8 ~2 ~26 stained_hardened_clay 11 
setblock ~10 ~3 ~24 stained_hardened_clay 11  
fill ~11 ~3 ~21 ~11 ~16 ~21 stained_hardened_clay 11  
fill ~12 ~3 ~26 ~18 ~3 ~26 stained_hardened_clay 11  
fill ~13 ~3 ~21 ~17 ~3 ~21 stained_hardened_clay 11  
fill ~13 ~3 ~22 ~16 ~3 ~22 stained_hardened_clay 11  
fill ~13 ~3 ~23 ~16 ~3 ~23 stained_hardened_clay 11  
fill ~13 ~3 ~24 ~16 ~3 ~24 stained_hardened_clay 11  
fill ~13 ~3 ~25 ~17 ~3 ~25 stained_hardened_clay 11  
fill ~13 ~3 ~27 ~19 ~3 ~27 stained_hardened_clay 11  
fill ~14 ~3 ~18 ~14 ~4 ~18 stained_hardened_clay 11  
fill ~14 ~3 ~19 ~15 ~3 ~19 stained_hardened_clay 11  
fill ~14 ~3 ~20 ~14 ~13 ~20 stained_hardened_clay 11  
fill ~16 ~3 ~28 ~19 ~3 ~28 stained_hardened_clay 11  
fill ~18 ~3 ~29 ~19 ~3 ~29 stained_hardened_clay 11  
fill ~19 ~3 ~23 ~19 ~4 ~23 stained_hardened_clay 11  
fill ~19 ~3 ~24 ~20 ~3 ~24 stained_hardened_clay 11 
setblock ~19 ~3 ~30 stained_hardened_clay 11  
fill ~20 ~3 ~25 ~20 ~2 ~25 stained_hardened_clay 11  
fill ~25 ~3 ~1 ~26 ~3 ~1 stained_hardened_clay 9  
fill ~25 ~3 ~4 ~27 ~3 ~4 stained_hardened_clay 9  
fill ~26 ~3 ~0 ~26 ~1 ~0 wool 7  
fill ~26 ~3 ~2 ~26 ~3 ~5 stained_hardened_clay 9  
fill ~27 ~3 ~-1 ~30 ~3 ~-1 wool 7  
fill ~27 ~3 ~0 ~27 ~5 ~0 stained_hardened_clay 9  
fill ~27 ~3 ~1 ~29 ~3 ~1 wool 7  
fill ~27 ~3 ~2 ~29 ~3 ~2 wool 7 
setblock ~27 ~3 ~3 stained_hardened_clay 9  
fill ~27 ~3 ~5 ~29 ~3 ~5 stained_hardened_clay 9 
setblock ~28 ~3 ~0 wool 7 
setblock ~28 ~3 ~3 wool 7 
setblock ~28 ~3 ~4 wool 8  
fill ~29 ~3 ~0 ~29 ~5 ~0 stained_hardened_clay 9 
setblock ~29 ~3 ~4 stained_hardened_clay 9  
fill ~30 ~3 ~0 ~31 ~3 ~0 wool 7  
fill ~30 ~3 ~1 ~30 ~4 ~1 stained_hardened_clay 9  
fill ~30 ~3 ~2 ~32 ~3 ~2 stained_hardened_clay 9  
fill ~30 ~3 ~3 ~30 ~3 ~1 stained_hardened_clay 9 
setblock ~31 ~3 ~1 wool 7 
setblock ~32 ~3 ~1 stained_hardened_clay 9  
fill ~43 ~3 ~23 ~45 ~3 ~23 stained_hardened_clay 9  
fill ~43 ~3 ~25 ~44 ~3 ~25 stained_hardened_clay 9  
fill ~43 ~3 ~26 ~44 ~3 ~26 stained_hardened_clay 9  
fill ~44 ~3 ~24 ~44 ~4 ~24 stained_hardened_clay 9 
setblock ~44 ~3 ~27 stained_hardened_clay 9  
fill ~45 ~3 ~24 ~51 ~3 ~24 wool 7  
fill ~45 ~3 ~25 ~52 ~3 ~25 wool 7  
fill ~45 ~3 ~26 ~51 ~3 ~26 wool 7  
fill ~45 ~3 ~27 ~46 ~3 ~27 wool 7 
setblock ~46 ~3 ~22 stained_hardened_clay 9  
fill ~46 ~3 ~23 ~49 ~3 ~23 wool 7  
fill ~47 ~3 ~22 ~49 ~3 ~22 wool 7 
setblock ~47 ~3 ~27 stained_hardened_clay 9  
fill ~48 ~3 ~27 ~50 ~3 ~27 wool 7  
fill ~50 ~3 ~23 ~51 ~3 ~23 stained_hardened_clay 9  
fill ~6 ~4 ~15 ~6 ~5 ~15 stained_hardened_clay 11  
fill ~6 ~4 ~24 ~7 ~4 ~24 stained_hardened_clay 11  
fill ~6 ~4 ~26 ~6 ~5 ~26 stained_hardened_clay 11  
fill ~7 ~4 ~19 ~7 ~6 ~19 stained_hardened_clay 11  
fill ~7 ~4 ~20 ~7 ~5 ~20 stained_hardened_clay 11  
fill ~7 ~4 ~23 ~7 ~6 ~23 stained_hardened_clay 11 
setblock ~7 ~4 ~27 stained_hardened_clay 11 
setblock ~9 ~4 ~24 stained_hardened_clay 11  
fill ~12 ~4 ~21 ~16 ~4 ~21 stained_hardened_clay 11  
fill ~12 ~4 ~22 ~18 ~4 ~22 stained_hardened_clay 11  
fill ~12 ~4 ~23 ~19 ~4 ~23 stained_hardened_clay 11  
fill ~12 ~4 ~25 ~18 ~4 ~25 stained_hardened_clay 11  
fill ~13 ~4 ~17 ~14 ~4 ~17 stained_hardened_clay 11  
fill ~13 ~4 ~18 ~13 ~4 ~17 stained_hardened_clay 11  
fill ~13 ~4 ~20 ~13 ~16 ~20 stained_hardened_clay 11  
fill ~13 ~4 ~24 ~17 ~4 ~24 stained_hardened_clay 11  
fill ~14 ~4 ~26 ~18 ~4 ~26 stained_hardened_clay 11  
fill ~15 ~4 ~20 ~15 ~11 ~20 stained_hardened_clay 11  
fill ~15 ~4 ~27 ~19 ~4 ~27 stained_hardened_clay 11  
fill ~17 ~4 ~28 ~19 ~4 ~28 stained_hardened_clay 11  
fill ~18 ~4 ~29 ~18 ~0 ~29 stained_hardened_clay 11  
fill ~18 ~4 ~30 ~18 ~4 ~25 stained_hardened_clay 11  
fill ~25 ~4 ~1 ~27 ~4 ~1 stained_hardened_clay 9  
fill ~25 ~4 ~4 ~27 ~4 ~4 wool 8 
setblock ~26 ~4 ~0 stained_hardened_clay 9  
fill ~26 ~4 ~2 ~26 ~6 ~2 wool 8  
fill ~26 ~4 ~3 ~30 ~4 ~3 wool 8  
fill ~26 ~4 ~5 ~27 ~4 ~5 wool 8  
fill ~27 ~4 ~-1 ~28 ~4 ~-1 stained_hardened_clay 9 
setblock ~27 ~4 ~2 snow 0 
setblock ~28 ~4 ~0 stained_hardened_clay 9  
fill ~28 ~4 ~1 ~28 ~6 ~1 wool 8  
fill ~28 ~4 ~2 ~30 ~4 ~2 wool 8  
fill ~28 ~4 ~4 ~28 ~4 ~5 snow 0 
setblock ~29 ~4 ~1 stained_hardened_clay 9  
fill ~29 ~4 ~4 ~29 ~5 ~4 wool 8 
setblock ~30 ~4 ~0 stained_hardened_clay 9  
fill ~31 ~4 ~1 ~31 ~4 ~3 stained_hardened_clay 9  
fill ~43 ~4 ~25 ~44 ~4 ~25 stone 0  
fill ~43 ~4 ~26 ~44 ~4 ~26 stone 0  
fill ~44 ~4 ~23 ~48 ~4 ~23 stained_hardened_clay 9  
fill ~44 ~4 ~27 ~45 ~4 ~27 stone 0 
setblock ~45 ~4 ~24 stained_hardened_clay 9  
fill ~45 ~4 ~25 ~51 ~4 ~25 wool 7 
setblock ~45 ~4 ~26 stained_hardened_clay 9  
fill ~46 ~4 ~22 ~47 ~4 ~22 wool 7  
fill ~46 ~4 ~24 ~47 ~4 ~24 wool 7  
fill ~46 ~4 ~26 ~47 ~4 ~26 wool 7  
fill ~46 ~4 ~27 ~47 ~4 ~27 wool 7 
setblock ~48 ~4 ~22 stained_hardened_clay 9  
fill ~48 ~4 ~24 ~49 ~4 ~24 stained_hardened_clay 9  
fill ~48 ~4 ~26 ~48 ~6 ~26 stained_hardened_clay 9  
fill ~48 ~4 ~27 ~49 ~4 ~27 stained_hardened_clay 9 
setblock ~49 ~4 ~23 wool 7 
setblock ~49 ~4 ~26 wool 7  
fill ~50 ~4 ~23 ~50 ~3 ~23 stained_hardened_clay 9 
setblock ~50 ~4 ~24 wool 7  
fill ~50 ~4 ~26 ~51 ~4 ~26 stained_hardened_clay 9 
setblock ~51 ~4 ~24 stained_hardened_clay 9  
fill ~5 ~5 ~15 ~5 ~12 ~15 stained_hardened_clay 11 
setblock ~6 ~5 ~23 stained_hardened_clay 11  
fill ~6 ~5 ~25 ~6 ~6 ~25 stained_hardened_clay 11  
fill ~8 ~5 ~25 ~8 ~6 ~25 stained_hardened_clay 11  
fill ~9 ~5 ~23 ~9 ~6 ~23 stained_hardened_clay 11  
fill ~10 ~5 ~21 ~10 ~13 ~21 stained_hardened_clay 11  
fill ~11 ~5 ~17 ~13 ~5 ~17 stained_hardened_clay 11  
fill ~11 ~5 ~25 ~18 ~5 ~25 stained_hardened_clay 11  
fill ~12 ~5 ~18 ~12 ~24 ~18 stained_hardened_clay 11  
fill ~12 ~5 ~19 ~16 ~5 ~19 stained_hardened_clay 11  
fill ~12 ~5 ~20 ~12 ~18 ~20 stained_hardened_clay 11  
fill ~12 ~5 ~21 ~16 ~5 ~21 stained_hardened_clay 11  
fill ~12 ~5 ~22 ~18 ~5 ~22 stained_hardened_clay 11  
fill ~12 ~5 ~23 ~17 ~5 ~23 stained_hardened_clay 11  
fill ~12 ~5 ~24 ~17 ~5 ~24 stained_hardened_clay 11  
fill ~14 ~5 ~26 ~18 ~5 ~26 stained_hardened_clay 11 
setblock ~15 ~5 ~18 stained_hardened_clay 11  
fill ~16 ~5 ~20 ~16 ~10 ~20 stained_hardened_clay 11  
fill ~16 ~5 ~27 ~18 ~5 ~27 stained_hardened_clay 11  
fill ~16 ~5 ~28 ~17 ~5 ~28 stained_hardened_clay 11  
fill ~25 ~5 ~2 ~25 ~5 ~3 wool 8  
fill ~26 ~5 ~1 ~26 ~6 ~1 wool 8  
fill ~26 ~5 ~3 ~30 ~5 ~3 wool 8 
setblock ~26 ~5 ~4 snow 0 
setblock ~27 ~5 ~1 snow 0  
fill ~27 ~5 ~2 ~30 ~5 ~2 wool 8  
fill ~27 ~5 ~4 ~29 ~5 ~4 wool 8  
fill ~27 ~5 ~5 ~28 ~5 ~5 wool 8 
setblock ~28 ~5 ~0 wool 8  
fill ~29 ~5 ~1 ~30 ~5 ~1 wool 8  
fill ~42 ~5 ~25 ~42 ~7 ~25 snow 0  
fill ~43 ~5 ~24 ~43 ~9 ~24 stone 0  
fill ~43 ~5 ~25 ~45 ~5 ~25 stone 0  
fill ~43 ~5 ~26 ~43 ~8 ~26 snow 0  
fill ~44 ~5 ~22 ~44 ~6 ~22 stained_hardened_clay 9  
fill ~44 ~5 ~23 ~49 ~5 ~23 stained_hardened_clay 9 
setblock ~44 ~5 ~24 snow 0  
fill ~44 ~5 ~26 ~46 ~5 ~26 stone 0  
fill ~44 ~5 ~27 ~46 ~5 ~27 stone 0  
fill ~45 ~5 ~24 ~45 ~9 ~24 stone 0  
fill ~46 ~5 ~22 ~47 ~5 ~22 stained_hardened_clay 9  
fill ~46 ~5 ~24 ~50 ~5 ~24 stained_hardened_clay 9 
setblock ~46 ~5 ~25 wool 7  
fill ~47 ~5 ~25 ~50 ~5 ~25 stained_hardened_clay 9  
fill ~47 ~5 ~26 ~47 ~5 ~27 stained_hardened_clay 9  
fill ~48 ~5 ~27 ~48 ~4 ~27 stained_hardened_clay 9 
setblock ~49 ~5 ~26 stained_hardened_clay 9 
setblock ~3 ~6 ~22 stained_hardened_clay 11  
fill ~5 ~6 ~22 ~7 ~6 ~22 stained_hardened_clay 11  
fill ~5 ~6 ~25 ~5 ~7 ~25 stained_hardened_clay 11  
fill ~6 ~6 ~21 ~6 ~7 ~21 stained_hardened_clay 11  
fill ~7 ~6 ~18 ~7 ~9 ~18 stained_hardened_clay 11  
fill ~9 ~6 ~17 ~9 ~6 ~20 stained_hardened_clay 11  
fill ~10 ~6 ~19 ~15 ~6 ~19 stained_hardened_clay 11  
fill ~10 ~6 ~20 ~16 ~6 ~20 stained_hardened_clay 11  
fill ~10 ~6 ~22 ~17 ~6 ~22 stained_hardened_clay 11  
fill ~11 ~6 ~17 ~11 ~35 ~17 stained_hardened_clay 11  
fill ~11 ~6 ~18 ~11 ~25 ~18 stained_hardened_clay 11  
fill ~11 ~6 ~23 ~17 ~6 ~23 stained_hardened_clay 11  
fill ~11 ~6 ~25 ~11 ~11 ~25 stained_hardened_clay 11  
fill ~12 ~6 ~21 ~17 ~6 ~21 stained_hardened_clay 11  
fill ~12 ~6 ~24 ~18 ~6 ~24 stained_hardened_clay 11  
fill ~13 ~6 ~18 ~14 ~6 ~18 stained_hardened_clay 11  
fill ~13 ~6 ~25 ~17 ~6 ~25 stained_hardened_clay 11  
fill ~15 ~6 ~26 ~17 ~6 ~26 stained_hardened_clay 11  
fill ~16 ~6 ~27 ~16 ~0 ~27 stained_hardened_clay 11  
fill ~26 ~6 ~3 ~26 ~10 ~3 snow 0  
fill ~26 ~6 ~4 ~27 ~6 ~4 wool 8  
fill ~27 ~6 ~1 ~27 ~6 ~4 wool 8  
fill ~28 ~6 ~2 ~30 ~6 ~2 wool 8  
fill ~28 ~6 ~3 ~30 ~6 ~3 wool 8  
fill ~28 ~6 ~4 ~28 ~7 ~4 snow 0  
fill ~29 ~6 ~1 ~30 ~6 ~1 wool 8 
setblock ~42 ~6 ~24 stone 0 
setblock ~42 ~6 ~26 stone 0  
fill ~43 ~6 ~23 ~45 ~6 ~23 stone 0  
fill ~43 ~6 ~25 ~46 ~6 ~25 stone 0  
fill ~43 ~6 ~27 ~46 ~6 ~27 stone 0  
fill ~44 ~6 ~24 ~44 ~7 ~24 stone 0  
fill ~44 ~6 ~26 ~47 ~6 ~26 stone 0  
fill ~46 ~6 ~23 ~48 ~6 ~23 stained_hardened_clay 9  
fill ~46 ~6 ~24 ~46 ~8 ~24 stone 0  
fill ~47 ~6 ~24 ~49 ~6 ~24 stained_hardened_clay 9  
fill ~47 ~6 ~25 ~49 ~6 ~25 stained_hardened_clay 9  
fill ~3 ~7 ~16 ~3 ~8 ~16 stained_hardened_clay 11  
fill ~3 ~7 ~21 ~3 ~8 ~21 stained_hardened_clay 11  
fill ~4 ~7 ~11 ~4 ~10 ~11 stained_hardened_clay 11  
fill ~5 ~7 ~20 ~5 ~8 ~20 stained_hardened_clay 11  
fill ~5 ~7 ~21 ~5 ~7 ~20 stained_hardened_clay 11  
fill ~5 ~7 ~24 ~5 ~9 ~24 stained_hardened_clay 11  
fill ~7 ~7 ~21 ~7 ~9 ~21 stained_hardened_clay 11  
fill ~7 ~7 ~22 ~7 ~7 ~21 stained_hardened_clay 11  
fill ~7 ~7 ~25 ~7 ~13 ~25 stained_hardened_clay 11  
fill ~8 ~7 ~15 ~8 ~8 ~15 stained_hardened_clay 11  
fill ~8 ~7 ~16 ~9 ~7 ~16 stained_hardened_clay 11  
fill ~8 ~7 ~17 ~8 ~7 ~15 stained_hardened_clay 11  
fill ~8 ~7 ~23 ~8 ~9 ~23 stained_hardened_clay 11  
fill ~8 ~7 ~24 ~8 ~8 ~24 stained_hardened_clay 11  
fill ~9 ~7 ~22 ~17 ~7 ~22 stained_hardened_clay 11  
fill ~10 ~7 ~17 ~10 ~63 ~17 stained_hardened_clay 11  
fill ~10 ~7 ~20 ~17 ~7 ~20 stained_hardened_clay 11  
fill ~11 ~7 ~16 ~11 ~62 ~16 stained_hardened_clay 11  
fill ~11 ~7 ~19 ~16 ~7 ~19 stained_hardened_clay 11  
fill ~11 ~7 ~23 ~17 ~7 ~23 stained_hardened_clay 11  
fill ~12 ~7 ~17 ~13 ~7 ~17 stained_hardened_clay 11  
fill ~12 ~7 ~21 ~17 ~7 ~21 stained_hardened_clay 11  
fill ~13 ~7 ~18 ~14 ~7 ~18 stained_hardened_clay 11  
fill ~13 ~7 ~24 ~16 ~7 ~24 stained_hardened_clay 11  
fill ~14 ~7 ~25 ~16 ~7 ~25 stained_hardened_clay 11  
fill ~14 ~7 ~26 ~15 ~7 ~26 stained_hardened_clay 11  
fill ~25 ~7 ~2 ~26 ~7 ~2 snow 0  
fill ~26 ~7 ~1 ~28 ~7 ~1 snow 0 
setblock ~26 ~7 ~4 snow 0  
fill ~27 ~7 ~2 ~30 ~7 ~2 wool 8 
setblock ~27 ~7 ~3 snow 0 
setblock ~27 ~7 ~4 wool 8  
fill ~28 ~7 ~3 ~29 ~7 ~3 wool 8  
fill ~29 ~7 ~1 ~29 ~9 ~1 wool 8  
fill ~41 ~7 ~24 ~41 ~8 ~24 stone 0  
fill ~41 ~7 ~25 ~41 ~8 ~25 stone 0  
fill ~41 ~7 ~26 ~41 ~7 ~24 stone 0 
setblock ~42 ~7 ~24 snow 0 
setblock ~42 ~7 ~26 snow 0  
fill ~43 ~7 ~23 ~46 ~7 ~23 stone 0  
fill ~43 ~7 ~25 ~47 ~7 ~25 stone 0  
fill ~43 ~7 ~27 ~43 ~8 ~27 stone 0  
fill ~44 ~7 ~26 ~44 ~7 ~27 snow 0  
fill ~45 ~7 ~26 ~46 ~7 ~26 stone 0 
setblock ~47 ~7 ~24 stone 0  
fill ~2 ~8 ~21 ~2 ~11 ~21 stained_hardened_clay 11  
fill ~3 ~8 ~15 ~3 ~11 ~15 stained_hardened_clay 11  
fill ~5 ~8 ~19 ~5 ~10 ~19 stained_hardened_clay 11  
fill ~7 ~8 ~14 ~8 ~8 ~14 stained_hardened_clay 11  
fill ~8 ~8 ~13 ~8 ~9 ~13 stained_hardened_clay 11  
fill ~9 ~8 ~21 ~9 ~8 ~22 stained_hardened_clay 11  
fill ~10 ~8 ~18 ~10 ~34 ~18 stained_hardened_clay 11  
fill ~10 ~8 ~19 ~15 ~8 ~19 stained_hardened_clay 11  
fill ~10 ~8 ~20 ~16 ~8 ~20 stained_hardened_clay 11  
fill ~11 ~8 ~15 ~11 ~61 ~15 stained_hardened_clay 11  
fill ~11 ~8 ~22 ~17 ~8 ~22 stained_hardened_clay 11  
fill ~12 ~8 ~16 ~12 ~59 ~16 stained_hardened_clay 11  
fill ~12 ~8 ~17 ~14 ~8 ~17 stained_hardened_clay 11  
fill ~12 ~8 ~21 ~17 ~8 ~21 stained_hardened_clay 11  
fill ~12 ~8 ~23 ~16 ~8 ~23 stained_hardened_clay 11  
fill ~13 ~8 ~18 ~15 ~8 ~18 stained_hardened_clay 11  
fill ~14 ~8 ~24 ~16 ~8 ~24 stained_hardened_clay 11  
fill ~14 ~8 ~25 ~14 ~11 ~25 stained_hardened_clay 11  
fill ~25 ~8 ~1 ~25 ~8 ~3 snow 0  
fill ~26 ~8 ~1 ~27 ~8 ~1 wool 8  
fill ~26 ~8 ~2 ~28 ~8 ~2 snow 0  
fill ~26 ~8 ~4 ~26 ~9 ~4 wool 8  
fill ~27 ~8 ~3 ~29 ~8 ~3 wool 8 
setblock ~27 ~8 ~4 snow 0 
setblock ~28 ~8 ~1 snow 0  
fill ~28 ~8 ~4 ~28 ~9 ~4 wool 8  
fill ~29 ~8 ~2 ~29 ~9 ~2 wool 8 
setblock ~40 ~8 ~24 wool 0 
setblock ~40 ~8 ~25 stone 0  
fill ~40 ~8 ~26 ~40 ~10 ~26 wool 8  
fill ~41 ~8 ~26 ~41 ~9 ~26 snow 0  
fill ~42 ~8 ~23 ~45 ~8 ~23 stone 0  
fill ~42 ~8 ~24 ~42 ~8 ~26 stone 0  
fill ~42 ~8 ~27 ~42 ~10 ~27 snow 0  
fill ~43 ~8 ~25 ~46 ~8 ~25 stone 0  
fill ~44 ~8 ~24 ~44 ~9 ~24 snow 0  
fill ~44 ~8 ~26 ~45 ~8 ~26 stone 0 
setblock ~44 ~8 ~27 snow 0  
fill ~1 ~9 ~13 ~1 ~10 ~13 stained_hardened_clay 11  
fill ~4 ~9 ~24 ~4 ~13 ~24 stained_hardened_clay 11  
fill ~5 ~9 ~18 ~5 ~10 ~18 stained_hardened_clay 11  
fill ~6 ~9 ~22 ~6 ~10 ~22 stained_hardened_clay 11  
fill ~7 ~9 ~13 ~7 ~12 ~13 stained_hardened_clay 11  
fill ~7 ~9 ~14 ~8 ~9 ~14 stained_hardened_clay 11  
fill ~7 ~9 ~17 ~7 ~57 ~17 stained_hardened_clay 11  
fill ~7 ~9 ~20 ~7 ~10 ~20 stained_hardened_clay 11  
fill ~7 ~9 ~23 ~7 ~13 ~23 stained_hardened_clay 11  
fill ~9 ~9 ~17 ~9 ~62 ~17 stained_hardened_clay 11  
fill ~9 ~9 ~18 ~9 ~48 ~18 stained_hardened_clay 11  
fill ~9 ~9 ~19 ~15 ~9 ~19 stained_hardened_clay 11  
fill ~9 ~9 ~20 ~16 ~9 ~20 stained_hardened_clay 11  
fill ~9 ~9 ~22 ~9 ~11 ~22 stained_hardened_clay 11  
fill ~10 ~9 ~16 ~10 ~61 ~16 stained_hardened_clay 11  
fill ~11 ~9 ~14 ~11 ~64 ~14 stained_hardened_clay 11  
fill ~11 ~9 ~22 ~16 ~9 ~22 stained_hardened_clay 11  
fill ~12 ~9 ~17 ~15 ~9 ~17 stained_hardened_clay 11  
fill ~12 ~9 ~21 ~16 ~9 ~21 stained_hardened_clay 11  
fill ~13 ~9 ~15 ~13 ~12 ~15 stained_hardened_clay 11  
fill ~13 ~9 ~16 ~14 ~9 ~16 stained_hardened_clay 11  
fill ~13 ~9 ~18 ~15 ~9 ~18 stained_hardened_clay 11  
fill ~13 ~9 ~23 ~15 ~9 ~23 stained_hardened_clay 11  
fill ~24 ~9 ~2 ~26 ~9 ~2 snow 0  
fill ~25 ~9 ~1 ~29 ~9 ~1 wool 8  
fill ~25 ~9 ~3 ~25 ~15 ~3 wool 8  
fill ~26 ~9 ~0 ~26 ~13 ~0 wool 8  
fill ~27 ~9 ~2 ~29 ~9 ~2 wool 8  
fill ~27 ~9 ~3 ~29 ~9 ~3 wool 8  
fill ~27 ~9 ~4 ~27 ~10 ~4 wool 8 
setblock ~39 ~9 ~25 wool 0  
fill ~40 ~9 ~24 ~40 ~9 ~25 snow 0 
setblock ~41 ~9 ~23 stone 0  
fill ~41 ~9 ~24 ~41 ~10 ~24 wool 0  
fill ~41 ~9 ~25 ~41 ~10 ~25 wool 8 
setblock ~41 ~9 ~27 wool 8  
fill ~42 ~9 ~23 ~43 ~9 ~23 snow 0 
setblock ~42 ~9 ~24 wool 8  
fill ~42 ~9 ~25 ~44 ~9 ~25 wool 0  
fill ~42 ~9 ~26 ~43 ~9 ~26 wool 8 
setblock ~44 ~9 ~23 stone 0 
setblock ~44 ~9 ~26 snow 0 
setblock ~45 ~9 ~25 stone 0  
fill ~1 ~10 ~12 ~1 ~14 ~12 stained_hardened_clay 11  
fill ~2 ~10 ~10 ~2 ~12 ~10 stained_hardened_clay 11  
fill ~4 ~10 ~10 ~4 ~13 ~10 stained_hardened_clay 11  
fill ~4 ~10 ~18 ~4 ~11 ~18 stained_hardened_clay 11  
fill ~6 ~10 ~21 ~6 ~13 ~21 stained_hardened_clay 11  
fill ~7 ~10 ~19 ~16 ~10 ~19 stained_hardened_clay 11  
fill ~8 ~10 ~17 ~8 ~61 ~17 stained_hardened_clay 11  
fill ~8 ~10 ~18 ~8 ~56 ~18 stained_hardened_clay 11  
fill ~9 ~10 ~15 ~13 ~10 ~15 stained_hardened_clay 11  
fill ~9 ~10 ~16 ~9 ~63 ~16 stained_hardened_clay 11  
fill ~9 ~10 ~20 ~16 ~10 ~20 stained_hardened_clay 11  
fill ~11 ~10 ~22 ~15 ~10 ~22 stained_hardened_clay 11  
fill ~12 ~10 ~17 ~15 ~10 ~17 stained_hardened_clay 11  
fill ~12 ~10 ~21 ~16 ~10 ~21 stained_hardened_clay 11  
fill ~13 ~10 ~14 ~13 ~11 ~14 stained_hardened_clay 11  
fill ~13 ~10 ~16 ~15 ~10 ~16 stained_hardened_clay 11  
fill ~13 ~10 ~18 ~16 ~10 ~18 stained_hardened_clay 11  
fill ~14 ~10 ~23 ~14 ~12 ~23 stained_hardened_clay 11  
fill ~15 ~10 ~15 ~15 ~11 ~15 stained_hardened_clay 11  
fill ~24 ~10 ~1 ~28 ~10 ~1 wool 8  
fill ~24 ~10 ~2 ~24 ~13 ~2 wool 8  
fill ~24 ~10 ~3 ~24 ~13 ~3 wool 8 
setblock ~25 ~10 ~2 snow 0  
fill ~25 ~10 ~4 ~25 ~13 ~4 wool 8  
fill ~26 ~10 ~2 ~28 ~10 ~2 wool 8 
setblock ~26 ~10 ~4 snow 0  
fill ~27 ~10 ~0 ~27 ~11 ~0 wool 8 
setblock ~27 ~10 ~3 snow 0  
fill ~28 ~10 ~3 ~28 ~11 ~3 wool 8  
fill ~38 ~10 ~24 ~38 ~12 ~24 wool 8 
setblock ~38 ~10 ~25 snow 0  
fill ~39 ~10 ~24 ~41 ~10 ~24 wool 0 
setblock ~39 ~10 ~25 wool 8  
fill ~39 ~10 ~26 ~39 ~12 ~26 wool 0 
setblock ~40 ~10 ~23 wool 8 
setblock ~40 ~10 ~25 snow 0 
setblock ~40 ~10 ~27 wool 0  
fill ~41 ~10 ~23 ~42 ~10 ~23 snow 0  
fill ~41 ~10 ~26 ~42 ~10 ~26 wool 8 
setblock ~41 ~10 ~27 snow 0 
setblock ~42 ~10 ~24 snow 0  
fill ~42 ~10 ~25 ~43 ~10 ~25 wool 0 
setblock ~43 ~10 ~24 wool 8 
setblock ~43 ~10 ~26 wool 0 
setblock ~44 ~10 ~24 wool 0 
setblock ~44 ~10 ~25 stone 0  
fill ~1 ~11 ~15 ~1 ~13 ~15 stained_hardened_clay 11  
fill ~1 ~11 ~21 ~1 ~20 ~21 stained_hardened_clay 11  
fill ~3 ~11 ~14 ~3 ~15 ~14 stained_hardened_clay 11  
fill ~3 ~11 ~19 ~3 ~12 ~19 stained_hardened_clay 11  
fill ~3 ~11 ~20 ~4 ~11 ~20 stained_hardened_clay 11  
fill ~4 ~11 ~17 ~4 ~13 ~17 stained_hardened_clay 11  
fill ~7 ~11 ~19 ~16 ~11 ~19 stained_hardened_clay 11  
fill ~8 ~11 ~16 ~8 ~62 ~16 stained_hardened_clay 11  
fill ~8 ~11 ~22 ~8 ~14 ~22 stained_hardened_clay 11  
fill ~9 ~11 ~15 ~15 ~11 ~15 stained_hardened_clay 11  
fill ~9 ~11 ~20 ~15 ~11 ~20 stained_hardened_clay 11  
fill ~10 ~11 ~12 ~10 ~65 ~12 stained_hardened_clay 11  
fill ~10 ~11 ~13 ~11 ~11 ~13 stained_hardened_clay 11  
fill ~10 ~11 ~14 ~10 ~61 ~14 stained_hardened_clay 11  
fill ~11 ~11 ~24 ~11 ~14 ~24 stained_hardened_clay 11  
fill ~12 ~11 ~14 ~12 ~64 ~14 stained_hardened_clay 11  
fill ~12 ~11 ~17 ~15 ~11 ~17 stained_hardened_clay 11  
fill ~12 ~11 ~21 ~14 ~11 ~21 stained_hardened_clay 11  
fill ~12 ~11 ~22 ~13 ~11 ~22 stained_hardened_clay 11  
fill ~13 ~11 ~13 ~13 ~13 ~13 stained_hardened_clay 11  
fill ~13 ~11 ~16 ~14 ~11 ~16 stained_hardened_clay 11  
fill ~13 ~11 ~18 ~16 ~11 ~18 stained_hardened_clay 11  
fill ~13 ~11 ~24 ~13 ~13 ~24 stained_hardened_clay 11  
fill ~14 ~11 ~14 ~14 ~26 ~14 stained_hardened_clay 11  
fill ~16 ~11 ~16 ~16 ~16 ~16 stained_hardened_clay 11  
fill ~23 ~11 ~2 ~23 ~14 ~2 wool 8  
fill ~24 ~11 ~1 ~28 ~11 ~1 wool 8  
fill ~25 ~11 ~0 ~25 ~16 ~0 wool 8  
fill ~25 ~11 ~2 ~28 ~11 ~2 wool 8  
fill ~26 ~11 ~3 ~28 ~11 ~3 wool 8  
fill ~26 ~11 ~4 ~26 ~13 ~4 wool 8 
setblock ~37 ~11 ~24 wool 8 
setblock ~38 ~11 ~23 wool 0 
setblock ~38 ~11 ~25 wool 8  
fill ~39 ~11 ~22 ~39 ~11 ~23 wool 8  
fill ~39 ~11 ~24 ~39 ~12 ~24 wool 0  
fill ~39 ~11 ~25 ~39 ~12 ~25 wool 0  
fill ~40 ~11 ~23 ~41 ~11 ~23 snow 0  
fill ~40 ~11 ~24 ~40 ~15 ~24 snow 0 
setblock ~40 ~11 ~25 wool 8  
fill ~40 ~11 ~26 ~41 ~11 ~26 wool 0 
setblock ~41 ~11 ~24 wool 8  
fill ~41 ~11 ~25 ~43 ~11 ~25 wool 0 
setblock ~41 ~11 ~27 wool 0 
setblock ~42 ~11 ~23 wool 8  
fill ~42 ~11 ~24 ~43 ~11 ~24 wool 0 
setblock ~42 ~11 ~26 wool 8 
setblock ~43 ~11 ~26 snow 0  
fill ~1 ~12 ~10 ~1 ~15 ~10 stained_hardened_clay 11  
fill ~3 ~12 ~18 ~3 ~14 ~18 stained_hardened_clay 11  
fill ~6 ~12 ~15 ~6 ~63 ~15 stained_hardened_clay 11  
fill ~6 ~12 ~17 ~6 ~13 ~17 stained_hardened_clay 11  
fill ~6 ~12 ~25 ~6 ~16 ~25 stained_hardened_clay 11  
fill ~7 ~12 ~12 ~7 ~62 ~12 stained_hardened_clay 11  
fill ~7 ~12 ~16 ~7 ~62 ~16 stained_hardened_clay 11  
fill ~7 ~12 ~18 ~7 ~56 ~18 stained_hardened_clay 11  
fill ~7 ~12 ~19 ~16 ~12 ~19 stained_hardened_clay 11  
fill ~8 ~12 ~15 ~13 ~12 ~15 stained_hardened_clay 11  
fill ~9 ~12 ~14 ~9 ~64 ~14 stained_hardened_clay 11  
fill ~9 ~12 ~20 ~14 ~12 ~20 stained_hardened_clay 11  
fill ~10 ~12 ~13 ~11 ~12 ~13 stained_hardened_clay 11  
fill ~12 ~12 ~17 ~16 ~12 ~17 stained_hardened_clay 11  
fill ~12 ~12 ~21 ~14 ~12 ~21 stained_hardened_clay 11  
fill ~13 ~12 ~16 ~14 ~12 ~16 stained_hardened_clay 11  
fill ~13 ~12 ~18 ~16 ~12 ~18 stained_hardened_clay 11  
fill ~14 ~12 ~22 ~14 ~15 ~22 stained_hardened_clay 11  
fill ~22 ~12 ~2 ~22 ~17 ~2 wool 8  
fill ~23 ~12 ~1 ~27 ~12 ~1 wool 8  
fill ~23 ~12 ~3 ~23 ~13 ~3 wool 8  
fill ~24 ~12 ~4 ~24 ~17 ~4 wool 8  
fill ~25 ~12 ~2 ~28 ~12 ~2 wool 8  
fill ~26 ~12 ~3 ~27 ~12 ~3 wool 8 
setblock ~37 ~12 ~24 wool 0 
setblock ~38 ~12 ~23 wool 8  
fill ~38 ~12 ~25 ~38 ~13 ~25 wool 0  
fill ~39 ~12 ~22 ~40 ~12 ~22 snow 0  
fill ~39 ~12 ~23 ~40 ~12 ~23 snow 0  
fill ~40 ~12 ~25 ~43 ~12 ~25 snow 0 
setblock ~40 ~12 ~26 wool 8 
setblock ~41 ~12 ~23 wool 8  
fill ~41 ~12 ~24 ~41 ~14 ~24 snow 0 
setblock ~41 ~12 ~26 wool 0 
setblock ~42 ~12 ~23 snow 0  
fill ~42 ~12 ~24 ~42 ~13 ~24 wool 8 
setblock ~42 ~12 ~26 snow 0 
setblock ~43 ~12 ~24 wool 0  
fill ~1 ~13 ~14 ~1 ~19 ~14 stained_hardened_clay 11  
fill ~3 ~13 ~10 ~3 ~16 ~10 stained_hardened_clay 11  
fill ~4 ~13 ~16 ~4 ~14 ~16 stained_hardened_clay 11  
fill ~4 ~13 ~23 ~4 ~16 ~23 stained_hardened_clay 11  
fill ~6 ~13 ~12 ~6 ~14 ~12 stained_hardened_clay 11 
setblock ~6 ~13 ~18 stained_hardened_clay 11  
fill ~6 ~13 ~20 ~6 ~15 ~20 stained_hardened_clay 11  
fill ~8 ~13 ~14 ~8 ~62 ~14 stained_hardened_clay 11  
fill ~8 ~13 ~15 ~12 ~13 ~15 stained_hardened_clay 11  
fill ~8 ~13 ~19 ~15 ~13 ~19 stained_hardened_clay 11  
fill ~9 ~13 ~12 ~9 ~14 ~12 stained_hardened_clay 11  
fill ~9 ~13 ~13 ~11 ~13 ~13 stained_hardened_clay 11  
fill ~9 ~13 ~20 ~14 ~13 ~20 stained_hardened_clay 11  
fill ~12 ~13 ~17 ~13 ~13 ~17 stained_hardened_clay 11  
fill ~12 ~13 ~21 ~13 ~13 ~21 stained_hardened_clay 11  
fill ~12 ~13 ~24 ~12 ~16 ~24 stained_hardened_clay 11  
fill ~13 ~13 ~12 ~13 ~15 ~12 stained_hardened_clay 11  
fill ~13 ~13 ~16 ~13 ~9 ~16 stained_hardened_clay 11  
fill ~13 ~13 ~18 ~15 ~13 ~18 stained_hardened_clay 11  
fill ~15 ~13 ~17 ~16 ~13 ~17 stained_hardened_clay 11 
setblock ~16 ~13 ~15 stained_hardened_clay 11  
fill ~23 ~13 ~1 ~27 ~13 ~1 wool 8  
fill ~23 ~13 ~4 ~23 ~16 ~4 wool 8  
fill ~24 ~13 ~0 ~24 ~18 ~0 wool 8  
fill ~25 ~13 ~2 ~27 ~13 ~2 wool 8  
fill ~26 ~13 ~3 ~27 ~13 ~3 wool 8  
fill ~36 ~13 ~24 ~41 ~13 ~24 snow 0 
setblock ~37 ~13 ~23 snow 0 
setblock ~37 ~13 ~25 wool 0  
fill ~38 ~13 ~22 ~38 ~13 ~23 wool 0 
setblock ~38 ~13 ~26 wool 0  
fill ~39 ~13 ~22 ~39 ~14 ~22 snow 0  
fill ~39 ~13 ~23 ~41 ~13 ~23 snow 0  
fill ~39 ~13 ~25 ~41 ~13 ~25 snow 0  
fill ~39 ~13 ~26 ~41 ~13 ~26 snow 0 
setblock ~40 ~13 ~22 wool 8 
setblock ~42 ~13 ~25 wool 0  
fill ~0 ~14 ~12 ~0 ~20 ~12 stained_hardened_clay 11  
fill ~0 ~14 ~17 ~0 ~18 ~17 stained_hardened_clay 11  
fill ~3 ~14 ~17 ~3 ~17 ~17 stained_hardened_clay 11  
fill ~4 ~14 ~15 ~4 ~15 ~15 stained_hardened_clay 11  
fill ~5 ~14 ~17 ~5 ~15 ~17 stained_hardened_clay 11  
fill ~6 ~14 ~8 ~6 ~16 ~8 stained_hardened_clay 11  
fill ~7 ~14 ~15 ~12 ~14 ~15 stained_hardened_clay 11  
fill ~7 ~14 ~19 ~15 ~14 ~19 stained_hardened_clay 11  
fill ~7 ~14 ~22 ~7 ~15 ~22 stained_hardened_clay 11  
fill ~8 ~14 ~11 ~9 ~14 ~11 stained_hardened_clay 11  
fill ~8 ~14 ~20 ~13 ~14 ~20 stained_hardened_clay 11  
fill ~9 ~14 ~13 ~11 ~14 ~13 stained_hardened_clay 11  
fill ~10 ~14 ~24 ~10 ~19 ~24 stained_hardened_clay 11 
setblock ~11 ~14 ~12 stained_hardened_clay 11  
fill ~12 ~14 ~7 ~12 ~17 ~7 stained_hardened_clay 11  
fill ~12 ~14 ~17 ~15 ~14 ~17 stained_hardened_clay 11  
fill ~12 ~14 ~21 ~12 ~15 ~21 stained_hardened_clay 11  
fill ~13 ~14 ~18 ~14 ~14 ~18 stained_hardened_clay 11  
fill ~22 ~14 ~1 ~24 ~14 ~1 wool 8  
fill ~22 ~14 ~3 ~23 ~14 ~3 snow 0 
setblock ~25 ~14 ~4 snow 0  
fill ~26 ~14 ~1 ~26 ~16 ~1 wool 8  
fill ~26 ~14 ~2 ~27 ~14 ~2 wool 8  
fill ~26 ~14 ~3 ~26 ~17 ~3 wool 8 
setblock ~36 ~14 ~23 wool 8  
fill ~36 ~14 ~24 ~36 ~17 ~24 wool 0  
fill ~36 ~14 ~25 ~36 ~14 ~24 wool 0 
setblock ~37 ~14 ~22 wool 8  
fill ~37 ~14 ~23 ~37 ~15 ~23 wool 0  
fill ~37 ~14 ~24 ~37 ~15 ~24 snow 0  
fill ~37 ~14 ~25 ~38 ~14 ~25 snow 0  
fill ~38 ~14 ~22 ~38 ~15 ~22 snow 0  
fill ~38 ~14 ~23 ~38 ~14 ~22 snow 0 
setblock ~38 ~14 ~24 wool 0 
setblock ~38 ~14 ~26 snow 0  
fill ~39 ~14 ~23 ~40 ~14 ~23 wool 0 
setblock ~39 ~14 ~24 wool 8  
fill ~39 ~14 ~25 ~40 ~14 ~25 wool 0  
fill ~39 ~14 ~26 ~39 ~14 ~25 wool 0 
setblock ~41 ~14 ~25 snow 0  
fill ~1 ~15 ~9 ~1 ~18 ~9 stained_hardened_clay 11  
fill ~4 ~15 ~14 ~4 ~18 ~14 stained_hardened_clay 11  
fill ~5 ~15 ~20 ~5 ~17 ~20 stained_hardened_clay 11  
fill ~6 ~15 ~11 ~8 ~15 ~11 stained_hardened_clay 11  
fill ~6 ~15 ~16 ~6 ~61 ~16 stained_hardened_clay 11  
fill ~6 ~15 ~17 ~6 ~54 ~17 stained_hardened_clay 11  
fill ~6 ~15 ~18 ~6 ~56 ~18 stained_hardened_clay 11  
fill ~6 ~15 ~22 ~6 ~17 ~22 stained_hardened_clay 11  
fill ~7 ~15 ~14 ~7 ~62 ~14 stained_hardened_clay 11  
fill ~7 ~15 ~15 ~14 ~15 ~15 stained_hardened_clay 11  
fill ~7 ~15 ~19 ~14 ~15 ~19 stained_hardened_clay 11  
fill ~8 ~15 ~13 ~12 ~15 ~13 stained_hardened_clay 11  
fill ~8 ~15 ~20 ~13 ~15 ~20 stained_hardened_clay 11  
fill ~8 ~15 ~21 ~8 ~17 ~21 stained_hardened_clay 11  
fill ~10 ~15 ~11 ~10 ~64 ~11 stained_hardened_clay 11  
fill ~12 ~15 ~17 ~15 ~15 ~17 stained_hardened_clay 11  
fill ~13 ~15 ~11 ~13 ~19 ~11 stained_hardened_clay 11  
fill ~13 ~15 ~16 ~14 ~15 ~16 stained_hardened_clay 11 
fill ~13 ~15 ~18 ~14 ~15 ~18 stained_hardened_clay 11  
fill ~14 ~15 ~21 ~14 ~18 ~21 stained_hardened_clay 11  
fill ~15 ~15 ~13 ~15 ~18 ~13 stained_hardened_clay 11  
fill ~15 ~15 ~14 ~15 ~15 ~13 stained_hardened_clay 11  
fill ~21 ~15 ~3 ~22 ~15 ~3 wool 8  
fill ~22 ~15 ~1 ~24 ~15 ~1 wool 8  
fill ~22 ~15 ~4 ~22 ~16 ~4 wool 8  
fill ~23 ~15 ~0 ~23 ~26 ~0 wool 8 
setblock ~25 ~15 ~4 wool 8  
fill ~26 ~15 ~2 ~27 ~15 ~2 wool 8 
setblock ~35 ~15 ~23 wool 8  
fill ~35 ~15 ~24 ~35 ~16 ~24 wool 0  
fill ~35 ~15 ~25 ~35 ~19 ~25 wool 0  
fill ~36 ~15 ~22 ~37 ~15 ~22 wool 0  
fill ~36 ~15 ~23 ~36 ~16 ~23 wool 0  
fill ~36 ~15 ~25 ~37 ~15 ~25 wool 8  
fill ~38 ~15 ~23 ~39 ~15 ~23 wool 0  
fill ~38 ~15 ~24 ~38 ~16 ~24 snow 0  
fill ~38 ~15 ~25 ~38 ~15 ~24 snow 0 
setblock ~39 ~15 ~24 wool 0 
setblock ~39 ~15 ~25 wool 8  
fill ~3 ~16 ~9 ~3 ~22 ~9 stained_hardened_clay 11  
fill ~4 ~16 ~22 ~4 ~20 ~22 stained_hardened_clay 11  
fill ~5 ~16 ~11 ~6 ~16 ~11 stained_hardened_clay 11 
setblock ~5 ~16 ~15 stained_hardened_clay 11  
fill ~6 ~16 ~7 ~6 ~22 ~7 stained_hardened_clay 11  
fill ~6 ~16 ~24 ~6 ~21 ~24 stained_hardened_clay 11  
fill ~7 ~16 ~13 ~13 ~16 ~13 stained_hardened_clay 11  
fill ~7 ~16 ~15 ~14 ~16 ~15 stained_hardened_clay 11  
fill ~7 ~16 ~19 ~14 ~16 ~19 stained_hardened_clay 11  
fill ~8 ~16 ~11 ~8 ~63 ~11 stained_hardened_clay 11  
fill ~8 ~16 ~12 ~12 ~16 ~12 stained_hardened_clay 11  
fill ~8 ~16 ~20 ~13 ~16 ~20 stained_hardened_clay 11  
fill ~10 ~16 ~10 ~10 ~17 ~10 stained_hardened_clay 11  
fill ~12 ~16 ~17 ~15 ~16 ~17 stained_hardened_clay 11  
fill ~12 ~16 ~23 ~12 ~19 ~23 stained_hardened_clay 11  
fill ~13 ~16 ~14 ~13 ~28 ~14 stained_hardened_clay 11  
fill ~13 ~16 ~16 ~16 ~16 ~16 stained_hardened_clay 11  
fill ~13 ~16 ~18 ~15 ~16 ~18 stained_hardened_clay 11 
setblock ~16 ~16 ~15 stained_hardened_clay 11  
fill ~21 ~16 ~1 ~21 ~16 ~3 stone 0  
fill ~22 ~16 ~1 ~23 ~16 ~1 wool 8  
fill ~22 ~16 ~3 ~23 ~16 ~3 wool 8  
fill ~23 ~16 ~2 ~23 ~18 ~2 wool 8  
fill ~25 ~16 ~3 ~25 ~16 ~4 snow 0  
fill ~26 ~16 ~2 ~26 ~17 ~2 wool 8  
fill ~34 ~16 ~23 ~36 ~16 ~23 wool 0  
fill ~34 ~16 ~24 ~34 ~18 ~24 wool 8  
fill ~34 ~16 ~25 ~34 ~18 ~25 wool 0  
fill ~35 ~16 ~22 ~37 ~16 ~22 wool 8  
fill ~36 ~16 ~25 ~38 ~16 ~25 wool 0  
fill ~37 ~16 ~23 ~38 ~16 ~23 snow 0 
setblock ~37 ~16 ~24 wool 0 
setblock ~37 ~16 ~26 wool 0  
fill ~39 ~16 ~24 ~39 ~17 ~24 snow 0  
fill ~3 ~17 ~16 ~3 ~20 ~16 stained_hardened_clay 11  
fill ~4 ~17 ~11 ~5 ~17 ~11 stained_hardened_clay 11  
fill ~5 ~17 ~16 ~5 ~60 ~16 stained_hardened_clay 11  
fill ~5 ~17 ~19 ~5 ~21 ~19 stained_hardened_clay 11  
fill ~6 ~17 ~10 ~6 ~18 ~10 stained_hardened_clay 11  
fill ~6 ~17 ~12 ~6 ~62 ~12 stained_hardened_clay 11  
fill ~6 ~17 ~13 ~13 ~17 ~13 stained_hardened_clay 11  
fill ~6 ~17 ~14 ~6 ~62 ~14 stained_hardened_clay 11  
fill ~6 ~17 ~21 ~8 ~17 ~21 stained_hardened_clay 11 
setblock ~7 ~17 ~11 stained_hardened_clay 11  
fill ~7 ~17 ~15 ~15 ~17 ~15 stained_hardened_clay 11  
fill ~7 ~17 ~19 ~13 ~17 ~19 stained_hardened_clay 11  
fill ~8 ~17 ~12 ~12 ~17 ~12 stained_hardened_clay 11  
fill ~8 ~17 ~20 ~12 ~17 ~20 stained_hardened_clay 11  
fill ~9 ~17 ~11 ~9 ~64 ~11 stained_hardened_clay 11  
fill ~11 ~17 ~10 ~11 ~62 ~10 stained_hardened_clay 11  
fill ~11 ~17 ~11 ~11 ~39 ~11 stained_hardened_clay 11  
fill ~12 ~17 ~17 ~14 ~17 ~17 stained_hardened_clay 11  
fill ~12 ~17 ~21 ~12 ~20 ~21 stained_hardened_clay 11  
fill ~13 ~17 ~7 ~13 ~22 ~7 stained_hardened_clay 11  
fill ~13 ~17 ~16 ~15 ~17 ~16 stained_hardened_clay 11  
fill ~13 ~17 ~18 ~15 ~17 ~18 stained_hardened_clay 11  
fill ~21 ~17 ~1 ~25 ~17 ~1 wool 8  
fill ~21 ~17 ~2 ~21 ~17 ~1 wool 8  
fill ~21 ~17 ~3 ~24 ~17 ~3 snow 0  
fill ~22 ~17 ~0 ~22 ~26 ~0 wool 8  
fill ~22 ~17 ~4 ~23 ~17 ~4 snow 0 
setblock ~24 ~17 ~2 snow 0  
fill ~25 ~17 ~2 ~25 ~17 ~3 wool 8  
fill ~33 ~17 ~23 ~33 ~18 ~23 wool 8 
setblock ~33 ~17 ~24 wool 0  
fill ~34 ~17 ~22 ~34 ~18 ~22 wool 8  
fill ~34 ~17 ~23 ~34 ~16 ~23 wool 0 
setblock ~35 ~17 ~22 wool 0  
fill ~35 ~17 ~23 ~36 ~17 ~23 wool 8  
fill ~35 ~17 ~24 ~35 ~17 ~23 wool 8  
fill ~36 ~17 ~22 ~37 ~17 ~22 wool 8  
fill ~36 ~17 ~25 ~37 ~17 ~25 wool 0 
setblock ~36 ~17 ~26 snow 0  
fill ~37 ~17 ~23 ~37 ~16 ~23 snow 0  
fill ~37 ~17 ~24 ~37 ~17 ~23 snow 0  
fill ~38 ~17 ~23 ~38 ~17 ~24 wool 0  
fill ~0 ~18 ~9 ~0 ~26 ~9 stained_hardened_clay 11  
fill ~0 ~18 ~16 ~0 ~22 ~16 stained_hardened_clay 11  
fill ~3 ~18 ~13 ~3 ~21 ~13 stained_hardened_clay 11  
fill ~3 ~18 ~14 ~3 ~18 ~13 stained_hardened_clay 11  
fill ~4 ~18 ~11 ~4 ~19 ~11 stained_hardened_clay 11  
fill ~5 ~18 ~13 ~13 ~18 ~13 stained_hardened_clay 11  
fill ~5 ~18 ~14 ~5 ~61 ~14 stained_hardened_clay 11  
fill ~5 ~18 ~15 ~5 ~61 ~15 stained_hardened_clay 11  
fill ~6 ~18 ~9 ~6 ~20 ~9 stained_hardened_clay 11 
setblock ~6 ~18 ~11 stained_hardened_clay 11  
fill ~6 ~18 ~20 ~6 ~21 ~20 stained_hardened_clay 11  
fill ~6 ~18 ~21 ~7 ~18 ~21 stained_hardened_clay 11  
fill ~7 ~18 ~10 ~8 ~18 ~10 stained_hardened_clay 11  
fill ~7 ~18 ~15 ~15 ~18 ~15 stained_hardened_clay 11  
fill ~7 ~18 ~19 ~13 ~18 ~19 stained_hardened_clay 11  
fill ~8 ~18 ~12 ~13 ~18 ~12 stained_hardened_clay 11  
fill ~9 ~18 ~20 ~12 ~18 ~20 stained_hardened_clay 11  
fill ~12 ~18 ~11 ~12 ~38 ~11 stained_hardened_clay 11  
fill ~12 ~18 ~17 ~14 ~18 ~17 stained_hardened_clay 11  
fill ~13 ~18 ~16 ~14 ~18 ~16 stained_hardened_clay 11  
fill ~13 ~18 ~18 ~15 ~18 ~18 stained_hardened_clay 11  
fill ~15 ~18 ~12 ~15 ~22 ~12 stained_hardened_clay 11  
fill ~15 ~18 ~21 ~15 ~22 ~21 stained_hardened_clay 11 
setblock ~20 ~18 ~2 wool 8  
fill ~21 ~18 ~1 ~25 ~18 ~1 wool 8  
fill ~21 ~18 ~2 ~22 ~18 ~2 snow 0  
fill ~21 ~18 ~3 ~24 ~18 ~3 snow 0  
fill ~22 ~18 ~4 ~24 ~18 ~4 snow 0 
setblock ~24 ~18 ~2 wool 8 
setblock ~25 ~18 ~2 snow 0 
setblock ~25 ~18 ~3 wool 8  
fill ~32 ~18 ~23 ~32 ~25 ~23 wool 8  
fill ~33 ~18 ~22 ~33 ~19 ~22 wool 8  
fill ~33 ~18 ~24 ~33 ~23 ~24 wool 8  
fill ~33 ~18 ~25 ~33 ~19 ~25 wool 8  
fill ~34 ~18 ~23 ~36 ~18 ~23 wool 8  
fill ~35 ~18 ~22 ~36 ~18 ~22 wool 8 
setblock ~35 ~18 ~24 snow 0  
fill ~35 ~18 ~26 ~36 ~18 ~26 wool 0  
fill ~36 ~18 ~24 ~36 ~20 ~24 wool 8  
fill ~36 ~18 ~25 ~37 ~18 ~25 wool 0  
fill ~37 ~18 ~23 ~37 ~18 ~25 wool 0  
fill ~-1 ~19 ~10 ~-1 ~28 ~10 stained_hardened_clay 11  
fill ~1 ~19 ~13 ~1 ~24 ~13 stained_hardened_clay 11  
fill ~3 ~19 ~11 ~3 ~21 ~11 stained_hardened_clay 11  
fill ~5 ~19 ~12 ~5 ~61 ~12 stained_hardened_clay 11  
fill ~5 ~19 ~13 ~13 ~19 ~13 stained_hardened_clay 11  
fill ~5 ~19 ~17 ~5 ~60 ~17 stained_hardened_clay 11  
fill ~7 ~19 ~11 ~7 ~62 ~11 stained_hardened_clay 11  
fill ~7 ~19 ~15 ~15 ~19 ~15 stained_hardened_clay 11  
fill ~7 ~19 ~19 ~13 ~19 ~19 stained_hardened_clay 11  
fill ~7 ~19 ~21 ~7 ~24 ~21 stained_hardened_clay 11  
fill ~8 ~19 ~9 ~8 ~33 ~9 stained_hardened_clay 11  
fill ~8 ~19 ~10 ~9 ~19 ~10 stained_hardened_clay 11  
fill ~8 ~19 ~12 ~13 ~19 ~12 stained_hardened_clay 11  
fill ~9 ~19 ~24 ~9 ~23 ~24 stained_hardened_clay 11  
fill ~11 ~19 ~9 ~11 ~43 ~9 stained_hardened_clay 11  
fill ~11 ~19 ~23 ~11 ~22 ~23 stained_hardened_clay 11  
fill ~12 ~19 ~17 ~15 ~19 ~17 stained_hardened_clay 11  
fill ~13 ~19 ~10 ~13 ~23 ~10 stained_hardened_clay 11  
fill ~13 ~19 ~16 ~14 ~19 ~16 stained_hardened_clay 11  
fill ~13 ~19 ~18 ~13 ~21 ~18 stained_hardened_clay 11  
fill ~15 ~19 ~19 ~15 ~23 ~19 stained_hardened_clay 11  
fill ~20 ~19 ~1 ~24 ~19 ~1 wool 8  
fill ~20 ~19 ~2 ~21 ~19 ~2 snow 0  
fill ~21 ~19 ~0 ~21 ~23 ~0 wool 8  
fill ~21 ~19 ~3 ~22 ~19 ~3 snow 0  
fill ~21 ~19 ~4 ~24 ~19 ~4 snow 0 
setblock ~22 ~19 ~2 wool 8  
fill ~23 ~19 ~2 ~24 ~19 ~2 snow 0 
setblock ~23 ~19 ~3 wool 8 
setblock ~24 ~19 ~3 snow 0  
fill ~32 ~19 ~22 ~32 ~25 ~22 wool 8  
fill ~32 ~19 ~24 ~32 ~20 ~24 wool 0  
fill ~33 ~19 ~23 ~34 ~19 ~23 wool 0  
fill ~34 ~19 ~22 ~35 ~19 ~22 wool 0 
setblock ~34 ~19 ~24 wool 0 
setblock ~34 ~19 ~25 wool 8  
fill ~34 ~19 ~26 ~35 ~19 ~26 wool 0  
fill ~35 ~19 ~23 ~35 ~20 ~23 wool 8  
fill ~35 ~19 ~24 ~35 ~21 ~24 wool 8  
fill ~36 ~19 ~23 ~36 ~20 ~23 wool 0  
fill ~36 ~19 ~25 ~36 ~16 ~25 wool 0 
setblock ~37 ~19 ~24 wool 0  
fill ~-3 ~20 ~10 ~-3 ~30 ~10 stained_hardened_clay 11  
fill ~-1 ~20 ~12 ~-1 ~28 ~12 stained_hardened_clay 11  
fill ~0 ~20 ~21 ~0 ~24 ~21 stained_hardened_clay 11  
fill ~2 ~20 ~16 ~2 ~23 ~16 stained_hardened_clay 11  
fill ~3 ~20 ~22 ~3 ~25 ~22 stained_hardened_clay 11  
fill ~4 ~20 ~14 ~4 ~54 ~14 stained_hardened_clay 11  
fill ~4 ~20 ~15 ~4 ~55 ~15 stained_hardened_clay 11  
fill ~5 ~20 ~9 ~5 ~23 ~9 stained_hardened_clay 11  
fill ~5 ~20 ~13 ~14 ~20 ~13 stained_hardened_clay 11  
fill ~5 ~20 ~24 ~5 ~25 ~24 stained_hardened_clay 11  
fill ~6 ~20 ~11 ~6 ~34 ~11 stained_hardened_clay 11  
fill ~7 ~20 ~10 ~11 ~20 ~10 stained_hardened_clay 11  
fill ~7 ~20 ~15 ~15 ~20 ~15 stained_hardened_clay 11  
fill ~7 ~20 ~19 ~12 ~20 ~19 stained_hardened_clay 11  
fill ~8 ~20 ~8 ~8 ~23 ~8 stained_hardened_clay 11  
fill ~8 ~20 ~12 ~13 ~20 ~12 stained_hardened_clay 11  
fill ~12 ~20 ~17 ~15 ~20 ~17 stained_hardened_clay 11  
fill ~12 ~20 ~22 ~12 ~28 ~22 stained_hardened_clay 11  
fill ~13 ~20 ~16 ~15 ~20 ~16 stained_hardened_clay 11  
fill ~13 ~20 ~20 ~13 ~21 ~20 stained_hardened_clay 11  
fill ~20 ~20 ~1 ~22 ~20 ~1 wool 8  
fill ~20 ~20 ~2 ~20 ~24 ~2 wool 8  
fill ~20 ~20 ~3 ~20 ~22 ~3 snow 0  
fill ~21 ~20 ~2 ~24 ~20 ~2 snow 0  
fill ~21 ~20 ~3 ~22 ~20 ~3 wool 8  
fill ~21 ~20 ~4 ~21 ~21 ~4 wool 8  
fill ~22 ~20 ~4 ~23 ~20 ~4 snow 0 
setblock ~23 ~20 ~1 snow 0  
fill ~23 ~20 ~3 ~23 ~22 ~3 snow 0  
fill ~24 ~20 ~1 ~24 ~28 ~1 wool 8 
setblock ~24 ~20 ~3 wool 8  
fill ~31 ~20 ~22 ~31 ~25 ~22 wool 8  
fill ~31 ~20 ~23 ~31 ~26 ~23 wool 8  
fill ~31 ~20 ~24 ~31 ~21 ~24 wool 8 
setblock ~32 ~20 ~25 wool 8 
setblock ~33 ~20 ~22 wool 0  
fill ~33 ~20 ~23 ~35 ~20 ~23 wool 8  
fill ~33 ~20 ~25 ~34 ~20 ~25 wool 0  
fill ~34 ~20 ~22 ~35 ~20 ~22 wool 8  
fill ~34 ~20 ~24 ~34 ~23 ~24 wool 8  
fill ~34 ~20 ~26 ~35 ~20 ~26 wool 0  
fill ~35 ~20 ~25 ~36 ~20 ~25 wool 8  
fill ~3 ~21 ~10 ~3 ~25 ~10 stained_hardened_clay 11  
fill ~3 ~21 ~12 ~3 ~55 ~12 stained_hardened_clay 11  
fill ~4 ~21 ~18 ~13 ~21 ~18 stained_hardened_clay 11  
fill ~5 ~21 ~13 ~13 ~21 ~13 stained_hardened_clay 11  
fill ~6 ~21 ~19 ~11 ~21 ~19 stained_hardened_clay 11  
fill ~7 ~21 ~10 ~11 ~21 ~10 stained_hardened_clay 11  
fill ~7 ~21 ~15 ~15 ~21 ~15 stained_hardened_clay 11  
fill ~8 ~21 ~12 ~13 ~21 ~12 stained_hardened_clay 11  
fill ~9 ~21 ~9 ~9 ~33 ~9 stained_hardened_clay 11  
fill ~12 ~21 ~17 ~13 ~21 ~17 stained_hardened_clay 11  
fill ~13 ~21 ~16 ~14 ~21 ~16 stained_hardened_clay 11  
fill ~16 ~21 ~16 ~16 ~26 ~16 stained_hardened_clay 11  
fill ~20 ~21 ~1 ~24 ~21 ~1 wool 8  
fill ~21 ~21 ~2 ~24 ~21 ~2 snow 0  
fill ~21 ~21 ~3 ~24 ~21 ~3 snow 0  
fill ~22 ~21 ~4 ~22 ~22 ~4 snow 0 
setblock ~23 ~21 ~4 wool 8  
fill ~30 ~21 ~22 ~30 ~25 ~22 wool 8  
fill ~30 ~21 ~23 ~30 ~23 ~23 wool 8  
fill ~30 ~21 ~24 ~30 ~23 ~24 wool 8  
fill ~31 ~21 ~21 ~31 ~26 ~21 wool 8  
fill ~31 ~21 ~25 ~31 ~23 ~25 wool 8 
setblock ~32 ~21 ~21 stone 0 
setblock ~32 ~21 ~24 wool 8  
fill ~32 ~21 ~25 ~32 ~22 ~25 wool 0  
fill ~33 ~21 ~22 ~33 ~25 ~22 wool 8  
fill ~33 ~21 ~23 ~33 ~22 ~23 wool 8  
fill ~33 ~21 ~25 ~35 ~21 ~25 wool 8  
fill ~33 ~21 ~26 ~34 ~21 ~26 wool 8  
fill ~34 ~21 ~22 ~34 ~22 ~22 wool 0  
fill ~34 ~21 ~23 ~35 ~21 ~23 wool 0 
setblock ~36 ~21 ~24 wool 0  
fill ~-1 ~22 ~16 ~-1 ~25 ~16 stained_hardened_clay 11  
fill ~2 ~22 ~7 ~2 ~25 ~7 stained_hardened_clay 11  
fill ~3 ~22 ~18 ~12 ~22 ~18 stained_hardened_clay 11  
fill ~4 ~22 ~13 ~13 ~22 ~13 stained_hardened_clay 11  
fill ~4 ~22 ~16 ~4 ~60 ~16 stained_hardened_clay 11  
fill ~6 ~22 ~6 ~6 ~27 ~6 stained_hardened_clay 11  
fill ~6 ~22 ~19 ~11 ~22 ~19 stained_hardened_clay 11  
fill ~7 ~22 ~10 ~11 ~22 ~10 stained_hardened_clay 11  
fill ~7 ~22 ~15 ~15 ~22 ~15 stained_hardened_clay 11 
setblock ~7 ~22 ~20 stained_hardened_clay 11  
fill ~8 ~22 ~12 ~13 ~22 ~12 stained_hardened_clay 11  
fill ~10 ~22 ~8 ~11 ~22 ~8 stained_hardened_clay 11  
fill ~10 ~22 ~9 ~10 ~61 ~9 stained_hardened_clay 11  
fill ~10 ~22 ~23 ~10 ~26 ~23 stained_hardened_clay 11  
fill ~11 ~22 ~24 ~11 ~27 ~24 stained_hardened_clay 11  
fill ~12 ~22 ~17 ~13 ~22 ~17 stained_hardened_clay 11  
fill ~13 ~22 ~6 ~13 ~28 ~6 stained_hardened_clay 11  
fill ~13 ~22 ~16 ~13 ~26 ~16 stained_hardened_clay 11  
fill ~14 ~22 ~21 ~14 ~29 ~21 stained_hardened_clay 11  
fill ~16 ~22 ~12 ~16 ~35 ~12 stained_hardened_clay 11  
fill ~20 ~22 ~1 ~24 ~22 ~1 wool 8  
fill ~21 ~22 ~2 ~23 ~22 ~2 snow 0  
fill ~21 ~22 ~3 ~24 ~22 ~3 snow 0  
fill ~21 ~22 ~4 ~21 ~22 ~2 snow 0 
setblock ~23 ~22 ~4 snow 0  
fill ~24 ~22 ~2 ~24 ~26 ~2 wool 8  
fill ~29 ~22 ~23 ~29 ~27 ~23 wool 8  
fill ~29 ~22 ~24 ~29 ~23 ~24 wool 8  
fill ~30 ~22 ~25 ~30 ~24 ~25 wool 8  
fill ~31 ~22 ~24 ~32 ~22 ~24 wool 0  
fill ~32 ~22 ~21 ~33 ~22 ~21 wool 8 
setblock ~32 ~22 ~26 wool 0  
fill ~33 ~22 ~25 ~35 ~22 ~25 wool 8  
fill ~33 ~22 ~26 ~33 ~24 ~26 wool 8 
setblock ~34 ~22 ~23 wool 8  
fill ~35 ~22 ~23 ~35 ~22 ~24 wool 0  
fill ~2 ~23 ~15 ~2 ~52 ~15 stained_hardened_clay 11  
fill ~3 ~23 ~18 ~3 ~25 ~18 stained_hardened_clay 11  
fill ~4 ~23 ~12 ~4 ~55 ~12 stained_hardened_clay 11  
fill ~4 ~23 ~13 ~14 ~23 ~13 stained_hardened_clay 11  
fill ~5 ~23 ~8 ~5 ~27 ~8 stained_hardened_clay 11  
fill ~5 ~23 ~11 ~5 ~49 ~11 stained_hardened_clay 11  
fill ~7 ~23 ~10 ~14 ~23 ~10 stained_hardened_clay 11  
fill ~7 ~23 ~15 ~15 ~23 ~15 stained_hardened_clay 11  
fill ~7 ~23 ~19 ~10 ~23 ~19 stained_hardened_clay 11  
fill ~8 ~23 ~7 ~8 ~27 ~7 stained_hardened_clay 11  
fill ~8 ~23 ~12 ~13 ~23 ~12 stained_hardened_clay 11  
fill ~9 ~23 ~23 ~9 ~24 ~23 stained_hardened_clay 11  
fill ~10 ~23 ~8 ~10 ~37 ~8 stained_hardened_clay 11  
fill ~12 ~23 ~17 ~13 ~23 ~17 stained_hardened_clay 11  
fill ~13 ~23 ~20 ~13 ~24 ~20 stained_hardened_clay 11  
fill ~15 ~23 ~14 ~15 ~31 ~14 stained_hardened_clay 11  
fill ~15 ~23 ~18 ~15 ~28 ~18 stained_hardened_clay 11  
fill ~19 ~23 ~2 ~19 ~24 ~2 wool 8  
fill ~20 ~23 ~1 ~20 ~24 ~1 wool 0  
fill ~20 ~23 ~3 ~21 ~23 ~3 wool 0  
fill ~21 ~23 ~1 ~24 ~23 ~1 wool 8  
fill ~21 ~23 ~2 ~24 ~23 ~2 wool 8  
fill ~21 ~23 ~4 ~23 ~23 ~4 wool 8  
fill ~22 ~23 ~3 ~24 ~23 ~3 wool 8  
fill ~27 ~23 ~24 ~31 ~23 ~24 wool 8  
fill ~28 ~23 ~23 ~28 ~27 ~23 wool 8  
fill ~28 ~23 ~25 ~32 ~23 ~25 wool 8  
fill ~29 ~23 ~22 ~29 ~28 ~22 wool 8  
fill ~30 ~23 ~21 ~30 ~25 ~21 wool 8  
fill ~31 ~23 ~26 ~31 ~24 ~26 wool 0  
fill ~32 ~23 ~21 ~32 ~22 ~21 wool 8 
setblock ~32 ~23 ~24 wool 0 
setblock ~32 ~23 ~26 wool 8 
setblock ~33 ~23 ~21 stone 0  
fill ~33 ~23 ~23 ~34 ~23 ~23 wool 0 
setblock ~33 ~23 ~25 wool 0 
setblock ~34 ~23 ~22 wool 8  
fill ~34 ~23 ~25 ~34 ~24 ~25 wool 8  
fill ~0 ~24 ~20 ~0 ~28 ~20 stained_hardened_clay 11  
fill ~2 ~24 ~13 ~2 ~53 ~13 stained_hardened_clay 11  
fill ~4 ~24 ~13 ~14 ~24 ~13 stained_hardened_clay 11  
fill ~4 ~24 ~17 ~4 ~52 ~17 stained_hardened_clay 11  
fill ~5 ~24 ~18 ~5 ~52 ~18 stained_hardened_clay 11  
fill ~6 ~24 ~10 ~12 ~24 ~10 stained_hardened_clay 11  
fill ~7 ~24 ~9 ~7 ~33 ~9 stained_hardened_clay 11  
fill ~7 ~24 ~15 ~14 ~24 ~15 stained_hardened_clay 11  
fill ~7 ~24 ~19 ~10 ~24 ~19 stained_hardened_clay 11  
fill ~7 ~24 ~20 ~7 ~27 ~20 stained_hardened_clay 11  
fill ~8 ~24 ~12 ~13 ~24 ~12 stained_hardened_clay 11  
fill ~8 ~24 ~23 ~8 ~30 ~23 stained_hardened_clay 11  
fill ~10 ~24 ~7 ~10 ~35 ~7 stained_hardened_clay 11  
fill ~12 ~24 ~17 ~13 ~24 ~17 stained_hardened_clay 11  
fill ~13 ~24 ~11 ~13 ~37 ~11 stained_hardened_clay 11  
fill ~13 ~24 ~19 ~13 ~29 ~19 stained_hardened_clay 11  
fill ~14 ~24 ~10 ~14 ~31 ~10 stained_hardened_clay 11 
setblock ~18 ~24 ~1 wool 0  
fill ~18 ~24 ~2 ~18 ~25 ~2 wool 8  
fill ~19 ~24 ~1 ~19 ~26 ~1 wool 8 
setblock ~19 ~24 ~3 wool 8  
fill ~20 ~24 ~0 ~20 ~27 ~0 wool 8  
fill ~20 ~24 ~3 ~20 ~23 ~3 wool 0  
fill ~21 ~24 ~0 ~21 ~24 ~1 wool 0  
fill ~21 ~24 ~2 ~24 ~24 ~2 wool 8  
fill ~21 ~24 ~3 ~24 ~24 ~3 wool 8 
setblock ~21 ~24 ~4 wool 0  
fill ~22 ~24 ~1 ~22 ~26 ~1 wool 8  
fill ~22 ~24 ~4 ~23 ~24 ~4 wool 8 
setblock ~23 ~24 ~1 wool 0  
fill ~27 ~24 ~23 ~27 ~26 ~23 wool 8  
fill ~27 ~24 ~24 ~28 ~24 ~24 wool 8  
fill ~27 ~24 ~25 ~30 ~24 ~25 wool 8  
fill ~28 ~24 ~22 ~28 ~26 ~22 wool 8  
fill ~29 ~24 ~24 ~31 ~24 ~24 wool 0  
fill ~29 ~24 ~26 ~29 ~25 ~26 wool 0 
setblock ~30 ~24 ~23 wool 0 
setblock ~30 ~24 ~26 wool 8 
setblock ~31 ~24 ~25 snow 0  
fill ~32 ~24 ~21 ~32 ~25 ~21 stone 0  
fill ~32 ~24 ~24 ~32 ~24 ~25 wool 8 
setblock ~32 ~24 ~26 wool 0 
setblock ~33 ~24 ~23 wool 8  
fill ~33 ~24 ~24 ~34 ~24 ~24 wool 0 
setblock ~33 ~24 ~25 snow 0 
setblock ~34 ~24 ~23 wool 0  
fill ~-1 ~25 ~15 ~-1 ~30 ~15 stained_hardened_clay 11  
fill ~0 ~25 ~8 ~0 ~28 ~8 stained_hardened_clay 11  
fill ~2 ~25 ~6 ~2 ~27 ~6 stained_hardened_clay 11  
fill ~2 ~25 ~18 ~2 ~28 ~18 stained_hardened_clay 11  
fill ~3 ~25 ~16 ~3 ~52 ~16 stained_hardened_clay 11  
fill ~3 ~25 ~21 ~3 ~30 ~21 stained_hardened_clay 11  
fill ~4 ~25 ~11 ~4 ~43 ~11 stained_hardened_clay 11  
fill ~4 ~25 ~13 ~14 ~25 ~13 stained_hardened_clay 11  
fill ~4 ~25 ~24 ~4 ~30 ~24 stained_hardened_clay 11  
fill ~5 ~25 ~10 ~12 ~25 ~10 stained_hardened_clay 11  
fill ~6 ~25 ~19 ~9 ~25 ~19 stained_hardened_clay 11  
fill ~7 ~25 ~15 ~13 ~25 ~15 stained_hardened_clay 11  
fill ~8 ~25 ~8 ~10 ~25 ~8 stained_hardened_clay 11  
fill ~8 ~25 ~12 ~14 ~25 ~12 stained_hardened_clay 11  
fill ~10 ~25 ~22 ~10 ~30 ~22 stained_hardened_clay 11  
fill ~12 ~25 ~17 ~12 ~26 ~17 stained_hardened_clay 11  
fill ~18 ~25 ~1 ~18 ~28 ~1 wool 8  
fill ~18 ~25 ~3 ~18 ~27 ~3 wool 8  
fill ~19 ~25 ~0 ~19 ~28 ~0 wool 8  
fill ~19 ~25 ~2 ~20 ~25 ~2 wool 0  
fill ~19 ~25 ~3 ~19 ~25 ~2 wool 0  
fill ~19 ~25 ~4 ~20 ~25 ~4 wool 8  
fill ~20 ~25 ~1 ~24 ~25 ~1 wool 8  
fill ~20 ~25 ~3 ~24 ~25 ~3 wool 8  
fill ~21 ~25 ~-1 ~22 ~25 ~-1 wool 8  
fill ~21 ~25 ~0 ~21 ~27 ~0 wool 8  
fill ~21 ~25 ~2 ~24 ~25 ~2 wool 8 
setblock ~21 ~25 ~4 snow 0  
fill ~22 ~25 ~4 ~23 ~25 ~4 wool 8  
fill ~27 ~25 ~24 ~30 ~25 ~24 wool 8  
fill ~27 ~25 ~25 ~28 ~25 ~25 wool 8  
fill ~28 ~25 ~26 ~28 ~26 ~26 wool 8  
fill ~29 ~25 ~21 ~29 ~26 ~21 wool 8 
setblock ~29 ~25 ~25 wool 0 
setblock ~30 ~25 ~23 wool 8  
fill ~30 ~25 ~25 ~30 ~27 ~25 snow 0  
fill ~30 ~25 ~26 ~30 ~28 ~26 snow 0 
setblock ~31 ~25 ~24 snow 0 
setblock ~31 ~25 ~25 wool 0  
fill ~31 ~25 ~26 ~32 ~25 ~26 wool 8 
setblock ~32 ~25 ~24 wool 0 
setblock ~32 ~25 ~25 wool 8  
fill ~33 ~25 ~23 ~34 ~25 ~23 stone 3  
fill ~33 ~25 ~24 ~34 ~25 ~24 wool 8 
setblock ~33 ~25 ~25 stone 3  
fill ~0 ~26 ~10 ~0 ~29 ~10 stained_hardened_clay 11  
fill ~2 ~26 ~10 ~2 ~30 ~10 stained_hardened_clay 11 
setblock ~3 ~26 ~10 stained_hardened_clay 3  
fill ~3 ~26 ~13 ~14 ~26 ~13 stained_hardened_clay 11  
fill ~3 ~26 ~14 ~3 ~56 ~14 stained_hardened_clay 11  
fill ~3 ~26 ~15 ~3 ~55 ~15 stained_hardened_clay 11  
fill ~4 ~26 ~18 ~4 ~51 ~18 stained_hardened_clay 11  
fill ~5 ~26 ~10 ~14 ~26 ~10 stained_hardened_clay 11  
fill ~5 ~26 ~19 ~9 ~26 ~19 stained_hardened_clay 11  
fill ~6 ~26 ~9 ~6 ~28 ~9 stained_hardened_clay 11  
fill ~7 ~26 ~15 ~13 ~26 ~15 stained_hardened_clay 11  
fill ~8 ~26 ~8 ~10 ~26 ~8 stained_hardened_clay 11  
fill ~8 ~26 ~12 ~14 ~26 ~12 stained_hardened_clay 11  
fill ~12 ~26 ~9 ~12 ~35 ~9 stained_hardened_clay 11  
fill ~14 ~26 ~11 ~14 ~29 ~11 stained_hardened_clay 11  
fill ~16 ~26 ~15 ~16 ~31 ~15 stained_hardened_clay 11  
fill ~18 ~26 ~2 ~19 ~26 ~2 wool 0  
fill ~19 ~26 ~3 ~20 ~26 ~3 wool 8  
fill ~19 ~26 ~4 ~23 ~26 ~4 wool 8  
fill ~20 ~26 ~-1 ~22 ~26 ~-1 wool 8  
fill ~20 ~26 ~1 ~24 ~26 ~1 wool 8  
fill ~20 ~26 ~2 ~24 ~26 ~2 wool 8  
fill ~21 ~26 ~3 ~21 ~28 ~3 wool 0  
fill ~22 ~26 ~3 ~22 ~27 ~3 wool 8 
setblock ~23 ~26 ~3 wool 0  
fill ~24 ~26 ~3 ~24 ~29 ~3 wool 8  
fill ~27 ~26 ~24 ~27 ~27 ~24 wool 0  
fill ~27 ~26 ~25 ~29 ~26 ~25 wool 8  
fill ~28 ~26 ~24 ~29 ~26 ~24 wool 8  
fill ~29 ~26 ~26 ~29 ~27 ~26 wool 8 
setblock ~30 ~26 ~21 stone 0  
fill ~30 ~26 ~22 ~31 ~26 ~22 wool 0  
fill ~30 ~26 ~23 ~30 ~27 ~23 wool 0 
setblock ~30 ~26 ~24 stone 3 
setblock ~31 ~26 ~24 wool 0  
fill ~31 ~26 ~25 ~31 ~26 ~26 snow 0  
fill ~32 ~26 ~22 ~33 ~26 ~22 stone 3  
fill ~32 ~26 ~23 ~33 ~26 ~23 stone 3  
fill ~32 ~26 ~24 ~33 ~26 ~24 snow 0  
fill ~32 ~26 ~25 ~32 ~27 ~25 stone 3 
setblock ~33 ~26 ~25 wool 8 
setblock ~34 ~26 ~23 wool 8  
fill ~34 ~26 ~24 ~34 ~34 ~24 stone 3  
fill ~3 ~27 ~6 ~3 ~31 ~6 stained_hardened_clay 11  
fill ~3 ~27 ~13 ~13 ~27 ~13 stained_hardened_clay 11  
fill ~3 ~27 ~17 ~3 ~52 ~17 stained_hardened_clay 11  
fill ~4 ~27 ~8 ~4 ~33 ~8 stained_hardened_clay 11  
fill ~4 ~27 ~10 ~4 ~33 ~10 stained_hardened_clay 11  
fill ~5 ~27 ~9 ~5 ~28 ~9 stained_hardened_clay 11  
fill ~5 ~27 ~10 ~6 ~27 ~10 stained_hardened_clay 3  
fill ~5 ~27 ~19 ~9 ~27 ~19 stained_hardened_clay 11  
fill ~6 ~27 ~20 ~6 ~54 ~20 stained_hardened_clay 11  
fill ~7 ~27 ~7 ~7 ~31 ~7 stained_hardened_clay 11  
fill ~7 ~27 ~8 ~10 ~27 ~8 stained_hardened_clay 11  
fill ~7 ~27 ~10 ~14 ~27 ~10 stained_hardened_clay 11  
fill ~7 ~27 ~15 ~13 ~27 ~15 stained_hardened_clay 11  
fill ~8 ~27 ~12 ~13 ~27 ~12 stained_hardened_clay 11  
fill ~9 ~27 ~4 ~9 ~30 ~4 stained_hardened_clay 11 
setblock ~11 ~27 ~23 stained_hardened_clay 11  
fill ~18 ~27 ~2 ~21 ~27 ~2 wool 0 
setblock ~19 ~27 ~1 wool 0  
fill ~19 ~27 ~3 ~21 ~27 ~3 wool 0  
fill ~19 ~27 ~4 ~21 ~27 ~4 wool 8  
fill ~20 ~27 ~-1 ~22 ~27 ~-1 wool 8  
fill ~20 ~27 ~1 ~21 ~27 ~1 wool 8  
fill ~22 ~27 ~0 ~23 ~27 ~0 wool 0  
fill ~22 ~27 ~1 ~23 ~27 ~1 wool 0  
fill ~22 ~27 ~2 ~23 ~27 ~2 wool 8  
fill ~22 ~27 ~4 ~22 ~29 ~4 wool 0  
fill ~23 ~27 ~-1 ~23 ~29 ~-1 wool 0  
fill ~23 ~27 ~3 ~23 ~27 ~4 wool 8  
fill ~24 ~27 ~0 ~24 ~28 ~0 wool 8 
setblock ~24 ~27 ~2 snow 0  
fill ~27 ~27 ~25 ~29 ~27 ~25 wool 8  
fill ~28 ~27 ~24 ~29 ~27 ~24 wool 8  
fill ~30 ~27 ~22 ~31 ~27 ~22 wool 8  
fill ~30 ~27 ~24 ~30 ~28 ~24 snow 0 
setblock ~31 ~27 ~23 wool 0  
fill ~31 ~27 ~24 ~32 ~27 ~24 stone 3  
fill ~31 ~27 ~25 ~31 ~27 ~26 stone 3  
fill ~32 ~27 ~22 ~33 ~27 ~22 stone 3  
fill ~32 ~27 ~23 ~34 ~27 ~23 stone 3 
setblock ~32 ~27 ~26 snow 0 
setblock ~33 ~27 ~24 wool 0  
fill ~33 ~27 ~25 ~34 ~27 ~25 stone 3  
fill ~-1 ~28 ~8 ~-1 ~33 ~8 stained_hardened_clay 11  
fill ~0 ~28 ~12 ~0 ~34 ~12 stained_hardened_clay 11  
fill ~1 ~28 ~18 ~1 ~29 ~18 stained_hardened_clay 11  
fill ~2 ~28 ~14 ~2 ~53 ~14 stained_hardened_clay 11  
fill ~3 ~28 ~11 ~3 ~46 ~11 stained_hardened_clay 11  
fill ~3 ~28 ~13 ~13 ~28 ~13 stained_hardened_clay 11  
fill ~5 ~28 ~10 ~14 ~28 ~10 stained_hardened_clay 11  
fill ~5 ~28 ~19 ~9 ~28 ~19 stained_hardened_clay 11  
fill ~6 ~28 ~5 ~6 ~28 ~6 stained_hardened_clay 3  
fill ~7 ~28 ~8 ~10 ~28 ~8 stained_hardened_clay 11  
fill ~7 ~28 ~15 ~12 ~28 ~15 stained_hardened_clay 11  
fill ~8 ~28 ~12 ~13 ~28 ~12 stained_hardened_clay 11 
setblock ~11 ~28 ~23 stained_hardened_clay 3  
fill ~12 ~28 ~6 ~12 ~33 ~6 stained_hardened_clay 11  
fill ~12 ~28 ~21 ~12 ~36 ~21 stained_hardened_clay 11  
fill ~15 ~28 ~11 ~15 ~30 ~11 stained_hardened_clay 11  
fill ~15 ~28 ~17 ~15 ~34 ~17 stained_hardened_clay 11  
fill ~18 ~28 ~2 ~20 ~28 ~2 wool 8 
setblock ~19 ~28 ~1 wool 8  
fill ~19 ~28 ~3 ~21 ~28 ~3 wool 0  
fill ~20 ~28 ~-1 ~20 ~28 ~1 wool 0 
setblock ~20 ~28 ~4 wool 0  
fill ~21 ~28 ~-1 ~22 ~28 ~-1 wool 8  
fill ~21 ~28 ~0 ~21 ~31 ~0 wool 0  
fill ~21 ~28 ~1 ~21 ~30 ~1 wool 8  
fill ~21 ~28 ~2 ~22 ~28 ~2 wool 0 
setblock ~21 ~28 ~4 wool 8  
fill ~22 ~28 ~0 ~24 ~28 ~0 wool 8  
fill ~22 ~28 ~1 ~22 ~31 ~1 wool 0  
fill ~22 ~28 ~3 ~23 ~28 ~3 snow 0  
fill ~23 ~28 ~1 ~23 ~28 ~2 wool 8 
setblock ~23 ~28 ~4 snow 0 
setblock ~24 ~28 ~2 wool 8  
fill ~25 ~28 ~1 ~25 ~28 ~2 snow 0  
fill ~28 ~28 ~24 ~30 ~28 ~24 snow 0  
fill ~28 ~28 ~25 ~30 ~28 ~25 stone 3  
fill ~29 ~28 ~23 ~29 ~30 ~23 stone 3 
setblock ~29 ~28 ~26 snow 0  
fill ~30 ~28 ~22 ~30 ~35 ~22 stone 3  
fill ~30 ~28 ~23 ~30 ~29 ~23 snow 0 
setblock ~31 ~28 ~21 stone 0  
fill ~31 ~28 ~22 ~33 ~28 ~22 wool 0  
fill ~31 ~28 ~23 ~32 ~28 ~23 stone 3  
fill ~31 ~28 ~24 ~31 ~30 ~24 stone 3  
fill ~31 ~28 ~25 ~32 ~28 ~25 snow 0  
fill ~31 ~28 ~26 ~32 ~28 ~26 stone 3  
fill ~32 ~28 ~24 ~33 ~28 ~24 snow 0  
fill ~33 ~28 ~23 ~34 ~28 ~23 wool 0  
fill ~33 ~28 ~25 ~33 ~32 ~25 stone 3  
fill ~0 ~29 ~15 ~0 ~32 ~15 stained_hardened_clay 11  
fill ~1 ~29 ~10 ~1 ~32 ~10 stained_hardened_clay 11  
fill ~1 ~29 ~17 ~1 ~32 ~17 stained_hardened_clay 11  
fill ~1 ~29 ~19 ~1 ~35 ~19 stained_hardened_clay 11  
fill ~1 ~29 ~20 ~1 ~29 ~17 stained_hardened_clay 11  
fill ~2 ~29 ~16 ~2 ~48 ~16 stained_hardened_clay 11  
fill ~3 ~29 ~13 ~13 ~29 ~13 stained_hardened_clay 11  
fill ~5 ~29 ~9 ~6 ~29 ~9 stained_hardened_clay 3  
fill ~5 ~29 ~10 ~12 ~29 ~10 stained_hardened_clay 11  
fill ~5 ~29 ~19 ~9 ~29 ~19 stained_hardened_clay 11  
fill ~6 ~29 ~5 ~6 ~33 ~5 stained_hardened_clay 11  
fill ~7 ~29 ~8 ~11 ~29 ~8 stained_hardened_clay 11  
fill ~7 ~29 ~15 ~12 ~29 ~15 stained_hardened_clay 11  
fill ~7 ~29 ~20 ~7 ~48 ~20 stained_hardened_clay 11  
fill ~8 ~29 ~12 ~13 ~29 ~12 stained_hardened_clay 11  
fill ~10 ~29 ~6 ~10 ~30 ~6 stained_hardened_clay 11  
fill ~10 ~29 ~23 ~11 ~29 ~23 stained_hardened_clay 11  
fill ~13 ~29 ~18 ~13 ~34 ~18 stained_hardened_clay 11  
fill ~14 ~29 ~20 ~14 ~33 ~20 stained_hardened_clay 11  
fill ~19 ~29 ~0 ~19 ~29 ~3 wool 0  
fill ~20 ~29 ~-1 ~20 ~30 ~-1 wool 8  
fill ~20 ~29 ~0 ~20 ~29 ~-1 wool 8  
fill ~20 ~29 ~1 ~20 ~30 ~1 wool 0  
fill ~20 ~29 ~2 ~20 ~29 ~3 wool 8  
fill ~21 ~29 ~-1 ~24 ~29 ~-1 wool 0  
fill ~21 ~29 ~2 ~22 ~29 ~2 wool 0  
fill ~21 ~29 ~3 ~21 ~30 ~3 wool 8 
setblock ~21 ~29 ~4 wool 0  
fill ~22 ~29 ~0 ~23 ~29 ~0 wool 8  
fill ~22 ~29 ~3 ~22 ~31 ~3 wool 0  
fill ~23 ~29 ~1 ~23 ~29 ~3 snow 0  
fill ~23 ~29 ~4 ~23 ~30 ~4 wool 0  
fill ~24 ~29 ~0 ~24 ~31 ~0 wool 0  
fill ~24 ~29 ~1 ~24 ~29 ~-1 wool 0 
setblock ~24 ~29 ~2 snow 0  
fill ~25 ~29 ~0 ~25 ~30 ~0 wool 8  
fill ~25 ~29 ~1 ~26 ~29 ~1 wool 8  
fill ~25 ~29 ~2 ~25 ~29 ~0 wool 8  
fill ~25 ~29 ~3 ~25 ~32 ~3 snow 0  
fill ~29 ~29 ~22 ~29 ~30 ~22 stone 3  
fill ~29 ~29 ~24 ~31 ~29 ~24 stone 3 
setblock ~29 ~29 ~25 snow 0 
setblock ~30 ~29 ~21 stone 0 
setblock ~30 ~29 ~25 stone 3  
fill ~31 ~29 ~21 ~33 ~29 ~21 stone 3  
fill ~31 ~29 ~22 ~31 ~28 ~22 wool 0  
fill ~31 ~29 ~23 ~32 ~29 ~23 wool 0  
fill ~31 ~29 ~25 ~32 ~29 ~25 snow 0 
setblock ~31 ~29 ~26 wool 0  
fill ~32 ~29 ~22 ~34 ~29 ~22 stone 3  
fill ~32 ~29 ~24 ~32 ~28 ~24 snow 0  
fill ~33 ~29 ~23 ~34 ~29 ~23 stone 3 
setblock ~33 ~29 ~24 wool 0  
fill ~-2 ~30 ~10 ~-2 ~36 ~10 stained_hardened_clay 11  
fill ~-1 ~30 ~14 ~-1 ~35 ~14 stained_hardened_clay 11  
fill ~2 ~30 ~9 ~2 ~37 ~9 stained_hardened_clay 11  
fill ~3 ~30 ~13 ~13 ~30 ~13 stained_hardened_clay 11  
fill ~3 ~30 ~18 ~3 ~53 ~18 stained_hardened_clay 11  
fill ~3 ~30 ~20 ~3 ~33 ~20 stained_hardened_clay 11  
fill ~4 ~30 ~23 ~4 ~39 ~23 stained_hardened_clay 11  
fill ~5 ~30 ~9 ~12 ~30 ~9 stained_hardened_clay 11  
fill ~5 ~30 ~10 ~12 ~30 ~10 stained_hardened_clay 11  
fill ~5 ~30 ~19 ~9 ~30 ~19 stained_hardened_clay 11  
fill ~6 ~30 ~8 ~11 ~30 ~8 stained_hardened_clay 11  
fill ~7 ~30 ~15 ~12 ~30 ~15 stained_hardened_clay 11  
fill ~7 ~30 ~23 ~7 ~34 ~23 stained_hardened_clay 11  
fill ~8 ~30 ~12 ~13 ~30 ~12 stained_hardened_clay 11  
fill ~9 ~30 ~6 ~9 ~36 ~6 stained_hardened_clay 11  
fill ~9 ~30 ~7 ~9 ~33 ~7 stained_hardened_clay 11  
fill ~9 ~30 ~22 ~9 ~33 ~22 stained_hardened_clay 11  
fill ~10 ~30 ~4 ~10 ~34 ~4 stained_hardened_clay 11  
fill ~10 ~30 ~23 ~10 ~33 ~23 stained_hardened_clay 11  
fill ~11 ~30 ~7 ~11 ~33 ~7 stained_hardened_clay 11  
fill ~15 ~30 ~10 ~15 ~32 ~10 stained_hardened_clay 11 
setblock ~19 ~30 ~1 wool 0 
setblock ~19 ~30 ~2 wool 8 
setblock ~20 ~30 ~0 wool 0  
fill ~20 ~30 ~2 ~24 ~30 ~2 wool 0 
setblock ~20 ~30 ~3 wool 8  
fill ~21 ~30 ~-1 ~23 ~30 ~-1 wool 8  
fill ~22 ~30 ~0 ~23 ~30 ~0 wool 8 
setblock ~22 ~30 ~4 wool 8 
setblock ~23 ~30 ~1 wool 0  
fill ~23 ~30 ~3 ~24 ~30 ~3 wool 0  
fill ~24 ~30 ~-1 ~24 ~31 ~-1 wool 0  
fill ~24 ~30 ~1 ~25 ~30 ~1 snow 0 
setblock ~24 ~30 ~4 wool 0  
fill ~25 ~30 ~2 ~26 ~30 ~2 snow 0 
setblock ~26 ~30 ~1 wool 8  
fill ~30 ~30 ~21 ~33 ~30 ~21 stone 3  
fill ~30 ~30 ~23 ~32 ~30 ~23 stone 3  
fill ~30 ~30 ~24 ~30 ~30 ~21 stone 3  
fill ~30 ~30 ~25 ~32 ~30 ~25 snow 0  
fill ~31 ~30 ~22 ~32 ~30 ~22 stone 3  
fill ~32 ~30 ~24 ~34 ~30 ~24 stone 3  
fill ~33 ~30 ~22 ~33 ~30 ~23 wool 0  
fill ~34 ~30 ~22 ~34 ~33 ~22 stone 3  
fill ~34 ~30 ~23 ~35 ~30 ~23 stone 3  
fill ~1 ~31 ~14 ~1 ~50 ~14 stained_hardened_clay 11  
fill ~2 ~31 ~12 ~2 ~48 ~12 stained_hardened_clay 11  
fill ~2 ~31 ~17 ~2 ~50 ~17 stained_hardened_clay 11  
fill ~2 ~31 ~18 ~2 ~34 ~18 stained_hardened_clay 11  
fill ~2 ~31 ~19 ~2 ~31 ~12 stained_hardened_clay 11  
fill ~3 ~31 ~5 ~3 ~37 ~5 stained_hardened_clay 11  
fill ~3 ~31 ~13 ~13 ~31 ~13 stained_hardened_clay 11  
fill ~4 ~31 ~19 ~9 ~31 ~19 stained_hardened_clay 11  
fill ~5 ~31 ~9 ~12 ~31 ~9 stained_hardened_clay 11  
fill ~5 ~31 ~10 ~6 ~31 ~10 stained_hardened_clay 3  
fill ~6 ~31 ~7 ~6 ~33 ~7 stained_hardened_clay 11  
fill ~6 ~31 ~8 ~11 ~31 ~8 stained_hardened_clay 11  
fill ~7 ~31 ~10 ~12 ~31 ~10 stained_hardened_clay 11  
fill ~7 ~31 ~15 ~12 ~31 ~15 stained_hardened_clay 11 
setblock ~8 ~31 ~7 stained_hardened_clay 11  
fill ~8 ~31 ~12 ~13 ~31 ~12 stained_hardened_clay 11  
fill ~13 ~31 ~14 ~15 ~31 ~14 stained_hardened_clay 11  
fill ~14 ~31 ~9 ~14 ~36 ~9 stained_hardened_clay 11  
fill ~15 ~31 ~15 ~15 ~34 ~15 stained_hardened_clay 11  
fill ~20 ~31 ~0 ~20 ~31 ~1 wool 8  
fill ~20 ~31 ~2 ~20 ~30 ~2 wool 0 
setblock ~21 ~31 ~1 wool 0 
setblock ~21 ~31 ~2 wool 8 
setblock ~21 ~31 ~3 wool 0 
setblock ~22 ~31 ~-1 wool 8 
setblock ~22 ~31 ~0 wool 0  
fill ~22 ~31 ~2 ~23 ~31 ~2 wool 0  
fill ~23 ~31 ~-1 ~23 ~32 ~-1 wool 0  
fill ~23 ~31 ~0 ~23 ~31 ~1 wool 8  
fill ~23 ~31 ~3 ~23 ~32 ~3 wool 8  
fill ~23 ~31 ~4 ~25 ~31 ~4 snow 0  
fill ~24 ~31 ~1 ~25 ~31 ~1 wool 0  
fill ~24 ~31 ~2 ~26 ~31 ~2 snow 0  
fill ~24 ~31 ~3 ~24 ~31 ~2 snow 0 
setblock ~25 ~31 ~0 wool 0 
setblock ~26 ~31 ~1 snow 0 
setblock ~26 ~31 ~3 wool 8  
fill ~30 ~31 ~23 ~31 ~31 ~23 stone 3  
fill ~30 ~31 ~24 ~32 ~31 ~24 snow 0  
fill ~31 ~31 ~21 ~34 ~31 ~21 stone 3  
fill ~31 ~31 ~22 ~34 ~31 ~22 stone 3  
fill ~31 ~31 ~25 ~32 ~31 ~25 snow 0 
setblock ~32 ~31 ~23 snow 0  
fill ~33 ~31 ~23 ~33 ~34 ~23 stone 3  
fill ~33 ~31 ~24 ~33 ~32 ~24 stone 3  
fill ~34 ~31 ~23 ~34 ~33 ~23 wool 0 
setblock ~35 ~31 ~23 stone 3  
fill ~0 ~32 ~17 ~0 ~36 ~17 stained_hardened_clay 11  
fill ~1 ~32 ~11 ~13 ~32 ~11 stained_hardened_clay 11  
fill ~1 ~32 ~13 ~1 ~48 ~13 stained_hardened_clay 11  
fill ~1 ~32 ~15 ~1 ~53 ~15 stained_hardened_clay 11  
fill ~3 ~32 ~13 ~13 ~32 ~13 stained_hardened_clay 11  
fill ~4 ~32 ~19 ~9 ~32 ~19 stained_hardened_clay 11  
fill ~5 ~32 ~9 ~5 ~42 ~9 stained_hardened_clay 11  
fill ~5 ~32 ~10 ~6 ~32 ~10 stained_hardened_clay 11  
fill ~5 ~32 ~20 ~5 ~50 ~20 stained_hardened_clay 11  
fill ~6 ~32 ~8 ~6 ~33 ~8 stained_hardened_clay 3  
fill ~6 ~32 ~9 ~6 ~33 ~9 stained_hardened_clay 3  
fill ~6 ~32 ~24 ~6 ~36 ~24 stained_hardened_clay 11  
fill ~7 ~32 ~8 ~11 ~32 ~8 stained_hardened_clay 11  
fill ~7 ~32 ~10 ~8 ~32 ~10 stained_hardened_clay 3  
fill ~7 ~32 ~15 ~12 ~32 ~15 stained_hardened_clay 11  
fill ~8 ~32 ~7 ~8 ~35 ~7 stained_hardened_clay 3  
fill ~8 ~32 ~12 ~13 ~32 ~12 stained_hardened_clay 11  
fill ~9 ~32 ~10 ~12 ~32 ~10 stained_hardened_clay 11  
fill ~13 ~32 ~14 ~14 ~32 ~14 stained_hardened_clay 11  
fill ~13 ~32 ~22 ~13 ~37 ~22 stained_hardened_clay 11  
fill ~15 ~32 ~11 ~15 ~36 ~11 stained_hardened_clay 11 
setblock ~21 ~32 ~1 snow 0 
setblock ~21 ~32 ~2 wool 0  
fill ~21 ~32 ~3 ~22 ~32 ~3 snow 0  
fill ~22 ~32 ~0 ~22 ~32 ~1 wool 8 
setblock ~22 ~32 ~2 snow 0  
fill ~23 ~32 ~0 ~23 ~34 ~0 wool 0 
setblock ~23 ~32 ~1 wool 8 
setblock ~23 ~32 ~2 wool 0  
fill ~24 ~32 ~0 ~25 ~32 ~0 stone 0  
fill ~24 ~32 ~1 ~25 ~32 ~1 wool 0  
fill ~24 ~32 ~2 ~27 ~32 ~2 snow 0   

KittysCommands:  
setblock ~24 ~32 ~3 wool 8  
fill ~24 ~32 ~4 ~25 ~32 ~4 snow 0  
fill ~26 ~32 ~0 ~26 ~32 ~1 stone 3  
fill ~26 ~32 ~3 ~27 ~32 ~3 snow 0  
fill ~27 ~32 ~1 ~27 ~33 ~1 snow 0  
fill ~30 ~32 ~23 ~31 ~32 ~23 snow 0  
fill ~30 ~32 ~24 ~30 ~33 ~24 snow 0  
fill ~31 ~32 ~21 ~34 ~32 ~21 stone 3  
fill ~31 ~32 ~22 ~35 ~32 ~22 stone 3  
fill ~31 ~32 ~24 ~31 ~33 ~24 wool 0  
fill ~31 ~32 ~25 ~31 ~28 ~25 snow 0 
setblock ~32 ~32 ~23 stone 3  
fill ~32 ~32 ~24 ~32 ~33 ~24 snow 0 
setblock ~32 ~32 ~25 wool 0  
fill ~35 ~32 ~23 ~35 ~33 ~23 wool 0  
fill ~0 ~33 ~8 ~0 ~40 ~8 stained_hardened_clay 11  
fill ~1 ~33 ~11 ~13 ~33 ~11 stained_hardened_clay 11  
fill ~1 ~33 ~16 ~1 ~48 ~16 stained_hardened_clay 11  
fill ~3 ~33 ~13 ~13 ~33 ~13 stained_hardened_clay 11  
fill ~4 ~33 ~7 ~4 ~40 ~7 stained_hardened_clay 11  
fill ~4 ~33 ~19 ~9 ~33 ~19 stained_hardened_clay 11  
fill ~4 ~33 ~20 ~4 ~34 ~20 stained_hardened_clay 11  
fill ~5 ~33 ~10 ~5 ~41 ~10 stained_hardened_clay 11  
fill ~6 ~33 ~6 ~6 ~34 ~6 stained_hardened_clay 11 
setblock ~6 ~33 ~10 stained_hardened_clay 3  
fill ~7 ~33 ~8 ~10 ~33 ~8 stained_hardened_clay 11  
fill ~7 ~33 ~10 ~12 ~33 ~10 stained_hardened_clay 11  
fill ~7 ~33 ~15 ~12 ~33 ~15 stained_hardened_clay 11  
fill ~8 ~33 ~12 ~13 ~33 ~12 stained_hardened_clay 11  
fill ~9 ~33 ~21 ~9 ~37 ~21 stained_hardened_clay 11 
setblock ~11 ~33 ~8 stained_hardened_clay 3  
fill ~11 ~33 ~23 ~11 ~39 ~23 stained_hardened_clay 11  
fill ~12 ~33 ~7 ~12 ~34 ~7 stained_hardened_clay 11  
fill ~12 ~33 ~8 ~12 ~35 ~8 stained_hardened_clay 11  
fill ~13 ~33 ~14 ~14 ~33 ~14 stained_hardened_clay 11  
fill ~15 ~33 ~20 ~15 ~37 ~20 stained_hardened_clay 11  
fill ~21 ~33 ~1 ~23 ~33 ~1 wool 0  
fill ~21 ~33 ~2 ~22 ~33 ~2 wool 8 
setblock ~22 ~33 ~0 wool 0  
fill ~22 ~33 ~3 ~22 ~34 ~3 snow 0  
fill ~23 ~33 ~2 ~24 ~33 ~2 snow 0 
setblock ~23 ~33 ~3 wool 0  
fill ~24 ~33 ~0 ~26 ~33 ~0 stone 0  
fill ~24 ~33 ~1 ~24 ~33 ~0 stone 0 
setblock ~24 ~33 ~3 snow 0 
setblock ~25 ~33 ~1 snow 0  
fill ~25 ~33 ~2 ~26 ~33 ~2 wool 0  
fill ~25 ~33 ~3 ~25 ~34 ~3 wool 0  
fill ~25 ~33 ~4 ~26 ~33 ~4 snow 0  
fill ~26 ~33 ~1 ~26 ~34 ~1 wool 0  
fill ~26 ~33 ~3 ~26 ~34 ~3 stone 3 
setblock ~27 ~33 ~2 stone 0  
fill ~27 ~33 ~3 ~27 ~38 ~3 snow 0  
fill ~30 ~33 ~23 ~31 ~33 ~23 stone 3 
setblock ~31 ~33 ~21 snow 0  
fill ~31 ~33 ~22 ~31 ~35 ~22 stone 3  
fill ~32 ~33 ~21 ~33 ~33 ~21 stone 3  
fill ~32 ~33 ~22 ~32 ~33 ~25 snow 0 
setblock ~33 ~33 ~22 stone 3  
fill ~33 ~33 ~24 ~33 ~33 ~25 wool 0 
setblock ~34 ~33 ~21 wool 0  
fill ~35 ~33 ~22 ~35 ~34 ~22 wool 0 
setblock ~35 ~33 ~24 stone 3  
fill ~0 ~34 ~14 ~0 ~50 ~14 stained_hardened_clay 11  
fill ~0 ~34 ~15 ~0 ~50 ~15 stained_hardened_clay 11 
setblock ~1 ~34 ~12 stained_hardened_clay 11  
fill ~2 ~34 ~11 ~2 ~44 ~11 stained_hardened_clay 11  
fill ~3 ~34 ~13 ~13 ~34 ~13 stained_hardened_clay 11 
setblock ~4 ~34 ~10 stained_hardened_clay 3  
fill ~4 ~34 ~19 ~8 ~34 ~19 stained_hardened_clay 11  
fill ~6 ~34 ~8 ~12 ~34 ~8 stained_hardened_clay 11  
fill ~6 ~34 ~9 ~6 ~34 ~20 stained_hardened_clay 11  
fill ~7 ~34 ~9 ~9 ~34 ~9 stained_hardened_clay 3  
fill ~7 ~34 ~10 ~7 ~34 ~9 stained_hardened_clay 3  
fill ~7 ~34 ~15 ~12 ~34 ~15 stained_hardened_clay 11  
fill ~7 ~34 ~22 ~7 ~42 ~22 stained_hardened_clay 11  
fill ~8 ~34 ~10 ~13 ~34 ~10 stained_hardened_clay 11  
fill ~8 ~34 ~12 ~13 ~34 ~12 stained_hardened_clay 11 
setblock ~9 ~34 ~7 stained_hardened_clay 3  
fill ~11 ~34 ~4 ~11 ~39 ~4 stained_hardened_clay 11  
fill ~13 ~34 ~14 ~15 ~34 ~14 stained_hardened_clay 11  
fill ~14 ~34 ~18 ~14 ~41 ~18 stained_hardened_clay 11 
setblock ~15 ~34 ~10 stained_hardened_clay 11  
fill ~16 ~34 ~17 ~16 ~38 ~17 stained_hardened_clay 11  
fill ~21 ~34 ~1 ~22 ~34 ~1 snow 0  
fill ~21 ~34 ~2 ~23 ~34 ~2 snow 0 
setblock ~22 ~34 ~0 snow 0 
setblock ~23 ~34 ~1 stone 0  
fill ~23 ~34 ~3 ~23 ~36 ~3 snow 0  
fill ~24 ~34 ~0 ~26 ~34 ~0 stone 3  
fill ~24 ~34 ~1 ~24 ~38 ~1 snow 0  
fill ~24 ~34 ~2 ~24 ~34 ~3 wool 0  
fill ~25 ~34 ~1 ~25 ~34 ~2 stone 3  
fill ~25 ~34 ~4 ~25 ~35 ~4 snow 0 
setblock ~26 ~34 ~2 wool 0 
setblock ~26 ~34 ~4 stone 0 
setblock ~27 ~34 ~1 stone 3  
fill ~27 ~34 ~2 ~28 ~34 ~2 snow 0 
setblock ~28 ~34 ~3 stone 0  
fill ~30 ~34 ~23 ~30 ~33 ~23 stone 3  
fill ~31 ~34 ~21 ~32 ~34 ~21 stone 3 
setblock ~31 ~34 ~23 wool 0  
fill ~31 ~34 ~24 ~31 ~35 ~24 snow 0  
fill ~32 ~34 ~22 ~32 ~34 ~25 stone 3  
fill ~33 ~34 ~21 ~33 ~35 ~21 wool 0  
fill ~33 ~34 ~22 ~35 ~34 ~22 wool 0  
fill ~33 ~34 ~24 ~33 ~35 ~24 stone 3  
fill ~33 ~34 ~25 ~33 ~37 ~25 wool 0 
setblock ~34 ~34 ~21 stone 3  
fill ~34 ~34 ~23 ~35 ~34 ~23 stone 3 
setblock ~35 ~34 ~24 wool 0  
fill ~0 ~35 ~19 ~0 ~41 ~19 stained_hardened_clay 11  
fill ~3 ~35 ~13 ~14 ~35 ~13 stained_hardened_clay 11  
fill ~4 ~35 ~9 ~4 ~36 ~9 stained_hardened_clay 11  
fill ~4 ~35 ~10 ~4 ~41 ~10 stained_hardened_clay 11  
fill ~4 ~35 ~19 ~8 ~35 ~19 stained_hardened_clay 11  
fill ~6 ~35 ~6 ~6 ~36 ~6 stained_hardened_clay 3  
fill ~6 ~35 ~8 ~6 ~36 ~8 stained_hardened_clay 3  
fill ~6 ~35 ~9 ~6 ~35 ~11 stained_hardened_clay 3  
fill ~7 ~35 ~7 ~7 ~41 ~7 stained_hardened_clay 11  
fill ~7 ~35 ~8 ~7 ~40 ~8 stained_hardened_clay 11  
fill ~7 ~35 ~9 ~7 ~42 ~9 stained_hardened_clay 11  
fill ~7 ~35 ~10 ~13 ~35 ~10 stained_hardened_clay 11  
fill ~7 ~35 ~15 ~13 ~35 ~15 stained_hardened_clay 11  
fill ~8 ~35 ~8 ~8 ~35 ~9 stained_hardened_clay 3  
fill ~8 ~35 ~12 ~16 ~35 ~12 stained_hardened_clay 11  
fill ~8 ~35 ~24 ~8 ~41 ~24 stained_hardened_clay 11  
fill ~9 ~35 ~7 ~9 ~47 ~7 stained_hardened_clay 11  
fill ~9 ~35 ~8 ~9 ~47 ~8 stained_hardened_clay 11  
fill ~9 ~35 ~9 ~9 ~61 ~9 stained_hardened_clay 11  
fill ~11 ~35 ~8 ~11 ~40 ~8 stained_hardened_clay 11  
fill ~12 ~35 ~7 ~12 ~37 ~7 stained_hardened_clay 3  
fill ~13 ~35 ~9 ~13 ~38 ~9 stained_hardened_clay 11  
fill ~13 ~35 ~14 ~14 ~35 ~14 stained_hardened_clay 11  
fill ~15 ~35 ~9 ~15 ~37 ~9 stained_hardened_clay 11 
setblock ~22 ~35 ~1 wool 0  
fill ~22 ~35 ~2 ~22 ~36 ~2 snow 0 
setblock ~22 ~35 ~3 wool 0  
fill ~23 ~35 ~0 ~24 ~35 ~0 stone 3  
fill ~23 ~35 ~1 ~23 ~37 ~1 snow 0 
setblock ~23 ~35 ~2 stone 0  
fill ~24 ~35 ~2 ~26 ~35 ~2 snow 0  
fill ~24 ~35 ~3 ~27 ~35 ~3 snow 0  
fill ~25 ~35 ~0 ~25 ~35 ~4 snow 0  
fill ~26 ~35 ~0 ~27 ~35 ~0 wool 0 
setblock ~26 ~35 ~1 stone 3 
setblock ~26 ~35 ~4 snow 0  
fill ~27 ~35 ~1 ~28 ~35 ~1 snow 0  
fill ~27 ~35 ~2 ~27 ~36 ~2 wool 0 
setblock ~27 ~35 ~4 wool 0  
fill ~28 ~35 ~2 ~28 ~37 ~2 stone 3  
fill ~28 ~35 ~3 ~29 ~35 ~3 wool 0  
fill ~29 ~35 ~1 ~29 ~36 ~1 stone 3 
setblock ~29 ~35 ~2 snow 0  
fill ~30 ~35 ~23 ~30 ~36 ~23 wool 0  
fill ~31 ~35 ~21 ~31 ~36 ~21 stone 3  
fill ~31 ~35 ~23 ~32 ~35 ~23 stone 3  
fill ~32 ~35 ~21 ~32 ~36 ~21 wool 8  
fill ~32 ~35 ~22 ~34 ~35 ~22 wool 0 
setblock ~32 ~35 ~24 stone 3  
fill ~32 ~35 ~25 ~32 ~37 ~25 wool 0 
setblock ~33 ~35 ~23 snow 0  
fill ~34 ~35 ~21 ~34 ~36 ~21 wool 0  
fill ~34 ~35 ~23 ~35 ~35 ~23 stone 3 
setblock ~34 ~35 ~24 snow 0 
setblock ~34 ~35 ~25 wool 0  
fill ~35 ~35 ~21 ~35 ~35 ~24 stone 3  
fill ~36 ~35 ~22 ~36 ~36 ~22 wool 0  
fill ~36 ~35 ~23 ~36 ~35 ~22 wool 0 
setblock ~36 ~35 ~24 stone 3  
fill ~-2 ~36 ~11 ~-2 ~43 ~11 stained_hardened_clay 11  
fill ~-1 ~36 ~16 ~-1 ~40 ~16 stained_hardened_clay 11  
fill ~-1 ~36 ~17 ~-1 ~36 ~16 stained_hardened_clay 11  
fill ~1 ~36 ~12 ~1 ~47 ~12 stained_hardened_clay 11  
fill ~2 ~36 ~18 ~2 ~48 ~18 stained_hardened_clay 11  
fill ~3 ~36 ~10 ~3 ~41 ~10 stained_hardened_clay 11  
fill ~3 ~36 ~13 ~14 ~36 ~13 stained_hardened_clay 11  
fill ~4 ~36 ~19 ~8 ~36 ~19 stained_hardened_clay 11  
fill ~5 ~36 ~8 ~5 ~39 ~8 stained_hardened_clay 11  
fill ~6 ~36 ~9 ~6 ~42 ~9 stained_hardened_clay 11  
fill ~6 ~36 ~10 ~13 ~36 ~10 stained_hardened_clay 11  
fill ~6 ~36 ~11 ~6 ~61 ~11 stained_hardened_clay 11  
fill ~6 ~36 ~25 ~6 ~43 ~25 stained_hardened_clay 11  
fill ~7 ~36 ~5 ~7 ~38 ~5 stained_hardened_clay 11  
fill ~7 ~36 ~15 ~13 ~36 ~15 stained_hardened_clay 11  
fill ~8 ~36 ~7 ~8 ~36 ~19 stained_hardened_clay 11  
fill ~9 ~36 ~12 ~9 ~65 ~12 stained_hardened_clay 11  
fill ~10 ~36 ~6 ~10 ~38 ~6 stained_hardened_clay 11  
fill ~10 ~36 ~7 ~10 ~38 ~7 stained_hardened_clay 3  
fill ~11 ~36 ~12 ~15 ~36 ~12 stained_hardened_clay 11  
fill ~12 ~36 ~8 ~12 ~36 ~9 stained_hardened_clay 3  
fill ~12 ~36 ~20 ~12 ~38 ~20 stained_hardened_clay 11  
fill ~13 ~36 ~14 ~14 ~36 ~14 stained_hardened_clay 11 
setblock ~14 ~36 ~8 stained_hardened_clay 11  
fill ~14 ~36 ~11 ~14 ~39 ~11 stained_hardened_clay 11  
fill ~16 ~36 ~11 ~16 ~38 ~11 stained_hardened_clay 11 
setblock ~23 ~36 ~2 snow 0 
setblock ~24 ~36 ~0 snow 0  
fill ~24 ~36 ~2 ~25 ~36 ~2 stone 3  
fill ~24 ~36 ~3 ~27 ~36 ~3 snow 0 
setblock ~25 ~36 ~0 wool 0  
fill ~25 ~36 ~1 ~26 ~36 ~1 snow 0 
setblock ~25 ~36 ~4 stone 3 
setblock ~26 ~36 ~0 stone 3 
setblock ~26 ~36 ~2 wool 0 
setblock ~26 ~36 ~4 wool 0 
setblock ~27 ~36 ~0 wool 0  
fill ~27 ~36 ~1 ~29 ~36 ~1 stone 3  
fill ~27 ~36 ~4 ~27 ~39 ~4 snow 0  
fill ~28 ~36 ~0 ~28 ~37 ~0 stone 3  
fill ~28 ~36 ~3 ~30 ~36 ~3 stone 3  
fill ~28 ~36 ~4 ~29 ~36 ~4 wool 0  
fill ~29 ~36 ~2 ~30 ~36 ~2 stone 3  
fill ~30 ~36 ~22 ~30 ~38 ~22 wool 8  
fill ~31 ~36 ~22 ~34 ~36 ~22 wool 0  
fill ~31 ~36 ~23 ~36 ~36 ~23 stone 3  
fill ~31 ~36 ~24 ~33 ~36 ~24 wool 0 
setblock ~33 ~36 ~21 wool 8  
fill ~34 ~36 ~24 ~34 ~36 ~25 stone 3  
fill ~35 ~36 ~21 ~35 ~38 ~21 wool 0 
setblock ~35 ~36 ~22 stone 3  
fill ~35 ~36 ~24 ~36 ~36 ~24 wool 0  
fill ~35 ~36 ~25 ~35 ~46 ~25 wool 0 
setblock ~36 ~36 ~21 stone 3  
fill ~37 ~36 ~22 ~37 ~36 ~23 wool 0  
fill ~1 ~37 ~9 ~1 ~43 ~9 stained_hardened_clay 11  
fill ~1 ~37 ~17 ~1 ~49 ~17 stained_hardened_clay 11  
fill ~2 ~37 ~19 ~8 ~37 ~19 stained_hardened_clay 11  
fill ~3 ~37 ~6 ~3 ~40 ~6 stained_hardened_clay 11  
fill ~3 ~37 ~13 ~14 ~37 ~13 stained_hardened_clay 11  
fill ~4 ~37 ~9 ~4 ~38 ~9 stained_hardened_clay 3  
fill ~6 ~37 ~6 ~6 ~39 ~6 stained_hardened_clay 11  
fill ~6 ~37 ~8 ~6 ~39 ~8 stained_hardened_clay 11  
fill ~6 ~37 ~10 ~13 ~37 ~10 stained_hardened_clay 11  
fill ~7 ~37 ~15 ~13 ~37 ~15 stained_hardened_clay 11  
fill ~8 ~37 ~6 ~8 ~37 ~7 stained_hardened_clay 3  
fill ~8 ~37 ~8 ~8 ~37 ~19 stained_hardened_clay 11  
fill ~9 ~37 ~20 ~9 ~39 ~20 stained_hardened_clay 11  
fill ~11 ~37 ~12 ~15 ~37 ~12 stained_hardened_clay 11  
fill ~12 ~37 ~8 ~13 ~37 ~8 stained_hardened_clay 11  
fill ~12 ~37 ~9 ~12 ~39 ~9 stained_hardened_clay 3 
setblock ~13 ~37 ~7 stained_hardened_clay 11  
fill ~13 ~37 ~14 ~14 ~37 ~14 stained_hardened_clay 11  
fill ~13 ~37 ~23 ~13 ~43 ~23 stained_hardened_clay 11 
setblock ~14 ~37 ~8 stained_hardened_clay 3  
fill ~15 ~37 ~19 ~15 ~40 ~19 stained_hardened_clay 11  
fill ~16 ~37 ~9 ~16 ~41 ~9 stained_hardened_clay 11  
fill ~23 ~37 ~2 ~24 ~37 ~2 stone 3 
setblock ~24 ~37 ~0 wool 0  
fill ~24 ~37 ~3 ~27 ~37 ~3 snow 0  
fill ~25 ~37 ~0 ~26 ~37 ~0 snow 0  
fill ~25 ~37 ~1 ~26 ~37 ~1 wool 0  
fill ~25 ~37 ~2 ~27 ~37 ~2 snow 0  
fill ~25 ~37 ~4 ~27 ~37 ~4 snow 0  
fill ~27 ~37 ~0 ~27 ~39 ~0 stone 3 
setblock ~27 ~37 ~1 snow 0 
setblock ~28 ~37 ~1 stone 3  
fill ~28 ~37 ~3 ~28 ~38 ~3 stone 3  
fill ~28 ~37 ~4 ~30 ~37 ~4 stone 3  
fill ~29 ~37 ~0 ~29 ~37 ~1 wool 0  
fill ~29 ~37 ~2 ~31 ~37 ~2 stone 3 
setblock ~29 ~37 ~3 wool 0  
fill ~30 ~37 ~1 ~30 ~40 ~1 stone 3  
fill ~30 ~37 ~3 ~31 ~37 ~3 stone 3  
fill ~30 ~37 ~23 ~31 ~37 ~23 wool 8  
fill ~31 ~37 ~21 ~31 ~42 ~21 wool 8  
fill ~31 ~37 ~22 ~33 ~37 ~22 wool 0  
fill ~31 ~37 ~24 ~31 ~36 ~24 wool 0  
fill ~32 ~37 ~21 ~33 ~37 ~21 wool 0  
fill ~32 ~37 ~23 ~33 ~37 ~23 wool 0 
setblock ~32 ~37 ~24 stone 3  
fill ~33 ~37 ~20 ~33 ~50 ~20 wool 8  
fill ~33 ~37 ~24 ~34 ~37 ~24 wool 0  
fill ~34 ~37 ~20 ~35 ~37 ~20 stone 3  
fill ~34 ~37 ~21 ~34 ~37 ~23 stone 3 
setblock ~34 ~37 ~25 stone 3  
fill ~35 ~37 ~22 ~35 ~37 ~23 wool 0 
setblock ~35 ~37 ~24 stone 3  
fill ~36 ~37 ~21 ~37 ~37 ~21 wool 0  
fill ~36 ~37 ~22 ~37 ~37 ~22 stone 3  
fill ~36 ~37 ~23 ~37 ~37 ~23 wool 0  
fill ~36 ~37 ~24 ~36 ~37 ~25 wool 0  
fill ~37 ~37 ~24 ~38 ~37 ~24 stone 3 
setblock ~38 ~37 ~22 wool 0  
fill ~38 ~37 ~23 ~38 ~39 ~23 stone 3  
fill ~107 ~37 ~23 ~111 ~37 ~23 wool 7  
fill ~0 ~38 ~13 ~0 ~47 ~13 stained_hardened_clay 11  
fill ~2 ~38 ~19 ~8 ~38 ~19 stained_hardened_clay 11  
fill ~3 ~38 ~13 ~15 ~38 ~13 stained_hardened_clay 11  
fill ~4 ~38 ~20 ~4 ~48 ~20 stained_hardened_clay 11 
setblock ~5 ~38 ~6 stained_hardened_clay 11  
fill ~6 ~38 ~10 ~11 ~38 ~10 stained_hardened_clay 11  
fill ~7 ~38 ~3 ~7 ~42 ~3 stained_hardened_clay 11  
fill ~7 ~38 ~15 ~13 ~38 ~15 stained_hardened_clay 11  
fill ~8 ~38 ~6 ~8 ~41 ~6 stained_hardened_clay 11  
fill ~8 ~38 ~7 ~8 ~46 ~7 stained_hardened_clay 11 
setblock ~8 ~38 ~8 stained_hardened_clay 3  
fill ~8 ~38 ~9 ~8 ~42 ~9 stained_hardened_clay 11  
fill ~8 ~38 ~12 ~8 ~63 ~12 stained_hardened_clay 11 
setblock ~10 ~38 ~8 stained_hardened_clay 3  
fill ~11 ~38 ~6 ~11 ~44 ~6 stained_hardened_clay 11  
fill ~11 ~38 ~12 ~15 ~38 ~12 stained_hardened_clay 11  
fill ~12 ~38 ~8 ~12 ~37 ~8 stained_hardened_clay 11  
fill ~12 ~38 ~10 ~12 ~41 ~10 stained_hardened_clay 3  
fill ~13 ~38 ~7 ~13 ~40 ~7 stained_hardened_clay 3  
fill ~13 ~38 ~10 ~13 ~63 ~10 stained_hardened_clay 11 
setblock ~13 ~38 ~11 stained_hardened_clay 3  
fill ~13 ~38 ~14 ~15 ~38 ~14 stained_hardened_clay 11  
fill ~13 ~38 ~16 ~13 ~61 ~16 stained_hardened_clay 11  
fill ~13 ~38 ~20 ~13 ~43 ~20 stained_hardened_clay 11  
fill ~14 ~38 ~8 ~14 ~41 ~8 stained_hardened_clay 11  
fill ~14 ~38 ~21 ~14 ~42 ~21 stained_hardened_clay 11  
fill ~17 ~38 ~11 ~17 ~44 ~11 stained_hardened_clay 11  
fill ~17 ~38 ~17 ~17 ~45 ~17 stained_hardened_clay 11 
setblock ~24 ~38 ~2 wool 0  
fill ~24 ~38 ~3 ~24 ~35 ~3 snow 0  
fill ~25 ~38 ~1 ~25 ~38 ~2 snow 0  
fill ~25 ~38 ~3 ~25 ~40 ~3 stone 3 
setblock ~25 ~38 ~4 wool 0  
fill ~26 ~38 ~0 ~26 ~38 ~1 wool 0  
fill ~26 ~38 ~2 ~26 ~39 ~2 snow 0  
fill ~26 ~38 ~3 ~26 ~39 ~3 snow 0 
setblock ~26 ~38 ~4 stone 3  
fill ~27 ~38 ~1 ~27 ~38 ~2 stone 3  
fill ~28 ~38 ~0 ~28 ~39 ~0 wool 0  
fill ~28 ~38 ~1 ~28 ~40 ~1 wool 0  
fill ~28 ~38 ~2 ~28 ~38 ~0 wool 0  
fill ~28 ~38 ~4 ~31 ~38 ~4 stone 3  
fill ~29 ~38 ~0 ~30 ~38 ~0 stone 3  
fill ~29 ~38 ~1 ~29 ~43 ~1 stone 3  
fill ~29 ~38 ~2 ~32 ~38 ~2 stone 3  
fill ~29 ~38 ~3 ~32 ~38 ~3 stone 3  
fill ~30 ~38 ~23 ~30 ~40 ~23 wool 8 
setblock ~31 ~38 ~1 stone 3  
fill ~31 ~38 ~22 ~31 ~39 ~22 stone 3  
fill ~31 ~38 ~23 ~31 ~39 ~23 wool 0 
setblock ~31 ~38 ~24 stone 3  
fill ~32 ~38 ~20 ~32 ~40 ~20 wool 8  
fill ~32 ~38 ~21 ~33 ~38 ~21 stone 3 
setblock ~32 ~38 ~22 wool 8 
setblock ~32 ~38 ~23 stone 3  
fill ~32 ~38 ~24 ~35 ~38 ~24 wool 0  
fill ~32 ~38 ~25 ~33 ~38 ~25 stone 3  
fill ~33 ~38 ~22 ~33 ~38 ~24 wool 0 
setblock ~34 ~38 ~20 wool 8  
fill ~34 ~38 ~21 ~34 ~40 ~21 wool 0  
fill ~34 ~38 ~22 ~35 ~38 ~22 stone 3  
fill ~34 ~38 ~23 ~34 ~40 ~23 wool 0 
setblock ~34 ~38 ~25 wool 0  
fill ~35 ~38 ~20 ~36 ~38 ~20 stone 3  
fill ~35 ~38 ~23 ~36 ~38 ~23 stone 3  
fill ~36 ~38 ~21 ~36 ~39 ~21 wool 0  
fill ~36 ~38 ~22 ~36 ~42 ~22 wool 0  
fill ~36 ~38 ~24 ~36 ~39 ~24 stone 3  
fill ~36 ~38 ~25 ~37 ~38 ~25 wool 0  
fill ~37 ~38 ~21 ~38 ~38 ~21 stone 3  
fill ~37 ~38 ~22 ~38 ~38 ~22 stone 3  
fill ~37 ~38 ~23 ~37 ~40 ~23 wool 0  
fill ~37 ~38 ~24 ~37 ~38 ~23 wool 0  
fill ~38 ~38 ~24 ~39 ~38 ~24 stone 3  
fill ~39 ~38 ~23 ~39 ~40 ~23 stone 3  
fill ~107 ~38 ~22 ~110 ~38 ~22 wool 7  
fill ~107 ~38 ~23 ~112 ~38 ~23 wool 7  
fill ~108 ~38 ~24 ~111 ~38 ~24 wool 7 
setblock ~111 ~38 ~22 stained_hardened_clay 9  
fill ~1 ~39 ~18 ~1 ~48 ~18 stained_hardened_clay 11  
fill ~2 ~39 ~19 ~8 ~39 ~19 stained_hardened_clay 11  
fill ~3 ~39 ~13 ~15 ~39 ~13 stained_hardened_clay 11  
fill ~4 ~39 ~9 ~4 ~40 ~9 stained_hardened_clay 11  
fill ~5 ~39 ~6 ~5 ~41 ~6 stained_hardened_clay 3  
fill ~5 ~39 ~23 ~5 ~43 ~23 stained_hardened_clay 11  
fill ~6 ~39 ~10 ~11 ~39 ~10 stained_hardened_clay 11  
fill ~7 ~39 ~5 ~7 ~40 ~5 stained_hardened_clay 3  
fill ~7 ~39 ~15 ~14 ~39 ~15 stained_hardened_clay 11  
fill ~8 ~39 ~8 ~8 ~42 ~8 stained_hardened_clay 11  
fill ~8 ~39 ~20 ~8 ~47 ~20 stained_hardened_clay 11  
fill ~10 ~39 ~8 ~10 ~45 ~8 stained_hardened_clay 11  
fill ~11 ~39 ~12 ~15 ~39 ~12 stained_hardened_clay 11  
fill ~11 ~39 ~17 ~11 ~58 ~17 stained_hardened_clay 11  
fill ~11 ~39 ~22 ~11 ~45 ~22 stained_hardened_clay 11  
fill ~12 ~39 ~11 ~12 ~41 ~11 stained_hardened_clay 3  
fill ~13 ~39 ~11 ~13 ~40 ~11 stained_hardened_clay 11  
fill ~13 ~39 ~14 ~15 ~39 ~14 stained_hardened_clay 11  
fill ~14 ~39 ~16 ~14 ~40 ~16 stained_hardened_clay 11 
setblock ~25 ~39 ~1 stone 3  
fill ~25 ~39 ~2 ~25 ~40 ~2 snow 0  
fill ~26 ~39 ~1 ~28 ~39 ~1 wool 0 
setblock ~26 ~39 ~4 wool 0  
fill ~27 ~39 ~2 ~28 ~39 ~2 stone 3  
fill ~27 ~39 ~3 ~27 ~39 ~2 stone 3 
setblock ~28 ~39 ~3 wool 0  
fill ~28 ~39 ~4 ~32 ~39 ~4 stone 3  
fill ~28 ~39 ~5 ~30 ~39 ~5 stone 3  
fill ~29 ~39 ~0 ~30 ~39 ~0 stone 3  
fill ~29 ~39 ~2 ~29 ~40 ~2 wool 0  
fill ~29 ~39 ~3 ~31 ~39 ~3 stone 3  
fill ~30 ~39 ~2 ~32 ~39 ~2 stone 3 
setblock ~30 ~39 ~22 stone 3  
fill ~31 ~39 ~1 ~31 ~47 ~1 wool 0  
fill ~31 ~39 ~20 ~31 ~40 ~20 wool 8 
setblock ~31 ~39 ~24 wool 8  
fill ~32 ~39 ~1 ~33 ~39 ~1 stone 3 
setblock ~32 ~39 ~3 wool 0  
fill ~32 ~39 ~19 ~33 ~39 ~19 wool 8  
fill ~32 ~39 ~21 ~32 ~38 ~21 stone 3  
fill ~32 ~39 ~22 ~32 ~40 ~22 wool 0  
fill ~32 ~39 ~23 ~37 ~39 ~23 wool 0  
fill ~32 ~39 ~24 ~35 ~39 ~24 wool 0  
fill ~32 ~39 ~25 ~32 ~40 ~25 wool 0  
fill ~33 ~39 ~2 ~34 ~39 ~2 wool 0  
fill ~33 ~39 ~3 ~33 ~42 ~3 stone 3  
fill ~33 ~39 ~21 ~33 ~40 ~21 wool 0 
setblock ~33 ~39 ~22 stone 3  
fill ~33 ~39 ~25 ~34 ~39 ~25 stone 3  
fill ~33 ~39 ~26 ~33 ~46 ~26 wool 0  
fill ~34 ~39 ~19 ~36 ~39 ~19 stone 0  
fill ~34 ~39 ~20 ~37 ~39 ~20 stone 3  
fill ~34 ~39 ~22 ~36 ~39 ~22 wool 0 
setblock ~34 ~39 ~26 stone 3  
fill ~35 ~39 ~2 ~35 ~41 ~2 stone 3 
setblock ~35 ~39 ~21 stone 3  
fill ~35 ~39 ~26 ~35 ~47 ~26 wool 0 
setblock ~36 ~39 ~25 stone 3  
fill ~37 ~39 ~21 ~38 ~39 ~21 stone 3  
fill ~37 ~39 ~22 ~37 ~41 ~22 stone 3 
setblock ~37 ~39 ~24 stone 3  
fill ~37 ~39 ~25 ~38 ~39 ~25 wool 0 
setblock ~38 ~39 ~22 wool 0  
fill ~38 ~39 ~24 ~38 ~44 ~24 wool 0 
setblock ~39 ~39 ~22 stone 3  
fill ~39 ~39 ~24 ~40 ~39 ~24 stone 3  
fill ~40 ~39 ~23 ~40 ~40 ~23 stone 3  
fill ~107 ~39 ~22 ~111 ~39 ~22 wool 7  
fill ~107 ~39 ~23 ~109 ~39 ~23 wool 7  
fill ~107 ~39 ~24 ~109 ~39 ~24 wool 7  
fill ~108 ~39 ~21 ~109 ~39 ~21 wool 7  
fill ~110 ~39 ~21 ~110 ~43 ~21 stained_hardened_clay 9  
fill ~110 ~39 ~23 ~113 ~39 ~23 stained_hardened_clay 9  
fill ~110 ~39 ~24 ~112 ~39 ~24 stained_hardened_clay 9  
fill ~112 ~39 ~22 ~112 ~40 ~22 stained_hardened_clay 9  
fill ~-1 ~40 ~15 ~-1 ~46 ~15 stained_hardened_clay 11  
fill ~0 ~40 ~9 ~0 ~41 ~9 stained_hardened_clay 11  
fill ~1 ~40 ~20 ~1 ~47 ~20 stained_hardened_clay 11  
fill ~2 ~40 ~19 ~9 ~40 ~19 stained_hardened_clay 11  
fill ~3 ~40 ~8 ~3 ~41 ~8 stained_hardened_clay 11  
fill ~3 ~40 ~13 ~14 ~40 ~13 stained_hardened_clay 11  
fill ~3 ~40 ~20 ~3 ~45 ~20 stained_hardened_clay 11  
fill ~4 ~40 ~6 ~4 ~45 ~6 stained_hardened_clay 11  
fill ~5 ~40 ~8 ~6 ~40 ~8 stained_hardened_clay 3  
fill ~6 ~40 ~10 ~11 ~40 ~10 stained_hardened_clay 11  
fill ~6 ~40 ~22 ~6 ~41 ~22 stained_hardened_clay 11  
fill ~7 ~40 ~15 ~14 ~40 ~15 stained_hardened_clay 11  
fill ~9 ~40 ~6 ~9 ~42 ~6 stained_hardened_clay 11  
fill ~10 ~40 ~18 ~10 ~57 ~18 stained_hardened_clay 11  
fill ~11 ~40 ~4 ~11 ~41 ~4 stained_hardened_clay 3  
fill ~11 ~40 ~11 ~11 ~41 ~11 stained_hardened_clay 3  
fill ~11 ~40 ~12 ~15 ~40 ~12 stained_hardened_clay 11  
fill ~12 ~40 ~9 ~12 ~43 ~9 stained_hardened_clay 11  
fill ~13 ~40 ~14 ~14 ~40 ~14 stained_hardened_clay 11  
fill ~15 ~40 ~8 ~15 ~43 ~8 stained_hardened_clay 11  
fill ~16 ~40 ~19 ~16 ~43 ~19 stained_hardened_clay 11  
fill ~26 ~40 ~1 ~27 ~40 ~1 stone 3  
fill ~26 ~40 ~2 ~27 ~40 ~2 stone 3  
fill ~26 ~40 ~3 ~26 ~41 ~3 stone 3  
fill ~26 ~40 ~4 ~28 ~40 ~4 stone 3 
setblock ~27 ~40 ~3 wool 0 
setblock ~27 ~40 ~5 snow 0  
fill ~28 ~40 ~0 ~29 ~40 ~0 stone 3  
fill ~28 ~40 ~2 ~28 ~41 ~2 wool 0  
fill ~28 ~40 ~3 ~28 ~41 ~3 stone 3  
fill ~28 ~40 ~5 ~28 ~39 ~5 stone 3  
fill ~29 ~40 ~3 ~30 ~40 ~3 wool 0  
fill ~29 ~40 ~4 ~30 ~40 ~4 wool 0  
fill ~29 ~40 ~5 ~30 ~40 ~5 wool 0  
fill ~30 ~40 ~0 ~33 ~40 ~0 wool 0  
fill ~30 ~40 ~2 ~32 ~40 ~2 wool 0  
fill ~30 ~40 ~21 ~30 ~41 ~21 wool 8  
fill ~30 ~40 ~22 ~31 ~40 ~22 wool 8 
setblock ~30 ~40 ~24 wool 8  
fill ~31 ~40 ~3 ~34 ~40 ~3 stone 3  
fill ~31 ~40 ~4 ~33 ~40 ~4 stone 3  
fill ~31 ~40 ~5 ~31 ~47 ~5 stone 3  
fill ~31 ~40 ~23 ~32 ~40 ~23 wool 8  
fill ~31 ~40 ~24 ~34 ~40 ~24 wool 0  
fill ~32 ~40 ~1 ~32 ~41 ~1 wool 0  
fill ~32 ~40 ~19 ~34 ~40 ~19 wool 8  
fill ~32 ~40 ~21 ~32 ~41 ~21 wool 8  
fill ~33 ~40 ~1 ~36 ~40 ~1 stone 3  
fill ~33 ~40 ~2 ~36 ~40 ~2 stone 3 
setblock ~33 ~40 ~18 wool 8  
fill ~33 ~40 ~22 ~33 ~40 ~24 wool 0  
fill ~33 ~40 ~25 ~33 ~38 ~25 stone 3  
fill ~34 ~40 ~18 ~35 ~40 ~18 stone 0  
fill ~34 ~40 ~20 ~34 ~42 ~20 wool 8  
fill ~34 ~40 ~22 ~35 ~40 ~22 stone 3  
fill ~34 ~40 ~25 ~34 ~44 ~25 wool 0  
fill ~34 ~40 ~26 ~34 ~47 ~26 wool 0 
setblock ~35 ~40 ~3 wool 0  
fill ~35 ~40 ~19 ~36 ~40 ~19 stone 0  
fill ~35 ~40 ~20 ~35 ~43 ~20 stone 0 
setblock ~35 ~40 ~21 wool 0 
setblock ~35 ~40 ~23 wool 0 
setblock ~35 ~40 ~24 stone 3  
fill ~36 ~40 ~20 ~38 ~40 ~20 stone 3  
fill ~36 ~40 ~21 ~39 ~40 ~21 stone 3  
fill ~36 ~40 ~23 ~36 ~41 ~23 stone 3  
fill ~36 ~40 ~24 ~38 ~40 ~24 wool 0  
fill ~36 ~40 ~25 ~40 ~40 ~25 wool 0  
fill ~36 ~40 ~26 ~37 ~40 ~26 stone 3 
setblock ~38 ~40 ~22 stone 3  
fill ~38 ~40 ~23 ~38 ~41 ~23 wool 0 
setblock ~39 ~40 ~22 wool 0  
fill ~39 ~40 ~24 ~41 ~40 ~24 stone 3  
fill ~40 ~40 ~22 ~40 ~47 ~22 stone 3  
fill ~41 ~40 ~23 ~41 ~42 ~23 stone 3  
fill ~107 ~40 ~22 ~107 ~38 ~22 wool 7  
fill ~107 ~40 ~23 ~114 ~40 ~23 stained_hardened_clay 9  
fill ~107 ~40 ~24 ~107 ~39 ~24 wool 7  
fill ~108 ~40 ~21 ~111 ~40 ~21 stained_hardened_clay 9  
fill ~108 ~40 ~22 ~113 ~40 ~22 stained_hardened_clay 9  
fill ~108 ~40 ~24 ~113 ~40 ~24 stained_hardened_clay 9  
fill ~110 ~40 ~25 ~112 ~40 ~25 stained_hardened_clay 9  
fill ~0 ~41 ~16 ~0 ~50 ~16 stained_hardened_clay 11  
fill ~2 ~41 ~19 ~10 ~41 ~19 stained_hardened_clay 11  
fill ~3 ~41 ~13 ~15 ~41 ~13 stained_hardened_clay 11  
fill ~4 ~41 ~9 ~4 ~42 ~9 stained_hardened_clay 3  
fill ~5 ~41 ~8 ~5 ~40 ~8 stained_hardened_clay 3  
fill ~6 ~41 ~5 ~7 ~41 ~5 stained_hardened_clay 11  
fill ~6 ~41 ~8 ~6 ~42 ~8 stained_hardened_clay 11  
fill ~6 ~41 ~10 ~11 ~41 ~10 stained_hardened_clay 11 
setblock ~7 ~41 ~8 stained_hardened_clay 3  
fill ~7 ~41 ~15 ~14 ~41 ~15 stained_hardened_clay 11 
setblock ~8 ~41 ~21 stained_hardened_clay 11  
fill ~9 ~41 ~23 ~9 ~43 ~23 stained_hardened_clay 11  
fill ~11 ~41 ~5 ~11 ~43 ~5 stained_hardened_clay 11 
setblock ~11 ~41 ~8 stained_hardened_clay 3  
fill ~11 ~41 ~12 ~14 ~41 ~12 stained_hardened_clay 11  
fill ~11 ~41 ~18 ~11 ~56 ~18 stained_hardened_clay 11 
setblock ~13 ~41 ~7 stained_hardened_clay 11 
setblock ~13 ~41 ~11 stained_hardened_clay 3  
fill ~13 ~41 ~14 ~14 ~41 ~14 stained_hardened_clay 11  
fill ~14 ~41 ~11 ~14 ~66 ~11 stained_hardened_clay 11  
fill ~15 ~41 ~18 ~15 ~44 ~18 stained_hardened_clay 11  
fill ~16 ~41 ~10 ~16 ~43 ~10 stained_hardened_clay 11  
fill ~26 ~41 ~2 ~28 ~41 ~2 wool 0  
fill ~26 ~41 ~4 ~27 ~41 ~4 snow 0  
fill ~27 ~41 ~1 ~27 ~45 ~1 wool 0 
setblock ~27 ~41 ~3 snow 0  
fill ~27 ~41 ~5 ~27 ~42 ~5 stone 3  
fill ~28 ~41 ~0 ~29 ~41 ~0 stone 3  
fill ~28 ~41 ~1 ~28 ~41 ~0 stone 3 
setblock ~28 ~41 ~4 stone 3  
fill ~28 ~41 ~5 ~28 ~43 ~5 snow 0  
fill ~29 ~41 ~2 ~29 ~41 ~3 snow 0  
fill ~29 ~41 ~4 ~30 ~41 ~4 wool 0  
fill ~29 ~41 ~5 ~29 ~40 ~5 wool 0  
fill ~29 ~41 ~6 ~30 ~41 ~6 stone 3  
fill ~29 ~41 ~23 ~30 ~41 ~23 stone 3  
fill ~30 ~41 ~-1 ~32 ~41 ~-1 stone 3  
fill ~30 ~41 ~0 ~30 ~42 ~0 wool 0  
fill ~30 ~41 ~1 ~30 ~43 ~1 wool 0  
fill ~30 ~41 ~2 ~30 ~43 ~2 stone 3 
setblock ~30 ~41 ~3 wool 0  
fill ~30 ~41 ~5 ~30 ~45 ~5 stone 3  
fill ~30 ~41 ~22 ~33 ~41 ~22 wool 8  
fill ~30 ~41 ~24 ~30 ~50 ~24 stone 3  
fill ~31 ~41 ~0 ~31 ~44 ~0 stone 3  
fill ~31 ~41 ~2 ~31 ~43 ~2 wool 0  
fill ~31 ~41 ~3 ~36 ~41 ~3 stone 3  
fill ~31 ~41 ~4 ~31 ~38 ~4 stone 3  
fill ~31 ~41 ~20 ~32 ~41 ~20 stone 3  
fill ~31 ~41 ~23 ~31 ~41 ~25 wool 0 
setblock ~32 ~41 ~0 wool 0  
fill ~32 ~41 ~2 ~33 ~41 ~2 stone 3  
fill ~32 ~41 ~4 ~32 ~43 ~4 wool 0  
fill ~32 ~41 ~5 ~33 ~41 ~5 stone 3  
fill ~32 ~41 ~19 ~33 ~41 ~19 wool 8  
fill ~32 ~41 ~23 ~32 ~42 ~23 stone 3  
fill ~32 ~41 ~24 ~32 ~43 ~24 wool 0  
fill ~32 ~41 ~25 ~32 ~42 ~25 stone 3 
setblock ~32 ~41 ~26 wool 0  
fill ~33 ~41 ~0 ~33 ~42 ~0 stone 3  
fill ~33 ~41 ~1 ~33 ~42 ~1 stone 3  
fill ~33 ~41 ~4 ~34 ~41 ~4 stone 3  
fill ~33 ~41 ~18 ~36 ~41 ~18 stone 0  
fill ~33 ~41 ~21 ~34 ~41 ~21 wool 8 
setblock ~33 ~41 ~23 wool 0  
fill ~33 ~41 ~24 ~34 ~41 ~24 stone 3  
fill ~33 ~41 ~25 ~33 ~43 ~25 wool 0  
fill ~34 ~41 ~0 ~34 ~42 ~0 snow 0  
fill ~34 ~41 ~1 ~35 ~41 ~1 snow 0  
fill ~34 ~41 ~2 ~34 ~42 ~2 wool 0  
fill ~34 ~41 ~17 ~34 ~43 ~17 stone 0  
fill ~34 ~41 ~19 ~38 ~41 ~19 stone 0  
fill ~34 ~41 ~22 ~34 ~42 ~22 stone 3  
fill ~34 ~41 ~23 ~37 ~41 ~23 stone 3 
setblock ~35 ~41 ~0 stone 3  
fill ~35 ~41 ~21 ~39 ~41 ~21 stone 3  
fill ~35 ~41 ~22 ~35 ~43 ~22 wool 0 
setblock ~35 ~41 ~24 wool 0  
fill ~35 ~41 ~27 ~35 ~43 ~27 wool 0  
fill ~36 ~41 ~0 ~36 ~50 ~0 snow 0 
setblock ~36 ~41 ~1 stone 3  
fill ~36 ~41 ~2 ~37 ~41 ~2 snow 0  
fill ~36 ~41 ~20 ~37 ~41 ~20 stone 0 
setblock ~36 ~41 ~24 stone 3  
fill ~36 ~41 ~25 ~41 ~41 ~25 wool 0  
fill ~36 ~41 ~26 ~36 ~40 ~26 stone 3  
fill ~36 ~41 ~27 ~36 ~41 ~26 stone 3 
setblock ~37 ~41 ~1 snow 0  
fill ~37 ~41 ~24 ~37 ~47 ~24 wool 0  
fill ~37 ~41 ~26 ~39 ~41 ~26 wool 0  
fill ~38 ~41 ~20 ~39 ~41 ~20 stone 3 
setblock ~38 ~41 ~22 wool 0  
fill ~39 ~41 ~22 ~39 ~43 ~22 stone 3  
fill ~39 ~41 ~23 ~40 ~41 ~23 wool 0  
fill ~39 ~41 ~24 ~41 ~41 ~24 wool 0 
setblock ~40 ~41 ~21 wool 8  
fill ~41 ~41 ~22 ~41 ~49 ~22 stone 3  
fill ~42 ~41 ~23 ~42 ~44 ~23 stone 3  
fill ~107 ~41 ~22 ~111 ~41 ~22 stained_hardened_clay 9  
fill ~107 ~41 ~23 ~111 ~41 ~23 stained_hardened_clay 9  
fill ~107 ~41 ~24 ~110 ~41 ~24 stained_hardened_clay 9  
fill ~108 ~41 ~21 ~112 ~41 ~21 stained_hardened_clay 9  
fill ~109 ~41 ~25 ~111 ~41 ~25 stained_hardened_clay 9  
fill ~111 ~41 ~24 ~113 ~41 ~24 wool 8  
fill ~112 ~41 ~22 ~113 ~41 ~22 wool 8  
fill ~112 ~41 ~23 ~114 ~41 ~23 wool 8  
fill ~112 ~41 ~25 ~112 ~44 ~25 wool 8  
fill ~0 ~42 ~17 ~0 ~48 ~17 stained_hardened_clay 11  
fill ~0 ~42 ~18 ~0 ~44 ~18 stained_hardened_clay 11  
fill ~2 ~42 ~19 ~10 ~42 ~19 stained_hardened_clay 11 
setblock ~3 ~42 ~8 stained_hardened_clay 3  
fill ~3 ~42 ~10 ~5 ~42 ~10 stained_hardened_clay 3  
fill ~3 ~42 ~13 ~15 ~42 ~13 stained_hardened_clay 11 
setblock ~5 ~42 ~6 stained_hardened_clay 11  
fill ~5 ~42 ~8 ~5 ~45 ~8 stained_hardened_clay 11  
fill ~6 ~42 ~5 ~6 ~46 ~5 stained_hardened_clay 11 
setblock ~6 ~42 ~7 stained_hardened_clay 11  
fill ~6 ~42 ~10 ~13 ~42 ~10 stained_hardened_clay 11 
setblock ~7 ~42 ~7 stained_hardened_clay 3  
fill ~7 ~42 ~8 ~7 ~48 ~8 stained_hardened_clay 11  
fill ~7 ~42 ~15 ~14 ~42 ~15 stained_hardened_clay 11  
fill ~7 ~42 ~21 ~7 ~48 ~21 stained_hardened_clay 11  
fill ~8 ~42 ~3 ~8 ~45 ~3 stained_hardened_clay 11 
setblock ~8 ~42 ~6 stained_hardened_clay 3  
fill ~9 ~42 ~5 ~9 ~43 ~5 stained_hardened_clay 11  
fill ~10 ~42 ~7 ~10 ~48 ~7 stained_hardened_clay 11  
fill ~11 ~42 ~8 ~11 ~45 ~8 stained_hardened_clay 11  
fill ~11 ~42 ~11 ~14 ~42 ~11 stained_hardened_clay 11  
fill ~11 ~42 ~12 ~14 ~42 ~12 stained_hardened_clay 11  
fill ~12 ~42 ~17 ~13 ~42 ~17 stained_hardened_clay 11  
fill ~13 ~42 ~6 ~13 ~43 ~6 stained_hardened_clay 3  
fill ~13 ~42 ~7 ~14 ~42 ~7 stained_hardened_clay 3  
fill ~13 ~42 ~14 ~14 ~42 ~14 stained_hardened_clay 11  
fill ~15 ~42 ~21 ~15 ~48 ~21 stained_hardened_clay 11  
fill ~26 ~42 ~2 ~26 ~43 ~2 stone 3  
fill ~26 ~42 ~3 ~26 ~42 ~5 snow 0  
fill ~27 ~42 ~2 ~27 ~43 ~2 wool 0 
setblock ~27 ~42 ~3 stone 3  
fill ~27 ~42 ~4 ~28 ~42 ~4 wool 0  
fill ~27 ~42 ~6 ~33 ~42 ~6 stone 3  
fill ~28 ~42 ~0 ~28 ~43 ~0 wool 0  
fill ~28 ~42 ~1 ~28 ~42 ~0 wool 0  
fill ~28 ~42 ~2 ~30 ~42 ~2 stone 3  
fill ~28 ~42 ~3 ~29 ~42 ~3 wool 0  
fill ~29 ~42 ~-1 ~31 ~42 ~-1 stone 3  
fill ~29 ~42 ~0 ~29 ~43 ~0 stone 3 
setblock ~29 ~42 ~4 snow 0 
setblock ~29 ~42 ~5 stone 3  
fill ~29 ~42 ~22 ~29 ~45 ~22 stone 3  
fill ~29 ~42 ~23 ~33 ~42 ~23 stone 3  
fill ~30 ~42 ~3 ~31 ~42 ~3 stone 3  
fill ~30 ~42 ~4 ~30 ~45 ~4 stone 3  
fill ~30 ~42 ~20 ~30 ~43 ~20 wool 8 
setblock ~30 ~42 ~21 stone 3  
fill ~30 ~42 ~22 ~30 ~40 ~22 wool 8  
fill ~31 ~42 ~4 ~31 ~43 ~4 wool 0  
fill ~31 ~42 ~19 ~33 ~42 ~19 wool 8  
fill ~31 ~42 ~20 ~31 ~41 ~20 stone 3  
fill ~31 ~42 ~22 ~31 ~43 ~22 stone 3  
fill ~31 ~42 ~24 ~31 ~42 ~25 wool 0  
fill ~32 ~42 ~-1 ~32 ~44 ~-1 wool 0 
setblock ~32 ~42 ~0 snow 0 
setblock ~32 ~42 ~1 stone 3 
setblock ~32 ~42 ~2 snow 0  
fill ~32 ~42 ~3 ~32 ~43 ~3 wool 0  
fill ~32 ~42 ~5 ~35 ~42 ~5 stone 3  
fill ~32 ~42 ~18 ~32 ~50 ~18 wool 8  
fill ~32 ~42 ~20 ~32 ~46 ~20 wool 8 
setblock ~32 ~42 ~21 stone 3  
fill ~32 ~42 ~22 ~33 ~42 ~22 wool 8  
fill ~32 ~42 ~26 ~32 ~44 ~26 stone 3  
fill ~33 ~42 ~-1 ~33 ~43 ~-1 stone 3 
setblock ~33 ~42 ~2 wool 0  
fill ~33 ~42 ~4 ~35 ~42 ~4 stone 3  
fill ~33 ~42 ~17 ~33 ~43 ~17 stone 0  
fill ~33 ~42 ~18 ~37 ~42 ~18 stone 0  
fill ~33 ~42 ~21 ~34 ~42 ~21 wool 8  
fill ~33 ~42 ~24 ~34 ~42 ~24 wool 0  
fill ~33 ~42 ~27 ~37 ~42 ~27 wool 0 
setblock ~34 ~42 ~-1 snow 0 
setblock ~34 ~42 ~1 wool 0  
fill ~34 ~42 ~3 ~35 ~42 ~3 stone 3  
fill ~34 ~42 ~19 ~39 ~42 ~19 stone 0  
fill ~34 ~42 ~23 ~36 ~42 ~23 wool 0 
setblock ~35 ~42 ~-1 wool 0  
fill ~35 ~42 ~0 ~35 ~42 ~2 snow 0  
fill ~35 ~42 ~17 ~35 ~43 ~17 stone 0  
fill ~35 ~42 ~21 ~36 ~42 ~21 stone 0 
setblock ~35 ~42 ~24 stone 3  
fill ~36 ~42 ~-1 ~36 ~43 ~-1 snow 0  
fill ~36 ~42 ~1 ~37 ~42 ~1 wool 0  
fill ~36 ~42 ~2 ~36 ~42 ~3 wool 0  
fill ~36 ~42 ~20 ~38 ~42 ~20 stone 0  
fill ~36 ~42 ~24 ~36 ~46 ~24 wool 0 
setblock ~36 ~42 ~25 stone 3  
fill ~36 ~42 ~26 ~40 ~42 ~26 wool 0  
fill ~37 ~42 ~-1 ~37 ~43 ~-1 stone 3  
fill ~37 ~42 ~0 ~38 ~42 ~0 snow 0 
setblock ~37 ~42 ~2 stone 3 
setblock ~37 ~42 ~3 wool 0  
fill ~37 ~42 ~5 ~37 ~47 ~5 stone 3  
fill ~37 ~42 ~21 ~37 ~43 ~21 stone 3  
fill ~37 ~42 ~22 ~37 ~43 ~22 wool 0  
fill ~37 ~42 ~23 ~38 ~42 ~23 stone 3  
fill ~37 ~42 ~25 ~41 ~42 ~25 wool 0 
setblock ~38 ~42 ~1 stone 3  
fill ~38 ~42 ~2 ~39 ~42 ~2 snow 0  
fill ~38 ~42 ~3 ~38 ~42 ~2 snow 0 
setblock ~38 ~42 ~21 stone 0  
fill ~38 ~42 ~22 ~38 ~44 ~22 stone 3 
setblock ~39 ~42 ~1 snow 0  
fill ~39 ~42 ~20 ~39 ~49 ~20 wool 8  
fill ~39 ~42 ~21 ~41 ~42 ~21 stone 3  
fill ~39 ~42 ~23 ~40 ~42 ~23 wool 0  
fill ~39 ~42 ~24 ~42 ~42 ~24 wool 0 
setblock ~40 ~42 ~20 stone 3  
fill ~42 ~42 ~22 ~42 ~50 ~22 stone 3  
fill ~108 ~42 ~22 ~110 ~42 ~22 stained_hardened_clay 9  
fill ~108 ~42 ~23 ~110 ~42 ~23 stained_hardened_clay 9  
fill ~108 ~42 ~24 ~109 ~42 ~24 stained_hardened_clay 9 
setblock ~109 ~42 ~21 stained_hardened_clay 9  
fill ~109 ~42 ~25 ~110 ~42 ~25 stained_hardened_clay 9  
fill ~110 ~42 ~24 ~114 ~42 ~24 wool 8 
setblock ~111 ~42 ~21 stained_hardened_clay 9  
fill ~111 ~42 ~22 ~114 ~42 ~22 wool 8  
fill ~111 ~42 ~23 ~115 ~42 ~23 wool 8  
fill ~111 ~42 ~25 ~111 ~44 ~25 wool 8 
setblock ~112 ~42 ~21 wool 8 
setblock ~113 ~42 ~25 wool 8  
fill ~-1 ~43 ~11 ~-1 ~48 ~11 stained_hardened_clay 11  
fill ~2 ~43 ~19 ~10 ~43 ~19 stained_hardened_clay 11 
setblock ~3 ~43 ~8 stained_hardened_clay 11  
fill ~3 ~43 ~10 ~14 ~43 ~10 stained_hardened_clay 11  
fill ~3 ~43 ~13 ~15 ~43 ~13 stained_hardened_clay 11 
setblock ~4 ~43 ~9 stained_hardened_clay 11  
fill ~4 ~43 ~21 ~4 ~49 ~21 stained_hardened_clay 11  
fill ~5 ~43 ~9 ~8 ~43 ~9 stained_hardened_clay 3  
fill ~5 ~43 ~22 ~5 ~47 ~22 stained_hardened_clay 11  
fill ~6 ~43 ~7 ~6 ~43 ~9 stained_hardened_clay 3 
fill ~6 ~43 ~24 ~6 ~47 ~24 stained_hardened_clay 11  
fill ~7 ~43 ~6 ~8 ~43 ~6 stained_hardened_clay 11  
fill ~7 ~43 ~7 ~7 ~45 ~7 stained_hardened_clay 11  
fill ~7 ~43 ~15 ~14 ~43 ~15 stained_hardened_clay 11 
setblock ~8 ~43 ~8 stained_hardened_clay 3  
fill ~10 ~43 ~6 ~10 ~45 ~6 stained_hardened_clay 11  
fill ~11 ~43 ~11 ~14 ~43 ~11 stained_hardened_clay 11  
fill ~11 ~43 ~12 ~15 ~43 ~12 stained_hardened_clay 11  
fill ~12 ~43 ~7 ~12 ~43 ~17 stained_hardened_clay 11  
fill ~12 ~43 ~23 ~12 ~47 ~23 stained_hardened_clay 11 
setblock ~13 ~43 ~9 stained_hardened_clay 11  
fill ~13 ~43 ~14 ~14 ~43 ~14 stained_hardened_clay 11  
fill ~13 ~43 ~17 ~13 ~58 ~17 stained_hardened_clay 11  
fill ~13 ~43 ~19 ~13 ~47 ~19 stained_hardened_clay 11  
fill ~14 ~43 ~7 ~14 ~45 ~7 stained_hardened_clay 3  
fill ~16 ~43 ~8 ~16 ~44 ~8 stained_hardened_clay 11  
fill ~17 ~43 ~19 ~17 ~46 ~19 stained_hardened_clay 11  
fill ~26 ~43 ~3 ~26 ~44 ~3 stone 3  
fill ~26 ~43 ~4 ~27 ~43 ~4 snow 0 
setblock ~26 ~43 ~5 stone 3 
setblock ~27 ~43 ~3 wool 0  
fill ~27 ~43 ~5 ~27 ~45 ~5 snow 0 
setblock ~27 ~43 ~6 wool 0 
setblock ~28 ~43 ~1 stone 3  
fill ~28 ~43 ~2 ~29 ~43 ~2 wool 0 
setblock ~28 ~43 ~3 snow 0  
fill ~28 ~43 ~4 ~28 ~46 ~4 stone 3  
fill ~28 ~43 ~6 ~36 ~43 ~6 stone 3  
fill ~29 ~43 ~-1 ~29 ~46 ~-1 stone 3  
fill ~29 ~43 ~3 ~30 ~43 ~3 wool 0  
fill ~29 ~43 ~4 ~29 ~43 ~2 wool 0  
fill ~29 ~43 ~5 ~29 ~45 ~5 snow 0  
fill ~29 ~43 ~7 ~32 ~43 ~7 stone 3  
fill ~29 ~43 ~21 ~30 ~43 ~21 wool 8  
fill ~29 ~43 ~23 ~31 ~43 ~23 stone 3  
fill ~30 ~43 ~-1 ~30 ~46 ~-1 wool 0  
fill ~30 ~43 ~0 ~30 ~45 ~0 stone 3 
setblock ~30 ~43 ~22 stone 3 
setblock ~31 ~43 ~-1 stone 3 
setblock ~31 ~43 ~3 stone 3  
fill ~31 ~43 ~19 ~32 ~43 ~19 wool 8  
fill ~31 ~43 ~20 ~31 ~49 ~20 wool 8 
setblock ~31 ~43 ~21 stone 3  
fill ~31 ~43 ~24 ~31 ~49 ~24 stone 3  
fill ~31 ~43 ~25 ~31 ~44 ~25 stone 3  
fill ~32 ~43 ~0 ~32 ~45 ~0 wool 0  
fill ~32 ~43 ~1 ~34 ~43 ~1 snow 0  
fill ~32 ~43 ~2 ~36 ~43 ~2 stone 3  
fill ~32 ~43 ~5 ~37 ~43 ~5 stone 3  
fill ~32 ~43 ~21 ~32 ~44 ~21 wool 8  
fill ~32 ~43 ~22 ~34 ~43 ~22 wool 8 
setblock ~32 ~43 ~23 wool 0  
fill ~32 ~43 ~25 ~32 ~44 ~25 wool 0 
setblock ~33 ~43 ~0 snow 0 
setblock ~33 ~43 ~3 wool 0  
fill ~33 ~43 ~4 ~33 ~44 ~4 snow 0  
fill ~33 ~43 ~18 ~37 ~43 ~18 stone 0  
fill ~33 ~43 ~19 ~38 ~43 ~19 stone 0  
fill ~33 ~43 ~21 ~35 ~43 ~21 stone 3  
fill ~33 ~43 ~23 ~34 ~43 ~23 stone 3  
fill ~33 ~43 ~24 ~42 ~43 ~24 wool 0  
fill ~33 ~43 ~27 ~38 ~43 ~27 wool 0 
setblock ~34 ~43 ~-1 wool 0  
fill ~34 ~43 ~0 ~35 ~43 ~0 stone 3  
fill ~34 ~43 ~3 ~36 ~43 ~3 stone 3  
fill ~34 ~43 ~4 ~35 ~43 ~4 stone 3 
setblock ~34 ~43 ~20 stone 0 
setblock ~35 ~43 ~-1 snow 0  
fill ~35 ~43 ~1 ~37 ~43 ~1 stone 3  
fill ~35 ~43 ~23 ~37 ~43 ~23 wool 0  
fill ~35 ~43 ~28 ~35 ~47 ~28 wool 0  
fill ~36 ~43 ~4 ~38 ~43 ~4 snow 0  
fill ~36 ~43 ~17 ~37 ~43 ~17 stone 0  
fill ~36 ~43 ~20 ~37 ~43 ~20 stone 0  
fill ~36 ~43 ~21 ~36 ~43 ~17 stone 0 
setblock ~36 ~43 ~22 stone 3  
fill ~36 ~43 ~25 ~40 ~43 ~25 wool 0  
fill ~36 ~43 ~26 ~37 ~43 ~26 stone 3  
fill ~37 ~43 ~0 ~37 ~50 ~0 snow 0  
fill ~37 ~43 ~2 ~40 ~43 ~2 snow 0  
fill ~37 ~43 ~3 ~37 ~46 ~3 snow 0  
fill ~38 ~43 ~-1 ~38 ~43 ~0 stone 3  
fill ~38 ~43 ~1 ~38 ~50 ~1 snow 0  
fill ~38 ~43 ~3 ~38 ~44 ~3 stone 3  
fill ~38 ~43 ~18 ~39 ~43 ~18 wool 8  
fill ~38 ~43 ~20 ~38 ~48 ~20 wool 8  
fill ~38 ~43 ~21 ~42 ~43 ~21 stone 3  
fill ~38 ~43 ~23 ~38 ~44 ~23 stone 3  
fill ~38 ~43 ~26 ~39 ~43 ~26 wool 0  
fill ~39 ~43 ~0 ~39 ~48 ~0 snow 0  
fill ~39 ~43 ~1 ~40 ~43 ~1 stone 3  
fill ~39 ~43 ~3 ~39 ~50 ~3 snow 0  
fill ~39 ~43 ~19 ~40 ~43 ~19 wool 8  
fill ~39 ~43 ~23 ~41 ~43 ~23 wool 0  
fill ~40 ~43 ~20 ~41 ~43 ~20 wool 8  
fill ~40 ~43 ~26 ~41 ~43 ~26 stone 3 
setblock ~41 ~43 ~25 stone 3 
setblock ~42 ~43 ~25 wool 0  
fill ~43 ~43 ~22 ~43 ~47 ~22 stone 3  
fill ~43 ~43 ~23 ~43 ~44 ~23 stone 3  
fill ~108 ~43 ~23 ~109 ~43 ~23 stained_hardened_clay 9 
setblock ~109 ~43 ~22 stained_hardened_clay 9 
setblock ~109 ~43 ~24 stained_hardened_clay 9  
fill ~110 ~43 ~22 ~115 ~43 ~22 wool 8  
fill ~110 ~43 ~23 ~115 ~43 ~23 wool 8  
fill ~110 ~43 ~24 ~115 ~43 ~24 wool 8  
fill ~110 ~43 ~25 ~110 ~43 ~22 wool 8 
setblock ~111 ~43 ~21 wool 8 
setblock ~113 ~43 ~25 snow 0  
fill ~-1 ~44 ~18 ~-1 ~50 ~18 stained_hardened_clay 11 
setblock ~1 ~44 ~9 stained_hardened_clay 3  
fill ~2 ~44 ~7 ~2 ~44 ~8 stained_hardened_clay 3  
fill ~2 ~44 ~19 ~11 ~44 ~19 stained_hardened_clay 11 
setblock ~3 ~44 ~8 stained_hardened_clay 3  
fill ~3 ~44 ~10 ~4 ~44 ~10 stained_hardened_clay 3  
fill ~3 ~44 ~13 ~15 ~44 ~13 stained_hardened_clay 11  
fill ~4 ~44 ~8 ~4 ~46 ~8 stained_hardened_clay 11 
setblock ~4 ~44 ~9 stained_hardened_clay 3 
