setblock ~-23 ~-1 ~3 glowstone
setblock ~-18 ~-1 ~1 glowstone
setblock ~-13 ~-1 ~0 glowstone
setblock ~-7 ~-1 ~-1 glowstone
fill ~-29 ~2 ~3 ~-29 ~4 ~3 glowstone
fill ~-2~-1~0 ~-2~-1~-2 glowstone
fill ~-3~-1~-1 ~-1~-1~-1 glowstone
setblock ~-1~-1~1 glowstone
setblock ~-1~-1~-3 glowstone
fill ~-32~-50~0 ~-32~-2~0 stonebrick 0
fill ~-32~-1~0 ~-26~-1~2 grass
fill ~-31~-50~0 ~-30~-50~3 cobblestone
fill ~-31~-49~0 ~-30~-49~2 cobblestone
fill ~-31~-48~0 ~-30~-2~0 cobblestone
fill ~-29~-50~0 ~-29~-2~0 stonebrick 0
fill ~-28~-50~0 ~-27~-46~4 cobblestone
fill ~-28~-45~0 ~-27~-2~0 cobblestone
fill ~-26~-50~0 ~-26~-2~0 stonebrick 0
fill ~-20~-50~0 ~-20~-45~0 stonebrick 0
fill ~-19~-50~0 ~-18~-45~0 cobblestone
fill ~-17~-50~0 ~-17~-45~0 stonebrick 0
fill ~-16~-50~0 ~-15~-45~0 cobblestone
fill ~-14~-50~0 ~-14~-45~0 stonebrick 0
fill ~-13~-50~0 ~-12~-45~0 cobblestone
fill ~-11~-50~0 ~-11~-45~0 stonebrick 0
fill ~-10~-50~0 ~-9~-45~0 cobblestone
fill ~-8~-50~0 ~-8~-45~0 stonebrick 0
fill ~-32~-50~1 ~-32~-2~2 cobblestone
setblock ~-31~-48~1 planks 0
fill ~-31~-47~1 ~-31~-40~5 air
fill ~-31~-39~1 ~-27~-37~1 air
setblock ~-31~-36~1 planks 0
fill ~-31~-35~1 ~-31~-28~5 air
fill ~-31~-27~1 ~-27~-25~1 air
setblock ~-31~-24~1 planks 0
fill ~-31~-23~1 ~-31~-16~5 air
fill ~-31~-15~1 ~-27~-13~1 air
setblock ~-31~-12~1 planks 0
fill ~-31~-11~1 ~-31~-4~5 air
fill ~-31~-3~1 ~-27~-2~1 air
fill ~-30~-48~1 ~-29~-48~2 cobblestone
setblock ~-30~-47~1 oak_stairs 0
fill ~-30~-46~1 ~-30~-40~1 air
fill ~-30~-36~1 ~-27~-36~1 air
setblock ~-30~-35~1 oak_stairs 0
fill ~-30~-34~1 ~-30~-28~1 air
fill ~-30~-24~1 ~-27~-24~1 air
setblock ~-30~-23~1 oak_stairs 0
fill ~-30~-22~1 ~-30~-16~1 air
fill ~-30~-12~1 ~-27~-12~1 air
setblock ~-30~-11~1 oak_stairs 0
fill ~-30~-10~1 ~-30~-4~1 air
fill ~-29~-50~1 ~-29~-49~4 cobblestone
fill ~-29~-47~1 ~-29~-47~2 cobblestone
setblock ~-29~-46~1 oak_stairs 0
fill ~-29~-45~1 ~-29~-40~1 air
fill ~-29~-35~1 ~-27~-35~1 air
setblock ~-29~-34~1 oak_stairs 0
fill ~-29~-33~1 ~-29~-28~1 air
fill ~-29~-23~1 ~-27~-23~1 air
setblock ~-29~-22~1 oak_stairs 0
fill ~-29~-21~1 ~-29~-16~1 air
fill ~-29~-11~1 ~-27~-11~1 air
setblock ~-29~-10~1 oak_stairs 0
fill ~-29~-9~1 ~-29~-4~1 air
setblock ~-28~-45~1 oak_stairs 0
fill ~-28~-44~1 ~-27~-40~1 air
fill ~-28~-34~1 ~-27~-34~1 air
setblock ~-28~-33~1 oak_stairs 0
fill ~-28~-32~1 ~-27~-28~1 air
fill ~-28~-22~1 ~-27~-22~1 air
setblock ~-28~-21~1 oak_stairs 0
fill ~-28~-20~1 ~-27~-16~1 air
fill ~-28~-10~1 ~-27~-10~1 air
setblock ~-28~-9~1 oak_stairs 0
fill ~-28~-8~1 ~-27~-4~1 air
setblock ~-27~-45~1 planks 0
setblock ~-27~-33~1 planks 0
setblock ~-27~-21~1 planks 0
setblock ~-27~-9~1 planks 0
fill ~-26~-50~1 ~-26~-2~2 cobblestone
fill ~-20~-50~1 ~-20~-45~2 cobblestone
fill ~-19~-50~1 ~-9~-50~5 double_stone_block_slab 0
fill ~-19~-49~1 ~-9~-46~5 air
fill ~-19~-45~1 ~-8~-45~1 cobblestone
fill ~-8~-50~1 ~-8~-46~2 cobblestone
setblock ~-31~-48~2 oak_stairs 3
fill ~-31~-39~2 ~-31~-39~4 air
fill ~-31~-38~2 ~-31~-38~3 air
setblock ~-31~-37~2 air
setblock ~-31~-36~2 oak_stairs 3
fill ~-31~-27~2 ~-31~-27~4 air
fill ~-31~-26~2 ~-31~-26~3 air
setblock ~-31~-25~2 air
setblock ~-31~-24~2 oak_stairs 3
fill ~-31~-15~2 ~-31~-15~4 air
fill ~-31~-14~2 ~-31~-14~3 air
setblock ~-31~-13~2 air
setblock ~-31~-12~2 oak_stairs 3
fill ~-31~-3~2 ~-31~-3~4 air
fill ~-31~-2~2 ~-31~-2~3 air
fill ~-30~-47~2 ~-30~-2~2 cobblestone
fill ~-29~-46~2 ~-29~-45~4 cobblestone
setblock ~-29~-44~2 lit_redstone_lamp
fill ~-29~-43~2 ~-28~-42~4 cobblestone
fill ~-29~-41~2 ~-28~-33~2 cobblestone
setblock ~-29~-32~2 lit_redstone_lamp
fill ~-29~-31~2 ~-28~-30~4 cobblestone
fill ~-29~-29~2 ~-28~-21~2 cobblestone
setblock ~-29~-20~2 lit_redstone_lamp
fill ~-29~-19~2 ~-28~-18~4 cobblestone
fill ~-29~-17~2 ~-28~-9~2 cobblestone
setblock ~-29~-8~2 lit_redstone_lamp
fill ~-29~-7~2 ~-28~-6~4 cobblestone
fill ~-29~-5~2 ~-28~-2~2 cobblestone
fill ~-28~-45~2 ~-27~-45~4 cobblestone
fill ~-28~-44~2 ~-28~-44~4 cobblestone
fill ~-28~-32~2 ~-28~-32~4 cobblestone
fill ~-28~-20~2 ~-28~-20~4 cobblestone
fill ~-28~-8~2 ~-28~-8~4 cobblestone
setblock ~-27~-44~2 oak_stairs 2
fill ~-27~-43~2 ~-27~-33~2 air
setblock ~-27~-32~2 oak_stairs 2
fill ~-27~-31~2 ~-27~-21~2 air
setblock ~-27~-20~2 oak_stairs 2
fill ~-27~-19~2 ~-27~-9~2 air
setblock ~-27~-8~2 oak_stairs 2
fill ~-27~-7~2 ~-27~-2~2 air
fill ~-19~-45~2 ~-19~-45~9 cobblestone
fill ~-18~-45~2 ~-18~-45~4 stone_stairs 5
setblock ~-17~-45~2 stone_stairs 7
fill ~-16~-45~2 ~-16~-45~3 stone_stairs 4
fill ~-15~-45~2 ~-15~-45~4 stone_stairs 5
setblock ~-14~-45~2 stone_stairs 7
fill ~-13~-45~2 ~-13~-45~4 stone_stairs 4
fill ~-12~-45~2 ~-10~-45~2 stone_stairs 7
fill ~-9~-45~2 ~-8~-45~2 cobblestone
fill ~-32~-50~3 ~-32~-2~3 stonebrick 0
fill ~-32~-1~3 ~-30~-1~3 grass
setblock ~-31~-49~3 oak_stairs 3
fill ~-31~-48~3 ~-31~-48~5 air
setblock ~-31~-37~3 oak_stairs 3
fill ~-31~-36~3 ~-31~-36~5 air
setblock ~-31~-25~3 oak_stairs 3
fill ~-31~-24~3 ~-31~-24~5 air
setblock ~-31~-13~3 oak_stairs 3
fill ~-31~-12~3 ~-31~-12~5 air
fill ~-30~-49~3 ~-30~-48~4 cobblestone
setblock ~-30~-47~3 lit_redstone_lamp
fill ~-30~-46~3 ~-30~-36~4 cobblestone
setblock ~-30~-35~3 lit_redstone_lamp
fill ~-30~-34~3 ~-28~-33~4 cobblestone
fill ~-30~-32~3 ~-30~-24~4 cobblestone
setblock ~-30~-23~3 lit_redstone_lamp
fill ~-30~-22~3 ~-28~-21~4 cobblestone
fill ~-30~-20~3 ~-30~-12~4 cobblestone
setblock ~-30~-11~3 lit_redstone_lamp
fill ~-30~-10~3 ~-28~-9~4 cobblestone
fill ~-30~-8~3 ~-30~-2~4 cobblestone
fill ~-29~-48~3 ~-29~-47~3 redstone_block
setblock ~-29~-44~3 redstone_block
setblock ~-29~-41~3 redstone_block
fill ~-29~-40~3 ~-28~-39~4 cobblestone
setblock ~-29~-38~3 redstone_block
fill ~-29~-37~3 ~-28~-37~4 cobblestone
fill ~-29~-36~3 ~-29~-35~3 redstone_block
setblock ~-29~-32~3 redstone_block
setblock ~-29~-29~3 redstone_block
fill ~-29~-28~3 ~-28~-27~4 cobblestone
setblock ~-29~-26~3 redstone_block
fill ~-29~-25~3 ~-28~-25~4 cobblestone
fill ~-29~-24~3 ~-29~-23~3 redstone_block
setblock ~-29~-20~3 redstone_block
setblock ~-29~-17~3 redstone_block
fill ~-29~-16~3 ~-28~-15~4 cobblestone
setblock ~-29~-14~3 redstone_block
fill ~-29~-13~3 ~-28~-13~4 cobblestone
fill ~-29~-12~3 ~-29~-11~3 redstone_block
setblock ~-29~-8~3 redstone_block
fill ~-29~-5~3 ~-29~-2~3 redstone_block
setblock ~-29~-1~3 lit_redstone_lamp
setblock ~-28~-41~3 lit_redstone_lamp
fill ~-28~-38~3 ~-28~-38~4 cobblestone
fill ~-28~-36~3 ~-28~-35~4 cobblestone
setblock ~-28~-29~3 lit_redstone_lamp
fill ~-28~-26~3 ~-28~-26~4 cobblestone
fill ~-28~-24~3 ~-28~-23~4 cobblestone
setblock ~-28~-17~3 lit_redstone_lamp
fill ~-28~-14~3 ~-28~-14~4 cobblestone
fill ~-28~-12~3 ~-28~-11~4 cobblestone
setblock ~-28~-5~3 lit_redstone_lamp
fill ~-28~-4~3 ~-28~-2~4 cobblestone
fill ~-28~-1~3 ~-26~-1~6 grass
fill ~-27~-44~3 ~-27~-44~4 cobblestone
setblock ~-27~-43~3 oak_stairs 2
fill ~-27~-42~3 ~-27~-32~3 air
setblock ~-27~-31~3 oak_stairs 2
fill ~-27~-30~3 ~-27~-20~3 air
setblock ~-27~-19~3 oak_stairs 2
fill ~-27~-18~3 ~-27~-8~3 air
setblock ~-27~-7~3 oak_stairs 2
fill ~-27~-6~3 ~-27~-2~3 air
fill ~-26~-50~3 ~-26~-2~3 stonebrick 0
fill ~-20~-50~3 ~-20~-45~3 stonebrick 0
setblock ~-17~-45~3 lit_redstone_lamp
setblock ~-17~-44~3 redstone_block
setblock ~-14~-45~3 lit_redstone_lamp
setblock ~-14~-44~3 redstone_block
setblock ~-12~-45~3 stone_stairs 5
setblock ~-11~-45~3 lit_redstone_lamp
setblock ~-11~-44~3 redstone_block
setblock ~-10~-45~3 stone_stairs 4
fill ~-9~-45~3 ~-9~-45~24 cobblestone
fill ~-8~-50~3 ~-8~-45~3 stonebrick 0
fill ~-32~-50~4 ~-32~-2~5 cobblestone
fill ~-32~-1~4 ~-32~-1~6 grass
fill ~-31~-50~4 ~-31~-50~5 double_stone_block_slab 0
fill ~-31~-49~4 ~-31~-49~5 air
setblock ~-31~-38~4 oak_stairs 3
fill ~-31~-37~4 ~-31~-37~5 air
setblock ~-31~-26~4 oak_stairs 3
fill ~-31~-25~4 ~-31~-25~5 air
setblock ~-31~-14~4 oak_stairs 3
fill ~-31~-13~4 ~-31~-13~5 air
setblock ~-31~-2~4 oak_stairs 3
fill ~-31~-1~4 ~-31~-1~5 air
setblock ~-30~-50~4 cobblestone
fill ~-30~-47~4 ~-29~-47~4 cobblestone
fill ~-30~-35~4 ~-29~-35~4 cobblestone
fill ~-30~-23~4 ~-29~-23~4 cobblestone
fill ~-30~-11~4 ~-29~-11~4 cobblestone
fill ~-30~-1~4 ~-29~-1~4 grass
setblock ~-29~-48~4 lit_redstone_lamp
setblock ~-29~-44~4 cobblestone
fill ~-29~-41~4 ~-28~-41~4 cobblestone
setblock ~-29~-38~4 lit_redstone_lamp
setblock ~-29~-36~4 lit_redstone_lamp
setblock ~-29~-32~4 cobblestone
fill ~-29~-29~4 ~-28~-29~4 cobblestone
setblock ~-29~-26~4 lit_redstone_lamp
setblock ~-29~-24~4 lit_redstone_lamp
setblock ~-29~-20~4 cobblestone
fill ~-29~-17~4 ~-28~-17~4 cobblestone
setblock ~-29~-14~4 lit_redstone_lamp
setblock ~-29~-12~4 lit_redstone_lamp
setblock ~-29~-8~4 cobblestone
fill ~-29~-5~4 ~-28~-5~4 cobblestone
fill ~-29~-4~4 ~-29~-3~4 cobblestone
setblock ~-29~-2~4 lit_redstone_lamp
fill ~-27~-43~4 ~-26~-43~4 cobblestone
setblock ~-27~-42~4 oak_stairs 2
fill ~-27~-41~4 ~-27~-31~5 air
setblock ~-27~-30~4 oak_stairs 2
fill ~-27~-29~4 ~-27~-19~5 air
setblock ~-27~-18~4 oak_stairs 2
fill ~-27~-17~4 ~-27~-7~5 air
setblock ~-27~-6~4 oak_stairs 2
fill ~-27~-5~4 ~-27~-2~5 air
fill ~-26~-50~4 ~-26~-50~6 cobblestone
fill ~-26~-49~4 ~-26~-44~5 cobblestone
fill ~-26~-42~4 ~-26~-2~5 cobblestone
fill ~-20~-50~4 ~-20~-45~5 cobblestone
fill ~-17~-45~4 ~-16~-45~4 stone_stairs 6
setblock ~-14~-45~4 stone_stairs 6
fill ~-12~-45~4 ~-10~-45~4 stone_stairs 6
fill ~-8~-50~4 ~-8~-45~5 cobblestone
setblock ~-31~-39~5 planks 0
fill ~-31~-38~5 ~-28~-38~5 air
setblock ~-31~-27~5 planks 0
fill ~-31~-26~5 ~-28~-26~5 air
setblock ~-31~-15~5 planks 0
fill ~-31~-14~5 ~-28~-14~5 air
setblock ~-31~-3~5 planks 0
fill ~-31~-2~5 ~-28~-2~5 air
fill ~-30~-50~5 ~-27~-50~5 double_stone_block_slab 0
fill ~-30~-49~5 ~-27~-43~5 air
fill ~-30~-42~5 ~-28~-42~5 air
fill ~-30~-41~5 ~-29~-41~5 air
setblock ~-30~-40~5 air
setblock ~-30~-39~5 oak_stairs 1
fill ~-30~-37~5 ~-28~-30~5 air
fill ~-30~-29~5 ~-29~-29~5 air
setblock ~-30~-28~5 air
setblock ~-30~-27~5 oak_stairs 1
fill ~-30~-25~5 ~-28~-18~5 air
fill ~-30~-17~5 ~-29~-17~5 air
setblock ~-30~-16~5 air
setblock ~-30~-15~5 oak_stairs 1
fill ~-30~-13~5 ~-28~-6~5 air
fill ~-30~-5~5 ~-29~-5~5 air
setblock ~-30~-4~5 air
setblock ~-30~-3~5 oak_stairs 1
fill ~-30~-1~5 ~-29~-1~5 air
setblock ~-29~-40~5 oak_stairs 1
fill ~-29~-39~5 ~-28~-39~5 air
setblock ~-29~-28~5 oak_stairs 1
fill ~-29~-27~5 ~-28~-27~5 air
setblock ~-29~-16~5 oak_stairs 1
fill ~-29~-15~5 ~-28~-15~5 air
setblock ~-29~-4~5 oak_stairs 1
fill ~-29~-3~5 ~-28~-3~5 air
setblock ~-28~-41~5 oak_stairs 1
setblock ~-28~-40~5 air
setblock ~-28~-29~5 oak_stairs 1
setblock ~-28~22~5 air
setblock ~-28~-17~5 oak_stairs 1
setblock ~-28~-16~5 air
setblock ~-28~-5~5 oak_stairs 1
setblock ~-28~-4~5 air
setblock ~-27~-42~5 planks 0
setblock ~-27~-30~5 planks 0
setblock ~-27~-18~5 planks 0
setblock ~-27~-6~5 planks 0
setblock ~-26~-43~5 cobblestone
fill ~-18~-45~5 ~-10~-45~5 cobblestone
fill ~-41~-50~6 ~-41~-45~6 stonebrick 0
fill ~-40~-50~6 ~-39~-45~6 cobblestone
fill ~-38~-50~6 ~-38~-45~6 stonebrick 0
fill ~-37~-50~6 ~-36~-45~6 cobblestone
fill ~-35~-50~6 ~-35~-45~6 stonebrick 0
fill ~-34~-50~6 ~-33~-45~6 cobblestone
fill ~-32~-50~6 ~-32~-2~6 stonebrick 0
fill ~-31~-50~6 ~-30~-2~6 cobblestone
fill ~-31~-1~6 ~-29~-1~6 grass
fill ~-29~-50~6 ~-29~-2~6 stonebrick 0
fill ~-28~-50~6 ~-27~-50~14 double_stone_block_slab 0
fill ~-28~-49~6 ~-27~-48~14 air
setblock ~-28~-47~6 stone_stairs 5
fill ~-28~-46~6 ~-27~-2~6 cobblestone
setblock ~-27~-47~6 stone_stairs 4
fill ~-26~-49~6 ~-26~-2~6 stonebrick 0
fill ~-25~-50~6 ~-24~-45~6 cobblestone
fill ~-23~-50~6 ~-23~-45~6 stonebrick 0
fill ~-22~-50~6 ~-21~-45~6 cobblestone
fill ~-20~-50~6 ~-20~-45~6 stonebrick 0
fill ~-19~-50~6 ~-18~-46~6 cobblestone
fill ~-18~-45~6 ~-18~-45~9 cobblestone
fill ~-17~-50~6 ~-17~-45~6 stonebrick 0
fill ~-16~-50~6 ~-15~-50~8 double_stone_block_slab 0
fill ~-16~-49~6 ~-15~-48~23 air
setblock ~-16~-47~6 stone_stairs 5
fill ~-16~-46~6 ~-15~-45~6 cobblestone
setblock ~-15~-47~6 stone_stairs 4
fill ~-14~-50~6 ~-14~-45~6 stonebrick 0
fill ~-13~-50~6 ~-12~-45~6 cobblestone
fill ~-11~-50~6 ~-11~-45~6 stonebrick 0
fill ~-10~-50~6 ~-9~-46~6 cobblestone
fill ~-10~-45~6 ~-10~-45~9 cobblestone
fill ~-8~-50~6 ~-8~-45~6 stonebrick 0
fill ~-41~-50~7 ~-41~-45~8 cobblestone
fill ~-40~-50~7 ~-29~-50~9 double_stone_block_slab 0
fill ~-40~-49~7 ~-36~-46~8 air
fill ~-40~-45~7 ~-20~-45~8 cobblestone
fill ~-35~-49~7 ~-34~-49~7 chest 3
fill ~-35~-48~7 ~-29~-47~14 air
setblock ~-35~-46~7 torch 3
fill ~-34~-46~7 ~-33~-46~14 air
fill ~-33~-49~7 ~-31~-49~14 air
setblock ~-32~-46~7 torch 3
fill ~-31~-46~7 ~-30~-46~14 air
fill ~-30~-49~7 ~-29~-49~7 chest 3
setblock ~-29~-46~7 torch 3
fill ~-28~-47~7 ~-24~-47~14 air
fill ~-28~-46~7 ~-27~-46~14 air
fill ~-26~-50~7 ~-24~-50~14 double_stone_block_slab 0
fill ~-26~-49~7 ~-24~-48~14 air
setblock ~-26~-46~7 torch 3
fill ~-25~-46~7 ~-24~-46~8 air
fill ~-23~-50~7 ~-23~-46~8 cobblestone
fill ~-22~-50~7 ~-17~-50~8 double_stone_block_slab 0
fill ~-22~-49~7 ~-17~-46~22 air
fill ~-17~-45~7 ~-11~-45~9 cobblestone
fill ~-16~-47~7 ~-9~-46~23 air
fill ~-14~-50~7 ~-9~-50~8 double_stone_block_slab 0
fill ~-14~-49~7 ~-10~-48~22 air
fill ~-9~-49~7 ~-9~-49~23 double_stone_block_slab 0
fill ~-9~-48~7 ~-9~-48~23 air
fill ~-8~-50~7 ~-8~-45~8 cobblestone
fill ~-35~-49~8 ~-34~-49~14 air
fill ~-35~-46~8 ~-35~-46~13 air
fill ~-32~-46~8 ~-32~-46~13 air
fill ~-30~-49~8 ~-29~-49~14 air
fill ~-29~-46~8 ~-29~-46~13 air
fill ~-26~-46~8 ~-26~-46~13 air
fill ~-41~-50~9 ~-41~-45~9 stonebrick 0
fill ~-40~-49~9 ~-39~-49~9 brick_block
setblock ~-40~-48~9 stone_stairs 2
fill ~-40~-47~9 ~-36~-46~14 air
fill ~-40~-45~9 ~-39~-45~27 cobblestone
fill ~-39~-48~9 ~-39~-48~12 stone_stairs 1
fill ~-38~-49~9 ~-36~-48~14 air
setblock ~-38~-45~9 lit_redstone_lamp
setblock ~-38~-44~9 redstone_block
fill ~-37~-45~9 ~-36~-45~17 cobblestone
setblock ~-35~-45~9 lit_redstone_lamp
setblock ~-35~-44~9 redstone_block
fill ~-34~-45~9 ~-33~-45~27 cobblestone
setblock ~-32~-45~9 lit_redstone_lamp
setblock ~-32~-44~9 redstone_block
fill ~-31~-45~9 ~-30~-45~17 cobblestone
setblock ~-29~-45~9 lit_redstone_lamp
setblock ~-29~-44~9 redstone_block
fill ~-28~-45~9 ~-27~-45~30 cobblestone
setblock ~-26~-45~9 lit_redstone_lamp
setblock ~-26~-44~9 redstone_block
fill ~-25~-46~9 ~-25~-46~14 air
fill ~-25~-45~9 ~-24~-45~30 cobblestone
setblock ~-24~-46~9 torch 2
fill ~-23~-50~9 ~-23~-45~9 stonebrick 0
fill ~-22~-50~9 ~-21~-50~23 double_stone_block_slab 0
fill ~-22~-45~9 ~-20~-45~9 cobblestone
fill ~-20~-50~9 ~-12~-50~12 dirt 0
fill ~-11~-50~9 ~-9~-50~23 double_stone_block_slab 0
fill ~-8~-50~9 ~-8~-45~9 stonebrick 0
fill ~-41~-50~10 ~-41~-45~11 cobblestone
fill ~-40~-50~10 ~-40~-50~11 netherrack
fill ~-40~-49~10 ~-40~-49~11 fire 15
fill ~-40~-48~10 ~-40~-48~11 air
fill ~-39~-50~10 ~-39~-50~11 cobblestone
fill ~-39~-49~10 ~-39~-49~11 iron_bars
fill ~-38~-50~10 ~-29~-50~14 double_stone_block_slab 0
setblock ~-38~-45~10 cobblestone
setblock ~-35~-45~10 cobblestone
setblock ~-32~-45~10 cobblestone
setblock ~-29~-45~10 cobblestone
setblock ~-26~-45~10 cobblestone
fill ~-24~-46~10 ~-24~-46~11 air
fill ~-23~-50~10 ~-23~-50~11 double_stone_block_slab 0
fill ~-23~-49~10 ~-23~-48~11 air
setblock ~-23~-47~10 stone_stairs 7
fill ~-23~-46~10 ~-23~-45~11 cobblestone
fill ~-22~-45~10 ~-22~-45~24 cobblestone
fill ~-21~-45~10 ~-21~-45~11 stone_stairs 5
fill ~-20~-45~10 ~-20~-45~11 lit_redstone_lamp
fill ~-20~-44~10 ~-20~-44~11 redstone_block
fill ~-19~-45~10 ~-19~-45~11 stone_stairs 4
fill ~-18~-45~10 ~-18~-45~11 stone_stairs 5
fill ~-17~-45~10 ~-17~-45~11 lit_redstone_lamp
fill ~-17~-44~10 ~-17~-44~11 redstone_block
fill ~-16~-45~10 ~-16~-45~11 stone_stairs 4
fill ~-15~-45~10 ~-15~-45~11 stone_stairs 5
fill ~-14~-45~10 ~-14~-45~11 lit_redstone_lamp
fill ~-14~-44~10 ~-14~-44~11 redstone_block
fill ~-13~-45~10 ~-13~-45~11 stone_stairs 4
fill ~-12~-45~10 ~-12~-45~11 stone_stairs 5
fill ~-11~-45~10 ~-11~-45~11 lit_redstone_lamp
fill ~-11~-44~10 ~-11~-44~11 redstone_block
fill ~-10~-45~10 ~-10~-45~11 stone_stairs 4
fill ~-8~-50~10 ~-8~-45~11 cobblestone
setblock ~-38~-45~11 lit_redstone_lamp
setblock ~-38~-44~11 redstone_block
setblock ~-35~-45~11 lit_redstone_lamp
setblock ~-35~-44~11 redstone_block
setblock ~-32~-45~11 lit_redstone_lamp
setblock ~-32~-44~11 redstone_block
setblock ~-29~-45~11 lit_redstone_lamp
setblock ~-29~-44~11 redstone_block
setblock ~-26~-45~11 lit_redstone_lamp
setblock ~-26~-44~11 redstone_block
setblock ~-23~-47~11 stone_stairs 6
fill ~-50~-50~12 ~-50~-45~12 stonebrick 0
fill ~-49~-50~12 ~-48~-45~12 cobblestone
fill ~-47~-50~12 ~-47~-45~13 stonebrick 0
fill ~-46~-50~12 ~-45~-45~12 cobblestone
fill ~-44~-50~12 ~-44~-45~13 stonebrick 0
fill ~-43~-50~12 ~-42~-45~12 cobblestone
fill ~-41~-50~12 ~-41~-45~12 stonebrick 0
fill ~-40~-50~12 ~-39~-50~14 double_stone_block_slab 0
fill ~-40~-49~12 ~-39~-49~12 brick_block
setblock ~-40~-48~12 stone_stairs 3
setblock ~-38~-45~12 cobblestone
setblock ~-35~-45~12 cobblestone
setblock ~-32~-45~12 cobblestone
setblock ~-29~-45~12 cobblestone
setblock ~-26~-45~12 cobblestone
setblock ~-24~-46~12 torch 2
fill ~-23~-50~12 ~-23~-45~12 stonebrick 0
fill ~-21~-45~12 ~-10~-45~12 cobblestone
fill ~-8~-50~12 ~-8~-45~12 stonebrick 0
fill ~-50~-50~13 ~-50~-45~14 cobblestone
fill ~-49~-50~13 ~-48~-50~14 double_stone_block_slab 0
fill ~-49~-49~13 ~-49~-46~14 chest 5
fill ~-49~-45~13 ~-49~-45~14 stone_block_slab 11
fill ~-48~-49~13 ~-48~-46~14 air
fill ~-48~-45~13 ~-48~-45~27 cobblestone
fill ~-46~-50~13 ~-45~-50~26 double_stone_block_slab 0
fill ~-46~-49~13 ~-45~-46~13 chest 3
fill ~-46~-45~13 ~-45~-45~13 stone_block_slab 11
fill ~-43~-50~13 ~-42~-50~14 double_stone_block_slab 0
fill ~-43~-49~13 ~-43~-46~14 air
fill ~-43~-45~13 ~-43~-45~27 cobblestone
fill ~-42~-49~13 ~-42~-46~14 chest 4
fill ~-42~-45~13 ~-42~-45~14 stone_block_slab 11
fill ~-41~-50~13 ~-41~-45~14 cobblestone
fill ~-40~-49~13 ~-39~-48~14 air
setblock ~-38~-45~13 lit_redstone_lamp
setblock ~-38~-44~13 redstone_block
setblock ~-35~-45~13 lit_redstone_lamp
setblock ~-35~-44~13 redstone_block
setblock ~-32~-45~13 lit_redstone_lamp
setblock ~-32~-44~13 redstone_block
setblock ~-29~-45~13 lit_redstone_lamp
setblock ~-29~-44~13 redstone_block
setblock ~-26~-45~13 lit_redstone_lamp
setblock ~-26~-44~13 redstone_block
fill ~-24~-46~13 ~-24~-46~14 air
fill ~-23~-50~13 ~-23~-45~14 cobblestone
fill ~-21~-45~13 ~-21~-45~14 stone_stairs 5
fill ~-20~-50~13 ~-17~-50~18 dirt 0
fill ~-20~-45~13 ~-20~-45~14 lit_redstone_lamp
fill ~-20~-44~13 ~-20~-44~14 redstone_block
fill ~-19~-45~13 ~-19~-45~14 stone_stairs 4
fill ~-18~-45~13 ~-18~-45~14 stone_stairs 5
fill ~-17~-45~13 ~-17~-45~14 lit_redstone_lamp
fill ~-17~-44~13 ~-17~-44~14 redstone_block
fill ~-16~-45~13 ~-16~-45~14 stone_stairs 4
fill ~-15~-50~13 ~-12~-50~18 dirt 0
fill ~-15~-45~13 ~-15~-45~14 stone_stairs 5
fill ~-14~-45~13 ~-14~-45~14 lit_redstone_lamp
fill ~-14~-44~13 ~-14~-44~14 redstone_block
fill ~-13~-45~13 ~-13~-45~14 stone_stairs 4
fill ~-12~-45~13 ~-12~-45~14 stone_stairs 5
fill ~-11~-45~13 ~-11~-45~14 lit_redstone_lamp
fill ~-11~-44~13 ~-11~-44~14 redstone_block
fill ~-10~-45~13 ~-10~-45~14 stone_stairs 4
fill ~-8~-50~13 ~-8~-45~14 cobblestone
fill ~-47~-50~14 ~-47~-50~25 double_stone_block_slab 0
fill ~-47~-49~14 ~-44~-46~25 air
fill ~-47~-45~14 ~-44~-45~14 stone_stairs 7
fill ~-44~-50~14 ~-44~-50~25 double_stone_block_slab 0
setblock ~-38~-45~14 cobblestone
setblock ~-35~-46~14 torch 4
setblock ~-35~-45~14 cobblestone
setblock ~-32~-46~14 torch 4
setblock ~-32~-45~14 cobblestone
setblock ~-29~-46~14 torch 4
setblock ~-29~-45~14 cobblestone
setblock ~-26~-46~14 torch 4
setblock ~-26~-45~14 cobblestone
fill ~-50~-50~15 ~-49~-45~15 stonebrick 0
fill ~-48~-50~15 ~-48~-50~26 double_stone_block_slab 0
setblock ~-48~-49~15 stone_brick_stairs 1
fill ~-48~2~15 ~-48~-47~26 air
setblock ~-48~-46~15 stone_brick_stairs 5
setblock ~-47~-45~15 stone_stairs 5
fill ~-46~-45~15 ~-45~-45~15 lit_redstone_lamp
fill ~-46~-44~15 ~-45~-44~15 redstone_block
setblock ~-44~-45~15 stone_stairs 4
fill ~-43~-50~15 ~-43~-50~26 double_stone_block_slab 0
setblock ~-43~-49~15 stone_brick_stairs 0
fill ~-43~-48~15 ~-43~-47~26 air
setblock ~-43~-46~15 stone_brick_stairs 4
fill ~-42~-50~15 ~-41~-45~15 stonebrick 0
fill ~-40~-50~15 ~-39~-46~15 cobblestone
fill ~-38~-50~15 ~-38~-45~15 stonebrick 0
fill ~-37~-50~15 ~-36~-50~38 double_stone_block_slab 0
fill ~-37~-49~15 ~-36~-48~36 air
setblock ~-37~-47~15 stone_stairs 5
fill ~-37~-46~15 ~-36~-46~15 cobblestone
setblock ~-36~-47~15 stone_stairs 4
fill ~-35~-50~15 ~-35~-45~15 stonebrick 0
fill ~-34~-50~15 ~-33~-46~15 cobblestone
fill ~-32~-50~15 ~-32~-45~15 stonebrick 0
fill ~-31~-50~15 ~-30~-46~15 cobblestone
fill ~-29~-50~15 ~-29~-45~15 stonebrick 0
fill ~-28~-50~15 ~-27~-46~15 cobblestone
fill ~-26~-50~15 ~-26~-45~15 stonebrick 0
fill ~-25~-50~15 ~-24~-46~15 cobblestone
fill ~-23~-50~15 ~-23~-45~15 stonebrick 0
fill ~-21~-45~15 ~-10~-45~15 cobblestone
fill ~-16~-50~15 ~-16~-50~18 dirt 0
fill ~-8~-50~15 ~-8~-45~15 stonebrick 0
fill ~-50~-50~16 ~-50~-45~17 cobblestone
fill ~-49~-50~16 ~-49~-50~17 double_stone_block_slab 0
fill ~-49~-49~16 ~-49~-46~17 chest 5
fill ~-49~-45~16 ~-49~-45~17 stone_block_slab 11
fill ~-48~-49~16 ~-48~-49~17 air
fill ~-48~-46~16 ~-48~-46~17 air
fill ~-47~-45~16 ~-44~-45~16 stone_stairs 6
fill ~-43~-49~16 ~-43~-49~17 air
fill ~-43~-46~16 ~-43~-46~17 air
fill ~-42~-50~16 ~-42~-50~17 double_stone_block_slab 0
fill ~-42~-49~16 ~-42~-46~17 chest 4
fill ~-42~-45~16 ~-42~-45~17 stone_block_slab 11
fill ~-41~-50~16 ~-41~-45~17 cobblestone
fill ~-40~-50~16 ~-38~-50~26 double_stone_block_slab 0
fill ~-40~-49~16 ~-38~-47~26 air
fill ~-40~-46~16 ~-39~-46~17 air
setblock ~-38~-46~16 torch 3
fill ~-38~-45~16 ~-38~-45~26 cobblestone
fill ~-37~-47~16 ~-33~-47~26 air
fill ~-37~-46~16 ~-36~-46~26 air
fill ~-35~-50~16 ~-33~-50~26 double_stone_block_slab 0
fill ~-35~-49~16 ~-33~-48~26 air
setblock ~-35~-46~16 torch 3
fill ~-35~-45~16 ~-35~-45~26 cobblestone
fill ~-34~-46~16 ~-33~-46~17 air
fill ~-32~-50~16 ~-32~-45~17 cobblestone
fill ~-31~-50~16 ~-24~-50~17 double_stone_block_slab 0
fill ~-31~-49~16 ~-31~-46~17 chest 5
fill ~-30~-49~16 ~-28~-47~17 air
fill ~-30~-46~16 ~-30~-46~17 air
setblock ~-29~-46~16 torch 3
fill ~-29~-45~16 ~-29~-45~17 cobblestone
fill ~-28~-46~16 ~-27~-46~17 air
fill ~-27~-49~16 ~-24~-47~16 bookshelf
setblock ~-26~-46~16 torch 3
setblock ~-26~-45~16 cobblestone
fill ~-25~-46~16 ~-24~-46~17 air
fill ~-23~-50~16 ~-23~-45~17 cobblestone
fill ~-21~-45~16 ~-21~-45~17 stone_stairs 5
fill ~-20~-45~16 ~-20~-45~17 lit_redstone_lamp
fill ~-20~-44~16 ~-20~-44~17 redstone_block
fill ~-19~-45~16 ~-19~-45~17 stone_stairs 4
fill ~-18~-45~16 ~-18~-45~17 stone_stairs 5
fill ~-17~-45~16 ~-17~-45~17 lit_redstone_lamp
fill ~-17~-44~16 ~-17~-44~17 redstone_block
fill ~-16~-45~16 ~-16~-45~17 stone_stairs 4
fill ~-15~-45~16 ~-15~-45~17 stone_stairs 5
fill ~-14~-45~16 ~-14~-45~17 lit_redstone_lamp
fill ~-14~-44~16 ~-14~-44~17 redstone_block
fill ~-13~-45~16 ~-13~-45~17 stone_stairs 4
fill ~-12~-45~16 ~-12~-45~17 stone_stairs 5
fill ~-11~-45~16 ~-11~-45~17 lit_redstone_lamp
fill ~-11~-44~16 ~-11~-44~17 redstone_block
fill ~-10~-45~16 ~-10~-45~17 stone_stairs 4
fill ~-8~-50~16 ~-8~-45~17 cobblestone
fill ~-47~-45~17 ~-44~-45~17 stone_stairs 7
fill ~-38~-46~17 ~-38~-46~25 air
fill ~-35~-46~17 ~-35~-46~25 air
setblock ~-29~-46~17 torch 4
fill ~-27~-49~17 ~-25~-47~17 air
fill ~-26~-46~17 ~-26~-46~19 air
setblock ~-26~-45~17 lit_redstone_lamp
setblock ~-26~-44~17 redstone_block
fill ~-24~-49~17 ~-24~-47~20 bookshelf
fill ~-50~-50~18 ~-49~-45~18 stonebrick 0
setblock ~-48~-49~18 stone_brick_stairs 1
setblock ~-48~-46~18 stone_brick_stairs 5
setblock ~-47~-45~18 stone_stairs 5
fill ~-46~-45~18 ~-45~-45~18 lit_redstone_lamp
fill ~-46~-44~18 ~-45~-44~18 redstone_block
setblock ~-44~-45~18 stone_stairs 4
setblock ~-43~-49~18 stone_brick_stairs 0
setblock ~-43~-46~18 stone_brick_stairs 4
fill ~-42~-50~18 ~-41~-45~18 stonebrick 0
setblock ~-40~-46~18 torch 1
fill ~-39~-46~18 ~-39~-46~26 air
fill ~-37~-45~18 ~-36~-45~18 lit_redstone_lamp
fill ~-37~-44~18 ~-36~-44~18 redstone_block
fill ~-34~-46~18 ~-34~-46~26 air
setblock ~-33~-46~18 torch 2
fill ~-32~-50~18 ~-29~-45~18 stonebrick 0
fill ~-28~-50~18 ~-24~-50~20 double_stone_block_slab 0
fill ~-28~-49~18 ~-27~-47~19 air
setblock ~-28~-46~18 torch 1
fill ~-27~-46~18 ~-27~-46~20 air
setblock ~-26~-49~18 enchanting_table
fill ~-26~-48~18 ~-25~-47~19 air
setblock ~-26~-45~18 cobblestone
fill ~-25~-49~18 ~-25~-49~19 air
fill ~-25~-46~18 ~-25~-46~20 air
setblock ~-24~-46~18 torch 2
fill ~-23~-50~18 ~-23~-45~18 stonebrick 0
fill ~-21~-45~18 ~-10~-45~18 cobblestone
fill ~-8~-50~18 ~-8~-45~18 stonebrick 0
fill ~-50~-50~19 ~-50~-45~20 cobblestone
fill ~-49~-50~19 ~-49~-50~20 double_stone_block_slab 0
fill ~-49~-49~19 ~-49~-46~20 chest 5
fill ~-49~-45~19 ~-49~-45~20 stone_block_slab 11
fill ~-48~-49~19 ~-48~-49~20 air
fill ~-48~-46~19 ~-48~-46~20 air
fill ~-47~-45~19 ~-44~-45~19 stone_stairs 6
fill ~-43~-49~19 ~-43~-49~20 air
fill ~-43~-46~19 ~-43~-46~20 air
fill ~-42~-50~19 ~-42~-50~20 double_stone_block_slab 0
fill ~-42~-49~19 ~-42~-46~20 chest 4
fill ~-42~-45~19 ~-42~-45~20 stone_block_slab 11
fill ~-41~-50~19 ~-41~-45~20 cobblestone
fill ~-40~-46~19 ~-40~-46~20 air
fill ~-37~-45~19 ~-36~-45~20 cobblestone
fill ~-33~-46~19 ~-33~-46~20 air
fill ~-32~-50~19 ~-29~-50~20 double_stone_block_slab 0
fill ~-32~-49~19 ~-29~-48~20 air
fill ~-32~-47~19 ~-29~-47~19 stone_stairs 7
fill ~-32~-46~19 ~-32~-45~20 cobblestone
fill ~-29~-46~19 ~-29~-45~20 cobblestone
fill ~-28~-46~19 ~-28~-46~20 air
setblock ~-26~-49~19 air
setblock ~-26~-45~19 lit_redstone_lamp
setblock ~-26~-44~19 redstone_block
fill ~-24~-46~19 ~-24~-46~20 air
fill ~-23~-50~19 ~-23~-45~20 cobblestone
fill ~-21~-45~19 ~-21~-45~20 stone_stairs 5
fill ~-20~-50~19 ~-12~-50~20 double_stone_block_slab 0
fill ~-20~-45~19 ~-20~-45~20 lit_redstone_lamp
fill ~-20~-44~19 ~-20~-44~20 redstone_block
fill ~-19~-45~19 ~-19~-45~20 stone_stairs 4
fill ~-18~-45~19 ~-18~-45~20 stone_stairs 5
fill ~-17~-45~19 ~-17~-45~20 lit_redstone_lamp
fill ~-17~-44~19 ~-17~-44~20 redstone_block
fill ~-16~-45~19 ~-16~-45~20 stone_stairs 4
fill ~-15~-45~19 ~-15~-45~20 stone_stairs 5
fill ~-14~-45~19 ~-14~-45~20 lit_redstone_lamp
fill ~-14~-44~19 ~-14~-44~20 redstone_block
fill ~-13~-45~19 ~-13~-45~20 stone_stairs 4
fill ~-12~-45~19 ~-12~-45~20 stone_stairs 5
fill ~-11~-45~19 ~-11~-45~20 lit_redstone_lamp
fill ~-11~-44~19 ~-11~-44~20 redstone_block
fill ~-10~-45~19 ~-10~-45~20 stone_stairs 4
fill ~-8~-50~19 ~-8~-45~20 cobblestone
fill ~-47~-45~20 ~-44~-45~20 stone_stairs 7
fill ~-32~-47~20 ~-29~-47~20 stone_stairs 6
fill ~-28~-49~20 ~-28~-47~20 air
fill ~-27~-49~20 ~-25~-47~20 bookshelf
setblock ~-26~-46~20 torch 4
setblock ~-26~-45~20 cobblestone
fill ~-50~-50~21 ~-49~-45~21 stonebrick 0
setblock ~-48~-49~21 stone_brick_stairs 1
setblock ~-48~-46~21 stone_brick_stairs 5
setblock ~-47~-45~21 stone_stairs 5
fill ~-46~-45~21 ~-45~-45~21 lit_redstone_lamp
fill ~-46~-44~21 ~-45~-44~21 redstone_block
setblock ~-44~-45~21 stone_stairs 4
setblock ~-43~-49~21 stone_brick_stairs 0
setblock ~-43~-46~21 stone_brick_stairs 4
fill ~-42~-50~21 ~-41~-45~21 stonebrick 0
setblock ~-40~-46~21 torch 1
fill ~-37~-45~21 ~-36~-45~21 lit_redstone_lamp
fill ~-37~-44~21 ~-36~-44~21 redstone_block
setblock ~-33~-46~21 torch 2
fill ~-32~-50~21 ~-29~-47~21 stonebrick 0
fill ~-32~-46~21 ~-32~-45~21 stonebrick 0
fill ~-29~-46~21 ~-29~-45~21 stonebrick 0
fill ~-28~-50~21 ~-27~-46~21 cobblestone
fill ~-26~-50~21 ~-26~-45~21 stonebrick 0
fill ~-25~-50~21 ~-24~-46~21 cobblestone
fill ~-23~-50~21 ~-23~-45~21 stonebrick 0
fill ~-21~-45~21 ~-10~-45~23 cobblestone
fill ~-20~-50~21 ~-13~-50~23 stone_block_slab 0
fill ~-12~-50~21 ~-12~-50~23 double_stone_block_slab 0
fill ~-8~-50~21 ~-8~-45~21 stonebrick 0
fill ~-50~-50~22 ~-50~-45~23 cobblestone
fill ~-49~-50~22 ~-49~-50~23 double_stone_block_slab 0
fill ~-49~-49~22 ~-49~-46~23 chest 5
fill ~-49~-45~22 ~-49~-45~23 stone_block_slab 11
fill ~-48~-49~22 ~-48~-49~23 air
fill ~-48~-46~22 ~-48~-46~23 air
fill ~-47~-45~22 ~-44~-45~22 stone_stairs 6
fill ~-43~-49~22 ~-41~-49~23 air
fill ~-43~-46~22 ~-43~-46~23 air
fill ~-42~-50~22 ~-41~-50~23 double_stone_block_slab 0
fill ~-42~-48~22 ~-41~-48~23 air
fill ~-42~-47~22 ~-41~-47~22 stone_stairs 7
fill ~-42~-46~22 ~-41~-45~23 cobblestone
fill ~-40~-46~22 ~-40~-46~23 air
fill ~-37~-45~22 ~-36~-45~23 cobblestone
fill ~-33~-46~22 ~-33~-46~23 air
fill ~-32~-50~22 ~-24~-50~23 double_stone_block_slab 0
fill ~-32~-49~22 ~-25~-48~23 air
setblock ~-32~-47~22 stone_stairs 7
fill ~-32~-46~22 ~-32~-45~23 cobblestone
setblock ~-31~-47~22 cobblestone
fill ~-30~-47~22 ~-29~-47~22 stone_stairs 7
fill ~-29~-46~22 ~-29~-45~23 cobblestone
fill ~-28~-47~22 ~-24~-47~29 air
fill ~-28~-46~22 ~-27~-46~23 air
setblock ~-26~-46~22 torch 3
setblock ~-26~-45~22 cobblestone
fill ~-25~-46~22 ~-24~-46~23 air
setblock ~-24~-49~22 jukebox
fill ~-24~-48~22 ~-24~-48~29 air
fill ~-23~-50~22 ~-23~-45~23 cobblestone
fill ~-8~-50~22 ~-8~-45~23 cobblestone
fill ~-47~-45~23 ~-44~-45~23 stone_stairs 7
fill ~-42~-47~23 ~-41~-47~23 stone_stairs 6
fill ~-32~-47~23 ~-29~-47~23 stone_stairs 6
fill ~-26~-46~23 ~-26~-46~28 air
setblock ~-26~-45~23 lit_redstone_lamp
setblock ~-26~-44~23 redstone_block
fill ~-24~-49~23 ~-24~-49~25 air
fill ~-22~-49~23 ~-21~-49~23 double_stone_block_slab 0
fill ~-22~-48~23 ~-17~-46~23 air
fill ~-20~-49~23 ~-17~-49~23 air
fill ~-14~-49~23 ~-13~-48~23 air
fill ~-12~-49~23 ~-10~-49~23 double_stone_block_slab 0
fill ~-12~-48~23 ~-10~-48~23 air
fill ~-50~-50~24 ~-49~-45~24 stonebrick 0
setblock ~-48~-49~24 stone_brick_stairs 1
setblock ~-48~-46~24 stone_brick_stairs 5
setblock ~-47~-45~24 stone_stairs 5
fill ~-46~-45~24 ~-45~-45~24 lit_redstone_lamp
fill ~-46~-44~24 ~-45~-44~24 redstone_block
setblock ~-44~-45~24 stone_stairs 4
setblock ~-43~-49~24 stone_brick_stairs 0
setblock ~-43~-46~24 stone_brick_stairs 4
fill ~-42~-50~24 ~-41~-45~24 stonebrick 0
setblock ~-40~-46~24 torch 1
fill ~-37~-45~24 ~-36~-45~24 lit_redstone_lamp
fill ~-37~-44~24 ~-36~-44~24 redstone_block
setblock ~-33~-46~24 torch 2
fill ~-32~-50~24 ~-29~-47~24 stonebrick 0
fill ~-32~-46~24 ~-32~-45~24 stonebrick 0
fill ~-29~-46~24 ~-29~-45~24 stonebrick 0
fill ~-28~-50~24 ~-24~-50~29 double_stone_block_slab 0
fill ~-28~-49~24 ~-25~-48~27 air
setblock ~-28~-46~24 torch 1
fill ~-27~-46~24 ~-27~-46~29 air
fill ~-26~-45~24 ~-26~-45~25 cobblestone
fill ~-25~-46~24 ~-25~-46~29 air
setblock ~-24~-46~24 torch 2
fill ~-23~-50~24 ~-23~-45~24 stonebrick 0
fill ~-22~-50~24 ~-21~-46~24 cobblestone
setblock ~-21~-45~24 cobblestone
fill ~-20~-50~24 ~-20~-45~24 stonebrick 0
fill ~-19~-50~24 ~-18~-45~24 cobblestone
fill ~-17~-50~24 ~-17~-45~24 stonebrick 0
fill ~-16~-50~24 ~-15~-45~24 cobblestone
fill ~-14~-50~24 ~-14~-45~24 stonebrick 0
fill ~-13~-50~24 ~-12~-45~24 cobblestone
fill ~-11~-50~24 ~-11~-45~24 stonebrick 0
fill ~-10~-50~24 ~-9~-46~24 cobblestone
setblock ~-10~-45~24 cobblestone
fill ~-8~-50~24 ~-8~-45~24 stonebrick 0
fill ~-50~-50~25 ~-50~-45~26 cobblestone
fill ~-49~-50~25 ~-49~-50~26 double_stone_block_slab 0
fill ~-49~-49~25 ~-49~-46~26 chest 5
fill ~-49~-45~25 ~-49~-45~26 stone_block_slab 11
fill ~-48~-49~25 ~-48~-49~26 air
fill ~-48~-46~25 ~-48~-46~26 air
fill ~-47~-45~25 ~-44~-45~25 stone_stairs 6
fill ~-43~-49~25 ~-43~-49~26 air
fill ~-43~-46~25 ~-43~-46~26 air
fill ~-42~-50~25 ~-42~-50~26 double_stone_block_slab 0
fill ~-42~-49~25 ~-42~-46~26 chest 4
fill ~-42~-45~25 ~-42~-45~26 stone_block_slab 11
fill ~-41~-50~25 ~-41~-45~26 cobblestone
fill ~-40~-46~25 ~-40~-46~26 air
fill ~-37~-45~25 ~-36~-45~27 cobblestone
fill ~-33~-46~25 ~-33~-46~26 air
fill ~-32~-50~25 ~-32~-45~26 cobblestone
fill ~-29~-50~25 ~-29~-45~26 cobblestone
fill ~-28~-46~25 ~-28~-46~26 air
fill ~-24~-46~25 ~-24~-46~26 air
fill ~-23~-50~25 ~-23~-45~26 cobblestone
fill ~-47~-50~26 ~-47~-45~27 stonebrick 0
fill ~-46~-49~26 ~-45~-46~26 chest 2
fill ~-46~-45~26 ~-45~-45~26 stone_block_slab 11
fill ~-44~-50~26 ~-44~-45~27 stonebrick 0
setblock ~-38~-46~26 torch 4
setblock ~-35~-46~26 torch 4
setblock ~-26~-45~26 lit_redstone_lamp
setblock ~-26~-44~26 redstone_block
setblock ~-24~-49~26 ender_chest 4
fill ~-50~-50~27 ~-50~-45~27 stonebrick 0
fill ~-49~-50~27 ~-48~-46~27 cobblestone
setblock ~-49~-45~27 cobblestone
fill ~-46~-50~27 ~-45~-45~27 cobblestone
fill ~-43~-50~27 ~-42~-46~27 cobblestone
setblock ~-42~-45~27 cobblestone
fill ~-41~-50~27 ~-41~-45~27 stonebrick 0
fill ~-40~-50~27 ~-39~-46~27 cobblestone
fill ~-38~-50~27 ~-38~-48~30 stonebrick 0
fill ~-38~-47~27 ~-38~-45~27 stonebrick 0
fill ~-37~-47~27 ~-37~-47~30 stone_stairs 5
fill ~-37~-46~27 ~-36~-46~27 cobblestone
fill ~-36~-47~27 ~-36~-47~30 stone_stairs 4
fill ~-35~-50~27 ~-35~-48~30 stonebrick 0
fill ~-35~-47~27 ~-35~-45~27 stonebrick 0
fill ~-34~-50~27 ~-33~-46~27 cobblestone
fill ~-32~-50~27 ~-32~-45~27 stonebrick 0
fill ~-29~-50~27 ~-29~-45~27 stonebrick 0
setblock ~-28~-46~27 torch 1
setblock ~-26~-45~27 cobblestone
fill ~-24~-49~27 ~-24~-49~28 air
setblock ~-24~-46~27 torch 2
fill ~-23~-50~27 ~-23~-45~27 stonebrick 0
fill ~-38~-47~28 ~-38~-47~29 cobblestone
fill ~-35~-47~28 ~-35~-47~29 cobblestone
fill ~-29~-50~28 ~-29~-45~29 cobblestone
fill ~-28~-49~28 ~-27~-48~28 air
fill ~-28~-46~28 ~-28~-46~29 air
fill ~-26~-48~28 ~-25~-48~29 air
setblock ~-26~-45~28 lit_redstone_lamp
setblock ~-26~-44~28 redstone_block
setblock ~-25~-9~28 air
fill ~-24~-46~28 ~-24~-46~29 air
fill ~-23~-50~28 ~-23~-45~29 cobblestone
fill ~-28~-49~29 ~-27~-49~29 chest 2
fill ~-28~-48~29 ~-27~-48~29 air
setblock ~-26~-49~29 bed 0
setblock ~-26~-46~29 torch 4
setblock ~-26~-45~29 cobblestone
fill ~-25~-49~29 ~-24~-49~29 chest 2
fill ~-41~-50~30 ~-41~-45~30 stonebrick 0
fill ~-40~-50~30 ~-39~-45~30 cobblestone
fill ~-38~-47~30 ~-38~-45~30 stonebrick 0
fill ~-37~-46~30 ~-36~-45~30 cobblestone
fill ~-35~-47~30 ~-35~-45~30 stonebrick 0
fill ~-34~-50~30 ~-33~-45~30 cobblestone
fill ~-32~-50~30 ~-32~-45~30 stonebrick 0
fill ~-29~-50~30 ~-29~-45~30 stonebrick 0
fill ~-28~-50~30 ~-27~-46~30 cobblestone
fill ~-26~-50~30 ~-26~-45~30 stonebrick 0
fill ~-25~-50~30 ~-24~-46~30 cobblestone
fill ~-23~-50~30 ~-23~-45~30 stonebrick 0
fill ~-41~-50~31 ~-41~-45~32 cobblestone
fill ~-40~-50~31 ~-38~-50~38 double_stone_block_slab 0
fill ~-40~-49~31 ~-38~-47~37 air
fill ~-40~-46~31 ~-39~-46~32 air
fill ~-40~-45~31 ~-32~-45~32 cobblestone
setblock ~-38~-46~31 torch 3
fill ~-37~-47~31 ~-33~-47~38 air
fill ~-37~-46~31 ~-36~-46~38 air
fill ~-35~-50~31 ~-33~-50~38 double_stone_block_slab 0
fill ~-35~-49~31 ~-33~-48~38 air
setblock ~-35~-46~31 torch 3
fill ~-34~-46~31 ~-33~-46~32 air
fill ~-32~-50~31 ~-32~-46~32 cobblestone
fill ~-38~-46~32 ~-38~-46~37 air
fill ~-35~-46~32 ~-35~-46~37 air
setblock ~-41~-50~33 stonebrick 0
fill ~-41~-49~33 ~-41~-49~35 cobblestone
fill ~-41~-48~33 ~-41~-45~33 stonebrick 0
setblock ~-40~-46~33 torch 1
fill ~-40~-45~33 ~-33~-45~33 cobblestone
fill ~-39~-46~33 ~-39~-46~38 air
fill ~-34~-46~33 ~-34~-46~38 air
setblock ~-33~-46~33 torch 2
fill ~-32~-50~33 ~-32~-45~33 stonebrick 0
fill ~-41~-50~34 ~-41~-50~35 cobblestone
fill ~-41~-48~34 ~-41~-45~35 cobblestone
fill ~-40~-46~34 ~-40~-46~35 air
fill ~-40~-45~34 ~-38~-45~38 cobblestone
fill ~-37~-45~34 ~-36~-45~35 lit_redstone_lamp
fill ~-37~-44~34 ~-36~-44~35 redstone_block
fill ~-35~-45~34 ~-32~-45~35 cobblestone
fill ~-33~-46~34 ~-33~-46~35 air
fill ~-32~-50~34 ~-32~-46~35 cobblestone
fill ~-41~-50~36 ~-41~-45~36 stonebrick 0
setblock ~-40~-46~36 torch 1
fill ~-37~-45~36 ~-33~-45~38 cobblestone
setblock ~-33~-46~36 torch 2
fill ~-32~-50~36 ~-32~-45~36 stonebrick 0
fill ~-41~-50~37 ~-41~-45~38 cobblestone
fill ~-40~-46~37 ~-40~-46~38 air
fill ~-37~-48~37 ~-36~-48~38 air
setblock ~-36~-49~37 air
fill ~-33~-46~37 ~-33~-46~38 air
fill ~-32~-50~37 ~-32~-45~38 cobblestone
fill ~-40~-49~38 ~-39~-47~38 air
setblock ~-38~-49~38 chest 2
fill ~-38~-48~38 ~-38~-47~38 air
setblock ~-38~-46~38 torch 4
setblock ~-37~-49~38 bed 0
setblock ~-36~-49~38 chest 2
setblock ~-35~-46~38 torch 4
fill ~-41~-50~39 ~-41~-45~39 stonebrick 0
fill ~-40~-50~39 ~-39~-45~39 cobblestone
fill ~-38~-50~39 ~-38~-45~39 stonebrick 0
fill ~-37~-50~39 ~-36~-45~39 cobblestone
fill ~-35~-50~39 ~-35~-45~39 stonebrick 0
fill ~-34~-50~39 ~-33~-45~39 cobblestone