fill ~25~16~2 ~33~17~2 minecraft:stained_glass 5
setblock ~29~15~2 minecraft:stained_hardened_clay 13
setblock ~29~18~2 minecraft:stained_hardened_clay 13
fill ~21~16~3 ~23~17~3 minecraft:stained_glass 5
fill ~24~15~3 ~26~15~3 minecraft:wool 15
fill ~24~16~3 ~24~18~3 minecraft:wool 15
fill ~25~18~3 ~26~18~3 minecraft:obsidian
fill ~27~15~3 ~28~15~4 minecraft:obsidian
fill ~27~18~3 ~28~18~3 minecraft:wool 15
setblock ~28~19~3 minecraft:stained_hardened_clay 13
setblock ~29~14~3 minecraft:stained_hardened_clay 13
setblock ~29~15~3 minecraft:wool 15
fill ~29~18~3 ~29~18~4 minecraft:obsidian
fill ~30~15~3 ~31~15~3 minecraft:obsidian
fill ~30~18~3 ~30~18~4 minecraft:wool 15
setblock ~30~19~3 minecraft:stained_hardened_clay 13
fill ~31~18~3 ~32~18~3 minecraft:obsidian
fill ~32~15~3 ~34~15~3 minecraft:wool 15
fill ~33~18~3 ~34~18~3 minecraft:wool 15
setblock ~34~16~3 minecraft:wool 15
setblock ~34~17~3 minecraft:obsidian
fill ~35~16~3 ~37~17~3 minecraft:stained_glass 5
fill ~18~16~4 ~19~17~4 minecraft:stained_glass 5
fill ~20~15~4 ~21~15~4 minecraft:wool 15
fill ~20~16~4 ~20~18~4 minecraft:obsidian
fill ~21~18~4 ~21~18~5 minecraft:obsidian
fill ~22~15~4 ~25~15~4 minecraft:obsidian
fill ~22~18~4 ~24~18~4 minecraft:wool 15
setblock ~25~18~4 minecraft:obsidian
setblock ~26~15~4 minecraft:wool 15
setblock ~26~18~4 minecraft:wool 15
fill ~27~18~4 ~28~18~4 minecraft:obsidian
setblock ~27~19~4 minecraft:stained_hardened_clay 13
setblock ~28~14~4 minecraft:stained_hardened_clay 13
fill ~29~15~4 ~30~15~4 minecraft:obsidian
setblock ~30~14~4 minecraft:stained_hardened_clay 13
setblock ~31~15~4 minecraft:wool 15
fill ~31~18~4 ~33~18~4 minecraft:wool 15
setblock ~31~19~4 minecraft:stained_hardened_clay 13
fill ~32~15~4 ~35~15~4 minecraft:obsidian
setblock ~34~18~4 minecraft:obsidian
fill ~35~18~4 ~37~18~4 minecraft:wool 15
fill ~36~15~4 ~37~15~5 minecraft:wool 15
fill ~38~15~4 ~38~15~5 minecraft:obsidian
fill ~38~16~4 ~38~18~4 minecraft:obsidian
fill ~39~16~4 ~40~17~4 minecraft:stained_glass 5
fill ~16~16~5 ~17~17~5 minecraft:stained_glass 5
setblock ~18~15~5 minecraft:obsidian
fill ~18~18~5 ~18~18~6 minecraft:obsidian
fill ~19~15~5 ~20~15~5 minecraft:wool 15
fill ~19~18~5 ~20~18~5 minecraft:wool 15
setblock ~21~15~5 minecraft:obsidian
setblock ~22~15~5 minecraft:wool 15
setblock ~22~18~5 minecraft:obsidian
fill ~23~14~5 ~23~14~6 minecraft:wool 15
fill ~23~19~5 ~23~19~6 minecraft:obsidian
fill ~24~14~5 ~27~14~5 minecraft:obsidian
fill ~24~19~5 ~26~19~6 minecraft:wool 15
fill ~27~13~5 ~28~13~5 minecraft:stained_hardened_clay 13
setblock ~27~19~5 minecraft:obsidian
setblock ~27~20~5 minecraft:stained_hardened_clay 13
fill ~28~14~5 ~30~14~5 minecraft:wool 15
fill ~28~19~5 ~31~19~5 minecraft:wool 15
fill ~30~13~5 ~31~13~5 minecraft:stained_hardened_clay 13
fill ~31~14~5 ~32~14~5 minecraft:obsidian
setblock ~31~20~5 minecraft:stained_hardened_clay 13
fill ~32~19~5 ~33~19~6 minecraft:obsidian
fill ~33~14~5 ~34~14~6 minecraft:wool 15
setblock ~34~19~5 minecraft:wool 15
fill ~35~14~5 ~35~14~6 minecraft:obsidian
setblock ~35~19~5 minecraft:obsidian
fill ~36~18~5 ~38~18~5 minecraft:obsidian
setblock ~39~15~5 minecraft:wool 15
fill ~39~18~5 ~40~18~6 minecraft:wool 15
setblock ~40~15~5 minecraft:obsidian
fill ~41~16~5 ~42~17~5 minecraft:stained_glass 5
fill ~14~16~6 ~15~17~6 minecraft:stained_glass 5
setblock ~16~15~6 minecraft:wool 15
fill ~16~18~6 ~17~18~6 minecraft:wool 15
setblock ~17~15~6 minecraft:obsidian
fill ~18~15~6 ~19~15~6 minecraft:wool 15
setblock ~19~18~6 minecraft:obsidian
fill ~20~14~6 ~22~14~6 minecraft:wool 15
fill ~20~19~6 ~22~19~7 minecraft:obsidian
setblock ~24~14~6 minecraft:obsidian
fill ~25~14~6 ~26~14~7 minecraft:wool 15
setblock ~27~13~6 minecraft:stained_hardened_clay 13
fill ~27~14~6 ~28~14~6 minecraft:obsidian
fill ~27~19~6 ~29~19~6 minecraft:wool 15
setblock ~27~20~6 minecraft:glowstone
fill ~27~21~6 ~27~21~9 minecraft:stained_hardened_clay 13
fill ~29~14~6 ~30~14~6 minecraft:wool 15
fill ~29~15~6 ~29~16~6 minecraft:quartz_block 2
setblock ~30~19~6 minecraft:obsidian
setblock ~31~13~6 minecraft:stained_hardened_clay 13
setblock ~31~14~6 minecraft:obsidian
setblock ~31~19~6 minecraft:wool 15
setblock ~31~20~6 minecraft:glowstone
fill ~31~21~6 ~31~21~9 minecraft:stained_hardened_clay 13
fill ~32~14~6 ~32~14~7 minecraft:wool 15
fill ~34~19~6 ~34~19~7 minecraft:obsidian
fill ~35~19~6 ~35~19~7 minecraft:wool 15
setblock ~36~14~6 minecraft:wool 15
setblock ~36~19~6 minecraft:obsidian
fill ~37~14~6 ~38~14~6 minecraft:obsidian
setblock ~37~19~6 minecraft:wool 15
setblock ~38~19~6 minecraft:obsidian
setblock ~39~15~6 minecraft:obsidian
setblock ~40~15~6 minecraft:wool 15
fill ~41~15~6 ~42~15~6 minecraft:obsidian
fill ~41~18~6 ~41~18~7 minecraft:wool 15
setblock ~42~18~6 minecraft:obsidian
fill ~43~16~6 ~44~17~6 minecraft:stained_glass 5
fill ~13~16~7 ~13~17~7 minecraft:stained_glass 5
fill ~14~15~7 ~14~15~8 minecraft:obsidian
fill ~14~18~7 ~14~18~8 minecraft:wool 15
setblock ~15~15~7 minecraft:wool 15
fill ~15~18~7 ~17~18~7 minecraft:obsidian
setblock ~16~15~7 minecraft:obsidian
setblock ~17~15~7 minecraft:wool 15
fill ~18~14~7 ~18~14~9 minecraft:wool 15
fill ~18~19~7 ~19~19~9 minecraft:obsidian
fill ~19~14~7 ~20~14~7 minecraft:obsidian
fill ~21~14~7 ~22~14~7 minecraft:wool 15
setblock ~23~14~7 minecraft:obsidian
fill ~23~19~7 ~25~19~7 minecraft:wool 15
setblock ~24~14~7 minecraft:wool 15
setblock ~26~19~7 minecraft:obsidian
setblock ~27~12~7 minecraft:stained_hardened_clay 13
fill ~27~13~7 ~28~13~7 minecraft:wool 15
fill ~27~15~7 ~29~15~7 minecraft:stained_glass_pane 11
setblock ~27~16~7 minecraft:stained_glass_pane 11
setblock ~27~17~7 minecraft:stained_glass_pane 14
fill ~27~20~7 ~28~20~7 minecraft:wool 15
fill ~28~16~7 ~29~16~7 minecraft:stained_glass_pane 14
setblock ~28~17~7 minecraft:stained_glass_pane 11
fill ~29~13~7 ~31~13~7 minecraft:obsidian
setblock ~29~17~7 minecraft:stained_glass_pane 14
setblock ~29~20~7 minecraft:obsidian
fill ~30~15~7 ~31~15~7 minecraft:stained_glass_pane 5
fill ~30~16~7 ~31~17~7 minecraft:stained_glass_pane 11
setblock ~30~20~7 minecraft:wool 15
setblock ~31~12~7 minecraft:stained_hardened_clay 13
setblock ~31~20~7 minecraft:obsidian
setblock ~32~19~7 minecraft:obsidian
setblock ~33~14~7 minecraft:obsidian
setblock ~33~19~7 minecraft:wool 15
fill ~34~14~7 ~35~14~7 minecraft:wool 15
fill ~36~14~7 ~37~14~7 minecraft:obsidian
setblock ~36~19~7 minecraft:wool 15
setblock ~37~19~7 minecraft:obsidian
setblock ~38~14~7 minecraft:wool 15
setblock ~38~19~7 minecraft:wool 15
fill ~39~14~7 ~40~14~7 minecraft:obsidian
fill ~39~19~7 ~40~19~7 minecraft:obsidian
setblock ~41~15~7 minecraft:wool 15
fill ~42~15~7 ~44~15~7 minecraft:obsidian
fill ~42~18~7 ~44~18~7 minecraft:wool 15
fill ~45~16~7 ~45~17~7 minecraft:stained_glass 5
fill ~12~16~8 ~12~17~8 minecraft:stained_glass 5
setblock ~13~15~8 minecraft:wool 15
setblock ~13~18~8 minecraft:obsidian
setblock ~15~15~8 minecraft:obsidian
setblock ~15~18~8 minecraft:wool 15
fill ~16~14~8 ~16~14~10 minecraft:wool 15
fill ~16~19~8 ~16~19~9 minecraft:wool 15
fill ~17~14~8 ~17~14~9 minecraft:obsidian
fill ~17~19~8 ~17~19~10 minecraft:obsidian
fill ~19~14~8 ~21~14~8 minecraft:wool 15
fill ~20~19~8 ~21~19~8 minecraft:wool 15
setblock ~22~13~8 minecraft:wool 15
fill ~22~20~8 ~23~20~8 minecraft:obsidian
setblock ~23~13~8 minecraft:obsidian
fill ~24~13~8 ~27~13~8 minecraft:wool 15
fill ~24~20~8 ~25~20~9 minecraft:wool 15
fill ~26~12~8 ~26~12~11 minecraft:stained_hardened_clay 13
fill ~26~20~8 ~27~20~8 minecraft:obsidian
fill ~28~12~8 ~28~12~11 minecraft:stained_hardened_clay 13
fill ~28~13~8 ~29~13~8 minecraft:obsidian
fill ~28~20~8 ~29~20~8 minecraft:wool 15
fill ~30~12~8 ~30~12~11 minecraft:stained_hardened_clay 13
fill ~30~13~8 ~32~13~8 minecraft:wool 15
setblock ~30~20~8 minecraft:obsidian
fill ~31~20~8 ~32~20~9 minecraft:wool 15
fill ~32~12~8 ~32~12~11 minecraft:stained_hardened_clay 13
fill ~33~13~8 ~33~13~11 minecraft:obsidian
fill ~33~20~8 ~35~20~8 minecraft:obsidian
fill ~34~13~8 ~34~13~10 minecraft:wool 15
fill ~35~13~8 ~35~13~12 minecraft:obsidian
setblock ~36~13~8 minecraft:wool 15
setblock ~36~20~8 minecraft:wool 15
fill ~37~14~8 ~38~14~8 minecraft:obsidian
setblock ~37~19~8 minecraft:wool 15
setblock ~38~19~8 minecraft:obsidian
fill ~39~14~8 ~39~14~9 minecraft:wool 15
setblock ~39~19~8 minecraft:wool 15
fill ~40~14~8 ~41~14~8 minecraft:obsidian
fill ~40~19~8 ~41~19~8 minecraft:obsidian
setblock ~42~14~8 minecraft:wool 15
fill ~42~19~8 ~42~19~9 minecraft:wool 15
setblock ~43~15~8 minecraft:wool 15
fill ~43~18~8 ~45~18~8 minecraft:wool 15
fill ~44~15~8 ~45~15~8 minecraft:obsidian
fill ~46~16~8 ~46~17~8 minecraft:stained_glass 5
fill ~10~16~9 ~11~17~9 minecraft:stained_glass 5
fill ~12~15~9 ~13~15~9 minecraft:obsidian
fill ~12~18~9 ~13~18~9 minecraft:wool 15
setblock ~14~14~9 minecraft:obsidian
fill ~14~19~9 ~15~19~9 minecraft:obsidian
fill ~15~14~9 ~15~14~11 minecraft:wool 15
setblock ~19~14~9 minecraft:wool 15
fill ~20~13~9 ~22~13~9 minecraft:obsidian
fill ~20~20~9 ~20~20~10 minecraft:obsidian
fill ~21~20~9 ~22~20~9 minecraft:wool 15
fill ~23~13~9 ~25~13~9 minecraft:wool 15
fill ~23~20~9 ~23~20~12 minecraft:obsidian
setblock ~26~13~9 minecraft:obsidian
fill ~26~20~9 ~26~20~11 minecraft:wool 15
setblock ~26~21~9 minecraft:stained_hardened_clay 13
fill ~27~13~9 ~27~13~10 minecraft:wool 15
fill ~27~20~9 ~28~20~9 minecraft:obsidian
setblock ~28~13~9 minecraft:obsidian
fill ~29~13~9 ~30~13~9 minecraft:wool 15
setblock ~29~14~9 minecraft:nether_brick_stairs 2
fill ~29~20~9 ~30~20~9 minecraft:wool 15
fill ~31~13~9 ~32~13~9 minecraft:obsidian
setblock ~32~21~9 minecraft:stained_hardened_clay 13
setblock ~33~20~9 minecraft:wool 15
fill ~34~20~9 ~36~20~9 minecraft:obsidian
fill ~36~13~9 ~37~13~9 minecraft:obsidian
setblock ~37~20~9 minecraft:wool 15
fill ~38~13~9 ~38~13~10 minecraft:wool 15
fill ~38~20~9 ~38~20~10 minecraft:obsidian
setblock ~39~19~9 minecraft:obsidian
fill ~40~14~9 ~41~14~9 minecraft:wool 15
fill ~40~19~9 ~41~19~9 minecraft:wool 15
fill ~42~14~9 ~42~14~10 minecraft:obsidian
fill ~43~14~9 ~44~14~10 minecraft:wool 15
fill ~43~19~9 ~43~19~10 minecraft:obsidian
fill ~44~19~9 ~44~19~12 minecraft:wool 15
setblock ~45~15~9 minecraft:obsidian
fill ~45~18~9 ~46~18~9 minecraft:obsidian
setblock ~46~15~9 minecraft:wool 15
fill ~47~16~9 ~48~17~9 minecraft:stained_glass 5
fill ~9~16~10 ~9~17~10 minecraft:stained_glass 5
setblock ~10~15~10 minecraft:obsidian
fill ~10~18~10 ~10~18~11 minecraft:obsidian
fill ~11~15~10 ~11~15~11 minecraft:wool 15
setblock ~11~18~10 minecraft:wool 15
setblock ~12~15~10 minecraft:obsidian
setblock ~12~18~10 minecraft:obsidian
fill ~13~14~10 ~13~14~12 minecraft:obsidian
fill ~13~19~10 ~15~19~10 minecraft:wool 15
setblock ~14~14~10 minecraft:wool 15
setblock ~16~19~10 minecraft:obsidian
setblock ~17~14~10 minecraft:wool 15
setblock ~18~13~10 minecraft:obsidian
setblock ~18~20~10 minecraft:obsidian
fill ~19~13~10 ~21~13~10 minecraft:wool 15
fill ~19~20~10 ~19~20~11 minecraft:wool 15
setblock ~21~20~10 minecraft:wool 15
fill ~22~13~10 ~22~13~12 minecraft:obsidian
fill ~22~20~10 ~22~20~11 minecraft:obsidian
setblock ~23~13~10 minecraft:wool 15
fill ~24~13~10 ~25~13~11 minecraft:obsidian
fill ~24~20~10 ~24~20~11 minecraft:obsidian
setblock ~25~20~10 minecraft:wool 15
fill ~25~21~10 ~25~21~11 minecraft:stained_hardened_clay 13
setblock ~26~13~10 minecraft:wool 15
fill ~27~20~10 ~27~20~11 minecraft:obsidian
fill ~28~13~10 ~29~13~10 minecraft:wool 15
setblock ~28~15~10 minecraft:quartz_stairs 4
setblock ~28~20~10 minecraft:wool 15
setblock ~29~14~10 minecraft:iron_bars
setblock ~29~15~10 minecraft:quartz_stairs 2
setblock ~29~17~10 minecraft:quartz_stairs 6
fill ~29~18~10 ~29~19~10 minecraft:nether_brick_fence
setblock ~29~20~10 minecraft:obsidian
fill ~30~13~10 ~30~13~11 minecraft:obsidian
setblock ~30~15~10 minecraft:quartz_stairs 5
fill ~30~20~10 ~30~20~11 minecraft:wool 15
fill ~31~13~10 ~32~13~10 minecraft:wool 15
fill ~31~20~10 ~31~20~11 minecraft:obsidian
setblock ~32~20~10 minecraft:wool 15
fill ~33~20~10 ~33~20~11 minecraft:obsidian
fill ~33~21~10 ~33~21~11 minecraft:stained_hardened_clay 13
fill ~34~20~10 ~36~20~10 minecraft:wool 15
fill ~36~13~10 ~37~13~10 minecraft:wool 15
setblock ~37~20~10 minecraft:obsidian
fill ~39~13~10 ~39~13~11 minecraft:obsidian
setblock ~39~20~10 minecraft:wool 15
setblock ~40~13~10 minecraft:wool 15
setblock ~40~20~10 minecraft:obsidian
setblock ~41~14~10 minecraft:wool 15
setblock ~41~19~10 minecraft:wool 15
setblock ~42~19~10 minecraft:obsidian
fill ~45~14~10 ~45~14~11 minecraft:obsidian
setblock ~45~19~10 minecraft:obsidian
setblock ~46~15~10 minecraft:obsidian
setblock ~46~18~10 minecraft:wool 15
fill ~47~15~10 ~47~15~11 minecraft:wool 15
fill ~47~18~10 ~48~18~11 minecraft:obsidian
setblock ~48~15~10 minecraft:obsidian
fill ~49~16~10 ~49~17~10 minecraft:stained_glass 5
fill ~8~16~11 ~8~17~12 minecraft:stained_glass 5
fill ~9~15~11 ~10~15~11 minecraft:wool 15
fill ~9~18~11 ~9~18~12 minecraft:obsidian
setblock ~11~18~11 minecraft:obsidian
setblock ~12~14~11 minecraft:wool 15
fill ~12~19~11 ~12~19~12 minecraft:obsidian
fill ~13~19~11 ~13~19~12 minecraft:wool 15
setblock ~14~14~11 minecraft:obsidian
fill ~14~19~11 ~15~19~11 minecraft:obsidian
fill ~16~13~11 ~17~13~11 minecraft:obsidian
fill ~16~20~11 ~16~20~12 minecraft:wool 15
fill ~17~20~11 ~17~20~13 minecraft:obsidian
fill ~18~13~11 ~18~13~13 minecraft:wool 15
fill ~18~20~11 ~18~20~12 minecraft:wool 15
fill ~19~13~11 ~20~13~13 minecraft:obsidian
fill ~20~20~11 ~20~20~13 minecraft:wool 15
setblock ~21~13~11 minecraft:wool 15
fill ~21~20~11 ~21~20~12 minecraft:obsidian
fill ~23~13~11 ~23~13~12 minecraft:obsidian
setblock ~24~21~11 minecraft:glowstone
setblock ~25~20~11 minecraft:obsidian
fill ~26~13~11 ~28~13~11 minecraft:obsidian
setblock ~27~12~11 minecraft:glowstone
setblock ~28~20~11 minecraft:obsidian
setblock ~29~12~11 minecraft:stained_hardened_clay 13
setblock ~29~13~11 minecraft:wool 15
setblock ~29~15~11 minecraft:stone_block_slab 14
fill ~29~16~11 ~29~17~11 minecraft:quartz_stairs 3
setblock ~29~20~11 minecraft:wool 15
setblock ~31~12~11 minecraft:glowstone
fill ~31~13~11 ~32~13~11 minecraft:obsidian
setblock ~32~20~11 minecraft:obsidian
setblock ~34~13~11 minecraft:obsidian
setblock ~34~20~11 minecraft:wool 15
setblock ~34~21~11 minecraft:glowstone
fill ~35~20~11 ~36~20~11 minecraft:obsidian
setblock ~36~13~11 minecraft:wool 15
fill ~37~13~11 ~38~13~11 minecraft:obsidian
fill ~37~20~11 ~38~20~12 minecraft:wool 15
fill ~39~20~11 ~39~20~12 minecraft:obsidian
setblock ~40~13~11 minecraft:obsidian
setblock ~40~20~11 minecraft:wool 15
fill ~41~13~11 ~41~13~12 minecraft:wool 15
fill ~41~20~11 ~42~20~11 minecraft:obsidian
setblock ~42~13~11 minecraft:obsidian
fill ~43~14~11 ~44~14~11 minecraft:obsidian
setblock ~43~19~11 minecraft:wool 15
fill ~45~19~11 ~46~19~11 minecraft:wool 15
setblock ~46~14~11 minecraft:obsidian
fill ~48~15~11 ~48~15~12 minecraft:wool 15
fill ~49~15~11 ~49~15~13 minecraft:obsidian
fill ~49~18~11 ~49~18~13 minecraft:obsidian
fill ~50~16~11 ~50~17~12 minecraft:stained_glass 5
fill ~9~15~12 ~10~15~12 minecraft:obsidian
setblock ~10~18~12 minecraft:wool 15
fill ~11~14~12 ~11~14~14 minecraft:wool 15
fill ~11~19~12 ~11~19~14 minecraft:wool 15
fill ~12~14~12 ~12~14~13 minecraft:obsidian
setblock ~14~14~12 minecraft:wool 15
setblock ~14~19~12 minecraft:obsidian
fill ~15~13~12 ~15~13~16 minecraft:obsidian
setblock ~15~20~12 minecraft:wool 15
setblock ~16~13~12 minecraft:wool 15
setblock ~17~13~12 minecraft:obsidian
fill ~19~20~12 ~19~20~14 minecraft:obsidian
setblock ~21~13~12 minecraft:obsidian
setblock ~22~20~12 minecraft:wool 15
fill ~24~12~12 ~24~12~13 minecraft:obsidian
setblock ~24~13~12 minecraft:glowstone
fill ~24~21~12 ~25~21~12 minecraft:wool 15
fill ~25~12~12 ~25~12~13 minecraft:wool 15
fill ~25~13~12 ~27~13~12 minecraft:nether_brick_stairs 3
fill ~25~22~12 ~25~22~15 minecraft:stained_hardened_clay 13
setblock ~26~11~12 minecraft:stained_hardened_clay 13
fill ~26~12~12 ~34~12~13 minecraft:obsidian
fill ~26~21~12 ~27~21~12 minecraft:obsidian
setblock ~28~21~12 minecraft:wool 15
setblock ~29~20~12 minecraft:glowstone
setblock ~29~21~12 minecraft:obsidian
setblock ~30~21~12 minecraft:wool 15
fill ~31~13~12 ~33~13~12 minecraft:nether_brick_stairs 3
fill ~31~21~12 ~31~21~15 minecraft:obsidian
setblock ~32~11~12 minecraft:stained_hardened_clay 13
fill ~32~21~12 ~32~21~17 minecraft:wool 15
fill ~33~21~12 ~33~21~14 minecraft:obsidian
fill ~33~22~12 ~33~22~15 minecraft:stained_hardened_clay 13
setblock ~34~13~12 minecraft:glowstone
fill ~34~21~12 ~34~21~14 minecraft:wool 15
setblock ~35~20~12 minecraft:obsidian
fill ~36~13~12 ~37~13~12 minecraft:obsidian
setblock ~36~20~12 minecraft:wool 15
fill ~38~13~12 ~40~13~12 minecraft:wool 15
setblock ~40~20~12 minecraft:obsidian
fill ~41~20~12 ~42~20~13 minecraft:wool 15
fill ~42~13~12 ~42~13~13 minecraft:wool 15
setblock ~43~13~12 minecraft:obsidian
setblock ~43~20~12 minecraft:obsidian
setblock ~44~14~12 minecraft:obsidian
fill ~45~14~12 ~47~14~12 minecraft:wool 15
setblock ~45~19~12 minecraft:wool 15
fill ~46~19~12 ~47~19~13 minecraft:obsidian
setblock ~48~18~12 minecraft:obsidian
fill ~7~16~13 ~7~17~13 minecraft:stained_glass 5
setblock ~8~15~13 minecraft:wool 15
fill ~8~18~13 ~8~18~14 minecraft:obsidian
setblock ~9~15~13 minecraft:obsidian
setblock ~9~18~13 minecraft:wool 15
setblock ~10~14~13 minecraft:wool 15
fill ~10~19~13 ~10~19~16 minecraft:wool 15
fill ~12~19~13 ~12~19~14 minecraft:wool 15
setblock ~13~14~13 minecraft:wool 15
setblock ~13~19~13 minecraft:obsidian
fill ~14~13~13 ~14~13~15 minecraft:wool 15
fill ~14~20~13 ~16~20~13 minecraft:obsidian
setblock ~16~13~13 minecraft:obsidian
fill ~17~13~13 ~17~13~14 minecraft:wool 15
fill ~18~20~13 ~18~20~14 minecraft:obsidian
setblock ~21~12~13 minecraft:obsidian
fill ~21~21~13 ~22~21~13 minecraft:wool 15
fill ~22~12~13 ~23~12~13 minecraft:wool 15
fill ~23~21~13 ~23~21~15 minecraft:obsidian
fill ~24~21~13 ~24~21~14 minecraft:wool 15
fill ~25~11~13 ~25~11~14 minecraft:stained_hardened_clay 13
setblock ~25~21~13 minecraft:obsidian
fill ~26~21~13 ~27~21~13 minecraft:wool 15
setblock ~28~21~13 minecraft:obsidian
fill ~29~21~13 ~29~21~14 minecraft:wool 15
setblock ~30~21~13 minecraft:obsidian
fill ~33~11~13 ~33~11~14 minecraft:stained_hardened_clay 13
fill ~35~12~13 ~37~12~14 minecraft:obsidian
fill ~35~21~13 ~36~21~13 minecraft:wool 15
fill ~37~21~13 ~37~21~16 minecraft:obsidian
setblock ~38~13~13 minecraft:obsidian
fill ~38~20~13 ~40~20~13 minecraft:wool 15
fill ~39~13~13 ~40~13~13 minecraft:wool 15
fill ~41~13~13 ~41~13~14 minecraft:obsidian
fill ~43~13~13 ~43~13~14 minecraft:wool 15
fill ~43~20~13 ~44~20~14 minecraft:wool 15
setblock ~44~13~13 minecraft:obsidian
fill ~45~14~13 ~46~14~13 minecraft:wool 15
setblock ~45~19~13 minecraft:obsidian
setblock ~47~14~13 minecraft:obsidian
setblock ~48~14~13 minecraft:wool 15
fill ~48~19~13 ~48~19~16 minecraft:wool 15
fill ~50~15~13 ~50~15~14 minecraft:wool 15
setblock ~50~18~13 minecraft:wool 15
fill ~51~16~13 ~51~17~13 minecraft:stained_glass 5
fill ~6~16~14 ~6~17~14 minecraft:stained_glass 5
fill ~7~15~14 ~8~15~14 minecraft:obsidian
setblock ~7~18~14 minecraft:obsidian
setblock ~9~14~14 minecraft:wool 15
setblock ~9~19~14 minecraft:wool 15
setblock ~10~14~14 minecraft:obsidian
setblock ~12~14~14 minecraft:wool 15
setblock ~13~13~14 minecraft:obsidian
fill ~13~20~14 ~13~20~17 minecraft:wool 15
fill ~14~20~14 ~15~20~14 minecraft:obsidian
fill ~16~13~14 ~16~13~16 minecraft:wool 15
fill ~16~20~14 ~17~20~14 minecraft:wool 15
fill ~18~13~14 ~19~13~14 minecraft:obsidian
fill ~20~12~14 ~21~12~14 minecraft:wool 15
fill ~20~21~14 ~21~21~16 minecraft:obsidian
setblock ~22~12~14 minecraft:obsidian
setblock ~22~21~14 minecraft:wool 15
fill ~23~12~14 ~24~12~14 minecraft:wool 15
fill ~25~12~14 ~27~12~14 minecraft:obsidian
fill ~25~21~14 ~25~21~16 minecraft:wool 15
fill ~26~21~14 ~27~21~14 minecraft:obsidian
fill ~28~12~14 ~28~12~18 minecraft:wool 15
fill ~28~21~14 ~28~21~15 minecraft:wool 15
fill ~29~12~14 ~30~12~14 minecraft:obsidian
fill ~30~21~14 ~30~21~18 minecraft:wool 15
fill ~31~12~14 ~32~12~16 minecraft:wool 15
fill ~33~12~14 ~34~12~14 minecraft:obsidian
fill ~35~21~14 ~35~21~17 minecraft:obsidian
setblock ~36~21~14 minecraft:wool 15
fill ~38~12~14 ~38~12~15 minecraft:obsidian
fill ~38~21~14 ~38~21~15 minecraft:wool 15
setblock ~39~13~14 minecraft:wool 15
setblock ~39~20~14 minecraft:wool 15
setblock ~40~13~14 minecraft:obsidian
fill ~40~20~14 ~41~20~14 minecraft:obsidian
fill ~42~13~14 ~42~13~15 minecraft:obsidian
fill ~42~20~14 ~42~20~16 minecraft:wool 15
fill ~44~13~14 ~45~13~14 minecraft:wool 15
setblock ~45~20~14 minecraft:obsidian
setblock ~46~14~14 minecraft:obsidian
fill ~46~19~14 ~47~19~14 minecraft:wool 15
fill ~47~14~14 ~47~14~15 minecraft:wool 15
setblock ~48~14~14 minecraft:obsidian
setblock ~49~14~14 minecraft:wool 15
setblock ~49~19~14 minecraft:obsidian
fill ~50~18~14 ~51~18~14 minecraft:obsidian
fill ~51~15~14 ~51~15~16 minecraft:obsidian
fill ~52~16~14 ~52~17~14 minecraft:stained_glass 5
fill ~5~16~15 ~5~17~16 minecraft:stained_glass 5
setblock ~6~15~15 minecraft:obsidian
fill ~6~18~15 ~6~18~18 minecraft:obsidian
fill ~7~15~15 ~7~15~16 minecraft:wool 15
setblock ~7~18~15 minecraft:wool 15
fill ~8~14~15 ~9~14~16 minecraft:obsidian
fill ~8~19~15 ~8~19~17 minecraft:wool 15
setblock ~9~19~15 minecraft:obsidian
fill ~10~14~15 ~10~14~16 minecraft:wool 15
setblock ~11~14~15 minecraft:obsidian
setblock ~11~19~15 minecraft:obsidian
setblock ~12~13~15 minecraft:obsidian
setblock ~12~20~15 minecraft:wool 15
setblock ~13~13~15 minecraft:wool 15
fill ~14~20~15 ~14~20~17 minecraft:wool 15
fill ~15~20~15 ~17~20~15 minecraft:obsidian
setblock ~17~13~15 minecraft:obsidian
fill ~18~12~15 ~19~12~16 minecraft:wool 15
fill ~18~21~15 ~19~21~15 minecraft:obsidian
setblock ~20~12~15 minecraft:obsidian
fill ~21~12~15 ~22~12~16 minecraft:wool 15
fill ~22~21~15 ~22~21~19 minecraft:obsidian
fill ~23~12~15 ~23~12~18 minecraft:obsidian
setblock ~24~11~15 minecraft:stained_hardened_clay 13
fill ~24~12~15 ~25~12~15 minecraft:wool 15
fill ~24~21~15 ~24~21~17 minecraft:obsidian
fill ~26~12~15 ~27~12~15 minecraft:obsidian
fill ~26~21~15 ~26~21~18 minecraft:wool 15
setblock ~26~22~15 minecraft:stained_hardened_clay 13
fill ~27~21~15 ~27~21~17 minecraft:obsidian
fill ~29~12~15 ~29~12~17 minecraft:wool 15
fill ~29~21~15 ~29~21~18 minecraft:obsidian
fill ~30~12~15 ~30~12~18 minecraft:obsidian
setblock ~32~22~15 minecraft:stained_hardened_clay 13
fill ~33~12~15 ~33~12~17 minecraft:wool 15
setblock ~33~21~15 minecraft:wool 15
setblock ~34~11~15 minecraft:stained_hardened_clay 13
fill ~34~12~15 ~35~12~15 minecraft:obsidian
setblock ~34~21~15 minecraft:obsidian
fill ~36~12~15 ~37~12~16 minecraft:wool 15
fill ~36~21~15 ~36~21~18 minecraft:obsidian
setblock ~39~12~15 minecraft:wool 15
fill ~39~21~15 ~40~21~16 minecraft:obsidian
setblock ~40~12~15 minecraft:obsidian
setblock ~41~13~15 minecraft:wool 15
setblock ~41~20~15 minecraft:obsidian
fill ~43~13~15 ~46~13~15 minecraft:obsidian
fill ~43~20~15 ~44~20~15 minecraft:obsidian
fill ~45~20~15 ~46~20~16 minecraft:wool 15
setblock ~47~19~15 minecraft:obsidian
fill ~48~14~15 ~48~14~16 minecraft:wool 15
fill ~49~14~15 ~50~14~15 minecraft:obsidian
fill ~49~19~15 ~50~19~15 minecraft:wool 15
setblock ~51~18~15 minecraft:obsidian
fill ~52~15~15 ~52~15~16 minecraft:wool 15
setblock ~52~18~15 minecraft:wool 15
fill ~53~16~15 ~53~17~16 minecraft:stained_glass 5
setblock ~6~15~16 minecraft:wool 15
setblock ~7~18~16 minecraft:obsidian
setblock ~9~19~16 minecraft:wool 15
fill ~11~13~16 ~12~13~16 minecraft:wool 15
fill ~11~20~16 ~12~20~16 minecraft:obsidian
fill ~13~13~16 ~14~13~16 minecraft:obsidian
fill ~15~20~16 ~15~20~17 minecraft:wool 15
setblock ~16~20~16 minecraft:obsidian
fill ~17~12~16 ~17~12~19 minecraft:obsidian
fill ~17~21~16 ~19~21~16 minecraft:wool 15
fill ~20~12~16 ~20~12~18 minecraft:wool 15
fill ~23~11~16 ~23~11~20 minecraft:stained_hardened_clay 13
fill ~23~21~16 ~23~21~19 minecraft:wool 15
fill ~24~12~16 ~25~12~17 minecraft:obsidian
fill ~26~12~16 ~27~12~17 minecraft:wool 15
fill ~27~22~16 ~27~22~17 minecraft:stained_hardened_clay 13
fill ~28~21~16 ~28~21~18 minecraft:obsidian
setblock ~31~21~16 minecraft:wool 15
fill ~31~22~16 ~31~22~17 minecraft:stained_hardened_clay 13
setblock ~33~21~16 minecraft:obsidian
setblock ~34~12~16 minecraft:wool 15
fill ~34~21~16 ~34~21~17 minecraft:wool 15
fill ~35~11~16 ~35~11~20 minecraft:stained_hardened_clay 13
setblock ~35~12~16 minecraft:obsidian
fill ~38~12~16 ~38~12~17 minecraft:wool 15
fill ~38~21~16 ~38~21~17 minecraft:obsidian
setblock ~39~12~16 minecraft:obsidian
fill ~40~12~16 ~40~12~18 minecraft:wool 15
setblock ~41~12~16 minecraft:obsidian
setblock ~41~21~16 minecraft:obsidian
setblock ~42~13~16 minecraft:wool 15
setblock ~43~13~16 minecraft:obsidian
fill ~43~20~16 ~44~20~16 minecraft:wool 15
fill ~44~13~16 ~44~13~17 minecraft:wool 15
fill ~45~13~16 ~45~13~17 minecraft:obsidian
fill ~46~13~16 ~46~13~17 minecraft:wool 15
fill ~47~13~16 ~47~13~17 minecraft:obsidian
fill ~47~20~16 ~47~20~17 minecraft:wool 15
setblock ~49~14~16 minecraft:wool 15
setblock ~49~19~16 minecraft:wool 15
setblock ~50~14~16 minecraft:obsidian
setblock ~50~19~16 minecraft:obsidian
setblock ~51~18~16 minecraft:wool 15
fill ~52~18~16 ~52~18~17 minecraft:obsidian
fill ~4~16~17 ~4~17~18 minecraft:stained_glass 5
fill ~5~15~17 ~6~15~17 minecraft:obsidian
setblock ~5~18~17 minecraft:obsidian
fill ~7~14~17 ~7~14~20 minecraft:wool 15
fill ~7~19~17 ~7~19~18 minecraft:wool 15
fill ~8~14~17 ~8~14~18 minecraft:obsidian
setblock ~9~14~17 minecraft:wool 15
fill ~9~19~17 ~9~19~18 minecraft:obsidian
fill ~10~13~17 ~11~13~19 minecraft:obsidian
fill ~10~20~17 ~11~20~17 minecraft:obsidian
fill ~12~13~17 ~15~13~17 minecraft:wool 15
fill ~12~20~17 ~12~20~18 minecraft:wool 15
setblock ~16~12~17 minecraft:obsidian
setblock ~16~20~17 minecraft:glowstone
fill ~16~21~17 ~18~21~17 minecraft:obsidian
fill ~18~12~17 ~19~12~17 minecraft:obsidian
fill ~18~22~17 ~18~22~18 minecraft:stained_hardened_clay 13
fill ~19~21~17 ~21~21~18 minecraft:wool 15
fill ~21~12~17 ~21~12~21 minecraft:obsidian
fill ~22~12~17 ~22~12~18 minecraft:wool 15
fill ~25~21~17 ~25~21~19 minecraft:obsidian
fill ~31~12~17 ~31~12~18 minecraft:wool 15
fill ~31~21~17 ~31~21~18 minecraft:obsidian
fill ~32~12~17 ~32~12~19 minecraft:obsidian
setblock ~33~21~17 minecraft:wool 15
fill ~34~12~17 ~34~12~18 minecraft:obsidian
setblock ~35~12~17 minecraft:wool 15
setblock ~36~12~17 minecraft:obsidian
setblock ~37~12~17 minecraft:wool 15
fill ~37~21~17 ~37~21~21 minecraft:wool 15
fill ~39~12~17 ~39~12~18 minecraft:wool 15
fill ~39~21~17 ~39~21~19 minecraft:wool 15
fill ~40~21~17 ~40~21~18 minecraft:obsidian
fill ~40~22~17 ~40~22~18 minecraft:stained_hardened_clay 13
fill ~41~12~17 ~42~12~17 minecraft:wool 15
fill ~41~21~17 ~41~21~21 minecraft:wool 15
setblock ~42~20~17 minecraft:glowstone
setblock ~42~21~17 minecraft:obsidian
setblock ~43~13~17 minecraft:wool 15
setblock ~43~20~17 minecraft:obsidian
fill ~44~20~17 ~45~20~17 minecraft:wool 15
fill ~46~20~17 ~46~20~18 minecraft:obsidian
fill ~48~13~17 ~48~13~20 minecraft:wool 15
setblock ~48~20~17 minecraft:obsidian
setblock ~49~14~17 minecraft:obsidian
setblock ~49~19~17 minecraft:obsidian
fill ~50~14~17 ~51~14~17 minecraft:wool 15
fill ~50~19~17 ~50~19~18 minecraft:wool 15
fill ~51~19~17 ~51~19~22 minecraft:obsidian
fill ~52~15~17 ~52~15~18 minecraft:obsidian
setblock ~53~15~17 minecraft:wool 15
fill ~53~18~17 ~53~18~19 minecraft:wool 15
fill ~54~16~17 ~54~17~18 minecraft:stained_glass 5
setblock ~5~15~18 minecraft:wool 15
setblock ~5~18~18 minecraft:wool 15
setblock ~6~15~18 minecraft:obsidian
fill ~8~19~18 ~8~19~19 minecraft:obsidian
setblock ~9~14~18 minecraft:obsidian
setblock ~10~20~18 minecraft:wool 15
fill ~11~20~18 ~11~20~19 minecraft:obsidian
fill ~12~13~18 ~12~13~19 minecraft:obsidian
fill ~13~13~18 ~14~13~18 minecraft:wool 15
fill ~13~20~18 ~14~20~18 minecraft:obsidian
fill ~15~12~18 ~16~12~18 minecraft:wool 15
setblock ~15~21~18 minecraft:obsidian
fill ~16~21~18 ~18~21~18 minecraft:wool 15
fill ~18~12~18 ~18~12~19 minecraft:wool 15
fill ~19~12~18 ~19~12~19 minecraft:obsidian
fill ~23~13~18 ~24~13~18 minecraft:chest 3
setblock ~24~12~18 minecraft:obsidian
fill ~24~21~18 ~24~21~19 minecraft:wool 15
setblock ~25~12~18 minecraft:wool 15
fill ~26~12~18 ~26~12~19 minecraft:obsidian
setblock ~27~12~18 minecraft:wool 15
setblock ~27~21~18 minecraft:wool 15
setblock ~27~22~18 minecraft:glowstone
fill ~28~22~18 ~30~22~18 minecraft:stained_hardened_clay 13
setblock ~29~12~18 minecraft:obsidian
setblock ~31~22~18 minecraft:glowstone
fill ~32~21~18 ~34~21~18 minecraft:obsidian
setblock ~33~12~18 minecraft:obsidian
setblock ~35~12~18 minecraft:obsidian
setblock ~35~21~18 minecraft:wool 15
fill ~36~12~18 ~36~12~20 minecraft:wool 15
fill ~37~12~18 ~38~12~19 minecraft:obsidian
fill ~38~21~18 ~38~21~19 minecraft:wool 15
setblock ~41~12~18 minecraft:wool 15
fill ~42~12~18 ~42~12~24 minecraft:obsidian
fill ~42~21~18 ~43~21~18 minecraft:wool 15
fill ~43~12~18 ~43~12~19 minecraft:wool 15
setblock ~44~13~18 minecraft:obsidian
setblock ~44~20~18 minecraft:wool 15
fill ~45~13~18 ~45~13~20 minecraft:wool 15
fill ~45~20~18 ~45~20~19 minecraft:obsidian
fill ~46~13~18 ~46~13~20 minecraft:obsidian
setblock ~47~13~18 minecraft:wool 15
setblock ~47~20~18 minecraft:obsidian
setblock ~48~20~18 minecraft:wool 15
setblock ~49~14~18 minecraft:wool 15
setblock ~49~19~18 minecraft:wool 15
fill ~50~14~18 ~50~14~20 minecraft:obsidian
fill ~51~14~18 ~51~14~20 minecraft:wool 15
setblock ~52~18~18 minecraft:wool 15
fill ~53~15~18 ~53~15~19 minecraft:obsidian
fill ~3~16~19 ~3~17~20 minecraft:stained_glass 5
fill ~4~15~19 ~5~15~19 minecraft:obsidian
fill ~4~18~19 ~5~18~19 minecraft:obsidian
setblock ~6~14~19 minecraft:wool 15
fill ~6~19~19 ~7~19~19 minecraft:obsidian
setblock ~8~14~19 minecraft:wool 15
setblock ~9~13~19 minecraft:obsidian
fill ~9~20~19 ~9~20~20 minecraft:wool 15
setblock ~10~20~19 minecraft:obsidian
setblock ~12~20~19 minecraft:obsidian
fill ~13~13~19 ~13~13~20 minecraft:obsidian
fill ~13~20~19 ~13~20~20 minecraft:wool 15
setblock ~14~12~19 minecraft:wool 15
fill ~14~21~19 ~14~21~20 minecraft:obsidian
setblock ~15~12~19 minecraft:obsidian
setblock ~15~21~19 minecraft:wool 15
setblock ~16~12~19 minecraft:wool 15
fill ~16~21~19 ~17~21~19 minecraft:obsidian
fill ~16~22~19 ~17~22~19 minecraft:stained_hardened_clay 13
fill ~18~21~19 ~18~21~23 minecraft:wool 15
fill ~19~21~19 ~21~21~19 minecraft:obsidian
setblock ~20~12~19 minecraft:obsidian
setblock ~22~12~19 minecraft:obsidian
fill ~23~12~19 ~24~12~19 minecraft:wool 15
setblock ~25~12~19 minecraft:obsidian
setblock ~26~21~19 minecraft:obsidian
fill ~27~11~19 ~27~11~20 minecraft:obsidian
fill ~27~12~19 ~31~12~19 minecraft:nether_brick_stairs 3
setblock ~27~22~19 minecraft:wool 15
fill ~28~11~19 ~28~11~22 minecraft:wool 15
fill ~28~22~19 ~29~22~19 minecraft:obsidian
fill ~29~11~19 ~29~11~20 minecraft:obsidian
setblock ~30~11~19 minecraft:wool 15
setblock ~30~22~19 minecraft:wool 15
setblock ~31~11~19 minecraft:obsidian
fill ~31~22~19 ~31~22~20 minecraft:obsidian
fill ~32~21~19 ~34~21~19 minecraft:wool 15
fill ~33~12~19 ~35~12~19 minecraft:wool 15
fill ~35~21~19 ~35~21~20 minecraft:obsidian
setblock ~36~21~19 minecraft:wool 15
fill ~39~12~19 ~41~12~19 minecraft:obsidian
fill ~40~21~19 ~40~21~20 minecraft:wool 15
fill ~41~22~19 ~42~22~19 minecraft:stained_hardened_clay 13
fill ~42~21~19 ~44~21~19 minecraft:obsidian
fill ~44~12~19 ~44~12~21 minecraft:wool 15
fill ~46~20~19 ~47~20~21 minecraft:wool 15
setblock ~47~13~19 minecraft:obsidian
fill ~48~20~19 ~49~20~19 minecraft:obsidian
fill ~49~13~19 ~49~13~24 minecraft:wool 15
setblock ~50~19~19 minecraft:obsidian
fill ~52~14~19 ~52~14~23 minecraft:obsidian
setblock ~52~19~19 minecraft:obsidian
fill ~54~15~19 ~54~15~21 minecraft:wool 15
fill ~54~18~19 ~54~18~20 minecraft:obsidian
fill ~55~16~19 ~55~17~20 minecraft:stained_glass 5
setblock ~4~15~20 minecraft:obsidian
fill ~4~18~20 ~4~18~22 minecraft:obsidian
setblock ~5~15~20 minecraft:wool 15
setblock ~5~18~20 minecraft:wool 15
fill ~6~14~20 ~6~14~21 minecraft:obsidian
setblock ~6~19~20 minecraft:wool 15
fill ~7~19~20 ~7~19~22 minecraft:obsidian
setblock ~8~14~20 minecraft:obsidian
setblock ~8~19~20 minecraft:wool 15
fill ~9~13~20 ~9~13~24 minecraft:wool 15
fill ~10~13~20 ~10~13~22 minecraft:obsidian
fill ~10~20~20 ~12~20~20 minecraft:wool 15
fill ~11~13~20 ~12~13~20 minecraft:wool 15
fill ~14~12~20 ~14~12~22 minecraft:obsidian
fill ~15~12~20 ~15~12~21 minecraft:wool 15
fill ~15~21~20 ~15~21~21 minecraft:obsidian
setblock ~16~12~20 minecraft:obsidian
fill ~16~21~20 ~17~21~20 minecraft:wool 15
setblock ~17~12~20 minecraft:wool 15
fill ~18~12~20 ~18~12~21 minecraft:obsidian
fill ~19~12~20 ~20~12~20 minecraft:wool 15
setblock ~19~21~20 minecraft:wool 15
setblock ~19~22~20 minecraft:stained_hardened_clay 13
fill ~20~21~20 ~21~21~21 minecraft:obsidian
setblock ~22~12~20 minecraft:wool 15
setblock ~22~21~20 minecraft:wool 15
setblock ~23~12~20 minecraft:obsidian
setblock ~23~21~20 minecraft:obsidian
fill ~24~11~20 ~25~11~20 minecraft:wool 15
fill ~24~22~20 ~24~22~22 minecraft:wool 15
fill ~25~22~20 ~28~22~20 minecraft:obsidian
fill ~26~11~20 ~26~11~22 minecraft:obsidian
setblock ~29~22~20 minecraft:wool 15
fill ~30~11~20 ~30~11~22 minecraft:obsidian
setblock ~30~22~20 minecraft:obsidian
fill ~31~11~20 ~31~11~21 minecraft:wool 15
fill ~32~11~20 ~32~11~23 minecraft:obsidian
setblock ~32~22~20 minecraft:wool 15
fill ~33~11~20 ~33~11~21 minecraft:wool 15
setblock ~33~22~20 minecraft:obsidian
setblock ~34~11~20 minecraft:obsidian
setblock ~34~22~20 minecraft:wool 15
setblock ~35~12~20 minecraft:obsidian
fill ~36~21~20 ~36~21~21 minecraft:obsidian
fill ~37~12~20 ~39~12~20 minecraft:wool 15
fill ~38~21~20 ~39~21~21 minecraft:obsidian
setblock ~39~22~20 minecraft:stained_hardened_clay 13
fill ~40~12~20 ~41~12~21 minecraft:obsidian
fill ~42~21~20 ~43~21~20 minecraft:wool 15
fill ~43~12~20 ~43~12~21 minecraft:obsidian
setblock ~44~21~20 minecraft:obsidian
setblock ~45~20~20 minecraft:wool 15
setblock ~47~13~20 minecraft:wool 15
fill ~48~20~20 ~48~20~21 minecraft:wool 15
fill ~49~20~20 ~49~20~21 minecraft:obsidian
setblock ~50~19~20 minecraft:wool 15
fill ~52~19~20 ~52~19~22 minecraft:wool 15
setblock ~53~15~20 minecraft:wool 15
setblock ~53~18~20 minecraft:obsidian
fill ~3~15~21 ~3~15~22 minecraft:obsidian
fill ~3~16~21 ~3~18~21 minecraft:obsidian
fill ~4~15~21 ~4~15~22 minecraft:wool 15
setblock ~5~14~21 minecraft:wool 15
fill ~5~19~21 ~5~19~22 minecraft:wool 15
fill ~6~19~21 ~6~19~24 minecraft:obsidian
setblock ~7~14~21 minecraft:obsidian
setblock ~8~13~21 minecraft:wool 15
fill ~8~20~21 ~10~20~22 minecraft:obsidian
fill ~11~13~21 ~11~13~23 minecraft:wool 15
fill ~11~20~21 ~12~20~21 minecraft:wool 15
setblock ~12~13~21 minecraft:obsidian
fill ~13~12~21 ~13~12~22 minecraft:obsidian
fill ~13~21~21 ~14~21~21 minecraft:wool 15
setblock ~16~12~21 minecraft:wool 15
fill ~16~21~21 ~16~21~24 minecraft:wool 15
setblock ~17~12~21 minecraft:obsidian
fill ~17~21~21 ~17~21~23 minecraft:obsidian
setblock ~19~12~21 minecraft:wool 15
fill ~19~21~21 ~19~21~22 minecraft:obsidian
setblock ~20~12~21 minecraft:obsidian
fill ~21~22~21 ~22~22~21 minecraft:stained_hardened_clay 13
setblock ~22~12~21 minecraft:obsidian
setblock ~22~21~21 minecraft:obsidian
fill ~23~11~21 ~24~11~22 minecraft:obsidian
fill ~23~22~21 ~23~22~23 minecraft:obsidian
fill ~24~12~21 ~25~12~21 minecraft:carpet 11
fill ~25~11~21 ~25~11~23 minecraft:wool 15
setblock ~25~22~21 minecraft:obsidian
fill ~26~22~21 ~26~22~22 minecraft:wool 15
fill ~27~11~21 ~27~11~24 minecraft:wool 15
setblock ~27~12~21 minecraft:carpet 11
fill ~27~22~21 ~29~22~21 minecraft:obsidian
fill ~29~11~21 ~29~11~22 minecraft:wool 15
fill ~30~22~21 ~31~22~21 minecraft:wool 15
setblock ~31~12~21 minecraft:carpet 11
fill ~32~22~21 ~32~22~23 minecraft:obsidian
fill ~33~12~21 ~34~12~21 minecraft:carpet 11
setblock ~33~22~21 minecraft:wool 15
fill ~34~11~21 ~35~11~21 minecraft:wool 15
fill ~34~22~21 ~35~22~21 minecraft:obsidian
fill ~36~12~21 ~39~12~21 minecraft:obsidian
fill ~36~22~21 ~37~22~21 minecraft:stained_hardened_clay 13
fill ~40~21~21 ~40~21~22 minecraft:obsidian
fill ~42~21~21 ~42~21~28 minecraft:obsidian
fill ~43~21~21 ~45~21~21 minecraft:wool 15
fill ~45~12~21 ~45~12~23 minecraft:obsidian
setblock ~46~13~21 minecraft:wool 15
fill ~47~13~21 ~48~13~21 minecraft:obsidian
fill ~50~13~21 ~50~13~26 minecraft:obsidian
setblock ~50~20~21 minecraft:obsidian
setblock ~51~14~21 minecraft:obsidian
setblock ~53~14~21 minecraft:wool 15
setblock ~53~19~21 minecraft:wool 15
fill ~54~18~21 ~55~18~22 minecraft:wool 15
fill ~55~15~21 ~55~15~22 minecraft:obsidian
setblock ~55~16~21 minecraft:obsidian
setblock ~55~17~21 minecraft:wool 15
fill ~2~16~22 ~2~17~24 minecraft:stained_glass 5
fill ~3~18~22 ~3~18~23 minecraft:obsidian
setblock ~5~14~22 minecraft:obsidian
fill ~6~14~22 ~7~14~22 minecraft:wool 15
fill ~8~13~22 ~8~13~25 minecraft:obsidian
setblock ~11~20~22 minecraft:obsidian
fill ~12~12~22 ~12~12~24 minecraft:wool 15
fill ~12~21~22 ~14~21~22 minecraft:obsidian
fill ~15~12~22 ~16~12~22 minecraft:obsidian
fill ~15~21~22 ~15~21~24 minecraft:wool 15
fill ~17~12~22 ~18~12~22 minecraft:wool 15
fill ~19~12~22 ~19~12~23 minecraft:obsidian
setblock ~20~12~22 minecraft:wool 15
fill ~20~21~22 ~20~21~23 minecraft:obsidian
fill ~20~22~22 ~20~22~23 minecraft:stained_hardened_clay 13
fill ~21~11~22 ~22~11~22 minecraft:obsidian
fill ~21~22~22 ~22~22~22 minecraft:wool 15
fill ~25~22~22 ~25~22~23 minecraft:wool 15
setblock ~26~12~22 minecraft:carpet 11
fill ~27~22~22 ~27~22~23 minecraft:wool 15
setblock ~28~12~22 minecraft:carpet 11
fill ~28~22~22 ~29~22~22 minecraft:obsidian
setblock ~30~12~22 minecraft:carpet 11
fill ~30~22~22 ~30~22~23 minecraft:wool 15
fill ~31~11~22 ~31~11~24 minecraft:obsidian
fill ~31~22~22 ~31~22~23 minecraft:obsidian
setblock ~32~12~22 minecraft:carpet 11
fill ~33~11~22 ~35~11~23 minecraft:obsidian
fill ~33~22~22 ~34~22~22 minecraft:obsidian
fill ~35~22~22 ~35~22~24 minecraft:wool 15
setblock ~36~11~22 minecraft:wool 15
fill ~36~22~22 ~37~22~23 minecraft:obsidian
setblock ~37~11~22 minecraft:obsidian
fill ~38~12~22 ~41~12~23 minecraft:wool 15
setblock ~38~21~22 minecraft:wool 15
fill ~38~22~22 ~38~22~23 minecraft:stained_hardened_clay 13
setblock ~39~21~22 minecraft:obsidian
fill ~41~21~22 ~41~21~26 minecraft:obsidian
fill ~43~12~22 ~43~12~26 minecraft:wool 15
setblock ~43~21~22 minecraft:wool 15
fill ~44~12~22 ~44~12~25 minecraft:obsidian
fill ~44~21~22 ~45~21~22 minecraft:obsidian
fill ~46~12~22 ~46~12~23 minecraft:obsidian
setblock ~46~13~22 minecraft:glowstone
fill ~46~21~22 ~46~21~23 minecraft:wool 15
setblock ~47~13~22 minecraft:obsidian
setblock ~47~20~22 minecraft:wool 15
setblock ~48~13~22 minecraft:wool 15
fill ~48~20~22 ~48~20~23 minecraft:obsidian
fill ~49~20~22 ~50~20~23 minecraft:wool 15
setblock ~51~14~22 minecraft:wool 15
setblock ~53~14~22 minecraft:obsidian
fill ~53~19~22 ~53~19~23 minecraft:obsidian
setblock ~54~15~22 minecraft:obsidian
fill ~56~16~22 ~56~17~24 minecraft:stained_glass 5
fill ~3~15~23 ~3~15~29 minecraft:wool 15
setblock ~4~15~23 minecraft:obsidian
setblock ~4~16~23 minecraft:redstone_wire 14
setblock ~4~18~23 minecraft:wool 15
fill ~5~14~23 ~5~14~24 minecraft:wool 15
fill ~5~19~23 ~5~19~24 minecraft:obsidian
setblock ~6~14~23 minecraft:obsidian
fill ~7~13~23 ~7~13~24 minecraft:wool 15
fill ~7~20~23 ~11~20~23 minecraft:wool 15
fill ~10~13~23 ~10~13~24 minecraft:wool 15
setblock ~12~21~23 minecraft:obsidian
fill ~13~12~23 ~14~12~25 minecraft:wool 15
fill ~13~21~23 ~14~21~23 minecraft:wool 15
setblock ~15~12~23 minecraft:obsidian
fill ~16~12~23 ~17~12~23 minecraft:wool 15
fill ~18~12~23 ~18~12~24 minecraft:obsidian
setblock ~19~21~23 minecraft:wool 15
setblock ~20~12~23 minecraft:obsidian
fill ~21~11~23 ~21~11~24 minecraft:wool 15
setblock ~21~22~23 minecraft:obsidian
setblock ~22~11~23 minecraft:obsidian
setblock ~22~22~23 minecraft:wool 15
fill ~23~11~23 ~23~11~24 minecraft:wool 15
fill ~24~11~23 ~24~11~25 minecraft:obsidian
setblock ~24~12~23 minecraft:stone_brick_stairs 2
setblock ~24~22~23 minecraft:obsidian
fill ~26~11~23 ~26~11~24 minecraft:wool 15
fill ~26~22~23 ~26~22~24 minecraft:obsidian
setblock ~27~5~23 minecraft:wool 15
setblock ~27~6~23 minecraft:obsidian
setblock ~27~7~23 minecraft:wool 15
fill ~27~8~23 ~27~8~24 minecraft:obsidian
setblock ~27~12~23 minecraft:end_portal_frame 2
fill ~28~11~23 ~29~11~23 minecraft:obsidian
setblock ~28~22~23 minecraft:wool 15
setblock ~29~12~23 minecraft:carpet 11
setblock ~29~22~23 minecraft:obsidian
fill ~30~11~23 ~30~11~25 minecraft:wool 15
fill ~31~5~23 ~31~6~23 minecraft:wool 15
fill ~31~7~23 ~31~8~23 minecraft:obsidian
setblock ~31~12~23 minecraft:end_portal_frame 2
setblock ~33~22~23 minecraft:obsidian
setblock ~34~12~23 minecraft:stone_brick_stairs 2
fill ~34~22~23 ~34~22~24 minecraft:wool 15
fill ~36~11~23 ~36~11~25 minecraft:obsidian
setblock ~37~11~23 minecraft:wool 15
setblock ~38~21~23 minecraft:obsidian
fill ~39~21~23 ~40~21~23 minecraft:wool 15
fill ~43~21~23 ~43~21~24 minecraft:obsidian
setblock ~44~21~23 minecraft:wool 15
setblock ~45~21~23 minecraft:obsidian
fill ~47~13~23 ~47~13~24 minecraft:wool 15
fill ~47~20~23 ~47~20~24 minecraft:obsidian
fill ~48~13~23 ~48~13~24 minecraft:obsidian
setblock ~51~13~23 minecraft:obsidian
setblock ~51~20~23 minecraft:wool 15
fill ~52~19~23 ~52~19~27 minecraft:obsidian
setblock ~53~14~23 minecraft:wool 15
fill ~54~15~23 ~55~15~23 minecraft:wool 15
fill ~54~18~23 ~55~18~23 minecraft:obsidian
fill ~3~18~24 ~3~18~25 minecraft:wool 15
setblock ~4~14~24 minecraft:wool 15
fill ~4~15~24 ~6~15~27 minecraft:planks 5
setblock ~4~16~24 minecraft:redstone_wire 15
fill ~4~19~24 ~4~19~25 minecraft:obsidian
setblock ~5~16~24 minecraft:powered_repeater 1
fill ~6~14~24 ~6~14~26 minecraft:wool 15
setblock ~6~16~24 minecraft:redstone_wire 15
setblock ~7~20~24 minecraft:obsidian
setblock ~8~20~24 minecraft:wool 15
fill ~9~20~24 ~9~20~25 minecraft:obsidian
fill ~10~20~24 ~10~20~25 minecraft:wool 15
setblock ~11~13~24 minecraft:obsidian
setblock ~11~20~24 minecraft:obsidian
fill ~12~21~24 ~13~21~25 minecraft:wool 15
fill ~14~21~24 ~14~21~25 minecraft:obsidian
fill ~15~11~24 ~19~11~24 minecraft:stained_hardened_clay 13
setblock ~15~12~24 minecraft:wool 15
fill ~16~12~24 ~16~12~25 minecraft:obsidian
fill ~17~12~24 ~17~12~25 minecraft:wool 15
fill ~17~21~24 ~17~21~25 minecraft:wool 15
fill ~18~21~24 ~19~21~24 minecraft:obsidian
setblock ~19~12~24 minecraft:wool 15
setblock ~20~11~24 minecraft:obsidian
fill ~20~22~24 ~21~22~24 minecraft:wool 15
fill ~22~11~24 ~22~11~26 minecraft:wool 15
fill ~22~22~24 ~22~22~29 minecraft:obsidian
fill ~23~22~24 ~24~22~24 minecraft:wool 15
setblock ~24~12~24 minecraft:obsidian
setblock ~24~13~24 minecraft:stone_brick_stairs 2
setblock ~25~11~24 minecraft:obsidian
fill ~25~14~24 ~27~14~24 minecraft:stained_glass 15
fill ~25~22~24 ~25~22~25 minecraft:obsidian
setblock ~27~4~24 minecraft:wool 15
setblock ~27~9~24 minecraft:obsidian
fill ~27~12~24 ~27~13~24 minecraft:stained_glass 15
setblock ~27~15~24 minecraft:stained_glass 15
fill ~27~22~24 ~28~22~24 minecraft:obsidian
fill ~28~4~24 ~30~4~24 minecraft:web
fill ~28~10~24 ~28~10~26 minecraft:obsidian
fill ~28~11~24 ~29~11~24 minecraft:wool 15
setblock ~28~16~24 minecraft:stained_glass 5
fill ~29~8~24 ~29~8~25 minecraft:wool 15
fill ~29~9~24 ~29~10~24 minecraft:wool 15
setblock ~29~12~24 minecraft:light_weighted_pressure_plate 0
fill ~29~16~24 ~30~16~24 minecraft:stained_glass 15
fill ~29~22~24 ~29~22~25 minecraft:wool 15
setblock ~30~10~24 minecraft:obsidian
fill ~30~22~24 ~30~22~25 minecraft:obsidian
setblock ~31~4~24 minecraft:wool 15
setblock ~31~8~24 minecraft:wool 15
fill ~31~9~24 ~31~9~25 minecraft:obsidian
setblock ~31~12~24 minecraft:stained_glass 5
setblock ~31~13~24 minecraft:stained_glass 15
setblock ~31~14~24 minecraft:stained_glass 5
setblock ~31~15~24 minecraft:stained_glass 15
fill ~31~22~24 ~33~22~24 minecraft:wool 15
fill ~32~11~24 ~32~11~25 minecraft:wool 15
fill ~32~14~24 ~33~14~24 minecraft:stained_glass 15
setblock ~33~11~24 minecraft:obsidian
fill ~34~11~24 ~34~11~25 minecraft:wool 15
setblock ~34~12~24 minecraft:obsidian
setblock ~34~13~24 minecraft:stone_brick_stairs 2
fill ~35~11~24 ~35~11~25 minecraft:obsidian
setblock ~36~22~24 minecraft:obsidian
fill ~37~11~24 ~38~11~24 minecraft:obsidian
fill ~37~22~24 ~37~22~25 minecraft:wool 15
setblock ~38~22~24 minecraft:obsidian
fill ~39~11~24 ~43~11~24 minecraft:stained_hardened_clay 13
setblock ~39~12~24 minecraft:wool 15
fill ~39~21~24 ~40~21~24 minecraft:obsidian
fill ~40~12~24 ~41~12~24 minecraft:obsidian
fill ~44~21~24 ~44~21~33 minecraft:obsidian
fill ~45~12~24 ~46~12~24 minecraft:wool 15
setblock ~45~21~24 minecraft:wool 15
fill ~46~21~24 ~46~21~25 minecraft:obsidian
fill ~48~20~24 ~48~20~27 minecraft:wool 15
fill ~49~20~24 ~51~20~25 minecraft:obsidian
fill ~51~13~24 ~51~13~27 minecraft:wool 15
setblock ~52~14~24 minecraft:wool 15
setblock ~53~14~24 minecraft:obsidian
fill ~53~19~24 ~54~19~24 minecraft:wool 15
setblock ~54~14~24 minecraft:wool 15
setblock ~55~15~24 minecraft:wool 15
setblock ~55~18~24 minecraft:obsidian
fill ~2~15~25 ~2~15~26 minecraft:obsidian
fill ~2~16~25 ~2~18~25 minecraft:obsidian
fill ~4~14~25 ~5~14~25 minecraft:obsidian
setblock ~4~16~25 minecraft:powered_repeater 0
fill ~5~19~25 ~6~19~25 minecraft:wool 15
setblock ~6~16~25 minecraft:powered_repeater 2
fill ~7~13~25 ~7~13~27 minecraft:obsidian
setblock ~7~20~25 minecraft:wool 15
fill ~8~20~25 ~8~20~26 minecraft:obsidian
fill ~9~13~25 ~10~13~25 minecraft:obsidian
setblock ~10~21~25 minecraft:glowstone
setblock ~11~12~25 minecraft:wool 15
setblock ~11~13~25 minecraft:glowstone
setblock ~11~21~25 minecraft:wool 15
setblock ~12~12~25 minecraft:obsidian
setblock ~14~11~25 minecraft:stained_hardened_clay 13
fill ~15~12~25 ~15~12~28 minecraft:obsidian
fill ~15~21~25 ~16~21~25 minecraft:obsidian
fill ~18~12~25 ~18~12~27 minecraft:wool 15
setblock ~18~21~25 minecraft:obsidian
fill ~19~11~25 ~19~11~26 minecraft:obsidian
fill ~19~22~25 ~19~22~27 minecraft:wool 15
fill ~20~11~25 ~20~11~29 minecraft:wool 15
fill ~20~12~25 ~20~12~26 minecraft:carpet 11
fill ~20~22~25 ~20~22~26 minecraft:obsidian
fill ~21~11~25 ~21~11~26 minecraft:obsidian
setblock ~21~22~25 minecraft:wool 15
setblock ~22~12~25 minecraft:stone_brick_stairs 0
fill ~23~11~25 ~23~11~26 minecraft:obsidian
setblock ~23~12~25 minecraft:wool 15
setblock ~23~13~25 minecraft:stone_brick_stairs 0
setblock ~23~22~25 minecraft:obsidian
setblock ~24~12~25 minecraft:glowstone
setblock ~24~13~25 minecraft:wool 15
fill ~24~22~25 ~24~22~28 minecraft:wool 15
fill ~25~11~25 ~25~11~28 minecraft:wool 15
setblock ~25~14~25 minecraft:stone_brick_stairs 0
setblock ~26~4~25 minecraft:web
fill ~26~11~25 ~27~11~27 minecraft:obsidian
fill ~26~14~25 ~27~14~25 minecraft:glowstone
setblock ~26~15~25 minecraft:stone_brick_stairs 0
fill ~26~22~25 ~28~22~25 minecraft:wool 15
setblock ~27~9~25 minecraft:wool 15
fill ~27~12~25 ~27~13~25 minecraft:glowstone
setblock ~27~15~25 minecraft:glowstone
setblock ~27~16~25 minecraft:stone_brick_stairs 0
fill ~28~11~25 ~28~11~28 minecraft:wool 15
fill ~28~12~25 ~28~12~26 minecraft:obsidian
fill ~28~13~25 ~28~16~25 minecraft:obsidian
fill ~29~10~25 ~30~10~25 minecraft:wool 15
fill ~29~11~25 ~29~11~27 minecraft:obsidian
setblock ~29~12~25 minecraft:iron_door 3
fill ~29~14~25 ~30~16~25 minecraft:obsidian
setblock ~29~23~25 minecraft:nether_brick_stairs 2
fill ~30~12~25 ~30~12~26 minecraft:obsidian
setblock ~30~13~25 minecraft:obsidian
fill ~31~11~25 ~31~11~27 minecraft:wool 15
fill ~31~12~25 ~31~15~25 minecraft:glowstone
setblock ~31~16~25 minecraft:stone_brick_stairs 1
fill ~31~22~25 ~31~22~28 minecraft:obsidian
setblock ~32~4~25 minecraft:web
setblock ~32~14~25 minecraft:glowstone
setblock ~32~15~25 minecraft:stone_brick_stairs 1
fill ~32~22~25 ~33~22~25 minecraft:wool 15
setblock ~33~11~25 minecraft:wool 15
setblock ~33~14~25 minecraft:stone_brick_stairs 1
setblock ~34~12~25 minecraft:glowstone
setblock ~34~13~25 minecraft:obsidian
fill ~34~22~25 ~35~22~25 minecraft:obsidian
setblock ~35~12~25 minecraft:obsidian
setblock ~35~13~25 minecraft:stone_brick_stairs 1
setblock ~36~12~25 minecraft:stone_brick_stairs 1
setblock ~36~22~25 minecraft:wool 15
fill ~37~11~25 ~37~11~26 minecraft:wool 15
fill ~38~11~25 ~39~11~25 minecraft:obsidian
fill ~38~12~25 ~38~12~26 minecraft:carpet 11
fill ~38~22~25 ~38~22~31 minecraft:wool 15
setblock ~39~22~25 minecraft:obsidian
fill ~40~12~25 ~42~12~25 minecraft:wool 15
setblock ~40~21~25 minecraft:obsidian
fill ~43~21~25 ~43~21~26 minecraft:wool 15
setblock ~44~11~25 minecraft:stained_hardened_clay 13
fill ~45~12~25 ~46~12~25 minecraft:obsidian
setblock ~45~21~25 minecraft:obsidian
fill ~47~12~25 ~47~12~27 minecraft:wool 15
fill ~47~13~25 ~47~13~27 minecraft:nether_brick_stairs 0
fill ~47~21~25 ~47~21~26 minecraft:obsidian
setblock ~48~13~25 minecraft:wool 15
setblock ~48~21~25 minecraft:glowstone
setblock ~49~13~25 minecraft:obsidian
fill ~52~14~25 ~52~14~27 minecraft:obsidian
setblock ~53~14~25 minecraft:wool 15
fill ~53~19~25 ~53~19~26 minecraft:wool 15
fill ~54~14~25 ~54~14~31 minecraft:obsidian
fill ~54~19~25 ~54~19~27 minecraft:obsidian
fill ~55~15~25 ~56~15~25 minecraft:obsidian
setblock ~55~18~25 minecraft:wool 15
setblock ~56~16~25 minecraft:wool 15
fill ~56~17~25 ~56~18~25 minecraft:obsidian
fill ~1~16~26 ~1~17~34 minecraft:stained_glass 5
fill ~2~18~26 ~3~18~27 minecraft:obsidian
setblock ~3~16~26 minecraft:redstone_wire 14
fill ~4~14~26 ~5~14~26 minecraft:wool 15
setblock ~4~16~26 minecraft:redstone_wire 15
fill ~4~19~26 ~4~19~27 minecraft:wool 15
setblock ~5~16~26 minecraft:powered_repeater 3
fill ~5~19~26 ~6~19~26 minecraft:obsidian
setblock ~6~16~26 minecraft:redstone_wire 15
setblock ~7~20~26 minecraft:obsidian
fill ~8~13~26 ~8~13~27 minecraft:wool 15
setblock ~9~13~26 minecraft:obsidian
fill ~9~20~26 ~9~20~27 minecraft:wool 15
fill ~9~21~26 ~10~21~26 minecraft:stained_hardened_clay 13
setblock ~10~13~26 minecraft:wool 15
setblock ~10~20~26 minecraft:obsidian
setblock ~11~12~26 minecraft:obsidian
fill ~11~21~26 ~11~21~29 minecraft:obsidian
fill ~11~22~26 ~14~22~26 minecraft:stained_hardened_clay 13
fill ~12~11~26 ~13~11~26 minecraft:stained_hardened_clay 13
setblock ~12~12~26 minecraft:wool 15
fill ~12~21~26 ~12~21~27 minecraft:wool 15
fill ~13~12~26 ~14~12~27 minecraft:obsidian
setblock ~13~21~26 minecraft:obsidian
fill ~14~21~26 ~16~21~26 minecraft:wool 15
setblock ~16~12~26 minecraft:wool 15
fill ~17~12~26 ~17~12~28 minecraft:obsidian
fill ~17~21~26 ~17~21~29 minecraft:obsidian
setblock ~18~21~26 minecraft:wool 15
setblock ~21~22~26 minecraft:obsidian
fill ~23~14~26 ~23~14~28 minecraft:stained_glass 15
setblock ~23~22~26 minecraft:wool 15
setblock ~24~11~26 minecraft:wool 15
setblock ~24~14~26 minecraft:stone_brick_stairs 2
setblock ~25~4~26 minecraft:web
setblock ~25~14~26 minecraft:stained_glass 15
fill ~25~22~26 ~25~22~27 minecraft:wool 15
setblock ~26~12~26 minecraft:wool 15
fill ~26~15~26 ~27~15~27 minecraft:stained_glass 15
fill ~26~22~26 ~26~22~28 minecraft:obsidian
fill ~27~9~26 ~27~9~27 minecraft:obsidian
fill ~27~12~26 ~27~12~27 minecraft:obsidian
fill ~27~16~26 ~27~16~27 minecraft:stained_glass 15
fill ~27~22~26 ~27~22~28 minecraft:wool 15
setblock ~28~16~26 minecraft:obsidian
setblock ~28~17~26 minecraft:stone_brick_stairs 2
fill ~28~22~26 ~29~22~26 minecraft:obsidian
fill ~29~8~26 ~29~8~27 minecraft:obsidian
setblock ~29~10~26 minecraft:obsidian
setblock ~29~12~26 minecraft:light_weighted_pressure_plate 0
fill ~29~23~26 ~29~23~27 minecraft:stained_glass 5
setblock ~29~24~26 minecraft:nether_brick_stairs 2
setblock ~30~10~26 minecraft:wool 15
fill ~30~11~26 ~30~11~28 minecraft:obsidian
setblock ~30~16~26 minecraft:obsidian
setblock ~30~17~26 minecraft:stone_brick_stairs 2
setblock ~30~22~26 minecraft:wool 15
setblock ~31~9~26 minecraft:wool 15
fill ~31~12~26 ~32~12~26 minecraft:obsidian
fill ~31~15~26 ~32~15~26 minecraft:stained_glass 15
fill ~31~16~26 ~31~16~27 minecraft:stained_glass 15
fill ~32~11~26 ~34~11~26 minecraft:obsidian
fill ~32~22~26 ~34~22~26 minecraft:obsidian
setblock ~33~4~26 minecraft:web
setblock ~33~14~26 minecraft:stained_glass 5
setblock ~34~14~26 minecraft:stone_brick_stairs 2
fill ~35~11~26 ~36~11~26 minecraft:wool 15
setblock ~35~14~26 minecraft:stained_glass 15
fill ~35~22~26 ~35~22~27 minecraft:wool 15
fill ~36~22~26 ~37~22~26 minecraft:obsidian
fill ~38~11~26 ~39~11~26 minecraft:wool 15
setblock ~39~22~26 minecraft:wool 15
fill ~40~12~26 ~40~12~27 minecraft:wool 15
setblock ~40~21~26 minecraft:wool 15
fill ~41~12~26 ~41~12~27 minecraft:obsidian
fill ~42~12~26 ~42~12~29 minecraft:wool 15
fill ~44~12~26 ~45~12~26 minecraft:wool 15
fill ~44~22~26 ~47~22~26 minecraft:stained_hardened_clay 13
fill ~45~11~26 ~46~11~26 minecraft:stained_hardened_clay 13
fill ~45~21~26 ~46~21~29 minecraft:wool 15
setblock ~46~12~26 minecraft:obsidian
fill ~48~13~26 ~48~13~29 minecraft:obsidian
fill ~48~21~26 ~49~21~26 minecraft:stained_hardened_clay 13
setblock ~49~13~26 minecraft:wool 15
fill ~49~20~26 ~49~20~28 minecraft:obsidian
fill ~50~20~26 ~51~20~26 minecraft:wool 15
fill ~53~14~26 ~53~14~27 minecraft:obsidian
setblock ~53~15~26 minecraft:stone_block_slab2 0
fill ~53~16~26 ~53~17~26 minecraft:stone_block_slab2 0
setblock ~55~15~26 minecraft:obsidian
fill ~55~18~26 ~55~18~27 minecraft:obsidian
setblock ~56~15~26 minecraft:wool 15
setblock ~56~18~26 minecraft:wool 15
fill ~57~16~26 ~57~17~34 minecraft:stained_glass 5
setblock ~2~15~27 minecraft:wool 15
setblock ~3~16~27 minecraft:redstone_wire 13
fill ~4~14~27 ~4~14~28 minecraft:obsidian
fill ~5~14~27 ~5~14~28 minecraft:wool 15
setblock ~5~19~27 minecraft:obsidian
setblock ~6~14~27 minecraft:obsidian
setblock ~6~19~27 minecraft:wool 15
fill ~7~12~27 ~10~12~27 minecraft:stained_hardened_clay 13
fill ~7~20~27 ~8~20~28 minecraft:wool 15
fill ~8~21~27 ~8~21~28 minecraft:stained_hardened_clay 13
fill ~9~13~27 ~9~13~29 minecraft:wool 15
fill ~10~13~27 ~10~13~28 minecraft:obsidian
setblock ~10~20~27 minecraft:wool 15
setblock ~11~11~27 minecraft:stained_hardened_clay 13
fill ~11~12~27 ~11~12~28 minecraft:wool 15
setblock ~11~13~27 minecraft:crafting_table
setblock ~12~12~27 minecraft:obsidian
fill ~13~21~27 ~13~21~29 minecraft:wool 15
fill ~14~13~27 ~15~13~27 minecraft:obsidian
fill ~14~14~27 ~15~14~27 minecraft:brewing_stand 0
fill ~14~21~27 ~14~21~29 minecraft:obsidian
setblock ~14~22~27 minecraft:stained_hardened_clay 13
fill ~15~21~27 ~15~21~33 minecraft:wool 15
fill ~16~12~27 ~16~12~30 minecraft:obsidian
fill ~16~21~27 ~16~21~28 minecraft:obsidian
setblock ~18~21~27 minecraft:obsidian
fill ~19~11~27 ~19~11~28 minecraft:wool 15
fill ~20~22~27 ~21~22~27 minecraft:wool 15
setblock ~21~11~27 minecraft:wool 15
setblock ~21~12~27 minecraft:carpet 11
fill ~22~11~27 ~22~11~29 minecraft:obsidian
setblock ~23~11~27 minecraft:wool 15
fill ~23~22~27 ~23~22~28 minecraft:obsidian
setblock ~24~4~27 minecraft:web
setblock ~24~11~27 minecraft:obsidian
fill ~24~14~27 ~24~14~28 minecraft:glowstone
setblock ~24~15~27 minecraft:stone_brick_stairs 2
fill ~25~12~27 ~25~12~29 minecraft:wool 15
fill ~25~15~27 ~25~15~28 minecraft:stained_glass 15
setblock ~26~12~27 minecraft:obsidian
fill ~26~16~27 ~26~16~28 minecraft:stained_glass 15
setblock ~27~10~27 minecraft:obsidian
fill ~27~13~27 ~27~14~27 minecraft:stained_glass 15
setblock ~27~17~27 minecraft:stained_glass 15
setblock ~27~18~27 minecraft:stained_glass 5
setblock ~28~9~27 minecraft:wool 15
setblock ~28~10~27 minecraft:lit_redstone_lamp
setblock ~28~12~27 minecraft:stained_glass 5
fill ~28~16~27 ~30~16~27 minecraft:stained_glass 15
setblock ~28~17~27 minecraft:obsidian
setblock ~28~18~27 minecraft:stone_brick_stairs 2
setblock ~28~22~27 minecraft:wool 15
setblock ~28~23~27 minecraft:stained_glass 5
setblock ~29~9~27 minecraft:obsidian
setblock ~29~10~27 minecraft:redstone_block
fill ~29~17~27 ~29~17~28 minecraft:stained_glass 5
fill ~29~22~27 ~30~22~27 minecraft:obsidian
setblock ~29~24~27 minecraft:stained_glass 5
setblock ~30~9~27 minecraft:wool 15
setblock ~30~10~27 minecraft:lit_redstone_lamp
setblock ~30~12~27 minecraft:stained_glass 15
setblock ~30~17~27 minecraft:obsidian
setblock ~30~18~27 minecraft:stone_brick_stairs 2
setblock ~30~23~27 minecraft:stained_glass 5
setblock ~31~9~27 minecraft:obsidian
setblock ~31~10~27 minecraft:wool 15
setblock ~31~12~27 minecraft:obsidian
setblock ~31~13~27 minecraft:stained_glass 15
fill ~31~14~27 ~31~15~27 minecraft:stained_glass 5
setblock ~31~17~27 minecraft:stained_glass 5
setblock ~31~18~27 minecraft:stained_glass 15
fill ~32~11~27 ~32~11~31 minecraft:wool 15
fill ~32~12~27 ~32~12~28 minecraft:wool 15
fill ~32~15~27 ~33~15~28 minecraft:stained_glass 15
fill ~32~16~27 ~32~16~33 minecraft:stained_glass 15
fill ~32~22~27 ~33~22~28 minecraft:obsidian
fill ~33~11~27 ~38~11~27 minecraft:obsidian
fill ~33~12~27 ~33~12~29 minecraft:obsidian
setblock ~34~4~27 minecraft:web
fill ~34~14~27 ~34~14~28 minecraft:glowstone
setblock ~34~15~27 minecraft:stone_brick_stairs 2
setblock ~34~22~27 minecraft:wool 15
setblock ~35~14~27 minecraft:stained_glass 5
setblock ~36~22~27 minecraft:obsidian
setblock ~37~12~27 minecraft:carpet 11
setblock ~37~22~27 minecraft:wool 15
fill ~39~11~27 ~39~11~28 minecraft:wool 15
setblock ~39~22~27 minecraft:obsidian
setblock ~40~21~27 minecraft:obsidian
setblock ~41~21~27 minecraft:wool 15
fill ~43~12~27 ~44~12~27 minecraft:obsidian
fill ~43~21~27 ~43~21~28 minecraft:obsidian
setblock ~44~22~27 minecraft:stained_hardened_clay 13
fill ~45~12~27 ~46~12~28 minecraft:wool 15
setblock ~47~11~27 minecraft:stained_hardened_clay 13
setblock ~47~21~27 minecraft:wool 15
fill ~48~12~27 ~51~12~27 minecraft:stained_hardened_clay 13
fill ~49~13~27 ~49~13~28 minecraft:obsidian
fill ~50~13~27 ~50~13~28 minecraft:wool 15
setblock ~50~20~27 minecraft:wool 15
fill ~50~21~27 ~50~21~28 minecraft:stained_hardened_clay 13
setblock ~51~20~27 minecraft:obsidian
setblock ~53~19~27 minecraft:obsidian
fill ~55~15~27 ~55~15~29 minecraft:wool 15
fill ~56~15~27 ~56~15~29 minecraft:obsidian
setblock ~56~18~27 minecraft:obsidian
setblock ~2~15~28 minecraft:obsidian
setblock ~2~18~28 minecraft:obsidian
setblock ~3~16~28 minecraft:redstone_wire 12
setblock ~3~18~28 minecraft:wool 15
setblock ~3~19~28 minecraft:stained_hardened_clay 13
fill ~4~13~28 ~5~13~28 minecraft:stained_hardened_clay 13
fill ~4~15~28 ~4~15~32 minecraft:planks 5
fill ~4~16~28 ~4~16~29 minecraft:chest 5
fill ~4~17~28 ~4~17~29 minecraft:trapped_chest 5
fill ~4~19~28 ~4~19~29 minecraft:obsidian
setblock ~4~20~28 minecraft:stained_hardened_clay 13
fill ~5~15~28 ~5~15~29 minecraft:chest 5
setblock ~5~19~28 minecraft:wool 15
setblock ~5~20~28 minecraft:glowstone
fill ~5~21~28 ~7~21~28 minecraft:stained_hardened_clay 13
setblock ~6~12~28 minecraft:stained_hardened_clay 13
fill ~6~13~28 ~6~13~31 minecraft:obsidian
setblock ~6~14~28 minecraft:chest 5
setblock ~6~20~28 minecraft:obsidian
fill ~7~13~28 ~7~13~29 minecraft:wool 15
fill ~7~14~28 ~7~14~29 minecraft:wall_sign 5
fill ~8~13~28 ~8~13~33 minecraft:obsidian
fill ~9~20~28 ~10~20~28 minecraft:obsidian
setblock ~10~12~28 minecraft:glowstone
fill ~11~13~28 ~11~13~32 minecraft:nether_brick_stairs 1
fill ~12~12~28 ~13~12~28 minecraft:wool 15
fill ~12~21~28 ~12~21~29 minecraft:obsidian
fill ~14~12~28 ~14~12~29 minecraft:obsidian
fill ~15~22~28 ~16~22~28 minecraft:stained_hardened_clay 13
setblock ~17~22~28 minecraft:glowstone
fill ~18~11~28 ~18~11~31 minecraft:wool 15
fill ~18~12~28 ~18~12~32 minecraft:nether_brick_stairs 1
fill ~18~22~28 ~18~22~30 minecraft:wool 15
fill ~19~22~28 ~21~22~28 minecraft:obsidian
setblock ~20~12~28 minecraft:carpet 11
fill ~21~11~28 ~21~11~29 minecraft:obsidian
fill ~22~5~28 ~22~6~28 minecraft:obsidian
setblock ~22~7~28 minecraft:wool 15
fill ~22~8~28 ~23~8~28 minecraft:obsidian
setblock ~22~12~28 minecraft:end_portal_frame 1
setblock ~23~4~28 minecraft:obsidian
fill ~23~9~28 ~24~9~28 minecraft:obsidian
setblock ~23~11~28 minecraft:obsidian
fill ~23~12~28 ~23~13~28 minecraft:stained_glass 15
setblock ~23~15~28 minecraft:stained_glass 15
setblock ~24~11~28 minecraft:wool 15
fill ~24~12~28 ~24~13~28 minecraft:glowstone
setblock ~24~15~28 minecraft:glowstone
setblock ~24~16~28 minecraft:stone_brick_stairs 2
fill ~25~9~28 ~27~9~28 minecraft:wool 15
setblock ~25~16~28 minecraft:stained_glass 5
fill ~25~22~28 ~25~22~29 minecraft:obsidian
fill ~26~10~28 ~26~12~28 minecraft:wool 15
fill ~26~13~28 ~26~15~28 minecraft:stained_glass 15
setblock ~26~17~28 minecraft:stained_glass 15
setblock ~26~18~28 minecraft:stained_glass 5
setblock ~27~11~28 minecraft:obsidian
setblock ~27~23~28 minecraft:stained_glass 5
fill ~28~3~28 ~30~4~28 minecraft:obsidian
setblock ~28~5~28 minecraft:stained_glass 5
setblock ~28~7~28 minecraft:redstone_lamp
fill ~28~8~28 ~29~8~28 minecraft:wool 15
setblock ~28~18~28 minecraft:wool 15
setblock ~28~19~28 minecraft:stone_brick_stairs 2
fill ~28~22~28 ~28~22~29 minecraft:obsidian
fill ~28~23~28 ~30~23~28 minecraft:obsidian
setblock ~28~24~28 minecraft:stained_glass 5
setblock ~29~5~28 minecraft:obsidian
setblock ~29~6~28 minecraft:wool 15
setblock ~29~11~28 minecraft:wool 15
setblock ~29~18~28 minecraft:stained_glass 15
fill ~29~19~28 ~29~22~28 minecraft:wool 15
setblock ~29~24~28 minecraft:obsidian
setblock ~30~5~28 minecraft:stained_glass 5
setblock ~30~7~28 minecraft:redstone_lamp
setblock ~30~8~28 minecraft:obsidian
setblock ~30~18~28 minecraft:wool 15
setblock ~30~19~28 minecraft:stone_brick_stairs 2
fill ~30~22~28 ~30~22~29 minecraft:obsidian
setblock ~30~24~28 minecraft:stained_glass 5
setblock ~31~9~28 minecraft:wool 15
fill ~31~11~28 ~31~11~29 minecraft:obsidian
setblock ~31~23~28 minecraft:stained_glass 5
fill ~32~9~28 ~32~9~29 minecraft:obsidian
setblock ~32~10~28 minecraft:obsidian
fill ~32~13~28 ~32~14~28 minecraft:stained_glass 5
fill ~32~17~28 ~32~18~28 minecraft:stained_glass 15
setblock ~33~9~28 minecraft:wool 15
fill ~33~11~28 ~33~11~31 minecraft:obsidian
setblock ~33~16~28 minecraft:stained_glass 5
setblock ~34~9~28 minecraft:obsidian
fill ~34~11~28 ~34~11~29 minecraft:wool 15
fill ~34~12~28 ~34~13~28 minecraft:glowstone
setblock ~34~15~28 minecraft:glowstone
setblock ~34~16~28 minecraft:stone_brick_stairs 2
fill ~34~22~28 ~35~22~28 minecraft:obsidian
setblock ~35~4~28 minecraft:obsidian
fill ~35~8~28 ~36~8~28 minecraft:obsidian
setblock ~35~9~28 minecraft:wool 15
setblock ~35~11~28 minecraft:obsidian
fill ~35~12~28 ~35~15~28 minecraft:stained_glass 15
fill ~36~5~28 ~36~7~28 minecraft:obsidian
fill ~36~11~28 ~36~11~31 minecraft:wool 15
setblock ~36~12~28 minecraft:end_portal_frame 3
setblock ~36~22~28 minecraft:wool 15
fill ~37~11~28 ~38~11~28 minecraft:obsidian
setblock ~37~22~28 minecraft:obsidian
setblock ~38~12~28 minecraft:carpet 11
fill ~39~22~28 ~40~22~28 minecraft:wool 15
setblock ~40~11~28 minecraft:wool 15
fill ~40~12~28 ~40~12~32 minecraft:nether_brick_stairs 0
setblock ~41~12~28 minecraft:wool 15
fill ~41~21~28 ~41~21~29 minecraft:obsidian
setblock ~41~22~28 minecraft:glowstone
fill ~42~22~28 ~43~22~28 minecraft:stained_hardened_clay 13
setblock ~43~12~28 minecraft:obsidian
fill ~43~13~28 ~45~13~28 minecraft:quartz_stairs 6
fill ~44~12~28 ~44~12~29 minecraft:wool 15
setblock ~47~12~28 minecraft:obsidian
setblock ~47~21~28 minecraft:obsidian
setblock ~48~12~28 minecraft:glowstone
fill ~48~20~28 ~48~20~29 minecraft:obsidian
setblock ~50~20~28 minecraft:obsidian
fill ~51~13~28 ~51~13~32 minecraft:obsidian
fill ~51~20~28 ~52~20~29 minecraft:wool 15
fill ~51~21~28 ~53~21~28 minecraft:stained_hardened_clay 13
setblock ~52~12~28 minecraft:stained_hardened_clay 13
setblock ~52~13~28 minecraft:wool 15
setblock ~52~14~28 minecraft:slime
fill ~53~13~28 ~54~13~28 minecraft:stained_hardened_clay 13
fill ~53~14~28 ~53~14~35 minecraft:wool 15
fill ~53~19~28 ~54~19~28 minecraft:wool 15
setblock ~53~20~28 minecraft:glowstone
setblock ~54~20~28 minecraft:stained_hardened_clay 13
fill ~55~18~28 ~56~18~28 minecraft:wool 15
setblock ~55~19~28 minecraft:stained_hardened_clay 13
setblock ~2~15~29 minecraft:wool 15
setblock ~2~18~29 minecraft:wool 15
setblock ~2~19~29 minecraft:stained_hardened_clay 13
setblock ~3~14~29 minecraft:stained_hardened_clay 13
setblock ~3~16~29 minecraft:powered_repeater 2
setblock ~3~18~29 minecraft:obsidian
setblock ~4~13~29 minecraft:stained_hardened_clay 13
fill ~4~14~29 ~4~14~32 minecraft:wool 15
setblock ~5~14~29 minecraft:obsidian
fill ~5~16~29 ~5~17~29 minecraft:wall_sign 5
setblock ~5~19~29 minecraft:obsidian
setblock ~6~14~29 minecraft:trapped_chest 5
fill ~6~15~29 ~6~15~30 minecraft:wall_sign 5
setblock ~6~20~29 minecraft:wool 15
setblock ~6~21~29 minecraft:stained_hardened_clay 13
fill ~7~12~29 ~10~12~29 minecraft:stained_hardened_clay 13
fill ~7~20~29 ~8~20~29 minecraft:obsidian
setblock ~9~20~29 minecraft:wool 15
fill ~10~13~29 ~10~13~32 minecraft:wool 15
fill ~10~20~29 ~10~20~30 minecraft:obsidian
fill ~11~12~29 ~13~12~29 minecraft:obsidian
fill ~15~12~29 ~15~12~31 minecraft:wool 15
fill ~16~21~29 ~16~21~30 minecraft:wool 15
setblock ~17~12~29 minecraft:wool 15
fill ~17~22~29 ~17~22~31 minecraft:stained_hardened_clay 13
fill ~19~11~29 ~19~11~31 minecraft:obsidian
setblock ~19~22~29 minecraft:wool 15
setblock ~20~22~29 minecraft:obsidian
setblock ~21~12~29 minecraft:carpet 11
fill ~21~22~29 ~21~22~30 minecraft:wool 15
fill ~23~4~29 ~23~4~31 minecraft:web
fill ~23~10~29 ~23~10~31 minecraft:wool 15
setblock ~23~11~29 minecraft:wool 15
setblock ~23~16~29 minecraft:stained_glass 5
fill ~23~22~29 ~23~22~30 minecraft:wool 15
fill ~24~10~29 ~24~16~29 minecraft:obsidian
fill ~24~22~29 ~24~22~30 minecraft:obsidian
setblock ~25~10~29 minecraft:wool 15
fill ~25~11~29 ~25~11~32 minecraft:obsidian
setblock ~25~16~29 minecraft:obsidian
setblock ~25~17~29 minecraft:stone_brick_stairs 0
setblock ~26~9~29 minecraft:obsidian
setblock ~26~10~29 minecraft:lit_redstone_lamp
fill ~26~11~29 ~27~11~29 minecraft:wool 15
setblock ~26~12~29 minecraft:stained_glass 5
fill ~26~16~29 ~26~16~30 minecraft:stained_glass 5
setblock ~26~17~29 minecraft:wool 15
setblock ~26~18~29 minecraft:stone_brick_stairs 0
setblock ~26~22~29 minecraft:wool 15
fill ~26~23~29 ~26~23~31 minecraft:stained_glass 5
fill ~27~3~29 ~27~3~31 minecraft:wool 15
fill ~27~4~29 ~27~4~30 minecraft:wool 15
setblock ~27~5~29 minecraft:stained_glass 5
setblock ~27~7~29 minecraft:redstone_block
setblock ~27~8~29 minecraft:obsidian
setblock ~27~18~29 minecraft:wool 15
setblock ~27~19~29 minecraft:stone_brick_stairs 0
setblock ~27~22~29 minecraft:obsidian
fill ~27~23~29 ~28~23~29 minecraft:wool 15
setblock ~27~24~29 minecraft:stained_glass 5
setblock ~28~3~29 minecraft:stained_glass 5
setblock ~28~6~29 minecraft:obsidian
fill ~28~7~29 ~30~7~29 minecraft:wool 15
fill ~28~8~29 ~30~8~29 minecraft:quartz_block 1
setblock ~28~18~29 minecraft:glowstone
setblock ~28~19~29 minecraft:wool 15
fill ~28~24~29 ~30~24~29 minecraft:wool 15
fill ~28~25~29 ~28~25~31 minecraft:stained_glass 5
setblock ~29~19~29 minecraft:obsidian
setblock ~29~22~29 minecraft:obsidian
setblock ~29~23~29 minecraft:glowstone
setblock ~30~3~29 minecraft:stained_glass 5
setblock ~30~4~29 minecraft:fence 0
setblock ~30~6~29 minecraft:obsidian
setblock ~30~18~29 minecraft:glowstone
setblock ~30~19~29 minecraft:wool 15
setblock ~30~23~29 minecraft:obsidian
fill ~30~25~29 ~30~25~31 minecraft:stained_glass 5
fill ~31~3~29 ~31~3~31 minecraft:obsidian
fill ~31~4~29 ~31~4~30 minecraft:obsidian
setblock ~31~5~29 minecraft:stained_glass 5
setblock ~31~7~29 minecraft:redstone_block
fill ~31~8~29 ~31~8~31 minecraft:wool 15
setblock ~31~18~29 minecraft:obsidian
setblock ~31~19~29 minecraft:stone_brick_stairs 1
fill ~31~22~29 ~34~22~29 minecraft:wool 15
setblock ~31~23~29 minecraft:wool 15
setblock ~31~24~29 minecraft:stained_glass 5
setblock ~32~10~29 minecraft:lit_redstone_lamp
setblock ~32~12~29 minecraft:stained_glass 15
setblock ~32~17~29 minecraft:wool 15
setblock ~32~18~29 minecraft:stone_brick_stairs 1
fill ~32~23~29 ~32~23~31 minecraft:stained_glass 5
setblock ~33~10~29 minecraft:wool 15
fill ~33~16~29 ~34~16~29 minecraft:obsidian
setblock ~33~17~29 minecraft:stone_brick_stairs 1
setblock ~34~10~29 minecraft:obsidian
setblock ~34~12~29 minecraft:wool 15
fill ~34~13~29 ~34~15~29 minecraft:obsidian
fill ~35~4~29 ~35~4~31 minecraft:web
fill ~35~10~29 ~35~10~30 minecraft:wool 15
setblock ~35~11~29 minecraft:wool 15
fill ~35~16~29 ~35~16~30 minecraft:stained_glass 15
fill ~35~22~29 ~36~22~29 minecraft:obsidian
setblock ~37~11~29 minecraft:obsidian
setblock ~37~12~29 minecraft:carpet 11
fill ~37~22~29 ~37~22~33 minecraft:wool 15
fill ~38~11~29 ~38~11~30 minecraft:wool 15
fill ~39~11~29 ~40~11~29 minecraft:obsidian
setblock ~39~22~29 minecraft:obsidian
setblock ~40~22~29 minecraft:wool 15
setblock ~41~12~29 minecraft:obsidian
fill ~41~22~29 ~41~22~31 minecraft:stained_hardened_clay 13
fill ~42~21~29 ~43~21~31 minecraft:wool 15
setblock ~43~12~29 minecraft:wool 15
setblock ~43~13~29 minecraft:quartz_stairs 4
fill ~44~13~29 ~45~13~29 minecraft:quartz_stairs 5
fill ~45~12~29 ~45~12~30 minecraft:wool 15
setblock ~46~12~29 minecraft:obsidian
setblock ~47~12~29 minecraft:wool 15
setblock ~47~21~29 minecraft:wool 15
fill ~48~12~29 ~51~12~29 minecraft:stained_hardened_clay 13
setblock ~49~13~29 minecraft:wool 15
fill ~49~20~29 ~50~20~29 minecraft:wool 15
setblock ~50~13~29 minecraft:obsidian
fill ~52~13~29 ~52~13~30 minecraft:obsidian
setblock ~52~14~29 minecraft:dark_oak_fence_gate 3
setblock ~52~21~29 minecraft:stained_hardened_clay 13
fill ~53~15~29 ~53~15~31 minecraft:jungle_fence_gate 3
fill ~53~16~29 ~53~16~31 minecraft:jungle_fence_gate 0
fill ~53~19~29 ~53~19~31 minecraft:obsidian
setblock ~54~13~29 minecraft:stained_hardened_clay 13
setblock ~54~19~29 minecraft:wool 15
setblock ~55~14~29 minecraft:stained_hardened_clay 13
setblock ~55~18~29 minecraft:wool 15
setblock ~56~18~29 minecraft:obsidian
setblock ~56~19~29 minecraft:stained_hardened_clay 13
setblock ~1~15~30 minecraft:stained_hardened_clay 13
setblock ~1~18~30 minecraft:stained_hardened_clay 13
setblock ~2~14~30 minecraft:stained_hardened_clay 13
fill ~2~18~30 ~2~18~35 minecraft:obsidian
setblock ~3~15~30 minecraft:dispenser 3
setblock ~3~16~30 minecraft:hopper 0
setblock ~3~18~30 minecraft:wool 15
setblock ~4~16~30 minecraft:hopper 4
setblock ~4~17~30 minecraft:chest 3
setblock ~4~18~30 minecraft:torch 1
fill ~4~19~30 ~5~19~30 minecraft:wool 15
fill ~5~14~30 ~5~14~32 minecraft:wool 15
setblock ~5~15~30 minecraft:trapped_chest 5
setblock ~5~17~30 minecraft:wall_sign 5
setblock ~6~14~30 minecraft:ender_chest 5
setblock ~6~20~30 minecraft:obsidian
fill ~7~13~30 ~7~13~31 minecraft:obsidian
setblock ~7~20~30 minecraft:wool 15
fill ~8~20~30 ~9~20~31 minecraft:obsidian
setblock ~9~13~30 minecraft:obsidian
fill ~10~12~30 ~10~12~31 minecraft:stained_hardened_clay 13
setblock ~11~12~30 minecraft:wool 15
setblock ~11~20~30 minecraft:glowstone
fill ~11~21~30 ~12~21~30 minecraft:wool 15
fill ~12~12~30 ~12~12~31 minecraft:obsidian
fill ~13~12~30 ~14~12~30 minecraft:wool 15
setblock ~13~21~30 minecraft:obsidian
setblock ~14~21~30 minecraft:wool 15
setblock ~17~12~30 minecraft:obsidian
setblock ~17~21~30 minecraft:wool 15
setblock ~19~22~30 minecraft:obsidian
fill ~20~11~30 ~20~11~31 minecraft:obsidian
setblock ~20~12~30 minecraft:carpet 11
setblock ~20~22~30 minecraft:wool 15
fill ~21~11~30 ~22~11~31 minecraft:wool 15
setblock ~22~12~30 minecraft:carpet 11
setblock ~22~22~30 minecraft:wool 15
fill ~23~8~30 ~26~8~30 minecraft:obsidian
setblock ~23~9~30 minecraft:wool 15
fill ~23~11~30 ~24~11~31 minecraft:obsidian
setblock ~23~12~30 minecraft:light_weighted_pressure_plate 0
fill ~23~16~30 ~23~16~31 minecraft:stained_glass 15
fill ~24~10~30 ~24~10~31 minecraft:wool 15
setblock ~24~12~30 minecraft:iron_door 2
fill ~24~14~30 ~24~16~31 minecraft:obsidian
setblock ~25~10~30 minecraft:obsidian
setblock ~25~12~30 minecraft:light_weighted_pressure_plate 0
fill ~25~22~30 ~25~22~31 minecraft:wool 15
fill ~26~9~30 ~26~9~31 minecraft:wool 15
setblock ~26~10~30 minecraft:redstone_block
fill ~26~11~30 ~26~11~31 minecraft:wool 15
fill ~26~17~30 ~27~17~30 minecraft:stained_glass 15
setblock ~26~22~30 minecraft:obsidian
setblock ~26~24~30 minecraft:stained_glass 5
fill ~27~5~30 ~27~6~30 minecraft:wool 15
setblock ~27~8~30 minecraft:wool 15
setblock ~27~11~30 minecraft:obsidian
setblock ~27~18~30 minecraft:stained_glass 15
setblock ~27~19~30 minecraft:wool 15
setblock ~27~20~30 minecraft:obsidian
fill ~27~21~30 ~27~23~30 minecraft:wool 15
setblock ~27~24~30 minecraft:obsidian
setblock ~27~25~30 minecraft:stained_glass 5
fill ~28~7~30 ~28~7~31 minecraft:wool 15
fill ~28~8~30 ~28~8~31 minecraft:quartz_block 1
setblock ~28~19~30 minecraft:obsidian
fill ~28~22~30 ~28~22~32 minecraft:wool 15
setblock ~28~23~30 minecraft:glowstone
setblock ~28~24~30 minecraft:wool 15
setblock ~29~16~30 minecraft:beacon
setblock ~29~18~30 minecraft:stained_hardened_clay 4
setblock ~29~23~30 minecraft:wall_sign 2
setblock ~30~7~30 minecraft:wool 15
fill ~30~8~30 ~30~8~31 minecraft:quartz_block 1
fill ~30~19~30 ~30~19~31 minecraft:obsidian
setblock ~30~22~30 minecraft:wool 15
setblock ~30~23~30 minecraft:glowstone
fill ~30~24~30 ~31~24~30 minecraft:obsidian
setblock ~31~5~30 minecraft:obsidian
setblock ~31~6~30 minecraft:wool 15
setblock ~31~11~30 minecraft:wool 15
fill ~31~17~30 ~32~17~30 minecraft:stained_glass 15
setblock ~31~18~30 minecraft:stained_glass 5
fill ~31~19~30 ~31~20~30 minecraft:wool 15
fill ~31~21~30 ~31~23~30 minecraft:obsidian
setblock ~31~25~30 minecraft:stained_glass 5
fill ~32~8~30 ~33~8~30 minecraft:wool 15
setblock ~32~9~30 minecraft:wool 15
setblock ~32~10~30 minecraft:redstone_block
fill ~32~22~30 ~33~22~30 minecraft:wool 15
setblock ~32~24~30 minecraft:stained_glass 5
setblock ~33~10~30 minecraft:obsidian
setblock ~33~12~30 minecraft:light_weighted_pressure_plate 0
setblock ~34~8~30 minecraft:obsidian
fill ~34~10~30 ~34~10~31 minecraft:wool 15
fill ~34~11~30 ~35~11~30 minecraft:obsidian
setblock ~34~12~30 minecraft:iron_door 0
fill ~34~14~30 ~34~15~31 minecraft:obsidian
fill ~34~16~30 ~34~16~31 minecraft:wool 15
fill ~34~22~30 ~34~22~31 minecraft:obsidian
fill ~35~8~30 ~35~9~30 minecraft:wool 15
setblock ~35~12~30 minecraft:light_weighted_pressure_plate 0
fill ~35~22~30 ~35~22~35 minecraft:wool 15
setblock ~36~12~30 minecraft:carpet 11
setblock ~36~22~30 minecraft:obsidian
setblock ~37~11~30 minecraft:wool 15
fill ~39~11~30 ~39~11~33 minecraft:wool 15
fill ~39~22~30 ~39~22~35 minecraft:wool 15
setblock ~40~11~30 minecraft:obsidian
fill ~40~22~30 ~40~22~32 minecraft:obsidian
fill ~41~12~30 ~41~12~32 minecraft:wool 15
fill ~41~21~30 ~41~21~33 minecraft:wool 15
fill ~42~12~30 ~44~12~30 minecraft:obsidian
setblock ~42~13~30 minecraft:stone_button 4
setblock ~43~13~30 minecraft:quartz_block 1
setblock ~44~13~30 minecraft:quartz_stairs 4
setblock ~44~14~30 minecraft:beacon
setblock ~45~13~30 minecraft:quartz_block 1
fill ~45~21~30 ~47~21~31 minecraft:obsidian
setblock ~46~12~30 minecraft:wool 15
setblock ~46~13~30 minecraft:stone_button 5
setblock ~47~12~30 minecraft:obsidian
setblock ~47~20~30 minecraft:glowstone
fill ~48~12~30 ~48~12~31 minecraft:stained_hardened_clay 13
setblock ~48~13~30 minecraft:wool 15
setblock ~48~20~30 minecraft:wool 15
fill ~49~13~30 ~49~13~32 minecraft:obsidian
fill ~49~20~30 ~49~20~33 minecraft:obsidian
fill ~50~13~30 ~50~13~32 minecraft:wool 15
fill ~50~20~30 ~51~20~30 minecraft:wool 15
setblock ~52~14~30 minecraft:daylight_detector_inverted 8
setblock ~52~15~30 minecraft:daylight_detector_inverted 7
setblock ~52~20~30 minecraft:obsidian
fill ~54~19~30 ~54~19~31 minecraft:obsidian
fill ~55~15~30 ~55~15~31 minecraft:obsidian
fill ~55~18~30 ~55~18~31 minecraft:obsidian
setblock ~56~14~30 minecraft:stained_hardened_clay 13
fill ~56~15~30 ~56~15~32 minecraft:wool 15
fill ~56~18~30 ~56~18~31 minecraft:wool 15
setblock ~57~15~30 minecraft:stained_hardened_clay 13
setblock ~57~18~30 minecraft:stained_hardened_clay 13
fill ~2~15~31 ~3~15~31 minecraft:obsidian
setblock ~2~19~31 minecraft:stained_hardened_clay 13
setblock ~3~14~31 minecraft:stained_hardened_clay 13
fill ~3~18~31 ~3~18~34 minecraft:obsidian
fill ~4~13~31 ~4~13~32 minecraft:stained_hardened_clay 13
fill ~4~16~31 ~4~16~32 minecraft:chest 5
fill ~4~17~31 ~4~17~32 minecraft:trapped_chest 5
fill ~4~19~31 ~5~19~31 minecraft:obsidian
setblock ~6~20~31 minecraft:wool 15
fill ~6~21~31 ~6~21~32 minecraft:stained_hardened_clay 13
fill ~7~12~31 ~9~12~31 minecraft:stained_hardened_clay 13
fill ~7~20~31 ~7~20~35 minecraft:obsidian
setblock ~9~13~31 minecraft:wool 15
setblock ~10~20~31 minecraft:wool 15
fill ~11~12~31 ~11~12~32 minecraft:obsidian
setblock ~11~21~31 minecraft:wool 15
fill ~12~21~31 ~12~21~32 minecraft:obsidian
fill ~13~12~31 ~13~12~34 minecraft:wool 15
setblock ~13~21~31 minecraft:wool 15
fill ~14~12~31 ~14~12~33 minecraft:obsidian
fill ~14~21~31 ~14~21~32 minecraft:obsidian
fill ~16~12~31 ~17~12~32 minecraft:wool 15
fill ~16~21~31 ~17~21~32 minecraft:obsidian
fill ~18~22~31 ~18~22~32 minecraft:obsidian
fill ~19~22~31 ~19~22~34 minecraft:wool 15
fill ~20~22~31 ~23~22~31 minecraft:obsidian
setblock ~21~12~31 minecraft:carpet 11
fill ~24~12~31 ~24~13~31 minecraft:obsidian
fill ~24~22~31 ~24~22~33 minecraft:wool 15
setblock ~25~10~31 minecraft:wool 15
fill ~25~12~31 ~25~12~33 minecraft:wool 15
setblock ~25~16~31 minecraft:obsidian
setblock ~25~17~31 minecraft:stone_brick_stairs 0
setblock ~26~10~31 minecraft:lit_redstone_lamp
setblock ~26~12~31 minecraft:stained_glass 15
fill ~26~16~31 ~26~16~33 minecraft:stained_glass 15
setblock ~26~17~31 minecraft:wool 15
setblock ~26~18~31 minecraft:stone_brick_stairs 0
fill ~26~22~31 ~27~22~31 minecraft:wool 15
setblock ~27~4~31 minecraft:obsidian
setblock ~27~5~31 minecraft:stained_glass 5
setblock ~27~7~31 minecraft:redstone_block
setblock ~27~8~31 minecraft:obsidian
setblock ~27~11~31 minecraft:wool 15
setblock ~27~18~31 minecraft:wool 15
setblock ~27~19~31 minecraft:stone_brick_stairs 0
setblock ~27~23~31 minecraft:obsidian
setblock ~27~24~31 minecraft:stained_glass 5
setblock ~28~3~31 minecraft:stained_glass 5
setblock ~28~6~31 minecraft:obsidian
setblock ~28~18~31 minecraft:glowstone
fill ~28~19~31 ~29~19~31 minecraft:wool 15
fill ~28~23~31 ~28~23~32 minecraft:wool 15
fill ~28~24~31 ~29~24~31 minecraft:obsidian
fill ~29~7~31 ~30~7~31 minecraft:obsidian
setblock ~29~8~31 minecraft:quartz_block 1
fill ~29~22~31 ~30~22~31 minecraft:obsidian
setblock ~29~23~31 minecraft:glowstone
fill ~29~25~31 ~29~25~32 minecraft:stained_glass 5
setblock ~30~3~31 minecraft:stained_glass 5
setblock ~30~6~31 minecraft:wool 15
setblock ~30~18~31 minecraft:glowstone
setblock ~30~23~31 minecraft:obsidian
setblock ~30~24~31 minecraft:wool 15
setblock ~31~4~31 minecraft:wool 15
setblock ~31~5~31 minecraft:stained_glass 5
setblock ~31~7~31 minecraft:redstone_block
setblock ~31~11~31 minecraft:obsidian
setblock ~31~18~31 minecraft:wool 15
setblock ~31~19~31 minecraft:stone_brick_stairs 1
fill ~31~22~31 ~32~22~31 minecraft:wool 15
setblock ~31~23~31 minecraft:wool 15
setblock ~31~24~31 minecraft:stained_glass 5
fill ~32~9~31 ~32~9~32 minecraft:obsidian
setblock ~32~10~31 minecraft:lit_redstone_lamp
setblock ~32~12~31 minecraft:stained_glass 5
setblock ~32~17~31 minecraft:obsidian
setblock ~32~18~31 minecraft:stone_brick_stairs 1
setblock ~33~10~31 minecraft:wool 15
fill ~33~12~31 ~34~12~31 minecraft:obsidian
setblock ~33~16~31 minecraft:obsidian
setblock ~33~17~31 minecraft:stone_brick_stairs 1
setblock ~33~22~31 minecraft:obsidian
fill ~34~11~31 ~34~11~33 minecraft:obsidian
setblock ~34~13~31 minecraft:obsidian
setblock ~35~10~31 minecraft:obsidian
setblock ~35~11~31 minecraft:wool 15
setblock ~35~16~31 minecraft:stained_glass 5
fill ~36~22~31 ~36~22~32 minecraft:wool 15
fill ~37~11~31 ~38~11~31 minecraft:obsidian
setblock ~37~12~31 minecraft:carpet 11
setblock ~40~11~31 minecraft:wool 15
fill ~42~12~31 ~44~12~31 minecraft:wool 15
fill ~43~13~31 ~43~13~32 minecraft:quartz_stairs 4
fill ~44~13~31 ~44~13~32 minecraft:quartz_stairs 7
fill ~45~12~31 ~46~12~31 minecraft:obsidian
fill ~45~13~31 ~45~13~32 minecraft:quartz_stairs 5
setblock ~47~12~31 minecraft:wool 15
fill ~48~13~31 ~48~13~32 minecraft:obsidian
setblock ~48~20~31 minecraft:obsidian
fill ~49~12~31 ~51~12~31 minecraft:stained_hardened_clay 13
fill ~50~20~31 ~51~20~31 minecraft:obsidian
fill ~52~13~31 ~52~13~32 minecraft:wool 15
setblock ~52~14~31 minecraft:dark_oak_fence_gate 3
fill ~52~20~31 ~52~20~32 minecraft:wool 15
fill ~52~21~31 ~52~21~32 minecraft:stained_hardened_clay 13
fill ~54~13~31 ~54~13~32 minecraft:stained_hardened_clay 13
setblock ~55~14~31 minecraft:stained_hardened_clay 13
setblock ~56~19~31 minecraft:stained_hardened_clay 13
setblock ~2~15~32 minecraft:wool 15
setblock ~3~15~32 minecraft:obsidian
setblock ~3~19~32 minecraft:stained_hardened_clay 13
fill ~4~19~32 ~4~19~33 minecraft:obsidian
setblock ~4~20~32 minecraft:stained_hardened_clay 13
setblock ~5~13~32 minecraft:stained_hardened_clay 13
setblock ~5~15~32 minecraft:chest 5
fill ~5~16~32 ~5~17~32 minecraft:wall_sign 5
fill ~5~19~32 ~5~19~33 minecraft:wool 15
setblock ~5~20~32 minecraft:glowstone
setblock ~5~21~32 minecraft:stained_hardened_clay 13
setblock ~6~12~32 minecraft:stained_hardened_clay 13
fill ~6~13~32 ~7~13~32 minecraft:wool 15
setblock ~6~15~32 minecraft:wall_sign 5
setblock ~6~20~32 minecraft:obsidian
fill ~7~21~32 ~8~21~32 minecraft:stained_hardened_clay 13
fill ~8~20~32 ~9~20~32 minecraft:wool 15
fill ~9~13~32 ~9~13~35 minecraft:obsidian
setblock ~10~12~32 minecraft:glowstone
setblock ~10~20~32 minecraft:obsidian
setblock ~11~21~32 minecraft:obsidian
setblock ~12~12~32 minecraft:wool 15
fill ~13~21~32 ~13~21~34 minecraft:obsidian
setblock ~15~12~32 minecraft:obsidian
fill ~15~22~32 ~16~22~32 minecraft:stained_hardened_clay 13
setblock ~17~22~32 minecraft:glowstone
setblock ~18~11~32 minecraft:obsidian
fill ~19~11~32 ~20~11~32 minecraft:wool 15
setblock ~20~22~32 minecraft:wool 15
setblock ~21~11~32 minecraft:obsidian
fill ~21~22~32 ~22~22~33 minecraft:obsidian
fill ~22~5~32 ~22~6~32 minecraft:obsidian
setblock ~22~7~32 minecraft:wool 15
fill ~22~8~32 ~23~8~32 minecraft:obsidian
fill ~22~11~32 ~23~11~33 minecraft:wool 15
setblock ~22~12~32 minecraft:end_portal_frame 1
setblock ~23~4~32 minecraft:wool 15
setblock ~23~9~32 minecraft:wool 15
setblock ~23~12~32 minecraft:stained_glass 5
fill ~23~13~32 ~23~15~32 minecraft:stained_glass 15
fill ~23~22~32 ~23~22~34 minecraft:wool 15
setblock ~24~9~32 minecraft:obsidian
setblock ~24~11~32 minecraft:obsidian
fill ~24~12~32 ~24~15~32 minecraft:glowstone
setblock ~24~16~32 minecraft:stone_brick_stairs 3
setblock ~25~9~32 minecraft:wool 15
fill ~25~15~32 ~26~15~32 minecraft:stained_glass 5
setblock ~25~16~32 minecraft:stained_glass 15
fill ~25~22~32 ~25~22~33 minecraft:obsidian
fill ~26~9~32 ~27~9~32 minecraft:obsidian
setblock ~26~10~32 minecraft:wool 15
fill ~26~11~32 ~27~11~33 minecraft:obsidian
fill ~26~12~32 ~26~12~34 minecraft:wool 15
fill ~26~13~32 ~26~14~32 minecraft:stained_glass 5
fill ~26~17~32 ~26~18~32 minecraft:stained_glass 15
fill ~26~22~32 ~26~22~33 minecraft:wool 15
fill ~27~22~32 ~27~22~34 minecraft:obsidian
setblock ~27~23~32 minecraft:stained_glass 5
setblock ~28~3~32 minecraft:obsidian
fill ~28~4~32 ~29~4~32 minecraft:wool 15
setblock ~28~5~32 minecraft:stained_glass 5
setblock ~28~7~32 minecraft:redstone_block
fill ~28~8~32 ~30~8~32 minecraft:wool 15
fill ~28~11~32 ~28~11~35 minecraft:wool 15
setblock ~28~18~32 minecraft:obsidian
setblock ~28~19~32 minecraft:stone_brick_stairs 3
setblock ~28~24~32 minecraft:stained_glass 5
setblock ~29~3~32 minecraft:wool 15
setblock ~29~5~32 minecraft:obsidian
setblock ~29~6~32 minecraft:wool 15
fill ~29~11~32 ~30~11~32 minecraft:obsidian
fill ~29~17~32 ~29~17~33 minecraft:stained_glass 5
setblock ~29~18~32 minecraft:stained_glass 5
fill ~29~19~32 ~29~20~32 minecraft:wool 15
setblock ~29~21~32 minecraft:obsidian
fill ~29~22~32 ~31~22~32 minecraft:wool 15
fill ~29~23~32 ~30~23~32 minecraft:wool 15
setblock ~29~24~32 minecraft:obsidian
fill ~30~3~32 ~30~4~32 minecraft:obsidian
setblock ~30~5~32 minecraft:stained_glass 5
setblock ~30~7~32 minecraft:redstone_block
setblock ~30~18~32 minecraft:wool 15
setblock ~30~19~32 minecraft:stone_brick_stairs 3
setblock ~30~24~32 minecraft:stained_glass 5
setblock ~31~9~32 minecraft:obsidian
setblock ~31~11~32 minecraft:wool 15
setblock ~31~23~32 minecraft:stained_glass 5
fill ~32~10~32 ~32~12~32 minecraft:obsidian
setblock ~32~13~32 minecraft:stained_glass 15
fill ~32~14~32 ~32~15~32 minecraft:stained_glass 5
fill ~32~17~32 ~32~18~32 minecraft:stained_glass 5
setblock ~32~22~32 minecraft:obsidian
fill ~33~9~32 ~34~9~32 minecraft:obsidian
fill ~33~11~32 ~33~12~32 minecraft:wool 15
fill ~33~15~32 ~33~15~33 minecraft:stained_glass 15
setblock ~33~16~32 minecraft:stained_glass 15
fill ~33~22~32 ~34~22~32 minecraft:wool 15
fill ~34~12~32 ~34~15~32 minecraft:glowstone
setblock ~34~16~32 minecraft:stone_brick_stairs 3
setblock ~35~4~32 minecraft:wool 15
fill ~35~8~32 ~35~9~32 minecraft:wool 15
fill ~35~11~32 ~36~11~32 minecraft:obsidian
setblock ~35~12~32 minecraft:stained_glass 15
setblock ~35~13~32 minecraft:stained_glass 5
fill ~35~14~32 ~35~14~33 minecraft:stained_glass 15
setblock ~35~15~32 minecraft:stained_glass 15
fill ~36~5~32 ~36~6~32 minecraft:wool 15
fill ~36~7~32 ~36~8~32 minecraft:obsidian
setblock ~36~12~32 minecraft:end_portal_frame 3
fill ~37~11~32 ~38~11~32 minecraft:wool 15
setblock ~38~12~32 minecraft:carpet 11
fill ~38~22~32 ~38~22~34 minecraft:obsidian
setblock ~40~11~32 minecraft:obsidian
setblock ~41~22~32 minecraft:glowstone
setblock ~42~12~32 minecraft:obsidian
fill ~42~21~32 ~42~21~33 minecraft:wool 15
fill ~42~22~32 ~43~22~32 minecraft:stained_hardened_clay 13
fill ~43~12~32 ~46~12~32 minecraft:wool 15
setblock ~43~21~32 minecraft:obsidian
fill ~45~21~32 ~45~21~33 minecraft:wool 15
fill ~46~21~32 ~47~21~32 minecraft:obsidian
setblock ~47~12~32 minecraft:obsidian
setblock ~48~12~32 minecraft:glowstone
setblock ~48~20~32 minecraft:wool 15
setblock ~50~20~32 minecraft:obsidian
fill ~50~21~32 ~51~21~32 minecraft:stained_hardened_clay 13
setblock ~51~20~32 minecraft:wool 15
setblock ~52~12~32 minecraft:stained_hardened_clay 13
setblock ~52~14~32 minecraft:slime
setblock ~53~13~32 minecraft:stained_hardened_clay 13
fill ~53~19~32 ~54~19~33 minecraft:wool 15
setblock ~53~20~32 minecraft:glowstone
setblock ~53~21~32 minecraft:stained_hardened_clay 13
fill ~54~14~32 ~54~14~33 minecraft:wool 15
setblock ~54~20~32 minecraft:stained_hardened_clay 13
setblock ~55~15~32 minecraft:wool 15
setblock ~55~18~32 minecraft:wool 15
setblock ~55~19~32 minecraft:stained_hardened_clay 13
setblock ~56~18~32 minecraft:obsidian
setblock ~2~15~33 minecraft:obsidian
fill ~2~16~33 ~2~16~34 minecraft:chest 5
fill ~3~15~33 ~3~15~34 minecraft:wool 15
fill ~4~14~33 ~6~14~33 minecraft:obsidian
setblock ~6~19~33 minecraft:wool 15
fill ~7~12~33 ~10~12~33 minecraft:stained_hardened_clay 13
fill ~7~13~33 ~7~13~34 minecraft:wool 15
setblock ~8~20~33 minecraft:obsidian
setblock ~8~21~33 minecraft:stained_hardened_clay 13
fill ~9~20~33 ~10~20~33 minecraft:wool 15
setblock ~10~13~33 minecraft:obsidian
setblock ~11~11~33 minecraft:stained_hardened_clay 13
fill ~11~12~33 ~11~12~35 minecraft:wool 15
fill ~11~13~33 ~11~13~34 minecraft:furnace 5
fill ~11~21~33 ~12~21~33 minecraft:wool 15
fill ~12~12~33 ~12~12~34 minecraft:obsidian
setblock ~14~13~33 minecraft:double_stone_block_slab2 0
fill ~14~21~33 ~14~21~34 minecraft:wool 15
fill ~14~22~33 ~14~22~34 minecraft:stained_hardened_clay 13
setblock ~15~12~33 minecraft:wool 15
setblock ~15~13~33 minecraft:anvil 0
fill ~16~12~33 ~18~12~33 minecraft:obsidian
fill ~16~21~33 ~16~21~34 minecraft:wool 15
fill ~17~21~33 ~17~21~35 minecraft:obsidian
setblock ~18~21~33 minecraft:wool 15
fill ~19~11~33 ~19~11~35 minecraft:obsidian
fill ~20~11~33 ~21~11~33 minecraft:wool 15
fill ~20~22~33 ~20~22~35 minecraft:obsidian
setblock ~23~14~33 minecraft:stained_glass 15
setblock ~24~4~33 minecraft:web
fill ~24~11~33 ~25~11~33 minecraft:wool 15
setblock ~24~14~33 minecraft:glowstone
setblock ~24~15~33 minecraft:stone_brick_stairs 3
fill ~25~15~33 ~27~15~33 minecraft:stained_glass 15
fill ~27~9~33 ~27~9~35 minecraft:obsidian
setblock ~27~10~33 minecraft:obsidian
fill ~27~12~33 ~27~12~34 minecraft:obsidian
fill ~27~13~33 ~27~14~33 minecraft:stained_glass 5
fill ~27~16~33 ~28~16~33 minecraft:stained_glass 15
setblock ~27~17~33 minecraft:stained_glass 5
setblock ~27~18~33 minecraft:stained_glass 15
setblock ~28~9~33 minecraft:wool 15
setblock ~28~10~33 minecraft:lit_redstone_lamp
setblock ~28~12~33 minecraft:stained_glass 5
setblock ~28~17~33 minecraft:obsidian
setblock ~28~18~33 minecraft:stone_brick_stairs 3
fill ~28~22~33 ~31~22~33 minecraft:obsidian
fill ~28~23~33 ~30~23~33 minecraft:stained_glass 5
fill ~29~8~33 ~29~9~33 minecraft:obsidian
setblock ~29~10~33 minecraft:redstone_block
fill ~29~11~33 ~30~11~33 minecraft:wool 15
fill ~29~16~33 ~31~16~33 minecraft:stained_glass 5
setblock ~29~24~33 minecraft:stained_glass 5
setblock ~30~9~33 minecraft:obsidian
setblock ~30~10~33 minecraft:lit_redstone_lamp
setblock ~30~12~33 minecraft:stained_glass 15
setblock ~30~17~33 minecraft:obsidian
setblock ~30~18~33 minecraft:stone_brick_stairs 3
fill ~31~9~33 ~31~10~33 minecraft:wool 15
fill ~31~11~33 ~31~11~34 minecraft:obsidian
fill ~31~12~33 ~33~12~33 minecraft:wool 15
fill ~31~13~33 ~31~14~33 minecraft:stained_glass 15
fill ~31~15~33 ~32~15~33 minecraft:stained_glass 5
fill ~31~17~33 ~31~18~33 minecraft:stained_glass 15
fill ~32~11~33 ~32~11~35 minecraft:wool 15
fill ~32~22~33 ~33~22~33 minecraft:wool 15
fill ~33~11~33 ~33~11~34 minecraft:obsidian
setblock ~34~4~33 minecraft:web
setblock ~34~14~33 minecraft:glowstone
setblock ~34~15~33 minecraft:stone_brick_stairs 3
fill ~34~22~33 ~34~22~34 minecraft:obsidian
fill ~35~11~33 ~35~11~34 minecraft:obsidian
fill ~36~11~33 ~37~11~33 minecraft:wool 15
fill ~36~22~33 ~36~22~36 minecraft:obsidian
setblock ~37~12~33 minecraft:carpet 11
setblock ~38~11~33 minecraft:obsidian
fill ~40~12~33 ~41~12~33 minecraft:obsidian
setblock ~40~21~33 minecraft:wool 15
fill ~42~12~33 ~45~12~33 minecraft:wool 15
setblock ~43~21~33 minecraft:wool 15
fill ~44~22~33 ~44~22~34 minecraft:stained_hardened_clay 13
fill ~46~12~33 ~46~12~34 minecraft:obsidian
setblock ~46~21~33 minecraft:obsidian
setblock ~47~11~33 minecraft:stained_hardened_clay 13
setblock ~47~12~33 minecraft:wool 15
fill ~47~13~33 ~47~13~35 minecraft:nether_brick_stairs 0
setblock ~47~21~33 minecraft:wool 15
fill ~48~12~33 ~51~12~33 minecraft:stained_hardened_clay 13
fill ~48~13~33 ~49~13~33 minecraft:wool 15
setblock ~48~20~33 minecraft:obsidian
fill ~50~13~33 ~50~13~36 minecraft:obsidian
setblock ~50~20~33 minecraft:wool 15
setblock ~50~21~33 minecraft:stained_hardened_clay 13
setblock ~51~13~33 minecraft:wool 15
fill ~51~20~33 ~51~20~37 minecraft:obsidian
setblock ~52~14~33 minecraft:wool 15
setblock ~52~19~33 minecraft:wool 15
fill ~55~15~33 ~56~15~33 minecraft:obsidian
fill ~55~18~33 ~55~18~36 minecraft:obsidian
fill ~56~18~33 ~56~18~35 minecraft:wool 15
setblock ~2~15~34 minecraft:wool 15
setblock ~3~16~34 minecraft:wall_sign 5
fill ~4~14~34 ~5~14~35 minecraft:wool 15
fill ~4~19~34 ~4~19~36 minecraft:wool 15
fill ~5~19~34 ~6~19~34 minecraft:obsidian
setblock ~6~14~34 minecraft:obsidian
setblock ~8~13~34 minecraft:wool 15
fill ~8~20~34 ~9~20~36 minecraft:wool 15
fill ~9~21~34 ~10~21~34 minecraft:stained_hardened_clay 13
fill ~10~13~34 ~10~13~37 minecraft:wool 15
fill ~10~20~34 ~10~20~36 minecraft:obsidian
fill ~11~21~34 ~12~21~35 minecraft:obsidian
fill ~11~22~34 ~13~22~34 minecraft:stained_hardened_clay 13
fill ~12~11~34 ~13~11~34 minecraft:stained_hardened_clay 13
fill ~14~12~34 ~14~12~35 minecraft:wool 15
fill ~15~12~34 ~16~12~34 minecraft:obsidian
setblock ~15~21~34 minecraft:obsidian
fill ~17~12~34 ~18~12~36 minecraft:wool 15
fill ~18~21~34 ~18~21~42 minecraft:obsidian
fill ~20~11~34 ~22~11~34 minecraft:obsidian
fill ~20~12~34 ~20~12~35 minecraft:carpet 11
setblock ~21~22~34 minecraft:wool 15
setblock ~22~22~34 minecraft:obsidian
fill ~23~11~34 ~23~11~36 minecraft:wool 15
fill ~24~11~34 ~26~11~34 minecraft:obsidian
setblock ~24~14~34 minecraft:stone_brick_stairs 3
setblock ~24~22~34 minecraft:obsidian
setblock ~25~4~34 minecraft:web
setblock ~25~14~34 minecraft:stained_glass 15
fill ~25~22~34 ~25~22~35 minecraft:wool 15
fill ~26~15~34 ~27~15~34 minecraft:stained_glass 15
setblock ~26~22~34 minecraft:obsidian
setblock ~27~11~34 minecraft:wool 15
setblock ~27~16~34 minecraft:stained_glass 15
fill ~28~10~34 ~30~10~34 minecraft:wool 15
setblock ~28~12~34 minecraft:obsidian
fill ~28~16~34 ~28~16~35 minecraft:obsidian
setblock ~28~17~34 minecraft:stone_brick_stairs 3
fill ~28~22~34 ~28~22~37 minecraft:obsidian
fill ~29~8~34 ~29~8~35 minecraft:wool 15
fill ~29~11~34 ~29~11~35 minecraft:obsidian
setblock ~29~12~34 minecraft:light_weighted_pressure_plate 0
fill ~29~22~34 ~32~22~34 minecraft:wool 15
fill ~30~11~34 ~30~12~34 minecraft:wool 15
fill ~30~16~34 ~30~16~35 minecraft:obsidian
setblock ~30~17~34 minecraft:stone_brick_stairs 3
fill ~31~9~34 ~31~9~36 minecraft:obsidian
setblock ~31~12~34 minecraft:obsidian
fill ~31~15~34 ~31~16~34 minecraft:stained_glass 5
setblock ~32~12~34 minecraft:wool 15
setblock ~32~15~34 minecraft:stained_glass 15
setblock ~33~4~34 minecraft:web
setblock ~33~14~34 minecraft:stained_glass 5
setblock ~33~22~34 minecraft:obsidian
fill ~34~11~34 ~34~11~37 minecraft:wool 15
setblock ~34~14~34 minecraft:stone_brick_stairs 3
setblock ~35~14~34 minecraft:stained_glass 5
setblock ~36~11~34 minecraft:obsidian
fill ~37~11~34 ~38~11~34 minecraft:wool 15
setblock ~37~22~34 minecraft:obsidian
fill ~38~12~34 ~38~12~35 minecraft:carpet 11
setblock ~39~11~34 minecraft:obsidian
fill ~40~12~34 ~41~12~34 minecraft:wool 15
fill ~40~21~34 ~43~21~34 minecraft:obsidian
fill ~42~12~34 ~43~12~34 minecraft:obsidian
fill ~44~12~34 ~45~12~34 minecraft:wool 15
setblock ~44~21~34 minecraft:wool 15
fill ~45~11~34 ~46~11~34 minecraft:stained_hardened_clay 13
setblock ~45~21~34 minecraft:obsidian
fill ~45~22~34 ~47~22~34 minecraft:stained_hardened_clay 13
fill ~46~21~34 ~46~21~37 minecraft:wool 15
fill ~47~12~34 ~47~12~35 minecraft:obsidian
setblock ~47~21~34 minecraft:obsidian
fill ~48~13~34 ~48~13~37 minecraft:obsidian
fill ~48~20~34 ~49~20~34 minecraft:wool 15
fill ~48~21~34 ~49~21~34 minecraft:stained_hardened_clay 13
setblock ~49~13~34 minecraft:wool 15
fill ~50~20~34 ~50~20~35 minecraft:obsidian
setblock ~51~13~34 minecraft:obsidian
setblock ~52~14~34 minecraft:obsidian
fill ~52~19~34 ~53~19~34 minecraft:obsidian
setblock ~53~15~34 minecraft:stone_block_slab2 0
fill ~53~16~34 ~53~17~34 minecraft:stone_block_slab2 0
setblock ~54~14~34 minecraft:obsidian
setblock ~54~19~34 minecraft:wool 15
fill ~55~15~34 ~56~15~34 minecraft:wool 15
fill ~2~15~35 ~3~15~35 minecraft:obsidian
fill ~2~16~35 ~2~17~35 minecraft:obsidian
fill ~3~18~35 ~3~18~36 minecraft:wool 15
setblock ~5~19~35 minecraft:wool 15
fill ~6~14~35 ~6~14~36 minecraft:wool 15
fill ~6~15~35 ~6~15~37 minecraft:flower_pot 0
setblock ~6~19~35 minecraft:obsidian
fill ~7~13~35 ~8~13~36 minecraft:obsidian
setblock ~10~21~35 minecraft:glowstone
setblock ~11~13~35 minecraft:glowstone
setblock ~12~12~35 minecraft:wool 15
fill ~13~12~35 ~13~12~36 minecraft:obsidian
fill ~13~13~35 ~16~13~35 minecraft:stone_block_slab 1
fill ~13~21~35 ~13~21~37 minecraft:wool 15
setblock ~14~11~35 minecraft:stained_hardened_clay 13
setblock ~14~21~35 minecraft:obsidian
fill ~15~12~35 ~16~12~36 minecraft:wool 15
setblock ~15~21~35 minecraft:wool 15
setblock ~16~21~35 minecraft:obsidian
setblock ~19~22~35 minecraft:obsidian
fill ~20~11~35 ~21~11~35 minecraft:wool 15
fill ~21~22~35 ~21~22~36 minecraft:obsidian
setblock ~22~11~35 minecraft:obsidian
setblock ~22~12~35 minecraft:stone_brick_stairs 0
setblock ~22~22~35 minecraft:wool 15
setblock ~23~12~35 minecraft:wool 15
setblock ~23~13~35 minecraft:stone_brick_stairs 0
fill ~23~22~35 ~23~22~38 minecraft:obsidian
setblock ~24~11~35 minecraft:obsidian
setblock ~24~12~35 minecraft:glowstone
setblock ~24~13~35 minecraft:obsidian
setblock ~24~22~35 minecraft:wool 15
fill ~25~11~35 ~26~11~35 minecraft:wool 15
setblock ~25~14~35 minecraft:stone_brick_stairs 0
setblock ~26~4~35 minecraft:web
fill ~26~14~35 ~27~14~35 minecraft:glowstone
setblock ~26~15~35 minecraft:stone_brick_stairs 0
fill ~26~22~35 ~27~22~35 minecraft:wool 15
fill ~27~11~35 ~27~11~38 minecraft:obsidian
fill ~27~12~35 ~27~13~35 minecraft:glowstone
setblock ~27~15~35 minecraft:glowstone
setblock ~27~16~35 minecraft:stone_brick_stairs 0
setblock ~28~10~35 minecraft:obsidian
setblock ~28~12~35 minecraft:wool 15
fill ~28~13~35 ~28~15~35 minecraft:obsidian
setblock ~29~10~35 minecraft:wool 15
setblock ~29~12~35 minecraft:iron_door 1
fill ~29~14~35 ~30~15~35 minecraft:obsidian
setblock ~29~16~35 minecraft:obsidian
setblock ~29~22~35 minecraft:obsidian
fill ~30~10~35 ~30~11~36 minecraft:obsidian
fill ~30~12~35 ~30~13~35 minecraft:obsidian
fill ~30~22~35 ~34~22~35 minecraft:wool 15
setblock ~31~11~35 minecraft:wool 15
fill ~31~12~35 ~31~15~35 minecraft:glowstone
setblock ~31~16~35 minecraft:stone_brick_stairs 1
setblock ~32~4~35 minecraft:web
setblock ~32~14~35 minecraft:glowstone
setblock ~32~15~35 minecraft:stone_brick_stairs 1
fill ~33~11~35 ~33~11~36 minecraft:wool 15
setblock ~33~14~35 minecraft:stone_brick_stairs 1
setblock ~34~12~35 minecraft:glowstone
setblock ~34~13~35 minecraft:obsidian
fill ~35~11~35 ~36~11~36 minecraft:wool 15
setblock ~35~12~35 minecraft:wool 15
setblock ~35~13~35 minecraft:stone_brick_stairs 1
setblock ~36~12~35 minecraft:stone_brick_stairs 1
fill ~37~11~35 ~37~11~36 minecraft:obsidian
fill ~37~22~35 ~38~22~35 minecraft:wool 15
fill ~38~11~35 ~39~11~35 minecraft:wool 15
fill ~40~12~35 ~40~12~36 minecraft:obsidian
setblock ~40~21~35 minecraft:wool 15
fill ~41~12~35 ~42~12~40 minecraft:wool 15
fill ~41~21~35 ~42~21~35 minecraft:obsidian
fill ~43~12~35 ~44~12~35 minecraft:obsidian
fill ~43~21~35 ~43~21~37 minecraft:wool 15
setblock ~44~11~35 minecraft:stained_hardened_clay 13
fill ~44~21~35 ~44~21~36 minecraft:obsidian
fill ~45~12~35 ~46~12~35 minecraft:wool 15
setblock ~45~21~35 minecraft:wool 15
setblock ~47~21~35 minecraft:wool 15
fill ~48~20~35 ~48~20~36 minecraft:wool 15
setblock ~48~21~35 minecraft:glowstone
fill ~49~13~35 ~49~13~36 minecraft:obsidian
setblock ~49~20~35 minecraft:obsidian
fill ~51~13~35 ~51~13~37 minecraft:wool 15
setblock ~52~14~35 minecraft:wool 15
fill ~52~19~35 ~53~19~35 minecraft:wool 15
setblock ~54~14~35 minecraft:wool 15
fill ~54~19~35 ~54~19~36 minecraft:obsidian
fill ~55~15~35 ~56~15~35 minecraft:obsidian
setblock ~56~16~35 minecraft:obsidian
setblock ~56~17~35 minecraft:wool 15
fill ~2~16~36 ~2~17~38 minecraft:stained_glass 5
fill ~3~15~36 ~3~15~37 minecraft:wool 15
setblock ~4~14~36 minecraft:wool 15
fill ~5~14~36 ~5~14~37 minecraft:obsidian
setblock ~5~19~36 minecraft:obsidian
fill ~6~19~36 ~6~19~39 minecraft:wool 15
fill ~7~20~36 ~7~20~37 minecraft:wool 15
setblock ~9~13~36 minecraft:wool 15
setblock ~11~13~36 minecraft:wool 15
setblock ~11~20~36 minecraft:wool 15
setblock ~12~12~36 minecraft:obsidian
fill ~12~13~36 ~12~13~38 minecraft:stone_block_slab 1
fill ~12~21~36 ~12~21~37 minecraft:wool 15
setblock ~13~13~36 minecraft:soul_sand
setblock ~13~14~36 minecraft:nether_wart 3
setblock ~14~12~36 minecraft:obsidian
fill ~14~13~36 ~15~13~36 minecraft:sand 0
fill ~14~14~36 ~14~16~36 minecraft:cactus 0
fill ~14~21~36 ~14~21~37 minecraft:wool 15
fill ~15~11~36 ~19~11~36 minecraft:stained_hardened_clay 13
fill ~15~14~36 ~15~16~36 minecraft:reeds 0
fill ~15~21~36 ~15~21~37 minecraft:obsidian
setblock ~16~13~36 minecraft:soul_sand
setblock ~16~14~36 minecraft:nether_wart 3
fill ~16~21~36 ~17~21~37 minecraft:wool 15
fill ~17~13~36 ~17~13~39 minecraft:stone_block_slab 1
