fill ~1 ~-3 ~0 ~1 ~-3 ~4 dirt 0  
fill ~1 ~-3 ~5 ~1 ~-3 ~5 stone 0  
fill ~1 ~-3 ~6 ~4 ~-3 ~6 stone 0  
fill ~1 ~-3 ~7 ~7 ~-3 ~7 stone 0  
fill ~1 ~-3 ~8 ~8 ~-3 ~8 stone 0  
fill ~1 ~-3 ~9 ~6 ~-3 ~9 stone 0  
fill ~1 ~-3 ~10 ~2 ~-3 ~10 dirt 0  
fill ~1 ~-3 ~11 ~3 ~-3 ~11 dirt 0  
fill ~1 ~-3 ~12 ~3 ~-3 ~12 dirt 0  
fill ~1 ~-3 ~13 ~1 ~-3 ~13 dirt 0  
fill ~1 ~-3 ~14 ~11 ~-3 ~14 stone 0  
fill ~1 ~-3 ~15 ~11 ~-3 ~15 stone 0  
fill ~1 ~-3 ~16 ~11 ~-3 ~16 stone 0  
fill ~1 ~-3 ~17 ~11 ~-3 ~17 stone 0  
fill ~1 ~-3 ~18 ~9 ~-3 ~18 stone 0  
fill ~1 ~-3 ~19 ~8 ~-3 ~19 stone 0  
fill ~1 ~-3 ~20 ~8 ~-3 ~20 stone 0  
fill ~1 ~-3 ~21 ~7 ~-3 ~21 stone 0  
fill ~1 ~-3 ~22 ~4 ~-3 ~22 stone 0  
fill ~1 ~-3 ~23 ~2 ~-3 ~23 stone 0  
fill ~1 ~-3 ~24 ~11 ~-3 ~24 dirt 0  
fill ~1 ~-3 ~25 ~12 ~-3 ~25 dirt 0  
fill ~1 ~-3 ~26 ~15 ~-3 ~26 dirt 0  
fill ~1 ~-3 ~27 ~38 ~-3 ~27 dirt 0  
fill ~1 ~-3 ~28 ~38 ~-3 ~28 dirt 0  
fill ~1 ~-3 ~29 ~39 ~-3 ~29 dirt 0  
fill ~1 ~-3 ~30 ~69 ~-3 ~30 dirt 0  
fill ~1 ~-3 ~31 ~18 ~-3 ~31 dirt 0  
fill ~1 ~-3 ~32 ~18 ~-3 ~32 dirt 0  
fill ~1 ~-3 ~33 ~18 ~-3 ~33 dirt 0  
fill ~1 ~-3 ~34 ~18 ~-3 ~34 dirt 0  
fill ~1 ~-3 ~35 ~18 ~-3 ~35 dirt 0  
fill ~1 ~-3 ~36 ~18 ~-3 ~36 dirt 0  
fill ~1 ~-3 ~37 ~17 ~-3 ~37 dirt 0  
fill ~1 ~-3 ~38 ~6 ~-3 ~38 dirt 0  
fill ~1 ~-3 ~39 ~5 ~-3 ~39 dirt 0  
fill ~1 ~-3 ~40 ~2 ~-3 ~40 stone 0  
fill ~1 ~-3 ~41 ~3 ~-3 ~41 stone 0  
fill ~1 ~-3 ~42 ~4 ~-3 ~42 stone 0  
fill ~1 ~-3 ~43 ~4 ~-3 ~43 stone 0  
fill ~1 ~-3 ~44 ~4 ~-3 ~44 stone 0  
fill ~1 ~-3 ~45 ~4 ~-3 ~45 stone 0  
fill ~1 ~-3 ~46 ~4 ~-3 ~46 stone 0  
fill ~1 ~-3 ~47 ~4 ~-3 ~47 stone 0  
fill ~1 ~-3 ~48 ~3 ~-3 ~48 stone 0  
fill ~1 ~-3 ~49 ~2 ~-3 ~49 stone 0  
fill ~1 ~-3 ~50 ~5 ~-3 ~50 dirt 0  
fill ~1 ~-3 ~51 ~5 ~-3 ~51 dirt 0  
fill ~1 ~-3 ~52 ~5 ~-3 ~52 dirt 0  
fill ~1 ~-3 ~53 ~5 ~-3 ~53 dirt 0  
fill ~1 ~-3 ~54 ~5 ~-3 ~54 dirt 0  
fill ~1 ~-3 ~55 ~5 ~-3 ~55 dirt 0  
fill ~1 ~-3 ~56 ~5 ~-3 ~56 dirt 0  
fill ~1 ~-3 ~57 ~5 ~-3 ~57 dirt 0  
fill ~1 ~-3 ~58 ~5 ~-3 ~58 dirt 0  
fill ~1 ~-3 ~59 ~5 ~-3 ~59 dirt 0  
fill ~1 ~-3 ~60 ~5 ~-3 ~60 dirt 0  
fill ~1 ~-3 ~61 ~4 ~-3 ~61 dirt 0  
fill ~1 ~-3 ~62 ~3 ~-3 ~62 dirt 0  
fill ~1 ~-3 ~63 ~2 ~-3 ~63 dirt 0  
fill ~1 ~-3 ~64 ~23 ~-3 ~64 stone 0  
fill ~1 ~-3 ~65 ~11 ~-3 ~65 dirt 0  
fill ~1 ~-3 ~66 ~11 ~-3 ~66 dirt 0  
fill ~1 ~-3 ~67 ~12 ~-3 ~67 dirt 0  
fill ~1 ~-3 ~68 ~14 ~-3 ~68 dirt 0  
fill ~2 ~-3 ~0 ~8 ~-3 ~0 stone 0  
fill ~2 ~-3 ~1 ~3 ~-3 ~1 dirt 0  
fill ~2 ~-3 ~2 ~4 ~-3 ~2 dirt 0  
fill ~2 ~-3 ~3 ~5 ~-3 ~3 dirt 0  
fill ~2 ~-3 ~4 ~69 ~-3 ~4 dirt 0  
fill ~2 ~-3 ~5 ~8 ~-3 ~5 dirt 0  
fill ~2 ~-3 ~13 ~11 ~-3 ~13 stone 0  
fill ~3 ~-3 ~10 ~9 ~-3 ~10 stone 0  
fill ~3 ~-3 ~23 ~10 ~-3 ~23 dirt 0  
fill ~3 ~-3 ~40 ~5 ~-3 ~40 dirt 0  
fill ~3 ~-3 ~49 ~5 ~-3 ~49 dirt 0  
fill ~3 ~-3 ~63 ~24 ~-3 ~63 stone 0  
fill ~4 ~-3 ~1 ~9 ~-3 ~1 stone 0  
fill ~4 ~-3 ~11 ~9 ~-3 ~11 stone 0  
fill ~4 ~-3 ~12 ~11 ~-3 ~12 stone 0  
fill ~4 ~-3 ~41 ~5 ~-3 ~41 dirt 0  
fill ~4 ~-3 ~48 ~5 ~-3 ~48 dirt 0  
fill ~4 ~-3 ~62 ~4 ~-3 ~62 stone 0  
fill ~5 ~-3 ~2 ~8 ~-3 ~2 stone 0  
fill ~5 ~-3 ~6 ~38 ~-3 ~6 dirt 0  
fill ~5 ~-3 ~22 ~10 ~-3 ~22 dirt 0  
fill ~5 ~-3 ~42 ~5 ~-2 ~42 dirt 0  
fill ~5 ~-3 ~43 ~5 ~-2 ~43 dirt 0  
fill ~5 ~-3 ~44 ~5 ~-2 ~44 dirt 0  
fill ~5 ~-3 ~45 ~5 ~-2 ~45 dirt 0  
fill ~5 ~-3 ~46 ~5 ~-2 ~46 dirt 0  
fill ~5 ~-3 ~47 ~5 ~-1 ~47 dirt 0  
fill ~5 ~-3 ~61 ~5 ~-3 ~61 stone 0  
fill ~5 ~-3 ~62 ~5 ~-1 ~62 dirt 0  
fill ~6 ~-3 ~3 ~7 ~-3 ~3 stone 0  
fill ~6 ~-3 ~39 ~6 ~-2 ~39 iron_block 0  
fill ~6 ~-3 ~40 ~6 ~-2 ~40 iron_block 0  
fill ~6 ~-3 ~41 ~6 ~-2 ~41 iron_block 0  
fill ~6 ~-3 ~42 ~6 ~-2 ~42 iron_block 0  
fill ~6 ~-3 ~43 ~6 ~-2 ~43 iron_block 0  
fill ~6 ~-3 ~44 ~6 ~-2 ~44 iron_block 0  
fill ~6 ~-3 ~45 ~6 ~-2 ~45 iron_block 0  
fill ~6 ~-3 ~46 ~6 ~-2 ~46 iron_block 0  
fill ~6 ~-3 ~47 ~6 ~-2 ~47 iron_block 0  
fill ~6 ~-3 ~48 ~6 ~-2 ~48 iron_block 0  
fill ~6 ~-3 ~49 ~6 ~-2 ~49 iron_block 0  
fill ~6 ~-3 ~50 ~6 ~-2 ~50 iron_block 0  
fill ~6 ~-3 ~51 ~6 ~-2 ~51 iron_block 0  
fill ~6 ~-3 ~52 ~6 ~-2 ~52 iron_block 0  
fill ~6 ~-3 ~53 ~6 ~-2 ~53 iron_block 0  
fill ~6 ~-3 ~54 ~6 ~-2 ~54 iron_block 0  
fill ~6 ~-3 ~55 ~6 ~-2 ~55 iron_block 0  
fill ~6 ~-3 ~56 ~6 ~-2 ~56 iron_block 0  
fill ~6 ~-3 ~57 ~6 ~-2 ~57 iron_block 0  
fill ~6 ~-3 ~58 ~6 ~-2 ~58 iron_block 0  
fill ~6 ~-3 ~59 ~6 ~-2 ~59 iron_block 0  
fill ~6 ~-3 ~60 ~6 ~-2 ~60 iron_block 0  
fill ~6 ~-3 ~61 ~6 ~-2 ~61 iron_block 0  
fill ~6 ~-3 ~62 ~6 ~-3 ~62 stone 0 
setblock ~7 ~-3 ~9 iron_ore 0  
fill ~7 ~-3 ~38 ~29 ~-3 ~38 iron_block 0  
fill ~7 ~-3 ~62 ~29 ~-3 ~62 iron_block 0  
fill ~8 ~-3 ~3 ~14 ~-3 ~3 dirt 0  
fill ~8 ~-3 ~7 ~19 ~-3 ~7 dirt 0  
fill ~8 ~-3 ~9 ~9 ~-3 ~9 stone 0  
fill ~8 ~-3 ~21 ~10 ~-3 ~21 dirt 0  
fill ~9 ~-3 ~0 ~15 ~-3 ~0 dirt 0  
fill ~9 ~-3 ~2 ~69 ~-3 ~2 dirt 0  
fill ~9 ~-3 ~5 ~9 ~-1 ~5 cobblestone 0  
fill ~9 ~-3 ~8 ~16 ~-3 ~8 dirt 0  
fill ~9 ~-3 ~19 ~10 ~-3 ~19 dirt 0  
fill ~9 ~-3 ~20 ~9 ~-2 ~20 dirt 0  
fill ~10 ~-3 ~1 ~69 ~-3 ~1 dirt 0  
fill ~10 ~-3 ~5 ~16 ~-3 ~5 dirt 0  
fill ~10 ~-3 ~9 ~15 ~-3 ~9 dirt 0  
fill ~10 ~-3 ~10 ~14 ~-3 ~10 dirt 0  
fill ~10 ~-3 ~11 ~14 ~-3 ~11 dirt 0  
fill ~10 ~-3 ~18 ~10 ~-2 ~18 dirt 0  
fill ~10 ~-3 ~20 ~22 ~-3 ~20 sand 0  
fill ~11 ~-3 ~18 ~23 ~-3 ~18 sand 0  
fill ~11 ~-3 ~19 ~21 ~-3 ~19 sand 0  
fill ~11 ~-3 ~21 ~21 ~-3 ~21 sand 0  
fill ~11 ~-3 ~22 ~21 ~-3 ~22 sand 0  
fill ~11 ~-3 ~23 ~21 ~-3 ~23 sand 0  
fill ~12 ~-3 ~12 ~14 ~-3 ~12 dirt 0  
fill ~12 ~-3 ~13 ~13 ~-3 ~13 dirt 0  
fill ~12 ~-3 ~14 ~14 ~-3 ~14 dirt 0  
fill ~12 ~-3 ~15 ~12 ~-2 ~15 dirt 0  
fill ~12 ~-3 ~16 ~25 ~-3 ~16 sand 0  
fill ~12 ~-3 ~17 ~17 ~-3 ~17 sand 0  
fill ~12 ~-3 ~24 ~20 ~-3 ~24 sand 0  
fill ~12 ~-3 ~65 ~23 ~-3 ~65 stone 0  
fill ~12 ~-3 ~66 ~26 ~-3 ~66 stone 0  
fill ~13 ~-3 ~15 ~25 ~-3 ~15 sand 0  
fill ~13 ~-3 ~25 ~19 ~-3 ~25 sand 0  
fill ~13 ~-3 ~49 ~13 ~4 ~49 iron_block 0  
fill ~13 ~-3 ~50 ~13 ~-2 ~50 glass_pane 0  
fill ~13 ~-3 ~51 ~13 ~4 ~51 iron_block 0  
fill ~13 ~-3 ~52 ~13 ~-2 ~52 glass_pane 0  
fill ~13 ~-3 ~53 ~23 ~-3 ~53 iron_block 0  
fill ~13 ~-3 ~54 ~14 ~-3 ~54 iron_block 0  
fill ~13 ~-3 ~55 ~23 ~-3 ~55 iron_block 0  
fill ~13 ~-3 ~67 ~25 ~-3 ~67 stone 0  
fill ~14 ~-3 ~13 ~26 ~-3 ~13 sand 0  
fill ~14 ~-3 ~49 ~14 ~3 ~49 glass_pane 0  
fill ~15 ~-3 ~10 ~25 ~-3 ~10 sand 0  
fill ~15 ~-3 ~11 ~25 ~-3 ~11 sand 0  
fill ~15 ~-3 ~12 ~25 ~-3 ~12 sand 0  
fill ~15 ~-3 ~14 ~25 ~-3 ~14 sand 0  
fill ~15 ~-3 ~49 ~15 ~4 ~49 iron_block 0  
fill ~15 ~-3 ~54 ~15 ~118 ~54 ladder 2  
fill ~15 ~-3 ~68 ~25 ~-3 ~68 stone 0  
fill ~16 ~-3 ~0 ~16 ~-3 ~0 stone 0  
fill ~16 ~-3 ~9 ~24 ~-3 ~9 sand 0  
fill ~16 ~-3 ~26 ~16 ~-2 ~26 sand 0  
fill ~16 ~-3 ~49 ~16 ~3 ~49 glass_pane 0  
fill ~16 ~-3 ~54 ~16 ~119 ~54 iron_block 0  
fill ~17 ~-3 ~0 ~30 ~-3 ~0 dirt 0  
fill ~17 ~-3 ~8 ~23 ~-3 ~8 sand 0  
fill ~17 ~-3 ~26 ~38 ~-3 ~26 dirt 0  
fill ~17 ~-3 ~49 ~19 ~-3 ~49 iron_block 0  
fill ~17 ~-3 ~54 ~17 ~118 ~54 ladder 2  
fill ~18 ~-3 ~3 ~20 ~-3 ~3 dirt 0  
fill ~18 ~-3 ~5 ~39 ~-3 ~5 dirt 0  
fill ~18 ~-3 ~37 ~21 ~-3 ~37 stone 0  
fill ~18 ~-3 ~54 ~18 ~119 ~54 iron_block 0  
fill ~19 ~-3 ~17 ~24 ~-3 ~17 sand 0  
fill ~19 ~-3 ~31 ~21 ~-3 ~31 stone 0  
fill ~19 ~-3 ~32 ~21 ~-3 ~32 stone 0  
fill ~19 ~-3 ~33 ~21 ~-3 ~33 stone 0  
fill ~19 ~-3 ~34 ~21 ~-3 ~34 stone 0  
fill ~19 ~-3 ~35 ~21 ~-3 ~35 stone 0  
fill ~19 ~-3 ~36 ~21 ~-3 ~36 stone 0  
fill ~19 ~-3 ~54 ~19 ~118 ~54 ladder 2  
fill ~20 ~-3 ~7 ~20 ~-2 ~7 sand 0  
fill ~20 ~-3 ~25 ~38 ~-3 ~25 dirt 0  
fill ~20 ~-3 ~49 ~20 ~3 ~49 glass_pane 0  
fill ~20 ~-3 ~54 ~20 ~119 ~54 iron_block 0  
fill ~21 ~-3 ~7 ~36 ~-3 ~7 dirt 0  
fill ~21 ~-3 ~24 ~38 ~-3 ~24 dirt 0  
fill ~21 ~-3 ~49 ~21 ~4 ~49 iron_block 0  
fill ~21 ~-3 ~54 ~21 ~118 ~54 ladder 2  
fill ~22 ~-3 ~19 ~38 ~-3 ~19 dirt 0  
fill ~22 ~-3 ~21 ~38 ~-3 ~21 dirt 0  
fill ~22 ~-3 ~22 ~38 ~-3 ~22 dirt 0  
fill ~22 ~-3 ~23 ~38 ~-3 ~23 dirt 0  
fill ~22 ~-3 ~31 ~69 ~-3 ~31 dirt 0  
fill ~22 ~-3 ~32 ~69 ~-3 ~32 dirt 0  
fill ~22 ~-3 ~33 ~69 ~-3 ~33 dirt 0  
fill ~22 ~-3 ~34 ~69 ~-3 ~34 dirt 0  
fill ~22 ~-3 ~35 ~69 ~-3 ~35 dirt 0  
fill ~22 ~-3 ~36 ~69 ~-3 ~36 dirt 0  
fill ~22 ~-3 ~37 ~69 ~-3 ~37 dirt 0  
fill ~22 ~-3 ~49 ~22 ~3 ~49 glass_pane 0  
fill ~22 ~-3 ~54 ~23 ~-3 ~54 iron_block 0  
fill ~23 ~-3 ~20 ~38 ~-3 ~20 dirt 0  
fill ~23 ~-3 ~49 ~23 ~4 ~49 iron_block 0  
fill ~23 ~-3 ~50 ~23 ~-2 ~50 glass_pane 0  
fill ~23 ~-3 ~51 ~23 ~4 ~51 iron_block 0  
fill ~23 ~-3 ~52 ~23 ~-2 ~52 glass_pane 0  
fill ~24 ~-3 ~3 ~69 ~-3 ~3 dirt 0  
fill ~24 ~-3 ~8 ~38 ~-3 ~8 dirt 0  
fill ~24 ~-3 ~18 ~38 ~-3 ~18 dirt 0  
fill ~24 ~-3 ~64 ~28 ~-3 ~64 dirt 0  
fill ~24 ~-3 ~65 ~27 ~-3 ~65 dirt 0  
fill ~25 ~-3 ~9 ~38 ~-3 ~9 dirt 0  
fill ~25 ~-3 ~17 ~38 ~-3 ~17 dirt 0  
fill ~25 ~-3 ~63 ~29 ~-3 ~63 dirt 0  
fill ~26 ~-3 ~10 ~34 ~-3 ~10 dirt 0  
fill ~26 ~-3 ~11 ~38 ~-3 ~11 dirt 0  
fill ~26 ~-3 ~12 ~38 ~-3 ~12 dirt 0  
fill ~26 ~-3 ~14 ~38 ~-3 ~14 dirt 0  
fill ~26 ~-3 ~15 ~38 ~-3 ~15 dirt 0  
fill ~26 ~-3 ~16 ~38 ~-3 ~16 dirt 0  
fill ~26 ~-3 ~51 ~27 ~-3 ~51 stone_brick_stairs 2  
fill ~26 ~-3 ~52 ~27 ~-3 ~52 stonebrick 0  
fill ~26 ~-3 ~67 ~28 ~-3 ~67 coal_ore 0  
fill ~26 ~-3 ~68 ~26 ~-3 ~68 coal_ore 0  
fill ~27 ~-3 ~13 ~38 ~-3 ~13 dirt 0  
fill ~27 ~-3 ~66 ~29 ~-3 ~66 coal_ore 0  
fill ~27 ~-3 ~68 ~30 ~-3 ~68 stone 0  
fill ~28 ~-3 ~65 ~32 ~-3 ~65 stone 0  
fill ~29 ~-3 ~64 ~31 ~-3 ~64 gravel 0  
fill ~29 ~-3 ~67 ~30 ~-3 ~67 stone 0  
fill ~30 ~-3 ~38 ~69 ~-3 ~38 dirt 0  
fill ~30 ~-3 ~39 ~30 ~-2 ~39 iron_block 0  
fill ~30 ~-3 ~40 ~30 ~-2 ~40 iron_block 0  
fill ~30 ~-3 ~41 ~30 ~-2 ~41 iron_block 0  
fill ~30 ~-3 ~42 ~30 ~-2 ~42 iron_block 0  
fill ~30 ~-3 ~43 ~30 ~-2 ~43 iron_block 0  
fill ~30 ~-3 ~44 ~30 ~-2 ~44 iron_block 0  
fill ~30 ~-3 ~45 ~30 ~-2 ~45 iron_block 0  
fill ~30 ~-3 ~46 ~30 ~-2 ~46 iron_block 0  
fill ~30 ~-3 ~47 ~30 ~-2 ~47 iron_block 0  
fill ~30 ~-3 ~48 ~30 ~-2 ~48 iron_block 0  
fill ~30 ~-3 ~49 ~30 ~-2 ~49 iron_block 0  
fill ~30 ~-3 ~50 ~30 ~-2 ~50 iron_block 0  
fill ~30 ~-3 ~51 ~30 ~-2 ~51 iron_block 0  
fill ~30 ~-3 ~52 ~30 ~-2 ~52 iron_block 0  
fill ~30 ~-3 ~53 ~30 ~-2 ~53 iron_block 0  
fill ~30 ~-3 ~54 ~30 ~-2 ~54 iron_block 0  
fill ~30 ~-3 ~55 ~30 ~-2 ~55 iron_block 0  
fill ~30 ~-3 ~56 ~30 ~-2 ~56 iron_block 0  
fill ~30 ~-3 ~57 ~30 ~-2 ~57 iron_block 0  
fill ~30 ~-3 ~58 ~30 ~-2 ~58 iron_block 0  
fill ~30 ~-3 ~59 ~30 ~-2 ~59 iron_block 0  
fill ~30 ~-3 ~60 ~30 ~-2 ~60 iron_block 0  
fill ~30 ~-3 ~61 ~30 ~-2 ~61 iron_block 0  
fill ~30 ~-3 ~62 ~30 ~-2 ~62 dirt 0  
fill ~30 ~-3 ~63 ~32 ~-3 ~63 gravel 0  
fill ~30 ~-3 ~66 ~30 ~-3 ~66 stone 0  
fill ~31 ~-3 ~0 ~33 ~-3 ~0 stone 0  
fill ~31 ~-3 ~39 ~65 ~-3 ~39 dirt 0  
fill ~31 ~-3 ~40 ~63 ~-3 ~40 dirt 0  
fill ~31 ~-3 ~41 ~58 ~-3 ~41 dirt 0  
fill ~31 ~-3 ~42 ~59 ~-3 ~42 dirt 0  
fill ~31 ~-3 ~43 ~60 ~-3 ~43 dirt 0  
fill ~31 ~-3 ~44 ~60 ~-3 ~44 dirt 0  
fill ~31 ~-3 ~45 ~61 ~-3 ~45 dirt 0  
fill ~31 ~-3 ~46 ~38 ~-3 ~46 dirt 0  
fill ~31 ~-3 ~47 ~36 ~-3 ~47 dirt 0  
fill ~31 ~-3 ~48 ~42 ~-3 ~48 stone 0  
fill ~31 ~-3 ~49 ~43 ~-3 ~49 stone 0  
fill ~31 ~-3 ~50 ~42 ~-3 ~50 stone 0  
fill ~31 ~-3 ~51 ~42 ~-3 ~51 stone 0  
fill ~31 ~-3 ~52 ~42 ~-3 ~52 stone 0  
fill ~31 ~-3 ~53 ~42 ~-3 ~53 stone 0  
fill ~31 ~-3 ~54 ~42 ~-3 ~54 stone 0  
fill ~31 ~-3 ~55 ~43 ~-3 ~55 stone 0  
fill ~31 ~-3 ~56 ~44 ~-3 ~56 stone 0  
fill ~31 ~-3 ~57 ~44 ~-3 ~57 stone 0  
fill ~31 ~-3 ~58 ~39 ~-3 ~58 stone 0  
fill ~31 ~-3 ~59 ~38 ~-3 ~59 stone 0  
fill ~31 ~-3 ~60 ~43 ~-3 ~60 stone 0  
fill ~31 ~-3 ~61 ~43 ~-3 ~61 stone 0  
fill ~31 ~-3 ~62 ~47 ~-3 ~62 stone 0  
fill ~31 ~-3 ~66 ~42 ~-3 ~66 dirt 0  
fill ~31 ~-3 ~67 ~34 ~-3 ~67 dirt 0  
fill ~31 ~-3 ~68 ~34 ~-3 ~68 dirt 0  
fill ~32 ~-3 ~64 ~32 ~-3 ~64 stone 0  
fill ~33 ~-3 ~63 ~50 ~-3 ~63 stone 0  
fill ~33 ~-3 ~64 ~35 ~-3 ~64 dirt 0  
fill ~33 ~-3 ~65 ~46 ~-3 ~65 dirt 0  
fill ~34 ~-3 ~0 ~69 ~-3 ~0 dirt 0 
setblock ~35 ~-3 ~10 grass 0  
fill ~35 ~-3 ~67 ~47 ~-3 ~67 stone 0  
fill ~35 ~-3 ~68 ~43 ~-3 ~68 stone 0  
fill ~36 ~-3 ~10 ~38 ~-3 ~10 dirt 0  
fill ~36 ~-3 ~64 ~53 ~-3 ~64 stone 0  
fill ~37 ~-3 ~7 ~37 ~-1 ~7 cobblestone 0  
fill ~37 ~-3 ~47 ~42 ~-3 ~47 stone 0  
fill ~38 ~-3 ~7 ~38 ~-2 ~7 dirt 0  
fill ~39 ~-3 ~6 ~39 ~-2 ~6 iron_block 0  
fill ~39 ~-3 ~7 ~39 ~-2 ~7 iron_block 0  
fill ~39 ~-3 ~8 ~39 ~-2 ~8 iron_block 0  
fill ~39 ~-3 ~9 ~39 ~-2 ~9 iron_block 0  
fill ~39 ~-3 ~10 ~39 ~-2 ~10 iron_block 0  
fill ~39 ~-3 ~11 ~39 ~-2 ~11 iron_block 0  
fill ~39 ~-3 ~12 ~39 ~-2 ~12 iron_block 0  
fill ~39 ~-3 ~13 ~39 ~-2 ~13 iron_block 0  
fill ~39 ~-3 ~14 ~39 ~-2 ~14 iron_block 0  
fill ~39 ~-3 ~15 ~39 ~-2 ~15 iron_block 0  
fill ~39 ~-3 ~16 ~39 ~-2 ~16 iron_block 0  
fill ~39 ~-3 ~17 ~39 ~-2 ~17 iron_block 0  
fill ~39 ~-3 ~18 ~39 ~-2 ~18 iron_block 0  
fill ~39 ~-3 ~19 ~39 ~-2 ~19 iron_block 0  
fill ~39 ~-3 ~20 ~39 ~-2 ~20 iron_block 0  
fill ~39 ~-3 ~21 ~39 ~-2 ~21 iron_block 0  
fill ~39 ~-3 ~22 ~39 ~-2 ~22 iron_block 0  
fill ~39 ~-3 ~23 ~39 ~-2 ~23 iron_block 0  
fill ~39 ~-3 ~24 ~39 ~-2 ~24 iron_block 0  
fill ~39 ~-3 ~25 ~39 ~-2 ~25 iron_block 0  
fill ~39 ~-3 ~26 ~39 ~-2 ~26 iron_block 0  
fill ~39 ~-3 ~27 ~39 ~-2 ~27 iron_block 0  
fill ~39 ~-3 ~28 ~39 ~-2 ~28 iron_block 0  
fill ~39 ~-3 ~46 ~40 ~-3 ~46 stone 0  
fill ~39 ~-3 ~59 ~39 ~-2 ~59 dirt 0  
fill ~40 ~-3 ~5 ~62 ~-3 ~5 iron_block 0  
fill ~40 ~-3 ~29 ~62 ~-3 ~29 iron_block 0  
fill ~40 ~-3 ~58 ~43 ~-3 ~58 dirt 0  
fill ~40 ~-3 ~59 ~40 ~-3 ~59 stone 0  
fill ~41 ~-3 ~46 ~67 ~-3 ~46 dirt 0  
fill ~41 ~-3 ~59 ~41 ~-2 ~59 dirt 0  
fill ~42 ~-3 ~59 ~44 ~-3 ~59 stone 0  
fill ~43 ~-3 ~47 ~66 ~-3 ~47 dirt 0  
fill ~43 ~-3 ~48 ~65 ~-3 ~48 dirt 0  
fill ~43 ~-3 ~50 ~66 ~-3 ~50 dirt 0  
fill ~43 ~-3 ~51 ~66 ~-3 ~51 dirt 0  
fill ~43 ~-3 ~52 ~67 ~-3 ~52 dirt 0  
fill ~43 ~-3 ~53 ~67 ~-3 ~53 dirt 0  
fill ~43 ~-3 ~54 ~67 ~-3 ~54 dirt 0  
fill ~43 ~-3 ~66 ~47 ~-3 ~66 stone 0  
fill ~44 ~-3 ~49 ~65 ~-3 ~49 dirt 0  
fill ~44 ~-3 ~55 ~66 ~-3 ~55 dirt 0  
fill ~44 ~-3 ~58 ~44 ~-3 ~58 stone 0  
fill ~44 ~-3 ~60 ~45 ~-3 ~60 dirt 0  
fill ~44 ~-3 ~61 ~44 ~-2 ~61 dirt 0  
fill ~44 ~-3 ~68 ~45 ~-3 ~68 iron_ore 0  
fill ~45 ~-3 ~56 ~66 ~-3 ~56 dirt 0  
fill ~45 ~-3 ~57 ~67 ~-3 ~57 dirt 0  
fill ~45 ~-3 ~58 ~67 ~-3 ~58 dirt 0  
fill ~45 ~-3 ~59 ~68 ~-3 ~59 dirt 0  
fill ~45 ~-3 ~61 ~50 ~-3 ~61 stone 0  
fill ~46 ~-3 ~60 ~46 ~-3 ~60 stone 0  
fill ~46 ~-3 ~68 ~47 ~-3 ~68 stone 0  
fill ~47 ~-3 ~60 ~68 ~-3 ~60 dirt 0  
fill ~47 ~-3 ~65 ~52 ~-3 ~65 stone 0  
fill ~48 ~-3 ~62 ~48 ~-2 ~62 dirt 0  
fill ~48 ~-3 ~66 ~49 ~-3 ~66 coal_ore 0  
fill ~48 ~-3 ~67 ~49 ~-3 ~67 coal_ore 0  
fill ~48 ~-3 ~68 ~49 ~-3 ~68 coal_ore 0  
fill ~49 ~-3 ~62 ~49 ~-3 ~62 stone 0  
fill ~50 ~-3 ~12 ~50 ~4 ~12 iron_block 0  
fill ~50 ~-3 ~13 ~50 ~3 ~13 glass_pane 0  
fill ~50 ~-3 ~14 ~50 ~4 ~14 iron_block 0  
fill ~50 ~-3 ~15 ~50 ~3 ~15 glass_pane 0  
fill ~50 ~-3 ~16 ~50 ~4 ~16 iron_block 0  
fill ~50 ~-3 ~17 ~50 ~-3 ~18 iron_block 0  
fill ~50 ~-3 ~19 ~50 ~3 ~19 glass_pane 0  
fill ~50 ~-3 ~20 ~50 ~4 ~20 iron_block 0  
fill ~50 ~-3 ~21 ~50 ~3 ~21 glass_pane 0  
fill ~50 ~-3 ~22 ~50 ~4 ~22 iron_block 0  
fill ~50 ~-3 ~62 ~50 ~-2 ~62 dirt 0  
fill ~50 ~-3 ~66 ~51 ~-3 ~66 stone 0  
fill ~50 ~-3 ~67 ~50 ~-2 ~67 stone 0  
fill ~50 ~-3 ~68 ~50 ~-2 ~68 stone 0  
fill ~51 ~-3 ~12 ~51 ~-2 ~12 glass_pane 0  
fill ~51 ~-3 ~22 ~51 ~-2 ~22 glass_pane 0  
fill ~51 ~-3 ~61 ~68 ~-3 ~61 dirt 0  
fill ~51 ~-3 ~62 ~51 ~-3 ~62 stone 0  
fill ~51 ~-3 ~63 ~51 ~-2 ~63 dirt 0  
fill ~52 ~-3 ~12 ~52 ~4 ~12 iron_block 0  
fill ~52 ~-3 ~22 ~52 ~4 ~22 iron_block 0  
fill ~52 ~-3 ~25 ~52 ~-3 ~26 stone_brick_stairs 0  
fill ~52 ~-3 ~62 ~52 ~-2 ~62 dirt 0  
fill ~52 ~-3 ~63 ~56 ~-3 ~63 stone 0  
fill ~53 ~-3 ~12 ~53 ~-2 ~12 glass_pane 0  
fill ~53 ~-3 ~22 ~53 ~-2 ~22 glass_pane 0  
fill ~53 ~-3 ~25 ~53 ~-3 ~26 stonebrick 0  
fill ~53 ~-3 ~62 ~53 ~-3 ~62 stone 0  
fill ~54 ~-3 ~12 ~56 ~-3 ~12 iron_block 0  
fill ~54 ~-3 ~13 ~56 ~-3 ~13 iron_block 0  
fill ~54 ~-3 ~14 ~54 ~4 ~14 iron_block 0  
fill ~54 ~-3 ~15 ~56 ~-3 ~15 iron_block 0  
fill ~54 ~-3 ~16 ~54 ~4 ~16 iron_block 0  
fill ~54 ~-3 ~17 ~56 ~-3 ~17 iron_block 0  
fill ~54 ~-3 ~18 ~54 ~4 ~18 iron_block 0  
fill ~54 ~-3 ~19 ~56 ~-3 ~19 iron_block 0  
fill ~54 ~-3 ~20 ~54 ~4 ~20 iron_block 0  
fill ~54 ~-3 ~21 ~56 ~-3 ~21 iron_block 0  
fill ~54 ~-3 ~22 ~56 ~-3 ~22 iron_block 0  
fill ~54 ~-3 ~62 ~56 ~-3 ~62 dirt 0  
fill ~55 ~-3 ~14 ~55 ~118 ~14 ladder 4  
fill ~55 ~-3 ~16 ~55 ~118 ~16 ladder 4  
fill ~55 ~-3 ~18 ~55 ~118 ~18 ladder 4  
fill ~55 ~-3 ~20 ~55 ~118 ~20 ladder 4  
fill ~56 ~-3 ~14 ~56 ~119 ~14 iron_block 0  
fill ~56 ~-3 ~16 ~56 ~119 ~16 iron_block 0  
fill ~56 ~-3 ~18 ~56 ~119 ~18 iron_block 0  
fill ~56 ~-3 ~20 ~56 ~119 ~20 iron_block 0  
fill ~57 ~-3 ~62 ~59 ~-3 ~62 coal_ore 0  
fill ~57 ~-3 ~63 ~57 ~-1 ~63 cobblestone 0  
fill ~57 ~-3 ~67 ~59 ~-3 ~67 stone 0  
fill ~57 ~-3 ~68 ~58 ~-3 ~68 stone 0  
fill ~59 ~-3 ~41 ~61 ~-3 ~41 stone 0  
fill ~60 ~-3 ~42 ~63 ~-3 ~42 stone 0  
fill ~60 ~-3 ~62 ~64 ~-3 ~62 dirt 0  
fill ~60 ~-3 ~63 ~61 ~-3 ~63 stone 0  
fill ~61 ~-3 ~43 ~63 ~-3 ~43 stone 0  
fill ~61 ~-3 ~44 ~62 ~-3 ~44 stone 0  
fill ~61 ~-3 ~64 ~61 ~-1 ~64 cobblestone 0  
fill ~62 ~-3 ~41 ~64 ~-3 ~41 coal_ore 0  
fill ~62 ~-3 ~45 ~62 ~-3 ~45 stone 0  
fill ~62 ~-3 ~63 ~63 ~-3 ~63 dirt 0  
fill ~62 ~-3 ~64 ~69 ~-3 ~64 stone 0  
fill ~62 ~-3 ~65 ~69 ~-3 ~65 stone 0  
fill ~63 ~-3 ~5 ~69 ~-3 ~5 dirt 0  
fill ~63 ~-3 ~6 ~63 ~-2 ~6 iron_block 0  
fill ~63 ~-3 ~7 ~63 ~-2 ~7 iron_block 0  
fill ~63 ~-3 ~8 ~63 ~-2 ~8 iron_block 0  
fill ~63 ~-3 ~9 ~63 ~-2 ~9 iron_block 0  
fill ~63 ~-3 ~10 ~63 ~-2 ~10 iron_block 0  
fill ~63 ~-3 ~11 ~63 ~-2 ~11 iron_block 0  
fill ~63 ~-3 ~12 ~63 ~-2 ~12 iron_block 0  
fill ~63 ~-3 ~13 ~63 ~-2 ~13 iron_block 0  
fill ~63 ~-3 ~14 ~63 ~-2 ~14 iron_block 0  
fill ~63 ~-3 ~15 ~63 ~-2 ~15 iron_block 0  
fill ~63 ~-3 ~16 ~63 ~-2 ~16 iron_block 0  
fill ~63 ~-3 ~17 ~63 ~-2 ~17 iron_block 0  
fill ~63 ~-3 ~18 ~63 ~-2 ~18 iron_block 0  
fill ~63 ~-3 ~19 ~63 ~-2 ~19 iron_block 0  
fill ~63 ~-3 ~20 ~63 ~-2 ~20 iron_block 0  
fill ~63 ~-3 ~21 ~63 ~-2 ~21 iron_block 0  
fill ~63 ~-3 ~22 ~63 ~-2 ~22 iron_block 0  
fill ~63 ~-3 ~23 ~63 ~-2 ~23 iron_block 0  
fill ~63 ~-3 ~24 ~63 ~-2 ~24 iron_block 0  
fill ~63 ~-3 ~25 ~63 ~-2 ~25 iron_block 0  
fill ~63 ~-3 ~26 ~63 ~-2 ~26 iron_block 0  
fill ~63 ~-3 ~27 ~63 ~-2 ~27 iron_block 0  
fill ~63 ~-3 ~28 ~63 ~-2 ~28 iron_block 0  
fill ~63 ~-3 ~29 ~69 ~-3 ~29 dirt 0  
fill ~63 ~-3 ~44 ~64 ~-3 ~44 gravel 0  
fill ~63 ~-3 ~45 ~64 ~-3 ~45 gravel 0  
fill ~63 ~-3 ~66 ~66 ~-3 ~66 gravel 0  
fill ~64 ~-3 ~6 ~69 ~-3 ~6 dirt 0  
fill ~64 ~-3 ~7 ~69 ~-3 ~7 dirt 0  
fill ~64 ~-3 ~8 ~69 ~-3 ~8 dirt 0  
fill ~64 ~-3 ~9 ~69 ~-3 ~9 dirt 0  
fill ~64 ~-3 ~10 ~69 ~-3 ~10 dirt 0  
fill ~64 ~-3 ~11 ~69 ~-3 ~11 dirt 0  
fill ~64 ~-3 ~12 ~69 ~-3 ~12 dirt 0  
fill ~64 ~-3 ~13 ~69 ~-3 ~13 dirt 0  
fill ~64 ~-3 ~14 ~69 ~-3 ~14 dirt 0  
fill ~64 ~-3 ~15 ~69 ~-3 ~15 dirt 0  
fill ~64 ~-3 ~16 ~69 ~-3 ~16 dirt 0  
fill ~64 ~-3 ~17 ~69 ~-3 ~17 dirt 0  
fill ~64 ~-3 ~18 ~69 ~-3 ~18 dirt 0  
fill ~64 ~-3 ~19 ~69 ~-3 ~19 dirt 0  
fill ~64 ~-3 ~20 ~69 ~-3 ~20 dirt 0  
fill ~64 ~-3 ~21 ~69 ~-3 ~21 dirt 0  
fill ~64 ~-3 ~22 ~69 ~-3 ~22 dirt 0  
fill ~64 ~-3 ~23 ~69 ~-3 ~23 dirt 0  
fill ~64 ~-3 ~24 ~69 ~-3 ~24 dirt 0  
fill ~64 ~-3 ~25 ~69 ~-3 ~25 dirt 0  
fill ~64 ~-3 ~26 ~69 ~-3 ~26 dirt 0  
fill ~64 ~-3 ~27 ~69 ~-3 ~27 dirt 0  
fill ~64 ~-3 ~28 ~69 ~-3 ~28 dirt 0  
fill ~64 ~-3 ~40 ~68 ~-3 ~40 stone 0 
setblock ~64 ~-3 ~42 coal_ore 0  
fill ~64 ~-3 ~43 ~65 ~-3 ~43 gravel 0  
fill ~64 ~-3 ~63 ~69 ~-3 ~63 stone 0  
fill ~64 ~-3 ~67 ~68 ~-3 ~67 gravel 0  
fill ~64 ~-3 ~68 ~69 ~-3 ~68 gravel 0  
fill ~65 ~-3 ~41 ~68 ~-3 ~41 stone 0  
fill ~65 ~-3 ~42 ~67 ~-3 ~42 stone 0  
fill ~65 ~-3 ~44 ~68 ~-3 ~44 dirt 0  
fill ~65 ~-3 ~45 ~68 ~-3 ~45 dirt 0  
fill ~65 ~-3 ~62 ~65 ~-3 ~62 stone 0  
fill ~66 ~-3 ~39 ~67 ~-3 ~39 stone 0  
fill ~66 ~-3 ~43 ~68 ~-3 ~43 dirt 0  
fill ~66 ~-3 ~48 ~69 ~-3 ~48 stone 0  
fill ~66 ~-3 ~49 ~69 ~-3 ~49 stone 0  
fill ~66 ~-3 ~62 ~67 ~-3 ~62 dirt 0  
fill ~67 ~-3 ~47 ~69 ~-3 ~47 stone 0  
fill ~67 ~-3 ~50 ~68 ~-3 ~50 stone 0  
fill ~67 ~-3 ~51 ~69 ~-3 ~51 stone 0  
fill ~67 ~-3 ~55 ~69 ~-3 ~55 stone 0  
fill ~67 ~-3 ~56 ~69 ~-3 ~56 stone 0  
fill ~67 ~-3 ~66 ~69 ~-3 ~66 stone 0  
fill ~68 ~-3 ~39 ~69 ~-3 ~39 dirt 0  
fill ~68 ~-3 ~42 ~69 ~-3 ~42 dirt 0  
fill ~68 ~-3 ~46 ~69 ~-3 ~46 stone 0  
fill ~68 ~-3 ~52 ~69 ~-3 ~52 stone 0  
fill ~68 ~-3 ~53 ~69 ~-3 ~53 stone 0  
fill ~68 ~-3 ~54 ~69 ~-3 ~54 stone 0  
fill ~68 ~-3 ~57 ~69 ~-3 ~57 stone 0  
fill ~68 ~-3 ~58 ~69 ~-3 ~58 stone 0  
fill ~68 ~-3 ~62 ~69 ~-3 ~62 stone 0  
fill ~69 ~-3 ~40 ~69 ~-3 ~40 dirt 0  
fill ~69 ~-3 ~41 ~69 ~-3 ~41 dirt 0  
fill ~69 ~-3 ~43 ~69 ~-3 ~49 stone 0  
fill ~69 ~-3 ~50 ~69 ~-3 ~50 dirt 0  
fill ~69 ~-3 ~59 ~69 ~-3 ~59 stone 0  
fill ~69 ~-3 ~60 ~69 ~-3 ~60 stone 0  
fill ~69 ~-3 ~61 ~69 ~-3 ~61 stone 0  
fill ~69 ~-3 ~67 ~69 ~-3 ~67 stone 0  
fill ~1 ~-2 ~0 ~6 ~-2 ~0 sand 0  
fill ~1 ~-2 ~1 ~5 ~-2 ~1 sand 0  
fill ~1 ~-2 ~2 ~1 ~-2 ~2 dirt 0  
fill ~1 ~-2 ~3 ~13 ~-2 ~3 dirt 0  
fill ~1 ~-2 ~4 ~69 ~-2 ~4 dirt 0  
fill ~1 ~-2 ~5 ~8 ~-2 ~5 dirt 0  
fill ~1 ~-2 ~6 ~38 ~-2 ~6 dirt 0  
fill ~1 ~-2 ~7 ~19 ~-2 ~7 dirt 0  
fill ~1 ~-2 ~8 ~16 ~-2 ~8 dirt 0  
fill ~1 ~-2 ~9 ~4 ~-2 ~9 dirt 0  
fill ~1 ~-2 ~10 ~14 ~-2 ~10 dirt 0  
fill ~1 ~-2 ~11 ~5 ~-2 ~11 dirt 0  
fill ~1 ~-2 ~12 ~5 ~-2 ~12 dirt 0  
fill ~1 ~-2 ~13 ~5 ~-2 ~13 dirt 0  
fill ~1 ~-2 ~14 ~5 ~-2 ~14 dirt 0  
fill ~1 ~-2 ~15 ~12 ~-2 ~15 dirt 0  
fill ~1 ~-2 ~16 ~11 ~-2 ~16 dirt 0  
fill ~1 ~-2 ~17 ~10 ~-2 ~17 dirt 0  
fill ~1 ~-2 ~18 ~10 ~-2 ~18 dirt 0  
fill ~1 ~-2 ~19 ~10 ~-2 ~19 dirt 0  
fill ~1 ~-2 ~20 ~9 ~-2 ~20 dirt 0  
fill ~1 ~-2 ~21 ~10 ~-2 ~21 dirt 0  
fill ~1 ~-2 ~22 ~10 ~-2 ~22 dirt 0  
fill ~1 ~-2 ~23 ~10 ~-2 ~23 dirt 0  
fill ~1 ~-2 ~24 ~11 ~-2 ~24 dirt 0  
fill ~1 ~-2 ~25 ~12 ~-2 ~25 dirt 0  
fill ~1 ~-2 ~26 ~15 ~-2 ~26 dirt 0  
fill ~1 ~-2 ~27 ~35 ~-2 ~27 dirt 0  
fill ~1 ~-2 ~28 ~38 ~-2 ~28 dirt 0  
fill ~1 ~-2 ~29 ~39 ~-2 ~29 dirt 0  
fill ~1 ~-2 ~30 ~1 ~-2 ~30 dirt 0  
fill ~1 ~-2 ~31 ~20 ~-2 ~31 dirt 0  
fill ~1 ~-2 ~32 ~1 ~-2 ~32 dirt 0  
fill ~1 ~-2 ~33 ~39 ~-2 ~33 dirt 0  
fill ~1 ~-2 ~34 ~40 ~-2 ~34 dirt 0  
fill ~1 ~-2 ~35 ~26 ~-2 ~35 dirt 0  
fill ~1 ~-2 ~36 ~69 ~-2 ~36 dirt 0  
fill ~1 ~-2 ~37 ~23 ~-2 ~37 dirt 0  
fill ~1 ~-2 ~38 ~6 ~-2 ~38 dirt 0  
fill ~1 ~-2 ~39 ~5 ~-2 ~39 dirt 0  
fill ~1 ~-2 ~40 ~5 ~-2 ~40 dirt 0  
fill ~1 ~-2 ~41 ~5 ~-2 ~41 dirt 0  
fill ~1 ~-2 ~42 ~5 ~-2 ~42 dirt 0  
fill ~1 ~-2 ~43 ~1 ~-2 ~43 dirt 0  
fill ~1 ~-2 ~44 ~5 ~-2 ~44 dirt 0  
fill ~1 ~-2 ~45 ~1 ~-2 ~45 stone 0  
fill ~1 ~-2 ~46 ~5 ~-2 ~46 dirt 0  
fill ~1 ~-2 ~47 ~5 ~-2 ~47 dirt 0  
fill ~1 ~-2 ~48 ~5 ~-2 ~48 dirt 0  
fill ~1 ~-2 ~49 ~5 ~-2 ~49 dirt 0  
fill ~1 ~-2 ~50 ~5 ~-2 ~50 dirt 0  
fill ~1 ~-2 ~51 ~5 ~-2 ~51 dirt 0  
fill ~1 ~-2 ~52 ~5 ~-2 ~52 dirt 0  
fill ~1 ~-2 ~53 ~5 ~-2 ~53 dirt 0  
fill ~1 ~-2 ~54 ~5 ~-2 ~54 dirt 0  
fill ~1 ~-2 ~55 ~5 ~-2 ~55 dirt 0  
fill ~1 ~-2 ~56 ~5 ~-2 ~56 dirt 0  
fill ~1 ~-2 ~57 ~5 ~-2 ~57 dirt 0  
fill ~1 ~-2 ~58 ~5 ~-2 ~58 dirt 0  
fill ~1 ~-2 ~59 ~5 ~-2 ~59 dirt 0  
fill ~1 ~-2 ~60 ~5 ~-2 ~60 dirt 0  
fill ~1 ~-2 ~61 ~5 ~-2 ~61 dirt 0  
fill ~1 ~-2 ~62 ~6 ~-2 ~62 dirt 0  
fill ~1 ~-2 ~63 ~10 ~-2 ~63 dirt 0  
fill ~1 ~-2 ~64 ~10 ~-2 ~64 dirt 0  
fill ~1 ~-2 ~65 ~20 ~-2 ~65 dirt 0  
fill ~1 ~-2 ~66 ~16 ~-2 ~66 dirt 0  
fill ~1 ~-2 ~67 ~38 ~-2 ~67 dirt 0  
fill ~1 ~-2 ~68 ~17 ~-2 ~68 dirt 0 
setblock ~2 ~-2 ~2 sand 0  
fill ~2 ~-2 ~30 ~2 ~-1 ~30 cobblestone 0  
fill ~2 ~-2 ~32 ~2 ~-1 ~32 cobblestone 0  
fill ~2 ~-2 ~43 ~2 ~-1 ~43 cobblestone 0  
fill ~2 ~-2 ~45 ~2 ~-1 ~45 cobblestone 0  
fill ~3 ~-2 ~2 ~69 ~-2 ~2 dirt 0  
fill ~3 ~-2 ~30 ~4 ~-2 ~30 dirt 0  
fill ~3 ~-2 ~32 ~69 ~-2 ~32 dirt 0  
fill ~3 ~-2 ~43 ~5 ~-2 ~43 dirt 0  
fill ~3 ~-2 ~45 ~5 ~-2 ~45 dirt 0  
fill ~5 ~-2 ~30 ~5 ~-1 ~30 cobblestone 0  
fill ~6 ~-2 ~1 ~69 ~-2 ~1 dirt 0  
fill ~6 ~-2 ~9 ~15 ~-2 ~9 dirt 0  
fill ~6 ~-2 ~30 ~69 ~-2 ~30 dirt 0  
fill ~7 ~-2 ~0 ~69 ~-2 ~0 dirt 0  
fill ~7 ~-2 ~11 ~14 ~-2 ~11 dirt 0  
fill ~7 ~-2 ~12 ~14 ~-2 ~12 dirt 0  
fill ~7 ~-2 ~13 ~13 ~-2 ~13 dirt 0  
fill ~7 ~-2 ~14 ~14 ~-2 ~14 dirt 0  
fill ~7 ~-2 ~38 ~29 ~-2 ~38 iron_block 0  
fill ~7 ~-2 ~62 ~29 ~-2 ~62 iron_block 0  
fill ~10 ~-2 ~5 ~16 ~-2 ~5 dirt 0  
fill ~10 ~-2 ~20 ~17 ~-2 ~20 sand 0  
fill ~11 ~-2 ~17 ~17 ~-2 ~17 sand 0  
fill ~11 ~-2 ~18 ~18 ~-2 ~18 sand 0  
fill ~11 ~-2 ~19 ~17 ~-2 ~19 sand 0  
fill ~11 ~-2 ~21 ~18 ~-2 ~21 sand 0  
fill ~11 ~-2 ~22 ~13 ~-2 ~22 sand 0  
fill ~11 ~-2 ~23 ~21 ~-2 ~23 sand 0  
fill ~11 ~-2 ~63 ~23 ~-2 ~63 stone 0  
fill ~11 ~-2 ~64 ~21 ~-2 ~64 stone 0  
fill ~12 ~-2 ~16 ~23 ~-2 ~16 sand 0  
fill ~12 ~-2 ~24 ~20 ~-2 ~24 sand 0  
fill ~13 ~-2 ~15 ~25 ~-2 ~15 sand 0  
fill ~13 ~-2 ~25 ~19 ~-2 ~25 sand 0  
fill ~13 ~-2 ~53 ~23 ~-2 ~53 iron_block 0  
fill ~13 ~-2 ~54 ~14 ~-2 ~54 iron_block 0  
fill ~13 ~-2 ~55 ~23 ~-2 ~55 iron_block 0  
fill ~14 ~-2 ~13 ~22 ~-2 ~13 sand 0  
fill ~15 ~-2 ~10 ~25 ~-2 ~10 sand 0  
fill ~15 ~-2 ~11 ~24 ~-2 ~11 sand 0  
fill ~15 ~-2 ~12 ~24 ~-2 ~12 sand 0  
fill ~15 ~-2 ~14 ~21 ~-2 ~14 sand 0  
fill ~16 ~-2 ~9 ~24 ~-2 ~9 sand 0  
fill ~17 ~-2 ~8 ~23 ~-2 ~8 sand 0  
fill ~17 ~-2 ~26 ~38 ~-2 ~26 dirt 0  
fill ~17 ~-2 ~49 ~17 ~4 ~49 iron_block 0 
setblock ~17 ~-2 ~66 stone 0  
fill ~18 ~-2 ~5 ~39 ~-2 ~5 dirt 0 
setblock ~18 ~-2 ~19 water 0  
fill ~18 ~-2 ~20 ~24 ~-2 ~20 cobblestone 0  
fill ~18 ~-2 ~22 ~19 ~-2 ~22 sand 0  
fill ~18 ~-2 ~49 ~18 ~3 ~49 glass_pane 0  
fill ~18 ~-2 ~66 ~21 ~-2 ~66 dirt 0  
fill ~18 ~-2 ~68 ~20 ~-2 ~68 stone 0  
fill ~19 ~-2 ~3 ~20 ~-2 ~3 dirt 0  
fill ~19 ~-2 ~17 ~19 ~-1 ~17 cobblestone 0  
fill ~19 ~-2 ~18 ~21 ~-2 ~18 cobblestone 0  
fill ~19 ~-2 ~19 ~22 ~-2 ~19 cobblestone 0  
fill ~19 ~-2 ~21 ~23 ~-2 ~21 cobblestone 0  
fill ~19 ~-2 ~49 ~19 ~4 ~49 iron_block 0 
setblock ~20 ~-2 ~17 water 0  
fill ~20 ~-2 ~22 ~22 ~-2 ~22 cobblestone 0  
fill ~20 ~-2 ~25 ~38 ~-2 ~25 dirt 0  
fill ~21 ~-2 ~7 ~36 ~-2 ~7 dirt 0  
fill ~21 ~-2 ~17 ~23 ~-2 ~17 sand 0  
fill ~21 ~-2 ~24 ~36 ~-2 ~24 dirt 0  
fill ~21 ~-2 ~65 ~22 ~-2 ~65 stone 0  
fill ~21 ~-2 ~68 ~23 ~-2 ~68 dirt 0  
fill ~22 ~-2 ~14 ~22 ~-1 ~14 cobblestone 0  
fill ~22 ~-2 ~18 ~23 ~-2 ~18 sand 0  
fill ~22 ~-2 ~23 ~38 ~-2 ~23 dirt 0  
fill ~22 ~-2 ~31 ~69 ~-2 ~31 dirt 0  
fill ~22 ~-2 ~54 ~23 ~-2 ~54 iron_block 0  
fill ~22 ~-2 ~64 ~22 ~-1 ~64 cobblestone 0  
fill ~22 ~-2 ~66 ~23 ~-2 ~66 stone 0  
fill ~23 ~-2 ~13 ~23 ~-2 ~14 water 0 
setblock ~23 ~-2 ~19 water 0  
fill ~23 ~-2 ~22 ~38 ~-2 ~22 dirt 0  
fill ~23 ~-2 ~64 ~23 ~-2 ~65 dirt 0  
fill ~24 ~-2 ~3 ~69 ~-2 ~3 dirt 0  
fill ~24 ~-2 ~8 ~34 ~-2 ~8 dirt 0  
fill ~24 ~-2 ~13 ~24 ~-2 ~15 sand 0  
fill ~24 ~-2 ~16 ~25 ~-2 ~16 water 0  
fill ~24 ~-2 ~17 ~24 ~-1 ~17 cobblestone 0  
fill ~24 ~-2 ~18 ~38 ~-2 ~18 dirt 0  
fill ~24 ~-2 ~19 ~38 ~-2 ~19 dirt 0  
fill ~24 ~-2 ~21 ~38 ~-2 ~21 dirt 0 
setblock ~24 ~-2 ~37 iron_block 0  
fill ~24 ~-2 ~63 ~30 ~-2 ~63 dirt 0  
fill ~24 ~-2 ~64 ~24 ~-1 ~64 cobblestone 0  
fill ~24 ~-2 ~65 ~49 ~-2 ~65 dirt 0  
fill ~24 ~-2 ~66 ~49 ~-2 ~66 dirt 0  
fill ~24 ~-2 ~68 ~25 ~-2 ~68 stone 0  
fill ~25 ~-2 ~9 ~38 ~-2 ~9 dirt 0 
setblock ~25 ~-2 ~17 water 0  
fill ~25 ~-2 ~20 ~38 ~-2 ~20 dirt 0  
fill ~25 ~-2 ~37 ~69 ~-2 ~37 dirt 0  
fill ~25 ~-2 ~64 ~29 ~-2 ~64 dirt 0  
fill ~26 ~-2 ~10 ~34 ~-2 ~10 dirt 0  
fill ~26 ~-2 ~11 ~38 ~-2 ~11 dirt 0  
fill ~26 ~-2 ~12 ~34 ~-2 ~12 dirt 0 
setblock ~26 ~-2 ~13 sand 0  
fill ~26 ~-2 ~14 ~38 ~-2 ~14 dirt 0  
fill ~26 ~-2 ~15 ~38 ~-2 ~15 dirt 0  
fill ~26 ~-2 ~16 ~38 ~-2 ~16 dirt 0  
fill ~26 ~-2 ~17 ~38 ~-2 ~17 dirt 0  
fill ~26 ~-2 ~52 ~27 ~-2 ~52 stone_brick_stairs 2  
fill ~26 ~-2 ~53 ~27 ~-2 ~53 stonebrick 0  
fill ~26 ~-2 ~68 ~35 ~-2 ~68 dirt 0  
fill ~27 ~-2 ~13 ~38 ~-2 ~13 dirt 0  
fill ~27 ~-2 ~35 ~28 ~-2 ~35 cobblestone 0  
fill ~29 ~-2 ~35 ~69 ~-2 ~35 dirt 0  
fill ~30 ~-2 ~38 ~69 ~-2 ~38 dirt 0  
fill ~30 ~-2 ~64 ~33 ~-2 ~64 gravel 0  
fill ~31 ~-2 ~39 ~69 ~-2 ~39 dirt 0  
fill ~31 ~-2 ~40 ~69 ~-2 ~40 dirt 0  
fill ~31 ~-2 ~41 ~69 ~-2 ~41 dirt 0  
fill ~31 ~-2 ~42 ~69 ~-2 ~42 dirt 0  
fill ~31 ~-2 ~43 ~49 ~-2 ~43 dirt 0  
fill ~31 ~-2 ~44 ~69 ~-2 ~44 dirt 0  
fill ~31 ~-2 ~45 ~69 ~-2 ~45 dirt 0  
fill ~31 ~-2 ~46 ~69 ~-2 ~46 dirt 0  
fill ~31 ~-2 ~47 ~69 ~-2 ~47 dirt 0  
fill ~31 ~-2 ~48 ~69 ~-2 ~48 dirt 0  
fill ~31 ~-2 ~49 ~69 ~-2 ~49 dirt 0  
fill ~31 ~-2 ~50 ~51 ~-2 ~50 dirt 0  
fill ~31 ~-2 ~51 ~62 ~-2 ~51 dirt 0  
fill ~31 ~-2 ~52 ~69 ~-2 ~52 dirt 0  
fill ~31 ~-2 ~53 ~69 ~-2 ~53 dirt 0  
fill ~31 ~-2 ~54 ~64 ~-2 ~54 dirt 0  
fill ~31 ~-2 ~55 ~58 ~-2 ~55 dirt 0  
fill ~31 ~-2 ~56 ~37 ~-2 ~56 dirt 0  
fill ~31 ~-2 ~57 ~31 ~-2 ~0 dirt 0  
fill ~31 ~-2 ~58 ~31 ~-3 ~58 stone 0  
fill ~31 ~-2 ~59 ~37 ~-2 ~59 stone 0  
fill ~31 ~-2 ~60 ~36 ~-2 ~60 stone 0  
fill ~31 ~-2 ~61 ~35 ~-2 ~61 stone 0  
fill ~31 ~-2 ~62 ~31 ~-1 ~62 dirt 0  
fill ~31 ~-2 ~63 ~34 ~-2 ~63 gravel 0 
setblock ~32 ~-2 ~57 stone 0  
fill ~32 ~-2 ~58 ~33 ~-2 ~58 dirt 0  
fill ~32 ~-2 ~62 ~34 ~-2 ~62 gravel 0 
setblock ~33 ~-2 ~57 dirt 0  
fill ~34 ~-2 ~57 ~34 ~-2 ~61 stone 0 
setblock ~34 ~-2 ~64 stone 0  
fill ~35 ~-2 ~57 ~37 ~-2 ~57 dirt 0 
setblock ~35 ~-2 ~58 stone 0  
fill ~35 ~-2 ~62 ~54 ~-2 ~62 dirt 0  
fill ~35 ~-2 ~63 ~39 ~-2 ~63 dirt 0  
fill ~35 ~-2 ~64 ~48 ~-2 ~64 dirt 0  
fill ~36 ~-2 ~8 ~38 ~-2 ~8 dirt 0  
fill ~36 ~-2 ~10 ~38 ~-2 ~10 dirt 0  
fill ~36 ~-2 ~12 ~38 ~-2 ~12 dirt 0  
fill ~36 ~-2 ~27 ~36 ~-1 ~27 cobblestone 0  
fill ~36 ~-2 ~58 ~60 ~-2 ~58 dirt 0  
fill ~36 ~-2 ~61 ~69 ~-2 ~61 dirt 0 
setblock ~36 ~-2 ~68 stone 0  
fill ~37 ~-2 ~24 ~37 ~-1 ~24 cobblestone 0  
fill ~37 ~-2 ~27 ~38 ~-2 ~27 dirt 0  
fill ~37 ~-2 ~60 ~69 ~-2 ~60 dirt 0  
fill ~37 ~-2 ~68 ~40 ~-2 ~68 dirt 0 
setblock ~38 ~-2 ~24 dirt 0  
fill ~38 ~-2 ~56 ~39 ~-2 ~56 stone 0  
fill ~38 ~-2 ~57 ~38 ~-2 ~56 stone 0 
setblock ~38 ~-2 ~59 dirt 0  
fill ~39 ~-2 ~57 ~61 ~-2 ~57 dirt 0 
setblock ~39 ~-2 ~67 stone 0  
fill ~40 ~-2 ~5 ~62 ~-2 ~5 iron_block 0  
fill ~40 ~-2 ~29 ~62 ~-2 ~29 iron_block 0  
fill ~40 ~-2 ~33 ~40 ~-1 ~33 cobblestone 0  
fill ~40 ~-2 ~56 ~41 ~-2 ~56 dirt 0 
setblock ~40 ~-2 ~59 dirt 0  
fill ~40 ~-2 ~63 ~40 ~-1 ~63 cobblestone 0 
setblock ~40 ~-2 ~67 dirt 0  
fill ~41 ~-2 ~33 ~69 ~-2 ~33 dirt 0  
fill ~41 ~-2 ~34 ~41 ~-1 ~34 cobblestone 0  
fill ~41 ~-2 ~63 ~53 ~-2 ~63 dirt 0  
fill ~41 ~-2 ~67 ~43 ~-2 ~67 stone 0  
fill ~41 ~-2 ~68 ~41 ~-2 ~67 stone 0  
fill ~42 ~-2 ~34 ~69 ~-2 ~34 dirt 0 
setblock ~42 ~-2 ~56 stone 0  
fill ~42 ~-2 ~59 ~69 ~-2 ~59 dirt 0 
setblock ~42 ~-2 ~68 dirt 0  
fill ~43 ~-2 ~56 ~69 ~-2 ~56 dirt 0  
fill ~43 ~-2 ~68 ~44 ~-2 ~68 stone 0 
setblock ~44 ~-2 ~67 dirt 0  
fill ~45 ~-2 ~67 ~47 ~-2 ~67 stone 0 
setblock ~45 ~-2 ~68 dirt 0  
fill ~46 ~-2 ~68 ~46 ~-3 ~68 stone 0 
setblock ~47 ~-2 ~68 dirt 0 
setblock ~48 ~-2 ~67 dirt 0  
fill ~48 ~-2 ~68 ~49 ~-2 ~68 coal_ore 0  
fill ~49 ~-2 ~64 ~51 ~-2 ~64 stone 0 
setblock ~49 ~-2 ~67 coal_ore 0  
fill ~50 ~-2 ~17 ~50 ~3 ~17 glass_pane 0  
fill ~50 ~-2 ~18 ~50 ~4 ~18 iron_block 0  
fill ~50 ~-2 ~43 ~50 ~-1 ~43 cobblestone 0  
fill ~50 ~-2 ~65 ~50 ~-2 ~68 stone 0  
fill ~51 ~-2 ~43 ~69 ~-2 ~43 dirt 0  
fill ~51 ~-2 ~65 ~51 ~-1 ~65 cobblestone 0  
fill ~51 ~-2 ~66 ~51 ~-1 ~66 cobblestone 0  
fill ~51 ~-2 ~67 ~56 ~-2 ~67 cobblestone 0  
fill ~52 ~-2 ~50 ~52 ~-1 ~50 cobblestone 0  
fill ~53 ~-2 ~25 ~53 ~-2 ~26 stone_brick_stairs 0  
fill ~53 ~-2 ~50 ~69 ~-2 ~50 dirt 0  
fill ~54 ~-2 ~12 ~56 ~-2 ~12 iron_block 0  
fill ~54 ~-2 ~13 ~56 ~-2 ~13 iron_block 0  
fill ~54 ~-2 ~15 ~56 ~-2 ~15 iron_block 0  
fill ~54 ~-2 ~17 ~56 ~-2 ~17 iron_block 0  
fill ~54 ~-2 ~19 ~56 ~-2 ~19 iron_block 0  
fill ~54 ~-2 ~21 ~56 ~-2 ~21 iron_block 0  
fill ~54 ~-2 ~22 ~56 ~-2 ~22 iron_block 0  
fill ~54 ~-2 ~25 ~54 ~-2 ~26 stonebrick 0  
fill ~54 ~-2 ~63 ~57 ~-2 ~63 cobblestone 0 
setblock ~55 ~-2 ~62 stone 0  
fill ~56 ~-2 ~62 ~59 ~-2 ~62 dirt 0  
fill ~57 ~-2 ~67 ~57 ~-3 ~67 stone 0  
fill ~57 ~-2 ~68 ~58 ~-2 ~68 stone 0 
setblock ~58 ~-2 ~67 dirt 0  
fill ~59 ~-2 ~55 ~59 ~-1 ~55 cobblestone 0 
setblock ~59 ~-2 ~67 stone 0  
fill ~60 ~-2 ~55 ~69 ~-2 ~55 dirt 0 
setblock ~60 ~-2 ~62 stone 0  
fill ~60 ~-2 ~63 ~60 ~-1 ~63 cobblestone 0  
fill ~61 ~-2 ~58 ~61 ~-1 ~58 cobblestone 0  
fill ~61 ~-2 ~62 ~69 ~-2 ~62 dirt 0  
fill ~61 ~-2 ~63 ~61 ~-2 ~59 dirt 0  
fill ~62 ~-2 ~57 ~62 ~-1 ~57 cobblestone 0  
fill ~62 ~-2 ~58 ~69 ~-2 ~58 dirt 0 
setblock ~62 ~-2 ~63 stone 0  
fill ~62 ~-2 ~64 ~63 ~-2 ~64 cobblestone 0  
fill ~62 ~-2 ~65 ~62 ~-1 ~65 cobblestone 0  
fill ~63 ~-2 ~5 ~69 ~-2 ~5 dirt 0  
fill ~63 ~-2 ~29 ~69 ~-2 ~29 dirt 0  
fill ~63 ~-2 ~51 ~63 ~-1 ~51 cobblestone 0  
fill ~63 ~-2 ~57 ~69 ~-2 ~57 dirt 0  
fill ~63 ~-2 ~63 ~69 ~-2 ~63 dirt 0  
fill ~63 ~-2 ~65 ~63 ~-2 ~66 stone 0  
fill ~63 ~-2 ~67 ~63 ~-1 ~67 cobblestone 0  
fill ~64 ~-2 ~6 ~69 ~-2 ~6 dirt 0  
fill ~64 ~-2 ~7 ~69 ~-2 ~7 dirt 0
fill ~64 ~-2 ~8 ~69 ~-2 ~8 dirt 0  
fill ~64 ~-2 ~9 ~69 ~-2 ~9 dirt 0  
fill ~64 ~-2 ~10 ~69 ~-2 ~10 dirt 0  
fill ~64 ~-2 ~11 ~64 ~-3 ~11 dirt 0  
fill ~64 ~-2 ~12 ~69 ~-2 ~12 dirt 0  
fill ~64 ~-2 ~13 ~69 ~-2 ~13 dirt 0  
fill ~64 ~-2 ~14 ~69 ~-2 ~14 dirt 0  
fill ~64 ~-2 ~15 ~69 ~-2 ~15 dirt 0  
fill ~64 ~-2 ~16 ~69 ~-2 ~16 dirt 0  
fill ~64 ~-2 ~17 ~69 ~-2 ~17 dirt 0  
fill ~64 ~-2 ~18 ~69 ~-2 ~18 dirt 0  
fill ~64 ~-2 ~19 ~64 ~-3 ~19 dirt 0  
fill ~64 ~-2 ~20 ~69 ~-2 ~20 dirt 0  
fill ~64 ~-2 ~21 ~69 ~-2 ~21 dirt 0  
fill ~64 ~-2 ~22 ~69 ~-2 ~22 dirt 0  
fill ~64 ~-2 ~23 ~69 ~-2 ~23 dirt 0  
fill ~64 ~-2 ~24 ~69 ~-2 ~24 dirt 0  
fill ~64 ~-2 ~25 ~69 ~-2 ~25 dirt 0  
fill ~64 ~-2 ~26 ~69 ~-2 ~26 dirt 0  
fill ~64 ~-2 ~27 ~69 ~-2 ~27 dirt 0  
fill ~64 ~-2 ~51 ~69 ~-2 ~51 dirt 0  
fill ~64 ~-2 ~64 ~69 ~-2 ~64 dirt 0  
fill ~64 ~-2 ~65 ~69 ~-2 ~65 dirt 0  
fill ~64 ~-2 ~66 ~69 ~-2 ~66 dirt 0  
fill ~64 ~-2 ~67 ~69 ~-2 ~67 dirt 0  
fill ~64 ~-2 ~68 ~64 ~-3 ~68 gravel 0  
fill ~65 ~-2 ~11 ~65 ~-1 ~11 cobblestone 0  
fill ~65 ~-2 ~54 ~65 ~-1 ~54 cobblestone 0  
fill ~65 ~-2 ~68 ~69 ~-2 ~68 dirt 0  
fill ~66 ~-2 ~11 ~69 ~-2 ~11 dirt 0  
fill ~66 ~-2 ~19 ~69 ~-2 ~19 dirt 0  
fill ~66 ~-2 ~28 ~69 ~-2 ~28 dirt 0  
fill ~66 ~-2 ~54 ~69 ~-2 ~54 dirt 0  
fill ~1 ~-1 ~0 ~3 ~-1 ~0 dirt 0  
fill ~1 ~-1 ~1 ~1 ~-1 ~0 dirt 0  
fill ~1 ~-1 ~2 ~1 ~-1 ~2 grass 0  
fill ~1 ~-1 ~3 ~1 ~-1 ~3 grass 0  
fill ~1 ~-1 ~4 ~1 ~-1 ~4 grass 0  
fill ~1 ~-1 ~5 ~1 ~-1 ~5 grass 0  
fill ~1 ~-1 ~6 ~1 ~-1 ~6 grass 0  
fill ~1 ~-1 ~7 ~1 ~-1 ~7 grass 0  
fill ~1 ~-1 ~8 ~1 ~-1 ~8 grass 0  
fill ~1 ~-1 ~9 ~1 ~-1 ~9 grass 0  
fill ~1 ~-1 ~10 ~1 ~-1 ~10 grass 0  
fill ~1 ~-1 ~11 ~1 ~-1 ~11 grass 0  
fill ~1 ~-1 ~12 ~1 ~-3 ~12 dirt 0  
fill ~1 ~-1 ~13 ~1 ~-3 ~13 dirt 0  
fill ~1 ~-1 ~14 ~1 ~-1 ~14 grass 0  
fill ~1 ~-1 ~15 ~1 ~-1 ~15 grass 0  
fill ~1 ~-1 ~16 ~1 ~-1 ~16 grass 0  
fill ~1 ~-1 ~17 ~1 ~-1 ~17 grass 0  
fill ~1 ~-1 ~18 ~1 ~-1 ~18 grass 0  
fill ~1 ~-1 ~19 ~1 ~-1 ~19 grass 0  
fill ~1 ~-1 ~20 ~1 ~-1 ~20 grass 0  
fill ~1 ~-1 ~21 ~1 ~-1 ~21 grass 0  
fill ~1 ~-1 ~22 ~1 ~-1 ~22 grass 0  
fill ~1 ~-1 ~23 ~1 ~-1 ~23 grass 0  
fill ~1 ~-1 ~24 ~1 ~-1 ~24 grass 0  
fill ~1 ~-1 ~25 ~1 ~-1 ~25 grass 0  
fill ~1 ~-1 ~26 ~1 ~-1 ~26 grass 0  
fill ~1 ~-1 ~27 ~1 ~-1 ~27 grass 0  
fill ~1 ~-1 ~28 ~1 ~-1 ~28 grass 0  
fill ~1 ~-1 ~29 ~1 ~-1 ~29 grass 0  
fill ~1 ~-1 ~30 ~1 ~-1 ~30 grass 0  
fill ~1 ~-1 ~31 ~1 ~-1 ~31 grass 0  
fill ~1 ~-1 ~32 ~1 ~-1 ~32 grass 0  
fill ~1 ~-1 ~33 ~1 ~-1 ~33 grass 0  
fill ~1 ~-1 ~34 ~1 ~-1 ~34 grass 0  
fill ~1 ~-1 ~35 ~1 ~-1 ~35 grass 0 
setblock ~1 ~-1 ~36 double_stone_slab 0  
fill ~1 ~-1 ~37 ~1 ~-1 ~37 grass 0  
fill ~1 ~-1 ~38 ~1 ~-1 ~38 grass 0  
fill ~1 ~-1 ~39 ~1 ~-1 ~39 grass 0  
fill ~1 ~-1 ~40 ~1 ~-1 ~40 grass 0  
fill ~1 ~-1 ~41 ~1 ~-1 ~41 grass 0  
fill ~1 ~-1 ~42 ~1 ~-1 ~42 grass 0  
fill ~1 ~-1 ~43 ~1 ~-1 ~43 grass 0  
fill ~1 ~-1 ~44 ~1 ~-1 ~44 grass 0  
fill ~1 ~-1 ~45 ~1 ~-1 ~45 grass 0  
fill ~1 ~-1 ~46 ~1 ~-1 ~46 grass 0  
fill ~1 ~-1 ~47 ~1 ~-1 ~47 grass 0  
fill ~1 ~-1 ~48 ~1 ~-1 ~48 grass 0  
fill ~1 ~-1 ~49 ~1 ~-1 ~49 grass 0  
fill ~1 ~-1 ~50 ~1 ~-1 ~50 grass 0  
fill ~1 ~-1 ~51 ~1 ~-1 ~51 grass 0  
fill ~1 ~-1 ~52 ~1 ~-1 ~52 grass 0  
fill ~1 ~-1 ~53 ~1 ~-1 ~53 grass 0  
fill ~1 ~-1 ~54 ~1 ~-1 ~54 grass 0  
fill ~1 ~-1 ~55 ~1 ~-1 ~55 grass 0  
fill ~1 ~-1 ~56 ~1 ~-1 ~56 grass 0  
fill ~1 ~-1 ~57 ~1 ~-1 ~57 grass 0  
fill ~1 ~-1 ~58 ~1 ~-1 ~58 grass 0  
fill ~1 ~-1 ~59 ~1 ~-1 ~59 grass 0  
fill ~1 ~-1 ~60 ~1 ~-1 ~60 grass 0  
fill ~1 ~-1 ~61 ~1 ~-1 ~61 grass 0  
fill ~1 ~-1 ~62 ~1 ~-1 ~62 grass 0  
fill ~1 ~-1 ~63 ~1 ~-1 ~63 grass 0  
fill ~1 ~-1 ~64 ~1 ~-1 ~64 grass 0  
fill ~1 ~-1 ~65 ~1 ~-1 ~65 grass 0  
fill ~1 ~-1 ~66 ~1 ~-1 ~66 grass 0  
fill ~1 ~-1 ~67 ~1 ~-1 ~67 grass 0  
fill ~1 ~-1 ~68 ~61 ~-1 ~68 grass 0  
fill ~2 ~-1 ~1 ~68 ~-1 ~1 cobblestone 0  
fill ~2 ~-1 ~2 ~68 ~-1 ~2 cobblestone 0  
fill ~2 ~-1 ~3 ~68 ~-1 ~3 cobblestone 0  
fill ~2 ~-1 ~4 ~38 ~-1 ~4 cobblestone 0  
fill ~2 ~-1 ~5 ~37 ~-1 ~5 cobblestone 0  
fill ~2 ~-1 ~6 ~38 ~-1 ~6 cobblestone 0  
fill ~2 ~-1 ~7 ~38 ~-1 ~7 cobblestone 0  
fill ~2 ~-1 ~8 ~14 ~-1 ~8 cobblestone 0  
fill ~2 ~-1 ~9 ~12 ~-1 ~9 cobblestone 0  
fill ~2 ~-1 ~10 ~11 ~-1 ~10 cobblestone 0  
fill ~2 ~-1 ~11 ~10 ~-1 ~11 cobblestone 0  
fill ~2 ~-1 ~12 ~10 ~-1 ~12 cobblestone 0  
fill ~2 ~-1 ~13 ~10 ~-1 ~13 cobblestone 0  
fill ~2 ~-1 ~14 ~11 ~-1 ~14 cobblestone 0  
fill ~2 ~-1 ~15 ~11 ~-1 ~15 cobblestone 0  
fill ~2 ~-1 ~16 ~12 ~-1 ~16 cobblestone 0  
fill ~2 ~-1 ~17 ~13 ~-1 ~17 cobblestone 0  
fill ~2 ~-1 ~18 ~14 ~-1 ~18 cobblestone 0  
fill ~2 ~-1 ~19 ~38 ~-1 ~19 cobblestone 0  
fill ~2 ~-1 ~20 ~37 ~-1 ~20 cobblestone 0  
fill ~2 ~-1 ~21 ~38 ~-1 ~21 cobblestone 0  
fill ~2 ~-1 ~22 ~38 ~-1 ~22 cobblestone 0  
fill ~2 ~-1 ~23 ~38 ~-1 ~23 cobblestone 0  
fill ~2 ~-1 ~24 ~38 ~-1 ~24 cobblestone 0  
fill ~2 ~-1 ~25 ~38 ~-1 ~25 cobblestone 0  
fill ~2 ~-1 ~26 ~37 ~-1 ~26 cobblestone 0  
fill ~2 ~-1 ~27 ~38 ~-1 ~27 cobblestone 0  
fill ~2 ~-1 ~28 ~38 ~-1 ~28 cobblestone 0  
fill ~2 ~-1 ~29 ~37 ~-1 ~29 cobblestone 0  
fill ~2 ~-1 ~31 ~68 ~-1 ~31 cobblestone 0  
fill ~2 ~-1 ~33 ~68 ~-1 ~33 cobblestone 0  
fill ~2 ~-1 ~34 ~68 ~-1 ~34 cobblestone 0  
fill ~2 ~-1 ~35 ~68 ~-1 ~35 cobblestone 0  
fill ~2 ~-1 ~36 ~68 ~-1 ~36 cobblestone 0  
fill ~2 ~-1 ~37 ~5 ~-1 ~37 cobblestone 0  
fill ~2 ~-1 ~38 ~4 ~-1 ~38 cobblestone 0  
fill ~2 ~-1 ~39 ~5 ~-1 ~39 cobblestone 0  
fill ~2 ~-1 ~40 ~5 ~-1 ~40 cobblestone 0  
fill ~2 ~-1 ~41 ~4 ~-1 ~41 cobblestone 0  
fill ~2 ~-1 ~42 ~5 ~-1 ~42 cobblestone 0  
fill ~2 ~-1 ~44 ~5 ~-1 ~44 cobblestone 0  
fill ~2 ~-1 ~46 ~5 ~-1 ~46 cobblestone 0  
fill ~2 ~-1 ~47 ~4 ~-1 ~47 cobblestone 0  
fill ~2 ~-1 ~48 ~5 ~-1 ~48 cobblestone 0  
fill ~2 ~-1 ~49 ~5 ~-1 ~49 cobblestone 0  
fill ~2 ~-1 ~50 ~5 ~-1 ~50 cobblestone 0  
fill ~2 ~-1 ~51 ~5 ~-1 ~51 cobblestone 0  
fill ~2 ~-1 ~52 ~5 ~-1 ~52 cobblestone 0  
fill ~2 ~-1 ~53 ~4 ~-1 ~53 cobblestone 0  
fill ~2 ~-1 ~54 ~5 ~-1 ~54 cobblestone 0  
fill ~2 ~-1 ~55 ~5 ~-1 ~55 cobblestone 0  
fill ~2 ~-1 ~56 ~5 ~-1 ~56 cobblestone 0  
fill ~2 ~-1 ~57 ~5 ~-1 ~57 cobblestone 0  
fill ~2 ~-1 ~58 ~5 ~-1 ~58 cobblestone 0  
fill ~2 ~-1 ~59 ~4 ~-1 ~59 cobblestone 0  
fill ~2 ~-1 ~60 ~5 ~-1 ~60 cobblestone 0  
fill ~2 ~-1 ~61 ~5 ~-1 ~61 cobblestone 0  
fill ~2 ~-1 ~62 ~4 ~-1 ~62 cobblestone 0  
fill ~2 ~-1 ~63 ~5 ~-1 ~63 cobblestone 0  
fill ~2 ~-1 ~64 ~68 ~-1 ~64 cobblestone 0  
fill ~2 ~-1 ~65 ~68 ~-1 ~65 cobblestone 0  
fill ~2 ~-1 ~66 ~68 ~-1 ~66 cobblestone 0  
fill ~2 ~-1 ~67 ~68 ~-1 ~67 cobblestone 0  
fill ~3 ~-1 ~30 ~38 ~-1 ~30 cobblestone 0  
fill ~3 ~-1 ~32 ~68 ~-1 ~32 cobblestone 0  
fill ~3 ~-1 ~43 ~5 ~-1 ~43 cobblestone 0  
fill ~3 ~-1 ~45 ~5 ~-1 ~45 cobblestone 0  
fill ~4 ~-1 ~0 ~6 ~-1 ~0 sand 0  
fill ~5 ~-1 ~38 ~6 ~-1 ~38 dirt 0  
fill ~5 ~-1 ~41 ~6 ~-1 ~41 dirt 0  
fill ~5 ~-1 ~53 ~6 ~-1 ~53 dirt 0  
fill ~5 ~-1 ~59 ~6 ~-1 ~59 dirt 0 
setblock ~6 ~-1 ~37 dirt 0  
fill ~6 ~-1 ~39 ~6 ~-1 ~40 stone 0  
fill ~6 ~-1 ~42 ~6 ~-1 ~46 stone 0 
setblock ~6 ~-1 ~47 dirt 0  
fill ~6 ~-1 ~48 ~6 ~-1 ~52 stone 0  
fill ~6 ~-1 ~54 ~6 ~-1 ~58 stone 0  
fill ~6 ~-1 ~60 ~6 ~-1 ~62 stone 0 
setblock ~6 ~-1 ~63 dirt 0  
fill ~7 ~-1 ~0 ~69 ~-1 ~0 grass 0  
fill ~7 ~-1 ~37 ~8 ~-1 ~37 cobblestone 0  
fill ~7 ~-1 ~38 ~8 ~-1 ~38 stone 0  
fill ~7 ~-1 ~39 ~29 ~-1 ~39 iron_block 0  
fill ~7 ~-1 ~40 ~7 ~-1 ~61 iron_block 0  
fill ~7 ~-1 ~62 ~8 ~-1 ~62 stone 0  
fill ~7 ~-1 ~63 ~8 ~-1 ~63 cobblestone 0  
fill ~8 ~-1 ~40 ~28 ~-1 ~40 wool 13  
fill ~8 ~-1 ~41 ~28 ~-1 ~41 wool 13  
fill ~8 ~-1 ~42 ~28 ~-1 ~42 wool 13  
fill ~8 ~-1 ~43 ~28 ~-1 ~43 wool 13  
fill ~8 ~-1 ~44 ~11 ~-1 ~44 wool 13  
fill ~8 ~-1 ~45 ~11 ~-1 ~45 wool 13  
fill ~8 ~-1 ~46 ~11 ~-1 ~46 wool 13  
fill ~8 ~-1 ~47 ~11 ~-1 ~47 wool 13  
fill ~8 ~-1 ~48 ~11 ~-1 ~48 wool 13  
fill ~8 ~-1 ~49 ~11 ~-1 ~49 wool 13  
fill ~8 ~-1 ~50 ~11 ~-1 ~50 wool 13  
fill ~8 ~-1 ~51 ~11 ~-1 ~51 wool 13  
fill ~8 ~-1 ~52 ~11 ~-1 ~52 wool 13  
fill ~8 ~-1 ~53 ~11 ~-1 ~53 wool 13  
fill ~8 ~-1 ~54 ~11 ~-1 ~54 wool 13  
fill ~8 ~-1 ~55 ~11 ~-1 ~55 wool 13  
fill ~8 ~-1 ~56 ~11 ~-1 ~56 wool 13  
fill ~8 ~-1 ~57 ~28 ~-1 ~57 wool 13  
fill ~8 ~-1 ~58 ~28 ~-1 ~58 wool 13  
fill ~8 ~-1 ~59 ~28 ~-1 ~59 wool 13  
fill ~8 ~-1 ~60 ~28 ~-1 ~60 wool 13  
fill ~8 ~-1 ~61 ~29 ~-1 ~61 iron_block 0  
fill ~9 ~-1 ~37 ~9 ~-1 ~38 dirt 0 
setblock ~9 ~-1 ~62 dirt 0  
fill ~9 ~-1 ~63 ~9 ~113 ~63 stone 0  
fill ~10 ~-1 ~37 ~14 ~-1 ~37 cobblestone 0  
fill ~10 ~-1 ~38 ~14 ~-1 ~38 stone 0  
fill ~10 ~-1 ~62 ~30 ~-1 ~62 stone 0  
fill ~10 ~-1 ~63 ~14 ~-1 ~63 cobblestone 0  
fill ~11 ~-1 ~11 ~19 ~-1 ~11 stonebrick 0  
fill ~11 ~-1 ~12 ~20 ~-1 ~12 stonebrick 0  
fill ~11 ~-1 ~13 ~20 ~-1 ~13 stonebrick 0  
fill ~12 ~-1 ~10 ~19 ~-1 ~10 stonebrick 0  
fill ~12 ~-1 ~14 ~19 ~-1 ~14 stonebrick 0  
fill ~12 ~-1 ~15 ~19 ~-1 ~15 stonebrick 0  
fill ~12 ~-1 ~44 ~24 ~-1 ~44 iron_block 0  
fill ~12 ~-1 ~45 ~12 ~-1 ~56 iron_block 0  
fill ~13 ~-1 ~9 ~18 ~-1 ~9 stonebrick 0  
fill ~13 ~-1 ~16 ~18 ~-1 ~16 stonebrick 0 
setblock ~13 ~-1 ~50 iron_block 0  
fill ~13 ~-1 ~52 ~13 ~-1 ~56 iron_block 0 
setblock ~14 ~-1 ~17 iron_block 0  
fill ~14 ~-1 ~53 ~25 ~-1 ~53 iron_block 0  
fill ~14 ~-1 ~54 ~14 ~119 ~54 iron_block 0  
fill ~14 ~-1 ~55 ~24 ~-1 ~55 iron_block 0  
fill ~14 ~-1 ~56 ~24 ~-1 ~56 iron_block 0  
fill ~15 ~-1 ~8 ~16 ~-1 ~8 stonebrick 0  
fill ~15 ~-1 ~17 ~16 ~-1 ~17 stonebrick 0  
fill ~15 ~-1 ~18 ~16 ~-1 ~18 stonebrick 0  
fill ~15 ~-1 ~37 ~15 ~-1 ~38 dirt 0 
setblock ~15 ~-1 ~63 dirt 0  
fill ~16 ~-1 ~37 ~20 ~-1 ~37 cobblestone 0  
fill ~16 ~-1 ~38 ~20 ~-1 ~38 stone 0  
fill ~16 ~-1 ~63 ~20 ~-1 ~63 cobblestone 0  
fill ~17 ~-1 ~8 ~37 ~-1 ~8 cobblestone 0 
setblock ~17 ~-1 ~17 iron_block 0  
fill ~17 ~-1 ~18 ~38 ~-1 ~18 cobblestone 0 
setblock ~18 ~-1 ~17 cobblestone 0  
fill ~19 ~-1 ~9 ~38 ~-1 ~9 cobblestone 0  
fill ~19 ~-1 ~16 ~38 ~-1 ~16 cobblestone 0  
fill ~20 ~-1 ~10 ~38 ~-1 ~10 cobblestone 0  
fill ~20 ~-1 ~11 ~38 ~-1 ~11 cobblestone 0  
fill ~20 ~-1 ~14 ~37 ~-1 ~14 cobblestone 0  
fill ~20 ~-1 ~15 ~38 ~-1 ~15 cobblestone 0  
fill ~20 ~-1 ~17 ~38 ~-1 ~17 cobblestone 0  
fill ~21 ~-1 ~12 ~38 ~-1 ~12 cobblestone 0  
fill ~21 ~-1 ~13 ~38 ~-1 ~13 cobblestone 0  
fill ~21 ~-1 ~37 ~21 ~-1 ~38 dirt 0  
fill ~21 ~-1 ~63 ~21 ~113 ~63 stone 0  
fill ~22 ~-1 ~37 ~26 ~-1 ~37 cobblestone 0  
fill ~22 ~-1 ~38 ~26 ~-1 ~38 stone 0  
fill ~22 ~-1 ~54 ~29 ~-1 ~54 iron_block 0  
fill ~22 ~-1 ~63 ~26 ~-1 ~63 cobblestone 0  
fill ~23 ~-1 ~50 ~25 ~-1 ~50 iron_block 0  
fill ~23 ~-1 ~52 ~25 ~-1 ~52 iron_block 0  
fill ~24 ~-1 ~45 ~24 ~-1 ~56 iron_block 0  
fill ~25 ~-1 ~44 ~28 ~-1 ~44 wool 13  
fill ~25 ~-1 ~45 ~28 ~-1 ~45 wool 13  
fill ~25 ~-1 ~46 ~28 ~-1 ~46 wool 13  
fill ~25 ~-1 ~47 ~28 ~-1 ~47 wool 13  
fill ~25 ~-1 ~48 ~28 ~-1 ~48 wool 13  
fill ~25 ~-1 ~49 ~29 ~-1 ~49 iron_block 0 
setblock ~25 ~-1 ~51 iron_block 0  
fill ~25 ~-1 ~55 ~28 ~-1 ~55 wool 13  
fill ~25 ~-1 ~56 ~28 ~-1 ~56 wool 13  
fill ~26 ~-1 ~53 ~27 ~-1 ~53 stone_brick_stairs 2  
fill ~27 ~-1 ~37 ~27 ~-1 ~38 dirt 0 
setblock ~27 ~-1 ~63 dirt 0  
fill ~28 ~-1 ~37 ~29 ~-1 ~37 cobblestone 0  
fill ~28 ~-1 ~38 ~30 ~-1 ~38 stone 0  
fill ~28 ~-1 ~50 ~29 ~-1 ~50 iron_block 0  
fill ~28 ~-1 ~51 ~29 ~-1 ~51 iron_block 0  
fill ~28 ~-1 ~52 ~29 ~-1 ~52 iron_block 0  
fill ~28 ~-1 ~53 ~29 ~-1 ~53 iron_block 0  
fill ~28 ~-1 ~63 ~29 ~-1 ~63 cobblestone 0  
fill ~29 ~-1 ~40 ~29 ~-1 ~61 iron_block 0 
setblock ~30 ~-1 ~37 dirt 0  
fill ~30 ~-1 ~39 ~30 ~-1 ~58 stone 0  
fill ~30 ~-1 ~59 ~31 ~-1 ~59 dirt 0  
fill ~30 ~-1 ~60 ~30 ~-1 ~62 stone 0 
setblock ~30 ~-1 ~63 dirt 0  
fill ~31 ~-1 ~37 ~68 ~-1 ~37 cobblestone 0 
setblock ~31 ~-1 ~38 dirt 0  
fill ~31 ~-1 ~39 ~68 ~-1 ~39 cobblestone 0  
fill ~31 ~-1 ~40 ~68 ~-1 ~40 cobblestone 0 
setblock ~31 ~-1 ~41 dirt 0  
fill ~31 ~-1 ~42 ~68 ~-1 ~42 cobblestone 0  
fill ~31 ~-1 ~43 ~68 ~-1 ~43 cobblestone 0  
fill ~31 ~-1 ~44 ~68 ~-1 ~44 cobblestone 0  
fill ~31 ~-1 ~45 ~68 ~-1 ~45 cobblestone 0  
fill ~31 ~-1 ~46 ~68 ~-1 ~46 cobblestone 0 
setblock ~31 ~-1 ~47 dirt 0  
fill ~31 ~-1 ~48 ~68 ~-1 ~48 cobblestone 0  
fill ~31 ~-1 ~49 ~68 ~-1 ~49 cobblestone 0  
fill ~31 ~-1 ~50 ~68 ~-1 ~50 cobblestone 0  
fill ~31 ~-1 ~51 ~68 ~-1 ~51 cobblestone 0  
fill ~31 ~-1 ~52 ~68 ~-1 ~52 cobblestone 0 
setblock ~31 ~-1 ~53 dirt 0  
fill ~31 ~-1 ~54 ~68 ~-1 ~54 cobblestone 0  
fill ~31 ~-1 ~55 ~68 ~-1 ~55 cobblestone 0  
fill ~31 ~-1 ~56 ~68 ~-1 ~56 cobblestone 0  
fill ~31 ~-1 ~57 ~68 ~-1 ~57 cobblestone 0  
fill ~31 ~-1 ~58 ~68 ~-1 ~58 cobblestone 0  
fill ~31 ~-1 ~60 ~68 ~-1 ~60 cobblestone 0  
fill ~31 ~-1 ~61 ~68 ~-1 ~61 cobblestone 0  
fill ~31 ~-1 ~63 ~68 ~-1 ~63 cobblestone 0  
fill ~32 ~-1 ~38 ~68 ~-1 ~38 cobblestone 0  
fill ~32 ~-1 ~41 ~68 ~-1 ~41 cobblestone 0  
fill ~32 ~-1 ~47 ~68 ~-1 ~47 cobblestone 0  
fill ~32 ~-1 ~53 ~68 ~-1 ~53 cobblestone 0  
fill ~32 ~-1 ~59 ~68 ~-1 ~59 cobblestone 0  
fill ~32 ~-1 ~62 ~68 ~-1 ~62 cobblestone 0 
setblock ~38 ~-1 ~5 dirt 0 
setblock ~38 ~-1 ~8 dirt 0 
setblock ~38 ~-1 ~14 dirt 0 
setblock ~38 ~-1 ~20 dirt 0 
setblock ~38 ~-1 ~26 dirt 0 
setblock ~38 ~-1 ~29 dirt 0 
setblock ~39 ~-1 ~4 dirt 0  
fill ~39 ~-1 ~5 ~63 ~-1 ~5 stone 0  
fill ~39 ~-1 ~6 ~39 ~-1 ~29 stone 0 
setblock ~39 ~-1 ~30 dirt 0  
fill ~40 ~-1 ~4 ~41 ~-1 ~4 cobblestone 0  
fill ~40 ~-1 ~6 ~62 ~-1 ~6 iron_block 0  
fill ~40 ~-1 ~7 ~40 ~-1 ~28 iron_block 0  
fill ~40 ~-1 ~29 ~63 ~-1 ~29 stone 0  
fill ~40 ~-1 ~30 ~41 ~-1 ~30 cobblestone 0  
fill ~41 ~-1 ~7 ~61 ~-1 ~7 wool 13  
fill ~41 ~-1 ~8 ~61 ~-1 ~8 wool 13  
fill ~41 ~-1 ~9 ~61 ~-1 ~9 wool 13  
fill ~41 ~-1 ~10 ~61 ~-1 ~10 wool 13  
fill ~41 ~-1 ~11 ~44 ~-1 ~11 wool 13  
fill ~41 ~-1 ~12 ~44 ~-1 ~12 wool 13  
fill ~41 ~-1 ~13 ~44 ~-1 ~13 wool 13  
fill ~41 ~-1 ~14 ~44 ~-1 ~14 wool 13  
fill ~41 ~-1 ~15 ~44 ~-1 ~15 wool 13  
fill ~41 ~-1 ~16 ~44 ~-1 ~16 wool 13  
fill ~41 ~-1 ~17 ~44 ~-1 ~17 wool 13  
fill ~41 ~-1 ~18 ~44 ~-1 ~18 wool 13  
fill ~41 ~-1 ~19 ~44 ~-1 ~19 wool 13  
fill ~41 ~-1 ~20 ~44 ~-1 ~20 wool 13  
fill ~41 ~-1 ~21 ~44 ~-1 ~21 wool 13  
fill ~41 ~-1 ~22 ~44 ~-1 ~22 wool 13  
fill ~41 ~-1 ~23 ~44 ~-1 ~23 wool 13  
fill ~41 ~-1 ~24 ~49 ~-1 ~24 wool 13  
fill ~41 ~-1 ~25 ~49 ~-1 ~25 wool 13  
fill ~41 ~-1 ~26 ~49 ~-1 ~26 wool 13  
fill ~41 ~-1 ~27 ~49 ~-1 ~27 wool 13  
fill ~41 ~-1 ~28 ~62 ~-1 ~28 iron_block 0 
setblock ~42 ~-1 ~4 dirt 0 
setblock ~42 ~-1 ~30 dirt 0  
fill ~43 ~-1 ~4 ~47 ~-1 ~4 cobblestone 0  
fill ~43 ~-1 ~30 ~47 ~-1 ~30 cobblestone 0  
fill ~45 ~-1 ~11 ~57 ~-1 ~11 iron_block 0  
fill ~45 ~-1 ~12 ~45 ~-1 ~23 iron_block 0  
fill ~46 ~-1 ~23 ~57 ~-1 ~23 iron_block 0 
setblock ~48 ~-1 ~4 dirt 0 
setblock ~48 ~-1 ~30 dirt 0  
fill ~49 ~-1 ~4 ~53 ~-1 ~4 cobblestone 0  
fill ~49 ~-1 ~30 ~59 ~-1 ~30 cobblestone 0  
fill ~50 ~-1 ~24 ~55 ~-1 ~24 iron_block 0  
fill ~50 ~-1 ~25 ~50 ~-1 ~28 iron_block 0 
setblock ~51 ~-1 ~12 iron_block 0 
setblock ~51 ~-1 ~22 iron_block 0  
fill ~51 ~-1 ~27 ~55 ~-1 ~27 iron_block 0  
fill ~53 ~-1 ~12 ~57 ~-1 ~12 iron_block 0  
fill ~53 ~-1 ~22 ~57 ~-1 ~22 iron_block 0 
setblock ~54 ~-1 ~4 dirt 0  
fill ~54 ~-1 ~13 ~57 ~-1 ~13 iron_block 0  
fill ~54 ~-1 ~15 ~57 ~-1 ~15 iron_block 0  
fill ~54 ~-1 ~17 ~57 ~-1 ~17 iron_block 0  
fill ~54 ~-1 ~19 ~57 ~-1 ~19 iron_block 0  
fill ~54 ~-1 ~21 ~57 ~-1 ~21 iron_block 0  
fill ~54 ~-1 ~25 ~54 ~-1 ~26 stone_brick_stairs 0  
fill ~55 ~-1 ~4 ~59 ~-1 ~4 cobblestone 0  
fill ~55 ~-1 ~25 ~55 ~-1 ~28 iron_block 0  
fill ~56 ~-1 ~24 ~61 ~-1 ~24 wool 13  
fill ~56 ~-1 ~25 ~61 ~-1 ~25 wool 13  
fill ~56 ~-1 ~26 ~61 ~-1 ~26 wool 13  
fill ~56 ~-1 ~27 ~61 ~-1 ~27 wool 13 
setblock ~57 ~-1 ~14 iron_block 0 
setblock ~57 ~-1 ~16 iron_block 0 
setblock ~57 ~-1 ~18 iron_block 0 
setblock ~57 ~-1 ~20 iron_block 0  
fill ~58 ~-1 ~11 ~61 ~-1 ~11 wool 13  
fill ~58 ~-1 ~12 ~61 ~-1 ~12 wool 13  
fill ~58 ~-1 ~13 ~61 ~-1 ~13 wool 13  
fill ~58 ~-1 ~14 ~61 ~-1 ~14 wool 13  
fill ~58 ~-1 ~15 ~61 ~-1 ~15 wool 13  
fill ~58 ~-1 ~16 ~61 ~-1 ~16 wool 13  
fill ~58 ~-1 ~17 ~61 ~-1 ~17 wool 13  
fill ~58 ~-1 ~18 ~61 ~-1 ~18 wool 13  
fill ~58 ~-1 ~19 ~61 ~-1 ~19 wool 13  
fill ~58 ~-1 ~20 ~61 ~-1 ~20 wool 13  
fill ~58 ~-1 ~21 ~61 ~-1 ~21 wool 13  
fill ~58 ~-1 ~22 ~61 ~-1 ~22 wool 13  
fill ~58 ~-1 ~23 ~61 ~-1 ~23 wool 13 
setblock ~60 ~-1 ~4 dirt 0 
setblock ~60 ~-1 ~30 dirt 0  
fill ~61 ~-1 ~4 ~62 ~-1 ~4 cobblestone 0  
fill ~61 ~-1 ~30 ~62 ~-1 ~30 cobblestone 0  
fill ~62 ~-1 ~7 ~62 ~-1 ~28 iron_block 0 
setblock ~62 ~-1 ~68 cobblestone 0 
setblock ~63 ~-1 ~4 dirt 0  
fill ~63 ~-1 ~6 ~63 ~-1 ~29 stone 0 
setblock ~63 ~-1 ~30 dirt 0  
fill ~63 ~-1 ~68 ~69 ~-1 ~68 grass 0  
fill ~64 ~-1 ~4 ~68 ~-1 ~4 cobblestone 0 
setblock ~64 ~-1 ~5 dirt 0  
fill ~64 ~-1 ~6 ~68 ~-1 ~6 cobblestone 0  
fill ~64 ~-1 ~7 ~68 ~-1 ~7 cobblestone 0  
fill ~64 ~-1 ~8 ~64 ~-3 ~8 dirt 0  
fill ~64 ~-1 ~9 ~68 ~-1 ~9 cobblestone 0  
fill ~64 ~-1 ~10 ~68 ~-1 ~10 cobblestone 0  
fill ~64 ~-1 ~11 ~64 ~-1 ~13 cobblestone 0  
fill ~64 ~-1 ~14 ~64 ~-3 ~14 dirt 0  
fill ~64 ~-1 ~15 ~68 ~-1 ~15 cobblestone 0  
fill ~64 ~-1 ~16 ~68 ~-1 ~16 cobblestone 0  
fill ~64 ~-1 ~17 ~68 ~-1 ~17 cobblestone 0  
fill ~64 ~-1 ~18 ~68 ~-1 ~18 cobblestone 0  
fill ~64 ~-1 ~19 ~68 ~-1 ~19 cobblestone 0  
fill ~64 ~-1 ~20 ~64 ~-3 ~20 dirt 0  
fill ~64 ~-1 ~21 ~68 ~-1 ~21 cobblestone 0  
fill ~64 ~-1 ~22 ~68 ~-1 ~22 cobblestone 0  
fill ~64 ~-1 ~23 ~68 ~-1 ~23 cobblestone 0  
fill ~64 ~-1 ~24 ~68 ~-1 ~24 cobblestone 0  
fill ~64 ~-1 ~25 ~68 ~-1 ~25 cobblestone 0  
fill ~64 ~-1 ~26 ~64 ~-3 ~26 dirt 0  
fill ~64 ~-1 ~27 ~68 ~-1 ~27 cobblestone 0  
fill ~64 ~-1 ~28 ~68 ~-1 ~28 cobblestone 0 
setblock ~64 ~-1 ~29 dirt 0  
fill ~64 ~-1 ~30 ~68 ~-1 ~30 cobblestone 0  
fill ~65 ~-1 ~5 ~68 ~-1 ~5 cobblestone 0  
fill ~65 ~-1 ~8 ~68 ~-1 ~8 cobblestone 0  
fill ~65 ~-1 ~12 ~68 ~-1 ~12 cobblestone 0  
fill ~65 ~-1 ~13 ~68 ~-1 ~13 cobblestone 0  
fill ~65 ~-1 ~14 ~68 ~-1 ~14 cobblestone 0  
fill ~65 ~-1 ~20 ~68 ~-1 ~20 cobblestone 0  
fill ~65 ~-1 ~26 ~68 ~-1 ~26 cobblestone 0  
fill ~65 ~-1 ~29 ~68 ~-1 ~29 cobblestone 0  
fill ~66 ~-1 ~11 ~68 ~-1 ~11 cobblestone 0  
fill ~69 ~-1 ~1 ~69 ~-1 ~1 grass 0  
fill ~69 ~-1 ~2 ~69 ~-1 ~2 grass 0  
fill ~69 ~-1 ~3 ~69 ~-1 ~3 grass 0  
fill ~69 ~-1 ~4 ~69 ~-1 ~4 grass 0  
fill ~69 ~-1 ~5 ~69 ~-1 ~5 grass 0  
fill ~69 ~-1 ~6 ~69 ~-1 ~6 grass 0  
fill ~69 ~-1 ~7 ~69 ~-1 ~7 grass 0  
fill ~69 ~-1 ~8 ~69 ~-1 ~8 grass 0  
fill ~69 ~-1 ~9 ~69 ~-1 ~9 grass 0  
fill ~69 ~-1 ~10 ~69 ~-1 ~10 grass 0  
fill ~69 ~-1 ~11 ~69 ~-1 ~11 grass 0  
fill ~69 ~-1 ~12 ~69 ~-1 ~12 grass 0  
fill ~69 ~-1 ~13 ~69 ~-1 ~13 grass 0  
fill ~69 ~-1 ~14 ~69 ~-1 ~14 grass 0  
fill ~69 ~-1 ~15 ~69 ~-1 ~15 grass 0  
fill ~69 ~-1 ~16 ~69 ~-1 ~16 grass 0  
fill ~69 ~-1 ~17 ~69 ~-1 ~17 grass 0  
fill ~69 ~-1 ~18 ~69 ~-1 ~18 grass 0  
fill ~69 ~-1 ~19 ~69 ~-1 ~19 grass 0  
fill ~69 ~-1 ~20 ~69 ~-1 ~20 grass 0  
fill ~69 ~-1 ~21 ~69 ~-1 ~21 grass 0  
fill ~69 ~-1 ~22 ~69 ~-1 ~22 grass 0  
fill ~69 ~-1 ~23 ~69 ~-1 ~23 grass 0  
fill ~69 ~-1 ~24 ~69 ~-1 ~24 grass 0  
fill ~69 ~-1 ~25 ~69 ~-1 ~25 grass 0  
fill ~69 ~-1 ~26 ~69 ~-1 ~26 grass 0  
fill ~69 ~-1 ~27 ~69 ~-1 ~27 grass 0  
fill ~69 ~-1 ~28 ~69 ~-1 ~28 grass 0  
fill ~69 ~-1 ~29 ~69 ~-1 ~29 grass 0  
fill ~69 ~-1 ~30 ~69 ~-1 ~30 grass 0  
fill ~69 ~-1 ~31 ~69 ~-1 ~31 grass 0  
fill ~69 ~-1 ~32 ~69 ~-1 ~32 grass 0  
fill ~69 ~-1 ~33 ~69 ~-1 ~33 grass 0  
fill ~69 ~-1 ~34 ~69 ~-1 ~34 grass 0  
fill ~69 ~-1 ~35 ~69 ~-1 ~35 grass 0  
fill ~69 ~-1 ~36 ~69 ~-1 ~36 grass 0  
fill ~69 ~-1 ~37 ~69 ~-1 ~37 grass 0  
fill ~69 ~-1 ~38 ~69 ~-1 ~38 grass 0  
fill ~69 ~-1 ~39 ~69 ~-1 ~39 grass 0  
fill ~69 ~-1 ~40 ~69 ~-1 ~40 grass 0  
fill ~69 ~-1 ~41 ~69 ~-1 ~41 grass 0  
fill ~69 ~-1 ~42 ~69 ~-1 ~42 grass 0  
fill ~69 ~-1 ~43 ~69 ~-1 ~43 grass 0  
fill ~69 ~-1 ~44 ~69 ~-1 ~44 grass 0  
fill ~69 ~-1 ~45 ~69 ~-1 ~45 grass 0  
fill ~69 ~-1 ~46 ~69 ~-1 ~46 grass 0  
fill ~69 ~-1 ~47 ~69 ~-1 ~47 grass 0  
fill ~69 ~-1 ~48 ~69 ~-1 ~48 grass 0  
fill ~69 ~-1 ~49 ~69 ~-1 ~49 grass 0  
fill ~69 ~-1 ~50 ~69 ~-1 ~50 grass 0 
setblock ~69 ~-1 ~51 double_stone_slab 0  
fill ~69 ~-1 ~52 ~69 ~-1 ~52 grass 0  
fill ~69 ~-1 ~53 ~69 ~-1 ~53 grass 0  
fill ~69 ~-1 ~54 ~69 ~-1 ~54 grass 0  
fill ~69 ~-1 ~55 ~69 ~-1 ~55 grass 0  
fill ~69 ~-1 ~56 ~69 ~-1 ~56 grass 0  
fill ~69 ~-1 ~57 ~69 ~-1 ~57 grass 0  
fill ~69 ~-1 ~58 ~69 ~-1 ~58 grass 0  
fill ~69 ~-1 ~59 ~69 ~-1 ~59 grass 0  
fill ~69 ~-1 ~60 ~69 ~-1 ~60 grass 0  
fill ~69 ~-1 ~61 ~69 ~-1 ~61 grass 0  
fill ~69 ~-1 ~62 ~69 ~-1 ~62 grass 0  
fill ~69 ~-1 ~63 ~69 ~-1 ~63 grass 0  
fill ~69 ~-1 ~64 ~69 ~-1 ~64 grass 0  
fill ~69 ~-1 ~65 ~69 ~-1 ~65 grass 0  
fill ~69 ~-1 ~66 ~69 ~-1 ~66 grass 0  
fill ~69 ~-1 ~67 ~69 ~-1 ~67 grass 0  
fill ~1 ~0 ~0 ~69 ~0 ~0 stone_slab 0  
fill ~1 ~0 ~1 ~1 ~0 ~68 stone_slab 0  
fill ~2 ~0 ~68 ~69 ~0 ~68 stone_slab 0  
fill ~5 ~0 ~38 ~5 ~121 ~38 double_stone_slab 0  
fill ~5 ~0 ~41 ~6 ~0 ~41 stone 0  
fill ~5 ~0 ~47 ~6 ~0 ~47 stone 0  
fill ~5 ~0 ~53 ~6 ~0 ~53 stone 0  
fill ~5 ~0 ~59 ~6 ~0 ~59 stone 0  
fill ~5 ~0 ~62 ~5 ~121 ~62 double_stone_slab 0  
fill ~6 ~0 ~3 ~6 ~3 ~3 fence 0 
setblock ~6 ~0 ~11 jungle_stairs 7  
fill ~6 ~0 ~12 ~6 ~0 ~13 wooden_slab 11 
setblock ~6 ~0 ~14 jungle_stairs 6  
fill ~6 ~0 ~22 ~6 ~3 ~22 fence 0  
fill ~6 ~0 ~37 ~6 ~121 ~37 double_stone_slab 0 
setblock ~6 ~0 ~38 stone 0  
fill ~6 ~0 ~39 ~6 ~3 ~39 glass 0  
fill ~6 ~0 ~40 ~6 ~3 ~40 glass 0  
fill ~6 ~0 ~42 ~6 ~3 ~42 glass 0  
fill ~6 ~0 ~43 ~6 ~3 ~43 glass 0  
fill ~6 ~0 ~45 ~6 ~3 ~45 glass 0  
fill ~6 ~0 ~46 ~6 ~3 ~46 glass 0  
fill ~6 ~0 ~48 ~6 ~3 ~48 glass 0  
fill ~6 ~0 ~49 ~6 ~3 ~49 glass 0  
fill ~6 ~0 ~51 ~6 ~3 ~51 glass 0  
fill ~6 ~0 ~52 ~6 ~3 ~52 glass 0  
fill ~6 ~0 ~54 ~6 ~3 ~54 glass 0  
fill ~6 ~0 ~55 ~6 ~3 ~55 glass 0  
fill ~6 ~0 ~57 ~6 ~3 ~57 glass 0  
fill ~6 ~0 ~58 ~6 ~3 ~58 glass 0  
fill ~6 ~0 ~60 ~6 ~3 ~60 glass 0  
fill ~6 ~0 ~61 ~6 ~3 ~61 glass 0  
fill ~6 ~0 ~63 ~6 ~121 ~63 double_stone_slab 0  
fill ~7 ~0 ~5 ~7 ~0 ~6 trapdoor 6  
fill ~7 ~0 ~19 ~7 ~0 ~20 trapdoor 6  
fill ~7 ~0 ~38 ~8 ~0 ~38 glass 0 
setblock ~7 ~0 ~40 trapdoor 4 
setblock ~7 ~0 ~41 dirt 0 
setblock ~7 ~0 ~42 trapdoor 5 
setblock ~7 ~0 ~46 trapdoor 4 
setblock ~7 ~0 ~47 dirt 0 
setblock ~7 ~0 ~48 trapdoor 5 
setblock ~7 ~0 ~52 trapdoor 4 
setblock ~7 ~0 ~53 dirt 0 
setblock ~7 ~0 ~54 trapdoor 5 
setblock ~7 ~0 ~58 trapdoor 4 
setblock ~7 ~0 ~59 dirt 0 
setblock ~7 ~0 ~60 trapdoor 5  
fill ~7 ~0 ~62 ~8 ~0 ~62 glass 0  
fill ~8 ~0 ~4 ~9 ~0 ~4 trapdoor 4  
fill ~8 ~0 ~5 ~9 ~0 ~5 dirt 0  
fill ~8 ~0 ~6 ~9 ~0 ~6 dirt 0  
fill ~8 ~0 ~7 ~9 ~0 ~7 trapdoor 5  
fill ~8 ~0 ~18 ~9 ~0 ~18 trapdoor 4  
fill ~8 ~0 ~19 ~9 ~0 ~19 dirt 0  
fill ~8 ~0 ~20 ~9 ~0 ~20 dirt 0  
fill ~8 ~0 ~21 ~9 ~0 ~21 trapdoor 5 
setblock ~8 ~0 ~39 trapdoor 6 
setblock ~8 ~0 ~41 trapdoor 7 
setblock ~8 ~0 ~47 trapdoor 7 
setblock ~8 ~0 ~53 trapdoor 7 
setblock ~8 ~0 ~59 trapdoor 7 
setblock ~8 ~0 ~61 trapdoor 6  
fill ~9 ~0 ~37 ~9 ~113 ~37 stone 0  
fill ~9 ~0 ~38 ~9 ~8 ~38 stone 0 
setblock ~9 ~0 ~39 dirt 0 
setblock ~9 ~0 ~40 trapdoor 5 
setblock ~9 ~0 ~60 trapdoor 4 
setblock ~9 ~0 ~61 dirt 0  
fill ~9 ~0 ~62 ~9 ~8 ~62 stone 0  
fill ~10 ~0 ~5 ~10 ~0 ~6 trapdoor 7  
fill ~10 ~0 ~12 ~11 ~0 ~12 stonebrick 0  
fill ~10 ~0 ~13 ~11 ~0 ~13 stonebrick 0  
fill ~10 ~0 ~19 ~10 ~0 ~20 trapdoor 7  
fill ~10 ~0 ~38 ~11 ~0 ~38 glass 0 
setblock ~10 ~0 ~39 trapdoor 7 
setblock ~10 ~0 ~61 trapdoor 7  
fill ~10 ~0 ~62 ~11 ~0 ~62 glass 0  
fill ~11 ~0 ~10 ~12 ~0 ~10 stonebrick 0  
fill ~11 ~0 ~11 ~11 ~-1 ~11 stonebrick 0  
fill ~11 ~0 ~14 ~11 ~0 ~15 stonebrick 0  
fill ~12 ~0 ~9 ~13 ~0 ~9 stonebrick 0  
fill ~12 ~0 ~11 ~12 ~0 ~14 water 2  
fill ~12 ~0 ~15 ~12 ~-1 ~15 stonebrick 0  
fill ~12 ~0 ~16 ~13 ~0 ~16 stonebrick 0  
fill ~12 ~0 ~44 ~24 ~0 ~44 glass_pane 0  
fill ~12 ~0 ~45 ~12 ~0 ~49 glass_pane 0  
fill ~13 ~0 ~8 ~18 ~0 ~8 stonebrick 0 
setblock ~13 ~0 ~10 water 2  
fill ~13 ~0 ~11 ~13 ~0 ~14 water 1 
setblock ~13 ~0 ~15 water 2  
fill ~13 ~0 ~17 ~18 ~0 ~17 stonebrick 0  
fill ~13 ~0 ~38 ~14 ~0 ~38 glass 0  
fill ~13 ~0 ~50 ~13 ~3 ~50 glass_pane 0  
fill ~13 ~0 ~52 ~13 ~3 ~52 glass_pane 0  
fill ~13 ~0 ~53 ~23 ~0 ~53 iron_block 0  
fill ~13 ~0 ~54 ~13 ~4 ~54 iron_block 0  
fill ~13 ~0 ~55 ~23 ~0 ~55 iron_block 0  
fill ~13 ~0 ~62 ~14 ~0 ~62 glass 0 
setblock ~14 ~0 ~3 jungle_stairs 5  
fill ~14 ~0 ~9 ~17 ~0 ~9 water 2  
fill ~14 ~0 ~10 ~17 ~0 ~10 water 1  
fill ~14 ~0 ~11 ~17 ~0 ~11 water 0  
fill ~14 ~0 ~12 ~14 ~0 ~14 water 0  
fill ~14 ~0 ~15 ~17 ~0 ~15 water 1  
fill ~14 ~0 ~16 ~17 ~0 ~16 water 2 
setblock ~14 ~0 ~22 jungle_stairs 5 
setblock ~14 ~0 ~39 trapdoor 6 
setblock ~14 ~0 ~61 trapdoor 6  
fill ~15 ~0 ~3 ~16 ~0 ~3 wooden_slab 11  
fill ~15 ~0 ~7 ~16 ~0 ~7 stonebrick 0  
fill ~15 ~0 ~12 ~16 ~0 ~12 stonebrick 0  
fill ~15 ~0 ~13 ~16 ~0 ~13 stonebrick 0  
fill ~15 ~0 ~14 ~17 ~0 ~14 water 0  
fill ~15 ~0 ~18 ~16 ~0 ~18 stonebrick 0  
fill ~15 ~0 ~22 ~16 ~0 ~22 wooden_slab 11  
fill ~15 ~0 ~37 ~15 ~113 ~37 stone 0  
fill ~15 ~0 ~38 ~15 ~8 ~38 stone 0 
setblock ~15 ~0 ~39 dirt 0 
setblock ~15 ~0 ~40 trapdoor 5 
setblock ~15 ~0 ~60 trapdoor 4 
setblock ~15 ~0 ~61 dirt 0  
fill ~15 ~0 ~62 ~15 ~8 ~62 stone 0  
fill ~15 ~0 ~63 ~15 ~113 ~63 stone 0  
fill ~16 ~0 ~38 ~17 ~0 ~38 glass 0 
setblock ~16 ~0 ~39 trapdoor 7 
setblock ~16 ~0 ~61 trapdoor 7  
fill ~16 ~0 ~62 ~17 ~0 ~62 glass 0 
setblock ~17 ~0 ~3 jungle_stairs 4  
fill ~17 ~0 ~12 ~17 ~0 ~14 water 0 
setblock ~17 ~0 ~22 jungle_stairs 4  
fill ~18 ~0 ~9 ~19 ~0 ~9 stonebrick 0 
setblock ~18 ~0 ~10 water 2  
fill ~18 ~0 ~11 ~18 ~0 ~14 water 1 
setblock ~18 ~0 ~15 water 2  
fill ~18 ~0 ~16 ~19 ~0 ~16 stonebrick 0  
fill ~18 ~0 ~32 ~18 ~1 ~32 wool 14  
fill ~19 ~0 ~10 ~20 ~0 ~10 stonebrick 0  
fill ~19 ~0 ~11 ~19 ~0 ~14 water 2  
fill ~19 ~0 ~15 ~20 ~0 ~15 stonebrick 0  
fill ~19 ~0 ~38 ~20 ~0 ~38 glass 0  
fill ~19 ~0 ~62 ~20 ~0 ~62 glass 0  
fill ~20 ~0 ~11 ~20 ~0 ~15 stonebrick 0 
setblock ~20 ~0 ~39 trapdoor 6 
setblock ~20 ~0 ~61 trapdoor 6  
fill ~21 ~0 ~5 ~21 ~0 ~6 trapdoor 6  
fill ~21 ~0 ~12 ~21 ~0 ~13 stonebrick 0  
fill ~21 ~0 ~19 ~21 ~0 ~20 trapdoor 6  
fill ~21 ~0 ~37 ~21 ~113 ~37 stone 0  
fill ~21 ~0 ~38 ~21 ~8 ~38 stone 0 
setblock ~21 ~0 ~39 dirt 0 
setblock ~21 ~0 ~40 trapdoor 5 
setblock ~21 ~0 ~60 trapdoor 4 
setblock ~21 ~0 ~61 dirt 0  
fill ~21 ~0 ~62 ~21 ~8 ~62 stone 0  
fill ~22 ~0 ~4 ~23 ~0 ~4 trapdoor 4  
fill ~22 ~0 ~5 ~23 ~0 ~5 dirt 0  
fill ~22 ~0 ~6 ~23 ~0 ~6 dirt 0  
fill ~22 ~0 ~7 ~23 ~0 ~7 trapdoor 5  
fill ~22 ~0 ~18 ~23 ~0 ~18 trapdoor 4  
fill ~22 ~0 ~19 ~23 ~0 ~19 dirt 0  
fill ~22 ~0 ~20 ~23 ~0 ~20 dirt 0  
fill ~22 ~0 ~21 ~23 ~0 ~21 trapdoor 5  
fill ~22 ~0 ~38 ~23 ~0 ~38 glass 0 
setblock ~22 ~0 ~39 trapdoor 7  
fill ~22 ~0 ~54 ~23 ~0 ~54 iron_block 0 
setblock ~22 ~0 ~61 trapdoor 7  
fill ~22 ~0 ~62 ~23 ~0 ~62 glass 0  
fill ~23 ~0 ~50 ~23 ~3 ~50 glass_pane 0  
fill ~23 ~0 ~52 ~23 ~3 ~52 glass_pane 0  
fill ~24 ~0 ~5 ~24 ~0 ~6 trapdoor 7  
fill ~24 ~0 ~19 ~24 ~0 ~20 trapdoor 7  
fill ~24 ~0 ~45 ~24 ~0 ~49 glass_pane 0  
fill ~25 ~0 ~3 ~25 ~3 ~3 fence 0 
setblock ~25 ~0 ~11 jungle_stairs 7  
fill ~25 ~0 ~12 ~25 ~0 ~13 wooden_slab 11 
setblock ~25 ~0 ~14 jungle_stairs 6  
fill ~25 ~0 ~22 ~25 ~3 ~22 fence 0  
fill ~25 ~0 ~38 ~26 ~0 ~38 glass 0  
fill ~25 ~0 ~62 ~26 ~0 ~62 glass 0 
setblock ~26 ~0 ~39 trapdoor 6 
setblock ~26 ~0 ~61 trapdoor 6  
fill ~27 ~0 ~37 ~27 ~113 ~37 stone 0  
fill ~27 ~0 ~38 ~27 ~8 ~38 stone 0 
setblock ~27 ~0 ~39 dirt 0 
setblock ~27 ~0 ~40 trapdoor 5 
setblock ~27 ~0 ~60 trapdoor 4 
setblock ~27 ~0 ~61 dirt 0  
fill ~27 ~0 ~62 ~27 ~8 ~62 stone 0  
fill ~27 ~0 ~63 ~27 ~113 ~63 stone 0  
fill ~28 ~0 ~38 ~29 ~0 ~38 glass 0 
setblock ~28 ~0 ~39 trapdoor 7 
setblock ~28 ~0 ~41 trapdoor 6 
setblock ~28 ~0 ~47 trapdoor 6 
setblock ~28 ~0 ~53 trapdoor 6 
setblock ~28 ~0 ~59 trapdoor 6 
setblock ~28 ~0 ~61 trapdoor 7  
fill ~28 ~0 ~62 ~29 ~0 ~62 glass 0 
setblock ~29 ~0 ~40 trapdoor 4 
setblock ~29 ~0 ~41 dirt 0 
setblock ~29 ~0 ~42 trapdoor 5 
setblock ~29 ~0 ~46 trapdoor 4 
setblock ~29 ~0 ~47 dirt 0 
setblock ~29 ~0 ~48 trapdoor 5 
setblock ~29 ~0 ~52 trapdoor 4 
setblock ~29 ~0 ~53 dirt 0 
setblock ~29 ~0 ~54 trapdoor 5 
setblock ~29 ~0 ~58 trapdoor 4 
setblock ~29 ~0 ~59 dirt 0 
setblock ~29 ~0 ~60 trapdoor 5  
fill ~30 ~0 ~37 ~30 ~121 ~37 double_stone_slab 0  
fill ~30 ~0 ~39 ~30 ~3 ~39 glass 0  
fill ~30 ~0 ~40 ~30 ~3 ~40 glass 0  
fill ~30 ~0 ~41 ~31 ~0 ~41 stone 0  
fill ~30 ~0 ~42 ~30 ~3 ~42 glass 0  
fill ~30 ~0 ~43 ~30 ~3 ~43 glass 0  
fill ~30 ~0 ~45 ~30 ~3 ~45 glass 0  
fill ~30 ~0 ~46 ~30 ~3 ~46 glass 0  
fill ~30 ~0 ~47 ~31 ~0 ~47 stone 0  
fill ~30 ~0 ~48 ~30 ~3 ~48 glass 0  
fill ~30 ~0 ~49 ~30 ~3 ~49 glass 0  
fill ~30 ~0 ~51 ~30 ~3 ~51 glass 0  
fill ~30 ~0 ~52 ~30 ~3 ~52 glass 0  
fill ~30 ~0 ~53 ~31 ~0 ~53 stone 0  
fill ~30 ~0 ~54 ~30 ~3 ~54 glass 0  
fill ~30 ~0 ~55 ~30 ~3 ~55 glass 0  
fill ~30 ~0 ~57 ~30 ~3 ~57 glass 0  
fill ~30 ~0 ~58 ~30 ~3 ~58 glass 0  
fill ~30 ~0 ~59 ~31 ~0 ~59 stone 0  
fill ~30 ~0 ~60 ~30 ~3 ~60 glass 0  
fill ~30 ~0 ~61 ~30 ~3 ~61 glass 0  
fill ~30 ~0 ~63 ~30 ~121 ~63 double_stone_slab 0  
fill ~31 ~0 ~38 ~31 ~121 ~38 double_stone_slab 0  
fill ~31 ~0 ~62 ~31 ~121 ~62 double_stone_slab 0  
fill ~34 ~0 ~17 ~34 ~1 ~17 wool 14  
fill ~38 ~0 ~5 ~38 ~121 ~5 double_stone_slab 0  
fill ~38 ~0 ~8 ~39 ~0 ~8 stone 0  
fill ~38 ~0 ~14 ~39 ~0 ~14 stone 0  
fill ~38 ~0 ~20 ~39 ~0 ~20 stone 0  
fill ~38 ~0 ~26 ~39 ~0 ~26 stone 0  
fill ~38 ~0 ~29 ~38 ~121 ~29 double_stone_slab 0  
fill ~39 ~0 ~4 ~39 ~121 ~4 double_stone_slab 0  
fill ~39 ~0 ~5 ~41 ~0 ~5 glass 0  
fill ~39 ~0 ~6 ~39 ~3 ~6 glass 0  
fill ~39 ~0 ~7 ~39 ~3 ~7 glass 0  
fill ~39 ~0 ~9 ~39 ~3 ~9 glass 0  
fill ~39 ~0 ~10 ~39 ~3 ~10 glass 0  
fill ~39 ~0 ~12 ~39 ~3 ~12 glass 0  
fill ~39 ~0 ~13 ~39 ~3 ~13 glass 0  
fill ~39 ~0 ~15 ~39 ~3 ~15 glass 0  
fill ~39 ~0 ~16 ~39 ~3 ~16 glass 0  
fill ~39 ~0 ~18 ~39 ~3 ~18 glass 0  
fill ~39 ~0 ~19 ~39 ~3 ~19 glass 0  
fill ~39 ~0 ~21 ~39 ~3 ~21 glass 0  
fill ~39 ~0 ~22 ~39 ~3 ~22 glass 0  
fill ~39 ~0 ~24 ~39 ~3 ~24 glass 0  
fill ~39 ~0 ~25 ~39 ~3 ~25 glass 0  
fill ~39 ~0 ~27 ~39 ~3 ~27 glass 0  
fill ~39 ~0 ~28 ~39 ~3 ~28 glass 0  
fill ~39 ~0 ~29 ~41 ~0 ~29 glass 0  
fill ~39 ~0 ~30 ~39 ~121 ~30 double_stone_slab 0 
setblock ~40 ~0 ~7 trapdoor 4 
setblock ~40 ~0 ~8 dirt 0 
setblock ~40 ~0 ~9 trapdoor 5 
setblock ~40 ~0 ~13 trapdoor 4 
setblock ~40 ~0 ~14 dirt 0 
setblock ~40 ~0 ~15 trapdoor 5 
setblock ~40 ~0 ~19 trapdoor 4 
setblock ~40 ~0 ~20 dirt 0 
setblock ~40 ~0 ~21 trapdoor 5 
setblock ~40 ~0 ~25 trapdoor 4 
setblock ~40 ~0 ~26 dirt 0 
setblock ~40 ~0 ~27 trapdoor 5 
setblock ~41 ~0 ~6 trapdoor 6 
setblock ~41 ~0 ~8 trapdoor 7 
setblock ~41 ~0 ~14 trapdoor 7 
setblock ~41 ~0 ~20 trapdoor 7 
setblock ~41 ~0 ~26 trapdoor 7 
setblock ~41 ~0 ~28 trapdoor 6 
setblock ~41 ~0 ~38 stone_slab 0  
fill ~42 ~0 ~4 ~42 ~113 ~4 stone 0  
fill ~42 ~0 ~5 ~42 ~8 ~5 stone 0 
setblock ~42 ~0 ~6 dirt 0 
setblock ~42 ~0 ~7 trapdoor 5 
setblock ~42 ~0 ~27 trapdoor 4 
setblock ~42 ~0 ~28 dirt 0  
fill ~42 ~0 ~29 ~42 ~8 ~29 stone 0  
fill ~42 ~0 ~30 ~42 ~113 ~30 stone 0  
fill ~42 ~0 ~38 ~42 ~0 ~39 double_stone_slab 0  
fill ~43 ~0 ~5 ~44 ~0 ~5 glass 0 
setblock ~43 ~0 ~6 trapdoor 7 
setblock ~43 ~0 ~28 trapdoor 7  
fill ~43 ~0 ~29 ~44 ~0 ~29 glass 0  
fill ~43 ~0 ~40 ~43 ~2 ~40 double_stone_slab 0  
fill ~43 ~0 ~45 ~43 ~2 ~45 double_stone_slab 0  
fill ~45 ~0 ~11 ~50 ~0 ~11 glass_pane 0  
fill ~45 ~0 ~12 ~45 ~0 ~23 glass_pane 0  
fill ~46 ~0 ~5 ~47 ~0 ~5 glass 0  
fill ~46 ~0 ~23 ~50 ~0 ~23 glass_pane 0  
fill ~46 ~0 ~29 ~47 ~0 ~29 glass 0 
setblock ~47 ~0 ~6 trapdoor 6 
setblock ~47 ~0 ~28 trapdoor 6  
fill ~48 ~0 ~4 ~48 ~113 ~4 stone 0  
fill ~48 ~0 ~5 ~48 ~8 ~5 stone 0 
setblock ~48 ~0 ~6 dirt 0 
setblock ~48 ~0 ~7 trapdoor 5 
setblock ~48 ~0 ~27 trapdoor 4 
setblock ~48 ~0 ~28 dirt 0  
fill ~48 ~0 ~29 ~48 ~8 ~29 stone 0  
fill ~48 ~0 ~30 ~48 ~113 ~30 stone 0  
fill ~49 ~0 ~5 ~50 ~0 ~5 glass 0 
setblock ~49 ~0 ~6 trapdoor 7 
setblock ~49 ~0 ~28 trapdoor 7  
fill ~49 ~0 ~29 ~50 ~0 ~29 glass 0  
fill ~51 ~0 ~12 ~51 ~3 ~12 glass_pane 0  
fill ~51 ~0 ~22 ~51 ~3 ~22 glass_pane 0  
fill ~52 ~0 ~5 ~53 ~0 ~5 glass 0  
fill ~52 ~0 ~29 ~53 ~0 ~29 glass 0 
setblock ~53 ~0 ~6 trapdoor 6  
fill ~53 ~0 ~12 ~53 ~3 ~12 glass_pane 0  
fill ~53 ~0 ~22 ~53 ~3 ~22 glass_pane 0 
setblock ~53 ~0 ~28 trapdoor 6  
fill ~54 ~0 ~4 ~54 ~113 ~4 stone 0  
fill ~54 ~0 ~5 ~54 ~8 ~5 stone 0 
setblock ~54 ~0 ~6 dirt 0 
setblock ~54 ~0 ~7 trapdoor 5  
fill ~54 ~0 ~12 ~56 ~0 ~12 iron_block 0  
fill ~54 ~0 ~13 ~56 ~0 ~13 iron_block 0  
fill ~54 ~0 ~15 ~56 ~0 ~15 iron_block 0  
fill ~54 ~0 ~17 ~56 ~0 ~17 iron_block 0  
fill ~54 ~0 ~19 ~56 ~0 ~19 iron_block 0  
fill ~54 ~0 ~21 ~56 ~0 ~21 iron_block 0  
fill ~54 ~0 ~22 ~56 ~0 ~22 iron_block 0 
setblock ~54 ~0 ~27 trapdoor 4 
setblock ~54 ~0 ~28 dirt 0 
fill ~54 ~0 ~29 ~54 ~8 ~29 stone 0  
fill ~54 ~0 ~30 ~54 ~113 ~30 stone 0  
fill ~55 ~0 ~5 ~56 ~0 ~5 glass 0 
setblock ~55 ~0 ~6 trapdoor 7 
setblock ~55 ~0 ~28 trapdoor 7  
fill ~55 ~0 ~29 ~56 ~0 ~29 glass 0  
fill ~58 ~0 ~5 ~59 ~0 ~5 glass 0  
fill ~58 ~0 ~29 ~59 ~0 ~29 glass 0 
setblock ~59 ~0 ~6 trapdoor 6 
setblock ~59 ~0 ~28 trapdoor 6  
fill ~60 ~0 ~4 ~60 ~113 ~4 stone 0  
fill ~60 ~0 ~5 ~60 ~8 ~5 stone 0 
setblock ~60 ~0 ~6 dirt 0 
setblock ~60 ~0 ~7 trapdoor 5 
setblock ~60 ~0 ~27 trapdoor 4 
setblock ~60 ~0 ~28 dirt 0  
fill ~60 ~0 ~29 ~60 ~8 ~29 stone 0  
fill ~60 ~0 ~30 ~60 ~113 ~30 stone 0  
fill ~61 ~0 ~5 ~63 ~0 ~5 glass 0 
setblock ~61 ~0 ~6 trapdoor 7 
setblock ~61 ~0 ~8 trapdoor 6 
setblock ~61 ~0 ~14 trapdoor 6 
setblock ~61 ~0 ~20 trapdoor 6 
setblock ~61 ~0 ~26 trapdoor 6 
setblock ~61 ~0 ~28 trapdoor 7  
fill ~61 ~0 ~29 ~63 ~0 ~29 glass 0 
setblock ~62 ~0 ~7 trapdoor 4 
setblock ~62 ~0 ~8 dirt 0 
setblock ~62 ~0 ~9 trapdoor 5 
setblock ~62 ~0 ~13 trapdoor 4 
setblock ~62 ~0 ~14 dirt 0 
setblock ~62 ~0 ~15 trapdoor 5 
setblock ~62 ~0 ~19 trapdoor 4 
setblock ~62 ~0 ~20 dirt 0 
setblock ~62 ~0 ~21 trapdoor 5 
setblock ~62 ~0 ~25 trapdoor 4 
setblock ~62 ~0 ~26 dirt 0 
setblock ~62 ~0 ~27 trapdoor 5  
fill ~63 ~0 ~4 ~63 ~121 ~4 double_stone_slab 0  
fill ~63 ~0 ~6 ~63 ~3 ~6 glass 0  
fill ~63 ~0 ~7 ~63 ~3 ~7 glass 0  
fill ~63 ~0 ~8 ~64 ~0 ~8 stone 0  
fill ~63 ~0 ~9 ~63 ~3 ~9 glass 0  
fill ~63 ~0 ~10 ~63 ~3 ~10 glass 0  
fill ~63 ~0 ~12 ~63 ~3 ~12 glass 0  
fill ~63 ~0 ~13 ~63 ~3 ~13 glass 0  
fill ~63 ~0 ~14 ~64 ~0 ~14 stone 0  
fill ~63 ~0 ~15 ~63 ~3 ~15 glass 0  
fill ~63 ~0 ~16 ~63 ~3 ~16 glass 0  
fill ~63 ~0 ~18 ~63 ~3 ~18 glass 0  
fill ~63 ~0 ~19 ~63 ~3 ~19 glass 0  
fill ~63 ~0 ~20 ~64 ~0 ~20 stone 0  
fill ~63 ~0 ~21 ~63 ~3 ~21 glass 0  
fill ~63 ~0 ~22 ~63 ~3 ~22 glass 0  
fill ~63 ~0 ~24 ~63 ~3 ~24 glass 0  
fill ~63 ~0 ~25 ~63 ~3 ~25 glass 0  
fill ~63 ~0 ~26 ~64 ~0 ~26 stone 0  
fill ~63 ~0 ~27 ~63 ~3 ~27 glass 0  
fill ~63 ~0 ~28 ~63 ~3 ~28 glass 0  
fill ~63 ~0 ~30 ~63 ~121 ~30 double_stone_slab 0  
fill ~64 ~0 ~5 ~64 ~121 ~5 double_stone_slab 0  
fill ~64 ~0 ~29 ~64 ~121 ~29 double_stone_slab 0  
fill ~69 ~0 ~1 ~69 ~0 ~68 stone_slab 0  
fill ~5 ~1 ~41 ~6 ~1 ~41 stone 0  
fill ~5 ~1 ~47 ~6 ~1 ~47 stone 0  
fill ~5 ~1 ~53 ~6 ~1 ~53 stone 0  
fill ~5 ~1 ~59 ~6 ~1 ~59 stone 0  
fill ~7 ~1 ~38 ~8 ~1 ~38 glass 0 
setblock ~7 ~1 ~41 leaves 7 
setblock ~7 ~1 ~47 leaves 7 
setblock ~7 ~1 ~53 leaves 7 
setblock ~7 ~1 ~59 leaves 7  
fill ~7 ~1 ~62 ~8 ~1 ~62 glass 0  
fill ~8 ~1 ~5 ~9 ~1 ~5 leaves 7  
fill ~8 ~1 ~6 ~9 ~1 ~6 leaves 7  
fill ~8 ~1 ~19 ~9 ~1 ~19 leaves 7  
fill ~8 ~1 ~20 ~9 ~1 ~20 leaves 7 
setblock ~9 ~1 ~39 leaves 7 
setblock ~9 ~1 ~61 leaves 7  
fill ~10 ~1 ~38 ~11 ~1 ~38 glass 0  
fill ~10 ~1 ~62 ~11 ~1 ~62 glass 0  
fill ~13 ~1 ~38 ~14 ~1 ~38 glass 0  
fill ~13 ~1 ~53 ~23 ~1 ~53 iron_block 0  
fill ~13 ~1 ~55 ~23 ~1 ~55 iron_block 0  
fill ~13 ~1 ~62 ~14 ~1 ~62 glass 0  
fill ~15 ~1 ~12 ~16 ~1 ~12 lit_redstone_lamp 0  
fill ~15 ~1 ~13 ~16 ~1 ~13 lit_redstone_lamp 0 
setblock ~15 ~1 ~39 leaves 7 
setblock ~15 ~1 ~61 leaves 7  
fill ~16 ~1 ~38 ~17 ~1 ~38 glass 0  
fill ~16 ~1 ~62 ~17 ~1 ~62 glass 0  
fill ~19 ~1 ~38 ~20 ~1 ~38 glass 0  
fill ~19 ~1 ~62 ~20 ~1 ~62 glass 0 
setblock ~21 ~1 ~39 leaves 7 
setblock ~21 ~1 ~61 leaves 7  
fill ~22 ~1 ~5 ~23 ~1 ~5 leaves 7  
fill ~22 ~1 ~6 ~23 ~1 ~6 leaves 7  
fill ~22 ~1 ~19 ~23 ~1 ~19 leaves 7  
fill ~22 ~1 ~20 ~23 ~1 ~20 leaves 7  
fill ~22 ~1 ~38 ~23 ~1 ~38 glass 0  
fill ~22 ~1 ~54 ~23 ~1 ~54 iron_block 0  
fill ~22 ~1 ~62 ~23 ~1 ~62 glass 0  
fill ~25 ~1 ~38 ~26 ~1 ~38 glass 0  
fill ~25 ~1 ~62 ~26 ~1 ~62 glass 0 
setblock ~27 ~1 ~39 leaves 7 
setblock ~27 ~1 ~61 leaves 7  
fill ~28 ~1 ~38 ~29 ~1 ~38 glass 0  
fill ~28 ~1 ~62 ~29 ~1 ~62 glass 0 
setblock ~29 ~1 ~41 leaves 7 
setblock ~29 ~1 ~47 leaves 7 
setblock ~29 ~1 ~53 leaves 7 
setblock ~29 ~1 ~59 leaves 7  
fill ~30 ~1 ~41 ~31 ~1 ~41 stone 0  
fill ~30 ~1 ~47 ~31 ~1 ~47 stone 0  
fill ~30 ~1 ~53 ~31 ~1 ~53 stone 0  
fill ~30 ~1 ~59 ~31 ~1 ~59 stone 0  
fill ~38 ~1 ~8 ~39 ~1 ~8 stone 0  
fill ~38 ~1 ~14 ~39 ~1 ~14 stone 0  
fill ~38 ~1 ~20 ~39 ~1 ~20 stone 0  
fill ~38 ~1 ~26 ~39 ~1 ~26 stone 0  
fill ~39 ~1 ~5 ~41 ~1 ~5 glass 0  
fill ~39 ~1 ~29 ~41 ~1 ~29 glass 0 
setblock ~40 ~1 ~8 leaves 7 
setblock ~40 ~1 ~14 leaves 7 
setblock ~40 ~1 ~20 leaves 7 
setblock ~40 ~1 ~26 leaves 7 
setblock ~42 ~1 ~6 leaves 7 
setblock ~42 ~1 ~28 leaves 7 
setblock ~42 ~1 ~39 double_stone_slab 0  
fill ~42 ~1 ~40 ~42 ~1 ~42 stone_slab 8  
fill ~43 ~1 ~5 ~44 ~1 ~5 glass 0  
fill ~43 ~1 ~29 ~44 ~1 ~29 glass 0 
setblock ~43 ~1 ~39 stone_slab 8  
fill ~43 ~1 ~42 ~43 ~1 ~44 stone_slab 8 
setblock ~44 ~1 ~40 stone_slab 8  
fill ~46 ~1 ~5 ~47 ~1 ~5 glass 0  
fill ~46 ~1 ~29 ~47 ~1 ~29 glass 0 
setblock ~48 ~1 ~6 leaves 7 
setblock ~48 ~1 ~28 leaves 7  
fill ~49 ~1 ~5 ~50 ~1 ~5 glass 0  
fill ~49 ~1 ~29 ~50 ~1 ~29 glass 0  
fill ~52 ~1 ~5 ~53 ~1 ~5 glass 0  
fill ~52 ~1 ~29 ~53 ~1 ~29 glass 0 
setblock ~54 ~1 ~6 leaves 7  
fill ~54 ~1 ~12 ~56 ~1 ~12 iron_block 0  
fill ~54 ~1 ~13 ~56 ~1 ~13 iron_block 0  
fill ~54 ~1 ~15 ~56 ~1 ~15 iron_block 0  
fill ~54 ~1 ~17 ~56 ~1 ~17 iron_block 0  
fill ~54 ~1 ~19 ~56 ~1 ~19 iron_block 0  
fill ~54 ~1 ~21 ~56 ~1 ~21 iron_block 0  
fill ~54 ~1 ~22 ~56 ~1 ~22 iron_block 0 
setblock ~54 ~1 ~28 leaves 7  
fill ~55 ~1 ~5 ~56 ~1 ~5 glass 0  
fill ~55 ~1 ~29 ~56 ~1 ~29 glass 0  
fill ~58 ~1 ~5 ~59 ~1 ~5 glass 0  
fill ~58 ~1 ~29 ~59 ~1 ~29 glass 0 
setblock ~60 ~1 ~6 leaves 7 
setblock ~60 ~1 ~28 leaves 7  
fill ~61 ~1 ~5 ~63 ~1 ~5 glass 0  
fill ~61 ~1 ~29 ~63 ~1 ~29 glass 0 
setblock ~62 ~1 ~8 leaves 7 
setblock ~62 ~1 ~14 leaves 7 
setblock ~62 ~1 ~20 leaves 7 
setblock ~62 ~1 ~26 leaves 7  
fill ~63 ~1 ~8 ~64 ~1 ~8 stone 0  
fill ~63 ~1 ~14 ~64 ~1 ~14 stone 0  
fill ~63 ~1 ~20 ~64 ~1 ~20 stone 0  
fill ~63 ~1 ~26 ~64 ~1 ~26 stone 0  
fill ~5 ~2 ~41 ~6 ~2 ~41 stone 0  
fill ~5 ~2 ~47 ~6 ~2 ~47 stone 0  
fill ~5 ~2 ~53 ~6 ~2 ~53 stone 0  
fill ~5 ~2 ~59 ~6 ~2 ~59 stone 0  
fill ~6 ~2 ~44 ~6 ~3 ~44 glass 0  
fill ~6 ~2 ~50 ~6 ~3 ~50 glass 0  
fill ~6 ~2 ~56 ~6 ~3 ~56 glass 0  
fill ~7 ~2 ~38 ~8 ~2 ~38 glass 0  
fill ~7 ~2 ~62 ~8 ~2 ~62 glass 0  
fill ~10 ~2 ~38 ~14 ~2 ~38 glass 0  
fill ~10 ~2 ~62 ~14 ~2 ~62 glass 0  
fill ~13 ~2 ~53 ~23 ~2 ~53 iron_block 0  
fill ~13 ~2 ~55 ~23 ~2 ~55 iron_block 0  
fill ~14 ~2 ~12 ~14 ~2 ~13 lit_redstone_lamp 0  
fill ~15 ~2 ~11 ~16 ~2 ~11 lit_redstone_lamp 0 
setblock ~15 ~2 ~12 redstone_wire 15 
setblock ~15 ~2 ~13 redstone_torch 5  
fill ~15 ~2 ~14 ~16 ~2 ~14 lit_redstone_lamp 0 
setblock ~16 ~2 ~12 redstone_torch 5 
setblock ~16 ~2 ~13 redstone_wire 15  
fill ~16 ~2 ~38 ~20 ~2 ~38 glass 0  
fill ~16 ~2 ~62 ~20 ~2 ~62 glass 0  
fill ~17 ~2 ~12 ~17 ~2 ~13 lit_redstone_lamp 0  
fill ~22 ~2 ~38 ~26 ~2 ~38 glass 0  
fill ~22 ~2 ~54 ~23 ~2 ~54 iron_block 0  
fill ~22 ~2 ~62 ~26 ~2 ~62 glass 0  
fill ~28 ~2 ~38 ~29 ~2 ~38 glass 0  
fill ~28 ~2 ~62 ~29 ~2 ~62 glass 0  
fill ~30 ~2 ~41 ~31 ~2 ~41 stone 0  
fill ~30 ~2 ~44 ~30 ~3 ~44 glass 0  
fill ~30 ~2 ~47 ~31 ~2 ~47 stone 0  
fill ~30 ~2 ~50 ~30 ~3 ~50 glass 0  
fill ~30 ~2 ~53 ~31 ~2 ~53 stone 0  
fill ~30 ~2 ~56 ~30 ~3 ~56 glass 0  
fill ~30 ~2 ~59 ~31 ~2 ~59 stone 0  
fill ~38 ~2 ~8 ~39 ~2 ~8 stone 0  
fill ~38 ~2 ~14 ~39 ~2 ~14 stone 0  
fill ~38 ~2 ~20 ~39 ~2 ~20 stone 0  
fill ~38 ~2 ~26 ~39 ~2 ~26 stone 0  
fill ~39 ~2 ~5 ~41 ~2 ~5 glass 0  
fill ~39 ~2 ~11 ~39 ~3 ~11 glass 0  
fill ~39 ~2 ~17 ~39 ~3 ~17 glass 0  
fill ~39 ~2 ~23 ~39 ~3 ~23 glass 0  
fill ~39 ~2 ~29 ~41 ~2 ~29 glass 0  
fill ~42 ~2 ~40 ~42 ~2 ~41 stone_slab 0  
fill ~42 ~2 ~45 ~42 ~4 ~45 double_stone_slab 0  
fill ~43 ~2 ~5 ~47 ~2 ~5 glass 0  
fill ~43 ~2 ~29 ~47 ~2 ~29 glass 0 
setblock ~43 ~2 ~39 stone_slab 0  
fill ~43 ~2 ~42 ~43 ~2 ~44 stone_slab 0  
fill ~44 ~2 ~40 ~44 ~3 ~40 double_stone_slab 0  
fill ~49 ~2 ~5 ~53 ~2 ~5 glass 0  
fill ~49 ~2 ~29 ~53 ~2 ~29 glass 0  
fill ~54 ~2 ~12 ~56 ~2 ~12 iron_block 0  
fill ~54 ~2 ~13 ~56 ~2 ~13 iron_block 0  
fill ~54 ~2 ~15 ~56 ~2 ~15 iron_block 0  
fill ~54 ~2 ~17 ~56 ~2 ~17 iron_block 0  
fill ~54 ~2 ~19 ~56 ~2 ~19 iron_block 0  
fill ~54 ~2 ~21 ~56 ~2 ~21 iron_block 0  
fill ~54 ~2 ~22 ~56 ~2 ~22 iron_block 0  
fill ~55 ~2 ~5 ~59 ~2 ~5 glass 0  
fill ~55 ~2 ~29 ~59 ~2 ~29 glass 0  
fill ~61 ~2 ~5 ~63 ~2 ~5 glass 0  
fill ~61 ~2 ~29 ~63 ~2 ~29 glass 0  
fill ~63 ~2 ~8 ~64 ~2 ~8 stone 0  
fill ~63 ~2 ~11 ~63 ~3 ~11 glass 0  
fill ~63 ~2 ~14 ~64 ~2 ~14 stone 0  
fill ~63 ~2 ~17 ~63 ~3 ~17 glass 0  
fill ~63 ~2 ~20 ~64 ~2 ~20 stone 0  
fill ~63 ~2 ~23 ~63 ~3 ~23 glass 0  
fill ~63 ~2 ~26 ~64 ~2 ~26 stone 0  
fill ~5 ~3 ~41 ~6 ~3 ~41 stone 0  
fill ~5 ~3 ~47 ~6 ~3 ~47 stone 0  
fill ~5 ~3 ~53 ~6 ~3 ~53 stone 0  
fill ~5 ~3 ~59 ~6 ~3 ~59 stone 0  
fill ~7 ~3 ~38 ~8 ~3 ~38 glass 0  
fill ~7 ~3 ~62 ~8 ~3 ~62 glass 0  
fill ~10 ~3 ~38 ~14 ~3 ~38 glass 0  
fill ~10 ~3 ~62 ~14 ~3 ~62 glass 0  
fill ~13 ~3 ~12 ~13 ~5 ~12 lit_redstone_lamp 0  
fill ~13 ~3 ~13 ~13 ~5 ~13 lit_redstone_lamp 0  
fill ~13 ~3 ~53 ~23 ~3 ~53 iron_block 0  
fill ~13 ~3 ~55 ~23 ~3 ~55 iron_block 0 
setblock ~14 ~3 ~11 lit_redstone_lamp 0 
setblock ~14 ~3 ~12 redstone_wire 15 
setblock ~14 ~3 ~13 redstone_torch 5 
setblock ~14 ~3 ~14 lit_redstone_lamp 0  
fill ~15 ~3 ~10 ~16 ~3 ~10 lit_redstone_lamp 0 
setblock ~15 ~3 ~11 redstone_torch 5 
setblock ~15 ~3 ~14 redstone_torch 5  
fill ~15 ~3 ~15 ~16 ~3 ~15 lit_redstone_lamp 0 
setblock ~16 ~3 ~11 redstone_wire 15 
setblock ~16 ~3 ~14 redstone_wire 15  
fill ~16 ~3 ~38 ~20 ~3 ~38 glass 0  
fill ~16 ~3 ~62 ~20 ~3 ~62 glass 0 
setblock ~17 ~3 ~11 lit_redstone_lamp 0 
setblock ~17 ~3 ~12 lever 10 
setblock ~17 ~3 ~13 lever 13 
setblock ~17 ~3 ~14 lit_redstone_lamp 0  
fill ~18 ~3 ~12 ~18 ~5 ~12 lit_redstone_lamp 0  
fill ~18 ~3 ~13 ~18 ~5 ~13 lit_redstone_lamp 0  
fill ~22 ~3 ~38 ~26 ~3 ~38 glass 0  
fill ~22 ~3 ~54 ~23 ~3 ~54 iron_block 0  
fill ~22 ~3 ~62 ~26 ~3 ~62 glass 0  
fill ~28 ~3 ~38 ~29 ~3 ~38 glass 0  
fill ~28 ~3 ~62 ~29 ~3 ~62 glass 0  
fill ~30 ~3 ~41 ~31 ~3 ~41 stone 0  
fill ~30 ~3 ~47 ~31 ~3 ~47 stone 0  
fill ~30 ~3 ~53 ~31 ~3 ~53 stone 0  
fill ~30 ~3 ~59 ~31 ~3 ~59 stone 0  
fill ~38 ~3 ~8 ~39 ~3 ~8 stone 0  
fill ~38 ~3 ~14 ~39 ~3 ~14 stone 0  
fill ~38 ~3 ~20 ~39 ~3 ~20 stone 0  
fill ~38 ~3 ~26 ~39 ~3 ~26 stone 0  
fill ~39 ~3 ~5 ~41 ~3 ~5 glass 0  
fill ~39 ~3 ~29 ~41 ~3 ~29 glass 0  
fill ~43 ~3 ~5 ~47 ~3 ~5 glass 0  
fill ~43 ~3 ~29 ~47 ~3 ~29 glass 0  
fill ~44 ~3 ~41 ~45 ~3 ~41 stone_slab 8  
fill ~49 ~3 ~5 ~53 ~3 ~5 glass 0  
fill ~49 ~3 ~29 ~53 ~3 ~29 glass 0  
fill ~54 ~3 ~12 ~56 ~3 ~12 iron_block 0  
fill ~54 ~3 ~13 ~56 ~3 ~13 iron_block 0  
fill ~54 ~3 ~15 ~56 ~3 ~15 iron_block 0  
fill ~54 ~3 ~17 ~56 ~3 ~17 iron_block 0  
fill ~54 ~3 ~19 ~56 ~3 ~19 iron_block 0  
fill ~54 ~3 ~21 ~56 ~3 ~21 iron_block 0  
fill ~54 ~3 ~22 ~56 ~3 ~22 iron_block 0  
fill ~55 ~3 ~5 ~59 ~3 ~5 glass 0  
fill ~55 ~3 ~29 ~59 ~3 ~29 glass 0  
fill ~61 ~3 ~5 ~63 ~3 ~5 glass 0  
fill ~61 ~3 ~29 ~63 ~3 ~29 glass 0  
fill ~63 ~3 ~8 ~64 ~3 ~8 stone 0  
fill ~63 ~3 ~14 ~64 ~3 ~14 stone 0  
fill ~63 ~3 ~20 ~64 ~3 ~20 stone 0  
fill ~63 ~3 ~26 ~64 ~3 ~26 stone 0  
fill ~5 ~4 ~41 ~6 ~4 ~41 stone 0  
fill ~5 ~4 ~47 ~6 ~4 ~47 stone 0  
fill ~5 ~4 ~53 ~6 ~4 ~53 stone 0  
fill ~5 ~4 ~59 ~6 ~4 ~59 stone 0 
setblock ~6 ~4 ~3 glowstone 0 
setblock ~6 ~4 ~22 glowstone 0  
fill ~6 ~4 ~38 ~30 ~4 ~38 stone 0  
fill ~6 ~4 ~39 ~6 ~4 ~62 stone 0  
fill ~7 ~4 ~39 ~29 ~4 ~39 iron_block 0  
fill ~7 ~4 ~40 ~7 ~4 ~61 iron_block 0  
fill ~7 ~4 ~62 ~30 ~4 ~62 stone 0 
setblock ~8 ~4 ~40 lit_redstone_lamp 0  
fill ~8 ~4 ~41 ~29 ~4 ~41 iron_block 0 
setblock ~8 ~4 ~42 lit_redstone_lamp 0  
fill ~8 ~4 ~43 ~29 ~4 ~43 iron_block 0 
setblock ~8 ~4 ~44 lit_redstone_lamp 0  
fill ~8 ~4 ~45 ~29 ~4 ~45 iron_block 0 
setblock ~8 ~4 ~46 lit_redstone_lamp 0  
fill ~8 ~4 ~47 ~29 ~4 ~47 iron_block 0 
setblock ~8 ~4 ~48 lit_redstone_lamp 0  
fill ~8 ~4 ~49 ~29 ~4 ~49 iron_block 0 
setblock ~8 ~4 ~50 lit_redstone_lamp 0  
fill ~8 ~4 ~51 ~29 ~4 ~51 iron_block 0 
setblock ~8 ~4 ~52 lit_redstone_lamp 0  
fill ~8 ~4 ~53 ~29 ~4 ~53 iron_block 0 
setblock ~8 ~4 ~54 lit_redstone_lamp 0  
fill ~8 ~4 ~55 ~29 ~4 ~55 iron_block 0 
setblock ~8 ~4 ~56 lit_redstone_lamp 0  
fill ~8 ~4 ~57 ~29 ~4 ~57 iron_block 0 
setblock ~8 ~4 ~58 lit_redstone_lamp 0  
fill ~8 ~4 ~59 ~29 ~4 ~59 iron_block 0 
setblock ~8 ~4 ~60 lit_redstone_lamp 0  
fill ~8 ~4 ~61 ~29 ~4 ~61 iron_block 0 
setblock ~9 ~4 ~40 iron_block 0 
setblock ~9 ~4 ~42 iron_block 0 
setblock ~9 ~4 ~44 iron_block 0 
setblock ~9 ~4 ~46 iron_block 0 
setblock ~9 ~4 ~48 iron_block 0 
setblock ~9 ~4 ~50 iron_block 0 
setblock ~9 ~4 ~52 iron_block 0 
setblock ~9 ~4 ~54 iron_block 0 
setblock ~9 ~4 ~56 iron_block 0 
setblock ~9 ~4 ~58 iron_block 0 
setblock ~9 ~4 ~60 iron_block 0 
setblock ~10 ~4 ~40 lit_redstone_lamp 0 
setblock ~10 ~4 ~42 lit_redstone_lamp 0 
setblock ~10 ~4 ~44 lit_redstone_lamp 0 
setblock ~10 ~4 ~46 lit_redstone_lamp 0 
setblock ~10 ~4 ~48 lit_redstone_lamp 0 
setblock ~10 ~4 ~50 lit_redstone_lamp 0 
setblock ~10 ~4 ~52 lit_redstone_lamp 0 
setblock ~10 ~4 ~54 lit_redstone_lamp 0 
setblock ~10 ~4 ~56 lit_redstone_lamp 0 
setblock ~10 ~4 ~58 lit_redstone_lamp 0 
setblock ~10 ~4 ~60 lit_redstone_lamp 0 
setblock ~11 ~4 ~40 iron_block 0 
setblock ~11 ~4 ~42 iron_block 0 
setblock ~11 ~4 ~44 iron_block 0 
setblock ~11 ~4 ~46 iron_block 0 
setblock ~11 ~4 ~48 iron_block 0 
setblock ~11 ~4 ~50 iron_block 0 
setblock ~11 ~4 ~52 iron_block 0 
setblock ~11 ~4 ~54 iron_block 0 
setblock ~11 ~4 ~56 iron_block 0 
setblock ~11 ~4 ~58 iron_block 0 
setblock ~11 ~4 ~60 iron_block 0 
setblock ~12 ~4 ~40 lit_redstone_lamp 0 
setblock ~12 ~4 ~42 lit_redstone_lamp 0 
setblock ~12 ~4 ~44 lit_redstone_lamp 0 
setblock ~12 ~4 ~46 lit_redstone_lamp 0 
setblock ~12 ~4 ~48 lit_redstone_lamp 0 
setblock ~12 ~4 ~50 lit_redstone_lamp 0 
setblock ~12 ~4 ~52 lit_redstone_lamp 0 
setblock ~12 ~4 ~54 lit_redstone_lamp 0 
setblock ~12 ~4 ~56 lit_redstone_lamp 0 
setblock ~12 ~4 ~58 lit_redstone_lamp 0 
setblock ~12 ~4 ~60 lit_redstone_lamp 0 
setblock ~13 ~4 ~11 lit_redstone_lamp 0 
setblock ~13 ~4 ~14 lit_redstone_lamp 0 
setblock ~13 ~4 ~40 iron_block 0 
setblock ~13 ~4 ~42 iron_block 0 
setblock ~13 ~4 ~44 iron_block 0 
setblock ~13 ~4 ~46 iron_block 0 
setblock ~13 ~4 ~48 iron_block 0 
setblock ~13 ~4 ~50 iron_block 0 
setblock ~13 ~4 ~52 iron_block 0 
setblock ~13 ~4 ~56 iron_block 0 
setblock ~13 ~4 ~58 iron_block 0 
setblock ~13 ~4 ~60 iron_block 0  
fill ~14 ~4 ~10 ~17 ~4 ~10 lit_redstone_lamp 0 
setblock ~14 ~4 ~11 redstone_torch 5 
setblock ~14 ~4 ~12 lever 9  
fill ~14 ~4 ~13 ~15 ~4 ~13 cobblestone 0 
setblock ~14 ~4 ~14 redstone_torch 5  
fill ~14 ~4 ~15 ~17 ~4 ~15 lit_redstone_lamp 0 
setblock ~14 ~4 ~40 lit_redstone_lamp 0 
setblock ~14 ~4 ~42 lit_redstone_lamp 0 
setblock ~14 ~4 ~44 lit_redstone_lamp 0 
setblock ~14 ~4 ~46 lit_redstone_lamp 0 
setblock ~14 ~4 ~48 lit_redstone_lamp 0 
setblock ~14 ~4 ~50 lit_redstone_lamp 0 
setblock ~14 ~4 ~52 lit_redstone_lamp 0 
setblock ~14 ~4 ~56 lit_redstone_lamp 0 
setblock ~14 ~4 ~58 lit_redstone_lamp 0 
setblock ~14 ~4 ~60 lit_redstone_lamp 0  
fill ~15 ~4 ~11 ~15 ~4 ~14 cobblestone 0 
setblock ~15 ~4 ~40 iron_block 0 
setblock ~15 ~4 ~42 iron_block 0 
setblock ~15 ~4 ~44 iron_block 0 
setblock ~15 ~4 ~46 iron_block 0 
setblock ~15 ~4 ~48 iron_block 0 
setblock ~15 ~4 ~50 iron_block 0 
setblock ~15 ~4 ~52 iron_block 0 
setblock ~15 ~4 ~56 iron_block 0 
setblock ~15 ~4 ~58 iron_block 0 
setblock ~15 ~4 ~60 iron_block 0 
setblock ~16 ~4 ~11 lever 11  
fill ~16 ~4 ~12 ~17 ~4 ~12 cobblestone 0 
setblock ~16 ~4 ~14 lever 12 
setblock ~16 ~4 ~40 lit_redstone_lamp 0 
setblock ~16 ~4 ~42 lit_redstone_lamp 0 
setblock ~16 ~4 ~44 lit_redstone_lamp 0 
setblock ~16 ~4 ~46 lit_redstone_lamp 0 
setblock ~16 ~4 ~48 lit_redstone_lamp 0 
setblock ~16 ~4 ~50 lit_redstone_lamp 0 
setblock ~16 ~4 ~52 lit_redstone_lamp 0 
setblock ~16 ~4 ~56 lit_redstone_lamp 0 
setblock ~16 ~4 ~58 lit_redstone_lamp 0 
setblock ~16 ~4 ~60 lit_redstone_lamp 0 
setblock ~17 ~4 ~11 redstone_wire 15 
setblock ~17 ~4 ~13 redstone_torch 3 
setblock ~17 ~4 ~14 redstone_torch 5 
setblock ~17 ~4 ~40 iron_block 0 
setblock ~17 ~4 ~42 iron_block 0 
setblock ~17 ~4 ~44 iron_block 0 
setblock ~17 ~4 ~46 iron_block 0 
setblock ~17 ~4 ~48 iron_block 0 
setblock ~17 ~4 ~50 iron_block 0 
setblock ~17 ~4 ~52 iron_block 0 
setblock ~17 ~4 ~56 iron_block 0 
setblock ~17 ~4 ~58 iron_block 0 
setblock ~17 ~4 ~60 iron_block 0 
setblock ~18 ~4 ~11 lit_redstone_lamp 0 
setblock ~18 ~4 ~14 lit_redstone_lamp 0 
setblock ~18 ~4 ~40 lit_redstone_lamp 0 
setblock ~18 ~4 ~42 lit_redstone_lamp 0 
setblock ~18 ~4 ~44 lit_redstone_lamp 0 
setblock ~18 ~4 ~46 lit_redstone_lamp 0 
setblock ~18 ~4 ~48 lit_redstone_lamp 0 
setblock ~18 ~4 ~50 lit_redstone_lamp 0 
setblock ~18 ~4 ~52 lit_redstone_lamp 0 
setblock ~18 ~4 ~56 lit_redstone_lamp 0 
setblock ~18 ~4 ~58 lit_redstone_lamp 0 
setblock ~18 ~4 ~60 lit_redstone_lamp 0 
setblock ~19 ~4 ~40 iron_block 0 
setblock ~19 ~4 ~42 iron_block 0 
setblock ~19 ~4 ~44 iron_block 0 
setblock ~19 ~4 ~46 iron_block 0 
setblock ~19 ~4 ~48 iron_block 0 
setblock ~19 ~4 ~50 iron_block 0 
setblock ~19 ~4 ~52 iron_block 0 
setblock ~19 ~4 ~56 iron_block 0 
setblock ~19 ~4 ~58 iron_block 0 
setblock ~19 ~4 ~60 iron_block 0 
setblock ~20 ~4 ~40 lit_redstone_lamp 0 
setblock ~20 ~4 ~42 lit_redstone_lamp 0 
setblock ~20 ~4 ~44 lit_redstone_lamp 0 
setblock ~20 ~4 ~46 lit_redstone_lamp 0 
setblock ~20 ~4 ~48 lit_redstone_lamp 0 
setblock ~20 ~4 ~50 lit_redstone_lamp 0 
setblock ~20 ~4 ~52 lit_redstone_lamp 0 
setblock ~20 ~4 ~56 lit_redstone_lamp 0 
setblock ~20 ~4 ~58 lit_redstone_lamp 0 
setblock ~20 ~4 ~60 lit_redstone_lamp 0 
setblock ~21 ~4 ~40 iron_block 0 
setblock ~21 ~4 ~42 iron_block 0 
setblock ~21 ~4 ~44 iron_block 0 
setblock ~21 ~4 ~46 iron_block 0 
setblock ~21 ~4 ~48 iron_block 0 
setblock ~21 ~4 ~50 iron_block 0 
setblock ~21 ~4 ~52 iron_block 0 
setblock ~21 ~4 ~56 iron_block 0 
setblock ~21 ~4 ~58 iron_block 0 
setblock ~21 ~4 ~60 iron_block 0 
setblock ~22 ~4 ~40 lit_redstone_lamp 0 
setblock ~22 ~4 ~42 lit_redstone_lamp 0 
setblock ~22 ~4 ~44 lit_redstone_lamp 0 
setblock ~22 ~4 ~46 lit_redstone_lamp 0 
setblock ~22 ~4 ~48 lit_redstone_lamp 0 
setblock ~22 ~4 ~50 lit_redstone_lamp 0 
setblock ~22 ~4 ~52 lit_redstone_lamp 0  
fill ~22 ~4 ~54 ~23 ~4 ~54 iron_block 0 
setblock ~22 ~4 ~56 lit_redstone_lamp 0 
setblock ~22 ~4 ~58 lit_redstone_lamp 0 
setblock ~22 ~4 ~60 lit_redstone_lamp 0 
setblock ~23 ~4 ~40 iron_block 0 
setblock ~23 ~4 ~42 iron_block 0 
setblock ~23 ~4 ~44 iron_block 0 
setblock ~23 ~4 ~46 iron_block 0 
setblock ~23 ~4 ~48 iron_block 0 
setblock ~23 ~4 ~50 iron_block 0 
setblock ~23 ~4 ~52 iron_block 0 
setblock ~23 ~4 ~56 iron_block 0 
setblock ~23 ~4 ~58 iron_block 0 
setblock ~23 ~4 ~60 iron_block 0 
setblock ~24 ~4 ~40 lit_redstone_lamp 0 
setblock ~24 ~4 ~42 lit_redstone_lamp 0 
setblock ~24 ~4 ~44 lit_redstone_lamp 0 
setblock ~24 ~4 ~46 lit_redstone_lamp 0 
setblock ~24 ~4 ~48 lit_redstone_lamp 0 
setblock ~24 ~4 ~50 lit_redstone_lamp 0 
setblock ~24 ~4 ~52 lit_redstone_lamp 0 
setblock ~24 ~4 ~54 lit_redstone_lamp 0 
setblock ~24 ~4 ~56 lit_redstone_lamp 0 
setblock ~24 ~4 ~58 lit_redstone_lamp 0 
setblock ~24 ~4 ~60 lit_redstone_lamp 0 
setblock ~25 ~4 ~3 glowstone 0 
setblock ~25 ~4 ~22 glowstone 0 
setblock ~25 ~4 ~40 iron_block 0 
setblock ~25 ~4 ~42 iron_block 0 
setblock ~25 ~4 ~44 iron_block 0 
setblock ~25 ~4 ~46 iron_block 0 
setblock ~25 ~4 ~48 iron_block 0 
setblock ~25 ~4 ~50 iron_block 0 
setblock ~25 ~4 ~52 iron_block 0 
setblock ~25 ~4 ~54 iron_block 0 
setblock ~25 ~4 ~56 iron_block 0 
setblock ~25 ~4 ~58 iron_block 0 
setblock ~25 ~4 ~60 iron_block 0 
setblock ~26 ~4 ~40 lit_redstone_lamp 0 
setblock ~26 ~4 ~42 lit_redstone_lamp 0 
setblock ~26 ~4 ~44 lit_redstone_lamp 0 
setblock ~26 ~4 ~46 lit_redstone_lamp 0 
setblock ~26 ~4 ~48 lit_redstone_lamp 0 
setblock ~26 ~4 ~50 lit_redstone_lamp 0 
setblock ~26 ~4 ~52 lit_redstone_lamp 0 
setblock ~26 ~4 ~54 lit_redstone_lamp 0 
setblock ~26 ~4 ~56 lit_redstone_lamp 0 
setblock ~26 ~4 ~58 lit_redstone_lamp 0 
setblock ~26 ~4 ~60 lit_redstone_lamp 0 
setblock ~27 ~4 ~40 iron_block 0 
setblock ~27 ~4 ~42 iron_block 0 
setblock ~27 ~4 ~44 iron_block 0 
setblock ~27 ~4 ~46 iron_block 0 
setblock ~27 ~4 ~48 iron_block 0 
setblock ~27 ~4 ~50 iron_block 0 
setblock ~27 ~4 ~52 iron_block 0 
setblock ~27 ~4 ~54 iron_block 0 
setblock ~27 ~4 ~56 iron_block 0 
setblock ~27 ~4 ~58 iron_block 0 
setblock ~27 ~4 ~60 iron_block 0 
setblock ~28 ~4 ~40 lit_redstone_lamp 0 
setblock ~28 ~4 ~42 lit_redstone_lamp 0 
setblock ~28 ~4 ~44 lit_redstone_lamp 0 
setblock ~28 ~4 ~46 lit_redstone_lamp 0 
setblock ~28 ~4 ~48 lit_redstone_lamp 0 
setblock ~28 ~4 ~50 lit_redstone_lamp 0 
setblock ~28 ~4 ~52 lit_redstone_lamp 0 
setblock ~28 ~4 ~54 lit_redstone_lamp 0 
setblock ~28 ~4 ~56 lit_redstone_lamp 0 
setblock ~28 ~4 ~58 lit_redstone_lamp 0 
setblock ~28 ~4 ~60 lit_redstone_lamp 0 
setblock ~29 ~4 ~40 iron_block 0 
setblock ~29 ~4 ~42 iron_block 0 
setblock ~29 ~4 ~44 iron_block 0 
setblock ~29 ~4 ~46 iron_block 0 
setblock ~29 ~4 ~48 iron_block 0 
setblock ~29 ~4 ~50 iron_block 0 
setblock ~29 ~4 ~52 iron_block 0 
setblock ~29 ~4 ~54 iron_block 0 
setblock ~29 ~4 ~56 iron_block 0 
setblock ~29 ~4 ~58 iron_block 0 
setblock ~29 ~4 ~60 iron_block 0  
fill ~30 ~4 ~39 ~30 ~4 ~62 stone 0  
fill ~31 ~4 ~41 ~31 ~113 ~41 stone 0  
fill ~31 ~4 ~47 ~31 ~113 ~47 stone 0  
fill ~31 ~4 ~53 ~31 ~113 ~53 stone 0  
fill ~31 ~4 ~59 ~31 ~113 ~59 stone 0  
fill ~38 ~4 ~8 ~39 ~4 ~8 stone 0  
fill ~38 ~4 ~14 ~39 ~4 ~14 stone 0  
fill ~38 ~4 ~20 ~39 ~4 ~20 stone 0  
fill ~38 ~4 ~26 ~39 ~4 ~26 stone 0  
fill ~39 ~4 ~5 ~63 ~4 ~5 stone 0  
fill ~39 ~4 ~6 ~39 ~4 ~29 stone 0  
fill ~40 ~4 ~6 ~62 ~4 ~6 iron_block 0  
fill ~40 ~4 ~7 ~40 ~4 ~28 iron_block 0  
fill ~40 ~4 ~29 ~63 ~4 ~29 stone 0 
setblock ~41 ~4 ~7 lit_redstone_lamp 0  
fill ~41 ~4 ~8 ~62 ~4 ~8 iron_block 0 
setblock ~41 ~4 ~9 lit_redstone_lamp 0  
fill ~41 ~4 ~10 ~62 ~4 ~10 iron_block 0 
setblock ~41 ~4 ~11 lit_redstone_lamp 0  
fill ~41 ~4 ~12 ~62 ~4 ~12 iron_block 0 
setblock ~41 ~4 ~13 lit_redstone_lamp 0  
fill ~41 ~4 ~14 ~54 ~4 ~14 iron_block 0 
setblock ~41 ~4 ~15 lit_redstone_lamp 0  
fill ~41 ~4 ~16 ~54 ~4 ~16 iron_block 0 
setblock ~41 ~4 ~17 lit_redstone_lamp 0  
fill ~41 ~4 ~18 ~54 ~4 ~18 iron_block 0 
setblock ~41 ~4 ~19 lit_redstone_lamp 0  
fill ~41 ~4 ~20 ~54 ~4 ~20 iron_block 0 
setblock ~41 ~4 ~21 lit_redstone_lamp 0  
fill ~41 ~4 ~22 ~62 ~4 ~22 iron_block 0 
setblock ~41 ~4 ~23 lit_redstone_lamp 0  
fill ~41 ~4 ~24 ~62 ~4 ~24 iron_block 0 
setblock ~41 ~4 ~25 lit_redstone_lamp 0  
fill ~41 ~4 ~26 ~62 ~4 ~26 iron_block 0 
setblock ~41 ~4 ~27 lit_redstone_lamp 0  
fill ~41 ~4 ~28 ~62 ~4 ~28 iron_block 0  
fill ~41 ~4 ~45 ~41 ~6 ~45 double_stone_slab 0 
setblock ~42 ~4 ~7 iron_block 0 
setblock ~42 ~4 ~9 iron_block 0 
setblock ~42 ~4 ~11 iron_block 0 
setblock ~42 ~4 ~13 iron_block 0 
setblock ~42 ~4 ~15 iron_block 0 
setblock ~42 ~4 ~17 iron_block 0 
setblock ~42 ~4 ~19 iron_block 0 
setblock ~42 ~4 ~21 iron_block 0 
setblock ~42 ~4 ~23 iron_block 0 
setblock ~42 ~4 ~25 iron_block 0 
setblock ~42 ~4 ~27 iron_block 0 
setblock ~43 ~4 ~7 lit_redstone_lamp 0 
setblock ~43 ~4 ~9 lit_redstone_lamp 0 
setblock ~43 ~4 ~11 lit_redstone_lamp 0 
setblock ~43 ~4 ~13 lit_redstone_lamp 0 
setblock ~43 ~4 ~15 lit_redstone_lamp 0 
setblock ~43 ~4 ~17 lit_redstone_lamp 0 
setblock ~43 ~4 ~19 lit_redstone_lamp 0 
setblock ~43 ~4 ~21 lit_redstone_lamp 0 
setblock ~43 ~4 ~23 lit_redstone_lamp 0 
setblock ~43 ~4 ~25 lit_redstone_lamp 0 
setblock ~43 ~4 ~27 lit_redstone_lamp 0 
setblock ~44 ~4 ~7 iron_block 0 
setblock ~44 ~4 ~9 iron_block 0 
setblock ~44 ~4 ~11 iron_block 0 
setblock ~44 ~4 ~13 iron_block 0 
setblock ~44 ~4 ~15 iron_block 0 
setblock ~44 ~4 ~17 iron_block 0 
setblock ~44 ~4 ~19 iron_block 0 
setblock ~44 ~4 ~21 iron_block 0 
setblock ~44 ~4 ~23 iron_block 0 
setblock ~44 ~4 ~25 iron_block 0 
setblock ~44 ~4 ~27 iron_block 0  
fill ~44 ~4 ~41 ~45 ~4 ~41 double_stone_slab 0 
setblock ~45 ~4 ~7 lit_redstone_lamp 0 
setblock ~45 ~4 ~9 lit_redstone_lamp 0 
setblock ~45 ~4 ~11 lit_redstone_lamp 0 
setblock ~45 ~4 ~13 lit_redstone_lamp 0 
setblock ~45 ~4 ~15 lit_redstone_lamp 0 
setblock ~45 ~4 ~17 lit_redstone_lamp 0 
setblock ~45 ~4 ~19 lit_redstone_lamp 0 
setblock ~45 ~4 ~21 lit_redstone_lamp 0 
setblock ~45 ~4 ~23 lit_redstone_lamp 0 
setblock ~45 ~4 ~25 lit_redstone_lamp 0 
setblock ~45 ~4 ~27 lit_redstone_lamp 0 
setblock ~46 ~4 ~7 iron_block 0 
setblock ~46 ~4 ~9 iron_block 0 
setblock ~46 ~4 ~11 iron_block 0 
setblock ~46 ~4 ~13 iron_block 0 
setblock ~46 ~4 ~15 iron_block 0 
setblock ~46 ~4 ~17 iron_block 0 
setblock ~46 ~4 ~19 iron_block 0 
setblock ~46 ~4 ~21 iron_block 0 
setblock ~46 ~4 ~23 iron_block 0 
setblock ~46 ~4 ~25 iron_block 0 
setblock ~46 ~4 ~27 iron_block 0 
setblock ~47 ~4 ~7 lit_redstone_lamp 0 
setblock ~47 ~4 ~9 lit_redstone_lamp 0 
setblock ~47 ~4 ~11 lit_redstone_lamp 0 
setblock ~47 ~4 ~13 lit_redstone_lamp 0 
setblock ~47 ~4 ~15 lit_redstone_lamp 0 
setblock ~47 ~4 ~17 lit_redstone_lamp 0 
setblock ~47 ~4 ~19 lit_redstone_lamp 0 
setblock ~47 ~4 ~21 lit_redstone_lamp 0 
setblock ~47 ~4 ~23 lit_redstone_lamp 0 
setblock ~47 ~4 ~25 lit_redstone_lamp 0 
setblock ~47 ~4 ~27 lit_redstone_lamp 0 
setblock ~48 ~4 ~7 iron_block 0 
setblock ~48 ~4 ~9 iron_block 0 
setblock ~48 ~4 ~11 iron_block 0 
setblock ~48 ~4 ~13 iron_block 0 
setblock ~48 ~4 ~15 iron_block 0 
setblock ~48 ~4 ~17 iron_block 0 
setblock ~48 ~4 ~19 iron_block 0 
setblock ~48 ~4 ~21 iron_block 0 
setblock ~48 ~4 ~23 iron_block 0 
setblock ~48 ~4 ~25 iron_block 0 
setblock ~48 ~4 ~27 iron_block 0 
setblock ~49 ~4 ~7 lit_redstone_lamp 0 
setblock ~49 ~4 ~9 lit_redstone_lamp 0 
setblock ~49 ~4 ~11 lit_redstone_lamp 0 
setblock ~49 ~4 ~13 lit_redstone_lamp 0 
setblock ~49 ~4 ~15 lit_redstone_lamp 0 
setblock ~49 ~4 ~17 lit_redstone_lamp 0 
setblock ~49 ~4 ~19 lit_redstone_lamp 0 
setblock ~49 ~4 ~21 lit_redstone_lamp 0 
setblock ~49 ~4 ~23 lit_redstone_lamp 0 
setblock ~49 ~4 ~25 lit_redstone_lamp 0 
setblock ~49 ~4 ~27 lit_redstone_lamp 0 
setblock ~50 ~4 ~7 iron_block 0 
setblock ~50 ~4 ~9 iron_block 0 
setblock ~50 ~4 ~11 iron_block 0 
setblock ~50 ~4 ~13 iron_block 0 
setblock ~50 ~4 ~15 iron_block 0 
setblock ~50 ~4 ~17 iron_block 0 
setblock ~50 ~4 ~19 iron_block 0 
setblock ~50 ~4 ~21 iron_block 0 
setblock ~50 ~4 ~23 iron_block 0 
setblock ~50 ~4 ~25 iron_block 0 
setblock ~50 ~4 ~27 iron_block 0 
setblock ~51 ~4 ~7 lit_redstone_lamp 0 
setblock ~51 ~4 ~9 lit_redstone_lamp 0 
setblock ~51 ~4 ~11 lit_redstone_lamp 0 
setblock ~51 ~4 ~13 lit_redstone_lamp 0 
setblock ~51 ~4 ~15 lit_redstone_lamp 0 
setblock ~51 ~4 ~17 lit_redstone_lamp 0 
setblock ~51 ~4 ~19 lit_redstone_lamp 0 
setblock ~51 ~4 ~21 lit_redstone_lamp 0 
setblock ~51 ~4 ~23 lit_redstone_lamp 0 
setblock ~51 ~4 ~25 lit_redstone_lamp 0 
setblock ~51 ~4 ~27 lit_redstone_lamp 0 
setblock ~52 ~4 ~7 iron_block 0 
setblock ~52 ~4 ~9 iron_block 0 
setblock ~52 ~4 ~11 iron_block 0 
setblock ~52 ~4 ~13 iron_block 0 
setblock ~52 ~4 ~15 iron_block 0 
setblock ~52 ~4 ~17 iron_block 0 
setblock ~52 ~4 ~19 iron_block 0 
setblock ~52 ~4 ~21 iron_block 0 
setblock ~52 ~4 ~23 iron_block 0 
setblock ~52 ~4 ~25 iron_block 0 
setblock ~52 ~4 ~27 iron_block 0 
setblock ~53 ~4 ~7 lit_redstone_lamp 0 
setblock ~53 ~4 ~9 lit_redstone_lamp 0 
setblock ~53 ~4 ~11 lit_redstone_lamp 0 
setblock ~53 ~4 ~13 lit_redstone_lamp 0 
setblock ~53 ~4 ~15 lit_redstone_lamp 0 
setblock ~53 ~4 ~17 lit_redstone_lamp 0 
setblock ~53 ~4 ~19 lit_redstone_lamp 0 
setblock ~53 ~4 ~21 lit_redstone_lamp 0 
setblock ~53 ~4 ~23 lit_redstone_lamp 0 
setblock ~53 ~4 ~25 lit_redstone_lamp 0 
setblock ~53 ~4 ~27 lit_redstone_lamp 0 
setblock ~54 ~4 ~7 iron_block 0 
setblock ~54 ~4 ~9 iron_block 0 
setblock ~54 ~4 ~11 iron_block 0  
fill ~54 ~4 ~13 ~54 ~7 ~13 iron_block 0  
fill ~54 ~4 ~15 ~56 ~4 ~15 iron_block 0  
fill ~54 ~4 ~17 ~56 ~4 ~17 iron_block 0  
fill ~54 ~4 ~19 ~56 ~4 ~19 iron_block 0  
fill ~54 ~4 ~21 ~54 ~7 ~21 iron_block 0 
setblock ~54 ~4 ~23 iron_block 0 
setblock ~54 ~4 ~25 iron_block 0 
setblock ~54 ~4 ~27 iron_block 0 
setblock ~55 ~4 ~7 lit_redstone_lamp 0 
setblock ~55 ~4 ~9 lit_redstone_lamp 0 
setblock ~55 ~4 ~11 lit_redstone_lamp 0 
setblock ~55 ~4 ~13 lit_redstone_lamp 0 
setblock ~55 ~4 ~21 lit_redstone_lamp 0 
setblock ~55 ~4 ~23 lit_redstone_lamp 0 
setblock ~55 ~4 ~25 lit_redstone_lamp 0 
setblock ~55 ~4 ~27 lit_redstone_lamp 0 
setblock ~56 ~4 ~7 iron_block 0 
setblock ~56 ~4 ~9 iron_block 0 
setblock ~56 ~4 ~11 iron_block 0  
fill ~56 ~4 ~13 ~56 ~7 ~13 iron_block 0  
fill ~56 ~4 ~21 ~56 ~7 ~21 iron_block 0 
setblock ~56 ~4 ~23 iron_block 0 
setblock ~56 ~4 ~25 iron_block 0 
setblock ~56 ~4 ~27 iron_block 0 
setblock ~57 ~4 ~7 lit_redstone_lamp 0 
setblock ~57 ~4 ~9 lit_redstone_lamp 0 
setblock ~57 ~4 ~11 lit_redstone_lamp 0 
setblock ~57 ~4 ~13 lit_redstone_lamp 0  
fill ~57 ~4 ~14 ~62 ~4 ~14 iron_block 0 
setblock ~57 ~4 ~15 lit_redstone_lamp 0  
fill ~57 ~4 ~16 ~62 ~4 ~16 iron_block 0 
setblock ~57 ~4 ~17 lit_redstone_lamp 0  
fill ~57 ~4 ~18 ~62 ~4 ~18 iron_block 0 
setblock ~57 ~4 ~19 lit_redstone_lamp 0  
fill ~57 ~4 ~20 ~62 ~4 ~20 iron_block 0 
setblock ~57 ~4 ~21 lit_redstone_lamp 0 
setblock ~57 ~4 ~23 lit_redstone_lamp 0 
setblock ~57 ~4 ~25 lit_redstone_lamp 0 
setblock ~57 ~4 ~27 lit_redstone_lamp 0 
setblock ~58 ~4 ~7 iron_block 0 
setblock ~58 ~4 ~9 iron_block 0 
setblock ~58 ~4 ~11 iron_block 0 
setblock ~58 ~4 ~13 iron_block 0 
setblock ~58 ~4 ~15 iron_block 0 
setblock ~58 ~4 ~17 iron_block 0 
setblock ~58 ~4 ~19 iron_block 0 
setblock ~58 ~4 ~21 iron_block 0 
setblock ~58 ~4 ~23 iron_block 0 
setblock ~58 ~4 ~25 iron_block 0 
setblock ~58 ~4 ~27 iron_block 0 
setblock ~59 ~4 ~7 lit_redstone_lamp 0 
setblock ~59 ~4 ~9 lit_redstone_lamp 0 
setblock ~59 ~4 ~11 lit_redstone_lamp 0 
setblock ~59 ~4 ~13 lit_redstone_lamp 0 
setblock ~59 ~4 ~15 lit_redstone_lamp 0 
setblock ~59 ~4 ~17 lit_redstone_lamp 0 
setblock ~59 ~4 ~19 lit_redstone_lamp 0 
setblock ~59 ~4 ~21 lit_redstone_lamp 0 
setblock ~59 ~4 ~23 lit_redstone_lamp 0 
setblock ~59 ~4 ~25 lit_redstone_lamp 0 
setblock ~59 ~4 ~27 lit_redstone_lamp 0 
setblock ~60 ~4 ~7 iron_block 0 
setblock ~60 ~4 ~9 iron_block 0 
setblock ~60 ~4 ~11 iron_block 0 
setblock ~60 ~4 ~13 iron_block 0 
setblock ~60 ~4 ~15 iron_block 0 
setblock ~60 ~4 ~17 iron_block 0 
setblock ~60 ~4 ~19 iron_block 0 
setblock ~60 ~4 ~21 iron_block 0 
setblock ~60 ~4 ~23 iron_block 0 
setblock ~60 ~4 ~25 iron_block 0 
setblock ~60 ~4 ~27 iron_block 0 
setblock ~61 ~4 ~7 lit_redstone_lamp 0 
setblock ~61 ~4 ~9 lit_redstone_lamp 0 
setblock ~61 ~4 ~11 lit_redstone_lamp 0 
setblock ~61 ~4 ~13 lit_redstone_lamp 0 
setblock ~61 ~4 ~15 lit_redstone_lamp 0 
setblock ~61 ~4 ~17 lit_redstone_lamp 0 
setblock ~61 ~4 ~19 lit_redstone_lamp 0 
setblock ~61 ~4 ~21 lit_redstone_lamp 0 
setblock ~61 ~4 ~23 lit_redstone_lamp 0 
setblock ~61 ~4 ~25 lit_redstone_lamp 0 
setblock ~61 ~4 ~27 lit_redstone_lamp 0 
setblock ~62 ~4 ~7 iron_block 0 
setblock ~62 ~4 ~9 iron_block 0 
setblock ~62 ~4 ~11 iron_block 0 
setblock ~62 ~4 ~13 iron_block 0 
setblock ~62 ~4 ~15 iron_block 0 
setblock ~62 ~4 ~17 iron_block 0 
setblock ~62 ~4 ~19 iron_block 0 
setblock ~62 ~4 ~21 iron_block 0 
setblock ~62 ~4 ~23 iron_block 0 
setblock ~62 ~4 ~25 iron_block 0 
setblock ~62 ~4 ~27 iron_block 0  
fill ~63 ~4 ~6 ~63 ~4 ~29 stone 0  
fill ~64 ~4 ~8 ~64 ~113 ~8 stone 0  
fill ~64 ~4 ~14 ~64 ~113 ~14 stone 0  
fill ~64 ~4 ~20 ~64 ~113 ~20 stone 0  
fill ~64 ~4 ~26 ~64 ~113 ~26 stone 0  
fill ~5 ~5 ~41 ~6 ~5 ~41 stone 0  
fill ~5 ~5 ~47 ~6 ~5 ~47 stone 0  
fill ~5 ~5 ~53 ~6 ~5 ~53 stone 0  
fill ~5 ~5 ~59 ~6 ~5 ~59 stone 0  
fill ~6 ~5 ~39 ~6 ~7 ~39 glass 0  
fill ~6 ~5 ~40 ~6 ~7 ~40 glass 0  
fill ~6 ~5 ~42 ~6 ~7 ~42 glass 0  
fill ~6 ~5 ~43 ~6 ~7 ~43 glass 0  
fill ~6 ~5 ~44 ~6 ~7 ~44 glass 0  
fill ~6 ~5 ~45 ~6 ~7 ~45 glass 0  
fill ~6 ~5 ~46 ~6 ~7 ~46 glass 0  
fill ~6 ~5 ~48 ~6 ~7 ~48 glass 0  
fill ~6 ~5 ~49 ~6 ~7 ~49 glass 0  
fill ~6 ~5 ~50 ~6 ~7 ~50 glass 0  
fill ~6 ~5 ~51 ~6 ~7 ~51 glass 0  
fill ~6 ~5 ~52 ~6 ~7 ~52 glass 0  
fill ~6 ~5 ~54 ~6 ~7 ~54 glass 0  
fill ~6 ~5 ~55 ~6 ~7 ~55 glass 0  
fill ~6 ~5 ~56 ~6 ~7 ~56 glass 0  
fill ~6 ~5 ~57 ~6 ~7 ~57 glass 0  
fill ~6 ~5 ~58 ~6 ~7 ~58 glass 0  
fill ~6 ~5 ~60 ~6 ~7 ~60 glass 0  
fill ~6 ~5 ~61 ~6 ~7 ~61 glass 0  
fill ~7 ~5 ~38 ~8 ~5 ~38 glass 0 
setblock ~7 ~5 ~39 redstone_wire 5 
setblock ~7 ~5 ~40 redstone_wire 6
setblock ~7 ~5 ~41 redstone_wire 7 
setblock ~7 ~5 ~42 redstone_wire 8 
setblock ~7 ~5 ~43 redstone_wire 9 
setblock ~7 ~5 ~44 redstone_wire 10 
setblock ~7 ~5 ~45 redstone_wire 11 
setblock ~7 ~5 ~46 redstone_wire 12 
setblock ~7 ~5 ~47 redstone_wire 13 
setblock ~7 ~5 ~48 redstone_wire 14 
setblock ~7 ~5 ~49 redstone_wire 15 
setblock ~7 ~5 ~50 redstone_torch 5 
setblock ~7 ~5 ~51 redstone_wire 15 
setblock ~7 ~5 ~52 redstone_wire 14 
setblock ~7 ~5 ~53 redstone_wire 13 
setblock ~7 ~5 ~54 redstone_wire 12 
setblock ~7 ~5 ~55 redstone_wire 11 
setblock ~7 ~5 ~56 redstone_wire 10 
setblock ~7 ~5 ~57 redstone_wire 9 
setblock ~7 ~5 ~58 redstone_wire 8 
setblock ~7 ~5 ~59 redstone_wire 7 
setblock ~7 ~5 ~60 redstone_wire 6 
setblock ~7 ~5 ~61 redstone_wire 5  
fill ~7 ~5 ~62 ~8 ~5 ~62 glass 0 
setblock ~8 ~5 ~39 redstone_wire 6 
setblock ~8 ~5 ~41 redstone_wire 6 
setblock ~8 ~5 ~43 redstone_wire 8 
setblock ~8 ~5 ~45 redstone_wire 10 
setblock ~8 ~5 ~47 redstone_wire 12 
setblock ~8 ~5 ~49 redstone_wire 14 
setblock ~8 ~5 ~51 redstone_wire 14 
setblock ~8 ~5 ~53 redstone_wire 12 
setblock ~8 ~5 ~55 redstone_wire 10 
setblock ~8 ~5 ~57 redstone_wire 8 
setblock ~8 ~5 ~59 redstone_wire 6 
setblock ~8 ~5 ~61 redstone_wire 6 
setblock ~9 ~5 ~39 redstone_wire 7 
setblock ~9 ~5 ~40 redstone_wire 6 
setblock ~9 ~5 ~41 redstone_wire 5 
setblock ~9 ~5 ~42 redstone_wire 6 
setblock ~9 ~5 ~43 redstone_wire 7 
setblock ~9 ~5 ~44 redstone_wire 8 
setblock ~9 ~5 ~45 redstone_wire 9 
setblock ~9 ~5 ~46 redstone_wire 10 
setblock ~9 ~5 ~47 redstone_wire 11 
setblock ~9 ~5 ~48 redstone_wire 12 
setblock ~9 ~5 ~49 redstone_wire 13 
setblock ~9 ~5 ~50 redstone_wire 12 
setblock ~9 ~5 ~51 redstone_wire 13 
setblock ~9 ~5 ~52 redstone_wire 12 
setblock ~9 ~5 ~53 redstone_wire 11 
setblock ~9 ~5 ~54 redstone_wire 10 
setblock ~9 ~5 ~55 redstone_wire 9 
setblock ~9 ~5 ~56 redstone_wire 8 
setblock ~9 ~5 ~57 redstone_wire 7 
setblock ~9 ~5 ~58 redstone_wire 6 
setblock ~9 ~5 ~59 redstone_wire 5 
setblock ~9 ~5 ~60 redstone_wire 6 
setblock ~9 ~5 ~61 redstone_wire 7  
fill ~10 ~5 ~38 ~14 ~5 ~38 glass 0 
setblock ~10 ~5 ~39 redstone_wire 8 
