fill ~1 ~0 ~1 ~16 ~0 ~1 nether_brick 0  
fill ~1 ~0 ~2 ~356 ~0 ~2 stone 0  
fill ~1 ~0 ~3 ~356 ~0 ~3 stone 0  
fill ~1 ~0 ~4 ~356 ~0 ~4 stone 0  
fill ~1 ~0 ~5 ~356 ~0 ~5 stone 0  
fill ~1 ~0 ~6 ~356 ~0 ~6 stone 0  
fill ~1 ~0 ~7 ~356 ~0 ~7 stone 0  
fill ~1 ~0 ~8 ~356 ~0 ~8 stone 0  
fill ~1 ~0 ~9 ~356 ~0 ~9 stone 0  
fill ~1 ~0 ~10 ~356 ~0 ~10 stone 0  
fill ~1 ~0 ~11 ~356 ~0 ~11 stone 0  
fill ~1 ~0 ~12 ~356 ~0 ~12 stone 0  
fill ~1 ~0 ~13 ~356 ~0 ~13 stone 0  
fill ~1 ~0 ~14 ~356 ~0 ~14 stone 0  
fill ~1 ~0 ~15 ~356 ~0 ~15 stone 0  
fill ~1 ~0 ~16 ~356 ~0 ~16 stone 0  
fill ~1 ~0 ~17 ~356 ~0 ~17 stone 0  
fill ~1 ~0 ~18 ~356 ~0 ~18 stone 0  
fill ~1 ~0 ~19 ~356 ~0 ~19 stone 0  
fill ~1 ~0 ~20 ~356 ~0 ~20 stone 0  
fill ~1 ~0 ~21 ~356 ~0 ~21 stone 0  
fill ~1 ~0 ~22 ~356 ~0 ~22 stone 0  
fill ~1 ~0 ~23 ~356 ~0 ~23 stone 0  
fill ~1 ~0 ~24 ~356 ~0 ~24 stone 0  
fill ~1 ~0 ~25 ~356 ~0 ~25 stone 0  
fill ~1 ~0 ~26 ~356 ~0 ~26 stone 0  
fill ~1 ~0 ~27 ~356 ~0 ~27 stone 0  
fill ~1 ~0 ~28 ~356 ~0 ~28 stone 0  
fill ~1 ~0 ~29 ~356 ~0 ~29 stone 0  
fill ~1 ~0 ~30 ~356 ~0 ~30 stone 0  
fill ~1 ~0 ~31 ~356 ~0 ~31 stone 0  
fill ~1 ~0 ~32 ~356 ~0 ~32 stone 0  
fill ~1 ~0 ~33 ~356 ~0 ~33 stone 0  
fill ~1 ~0 ~34 ~356 ~0 ~34 stone 0  
fill ~1 ~0 ~35 ~356 ~0 ~35 stone 0  
fill ~1 ~0 ~36 ~356 ~0 ~36 stone 0  
fill ~1 ~0 ~37 ~356 ~0 ~37 stone 0  
fill ~1 ~0 ~38 ~356 ~0 ~38 stone 0  
fill ~1 ~0 ~39 ~356 ~0 ~39 stone 0  
fill ~1 ~0 ~40 ~356 ~0 ~40 stone 0  
fill ~1 ~0 ~41 ~356 ~0 ~41 stone 0  
fill ~1 ~0 ~42 ~356 ~0 ~42 stone 0  
fill ~1 ~0 ~43 ~356 ~0 ~43 stone 0  
fill ~1 ~0 ~44 ~356 ~0 ~44 stone 0  
fill ~1 ~0 ~45 ~356 ~0 ~45 stone 0  
fill ~1 ~0 ~46 ~356 ~0 ~46 stone 0  
fill ~1 ~0 ~47 ~356 ~0 ~47 stone 0  
fill ~1 ~0 ~48 ~356 ~0 ~48 stone 0  
fill ~1 ~0 ~49 ~356 ~0 ~49 stone 0  
fill ~1 ~0 ~50 ~356 ~0 ~50 stone 0  
fill ~1 ~0 ~51 ~356 ~0 ~51 stone 0  
fill ~1 ~0 ~52 ~356 ~0 ~52 stone 0  
fill ~1 ~0 ~53 ~356 ~0 ~53 stone 0  
fill ~1 ~0 ~54 ~356 ~0 ~54 stone 0  
fill ~1 ~0 ~55 ~356 ~0 ~55 stone 0  
fill ~1 ~0 ~56 ~356 ~0 ~56 stone 0  
fill ~1 ~0 ~57 ~356 ~0 ~57 stone 0  
fill ~1 ~0 ~58 ~356 ~0 ~58 stone 0  
fill ~1 ~0 ~59 ~356 ~0 ~59 stone 0  
fill ~1 ~0 ~60 ~356 ~0 ~60 stone 0  
fill ~1 ~0 ~61 ~356 ~0 ~61 stone 0  
fill ~1 ~0 ~62 ~356 ~0 ~62 stone 0  
fill ~1 ~0 ~63 ~356 ~0 ~63 stone 0  
fill ~1 ~0 ~64 ~356 ~0 ~64 stone 0  
fill ~1 ~0 ~65 ~356 ~0 ~65 stone 0  
fill ~1 ~0 ~66 ~356 ~0 ~66 stone 0  
fill ~1 ~0 ~67 ~356 ~0 ~67 stone 0  
fill ~1 ~0 ~68 ~356 ~0 ~68 stone 0  
fill ~1 ~0 ~69 ~356 ~0 ~69 stone 0  
fill ~1 ~0 ~70 ~356 ~0 ~70 stone 0  
fill ~1 ~0 ~71 ~356 ~0 ~71 stone 0  
fill ~1 ~0 ~72 ~356 ~0 ~72 stone 0  
fill ~1 ~0 ~73 ~356 ~0 ~73 stone 0  
fill ~1 ~0 ~74 ~356 ~0 ~74 stone 0  
fill ~1 ~0 ~75 ~356 ~0 ~75 stone 0  
fill ~1 ~0 ~76 ~356 ~0 ~76 stone 0  
fill ~1 ~0 ~77 ~356 ~0 ~77 stone 0  
fill ~1 ~0 ~78 ~356 ~0 ~78 stone 0  
fill ~1 ~0 ~79 ~356 ~0 ~79 stone 0  
fill ~1 ~0 ~80 ~356 ~0 ~80 stone 0  
fill ~1 ~0 ~81 ~356 ~0 ~81 stone 0  
fill ~1 ~0 ~82 ~356 ~0 ~82 stone 0  
fill ~1 ~0 ~83 ~356 ~0 ~83 stone 0  
fill ~1 ~0 ~84 ~356 ~0 ~84 stone 0  
fill ~1 ~0 ~85 ~356 ~0 ~85 stone 0  
fill ~1 ~0 ~86 ~356 ~0 ~86 stone 0  
fill ~1 ~0 ~87 ~356 ~0 ~87 stone 0  
fill ~1 ~0 ~88 ~356 ~0 ~88 stone 0  
fill ~1 ~0 ~89 ~356 ~0 ~89 stone 0  
fill ~1 ~0 ~90 ~356 ~0 ~90 stone 0  
fill ~1 ~0 ~91 ~356 ~0 ~91 stone 0  
fill ~1 ~0 ~92 ~356 ~0 ~92 stone 0  
fill ~1 ~0 ~93 ~356 ~0 ~93 stone 0  
fill ~1 ~0 ~94 ~356 ~0 ~94 stone 0  
fill ~1 ~0 ~95 ~356 ~0 ~95 stone 0  
fill ~1 ~0 ~96 ~356 ~0 ~96 stone 0  
fill ~1 ~0 ~97 ~356 ~0 ~97 stone 0  
fill ~1 ~0 ~98 ~356 ~0 ~98 stone 0  
fill ~1 ~0 ~99 ~356 ~0 ~99 stone 0  
fill ~1 ~0 ~100 ~356 ~0 ~100 stone 0  
fill ~1 ~0 ~101 ~356 ~0 ~101 stone 0  
fill ~1 ~0 ~102 ~356 ~0 ~102 stone 0  
fill ~1 ~0 ~103 ~356 ~0 ~103 stone 0  
fill ~1 ~0 ~104 ~356 ~0 ~104 stone 0  
fill ~1 ~0 ~105 ~356 ~0 ~105 stone 0  
fill ~1 ~0 ~106 ~356 ~0 ~106 stone 0  
fill ~1 ~0 ~107 ~356 ~0 ~107 stone 0  
fill ~1 ~0 ~108 ~356 ~0 ~108 stone 0  
fill ~1 ~0 ~109 ~356 ~0 ~109 stone 0  
fill ~1 ~0 ~110 ~356 ~0 ~110 stone 0  
fill ~1 ~0 ~111 ~356 ~0 ~111 stone 0  
fill ~1 ~0 ~112 ~356 ~0 ~112 stone 0  
fill ~1 ~0 ~113 ~356 ~0 ~113 stone 0  
fill ~1 ~0 ~114 ~356 ~0 ~114 stone 0  
fill ~1 ~0 ~115 ~356 ~0 ~115 stone 0  
fill ~1 ~0 ~116 ~356 ~0 ~116 stone 0  
fill ~1 ~0 ~117 ~356 ~0 ~117 stone 0  
fill ~1 ~0 ~118 ~356 ~0 ~118 stone 0  
fill ~1 ~0 ~119 ~356 ~0 ~119 stone 0  
fill ~1 ~0 ~120 ~356 ~0 ~120 stone 0  
fill ~1 ~0 ~121 ~356 ~0 ~121 stone 0  
fill ~1 ~0 ~122 ~356 ~0 ~122 stone 0  
fill ~1 ~0 ~123 ~356 ~0 ~123 stone 0  
fill ~1 ~0 ~124 ~356 ~0 ~124 stone 0  
fill ~1 ~0 ~125 ~356 ~0 ~125 stone 0  
fill ~1 ~0 ~126 ~356 ~0 ~126 stone 0  
fill ~1 ~0 ~127 ~356 ~0 ~127 stone 0  
fill ~1 ~0 ~128 ~356 ~0 ~128 stone 0  
fill ~1 ~0 ~129 ~356 ~0 ~129 stone 0  
fill ~1 ~0 ~130 ~356 ~0 ~130 stone 0  
fill ~1 ~0 ~131 ~356 ~0 ~131 stone 0  
fill ~1 ~0 ~132 ~356 ~0 ~132 stone 0  
fill ~1 ~0 ~133 ~356 ~0 ~133 stone 0  
fill ~1 ~0 ~134 ~356 ~0 ~134 stone 0  
fill ~1 ~0 ~135 ~356 ~0 ~135 stone 0  
fill ~1 ~0 ~136 ~356 ~0 ~136 stone 0  
fill ~1 ~0 ~137 ~356 ~0 ~137 stone 0  
fill ~1 ~0 ~138 ~356 ~0 ~138 stone 0  
fill ~1 ~0 ~139 ~356 ~0 ~139 stone 0  
fill ~1 ~0 ~140 ~356 ~0 ~140 stone 0  
fill ~1 ~0 ~141 ~356 ~0 ~141 stone 0  
fill ~1 ~0 ~142 ~356 ~0 ~142 stone 0  
fill ~1 ~0 ~143 ~356 ~0 ~143 stone 0  
fill ~1 ~0 ~144 ~356 ~0 ~144 stone 0  
fill ~1 ~0 ~145 ~356 ~0 ~145 stone 0  
fill ~1 ~0 ~146 ~356 ~0 ~146 stone 0  
fill ~1 ~0 ~147 ~356 ~0 ~147 stone 0  
fill ~1 ~0 ~148 ~356 ~0 ~148 stone 0  
fill ~1 ~0 ~149 ~356 ~0 ~149 stone 0  
fill ~1 ~0 ~150 ~356 ~0 ~150 stone 0  
fill ~1 ~0 ~151 ~356 ~0 ~151 stone 0  
fill ~1 ~0 ~152 ~356 ~0 ~152 stone 0  
fill ~1 ~0 ~153 ~356 ~0 ~153 stone 0  
fill ~1 ~0 ~154 ~356 ~0 ~154 stone 0  
fill ~1 ~0 ~155 ~356 ~0 ~155 stone 0  
fill ~1 ~0 ~156 ~356 ~0 ~156 stone 0  
fill ~1 ~0 ~157 ~356 ~0 ~157 stone 0  
fill ~1 ~0 ~158 ~356 ~0 ~158 stone 0  
fill ~1 ~0 ~159 ~356 ~0 ~159 stone 0  
fill ~1 ~0 ~160 ~356 ~0 ~160 stone 0  
fill ~1 ~0 ~161 ~356 ~0 ~161 stone 0  
fill ~1 ~0 ~162 ~356 ~0 ~162 stone 0  
fill ~1 ~0 ~163 ~356 ~0 ~163 stone 0  
fill ~1 ~0 ~164 ~356 ~0 ~164 stone 0  
fill ~1 ~0 ~165 ~356 ~0 ~165 stone 0  
fill ~1 ~0 ~166 ~356 ~0 ~166 stone 0  
fill ~1 ~0 ~167 ~356 ~0 ~167 stone 0  
fill ~1 ~0 ~168 ~356 ~0 ~168 stone 0  
fill ~1 ~0 ~169 ~356 ~0 ~169 stone 0  
fill ~1 ~0 ~170 ~356 ~0 ~170 stone 0  
fill ~1 ~0 ~171 ~356 ~0 ~171 stone 0  
fill ~1 ~0 ~172 ~356 ~0 ~172 stone 0  
fill ~1 ~0 ~173 ~356 ~0 ~173 stone 0  
fill ~1 ~0 ~174 ~356 ~0 ~174 stone 0  
fill ~1 ~0 ~175 ~356 ~0 ~175 stone 0  
fill ~1 ~0 ~176 ~356 ~0 ~176 stone 0  
fill ~1 ~0 ~177 ~356 ~0 ~177 stone 0  
fill ~1 ~0 ~178 ~356 ~0 ~178 stone 0  
fill ~1 ~0 ~179 ~356 ~0 ~179 stone 0  
fill ~1 ~0 ~180 ~356 ~0 ~180 stone 0  
fill ~1 ~0 ~181 ~356 ~0 ~181 stone 0  
fill ~1 ~0 ~182 ~356 ~0 ~182 stone 0  
fill ~1 ~0 ~183 ~356 ~0 ~183 stone 0  
fill ~1 ~0 ~184 ~356 ~0 ~184 stone 0  
fill ~1 ~0 ~185 ~356 ~0 ~185 stone 0  
fill ~1 ~0 ~186 ~356 ~0 ~186 stone 0  
fill ~1 ~0 ~187 ~356 ~0 ~187 stone 0  
fill ~1 ~0 ~188 ~356 ~0 ~188 stone 0  
fill ~1 ~0 ~189 ~356 ~0 ~189 stone 0  
fill ~1 ~0 ~190 ~356 ~0 ~190 stone 0  
fill ~1 ~0 ~191 ~356 ~0 ~191 stone 0  
fill ~1 ~0 ~192 ~356 ~0 ~192 stone 0  
fill ~1 ~0 ~193 ~356 ~0 ~193 stone 0  
fill ~1 ~0 ~194 ~356 ~0 ~194 stone 0  
fill ~1 ~0 ~195 ~356 ~0 ~195 stone 0  
fill ~1 ~0 ~196 ~356 ~0 ~196 stone 0  
fill ~1 ~0 ~197 ~356 ~0 ~197 stone 0  
fill ~1 ~0 ~198 ~356 ~0 ~198 stone 0  
fill ~1 ~0 ~199 ~356 ~0 ~199 stone 0  
fill ~1 ~0 ~200 ~356 ~0 ~200 stone 0  
fill ~1 ~0 ~201 ~356 ~0 ~201 stone 0  
fill ~1 ~0 ~202 ~356 ~0 ~202 stone 0  
fill ~1 ~0 ~203 ~356 ~0 ~203 stone 0  
fill ~1 ~0 ~204 ~356 ~0 ~204 stone 0  
fill ~1 ~0 ~205 ~356 ~0 ~205 stone 0  
fill ~1 ~0 ~206 ~356 ~0 ~206 stone 0  
fill ~1 ~0 ~207 ~356 ~0 ~207 stone 0  
fill ~1 ~0 ~208 ~356 ~0 ~208 stone 0  
fill ~1 ~0 ~209 ~356 ~0 ~209 stone 0  
fill ~1 ~0 ~210 ~356 ~0 ~210 stone 0  
fill ~1 ~0 ~211 ~356 ~0 ~211 stone 0  
fill ~1 ~0 ~212 ~356 ~0 ~212 stone 0  
fill ~1 ~0 ~213 ~356 ~0 ~213 stone 0  
fill ~1 ~0 ~214 ~356 ~0 ~214 stone 0  
fill ~1 ~0 ~215 ~356 ~0 ~215 stone 0  
fill ~1 ~0 ~216 ~356 ~0 ~216 stone 0  
fill ~1 ~0 ~217 ~356 ~0 ~217 stone 0  
fill ~1 ~0 ~218 ~356 ~0 ~218 stone 0  
fill ~1 ~0 ~219 ~356 ~0 ~219 stone 0  
fill ~1 ~0 ~220 ~356 ~0 ~220 stone 0  
fill ~1 ~0 ~221 ~356 ~0 ~221 stone 0  
fill ~1 ~0 ~222 ~356 ~0 ~222 stone 0  
fill ~1 ~0 ~223 ~356 ~0 ~223 stone 0  
fill ~1 ~0 ~224 ~356 ~0 ~224 stone 0  
fill ~1 ~0 ~225 ~356 ~0 ~225 stone 0  
fill ~1 ~0 ~226 ~356 ~0 ~226 stone 0  
fill ~1 ~0 ~227 ~356 ~0 ~227 stone 0  
fill ~1 ~0 ~228 ~356 ~0 ~228 stone 0  
fill ~1 ~0 ~229 ~356 ~0 ~229 stone 0  
fill ~1 ~0 ~230 ~356 ~0 ~230 stone 0  
fill ~1 ~0 ~231 ~356 ~0 ~231 stone 0  
fill ~1 ~0 ~232 ~356 ~0 ~232 stone 0  
fill ~1 ~0 ~233 ~356 ~0 ~233 stone 0  
fill ~1 ~0 ~234 ~356 ~0 ~234 stone 0  
fill ~1 ~0 ~235 ~356 ~0 ~235 stone 0  
fill ~1 ~0 ~236 ~356 ~0 ~236 stone 0  
fill ~1 ~0 ~237 ~356 ~0 ~237 stone 0  
fill ~1 ~0 ~238 ~356 ~0 ~238 stone 0  
fill ~1 ~0 ~239 ~356 ~0 ~239 stone 0  
fill ~1 ~0 ~240 ~356 ~0 ~240 stone 0  
fill ~1 ~0 ~241 ~356 ~0 ~241 stone 0  
fill ~1 ~0 ~242 ~356 ~0 ~242 stone 0  
fill ~1 ~0 ~243 ~356 ~0 ~243 stone 0  
fill ~1 ~0 ~244 ~356 ~0 ~244 stone 0  
fill ~1 ~0 ~245 ~356 ~0 ~245 stone 0  
fill ~1 ~0 ~246 ~356 ~0 ~246 stone 0  
fill ~1 ~0 ~247 ~356 ~0 ~247 stone 0  
fill ~1 ~0 ~248 ~356 ~0 ~248 stone 0  
fill ~1 ~0 ~249 ~356 ~0 ~249 stone 0  
fill ~1 ~0 ~250 ~356 ~0 ~250 stone 0  
fill ~1 ~0 ~251 ~356 ~0 ~251 stone 0  
fill ~1 ~0 ~252 ~356 ~0 ~252 stone 0  
fill ~1 ~0 ~253 ~356 ~0 ~253 stone 0  
fill ~1 ~0 ~254 ~356 ~0 ~254 stone 0  
fill ~1 ~0 ~255 ~356 ~0 ~255 stone 0  
fill ~1 ~0 ~256 ~356 ~0 ~256 stone 0  
fill ~1 ~0 ~257 ~356 ~0 ~257 stone 0  
fill ~1 ~0 ~258 ~356 ~0 ~258 stone 0  
fill ~1 ~0 ~259 ~356 ~0 ~259 stone 0  
fill ~1 ~0 ~260 ~356 ~0 ~260 stone 0  
fill ~1 ~0 ~261 ~356 ~0 ~261 stone 0  
fill ~1 ~0 ~262 ~356 ~0 ~262 stone 0  
fill ~1 ~0 ~263 ~356 ~0 ~263 stone 0  
fill ~1 ~0 ~264 ~356 ~0 ~264 stone 0  
fill ~1 ~0 ~265 ~356 ~0 ~265 stone 0  
fill ~1 ~0 ~266 ~356 ~0 ~266 stone 0  
fill ~1 ~0 ~267 ~356 ~0 ~267 stone 0  
fill ~1 ~0 ~268 ~356 ~0 ~268 stone 0  
fill ~1 ~0 ~269 ~356 ~0 ~269 stone 0  
fill ~1 ~0 ~270 ~356 ~0 ~270 stone 0  
fill ~1 ~0 ~271 ~356 ~0 ~271 stone 0  
fill ~1 ~0 ~272 ~356 ~0 ~272 stone 0  
fill ~1 ~0 ~273 ~356 ~0 ~273 stone 0  
fill ~1 ~0 ~274 ~356 ~0 ~274 stone 0  
fill ~1 ~0 ~275 ~356 ~0 ~275 stone 0  
fill ~1 ~0 ~276 ~356 ~0 ~276 stone 0  
fill ~1 ~0 ~277 ~356 ~0 ~277 stone 0  
fill ~1 ~0 ~278 ~356 ~0 ~278 stone 0  
fill ~1 ~0 ~279 ~356 ~0 ~279 stone 0  
fill ~1 ~0 ~280 ~356 ~0 ~280 stone 0  
fill ~1 ~0 ~281 ~356 ~0 ~281 stone 0  
fill ~1 ~0 ~282 ~356 ~0 ~282 stone 0  
fill ~1 ~0 ~283 ~356 ~0 ~283 stone 0  
fill ~1 ~0 ~284 ~356 ~0 ~284 stone 0  
fill ~1 ~0 ~285 ~356 ~0 ~285 stone 0  
fill ~1 ~0 ~286 ~356 ~0 ~286 stone 0  
fill ~1 ~0 ~287 ~356 ~0 ~287 stone 0  
fill ~1 ~0 ~288 ~356 ~0 ~288 stone 0  
fill ~1 ~0 ~289 ~356 ~0 ~289 stone 0  
fill ~1 ~0 ~290 ~356 ~0 ~290 stone 0  
fill ~1 ~0 ~291 ~356 ~0 ~291 stone 0  
fill ~1 ~0 ~292 ~356 ~0 ~292 stone 0  
fill ~1 ~0 ~293 ~356 ~0 ~293 stone 0  
fill ~1 ~0 ~294 ~356 ~0 ~294 stone 0  
fill ~1 ~0 ~295 ~356 ~0 ~295 stone 0  
fill ~1 ~0 ~296 ~356 ~0 ~296 stone 0  
fill ~1 ~0 ~297 ~356 ~0 ~297 stone 0  
fill ~1 ~0 ~298 ~356 ~0 ~298 stone 0  
fill ~1 ~0 ~299 ~356 ~0 ~299 stone 0  
fill ~1 ~0 ~300 ~356 ~0 ~300 stone 0  
fill ~1 ~0 ~301 ~356 ~0 ~301 stone 0  
fill ~1 ~0 ~302 ~356 ~0 ~302 stone 0  
fill ~1 ~0 ~303 ~356 ~0 ~303 stone 0  
fill ~1 ~0 ~304 ~356 ~0 ~304 stone 0  
fill ~1 ~0 ~305 ~356 ~0 ~305 stone 0  
fill ~1 ~0 ~306 ~356 ~0 ~306 stone 0  
fill ~1 ~0 ~307 ~356 ~0 ~307 stone 0  
fill ~1 ~0 ~308 ~356 ~0 ~308 stone 0  
fill ~1 ~0 ~309 ~356 ~0 ~309 stone 0  
fill ~1 ~0 ~310 ~356 ~0 ~310 stone 0  
fill ~1 ~0 ~311 ~356 ~0 ~311 stone 0  
fill ~1 ~0 ~312 ~356 ~0 ~312 stone 0  
fill ~1 ~0 ~313 ~356 ~0 ~313 stone 0  
fill ~1 ~0 ~314 ~356 ~0 ~314 stone 0  
fill ~1 ~0 ~315 ~356 ~0 ~315 stone 0  
fill ~1 ~0 ~316 ~356 ~0 ~316 stone 0  
fill ~1 ~0 ~317 ~356 ~0 ~317 stone 0  
fill ~1 ~0 ~318 ~356 ~0 ~318 stone 0  
fill ~1 ~0 ~319 ~356 ~0 ~319 stone 0  
fill ~1 ~0 ~320 ~356 ~0 ~320 stone 0  
fill ~1 ~0 ~321 ~356 ~0 ~321 stone 0  
fill ~1 ~0 ~322 ~356 ~0 ~322 stone 0  
fill ~1 ~0 ~323 ~356 ~0 ~323 stone 0  
fill ~1 ~0 ~324 ~356 ~0 ~324 stone 0  
fill ~1 ~0 ~325 ~356 ~0 ~325 stone 0  
fill ~1 ~0 ~326 ~356 ~0 ~326 stone 0  
fill ~1 ~0 ~327 ~356 ~0 ~327 stone 0  
fill ~1 ~0 ~328 ~356 ~0 ~328 stone 0  
fill ~1 ~0 ~329 ~356 ~0 ~329 stone 0  
fill ~1 ~0 ~330 ~356 ~0 ~330 stone 0  
fill ~1 ~0 ~331 ~356 ~0 ~331 stone 0  
fill ~1 ~0 ~332 ~356 ~0 ~332 stone 0  
fill ~1 ~0 ~333 ~356 ~0 ~333 stone 0  
fill ~1 ~0 ~334 ~356 ~0 ~334 stone 0  
fill ~1 ~0 ~335 ~356 ~0 ~335 stone 0  
fill ~1 ~0 ~336 ~356 ~0 ~336 stone 0  
fill ~1 ~0 ~337 ~356 ~0 ~337 stone 0  
fill ~1 ~0 ~338 ~356 ~0 ~338 stone 0  
fill ~1 ~0 ~339 ~356 ~0 ~339 stone 0  
fill ~1 ~0 ~340 ~356 ~0 ~340 stone 0  
fill ~1 ~0 ~341 ~356 ~0 ~341 stone 0  
fill ~1 ~0 ~342 ~356 ~0 ~342 stone 0  
fill ~1 ~0 ~343 ~356 ~0 ~343 stone 0  
fill ~1 ~0 ~344 ~356 ~0 ~344 stone 0  
fill ~1 ~0 ~345 ~356 ~0 ~345 stone 0  
fill ~1 ~0 ~346 ~356 ~0 ~346 stone 0  
fill ~1 ~0 ~347 ~356 ~0 ~347 stone 0  
fill ~1 ~0 ~348 ~356 ~0 ~348 stone 0  
fill ~1 ~0 ~349 ~356 ~0 ~349 stone 0  
fill ~1 ~0 ~350 ~356 ~0 ~350 stone 0  
fill ~1 ~0 ~351 ~356 ~0 ~351 stone 0  
fill ~1 ~0 ~352 ~356 ~0 ~352 stone 0  
fill ~1 ~0 ~353 ~356 ~0 ~353 stone 0  
fill ~1 ~0 ~354 ~356 ~0 ~354 stone 0  
fill ~1 ~0 ~355 ~356 ~0 ~355 stone 0  
fill ~1 ~0 ~356 ~356 ~0 ~356 stone 0 
setblock ~17 ~0 ~1 stained_hardened_clay 7  
fill ~18 ~0 ~1 ~18 ~4 ~1 black_glazed_terracotta 0  
fill ~19 ~0 ~1 ~21 ~0 ~1 stained_hardened_clay 7  
fill ~22 ~0 ~1 ~27 ~0 ~1 black_glazed_terracotta 0  
fill ~28 ~0 ~1 ~28 ~1 ~1 stained_hardened_clay 12  
fill ~29 ~0 ~1 ~36 ~0 ~1 black_glazed_terracotta 0  
fill ~37 ~0 ~1 ~67 ~0 ~1 concrete 14  
fill ~68 ~0 ~1 ~73 ~0 ~1 concrete 12  
fill ~74 ~0 ~1 ~76 ~0 ~1 black_glazed_terracotta 0  
fill ~77 ~0 ~1 ~96 ~0 ~1 stained_hardened_clay 12 
setblock ~97 ~0 ~1 stained_hardened_clay 7  
fill ~98 ~0 ~1 ~104 ~0 ~1 black_glazed_terracotta 0  
fill ~105 ~0 ~1 ~105 ~0 ~1 stained_hardened_clay 7  
fill ~106 ~0 ~1 ~120 ~0 ~1 black_glazed_terracotta 0  
fill ~121 ~0 ~1 ~122 ~0 ~1 stained_hardened_clay 7  
fill ~123 ~0 ~1 ~138 ~0 ~1 stained_hardened_clay 12  
fill ~139 ~0 ~1 ~145 ~0 ~1 soul_sand 0  
fill ~146 ~0 ~1 ~147 ~0 ~1 stained_hardened_clay 12  
fill ~148 ~0 ~1 ~148 ~4 ~1 soul_sand 0  
fill ~149 ~0 ~1 ~154 ~0 ~1 stained_hardened_clay 12  
fill ~155 ~0 ~1 ~164 ~0 ~1 soul_sand 0  
fill ~165 ~0 ~1 ~169 ~0 ~1 concrete 7  
fill ~170 ~0 ~1 ~175 ~0 ~1 wool 7  
fill ~176 ~0 ~1 ~178 ~0 ~1 concrete 7  
fill ~179 ~0 ~1 ~182 ~0 ~1 gray_glazed_terracotta 0  
fill ~183 ~0 ~1 ~188 ~0 ~1 lapis_ore 0  
fill ~189 ~0 ~1 ~190 ~0 ~1 prismarine 1  
fill ~191 ~0 ~1 ~193 ~0 ~1 prismarine 0  
fill ~194 ~0 ~1 ~194 ~0 ~1 diamond_ore 0  
fill ~195 ~0 ~1 ~201 ~0 ~1 light_gray_glazed_terracotta 0  
fill ~202 ~0 ~1 ~204 ~0 ~1 clay 0  
fill ~205 ~0 ~1 ~205 ~8 ~1 light_gray_glazed_terracotta 0  
fill ~206 ~0 ~1 ~218 ~0 ~1 diamond_ore 0  
fill ~219 ~0 ~1 ~236 ~0 ~1 lapis_ore 0  
fill ~237 ~0 ~1 ~242 ~0 ~1 diamond_ore 0  
fill ~243 ~0 ~1 ~245 ~0 ~1 light_gray_glazed_terracotta 0  
fill ~246 ~0 ~1 ~247 ~0 ~1 diamond_ore 0  
fill ~248 ~0 ~1 ~257 ~0 ~1 lapis_ore 0  
fill ~258 ~0 ~1 ~259 ~0 ~1 prismarine 1  
fill ~260 ~0 ~1 ~261 ~0 ~1 prismarine 0  
fill ~262 ~0 ~1 ~266 ~0 ~1 light_gray_glazed_terracotta 0  
fill ~267 ~0 ~1 ~268 ~0 ~1 clay 0  
fill ~269 ~0 ~1 ~293 ~0 ~1 light_gray_glazed_terracotta 0  
fill ~294 ~0 ~1 ~294 ~2 ~1 diamond_ore 0  
fill ~295 ~0 ~1 ~300 ~0 ~1 lapis_ore 0  
fill ~301 ~0 ~1 ~306 ~0 ~1 gray_glazed_terracotta 0  
fill ~307 ~0 ~1 ~308 ~0 ~1 concrete 7  
fill ~309 ~0 ~1 ~309 ~1 ~1 prismarine 2  
fill ~310 ~0 ~1 ~311 ~0 ~1 concrete 7 
setblock ~312 ~0 ~1 prismarine 2  
fill ~313 ~0 ~1 ~324 ~0 ~1 wool 7  
fill ~325 ~0 ~1 ~345 ~0 ~1 concrete 7  
fill ~346 ~0 ~1 ~356 ~0 ~1 stained_hardened_clay 7  
fill ~1 ~1 ~1 ~5 ~1 ~1 nether_brick 0  
fill ~1 ~1 ~2 ~1 ~191 ~2 concrete 15  
fill ~1 ~1 ~3 ~1 ~191 ~3 concrete 15  
fill ~1 ~1 ~4 ~1 ~191 ~4 concrete 15  
fill ~1 ~1 ~5 ~1 ~191 ~5 concrete 15  
fill ~1 ~1 ~6 ~1 ~191 ~6 concrete 15  
fill ~1 ~1 ~7 ~1 ~112 ~7 concrete 15  
fill ~1 ~1 ~8 ~1 ~112 ~8 concrete 15  
fill ~1 ~1 ~9 ~1 ~111 ~9 concrete 15  
fill ~1 ~1 ~10 ~1 ~111 ~10 concrete 15  
fill ~1 ~1 ~11 ~1 ~111 ~11 concrete 15  
fill ~1 ~1 ~12 ~1 ~112 ~12 concrete 15  
fill ~1 ~1 ~13 ~1 ~113 ~13 concrete 15  
fill ~1 ~1 ~14 ~1 ~84 ~14 concrete 15  
fill ~1 ~1 ~15 ~1 ~82 ~15 concrete 15  
fill ~1 ~1 ~16 ~1 ~82 ~16 concrete 15  
fill ~1 ~1 ~17 ~1 ~81 ~17 concrete 15  
fill ~1 ~1 ~18 ~1 ~81 ~18 concrete 15  
fill ~1 ~1 ~19 ~1 ~81 ~19 concrete 15  
fill ~1 ~1 ~20 ~1 ~82 ~20 concrete 15  
fill ~1 ~1 ~21 ~1 ~82 ~21 concrete 15  
fill ~1 ~1 ~22 ~1 ~84 ~22 concrete 15  
fill ~1 ~1 ~23 ~1 ~133 ~23 concrete 15  
fill ~1 ~1 ~24 ~1 ~133 ~24 concrete 15  
fill ~1 ~1 ~25 ~1 ~191 ~25 concrete 15  
fill ~1 ~1 ~26 ~1 ~191 ~26 concrete 15  
fill ~1 ~1 ~27 ~1 ~191 ~27 concrete 15  
fill ~1 ~1 ~28 ~1 ~59 ~28 concrete 15  
fill ~1 ~1 ~29 ~1 ~58 ~29 concrete 15  
fill ~1 ~1 ~30 ~1 ~57 ~30 concrete 15  
fill ~1 ~1 ~31 ~1 ~57 ~31 concrete 15  
fill ~1 ~1 ~32 ~1 ~57 ~32 concrete 15  
fill ~1 ~1 ~33 ~1 ~56 ~33 concrete 15  
fill ~1 ~1 ~34 ~1 ~50 ~34 concrete 15  
fill ~1 ~1 ~35 ~1 ~49 ~35 concrete 15  
fill ~1 ~1 ~36 ~1 ~35 ~36 concrete 15  
fill ~1 ~1 ~37 ~1 ~34 ~37 concrete 15  
fill ~1 ~1 ~38 ~1 ~34 ~38 concrete 15  
fill ~1 ~1 ~39 ~1 ~34 ~39 concrete 15  
fill ~1 ~1 ~40 ~1 ~34 ~40 concrete 15  
fill ~1 ~1 ~41 ~1 ~34 ~41 concrete 15  
fill ~1 ~1 ~42 ~1 ~35 ~42 concrete 15  
fill ~1 ~1 ~43 ~1 ~35 ~43 concrete 15  
fill ~1 ~1 ~44 ~1 ~36 ~44 concrete 15  
fill ~1 ~1 ~45 ~1 ~51 ~45 concrete 15  
fill ~1 ~1 ~46 ~1 ~31 ~46 concrete 15  
fill ~1 ~1 ~47 ~1 ~30 ~47 concrete 15  
fill ~1 ~1 ~48 ~1 ~29 ~48 concrete 15  
fill ~1 ~1 ~49 ~1 ~29 ~49 concrete 15  
fill ~1 ~1 ~50 ~1 ~29 ~50 concrete 15  
fill ~1 ~1 ~51 ~1 ~29 ~51 concrete 15  
fill ~1 ~1 ~52 ~1 ~27 ~52 concrete 15  
fill ~1 ~1 ~53 ~1 ~26 ~53 concrete 15  
fill ~1 ~1 ~54 ~1 ~24 ~54 concrete 15  
fill ~1 ~1 ~55 ~1 ~12 ~55 concrete 15  
fill ~1 ~1 ~56 ~1 ~11 ~56 concrete 15 
setblock ~1 ~1 ~57 wool 15 
setblock ~1 ~1 ~58 wool 7 
setblock ~1 ~1 ~59 stained_hardened_clay 9 
setblock ~1 ~1 ~60 bedrock 0 
setblock ~1 ~1 ~61 concrete 15 
setblock ~1 ~1 ~62 coal_block 0  
fill ~1 ~1 ~63 ~1 ~12 ~63 concrete 15  
fill ~1 ~1 ~64 ~1 ~14 ~64 concrete 15  
fill ~1 ~1 ~65 ~1 ~13 ~65 concrete 15  
fill ~1 ~1 ~66 ~1 ~13 ~66 concrete 15  
fill ~1 ~1 ~67 ~1 ~8 ~67 concrete 15  
fill ~1 ~1 ~68 ~1 ~8 ~68 concrete 15  
fill ~1 ~1 ~69 ~1 ~7 ~69 concrete 15  
fill ~1 ~1 ~70 ~1 ~7 ~70 concrete 15  
fill ~1 ~1 ~71 ~1 ~8 ~71 concrete 15  
fill ~1 ~1 ~72 ~1 ~9 ~72 concrete 15  
fill ~1 ~1 ~73 ~1 ~9 ~73 concrete 15  
fill ~1 ~1 ~74 ~1 ~8 ~74 concrete 15  
fill ~1 ~1 ~75 ~1 ~8 ~75 concrete 15  
fill ~1 ~1 ~76 ~1 ~7 ~76 concrete 15  
fill ~1 ~1 ~77 ~1 ~6 ~77 concrete 15 
setblock ~1 ~1 ~78 coal_block 0  
fill ~1 ~1 ~79 ~1 ~1 ~82 stained_hardened_clay 15 
setblock ~1 ~1 ~83 coal_block 0  
fill ~1 ~1 ~84 ~1 ~2 ~84 concrete 15  
fill ~1 ~1 ~85 ~1 ~2 ~85 concrete 15  
fill ~1 ~1 ~86 ~1 ~8 ~86 coal_block 0  
fill ~1 ~1 ~87 ~1 ~4 ~87 coal_block 0 
setblock ~1 ~1 ~88 log2 1 
setblock ~1 ~1 ~89 stonebrick 1 
setblock ~1 ~1 ~90 wool 8  
fill ~1 ~1 ~91 ~1 ~2 ~91 log2 1  
fill ~1 ~1 ~92 ~1 ~6 ~92 stained_hardened_clay 15  
fill ~1 ~1 ~93 ~1 ~5 ~93 stained_hardened_clay 15  
fill ~1 ~1 ~94 ~1 ~5 ~94 stained_hardened_clay 15  
fill ~1 ~1 ~95 ~1 ~5 ~95 stained_hardened_clay 15  
fill ~1 ~1 ~96 ~1 ~2 ~96 stained_hardened_clay 15  
fill ~1 ~1 ~97 ~1 ~2 ~97 coal_block 0  
fill ~1 ~1 ~98 ~1 ~3 ~98 coal_block 0  
fill ~1 ~1 ~99 ~1 ~3 ~99 coal_block 0  
fill ~1 ~1 ~100 ~1 ~3 ~100 coal_block 0  
fill ~1 ~1 ~101 ~1 ~2 ~101 coal_block 0  
fill ~1 ~1 ~102 ~1 ~2 ~102 coal_block 0  
fill ~1 ~1 ~103 ~1 ~2 ~103 coal_block 0  
fill ~1 ~1 ~104 ~1 ~2 ~104 coal_block 0  
fill ~1 ~1 ~105 ~1 ~2 ~105 coal_block 0  
fill ~1 ~1 ~106 ~1 ~2 ~106 coal_block 0  
fill ~1 ~1 ~107 ~1 ~2 ~107 coal_block 0  
fill ~1 ~1 ~108 ~1 ~2 ~108 coal_block 0  
fill ~1 ~1 ~109 ~1 ~2 ~109 coal_block 0  
fill ~1 ~1 ~110 ~1 ~2 ~110 coal_block 0  
fill ~1 ~1 ~111 ~1 ~2 ~111 coal_block 0  
fill ~1 ~1 ~112 ~1 ~2 ~112 coal_block 0  
fill ~1 ~1 ~113 ~1 ~3 ~113 coal_block 0  
fill ~1 ~1 ~114 ~1 ~3 ~114 coal_block 0  
fill ~1 ~1 ~115 ~1 ~3 ~115 coal_block 0  
fill ~1 ~1 ~116 ~1 ~3 ~116 coal_block 0  
fill ~1 ~1 ~117 ~1 ~2 ~117 coal_block 0  
fill ~1 ~1 ~118 ~1 ~3 ~118 coal_block 0  
fill ~1 ~1 ~119 ~1 ~3 ~119 coal_block 0  
fill ~1 ~1 ~120 ~1 ~3 ~120 coal_block 0  
fill ~1 ~1 ~121 ~1 ~4 ~121 coal_block 0  
fill ~1 ~1 ~122 ~1 ~4 ~122 coal_block 0  
fill ~1 ~1 ~123 ~1 ~4 ~123 coal_block 0  
fill ~1 ~1 ~124 ~1 ~4 ~124 coal_block 0  
fill ~1 ~1 ~125 ~1 ~4 ~125 coal_block 0  
fill ~1 ~1 ~126 ~1 ~4 ~126 coal_block 0  
fill ~1 ~1 ~127 ~1 ~3 ~127 coal_block 0  
fill ~1 ~1 ~128 ~1 ~3 ~128 coal_block 0  
fill ~1 ~1 ~129 ~1 ~4 ~129 coal_block 0  
fill ~1 ~1 ~130 ~1 ~4 ~130 coal_block 0  
fill ~1 ~1 ~131 ~1 ~4 ~131 coal_block 0  
fill ~1 ~1 ~132 ~1 ~4 ~132 coal_block 0  
fill ~1 ~1 ~133 ~1 ~4 ~133 coal_block 0  
fill ~1 ~1 ~134 ~1 ~5 ~134 coal_block 0  
fill ~1 ~1 ~135 ~1 ~5 ~135 coal_block 0  
fill ~1 ~1 ~136 ~1 ~6 ~136 coal_block 0  
fill ~1 ~1 ~137 ~1 ~6 ~137 coal_block 0  
fill ~1 ~1 ~138 ~1 ~7 ~138 coal_block 0  
fill ~1 ~1 ~139 ~1 ~9 ~139 coal_block 0  
fill ~1 ~1 ~140 ~1 ~9 ~140 coal_block 0  
fill ~1 ~1 ~141 ~1 ~8 ~141 coal_block 0  
fill ~1 ~1 ~142 ~1 ~8 ~142 coal_block 0  
fill ~1 ~1 ~143 ~1 ~8 ~143 coal_block 0  
fill ~1 ~1 ~144 ~1 ~8 ~144 coal_block 0  
fill ~1 ~1 ~145 ~1 ~8 ~145 coal_block 0  
fill ~1 ~1 ~146 ~1 ~9 ~146 coal_block 0  
fill ~1 ~1 ~147 ~1 ~11 ~147 coal_block 0  
fill ~1 ~1 ~148 ~1 ~12 ~148 coal_block 0  
fill ~1 ~1 ~149 ~1 ~11 ~149 coal_block 0  
fill ~1 ~1 ~150 ~1 ~11 ~150 coal_block 0  
fill ~1 ~1 ~151 ~1 ~11 ~151 coal_block 0  
fill ~1 ~1 ~152 ~1 ~2 ~152 concrete 15  
fill ~1 ~1 ~153 ~1 ~3 ~153 concrete 15  
fill ~1 ~1 ~154 ~1 ~3 ~154 concrete 15  
fill ~1 ~1 ~155 ~1 ~4 ~155 concrete 15  
fill ~1 ~1 ~156 ~1 ~4 ~156 concrete 15  
fill ~1 ~1 ~157 ~1 ~5 ~157 concrete 15  
fill ~1 ~1 ~158 ~1 ~8 ~158 concrete 15  
fill ~1 ~1 ~159 ~1 ~9 ~159 concrete 15  
fill ~1 ~1 ~160 ~1 ~10 ~160 concrete 15  
fill ~1 ~1 ~161 ~1 ~12 ~161 concrete 15  
fill ~1 ~1 ~162 ~1 ~12 ~162 concrete 15  
fill ~1 ~1 ~163 ~1 ~13 ~163 concrete 15  
fill ~1 ~1 ~164 ~1 ~12 ~164 concrete 15  
fill ~1 ~1 ~165 ~1 ~13 ~165 concrete 15  
fill ~1 ~1 ~166 ~1 ~13 ~166 concrete 15  
fill ~1 ~1 ~167 ~1 ~4 ~167 coal_block 0 
setblock ~1 ~1 ~168 stained_hardened_clay 7 
setblock ~1 ~1 ~169 stone 5 
setblock ~1 ~1 ~170 concrete 0  
fill ~1 ~1 ~171 ~1 ~3 ~171 wool 0  
fill ~1 ~1 ~172 ~1 ~4 ~172 wool 0 
setblock ~1 ~1 ~173 quartz_block 0 
setblock ~1 ~1 ~174 clay 0 
setblock ~1 ~1 ~175 stained_hardened_clay 7  
fill ~1 ~1 ~176 ~1 ~4 ~176 coal_block 0  
fill ~1 ~1 ~177 ~1 ~20 ~177 concrete 15  
fill ~1 ~1 ~178 ~1 ~20 ~178 concrete 15  
fill ~1 ~1 ~179 ~1 ~20 ~179 concrete 15  
fill ~1 ~1 ~180 ~1 ~20 ~180 concrete 15  
fill ~1 ~1 ~181 ~1 ~21 ~181 concrete 15  
fill ~1 ~1 ~182 ~1 ~20 ~182 concrete 15  
fill ~1 ~1 ~183 ~1 ~19 ~183 concrete 15  
fill ~1 ~1 ~184 ~1 ~19 ~184 concrete 15  
fill ~1 ~1 ~185 ~1 ~23 ~185 concrete 15  
fill ~1 ~1 ~186 ~1 ~25 ~186 concrete 15  
fill ~1 ~1 ~187 ~1 ~25 ~187 concrete 15  
fill ~1 ~1 ~188 ~1 ~26 ~188 concrete 15  
fill ~1 ~1 ~189 ~1 ~26 ~189 concrete 15  
fill ~1 ~1 ~190 ~1 ~27 ~190 concrete 15  
fill ~1 ~1 ~191 ~1 ~27 ~191 concrete 15  
fill ~1 ~1 ~192 ~1 ~25 ~192 concrete 15  
fill ~1 ~1 ~193 ~1 ~25 ~193 concrete 15  
fill ~1 ~1 ~194 ~1 ~23 ~194 concrete 15  
fill ~1 ~1 ~195 ~1 ~29 ~195 concrete 15  
fill ~1 ~1 ~196 ~1 ~29 ~196 concrete 15  
fill ~1 ~1 ~197 ~1 ~30 ~197 concrete 15  
fill ~1 ~1 ~198 ~1 ~30 ~198 concrete 15  
fill ~1 ~1 ~199 ~1 ~4 ~199 coal_block 0 
setblock ~1 ~1 ~200 stained_hardened_clay 7 
setblock ~1 ~1 ~201 concrete 8 
setblock ~1 ~1 ~202 concrete 0 
setblock ~1 ~1 ~203 iron_block 0 
setblock ~1 ~1 ~204 concrete 0 
setblock ~1 ~1 ~205 stained_hardened_clay 9 
setblock ~1 ~1 ~206 concrete 15  
fill ~1 ~1 ~207 ~1 ~1 ~231 concrete 15  
fill ~1 ~1 ~232 ~1 ~1 ~233 coal_block 0  
fill ~1 ~1 ~234 ~1 ~32 ~234 concrete 15  
fill ~1 ~1 ~235 ~1 ~32 ~235 concrete 15  
fill ~1 ~1 ~236 ~1 ~33 ~236 concrete 15  
fill ~1 ~1 ~237 ~1 ~33 ~237 concrete 15  
fill ~1 ~1 ~238 ~1 ~11 ~238 concrete 15  
fill ~1 ~1 ~239 ~1 ~10 ~239 concrete 15  
fill ~1 ~1 ~240 ~1 ~10 ~240 concrete 15  
fill ~1 ~1 ~241 ~1 ~33 ~241 concrete 15  
fill ~1 ~1 ~242 ~1 ~34 ~242 concrete 15  
fill ~1 ~1 ~243 ~1 ~34 ~243 concrete 15  
fill ~1 ~1 ~244 ~1 ~34 ~244 concrete 15  
fill ~1 ~1 ~245 ~1 ~19 ~245 concrete 15  
fill ~1 ~1 ~246 ~1 ~19 ~246 concrete 15  
fill ~1 ~1 ~247 ~1 ~18 ~247 concrete 15  
fill ~1 ~1 ~248 ~1 ~18 ~248 concrete 15  
fill ~1 ~1 ~249 ~1 ~19 ~249 concrete 15  
fill ~1 ~1 ~250 ~1 ~19 ~250 concrete 15  
fill ~1 ~1 ~251 ~1 ~33 ~251 concrete 15  
fill ~1 ~1 ~252 ~1 ~33 ~252 concrete 15  
fill ~1 ~1 ~253 ~1 ~33 ~253 concrete 15  
fill ~1 ~1 ~254 ~1 ~35 ~254 concrete 15  
fill ~1 ~1 ~255 ~1 ~28 ~255 concrete 15  
fill ~1 ~1 ~256 ~1 ~27 ~256 concrete 15 
setblock ~1 ~1 ~257 wool 15 
setblock ~1 ~1 ~258 concrete 7 
setblock ~1 ~1 ~259 wool 7 
setblock ~1 ~1 ~260 concrete 15  
fill ~1 ~1 ~261 ~1 ~1 ~264 coal_block 0  
fill ~1 ~1 ~265 ~1 ~1 ~356 concrete 15  
fill ~2 ~1 ~356 ~4 ~1 ~356 concrete 3  
fill ~5 ~1 ~356 ~10 ~1 ~356 light_blue_glazed_terracotta 0  
fill ~6 ~1 ~1 ~13 ~1 ~1 stained_hardened_clay 7 
setblock ~11 ~1 ~356 concrete 3  
fill ~12 ~1 ~356 ~14 ~1 ~356 light_blue_glazed_terracotta 0  
fill ~14 ~1 ~1 ~17 ~1 ~1 nether_brick 0  
fill ~15 ~1 ~356 ~15 ~8 ~356 concrete 11  
fill ~16 ~1 ~356 ~16 ~2 ~356 concrete 3  
fill ~17 ~1 ~356 ~18 ~1 ~356 concrete 3  
fill ~19 ~1 ~1 ~21 ~1 ~1 stained_hardened_clay 7  
fill ~19 ~1 ~356 ~20 ~1 ~356 light_blue_glazed_terracotta 0  
fill ~21 ~1 ~356 ~22 ~1 ~356 concrete 3  
fill ~22 ~1 ~1 ~27 ~1 ~1 black_glazed_terracotta 0  
fill ~23 ~1 ~356 ~23 ~2 ~356 concrete 11  
fill ~24 ~1 ~356 ~25 ~1 ~356 cyan_glazed_terracotta 0  
fill ~26 ~1 ~356 ~27 ~1 ~356 wool 11  
fill ~28 ~1 ~356 ~29 ~1 ~356 concrete 3 
setblock ~29 ~1 ~1 stained_hardened_clay 12  
fill ~30 ~1 ~1 ~30 ~5 ~1 black_glazed_terracotta 0  
fill ~30 ~1 ~356 ~30 ~2 ~356 concrete 11  
fill ~31 ~1 ~1 ~31 ~2 ~1 stained_hardened_clay 12  
fill ~31 ~1 ~356 ~31 ~3 ~356 blue_glazed_terracotta 0  
fill ~32 ~1 ~1 ~34 ~1 ~1 concrete 12  
fill ~32 ~1 ~356 ~32 ~2 ~356 light_blue_glazed_terracotta 0 
setblock ~33 ~1 ~356 lapis_ore 0  
fill ~34 ~1 ~356 ~35 ~1 ~356 cyan_glazed_terracotta 0  
fill ~35 ~1 ~1 ~38 ~1 ~1 netherrack 0  
fill ~36 ~1 ~356 ~38 ~1 ~356 concrete 3  
fill ~39 ~1 ~1 ~65 ~1 ~1 concrete 14 
setblock ~39 ~1 ~356 concrete 11  
fill ~40 ~1 ~356 ~43 ~1 ~356 blue_glazed_terracotta 0 
setblock ~44 ~1 ~356 wool 11  
fill ~45 ~1 ~356 ~46 ~1 ~356 concrete 11 
setblock ~47 ~1 ~356 cyan_glazed_terracotta 0 
setblock ~48 ~1 ~356 blue_glazed_terracotta 0  
fill ~49 ~1 ~356 ~49 ~4 ~356 concrete 11 
setblock ~50 ~1 ~356 lapis_ore 0 
setblock ~51 ~1 ~356 cyan_glazed_terracotta 0 
setblock ~52 ~1 ~356 lapis_block 0 
setblock ~53 ~1 ~356 concrete 11 
setblock ~54 ~1 ~356 lapis_ore 0  
fill ~55 ~1 ~356 ~57 ~1 ~356 prismarine 2  
fill ~58 ~1 ~356 ~58 ~3 ~356 lapis_block 0  
fill ~59 ~1 ~356 ~61 ~1 ~356 blue_glazed_terracotta 0  
fill ~62 ~1 ~356 ~65 ~1 ~356 lapis_block 0  
fill ~66 ~1 ~1 ~69 ~1 ~1 netherrack 0  
fill ~66 ~1 ~356 ~70 ~1 ~356 concrete 11  
fill ~70 ~1 ~1 ~74 ~1 ~1 concrete 12  
fill ~71 ~1 ~356 ~80 ~1 ~356 lapis_block 0  
fill ~75 ~1 ~1 ~81 ~1 ~1 stained_hardened_clay 12  
fill ~81 ~1 ~356 ~85 ~1 ~356 prismarine 2  
fill ~82 ~1 ~1 ~84 ~1 ~1 black_glazed_terracotta 0  
fill ~85 ~1 ~1 ~94 ~1 ~1 stained_hardened_clay 12  
fill ~86 ~1 ~356 ~86 ~2 ~356 cyan_glazed_terracotta 0  
fill ~87 ~1 ~356 ~87 ~2 ~356 blue_glazed_terracotta 0  
fill ~88 ~1 ~356 ~93 ~1 ~356 lapis_block 0  
fill ~94 ~1 ~356 ~96 ~1 ~356 concrete 7  
fill ~95 ~1 ~1 ~95 ~3 ~1 stained_hardened_clay 7  
fill ~96 ~1 ~1 ~98 ~1 ~1 black_glazed_terracotta 0  
fill ~97 ~1 ~356 ~97 ~2 ~356 stained_hardened_clay 11 
setblock ~98 ~1 ~356 wool 7  
fill ~99 ~1 ~1 ~99 ~3 ~1 stained_hardened_clay 7  
fill ~99 ~1 ~356 ~99 ~2 ~356 blue_glazed_terracotta 0  
fill ~100 ~1 ~1 ~112 ~1 ~1 black_glazed_terracotta 0 
setblock ~100 ~1 ~356 stained_hardened_clay 11  
fill ~101 ~1 ~356 ~105 ~1 ~356 concrete 7 
setblock ~106 ~1 ~356 stained_hardened_clay 11  
fill ~107 ~1 ~356 ~108 ~1 ~356 concrete 11  
fill ~109 ~1 ~356 ~110 ~1 ~356 concrete 7 
setblock ~111 ~1 ~356 lapis_block 0 
setblock ~112 ~1 ~356 stained_hardened_clay 11  
fill ~113 ~1 ~1 ~114 ~1 ~1 stained_hardened_clay 7  
fill ~113 ~1 ~356 ~125 ~1 ~356 blue_glazed_terracotta 0  
fill ~115 ~1 ~1 ~116 ~1 ~1 black_glazed_terracotta 0  
fill ~117 ~1 ~1 ~119 ~1 ~1 stained_hardened_clay 7  
fill ~120 ~1 ~1 ~120 ~3 ~1 stained_hardened_clay 12  
fill ~121 ~1 ~1 ~121 ~0 ~1 stained_hardened_clay 7  
fill ~122 ~1 ~1 ~131 ~1 ~1 stained_hardened_clay 12  
fill ~126 ~1 ~356 ~132 ~1 ~356 concrete 11  
fill ~132 ~1 ~1 ~133 ~1 ~1 soul_sand 0  
fill ~133 ~1 ~356 ~133 ~2 ~356 stained_hardened_clay 11  
fill ~134 ~1 ~1 ~134 ~9 ~1 stained_hardened_clay 12 
setblock ~134 ~1 ~356 concrete 7  
fill ~135 ~1 ~1 ~136 ~1 ~1 soul_sand 0 
setblock ~135 ~1 ~356 stained_hardened_clay 11  
fill ~136 ~1 ~356 ~138 ~1 ~356 concrete 7  
fill ~137 ~1 ~1 ~139 ~1 ~1 stained_hardened_clay 12 
setblock ~139 ~1 ~356 blue_glazed_terracotta 0 
setblock ~140 ~1 ~1 soul_sand 0  
fill ~140 ~1 ~356 ~141 ~1 ~356 concrete 7  
fill ~141 ~1 ~1 ~141 ~2 ~1 stained_hardened_clay 12  
fill ~142 ~1 ~1 ~144 ~1 ~1 soul_sand 0 
setblock ~142 ~1 ~356 blue_glazed_terracotta 0  
fill ~143 ~1 ~356 ~144 ~1 ~356 concrete 7  
fill ~145 ~1 ~1 ~147 ~1 ~1 stained_hardened_clay 12  
fill ~145 ~1 ~356 ~154 ~1 ~356 concrete 11  
fill ~149 ~1 ~1 ~150 ~1 ~1 stained_hardened_clay 12  
fill ~151 ~1 ~1 ~154 ~1 ~1 soul_sand 0 
setblock ~155 ~1 ~1 stained_hardened_clay 12 
setblock ~155 ~1 ~356 lapis_block 0  
fill ~156 ~1 ~1 ~164 ~1 ~1 soul_sand 0 
setblock ~156 ~1 ~356 stained_hardened_clay 11  
fill ~157 ~1 ~356 ~159 ~1 ~356 concrete 7  
fill ~160 ~1 ~356 ~162 ~1 ~356 stained_hardened_clay 11  
fill ~163 ~1 ~356 ~164 ~1 ~356 concrete 11 
setblock ~165 ~1 ~1 wool 7 
setblock ~165 ~1 ~356 stained_hardened_clay 11  
fill ~166 ~1 ~1 ~170 ~1 ~1 concrete 7  
fill ~166 ~1 ~356 ~175 ~1 ~356 concrete 11  
fill ~171 ~1 ~1 ~174 ~1 ~1 wool 7  
fill ~175 ~1 ~1 ~178 ~1 ~1 concrete 7 
setblock ~176 ~1 ~356 lapis_block 0  
fill ~177 ~1 ~356 ~181 ~1 ~356 blue_glazed_terracotta 0  
fill ~179 ~1 ~1 ~182 ~1 ~1 gray_glazed_terracotta 0  
fill ~182 ~1 ~356 ~185 ~1 ~356 concrete 7  
fill ~183 ~1 ~1 ~188 ~1 ~1 lapis_ore 0  
fill ~186 ~1 ~356 ~186 ~3 ~356 stained_hardened_clay 11 
setblock ~187 ~1 ~356 concrete 7  
fill ~188 ~1 ~356 ~188 ~2 ~356 stained_hardened_clay 11  
fill ~189 ~1 ~1 ~189 ~0 ~1 prismarine 1 
setblock ~189 ~1 ~356 concrete 11  
fill ~190 ~1 ~1 ~194 ~1 ~1 prismarine 0  
fill ~190 ~1 ~356 ~190 ~3 ~356 lapis_block 0 
setblock ~191 ~1 ~356 stained_hardened_clay 11  
fill ~192 ~1 ~356 ~202 ~1 ~356 lapis_block 0  
fill ~195 ~1 ~1 ~201 ~1 ~1 light_gray_glazed_terracotta 0  
fill ~202 ~1 ~1 ~204 ~1 ~1 clay 0 
setblock ~203 ~1 ~356 wool 7  
fill ~204 ~1 ~356 ~208 ~1 ~356 stained_hardened_clay 11  
fill ~206 ~1 ~1 ~208 ~1 ~1 light_gray_glazed_terracotta 0  
summon Chicken ~132.5 ~1.0 ~58.5 
summon Chicken ~134.564583107 ~1.0 ~58.3343820402 
summon Chicken ~136.177396603 ~1.0 ~58.759146353 
summon Chicken ~137.36822424 ~1.0 ~60.3580569619 
summon Cow ~165.5 ~1.0 ~70.5 
summon Cow ~153.139697029 ~1.0 ~77.0625378997 
summon Cow ~163.713234246 ~1.0 ~71.2290950423 
summon Cow ~169.5 ~1.0 ~71.5 
summon Chicken ~350.718095155 ~1.0 ~101.551674075 
fill ~209 ~1 ~1 ~216 ~1 ~1 diamond_ore 0 
setblock ~209 ~1 ~356 lapis_block 0 
setblock ~210 ~1 ~356 wool 7  
fill ~211 ~1 ~356 ~212 ~1 ~356 lapis_block 0 
setblock ~213 ~1 ~356 blue_glazed_terracotta 0 
setblock ~214 ~1 ~356 cyan_glazed_terracotta 0  
fill ~215 ~1 ~356 ~215 ~2 ~356 blue_glazed_terracotta 0  
fill ~216 ~1 ~356 ~216 ~2 ~356 lapis_block 0  
fill ~217 ~1 ~1 ~236 ~1 ~1 lapis_ore 0  
fill ~217 ~1 ~356 ~218 ~1 ~356 blue_glazed_terracotta 0 
setblock ~219 ~1 ~356 lapis_block 0  
fill ~220 ~1 ~356 ~220 ~4 ~356 stained_hardened_clay 11  
fill ~221 ~1 ~356 ~221 ~2 ~356 concrete 7  
fill ~222 ~1 ~356 ~222 ~3 ~356 wool 7 
setblock ~223 ~1 ~356 concrete 7 
setblock ~224 ~1 ~356 stained_hardened_clay 11  
fill ~225 ~1 ~356 ~226 ~1 ~356 lapis_block 0 
setblock ~227 ~1 ~356 concrete 7  
fill ~228 ~1 ~356 ~230 ~1 ~356 lapis_block 0  
fill ~231 ~1 ~356 ~231 ~3 ~356 stained_hardened_clay 11  
fill ~232 ~1 ~356 ~233 ~1 ~356 blue_glazed_terracotta 0 
setblock ~234 ~1 ~356 stained_hardened_clay 11  
fill ~235 ~1 ~356 ~235 ~3 ~356 concrete 7  
fill ~236 ~1 ~356 ~238 ~1 ~356 concrete 11  
fill ~237 ~1 ~1 ~243 ~1 ~1 diamond_ore 0  
fill ~239 ~1 ~356 ~240 ~1 ~356 stained_hardened_clay 11  
fill ~241 ~1 ~356 ~245 ~1 ~356 concrete 11  
fill ~244 ~1 ~1 ~245 ~1 ~1 light_gray_glazed_terracotta 0  
fill ~246 ~1 ~1 ~247 ~1 ~1 diamond_ore 0  
fill ~246 ~1 ~356 ~250 ~1 ~356 stained_hardened_clay 11  
fill ~248 ~1 ~1 ~256 ~1 ~1 lapis_ore 0  
fill ~251 ~1 ~356 ~253 ~1 ~356 concrete 11  
fill ~254 ~1 ~356 ~255 ~1 ~356 lapis_block 0 
setblock ~256 ~1 ~356 stained_hardened_clay 11  
fill ~257 ~1 ~1 ~259 ~1 ~1 prismarine 1  
fill ~257 ~1 ~356 ~257 ~2 ~356 concrete 11  
fill ~258 ~1 ~356 ~260 ~1 ~356 stained_hardened_clay 11  
fill ~260 ~1 ~1 ~261 ~1 ~1 prismarine 0  
fill ~261 ~1 ~356 ~263 ~1 ~356 lapis_block 0  
fill ~262 ~1 ~1 ~293 ~1 ~1 light_gray_glazed_terracotta 0  
fill ~264 ~1 ~356 ~267 ~1 ~356 blue_glazed_terracotta 0 
setblock ~268 ~1 ~356 cyan_glazed_terracotta 0  
fill ~269 ~1 ~356 ~271 ~1 ~356 lapis_block 0  
fill ~272 ~1 ~356 ~272 ~8 ~356 blue_glazed_terracotta 0  
fill ~273 ~1 ~356 ~273 ~3 ~356 lapis_block 0  
fill ~274 ~1 ~356 ~276 ~1 ~356 concrete 11  
fill ~277 ~1 ~356 ~280 ~1 ~356 stained_hardened_clay 11  
fill ~281 ~1 ~356 ~290 ~1 ~356 concrete 15 
setblock ~291 ~1 ~356 wool 15  
fill ~292 ~1 ~356 ~293 ~1 ~356 obsidian 0  
fill ~294 ~1 ~356 ~295 ~1 ~356 concrete 15  
fill ~295 ~1 ~1 ~299 ~1 ~1 lapis_ore 0  
fill ~296 ~1 ~356 ~310 ~1 ~356 obsidian 0  
fill ~300 ~1 ~1 ~300 ~3 ~1 coal_ore 0  
fill ~301 ~1 ~1 ~305 ~1 ~1 gray_glazed_terracotta 0  
fill ~306 ~1 ~1 ~308 ~1 ~1 concrete 7  
fill ~310 ~1 ~1 ~310 ~0 ~1 concrete 7  
fill ~311 ~1 ~1 ~324 ~1 ~1 wool 7 
setblock ~311 ~1 ~356 concrete 15 
setblock ~312 ~1 ~356 concrete 7  
fill ~313 ~1 ~356 ~324 ~1 ~356 obsidian 0  
fill ~325 ~1 ~1 ~344 ~1 ~1 concrete 7  
fill ~325 ~1 ~356 ~325 ~3 ~356 wool 15  
fill ~326 ~1 ~356 ~328 ~1 ~356 coal_block 0  
fill ~329 ~1 ~356 ~356 ~1 ~356 concrete 15  
fill ~345 ~1 ~1 ~350 ~1 ~1 stained_hardened_clay 7  
fill ~351 ~1 ~1 ~355 ~1 ~1 concrete 7  
fill ~356 ~1 ~1 ~356 ~3 ~1 stained_hardened_clay 7 
setblock ~356 ~1 ~2 concrete 15  
fill ~356 ~1 ~3 ~356 ~7 ~3 coal_block 0  
fill ~356 ~1 ~4 ~356 ~7 ~4 coal_block 0  
fill ~356 ~1 ~5 ~356 ~7 ~5 coal_block 0  
fill ~356 ~1 ~6 ~356 ~8 ~6 coal_block 0  
fill ~356 ~1 ~7 ~356 ~8 ~7 coal_block 0  
fill ~356 ~1 ~8 ~356 ~9 ~8 coal_block 0  
fill ~356 ~1 ~9 ~356 ~2 ~9 concrete 15  
fill ~356 ~1 ~10 ~356 ~1 ~12 concrete 15  
fill ~356 ~1 ~13 ~356 ~1 ~14 coal_block 0 
setblock ~356 ~1 ~15 concrete 15  
fill ~356 ~1 ~16 ~356 ~1 ~17 stained_hardened_clay 15  
fill ~356 ~1 ~18 ~356 ~1 ~19 nether_brick 0  
fill ~356 ~1 ~20 ~356 ~2 ~20 stained_hardened_clay 15  
fill ~356 ~1 ~21 ~356 ~1 ~25 coal_block 0  
fill ~356 ~1 ~26 ~356 ~3 ~26 stained_hardened_clay 7  
fill ~356 ~1 ~27 ~356 ~2 ~27 concrete 15  
fill ~356 ~1 ~28 ~356 ~1 ~31 concrete 15  
fill ~356 ~1 ~32 ~356 ~2 ~32 stained_hardened_clay 7  
fill ~356 ~1 ~33 ~356 ~1 ~32 stained_hardened_clay 7  
fill ~356 ~1 ~34 ~356 ~1 ~35 concrete 15  
fill ~356 ~1 ~36 ~356 ~2 ~36 stained_hardened_clay 7 
setblock ~356 ~1 ~37 concrete 15 
setblock ~356 ~1 ~38 wool 15  
fill ~356 ~1 ~39 ~356 ~2 ~39 concrete 15  
fill ~356 ~1 ~40 ~356 ~6 ~40 concrete 15  
fill ~356 ~1 ~41 ~356 ~1 ~42 concrete 15 
setblock ~356 ~1 ~43 wool 15  
fill ~356 ~1 ~44 ~356 ~3 ~44 concrete 15  
fill ~356 ~1 ~45 ~356 ~6 ~45 concrete 15  
fill ~356 ~1 ~46 ~356 ~6 ~46 concrete 15 
setblock ~356 ~1 ~47 stained_hardened_clay 7  
fill ~356 ~1 ~48 ~356 ~1 ~49 concrete 7  
fill ~356 ~1 ~50 ~356 ~1 ~51 stained_hardened_clay 7  
fill ~356 ~1 ~52 ~356 ~2 ~52 concrete 7  
fill ~356 ~1 ~53 ~356 ~4 ~53 wool 7  
fill ~356 ~1 ~54 ~356 ~2 ~54 wool 7  
fill ~356 ~1 ~55 ~356 ~1 ~56 concrete 7  
fill ~356 ~1 ~57 ~356 ~1 ~59 wool 7 
setblock ~356 ~1 ~60 concrete 7  
fill ~356 ~1 ~61 ~356 ~1 ~63 concrete 15 
setblock ~356 ~1 ~64 stained_hardened_clay 7 
setblock ~356 ~1 ~65 bedrock 0 
setblock ~356 ~1 ~66 gold_ore 0 
setblock ~356 ~1 ~67 brown_glazed_terracotta 0  
fill ~356 ~1 ~68 ~356 ~3 ~68 stained_hardened_clay 8  
fill ~356 ~1 ~69 ~356 ~1 ~68 stained_hardened_clay 8 
setblock ~356 ~1 ~70 log2 0  
fill ~356 ~1 ~71 ~356 ~1 ~72 brown_glazed_terracotta 0  
fill ~356 ~1 ~73 ~356 ~1 ~74 gold_ore 0  
fill ~356 ~1 ~75 ~356 ~2 ~75 stained_hardened_clay 8  
fill ~356 ~1 ~76 ~356 ~3 ~76 stained_hardened_clay 8  
fill ~356 ~1 ~77 ~356 ~1 ~75 stained_hardened_clay 8 
setblock ~356 ~1 ~78 brown_glazed_terracotta 0 
setblock ~356 ~1 ~79 stained_hardened_clay 8 
setblock ~356 ~1 ~80 iron_ore 0 
setblock ~356 ~1 ~81 stained_hardened_clay 8  
fill ~356 ~1 ~82 ~356 ~2 ~82 brown_glazed_terracotta 0 
setblock ~356 ~1 ~83 stained_hardened_clay 8 
setblock ~356 ~1 ~84 brown_glazed_terracotta 0 
setblock ~356 ~1 ~85 orange_glazed_terracotta 0 
setblock ~356 ~1 ~86 gold_ore 0 
setblock ~356 ~1 ~87 brown_glazed_terracotta 0 
setblock ~356 ~1 ~88 log2 0 
setblock ~356 ~1 ~89 brown_glazed_terracotta 0  
fill ~356 ~1 ~90 ~356 ~1 ~91 stained_hardened_clay 8 
setblock ~356 ~1 ~92 brown_glazed_terracotta 0 
setblock ~356 ~1 ~93 iron_ore 0 
setblock ~356 ~1 ~94 brown_glazed_terracotta 0  
fill ~356 ~1 ~95 ~356 ~2 ~95 stained_hardened_clay 8  
fill ~356 ~1 ~96 ~356 ~1 ~97 gold_ore 0 
setblock ~356 ~1 ~98 brown_glazed_terracotta 0 
setblock ~356 ~1 ~99 iron_ore 0 
setblock ~356 ~1 ~100 gold_ore 0 
setblock ~356 ~1 ~101 orange_glazed_terracotta 0  
fill ~356 ~1 ~102 ~356 ~3 ~102 stained_hardened_clay 8 
setblock ~356 ~1 ~103 dirt 0 
setblock ~356 ~1 ~104 concrete 12 
setblock ~356 ~1 ~105 wool 12 
setblock ~356 ~1 ~106 noteblock 0 
setblock ~356 ~1 ~107 stained_hardened_clay 7  
fill ~356 ~1 ~108 ~356 ~2 ~108 concrete 7  
fill ~356 ~1 ~109 ~356 ~3 ~109 concrete 7  
fill ~356 ~1 ~110 ~356 ~9 ~110 concrete 7  
fill ~356 ~1 ~111 ~356 ~11 ~111 concrete 7  
fill ~356 ~1 ~112 ~356 ~4 ~112 concrete 7  
fill ~356 ~1 ~113 ~356 ~5 ~113 concrete 7  
fill ~356 ~1 ~114 ~356 ~4 ~114 concrete 7 
setblock ~356 ~1 ~115 wool 7  
fill ~356 ~1 ~116 ~356 ~2 ~116 concrete 7  
fill ~356 ~1 ~117 ~356 ~1 ~118 concrete 7 
setblock ~356 ~1 ~119 wool 7  
fill ~356 ~1 ~120 ~356 ~2 ~120 concrete 7  
fill ~356 ~1 ~121 ~356 ~3 ~121 concrete 7  
fill ~356 ~1 ~122 ~356 ~3 ~122 concrete 7  
fill ~356 ~1 ~123 ~356 ~3 ~123 concrete 7  
fill ~356 ~1 ~124 ~356 ~1 ~140 concrete 7  
fill ~356 ~1 ~141 ~356 ~9 ~141 wool 7  
fill ~356 ~1 ~142 ~356 ~1 ~144 wool 7 
setblock ~356 ~1 ~145 concrete 7  
fill ~356 ~1 ~146 ~356 ~23 ~146 wool 7  
fill ~356 ~1 ~147 ~356 ~4 ~147 wool 7 
setblock ~356 ~1 ~148 concrete 7  
fill ~356 ~1 ~149 ~356 ~4 ~149 wool 7  
fill ~356 ~1 ~150 ~356 ~9 ~150 wool 7 
setblock ~356 ~1 ~151 concrete 7  
fill ~356 ~1 ~152 ~356 ~7 ~152 wool 7  
fill ~356 ~1 ~153 ~356 ~1 ~154 wool 7  
fill ~356 ~1 ~155 ~356 ~6 ~155 concrete 7  
fill ~356 ~1 ~156 ~356 ~4 ~156 wool 7  
fill ~356 ~1 ~157 ~356 ~2 ~157 wool 7  
fill ~356 ~1 ~158 ~356 ~3 ~158 wool 7  
fill ~356 ~1 ~159 ~356 ~2 ~159 concrete 7  
fill ~356 ~1 ~160 ~356 ~3 ~160 concrete 7  
fill ~356 ~1 ~161 ~356 ~2 ~161 concrete 7  
fill ~356 ~1 ~162 ~356 ~1 ~159 concrete 7  
fill ~356 ~1 ~163 ~356 ~1 ~165 wool 7  
fill ~356 ~1 ~166 ~356 ~1 ~168 concrete 7 
setblock ~356 ~1 ~169 wool 7  
fill ~356 ~1 ~170 ~356 ~1 ~173 concrete 7  
fill ~356 ~1 ~174 ~356 ~3 ~174 wool 7  
fill ~356 ~1 ~175 ~356 ~2 ~175 concrete 7  
fill ~356 ~1 ~176 ~356 ~2 ~176 concrete 7  
fill ~356 ~1 ~177 ~356 ~2 ~177 concrete 7  
fill ~356 ~1 ~178 ~356 ~7 ~178 wool 7 
setblock ~356 ~1 ~179 concrete 7  
fill ~356 ~1 ~180 ~356 ~13 ~180 wool 7  
fill ~356 ~1 ~181 ~356 ~3 ~181 wool 7  
fill ~356 ~1 ~182 ~356 ~13 ~182 wool 7  
fill ~356 ~1 ~183 ~356 ~10 ~183 wool 7 
setblock ~356 ~1 ~184 concrete 7  
fill ~356 ~1 ~185 ~356 ~2 ~185 wool 7  
fill ~356 ~1 ~186 ~356 ~13 ~186 wool 7  
fill ~356 ~1 ~187 ~356 ~1 ~192 wool 7  
fill ~356 ~1 ~193 ~356 ~1 ~194 concrete 7  
fill ~356 ~1 ~195 ~356 ~15 ~195 wool 7  
fill ~356 ~1 ~196 ~356 ~8 ~196 wool 7  
fill ~356 ~1 ~197 ~356 ~1 ~199 concrete 7  
fill ~356 ~1 ~200 ~356 ~1 ~206 wool 7  
fill ~356 ~1 ~207 ~356 ~5 ~207 concrete 7  
fill ~356 ~1 ~208 ~356 ~1 ~209 concrete 7  
fill ~356 ~1 ~210 ~356 ~2 ~210 gray_glazed_terracotta 0  
fill ~356 ~1 ~211 ~356 ~1 ~215 wool 7  
fill ~356 ~1 ~216 ~356 ~3 ~216 concrete 7  
fill ~356 ~1 ~217 ~356 ~3 ~217 concrete 7  
fill ~356 ~1 ~218 ~356 ~2 ~218 concrete 7  
fill ~356 ~1 ~219 ~356 ~2 ~219 concrete 15  
fill ~356 ~1 ~220 ~356 ~4 ~220 stained_hardened_clay 7  
fill ~356 ~1 ~221 ~356 ~1 ~222 log2 1 
setblock ~356 ~1 ~223 stained_hardened_clay 7  
fill ~356 ~1 ~224 ~356 ~1 ~228 stained_hardened_clay 15 
setblock ~356 ~1 ~229 coal_block 0 
setblock ~356 ~1 ~230 stained_hardened_clay 15  
fill ~356 ~1 ~231 ~356 ~3 ~231 stained_hardened_clay 7  
fill ~356 ~1 ~232 ~356 ~1 ~231 stained_hardened_clay 7  
fill ~356 ~1 ~233 ~356 ~4 ~233 concrete 13  
fill ~356 ~1 ~234 ~356 ~1 ~233 concrete 13  
fill ~356 ~1 ~235 ~356 ~1 ~238 log2 1  
fill ~356 ~1 ~239 ~356 ~3 ~239 log 1  
fill ~356 ~1 ~240 ~356 ~2 ~240 log2 1  
fill ~356 ~1 ~241 ~356 ~1 ~242 stained_hardened_clay 15  
fill ~356 ~1 ~243 ~356 ~7 ~243 concrete 7  
fill ~356 ~1 ~244 ~356 ~1 ~243 concrete 7 
setblock ~356 ~1 ~245 concrete 7  
fill ~356 ~1 ~246 ~356 ~3 ~246 wool 7  
fill ~356 ~1 ~247 ~356 ~2 ~247 wool 7  
fill ~356 ~1 ~248 ~356 ~1 ~249 bedrock 0  
fill ~356 ~1 ~250 ~356 ~1 ~251 bookshelf 0 
setblock ~356 ~1 ~252 log 0 
setblock ~356 ~1 ~253 brown_glazed_terracotta 0  
fill ~356 ~1 ~254 ~356 ~3 ~254 stained_hardened_clay 8 
setblock ~356 ~1 ~255 brown_glazed_terracotta 0 
setblock ~356 ~1 ~256 log2 0  
fill ~356 ~1 ~257 ~356 ~1 ~258 brown_glazed_terracotta 0 
setblock ~356 ~1 ~259 log 6 
setblock ~356 ~1 ~260 iron_ore 0  
fill ~356 ~1 ~261 ~356 ~2 ~261 stained_hardened_clay 9 
setblock ~356 ~1 ~262 concrete 7  
fill ~356 ~1 ~263 ~356 ~1 ~265 concrete 7  
fill ~356 ~1 ~266 ~356 ~5 ~266 concrete 7  
fill ~356 ~1 ~267 ~356 ~1 ~269 concrete 7 
setblock ~356 ~1 ~270 wool 7 
setblock ~356 ~1 ~271 concrete 7  
fill ~356 ~1 ~272 ~356 ~1 ~274 stained_hardened_clay 7  
fill ~356 ~1 ~275 ~356 ~3 ~275 concrete 7 
setblock ~356 ~1 ~276 stained_hardened_clay 7  
fill ~356 ~1 ~277 ~356 ~1 ~281 wool 15  
fill ~356 ~1 ~282 ~356 ~2 ~282 concrete 15  
fill ~356 ~1 ~283 ~356 ~2 ~283 concrete 15  
fill ~356 ~1 ~284 ~356 ~2 ~284 concrete 15  
fill ~356 ~1 ~285 ~356 ~2 ~285 concrete 15  
fill ~356 ~1 ~286 ~356 ~1 ~287 coal_block 0 
setblock ~356 ~1 ~288 wool 15  
fill ~356 ~1 ~289 ~356 ~2 ~289 coal_block 0  
fill ~356 ~1 ~290 ~356 ~8 ~290 concrete 15  
fill ~356 ~1 ~291 ~356 ~1 ~290 concrete 15  
fill ~356 ~1 ~292 ~356 ~2 ~292 stained_hardened_clay 7 
setblock ~356 ~1 ~293 concrete 7 
setblock ~356 ~1 ~294 concrete 15  
fill ~356 ~1 ~295 ~356 ~2 ~295 stained_hardened_clay 7  
fill ~356 ~1 ~296 ~356 ~3 ~296 concrete 7  
fill ~356 ~1 ~297 ~356 ~4 ~297 stained_hardened_clay 7  
fill ~356 ~1 ~298 ~356 ~2 ~298 concrete 15  
fill ~356 ~1 ~299 ~356 ~1 ~304 wool 15  
fill ~356 ~1 ~305 ~356 ~6 ~305 concrete 15  
fill ~356 ~1 ~306 ~356 ~2 ~306 concrete 15  
fill ~356 ~1 ~307 ~356 ~2 ~307 concrete 15  
fill ~356 ~1 ~308 ~356 ~2 ~308 concrete 15  
fill ~356 ~1 ~309 ~356 ~2 ~309 concrete 15  
fill ~356 ~1 ~310 ~356 ~2 ~310 concrete 15 
setblock ~356 ~1 ~311 wool 15  
fill ~356 ~1 ~312 ~356 ~2 ~312 concrete 15  
fill ~356 ~1 ~313 ~356 ~2 ~313 concrete 15  
fill ~356 ~1 ~314 ~356 ~2 ~314 wool 15  
fill ~356 ~1 ~315 ~356 ~1 ~321 concrete 15 
setblock ~356 ~1 ~322 coal_block 0  
fill ~356 ~1 ~323 ~356 ~2 ~323 wool 15  
fill ~356 ~1 ~324 ~356 ~1 ~323 wool 15  
fill ~356 ~1 ~325 ~356 ~1 ~326 coal_block 0  
fill ~356 ~1 ~327 ~356 ~1 ~328 wool 15 
setblock ~356 ~1 ~329 coal_block 0 
setblock ~356 ~1 ~330 wool 15  
fill ~356 ~1 ~331 ~356 ~3 ~331 concrete 15  
fill ~356 ~1 ~332 ~356 ~1 ~331 concrete 15  
fill ~356 ~1 ~333 ~356 ~3 ~333 wool 15  
fill ~356 ~1 ~334 ~356 ~1 ~335 wool 15  
fill ~356 ~1 ~336 ~356 ~1 ~340 coal_block 0 
setblock ~356 ~1 ~341 concrete 15 
setblock ~356 ~1 ~342 coal_block 0  
fill ~356 ~1 ~343 ~356 ~2 ~343 concrete 15  
fill ~356 ~1 ~344 ~356 ~3 ~344 concrete 15  
fill ~356 ~1 ~345 ~356 ~2 ~345 concrete 15  
fill ~356 ~1 ~346 ~356 ~1 ~350 concrete 15 
setblock ~356 ~1 ~351 coal_block 0  
fill ~356 ~1 ~352 ~356 ~6 ~352 concrete 15  
fill ~356 ~1 ~353 ~356 ~3 ~353 coal_block 0  
fill ~356 ~1 ~354 ~356 ~2 ~354 coal_block 0  
fill ~356 ~1 ~355 ~356 ~2 ~355 coal_block 0  
fill ~1 ~2 ~1 ~5 ~2 ~1 nether_brick 0 
setblock ~1 ~2 ~57 coal_block 0  
fill ~1 ~2 ~58 ~1 ~2 ~60 concrete 15 
setblock ~1 ~2 ~61 coal_block 0  
fill ~1 ~2 ~62 ~1 ~11 ~62 concrete 15  
fill ~1 ~2 ~78 ~1 ~6 ~78 concrete 15  
fill ~1 ~2 ~79 ~1 ~2 ~82 coal_block 0  
fill ~1 ~2 ~83 ~1 ~3 ~83 concrete 15  
fill ~1 ~2 ~88 ~1 ~12 ~88 stained_hardened_clay 15  
fill ~1 ~2 ~89 ~1 ~2 ~90 soul_sand 0 
setblock ~1 ~2 ~168 concrete 7 
setblock ~1 ~2 ~169 stone 4  
fill ~1 ~2 ~170 ~1 ~3 ~170 wool 0  
fill ~1 ~2 ~173 ~1 ~3 ~173 wool 0 
setblock ~1 ~2 ~174 log 2  
fill ~1 ~2 ~175 ~1 ~3 ~175 concrete 7 
setblock ~1 ~2 ~200 wool 7  
fill ~1 ~2 ~201 ~1 ~3 ~201 log 2  
fill ~1 ~2 ~202 ~1 ~3 ~202 iron_block 0  
fill ~1 ~2 ~203 ~1 ~3 ~203 concrete 0  
fill ~1 ~2 ~204 ~1 ~3 ~204 iron_block 0 
setblock ~1 ~2 ~205 stone 3  
fill ~1 ~2 ~206 ~1 ~3 ~206 stained_hardened_clay 7  
fill ~1 ~2 ~207 ~1 ~3 ~207 coal_block 0  
fill ~1 ~2 ~208 ~1 ~34 ~208 concrete 15  
fill ~1 ~2 ~209 ~1 ~34 ~209 concrete 15  
fill ~1 ~2 ~210 ~1 ~34 ~210 concrete 15  
fill ~1 ~2 ~211 ~1 ~33 ~211 concrete 15  
fill ~1 ~2 ~212 ~1 ~32 ~212 concrete 15  
fill ~1 ~2 ~213 ~1 ~33 ~213 concrete 15  
fill ~1 ~2 ~214 ~1 ~33 ~214 concrete 15  
fill ~1 ~2 ~215 ~1 ~33 ~215 concrete 15  
fill ~1 ~2 ~216 ~1 ~20 ~216 concrete 15  
fill ~1 ~2 ~217 ~1 ~19 ~217 concrete 15  
fill ~1 ~2 ~218 ~1 ~18 ~218 concrete 15  
fill ~1 ~2 ~219 ~1 ~17 ~219 concrete 15  
fill ~1 ~2 ~220 ~1 ~16 ~220 concrete 15  
fill ~1 ~2 ~221 ~1 ~16 ~221 concrete 15  
fill ~1 ~2 ~222 ~1 ~15 ~222 concrete 15  
fill ~1 ~2 ~223 ~1 ~15 ~223 concrete 15  
fill ~1 ~2 ~224 ~1 ~15 ~224 concrete 15  
fill ~1 ~2 ~225 ~1 ~16 ~225 concrete 15  
fill ~1 ~2 ~226 ~1 ~16 ~226 concrete 15  
fill ~1 ~2 ~227 ~1 ~17 ~227 concrete 15  
fill ~1 ~2 ~228 ~1 ~34 ~228 concrete 15  
fill ~1 ~2 ~229 ~1 ~33 ~229 concrete 15  
fill ~1 ~2 ~230 ~1 ~33 ~230 concrete 15  
fill ~1 ~2 ~231 ~1 ~32 ~231 concrete 15  
fill ~1 ~2 ~232 ~1 ~30 ~232 concrete 15  
fill ~1 ~2 ~233 ~1 ~30 ~233 concrete 15  
fill ~1 ~2 ~257 ~1 ~3 ~257 concrete 7  
fill ~1 ~2 ~258 ~1 ~3 ~258 bedrock 0  
fill ~1 ~2 ~259 ~1 ~3 ~259 bedrock 0  
fill ~1 ~2 ~260 ~1 ~3 ~260 wool 7  
fill ~1 ~2 ~261 ~1 ~2 ~262 concrete 15 
setblock ~1 ~2 ~263 stained_hardened_clay 7 
setblock ~1 ~2 ~264 concrete 7 
setblock ~1 ~2 ~265 concrete 15 
setblock ~1 ~2 ~266 coal_block 0  
fill ~1 ~2 ~267 ~1 ~19 ~267 concrete 15  
fill ~1 ~2 ~268 ~1 ~19 ~268 concrete 15  
fill ~1 ~2 ~269 ~1 ~20 ~269 concrete 15  
fill ~1 ~2 ~270 ~1 ~20 ~270 concrete 15  
fill ~1 ~2 ~271 ~1 ~22 ~271 concrete 15  
fill ~1 ~2 ~272 ~1 ~42 ~272 concrete 15  
fill ~1 ~2 ~273 ~1 ~42 ~273 concrete 15  
fill ~1 ~2 ~274 ~1 ~42 ~274 concrete 15  
fill ~1 ~2 ~275 ~1 ~41 ~275 concrete 15  
fill ~1 ~2 ~276 ~1 ~41 ~276 concrete 15  
fill ~1 ~2 ~277 ~1 ~41 ~277 concrete 15  
fill ~1 ~2 ~278 ~1 ~41 ~278 concrete 15  
fill ~1 ~2 ~279 ~1 ~42 ~279 concrete 15  
fill ~1 ~2 ~280 ~1 ~42 ~280 concrete 15  
fill ~1 ~2 ~281 ~1 ~37 ~281 concrete 15  
fill ~1 ~2 ~282 ~1 ~36 ~282 concrete 15  
fill ~1 ~2 ~283 ~1 ~35 ~283 concrete 15  
fill ~1 ~2 ~284 ~1 ~35 ~284 concrete 15  
fill ~1 ~2 ~285 ~1 ~35 ~285 concrete 15  
fill ~1 ~2 ~286 ~1 ~35 ~286 concrete 15  
fill ~1 ~2 ~287 ~1 ~9 ~287 concrete 15  
fill ~1 ~2 ~288 ~1 ~8 ~288 concrete 15  
fill ~1 ~2 ~289 ~1 ~8 ~289 concrete 15  
fill ~1 ~2 ~290 ~1 ~8 ~290 concrete 15  
fill ~1 ~2 ~291 ~1 ~8 ~291 concrete 15  
fill ~1 ~2 ~292 ~1 ~8 ~292 concrete 15  
fill ~1 ~2 ~293 ~1 ~9 ~293 concrete 15  
fill ~1 ~2 ~294 ~1 ~23 ~294 concrete 15  
fill ~1 ~2 ~295 ~1 ~31 ~295 concrete 15  
fill ~1 ~2 ~296 ~1 ~31 ~296 concrete 15  
fill ~1 ~2 ~297 ~1 ~13 ~297 concrete 15  
fill ~1 ~2 ~298 ~1 ~27 ~298 concrete 15  
fill ~1 ~2 ~299 ~1 ~25 ~299 concrete 15  
fill ~1 ~2 ~300 ~1 ~25 ~300 concrete 15  
fill ~1 ~2 ~301 ~1 ~25 ~301 concrete 15  
fill ~1 ~2 ~302 ~1 ~25 ~302 concrete 15  
fill ~1 ~2 ~303 ~1 ~26 ~303 concrete 15  
fill ~1 ~2 ~304 ~1 ~60 ~304 concrete 15  
fill ~1 ~2 ~305 ~1 ~61 ~305 concrete 15  
fill ~1 ~2 ~306 ~1 ~42 ~306 concrete 15  
fill ~1 ~2 ~307 ~1 ~40 ~307 concrete 15  
fill ~1 ~2 ~308 ~1 ~40 ~308 concrete 15  
fill ~1 ~2 ~309 ~1 ~39 ~309 concrete 15  
fill ~1 ~2 ~310 ~1 ~39 ~310 concrete 15  
fill ~1 ~2 ~311 ~1 ~40 ~311 concrete 15  
fill ~1 ~2 ~312 ~1 ~40 ~312 concrete 15  
fill ~1 ~2 ~313 ~1 ~19 ~313 concrete 15  
fill ~1 ~2 ~314 ~1 ~19 ~314 concrete 15  
fill ~1 ~2 ~315 ~1 ~77 ~315 concrete 15  
fill ~1 ~2 ~316 ~1 ~79 ~316 concrete 15  
fill ~1 ~2 ~317 ~1 ~45 ~317 concrete 15  
fill ~1 ~2 ~318 ~1 ~43 ~318 concrete 15  
fill ~1 ~2 ~319 ~1 ~31 ~319 concrete 15  
fill ~1 ~2 ~320 ~1 ~30 ~320 concrete 15  
fill ~1 ~2 ~321 ~1 ~30 ~321 concrete 15  
fill ~1 ~2 ~322 ~1 ~30 ~322 concrete 15  
fill ~1 ~2 ~323 ~1 ~31 ~323 concrete 15  
fill ~1 ~2 ~324 ~1 ~44 ~324 concrete 15  
fill ~1 ~2 ~325 ~1 ~51 ~325 concrete 15  
fill ~1 ~2 ~326 ~1 ~51 ~326 concrete 15  
fill ~1 ~2 ~327 ~1 ~52 ~327 concrete 15  
fill ~1 ~2 ~328 ~1 ~57 ~328 concrete 15  
fill ~1 ~2 ~329 ~1 ~58 ~329 concrete 15  
fill ~1 ~2 ~330 ~1 ~59 ~330 concrete 15  
fill ~1 ~2 ~331 ~1 ~72 ~331 concrete 15  
fill ~1 ~2 ~332 ~1 ~72 ~332 concrete 15  
fill ~1 ~2 ~333 ~1 ~72 ~333 concrete 15  
fill ~1 ~2 ~334 ~1 ~71 ~334 concrete 15  
fill ~1 ~2 ~335 ~1 ~71 ~335 concrete 15  
fill ~1 ~2 ~336 ~1 ~71 ~336 concrete 15  
fill ~1 ~2 ~337 ~1 ~71 ~337 concrete 15  
fill ~1 ~2 ~338 ~1 ~71 ~338 concrete 15  
fill ~1 ~2 ~339 ~1 ~72 ~339 concrete 15  
fill ~1 ~2 ~340 ~1 ~112 ~340 concrete 15  
fill ~1 ~2 ~341 ~1 ~112 ~341 concrete 15  
fill ~1 ~2 ~342 ~1 ~112 ~342 concrete 15  
fill ~1 ~2 ~343 ~1 ~113 ~343 concrete 15  
fill ~1 ~2 ~344 ~1 ~146 ~344 concrete 15  
fill ~1 ~2 ~345 ~1 ~147 ~345 concrete 15  
fill ~1 ~2 ~346 ~1 ~191 ~346 concrete 15  
fill ~1 ~2 ~347 ~1 ~191 ~347 concrete 15  
fill ~1 ~2 ~348 ~1 ~191 ~348 concrete 15  
fill ~1 ~2 ~349 ~1 ~191 ~349 concrete 15  
fill ~1 ~2 ~350 ~1 ~191 ~350 concrete 15  
fill ~1 ~2 ~351 ~1 ~100 ~351 concrete 15  
fill ~1 ~2 ~352 ~1 ~100 ~352 concrete 15  
fill ~1 ~2 ~353 ~1 ~99 ~353 concrete 15  
fill ~1 ~2 ~354 ~1 ~99 ~354 concrete 15  
fill ~1 ~2 ~355 ~1 ~99 ~355 concrete 15  
fill ~1 ~2 ~356 ~1 ~100 ~356 concrete 15 
setblock ~2 ~2 ~356 wool 3  
fill ~3 ~2 ~356 ~11 ~2 ~356 light_blue_glazed_terracotta 0  
fill ~6 ~2 ~1 ~11 ~2 ~1 stained_hardened_clay 7  
fill ~12 ~2 ~1 ~17 ~2 ~1 nether_brick 0  
fill ~12 ~2 ~356 ~12 ~3 ~356 concrete 11  
fill ~13 ~2 ~356 ~14 ~2 ~356 light_blue_glazed_terracotta 0  
fill ~17 ~2 ~356 ~17 ~4 ~356 wool 3 
setblock ~18 ~2 ~356 concrete 3  
fill ~19 ~2 ~1 ~20 ~2 ~1 black_glazed_terracotta 0  
fill ~19 ~2 ~356 ~20 ~2 ~356 light_blue_glazed_terracotta 0 
setblock ~21 ~2 ~1 stained_hardened_clay 7 
setblock ~21 ~2 ~356 concrete 3  
fill ~22 ~2 ~1 ~30 ~2 ~1 black_glazed_terracotta 0  
fill ~22 ~2 ~356 ~22 ~3 ~356 concrete 11  
fill ~24 ~2 ~356 ~24 ~3 ~356 light_blue_glazed_terracotta 0  
fill ~25 ~2 ~356 ~26 ~2 ~356 concrete 11 
setblock ~27 ~2 ~356 wool 11  
fill ~28 ~2 ~356 ~28 ~5 ~356 concrete 11 
setblock ~29 ~2 ~356 concrete 3  
fill ~32 ~2 ~1 ~33 ~2 ~1 concrete 12 
setblock ~33 ~2 ~356 prismarine 1  
fill ~34 ~2 ~1 ~39 ~2 ~1 netherrack 0 
setblock ~34 ~2 ~356 lapis_ore 0  
fill ~35 ~2 ~356 ~37 ~2 ~356 concrete 3  
fill ~38 ~2 ~356 ~38 ~3 ~356 concrete 11  
fill ~39 ~2 ~356 ~39 ~4 ~356 cyan_glazed_terracotta 0  
fill ~40 ~2 ~1 ~56 ~2 ~1 concrete 14 
setblock ~40 ~2 ~356 lapis_ore 0  
fill ~41 ~2 ~356 ~41 ~3 ~356 concrete 11  
fill ~42 ~2 ~356 ~43 ~2 ~356 blue_glazed_terracotta 0  
fill ~44 ~2 ~356 ~44 ~3 ~356 lapis_block 0 
setblock ~45 ~2 ~356 wool 11  
fill ~46 ~2 ~356 ~46 ~4 ~356 lapis_block 0  
fill ~47 ~2 ~356 ~51 ~2 ~356 concrete 11  
fill ~52 ~2 ~356 ~53 ~2 ~356 wool 11  
fill ~54 ~2 ~356 ~54 ~3 ~356 cyan_glazed_terracotta 0  
fill ~55 ~2 ~356 ~57 ~2 ~356 prismarine 2 
setblock ~57 ~2 ~1 wool 14  
fill ~58 ~2 ~1 ~66 ~2 ~1 concrete 14  
fill ~59 ~2 ~356 ~64 ~2 ~356 lapis_block 0  
fill ~65 ~2 ~356 ~69 ~2 ~356 concrete 11  
fill ~67 ~2 ~1 ~71 ~2 ~1 netherrack 0 
setblock ~70 ~2 ~356 lapis_block 0  
fill ~71 ~2 ~356 ~72 ~2 ~356 concrete 7  
fill ~72 ~2 ~1 ~73 ~2 ~1 concrete 12 
setblock ~73 ~2 ~356 stained_hardened_clay 11  
fill ~74 ~2 ~1 ~82 ~2 ~1 stained_hardened_clay 12  
fill ~74 ~2 ~356 ~75 ~2 ~356 lapis_block 0  
fill ~76 ~2 ~356 ~77 ~2 ~356 blue_glazed_terracotta 0  
fill ~78 ~2 ~356 ~84 ~2 ~356 lapis_block 0  
fill ~83 ~2 ~1 ~86 ~2 ~1 black_glazed_terracotta 0 
setblock ~85 ~2 ~356 prismarine 2  
fill ~87 ~2 ~1 ~91 ~2 ~1 stained_hardened_clay 12 
setblock ~88 ~2 ~356 blue_glazed_terracotta 0  
fill ~89 ~2 ~356 ~93 ~2 ~356 lapis_block 0  
fill ~92 ~2 ~1 ~101 ~2 ~1 stained_hardened_clay 7 
setblock ~94 ~2 ~356 stained_hardened_clay 11  
fill ~95 ~2 ~356 ~95 ~3 ~356 wool 7 
setblock ~96 ~2 ~356 concrete 7 
setblock ~98 ~2 ~356 lapis_block 0 
setblock ~100 ~2 ~356 blue_glazed_terracotta 0  
fill ~101 ~2 ~356 ~101 ~3 ~356 concrete 7  
fill ~102 ~2 ~1 ~109 ~2 ~1 black_glazed_terracotta 0  
fill ~102 ~2 ~356 ~102 ~5 ~356 stained_hardened_clay 11  
fill ~103 ~2 ~356 ~106 ~2 ~356 concrete 7 
setblock ~107 ~2 ~356 concrete 15 
setblock ~108 ~2 ~356 stained_hardened_clay 11  
fill ~109 ~2 ~356 ~110 ~2 ~356 lapis_block 0  
fill ~110 ~2 ~1 ~111 ~2 ~1 stained_hardened_clay 7  
fill ~111 ~2 ~356 ~115 ~2 ~356 blue_glazed_terracotta 0 
setblock ~112 ~2 ~1 black_glazed_terracotta 0  
fill ~113 ~2 ~1 ~118 ~2 ~1 stained_hardened_clay 7  
fill ~116 ~2 ~356 ~116 ~3 ~356 concrete 11  
fill ~117 ~2 ~356 ~120 ~2 ~356 blue_glazed_terracotta 0 
setblock ~119 ~2 ~1 stained_hardened_clay 12  
fill ~121 ~2 ~1 ~127 ~2 ~1 stained_hardened_clay 12 
setblock ~121 ~2 ~356 lapis_block 0  
fill ~122 ~2 ~356 ~125 ~2 ~356 blue_glazed_terracotta 0  
fill ~126 ~2 ~356 ~132 ~2 ~356 concrete 11  
fill ~128 ~2 ~1 ~133 ~2 ~1 soul_sand 0 
setblock ~134 ~2 ~356 stained_hardened_clay 11  
fill ~135 ~2 ~1 ~143 ~2 ~1 stained_hardened_clay 12  
fill ~135 ~2 ~356 ~144 ~2 ~356 concrete 7  
fill ~144 ~2 ~1 ~144 ~4 ~1 soul_sand 0  
fill ~145 ~2 ~1 ~147 ~2 ~1 stained_hardened_clay 12  
fill ~145 ~2 ~356 ~145 ~6 ~356 stained_hardened_clay 11  
fill ~146 ~2 ~356 ~156 ~2 ~356 concrete 11  
fill ~149 ~2 ~1 ~163 ~2 ~1 soul_sand 0  
fill ~157 ~2 ~356 ~159 ~2 ~356 concrete 7  
fill ~160 ~2 ~356 ~160 ~1 ~356 stained_hardened_clay 11  
fill ~161 ~2 ~356 ~162 ~2 ~356 blue_glazed_terracotta 0  
fill ~163 ~2 ~356 ~163 ~4 ~356 concrete 7 
setblock ~164 ~2 ~1 stained_hardened_clay 12 
setblock ~164 ~2 ~356 stained_hardened_clay 11  
fill ~165 ~2 ~1 ~170 ~2 ~1 concrete 7 
setblock ~165 ~2 ~356 concrete 11  
fill ~166 ~2 ~356 ~167 ~2 ~356 stained_hardened_clay 11  
fill ~168 ~2 ~356 ~174 ~2 ~356 concrete 11  
fill ~171 ~2 ~1 ~176 ~2 ~1 wool 7 
setblock ~175 ~2 ~356 lapis_block 0  
fill ~176 ~2 ~356 ~181 ~2 ~356 blue_glazed_terracotta 0  
fill ~177 ~2 ~1 ~179 ~2 ~1 concrete 7  
fill ~180 ~2 ~1 ~182 ~2 ~1 gray_glazed_terracotta 0  
fill ~182 ~2 ~356 ~182 ~3 ~356 concrete 7  
fill ~183 ~2 ~1 ~187 ~2 ~1 lapis_ore 0 
setblock ~183 ~2 ~356 stained_hardened_clay 11 
setblock ~184 ~2 ~356 concrete 7  
fill ~185 ~2 ~356 ~185 ~3 ~356 stained_hardened_clay 11 
setblock ~187 ~2 ~356 stained_hardened_clay 11  
fill ~188 ~2 ~1 ~188 ~7 ~1 prismarine 1  
fill ~189 ~2 ~1 ~193 ~2 ~1 prismarine 0  
fill ~189 ~2 ~356 ~189 ~4 ~356 stained_hardened_clay 11  
fill ~191 ~2 ~356 ~206 ~2 ~356 lapis_block 0  
fill ~194 ~2 ~1 ~208 ~2 ~1 light_gray_glazed_terracotta 0 
setblock ~207 ~2 ~356 stained_hardened_clay 11  
fill ~208 ~2 ~356 ~208 ~5 ~356 lapis_block 0  
fill ~209 ~2 ~1 ~216 ~2 ~1 diamond_ore 0  
fill ~209 ~2 ~356 ~210 ~2 ~356 blue_glazed_terracotta 0  
fill ~211 ~2 ~356 ~213 ~2 ~356 lapis_block 0 
setblock ~214 ~2 ~356 blue_glazed_terracotta 0  
fill ~217 ~2 ~1 ~236 ~2 ~1 lapis_ore 0  
fill ~217 ~2 ~356 ~217 ~3 ~356 lapis_block 0 
setblock ~218 ~2 ~356 blue_glazed_terracotta 0  
fill ~219 ~2 ~356 ~219 ~5 ~356 stained_hardened_clay 11  
fill ~223 ~2 ~356 ~224 ~2 ~356 wool 7 
setblock ~225 ~2 ~356 stained_hardened_clay 11  
fill ~226 ~2 ~356 ~229 ~2 ~356 lapis_block 0 
setblock ~230 ~2 ~356 concrete 11  
fill ~232 ~2 ~356 ~236 ~2 ~356 concrete 7  
fill ~237 ~2 ~1 ~240 ~2 ~1 diamond_ore 0  
fill ~237 ~2 ~356 ~239 ~2 ~356 concrete 11 
setblock ~240 ~2 ~356 stained_hardened_clay 11 
setblock ~241 ~2 ~1 light_gray_glazed_terracotta 0  
fill ~241 ~2 ~356 ~245 ~2 ~356 concrete 11  
fill ~242 ~2 ~1 ~244 ~2 ~1 diamond_ore 0 
setblock ~245 ~2 ~1 light_gray_glazed_terracotta 0  
fill ~246 ~2 ~1 ~248 ~2 ~1 diamond_ore 0  
fill ~246 ~2 ~356 ~249 ~2 ~356 concrete 7  
fill ~249 ~2 ~1 ~256 ~2 ~1 lapis_ore 0  
fill ~250 ~2 ~356 ~250 ~3 ~356 stained_hardened_clay 11  
fill ~251 ~2 ~356 ~253 ~2 ~356 concrete 11  
fill ~254 ~2 ~356 ~255 ~2 ~356 lapis_block 0 
setblock ~256 ~2 ~356 concrete 11  
fill ~257 ~2 ~1 ~258 ~2 ~1 prismarine 1  
fill ~258 ~2 ~356 ~265 ~2 ~356 lapis_block 0  
fill ~259 ~2 ~1 ~261 ~2 ~1 prismarine 0  
fill ~262 ~2 ~1 ~288 ~2 ~1 light_gray_glazed_terracotta 0  
fill ~266 ~2 ~356 ~268 ~2 ~356 blue_glazed_terracotta 0  
fill ~269 ~2 ~356 ~269 ~5 ~356 lapis_block 0 
setblock ~270 ~2 ~356 wool 7  
fill ~271 ~2 ~356 ~271 ~3 ~356 lapis_block 0  
fill ~274 ~2 ~356 ~278 ~2 ~356 concrete 11  
fill ~279 ~2 ~356 ~280 ~2 ~356 stained_hardened_clay 11  
fill ~281 ~2 ~356 ~289 ~2 ~356 concrete 15  
fill ~289 ~2 ~1 ~294 ~2 ~1 diamond_ore 0  
fill ~290 ~2 ~356 ~290 ~4 ~356 obsidian 0  
fill ~291 ~2 ~356 ~291 ~3 ~356 concrete 7  
fill ~292 ~2 ~356 ~295 ~2 ~356 obsidian 0  
fill ~295 ~2 ~1 ~299 ~2 ~1 lapis_ore 0  
fill ~296 ~2 ~356 ~296 ~3 ~356 wool 15  
fill ~297 ~2 ~356 ~297 ~13 ~356 concrete 15  
fill ~298 ~2 ~356 ~300 ~2 ~356 obsidian 0  
fill ~301 ~2 ~1 ~306 ~2 ~1 gray_glazed_terracotta 0  
fill ~301 ~2 ~356 ~302 ~2 ~356 concrete 15  
fill ~303 ~2 ~356 ~313 ~2 ~356 obsidian 0  
fill ~307 ~2 ~1 ~309 ~2 ~1 concrete 7  
fill ~310 ~2 ~1 ~320 ~2 ~1 wool 7 
setblock ~314 ~2 ~356 wool 15  
fill ~315 ~2 ~356 ~315 ~3 ~356 concrete 15 
setblock ~316 ~2 ~356 stonebrick 0  
fill ~317 ~2 ~356 ~318 ~2 ~356 concrete 15  
fill ~319 ~2 ~356 ~324 ~2 ~356 obsidian 0  
fill ~321 ~2 ~1 ~345 ~2 ~1 concrete 7  
fill ~326 ~2 ~356 ~326 ~3 ~356 coal_block 0  
fill ~327 ~2 ~356 ~352 ~2 ~356 concrete 15  
fill ~346 ~2 ~1 ~350 ~2 ~1 stained_hardened_clay 7  
fill ~351 ~2 ~1 ~355 ~2 ~1 concrete 7 
setblock ~353 ~2 ~356 concrete 15  
fill ~354 ~2 ~356 ~356 ~2 ~356 concrete 15  
fill ~356 ~2 ~2 ~356 ~7 ~2 coal_block 0  
fill ~356 ~2 ~10 ~356 ~10 ~10 coal_block 0  
fill ~356 ~2 ~11 ~356 ~4 ~11 coal_block 0  
fill ~356 ~2 ~12 ~356 ~2 ~15 concrete 15 
setblock ~356 ~2 ~16 coal_block 0  
fill ~356 ~2 ~17 ~356 ~2 ~18 stained_hardened_clay 15 
setblock ~356 ~2 ~19 nether_brick 0 
setblock ~356 ~2 ~21 stained_hardened_clay 15  
fill ~356 ~2 ~22 ~356 ~2 ~25 coal_block 0  
fill ~356 ~2 ~28 ~356 ~3 ~28 stained_hardened_clay 7  
fill ~356 ~2 ~29 ~356 ~3 ~29 concrete 7  
fill ~356 ~2 ~30 ~356 ~4 ~30 stained_hardened_clay 7  
fill ~356 ~2 ~31 ~356 ~3 ~31 concrete 15 
setblock ~356 ~2 ~33 concrete 7  
fill ~356 ~2 ~34 ~356 ~3 ~34 stained_hardened_clay 7  
fill ~356 ~2 ~35 ~356 ~5 ~35 concrete 15  
fill ~356 ~2 ~37 ~356 ~3 ~37 stained_hardened_clay 7 
setblock ~356 ~2 ~38 concrete 15 
setblock ~356 ~2 ~41 stained_hardened_clay 7  
fill ~356 ~2 ~42 ~356 ~7 ~42 concrete 15  
fill ~356 ~2 ~43 ~356 ~2 ~42 concrete 15  
fill ~356 ~2 ~47 ~356 ~5 ~47 concrete 15  
fill ~356 ~2 ~48 ~356 ~3 ~48 concrete 15  
fill ~356 ~2 ~49 ~356 ~2 ~50 concrete 15 
setblock ~356 ~2 ~51 stained_hardened_clay 7  
fill ~356 ~2 ~55 ~356 ~4 ~55 wool 7 
setblock ~356 ~2 ~56 stained_hardened_clay 7  
fill ~356 ~2 ~57 ~356 ~4 ~57 concrete 7  
fill ~356 ~2 ~58 ~356 ~3 ~58 concrete 7  
fill ~356 ~2 ~59 ~356 ~2 ~62 wool 7 
setblock ~356 ~2 ~63 stained_hardened_clay 7  
fill ~356 ~2 ~64 ~356 ~3 ~64 concrete 15 
setblock ~356 ~2 ~65 wool 7 
setblock ~356 ~2 ~66 brown_glazed_terracotta 0 
setblock ~356 ~2 ~67 gold_ore 0 
setblock ~356 ~2 ~69 gold_ore 0  
fill ~356 ~2 ~70 ~356 ~2 ~71 stained_hardened_clay 8 
setblock ~356 ~2 ~72 brown_glazed_terracotta 0 
setblock ~356 ~2 ~73 log2 0 
setblock ~356 ~2 ~74 brown_glazed_terracotta 0  
fill ~356 ~2 ~77 ~356 ~3 ~77 brown_glazed_terracotta 0 
setblock ~356 ~2 ~78 orange_glazed_terracotta 0  
fill ~356 ~2 ~79 ~356 ~2 ~83 brown_glazed_terracotta 0 
setblock ~356 ~2 ~84 orange_glazed_terracotta 0  
fill ~356 ~2 ~85 ~356 ~3 ~85 stained_hardened_clay 8  
fill ~356 ~2 ~86 ~356 ~2 ~85 stained_hardened_clay 8 
setblock ~356 ~2 ~87 gold_ore 0  
fill ~356 ~2 ~88 ~356 ~2 ~89 stained_hardened_clay 8  
fill ~356 ~2 ~90 ~356 ~2 ~91 gold_ore 0 
setblock ~356 ~2 ~92 orange_glazed_terracotta 0 
setblock ~356 ~2 ~93 brown_glazed_terracotta 0 
setblock ~356 ~2 ~94 stained_hardened_clay 8  
fill ~356 ~2 ~96 ~356 ~2 ~97 brown_glazed_terracotta 0 
setblock ~356 ~2 ~98 orange_glazed_terracotta 0 
setblock ~356 ~2 ~99 brown_glazed_terracotta 0  
fill ~356 ~2 ~100 ~356 ~2 ~102 stained_hardened_clay 8  
fill ~356 ~2 ~103 ~356 ~3 ~103 crafting_table 0 
setblock ~356 ~2 ~104 wool 12 
setblock ~356 ~2 ~105 concrete 12  
fill ~356 ~2 ~106 ~356 ~6 ~106 wool 12 
setblock ~356 ~2 ~107 planks 1  
fill ~356 ~2 ~115 ~356 ~15 ~115 concrete 7  
fill ~356 ~2 ~117 ~356 ~2 ~118 wool 7  
fill ~356 ~2 ~119 ~356 ~5 ~119 concrete 7 
setblock ~356 ~2 ~124 wool 7  
fill ~356 ~2 ~125 ~356 ~4 ~125 concrete 7  
fill ~356 ~2 ~126 ~356 ~4 ~126 concrete 7  
fill ~356 ~2 ~127 ~356 ~6 ~127 concrete 7  
fill ~356 ~2 ~128 ~356 ~4 ~128 concrete 7  
fill ~356 ~2 ~129 ~356 ~3 ~129 wool 7  
fill ~356 ~2 ~130 ~356 ~6 ~130 concrete 7  
fill ~356 ~2 ~131 ~356 ~6 ~131 concrete 7  
fill ~356 ~2 ~132 ~356 ~7 ~132 concrete 7  
fill ~356 ~2 ~133 ~356 ~6 ~133 concrete 7  
fill ~356 ~2 ~134 ~356 ~6 ~134 concrete 7  
fill ~356 ~2 ~135 ~356 ~7 ~135 concrete 7  
fill ~356 ~2 ~136 ~356 ~6 ~136 concrete 7  
fill ~356 ~2 ~137 ~356 ~5 ~137 concrete 7  
fill ~356 ~2 ~138 ~356 ~5 ~138 concrete 7  
fill ~356 ~2 ~139 ~356 ~5 ~139 concrete 7 
setblock ~356 ~2 ~140 wool 7  
fill ~356 ~2 ~142 ~356 ~2 ~144 concrete 7  
fill ~356 ~2 ~145 ~356 ~6 ~145 wool 7  
fill ~356 ~2 ~148 ~356 ~4 ~148 wool 7 
setblock ~356 ~2 ~151 wool 7  
fill ~356 ~2 ~153 ~356 ~4 ~153 concrete 7  
fill ~356 ~2 ~154 ~356 ~4 ~154 concrete 7  
fill ~356 ~2 ~162 ~356 ~3 ~162 wool 7  
fill ~356 ~2 ~163 ~356 ~9 ~163 concrete 7  
fill ~356 ~2 ~164 ~356 ~9 ~164 concrete 7  
fill ~356 ~2 ~165 ~356 ~2 ~166 wool 7  
fill ~356 ~2 ~167 ~356 ~3 ~167 concrete 7  
fill ~356 ~2 ~168 ~356 ~9 ~168 concrete 7  
fill ~356 ~2 ~169 ~356 ~2 ~167 concrete 7 
setblock ~356 ~2 ~170 prismarine 2 
setblock ~356 ~2 ~171 concrete 7  
fill ~356 ~2 ~172 ~356 ~3 ~172 prismarine 2 
setblock ~356 ~2 ~173 concrete 7  
fill ~356 ~2 ~179 ~356 ~14 ~179 wool 7 
setblock ~356 ~2 ~184 wool 7  
fill ~356 ~2 ~187 ~356 ~2 ~189 concrete 7  
fill ~356 ~2 ~190 ~356 ~12 ~190 wool 7  
fill ~356 ~2 ~191 ~356 ~2 ~190 wool 7  
fill ~356 ~2 ~192 ~356 ~3 ~192 concrete 7  
fill ~356 ~2 ~193 ~356 ~18 ~193 wool 7 
setblock ~356 ~2 ~194 concrete 7  
fill ~356 ~2 ~197 ~356 ~15 ~197 wool 7  
fill ~356 ~2 ~198 ~356 ~15 ~198 wool 7  
fill ~356 ~2 ~199 ~356 ~3 ~199 concrete 7  
fill ~356 ~2 ~200 ~356 ~2 ~199 concrete 7  
fill ~356 ~2 ~201 ~356 ~11 ~201 wool 7  
fill ~356 ~2 ~202 ~356 ~4 ~202 wool 7  
fill ~356 ~2 ~203 ~356 ~5 ~203 wool 7  
fill ~356 ~2 ~204 ~356 ~6 ~204 wool 7  
fill ~356 ~2 ~205 ~356 ~4 ~205 wool 7  
fill ~356 ~2 ~206 ~356 ~4 ~206 wool 7  
fill ~356 ~2 ~208 ~356 ~4 ~208 wool 7 
setblock ~356 ~2 ~209 concrete 7  
fill ~356 ~2 ~211 ~356 ~2 ~212 concrete 7 
setblock ~356 ~2 ~213 concrete 7  
fill ~356 ~2 ~214 ~356 ~3 ~214 wool 7  
fill ~356 ~2 ~215 ~356 ~3 ~215 concrete 7 
setblock ~356 ~2 ~221 stained_hardened_clay 12 
setblock ~356 ~2 ~222 nether_brick 0  
fill ~356 ~2 ~223 ~356 ~2 ~224 log2 1  
fill ~356 ~2 ~225 ~356 ~2 ~226 nether_brick 0  
fill ~356 ~2 ~227 ~356 ~3 ~227 log2 1  
fill ~356 ~2 ~228 ~356 ~2 ~230 nether_brick 0 
setblock ~356 ~2 ~232 log2 1 
setblock ~356 ~2 ~234 log2 1  
fill ~356 ~2 ~235 ~356 ~3 ~235 concrete 13  
fill ~356 ~2 ~236 ~356 ~5 ~236 log2 1  
fill ~356 ~2 ~237 ~356 ~4 ~237 log2 1  
fill ~356 ~2 ~238 ~356 ~3 ~238 log2 1  
fill ~356 ~2 ~241 ~356 ~3 ~241 log 1 
setblock ~356 ~2 ~242 log2 1  
fill ~356 ~2 ~244 ~356 ~3 ~244 wool 7  
fill ~356 ~2 ~245 ~356 ~2 ~244 wool 7 
setblock ~356 ~2 ~248 concrete 7  
fill ~356 ~2 ~249 ~356 ~3 ~249 brown_glazed_terracotta 0  
fill ~356 ~2 ~250 ~356 ~2 ~251 stained_hardened_clay 8 
setblock ~356 ~2 ~252 brown_glazed_terracotta 0 
setblock ~356 ~2 ~253 stained_hardened_clay 8 
setblock ~356 ~2 ~255 orange_glazed_terracotta 0 
setblock ~356 ~2 ~256 log 6 
setblock ~356 ~2 ~257 stained_hardened_clay 8 
setblock ~356 ~2 ~258 log 6 
setblock ~356 ~2 ~259 gold_ore 0 
setblock ~356 ~2 ~260 log2 0  
fill ~356 ~2 ~262 ~356 ~3 ~262 concrete 7  
fill ~356 ~2 ~263 ~356 ~2 ~265 wool 7 
setblock ~356 ~2 ~267 wool 7 
setblock ~356 ~2 ~268 stained_hardened_clay 7  
fill ~356 ~2 ~269 ~356 ~4 ~269 concrete 7  
fill ~356 ~2 ~270 ~356 ~3 ~270 concrete 7 
setblock ~356 ~2 ~271 stained_hardened_clay 7  
fill ~356 ~2 ~272 ~356 ~6 ~272 concrete 15  
fill ~356 ~2 ~273 ~356 ~2 ~275 concrete 7 
setblock ~356 ~2 ~276 concrete 15 
setblock ~356 ~2 ~277 stained_hardened_clay 7  
fill ~356 ~2 ~278 ~356 ~2 ~279 concrete 15 
setblock ~356 ~2 ~280 wool 15  
fill ~356 ~2 ~281 ~356 ~6 ~281 concrete 15  
fill ~356 ~2 ~286 ~356 ~2 ~287 wool 15 
setblock ~356 ~2 ~288 concrete 15  
fill ~356 ~2 ~291 ~356 ~3 ~291 stained_hardened_clay 7  
fill ~356 ~2 ~293 ~356 ~2 ~295 stained_hardened_clay 7  
fill ~356 ~2 ~299 ~356 ~2 ~302 concrete 15  
fill ~356 ~2 ~303 ~356 ~2 ~304 wool 15 
setblock ~356 ~2 ~311 concrete 15 
setblock ~356 ~2 ~315 wool 15  
fill ~356 ~2 ~316 ~356 ~7 ~316 concrete 15  
fill ~356 ~2 ~317 ~356 ~6 ~317 concrete 15  
fill ~356 ~2 ~318 ~356 ~3 ~318 concrete 15  
fill ~356 ~2 ~319 ~356 ~2 ~320 concrete 15  
fill ~356 ~2 ~321 ~356 ~2 ~323 wool 15  
fill ~356 ~2 ~324 ~356 ~3 ~324 concrete 15  
fill ~356 ~2 ~325 ~356 ~4 ~325 concrete 15  
fill ~356 ~2 ~326 ~356 ~3 ~326 concrete 15  
fill ~356 ~2 ~327 ~356 ~2 ~331 concrete 15  
fill ~356 ~2 ~332 ~356 ~3 ~332 wool 15  
fill ~356 ~2 ~334 ~356 ~2 ~335 coal_block 0  
fill ~356 ~2 ~336 ~356 ~3 ~336 concrete 15  
fill ~356 ~2 ~337 ~356 ~3 ~337 coal_block 0  
fill ~356 ~2 ~338 ~356 ~2 ~337 coal_block 0  
fill ~356 ~2 ~339 ~356 ~3 ~339 wool 15  
fill ~356 ~2 ~340 ~356 ~3 ~340 wool 15  
fill ~356 ~2 ~341 ~356 ~3 ~341 coal_block 0  
fill ~356 ~2 ~342 ~356 ~3 ~342 concrete 15  
fill ~356 ~2 ~346 ~356 ~4 ~346 coal_block 0  
fill ~356 ~2 ~347 ~356 ~2 ~346 coal_block 0  
fill ~356 ~2 ~348 ~356 ~5 ~348 concrete 15  
fill ~356 ~2 ~349 ~356 ~8 ~349 concrete 15  
fill ~356 ~2 ~350 ~356 ~11 ~350 concrete 15  
fill ~356 ~2 ~351 ~356 ~3 ~351 concrete 15  
fill ~1 ~3 ~1 ~16 ~3 ~1 nether_brick 0  
fill ~1 ~3 ~57 ~1 ~10 ~57 concrete 15  
fill ~1 ~3 ~58 ~1 ~8 ~58 concrete 15  
fill ~1 ~3 ~59 ~1 ~3 ~60 coal_block 0  
fill ~1 ~3 ~61 ~1 ~10 ~61 concrete 15  
fill ~1 ~3 ~79 ~1 ~5 ~79 concrete 15  
fill ~1 ~3 ~80 ~1 ~4 ~80 concrete 15  
fill ~1 ~3 ~81 ~1 ~4 ~81 concrete 15  
fill ~1 ~3 ~82 ~1 ~4 ~82 concrete 15  
fill ~1 ~3 ~84 ~1 ~9 ~84 coal_block 0  
fill ~1 ~3 ~85 ~1 ~9 ~85 coal_block 0  
fill ~1 ~3 ~89 ~1 ~3 ~90 log2 1  
fill ~1 ~3 ~91 ~1 ~6 ~91 stained_hardened_clay 15  
fill ~1 ~3 ~96 ~1 ~8 ~96 log 1 
setblock ~1 ~3 ~97 stained_hardened_clay 15  
fill ~1 ~3 ~101 ~1 ~7 ~101 stained_hardened_clay 15  
fill ~1 ~3 ~102 ~1 ~6 ~102 stained_hardened_clay 15  
fill ~1 ~3 ~103 ~1 ~6 ~103 stained_hardened_clay 15  
fill ~1 ~3 ~104 ~1 ~6 ~104 stained_hardened_clay 15  
fill ~1 ~3 ~105 ~1 ~6 ~105 stained_hardened_clay 15  
fill ~1 ~3 ~106 ~1 ~6 ~106 stained_hardened_clay 15  
fill ~1 ~3 ~107 ~1 ~6 ~107 stained_hardened_clay 15  
fill ~1 ~3 ~108 ~1 ~5 ~108 stained_hardened_clay 15  
fill ~1 ~3 ~109 ~1 ~6 ~109 stained_hardened_clay 15  
fill ~1 ~3 ~110 ~1 ~6 ~110 stained_hardened_clay 15  
fill ~1 ~3 ~111 ~1 ~6 ~111 stained_hardened_clay 15  
fill ~1 ~3 ~112 ~1 ~6 ~112 stained_hardened_clay 15  
fill ~1 ~3 ~117 ~1 ~5 ~117 stained_hardened_clay 15  
fill ~1 ~3 ~152 ~1 ~11 ~152 coal_block 0 
setblock ~1 ~3 ~168 stained_hardened_clay 7 
setblock ~1 ~3 ~169 stone 3 
setblock ~1 ~3 ~174 stone 4 
setblock ~1 ~3 ~200 concrete 7 
setblock ~1 ~3 ~205 clay 0 
setblock ~1 ~3 ~261 stained_hardened_clay 7  
fill ~1 ~3 ~262 ~1 ~4 ~262 concrete 7 
setblock ~1 ~3 ~263 clay 0 
setblock ~1 ~3 ~264 stone 4  
fill ~1 ~3 ~265 ~1 ~4 ~265 concrete 7  
fill ~1 ~3 ~266 ~1 ~4 ~266 wool 15 
setblock ~2 ~3 ~356 concrete 3  
fill ~3 ~3 ~356 ~7 ~3 ~356 light_blue_glazed_terracotta 0  
fill ~8 ~3 ~356 ~9 ~3 ~356 concrete 3  
fill ~10 ~3 ~356 ~10 ~5 ~356 concrete 3  
fill ~11 ~3 ~356 ~11 ~5 ~356 light_blue_glazed_terracotta 0  
fill ~13 ~3 ~356 ~14 ~3 ~356 light_blue_glazed_terracotta 0  
fill ~16 ~3 ~356 ~16 ~4 ~356 concrete 3  
fill ~17 ~3 ~1 ~17 ~4 ~1 black_glazed_terracotta 0 
setblock ~18 ~3 ~356 wool 3  
fill ~19 ~3 ~1 ~31 ~3 ~1 black_glazed_terracotta 0  
fill ~19 ~3 ~356 ~19 ~5 ~356 light_blue_glazed_terracotta 0  
fill ~20 ~3 ~356 ~21 ~3 ~356 concrete 3 
setblock ~23 ~3 ~356 light_blue_glazed_terracotta 0  
fill ~25 ~3 ~356 ~25 ~2 ~356 concrete 11 
setblock ~26 ~3 ~356 blue_glazed_terracotta 0  
fill ~27 ~3 ~356 ~27 ~6 ~356 concrete 11 
setblock ~29 ~3 ~356 concrete 11 
setblock ~30 ~3 ~356 wool 11  
fill ~32 ~3 ~1 ~34 ~3 ~1 concrete 12 
setblock ~32 ~3 ~356 concrete 11 
setblock ~33 ~3 ~356 light_blue_glazed_terracotta 0  
fill ~34 ~3 ~356 ~37 ~3 ~356 concrete 3 
setblock ~35 ~3 ~1 netherrack 0  
fill ~36 ~3 ~1 ~55 ~3 ~1 concrete 14  
fill ~40 ~3 ~356 ~40 ~4 ~356 blue_glazed_terracotta 0  
fill ~42 ~3 ~356 ~43 ~3 ~356 blue_glazed_terracotta 0  
fill ~45 ~3 ~356 ~45 ~4 ~356 blue_glazed_terracotta 0  
fill ~47 ~3 ~356 ~49 ~3 ~356 concrete 11  
fill ~50 ~3 ~356 ~51 ~3 ~356 wool 11 
setblock ~52 ~3 ~356 concrete 11  
fill ~53 ~3 ~356 ~53 ~4 ~356 cyan_glazed_terracotta 0 
setblock ~55 ~3 ~356 lapis_ore 0  
fill ~56 ~3 ~1 ~56 ~5 ~1 wool 14 
setblock ~56 ~3 ~356 prismarine 2  
fill ~57 ~3 ~1 ~57 ~4 ~1 red_mushroom_block 14 
setblock ~57 ~3 ~356 blue_glazed_terracotta 0 
setblock ~58 ~3 ~1 wool 14  
fill ~59 ~3 ~1 ~66 ~3 ~1 concrete 14  
fill ~59 ~3 ~356 ~64 ~3 ~356 lapis_block 0  
fill ~65 ~3 ~356 ~68 ~3 ~356 concrete 11 
setblock ~67 ~3 ~1 black_glazed_terracotta 0 
setblock ~68 ~3 ~1 concrete 14 
setblock ~69 ~3 ~1 netherrack 0  
fill ~69 ~3 ~356 ~69 ~5 ~356 lapis_block 0  
fill ~70 ~3 ~1 ~72 ~3 ~1 concrete 12  
fill ~70 ~3 ~356 ~72 ~3 ~356 concrete 7 
setblock ~73 ~3 ~1 stained_hardened_clay 12  
fill ~73 ~3 ~356 ~74 ~3 ~356 wool 7  
fill ~74 ~3 ~1 ~74 ~5 ~1 black_glazed_terracotta 0  
fill ~75 ~3 ~1 ~83 ~3 ~1 stained_hardened_clay 12  
fill ~75 ~3 ~356 ~75 ~4 ~356 prismarine 2  
fill ~76 ~3 ~356 ~77 ~3 ~356 blue_glazed_terracotta 0  
fill ~78 ~3 ~356 ~86 ~3 ~356 lapis_block 0  
fill ~84 ~3 ~1 ~93 ~3 ~1 black_glazed_terracotta 0  
fill ~87 ~3 ~356 ~88 ~3 ~356 cyan_glazed_terracotta 0 
setblock ~89 ~3 ~356 blue_glazed_terracotta 0  
fill ~90 ~3 ~356 ~93 ~3 ~356 lapis_block 0 
setblock ~94 ~3 ~1 stained_hardened_clay 7  
fill ~94 ~3 ~356 ~94 ~6 ~356 wool 7  
fill ~96 ~3 ~1 ~96 ~5 ~1 black_glazed_terracotta 0  
fill ~96 ~3 ~356 ~97 ~3 ~356 wool 7  
fill ~97 ~3 ~1 ~102 ~3 ~1 stained_hardened_clay 7  
fill ~98 ~3 ~356 ~101 ~3 ~356 concrete 7 
setblock ~103 ~3 ~1 black_glazed_terracotta 0  
fill ~103 ~3 ~356 ~108 ~3 ~356 concrete 7  
fill ~104 ~3 ~1 ~104 ~18 ~1 stained_hardened_clay 7  
fill ~105 ~3 ~1 ~109 ~3 ~1 black_glazed_terracotta 0  
fill ~109 ~3 ~356 ~111 ~3 ~356 lapis_block 0  
fill ~110 ~3 ~1 ~116 ~3 ~1 stained_hardened_clay 7  
fill ~112 ~3 ~356 ~112 ~4 ~356 concrete 11 
setblock ~113 ~3 ~356 blue_glazed_terracotta 0  
fill ~114 ~3 ~356 ~115 ~3 ~356 lapis_block 0 
setblock ~117 ~3 ~1 black_glazed_terracotta 0 
setblock ~117 ~3 ~356 stained_hardened_clay 11  
fill ~118 ~3 ~1 ~119 ~3 ~1 stained_hardened_clay 7  
fill ~118 ~3 ~356 ~118 ~4 ~356 wool 7  
fill ~119 ~3 ~356 ~119 ~4 ~356 lapis_block 0 
setblock ~120 ~3 ~356 blue_glazed_terracotta 0  
fill ~121 ~3 ~1 ~138 ~3 ~1 stained_hardened_clay 12  
fill ~121 ~3 ~356 ~121 ~7 ~356 concrete 11  
fill ~122 ~3 ~356 ~123 ~3 ~356 lapis_block 0  
fill ~124 ~3 ~356 ~125 ~3 ~356 blue_glazed_terracotta 0  
fill ~126 ~3 ~356 ~134 ~3 ~356 concrete 11  
fill ~135 ~3 ~356 ~135 ~5 ~356 stained_hardened_clay 11  
fill ~136 ~3 ~356 ~143 ~3 ~356 concrete 7  
fill ~139 ~3 ~1 ~145 ~3 ~1 soul_sand 0 
setblock ~144 ~3 ~356 stained_hardened_clay 11 
setblock ~146 ~3 ~1 stained_hardened_clay 12  
fill ~146 ~3 ~356 ~147 ~3 ~356 concrete 7  
fill ~147 ~3 ~1 ~147 ~4 ~1 soul_sand 0 
setblock ~148 ~3 ~356 stained_hardened_clay 11  
fill ~149 ~3 ~1 ~159 ~3 ~1 soul_sand 0  
fill ~149 ~3 ~356 ~156 ~3 ~356 concrete 11  
fill ~157 ~3 ~356 ~159 ~3 ~356 stained_hardened_clay 11  
fill ~160 ~3 ~1 ~163 ~3 ~1 stained_hardened_clay 12 
setblock ~160 ~3 ~356 lapis_block 0  
fill ~161 ~3 ~356 ~162 ~3 ~356 stained_hardened_clay 11  
fill ~164 ~3 ~1 ~165 ~3 ~1 concrete 7 
setblock ~164 ~3 ~356 concrete 15  
fill ~165 ~3 ~356 ~165 ~4 ~356 stained_hardened_clay 11 
setblock ~166 ~3 ~1 stained_hardened_clay 12  
fill ~166 ~3 ~356 ~167 ~3 ~356 concrete 7  
fill ~167 ~3 ~1 ~169 ~3 ~1 concrete 7  
fill ~168 ~3 ~356 ~169 ~3 ~356 stained_hardened_clay 11  
fill ~170 ~3 ~1 ~177 ~3 ~1 wool 7  
fill ~170 ~3 ~356 ~172 ~3 ~356 concrete 11  
fill ~173 ~3 ~356 ~173 ~6 ~356 lapis_block 0  
fill ~174 ~3 ~356 ~181 ~3 ~356 blue_glazed_terracotta 0  
fill ~178 ~3 ~1 ~179 ~3 ~1 concrete 7  
fill ~180 ~3 ~1 ~182 ~3 ~1 gray_glazed_terracotta 0  
fill ~183 ~3 ~1 ~187 ~3 ~1 lapis_ore 0 
setblock ~183 ~3 ~356 concrete 7  
fill ~184 ~3 ~356 ~184 ~4 ~356 stained_hardened_clay 11  
fill ~187 ~3 ~356 ~188 ~3 ~356 lapis_block 0  
fill ~189 ~3 ~1 ~193 ~3 ~1 prismarine 0  
fill ~191 ~3 ~356 ~193 ~3 ~356 lapis_block 0  
fill ~194 ~3 ~1 ~208 ~3 ~1 light_gray_glazed_terracotta 0 
setblock ~194 ~3 ~356 blue_glazed_terracotta 0  
fill ~195 ~3 ~356 ~202 ~3 ~356 lapis_block 0 
setblock ~203 ~3 ~356 stained_hardened_clay 11  
fill ~204 ~3 ~356 ~205 ~3 ~356 lapis_block 0 
setblock ~206 ~3 ~356 blue_glazed_terracotta 0 
setblock ~207 ~3 ~356 lapis_block 0  
fill ~209 ~3 ~1 ~213 ~3 ~1 diamond_ore 0  
fill ~209 ~3 ~356 ~209 ~4 ~356 blue_glazed_terracotta 0  
fill ~210 ~3 ~356 ~215 ~3 ~356 lapis_block 0  
fill ~214 ~3 ~1 ~235 ~3 ~1 lapis_ore 0 
setblock ~216 ~3 ~356 stained_hardened_clay 11  
fill ~218 ~3 ~356 ~218 ~5 ~356 stained_hardened_clay 11  
fill ~221 ~3 ~356 ~221 ~4 ~356 wool 7  
fill ~223 ~3 ~356 ~223 ~4 ~356 concrete 7 
setblock ~224 ~3 ~356 stained_hardened_clay 11  
fill ~225 ~3 ~356 ~225 ~4 ~356 concrete 7 
setblock ~226 ~3 ~356 stained_hardened_clay 11  
fill ~227 ~3 ~356 ~228 ~3 ~356 lapis_block 0 
setblock ~229 ~3 ~356 stained_hardened_clay 11  
fill ~230 ~3 ~356 ~230 ~4 ~356 concrete 7 
setblock ~232 ~3 ~356 stained_hardened_clay 11  
fill ~233 ~3 ~356 ~235 ~3 ~356 concrete 7  
fill ~236 ~3 ~1 ~239 ~3 ~1 diamond_ore 0  
fill ~236 ~3 ~356 ~238 ~3 ~356 stained_hardened_clay 11  
fill ~239 ~3 ~356 ~245 ~3 ~356 concrete 11  
fill ~240 ~3 ~1 ~240 ~4 ~1 light_gray_glazed_terracotta 0  
fill ~241 ~3 ~1 ~241 ~8 ~1 clay 0  
fill ~242 ~3 ~1 ~248 ~3 ~1 diamond_ore 0  
fill ~246 ~3 ~356 ~247 ~3 ~356 stained_hardened_clay 11  
fill ~248 ~3 ~356 ~249 ~3 ~356 concrete 7  
fill ~249 ~3 ~1 ~255 ~3 ~1 lapis_ore 0 
setblock ~251 ~3 ~356 stained_hardened_clay 11 
setblock ~252 ~3 ~356 lapis_block 0  
fill ~253 ~3 ~356 ~255 ~3 ~356 concrete 11  
fill ~256 ~3 ~1 ~258 ~3 ~1 prismarine 1  
fill ~256 ~3 ~356 ~260 ~3 ~356 lapis_block 0  
fill ~259 ~3 ~1 ~261 ~3 ~1 prismarine 0 
setblock ~261 ~3 ~356 stained_hardened_clay 11  
fill ~262 ~3 ~1 ~280 ~3 ~1 light_gray_glazed_terracotta 0 
setblock ~262 ~3 ~356 lapis_block 0  
fill ~263 ~3 ~356 ~268 ~3 ~356 blue_glazed_terracotta 0  
fill ~270 ~3 ~356 ~270 ~4 ~356 lapis_block 0  
fill ~274 ~3 ~356 ~278 ~3 ~356 concrete 11 
setblock ~279 ~3 ~356 blue_glazed_terracotta 0 
setblock ~280 ~3 ~356 stained_hardened_clay 11  
fill ~281 ~3 ~1 ~281 ~24 ~1 diamond_ore 0  
fill ~281 ~3 ~356 ~286 ~3 ~356 concrete 15 
setblock ~282 ~3 ~1 prismarine 0  
fill ~283 ~3 ~1 ~292 ~3 ~1 diamond_ore 0  
fill ~287 ~3 ~356 ~288 ~3 ~356 stained_hardened_clay 11  
fill ~289 ~3 ~356 ~289 ~18 ~356 concrete 15  
fill ~292 ~3 ~356 ~295 ~3 ~356 obsidian 0  
fill ~293 ~3 ~1 ~299 ~3 ~1 lapis_ore 0 
setblock ~298 ~3 ~356 wool 15  
fill ~299 ~3 ~356 ~311 ~3 ~356 obsidian 0  
fill ~301 ~3 ~1 ~305 ~3 ~1 gray_glazed_terracotta 0  
fill ~306 ~3 ~1 ~308 ~3 ~1 concrete 7 
setblock ~309 ~3 ~1 prismarine 2  
fill ~310 ~3 ~1 ~320 ~3 ~1 wool 7 
setblock ~312 ~3 ~356 wool 15  
fill ~313 ~3 ~356 ~319 ~3 ~356 concrete 15  
fill ~320 ~3 ~356 ~324 ~3 ~356 obsidian 0  
fill ~321 ~3 ~1 ~345 ~3 ~1 concrete 7  
fill ~327 ~3 ~356 ~345 ~3 ~356 concrete 15  
fill ~346 ~3 ~1 ~356 ~3 ~1 stained_hardened_clay 7 
setblock ~346 ~3 ~356 concrete 15  
fill ~347 ~3 ~356 ~356 ~3 ~356 concrete 15 
setblock ~356 ~3 ~9 coal_block 0  
fill ~356 ~3 ~12 ~356 ~5 ~12 log 1  
fill ~356 ~3 ~13 ~356 ~5 ~13 coal_block 0  
fill ~356 ~3 ~14 ~356 ~3 ~17 concrete 15 
setblock ~356 ~3 ~18 coal_block 0 
setblock ~356 ~3 ~19 stained_hardened_clay 15  
fill ~356 ~3 ~20 ~356 ~3 ~22 nether_brick 0  
fill ~356 ~3 ~23 ~356 ~3 ~24 stained_hardened_clay 15 
setblock ~356 ~3 ~25 coal_block 0 
setblock ~356 ~3 ~27 stained_hardened_clay 7  
fill ~356 ~3 ~32 ~356 ~3 ~33 concrete 15 
setblock ~356 ~3 ~36 concrete 15  
fill ~356 ~3 ~38 ~356 ~3 ~39 stained_hardened_clay 7  
fill ~356 ~3 ~41 ~356 ~4 ~41 concrete 15  
fill ~356 ~3 ~43 ~356 ~4 ~43 wool 15  
fill ~356 ~3 ~49 ~356 ~4 ~49 stained_hardened_clay 7  
fill ~356 ~3 ~50 ~356 ~5 ~50 stained_hardened_clay 7  
fill ~356 ~3 ~51 ~356 ~6 ~51 concrete 7  
fill ~356 ~3 ~52 ~356 ~4 ~52 wool 7 
setblock ~356 ~3 ~54 concrete 7  
fill ~356 ~3 ~56 ~356 ~5 ~56 wool 7  
fill ~356 ~3 ~59 ~356 ~4 ~59 concrete 7 
setblock ~356 ~3 ~60 wool 7 
setblock ~356 ~3 ~61 bedrock 0  
fill ~356 ~3 ~62 ~356 ~4 ~62 wool 7 
setblock ~356 ~3 ~63 concrete 7  
fill ~356 ~3 ~65 ~356 ~4 ~65 concrete 7 
setblock ~356 ~3 ~66 stained_hardened_clay 9 
setblock ~356 ~3 ~67 log2 0 
setblock ~356 ~3 ~69 stained_hardened_clay 8 
setblock ~356 ~3 ~70 gold_ore 0 
setblock ~356 ~3 ~71 brown_glazed_terracotta 0 
setblock ~356 ~3 ~72 iron_ore 0  
fill ~356 ~3 ~73 ~356 ~4 ~73 stained_hardened_clay 8 
setblock ~356 ~3 ~74 gold_ore 0 
setblock ~356 ~3 ~75 orange_glazed_terracotta 0 
setblock ~356 ~3 ~78 bookshelf 0 
setblock ~356 ~3 ~79 log2 0  
fill ~356 ~3 ~80 ~356 ~4 ~80 stained_hardened_clay 8 
setblock ~356 ~3 ~81 gold_ore 0  
fill ~356 ~3 ~82 ~356 ~3 ~83 stained_hardened_clay 8 
setblock ~356 ~3 ~84 log2 0  
fill ~356 ~3 ~86 ~356 ~3 ~87 brown_glazed_terracotta 0 
setblock ~356 ~3 ~88 gold_ore 0  
fill ~356 ~3 ~89 ~356 ~4 ~89 stained_hardened_clay 8  
fill ~356 ~3 ~90 ~356 ~3 ~92 stained_hardened_clay 8 
setblock ~356 ~3 ~93 gold_ore 0  
fill ~356 ~3 ~94 ~356 ~4 ~94 brown_glazed_terracotta 0  
fill ~356 ~3 ~95 ~356 ~3 ~94 brown_glazed_terracotta 0  
fill ~356 ~3 ~96 ~356 ~5 ~96 orange_glazed_terracotta 0 
setblock ~356 ~3 ~97 stained_hardened_clay 8  
fill ~356 ~3 ~98 ~356 ~3 ~101 gold_ore 0 
setblock ~356 ~3 ~104 concrete 12 
setblock ~356 ~3 ~105 dirt 0  
fill ~356 ~3 ~107 ~356 ~5 ~107 concrete 12 
setblock ~356 ~3 ~108 noteblock 0 
setblock ~356 ~3 ~116 wool 7  
fill ~356 ~3 ~117 ~356 ~5 ~117 concrete 7  
fill ~356 ~3 ~118 ~356 ~5 ~118 wool 7  
fill ~356 ~3 ~120 ~356 ~4 ~120 wool 7 
setblock ~356 ~3 ~124 concrete 7 
setblock ~356 ~3 ~140 concrete 7  
fill ~356 ~3 ~142 ~356 ~6 ~142 wool 7  
fill ~356 ~3 ~143 ~356 ~3 ~141 wool 7 
setblock ~356 ~3 ~144 concrete 7  
fill ~356 ~3 ~151 ~356 ~5 ~151 concrete 7  
fill ~356 ~3 ~157 ~356 ~6 ~157 concrete 7  
fill ~356 ~3 ~159 ~356 ~4 ~159 wool 7 
setblock ~356 ~3 ~161 wool 7  
fill ~356 ~3 ~165 ~356 ~5 ~165 concrete 7  
fill ~356 ~3 ~166 ~356 ~8 ~166 concrete 7  
fill ~356 ~3 ~169 ~356 ~3 ~170 wool 7 
setblock ~356 ~3 ~171 prismarine 2 
setblock ~356 ~3 ~173 prismarine 2  
fill ~356 ~3 ~175 ~356 ~9 ~175 wool 7  
fill ~356 ~3 ~176 ~356 ~6 ~176 wool 7  
fill ~356 ~3 ~177 ~356 ~8 ~177 wool 7  
fill ~356 ~3 ~184 ~356 ~3 ~185 concrete 7  
fill ~356 ~3 ~187 ~356 ~4 ~187 wool 7  
fill ~356 ~3 ~188 ~356 ~12 ~188 wool 7  
fill ~356 ~3 ~189 ~356 ~11 ~189 wool 7 
setblock ~356 ~3 ~191 concrete 7  
fill ~356 ~3 ~194 ~356 ~18 ~194 wool 7  
fill ~356 ~3 ~200 ~356 ~19 ~200 wool 7 
setblock ~356 ~3 ~209 wool 7  
fill ~356 ~3 ~210 ~356 ~4 ~210 concrete 7  
fill ~356 ~3 ~211 ~356 ~3 ~214 wool 7  
fill ~356 ~3 ~218 ~356 ~10 ~218 concrete 15 
setblock ~356 ~3 ~219 obsidian 0 
setblock ~356 ~3 ~221 soul_sand 0  
fill ~356 ~3 ~222 ~356 ~4 ~222 stained_hardened_clay 12  
fill ~356 ~3 ~223 ~356 ~3 ~226 stained_hardened_clay 7 
setblock ~356 ~3 ~228 log2 1 
setblock ~356 ~3 ~229 nether_brick 0  
fill ~356 ~3 ~230 ~356 ~4 ~230 coal_block 0 
setblock ~356 ~3 ~232 stained_hardened_clay 13  
fill ~356 ~3 ~234 ~356 ~5 ~234 concrete 13 
setblock ~356 ~3 ~240 log 1 
setblock ~356 ~3 ~242 concrete 15 
setblock ~356 ~3 ~245 concrete 7 
setblock ~356 ~3 ~247 bedrock 0 
setblock ~356 ~3 ~248 mossy_cobblestone 0  
fill ~356 ~3 ~250 ~356 ~4 ~250 log 6  
fill ~356 ~3 ~251 ~356 ~4 ~251 log 6  
fill ~356 ~3 ~252 ~356 ~4 ~252 log 6  
fill ~356 ~3 ~253 ~356 ~3 ~250 log 6 
setblock ~356 ~3 ~255 log 6  
fill ~356 ~3 ~256 ~356 ~4 ~256 brown_glazed_terracotta 0  
fill ~356 ~3 ~257 ~356 ~4 ~257 log 6 
setblock ~356 ~3 ~258 orange_glazed_terracotta 0 
setblock ~356 ~3 ~259 log2 0  
fill ~356 ~3 ~260 ~356 ~4 ~260 concrete 7  
fill ~356 ~3 ~261 ~356 ~4 ~261 concrete 7 
setblock ~356 ~3 ~263 concrete 7  
fill ~356 ~3 ~264 ~356 ~7 ~264 concrete 7  
fill ~356 ~3 ~265 ~356 ~6 ~265 concrete 7  
fill ~356 ~3 ~267 ~356 ~4 ~267 stained_hardened_clay 7 
setblock ~356 ~3 ~268 concrete 7 
setblock ~356 ~3 ~271 concrete 7 
setblock ~356 ~3 ~273 stained_hardened_clay 7  
fill ~356 ~3 ~274 ~356 ~11 ~274 concrete 7 
setblock ~356 ~3 ~276 stained_hardened_clay 7 
setblock ~356 ~3 ~277 concrete 7  
fill ~356 ~3 ~278 ~356 ~4 ~278 stained_hardened_clay 7  
fill ~356 ~3 ~279 ~356 ~3 ~281 concrete 15  
fill ~356 ~3 ~282 ~356 ~5 ~282 wool 15 
setblock ~356 ~3 ~283 coal_block 0 
setblock ~356 ~3 ~284 concrete 15  
fill ~356 ~3 ~285 ~356 ~3 ~288 coal_block 0  
fill ~356 ~3 ~289 ~356 ~5 ~289 wool 15 
setblock ~356 ~3 ~292 concrete 7  
fill ~356 ~3 ~293 ~356 ~4 ~293 concrete 15  
fill ~356 ~3 ~294 ~356 ~4 ~294 concrete 7  
fill ~356 ~3 ~295 ~356 ~4 ~295 concrete 7  
fill ~356 ~3 ~298 ~356 ~3 ~300 stained_hardened_clay 7  
fill ~356 ~3 ~301 ~356 ~8 ~301 concrete 15  
fill ~356 ~3 ~302 ~356 ~5 ~302 concrete 15  
fill ~356 ~3 ~303 ~356 ~5 ~303 concrete 15  
fill ~356 ~3 ~304 ~356 ~7 ~304 concrete 15 
setblock ~356 ~3 ~306 wool 15  
fill ~356 ~3 ~307 ~356 ~3 ~309 coal_block 0 
setblock ~356 ~3 ~310 wool 15 
setblock ~356 ~3 ~311 coal_block 0  
fill ~356 ~3 ~312 ~356 ~4 ~312 wool 15  
fill ~356 ~3 ~313 ~356 ~3 ~312 wool 15  
fill ~356 ~3 ~314 ~356 ~8 ~314 concrete 15  
fill ~356 ~3 ~315 ~356 ~4 ~315 concrete 15  
fill ~356 ~3 ~319 ~356 ~4 ~319 wool 15  
fill ~356 ~3 ~320 ~356 ~3 ~319 wool 15  
fill ~356 ~3 ~321 ~356 ~6 ~321 concrete 15  
fill ~356 ~3 ~322 ~356 ~6 ~322 concrete 15  
fill ~356 ~3 ~323 ~356 ~5 ~323 concrete 15  
fill ~356 ~3 ~327 ~356 ~4 ~327 wool 15 
setblock ~356 ~3 ~328 coal_block 0 
setblock ~356 ~3 ~329 wool 15 
setblock ~356 ~3 ~330 concrete 15  
fill ~356 ~3 ~334 ~356 ~3 ~335 wool 15 
setblock ~356 ~3 ~338 wool 15  
fill ~356 ~3 ~343 ~356 ~4 ~343 coal_block 0  
fill ~356 ~3 ~345 ~356 ~5 ~345 coal_block 0  
fill ~356 ~3 ~347 ~356 ~5 ~347 concrete 15  
fill ~356 ~3 ~354 ~356 ~5 ~354 concrete 15  
fill ~356 ~3 ~355 ~356 ~4 ~355 concrete 15  
fill ~1 ~4 ~1 ~16 ~4 ~1 nether_brick 0  
fill ~1 ~4 ~59 ~1 ~10 ~59 concrete 15  
fill ~1 ~4 ~60 ~1 ~10 ~60 concrete 15  
fill ~1 ~4 ~83 ~1 ~10 ~83 coal_block 0  
fill ~1 ~4 ~89 ~1 ~6 ~89 stained_hardened_clay 15  
fill ~1 ~4 ~90 ~1 ~6 ~90 stained_hardened_clay 15  
fill ~1 ~4 ~97 ~1 ~8 ~97 log 1  
fill ~1 ~4 ~98 ~1 ~7 ~98 stained_hardened_clay 15  
fill ~1 ~4 ~99 ~1 ~7 ~99 stained_hardened_clay 15  
fill ~1 ~4 ~100 ~1 ~7 ~100 stained_hardened_clay 15  
fill ~1 ~4 ~113 ~1 ~6 ~113 stained_hardened_clay 15  
fill ~1 ~4 ~114 ~1 ~6 ~114 stained_hardened_clay 15  
fill ~1 ~4 ~115 ~1 ~5 ~115 stained_hardened_clay 15  
fill ~1 ~4 ~116 ~1 ~5 ~116 stained_hardened_clay 15  
fill ~1 ~4 ~118 ~1 ~5 ~118 stained_hardened_clay 15  
fill ~1 ~4 ~119 ~1 ~5 ~119 stained_hardened_clay 15  
fill ~1 ~4 ~120 ~1 ~6 ~120 stained_hardened_clay 15  
fill ~1 ~4 ~127 ~1 ~4 ~128 log 1  
fill ~1 ~4 ~153 ~1 ~13 ~153 coal_block 0  
fill ~1 ~4 ~154 ~1 ~26 ~154 coal_block 0 
setblock ~1 ~4 ~168 log2 1 
setblock ~1 ~4 ~169 stained_hardened_clay 9 
setblock ~1 ~4 ~170 concrete 0 
setblock ~1 ~4 ~171 quartz_block 0 
setblock ~1 ~4 ~173 iron_block 0 
setblock ~1 ~4 ~174 stonebrick 1 
setblock ~1 ~4 ~175 stained_hardened_clay 7 
setblock ~1 ~4 ~200 stained_hardened_clay 7 
setblock ~1 ~4 ~201 stonebrick 2  
fill ~1 ~4 ~202 ~1 ~4 ~203 concrete 0 
setblock ~1 ~4 ~204 log 2 
setblock ~1 ~4 ~205 concrete 7 
setblock ~1 ~4 ~206 concrete 15  
fill ~1 ~4 ~207 ~1 ~31 ~207 concrete 15 
setblock ~1 ~4 ~257 wool 15  
fill ~1 ~4 ~258 ~1 ~4 ~259 concrete 7 
setblock ~1 ~4 ~260 stained_hardened_clay 7 
setblock ~1 ~4 ~261 concrete 15 
setblock ~1 ~4 ~263 stone 4 
setblock ~1 ~4 ~264 concrete 0  
fill ~2 ~4 ~356 ~4 ~4 ~356 light_blue_glazed_terracotta 0  
fill ~5 ~4 ~356 ~6 ~4 ~356 concrete 3 
setblock ~7 ~4 ~356 concrete 3 
setblock ~8 ~4 ~356 wool 3  
fill ~9 ~4 ~356 ~9 ~5 ~356 light_blue_glazed_terracotta 0  
fill ~12 ~4 ~356 ~13 ~4 ~356 concrete 3 
setblock ~14 ~4 ~356 light_blue_glazed_terracotta 0  
fill ~18 ~4 ~356 ~18 ~7 ~356 concrete 3  
fill ~19 ~4 ~1 ~21 ~4 ~1 stained_hardened_clay 7 
setblock ~20 ~4 ~356 concrete 11  
fill ~21 ~4 ~356 ~21 ~5 ~356 light_blue_glazed_terracotta 0  
fill ~22 ~4 ~1 ~27 ~4 ~1 black_glazed_terracotta 0 
setblock ~22 ~4 ~356 cyan_glazed_terracotta 0  
fill ~23 ~4 ~356 ~24 ~4 ~356 concrete 11  
fill ~25 ~4 ~356 ~25 ~5 ~356 blue_glazed_terracotta 0 
setblock ~26 ~4 ~356 concrete 11 
setblock ~28 ~4 ~1 stained_hardened_clay 12  
fill ~29 ~4 ~1 ~29 ~5 ~1 black_glazed_terracotta 0  
fill ~29 ~4 ~356 ~30 ~4 ~356 blue_glazed_terracotta 0  
fill ~31 ~4 ~1 ~35 ~4 ~1 black_glazed_terracotta 0  
fill ~31 ~4 ~356 ~31 ~7 ~356 concrete 11 
setblock ~32 ~4 ~356 light_blue_glazed_terracotta 0  
fill ~33 ~4 ~356 ~37 ~4 ~356 concrete 3  
fill ~36 ~4 ~1 ~41 ~4 ~1 concrete 14 
setblock ~38 ~4 ~356 lapis_ore 0 
setblock ~41 ~4 ~356 cyan_glazed_terracotta 0  
fill ~42 ~4 ~1 ~42 ~7 ~1 wool 14  
fill ~42 ~4 ~356 ~45 ~4 ~356 blue_glazed_terracotta 0  
fill ~43 ~4 ~1 ~43 ~5 ~1 red_mushroom_block 14  
fill ~44 ~4 ~1 ~55 ~4 ~1 concrete 14 
setblock ~47 ~4 ~356 lapis_block 0 
setblock ~48 ~4 ~356 blue_glazed_terracotta 0 
setblock ~50 ~4 ~356 concrete 11 
setblock ~51 ~4 ~356 cyan_glazed_terracotta 0  
fill ~52 ~4 ~356 ~52 ~6 ~356 blue_glazed_terracotta 0 
setblock ~54 ~4 ~356 lapis_block 0  
fill ~55 ~4 ~356 ~57 ~4 ~356 wool 7  
fill ~58 ~4 ~1 ~67 ~4 ~1 concrete 14 
setblock ~58 ~4 ~356 blue_glazed_terracotta 0  
fill ~59 ~4 ~356 ~64 ~4 ~356 lapis_block 0  
fill ~65 ~4 ~356 ~65 ~9 ~356 blue_glazed_terracotta 0  
fill ~66 ~4 ~356 ~66 ~7 ~356 lapis_block 0  
fill ~67 ~4 ~356 ~68 ~4 ~356 concrete 11  
fill ~68 ~4 ~1 ~71 ~4 ~1 concrete 12  
fill ~70 ~4 ~356 ~72 ~4 ~356 concrete 7  
fill ~72 ~4 ~1 ~75 ~4 ~1 black_glazed_terracotta 0  
fill ~73 ~4 ~356 ~74 ~4 ~356 wool 7  
fill ~76 ~4 ~1 ~82 ~4 ~1 stained_hardened_clay 12  
fill ~76 ~4 ~356 ~76 ~5 ~356 prismarine 2  
fill ~77 ~4 ~356 ~82 ~4 ~356 lapis_block 0  
fill ~83 ~4 ~1 ~97 ~4 ~1 black_glazed_terracotta 0 
setblock ~83 ~4 ~356 concrete 11  
fill ~84 ~4 ~356 ~85 ~4 ~356 lapis_block 0  
fill ~86 ~4 ~356 ~87 ~4 ~356 cyan_glazed_terracotta 0 
setblock ~88 ~4 ~356 prismarine 2  
fill ~89 ~4 ~356 ~90 ~4 ~356 cyan_glazed_terracotta 0  
fill ~91 ~4 ~356 ~93 ~4 ~356 lapis_block 0 
setblock ~95 ~4 ~356 concrete 7  
fill ~96 ~4 ~356 ~97 ~4 ~356 wool 7 
setblock ~98 ~4 ~1 stained_hardened_clay 7  
fill ~98 ~4 ~356 ~100 ~4 ~356 concrete 7  
fill ~99 ~4 ~1 ~100 ~4 ~1 black_glazed_terracotta 0  
fill ~101 ~4 ~1 ~106 ~4 ~1 stained_hardened_clay 7 
setblock ~101 ~4 ~356 stained_hardened_clay 11 
setblock ~103 ~4 ~356 concrete 11  
fill ~104 ~4 ~356 ~105 ~4 ~356 concrete 7  
fill ~106 ~4 ~356 ~106 ~5 ~356 stained_hardened_clay 11  
fill ~107 ~4 ~1 ~110 ~4 ~1 black_glazed_terracotta 0 
setblock ~107 ~4 ~356 blue_glazed_terracotta 0  
fill ~108 ~4 ~356 ~108 ~5 ~356 stained_hardened_clay 11  
fill ~109 ~4 ~356 ~110 ~4 ~356 lapis_block 0  
fill ~111 ~4 ~1 ~115 ~4 ~1 stained_hardened_clay 7 
setblock ~111 ~4 ~356 stained_hardened_clay 11  
fill ~113 ~4 ~356 ~115 ~4 ~356 concrete 11 
setblock ~116 ~4 ~1 black_glazed_terracotta 0  
fill ~116 ~4 ~356 ~116 ~7 ~356 lapis_block 0  
fill ~117 ~4 ~1 ~117 ~20 ~1 stained_hardened_clay 7  
fill ~117 ~4 ~356 ~117 ~6 ~356 concrete 7 
setblock ~118 ~4 ~1 black_glazed_terracotta 0  
fill ~119 ~4 ~1 ~124 ~4 ~1 stained_hardened_clay 7  
fill ~120 ~4 ~356 ~120 ~7 ~356 concrete 11  
fill ~122 ~4 ~356 ~134 ~4 ~356 concrete 11  
fill ~125 ~4 ~1 ~136 ~4 ~1 stained_hardened_clay 12  
fill ~136 ~4 ~356 ~138 ~4 ~356 concrete 7  
fill ~137 ~4 ~1 ~141 ~4 ~1 soul_sand 0  
fill ~139 ~4 ~356 ~139 ~5 ~356 stained_hardened_clay 11  
fill ~140 ~4 ~356 ~143 ~4 ~356 concrete 7 
setblock ~142 ~4 ~1 stained_hardened_clay 12  
fill ~143 ~4 ~1 ~143 ~7 ~1 soul_sand 0 
setblock ~144 ~4 ~356 concrete 11  
fill ~145 ~4 ~1 ~160 ~4 ~1 soul_sand 0  
fill ~146 ~4 ~356 ~149 ~4 ~356 concrete 7 
setblock ~150 ~4 ~356 lapis_block 0  
fill ~151 ~4 ~356 ~154 ~4 ~356 concrete 11 
setblock ~155 ~4 ~356 lapis_block 0  
fill ~156 ~4 ~356 ~156 ~8 ~356 concrete 11  
fill ~157 ~4 ~356 ~157 ~5 ~356 stained_hardened_clay 11  
fill ~158 ~4 ~356 ~160 ~4 ~356 concrete 11 
setblock ~161 ~4 ~1 concrete 7  
fill ~161 ~4 ~356 ~163 ~4 ~356 concrete 7 
setblock ~162 ~4 ~1 soul_sand 0  
fill ~163 ~4 ~1 ~170 ~4 ~1 concrete 7  
fill ~164 ~4 ~356 ~164 ~5 ~356 stained_hardened_clay 11 
setblock ~166 ~4 ~356 stained_hardened_clay 11 
setblock ~167 ~4 ~356 blue_glazed_terracotta 0  
fill ~168 ~4 ~356 ~169 ~4 ~356 concrete 7  
fill ~170 ~4 ~356 ~172 ~4 ~356 concrete 11  
fill ~171 ~4 ~1 ~176 ~4 ~1 wool 7  
fill ~174 ~4 ~356 ~181 ~4 ~356 blue_glazed_terracotta 0  
fill ~177 ~4 ~1 ~179 ~4 ~1 concrete 7  
fill ~180 ~4 ~1 ~182 ~4 ~1 gray_glazed_terracotta 0  
fill ~182 ~4 ~356 ~184 ~4 ~356 stained_hardened_clay 11  
fill ~183 ~4 ~1 ~186 ~4 ~1 lapis_ore 0  
fill ~185 ~4 ~356 ~185 ~10 ~356 concrete 11 
setblock ~186 ~4 ~356 lapis_block 0  
fill ~187 ~4 ~1 ~187 ~6 ~1 prismarine 1  
fill ~187 ~4 ~356 ~189 ~4 ~356 stained_hardened_clay 11  
fill ~189 ~4 ~1 ~192 ~4 ~1 prismarine 0 
setblock ~190 ~4 ~356 blue_glazed_terracotta 0  
fill ~191 ~4 ~356 ~192 ~4 ~356 lapis_block 0  
fill ~193 ~4 ~1 ~208 ~4 ~1 light_gray_glazed_terracotta 0 
setblock ~193 ~4 ~356 wool 7  
fill ~194 ~4 ~356 ~201 ~4 ~356 lapis_block 0  
fill ~202 ~4 ~356 ~203 ~4 ~356 concrete 7  
fill ~204 ~4 ~356 ~204 ~6 ~356 stained_hardened_clay 11 
setblock ~205 ~4 ~356 lapis_block 0 
setblock ~206 ~4 ~356 stained_hardened_clay 11 
setblock ~207 ~4 ~356 concrete 7  
fill ~209 ~4 ~1 ~213 ~4 ~1 diamond_ore 0 
setblock ~210 ~4 ~356 blue_glazed_terracotta 0  
fill ~211 ~4 ~356 ~214 ~4 ~356 lapis_block 0  
fill ~214 ~4 ~1 ~215 ~4 ~1 lapis_ore 0 
setblock ~215 ~4 ~356 stained_hardened_clay 11  
fill ~216 ~4 ~1 ~216 ~5 ~1 diamond_ore 0 
setblock ~216 ~4 ~356 concrete 7  
fill ~217 ~4 ~1 ~219 ~4 ~1 prismarine 0  
fill ~217 ~4 ~356 ~217 ~5 ~356 stained_hardened_clay 11  
fill ~220 ~4 ~1 ~235 ~4 ~1 lapis_ore 0 
setblock ~222 ~4 ~356 stained_hardened_clay 11  
fill ~224 ~4 ~356 ~224 ~5 ~356 concrete 7  
fill ~226 ~4 ~356 ~226 ~6 ~356 concrete 7  
fill ~227 ~4 ~356 ~228 ~4 ~356 stained_hardened_clay 11 
setblock ~229 ~4 ~356 concrete 11 
setblock ~231 ~4 ~356 concrete 11 
setblock ~232 ~4 ~356 lapis_block 0  
fill ~233 ~4 ~356 ~233 ~6 ~356 stained_hardened_clay 11 
setblock ~234 ~4 ~356 concrete 7  
fill ~235 ~4 ~356 ~235 ~5 ~356 stained_hardened_clay 11  
fill ~236 ~4 ~1 ~239 ~4 ~1 diamond_ore 0  
fill ~236 ~4 ~356 ~236 ~7 ~356 concrete 11  
fill ~237 ~4 ~356 ~238 ~4 ~356 stained_hardened_clay 11  
fill ~239 ~4 ~356 ~240 ~4 ~356 concrete 11  
fill ~241 ~4 ~356 ~241 ~5 ~356 stained_hardened_clay 11  
fill ~242 ~4 ~1 ~242 ~6 ~1 light_gray_glazed_terracotta 0  
fill ~242 ~4 ~356 ~245 ~4 ~356 concrete 11  
fill ~243 ~4 ~1 ~249 ~4 ~1 diamond_ore 0  
fill ~246 ~4 ~356 ~246 ~3 ~356 stained_hardened_clay 11 
setblock ~247 ~4 ~356 concrete 7  
fill ~248 ~4 ~356 ~248 ~5 ~356 stained_hardened_clay 11  
fill ~249 ~4 ~356 ~250 ~4 ~356 concrete 7  
fill ~250 ~4 ~1 ~256 ~4 ~1 lapis_ore 0 
setblock ~251 ~4 ~356 lapis_block 0 
setblock ~252 ~4 ~356 blue_glazed_terracotta 0  
fill ~253 ~4 ~356 ~254 ~4 ~356 concrete 11  
fill ~255 ~4 ~356 ~258 ~4 ~356 lapis_block 0  
fill ~257 ~4 ~1 ~258 ~4 ~1 prismarine 1  
fill ~259 ~4 ~1 ~261 ~4 ~1 prismarine 0 
setblock ~259 ~4 ~356 blue_glazed_terracotta 0 
setblock ~260 ~4 ~356 stained_hardened_clay 11  
fill ~261 ~4 ~356 ~261 ~5 ~356 lapis_block 0  
fill ~262 ~4 ~1 ~278 ~4 ~1 light_gray_glazed_terracotta 0 
setblock ~262 ~4 ~356 wool 7  
fill ~263 ~4 ~356 ~265 ~4 ~356 lapis_block 0 
setblock ~266 ~4 ~356 blue_glazed_terracotta 0  
fill ~267 ~4 ~356 ~267 ~6 ~356 lapis_block 0 
setblock ~268 ~4 ~356 blue_glazed_terracotta 0  
fill ~271 ~4 ~356 ~271 ~6 ~356 blue_glazed_terracotta 0  
fill ~273 ~4 ~356 ~273 ~20 ~356 blue_glazed_terracotta 0  
fill ~274 ~4 ~356 ~277 ~4 ~356 lapis_block 0 
setblock ~278 ~4 ~356 concrete 11  
fill ~279 ~4 ~1 ~292 ~4 ~1 diamond_ore 0  
fill ~279 ~4 ~356 ~279 ~8 ~356 stained_hardened_clay 11  
fill ~280 ~4 ~356 ~289 ~4 ~356 concrete 15  
fill ~291 ~4 ~356 ~292 ~4 ~356 wool 15  
fill ~293 ~4 ~1 ~300 ~4 ~1 lapis_ore 0 
setblock ~293 ~4 ~356 obsidian 0 
setblock ~294 ~4 ~356 wool 15  
fill ~295 ~4 ~356 ~298 ~4 ~356 concrete 15  
fill ~299 ~4 ~356 ~299 ~1 ~356 obsidian 0  
fill ~300 ~4 ~356 ~300 ~6 ~356 concrete 15  
fill ~301 ~4 ~1 ~306 ~4 ~1 gray_glazed_terracotta 0 
setblock ~301 ~4 ~356 obsidian 0  
fill ~302 ~4 ~356 ~304 ~4 ~356 wool 15  
fill ~305 ~4 ~356 ~309 ~4 ~356 obsidian 0  
fill ~307 ~4 ~1 ~309 ~4 ~1 concrete 7 
setblock ~310 ~4 ~1 prismarine 2 
setblock ~310 ~4 ~356 wool 15  
fill ~311 ~4 ~1 ~312 ~4 ~1 concrete 7  
fill ~311 ~4 ~356 ~313 ~4 ~356 concrete 15  
fill ~313 ~4 ~1 ~319 ~4 ~1 wool 7 
setblock ~314 ~4 ~356 concrete 7 
setblock ~315 ~4 ~356 gray_glazed_terracotta 0  
fill ~316 ~4 ~356 ~319 ~4 ~356 concrete 15  
fill ~320 ~4 ~1 ~345 ~4 ~1 concrete 7  
fill ~320 ~4 ~356 ~325 ~4 ~356 obsidian 0  
fill ~326 ~4 ~356 ~339 ~4 ~356 concrete 15 
setblock ~340 ~4 ~356 stained_hardened_clay 7  
fill ~341 ~4 ~356 ~341 ~9 ~356 concrete 15 
setblock ~342 ~4 ~356 light_gray_glazed_terracotta 0 
setblock ~343 ~4 ~356 concrete 15  
fill ~344 ~4 ~356 ~356 ~4 ~356 concrete 15  
fill ~346 ~4 ~1 ~350 ~4 ~1 stained_hardened_clay 7  
fill ~351 ~4 ~1 ~354 ~4 ~1 concrete 7  
fill ~355 ~4 ~1 ~355 ~8 ~1 stained_hardened_clay 7  
fill ~356 ~4 ~1 ~356 ~5 ~1 concrete 7 
setblock ~356 ~4 ~9 log 1  
fill ~356 ~4 ~14 ~356 ~5 ~14 coal_block 0  
fill ~356 ~4 ~15 ~356 ~5 ~15 coal_block 0  
fill ~356 ~4 ~16 ~356 ~5 ~16 coal_block 0  
fill ~356 ~4 ~17 ~356 ~4 ~13 coal_block 0  
fill ~356 ~4 ~18 ~356 ~4 ~19 concrete 15 
setblock ~356 ~4 ~20 coal_block 0  
fill ~356 ~4 ~21 ~356 ~4 ~23 nether_brick 0  
fill ~356 ~4 ~24 ~356 ~4 ~25 stained_hardened_clay 15  
fill ~356 ~4 ~26 ~356 ~4 ~27 concrete 15 
setblock ~356 ~4 ~28 wool 15  
fill ~356 ~4 ~29 ~356 ~5 ~29 concrete 15  
fill ~356 ~4 ~31 ~356 ~5 ~31 stained_hardened_clay 7  
fill ~356 ~4 ~32 ~356 ~4 ~30 stained_hardened_clay 7 
setblock ~356 ~4 ~33 concrete 15 
setblock ~356 ~4 ~34 wool 15 
setblock ~356 ~4 ~36 wool 15  
fill ~356 ~4 ~37 ~356 ~5 ~37 concrete 15  
fill ~356 ~4 ~38 ~356 ~11 ~38 concrete 15  
fill ~356 ~4 ~39 ~356 ~5 ~39 concrete 15 
setblock ~356 ~4 ~44 wool 15  
fill ~356 ~4 ~48 ~356 ~5 ~48 stained_hardened_clay 7  
fill ~356 ~4 ~54 ~356 ~5 ~54 wool 7 
setblock ~356 ~4 ~58 wool 7  
fill ~356 ~4 ~60 ~356 ~4 ~61 concrete 7  
fill ~356 ~4 ~63 ~356 ~4 ~64 wool 7 
setblock ~356 ~4 ~66 bedrock 0 
setblock ~356 ~4 ~67 stonebrick 1 
setblock ~356 ~4 ~68 log2 0  
fill ~356 ~4 ~69 ~356 ~6 ~69 brown_glazed_terracotta 0  
fill ~356 ~4 ~70 ~356 ~4 ~72 log2 0  
fill ~356 ~4 ~74 ~356 ~6 ~74 brown_glazed_terracotta 0  
fill ~356 ~4 ~75 ~356 ~4 ~74 brown_glazed_terracotta 0  
fill ~356 ~4 ~76 ~356 ~4 ~77 gold_ore 0 
setblock ~356 ~4 ~78 stained_hardened_clay 8  
fill ~356 ~4 ~79 ~356 ~5 ~79 gold_ore 0 
setblock ~356 ~4 ~81 orange_glazed_terracotta 0  
fill ~356 ~4 ~82 ~356 ~4 ~83 gold_ore 0 
setblock ~356 ~4 ~84 stained_hardened_clay 8 
setblock ~356 ~4 ~85 brown_glazed_terracotta 0  
fill ~356 ~4 ~86 ~356 ~4 ~87 stained_hardened_clay 8 
setblock ~356 ~4 ~88 brown_glazed_terracotta 0 
setblock ~356 ~4 ~90 gold_ore 0 
setblock ~356 ~4 ~91 brown_glazed_terracotta 0 
setblock ~356 ~4 ~92 iron_ore 0 
setblock ~356 ~4 ~93 log2 0  
fill ~356 ~4 ~95 ~356 ~5 ~95 gold_ore 0 
setblock ~356 ~4 ~97 gold_ore 0 
setblock ~356 ~4 ~98 log2 0  
fill ~356 ~4 ~99 ~356 ~5 ~99 brown_glazed_terracotta 0  
fill ~356 ~4 ~100 ~356 ~4 ~102 orange_glazed_terracotta 0 
setblock ~356 ~4 ~103 brown_mushroom_block 14  
fill ~356 ~4 ~104 ~356 ~5 ~104 wool 12 
setblock ~356 ~4 ~105 planks 1 
setblock ~356 ~4 ~108 wool 12 
setblock ~356 ~4 ~109 noteblock 0  
fill ~356 ~4 ~116 ~356 ~5 ~116 concrete 7  
fill ~356 ~4 ~121 ~356 ~4 ~124 wool 7  
fill ~356 ~4 ~129 ~356 ~5 ~129 concrete 7 
setblock ~356 ~4 ~140 wool 7 
setblock ~356 ~4 ~143 concrete 7  
fill ~356 ~4 ~144 ~356 ~8 ~144 wool 7  
fill ~356 ~4 ~158 ~356 ~8 ~158 concrete 7 
setblock ~356 ~4 ~160 wool 7  
fill ~356 ~4 ~161 ~356 ~4 ~166 concrete 7 
setblock ~356 ~4 ~167 wool 7  
fill ~356 ~4 ~169 ~356 ~10 ~169 concrete 7  
fill ~356 ~4 ~170 ~356 ~11 ~170 concrete 7  
fill ~356 ~4 ~171 ~356 ~8 ~171 concrete 7  
fill ~356 ~4 ~172 ~356 ~9 ~172 concrete 7  
fill ~356 ~4 ~173 ~356 ~7 ~173 concrete 7  
fill ~356 ~4 ~174 ~356 ~5 ~174 concrete 7 
setblock ~356 ~4 ~181 concrete 7  
fill ~356 ~4 ~184 ~356 ~13 ~184 wool 7  
fill ~356 ~4 ~185 ~356 ~14 ~185 wool 7  
fill ~356 ~4 ~191 ~356 ~11 ~191 wool 7  
fill ~356 ~4 ~192 ~356 ~18 ~192 wool 7  
fill ~356 ~4 ~199 ~356 ~21 ~199 wool 7  
fill ~356 ~4 ~209 ~356 ~6 ~209 concrete 7  
fill ~356 ~4 ~211 ~356 ~8 ~211 concrete 7 
setblock ~356 ~4 ~212 wool 7 
setblock ~356 ~4 ~213 concrete 7  
fill ~356 ~4 ~214 ~356 ~13 ~214 concrete 15  
fill ~356 ~4 ~215 ~356 ~11 ~215 concrete 15  
fill ~356 ~4 ~216 ~356 ~11 ~216 concrete 15  
fill ~356 ~4 ~217 ~356 ~11 ~217 concrete 15  
fill ~356 ~4 ~219 ~356 ~11 ~219 concrete 15 
setblock ~356 ~4 ~221 stained_hardened_clay 7  
fill ~356 ~4 ~223 ~356 ~4 ~224 stained_hardened_clay 12 
