fill ~21 ~-1 ~47 ~51 ~-1 ~47 quartz_block 0  
fill ~21 ~-1 ~48 ~51 ~-1 ~48 quartz_block 0  
fill ~21 ~-1 ~49 ~51 ~-1 ~49 quartz_block 0  
fill ~22 ~-1 ~17 ~24 ~-1 ~17 dirt 0  
fill ~22 ~-1 ~19 ~24 ~-1 ~19 dirt 0 
setblock ~22 ~-1 ~44 sea_lantern 0 
setblock ~22 ~-1 ~46 dirt 0 
setblock ~22 ~-1 ~50 dirt 0 
setblock ~22 ~-1 ~52 sea_lantern 0  
fill ~22 ~-1 ~77 ~24 ~-1 ~77 dirt 0  
fill ~22 ~-1 ~78 ~23 ~-1 ~78 dirt 0  
fill ~22 ~-1 ~79 ~22 ~-1 ~77 dirt 0 
setblock ~23 ~-1 ~16 dirt 0  
fill ~23 ~-1 ~18 ~24 ~-1 ~18 dirt 0  
fill ~23 ~-1 ~41 ~23 ~-1 ~43 sea_lantern 0  
fill ~23 ~-1 ~44 ~52 ~-1 ~44 quartz_block 0  
fill ~23 ~-1 ~45 ~51 ~-1 ~45 quartz_block 0  
fill ~23 ~-1 ~46 ~23 ~-1 ~44 quartz_block 0  
fill ~23 ~-1 ~50 ~23 ~-1 ~52 quartz_block 0  
fill ~23 ~-1 ~53 ~23 ~-1 ~55 sea_lantern 0 
setblock ~23 ~-1 ~80 dirt 0 
setblock ~24 ~-1 ~40 sea_lantern 0  
fill ~24 ~-1 ~41 ~53 ~-1 ~41 quartz_block 0  
fill ~24 ~-1 ~42 ~53 ~-1 ~42 quartz_block 0  
fill ~24 ~-1 ~43 ~52 ~-1 ~43 quartz_block 0 
setblock ~24 ~-1 ~46 sea_lantern 0 
setblock ~24 ~-1 ~50 sea_lantern 0  
fill ~24 ~-1 ~51 ~51 ~-1 ~51 quartz_block 0  
fill ~24 ~-1 ~52 ~52 ~-1 ~52 quartz_block 0  
fill ~24 ~-1 ~53 ~52 ~-1 ~53 quartz_block 0  
fill ~24 ~-1 ~54 ~53 ~-1 ~54 quartz_block 0  
fill ~24 ~-1 ~55 ~53 ~-1 ~55 quartz_block 0 
setblock ~24 ~-1 ~56 sea_lantern 0 
setblock ~24 ~-1 ~79 dirt 0 
setblock ~25 ~-1 ~37 dirt 0  
fill ~25 ~-1 ~38 ~25 ~-1 ~39 sea_lantern 0  
fill ~25 ~-1 ~40 ~30 ~-1 ~40 quartz_block 0 
setblock ~25 ~-1 ~46 quartz_block 0 
setblock ~25 ~-1 ~50 quartz_block 0  
fill ~25 ~-1 ~56 ~30 ~-1 ~56 quartz_block 0  
fill ~25 ~-1 ~57 ~25 ~-1 ~58 sea_lantern 0 
setblock ~25 ~-1 ~59 dirt 0 
setblock ~26 ~-1 ~38 dirt 0  
fill ~26 ~-1 ~39 ~27 ~-1 ~39 quartz_block 0 
setblock ~26 ~-1 ~46 sea_lantern 0 
setblock ~26 ~-1 ~50 sea_lantern 0  
fill ~26 ~-1 ~57 ~27 ~-1 ~57 quartz_block 0 
setblock ~26 ~-1 ~58 dirt 0 
setblock ~27 ~-1 ~46 quartz_block 0 
setblock ~27 ~-1 ~50 quartz_block 0  
fill ~28 ~-1 ~17 ~28 ~-1 ~19 dirt 0 
setblock ~28 ~-1 ~21 dirt 0 
setblock ~28 ~-1 ~46 sea_lantern 0 
setblock ~28 ~-1 ~50 sea_lantern 0 
setblock ~28 ~-1 ~75 dirt 0  
fill ~28 ~-1 ~77 ~28 ~-1 ~79 dirt 0 
setblock ~29 ~-1 ~46 quartz_block 0 
setblock ~29 ~-1 ~50 quartz_block 0 
setblock ~30 ~-1 ~46 sea_lantern 0 
setblock ~30 ~-1 ~50 sea_lantern 0  
fill ~31 ~-1 ~40 ~35 ~-1 ~40 dirt 0 
setblock ~31 ~-1 ~46 quartz_block 0 
setblock ~31 ~-1 ~50 quartz_block 0  
fill ~31 ~-1 ~56 ~35 ~-1 ~56 dirt 0 
setblock ~32 ~-1 ~46 sea_lantern 0 
setblock ~32 ~-1 ~50 sea_lantern 0 
setblock ~33 ~-1 ~46 quartz_block 0 
setblock ~33 ~-1 ~50 quartz_block 0 
setblock ~34 ~-1 ~46 sea_lantern 0 
setblock ~34 ~-1 ~50 sea_lantern 0 
setblock ~35 ~-1 ~46 quartz_block 0 
setblock ~35 ~-1 ~50 quartz_block 0  
fill ~36 ~-1 ~40 ~39 ~-1 ~40 quartz_block 0 
setblock ~36 ~-1 ~46 sea_lantern 0 
setblock ~36 ~-1 ~50 sea_lantern 0  
fill ~36 ~-1 ~56 ~39 ~-1 ~56 quartz_block 0 
setblock ~37 ~-1 ~46 quartz_block 0 
setblock ~37 ~-1 ~50 quartz_block 0 
setblock ~38 ~-1 ~46 sea_lantern 0 
setblock ~38 ~-1 ~50 sea_lantern 0 
setblock ~39 ~-1 ~46 quartz_block 0 
setblock ~39 ~-1 ~50 quartz_block 0  
fill ~40 ~-1 ~40 ~44 ~-1 ~40 dirt 0 
setblock ~40 ~-1 ~46 sea_lantern 0 
setblock ~40 ~-1 ~50 sea_lantern 0  
fill ~40 ~-1 ~56 ~44 ~-1 ~56 dirt 0 
setblock ~41 ~-1 ~46 quartz_block 0 
setblock ~41 ~-1 ~50 quartz_block 0 
setblock ~41 ~-1 ~57 dirt 0 
setblock ~42 ~-1 ~46 sea_lantern 0 
setblock ~42 ~-1 ~50 sea_lantern 0 
setblock ~43 ~-1 ~46 quartz_block 0 
setblock ~43 ~-1 ~50 quartz_block 0 
setblock ~44 ~-1 ~46 sea_lantern 0 
setblock ~44 ~-1 ~50 sea_lantern 0  
fill ~45 ~-1 ~39 ~47 ~-1 ~39 dirt 0  
fill ~45 ~-1 ~40 ~54 ~-1 ~40 quartz_block 0 
setblock ~45 ~-1 ~46 quartz_block 0 
setblock ~45 ~-1 ~50 quartz_block 0  
fill ~45 ~-1 ~56 ~54 ~-1 ~56 quartz_block 0  
fill ~45 ~-1 ~57 ~47 ~-1 ~57 dirt 0 
setblock ~46 ~-1 ~46 sea_lantern 0 
setblock ~46 ~-1 ~50 sea_lantern 0  
fill ~47 ~-1 ~17 ~49 ~-1 ~17 dirt 0  
fill ~47 ~-1 ~19 ~49 ~-1 ~19 dirt 0 
setblock ~47 ~-1 ~46 quartz_block 0 
setblock ~47 ~-1 ~50 quartz_block 0  
fill ~47 ~-1 ~77 ~49 ~-1 ~77 dirt 0  
fill ~47 ~-1 ~78 ~48 ~-1 ~78 dirt 0  
fill ~47 ~-1 ~79 ~47 ~-1 ~77 dirt 0 
setblock ~48 ~-1 ~16 dirt 0  
fill ~48 ~-1 ~18 ~49 ~-1 ~18 dirt 0  
fill ~48 ~-1 ~38 ~49 ~-1 ~38 dirt 0  
fill ~48 ~-1 ~39 ~55 ~-1 ~39 quartz_block 0 
setblock ~48 ~-1 ~46 sea_lantern 0 
setblock ~48 ~-1 ~50 sea_lantern 0  
fill ~48 ~-1 ~57 ~55 ~-1 ~57 quartz_block 0  
fill ~48 ~-1 ~58 ~49 ~-1 ~58 dirt 0 
setblock ~48 ~-1 ~80 dirt 0 
setblock ~49 ~-1 ~46 quartz_block 0 
setblock ~49 ~-1 ~50 quartz_block 0 
setblock ~49 ~-1 ~79 dirt 0 
setblock ~50 ~-1 ~29 dirt 0 
setblock ~50 ~-1 ~37 dirt 0  
fill ~50 ~-1 ~38 ~57 ~-1 ~38 quartz_block 0 
setblock ~50 ~-1 ~46 sea_lantern 0 
setblock ~50 ~-1 ~50 sea_lantern 0  
fill ~50 ~-1 ~58 ~57 ~-1 ~58 quartz_block 0 
setblock ~50 ~-1 ~59 dirt 0  
fill ~51 ~-1 ~30 ~58 ~-1 ~30 dirt 0  
fill ~51 ~-1 ~31 ~51 ~-1 ~36 dirt 0  
fill ~51 ~-1 ~37 ~59 ~-1 ~37 quartz_block 0 
setblock ~51 ~-1 ~46 quartz_block 0 
setblock ~51 ~-1 ~50 quartz_block 0  
fill ~51 ~-1 ~59 ~59 ~-1 ~59 quartz_block 0  
fill ~51 ~-1 ~60 ~51 ~-1 ~66 dirt 0 
setblock ~52 ~-1 ~31 sea_lantern 0  
fill ~52 ~-1 ~32 ~74 ~-1 ~32 quartz_block 0  
fill ~52 ~-1 ~33 ~74 ~-1 ~33 quartz_block 0  
fill ~52 ~-1 ~34 ~74 ~-1 ~34 quartz_block 0  
fill ~52 ~-1 ~35 ~74 ~-1 ~35 quartz_block 0  
fill ~52 ~-1 ~36 ~74 ~-1 ~36 quartz_block 0  
fill ~52 ~-1 ~45 ~52 ~-1 ~51 sea_lantern 0  
fill ~52 ~-1 ~60 ~74 ~-1 ~60 quartz_block 0  
fill ~52 ~-1 ~61 ~74 ~-1 ~61 quartz_block 0  
fill ~52 ~-1 ~62 ~74 ~-1 ~62 quartz_block 0  
fill ~52 ~-1 ~63 ~74 ~-1 ~63 quartz_block 0  
fill ~52 ~-1 ~64 ~74 ~-1 ~64 quartz_block 0 
setblock ~52 ~-1 ~65 sea_lantern 0  
fill ~52 ~-1 ~66 ~58 ~-1 ~66 dirt 0  
fill ~53 ~-1 ~17 ~53 ~-1 ~19 dirt 0 
setblock ~53 ~-1 ~21 dirt 0  
fill ~53 ~-1 ~31 ~54 ~-1 ~31 quartz_block 0  
fill ~53 ~-1 ~43 ~53 ~-1 ~44 sea_lantern 0  
fill ~53 ~-1 ~45 ~53 ~-1 ~51 quartz_block 0  
fill ~53 ~-1 ~52 ~53 ~-1 ~53 sea_lantern 0  
fill ~53 ~-1 ~65 ~54 ~-1 ~65 quartz_block 0 
setblock ~53 ~-1 ~75 dirt 0  
fill ~53 ~-1 ~77 ~53 ~-1 ~79 dirt 0 
setblock ~54 ~-1 ~29 dirt 0  
fill ~54 ~-1 ~41 ~54 ~-1 ~42 sea_lantern 0  
fill ~54 ~-1 ~43 ~54 ~-1 ~44 quartz_block 0  
fill ~54 ~-1 ~45 ~54 ~-1 ~51 sea_lantern 0  
fill ~54 ~-1 ~52 ~54 ~-1 ~53 quartz_block 0  
fill ~54 ~-1 ~54 ~54 ~-1 ~55 sea_lantern 0 
setblock ~54 ~-1 ~67 dirt 0 
setblock ~55 ~-1 ~31 sea_lantern 0 
setblock ~55 ~-1 ~40 sea_lantern 0  
fill ~55 ~-1 ~41 ~56 ~-1 ~41 quartz_block 0  
fill ~55 ~-1 ~42 ~55 ~-1 ~41 quartz_block 0  
fill ~55 ~-1 ~43 ~55 ~-1 ~44 sea_lantern 0  
fill ~55 ~-1 ~45 ~56 ~-1 ~45 quartz_block 0  
fill ~55 ~-1 ~46 ~55 ~-1 ~51 quartz_block 0  
fill ~55 ~-1 ~52 ~55 ~-1 ~53 sea_lantern 0  
fill ~55 ~-1 ~54 ~55 ~-1 ~55 quartz_block 0 
setblock ~55 ~-1 ~56 sea_lantern 0 
setblock ~55 ~-1 ~65 sea_lantern 0  
fill ~55 ~-1 ~67 ~56 ~-1 ~67 sea_lantern 0  
fill ~56 ~-1 ~31 ~57 ~-1 ~31 quartz_block 0  
fill ~56 ~-1 ~39 ~57 ~-1 ~39 sea_lantern 0  
fill ~56 ~-1 ~40 ~57 ~-1 ~40 quartz_block 0 
setblock ~56 ~-1 ~42 sea_lantern 0  
fill ~56 ~-1 ~43 ~57 ~-1 ~43 quartz_block 0  
fill ~56 ~-1 ~44 ~56 ~-1 ~43 quartz_block 0  
fill ~56 ~-1 ~46 ~56 ~-1 ~50 sea_lantern 0  
fill ~56 ~-1 ~51 ~56 ~-1 ~53 quartz_block 0 
setblock ~56 ~-1 ~54 sea_lantern 0  
fill ~56 ~-1 ~55 ~56 ~-1 ~56 quartz_block 0  
fill ~56 ~-1 ~57 ~57 ~-1 ~57 sea_lantern 0  
fill ~56 ~-1 ~65 ~57 ~-1 ~65 quartz_block 0 
setblock ~57 ~-1 ~29 dirt 0 
setblock ~57 ~-1 ~41 sea_lantern 0  
fill ~57 ~-1 ~42 ~58 ~-1 ~42 quartz_block 0  
fill ~57 ~-1 ~44 ~57 ~-1 ~45 sea_lantern 0  
fill ~57 ~-1 ~46 ~57 ~-1 ~50 quartz_block 0  
fill ~57 ~-1 ~51 ~57 ~-1 ~52 sea_lantern 0  
fill ~57 ~-1 ~53 ~57 ~-1 ~54 quartz_block 0 
setblock ~57 ~-1 ~55 sea_lantern 0 
setblock ~57 ~-1 ~56 quartz_block 0 
setblock ~57 ~-1 ~67 dirt 0 
setblock ~58 ~-1 ~31 sea_lantern 0  
fill ~58 ~-1 ~38 ~59 ~-1 ~38 sea_lantern 0  
fill ~58 ~-1 ~39 ~59 ~-1 ~39 quartz_block 0  
fill ~58 ~-1 ~40 ~59 ~-1 ~40 sea_lantern 0  
fill ~58 ~-1 ~41 ~60 ~-1 ~41 quartz_block 0 
setblock ~58 ~-1 ~43 sea_lantern 0  
fill ~58 ~-1 ~44 ~59 ~-1 ~44 quartz_block 0  
fill ~58 ~-1 ~45 ~58 ~-1 ~44 quartz_block 0  
fill ~58 ~-1 ~46 ~58 ~-1 ~50 sea_lantern 0  
fill ~58 ~-1 ~51 ~58 ~-1 ~52 quartz_block 0 
setblock ~58 ~-1 ~53 sea_lantern 0  
fill ~58 ~-1 ~54 ~58 ~-1 ~55 quartz_block 0  
fill ~58 ~-1 ~56 ~59 ~-1 ~56 sea_lantern 0  
fill ~58 ~-1 ~57 ~59 ~-1 ~57 quartz_block 0  
fill ~58 ~-1 ~58 ~59 ~-1 ~58 sea_lantern 0 
setblock ~58 ~-1 ~65 sea_lantern 0  
fill ~59 ~-1 ~30 ~67 ~-1 ~30 quartz_block 0  
fill ~59 ~-1 ~31 ~67 ~-1 ~31 quartz_block 0  
fill ~59 ~-1 ~42 ~60 ~-1 ~42 sea_lantern 0  
fill ~59 ~-1 ~43 ~60 ~-1 ~43 quartz_block 0 
setblock ~59 ~-1 ~45 sea_lantern 0  
fill ~59 ~-1 ~46 ~60 ~-1 ~46 quartz_block 0  
fill ~59 ~-1 ~47 ~59 ~-1 ~50 quartz_block 0 
setblock ~59 ~-1 ~51 sea_lantern 0  
fill ~59 ~-1 ~52 ~59 ~-1 ~53 quartz_block 0  
fill ~59 ~-1 ~54 ~60 ~-1 ~54 sea_lantern 0  
fill ~59 ~-1 ~55 ~60 ~-1 ~55 quartz_block 0  
fill ~59 ~-1 ~65 ~67 ~-1 ~65 quartz_block 0  
fill ~59 ~-1 ~66 ~67 ~-1 ~66 quartz_block 0  
fill ~60 ~-1 ~37 ~66 ~-1 ~37 sea_lantern 0  
fill ~60 ~-1 ~38 ~66 ~-1 ~38 quartz_block 0  
fill ~60 ~-1 ~39 ~66 ~-1 ~39 sea_lantern 0  
fill ~60 ~-1 ~40 ~66 ~-1 ~40 quartz_block 0 
setblock ~60 ~-1 ~44 sea_lantern 0  
fill ~60 ~-1 ~45 ~61 ~-1 ~45 quartz_block 0  
fill ~60 ~-1 ~47 ~60 ~-1 ~49 sea_lantern 0  
fill ~60 ~-1 ~50 ~60 ~-1 ~51 quartz_block 0 
setblock ~60 ~-1 ~52 sea_lantern 0 
setblock ~60 ~-1 ~53 quartz_block 0  
fill ~60 ~-1 ~56 ~66 ~-1 ~56 quartz_block 0  
fill ~60 ~-1 ~57 ~66 ~-1 ~57 sea_lantern 0  
fill ~60 ~-1 ~58 ~66 ~-1 ~58 quartz_block 0  
fill ~60 ~-1 ~59 ~66 ~-1 ~59 sea_lantern 0  
fill ~61 ~-1 ~41 ~65 ~-1 ~41 sea_lantern 0  
fill ~61 ~-1 ~42 ~65 ~-1 ~42 quartz_block 0  
fill ~61 ~-1 ~43 ~65 ~-1 ~43 sea_lantern 0  
fill ~61 ~-1 ~44 ~65 ~-1 ~44 quartz_block 0 
setblock ~61 ~-1 ~46 sea_lantern 0  
fill ~61 ~-1 ~47 ~62 ~-1 ~47 quartz_block 0  
fill ~61 ~-1 ~48 ~61 ~-1 ~49 quartz_block 0 
setblock ~61 ~-1 ~50 sea_lantern 0  
fill ~61 ~-1 ~51 ~61 ~-1 ~52 quartz_block 0  
fill ~61 ~-1 ~53 ~65 ~-1 ~53 sea_lantern 0  
fill ~61 ~-1 ~54 ~65 ~-1 ~54 quartz_block 0  
fill ~61 ~-1 ~55 ~65 ~-1 ~55 sea_lantern 0  
fill ~62 ~-1 ~45 ~64 ~-1 ~45 sea_lantern 0  
fill ~62 ~-1 ~46 ~64 ~-1 ~46 quartz_block 0  
fill ~62 ~-1 ~48 ~64 ~-1 ~48 sea_lantern 0  
fill ~62 ~-1 ~49 ~62 ~-1 ~50 quartz_block 0  
fill ~62 ~-1 ~51 ~64 ~-1 ~51 sea_lantern 0  
fill ~62 ~-1 ~52 ~65 ~-1 ~52 quartz_block 0 
setblock ~63 ~-1 ~47 sea_lantern 0 
setblock ~63 ~-1 ~49 sea_lantern 0  
fill ~63 ~-1 ~50 ~64 ~-1 ~50 quartz_block 0  
fill ~64 ~-1 ~47 ~65 ~-1 ~47 quartz_block 0  
fill ~64 ~-1 ~49 ~65 ~-1 ~49 quartz_block 0  
fill ~65 ~-1 ~45 ~66 ~-1 ~45 quartz_block 0 
setblock ~65 ~-1 ~46 sea_lantern 0 
setblock ~65 ~-1 ~48 quartz_block 0 
setblock ~65 ~-1 ~50 sea_lantern 0  
fill ~65 ~-1 ~51 ~66 ~-1 ~51 quartz_block 0  
fill ~66 ~-1 ~41 ~68 ~-1 ~41 quartz_block 0  
fill ~66 ~-1 ~42 ~67 ~-1 ~42 sea_lantern 0  
fill ~66 ~-1 ~43 ~67 ~-1 ~43 quartz_block 0 
setblock ~66 ~-1 ~44 sea_lantern 0  
fill ~66 ~-1 ~46 ~67 ~-1 ~46 quartz_block 0  
fill ~66 ~-1 ~47 ~66 ~-1 ~49 sea_lantern 0  
fill ~66 ~-1 ~50 ~67 ~-1 ~50 quartz_block 0 
setblock ~66 ~-1 ~52 sea_lantern 0  
fill ~66 ~-1 ~53 ~67 ~-1 ~53 quartz_block 0  
fill ~66 ~-1 ~54 ~67 ~-1 ~54 sea_lantern 0  
fill ~66 ~-1 ~55 ~68 ~-1 ~55 quartz_block 0  
fill ~67 ~-1 ~37 ~75 ~-1 ~37 quartz_block 0  
fill ~67 ~-1 ~38 ~68 ~-1 ~38 sea_lantern 0  
fill ~67 ~-1 ~39 ~68 ~-1 ~39 quartz_block 0  
fill ~67 ~-1 ~40 ~68 ~-1 ~40 sea_lantern 0  
fill ~67 ~-1 ~44 ~68 ~-1 ~44 quartz_block 0 
setblock ~67 ~-1 ~45 sea_lantern 0  
fill ~67 ~-1 ~47 ~67 ~-1 ~50 quartz_block 0 
setblock ~67 ~-1 ~51 sea_lantern 0  
fill ~67 ~-1 ~52 ~68 ~-1 ~52 quartz_block 0  
fill ~67 ~-1 ~56 ~68 ~-1 ~56 sea_lantern 0  
fill ~67 ~-1 ~57 ~68 ~-1 ~57 quartz_block 0  
fill ~67 ~-1 ~58 ~68 ~-1 ~58 sea_lantern 0  
fill ~67 ~-1 ~59 ~75 ~-1 ~59 quartz_block 0  
fill ~68 ~-1 ~30 ~75 ~-1 ~30 dirt 0 
setblock ~68 ~-1 ~31 sea_lantern 0  
fill ~68 ~-1 ~42 ~69 ~-1 ~42 quartz_block 0 
setblock ~68 ~-1 ~43 sea_lantern 0 
setblock ~68 ~-1 ~45 quartz_block 0  
fill ~68 ~-1 ~46 ~68 ~-1 ~50 sea_lantern 0 
setblock ~68 ~-1 ~51 quartz_block 0 
setblock ~68 ~-1 ~53 sea_lantern 0  
fill ~68 ~-1 ~54 ~69 ~-1 ~54 quartz_block 0 
setblock ~68 ~-1 ~65 sea_lantern 0  
fill ~68 ~-1 ~66 ~75 ~-1 ~66 dirt 0 
setblock ~69 ~-1 ~29 dirt 0  
fill ~69 ~-1 ~31 ~70 ~-1 ~31 quartz_block 0  
fill ~69 ~-1 ~38 ~76 ~-1 ~38 quartz_block 0  
fill ~69 ~-1 ~39 ~70 ~-1 ~39 sea_lantern 0  
fill ~69 ~-1 ~40 ~70 ~-1 ~40 quartz_block 0 
setblock ~69 ~-1 ~41 sea_lantern 0  
fill ~69 ~-1 ~43 ~70 ~-1 ~43 quartz_block 0  
fill ~69 ~-1 ~44 ~69 ~-1 ~45 sea_lantern 0  
fill ~69 ~-1 ~46 ~69 ~-1 ~50 quartz_block 0  
fill ~69 ~-1 ~51 ~69 ~-1 ~52 sea_lantern 0  
fill ~69 ~-1 ~53 ~70 ~-1 ~53 quartz_block 0 
setblock ~69 ~-1 ~55 sea_lantern 0  
fill ~69 ~-1 ~56 ~70 ~-1 ~56 quartz_block 0  
fill ~69 ~-1 ~57 ~70 ~-1 ~57 sea_lantern 0  
fill ~69 ~-1 ~58 ~76 ~-1 ~58 quartz_block 0  
fill ~69 ~-1 ~65 ~70 ~-1 ~65 quartz_block 0 
setblock ~69 ~-1 ~67 dirt 0  
fill ~70 ~-1 ~41 ~71 ~-1 ~41 quartz_block 0 
setblock ~70 ~-1 ~42 sea_lantern 0  
fill ~70 ~-1 ~44 ~70 ~-1 ~45 quartz_block 0  
fill ~70 ~-1 ~46 ~70 ~-1 ~50 sea_lantern 0  
fill ~70 ~-1 ~51 ~71 ~-1 ~51 quartz_block 0  
fill ~70 ~-1 ~52 ~70 ~-1 ~51 quartz_block 0 
setblock ~70 ~-1 ~54 sea_lantern 0  
fill ~70 ~-1 ~55 ~71 ~-1 ~55 quartz_block 0  
fill ~70 ~-1 ~67 ~71 ~-1 ~67 sea_lantern 0 
setblock ~71 ~-1 ~31 sea_lantern 0  
fill ~71 ~-1 ~39 ~78 ~-1 ~39 quartz_block 0 
setblock ~71 ~-1 ~40 sea_lantern 0 
setblock ~71 ~-1 ~42 quartz_block 0  
fill ~71 ~-1 ~43 ~71 ~-1 ~44 sea_lantern 0  
fill ~71 ~-1 ~45 ~71 ~-1 ~51 quartz_block 0  
fill ~71 ~-1 ~52 ~71 ~-1 ~53 sea_lantern 0 
setblock ~71 ~-1 ~54 quartz_block 0 
setblock ~71 ~-1 ~56 sea_lantern 0  
fill ~71 ~-1 ~57 ~78 ~-1 ~57 quartz_block 0 
setblock ~71 ~-1 ~65 sea_lantern 0 
setblock ~72 ~-1 ~29 dirt 0  
fill ~72 ~-1 ~31 ~73 ~-1 ~31 quartz_block 0  
fill ~72 ~-1 ~40 ~81 ~-1 ~40 quartz_block 0  
fill ~72 ~-1 ~41 ~72 ~-1 ~42 sea_lantern 0  
fill ~72 ~-1 ~43 ~72 ~-1 ~44 quartz_block 0  
fill ~72 ~-1 ~45 ~72 ~-1 ~51 sea_lantern 0  
fill ~72 ~-1 ~52 ~72 ~-1 ~53 quartz_block 0  
fill ~72 ~-1 ~54 ~72 ~-1 ~55 sea_lantern 0  
fill ~72 ~-1 ~56 ~81 ~-1 ~56 quartz_block 0  
fill ~72 ~-1 ~65 ~73 ~-1 ~65 quartz_block 0 
setblock ~72 ~-1 ~67 dirt 0  
fill ~73 ~-1 ~17 ~73 ~-1 ~19 dirt 0 
setblock ~73 ~-1 ~21 dirt 0  
fill ~73 ~-1 ~41 ~102 ~-1 ~41 quartz_block 0  
fill ~73 ~-1 ~42 ~102 ~-1 ~42 quartz_block 0  
fill ~73 ~-1 ~43 ~73 ~-1 ~44 sea_lantern 0  
fill ~73 ~-1 ~45 ~73 ~-1 ~51 quartz_block 0  
fill ~73 ~-1 ~52 ~73 ~-1 ~53 sea_lantern 0  
fill ~73 ~-1 ~54 ~102 ~-1 ~54 quartz_block 0  
fill ~73 ~-1 ~55 ~102 ~-1 ~55 quartz_block 0 
setblock ~73 ~-1 ~75 dirt 0  
fill ~73 ~-1 ~77 ~73 ~-1 ~79 dirt 0 
setblock ~74 ~-1 ~31 sea_lantern 0  
fill ~74 ~-1 ~43 ~102 ~-1 ~43 quartz_block 0  
fill ~74 ~-1 ~44 ~103 ~-1 ~44 quartz_block 0  
fill ~74 ~-1 ~45 ~74 ~-1 ~51 sea_lantern 0  
fill ~74 ~-1 ~52 ~103 ~-1 ~52 quartz_block 0  
fill ~74 ~-1 ~53 ~102 ~-1 ~53 quartz_block 0 
setblock ~74 ~-1 ~65 sea_lantern 0  
fill ~75 ~-1 ~31 ~75 ~-1 ~36 dirt 0  
fill ~75 ~-1 ~45 ~103 ~-1 ~45 quartz_block 0  
fill ~75 ~-1 ~46 ~75 ~-1 ~59 quartz_block 0  
fill ~75 ~-1 ~60 ~75 ~-1 ~66 dirt 0 
setblock ~76 ~-1 ~29 dirt 0  
fill ~76 ~-1 ~35 ~76 ~-1 ~36 quartz_block 0 
setblock ~76 ~-1 ~37 dirt 0 
setblock ~76 ~-1 ~46 sea_lantern 0  
fill ~76 ~-1 ~47 ~105 ~-1 ~47 quartz_block 0  
fill ~76 ~-1 ~48 ~105 ~-1 ~48 quartz_block 0  
fill ~76 ~-1 ~49 ~105 ~-1 ~49 quartz_block 0 
setblock ~76 ~-1 ~50 sea_lantern 0  
fill ~76 ~-1 ~51 ~103 ~-1 ~51 quartz_block 0 
setblock ~76 ~-1 ~59 dirt 0  
fill ~77 ~-1 ~17 ~79 ~-1 ~17 dirt 0  
fill ~77 ~-1 ~18 ~78 ~-1 ~18 dirt 0  
fill ~77 ~-1 ~19 ~79 ~-1 ~19 dirt 0 
setblock ~77 ~-1 ~38 dirt 0 
setblock ~77 ~-1 ~46 quartz_block 0 
setblock ~77 ~-1 ~50 quartz_block 0 
setblock ~77 ~-1 ~58 dirt 0  
fill ~77 ~-1 ~77 ~79 ~-1 ~77 dirt 0  
fill ~77 ~-1 ~78 ~78 ~-1 ~78 dirt 0  
fill ~77 ~-1 ~79 ~79 ~-1 ~79 dirt 0 
setblock ~78 ~-1 ~16 dirt 0 
setblock ~78 ~-1 ~46 sea_lantern 0 
setblock ~78 ~-1 ~50 sea_lantern 0 
setblock ~78 ~-1 ~80 dirt 0 
setblock ~79 ~-1 ~46 quartz_block 0 
setblock ~79 ~-1 ~50 quartz_block 0 
setblock ~80 ~-1 ~46 sea_lantern 0 
setblock ~80 ~-1 ~50 sea_lantern 0 
setblock ~81 ~-1 ~46 quartz_block 0 
setblock ~81 ~-1 ~50 quartz_block 0  
fill ~82 ~-1 ~40 ~86 ~-1 ~40 dirt 0 
setblock ~82 ~-1 ~46 sea_lantern 0 
setblock ~82 ~-1 ~50 sea_lantern 0  
fill ~82 ~-1 ~56 ~86 ~-1 ~56 dirt 0 
setblock ~83 ~-1 ~46 quartz_block 0 
setblock ~83 ~-1 ~50 quartz_block 0 
setblock ~84 ~-1 ~46 sea_lantern 0 
setblock ~84 ~-1 ~50 sea_lantern 0 
setblock ~85 ~-1 ~46 quartz_block 0 
setblock ~85 ~-1 ~50 quartz_block 0 
setblock ~86 ~-1 ~46 sea_lantern 0 
setblock ~86 ~-1 ~50 sea_lantern 0  
fill ~87 ~-1 ~40 ~90 ~-1 ~40 quartz_block 0 
setblock ~87 ~-1 ~46 quartz_block 0 
setblock ~87 ~-1 ~50 quartz_block 0  
fill ~87 ~-1 ~56 ~90 ~-1 ~56 quartz_block 0 
setblock ~88 ~-1 ~46 sea_lantern 0 
setblock ~88 ~-1 ~50 sea_lantern 0 
setblock ~89 ~-1 ~46 quartz_block 0 
setblock ~89 ~-1 ~50 quartz_block 0 
setblock ~90 ~-1 ~46 sea_lantern 0 
setblock ~90 ~-1 ~50 sea_lantern 0  
fill ~91 ~-1 ~40 ~95 ~-1 ~40 dirt 0 
setblock ~91 ~-1 ~46 quartz_block 0 
setblock ~91 ~-1 ~50 quartz_block 0  
fill ~91 ~-1 ~56 ~95 ~-1 ~56 dirt 0 
setblock ~92 ~-1 ~46 sea_lantern 0 
setblock ~92 ~-1 ~50 sea_lantern 0 
setblock ~93 ~-1 ~46 quartz_block 0 
setblock ~93 ~-1 ~50 quartz_block 0 
setblock ~94 ~-1 ~46 sea_lantern 0 
setblock ~94 ~-1 ~50 sea_lantern 0 
setblock ~95 ~-1 ~46 quartz_block 0 
setblock ~95 ~-1 ~50 quartz_block 0  
fill ~96 ~-1 ~40 ~101 ~-1 ~40 quartz_block 0 
setblock ~96 ~-1 ~46 sea_lantern 0 
setblock ~96 ~-1 ~50 sea_lantern 0  
fill ~96 ~-1 ~56 ~101 ~-1 ~56 quartz_block 0 
setblock ~97 ~-1 ~46 quartz_block 0 
setblock ~97 ~-1 ~50 quartz_block 0  
fill ~98 ~-1 ~17 ~98 ~-1 ~19 dirt 0 
setblock ~98 ~-1 ~21 dirt 0 
setblock ~98 ~-1 ~46 sea_lantern 0 
setblock ~98 ~-1 ~50 sea_lantern 0 
setblock ~98 ~-1 ~75 dirt 0  
fill ~98 ~-1 ~77 ~98 ~-1 ~79 dirt 0  
fill ~99 ~-1 ~39 ~100 ~-1 ~39 quartz_block 0 
setblock ~99 ~-1 ~46 quartz_block 0 
setblock ~99 ~-1 ~50 quartz_block 0  
fill ~99 ~-1 ~57 ~100 ~-1 ~57 quartz_block 0 
setblock ~100 ~-1 ~38 dirt 0 
setblock ~100 ~-1 ~46 sea_lantern 0 
setblock ~100 ~-1 ~50 sea_lantern 0 
setblock ~100 ~-1 ~58 dirt 0 
setblock ~101 ~-1 ~37 dirt 0  
fill ~101 ~-1 ~38 ~101 ~-1 ~39 sea_lantern 0 
setblock ~101 ~-1 ~46 quartz_block 0 
setblock ~101 ~-1 ~50 quartz_block 0  
fill ~101 ~-1 ~57 ~101 ~-1 ~58 sea_lantern 0 
setblock ~101 ~-1 ~59 dirt 0  
fill ~102 ~-1 ~17 ~104 ~-1 ~17 dirt 0  
fill ~102 ~-1 ~18 ~103 ~-1 ~18 dirt 0  
fill ~102 ~-1 ~19 ~104 ~-1 ~19 dirt 0 
setblock ~102 ~-1 ~40 sea_lantern 0 
setblock ~102 ~-1 ~46 sea_lantern 0 
setblock ~102 ~-1 ~50 sea_lantern 0 
setblock ~102 ~-1 ~56 sea_lantern 0  
fill ~102 ~-1 ~77 ~104 ~-1 ~77 dirt 0  
fill ~102 ~-1 ~78 ~103 ~-1 ~78 dirt 0  
fill ~102 ~-1 ~79 ~104 ~-1 ~79 dirt 0 
setblock ~103 ~-1 ~16 dirt 0  
fill ~103 ~-1 ~41 ~103 ~-1 ~43 sea_lantern 0 
setblock ~103 ~-1 ~46 quartz_block 0 
setblock ~103 ~-1 ~50 quartz_block 0  
fill ~103 ~-1 ~53 ~103 ~-1 ~55 sea_lantern 0 
setblock ~103 ~-1 ~80 dirt 0 
setblock ~104 ~-1 ~44 sea_lantern 0 
setblock ~104 ~-1 ~46 dirt 0 
setblock ~104 ~-1 ~50 dirt 0 
setblock ~104 ~-1 ~52 sea_lantern 0 
setblock ~20 ~0 ~46 quartz_stairs 0 
setblock ~20 ~0 ~50 quartz_stairs 0  
fill ~21 ~0 ~44 ~21 ~2 ~44 stained_glass 11  
fill ~21 ~0 ~45 ~21 ~2 ~45 stained_glass 11 
setblock ~21 ~0 ~46 sea_lantern 0 
setblock ~21 ~0 ~50 sea_lantern 0  
fill ~21 ~0 ~51 ~21 ~2 ~51 stained_glass 11  
fill ~21 ~0 ~52 ~21 ~2 ~52 stained_glass 11 
setblock ~22 ~0 ~17 quartz_block 0 
setblock ~22 ~0 ~18 sea_lantern 0  
fill ~22 ~0 ~19 ~24 ~0 ~19 quartz_block 0  
fill ~22 ~0 ~41 ~22 ~1 ~41 stained_glass 11  
fill ~22 ~0 ~42 ~22 ~0 ~43 stained_glass 11 
setblock ~22 ~0 ~45 quartz_stairs 2  
fill ~22 ~0 ~46 ~22 ~2 ~46 quartz_block 0  
fill ~22 ~0 ~50 ~22 ~2 ~50 quartz_block 0 
setblock ~22 ~0 ~51 quartz_stairs 3  
fill ~22 ~0 ~53 ~22 ~0 ~55 stained_glass 11  
fill ~22 ~0 ~77 ~24 ~0 ~77 quartz_block 0 
setblock ~22 ~0 ~78 sea_lantern 0 
setblock ~22 ~0 ~79 quartz_block 0 
setblock ~23 ~0 ~16 quartz_block 0 
setblock ~23 ~0 ~17 sea_lantern 0  
fill ~23 ~0 ~18 ~23 ~1 ~18 quartz_block 0  
fill ~23 ~0 ~39 ~24 ~0 ~39 stained_glass 11  
fill ~23 ~0 ~40 ~23 ~0 ~39 stained_glass 11  
fill ~23 ~0 ~56 ~23 ~0 ~57 stained_glass 11  
fill ~23 ~0 ~78 ~23 ~1 ~78 quartz_block 0 
setblock ~23 ~0 ~79 sea_lantern 0 
setblock ~23 ~0 ~80 quartz_block 0  
fill ~24 ~0 ~17 ~24 ~2 ~17 quartz_block 0 
setblock ~24 ~0 ~18 sea_lantern 0  
fill ~24 ~0 ~38 ~24 ~1 ~38 stained_glass 11  
fill ~24 ~0 ~57 ~24 ~0 ~58 stained_glass 11 
setblock ~24 ~0 ~78 sea_lantern 0  
fill ~24 ~0 ~79 ~24 ~2 ~79 quartz_block 0 
setblock ~25 ~0 ~37 quartz_block 1 
setblock ~25 ~0 ~59 quartz_block 1 
setblock ~26 ~0 ~38 quartz_block 0 
setblock ~26 ~0 ~58 quartz_block 0 
setblock ~27 ~0 ~38 quartz_stairs 6 
setblock ~27 ~0 ~58 quartz_stairs 7  
fill ~28 ~0 ~17 ~28 ~0 ~19 quartz_block 0 
setblock ~28 ~0 ~20 sea_lantern 0 
setblock ~28 ~0 ~21 quartz_block 0 
setblock ~28 ~0 ~39 quartz_stairs 5 
setblock ~28 ~0 ~57 quartz_stairs 5 
setblock ~28 ~0 ~75 quartz_block 0 
setblock ~28 ~0 ~76 sea_lantern 0  
fill ~28 ~0 ~77 ~28 ~1 ~77 quartz_block 0  
fill ~28 ~0 ~78 ~28 ~0 ~79 quartz_block 0  
fill ~29 ~0 ~39 ~31 ~0 ~39 quartz_stairs 6  
fill ~29 ~0 ~57 ~31 ~0 ~57 quartz_stairs 7  
fill ~31 ~0 ~40 ~35 ~0 ~40 stained_hardened_clay 10  
fill ~31 ~0 ~56 ~35 ~0 ~56 stained_hardened_clay 10  
fill ~32 ~0 ~39 ~34 ~0 ~39 stone_slab 15  
fill ~32 ~0 ~57 ~34 ~0 ~57 stone_slab 15 
setblock ~35 ~0 ~39 quartz_stairs 6 
setblock ~35 ~0 ~57 quartz_stairs 7  
fill ~36 ~0 ~40 ~39 ~0 ~40 stained_glass 0  
fill ~36 ~0 ~56 ~39 ~0 ~56 stained_glass 0 
setblock ~40 ~0 ~39 quartz_stairs 6  
fill ~40 ~0 ~40 ~44 ~0 ~40 stained_hardened_clay 10  
fill ~40 ~0 ~56 ~44 ~0 ~56 stained_hardened_clay 10 
setblock ~40 ~0 ~57 quartz_stairs 7  
fill ~41 ~0 ~39 ~43 ~0 ~39 stone_slab 15  
fill ~41 ~0 ~57 ~43 ~0 ~57 stone_slab 15  
fill ~44 ~0 ~39 ~46 ~0 ~39 quartz_stairs 6  
fill ~44 ~0 ~57 ~46 ~0 ~57 quartz_stairs 7 
setblock ~47 ~0 ~17 quartz_block 0 
setblock ~47 ~0 ~18 sea_lantern 0  
fill ~47 ~0 ~19 ~49 ~0 ~19 quartz_block 0 
setblock ~47 ~0 ~39 quartz_stairs 4 
setblock ~47 ~0 ~57 quartz_stairs 4  
fill ~47 ~0 ~77 ~49 ~0 ~77 quartz_block 0 
setblock ~47 ~0 ~78 sea_lantern 0 
setblock ~47 ~0 ~79 quartz_block 0 
setblock ~48 ~0 ~16 quartz_block 0 
setblock ~48 ~0 ~17 sea_lantern 0  
fill ~48 ~0 ~18 ~48 ~1 ~18 quartz_block 0 
setblock ~48 ~0 ~38 quartz_stairs 6 
setblock ~48 ~0 ~58 quartz_stairs 7  
fill ~48 ~0 ~78 ~48 ~1 ~78 quartz_block 0 
setblock ~48 ~0 ~79 sea_lantern 0 
setblock ~48 ~0 ~80 quartz_block 0  
fill ~49 ~0 ~17 ~49 ~2 ~17 quartz_block 0 
setblock ~49 ~0 ~18 sea_lantern 0 
setblock ~49 ~0 ~38 quartz_block 0 
setblock ~49 ~0 ~58 quartz_block 0 
setblock ~49 ~0 ~78 sea_lantern 0  
fill ~49 ~0 ~79 ~49 ~2 ~79 quartz_block 0 
setblock ~50 ~0 ~29 double_stone_slab 0 
setblock ~50 ~0 ~37 quartz_block 1 
setblock ~50 ~0 ~59 quartz_block 1 
setblock ~50 ~0 ~67 double_stone_slab 0  
fill ~51 ~0 ~30 ~53 ~0 ~30 stonebrick 0  
fill ~51 ~0 ~31 ~51 ~9 ~31 stonebrick 0  
fill ~51 ~0 ~32 ~51 ~6 ~32 stonebrick 0  
fill ~51 ~0 ~33 ~51 ~4 ~33 stonebrick 0  
fill ~51 ~0 ~34 ~51 ~2 ~34 stonebrick 0  
fill ~51 ~0 ~35 ~51 ~1 ~35 stonebrick 0  
fill ~51 ~0 ~36 ~51 ~0 ~30 stonebrick 0  
fill ~51 ~0 ~60 ~51 ~0 ~66 stonebrick 0 
setblock ~52 ~0 ~31 cobblestone_wall 0 
setblock ~52 ~0 ~65 cobblestone_wall 0  
fill ~52 ~0 ~66 ~53 ~0 ~66 stonebrick 0  
fill ~53 ~0 ~17 ~53 ~0 ~19 quartz_block 0 
setblock ~53 ~0 ~20 sea_lantern 0 
setblock ~53 ~0 ~21 quartz_block 0  
fill ~53 ~0 ~29 ~53 ~2 ~29 stone_slab 7  
fill ~53 ~0 ~67 ~53 ~2 ~67 stone_slab 7 
setblock ~53 ~0 ~75 quartz_block 0 
setblock ~53 ~0 ~76 sea_lantern 0  
fill ~53 ~0 ~77 ~53 ~1 ~77 quartz_block 0  
fill ~53 ~0 ~78 ~53 ~0 ~79 quartz_block 0  
fill ~54 ~0 ~29 ~54 ~1 ~29 quartz_block 0  
fill ~54 ~0 ~30 ~54 ~1 ~30 sea_lantern 0  
fill ~54 ~0 ~66 ~54 ~1 ~66 sea_lantern 0  
fill ~54 ~0 ~67 ~54 ~1 ~67 quartz_block 0  
fill ~55 ~0 ~30 ~56 ~0 ~30 stained_hardened_clay 10 
setblock ~55 ~0 ~31 cobblestone_wall 0 
setblock ~55 ~0 ~65 cobblestone_wall 0  
fill ~55 ~0 ~66 ~56 ~0 ~66 stained_hardened_clay 10  
fill ~56 ~0 ~31 ~56 ~3 ~31 stained_hardened_clay 10  
fill ~56 ~0 ~65 ~56 ~3 ~65 stained_hardened_clay 10  
fill ~57 ~0 ~29 ~57 ~1 ~29 quartz_block 0  
fill ~57 ~0 ~30 ~57 ~1 ~30 stonebrick 0  
fill ~57 ~0 ~31 ~58 ~0 ~31 cobblestone_wall 0  
fill ~57 ~0 ~65 ~58 ~0 ~65 cobblestone_wall 0  
fill ~57 ~0 ~66 ~57 ~1 ~66 stonebrick 0  
fill ~57 ~0 ~67 ~57 ~1 ~67 quartz_block 0  
fill ~58 ~0 ~30 ~58 ~1 ~30 quartz_block 0  
fill ~58 ~0 ~66 ~58 ~1 ~66 quartz_block 0  
fill ~68 ~0 ~30 ~68 ~1 ~30 quartz_block 0  
fill ~68 ~0 ~31 ~69 ~0 ~31 cobblestone_wall 0  
fill ~68 ~0 ~65 ~69 ~0 ~65 cobblestone_wall 0  
fill ~68 ~0 ~66 ~68 ~1 ~66 quartz_block 0  
fill ~69 ~0 ~29 ~69 ~1 ~29 quartz_block 0  
fill ~69 ~0 ~30 ~69 ~1 ~30 stonebrick 0  
fill ~69 ~0 ~66 ~69 ~1 ~66 stonebrick 0  
fill ~69 ~0 ~67 ~69 ~1 ~67 quartz_block 0  
fill ~70 ~0 ~30 ~71 ~0 ~30 stained_hardened_clay 10  
fill ~70 ~0 ~31 ~70 ~3 ~31 stained_hardened_clay 10  
fill ~70 ~0 ~65 ~70 ~3 ~65 stained_hardened_clay 10  
fill ~70 ~0 ~66 ~71 ~0 ~66 stained_hardened_clay 10 
setblock ~71 ~0 ~31 cobblestone_wall 0 
setblock ~71 ~0 ~65 cobblestone_wall 0  
fill ~72 ~0 ~29 ~72 ~1 ~29 quartz_block 0  
fill ~72 ~0 ~30 ~72 ~1 ~30 sea_lantern 0  
fill ~72 ~0 ~66 ~72 ~1 ~66 sea_lantern 0  
fill ~72 ~0 ~67 ~72 ~1 ~67 quartz_block 0  
fill ~73 ~0 ~17 ~73 ~0 ~19 quartz_block 0 
setblock ~73 ~0 ~20 sea_lantern 0 
setblock ~73 ~0 ~21 quartz_block 0  
fill ~73 ~0 ~29 ~73 ~2 ~29 stone_slab 7  
fill ~73 ~0 ~30 ~75 ~0 ~30 stonebrick 0  
fill ~73 ~0 ~66 ~75 ~0 ~66 stonebrick 0  
fill ~73 ~0 ~67 ~73 ~2 ~67 stone_slab 7 
setblock ~73 ~0 ~75 quartz_block 0 
setblock ~73 ~0 ~76 sea_lantern 0  
fill ~73 ~0 ~77 ~73 ~1 ~77 quartz_block 0  
fill ~73 ~0 ~78 ~73 ~0 ~79 quartz_block 0 
setblock ~74 ~0 ~31 cobblestone_wall 0 
setblock ~74 ~0 ~65 cobblestone_wall 0  
fill ~75 ~0 ~31 ~75 ~9 ~31 stonebrick 0  
fill ~75 ~0 ~32 ~75 ~6 ~32 stonebrick 0  
fill ~75 ~0 ~33 ~75 ~4 ~33 stonebrick 0  
fill ~75 ~0 ~34 ~75 ~2 ~34 stonebrick 0  
fill ~75 ~0 ~35 ~75 ~1 ~35 stonebrick 0  
fill ~75 ~0 ~36 ~75 ~0 ~30 stonebrick 0  
fill ~75 ~0 ~60 ~75 ~0 ~66 stonebrick 0 
setblock ~76 ~0 ~29 double_stone_slab 0 
setblock ~76 ~0 ~37 quartz_block 1 
setblock ~76 ~0 ~59 quartz_block 1 
setblock ~76 ~0 ~67 double_stone_slab 0  
fill ~77 ~0 ~17 ~77 ~2 ~17 quartz_block 0 
setblock ~77 ~0 ~18 sea_lantern 0  
fill ~77 ~0 ~19 ~79 ~0 ~19 quartz_block 0 
setblock ~77 ~0 ~38 quartz_block 0 
setblock ~77 ~0 ~58 quartz_block 0  
fill ~77 ~0 ~77 ~79 ~0 ~77 quartz_block 0 
setblock ~77 ~0 ~78 sea_lantern 0  
fill ~77 ~0 ~79 ~77 ~2 ~79 quartz_block 0 
setblock ~78 ~0 ~16 quartz_block 0 
setblock ~78 ~0 ~17 sea_lantern 0  
fill ~78 ~0 ~18 ~78 ~1 ~18 quartz_block 0 
setblock ~78 ~0 ~38 quartz_stairs 6 
setblock ~78 ~0 ~58 quartz_stairs 7  
fill ~78 ~0 ~78 ~78 ~1 ~78 quartz_block 0 
setblock ~78 ~0 ~79 sea_lantern 0 
setblock ~78 ~0 ~80 quartz_block 0 
setblock ~79 ~0 ~17 quartz_block 0 
setblock ~79 ~0 ~18 sea_lantern 0 
setblock ~79 ~0 ~39 quartz_stairs 5 
setblock ~79 ~0 ~57 quartz_stairs 5 
setblock ~79 ~0 ~78 sea_lantern 0 
setblock ~79 ~0 ~79 quartz_block 0  
fill ~80 ~0 ~39 ~82 ~0 ~39 quartz_stairs 6  
fill ~80 ~0 ~57 ~82 ~0 ~57 quartz_stairs 7  
fill ~82 ~0 ~40 ~86 ~0 ~40 stained_hardened_clay 10  
fill ~82 ~0 ~56 ~86 ~0 ~56 stained_hardened_clay 10  
fill ~83 ~0 ~39 ~85 ~0 ~39 stone_slab 15  
fill ~83 ~0 ~57 ~85 ~0 ~57 stone_slab 15 
setblock ~86 ~0 ~39 quartz_stairs 6 
setblock ~86 ~0 ~57 quartz_stairs 7  
fill ~87 ~0 ~40 ~90 ~0 ~40 stained_glass 0  
fill ~87 ~0 ~56 ~90 ~0 ~56 stained_glass 0 
setblock ~91 ~0 ~39 quartz_stairs 6  
fill ~91 ~0 ~40 ~95 ~0 ~40 stained_hardened_clay 10  
fill ~91 ~0 ~56 ~95 ~0 ~56 stained_hardened_clay 10 
setblock ~91 ~0 ~57 quartz_stairs 7  
fill ~92 ~0 ~39 ~94 ~0 ~39 stone_slab 15  
fill ~92 ~0 ~57 ~94 ~0 ~57 stone_slab 15  
fill ~95 ~0 ~39 ~97 ~0 ~39 quartz_stairs 6  
fill ~95 ~0 ~57 ~97 ~0 ~57 quartz_stairs 7  
fill ~98 ~0 ~17 ~98 ~0 ~19 quartz_block 0 
setblock ~98 ~0 ~20 sea_lantern 0 
setblock ~98 ~0 ~21 quartz_block 0 
setblock ~98 ~0 ~39 quartz_stairs 4 
setblock ~98 ~0 ~57 quartz_stairs 4 
setblock ~98 ~0 ~75 quartz_block 0 
setblock ~98 ~0 ~76 sea_lantern 0  
fill ~98 ~0 ~77 ~98 ~1 ~77 quartz_block 0  
fill ~98 ~0 ~78 ~98 ~0 ~79 quartz_block 0 
setblock ~99 ~0 ~38 quartz_stairs 6 
setblock ~99 ~0 ~58 quartz_stairs 7 
setblock ~100 ~0 ~38 quartz_block 0 
setblock ~100 ~0 ~58 quartz_block 0 
setblock ~101 ~0 ~37 quartz_block 1 
setblock ~101 ~0 ~59 quartz_block 1  
fill ~102 ~0 ~17 ~102 ~2 ~17 quartz_block 0 
setblock ~102 ~0 ~18 sea_lantern 0  
fill ~102 ~0 ~19 ~104 ~0 ~19 quartz_block 0  
fill ~102 ~0 ~38 ~102 ~1 ~38 stained_glass 11  
fill ~102 ~0 ~39 ~103 ~0 ~39 stained_glass 11  
fill ~102 ~0 ~57 ~103 ~0 ~57 stained_glass 11  
fill ~102 ~0 ~58 ~102 ~1 ~58 stained_glass 11  
fill ~102 ~0 ~77 ~104 ~0 ~77 quartz_block 0 
setblock ~102 ~0 ~78 sea_lantern 0  
fill ~102 ~0 ~79 ~102 ~2 ~79 quartz_block 0 
setblock ~103 ~0 ~16 quartz_block 0 
setblock ~103 ~0 ~17 sea_lantern 0  
fill ~103 ~0 ~18 ~103 ~1 ~18 quartz_block 0 
setblock ~103 ~0 ~40 stained_glass 11 
setblock ~103 ~0 ~56 stained_glass 11  
fill ~103 ~0 ~78 ~103 ~1 ~78 quartz_block 0 
setblock ~103 ~0 ~79 sea_lantern 0 
setblock ~103 ~0 ~80 quartz_block 0 
setblock ~104 ~0 ~17 quartz_block 0 
setblock ~104 ~0 ~18 sea_lantern 0  
fill ~104 ~0 ~41 ~104 ~1 ~41 stained_glass 11  
fill ~104 ~0 ~42 ~104 ~0 ~43 stained_glass 11 
setblock ~104 ~0 ~45 quartz_stairs 2  
fill ~104 ~0 ~46 ~104 ~2 ~46 quartz_block 0  
fill ~104 ~0 ~50 ~104 ~2 ~50 quartz_block 0 
setblock ~104 ~0 ~51 quartz_stairs 3  
fill ~104 ~0 ~53 ~104 ~0 ~55 stained_glass 11 
setblock ~104 ~0 ~78 sea_lantern 0 
setblock ~104 ~0 ~79 quartz_block 0  
fill ~105 ~0 ~44 ~105 ~2 ~44 stained_glass 11  
fill ~105 ~0 ~45 ~105 ~2 ~45 stained_glass 11 
setblock ~105 ~0 ~46 sea_lantern 0 
setblock ~105 ~0 ~50 sea_lantern 0  
fill ~105 ~0 ~51 ~105 ~2 ~51 stained_glass 11  
fill ~105 ~0 ~52 ~105 ~2 ~52 stained_glass 11 
setblock ~106 ~0 ~46 quartz_stairs 1 
setblock ~106 ~0 ~50 quartz_stairs 1  
fill ~21 ~1 ~42 ~21 ~3 ~42 stained_glass 11  
fill ~21 ~1 ~43 ~21 ~3 ~43 stained_glass 11  
fill ~21 ~1 ~46 ~21 ~3 ~46 quartz_block 0  
fill ~21 ~1 ~50 ~21 ~3 ~50 quartz_block 0  
fill ~21 ~1 ~53 ~21 ~3 ~53 stained_glass 11  
fill ~21 ~1 ~54 ~21 ~3 ~54 stained_glass 11  
fill ~22 ~1 ~39 ~22 ~2 ~39 stained_glass 11  
fill ~22 ~1 ~40 ~22 ~2 ~40 stained_glass 11  
fill ~22 ~1 ~55 ~22 ~1 ~57 stained_glass 11  
fill ~23 ~1 ~15 ~24 ~1 ~15 quartz_block 0  
fill ~23 ~1 ~16 ~24 ~1 ~16 sea_lantern 0 
setblock ~23 ~1 ~17 quartz_block 0 
setblock ~23 ~1 ~38 stained_glass 11  
fill ~23 ~1 ~58 ~24 ~1 ~58 stained_glass 11 
setblock ~23 ~1 ~79 quartz_block 0  
fill ~23 ~1 ~80 ~24 ~1 ~80 sea_lantern 0  
fill ~23 ~1 ~81 ~24 ~1 ~81 quartz_block 0 
setblock ~24 ~1 ~37 stained_glass 11 
setblock ~24 ~1 ~59 stained_glass 11 
setblock ~25 ~1 ~36 quartz_block 1 
setblock ~25 ~1 ~60 quartz_block 1 
setblock ~26 ~1 ~37 quartz_block 0 
setblock ~26 ~1 ~59 quartz_block 0  
fill ~27 ~1 ~20 ~28 ~1 ~20 quartz_block 0  
fill ~27 ~1 ~21 ~28 ~1 ~21 sea_lantern 0  
fill ~27 ~1 ~22 ~28 ~1 ~22 quartz_block 0 
setblock ~27 ~1 ~37 quartz_stairs 6 
setblock ~27 ~1 ~59 quartz_stairs 7  
fill ~27 ~1 ~74 ~28 ~1 ~74 quartz_block 0   
fill ~27 ~1 ~75 ~28 ~1 ~75 sea_lantern 0  
fill ~27 ~1 ~76 ~28 ~1 ~76 quartz_block 0 
setblock ~28 ~1 ~19 quartz_block 0 
setblock ~28 ~1 ~38 quartz_stairs 5 
setblock ~28 ~1 ~58 quartz_stairs 5  
fill ~29 ~1 ~38 ~31 ~1 ~38 quartz_stairs 6  
fill ~29 ~1 ~58 ~31 ~1 ~58 quartz_stairs 7  
fill ~31 ~1 ~39 ~35 ~1 ~39 stained_hardened_clay 10  
fill ~31 ~1 ~57 ~35 ~1 ~57 stained_hardened_clay 10  
fill ~32 ~1 ~38 ~34 ~1 ~38 stone_slab 15  
fill ~32 ~1 ~58 ~34 ~1 ~58 stone_slab 15 
setblock ~35 ~1 ~38 quartz_stairs 6 
setblock ~35 ~1 ~58 quartz_stairs 7 
setblock ~36 ~1 ~39 sea_lantern 0 
setblock ~36 ~1 ~57 sea_lantern 0  
fill ~37 ~1 ~39 ~38 ~1 ~39 stained_glass 0  
fill ~37 ~1 ~57 ~38 ~1 ~57 stained_glass 0 
setblock ~39 ~1 ~39 sea_lantern 0 
setblock ~39 ~1 ~57 sea_lantern 0 
setblock ~40 ~1 ~38 quartz_stairs 6  
fill ~40 ~1 ~39 ~44 ~1 ~39 stained_hardened_clay 10  
fill ~40 ~1 ~57 ~44 ~1 ~57 stained_hardened_clay 10 
setblock ~40 ~1 ~58 quartz_stairs 7  
fill ~41 ~1 ~38 ~43 ~1 ~38 stone_slab 15  
fill ~41 ~1 ~58 ~43 ~1 ~58 stone_slab 15  
fill ~44 ~1 ~38 ~46 ~1 ~38 quartz_stairs 6  
fill ~44 ~1 ~58 ~46 ~1 ~58 quartz_stairs 7 
setblock ~47 ~1 ~38 quartz_stairs 4 
setblock ~47 ~1 ~58 quartz_stairs 4  
fill ~48 ~1 ~15 ~49 ~1 ~15 quartz_block 0  
fill ~48 ~1 ~16 ~49 ~1 ~16 sea_lantern 0 
setblock ~48 ~1 ~17 quartz_block 0 
setblock ~48 ~1 ~37 quartz_stairs 6 
setblock ~48 ~1 ~59 quartz_stairs 7 
setblock ~48 ~1 ~79 quartz_block 0  
fill ~48 ~1 ~80 ~49 ~1 ~80 sea_lantern 0  
fill ~48 ~1 ~81 ~49 ~1 ~81 quartz_block 0 
setblock ~49 ~1 ~37 quartz_block 0 
setblock ~49 ~1 ~59 quartz_block 0 
setblock ~50 ~1 ~29 quartz_block 2 
setblock ~50 ~1 ~36 quartz_block 1 
setblock ~50 ~1 ~60 quartz_block 1 
setblock ~50 ~1 ~67 quartz_block 2  
fill ~51 ~1 ~30 ~53 ~1 ~30 stonebrick 0  
fill ~51 ~1 ~61 ~51 ~1 ~66 stonebrick 0  
fill ~52 ~1 ~20 ~53 ~1 ~20 quartz_block 0  
fill ~52 ~1 ~21 ~53 ~1 ~21 sea_lantern 0  
fill ~52 ~1 ~22 ~53 ~1 ~22 quartz_block 0  
fill ~52 ~1 ~31 ~52 ~3 ~31 sea_lantern 0  
fill ~52 ~1 ~32 ~53 ~1 ~32 quartz_stairs 7  
fill ~52 ~1 ~64 ~53 ~1 ~64 quartz_stairs 6  
fill ~52 ~1 ~65 ~52 ~3 ~65 sea_lantern 0  
fill ~52 ~1 ~66 ~53 ~1 ~66 stonebrick 0  
fill ~52 ~1 ~74 ~53 ~1 ~74 quartz_block 0  
fill ~52 ~1 ~75 ~53 ~1 ~75 sea_lantern 0  
fill ~52 ~1 ~76 ~53 ~1 ~76 quartz_block 0 
setblock ~53 ~1 ~19 quartz_block 0 
setblock ~53 ~1 ~31 quartz_stairs 5 
setblock ~53 ~1 ~65 quartz_stairs 5  
fill ~55 ~1 ~30 ~56 ~1 ~30 stained_hardened_clay 10  
fill ~55 ~1 ~31 ~55 ~1 ~30 stained_hardened_clay 10  
fill ~55 ~1 ~65 ~55 ~1 ~66 stained_hardened_clay 10  
fill ~56 ~1 ~66 ~56 ~3 ~66 stained_hardened_clay 10  
fill ~57 ~1 ~31 ~57 ~0 ~31 cobblestone_wall 0  
fill ~57 ~1 ~65 ~57 ~0 ~65 cobblestone_wall 0 
setblock ~58 ~1 ~31 quartz_block 0 
setblock ~58 ~1 ~65 quartz_block 0 
setblock ~68 ~1 ~31 quartz_block 0 
setblock ~68 ~1 ~65 quartz_block 0 
setblock ~69 ~1 ~31 cobblestone_wall 0 
setblock ~69 ~1 ~65 cobblestone_wall 0  
fill ~70 ~1 ~30 ~71 ~1 ~30 stained_hardened_clay 10  
fill ~70 ~1 ~66 ~71 ~1 ~66 stained_hardened_clay 10 
setblock ~71 ~1 ~31 stained_hardened_clay 10 
setblock ~71 ~1 ~65 stained_hardened_clay 10  
fill ~73 ~1 ~19 ~73 ~1 ~20 quartz_block 0  
fill ~73 ~1 ~21 ~74 ~1 ~21 sea_lantern 0  
fill ~73 ~1 ~22 ~74 ~1 ~22 quartz_block 0  
fill ~73 ~1 ~30 ~75 ~1 ~30 stonebrick 0 
setblock ~73 ~1 ~31 quartz_stairs 4  
fill ~73 ~1 ~32 ~74 ~1 ~32 quartz_stairs 7  
fill ~73 ~1 ~64 ~74 ~1 ~64 quartz_stairs 6 
setblock ~73 ~1 ~65 quartz_stairs 4  
fill ~73 ~1 ~66 ~75 ~1 ~66 stonebrick 0  
fill ~73 ~1 ~74 ~74 ~1 ~74 quartz_block 0  
fill ~73 ~1 ~75 ~74 ~1 ~75 sea_lantern 0  
fill ~73 ~1 ~76 ~74 ~1 ~76 quartz_block 0  
fill ~74 ~1 ~20 ~74 ~2 ~20 quartz_block 0  
fill ~74 ~1 ~31 ~74 ~3 ~31 sea_lantern 0  
fill ~74 ~1 ~65 ~74 ~3 ~65 sea_lantern 0  
fill ~75 ~1 ~61 ~75 ~1 ~66 stonebrick 0 
setblock ~76 ~1 ~29 quartz_block 2 
setblock ~76 ~1 ~36 quartz_block 1 
setblock ~76 ~1 ~60 quartz_block 1 
setblock ~76 ~1 ~67 quartz_block 2  
fill ~77 ~1 ~15 ~78 ~1 ~15 quartz_block 0  
fill ~77 ~1 ~16 ~78 ~1 ~16 sea_lantern 0 
setblock ~77 ~1 ~37 quartz_block 0 
setblock ~77 ~1 ~59 quartz_block 0  
fill ~77 ~1 ~80 ~78 ~1 ~80 sea_lantern 0  
fill ~77 ~1 ~81 ~78 ~1 ~81 quartz_block 0 
setblock ~78 ~1 ~17 quartz_block 0 
setblock ~78 ~1 ~37 quartz_stairs 6 
setblock ~78 ~1 ~59 quartz_stairs 7 
setblock ~78 ~1 ~79 quartz_block 0 
setblock ~79 ~1 ~38 quartz_stairs 5 
setblock ~79 ~1 ~58 quartz_stairs 5  
fill ~80 ~1 ~38 ~82 ~1 ~38 quartz_stairs 6  
fill ~80 ~1 ~58 ~82 ~1 ~58 quartz_stairs 7  
fill ~82 ~1 ~39 ~86 ~1 ~39 stained_hardened_clay 10  
fill ~82 ~1 ~57 ~86 ~1 ~57 stained_hardened_clay 10  
fill ~83 ~1 ~38 ~85 ~1 ~38 stone_slab 15  
fill ~83 ~1 ~58 ~85 ~1 ~58 stone_slab 15 
setblock ~86 ~1 ~38 quartz_stairs 6 
setblock ~86 ~1 ~58 quartz_stairs 7 
setblock ~87 ~1 ~39 sea_lantern 0 
setblock ~87 ~1 ~57 sea_lantern 0  
fill ~88 ~1 ~39 ~89 ~1 ~39 stained_glass 0  
fill ~88 ~1 ~57 ~89 ~1 ~57 stained_glass 0 
setblock ~90 ~1 ~39 sea_lantern 0 
setblock ~90 ~1 ~57 sea_lantern 0 
setblock ~91 ~1 ~38 quartz_stairs 6  
fill ~91 ~1 ~39 ~95 ~1 ~39 stained_hardened_clay 10  
fill ~91 ~1 ~57 ~95 ~1 ~57 stained_hardened_clay 10 
setblock ~91 ~1 ~58 quartz_stairs 7  
fill ~92 ~1 ~38 ~94 ~1 ~38 stone_slab 15  
fill ~92 ~1 ~58 ~94 ~1 ~58 stone_slab 15  
fill ~95 ~1 ~38 ~97 ~1 ~38 quartz_stairs 6  
fill ~95 ~1 ~58 ~97 ~1 ~58 quartz_stairs 7  
fill ~98 ~1 ~19 ~98 ~1 ~20 quartz_block 0  
fill ~98 ~1 ~21 ~99 ~1 ~21 sea_lantern 0  
fill ~98 ~1 ~22 ~99 ~1 ~22 quartz_block 0 
setblock ~98 ~1 ~38 quartz_stairs 4 
setblock ~98 ~1 ~58 quartz_stairs 4  
fill ~98 ~1 ~74 ~99 ~1 ~74 quartz_block 0  
fill ~98 ~1 ~75 ~99 ~1 ~75 sea_lantern 0  
fill ~98 ~1 ~76 ~99 ~1 ~76 quartz_block 0  
fill ~99 ~1 ~20 ~99 ~2 ~20 quartz_block 0 
setblock ~99 ~1 ~37 quartz_stairs 6 
setblock ~99 ~1 ~59 quartz_stairs 7 
setblock ~100 ~1 ~37 quartz_block 0 
setblock ~100 ~1 ~59 quartz_block 0 
setblock ~101 ~1 ~36 quartz_block 1 
setblock ~101 ~1 ~60 quartz_block 1  
fill ~102 ~1 ~15 ~103 ~1 ~15 quartz_block 0  
fill ~102 ~1 ~16 ~103 ~1 ~16 sea_lantern 0 
setblock ~102 ~1 ~37 stained_glass 11 
setblock ~102 ~1 ~59 stained_glass 11  
fill ~102 ~1 ~80 ~103 ~1 ~80 sea_lantern 0  
fill ~102 ~1 ~81 ~103 ~1 ~81 quartz_block 0 
setblock ~103 ~1 ~17 quartz_block 0 
setblock ~103 ~1 ~38 stained_glass 11 
setblock ~103 ~1 ~58 stained_glass 11 
setblock ~103 ~1 ~79 quartz_block 0  
fill ~104 ~1 ~39 ~104 ~2 ~39 stained_glass 11  
fill ~104 ~1 ~40 ~104 ~2 ~40 stained_glass 11  
fill ~104 ~1 ~55 ~104 ~1 ~57 stained_glass 11  
fill ~105 ~1 ~42 ~105 ~3 ~42 stained_glass 11  
fill ~105 ~1 ~43 ~105 ~3 ~43 stained_glass 11  
fill ~105 ~1 ~46 ~105 ~3 ~46 quartz_block 0  
fill ~105 ~1 ~50 ~105 ~3 ~50 quartz_block 0  
fill ~105 ~1 ~53 ~105 ~3 ~53 stained_glass 11  
fill ~105 ~1 ~54 ~105 ~3 ~54 stained_glass 11 
setblock ~20 ~2 ~46 quartz_stairs 4 
setblock ~20 ~2 ~50 quartz_stairs 4  
fill ~21 ~2 ~41 ~21 ~4 ~41 stained_glass 11  
fill ~21 ~2 ~55 ~21 ~4 ~55 stained_glass 11  
fill ~22 ~2 ~38 ~22 ~3 ~38 stained_glass 11  
fill ~22 ~2 ~56 ~22 ~2 ~58 stained_glass 11 
setblock ~23 ~2 ~37 stained_glass 11 
setblock ~23 ~2 ~59 stained_glass 11  
fill ~24 ~2 ~15 ~25 ~2 ~15 quartz_block 0  
fill ~24 ~2 ~16 ~25 ~2 ~16 sea_lantern 0  
fill ~24 ~2 ~36 ~24 ~3 ~36 stained_glass 11  
fill ~24 ~2 ~60 ~24 ~3 ~60 stained_glass 11  
fill ~24 ~2 ~80 ~25 ~2 ~80 sea_lantern 0  
fill ~24 ~2 ~81 ~25 ~2 ~81 quartz_block 0  
fill ~25 ~2 ~17 ~25 ~3 ~17 quartz_block 0 
setblock ~25 ~2 ~35 quartz_block 1 
setblock ~25 ~2 ~61 quartz_block 1  
fill ~25 ~2 ~79 ~25 ~3 ~79 quartz_block 0  
fill ~26 ~2 ~20 ~27 ~2 ~20 quartz_block 0  
fill ~26 ~2 ~21 ~27 ~2 ~21 sea_lantern 0  
fill ~26 ~2 ~22 ~27 ~2 ~22 quartz_block 0 
setblock ~26 ~2 ~36 quartz_block 0 
setblock ~26 ~2 ~60 quartz_block 0  
fill ~26 ~2 ~74 ~27 ~2 ~74 quartz_block 0  
fill ~26 ~2 ~75 ~27 ~2 ~75 sea_lantern 0  
fill ~26 ~2 ~76 ~27 ~2 ~76 quartz_block 0 
setblock ~27 ~2 ~36 quartz_stairs 6 
setblock ~27 ~2 ~60 quartz_stairs 7 
setblock ~28 ~2 ~37 quartz_stairs 5 
setblock ~28 ~2 ~59 quartz_stairs 5  
fill ~29 ~2 ~37 ~31 ~2 ~37 quartz_stairs 6  
fill ~29 ~2 ~59 ~31 ~2 ~59 quartz_stairs 7  
fill ~31 ~2 ~38 ~35 ~2 ~38 stained_hardened_clay 10  
fill ~31 ~2 ~58 ~35 ~2 ~58 stained_hardened_clay 10  
fill ~32 ~2 ~37 ~34 ~2 ~37 stone_slab 15  
fill ~32 ~2 ~59 ~34 ~2 ~59 stone_slab 15 
setblock ~35 ~2 ~37 quartz_stairs 6 
setblock ~35 ~2 ~59 quartz_stairs 7  
fill ~36 ~2 ~38 ~39 ~2 ~38 stained_glass 0  
fill ~36 ~2 ~58 ~39 ~2 ~58 stained_glass 0 
setblock ~40 ~2 ~37 quartz_stairs 6  
fill ~40 ~2 ~38 ~44 ~2 ~38 stained_hardened_clay 10  
fill ~40 ~2 ~58 ~44 ~2 ~58 stained_hardened_clay 10 
setblock ~40 ~2 ~59 quartz_stairs 7  
fill ~41 ~2 ~37 ~43 ~2 ~37 stone_slab 15  
fill ~41 ~2 ~59 ~43 ~2 ~59 stone_slab 15  
fill ~44 ~2 ~37 ~46 ~2 ~37 quartz_stairs 6  
fill ~44 ~2 ~59 ~46 ~2 ~59 quartz_stairs 7 
setblock ~47 ~2 ~37 quartz_stairs 4 
setblock ~47 ~2 ~59 quartz_stairs 4 
setblock ~48 ~2 ~36 quartz_stairs 6 
setblock ~48 ~2 ~60 quartz_stairs 7  
fill ~49 ~2 ~15 ~50 ~2 ~15 quartz_block 0  
fill ~49 ~2 ~16 ~50 ~2 ~16 sea_lantern 0 
setblock ~49 ~2 ~36 quartz_block 0 
setblock ~49 ~2 ~60 quartz_block 0  
fill ~49 ~2 ~80 ~50 ~2 ~80 sea_lantern 0  
fill ~49 ~2 ~81 ~50 ~2 ~81 quartz_block 0  
fill ~50 ~2 ~17 ~50 ~3 ~17 quartz_block 0 
setblock ~50 ~2 ~29 cobblestone_wall 0 
setblock ~50 ~2 ~35 quartz_block 1 
setblock ~50 ~2 ~61 quartz_block 1 
setblock ~50 ~2 ~67 cobblestone_wall 0  
fill ~50 ~2 ~79 ~50 ~3 ~79 quartz_block 0  
fill ~51 ~2 ~20 ~52 ~2 ~20 quartz_block 0  
fill ~51 ~2 ~21 ~52 ~2 ~21 sea_lantern 0  
fill ~51 ~2 ~22 ~52 ~2 ~22 quartz_block 0  
fill ~51 ~2 ~30 ~54 ~2 ~30 stonebrick 0  
fill ~51 ~2 ~62 ~51 ~2 ~66 stonebrick 0  
fill ~51 ~2 ~74 ~52 ~2 ~74 quartz_block 0  
fill ~51 ~2 ~75 ~52 ~2 ~75 sea_lantern 0  
fill ~51 ~2 ~76 ~52 ~2 ~76 quartz_block 0  
fill ~52 ~2 ~32 ~53 ~2 ~32 cobblestone_wall 0  
fill ~52 ~2 ~64 ~53 ~2 ~64 cobblestone_wall 0  
fill ~52 ~2 ~66 ~54 ~2 ~66 stonebrick 0 
setblock ~53 ~2 ~31 cobblestone_wall 0 
setblock ~53 ~2 ~65 cobblestone_wall 0  
fill ~54 ~2 ~29 ~54 ~4 ~29 stone_slab 7  
fill ~54 ~2 ~67 ~54 ~4 ~67 stone_slab 7  
fill ~55 ~2 ~29 ~55 ~3 ~29 quartz_block 0  
fill ~55 ~2 ~30 ~55 ~3 ~30 sea_lantern 0  
fill ~55 ~2 ~66 ~55 ~3 ~66 sea_lantern 0  
fill ~55 ~2 ~67 ~55 ~3 ~67 quartz_block 0  
fill ~56 ~2 ~30 ~57 ~2 ~30 stained_hardened_clay 10  
fill ~57 ~2 ~31 ~57 ~4 ~31 stained_hardened_clay 10  
fill ~57 ~2 ~65 ~57 ~4 ~65 stained_hardened_clay 10  
fill ~57 ~2 ~66 ~57 ~4 ~66 stained_hardened_clay 10  
fill ~58 ~2 ~29 ~58 ~3 ~29 quartz_block 0  
fill ~58 ~2 ~30 ~58 ~3 ~30 stonebrick 0  
fill ~58 ~2 ~31 ~58 ~3 ~31 cobblestone_wall 0  
fill ~58 ~2 ~65 ~58 ~3 ~65 cobblestone_wall 0  
fill ~58 ~2 ~66 ~58 ~3 ~66 stonebrick 0  
fill ~58 ~2 ~67 ~58 ~3 ~67 quartz_block 0  
fill ~59 ~2 ~30 ~59 ~3 ~30 quartz_block 0  
fill ~59 ~2 ~31 ~59 ~3 ~31 quartz_block 0  
fill ~59 ~2 ~65 ~59 ~3 ~65 quartz_block 0  
fill ~59 ~2 ~66 ~59 ~3 ~66 quartz_block 0  
fill ~67 ~2 ~30 ~67 ~3 ~30 quartz_block 0  
fill ~67 ~2 ~31 ~67 ~3 ~31 quartz_block 0  
fill ~67 ~2 ~65 ~67 ~3 ~65 quartz_block 0  
fill ~67 ~2 ~66 ~67 ~3 ~66 quartz_block 0  
fill ~68 ~2 ~29 ~68 ~3 ~29 quartz_block 0  
fill ~68 ~2 ~30 ~68 ~3 ~30 stonebrick 0  
fill ~68 ~2 ~31 ~68 ~3 ~31 cobblestone_wall 0  
fill ~68 ~2 ~65 ~68 ~3 ~65 cobblestone_wall 0  
fill ~68 ~2 ~66 ~68 ~3 ~66 stonebrick 0  
fill ~68 ~2 ~67 ~68 ~3 ~67 quartz_block 0  
fill ~69 ~2 ~30 ~70 ~2 ~30 stained_hardened_clay 10  
fill ~69 ~2 ~31 ~69 ~4 ~31 stained_hardened_clay 10  
fill ~69 ~2 ~65 ~69 ~4 ~65 stained_hardened_clay 10  
fill ~69 ~2 ~66 ~70 ~2 ~66 stained_hardened_clay 10  
fill ~71 ~2 ~29 ~71 ~3 ~29 quartz_block 0  
fill ~71 ~2 ~30 ~71 ~3 ~30 sea_lantern 0  
fill ~71 ~2 ~66 ~71 ~3 ~66 sea_lantern 0  
fill ~71 ~2 ~67 ~71 ~3 ~67 quartz_block 0  
fill ~72 ~2 ~29 ~72 ~4 ~29 stone_slab 7  
fill ~72 ~2 ~30 ~75 ~2 ~30 stonebrick 0  
fill ~72 ~2 ~66 ~75 ~2 ~66 stonebrick 0  
fill ~72 ~2 ~67 ~72 ~4 ~67 stone_slab 7  
fill ~73 ~2 ~31 ~73 ~2 ~32 cobblestone_wall 0  
fill ~73 ~2 ~64 ~74 ~2 ~64 cobblestone_wall 0  
fill ~73 ~2 ~65 ~73 ~2 ~64 cobblestone_wall 0  
fill ~74 ~2 ~21 ~75 ~2 ~21 sea_lantern 0  
fill ~74 ~2 ~22 ~75 ~2 ~22 quartz_block 0 
setblock ~74 ~2 ~32 cobblestone_wall 0  
fill ~74 ~2 ~74 ~75 ~2 ~74 quartz_block 0  
fill ~74 ~2 ~75 ~75 ~2 ~75 sea_lantern 0  
fill ~74 ~2 ~76 ~75 ~2 ~76 quartz_block 0  
fill ~75 ~2 ~20 ~75 ~3 ~20 quartz_block 0  
fill ~75 ~2 ~62 ~75 ~2 ~66 stonebrick 0  
fill ~76 ~2 ~15 ~77 ~2 ~15 quartz_block 0  
fill ~76 ~2 ~16 ~77 ~2 ~16 sea_lantern 0  
fill ~76 ~2 ~17 ~76 ~3 ~17 quartz_block 0 
setblock ~76 ~2 ~29 cobblestone_wall 0 
setblock ~76 ~2 ~35 quartz_block 1 
setblock ~76 ~2 ~61 quartz_block 1 
setblock ~76 ~2 ~67 cobblestone_wall 0  
fill ~76 ~2 ~79 ~76 ~3 ~79 quartz_block 0  
fill ~76 ~2 ~80 ~77 ~2 ~80 sea_lantern 0  
fill ~76 ~2 ~81 ~77 ~2 ~81 quartz_block 0 
setblock ~77 ~2 ~36 quartz_block 0 
setblock ~77 ~2 ~60 quartz_block 0 
setblock ~78 ~2 ~36 quartz_stairs 6 
setblock ~78 ~2 ~60 quartz_stairs 7 
setblock ~79 ~2 ~37 quartz_stairs 5 
setblock ~79 ~2 ~59 quartz_stairs 5  
fill ~80 ~2 ~37 ~82 ~2 ~37 quartz_stairs 6  
fill ~80 ~2 ~59 ~82 ~2 ~59 quartz_stairs 7  
fill ~82 ~2 ~38 ~86 ~2 ~38 stained_hardened_clay 10  
fill ~82 ~2 ~58 ~86 ~2 ~58 stained_hardened_clay 10  
fill ~83 ~2 ~37 ~85 ~2 ~37 stone_slab 15  
fill ~83 ~2 ~59 ~85 ~2 ~59 stone_slab 15 
setblock ~86 ~2 ~37 quartz_stairs 6 
setblock ~86 ~2 ~59 quartz_stairs 7  
fill ~87 ~2 ~38 ~90 ~2 ~38 stained_glass 0  
fill ~87 ~2 ~58 ~90 ~2 ~58 stained_glass 0 
setblock ~91 ~2 ~37 quartz_stairs 6  
fill ~91 ~2 ~38 ~95 ~2 ~38 stained_hardened_clay 10  
fill ~91 ~2 ~58 ~95 ~2 ~58 stained_hardened_clay 10 
setblock ~91 ~2 ~59 quartz_stairs 7  
fill ~92 ~2 ~37 ~94 ~2 ~37 stone_slab 15  
fill ~92 ~2 ~59 ~94 ~2 ~59 stone_slab 15  
fill ~95 ~2 ~37 ~97 ~2 ~37 quartz_stairs 6  
fill ~95 ~2 ~59 ~97 ~2 ~59 quartz_stairs 7 
setblock ~98 ~2 ~37 quartz_stairs 4 
setblock ~98 ~2 ~59 quartz_stairs 4  
fill ~99 ~2 ~21 ~100 ~2 ~21 sea_lantern 0  
fill ~99 ~2 ~22 ~100 ~2 ~22 quartz_block 0 
setblock ~99 ~2 ~36 quartz_stairs 6 
setblock ~99 ~2 ~60 quartz_stairs 7  
fill ~99 ~2 ~74 ~100 ~2 ~74 quartz_block 0  
fill ~99 ~2 ~75 ~100 ~2 ~75 sea_lantern 0  
fill ~99 ~2 ~76 ~100 ~2 ~76 quartz_block 0  
fill ~100 ~2 ~20 ~100 ~3 ~20 quartz_block 0 
setblock ~100 ~2 ~36 quartz_block 0 
setblock ~100 ~2 ~60 quartz_block 0  
fill ~101 ~2 ~15 ~102 ~2 ~15 quartz_block 0  
fill ~101 ~2 ~16 ~102 ~2 ~16 sea_lantern 0  
fill ~101 ~2 ~17 ~101 ~3 ~17 quartz_block 0 
setblock ~101 ~2 ~35 quartz_block 1 
setblock ~101 ~2 ~61 quartz_block 1  
fill ~101 ~2 ~79 ~101 ~3 ~79 quartz_block 0  
fill ~101 ~2 ~80 ~102 ~2 ~80 sea_lantern 0  
fill ~101 ~2 ~81 ~102 ~2 ~81 quartz_block 0  
fill ~102 ~2 ~36 ~102 ~3 ~36 stained_glass 11  
fill ~102 ~2 ~60 ~102 ~3 ~60 stained_glass 11 
setblock ~103 ~2 ~37 stained_glass 11 
setblock ~103 ~2 ~59 stained_glass 11  
fill ~104 ~2 ~38 ~104 ~3 ~38 stained_glass 11  
fill ~104 ~2 ~56 ~104 ~2 ~58 stained_glass 11  
fill ~105 ~2 ~41 ~105 ~4 ~41 stained_glass 11  
fill ~105 ~2 ~55 ~105 ~4 ~55 stained_glass 11 
setblock ~106 ~2 ~46 quartz_stairs 5 
setblock ~106 ~2 ~50 quartz_stairs 5  
fill ~20 ~3 ~44 ~20 ~8 ~44 stained_glass 11  
fill ~20 ~3 ~45 ~20 ~7 ~45 stained_glass 11  
fill ~20 ~3 ~46 ~20 ~4 ~46 quartz_block 0 
setblock ~20 ~3 ~47 quartz_stairs 7 
setblock ~20 ~3 ~48 quartz_stairs 4 
setblock ~20 ~3 ~49 quartz_stairs 6  
fill ~20 ~3 ~50 ~20 ~4 ~50 quartz_block 0  
fill ~20 ~3 ~51 ~20 ~7 ~51 stained_glass 11  
fill ~20 ~3 ~52 ~20 ~8 ~52 stained_glass 11  
fill ~21 ~3 ~39 ~21 ~6 ~39 stained_glass 11  
fill ~21 ~3 ~40 ~21 ~5 ~40 stained_glass 11  
fill ~21 ~3 ~47 ~21 ~3 ~50 quartz_block 0  
fill ~21 ~3 ~56 ~21 ~5 ~56 stained_glass 11  
fill ~21 ~3 ~57 ~21 ~6 ~57 stained_glass 11  
fill ~22 ~3 ~37 ~22 ~5 ~37 stained_glass 11 
setblock ~22 ~3 ~46 quartz_stairs 1 
setblock ~22 ~3 ~50 quartz_stairs 1  
fill ~22 ~3 ~58 ~22 ~3 ~59 stained_glass 11 
setblock ~23 ~3 ~36 stained_glass 11 
setblock ~23 ~3 ~60 stained_glass 11  
fill ~24 ~3 ~20 ~26 ~3 ~20 quartz_block 0  
fill ~24 ~3 ~21 ~26 ~3 ~21 sea_lantern 0  
fill ~24 ~3 ~22 ~26 ~3 ~22 quartz_block 0  
fill ~24 ~3 ~35 ~24 ~4 ~35 stained_glass 11  
fill ~24 ~3 ~61 ~24 ~4 ~61 stained_glass 11  
fill ~24 ~3 ~74 ~26 ~3 ~74 quartz_block 0  
fill ~24 ~3 ~75 ~26 ~3 ~75 sea_lantern 0  
fill ~24 ~3 ~76 ~26 ~3 ~76 quartz_block 0 
setblock ~25 ~3 ~14 quartz_block 0 
setblock ~25 ~3 ~15 sea_lantern 0 
setblock ~25 ~3 ~16 quartz_block 0  
fill ~25 ~3 ~34 ~25 ~4 ~34 quartz_block 1  
fill ~25 ~3 ~62 ~25 ~4 ~62 quartz_block 1 
setblock ~25 ~3 ~80 quartz_block 0 
setblock ~25 ~3 ~81 sea_lantern 0 
setblock ~25 ~3 ~82 quartz_block 0  
fill ~26 ~3 ~15 ~27 ~3 ~15 quartz_block 0  
fill ~26 ~3 ~16 ~27 ~3 ~16 sea_lantern 0  
fill ~26 ~3 ~17 ~27 ~3 ~17 quartz_block 0  
fill ~26 ~3 ~35 ~26 ~4 ~35 quartz_block 0  
fill ~26 ~3 ~61 ~26 ~4 ~61 quartz_block 0  
fill ~26 ~3 ~79 ~27 ~3 ~79 quartz_block 0  
fill ~26 ~3 ~80 ~27 ~3 ~80 sea_lantern 0  
fill ~26 ~3 ~81 ~27 ~3 ~81 quartz_block 0 
setblock ~27 ~3 ~35 quartz_stairs 6 
setblock ~27 ~3 ~61 quartz_stairs 7 
setblock ~28 ~3 ~36 quartz_stairs 5 
setblock ~28 ~3 ~60 quartz_stairs 5  
fill ~29 ~3 ~36 ~31 ~3 ~36 quartz_stairs 6 
setblock ~29 ~3 ~37 quartz_block 1 
setblock ~29 ~3 ~59 quartz_block 1  
fill ~29 ~3 ~60 ~31 ~3 ~60 quartz_stairs 7  
fill ~31 ~3 ~37 ~35 ~3 ~37 stained_hardened_clay 10  
fill ~31 ~3 ~59 ~35 ~3 ~59 stained_hardened_clay 10  
fill ~32 ~3 ~36 ~34 ~3 ~36 stone_slab 15  
fill ~32 ~3 ~60 ~34 ~3 ~60 stone_slab 15 
setblock ~35 ~3 ~36 quartz_stairs 6 
setblock ~35 ~3 ~60 quartz_stairs 7 
setblock ~36 ~3 ~37 sea_lantern 0 
setblock ~36 ~3 ~59 sea_lantern 0  
fill ~37 ~3 ~37 ~38 ~3 ~37 stained_glass 0  
fill ~37 ~3 ~59 ~38 ~3 ~59 stained_glass 0 
setblock ~39 ~3 ~37 sea_lantern 0 
setblock ~39 ~3 ~59 sea_lantern 0 
setblock ~40 ~3 ~36 quartz_stairs 6  
fill ~40 ~3 ~37 ~44 ~3 ~37 stained_hardened_clay 10  
fill ~40 ~3 ~59 ~44 ~3 ~59 stained_hardened_clay 10 
setblock ~40 ~3 ~60 quartz_stairs 7  
fill ~41 ~3 ~36 ~43 ~3 ~36 stone_slab 15  
fill ~41 ~3 ~60 ~43 ~3 ~60 stone_slab 15  
fill ~44 ~3 ~36 ~46 ~3 ~36 quartz_stairs 6  
fill ~44 ~3 ~60 ~46 ~3 ~60 quartz_stairs 7 
setblock ~46 ~3 ~37 quartz_block 1 
setblock ~46 ~3 ~59 quartz_block 1 
setblock ~47 ~3 ~36 quartz_stairs 4 
setblock ~47 ~3 ~60 quartz_stairs 4 
setblock ~48 ~3 ~35 quartz_stairs 6 
setblock ~48 ~3 ~61 quartz_stairs 7  
fill ~49 ~3 ~20 ~51 ~3 ~20 quartz_block 0  
fill ~49 ~3 ~21 ~51 ~3 ~21 sea_lantern 0  
fill ~49 ~3 ~22 ~51 ~3 ~22 quartz_block 0  
fill ~49 ~3 ~35 ~49 ~4 ~35 quartz_block 0  
fill ~49 ~3 ~61 ~49 ~4 ~61 quartz_block 0  
fill ~49 ~3 ~74 ~51 ~3 ~74 quartz_block 0  
fill ~49 ~3 ~75 ~51 ~3 ~75 sea_lantern 0  
fill ~49 ~3 ~76 ~51 ~3 ~76 quartz_block 0 
setblock ~50 ~3 ~14 quartz_block 0 
setblock ~50 ~3 ~15 sea_lantern 0 
setblock ~50 ~3 ~16 quartz_block 0 
setblock ~50 ~3 ~29 quartz_block 2  
fill ~50 ~3 ~34 ~50 ~4 ~34 quartz_block 1  
fill ~50 ~3 ~62 ~50 ~4 ~62 quartz_block 1 
setblock ~50 ~3 ~67 quartz_block 2 
setblock ~50 ~3 ~80 quartz_block 0 
setblock ~50 ~3 ~81 sea_lantern 0 
setblock ~50 ~3 ~82 quartz_block 0  
fill ~51 ~3 ~15 ~52 ~3 ~15 quartz_block 0  
fill ~51 ~3 ~16 ~52 ~3 ~16 sea_lantern 0  
fill ~51 ~3 ~17 ~52 ~3 ~17 quartz_block 0  
fill ~51 ~3 ~30 ~54 ~3 ~30 stonebrick 0  
fill ~51 ~3 ~63 ~51 ~4 ~63 stonebrick 0  
fill ~51 ~3 ~64 ~51 ~6 ~64 stonebrick 0  
fill ~51 ~3 ~65 ~51 ~9 ~65 stonebrick 0  
fill ~51 ~3 ~66 ~54 ~3 ~66 stonebrick 0  
fill ~51 ~3 ~79 ~52 ~3 ~79 quartz_block 0  
fill ~51 ~3 ~80 ~52 ~3 ~80 sea_lantern 0  
fill ~51 ~3 ~81 ~52 ~3 ~81 quartz_block 0 
setblock ~52 ~3 ~32 quartz_stairs 3 
setblock ~52 ~3 ~64 quartz_stairs 2  
fill ~53 ~3 ~31 ~53 ~3 ~32 quartz_stairs 1  
fill ~53 ~3 ~64 ~53 ~3 ~65 quartz_stairs 1  
fill ~56 ~3 ~30 ~57 ~3 ~30 stained_hardened_clay 10  
fill ~60 ~3 ~30 ~60 ~3 ~31 quartz_block 0  
fill ~60 ~3 ~65 ~60 ~3 ~66 quartz_block 0  
fill ~66 ~3 ~30 ~66 ~3 ~31 quartz_block 0  
fill ~66 ~3 ~65 ~66 ~3 ~66 quartz_block 0  
fill ~69 ~3 ~30 ~70 ~3 ~30 stained_hardened_clay 10  
fill ~69 ~3 ~66 ~70 ~3 ~66 stained_hardened_clay 10  
fill ~72 ~3 ~30 ~75 ~3 ~30 stonebrick 0  
fill ~72 ~3 ~66 ~75 ~3 ~66 stonebrick 0 
setblock ~73 ~3 ~31 quartz_stairs 0  
fill ~73 ~3 ~32 ~74 ~3 ~32 quartz_stairs 3  
fill ~73 ~3 ~64 ~74 ~3 ~64 quartz_stairs 2 
setblock ~73 ~3 ~65 quartz_stairs 0  
fill ~74 ~3 ~15 ~75 ~3 ~15 quartz_block 0  
fill ~74 ~3 ~16 ~75 ~3 ~16 sea_lantern 0  
fill ~74 ~3 ~17 ~76 ~3 ~17 quartz_block 0  
fill ~74 ~3 ~79 ~76 ~3 ~79 quartz_block 0  
fill ~74 ~3 ~80 ~75 ~3 ~80 sea_lantern 0  
fill ~74 ~3 ~81 ~75 ~3 ~81 quartz_block 0  
fill ~75 ~3 ~21 ~77 ~3 ~21 sea_lantern 0  
fill ~75 ~3 ~22 ~77 ~3 ~22 quartz_block 0  
fill ~75 ~3 ~63 ~75 ~4 ~63 stonebrick 0  
fill ~75 ~3 ~64 ~75 ~6 ~64 stonebrick 0  
fill ~75 ~3 ~65 ~75 ~9 ~65 stonebrick 0  
fill ~75 ~3 ~74 ~77 ~3 ~74 quartz_block 0  
fill ~75 ~3 ~75 ~77 ~3 ~75 sea_lantern 0  
fill ~75 ~3 ~76 ~77 ~3 ~76 quartz_block 0 
setblock ~76 ~3 ~14 quartz_block 0 
setblock ~76 ~3 ~15 sea_lantern 0 
setblock ~76 ~3 ~16 quartz_block 0  
fill ~76 ~3 ~20 ~77 ~3 ~20 quartz_block 0 
setblock ~76 ~3 ~29 quartz_block 2  
fill ~76 ~3 ~34 ~76 ~4 ~34 quartz_block 1  
fill ~76 ~3 ~62 ~76 ~4 ~62 quartz_block 1 
setblock ~76 ~3 ~67 quartz_block 2 
setblock ~76 ~3 ~80 quartz_block 0 
setblock ~76 ~3 ~81 sea_lantern 0 
setblock ~76 ~3 ~82 quartz_block 0  
fill ~77 ~3 ~35 ~77 ~4 ~35 quartz_block 0  
fill ~77 ~3 ~61 ~77 ~4 ~61 quartz_block 0 
setblock ~78 ~3 ~35 quartz_stairs 6 
setblock ~78 ~3 ~61 quartz_stairs 7 
setblock ~79 ~3 ~36 quartz_stairs 5 
setblock ~79 ~3 ~60 quartz_stairs 5  
fill ~80 ~3 ~36 ~82 ~3 ~36 quartz_stairs 6 
setblock ~80 ~3 ~37 quartz_block 1 
setblock ~80 ~3 ~59 quartz_block 1  
fill ~80 ~3 ~60 ~82 ~3 ~60 quartz_stairs 7  
fill ~82 ~3 ~37 ~86 ~3 ~37 stained_hardened_clay 10  
fill ~82 ~3 ~59 ~86 ~3 ~59 stained_hardened_clay 10  
fill ~83 ~3 ~36 ~85 ~3 ~36 stone_slab 15  
fill ~83 ~3 ~60 ~85 ~3 ~60 stone_slab 15 
setblock ~86 ~3 ~36 quartz_stairs 6 
setblock ~86 ~3 ~60 quartz_stairs 7 
setblock ~87 ~3 ~37 sea_lantern 0 
setblock ~87 ~3 ~59 sea_lantern 0  
fill ~88 ~3 ~37 ~89 ~3 ~37 stained_glass 0  
fill ~88 ~3 ~59 ~89 ~3 ~59 stained_glass 0 
setblock ~90 ~3 ~37 sea_lantern 0 
setblock ~90 ~3 ~59 sea_lantern 0 
setblock ~91 ~3 ~36 quartz_stairs 6  
fill ~91 ~3 ~37 ~95 ~3 ~37 stained_hardened_clay 10  
fill ~91 ~3 ~59 ~95 ~3 ~59 stained_hardened_clay 10 
setblock ~91 ~3 ~60 quartz_stairs 7  
fill ~92 ~3 ~36 ~94 ~3 ~36 stone_slab 15  
fill ~92 ~3 ~60 ~94 ~3 ~60 stone_slab 15  
fill ~95 ~3 ~36 ~97 ~3 ~36 quartz_stairs 6  
fill ~95 ~3 ~60 ~97 ~3 ~60 quartz_stairs 7 
setblock ~97 ~3 ~37 quartz_block 1 
setblock ~97 ~3 ~59 quartz_block 1 
setblock ~98 ~3 ~36 quartz_stairs 4 
setblock ~98 ~3 ~60 quartz_stairs 4  
fill ~99 ~3 ~15 ~100 ~3 ~15 quartz_block 0  
fill ~99 ~3 ~16 ~100 ~3 ~16 sea_lantern 0  
fill ~99 ~3 ~17 ~101 ~3 ~17 quartz_block 0 
setblock ~99 ~3 ~35 quartz_stairs 6 
setblock ~99 ~3 ~61 quartz_stairs 7  
fill ~99 ~3 ~79 ~101 ~3 ~79 quartz_block 0  
fill ~99 ~3 ~80 ~100 ~3 ~80 sea_lantern 0  
fill ~99 ~3 ~81 ~100 ~3 ~81 quartz_block 0  
fill ~100 ~3 ~21 ~102 ~3 ~21 sea_lantern 0  
fill ~100 ~3 ~22 ~102 ~3 ~22 quartz_block 0  
fill ~100 ~3 ~35 ~100 ~4 ~35 quartz_block 0  
fill ~100 ~3 ~61 ~100 ~4 ~61 quartz_block 0  
fill ~100 ~3 ~74 ~102 ~3 ~74 quartz_block 0  
fill ~100 ~3 ~75 ~102 ~3 ~75 sea_lantern 0  
fill ~100 ~3 ~76 ~102 ~3 ~76 quartz_block 0 
setblock ~101 ~3 ~14 quartz_block 0 
setblock ~101 ~3 ~15 sea_lantern 0 
setblock ~101 ~3 ~16 quartz_block 0  
fill ~101 ~3 ~20 ~102 ~3 ~20 quartz_block 0  
fill ~101 ~3 ~34 ~101 ~4 ~34 quartz_block 1  
fill ~101 ~3 ~62 ~101 ~4 ~62 quartz_block 1 
setblock ~101 ~3 ~80 quartz_block 0 
setblock ~101 ~3 ~81 sea_lantern 0 
setblock ~101 ~3 ~82 quartz_block 0  
fill ~102 ~3 ~35 ~102 ~4 ~35 stained_glass 11  
fill ~102 ~3 ~61 ~102 ~4 ~61 stained_glass 11 
setblock ~103 ~3 ~36 stained_glass 11 
setblock ~103 ~3 ~60 stained_glass 11  
fill ~104 ~3 ~37 ~104 ~5 ~37 stained_glass 11 
setblock ~104 ~3 ~46 quartz_stairs 0 
setblock ~104 ~3 ~50 quartz_stairs 0  
fill ~104 ~3 ~58 ~104 ~3 ~59 stained_glass 11  
fill ~105 ~3 ~39 ~105 ~6 ~39 stained_glass 11  
fill ~105 ~3 ~40 ~105 ~5 ~40 stained_glass 11  
fill ~105 ~3 ~47 ~105 ~3 ~50 quartz_block 0  
fill ~105 ~3 ~56 ~105 ~5 ~56 stained_glass 11  
fill ~105 ~3 ~57 ~105 ~6 ~57 stained_glass 11  
fill ~106 ~3 ~44 ~106 ~8 ~44 stained_glass 11  
fill ~106 ~3 ~45 ~106 ~7 ~45 stained_glass 11  
fill ~106 ~3 ~46 ~106 ~4 ~46 quartz_block 0 
setblock ~106 ~3 ~47 quartz_stairs 7 
setblock ~106 ~3 ~48 quartz_stairs 5 
setblock ~106 ~3 ~49 quartz_stairs 6  
fill ~106 ~3 ~50 ~106 ~4 ~50 quartz_block 0  
fill ~106 ~3 ~51 ~106 ~7 ~51 stained_glass 11  
fill ~106 ~3 ~52 ~106 ~8 ~52 stained_glass 11  
fill ~19 ~4 ~46 ~19 ~4 ~50 quartz_stairs 4  
fill ~20 ~4 ~42 ~20 ~10 ~42 stained_glass 11  
fill ~20 ~4 ~43 ~20 ~8 ~43 stained_glass 11 
setblock ~20 ~4 ~47 sea_lantern 0 
setblock ~20 ~4 ~48 quartz_block 0 
setblock ~20 ~4 ~49 sea_lantern 0  
fill ~20 ~4 ~53 ~20 ~8 ~53 stained_glass 11  
fill ~20 ~4 ~54 ~20 ~10 ~54 stained_glass 11  
fill ~21 ~4 ~38 ~21 ~8 ~38 stained_glass 11  
fill ~21 ~4 ~46 ~21 ~4 ~50 quartz_stairs 1  
fill ~21 ~4 ~58 ~21 ~8 ~58 stained_glass 11  
fill ~22 ~4 ~36 ~22 ~6 ~36 stained_glass 11  
fill ~22 ~4 ~59 ~22 ~5 ~59 stained_glass 11  
fill ~22 ~4 ~60 ~22 ~6 ~60 stained_glass 11 
setblock ~23 ~4 ~19 quartz_block 0 
setblock ~23 ~4 ~20 sea_lantern 0  
fill ~23 ~4 ~21 ~23 ~5 ~21 quartz_block 0  
fill ~23 ~4 ~22 ~24 ~4 ~22 quartz_block 0  
fill ~23 ~4 ~35 ~23 ~5 ~35 stained_glass 11  
fill ~23 ~4 ~61 ~23 ~5 ~61 stained_glass 11  
fill ~23 ~4 ~74 ~24 ~4 ~74 quartz_block 0  
fill ~23 ~4 ~75 ~23 ~5 ~75 quartz_block 0 
setblock ~23 ~4 ~76 sea_lantern 0 
setblock ~23 ~4 ~77 quartz_block 0  
fill ~24 ~4 ~20 ~24 ~3 ~20 quartz_block 0  
fill ~24 ~4 ~21 ~24 ~3 ~21 sea_lantern 0  
fill ~24 ~4 ~75 ~24 ~3 ~75 sea_lantern 0  
fill ~24 ~4 ~76 ~24 ~3 ~76 quartz_block 0  
fill ~27 ~4 ~15 ~28 ~4 ~15 quartz_block 0 
setblock ~27 ~4 ~16 sea_lantern 0 
setblock ~27 ~4 ~17 quartz_block 0 
setblock ~27 ~4 ~35 quartz_block 0 
setblock ~27 ~4 ~61 quartz_block 0 
setblock ~27 ~4 ~79 quartz_block 0 
setblock ~27 ~4 ~80 sea_lantern 0  
fill ~27 ~4 ~81 ~28 ~4 ~81 quartz_block 0  
fill ~28 ~4 ~16 ~28 ~5 ~16 quartz_block 0 
setblock ~28 ~4 ~17 sea_lantern 0 
setblock ~28 ~4 ~18 quartz_block 0 
setblock ~28 ~4 ~36 quartz_block 0 
setblock ~28 ~4 ~60 quartz_block 0 
setblock ~28 ~4 ~78 quartz_block 0 
setblock ~28 ~4 ~79 sea_lantern 0  
fill ~28 ~4 ~80 ~28 ~5 ~80 quartz_block 0 
setblock ~29 ~4 ~37 sea_lantern 0 
setblock ~29 ~4 ~59 sea_lantern 0 
setblock ~30 ~4 ~36 quartz_block 0 
setblock ~30 ~4 ~60 quartz_block 0 
setblock ~31 ~4 ~36 cobblestone_wall 0  
fill ~31 ~4 ~37 ~35 ~4 ~37 stained_hardened_clay 10  
fill ~31 ~4 ~59 ~35 ~4 ~59 stained_hardened_clay 10 
setblock ~31 ~4 ~60 cobblestone_wall 0 
setblock ~35 ~4 ~36 cobblestone_wall 0 
setblock ~35 ~4 ~60 cobblestone_wall 0  
fill ~36 ~4 ~37 ~39 ~4 ~37 stained_glass 0  
fill ~36 ~4 ~59 ~39 ~4 ~59 stained_glass 0 
setblock ~40 ~4 ~36 cobblestone_wall 0  
fill ~40 ~4 ~37 ~44 ~4 ~37 stained_hardened_clay 10  
fill ~40 ~4 ~59 ~44 ~4 ~59 stained_hardened_clay 10 
setblock ~40 ~4 ~60 cobblestone_wall 0 
setblock ~44 ~4 ~36 cobblestone_wall 0 
setblock ~44 ~4 ~60 cobblestone_wall 0 
setblock ~45 ~4 ~36 quartz_block 0 
setblock ~45 ~4 ~60 quartz_block 0 
setblock ~46 ~4 ~37 sea_lantern 0 
setblock ~46 ~4 ~59 sea_lantern 0 
setblock ~47 ~4 ~36 quartz_block 0 
setblock ~47 ~4 ~60 quartz_block 0 
setblock ~48 ~4 ~19 quartz_block 0 
setblock ~48 ~4 ~20 sea_lantern 0  
fill ~48 ~4 ~21 ~48 ~5 ~21 quartz_block 0  
fill ~48 ~4 ~22 ~49 ~4 ~22 quartz_block 0 
setblock ~48 ~4 ~35 quartz_block 0 
setblock ~48 ~4 ~61 quartz_block 0  
fill ~48 ~4 ~74 ~49 ~4 ~74 quartz_block 0  
fill ~48 ~4 ~75 ~48 ~5 ~75 quartz_block 0 
setblock ~48 ~4 ~76 sea_lantern 0 
setblock ~48 ~4 ~77 quartz_block 0  
fill ~49 ~4 ~20 ~49 ~3 ~20 quartz_block 0  
fill ~49 ~4 ~21 ~49 ~3 ~21 sea_lantern 0  
fill ~49 ~4 ~75 ~49 ~3 ~75 sea_lantern 0  
fill ~49 ~4 ~76 ~49 ~3 ~76 quartz_block 0 
setblock ~50 ~4 ~29 double_stone_slab 0 
setblock ~50 ~4 ~67 double_stone_slab 0  
fill ~51 ~4 ~30 ~55 ~4 ~30 stonebrick 0  
fill ~51 ~4 ~66 ~55 ~4 ~66 stonebrick 0  
fill ~52 ~4 ~15 ~53 ~4 ~15 quartz_block 0 
setblock ~52 ~4 ~16 sea_lantern 0 
setblock ~52 ~4 ~17 quartz_block 0 
setblock ~52 ~4 ~31 cobblestone_wall 0 
setblock ~52 ~4 ~65 cobblestone_wall 0 
setblock ~52 ~4 ~79 quartz_block 0 
setblock ~52 ~4 ~80 sea_lantern 0  
fill ~52 ~4 ~81 ~53 ~4 ~81 quartz_block 0  
fill ~53 ~4 ~16 ~53 ~5 ~16 quartz_block 0 
setblock ~53 ~4 ~17 sea_lantern 0 
setblock ~53 ~4 ~18 quartz_block 0 
setblock ~53 ~4 ~78 quartz_block 0 
setblock ~53 ~4 ~79 sea_lantern 0  
fill ~53 ~4 ~80 ~53 ~5 ~80 quartz_block 0  
fill ~55 ~4 ~29 ~55 ~5 ~29 stone_slab 7  
fill ~55 ~4 ~67 ~55 ~5 ~67 stone_slab 7 
setblock ~56 ~4 ~29 quartz_block 0 
setblock ~56 ~4 ~30 sea_lantern 0 
setblock ~56 ~4 ~66 sea_lantern 0 
setblock ~56 ~4 ~67 quartz_block 0  
fill ~57 ~4 ~30 ~58 ~4 ~30 stained_hardened_clay 10  
fill ~58 ~4 ~31 ~58 ~5 ~31 stained_hardened_clay 10  
fill ~58 ~4 ~65 ~58 ~5 ~65 stained_hardened_clay 10  
fill ~58 ~4 ~66 ~58 ~5 ~66 stained_hardened_clay 10  
fill ~59 ~4 ~29 ~60 ~4 ~29 quartz_block 0  
fill ~59 ~4 ~30 ~60 ~4 ~30 stonebrick 0  
fill ~59 ~4 ~31 ~60 ~4 ~31 cobblestone_wall 0  
fill ~59 ~4 ~65 ~60 ~4 ~65 cobblestone_wall 0  
fill ~59 ~4 ~66 ~60 ~4 ~66 stonebrick 0  
fill ~59 ~4 ~67 ~60 ~4 ~67 quartz_block 0  
fill ~61 ~4 ~30 ~65 ~4 ~30 quartz_block 0  
fill ~61 ~4 ~31 ~65 ~4 ~31 quartz_block 0  
fill ~61 ~4 ~65 ~65 ~4 ~65 quartz_block 0  
fill ~61 ~4 ~66 ~65 ~4 ~66 quartz_block 0  
fill ~66 ~4 ~29 ~67 ~4 ~29 quartz_block 0  
fill ~66 ~4 ~30 ~67 ~4 ~30 stonebrick 0  
fill ~66 ~4 ~31 ~67 ~4 ~31 cobblestone_wall 0  
fill ~66 ~4 ~65 ~67 ~4 ~65 cobblestone_wall 0  
fill ~66 ~4 ~66 ~67 ~4 ~66 stonebrick 0  
fill ~66 ~4 ~67 ~67 ~4 ~67 quartz_block 0  
fill ~68 ~4 ~30 ~69 ~4 ~30 stained_hardened_clay 10  
fill ~68 ~4 ~31 ~68 ~5 ~31 stained_hardened_clay 10  
fill ~68 ~4 ~65 ~68 ~5 ~65 stained_hardened_clay 10  
fill ~68 ~4 ~66 ~69 ~4 ~66 stained_hardened_clay 10 
setblock ~70 ~4 ~29 quartz_block 0 
setblock ~70 ~4 ~30 sea_lantern 0 
setblock ~70 ~4 ~66 sea_lantern 0 
setblock ~70 ~4 ~67 quartz_block 0  
fill ~71 ~4 ~29 ~71 ~5 ~29 stone_slab 7  
fill ~71 ~4 ~30 ~75 ~4 ~30 stonebrick 0  
fill ~71 ~4 ~66 ~75 ~4 ~66 stonebrick 0  
fill ~71 ~4 ~67 ~71 ~5 ~67 stone_slab 7  
fill ~73 ~4 ~15 ~74 ~4 ~15 quartz_block 0  
fill ~73 ~4 ~16 ~73 ~5 ~16 quartz_block 0 
setblock ~73 ~4 ~17 sea_lantern 0 
setblock ~73 ~4 ~18 quartz_block 0 
setblock ~73 ~4 ~78 quartz_block 0 
setblock ~73 ~4 ~79 sea_lantern 0  
fill ~73 ~4 ~80 ~73 ~5 ~80 quartz_block 0  
fill ~73 ~4 ~81 ~74 ~4 ~81 quartz_block 0  
fill ~74 ~4 ~16 ~74 ~3 ~16 sea_lantern 0  
fill ~74 ~4 ~17 ~74 ~3 ~17 quartz_block 0 
setblock ~74 ~4 ~31 cobblestone_wall 0 
setblock ~74 ~4 ~65 cobblestone_wall 0  
fill ~74 ~4 ~79 ~74 ~3 ~79 quartz_block 0  
fill ~74 ~4 ~80 ~74 ~3 ~80 sea_lantern 0 
setblock ~76 ~4 ~29 double_stone_slab 0 
setblock ~76 ~4 ~67 double_stone_slab 0 
setblock ~77 ~4 ~20 quartz_block 0 
setblock ~77 ~4 ~21 sea_lantern 0  
fill ~77 ~4 ~22 ~78 ~4 ~22 quartz_block 0  
fill ~77 ~4 ~74 ~78 ~4 ~74 quartz_block 0 
setblock ~77 ~4 ~75 sea_lantern 0 
setblock ~77 ~4 ~76 quartz_block 0 
setblock ~78 ~4 ~19 quartz_block 0 
setblock ~78 ~4 ~20 sea_lantern 0  
fill ~78 ~4 ~21 ~78 ~5 ~21 quartz_block 0 
setblock ~78 ~4 ~35 quartz_block 0 
setblock ~78 ~4 ~61 quartz_block 0  
fill ~78 ~4 ~75 ~78 ~5 ~75 quartz_block 0 
setblock ~78 ~4 ~76 sea_lantern 0 
setblock ~78 ~4 ~77 quartz_block 0   

KittysCommands:  
setblock ~79 ~4 ~36 quartz_block 0 
setblock ~79 ~4 ~60 quartz_block 0 
setblock ~80 ~4 ~37 sea_lantern 0 
setblock ~80 ~4 ~59 sea_lantern 0 
setblock ~81 ~4 ~36 quartz_block 0 
setblock ~81 ~4 ~60 quartz_block 0 
setblock ~82 ~4 ~36 cobblestone_wall 0  
fill ~82 ~4 ~37 ~86 ~4 ~37 stained_hardened_clay 10  
fill ~82 ~4 ~59 ~86 ~4 ~59 stained_hardened_clay 10 
setblock ~82 ~4 ~60 cobblestone_wall 0 
setblock ~86 ~4 ~36 cobblestone_wall 0 
setblock ~86 ~4 ~60 cobblestone_wall 0  
fill ~87 ~4 ~37 ~90 ~4 ~37 stained_glass 0  
fill ~87 ~4 ~59 ~90 ~4 ~59 stained_glass 0 
setblock ~91 ~4 ~36 cobblestone_wall 0  
fill ~91 ~4 ~37 ~95 ~4 ~37 stained_hardened_clay 10  
fill ~91 ~4 ~59 ~95 ~4 ~59 stained_hardened_clay 10 
setblock ~91 ~4 ~60 cobblestone_wall 0 
setblock ~95 ~4 ~36 cobblestone_wall 0 
setblock ~95 ~4 ~60 cobblestone_wall 0 
setblock ~96 ~4 ~36 quartz_block 0 
setblock ~96 ~4 ~60 quartz_block 0 
setblock ~97 ~4 ~37 sea_lantern 0 
setblock ~97 ~4 ~59 sea_lantern 0  
fill ~98 ~4 ~15 ~99 ~4 ~15 quartz_block 0  
fill ~98 ~4 ~16 ~98 ~5 ~16 quartz_block 0 
setblock ~98 ~4 ~17 sea_lantern 0 
setblock ~98 ~4 ~18 quartz_block 0 
setblock ~98 ~4 ~36 quartz_block 0 
setblock ~98 ~4 ~60 quartz_block 0 
setblock ~98 ~4 ~78 quartz_block 0 
setblock ~98 ~4 ~79 sea_lantern 0  
fill ~98 ~4 ~80 ~98 ~5 ~80 quartz_block 0  
fill ~98 ~4 ~81 ~99 ~4 ~81 quartz_block 0  
fill ~99 ~4 ~16 ~99 ~3 ~16 sea_lantern 0  
fill ~99 ~4 ~17 ~99 ~3 ~17 quartz_block 0 
setblock ~99 ~4 ~35 quartz_block 0 
setblock ~99 ~4 ~61 quartz_block 0  
fill ~99 ~4 ~79 ~99 ~3 ~79 quartz_block 0  
fill ~99 ~4 ~80 ~99 ~3 ~80 sea_lantern 0 
setblock ~102 ~4 ~20 quartz_block 0 
setblock ~102 ~4 ~21 sea_lantern 0  
fill ~102 ~4 ~22 ~103 ~4 ~22 quartz_block 0  
fill ~102 ~4 ~74 ~103 ~4 ~74 quartz_block 0 
setblock ~102 ~4 ~75 sea_lantern 0 
setblock ~102 ~4 ~76 quartz_block 0 
setblock ~103 ~4 ~19 quartz_block 0 
setblock ~103 ~4 ~20 sea_lantern 0  
fill ~103 ~4 ~21 ~103 ~5 ~21 quartz_block 0  
fill ~103 ~4 ~35 ~103 ~5 ~35 stained_glass 11  
fill ~103 ~4 ~61 ~103 ~5 ~61 stained_glass 11  
fill ~103 ~4 ~75 ~103 ~5 ~75 quartz_block 0 
setblock ~103 ~4 ~76 sea_lantern 0 
setblock ~103 ~4 ~77 quartz_block 0  
fill ~104 ~4 ~36 ~104 ~6 ~36 stained_glass 11  
fill ~104 ~4 ~59 ~104 ~5 ~59 stained_glass 11  
fill ~104 ~4 ~60 ~104 ~6 ~60 stained_glass 11  
fill ~105 ~4 ~38 ~105 ~8 ~38 stained_glass 11  
fill ~105 ~4 ~46 ~105 ~4 ~50 quartz_stairs 0  
fill ~105 ~4 ~58 ~105 ~8 ~58 stained_glass 11  
fill ~106 ~4 ~42 ~106 ~10 ~42 stained_glass 11  
fill ~106 ~4 ~43 ~106 ~8 ~43 stained_glass 11 
setblock ~106 ~4 ~47 sea_lantern 0 
setblock ~106 ~4 ~48 quartz_block 0 
setblock ~106 ~4 ~49 sea_lantern 0  
fill ~106 ~4 ~53 ~106 ~8 ~53 stained_glass 11  
fill ~106 ~4 ~54 ~106 ~10 ~54 stained_glass 11  
fill ~107 ~4 ~46 ~107 ~4 ~50 quartz_stairs 5 
setblock ~19 ~5 ~46 double_stone_slab 7 
setblock ~19 ~5 ~47 stone_slab 7 
setblock ~19 ~5 ~48 cobblestone_wall 0 
setblock ~19 ~5 ~49 stone_slab 7 
setblock ~19 ~5 ~50 double_stone_slab 7  
fill ~20 ~5 ~41 ~20 ~23 ~41 stained_glass 11  
fill ~20 ~5 ~46 ~20 ~7 ~46 stained_glass 11  
fill ~20 ~5 ~47 ~20 ~6 ~47 stained_glass 11  
fill ~20 ~5 ~48 ~20 ~6 ~48 stained_glass 11  
fill ~20 ~5 ~49 ~20 ~6 ~49 stained_glass 11  
fill ~20 ~5 ~50 ~20 ~7 ~50 stained_glass 11  
fill ~20 ~5 ~55 ~20 ~23 ~55 stained_glass 11 
setblock ~23 ~5 ~18 quartz_block 0 
setblock ~23 ~5 ~19 sea_lantern 0  
fill ~23 ~5 ~20 ~23 ~6 ~20 quartz_block 0  
fill ~23 ~5 ~76 ~23 ~6 ~76 quartz_block 0 
setblock ~23 ~5 ~77 sea_lantern 0 
setblock ~23 ~5 ~78 quartz_block 0  
fill ~24 ~5 ~34 ~24 ~6 ~34 stained_glass 11  
fill ~24 ~5 ~62 ~24 ~6 ~62 stained_glass 11  
fill ~25 ~5 ~33 ~25 ~6 ~33 quartz_block 1  
fill ~25 ~5 ~63 ~25 ~6 ~63 quartz_block 1  
fill ~26 ~5 ~34 ~26 ~6 ~34 quartz_block 0  
fill ~26 ~5 ~62 ~26 ~6 ~62 quartz_block 0 
setblock ~27 ~5 ~34 quartz_stairs 6 
setblock ~27 ~5 ~62 quartz_stairs 7  
fill ~28 ~5 ~17 ~28 ~6 ~17 quartz_block 0 
setblock ~28 ~5 ~18 sea_lantern 0 
setblock ~28 ~5 ~19 quartz_block 0 
setblock ~28 ~5 ~35 quartz_stairs 5 
setblock ~28 ~5 ~61 quartz_stairs 5 
setblock ~28 ~5 ~77 quartz_block 0 
setblock ~28 ~5 ~78 sea_lantern 0  
fill ~28 ~5 ~79 ~28 ~6 ~79 quartz_block 0  
fill ~29 ~5 ~35 ~31 ~5 ~35 quartz_stairs 6 
setblock ~29 ~5 ~36 quartz_block 1 
setblock ~29 ~5 ~37 quartz_stairs 3 
setblock ~29 ~5 ~59 quartz_stairs 2 
setblock ~29 ~5 ~60 quartz_block 1  
fill ~29 ~5 ~61 ~31 ~5 ~61 quartz_stairs 7  
fill ~31 ~5 ~36 ~35 ~5 ~36 stained_hardened_clay 10  
fill ~31 ~5 ~60 ~35 ~5 ~60 stained_hardened_clay 10  
fill ~32 ~5 ~35 ~34 ~5 ~35 stone_slab 15  
fill ~32 ~5 ~61 ~34 ~5 ~61 stone_slab 15 
setblock ~35 ~5 ~35 quartz_stairs 6 
setblock ~35 ~5 ~61 quartz_stairs 7 
setblock ~36 ~5 ~36 sea_lantern 0 
setblock ~36 ~5 ~60 sea_lantern 0  
fill ~37 ~5 ~36 ~38 ~5 ~36 stained_glass 0  
fill ~37 ~5 ~60 ~38 ~5 ~60 stained_glass 0 
setblock ~39 ~5 ~36 sea_lantern 0 
setblock ~39 ~5 ~60 sea_lantern 0 
setblock ~40 ~5 ~35 quartz_stairs 6  
fill ~40 ~5 ~36 ~44 ~5 ~36 stained_hardened_clay 10  
fill ~40 ~5 ~60 ~44 ~5 ~60 stained_hardened_clay 10 
setblock ~40 ~5 ~61 quartz_stairs 7  
fill ~41 ~5 ~35 ~43 ~5 ~35 stone_slab 15  
fill ~41 ~5 ~61 ~43 ~5 ~61 stone_slab 15  
fill ~44 ~5 ~35 ~46 ~5 ~35 quartz_stairs 6  
fill ~44 ~5 ~61 ~46 ~5 ~61 quartz_stairs 7 
setblock ~46 ~5 ~36 quartz_block 1 
setblock ~46 ~5 ~37 quartz_stairs 3 
setblock ~46 ~5 ~59 quartz_stairs 2 
setblock ~46 ~5 ~60 quartz_block 1 
setblock ~47 ~5 ~35 quartz_stairs 4 
setblock ~47 ~5 ~61 quartz_stairs 4 
setblock ~48 ~5 ~18 quartz_block 0 
setblock ~48 ~5 ~19 sea_lantern 0  
fill ~48 ~5 ~20 ~48 ~6 ~20 quartz_block 0 
setblock ~48 ~5 ~34 quartz_stairs 6 
setblock ~48 ~5 ~62 quartz_stairs 7  
fill ~48 ~5 ~76 ~48 ~6 ~76 quartz_block 0 
setblock ~48 ~5 ~77 sea_lantern 0 
setblock ~48 ~5 ~78 quartz_block 0  
fill ~49 ~5 ~34 ~49 ~6 ~34 quartz_block 0  
fill ~49 ~5 ~62 ~49 ~6 ~62 quartz_block 0  
fill ~50 ~5 ~29 ~51 ~5 ~29 stone_slab 7  
fill ~50 ~5 ~30 ~50 ~9 ~30 stone_slab 7  
fill ~50 ~5 ~31 ~50 ~9 ~31 stone_slab 7  
fill ~50 ~5 ~32 ~50 ~6 ~32 stone_slab 7  
fill ~50 ~5 ~33 ~50 ~6 ~33 quartz_block 1  
fill ~50 ~5 ~63 ~50 ~6 ~63 quartz_block 1  
fill ~50 ~5 ~64 ~50 ~6 ~64 stone_slab 7  
fill ~50 ~5 ~65 ~50 ~9 ~65 stone_slab 7  
fill ~50 ~5 ~66 ~50 ~9 ~66 stone_slab 7  
fill ~50 ~5 ~67 ~51 ~5 ~67 stone_slab 7  
fill ~51 ~5 ~30 ~56 ~5 ~30 stonebrick 0  
fill ~51 ~5 ~66 ~56 ~5 ~66 stonebrick 0  
fill ~53 ~5 ~17 ~53 ~6 ~17 quartz_block 0 
setblock ~53 ~5 ~18 sea_lantern 0 
setblock ~53 ~5 ~19 quartz_block 0 
setblock ~53 ~5 ~77 quartz_block 0 
setblock ~53 ~5 ~78 sea_lantern 0  
fill ~53 ~5 ~79 ~53 ~6 ~79 quartz_block 0  
fill ~56 ~5 ~29 ~56 ~6 ~29 stone_slab 7  
fill ~56 ~5 ~67 ~56 ~6 ~67 stone_slab 7 
setblock ~57 ~5 ~29 quartz_block 0 
setblock ~57 ~5 ~30 sea_lantern 0 
setblock ~57 ~5 ~66 sea_lantern 0 
setblock ~57 ~5 ~67 quartz_block 0  
fill ~58 ~5 ~30 ~60 ~5 ~30 stained_hardened_clay 10  
fill ~59 ~5 ~31 ~60 ~5 ~31 stained_hardened_clay 10  
fill ~59 ~5 ~65 ~60 ~5 ~65 stained_hardened_clay 10  
fill ~59 ~5 ~66 ~60 ~5 ~66 stained_hardened_clay 10  
fill ~61 ~5 ~29 ~65 ~5 ~29 quartz_block 0  
fill ~61 ~5 ~30 ~65 ~5 ~30 stonebrick 0  
fill ~61 ~5 ~31 ~65 ~5 ~31 cobblestone_wall 0  
fill ~61 ~5 ~65 ~65 ~5 ~65 cobblestone_wall 0  
fill ~61 ~5 ~66 ~65 ~5 ~66 stonebrick 0  
fill ~61 ~5 ~67 ~65 ~5 ~67 quartz_block 0  
fill ~66 ~5 ~30 ~68 ~5 ~30 stained_hardened_clay 10  
fill ~66 ~5 ~31 ~68 ~5 ~31 stained_hardened_clay 10  
fill ~66 ~5 ~65 ~68 ~5 ~65 stained_hardened_clay 10  
fill ~66 ~5 ~66 ~68 ~5 ~66 stained_hardened_clay 10 
setblock ~69 ~5 ~29 quartz_block 0 
setblock ~69 ~5 ~30 sea_lantern 0 
setblock ~69 ~5 ~66 sea_lantern 0 
setblock ~69 ~5 ~67 quartz_block 0  
fill ~70 ~5 ~29 ~70 ~6 ~29 stone_slab 7  
fill ~70 ~5 ~30 ~75 ~5 ~30 stonebrick 0  
fill ~70 ~5 ~66 ~75 ~5 ~66 stonebrick 0  
fill ~70 ~5 ~67 ~70 ~6 ~67 stone_slab 7  
fill ~73 ~5 ~17 ~73 ~6 ~17 quartz_block 0 
setblock ~73 ~5 ~18 sea_lantern 0 
setblock ~73 ~5 ~19 quartz_block 0 
setblock ~73 ~5 ~77 quartz_block 0 
setblock ~73 ~5 ~78 sea_lantern 0  
fill ~73 ~5 ~79 ~73 ~6 ~79 quartz_block 0  
fill ~75 ~5 ~29 ~76 ~5 ~29 stone_slab 7  
fill ~75 ~5 ~67 ~76 ~5 ~67 stone_slab 7  
fill ~76 ~5 ~30 ~76 ~9 ~30 stone_slab 7  
fill ~76 ~5 ~31 ~76 ~9 ~31 stone_slab 7  
fill ~76 ~5 ~32 ~76 ~6 ~32 stone_slab 7  
fill ~76 ~5 ~33 ~76 ~6 ~33 quartz_block 1  
fill ~76 ~5 ~63 ~76 ~6 ~63 quartz_block 1  
fill ~76 ~5 ~64 ~76 ~6 ~64 stone_slab 7  
fill ~76 ~5 ~65 ~76 ~9 ~65 stone_slab 7  
fill ~76 ~5 ~66 ~76 ~9 ~66 stone_slab 7  
fill ~77 ~5 ~34 ~77 ~6 ~34 quartz_block 0  
fill ~77 ~5 ~62 ~77 ~6 ~62 quartz_block 0 
setblock ~78 ~5 ~18 quartz_block 0 
setblock ~78 ~5 ~19 sea_lantern 0  
fill ~78 ~5 ~20 ~78 ~6 ~20 quartz_block 0 
setblock ~78 ~5 ~34 quartz_stairs 6 
setblock ~78 ~5 ~62 quartz_stairs 7  
fill ~78 ~5 ~76 ~78 ~6 ~76 quartz_block 0 
setblock ~78 ~5 ~77 sea_lantern 0 
setblock ~78 ~5 ~78 quartz_block 0 
setblock ~79 ~5 ~35 quartz_stairs 5 
setblock ~79 ~5 ~61 quartz_stairs 5  
fill ~80 ~5 ~35 ~82 ~5 ~35 quartz_stairs 6 
setblock ~80 ~5 ~36 quartz_block 1 
setblock ~80 ~5 ~37 quartz_stairs 3 
setblock ~80 ~5 ~59 quartz_stairs 2 
setblock ~80 ~5 ~60 quartz_block 1  
fill ~80 ~5 ~61 ~82 ~5 ~61 quartz_stairs 7  
fill ~82 ~5 ~36 ~86 ~5 ~36 stained_hardened_clay 10  
fill ~82 ~5 ~60 ~86 ~5 ~60 stained_hardened_clay 10  
fill ~83 ~5 ~35 ~85 ~5 ~35 stone_slab 15  
fill ~83 ~5 ~61 ~85 ~5 ~61 stone_slab 15 
setblock ~86 ~5 ~35 quartz_stairs 6 
setblock ~86 ~5 ~61 quartz_stairs 7 
setblock ~87 ~5 ~36 sea_lantern 0 
setblock ~87 ~5 ~60 sea_lantern 0  
fill ~88 ~5 ~36 ~89 ~5 ~36 stained_glass 0  
fill ~88 ~5 ~60 ~89 ~5 ~60 stained_glass 0 
setblock ~90 ~5 ~36 sea_lantern 0 
setblock ~90 ~5 ~60 sea_lantern 0 
setblock ~91 ~5 ~35 quartz_stairs 6  
fill ~91 ~5 ~36 ~95 ~5 ~36 stained_hardened_clay 10  
fill ~91 ~5 ~60 ~95 ~5 ~60 stained_hardened_clay 10 
setblock ~91 ~5 ~61 quartz_stairs 7  
fill ~92 ~5 ~35 ~94 ~5 ~35 stone_slab 15  
fill ~92 ~5 ~61 ~94 ~5 ~61 stone_slab 15  
fill ~95 ~5 ~35 ~97 ~5 ~35 quartz_stairs 6  
fill ~95 ~5 ~61 ~97 ~5 ~61 quartz_stairs 7 
setblock ~97 ~5 ~36 quartz_block 1 
setblock ~97 ~5 ~37 quartz_stairs 3 
setblock ~97 ~5 ~59 quartz_stairs 2 
setblock ~97 ~5 ~60 quartz_block 1  
fill ~98 ~5 ~17 ~98 ~6 ~17 quartz_block 0 
setblock ~98 ~5 ~18 sea_lantern 0 
setblock ~98 ~5 ~19 quartz_block 0 
setblock ~98 ~5 ~35 quartz_stairs 4 
setblock ~98 ~5 ~61 quartz_stairs 4 
setblock ~98 ~5 ~77 quartz_block 0 
setblock ~98 ~5 ~78 sea_lantern 0  
fill ~98 ~5 ~79 ~98 ~6 ~79 quartz_block 0 
setblock ~99 ~5 ~34 quartz_stairs 6 
setblock ~99 ~5 ~62 quartz_stairs 7  
fill ~100 ~5 ~34 ~100 ~6 ~34 quartz_block 0  
fill ~100 ~5 ~62 ~100 ~6 ~62 quartz_block 0  
fill ~101 ~5 ~33 ~101 ~6 ~33 quartz_block 1  
fill ~101 ~5 ~63 ~101 ~6 ~63 quartz_block 1  
fill ~102 ~5 ~34 ~102 ~6 ~34 stained_glass 11  
fill ~102 ~5 ~62 ~102 ~6 ~62 stained_glass 11 
setblock ~103 ~5 ~18 quartz_block 0 
setblock ~103 ~5 ~19 sea_lantern 0  
fill ~103 ~5 ~20 ~103 ~6 ~20 quartz_block 0  
fill ~103 ~5 ~76 ~103 ~6 ~76 quartz_block 0 
setblock ~103 ~5 ~77 sea_lantern 0 
setblock ~103 ~5 ~78 quartz_block 0  
fill ~106 ~5 ~41 ~106 ~23 ~41 stained_glass 11  
fill ~106 ~5 ~46 ~106 ~7 ~46 stained_glass 11  
fill ~106 ~5 ~47 ~106 ~6 ~47 stained_glass 11  
fill ~106 ~5 ~48 ~106 ~6 ~48 stained_glass 11  
fill ~106 ~5 ~49 ~106 ~6 ~49 stained_glass 11  
fill ~106 ~5 ~50 ~106 ~7 ~50 stained_glass 11  
fill ~106 ~5 ~55 ~106 ~23 ~55 stained_glass 11 
setblock ~107 ~5 ~46 double_stone_slab 7 
setblock ~107 ~5 ~47 stone_slab 7 
setblock ~107 ~5 ~48 cobblestone_wall 0 
setblock ~107 ~5 ~49 stone_slab 7 
setblock ~107 ~5 ~50 double_stone_slab 7 
setblock ~19 ~6 ~46 cobblestone_wall 0 
setblock ~19 ~6 ~47 stone_slab 15 
setblock ~19 ~6 ~48 double_stone_slab 7 
setblock ~19 ~6 ~49 stone_slab 15 
setblock ~19 ~6 ~50 cobblestone_wall 0  
fill ~20 ~6 ~40 ~20 ~22 ~40 stained_glass 11  
fill ~20 ~6 ~56 ~20 ~22 ~56 stained_glass 11  
fill ~21 ~6 ~37 ~21 ~11 ~37 stained_glass 11  
fill ~21 ~6 ~59 ~21 ~11 ~59 stained_glass 11  
fill ~22 ~6 ~17 ~23 ~6 ~17 quartz_block 0  
fill ~22 ~6 ~18 ~23 ~6 ~18 sea_lantern 0  
fill ~22 ~6 ~19 ~23 ~6 ~19 quartz_block 0  
fill ~22 ~6 ~35 ~22 ~8 ~35 stained_glass 11  
fill ~22 ~6 ~61 ~22 ~8 ~61 stained_glass 11  
fill ~22 ~6 ~77 ~23 ~6 ~77 quartz_block 0  
fill ~22 ~6 ~78 ~23 ~6 ~78 sea_lantern 0  
fill ~22 ~6 ~79 ~23 ~6 ~79 quartz_block 0  
fill ~23 ~6 ~34 ~23 ~7 ~34 stained_glass 11  
fill ~23 ~6 ~62 ~23 ~7 ~62 stained_glass 11 
setblock ~27 ~6 ~34 quartz_block 0 
setblock ~27 ~6 ~62 quartz_block 0  
fill ~28 ~6 ~18 ~28 ~7 ~18 quartz_block 0 
setblock ~28 ~6 ~19 sea_lantern 0  
fill ~28 ~6 ~20 ~28 ~8 ~20 quartz_block 0 
setblock ~28 ~6 ~35 quartz_block 0 
setblock ~28 ~6 ~61 quartz_block 0  
fill ~28 ~6 ~76 ~28 ~8 ~76 quartz_block 0 
setblock ~28 ~6 ~77 sea_lantern 0  
fill ~28 ~6 ~78 ~28 ~7 ~78 quartz_block 0 
setblock ~29 ~6 ~36 sea_lantern 0 
setblock ~29 ~6 ~60 sea_lantern 0 
setblock ~30 ~6 ~35 quartz_block 0 
setblock ~30 ~6 ~61 quartz_block 0 
setblock ~31 ~6 ~35 cobblestone_wall 0  
fill ~31 ~6 ~36 ~35 ~6 ~36 stained_hardened_clay 10  
fill ~31 ~6 ~60 ~35 ~6 ~60 stained_hardened_clay 10 
setblock ~31 ~6 ~61 cobblestone_wall 0 
setblock ~35 ~6 ~35 cobblestone_wall 0 
setblock ~35 ~6 ~61 cobblestone_wall 0  
fill ~36 ~6 ~36 ~39 ~6 ~36 stained_glass 0  
fill ~36 ~6 ~60 ~39 ~6 ~60 stained_glass 0 
setblock ~40 ~6 ~35 cobblestone_wall 0  
fill ~40 ~6 ~36 ~44 ~6 ~36 stained_hardened_clay 10  
fill ~40 ~6 ~60 ~44 ~6 ~60 stained_hardened_clay 10 
setblock ~40 ~6 ~61 cobblestone_wall 0 
setblock ~44 ~6 ~35 cobblestone_wall 0 
setblock ~44 ~6 ~61 cobblestone_wall 0 
setblock ~45 ~6 ~35 quartz_block 0 
setblock ~45 ~6 ~61 quartz_block 0 
setblock ~46 ~6 ~36 sea_lantern 0 
setblock ~46 ~6 ~60 sea_lantern 0  
fill ~47 ~6 ~17 ~48 ~6 ~17 quartz_block 0  
fill ~47 ~6 ~18 ~48 ~6 ~18 sea_lantern 0  
fill ~47 ~6 ~19 ~48 ~6 ~19 quartz_block 0 
setblock ~47 ~6 ~35 quartz_block 0 
setblock ~47 ~6 ~61 quartz_block 0  
fill ~47 ~6 ~77 ~48 ~6 ~77 quartz_block 0  
fill ~47 ~6 ~78 ~48 ~6 ~78 sea_lantern 0  
fill ~47 ~6 ~79 ~48 ~6 ~79 quartz_block 0 
setblock ~48 ~6 ~34 quartz_block 0 
setblock ~48 ~6 ~62 quartz_block 0  
fill ~50 ~6 ~29 ~52 ~6 ~29 stone_slab 7  
fill ~50 ~6 ~67 ~52 ~6 ~67 stone_slab 7  
fill ~51 ~6 ~30 ~57 ~6 ~30 stonebrick 0  
fill ~51 ~6 ~66 ~57 ~6 ~66 stonebrick 0  
fill ~53 ~6 ~18 ~53 ~7 ~18 quartz_block 0 
setblock ~53 ~6 ~19 sea_lantern 0  
fill ~53 ~6 ~20 ~53 ~8 ~20 quartz_block 0  
fill ~53 ~6 ~76 ~53 ~8 ~76 quartz_block 0 
setblock ~53 ~6 ~77 sea_lantern 0  
fill ~53 ~6 ~78 ~53 ~7 ~78 quartz_block 0  
fill ~57 ~6 ~29 ~57 ~7 ~29 stone_slab 7  
fill ~57 ~6 ~67 ~57 ~7 ~67 stone_slab 7 
setblock ~58 ~6 ~29 quartz_block 0 
setblock ~58 ~6 ~30 sea_lantern 0 
setblock ~58 ~6 ~66 sea_lantern 0 
setblock ~58 ~6 ~67 quartz_block 0  
fill ~59 ~6 ~30 ~67 ~6 ~30 stained_hardened_clay 10  
fill ~59 ~6 ~31 ~67 ~6 ~31 stained_hardened_clay 10  
fill ~59 ~6 ~65 ~67 ~6 ~65 stained_hardened_clay 10  
fill ~59 ~6 ~66 ~67 ~6 ~66 stained_hardened_clay 10 
setblock ~68 ~6 ~29 quartz_block 0 
setblock ~68 ~6 ~30 sea_lantern 0 
setblock ~68 ~6 ~66 sea_lantern 0 
setblock ~68 ~6 ~67 quartz_block 0  
fill ~69 ~6 ~29 ~69 ~7 ~29 stone_slab 7  
fill ~69 ~6 ~30 ~75 ~6 ~30 stonebrick 0  
fill ~69 ~6 ~66 ~75 ~6 ~66 stonebrick 0  
fill ~69 ~6 ~67 ~69 ~7 ~67 stone_slab 7  
fill ~73 ~6 ~18 ~73 ~7 ~18 quartz_block 0 
setblock ~73 ~6 ~19 sea_lantern 0  
fill ~73 ~6 ~20 ~73 ~8 ~20 quartz_block 0  
fill ~73 ~6 ~76 ~73 ~8 ~76 quartz_block 0 
setblock ~73 ~6 ~77 sea_lantern 0  
fill ~73 ~6 ~78 ~73 ~7 ~78 quartz_block 0  
fill ~74 ~6 ~29 ~76 ~6 ~29 stone_slab 7  
fill ~74 ~6 ~67 ~76 ~6 ~67 stone_slab 7  
fill ~78 ~6 ~17 ~79 ~6 ~17 quartz_block 0  
fill ~78 ~6 ~18 ~79 ~6 ~18 sea_lantern 0  
fill ~78 ~6 ~19 ~79 ~6 ~19 quartz_block 0 
setblock ~78 ~6 ~34 quartz_block 0 
setblock ~78 ~6 ~62 quartz_block 0  
fill ~78 ~6 ~77 ~79 ~6 ~77 quartz_block 0  
fill ~78 ~6 ~78 ~79 ~6 ~78 sea_lantern 0  
fill ~78 ~6 ~79 ~79 ~6 ~79 quartz_block 0 
setblock ~79 ~6 ~35 quartz_block 0 
setblock ~79 ~6 ~61 quartz_block 0 
setblock ~80 ~6 ~36 sea_lantern 0 
setblock ~80 ~6 ~60 sea_lantern 0 
setblock ~81 ~6 ~35 quartz_block 0 
setblock ~81 ~6 ~61 quartz_block 0 
setblock ~82 ~6 ~35 cobblestone_wall 0  
fill ~82 ~6 ~36 ~86 ~6 ~36 stained_hardened_clay 10  
fill ~82 ~6 ~60 ~86 ~6 ~60 stained_hardened_clay 10 
setblock ~82 ~6 ~61 cobblestone_wall 0 
setblock ~86 ~6 ~35 cobblestone_wall 0 
setblock ~86 ~6 ~61 cobblestone_wall 0  
fill ~87 ~6 ~36 ~90 ~6 ~36 stained_glass 0  
fill ~87 ~6 ~60 ~90 ~6 ~60 stained_glass 0 
setblock ~91 ~6 ~35 cobblestone_wall 0  
fill ~91 ~6 ~36 ~95 ~6 ~36 stained_hardened_clay 10  
fill ~91 ~6 ~60 ~95 ~6 ~60 stained_hardened_clay 10 
setblock ~91 ~6 ~61 cobblestone_wall 0 
setblock ~95 ~6 ~35 cobblestone_wall 0 
setblock ~95 ~6 ~61 cobblestone_wall 0 
setblock ~96 ~6 ~35 quartz_block 0 
setblock ~96 ~6 ~61 quartz_block 0 
setblock ~97 ~6 ~36 sea_lantern 0 
setblock ~97 ~6 ~60 sea_lantern 0  
fill ~98 ~6 ~18 ~98 ~7 ~18 quartz_block 0 
setblock ~98 ~6 ~19 sea_lantern 0  
fill ~98 ~6 ~20 ~98 ~8 ~20 quartz_block 0 
setblock ~98 ~6 ~35 quartz_block 0 
setblock ~98 ~6 ~61 quartz_block 0  
fill ~98 ~6 ~76 ~98 ~8 ~76 quartz_block 0 
setblock ~98 ~6 ~77 sea_lantern 0  
fill ~98 ~6 ~78 ~98 ~7 ~78 quartz_block 0 
setblock ~99 ~6 ~34 quartz_block 0 
setblock ~99 ~6 ~62 quartz_block 0  
fill ~103 ~6 ~17 ~104 ~6 ~17 quartz_block 0  
fill ~103 ~6 ~18 ~104 ~6 ~18 sea_lantern 0  
fill ~103 ~6 ~19 ~104 ~6 ~19 quartz_block 0  
fill ~103 ~6 ~34 ~103 ~7 ~34 stained_glass 11  
fill ~103 ~6 ~62 ~103 ~7 ~62 stained_glass 11  
fill ~103 ~6 ~77 ~104 ~6 ~77 quartz_block 0  
fill ~103 ~6 ~78 ~104 ~6 ~78 sea_lantern 0  
fill ~103 ~6 ~79 ~104 ~6 ~79 quartz_block 0  
fill ~104 ~6 ~35 ~104 ~8 ~35 stained_glass 11  
fill ~104 ~6 ~61 ~104 ~8 ~61 stained_glass 11  
fill ~105 ~6 ~37 ~105 ~11 ~37 stained_glass 11  
fill ~105 ~6 ~59 ~105 ~11 ~59 stained_glass 11  
fill ~106 ~6 ~40 ~106 ~22 ~40 stained_glass 11  
fill ~106 ~6 ~56 ~106 ~22 ~56 stained_glass 11 
setblock ~107 ~6 ~46 cobblestone_wall 0 
setblock ~107 ~6 ~47 stone_slab 15 
setblock ~107 ~6 ~48 double_stone_slab 7 
setblock ~107 ~6 ~49 stone_slab 15 
setblock ~107 ~6 ~50 cobblestone_wall 0 
setblock ~19 ~7 ~46 stone_slab 7  
fill ~19 ~7 ~47 ~19 ~21 ~47 stained_glass 11  
fill ~19 ~7 ~48 ~19 ~21 ~48 stained_glass 11  
fill ~19 ~7 ~49 ~19 ~21 ~49 stained_glass 11 
setblock ~19 ~7 ~50 stone_slab 7  
fill ~20 ~7 ~39 ~20 ~21 ~39 stained_glass 11  
fill ~20 ~7 ~57 ~20 ~21 ~57 stained_glass 11  
fill ~21 ~7 ~36 ~21 ~21 ~36 stained_glass 11  
fill ~21 ~7 ~60 ~21 ~21 ~60 stained_glass 11  
fill ~23 ~7 ~15 ~23 ~8 ~15 quartz_block 0  
fill ~23 ~7 ~16 ~23 ~8 ~16 sea_lantern 0  
fill ~23 ~7 ~17 ~23 ~8 ~17 quartz_block 0  
fill ~23 ~7 ~18 ~23 ~7 ~19 quartz_block 0  
fill ~23 ~7 ~77 ~23 ~7 ~79 quartz_block 0  
fill ~23 ~7 ~80 ~23 ~8 ~80 sea_lantern 0  
fill ~23 ~7 ~81 ~23 ~8 ~81 quartz_block 0  
fill ~24 ~7 ~33 ~24 ~9 ~33 stained_glass 11  
fill ~24 ~7 ~63 ~24 ~9 ~63 stained_glass 11  
fill ~25 ~7 ~32 ~25 ~9 ~32 quartz_block 1  
fill ~25 ~7 ~64 ~25 ~9 ~64 quartz_block 1  
fill ~26 ~7 ~33 ~26 ~9 ~33 quartz_block 0  
fill ~26 ~7 ~63 ~26 ~9 ~63 quartz_block 0 
setblock ~27 ~7 ~33 quartz_stairs 6 
setblock ~27 ~7 ~63 quartz_stairs 7 
setblock ~28 ~7 ~19 quartz_block 0  
fill ~28 ~7 ~21 ~28 ~8 ~21 sea_lantern 0  
fill ~28 ~7 ~22 ~28 ~8 ~22 quartz_block 0 
setblock ~28 ~7 ~34 quartz_stairs 5 
setblock ~28 ~7 ~62 quartz_stairs 5  
fill ~28 ~7 ~74 ~28 ~8 ~74 quartz_block 0  
fill ~28 ~7 ~75 ~28 ~8 ~75 sea_lantern 0 
setblock ~28 ~7 ~77 quartz_block 0  
fill ~29 ~7 ~34 ~31 ~7 ~34 quartz_stairs 6 
setblock ~29 ~7 ~35 quartz_block 1 
setblock ~29 ~7 ~36 quartz_stairs 3 
setblock ~29 ~7 ~60 quartz_stairs 2 
setblock ~29 ~7 ~61 quartz_block 1  
fill ~29 ~7 ~62 ~31 ~7 ~62 quartz_stairs 7  
fill ~31 ~7 ~35 ~35 ~7 ~35 stained_hardened_clay 10  
fill ~31 ~7 ~61 ~35 ~7 ~61 stained_hardened_clay 10  
fill ~32 ~7 ~34 ~34 ~7 ~34 stone_slab 15  
fill ~32 ~7 ~62 ~34 ~7 ~62 stone_slab 15 
setblock ~35 ~7 ~34 quartz_stairs 6 
setblock ~35 ~7 ~62 quartz_stairs 7 
setblock ~36 ~7 ~35 sea_lantern 0 
setblock ~36 ~7 ~61 sea_lantern 0  
fill ~37 ~7 ~35 ~38 ~7 ~35 stained_glass 0  
fill ~37 ~7 ~61 ~38 ~7 ~61 stained_glass 0 
setblock ~39 ~7 ~35 sea_lantern 0 
setblock ~39 ~7 ~61 sea_lantern 0 
setblock ~40 ~7 ~34 quartz_stairs 6  
fill ~40 ~7 ~35 ~44 ~7 ~35 stained_hardened_clay 10  
fill ~40 ~7 ~61 ~44 ~7 ~61 stained_hardened_clay 10 
setblock ~40 ~7 ~62 quartz_stairs 7  
fill ~41 ~7 ~34 ~43 ~7 ~34 stone_slab 15  
fill ~41 ~7 ~62 ~43 ~7 ~62 stone_slab 15  
fill ~44 ~7 ~34 ~46 ~7 ~34 quartz_stairs 6  
fill ~44 ~7 ~62 ~46 ~7 ~62 quartz_stairs 7 
setblock ~46 ~7 ~35 quartz_block 1 
setblock ~46 ~7 ~36 quartz_stairs 3 
setblock ~46 ~7 ~60 quartz_stairs 2 
setblock ~46 ~7 ~61 quartz_block 1 
setblock ~47 ~7 ~34 quartz_stairs 4 
setblock ~47 ~7 ~62 quartz_stairs 4  
fill ~48 ~7 ~15 ~48 ~8 ~15 quartz_block 0  
fill ~48 ~7 ~16 ~48 ~8 ~16 sea_lantern 0  
fill ~48 ~7 ~17 ~48 ~8 ~17 quartz_block 0  
fill ~48 ~7 ~18 ~48 ~7 ~19 quartz_block 0 
setblock ~48 ~7 ~33 quartz_stairs 6 
setblock ~48 ~7 ~63 quartz_stairs 7  
fill ~48 ~7 ~77 ~48 ~7 ~79 quartz_block 0  
fill ~48 ~7 ~80 ~48 ~8 ~80 sea_lantern 0  
fill ~48 ~7 ~81 ~48 ~8 ~81 quartz_block 0  
fill ~49 ~7 ~33 ~49 ~9 ~33 quartz_block 0  
fill ~49 ~7 ~63 ~49 ~9 ~63 quartz_block 0  
fill ~50 ~7 ~29 ~53 ~7 ~29 stone_slab 7  
fill ~50 ~7 ~32 ~50 ~9 ~32 quartz_block 1  
fill ~50 ~7 ~64 ~50 ~9 ~64 quartz_block 1  
fill ~50 ~7 ~67 ~53 ~7 ~67 stone_slab 7  
fill ~51 ~7 ~30 ~58 ~7 ~30 stonebrick 0  
fill ~51 ~7 ~66 ~58 ~7 ~66 stonebrick 0 
setblock ~53 ~7 ~19 quartz_block 0  
fill ~53 ~7 ~21 ~53 ~8 ~21 sea_lantern 0  
fill ~53 ~7 ~22 ~53 ~8 ~22 quartz_block 0  
fill ~53 ~7 ~74 ~53 ~8 ~74 quartz_block 0  
fill ~53 ~7 ~75 ~53 ~8 ~75 sea_lantern 0 
setblock ~53 ~7 ~77 quartz_block 0  
fill ~58 ~7 ~29 ~58 ~8 ~29 stone_slab 7  
fill ~58 ~7 ~67 ~58 ~8 ~67 stone_slab 7  
fill ~59 ~7 ~29 ~60 ~7 ~29 quartz_block 0  
fill ~59 ~7 ~30 ~60 ~7 ~30 sea_lantern 0  
fill ~59 ~7 ~66 ~60 ~7 ~66 sea_lantern 0  
fill ~59 ~7 ~67 ~60 ~7 ~67 quartz_block 0  
fill ~61 ~7 ~30 ~65 ~7 ~30 stained_hardened_clay 10  
fill ~61 ~7 ~31 ~65 ~7 ~31 stained_hardened_clay 10  
fill ~61 ~7 ~65 ~65 ~7 ~65 stained_hardened_clay 10  
fill ~61 ~7 ~66 ~65 ~7 ~66 stained_hardened_clay 10  
fill ~66 ~7 ~29 ~67 ~7 ~29 quartz_block 0  
fill ~66 ~7 ~30 ~67 ~7 ~30 sea_lantern 0  
fill ~66 ~7 ~66 ~67 ~7 ~66 sea_lantern 0  
fill ~66 ~7 ~67 ~67 ~7 ~67 quartz_block 0  
fill ~68 ~7 ~29 ~68 ~8 ~29 stone_slab 7  
fill ~68 ~7 ~30 ~75 ~7 ~30 stonebrick 0  
fill ~68 ~7 ~66 ~75 ~7 ~66 stonebrick 0  
fill ~68 ~7 ~67 ~68 ~8 ~67 stone_slab 7 
setblock ~73 ~7 ~19 quartz_block 0  
fill ~73 ~7 ~21 ~73 ~8 ~21 sea_lantern 0  
fill ~73 ~7 ~22 ~73 ~8 ~22 quartz_block 0  
fill ~73 ~7 ~29 ~76 ~7 ~29 stone_slab 7  
fill ~73 ~7 ~67 ~76 ~7 ~67 stone_slab 7  
fill ~73 ~7 ~74 ~73 ~8 ~74 quartz_block 0  
fill ~73 ~7 ~75 ~73 ~8 ~75 sea_lantern 0 
setblock ~73 ~7 ~77 quartz_block 0  
fill ~76 ~7 ~32 ~76 ~9 ~32 quartz_block 1  
fill ~76 ~7 ~64 ~76 ~9 ~64 quartz_block 1  
fill ~77 ~7 ~33 ~77 ~9 ~33 quartz_block 0  
fill ~77 ~7 ~63 ~77 ~9 ~63 quartz_block 0  
fill ~78 ~7 ~15 ~78 ~8 ~15 quartz_block 0  
fill ~78 ~7 ~16 ~78 ~8 ~16 sea_lantern 0  
fill ~78 ~7 ~17 ~78 ~8 ~17 quartz_block 0  
fill ~78 ~7 ~18 ~78 ~7 ~19 quartz_block 0 
setblock ~78 ~7 ~33 quartz_stairs 6 
setblock ~78 ~7 ~63 quartz_stairs 7  
fill ~78 ~7 ~77 ~78 ~6 ~77 quartz_block 0  
fill ~78 ~7 ~78 ~78 ~7 ~79 quartz_block 0  
fill ~78 ~7 ~80 ~78 ~8 ~80 sea_lantern 0  
fill ~78 ~7 ~81 ~78 ~8 ~81 quartz_block 0 
setblock ~79 ~7 ~34 quartz_stairs 5 
setblock ~79 ~7 ~62 quartz_stairs 5  
fill ~80 ~7 ~34 ~82 ~7 ~34 quartz_stairs 6 
setblock ~80 ~7 ~35 quartz_block 1 
setblock ~80 ~7 ~36 quartz_stairs 3 
setblock ~80 ~7 ~60 quartz_stairs 2 
setblock ~80 ~7 ~61 quartz_block 1  
fill ~80 ~7 ~62 ~82 ~7 ~62 quartz_stairs 7  
fill ~82 ~7 ~35 ~86 ~7 ~35 stained_hardened_clay 10  
fill ~82 ~7 ~61 ~86 ~7 ~61 stained_hardened_clay 10  
fill ~83 ~7 ~34 ~85 ~7 ~34 stone_slab 15  
fill ~83 ~7 ~62 ~85 ~7 ~62 stone_slab 15 
setblock ~86 ~7 ~34 quartz_stairs 6 
setblock ~86 ~7 ~62 quartz_stairs 7 
setblock ~87 ~7 ~35 sea_lantern 0 
setblock ~87 ~7 ~61 sea_lantern 0  
fill ~88 ~7 ~35 ~89 ~7 ~35 stained_glass 0  
fill ~88 ~7 ~61 ~89 ~7 ~61 stained_glass 0 
setblock ~90 ~7 ~35 sea_lantern 0 
setblock ~90 ~7 ~61 sea_lantern 0 
setblock ~91 ~7 ~34 quartz_stairs 6  
fill ~91 ~7 ~35 ~95 ~7 ~35 stained_hardened_clay 10  
fill ~91 ~7 ~61 ~95 ~7 ~61 stained_hardened_clay 10 
setblock ~91 ~7 ~62 quartz_stairs 7  
fill ~92 ~7 ~34 ~94 ~7 ~34 stone_slab 15  
fill ~92 ~7 ~62 ~94 ~7 ~62 stone_slab 15  
fill ~95 ~7 ~34 ~97 ~7 ~34 quartz_stairs 6  
fill ~95 ~7 ~62 ~97 ~7 ~62 quartz_stairs 7 
setblock ~97 ~7 ~35 quartz_block 1 
setblock ~97 ~7 ~36 quartz_stairs 3 
setblock ~97 ~7 ~60 quartz_stairs 2 
setblock ~97 ~7 ~61 quartz_block 1 
setblock ~98 ~7 ~19 quartz_block 0  
fill ~98 ~7 ~21 ~98 ~8 ~21 sea_lantern 0  
fill ~98 ~7 ~22 ~98 ~8 ~22 quartz_block 0 
setblock ~98 ~7 ~34 quartz_stairs 4 
setblock ~98 ~7 ~62 quartz_stairs 4  
fill ~98 ~7 ~74 ~98 ~8 ~74 quartz_block 0  
fill ~98 ~7 ~75 ~98 ~8 ~75 sea_lantern 0 
setblock ~98 ~7 ~77 quartz_block 0 
setblock ~99 ~7 ~33 quartz_stairs 6 
setblock ~99 ~7 ~63 quartz_stairs 7  
fill ~100 ~7 ~33 ~100 ~9 ~33 quartz_block 0  
fill ~100 ~7 ~63 ~100 ~9 ~63 quartz_block 0  
fill ~101 ~7 ~32 ~101 ~9 ~32 quartz_block 1  
fill ~101 ~7 ~64 ~101 ~9 ~64 quartz_block 1  
fill ~102 ~7 ~33 ~102 ~9 ~33 stained_glass 11  
fill ~102 ~7 ~63 ~102 ~9 ~63 stained_glass 11  
fill ~103 ~7 ~15 ~103 ~8 ~15 quartz_block 0  
fill ~103 ~7 ~16 ~103 ~8 ~16 sea_lantern 0  
fill ~103 ~7 ~17 ~103 ~8 ~17 quartz_block 0  
fill ~103 ~7 ~18 ~103 ~7 ~19 quartz_block 0  
fill ~103 ~7 ~77 ~103 ~6 ~77 quartz_block 0  
fill ~103 ~7 ~78 ~103 ~7 ~79 quartz_block 0  
fill ~103 ~7 ~80 ~103 ~8 ~80 sea_lantern 0  
fill ~103 ~7 ~81 ~103 ~8 ~81 quartz_block 0  
fill ~105 ~7 ~36 ~105 ~21 ~36 stained_glass 11  
fill ~105 ~7 ~60 ~105 ~21 ~60 stained_glass 11  
fill ~106 ~7 ~39 ~106 ~21 ~39 stained_glass 11  
fill ~106 ~7 ~57 ~106 ~21 ~57 stained_glass 11 
setblock ~107 ~7 ~46 stone_slab 7  
fill ~107 ~7 ~47 ~107 ~21 ~47 stained_glass 11  
fill ~107 ~7 ~48 ~107 ~21 ~48 stained_glass 11  
fill ~107 ~7 ~49 ~107 ~21 ~49 stained_glass 11 
setblock ~107 ~7 ~50 stone_slab 7  
fill ~19 ~8 ~45 ~19 ~20 ~45 stained_glass 11  
fill ~19 ~8 ~46 ~19 ~20 ~46 stained_glass 11  
fill ~19 ~8 ~50 ~19 ~20 ~50 stained_glass 11  
fill ~19 ~8 ~51 ~19 ~20 ~51 stained_glass 11  
fill ~22 ~8 ~34 ~22 ~20 ~34 stained_glass 11  
fill ~22 ~8 ~62 ~22 ~20 ~62 stained_glass 11  
fill ~23 ~8 ~33 ~23 ~11 ~33 stained_glass 11  
fill ~23 ~8 ~63 ~23 ~11 ~63 stained_glass 11  
fill ~23 ~8 ~79 ~25 ~8 ~79 quartz_block 0  
fill ~24 ~8 ~15 ~25 ~8 ~15 quartz_block 0  
fill ~24 ~8 ~16 ~25 ~8 ~16 sea_lantern 0  
fill ~24 ~8 ~17 ~25 ~8 ~17 quartz_block 0  
fill ~24 ~8 ~80 ~25 ~8 ~80 sea_lantern 0  
fill ~24 ~8 ~81 ~25 ~8 ~81 quartz_block 0  
fill ~26 ~8 ~20 ~28 ~8 ~20 quartz_block 0  
fill ~26 ~8 ~21 ~28 ~8 ~21 sea_lantern 0  
fill ~26 ~8 ~22 ~28 ~8 ~22 quartz_block 0  
fill ~26 ~8 ~74 ~28 ~8 ~74 quartz_block 0  
fill ~26 ~8 ~75 ~28 ~8 ~75 sea_lantern 0  
fill ~26 ~8 ~76 ~28 ~8 ~76 quartz_block 0  
fill ~27 ~8 ~33 ~27 ~9 ~33 quartz_block 0  
fill ~27 ~8 ~63 ~27 ~9 ~63 quartz_block 0  
fill ~28 ~8 ~34 ~28 ~9 ~34 quartz_block 0  
fill ~28 ~8 ~62 ~28 ~9 ~62 quartz_block 0 
setblock ~29 ~8 ~35 sea_lantern 0 
setblock ~29 ~8 ~61 sea_lantern 0  
fill ~30 ~8 ~34 ~30 ~9 ~34 quartz_block 0  
fill ~30 ~8 ~62 ~30 ~9 ~62 quartz_block 0 
setblock ~31 ~8 ~34 cobblestone_wall 0  
fill ~31 ~8 ~35 ~35 ~8 ~35 stained_hardened_clay 10  
fill ~31 ~8 ~61 ~35 ~8 ~61 stained_hardened_clay 10 
setblock ~31 ~8 ~62 cobblestone_wall 0 
setblock ~35 ~8 ~34 cobblestone_wall 0 
setblock ~35 ~8 ~62 cobblestone_wall 0  
fill ~36 ~8 ~35 ~39 ~8 ~35 stained_glass 0  
fill ~36 ~8 ~61 ~39 ~8 ~61 stained_glass 0 
setblock ~40 ~8 ~34 cobblestone_wall 0  
fill ~40 ~8 ~35 ~44 ~8 ~35 stained_hardened_clay 10  
fill ~40 ~8 ~61 ~44 ~8 ~61 stained_hardened_clay 10 
setblock ~40 ~8 ~62 cobblestone_wall 0 
setblock ~44 ~8 ~34 cobblestone_wall 0 
setblock ~44 ~8 ~62 cobblestone_wall 0  
fill ~45 ~8 ~34 ~45 ~9 ~34 quartz_block 0  
fill ~45 ~8 ~62 ~45 ~9 ~62 quartz_block 0 
setblock ~46 ~8 ~35 sea_lantern 0 
setblock ~46 ~8 ~61 sea_lantern 0  
fill ~47 ~8 ~34 ~47 ~9 ~34 quartz_block 0  
fill ~47 ~8 ~62 ~47 ~9 ~62 quartz_block 0  
fill ~48 ~8 ~33 ~48 ~9 ~33 quartz_block 0  
fill ~48 ~8 ~63 ~48 ~9 ~63 quartz_block 0  
fill ~48 ~8 ~79 ~50 ~8 ~79 quartz_block 0  
fill ~49 ~8 ~15 ~50 ~8 ~15 quartz_block 0  
fill ~49 ~8 ~16 ~50 ~8 ~16 sea_lantern 0  
fill ~49 ~8 ~17 ~50 ~8 ~17 quartz_block 0  
fill ~49 ~8 ~80 ~50 ~8 ~80 sea_lantern 0  
fill ~49 ~8 ~81 ~50 ~8 ~81 quartz_block 0  
fill ~50 ~8 ~29 ~54 ~8 ~29 stone_slab 7  
fill ~50 ~8 ~67 ~54 ~8 ~67 stone_slab 7  
fill ~51 ~8 ~20 ~53 ~8 ~20 quartz_block 0  
fill ~51 ~8 ~21 ~53 ~8 ~21 sea_lantern 0  
fill ~51 ~8 ~22 ~53 ~8 ~22 quartz_block 0  
fill ~51 ~8 ~30 ~60 ~8 ~30 stonebrick 0  
fill ~51 ~8 ~66 ~60 ~8 ~66 stonebrick 0  
fill ~51 ~8 ~74 ~53 ~8 ~74 quartz_block 0  
fill ~51 ~8 ~75 ~53 ~8 ~75 sea_lantern 0  
fill ~51 ~8 ~76 ~53 ~8 ~76 quartz_block 0  
fill ~59 ~8 ~29 ~60 ~8 ~29 stone_slab 7  
fill ~59 ~8 ~67 ~60 ~8 ~67 stone_slab 7  
fill ~61 ~8 ~29 ~65 ~8 ~29 quartz_block 0  
fill ~61 ~8 ~30 ~65 ~8 ~30 sea_lantern 0  
fill ~61 ~8 ~66 ~65 ~8 ~66 sea_lantern 0  
fill ~61 ~8 ~67 ~65 ~8 ~67 quartz_block 0  
fill ~66 ~8 ~29 ~68 ~8 ~29 stone_slab 7  
fill ~66 ~8 ~30 ~75 ~8 ~30 stonebrick 0  
fill ~66 ~8 ~66 ~75 ~8 ~66 stonebrick 0  
fill ~66 ~8 ~67 ~68 ~8 ~67 stone_slab 7  
fill ~72 ~8 ~29 ~76 ~8 ~29 stone_slab 7  
fill ~72 ~8 ~67 ~76 ~8 ~67 stone_slab 7  
fill ~74 ~8 ~20 ~75 ~8 ~20 quartz_block 0  
fill ~74 ~8 ~21 ~75 ~8 ~21 sea_lantern 0  
fill ~74 ~8 ~22 ~75 ~8 ~22 quartz_block 0  
fill ~74 ~8 ~74 ~75 ~8 ~74 quartz_block 0  
fill ~74 ~8 ~75 ~75 ~8 ~75 sea_lantern 0  
fill ~74 ~8 ~76 ~75 ~8 ~76 quartz_block 0  
fill ~76 ~8 ~15 ~78 ~8 ~15 quartz_block 0  
fill ~76 ~8 ~16 ~78 ~8 ~16 sea_lantern 0  
fill ~76 ~8 ~17 ~78 ~8 ~17 quartz_block 0  
fill ~76 ~8 ~79 ~78 ~8 ~79 quartz_block 0  
fill ~76 ~8 ~80 ~78 ~8 ~80 sea_lantern 0  
fill ~76 ~8 ~81 ~78 ~8 ~81 quartz_block 0  
fill ~78 ~8 ~33 ~78 ~9 ~33 quartz_block 0  
fill ~78 ~8 ~63 ~78 ~9 ~63 quartz_block 0  
fill ~79 ~8 ~34 ~79 ~9 ~34 quartz_block 0  
fill ~79 ~8 ~62 ~79 ~9 ~62 quartz_block 0 
setblock ~80 ~8 ~35 sea_lantern 0 
setblock ~80 ~8 ~61 sea_lantern 0  
fill ~81 ~8 ~34 ~81 ~9 ~34 quartz_block 0  
fill ~81 ~8 ~62 ~81 ~9 ~62 quartz_block 0 
setblock ~82 ~8 ~34 cobblestone_wall 0  
fill ~82 ~8 ~35 ~86 ~8 ~35 stained_hardened_clay 10  
fill ~82 ~8 ~61 ~86 ~8 ~61 stained_hardened_clay 10 
setblock ~82 ~8 ~62 cobblestone_wall 0 
setblock ~86 ~8 ~34 cobblestone_wall 0 
setblock ~86 ~8 ~62 cobblestone_wall 0  
fill ~87 ~8 ~35 ~90 ~8 ~35 stained_glass 0  
fill ~87 ~8 ~61 ~90 ~8 ~61 stained_glass 0 
setblock ~91 ~8 ~34 cobblestone_wall 0  
fill ~91 ~8 ~35 ~95 ~8 ~35 stained_hardened_clay 10  
fill ~91 ~8 ~61 ~95 ~8 ~61 stained_hardened_clay 10 
setblock ~91 ~8 ~62 cobblestone_wall 0 
setblock ~95 ~8 ~34 cobblestone_wall 0 
setblock ~95 ~8 ~62 cobblestone_wall 0  
fill ~96 ~8 ~34 ~96 ~9 ~34 quartz_block 0  
fill ~96 ~8 ~62 ~96 ~9 ~62 quartz_block 0 
setblock ~97 ~8 ~35 sea_lantern 0 
setblock ~97 ~8 ~61 sea_lantern 0  
fill ~98 ~8 ~34 ~98 ~9 ~34 quartz_block 0  
fill ~98 ~8 ~62 ~98 ~9 ~62 quartz_block 0  
fill ~99 ~8 ~20 ~100 ~8 ~20 quartz_block 0  
fill ~99 ~8 ~21 ~100 ~8 ~21 sea_lantern 0  
fill ~99 ~8 ~22 ~100 ~8 ~22 quartz_block 0  
fill ~99 ~8 ~33 ~99 ~9 ~33 quartz_block 0   
fill ~99 ~8 ~63 ~99 ~9 ~63 quartz_block 0  
fill ~99 ~8 ~74 ~100 ~8 ~74 quartz_block 0  
fill ~99 ~8 ~75 ~100 ~8 ~75 sea_lantern 0  
fill ~99 ~8 ~76 ~100 ~8 ~76 quartz_block 0  
fill ~101 ~8 ~15 ~103 ~8 ~15 quartz_block 0  
fill ~101 ~8 ~16 ~103 ~8 ~16 sea_lantern 0  
fill ~101 ~8 ~17 ~103 ~8 ~17 quartz_block 0  
fill ~101 ~8 ~79 ~103 ~8 ~79 quartz_block 0  
fill ~101 ~8 ~80 ~103 ~8 ~80 sea_lantern 0  
fill ~101 ~8 ~81 ~103 ~8 ~81 quartz_block 0  
fill ~103 ~8 ~33 ~103 ~11 ~33 stained_glass 11  
fill ~103 ~8 ~63 ~103 ~11 ~63 stained_glass 11  
fill ~104 ~8 ~34 ~104 ~20 ~34 stained_glass 11  
fill ~104 ~8 ~62 ~104 ~20 ~62 stained_glass 11  
fill ~107 ~8 ~45 ~107 ~20 ~45 stained_glass 11  
fill ~107 ~8 ~46 ~107 ~20 ~46 stained_glass 11  
fill ~107 ~8 ~50 ~107 ~20 ~50 stained_glass 11  
fill ~107 ~8 ~51 ~107 ~20 ~51 stained_glass 11  
fill ~19 ~9 ~43 ~19 ~19 ~43 stained_glass 11  
fill ~19 ~9 ~44 ~19 ~19 ~44 stained_glass 11  
fill ~19 ~9 ~52 ~19 ~19 ~52 stained_glass 11  
fill ~19 ~9 ~53 ~19 ~19 ~53 stained_glass 11  
fill ~20 ~9 ~38 ~20 ~19 ~38 stained_glass 11  
fill ~20 ~9 ~58 ~20 ~19 ~58 stained_glass 11  
fill ~21 ~9 ~35 ~21 ~19 ~35 stained_glass 11  
fill ~21 ~9 ~61 ~21 ~19 ~61 stained_glass 11 
setblock ~25 ~9 ~14 quartz_block 0 
setblock ~25 ~9 ~15 sea_lantern 0  
fill ~25 ~9 ~16 ~25 ~9 ~17 quartz_block 0  
fill ~25 ~9 ~20 ~26 ~9 ~20 quartz_block 0  
fill ~25 ~9 ~21 ~26 ~9 ~21 sea_lantern 0  
fill ~25 ~9 ~22 ~26 ~9 ~22 quartz_block 0  
fill ~25 ~9 ~74 ~26 ~9 ~74 quartz_block 0  
fill ~25 ~9 ~75 ~26 ~9 ~75 sea_lantern 0  
fill ~25 ~9 ~76 ~26 ~9 ~76 quartz_block 0  
fill ~25 ~9 ~79 ~26 ~9 ~79 quartz_block 0  
fill ~25 ~9 ~80 ~25 ~9 ~79 quartz_block 0 
setblock ~25 ~9 ~81 sea_lantern 0 
setblock ~25 ~9 ~82 quartz_block 0  
fill ~26 ~9 ~15 ~26 ~10 ~15 quartz_block 0  
fill ~26 ~9 ~16 ~26 ~10 ~16 sea_lantern 0  
fill ~26 ~9 ~17 ~26 ~10 ~17 quartz_block 0  
fill ~26 ~9 ~80 ~26 ~10 ~80 sea_lantern 0  
fill ~26 ~9 ~81 ~26 ~10 ~81 quartz_block 0 
setblock ~29 ~9 ~34 quartz_block 0 
setblock ~29 ~9 ~35 quartz_stairs 3 
setblock ~29 ~9 ~61 quartz_stairs 2 
setblock ~29 ~9 ~62 quartz_block 0 
setblock ~31 ~9 ~34 quartz_block 1  
fill ~31 ~9 ~35 ~35 ~9 ~35 stained_hardened_clay 10  
fill ~31 ~9 ~61 ~35 ~9 ~61 stained_hardened_clay 10 
setblock ~31 ~9 ~62 quartz_block 1 
setblock ~35 ~9 ~34 quartz_block 1 
setblock ~35 ~9 ~62 quartz_block 1  
fill ~36 ~9 ~35 ~39 ~9 ~35 stained_glass 0  
fill ~36 ~9 ~61 ~39 ~9 ~61 stained_glass 0 
setblock ~40 ~9 ~34 quartz_block 1  
fill ~40 ~9 ~35 ~44 ~9 ~35 stained_hardened_clay 10  
fill ~40 ~9 ~61 ~44 ~9 ~61 stained_hardened_clay 10 
setblock ~40 ~9 ~62 quartz_block 1 
setblock ~44 ~9 ~34 quartz_block 1 
setblock ~44 ~9 ~62 quartz_block 1 
setblock ~46 ~9 ~34 quartz_block 0 
setblock ~46 ~9 ~35 quartz_stairs 3 
setblock ~46 ~9 ~61 quartz_stairs 2 
setblock ~46 ~9 ~62 quartz_block 0 
setblock ~50 ~9 ~14 quartz_block 0 
setblock ~50 ~9 ~15 sea_lantern 0  
fill ~50 ~9 ~16 ~50 ~9 ~17 quartz_block 0  
fill ~50 ~9 ~20 ~51 ~9 ~20 quartz_block 0  
fill ~50 ~9 ~21 ~51 ~9 ~21 sea_lantern 0  
fill ~50 ~9 ~22 ~51 ~9 ~22 quartz_block 0  
fill ~50 ~9 ~29 ~56 ~9 ~29 stone_slab 7  
fill ~50 ~9 ~67 ~56 ~9 ~67 stone_slab 7  
fill ~50 ~9 ~74 ~51 ~9 ~74 quartz_block 0  
fill ~50 ~9 ~75 ~51 ~9 ~75 sea_lantern 0  
fill ~50 ~9 ~76 ~51 ~9 ~76 quartz_block 0  
fill ~50 ~9 ~79 ~51 ~9 ~79 quartz_block 0  
fill ~50 ~9 ~80 ~50 ~9 ~79 quartz_block 0 
setblock ~50 ~9 ~81 sea_lantern 0 
setblock ~50 ~9 ~82 quartz_block 0  
fill ~51 ~9 ~15 ~51 ~10 ~15 quartz_block 0  
fill ~51 ~9 ~16 ~51 ~10 ~16 sea_lantern 0  
fill ~51 ~9 ~17 ~51 ~10 ~17 quartz_block 0  
fill ~51 ~9 ~30 ~75 ~9 ~30 stonebrick 0  
fill ~51 ~9 ~66 ~75 ~9 ~66 stonebrick 0  
fill ~51 ~9 ~80 ~51 ~10 ~80 sea_lantern 0  
fill ~51 ~9 ~81 ~51 ~10 ~81 quartz_block 0  
fill ~60 ~9 ~29 ~66 ~9 ~29 stone_slab 7  
fill ~60 ~9 ~67 ~66 ~9 ~67 stone_slab 7  
fill ~70 ~9 ~29 ~76 ~9 ~29 stone_slab 7  
fill ~70 ~9 ~67 ~76 ~9 ~67 stone_slab 7  
fill ~75 ~9 ~15 ~75 ~10 ~15 quartz_block 0  
fill ~75 ~9 ~16 ~75 ~10 ~16 sea_lantern 0  
fill ~75 ~9 ~17 ~76 ~9 ~17 quartz_block 0  
fill ~75 ~9 ~20 ~76 ~9 ~20 quartz_block 0  
fill ~75 ~9 ~21 ~76 ~9 ~21 sea_lantern 0  
fill ~75 ~9 ~22 ~76 ~9 ~22 quartz_block 0  
fill ~75 ~9 ~74 ~76 ~9 ~74 quartz_block 0  
fill ~75 ~9 ~75 ~76 ~9 ~75 sea_lantern 0  
fill ~75 ~9 ~76 ~76 ~9 ~76 quartz_block 0  
fill ~75 ~9 ~79 ~76 ~9 ~79 quartz_block 0  
fill ~75 ~9 ~80 ~75 ~10 ~80 sea_lantern 0  
fill ~75 ~9 ~81 ~75 ~10 ~81 quartz_block 0 
setblock ~76 ~9 ~14 quartz_block 0 
setblock ~76 ~9 ~15 sea_lantern 0 
setblock ~76 ~9 ~16 quartz_block 0 
setblock ~76 ~9 ~80 quartz_block 0 
setblock ~76 ~9 ~81 sea_lantern 0 
setblock ~76 ~9 ~82 quartz_block 0 
