fill ~1 ~0 ~1 ~2 ~0 ~1 stone 0  
fill ~1 ~0 ~2 ~1 ~0 ~1 stone 0 
setblock ~11 ~0 ~31 stonebrick 0 
setblock ~12 ~0 ~30 stonebrick 0 
setblock ~12 ~0 ~31 diamond_block 0 
setblock ~12 ~0 ~32 stonebrick 0  
fill ~13 ~0 ~29 ~14 ~0 ~29 stonebrick 0  
fill ~13 ~0 ~30 ~14 ~0 ~30 diamond_block 0  
fill ~13 ~0 ~31 ~14 ~0 ~31 stonebrick 0  
fill ~13 ~0 ~32 ~14 ~0 ~32 diamond_block 0  
fill ~13 ~0 ~33 ~14 ~0 ~33 stonebrick 0 
setblock ~15 ~0 ~28 stonebrick 0  
fill ~15 ~0 ~29 ~16 ~0 ~29 diamond_block 0 
setblock ~15 ~0 ~30 stonebrick 0 
setblock ~15 ~0 ~31 gold_block 0 
setblock ~15 ~0 ~32 stonebrick 0  
fill ~15 ~0 ~33 ~16 ~0 ~33 diamond_block 0 
setblock ~15 ~0 ~34 stonebrick 0 
setblock ~16 ~0 ~28 stonebrick 1 
setblock ~16 ~0 ~30 gold_block 0 
setblock ~16 ~0 ~31 stonebrick 1 
setblock ~16 ~0 ~32 gold_block 0 
setblock ~16 ~0 ~34 stonebrick 1  
fill ~17 ~0 ~27 ~18 ~0 ~27 stonebrick 1  
fill ~17 ~0 ~28 ~18 ~0 ~28 diamond_block 0 
setblock ~17 ~0 ~29 gold_block 0 
setblock ~17 ~0 ~30 stonebrick 1 
setblock ~17 ~0 ~31 stonebrick 0  
fill ~17 ~0 ~32 ~18 ~0 ~32 stonebrick 2 
setblock ~17 ~0 ~33 gold_block 0  
fill ~17 ~0 ~34 ~18 ~0 ~34 diamond_block 0 
setblock ~17 ~0 ~35 stonebrick 0  
fill ~18 ~0 ~29 ~19 ~0 ~29 stonebrick 2 
setblock ~18 ~0 ~30 stonebrick 0  
fill ~18 ~0 ~31 ~19 ~0 ~31 stonebrick 1 
setblock ~18 ~0 ~33 stonebrick 2 
setblock ~18 ~0 ~35 stonebrick 2 
setblock ~19 ~0 ~26 stonebrick 2  
fill ~19 ~0 ~27 ~20 ~0 ~27 diamond_block 0 
setblock ~19 ~0 ~28 stonebrick 2 
setblock ~19 ~0 ~30 stonebrick 2  
fill ~19 ~0 ~32 ~21 ~0 ~32 stonebrick 1  
fill ~19 ~0 ~33 ~19 ~0 ~34 stonebrick 0  
fill ~19 ~0 ~35 ~20 ~0 ~35 diamond_block 0 
setblock ~19 ~0 ~36 stonebrick 1 
setblock ~20 ~0 ~25 stonebrick 1 
setblock ~20 ~0 ~26 gold_block 0 
setblock ~20 ~0 ~28 stonebrick 1  
fill ~20 ~0 ~29 ~20 ~0 ~30 stonebrick 0 
setblock ~20 ~0 ~31 stonebrick 2  
fill ~20 ~0 ~33 ~21 ~0 ~33 stonebrick 2  
fill ~20 ~0 ~34 ~20 ~0 ~33 stonebrick 2 
setblock ~20 ~0 ~36 gold_block 0 
setblock ~20 ~0 ~37 stonebrick 0 
setblock ~21 ~0 ~24 stonebrick 2 
setblock ~21 ~0 ~25 gold_block 0  
fill ~21 ~0 ~26 ~22 ~0 ~26 diamond_block 0  
fill ~21 ~0 ~27 ~22 ~0 ~27 stonebrick 1  
fill ~21 ~0 ~28 ~22 ~0 ~28 stonebrick 2  
fill ~21 ~0 ~29 ~21 ~0 ~28 stonebrick 2  
fill ~21 ~0 ~30 ~23 ~0 ~30 stonebrick 1 
setblock ~21 ~0 ~31 stonebrick 0 
setblock ~21 ~0 ~34 stonebrick 0 
setblock ~21 ~0 ~35 stonebrick 2  
fill ~21 ~0 ~36 ~22 ~0 ~36 diamond_block 0 
setblock ~21 ~0 ~37 gold_block 0 
setblock ~21 ~0 ~38 stonebrick 0 
setblock ~22 ~0 ~24 stonebrick 0 
setblock ~22 ~0 ~25 stonebrick 2  
fill ~22 ~0 ~29 ~23 ~0 ~29 stonebrick 1 
setblock ~22 ~0 ~31 stonebrick 2  
fill ~22 ~0 ~32 ~22 ~0 ~33 stonebrick 0 
setblock ~22 ~0 ~34 stonebrick 1 
setblock ~22 ~0 ~35 stonebrick 0  
fill ~22 ~0 ~37 ~26 ~0 ~37 stonebrick 1  
fill ~22 ~0 ~38 ~22 ~0 ~37 stonebrick 1 
setblock ~23 ~0 ~23 stonebrick 1  
fill ~23 ~0 ~24 ~24 ~0 ~24 stonebrick 2  
fill ~23 ~0 ~25 ~23 ~0 ~26 stonebrick 0 
setblock ~23 ~0 ~27 stonebrick 2 
setblock ~23 ~0 ~28 stonebrick 0 
setblock ~23 ~0 ~31 diamond_block 0 
setblock ~23 ~0 ~32 stonebrick 1 
setblock ~23 ~0 ~33 stonebrick 0 
setblock ~23 ~0 ~34 stonebrick 2  
fill ~23 ~0 ~35 ~24 ~0 ~35 stonebrick 1  
fill ~23 ~0 ~36 ~24 ~0 ~36 stonebrick 0 
setblock ~23 ~0 ~38 stonebrick 2 
setblock ~23 ~0 ~39 stonebrick 0  
fill ~24 ~0 ~21 ~24 ~0 ~22 stonebrick 1 
setblock ~24 ~0 ~23 stonebrick 0  
fill ~24 ~0 ~25 ~26 ~0 ~25 stonebrick 1  
fill ~24 ~0 ~26 ~24 ~0 ~27 stonebrick 0  
fill ~24 ~0 ~28 ~24 ~0 ~29 stonebrick 2 
setblock ~24 ~0 ~30 diamond_block 0 
setblock ~24 ~0 ~31 stonebrick 1 
setblock ~24 ~0 ~32 diamond_block 0  
fill ~24 ~0 ~33 ~24 ~0 ~35 stonebrick 1  
fill ~24 ~0 ~38 ~25 ~0 ~38 stonebrick 1 
setblock ~24 ~0 ~39 stonebrick 2  
fill ~24 ~0 ~40 ~25 ~0 ~40 stonebrick 1 
setblock ~24 ~0 ~41 stonebrick 0 
setblock ~25 ~0 ~20 stonebrick 0 
setblock ~25 ~0 ~21 gold_block 0 
setblock ~25 ~0 ~22 stonebrick 2  
fill ~25 ~0 ~23 ~25 ~0 ~25 stonebrick 1  
fill ~25 ~0 ~26 ~26 ~0 ~26 stonebrick 2  
fill ~25 ~0 ~27 ~26 ~0 ~27 stonebrick 2  
fill ~25 ~0 ~28 ~26 ~0 ~28 stonebrick 0  
fill ~25 ~0 ~29 ~25 ~0 ~30 stonebrick 0  
fill ~25 ~0 ~31 ~26 ~0 ~31 gold_block 0  
fill ~25 ~0 ~32 ~25 ~0 ~33 stonebrick 0  
fill ~25 ~0 ~34 ~25 ~0 ~36 stonebrick 2 
setblock ~25 ~0 ~39 stonebrick 0 
setblock ~25 ~0 ~41 gold_block 0 
setblock ~25 ~0 ~42 stonebrick 1 
setblock ~26 ~0 ~19 stonebrick 0 
setblock ~26 ~0 ~20 gold_block 0  
fill ~26 ~0 ~21 ~26 ~0 ~22 diamond_block 0  
fill ~26 ~0 ~23 ~27 ~0 ~23 stonebrick 2 
setblock ~26 ~0 ~24 stonebrick 1 
setblock ~26 ~0 ~29 stonebrick 2 
setblock ~26 ~0 ~30 stonebrick 0 
setblock ~26 ~0 ~32 stonebrick 1  
fill ~26 ~0 ~33 ~27 ~0 ~33 stonebrick 2  
fill ~26 ~0 ~34 ~27 ~0 ~34 stonebrick 0 
setblock ~26 ~0 ~35 stonebrick 1  
fill ~26 ~0 ~36 ~29 ~0 ~36 stonebrick 0 
setblock ~26 ~0 ~38 stonebrick 2  
fill ~26 ~0 ~39 ~27 ~0 ~39 stonebrick 1  
fill ~26 ~0 ~40 ~26 ~0 ~41 diamond_block 0 
setblock ~26 ~0 ~42 gold_block 0 
setblock ~26 ~0 ~43 stonebrick 2 
setblock ~27 ~0 ~17 stonebrick 2 
setblock ~27 ~0 ~18 stonebrick 1  
fill ~27 ~0 ~19 ~27 ~0 ~20 diamond_block 0 
setblock ~27 ~0 ~21 stonebrick 0  
fill ~27 ~0 ~22 ~29 ~0 ~22 stonebrick 2  
fill ~27 ~0 ~24 ~29 ~0 ~24 stonebrick 0  
fill ~27 ~0 ~25 ~27 ~0 ~24 stonebrick 0  
fill ~27 ~0 ~26 ~28 ~0 ~26 stonebrick 1 
setblock ~27 ~0 ~27 stonebrick 0  
fill ~27 ~0 ~28 ~28 ~0 ~28 stonebrick 2 
setblock ~27 ~0 ~29 stonebrick 1  
fill ~27 ~0 ~30 ~29 ~0 ~30 stonebrick 2  
fill ~27 ~0 ~31 ~28 ~0 ~31 stonebrick 0 
setblock ~27 ~0 ~32 stonebrick 2 
setblock ~27 ~0 ~35 stonebrick 2 
setblock ~27 ~0 ~37 stonebrick 2 
setblock ~27 ~0 ~38 stonebrick 1  
fill ~27 ~0 ~40 ~28 ~0 ~40 stonebrick 2 
setblock ~27 ~0 ~41 stonebrick 0  
fill ~27 ~0 ~42 ~27 ~0 ~43 diamond_block 0 
setblock ~27 ~0 ~44 stonebrick 1 
setblock ~27 ~0 ~45 stonebrick 0 
setblock ~28 ~0 ~15 stonebrick 0 
setblock ~28 ~0 ~16 stonebrick 2  
fill ~28 ~0 ~17 ~28 ~0 ~18 diamond_block 0  
fill ~28 ~0 ~19 ~28 ~0 ~20 stonebrick 1  
fill ~28 ~0 ~21 ~30 ~0 ~21 stonebrick 2  
fill ~28 ~0 ~23 ~30 ~0 ~23 stonebrick 0 
setblock ~28 ~0 ~25 stonebrick 1 
setblock ~28 ~0 ~27 stonebrick 1 
setblock ~28 ~0 ~29 stonebrick 0 
setblock ~28 ~0 ~32 stonebrick 1  
fill ~28 ~0 ~33 ~29 ~0 ~33 stonebrick 0 
setblock ~28 ~0 ~34 stonebrick 2 
setblock ~28 ~0 ~35 stonebrick 1 
setblock ~28 ~0 ~37 stonebrick 1  
fill ~28 ~0 ~38 ~28 ~0 ~39 stonebrick 0  
fill ~28 ~0 ~41 ~29 ~0 ~41 stonebrick 2  
fill ~28 ~0 ~42 ~30 ~0 ~42 stonebrick 2  
fill ~28 ~0 ~43 ~29 ~0 ~43 stonebrick 0  
fill ~28 ~0 ~44 ~28 ~0 ~45 diamond_block 0 
setblock ~28 ~0 ~46 stonebrick 2 
setblock ~28 ~0 ~47 stonebrick 0  
fill ~29 ~0 ~13 ~29 ~0 ~14 stonebrick 0  
fill ~29 ~0 ~15 ~29 ~0 ~16 diamond_block 0 
setblock ~29 ~0 ~17 gold_block 0  
fill ~29 ~0 ~18 ~29 ~0 ~22 stonebrick 2 
setblock ~29 ~0 ~25 stonebrick 0  
fill ~29 ~0 ~26 ~29 ~0 ~27 stonebrick 2 
setblock ~29 ~0 ~28 stonebrick 0 
setblock ~29 ~0 ~29 stonebrick 1  
fill ~29 ~0 ~31 ~30 ~0 ~31 stonebrick 1 
setblock ~29 ~0 ~32 stonebrick 0 
setblock ~29 ~0 ~34 stonebrick 1 
setblock ~29 ~0 ~35 stonebrick 0  
fill ~29 ~0 ~37 ~29 ~0 ~38 stonebrick 2  
fill ~29 ~0 ~39 ~30 ~0 ~39 stonebrick 1  
fill ~29 ~0 ~40 ~30 ~0 ~40 stonebrick 1  
fill ~29 ~0 ~44 ~30 ~0 ~44 stonebrick 2 
setblock ~29 ~0 ~45 gold_block 0  
fill ~29 ~0 ~46 ~29 ~0 ~47 diamond_block 0  
fill ~29 ~0 ~48 ~29 ~0 ~49 stonebrick 0 
setblock ~30 ~0 ~12 stonebrick 0  
fill ~30 ~0 ~13 ~30 ~0 ~14 diamond_block 0 
setblock ~30 ~0 ~15 stonebrick 0 
setblock ~30 ~0 ~16 gold_block 0 
setblock ~30 ~0 ~17 stonebrick 2 
setblock ~30 ~0 ~18 stonebrick 1  
fill ~30 ~0 ~19 ~30 ~0 ~21 stonebrick 2  
fill ~30 ~0 ~22 ~32 ~0 ~22 stonebrick 1 
setblock ~30 ~0 ~24 diamond_block 0 
setblock ~30 ~0 ~25 stonebrick 2 
setblock ~30 ~0 ~26 stonebrick 1  
fill ~30 ~0 ~27 ~35 ~0 ~27 stonebrick 0  
fill ~30 ~0 ~28 ~32 ~0 ~28 stonebrick 1  
fill ~30 ~0 ~29 ~32 ~0 ~29 stonebrick 2 
setblock ~30 ~0 ~30 stonebrick 1 
setblock ~30 ~0 ~32 stonebrick 1  
fill ~30 ~0 ~33 ~31 ~0 ~33 stonebrick 2  
fill ~30 ~0 ~34 ~31 ~0 ~34 stonebrick 0  
fill ~30 ~0 ~35 ~30 ~0 ~36 stonebrick 2 
setblock ~30 ~0 ~37 stonebrick 0 
setblock ~30 ~0 ~38 diamond_block 0 
setblock ~30 ~0 ~41 stonebrick 1 
setblock ~30 ~0 ~43 stonebrick 2  
fill ~30 ~0 ~45 ~31 ~0 ~45 stonebrick 2 
setblock ~30 ~0 ~46 gold_block 0 
setblock ~30 ~0 ~47 stonebrick 1  
fill ~30 ~0 ~48 ~30 ~0 ~49 diamond_block 0 
setblock ~30 ~0 ~50 stonebrick 0 
setblock ~31 ~0 ~11 stonebrick 0 
setblock ~31 ~0 ~12 diamond_block 0  
fill ~31 ~0 ~13 ~31 ~0 ~14 stonebrick 0 
setblock ~31 ~0 ~15 gold_block 0 
setblock ~31 ~0 ~16 stonebrick 1  
fill ~31 ~0 ~17 ~31 ~0 ~19 stonebrick 0  
fill ~31 ~0 ~20 ~31 ~0 ~22 stonebrick 1 
setblock ~31 ~0 ~23 diamond_block 0 
setblock ~31 ~0 ~24 stonebrick 2  
fill ~31 ~0 ~25 ~31 ~0 ~26 gold_block 0  
fill ~31 ~0 ~30 ~32 ~0 ~30 stonebrick 2  
fill ~31 ~0 ~31 ~31 ~0 ~32 stonebrick 0 
setblock ~31 ~0 ~35 stonebrick 0  
fill ~31 ~0 ~36 ~31 ~0 ~37 gold_block 0 
setblock ~31 ~0 ~38 stonebrick 1 
setblock ~31 ~0 ~39 diamond_block 0  
fill ~31 ~0 ~40 ~31 ~0 ~41 stonebrick 2 
setblock ~31 ~0 ~42 stonebrick 1  
fill ~31 ~0 ~43 ~33 ~0 ~43 stonebrick 0 
setblock ~31 ~0 ~44 stonebrick 1 
setblock ~31 ~0 ~46 stonebrick 0 
setblock ~31 ~0 ~47 gold_block 0  
fill ~31 ~0 ~48 ~31 ~0 ~49 stonebrick 0 
setblock ~31 ~0 ~50 diamond_block 0 
setblock ~31 ~0 ~51 stonebrick 0 
setblock ~32 ~0 ~12 stonebrick 0  
fill ~32 ~0 ~13 ~32 ~0 ~14 diamond_block 0 
setblock ~32 ~0 ~15 stonebrick 0 
setblock ~32 ~0 ~16 gold_block 0 
setblock ~32 ~0 ~17 stonebrick 2 
setblock ~32 ~0 ~18 stonebrick 0 
setblock ~32 ~0 ~19 stonebrick 1  
fill ~32 ~0 ~20 ~32 ~0 ~21 stonebrick 0 
setblock ~32 ~0 ~23 stonebrick 1 
setblock ~32 ~0 ~24 diamond_block 0 
setblock ~32 ~0 ~25 stonebrick 0 
setblock ~32 ~0 ~26 stonebrick 1  
fill ~32 ~0 ~31 ~35 ~0 ~31 stonebrick 2  
fill ~32 ~0 ~32 ~32 ~0 ~29 stonebrick 2 
setblock ~32 ~0 ~33 stonebrick 1  
fill ~32 ~0 ~34 ~32 ~1 ~34 stonebrick 2  
fill ~32 ~0 ~35 ~33 ~0 ~35 stonebrick 1  
fill ~32 ~0 ~36 ~32 ~0 ~35 stonebrick 1 
setblock ~32 ~0 ~37 stonebrick 2 
setblock ~32 ~0 ~38 diamond_block 0 
setblock ~32 ~0 ~39 stonebrick 2 
setblock ~32 ~0 ~40 stonebrick 1  
fill ~32 ~0 ~41 ~32 ~0 ~43 stonebrick 0 
setblock ~32 ~0 ~44 stonebrick 2 
setblock ~32 ~0 ~45 stonebrick 1 
setblock ~32 ~0 ~46 gold_block 0 
setblock ~32 ~0 ~47 stonebrick 1  
fill ~32 ~0 ~48 ~32 ~0 ~49 diamond_block 0 
setblock ~32 ~0 ~50 stonebrick 0  
fill ~33 ~0 ~13 ~33 ~0 ~14 stonebrick 0  
fill ~33 ~0 ~15 ~33 ~0 ~16 diamond_block 0 
setblock ~33 ~0 ~17 gold_block 0 
setblock ~33 ~0 ~18 stonebrick 1 
setblock ~33 ~0 ~19 stonebrick 0 
setblock ~33 ~0 ~20 stonebrick 2 
setblock ~33 ~0 ~21 stonebrick 0  
fill ~33 ~0 ~22 ~34 ~0 ~22 stonebrick 2 
setblock ~33 ~0 ~23 stonebrick 0  
fill ~33 ~0 ~24 ~34 ~0 ~24 stonebrick 1  
fill ~33 ~0 ~25 ~33 ~0 ~24 stonebrick 1 
setblock ~33 ~0 ~26 stonebrick 2 
setblock ~33 ~0 ~28 stonebrick 2 
setblock ~33 ~0 ~29 stonebrick 0 
setblock ~33 ~0 ~30 stonebrick 1 
setblock ~33 ~0 ~32 stonebrick 1 
setblock ~33 ~0 ~33 stonebrick 2  
fill ~33 ~0 ~34 ~34 ~0 ~34 stonebrick 1  
fill ~33 ~0 ~36 ~34 ~0 ~36 stonebrick 0  
fill ~33 ~0 ~37 ~33 ~0 ~38 stonebrick 1 
setblock ~33 ~0 ~39 stonebrick 0 
setblock ~33 ~0 ~40 stonebrick 2  
fill ~33 ~0 ~41 ~34 ~0 ~41 stonebrick 1  
fill ~33 ~0 ~42 ~34 ~0 ~42 stonebrick 0 
setblock ~33 ~0 ~44 stonebrick 0 
setblock ~33 ~0 ~45 gold_block 0  
fill ~33 ~0 ~46 ~33 ~0 ~47 diamond_block 0  
fill ~33 ~0 ~48 ~33 ~0 ~49 stonebrick 0  
fill ~34 ~0 ~15 ~34 ~0 ~16 stonebrick 0  
fill ~34 ~0 ~17 ~34 ~0 ~18 diamond_block 0  
fill ~34 ~0 ~19 ~34 ~0 ~20 stonebrick 1 
setblock ~34 ~0 ~21 stonebrick 2 
setblock ~34 ~0 ~23 stonebrick 2  
fill ~34 ~0 ~25 ~35 ~0 ~25 stonebrick 0 
setblock ~34 ~0 ~26 stonebrick 1 
setblock ~34 ~0 ~28 stonebrick 1  
fill ~34 ~0 ~29 ~35 ~0 ~29 stonebrick 2 
setblock ~34 ~0 ~30 stonebrick 0  
fill ~34 ~0 ~32 ~34 ~0 ~33 stonebrick 0 
setblock ~34 ~0 ~35 stonebrick 2 
setblock ~34 ~0 ~37 stonebrick 2 
setblock ~34 ~0 ~38 stonebrick 0  
fill ~34 ~0 ~39 ~35 ~0 ~39 stonebrick 1  
fill ~34 ~0 ~40 ~34 ~0 ~39 stonebrick 1 
setblock ~34 ~0 ~43 stonebrick 2  
fill ~34 ~0 ~44 ~34 ~0 ~45 diamond_block 0  
fill ~34 ~0 ~46 ~34 ~0 ~47 stonebrick 2 
setblock ~35 ~0 ~17 stonebrick 2 
setblock ~35 ~0 ~18 stonebrick 0  
fill ~35 ~0 ~19 ~35 ~0 ~20 diamond_block 0 
setblock ~35 ~0 ~21 stonebrick 1  
fill ~35 ~0 ~22 ~35 ~0 ~23 stonebrick 0 
setblock ~35 ~0 ~24 stonebrick 2 
setblock ~35 ~0 ~26 stonebrick 2  
fill ~35 ~0 ~28 ~36 ~0 ~28 stonebrick 0 
setblock ~35 ~0 ~30 stonebrick 2  
fill ~35 ~0 ~32 ~35 ~0 ~33 stonebrick 2  
fill ~35 ~0 ~34 ~36 ~0 ~34 stonebrick 0  
fill ~35 ~0 ~35 ~35 ~0 ~34 stonebrick 0  
fill ~35 ~0 ~36 ~39 ~0 ~36 stonebrick 2  
fill ~35 ~0 ~37 ~36 ~0 ~37 stonebrick 1  
fill ~35 ~0 ~38 ~36 ~0 ~38 stonebrick 1 
setblock ~35 ~0 ~40 stonebrick 2 
setblock ~35 ~0 ~41 stonebrick 0  
fill ~35 ~0 ~42 ~35 ~0 ~43 diamond_block 0 
setblock ~35 ~0 ~44 stonebrick 1 
setblock ~35 ~0 ~45 stonebrick 2 
setblock ~36 ~0 ~19 stonebrick 0 
setblock ~36 ~0 ~20 gold_block 0  
fill ~36 ~0 ~21 ~36 ~0 ~22 diamond_block 0  
fill ~36 ~0 ~23 ~38 ~0 ~23 stonebrick 1 
setblock ~36 ~0 ~24 stonebrick 0 
setblock ~36 ~0 ~25 stonebrick 1 
setblock ~36 ~0 ~26 stonebrick 0 
setblock ~36 ~0 ~27 stonebrick 1  
fill ~36 ~0 ~29 ~36 ~0 ~30 stonebrick 0  
fill ~36 ~0 ~31 ~37 ~0 ~31 gold_block 0  
fill ~36 ~0 ~32 ~36 ~0 ~34 stonebrick 0 
setblock ~36 ~0 ~35 stonebrick 2 
setblock ~36 ~0 ~39 stonebrick 0  
fill ~36 ~0 ~40 ~36 ~0 ~41 diamond_block 0 
setblock ~36 ~0 ~42 gold_block 0 
setblock ~36 ~0 ~43 stonebrick 1 
setblock ~37 ~0 ~20 stonebrick 1 
setblock ~37 ~0 ~21 gold_block 0 
setblock ~37 ~0 ~22 stonebrick 1 
setblock ~37 ~0 ~24 stonebrick 1 
setblock ~37 ~0 ~25 stonebrick 0  
fill ~37 ~0 ~26 ~37 ~0 ~28 stonebrick 2  
fill ~37 ~0 ~29 ~39 ~0 ~29 stonebrick 1 
setblock ~37 ~0 ~30 stonebrick 2 
setblock ~37 ~0 ~32 stonebrick 2  
fill ~37 ~0 ~33 ~39 ~0 ~33 stonebrick 0  
fill ~37 ~0 ~34 ~41 ~0 ~34 stonebrick 1 
setblock ~37 ~0 ~35 stonebrick 0  
fill ~37 ~0 ~37 ~40 ~0 ~37 stonebrick 0  
fill ~37 ~0 ~38 ~38 ~0 ~38 stonebrick 0  
fill ~37 ~0 ~39 ~38 ~0 ~39 stonebrick 2 
setblock ~37 ~0 ~40 stonebrick 0 
setblock ~37 ~0 ~41 gold_block 0 
setblock ~37 ~0 ~42 stonebrick 1  
fill ~38 ~0 ~21 ~38 ~0 ~22 stonebrick 2 
setblock ~38 ~0 ~24 stonebrick 0 
setblock ~38 ~0 ~25 stonebrick 2  
fill ~38 ~0 ~26 ~39 ~0 ~26 stonebrick 0  
fill ~38 ~0 ~27 ~38 ~0 ~28 stonebrick 2 
setblock ~38 ~0 ~30 diamond_block 0 
setblock ~38 ~0 ~31 stonebrick 1 
setblock ~38 ~0 ~32 diamond_block 0  
fill ~38 ~0 ~35 ~39 ~0 ~35 stonebrick 2 
setblock ~38 ~0 ~40 stonebrick 2 
setblock ~38 ~0 ~41 stonebrick 0 
setblock ~39 ~0 ~23 stonebrick 0  
fill ~39 ~0 ~24 ~41 ~0 ~24 stonebrick 1  
fill ~39 ~0 ~25 ~40 ~0 ~25 stonebrick 1 
setblock ~39 ~0 ~27 stonebrick 0 
setblock ~39 ~0 ~28 stonebrick 2 
setblock ~39 ~0 ~30 stonebrick 2 
setblock ~39 ~0 ~31 diamond_block 0 
setblock ~39 ~0 ~32 stonebrick 1 
setblock ~39 ~0 ~38 stonebrick 2 
setblock ~39 ~0 ~39 stonebrick 1  
fill ~40 ~0 ~26 ~41 ~0 ~26 diamond_block 0 
setblock ~40 ~0 ~27 stonebrick 2 
setblock ~40 ~0 ~28 stonebrick 1  
fill ~40 ~0 ~29 ~40 ~0 ~30 stonebrick 0  
fill ~40 ~0 ~31 ~41 ~0 ~31 stonebrick 1  
fill ~40 ~0 ~32 ~40 ~0 ~33 stonebrick 2  
fill ~40 ~0 ~35 ~41 ~0 ~35 stonebrick 1  
fill ~40 ~0 ~36 ~41 ~0 ~36 diamond_block 0  
fill ~40 ~0 ~38 ~41 ~0 ~38 stonebrick 1 
setblock ~41 ~0 ~25 gold_block 0 
setblock ~41 ~0 ~27 stonebrick 0  
fill ~41 ~0 ~28 ~42 ~0 ~28 stonebrick 2  
fill ~41 ~0 ~29 ~42 ~0 ~29 stonebrick 1  
fill ~41 ~0 ~30 ~41 ~0 ~29 stonebrick 1 
setblock ~41 ~0 ~32 stonebrick 0 
setblock ~41 ~0 ~33 stonebrick 2 
setblock ~41 ~0 ~37 gold_block 0 
setblock ~42 ~0 ~25 stonebrick 2 
setblock ~42 ~0 ~26 gold_block 0  
fill ~42 ~0 ~27 ~43 ~0 ~27 diamond_block 0  
fill ~42 ~0 ~30 ~42 ~0 ~31 stonebrick 0  
fill ~42 ~0 ~32 ~42 ~0 ~33 stonebrick 1 
setblock ~42 ~0 ~34 stonebrick 2  
fill ~42 ~0 ~35 ~43 ~0 ~35 diamond_block 0 
setblock ~42 ~0 ~36 gold_block 0 
setblock ~42 ~0 ~37 stonebrick 2 
setblock ~43 ~0 ~26 stonebrick 2 
setblock ~43 ~0 ~28 stonebrick 1 
setblock ~43 ~0 ~29 stonebrick 2  
fill ~43 ~0 ~30 ~43 ~0 ~31 stonebrick 1 
setblock ~43 ~0 ~32 stonebrick 0 
setblock ~43 ~0 ~33 stonebrick 2 
setblock ~43 ~0 ~34 stonebrick 0 
setblock ~43 ~0 ~36 stonebrick 0 
setblock ~44 ~0 ~27 stonebrick 0  
fill ~44 ~0 ~28 ~45 ~0 ~28 diamond_block 0 
setblock ~44 ~0 ~29 stonebrick 1  
fill ~44 ~0 ~30 ~45 ~0 ~30 stonebrick 0 
setblock ~44 ~0 ~31 stonebrick 2 
setblock ~44 ~0 ~32 stonebrick 1 
setblock ~44 ~0 ~33 stonebrick 0  
fill ~44 ~0 ~34 ~45 ~0 ~34 diamond_block 0 
setblock ~44 ~0 ~35 stonebrick 2 
setblock ~45 ~0 ~27 stonebrick 1 
setblock ~45 ~0 ~29 gold_block 0  
fill ~45 ~0 ~31 ~45 ~0 ~32 stonebrick 0 
setblock ~45 ~0 ~33 gold_block 0 
setblock ~45 ~0 ~35 stonebrick 0  
fill ~46 ~0 ~28 ~47 ~0 ~28 stonebrick 0  
fill ~46 ~0 ~29 ~47 ~0 ~29 diamond_block 0 
setblock ~46 ~0 ~30 gold_block 0 
setblock ~46 ~0 ~31 stonebrick 1 
setblock ~46 ~0 ~32 gold_block 0  
fill ~46 ~0 ~33 ~47 ~0 ~33 diamond_block 0 
setblock ~46 ~0 ~34 stonebrick 1 
setblock ~47 ~0 ~30 stonebrick 0 
setblock ~47 ~0 ~31 gold_block 0 
setblock ~47 ~0 ~32 stonebrick 0 
setblock ~47 ~0 ~34 stonebrick 0  
fill ~48 ~0 ~29 ~49 ~0 ~29 stonebrick 0  
fill ~48 ~0 ~30 ~49 ~0 ~30 diamond_block 0  
fill ~48 ~0 ~31 ~49 ~0 ~31 stonebrick 0  
fill ~48 ~0 ~32 ~49 ~0 ~32 diamond_block 0  
fill ~48 ~0 ~33 ~49 ~0 ~33 stonebrick 0 
setblock ~50 ~0 ~30 stonebrick 0 
setblock ~50 ~0 ~31 diamond_block 0 
setblock ~50 ~0 ~32 stonebrick 0 
setblock ~51 ~0 ~31 stonebrick 0  
fill ~1 ~1 ~28 ~1 ~32 ~28 vine 8 
setblock ~6 ~1 ~32 yellow_flower 0  
fill ~8 ~1 ~37 ~9 ~1 ~37 yellow_flower 0 
setblock ~9 ~1 ~40 yellow_flower 0 
setblock ~10 ~1 ~29 red_flower 0 
setblock ~10 ~1 ~30 stonebrick 1  
fill ~10 ~1 ~31 ~10 ~2 ~31 glowstone 0 
setblock ~10 ~1 ~32 stonebrick 1 
setblock ~10 ~1 ~34 red_flower 0  
fill ~11 ~1 ~28 ~11 ~1 ~29 stonebrick 0 
setblock ~11 ~1 ~30 vine 4  
fill ~11 ~1 ~33 ~11 ~2 ~33 stonebrick 0  
fill ~11 ~1 ~34 ~11 ~2 ~34 stonebrick 0  
fill ~12 ~1 ~26 ~12 ~2 ~26 stonebrick 0 
setblock ~12 ~1 ~27 stonebrick 2  
fill ~12 ~1 ~28 ~12 ~2 ~28 vine 6  
fill ~12 ~1 ~29 ~12 ~2 ~29 vine 2  
fill ~12 ~1 ~34 ~12 ~2 ~34 vine 3  
fill ~12 ~1 ~35 ~12 ~1 ~36 stonebrick 1  
fill ~13 ~1 ~25 ~13 ~2 ~25 diamond_block 0  
fill ~13 ~1 ~27 ~13 ~2 ~27 vine 2  
fill ~13 ~1 ~35 ~13 ~2 ~35 vine 2  
fill ~13 ~1 ~36 ~13 ~2 ~36 vine 2  
fill ~13 ~1 ~37 ~13 ~2 ~37 diamond_block 0 
setblock ~13 ~1 ~48 yellow_flower 0 
setblock ~15 ~1 ~39 yellow_flower 0 
setblock ~15 ~1 ~42 yellow_flower 0  
fill ~19 ~1 ~38 ~20 ~1 ~38 yellow_flower 0  
fill ~19 ~1 ~39 ~19 ~1 ~38 yellow_flower 0 
setblock ~20 ~1 ~6 yellow_flower 0 
setblock ~20 ~1 ~45 yellow_flower 0  
fill ~20 ~1 ~48 ~20 ~1 ~49 red_flower 0 
setblock ~20 ~1 ~51 yellow_flower 0 
setblock ~21 ~1 ~40 red_flower 0 
setblock ~21 ~1 ~41 yellow_flower 0  
fill ~24 ~1 ~10 ~24 ~5 ~10 vine 8  
fill ~24 ~1 ~54 ~24 ~10 ~54 vine 8  
fill ~24 ~1 ~56 ~24 ~15 ~56 vine 8  
fill ~25 ~1 ~13 ~25 ~2 ~13 diamond_block 0  
fill ~25 ~1 ~49 ~25 ~2 ~49 diamond_block 0 
setblock ~26 ~1 ~7 yellow_flower 0 
setblock ~26 ~1 ~12 stonebrick 2 
setblock ~26 ~1 ~17 red_flower 0  
fill ~26 ~1 ~27 ~26 ~1 ~28 stone_brick_stairs 0  
fill ~26 ~1 ~34 ~26 ~1 ~35 stone_brick_stairs 0 
setblock ~26 ~1 ~48 red_flower 0  
fill ~26 ~1 ~50 ~26 ~2 ~50 stonebrick 2 
setblock ~26 ~1 ~53 yellow_flower 0  
fill ~26 ~1 ~58 ~26 ~15 ~58 vine 4 
setblock ~27 ~1 ~7 red_flower 0 
setblock ~27 ~1 ~12 stonebrick 0  
fill ~27 ~1 ~27 ~30 ~1 ~27 stone_slab 5  
fill ~27 ~1 ~28 ~28 ~1 ~28 glowstone 0  
fill ~27 ~1 ~34 ~28 ~1 ~34 glowstone 0  
fill ~27 ~1 ~35 ~30 ~1 ~35 stone_slab 5  
fill ~27 ~1 ~50 ~27 ~2 ~50 stonebrick 0 
setblock ~27 ~1 ~58 yellow_flower 0  
fill ~28 ~1 ~5 ~28 ~10 ~5 vine 1  
fill ~28 ~1 ~11 ~29 ~1 ~11 stonebrick 0  
fill ~28 ~1 ~12 ~28 ~2 ~12 vine 6  
fill ~28 ~1 ~51 ~28 ~2 ~51 stonebrick 2  
fill ~28 ~1 ~58 ~28 ~12 ~58 vine 4 
setblock ~29 ~1 ~9 yellow_flower 0  
fill ~29 ~1 ~12 ~29 ~53 ~12 vine 4  
fill ~29 ~1 ~28 ~29 ~4 ~28 diamond_block 0  
fill ~29 ~1 ~29 ~29 ~4 ~29 fence 0  
fill ~29 ~1 ~30 ~29 ~5 ~30 fence 0  
fill ~29 ~1 ~31 ~29 ~5 ~31 fence 0  
fill ~29 ~1 ~32 ~29 ~5 ~32 fence 0  
fill ~29 ~1 ~33 ~29 ~4 ~33 fence 0  
fill ~29 ~1 ~34 ~29 ~4 ~34 diamond_block 0 
setblock ~29 ~1 ~51 stonebrick 0  
fill ~29 ~1 ~58 ~29 ~12 ~58 vine 12 
setblock ~30 ~1 ~10 stonebrick 1  
fill ~30 ~1 ~28 ~30 ~4 ~28 stonebrick 0  
fill ~30 ~1 ~29 ~30 ~3 ~29 vine 4  
fill ~30 ~1 ~33 ~30 ~3 ~33 vine 1  
fill ~30 ~1 ~34 ~30 ~4 ~34 stonebrick 0  
fill ~30 ~1 ~51 ~32 ~1 ~51 vine 1  
fill ~30 ~1 ~52 ~30 ~2 ~52 stonebrick 0  
fill ~30 ~1 ~55 ~31 ~1 ~55 yellow_flower 0  
fill ~30 ~1 ~60 ~31 ~1 ~60 vine 4  
fill ~31 ~1 ~10 ~31 ~2 ~10 glowstone 0 
setblock ~31 ~1 ~27 stone_brick_stairs 2  
fill ~31 ~1 ~28 ~31 ~4 ~28 gold_block 0  
fill ~31 ~1 ~29 ~31 ~4 ~29 portal 0  
fill ~31 ~1 ~30 ~31 ~5 ~30 portal 0  
fill ~31 ~1 ~31 ~31 ~5 ~31 portal 0  
fill ~31 ~1 ~32 ~31 ~5 ~32 portal 0  
fill ~31 ~1 ~33 ~31 ~4 ~33 portal 0  
fill ~31 ~1 ~34 ~31 ~4 ~34 gold_block 0 
setblock ~31 ~1 ~35 stone_brick_stairs 3  
fill ~31 ~1 ~52 ~31 ~2 ~52 glowstone 0  
fill ~31 ~1 ~62 ~32 ~1 ~62 vine 4  
fill ~32 ~1 ~10 ~32 ~2 ~10 stonebrick 1  
fill ~32 ~1 ~27 ~35 ~1 ~27 stone_slab 5  
fill ~32 ~1 ~28 ~32 ~4 ~28 stonebrick 0  
fill ~32 ~1 ~29 ~32 ~4 ~29 vine 4  
fill ~32 ~1 ~35 ~35 ~1 ~35 stone_slab 5 
setblock ~32 ~1 ~52 stonebrick 1 
setblock ~33 ~1 ~11 stonebrick 1  
fill ~33 ~1 ~28 ~33 ~4 ~28 diamond_block 0  
fill ~33 ~1 ~29 ~33 ~4 ~29 fence 0  
fill ~33 ~1 ~30 ~33 ~5 ~30 fence 0  
fill ~33 ~1 ~31 ~33 ~5 ~31 fence 0  
fill ~33 ~1 ~32 ~33 ~5 ~32 fence 0  
fill ~33 ~1 ~33 ~33 ~4 ~33 fence 0  
fill ~33 ~1 ~34 ~33 ~4 ~34 diamond_block 0  
fill ~33 ~1 ~50 ~33 ~2 ~50 vine 1 
setblock ~33 ~1 ~51 stonebrick 1 
setblock ~33 ~1 ~57 yellow_flower 0 
setblock ~34 ~1 ~6 yellow_flower 0 
setblock ~34 ~1 ~10 yellow_flower 0 
setblock ~34 ~1 ~11 stonebrick 0  
fill ~34 ~1 ~28 ~35 ~1 ~28 glowstone 0  
fill ~34 ~1 ~34 ~35 ~1 ~34 glowstone 0 
setblock ~34 ~1 ~51 stonebrick 0 
setblock ~34 ~1 ~58 yellow_flower 0 
setblock ~35 ~1 ~5 yellow_flower 0 
setblock ~35 ~1 ~12 stonebrick 2 
setblock ~35 ~1 ~46 yellow_flower 0  
fill ~35 ~1 ~49 ~35 ~2 ~49 vine 1  
fill ~35 ~1 ~50 ~35 ~2 ~50 stonebrick 0 
setblock ~35 ~1 ~52 yellow_flower 0  
fill ~36 ~1 ~2 ~36 ~30 ~2 vine 1 
setblock ~36 ~1 ~12 stonebrick 1  
fill ~36 ~1 ~27 ~36 ~1 ~28 stone_brick_stairs 1  
fill ~36 ~1 ~34 ~36 ~1 ~35 stone_brick_stairs 1  
fill ~36 ~1 ~50 ~36 ~2 ~50 stonebrick 1  
fill ~37 ~1 ~9 ~37 ~5 ~9 vine 3  
fill ~37 ~1 ~13 ~37 ~2 ~13 diamond_block 0  
fill ~37 ~1 ~49 ~37 ~2 ~49 diamond_block 0  
fill ~37 ~1 ~59 ~37 ~26 ~59 vine 4 
setblock ~38 ~1 ~15 red_flower 0 
setblock ~39 ~1 ~15 yellow_flower 0 
setblock ~39 ~1 ~49 red_flower 0 
setblock ~40 ~1 ~8 red_flower 0 
setblock ~40 ~1 ~11 yellow_flower 0 
setblock ~40 ~1 ~42 red_flower 0 
setblock ~41 ~1 ~7 yellow_flower 0 
setblock ~41 ~1 ~16 yellow_flower 0 
setblock ~41 ~1 ~18 yellow_flower 0 
setblock ~41 ~1 ~44 yellow_flower 0 
setblock ~42 ~1 ~6 yellow_flower 0 
setblock ~42 ~1 ~13 yellow_flower 0 
setblock ~42 ~1 ~42 yellow_flower 0 
setblock ~43 ~1 ~50 yellow_flower 0  
fill ~44 ~1 ~11 ~45 ~1 ~11 yellow_flower 0 
setblock ~45 ~1 ~24 red_flower 0  
fill ~46 ~1 ~17 ~46 ~1 ~18 yellow_flower 0 
setblock ~46 ~1 ~27 red_flower 0 
setblock ~46 ~1 ~39 yellow_flower 0 
setblock ~47 ~1 ~20 yellow_flower 0 
setblock ~47 ~1 ~53 red_flower 0 
setblock ~48 ~1 ~21 red_flower 0 
setblock ~48 ~1 ~46 yellow_flower 0 
setblock ~48 ~1 ~47 red_flower 0  
fill ~49 ~1 ~25 ~49 ~2 ~25 diamond_block 0  
fill ~49 ~1 ~37 ~49 ~2 ~37 diamond_block 0 
setblock ~49 ~1 ~45 yellow_flower 0 
setblock ~50 ~1 ~26 stonebrick 1  
fill ~50 ~1 ~27 ~50 ~2 ~27 stonebrick 0  
fill ~50 ~1 ~29 ~50 ~2 ~29 vine 8  
fill ~50 ~1 ~35 ~50 ~2 ~35 stonebrick 0 
setblock ~50 ~1 ~36 stonebrick 2 
setblock ~50 ~1 ~39 yellow_flower 0  
fill ~51 ~1 ~28 ~51 ~1 ~29 stonebrick 1  
fill ~51 ~1 ~33 ~51 ~1 ~34 stonebrick 0 
setblock ~52 ~1 ~27 yellow_flower 0  
fill ~52 ~1 ~30 ~52 ~2 ~30 stonebrick 0  
fill ~52 ~1 ~31 ~52 ~2 ~31 glowstone 0 
setblock ~52 ~1 ~32 stonebrick 0 
setblock ~52 ~1 ~36 yellow_flower 0 
setblock ~53 ~1 ~24 yellow_flower 0  
fill ~54 ~1 ~26 ~54 ~6 ~26 vine 2 
setblock ~54 ~1 ~31 yellow_flower 0  
fill ~54 ~1 ~38 ~54 ~10 ~38 vine 4  
fill ~55 ~1 ~37 ~55 ~10 ~37 vine 4  
fill ~56 ~1 ~36 ~56 ~10 ~36 vine 2  
fill ~57 ~1 ~38 ~57 ~19 ~38 vine 4  
fill ~58 ~1 ~27 ~58 ~14 ~27 vine 2  
fill ~58 ~1 ~31 ~58 ~10 ~31 vine 2  
fill ~5 ~2 ~29 ~5 ~10 ~29 vine 1  
fill ~6 ~2 ~31 ~6 ~6 ~31 vine 8 
setblock ~10 ~2 ~30 stonebrick 0 
setblock ~10 ~2 ~32 stonebrick 2 
setblock ~11 ~2 ~28 stonebrick 1 
setblock ~11 ~2 ~29 stonebrick 0 
setblock ~12 ~2 ~27 stonebrick 0  
fill ~12 ~2 ~35 ~12 ~2 ~36 stonebrick 2 
setblock ~13 ~2 ~24 vine 1  
fill ~24 ~2 ~52 ~24 ~5 ~52 vine 8  
fill ~26 ~2 ~12 ~27 ~2 ~12 stonebrick 1  
fill ~27 ~2 ~8 ~27 ~6 ~8 vine 8  
fill ~27 ~2 ~27 ~27 ~2 ~28 stone_brick_stairs 0  
fill ~27 ~2 ~34 ~27 ~2 ~35 stone_brick_stairs 0  
fill ~28 ~2 ~11 ~29 ~2 ~11 stonebrick 0  
fill ~28 ~2 ~27 ~30 ~2 ~27 stone_slab 5 
setblock ~28 ~2 ~28 glowstone 0 
setblock ~28 ~2 ~34 glowstone 0  
fill ~28 ~2 ~35 ~30 ~2 ~35 stone_slab 5  
fill ~29 ~2 ~7 ~29 ~6 ~7 vine 8 
setblock ~29 ~2 ~51 stonebrick 2 
setblock ~30 ~2 ~10 stonebrick 2  
fill ~30 ~2 ~51 ~32 ~2 ~51 vine 1  
fill ~30 ~2 ~57 ~30 ~8 ~57 vine 4  
fill ~30 ~2 ~60 ~31 ~2 ~60 vine 4  
fill ~31 ~2 ~4 ~32 ~2 ~4 vine 1  
fill ~31 ~2 ~6 ~31 ~6 ~6 vine 1 
setblock ~31 ~2 ~27 stone_brick_stairs 6 
setblock ~31 ~2 ~35 stone_brick_stairs 7  
fill ~31 ~2 ~56 ~31 ~6 ~56 vine 4  
fill ~31 ~2 ~58 ~31 ~10 ~58 vine 4  
fill ~31 ~2 ~62 ~32 ~2 ~62 vine 4  
fill ~32 ~2 ~27 ~34 ~2 ~27 stone_slab 5 
setblock ~32 ~2 ~34 stonebrick 0  
fill ~32 ~2 ~35 ~34 ~2 ~35 stone_slab 5 
setblock ~32 ~2 ~52 stonebrick 0  
fill ~32 ~2 ~57 ~33 ~2 ~57 vine 4 
setblock ~33 ~2 ~11 stonebrick 0 
setblock ~33 ~2 ~51 stonebrick 2 
setblock ~34 ~2 ~11 stonebrick 2  
fill ~34 ~2 ~28 ~34 ~1 ~28 glowstone 0  
fill ~34 ~2 ~34 ~34 ~1 ~34 glowstone 0 
setblock ~34 ~2 ~51 stonebrick 1  
fill ~35 ~2 ~7 ~35 ~8 ~7 vine 1 
setblock ~35 ~2 ~12 stonebrick 0  
fill ~35 ~2 ~27 ~35 ~2 ~28 stone_brick_stairs 1  
fill ~35 ~2 ~34 ~35 ~2 ~35 stone_brick_stairs 1  
fill ~35 ~2 ~57 ~35 ~11 ~57 vine 2  
fill ~36 ~2 ~8 ~36 ~5 ~8 vine 1 
setblock ~36 ~2 ~12 stonebrick 2  
fill ~36 ~2 ~57 ~36 ~11 ~57 vine 4  
fill ~37 ~2 ~55 ~37 ~9 ~55 vine 2  
fill ~38 ~2 ~54 ~38 ~10 ~54 vine 2 
setblock ~50 ~2 ~26 stonebrick 0 
setblock ~50 ~2 ~36 stonebrick 1 
setblock ~51 ~2 ~28 stonebrick 0 
setblock ~51 ~2 ~29 stonebrick 2 
setblock ~51 ~2 ~33 stonebrick 2 
setblock ~51 ~2 ~34 stonebrick 0  
fill ~52 ~2 ~24 ~52 ~6 ~24 vine 1 
setblock ~52 ~2 ~32 stonebrick 2  
fill ~2 ~3 ~32 ~2 ~16 ~32 vine 8 
setblock ~9 ~3 ~30 stonebrick 2 
setblock ~9 ~3 ~31 glowstone 0 
setblock ~9 ~3 ~32 stonebrick 0 
setblock ~10 ~3 ~28 stonebrick 2 
setblock ~10 ~3 ~29 stonebrick 1 
setblock ~10 ~3 ~33 stonebrick 0 
setblock ~10 ~3 ~34 stonebrick 1  
fill ~11 ~3 ~26 ~11 ~3 ~27 stonebrick 0  
fill ~11 ~3 ~35 ~11 ~3 ~36 stonebrick 2 
setblock ~12 ~3 ~25 diamond_block 0 
setblock ~12 ~3 ~26 vine 6 
setblock ~12 ~3 ~27 vine 2 
setblock ~12 ~3 ~37 diamond_block 0 
setblock ~25 ~3 ~12 diamond_block 0 
setblock ~25 ~3 ~50 diamond_block 0 
setblock ~26 ~3 ~11 stonebrick 1 
setblock ~26 ~3 ~51 stonebrick 2 
setblock ~27 ~3 ~11 stonebrick 0 
setblock ~27 ~3 ~51 stonebrick 0  
fill ~28 ~3 ~10 ~29 ~3 ~10 stonebrick 2  
fill ~28 ~3 ~27 ~28 ~3 ~28 stone_brick_stairs 0  
fill ~28 ~3 ~34 ~28 ~3 ~35 stone_brick_stairs 0  
fill ~28 ~3 ~52 ~29 ~3 ~52 stonebrick 1  
fill ~29 ~3 ~27 ~30 ~3 ~27 stone_slab 5  
fill ~29 ~3 ~35 ~30 ~3 ~35 stone_slab 5 
setblock ~29 ~3 ~51 vine 1 
setblock ~30 ~3 ~9 stonebrick 1 
setblock ~30 ~3 ~53 stonebrick 0  
fill ~30 ~3 ~60 ~31 ~3 ~60 vine 4  
fill ~31 ~3 ~4 ~32 ~3 ~4 vine 1 
setblock ~31 ~3 ~9 glowstone 0 
setblock ~31 ~3 ~27 stone_brick_stairs 2 
setblock ~31 ~3 ~35 stone_brick_stairs 3 
setblock ~31 ~3 ~53 glowstone 0  
fill ~31 ~3 ~62 ~32 ~3 ~62 vine 4 
setblock ~32 ~3 ~9 stonebrick 1  
fill ~32 ~3 ~27 ~33 ~3 ~27 stone_slab 5 
setblock ~32 ~3 ~34 stonebrick 1  
fill ~32 ~3 ~35 ~33 ~3 ~35 stone_slab 5 
setblock ~32 ~3 ~53 stonebrick 0  
fill ~32 ~3 ~57 ~33 ~3 ~57 vine 4 
setblock ~33 ~3 ~10 stonebrick 1  
fill ~33 ~3 ~52 ~34 ~3 ~52 stonebrick 0 
setblock ~34 ~3 ~10 stonebrick 0  
fill ~34 ~3 ~27 ~34 ~3 ~28 stone_brick_stairs 1  
fill ~34 ~3 ~34 ~34 ~3 ~35 stone_brick_stairs 1 
setblock ~34 ~3 ~51 vine 8  
fill ~35 ~3 ~11 ~36 ~3 ~11 stonebrick 0 
setblock ~35 ~3 ~50 vine 1  
fill ~35 ~3 ~51 ~36 ~3 ~51 stonebrick 2 
setblock ~37 ~3 ~12 diamond_block 0 
setblock ~37 ~3 ~50 diamond_block 0 
setblock ~50 ~3 ~25 diamond_block 0 
setblock ~50 ~3 ~37 diamond_block 0 
setblock ~51 ~3 ~26 stonebrick 0 
setblock ~51 ~3 ~27 stonebrick 1 
setblock ~51 ~3 ~28 vine 8 
setblock ~51 ~3 ~35 stonebrick 1 
setblock ~51 ~3 ~36 stonebrick 2 
setblock ~52 ~3 ~28 stonebrick 2 
setblock ~52 ~3 ~29 stonebrick 1 
setblock ~52 ~3 ~33 stonebrick 0 
setblock ~52 ~3 ~34 stonebrick 1 
setblock ~53 ~3 ~30 stonebrick 2 
setblock ~53 ~3 ~31 glowstone 0 
setblock ~53 ~3 ~32 stonebrick 2  
fill ~59 ~3 ~37 ~59 ~28 ~37 vine 6 
setblock ~8 ~4 ~30 stonebrick 0 
setblock ~8 ~4 ~31 glowstone 0 
setblock ~8 ~4 ~32 stonebrick 2 
setblock ~9 ~4 ~28 stonebrick 0 
setblock ~9 ~4 ~29 stonebrick 2  
fill ~9 ~4 ~33 ~9 ~4 ~34 stonebrick 0  
fill ~10 ~4 ~26 ~10 ~4 ~27 stonebrick 2 
setblock ~10 ~4 ~35 stonebrick 1 
setblock ~10 ~4 ~36 stonebrick 0 
setblock ~11 ~4 ~25 diamond_block 0 
setblock ~11 ~4 ~37 diamond_block 0 
setblock ~25 ~4 ~11 diamond_block 0 
setblock ~25 ~4 ~51 diamond_block 0 
setblock ~26 ~4 ~10 stonebrick 1 
setblock ~26 ~4 ~52 stonebrick 0  
fill ~27 ~4 ~6 ~27 ~10 ~6 vine 9 
setblock ~27 ~4 ~10 stonebrick 0 
setblock ~27 ~4 ~52 stonebrick 2  
fill ~28 ~4 ~9 ~29 ~4 ~9 stonebrick 1 
setblock ~28 ~4 ~28 stone_slab 13 
setblock ~28 ~4 ~34 stone_slab 13 
setblock ~28 ~4 ~53 stonebrick 0 
setblock ~29 ~4 ~10 vine 4 
setblock ~29 ~4 ~27 stone_brick_stairs 0 
setblock ~29 ~4 ~35 stone_brick_stairs 0 
setblock ~29 ~4 ~53 stonebrick 2 
setblock ~30 ~4 ~8 stonebrick 0 
setblock ~30 ~4 ~9 vine 6 
setblock ~30 ~4 ~27 stone_slab 5 
setblock ~30 ~4 ~35 stone_slab 5 
setblock ~30 ~4 ~54 stonebrick 2  
fill ~30 ~4 ~60 ~31 ~4 ~60 vine 4  
fill ~31 ~4 ~4 ~32 ~4 ~4 vine 1 
setblock ~31 ~4 ~8 glowstone 0 
setblock ~31 ~4 ~27 stone_brick_stairs 6 
setblock ~31 ~4 ~35 stone_brick_stairs 7 
setblock ~31 ~4 ~54 glowstone 0  
fill ~31 ~4 ~62 ~32 ~4 ~62 vine 4 
setblock ~32 ~4 ~8 stonebrick 1  
fill ~32 ~4 ~27 ~32 ~1 ~27 stone_slab 5 
setblock ~32 ~4 ~34 stonebrick 0  
fill ~32 ~4 ~35 ~32 ~1 ~35 stone_slab 5 
setblock ~32 ~4 ~53 vine 8 
setblock ~32 ~4 ~54 stonebrick 0  
fill ~32 ~4 ~57 ~33 ~4 ~57 vine 4 
setblock ~33 ~4 ~9 stonebrick 1 
setblock ~33 ~4 ~27 stone_brick_stairs 1 
setblock ~33 ~4 ~35 stone_brick_stairs 1 
setblock ~33 ~4 ~53 stonebrick 0 
setblock ~34 ~4 ~9 stonebrick 0 
setblock ~34 ~4 ~28 stone_slab 13 
setblock ~34 ~4 ~34 stone_slab 13 
setblock ~34 ~4 ~53 stonebrick 1 
setblock ~35 ~4 ~10 stonebrick 2  
fill ~35 ~4 ~52 ~36 ~4 ~52 stonebrick 0 
setblock ~36 ~4 ~10 stonebrick 1 
setblock ~37 ~4 ~11 diamond_block 0 
setblock ~37 ~4 ~51 diamond_block 0 
setblock ~51 ~4 ~25 diamond_block 0 
setblock ~51 ~4 ~37 diamond_block 0 
setblock ~52 ~4 ~26 stonebrick 0 
setblock ~52 ~4 ~27 stonebrick 1  
fill ~52 ~4 ~35 ~52 ~4 ~36 stonebrick 2 
setblock ~53 ~4 ~28 stonebrick 1 
setblock ~53 ~4 ~29 stonebrick 0 
setblock ~53 ~4 ~33 stonebrick 2 
setblock ~53 ~4 ~34 stonebrick 1 
setblock ~54 ~4 ~30 stonebrick 1 
setblock ~54 ~4 ~31 glowstone 0   

KittysCommands:  
setblock ~54 ~4 ~32 stonebrick 1 
setblock ~7 ~5 ~30 stonebrick 0  
fill ~7 ~5 ~31 ~7 ~6 ~31 glowstone 0 
setblock ~7 ~5 ~32 stonebrick 1  
fill ~8 ~5 ~28 ~8 ~6 ~28 stonebrick 0  
fill ~8 ~5 ~29 ~8 ~6 ~29 stonebrick 0 
setblock ~8 ~5 ~33 stonebrick 1  
fill ~8 ~5 ~34 ~8 ~6 ~34 stonebrick 0  
fill ~9 ~5 ~26 ~9 ~5 ~27 stonebrick 1  
fill ~9 ~5 ~35 ~9 ~6 ~35 stonebrick 0  
fill ~9 ~5 ~36 ~9 ~6 ~36 stonebrick 0  
fill ~10 ~5 ~25 ~10 ~6 ~25 diamond_block 0  
fill ~10 ~5 ~37 ~10 ~6 ~37 diamond_block 0 
setblock ~25 ~5 ~9 vine 1  
fill ~25 ~5 ~10 ~25 ~6 ~10 diamond_block 0  
fill ~25 ~5 ~52 ~25 ~6 ~52 diamond_block 0 
setblock ~25 ~5 ~53 vine 12  
fill ~26 ~5 ~3 ~26 ~18 ~3 vine 1  
fill ~26 ~5 ~6 ~26 ~9 ~6 vine 1 
setblock ~26 ~5 ~9 stonebrick 2  
fill ~26 ~5 ~53 ~26 ~6 ~53 stonebrick 2  
fill ~27 ~5 ~9 ~27 ~6 ~9 stonebrick 0 
setblock ~27 ~5 ~10 vine 4  
fill ~27 ~5 ~53 ~27 ~6 ~53 stonebrick 0  
fill ~28 ~5 ~8 ~28 ~6 ~8 stonebrick 0  
fill ~28 ~5 ~9 ~28 ~6 ~9 vine 2 
setblock ~28 ~5 ~29 stone_slab 13 
setblock ~28 ~5 ~33 stone_slab 13  
fill ~28 ~5 ~53 ~28 ~6 ~53 vine 1 
setblock ~28 ~5 ~54 stonebrick 1 
setblock ~29 ~5 ~8 stonebrick 1 
setblock ~29 ~5 ~28 stone_slab 13 
setblock ~29 ~5 ~29 diamond_block 0 
setblock ~29 ~5 ~33 diamond_block 0 
setblock ~29 ~5 ~34 stone_slab 13  
fill ~29 ~5 ~54 ~29 ~6 ~54 stonebrick 2  
fill ~30 ~5 ~2 ~31 ~5 ~2 vine 1 
setblock ~30 ~5 ~7 stonebrick 0  
fill ~30 ~5 ~8 ~31 ~5 ~8 vine 4 
setblock ~30 ~5 ~28 stone_brick_stairs 2 
setblock ~30 ~5 ~29 stonebrick 0 
setblock ~30 ~5 ~32 vine 1 
setblock ~30 ~5 ~33 stonebrick 0 
setblock ~30 ~5 ~34 stone_brick_stairs 3  
fill ~30 ~5 ~54 ~30 ~6 ~54 vine 1 
setblock ~30 ~5 ~55 stonebrick 2  
fill ~30 ~5 ~60 ~31 ~5 ~60 vine 4  
fill ~31 ~5 ~4 ~32 ~5 ~4 vine 1  
fill ~31 ~5 ~7 ~31 ~6 ~7 glowstone 0 
setblock ~31 ~5 ~28 stone_slab 13 
setblock ~31 ~5 ~29 gold_block 0 
setblock ~31 ~5 ~33 gold_block 0 
setblock ~31 ~5 ~34 stone_slab 13  
fill ~31 ~5 ~55 ~31 ~6 ~55 glowstone 0  
fill ~31 ~5 ~62 ~32 ~5 ~62 vine 4 
setblock ~32 ~5 ~7 stonebrick 0 
setblock ~32 ~5 ~28 stone_brick_stairs 2 
setblock ~32 ~5 ~29 stonebrick 0 
setblock ~32 ~5 ~33 stonebrick 1 
setblock ~32 ~5 ~34 stone_brick_stairs 3 
setblock ~32 ~5 ~55 stonebrick 2  
fill ~32 ~5 ~57 ~33 ~5 ~57 vine 4 
setblock ~33 ~5 ~8 stonebrick 1 
setblock ~33 ~5 ~28 stone_slab 13 
setblock ~33 ~5 ~29 diamond_block 0 
setblock ~33 ~5 ~33 diamond_block 0 
setblock ~33 ~5 ~34 stone_slab 13  
fill ~33 ~5 ~54 ~34 ~5 ~54 stonebrick 0  
fill ~34 ~5 ~8 ~34 ~6 ~8 stonebrick 0 
setblock ~34 ~5 ~29 stone_slab 13 
setblock ~34 ~5 ~33 stone_slab 13 
setblock ~35 ~5 ~9 stonebrick 0  
fill ~35 ~5 ~53 ~36 ~5 ~53 stonebrick 2 
setblock ~36 ~5 ~9 stonebrick 1  
fill ~36 ~5 ~10 ~36 ~6 ~10 vine 4  
fill ~37 ~5 ~10 ~37 ~6 ~10 diamond_block 0  
fill ~37 ~5 ~52 ~37 ~6 ~52 diamond_block 0  
fill ~52 ~5 ~25 ~52 ~6 ~25 diamond_block 0  
fill ~52 ~5 ~27 ~52 ~6 ~27 vine 8  
fill ~52 ~5 ~37 ~52 ~6 ~37 diamond_block 0  
fill ~53 ~5 ~25 ~53 ~6 ~25 vine 3  
fill ~53 ~5 ~26 ~53 ~5 ~27 stonebrick 0 
setblock ~53 ~5 ~35 stonebrick 1 
setblock ~53 ~5 ~36 stonebrick 0  
fill ~54 ~5 ~28 ~54 ~6 ~28 stonebrick 0  
fill ~54 ~5 ~29 ~54 ~5 ~28 stonebrick 0  
fill ~54 ~5 ~33 ~54 ~6 ~33 stonebrick 2  
fill ~54 ~5 ~34 ~54 ~6 ~34 stonebrick 0 
setblock ~55 ~5 ~30 stonebrick 0  
fill ~55 ~5 ~31 ~55 ~6 ~31 glowstone 0  
fill ~55 ~5 ~32 ~55 ~6 ~32 stonebrick 2  
fill ~56 ~5 ~31 ~56 ~6 ~31 vine 2  
fill ~56 ~5 ~32 ~56 ~6 ~32 vine 2 
setblock ~7 ~6 ~30 stonebrick 1 
setblock ~7 ~6 ~32 stonebrick 0 
setblock ~8 ~6 ~33 stonebrick 0  
fill ~9 ~6 ~26 ~9 ~6 ~27 stonebrick 0  
fill ~25 ~6 ~8 ~25 ~7 ~8 vine 8 
setblock ~25 ~6 ~53 vine 8  
fill ~25 ~6 ~55 ~25 ~10 ~55 vine 8 
setblock ~26 ~6 ~9 stonebrick 0 
setblock ~28 ~6 ~30 stone_slab 13 
setblock ~28 ~6 ~31 fence 0 
setblock ~28 ~6 ~32 stone_slab 13 
setblock ~28 ~6 ~54 stonebrick 0 
setblock ~29 ~6 ~8 stonebrick 2 
setblock ~29 ~6 ~29 stone_slab 13  
fill ~29 ~6 ~30 ~29 ~6 ~32 diamond_block 0 
setblock ~29 ~6 ~33 stone_slab 13  
fill ~30 ~6 ~2 ~31 ~6 ~2 vine 1 
setblock ~30 ~6 ~7 stonebrick 1  
fill ~30 ~6 ~8 ~31 ~6 ~8 vine 4 
setblock ~30 ~6 ~29 stone_brick_stairs 2 
setblock ~30 ~6 ~30 stonebrick 0 
setblock ~30 ~6 ~31 stonebrick 2 
setblock ~30 ~6 ~32 stonebrick 0 
setblock ~30 ~6 ~33 stone_brick_stairs 3 
setblock ~30 ~6 ~55 stonebrick 0  
fill ~30 ~6 ~60 ~31 ~6 ~60 vine 4  
fill ~31 ~6 ~4 ~32 ~6 ~4 vine 1 
setblock ~31 ~6 ~29 stone_slab 13  
fill ~31 ~6 ~30 ~31 ~6 ~32 gold_block 0 
setblock ~31 ~6 ~33 stone_slab 13  
fill ~31 ~6 ~62 ~32 ~6 ~62 vine 4 
setblock ~32 ~6 ~7 stonebrick 2 
setblock ~32 ~6 ~29 stone_brick_stairs 2  
fill ~32 ~6 ~30 ~32 ~6 ~32 stonebrick 0 
setblock ~32 ~6 ~33 stone_brick_stairs 3 
setblock ~32 ~6 ~55 stonebrick 0  
fill ~32 ~6 ~57 ~33 ~6 ~57 vine 4  
fill ~33 ~6 ~6 ~33 ~7 ~6 vine 2 
setblock ~33 ~6 ~8 stonebrick 0 
setblock ~33 ~6 ~29 stone_slab 13  
fill ~33 ~6 ~30 ~33 ~6 ~32 diamond_block 0 
setblock ~33 ~6 ~33 stone_slab 13  
fill ~33 ~6 ~54 ~34 ~6 ~54 stonebrick 1 
setblock ~34 ~6 ~30 stone_slab 13 
setblock ~34 ~6 ~31 fence 0 
setblock ~34 ~6 ~32 stone_slab 13 
setblock ~35 ~6 ~9 stonebrick 2  
fill ~35 ~6 ~53 ~36 ~6 ~53 stonebrick 0 
setblock ~36 ~6 ~9 stonebrick 0 
setblock ~53 ~6 ~26 stonebrick 1 
setblock ~53 ~6 ~27 stonebrick 2 
setblock ~53 ~6 ~35 stonebrick 0 
setblock ~53 ~6 ~36 stonebrick 2 
setblock ~54 ~6 ~29 stonebrick 1 
setblock ~55 ~6 ~30 stonebrick 2  
fill ~55 ~6 ~36 ~55 ~8 ~36 vine 2 
setblock ~6 ~7 ~30 stonebrick 0  
fill ~6 ~7 ~31 ~6 ~8 ~31 glowstone 0  
fill ~6 ~7 ~32 ~6 ~8 ~32 stonebrick 1  
fill ~7 ~7 ~28 ~7 ~7 ~29 stonebrick 0 
setblock ~7 ~7 ~33 stonebrick 2 
setblock ~7 ~7 ~34 stonebrick 0  
fill ~8 ~7 ~26 ~8 ~8 ~26 stonebrick 0  
fill ~8 ~7 ~27 ~8 ~7 ~26 stonebrick 0  
fill ~8 ~7 ~35 ~8 ~7 ~36 stonebrick 1  
fill ~9 ~7 ~25 ~9 ~8 ~25 diamond_block 0  
fill ~9 ~7 ~37 ~9 ~8 ~37 diamond_block 0  
fill ~25 ~7 ~9 ~25 ~8 ~9 diamond_block 0  
fill ~25 ~7 ~53 ~25 ~8 ~53 diamond_block 0 
setblock ~25 ~7 ~54 vine 8 
setblock ~26 ~7 ~8 stonebrick 1  
fill ~26 ~7 ~9 ~27 ~7 ~9 vine 4  
fill ~26 ~7 ~53 ~26 ~8 ~53 vine 3  
fill ~26 ~7 ~54 ~27 ~7 ~54 stonebrick 0 
setblock ~27 ~7 ~8 stonebrick 0  
fill ~28 ~7 ~7 ~29 ~7 ~7 stonebrick 1 
setblock ~28 ~7 ~8 vine 2 
setblock ~28 ~7 ~31 stone_slab 5 
setblock ~28 ~7 ~55 stonebrick 0  
fill ~29 ~7 ~30 ~33 ~7 ~30 stone_slab 5 
setblock ~29 ~7 ~31 stone_brick_stairs 0  
fill ~29 ~7 ~32 ~33 ~7 ~32 stone_slab 5 
setblock ~29 ~7 ~55 stonebrick 1  
fill ~30 ~7 ~2 ~31 ~7 ~2 vine 1 
setblock ~30 ~7 ~6 stonebrick 2  
fill ~30 ~7 ~31 ~32 ~7 ~31 glowstone 0  
fill ~30 ~7 ~56 ~30 ~8 ~56 stonebrick 1  
fill ~30 ~7 ~60 ~31 ~7 ~60 vine 4  
fill ~31 ~7 ~4 ~32 ~7 ~4 vine 1  
fill ~31 ~7 ~6 ~31 ~8 ~6 glowstone 0  
fill ~31 ~7 ~8 ~31 ~49 ~8 vine 4  
fill ~31 ~7 ~56 ~31 ~8 ~56 glowstone 0  
fill ~31 ~7 ~62 ~32 ~7 ~62 vine 4 
setblock ~32 ~7 ~6 stonebrick 1  
fill ~32 ~7 ~55 ~32 ~8 ~55 vine 1 
setblock ~32 ~7 ~56 stonebrick 0  
fill ~32 ~7 ~57 ~33 ~7 ~57 vine 4  
fill ~33 ~7 ~7 ~33 ~8 ~7 stonebrick 0  
fill ~33 ~7 ~8 ~33 ~8 ~8 vine 4 
setblock ~33 ~7 ~31 stone_brick_stairs 1  
fill ~33 ~7 ~55 ~34 ~7 ~55 stonebrick 0 
setblock ~34 ~7 ~7 stonebrick 1 
setblock ~34 ~7 ~8 vine 8 
setblock ~34 ~7 ~31 stone_slab 5 
setblock ~35 ~7 ~8 stonebrick 2  
fill ~35 ~7 ~54 ~36 ~7 ~54 stonebrick 2 
setblock ~36 ~7 ~8 stonebrick 0  
fill ~37 ~7 ~8 ~37 ~8 ~8 vine 2  
fill ~37 ~7 ~9 ~37 ~8 ~9 diamond_block 0  
fill ~37 ~7 ~53 ~37 ~8 ~53 diamond_block 0  
fill ~53 ~7 ~24 ~53 ~8 ~24 vine 1  
fill ~53 ~7 ~25 ~53 ~8 ~25 diamond_block 0  
fill ~53 ~7 ~37 ~53 ~8 ~37 diamond_block 0  
fill ~54 ~7 ~26 ~54 ~8 ~26 stonebrick 0  
fill ~54 ~7 ~27 ~54 ~8 ~27 stonebrick 2 
setblock ~54 ~7 ~35 stonebrick 0 
setblock ~54 ~7 ~36 stonebrick 2 
setblock ~55 ~7 ~28 stonebrick 2  
fill ~55 ~7 ~29 ~55 ~8 ~29 stonebrick 0 
setblock ~55 ~7 ~33 stonebrick 0 
setblock ~55 ~7 ~34 stonebrick 1 
setblock ~55 ~7 ~35 vine 2  
fill ~56 ~7 ~30 ~56 ~8 ~30 stonebrick 0  
fill ~56 ~7 ~31 ~56 ~8 ~31 glowstone 0 
setblock ~56 ~7 ~32 stonebrick 0 
setblock ~6 ~8 ~30 stonebrick 1  
fill ~7 ~8 ~28 ~7 ~8 ~29 stonebrick 1  
fill ~7 ~8 ~33 ~7 ~8 ~34 stonebrick 1 
setblock ~8 ~8 ~27 stonebrick 1 
setblock ~8 ~8 ~35 stonebrick 0 
setblock ~8 ~8 ~36 stonebrick 1  
fill ~26 ~8 ~8 ~27 ~8 ~8 stonebrick 2  
fill ~26 ~8 ~9 ~26 ~7 ~9 vine 4  
fill ~26 ~8 ~54 ~26 ~7 ~54 stonebrick 0 
setblock ~27 ~8 ~54 stonebrick 2  
fill ~28 ~8 ~7 ~28 ~7 ~7 stonebrick 1 
setblock ~28 ~8 ~55 stonebrick 1 
setblock ~29 ~8 ~7 stonebrick 2 
setblock ~29 ~8 ~55 stonebrick 0  
fill ~30 ~8 ~2 ~31 ~8 ~2 vine 1 
setblock ~30 ~8 ~6 stonebrick 0  
fill ~30 ~8 ~31 ~32 ~8 ~31 stone_slab 5  
fill ~30 ~8 ~60 ~31 ~8 ~60 vine 4  
fill ~31 ~8 ~4 ~32 ~8 ~4 vine 1  
fill ~31 ~8 ~62 ~32 ~8 ~62 vine 4 
setblock ~32 ~8 ~6 stonebrick 2 
setblock ~32 ~8 ~56 stonebrick 2  
fill ~32 ~8 ~57 ~33 ~8 ~57 vine 4  
fill ~33 ~8 ~5 ~33 ~10 ~5 vine 2  
fill ~33 ~8 ~55 ~33 ~7 ~55 stonebrick 0 
setblock ~34 ~8 ~7 stonebrick 0 
setblock ~34 ~8 ~55 stonebrick 2 
setblock ~35 ~8 ~8 stonebrick 0  
fill ~35 ~8 ~54 ~35 ~7 ~54 stonebrick 2 
setblock ~36 ~8 ~8 stonebrick 2 
setblock ~36 ~8 ~54 stonebrick 0 
setblock ~54 ~8 ~35 stonebrick 2 
setblock ~54 ~8 ~36 stonebrick 1 
setblock ~55 ~8 ~28 stonebrick 0 
setblock ~55 ~8 ~33 stonebrick 1 
setblock ~55 ~8 ~34 stonebrick 2  
fill ~56 ~8 ~27 ~56 ~10 ~27 vine 2 
setblock ~56 ~8 ~32 stonebrick 2  
fill ~4 ~9 ~30 ~4 ~10 ~30 vine 8  
fill ~4 ~9 ~31 ~4 ~10 ~31 vine 8 
setblock ~5 ~9 ~30 stonebrick 2  
fill ~5 ~9 ~31 ~5 ~10 ~31 glowstone 0 
setblock ~5 ~9 ~32 stonebrick 0 
setblock ~6 ~9 ~28 stonebrick 0 
setblock ~6 ~9 ~29 stonebrick 1  
fill ~6 ~9 ~33 ~6 ~10 ~33 stonebrick 1  
fill ~6 ~9 ~34 ~6 ~10 ~34 stonebrick 1  
fill ~7 ~9 ~26 ~7 ~9 ~27 stonebrick 2 
setblock ~7 ~9 ~35 stonebrick 2 
setblock ~7 ~9 ~36 stonebrick 0  
fill ~8 ~9 ~25 ~8 ~10 ~25 diamond_block 0  
fill ~8 ~9 ~37 ~8 ~10 ~37 diamond_block 0  
fill ~25 ~9 ~8 ~25 ~10 ~8 diamond_block 0  
fill ~25 ~9 ~53 ~25 ~10 ~53 vine 1  
fill ~25 ~9 ~54 ~25 ~10 ~54 diamond_block 0  
fill ~26 ~9 ~7 ~27 ~9 ~7 stonebrick 1 
setblock ~26 ~9 ~55 stonebrick 0 
setblock ~27 ~9 ~55 stonebrick 2  
fill ~28 ~9 ~6 ~28 ~10 ~6 stonebrick 1  
fill ~28 ~9 ~7 ~28 ~10 ~7 vine 6  
fill ~28 ~9 ~56 ~29 ~9 ~56 stonebrick 0  
fill ~29 ~9 ~6 ~29 ~10 ~6 stonebrick 0  
fill ~29 ~9 ~55 ~29 ~10 ~55 vine 1  
fill ~30 ~9 ~2 ~31 ~9 ~2 vine 1  
fill ~30 ~9 ~5 ~30 ~10 ~5 stonebrick 0  
fill ~30 ~9 ~6 ~31 ~9 ~6 vine 4  
fill ~30 ~9 ~56 ~30 ~10 ~56 vine 2 
setblock ~30 ~9 ~57 stonebrick 0  
fill ~30 ~9 ~60 ~31 ~9 ~60 vine 4  
fill ~31 ~9 ~4 ~32 ~9 ~4 vine 1  
fill ~31 ~9 ~5 ~31 ~10 ~5 glowstone 0  
fill ~31 ~9 ~57 ~31 ~10 ~57 glowstone 0  
fill ~31 ~9 ~62 ~32 ~9 ~62 vine 4 
setblock ~32 ~9 ~5 stonebrick 2  
fill ~32 ~9 ~57 ~32 ~10 ~57 stonebrick 1  
fill ~33 ~9 ~6 ~34 ~9 ~6 stonebrick 0 
setblock ~33 ~9 ~55 vine 1  
fill ~33 ~9 ~56 ~33 ~10 ~56 stonebrick 2 
setblock ~33 ~9 ~57 vine 4 
setblock ~34 ~9 ~56 stonebrick 0 
setblock ~35 ~9 ~7 stonebrick 1 
setblock ~35 ~9 ~55 stonebrick 0  
fill ~36 ~9 ~7 ~36 ~10 ~7 stonebrick 0  
fill ~36 ~9 ~55 ~36 ~10 ~55 stonebrick 2 
setblock ~37 ~9 ~7 vine 2  
fill ~37 ~9 ~8 ~37 ~10 ~8 diamond_block 0  
fill ~37 ~9 ~53 ~37 ~10 ~53 vine 1  
fill ~37 ~9 ~54 ~37 ~10 ~54 diamond_block 0 
setblock ~53 ~9 ~25 vine 8  
fill ~54 ~9 ~25 ~54 ~10 ~25 diamond_block 0 
setblock ~54 ~9 ~27 vine 8  
fill ~54 ~9 ~37 ~54 ~10 ~37 diamond_block 0 
setblock ~55 ~9 ~26 stonebrick 1 
setblock ~55 ~9 ~27 stonebrick 0  
fill ~55 ~9 ~29 ~55 ~10 ~29 vine 8  
fill ~55 ~9 ~35 ~55 ~10 ~35 stonebrick 2  
fill ~55 ~9 ~36 ~55 ~10 ~36 stonebrick 1  
fill ~56 ~9 ~26 ~56 ~10 ~26 vine 2  
fill ~56 ~9 ~28 ~56 ~9 ~29 stonebrick 0  
fill ~56 ~9 ~33 ~56 ~10 ~33 stonebrick 0 
setblock ~56 ~9 ~34 stonebrick 2 
setblock ~57 ~9 ~30 stonebrick 2  
fill ~57 ~9 ~31 ~57 ~10 ~31 glowstone 0  
fill ~57 ~9 ~32 ~57 ~10 ~32 stonebrick 2 
setblock ~5 ~10 ~30 stonebrick 0 
setblock ~5 ~10 ~32 stonebrick 1 
setblock ~6 ~10 ~28 stonebrick 2 
setblock ~6 ~10 ~29 stonebrick 0  
fill ~7 ~10 ~26 ~7 ~10 ~27 stonebrick 1  
fill ~7 ~10 ~35 ~7 ~10 ~36 stonebrick 1 
setblock ~26 ~10 ~7 stonebrick 0 
setblock ~26 ~10 ~55 stonebrick 2 
setblock ~27 ~10 ~7 stonebrick 1 
setblock ~27 ~10 ~55 stonebrick 0  
fill ~28 ~10 ~56 ~29 ~10 ~56 stonebrick 2  
fill ~30 ~10 ~2 ~31 ~10 ~2 vine 1  
fill ~30 ~10 ~6 ~31 ~10 ~6 vine 4 
setblock ~30 ~10 ~57 stonebrick 1  
fill ~30 ~10 ~60 ~31 ~10 ~60 vine 4  
fill ~31 ~10 ~4 ~32 ~10 ~4 vine 1  
fill ~31 ~10 ~62 ~32 ~10 ~62 vine 4 
setblock ~32 ~10 ~5 stonebrick 0 
setblock ~33 ~10 ~6 stonebrick 2 
setblock ~34 ~10 ~6 stonebrick 0 
setblock ~34 ~10 ~56 stonebrick 2 
setblock ~35 ~10 ~7 stonebrick 2 
setblock ~35 ~10 ~55 stonebrick 1  
fill ~35 ~10 ~60 ~35 ~31 ~60 vine 6 
setblock ~55 ~10 ~26 stonebrick 0 
setblock ~55 ~10 ~27 stonebrick 2 
setblock ~56 ~10 ~28 stonebrick 2 
setblock ~56 ~10 ~29 stonebrick 0 
setblock ~56 ~10 ~34 stonebrick 0 
setblock ~57 ~10 ~30 stonebrick 0  
fill ~2 ~11 ~27 ~2 ~28 ~27 vine 9  
fill ~4 ~11 ~30 ~4 ~12 ~30 stonebrick 0  
fill ~4 ~11 ~31 ~4 ~12 ~31 glowstone 0 
setblock ~4 ~11 ~32 stonebrick 1  
fill ~4 ~11 ~38 ~4 ~31 ~38 vine 4  
fill ~5 ~11 ~28 ~5 ~12 ~28 stonebrick 0 
setblock ~5 ~11 ~29 stonebrick 2  
fill ~5 ~11 ~33 ~5 ~12 ~33 stonebrick 2  
fill ~5 ~11 ~34 ~5 ~12 ~34 stonebrick 2 
setblock ~6 ~11 ~26 stonebrick 0 
setblock ~6 ~11 ~27 stonebrick 1  
fill ~6 ~11 ~35 ~6 ~12 ~35 stonebrick 1 
setblock ~6 ~11 ~36 stonebrick 0  
fill ~7 ~11 ~25 ~7 ~12 ~25 diamond_block 0  
fill ~7 ~11 ~37 ~7 ~12 ~37 diamond_block 0  
fill ~24 ~11 ~4 ~24 ~27 ~4 vine 8  
fill ~25 ~11 ~7 ~25 ~12 ~7 diamond_block 0  
fill ~25 ~11 ~55 ~25 ~12 ~55 diamond_block 0  
fill ~26 ~11 ~6 ~27 ~11 ~6 stonebrick 1 
setblock ~26 ~11 ~56 stonebrick 2  
fill ~27 ~11 ~7 ~27 ~12 ~7 vine 4 
setblock ~27 ~11 ~56 stonebrick 0  
fill ~28 ~11 ~5 ~28 ~12 ~5 stonebrick 2 
setblock ~28 ~11 ~57 stonebrick 2  
fill ~29 ~11 ~1 ~29 ~32 ~1 vine 1 
setblock ~29 ~11 ~5 stonebrick 1  
fill ~29 ~11 ~57 ~29 ~12 ~57 stonebrick 0  
fill ~30 ~11 ~2 ~31 ~11 ~2 vine 1 
setblock ~30 ~11 ~58 stonebrick 1  
fill ~30 ~11 ~60 ~32 ~11 ~60 vine 4  
fill ~30 ~11 ~62 ~32 ~11 ~62 vine 4  
fill ~31 ~11 ~4 ~31 ~12 ~4 glowstone 0  
fill ~31 ~11 ~58 ~31 ~12 ~58 glowstone 0  
fill ~32 ~11 ~4 ~32 ~12 ~4 stonebrick 2  
fill ~32 ~11 ~5 ~32 ~42 ~5 vine 8  
fill ~32 ~11 ~57 ~32 ~12 ~57 vine 8 
setblock ~32 ~11 ~58 stonebrick 0 
setblock ~32 ~11 ~59 vine 4 
setblock ~33 ~11 ~5 stonebrick 0  
fill ~33 ~11 ~6 ~33 ~42 ~6 vine 4  
fill ~33 ~11 ~56 ~33 ~12 ~56 vine 1 
setblock ~33 ~11 ~57 stonebrick 0 
setblock ~34 ~11 ~5 stonebrick 2  
fill ~34 ~11 ~57 ~34 ~12 ~57 stonebrick 1  
fill ~35 ~11 ~6 ~36 ~11 ~6 stonebrick 0  
fill ~35 ~11 ~56 ~35 ~12 ~56 stonebrick 2  
fill ~36 ~11 ~56 ~36 ~12 ~56 stonebrick 0  
fill ~37 ~11 ~7 ~37 ~12 ~7 diamond_block 0  
fill ~37 ~11 ~55 ~37 ~12 ~55 diamond_block 0  
fill ~55 ~11 ~25 ~55 ~12 ~25 diamond_block 0  
fill ~55 ~11 ~37 ~55 ~12 ~37 diamond_block 0 
setblock ~56 ~11 ~26 stonebrick 0  
fill ~56 ~11 ~27 ~56 ~12 ~27 stonebrick 1 
setblock ~56 ~11 ~28 vine 8  
fill ~56 ~11 ~35 ~56 ~11 ~36 stonebrick 2  
fill ~57 ~11 ~28 ~57 ~11 ~29 stonebrick 1  
fill ~57 ~11 ~33 ~57 ~11 ~34 stonebrick 0  
fill ~58 ~11 ~30 ~58 ~12 ~30 stonebrick 2  
fill ~58 ~11 ~31 ~58 ~12 ~31 glowstone 0 
setblock ~58 ~11 ~32 stonebrick 0  
fill ~3 ~12 ~25 ~3 ~31 ~25 vine 1  
fill ~3 ~12 ~27 ~3 ~19 ~27 vine 1  
fill ~3 ~12 ~33 ~3 ~15 ~33 vine 4  
fill ~3 ~12 ~37 ~3 ~28 ~37 vine 8  
fill ~4 ~12 ~24 ~4 ~24 ~24 vine 1 
setblock ~4 ~12 ~32 stonebrick 0 
setblock ~5 ~12 ~29 stonebrick 0 
setblock ~6 ~12 ~26 stonebrick 2 
setblock ~6 ~12 ~27 stonebrick 0 
setblock ~6 ~12 ~36 stonebrick 2  
fill ~26 ~12 ~6 ~27 ~12 ~6 stonebrick 0 
setblock ~26 ~12 ~56 stonebrick 0  
fill ~26 ~12 ~60 ~27 ~12 ~60 vine 4  
fill ~27 ~12 ~3 ~27 ~17 ~3 vine 9 
setblock ~27 ~12 ~56 stonebrick 1 
setblock ~28 ~12 ~57 stonebrick 0 
setblock ~29 ~12 ~5 stonebrick 0  
fill ~29 ~12 ~61 ~29 ~30 ~61 vine 12  
fill ~30 ~12 ~2 ~31 ~12 ~2 vine 1 
setblock ~30 ~12 ~4 stonebrick 2 
setblock ~30 ~12 ~5 vine 4 
setblock ~30 ~12 ~58 stonebrick 0  
fill ~30 ~12 ~60 ~32 ~12 ~60 vine 4  
fill ~30 ~12 ~62 ~32 ~12 ~62 vine 4  
fill ~32 ~12 ~1 ~33 ~12 ~1 vine 1 
setblock ~32 ~12 ~58 stonebrick 2 
setblock ~33 ~12 ~5 stonebrick 1 
setblock ~33 ~12 ~57 stonebrick 1  
fill ~33 ~12 ~61 ~33 ~27 ~61 vine 6 
setblock ~34 ~12 ~5 stonebrick 0  
fill ~35 ~12 ~6 ~35 ~11 ~6 stonebrick 0 
setblock ~36 ~12 ~6 stonebrick 2  
fill ~38 ~12 ~58 ~38 ~29 ~58 vine 2 
setblock ~56 ~12 ~26 stonebrick 1 
setblock ~56 ~12 ~35 stonebrick 0 
setblock ~56 ~12 ~36 stonebrick 2 
setblock ~57 ~12 ~28 stonebrick 2 
setblock ~57 ~12 ~29 stonebrick 1 
setblock ~57 ~12 ~33 stonebrick 1 
setblock ~57 ~12 ~34 stonebrick 0 
setblock ~58 ~12 ~32 stonebrick 2  
fill ~58 ~12 ~38 ~58 ~23 ~38 vine 4  
fill ~60 ~12 ~32 ~60 ~15 ~32 vine 2 
setblock ~3 ~13 ~30 stonebrick 1  
fill ~3 ~13 ~31 ~3 ~16 ~31 glowstone 0 
setblock ~3 ~13 ~32 stonebrick 1  
fill ~4 ~13 ~28 ~4 ~16 ~28 stonebrick 0  
fill ~4 ~13 ~29 ~4 ~13 ~28 stonebrick 0 
setblock ~4 ~13 ~33 stonebrick 0 
setblock ~4 ~13 ~34 stonebrick 1 
setblock ~5 ~13 ~26 stonebrick 1  
fill ~5 ~13 ~27 ~5 ~15 ~27 stonebrick 2 
setblock ~5 ~13 ~35 stonebrick 2 
setblock ~5 ~13 ~36 stonebrick 1  
fill ~6 ~13 ~25 ~6 ~16 ~25 diamond_block 0  
fill ~6 ~13 ~37 ~6 ~16 ~37 diamond_block 0  
fill ~25 ~13 ~6 ~25 ~16 ~6 diamond_block 0  
fill ~25 ~13 ~56 ~25 ~16 ~56 diamond_block 0  
fill ~25 ~13 ~57 ~25 ~15 ~57 vine 12  
fill ~26 ~13 ~5 ~27 ~13 ~5 stonebrick 0  
fill ~26 ~13 ~6 ~27 ~13 ~6 vine 4  
fill ~26 ~13 ~57 ~27 ~13 ~57 stonebrick 0  
fill ~26 ~13 ~60 ~27 ~13 ~60 vine 4 
setblock ~28 ~13 ~4 stonebrick 0  
fill ~28 ~13 ~5 ~29 ~13 ~5 vine 4  
fill ~28 ~13 ~57 ~28 ~16 ~57 vine 3 
setblock ~28 ~13 ~58 stonebrick 0 
setblock ~29 ~13 ~4 stonebrick 1 
setblock ~29 ~13 ~58 stonebrick 1  
fill ~30 ~13 ~2 ~31 ~13 ~2 vine 1 
setblock ~30 ~13 ~3 stonebrick 0  
fill ~30 ~13 ~4 ~30 ~14 ~4 vine 2  
fill ~30 ~13 ~58 ~30 ~16 ~58 vine 2 
setblock ~30 ~13 ~59 stonebrick 0  
fill ~30 ~13 ~60 ~32 ~13 ~60 vine 4  
fill ~30 ~13 ~62 ~32 ~13 ~62 vine 4  
fill ~31 ~13 ~3 ~31 ~16 ~3 glowstone 0  
fill ~31 ~13 ~59 ~31 ~16 ~59 glowstone 0  
fill ~32 ~13 ~1 ~33 ~13 ~1 vine 1 
setblock ~32 ~13 ~3 stonebrick 1  
fill ~32 ~13 ~58 ~32 ~16 ~58 vine 1 
setblock ~32 ~13 ~59 stonebrick 2  
fill ~33 ~13 ~4 ~34 ~13 ~4 stonebrick 0  
fill ~33 ~13 ~5 ~33 ~16 ~5 vine 4  
fill ~33 ~13 ~57 ~33 ~16 ~57 vine 1  
fill ~33 ~13 ~58 ~34 ~13 ~58 stonebrick 1  
fill ~34 ~13 ~5 ~34 ~15 ~5 vine 12 
setblock ~35 ~13 ~5 stonebrick 2  
fill ~35 ~13 ~6 ~35 ~40 ~6 vine 4  
fill ~35 ~13 ~56 ~35 ~16 ~56 vine 1 
setblock ~35 ~13 ~57 stonebrick 1 
setblock ~36 ~13 ~5 stonebrick 0  
fill ~36 ~13 ~57 ~36 ~14 ~57 stonebrick 2  
fill ~37 ~13 ~6 ~37 ~16 ~6 diamond_block 0  
fill ~37 ~13 ~56 ~37 ~16 ~56 diamond_block 0  
fill ~56 ~13 ~25 ~56 ~16 ~25 diamond_block 0  
fill ~56 ~13 ~26 ~56 ~16 ~26 vine 12  
fill ~56 ~13 ~27 ~56 ~16 ~27 vine 8  
fill ~56 ~13 ~37 ~56 ~16 ~37 diamond_block 0  
fill ~57 ~13 ~26 ~57 ~14 ~26 stonebrick 0 
setblock ~57 ~13 ~27 stonebrick 1  
fill ~57 ~13 ~28 ~57 ~16 ~28 vine 4  
fill ~57 ~13 ~35 ~57 ~13 ~36 stonebrick 0  
fill ~58 ~13 ~26 ~58 ~15 ~26 vine 2  
fill ~58 ~13 ~28 ~58 ~13 ~29 stonebrick 0  
fill ~58 ~13 ~30 ~58 ~16 ~30 vine 4  
fill ~58 ~13 ~33 ~58 ~13 ~34 stonebrick 0  
fill ~59 ~13 ~28 ~59 ~14 ~28 vine 2  
fill ~59 ~13 ~29 ~59 ~16 ~29 vine 2 
setblock ~59 ~13 ~30 stonebrick 1  
fill ~59 ~13 ~31 ~59 ~16 ~31 glowstone 0 
setblock ~59 ~13 ~32 stonebrick 0  
fill ~60 ~13 ~29 ~60 ~17 ~29 vine 1  
fill ~60 ~13 ~31 ~60 ~15 ~31 vine 2 
setblock ~3 ~14 ~30 stonebrick 0 
setblock ~3 ~14 ~32 stonebrick 2 
setblock ~4 ~14 ~29 stonebrick 1 
setblock ~4 ~14 ~33 stonebrick 1 
setblock ~4 ~14 ~34 stonebrick 0 
setblock ~5 ~14 ~26 stonebrick 0 
setblock ~5 ~14 ~35 stonebrick 1 
setblock ~5 ~14 ~36 stonebrick 0  
fill ~26 ~14 ~5 ~26 ~15 ~5 stonebrick 2  
fill ~26 ~14 ~6 ~27 ~14 ~6 vine 4  
fill ~26 ~14 ~57 ~27 ~14 ~57 stonebrick 1  
fill ~26 ~14 ~60 ~27 ~14 ~60 vine 4 
setblock ~27 ~14 ~5 stonebrick 0 
setblock ~28 ~14 ~4 stonebrick 1  
fill ~28 ~14 ~5 ~29 ~14 ~5 vine 4  
fill ~28 ~14 ~58 ~29 ~14 ~58 stonebrick 2  
fill ~29 ~14 ~4 ~29 ~15 ~4 stonebrick 0  
fill ~30 ~14 ~2 ~31 ~14 ~2 vine 1 
setblock ~30 ~14 ~3 stonebrick 1 
setblock ~30 ~14 ~59 stonebrick 1  
fill ~30 ~14 ~60 ~32 ~14 ~60 vine 4  
fill ~30 ~14 ~62 ~32 ~14 ~62 vine 4  
fill ~32 ~14 ~1 ~33 ~14 ~1 vine 1 
setblock ~32 ~14 ~3 stonebrick 2  
fill ~32 ~14 ~59 ~32 ~15 ~59 stonebrick 0  
fill ~33 ~14 ~4 ~33 ~15 ~4 stonebrick 0  
fill ~33 ~14 ~58 ~33 ~15 ~58 stonebrick 2  
fill ~34 ~14 ~4 ~34 ~16 ~4 stonebrick 2 
setblock ~34 ~14 ~58 stonebrick 1 
setblock ~35 ~14 ~5 stonebrick 1 
setblock ~35 ~14 ~57 stonebrick 0 
setblock ~36 ~14 ~5 stonebrick 2 
setblock ~57 ~14 ~27 stonebrick 0 
setblock ~57 ~14 ~35 stonebrick 1 
setblock ~57 ~14 ~36 stonebrick 2  
fill ~58 ~14 ~28 ~58 ~15 ~28 stonebrick 2  
fill ~58 ~14 ~29 ~58 ~15 ~29 stonebrick 1 
setblock ~58 ~14 ~33 stonebrick 1  
fill ~58 ~14 ~34 ~58 ~15 ~34 stonebrick 2  
fill ~59 ~14 ~25 ~59 ~26 ~25 vine 3  
fill ~59 ~14 ~30 ~59 ~15 ~30 stonebrick 0  
fill ~59 ~14 ~32 ~59 ~15 ~32 stonebrick 2  
fill ~59 ~14 ~35 ~59 ~18 ~35 vine 4  
fill ~62 ~14 ~32 ~62 ~32 ~32 vine 2  
fill ~3 ~15 ~30 ~3 ~16 ~30 stonebrick 1  
fill ~3 ~15 ~32 ~3 ~16 ~32 stonebrick 0 
setblock ~4 ~15 ~29 stonebrick 2  
fill ~4 ~15 ~33 ~4 ~16 ~33 stonebrick 0 
setblock ~4 ~15 ~34 stonebrick 2  
fill ~5 ~15 ~26 ~5 ~16 ~26 stonebrick 1  
fill ~5 ~15 ~35 ~5 ~16 ~35 stonebrick 0  
fill ~5 ~15 ~36 ~5 ~16 ~36 stonebrick 1  
fill ~25 ~15 ~4 ~25 ~18 ~4 vine 8  
fill ~26 ~15 ~6 ~27 ~15 ~6 vine 4 
setblock ~26 ~15 ~57 stonebrick 0  
fill ~26 ~15 ~60 ~27 ~15 ~60 vine 4 
setblock ~27 ~15 ~5 stonebrick 2 
setblock ~27 ~15 ~57 stonebrick 1 
setblock ~28 ~15 ~4 stonebrick 0  
fill ~28 ~15 ~5 ~29 ~15 ~5 vine 4  
fill ~28 ~15 ~58 ~28 ~16 ~58 stonebrick 0 
setblock ~29 ~15 ~58 stonebrick 1  
fill ~30 ~15 ~2 ~31 ~15 ~2 vine 1  
fill ~30 ~15 ~3 ~30 ~16 ~3 stonebrick 0  
fill ~30 ~15 ~59 ~30 ~16 ~59 stonebrick 0  
fill ~30 ~15 ~60 ~32 ~15 ~60 vine 4  
fill ~30 ~15 ~62 ~32 ~15 ~62 vine 4  
fill ~32 ~15 ~1 ~33 ~15 ~1 vine 1 
setblock ~32 ~15 ~3 stonebrick 0  
fill ~34 ~15 ~58 ~34 ~16 ~58 stonebrick 0  
fill ~35 ~15 ~5 ~35 ~16 ~5 stonebrick 0 
setblock ~35 ~15 ~57 stonebrick 1 
setblock ~36 ~15 ~5 stonebrick 1 
setblock ~36 ~15 ~57 stonebrick 0  
fill ~57 ~15 ~26 ~57 ~15 ~27 stonebrick 2  
fill ~57 ~15 ~35 ~57 ~16 ~35 stonebrick 2 
setblock ~57 ~15 ~36 stonebrick 0  
fill ~58 ~15 ~25 ~58 ~17 ~25 vine 2  
fill ~58 ~15 ~33 ~58 ~16 ~33 stonebrick 0 
setblock ~2 ~16 ~31 vine 0 
setblock ~4 ~16 ~29 stonebrick 1 
setblock ~4 ~16 ~34 stonebrick 0 
setblock ~5 ~16 ~27 stonebrick 0 
setblock ~25 ~16 ~57 vine 8  
fill ~25 ~16 ~59 ~25 ~25 ~59 vine 12 
setblock ~26 ~16 ~5 stonebrick 0  
fill ~26 ~16 ~6 ~27 ~16 ~6 vine 4  
fill ~26 ~16 ~57 ~27 ~16 ~57 stonebrick 2  
fill ~26 ~16 ~60 ~27 ~16 ~60 vine 4 
setblock ~27 ~16 ~5 stonebrick 1  
fill ~28 ~16 ~2 ~28 ~17 ~2 vine 1  
fill ~28 ~16 ~4 ~29 ~16 ~4 stonebrick 2  
fill ~28 ~16 ~5 ~29 ~16 ~5 vine 4 
setblock ~29 ~16 ~58 stonebrick 0  
fill ~30 ~16 ~62 ~32 ~16 ~62 vine 4  
fill ~31 ~16 ~60 ~32 ~16 ~60 vine 4  
fill ~32 ~16 ~1 ~33 ~16 ~1 vine 1 
setblock ~32 ~16 ~3 stonebrick 1 
setblock ~32 ~16 ~59 stonebrick 1 
setblock ~33 ~16 ~4 stonebrick 1 
setblock ~33 ~16 ~58 stonebrick 0  
fill ~34 ~16 ~2 ~34 ~17 ~2 vine 1 
setblock ~34 ~16 ~5 vine 8 
setblock ~35 ~16 ~57 stonebrick 0 
setblock ~36 ~16 ~5 stonebrick 2 
setblock ~36 ~16 ~57 stonebrick 1  
fill ~38 ~16 ~5 ~38 ~17 ~5 vine 2 
setblock ~57 ~16 ~26 stonebrick 1 
setblock ~57 ~16 ~27 stonebrick 0 
setblock ~57 ~16 ~36 stonebrick 2 
setblock ~58 ~16 ~28 stonebrick 1 
setblock ~58 ~16 ~29 stonebrick 2 
setblock ~58 ~16 ~34 stonebrick 0 
setblock ~59 ~16 ~30 stonebrick 1 
setblock ~59 ~16 ~32 stonebrick 0  
fill ~60 ~16 ~33 ~60 ~18 ~33 vine 6  
fill ~61 ~16 ~32 ~61 ~20 ~32 vine 2  
fill ~2 ~17 ~30 ~2 ~20 ~30 stonebrick 0  
fill ~2 ~17 ~31 ~2 ~20 ~31 glowstone 0  
fill ~2 ~17 ~32 ~2 ~20 ~32 stonebrick 0 
setblock ~3 ~17 ~28 stonebrick 0 
setblock ~3 ~17 ~29 stonebrick 2 
setblock ~3 ~17 ~33 stonebrick 0 
setblock ~3 ~17 ~34 stonebrick 1  
fill ~4 ~17 ~26 ~4 ~18 ~26 stonebrick 1  
fill ~4 ~17 ~27 ~4 ~18 ~27 stonebrick 0 
setblock ~4 ~17 ~35 stonebrick 1 
setblock ~4 ~17 ~36 stonebrick 2  
fill ~5 ~17 ~25 ~5 ~20 ~25 diamond_block 0  
fill ~5 ~17 ~37 ~5 ~20 ~37 diamond_block 0  
fill ~25 ~17 ~5 ~25 ~20 ~5 diamond_block 0  
fill ~25 ~17 ~57 ~25 ~20 ~57 diamond_block 0  
fill ~25 ~17 ~58 ~25 ~19 ~58 vine 8 
setblock ~26 ~17 ~4 stonebrick 0  
fill ~26 ~17 ~58 ~27 ~17 ~58 stonebrick 0  
fill ~26 ~17 ~60 ~27 ~17 ~60 vine 4  
fill ~27 ~17 ~4 ~27 ~18 ~4 stonebrick 1  
fill ~28 ~17 ~3 ~29 ~17 ~3 stonebrick 2  
fill ~28 ~17 ~5 ~29 ~17 ~5 vine 4  
fill ~28 ~17 ~58 ~28 ~20 ~58 vine 1 
setblock ~28 ~17 ~59 stonebrick 2 
setblock ~29 ~17 ~59 stonebrick 0 
setblock ~30 ~17 ~2 stonebrick 0  
fill ~30 ~17 ~60 ~30 ~18 ~60 stonebrick 0  
fill ~30 ~17 ~62 ~32 ~17 ~62 vine 4  
fill ~31 ~17 ~2 ~31 ~20 ~2 glowstone 0  
fill ~31 ~17 ~59 ~32 ~17 ~59 vine 1  
fill ~31 ~17 ~60 ~31 ~20 ~60 glowstone 0  
fill ~32 ~17 ~1 ~33 ~17 ~1 vine 1 
setblock ~32 ~17 ~2 stonebrick 1 
setblock ~32 ~17 ~60 stonebrick 0  
fill ~33 ~17 ~3 ~33 ~18 ~3 stonebrick 2  
fill ~33 ~17 ~58 ~33 ~20 ~58 vine 1 
setblock ~33 ~17 ~59 stonebrick 1  
fill ~34 ~17 ~3 ~34 ~18 ~3 stonebrick 0  
fill ~34 ~17 ~4 ~34 ~20 ~4 vine 8  
fill ~34 ~17 ~58 ~34 ~20 ~58 vine 8 
setblock ~34 ~17 ~59 stonebrick 0  
fill ~34 ~17 ~60 ~34 ~18 ~60 vine 4  
fill ~34 ~17 ~61 ~34 ~28 ~61 vine 4  
fill ~35 ~17 ~3 ~35 ~18 ~3 vine 2  
fill ~35 ~17 ~4 ~35 ~20 ~4 stonebrick 0  
fill ~35 ~17 ~57 ~35 ~20 ~57 vine 1  
fill ~35 ~17 ~58 ~35 ~20 ~58 stonebrick 0 
setblock ~36 ~17 ~4 stonebrick 1  
fill ~36 ~17 ~5 ~36 ~18 ~5 vine 4 
setblock ~36 ~17 ~58 stonebrick 1  
fill ~37 ~17 ~4 ~38 ~17 ~4 vine 2  
fill ~37 ~17 ~5 ~37 ~20 ~5 diamond_block 0  
fill ~37 ~17 ~57 ~37 ~20 ~57 diamond_block 0  
fill ~56 ~17 ~37 ~56 ~18 ~37 vine 8  
fill ~57 ~17 ~25 ~57 ~20 ~25 diamond_block 0 
setblock ~57 ~17 ~26 vine 4  
fill ~57 ~17 ~27 ~57 ~18 ~27 vine 8 
setblock ~57 ~17 ~35 vine 8  
fill ~57 ~17 ~37 ~57 ~20 ~37 diamond_block 0  
fill ~58 ~17 ~26 ~58 ~20 ~26 stonebrick 0  
fill ~58 ~17 ~27 ~58 ~17 ~26 stonebrick 0  
fill ~58 ~17 ~28 ~58 ~18 ~28 vine 12  
fill ~58 ~17 ~29 ~58 ~20 ~29 vine 8  
fill ~58 ~17 ~34 ~58 ~20 ~34 vine 8  
fill ~58 ~17 ~35 ~58 ~18 ~35 stonebrick 1  
fill ~58 ~17 ~36 ~58 ~19 ~36 stonebrick 0  
fill ~59 ~17 ~28 ~59 ~17 ~29 stonebrick 2  
fill ~59 ~17 ~30 ~59 ~37 ~30 vine 4  
fill ~59 ~17 ~33 ~59 ~17 ~34 stonebrick 2  
fill ~60 ~17 ~30 ~60 ~20 ~30 stonebrick 0  
fill ~60 ~17 ~31 ~60 ~20 ~31 glowstone 0  
fill ~60 ~17 ~32 ~60 ~18 ~32 stonebrick 0  
fill ~60 ~17 ~34 ~60 ~20 ~34 vine 2  
fill ~61 ~17 ~33 ~61 ~26 ~33 vine 6  
fill ~3 ~18 ~28 ~3 ~20 ~28 stonebrick 2  
fill ~3 ~18 ~29 ~3 ~20 ~29 stonebrick 0 
setblock ~3 ~18 ~33 stonebrick 1  
fill ~3 ~18 ~34 ~3 ~19 ~34 stonebrick 0 
setblock ~4 ~18 ~35 stonebrick 2  
fill ~4 ~18 ~36 ~4 ~19 ~36 stonebrick 1  
fill ~13 ~18 ~29 ~13 ~54 ~29 vine 2  
fill ~26 ~18 ~4 ~26 ~19 ~4 stonebrick 1  
fill ~26 ~18 ~58 ~27 ~18 ~58 stonebrick 0  
fill ~26 ~18 ~60 ~27 ~18 ~60 vine 4 
setblock ~27 ~18 ~3 vine 1  
fill ~28 ~18 ~1 ~28 ~32 ~1 vine 1  
fill ~28 ~18 ~3 ~29 ~18 ~3 stonebrick 0  
fill ~28 ~18 ~5 ~29 ~18 ~5 vine 4 
setblock ~28 ~18 ~59 stonebrick 1  
fill ~29 ~18 ~59 ~29 ~19 ~59 stonebrick 2 
setblock ~30 ~18 ~2 stonebrick 1  
fill ~30 ~18 ~62 ~32 ~18 ~62 vine 4  
fill ~31 ~18 ~6 ~31 ~45 ~6 vine 4  
fill ~31 ~18 ~59 ~32 ~18 ~59 vine 1  
fill ~32 ~18 ~1 ~34 ~18 ~1 vine 1 
setblock ~32 ~18 ~2 stonebrick 2 
setblock ~32 ~18 ~60 stonebrick 2  
fill ~33 ~18 ~59 ~34 ~18 ~59 stonebrick 2 
setblock ~36 ~18 ~4 stonebrick 0 
setblock ~36 ~18 ~58 stonebrick 2  
fill ~37 ~18 ~3 ~37 ~30 ~3 vine 3  
fill ~38 ~18 ~4 ~38 ~32 ~4 vine 2 
setblock ~58 ~18 ~27 stonebrick 2  
fill ~59 ~18 ~28 ~59 ~18 ~29 stonebrick 0 
setblock ~59 ~18 ~33 stonebrick 1 
setblock ~59 ~18 ~34 stonebrick 2 
setblock ~3 ~19 ~33 stonebrick 2 
setblock ~4 ~19 ~26 stonebrick 2 
setblock ~4 ~19 ~27 stonebrick 1 
setblock ~4 ~19 ~35 stonebrick 1  
fill ~12 ~19 ~28 ~12 ~52 ~28 vine 2  
fill ~13 ~19 ~24 ~13 ~52 ~24 vine 1  
fill ~25 ~19 ~3 ~25 ~22 ~3 vine 9 
setblock ~26 ~19 ~58 stonebrick 2  
fill ~26 ~19 ~60 ~27 ~19 ~60 vine 4  
fill ~27 ~19 ~4 ~27 ~20 ~4 stonebrick 2 
setblock ~27 ~19 ~58 stonebrick 0 
setblock ~28 ~19 ~3 stonebrick 2  
fill ~28 ~19 ~5 ~29 ~19 ~5 vine 4  
fill ~28 ~19 ~59 ~28 ~20 ~59 stonebrick 0  
fill ~29 ~19 ~3 ~29 ~20 ~3 stonebrick 0 
setblock ~30 ~19 ~2 stonebrick 2 
setblock ~30 ~19 ~60 stonebrick 2  
fill ~30 ~19 ~62 ~32 ~19 ~62 vine 4  
fill ~31 ~19 ~59 ~32 ~19 ~59 vine 1 
setblock ~32 ~19 ~2 stonebrick 0  
fill ~32 ~19 ~51 ~32 ~52 ~51 vine 1  
fill ~32 ~19 ~60 ~32 ~20 ~60 stonebrick 1  
fill ~33 ~19 ~1 ~34 ~19 ~1 vine 1 
setblock ~33 ~19 ~3 stonebrick 1  
fill ~33 ~19 ~59 ~33 ~18 ~59 stonebrick 2 
setblock ~34 ~19 ~3 stonebrick 2  
fill ~34 ~19 ~59 ~34 ~20 ~59 stonebrick 0  
fill ~35 ~19 ~2 ~35 ~32 ~2 vine 1  
fill ~36 ~19 ~4 ~36 ~20 ~4 stonebrick 1  
fill ~36 ~19 ~58 ~36 ~20 ~58 stonebrick 0  
fill ~58 ~19 ~27 ~58 ~20 ~27 stonebrick 0  
fill ~58 ~19 ~28 ~58 ~20 ~28 vine 8 
setblock ~58 ~19 ~35 stonebrick 0 
setblock ~59 ~19 ~28 stonebrick 1 
setblock ~59 ~19 ~29 stonebrick 0 
setblock ~59 ~19 ~33 stonebrick 0 
setblock ~59 ~19 ~34 stonebrick 1 
setblock ~60 ~19 ~32 stonebrick 2  
fill ~60 ~19 ~33 ~60 ~20 ~33 vine 2 
setblock ~3 ~20 ~33 stonebrick 0 
setblock ~3 ~20 ~34 stonebrick 1 
setblock ~4 ~20 ~26 stonebrick 1 
setblock ~4 ~20 ~27 stonebrick 0 
setblock ~4 ~20 ~35 stonebrick 2 
setblock ~4 ~20 ~36 stonebrick 0 
setblock ~26 ~20 ~4 stonebrick 0 
setblock ~26 ~20 ~58 stonebrick 0  
fill ~26 ~20 ~60 ~27 ~20 ~60 vine 4 
setblock ~27 ~20 ~58 stonebrick 1 
setblock ~28 ~20 ~3 stonebrick 0  
fill ~28 ~20 ~5 ~29 ~20 ~5 vine 4  
fill ~28 ~20 ~7 ~28 ~45 ~7 vine 6  
fill ~29 ~20 ~10 ~29 ~50 ~10 vine 4 
setblock ~29 ~20 ~59 stonebrick 1 
setblock ~30 ~20 ~2 stonebrick 1 
setblock ~30 ~20 ~60 stonebrick 0  
fill ~30 ~20 ~62 ~32 ~20 ~62 vine 4  
fill ~31 ~20 ~12 ~31 ~54 ~12 vine 4  
fill ~31 ~20 ~59 ~32 ~20 ~59 vine 1 
setblock ~32 ~20 ~2 stonebrick 1  
fill ~33 ~20 ~1 ~34 ~20 ~1 vine 1  
fill ~33 ~20 ~3 ~34 ~20 ~3 stonebrick 0 
setblock ~33 ~20 ~59 stonebrick 0  
fill ~58 ~20 ~35 ~58 ~20 ~36 stonebrick 1 
setblock ~59 ~20 ~28 stonebrick 0 
setblock ~59 ~20 ~29 stonebrick 1 
setblock ~59 ~20 ~33 stonebrick 2 
setblock ~59 ~20 ~34 stonebrick 0 
setblock ~60 ~20 ~32 stonebrick 0  
fill ~60 ~20 ~35 ~60 ~25 ~35 vine 2  
fill ~61 ~20 ~28 ~61 ~30 ~28 vine 2  
fill ~62 ~20 ~31 ~62 ~30 ~31 vine 2  
fill ~1 ~21 ~30 ~1 ~33 ~30 stonebrick 0  
fill ~1 ~21 ~31 ~1 ~33 ~31 glowstone 0  
fill ~1 ~21 ~32 ~1 ~33 ~32 stonebrick 0  
fill ~1 ~21 ~33 ~1 ~25 ~33 vine 12  
fill ~1 ~21 ~34 ~1 ~30 ~34 vine 8  
fill ~2 ~21 ~28 ~2 ~33 ~28 stonebrick 0  
fill ~2 ~21 ~29 ~2 ~33 ~29 stonebrick 0  
fill ~2 ~21 ~30 ~2 ~28 ~30 vine 6  
fill ~2 ~21 ~31 ~2 ~32 ~31 vine 2  
fill ~2 ~21 ~32 ~2 ~33 ~32 vine 3  
fill ~2 ~21 ~33 ~2 ~33 ~33 stonebrick 0  
fill ~2 ~21 ~34 ~2 ~33 ~34 stonebrick 0  
fill ~2 ~21 ~35 ~2 ~31 ~35 vine 8  
fill ~2 ~21 ~36 ~2 ~30 ~36 vine 8  
fill ~3 ~21 ~26 ~3 ~25 ~26 stonebrick 0 
setblock ~3 ~21 ~27 stonebrick 2  
fill ~3 ~21 ~28 ~3 ~28 ~28 vine 4  
fill ~3 ~21 ~33 ~3 ~33 ~33 vine 2  
fill ~3 ~21 ~35 ~3 ~22 ~35 stonebrick 0 
setblock ~3 ~21 ~36 stonebrick 2  
fill ~4 ~21 ~25 ~4 ~33 ~25 diamond_block 0  
fill ~4 ~21 ~26 ~4 ~30 ~26 vine 6  
fill ~4 ~21 ~27 ~4 ~30 ~27 vine 2  
fill ~4 ~21 ~36 ~4 ~27 ~36 vine 3  
fill ~4 ~21 ~37 ~4 ~33 ~37 diamond_block 0  
fill ~5 ~21 ~25 ~5 ~30 ~25 vine 2  
fill ~25 ~21 ~4 ~25 ~33 ~4 diamond_block 0  
fill ~25 ~21 ~57 ~25 ~29 ~57 vine 1   
fill ~25 ~21 ~58 ~25 ~33 ~58 diamond_block 0 
setblock ~26 ~21 ~3 stonebrick 2  
fill ~26 ~21 ~4 ~27 ~21 ~4 vine 4  
fill ~26 ~21 ~58 ~26 ~29 ~58 vine 2 
setblock ~26 ~21 ~59 stonebrick 1  
fill ~26 ~21 ~60 ~27 ~21 ~60 vine 4  
fill ~27 ~21 ~3 ~27 ~22 ~3 stonebrick 0  
fill ~27 ~21 ~58 ~27 ~26 ~58 vine 1  
fill ~27 ~21 ~59 ~27 ~23 ~59 stonebrick 0  
fill ~28 ~21 ~2 ~28 ~25 ~2 stonebrick 0  
fill ~28 ~21 ~3 ~28 ~30 ~3 vine 6  
fill ~28 ~21 ~5 ~29 ~21 ~5 vine 4  
fill ~28 ~21 ~60 ~29 ~21 ~60 stonebrick 0 
setblock ~29 ~21 ~2 stonebrick 2  
fill ~29 ~21 ~3 ~29 ~26 ~3 vine 4 
setblock ~30 ~21 ~1 stonebrick 2  
fill ~30 ~21 ~2 ~30 ~23 ~2 vine 6  
fill ~30 ~21 ~60 ~30 ~23 ~60 vine 1 
setblock ~30 ~21 ~61 stonebrick 1  
fill ~30 ~21 ~62 ~32 ~21 ~62 vine 4  
fill ~31 ~21 ~1 ~31 ~33 ~1 glowstone 0  
fill ~31 ~21 ~2 ~31 ~23 ~2 vine 4  
fill ~31 ~21 ~59 ~31 ~37 ~59 vine 1  
fill ~31 ~21 ~61 ~31 ~33 ~61 glowstone 0 
setblock ~32 ~21 ~1 stonebrick 1  
fill ~32 ~21 ~2 ~32 ~23 ~2 vine 12  
fill ~32 ~21 ~60 ~32 ~29 ~60 vine 1 
setblock ~32 ~21 ~61 stonebrick 2  
fill ~33 ~21 ~1 ~34 ~21 ~1 vine 1  
fill ~33 ~21 ~2 ~34 ~21 ~2 stonebrick 0  
fill ~33 ~21 ~3 ~33 ~29 ~3 vine 4  
fill ~33 ~21 ~59 ~33 ~26 ~59 vine 1 
setblock ~33 ~21 ~60 stonebrick 1  
fill ~34 ~21 ~3 ~34 ~29 ~3 vine 12  
fill ~34 ~21 ~59 ~34 ~27 ~59 vine 9  
fill ~34 ~21 ~60 ~34 ~23 ~60 stonebrick 0  
fill ~35 ~21 ~3 ~36 ~21 ~3 stonebrick 0  
fill ~35 ~21 ~4 ~35 ~29 ~4 vine 4  
fill ~35 ~21 ~58 ~36 ~21 ~58 vine 1  
fill ~35 ~21 ~59 ~36 ~21 ~59 stonebrick 2  
fill ~36 ~21 ~4 ~36 ~25 ~4 vine 12  
fill ~37 ~21 ~4 ~37 ~33 ~4 diamond_block 0  
fill ~37 ~21 ~5 ~37 ~25 ~5 vine 4  
fill ~37 ~21 ~57 ~37 ~29 ~57 vine 1  
fill ~37 ~21 ~58 ~37 ~33 ~58 diamond_block 0  
fill ~57 ~21 ~25 ~57 ~27 ~25 vine 8  
fill ~58 ~21 ~25 ~58 ~33 ~25 diamond_block 0  
fill ~58 ~21 ~26 ~58 ~25 ~26 vine 12  
fill ~58 ~21 ~27 ~58 ~30 ~27 vine 8  
fill ~58 ~21 ~35 ~58 ~33 ~35 vine 8  
fill ~58 ~21 ~36 ~58 ~31 ~36 vine 8  
fill ~58 ~21 ~37 ~58 ~33 ~37 diamond_block 0  
fill ~59 ~21 ~26 ~59 ~22 ~26 stonebrick 2  
fill ~59 ~21 ~27 ~59 ~22 ~27 stonebrick 0  
fill ~59 ~21 ~29 ~59 ~27 ~29 vine 8  
fill ~59 ~21 ~34 ~59 ~33 ~34 vine 9  
fill ~59 ~21 ~35 ~59 ~21 ~36 stonebrick 2  
fill ~60 ~21 ~26 ~60 ~33 ~26 vine 2  
fill ~60 ~21 ~27 ~60 ~26 ~27 vine 3  
fill ~60 ~21 ~28 ~60 ~25 ~28 stonebrick 0  
fill ~60 ~21 ~29 ~60 ~21 ~28 stonebrick 0  
fill ~60 ~21 ~30 ~60 ~28 ~30 vine 8  
fill ~60 ~21 ~33 ~60 ~21 ~34 stonebrick 0  
fill ~60 ~21 ~36 ~60 ~28 ~36 vine 2  
fill ~61 ~21 ~29 ~61 ~25 ~29 vine 1 
setblock ~61 ~21 ~30 stonebrick 1  
fill ~61 ~21 ~31 ~61 ~33 ~31 glowstone 0 
setblock ~61 ~21 ~32 stonebrick 1  
fill ~62 ~21 ~30 ~62 ~25 ~30 vine 2 
setblock ~3 ~22 ~27 stonebrick 1 
setblock ~3 ~22 ~36 stonebrick 0 
setblock ~26 ~22 ~3 stonebrick 1  
fill ~26 ~22 ~4 ~27 ~22 ~4 vine 4  
fill ~26 ~22 ~59 ~26 ~23 ~59 stonebrick 2  
fill ~26 ~22 ~60 ~27 ~22 ~60 vine 4  
fill ~28 ~22 ~5 ~29 ~22 ~5 vine 4  
fill ~28 ~22 ~60 ~28 ~23 ~60 stonebrick 2  
fill ~29 ~22 ~2 ~29 ~23 ~2 stonebrick 0 
setblock ~29 ~22 ~60 stonebrick 1  
fill ~30 ~22 ~1 ~30 ~23 ~1 stonebrick 0  
fill ~30 ~22 ~61 ~30 ~23 ~61 stonebrick 2  
fill ~30 ~22 ~62 ~32 ~22 ~62 vine 4 
setblock ~32 ~22 ~1 stonebrick 0  
fill ~32 ~22 ~61 ~32 ~23 ~61 stonebrick 0  
fill ~33 ~22 ~1 ~34 ~22 ~1 vine 1  
fill ~33 ~22 ~2 ~33 ~25 ~2 stonebrick 0 
setblock ~33 ~22 ~60 stonebrick 2  
fill ~34 ~22 ~2 ~34 ~26 ~2 stonebrick 1 
setblock ~35 ~22 ~3 stonebrick 2  
fill ~35 ~22 ~58 ~36 ~22 ~58 vine 1  
fill ~35 ~22 ~59 ~35 ~21 ~59 stonebrick 2 
setblock ~36 ~22 ~3 stonebrick 1 
setblock ~36 ~22 ~59 stonebrick 1  
fill ~59 ~22 ~35 ~59 ~23 ~35 stonebrick 0 
setblock ~59 ~22 ~36 stonebrick 1 
setblock ~60 ~22 ~29 stonebrick 1 
setblock ~60 ~22 ~33 stonebrick 2 
setblock ~60 ~22 ~34 stonebrick 1 
setblock ~61 ~22 ~30 stonebrick 2 
setblock ~61 ~22 ~32 stonebrick 0 
setblock ~3 ~23 ~27 stonebrick 2 
setblock ~3 ~23 ~35 stonebrick 1 
setblock ~3 ~23 ~36 stonebrick 2  
fill ~25 ~23 ~3 ~25 ~27 ~3 vine 1  
fill ~26 ~23 ~3 ~27 ~23 ~3 stonebrick 2  
fill ~26 ~23 ~4 ~27 ~23 ~4 vine 4  
fill ~26 ~23 ~60 ~27 ~23 ~60 vine 4  
fill ~28 ~23 ~5 ~29 ~23 ~5 vine 4 
setblock ~29 ~23 ~60 stonebrick 2  
fill ~30 ~23 ~62 ~32 ~23 ~62 vine 4 
setblock ~32 ~23 ~1 stonebrick 2  
fill ~33 ~23 ~1 ~34 ~23 ~1 vine 1 
setblock ~33 ~23 ~60 stonebrick 0  
fill ~35 ~23 ~3 ~35 ~27 ~3 stonebrick 0  
fill ~35 ~23 ~58 ~36 ~23 ~58 vine 1  
fill ~35 ~23 ~59 ~36 ~23 ~59 stonebrick 0 
setblock ~36 ~23 ~3 stonebrick 2  
fill ~59 ~23 ~26 ~59 ~23 ~27 stonebrick 1  
fill ~59 ~23 ~36 ~59 ~24 ~36 stonebrick 0 
setblock ~60 ~23 ~29 stonebrick 2 
setblock ~60 ~23 ~33 stonebrick 1 
setblock ~60 ~23 ~34 stonebrick 2  
fill ~61 ~23 ~30 ~61 ~24 ~30 stonebrick 0 
setblock ~61 ~23 ~32 stonebrick 1 
setblock ~3 ~24 ~27 stonebrick 0  
fill ~3 ~24 ~35 ~3 ~26 ~35 stonebrick 0 
setblock ~3 ~24 ~36 stonebrick 1  
fill ~26 ~24 ~3 ~27 ~24 ~3 stonebrick 0  
fill ~26 ~24 ~4 ~27 ~24 ~4 vine 4 
setblock ~26 ~24 ~59 stonebrick 0  
fill ~26 ~24 ~60 ~27 ~24 ~60 vine 4 
setblock ~27 ~24 ~59 stonebrick 1  
fill ~28 ~24 ~5 ~29 ~24 ~5 vine 4  
fill ~28 ~24 ~60 ~29 ~24 ~60 stonebrick 0 
setblock ~29 ~24 ~2 stonebrick 2  
fill ~29 ~24 ~55 ~29 ~44 ~55 vine 1  
fill ~30 ~24 ~1 ~30 ~25 ~1 stonebrick 2  
fill ~30 ~24 ~2 ~30 ~25 ~2 vine 4 
setblock ~30 ~24 ~61 stonebrick 0  
fill ~30 ~24 ~62 ~32 ~24 ~62 vine 4  
fill ~32 ~24 ~1 ~32 ~26 ~1 stonebrick 0  
fill ~32 ~24 ~2 ~32 ~27 ~2 vine 8 
setblock ~32 ~24 ~61 stonebrick 1  
fill ~33 ~24 ~1 ~34 ~24 ~1 vine 1 
setblock ~33 ~24 ~60 stonebrick 2  
fill ~34 ~24 ~60 ~34 ~27 ~60 stonebrick 1  
fill ~35 ~24 ~58 ~36 ~24 ~58 vine 1  
fill ~35 ~24 ~59 ~36 ~24 ~59 stonebrick 0 
setblock ~36 ~24 ~3 stonebrick 1  
fill ~59 ~24 ~26 ~59 ~24 ~27 stonebrick 2 
setblock ~59 ~24 ~35 stonebrick 1 
setblock ~60 ~24 ~29 stonebrick 1  
fill ~60 ~24 ~33 ~60 ~25 ~33 stonebrick 0  
fill ~60 ~24 ~34 ~60 ~25 ~34 stonebrick 0  
fill ~61 ~24 ~32 ~61 ~25 ~32 stonebrick 2 
setblock ~3 ~25 ~27 stonebrick 2 
setblock ~3 ~25 ~36 stonebrick 2  
fill ~26 ~25 ~3 ~26 ~26 ~3 stonebrick 2  
fill ~26 ~25 ~4 ~27 ~25 ~4 vine 4  
fill ~26 ~25 ~59 ~27 ~25 ~59 stonebrick 2  
fill ~26 ~25 ~60 ~27 ~25 ~60 vine 4  
fill ~27 ~25 ~3 ~27 ~26 ~3 stonebrick 1  
fill ~28 ~25 ~5 ~29 ~25 ~5 vine 4 
setblock ~28 ~25 ~60 stonebrick 2  
fill ~29 ~25 ~2 ~29 ~27 ~2 stonebrick 0  
fill ~29 ~25 ~60 ~29 ~27 ~60 stonebrick 0  
fill ~30 ~25 ~54 ~30 ~48 ~54 vine 1  
fill ~30 ~25 ~61 ~30 ~26 ~61 stonebrick 1  
fill ~30 ~25 ~62 ~32 ~25 ~62 vine 4  
fill ~32 ~25 ~61 ~32 ~26 ~61 stonebrick 0  
fill ~33 ~25 ~1 ~34 ~25 ~1 vine 1  
fill ~33 ~25 ~60 ~33 ~26 ~60 stonebrick 1  
fill ~35 ~25 ~58 ~36 ~25 ~58 vine 1  
fill ~35 ~25 ~59 ~36 ~25 ~59 stonebrick 0 
setblock ~36 ~25 ~3 stonebrick 0  
fill ~59 ~25 ~26 ~59 ~25 ~27 stonebrick 0 
setblock ~59 ~25 ~35 stonebrick 2 
setblock ~59 ~25 ~36 stonebrick 1  
fill ~60 ~25 ~29 ~60 ~30 ~29 stonebrick 0  
fill ~61 ~25 ~30 ~61 ~26 ~30 stonebrick 1  
fill ~1 ~26 ~33 ~1 ~32 ~33 vine 8  
fill ~3 ~26 ~26 ~3 ~27 ~26 stonebrick 2 
setblock ~3 ~26 ~27 stonebrick 0 
setblock ~3 ~26 ~36 stonebrick 1  
fill ~25 ~26 ~59 ~25 ~31 ~59 vine 4  
fill ~26 ~26 ~4 ~27 ~26 ~4 vine 4  
fill ~26 ~26 ~59 ~27 ~26 ~59 stonebrick 0  
fill ~26 ~26 ~60 ~27 ~26 ~60 vine 4 
setblock ~28 ~26 ~2 stonebrick 2  
fill ~28 ~26 ~5 ~29 ~26 ~5 vine 4  
fill ~28 ~26 ~60 ~28 ~29 ~60 stonebrick 0 
setblock ~30 ~26 ~1 stonebrick 0  
fill ~30 ~26 ~62 ~32 ~26 ~62 vine 4  
fill ~33 ~26 ~1 ~34 ~26 ~1 vine 1 
setblock ~33 ~26 ~2 stonebrick 1  
fill ~33 ~26 ~58 ~33 ~35 ~58 vine 1  
fill ~35 ~26 ~58 ~36 ~26 ~58 vine 1  
fill ~35 ~26 ~59 ~36 ~26 ~59 stonebrick 0 
setblock ~36 ~26 ~3 stonebrick 2  
fill ~36 ~26 ~4 ~36 ~29 ~4 vine 4  
fill ~58 ~26 ~26 ~58 ~28 ~26 vine 8 
setblock ~59 ~26 ~26 stonebrick 2 
setblock ~59 ~26 ~27 stonebrick 1  
fill ~59 ~26 ~35 ~59 ~27 ~35 stonebrick 0  
fill ~59 ~26 ~36 ~59 ~27 ~36 stonebrick 2 
setblock ~60 ~26 ~28 stonebrick 1 
setblock ~60 ~26 ~33 stonebrick 1 
setblock ~60 ~26 ~34 stonebrick 2 
setblock ~61 ~26 ~32 stonebrick 0 
setblock ~3 ~27 ~27 stonebrick 1 
setblock ~3 ~27 ~35 stonebrick 1  
fill ~3 ~27 ~36 ~3 ~28 ~36 stonebrick 0  
fill ~26 ~27 ~3 ~27 ~27 ~3 stonebrick 0  
fill ~26 ~27 ~4 ~27 ~27 ~4 vine 4 
setblock ~26 ~27 ~59 stonebrick 1  
fill ~26 ~27 ~60 ~27 ~27 ~60 vine 4  
fill ~27 ~27 ~59 ~27 ~29 ~59 stonebrick 0 
setblock ~28 ~27 ~2 stonebrick 0  
fill ~28 ~27 ~5 ~29 ~27 ~5 vine 4 
setblock ~30 ~27 ~1 stonebrick 1  
fill ~30 ~27 ~58 ~30 ~39 ~58 vine 2  
fill ~30 ~27 ~61 ~30 ~28 ~61 stonebrick 0  
fill ~30 ~27 ~62 ~31 ~27 ~62 vine 4  
fill ~32 ~27 ~1 ~32 ~28 ~1 stonebrick 1 
setblock ~32 ~27 ~61 stonebrick 1  
fill ~33 ~27 ~1 ~34 ~27 ~1 vine 1  
fill ~33 ~27 ~2 ~34 ~27 ~2 stonebrick 0  
fill ~33 ~27 ~60 ~33 ~29 ~60 stonebrick 2  
fill ~35 ~27 ~58 ~35 ~29 ~58 vine 1  
fill ~35 ~27 ~59 ~35 ~28 ~59 stonebrick 2 
setblock ~36 ~27 ~3 stonebrick 1 
setblock ~36 ~27 ~59 stonebrick 1  
fill ~50 ~27 ~30 ~50 ~54 ~30 vine 8  
fill ~59 ~27 ~25 ~59 ~31 ~25 vine 2 
setblock ~59 ~27 ~26 stonebrick 1  
fill ~59 ~27 ~27 ~59 ~29 ~27 stonebrick 2  
fill ~60 ~27 ~27 ~60 ~32 ~27 vine 2 
setblock ~60 ~27 ~28 stonebrick 0  
fill ~60 ~27 ~33 ~60 ~31 ~33 stonebrick 0 
setblock ~60 ~27 ~34 stonebrick 1 
setblock ~61 ~27 ~30 stonebrick 0 
setblock ~61 ~27 ~32 stonebrick 1  
fill ~61 ~27 ~33 ~61 ~32 ~33 vine 4  
fill ~3 ~28 ~26 ~3 ~28 ~27 stonebrick 0  
fill ~3 ~28 ~35 ~3 ~31 ~35 stonebrick 0  
fill ~4 ~28 ~36 ~4 ~31 ~36 vine 1  
fill ~26 ~28 ~3 ~27 ~28 ~3 stonebrick 1  
fill ~26 ~28 ~4 ~27 ~28 ~4 vine 4  
fill ~26 ~28 ~59 ~26 ~30 ~59 stonebrick 2  
fill ~26 ~28 ~60 ~27 ~28 ~60 vine 4 
setblock ~28 ~28 ~2 stonebrick 1  
fill ~28 ~28 ~5 ~29 ~28 ~5 vine 4 
setblock ~29 ~28 ~2 stonebrick 2 
setblock ~29 ~28 ~60 stonebrick 2 
setblock ~30 ~28 ~1 stonebrick 2  
fill ~30 ~28 ~62 ~31 ~28 ~62 vine 4 
setblock ~32 ~28 ~61 stonebrick 0  
fill ~33 ~28 ~1 ~34 ~28 ~1 vine 1  
fill ~33 ~28 ~2 ~34 ~28 ~2 stonebrick 1  
fill ~33 ~28 ~61 ~33 ~31 ~61 vine 2  
fill ~34 ~28 ~59 ~34 ~32 ~59 vine 8 
setblock ~34 ~28 ~60 stonebrick 0 
setblock ~35 ~28 ~3 stonebrick 1 
setblock ~36 ~28 ~3 stonebrick 2 
setblock ~36 ~28 ~59 stonebrick 2 
setblock ~59 ~28 ~26 stonebrick 0  
fill ~59 ~28 ~35 ~59 ~28 ~36 stonebrick 1 
setblock ~60 ~28 ~28 stonebrick 1 
setblock ~60 ~28 ~34 stonebrick 0  
fill ~61 ~28 ~30 ~61 ~29 ~30 stonebrick 1  
fill ~61 ~28 ~32 ~61 ~29 ~32 stonebrick 0  
fill ~2 ~29 ~27 ~2 ~31 ~27 vine 8  
fill ~2 ~29 ~30 ~2 ~30 ~30 vine 4  
fill ~3 ~29 ~26 ~3 ~32 ~26 stonebrick 1 
setblock ~3 ~29 ~27 stonebrick 0 
setblock ~3 ~29 ~36 stonebrick 2 
setblock ~26 ~29 ~3 stonebrick 0  
fill ~26 ~29 ~4 ~27 ~29 ~4 vine 4  
fill ~27 ~29 ~3 ~27 ~30 ~3 stonebrick 1  
fill ~27 ~29 ~60 ~27 ~31 ~60 vine 4 
setblock ~28 ~29 ~2 stonebrick 2  
fill ~28 ~29 ~5 ~29 ~29 ~5 vine 4 
setblock ~29 ~29 ~2 stonebrick 0 
setblock ~29 ~29 ~60 stonebrick 1  
fill ~30 ~29 ~1 ~30 ~30 ~1 stonebrick 0  
fill ~30 ~29 ~56 ~30 ~45 ~56 vine 2 
setblock ~30 ~29 ~61 stonebrick 1  
fill ~30 ~29 ~62 ~31 ~29 ~62 vine 4  
fill ~32 ~29 ~1 ~32 ~33 ~1 stonebrick 0  
fill ~32 ~29 ~61 ~32 ~31 ~61 stonebrick 1 
setblock ~33 ~29 ~2 stonebrick 0  
fill ~34 ~29 ~1 ~34 ~31 ~1 vine 1 
setblock ~34 ~29 ~2 stonebrick 2 
setblock ~34 ~29 ~60 stonebrick 2  
fill ~35 ~29 ~3 ~36 ~29 ~3 stonebrick 0  
fill ~35 ~29 ~59 ~36 ~29 ~59 stonebrick 0 
setblock ~59 ~29 ~26 stonebrick 2  
fill ~59 ~29 ~35 ~59 ~32 ~35 stonebrick 0 
setblock ~59 ~29 ~36 stonebrick 1  
fill ~59 ~29 ~37 ~59 ~32 ~37 vine 2 
setblock ~60 ~29 ~28 stonebrick 0  
fill ~60 ~29 ~34 ~60 ~30 ~34 stonebrick 2 
setblock ~3 ~30 ~27 stonebrick 2 
setblock ~3 ~30 ~36 stonebrick 1 
setblock ~26 ~30 ~3 stonebrick 1  
fill ~26 ~30 ~4 ~27 ~30 ~4 vine 4 
setblock ~27 ~30 ~59 stonebrick 1  
fill ~28 ~30 ~2 ~28 ~31 ~2 stonebrick 0  
fill ~28 ~30 ~5 ~29 ~30 ~5 vine 4 
setblock ~28 ~30 ~60 stonebrick 1 
setblock ~29 ~30 ~2 stonebrick 2 
setblock ~29 ~30 ~60 stonebrick 2  
fill ~30 ~30 ~61 ~30 ~31 ~61 stonebrick 0  
fill ~30 ~30 ~62 ~31 ~30 ~62 vine 4  
fill ~32 ~30 ~59 ~32 ~34 ~59 vine 1  
fill ~33 ~30 ~2 ~33 ~31 ~2 stonebrick 2  
fill ~33 ~30 ~60 ~34 ~30 ~60 stonebrick 0  
fill ~34 ~30 ~2 ~34 ~31 ~2 stonebrick 0 
setblock ~34 ~30 ~3 vine 8  
fill ~35 ~30 ~3 ~36 ~30 ~3 stonebrick 0  
fill ~35 ~30 ~59 ~36 ~30 ~59 stonebrick 0  
fill ~51 ~30 ~28 ~51 ~51 ~28 vine 8 
setblock ~59 ~30 ~26 stonebrick 1  
fill ~59 ~30 ~27 ~59 ~32 ~27 stonebrick 0 
setblock ~59 ~30 ~36 stonebrick 0  
fill ~60 ~30 ~28 ~60 ~31 ~28 stonebrick 2 
setblock ~61 ~30 ~30 stonebrick 2 
setblock ~61 ~30 ~32 stonebrick 2 
setblock ~3 ~31 ~27 stonebrick 0 
setblock ~3 ~31 ~36 stonebrick 0  
fill ~26 ~31 ~3 ~26 ~32 ~3 stonebrick 2  
fill ~26 ~31 ~59 ~26 ~32 ~59 stonebrick 0 
setblock ~27 ~31 ~3 stonebrick 0 
setblock ~27 ~31 ~59 stonebrick 2  
fill ~28 ~31 ~5 ~29 ~31 ~5 vine 4  
fill ~28 ~31 ~60 ~29 ~31 ~60 stonebrick 0 
setblock ~29 ~31 ~2 stonebrick 0 
setblock ~29 ~31 ~61 vine 4 
setblock ~30 ~31 ~1 stonebrick 2 
setblock ~31 ~31 ~62 vine 4  
fill ~33 ~31 ~60 ~33 ~32 ~60 stonebrick 2 
setblock ~34 ~31 ~60 stonebrick 1  
fill ~35 ~31 ~3 ~36 ~31 ~3 stonebrick 0  
fill ~35 ~31 ~59 ~35 ~32 ~59 stonebrick 1  
fill ~36 ~31 ~59 ~36 ~33 ~59 stonebrick 0  
fill ~37 ~31 ~3 ~37 ~32 ~3 vine 1  
fill ~52 ~31 ~24 ~53 ~31 ~24 vine 1  
fill ~57 ~31 ~28 ~57 ~41 ~28 vine 4  
fill ~59 ~31 ~26 ~59 ~33 ~26 stonebrick 0  
fill ~59 ~31 ~36 ~59 ~32 ~36 stonebrick 2 
setblock ~60 ~31 ~29 stonebrick 2  
fill ~60 ~31 ~34 ~60 ~32 ~34 stonebrick 0 
setblock ~61 ~31 ~30 stonebrick 1 
setblock ~61 ~31 ~32 stonebrick 1 
setblock ~3 ~32 ~27 stonebrick 2  
fill ~3 ~32 ~35 ~3 ~33 ~35 stonebrick 2  
fill ~3 ~32 ~36 ~3 ~33 ~36 stonebrick 1 
setblock ~27 ~32 ~3 stonebrick 2  
fill ~27 ~32 ~59 ~27 ~33 ~59 stonebrick 0 
setblock ~28 ~32 ~2 stonebrick 1  
fill ~28 ~32 ~5 ~29 ~32 ~5 vine 4  
fill ~28 ~32 ~60 ~29 ~32 ~60 stonebrick 0 
setblock ~29 ~32 ~2 stonebrick 2 
setblock ~30 ~32 ~1 stonebrick 0 
setblock ~30 ~32 ~61 stonebrick 1  
fill ~32 ~32 ~61 ~32 ~33 ~61 stonebrick 2 
setblock ~33 ~32 ~2 stonebrick 0 
setblock ~34 ~32 ~2 stonebrick 1  
fill ~34 ~32 ~60 ~34 ~33 ~60 stonebrick 0  
fill ~35 ~32 ~3 ~36 ~32 ~3 stonebrick 0 
setblock ~35 ~32 ~60 vine 2  
fill ~52 ~32 ~24 ~53 ~32 ~24 vine 1  
fill ~52 ~32 ~27 ~52 ~49 ~27 vine 8  
fill ~60 ~32 ~28 ~60 ~32 ~29 stonebrick 0  
fill ~60 ~32 ~33 ~60 ~33 ~33 stonebrick 2 
setblock ~61 ~32 ~30 stonebrick 0  
fill ~61 ~32 ~32 ~61 ~33 ~32 stonebrick 0 
setblock ~3 ~33 ~26 stonebrick 2 
setblock ~3 ~33 ~27 stonebrick 0 
setblock ~26 ~33 ~3 stonebrick 1 
setblock ~26 ~33 ~59 stonebrick 1 
setblock ~27 ~33 ~3 stonebrick 0 
setblock ~28 ~33 ~2 stonebrick 2  
fill ~28 ~33 ~5 ~29 ~33 ~5 vine 4 
setblock ~28 ~33 ~60 stonebrick 1 
setblock ~29 ~33 ~2 stonebrick 0 
setblock ~29 ~33 ~60 stonebrick 2 
setblock ~30 ~33 ~1 stonebrick 2 
setblock ~30 ~33 ~61 stonebrick 0 
setblock ~33 ~33 ~2 stonebrick 2 
setblock ~33 ~33 ~60 stonebrick 1 
setblock ~34 ~33 ~2 stonebrick 0  
fill ~34 ~33 ~58 ~34 ~34 ~58 vine 8  
fill ~35 ~33 ~3 ~36 ~33 ~3 stonebrick 2 
setblock ~35 ~33 ~59 stonebrick 0  
fill ~52 ~33 ~24 ~53 ~33 ~24 vine 1  
fill ~58 ~33 ~29 ~58 ~37 ~29 vine 8 
setblock ~59 ~33 ~27 stonebrick 2 
setblock ~59 ~33 ~33 vine 0 
setblock ~59 ~33 ~35 stonebrick 1 
setblock ~59 ~33 ~36 stonebrick 0  
fill ~60 ~33 ~28 ~60 ~33 ~29 stonebrick 2 
setblock ~60 ~33 ~34 stonebrick 2 
setblock ~61 ~33 ~30 stonebrick 1  
fill ~2 ~34 ~30 ~2 ~37 ~30 stonebrick 0  
fill ~2 ~34 ~31 ~2 ~37 ~31 glowstone 0  
fill ~2 ~34 ~32 ~2 ~37 ~32 stonebrick 0 
setblock ~3 ~34 ~28 stonebrick 2 
setblock ~3 ~34 ~29 stonebrick 1  
fill ~3 ~34 ~33 ~3 ~34 ~34 stonebrick 1 
setblock ~4 ~34 ~26 stonebrick 0 
setblock ~4 ~34 ~27 stonebrick 1 
setblock ~4 ~34 ~35 stonebrick 0 
setblock ~4 ~34 ~36 stonebrick 1  
fill ~5 ~34 ~25 ~5 ~37 ~25 diamond_block 0  
fill ~5 ~34 ~37 ~5 ~37 ~37 diamond_block 0  
fill ~25 ~34 ~5 ~25 ~37 ~5 diamond_block 0  
fill ~25 ~34 ~57 ~25 ~37 ~57 diamond_block 0 
setblock ~26 ~34 ~4 stonebrick 0  
fill ~26 ~34 ~58 ~27 ~34 ~58 stonebrick 1 
setblock ~27 ~34 ~4 stonebrick 2 
setblock ~28 ~34 ~3 stonebrick 2  
fill ~28 ~34 ~5 ~29 ~34 ~5 vine 4  
fill ~28 ~34 ~58 ~28 ~36 ~58 vine 1 
setblock ~28 ~34 ~59 stonebrick 2 
setblock ~29 ~34 ~3 stonebrick 0  
fill ~29 ~34 ~59 ~29 ~37 ~59 stonebrick 0  
fill ~30 ~34 ~2 ~30 ~35 ~2 stonebrick 0 
setblock ~30 ~34 ~60 stonebrick 0  
fill ~31 ~34 ~2 ~31 ~37 ~2 glowstone 0  
fill ~31 ~34 ~60 ~31 ~37 ~60 glowstone 0 
setblock ~32 ~34 ~2 stonebrick 2 
setblock ~32 ~34 ~60 stonebrick 0  
fill ~32 ~34 ~61 ~32 ~36 ~61 vine 4  
fill ~33 ~34 ~3 ~34 ~34 ~3 stonebrick 0 
setblock ~33 ~34 ~59 stonebrick 0  
fill ~33 ~34 ~60 ~33 ~35 ~60 vine 2  
fill ~34 ~34 ~4 ~34 ~35 ~4 vine 8  
fill ~34 ~34 ~5 ~34 ~40 ~5 vine 8 
setblock ~34 ~34 ~59 stonebrick 2  
fill ~35 ~34 ~4 ~35 ~36 ~4 stonebrick 0  
fill ~35 ~34 ~56 ~35 ~40 ~56 vine 1  
fill ~35 ~34 ~57 ~35 ~35 ~57 vine 1  
fill ~35 ~34 ~58 ~36 ~34 ~58 stonebrick 0  
fill ~35 ~34 ~59 ~35 ~37 ~59 vine 2 
setblock ~36 ~34 ~4 stonebrick 2  
fill ~37 ~34 ~5 ~37 ~37 ~5 diamond_block 0  
fill ~37 ~34 ~57 ~37 ~37 ~57 diamond_block 0  
fill ~52 ~34 ~24 ~53 ~34 ~24 vine 1  
fill ~57 ~34 ~25 ~57 ~37 ~25 diamond_block 0  
fill ~57 ~34 ~37 ~57 ~37 ~37 diamond_block 0 
setblock ~58 ~34 ~26 stonebrick 2 
setblock ~58 ~34 ~27 stonebrick 0  
fill ~58 ~34 ~28 ~58 ~36 ~28 vine 8  
fill ~58 ~34 ~35 ~58 ~34 ~36 stonebrick 2  
fill ~59 ~34 ~28 ~59 ~34 ~29 stonebrick 0  
fill ~59 ~34 ~33 ~59 ~35 ~33 stonebrick 0 
setblock ~59 ~34 ~34 stonebrick 1  
fill ~60 ~34 ~30 ~60 ~36 ~30 stonebrick 0  
fill ~60 ~34 ~31 ~60 ~37 ~31 glowstone 0 
setblock ~60 ~34 ~32 stonebrick 0  
fill ~3 ~35 ~28 ~3 ~36 ~28 stonebrick 0 
setblock ~3 ~35 ~29 stonebrick 2  
fill ~3 ~35 ~33 ~3 ~35 ~34 stonebrick 0 
setblock ~4 ~35 ~26 stonebrick 2 
setblock ~4 ~35 ~27 stonebrick 0 
setblock ~4 ~35 ~35 stonebrick 1  
fill ~4 ~35 ~36 ~4 ~37 ~36 stonebrick 0 
setblock ~26 ~35 ~4 stonebrick 2  
fill ~26 ~35 ~58 ~27 ~35 ~58 stonebrick 0  
fill ~27 ~35 ~4 ~27 ~37 ~4 stonebrick 0 
setblock ~28 ~35 ~3 stonebrick 0  
fill ~28 ~35 ~5 ~29 ~35 ~5 vine 4  
fill ~28 ~35 ~59 ~28 ~36 ~59 stonebrick 1 
setblock ~29 ~35 ~3 stonebrick 2 
setblock ~30 ~35 ~60 stonebrick 2  
fill ~32 ~35 ~2 ~32 ~37 ~2 stonebrick 0 
setblock ~32 ~35 ~60 stonebrick 1 
setblock ~33 ~35 ~3 stonebrick 2  
fill ~33 ~35 ~59 ~34 ~35 ~59 stonebrick 1 
setblock ~34 ~35 ~3 stonebrick 0 
setblock ~35 ~35 ~58 stonebrick 1  
fill ~36 ~35 ~4 ~36 ~36 ~4 stonebrick 0 
setblock ~36 ~35 ~58 stonebrick 2  
fill ~52 ~35 ~24 ~53 ~35 ~24 vine 1 
setblock ~58 ~35 ~26 stonebrick 1 
setblock ~58 ~35 ~27 stonebrick 2  
fill ~58 ~35 ~35 ~58 ~37 ~35 stonebrick 0  
fill ~58 ~35 ~36 ~58 ~35 ~35 stonebrick 0 
setblock ~59 ~35 ~28 stonebrick 2  
fill ~59 ~35 ~29 ~59 ~37 ~29 stonebrick 0  
fill ~59 ~35 ~34 ~59 ~37 ~34 stonebrick 0 
setblock ~60 ~35 ~32 stonebrick 1  
fill ~3 ~36 ~29 ~3 ~37 ~29 stonebrick 0 
setblock ~3 ~36 ~33 stonebrick 1 
setblock ~3 ~36 ~34 stonebrick 0  
fill ~4 ~36 ~26 ~4 ~37 ~26 stonebrick 0 
setblock ~4 ~36 ~27 stonebrick 2 
setblock ~4 ~36 ~35 stonebrick 0 
setblock ~26 ~36 ~4 stonebrick 0  
fill ~26 ~36 ~58 ~26 ~37 ~58 stonebrick 1  
fill ~27 ~36 ~58 ~27 ~37 ~58 stonebrick 0 
setblock ~28 ~36 ~3 stonebrick 2  
fill ~28 ~36 ~5 ~29 ~36 ~5 vine 4  
fill ~28 ~36 ~57 ~28 ~39 ~57 vine 3 
setblock ~29 ~36 ~3 stonebrick 0  
fill ~30 ~36 ~2 ~30 ~37 ~2 stonebrick 1  
fill ~30 ~36 ~60 ~30 ~37 ~60 stonebrick 0 
setblock ~32 ~36 ~60 stonebrick 0  
fill ~33 ~36 ~3 ~33 ~37 ~3 stonebrick 0  
fill ~33 ~36 ~59 ~33 ~37 ~59 stonebrick 0  
fill ~34 ~36 ~3 ~34 ~37 ~3 stonebrick 1  
fill ~34 ~36 ~59 ~34 ~37 ~59 stonebrick 2  
fill ~35 ~36 ~58 ~36 ~36 ~58 stonebrick 0  
fill ~52 ~36 ~24 ~53 ~36 ~24 vine 1  
fill ~58 ~36 ~26 ~58 ~37 ~26 stonebrick 0  
fill ~58 ~36 ~27 ~58 ~36 ~26 stonebrick 0 
setblock ~58 ~36 ~36 stonebrick 2 
setblock ~59 ~36 ~28 stonebrick 0 
setblock ~59 ~36 ~33 stonebrick 1 
setblock ~60 ~36 ~32 stonebrick 2 
setblock ~3 ~37 ~28 stonebrick 2 
setblock ~3 ~37 ~33 stonebrick 0 
setblock ~3 ~37 ~34 stonebrick 2 
setblock ~4 ~37 ~27 stonebrick 0 
setblock ~4 ~37 ~35 stonebrick 1 
setblock ~26 ~37 ~4 stonebrick 1 
setblock ~28 ~37 ~3 stonebrick 0  
fill ~28 ~37 ~5 ~29 ~37 ~5 vine 4 
setblock ~28 ~37 ~59 stonebrick 0 
setblock ~29 ~37 ~3 stonebrick 1  
fill ~32 ~37 ~58 ~32 ~40 ~58 vine 1 
setblock ~32 ~37 ~60 stonebrick 1  
fill ~35 ~37 ~4 ~36 ~37 ~4 stonebrick 2 
setblock ~35 ~37 ~58 stonebrick 1 
setblock ~36 ~37 ~58 stonebrick 0  
fill ~52 ~37 ~24 ~53 ~37 ~24 vine 1  
fill ~56 ~37 ~26 ~56 ~41 ~26 vine 12 
setblock ~58 ~37 ~27 stonebrick 2 
setblock ~58 ~37 ~36 stonebrick 1 
setblock ~59 ~37 ~28 stonebrick 1 
setblock ~59 ~37 ~33 stonebrick 2 
setblock ~60 ~37 ~30 stonebrick 2 
setblock ~60 ~37 ~32 stonebrick 0  
fill ~3 ~38 ~30 ~3 ~40 ~30 stonebrick 0  
fill ~3 ~38 ~31 ~3 ~41 ~31 glowstone 0 
setblock ~3 ~38 ~32 stonebrick 1 
setblock ~4 ~38 ~28 stonebrick 1 
setblock ~4 ~38 ~29 stonebrick 0  
fill ~4 ~38 ~33 ~4 ~38 ~34 stonebrick 0  
fill ~5 ~38 ~26 ~5 ~41 ~26 stonebrick 0  
fill ~5 ~38 ~27 ~5 ~39 ~27 stonebrick 2 
setblock ~5 ~38 ~35 stonebrick 2 
setblock ~5 ~38 ~36 stonebrick 0  
fill ~6 ~38 ~25 ~6 ~41 ~25 diamond_block 0  
fill ~6 ~38 ~37 ~6 ~41 ~37 diamond_block 0  
fill ~25 ~38 ~6 ~25 ~41 ~6 diamond_block 0  
fill ~25 ~38 ~56 ~25 ~41 ~56 diamond_block 0 
setblock ~26 ~38 ~5 stonebrick 1  
fill ~26 ~38 ~57 ~26 ~39 ~57 stonebrick 0  
fill ~27 ~38 ~5 ~27 ~41 ~5 stonebrick 0  
fill ~27 ~38 ~6 ~27 ~41 ~6 vine 4  
fill ~27 ~38 ~7 ~27 ~42 ~7 vine 4  
fill ~27 ~38 ~57 ~27 ~39 ~57 stonebrick 1  
fill ~27 ~38 ~58 ~27 ~40 ~58 vine 8 
setblock ~28 ~38 ~4 stonebrick 0  
fill ~28 ~38 ~5 ~29 ~38 ~5 vine 4 
setblock ~28 ~38 ~58 stonebrick 1  
fill ~29 ~38 ~4 ~29 ~40 ~4 stonebrick 1  
fill ~29 ~38 ~58 ~29 ~40 ~58 stonebrick 0  
fill ~29 ~38 ~59 ~29 ~39 ~59 vine 4 
setblock ~30 ~38 ~3 stonebrick 2  
fill ~30 ~38 ~59 ~30 ~40 ~59 stonebrick 0  
fill ~30 ~38 ~60 ~31 ~38 ~60 vine 4  
fill ~31 ~38 ~3 ~31 ~41 ~3 glowstone 0  
fill ~31 ~38 ~59 ~31 ~41 ~59 glowstone 0  
fill ~32 ~38 ~3 ~32 ~39 ~3 stonebrick 1  
fill ~32 ~38 ~59 ~32 ~39 ~59 stonebrick 0 
setblock ~33 ~38 ~4 stonebrick 2  
fill ~33 ~38 ~57 ~33 ~39 ~57 vine 1  
fill ~33 ~38 ~58 ~33 ~39 ~58 stonebrick 0 
setblock ~33 ~38 ~59 vine 2 
setblock ~34 ~38 ~4 stonebrick 0 
setblock ~34 ~38 ~58 stonebrick 2  
fill ~34 ~38 ~59 ~34 ~39 ~59 vine 4  
fill ~35 ~38 ~5 ~35 ~41 ~5 stonebrick 0  
fill ~35 ~38 ~57 ~36 ~38 ~57 stonebrick 0  
fill ~36 ~38 ~5 ~36 ~40 ~5 stonebrick 1  
fill ~37 ~38 ~6 ~37 ~41 ~6 diamond_block 0  
fill ~37 ~38 ~56 ~37 ~41 ~56 diamond_block 0  
fill ~52 ~38 ~24 ~53 ~38 ~24 vine 1  
fill ~56 ~38 ~25 ~56 ~41 ~25 diamond_block 0  
fill ~56 ~38 ~27 ~56 ~41 ~27 vine 8  
fill ~56 ~38 ~37 ~56 ~41 ~37 diamond_block 0  
fill ~57 ~38 ~26 ~57 ~41 ~26 stonebrick 0  
fill ~57 ~38 ~27 ~57 ~38 ~26 stonebrick 0  
fill ~57 ~38 ~35 ~57 ~39 ~35 stonebrick 2 
setblock ~57 ~38 ~36 stonebrick 0 
setblock ~58 ~38 ~28 stonebrick 0 
setblock ~58 ~38 ~29 stonebrick 2 
setblock ~58 ~38 ~33 stonebrick 2 
setblock ~58 ~38 ~34 stonebrick 1  
fill ~59 ~38 ~30 ~59 ~39 ~30 stonebrick 2  
fill ~59 ~38 ~31 ~59 ~41 ~31 glowstone 0 
setblock ~59 ~38 ~32 stonebrick 0 
setblock ~3 ~39 ~32 stonebrick 0  
fill ~4 ~39 ~28 ~4 ~40 ~28 stonebrick 0 
setblock ~4 ~39 ~29 stonebrick 1  
fill ~4 ~39 ~33 ~4 ~40 ~33 stonebrick 1 
setblock ~4 ~39 ~34 stonebrick 0  
fill ~5 ~39 ~35 ~5 ~41 ~35 stonebrick 0 
setblock ~5 ~39 ~36 stonebrick 1 
setblock ~26 ~39 ~5 stonebrick 0  
fill ~28 ~39 ~4 ~28 ~41 ~4 stonebrick 1  
fill ~28 ~39 ~5 ~29 ~39 ~5 vine 4 
setblock ~28 ~39 ~58 stonebrick 0 
setblock ~30 ~39 ~3 stonebrick 1  
fill ~30 ~39 ~60 ~31 ~39 ~60 vine 4 
setblock ~33 ~39 ~4 stonebrick 1 
setblock ~34 ~39 ~4 stonebrick 2 
setblock ~34 ~39 ~58 stonebrick 0  
fill ~35 ~39 ~57 ~35 ~38 ~57 stonebrick 0 
setblock ~36 ~39 ~57 stonebrick 1  
fill ~52 ~39 ~24 ~53 ~39 ~24 vine 1 
setblock ~57 ~39 ~27 stonebrick 2 
setblock ~57 ~39 ~36 stonebrick 2 
setblock ~58 ~39 ~28 stonebrick 1  
fill ~58 ~39 ~29 ~58 ~41 ~29 stonebrick 0  
fill ~58 ~39 ~33 ~58 ~41 ~33 stonebrick 1  
fill ~58 ~39 ~34 ~58 ~40 ~34 stonebrick 0 
setblock ~59 ~39 ~32 stonebrick 2  
fill ~3 ~40 ~32 ~3 ~41 ~32 stonebrick 1 
setblock ~4 ~40 ~29 stonebrick 0  
fill ~4 ~40 ~34 ~4 ~41 ~34 stonebrick 1 
setblock ~5 ~40 ~27 stonebrick 0 
setblock ~5 ~40 ~36 stonebrick 2 
setblock ~26 ~40 ~5 stonebrick 2  
fill ~26 ~40 ~57 ~27 ~40 ~57 stonebrick 2  
fill ~28 ~40 ~5 ~29 ~40 ~5 vine 4 
setblock ~28 ~40 ~57 vine 1 
setblock ~28 ~40 ~58 stonebrick 2  
fill ~30 ~40 ~3 ~30 ~41 ~3 stonebrick 0  
fill ~30 ~40 ~60 ~31 ~40 ~60 vine 4 
setblock ~32 ~40 ~3 stonebrick 2 
setblock ~32 ~40 ~59 stonebrick 1  
fill ~33 ~40 ~4 ~33 ~41 ~4 stonebrick 0  
fill ~33 ~40 ~56 ~33 ~43 ~56 vine 1 
setblock ~33 ~40 ~58 stonebrick 1 
setblock ~34 ~40 ~4 stonebrick 1 
setblock ~34 ~40 ~58 stonebrick 2 
setblock ~35 ~40 ~57 stonebrick 2  
fill ~36 ~40 ~57 ~36 ~41 ~57 stonebrick 0  
fill ~52 ~40 ~24 ~53 ~40 ~24 vine 1 
setblock ~57 ~40 ~27 stonebrick 1  
fill ~57 ~40 ~35 ~57 ~41 ~35 stonebrick 0  
fill ~57 ~40 ~36 ~57 ~41 ~36 stonebrick 0 
setblock ~58 ~40 ~28 stonebrick 2  
fill ~59 ~40 ~30 ~59 ~41 ~30 stonebrick 0 
setblock ~59 ~40 ~32 stonebrick 1 
setblock ~3 ~41 ~30 stonebrick 1  
fill ~4 ~41 ~28 ~4 ~41 ~29 stonebrick 1 
setblock ~4 ~41 ~33 stonebrick 0 
setblock ~5 ~41 ~27 stonebrick 1 
setblock ~5 ~41 ~36 stonebrick 1 
setblock ~26 ~41 ~5 stonebrick 1 
setblock ~26 ~41 ~57 stonebrick 1 
setblock ~27 ~41 ~57 stonebrick 2  
fill ~28 ~41 ~5 ~28 ~13 ~5 vine 4 
setblock ~28 ~41 ~58 stonebrick 0 
setblock ~29 ~41 ~4 stonebrick 0 
setblock ~29 ~41 ~58 stonebrick 1  
fill ~30 ~41 ~6 ~30 ~44 ~6 vine 4 
setblock ~30 ~41 ~59 stonebrick 2  
fill ~30 ~41 ~60 ~30 ~38 ~60 vine 4 
setblock ~32 ~41 ~3 stonebrick 0  
fill ~32 ~41 ~57 ~32 ~43 ~57 vine 8 
setblock ~32 ~41 ~59 stonebrick 0 
setblock ~33 ~41 ~58 stonebrick 0 
setblock ~34 ~41 ~4 stonebrick 0 
setblock ~34 ~41 ~58 stonebrick 1 
setblock ~35 ~41 ~57 stonebrick 0 
setblock ~36 ~41 ~5 stonebrick 0  
fill ~52 ~41 ~24 ~53 ~41 ~24 vine 1 
setblock ~57 ~41 ~27 stonebrick 0 
setblock ~58 ~41 ~28 stonebrick 0 
setblock ~58 ~41 ~34 stonebrick 2 
setblock ~59 ~41 ~32 stonebrick 0 
setblock ~4 ~42 ~30 stonebrick 1  
fill ~4 ~42 ~31 ~4 ~43 ~31 glowstone 0 
setblock ~4 ~42 ~32 stonebrick 0  
fill ~5 ~42 ~28 ~5 ~43 ~28 stonebrick 0  
fill ~5 ~42 ~29 ~5 ~42 ~28 stonebrick 0  
fill ~5 ~42 ~33 ~5 ~43 ~33 stonebrick 0  
fill ~5 ~42 ~34 ~5 ~43 ~34 stonebrick 0  
fill ~6 ~42 ~26 ~6 ~43 ~26 stonebrick 0 
setblock ~6 ~42 ~27 stonebrick 1  
fill ~6 ~42 ~35 ~6 ~42 ~36 stonebrick 0  
fill ~7 ~42 ~25 ~7 ~43 ~25 diamond_block 0  
fill ~7 ~42 ~37 ~7 ~43 ~37 diamond_block 0  
fill ~25 ~42 ~7 ~25 ~43 ~7 diamond_block 0  
fill ~25 ~42 ~55 ~25 ~43 ~55 diamond_block 0 
setblock ~25 ~42 ~56 vine 12  
fill ~26 ~42 ~6 ~27 ~42 ~6 stonebrick 0  
fill ~26 ~42 ~56 ~27 ~42 ~56 stonebrick 1 
setblock ~26 ~42 ~57 vine 4 
setblock ~27 ~42 ~57 vine 12 
setblock ~28 ~42 ~5 stonebrick 2  
fill ~28 ~42 ~57 ~28 ~43 ~57 stonebrick 0 
setblock ~29 ~42 ~5 stonebrick 0 
setblock ~29 ~42 ~57 stonebrick 1 
setblock ~30 ~42 ~4 stonebrick 0 
setblock ~30 ~42 ~5 vine 4  
fill ~30 ~42 ~58 ~30 ~43 ~58 stonebrick 1  
fill ~31 ~42 ~4 ~31 ~43 ~4 glowstone 0  
fill ~31 ~42 ~58 ~31 ~43 ~58 glowstone 0  
fill ~32 ~42 ~4 ~32 ~43 ~4 stonebrick 1  
fill ~32 ~42 ~53 ~32 ~50 ~53 vine 8 
setblock ~32 ~42 ~58 stonebrick 1 
setblock ~33 ~42 ~5 stonebrick 0  
fill ~33 ~42 ~57 ~33 ~43 ~57 stonebrick 2 
setblock ~34 ~42 ~5 stonebrick 2  
fill ~34 ~42 ~57 ~34 ~43 ~57 stonebrick 0 
setblock ~35 ~42 ~6 stonebrick 1  
fill ~35 ~42 ~56 ~36 ~42 ~56 stonebrick 0 
setblock ~36 ~42 ~6 stonebrick 2  
fill ~37 ~42 ~7 ~37 ~43 ~7 diamond_block 0  
fill ~37 ~42 ~55 ~37 ~43 ~55 diamond_block 0  
fill ~52 ~42 ~24 ~53 ~42 ~24 vine 1  
fill ~55 ~42 ~25 ~55 ~43 ~25 diamond_block 0  
fill ~55 ~42 ~37 ~55 ~43 ~37 diamond_block 0 
setblock ~56 ~42 ~26 stonebrick 0 
setblock ~56 ~42 ~27 stonebrick 2 
setblock ~56 ~42 ~35 stonebrick 0 
setblock ~56 ~42 ~36 stonebrick 2  
fill ~57 ~42 ~28 ~57 ~42 ~29 stonebrick 0 
setblock ~57 ~42 ~33 stonebrick 2 
setblock ~57 ~42 ~34 stonebrick 0  
fill ~58 ~42 ~30 ~58 ~43 ~30 stonebrick 0  
fill ~58 ~42 ~31 ~58 ~43 ~31 glowstone 0 
setblock ~58 ~42 ~32 stonebrick 1 
setblock ~4 ~43 ~30 stonebrick 2 
setblock ~4 ~43 ~32 stonebrick 2 
setblock ~5 ~43 ~29 stonebrick 2 
setblock ~6 ~43 ~27 stonebrick 0 
setblock ~6 ~43 ~35 stonebrick 2 
setblock ~6 ~43 ~36 stonebrick 0 
setblock ~25 ~43 ~56 vine 8 
setblock ~26 ~43 ~6 stonebrick 2  
fill ~26 ~43 ~56 ~27 ~43 ~56 stonebrick 0 
setblock ~27 ~43 ~6 stonebrick 1 
setblock ~27 ~43 ~57 vine 8 
setblock ~28 ~43 ~5 stonebrick 0 
setblock ~29 ~43 ~5 stonebrick 2  
fill ~29 ~43 ~51 ~29 ~51 ~51 vine 1 
setblock ~29 ~43 ~57 stonebrick 2 
setblock ~30 ~43 ~4 stonebrick 2  
fill ~31 ~43 ~31 ~31 ~45 ~31 gold_block 0 
setblock ~32 ~43 ~58 stonebrick 0 
setblock ~33 ~43 ~5 stonebrick 1 
setblock ~34 ~43 ~5 stonebrick 0  
fill ~34 ~43 ~51 ~34 ~51 ~51 vine 8  
fill ~35 ~43 ~6 ~36 ~43 ~6 stonebrick 0  
fill ~35 ~43 ~56 ~35 ~42 ~56 stonebrick 0 
setblock ~36 ~43 ~56 stonebrick 2  
fill ~52 ~43 ~24 ~53 ~43 ~24 vine 1 
setblock ~56 ~43 ~26 stonebrick 2 
setblock ~56 ~43 ~27 stonebrick 1 
setblock ~56 ~43 ~35 stonebrick 2 
setblock ~56 ~43 ~36 stonebrick 1 
setblock ~57 ~43 ~28 stonebrick 2 
setblock ~57 ~43 ~29 stonebrick 0  
fill ~57 ~43 ~33 ~57 ~43 ~34 stonebrick 1 
setblock ~58 ~43 ~32 stonebrick 0 
setblock ~5 ~44 ~30 stonebrick 0  
fill ~5 ~44 ~31 ~5 ~45 ~31 glowstone 0 
setblock ~5 ~44 ~32 stonebrick 1  
fill ~6 ~44 ~28 ~6 ~44 ~29 stonebrick 1  
fill ~6 ~44 ~33 ~6 ~44 ~34 stonebrick 1  
fill ~7 ~44 ~26 ~7 ~45 ~26 stonebrick 2 
setblock ~7 ~44 ~27 stonebrick 0 
setblock ~7 ~44 ~35 stonebrick 2 
setblock ~7 ~44 ~36 stonebrick 1  
fill ~8 ~44 ~25 ~8 ~45 ~25 diamond_block 0  
fill ~8 ~44 ~37 ~8 ~45 ~37 diamond_block 0  
fill ~25 ~44 ~8 ~25 ~45 ~8 diamond_block 0  
fill ~25 ~44 ~54 ~25 ~45 ~54 diamond_block 0  
fill ~25 ~44 ~55 ~25 ~45 ~55 vine 8  
fill ~26 ~44 ~7 ~27 ~44 ~7 stonebrick 2  
fill ~26 ~44 ~55 ~27 ~44 ~55 stonebrick 0 
setblock ~26 ~44 ~56 vine 4 
setblock ~28 ~44 ~6 stonebrick 2  
fill ~28 ~44 ~35 ~28 ~65 ~35 vine 8  
fill ~28 ~44 ~53 ~28 ~49 ~53 vine 1  
fill ~28 ~44 ~56 ~28 ~45 ~56 stonebrick 1  
fill ~29 ~44 ~6 ~29 ~45 ~6 stonebrick 0  
fill ~29 ~44 ~28 ~29 ~57 ~28 vine 8 
setblock ~29 ~44 ~56 stonebrick 0 
setblock ~30 ~44 ~5 stonebrick 0  
fill ~30 ~44 ~51 ~30 ~53 ~51 vine 1  
fill ~30 ~44 ~57 ~30 ~45 ~57 stonebrick 0  
fill ~31 ~44 ~5 ~31 ~45 ~5 glowstone 0  
fill ~31 ~44 ~23 ~31 ~87 ~23 vine 4  
fill ~31 ~44 ~27 ~31 ~59 ~27 vine 1  
fill ~31 ~44 ~57 ~31 ~45 ~57 glowstone 0 
setblock ~32 ~44 ~5 stonebrick 0 
setblock ~32 ~44 ~57 stonebrick 0  
fill ~33 ~44 ~6 ~33 ~45 ~6 stonebrick 1  
fill ~33 ~44 ~50 ~33 ~53 ~50 vine 1  
fill ~33 ~44 ~56 ~34 ~44 ~56 stonebrick 0 
setblock ~34 ~44 ~6 stonebrick 0  
fill ~35 ~44 ~7 ~35 ~45 ~7 stonebrick 0 
setblock ~35 ~44 ~55 stonebrick 0 
setblock ~36 ~44 ~7 stonebrick 1 
setblock ~36 ~44 ~55 stonebrick 1  
fill ~37 ~44 ~8 ~37 ~45 ~8 diamond_block 0  
fill ~37 ~44 ~54 ~37 ~45 ~54 diamond_block 0  
fill ~52 ~44 ~24 ~53 ~44 ~24 vine 1  
fill ~54 ~44 ~25 ~54 ~45 ~25 diamond_block 0  
fill ~54 ~44 ~37 ~54 ~45 ~37 diamond_block 0  
fill ~55 ~44 ~26 ~55 ~45 ~26 stonebrick 2  
fill ~55 ~44 ~27 ~55 ~44 ~26 stonebrick 2  
fill ~55 ~44 ~35 ~55 ~44 ~36 stonebrick 1  
fill ~56 ~44 ~28 ~56 ~45 ~28 stonebrick 2 
setblock ~56 ~44 ~29 stonebrick 1  
fill ~56 ~44 ~33 ~56 ~45 ~33 stonebrick 0  
fill ~56 ~44 ~34 ~56 ~44 ~33 stonebrick 0 
setblock ~57 ~44 ~30 stonebrick 2  
fill ~57 ~44 ~31 ~57 ~45 ~31 glowstone 0  
fill ~57 ~44 ~32 ~57 ~45 ~32 stonebrick 0 
setblock ~5 ~45 ~30 stonebrick 1 
setblock ~5 ~45 ~32 stonebrick 0 
setblock ~6 ~45 ~28 stonebrick 2 
setblock ~6 ~45 ~29 stonebrick 1   
fill ~6 ~45 ~33 ~6 ~45 ~34 stonebrick 2 
setblock ~7 ~45 ~27 stonebrick 1  
fill ~7 ~45 ~35 ~7 ~45 ~36 stonebrick 0  
fill ~26 ~45 ~7 ~27 ~45 ~7 stonebrick 0  
fill ~26 ~45 ~34 ~26 ~66 ~34 vine 8  
fill ~26 ~45 ~55 ~26 ~44 ~55 stonebrick 0 
setblock ~27 ~45 ~55 stonebrick 2 
setblock ~28 ~45 ~6 stonebrick 1  
fill ~28 ~45 ~29 ~28 ~59 ~29 vine 9 
setblock ~29 ~45 ~56 stonebrick 2 
setblock ~30 ~45 ~5 stonebrick 1  
fill ~30 ~45 ~27 ~30 ~60 ~27 vine 1 
setblock ~32 ~45 ~5 stonebrick 1 
setblock ~32 ~45 ~57 stonebrick 2  
fill ~33 ~45 ~56 ~33 ~44 ~56 stonebrick 0 
setblock ~34 ~45 ~6 stonebrick 1 
setblock ~34 ~45 ~56 stonebrick 1 
setblock ~35 ~45 ~55 stonebrick 1 
setblock ~36 ~45 ~7 stonebrick 0  
fill ~36 ~45 ~24 ~36 ~79 ~24 vine 4 
setblock ~36 ~45 ~55 stonebrick 0  
fill ~52 ~45 ~24 ~53 ~45 ~24 vine 1 
setblock ~55 ~45 ~27 stonebrick 0  
fill ~55 ~45 ~35 ~55 ~45 ~36 stonebrick 0 
setblock ~56 ~45 ~29 stonebrick 2 
setblock ~56 ~45 ~34 stonebrick 2 
setblock ~57 ~45 ~30 stonebrick 0 
setblock ~6 ~46 ~30 stonebrick 2  
fill ~6 ~46 ~31 ~6 ~47 ~31 glowstone 0  
fill ~6 ~46 ~32 ~6 ~47 ~32 stonebrick 0  
fill ~7 ~46 ~28 ~7 ~47 ~28 stonebrick 2  
fill ~7 ~46 ~29 ~7 ~46 ~28 stonebrick 2  
fill ~7 ~46 ~33 ~7 ~47 ~33 stonebrick 0 
setblock ~7 ~46 ~34 stonebrick 1  
fill ~8 ~46 ~26 ~8 ~47 ~26 stonebrick 0  
fill ~8 ~46 ~27 ~8 ~47 ~27 stonebrick 0  
fill ~8 ~46 ~35 ~8 ~47 ~35 stonebrick 1  
fill ~8 ~46 ~36 ~8 ~46 ~35 stonebrick 1  
fill ~9 ~46 ~25 ~9 ~47 ~25 diamond_block 0  
fill ~9 ~46 ~37 ~9 ~47 ~37 diamond_block 0  
fill ~21 ~46 ~32 ~21 ~76 ~32 vine 2  
fill ~25 ~46 ~9 ~25 ~47 ~9 diamond_block 0  
fill ~25 ~46 ~53 ~25 ~47 ~53 diamond_block 0  
fill ~26 ~46 ~8 ~27 ~46 ~8 stonebrick 1  
fill ~26 ~46 ~29 ~26 ~65 ~29 vine 1  
fill ~26 ~46 ~32 ~26 ~64 ~32 vine 8  
fill ~26 ~46 ~54 ~26 ~47 ~54 stonebrick 0  
fill ~27 ~46 ~27 ~27 ~68 ~27 vine 8  
fill ~27 ~46 ~33 ~27 ~64 ~33 vine 8  
fill ~27 ~46 ~35 ~27 ~67 ~35 vine 8 
setblock ~27 ~46 ~54 stonebrick 2 
setblock ~28 ~46 ~7 stonebrick 1  
fill ~28 ~46 ~26 ~28 ~68 ~26 vine 1  
fill ~28 ~46 ~55 ~29 ~46 ~55 stonebrick 2  
fill ~29 ~46 ~7 ~29 ~47 ~7 stonebrick 0  
fill ~30 ~46 ~6 ~30 ~47 ~6 stonebrick 0  
fill ~30 ~46 ~31 ~30 ~52 ~31 gold_block 0  
fill ~30 ~46 ~32 ~30 ~47 ~32 vine 8  
fill ~30 ~46 ~33 ~32 ~46 ~33 vine 4  
fill ~30 ~46 ~37 ~30 ~68 ~37 vine 4  
fill ~30 ~46 ~56 ~30 ~47 ~56 stonebrick 0  
fill ~31 ~46 ~6 ~31 ~47 ~6 glowstone 0  
fill ~31 ~46 ~30 ~31 ~52 ~30 gold_block 0  
fill ~31 ~46 ~31 ~31 ~72 ~31 glowstone 0  
fill ~31 ~46 ~32 ~31 ~52 ~32 gold_block 0  
fill ~31 ~46 ~34 ~31 ~55 ~34 vine 4  
fill ~31 ~46 ~56 ~31 ~47 ~56 glowstone 0 
setblock ~32 ~46 ~6 stonebrick 1  
fill ~32 ~46 ~31 ~32 ~52 ~31 gold_block 0 
setblock ~32 ~46 ~56 stonebrick 0  
fill ~33 ~46 ~7 ~34 ~46 ~7 stonebrick 0  
fill ~33 ~46 ~28 ~33 ~57 ~28 vine 1  
fill ~33 ~46 ~55 ~34 ~46 ~55 stonebrick 2  
fill ~34 ~46 ~49 ~34 ~54 ~49 vine 1  
fill ~35 ~46 ~8 ~36 ~46 ~8 stonebrick 0  
fill ~35 ~46 ~30 ~35 ~60 ~30 vine 2 
setblock ~35 ~46 ~54 stonebrick 2  
fill ~36 ~46 ~34 ~36 ~68 ~34 vine 4 
setblock ~36 ~46 ~54 stonebrick 0  
fill ~37 ~46 ~9 ~37 ~47 ~9 diamond_block 0  
fill ~37 ~46 ~33 ~37 ~69 ~33 vine 2  
fill ~37 ~46 ~53 ~37 ~47 ~53 diamond_block 0  
fill ~43 ~46 ~30 ~43 ~65 ~30 vine 8  
fill ~52 ~46 ~24 ~53 ~46 ~24 vine 1  
fill ~53 ~46 ~25 ~53 ~47 ~25 diamond_block 0  
fill ~53 ~46 ~37 ~53 ~47 ~37 diamond_block 0 
setblock ~54 ~46 ~25 vine 2  
fill ~54 ~46 ~26 ~54 ~46 ~27 stonebrick 0 
setblock ~54 ~46 ~35 stonebrick 0  
fill ~54 ~46 ~36 ~54 ~47 ~36 stonebrick 1 
setblock ~55 ~46 ~28 stonebrick 2 
setblock ~55 ~46 ~29 stonebrick 1  
fill ~55 ~46 ~33 ~55 ~47 ~33 stonebrick 1 
setblock ~55 ~46 ~34 stonebrick 0  
fill ~56 ~46 ~30 ~56 ~47 ~30 stonebrick 0  
fill ~56 ~46 ~31 ~56 ~47 ~31 glowstone 0  
fill ~56 ~46 ~32 ~56 ~47 ~32 stonebrick 0 
setblock ~6 ~47 ~30 stonebrick 0 
setblock ~7 ~47 ~29 stonebrick 0 
setblock ~7 ~47 ~34 stonebrick 0 
setblock ~8 ~47 ~36 stonebrick 0  
fill ~13 ~47 ~27 ~13 ~53 ~27 vine 2 
setblock ~26 ~47 ~8 stonebrick 0 
setblock ~27 ~47 ~8 stonebrick 2 
setblock ~27 ~47 ~54 stonebrick 0 
setblock ~28 ~47 ~7 stonebrick 2  
fill ~28 ~47 ~55 ~29 ~47 ~55 stonebrick 0  
fill ~30 ~47 ~33 ~32 ~47 ~33 vine 4 
setblock ~32 ~47 ~6 stonebrick 2 
setblock ~32 ~47 ~56 stonebrick 1  
fill ~33 ~47 ~7 ~34 ~47 ~7 stonebrick 0  
fill ~33 ~47 ~55 ~34 ~47 ~55 stonebrick 0  
fill ~35 ~47 ~8 ~36 ~47 ~8 stonebrick 0 
setblock ~35 ~47 ~54 stonebrick 0 
setblock ~36 ~47 ~54 stonebrick 1  
fill ~52 ~47 ~24 ~53 ~47 ~24 vine 1 
setblock ~54 ~47 ~26 stonebrick 2 
setblock ~54 ~47 ~27 stonebrick 0 
setblock ~54 ~47 ~35 stonebrick 2 
setblock ~55 ~47 ~28 stonebrick 0 
setblock ~55 ~47 ~29 stonebrick 2 
