fill ~1 ~-1 ~1 ~62 ~-1 ~1 grass 0  
fill ~1 ~-1 ~2 ~26 ~-1 ~2 grass 0  
fill ~1 ~-1 ~3 ~22 ~-1 ~3 grass 0  
fill ~1 ~-1 ~4 ~19 ~-1 ~4 grass 0  
fill ~1 ~-1 ~5 ~17 ~-1 ~5 grass 0  
fill ~1 ~-1 ~6 ~16 ~-1 ~6 grass 0  
fill ~1 ~-1 ~7 ~14 ~-1 ~7 grass 0  
fill ~1 ~-1 ~8 ~13 ~-1 ~8 grass 0  
fill ~1 ~-1 ~9 ~11 ~-1 ~9 grass 0  
fill ~1 ~-1 ~10 ~10 ~-1 ~10 grass 0  
fill ~1 ~-1 ~11 ~9 ~-1 ~11 grass 0  
fill ~1 ~-1 ~12 ~8 ~-1 ~12 grass 0  
fill ~1 ~-1 ~13 ~8 ~-1 ~13 grass 0  
fill ~1 ~-1 ~14 ~7 ~-1 ~14 grass 0  
fill ~1 ~-1 ~15 ~6 ~-1 ~15 grass 0  
fill ~1 ~-1 ~16 ~6 ~-1 ~16 grass 0  
fill ~1 ~-1 ~17 ~5 ~-1 ~17 grass 0  
fill ~1 ~-1 ~18 ~4 ~-1 ~18 grass 0  
fill ~1 ~-1 ~19 ~4 ~-1 ~19 grass 0  
fill ~1 ~-1 ~20 ~3 ~-1 ~20 grass 0  
fill ~1 ~-1 ~21 ~3 ~-1 ~21 grass 0  
fill ~1 ~-1 ~22 ~3 ~-1 ~22 grass 0  
fill ~1 ~-1 ~23 ~2 ~-1 ~23 grass 0  
fill ~1 ~-1 ~24 ~2 ~-1 ~24 grass 0  
fill ~1 ~-1 ~25 ~2 ~-1 ~25 grass 0  
fill ~1 ~-1 ~26 ~2 ~-1 ~26 grass 0  
fill ~1 ~-1 ~27 ~1 ~-1 ~62 grass 0  
fill ~2 ~-1 ~27 ~62 ~-1 ~27 dirt 0  
fill ~2 ~-1 ~28 ~22 ~-1 ~28 dirt 0  
fill ~2 ~-1 ~29 ~27 ~-1 ~29 dirt 0  
fill ~2 ~-1 ~30 ~13 ~-1 ~30 dirt 0  
fill ~2 ~-1 ~31 ~43 ~-1 ~31 dirt 0  
fill ~2 ~-1 ~32 ~34 ~-1 ~32 dirt 0  
fill ~2 ~-1 ~33 ~21 ~-1 ~33 dirt 0  
fill ~2 ~-1 ~34 ~17 ~-1 ~34 dirt 0  
fill ~2 ~-1 ~35 ~26 ~-1 ~35 dirt 0  
fill ~2 ~-1 ~36 ~48 ~-1 ~36 dirt 0  
fill ~2 ~-1 ~37 ~20 ~-1 ~37 dirt 0  
fill ~2 ~-1 ~38 ~2 ~-1 ~61 grass 0 
setblock ~2 ~-1 ~62 dirt 0  
fill ~3 ~-1 ~23 ~21 ~-1 ~23 dirt 0  
fill ~3 ~-1 ~24 ~43 ~-1 ~24 dirt 0  
fill ~3 ~-1 ~25 ~61 ~-1 ~25 dirt 0  
fill ~3 ~-1 ~26 ~19 ~-1 ~26 dirt 0  
fill ~3 ~-1 ~38 ~23 ~-1 ~38 dirt 0  
fill ~3 ~-1 ~39 ~33 ~-1 ~39 dirt 0  
fill ~3 ~-1 ~40 ~19 ~-1 ~40 dirt 0  
fill ~3 ~-1 ~41 ~38 ~-1 ~41 dirt 0  
fill ~3 ~-1 ~42 ~3 ~-1 ~62 grass 0  
fill ~4 ~-1 ~20 ~60 ~-1 ~20 dirt 0  
fill ~4 ~-1 ~21 ~60 ~-1 ~21 dirt 0  
fill ~4 ~-1 ~22 ~26 ~-1 ~22 dirt 0  
fill ~4 ~-1 ~42 ~23 ~-1 ~42 dirt 0  
fill ~4 ~-1 ~43 ~34 ~-1 ~43 dirt 0  
fill ~4 ~-1 ~44 ~60 ~-1 ~44 dirt 0  
fill ~4 ~-1 ~45 ~4 ~-1 ~62 grass 0  
fill ~5 ~-1 ~18 ~27 ~-1 ~18 dirt 0  
fill ~5 ~-1 ~19 ~59 ~-1 ~19 dirt 0  
fill ~5 ~-1 ~45 ~26 ~-1 ~45 dirt 0  
fill ~5 ~-1 ~46 ~31 ~-1 ~46 dirt 0  
fill ~5 ~-1 ~47 ~5 ~-1 ~62 grass 0  
fill ~6 ~-1 ~17 ~30 ~-1 ~17 dirt 0  
fill ~6 ~-1 ~47 ~58 ~-1 ~47 dirt 0  
fill ~6 ~-1 ~48 ~6 ~-1 ~62 grass 0  
fill ~7 ~-1 ~15 ~35 ~-1 ~15 dirt 0  
fill ~7 ~-1 ~16 ~57 ~-1 ~16 dirt 0  
fill ~7 ~-1 ~48 ~57 ~-1 ~48 dirt 0  
fill ~7 ~-1 ~49 ~34 ~-1 ~49 dirt 0  
fill ~7 ~-1 ~50 ~7 ~-1 ~62 grass 0  
fill ~8 ~-1 ~14 ~56 ~-1 ~14 dirt 0  
fill ~8 ~-1 ~50 ~28 ~-1 ~50 dirt 0  
fill ~8 ~-1 ~51 ~8 ~-1 ~62 grass 0  
fill ~9 ~-1 ~12 ~55 ~-1 ~12 dirt 0  
fill ~9 ~-1 ~13 ~55 ~-1 ~13 dirt 0  
fill ~9 ~-1 ~51 ~55 ~-1 ~51 dirt 0  
fill ~9 ~-1 ~52 ~55 ~-1 ~52 dirt 0  
fill ~9 ~-1 ~53 ~9 ~-1 ~62 grass 0  
fill ~10 ~-1 ~11 ~54 ~-1 ~11 dirt 0  
fill ~10 ~-1 ~53 ~54 ~-1 ~53 dirt 0  
fill ~10 ~-1 ~54 ~10 ~-1 ~62 grass 0  
fill ~11 ~-1 ~10 ~53 ~-1 ~10 dirt 0  
fill ~11 ~-1 ~54 ~53 ~-1 ~54 dirt 0  
fill ~11 ~-1 ~55 ~11 ~-1 ~62 grass 0  
fill ~12 ~-1 ~9 ~52 ~-1 ~9 dirt 0  
fill ~12 ~-1 ~55 ~52 ~-1 ~55 dirt 0  
fill ~12 ~-1 ~56 ~13 ~-1 ~56 grass 0  
fill ~12 ~-1 ~57 ~14 ~-1 ~57 grass 0  
fill ~12 ~-1 ~58 ~16 ~-1 ~58 grass 0  
fill ~12 ~-1 ~59 ~17 ~-1 ~59 grass 0  
fill ~12 ~-1 ~60 ~19 ~-1 ~60 grass 0  
fill ~12 ~-1 ~61 ~22 ~-1 ~61 grass 0  
fill ~12 ~-1 ~62 ~63 ~-1 ~62 grass 0  
fill ~14 ~-1 ~8 ~50 ~-1 ~8 dirt 0  
fill ~14 ~-1 ~30 ~14 ~0 ~30 gravel 0  
fill ~14 ~-1 ~56 ~50 ~-1 ~56 dirt 0  
fill ~15 ~-1 ~7 ~49 ~-1 ~7 dirt 0  
fill ~15 ~-1 ~30 ~18 ~-1 ~30 dirt 0  
fill ~15 ~-1 ~57 ~49 ~-1 ~57 dirt 0  
fill ~17 ~-1 ~6 ~47 ~-1 ~6 dirt 0  
fill ~17 ~-1 ~58 ~47 ~-1 ~58 dirt 0  
fill ~18 ~-1 ~5 ~46 ~-1 ~5 dirt 0 
setblock ~18 ~-1 ~34 redstone_block 0  
fill ~18 ~-1 ~59 ~46 ~-1 ~59 dirt 0 
setblock ~19 ~-1 ~30 redstone_block 0  
fill ~19 ~-1 ~34 ~31 ~-1 ~34 dirt 0  
fill ~20 ~-1 ~4 ~44 ~-1 ~4 dirt 0 
setblock ~20 ~-1 ~26 redstone_block 0  
fill ~20 ~-1 ~30 ~46 ~-1 ~30 dirt 0 
setblock ~20 ~-1 ~40 redstone_block 0  
fill ~20 ~-1 ~60 ~44 ~-1 ~60 dirt 0  
fill ~21 ~-1 ~26 ~25 ~-1 ~26 dirt 0 
setblock ~21 ~-1 ~37 redstone_block 0  
fill ~21 ~-1 ~40 ~28 ~-1 ~40 dirt 0 
setblock ~22 ~-1 ~23 redstone_block 0 
setblock ~22 ~-1 ~33 redstone_block 0  
fill ~22 ~-1 ~37 ~43 ~-1 ~37 dirt 0  
fill ~23 ~-1 ~3 ~41 ~-1 ~3 dirt 0  
fill ~23 ~-1 ~23 ~61 ~-1 ~23 dirt 0 
setblock ~23 ~-1 ~28 redstone_block 0  
fill ~23 ~-1 ~33 ~62 ~-1 ~33 dirt 0  
fill ~23 ~-1 ~61 ~41 ~-1 ~61 dirt 0  
fill ~24 ~-1 ~28 ~35 ~-1 ~28 dirt 0 
setblock ~24 ~-1 ~38 redstone_block 0 
setblock ~24 ~-1 ~42 redstone_block 0  
fill ~25 ~-1 ~38 ~61 ~-1 ~38 dirt 0  
fill ~25 ~-1 ~42 ~60 ~-1 ~42 dirt 0 
setblock ~26 ~-1 ~26 redstone_block 0  
fill ~27 ~-1 ~2 ~37 ~-1 ~2 dirt 0 
setblock ~27 ~-1 ~22 redstone_block 0  
fill ~27 ~-1 ~26 ~31 ~-1 ~26 dirt 0 
setblock ~27 ~-1 ~35 redstone_block 0 
setblock ~27 ~-1 ~45 redstone_block 0 
setblock ~28 ~-1 ~18 redstone_block 0  
fill ~28 ~-1 ~22 ~31 ~-1 ~22 dirt 0 
setblock ~28 ~-1 ~29 redstone_block 0  
fill ~28 ~-1 ~35 ~38 ~-1 ~35 dirt 0  
fill ~28 ~-1 ~45 ~59 ~-1 ~45 dirt 0  
fill ~29 ~-1 ~18 ~59 ~-1 ~18 dirt 0  
fill ~29 ~-1 ~29 ~40 ~-1 ~29 dirt 0 
setblock ~29 ~-1 ~40 redstone_block 0 
setblock ~29 ~-1 ~50 redstone_block 0  
fill ~30 ~-1 ~40 ~61 ~-1 ~40 dirt 0  
fill ~30 ~-1 ~50 ~56 ~-1 ~50 dirt 0 
setblock ~31 ~-1 ~17 redstone_block 0  
fill ~32 ~-1 ~17 ~58 ~-1 ~17 dirt 0 
setblock ~32 ~-1 ~22 redstone_block 0 
setblock ~32 ~-1 ~26 redstone_block 0 
setblock ~32 ~-1 ~34 redstone_block 0 
setblock ~32 ~-1 ~46 redstone_block 0  
fill ~33 ~-1 ~22 ~38 ~-1 ~22 dirt 0  
fill ~33 ~-1 ~26 ~39 ~-1 ~26 dirt 0  
fill ~33 ~-1 ~34 ~62 ~-1 ~34 dirt 0  
fill ~33 ~-1 ~46 ~59 ~-1 ~46 dirt 0 
setblock ~34 ~-1 ~39 redstone_block 0 
setblock ~35 ~-1 ~32 redstone_block 0  
fill ~35 ~-1 ~39 ~61 ~-1 ~39 dirt 0 
setblock ~35 ~-1 ~43 redstone_block 0 
setblock ~35 ~-1 ~49 redstone_block 0 
setblock ~36 ~-1 ~15 redstone_block 0 
setblock ~36 ~-1 ~28 redstone_block 0  
fill ~36 ~-1 ~32 ~62 ~-1 ~32 dirt 0  
fill ~36 ~-1 ~43 ~60 ~-1 ~43 dirt 0  
fill ~36 ~-1 ~49 ~57 ~-1 ~49 dirt 0  
fill ~37 ~-1 ~15 ~57 ~-1 ~15 dirt 0  
fill ~37 ~-1 ~28 ~62 ~-1 ~28 dirt 0  
fill ~38 ~-1 ~2 ~63 ~-1 ~2 grass 0 
setblock ~39 ~-1 ~22 redstone_block 0 
setblock ~39 ~-1 ~35 redstone_block 0 
setblock ~39 ~-1 ~41 redstone_block 0  
fill ~40 ~-1 ~22 ~60 ~-1 ~22 dirt 0 
setblock ~40 ~-1 ~26 redstone_block 0  
fill ~40 ~-1 ~35 ~62 ~-1 ~35 dirt 0  
fill ~40 ~-1 ~41 ~61 ~-1 ~41 dirt 0  
fill ~41 ~-1 ~26 ~46 ~-1 ~26 dirt 0 
setblock ~41 ~-1 ~29 redstone_block 0  
fill ~42 ~-1 ~3 ~63 ~-1 ~3 grass 0  
fill ~42 ~-1 ~29 ~62 ~-1 ~29 dirt 0  
fill ~42 ~-1 ~61 ~63 ~-1 ~61 grass 0 
setblock ~44 ~-1 ~24 redstone_block 0 
setblock ~44 ~-1 ~31 redstone_block 0 
setblock ~44 ~-1 ~37 redstone_block 0  
fill ~45 ~-1 ~4 ~63 ~-1 ~4 grass 0  
fill ~45 ~-1 ~24 ~61 ~-1 ~24 dirt 0  
fill ~45 ~-1 ~31 ~62 ~-1 ~31 dirt 0  
fill ~45 ~-1 ~37 ~48 ~-1 ~37 dirt 0  
fill ~45 ~-1 ~60 ~63 ~-1 ~60 grass 0  
fill ~47 ~-1 ~5 ~63 ~-1 ~5 grass 0 
setblock ~47 ~-1 ~26 cobblestone 0  
fill ~47 ~-1 ~30 ~47 ~0 ~30 cobblestone 0  
fill ~47 ~-1 ~59 ~63 ~-1 ~59 grass 0  
fill ~48 ~-1 ~6 ~63 ~-1 ~6 grass 0 
setblock ~48 ~-1 ~26 dirt 0  
fill ~48 ~-1 ~30 ~62 ~-1 ~30 dirt 0  
fill ~48 ~-1 ~58 ~63 ~-1 ~58 grass 0  
fill ~49 ~-1 ~36 ~49 ~0 ~36 gravel 0  
fill ~49 ~-1 ~37 ~49 ~0 ~37 gravel 0  
fill ~50 ~-1 ~7 ~63 ~-1 ~7 grass 0  
fill ~50 ~-1 ~26 ~61 ~-1 ~26 dirt 0  
fill ~50 ~-1 ~36 ~62 ~-1 ~36 dirt 0  
fill ~50 ~-1 ~37 ~62 ~-1 ~37 dirt 0  
fill ~50 ~-1 ~57 ~63 ~-1 ~57 grass 0  
fill ~51 ~-1 ~8 ~63 ~-1 ~8 grass 0  
fill ~51 ~-1 ~56 ~63 ~-1 ~56 grass 0  
fill ~53 ~-1 ~9 ~63 ~-1 ~9 grass 0  
fill ~53 ~-1 ~55 ~63 ~-1 ~55 grass 0  
fill ~54 ~-1 ~10 ~63 ~-1 ~10 grass 0  
fill ~54 ~-1 ~54 ~63 ~-1 ~54 grass 0  
fill ~55 ~-1 ~11 ~63 ~-1 ~11 grass 0  
fill ~55 ~-1 ~53 ~63 ~-1 ~53 grass 0  
fill ~56 ~-1 ~12 ~63 ~-1 ~12 grass 0  
fill ~56 ~-1 ~13 ~63 ~-1 ~13 grass 0  
fill ~56 ~-1 ~51 ~63 ~-1 ~51 grass 0  
fill ~56 ~-1 ~52 ~63 ~-1 ~52 grass 0  
fill ~57 ~-1 ~14 ~63 ~-1 ~14 grass 0  
fill ~57 ~-1 ~50 ~63 ~-1 ~50 grass 0  
fill ~58 ~-1 ~15 ~63 ~-1 ~15 grass 0  
fill ~58 ~-1 ~16 ~63 ~-1 ~16 grass 0  
fill ~58 ~-1 ~48 ~63 ~-1 ~48 grass 0  
fill ~58 ~-1 ~49 ~63 ~-1 ~49 grass 0  
fill ~59 ~-1 ~17 ~63 ~-1 ~17 grass 0  
fill ~59 ~-1 ~47 ~63 ~-1 ~47 grass 0  
fill ~60 ~-1 ~18 ~63 ~-1 ~18 grass 0  
fill ~60 ~-1 ~19 ~63 ~-1 ~19 grass 0  
fill ~60 ~-1 ~45 ~63 ~-1 ~45 grass 0  
fill ~60 ~-1 ~46 ~63 ~-1 ~46 grass 0  
fill ~61 ~-1 ~20 ~63 ~-1 ~20 grass 0  
fill ~61 ~-1 ~21 ~63 ~-1 ~21 grass 0  
fill ~61 ~-1 ~22 ~63 ~-1 ~22 grass 0  
fill ~61 ~-1 ~42 ~63 ~-1 ~42 grass 0  
fill ~61 ~-1 ~43 ~63 ~-1 ~43 grass 0  
fill ~61 ~-1 ~44 ~63 ~-1 ~44 grass 0  
fill ~62 ~-1 ~23 ~63 ~-1 ~23 grass 0  
fill ~62 ~-1 ~24 ~63 ~-1 ~24 grass 0  
fill ~62 ~-1 ~25 ~63 ~-1 ~25 grass 0  
fill ~62 ~-1 ~26 ~63 ~-1 ~26 grass 0  
fill ~62 ~-1 ~38 ~63 ~-1 ~38 grass 0  
fill ~62 ~-1 ~39 ~63 ~-1 ~39 grass 0  
fill ~62 ~-1 ~40 ~63 ~-1 ~40 grass 0  
fill ~62 ~-1 ~41 ~63 ~-1 ~41 grass 0 
setblock ~63 ~-1 ~1 stonebrick 1  
fill ~63 ~-1 ~27 ~63 ~-1 ~62 grass 0  
fill ~2 ~0 ~27 ~13 ~0 ~27 stonebrick 1  
fill ~2 ~0 ~28 ~13 ~0 ~28 stonebrick 1  
fill ~2 ~0 ~29 ~13 ~0 ~29 stonebrick 1  
fill ~2 ~0 ~30 ~13 ~0 ~30 stonebrick 1  
fill ~2 ~0 ~31 ~13 ~0 ~31 stonebrick 1  
fill ~2 ~0 ~32 ~13 ~0 ~32 stonebrick 1  
fill ~2 ~0 ~33 ~13 ~0 ~33 stonebrick 1  
fill ~2 ~0 ~34 ~11 ~0 ~34 stonebrick 1  
fill ~2 ~0 ~35 ~13 ~0 ~35 stonebrick 1  
fill ~2 ~0 ~36 ~13 ~0 ~36 stonebrick 1  
fill ~2 ~0 ~37 ~13 ~0 ~37 stonebrick 1  
fill ~3 ~0 ~23 ~15 ~0 ~23 stonebrick 1  
fill ~3 ~0 ~24 ~14 ~0 ~24 stonebrick 1  
fill ~3 ~0 ~25 ~14 ~0 ~25 stonebrick 1  
fill ~3 ~0 ~26 ~14 ~0 ~26 stonebrick 1  
fill ~3 ~0 ~38 ~14 ~0 ~38 stonebrick 1  
fill ~3 ~0 ~39 ~14 ~0 ~39 stonebrick 1  
fill ~3 ~0 ~40 ~14 ~0 ~40 stonebrick 1  
fill ~3 ~0 ~41 ~15 ~0 ~41 stonebrick 1  
fill ~4 ~0 ~20 ~17 ~0 ~20 stonebrick 1  
fill ~4 ~0 ~21 ~16 ~0 ~21 stonebrick 1  
fill ~4 ~0 ~22 ~16 ~0 ~22 stonebrick 1  
fill ~4 ~0 ~42 ~16 ~0 ~42 stonebrick 1  
fill ~4 ~0 ~43 ~16 ~0 ~43 stonebrick 1  
fill ~4 ~0 ~44 ~17 ~0 ~44 stonebrick 1  
fill ~5 ~0 ~18 ~19 ~0 ~18 stonebrick 1  
fill ~5 ~0 ~19 ~18 ~0 ~19 stonebrick 1  
fill ~5 ~0 ~45 ~18 ~0 ~45 stonebrick 1  
fill ~5 ~0 ~46 ~19 ~0 ~46 stonebrick 1  
fill ~6 ~0 ~17 ~20 ~0 ~17 stonebrick 1  
fill ~6 ~0 ~47 ~20 ~0 ~47 stonebrick 1  
fill ~7 ~0 ~15 ~23 ~0 ~15 stonebrick 1  
fill ~7 ~0 ~16 ~22 ~0 ~16 stonebrick 1  
fill ~7 ~0 ~48 ~22 ~0 ~48 stonebrick 1  
fill ~7 ~0 ~49 ~23 ~0 ~49 stonebrick 1  
fill ~8 ~0 ~14 ~26 ~0 ~14 stonebrick 1  
fill ~8 ~0 ~50 ~26 ~0 ~50 stonebrick 1  
fill ~9 ~0 ~12 ~55 ~0 ~12 stonebrick 1  
fill ~9 ~0 ~13 ~55 ~0 ~13 stonebrick 1  
fill ~9 ~0 ~51 ~55 ~0 ~51 stonebrick 1  
fill ~9 ~0 ~52 ~55 ~0 ~52 stonebrick 1  
fill ~10 ~0 ~11 ~54 ~0 ~11 stonebrick 1  
fill ~10 ~0 ~53 ~54 ~0 ~53 stonebrick 1  
fill ~11 ~0 ~10 ~53 ~0 ~10 stonebrick 1  
fill ~11 ~0 ~54 ~53 ~0 ~54 stonebrick 1  
fill ~12 ~0 ~9 ~52 ~0 ~9 stonebrick 1 
setblock ~12 ~0 ~34 obsidian 0  
fill ~12 ~0 ~55 ~52 ~0 ~55 stonebrick 1 
setblock ~13 ~0 ~34 stonebrick 1  
fill ~14 ~0 ~8 ~50 ~0 ~8 stonebrick 1 
setblock ~14 ~0 ~27 grass 0  
fill ~14 ~0 ~28 ~14 ~0 ~29 cobblestone 0  
fill ~14 ~0 ~31 ~14 ~0 ~34 cobblestone 0  
fill ~14 ~0 ~35 ~14 ~0 ~36 gravel 0 
setblock ~14 ~0 ~37 cobblestone 0  
fill ~14 ~0 ~56 ~50 ~0 ~56 stonebrick 1  
fill ~15 ~0 ~7 ~49 ~0 ~7 stonebrick 1  
fill ~15 ~0 ~24 ~15 ~0 ~25 obsidian 0 
setblock ~15 ~0 ~26 grass 0  
fill ~15 ~0 ~27 ~16 ~0 ~27 cobblestone 0  
fill ~15 ~0 ~28 ~16 ~0 ~28 gravel 0  
fill ~15 ~0 ~29 ~16 ~0 ~29 grass 0  
fill ~15 ~0 ~30 ~16 ~0 ~30 cobblestone 0  
fill ~15 ~0 ~31 ~15 ~0 ~32 gravel 0 
setblock ~15 ~0 ~33 cobblestone 0 
setblock ~15 ~0 ~34 grass 0  
fill ~15 ~0 ~35 ~17 ~0 ~35 cobblestone 0 
setblock ~15 ~0 ~36 grass 0 
setblock ~15 ~0 ~37 gravel 0 
setblock ~15 ~0 ~38 grass 0  
fill ~15 ~0 ~39 ~15 ~0 ~40 obsidian 0  
fill ~15 ~0 ~57 ~49 ~0 ~57 stonebrick 1 
setblock ~16 ~0 ~23 obsidian 0  
fill ~16 ~0 ~24 ~17 ~0 ~24 cobblestone 0 
setblock ~16 ~0 ~25 gravel 0 
setblock ~16 ~0 ~26 cobblestone 0 
setblock ~16 ~0 ~31 grass 0  
fill ~16 ~0 ~32 ~17 ~0 ~32 cobblestone 0 
setblock ~16 ~0 ~33 gravel 0 
setblock ~16 ~0 ~34 cobblestone 0  
fill ~16 ~0 ~36 ~17 ~0 ~36 gravel 0 
setblock ~16 ~0 ~37 grass 0 
setblock ~16 ~0 ~38 cobblestone 0 
setblock ~16 ~0 ~39 gravel 0 
setblock ~16 ~0 ~40 grass 0 
setblock ~16 ~0 ~41 obsidian 0  
fill ~17 ~0 ~6 ~47 ~0 ~6 stonebrick 1  
fill ~17 ~0 ~21 ~17 ~0 ~22 obsidian 0  
fill ~17 ~0 ~23 ~19 ~0 ~23 gravel 0 
setblock ~17 ~0 ~25 grass 0 
setblock ~17 ~0 ~26 gravel 0 
setblock ~17 ~0 ~27 grass 0  
fill ~17 ~0 ~28 ~17 ~0 ~29 cobblestone 0 
setblock ~17 ~0 ~30 gravel 0 
setblock ~17 ~0 ~31 cobblestone 0 
setblock ~17 ~0 ~33 cobblestone 0 
setblock ~17 ~0 ~34 grass 0 
setblock ~17 ~0 ~37 cobblestone 0  
fill ~17 ~0 ~38 ~18 ~0 ~38 grass 0  
fill ~17 ~0 ~39 ~18 ~0 ~39 cobblestone 0  
fill ~17 ~0 ~40 ~18 ~0 ~40 gravel 0  
fill ~17 ~0 ~41 ~18 ~0 ~41 cobblestone 0  
fill ~17 ~0 ~42 ~17 ~0 ~43 obsidian 0  
fill ~17 ~0 ~58 ~47 ~0 ~58 stonebrick 1  
fill ~18 ~0 ~5 ~46 ~0 ~5 stonebrick 1 
setblock ~18 ~0 ~20 obsidian 0 
setblock ~18 ~0 ~21 grass 0 
setblock ~18 ~0 ~22 cobblestone 0 
setblock ~18 ~0 ~24 gravel 0 
setblock ~18 ~0 ~25 cobblestone 0 
setblock ~18 ~0 ~26 grass 0 
setblock ~18 ~0 ~27 stained_hardened_clay 10  
fill ~18 ~0 ~28 ~18 ~0 ~29 grass 0 
setblock ~18 ~0 ~30 clay 0 
setblock ~18 ~0 ~31 log 9 
setblock ~18 ~0 ~32 grass 0 
setblock ~18 ~0 ~33 stained_hardened_clay 4 
setblock ~18 ~0 ~34 lit_redstone_lamp 0 
setblock ~18 ~0 ~35 stained_hardened_clay 14  
fill ~18 ~0 ~36 ~19 ~0 ~36 grass 0 
setblock ~18 ~0 ~37 stained_hardened_clay 7  
fill ~18 ~0 ~42 ~19 ~0 ~42 gravel 0  
fill ~18 ~0 ~43 ~19 ~0 ~43 cobblestone 0 
setblock ~18 ~0 ~44 obsidian 0  
fill ~18 ~0 ~59 ~46 ~0 ~59 stonebrick 1 
setblock ~19 ~0 ~19 obsidian 0  
fill ~19 ~0 ~20 ~19 ~0 ~21 gravel 0 
setblock ~19 ~0 ~22 grass 0  
fill ~19 ~0 ~24 ~20 ~0 ~24 grass 0 
setblock ~19 ~0 ~25 stained_hardened_clay 4 
setblock ~19 ~0 ~26 stained_hardened_clay 9 
setblock ~19 ~0 ~27 log 9 
setblock ~19 ~0 ~28 stained_hardened_clay 7 
setblock ~19 ~0 ~29 clay 0 
setblock ~19 ~0 ~30 lit_redstone_lamp 0 
setblock ~19 ~0 ~31 clay 0 
setblock ~19 ~0 ~32 stained_hardened_clay 13 
setblock ~19 ~0 ~33 stained_hardened_clay 7 
setblock ~19 ~0 ~34 clay 0 
setblock ~19 ~0 ~35 cobblestone 0 
setblock ~19 ~0 ~37 stonebrick 2 
setblock ~19 ~0 ~38 clay 0 
setblock ~19 ~0 ~39 stained_hardened_clay 1 
setblock ~19 ~0 ~40 cobblestone 0 
setblock ~19 ~0 ~41 grass 0  
fill ~19 ~0 ~44 ~21 ~0 ~44 gravel 0 
setblock ~19 ~0 ~45 obsidian 0  
fill ~20 ~0 ~4 ~44 ~0 ~4 stonebrick 1 
setblock ~20 ~0 ~18 obsidian 0 
setblock ~20 ~0 ~19 cobblestone 0 
setblock ~20 ~0 ~20 grass 0  
fill ~20 ~0 ~21 ~20 ~0 ~22 gravel 0 
setblock ~20 ~0 ~23 cobblestone 0 
setblock ~20 ~0 ~25 cobblestone 0 
setblock ~20 ~0 ~26 lit_redstone_lamp 0 
setblock ~20 ~0 ~27 clay 0 
setblock ~20 ~0 ~28 stonebrick 2 
setblock ~20 ~0 ~29 stained_hardened_clay 10 
setblock ~20 ~0 ~30 cobblestone 0 
setblock ~20 ~0 ~31 stained_hardened_clay 9 
setblock ~20 ~0 ~32 stonebrick 2 
setblock ~20 ~0 ~33 clay 0 
setblock ~20 ~0 ~34 stained_hardened_clay 9 
setblock ~20 ~0 ~35 log 9 
setblock ~20 ~0 ~36 gravel 0 
setblock ~20 ~0 ~37 stained_hardened_clay 10 
setblock ~20 ~0 ~38 gravel 0 
setblock ~20 ~0 ~39 stained_hardened_clay 9 
setblock ~20 ~0 ~40 lit_redstone_lamp 0  
fill ~20 ~0 ~41 ~20 ~0 ~42 cobblestone 0 
setblock ~20 ~0 ~43 grass 0 
setblock ~20 ~0 ~45 grass 0 
setblock ~20 ~0 ~46 obsidian 0  
fill ~20 ~0 ~60 ~26 ~0 ~60 stonebrick 1  
fill ~21 ~0 ~17 ~22 ~0 ~17 obsidian 0  
fill ~21 ~0 ~18 ~21 ~0 ~19 grass 0 
setblock ~21 ~0 ~20 gravel 0 
setblock ~21 ~0 ~21 grass 0 
setblock ~21 ~0 ~22 cobblestone 0 
setblock ~21 ~0 ~23 stained_hardened_clay 9  
fill ~21 ~0 ~24 ~22 ~0 ~24 clay 0 
setblock ~21 ~0 ~25 grass 0 
setblock ~21 ~0 ~26 stonebrick 2 
setblock ~21 ~0 ~27 stained_hardened_clay 13 
setblock ~21 ~0 ~28 gravel 0 
setblock ~21 ~0 ~29 stained_hardened_clay 14 
setblock ~21 ~0 ~30 clay 0 
setblock ~21 ~0 ~31 stained_hardened_clay 4  
fill ~21 ~0 ~32 ~22 ~0 ~32 clay 0 
setblock ~21 ~0 ~33 cobblestone 0 
setblock ~21 ~0 ~34 gravel 0 
setblock ~21 ~0 ~35 clay 0 
setblock ~21 ~0 ~36 stained_hardened_clay 13 
setblock ~21 ~0 ~37 lit_redstone_lamp 0 
setblock ~21 ~0 ~38 stained_hardened_clay 4 
setblock ~21 ~0 ~39 cobblestone 0 
setblock ~21 ~0 ~40 stained_hardened_clay 7 
setblock ~21 ~0 ~41 grass 0 
setblock ~21 ~0 ~42 gravel 0  
fill ~21 ~0 ~43 ~22 ~0 ~43 cobblestone 0 
setblock ~21 ~0 ~45 gravel 0 
setblock ~21 ~0 ~46 cobblestone 0  
fill ~21 ~0 ~47 ~22 ~0 ~47 obsidian 0  
fill ~22 ~0 ~18 ~23 ~0 ~18 gravel 0  
fill ~22 ~0 ~19 ~22 ~0 ~18 gravel 0  
fill ~22 ~0 ~20 ~23 ~0 ~20 cobblestone 0 
setblock ~22 ~0 ~21 gravel 0 
setblock ~22 ~0 ~22 grass 0 
setblock ~22 ~0 ~23 lit_redstone_lamp 0 
setblock ~22 ~0 ~25 log 9 
setblock ~22 ~0 ~26 clay 0 
setblock ~22 ~0 ~27 cobblestone 0 
setblock ~22 ~0 ~28 clay 0 
setblock ~22 ~0 ~29 grass 0 
setblock ~22 ~0 ~30 log 9 
setblock ~22 ~0 ~31 stained_hardened_clay 7 
setblock ~22 ~0 ~33 lit_redstone_lamp 0 
setblock ~22 ~0 ~34 stained_hardened_clay 10 
setblock ~22 ~0 ~35 cobblestone 0 
setblock ~22 ~0 ~36 stained_hardened_clay 1 
setblock ~22 ~0 ~37 clay 0 
setblock ~22 ~0 ~38 grass 0 
setblock ~22 ~0 ~39 clay 0 
setblock ~22 ~0 ~40 stained_hardened_clay 10 
setblock ~22 ~0 ~41 clay 0 
setblock ~22 ~0 ~42 stained_hardened_clay 13 
setblock ~22 ~0 ~44 grass 0  
fill ~22 ~0 ~45 ~23 ~0 ~45 cobblestone 0  
fill ~22 ~0 ~46 ~24 ~0 ~46 gravel 0  
fill ~23 ~0 ~3 ~41 ~0 ~3 stonebrick 1 
setblock ~23 ~0 ~16 obsidian 0 
setblock ~23 ~0 ~17 grass 0 
setblock ~23 ~0 ~19 grass 0 
setblock ~23 ~0 ~21 stained_hardened_clay 10 
setblock ~23 ~0 ~22 cobblestone 0 
setblock ~23 ~0 ~23 stained_hardened_clay 13 
setblock ~23 ~0 ~24 cobblestone 0 
setblock ~23 ~0 ~25 stained_hardened_clay 10 
setblock ~23 ~0 ~26 stained_hardened_clay 9  
fill ~23 ~0 ~27 ~24 ~0 ~27 clay 0 
setblock ~23 ~0 ~28 lit_redstone_lamp 0 
setblock ~23 ~0 ~29 stonebrick 2 
setblock ~23 ~0 ~30 clay 0 
setblock ~23 ~0 ~31 stained_hardened_clay 14 
setblock ~23 ~0 ~32 stonebrick 2 
setblock ~23 ~0 ~33 stained_hardened_clay 13 
setblock ~23 ~0 ~34 gravel 0 
setblock ~23 ~0 ~35 clay 0 
setblock ~23 ~0 ~36 stained_hardened_clay 14 
setblock ~23 ~0 ~37 stonebrick 2 
setblock ~23 ~0 ~38 clay 0 
setblock ~23 ~0 ~39 grass 0 
setblock ~23 ~0 ~40 stained_hardened_clay 9 
setblock ~23 ~0 ~41 stained_hardened_clay 4 
setblock ~23 ~0 ~42 grass 0 
setblock ~23 ~0 ~43 stained_hardened_clay 14 
setblock ~23 ~0 ~44 gravel 0 
setblock ~23 ~0 ~47 grass 0 
setblock ~23 ~0 ~48 obsidian 0  
fill ~23 ~0 ~61 ~26 ~0 ~61 stonebrick 1  
fill ~24 ~0 ~15 ~25 ~0 ~15 obsidian 0 
setblock ~24 ~0 ~16 cobblestone 0 
setblock ~24 ~0 ~17 gravel 0 
setblock ~24 ~0 ~18 cobblestone 0 
setblock ~24 ~0 ~19 gravel 0  
fill ~24 ~0 ~20 ~26 ~0 ~20 stonebrick 1 
setblock ~24 ~0 ~21 stained_hardened_clay 9 
setblock ~24 ~0 ~22 clay 0 
setblock ~24 ~0 ~23 gravel 0 
setblock ~24 ~0 ~24 grass 0 
setblock ~24 ~0 ~25 stonebrick 2 
setblock ~24 ~0 ~26 stained_hardened_clay 7 
setblock ~24 ~0 ~28 gravel 0 
setblock ~24 ~0 ~29 stained_hardened_clay 1  
fill ~24 ~0 ~30 ~26 ~0 ~30 stonebrick 1 
setblock ~24 ~0 ~31 cobblestone 0 
setblock ~24 ~0 ~32 clay 0 
setblock ~24 ~0 ~33 grass 0  
fill ~24 ~0 ~34 ~26 ~0 ~34 stonebrick 1 
setblock ~24 ~0 ~35 log 9 
setblock ~24 ~0 ~36 stained_hardened_clay 7 
setblock ~24 ~0 ~37 stained_hardened_clay 13 
setblock ~24 ~0 ~38 lit_redstone_lamp 0 
setblock ~24 ~0 ~39 stained_hardened_clay 14 
setblock ~24 ~0 ~40 cobblestone 0 
setblock ~24 ~0 ~41 clay 0 
setblock ~24 ~0 ~42 lit_redstone_lamp 0 
setblock ~24 ~0 ~43 gravel 0  
fill ~24 ~0 ~44 ~26 ~0 ~44 stonebrick 1 
setblock ~24 ~0 ~45 grass 0 
setblock ~24 ~0 ~47 cobblestone 0 
setblock ~24 ~0 ~48 grass 0  
fill ~24 ~0 ~49 ~25 ~0 ~49 obsidian 0 
setblock ~25 ~0 ~16 grass 0  
fill ~25 ~0 ~17 ~26 ~0 ~17 cobblestone 0 
setblock ~25 ~0 ~18 grass 0 
setblock ~25 ~0 ~19 stonebrick 1 
setblock ~25 ~0 ~21 cobblestone 0 
setblock ~25 ~0 ~22 stained_hardened_clay 13 
setblock ~25 ~0 ~23 clay 0 
setblock ~25 ~0 ~24 cobblestone 0 
setblock ~25 ~0 ~25 stained_hardened_clay 4 
setblock ~25 ~0 ~26 clay 0 
setblock ~25 ~0 ~27 stonebrick 2 
setblock ~25 ~0 ~28 stained_hardened_clay 14 
setblock ~25 ~0 ~29 log 9 
setblock ~25 ~0 ~31 stonebrick 1 
setblock ~25 ~0 ~32 stained_hardened_clay 11 
setblock ~25 ~0 ~33 stonebrick 1 
setblock ~25 ~0 ~35 stained_hardened_clay 4 
setblock ~25 ~0 ~36 clay 0 
setblock ~25 ~0 ~37 cobblestone 0 
setblock ~25 ~0 ~38 stained_hardened_clay 10 
setblock ~25 ~0 ~39 stonebrick 2 
setblock ~25 ~0 ~40 clay 0 
setblock ~25 ~0 ~41 cobblestone 0 
setblock ~25 ~0 ~42 stained_hardened_clay 13 
setblock ~25 ~0 ~43 stained_hardened_clay 7 
setblock ~25 ~0 ~45 stonebrick 1 
setblock ~25 ~0 ~46 cobblestone 0 
setblock ~25 ~0 ~47 grass 0  
fill ~25 ~0 ~48 ~26 ~0 ~48 gravel 0 
setblock ~26 ~0 ~15 stained_hardened_clay 1 
setblock ~26 ~0 ~16 cobblestone 0 
setblock ~26 ~0 ~18 stained_hardened_clay 13 
setblock ~26 ~0 ~19 stained_hardened_clay 10 
setblock ~26 ~0 ~21 stained_hardened_clay 4 
setblock ~26 ~0 ~22 log 9 
setblock ~26 ~0 ~23 stonebrick 2 
setblock ~26 ~0 ~24 stained_hardened_clay 7 
setblock ~26 ~0 ~25 grass 0 
setblock ~26 ~0 ~26 lit_redstone_lamp 0 
setblock ~26 ~0 ~27 stained_hardened_clay 9 
setblock ~26 ~0 ~28 grass 0 
setblock ~26 ~0 ~29 stained_hardened_clay 10 
setblock ~26 ~0 ~31 log 9 
setblock ~26 ~0 ~32 stained_hardened_clay 10 
setblock ~26 ~0 ~33 grass 0 
setblock ~26 ~0 ~35 gravel 0 
setblock ~26 ~0 ~36 cobblestone 0 
setblock ~26 ~0 ~37 stained_hardened_clay 7  
fill ~26 ~0 ~38 ~27 ~0 ~38 clay 0 
setblock ~26 ~0 ~39 stained_hardened_clay 1 
setblock ~26 ~0 ~40 stained_hardened_clay 9  
fill ~26 ~0 ~41 ~26 ~0 ~42 clay 0 
setblock ~26 ~0 ~43 stonebrick 2 
setblock ~26 ~0 ~45 stained_hardened_clay 10 
setblock ~26 ~0 ~46 stained_hardened_clay 9 
setblock ~26 ~0 ~47 cobblestone 0 
setblock ~26 ~0 ~49 stained_hardened_clay 1  
fill ~27 ~0 ~2 ~37 ~0 ~2 stonebrick 1 
setblock ~27 ~0 ~14 clay 0 
setblock ~27 ~0 ~15 log 9 
setblock ~27 ~0 ~16 clay 0 
setblock ~27 ~0 ~17 gravel 0 
setblock ~27 ~0 ~18 stained_hardened_clay 7 
setblock ~27 ~0 ~19 stained_hardened_clay 9 
setblock ~27 ~0 ~20 clay 0 
setblock ~27 ~0 ~21 stained_hardened_clay 13 
setblock ~27 ~0 ~22 lit_redstone_lamp 0 
setblock ~27 ~0 ~23 clay 0 
setblock ~27 ~0 ~24 log 9 
setblock ~27 ~0 ~25 gravel 0  
fill ~27 ~0 ~26 ~29 ~0 ~26 clay 0 
setblock ~27 ~0 ~27 cobblestone 0 
setblock ~27 ~0 ~28 stonebrick 2 
setblock ~27 ~0 ~29 stained_hardened_clay 11  
fill ~27 ~0 ~30 ~28 ~0 ~30 clay 0 
setblock ~27 ~0 ~31 grass 0 
setblock ~27 ~0 ~32 stained_hardened_clay 14 
setblock ~27 ~0 ~33 clay 0 
setblock ~27 ~0 ~34 gravel 0 
setblock ~27 ~0 ~35 lit_redstone_lamp 0  
fill ~27 ~0 ~36 ~28 ~0 ~36 clay 0 
setblock ~27 ~0 ~37 log 9 
setblock ~27 ~0 ~39 grass 0 
setblock ~27 ~0 ~40 log 9 
setblock ~27 ~0 ~41 stained_hardened_clay 14  
fill ~27 ~0 ~42 ~27 ~0 ~43 clay 0 
setblock ~27 ~0 ~44 stained_hardened_clay 9 
setblock ~27 ~0 ~45 lit_redstone_lamp 0  
fill ~27 ~0 ~46 ~27 ~0 ~47 clay 0  
fill ~27 ~0 ~48 ~27 ~0 ~49 stonebrick 2  
fill ~27 ~0 ~50 ~28 ~0 ~50 clay 0  
fill ~27 ~0 ~61 ~37 ~0 ~61 stone_slab 0 
setblock ~28 ~0 ~14 grass 0 
setblock ~28 ~0 ~15 stained_hardened_clay 10 
setblock ~28 ~0 ~16 stained_hardened_clay 13 
setblock ~28 ~0 ~17 cobblestone 0 
setblock ~28 ~0 ~18 lit_redstone_lamp 0 
setblock ~28 ~0 ~19 stained_hardened_clay 15 
setblock ~28 ~0 ~20 grass 0 
setblock ~28 ~0 ~21 gravel 0 
setblock ~28 ~0 ~22 clay 0 
setblock ~28 ~0 ~23 stained_hardened_clay 7 
setblock ~28 ~0 ~24 stained_hardened_clay 10 
setblock ~28 ~0 ~25 stained_hardened_clay 13 
setblock ~28 ~0 ~27 stained_hardened_clay 14 
setblock ~28 ~0 ~28 log 9 
setblock ~28 ~0 ~29 lit_redstone_lamp 0 
setblock ~28 ~0 ~31 stained_hardened_clay 13 
setblock ~28 ~0 ~32 gravel 0 
setblock ~28 ~0 ~33 cobblestone 0 
setblock ~28 ~0 ~34 stained_hardened_clay 4 
setblock ~28 ~0 ~35 clay 0 
setblock ~28 ~0 ~37 stained_hardened_clay 13 
setblock ~28 ~0 ~38 stained_hardened_clay 10  
fill ~28 ~0 ~39 ~29 ~0 ~39 clay 0 
setblock ~28 ~0 ~40 stained_hardened_clay 7 
setblock ~28 ~0 ~41 clay 0 
setblock ~28 ~0 ~42 cobblestone 0 
setblock ~28 ~0 ~43 gravel 0  
fill ~28 ~0 ~44 ~28 ~0 ~45 clay 0 
setblock ~28 ~0 ~46 grass 0 
setblock ~28 ~0 ~47 stained_hardened_clay 11 
setblock ~28 ~0 ~48 stained_hardened_clay 4 
setblock ~28 ~0 ~49 log 9 
setblock ~29 ~0 ~14 gravel 0 
setblock ~29 ~0 ~15 stained_hardened_clay 14 
setblock ~29 ~0 ~16 cobblestone 0 
setblock ~29 ~0 ~17 stained_hardened_clay 11 
setblock ~29 ~0 ~18 clay 0 
setblock ~29 ~0 ~19 stained_hardened_clay 10 
setblock ~29 ~0 ~20 stonebrick 2 
setblock ~29 ~0 ~21 stained_hardened_clay 14 
setblock ~29 ~0 ~22 cobblestone 0 
setblock ~29 ~0 ~23 stained_hardened_clay 9 
setblock ~29 ~0 ~24 clay 0 
setblock ~29 ~0 ~25 grass 0  
fill ~29 ~0 ~27 ~30 ~0 ~27 clay 0 
setblock ~29 ~0 ~28 gravel 0 
setblock ~29 ~0 ~29 stained_hardened_clay 13 
setblock ~29 ~0 ~30 stained_hardened_clay 9 
setblock ~29 ~0 ~31 gravel 0 
setblock ~29 ~0 ~32 stained_hardened_clay 14 
setblock ~29 ~0 ~33 gravel 0 
setblock ~29 ~0 ~34 log 9 
setblock ~29 ~0 ~35 stonebrick 2 
setblock ~29 ~0 ~36 stained_hardened_clay 14 
setblock ~29 ~0 ~37 stained_hardened_clay 11 
setblock ~29 ~0 ~38 stonebrick 2 
setblock ~29 ~0 ~40 lit_redstone_lamp 0 
setblock ~29 ~0 ~41 stained_hardened_clay 13 
setblock ~29 ~0 ~42 clay 0 
setblock ~29 ~0 ~43 stained_hardened_clay 1 
setblock ~29 ~0 ~44 stained_hardened_clay 4 
setblock ~29 ~0 ~45 gravel 0 
setblock ~29 ~0 ~46 stained_hardened_clay 14 
setblock ~29 ~0 ~47 cobblestone 0 
setblock ~29 ~0 ~48 stonebrick 2 
setblock ~29 ~0 ~49 stained_hardened_clay 10 
setblock ~29 ~0 ~50 lit_redstone_lamp 0 
setblock ~30 ~0 ~14 stained_hardened_clay 1 
setblock ~30 ~0 ~15 clay 0 
setblock ~30 ~0 ~16 stained_hardened_clay 7 
setblock ~30 ~0 ~17 clay 0 
setblock ~30 ~0 ~18 stained_hardened_clay 13 
setblock ~30 ~0 ~19 gravel 0  
fill ~30 ~0 ~20 ~30 ~0 ~21 clay 0 
setblock ~30 ~0 ~22 stonebrick 2 
setblock ~30 ~0 ~23 stained_hardened_clay 13 
setblock ~30 ~0 ~24 cobblestone 0 
setblock ~30 ~0 ~25 stained_hardened_clay 15 
setblock ~30 ~0 ~26 stonebrick 2 
setblock ~30 ~0 ~28 stained_hardened_clay 10  
fill ~30 ~0 ~29 ~31 ~0 ~29 clay 0 
setblock ~30 ~0 ~30 cobblestone 0  
fill ~30 ~0 ~31 ~31 ~0 ~31 clay 0 
setblock ~30 ~0 ~32 stonebrick 2  
fill ~30 ~0 ~33 ~31 ~0 ~33 clay 0 
setblock ~30 ~0 ~34 stained_hardened_clay 13 
setblock ~30 ~0 ~35 clay 0 
setblock ~30 ~0 ~36 gravel 0 
setblock ~30 ~0 ~37 stained_hardened_clay 10 
setblock ~30 ~0 ~38 clay 0 
setblock ~30 ~0 ~39 stained_hardened_clay 15 
setblock ~30 ~0 ~40 clay 0 
setblock ~30 ~0 ~41 stained_hardened_clay 1 
setblock ~30 ~0 ~42 gravel 0 
setblock ~30 ~0 ~43 stained_hardened_clay 10  
fill ~30 ~0 ~44 ~30 ~0 ~45 clay 0 
setblock ~30 ~0 ~46 stained_hardened_clay 9 
setblock ~30 ~0 ~47 stained_hardened_clay 7 
setblock ~30 ~0 ~48 grass 0 
setblock ~30 ~0 ~49 clay 0 
setblock ~30 ~0 ~50 stonebrick 2 
setblock ~31 ~0 ~14 clay 0 
setblock ~31 ~0 ~15 stained_hardened_clay 9 
setblock ~31 ~0 ~16 log 9 
setblock ~31 ~0 ~17 lit_redstone_lamp 0  
fill ~31 ~0 ~18 ~32 ~0 ~18 clay 0 
setblock ~31 ~0 ~19 grass 0 
setblock ~31 ~0 ~20 stained_hardened_clay 9 
setblock ~31 ~0 ~21 stonebrick 2 
setblock ~31 ~0 ~22 log 9  
fill ~31 ~0 ~23 ~32 ~0 ~23 clay 0  
fill ~31 ~0 ~24 ~31 ~0 ~23 clay 0 
setblock ~31 ~0 ~25 gravel 0 
setblock ~31 ~0 ~26 clay 0 
setblock ~31 ~0 ~27 stained_hardened_clay 1 
setblock ~31 ~0 ~28 grass 0 
setblock ~31 ~0 ~30 stained_hardened_clay 10 
setblock ~31 ~0 ~32 gravel 0 
setblock ~31 ~0 ~34 stonebrick 2 
setblock ~31 ~0 ~35 grass 0  
fill ~31 ~0 ~36 ~31 ~0 ~37 clay 0 
setblock ~31 ~0 ~38 cobblestone 0  
fill ~31 ~0 ~39 ~33 ~0 ~39 clay 0 
setblock ~31 ~0 ~40 grass 0 
setblock ~31 ~0 ~41 clay 0 
setblock ~31 ~0 ~42 stained_hardened_clay 13 
setblock ~31 ~0 ~43 log 9 
setblock ~31 ~0 ~44 gravel 0 
setblock ~31 ~0 ~45 stained_hardened_clay 15 
setblock ~31 ~0 ~46 clay 0 
setblock ~31 ~0 ~47 cobblestone 0 
setblock ~31 ~0 ~48 stained_hardened_clay 13 
setblock ~31 ~0 ~49 gravel 0  
fill ~31 ~0 ~50 ~32 ~0 ~50 clay 0 
setblock ~32 ~0 ~14 cobblestone 0 
setblock ~32 ~0 ~15 clay 0 
setblock ~32 ~0 ~16 stained_hardened_clay 4 
setblock ~32 ~0 ~17 clay 0 
setblock ~32 ~0 ~19 cobblestone 0 
setblock ~32 ~0 ~20 clay 0 
setblock ~32 ~0 ~21 stained_hardened_clay 13 
setblock ~32 ~0 ~22 lit_redstone_lamp 0 
setblock ~32 ~0 ~24 gravel 0 
setblock ~32 ~0 ~25 stained_hardened_clay 14 
setblock ~32 ~0 ~26 lit_redstone_lamp 0 
setblock ~32 ~0 ~27 clay 0 
setblock ~32 ~0 ~28 stonebrick 2 
setblock ~32 ~0 ~29 gravel 0 
setblock ~32 ~0 ~30 stained_hardened_clay 13 
setblock ~32 ~0 ~31 stained_hardened_clay 1 
setblock ~32 ~0 ~32 log 9 
setblock ~32 ~0 ~33 stained_hardened_clay 4 
setblock ~32 ~0 ~34 lit_redstone_lamp 0 
setblock ~32 ~0 ~35 stained_hardened_clay 15 
setblock ~32 ~0 ~36 stonebrick 2 
setblock ~32 ~0 ~37 stained_hardened_clay 10 
setblock ~32 ~0 ~38 gravel 0 
setblock ~32 ~0 ~40 stained_hardened_clay 9 
setblock ~32 ~0 ~41 stained_hardened_clay 4 
setblock ~32 ~0 ~42 stained_hardened_clay 11 
setblock ~32 ~0 ~43 clay 0 
setblock ~32 ~0 ~44 grass 0 
setblock ~32 ~0 ~45 stained_hardened_clay 9 
setblock ~32 ~0 ~46 lit_redstone_lamp 0 
setblock ~32 ~0 ~47 stained_hardened_clay 10 
setblock ~32 ~0 ~48 log 9 
setblock ~32 ~0 ~49 stained_hardened_clay 11 
setblock ~33 ~0 ~14 stained_hardened_clay 13 
setblock ~33 ~0 ~15 grass 0 
setblock ~33 ~0 ~16 clay 0 
setblock ~33 ~0 ~17 stained_hardened_clay 11 
setblock ~33 ~0 ~18 stained_hardened_clay 7 
setblock ~33 ~0 ~19 clay 0 
setblock ~33 ~0 ~20 stained_hardened_clay 10 
setblock ~33 ~0 ~21 stained_hardened_clay 1 
setblock ~33 ~0 ~22 grass 0 
setblock ~33 ~0 ~23 stained_hardened_clay 14 
setblock ~33 ~0 ~24 cobblestone 0 
setblock ~33 ~0 ~25 clay 0 
setblock ~33 ~0 ~26 cobblestone 0 
setblock ~33 ~0 ~27 stonebrick 2 
setblock ~33 ~0 ~28 stained_hardened_clay 4 
setblock ~33 ~0 ~29 stonebrick 2 
setblock ~33 ~0 ~30 gravel 0 
setblock ~33 ~0 ~31 cobblestone 0  
fill ~33 ~0 ~32 ~34 ~0 ~32 clay 0  
fill ~33 ~0 ~33 ~34 ~0 ~33 cobblestone 0 
setblock ~33 ~0 ~34 clay 0 
setblock ~33 ~0 ~35 stonebrick 2 
setblock ~33 ~0 ~36 stained_hardened_clay 9 
setblock ~33 ~0 ~37 cobblestone 0 
setblock ~33 ~0 ~38 stained_hardened_clay 9 
setblock ~33 ~0 ~40 stonebrick 2 
setblock ~33 ~0 ~41 gravel 0  
fill ~33 ~0 ~42 ~34 ~0 ~42 clay 0 
setblock ~33 ~0 ~43 stained_hardened_clay 14 
setblock ~33 ~0 ~44 clay 0 
setblock ~33 ~0 ~45 stained_hardened_clay 7  
fill ~33 ~0 ~46 ~33 ~0 ~47 clay 0 
setblock ~33 ~0 ~48 stained_hardened_clay 1 
setblock ~33 ~0 ~49 clay 0 
setblock ~33 ~0 ~50 cobblestone 0 
setblock ~34 ~0 ~14 log 9 
setblock ~34 ~0 ~15 clay 0 
setblock ~34 ~0 ~16 stained_hardened_clay 10 
setblock ~34 ~0 ~17 stained_hardened_clay 13 
setblock ~34 ~0 ~18 gravel 0 
setblock ~34 ~0 ~19 grass 0 
setblock ~34 ~0 ~20 stonebrick 2 
setblock ~34 ~0 ~21 log 9 
setblock ~34 ~0 ~22 stonebrick 2 
setblock ~34 ~0 ~23 gravel 0  
fill ~34 ~0 ~24 ~35 ~0 ~24 clay 0 
setblock ~34 ~0 ~25 stained_hardened_clay 10 
setblock ~34 ~0 ~26 stained_hardened_clay 1  
fill ~34 ~0 ~27 ~34 ~0 ~30 clay 0 
setblock ~34 ~0 ~31 stained_hardened_clay 13 
setblock ~34 ~0 ~34 stonebrick 2 
setblock ~34 ~0 ~35 stained_hardened_clay 13 
setblock ~34 ~0 ~36 clay 0 
setblock ~34 ~0 ~37 log 9 
setblock ~34 ~0 ~38 clay 0 
setblock ~34 ~0 ~39 lit_redstone_lamp 0  
fill ~34 ~0 ~40 ~35 ~0 ~40 clay 0 
setblock ~34 ~0 ~41 log 9 
setblock ~34 ~0 ~43 stained_hardened_clay 1 
setblock ~34 ~0 ~44 stonebrick 2 
setblock ~34 ~0 ~45 clay 0   

KittysCommands:  
setblock ~34 ~0 ~46 cobblestone 0 
setblock ~34 ~0 ~47 stained_hardened_clay 4 
setblock ~34 ~0 ~48 gravel 0 
setblock ~34 ~0 ~49 stonebrick 2 
setblock ~34 ~0 ~50 clay 0 
setblock ~35 ~0 ~14 stained_hardened_clay 9 
setblock ~35 ~0 ~15 stained_hardened_clay 14 
setblock ~35 ~0 ~16 stained_hardened_clay 4 
setblock ~35 ~0 ~17 clay 0 
setblock ~35 ~0 ~18 stonebrick 2 
setblock ~35 ~0 ~19 stained_hardened_clay 1  
fill ~35 ~0 ~20 ~35 ~0 ~21 clay 0 
setblock ~35 ~0 ~22 stained_hardened_clay 11 
setblock ~35 ~0 ~23 stained_hardened_clay 13 
setblock ~35 ~0 ~25 clay 0 
setblock ~35 ~0 ~26 log 9 
setblock ~35 ~0 ~27 stained_hardened_clay 14 
setblock ~35 ~0 ~28 grass 0 
setblock ~35 ~0 ~29 stained_hardened_clay 15 
setblock ~35 ~0 ~30 clay 0 
setblock ~35 ~0 ~31 stained_hardened_clay 9 
setblock ~35 ~0 ~32 lit_redstone_lamp 0 
setblock ~35 ~0 ~33 clay 0  
fill ~35 ~0 ~34 ~35 ~0 ~35 cobblestone 0 
setblock ~35 ~0 ~36 stained_hardened_clay 9 
setblock ~35 ~0 ~37 stained_hardened_clay 1 
setblock ~35 ~0 ~38 grass 0 
setblock ~35 ~0 ~39 stained_hardened_clay 15 
setblock ~35 ~0 ~41 stained_hardened_clay 9 
setblock ~35 ~0 ~42 stained_hardened_clay 15 
setblock ~35 ~0 ~43 lit_redstone_lamp 0 
setblock ~35 ~0 ~44 clay 0 
setblock ~35 ~0 ~45 stained_hardened_clay 15 
setblock ~35 ~0 ~46 log 9 
setblock ~35 ~0 ~47 stonebrick 2 
setblock ~35 ~0 ~48 clay 0 
setblock ~35 ~0 ~49 lit_redstone_lamp 0 
setblock ~35 ~0 ~50 stonebrick 2 
setblock ~36 ~0 ~14 clay 0 
setblock ~36 ~0 ~15 lit_redstone_lamp 0 
setblock ~36 ~0 ~16 clay 0 
setblock ~36 ~0 ~17 cobblestone 0 
setblock ~36 ~0 ~18 log 9 
setblock ~36 ~0 ~19 clay 0 
setblock ~36 ~0 ~20 stonebrick 2 
setblock ~36 ~0 ~21 stained_hardened_clay 7 
setblock ~36 ~0 ~22 gravel 0 
setblock ~36 ~0 ~23 stained_hardened_clay 4 
setblock ~36 ~0 ~24 grass 0 
setblock ~36 ~0 ~25 stained_hardened_clay 14 
setblock ~36 ~0 ~26 clay 0 
setblock ~36 ~0 ~27 stained_hardened_clay 7 
setblock ~36 ~0 ~28 lit_redstone_lamp 0 
setblock ~36 ~0 ~29 cobblestone 0 
setblock ~36 ~0 ~30 stained_hardened_clay 10 
setblock ~36 ~0 ~31 grass 0 
setblock ~36 ~0 ~32 gravel 0 
setblock ~36 ~0 ~33 stained_hardened_clay 14 
setblock ~36 ~0 ~34 log 9  
fill ~36 ~0 ~35 ~36 ~0 ~36 clay 0 
setblock ~36 ~0 ~37 stained_hardened_clay 10  
fill ~36 ~0 ~38 ~36 ~0 ~39 clay 0 
setblock ~36 ~0 ~40 stained_hardened_clay 7 
setblock ~36 ~0 ~41 cobblestone 0 
setblock ~36 ~0 ~42 stained_hardened_clay 10 
setblock ~36 ~0 ~43 cobblestone 0 
setblock ~36 ~0 ~44 stained_hardened_clay 14 
setblock ~36 ~0 ~45 stonebrick 2 
setblock ~36 ~0 ~46 clay 0 
setblock ~36 ~0 ~47 gravel 0 
setblock ~36 ~0 ~48 grass 0  
fill ~36 ~0 ~49 ~36 ~0 ~50 clay 0 
setblock ~37 ~0 ~14 gravel 0 
setblock ~37 ~0 ~15 clay 0 
setblock ~37 ~0 ~16 stonebrick 2 
setblock ~37 ~0 ~17 clay 0 
setblock ~37 ~0 ~18 gravel 0 
setblock ~37 ~0 ~19 stained_hardened_clay 1  
fill ~37 ~0 ~20 ~37 ~0 ~22 clay 0 
setblock ~37 ~0 ~23 stained_hardened_clay 10 
setblock ~37 ~0 ~24 clay 0 
setblock ~37 ~0 ~25 cobblestone 0 
setblock ~37 ~0 ~26 stained_hardened_clay 1 
setblock ~37 ~0 ~27 clay 0 
setblock ~37 ~0 ~28 stonebrick 2 
setblock ~37 ~0 ~29 stained_hardened_clay 7 
setblock ~37 ~0 ~30 log 9 
setblock ~37 ~0 ~31 clay 0 
setblock ~37 ~0 ~32 stained_hardened_clay 1 
setblock ~37 ~0 ~33 clay 0 
setblock ~37 ~0 ~34 gravel 0 
setblock ~37 ~0 ~35 stained_hardened_clay 4 
setblock ~37 ~0 ~36 stonebrick 2 
setblock ~37 ~0 ~37 clay 0 
setblock ~37 ~0 ~38 gravel 0 
setblock ~37 ~0 ~39 stained_hardened_clay 14 
setblock ~37 ~0 ~40 cobblestone 0 
setblock ~37 ~0 ~41 stonebrick 2 
setblock ~37 ~0 ~42 clay 0 
setblock ~37 ~0 ~43 stained_hardened_clay 1 
setblock ~37 ~0 ~44 gravel 0 
setblock ~37 ~0 ~45 clay 0 
setblock ~37 ~0 ~46 gravel 0 
setblock ~37 ~0 ~47 stonebrick 2 
setblock ~37 ~0 ~48 clay 0 
setblock ~37 ~0 ~49 stained_hardened_clay 4 
setblock ~37 ~0 ~50 stained_hardened_clay 10  
fill ~38 ~0 ~14 ~56 ~0 ~14 stonebrick 1 
setblock ~38 ~0 ~15 stained_hardened_clay 1  
fill ~38 ~0 ~16 ~39 ~0 ~16 gravel 0 
setblock ~38 ~0 ~17 cobblestone 0 
setblock ~38 ~0 ~18 stained_hardened_clay 9 
setblock ~38 ~0 ~19 stained_hardened_clay 13  
fill ~38 ~0 ~20 ~40 ~0 ~20 stonebrick 1 
setblock ~38 ~0 ~21 clay 0 
setblock ~38 ~0 ~22 stained_hardened_clay 10 
setblock ~38 ~0 ~23 gravel 0 
setblock ~38 ~0 ~24 stained_hardened_clay 4 
setblock ~38 ~0 ~25 stained_hardened_clay 11 
setblock ~38 ~0 ~26 stained_hardened_clay 9 
setblock ~38 ~0 ~27 stained_hardened_clay 13 
setblock ~38 ~0 ~28 grass 0 
setblock ~38 ~0 ~29 stained_hardened_clay 4  
fill ~38 ~0 ~30 ~40 ~0 ~30 stonebrick 1 
setblock ~38 ~0 ~31 stained_hardened_clay 4 
setblock ~38 ~0 ~32 gravel 0 
setblock ~38 ~0 ~33 stained_hardened_clay 9  
fill ~38 ~0 ~34 ~40 ~0 ~34 stonebrick 1 
setblock ~38 ~0 ~35 stained_hardened_clay 7 
setblock ~38 ~0 ~36 grass 0 
setblock ~38 ~0 ~37 gravel 0 
setblock ~38 ~0 ~38 grass 0 
setblock ~38 ~0 ~39 stonebrick 2 
setblock ~38 ~0 ~40 stained_hardened_clay 4 
setblock ~38 ~0 ~41 stained_hardened_clay 1 
setblock ~38 ~0 ~42 stonebrick 2 
setblock ~38 ~0 ~43 stained_hardened_clay 9  
fill ~38 ~0 ~44 ~40 ~0 ~44 stonebrick 1 
setblock ~38 ~0 ~45 stained_hardened_clay 9 
setblock ~38 ~0 ~46 stained_hardened_clay 4 
setblock ~38 ~0 ~47 cobblestone 0 
setblock ~38 ~0 ~48 grass 0 
setblock ~38 ~0 ~49 stained_hardened_clay 1  
fill ~38 ~0 ~50 ~56 ~0 ~50 stonebrick 1  
fill ~38 ~0 ~60 ~44 ~0 ~60 stonebrick 1  
fill ~38 ~0 ~61 ~41 ~0 ~61 stonebrick 1  
fill ~39 ~0 ~15 ~40 ~0 ~15 obsidian 0 
setblock ~39 ~0 ~17 grass 0 
setblock ~39 ~0 ~18 cobblestone 0 
setblock ~39 ~0 ~19 stonebrick 1 
setblock ~39 ~0 ~21 stonebrick 2 
setblock ~39 ~0 ~22 lit_redstone_lamp 0 
setblock ~39 ~0 ~23 clay 0 
setblock ~39 ~0 ~24 stonebrick 2 
setblock ~39 ~0 ~25 clay 0 
setblock ~39 ~0 ~26 gravel 0 
setblock ~39 ~0 ~27 stonebrick 2 
setblock ~39 ~0 ~28 stained_hardened_clay 7 
setblock ~39 ~0 ~29 stained_hardened_clay 1 
setblock ~39 ~0 ~31 stonebrick 1 
setblock ~39 ~0 ~32 stained_hardened_clay 10 
setblock ~39 ~0 ~33 stonebrick 1 
setblock ~39 ~0 ~35 lit_redstone_lamp 0 
setblock ~39 ~0 ~36 stonebrick 2 
setblock ~39 ~0 ~37 clay 0 
setblock ~39 ~0 ~38 stained_hardened_clay 4 
setblock ~39 ~0 ~39 clay 0 
setblock ~39 ~0 ~40 log 9 
setblock ~39 ~0 ~41 lit_redstone_lamp 0 
setblock ~39 ~0 ~42 gravel 0 
setblock ~39 ~0 ~43 stained_hardened_clay 10 
setblock ~39 ~0 ~45 stonebrick 1  
fill ~39 ~0 ~46 ~41 ~0 ~46 cobblestone 0 
setblock ~39 ~0 ~47 grass 0 
setblock ~39 ~0 ~48 cobblestone 0  
fill ~39 ~0 ~49 ~40 ~0 ~49 obsidian 0 
setblock ~40 ~0 ~16 grass 0  
fill ~40 ~0 ~17 ~40 ~0 ~18 gravel 0 
setblock ~40 ~0 ~19 cobblestone 0 
setblock ~40 ~0 ~21 log 9 
setblock ~40 ~0 ~22 stained_hardened_clay 11 
setblock ~40 ~0 ~23 gravel 0 
setblock ~40 ~0 ~24 stained_hardened_clay 9 
setblock ~40 ~0 ~25 stained_hardened_clay 10 
setblock ~40 ~0 ~26 lit_redstone_lamp 0 
setblock ~40 ~0 ~27 stained_hardened_clay 11 
setblock ~40 ~0 ~28 log 9 
setblock ~40 ~0 ~29 gravel 0 
setblock ~40 ~0 ~31 grass 0 
setblock ~40 ~0 ~32 clay 0 
setblock ~40 ~0 ~33 stained_hardened_clay 10 
setblock ~40 ~0 ~35 stained_hardened_clay 9 
setblock ~40 ~0 ~36 stained_hardened_clay 4 
setblock ~40 ~0 ~37 grass 0 
setblock ~40 ~0 ~38 stained_hardened_clay 7 
setblock ~40 ~0 ~39 gravel 0 
setblock ~40 ~0 ~40 stained_hardened_clay 9 
setblock ~40 ~0 ~41 stained_hardened_clay 13 
setblock ~40 ~0 ~42 stonebrick 2 
setblock ~40 ~0 ~43 stained_hardened_clay 7 
setblock ~40 ~0 ~45 cobblestone 0 
setblock ~40 ~0 ~47 gravel 0 
setblock ~40 ~0 ~48 grass 0  
fill ~41 ~0 ~15 ~57 ~0 ~15 stonebrick 1 
setblock ~41 ~0 ~16 obsidian 0 
setblock ~41 ~0 ~17 grass 0 
setblock ~41 ~0 ~18 cobblestone 0 
setblock ~41 ~0 ~19 grass 0  
fill ~41 ~0 ~20 ~42 ~0 ~20 cobblestone 0 
setblock ~41 ~0 ~21 clay 0 
setblock ~41 ~0 ~22 gravel 0 
setblock ~41 ~0 ~23 stained_hardened_clay 7 
setblock ~41 ~0 ~24 gravel 0 
setblock ~41 ~0 ~25 stained_hardened_clay 13 
setblock ~41 ~0 ~26 stonebrick 2 
setblock ~41 ~0 ~27 gravel 0 
setblock ~41 ~0 ~28 clay 0 
setblock ~41 ~0 ~29 lit_redstone_lamp 0 
setblock ~41 ~0 ~30 stonebrick 2 
setblock ~41 ~0 ~31 stained_hardened_clay 4 
setblock ~41 ~0 ~32 stonebrick 2 
setblock ~41 ~0 ~33 grass 0 
setblock ~41 ~0 ~34 stonebrick 2 
setblock ~41 ~0 ~35 stained_hardened_clay 1 
setblock ~41 ~0 ~36 stained_hardened_clay 7 
setblock ~41 ~0 ~37 stained_hardened_clay 9 
setblock ~41 ~0 ~38 gravel 0 
setblock ~41 ~0 ~39 grass 0 
setblock ~41 ~0 ~40 clay 0 
setblock ~41 ~0 ~41 gravel 0 
setblock ~41 ~0 ~42 clay 0 
setblock ~41 ~0 ~43 log 9 
setblock ~41 ~0 ~44 gravel 0 
setblock ~41 ~0 ~45 grass 0 
setblock ~41 ~0 ~47 grass 0 
setblock ~41 ~0 ~48 obsidian 0  
fill ~41 ~0 ~49 ~57 ~0 ~49 stonebrick 1  
fill ~42 ~0 ~16 ~57 ~0 ~16 stonebrick 1  
fill ~42 ~0 ~17 ~43 ~0 ~17 obsidian 0 
setblock ~42 ~0 ~18 gravel 0 
setblock ~42 ~0 ~19 cobblestone 0 
setblock ~42 ~0 ~21 cobblestone 0 
setblock ~42 ~0 ~22 stained_hardened_clay 9 
setblock ~42 ~0 ~23 clay 0 
setblock ~42 ~0 ~24 stonebrick 2 
setblock ~42 ~0 ~25 log 9 
setblock ~42 ~0 ~26 stained_hardened_clay 4 
setblock ~42 ~0 ~27 clay 0 
setblock ~42 ~0 ~28 stained_hardened_clay 9 
setblock ~42 ~0 ~29 stained_hardened_clay 1 
setblock ~42 ~0 ~30 clay 0 
setblock ~42 ~0 ~31 stained_hardened_clay 9 
setblock ~42 ~0 ~32 stained_hardened_clay 11 
setblock ~42 ~0 ~33 clay 0 
setblock ~42 ~0 ~34 log 9 
setblock ~42 ~0 ~35 stained_hardened_clay 9 
setblock ~42 ~0 ~36 grass 0 
setblock ~42 ~0 ~37 clay 0 
setblock ~42 ~0 ~38 log 9 
setblock ~42 ~0 ~39 stained_hardened_clay 7 
setblock ~42 ~0 ~40 stonebrick 2 
setblock ~42 ~0 ~41 stained_hardened_clay 7 
setblock ~42 ~0 ~42 stained_hardened_clay 13 
setblock ~42 ~0 ~43 grass 0 
setblock ~42 ~0 ~44 cobblestone 0  
fill ~42 ~0 ~45 ~42 ~0 ~46 gravel 0  
fill ~42 ~0 ~47 ~43 ~0 ~47 obsidian 0  
fill ~42 ~0 ~48 ~57 ~0 ~48 stonebrick 1 
setblock ~43 ~0 ~18 cobblestone 0  
fill ~43 ~0 ~19 ~44 ~0 ~19 gravel 0 
setblock ~43 ~0 ~20 grass 0 
setblock ~43 ~0 ~21 gravel 0 
setblock ~43 ~0 ~22 grass 0 
setblock ~43 ~0 ~23 stained_hardened_clay 4 
setblock ~43 ~0 ~24 stained_hardened_clay 7 
setblock ~43 ~0 ~25 clay 0 
setblock ~43 ~0 ~26 grass 0 
setblock ~43 ~0 ~27 stained_hardened_clay 13 
setblock ~43 ~0 ~28 grass 0 
setblock ~43 ~0 ~29 clay 0 
setblock ~43 ~0 ~30 stained_hardened_clay 11 
setblock ~43 ~0 ~31 log 9 
setblock ~43 ~0 ~32 clay 0 
setblock ~43 ~0 ~33 gravel 0 
setblock ~43 ~0 ~34 stained_hardened_clay 7 
setblock ~43 ~0 ~35 clay 0 
setblock ~43 ~0 ~36 stained_hardened_clay 1 
setblock ~43 ~0 ~37 stonebrick 2 
setblock ~43 ~0 ~38 stained_hardened_clay 4 
setblock ~43 ~0 ~39 gravel 0 
setblock ~43 ~0 ~40 clay 0 
setblock ~43 ~0 ~41 stained_hardened_clay 1  
fill ~43 ~0 ~42 ~43 ~0 ~43 cobblestone 0 
setblock ~43 ~0 ~44 gravel 0 
setblock ~43 ~0 ~45 grass 0 
setblock ~43 ~0 ~46 gravel 0  
fill ~44 ~0 ~17 ~58 ~0 ~17 stonebrick 1 
setblock ~44 ~0 ~18 obsidian 0  
fill ~44 ~0 ~20 ~44 ~0 ~21 cobblestone 0  
fill ~44 ~0 ~22 ~46 ~0 ~22 gravel 0 
setblock ~44 ~0 ~23 cobblestone 0 
setblock ~44 ~0 ~24 lit_redstone_lamp 0 
setblock ~44 ~0 ~25 stained_hardened_clay 4 
setblock ~44 ~0 ~26 gravel 0 
setblock ~44 ~0 ~27 stained_hardened_clay 7 
setblock ~44 ~0 ~28 stained_hardened_clay 4 
setblock ~44 ~0 ~29 gravel 0 
setblock ~44 ~0 ~30 stained_hardened_clay 13 
setblock ~44 ~0 ~31 lit_redstone_lamp 0 
setblock ~44 ~0 ~32 stained_hardened_clay 1 
setblock ~44 ~0 ~33 stained_hardened_clay 9 
setblock ~44 ~0 ~34 grass 0 
setblock ~44 ~0 ~35 stained_hardened_clay 11 
setblock ~44 ~0 ~36 stained_hardened_clay 9 
setblock ~44 ~0 ~37 lit_redstone_lamp 0 
setblock ~44 ~0 ~38 stained_hardened_clay 7 
setblock ~44 ~0 ~39 stained_hardened_clay 10 
setblock ~44 ~0 ~40 gravel 0 
setblock ~44 ~0 ~41 cobblestone 0 
setblock ~44 ~0 ~42 grass 0  
fill ~44 ~0 ~43 ~44 ~0 ~44 cobblestone 0 
setblock ~44 ~0 ~45 gravel 0 
setblock ~44 ~0 ~46 obsidian 0  
fill ~44 ~0 ~47 ~58 ~0 ~47 stonebrick 1  
fill ~45 ~0 ~18 ~59 ~0 ~18 stonebrick 1 
setblock ~45 ~0 ~19 obsidian 0 
setblock ~45 ~0 ~20 gravel 0 
setblock ~45 ~0 ~21 grass 0 
setblock ~45 ~0 ~23 grass 0 
setblock ~45 ~0 ~24 cobblestone 0 
setblock ~45 ~0 ~25 stained_hardened_clay 7 
setblock ~45 ~0 ~26 stained_hardened_clay 9 
setblock ~45 ~0 ~27 stonebrick 2 
setblock ~45 ~0 ~28 clay 0 
setblock ~45 ~0 ~29 stained_hardened_clay 7 
setblock ~45 ~0 ~30 stonebrick 2 
setblock ~45 ~0 ~31 clay 0 
setblock ~45 ~0 ~32 stained_hardened_clay 13 
setblock ~45 ~0 ~33 stonebrick 2 
setblock ~45 ~0 ~34 clay 0 
setblock ~45 ~0 ~35 gravel 0 
setblock ~45 ~0 ~36 grass 0 
setblock ~45 ~0 ~37 gravel 0 
setblock ~45 ~0 ~38 stained_hardened_clay 13  
fill ~45 ~0 ~39 ~45 ~0 ~41 grass 0 
setblock ~45 ~0 ~42 cobblestone 0 
setblock ~45 ~0 ~43 gravel 0 
setblock ~45 ~0 ~44 grass 0 
setblock ~45 ~0 ~45 obsidian 0  
fill ~45 ~0 ~46 ~59 ~0 ~46 stonebrick 1  
fill ~46 ~0 ~19 ~59 ~0 ~19 stonebrick 1 
setblock ~46 ~0 ~20 obsidian 0 
setblock ~46 ~0 ~21 cobblestone 0 
setblock ~46 ~0 ~23 gravel 0 
setblock ~46 ~0 ~24 grass 0 
setblock ~46 ~0 ~25 cobblestone 0  
fill ~46 ~0 ~26 ~47 ~0 ~26 grass 0 
setblock ~46 ~0 ~27 stained_hardened_clay 11 
setblock ~46 ~0 ~28 stained_hardened_clay 7  
fill ~46 ~0 ~29 ~47 ~0 ~29 grass 0 
setblock ~46 ~0 ~30 stained_hardened_clay 4 
setblock ~46 ~0 ~31 stained_hardened_clay 10 
setblock ~46 ~0 ~32 gravel 0 
setblock ~46 ~0 ~33 grass 0 
setblock ~46 ~0 ~34 log 9 
setblock ~46 ~0 ~35 stained_hardened_clay 10 
setblock ~46 ~0 ~36 stonebrick 2 
setblock ~46 ~0 ~37 stained_hardened_clay 7 
setblock ~46 ~0 ~38 grass 0 
setblock ~46 ~0 ~39 cobblestone 0  
fill ~46 ~0 ~40 ~46 ~0 ~42 gravel 0 
setblock ~46 ~0 ~43 cobblestone 0 
setblock ~46 ~0 ~44 obsidian 0  
fill ~46 ~0 ~45 ~59 ~0 ~45 stonebrick 1  
fill ~47 ~0 ~20 ~60 ~0 ~20 stonebrick 1  
fill ~47 ~0 ~21 ~47 ~0 ~22 obsidian 0 
setblock ~47 ~0 ~23 cobblestone 0  
fill ~47 ~0 ~24 ~48 ~0 ~24 gravel 0  
fill ~47 ~0 ~25 ~48 ~0 ~25 gravel 0 
setblock ~47 ~0 ~27 gravel 0  
fill ~47 ~0 ~28 ~48 ~0 ~28 cobblestone 0 
setblock ~47 ~0 ~31 cobblestone 0 
setblock ~47 ~0 ~32 stained_hardened_clay 10 
setblock ~47 ~0 ~33 cobblestone 0 
setblock ~47 ~0 ~34 grass 0  
fill ~47 ~0 ~35 ~47 ~0 ~36 cobblestone 0 
setblock ~47 ~0 ~37 grass 0 
setblock ~47 ~0 ~38 cobblestone 0 
setblock ~47 ~0 ~39 gravel 0  
fill ~47 ~0 ~40 ~48 ~0 ~40 grass 0  
fill ~47 ~0 ~41 ~47 ~0 ~40 grass 0  
fill ~47 ~0 ~42 ~47 ~0 ~43 obsidian 0  
fill ~47 ~0 ~44 ~60 ~0 ~44 stonebrick 1  
fill ~48 ~0 ~21 ~60 ~0 ~21 stonebrick 1  
fill ~48 ~0 ~22 ~60 ~0 ~22 stonebrick 1 
setblock ~48 ~0 ~23 obsidian 0 
setblock ~48 ~0 ~26 cobblestone 0 
setblock ~48 ~0 ~27 grass 0  
fill ~48 ~0 ~29 ~48 ~0 ~31 gravel 0 
setblock ~48 ~0 ~32 grass 0  
fill ~48 ~0 ~33 ~49 ~0 ~33 gravel 0  
fill ~48 ~0 ~34 ~49 ~0 ~34 cobblestone 0 
setblock ~48 ~0 ~35 gravel 0 
setblock ~48 ~0 ~36 grass 0 
setblock ~48 ~0 ~37 cobblestone 0  
fill ~48 ~0 ~38 ~49 ~0 ~38 grass 0 
setblock ~48 ~0 ~39 cobblestone 0 
setblock ~48 ~0 ~41 obsidian 0  
fill ~48 ~0 ~42 ~60 ~0 ~42 stonebrick 1  
fill ~48 ~0 ~43 ~60 ~0 ~43 stonebrick 1  
fill ~49 ~0 ~23 ~61 ~0 ~23 stonebrick 1  
fill ~49 ~0 ~24 ~49 ~0 ~25 obsidian 0 
setblock ~49 ~0 ~26 grass 0  
fill ~49 ~0 ~27 ~49 ~0 ~28 gravel 0 
setblock ~49 ~0 ~29 grass 0 
setblock ~49 ~0 ~30 cobblestone 0  
fill ~49 ~0 ~31 ~50 ~0 ~31 gravel 0 
setblock ~49 ~0 ~32 cobblestone 0 
setblock ~49 ~0 ~35 cobblestone 0  
fill ~49 ~0 ~39 ~49 ~0 ~40 obsidian 0  
fill ~49 ~0 ~41 ~61 ~0 ~41 stonebrick 1  
fill ~50 ~0 ~24 ~61 ~0 ~24 stonebrick 1  
fill ~50 ~0 ~25 ~61 ~0 ~25 stonebrick 1  
fill ~50 ~0 ~26 ~61 ~0 ~26 stonebrick 1 
setblock ~50 ~0 ~27 cobblestone 0 
setblock ~50 ~0 ~28 gravel 0 
setblock ~50 ~0 ~29 cobblestone 0 
setblock ~50 ~0 ~30 gravel 0 
setblock ~50 ~0 ~32 gravel 0 
setblock ~50 ~0 ~33 cobblestone 0 
setblock ~50 ~0 ~34 grass 0  
fill ~50 ~0 ~35 ~50 ~0 ~36 gravel 0 
setblock ~50 ~0 ~37 grass 0  
fill ~50 ~0 ~38 ~61 ~0 ~38 stonebrick 1  
fill ~50 ~0 ~39 ~61 ~0 ~39 stonebrick 1  
fill ~50 ~0 ~40 ~61 ~0 ~40 stonebrick 1  
fill ~51 ~0 ~27 ~62 ~0 ~27 stonebrick 1  
fill ~51 ~0 ~28 ~62 ~0 ~28 stonebrick 1  
fill ~51 ~0 ~29 ~62 ~0 ~29 stonebrick 1  
fill ~51 ~0 ~30 ~62 ~0 ~30 stonebrick 1  
fill ~51 ~0 ~31 ~62 ~0 ~31 stonebrick 1  
fill ~51 ~0 ~32 ~62 ~0 ~32 stonebrick 1  
fill ~51 ~0 ~33 ~62 ~0 ~33 stonebrick 1  
fill ~51 ~0 ~34 ~62 ~0 ~34 stonebrick 1  
fill ~51 ~0 ~35 ~62 ~0 ~35 stonebrick 1  
fill ~51 ~0 ~36 ~62 ~0 ~36 stonebrick 1  
fill ~51 ~0 ~37 ~62 ~0 ~37 stonebrick 1  
fill ~2 ~1 ~27 ~6 ~1 ~27 stonebrick 1  
fill ~2 ~1 ~28 ~6 ~1 ~28 stonebrick 1  
fill ~2 ~1 ~29 ~6 ~1 ~29 stonebrick 1  
fill ~2 ~1 ~30 ~5 ~1 ~30 stonebrick 1  
fill ~2 ~1 ~31 ~5 ~1 ~31 stonebrick 1  
fill ~2 ~1 ~32 ~5 ~1 ~32 stonebrick 1  
fill ~2 ~1 ~33 ~5 ~1 ~33 stonebrick 1  
fill ~2 ~1 ~34 ~5 ~1 ~34 stonebrick 1  
fill ~2 ~1 ~35 ~6 ~1 ~35 stonebrick 1  
fill ~2 ~1 ~36 ~6 ~1 ~36 stonebrick 1  
fill ~2 ~1 ~37 ~6 ~1 ~37 stonebrick 1  
fill ~3 ~1 ~23 ~6 ~1 ~23 stonebrick 1  
fill ~3 ~1 ~24 ~6 ~1 ~24 stonebrick 1  
fill ~3 ~1 ~25 ~6 ~1 ~25 stonebrick 1  
fill ~3 ~1 ~26 ~6 ~1 ~26 stonebrick 1  
fill ~3 ~1 ~38 ~6 ~1 ~38 stonebrick 1  
fill ~3 ~1 ~39 ~6 ~1 ~39 stonebrick 1  
fill ~3 ~1 ~40 ~6 ~1 ~40 stonebrick 1  
fill ~3 ~1 ~41 ~6 ~1 ~41 stonebrick 1  
fill ~4 ~1 ~20 ~10 ~1 ~20 stonebrick 1  
fill ~4 ~1 ~21 ~8 ~1 ~21 stonebrick 1  
fill ~4 ~1 ~22 ~7 ~1 ~22 stonebrick 1  
fill ~4 ~1 ~42 ~7 ~1 ~42 stonebrick 1  
fill ~4 ~1 ~43 ~8 ~1 ~43 stonebrick 1  
fill ~4 ~1 ~44 ~10 ~1 ~44 stonebrick 1  
fill ~5 ~1 ~18 ~10 ~1 ~18 stonebrick 1  
fill ~5 ~1 ~19 ~10 ~1 ~19 stonebrick 1  
fill ~5 ~1 ~45 ~10 ~1 ~45 stonebrick 1  
fill ~5 ~1 ~46 ~10 ~1 ~46 stonebrick 1  
fill ~6 ~1 ~17 ~9 ~1 ~17 stonebrick 1  
fill ~6 ~1 ~30 ~10 ~1 ~30 grass 0  
fill ~6 ~1 ~31 ~10 ~1 ~31 grass 0  
fill ~6 ~1 ~32 ~10 ~1 ~32 grass 0  
fill ~6 ~1 ~33 ~10 ~1 ~33 grass 0  
fill ~6 ~1 ~34 ~10 ~1 ~34 grass 0  
fill ~6 ~1 ~47 ~9 ~1 ~47 stonebrick 1  
fill ~7 ~1 ~15 ~9 ~1 ~15 stonebrick 1  
fill ~7 ~1 ~16 ~9 ~1 ~16 stonebrick 1  
fill ~7 ~1 ~23 ~13 ~1 ~23 grass 0  
fill ~7 ~1 ~24 ~13 ~1 ~24 grass 0  
fill ~7 ~1 ~25 ~12 ~1 ~25 grass 0  
fill ~7 ~1 ~26 ~10 ~1 ~26 grass 0  
fill ~7 ~1 ~27 ~10 ~1 ~27 grass 0  
fill ~7 ~1 ~28 ~10 ~1 ~28 grass 0  
fill ~7 ~1 ~29 ~10 ~1 ~29 grass 0  
fill ~7 ~1 ~35 ~10 ~1 ~35 grass 0  
fill ~7 ~1 ~36 ~10 ~1 ~36 grass 0  
fill ~7 ~1 ~37 ~10 ~1 ~37 grass 0  
fill ~7 ~1 ~38 ~10 ~1 ~38 grass 0  
fill ~7 ~1 ~39 ~12 ~1 ~39 grass 0  
fill ~7 ~1 ~40 ~13 ~1 ~40 grass 0  
fill ~7 ~1 ~41 ~13 ~1 ~41 grass 0  
fill ~7 ~1 ~48 ~9 ~1 ~48 stonebrick 1  
fill ~7 ~1 ~49 ~9 ~1 ~49 stonebrick 1  
fill ~8 ~1 ~14 ~9 ~1 ~14 stonebrick 1  
fill ~8 ~1 ~22 ~14 ~1 ~22 grass 0  
fill ~8 ~1 ~42 ~14 ~1 ~42 grass 0  
fill ~8 ~1 ~50 ~9 ~1 ~50 stonebrick 1  
fill ~9 ~1 ~12 ~10 ~1 ~12 stonebrick 1  
fill ~9 ~1 ~13 ~9 ~11 ~13 stonebrick 1  
fill ~9 ~1 ~21 ~15 ~1 ~21 grass 0  
fill ~9 ~1 ~43 ~15 ~1 ~43 grass 0  
fill ~9 ~1 ~51 ~9 ~11 ~51 stonebrick 1  
fill ~9 ~1 ~52 ~10 ~1 ~52 stonebrick 1  
fill ~10 ~1 ~11 ~11 ~1 ~11 stonebrick 1  
fill ~10 ~1 ~13 ~20 ~1 ~13 cobblestone 0  
fill ~10 ~1 ~14 ~20 ~1 ~14 cobblestone 0  
fill ~10 ~1 ~15 ~17 ~1 ~15 cobblestone 0  
fill ~10 ~1 ~16 ~16 ~1 ~16 cobblestone 0  
fill ~10 ~1 ~17 ~15 ~1 ~17 cobblestone 0  
fill ~10 ~1 ~47 ~15 ~1 ~47 cobblestone 0  
fill ~10 ~1 ~48 ~16 ~1 ~48 cobblestone 0  
fill ~10 ~1 ~49 ~17 ~1 ~49 cobblestone 0  
fill ~10 ~1 ~50 ~20 ~1 ~50 cobblestone 0  
fill ~10 ~1 ~51 ~20 ~1 ~51 cobblestone 0  
fill ~10 ~1 ~53 ~11 ~1 ~53 stonebrick 1  
fill ~11 ~1 ~10 ~12 ~1 ~10 stonebrick 1  
fill ~11 ~1 ~12 ~20 ~1 ~12 cobblestone 0  
fill ~11 ~1 ~18 ~14 ~1 ~18 cobblestone 0  
fill ~11 ~1 ~19 ~14 ~1 ~19 cobblestone 0  
fill ~11 ~1 ~20 ~14 ~1 ~20 cobblestone 0  
fill ~11 ~1 ~26 ~13 ~1 ~26 cobblestone 0  
fill ~11 ~1 ~27 ~11 ~1 ~38 cobblestone 0  
fill ~11 ~1 ~44 ~14 ~1 ~44 cobblestone 0  
fill ~11 ~1 ~45 ~14 ~1 ~45 cobblestone 0  
fill ~11 ~1 ~46 ~14 ~1 ~46 cobblestone 0  
fill ~11 ~1 ~52 ~20 ~1 ~52 cobblestone 0  
fill ~11 ~1 ~54 ~12 ~1 ~54 stonebrick 1  
fill ~12 ~1 ~9 ~20 ~1 ~9 stonebrick 1  
fill ~12 ~1 ~11 ~20 ~1 ~11 cobblestone 0  
fill ~12 ~1 ~27 ~12 ~1 ~37 stone_slab 8  
fill ~12 ~1 ~38 ~13 ~1 ~38 cobblestone 0  
fill ~12 ~1 ~53 ~20 ~1 ~53 cobblestone 0  
fill ~12 ~1 ~55 ~20 ~1 ~55 stonebrick 1  
fill ~13 ~1 ~10 ~17 ~1 ~10 cobblestone 0  
fill ~13 ~1 ~25 ~14 ~1 ~25 cobblestone 0  
fill ~13 ~1 ~27 ~13 ~1 ~37 stone_slab 0  
fill ~13 ~1 ~39 ~14 ~1 ~39 cobblestone 0  
fill ~13 ~1 ~54 ~17 ~1 ~54 cobblestone 0  
fill ~14 ~1 ~8 ~21 ~1 ~8 stonebrick 1  
fill ~14 ~1 ~23 ~15 ~1 ~23 cobblestone 0  
fill ~14 ~1 ~24 ~14 ~1 ~23 cobblestone 0 
setblock ~14 ~1 ~26 stone_slab 0 
setblock ~14 ~1 ~27 tallgrass 1 
setblock ~14 ~1 ~38 stone_slab 0  
fill ~14 ~1 ~40 ~14 ~1 ~41 cobblestone 0  
fill ~14 ~1 ~56 ~21 ~1 ~56 stonebrick 1  
fill ~15 ~1 ~7 ~22 ~1 ~7 stonebrick 1  
fill ~15 ~1 ~18 ~15 ~5 ~18 stonebrick 1  
fill ~15 ~1 ~19 ~15 ~1 ~20 stonebrick 1  
fill ~15 ~1 ~22 ~16 ~1 ~22 cobblestone 0  
fill ~15 ~1 ~24 ~15 ~1 ~25 stone_slab 0 
setblock ~15 ~1 ~26 tallgrass 1  
fill ~15 ~1 ~29 ~16 ~1 ~29 tallgrass 1 
setblock ~15 ~1 ~34 tallgrass 1 
setblock ~15 ~1 ~36 tallgrass 1 
setblock ~15 ~1 ~38 tallgrass 1  
fill ~15 ~1 ~39 ~15 ~1 ~40 stone_slab 0  
fill ~15 ~1 ~41 ~15 ~1 ~42 cobblestone 0  
fill ~15 ~1 ~44 ~15 ~5 ~44 stonebrick 1  
fill ~15 ~1 ~45 ~15 ~1 ~46 stonebrick 1  
fill ~15 ~1 ~57 ~22 ~1 ~57 stonebrick 1  
fill ~16 ~1 ~19 ~18 ~1 ~19 cobblestone 0  
fill ~16 ~1 ~20 ~17 ~1 ~20 cobblestone 0  
fill ~16 ~1 ~21 ~16 ~1 ~19 cobblestone 0 
setblock ~16 ~1 ~23 stone_slab 0 
setblock ~16 ~1 ~31 tallgrass 1 
setblock ~16 ~1 ~37 tallgrass 1 
setblock ~16 ~1 ~40 tallgrass 1 
setblock ~16 ~1 ~41 stone_slab 0  
fill ~16 ~1 ~42 ~16 ~1 ~45 cobblestone 0  
fill ~17 ~1 ~6 ~29 ~1 ~6 stonebrick 1  
fill ~17 ~1 ~21 ~17 ~1 ~22 stone_slab 0 
setblock ~17 ~1 ~25 tallgrass 1 
setblock ~17 ~1 ~27 tallgrass 1 
setblock ~17 ~1 ~34 tallgrass 1  
fill ~17 ~1 ~38 ~18 ~1 ~38 tallgrass 1  
fill ~17 ~1 ~42 ~17 ~1 ~43 stone_slab 0  
fill ~17 ~1 ~44 ~17 ~1 ~45 cobblestone 0  
fill ~17 ~1 ~58 ~26 ~1 ~58 stonebrick 1  
fill ~18 ~1 ~5 ~46 ~1 ~5 stonebrick 1  
fill ~18 ~1 ~10 ~20 ~1 ~10 stonebrick 1  
fill ~18 ~1 ~15 ~20 ~1 ~15 stonebrick 1  
fill ~18 ~1 ~18 ~19 ~1 ~18 cobblestone 0 
setblock ~18 ~1 ~20 stone_slab 0 
setblock ~18 ~1 ~21 tallgrass 1 
setblock ~18 ~1 ~26 tallgrass 1  
fill ~18 ~1 ~28 ~18 ~1 ~29 tallgrass 1 
setblock ~18 ~1 ~32 tallgrass 1  
fill ~18 ~1 ~36 ~19 ~1 ~36 tallgrass 1 
setblock ~18 ~1 ~44 stone_slab 0  
fill ~18 ~1 ~45 ~18 ~1 ~46 cobblestone 0  
fill ~18 ~1 ~49 ~20 ~1 ~49 stonebrick 1  
fill ~18 ~1 ~54 ~20 ~1 ~54 stonebrick 1  
fill ~18 ~1 ~59 ~26 ~1 ~59 stonebrick 1  
fill ~19 ~1 ~16 ~22 ~1 ~16 cobblestone 0  
fill ~19 ~1 ~17 ~20 ~1 ~17 cobblestone 0 
setblock ~19 ~1 ~19 stone_slab 0 
setblock ~19 ~1 ~22 tallgrass 1  
fill ~19 ~1 ~24 ~20 ~1 ~24 tallgrass 1 
setblock ~19 ~1 ~41 tallgrass 1 
setblock ~19 ~1 ~45 stone_slab 0  
fill ~19 ~1 ~46 ~19 ~1 ~48 cobblestone 0  
fill ~20 ~1 ~4 ~44 ~1 ~4 stonebrick 1 
setblock ~20 ~1 ~18 stone_slab 0 
setblock ~20 ~1 ~20 tallgrass 1 
setblock ~20 ~1 ~43 tallgrass 1 
setblock ~20 ~1 ~45 tallgrass 1 
setblock ~20 ~1 ~46 stone_slab 0  
fill ~20 ~1 ~47 ~20 ~1 ~48 cobblestone 0  
fill ~20 ~1 ~60 ~26 ~1 ~60 stonebrick 1  
fill ~21 ~1 ~9 ~43 ~1 ~9 grass 0  
fill ~21 ~1 ~10 ~43 ~1 ~10 grass 0  
fill ~21 ~1 ~11 ~25 ~1 ~11 grass 0  
fill ~21 ~1 ~12 ~25 ~1 ~12 grass 0  
fill ~21 ~1 ~13 ~24 ~1 ~13 grass 0  
fill ~21 ~1 ~14 ~22 ~1 ~14 grass 0  
fill ~21 ~1 ~15 ~21 ~1 ~9 grass 0  
fill ~21 ~1 ~17 ~22 ~1 ~17 stone_slab 0  
fill ~21 ~1 ~18 ~21 ~1 ~19 tallgrass 1 
setblock ~21 ~1 ~21 tallgrass 1 
setblock ~21 ~1 ~25 tallgrass 1 
setblock ~21 ~1 ~41 tallgrass 1  
fill ~21 ~1 ~47 ~22 ~1 ~47 stone_slab 0  
fill ~21 ~1 ~48 ~22 ~1 ~48 cobblestone 0  
fill ~21 ~1 ~49 ~21 ~1 ~55 grass 0  
fill ~22 ~1 ~8 ~42 ~1 ~8 grass 0  
fill ~22 ~1 ~15 ~23 ~1 ~15 cobblestone 0 
setblock ~22 ~1 ~22 tallgrass 1 
setblock ~22 ~1 ~29 tallgrass 1 
setblock ~22 ~1 ~38 tallgrass 1 
setblock ~22 ~1 ~44 tallgrass 1  
fill ~22 ~1 ~49 ~23 ~1 ~49 cobblestone 0  
fill ~22 ~1 ~50 ~22 ~1 ~56 grass 0  
fill ~23 ~1 ~3 ~41 ~1 ~3 stonebrick 1  
fill ~23 ~1 ~7 ~41 ~1 ~7 grass 0  
fill ~23 ~1 ~14 ~25 ~1 ~14 cobblestone 0 
setblock ~23 ~1 ~16 stone_slab 0 
setblock ~23 ~1 ~17 tallgrass 1 
setblock ~23 ~1 ~19 tallgrass 1 
setblock ~23 ~1 ~39 tallgrass 1 
setblock ~23 ~1 ~42 tallgrass 1 
setblock ~23 ~1 ~47 tallgrass 1 
setblock ~23 ~1 ~48 stone_slab 0  
fill ~23 ~1 ~50 ~25 ~1 ~50 cobblestone 0  
fill ~23 ~1 ~51 ~24 ~1 ~51 grass 0  
fill ~23 ~1 ~52 ~25 ~1 ~52 grass 0  
fill ~23 ~1 ~53 ~25 ~1 ~53 grass 0  
fill ~23 ~1 ~54 ~43 ~1 ~54 grass 0  
fill ~23 ~1 ~55 ~43 ~1 ~55 grass 0  
fill ~23 ~1 ~56 ~42 ~1 ~56 grass 0  
fill ~23 ~1 ~57 ~41 ~1 ~57 grass 0  
fill ~23 ~1 ~61 ~26 ~1 ~61 stonebrick 1  
fill ~24 ~1 ~15 ~25 ~1 ~15 stone_slab 0  
fill ~24 ~1 ~20 ~24 ~11 ~20 stonebrick 1 
setblock ~24 ~1 ~24 tallgrass 1  
fill ~24 ~1 ~30 ~24 ~11 ~30 stonebrick 1 
setblock ~24 ~1 ~33 tallgrass 1  
fill ~24 ~1 ~34 ~24 ~11 ~34 stonebrick 1  
fill ~24 ~1 ~44 ~24 ~11 ~44 stonebrick 1 
setblock ~24 ~1 ~45 tallgrass 1 
setblock ~24 ~1 ~48 tallgrass 1  
fill ~24 ~1 ~49 ~25 ~1 ~49 stone_slab 0  
fill ~25 ~1 ~13 ~26 ~1 ~13 cobblestone 0 
setblock ~25 ~1 ~16 tallgrass 1 
setblock ~25 ~1 ~18 tallgrass 1  
fill ~25 ~1 ~19 ~25 ~11 ~19 stonebrick 3  
fill ~25 ~1 ~20 ~25 ~11 ~20 planks 1  
fill ~25 ~1 ~30 ~25 ~11 ~30 planks 1  
fill ~25 ~1 ~31 ~25 ~11 ~31 stonebrick 3  
fill ~25 ~1 ~33 ~25 ~11 ~33 stonebrick 3  
fill ~25 ~1 ~34 ~25 ~11 ~34 planks 1  
fill ~25 ~1 ~44 ~25 ~11 ~44 planks 1  
fill ~25 ~1 ~45 ~25 ~11 ~45 stonebrick 3 
setblock ~25 ~1 ~47 tallgrass 1  
fill ~25 ~1 ~51 ~26 ~1 ~51 cobblestone 0  
fill ~26 ~1 ~11 ~38 ~1 ~11 cobblestone 0  
fill ~26 ~1 ~12 ~26 ~1 ~11 cobblestone 0 
setblock ~26 ~1 ~14 stone_slab 0  
fill ~26 ~1 ~20 ~26 ~11 ~20 stonebrick 1 
setblock ~26 ~1 ~25 tallgrass 1 
setblock ~26 ~1 ~28 tallgrass 1  
fill ~26 ~1 ~30 ~26 ~11 ~30 stonebrick 1 
setblock ~26 ~1 ~33 tallgrass 1  
fill ~26 ~1 ~34 ~26 ~11 ~34 stonebrick 1  
fill ~26 ~1 ~44 ~26 ~11 ~44 stonebrick 1 
setblock ~26 ~1 ~50 stone_slab 0  
fill ~26 ~1 ~52 ~26 ~1 ~53 cobblestone 0  
fill ~27 ~1 ~2 ~37 ~1 ~2 stonebrick 1  
fill ~27 ~1 ~12 ~31 ~1 ~12 stone_slab 8  
fill ~27 ~1 ~13 ~37 ~1 ~13 stone_slab 0 
setblock ~27 ~1 ~31 tallgrass 1 
setblock ~27 ~1 ~39 tallgrass 1  
fill ~27 ~1 ~51 ~37 ~1 ~51 stone_slab 0  
fill ~27 ~1 ~52 ~37 ~1 ~52 double_stone_slab 0  
fill ~27 ~1 ~53 ~38 ~1 ~53 cobblestone 0  
fill ~27 ~1 ~58 ~37 ~1 ~58 grass 0  
fill ~27 ~1 ~59 ~37 ~1 ~59 grass 0  
fill ~27 ~1 ~60 ~37 ~1 ~60 stone_slab 8  
fill ~27 ~1 ~61 ~37 ~1 ~61 stone_slab 0 
setblock ~28 ~1 ~14 tallgrass 1 
setblock ~28 ~1 ~20 tallgrass 1 
setblock ~28 ~1 ~46 tallgrass 1 
setblock ~29 ~1 ~25 tallgrass 1  
fill ~30 ~1 ~6 ~34 ~1 ~6 grass 0 
setblock ~30 ~1 ~48 tallgrass 1 
setblock ~31 ~1 ~28 tallgrass 1 
setblock ~31 ~1 ~35 tallgrass 1 
setblock ~31 ~1 ~40 tallgrass 1 
setblock ~32 ~1 ~12 double_stone_slab 0 
setblock ~32 ~1 ~44 tallgrass 1  
fill ~33 ~1 ~12 ~37 ~1 ~12 stone_slab 8 
setblock ~33 ~1 ~15 tallgrass 1 
setblock ~33 ~1 ~22 tallgrass 1 
setblock ~34 ~1 ~19 tallgrass 1  
fill ~35 ~1 ~6 ~47 ~1 ~6 stonebrick 1 
setblock ~35 ~1 ~28 tallgrass 1 
setblock ~35 ~1 ~38 tallgrass 1 
setblock ~36 ~1 ~24 tallgrass 1 
setblock ~36 ~1 ~31 tallgrass 1 
setblock ~36 ~1 ~48 tallgrass 1  
fill ~38 ~1 ~12 ~38 ~1 ~13 cobblestone 0 
setblock ~38 ~1 ~14 stone_slab 0  
fill ~38 ~1 ~20 ~38 ~11 ~20 stonebrick 1 
setblock ~38 ~1 ~28 tallgrass 1  
fill ~38 ~1 ~30 ~38 ~11 ~30 stonebrick 1  
fill ~38 ~1 ~34 ~38 ~11 ~34 stonebrick 1 
setblock ~38 ~1 ~36 tallgrass 1 
setblock ~38 ~1 ~38 tallgrass 1  
fill ~38 ~1 ~44 ~38 ~11 ~44 stonebrick 1 
setblock ~38 ~1 ~48 tallgrass 1 
setblock ~38 ~1 ~50 stone_slab 0  
fill ~38 ~1 ~51 ~39 ~1 ~51 cobblestone 0  
fill ~38 ~1 ~52 ~38 ~1 ~51 cobblestone 0  
fill ~38 ~1 ~58 ~47 ~1 ~58 stonebrick 1  
fill ~38 ~1 ~59 ~46 ~1 ~59 stonebrick 1  
fill ~38 ~1 ~60 ~44 ~1 ~60 stonebrick 1  
fill ~38 ~1 ~61 ~41 ~1 ~61 stonebrick 1  
fill ~39 ~1 ~11 ~43 ~1 ~11 grass 0  
fill ~39 ~1 ~12 ~43 ~1 ~12 grass 0  
fill ~39 ~1 ~13 ~39 ~1 ~14 cobblestone 0  
fill ~39 ~1 ~15 ~40 ~1 ~15 stone_slab 0 
setblock ~39 ~1 ~17 tallgrass 1  
fill ~39 ~1 ~19 ~39 ~11 ~19 stonebrick 3  
fill ~39 ~1 ~20 ~39 ~11 ~20 planks 1  
fill ~39 ~1 ~30 ~39 ~11 ~30 planks 1  
fill ~39 ~1 ~31 ~39 ~11 ~31 stonebrick 3  
fill ~39 ~1 ~33 ~39 ~11 ~33 stonebrick 3  
fill ~39 ~1 ~34 ~39 ~11 ~34 planks 1  
fill ~39 ~1 ~44 ~39 ~11 ~44 planks 1  
fill ~39 ~1 ~45 ~39 ~11 ~45 stonebrick 3 
setblock ~39 ~1 ~47 tallgrass 1  
fill ~39 ~1 ~49 ~40 ~1 ~49 stone_slab 0  
fill ~39 ~1 ~50 ~41 ~1 ~50 cobblestone 0  
fill ~39 ~1 ~52 ~43 ~1 ~52 grass 0  
fill ~39 ~1 ~53 ~43 ~1 ~53 grass 0  
fill ~40 ~1 ~13 ~43 ~1 ~13 grass 0  
fill ~40 ~1 ~14 ~41 ~1 ~14 cobblestone 0 
setblock ~40 ~1 ~16 tallgrass 1  
fill ~40 ~1 ~20 ~40 ~11 ~20 stonebrick 1  
fill ~40 ~1 ~30 ~40 ~11 ~30 stonebrick 1 
setblock ~40 ~1 ~31 tallgrass 1  
fill ~40 ~1 ~34 ~40 ~11 ~34 stonebrick 1 
setblock ~40 ~1 ~37 tallgrass 1  
fill ~40 ~1 ~44 ~40 ~11 ~44 stonebrick 1 
setblock ~40 ~1 ~48 tallgrass 1  
fill ~40 ~1 ~51 ~43 ~1 ~51 grass 0  
fill ~41 ~1 ~15 ~42 ~1 ~15 cobblestone 0 
setblock ~41 ~1 ~16 stone_slab 0 
setblock ~41 ~1 ~17 tallgrass 1 
setblock ~41 ~1 ~19 tallgrass 1 
setblock ~41 ~1 ~33 tallgrass 1 
setblock ~41 ~1 ~39 tallgrass 1 
setblock ~41 ~1 ~45 tallgrass 1 
setblock ~41 ~1 ~47 tallgrass 1 
setblock ~41 ~1 ~48 stone_slab 0  
fill ~41 ~1 ~49 ~42 ~1 ~49 cobblestone 0  
fill ~42 ~1 ~7 ~49 ~1 ~7 stonebrick 1  
fill ~42 ~1 ~14 ~43 ~1 ~14 grass 0  
fill ~42 ~1 ~16 ~45 ~1 ~16 cobblestone 0  
fill ~42 ~1 ~17 ~43 ~1 ~17 stone_slab 0 
setblock ~42 ~1 ~36 tallgrass 1 
setblock ~42 ~1 ~43 tallgrass 1  
fill ~42 ~1 ~47 ~43 ~1 ~47 stone_slab 0  
fill ~42 ~1 ~48 ~45 ~1 ~48 cobblestone 0  
fill ~42 ~1 ~50 ~43 ~1 ~50 grass 0  
fill ~42 ~1 ~57 ~49 ~1 ~57 stonebrick 1  
fill ~43 ~1 ~8 ~50 ~1 ~8 stonebrick 1 
setblock ~43 ~1 ~15 grass 0 
setblock ~43 ~1 ~20 tallgrass 1 
setblock ~43 ~1 ~22 tallgrass 1 
setblock ~43 ~1 ~26 tallgrass 1 
setblock ~43 ~1 ~28 tallgrass 1 
setblock ~43 ~1 ~45 tallgrass 1 
setblock ~43 ~1 ~49 grass 0  
fill ~43 ~1 ~56 ~50 ~1 ~56 stonebrick 1  
fill ~44 ~1 ~9 ~52 ~1 ~9 stonebrick 1  
fill ~44 ~1 ~10 ~46 ~1 ~10 stonebrick 1  
fill ~44 ~1 ~11 ~52 ~1 ~11 cobblestone 0  
fill ~44 ~1 ~12 ~53 ~1 ~12 cobblestone 0  
fill ~44 ~1 ~13 ~54 ~1 ~13 cobblestone 0  
fill ~44 ~1 ~14 ~54 ~1 ~14 cobblestone 0  
fill ~44 ~1 ~15 ~46 ~1 ~15 stonebrick 1  
fill ~44 ~1 ~17 ~45 ~1 ~17 cobblestone 0 
setblock ~44 ~1 ~18 stone_slab 0 
setblock ~44 ~1 ~34 tallgrass 1 
setblock ~44 ~1 ~42 tallgrass 1 
setblock ~44 ~1 ~46 stone_slab 0  
fill ~44 ~1 ~47 ~45 ~1 ~47 cobblestone 0  
fill ~44 ~1 ~49 ~46 ~1 ~49 stonebrick 1  
fill ~44 ~1 ~50 ~54 ~1 ~50 cobblestone 0  
fill ~44 ~1 ~51 ~54 ~1 ~51 cobblestone 0  
fill ~44 ~1 ~52 ~53 ~1 ~52 cobblestone 0  
fill ~44 ~1 ~53 ~52 ~1 ~53 cobblestone 0  
fill ~44 ~1 ~54 ~46 ~1 ~54 stonebrick 1  
fill ~44 ~1 ~55 ~52 ~1 ~55 stonebrick 1  
fill ~45 ~1 ~18 ~46 ~1 ~18 cobblestone 0 
setblock ~45 ~1 ~19 stone_slab 0 
setblock ~45 ~1 ~21 tallgrass 1 
setblock ~45 ~1 ~23 tallgrass 1 
setblock ~45 ~1 ~36 tallgrass 1  
fill ~45 ~1 ~39 ~45 ~1 ~41 tallgrass 1 
setblock ~45 ~1 ~44 tallgrass 1 
setblock ~45 ~1 ~45 stone_slab 0  
fill ~45 ~1 ~46 ~46 ~1 ~46 cobblestone 0  
fill ~46 ~1 ~19 ~48 ~1 ~19 cobblestone 0 
setblock ~46 ~1 ~20 stone_slab 0 
setblock ~46 ~1 ~24 tallgrass 1  
fill ~46 ~1 ~26 ~47 ~1 ~26 tallgrass 1  
fill ~46 ~1 ~29 ~47 ~1 ~29 tallgrass 1 
setblock ~46 ~1 ~33 tallgrass 1 
setblock ~46 ~1 ~38 tallgrass 1 
setblock ~46 ~1 ~44 stone_slab 0  
fill ~46 ~1 ~45 ~48 ~1 ~45 cobblestone 0  
fill ~47 ~1 ~10 ~51 ~1 ~10 cobblestone 0  
fill ~47 ~1 ~15 ~54 ~1 ~15 cobblestone 0  
fill ~47 ~1 ~20 ~48 ~1 ~20 cobblestone 0  
fill ~47 ~1 ~21 ~47 ~1 ~22 stone_slab 0   

KittysCommands:  
setblock ~47 ~1 ~34 tallgrass 1 
setblock ~47 ~1 ~37 tallgrass 1  
fill ~47 ~1 ~40 ~48 ~1 ~40 tallgrass 1  
fill ~47 ~1 ~41 ~47 ~1 ~40 tallgrass 1  
fill ~47 ~1 ~42 ~47 ~1 ~43 stone_slab 0  
fill ~47 ~1 ~44 ~48 ~1 ~44 cobblestone 0  
fill ~47 ~1 ~49 ~54 ~1 ~49 cobblestone 0  
fill ~47 ~1 ~54 ~51 ~1 ~54 cobblestone 0  
fill ~48 ~1 ~16 ~54 ~1 ~16 cobblestone 0  
fill ~48 ~1 ~21 ~48 ~1 ~22 cobblestone 0 
setblock ~48 ~1 ~23 stone_slab 0 
setblock ~48 ~1 ~27 tallgrass 1 
setblock ~48 ~1 ~32 tallgrass 1 
setblock ~48 ~1 ~36 tallgrass 1  
fill ~48 ~1 ~38 ~49 ~1 ~38 tallgrass 1 
setblock ~48 ~1 ~41 stone_slab 0  
fill ~48 ~1 ~42 ~49 ~1 ~42 cobblestone 0  
fill ~48 ~1 ~43 ~48 ~1 ~42 cobblestone 0  
fill ~48 ~1 ~48 ~54 ~1 ~48 cobblestone 0  
fill ~49 ~1 ~17 ~54 ~1 ~17 cobblestone 0  
fill ~49 ~1 ~18 ~49 ~5 ~18 stonebrick 1  
fill ~49 ~1 ~19 ~49 ~1 ~20 stonebrick 1  
fill ~49 ~1 ~21 ~55 ~1 ~21 grass 0  
fill ~49 ~1 ~22 ~49 ~1 ~23 cobblestone 0  
fill ~49 ~1 ~24 ~49 ~1 ~25 stone_slab 0 
setblock ~49 ~1 ~26 tallgrass 1 
setblock ~49 ~1 ~29 tallgrass 1  
fill ~49 ~1 ~39 ~49 ~1 ~40 stone_slab 0  
fill ~49 ~1 ~41 ~50 ~1 ~41 cobblestone 0  
fill ~49 ~1 ~43 ~55 ~1 ~43 grass 0  
fill ~49 ~1 ~44 ~49 ~5 ~44 stonebrick 1  
fill ~49 ~1 ~45 ~49 ~1 ~46 stonebrick 1  
fill ~49 ~1 ~47 ~54 ~1 ~47 cobblestone 0  
fill ~50 ~1 ~18 ~53 ~1 ~18 cobblestone 0  
fill ~50 ~1 ~19 ~53 ~1 ~19 cobblestone 0  
fill ~50 ~1 ~20 ~53 ~1 ~20 cobblestone 0  
fill ~50 ~1 ~22 ~56 ~1 ~22 grass 0  
fill ~50 ~1 ~23 ~50 ~1 ~25 cobblestone 0 
setblock ~50 ~1 ~26 stone_slab 0 
setblock ~50 ~1 ~34 tallgrass 1 
setblock ~50 ~1 ~37 tallgrass 1 
setblock ~50 ~1 ~38 stone_slab 0  
fill ~50 ~1 ~39 ~51 ~1 ~39 cobblestone 0  
fill ~50 ~1 ~40 ~50 ~1 ~39 cobblestone 0  
fill ~50 ~1 ~42 ~56 ~1 ~42 grass 0  
fill ~50 ~1 ~44 ~53 ~1 ~44 cobblestone 0  
fill ~50 ~1 ~45 ~53 ~1 ~45 cobblestone 0  
fill ~50 ~1 ~46 ~53 ~1 ~46 cobblestone 0  
fill ~51 ~1 ~23 ~57 ~1 ~23 grass 0  
fill ~51 ~1 ~24 ~57 ~1 ~24 grass 0  
fill ~51 ~1 ~25 ~51 ~1 ~26 cobblestone 0  
fill ~51 ~1 ~27 ~51 ~1 ~37 stone_slab 0  
fill ~51 ~1 ~38 ~53 ~1 ~38 cobblestone 0  
fill ~51 ~1 ~40 ~57 ~1 ~40 grass 0  
fill ~51 ~1 ~41 ~57 ~1 ~41 grass 0  
fill ~52 ~1 ~10 ~53 ~1 ~10 stonebrick 1  
fill ~52 ~1 ~25 ~57 ~1 ~25 grass 0  
fill ~52 ~1 ~26 ~53 ~1 ~26 cobblestone 0  
fill ~52 ~1 ~27 ~52 ~1 ~37 stone_slab 8  
fill ~52 ~1 ~39 ~57 ~1 ~39 grass 0  
fill ~52 ~1 ~54 ~53 ~1 ~54 stonebrick 1  
fill ~53 ~1 ~11 ~54 ~1 ~11 stonebrick 1  
fill ~53 ~1 ~27 ~53 ~1 ~38 cobblestone 0  
fill ~53 ~1 ~53 ~54 ~1 ~53 stonebrick 1  
fill ~54 ~1 ~12 ~55 ~1 ~12 stonebrick 1  
fill ~54 ~1 ~18 ~59 ~1 ~18 stonebrick 1  
fill ~54 ~1 ~19 ~59 ~1 ~19 stonebrick 1  
fill ~54 ~1 ~20 ~60 ~1 ~20 stonebrick 1  
fill ~54 ~1 ~26 ~57 ~1 ~26 grass 0  
fill ~54 ~1 ~27 ~57 ~1 ~27 grass 0  
fill ~54 ~1 ~28 ~57 ~1 ~28 grass 0  
fill ~54 ~1 ~29 ~57 ~1 ~29 grass 0  
fill ~54 ~1 ~30 ~58 ~1 ~30 grass 0  
fill ~54 ~1 ~31 ~58 ~1 ~31 grass 0  
fill ~54 ~1 ~32 ~58 ~1 ~32 grass 0  
fill ~54 ~1 ~33 ~58 ~1 ~33 grass 0  
fill ~54 ~1 ~34 ~58 ~1 ~34 grass 0  
fill ~54 ~1 ~35 ~57 ~1 ~35 grass 0  
fill ~54 ~1 ~36 ~57 ~1 ~36 grass 0  
fill ~54 ~1 ~37 ~57 ~1 ~37 grass 0  
fill ~54 ~1 ~38 ~57 ~1 ~38 grass 0  
fill ~54 ~1 ~44 ~60 ~1 ~44 stonebrick 1  
fill ~54 ~1 ~45 ~59 ~1 ~45 stonebrick 1  
fill ~54 ~1 ~46 ~59 ~1 ~46 stonebrick 1  
fill ~54 ~1 ~52 ~55 ~1 ~52 stonebrick 1  
fill ~55 ~1 ~13 ~55 ~11 ~13 stonebrick 1  
fill ~55 ~1 ~14 ~56 ~1 ~14 stonebrick 1  
fill ~55 ~1 ~15 ~57 ~1 ~15 stonebrick 1  
fill ~55 ~1 ~16 ~57 ~1 ~16 stonebrick 1  
fill ~55 ~1 ~17 ~58 ~1 ~17 stonebrick 1  
fill ~55 ~1 ~47 ~58 ~1 ~47 stonebrick 1  
fill ~55 ~1 ~48 ~57 ~1 ~48 stonebrick 1  
fill ~55 ~1 ~49 ~57 ~1 ~49 stonebrick 1  
fill ~55 ~1 ~50 ~56 ~1 ~50 stonebrick 1  
fill ~55 ~1 ~51 ~55 ~11 ~51 stonebrick 1  
fill ~56 ~1 ~21 ~60 ~1 ~21 stonebrick 1  
fill ~56 ~1 ~43 ~60 ~1 ~43 stonebrick 1  
fill ~57 ~1 ~22 ~60 ~1 ~22 stonebrick 1  
fill ~57 ~1 ~42 ~60 ~1 ~42 stonebrick 1  
fill ~58 ~1 ~23 ~61 ~1 ~23 stonebrick 1  
fill ~58 ~1 ~24 ~61 ~1 ~24 stonebrick 1  
fill ~58 ~1 ~25 ~61 ~1 ~25 stonebrick 1  
fill ~58 ~1 ~26 ~61 ~1 ~26 stonebrick 1  
fill ~58 ~1 ~27 ~62 ~1 ~27 stonebrick 1  
fill ~58 ~1 ~28 ~62 ~1 ~28 stonebrick 1  
fill ~58 ~1 ~29 ~62 ~1 ~29 stonebrick 1  
fill ~58 ~1 ~35 ~62 ~1 ~35 stonebrick 1  
fill ~58 ~1 ~36 ~62 ~1 ~36 stonebrick 1  
fill ~58 ~1 ~37 ~62 ~1 ~37 stonebrick 1  
fill ~58 ~1 ~38 ~61 ~1 ~38 stonebrick 1  
fill ~58 ~1 ~39 ~61 ~1 ~39 stonebrick 1  
fill ~58 ~1 ~40 ~61 ~1 ~40 stonebrick 1  
fill ~58 ~1 ~41 ~61 ~1 ~41 stonebrick 1  
fill ~59 ~1 ~30 ~62 ~1 ~30 stonebrick 1  
fill ~59 ~1 ~31 ~62 ~1 ~31 stonebrick 1  
fill ~59 ~1 ~32 ~62 ~1 ~32 stonebrick 1  
fill ~59 ~1 ~33 ~62 ~1 ~33 stonebrick 1  
fill ~59 ~1 ~34 ~62 ~1 ~34 stonebrick 1  
fill ~2 ~2 ~27 ~6 ~2 ~27 stonebrick 1  
fill ~2 ~2 ~28 ~6 ~2 ~28 stonebrick 1  
fill ~2 ~2 ~29 ~6 ~2 ~29 stonebrick 1  
fill ~2 ~2 ~30 ~5 ~2 ~30 stonebrick 1  
fill ~2 ~2 ~31 ~5 ~2 ~31 stonebrick 1  
fill ~2 ~2 ~32 ~5 ~2 ~32 stonebrick 1  
fill ~2 ~2 ~33 ~5 ~2 ~33 stonebrick 1  
fill ~2 ~2 ~34 ~5 ~2 ~34 stonebrick 1  
fill ~2 ~2 ~35 ~6 ~2 ~35 stonebrick 1  
fill ~2 ~2 ~36 ~6 ~2 ~36 stonebrick 1  
fill ~2 ~2 ~37 ~6 ~2 ~37 stonebrick 1  
fill ~3 ~2 ~23 ~6 ~2 ~23 stonebrick 1  
fill ~3 ~2 ~24 ~6 ~2 ~24 stonebrick 1  
fill ~3 ~2 ~25 ~6 ~2 ~25 stonebrick 1  
fill ~3 ~2 ~26 ~6 ~2 ~26 stonebrick 1  
fill ~3 ~2 ~38 ~6 ~2 ~38 stonebrick 1  
fill ~3 ~2 ~39 ~6 ~2 ~39 stonebrick 1  
fill ~3 ~2 ~40 ~6 ~2 ~40 stonebrick 1  
fill ~3 ~2 ~41 ~6 ~2 ~41 stonebrick 1 
setblock ~4 ~2 ~20 obsidian 0  
fill ~4 ~2 ~21 ~8 ~2 ~21 stonebrick 1  
fill ~4 ~2 ~22 ~7 ~2 ~22 stonebrick 1  
fill ~4 ~2 ~42 ~7 ~2 ~42 stonebrick 1  
fill ~4 ~2 ~43 ~8 ~2 ~43 stonebrick 1 
setblock ~4 ~2 ~44 obsidian 0  
fill ~5 ~2 ~18 ~10 ~2 ~18 stonebrick 1  
fill ~5 ~2 ~19 ~9 ~2 ~19 stonebrick 1  
fill ~5 ~2 ~20 ~10 ~2 ~20 stonebrick 1  
fill ~5 ~2 ~44 ~10 ~2 ~44 stonebrick 1  
fill ~5 ~2 ~45 ~9 ~2 ~45 stonebrick 1  
fill ~5 ~2 ~46 ~10 ~2 ~46 stonebrick 1  
fill ~6 ~2 ~17 ~9 ~2 ~17 stonebrick 1  
fill ~6 ~2 ~47 ~9 ~2 ~47 stonebrick 1  
fill ~7 ~2 ~15 ~9 ~2 ~15 stonebrick 1  
fill ~7 ~2 ~16 ~9 ~2 ~16 stonebrick 1  
fill ~7 ~2 ~48 ~9 ~2 ~48 stonebrick 1  
fill ~7 ~2 ~49 ~9 ~2 ~49 stonebrick 1  
fill ~8 ~2 ~14 ~9 ~2 ~14 stonebrick 1  
fill ~8 ~2 ~50 ~9 ~2 ~50 stonebrick 1  
fill ~9 ~2 ~12 ~10 ~2 ~12 stonebrick 1 
setblock ~9 ~2 ~52 obsidian 0  
fill ~10 ~2 ~11 ~11 ~2 ~11 stonebrick 1  
fill ~10 ~2 ~19 ~10 ~5 ~19 planks 1  
fill ~10 ~2 ~45 ~10 ~5 ~45 planks 1  
fill ~10 ~2 ~52 ~10 ~8 ~52 stonebrick 1  
fill ~10 ~2 ~53 ~11 ~2 ~53 stonebrick 1  
fill ~11 ~2 ~10 ~12 ~2 ~10 stonebrick 1  
fill ~11 ~2 ~54 ~12 ~2 ~54 stonebrick 1  
fill ~12 ~2 ~9 ~20 ~2 ~9 stonebrick 1 
setblock ~12 ~2 ~55 obsidian 0  
fill ~13 ~2 ~55 ~20 ~2 ~55 stonebrick 1  
fill ~14 ~2 ~8 ~21 ~2 ~8 stonebrick 1  
fill ~14 ~2 ~56 ~21 ~2 ~56 stonebrick 1  
fill ~15 ~2 ~7 ~22 ~2 ~7 stonebrick 1  
fill ~15 ~2 ~17 ~15 ~5 ~17 cobblestone 0  
fill ~15 ~2 ~19 ~15 ~5 ~19 planks 1  
fill ~15 ~2 ~20 ~15 ~5 ~20 stonebrick 1  
fill ~15 ~2 ~45 ~15 ~5 ~45 planks 1  
fill ~15 ~2 ~46 ~15 ~5 ~46 stonebrick 1  
fill ~15 ~2 ~47 ~15 ~5 ~47 cobblestone 0  
fill ~15 ~2 ~57 ~22 ~2 ~57 stonebrick 1  
fill ~16 ~2 ~16 ~16 ~5 ~16 cobblestone 0  
fill ~16 ~2 ~19 ~16 ~5 ~19 stonebrick 3  
fill ~16 ~2 ~45 ~16 ~5 ~45 stonebrick 3  
fill ~16 ~2 ~48 ~16 ~5 ~48 cobblestone 0  
fill ~17 ~2 ~6 ~29 ~2 ~6 stonebrick 1  
fill ~17 ~2 ~15 ~17 ~5 ~15 cobblestone 0  
fill ~17 ~2 ~49 ~17 ~5 ~49 cobblestone 0  
fill ~17 ~2 ~58 ~26 ~2 ~58 stonebrick 1  
fill ~18 ~2 ~5 ~46 ~2 ~5 stonebrick 1  
fill ~18 ~2 ~10 ~18 ~5 ~10 stonebrick 1  
fill ~18 ~2 ~15 ~18 ~5 ~15 stonebrick 1  
fill ~18 ~2 ~49 ~18 ~5 ~49 stonebrick 1  
fill ~18 ~2 ~54 ~18 ~5 ~54 stonebrick 1  
fill ~18 ~2 ~59 ~25 ~2 ~59 stonebrick 1  
fill ~19 ~2 ~10 ~19 ~5 ~10 planks 1  
fill ~19 ~2 ~15 ~19 ~5 ~15 planks 1  
fill ~19 ~2 ~16 ~19 ~5 ~16 stonebrick 3  
fill ~19 ~2 ~48 ~19 ~5 ~48 stonebrick 3  
fill ~19 ~2 ~49 ~19 ~5 ~49 planks 1  
fill ~19 ~2 ~54 ~19 ~5 ~54 planks 1 
setblock ~20 ~2 ~4 obsidian 0  
fill ~20 ~2 ~10 ~20 ~5 ~10 stonebrick 1  
fill ~20 ~2 ~15 ~20 ~5 ~15 stonebrick 1  
fill ~20 ~2 ~49 ~20 ~5 ~49 stonebrick 1  
fill ~20 ~2 ~54 ~20 ~5 ~54 stonebrick 1 
setblock ~20 ~2 ~60 obsidian 0  
fill ~21 ~2 ~4 ~43 ~2 ~4 stonebrick 1  
fill ~21 ~2 ~60 ~26 ~2 ~60 stonebrick 1  
fill ~23 ~2 ~3 ~41 ~2 ~3 stonebrick 1  
fill ~23 ~2 ~61 ~26 ~2 ~61 stonebrick 1  
fill ~26 ~2 ~59 ~26 ~7 ~59 planks 1  
fill ~27 ~2 ~2 ~37 ~2 ~2 stonebrick 1  
fill ~35 ~2 ~6 ~47 ~2 ~6 stonebrick 1  
fill ~38 ~2 ~58 ~47 ~2 ~58 stonebrick 1  
fill ~38 ~2 ~59 ~38 ~7 ~59 planks 1  
fill ~38 ~2 ~60 ~43 ~2 ~60 stonebrick 1  
fill ~38 ~2 ~61 ~41 ~2 ~61 stonebrick 1  
fill ~39 ~2 ~59 ~46 ~2 ~59 stonebrick 1  
fill ~42 ~2 ~7 ~49 ~2 ~7 stonebrick 1  
fill ~42 ~2 ~57 ~49 ~2 ~57 stonebrick 1  
fill ~43 ~2 ~8 ~50 ~2 ~8 stonebrick 1  
fill ~43 ~2 ~56 ~50 ~2 ~56 stonebrick 1 
setblock ~44 ~2 ~4 obsidian 0  
fill ~44 ~2 ~9 ~51 ~2 ~9 stonebrick 1  
fill ~44 ~2 ~10 ~44 ~5 ~10 stonebrick 1  
fill ~44 ~2 ~15 ~44 ~5 ~15 stonebrick 1  
fill ~44 ~2 ~49 ~44 ~5 ~49 stonebrick 1  
fill ~44 ~2 ~54 ~44 ~5 ~54 stonebrick 1  
fill ~44 ~2 ~55 ~51 ~2 ~55 stonebrick 1 
setblock ~44 ~2 ~60 obsidian 0  
fill ~45 ~2 ~10 ~45 ~5 ~10 planks 1  
fill ~45 ~2 ~15 ~45 ~5 ~15 planks 1  
fill ~45 ~2 ~16 ~45 ~5 ~16 stonebrick 3  
fill ~45 ~2 ~48 ~45 ~5 ~48 stonebrick 3  
fill ~45 ~2 ~49 ~45 ~5 ~49 planks 1  
fill ~45 ~2 ~54 ~45 ~5 ~54 planks 1  
fill ~46 ~2 ~10 ~46 ~5 ~10 stonebrick 1  
fill ~46 ~2 ~15 ~46 ~5 ~15 stonebrick 1  
fill ~46 ~2 ~49 ~46 ~5 ~49 stonebrick 1  
fill ~46 ~2 ~54 ~46 ~5 ~54 stonebrick 1  
fill ~47 ~2 ~15 ~47 ~5 ~15 cobblestone 0  
fill ~47 ~2 ~49 ~47 ~5 ~49 cobblestone 0  
fill ~48 ~2 ~16 ~48 ~5 ~16 cobblestone 0  
fill ~48 ~2 ~19 ~48 ~5 ~19 stonebrick 3  
fill ~48 ~2 ~45 ~48 ~5 ~45 stonebrick 3  
fill ~48 ~2 ~48 ~48 ~5 ~48 cobblestone 0  
fill ~49 ~2 ~17 ~49 ~5 ~17 cobblestone 0  
fill ~49 ~2 ~19 ~49 ~5 ~19 planks 1  
fill ~49 ~2 ~20 ~49 ~5 ~20 stonebrick 1  
fill ~49 ~2 ~45 ~49 ~5 ~45 planks 1  
fill ~49 ~2 ~46 ~49 ~5 ~46 stonebrick 1  
fill ~49 ~2 ~47 ~49 ~5 ~47 cobblestone 0 
setblock ~52 ~2 ~9 obsidian 0  
fill ~52 ~2 ~10 ~53 ~2 ~10 stonebrick 1  
fill ~52 ~2 ~54 ~53 ~2 ~54 stonebrick 1 
setblock ~52 ~2 ~55 obsidian 0  
fill ~53 ~2 ~11 ~54 ~2 ~11 stonebrick 1  
fill ~53 ~2 ~53 ~54 ~2 ~53 stonebrick 1  
fill ~54 ~2 ~12 ~54 ~8 ~12 stonebrick 1  
fill ~54 ~2 ~18 ~59 ~2 ~18 stonebrick 1  
fill ~54 ~2 ~19 ~54 ~5 ~19 planks 1  
fill ~54 ~2 ~20 ~59 ~2 ~20 stonebrick 1  
fill ~54 ~2 ~44 ~59 ~2 ~44 stonebrick 1  
fill ~54 ~2 ~45 ~54 ~5 ~45 planks 1  
fill ~54 ~2 ~46 ~59 ~2 ~46 stonebrick 1  
fill ~54 ~2 ~52 ~54 ~8 ~52 stonebrick 1 
setblock ~55 ~2 ~12 obsidian 0  
fill ~55 ~2 ~14 ~56 ~2 ~14 stonebrick 1  
fill ~55 ~2 ~15 ~57 ~2 ~15 stonebrick 1  
fill ~55 ~2 ~16 ~57 ~2 ~16 stonebrick 1  
fill ~55 ~2 ~17 ~58 ~2 ~17 stonebrick 1  
fill ~55 ~2 ~19 ~59 ~2 ~19 stonebrick 1  
fill ~55 ~2 ~45 ~59 ~2 ~45 stonebrick 1  
fill ~55 ~2 ~47 ~58 ~2 ~47 stonebrick 1  
fill ~55 ~2 ~48 ~57 ~2 ~48 stonebrick 1  
fill ~55 ~2 ~49 ~57 ~2 ~49 stonebrick 1  
fill ~55 ~2 ~50 ~56 ~2 ~50 stonebrick 1 
setblock ~55 ~2 ~52 obsidian 0  
fill ~56 ~2 ~21 ~60 ~2 ~21 stonebrick 1  
fill ~56 ~2 ~43 ~60 ~2 ~43 stonebrick 1  
fill ~57 ~2 ~22 ~60 ~2 ~22 stonebrick 1  
fill ~57 ~2 ~42 ~60 ~2 ~42 stonebrick 1  
fill ~58 ~2 ~23 ~61 ~2 ~23 stonebrick 1  
fill ~58 ~2 ~24 ~61 ~2 ~24 stonebrick 1  
fill ~58 ~2 ~25 ~61 ~2 ~25 stonebrick 1  
fill ~58 ~2 ~26 ~61 ~2 ~26 stonebrick 1  
fill ~58 ~2 ~27 ~62 ~2 ~27 stonebrick 1  
fill ~58 ~2 ~28 ~62 ~2 ~28 stonebrick 1  
fill ~58 ~2 ~29 ~62 ~2 ~29 stonebrick 1  
fill ~58 ~2 ~35 ~62 ~2 ~35 stonebrick 1  
fill ~58 ~2 ~36 ~62 ~2 ~36 stonebrick 1  
fill ~58 ~2 ~37 ~62 ~2 ~37 stonebrick 1  
fill ~58 ~2 ~38 ~61 ~2 ~38 stonebrick 1  
fill ~58 ~2 ~39 ~61 ~2 ~39 stonebrick 1  
fill ~58 ~2 ~40 ~61 ~2 ~40 stonebrick 1  
fill ~58 ~2 ~41 ~61 ~2 ~41 stonebrick 1  
fill ~59 ~2 ~30 ~62 ~2 ~30 stonebrick 1  
fill ~59 ~2 ~31 ~62 ~2 ~31 stonebrick 1  
fill ~59 ~2 ~32 ~62 ~2 ~32 stonebrick 1  
fill ~59 ~2 ~33 ~62 ~2 ~33 stonebrick 1  
fill ~59 ~2 ~34 ~62 ~2 ~34 stonebrick 1 
setblock ~60 ~2 ~20 obsidian 0 
setblock ~60 ~2 ~44 obsidian 0  
fill ~2 ~3 ~27 ~4 ~3 ~27 stonebrick 1  
fill ~2 ~3 ~28 ~4 ~3 ~28 stonebrick 1  
fill ~2 ~3 ~29 ~4 ~3 ~29 stonebrick 1  
fill ~2 ~3 ~30 ~4 ~3 ~30 stonebrick 1  
fill ~2 ~3 ~31 ~4 ~3 ~31 stonebrick 1  
fill ~2 ~3 ~32 ~4 ~3 ~32 stonebrick 1  
fill ~2 ~3 ~33 ~4 ~3 ~33 stonebrick 1  
fill ~2 ~3 ~34 ~4 ~3 ~34 stonebrick 1  
fill ~2 ~3 ~35 ~4 ~3 ~35 stonebrick 1  
fill ~2 ~3 ~36 ~4 ~3 ~36 stonebrick 1  
fill ~2 ~3 ~37 ~4 ~3 ~37 stonebrick 1  
fill ~3 ~3 ~23 ~4 ~3 ~23 stonebrick 1  
fill ~3 ~3 ~24 ~4 ~3 ~24 stonebrick 1  
fill ~3 ~3 ~25 ~4 ~3 ~25 stonebrick 1  
fill ~3 ~3 ~26 ~4 ~3 ~26 stonebrick 1  
fill ~3 ~3 ~38 ~4 ~3 ~38 stonebrick 1  
fill ~3 ~3 ~39 ~4 ~3 ~39 stonebrick 1  
fill ~3 ~3 ~40 ~4 ~3 ~40 stonebrick 1  
fill ~3 ~3 ~41 ~4 ~3 ~41 stonebrick 1  
fill ~4 ~3 ~21 ~6 ~3 ~21 stonebrick 1  
fill ~4 ~3 ~22 ~5 ~3 ~22 stonebrick 1  
fill ~4 ~3 ~42 ~5 ~3 ~42 stonebrick 1  
fill ~4 ~3 ~43 ~6 ~3 ~43 stonebrick 1  
fill ~5 ~3 ~18 ~7 ~3 ~18 stonebrick 1  
fill ~5 ~3 ~19 ~6 ~3 ~19 stonebrick 1  
fill ~5 ~3 ~20 ~6 ~3 ~20 stonebrick 1  
fill ~5 ~3 ~23 ~6 ~3 ~23 obsidian 0  
fill ~5 ~3 ~24 ~6 ~3 ~24 obsidian 0  
fill ~5 ~3 ~25 ~6 ~3 ~25 obsidian 0  
fill ~5 ~3 ~26 ~6 ~3 ~26 obsidian 0  
fill ~5 ~3 ~27 ~6 ~3 ~27 obsidian 0  
fill ~5 ~3 ~28 ~6 ~3 ~28 obsidian 0  
fill ~5 ~3 ~29 ~6 ~3 ~29 obsidian 0  
fill ~5 ~3 ~30 ~5 ~3 ~41 obsidian 0  
fill ~5 ~3 ~44 ~6 ~3 ~44 stonebrick 1  
fill ~5 ~3 ~45 ~6 ~3 ~45 stonebrick 1  
fill ~5 ~3 ~46 ~7 ~3 ~46 stonebrick 1  
fill ~6 ~3 ~17 ~8 ~3 ~17 stonebrick 1  
fill ~6 ~3 ~22 ~7 ~3 ~22 obsidian 0  
fill ~6 ~3 ~35 ~6 ~3 ~42 obsidian 0  
fill ~6 ~3 ~47 ~8 ~3 ~47 stonebrick 1  
fill ~7 ~3 ~15 ~8 ~3 ~15 stonebrick 1  
fill ~7 ~3 ~16 ~8 ~3 ~16 stonebrick 1  
fill ~7 ~3 ~19 ~9 ~3 ~19 obsidian 0  
fill ~7 ~3 ~20 ~9 ~3 ~20 obsidian 0  
fill ~7 ~3 ~21 ~8 ~3 ~21 obsidian 0  
fill ~7 ~3 ~42 ~7 ~3 ~45 obsidian 0  
fill ~7 ~3 ~48 ~8 ~3 ~48 stonebrick 1  
fill ~7 ~3 ~49 ~8 ~3 ~49 stonebrick 1  
fill ~8 ~3 ~14 ~9 ~3 ~14 stonebrick 1  
fill ~8 ~3 ~18 ~9 ~3 ~18 obsidian 0  
fill ~8 ~3 ~43 ~8 ~3 ~46 obsidian 0  
fill ~8 ~3 ~50 ~9 ~3 ~50 stonebrick 1  
fill ~9 ~3 ~12 ~10 ~3 ~12 stonebrick 1  
fill ~9 ~3 ~15 ~9 ~3 ~20 obsidian 0  
fill ~9 ~3 ~44 ~9 ~3 ~49 obsidian 0  
fill ~10 ~3 ~11 ~11 ~3 ~11 stonebrick 1  
fill ~10 ~3 ~18 ~10 ~5 ~18 stonebrick 1  
fill ~10 ~3 ~20 ~10 ~5 ~20 stonebrick 1  
fill ~10 ~3 ~44 ~10 ~5 ~44 stonebrick 1  
fill ~10 ~3 ~46 ~10 ~5 ~46 stonebrick 1  
fill ~10 ~3 ~53 ~11 ~3 ~53 stonebrick 1  
fill ~11 ~3 ~10 ~12 ~3 ~10 stonebrick 1  
fill ~11 ~3 ~54 ~12 ~3 ~54 stonebrick 1  
fill ~12 ~3 ~9 ~14 ~3 ~9 stonebrick 1  
fill ~13 ~3 ~55 ~14 ~3 ~55 stonebrick 1  
fill ~14 ~3 ~8 ~17 ~3 ~8 stonebrick 1  
fill ~14 ~3 ~56 ~17 ~3 ~56 stonebrick 1  
fill ~15 ~3 ~7 ~18 ~3 ~7 stonebrick 1  
fill ~15 ~3 ~9 ~20 ~3 ~9 obsidian 0  
fill ~15 ~3 ~55 ~20 ~3 ~55 obsidian 0  
fill ~15 ~3 ~57 ~18 ~3 ~57 stonebrick 1  
fill ~17 ~3 ~6 ~21 ~3 ~6 stonebrick 1  
fill ~17 ~3 ~58 ~21 ~3 ~58 stonebrick 1  
fill ~18 ~3 ~5 ~22 ~3 ~5 stonebrick 1  
fill ~18 ~3 ~8 ~21 ~3 ~8 obsidian 0  
fill ~18 ~3 ~56 ~21 ~3 ~56 obsidian 0  
fill ~18 ~3 ~59 ~22 ~3 ~59 stonebrick 1  
fill ~19 ~3 ~7 ~22 ~3 ~7 obsidian 0  
fill ~19 ~3 ~57 ~22 ~3 ~57 obsidian 0  
fill ~21 ~3 ~4 ~43 ~3 ~4 stonebrick 1  
fill ~21 ~3 ~60 ~26 ~3 ~60 stonebrick 1  
fill ~22 ~3 ~6 ~29 ~3 ~6 obsidian 0  
fill ~22 ~3 ~58 ~25 ~3 ~58 obsidian 0  
fill ~23 ~3 ~3 ~41 ~3 ~3 stonebrick 1  
fill ~23 ~3 ~5 ~41 ~3 ~5 obsidian 0  
fill ~23 ~3 ~59 ~25 ~3 ~59 obsidian 0  
fill ~23 ~3 ~61 ~26 ~3 ~61 stonebrick 1  
fill ~26 ~3 ~58 ~26 ~7 ~58 stonebrick 1  
fill ~27 ~3 ~2 ~37 ~3 ~2 stonebrick 1  
fill ~35 ~3 ~6 ~42 ~3 ~6 obsidian 0  
fill ~38 ~3 ~58 ~38 ~7 ~58 stonebrick 1  
fill ~38 ~3 ~60 ~43 ~3 ~60 stonebrick 1  
fill ~38 ~3 ~61 ~41 ~3 ~61 stonebrick 1  
fill ~39 ~3 ~58 ~42 ~3 ~58 obsidian 0  
fill ~39 ~3 ~59 ~41 ~3 ~59 obsidian 0  
fill ~42 ~3 ~5 ~46 ~3 ~5 stonebrick 1  
fill ~42 ~3 ~7 ~45 ~3 ~7 obsidian 0  
fill ~42 ~3 ~57 ~45 ~3 ~57 obsidian 0  
fill ~42 ~3 ~59 ~46 ~3 ~59 stonebrick 1  
fill ~43 ~3 ~6 ~47 ~3 ~6 stonebrick 1  
fill ~43 ~3 ~8 ~46 ~3 ~8 obsidian 0  
fill ~43 ~3 ~56 ~46 ~3 ~56 obsidian 0  
fill ~43 ~3 ~58 ~47 ~3 ~58 stonebrick 1  
fill ~44 ~3 ~9 ~49 ~3 ~9 obsidian 0  
fill ~44 ~3 ~55 ~49 ~3 ~55 obsidian 0  
fill ~46 ~3 ~7 ~49 ~3 ~7 stonebrick 1  
fill ~46 ~3 ~57 ~49 ~3 ~57 stonebrick 1  
fill ~47 ~3 ~8 ~50 ~3 ~8 stonebrick 1  
fill ~47 ~3 ~56 ~50 ~3 ~56 stonebrick 1  
fill ~50 ~3 ~9 ~51 ~3 ~9 stonebrick 1  
fill ~50 ~3 ~55 ~51 ~3 ~55 stonebrick 1  
fill ~52 ~3 ~10 ~53 ~3 ~10 stonebrick 1  
fill ~52 ~3 ~54 ~53 ~3 ~54 stonebrick 1  
fill ~53 ~3 ~11 ~54 ~3 ~11 stonebrick 1  
fill ~53 ~3 ~53 ~54 ~3 ~53 stonebrick 1  
fill ~54 ~3 ~18 ~54 ~5 ~18 stonebrick 1  
fill ~54 ~3 ~20 ~54 ~5 ~20 stonebrick 1  
fill ~54 ~3 ~44 ~54 ~5 ~44 stonebrick 1  
fill ~54 ~3 ~46 ~54 ~5 ~46 stonebrick 1  
fill ~55 ~3 ~14 ~56 ~3 ~14 stonebrick 1  
fill ~55 ~3 ~15 ~55 ~3 ~20 obsidian 0  
fill ~55 ~3 ~44 ~57 ~3 ~44 obsidian 0  
fill ~55 ~3 ~45 ~57 ~3 ~45 obsidian 0  
fill ~55 ~3 ~46 ~56 ~3 ~46 obsidian 0  
fill ~55 ~3 ~47 ~55 ~3 ~49 obsidian 0  
fill ~55 ~3 ~50 ~56 ~3 ~50 stonebrick 1  
fill ~56 ~3 ~15 ~57 ~3 ~15 stonebrick 1  
fill ~56 ~3 ~16 ~57 ~3 ~16 stonebrick 1  
fill ~56 ~3 ~17 ~58 ~3 ~17 stonebrick 1  
fill ~56 ~3 ~18 ~56 ~3 ~21 obsidian 0  
fill ~56 ~3 ~43 ~57 ~3 ~43 obsidian 0  
fill ~56 ~3 ~47 ~58 ~3 ~47 stonebrick 1  
fill ~56 ~3 ~48 ~57 ~3 ~48 stonebrick 1  
fill ~56 ~3 ~49 ~57 ~3 ~49 stonebrick 1  
fill ~57 ~3 ~18 ~59 ~3 ~18 stonebrick 1  
fill ~57 ~3 ~19 ~57 ~3 ~22 obsidian 0  
fill ~57 ~3 ~42 ~58 ~3 ~42 obsidian 0  
fill ~57 ~3 ~46 ~59 ~3 ~46 stonebrick 1  
fill ~58 ~3 ~19 ~59 ~3 ~19 stonebrick 1  
fill ~58 ~3 ~20 ~59 ~3 ~20 stonebrick 1  
fill ~58 ~3 ~21 ~60 ~3 ~21 stonebrick 1  
fill ~58 ~3 ~22 ~58 ~3 ~29 obsidian 0  
fill ~58 ~3 ~35 ~59 ~3 ~35 obsidian 0  
fill ~58 ~3 ~36 ~59 ~3 ~36 obsidian 0  
fill ~58 ~3 ~37 ~59 ~3 ~37 obsidian 0  
fill ~58 ~3 ~38 ~59 ~3 ~38 obsidian 0  
fill ~58 ~3 ~39 ~59 ~3 ~39 obsidian 0  
fill ~58 ~3 ~40 ~59 ~3 ~40 obsidian 0  
fill ~58 ~3 ~41 ~59 ~3 ~41 obsidian 0  
fill ~58 ~3 ~43 ~60 ~3 ~43 stonebrick 1  
fill ~58 ~3 ~44 ~59 ~3 ~44 stonebrick 1  
fill ~58 ~3 ~45 ~59 ~3 ~45 stonebrick 1  
fill ~59 ~3 ~22 ~60 ~3 ~22 stonebrick 1  
fill ~59 ~3 ~23 ~59 ~3 ~41 obsidian 0  
fill ~59 ~3 ~42 ~60 ~3 ~42 stonebrick 1  
fill ~60 ~3 ~23 ~61 ~3 ~23 stonebrick 1  
fill ~60 ~3 ~24 ~61 ~3 ~24 stonebrick 1  
fill ~60 ~3 ~25 ~61 ~3 ~25 stonebrick 1  
fill ~60 ~3 ~26 ~61 ~3 ~26 stonebrick 1  
fill ~60 ~3 ~27 ~62 ~3 ~27 stonebrick 1  
fill ~60 ~3 ~28 ~62 ~3 ~28 stonebrick 1  
fill ~60 ~3 ~29 ~62 ~3 ~29 stonebrick 1  
fill ~60 ~3 ~30 ~62 ~3 ~30 stonebrick 1  
fill ~60 ~3 ~31 ~62 ~3 ~31 stonebrick 1  
fill ~60 ~3 ~32 ~62 ~3 ~32 stonebrick 1  
fill ~60 ~3 ~33 ~62 ~3 ~33 stonebrick 1  
fill ~60 ~3 ~34 ~62 ~3 ~34 stonebrick 1  
fill ~60 ~3 ~35 ~62 ~3 ~35 stonebrick 1  
fill ~60 ~3 ~36 ~62 ~3 ~36 stonebrick 1  
fill ~60 ~3 ~37 ~62 ~3 ~37 stonebrick 1  
fill ~60 ~3 ~38 ~61 ~3 ~38 stonebrick 1  
fill ~60 ~3 ~39 ~61 ~3 ~39 stonebrick 1  
fill ~60 ~3 ~40 ~61 ~3 ~40 stonebrick 1  
fill ~60 ~3 ~41 ~61 ~3 ~41 stonebrick 1 
setblock ~2 ~4 ~27 obsidian 0  
fill ~2 ~4 ~28 ~4 ~4 ~28 stonebrick 1  
fill ~2 ~4 ~29 ~4 ~4 ~29 stonebrick 1  
fill ~2 ~4 ~30 ~4 ~4 ~30 stonebrick 1  
fill ~2 ~4 ~31 ~4 ~4 ~31 stonebrick 1  
fill ~2 ~4 ~32 ~4 ~4 ~32 stonebrick 1  
fill ~2 ~4 ~33 ~4 ~4 ~33 stonebrick 1  
fill ~2 ~4 ~34 ~4 ~4 ~34 stonebrick 1  
fill ~2 ~4 ~35 ~4 ~4 ~35 stonebrick 1  
fill ~2 ~4 ~36 ~4 ~4 ~36 stonebrick 1 
setblock ~2 ~4 ~37 obsidian 0 
setblock ~3 ~4 ~23 obsidian 0  
fill ~3 ~4 ~24 ~4 ~4 ~24 stonebrick 1  
fill ~3 ~4 ~25 ~4 ~4 ~25 stonebrick 1  
fill ~3 ~4 ~26 ~4 ~4 ~26 stonebrick 1  
fill ~3 ~4 ~27 ~4 ~4 ~27 stonebrick 1  
fill ~3 ~4 ~37 ~4 ~4 ~37 stonebrick 1  
fill ~3 ~4 ~38 ~4 ~4 ~38 stonebrick 1  
fill ~3 ~4 ~39 ~4 ~4 ~39 stonebrick 1  
fill ~3 ~4 ~40 ~4 ~4 ~40 stonebrick 1 
setblock ~3 ~4 ~41 obsidian 0  
fill ~4 ~4 ~21 ~6 ~4 ~21 stonebrick 1  
fill ~4 ~4 ~22 ~5 ~4 ~22 stonebrick 1  
fill ~4 ~4 ~23 ~4 ~10 ~23 stonebrick 1  
fill ~4 ~4 ~41 ~4 ~10 ~41 stonebrick 1  
fill ~4 ~4 ~42 ~5 ~4 ~42 stonebrick 1  
fill ~4 ~4 ~43 ~6 ~4 ~43 stonebrick 1 
setblock ~5 ~4 ~18 obsidian 0  
fill ~5 ~4 ~19 ~6 ~4 ~19 stonebrick 1  
fill ~5 ~4 ~20 ~6 ~4 ~20 stonebrick 1  
fill ~5 ~4 ~44 ~6 ~4 ~44 stonebrick 1  
fill ~5 ~4 ~45 ~6 ~4 ~45 stonebrick 1 
setblock ~5 ~4 ~46 obsidian 0  
fill ~6 ~4 ~17 ~8 ~4 ~17 stonebrick 1  
fill ~6 ~4 ~18 ~7 ~4 ~18 stonebrick 1  
fill ~6 ~4 ~46 ~7 ~4 ~46 stonebrick 1  
fill ~6 ~4 ~47 ~8 ~4 ~47 stonebrick 1  
fill ~7 ~4 ~15 ~8 ~4 ~15 stonebrick 1  
fill ~7 ~4 ~16 ~8 ~4 ~16 stonebrick 1  
fill ~7 ~4 ~48 ~8 ~4 ~48 stonebrick 1  
fill ~7 ~4 ~49 ~8 ~4 ~49 stonebrick 1  
fill ~8 ~4 ~14 ~9 ~4 ~14 stonebrick 1  
fill ~8 ~4 ~50 ~9 ~4 ~50 stonebrick 1  
fill ~9 ~4 ~12 ~10 ~4 ~12 stonebrick 1  
fill ~9 ~4 ~19 ~9 ~5 ~19 stonebrick 3  
fill ~9 ~4 ~45 ~9 ~5 ~45 stonebrick 3  
fill ~10 ~4 ~11 ~11 ~4 ~11 stonebrick 1 
setblock ~10 ~4 ~53 obsidian 0  
fill ~11 ~4 ~10 ~12 ~4 ~10 stonebrick 1  
fill ~11 ~4 ~53 ~11 ~8 ~53 stonebrick 1 
setblock ~11 ~4 ~54 obsidian 0  
fill ~12 ~4 ~9 ~14 ~4 ~9 stonebrick 1  
fill ~12 ~4 ~54 ~12 ~8 ~54 stonebrick 1  
fill ~13 ~4 ~55 ~14 ~4 ~55 stonebrick 1  
fill ~14 ~4 ~8 ~17 ~4 ~8 stonebrick 1  
fill ~14 ~4 ~56 ~17 ~4 ~56 stonebrick 1  
fill ~15 ~4 ~7 ~18 ~4 ~7 stonebrick 1  
fill ~15 ~4 ~57 ~18 ~4 ~57 stonebrick 1 
setblock ~16 ~4 ~17 cobblestone 0 
setblock ~16 ~4 ~47 cobblestone 0  
fill ~17 ~4 ~6 ~21 ~4 ~6 stonebrick 1 
setblock ~17 ~4 ~16 cobblestone 0 
setblock ~17 ~4 ~48 cobblestone 0  
fill ~17 ~4 ~58 ~21 ~4 ~58 stonebrick 1 
setblock ~18 ~4 ~5 obsidian 0 
setblock ~18 ~4 ~59 obsidian 0  
fill ~19 ~4 ~5 ~20 ~4 ~5 stonebrick 1  
fill ~19 ~4 ~9 ~19 ~5 ~9 stonebrick 3  
fill ~19 ~4 ~55 ~19 ~5 ~55 stonebrick 3  
fill ~19 ~4 ~59 ~20 ~4 ~59 stonebrick 1  
fill ~21 ~4 ~4 ~43 ~4 ~4 stonebrick 1 
setblock ~21 ~4 ~5 obsidian 0 
setblock ~21 ~4 ~59 obsidian 0  
fill ~21 ~4 ~60 ~26 ~4 ~60 stonebrick 1  
fill ~22 ~4 ~5 ~22 ~6 ~5 stonebrick 1  
fill ~22 ~4 ~59 ~22 ~6 ~59 stonebrick 1 
setblock ~23 ~4 ~3 obsidian 0 
setblock ~23 ~4 ~61 obsidian 0  
fill ~24 ~4 ~3 ~40 ~4 ~3 stonebrick 1  
fill ~24 ~4 ~61 ~26 ~4 ~61 stonebrick 1  
fill ~25 ~4 ~59 ~25 ~7 ~59 stonebrick 3 
setblock ~27 ~4 ~2 obsidian 0  
fill ~28 ~4 ~2 ~36 ~4 ~2 stonebrick 1 
setblock ~37 ~4 ~2 obsidian 0  
fill ~38 ~4 ~60 ~43 ~4 ~60 stonebrick 1  
fill ~38 ~4 ~61 ~40 ~4 ~61 stonebrick 1  
fill ~39 ~4 ~59 ~39 ~7 ~59 stonebrick 3 
setblock ~41 ~4 ~3 obsidian 0 
setblock ~41 ~4 ~61 obsidian 0  
fill ~42 ~4 ~5 ~45 ~4 ~5 stonebrick 1  
fill ~42 ~4 ~59 ~42 ~6 ~59 stonebrick 1  
fill ~43 ~4 ~6 ~47 ~4 ~6 stonebrick 1  
fill ~43 ~4 ~58 ~47 ~4 ~58 stonebrick 1 
setblock ~43 ~4 ~59 obsidian 0  
fill ~44 ~4 ~59 ~45 ~4 ~59 stonebrick 1  
fill ~45 ~4 ~9 ~45 ~5 ~9 stonebrick 3  
fill ~45 ~4 ~55 ~45 ~5 ~55 stonebrick 3 
setblock ~46 ~4 ~5 obsidian 0  
fill ~46 ~4 ~7 ~49 ~4 ~7 stonebrick 1  
fill ~46 ~4 ~57 ~49 ~4 ~57 stonebrick 1 
setblock ~46 ~4 ~59 obsidian 0  
fill ~47 ~4 ~8 ~50 ~4 ~8 stonebrick 1 
setblock ~47 ~4 ~16 cobblestone 0 
setblock ~47 ~4 ~48 cobblestone 0  
fill ~47 ~4 ~56 ~50 ~4 ~56 stonebrick 1 
setblock ~48 ~4 ~17 cobblestone 0 
setblock ~48 ~4 ~47 cobblestone 0  
fill ~50 ~4 ~9 ~51 ~4 ~9 stonebrick 1  
fill ~50 ~4 ~55 ~51 ~4 ~55 stonebrick 1  
fill ~52 ~4 ~10 ~52 ~8 ~10 stonebrick 1  
fill ~52 ~4 ~54 ~52 ~8 ~54 stonebrick 1 
setblock ~53 ~4 ~10 obsidian 0  
fill ~53 ~4 ~11 ~53 ~8 ~11 stonebrick 1  
fill ~53 ~4 ~53 ~53 ~8 ~53 stonebrick 1 
setblock ~53 ~4 ~54 obsidian 0 
setblock ~54 ~4 ~11 obsidian 0 
setblock ~54 ~4 ~53 obsidian 0  
fill ~55 ~4 ~14 ~56 ~4 ~14 stonebrick 1  
fill ~55 ~4 ~19 ~55 ~5 ~19 stonebrick 3  
fill ~55 ~4 ~45 ~55 ~5 ~45 stonebrick 3  
fill ~55 ~4 ~50 ~56 ~4 ~50 stonebrick 1  
fill ~56 ~4 ~15 ~57 ~4 ~15 stonebrick 1  
fill ~56 ~4 ~16 ~57 ~4 ~16 stonebrick 1  
fill ~56 ~4 ~17 ~58 ~4 ~17 stonebrick 1  
fill ~56 ~4 ~47 ~58 ~4 ~47 stonebrick 1  
fill ~56 ~4 ~48 ~57 ~4 ~48 stonebrick 1  
fill ~56 ~4 ~49 ~57 ~4 ~49 stonebrick 1  
fill ~57 ~4 ~18 ~58 ~4 ~18 stonebrick 1  
fill ~57 ~4 ~46 ~58 ~4 ~46 stonebrick 1  
fill ~58 ~4 ~19 ~59 ~4 ~19 stonebrick 1  
fill ~58 ~4 ~20 ~59 ~4 ~20 stonebrick 1  
fill ~58 ~4 ~21 ~60 ~4 ~21 stonebrick 1  
fill ~58 ~4 ~43 ~60 ~4 ~43 stonebrick 1  
fill ~58 ~4 ~44 ~59 ~4 ~44 stonebrick 1  
fill ~58 ~4 ~45 ~59 ~4 ~45 stonebrick 1 
setblock ~59 ~4 ~18 obsidian 0  
fill ~59 ~4 ~22 ~60 ~4 ~22 stonebrick 1  
fill ~59 ~4 ~42 ~60 ~4 ~42 stonebrick 1 
setblock ~59 ~4 ~46 obsidian 0  
fill ~60 ~4 ~23 ~60 ~10 ~23 stonebrick 1  
fill ~60 ~4 ~24 ~61 ~4 ~24 stonebrick 1  
fill ~60 ~4 ~25 ~61 ~4 ~25 stonebrick 1  
fill ~60 ~4 ~26 ~61 ~4 ~26 stonebrick 1  
fill ~60 ~4 ~27 ~61 ~4 ~27 stonebrick 1  
fill ~60 ~4 ~28 ~62 ~4 ~28 stonebrick 1  
fill ~60 ~4 ~29 ~62 ~4 ~29 stonebrick 1  
fill ~60 ~4 ~30 ~62 ~4 ~30 stonebrick 1  
fill ~60 ~4 ~31 ~62 ~4 ~31 stonebrick 1  
fill ~60 ~4 ~32 ~62 ~4 ~32 stonebrick 1  
fill ~60 ~4 ~33 ~62 ~4 ~33 stonebrick 1  
fill ~60 ~4 ~34 ~62 ~4 ~34 stonebrick 1  
fill ~60 ~4 ~35 ~62 ~4 ~35 stonebrick 1  
fill ~60 ~4 ~36 ~62 ~4 ~36 stonebrick 1  
fill ~60 ~4 ~37 ~61 ~4 ~37 stonebrick 1  
fill ~60 ~4 ~38 ~61 ~4 ~38 stonebrick 1  
fill ~60 ~4 ~39 ~61 ~4 ~39 stonebrick 1  
fill ~60 ~4 ~40 ~61 ~4 ~40 stonebrick 1  
fill ~60 ~4 ~41 ~60 ~10 ~41 stonebrick 1 
setblock ~61 ~4 ~23 obsidian 0 
setblock ~61 ~4 ~41 obsidian 0 
setblock ~62 ~4 ~27 obsidian 0 
setblock ~62 ~4 ~37 obsidian 0  
fill ~2 ~5 ~28 ~3 ~5 ~28 stonebrick 1  
fill ~2 ~5 ~29 ~3 ~5 ~29 stonebrick 1  
fill ~2 ~5 ~30 ~3 ~5 ~30 stonebrick 1  
fill ~2 ~5 ~31 ~3 ~5 ~31 stonebrick 1  
fill ~2 ~5 ~32 ~3 ~5 ~32 stonebrick 1  
fill ~2 ~5 ~33 ~3 ~5 ~33 stonebrick 1  
fill ~2 ~5 ~34 ~3 ~5 ~34 stonebrick 1  
fill ~2 ~5 ~35 ~3 ~5 ~35 stonebrick 1  
fill ~2 ~5 ~36 ~3 ~5 ~36 stonebrick 1  
fill ~3 ~5 ~24 ~4 ~5 ~24 stonebrick 1  
fill ~3 ~5 ~25 ~3 ~11 ~25 stonebrick 1  
fill ~3 ~5 ~26 ~3 ~13 ~26 stonebrick 1  
fill ~3 ~5 ~27 ~3 ~9 ~27 stonebrick 1  
fill ~3 ~5 ~37 ~3 ~9 ~37 stonebrick 1  
fill ~3 ~5 ~38 ~3 ~13 ~38 stonebrick 1  
fill ~3 ~5 ~39 ~3 ~11 ~39 stonebrick 1  
fill ~3 ~5 ~40 ~4 ~5 ~40 stonebrick 1  
fill ~4 ~5 ~21 ~4 ~9 ~21 stonebrick 1  
fill ~4 ~5 ~22 ~5 ~5 ~22 stonebrick 1  
fill ~4 ~5 ~25 ~4 ~5 ~39 obsidian 0  
fill ~4 ~5 ~42 ~5 ~5 ~42 stonebrick 1  
fill ~4 ~5 ~43 ~4 ~9 ~43 stonebrick 1  
fill ~5 ~5 ~19 ~6 ~5 ~19 stonebrick 1  
fill ~5 ~5 ~20 ~5 ~7 ~20 stonebrick 1  
fill ~5 ~5 ~21 ~6 ~5 ~21 obsidian 0  
fill ~5 ~5 ~43 ~6 ~5 ~43 obsidian 0  
fill ~5 ~5 ~44 ~5 ~7 ~44 stonebrick 1  
fill ~5 ~5 ~45 ~6 ~5 ~45 stonebrick 1  
fill ~6 ~5 ~17 ~6 ~9 ~17 stonebrick 1  
fill ~6 ~5 ~18 ~6 ~6 ~18 stonebrick 1 
setblock ~6 ~5 ~20 obsidian 0 
setblock ~6 ~5 ~44 obsidian 0  
fill ~6 ~5 ~46 ~6 ~6 ~46 stonebrick 1  
fill ~6 ~5 ~47 ~6 ~9 ~47 stonebrick 1  
fill ~7 ~5 ~15 ~8 ~5 ~15 stonebrick 1  
fill ~7 ~5 ~16 ~7 ~13 ~16 stonebrick 1  
fill ~7 ~5 ~17 ~8 ~5 ~17 obsidian 0  
fill ~7 ~5 ~18 ~7 ~5 ~17 obsidian 0  
fill ~7 ~5 ~46 ~7 ~5 ~47 obsidian 0  
fill ~7 ~5 ~48 ~7 ~13 ~48 stonebrick 1  
fill ~7 ~5 ~49 ~8 ~5 ~49 stonebrick 1  
fill ~8 ~5 ~14 ~8 ~9 ~14 stonebrick 1 
setblock ~8 ~5 ~16 obsidian 0  
fill ~8 ~5 ~47 ~8 ~5 ~48 obsidian 0  
fill ~8 ~5 ~50 ~8 ~9 ~50 stonebrick 1 
setblock ~9 ~5 ~12 obsidian 0 
setblock ~9 ~5 ~14 obsidian 0 
setblock ~9 ~5 ~50 obsidian 0  
fill ~10 ~5 ~11 ~11 ~5 ~11 stonebrick 1  
fill ~10 ~5 ~12 ~10 ~8 ~12 stonebrick 1  
fill ~11 ~5 ~10 ~12 ~5 ~10 stonebrick 1 
setblock ~12 ~5 ~9 obsidian 0  
fill ~13 ~5 ~9 ~13 ~11 ~9 stonebrick 1  
fill ~13 ~5 ~55 ~13 ~11 ~55 stonebrick 1  
fill ~14 ~5 ~8 ~15 ~5 ~8 stonebrick 1 
setblock ~14 ~5 ~9 obsidian 0 
setblock ~14 ~5 ~55 obsidian 0  
fill ~14 ~5 ~56 ~15 ~5 ~56 stonebrick 1  
fill ~15 ~5 ~7 ~16 ~5 ~7 stonebrick 1  
fill ~15 ~5 ~57 ~16 ~5 ~57 stonebrick 1  
fill ~16 ~5 ~8 ~17 ~5 ~8 obsidian 0  
fill ~16 ~5 ~56 ~17 ~5 ~56 obsidian 0  
fill ~17 ~5 ~6 ~19 ~5 ~6 stonebrick 1  
fill ~17 ~5 ~7 ~18 ~5 ~7 obsidian 0  
fill ~17 ~5 ~57 ~18 ~5 ~57 obsidian 0  
fill ~17 ~5 ~58 ~19 ~5 ~58 stonebrick 1  
fill ~19 ~5 ~5 ~20 ~5 ~5 stonebrick 1  
fill ~19 ~5 ~59 ~20 ~5 ~59 stonebrick 1  
fill ~20 ~5 ~6 ~21 ~5 ~6 obsidian 0  
fill ~20 ~5 ~58 ~21 ~5 ~58 obsidian 0  
fill ~21 ~5 ~4 ~24 ~5 ~4 stonebrick 1  
fill ~21 ~5 ~60 ~24 ~5 ~60 stonebrick 1  
fill ~24 ~5 ~3 ~40 ~5 ~3 stonebrick 1  
fill ~24 ~5 ~61 ~26 ~5 ~61 stonebrick 1  
fill ~25 ~5 ~4 ~39 ~5 ~4 obsidian 0 
setblock ~25 ~5 ~60 obsidian 0  
fill ~26 ~5 ~60 ~26 ~7 ~60 stonebrick 1  
fill ~28 ~5 ~2 ~36 ~5 ~2 stonebrick 1  
fill ~38 ~5 ~60 ~38 ~7 ~60 stonebrick 1  
fill ~38 ~5 ~61 ~40 ~5 ~61 stonebrick 1 
setblock ~39 ~5 ~60 obsidian 0  
fill ~40 ~5 ~4 ~43 ~5 ~4 stonebrick 1  
fill ~40 ~5 ~60 ~43 ~5 ~60 stonebrick 1  
fill ~42 ~5 ~5 ~42 ~6 ~5 stonebrick 1  
fill ~43 ~5 ~5 ~43 ~5 ~6 obsidian 0  
fill ~43 ~5 ~58 ~44 ~5 ~58 obsidian 0  
fill ~44 ~5 ~5 ~45 ~5 ~5 stonebrick 1 
setblock ~44 ~5 ~6 obsidian 0  
fill ~44 ~5 ~59 ~45 ~5 ~59 stonebrick 1  
fill ~45 ~5 ~6 ~47 ~5 ~6 stonebrick 1  
fill ~45 ~5 ~58 ~47 ~5 ~58 stonebrick 1  
fill ~46 ~5 ~7 ~47 ~5 ~7 obsidian 0  
fill ~46 ~5 ~57 ~47 ~5 ~57 obsidian 0  
fill ~47 ~5 ~8 ~48 ~5 ~8 obsidian 0  
fill ~47 ~5 ~56 ~48 ~5 ~56 obsidian 0  
fill ~48 ~5 ~7 ~49 ~5 ~7 stonebrick 1  
fill ~48 ~5 ~57 ~49 ~5 ~57 stonebrick 1  
fill ~49 ~5 ~8 ~50 ~5 ~8 stonebrick 1  
fill ~49 ~5 ~56 ~50 ~5 ~56 stonebrick 1 
setblock ~50 ~5 ~9 obsidian 0 
setblock ~50 ~5 ~55 obsidian 0  
fill ~51 ~5 ~9 ~51 ~11 ~9 stonebrick 1  
fill ~51 ~5 ~55 ~51 ~11 ~55 stonebrick 1 
setblock ~55 ~5 ~14 obsidian 0 
setblock ~55 ~5 ~50 obsidian 0  
fill ~56 ~5 ~14 ~56 ~9 ~14 stonebrick 1  
fill ~56 ~5 ~15 ~57 ~5 ~15 stonebrick 1  
fill ~56 ~5 ~16 ~56 ~5 ~17 obsidian 0  
fill ~56 ~5 ~47 ~57 ~5 ~47 obsidian 0  
fill ~56 ~5 ~48 ~56 ~5 ~47 obsidian 0  
fill ~56 ~5 ~49 ~57 ~5 ~49 stonebrick 1  
fill ~56 ~5 ~50 ~56 ~9 ~50 stonebrick 1  
fill ~57 ~5 ~16 ~57 ~13 ~16 stonebrick 1  
fill ~57 ~5 ~17 ~57 ~5 ~18 obsidian 0 
setblock ~57 ~5 ~46 obsidian 0  
fill ~57 ~5 ~48 ~57 ~13 ~48 stonebrick 1  
fill ~58 ~5 ~17 ~58 ~9 ~17 stonebrick 1  
fill ~58 ~5 ~18 ~58 ~6 ~18 stonebrick 1  
fill ~58 ~5 ~19 ~59 ~5 ~19 stonebrick 1  
fill ~58 ~5 ~20 ~58 ~5 ~21 obsidian 0  
fill ~58 ~5 ~43 ~59 ~5 ~43 obsidian 0  
fill ~58 ~5 ~44 ~58 ~5 ~43 obsidian 0  
fill ~58 ~5 ~45 ~59 ~5 ~45 stonebrick 1  
fill ~58 ~5 ~46 ~58 ~6 ~46 stonebrick 1  
fill ~58 ~5 ~47 ~58 ~9 ~47 stonebrick 1  
fill ~59 ~5 ~20 ~59 ~7 ~20 stonebrick 1 
setblock ~59 ~5 ~21 obsidian 0  
fill ~59 ~5 ~22 ~60 ~5 ~22 stonebrick 1  
fill ~59 ~5 ~42 ~60 ~5 ~42 stonebrick 1  
fill ~59 ~5 ~44 ~59 ~7 ~44 stonebrick 1  
fill ~60 ~5 ~21 ~60 ~9 ~21 stonebrick 1  
fill ~60 ~5 ~24 ~61 ~5 ~24 stonebrick 1  
fill ~60 ~5 ~25 ~60 ~5 ~39 obsidian 0  
fill ~60 ~5 ~40 ~61 ~5 ~40 stonebrick 1  
fill ~60 ~5 ~43 ~60 ~9 ~43 stonebrick 1  
fill ~61 ~5 ~25 ~61 ~11 ~25 stonebrick 1  
fill ~61 ~5 ~26 ~61 ~13 ~26 stonebrick 1  
fill ~61 ~5 ~27 ~61 ~9 ~27 stonebrick 1  
fill ~61 ~5 ~28 ~62 ~5 ~28 stonebrick 1  
fill ~61 ~5 ~29 ~62 ~5 ~29 stonebrick 1  
fill ~61 ~5 ~30 ~62 ~5 ~30 stonebrick 1  
fill ~61 ~5 ~31 ~62 ~5 ~31 stonebrick 1  
fill ~61 ~5 ~32 ~62 ~5 ~32 stonebrick 1  
fill ~61 ~5 ~33 ~62 ~5 ~33 stonebrick 1  
fill ~61 ~5 ~34 ~62 ~5 ~34 stonebrick 1  
fill ~61 ~5 ~35 ~62 ~5 ~35 stonebrick 1  
fill ~61 ~5 ~36 ~62 ~5 ~36 stonebrick 1  
fill ~61 ~5 ~37 ~61 ~9 ~37 stonebrick 1  
fill ~61 ~5 ~38 ~61 ~13 ~38 stonebrick 1  
fill ~61 ~5 ~39 ~61 ~11 ~39 stonebrick 1 
setblock ~2 ~6 ~28 obsidian 0  
fill ~2 ~6 ~29 ~3 ~6 ~29 stonebrick 1  
fill ~2 ~6 ~30 ~3 ~6 ~30 stonebrick 1  
fill ~2 ~6 ~31 ~3 ~6 ~31 stonebrick 1  
fill ~2 ~6 ~32 ~3 ~6 ~32 stonebrick 1  
fill ~2 ~6 ~33 ~3 ~6 ~33 stonebrick 1   
fill ~2 ~6 ~34 ~3 ~6 ~34 stonebrick 1  
fill ~2 ~6 ~35 ~3 ~6 ~35 stonebrick 1 
setblock ~2 ~6 ~36 obsidian 0  
fill ~3 ~6 ~24 ~4 ~6 ~24 stonebrick 1  
fill ~3 ~6 ~28 ~3 ~7 ~28 stonebrick 1  
fill ~3 ~6 ~36 ~3 ~7 ~36 stonebrick 1  
fill ~3 ~6 ~40 ~4 ~6 ~40 stonebrick 1  
fill ~4 ~6 ~22 ~5 ~6 ~22 stonebrick 1  
fill ~4 ~6 ~42 ~5 ~6 ~42 stonebrick 1  
fill ~5 ~6 ~19 ~6 ~6 ~19 stonebrick 1  
fill ~5 ~6 ~45 ~6 ~6 ~45 stonebrick 1  
fill ~7 ~6 ~15 ~7 ~7 ~15 stonebrick 1  
fill ~7 ~6 ~49 ~7 ~7 ~49 stonebrick 1 
setblock ~8 ~6 ~15 obsidian 0 
setblock ~8 ~6 ~49 obsidian 0 
setblock ~10 ~6 ~11 obsidian 0 
setblock ~10 ~6 ~19 stonebrick 3 
setblock ~10 ~6 ~45 stonebrick 3 
setblock ~11 ~6 ~10 obsidian 0  
fill ~11 ~6 ~11 ~11 ~8 ~11 stonebrick 1 
setblock ~11 ~6 ~18 stonebrick 1 
setblock ~11 ~6 ~19 planks 1 
setblock ~11 ~6 ~20 stonebrick 1 
setblock ~11 ~6 ~44 stonebrick 1 
setblock ~11 ~6 ~45 planks 1 
setblock ~11 ~6 ~46 stonebrick 1  
fill ~12 ~6 ~10 ~12 ~8 ~10 stonebrick 1  
fill ~14 ~6 ~8 ~14 ~9 ~8 stonebrick 1 
setblock ~14 ~6 ~18 stonebrick 1 
setblock ~14 ~6 ~19 planks 1 
setblock ~14 ~6 ~20 stonebrick 1 
setblock ~14 ~6 ~44 stonebrick 1 
setblock ~14 ~6 ~45 planks 1 
setblock ~14 ~6 ~46 stonebrick 1  
fill ~14 ~6 ~56 ~14 ~9 ~56 stonebrick 1  
fill ~15 ~6 ~7 ~16 ~6 ~7 stonebrick 1 
setblock ~15 ~6 ~8 obsidian 0  
fill ~15 ~6 ~17 ~16 ~6 ~17 stone_slab 0  
fill ~15 ~6 ~18 ~15 ~6 ~17 stone_slab 0 
setblock ~15 ~6 ~19 stonebrick 3 
setblock ~15 ~6 ~45 stonebrick 3  
fill ~15 ~6 ~46 ~15 ~6 ~47 stone_slab 0 
setblock ~15 ~6 ~56 obsidian 0  
fill ~15 ~6 ~57 ~16 ~6 ~57 stonebrick 1  
fill ~16 ~6 ~16 ~17 ~6 ~16 stone_slab 0  
fill ~16 ~6 ~47 ~16 ~6 ~48 stone_slab 0  
fill ~17 ~6 ~6 ~18 ~6 ~6 stonebrick 1  
fill ~17 ~6 ~15 ~18 ~6 ~15 stone_slab 0  
fill ~17 ~6 ~48 ~17 ~6 ~49 stone_slab 0  
fill ~17 ~6 ~58 ~18 ~6 ~58 stonebrick 1 
setblock ~18 ~6 ~11 stonebrick 1 
setblock ~18 ~6 ~14 stonebrick 1 
setblock ~18 ~6 ~49 stone_slab 0 
setblock ~18 ~6 ~50 stonebrick 1 
setblock ~18 ~6 ~53 stonebrick 1  
fill ~19 ~6 ~5 ~20 ~6 ~5 stonebrick 1 
setblock ~19 ~6 ~6 obsidian 0 
setblock ~19 ~6 ~10 stonebrick 3 
setblock ~19 ~6 ~11 planks 1 
setblock ~19 ~6 ~14 planks 1 
setblock ~19 ~6 ~15 stonebrick 3 
setblock ~19 ~6 ~49 stonebrick 3 
setblock ~19 ~6 ~50 planks 1 
setblock ~19 ~6 ~53 planks 1 
setblock ~19 ~6 ~54 stonebrick 3 
setblock ~19 ~6 ~58 obsidian 0  
fill ~19 ~6 ~59 ~20 ~6 ~59 stonebrick 1 
setblock ~20 ~6 ~11 stonebrick 1 
setblock ~20 ~6 ~14 stonebrick 1 
setblock ~20 ~6 ~50 stonebrick 1 
setblock ~20 ~6 ~53 stonebrick 1  
fill ~21 ~6 ~4 ~24 ~6 ~4 stonebrick 1  
fill ~21 ~6 ~60 ~24 ~6 ~60 stonebrick 1  
fill ~24 ~6 ~3 ~29 ~6 ~3 stonebrick 1  
fill ~24 ~6 ~61 ~26 ~6 ~61 stonebrick 1 
setblock ~28 ~6 ~2 obsidian 0  
fill ~29 ~6 ~2 ~35 ~6 ~2 stonebrick 1  
fill ~30 ~6 ~3 ~34 ~6 ~3 obsidian 0  
fill ~35 ~6 ~3 ~40 ~6 ~3 stonebrick 1 
setblock ~36 ~6 ~2 obsidian 0  
fill ~38 ~6 ~61 ~40 ~6 ~61 stonebrick 1  
fill ~40 ~6 ~4 ~43 ~6 ~4 stonebrick 1  
fill ~40 ~6 ~60 ~43 ~6 ~60 stonebrick 1  
fill ~44 ~6 ~5 ~45 ~6 ~5 stonebrick 1 
setblock ~44 ~6 ~11 stonebrick 1 
setblock ~44 ~6 ~14 stonebrick 1 
setblock ~44 ~6 ~50 stonebrick 1 
setblock ~44 ~6 ~53 stonebrick 1  
fill ~44 ~6 ~59 ~45 ~6 ~59 stonebrick 1  
fill ~45 ~6 ~6 ~47 ~6 ~6 stonebrick 1 
setblock ~45 ~6 ~10 stonebrick 3 
setblock ~45 ~6 ~11 planks 1 
setblock ~45 ~6 ~14 planks 1 
setblock ~45 ~6 ~15 stonebrick 3 
setblock ~45 ~6 ~49 stonebrick 3 
setblock ~45 ~6 ~50 planks 1 
setblock ~45 ~6 ~53 planks 1 
setblock ~45 ~6 ~54 stonebrick 3 
setblock ~45 ~6 ~58 obsidian 0 
setblock ~46 ~6 ~11 stonebrick 1 
setblock ~46 ~6 ~14 stonebrick 1  
fill ~46 ~6 ~15 ~47 ~6 ~15 stone_slab 0  
fill ~46 ~6 ~49 ~47 ~6 ~49 stone_slab 0 
setblock ~46 ~6 ~50 stonebrick 1 
setblock ~46 ~6 ~53 stonebrick 1  
fill ~46 ~6 ~58 ~47 ~6 ~58 stonebrick 1  
fill ~47 ~6 ~16 ~48 ~6 ~16 stone_slab 0  
fill ~47 ~6 ~48 ~48 ~6 ~48 stone_slab 0  
fill ~48 ~6 ~7 ~49 ~6 ~7 stonebrick 1  
fill ~48 ~6 ~17 ~49 ~6 ~17 stone_slab 0  
fill ~48 ~6 ~47 ~49 ~6 ~47 stone_slab 0  
fill ~48 ~6 ~57 ~49 ~6 ~57 stonebrick 1 
setblock ~49 ~6 ~8 obsidian 0 
setblock ~49 ~6 ~18 stone_slab 0 
setblock ~49 ~6 ~19 stonebrick 3 
setblock ~49 ~6 ~45 stonebrick 3 
setblock ~49 ~6 ~46 stone_slab 0  
fill ~49 ~6 ~56 ~50 ~6 ~56 stonebrick 1  
fill ~50 ~6 ~8 ~50 ~9 ~8 stonebrick 1 
setblock ~50 ~6 ~18 stonebrick 1 
setblock ~50 ~6 ~19 planks 1 
setblock ~50 ~6 ~20 stonebrick 1 
setblock ~50 ~6 ~44 stonebrick 1 
setblock ~50 ~6 ~45 planks 1 
setblock ~50 ~6 ~46 stonebrick 1 
setblock ~53 ~6 ~18 stonebrick 1 
setblock ~53 ~6 ~19 planks 1 
setblock ~53 ~6 ~20 stonebrick 1 
setblock ~53 ~6 ~44 stonebrick 1 
setblock ~53 ~6 ~45 planks 1 
