setblock ~4 ~4 ~37 chest 5  
setblock ~4 ~5 ~46 chest 5  
setblock ~77 ~10 ~74 chest 2  
setblock ~77 ~11 ~75 chest 3  
setblock ~78 ~10 ~75 chest 5  
setblock ~78 ~9 ~75 chest 5  
fill ~2 ~0 ~26 ~13 ~0 ~26 bedrock 0  
fill ~2 ~0 ~27 ~54 ~0 ~27 bedrock 0  
fill ~2 ~0 ~28 ~53 ~0 ~28 bedrock 0  
fill ~2 ~0 ~29 ~53 ~0 ~29 bedrock 0  
fill ~2 ~0 ~30 ~53 ~0 ~30 bedrock 0  
fill ~2 ~0 ~31 ~53 ~0 ~31 bedrock 0  
fill ~2 ~0 ~32 ~52 ~0 ~32 bedrock 0  
fill ~2 ~0 ~33 ~52 ~0 ~33 bedrock 0  
fill ~2 ~0 ~34 ~53 ~0 ~34 bedrock 0  
fill ~2 ~0 ~35 ~52 ~0 ~35 bedrock 0  
fill ~2 ~0 ~36 ~52 ~0 ~36 bedrock 0  
fill ~2 ~0 ~37 ~52 ~0 ~37 bedrock 0  
fill ~2 ~0 ~38 ~53 ~0 ~38 bedrock 0  
fill ~2 ~0 ~39 ~53 ~0 ~39 bedrock 0  
fill ~2 ~0 ~40 ~53 ~0 ~40 bedrock 0  
fill ~2 ~0 ~41 ~139 ~0 ~41 bedrock 0  
fill ~2 ~0 ~42 ~139 ~0 ~42 bedrock 0  
fill ~2 ~0 ~43 ~140 ~0 ~43 bedrock 0  
fill ~2 ~0 ~44 ~142 ~0 ~44 bedrock 0  
fill ~2 ~0 ~45 ~142 ~0 ~45 bedrock 0  
fill ~2 ~0 ~46 ~142 ~0 ~46 bedrock 0  
fill ~2 ~0 ~47 ~142 ~0 ~47 bedrock 0  
fill ~3 ~0 ~48 ~143 ~0 ~48 bedrock 0  
fill ~9 ~0 ~23 ~13 ~0 ~23 bedrock 0  
fill ~9 ~0 ~24 ~13 ~0 ~24 bedrock 0  
fill ~9 ~0 ~25 ~13 ~0 ~25 bedrock 0  
fill ~11 ~0 ~21 ~13 ~0 ~21 bedrock 0  
fill ~11 ~0 ~22 ~13 ~0 ~22 bedrock 0  
fill ~12 ~0 ~20 ~13 ~0 ~20 bedrock 0  
fill ~13 ~0 ~19 ~14 ~0 ~19 bedrock 0  
fill ~14 ~0 ~17 ~52 ~0 ~17 bedrock 0  
fill ~14 ~0 ~18 ~54 ~0 ~18 bedrock 0  
fill ~14 ~0 ~20 ~17 ~0 ~20 dirt 0  
fill ~14 ~0 ~21 ~17 ~0 ~21 dirt 0  
fill ~14 ~0 ~22 ~17 ~0 ~22 dirt 0  
fill ~14 ~0 ~23 ~17 ~0 ~23 dirt 0  
fill ~14 ~0 ~24 ~17 ~0 ~24 dirt 0  
fill ~14 ~0 ~25 ~17 ~0 ~25 dirt 0  
fill ~14 ~0 ~26 ~17 ~0 ~26 dirt 0  
fill ~14 ~0 ~103 ~42 ~0 ~103 bedrock 0  
fill ~14 ~0 ~104 ~42 ~0 ~104 bedrock 0  
fill ~14 ~0 ~105 ~42 ~0 ~105 bedrock 0  
fill ~14 ~0 ~106 ~42 ~0 ~106 bedrock 0  
fill ~14 ~0 ~107 ~42 ~0 ~107 bedrock 0  
fill ~14 ~0 ~108 ~41 ~0 ~108 bedrock 0  
fill ~14 ~0 ~109 ~40 ~0 ~109 bedrock 0  
fill ~14 ~0 ~110 ~40 ~0 ~110 bedrock 0  
fill ~14 ~0 ~111 ~41 ~0 ~111 bedrock 0  
fill ~14 ~0 ~112 ~41 ~0 ~112 bedrock 0  
fill ~14 ~0 ~113 ~41 ~0 ~113 bedrock 0  
fill ~14 ~0 ~114 ~74 ~0 ~114 bedrock 0  
fill ~14 ~0 ~115 ~75 ~0 ~115 bedrock 0  
fill ~14 ~0 ~116 ~76 ~0 ~116 bedrock 0  
fill ~15 ~0 ~16 ~52 ~0 ~16 bedrock 0  
fill ~15 ~0 ~19 ~15 ~1 ~19 dirt 0  
fill ~15 ~0 ~50 ~143 ~0 ~50 bedrock 0  
fill ~15 ~0 ~51 ~144 ~0 ~51 bedrock 0  
fill ~15 ~0 ~52 ~145 ~0 ~52 bedrock 0  
fill ~15 ~0 ~53 ~149 ~0 ~53 bedrock 0  
fill ~15 ~0 ~54 ~150 ~0 ~54 bedrock 0  
fill ~15 ~0 ~117 ~76 ~0 ~117 bedrock 0  
fill ~16 ~0 ~19 ~55 ~0 ~19 bedrock 0  
fill ~16 ~0 ~49 ~143 ~0 ~49 bedrock 0  
fill ~16 ~0 ~55 ~153 ~0 ~55 bedrock 0  
fill ~16 ~0 ~56 ~154 ~0 ~56 bedrock 0  
fill ~16 ~0 ~57 ~20 ~0 ~57 bedrock 0  
fill ~16 ~0 ~102 ~42 ~0 ~102 bedrock 0  
fill ~16 ~0 ~118 ~77 ~0 ~118 bedrock 0  
fill ~17 ~0 ~15 ~53 ~0 ~15 bedrock 0  
fill ~17 ~0 ~101 ~42 ~0 ~101 bedrock 0  
fill ~17 ~0 ~119 ~78 ~0 ~119 bedrock 0  
fill ~18 ~0 ~20 ~56 ~0 ~20 bedrock 0  
fill ~18 ~0 ~21 ~57 ~0 ~21 bedrock 0  
fill ~18 ~0 ~22 ~57 ~0 ~22 bedrock 0  
fill ~18 ~0 ~23 ~57 ~0 ~23 bedrock 0  
fill ~18 ~0 ~24 ~56 ~0 ~24 bedrock 0  
fill ~18 ~0 ~25 ~55 ~0 ~25 bedrock 0  
fill ~18 ~0 ~26 ~54 ~0 ~26 bedrock 0  
fill ~18 ~0 ~100 ~42 ~0 ~100 bedrock 0  
fill ~18 ~0 ~120 ~78 ~0 ~120 bedrock 0  
fill ~19 ~0 ~14 ~53 ~0 ~14 bedrock 0  
fill ~19 ~0 ~121 ~77 ~0 ~121 bedrock 0  
fill ~20 ~0 ~66 ~149 ~0 ~66 bedrock 0  
fill ~20 ~0 ~77 ~145 ~0 ~77 bedrock 0  
fill ~20 ~0 ~78 ~145 ~0 ~78 bedrock 0  
fill ~20 ~0 ~79 ~146 ~0 ~79 bedrock 0  
fill ~20 ~0 ~98 ~41 ~0 ~98 bedrock 0  
fill ~20 ~0 ~122 ~29 ~0 ~122 bedrock 0  
fill ~21 ~0 ~13 ~53 ~0 ~13 bedrock 0  
fill ~21 ~0 ~64 ~151 ~0 ~64 bedrock 0  
fill ~21 ~0 ~65 ~150 ~0 ~65 bedrock 0  
fill ~21 ~0 ~67 ~149 ~0 ~67 bedrock 0  
fill ~21 ~0 ~76 ~145 ~0 ~76 bedrock 0  
fill ~21 ~0 ~80 ~147 ~0 ~80 bedrock 0  
fill ~21 ~0 ~97 ~41 ~0 ~97 bedrock 0  
fill ~21 ~0 ~99 ~42 ~0 ~99 bedrock 0  
fill ~21 ~0 ~123 ~27 ~0 ~123 bedrock 0  
fill ~21 ~0 ~124 ~27 ~0 ~124 bedrock 0  
fill ~22 ~0 ~57 ~154 ~0 ~57 bedrock 0  
fill ~22 ~0 ~63 ~152 ~0 ~63 bedrock 0  
fill ~22 ~0 ~68 ~148 ~0 ~68 bedrock 0  
fill ~22 ~0 ~75 ~145 ~0 ~75 bedrock 0  
fill ~22 ~0 ~81 ~148 ~0 ~81 bedrock 0  
fill ~22 ~0 ~96 ~40 ~0 ~96 bedrock 0  
fill ~23 ~0 ~58 ~154 ~0 ~58 bedrock 0  
fill ~23 ~0 ~60 ~123 ~0 ~60 bedrock 0  
fill ~23 ~0 ~61 ~154 ~0 ~61 bedrock 0  
fill ~23 ~0 ~62 ~153 ~0 ~62 bedrock 0  
fill ~23 ~0 ~69 ~147 ~0 ~69 bedrock 0  
fill ~23 ~0 ~72 ~146 ~0 ~72 bedrock 0  
fill ~23 ~0 ~74 ~145 ~0 ~74 bedrock 0  
fill ~23 ~0 ~82 ~149 ~0 ~82 bedrock 0  
fill ~23 ~0 ~93 ~40 ~0 ~93 bedrock 0  
fill ~23 ~0 ~95 ~40 ~0 ~95 bedrock 0  
fill ~23 ~0 ~125 ~25 ~0 ~125 bedrock 0  
fill ~24 ~0 ~12 ~53 ~0 ~12 bedrock 0  
fill ~24 ~0 ~59 ~154 ~0 ~59 bedrock 0  
fill ~24 ~0 ~70 ~146 ~0 ~70 bedrock 0  
fill ~24 ~0 ~71 ~146 ~0 ~71 bedrock 0  
fill ~24 ~0 ~73 ~145 ~0 ~73 bedrock 0  
fill ~24 ~0 ~83 ~149 ~0 ~83 bedrock 0  
fill ~24 ~0 ~92 ~80 ~0 ~92 bedrock 0  
fill ~24 ~0 ~94 ~40 ~0 ~94 bedrock 0  
fill ~25 ~0 ~84 ~149 ~0 ~84 bedrock 0  
fill ~25 ~0 ~91 ~79 ~0 ~91 bedrock 0  
fill ~26 ~0 ~85 ~148 ~0 ~85 bedrock 0  
fill ~26 ~0 ~90 ~78 ~0 ~90 bedrock 0  
fill ~27 ~0 ~86 ~147 ~0 ~86 bedrock 0  
fill ~27 ~0 ~87 ~73 ~0 ~87 bedrock 0  
fill ~27 ~0 ~88 ~79 ~0 ~88 bedrock 0  
fill ~27 ~0 ~89 ~79 ~0 ~89 bedrock 0  
fill ~29 ~0 ~138 ~64 ~0 ~138 bedrock 0  
fill ~29 ~0 ~139 ~62 ~0 ~139 bedrock 0  
fill ~29 ~0 ~140 ~61 ~0 ~140 bedrock 0  
fill ~29 ~0 ~141 ~50 ~0 ~141 bedrock 0  
fill ~30 ~0 ~134 ~64 ~0 ~134 bedrock 0  
fill ~30 ~0 ~135 ~65 ~0 ~135 bedrock 0  
fill ~30 ~0 ~136 ~66 ~0 ~136 bedrock 0  
fill ~30 ~0 ~137 ~65 ~0 ~137 bedrock 0  
fill ~30 ~0 ~142 ~49 ~0 ~142 bedrock 0  
fill ~31 ~0 ~133 ~63 ~0 ~133 bedrock 0  
fill ~31 ~0 ~143 ~48 ~0 ~143 bedrock 0  
fill ~31 ~0 ~144 ~47 ~0 ~144 bedrock 0  
fill ~32 ~0 ~132 ~62 ~0 ~132 bedrock 0  
fill ~32 ~0 ~145 ~46 ~0 ~145 bedrock 0  
fill ~33 ~0 ~122 ~76 ~0 ~122 bedrock 0  
fill ~33 ~0 ~146 ~45 ~0 ~146 bedrock 0  
fill ~34 ~0 ~131 ~63 ~0 ~131 bedrock 0  
fill ~35 ~0 ~123 ~75 ~0 ~123 bedrock 0  
fill ~35 ~0 ~130 ~66 ~0 ~130 bedrock 0  
fill ~35 ~0 ~147 ~39 ~0 ~147 bedrock 0  
fill ~36 ~0 ~124 ~74 ~0 ~124 bedrock 0  
fill ~36 ~0 ~125 ~70 ~0 ~125 bedrock 0  
fill ~36 ~0 ~129 ~67 ~0 ~129 bedrock 0  
fill ~37 ~0 ~126 ~69 ~0 ~126 bedrock 0  
fill ~37 ~0 ~128 ~68 ~0 ~128 bedrock 0  
fill ~38 ~0 ~127 ~69 ~0 ~127 bedrock 0  
fill ~41 ~0 ~93 ~43 ~0 ~93 dirt 0  
fill ~41 ~0 ~94 ~43 ~0 ~94 dirt 0  
fill ~41 ~0 ~95 ~43 ~0 ~95 dirt 0  
fill ~41 ~0 ~96 ~43 ~0 ~96 dirt 0  
fill ~41 ~0 ~109 ~44 ~0 ~109 dirt 0  
fill ~41 ~0 ~110 ~43 ~0 ~110 dirt 0  
fill ~42 ~0 ~97 ~43 ~0 ~97 dirt 0  
fill ~42 ~0 ~98 ~44 ~0 ~98 dirt 0  
fill ~42 ~0 ~108 ~45 ~0 ~108 dirt 0  
fill ~42 ~0 ~111 ~43 ~0 ~111 dirt 0  
fill ~42 ~0 ~112 ~44 ~0 ~112 dirt 0  
fill ~42 ~0 ~113 ~44 ~0 ~113 dirt 0  
fill ~42 ~0 ~147 ~44 ~0 ~147 bedrock 0  
fill ~43 ~0 ~99 ~44 ~0 ~99 dirt 0  
fill ~43 ~0 ~100 ~44 ~0 ~100 dirt 0  
fill ~43 ~0 ~101 ~44 ~0 ~101 dirt 0  
fill ~43 ~0 ~102 ~45 ~0 ~102 dirt 0  
fill ~43 ~0 ~103 ~45 ~0 ~103 dirt 0  
fill ~43 ~0 ~104 ~45 ~0 ~104 dirt 0  
fill ~43 ~0 ~105 ~45 ~0 ~105 dirt 0  
fill ~43 ~0 ~106 ~45 ~0 ~106 dirt 0  
fill ~43 ~0 ~107 ~45 ~0 ~107 dirt 0 
setblock ~43 ~0 ~148 bedrock 0  
fill ~44 ~0 ~93 ~81 ~0 ~93 bedrock 0  
fill ~44 ~0 ~94 ~48 ~0 ~94 bedrock 0  
fill ~44 ~0 ~95 ~48 ~0 ~95 bedrock 0  
fill ~44 ~0 ~96 ~48 ~0 ~96 bedrock 0  
fill ~44 ~0 ~97 ~48 ~0 ~97 bedrock 0  
fill ~44 ~0 ~110 ~47 ~0 ~110 bedrock 0  
fill ~44 ~0 ~111 ~47 ~0 ~111 bedrock 0  
fill ~45 ~0 ~98 ~48 ~0 ~98 bedrock 0  
fill ~45 ~0 ~99 ~48 ~0 ~99 bedrock 0  
fill ~45 ~0 ~100 ~47 ~0 ~100 bedrock 0  
fill ~45 ~0 ~101 ~47 ~0 ~101 bedrock 0  
fill ~45 ~0 ~109 ~48 ~0 ~109 bedrock 0  
fill ~45 ~0 ~112 ~47 ~0 ~112 bedrock 0  
fill ~45 ~0 ~113 ~48 ~0 ~113 bedrock 0  
fill ~46 ~0 ~10 ~52 ~0 ~10 bedrock 0  
fill ~46 ~0 ~11 ~53 ~0 ~11 bedrock 0  
fill ~46 ~0 ~102 ~47 ~0 ~102 bedrock 0  
fill ~46 ~0 ~103 ~46 ~0 ~145 bedrock 0  
fill ~47 ~0 ~103 ~52 ~0 ~103 dirt 0  
fill ~47 ~0 ~104 ~48 ~0 ~104 bedrock 0  
fill ~47 ~0 ~105 ~48 ~0 ~105 bedrock 0  
fill ~47 ~0 ~106 ~48 ~0 ~106 bedrock 0  
fill ~47 ~0 ~107 ~48 ~0 ~107 bedrock 0  
fill ~47 ~0 ~108 ~48 ~0 ~108 bedrock 0  
fill ~48 ~0 ~100 ~52 ~0 ~100 dirt 0  
fill ~48 ~0 ~101 ~52 ~0 ~101 dirt 0  
fill ~48 ~0 ~102 ~52 ~0 ~102 dirt 0  
fill ~48 ~0 ~110 ~48 ~0 ~112 mycelium 0  
fill ~49 ~0 ~94 ~53 ~0 ~94 dirt 0  
fill ~49 ~0 ~95 ~52 ~0 ~95 dirt 0  
fill ~49 ~0 ~96 ~52 ~0 ~96 dirt 0  
fill ~49 ~0 ~97 ~52 ~0 ~97 dirt 0  
fill ~49 ~0 ~98 ~52 ~0 ~98 dirt 0  
fill ~49 ~0 ~99 ~52 ~0 ~99 dirt 0  
fill ~49 ~0 ~104 ~52 ~0 ~104 dirt 0  
fill ~49 ~0 ~105 ~52 ~0 ~105 dirt 0  
fill ~49 ~0 ~106 ~52 ~0 ~106 dirt 0  
fill ~49 ~0 ~107 ~52 ~0 ~107 dirt 0  
fill ~49 ~0 ~108 ~52 ~0 ~108 dirt 0  
fill ~49 ~0 ~109 ~51 ~0 ~109 dirt 0  
fill ~49 ~0 ~110 ~49 ~0 ~94 dirt 0 
setblock ~49 ~0 ~111 mycelium 0  
fill ~49 ~0 ~112 ~52 ~0 ~112 dirt 0  
fill ~49 ~0 ~113 ~52 ~0 ~113 dirt 0 
setblock ~50 ~0 ~110 mycelium 0  
fill ~50 ~0 ~111 ~52 ~0 ~111 dirt 0 
setblock ~51 ~0 ~110 dirt 0  
fill ~52 ~0 ~109 ~52 ~0 ~110 mycelium 0  
fill ~53 ~0 ~95 ~84 ~0 ~95 bedrock 0  
fill ~53 ~0 ~96 ~85 ~0 ~96 bedrock 0  
fill ~53 ~0 ~97 ~86 ~0 ~97 bedrock 0  
fill ~53 ~0 ~98 ~86 ~0 ~98 bedrock 0  
fill ~53 ~0 ~99 ~87 ~0 ~99 bedrock 0  
fill ~53 ~0 ~100 ~87 ~0 ~100 bedrock 0  
fill ~53 ~0 ~101 ~88 ~0 ~101 bedrock 0  
fill ~53 ~0 ~102 ~93 ~0 ~102 bedrock 0  
fill ~53 ~0 ~103 ~92 ~0 ~103 bedrock 0  
fill ~53 ~0 ~104 ~92 ~0 ~104 bedrock 0  
fill ~53 ~0 ~105 ~89 ~0 ~105 bedrock 0  
fill ~53 ~0 ~106 ~87 ~0 ~106 bedrock 0  
fill ~53 ~0 ~107 ~86 ~0 ~107 bedrock 0  
fill ~53 ~0 ~108 ~83 ~0 ~108 bedrock 0  
fill ~53 ~0 ~109 ~81 ~0 ~109 bedrock 0  
fill ~53 ~0 ~110 ~78 ~0 ~110 bedrock 0  
fill ~53 ~0 ~111 ~76 ~0 ~111 bedrock 0  
fill ~53 ~0 ~112 ~74 ~0 ~112 bedrock 0  
fill ~53 ~0 ~113 ~72 ~0 ~113 bedrock 0  
fill ~54 ~0 ~94 ~82 ~0 ~94 bedrock 0  
fill ~54 ~0 ~141 ~61 ~0 ~141 bedrock 0  
fill ~55 ~0 ~40 ~58 ~0 ~40 bedrock 0  
fill ~55 ~0 ~142 ~60 ~0 ~142 bedrock 0 
setblock ~56 ~0 ~39 bedrock 0  
fill ~56 ~0 ~143 ~59 ~0 ~143 bedrock 0 
setblock ~58 ~0 ~144 bedrock 0  
fill ~65 ~0 ~40 ~138 ~0 ~40 bedrock 0  
fill ~66 ~0 ~35 ~133 ~0 ~35 bedrock 0  
fill ~66 ~0 ~36 ~134 ~0 ~36 bedrock 0  
fill ~66 ~0 ~37 ~135 ~0 ~37 bedrock 0  
fill ~66 ~0 ~38 ~136 ~0 ~38 bedrock 0  
fill ~66 ~0 ~39 ~137 ~0 ~39 bedrock 0  
fill ~67 ~0 ~34 ~133 ~0 ~34 bedrock 0  
fill ~68 ~0 ~33 ~133 ~0 ~33 bedrock 0  
fill ~69 ~0 ~32 ~132 ~0 ~32 bedrock 0  
fill ~70 ~0 ~31 ~128 ~0 ~31 bedrock 0  
fill ~72 ~0 ~30 ~127 ~0 ~30 bedrock 0  
fill ~73 ~0 ~25 ~79 ~0 ~25 bedrock 0  
fill ~73 ~0 ~26 ~123 ~0 ~26 bedrock 0  
fill ~73 ~0 ~27 ~123 ~0 ~27 bedrock 0  
fill ~73 ~0 ~28 ~124 ~0 ~28 bedrock 0  
fill ~73 ~0 ~29 ~125 ~0 ~29 bedrock 0  
fill ~74 ~0 ~10 ~110 ~0 ~10 bedrock 0  
fill ~74 ~0 ~11 ~111 ~0 ~11 bedrock 0  
fill ~74 ~0 ~12 ~111 ~0 ~12 bedrock 0  
fill ~74 ~0 ~13 ~114 ~0 ~13 bedrock 0  
fill ~74 ~0 ~24 ~78 ~0 ~24 bedrock 0  
fill ~75 ~0 ~9 ~109 ~0 ~9 bedrock 0  
fill ~75 ~0 ~14 ~115 ~0 ~14 bedrock 0  
fill ~75 ~0 ~16 ~119 ~0 ~16 bedrock 0  
fill ~75 ~0 ~17 ~120 ~0 ~17 bedrock 0  
fill ~75 ~0 ~18 ~121 ~0 ~18 bedrock 0  
fill ~76 ~0 ~7 ~107 ~0 ~7 bedrock 0  
fill ~76 ~0 ~8 ~108 ~0 ~8 bedrock 0  
fill ~76 ~0 ~15 ~118 ~0 ~15 bedrock 0  
fill ~76 ~0 ~19 ~122 ~0 ~19 bedrock 0  
fill ~76 ~0 ~23 ~77 ~0 ~23 bedrock 0  
fill ~77 ~0 ~4 ~103 ~0 ~4 bedrock 0  
fill ~77 ~0 ~5 ~105 ~0 ~5 bedrock 0  
fill ~77 ~0 ~6 ~106 ~0 ~6 bedrock 0  
fill ~77 ~0 ~20 ~123 ~0 ~20 bedrock 0  
fill ~78 ~0 ~3 ~91 ~0 ~3 bedrock 0  
fill ~78 ~0 ~21 ~123 ~0 ~21 bedrock 0  
fill ~79 ~0 ~22 ~123 ~0 ~22 bedrock 0  
fill ~80 ~0 ~2 ~88 ~0 ~2 bedrock 0  
fill ~80 ~0 ~23 ~123 ~0 ~23 bedrock 0  
fill ~81 ~0 ~1 ~84 ~0 ~1 bedrock 0  
fill ~81 ~0 ~24 ~123 ~0 ~24 bedrock 0  
fill ~81 ~0 ~25 ~123 ~0 ~25 bedrock 0  
fill ~81 ~0 ~87 ~147 ~0 ~87 bedrock 0  
fill ~81 ~0 ~88 ~147 ~0 ~88 bedrock 0  
fill ~81 ~0 ~89 ~147 ~0 ~89 bedrock 0  
fill ~81 ~0 ~90 ~147 ~0 ~90 bedrock 0  
fill ~82 ~0 ~91 ~146 ~0 ~91 bedrock 0  
fill ~83 ~0 ~92 ~146 ~0 ~92 bedrock 0  
fill ~84 ~0 ~93 ~146 ~0 ~93 bedrock 0  
fill ~86 ~0 ~94 ~145 ~0 ~94 bedrock 0  
fill ~87 ~0 ~95 ~145 ~0 ~95 bedrock 0  
fill ~88 ~0 ~96 ~144 ~0 ~96 bedrock 0  
fill ~88 ~0 ~97 ~143 ~0 ~97 bedrock 0  
fill ~89 ~0 ~98 ~101 ~0 ~98 bedrock 0  
fill ~89 ~0 ~99 ~98 ~0 ~99 bedrock 0  
fill ~90 ~0 ~100 ~98 ~0 ~100 bedrock 0  
fill ~93 ~0 ~3 ~102 ~0 ~3 bedrock 0 
setblock ~93 ~0 ~101 bedrock 0  
fill ~94 ~0 ~2 ~101 ~0 ~2 bedrock 0  
fill ~95 ~0 ~1 ~100 ~0 ~1 bedrock 0  
fill ~125 ~0 ~60 ~155 ~0 ~60 bedrock 0  
fill ~130 ~0 ~31 ~132 ~0 ~31 bedrock 0 
setblock ~131 ~0 ~30 bedrock 0  
fill ~2 ~1 ~26 ~13 ~1 ~26 dirt 0  
fill ~2 ~1 ~27 ~54 ~1 ~27 dirt 0  
fill ~2 ~1 ~28 ~53 ~1 ~28 dirt 0  
fill ~2 ~1 ~29 ~53 ~1 ~29 dirt 0  
fill ~2 ~1 ~30 ~53 ~1 ~30 dirt 0  
fill ~2 ~1 ~31 ~53 ~1 ~31 dirt 0  
fill ~2 ~1 ~32 ~52 ~1 ~32 dirt 0  
fill ~2 ~1 ~33 ~52 ~1 ~33 dirt 0  
fill ~2 ~1 ~34 ~53 ~1 ~34 dirt 0  
fill ~2 ~1 ~35 ~52 ~1 ~35 dirt 0  
fill ~2 ~1 ~36 ~52 ~1 ~36 dirt 0  
fill ~2 ~1 ~37 ~27 ~1 ~37 dirt 0  
fill ~2 ~1 ~38 ~29 ~1 ~38 dirt 0  
fill ~2 ~1 ~39 ~53 ~1 ~39 dirt 0  
fill ~2 ~1 ~40 ~53 ~1 ~40 dirt 0  
fill ~2 ~1 ~41 ~128 ~1 ~41 dirt 0  
fill ~2 ~1 ~42 ~65 ~1 ~42 dirt 0  
fill ~2 ~1 ~43 ~65 ~1 ~43 dirt 0  
fill ~2 ~1 ~44 ~142 ~1 ~44 dirt 0  
fill ~2 ~1 ~45 ~26 ~1 ~45 dirt 0  
fill ~2 ~1 ~46 ~142 ~1 ~46 dirt 0  
fill ~2 ~1 ~47 ~142 ~1 ~47 dirt 0  
fill ~3 ~1 ~48 ~143 ~1 ~48 dirt 0  
fill ~9 ~1 ~23 ~13 ~1 ~23 dirt 0  
fill ~9 ~1 ~24 ~13 ~1 ~24 dirt 0  
fill ~9 ~1 ~25 ~13 ~1 ~25 dirt 0  
fill ~11 ~1 ~21 ~13 ~1 ~21 dirt 0  
fill ~11 ~1 ~22 ~13 ~1 ~22 dirt 0  
fill ~12 ~1 ~20 ~13 ~1 ~20 dirt 0  
fill ~13 ~1 ~19 ~55 ~1 ~19 dirt 0  
fill ~14 ~1 ~17 ~46 ~1 ~17 dirt 0  
fill ~14 ~1 ~18 ~54 ~1 ~18 dirt 0  
fill ~14 ~1 ~103 ~33 ~1 ~103 dirt 0  
fill ~14 ~1 ~104 ~36 ~1 ~104 dirt 0  
fill ~14 ~1 ~105 ~35 ~1 ~105 dirt 0  
fill ~14 ~1 ~106 ~34 ~1 ~106 dirt 0  
fill ~14 ~1 ~107 ~34 ~1 ~107 dirt 0  
fill ~14 ~1 ~108 ~32 ~1 ~108 dirt 0  
fill ~14 ~1 ~109 ~31 ~1 ~109 dirt 0  
fill ~14 ~1 ~110 ~31 ~1 ~110 dirt 0  
fill ~14 ~1 ~111 ~32 ~1 ~111 dirt 0  
fill ~14 ~1 ~112 ~32 ~1 ~112 dirt 0  
fill ~14 ~1 ~113 ~33 ~1 ~113 dirt 0  
fill ~14 ~1 ~114 ~48 ~1 ~114 dirt 0  
fill ~14 ~1 ~115 ~75 ~1 ~115 dirt 0  
fill ~14 ~1 ~116 ~76 ~1 ~116 dirt 0  
fill ~15 ~1 ~16 ~47 ~1 ~16 dirt 0  
fill ~15 ~1 ~117 ~76 ~1 ~117 dirt 0  
fill ~16 ~1 ~20 ~56 ~1 ~20 dirt 0  
fill ~16 ~1 ~21 ~57 ~1 ~21 dirt 0  
fill ~16 ~1 ~22 ~57 ~1 ~22 dirt 0  
fill ~16 ~1 ~23 ~57 ~1 ~23 dirt 0  
fill ~16 ~1 ~51 ~108 ~1 ~51 dirt 0  
fill ~16 ~1 ~52 ~37 ~1 ~52 dirt 0  
fill ~16 ~1 ~53 ~149 ~1 ~53 dirt 0  
fill ~16 ~1 ~54 ~150 ~1 ~54 dirt 0  
fill ~16 ~1 ~55 ~153 ~1 ~55 dirt 0  
fill ~16 ~1 ~56 ~154 ~1 ~56 dirt 0  
fill ~16 ~1 ~57 ~20 ~1 ~57 dirt 0  
fill ~16 ~1 ~102 ~33 ~1 ~102 dirt 0  
fill ~16 ~1 ~118 ~77 ~1 ~118 dirt 0  
fill ~17 ~1 ~15 ~53 ~1 ~15 dirt 0  
fill ~17 ~1 ~24 ~56 ~1 ~24 dirt 0  
fill ~17 ~1 ~25 ~55 ~1 ~25 dirt 0  
fill ~17 ~1 ~26 ~54 ~1 ~26 dirt 0  
fill ~17 ~1 ~101 ~31 ~1 ~101 dirt 0  
fill ~17 ~1 ~119 ~78 ~1 ~119 dirt 0  
fill ~18 ~1 ~49 ~143 ~1 ~49 dirt 0  
fill ~18 ~1 ~50 ~143 ~1 ~50 dirt 0  
fill ~18 ~1 ~100 ~41 ~1 ~100 dirt 0  
fill ~18 ~1 ~120 ~78 ~1 ~120 dirt 0  
fill ~19 ~1 ~14 ~53 ~1 ~14 dirt 0  
fill ~19 ~1 ~121 ~77 ~1 ~121 dirt 0  
fill ~20 ~1 ~66 ~149 ~1 ~66 dirt 0  
fill ~20 ~1 ~77 ~145 ~1 ~77 dirt 0  
fill ~20 ~1 ~78 ~50 ~1 ~78 dirt 0  
fill ~20 ~1 ~79 ~146 ~1 ~79 dirt 0  
fill ~20 ~1 ~98 ~40 ~1 ~98 dirt 0  
fill ~20 ~1 ~122 ~29 ~1 ~122 dirt 0  
fill ~21 ~1 ~13 ~53 ~1 ~13 dirt 0  
fill ~21 ~1 ~64 ~151 ~1 ~64 dirt 0  
fill ~21 ~1 ~65 ~150 ~1 ~65 dirt 0  
fill ~21 ~1 ~67 ~149 ~1 ~67 dirt 0  
fill ~21 ~1 ~76 ~145 ~1 ~76 dirt 0  
fill ~21 ~1 ~80 ~147 ~1 ~80 dirt 0  
fill ~21 ~1 ~97 ~26 ~1 ~97 dirt 0  
fill ~21 ~1 ~99 ~40 ~1 ~99 dirt 0  
fill ~21 ~1 ~123 ~27 ~1 ~123 dirt 0  
fill ~21 ~1 ~124 ~27 ~1 ~124 dirt 0  
fill ~22 ~1 ~57 ~154 ~1 ~57 dirt 0  
fill ~22 ~1 ~63 ~152 ~1 ~63 dirt 0  
fill ~22 ~1 ~68 ~148 ~1 ~68 dirt 0  
fill ~22 ~1 ~75 ~145 ~1 ~75 dirt 0  
fill ~22 ~1 ~81 ~148 ~1 ~81 dirt 0  
fill ~22 ~1 ~96 ~26 ~1 ~96 dirt 0  
fill ~23 ~1 ~58 ~154 ~1 ~58 dirt 0  
fill ~23 ~1 ~60 ~122 ~1 ~60 dirt 0  
fill ~23 ~1 ~61 ~122 ~1 ~61 dirt 0  
fill ~23 ~1 ~62 ~153 ~1 ~62 dirt 0  
fill ~23 ~1 ~69 ~147 ~1 ~69 dirt 0  
fill ~23 ~1 ~72 ~146 ~1 ~72 dirt 0  
fill ~23 ~1 ~74 ~145 ~1 ~74 dirt 0  
fill ~23 ~1 ~82 ~149 ~1 ~82 dirt 0  
fill ~23 ~1 ~93 ~26 ~1 ~93 dirt 0  
fill ~23 ~1 ~95 ~26 ~1 ~95 dirt 0  
fill ~23 ~1 ~125 ~25 ~1 ~125 dirt 0  
fill ~24 ~1 ~12 ~53 ~1 ~12 dirt 0  
fill ~24 ~1 ~59 ~154 ~1 ~59 dirt 0  
fill ~24 ~1 ~70 ~53 ~1 ~70 dirt 0  
fill ~24 ~1 ~71 ~146 ~1 ~71 dirt 0  
fill ~24 ~1 ~73 ~145 ~1 ~73 dirt 0  
fill ~24 ~1 ~83 ~149 ~1 ~83 dirt 0  
fill ~24 ~1 ~92 ~26 ~1 ~92 dirt 0  
fill ~24 ~1 ~94 ~26 ~1 ~94 dirt 0  
fill ~25 ~1 ~84 ~149 ~1 ~84 dirt 0  
fill ~25 ~1 ~91 ~28 ~1 ~91 dirt 0  
fill ~26 ~1 ~85 ~148 ~1 ~85 dirt 0  
fill ~26 ~1 ~90 ~27 ~1 ~90 dirt 0  
fill ~27 ~1 ~45 ~27 ~2 ~45 planks 1  
fill ~27 ~1 ~86 ~147 ~1 ~86 dirt 0  
fill ~27 ~1 ~87 ~41 ~1 ~87 dirt 0  
fill ~27 ~1 ~88 ~27 ~1 ~91 dirt 0  
fill ~27 ~1 ~92 ~31 ~1 ~92 grass 0  
fill ~27 ~1 ~93 ~30 ~1 ~93 grass 0  
fill ~27 ~1 ~94 ~30 ~1 ~94 grass 0  
fill ~27 ~1 ~95 ~29 ~1 ~95 grass 0  
fill ~27 ~1 ~96 ~29 ~1 ~96 grass 0  
fill ~27 ~1 ~97 ~27 ~1 ~92 grass 0 
setblock ~28 ~1 ~37 grass 0  
fill ~28 ~1 ~45 ~142 ~1 ~45 dirt 0  
fill ~28 ~1 ~88 ~28 ~1 ~90 grass 0  
fill ~28 ~1 ~97 ~39 ~1 ~97 dirt 0  
fill ~29 ~1 ~37 ~52 ~1 ~37 dirt 0  
fill ~29 ~1 ~88 ~29 ~1 ~90 dirt 0  
fill ~29 ~1 ~91 ~32 ~1 ~91 grass 0  
fill ~29 ~1 ~138 ~64 ~1 ~138 dirt 0  
fill ~29 ~1 ~139 ~62 ~1 ~139 dirt 0  
fill ~29 ~1 ~140 ~61 ~1 ~140 dirt 0  
fill ~29 ~1 ~141 ~50 ~1 ~141 dirt 0 
setblock ~30 ~1 ~38 grass 0  
fill ~30 ~1 ~88 ~34 ~1 ~88 grass 0  
fill ~30 ~1 ~89 ~33 ~1 ~89 grass 0  
fill ~30 ~1 ~90 ~33 ~1 ~90 grass 0  
fill ~30 ~1 ~95 ~39 ~1 ~95 dirt 0  
fill ~30 ~1 ~96 ~39 ~1 ~96 dirt 0  
fill ~30 ~1 ~134 ~64 ~1 ~134 dirt 0  
fill ~30 ~1 ~135 ~65 ~1 ~135 dirt 0  
fill ~30 ~1 ~136 ~66 ~1 ~136 dirt 0  
fill ~30 ~1 ~137 ~65 ~1 ~137 dirt 0  
fill ~30 ~1 ~142 ~49 ~1 ~142 dirt 0  
fill ~31 ~1 ~38 ~53 ~1 ~38 dirt 0  
fill ~31 ~1 ~93 ~39 ~1 ~93 dirt 0  
fill ~31 ~1 ~94 ~39 ~1 ~94 dirt 0  
fill ~31 ~1 ~133 ~63 ~1 ~133 dirt 0  
fill ~31 ~1 ~143 ~48 ~1 ~143 dirt 0  
fill ~31 ~1 ~144 ~47 ~1 ~144 dirt 0  
fill ~32 ~1 ~92 ~41 ~1 ~92 dirt 0 
setblock ~32 ~1 ~101 grass 0  
fill ~32 ~1 ~109 ~33 ~1 ~109 grass 0  
fill ~32 ~1 ~110 ~35 ~1 ~110 grass 0  
fill ~32 ~1 ~132 ~62 ~1 ~132 dirt 0  
fill ~32 ~1 ~145 ~46 ~1 ~145 dirt 0  
fill ~33 ~1 ~91 ~41 ~1 ~91 dirt 0  
fill ~33 ~1 ~101 ~34 ~1 ~101 dirt 0  
fill ~33 ~1 ~108 ~34 ~1 ~108 grass 0  
fill ~33 ~1 ~111 ~34 ~1 ~111 grass 0  
fill ~33 ~1 ~112 ~33 ~1 ~108 grass 0  
fill ~33 ~1 ~122 ~76 ~1 ~122 dirt 0  
fill ~33 ~1 ~146 ~45 ~1 ~146 dirt 0  
fill ~34 ~1 ~89 ~41 ~1 ~89 dirt 0  
fill ~34 ~1 ~90 ~41 ~1 ~90 dirt 0  
fill ~34 ~1 ~102 ~35 ~1 ~102 grass 0  
fill ~34 ~1 ~103 ~34 ~1 ~102 grass 0  
fill ~34 ~1 ~109 ~38 ~1 ~109 dirt 0  
fill ~34 ~1 ~112 ~35 ~1 ~112 dirt 0  
fill ~34 ~1 ~113 ~39 ~1 ~113 grass 0  
fill ~34 ~1 ~131 ~63 ~1 ~131 dirt 0  
fill ~35 ~1 ~88 ~42 ~1 ~88 dirt 0  
fill ~35 ~1 ~101 ~36 ~1 ~101 grass 0  
fill ~35 ~1 ~103 ~41 ~1 ~103 dirt 0  
fill ~35 ~1 ~106 ~37 ~1 ~106 grass 0  
fill ~35 ~1 ~107 ~40 ~1 ~107 grass 0 
setblock ~35 ~1 ~108 dirt 0 
setblock ~35 ~1 ~111 dirt 0  
fill ~35 ~1 ~123 ~75 ~1 ~123 dirt 0  
fill ~35 ~1 ~130 ~66 ~1 ~130 dirt 0  
fill ~35 ~1 ~147 ~39 ~1 ~147 dirt 0  
fill ~36 ~1 ~102 ~41 ~1 ~102 dirt 0  
fill ~36 ~1 ~105 ~38 ~1 ~105 grass 0 
setblock ~36 ~1 ~108 grass 0  
fill ~36 ~1 ~110 ~37 ~1 ~110 dirt 0  
fill ~36 ~1 ~111 ~38 ~1 ~111 grass 0  
fill ~36 ~1 ~112 ~36 ~1 ~111 grass 0  
fill ~36 ~1 ~124 ~74 ~1 ~124 dirt 0  
fill ~36 ~1 ~125 ~70 ~1 ~125 dirt 0  
fill ~36 ~1 ~129 ~67 ~1 ~129 dirt 0  
fill ~37 ~1 ~101 ~41 ~1 ~101 dirt 0 
setblock ~37 ~1 ~104 grass 0 
setblock ~37 ~1 ~108 dirt 0  
fill ~37 ~1 ~112 ~38 ~1 ~112 dirt 0  
fill ~37 ~1 ~126 ~69 ~1 ~126 dirt 0  
fill ~37 ~1 ~128 ~68 ~1 ~128 dirt 0 
setblock ~38 ~1 ~52 stone 0  
fill ~38 ~1 ~104 ~41 ~1 ~104 dirt 0  
fill ~38 ~1 ~106 ~41 ~1 ~106 dirt 0  
fill ~38 ~1 ~108 ~40 ~1 ~108 grass 0 
setblock ~38 ~1 ~110 grass 0  
fill ~38 ~1 ~127 ~69 ~1 ~127 dirt 0  
fill ~39 ~1 ~52 ~108 ~1 ~52 dirt 0  
fill ~39 ~1 ~105 ~41 ~1 ~105 dirt 0 
setblock ~39 ~1 ~109 grass 0  
fill ~39 ~1 ~110 ~39 ~1 ~111 dirt 0 
setblock ~39 ~1 ~112 grass 0  
fill ~40 ~1 ~93 ~40 ~4 ~93 planks 0  
fill ~40 ~1 ~94 ~40 ~4 ~94 planks 0  
fill ~40 ~1 ~95 ~40 ~4 ~95 planks 0  
fill ~40 ~1 ~96 ~40 ~4 ~96 planks 0  
fill ~40 ~1 ~97 ~41 ~1 ~97 planks 0  
fill ~40 ~1 ~109 ~40 ~4 ~109 planks 0  
fill ~40 ~1 ~110 ~40 ~4 ~110 planks 0  
fill ~40 ~1 ~111 ~40 ~1 ~146 dirt 0  
fill ~41 ~1 ~98 ~41 ~4 ~98 planks 0  
fill ~41 ~1 ~99 ~42 ~1 ~99 planks 0 
setblock ~41 ~1 ~107 dirt 0  
fill ~41 ~1 ~108 ~41 ~4 ~108 planks 0  
fill ~41 ~1 ~111 ~41 ~4 ~111 planks 0  
fill ~41 ~1 ~112 ~41 ~4 ~112 planks 0  
fill ~41 ~1 ~113 ~41 ~4 ~113 planks 0  
fill ~42 ~1 ~87 ~44 ~1 ~87 grass 0 
setblock ~42 ~1 ~89 grass 0  
fill ~42 ~1 ~90 ~49 ~1 ~90 mycelium 0  
fill ~42 ~1 ~91 ~50 ~1 ~91 mycelium 0  
fill ~42 ~1 ~92 ~43 ~1 ~92 mycelium 0  
fill ~42 ~1 ~100 ~42 ~4 ~100 planks 0  
fill ~42 ~1 ~101 ~42 ~4 ~101 planks 0  
fill ~42 ~1 ~102 ~42 ~4 ~102 planks 0  
fill ~42 ~1 ~103 ~42 ~4 ~103 planks 0  
fill ~42 ~1 ~104 ~42 ~4 ~104 planks 0  
fill ~42 ~1 ~105 ~42 ~4 ~105 planks 0  
fill ~42 ~1 ~106 ~42 ~4 ~106 planks 0  
fill ~42 ~1 ~107 ~42 ~4 ~107 planks 0  
fill ~42 ~1 ~113 ~44 ~1 ~113 planks 1  
fill ~42 ~1 ~147 ~44 ~1 ~147 dirt 0 
setblock ~43 ~1 ~88 grass 0  
fill ~43 ~1 ~89 ~47 ~1 ~89 mycelium 0  
fill ~43 ~1 ~148 ~43 ~3 ~148 dirt 0  
fill ~44 ~1 ~88 ~47 ~1 ~88 mycelium 0  
fill ~44 ~1 ~92 ~44 ~3 ~92 planks 0  
fill ~44 ~1 ~93 ~44 ~3 ~93 planks 0  
fill ~44 ~1 ~94 ~44 ~3 ~94 planks 0  
fill ~44 ~1 ~95 ~44 ~3 ~95 planks 0  
fill ~44 ~1 ~96 ~44 ~3 ~96 planks 0  
fill ~44 ~1 ~97 ~45 ~1 ~97 planks 0  
fill ~44 ~1 ~110 ~45 ~1 ~110 planks 0  
fill ~44 ~1 ~111 ~45 ~1 ~111 planks 0  
fill ~45 ~1 ~87 ~47 ~1 ~87 mycelium 0 
setblock ~45 ~1 ~92 mycelium 0 
setblock ~45 ~1 ~93 dirt 0  
fill ~45 ~1 ~94 ~48 ~1 ~94 grass 0  
fill ~45 ~1 ~95 ~45 ~1 ~96 grass 0  
fill ~45 ~1 ~98 ~45 ~3 ~98 planks 0  
fill ~45 ~1 ~99 ~45 ~3 ~99 planks 0  
fill ~45 ~1 ~100 ~45 ~3 ~100 planks 0  
fill ~45 ~1 ~101 ~46 ~1 ~101 planks 0  
fill ~45 ~1 ~109 ~46 ~1 ~109 planks 0  
fill ~45 ~1 ~112 ~45 ~5 ~112 planks 0  
fill ~45 ~1 ~113 ~45 ~1 ~109 planks 0  
fill ~46 ~1 ~10 ~52 ~1 ~10 dirt 0  
fill ~46 ~1 ~11 ~53 ~1 ~11 dirt 0  
fill ~46 ~1 ~92 ~48 ~1 ~92 grass 0  
fill ~46 ~1 ~93 ~53 ~1 ~93 grass 0 
setblock ~46 ~1 ~95 dirt 0  
fill ~46 ~1 ~96 ~48 ~1 ~96 grass 0  
fill ~46 ~1 ~97 ~47 ~1 ~97 grass 0  
fill ~46 ~1 ~98 ~48 ~1 ~98 grass 0 
setblock ~46 ~1 ~99 dirt 0  
fill ~46 ~1 ~100 ~47 ~1 ~100 grass 0  
fill ~46 ~1 ~102 ~46 ~3 ~102 planks 0  
fill ~46 ~1 ~103 ~46 ~3 ~103 planks 0  
fill ~46 ~1 ~104 ~46 ~3 ~104 planks 0  
fill ~46 ~1 ~105 ~46 ~3 ~105 planks 0  
fill ~46 ~1 ~106 ~46 ~3 ~106 planks 0  
fill ~46 ~1 ~107 ~46 ~3 ~107 planks 0  
fill ~46 ~1 ~108 ~46 ~3 ~108 planks 0  
fill ~46 ~1 ~110 ~47 ~1 ~110 grass 0  
fill ~46 ~1 ~111 ~47 ~1 ~111 grass 0  
fill ~46 ~1 ~112 ~47 ~1 ~112 grass 0  
fill ~46 ~1 ~113 ~48 ~1 ~113 grass 0  
fill ~47 ~1 ~95 ~48 ~1 ~95 grass 0  
fill ~47 ~1 ~99 ~48 ~1 ~99 grass 0  
fill ~47 ~1 ~101 ~47 ~1 ~102 grass 0  
fill ~47 ~1 ~104 ~48 ~1 ~104 grass 0  
fill ~47 ~1 ~105 ~48 ~1 ~105 grass 0  
fill ~47 ~1 ~106 ~48 ~1 ~106 grass 0  
fill ~47 ~1 ~107 ~48 ~1 ~107 grass 0  
fill ~47 ~1 ~108 ~48 ~1 ~108 grass 0  
fill ~47 ~1 ~109 ~48 ~1 ~109 grass 0  
fill ~48 ~1 ~87 ~49 ~1 ~87 grass 0  
fill ~48 ~1 ~88 ~79 ~1 ~88 dirt 0  
fill ~48 ~1 ~89 ~79 ~1 ~89 dirt 0 
setblock ~48 ~1 ~97 dirt 0  
fill ~49 ~1 ~16 ~52 ~1 ~16 dirt 0 
setblock ~49 ~1 ~92 mycelium 0  
fill ~49 ~1 ~114 ~52 ~1 ~114 grass 0  
fill ~50 ~1 ~17 ~52 ~1 ~17 dirt 0  
fill ~50 ~1 ~87 ~71 ~1 ~87 dirt 0  
fill ~50 ~1 ~90 ~79 ~1 ~90 dirt 0 
setblock ~50 ~1 ~92 grass 0  
fill ~51 ~1 ~91 ~52 ~1 ~91 dirt 0  
fill ~51 ~1 ~92 ~52 ~1 ~92 dirt 0  
fill ~52 ~1 ~78 ~145 ~1 ~78 dirt 0  
fill ~53 ~1 ~91 ~53 ~1 ~113 grass 0  
fill ~53 ~1 ~114 ~74 ~1 ~114 dirt 0 
setblock ~54 ~1 ~70 grass 0  
fill ~54 ~1 ~91 ~79 ~1 ~91 dirt 0  
fill ~54 ~1 ~92 ~80 ~1 ~92 dirt 0  
fill ~54 ~1 ~93 ~81 ~1 ~93 dirt 0  
fill ~54 ~1 ~94 ~82 ~1 ~94 dirt 0  
fill ~54 ~1 ~95 ~84 ~1 ~95 dirt 0  
fill ~54 ~1 ~96 ~85 ~1 ~96 dirt 0  
fill ~54 ~1 ~97 ~86 ~1 ~97 dirt 0  
fill ~54 ~1 ~98 ~86 ~1 ~98 dirt 0  
fill ~54 ~1 ~99 ~87 ~1 ~99 dirt 0  
fill ~54 ~1 ~100 ~87 ~1 ~100 dirt 0  
fill ~54 ~1 ~101 ~88 ~1 ~101 dirt 0  
fill ~54 ~1 ~102 ~93 ~1 ~102 dirt 0  
fill ~54 ~1 ~103 ~92 ~1 ~103 dirt 0  
fill ~54 ~1 ~104 ~92 ~1 ~104 dirt 0  
fill ~54 ~1 ~105 ~91 ~1 ~105 dirt 0  
fill ~54 ~1 ~106 ~87 ~1 ~106 dirt 0  
fill ~54 ~1 ~107 ~86 ~1 ~107 dirt 0  
fill ~54 ~1 ~108 ~83 ~1 ~108 dirt 0  
fill ~54 ~1 ~109 ~81 ~1 ~109 dirt 0  
fill ~54 ~1 ~110 ~78 ~1 ~110 dirt 0  
fill ~54 ~1 ~111 ~76 ~1 ~111 dirt 0  
fill ~54 ~1 ~112 ~74 ~1 ~112 dirt 0  
fill ~54 ~1 ~113 ~72 ~1 ~113 dirt 0  
fill ~54 ~1 ~141 ~61 ~1 ~141 dirt 0  
fill ~55 ~1 ~40 ~58 ~1 ~40 dirt 0  
fill ~55 ~1 ~70 ~146 ~1 ~70 dirt 0  
fill ~55 ~1 ~142 ~60 ~1 ~142 dirt 0  
fill ~56 ~1 ~39 ~56 ~3 ~39 dirt 0  
fill ~56 ~1 ~143 ~59 ~1 ~143 dirt 0  
fill ~58 ~1 ~144 ~58 ~3 ~144 dirt 0  
fill ~65 ~1 ~40 ~138 ~1 ~40 dirt 0  
fill ~66 ~1 ~35 ~133 ~1 ~35 dirt 0  
fill ~66 ~1 ~36 ~134 ~1 ~36 dirt 0  
fill ~66 ~1 ~37 ~136 ~1 ~37 dirt 0  
fill ~66 ~1 ~38 ~137 ~1 ~38 dirt 0  
fill ~66 ~1 ~39 ~138 ~1 ~39 dirt 0  
fill ~67 ~1 ~34 ~133 ~1 ~34 dirt 0  
fill ~67 ~1 ~42 ~140 ~1 ~42 dirt 0  
fill ~68 ~1 ~33 ~133 ~1 ~33 dirt 0  
fill ~69 ~1 ~32 ~132 ~1 ~32 dirt 0  
fill ~69 ~1 ~43 ~141 ~1 ~43 dirt 0  
fill ~70 ~1 ~31 ~128 ~1 ~31 dirt 0  
fill ~72 ~1 ~30 ~127 ~1 ~30 dirt 0  
fill ~73 ~1 ~25 ~79 ~1 ~25 dirt 0  
fill ~73 ~1 ~26 ~123 ~1 ~26 dirt 0  
fill ~73 ~1 ~27 ~123 ~1 ~27 dirt 0  
fill ~73 ~1 ~28 ~124 ~1 ~28 dirt 0  
fill ~73 ~1 ~29 ~125 ~1 ~29 dirt 0  
fill ~74 ~1 ~10 ~110 ~1 ~10 dirt 0  
fill ~74 ~1 ~11 ~111 ~1 ~11 dirt 0  
fill ~74 ~1 ~12 ~111 ~1 ~12 dirt 0  
fill ~74 ~1 ~13 ~114 ~1 ~13 dirt 0  
fill ~74 ~1 ~24 ~78 ~1 ~24 dirt 0  
fill ~75 ~1 ~9 ~109 ~1 ~9 dirt 0  
fill ~75 ~1 ~14 ~115 ~1 ~14 dirt 0  
fill ~75 ~1 ~16 ~119 ~1 ~16 dirt 0  
fill ~75 ~1 ~17 ~120 ~1 ~17 dirt 0  
fill ~75 ~1 ~18 ~121 ~1 ~18 dirt 0  
fill ~76 ~1 ~7 ~107 ~1 ~7 dirt 0  
fill ~76 ~1 ~8 ~108 ~1 ~8 dirt 0  
fill ~76 ~1 ~15 ~118 ~1 ~15 dirt 0  
fill ~76 ~1 ~19 ~122 ~1 ~19 dirt 0  
fill ~76 ~1 ~23 ~77 ~1 ~23 dirt 0  
fill ~77 ~1 ~4 ~103 ~1 ~4 dirt 0  
fill ~77 ~1 ~5 ~105 ~1 ~5 dirt 0  
fill ~77 ~1 ~6 ~106 ~1 ~6 dirt 0  
fill ~77 ~1 ~20 ~123 ~1 ~20 dirt 0  
fill ~78 ~1 ~3 ~91 ~1 ~3 dirt 0  
fill ~78 ~1 ~21 ~123 ~1 ~21 dirt 0  
fill ~79 ~1 ~22 ~123 ~1 ~22 dirt 0  
fill ~80 ~1 ~2 ~88 ~1 ~2 dirt 0  
fill ~80 ~1 ~23 ~123 ~1 ~23 dirt 0  
fill ~81 ~1 ~1 ~84 ~1 ~1 dirt 0  
fill ~81 ~1 ~24 ~123 ~1 ~24 dirt 0  
fill ~81 ~1 ~25 ~123 ~1 ~25 dirt 0  
fill ~81 ~1 ~87 ~147 ~1 ~87 dirt 0  
fill ~81 ~1 ~88 ~147 ~1 ~88 dirt 0  
fill ~81 ~1 ~89 ~147 ~1 ~89 dirt 0  
fill ~81 ~1 ~90 ~147 ~1 ~90 dirt 0  
fill ~82 ~1 ~91 ~146 ~1 ~91 dirt 0  
fill ~83 ~1 ~92 ~146 ~1 ~92 dirt 0  
fill ~84 ~1 ~93 ~146 ~1 ~93 dirt 0  
fill ~86 ~1 ~94 ~146 ~1 ~94 dirt 0  
fill ~87 ~1 ~95 ~145 ~1 ~95 dirt 0  
fill ~88 ~1 ~96 ~144 ~1 ~96 dirt 0  
fill ~88 ~1 ~97 ~143 ~1 ~97 dirt 0  
fill ~89 ~1 ~98 ~101 ~1 ~98 dirt 0  
fill ~89 ~1 ~99 ~98 ~1 ~99 dirt 0  
fill ~90 ~1 ~100 ~98 ~1 ~100 dirt 0  
fill ~93 ~1 ~3 ~102 ~1 ~3 dirt 0  
fill ~93 ~1 ~101 ~93 ~3 ~101 dirt 0  
fill ~94 ~1 ~2 ~101 ~1 ~2 dirt 0  
fill ~95 ~1 ~1 ~100 ~1 ~1 dirt 0  
fill ~109 ~1 ~51 ~109 ~1 ~52 bedrock 0  
fill ~110 ~1 ~51 ~144 ~1 ~51 dirt 0  
fill ~110 ~1 ~52 ~145 ~1 ~52 dirt 0  
fill ~125 ~1 ~60 ~155 ~1 ~60 dirt 0  
fill ~125 ~1 ~61 ~154 ~1 ~61 dirt 0  
fill ~130 ~1 ~31 ~132 ~1 ~31 dirt 0  
fill ~130 ~1 ~41 ~139 ~1 ~41 dirt 0  
fill ~131 ~1 ~30 ~131 ~3 ~30 dirt 0  
fill ~2 ~2 ~26 ~9 ~2 ~26 dirt 0  
fill ~2 ~2 ~27 ~2 ~3 ~27 dirt 0  
fill ~2 ~2 ~28 ~2 ~3 ~28 dirt 0  
fill ~2 ~2 ~29 ~2 ~3 ~29 dirt 0  
fill ~2 ~2 ~30 ~2 ~3 ~30 dirt 0  
fill ~2 ~2 ~31 ~2 ~3 ~31 dirt 0  
fill ~2 ~2 ~32 ~2 ~3 ~32 dirt 0  
fill ~2 ~2 ~33 ~2 ~3 ~33 dirt 0  
fill ~2 ~2 ~34 ~2 ~3 ~34 dirt 0  
fill ~2 ~2 ~35 ~2 ~3 ~35 dirt 0  
fill ~2 ~2 ~36 ~2 ~3 ~36 dirt 0  
fill ~2 ~2 ~37 ~2 ~3 ~37 dirt 0  
fill ~2 ~2 ~38 ~2 ~3 ~38 dirt 0  
fill ~2 ~2 ~39 ~2 ~3 ~39 dirt 0  
fill ~2 ~2 ~40 ~2 ~3 ~40 dirt 0  
fill ~2 ~2 ~41 ~2 ~3 ~41 dirt 0  
fill ~2 ~2 ~42 ~2 ~3 ~42 dirt 0  
fill ~2 ~2 ~43 ~2 ~3 ~43 dirt 0  
fill ~2 ~2 ~44 ~2 ~3 ~44 dirt 0  
fill ~2 ~2 ~45 ~2 ~3 ~45 dirt 0  
fill ~2 ~2 ~46 ~2 ~3 ~46 dirt 0  
fill ~2 ~2 ~47 ~2 ~3 ~47 dirt 0  
fill ~3 ~2 ~27 ~18 ~2 ~27 stonebrick 0  
fill ~3 ~2 ~28 ~18 ~2 ~28 stonebrick 0  
fill ~3 ~2 ~29 ~18 ~2 ~29 stonebrick 0  
fill ~3 ~2 ~30 ~18 ~2 ~30 stonebrick 0  
fill ~3 ~2 ~31 ~18 ~2 ~31 stonebrick 0  
fill ~3 ~2 ~32 ~18 ~2 ~32 stonebrick 0  
fill ~3 ~2 ~33 ~18 ~2 ~33 stonebrick 0  
fill ~3 ~2 ~34 ~18 ~2 ~34 stonebrick 0  
fill ~3 ~2 ~35 ~19 ~2 ~35 stonebrick 0  
fill ~3 ~2 ~36 ~19 ~2 ~36 stonebrick 0  
fill ~3 ~2 ~37 ~19 ~2 ~37 stonebrick 0  
fill ~3 ~2 ~38 ~19 ~2 ~38 stonebrick 0  
fill ~3 ~2 ~39 ~18 ~2 ~39 stonebrick 0  
fill ~3 ~2 ~40 ~18 ~2 ~40 stonebrick 0  
fill ~3 ~2 ~41 ~18 ~2 ~41 stonebrick 0  
fill ~3 ~2 ~42 ~18 ~2 ~42 stonebrick 0  
fill ~3 ~2 ~43 ~18 ~2 ~43 stonebrick 0  
fill ~3 ~2 ~44 ~18 ~2 ~44 stonebrick 0  
fill ~3 ~2 ~45 ~18 ~2 ~45 stonebrick 0  
fill ~3 ~2 ~46 ~18 ~2 ~46 stonebrick 0  
fill ~3 ~2 ~47 ~18 ~2 ~47 stonebrick 0  
fill ~3 ~2 ~48 ~17 ~2 ~48 dirt 0  
fill ~9 ~2 ~23 ~9 ~3 ~23 dirt 0  
fill ~9 ~2 ~24 ~9 ~3 ~24 dirt 0  
fill ~9 ~2 ~25 ~9 ~3 ~25 dirt 0  
fill ~10 ~2 ~23 ~10 ~3 ~23 bedrock 0  
fill ~10 ~2 ~24 ~10 ~5 ~24 log 1  
fill ~10 ~2 ~25 ~10 ~3 ~25 bedrock 0  
fill ~10 ~2 ~26 ~10 ~3 ~26 bedrock 0  
fill ~11 ~2 ~21 ~11 ~3 ~21 bedrock 0  
fill ~11 ~2 ~22 ~11 ~3 ~22 bedrock 0  
fill ~11 ~2 ~23 ~11 ~6 ~23 log 1  
fill ~11 ~2 ~26 ~11 ~5 ~26 log 1  
fill ~12 ~2 ~20 ~12 ~3 ~20 bedrock 0  
fill ~12 ~2 ~21 ~12 ~5 ~21 log 1  
fill ~12 ~2 ~22 ~12 ~6 ~22 log 1  
fill ~13 ~2 ~19 ~13 ~3 ~19 bedrock 0  
fill ~13 ~2 ~20 ~13 ~5 ~20 log 1  
fill ~14 ~2 ~17 ~14 ~3 ~17 bedrock 0  
fill ~14 ~2 ~18 ~14 ~3 ~18 bedrock 0  
fill ~14 ~2 ~19 ~14 ~6 ~19 log 1  
fill ~14 ~2 ~20 ~15 ~2 ~20 glass 0  
fill ~14 ~2 ~21 ~15 ~2 ~21 glass 0  
fill ~14 ~2 ~22 ~15 ~2 ~22 glass 0  
fill ~14 ~2 ~23 ~15 ~2 ~23 glass 0  
fill ~14 ~2 ~24 ~16 ~2 ~24 glass 0  
fill ~14 ~2 ~25 ~16 ~2 ~25 glass 0  
fill ~14 ~2 ~26 ~16 ~2 ~26 glass 0  
fill ~14 ~2 ~103 ~14 ~3 ~103 dirt 0  
fill ~14 ~2 ~104 ~14 ~3 ~104 dirt 0  
fill ~14 ~2 ~105 ~14 ~3 ~105 dirt 0  
fill ~14 ~2 ~106 ~14 ~3 ~106 dirt 0  
fill ~14 ~2 ~107 ~14 ~3 ~107 dirt 0  
fill ~14 ~2 ~108 ~14 ~3 ~108 dirt 0  
fill ~14 ~2 ~109 ~14 ~3 ~109 dirt 0  
fill ~14 ~2 ~110 ~14 ~3 ~110 dirt 0  
fill ~14 ~2 ~111 ~14 ~3 ~111 dirt 0  
fill ~14 ~2 ~112 ~14 ~3 ~112 dirt 0  
fill ~14 ~2 ~113 ~14 ~3 ~113 dirt 0  
fill ~14 ~2 ~114 ~14 ~3 ~114 dirt 0  
fill ~14 ~2 ~115 ~14 ~3 ~115 dirt 0  
fill ~14 ~2 ~116 ~14 ~3 ~116 dirt 0  
fill ~15 ~2 ~16 ~16 ~2 ~16 bedrock 0  
fill ~15 ~2 ~17 ~17 ~2 ~17 log 1  
fill ~15 ~2 ~18 ~15 ~5 ~18 log 1  
fill ~15 ~2 ~103 ~15 ~5 ~103 bedrock 0  
fill ~15 ~2 ~104 ~15 ~7 ~104 log 1  
fill ~15 ~2 ~105 ~15 ~5 ~105 log 1  
fill ~15 ~2 ~106 ~15 ~5 ~106 log 1  
fill ~15 ~2 ~107 ~15 ~6 ~107 log 1  
fill ~15 ~2 ~108 ~15 ~5 ~108 log 1  
fill ~15 ~2 ~109 ~15 ~6 ~109 log 1  
fill ~15 ~2 ~110 ~15 ~5 ~110 log 1  
fill ~15 ~2 ~111 ~15 ~5 ~111 log 1  
fill ~15 ~2 ~112 ~15 ~5 ~112 log 1  
fill ~15 ~2 ~113 ~15 ~4 ~113 bedrock 0  
fill ~15 ~2 ~114 ~15 ~4 ~114 bedrock 0  
fill ~15 ~2 ~115 ~15 ~4 ~115 bedrock 0  
fill ~15 ~2 ~116 ~15 ~5 ~116 log 1  
fill ~15 ~2 ~117 ~15 ~3 ~117 bedrock 0  
fill ~16 ~2 ~51 ~16 ~3 ~51 dirt 0  
fill ~16 ~2 ~52 ~18 ~2 ~52 dirt 0  
fill ~16 ~2 ~53 ~17 ~2 ~53 dirt 0  
fill ~16 ~2 ~54 ~16 ~3 ~54 dirt 0  
fill ~16 ~2 ~55 ~17 ~2 ~55 dirt 0  
fill ~16 ~2 ~56 ~23 ~2 ~56 dirt 0  
fill ~16 ~2 ~57 ~20 ~2 ~57 dirt 0  
fill ~16 ~2 ~102 ~26 ~2 ~102 dirt 0  
fill ~16 ~2 ~103 ~16 ~5 ~103 log 1  
fill ~16 ~2 ~113 ~16 ~5 ~113 log 1  
fill ~16 ~2 ~115 ~16 ~5 ~115 log 1  
fill ~16 ~2 ~117 ~16 ~5 ~117 log 1  
fill ~16 ~2 ~118 ~16 ~3 ~118 bedrock 0  
fill ~17 ~2 ~15 ~18 ~2 ~15 bedrock 0  
fill ~17 ~2 ~16 ~18 ~2 ~16 log 1  
fill ~17 ~2 ~50 ~17 ~2 ~51 grass 0 
setblock ~17 ~2 ~54 grass 0  
fill ~17 ~2 ~101 ~26 ~2 ~101 dirt 0  
fill ~17 ~2 ~104 ~20 ~2 ~104 wool 14 
setblock ~17 ~2 ~105 netherrack 0  
fill ~17 ~2 ~106 ~20 ~2 ~106 wool 14  
fill ~17 ~2 ~107 ~20 ~2 ~107 wool 14  
fill ~17 ~2 ~108 ~20 ~2 ~108 wool 14  
fill ~17 ~2 ~109 ~20 ~2 ~109 wool 14  
fill ~17 ~2 ~110 ~20 ~2 ~110 wool 14  
fill ~17 ~2 ~111 ~18 ~2 ~111 wool 14  
fill ~17 ~2 ~112 ~18 ~2 ~112 netherrack 0  
fill ~17 ~2 ~119 ~17 ~3 ~119 bedrock 0  
fill ~18 ~2 ~48 ~18 ~2 ~49 grass 0  
fill ~18 ~2 ~50 ~18 ~1 ~50 dirt 0 
setblock ~18 ~2 ~51 grass 0 
setblock ~18 ~2 ~53 grass 0 
setblock ~18 ~2 ~54 dirt 0 
setblock ~18 ~2 ~55 grass 0  
fill ~18 ~2 ~100 ~26 ~2 ~100 dirt 0  
fill ~18 ~2 ~105 ~18 ~3 ~105 wool 14  
fill ~18 ~2 ~119 ~18 ~3 ~119 log 1  
fill ~18 ~2 ~120 ~18 ~3 ~120 bedrock 0  
fill ~19 ~2 ~14 ~20 ~2 ~14 bedrock 0  
fill ~19 ~2 ~15 ~21 ~2 ~15 log 1  
fill ~19 ~2 ~28 ~48 ~2 ~28 stonebrick 3  
fill ~19 ~2 ~29 ~20 ~2 ~29 stonebrick 3  
fill ~19 ~2 ~30 ~22 ~2 ~30 stonebrick 3  
fill ~19 ~2 ~31 ~20 ~2 ~31 stonebrick 3  
fill ~19 ~2 ~32 ~20 ~2 ~32 stonebrick 3  
fill ~19 ~2 ~33 ~22 ~2 ~33 stonebrick 3  
fill ~19 ~2 ~34 ~22 ~2 ~34 stonebrick 3 
setblock ~19 ~2 ~55 dirt 0  
fill ~19 ~2 ~78 ~50 ~2 ~78 dirt 0 
setblock ~19 ~2 ~105 netherrack 0  
fill ~19 ~2 ~111 ~19 ~3 ~111 netherrack 0  
fill ~19 ~2 ~112 ~20 ~2 ~112 wool 14  
fill ~19 ~2 ~120 ~19 ~4 ~120 log 1  
fill ~19 ~2 ~121 ~19 ~3 ~121 bedrock 0  
fill ~20 ~2 ~35 ~23 ~2 ~35 stonebrick 3  
fill ~20 ~2 ~36 ~20 ~2 ~38 stonebrick 3 
setblock ~20 ~2 ~55 grass 0  
fill ~20 ~2 ~66 ~149 ~2 ~66 dirt 0  
fill ~20 ~2 ~77 ~145 ~2 ~77 dirt 0  
fill ~20 ~2 ~79 ~146 ~2 ~79 dirt 0  
fill ~20 ~2 ~98 ~26 ~2 ~98 dirt 0  
fill ~20 ~2 ~105 ~20 ~3 ~105 wool 14  
fill ~20 ~2 ~111 ~20 ~4 ~111 wool 14  
fill ~20 ~2 ~121 ~20 ~5 ~121 log 1  
fill ~20 ~2 ~122 ~20 ~3 ~122 bedrock 0  
fill ~21 ~2 ~13 ~24 ~2 ~13 bedrock 0  
fill ~21 ~2 ~14 ~25 ~2 ~14 log 1 
setblock ~21 ~2 ~29 stonebrick 0  
fill ~21 ~2 ~31 ~21 ~2 ~32 planks 1 
setblock ~21 ~2 ~36 planks 1  
fill ~21 ~2 ~37 ~21 ~2 ~38 stonebrick 3  
fill ~21 ~2 ~55 ~22 ~2 ~55 dirt 0  
fill ~21 ~2 ~64 ~151 ~2 ~64 dirt 0  
fill ~21 ~2 ~65 ~150 ~2 ~65 dirt 0  
fill ~21 ~2 ~67 ~55 ~2 ~67 dirt 0  
fill ~21 ~2 ~76 ~127 ~2 ~76 dirt 0  
fill ~21 ~2 ~80 ~103 ~2 ~80 dirt 0  
fill ~21 ~2 ~97 ~26 ~2 ~97 dirt 0  
fill ~21 ~2 ~99 ~26 ~2 ~99 dirt 0  
fill ~21 ~2 ~122 ~21 ~5 ~122 log 1  
fill ~21 ~2 ~123 ~21 ~3 ~123 bedrock 0  
fill ~21 ~2 ~124 ~22 ~2 ~124 bedrock 0  
fill ~22 ~2 ~27 ~48 ~2 ~27 stonebrick 3  
fill ~22 ~2 ~29 ~23 ~2 ~29 stonebrick 3  
fill ~22 ~2 ~31 ~22 ~2 ~36 stonebrick 3  
fill ~22 ~2 ~37 ~23 ~2 ~37 planks 1  
fill ~22 ~2 ~38 ~22 ~2 ~39 stonebrick 3  
fill ~22 ~2 ~57 ~154 ~2 ~57 dirt 0  
fill ~22 ~2 ~63 ~152 ~2 ~63 dirt 0  
fill ~22 ~2 ~68 ~148 ~2 ~68 dirt 0  
fill ~22 ~2 ~75 ~145 ~2 ~75 dirt 0  
fill ~22 ~2 ~81 ~148 ~2 ~81 dirt 0  
fill ~22 ~2 ~96 ~26 ~2 ~96 dirt 0  
fill ~22 ~2 ~123 ~22 ~5 ~123 log 1  
fill ~23 ~2 ~36 ~25 ~2 ~36 stonebrick 3  
fill ~23 ~2 ~38 ~24 ~2 ~38 planks 1  
fill ~23 ~2 ~39 ~25 ~2 ~39 stonebrick 3 
setblock ~23 ~2 ~55 grass 0  
fill ~23 ~2 ~58 ~154 ~2 ~58 dirt 0  
fill ~23 ~2 ~60 ~122 ~2 ~60 dirt 0  
fill ~23 ~2 ~61 ~122 ~2 ~61 dirt 0  
fill ~23 ~2 ~62 ~153 ~2 ~62 dirt 0  
fill ~23 ~2 ~69 ~147 ~2 ~69 dirt 0  
fill ~23 ~2 ~72 ~146 ~2 ~72 dirt 0  
fill ~23 ~2 ~74 ~145 ~2 ~74 dirt 0  
fill ~23 ~2 ~82 ~89 ~2 ~82 dirt 0  
fill ~23 ~2 ~93 ~26 ~2 ~93 dirt 0  
fill ~23 ~2 ~95 ~26 ~2 ~95 dirt 0  
fill ~23 ~2 ~124 ~25 ~2 ~124 log 1  
fill ~23 ~2 ~125 ~25 ~2 ~125 dirt 0  
fill ~24 ~2 ~12 ~53 ~2 ~12 dirt 0 
setblock ~24 ~2 ~37 stonebrick 0  
fill ~24 ~2 ~40 ~25 ~2 ~40 stonebrick 3 
setblock ~24 ~2 ~55 dirt 0 
setblock ~24 ~2 ~56 grass 0  
fill ~24 ~2 ~59 ~154 ~2 ~59 dirt 0  
fill ~24 ~2 ~70 ~52 ~2 ~70 dirt 0  
fill ~24 ~2 ~71 ~146 ~2 ~71 dirt 0  
fill ~24 ~2 ~73 ~145 ~2 ~73 dirt 0  
fill ~24 ~2 ~83 ~149 ~2 ~83 dirt 0  
fill ~24 ~2 ~92 ~26 ~2 ~92 dirt 0  
fill ~24 ~2 ~94 ~26 ~2 ~94 dirt 0  
fill ~25 ~2 ~13 ~30 ~2 ~13 log 1  
fill ~25 ~2 ~37 ~27 ~2 ~37 stonebrick 3 
setblock ~25 ~2 ~38 stonebrick 0  
fill ~25 ~2 ~41 ~26 ~2 ~41 stonebrick 3  
fill ~25 ~2 ~55 ~26 ~2 ~55 grass 0  
fill ~25 ~2 ~56 ~40 ~2 ~56 dirt 0  
fill ~25 ~2 ~84 ~86 ~2 ~84 dirt 0  
fill ~25 ~2 ~91 ~26 ~2 ~91 dirt 0  
fill ~26 ~2 ~38 ~29 ~2 ~38 stonebrick 3  
fill ~26 ~2 ~39 ~26 ~2 ~40 planks 1  
fill ~26 ~2 ~42 ~26 ~2 ~48 stonebrick 3  
fill ~26 ~2 ~85 ~148 ~2 ~85 dirt 0  
fill ~26 ~2 ~90 ~26 ~3 ~90 dirt 0  
fill ~26 ~2 ~122 ~26 ~8 ~122 log 1  
fill ~26 ~2 ~123 ~26 ~6 ~123 log 1  
fill ~26 ~2 ~124 ~26 ~4 ~124 bedrock 0  
fill ~27 ~2 ~39 ~29 ~2 ~39 stonebrick 3 
setblock ~27 ~2 ~40 planks 1 
setblock ~27 ~2 ~41 stonebrick 0  
fill ~27 ~2 ~42 ~27 ~2 ~51 planks 1 
setblock ~27 ~2 ~55 dirt 0  
fill ~27 ~2 ~86 ~147 ~2 ~86 dirt 0  
fill ~27 ~2 ~87 ~28 ~2 ~87 dirt 0  
fill ~27 ~2 ~88 ~27 ~5 ~88 bedrock 0  
fill ~27 ~2 ~89 ~27 ~5 ~89 bedrock 0  
fill ~27 ~2 ~90 ~27 ~5 ~90 bedrock 0  
fill ~27 ~2 ~91 ~28 ~2 ~91 log 1  
fill ~27 ~2 ~98 ~27 ~2 ~99 grass 0  
fill ~27 ~2 ~100 ~30 ~2 ~100 mycelium 0  
fill ~27 ~2 ~101 ~28 ~2 ~101 mycelium 0  
fill ~27 ~2 ~102 ~28 ~2 ~102 mycelium 0  
fill ~27 ~2 ~121 ~27 ~6 ~121 log 1  
fill ~27 ~2 ~122 ~29 ~2 ~122 bedrock 0  
fill ~27 ~2 ~123 ~27 ~3 ~123 dirt 0  
fill ~27 ~2 ~124 ~27 ~3 ~124 dirt 0  
fill ~28 ~2 ~40 ~30 ~2 ~40 stonebrick 3  
fill ~28 ~2 ~41 ~29 ~2 ~41 stonebrick 3  
fill ~28 ~2 ~42 ~28 ~2 ~38 stonebrick 3  
fill ~28 ~2 ~43 ~28 ~2 ~51 planks 1  
fill ~28 ~2 ~55 ~33 ~2 ~55 grass 0  
fill ~28 ~2 ~97 ~31 ~2 ~97 mycelium 0  
fill ~28 ~2 ~98 ~30 ~2 ~98 mycelium 0  
fill ~28 ~2 ~99 ~29 ~2 ~99 mycelium 0  
fill ~28 ~2 ~120 ~28 ~7 ~120 log 1  
fill ~29 ~2 ~42 ~30 ~2 ~42 stonebrick 0  
fill ~29 ~2 ~43 ~30 ~2 ~43 stonebrick 3  
fill ~29 ~2 ~44 ~30 ~2 ~44 planks 1  
fill ~29 ~2 ~45 ~29 ~2 ~46 planks 1  
fill ~29 ~2 ~48 ~29 ~2 ~51 planks 1  
fill ~29 ~2 ~87 ~41 ~2 ~87 grass 0  
fill ~29 ~2 ~88 ~29 ~7 ~88 log 1  
fill ~29 ~2 ~89 ~29 ~7 ~89 log 1  
fill ~29 ~2 ~90 ~29 ~7 ~90 log 1  
fill ~29 ~2 ~119 ~29 ~5 ~119 log 1  
fill ~29 ~2 ~121 ~32 ~2 ~121 bedrock 0  
fill ~29 ~2 ~138 ~64 ~2 ~138 dirt 0  
fill ~29 ~2 ~139 ~62 ~2 ~139 dirt 0  
fill ~29 ~2 ~140 ~61 ~2 ~140 dirt 0  
fill ~29 ~2 ~141 ~50 ~2 ~141 dirt 0 
setblock ~30 ~2 ~41 planks 1  
fill ~30 ~2 ~95 ~31 ~2 ~95 mycelium 0  
fill ~30 ~2 ~96 ~31 ~2 ~96 mycelium 0  
fill ~30 ~2 ~99 ~36 ~2 ~99 planks 0  
fill ~30 ~2 ~118 ~31 ~2 ~118 log 1  
fill ~30 ~2 ~134 ~64 ~2 ~134 dirt 0  
fill ~30 ~2 ~135 ~65 ~2 ~135 dirt 0  
fill ~30 ~2 ~136 ~66 ~2 ~136 dirt 0  
fill ~30 ~2 ~137 ~65 ~2 ~137 dirt 0  
fill ~30 ~2 ~142 ~49 ~2 ~142 dirt 0  
fill ~31 ~2 ~13 ~31 ~3 ~13 bedrock 0  
fill ~31 ~2 ~14 ~31 ~5 ~14 log 1  
fill ~31 ~2 ~41 ~33 ~2 ~41 stonebrick 3  
fill ~31 ~2 ~42 ~33 ~2 ~42 stonebrick 3  
fill ~31 ~2 ~43 ~32 ~2 ~43 planks 1  
fill ~31 ~2 ~44 ~31 ~2 ~45 stonebrick 3  
fill ~31 ~2 ~93 ~34 ~2 ~93 mycelium 0  
fill ~31 ~2 ~94 ~33 ~2 ~94 mycelium 0  
fill ~31 ~2 ~98 ~36 ~2 ~98 planks 0  
fill ~31 ~2 ~100 ~36 ~2 ~100 planks 0  
fill ~31 ~2 ~117 ~31 ~5 ~117 log 1  
fill ~31 ~2 ~133 ~63 ~2 ~133 dirt 0  
fill ~31 ~2 ~143 ~48 ~2 ~143 dirt 0  
fill ~31 ~2 ~144 ~47 ~2 ~144 dirt 0  
fill ~32 ~2 ~14 ~32 ~3 ~14 bedrock 0  
fill ~32 ~2 ~15 ~32 ~5 ~15 log 1  
fill ~32 ~2 ~44 ~33 ~2 ~44 planks 1  
fill ~32 ~2 ~45 ~36 ~2 ~45 stonebrick 3  
fill ~32 ~2 ~46 ~34 ~2 ~46 stonebrick 3  
fill ~32 ~2 ~92 ~41 ~2 ~92 mycelium 0  
fill ~32 ~2 ~95 ~32 ~2 ~96 dirt 0  
fill ~32 ~2 ~97 ~36 ~2 ~97 planks 0  
fill ~32 ~2 ~119 ~32 ~5 ~119 log 1  
fill ~32 ~2 ~132 ~62 ~2 ~132 dirt 0  
fill ~32 ~2 ~145 ~46 ~2 ~145 dirt 0  
fill ~33 ~2 ~15 ~34 ~2 ~15 bedrock 0  
fill ~33 ~2 ~16 ~34 ~2 ~16 log 1 
setblock ~33 ~2 ~40 log 1  
fill ~33 ~2 ~43 ~34 ~2 ~43 stonebrick 3  
fill ~33 ~2 ~47 ~34 ~2 ~47 stonebrick 3  
fill ~33 ~2 ~91 ~41 ~2 ~91 mycelium 0  
fill ~33 ~2 ~95 ~36 ~2 ~95 planks 0  
fill ~33 ~2 ~96 ~36 ~2 ~96 planks 0  
fill ~33 ~2 ~120 ~33 ~7 ~120 log 1  
fill ~33 ~2 ~121 ~38 ~2 ~121 dirt 0  
fill ~33 ~2 ~122 ~38 ~2 ~122 dirt 0  
fill ~33 ~2 ~146 ~45 ~2 ~146 dirt 0  
fill ~34 ~2 ~39 ~39 ~2 ~39 dirt 0  
fill ~34 ~2 ~40 ~39 ~2 ~40 dirt 0  
fill ~34 ~2 ~41 ~39 ~2 ~41 dirt 0  
fill ~34 ~2 ~42 ~39 ~2 ~42 dirt 0  
fill ~34 ~2 ~44 ~35 ~2 ~44 stonebrick 3  
fill ~34 ~2 ~48 ~37 ~2 ~48 stonebrick 3  
fill ~34 ~2 ~50 ~38 ~2 ~50 stonebrick 3  
fill ~34 ~2 ~51 ~39 ~2 ~51 stone 0  
fill ~34 ~2 ~52 ~36 ~2 ~52 stone 0  
fill ~34 ~2 ~53 ~43 ~2 ~53 stone 0  
fill ~34 ~2 ~55 ~38 ~2 ~55 dirt 0  
fill ~34 ~2 ~89 ~40 ~2 ~89 mycelium 0  
fill ~34 ~2 ~90 ~40 ~2 ~90 mycelium 0  
fill ~34 ~2 ~94 ~36 ~2 ~94 planks 0  
fill ~34 ~2 ~131 ~63 ~2 ~131 dirt 0  
fill ~35 ~2 ~14 ~35 ~3 ~14 bedrock 0  
fill ~35 ~2 ~15 ~36 ~2 ~15 log 1  
fill ~35 ~2 ~43 ~39 ~2 ~43 dirt 0  
fill ~35 ~2 ~46 ~35 ~2 ~47 planks 1  
fill ~35 ~2 ~49 ~37 ~2 ~49 stonebrick 3  
fill ~35 ~2 ~88 ~41 ~2 ~88 mycelium 0  
fill ~35 ~2 ~93 ~36 ~2 ~93 planks 0  
fill ~35 ~2 ~123 ~75 ~2 ~123 dirt 0  
fill ~35 ~2 ~130 ~66 ~2 ~130 dirt 0  
fill ~35 ~2 ~147 ~39 ~2 ~147 dirt 0  
fill ~36 ~2 ~13 ~37 ~2 ~13 bedrock 0  
fill ~36 ~2 ~14 ~37 ~2 ~14 log 1  
fill ~36 ~2 ~44 ~39 ~2 ~44 dirt 0  
fill ~36 ~2 ~46 ~37 ~2 ~46 stonebrick 3  
fill ~36 ~2 ~47 ~37 ~2 ~47 planks 1  
fill ~36 ~2 ~124 ~74 ~2 ~124 dirt 0  
fill ~36 ~2 ~125 ~70 ~2 ~125 dirt 0  
fill ~36 ~2 ~129 ~67 ~2 ~129 dirt 0  
fill ~37 ~2 ~45 ~38 ~2 ~45 dirt 0  
fill ~37 ~2 ~52 ~39 ~2 ~52 planks 1  
fill ~37 ~2 ~54 ~38 ~2 ~54 stonebrick 3 
setblock ~37 ~2 ~93 mycelium 0  
fill ~37 ~2 ~126 ~69 ~2 ~126 dirt 0  
fill ~37 ~2 ~128 ~68 ~2 ~128 dirt 0  
fill ~38 ~2 ~13 ~49 ~2 ~13 log 1  
fill ~38 ~2 ~38 ~39 ~2 ~38 dirt 0  
fill ~38 ~2 ~46 ~40 ~2 ~46 stone 0  
fill ~38 ~2 ~47 ~43 ~2 ~47 stone 0  
fill ~38 ~2 ~48 ~39 ~2 ~48 stone 0  
fill ~38 ~2 ~49 ~42 ~2 ~49 stone 0  
fill ~38 ~2 ~110 ~38 ~6 ~110 fence 0  
fill ~38 ~2 ~127 ~69 ~2 ~127 dirt 0  
fill ~39 ~2 ~45 ~48 ~2 ~45 stone 0  
fill ~39 ~2 ~50 ~42 ~2 ~50 stone 0  
fill ~39 ~2 ~54 ~45 ~2 ~54 mycelium 0  
fill ~39 ~2 ~55 ~44 ~2 ~55 mycelium 0  
fill ~40 ~2 ~48 ~41 ~2 ~48 planks 1  
fill ~40 ~2 ~51 ~41 ~2 ~51 planks 1  
fill ~40 ~2 ~52 ~41 ~2 ~52 stone 0  
fill ~40 ~2 ~97 ~41 ~2 ~97 planks 0  
fill ~40 ~2 ~121 ~40 ~2 ~122 stone_slab 1  
fill ~41 ~2 ~46 ~42 ~2 ~46 planks 1 
setblock ~41 ~2 ~56 mycelium 0  
fill ~41 ~2 ~89 ~41 ~2 ~90 stone_slab 1  
fill ~41 ~2 ~99 ~42 ~2 ~99 planks 0  
fill ~41 ~2 ~114 ~41 ~2 ~120 dirt 0  
fill ~41 ~2 ~121 ~41 ~2 ~122 grass 0 
setblock ~42 ~2 ~48 stone 0  
fill ~42 ~2 ~51 ~45 ~2 ~51 stone 0  
fill ~42 ~2 ~52 ~43 ~2 ~52 planks 1  
fill ~42 ~2 ~56 ~154 ~2 ~56 dirt 0  
fill ~42 ~2 ~87 ~49 ~2 ~87 fence 0 
setblock ~42 ~2 ~88 stone_slab 1  
fill ~42 ~2 ~114 ~43 ~2 ~114 oak_stairs 2  
fill ~42 ~2 ~115 ~44 ~2 ~115 mycelium 0  
fill ~42 ~2 ~116 ~48 ~2 ~116 dirt 0  
fill ~42 ~2 ~117 ~76 ~2 ~117 dirt 0  
fill ~42 ~2 ~118 ~77 ~2 ~118 dirt 0  
fill ~42 ~2 ~119 ~78 ~2 ~119 dirt 0  
fill ~42 ~2 ~120 ~78 ~2 ~120 dirt 0  
fill ~42 ~2 ~121 ~77 ~2 ~121 dirt 0  
fill ~42 ~2 ~122 ~76 ~2 ~122 dirt 0  
fill ~42 ~2 ~147 ~44 ~2 ~147 dirt 0  
fill ~43 ~2 ~46 ~46 ~2 ~46 stone 0  
fill ~43 ~2 ~48 ~43 ~2 ~50 planks 1  
fill ~44 ~2 ~47 ~45 ~2 ~47 planks 1  
fill ~44 ~2 ~48 ~47 ~2 ~48 stone 0  
fill ~44 ~2 ~49 ~45 ~2 ~49 planks 1  
fill ~44 ~2 ~50 ~44 ~2 ~49 planks 1  
fill ~44 ~2 ~52 ~45 ~2 ~52 stone 0  
fill ~44 ~2 ~53 ~45 ~2 ~53 planks 1  
fill ~44 ~2 ~97 ~45 ~2 ~97 planks 0  
fill ~44 ~2 ~110 ~45 ~2 ~110 planks 0  
fill ~44 ~2 ~111 ~45 ~2 ~111 planks 0 
setblock ~44 ~2 ~114 mycelium 0  
fill ~45 ~2 ~29 ~45 ~2 ~31 stonebrick 0  
fill ~45 ~2 ~50 ~47 ~2 ~50 stone 0 
setblock ~45 ~2 ~55 dirt 0  
fill ~45 ~2 ~92 ~47 ~2 ~92 fence 0  
fill ~45 ~2 ~93 ~45 ~10 ~93 log 1  
fill ~45 ~2 ~101 ~46 ~2 ~101 planks 0  
fill ~45 ~2 ~109 ~46 ~2 ~109 planks 0  
fill ~45 ~2 ~113 ~45 ~6 ~113 planks 1  
fill ~45 ~2 ~114 ~48 ~2 ~114 dirt 0  
fill ~45 ~2 ~115 ~48 ~2 ~115 dirt 0  
fill ~46 ~2 ~10 ~52 ~2 ~10 dirt 0  
fill ~46 ~2 ~11 ~53 ~2 ~11 dirt 0  
fill ~46 ~2 ~24 ~48 ~2 ~24 stonebrick 3  
fill ~46 ~2 ~25 ~48 ~2 ~25 stonebrick 3  
fill ~46 ~2 ~26 ~48 ~2 ~26 stonebrick 3  
fill ~46 ~2 ~29 ~48 ~2 ~29 stonebrick 3  
fill ~46 ~2 ~30 ~48 ~2 ~30 stonebrick 3  
fill ~46 ~2 ~31 ~48 ~2 ~31 stonebrick 3  
fill ~46 ~2 ~32 ~47 ~2 ~32 stonebrick 3  
fill ~46 ~2 ~33 ~47 ~2 ~33 stonebrick 3  
fill ~46 ~2 ~34 ~47 ~2 ~34 stonebrick 3  
fill ~46 ~2 ~35 ~47 ~2 ~35 stonebrick 3  
fill ~46 ~2 ~36 ~47 ~2 ~36 stonebrick 3  
fill ~46 ~2 ~43 ~47 ~2 ~43 stone 0  
fill ~46 ~2 ~44 ~46 ~2 ~43 stone 0  
fill ~46 ~2 ~47 ~49 ~2 ~47 stone 0  
fill ~46 ~2 ~49 ~47 ~2 ~49 stone 0  
fill ~46 ~2 ~51 ~46 ~2 ~52 planks 1  
fill ~46 ~2 ~53 ~48 ~2 ~53 stone 0  
fill ~46 ~2 ~54 ~46 ~2 ~55 grass 0  
fill ~46 ~2 ~95 ~46 ~7 ~95 log 1  
fill ~46 ~2 ~99 ~46 ~10 ~99 log 1  
fill ~47 ~2 ~14 ~49 ~2 ~14 log 1 
setblock ~47 ~2 ~42 stone 0 
setblock ~47 ~2 ~44 planks 1 
setblock ~47 ~2 ~46 planks 1  
fill ~47 ~2 ~51 ~48 ~2 ~51 stone 0  
fill ~47 ~2 ~52 ~48 ~2 ~52 stone 0  
fill ~47 ~2 ~54 ~85 ~2 ~54 dirt 0  
fill ~47 ~2 ~55 ~153 ~2 ~55 dirt 0  
fill ~47 ~2 ~93 ~49 ~2 ~93 fence 0  
fill ~47 ~2 ~99 ~49 ~2 ~99 fence 0  
fill ~47 ~2 ~100 ~47 ~2 ~104 fence 0  
fill ~47 ~2 ~109 ~48 ~2 ~109 fence 0  
fill ~47 ~2 ~110 ~47 ~2 ~111 fence 0 
setblock ~47 ~2 ~112 glowstone 0  
fill ~48 ~2 ~15 ~49 ~2 ~15 log 1 
setblock ~48 ~2 ~44 stone 0  
fill ~48 ~2 ~46 ~49 ~2 ~46 stone 0  
fill ~48 ~2 ~48 ~49 ~2 ~48 planks 1  
fill ~48 ~2 ~49 ~48 ~2 ~50 planks 1  
fill ~48 ~2 ~88 ~48 ~2 ~89 oak_stairs 0  
fill ~48 ~2 ~94 ~48 ~2 ~96 fence 0  
fill ~48 ~2 ~97 ~48 ~8 ~97 log 1  
fill ~48 ~2 ~104 ~49 ~2 ~104 fence 0  
fill ~48 ~2 ~108 ~49 ~2 ~108 fence 0  
fill ~48 ~2 ~111 ~48 ~3 ~111 fence 0  
fill ~48 ~2 ~112 ~49 ~2 ~112 fence 0  
fill ~49 ~2 ~49 ~50 ~2 ~49 stone 0  
fill ~49 ~2 ~50 ~49 ~2 ~49 stone 0  
fill ~49 ~2 ~51 ~144 ~2 ~51 dirt 0  
fill ~49 ~2 ~52 ~49 ~2 ~53 grass 0  
fill ~49 ~2 ~88 ~49 ~2 ~89 planks 0  
fill ~49 ~2 ~96 ~49 ~2 ~99 fence 0  
fill ~49 ~2 ~105 ~49 ~2 ~108 fence 0  
fill ~49 ~2 ~113 ~49 ~3 ~113 fence 0  
fill ~49 ~2 ~114 ~49 ~3 ~114 fence 0  
fill ~49 ~2 ~115 ~50 ~2 ~115 grass 0  
fill ~49 ~2 ~116 ~51 ~2 ~116 grass 0  
fill ~50 ~2 ~13 ~53 ~2 ~13 dirt 0  
fill ~50 ~2 ~14 ~53 ~2 ~14 dirt 0  
fill ~50 ~2 ~15 ~53 ~2 ~15 dirt 0  
fill ~50 ~2 ~16 ~52 ~2 ~16 dirt 0  
fill ~50 ~2 ~17 ~52 ~2 ~17 dirt 0  
fill ~50 ~2 ~18 ~54 ~2 ~18 dirt 0  
fill ~50 ~2 ~19 ~55 ~2 ~19 dirt 0  
fill ~50 ~2 ~20 ~56 ~2 ~20 dirt 0  
fill ~50 ~2 ~21 ~57 ~2 ~21 dirt 0  
fill ~50 ~2 ~22 ~57 ~2 ~22 dirt 0  
fill ~50 ~2 ~23 ~57 ~2 ~23 dirt 0  
fill ~50 ~2 ~24 ~56 ~2 ~24 dirt 0  
fill ~50 ~2 ~25 ~55 ~2 ~25 dirt 0  
fill ~50 ~2 ~26 ~50 ~2 ~28 grass 0  
fill ~50 ~2 ~29 ~53 ~2 ~29 dirt 0  
fill ~50 ~2 ~30 ~53 ~2 ~30 dirt 0  
fill ~50 ~2 ~31 ~53 ~2 ~31 dirt 0  
fill ~50 ~2 ~32 ~52 ~2 ~32 dirt 0  
fill ~50 ~2 ~33 ~52 ~2 ~33 dirt 0  
fill ~50 ~2 ~34 ~53 ~2 ~34 dirt 0  
fill ~50 ~2 ~35 ~52 ~2 ~35 dirt 0  
fill ~50 ~2 ~36 ~52 ~2 ~36 dirt 0  
fill ~50 ~2 ~37 ~52 ~2 ~37 dirt 0  
fill ~50 ~2 ~38 ~53 ~2 ~38 dirt 0  
fill ~50 ~2 ~39 ~53 ~2 ~39 dirt 0  
fill ~50 ~2 ~40 ~53 ~2 ~40 dirt 0  
fill ~50 ~2 ~41 ~128 ~2 ~41 dirt 0  
fill ~50 ~2 ~42 ~65 ~2 ~42 dirt 0  
fill ~50 ~2 ~43 ~65 ~2 ~43 dirt 0  
fill ~50 ~2 ~44 ~56 ~2 ~44 dirt 0  
fill ~50 ~2 ~45 ~66 ~2 ~45 dirt 0  
fill ~50 ~2 ~46 ~142 ~2 ~46 dirt 0 
setblock ~50 ~2 ~47 planks 1 
setblock ~50 ~2 ~48 stone 0  
fill ~50 ~2 ~50 ~83 ~2 ~50 dirt 0  
fill ~50 ~2 ~52 ~145 ~2 ~52 dirt 0  
fill ~50 ~2 ~53 ~89 ~2 ~53 dirt 0  
fill ~50 ~2 ~87 ~71 ~2 ~87 dirt 0  
fill ~50 ~2 ~88 ~79 ~2 ~88 dirt 0  
fill ~50 ~2 ~89 ~79 ~2 ~89 dirt 0  
fill ~50 ~2 ~90 ~50 ~3 ~90 planks 1  
fill ~51 ~2 ~26 ~54 ~2 ~26 dirt 0  
fill ~51 ~2 ~27 ~54 ~2 ~27 dirt 0  
fill ~51 ~2 ~28 ~53 ~2 ~28 dirt 0  
fill ~51 ~2 ~47 ~142 ~2 ~47 dirt 0  
fill ~51 ~2 ~48 ~83 ~2 ~48 dirt 0  
fill ~51 ~2 ~49 ~82 ~2 ~49 dirt 0  
fill ~51 ~2 ~90 ~52 ~2 ~90 dirt 0  
fill ~51 ~2 ~91 ~52 ~2 ~91 planks 0  
fill ~51 ~2 ~92 ~52 ~2 ~92 oak_stairs 3 
setblock ~51 ~2 ~115 mycelium 0  
fill ~52 ~2 ~78 ~145 ~2 ~78 dirt 0 
setblock ~52 ~2 ~115 grass 0 
setblock ~52 ~2 ~116 mycelium 0  
fill ~53 ~2 ~90 ~53 ~3 ~90 planks 0  
fill ~53 ~2 ~91 ~53 ~4 ~91 fence 0  
fill ~53 ~2 ~92 ~53 ~4 ~92 fence 0  
fill ~53 ~2 ~93 ~53 ~4 ~93 fence 0  
fill ~53 ~2 ~94 ~53 ~4 ~94 fence 0  
fill ~53 ~2 ~95 ~53 ~3 ~95 fence 0  
fill ~53 ~2 ~96 ~53 ~2 ~113 fence 0  
fill ~53 ~2 ~114 ~74 ~2 ~114 dirt 0  
fill ~53 ~2 ~115 ~75 ~2 ~115 dirt 0  
fill ~53 ~2 ~116 ~76 ~2 ~116 dirt 0 
setblock ~54 ~2 ~70 redstone_torch 5  
fill ~54 ~2 ~90 ~79 ~2 ~90 dirt 0  
fill ~54 ~2 ~91 ~79 ~2 ~91 dirt 0  
fill ~54 ~2 ~92 ~54 ~2 ~113 grass 0  
fill ~54 ~2 ~141 ~61 ~2 ~141 dirt 0  
fill ~55 ~2 ~40 ~58 ~2 ~40 dirt 0  
fill ~55 ~2 ~70 ~146 ~2 ~70 dirt 0  
fill ~55 ~2 ~92 ~80 ~2 ~92 dirt 0  
fill ~55 ~2 ~93 ~81 ~2 ~93 dirt 0  
fill ~55 ~2 ~94 ~82 ~2 ~94 dirt 0  
fill ~55 ~2 ~95 ~84 ~2 ~95 dirt 0  
fill ~55 ~2 ~96 ~85 ~2 ~96 dirt 0  
fill ~55 ~2 ~97 ~86 ~2 ~97 dirt 0  
fill ~55 ~2 ~98 ~86 ~2 ~98 dirt 0  
fill ~55 ~2 ~99 ~87 ~2 ~99 dirt 0  
fill ~55 ~2 ~100 ~87 ~2 ~100 dirt 0  
fill ~55 ~2 ~101 ~88 ~2 ~101 dirt 0  
fill ~55 ~2 ~102 ~93 ~2 ~102 dirt 0  
fill ~55 ~2 ~103 ~92 ~2 ~103 dirt 0  
fill ~55 ~2 ~104 ~92 ~2 ~104 dirt 0  
fill ~55 ~2 ~105 ~91 ~2 ~105 dirt 0  
fill ~55 ~2 ~106 ~87 ~2 ~106 dirt 0  
fill ~55 ~2 ~107 ~86 ~2 ~107 dirt 0  
fill ~55 ~2 ~108 ~83 ~2 ~108 dirt 0  
fill ~55 ~2 ~109 ~81 ~2 ~109 dirt 0  
fill ~55 ~2 ~110 ~78 ~2 ~110 dirt 0  
fill ~55 ~2 ~111 ~76 ~2 ~111 dirt 0  
fill ~55 ~2 ~112 ~74 ~2 ~112 dirt 0  
fill ~55 ~2 ~113 ~72 ~2 ~113 dirt 0  
fill ~55 ~2 ~142 ~60 ~2 ~142 dirt 0  
fill ~56 ~2 ~67 ~56 ~7 ~67 planks 0  
fill ~56 ~2 ~143 ~59 ~2 ~143 dirt 0 
setblock ~57 ~2 ~44 mob_spawner 0  
fill ~57 ~2 ~67 ~149 ~2 ~67 dirt 0  
fill ~58 ~2 ~44 ~66 ~2 ~44 dirt 0  
fill ~65 ~2 ~40 ~139 ~2 ~40 dirt 0  
fill ~66 ~2 ~35 ~73 ~2 ~35 dirt 0  
fill ~66 ~2 ~36 ~91 ~2 ~36 dirt 0  
fill ~66 ~2 ~37 ~136 ~2 ~37 dirt 0  
fill ~66 ~2 ~38 ~137 ~2 ~38 dirt 0  
fill ~66 ~2 ~39 ~138 ~2 ~39 dirt 0  
fill ~67 ~2 ~34 ~73 ~2 ~34 dirt 0  
fill ~68 ~2 ~33 ~73 ~2 ~33 dirt 0  
fill ~68 ~2 ~45 ~142 ~2 ~45 dirt 0  
fill ~69 ~2 ~32 ~132 ~2 ~32 dirt 0  
fill ~69 ~2 ~42 ~140 ~2 ~42 dirt 0  
fill ~69 ~2 ~43 ~141 ~2 ~43 dirt 0  
fill ~69 ~2 ~44 ~142 ~2 ~44 dirt 0  
fill ~70 ~2 ~31 ~128 ~2 ~31 dirt 0  
fill ~72 ~2 ~30 ~127 ~2 ~30 dirt 0  
fill ~73 ~2 ~25 ~79 ~2 ~25 dirt 0  
fill ~73 ~2 ~26 ~123 ~2 ~26 dirt 0  
fill ~73 ~2 ~27 ~123 ~2 ~27 dirt 0  
fill ~73 ~2 ~28 ~124 ~2 ~28 dirt 0  
fill ~73 ~2 ~29 ~125 ~2 ~29 dirt 0  
fill ~74 ~2 ~10 ~110 ~2 ~10 dirt 0  
fill ~74 ~2 ~11 ~111 ~2 ~11 dirt 0  
fill ~74 ~2 ~12 ~111 ~2 ~12 dirt 0  
fill ~74 ~2 ~13 ~114 ~2 ~13 dirt 0  
fill ~74 ~2 ~24 ~78 ~2 ~24 dirt 0  
fill ~75 ~2 ~9 ~109 ~2 ~9 dirt 0  
fill ~75 ~2 ~14 ~115 ~2 ~14 dirt 0  
fill ~75 ~2 ~16 ~119 ~2 ~16 dirt 0  
fill ~75 ~2 ~17 ~120 ~2 ~17 dirt 0  
fill ~75 ~2 ~18 ~121 ~2 ~18 dirt 0  
fill ~76 ~2 ~7 ~107 ~2 ~7 dirt 0  
fill ~76 ~2 ~8 ~108 ~2 ~8 dirt 0  
fill ~76 ~2 ~15 ~118 ~2 ~15 dirt 0  
fill ~76 ~2 ~19 ~122 ~2 ~19 dirt 0  
fill ~76 ~2 ~23 ~77 ~2 ~23 dirt 0  
fill ~77 ~2 ~4 ~103 ~2 ~4 dirt 0  
fill ~77 ~2 ~5 ~105 ~2 ~5 dirt 0  
fill ~77 ~2 ~6 ~103 ~2 ~6 dirt 0  
fill ~77 ~2 ~20 ~123 ~2 ~20 dirt 0  
fill ~78 ~2 ~3 ~91 ~2 ~3 dirt 0  
fill ~78 ~2 ~21 ~123 ~2 ~21 dirt 0  
fill ~79 ~2 ~22 ~123 ~2 ~22 dirt 0  
fill ~80 ~2 ~2 ~88 ~2 ~2 dirt 0  
fill ~80 ~2 ~23 ~123 ~2 ~23 dirt 0  
fill ~81 ~2 ~1 ~84 ~2 ~1 dirt 0  
fill ~81 ~2 ~24 ~123 ~2 ~24 dirt 0  
fill ~81 ~2 ~25 ~123 ~2 ~25 dirt 0  
fill ~81 ~2 ~87 ~86 ~2 ~87 dirt 0  
fill ~81 ~2 ~88 ~147 ~2 ~88 dirt 0  
fill ~81 ~2 ~89 ~92 ~2 ~89 dirt 0  
fill ~81 ~2 ~90 ~91 ~2 ~90 dirt 0  
fill ~82 ~2 ~91 ~146 ~2 ~91 dirt 0  
fill ~83 ~2 ~49 ~84 ~2 ~49 gravel 0  
fill ~83 ~2 ~92 ~146 ~2 ~92 dirt 0  
fill ~83 ~2 ~93 ~146 ~2 ~93 dirt 0 
setblock ~84 ~2 ~48 gravel 0 
setblock ~84 ~2 ~50 gravel 0  
fill ~85 ~2 ~48 ~143 ~2 ~48 dirt 0  
fill ~85 ~2 ~49 ~143 ~2 ~49 dirt 0  
fill ~85 ~2 ~50 ~143 ~2 ~50 dirt 0  
fill ~86 ~2 ~54 ~87 ~2 ~54 grass 0  
fill ~86 ~2 ~94 ~146 ~2 ~94 dirt 0 
setblock ~87 ~2 ~84 grass 0 
setblock ~87 ~2 ~87 grass 0  
fill ~87 ~2 ~95 ~145 ~2 ~95 dirt 0  
fill ~88 ~2 ~54 ~150 ~2 ~54 dirt 0 
setblock ~88 ~2 ~84 dirt 0  
fill ~88 ~2 ~87 ~147 ~2 ~87 dirt 0  
fill ~88 ~2 ~96 ~144 ~2 ~96 dirt 0  
fill ~88 ~2 ~97 ~143 ~2 ~97 dirt 0 
setblock ~89 ~2 ~84 grass 0  
fill ~89 ~2 ~98 ~101 ~2 ~98 dirt 0  
fill ~89 ~2 ~99 ~98 ~2 ~99 dirt 0 
setblock ~90 ~2 ~53 mycelium 0  
fill ~90 ~2 ~84 ~149 ~2 ~84 dirt 0  
fill ~90 ~2 ~100 ~98 ~2 ~100 dirt 0  
fill ~91 ~2 ~53 ~149 ~2 ~53 dirt 0  
fill ~91 ~2 ~82 ~149 ~2 ~82 dirt 0  
fill ~92 ~2 ~90 ~94 ~2 ~90 cobblestone 0  
fill ~93 ~2 ~3 ~102 ~2 ~3 dirt 0  
fill ~93 ~2 ~89 ~93 ~4 ~89 cobblestone 0  
fill ~94 ~2 ~2 ~101 ~2 ~2 dirt 0  
fill ~94 ~2 ~36 ~135 ~2 ~36 dirt 0  
fill ~94 ~2 ~89 ~147 ~2 ~89 dirt 0  
fill ~95 ~2 ~1 ~100 ~2 ~1 dirt 0  
fill ~95 ~2 ~90 ~147 ~2 ~90 dirt 0  
fill ~104 ~2 ~6 ~104 ~7 ~6 log 1  
fill ~105 ~2 ~6 ~106 ~2 ~6 dirt 0  
fill ~105 ~2 ~33 ~133 ~2 ~33 dirt 0  
fill ~105 ~2 ~34 ~133 ~2 ~34 dirt 0  
fill ~105 ~2 ~35 ~133 ~2 ~35 dirt 0  
fill ~105 ~2 ~80 ~147 ~2 ~80 dirt 0 
setblock ~123 ~2 ~60 bedrock 0  
fill ~125 ~2 ~60 ~155 ~2 ~60 dirt 0  
fill ~125 ~2 ~61 ~154 ~2 ~61 dirt 0  
fill ~128 ~2 ~76 ~128 ~4 ~76 planks 1  
fill ~129 ~2 ~76 ~145 ~2 ~76 dirt 0  
fill ~130 ~2 ~31 ~132 ~2 ~31 dirt 0  
fill ~131 ~2 ~41 ~139 ~2 ~41 dirt 0  
fill ~2 ~3 ~26 ~9 ~3 ~26 dirt 0  
fill ~3 ~3 ~27 ~18 ~3 ~27 stonebrick 0  
fill ~3 ~3 ~28 ~18 ~3 ~28 stonebrick 0  
fill ~3 ~3 ~29 ~18 ~3 ~29 stonebrick 0  
fill ~3 ~3 ~30 ~18 ~3 ~30 stonebrick 0  
fill ~3 ~3 ~31 ~18 ~3 ~31 stonebrick 0  
fill ~3 ~3 ~32 ~18 ~3 ~32 stonebrick 0  
fill ~3 ~3 ~33 ~18 ~3 ~33 stonebrick 0  
fill ~3 ~3 ~34 ~18 ~3 ~34 stonebrick 0  
fill ~3 ~3 ~35 ~18 ~3 ~35 stonebrick 0  
fill ~3 ~3 ~36 ~18 ~3 ~36 stonebrick 0  
fill ~3 ~3 ~37 ~18 ~3 ~37 stonebrick 0  
fill ~3 ~3 ~38 ~18 ~3 ~38 stonebrick 0  
fill ~3 ~3 ~39 ~18 ~3 ~39 stonebrick 0  
fill ~3 ~3 ~40 ~18 ~3 ~40 stonebrick 0  
fill ~3 ~3 ~41 ~18 ~3 ~41 stonebrick 0  
fill ~3 ~3 ~42 ~18 ~3 ~42 stonebrick 0  
fill ~3 ~3 ~43 ~18 ~3 ~43 stonebrick 0  
fill ~3 ~3 ~44 ~18 ~3 ~44 stonebrick 0  
fill ~3 ~3 ~45 ~18 ~3 ~45 stonebrick 0  
fill ~3 ~3 ~46 ~18 ~3 ~46 stonebrick 0  
fill ~3 ~3 ~47 ~18 ~3 ~47 stonebrick 0  
fill ~3 ~3 ~48 ~16 ~3 ~48 dirt 0  
fill ~15 ~3 ~16 ~16 ~3 ~16 bedrock 0  
fill ~15 ~3 ~17 ~17 ~3 ~17 log 1  
fill ~15 ~3 ~19 ~15 ~3 ~23 glass 0  
fill ~15 ~3 ~50 ~16 ~3 ~50 dirt 0  
fill ~15 ~3 ~51 ~15 ~3 ~54 dirt 0  
fill ~16 ~3 ~19 ~17 ~3 ~19 fence 0  
fill ~16 ~3 ~20 ~16 ~3 ~23 fence 0  
fill ~16 ~3 ~24 ~16 ~3 ~25 glass 0 
setblock ~16 ~3 ~49 dirt 0  
fill ~16 ~3 ~52 ~16 ~1 ~52 dirt 0  
fill ~16 ~3 ~53 ~16 ~1 ~53 dirt 0  
fill ~16 ~3 ~55 ~16 ~1 ~55 dirt 0  
fill ~16 ~3 ~56 ~16 ~1 ~56 dirt 0  
fill ~16 ~3 ~57 ~20 ~3 ~57 dirt 0  
fill ~16 ~3 ~102 ~17 ~3 ~102 dirt 0  
fill ~17 ~3 ~15 ~18 ~3 ~15 bedrock 0  
fill ~17 ~3 ~16 ~18 ~3 ~16 log 1  
fill ~17 ~3 ~18 ~18 ~3 ~18 fence 0  
fill ~17 ~3 ~23 ~17 ~3 ~25 fence 0 
setblock ~17 ~3 ~26 glass 0  
fill ~17 ~3 ~48 ~17 ~11 ~48 log 1  
fill ~17 ~3 ~49 ~17 ~10 ~49 log 1  
fill ~17 ~3 ~52 ~18 ~3 ~52 log 1  
fill ~17 ~3 ~53 ~17 ~6 ~53 log 1  
fill ~17 ~3 ~55 ~17 ~9 ~55 log 1  
fill ~17 ~3 ~56 ~19 ~3 ~56 bedrock 0  
fill ~17 ~3 ~101 ~22 ~3 ~101 dirt 0  
fill ~17 ~3 ~104 ~20 ~3 ~104 wool 14  
fill ~17 ~3 ~105 ~17 ~3 ~106 wool 14  
fill ~17 ~3 ~107 ~17 ~4 ~107 netherrack 0  
fill ~17 ~3 ~108 ~19 ~3 ~108 wool 14  
fill ~17 ~3 ~109 ~20 ~3 ~109 wool 14  
fill ~17 ~3 ~110 ~19 ~3 ~110 wool 14  
fill ~17 ~3 ~111 ~19 ~3 ~111 netherrack 0  
fill ~17 ~3 ~112 ~20 ~3 ~112 wool 14  
fill ~18 ~3 ~17 ~21 ~3 ~17 fence 0  
fill ~18 ~3 ~25 ~18 ~4 ~25 fence 0  
fill ~18 ~3 ~26 ~18 ~4 ~26 fence 0  
fill ~18 ~3 ~50 ~18 ~8 ~50 log 1  
fill ~18 ~3 ~53 ~18 ~4 ~53 fence 0  
fill ~18 ~3 ~54 ~18 ~8 ~54 log 1  
fill ~18 ~3 ~100 ~23 ~3 ~100 dirt 0  
fill ~18 ~3 ~102 ~26 ~3 ~102 grass 0  
fill ~18 ~3 ~106 ~18 ~3 ~110 wool 14  
fill ~19 ~3 ~14 ~20 ~3 ~14 bedrock 0  
fill ~19 ~3 ~15 ~21 ~3 ~15 log 1  
fill ~19 ~3 ~28 ~19 ~3 ~34 fence 0  
fill ~19 ~3 ~35 ~19 ~3 ~38 stone_slab 2  
fill ~19 ~3 ~55 ~19 ~9 ~55 log 1  
fill ~19 ~3 ~78 ~20 ~3 ~78 dirt 0  
fill ~19 ~3 ~105 ~19 ~4 ~105 wool 14  
fill ~19 ~3 ~106 ~19 ~4 ~106 netherrack 0  
fill ~19 ~3 ~107 ~19 ~5 ~107 wool 14 
setblock ~20 ~3 ~28 stone 0  
fill ~20 ~3 ~55 ~20 ~4 ~55 fence 0  
fill ~20 ~3 ~56 ~20 ~8 ~56 log 1  
fill ~20 ~3 ~66 ~21 ~3 ~66 dirt 0  
fill ~20 ~3 ~77 ~21 ~3 ~77 dirt 0  
fill ~20 ~3 ~79 ~21 ~3 ~79 dirt 0  
fill ~20 ~3 ~98 ~21 ~3 ~98 dirt 0  
fill ~20 ~3 ~106 ~20 ~4 ~106 wool 14  
fill ~20 ~3 ~107 ~20 ~3 ~108 netherrack 0  
fill ~20 ~3 ~110 ~20 ~4 ~110 netherrack 0  
fill ~21 ~3 ~13 ~24 ~3 ~13 bedrock 0  
fill ~21 ~3 ~14 ~25 ~3 ~14 log 1  
fill ~21 ~3 ~16 ~22 ~3 ~16 fence 0 
setblock ~21 ~3 ~27 stone 0  
fill ~21 ~3 ~55 ~22 ~3 ~55 log 1  
fill ~21 ~3 ~56 ~22 ~3 ~56 bedrock 0  
fill ~21 ~3 ~64 ~22 ~3 ~64 dirt 0  
fill ~21 ~3 ~65 ~22 ~3 ~65 dirt 0  
fill ~21 ~3 ~67 ~22 ~3 ~67 dirt 0  
fill ~21 ~3 ~76 ~22 ~3 ~76 dirt 0  
fill ~21 ~3 ~78 ~33 ~3 ~78 grass 0  
fill ~21 ~3 ~80 ~22 ~3 ~80 dirt 0  
fill ~21 ~3 ~97 ~22 ~3 ~97 dirt 0  
fill ~21 ~3 ~99 ~22 ~3 ~99 dirt 0  
fill ~21 ~3 ~124 ~22 ~3 ~124 bedrock 0  
fill ~22 ~3 ~15 ~26 ~3 ~15 fence 0  
fill ~22 ~3 ~57 ~26 ~3 ~57 dirt 0  
fill ~22 ~3 ~63 ~23 ~3 ~63 dirt 0  
fill ~22 ~3 ~66 ~48 ~3 ~66 grass 0  
fill ~22 ~3 ~68 ~23 ~3 ~68 dirt 0  
fill ~22 ~3 ~75 ~23 ~3 ~75 dirt 0  
fill ~22 ~3 ~77 ~34 ~3 ~77 grass 0  
fill ~22 ~3 ~79 ~33 ~3 ~79 grass 0  
fill ~22 ~3 ~81 ~23 ~3 ~81 dirt 0  
fill ~22 ~3 ~96 ~23 ~3 ~96 dirt 0  
fill ~22 ~3 ~98 ~26 ~3 ~98 grass 0  
fill ~23 ~3 ~26 ~25 ~3 ~26 stone 0  
fill ~23 ~3 ~30 ~24 ~3 ~30 stone 0  
fill ~23 ~3 ~31 ~23 ~3 ~32 stone 0 
setblock ~23 ~3 ~33 cobblestone 0  
fill ~23 ~3 ~34 ~24 ~3 ~34 stone 0  
fill ~23 ~3 ~35 ~23 ~8 ~35 fence 0  
fill ~23 ~3 ~55 ~23 ~4 ~55 fence 0  
fill ~23 ~3 ~56 ~23 ~7 ~56 log 1  
fill ~23 ~3 ~58 ~26 ~3 ~58 dirt 0  
fill ~23 ~3 ~60 ~24 ~3 ~60 dirt 0  
fill ~23 ~3 ~61 ~24 ~3 ~61 dirt 0  
fill ~23 ~3 ~62 ~24 ~3 ~62 dirt 0  
fill ~23 ~3 ~64 ~38 ~3 ~64 grass 0  
fill ~23 ~3 ~65 ~31 ~3 ~65 grass 0  
fill ~23 ~3 ~67 ~48 ~3 ~67 grass 0  
fill ~23 ~3 ~69 ~24 ~3 ~69 dirt 0  
fill ~23 ~3 ~72 ~24 ~3 ~72 dirt 0  
fill ~23 ~3 ~74 ~24 ~3 ~74 dirt 0  
fill ~23 ~3 ~76 ~35 ~3 ~76 grass 0  
fill ~23 ~3 ~80 ~32 ~3 ~80 grass 0  
fill ~23 ~3 ~82 ~24 ~3 ~82 dirt 0  
fill ~23 ~3 ~93 ~24 ~3 ~93 dirt 0  
fill ~23 ~3 ~95 ~24 ~3 ~95 dirt 0  
fill ~23 ~3 ~97 ~26 ~3 ~97 grass 0  
fill ~23 ~3 ~99 ~26 ~3 ~99 grass 0  
fill ~23 ~3 ~101 ~26 ~3 ~101 grass 0  
fill ~23 ~3 ~124 ~25 ~3 ~124 log 1  
fill ~23 ~3 ~125 ~25 ~3 ~125 dirt 0  
fill ~24 ~3 ~12 ~47 ~3 ~12 dirt 0  
fill ~24 ~3 ~29 ~26 ~3 ~29 stone 0  
fill ~24 ~3 ~35 ~26 ~3 ~35 stone 0 
setblock ~24 ~3 ~40 stone 0  
fill ~24 ~3 ~55 ~24 ~9 ~55 log 1  
fill ~24 ~3 ~59 ~25 ~3 ~59 dirt 0  
fill ~24 ~3 ~63 ~36 ~3 ~63 grass 0  
fill ~24 ~3 ~68 ~42 ~3 ~68 grass 0  
fill ~24 ~3 ~70 ~25 ~3 ~70 dirt 0  
fill ~24 ~3 ~71 ~25 ~3 ~71 dirt 0  
fill ~24 ~3 ~73 ~25 ~3 ~73 dirt 0  
fill ~24 ~3 ~75 ~37 ~3 ~75 grass 0  
fill ~24 ~3 ~81 ~30 ~3 ~81 grass 0  
fill ~24 ~3 ~83 ~25 ~3 ~83 dirt 0  
fill ~24 ~3 ~92 ~25 ~3 ~92 dirt 0  
fill ~24 ~3 ~94 ~25 ~3 ~94 dirt 0  
fill ~24 ~3 ~96 ~26 ~3 ~96 grass 0  
fill ~24 ~3 ~100 ~26 ~3 ~100 grass 0  
fill ~25 ~3 ~13 ~30 ~3 ~13 log 1 
setblock ~25 ~3 ~41 stone 0  
fill ~25 ~3 ~55 ~26 ~3 ~55 fence 0  
fill ~25 ~3 ~56 ~33 ~3 ~56 log 1  
fill ~25 ~3 ~60 ~45 ~3 ~60 grass 0  
fill ~25 ~3 ~61 ~35 ~3 ~61 grass 0  
fill ~25 ~3 ~62 ~36 ~3 ~62 grass 0  
fill ~25 ~3 ~69 ~41 ~3 ~69 grass 0  
fill ~25 ~3 ~72 ~48 ~3 ~72 grass 0  
fill ~25 ~3 ~74 ~37 ~3 ~74 grass 0  
fill ~25 ~3 ~82 ~29 ~3 ~82 grass 0  
fill ~25 ~3 ~84 ~26 ~3 ~84 dirt 0  
fill ~25 ~3 ~91 ~26 ~3 ~91 dirt 0  
fill ~25 ~3 ~93 ~26 ~3 ~93 grass 0  
fill ~25 ~3 ~95 ~26 ~3 ~95 grass 0  
fill ~26 ~3 ~14 ~29 ~3 ~14 fence 0 
setblock ~26 ~3 ~36 stone 0 
setblock ~26 ~3 ~42 stone 0  
fill ~26 ~3 ~43 ~26 ~4 ~43 fence 0  
fill ~26 ~3 ~44 ~26 ~4 ~44 fence 0  
fill ~26 ~3 ~45 ~26 ~4 ~45 fence 0  
fill ~26 ~3 ~46 ~26 ~4 ~46 fence 0  
fill ~26 ~3 ~47 ~26 ~4 ~47 fence 0  
fill ~26 ~3 ~48 ~26 ~3 ~51 fence 0  
fill ~26 ~3 ~59 ~48 ~3 ~59 grass 0  
fill ~26 ~3 ~70 ~40 ~3 ~70 grass 0  
fill ~26 ~3 ~71 ~39 ~3 ~71 grass 0  
fill ~26 ~3 ~73 ~37 ~3 ~73 grass 0  
fill ~26 ~3 ~83 ~29 ~3 ~83 grass 0  
fill ~26 ~3 ~85 ~27 ~3 ~85 dirt 0 
setblock ~26 ~3 ~92 grass 0 
setblock ~26 ~3 ~94 grass 0  
fill ~27 ~3 ~37 ~27 ~4 ~37 fence 0  
fill ~27 ~3 ~55 ~27 ~9 ~55 log 1  
fill ~27 ~3 ~57 ~29 ~3 ~57 grass 0  
fill ~27 ~3 ~58 ~48 ~3 ~58 grass 0  
fill ~27 ~3 ~84 ~48 ~3 ~84 grass 0  
fill ~27 ~3 ~86 ~28 ~3 ~86 dirt 0  
fill ~27 ~3 ~87 ~27 ~5 ~87 bedrock 0  
fill ~27 ~3 ~91 ~28 ~3 ~91 log 1  
fill ~27 ~3 ~98 ~28 ~3 ~98 fence 0  
fill ~27 ~3 ~102 ~27 ~4 ~102 fence 0  
fill ~27 ~3 ~103 ~27 ~4 ~103 fence 0  
fill ~27 ~3 ~104 ~27 ~3 ~106 fence 0  
fill ~27 ~3 ~122 ~29 ~3 ~122 bedrock 0  
fill ~28 ~3 ~26 ~31 ~3 ~26 stone 0  
fill ~28 ~3 ~38 ~28 ~4 ~38 stone 0  
fill ~28 ~3 ~55 ~33 ~3 ~55 fence 0  
fill ~28 ~3 ~85 ~48 ~3 ~85 grass 0  
fill ~28 ~3 ~87 ~28 ~7 ~87 log 1  
fill ~28 ~3 ~97 ~30 ~3 ~97 fence 0  
fill ~28 ~3 ~106 ~28 ~3 ~107 fence 0  
fill ~29 ~3 ~15 ~30 ~3 ~15 fence 0  
fill ~29 ~3 ~29 ~32 ~3 ~29 stone 0  
fill ~29 ~3 ~39 ~29 ~4 ~39 fence 0  
fill ~29 ~3 ~48 ~29 ~4 ~48 fence 0  
fill ~29 ~3 ~86 ~49 ~3 ~86 grass 0  
fill ~29 ~3 ~107 ~29 ~3 ~108 fence 0  
fill ~29 ~3 ~121 ~32 ~3 ~121 bedrock 0  
fill ~29 ~3 ~138 ~30 ~3 ~138 dirt 0  
fill ~29 ~3 ~139 ~30 ~3 ~139 dirt 0  
fill ~29 ~3 ~140 ~30 ~3 ~140 dirt 0  
fill ~29 ~3 ~141 ~30 ~3 ~141 dirt 0  
fill ~30 ~3 ~16 ~31 ~3 ~16 fence 0  
fill ~30 ~3 ~44 ~30 ~4 ~44 fence 0 
setblock ~30 ~3 ~57 dirt 0  
fill ~30 ~3 ~82 ~30 ~3 ~83 dirt 0  
fill ~30 ~3 ~95 ~31 ~3 ~95 fence 0  
fill ~30 ~3 ~96 ~30 ~3 ~95 fence 0  
fill ~30 ~3 ~108 ~30 ~3 ~109 fence 0  
fill ~30 ~3 ~118 ~31 ~3 ~118 log 1  
fill ~30 ~3 ~134 ~40 ~3 ~134 dirt 0  
fill ~30 ~3 ~135 ~41 ~3 ~135 dirt 0  
fill ~30 ~3 ~136 ~42 ~3 ~136 dirt 0  
fill ~30 ~3 ~137 ~43 ~3 ~137 dirt 0  
fill ~30 ~3 ~142 ~31 ~3 ~142 dirt 0  
fill ~31 ~3 ~17 ~33 ~3 ~17 fence 0 
setblock ~31 ~3 ~35 waterlily 0 
setblock ~31 ~3 ~57 grass 0  
fill ~31 ~3 ~81 ~32 ~3 ~81 dirt 0  
fill ~31 ~3 ~82 ~48 ~3 ~82 grass 0  
fill ~31 ~3 ~83 ~48 ~3 ~83 grass 0  
fill ~31 ~3 ~93 ~32 ~3 ~93 fence 0  
fill ~31 ~3 ~94 ~31 ~3 ~93 fence 0  
fill ~31 ~3 ~109 ~31 ~3 ~110 fence 0  
fill ~31 ~3 ~133 ~39 ~3 ~133 dirt 0  
fill ~31 ~3 ~138 ~31 ~3 ~141 grass 0  
fill ~31 ~3 ~143 ~32 ~3 ~143 dirt 0  
fill ~31 ~3 ~144 ~32 ~3 ~144 dirt 0  
fill ~32 ~3 ~41 ~33 ~3 ~41 fence 0 
setblock ~32 ~3 ~57 dirt 0  
fill ~32 ~3 ~65 ~49 ~3 ~65 dirt 0  
fill ~32 ~3 ~92 ~33 ~3 ~92 fence 0  
fill ~32 ~3 ~95 ~33 ~3 ~95 planks 0  
fill ~32 ~3 ~96 ~32 ~4 ~96 planks 0  
fill ~32 ~3 ~97 ~32 ~4 ~97 planks 0  
fill ~32 ~3 ~98 ~32 ~4 ~98 planks 0  
fill ~32 ~3 ~99 ~32 ~4 ~99 planks 0  
fill ~32 ~3 ~100 ~33 ~3 ~100 planks 0  
fill ~32 ~3 ~110 ~32 ~3 ~111 fence 0  
fill ~32 ~3 ~115 ~33 ~3 ~115 fence 0  
fill ~32 ~3 ~116 ~32 ~3 ~118 fence 0  
fill ~32 ~3 ~132 ~38 ~3 ~132 dirt 0  
fill ~32 ~3 ~138 ~44 ~3 ~138 dirt 0  
fill ~32 ~3 ~139 ~48 ~3 ~139 dirt 0  
fill ~32 ~3 ~140 ~49 ~3 ~140 grass 0  
fill ~32 ~3 ~141 ~48 ~3 ~141 grass 0  
fill ~32 ~3 ~142 ~47 ~3 ~142 grass 0  
fill ~32 ~3 ~145 ~34 ~3 ~145 dirt 0  
fill ~33 ~3 ~15 ~34 ~3 ~15 bedrock 0  
fill ~33 ~3 ~16 ~34 ~3 ~16 log 1  
fill ~33 ~3 ~18 ~35 ~3 ~18 fence 0  
fill ~33 ~3 ~47 ~33 ~4 ~47 fence 0  
fill ~33 ~3 ~57 ~34 ~3 ~57 grass 0 
setblock ~33 ~3 ~80 dirt 0  
fill ~33 ~3 ~81 ~48 ~3 ~81 grass 0  
fill ~33 ~3 ~91 ~34 ~3 ~91 fence 0  
fill ~33 ~3 ~111 ~33 ~3 ~112 fence 0  
fill ~33 ~3 ~114 ~34 ~3 ~114 fence 0  
fill ~33 ~3 ~118 ~33 ~3 ~119 fence 0  
fill ~33 ~3 ~121 ~34 ~3 ~121 dirt 0  
fill ~33 ~3 ~122 ~35 ~3 ~122 dirt 0  
fill ~33 ~3 ~143 ~46 ~3 ~143 grass 0  
fill ~33 ~3 ~144 ~45 ~3 ~144 grass 0  
fill ~33 ~3 ~146 ~42 ~3 ~146 dirt 0 
setblock ~34 ~3 ~26 stone 0  
fill ~34 ~3 ~39 ~37 ~3 ~39 iron_bars 0  
fill ~34 ~3 ~40 ~34 ~3 ~42 iron_bars 0  
fill ~34 ~3 ~50 ~35 ~3 ~50 stonebrick 3  
fill ~34 ~3 ~54 ~38 ~3 ~54 stonebrick 3  
fill ~34 ~3 ~55 ~34 ~1 ~55 dirt 0  
fill ~34 ~3 ~56 ~34 ~3 ~55 dirt 0  
fill ~34 ~3 ~78 ~34 ~3 ~79 dirt 0  
fill ~34 ~3 ~80 ~48 ~3 ~80 grass 0  
fill ~34 ~3 ~89 ~35 ~3 ~89 fence 0  
fill ~34 ~3 ~90 ~34 ~3 ~89 fence 0  
fill ~34 ~3 ~112 ~34 ~3 ~114 fence 0  
fill ~34 ~3 ~119 ~35 ~3 ~119 fence 0  
fill ~34 ~3 ~131 ~35 ~3 ~131 dirt 0  
fill ~35 ~3 ~15 ~36 ~3 ~15 log 1  
fill ~35 ~3 ~19 ~37 ~3 ~19 fence 0  
fill ~35 ~3 ~29 ~36 ~3 ~29 stone 0  
fill ~35 ~3 ~40 ~36 ~3 ~40 leaves 13  
fill ~35 ~3 ~41 ~35 ~3 ~40 leaves 13  
fill ~35 ~3 ~42 ~35 ~3 ~44 iron_bars 0  
fill ~35 ~3 ~55 ~37 ~3 ~55 grass 0  
fill ~35 ~3 ~56 ~36 ~3 ~56 grass 0 
setblock ~35 ~3 ~57 dirt 0 
setblock ~35 ~3 ~77 dirt 0  
fill ~35 ~3 ~78 ~48 ~3 ~78 grass 0  
fill ~35 ~3 ~79 ~48 ~3 ~79 grass 0  
fill ~35 ~3 ~88 ~36 ~3 ~88 fence 0  
fill ~35 ~3 ~95 ~36 ~3 ~95 planks 0  
fill ~35 ~3 ~100 ~36 ~3 ~100 planks 0  
fill ~35 ~3 ~120 ~36 ~3 ~120 fence 0  
fill ~35 ~3 ~121 ~38 ~3 ~121 grass 0  
fill ~35 ~3 ~123 ~36 ~3 ~123 dirt 0  
fill ~35 ~3 ~130 ~36 ~3 ~130 dirt 0  
fill ~35 ~3 ~145 ~39 ~3 ~145 grass 0  
fill ~35 ~3 ~147 ~39 ~3 ~147 dirt 0  
fill ~36 ~3 ~13 ~37 ~3 ~13 bedrock 0  
fill ~36 ~3 ~14 ~37 ~3 ~14 log 1  
fill ~36 ~3 ~20 ~37 ~3 ~20 waterlily 0  
fill ~36 ~3 ~26 ~42 ~3 ~26 stone 0  
fill ~36 ~3 ~41 ~36 ~4 ~41 log 1  
fill ~36 ~3 ~42 ~36 ~3 ~43 tallgrass 1  
fill ~36 ~3 ~44 ~36 ~3 ~45 iron_bars 0  
fill ~36 ~3 ~57 ~40 ~3 ~57 grass 0 
setblock ~36 ~3 ~61 dirt 0 
setblock ~36 ~3 ~76 dirt 0  
fill ~36 ~3 ~77 ~48 ~3 ~77 grass 0  
fill ~36 ~3 ~87 ~49 ~3 ~87 fence 0  
fill ~36 ~3 ~96 ~36 ~4 ~96 planks 0  
fill ~36 ~3 ~97 ~36 ~4 ~97 planks 0  
fill ~36 ~3 ~98 ~36 ~4 ~98 planks 0  
fill ~36 ~3 ~99 ~36 ~4 ~99 planks 0  
fill ~36 ~3 ~122 ~38 ~3 ~122 grass 0  
fill ~36 ~3 ~124 ~37 ~3 ~124 dirt 0  
fill ~36 ~3 ~125 ~37 ~3 ~125 dirt 0  
fill ~36 ~3 ~129 ~37 ~3 ~129 dirt 0  
fill ~36 ~3 ~131 ~37 ~3 ~131 grass 0  
fill ~37 ~3 ~17 ~40 ~3 ~17 fence 0  
fill ~37 ~3 ~18 ~37 ~3 ~17 fence 0 
setblock ~37 ~3 ~21 waterlily 0 
setblock ~37 ~3 ~41 tallgrass 1  
fill ~37 ~3 ~42 ~37 ~6 ~42 log 1  
fill ~37 ~3 ~43 ~37 ~4 ~43 leaves 13  
fill ~37 ~3 ~44 ~37 ~4 ~44 leaves 13  
fill ~37 ~3 ~45 ~38 ~3 ~45 iron_bars 0  
fill ~37 ~3 ~46 ~37 ~4 ~46 iron_bars 0  
fill ~37 ~3 ~56 ~39 ~3 ~56 dirt 0  
fill ~37 ~3 ~61 ~48 ~3 ~61 grass 0  
fill ~37 ~3 ~62 ~38 ~3 ~62 dirt 0  
fill ~37 ~3 ~63 ~37 ~3 ~62 dirt 0  
fill ~37 ~3 ~76 ~48 ~3 ~76 grass 0  
fill ~37 ~3 ~123 ~43 ~3 ~123 grass 0  
fill ~37 ~3 ~126 ~38 ~3 ~126 dirt 0  
fill ~37 ~3 ~128 ~38 ~3 ~128 dirt 0  
fill ~37 ~3 ~130 ~38 ~3 ~130 grass 0  
fill ~38 ~3 ~13 ~49 ~3 ~13 log 1  
fill ~38 ~3 ~29 ~39 ~3 ~29 stone 0  
fill ~38 ~3 ~38 ~39 ~3 ~38 iron_bars 0 
setblock ~38 ~3 ~39 leaves 13  
fill ~38 ~3 ~40 ~38 ~5 ~40 log 1  
fill ~38 ~3 ~41 ~38 ~6 ~41 log 1  
fill ~38 ~3 ~42 ~38 ~3 ~43 tallgrass 1  
fill ~38 ~3 ~44 ~39 ~3 ~44 iron_bars 0  
fill ~38 ~3 ~46 ~38 ~4 ~46 planks 1  
fill ~38 ~3 ~47 ~38 ~4 ~47 fence 0  
fill ~38 ~3 ~48 ~38 ~4 ~48 fence 0  
fill ~38 ~3 ~49 ~38 ~4 ~49 fence 0  
fill ~38 ~3 ~50 ~38 ~6 ~50 stonebrick 3 
setblock ~38 ~3 ~55 dirt 0 
setblock ~38 ~3 ~63 grass 0  
fill ~38 ~3 ~73 ~38 ~3 ~75 dirt 0  
fill ~38 ~3 ~124 ~44 ~3 ~124 grass 0  
fill ~38 ~3 ~125 ~44 ~3 ~125 grass 0  
fill ~38 ~3 ~127 ~39 ~3 ~127 dirt 0  
fill ~38 ~3 ~129 ~39 ~3 ~129 grass 0  
fill ~38 ~3 ~131 ~39 ~3 ~131 dirt 0  
fill ~39 ~3 ~39 ~39 ~3 ~44 iron_bars 0  
fill ~39 ~3 ~47 ~39 ~4 ~47 planks 1  
fill ~39 ~3 ~50 ~39 ~8 ~50 fence 0  
fill ~39 ~3 ~54 ~44 ~3 ~54 fence 0  
fill ~39 ~3 ~62 ~48 ~3 ~62 grass 0  
fill ~39 ~3 ~63 ~39 ~3 ~65 dirt 0  
fill ~39 ~3 ~73 ~48 ~3 ~73 grass 0  
fill ~39 ~3 ~74 ~48 ~3 ~74 grass 0  
fill ~39 ~3 ~75 ~48 ~3 ~75 grass 0  
fill ~39 ~3 ~126 ~42 ~3 ~126 grass 0  
fill ~39 ~3 ~128 ~40 ~3 ~128 grass 0  
fill ~39 ~3 ~130 ~40 ~3 ~130 dirt 0  
fill ~39 ~3 ~132 ~54 ~3 ~132 grass 0  
fill ~40 ~3 ~14 ~44 ~3 ~14 fence 0  
fill ~40 ~3 ~15 ~40 ~3 ~17 fence 0 
setblock ~40 ~3 ~27 torch 3  
fill ~40 ~3 ~29 ~41 ~3 ~29 planks 0  
fill ~40 ~3 ~45 ~41 ~3 ~45 planks 1  
fill ~40 ~3 ~46 ~40 ~4 ~46 planks 1  
fill ~40 ~3 ~56 ~40 ~5 ~56 log 1  
fill ~40 ~3 ~63 ~48 ~3 ~63 grass 0 
setblock ~40 ~3 ~64 dirt 0 
setblock ~40 ~3 ~71 dirt 0  
fill ~40 ~3 ~97 ~41 ~3 ~97 planks 0  
fill ~40 ~3 ~127 ~41 ~3 ~127 grass 0  
fill ~40 ~3 ~129 ~41 ~3 ~129 dirt 0  
fill ~40 ~3 ~131 ~53 ~3 ~131 grass 0  
fill ~40 ~3 ~133 ~53 ~3 ~133 grass 0  
fill ~40 ~3 ~145 ~41 ~3 ~145 dirt 0 
setblock ~41 ~3 ~44 waterlily 0  
fill ~41 ~3 ~57 ~42 ~3 ~57 dirt 0  
fill ~41 ~3 ~64 ~48 ~3 ~64 grass 0 
setblock ~41 ~3 ~70 dirt 0  
fill ~41 ~3 ~71 ~48 ~3 ~71 grass 0  
fill ~41 ~3 ~99 ~42 ~3 ~99 planks 0  
fill ~41 ~3 ~114 ~41 ~4 ~114 planks 0  
fill ~41 ~3 ~115 ~41 ~5 ~115 planks 0  
fill ~41 ~3 ~116 ~41 ~3 ~120 dirt 0  
fill ~41 ~3 ~128 ~42 ~3 ~128 dirt 0  
fill ~41 ~3 ~130 ~52 ~3 ~130 grass 0  
fill ~41 ~3 ~134 ~52 ~3 ~134 grass 0 
setblock ~42 ~3 ~29 stone 0  
fill ~42 ~3 ~39 ~43 ~3 ~39 waterlily 0  
fill ~42 ~3 ~56 ~43 ~3 ~56 log 1 
setblock ~42 ~3 ~69 dirt 0  
fill ~42 ~3 ~70 ~48 ~3 ~70 grass 0  
fill ~42 ~3 ~115 ~43 ~3 ~115 oak_stairs 2  
fill ~42 ~3 ~116 ~45 ~3 ~116 mycelium 0  
fill ~42 ~3 ~117 ~53 ~3 ~117 mycelium 0  
fill ~42 ~3 ~118 ~53 ~3 ~118 mycelium 0  
fill ~42 ~3 ~119 ~44 ~3 ~119 mycelium 0  
fill ~42 ~3 ~120 ~47 ~3 ~120 dirt 0  
fill ~42 ~3 ~121 ~42 ~3 ~122 oak_stairs 0  
fill ~42 ~3 ~127 ~43 ~3 ~127 dirt 0  
fill ~42 ~3 ~129 ~51 ~3 ~129 grass 0  
fill ~42 ~3 ~135 ~51 ~3 ~135 grass 0  
fill ~42 ~3 ~145 ~44 ~3 ~145 grass 0  
fill ~42 ~3 ~147 ~44 ~3 ~147 dirt 0 
setblock ~43 ~3 ~26 planks 0  
fill ~43 ~3 ~57 ~45 ~3 ~57 grass 0 
setblock ~43 ~3 ~68 dirt 0  
fill ~43 ~3 ~69 ~48 ~3 ~69 grass 0  
fill ~43 ~3 ~121 ~43 ~3 ~125 grass 0  
fill ~43 ~3 ~126 ~49 ~3 ~126 dirt 0  
fill ~43 ~3 ~128 ~50 ~3 ~128 grass 0  
fill ~43 ~3 ~136 ~50 ~3 ~136 grass 0 
setblock ~43 ~3 ~146 grass 0  
fill ~44 ~3 ~15 ~45 ~3 ~15 fence 0  
fill ~44 ~3 ~26 ~45 ~3 ~26 stone 0 
setblock ~44 ~3 ~29 stone 0 
setblock ~44 ~3 ~56 dirt 0  
fill ~44 ~3 ~68 ~48 ~3 ~68 grass 0  
fill ~44 ~3 ~97 ~45 ~3 ~97 planks 0  
fill ~44 ~3 ~110 ~45 ~3 ~110 planks 0  
fill ~44 ~3 ~111 ~45 ~3 ~111 planks 0  
fill ~44 ~3 ~121 ~48 ~3 ~121 dirt 0  
fill ~44 ~3 ~122 ~48 ~3 ~122 dirt 0  
fill ~44 ~3 ~123 ~45 ~3 ~123 dirt 0  
fill ~44 ~3 ~127 ~49 ~3 ~127 grass 0  
fill ~44 ~3 ~137 ~49 ~3 ~137 grass 0  
fill ~44 ~3 ~146 ~45 ~3 ~146 dirt 0  
fill ~45 ~3 ~16 ~48 ~3 ~16 fence 0  
fill ~45 ~3 ~22 ~46 ~3 ~22 fence 0  
fill ~45 ~3 ~23 ~45 ~4 ~23 fence 0  
fill ~45 ~3 ~24 ~48 ~3 ~24 stonebrick 0  
fill ~45 ~3 ~25 ~45 ~6 ~25 stonebrick 0 
setblock ~45 ~3 ~29 planks 0  
fill ~45 ~3 ~30 ~45 ~3 ~31 stonebrick 0  
fill ~45 ~3 ~54 ~45 ~4 ~54 iron_bars 0  
fill ~45 ~3 ~55 ~45 ~4 ~55 planks 0  
fill ~45 ~3 ~56 ~48 ~3 ~56 grass 0 
setblock ~45 ~3 ~95 leaves 5  
fill ~45 ~3 ~101 ~46 ~3 ~101 planks 0  
fill ~45 ~3 ~109 ~46 ~3 ~109 planks 0  
fill ~45 ~3 ~114 ~45 ~3 ~115 grass 0  
fill ~45 ~3 ~119 ~46 ~3 ~119 dirt 0  
fill ~45 ~3 ~124 ~45 ~3 ~126 dirt 0  
fill ~45 ~3 ~138 ~48 ~3 ~138 grass 0  
fill ~45 ~3 ~145 ~46 ~3 ~145 dirt 0  
fill ~46 ~3 ~10 ~52 ~3 ~10 dirt 0  
fill ~46 ~3 ~11 ~53 ~3 ~11 dirt 0  
fill ~46 ~3 ~21 ~47 ~3 ~21 fence 0 
setblock ~46 ~3 ~57 dirt 0 
setblock ~46 ~3 ~60 dirt 0  
fill ~46 ~3 ~114 ~48 ~3 ~114 dirt 0  
fill ~46 ~3 ~115 ~48 ~3 ~115 grass 0  
fill ~46 ~3 ~116 ~48 ~3 ~116 grass 0  
fill ~46 ~3 ~123 ~46 ~3 ~125 grass 0  
fill ~46 ~3 ~144 ~47 ~3 ~144 dirt 0  
fill ~47 ~3 ~14 ~49 ~3 ~14 log 1  
fill ~47 ~3 ~19 ~48 ~3 ~19 fence 0  
fill ~47 ~3 ~20 ~47 ~3 ~19 fence 0  
fill ~47 ~3 ~54 ~48 ~3 ~54 planks 1  
fill ~47 ~3 ~55 ~48 ~3 ~55 grass 0  
fill ~47 ~3 ~57 ~48 ~3 ~57 grass 0  
fill ~47 ~3 ~60 ~48 ~3 ~60 grass 0  
fill ~47 ~3 ~95 ~47 ~5 ~95 leaves 13  
fill ~47 ~3 ~119 ~53 ~3 ~119 mycelium 0  
fill ~47 ~3 ~123 ~48 ~3 ~123 dirt 0  
fill ~47 ~3 ~124 ~47 ~3 ~126 dirt 0  
fill ~47 ~3 ~143 ~48 ~3 ~143 dirt 0  
fill ~48 ~3 ~12 ~51 ~3 ~12 grass 0  
fill ~48 ~3 ~15 ~49 ~3 ~15 log 1  
fill ~48 ~3 ~17 ~48 ~3 ~19 fence 0  
fill ~48 ~3 ~25 ~48 ~3 ~31 stonebrick 0  
fill ~48 ~3 ~32 ~49 ~3 ~32 fence 0  
fill ~48 ~3 ~112 ~49 ~3 ~112 fence 0  
fill ~48 ~3 ~120 ~53 ~3 ~120 mycelium 0  
fill ~48 ~3 ~124 ~55 ~3 ~124 grass 0  
fill ~48 ~3 ~125 ~55 ~3 ~125 grass 0  
fill ~48 ~3 ~142 ~49 ~3 ~142 dirt 0  
fill ~49 ~3 ~33 ~49 ~8 ~33 fence 0  
fill ~49 ~3 ~34 ~49 ~3 ~46 fence 0 
setblock ~49 ~3 ~50 stone_slab 2  
fill ~49 ~3 ~51 ~49 ~3 ~53 oak_stairs 0  
fill ~49 ~3 ~54 ~49 ~7 ~54 planks 0  
fill ~49 ~3 ~55 ~50 ~3 ~55 dirt 0  
fill ~49 ~3 ~56 ~50 ~3 ~56 dirt 0  
fill ~49 ~3 ~57 ~50 ~3 ~57 dirt 0  
fill ~49 ~3 ~58 ~51 ~3 ~58 dirt 0  
fill ~49 ~3 ~59 ~51 ~3 ~59 dirt 0  
fill ~49 ~3 ~60 ~51 ~3 ~60 dirt 0  
fill ~49 ~3 ~61 ~49 ~3 ~72 dirt 0  
fill ~49 ~3 ~73 ~85 ~3 ~73 planks 0  
fill ~49 ~3 ~74 ~85 ~3 ~74 planks 0  
fill ~49 ~3 ~75 ~49 ~3 ~78 dirt 0  
fill ~49 ~3 ~79 ~65 ~3 ~79 planks 0  
fill ~49 ~3 ~80 ~65 ~3 ~80 planks 0  
fill ~49 ~3 ~81 ~65 ~3 ~81 planks 0  
fill ~49 ~3 ~82 ~65 ~3 ~82 planks 0  
fill ~49 ~3 ~83 ~65 ~3 ~83 planks 0  
fill ~49 ~3 ~84 ~65 ~3 ~84 planks 0  
fill ~49 ~3 ~85 ~82 ~3 ~85 planks 0  
fill ~49 ~3 ~88 ~49 ~3 ~89 oak_stairs 0  
fill ~49 ~3 ~121 ~53 ~3 ~121 mycelium 0  
fill ~49 ~3 ~122 ~51 ~3 ~122 mycelium 0  
fill ~49 ~3 ~123 ~55 ~3 ~123 grass 0 
setblock ~49 ~3 ~138 dirt 0  
fill ~49 ~3 ~139 ~50 ~3 ~139 grass 0  
fill ~49 ~3 ~141 ~50 ~3 ~141 dirt 0  
fill ~50 ~3 ~13 ~51 ~3 ~13 grass 0  
fill ~50 ~3 ~14 ~51 ~3 ~14 grass 0  
fill ~50 ~3 ~15 ~51 ~3 ~15 grass 0  
fill ~50 ~3 ~16 ~50 ~3 ~25 grass 0  
fill ~50 ~3 ~29 ~52 ~3 ~29 grass 0  
fill ~50 ~3 ~30 ~51 ~3 ~30 grass 0  
fill ~50 ~3 ~31 ~50 ~3 ~46 grass 0 
setblock ~50 ~3 ~50 oak_stairs 2  
fill ~50 ~3 ~51 ~54 ~3 ~51 planks 0  
fill ~50 ~3 ~52 ~54 ~3 ~52 planks 0  
fill ~50 ~3 ~53 ~54 ~3 ~53 planks 0  
fill ~50 ~3 ~54 ~51 ~3 ~54 dirt 0  
fill ~50 ~3 ~61 ~65 ~3 ~61 planks 0  
fill ~50 ~3 ~62 ~65 ~3 ~62 planks 0  
fill ~50 ~3 ~63 ~65 ~3 ~63 planks 0  
fill ~50 ~3 ~64 ~65 ~3 ~64 planks 0  
fill ~50 ~3 ~65 ~51 ~3 ~65 planks 0  
fill ~50 ~3 ~66 ~50 ~3 ~89 planks 0  
fill ~50 ~3 ~126 ~54 ~3 ~126 grass 0 
setblock ~50 ~3 ~127 dirt 0 
setblock ~50 ~3 ~137 dirt 0  
fill ~50 ~3 ~138 ~61 ~3 ~138 grass 0  
fill ~50 ~3 ~140 ~54 ~3 ~140 dirt 0  
fill ~51 ~3 ~16 ~52 ~3 ~16 dirt 0  
fill ~51 ~3 ~17 ~52 ~3 ~17 dirt 0  
fill ~51 ~3 ~18 ~51 ~3 ~30 grass 0  
fill ~51 ~3 ~31 ~53 ~3 ~31 dirt 0  
fill ~51 ~3 ~32 ~52 ~3 ~32 dirt 0  
fill ~51 ~3 ~33 ~52 ~3 ~33 dirt 0 
setblock ~51 ~3 ~34 grass 0  
fill ~51 ~3 ~35 ~52 ~3 ~35 dirt 0  
fill ~51 ~3 ~36 ~52 ~3 ~36 dirt 0  
fill ~51 ~3 ~37 ~52 ~3 ~37 dirt 0  
fill ~51 ~3 ~38 ~51 ~3 ~49 grass 0  
fill ~51 ~3 ~50 ~53 ~3 ~50 planks 0  
fill ~51 ~3 ~55 ~54 ~3 ~55 planks 0  
fill ~51 ~3 ~56 ~54 ~3 ~56 planks 0  
fill ~51 ~3 ~57 ~64 ~3 ~57 planks 0 
setblock ~51 ~3 ~66 cobblestone 0  
fill ~51 ~3 ~67 ~51 ~3 ~90 planks 0  
fill ~51 ~3 ~91 ~52 ~3 ~91 oak_stairs 3  
fill ~51 ~3 ~127 ~52 ~3 ~127 grass 0  
fill ~51 ~3 ~128 ~52 ~3 ~128 dirt 0 
setblock ~51 ~3 ~136 dirt 0  
fill ~51 ~3 ~137 ~62 ~3 ~137 grass 0  
fill ~51 ~3 ~139 ~53 ~3 ~139 dirt 0  
fill ~52 ~3 ~12 ~53 ~3 ~12 dirt 0  
fill ~52 ~3 ~13 ~53 ~3 ~13 dirt 0  
fill ~52 ~3 ~14 ~53 ~3 ~14 dirt 0  
fill ~52 ~3 ~15 ~53 ~3 ~15 dirt 0  
fill ~52 ~3 ~18 ~54 ~3 ~18 dirt 0  
fill ~52 ~3 ~19 ~52 ~3 ~27 grass 0  
fill ~52 ~3 ~28 ~53 ~3 ~28 dirt 0  
fill ~52 ~3 ~30 ~53 ~3 ~30 dirt 0  
fill ~52 ~3 ~34 ~53 ~3 ~34 dirt 0  
fill ~52 ~3 ~38 ~53 ~3 ~38 dirt 0  
fill ~52 ~3 ~39 ~53 ~3 ~39 dirt 0  
fill ~52 ~3 ~40 ~53 ~3 ~40 dirt 0  
fill ~52 ~3 ~41 ~52 ~3 ~49 grass 0  
fill ~52 ~3 ~54 ~54 ~3 ~54 planks 0  
fill ~52 ~3 ~58 ~65 ~3 ~58 planks 0  
fill ~52 ~3 ~59 ~65 ~3 ~59 planks 0  
fill ~52 ~3 ~60 ~65 ~3 ~60 planks 0  
fill ~52 ~3 ~65 ~54 ~3 ~65 cobblestone 0 
setblock ~52 ~3 ~66 netherrack 0  
fill ~52 ~3 ~67 ~53 ~3 ~67 cobblestone 0  
fill ~52 ~3 ~68 ~85 ~3 ~68 planks 0  
fill ~52 ~3 ~69 ~85 ~3 ~69 planks 0  
fill ~52 ~3 ~70 ~85 ~3 ~70 planks 0  
fill ~52 ~3 ~71 ~85 ~3 ~71 planks 0  
fill ~52 ~3 ~72 ~85 ~3 ~72 planks 0  
fill ~52 ~3 ~75 ~85 ~3 ~75 planks 0  
fill ~52 ~3 ~76 ~85 ~3 ~76 planks 0  
fill ~52 ~3 ~77 ~85 ~3 ~77 planks 0  
fill ~52 ~3 ~78 ~65 ~3 ~78 planks 0  
fill ~52 ~3 ~86 ~53 ~3 ~86 planks 0  
fill ~52 ~3 ~87 ~53 ~3 ~87 planks 0  
fill ~52 ~3 ~88 ~53 ~3 ~88 planks 0  
fill ~52 ~3 ~89 ~53 ~3 ~89 planks 0  
fill ~52 ~3 ~90 ~52 ~3 ~68 planks 0  
fill ~52 ~3 ~122 ~74 ~3 ~122 grass 0 
setblock ~52 ~3 ~129 dirt 0 
setblock ~52 ~3 ~135 dirt 0  
fill ~52 ~3 ~136 ~64 ~3 ~136 grass 0  
fill ~53 ~3 ~19 ~55 ~3 ~19 dirt 0  
fill ~53 ~3 ~20 ~54 ~3 ~20 grass 0  
fill ~53 ~3 ~21 ~55 ~3 ~21 grass 0  
fill ~53 ~3 ~22 ~55 ~3 ~22 grass 0  
fill ~53 ~3 ~23 ~55 ~3 ~23 grass 0  
fill ~53 ~3 ~24 ~54 ~3 ~24 grass 0  
fill ~53 ~3 ~25 ~53 ~3 ~20 grass 0  
fill ~53 ~3 ~26 ~54 ~3 ~26 dirt 0  
fill ~53 ~3 ~27 ~54 ~3 ~27 dirt 0 
setblock ~53 ~3 ~29 dirt 0  
fill ~53 ~3 ~41 ~55 ~3 ~41 dirt 0  
fill ~53 ~3 ~42 ~53 ~3 ~49 grass 0  
fill ~53 ~3 ~66 ~54 ~3 ~66 cobblestone 0  
fill ~53 ~3 ~111 ~53 ~3 ~113 fence 0  
fill ~53 ~3 ~114 ~57 ~3 ~114 grass 0  
fill ~53 ~3 ~115 ~56 ~3 ~115 grass 0  
fill ~53 ~3 ~116 ~56 ~3 ~116 grass 0  
fill ~53 ~3 ~127 ~54 ~3 ~127 dirt 0  
fill ~53 ~3 ~128 ~55 ~3 ~128 grass 0  
fill ~53 ~3 ~129 ~54 ~3 ~129 grass 0  
fill ~53 ~3 ~130 ~54 ~3 ~130 dirt 0 
setblock ~53 ~3 ~134 dirt 0  
fill ~53 ~3 ~135 ~63 ~3 ~135 grass 0  
fill ~54 ~3 ~25 ~55 ~3 ~25 dirt 0 
setblock ~54 ~3 ~42 dirt 0  
fill ~54 ~3 ~43 ~61 ~3 ~43 grass 0  
fill ~54 ~3 ~44 ~65 ~3 ~44 grass 0  
fill ~54 ~3 ~45 ~65 ~3 ~45 grass 0  
fill ~54 ~3 ~46 ~56 ~3 ~46 grass 0  
fill ~54 ~3 ~47 ~69 ~3 ~47 grass 0  
fill ~54 ~3 ~48 ~60 ~3 ~48 grass 0  
fill ~54 ~3 ~49 ~61 ~3 ~49 grass 0 
setblock ~54 ~3 ~50 dirt 0  
fill ~54 ~3 ~67 ~85 ~3 ~67 planks 0  
fill ~54 ~3 ~86 ~82 ~3 ~86 dirt 0  
fill ~54 ~3 ~87 ~56 ~3 ~87 dirt 0  
fill ~54 ~3 ~88 ~54 ~3 ~90 grass 0  
fill ~54 ~3 ~91 ~54 ~1 ~91 dirt 0  
fill ~54 ~3 ~113 ~54 ~5 ~113 fence 0  
fill ~54 ~3 ~117 ~74 ~3 ~117 grass 0  
fill ~54 ~3 ~118 ~56 ~3 ~118 grass 0  
fill ~54 ~3 ~119 ~56 ~3 ~119 grass 0  
fill ~54 ~3 ~120 ~56 ~3 ~120 grass 0  
fill ~54 ~3 ~121 ~56 ~3 ~121 grass 0 
setblock ~54 ~3 ~131 dirt 0 
setblock ~54 ~3 ~133 dirt 0  
fill ~54 ~3 ~134 ~62 ~3 ~134 grass 0  
fill ~54 ~3 ~139 ~60 ~3 ~139 grass 0  
fill ~54 ~3 ~141 ~55 ~3 ~141 dirt 0  
fill ~55 ~3 ~20 ~56 ~3 ~20 dirt 0  
fill ~55 ~3 ~24 ~56 ~3 ~24 dirt 0  
fill ~55 ~3 ~40 ~58 ~3 ~40 dirt 0  
fill ~55 ~3 ~42 ~58 ~3 ~42 grass 0  
fill ~55 ~3 ~50 ~61 ~3 ~50 grass 0  
fill ~55 ~3 ~51 ~55 ~3 ~56 dirt 0  
fill ~55 ~3 ~65 ~65 ~3 ~65 planks 0  
fill ~55 ~3 ~66 ~65 ~3 ~66 planks 0  
fill ~55 ~3 ~88 ~56 ~3 ~88 dirt 0  
fill ~55 ~3 ~89 ~56 ~3 ~89 dirt 0  
fill ~55 ~3 ~90 ~56 ~3 ~90 dirt 0  
fill ~55 ~3 ~91 ~55 ~3 ~95 grass 0  
fill ~55 ~3 ~96 ~56 ~3 ~96 dirt 0  
fill ~55 ~3 ~97 ~56 ~3 ~97 dirt 0  
fill ~55 ~3 ~98 ~56 ~3 ~98 dirt 0  
fill ~55 ~3 ~99 ~56 ~3 ~99 dirt 0  
fill ~55 ~3 ~100 ~56 ~3 ~100 dirt 0  
fill ~55 ~3 ~101 ~56 ~3 ~101 dirt 0  
fill ~55 ~3 ~102 ~55 ~3 ~108 grass 0  
fill ~55 ~3 ~109 ~56 ~3 ~109 dirt 0  
fill ~55 ~3 ~110 ~56 ~3 ~110 dirt 0  
fill ~55 ~3 ~111 ~56 ~3 ~111 dirt 0  
fill ~55 ~3 ~112 ~55 ~3 ~125 grass 0 
setblock ~55 ~3 ~126 dirt 0  
fill ~55 ~3 ~127 ~56 ~3 ~127 grass 0 
setblock ~55 ~3 ~129 dirt 0  
fill ~55 ~3 ~130 ~62 ~3 ~130 grass 0  
fill ~55 ~3 ~131 ~61 ~3 ~131 grass 0 
setblock ~55 ~3 ~132 dirt 0  
fill ~55 ~3 ~133 ~61 ~3 ~133 grass 0  
fill ~55 ~3 ~140 ~59 ~3 ~140 grass 0  
fill ~55 ~3 ~142 ~57 ~3 ~142 dirt 0  
fill ~56 ~3 ~21 ~57 ~3 ~21 dirt 0  
fill ~56 ~3 ~22 ~57 ~3 ~22 dirt 0  
fill ~56 ~3 ~23 ~57 ~3 ~23 dirt 0 
setblock ~56 ~3 ~41 grass 0  
fill ~56 ~3 ~51 ~61 ~3 ~51 grass 0  
fill ~56 ~3 ~52 ~64 ~3 ~52 dirt 0  
fill ~56 ~3 ~53 ~56 ~3 ~52 dirt 0  
fill ~56 ~3 ~54 ~64 ~3 ~54 planks 0  
fill ~56 ~3 ~55 ~64 ~3 ~55 planks 0  
fill ~56 ~3 ~56 ~64 ~3 ~56 planks 0  
fill ~56 ~3 ~91 ~57 ~3 ~91 dirt 0  
fill ~56 ~3 ~92 ~56 ~3 ~94 grass 0  
fill ~56 ~3 ~95 ~57 ~3 ~95 dirt 0  
fill ~56 ~3 ~102 ~58 ~3 ~102 dirt 0  
fill ~56 ~3 ~103 ~56 ~3 ~107 grass 0  
fill ~56 ~3 ~108 ~57 ~3 ~108 dirt 0  
fill ~56 ~3 ~112 ~57 ~3 ~112 dirt 0 
setblock ~56 ~3 ~113 grass 0  
fill ~56 ~3 ~123 ~57 ~3 ~123 dirt 0  
fill ~56 ~3 ~124 ~56 ~3 ~125 dirt 0 
setblock ~56 ~3 ~126 grass 0 
setblock ~56 ~3 ~128 dirt 0  
fill ~56 ~3 ~129 ~63 ~3 ~129 grass 0  
fill ~56 ~3 ~132 ~60 ~3 ~132 grass 0  
fill ~56 ~3 ~141 ~59 ~3 ~141 grass 0  
fill ~56 ~3 ~143 ~59 ~3 ~143 dirt 0  
fill ~57 ~3 ~41 ~64 ~3 ~41 dirt 0 
setblock ~57 ~3 ~46 dirt 0  
fill ~57 ~3 ~53 ~64 ~3 ~53 planks 0  
fill ~57 ~3 ~87 ~80 ~3 ~87 grass 0  
fill ~57 ~3 ~88 ~80 ~3 ~88 grass 0  
fill ~57 ~3 ~89 ~57 ~3 ~90 grass 0  
fill ~57 ~3 ~92 ~58 ~3 ~92 dirt 0  
fill ~57 ~3 ~93 ~58 ~3 ~93 dirt 0  
fill ~57 ~3 ~94 ~58 ~3 ~94 dirt 0  
fill ~57 ~3 ~96 ~76 ~3 ~96 grass 0  
fill ~57 ~3 ~97 ~69 ~3 ~97 grass 0  
fill ~57 ~3 ~98 ~88 ~3 ~98 grass 0  
fill ~57 ~3 ~99 ~72 ~3 ~99 grass 0  
fill ~57 ~3 ~100 ~68 ~3 ~100 grass 0  
fill ~57 ~3 ~101 ~71 ~3 ~101 grass 0  
fill ~57 ~3 ~103 ~59 ~3 ~103 dirt 0  
fill ~57 ~3 ~104 ~57 ~3 ~106 grass 0  
fill ~57 ~3 ~107 ~58 ~3 ~107 dirt 0  
fill ~57 ~3 ~109 ~78 ~3 ~109 grass 0  
fill ~57 ~3 ~110 ~76 ~3 ~110 grass 0  
fill ~57 ~3 ~111 ~74 ~3 ~111 grass 0  
fill ~57 ~3 ~113 ~58 ~3 ~113 dirt 0  
fill ~57 ~3 ~115 ~64 ~3 ~115 dirt 0  
fill ~57 ~3 ~116 ~59 ~3 ~116 dirt 0  
fill ~57 ~3 ~118 ~69 ~3 ~118 wool 15  
fill ~57 ~3 ~119 ~74 ~3 ~119 wool 15  
fill ~57 ~3 ~120 ~70 ~3 ~120 wool 15  
fill ~57 ~3 ~121 ~69 ~3 ~121 wool 15  
fill ~57 ~3 ~124 ~57 ~3 ~125 grass 0  
fill ~57 ~3 ~126 ~57 ~3 ~127 dirt 0  
fill ~57 ~3 ~128 ~66 ~3 ~128 grass 0  
fill ~58 ~3 ~46 ~59 ~3 ~46 grass 0 
setblock ~58 ~3 ~89 dirt 0  
fill ~58 ~3 ~90 ~59 ~3 ~90 grass 0  
fill ~58 ~3 ~91 ~74 ~3 ~91 grass 0  
fill ~58 ~3 ~95 ~67 ~3 ~95 grass 0  
fill ~58 ~3 ~104 ~59 ~3 ~104 dirt 0  
fill ~58 ~3 ~105 ~59 ~3 ~105 dirt 0  
fill ~58 ~3 ~106 ~59 ~3 ~106 dirt 0  
fill ~58 ~3 ~108 ~64 ~3 ~108 grass 0  
fill ~58 ~3 ~112 ~64 ~3 ~112 grass 0  
fill ~58 ~3 ~114 ~60 ~3 ~114 dirt 0  
fill ~58 ~3 ~123 ~60 ~3 ~123 grass 0 
setblock ~58 ~3 ~124 dirt 0  
fill ~58 ~3 ~125 ~58 ~3 ~142 grass 0  
fill ~59 ~3 ~42 ~61 ~3 ~42 dirt 0  
fill ~59 ~3 ~89 ~68 ~3 ~89 grass 0  
fill ~59 ~3 ~92 ~68 ~3 ~92 grass 0  
fill ~59 ~3 ~93 ~73 ~3 ~93 grass 0  
fill ~59 ~3 ~94 ~70 ~3 ~94 grass 0  
fill ~59 ~3 ~102 ~92 ~3 ~102 grass 0  
fill ~59 ~3 ~107 ~76 ~3 ~107 grass 0  
fill ~59 ~3 ~113 ~63 ~3 ~113 grass 0 
setblock ~59 ~3 ~124 grass 0 
setblock ~59 ~3 ~125 dirt 0  
fill ~59 ~3 ~126 ~63 ~3 ~126 grass 0  
fill ~59 ~3 ~127 ~64 ~3 ~127 grass 0  
fill ~59 ~3 ~142 ~60 ~3 ~142 dirt 0 
setblock ~60 ~3 ~46 dirt 0 
setblock ~60 ~3 ~90 dirt 0  
fill ~60 ~3 ~103 ~70 ~3 ~103 grass 0  
fill ~60 ~3 ~104 ~91 ~3 ~104 grass 0  
fill ~60 ~3 ~105 ~73 ~3 ~105 grass 0  
fill ~60 ~3 ~106 ~67 ~3 ~106 grass 0 
setblock ~60 ~3 ~116 grass 0 
setblock ~60 ~3 ~124 dirt 0  
fill ~60 ~3 ~125 ~62 ~3 ~125 grass 0  
fill ~60 ~3 ~140 ~61 ~3 ~140 dirt 0  
fill ~60 ~3 ~141 ~61 ~3 ~141 dirt 0  
fill ~61 ~3 ~46 ~65 ~3 ~46 grass 0  
fill ~61 ~3 ~48 ~64 ~3 ~48 dirt 0  
fill ~61 ~3 ~90 ~72 ~3 ~90 grass 0  
fill ~61 ~3 ~114 ~62 ~3 ~114 grass 0  
fill ~61 ~3 ~116 ~64 ~3 ~116 dirt 0 
setblock ~61 ~3 ~123 dirt 0 
setblock ~61 ~3 ~124 grass 0  
fill ~61 ~3 ~132 ~62 ~3 ~132 dirt 0  
fill ~61 ~3 ~139 ~62 ~3 ~139 dirt 0 
setblock ~62 ~3 ~42 grass 0 
setblock ~62 ~3 ~43 dirt 0  
fill ~62 ~3 ~49 ~64 ~3 ~49 dirt 0  
fill ~62 ~3 ~50 ~64 ~3 ~50 dirt 0  
fill ~62 ~3 ~51 ~64 ~3 ~51 dirt 0  
fill ~62 ~3 ~123 ~68 ~3 ~123 grass 0 
setblock ~62 ~3 ~124 dirt 0  
fill ~62 ~3 ~131 ~63 ~3 ~131 dirt 0  
fill ~62 ~3 ~133 ~63 ~3 ~133 dirt 0  
fill ~62 ~3 ~138 ~64 ~3 ~138 dirt 0 
setblock ~63 ~3 ~42 dirt 0  
fill ~63 ~3 ~43 ~64 ~3 ~43 grass 0  
fill ~63 ~3 ~114 ~64 ~3 ~114 dirt 0  
fill ~63 ~3 ~124 ~68 ~3 ~124 grass 0 
setblock ~63 ~3 ~125 dirt 0  
fill ~63 ~3 ~130 ~66 ~3 ~130 dirt 0  
fill ~63 ~3 ~134 ~64 ~3 ~134 dirt 0  
fill ~63 ~3 ~137 ~65 ~3 ~137 dirt 0 
setblock ~64 ~3 ~42 grass 0  
fill ~64 ~3 ~113 ~67 ~3 ~113 dirt 0  
fill ~64 ~3 ~125 ~68 ~3 ~125 grass 0 
setblock ~64 ~3 ~126 dirt 0  
fill ~64 ~3 ~129 ~67 ~3 ~129 dirt 0  
fill ~64 ~3 ~135 ~65 ~3 ~135 dirt 0  
fill ~65 ~3 ~40 ~65 ~1 ~40 dirt 0 
setblock ~65 ~3 ~41 grass 0  
fill ~65 ~3 ~42 ~65 ~4 ~42 log 1  
fill ~65 ~3 ~48 ~70 ~3 ~48 grass 0  
fill ~65 ~3 ~49 ~71 ~3 ~49 grass 0  
fill ~65 ~3 ~50 ~72 ~3 ~50 grass 0  
fill ~65 ~3 ~51 ~72 ~3 ~51 grass 0  
fill ~65 ~3 ~52 ~72 ~3 ~52 grass 0  
fill ~65 ~3 ~53 ~71 ~3 ~53 dirt 0  
fill ~65 ~3 ~54 ~65 ~3 ~57 dirt 0 
setblock ~65 ~3 ~108 dirt 0  
fill ~65 ~3 ~112 ~66 ~3 ~112 dirt 0  
fill ~65 ~3 ~114 ~66 ~3 ~114 grass 0  
fill ~65 ~3 ~115 ~66 ~3 ~115 grass 0  
fill ~65 ~3 ~116 ~67 ~3 ~116 grass 0 
setblock ~65 ~3 ~126 grass 0 
setblock ~65 ~3 ~127 dirt 0  
fill ~65 ~3 ~136 ~66 ~3 ~136 dirt 0  
fill ~66 ~3 ~35 ~67 ~3 ~35 dirt 0  
fill ~66 ~3 ~36 ~67 ~3 ~36 dirt 0  
fill ~66 ~3 ~37 ~66 ~1 ~37 dirt 0  
fill ~66 ~3 ~38 ~66 ~1 ~38 dirt 0  
fill ~66 ~3 ~39 ~66 ~1 ~39 dirt 0  
fill ~66 ~3 ~40 ~70 ~3 ~40 grass 0  
fill ~66 ~3 ~54 ~83 ~3 ~54 grass 0  
fill ~66 ~3 ~55 ~84 ~3 ~55 grass 0  
fill ~66 ~3 ~56 ~84 ~3 ~56 grass 0  
fill ~66 ~3 ~57 ~84 ~3 ~57 grass 0  
fill ~66 ~3 ~58 ~84 ~3 ~58 grass 0  
fill ~66 ~3 ~59 ~84 ~3 ~59 grass 0  
fill ~66 ~3 ~60 ~70 ~3 ~60 grass 0  
fill ~66 ~3 ~61 ~69 ~3 ~61 grass 0  
fill ~66 ~3 ~62 ~69 ~3 ~62 grass 0  
fill ~66 ~3 ~63 ~84 ~3 ~63 grass 0  
fill ~66 ~3 ~64 ~84 ~3 ~64 grass 0  
fill ~66 ~3 ~65 ~84 ~3 ~65 grass 0  
fill ~66 ~3 ~66 ~84 ~3 ~66 grass 0  
fill ~66 ~3 ~78 ~66 ~3 ~80 wool 12 
setblock ~66 ~3 ~81 dirt 0  
fill ~66 ~3 ~82 ~68 ~3 ~82 wool 12  
fill ~66 ~3 ~83 ~69 ~3 ~83 wool 12 
setblock ~66 ~3 ~84 dirt 0  
fill ~66 ~3 ~108 ~69 ~3 ~108 grass 0 
setblock ~66 ~3 ~126 dirt 0 
setblock ~66 ~3 ~127 grass 0  
fill ~67 ~3 ~34 ~68 ~3 ~34 dirt 0  
fill ~67 ~3 ~37 ~67 ~3 ~40 grass 0 
setblock ~67 ~3 ~78 planks 0  
fill ~67 ~3 ~79 ~67 ~3 ~80 wool 12  
fill ~67 ~3 ~81 ~68 ~3 ~81 planks 0  
fill ~67 ~3 ~84 ~84 ~3 ~84 wool 12  
fill ~67 ~3 ~112 ~68 ~3 ~112 grass 0  
fill ~67 ~3 ~114 ~74 ~3 ~114 dirt 0  
fill ~67 ~3 ~115 ~69 ~3 ~115 dirt 0 
setblock ~67 ~3 ~126 grass 0  
fill ~67 ~3 ~127 ~69 ~3 ~127 dirt 0  
fill ~67 ~3 ~128 ~68 ~3 ~128 dirt 0  
fill ~68 ~3 ~33 ~69 ~3 ~33 dirt 0  
fill ~68 ~3 ~35 ~73 ~3 ~35 grass 0  
fill ~68 ~3 ~36 ~74 ~3 ~36 grass 0 
setblock ~68 ~3 ~37 dirt 0  
fill ~68 ~3 ~38 ~73 ~3 ~38 grass 0  
fill ~68 ~3 ~39 ~68 ~3 ~38 grass 0 
setblock ~68 ~3 ~78 wool 12 
setblock ~68 ~3 ~79 planks 0  
fill ~68 ~3 ~80 ~74 ~3 ~80 wool 12 
setblock ~68 ~3 ~95 dirt 0 
setblock ~68 ~3 ~106 dirt 0  
fill ~68 ~3 ~113 ~69 ~3 ~113 grass 0 
setblock ~68 ~3 ~116 dirt 0  
fill ~68 ~3 ~126 ~69 ~3 ~126 dirt 0  
fill ~69 ~3 ~32 ~71 ~3 ~32 dirt 0  
fill ~69 ~3 ~34 ~73 ~3 ~34 grass 0  
fill ~69 ~3 ~37 ~73 ~3 ~37 grass 0  
fill ~69 ~3 ~39 ~70 ~3 ~39 dirt 0  
fill ~69 ~3 ~41 ~70 ~3 ~41 grass 0  
fill ~69 ~3 ~42 ~69 ~3 ~52 grass 0  
fill ~69 ~3 ~78 ~71 ~3 ~78 planks 0 
setblock ~69 ~3 ~79 wool 12  
fill ~69 ~3 ~81 ~72 ~3 ~81 wool 12 
setblock ~69 ~3 ~82 planks 0 
setblock ~69 ~3 ~89 dirt 0  
fill ~69 ~3 ~92 ~69 ~12 ~92 log 1  
fill ~69 ~3 ~95 ~74 ~3 ~95 grass 0 
setblock ~69 ~3 ~100 dirt 0  
fill ~69 ~3 ~106 ~85 ~3 ~106 grass 0 
setblock ~69 ~3 ~112 dirt 0  
fill ~69 ~3 ~116 ~74 ~3 ~116 grass 0  
fill ~69 ~3 ~123 ~74 ~3 ~123 dirt 0  
fill ~69 ~3 ~124 ~74 ~3 ~124 dirt 0  
fill ~69 ~3 ~125 ~70 ~3 ~125 dirt 0  
fill ~70 ~3 ~31 ~72 ~3 ~31 dirt 0  
fill ~70 ~3 ~33 ~73 ~3 ~33 grass 0  
fill ~70 ~3 ~42 ~70 ~3 ~43 dirt 0  
fill ~70 ~3 ~44 ~70 ~3 ~46 grass 0 
setblock ~70 ~3 ~47 dirt 0  
fill ~70 ~3 ~61 ~73 ~3 ~61 dirt 0  
fill ~70 ~3 ~62 ~73 ~3 ~62 dirt 0  
fill ~70 ~3 ~79 ~72 ~3 ~79 planks 0  
fill ~70 ~3 ~82 ~84 ~3 ~82 wool 12  
fill ~70 ~3 ~83 ~72 ~3 ~83 planks 0  
fill ~70 ~3 ~89 ~80 ~3 ~89 grass 0  
fill ~70 ~3 ~92 ~82 ~3 ~92 grass 0 
setblock ~70 ~3 ~97 dirt 0  
fill ~70 ~3 ~100 ~73 ~3 ~100 grass 0 
setblock ~70 ~3 ~108 dirt 0 
setblock ~70 ~3 ~112 grass 0  
fill ~70 ~3 ~113 ~72 ~3 ~113 dirt 0  
fill ~70 ~3 ~115 ~72 ~3 ~115 grass 0  
fill ~70 ~3 ~118 ~75 ~3 ~118 grass 0  
fill ~70 ~3 ~121 ~75 ~3 ~121 grass 0  
fill ~71 ~3 ~39 ~73 ~3 ~39 grass 0  
fill ~71 ~3 ~40 ~71 ~3 ~41 dirt 0  
fill ~71 ~3 ~42 ~73 ~3 ~42 grass 0  
fill ~71 ~3 ~43 ~73 ~3 ~43 grass 0  
fill ~71 ~3 ~44 ~71 ~3 ~46 dirt 0  
fill ~71 ~3 ~47 ~73 ~3 ~47 grass 0  
fill ~71 ~3 ~48 ~79 ~3 ~48 dirt 0  
fill ~71 ~3 ~60 ~73 ~3 ~60 dirt 0 
setblock ~71 ~3 ~94 dirt 0  
fill ~71 ~3 ~97 ~73 ~3 ~97 grass 0 
setblock ~71 ~3 ~103 dirt 0  
fill ~71 ~3 ~108 ~80 ~3 ~108 grass 0  
fill ~71 ~3 ~112 ~74 ~3 ~112 dirt 0  
fill ~71 ~3 ~120 ~74 ~3 ~120 grass 0  
fill ~72 ~3 ~30 ~73 ~3 ~30 dirt 0  
fill ~72 ~3 ~32 ~73 ~3 ~32 grass 0  
fill ~72 ~3 ~40 ~73 ~3 ~40 grass 0  
fill ~72 ~3 ~41 ~73 ~3 ~41 grass 0  
fill ~72 ~3 ~44 ~73 ~3 ~44 grass 0  
fill ~72 ~3 ~45 ~73 ~3 ~45 grass 0  
fill ~72 ~3 ~46 ~73 ~3 ~46 grass 0  
fill ~72 ~3 ~49 ~80 ~3 ~49 dirt 0  
fill ~72 ~3 ~53 ~72 ~13 ~53 planks 0 
setblock ~72 ~3 ~78 wool 12  
fill ~72 ~3 ~94 ~85 ~3 ~94 grass 0 
setblock ~72 ~3 ~101 dirt 0  
fill ~72 ~3 ~103 ~74 ~3 ~103 grass 0  
fill ~73 ~3 ~25 ~73 ~1 ~25 dirt 0  
fill ~73 ~3 ~26 ~73 ~1 ~26 dirt 0  
fill ~73 ~3 ~27 ~73 ~1 ~27 dirt 0  
fill ~73 ~3 ~28 ~73 ~1 ~28 dirt 0  
fill ~73 ~3 ~29 ~73 ~1 ~29 dirt 0 
setblock ~73 ~3 ~31 grass 0  
fill ~73 ~3 ~50 ~83 ~3 ~50 dirt 0  
fill ~73 ~3 ~51 ~74 ~3 ~51 dirt 0  
fill ~73 ~3 ~52 ~74 ~3 ~52 dirt 0 
setblock ~73 ~3 ~53 grass 0  
fill ~73 ~3 ~78 ~75 ~3 ~78 planks 0 
setblock ~73 ~3 ~79 wool 12  
fill ~73 ~3 ~81 ~74 ~3 ~81 dirt 0  
fill ~73 ~3 ~83 ~84 ~3 ~83 wool 12 
setblock ~73 ~3 ~90 dirt 0 
setblock ~73 ~3 ~99 dirt 0  
fill ~73 ~3 ~101 ~92 ~3 ~101 grass 0  
fill ~73 ~3 ~115 ~75 ~3 ~115 dirt 0  
fill ~74 ~3 ~10 ~74 ~4 ~10 bedrock 0  
fill ~74 ~3 ~11 ~74 ~4 ~11 bedrock 0  
fill ~74 ~3 ~12 ~74 ~4 ~12 bedrock 0  
fill ~74 ~3 ~13 ~74 ~4 ~13 bedrock 0  
fill ~74 ~3 ~24 ~75 ~3 ~24 bedrock 0  
fill ~74 ~3 ~25 ~74 ~4 ~25 bedrock 0  
fill ~74 ~3 ~26 ~74 ~4 ~26 bedrock 0  
fill ~74 ~3 ~27 ~74 ~4 ~27 bedrock 0  
fill ~74 ~3 ~28 ~74 ~4 ~28 bedrock 0  
fill ~74 ~3 ~29 ~74 ~6 ~29 log 1  
fill ~74 ~3 ~33 ~76 ~3 ~33 glass 0  
fill ~74 ~3 ~34 ~104 ~3 ~34 glass 0  
fill ~74 ~3 ~35 ~104 ~3 ~35 glass 0  
fill ~74 ~3 ~37 ~91 ~3 ~37 dirt 0  
fill ~74 ~3 ~38 ~91 ~3 ~38 dirt 0  
fill ~74 ~3 ~39 ~91 ~3 ~39 dirt 0  
fill ~74 ~3 ~40 ~91 ~3 ~40 dirt 0  
fill ~74 ~3 ~41 ~91 ~3 ~41 dirt 0  
fill ~74 ~3 ~42 ~91 ~3 ~42 dirt 0  
fill ~74 ~3 ~43 ~91 ~3 ~43 dirt 0  
fill ~74 ~3 ~44 ~91 ~3 ~44 dirt 0  
fill ~74 ~3 ~45 ~90 ~3 ~45 dirt 0  
fill ~74 ~3 ~46 ~79 ~3 ~46 dirt 0  
fill ~74 ~3 ~47 ~79 ~3 ~47 dirt 0 
setblock ~74 ~3 ~53 dirt 0  
fill ~74 ~3 ~60 ~84 ~3 ~60 grass 0  
fill ~74 ~3 ~61 ~84 ~3 ~61 grass 0  
fill ~74 ~3 ~62 ~84 ~3 ~62 grass 0  
fill ~74 ~3 ~79 ~75 ~3 ~79 planks 0  
fill ~74 ~3 ~90 ~77 ~3 ~90 grass 0 
setblock ~74 ~3 ~93 dirt 0 
setblock ~74 ~3 ~97 dirt 0  
fill ~74 ~3 ~99 ~76 ~3 ~99 grass 0 
setblock ~74 ~3 ~100 dirt 0 
setblock ~74 ~3 ~105 dirt 0  
fill ~75 ~3 ~9 ~75 ~4 ~9 bedrock 0  
fill ~75 ~3 ~10 ~76 ~3 ~10 log 1  
fill ~75 ~3 ~11 ~75 ~6 ~11 log 1  
fill ~75 ~3 ~12 ~75 ~6 ~12 log 1  
fill ~75 ~3 ~13 ~75 ~6 ~13 log 1  
fill ~75 ~3 ~14 ~75 ~4 ~14 bedrock 0  
fill ~75 ~3 ~16 ~75 ~4 ~16 bedrock 0  
fill ~75 ~3 ~17 ~75 ~4 ~17 bedrock 0  
fill ~75 ~3 ~18 ~75 ~4 ~18 bedrock 0  
fill ~75 ~3 ~25 ~75 ~6 ~25 log 1  
fill ~75 ~3 ~26 ~75 ~6 ~26 log 1  
fill ~75 ~3 ~28 ~75 ~6 ~28 log 1  
fill ~75 ~3 ~36 ~91 ~3 ~36 dirt 0  
fill ~75 ~3 ~51 ~79 ~3 ~51 grass 0  
fill ~75 ~3 ~52 ~79 ~3 ~52 grass 0  
fill ~75 ~3 ~53 ~75 ~3 ~51 grass 0  
fill ~75 ~3 ~80 ~76 ~3 ~80 dirt 0  
fill ~75 ~3 ~81 ~84 ~3 ~81 wool 12 
setblock ~75 ~3 ~91 dirt 0  
fill ~75 ~3 ~93 ~77 ~3 ~93 grass 0 
setblock ~75 ~3 ~95 dirt 0  
fill ~75 ~3 ~97 ~87 ~3 ~97 grass 0  
fill ~75 ~3 ~100 ~89 ~3 ~100 grass 0 
setblock ~75 ~3 ~103 dirt 0  
fill ~75 ~3 ~105 ~86 ~3 ~105 grass 0  
fill ~75 ~3 ~111 ~76 ~3 ~111 dirt 0  
fill ~75 ~3 ~116 ~76 ~3 ~116 dirt 0  
fill ~75 ~3 ~117 ~76 ~3 ~117 dirt 0  
fill ~75 ~3 ~119 ~76 ~3 ~119 grass 0 
setblock ~75 ~3 ~120 wool 15  
fill ~75 ~3 ~122 ~76 ~3 ~122 dirt 0  
fill ~75 ~3 ~123 ~75 ~5 ~123 bedrock 0  
fill ~76 ~3 ~7 ~76 ~4 ~7 bedrock 0  
fill ~76 ~3 ~8 ~76 ~4 ~8 bedrock 0  
fill ~76 ~3 ~9 ~76 ~6 ~9 log 1  
fill ~76 ~3 ~14 ~76 ~6 ~14 log 1  
fill ~76 ~3 ~15 ~76 ~4 ~15 bedrock 0  
fill ~76 ~3 ~16 ~76 ~6 ~16 log 1  
fill ~76 ~3 ~17 ~77 ~3 ~17 log 1  
fill ~76 ~3 ~18 ~76 ~6 ~18 log 1  
fill ~76 ~3 ~19 ~76 ~4 ~19 bedrock 0  
fill ~76 ~3 ~23 ~77 ~3 ~23 bedrock 0  
fill ~76 ~3 ~24 ~77 ~3 ~24 log 1  
fill ~76 ~3 ~27 ~76 ~6 ~27 log 1 
setblock ~76 ~3 ~53 dirt 0  
fill ~76 ~3 ~78 ~76 ~3 ~79 wool 12  
fill ~76 ~3 ~91 ~81 ~3 ~91 grass 0  
fill ~76 ~3 ~95 ~86 ~3 ~95 grass 0  
fill ~76 ~3 ~103 ~77 ~3 ~103 grass 0  
fill ~76 ~3 ~118 ~77 ~3 ~118 dirt 0 
setblock ~76 ~3 ~120 grass 0  
fill ~76 ~3 ~121 ~77 ~3 ~121 dirt 0  
fill ~77 ~3 ~4 ~77 ~4 ~4 bedrock 0  
fill ~77 ~3 ~5 ~77 ~4 ~5 bedrock 0  
fill ~77 ~3 ~6 ~77 ~4 ~6 bedrock 0  
fill ~77 ~3 ~7 ~78 ~3 ~7 log 1  
fill ~77 ~3 ~8 ~77 ~6 ~8 log 1  
fill ~77 ~3 ~15 ~77 ~6 ~15 log 1  
fill ~77 ~3 ~19 ~77 ~6 ~19 log 1  
fill ~77 ~3 ~20 ~77 ~4 ~20 bedrock 0 
setblock ~77 ~3 ~53 grass 0  
fill ~77 ~3 ~78 ~79 ~3 ~78 planks 0  
fill ~77 ~3 ~79 ~78 ~3 ~79 dirt 0  
fill ~77 ~3 ~80 ~84 ~3 ~80 wool 12 
setblock ~77 ~3 ~96 dirt 0 
setblock ~77 ~3 ~99 dirt 0 
setblock ~77 ~3 ~107 dirt 0  
fill ~77 ~3 ~110 ~78 ~3 ~110 dirt 0  
fill ~77 ~3 ~119 ~78 ~3 ~119 dirt 0  
fill ~77 ~3 ~120 ~78 ~3 ~120 dirt 0  
fill ~78 ~3 ~3 ~79 ~3 ~3 bedrock 0  
fill ~78 ~3 ~4 ~79 ~3 ~4 log 1  
fill ~78 ~3 ~5 ~78 ~6 ~5 log 1  
fill ~78 ~3 ~6 ~78 ~6 ~6 log 1  
fill ~78 ~3 ~20 ~78 ~6 ~20 log 1  
fill ~78 ~3 ~21 ~78 ~4 ~21 bedrock 0  
fill ~78 ~3 ~24 ~78 ~4 ~24 bedrock 0  
fill ~78 ~3 ~25 ~78 ~6 ~25 log 1 
setblock ~78 ~3 ~33 glass 0  
fill ~78 ~3 ~53 ~89 ~3 ~53 dirt 0 
setblock ~78 ~3 ~90 dirt 0 
setblock ~78 ~3 ~93 dirt 0  
fill ~78 ~3 ~96 ~87 ~3 ~96 grass 0  
fill ~78 ~3 ~99 ~88 ~3 ~99 grass 0 
setblock ~78 ~3 ~103 dirt 0  
fill ~78 ~3 ~107 ~83 ~3 ~107 grass 0  
fill ~79 ~3 ~21 ~79 ~6 ~21 log 1  
fill ~79 ~3 ~22 ~79 ~4 ~22 bedrock 0  
fill ~79 ~3 ~25 ~79 ~4 ~25 bedrock 0  
fill ~79 ~3 ~26 ~79 ~6 ~26 log 1  
fill ~79 ~3 ~27 ~81 ~3 ~27 log 1 
setblock ~79 ~3 ~79 planks 0  
fill ~79 ~3 ~90 ~80 ~3 ~90 grass 0  
fill ~79 ~3 ~93 ~83 ~3 ~93 grass 0  
fill ~79 ~3 ~103 ~91 ~3 ~103 grass 0  
fill ~79 ~3 ~109 ~81 ~3 ~109 dirt 0  
fill ~80 ~3 ~2 ~80 ~4 ~2 bedrock 0  
fill ~80 ~3 ~3 ~80 ~6 ~3 log 1  
fill ~80 ~3 ~22 ~80 ~6 ~22 log 1  
fill ~80 ~3 ~23 ~80 ~4 ~23 bedrock 0  
fill ~80 ~3 ~26 ~81 ~3 ~26 bedrock 0  
fill ~80 ~3 ~33 ~104 ~3 ~33 glass 0 
setblock ~80 ~3 ~46 gravel 0 
setblock ~80 ~3 ~47 planks 1 
setblock ~80 ~3 ~48 mycelium 0  
fill ~80 ~3 ~51 ~89 ~3 ~51 dirt 0  
fill ~80 ~3 ~52 ~89 ~3 ~52 dirt 0  
fill ~80 ~3 ~78 ~80 ~3 ~84 wool 12  
fill ~81 ~3 ~1 ~84 ~3 ~1 bedrock 0  
fill ~81 ~3 ~2 ~84 ~3 ~2 log 1  
fill ~81 ~3 ~23 ~81 ~6 ~23 log 1  
fill ~81 ~3 ~24 ~81 ~4 ~24 bedrock 0  
fill ~81 ~3 ~25 ~81 ~4 ~25 bedrock 0  
fill ~81 ~3 ~46 ~89 ~3 ~46 dirt 0 
setblock ~81 ~3 ~47 mycelium 0  
fill ~81 ~3 ~48 ~82 ~3 ~48 planks 1  
fill ~81 ~3 ~49 ~82 ~3 ~49 planks 1  
fill ~81 ~3 ~78 ~85 ~3 ~78 planks 0  
fill ~81 ~3 ~79 ~81 ~3 ~67 planks 0  
fill ~81 ~3 ~87 ~82 ~3 ~87 dirt 0  
fill ~81 ~3 ~88 ~82 ~3 ~88 dirt 0  
fill ~81 ~3 ~89 ~82 ~3 ~89 dirt 0  
fill ~81 ~3 ~90 ~83 ~3 ~90 dirt 0  
fill ~81 ~3 ~108 ~83 ~3 ~108 dirt 0  
fill ~82 ~3 ~24 ~82 ~6 ~24 log 1  
fill ~82 ~3 ~25 ~82 ~6 ~25 log 1  
fill ~82 ~3 ~26 ~82 ~6 ~26 log 1  
fill ~82 ~3 ~47 ~83 ~3 ~47 gravel 0 
setblock ~82 ~3 ~79 wool 12  
fill ~82 ~3 ~91 ~83 ~3 ~91 dirt 0 
setblock ~83 ~3 ~18 log 1  
fill ~83 ~3 ~48 ~83 ~3 ~49 mycelium 0  
fill ~83 ~3 ~79 ~85 ~3 ~79 planks 0 
setblock ~83 ~3 ~85 dirt 0  
fill ~83 ~3 ~86 ~84 ~3 ~86 grass 0  
fill ~83 ~3 ~87 ~85 ~3 ~87 grass 0  
fill ~83 ~3 ~88 ~86 ~3 ~88 grass 0  
fill ~83 ~3 ~89 ~86 ~3 ~89 grass 0  
fill ~83 ~3 ~92 ~85 ~3 ~92 dirt 0  
fill ~84 ~3 ~47 ~88 ~3 ~47 dirt 0  
fill ~84 ~3 ~54 ~85 ~3 ~54 planks 0  
fill ~84 ~3 ~85 ~85 ~3 ~85 grass 0  
fill ~84 ~3 ~90 ~87 ~3 ~90 grass 0  
fill ~84 ~3 ~91 ~88 ~3 ~91 grass 0  
fill ~84 ~3 ~93 ~86 ~3 ~93 dirt 0  
fill ~84 ~3 ~107 ~86 ~3 ~107 dirt 0  
fill ~85 ~3 ~2 ~88 ~3 ~2 bedrock 0  
fill ~85 ~3 ~3 ~88 ~3 ~3 log 1  
fill ~85 ~3 ~55 ~85 ~3 ~58 dirt 0  
fill ~85 ~3 ~59 ~87 ~3 ~59 planks 0  
fill ~85 ~3 ~60 ~87 ~3 ~60 planks 0  
fill ~85 ~3 ~61 ~87 ~3 ~61 planks 0  
fill ~85 ~3 ~62 ~87 ~3 ~62 planks 0  
fill ~85 ~3 ~63 ~87 ~3 ~63 planks 0  
fill ~85 ~3 ~64 ~85 ~3 ~82 planks 0  
fill ~85 ~3 ~83 ~88 ~3 ~83 grass 0  
fill ~85 ~3 ~84 ~85 ~3 ~83 grass 0  
fill ~85 ~3 ~86 ~86 ~3 ~86 stone_slab 1  
fill ~86 ~3 ~15 ~88 ~3 ~15 stone 0  
fill ~86 ~3 ~16 ~87 ~3 ~16 stone 0  
fill ~86 ~3 ~55 ~89 ~3 ~55 grass 0  
fill ~86 ~3 ~56 ~89 ~3 ~56 grass 0  
fill ~86 ~3 ~57 ~89 ~3 ~57 grass 0  
fill ~86 ~3 ~58 ~88 ~3 ~58 dirt 0  
fill ~86 ~3 ~64 ~88 ~3 ~64 dirt 0  
fill ~86 ~3 ~65 ~88 ~3 ~65 dirt 0  
fill ~86 ~3 ~66 ~88 ~3 ~66 dirt 0  
fill ~86 ~3 ~67 ~88 ~3 ~67 dirt 0  
fill ~86 ~3 ~68 ~88 ~3 ~68 dirt 0  
fill ~86 ~3 ~69 ~88 ~3 ~69 dirt 0  
fill ~86 ~3 ~70 ~88 ~3 ~70 dirt 0  
fill ~86 ~3 ~71 ~103 ~3 ~71 grass 0  
fill ~86 ~3 ~72 ~102 ~3 ~72 grass 0  
fill ~86 ~3 ~73 ~90 ~3 ~73 grass 0  
fill ~86 ~3 ~74 ~89 ~3 ~74 grass 0  
fill ~86 ~3 ~75 ~89 ~3 ~75 grass 0  
fill ~86 ~3 ~76 ~89 ~3 ~76 grass 0  
fill ~86 ~3 ~77 ~88 ~3 ~77 grass 0  
fill ~86 ~3 ~78 ~90 ~3 ~78 grass 0  
fill ~86 ~3 ~79 ~88 ~3 ~79 grass 0  
fill ~86 ~3 ~80 ~88 ~3 ~80 grass 0  
fill ~86 ~3 ~81 ~88 ~3 ~81 grass 0  
fill ~86 ~3 ~82 ~88 ~3 ~82 grass 0  
fill ~86 ~3 ~84 ~86 ~3 ~86 stone_slab 1  
fill ~86 ~3 ~92 ~88 ~3 ~92 grass 0  
fill ~86 ~3 ~94 ~87 ~3 ~94 dirt 0  
fill ~86 ~3 ~106 ~87 ~3 ~106 dirt 0 
setblock ~87 ~3 ~14 stone 0  
fill ~87 ~3 ~93 ~88 ~3 ~93 grass 0  
fill ~87 ~3 ~95 ~89 ~3 ~95 dirt 0  
fill ~87 ~3 ~105 ~88 ~3 ~105 dirt 0 
setblock ~88 ~3 ~54 grass 0  
fill ~88 ~3 ~59 ~88 ~3 ~70 dirt 0 
setblock ~88 ~3 ~94 grass 0  
fill ~88 ~3 ~96 ~89 ~3 ~96 dirt 0  
fill ~88 ~3 ~97 ~90 ~3 ~97 dirt 0  
fill ~89 ~3 ~3 ~91 ~3 ~3 bedrock 0  
fill ~89 ~3 ~4 ~91 ~3 ~4 log 1 
setblock ~89 ~3 ~8 log 1 
setblock ~89 ~3 ~15 log 1  
fill ~89 ~3 ~58 ~89 ~3 ~76 grass 0 
setblock ~89 ~3 ~77 dirt 0  
fill ~89 ~3 ~98 ~101 ~3 ~98 dirt 0  
fill ~89 ~3 ~99 ~93 ~3 ~99 dirt 0 
setblock ~89 ~3 ~105 grass 0  
fill ~90 ~3 ~21 ~90 ~6 ~21 log 1 
setblock ~90 ~3 ~23 log 1  
fill ~90 ~3 ~67 ~113 ~3 ~67 grass 0  
fill ~90 ~3 ~68 ~113 ~3 ~68 grass 0  
fill ~90 ~3 ~69 ~113 ~3 ~69 grass 0  
fill ~90 ~3 ~70 ~113 ~3 ~70 grass 0  
fill ~90 ~3 ~74 ~90 ~3 ~76 dirt 0  
fill ~90 ~3 ~77 ~91 ~3 ~77 grass 0  
fill ~90 ~3 ~83 ~92 ~3 ~83 grass 0  
fill ~90 ~3 ~84 ~92 ~3 ~84 grass 0  
fill ~90 ~3 ~85 ~90 ~3 ~87 stone_slab 1  
fill ~90 ~3 ~88 ~92 ~3 ~88 grass 0  
fill ~90 ~3 ~89 ~91 ~3 ~89 grass 0  
fill ~90 ~3 ~95 ~91 ~3 ~95 grass 0  
fill ~90 ~3 ~96 ~92 ~3 ~96 grass 0  
fill ~90 ~3 ~100 ~98 ~3 ~100 dirt 0  
fill ~90 ~3 ~105 ~91 ~3 ~105 dirt 0  
fill ~91 ~3 ~26 ~91 ~4 ~26 log 1  
fill ~91 ~3 ~52 ~91 ~5 ~52 log 1  
fill ~91 ~3 ~73 ~92 ~3 ~73 dirt 0  
fill ~91 ~3 ~74 ~95 ~3 ~74 grass 0  
fill ~91 ~3 ~75 ~91 ~3 ~77 grass 0  
fill ~91 ~3 ~82 ~94 ~3 ~82 grass 0  
fill ~91 ~3 ~85 ~97 ~3 ~85 grass 0  
fill ~91 ~3 ~86 ~98 ~3 ~86 grass 0  
fill ~91 ~3 ~87 ~97 ~3 ~87 grass 0  
fill ~91 ~3 ~97 ~97 ~3 ~97 grass 0  
fill ~92 ~3 ~4 ~92 ~4 ~4 bedrock 0  
fill ~92 ~3 ~5 ~92 ~6 ~5 log 1  
fill ~92 ~3 ~54 ~92 ~7 ~54 log 1  
fill ~92 ~3 ~81 ~95 ~3 ~81 grass 0 
setblock ~92 ~3 ~89 cobblestone 0  
fill ~92 ~3 ~103 ~92 ~5 ~103 log 1  
fill ~92 ~3 ~104 ~92 ~6 ~104 log 1  
fill ~93 ~3 ~3 ~93 ~4 ~3 bedrock 0  
fill ~93 ~3 ~4 ~93 ~6 ~4 log 1  
fill ~93 ~3 ~28 ~93 ~4 ~28 log 1  
fill ~93 ~3 ~73 ~94 ~3 ~73 grass 0  
fill ~93 ~3 ~75 ~96 ~3 ~75 grass 0  
fill ~93 ~3 ~83 ~94 ~3 ~83 dirt 0  
fill ~93 ~3 ~84 ~93 ~3 ~83 dirt 0  
fill ~93 ~3 ~88 ~94 ~3 ~88 dirt 0 
setblock ~93 ~3 ~90 cobblestone 0 
setblock ~93 ~3 ~102 dirt 0  
