setblock ~1 ~0 ~32 quartz_block 0  
fill ~1 ~0 ~33 ~1 ~0 ~41 stone_slab 7 
setblock ~1 ~0 ~42 quartz_block 0  
fill ~2 ~0 ~33 ~3 ~0 ~33 quartz_block 0  
fill ~2 ~0 ~34 ~3 ~0 ~34 quartz_block 0  
fill ~2 ~0 ~35 ~2 ~0 ~41 quartz_block 0 
setblock ~3 ~0 ~35 stained_hardened_clay 3  
fill ~3 ~0 ~36 ~3 ~0 ~41 quartz_block 0  
fill ~4 ~0 ~35 ~8 ~0 ~35 quartz_block 0  
fill ~4 ~0 ~39 ~8 ~0 ~39 quartz_block 0  
fill ~5 ~0 ~20 ~5 ~3 ~20 stained_hardened_clay 3  
fill ~5 ~0 ~21 ~5 ~3 ~21 stained_hardened_clay 3  
fill ~5 ~0 ~22 ~5 ~3 ~22 stained_hardened_clay 3  
fill ~5 ~0 ~52 ~5 ~3 ~52 stained_hardened_clay 3  
fill ~5 ~0 ~53 ~5 ~3 ~53 stained_hardened_clay 3  
fill ~5 ~0 ~54 ~5 ~3 ~54 stained_hardened_clay 3  
fill ~6 ~0 ~19 ~6 ~3 ~19 stained_hardened_clay 3  
fill ~6 ~0 ~23 ~9 ~0 ~23 stained_hardened_clay 3  
fill ~6 ~0 ~51 ~9 ~0 ~51 stained_hardened_clay 3  
fill ~6 ~0 ~55 ~6 ~3 ~55 stained_hardened_clay 3  
fill ~7 ~0 ~16 ~7 ~3 ~16 stained_hardened_clay 3  
fill ~7 ~0 ~17 ~7 ~3 ~17 stained_hardened_clay 3  
fill ~7 ~0 ~18 ~7 ~3 ~18 stained_hardened_clay 3  
fill ~7 ~0 ~56 ~7 ~3 ~56 stained_hardened_clay 3  
fill ~7 ~0 ~57 ~7 ~3 ~57 stained_hardened_clay 3  
fill ~7 ~0 ~58 ~7 ~3 ~58 stained_hardened_clay 3  
fill ~8 ~0 ~13 ~8 ~3 ~13 stained_hardened_clay 3  
fill ~8 ~0 ~14 ~8 ~3 ~14 stained_hardened_clay 3  
fill ~8 ~0 ~15 ~8 ~3 ~15 stained_hardened_clay 3  
fill ~8 ~0 ~59 ~8 ~3 ~59 stained_hardened_clay 3  
fill ~8 ~0 ~60 ~8 ~3 ~60 stained_hardened_clay 3  
fill ~8 ~0 ~61 ~8 ~3 ~61 stained_hardened_clay 3  
fill ~9 ~0 ~11 ~9 ~3 ~11 stained_hardened_clay 3  
fill ~9 ~0 ~12 ~9 ~3 ~12 stained_hardened_clay 3  
fill ~9 ~0 ~27 ~9 ~3 ~27 stained_hardened_clay 3  
fill ~9 ~0 ~28 ~9 ~3 ~28 stained_hardened_clay 3  
fill ~9 ~0 ~29 ~9 ~3 ~29 stained_hardened_clay 3  
fill ~9 ~0 ~34 ~9 ~5 ~34 quartz_block 2  
fill ~9 ~0 ~40 ~9 ~5 ~40 quartz_block 2  
fill ~9 ~0 ~45 ~9 ~3 ~45 stained_hardened_clay 3  
fill ~9 ~0 ~46 ~9 ~3 ~46 stained_hardened_clay 3  
fill ~9 ~0 ~47 ~9 ~3 ~47 stained_hardened_clay 3  
fill ~9 ~0 ~62 ~9 ~3 ~62 stained_hardened_clay 3  
fill ~9 ~0 ~63 ~9 ~3 ~63 stained_hardened_clay 3  
fill ~10 ~0 ~10 ~10 ~3 ~10 stained_hardened_clay 3  
fill ~10 ~0 ~24 ~10 ~3 ~24 stained_hardened_clay 3  
fill ~10 ~0 ~25 ~10 ~3 ~25 stained_hardened_clay 3  
fill ~10 ~0 ~26 ~10 ~3 ~26 stained_hardened_clay 3  
fill ~10 ~0 ~30 ~10 ~3 ~30 stained_hardened_clay 3  
fill ~10 ~0 ~35 ~10 ~3 ~35 stained_hardened_clay 3  
fill ~10 ~0 ~39 ~10 ~3 ~39 stained_hardened_clay 3  
fill ~10 ~0 ~44 ~10 ~3 ~44 stained_hardened_clay 3  
fill ~10 ~0 ~48 ~10 ~3 ~48 stained_hardened_clay 3  
fill ~10 ~0 ~49 ~10 ~3 ~49 stained_hardened_clay 3  
fill ~10 ~0 ~50 ~10 ~3 ~50 stained_hardened_clay 3  
fill ~10 ~0 ~64 ~10 ~3 ~64 stained_hardened_clay 3  
fill ~11 ~0 ~9 ~12 ~0 ~9 stained_hardened_clay 3  
fill ~11 ~0 ~31 ~11 ~3 ~31 stained_hardened_clay 3  
fill ~11 ~0 ~32 ~11 ~3 ~32 stained_hardened_clay 3  
fill ~11 ~0 ~33 ~11 ~3 ~33 stained_hardened_clay 3  
fill ~11 ~0 ~34 ~11 ~3 ~34 stained_hardened_clay 3  
fill ~11 ~0 ~40 ~11 ~3 ~40 stained_hardened_clay 3  
fill ~11 ~0 ~41 ~11 ~3 ~41 stained_hardened_clay 3  
fill ~11 ~0 ~42 ~11 ~3 ~42 stained_hardened_clay 3  
fill ~11 ~0 ~43 ~11 ~3 ~43 stained_hardened_clay 3  
fill ~11 ~0 ~65 ~12 ~0 ~65 stained_hardened_clay 3  
fill ~13 ~0 ~8 ~15 ~0 ~8 stained_hardened_clay 3  
fill ~13 ~0 ~66 ~15 ~0 ~66 stained_hardened_clay 3  
fill ~16 ~0 ~7 ~18 ~0 ~7 stained_hardened_clay 3  
fill ~16 ~0 ~67 ~18 ~0 ~67 stained_hardened_clay 3  
fill ~19 ~0 ~6 ~19 ~3 ~6 stained_hardened_clay 3  
fill ~19 ~0 ~68 ~19 ~3 ~68 stained_hardened_clay 3  
fill ~20 ~0 ~5 ~22 ~0 ~5 stained_hardened_clay 3  
fill ~20 ~0 ~69 ~22 ~0 ~69 stained_hardened_clay 3  
fill ~23 ~0 ~6 ~23 ~3 ~6 stained_hardened_clay 3  
fill ~23 ~0 ~7 ~23 ~3 ~7 stained_hardened_clay 3  
fill ~23 ~0 ~8 ~23 ~3 ~8 stained_hardened_clay 3  
fill ~23 ~0 ~9 ~23 ~4 ~9 stained_hardened_clay 3  
fill ~23 ~0 ~65 ~23 ~4 ~65 stained_hardened_clay 3  
fill ~23 ~0 ~66 ~23 ~3 ~66 stained_hardened_clay 3  
fill ~23 ~0 ~67 ~23 ~3 ~67 stained_hardened_clay 3  
fill ~23 ~0 ~68 ~23 ~3 ~68 stained_hardened_clay 3  
fill ~24 ~0 ~10 ~26 ~0 ~10 stained_hardened_clay 3  
fill ~24 ~0 ~64 ~26 ~0 ~64 stained_hardened_clay 3  
fill ~27 ~0 ~9 ~29 ~0 ~9 stained_hardened_clay 3  
fill ~27 ~0 ~65 ~29 ~0 ~65 stained_hardened_clay 3  
fill ~30 ~0 ~10 ~30 ~3 ~10 stained_hardened_clay 3  
fill ~30 ~0 ~64 ~30 ~3 ~64 stained_hardened_clay 3  
fill ~31 ~0 ~11 ~34 ~0 ~11 stained_hardened_clay 3  
fill ~31 ~0 ~63 ~34 ~0 ~63 stained_hardened_clay 3 
setblock ~32 ~0 ~1 quartz_block 0 
setblock ~32 ~0 ~73 quartz_block 0  
fill ~33 ~0 ~1 ~41 ~0 ~1 stone_slab 7  
fill ~33 ~0 ~2 ~41 ~0 ~2 quartz_block 0  
fill ~33 ~0 ~3 ~38 ~0 ~3 quartz_block 0  
fill ~33 ~0 ~71 ~34 ~0 ~71 quartz_block 0  
fill ~33 ~0 ~72 ~41 ~0 ~72 quartz_block 0  
fill ~33 ~0 ~73 ~41 ~0 ~73 stone_slab 7  
fill ~34 ~0 ~9 ~34 ~5 ~9 quartz_block 2  
fill ~34 ~0 ~65 ~34 ~5 ~65 quartz_block 2  
fill ~35 ~0 ~4 ~35 ~1 ~4 quartz_block 0  
fill ~35 ~0 ~5 ~35 ~1 ~5 quartz_block 0  
fill ~35 ~0 ~6 ~35 ~2 ~6 quartz_block 0  
fill ~35 ~0 ~7 ~35 ~2 ~7 quartz_block 0  
fill ~35 ~0 ~8 ~35 ~3 ~8 quartz_block 0  
fill ~35 ~0 ~10 ~35 ~3 ~10 stained_hardened_clay 3  
fill ~35 ~0 ~64 ~35 ~3 ~64 stained_hardened_clay 3  
fill ~35 ~0 ~66 ~35 ~3 ~66 quartz_block 0  
fill ~35 ~0 ~67 ~35 ~2 ~67 quartz_block 0  
fill ~35 ~0 ~68 ~35 ~2 ~68 quartz_block 0  
fill ~35 ~0 ~69 ~35 ~1 ~69 quartz_block 0  
fill ~35 ~0 ~70 ~35 ~1 ~70 quartz_block 0 
setblock ~35 ~0 ~71 stained_hardened_clay 3  
fill ~36 ~0 ~71 ~41 ~0 ~71 quartz_block 0  
fill ~37 ~0 ~37 ~37 ~2 ~37 quartz_block 0 
setblock ~39 ~0 ~3 stained_hardened_clay 3  
fill ~39 ~0 ~4 ~39 ~1 ~4 quartz_block 0  
fill ~39 ~0 ~5 ~39 ~1 ~5 quartz_block 0  
fill ~39 ~0 ~6 ~39 ~2 ~6 quartz_block 0  
fill ~39 ~0 ~7 ~39 ~2 ~7 quartz_block 0  
fill ~39 ~0 ~8 ~39 ~3 ~8 quartz_block 0  
fill ~39 ~0 ~10 ~39 ~3 ~10 stained_hardened_clay 3  
fill ~39 ~0 ~64 ~39 ~3 ~64 stained_hardened_clay 3  
fill ~39 ~0 ~66 ~39 ~3 ~66 quartz_block 0  
fill ~39 ~0 ~67 ~39 ~2 ~67 quartz_block 0  
fill ~39 ~0 ~68 ~39 ~2 ~68 quartz_block 0  
fill ~39 ~0 ~69 ~39 ~1 ~69 quartz_block 0  
fill ~39 ~0 ~70 ~39 ~1 ~70 quartz_block 0  
fill ~40 ~0 ~3 ~41 ~0 ~3 quartz_block 0  
fill ~40 ~0 ~9 ~40 ~5 ~9 quartz_block 2  
fill ~40 ~0 ~11 ~43 ~0 ~11 stained_hardened_clay 3  
fill ~40 ~0 ~63 ~43 ~0 ~63 stained_hardened_clay 3  
fill ~40 ~0 ~65 ~40 ~5 ~65 quartz_block 2 
setblock ~42 ~0 ~1 quartz_block 0 
setblock ~42 ~0 ~73 quartz_block 0  
fill ~44 ~0 ~10 ~44 ~3 ~10 stained_hardened_clay 3  
fill ~44 ~0 ~64 ~44 ~3 ~64 stained_hardened_clay 3  
fill ~45 ~0 ~9 ~47 ~0 ~9 stained_hardened_clay 3  
fill ~45 ~0 ~65 ~47 ~0 ~65 stained_hardened_clay 3  
fill ~48 ~0 ~10 ~50 ~0 ~10 stained_hardened_clay 3  
fill ~48 ~0 ~64 ~50 ~0 ~64 stained_hardened_clay 3  
fill ~51 ~0 ~6 ~51 ~3 ~6 stained_hardened_clay 3  
fill ~51 ~0 ~7 ~51 ~3 ~7 stained_hardened_clay 3  
fill ~51 ~0 ~8 ~51 ~3 ~8 stained_hardened_clay 3  
fill ~51 ~0 ~9 ~51 ~4 ~9 stained_hardened_clay 3  
fill ~51 ~0 ~65 ~51 ~4 ~65 stained_hardened_clay 3  
fill ~51 ~0 ~66 ~51 ~3 ~66 stained_hardened_clay 3  
fill ~51 ~0 ~67 ~51 ~3 ~67 stained_hardened_clay 3  
fill ~51 ~0 ~68 ~51 ~3 ~68 stained_hardened_clay 3  
fill ~52 ~0 ~5 ~54 ~0 ~5 stained_hardened_clay 3  
fill ~52 ~0 ~69 ~54 ~0 ~69 stained_hardened_clay 3  
fill ~55 ~0 ~6 ~55 ~3 ~6 stained_hardened_clay 3  
fill ~55 ~0 ~68 ~55 ~3 ~68 stained_hardened_clay 3  
fill ~56 ~0 ~7 ~58 ~0 ~7 stained_hardened_clay 3  
fill ~56 ~0 ~67 ~58 ~0 ~67 stained_hardened_clay 3  
fill ~59 ~0 ~8 ~61 ~0 ~8 stained_hardened_clay 3  
fill ~59 ~0 ~66 ~61 ~0 ~66 stained_hardened_clay 3  
fill ~62 ~0 ~9 ~63 ~0 ~9 stained_hardened_clay 3  
fill ~62 ~0 ~65 ~63 ~0 ~65 stained_hardened_clay 3  
fill ~63 ~0 ~31 ~63 ~3 ~31 stained_hardened_clay 3  
fill ~63 ~0 ~32 ~63 ~3 ~32 stained_hardened_clay 3  
fill ~63 ~0 ~33 ~63 ~3 ~33 stained_hardened_clay 3  
fill ~63 ~0 ~34 ~63 ~3 ~34 stained_hardened_clay 3  
fill ~63 ~0 ~40 ~63 ~3 ~40 stained_hardened_clay 3  
fill ~63 ~0 ~41 ~63 ~3 ~41 stained_hardened_clay 3  
fill ~63 ~0 ~42 ~63 ~3 ~42 stained_hardened_clay 3  
fill ~63 ~0 ~43 ~63 ~3 ~43 stained_hardened_clay 3  
fill ~64 ~0 ~10 ~64 ~3 ~10 stained_hardened_clay 3  
fill ~64 ~0 ~24 ~64 ~3 ~24 stained_hardened_clay 3  
fill ~64 ~0 ~25 ~64 ~3 ~25 stained_hardened_clay 3  
fill ~64 ~0 ~26 ~64 ~3 ~26 stained_hardened_clay 3  
fill ~64 ~0 ~30 ~64 ~3 ~30 stained_hardened_clay 3  
fill ~64 ~0 ~35 ~64 ~3 ~35 stained_hardened_clay 3  
fill ~64 ~0 ~39 ~64 ~3 ~39 stained_hardened_clay 3  
fill ~64 ~0 ~44 ~64 ~3 ~44 stained_hardened_clay 3  
fill ~64 ~0 ~48 ~64 ~3 ~48 stained_hardened_clay 3  
fill ~64 ~0 ~49 ~64 ~3 ~49 stained_hardened_clay 3  
fill ~64 ~0 ~50 ~64 ~3 ~50 stained_hardened_clay 3  
fill ~64 ~0 ~64 ~64 ~3 ~64 stained_hardened_clay 3  
fill ~65 ~0 ~11 ~65 ~3 ~11 stained_hardened_clay 3  
fill ~65 ~0 ~12 ~65 ~3 ~12 stained_hardened_clay 3  
fill ~65 ~0 ~23 ~68 ~0 ~23 stained_hardened_clay 3  
fill ~65 ~0 ~27 ~65 ~3 ~27 stained_hardened_clay 3  
fill ~65 ~0 ~28 ~65 ~3 ~28 stained_hardened_clay 3  
fill ~65 ~0 ~29 ~65 ~3 ~29 stained_hardened_clay 3  
fill ~65 ~0 ~34 ~65 ~5 ~34 quartz_block 2  
fill ~65 ~0 ~40 ~65 ~5 ~40 quartz_block 2  
fill ~65 ~0 ~45 ~65 ~3 ~45 stained_hardened_clay 3  
fill ~65 ~0 ~46 ~65 ~3 ~46 stained_hardened_clay 3  
fill ~65 ~0 ~47 ~65 ~3 ~47 stained_hardened_clay 3  
fill ~65 ~0 ~51 ~68 ~0 ~51 stained_hardened_clay 3  
fill ~65 ~0 ~62 ~65 ~3 ~62 stained_hardened_clay 3  
fill ~65 ~0 ~63 ~65 ~3 ~63 stained_hardened_clay 3  
fill ~66 ~0 ~13 ~66 ~3 ~13 stained_hardened_clay 3  
fill ~66 ~0 ~14 ~66 ~3 ~14 stained_hardened_clay 3  
fill ~66 ~0 ~15 ~66 ~3 ~15 stained_hardened_clay 3  
fill ~66 ~0 ~35 ~72 ~0 ~35 quartz_block 0  
fill ~66 ~0 ~39 ~70 ~0 ~39 quartz_block 0  
fill ~66 ~0 ~59 ~66 ~3 ~59 stained_hardened_clay 3  
fill ~66 ~0 ~60 ~66 ~3 ~60 stained_hardened_clay 3  
fill ~66 ~0 ~61 ~66 ~3 ~61 stained_hardened_clay 3  
fill ~67 ~0 ~16 ~67 ~3 ~16 stained_hardened_clay 3  
fill ~67 ~0 ~17 ~67 ~3 ~17 stained_hardened_clay 3  
fill ~67 ~0 ~18 ~67 ~3 ~18 stained_hardened_clay 3  
fill ~67 ~0 ~56 ~67 ~3 ~56 stained_hardened_clay 3  
fill ~67 ~0 ~57 ~67 ~3 ~57 stained_hardened_clay 3  
fill ~67 ~0 ~58 ~67 ~3 ~58 stained_hardened_clay 3  
fill ~68 ~0 ~19 ~68 ~3 ~19 stained_hardened_clay 3  
fill ~68 ~0 ~55 ~68 ~3 ~55 stained_hardened_clay 3  
fill ~69 ~0 ~20 ~69 ~3 ~20 stained_hardened_clay 3  
fill ~69 ~0 ~21 ~69 ~3 ~21 stained_hardened_clay 3  
fill ~69 ~0 ~22 ~69 ~3 ~22 stained_hardened_clay 3  
fill ~69 ~0 ~52 ~69 ~3 ~52 stained_hardened_clay 3  
fill ~69 ~0 ~53 ~69 ~3 ~53 stained_hardened_clay 3  
fill ~69 ~0 ~54 ~69 ~3 ~54 stained_hardened_clay 3  
fill ~71 ~0 ~33 ~72 ~0 ~33 quartz_block 0  
fill ~71 ~0 ~34 ~72 ~0 ~34 quartz_block 0  
fill ~71 ~0 ~36 ~72 ~0 ~36 quartz_block 0  
fill ~71 ~0 ~37 ~72 ~0 ~37 quartz_block 0  
fill ~71 ~0 ~38 ~72 ~0 ~38 quartz_block 0 
setblock ~71 ~0 ~39 stained_hardened_clay 3  
fill ~71 ~0 ~40 ~72 ~0 ~40 quartz_block 0  
fill ~71 ~0 ~41 ~72 ~0 ~41 quartz_block 0 
setblock ~72 ~0 ~39 quartz_block 0 
setblock ~73 ~0 ~32 quartz_block 0  
fill ~73 ~0 ~33 ~73 ~0 ~41 stone_slab 7 
setblock ~73 ~0 ~42 quartz_block 0 
setblock ~2 ~1 ~33 stone_slab 7 
setblock ~2 ~1 ~41 stone_slab 7 
setblock ~3 ~1 ~33 quartz_block 0  
fill ~3 ~1 ~34 ~3 ~1 ~40 stone_slab 7 
setblock ~3 ~1 ~41 quartz_block 0  
fill ~4 ~1 ~34 ~4 ~1 ~40 quartz_block 0 
setblock ~5 ~1 ~34 stone_slab 15  
fill ~5 ~1 ~35 ~8 ~1 ~35 quartz_block 0  
fill ~5 ~1 ~36 ~5 ~1 ~39 quartz_block 0 
setblock ~5 ~1 ~40 stone_slab 15  
fill ~6 ~1 ~23 ~9 ~1 ~23 stained_hardened_clay 3  
fill ~6 ~1 ~39 ~8 ~1 ~39 quartz_block 0  
fill ~6 ~1 ~51 ~9 ~1 ~51 stained_hardened_clay 3  
fill ~11 ~1 ~9 ~12 ~1 ~9 stained_hardened_clay 3  
fill ~11 ~1 ~65 ~12 ~1 ~65 stained_hardened_clay 3  
fill ~13 ~1 ~8 ~15 ~1 ~8 stained_hardened_clay 3  
fill ~13 ~1 ~66 ~15 ~1 ~66 stained_hardened_clay 3  
fill ~16 ~1 ~7 ~18 ~1 ~7 stained_hardened_clay 3  
fill ~16 ~1 ~67 ~18 ~1 ~67 stained_hardened_clay 3  
fill ~20 ~1 ~5 ~22 ~1 ~5 stained_hardened_clay 3  
fill ~20 ~1 ~69 ~22 ~1 ~69 stained_hardened_clay 3  
fill ~24 ~1 ~10 ~26 ~1 ~10 stained_hardened_clay 3  
fill ~24 ~1 ~64 ~26 ~1 ~64 stained_hardened_clay 3  
fill ~27 ~1 ~9 ~29 ~1 ~9 stained_hardened_clay 3  
fill ~27 ~1 ~65 ~29 ~1 ~65 stained_hardened_clay 3  
fill ~31 ~1 ~11 ~34 ~1 ~11 stained_hardened_clay 3  
fill ~31 ~1 ~63 ~34 ~1 ~63 stained_hardened_clay 3 
setblock ~33 ~1 ~2 stone_slab 7  
fill ~33 ~1 ~3 ~33 ~0 ~3 quartz_block 0  
fill ~33 ~1 ~71 ~33 ~0 ~71 quartz_block 0 
setblock ~33 ~1 ~72 stone_slab 7  
fill ~34 ~1 ~3 ~40 ~1 ~3 stone_slab 7 
setblock ~34 ~1 ~4 quartz_block 0 
setblock ~34 ~1 ~5 stone_slab 15 
setblock ~34 ~1 ~69 stone_slab 15 
setblock ~34 ~1 ~70 quartz_block 0  
fill ~34 ~1 ~71 ~40 ~1 ~71 stone_slab 7  
fill ~36 ~1 ~4 ~40 ~1 ~4 quartz_block 0  
fill ~36 ~1 ~5 ~39 ~1 ~5 quartz_block 0  
fill ~36 ~1 ~69 ~39 ~1 ~69 quartz_block 0  
fill ~36 ~1 ~70 ~40 ~1 ~70 quartz_block 0 
setblock ~40 ~1 ~5 stone_slab 15  
fill ~40 ~1 ~11 ~43 ~1 ~11 stained_hardened_clay 3  
fill ~40 ~1 ~63 ~43 ~1 ~63 stained_hardened_clay 3 
setblock ~40 ~1 ~69 stone_slab 15 
setblock ~41 ~1 ~2 stone_slab 7 
setblock ~41 ~1 ~3 quartz_block 0 
setblock ~41 ~1 ~71 quartz_block 0 
setblock ~41 ~1 ~72 stone_slab 7  
fill ~45 ~1 ~9 ~47 ~1 ~9 stained_hardened_clay 3  
fill ~45 ~1 ~65 ~47 ~1 ~65 stained_hardened_clay 3  
fill ~48 ~1 ~10 ~50 ~1 ~10 stained_hardened_clay 3  
fill ~48 ~1 ~64 ~50 ~1 ~64 stained_hardened_clay 3  
fill ~52 ~1 ~5 ~54 ~1 ~5 stained_hardened_clay 3  
fill ~52 ~1 ~69 ~54 ~1 ~69 stained_hardened_clay 3  
fill ~56 ~1 ~7 ~58 ~1 ~7 stained_hardened_clay 3  
fill ~56 ~1 ~67 ~58 ~1 ~67 stained_hardened_clay 3  
fill ~59 ~1 ~8 ~61 ~1 ~8 stained_hardened_clay 3  
fill ~59 ~1 ~66 ~61 ~1 ~66 stained_hardened_clay 3  
fill ~62 ~1 ~9 ~63 ~1 ~9 stained_hardened_clay 3  
fill ~62 ~1 ~65 ~63 ~1 ~65 stained_hardened_clay 3  
fill ~65 ~1 ~23 ~68 ~1 ~23 stained_hardened_clay 3  
fill ~65 ~1 ~51 ~68 ~1 ~51 stained_hardened_clay 3  
fill ~66 ~1 ~35 ~70 ~1 ~35 quartz_block 0  
fill ~66 ~1 ~39 ~70 ~1 ~39 quartz_block 0 
setblock ~69 ~1 ~34 stone_slab 15  
fill ~69 ~1 ~36 ~70 ~1 ~36 quartz_block 0  
fill ~69 ~1 ~37 ~70 ~1 ~37 quartz_block 0  
fill ~69 ~1 ~38 ~70 ~1 ~38 quartz_block 0 
setblock ~69 ~1 ~40 stone_slab 15 
setblock ~70 ~1 ~34 quartz_block 0 
setblock ~70 ~1 ~40 quartz_block 0  
fill ~71 ~1 ~33 ~71 ~0 ~33 quartz_block 0  
fill ~71 ~1 ~34 ~71 ~1 ~40 stone_slab 7  
fill ~71 ~1 ~41 ~71 ~0 ~41 quartz_block 0 
setblock ~72 ~1 ~33 stone_slab 7 
setblock ~72 ~1 ~41 stone_slab 7 
setblock ~4 ~2 ~34 stone_slab 7 
setblock ~4 ~2 ~40 stone_slab 7  
fill ~5 ~2 ~34 ~6 ~2 ~34 quartz_block 0  
fill ~5 ~2 ~35 ~5 ~2 ~39 stone_slab 7  
fill ~5 ~2 ~40 ~6 ~2 ~40 quartz_block 0  
fill ~6 ~2 ~23 ~9 ~2 ~23 stained_hardened_clay 3  
fill ~6 ~2 ~35 ~8 ~2 ~35 quartz_block 0  
fill ~6 ~2 ~36 ~7 ~2 ~36 quartz_block 0  
fill ~6 ~2 ~37 ~7 ~2 ~37 quartz_block 0  
fill ~6 ~2 ~38 ~7 ~2 ~38 quartz_block 0  
fill ~6 ~2 ~39 ~8 ~2 ~39 quartz_block 0  
fill ~6 ~2 ~51 ~9 ~2 ~51 stained_hardened_clay 3 
setblock ~7 ~2 ~34 stone_slab 15 
setblock ~7 ~2 ~40 stone_slab 15  
fill ~11 ~2 ~9 ~12 ~2 ~9 stained_hardened_clay 3  
fill ~11 ~2 ~65 ~12 ~2 ~65 stained_hardened_clay 3  
fill ~13 ~2 ~8 ~15 ~2 ~8 stained_hardened_clay 3  
fill ~13 ~2 ~66 ~15 ~2 ~66 stained_hardened_clay 3  
fill ~16 ~2 ~7 ~18 ~2 ~7 stained_hardened_clay 3  
fill ~16 ~2 ~67 ~18 ~2 ~67 stained_hardened_clay 3 
setblock ~17 ~2 ~37 quartz_block 0  
fill ~20 ~2 ~5 ~22 ~2 ~5 stained_hardened_clay 3  
fill ~20 ~2 ~69 ~22 ~2 ~69 stained_hardened_clay 3 
setblock ~21 ~2 ~37 quartz_block 0  
fill ~24 ~2 ~10 ~26 ~2 ~10 stained_hardened_clay 3  
fill ~24 ~2 ~64 ~26 ~2 ~64 stained_hardened_clay 3 
setblock ~25 ~2 ~25 quartz_block 0 
setblock ~25 ~2 ~29 quartz_block 0 
setblock ~25 ~2 ~33 quartz_block 0 
setblock ~25 ~2 ~37 quartz_block 0 
setblock ~25 ~2 ~41 quartz_block 0 
setblock ~25 ~2 ~45 quartz_block 0 
setblock ~25 ~2 ~49 quartz_block 0  
fill ~27 ~2 ~9 ~29 ~2 ~9 stained_hardened_clay 3  
fill ~27 ~2 ~65 ~29 ~2 ~65 stained_hardened_clay 3 
setblock ~29 ~2 ~25 quartz_block 0 
setblock ~29 ~2 ~29 quartz_block 0 
setblock ~29 ~2 ~33 quartz_block 0 
setblock ~29 ~2 ~37 quartz_block 0 
setblock ~29 ~2 ~41 quartz_block 0 
setblock ~29 ~2 ~45 quartz_block 0 
setblock ~29 ~2 ~49 quartz_block 0  
fill ~31 ~2 ~11 ~34 ~2 ~11 stained_hardened_clay 3  
fill ~31 ~2 ~63 ~34 ~2 ~63 stained_hardened_clay 3 
setblock ~33 ~2 ~25 quartz_block 0 
setblock ~33 ~2 ~29 quartz_block 0 
setblock ~33 ~2 ~33 quartz_block 0 
setblock ~33 ~2 ~37 quartz_block 0 
setblock ~33 ~2 ~41 quartz_block 0 
setblock ~33 ~2 ~45 quartz_block 0 
setblock ~33 ~2 ~49 quartz_block 0 
setblock ~34 ~2 ~4 stone_slab 7  
fill ~34 ~2 ~5 ~34 ~2 ~6 quartz_block 0 
setblock ~34 ~2 ~7 stone_slab 15 
setblock ~34 ~2 ~67 stone_slab 15  
fill ~34 ~2 ~68 ~34 ~2 ~69 quartz_block 0 
setblock ~34 ~2 ~70 stone_slab 7  
fill ~35 ~2 ~5 ~39 ~2 ~5 stone_slab 7  
fill ~35 ~2 ~69 ~39 ~2 ~69 stone_slab 7  
fill ~36 ~2 ~6 ~40 ~2 ~6 quartz_block 0  
fill ~36 ~2 ~7 ~39 ~2 ~7 quartz_block 0  
fill ~36 ~2 ~67 ~39 ~2 ~67 quartz_block 0  
fill ~36 ~2 ~68 ~40 ~2 ~68 quartz_block 0 
setblock ~37 ~2 ~17 quartz_block 0 
setblock ~37 ~2 ~21 quartz_block 0 
setblock ~37 ~2 ~25 quartz_block 0 
setblock ~37 ~2 ~29 quartz_block 0 
setblock ~37 ~2 ~33 quartz_block 0 
setblock ~37 ~2 ~41 quartz_block 0 
setblock ~37 ~2 ~45 quartz_block 0 
setblock ~37 ~2 ~49 quartz_block 0 
setblock ~37 ~2 ~53 quartz_block 0 
setblock ~37 ~2 ~57 quartz_block 0 
setblock ~40 ~2 ~4 stone_slab 7 
setblock ~40 ~2 ~5 quartz_block 0 
setblock ~40 ~2 ~7 stone_slab 15  
fill ~40 ~2 ~11 ~43 ~2 ~11 stained_hardened_clay 3  
fill ~40 ~2 ~63 ~43 ~2 ~63 stained_hardened_clay 3 
setblock ~40 ~2 ~67 stone_slab 15 
setblock ~40 ~2 ~69 quartz_block 0 
setblock ~40 ~2 ~70 stone_slab 7 
setblock ~41 ~2 ~25 quartz_block 0 
setblock ~41 ~2 ~29 quartz_block 0 
setblock ~41 ~2 ~33 quartz_block 0 
setblock ~41 ~2 ~37 quartz_block 0 
setblock ~41 ~2 ~41 quartz_block 0 
setblock ~41 ~2 ~45 quartz_block 0 
setblock ~41 ~2 ~49 quartz_block 0  
fill ~45 ~2 ~9 ~47 ~2 ~9 stained_hardened_clay 3 
setblock ~45 ~2 ~25 quartz_block 0 
setblock ~45 ~2 ~29 quartz_block 0 
setblock ~45 ~2 ~33 quartz_block 0 
setblock ~45 ~2 ~37 quartz_block 0 
setblock ~45 ~2 ~41 quartz_block 0 
setblock ~45 ~2 ~45 quartz_block 0 
setblock ~45 ~2 ~49 quartz_block 0  
fill ~45 ~2 ~65 ~47 ~2 ~65 stained_hardened_clay 3  
fill ~48 ~2 ~10 ~50 ~2 ~10 stained_hardened_clay 3  
fill ~48 ~2 ~64 ~50 ~2 ~64 stained_hardened_clay 3 
setblock ~49 ~2 ~25 quartz_block 0 
setblock ~49 ~2 ~29 quartz_block 0 
setblock ~49 ~2 ~33 quartz_block 0 
setblock ~49 ~2 ~37 quartz_block 0 
setblock ~49 ~2 ~41 quartz_block 0 
setblock ~49 ~2 ~45 quartz_block 0 
setblock ~49 ~2 ~49 quartz_block 0  
fill ~52 ~2 ~5 ~54 ~2 ~5 stained_hardened_clay 3  
fill ~52 ~2 ~69 ~54 ~2 ~69 stained_hardened_clay 3 
setblock ~53 ~2 ~37 quartz_block 0  
fill ~56 ~2 ~7 ~58 ~2 ~7 stained_hardened_clay 3  
fill ~56 ~2 ~67 ~58 ~2 ~67 stained_hardened_clay 3 
setblock ~57 ~2 ~37 quartz_block 0  
fill ~59 ~2 ~8 ~61 ~2 ~8 stained_hardened_clay 3  
fill ~59 ~2 ~66 ~61 ~2 ~66 stained_hardened_clay 3  
fill ~62 ~2 ~9 ~63 ~2 ~9 stained_hardened_clay 3  
fill ~62 ~2 ~65 ~63 ~2 ~65 stained_hardened_clay 3  
fill ~65 ~2 ~23 ~68 ~2 ~23 stained_hardened_clay 3  
fill ~65 ~2 ~51 ~68 ~2 ~51 stained_hardened_clay 3  
fill ~66 ~2 ~35 ~68 ~2 ~35 quartz_block 0  
fill ~66 ~2 ~39 ~68 ~2 ~39 quartz_block 0 
setblock ~67 ~2 ~34 stone_slab 15  
fill ~67 ~2 ~36 ~68 ~2 ~36 quartz_block 0  
fill ~67 ~2 ~37 ~68 ~2 ~37 quartz_block 0  
fill ~67 ~2 ~38 ~68 ~2 ~38 quartz_block 0 
setblock ~67 ~2 ~40 stone_slab 15  
fill ~68 ~2 ~34 ~69 ~2 ~34 quartz_block 0  
fill ~68 ~2 ~40 ~69 ~2 ~40 quartz_block 0  
fill ~69 ~2 ~35 ~69 ~2 ~39 stone_slab 7 
setblock ~70 ~2 ~34 stone_slab 7 
setblock ~70 ~2 ~40 stone_slab 7  
fill ~6 ~3 ~23 ~9 ~3 ~23 stained_hardened_clay 3 
setblock ~6 ~3 ~34 stone_slab 7 
setblock ~6 ~3 ~40 stone_slab 7  
fill ~6 ~3 ~51 ~9 ~3 ~51 stained_hardened_clay 3  
fill ~7 ~3 ~34 ~8 ~3 ~34 quartz_block 0  
fill ~7 ~3 ~35 ~7 ~3 ~39 stone_slab 7  
fill ~7 ~3 ~40 ~8 ~3 ~40 quartz_block 0  
fill ~8 ~3 ~35 ~9 ~3 ~35 quartz_block 0  
fill ~8 ~3 ~36 ~9 ~3 ~36 quartz_block 0  
fill ~8 ~3 ~37 ~9 ~3 ~37 quartz_block 0  
fill ~8 ~3 ~38 ~9 ~3 ~38 quartz_block 0  
fill ~8 ~3 ~39 ~9 ~3 ~39 quartz_block 0  
fill ~11 ~3 ~9 ~12 ~3 ~9 stained_hardened_clay 3  
fill ~11 ~3 ~65 ~12 ~3 ~65 stained_hardened_clay 3  
fill ~13 ~3 ~8 ~15 ~3 ~8 stained_hardened_clay 3  
fill ~13 ~3 ~66 ~15 ~3 ~66 stained_hardened_clay 3  
fill ~16 ~3 ~7 ~18 ~3 ~7 stained_hardened_clay 3  
fill ~16 ~3 ~67 ~18 ~3 ~67 stained_hardened_clay 3 
setblock ~17 ~3 ~37 redstone_torch 5  
fill ~20 ~3 ~5 ~22 ~3 ~5 stained_hardened_clay 3  
fill ~20 ~3 ~69 ~22 ~3 ~69 stained_hardened_clay 3 
setblock ~21 ~3 ~37 redstone_torch 5  
fill ~24 ~3 ~10 ~26 ~3 ~10 stained_hardened_clay 3  
fill ~24 ~3 ~64 ~26 ~3 ~64 stained_hardened_clay 3 
setblock ~25 ~3 ~25 redstone_torch 5 
setblock ~25 ~3 ~29 redstone_torch 5 
setblock ~25 ~3 ~33 redstone_torch 5 
setblock ~25 ~3 ~37 redstone_torch 5 
setblock ~25 ~3 ~41 redstone_torch 5 
setblock ~25 ~3 ~45 redstone_torch 5 
setblock ~25 ~3 ~49 redstone_torch 5  
fill ~27 ~3 ~9 ~29 ~3 ~9 stained_hardened_clay 3  
fill ~27 ~3 ~65 ~29 ~3 ~65 stained_hardened_clay 3 
setblock ~29 ~3 ~25 redstone_torch 5 
setblock ~29 ~3 ~29 redstone_torch 5 
setblock ~29 ~3 ~33 redstone_torch 5 
setblock ~29 ~3 ~37 redstone_torch 5 
setblock ~29 ~3 ~41 redstone_torch 5 
setblock ~29 ~3 ~45 redstone_torch 5 
setblock ~29 ~3 ~49 redstone_torch 5  
fill ~31 ~3 ~11 ~34 ~3 ~11 stained_hardened_clay 3  
fill ~31 ~3 ~63 ~34 ~3 ~63 stained_hardened_clay 3 
setblock ~33 ~3 ~25 redstone_torch 5 
setblock ~33 ~3 ~29 redstone_torch 5 
setblock ~33 ~3 ~33 redstone_torch 5 
setblock ~33 ~3 ~37 redstone_torch 5 
setblock ~33 ~3 ~41 redstone_torch 5 
setblock ~33 ~3 ~45 redstone_torch 5 
setblock ~33 ~3 ~49 redstone_torch 5 
setblock ~34 ~3 ~6 stone_slab 7  
fill ~34 ~3 ~7 ~34 ~3 ~8 quartz_block 0  
fill ~34 ~3 ~66 ~34 ~3 ~67 quartz_block 0 
setblock ~34 ~3 ~68 stone_slab 7  
fill ~35 ~3 ~7 ~39 ~3 ~7 stone_slab 7  
fill ~35 ~3 ~9 ~39 ~3 ~9 quartz_block 0  
fill ~35 ~3 ~65 ~39 ~3 ~65 quartz_block 0  
fill ~35 ~3 ~67 ~39 ~3 ~67 stone_slab 7  
fill ~36 ~3 ~8 ~40 ~3 ~8 quartz_block 0  
fill ~36 ~3 ~66 ~40 ~3 ~66 quartz_block 0 
setblock ~37 ~3 ~17 redstone_torch 5 
setblock ~37 ~3 ~21 redstone_torch 5 
setblock ~37 ~3 ~25 redstone_torch 5 
setblock ~37 ~3 ~29 redstone_torch 5 
setblock ~37 ~3 ~33 redstone_torch 5 
setblock ~37 ~3 ~37 redstone_torch 5 
setblock ~37 ~3 ~41 redstone_torch 5 
setblock ~37 ~3 ~45 redstone_torch 5 
setblock ~37 ~3 ~49 redstone_torch 5 
setblock ~37 ~3 ~53 redstone_torch 5 
setblock ~37 ~3 ~57 redstone_torch 5 
setblock ~40 ~3 ~6 stone_slab 7 
setblock ~40 ~3 ~7 quartz_block 0  
fill ~40 ~3 ~11 ~43 ~3 ~11 stained_hardened_clay 3  
fill ~40 ~3 ~63 ~43 ~3 ~63 stained_hardened_clay 3 
setblock ~40 ~3 ~67 quartz_block 0 
setblock ~40 ~3 ~68 stone_slab 7 
setblock ~41 ~3 ~25 redstone_torch 5 
setblock ~41 ~3 ~29 redstone_torch 5 
setblock ~41 ~3 ~33 redstone_torch 5 
setblock ~41 ~3 ~37 redstone_torch 5 
setblock ~41 ~3 ~41 redstone_torch 5 
setblock ~41 ~3 ~45 redstone_torch 5 
setblock ~41 ~3 ~49 redstone_torch 5  
fill ~45 ~3 ~9 ~47 ~3 ~9 stained_hardened_clay 3 
setblock ~45 ~3 ~25 redstone_torch 5 
setblock ~45 ~3 ~29 redstone_torch 5 
setblock ~45 ~3 ~33 redstone_torch 5 
setblock ~45 ~3 ~37 redstone_torch 5 
setblock ~45 ~3 ~41 redstone_torch 5 
setblock ~45 ~3 ~45 redstone_torch 5 
setblock ~45 ~3 ~49 redstone_torch 5  
fill ~45 ~3 ~65 ~47 ~3 ~65 stained_hardened_clay 3  
fill ~48 ~3 ~10 ~50 ~3 ~10 stained_hardened_clay 3  
fill ~48 ~3 ~64 ~50 ~3 ~64 stained_hardened_clay 3 
setblock ~49 ~3 ~25 redstone_torch 5 
setblock ~49 ~3 ~29 redstone_torch 5 
setblock ~49 ~3 ~33 redstone_torch 5 
setblock ~49 ~3 ~37 redstone_torch 5 
setblock ~49 ~3 ~41 redstone_torch 5 
setblock ~49 ~3 ~45 redstone_torch 5 
setblock ~49 ~3 ~49 redstone_torch 5  
fill ~52 ~3 ~5 ~54 ~3 ~5 stained_hardened_clay 3  
fill ~52 ~3 ~69 ~54 ~3 ~69 stained_hardened_clay 3 
setblock ~53 ~3 ~37 redstone_torch 5  
fill ~56 ~3 ~7 ~58 ~3 ~7 stained_hardened_clay 3  
fill ~56 ~3 ~67 ~58 ~3 ~67 stained_hardened_clay 3 
setblock ~57 ~3 ~37 redstone_torch 5  
fill ~59 ~3 ~8 ~61 ~3 ~8 stained_hardened_clay 3  
fill ~59 ~3 ~66 ~61 ~3 ~66 stained_hardened_clay 3  
fill ~62 ~3 ~9 ~63 ~3 ~9 stained_hardened_clay 3  
fill ~62 ~3 ~65 ~63 ~3 ~65 stained_hardened_clay 3  
fill ~65 ~3 ~23 ~68 ~3 ~23 stained_hardened_clay 3  
fill ~65 ~3 ~35 ~66 ~3 ~35 quartz_block 0  
fill ~65 ~3 ~36 ~66 ~3 ~36 quartz_block 0  
fill ~65 ~3 ~37 ~66 ~3 ~37 quartz_block 0  
fill ~65 ~3 ~38 ~66 ~3 ~38 quartz_block 0  
fill ~65 ~3 ~39 ~66 ~3 ~39 quartz_block 0  
fill ~65 ~3 ~51 ~68 ~3 ~51 stained_hardened_clay 3  
fill ~66 ~3 ~34 ~67 ~3 ~34 quartz_block 0  
fill ~66 ~3 ~40 ~67 ~3 ~40 quartz_block 0  
fill ~67 ~3 ~35 ~67 ~3 ~39 stone_slab 7 
setblock ~68 ~3 ~34 stone_slab 7 
setblock ~68 ~3 ~40 stone_slab 7 
setblock ~4 ~4 ~19 quartz_stairs 6  
fill ~4 ~4 ~20 ~4 ~4 ~23 quartz_stairs 4 
setblock ~4 ~4 ~51 quartz_stairs 6  
fill ~4 ~4 ~52 ~4 ~4 ~55 quartz_stairs 4 
setblock ~5 ~4 ~18 quartz_stairs 6 
setblock ~5 ~4 ~19 quartz_stairs 4  
fill ~5 ~4 ~20 ~11 ~4 ~20 grass 0  
fill ~5 ~4 ~21 ~6 ~4 ~21 grass 0  
fill ~5 ~4 ~22 ~9 ~4 ~22 grass 0 
setblock ~5 ~4 ~23 quartz_stairs 7 
setblock ~5 ~4 ~24 quartz_stairs 4  
fill ~5 ~4 ~50 ~9 ~4 ~50 quartz_stairs 6 
setblock ~5 ~4 ~51 quartz_stairs 4  
fill ~5 ~4 ~52 ~9 ~4 ~52 grass 0  
fill ~5 ~4 ~53 ~6 ~4 ~53 grass 0  
fill ~5 ~4 ~54 ~11 ~4 ~54 grass 0 
setblock ~5 ~4 ~55 quartz_stairs 7 
setblock ~5 ~4 ~56 quartz_stairs 4 
setblock ~6 ~4 ~15 quartz_stairs 6  
fill ~6 ~4 ~16 ~6 ~4 ~18 quartz_stairs 4  
fill ~6 ~4 ~19 ~11 ~4 ~19 grass 0  
fill ~6 ~4 ~23 ~8 ~4 ~23 grass 0  
fill ~6 ~4 ~24 ~9 ~4 ~24 quartz_stairs 7  
fill ~6 ~4 ~51 ~8 ~4 ~51 grass 0  
fill ~6 ~4 ~55 ~11 ~4 ~55 grass 0 
setblock ~6 ~4 ~56 quartz_stairs 7  
fill ~6 ~4 ~57 ~6 ~4 ~58 quartz_stairs 4  
fill ~6 ~4 ~59 ~7 ~4 ~59 quartz_stairs 7 
setblock ~7 ~4 ~12 quartz_stairs 6  
fill ~7 ~4 ~13 ~7 ~4 ~15 quartz_stairs 4  
fill ~7 ~4 ~16 ~12 ~4 ~16 grass 0  
fill ~7 ~4 ~17 ~11 ~4 ~17 grass 0  
fill ~7 ~4 ~18 ~11 ~4 ~18 grass 0 
setblock ~7 ~4 ~21 dirt 0 
setblock ~7 ~4 ~53 dirt 0  
fill ~7 ~4 ~56 ~11 ~4 ~56 grass 0  
fill ~7 ~4 ~57 ~11 ~4 ~57 grass 0  
fill ~7 ~4 ~58 ~12 ~4 ~58 grass 0  
fill ~7 ~4 ~60 ~7 ~4 ~61 quartz_stairs 4  
fill ~7 ~4 ~62 ~8 ~4 ~62 quartz_stairs 7 
setblock ~8 ~4 ~10 quartz_stairs 6  
fill ~8 ~4 ~11 ~8 ~4 ~12 quartz_stairs 4  
fill ~8 ~4 ~13 ~15 ~4 ~13 grass 0  
fill ~8 ~4 ~14 ~14 ~4 ~14 grass 0  
fill ~8 ~4 ~15 ~13 ~4 ~15 grass 0  
fill ~8 ~4 ~21 ~10 ~4 ~21 grass 0  
fill ~8 ~4 ~26 ~8 ~4 ~30 quartz_stairs 4 
setblock ~8 ~4 ~34 stone_slab 7 
setblock ~8 ~4 ~40 stone_slab 7  
fill ~8 ~4 ~44 ~8 ~4 ~48 quartz_stairs 4  
fill ~8 ~4 ~53 ~10 ~4 ~53 grass 0  
fill ~8 ~4 ~59 ~13 ~4 ~59 grass 0  
fill ~8 ~4 ~60 ~14 ~4 ~60 grass 0  
fill ~8 ~4 ~61 ~15 ~4 ~61 grass 0 
setblock ~8 ~4 ~63 quartz_stairs 4  
fill ~8 ~4 ~64 ~9 ~4 ~64 quartz_stairs 7 
setblock ~9 ~4 ~9 quartz_stairs 6 
setblock ~9 ~4 ~10 quartz_stairs 4  
fill ~9 ~4 ~11 ~20 ~4 ~11 grass 0  
fill ~9 ~4 ~12 ~11 ~4 ~12 grass 0 
setblock ~9 ~4 ~23 stained_hardened_clay 3 
setblock ~9 ~4 ~25 quartz_stairs 4 
setblock ~9 ~4 ~26 quartz_stairs 6  
fill ~9 ~4 ~27 ~12 ~4 ~27 quartz_block 0  
fill ~9 ~4 ~28 ~10 ~4 ~28 quartz_block 0  
fill ~9 ~4 ~29 ~11 ~4 ~29 quartz_block 0 
setblock ~9 ~4 ~30 quartz_stairs 7 
setblock ~9 ~4 ~31 quartz_stairs 4  
fill ~9 ~4 ~35 ~9 ~4 ~39 stone_slab 7 
setblock ~9 ~4 ~43 quartz_stairs 4 
setblock ~9 ~4 ~44 quartz_stairs 6  
fill ~9 ~4 ~45 ~11 ~4 ~45 quartz_block 0  
fill ~9 ~4 ~46 ~10 ~4 ~46 quartz_block 0  
fill ~9 ~4 ~47 ~12 ~4 ~47 quartz_block 0 
setblock ~9 ~4 ~48 quartz_stairs 7 
setblock ~9 ~4 ~49 quartz_stairs 4 
setblock ~9 ~4 ~51 stained_hardened_clay 3  
fill ~9 ~4 ~62 ~11 ~4 ~62 grass 0  
fill ~9 ~4 ~63 ~20 ~4 ~63 grass 0 
setblock ~9 ~4 ~65 quartz_stairs 4  
fill ~10 ~4 ~8 ~10 ~4 ~9 quartz_stairs 4  
fill ~10 ~4 ~10 ~21 ~4 ~10 grass 0  
fill ~10 ~4 ~24 ~15 ~4 ~24 quartz_block 0  
fill ~10 ~4 ~25 ~14 ~4 ~25 quartz_block 0  
fill ~10 ~4 ~26 ~13 ~4 ~26 quartz_block 0  
fill ~10 ~4 ~30 ~12 ~4 ~30 quartz_block 0 
setblock ~10 ~4 ~31 quartz_stairs 7  
fill ~10 ~4 ~32 ~10 ~4 ~33 quartz_stairs 4 
setblock ~10 ~4 ~34 quartz_stairs 6  
fill ~10 ~4 ~35 ~64 ~4 ~35 quartz_block 0  
fill ~10 ~4 ~36 ~64 ~4 ~36 quartz_block 0  
fill ~10 ~4 ~37 ~16 ~4 ~37 quartz_block 0  
fill ~10 ~4 ~38 ~64 ~4 ~38 quartz_block 0  
fill ~10 ~4 ~39 ~64 ~4 ~39 quartz_block 0 
setblock ~10 ~4 ~40 quartz_stairs 7  
fill ~10 ~4 ~41 ~10 ~4 ~42 quartz_stairs 4 
setblock ~10 ~4 ~43 quartz_stairs 6  
fill ~10 ~4 ~44 ~12 ~4 ~44 quartz_block 0  
fill ~10 ~4 ~48 ~13 ~4 ~48 quartz_block 0  
fill ~10 ~4 ~49 ~14 ~4 ~49 quartz_block 0  
fill ~10 ~4 ~50 ~15 ~4 ~50 quartz_block 0  
fill ~10 ~4 ~64 ~21 ~4 ~64 grass 0 
setblock ~10 ~4 ~65 quartz_stairs 7 
setblock ~10 ~4 ~66 quartz_stairs 4 
setblock ~11 ~4 ~8 quartz_stairs 6  
fill ~11 ~4 ~9 ~22 ~4 ~9 grass 0  
fill ~11 ~4 ~23 ~16 ~4 ~23 quartz_block 0  
fill ~11 ~4 ~31 ~13 ~4 ~31 quartz_block 0  
fill ~11 ~4 ~32 ~20 ~4 ~32 quartz_block 0  
fill ~11 ~4 ~33 ~18 ~4 ~33 quartz_block 0  
fill ~11 ~4 ~34 ~15 ~4 ~34 quartz_block 0  
fill ~11 ~4 ~40 ~14 ~4 ~40 quartz_block 0  
fill ~11 ~4 ~41 ~18 ~4 ~41 quartz_block 0  
fill ~11 ~4 ~42 ~20 ~4 ~42 quartz_block 0  
fill ~11 ~4 ~43 ~13 ~4 ~43 quartz_block 0  
fill ~11 ~4 ~51 ~16 ~4 ~51 quartz_block 0  
fill ~11 ~4 ~65 ~22 ~4 ~65 grass 0  
fill ~11 ~4 ~66 ~12 ~4 ~66 quartz_stairs 7  
fill ~12 ~4 ~7 ~12 ~4 ~8 quartz_stairs 4 
setblock ~12 ~4 ~12 dirt 0  
fill ~12 ~4 ~22 ~16 ~4 ~22 quartz_block 0  
fill ~12 ~4 ~52 ~16 ~4 ~52 quartz_block 0 
setblock ~12 ~4 ~62 dirt 0 
setblock ~12 ~4 ~67 quartz_stairs 4  
fill ~13 ~4 ~7 ~14 ~4 ~7 quartz_stairs 6  
fill ~13 ~4 ~8 ~23 ~4 ~8 grass 0  
fill ~13 ~4 ~12 ~16 ~4 ~12 grass 0  
fill ~13 ~4 ~18 ~16 ~4 ~18 quartz_block 0  
fill ~13 ~4 ~19 ~15 ~4 ~19 quartz_block 0  
fill ~13 ~4 ~20 ~15 ~4 ~20 quartz_block 0  
fill ~13 ~4 ~21 ~15 ~4 ~21 quartz_block 0  
fill ~13 ~4 ~53 ~15 ~4 ~53 quartz_block 0  
fill ~13 ~4 ~54 ~15 ~4 ~54 quartz_block 0  
fill ~13 ~4 ~55 ~15 ~4 ~55 quartz_block 0  
fill ~13 ~4 ~56 ~16 ~4 ~56 quartz_block 0  
fill ~13 ~4 ~62 ~16 ~4 ~62 grass 0  
fill ~13 ~4 ~66 ~23 ~4 ~66 grass 0  
fill ~13 ~4 ~67 ~15 ~4 ~67 quartz_stairs 7  
fill ~14 ~4 ~17 ~17 ~4 ~17 quartz_block 0  
fill ~14 ~4 ~57 ~17 ~4 ~57 quartz_block 0  
fill ~15 ~4 ~6 ~15 ~4 ~7 quartz_stairs 4  
fill ~15 ~4 ~16 ~18 ~4 ~16 quartz_block 0  
fill ~15 ~4 ~30 ~21 ~4 ~30 quartz_block 0  
fill ~15 ~4 ~31 ~21 ~4 ~31 quartz_block 0  
fill ~15 ~4 ~43 ~21 ~4 ~43 quartz_block 0  
fill ~15 ~4 ~44 ~21 ~4 ~44 quartz_block 0  
fill ~15 ~4 ~58 ~18 ~4 ~58 quartz_block 0 
setblock ~15 ~4 ~68 quartz_stairs 4  
fill ~16 ~4 ~6 ~17 ~4 ~6 quartz_stairs 6  
fill ~16 ~4 ~7 ~20 ~4 ~7 grass 0  
fill ~16 ~4 ~15 ~24 ~4 ~15 quartz_block 0  
fill ~16 ~4 ~29 ~22 ~4 ~29 quartz_block 0  
fill ~16 ~4 ~45 ~22 ~4 ~45 quartz_block 0  
fill ~16 ~4 ~59 ~24 ~4 ~59 quartz_block 0  
fill ~16 ~4 ~67 ~20 ~4 ~67 grass 0  
fill ~16 ~4 ~68 ~18 ~4 ~68 quartz_stairs 7  
fill ~17 ~4 ~14 ~25 ~4 ~14 quartz_block 0  
fill ~17 ~4 ~19 ~20 ~4 ~19 stained_hardened_clay 11  
fill ~17 ~4 ~20 ~19 ~4 ~20 stained_hardened_clay 11  
fill ~17 ~4 ~21 ~18 ~4 ~21 stained_hardened_clay 11  
fill ~17 ~4 ~28 ~22 ~4 ~28 quartz_block 0 
setblock ~17 ~4 ~37 lit_redstone_lamp 0  
fill ~17 ~4 ~46 ~22 ~4 ~46 quartz_block 0  
fill ~17 ~4 ~53 ~18 ~4 ~53 stained_hardened_clay 11  
fill ~17 ~4 ~54 ~19 ~4 ~54 stained_hardened_clay 11   
fill ~17 ~4 ~55 ~20 ~4 ~55 stained_hardened_clay 11  
fill ~17 ~4 ~60 ~25 ~4 ~60 quartz_block 0 
setblock ~18 ~4 ~5 quartz_stairs 6 
setblock ~18 ~4 ~6 quartz_stairs 4  
fill ~18 ~4 ~13 ~26 ~4 ~13 quartz_block 0  
fill ~18 ~4 ~18 ~21 ~4 ~18 stained_hardened_clay 11  
fill ~18 ~4 ~27 ~22 ~4 ~27 quartz_block 0  
fill ~18 ~4 ~37 ~20 ~4 ~37 quartz_block 0  
fill ~18 ~4 ~47 ~22 ~4 ~47 quartz_block 0  
fill ~18 ~4 ~56 ~21 ~4 ~56 stained_hardened_clay 11  
fill ~18 ~4 ~61 ~26 ~4 ~61 quartz_block 0 
setblock ~18 ~4 ~69 quartz_stairs 4  
fill ~19 ~4 ~4 ~22 ~4 ~4 quartz_stairs 6 
setblock ~19 ~4 ~5 quartz_stairs 4  
fill ~19 ~4 ~6 ~23 ~4 ~6 grass 0  
fill ~19 ~4 ~17 ~21 ~4 ~17 stained_hardened_clay 11  
fill ~19 ~4 ~26 ~22 ~4 ~26 quartz_block 0  
fill ~19 ~4 ~34 ~55 ~4 ~34 quartz_block 0  
fill ~19 ~4 ~40 ~55 ~4 ~40 quartz_block 0  
fill ~19 ~4 ~48 ~22 ~4 ~48 quartz_block 0  
fill ~19 ~4 ~57 ~21 ~4 ~57 stained_hardened_clay 11  
fill ~19 ~4 ~68 ~23 ~4 ~68 grass 0 
setblock ~19 ~4 ~69 quartz_stairs 7 
setblock ~19 ~4 ~70 quartz_stairs 4  
fill ~20 ~4 ~5 ~22 ~4 ~5 grass 0  
fill ~20 ~4 ~25 ~22 ~4 ~25 quartz_block 0  
fill ~20 ~4 ~49 ~22 ~4 ~49 quartz_block 0  
fill ~20 ~4 ~69 ~22 ~4 ~69 grass 0  
fill ~20 ~4 ~70 ~23 ~4 ~70 quartz_stairs 7 
setblock ~21 ~4 ~7 dirt 0  
fill ~21 ~4 ~24 ~22 ~4 ~24 quartz_block 0  
fill ~21 ~4 ~33 ~24 ~4 ~33 quartz_block 0 
setblock ~21 ~4 ~37 lit_redstone_lamp 0  
fill ~21 ~4 ~41 ~24 ~4 ~41 quartz_block 0  
fill ~21 ~4 ~50 ~22 ~4 ~50 quartz_block 0 
setblock ~21 ~4 ~67 dirt 0  
fill ~22 ~4 ~7 ~23 ~4 ~7 grass 0  
fill ~22 ~4 ~12 ~27 ~4 ~12 quartz_block 0  
fill ~22 ~4 ~16 ~23 ~4 ~16 quartz_block 0  
fill ~22 ~4 ~32 ~52 ~4 ~32 quartz_block 0  
fill ~22 ~4 ~37 ~24 ~4 ~37 quartz_block 0  
fill ~22 ~4 ~42 ~52 ~4 ~42 quartz_block 0  
fill ~22 ~4 ~58 ~23 ~4 ~58 quartz_block 0  
fill ~22 ~4 ~62 ~27 ~4 ~62 quartz_block 0  
fill ~22 ~4 ~67 ~23 ~4 ~67 grass 0 
setblock ~23 ~4 ~4 quartz_stairs 5 
setblock ~23 ~4 ~5 quartz_stairs 6  
fill ~23 ~4 ~11 ~27 ~4 ~11 quartz_block 0  
fill ~23 ~4 ~30 ~51 ~4 ~30 quartz_block 0  
fill ~23 ~4 ~31 ~51 ~4 ~31 quartz_block 0  
fill ~23 ~4 ~43 ~51 ~4 ~43 quartz_block 0  
fill ~23 ~4 ~44 ~51 ~4 ~44 quartz_block 0  
fill ~23 ~4 ~63 ~27 ~4 ~63 quartz_block 0 
setblock ~23 ~4 ~69 quartz_stairs 5  
fill ~24 ~4 ~5 ~24 ~4 ~9 quartz_stairs 5  
fill ~24 ~4 ~10 ~30 ~4 ~10 quartz_block 0  
fill ~24 ~4 ~21 ~31 ~4 ~21 quartz_block 0  
fill ~24 ~4 ~22 ~29 ~4 ~22 quartz_block 0  
fill ~24 ~4 ~24 ~50 ~4 ~24 quartz_block 0  
fill ~24 ~4 ~25 ~24 ~4 ~50 quartz_block 0  
fill ~24 ~4 ~52 ~29 ~4 ~52 quartz_block 0  
fill ~24 ~4 ~53 ~31 ~4 ~53 quartz_block 0  
fill ~24 ~4 ~64 ~30 ~4 ~64 quartz_block 0  
fill ~24 ~4 ~65 ~24 ~4 ~68 quartz_stairs 5 
setblock ~24 ~4 ~69 quartz_stairs 7 
setblock ~25 ~4 ~9 quartz_stairs 6  
fill ~25 ~4 ~20 ~32 ~4 ~20 quartz_block 0 
setblock ~25 ~4 ~25 lit_redstone_lamp 0  
fill ~25 ~4 ~26 ~50 ~4 ~26 quartz_block 0  
fill ~25 ~4 ~27 ~50 ~4 ~27 quartz_block 0  
fill ~25 ~4 ~28 ~50 ~4 ~28 quartz_block 0 
setblock ~25 ~4 ~29 lit_redstone_lamp 0 
setblock ~25 ~4 ~33 lit_redstone_lamp 0 
setblock ~25 ~4 ~37 lit_redstone_lamp 0 
setblock ~25 ~4 ~41 lit_redstone_lamp 0 
setblock ~25 ~4 ~45 lit_redstone_lamp 0  
fill ~25 ~4 ~46 ~50 ~4 ~46 quartz_block 0  
fill ~25 ~4 ~47 ~50 ~4 ~47 quartz_block 0  
fill ~25 ~4 ~48 ~50 ~4 ~48 quartz_block 0 
setblock ~25 ~4 ~49 lit_redstone_lamp 0  
fill ~25 ~4 ~50 ~50 ~4 ~50 quartz_block 0  
fill ~25 ~4 ~54 ~32 ~4 ~54 quartz_block 0 
setblock ~25 ~4 ~65 quartz_stairs 7  
fill ~26 ~4 ~8 ~30 ~4 ~8 quartz_stairs 6 
setblock ~26 ~4 ~9 quartz_stairs 4  
fill ~26 ~4 ~19 ~32 ~4 ~19 quartz_block 0  
fill ~26 ~4 ~25 ~28 ~4 ~25 quartz_block 0  
fill ~26 ~4 ~29 ~28 ~4 ~29 quartz_block 0  
fill ~26 ~4 ~33 ~28 ~4 ~33 quartz_block 0  
fill ~26 ~4 ~37 ~28 ~4 ~37 quartz_block 0  
fill ~26 ~4 ~41 ~28 ~4 ~41 quartz_block 0  
fill ~26 ~4 ~45 ~28 ~4 ~45 quartz_block 0  
fill ~26 ~4 ~49 ~28 ~4 ~49 quartz_block 0  
fill ~26 ~4 ~55 ~32 ~4 ~55 quartz_block 0 
setblock ~26 ~4 ~65 quartz_stairs 4  
fill ~26 ~4 ~66 ~30 ~4 ~66 quartz_stairs 7  
fill ~27 ~4 ~9 ~29 ~4 ~9 quartz_block 0  
fill ~27 ~4 ~18 ~33 ~4 ~18 quartz_block 0  
fill ~27 ~4 ~56 ~33 ~4 ~56 quartz_block 0  
fill ~27 ~4 ~65 ~29 ~4 ~65 quartz_block 0  
fill ~28 ~4 ~17 ~33 ~4 ~17 quartz_block 0  
fill ~28 ~4 ~57 ~33 ~4 ~57 quartz_block 0  
fill ~29 ~4 ~11 ~45 ~4 ~11 quartz_block 0  
fill ~29 ~4 ~16 ~33 ~4 ~16 quartz_block 0 
setblock ~29 ~4 ~25 lit_redstone_lamp 0 
setblock ~29 ~4 ~29 lit_redstone_lamp 0 
setblock ~29 ~4 ~33 lit_redstone_lamp 0 
setblock ~29 ~4 ~37 lit_redstone_lamp 0 
setblock ~29 ~4 ~41 lit_redstone_lamp 0 
setblock ~29 ~4 ~45 lit_redstone_lamp 0 
setblock ~29 ~4 ~49 lit_redstone_lamp 0  
fill ~29 ~4 ~58 ~33 ~4 ~58 quartz_block 0  
fill ~29 ~4 ~63 ~45 ~4 ~63 quartz_block 0 
setblock ~30 ~4 ~9 quartz_stairs 5  
fill ~30 ~4 ~12 ~44 ~4 ~12 quartz_block 0  
fill ~30 ~4 ~15 ~33 ~4 ~15 quartz_block 0  
fill ~30 ~4 ~23 ~44 ~4 ~23 quartz_block 0  
fill ~30 ~4 ~25 ~32 ~4 ~25 quartz_block 0  
fill ~30 ~4 ~29 ~32 ~4 ~29 quartz_block 0  
fill ~30 ~4 ~33 ~32 ~4 ~33 quartz_block 0  
fill ~30 ~4 ~37 ~32 ~4 ~37 quartz_block 0  
fill ~30 ~4 ~41 ~32 ~4 ~41 quartz_block 0  
fill ~30 ~4 ~45 ~32 ~4 ~45 quartz_block 0  
fill ~30 ~4 ~49 ~32 ~4 ~49 quartz_block 0  
fill ~30 ~4 ~51 ~44 ~4 ~51 quartz_block 0  
fill ~30 ~4 ~59 ~39 ~4 ~59 quartz_block 0  
fill ~30 ~4 ~62 ~44 ~4 ~62 quartz_block 0 
setblock ~30 ~4 ~65 quartz_stairs 5 
setblock ~31 ~4 ~9 quartz_stairs 6 
setblock ~31 ~4 ~10 quartz_stairs 5  
fill ~31 ~4 ~13 ~43 ~4 ~13 quartz_block 0  
fill ~31 ~4 ~61 ~43 ~4 ~61 quartz_block 0 
setblock ~31 ~4 ~64 quartz_stairs 5 
setblock ~31 ~4 ~65 quartz_stairs 7  
fill ~32 ~4 ~10 ~33 ~4 ~10 quartz_stairs 6  
fill ~32 ~4 ~14 ~42 ~4 ~14 quartz_block 0  
fill ~32 ~4 ~22 ~42 ~4 ~22 quartz_block 0  
fill ~32 ~4 ~52 ~42 ~4 ~52 quartz_block 0  
fill ~32 ~4 ~60 ~42 ~4 ~60 quartz_block 0  
fill ~32 ~4 ~64 ~33 ~4 ~64 quartz_stairs 7  
fill ~33 ~4 ~21 ~36 ~4 ~21 quartz_block 0 
setblock ~33 ~4 ~25 lit_redstone_lamp 0 
setblock ~33 ~4 ~29 lit_redstone_lamp 0 
setblock ~33 ~4 ~33 lit_redstone_lamp 0 
setblock ~33 ~4 ~37 lit_redstone_lamp 0 
setblock ~33 ~4 ~41 lit_redstone_lamp 0 
setblock ~33 ~4 ~45 lit_redstone_lamp 0 
setblock ~33 ~4 ~49 lit_redstone_lamp 0  
fill ~33 ~4 ~53 ~36 ~4 ~53 quartz_block 0 
setblock ~34 ~4 ~8 stone_slab 7 
setblock ~34 ~4 ~10 quartz_stairs 4  
fill ~34 ~4 ~19 ~40 ~4 ~19 quartz_block 0  
fill ~34 ~4 ~20 ~40 ~4 ~20 quartz_block 0  
fill ~34 ~4 ~25 ~36 ~4 ~25 quartz_block 0  
fill ~34 ~4 ~29 ~36 ~4 ~29 quartz_block 0  
fill ~34 ~4 ~33 ~36 ~4 ~33 quartz_block 0  
fill ~34 ~4 ~37 ~36 ~4 ~37 quartz_block 0  
fill ~34 ~4 ~41 ~36 ~4 ~41 quartz_block 0  
fill ~34 ~4 ~45 ~36 ~4 ~45 quartz_block 0  
fill ~34 ~4 ~49 ~36 ~4 ~49 quartz_block 0  
fill ~34 ~4 ~54 ~40 ~4 ~54 quartz_block 0  
fill ~34 ~4 ~55 ~40 ~4 ~55 quartz_block 0 
setblock ~34 ~4 ~64 quartz_stairs 4 
setblock ~34 ~4 ~66 stone_slab 7  
fill ~35 ~4 ~9 ~39 ~4 ~9 stone_slab 7  
fill ~35 ~4 ~10 ~39 ~4 ~10 quartz_block 0  
fill ~35 ~4 ~15 ~44 ~4 ~15 quartz_block 0  
fill ~35 ~4 ~16 ~39 ~4 ~16 quartz_block 0  
fill ~35 ~4 ~17 ~36 ~4 ~17 quartz_block 0  
fill ~35 ~4 ~18 ~39 ~4 ~18 quartz_block 0  
fill ~35 ~4 ~56 ~39 ~4 ~56 quartz_block 0  
fill ~35 ~4 ~57 ~36 ~4 ~57 quartz_block 0  
fill ~35 ~4 ~58 ~39 ~4 ~58 quartz_block 0  
fill ~35 ~4 ~64 ~39 ~4 ~64 quartz_block 0  
fill ~35 ~4 ~65 ~39 ~4 ~65 stone_slab 7 
setblock ~37 ~4 ~17 lit_redstone_lamp 0 
setblock ~37 ~4 ~21 lit_redstone_lamp 0 
setblock ~37 ~4 ~25 lit_redstone_lamp 0 
setblock ~37 ~4 ~29 lit_redstone_lamp 0 
setblock ~37 ~4 ~33 lit_redstone_lamp 0 
setblock ~37 ~4 ~37 lit_redstone_lamp 0 
setblock ~37 ~4 ~41 lit_redstone_lamp 0 
setblock ~37 ~4 ~45 lit_redstone_lamp 0 
setblock ~37 ~4 ~49 lit_redstone_lamp 0 
setblock ~37 ~4 ~53 lit_redstone_lamp 0 
setblock ~37 ~4 ~57 lit_redstone_lamp 0  
fill ~38 ~4 ~17 ~39 ~4 ~17 quartz_block 0  
fill ~38 ~4 ~21 ~41 ~4 ~21 quartz_block 0  
fill ~38 ~4 ~25 ~40 ~4 ~25 quartz_block 0  
fill ~38 ~4 ~29 ~40 ~4 ~29 quartz_block 0  
fill ~38 ~4 ~33 ~40 ~4 ~33 quartz_block 0  
fill ~38 ~4 ~37 ~40 ~4 ~37 quartz_block 0  
fill ~38 ~4 ~41 ~40 ~4 ~41 quartz_block 0  
fill ~38 ~4 ~45 ~40 ~4 ~45 quartz_block 0  
fill ~38 ~4 ~49 ~40 ~4 ~49 quartz_block 0  
fill ~38 ~4 ~53 ~41 ~4 ~53 quartz_block 0  
fill ~38 ~4 ~57 ~39 ~4 ~57 quartz_block 0 
setblock ~40 ~4 ~8 stone_slab 7 
setblock ~40 ~4 ~10 quartz_stairs 5 
setblock ~40 ~4 ~64 quartz_stairs 5 
setblock ~40 ~4 ~66 stone_slab 7  
fill ~41 ~4 ~10 ~42 ~4 ~10 quartz_stairs 6  
fill ~41 ~4 ~16 ~45 ~4 ~16 quartz_block 0  
fill ~41 ~4 ~17 ~46 ~4 ~17 quartz_block 0  
fill ~41 ~4 ~18 ~47 ~4 ~18 quartz_block 0 
setblock ~41 ~4 ~25 lit_redstone_lamp 0 
setblock ~41 ~4 ~29 lit_redstone_lamp 0 
setblock ~41 ~4 ~33 lit_redstone_lamp 0 
setblock ~41 ~4 ~37 lit_redstone_lamp 0 
setblock ~41 ~4 ~41 lit_redstone_lamp 0 
setblock ~41 ~4 ~45 lit_redstone_lamp 0 
setblock ~41 ~4 ~49 lit_redstone_lamp 0  
fill ~41 ~4 ~56 ~47 ~4 ~56 quartz_block 0  
fill ~41 ~4 ~57 ~46 ~4 ~57 quartz_block 0  
fill ~41 ~4 ~58 ~45 ~4 ~58 quartz_block 0  
fill ~41 ~4 ~59 ~44 ~4 ~59 quartz_block 0  
fill ~41 ~4 ~64 ~42 ~4 ~64 quartz_stairs 7  
fill ~42 ~4 ~19 ~48 ~4 ~19 quartz_block 0  
fill ~42 ~4 ~20 ~49 ~4 ~20 quartz_block 0  
fill ~42 ~4 ~25 ~44 ~4 ~25 quartz_block 0  
fill ~42 ~4 ~29 ~44 ~4 ~29 quartz_block 0  
fill ~42 ~4 ~33 ~44 ~4 ~33 quartz_block 0  
fill ~42 ~4 ~37 ~44 ~4 ~37 quartz_block 0  
fill ~42 ~4 ~41 ~44 ~4 ~41 quartz_block 0  
fill ~42 ~4 ~45 ~44 ~4 ~45 quartz_block 0  
fill ~42 ~4 ~49 ~44 ~4 ~49 quartz_block 0  
fill ~42 ~4 ~54 ~49 ~4 ~54 quartz_block 0  
fill ~42 ~4 ~55 ~48 ~4 ~55 quartz_block 0 
setblock ~43 ~4 ~9 quartz_stairs 6 
setblock ~43 ~4 ~10 quartz_stairs 4  
fill ~43 ~4 ~21 ~50 ~4 ~21 quartz_block 0  
fill ~43 ~4 ~53 ~50 ~4 ~53 quartz_block 0 
setblock ~43 ~4 ~64 quartz_stairs 4 
setblock ~43 ~4 ~65 quartz_stairs 7  
fill ~44 ~4 ~8 ~48 ~4 ~8 quartz_stairs 6 
setblock ~44 ~4 ~9 quartz_stairs 4  
fill ~44 ~4 ~10 ~50 ~4 ~10 quartz_block 0  
fill ~44 ~4 ~64 ~50 ~4 ~64 quartz_block 0 
setblock ~44 ~4 ~65 quartz_stairs 4  
fill ~44 ~4 ~66 ~48 ~4 ~66 quartz_stairs 7  
fill ~45 ~4 ~9 ~47 ~4 ~9 quartz_block 0  
fill ~45 ~4 ~22 ~50 ~4 ~22 quartz_block 0 
setblock ~45 ~4 ~25 lit_redstone_lamp 0 
setblock ~45 ~4 ~29 lit_redstone_lamp 0 
setblock ~45 ~4 ~33 lit_redstone_lamp 0 
setblock ~45 ~4 ~37 lit_redstone_lamp 0 
setblock ~45 ~4 ~41 lit_redstone_lamp 0 
setblock ~45 ~4 ~45 lit_redstone_lamp 0 
setblock ~45 ~4 ~49 lit_redstone_lamp 0  
fill ~45 ~4 ~52 ~50 ~4 ~52 quartz_block 0  
fill ~45 ~4 ~65 ~47 ~4 ~65 quartz_block 0  
fill ~46 ~4 ~25 ~48 ~4 ~25 quartz_block 0  
fill ~46 ~4 ~29 ~48 ~4 ~29 quartz_block 0  
fill ~46 ~4 ~33 ~48 ~4 ~33 quartz_block 0  
fill ~46 ~4 ~37 ~48 ~4 ~37 quartz_block 0  
fill ~46 ~4 ~41 ~48 ~4 ~41 quartz_block 0  
fill ~46 ~4 ~45 ~48 ~4 ~45 quartz_block 0  
fill ~46 ~4 ~49 ~48 ~4 ~49 quartz_block 0  
fill ~47 ~4 ~11 ~51 ~4 ~11 quartz_block 0  
fill ~47 ~4 ~12 ~52 ~4 ~12 quartz_block 0  
fill ~47 ~4 ~62 ~52 ~4 ~62 quartz_block 0  
fill ~47 ~4 ~63 ~51 ~4 ~63 quartz_block 0 
setblock ~48 ~4 ~9 quartz_stairs 5  
fill ~48 ~4 ~13 ~56 ~4 ~13 quartz_block 0  
fill ~48 ~4 ~61 ~56 ~4 ~61 quartz_block 0 
setblock ~48 ~4 ~65 quartz_stairs 5 
setblock ~49 ~4 ~9 quartz_stairs 6  
fill ~49 ~4 ~14 ~57 ~4 ~14 quartz_block 0 
setblock ~49 ~4 ~25 lit_redstone_lamp 0 
setblock ~49 ~4 ~29 lit_redstone_lamp 0 
setblock ~49 ~4 ~33 lit_redstone_lamp 0 
setblock ~49 ~4 ~37 lit_redstone_lamp 0 
setblock ~49 ~4 ~41 lit_redstone_lamp 0 
setblock ~49 ~4 ~45 lit_redstone_lamp 0 
setblock ~49 ~4 ~49 lit_redstone_lamp 0  
fill ~49 ~4 ~60 ~57 ~4 ~60 quartz_block 0 
setblock ~49 ~4 ~65 quartz_stairs 7 
setblock ~50 ~4 ~5 quartz_stairs 6  
fill ~50 ~4 ~6 ~50 ~4 ~9 quartz_stairs 4  
fill ~50 ~4 ~15 ~58 ~4 ~15 quartz_block 0 
setblock ~50 ~4 ~25 quartz_block 0 
setblock ~50 ~4 ~29 quartz_block 0  
fill ~50 ~4 ~33 ~53 ~4 ~33 quartz_block 0  
fill ~50 ~4 ~37 ~52 ~4 ~37 quartz_block 0  
fill ~50 ~4 ~41 ~53 ~4 ~41 quartz_block 0 
setblock ~50 ~4 ~45 quartz_block 0 
setblock ~50 ~4 ~49 quartz_block 0  
fill ~50 ~4 ~59 ~58 ~4 ~59 quartz_block 0  
fill ~50 ~4 ~65 ~50 ~4 ~69 quartz_stairs 4  
fill ~51 ~4 ~4 ~54 ~4 ~4 quartz_stairs 6 
setblock ~51 ~4 ~5 quartz_stairs 4  
fill ~51 ~4 ~6 ~55 ~4 ~6 grass 0  
fill ~51 ~4 ~7 ~52 ~4 ~7 grass 0  
fill ~51 ~4 ~8 ~61 ~4 ~8 grass 0  
fill ~51 ~4 ~16 ~52 ~4 ~16 quartz_block 0  
fill ~51 ~4 ~58 ~52 ~4 ~58 quartz_block 0  
fill ~51 ~4 ~66 ~61 ~4 ~66 grass 0  
fill ~51 ~4 ~67 ~52 ~4 ~67 grass 0  
fill ~51 ~4 ~68 ~55 ~4 ~68 grass 0 
setblock ~51 ~4 ~69 quartz_stairs 7 
setblock ~51 ~4 ~70 quartz_stairs 4  
fill ~52 ~4 ~5 ~54 ~4 ~5 grass 0  
fill ~52 ~4 ~9 ~63 ~4 ~9 grass 0  
fill ~52 ~4 ~24 ~53 ~4 ~24 quartz_block 0  
fill ~52 ~4 ~25 ~54 ~4 ~25 quartz_block 0  
fill ~52 ~4 ~26 ~55 ~4 ~26 quartz_block 0  
fill ~52 ~4 ~27 ~56 ~4 ~27 quartz_block 0  
fill ~52 ~4 ~28 ~57 ~4 ~28 quartz_block 0  
fill ~52 ~4 ~29 ~58 ~4 ~29 quartz_block 0  
fill ~52 ~4 ~45 ~58 ~4 ~45 quartz_block 0  
fill ~52 ~4 ~46 ~57 ~4 ~46 quartz_block 0  
fill ~52 ~4 ~47 ~56 ~4 ~47 quartz_block 0  
fill ~52 ~4 ~48 ~55 ~4 ~48 quartz_block 0  
fill ~52 ~4 ~49 ~54 ~4 ~49 quartz_block 0  
fill ~52 ~4 ~50 ~53 ~4 ~50 quartz_block 0  
fill ~52 ~4 ~65 ~63 ~4 ~65 grass 0  
fill ~52 ~4 ~69 ~54 ~4 ~69 grass 0  
fill ~52 ~4 ~70 ~55 ~4 ~70 quartz_stairs 7 
setblock ~53 ~4 ~7 dirt 0  
fill ~53 ~4 ~10 ~64 ~4 ~10 grass 0  
fill ~53 ~4 ~17 ~55 ~4 ~17 stained_hardened_clay 11  
fill ~53 ~4 ~18 ~56 ~4 ~18 stained_hardened_clay 11  
fill ~53 ~4 ~30 ~59 ~4 ~30 quartz_block 0  
fill ~53 ~4 ~31 ~59 ~4 ~31 quartz_block 0 
setblock ~53 ~4 ~37 lit_redstone_lamp 0  
fill ~53 ~4 ~43 ~59 ~4 ~43 quartz_block 0  
fill ~53 ~4 ~44 ~59 ~4 ~44 quartz_block 0  
fill ~53 ~4 ~56 ~56 ~4 ~56 stained_hardened_clay 11  
fill ~53 ~4 ~57 ~55 ~4 ~57 stained_hardened_clay 11  
fill ~53 ~4 ~64 ~64 ~4 ~64 grass 0 
setblock ~53 ~4 ~67 dirt 0  
fill ~54 ~4 ~7 ~58 ~4 ~7 grass 0  
fill ~54 ~4 ~11 ~65 ~4 ~11 grass 0  
fill ~54 ~4 ~19 ~57 ~4 ~19 stained_hardened_clay 11  
fill ~54 ~4 ~32 ~63 ~4 ~32 quartz_block 0  
fill ~54 ~4 ~37 ~56 ~4 ~37 quartz_block 0  
fill ~54 ~4 ~42 ~63 ~4 ~42 quartz_block 0  
fill ~54 ~4 ~55 ~57 ~4 ~55 stained_hardened_clay 11  
fill ~54 ~4 ~63 ~65 ~4 ~63 grass 0  
fill ~54 ~4 ~67 ~58 ~4 ~67 grass 0 
setblock ~55 ~4 ~4 quartz_stairs 5 
setblock ~55 ~4 ~5 quartz_stairs 6  
fill ~55 ~4 ~20 ~57 ~4 ~20 stained_hardened_clay 11  
fill ~55 ~4 ~54 ~57 ~4 ~54 stained_hardened_clay 11 
setblock ~55 ~4 ~69 quartz_stairs 5 
setblock ~56 ~4 ~5 quartz_stairs 5  
fill ~56 ~4 ~6 ~58 ~4 ~6 quartz_stairs 6  
fill ~56 ~4 ~16 ~59 ~4 ~16 quartz_block 0  
fill ~56 ~4 ~21 ~57 ~4 ~21 stained_hardened_clay 11  
fill ~56 ~4 ~33 ~63 ~4 ~33 quartz_block 0  
fill ~56 ~4 ~41 ~63 ~4 ~41 quartz_block 0  
fill ~56 ~4 ~53 ~57 ~4 ~53 stained_hardened_clay 11  
fill ~56 ~4 ~58 ~59 ~4 ~58 quartz_block 0 
setblock ~56 ~4 ~68 quartz_stairs 5 
setblock ~56 ~4 ~69 quartz_stairs 7  
fill ~57 ~4 ~17 ~60 ~4 ~17 quartz_block 0 
setblock ~57 ~4 ~37 lit_redstone_lamp 0  
fill ~57 ~4 ~57 ~60 ~4 ~57 quartz_block 0  
fill ~57 ~4 ~68 ~58 ~4 ~68 quartz_stairs 7  
fill ~58 ~4 ~12 ~61 ~4 ~12 grass 0  
fill ~58 ~4 ~18 ~61 ~4 ~18 quartz_block 0  
fill ~58 ~4 ~22 ~62 ~4 ~22 quartz_block 0  
fill ~58 ~4 ~23 ~63 ~4 ~23 quartz_block 0  
fill ~58 ~4 ~37 ~64 ~4 ~37 quartz_block 0  
fill ~58 ~4 ~51 ~63 ~4 ~51 quartz_block 0  
fill ~58 ~4 ~52 ~62 ~4 ~52 quartz_block 0  
fill ~58 ~4 ~56 ~61 ~4 ~56 quartz_block 0  
fill ~58 ~4 ~62 ~61 ~4 ~62 grass 0 
setblock ~59 ~4 ~6 quartz_stairs 5  
fill ~59 ~4 ~7 ~61 ~4 ~7 quartz_stairs 6  
fill ~59 ~4 ~13 ~66 ~4 ~13 grass 0  
fill ~59 ~4 ~19 ~61 ~4 ~19 quartz_block 0  
fill ~59 ~4 ~20 ~61 ~4 ~20 quartz_block 0  
fill ~59 ~4 ~21 ~61 ~4 ~21 quartz_block 0  
fill ~59 ~4 ~24 ~64 ~4 ~24 quartz_block 0  
fill ~59 ~4 ~40 ~63 ~4 ~40 quartz_block 0  
fill ~59 ~4 ~50 ~64 ~4 ~50 quartz_block 0  
fill ~59 ~4 ~53 ~61 ~4 ~53 quartz_block 0  
fill ~59 ~4 ~54 ~61 ~4 ~54 quartz_block 0  
fill ~59 ~4 ~55 ~61 ~4 ~55 quartz_block 0  
fill ~59 ~4 ~61 ~66 ~4 ~61 grass 0  
fill ~59 ~4 ~67 ~59 ~4 ~68 quartz_stairs 5  
fill ~60 ~4 ~14 ~66 ~4 ~14 grass 0  
fill ~60 ~4 ~25 ~64 ~4 ~25 quartz_block 0  
fill ~60 ~4 ~34 ~63 ~4 ~34 quartz_block 0  
fill ~60 ~4 ~49 ~64 ~4 ~49 quartz_block 0  
fill ~60 ~4 ~60 ~66 ~4 ~60 grass 0  
fill ~60 ~4 ~67 ~61 ~4 ~67 quartz_stairs 7  
fill ~61 ~4 ~15 ~66 ~4 ~15 grass 0  
fill ~61 ~4 ~26 ~64 ~4 ~26 quartz_block 0  
fill ~61 ~4 ~31 ~63 ~4 ~31 quartz_block 0  
fill ~61 ~4 ~43 ~63 ~4 ~43 quartz_block 0  
fill ~61 ~4 ~48 ~64 ~4 ~48 quartz_block 0  
fill ~61 ~4 ~59 ~66 ~4 ~59 grass 0 
setblock ~62 ~4 ~7 quartz_stairs 5  
fill ~62 ~4 ~8 ~63 ~4 ~8 quartz_stairs 6 
setblock ~62 ~4 ~12 dirt 0  
fill ~62 ~4 ~16 ~67 ~4 ~16 grass 0  
fill ~62 ~4 ~27 ~65 ~4 ~27 quartz_block 0  
fill ~62 ~4 ~30 ~64 ~4 ~30 quartz_block 0  
fill ~62 ~4 ~44 ~64 ~4 ~44 quartz_block 0  
fill ~62 ~4 ~47 ~65 ~4 ~47 quartz_block 0  
fill ~62 ~4 ~58 ~67 ~4 ~58 grass 0 
setblock ~62 ~4 ~62 dirt 0  
fill ~62 ~4 ~66 ~62 ~4 ~67 quartz_stairs 5  
fill ~63 ~4 ~12 ~65 ~4 ~12 grass 0  
fill ~63 ~4 ~17 ~67 ~4 ~17 grass 0  
fill ~63 ~4 ~18 ~67 ~4 ~18 grass 0  
fill ~63 ~4 ~19 ~68 ~4 ~19 grass 0  
fill ~63 ~4 ~20 ~69 ~4 ~20 grass 0  
fill ~63 ~4 ~29 ~65 ~4 ~29 quartz_block 0  
fill ~63 ~4 ~45 ~65 ~4 ~45 quartz_block 0  
fill ~63 ~4 ~54 ~69 ~4 ~54 grass 0  
fill ~63 ~4 ~55 ~68 ~4 ~55 grass 0  
fill ~63 ~4 ~56 ~67 ~4 ~56 grass 0  
fill ~63 ~4 ~57 ~67 ~4 ~57 grass 0  
fill ~63 ~4 ~62 ~65 ~4 ~62 grass 0 
setblock ~63 ~4 ~66 quartz_stairs 7 
setblock ~64 ~4 ~8 quartz_stairs 5 
setblock ~64 ~4 ~9 quartz_stairs 6  
fill ~64 ~4 ~21 ~66 ~4 ~21 grass 0  
fill ~64 ~4 ~28 ~65 ~4 ~28 quartz_block 0 
setblock ~64 ~4 ~31 quartz_stairs 7  
fill ~64 ~4 ~32 ~64 ~4 ~33 quartz_stairs 5 
setblock ~64 ~4 ~34 quartz_stairs 6 
setblock ~64 ~4 ~40 quartz_stairs 7  
fill ~64 ~4 ~41 ~64 ~4 ~42 quartz_stairs 5 
setblock ~64 ~4 ~43 quartz_stairs 6  
fill ~64 ~4 ~46 ~65 ~4 ~46 quartz_block 0  
fill ~64 ~4 ~53 ~66 ~4 ~53 grass 0  
fill ~64 ~4 ~65 ~64 ~4 ~66 quartz_stairs 5 
setblock ~65 ~4 ~9 quartz_stairs 5  
fill ~65 ~4 ~10 ~66 ~4 ~10 quartz_stairs 6  
fill ~65 ~4 ~22 ~69 ~4 ~22 grass 0  
fill ~65 ~4 ~23 ~65 ~0 ~23 stained_hardened_clay 3  
fill ~65 ~4 ~24 ~69 ~4 ~24 quartz_stairs 7 
setblock ~65 ~4 ~25 quartz_stairs 5 
setblock ~65 ~4 ~26 quartz_stairs 6 
setblock ~65 ~4 ~30 quartz_stairs 7 
setblock ~65 ~4 ~31 quartz_stairs 5  
fill ~65 ~4 ~35 ~65 ~4 ~39 stone_slab 7 
setblock ~65 ~4 ~43 quartz_stairs 5 
setblock ~65 ~4 ~44 quartz_stairs 6 
setblock ~65 ~4 ~48 quartz_stairs 7 
setblock ~65 ~4 ~49 quartz_stairs 5  
fill ~65 ~4 ~50 ~68 ~4 ~50 quartz_stairs 6  
fill ~65 ~4 ~51 ~65 ~0 ~51 stained_hardened_clay 3  
fill ~65 ~4 ~52 ~69 ~4 ~52 grass 0 
setblock ~65 ~4 ~64 quartz_stairs 5 
setblock ~65 ~4 ~65 quartz_stairs 7 
setblock ~66 ~4 ~11 quartz_stairs 5  
fill ~66 ~4 ~12 ~67 ~4 ~12 quartz_stairs 6  
fill ~66 ~4 ~23 ~68 ~4 ~23 grass 0  
fill ~66 ~4 ~26 ~66 ~4 ~30 quartz_stairs 5 
setblock ~66 ~4 ~34 stone_slab 7 
setblock ~66 ~4 ~40 stone_slab 7  
fill ~66 ~4 ~44 ~66 ~4 ~48 quartz_stairs 5  
fill ~66 ~4 ~51 ~68 ~4 ~51 grass 0  
fill ~66 ~4 ~62 ~66 ~4 ~63 quartz_stairs 5 
setblock ~66 ~4 ~64 quartz_stairs 7  
fill ~67 ~4 ~13 ~67 ~4 ~14 quartz_stairs 5  
fill ~67 ~4 ~15 ~68 ~4 ~15 quartz_stairs 6 
setblock ~67 ~4 ~21 dirt 0 
setblock ~67 ~4 ~53 dirt 0  
fill ~67 ~4 ~59 ~67 ~4 ~61 quartz_stairs 5 
setblock ~67 ~4 ~62 quartz_stairs 7  
fill ~68 ~4 ~16 ~68 ~4 ~17 quartz_stairs 5 
setblock ~68 ~4 ~18 quartz_stairs 6  
fill ~68 ~4 ~21 ~69 ~4 ~21 grass 0  
fill ~68 ~4 ~53 ~69 ~4 ~53 grass 0  
fill ~68 ~4 ~56 ~68 ~4 ~58 quartz_stairs 5 
setblock ~68 ~4 ~59 quartz_stairs 7 
setblock ~69 ~4 ~18 quartz_stairs 5 
setblock ~69 ~4 ~19 quartz_stairs 6 
setblock ~69 ~4 ~23 quartz_stairs 5 
setblock ~69 ~4 ~50 quartz_stairs 5 
setblock ~69 ~4 ~51 quartz_stairs 6 
setblock ~69 ~4 ~55 quartz_stairs 5 
setblock ~69 ~4 ~56 quartz_stairs 7  
fill ~70 ~4 ~19 ~70 ~4 ~22 quartz_stairs 5 
setblock ~70 ~4 ~23 quartz_stairs 7  
fill ~70 ~4 ~51 ~70 ~4 ~54 quartz_stairs 5 
setblock ~70 ~4 ~55 quartz_stairs 7  
fill ~4 ~5 ~20 ~4 ~5 ~22 stone_slab 7  
fill ~4 ~5 ~52 ~4 ~5 ~54 stone_slab 7 
setblock ~5 ~5 ~19 stone_slab 7 
setblock ~5 ~5 ~23 stone_slab 7 
setblock ~5 ~5 ~51 stone_slab 7 
setblock ~5 ~5 ~55 stone_slab 7  
fill ~6 ~5 ~16 ~6 ~5 ~18 stone_slab 7  
fill ~6 ~5 ~24 ~9 ~5 ~24 stone_slab 7  
fill ~6 ~5 ~50 ~9 ~5 ~50 stone_slab 7  
fill ~6 ~5 ~56 ~6 ~5 ~58 stone_slab 7  
fill ~7 ~5 ~13 ~7 ~5 ~15 stone_slab 7  
fill ~7 ~5 ~21 ~7 ~12 ~21 log 0  
fill ~7 ~5 ~53 ~7 ~12 ~53 log 0  
fill ~7 ~5 ~59 ~7 ~5 ~61 stone_slab 7  
fill ~8 ~5 ~11 ~8 ~5 ~12 stone_slab 7  
fill ~8 ~5 ~26 ~8 ~5 ~30 stone_slab 7  
fill ~8 ~5 ~44 ~8 ~5 ~48 stone_slab 7  
fill ~8 ~5 ~62 ~8 ~5 ~63 stone_slab 7 
setblock ~9 ~5 ~10 stone_slab 7  
fill ~9 ~5 ~23 ~10 ~5 ~23 stone_slab 7 
setblock ~9 ~5 ~25 stone_slab 7 
setblock ~9 ~5 ~31 stone_slab 7 
setblock ~9 ~5 ~43 stone_slab 7 
setblock ~9 ~5 ~49 stone_slab 7  
fill ~9 ~5 ~51 ~10 ~5 ~51 stone_slab 7 
setblock ~9 ~5 ~64 stone_slab 7 
setblock ~10 ~5 ~9 stone_slab 7  
fill ~10 ~5 ~22 ~11 ~5 ~22 stone_slab 7  
fill ~10 ~5 ~32 ~10 ~5 ~33 stone_slab 7  
fill ~10 ~5 ~41 ~10 ~5 ~42 stone_slab 7  
fill ~10 ~5 ~52 ~11 ~5 ~52 stone_slab 7 
setblock ~10 ~5 ~65 stone_slab 7  
fill ~11 ~5 ~8 ~12 ~5 ~8 stone_slab 7  
fill ~11 ~5 ~21 ~12 ~5 ~21 stone_slab 7  
fill ~11 ~5 ~28 ~13 ~5 ~28 quartz_block 0  
fill ~11 ~5 ~46 ~13 ~5 ~46 quartz_block 0  
fill ~11 ~5 ~53 ~12 ~5 ~53 stone_slab 7  
fill ~11 ~5 ~66 ~12 ~5 ~66 stone_slab 7  
fill ~12 ~5 ~12 ~12 ~12 ~12 log 0  
fill ~12 ~5 ~17 ~13 ~5 ~17 stone_slab 7  
fill ~12 ~5 ~18 ~12 ~5 ~21 stone_slab 7 
setblock ~12 ~5 ~29 stone_slab 7 
setblock ~12 ~5 ~45 stone_slab 7  
fill ~12 ~5 ~54 ~12 ~5 ~57 stone_slab 7  
fill ~12 ~5 ~62 ~12 ~12 ~62 log 0  
fill ~13 ~5 ~7 ~15 ~5 ~7 stone_slab 7  
fill ~13 ~5 ~16 ~14 ~5 ~16 stone_slab 7 
setblock ~13 ~5 ~27 stained_hardened_clay 3  
fill ~13 ~5 ~29 ~14 ~5 ~29 quartz_block 0 
setblock ~13 ~5 ~30 stone_slab 7 
setblock ~13 ~5 ~44 stone_slab 7  
fill ~13 ~5 ~45 ~14 ~5 ~45 quartz_block 0 
setblock ~13 ~5 ~47 stained_hardened_clay 3  
fill ~13 ~5 ~57 ~13 ~5 ~58 stone_slab 7  
fill ~13 ~5 ~67 ~15 ~5 ~67 stone_slab 7  
fill ~14 ~5 ~15 ~15 ~5 ~15 stone_slab 7  
fill ~14 ~5 ~26 ~14 ~6 ~26 stained_hardened_clay 3  
fill ~14 ~5 ~30 ~14 ~5 ~31 quartz_block 0  
fill ~14 ~5 ~43 ~14 ~5 ~45 quartz_block 0  
fill ~14 ~5 ~48 ~14 ~6 ~48 stained_hardened_clay 3  
fill ~14 ~5 ~58 ~14 ~5 ~59 stone_slab 7  
fill ~15 ~5 ~14 ~16 ~5 ~14 stone_slab 7  
fill ~15 ~5 ~25 ~15 ~7 ~25 stained_hardened_clay 3 
setblock ~15 ~5 ~29 stained_hardened_clay 3  
fill ~15 ~5 ~34 ~15 ~13 ~34 quartz_block 0  
fill ~15 ~5 ~40 ~15 ~13 ~40 quartz_block 0 
setblock ~15 ~5 ~45 stained_hardened_clay 3  
fill ~15 ~5 ~49 ~15 ~7 ~49 stained_hardened_clay 3  
fill ~15 ~5 ~59 ~15 ~5 ~60 stone_slab 7  
fill ~16 ~5 ~6 ~18 ~5 ~6 stone_slab 7  
fill ~16 ~5 ~13 ~17 ~5 ~13 stone_slab 7  
fill ~16 ~5 ~19 ~16 ~5 ~21 stone_slab 7  
fill ~16 ~5 ~24 ~16 ~8 ~24 stained_hardened_clay 3  
fill ~16 ~5 ~28 ~16 ~6 ~28 stained_hardened_clay 3  
fill ~16 ~5 ~34 ~18 ~5 ~34 stained_hardened_clay 3  
fill ~16 ~5 ~40 ~18 ~5 ~40 stained_hardened_clay 3  
fill ~16 ~5 ~46 ~16 ~6 ~46 stained_hardened_clay 3  
fill ~16 ~5 ~50 ~16 ~8 ~50 stained_hardened_clay 3  
fill ~16 ~5 ~53 ~16 ~5 ~55 stone_slab 7  
fill ~16 ~5 ~60 ~16 ~5 ~61 stone_slab 7  
fill ~16 ~5 ~68 ~18 ~5 ~68 stone_slab 7  
fill ~17 ~5 ~12 ~21 ~5 ~12 stone_slab 7 
setblock ~17 ~5 ~18 stone_slab 7 
setblock ~17 ~5 ~22 stone_slab 7  
fill ~17 ~5 ~23 ~17 ~9 ~23 stained_hardened_clay 3  
fill ~17 ~5 ~27 ~17 ~7 ~27 stained_hardened_clay 3  
fill ~17 ~5 ~47 ~17 ~7 ~47 stained_hardened_clay 3  
fill ~17 ~5 ~51 ~17 ~9 ~51 stained_hardened_clay 3 
setblock ~17 ~5 ~52 stone_slab 7 
setblock ~17 ~5 ~56 stone_slab 7  
fill ~17 ~5 ~61 ~17 ~5 ~62 stone_slab 7 
setblock ~18 ~5 ~17 stone_slab 7  
fill ~18 ~5 ~22 ~18 ~10 ~22 stained_hardened_clay 3  
fill ~18 ~5 ~26 ~18 ~8 ~26 stained_hardened_clay 3  
fill ~18 ~5 ~48 ~18 ~8 ~48 stained_hardened_clay 3  
fill ~18 ~5 ~52 ~18 ~10 ~52 stained_hardened_clay 3 
setblock ~18 ~5 ~57 stone_slab 7  
fill ~18 ~5 ~62 ~21 ~5 ~62 stone_slab 7 
setblock ~19 ~5 ~5 stone_slab 7  
fill ~19 ~5 ~16 ~21 ~5 ~16 stone_slab 7  
fill ~19 ~5 ~21 ~19 ~10 ~21 stained_hardened_clay 3  
fill ~19 ~5 ~25 ~19 ~9 ~25 stained_hardened_clay 3  
fill ~19 ~5 ~33 ~20 ~5 ~33 stained_hardened_clay 3  
fill ~19 ~5 ~41 ~20 ~5 ~41 stained_hardened_clay 3  
fill ~19 ~5 ~49 ~19 ~9 ~49 stained_hardened_clay 3  
fill ~19 ~5 ~53 ~19 ~10 ~53 stained_hardened_clay 3  
fill ~19 ~5 ~58 ~21 ~5 ~58 stone_slab 7 
setblock ~19 ~5 ~69 stone_slab 7  
fill ~20 ~5 ~4 ~22 ~5 ~4 stone_slab 7  
fill ~20 ~5 ~20 ~20 ~10 ~20 stained_hardened_clay 3  
fill ~20 ~5 ~24 ~20 ~10 ~24 stained_hardened_clay 3  
fill ~20 ~5 ~50 ~20 ~10 ~50 stained_hardened_clay 3  
fill ~20 ~5 ~54 ~20 ~10 ~54 stained_hardened_clay 3  
fill ~20 ~5 ~70 ~22 ~5 ~70 stone_slab 7  
fill ~21 ~5 ~7 ~21 ~12 ~7 log 0  
fill ~21 ~5 ~11 ~22 ~5 ~11 stone_slab 7  
fill ~21 ~5 ~19 ~21 ~10 ~19 stained_hardened_clay 3  
fill ~21 ~5 ~23 ~22 ~5 ~23 stained_hardened_clay 3  
fill ~21 ~5 ~32 ~21 ~12 ~32 stained_hardened_clay 3  
fill ~21 ~5 ~42 ~21 ~11 ~42 stained_hardened_clay 3  
fill ~21 ~5 ~51 ~22 ~5 ~51 stained_hardened_clay 3  
fill ~21 ~5 ~55 ~21 ~10 ~55 stained_hardened_clay 3  
fill ~21 ~5 ~63 ~22 ~5 ~63 stone_slab 7  
fill ~21 ~5 ~67 ~21 ~12 ~67 log 0  
fill ~22 ~5 ~10 ~23 ~5 ~10 stone_slab 7 
setblock ~22 ~5 ~17 stone_slab 7  
fill ~22 ~5 ~18 ~22 ~10 ~18 stained_hardened_clay 3  
fill ~22 ~5 ~30 ~22 ~12 ~30 stained_hardened_clay 3  
fill ~22 ~5 ~31 ~22 ~12 ~31 stained_hardened_clay 3  
fill ~22 ~5 ~43 ~22 ~11 ~43 stained_hardened_clay 3  
fill ~22 ~5 ~44 ~22 ~11 ~44 stained_hardened_clay 3  
fill ~22 ~5 ~56 ~22 ~10 ~56 stained_hardened_clay 3 
setblock ~22 ~5 ~57 stone_slab 7  
fill ~22 ~5 ~64 ~23 ~5 ~64 stone_slab 7 
setblock ~23 ~5 ~5 stone_slab 7  
fill ~23 ~5 ~9 ~25 ~5 ~9 stone_slab 7  
fill ~23 ~5 ~17 ~23 ~9 ~17 stained_hardened_clay 3  
fill ~23 ~5 ~21 ~23 ~11 ~21 stained_hardened_clay 3  
fill ~23 ~5 ~22 ~23 ~11 ~22 stained_hardened_clay 3  
fill ~23 ~5 ~24 ~23 ~12 ~24 stained_hardened_clay 3  
fill ~23 ~5 ~25 ~23 ~12 ~25 stained_hardened_clay 3  
fill ~23 ~5 ~26 ~23 ~12 ~26 stained_hardened_clay 3  
fill ~23 ~5 ~27 ~23 ~12 ~27 stained_hardened_clay 3  
fill ~23 ~5 ~28 ~23 ~12 ~28 stained_hardened_clay 3  
fill ~23 ~5 ~29 ~23 ~12 ~29 stained_hardened_clay 3  
fill ~23 ~5 ~45 ~23 ~11 ~45 stained_hardened_clay 3  
fill ~23 ~5 ~46 ~23 ~11 ~46 stained_hardened_clay 3  
fill ~23 ~5 ~47 ~23 ~11 ~47 stained_hardened_clay 3  
fill ~23 ~5 ~48 ~23 ~12 ~48 stained_hardened_clay 3  
fill ~23 ~5 ~49 ~23 ~12 ~49 stained_hardened_clay 3  
fill ~23 ~5 ~50 ~23 ~12 ~50 stained_hardened_clay 3  
fill ~23 ~5 ~52 ~23 ~11 ~52 stained_hardened_clay 3  
fill ~23 ~5 ~53 ~23 ~11 ~53 stained_hardened_clay 3  
fill ~23 ~5 ~57 ~23 ~9 ~57 stained_hardened_clay 3  
fill ~23 ~5 ~65 ~25 ~5 ~65 stone_slab 7 
setblock ~23 ~5 ~69 stone_slab 7  
fill ~24 ~5 ~6 ~24 ~5 ~9 stone_slab 7  
fill ~24 ~5 ~16 ~24 ~8 ~16 stained_hardened_clay 3  
fill ~24 ~5 ~20 ~24 ~10 ~20 stained_hardened_clay 3  
fill ~24 ~5 ~23 ~29 ~5 ~23 stained_hardened_clay 3  
fill ~24 ~5 ~51 ~29 ~5 ~51 stained_hardened_clay 3  
fill ~24 ~5 ~54 ~24 ~10 ~54 stained_hardened_clay 3  
fill ~24 ~5 ~58 ~24 ~8 ~58 stained_hardened_clay 3  
fill ~24 ~5 ~66 ~24 ~5 ~68 stone_slab 7  
fill ~25 ~5 ~15 ~25 ~7 ~15 stained_hardened_clay 3  
fill ~25 ~5 ~19 ~25 ~9 ~19 stained_hardened_clay 3  
fill ~25 ~5 ~55 ~25 ~9 ~55 stained_hardened_clay 3  
fill ~25 ~5 ~59 ~25 ~7 ~59 stained_hardened_clay 3  
fill ~26 ~5 ~8 ~30 ~5 ~8 stone_slab 7  
fill ~26 ~5 ~14 ~26 ~6 ~14 stained_hardened_clay 3  
fill ~26 ~5 ~18 ~26 ~8 ~18 stained_hardened_clay 3  
fill ~26 ~5 ~56 ~26 ~8 ~56 stained_hardened_clay 3  
fill ~26 ~5 ~60 ~26 ~6 ~60 stained_hardened_clay 3  
fill ~26 ~5 ~66 ~30 ~5 ~66 stone_slab 7 
setblock ~27 ~5 ~13 stained_hardened_clay 3  
fill ~27 ~5 ~17 ~27 ~7 ~17 stained_hardened_clay 3  
fill ~27 ~5 ~57 ~27 ~7 ~57 stained_hardened_clay 3 
setblock ~27 ~5 ~61 stained_hardened_clay 3  
fill ~28 ~5 ~11 ~28 ~5 ~13 quartz_block 0  
fill ~28 ~5 ~16 ~28 ~6 ~16 stained_hardened_clay 3  
fill ~28 ~5 ~58 ~28 ~6 ~58 stained_hardened_clay 3  
fill ~28 ~5 ~61 ~29 ~5 ~61 quartz_block 0  
fill ~28 ~5 ~62 ~28 ~5 ~63 quartz_block 0 
setblock ~29 ~5 ~12 stone_slab 7  
fill ~29 ~5 ~13 ~29 ~5 ~14 quartz_block 0 
setblock ~29 ~5 ~15 stained_hardened_clay 3 
setblock ~29 ~5 ~59 stained_hardened_clay 3  
fill ~29 ~5 ~60 ~31 ~5 ~60 quartz_block 0 
setblock ~29 ~5 ~62 stone_slab 7 
setblock ~30 ~5 ~13 stone_slab 7  
fill ~30 ~5 ~14 ~31 ~5 ~14 quartz_block 0  
fill ~30 ~5 ~22 ~31 ~5 ~22 stained_hardened_clay 3  
fill ~30 ~5 ~52 ~31 ~5 ~52 stained_hardened_clay 3 
setblock ~30 ~5 ~61 stone_slab 7 
setblock ~31 ~5 ~9 stone_slab 7 
setblock ~31 ~5 ~65 stone_slab 7  
fill ~32 ~5 ~10 ~33 ~5 ~10 stone_slab 7  
fill ~32 ~5 ~21 ~32 ~11 ~21 stained_hardened_clay 3  
fill ~32 ~5 ~53 ~32 ~12 ~53 stained_hardened_clay 3  
fill ~32 ~5 ~64 ~33 ~5 ~64 stone_slab 7  
fill ~33 ~5 ~19 ~33 ~11 ~19 stained_hardened_clay 3  
fill ~33 ~5 ~20 ~33 ~11 ~20 stained_hardened_clay 3  
fill ~33 ~5 ~54 ~33 ~12 ~54 stained_hardened_clay 3  
fill ~33 ~5 ~55 ~33 ~12 ~55 stained_hardened_clay 3  
fill ~34 ~5 ~15 ~34 ~13 ~15 quartz_block 0  
fill ~34 ~5 ~16 ~34 ~11 ~16 stained_hardened_clay 3  
fill ~34 ~5 ~17 ~34 ~11 ~17 stained_hardened_clay 3  
fill ~34 ~5 ~18 ~34 ~11 ~18 stained_hardened_clay 3  
fill ~34 ~5 ~56 ~34 ~12 ~56 stained_hardened_clay 3  
fill ~34 ~5 ~57 ~34 ~12 ~57 stained_hardened_clay 3  
fill ~34 ~5 ~58 ~34 ~12 ~58 stained_hardened_clay 3  
fill ~34 ~5 ~59 ~34 ~13 ~59 quartz_block 0  
fill ~40 ~5 ~15 ~40 ~13 ~15 quartz_block 0  
fill ~40 ~5 ~16 ~40 ~12 ~16 stained_hardened_clay 3  
fill ~40 ~5 ~17 ~40 ~12 ~17 stained_hardened_clay 3  
fill ~40 ~5 ~18 ~40 ~12 ~18 stained_hardened_clay 3  
fill ~40 ~5 ~56 ~40 ~11 ~56 stained_hardened_clay 3  
fill ~40 ~5 ~57 ~40 ~11 ~57 stained_hardened_clay 3  
fill ~40 ~5 ~58 ~40 ~11 ~58 stained_hardened_clay 3  
fill ~40 ~5 ~59 ~40 ~13 ~59 quartz_block 0  
fill ~41 ~5 ~10 ~42 ~5 ~10 stone_slab 7  
fill ~41 ~5 ~19 ~41 ~12 ~19 stained_hardened_clay 3  
fill ~41 ~5 ~20 ~41 ~12 ~20 stained_hardened_clay 3  
fill ~41 ~5 ~54 ~41 ~11 ~54 stained_hardened_clay 3  
fill ~41 ~5 ~55 ~41 ~11 ~55 stained_hardened_clay 3  
fill ~41 ~5 ~64 ~42 ~5 ~64 stone_slab 7  
fill ~42 ~5 ~21 ~42 ~12 ~21 stained_hardened_clay 3  
fill ~42 ~5 ~53 ~42 ~11 ~53 stained_hardened_clay 3 
setblock ~43 ~5 ~9 stone_slab 7  
fill ~43 ~5 ~14 ~45 ~5 ~14 quartz_block 0  
fill ~43 ~5 ~22 ~44 ~5 ~22 stained_hardened_clay 3  
fill ~43 ~5 ~52 ~44 ~5 ~52 stained_hardened_clay 3  
fill ~43 ~5 ~60 ~45 ~5 ~60 quartz_block 0 
setblock ~43 ~5 ~65 stone_slab 7  
fill ~44 ~5 ~8 ~48 ~5 ~8 stone_slab 7 
setblock ~44 ~5 ~13 stone_slab 7 
setblock ~44 ~5 ~61 stone_slab 7  
fill ~44 ~5 ~66 ~48 ~5 ~66 stone_slab 7 
setblock ~45 ~5 ~12 stone_slab 7  
fill ~45 ~5 ~13 ~46 ~5 ~13 quartz_block 0 
setblock ~45 ~5 ~15 stained_hardened_clay 3  
fill ~45 ~5 ~23 ~50 ~5 ~23 stained_hardened_clay 3  
fill ~45 ~5 ~51 ~50 ~5 ~51 stained_hardened_clay 3 
setblock ~45 ~5 ~59 stained_hardened_clay 3  
fill ~45 ~5 ~61 ~46 ~5 ~61 quartz_block 0 
setblock ~45 ~5 ~62 stone_slab 7  
fill ~46 ~5 ~11 ~46 ~5 ~13 quartz_block 0  
fill ~46 ~5 ~16 ~46 ~6 ~16 stained_hardened_clay 3  
fill ~46 ~5 ~58 ~46 ~6 ~58 stained_hardened_clay 3  
fill ~46 ~5 ~62 ~46 ~5 ~63 quartz_block 0 
setblock ~47 ~5 ~13 stained_hardened_clay 3  
fill ~47 ~5 ~17 ~47 ~7 ~17 stained_hardened_clay 3  
fill ~47 ~5 ~57 ~47 ~7 ~57 stained_hardened_clay 3 
setblock ~47 ~5 ~61 stained_hardened_clay 3  
fill ~48 ~5 ~14 ~48 ~6 ~14 stained_hardened_clay 3   
fill ~48 ~5 ~18 ~48 ~8 ~18 stained_hardened_clay 3  
fill ~48 ~5 ~56 ~48 ~8 ~56 stained_hardened_clay 3  
fill ~48 ~5 ~60 ~48 ~6 ~60 stained_hardened_clay 3  
fill ~49 ~5 ~9 ~51 ~5 ~9 stone_slab 7  
fill ~49 ~5 ~15 ~49 ~7 ~15 stained_hardened_clay 3  
fill ~49 ~5 ~19 ~49 ~9 ~19 stained_hardened_clay 3  
fill ~49 ~5 ~55 ~49 ~9 ~55 stained_hardened_clay 3  
fill ~49 ~5 ~59 ~49 ~7 ~59 stained_hardened_clay 3  
fill ~49 ~5 ~65 ~51 ~5 ~65 stone_slab 7  
fill ~50 ~5 ~6 ~50 ~5 ~9 stone_slab 7  
fill ~50 ~5 ~16 ~50 ~8 ~16 stained_hardened_clay 3  
fill ~50 ~5 ~20 ~50 ~10 ~20 stained_hardened_clay 3  
fill ~50 ~5 ~54 ~50 ~10 ~54 stained_hardened_clay 3  
fill ~50 ~5 ~58 ~50 ~8 ~58 stained_hardened_clay 3  
fill ~50 ~5 ~66 ~50 ~5 ~68 stone_slab 7 
setblock ~51 ~5 ~5 stone_slab 7  
fill ~51 ~5 ~10 ~52 ~5 ~10 stone_slab 7  
fill ~51 ~5 ~17 ~51 ~9 ~17 stained_hardened_clay 3  
fill ~51 ~5 ~21 ~51 ~11 ~21 stained_hardened_clay 3  
fill ~51 ~5 ~22 ~51 ~11 ~22 stained_hardened_clay 3  
fill ~51 ~5 ~24 ~51 ~12 ~24 stained_hardened_clay 3  
fill ~51 ~5 ~25 ~51 ~12 ~25 stained_hardened_clay 3  
fill ~51 ~5 ~26 ~51 ~12 ~26 stained_hardened_clay 3  
fill ~51 ~5 ~27 ~51 ~11 ~27 stained_hardened_clay 3  
fill ~51 ~5 ~28 ~51 ~11 ~28 stained_hardened_clay 3  
fill ~51 ~5 ~29 ~51 ~11 ~29 stained_hardened_clay 3  
fill ~51 ~5 ~45 ~51 ~12 ~45 stained_hardened_clay 3  
fill ~51 ~5 ~46 ~51 ~12 ~46 stained_hardened_clay 3  
fill ~51 ~5 ~47 ~51 ~12 ~47 stained_hardened_clay 3  
fill ~51 ~5 ~48 ~51 ~12 ~48 stained_hardened_clay 3  
fill ~51 ~5 ~49 ~51 ~12 ~49 stained_hardened_clay 3  
fill ~51 ~5 ~50 ~51 ~12 ~50 stained_hardened_clay 3  
fill ~51 ~5 ~52 ~51 ~11 ~52 stained_hardened_clay 3  
fill ~51 ~5 ~53 ~51 ~11 ~53 stained_hardened_clay 3  
fill ~51 ~5 ~57 ~51 ~9 ~57 stained_hardened_clay 3  
fill ~51 ~5 ~64 ~52 ~5 ~64 stone_slab 7 
setblock ~51 ~5 ~69 stone_slab 7  
fill ~52 ~5 ~4 ~54 ~5 ~4 stone_slab 7  
fill ~52 ~5 ~11 ~53 ~5 ~11 stone_slab 7 
setblock ~52 ~5 ~17 stone_slab 7  
fill ~52 ~5 ~18 ~52 ~10 ~18 stained_hardened_clay 3  
fill ~52 ~5 ~23 ~53 ~5 ~23 stained_hardened_clay 3  
fill ~52 ~5 ~30 ~52 ~11 ~30 stained_hardened_clay 3  
fill ~52 ~5 ~31 ~52 ~11 ~31 stained_hardened_clay 3  
fill ~52 ~5 ~43 ~52 ~12 ~43 stained_hardened_clay 3  
fill ~52 ~5 ~44 ~52 ~12 ~44 stained_hardened_clay 3  
fill ~52 ~5 ~51 ~53 ~5 ~51 stained_hardened_clay 3  
fill ~52 ~5 ~56 ~52 ~10 ~56 stained_hardened_clay 3 
setblock ~52 ~5 ~57 stone_slab 7  
fill ~52 ~5 ~63 ~53 ~5 ~63 stone_slab 7  
fill ~52 ~5 ~70 ~54 ~5 ~70 stone_slab 7  
fill ~53 ~5 ~7 ~53 ~12 ~7 log 0  
fill ~53 ~5 ~12 ~57 ~5 ~12 stone_slab 7  
fill ~53 ~5 ~16 ~55 ~5 ~16 stone_slab 7  
fill ~53 ~5 ~19 ~53 ~10 ~19 stained_hardened_clay 3  
fill ~53 ~5 ~32 ~53 ~11 ~32 stained_hardened_clay 3  
fill ~53 ~5 ~42 ~53 ~12 ~42 stained_hardened_clay 3  
fill ~53 ~5 ~55 ~53 ~10 ~55 stained_hardened_clay 3  
fill ~53 ~5 ~58 ~55 ~5 ~58 stone_slab 7  
fill ~53 ~5 ~62 ~57 ~5 ~62 stone_slab 7  
fill ~53 ~5 ~67 ~53 ~12 ~67 log 0  
fill ~54 ~5 ~20 ~54 ~10 ~20 stained_hardened_clay 3  
fill ~54 ~5 ~24 ~54 ~10 ~24 stained_hardened_clay 3  
fill ~54 ~5 ~33 ~55 ~5 ~33 stained_hardened_clay 3  
fill ~54 ~5 ~41 ~55 ~5 ~41 stained_hardened_clay 3  
fill ~54 ~5 ~50 ~54 ~10 ~50 stained_hardened_clay 3  
fill ~54 ~5 ~54 ~54 ~10 ~54 stained_hardened_clay 3 
setblock ~55 ~5 ~5 stone_slab 7  
fill ~55 ~5 ~21 ~55 ~10 ~21 stained_hardened_clay 3  
fill ~55 ~5 ~25 ~55 ~9 ~25 stained_hardened_clay 3  
fill ~55 ~5 ~49 ~55 ~9 ~49 stained_hardened_clay 3  
fill ~55 ~5 ~53 ~55 ~10 ~53 stained_hardened_clay 3 
setblock ~55 ~5 ~69 stone_slab 7  
fill ~56 ~5 ~6 ~58 ~5 ~6 stone_slab 7 
setblock ~56 ~5 ~17 stone_slab 7  
fill ~56 ~5 ~22 ~56 ~10 ~22 stained_hardened_clay 3  
fill ~56 ~5 ~26 ~56 ~8 ~26 stained_hardened_clay 3  
fill ~56 ~5 ~34 ~58 ~5 ~34 stained_hardened_clay 3  
fill ~56 ~5 ~40 ~58 ~5 ~40 stained_hardened_clay 3  
fill ~56 ~5 ~48 ~56 ~8 ~48 stained_hardened_clay 3  
fill ~56 ~5 ~52 ~56 ~10 ~52 stained_hardened_clay 3 
setblock ~56 ~5 ~57 stone_slab 7  
fill ~56 ~5 ~68 ~58 ~5 ~68 stone_slab 7  
fill ~57 ~5 ~13 ~58 ~5 ~13 stone_slab 7 
setblock ~57 ~5 ~18 stone_slab 7 
setblock ~57 ~5 ~22 stone_slab 7  
fill ~57 ~5 ~23 ~57 ~9 ~23 stained_hardened_clay 3  
fill ~57 ~5 ~27 ~57 ~7 ~27 stained_hardened_clay 3  
fill ~57 ~5 ~47 ~57 ~7 ~47 stained_hardened_clay 3  
fill ~57 ~5 ~51 ~57 ~9 ~51 stained_hardened_clay 3 
setblock ~57 ~5 ~52 stone_slab 7 
setblock ~57 ~5 ~56 stone_slab 7  
fill ~57 ~5 ~61 ~58 ~5 ~61 stone_slab 7  
fill ~58 ~5 ~14 ~59 ~5 ~14 stone_slab 7  
fill ~58 ~5 ~19 ~58 ~5 ~21 stone_slab 7  
fill ~58 ~5 ~24 ~58 ~8 ~24 stained_hardened_clay 3  
fill ~58 ~5 ~28 ~58 ~6 ~28 stained_hardened_clay 3  
fill ~58 ~5 ~46 ~58 ~6 ~46 stained_hardened_clay 3  
fill ~58 ~5 ~50 ~58 ~8 ~50 stained_hardened_clay 3  
fill ~58 ~5 ~53 ~58 ~5 ~55 stone_slab 7  
fill ~58 ~5 ~60 ~59 ~5 ~60 stone_slab 7  
fill ~59 ~5 ~7 ~61 ~5 ~7 stone_slab 7  
fill ~59 ~5 ~15 ~60 ~5 ~15 stone_slab 7  
fill ~59 ~5 ~25 ~59 ~7 ~25 stained_hardened_clay 3 
setblock ~59 ~5 ~29 stained_hardened_clay 3  
fill ~59 ~5 ~34 ~59 ~13 ~34 quartz_block 0  
fill ~59 ~5 ~40 ~59 ~13 ~40 quartz_block 0 
setblock ~59 ~5 ~45 stained_hardened_clay 3  
fill ~59 ~5 ~49 ~59 ~7 ~49 stained_hardened_clay 3  
fill ~59 ~5 ~59 ~60 ~5 ~59 stone_slab 7  
fill ~59 ~5 ~67 ~61 ~5 ~67 stone_slab 7  
fill ~60 ~5 ~16 ~61 ~5 ~16 stone_slab 7  
fill ~60 ~5 ~26 ~60 ~6 ~26 stained_hardened_clay 3  
fill ~60 ~5 ~29 ~61 ~5 ~29 quartz_block 0  
fill ~60 ~5 ~30 ~60 ~5 ~31 quartz_block 0  
fill ~60 ~5 ~43 ~60 ~5 ~45 quartz_block 0  
fill ~60 ~5 ~48 ~60 ~6 ~48 stained_hardened_clay 3  
fill ~60 ~5 ~58 ~61 ~5 ~58 stone_slab 7  
fill ~61 ~5 ~17 ~62 ~5 ~17 stone_slab 7 
setblock ~61 ~5 ~27 stained_hardened_clay 3  
fill ~61 ~5 ~28 ~63 ~5 ~28 quartz_block 0 
setblock ~61 ~5 ~30 stone_slab 7 
setblock ~61 ~5 ~44 stone_slab 7  
fill ~61 ~5 ~45 ~61 ~5 ~46 quartz_block 0 
setblock ~61 ~5 ~47 stained_hardened_clay 3  
fill ~61 ~5 ~57 ~62 ~5 ~57 stone_slab 7  
fill ~62 ~5 ~8 ~63 ~5 ~8 stone_slab 7  
fill ~62 ~5 ~12 ~62 ~12 ~12 log 0  
fill ~62 ~5 ~18 ~62 ~5 ~21 stone_slab 7 
setblock ~62 ~5 ~29 stone_slab 7 
setblock ~62 ~5 ~45 stone_slab 7  
fill ~62 ~5 ~46 ~63 ~5 ~46 quartz_block 0  
fill ~62 ~5 ~53 ~63 ~5 ~53 stone_slab 7  
fill ~62 ~5 ~54 ~62 ~5 ~57 stone_slab 7  
fill ~62 ~5 ~62 ~62 ~12 ~62 log 0  
fill ~62 ~5 ~66 ~63 ~5 ~66 stone_slab 7  
fill ~63 ~5 ~21 ~63 ~5 ~22 stone_slab 7  
fill ~63 ~5 ~52 ~64 ~5 ~52 stone_slab 7 
setblock ~64 ~5 ~9 stone_slab 7  
fill ~64 ~5 ~22 ~64 ~5 ~23 stone_slab 7  
fill ~64 ~5 ~32 ~64 ~5 ~33 stone_slab 7  
fill ~64 ~5 ~41 ~64 ~5 ~42 stone_slab 7  
fill ~64 ~5 ~51 ~65 ~5 ~51 stone_slab 7 
setblock ~64 ~5 ~65 stone_slab 7 
setblock ~65 ~5 ~10 stone_slab 7  
fill ~65 ~5 ~23 ~65 ~5 ~25 stone_slab 7 
setblock ~65 ~5 ~31 stone_slab 7 
setblock ~65 ~5 ~43 stone_slab 7  
fill ~65 ~5 ~49 ~65 ~5 ~51 stone_slab 7 
setblock ~65 ~5 ~64 stone_slab 7  
fill ~66 ~5 ~11 ~66 ~5 ~12 stone_slab 7  
fill ~66 ~5 ~24 ~68 ~5 ~24 stone_slab 7  
fill ~66 ~5 ~26 ~66 ~5 ~30 stone_slab 7  
fill ~66 ~5 ~44 ~66 ~5 ~48 stone_slab 7  
fill ~66 ~5 ~50 ~68 ~5 ~50 stone_slab 7  
fill ~66 ~5 ~62 ~66 ~5 ~63 stone_slab 7  
fill ~67 ~5 ~13 ~67 ~5 ~15 stone_slab 7  
fill ~67 ~5 ~21 ~67 ~12 ~21 log 0  
fill ~67 ~5 ~53 ~67 ~12 ~53 log 0  
fill ~67 ~5 ~59 ~67 ~5 ~61 stone_slab 7  
fill ~68 ~5 ~16 ~68 ~5 ~18 stone_slab 7  
fill ~68 ~5 ~56 ~68 ~5 ~58 stone_slab 7 
setblock ~69 ~5 ~19 stone_slab 7 
setblock ~69 ~5 ~23 stone_slab 7 
setblock ~69 ~5 ~51 stone_slab 7 
setblock ~69 ~5 ~55 stone_slab 7  
fill ~70 ~5 ~20 ~70 ~5 ~22 stone_slab 7  
fill ~70 ~5 ~52 ~70 ~5 ~54 stone_slab 7  
fill ~6 ~6 ~21 ~6 ~12 ~21 leaves 6  
fill ~6 ~6 ~53 ~6 ~12 ~53 leaves 6  
fill ~7 ~6 ~20 ~7 ~12 ~20 leaves 6  
fill ~7 ~6 ~22 ~7 ~12 ~22 leaves 6  
fill ~7 ~6 ~52 ~7 ~12 ~52 leaves 6  
fill ~7 ~6 ~54 ~7 ~12 ~54 leaves 6  
fill ~8 ~6 ~21 ~8 ~12 ~21 leaves 6  
fill ~8 ~6 ~53 ~8 ~12 ~53 leaves 6  
fill ~11 ~6 ~12 ~11 ~12 ~12 leaves 6 
setblock ~11 ~6 ~28 stone_slab 7 
setblock ~11 ~6 ~46 stone_slab 7  
fill ~11 ~6 ~62 ~11 ~12 ~62 leaves 6  
fill ~12 ~6 ~11 ~12 ~12 ~11 leaves 6  
fill ~12 ~6 ~13 ~12 ~12 ~13 leaves 6  
fill ~12 ~6 ~27 ~14 ~6 ~27 quartz_block 0  
fill ~12 ~6 ~47 ~14 ~6 ~47 quartz_block 0  
fill ~12 ~6 ~61 ~12 ~12 ~61 leaves 6  
fill ~12 ~6 ~63 ~12 ~12 ~63 leaves 6  
fill ~13 ~6 ~12 ~13 ~12 ~12 leaves 6 
setblock ~13 ~6 ~28 stone_slab 7 
setblock ~13 ~6 ~46 stone_slab 7  
fill ~13 ~6 ~62 ~13 ~12 ~62 leaves 6  
fill ~14 ~6 ~28 ~15 ~6 ~28 quartz_block 0 
setblock ~14 ~6 ~29 stone_slab 7 
setblock ~14 ~6 ~31 stone_slab 7 
setblock ~14 ~6 ~43 stone_slab 7 
setblock ~14 ~6 ~45 stone_slab 7  
fill ~14 ~6 ~46 ~15 ~6 ~46 quartz_block 0  
fill ~15 ~6 ~29 ~15 ~6 ~30 quartz_block 0  
fill ~15 ~6 ~44 ~15 ~6 ~46 quartz_block 0  
fill ~16 ~6 ~34 ~18 ~6 ~34 stained_hardened_clay 3  
fill ~16 ~6 ~40 ~18 ~6 ~40 stained_hardened_clay 3  
fill ~19 ~6 ~33 ~20 ~6 ~33 stained_hardened_clay 3  
fill ~19 ~6 ~41 ~20 ~6 ~41 stained_hardened_clay 3  
fill ~20 ~6 ~7 ~20 ~12 ~7 leaves 6  
fill ~20 ~6 ~67 ~20 ~12 ~67 leaves 6  
fill ~21 ~6 ~6 ~21 ~12 ~6 leaves 6  
fill ~21 ~6 ~8 ~21 ~12 ~8 leaves 6  
fill ~21 ~6 ~23 ~22 ~6 ~23 stained_hardened_clay 3  
fill ~21 ~6 ~51 ~22 ~6 ~51 stained_hardened_clay 3  
fill ~21 ~6 ~66 ~21 ~12 ~66 leaves 6  
fill ~21 ~6 ~68 ~21 ~12 ~68 leaves 6  
fill ~22 ~6 ~7 ~22 ~12 ~7 leaves 6  
fill ~22 ~6 ~67 ~22 ~12 ~67 leaves 6  
fill ~24 ~6 ~23 ~29 ~6 ~23 stained_hardened_clay 3  
fill ~24 ~6 ~51 ~29 ~6 ~51 stained_hardened_clay 3  
fill ~27 ~6 ~12 ~27 ~6 ~14 quartz_block 0  
fill ~27 ~6 ~60 ~28 ~6 ~60 quartz_block 0  
fill ~27 ~6 ~61 ~27 ~6 ~62 quartz_block 0 
setblock ~28 ~6 ~11 stone_slab 7 
setblock ~28 ~6 ~13 stone_slab 7  
fill ~28 ~6 ~14 ~28 ~6 ~15 quartz_block 0  
fill ~28 ~6 ~59 ~30 ~6 ~59 quartz_block 0 
setblock ~28 ~6 ~61 stone_slab 7 
setblock ~28 ~6 ~63 stone_slab 7 
setblock ~29 ~6 ~14 stone_slab 7  
fill ~29 ~6 ~15 ~30 ~6 ~15 quartz_block 0 
setblock ~29 ~6 ~60 stone_slab 7  
fill ~30 ~6 ~22 ~31 ~6 ~22 stained_hardened_clay 3  
fill ~30 ~6 ~52 ~31 ~6 ~52 stained_hardened_clay 3 
setblock ~31 ~6 ~14 stone_slab 7 
setblock ~31 ~6 ~60 stone_slab 7 
setblock ~43 ~6 ~14 stone_slab 7  
fill ~43 ~6 ~22 ~44 ~6 ~22 stained_hardened_clay 3  
fill ~43 ~6 ~52 ~44 ~6 ~52 stained_hardened_clay 3 
setblock ~43 ~6 ~60 stone_slab 7  
fill ~44 ~6 ~15 ~46 ~6 ~15 quartz_block 0  
fill ~44 ~6 ~59 ~46 ~6 ~59 quartz_block 0 
setblock ~45 ~6 ~14 stone_slab 7  
fill ~45 ~6 ~23 ~50 ~6 ~23 stained_hardened_clay 3  
fill ~45 ~6 ~51 ~50 ~6 ~51 stained_hardened_clay 3 
setblock ~45 ~6 ~60 stone_slab 7 
setblock ~46 ~6 ~11 stone_slab 7 
setblock ~46 ~6 ~13 stone_slab 7  
fill ~46 ~6 ~14 ~47 ~6 ~14 quartz_block 0  
fill ~46 ~6 ~60 ~47 ~6 ~60 quartz_block 0 
setblock ~46 ~6 ~61 stone_slab 7 
setblock ~46 ~6 ~63 stone_slab 7  
fill ~47 ~6 ~12 ~47 ~6 ~14 quartz_block 0  
fill ~47 ~6 ~61 ~47 ~6 ~62 quartz_block 0  
fill ~52 ~6 ~7 ~52 ~12 ~7 leaves 6  
fill ~52 ~6 ~23 ~53 ~6 ~23 stained_hardened_clay 3  
fill ~52 ~6 ~51 ~53 ~6 ~51 stained_hardened_clay 3  
fill ~52 ~6 ~67 ~52 ~12 ~67 leaves 6  
fill ~53 ~6 ~6 ~53 ~12 ~6 leaves 6  
fill ~53 ~6 ~8 ~53 ~12 ~8 leaves 6  
fill ~53 ~6 ~66 ~53 ~12 ~66 leaves 6  
fill ~53 ~6 ~68 ~53 ~12 ~68 leaves 6  
fill ~54 ~6 ~7 ~54 ~12 ~7 leaves 6  
fill ~54 ~6 ~33 ~55 ~6 ~33 stained_hardened_clay 3  
fill ~54 ~6 ~41 ~55 ~6 ~41 stained_hardened_clay 3  
fill ~54 ~6 ~67 ~54 ~12 ~67 leaves 6  
fill ~56 ~6 ~34 ~58 ~6 ~34 stained_hardened_clay 3  
fill ~56 ~6 ~40 ~58 ~6 ~40 stained_hardened_clay 3  
fill ~59 ~6 ~28 ~60 ~6 ~28 quartz_block 0  
fill ~59 ~6 ~29 ~59 ~6 ~30 quartz_block 0  
fill ~59 ~6 ~44 ~59 ~6 ~46 quartz_block 0  
fill ~60 ~6 ~27 ~62 ~6 ~27 quartz_block 0 
setblock ~60 ~6 ~29 stone_slab 7 
setblock ~60 ~6 ~31 stone_slab 7 
setblock ~60 ~6 ~43 stone_slab 7 
setblock ~60 ~6 ~45 stone_slab 7  
fill ~60 ~6 ~46 ~60 ~6 ~47 quartz_block 0  
fill ~61 ~6 ~12 ~61 ~12 ~12 leaves 6 
setblock ~61 ~6 ~28 stone_slab 7 
setblock ~61 ~6 ~46 stone_slab 7  
fill ~61 ~6 ~47 ~62 ~6 ~47 quartz_block 0  
fill ~61 ~6 ~62 ~61 ~12 ~62 leaves 6  
fill ~62 ~6 ~11 ~62 ~12 ~11 leaves 6  
fill ~62 ~6 ~13 ~62 ~12 ~13 leaves 6  
fill ~62 ~6 ~61 ~62 ~12 ~61 leaves 6  
fill ~62 ~6 ~63 ~62 ~12 ~63 leaves 6  
fill ~63 ~6 ~12 ~63 ~12 ~12 leaves 6 
setblock ~63 ~6 ~28 stone_slab 7 
setblock ~63 ~6 ~46 stone_slab 7  
fill ~63 ~6 ~62 ~63 ~12 ~62 leaves 6  
fill ~66 ~6 ~21 ~66 ~12 ~21 leaves 6  
fill ~66 ~6 ~53 ~66 ~12 ~53 leaves 6  
fill ~67 ~6 ~20 ~67 ~12 ~20 leaves 14  
fill ~67 ~6 ~22 ~67 ~12 ~22 leaves 6  
fill ~67 ~6 ~52 ~67 ~12 ~52 leaves 6  
fill ~67 ~6 ~54 ~67 ~12 ~54 leaves 6  
fill ~68 ~6 ~21 ~68 ~12 ~21 leaves 6  
fill ~68 ~6 ~53 ~68 ~12 ~53 leaves 6 
setblock ~12 ~7 ~27 stone_slab 7 
setblock ~12 ~7 ~47 stone_slab 7  
fill ~13 ~7 ~26 ~15 ~7 ~26 quartz_block 0  
fill ~13 ~7 ~48 ~15 ~7 ~48 quartz_block 0 
setblock ~14 ~7 ~27 stone_slab 7 
setblock ~14 ~7 ~47 stone_slab 7  
fill ~15 ~7 ~27 ~16 ~7 ~27 quartz_block 0 
setblock ~15 ~7 ~28 stone_slab 7 
setblock ~15 ~7 ~30 stone_slab 7 
setblock ~15 ~7 ~44 stone_slab 7 
setblock ~15 ~7 ~46 stone_slab 7  
fill ~15 ~7 ~47 ~16 ~7 ~47 quartz_block 0  
fill ~16 ~7 ~28 ~16 ~7 ~29 quartz_block 0  
fill ~16 ~7 ~34 ~18 ~7 ~34 stained_hardened_clay 3  
fill ~16 ~7 ~40 ~18 ~7 ~40 stained_hardened_clay 3  
fill ~16 ~7 ~45 ~16 ~7 ~47 quartz_block 0 
setblock ~19 ~7 ~20 quartz_stairs 4  
fill ~19 ~7 ~33 ~20 ~7 ~33 stained_hardened_clay 3  
fill ~19 ~7 ~41 ~20 ~7 ~41 stained_hardened_clay 3 
setblock ~19 ~7 ~54 quartz_stairs 4 
setblock ~20 ~7 ~19 quartz_stairs 6 
setblock ~20 ~7 ~55 quartz_stairs 7  
fill ~21 ~7 ~23 ~22 ~7 ~23 stained_hardened_clay 3  
fill ~21 ~7 ~51 ~22 ~7 ~51 stained_hardened_clay 3  
fill ~24 ~7 ~23 ~29 ~7 ~23 stained_hardened_clay 3  
fill ~24 ~7 ~51 ~29 ~7 ~51 stained_hardened_clay 3  
fill ~26 ~7 ~13 ~26 ~7 ~15 quartz_block 0  
fill ~26 ~7 ~59 ~27 ~7 ~59 quartz_block 0  
fill ~26 ~7 ~60 ~26 ~7 ~61 quartz_block 0 
setblock ~27 ~7 ~12 stone_slab 7 
setblock ~27 ~7 ~14 stone_slab 7  
fill ~27 ~7 ~15 ~27 ~7 ~16 quartz_block 0  
fill ~27 ~7 ~58 ~29 ~7 ~58 quartz_block 0 
setblock ~27 ~7 ~60 stone_slab 7 
setblock ~27 ~7 ~62 stone_slab 7 
setblock ~28 ~7 ~15 stone_slab 7  
fill ~28 ~7 ~16 ~29 ~7 ~16 quartz_block 0 
setblock ~28 ~7 ~59 stone_slab 7 
setblock ~30 ~7 ~15 stone_slab 7  
fill ~30 ~7 ~22 ~31 ~7 ~22 stained_hardened_clay 3  
fill ~30 ~7 ~52 ~31 ~7 ~52 stained_hardened_clay 3 
setblock ~30 ~7 ~59 stone_slab 7  
fill ~43 ~7 ~22 ~44 ~7 ~22 stained_hardened_clay 3  
fill ~43 ~7 ~52 ~44 ~7 ~52 stained_hardened_clay 3 
setblock ~44 ~7 ~15 stone_slab 7 
setblock ~44 ~7 ~59 stone_slab 7  
fill ~45 ~7 ~16 ~47 ~7 ~16 quartz_block 0  
fill ~45 ~7 ~23 ~50 ~7 ~23 stained_hardened_clay 3  
fill ~45 ~7 ~51 ~50 ~7 ~51 stained_hardened_clay 3  
fill ~45 ~7 ~58 ~47 ~7 ~58 quartz_block 0 
setblock ~46 ~7 ~15 stone_slab 7 
setblock ~46 ~7 ~59 stone_slab 7 
setblock ~47 ~7 ~12 stone_slab 7 
setblock ~47 ~7 ~14 stone_slab 7  
fill ~47 ~7 ~15 ~48 ~7 ~15 quartz_block 0  
fill ~47 ~7 ~59 ~48 ~7 ~59 quartz_block 0 
setblock ~47 ~7 ~60 stone_slab 7 
setblock ~47 ~7 ~62 stone_slab 7  
fill ~48 ~7 ~13 ~48 ~7 ~15 quartz_block 0  
fill ~48 ~7 ~60 ~48 ~7 ~61 quartz_block 0  
fill ~52 ~7 ~23 ~53 ~7 ~23 stained_hardened_clay 3  
fill ~52 ~7 ~51 ~53 ~7 ~51 stained_hardened_clay 3 
setblock ~54 ~7 ~19 quartz_stairs 6  
fill ~54 ~7 ~33 ~55 ~7 ~33 stained_hardened_clay 3  
fill ~54 ~7 ~41 ~55 ~7 ~41 stained_hardened_clay 3 
setblock ~54 ~7 ~55 quartz_stairs 7 
setblock ~55 ~7 ~20 quartz_stairs 5 
setblock ~55 ~7 ~54 quartz_stairs 5  
fill ~56 ~7 ~34 ~58 ~7 ~34 stained_hardened_clay 3  
fill ~56 ~7 ~40 ~58 ~7 ~40 stained_hardened_clay 3  
fill ~58 ~7 ~27 ~59 ~7 ~27 quartz_block 0  
fill ~58 ~7 ~28 ~58 ~7 ~29 quartz_block 0  
fill ~58 ~7 ~45 ~58 ~7 ~47 quartz_block 0  
fill ~59 ~7 ~26 ~61 ~7 ~26 quartz_block 0 
setblock ~59 ~7 ~28 stone_slab 7 
setblock ~59 ~7 ~30 stone_slab 7 
setblock ~59 ~7 ~44 stone_slab 7 
setblock ~59 ~7 ~46 stone_slab 7  
fill ~59 ~7 ~47 ~59 ~7 ~48 quartz_block 0 
setblock ~60 ~7 ~27 stone_slab 7 
setblock ~60 ~7 ~47 stone_slab 7  
fill ~60 ~7 ~48 ~61 ~7 ~48 quartz_block 0 
setblock ~62 ~7 ~27 stone_slab 7 
setblock ~62 ~7 ~47 stone_slab 7  
fill ~6 ~8 ~20 ~6 ~10 ~20 leaves 6  
fill ~6 ~8 ~22 ~6 ~10 ~22 leaves 6  
fill ~6 ~8 ~52 ~6 ~10 ~52 leaves 6  
fill ~6 ~8 ~54 ~6 ~10 ~54 leaves 6  
fill ~8 ~8 ~20 ~8 ~10 ~20 leaves 6  
fill ~8 ~8 ~22 ~8 ~10 ~22 leaves 6  
fill ~8 ~8 ~52 ~8 ~10 ~52 leaves 6  
fill ~8 ~8 ~54 ~8 ~10 ~54 leaves 6  
fill ~11 ~8 ~11 ~11 ~10 ~11 leaves 6  
fill ~11 ~8 ~13 ~11 ~10 ~13 leaves 6  
fill ~11 ~8 ~61 ~11 ~10 ~61 leaves 6  
fill ~11 ~8 ~63 ~11 ~10 ~63 leaves 6  
fill ~13 ~8 ~11 ~13 ~10 ~11 leaves 6  
fill ~13 ~8 ~13 ~13 ~10 ~13 leaves 6 
setblock ~13 ~8 ~26 stone_slab 7 
setblock ~13 ~8 ~48 stone_slab 7  
fill ~13 ~8 ~61 ~13 ~10 ~61 leaves 6  
fill ~13 ~8 ~63 ~13 ~10 ~63 leaves 6  
fill ~14 ~8 ~25 ~16 ~8 ~25 quartz_block 0  
fill ~14 ~8 ~49 ~16 ~8 ~49 quartz_block 0 
setblock ~15 ~8 ~26 stone_slab 7 
setblock ~15 ~8 ~48 stone_slab 7  
fill ~16 ~8 ~26 ~17 ~8 ~26 quartz_block 0 
setblock ~16 ~8 ~27 stone_slab 7 
setblock ~16 ~8 ~29 stone_slab 7  
fill ~16 ~8 ~34 ~18 ~8 ~34 stained_hardened_clay 3  
fill ~16 ~8 ~40 ~18 ~8 ~40 stained_hardened_clay 3 
setblock ~16 ~8 ~45 stone_slab 7 
setblock ~16 ~8 ~47 stone_slab 7  
fill ~16 ~8 ~48 ~17 ~8 ~48 quartz_block 0  
fill ~17 ~8 ~27 ~17 ~8 ~28 quartz_block 0  
fill ~17 ~8 ~46 ~17 ~8 ~48 quartz_block 0 
setblock ~19 ~8 ~19 double_stone_slab 7  
fill ~19 ~8 ~33 ~20 ~8 ~33 stained_hardened_clay 3  
fill ~19 ~8 ~41 ~20 ~8 ~41 stained_hardened_clay 3 
setblock ~19 ~8 ~55 double_stone_slab 7  
fill ~20 ~8 ~6 ~20 ~10 ~6 leaves 6  
fill ~20 ~8 ~8 ~20 ~10 ~8 leaves 6  
fill ~20 ~8 ~66 ~20 ~10 ~66 leaves 6  
fill ~20 ~8 ~68 ~20 ~10 ~68 leaves 6  
fill ~21 ~8 ~23 ~22 ~8 ~23 stained_hardened_clay 3  
fill ~21 ~8 ~51 ~22 ~8 ~51 stained_hardened_clay 3  
fill ~22 ~8 ~6 ~22 ~10 ~6 leaves 6  
fill ~22 ~8 ~8 ~22 ~10 ~8 leaves 6  
fill ~22 ~8 ~66 ~22 ~10 ~66 leaves 6  
fill ~22 ~8 ~68 ~22 ~10 ~68 leaves 6  
fill ~24 ~8 ~23 ~29 ~8 ~23 stained_hardened_clay 3  
fill ~24 ~8 ~51 ~29 ~8 ~51 stained_hardened_clay 3  
fill ~25 ~8 ~14 ~25 ~8 ~16 quartz_block 0  
fill ~25 ~8 ~58 ~26 ~8 ~58 quartz_block 0  
fill ~25 ~8 ~59 ~25 ~8 ~60 quartz_block 0 
setblock ~26 ~8 ~13 stone_slab 7 
setblock ~26 ~8 ~15 stone_slab 7  
fill ~26 ~8 ~16 ~26 ~8 ~17 quartz_block 0  
fill ~26 ~8 ~57 ~28 ~8 ~57 quartz_block 0 
setblock ~26 ~8 ~59 stone_slab 7 
setblock ~26 ~8 ~61 stone_slab 7 
setblock ~27 ~8 ~16 stone_slab 7  
fill ~27 ~8 ~17 ~28 ~8 ~17 quartz_block 0 
setblock ~27 ~8 ~58 stone_slab 7 
setblock ~29 ~8 ~16 stone_slab 7 
setblock ~29 ~8 ~58 stone_slab 7  
fill ~30 ~8 ~22 ~31 ~8 ~22 stained_hardened_clay 3  
fill ~30 ~8 ~52 ~31 ~8 ~52 stained_hardened_clay 3  
fill ~43 ~8 ~22 ~44 ~8 ~22 stained_hardened_clay 3  
fill ~43 ~8 ~52 ~44 ~8 ~52 stained_hardened_clay 3 
setblock ~45 ~8 ~16 stone_slab 7  
fill ~45 ~8 ~23 ~50 ~8 ~23 stained_hardened_clay 3  
fill ~45 ~8 ~51 ~50 ~8 ~51 stained_hardened_clay 3 
setblock ~45 ~8 ~58 stone_slab 7  
fill ~46 ~8 ~17 ~48 ~8 ~17 quartz_block 0  
fill ~46 ~8 ~57 ~48 ~8 ~57 quartz_block 0 
setblock ~47 ~8 ~16 stone_slab 7 
setblock ~47 ~8 ~58 stone_slab 7 
setblock ~48 ~8 ~13 stone_slab 7 
setblock ~48 ~8 ~15 stone_slab 7  
fill ~48 ~8 ~16 ~49 ~8 ~16 quartz_block 0  
fill ~48 ~8 ~58 ~49 ~8 ~58 quartz_block 0 
setblock ~48 ~8 ~59 stone_slab 7 
setblock ~48 ~8 ~61 stone_slab 7  
fill ~49 ~8 ~14 ~49 ~8 ~16 quartz_block 0  
fill ~49 ~8 ~59 ~49 ~8 ~60 quartz_block 0  
fill ~52 ~8 ~6 ~52 ~10 ~6 leaves 6  
fill ~52 ~8 ~8 ~52 ~10 ~8 leaves 6  
fill ~52 ~8 ~23 ~53 ~8 ~23 stained_hardened_clay 3  
fill ~52 ~8 ~51 ~53 ~8 ~51 stained_hardened_clay 3  
fill ~52 ~8 ~66 ~52 ~10 ~66 leaves 6  
fill ~52 ~8 ~68 ~52 ~10 ~68 leaves 6  
fill ~54 ~8 ~6 ~54 ~10 ~6 leaves 6  
fill ~54 ~8 ~8 ~54 ~10 ~8 leaves 6  
fill ~54 ~8 ~33 ~55 ~8 ~33 stained_hardened_clay 3  
fill ~54 ~8 ~41 ~55 ~8 ~41 stained_hardened_clay 3  
fill ~54 ~8 ~66 ~54 ~10 ~66 leaves 6  
fill ~54 ~8 ~68 ~54 ~10 ~68 leaves 6 
setblock ~55 ~8 ~19 double_stone_slab 7 
setblock ~55 ~8 ~55 double_stone_slab 7  
fill ~56 ~8 ~34 ~58 ~8 ~34 stained_hardened_clay 3  
fill ~56 ~8 ~40 ~58 ~8 ~40 stained_hardened_clay 3  
fill ~57 ~8 ~26 ~58 ~8 ~26 quartz_block 0  
fill ~57 ~8 ~27 ~57 ~8 ~28 quartz_block 0  
fill ~57 ~8 ~46 ~57 ~8 ~48 quartz_block 0  
fill ~58 ~8 ~25 ~60 ~8 ~25 quartz_block 0 
setblock ~58 ~8 ~27 stone_slab 7 
setblock ~58 ~8 ~29 stone_slab 7 
setblock ~58 ~8 ~45 stone_slab 7 
setblock ~58 ~8 ~47 stone_slab 7  
fill ~58 ~8 ~48 ~58 ~8 ~49 quartz_block 0 
setblock ~59 ~8 ~26 stone_slab 7 
setblock ~59 ~8 ~48 stone_slab 7  
fill ~59 ~8 ~49 ~60 ~8 ~49 quartz_block 0  
fill ~61 ~8 ~11 ~61 ~10 ~11 leaves 6  
fill ~61 ~8 ~13 ~61 ~10 ~13 leaves 6 
setblock ~61 ~8 ~26 stone_slab 7 
setblock ~61 ~8 ~48 stone_slab 7  
fill ~61 ~8 ~61 ~61 ~10 ~61 leaves 6  
fill ~61 ~8 ~63 ~61 ~10 ~63 leaves 6  
fill ~63 ~8 ~11 ~63 ~10 ~11 leaves 6  
fill ~63 ~8 ~13 ~63 ~10 ~13 leaves 6  
fill ~63 ~8 ~61 ~63 ~10 ~61 leaves 6  
fill ~63 ~8 ~63 ~63 ~10 ~63 leaves 6  
fill ~66 ~8 ~20 ~66 ~10 ~20 leaves 14  
fill ~66 ~8 ~22 ~66 ~10 ~22 leaves 6  
fill ~66 ~8 ~52 ~66 ~10 ~52 leaves 6  
fill ~66 ~8 ~54 ~66 ~10 ~54 leaves 6  
fill ~68 ~8 ~20 ~68 ~10 ~20 leaves 14  
fill ~68 ~8 ~22 ~68 ~10 ~22 leaves 6  
fill ~68 ~8 ~52 ~68 ~10 ~52 leaves 6  
fill ~68 ~8 ~54 ~68 ~10 ~54 leaves 6 
setblock ~14 ~9 ~25 stone_slab 7 
setblock ~14 ~9 ~49 stone_slab 7  
fill ~15 ~9 ~24 ~17 ~9 ~24 quartz_block 0  
fill ~15 ~9 ~50 ~17 ~9 ~50 quartz_block 0 
setblock ~16 ~9 ~25 stone_slab 7  
fill ~16 ~9 ~34 ~18 ~9 ~34 stained_hardened_clay 3  
fill ~16 ~9 ~40 ~18 ~9 ~40 stained_hardened_clay 3 
setblock ~16 ~9 ~49 stone_slab 7  
fill ~17 ~9 ~25 ~18 ~9 ~25 quartz_block 0 
setblock ~17 ~9 ~26 stone_slab 7 
setblock ~17 ~9 ~28 stone_slab 7 
setblock ~17 ~9 ~46 stone_slab 7 
setblock ~17 ~9 ~48 stone_slab 7  
fill ~17 ~9 ~49 ~18 ~9 ~49 quartz_block 0  
fill ~18 ~9 ~26 ~18 ~9 ~27 quartz_block 0  
fill ~18 ~9 ~47 ~18 ~9 ~49 quartz_block 0  
fill ~19 ~9 ~33 ~20 ~9 ~33 stained_hardened_clay 3  
fill ~19 ~9 ~41 ~20 ~9 ~41 stained_hardened_clay 3  
fill ~21 ~9 ~23 ~22 ~9 ~23 stained_hardened_clay 3  
fill ~21 ~9 ~51 ~22 ~9 ~51 stained_hardened_clay 3  
fill ~24 ~9 ~15 ~24 ~9 ~17 quartz_block 0  
fill ~24 ~9 ~23 ~29 ~9 ~23 stained_hardened_clay 3  
fill ~24 ~9 ~51 ~29 ~9 ~51 stained_hardened_clay 3  
fill ~24 ~9 ~57 ~25 ~9 ~57 quartz_block 0  
fill ~24 ~9 ~58 ~24 ~9 ~59 quartz_block 0 
setblock ~25 ~9 ~14 stone_slab 7 
setblock ~25 ~9 ~16 stone_slab 7  
fill ~25 ~9 ~17 ~25 ~9 ~18 quartz_block 0  
fill ~25 ~9 ~56 ~27 ~9 ~56 quartz_block 0 
setblock ~25 ~9 ~58 stone_slab 7 
setblock ~25 ~9 ~60 stone_slab 7 
setblock ~26 ~9 ~17 stone_slab 7  
fill ~26 ~9 ~18 ~27 ~9 ~18 quartz_block 0 
setblock ~26 ~9 ~57 stone_slab 7 
setblock ~28 ~9 ~17 stone_slab 7 
setblock ~28 ~9 ~57 stone_slab 7  
fill ~30 ~9 ~22 ~31 ~9 ~22 stained_hardened_clay 3  
fill ~30 ~9 ~52 ~31 ~9 ~52 stained_hardened_clay 3  
fill ~43 ~9 ~22 ~44 ~9 ~22 stained_hardened_clay 3  
fill ~43 ~9 ~52 ~44 ~9 ~52 stained_hardened_clay 3  
fill ~45 ~9 ~23 ~50 ~9 ~23 stained_hardened_clay 3  
fill ~45 ~9 ~51 ~50 ~9 ~51 stained_hardened_clay 3 
setblock ~46 ~9 ~17 stone_slab 7 
setblock ~46 ~9 ~57 stone_slab 7  
fill ~47 ~9 ~18 ~49 ~9 ~18 quartz_block 0  
fill ~47 ~9 ~56 ~49 ~9 ~56 quartz_block 0 
setblock ~48 ~9 ~17 stone_slab 7 
setblock ~48 ~9 ~57 stone_slab 7 
setblock ~49 ~9 ~14 stone_slab 7 
setblock ~49 ~9 ~16 stone_slab 7  
fill ~49 ~9 ~17 ~50 ~9 ~17 quartz_block 0  
fill ~49 ~9 ~57 ~50 ~9 ~57 quartz_block 0 
setblock ~49 ~9 ~58 stone_slab 7 
setblock ~49 ~9 ~60 stone_slab 7  
fill ~50 ~9 ~15 ~50 ~9 ~17 quartz_block 0  
fill ~50 ~9 ~58 ~50 ~9 ~59 quartz_block 0  
fill ~52 ~9 ~23 ~53 ~9 ~23 stained_hardened_clay 3  
fill ~52 ~9 ~51 ~53 ~9 ~51 stained_hardened_clay 3  
fill ~54 ~9 ~33 ~55 ~9 ~33 stained_hardened_clay 3  
fill ~54 ~9 ~41 ~55 ~9 ~41 stained_hardened_clay 3  
fill ~56 ~9 ~25 ~57 ~9 ~25 quartz_block 0  
fill ~56 ~9 ~26 ~56 ~9 ~27 quartz_block 0  
fill ~56 ~9 ~34 ~58 ~9 ~34 stained_hardened_clay 3  
fill ~56 ~9 ~40 ~58 ~9 ~40 stained_hardened_clay 3  
fill ~56 ~9 ~47 ~56 ~9 ~49 quartz_block 0  
fill ~57 ~9 ~24 ~59 ~9 ~24 quartz_block 0 
setblock ~57 ~9 ~26 stone_slab 7 
setblock ~57 ~9 ~28 stone_slab 7 
setblock ~57 ~9 ~46 stone_slab 7 
setblock ~57 ~9 ~48 stone_slab 7  
fill ~57 ~9 ~49 ~57 ~9 ~50 quartz_block 0 
setblock ~58 ~9 ~25 stone_slab 7 
setblock ~58 ~9 ~49 stone_slab 7  
fill ~58 ~9 ~50 ~59 ~9 ~50 quartz_block 0 
setblock ~60 ~9 ~25 stone_slab 7 
setblock ~60 ~9 ~49 stone_slab 7 
setblock ~15 ~10 ~24 stone_slab 7 
setblock ~15 ~10 ~50 stone_slab 7  
fill ~16 ~10 ~23 ~18 ~10 ~23 quartz_block 0  
fill ~16 ~10 ~34 ~18 ~10 ~34 stained_hardened_clay 3  
fill ~16 ~10 ~40 ~18 ~10 ~40 stained_hardened_clay 3  
fill ~16 ~10 ~51 ~18 ~10 ~51 quartz_block 0 
setblock ~17 ~10 ~24 stone_slab 7 
setblock ~17 ~10 ~50 stone_slab 7  
fill ~18 ~10 ~24 ~19 ~10 ~24 quartz_block 0 
setblock ~18 ~10 ~25 stone_slab 7 
setblock ~18 ~10 ~27 stone_slab 7 
setblock ~18 ~10 ~47 stone_slab 7 
setblock ~18 ~10 ~49 stone_slab 7  
fill ~18 ~10 ~50 ~19 ~10 ~50 quartz_block 0  
fill ~19 ~10 ~25 ~19 ~10 ~26 quartz_block 0  
fill ~19 ~10 ~33 ~20 ~10 ~33 stained_hardened_clay 3  
fill ~19 ~10 ~41 ~20 ~10 ~41 stained_hardened_clay 3  
fill ~19 ~10 ~48 ~19 ~10 ~50 quartz_block 0  
fill ~21 ~10 ~23 ~22 ~10 ~23 stained_hardened_clay 3  
fill ~21 ~10 ~51 ~22 ~10 ~51 stained_hardened_clay 3  
fill ~23 ~10 ~16 ~23 ~10 ~18 quartz_block 0  
fill ~23 ~10 ~56 ~24 ~10 ~56 quartz_block 0  
fill ~23 ~10 ~57 ~23 ~10 ~58 quartz_block 0 
setblock ~24 ~10 ~15 stone_slab 7 
setblock ~24 ~10 ~17 stone_slab 7  
fill ~24 ~10 ~18 ~24 ~10 ~19 quartz_block 0  
fill ~24 ~10 ~23 ~29 ~10 ~23 stained_hardened_clay 3  
fill ~24 ~10 ~51 ~29 ~10 ~51 stained_hardened_clay 3  
fill ~24 ~10 ~55 ~26 ~10 ~55 quartz_block 0 
setblock ~24 ~10 ~57 stone_slab 7 
setblock ~24 ~10 ~59 stone_slab 7 
setblock ~25 ~10 ~18 stone_slab 7  
fill ~25 ~10 ~19 ~26 ~10 ~19 quartz_block 0 
setblock ~25 ~10 ~56 stone_slab 7 
setblock ~27 ~10 ~18 stone_slab 7 
setblock ~27 ~10 ~56 stone_slab 7  
fill ~30 ~10 ~22 ~31 ~10 ~22 stained_hardened_clay 3  
fill ~30 ~10 ~52 ~31 ~10 ~52 stained_hardened_clay 3  
fill ~43 ~10 ~22 ~44 ~10 ~22 stained_hardened_clay 3  
fill ~43 ~10 ~52 ~44 ~10 ~52 stained_hardened_clay 3  
fill ~45 ~10 ~23 ~50 ~10 ~23 stained_hardened_clay 3  
fill ~45 ~10 ~51 ~50 ~10 ~51 stained_hardened_clay 3 
setblock ~47 ~10 ~18 stone_slab 7 
setblock ~47 ~10 ~56 stone_slab 7  
fill ~48 ~10 ~19 ~50 ~10 ~19 quartz_block 0  
fill ~48 ~10 ~55 ~50 ~10 ~55 quartz_block 0 
setblock ~49 ~10 ~18 stone_slab 7 
setblock ~49 ~10 ~56 stone_slab 7 
setblock ~50 ~10 ~15 stone_slab 7 
setblock ~50 ~10 ~17 stone_slab 7  
fill ~50 ~10 ~18 ~51 ~10 ~18 quartz_block 0  
fill ~50 ~10 ~56 ~51 ~10 ~56 quartz_block 0 
setblock ~50 ~10 ~57 stone_slab 7 
setblock ~50 ~10 ~59 stone_slab 7  
fill ~51 ~10 ~16 ~51 ~10 ~18 quartz_block 0  
fill ~51 ~10 ~57 ~51 ~10 ~58 quartz_block 0  
fill ~52 ~10 ~23 ~53 ~10 ~23 stained_hardened_clay 3  
fill ~52 ~10 ~51 ~53 ~10 ~51 stained_hardened_clay 3  
fill ~54 ~10 ~33 ~55 ~10 ~33 stained_hardened_clay 3  
fill ~54 ~10 ~41 ~55 ~10 ~41 stained_hardened_clay 3  
fill ~55 ~10 ~24 ~56 ~10 ~24 quartz_block 0  
fill ~55 ~10 ~25 ~55 ~10 ~26 quartz_block 0  
fill ~55 ~10 ~48 ~55 ~10 ~50 quartz_block 0  
fill ~56 ~10 ~23 ~58 ~10 ~23 quartz_block 0 
setblock ~56 ~10 ~25 stone_slab 7 
setblock ~56 ~10 ~27 stone_slab 7  
fill ~56 ~10 ~34 ~58 ~10 ~34 stained_hardened_clay 3  
fill ~56 ~10 ~40 ~58 ~10 ~40 stained_hardened_clay 3 
setblock ~56 ~10 ~47 stone_slab 7 
setblock ~56 ~10 ~49 stone_slab 7  
fill ~56 ~10 ~50 ~56 ~10 ~51 quartz_block 0 
setblock ~57 ~10 ~24 stone_slab 7 
setblock ~57 ~10 ~50 stone_slab 7  
fill ~57 ~10 ~51 ~58 ~10 ~51 quartz_block 0 
setblock ~59 ~10 ~24 stone_slab 7 
setblock ~59 ~10 ~50 stone_slab 7 
setblock ~16 ~11 ~23 stone_slab 7  
fill ~16 ~11 ~34 ~18 ~11 ~34 stained_hardened_clay 3  
fill ~16 ~11 ~40 ~18 ~11 ~40 stained_hardened_clay 3 
setblock ~16 ~11 ~51 stone_slab 7  
fill ~17 ~11 ~22 ~21 ~11 ~22 quartz_block 0  
fill ~17 ~11 ~52 ~21 ~11 ~52 quartz_block 0  
fill ~18 ~11 ~21 ~22 ~11 ~21 quartz_block 0 
setblock ~18 ~11 ~23 stone_slab 7 
setblock ~18 ~11 ~51 stone_slab 7  
fill ~18 ~11 ~53 ~22 ~11 ~53 quartz_block 0  
fill ~19 ~11 ~20 ~25 ~11 ~20 quartz_block 0  
fill ~19 ~11 ~23 ~20 ~11 ~23 quartz_block 0 
setblock ~19 ~11 ~24 stone_slab 7 
setblock ~19 ~11 ~26 stone_slab 7  
fill ~19 ~11 ~33 ~20 ~11 ~33 stained_hardened_clay 3  
fill ~19 ~11 ~41 ~20 ~11 ~41 stained_hardened_clay 3 
setblock ~19 ~11 ~48 stone_slab 7 
setblock ~19 ~11 ~50 stone_slab 7  
fill ~19 ~11 ~51 ~20 ~11 ~51 quartz_block 0  
fill ~19 ~11 ~54 ~25 ~11 ~54 quartz_block 0  
fill ~20 ~11 ~19 ~23 ~11 ~19 quartz_block 0  
fill ~20 ~11 ~24 ~20 ~11 ~25 quartz_block 0  
fill ~20 ~11 ~49 ~20 ~11 ~55 quartz_block 0  
fill ~21 ~11 ~18 ~22 ~11 ~18 quartz_block 0  
fill ~21 ~11 ~23 ~22 ~11 ~23 stained_hardened_clay 3  
fill ~21 ~11 ~51 ~22 ~11 ~51 stained_hardened_clay 3  
fill ~21 ~11 ~55 ~23 ~11 ~55 quartz_block 0  
fill ~21 ~11 ~56 ~22 ~11 ~56 quartz_block 0 
setblock ~22 ~11 ~17 quartz_block 0 
setblock ~22 ~11 ~57 quartz_block 0 
setblock ~23 ~11 ~16 stone_slab 7 
setblock ~23 ~11 ~18 stone_slab 7 
setblock ~23 ~11 ~56 stone_slab 7 
setblock ~23 ~11 ~58 stone_slab 7 
setblock ~24 ~11 ~19 stone_slab 7  
fill ~24 ~11 ~23 ~29 ~11 ~23 stained_hardened_clay 3  
fill ~24 ~11 ~51 ~29 ~11 ~51 stained_hardened_clay 3 
setblock ~24 ~11 ~55 stone_slab 7 
setblock ~26 ~11 ~19 stone_slab 7 
setblock ~26 ~11 ~55 stone_slab 7  
fill ~30 ~11 ~22 ~31 ~11 ~22 stained_hardened_clay 3  
fill ~30 ~11 ~52 ~31 ~11 ~52 stained_hardened_clay 3  
fill ~43 ~11 ~22 ~44 ~11 ~22 stained_hardened_clay 3  
fill ~43 ~11 ~52 ~44 ~11 ~52 stained_hardened_clay 3  
fill ~45 ~11 ~23 ~50 ~11 ~23 stained_hardened_clay 3  
fill ~45 ~11 ~51 ~50 ~11 ~51 stained_hardened_clay 3 
setblock ~48 ~11 ~19 stone_slab 7 
setblock ~48 ~11 ~55 stone_slab 7  
fill ~49 ~11 ~20 ~55 ~11 ~20 quartz_block 0  
fill ~49 ~11 ~54 ~55 ~11 ~54 quartz_block 0 
setblock ~50 ~11 ~19 stone_slab 7 
setblock ~50 ~11 ~55 stone_slab 7 
setblock ~51 ~11 ~16 stone_slab 7 
setblock ~51 ~11 ~18 stone_slab 7  
fill ~51 ~11 ~19 ~54 ~11 ~19 quartz_block 0  
fill ~51 ~11 ~55 ~54 ~11 ~55 quartz_block 0 
setblock ~51 ~11 ~56 stone_slab 7 
setblock ~51 ~11 ~58 stone_slab 7  
fill ~52 ~11 ~17 ~52 ~11 ~21 quartz_block 0  
fill ~52 ~11 ~23 ~53 ~11 ~23 stained_hardened_clay 3  
fill ~52 ~11 ~51 ~53 ~11 ~51 stained_hardened_clay 3  
fill ~52 ~11 ~53 ~56 ~11 ~53 quartz_block 0  
fill ~52 ~11 ~56 ~53 ~11 ~56 quartz_block 0  
fill ~52 ~11 ~57 ~52 ~11 ~53 quartz_block 0  
fill ~53 ~11 ~18 ~53 ~12 ~18 quartz_block 0  
fill ~53 ~11 ~21 ~56 ~11 ~21 quartz_block 0  
fill ~53 ~11 ~22 ~57 ~11 ~22 quartz_block 0  
fill ~53 ~11 ~52 ~57 ~11 ~52 quartz_block 0  
fill ~54 ~11 ~23 ~55 ~11 ~23 quartz_block 0  
fill ~54 ~11 ~24 ~54 ~11 ~25 quartz_block 0  
fill ~54 ~11 ~33 ~55 ~11 ~33 stained_hardened_clay 3  
fill ~54 ~11 ~41 ~55 ~11 ~41 stained_hardened_clay 3  
fill ~54 ~11 ~49 ~54 ~11 ~55 quartz_block 0 
setblock ~55 ~11 ~24 stone_slab 7 
setblock ~55 ~11 ~26 stone_slab 7 
setblock ~55 ~11 ~48 stone_slab 7 
setblock ~55 ~11 ~50 stone_slab 7 
setblock ~55 ~11 ~51 quartz_block 0 
setblock ~56 ~11 ~23 stone_slab 7  
fill ~56 ~11 ~34 ~58 ~11 ~34 stained_hardened_clay 3  
fill ~56 ~11 ~40 ~58 ~11 ~40 stained_hardened_clay 3 
setblock ~56 ~11 ~51 stone_slab 7 
setblock ~58 ~11 ~23 stone_slab 7 
setblock ~58 ~11 ~51 stone_slab 7  
fill ~14 ~12 ~33 ~14 ~12 ~35 quartz_stairs 4  
fill ~14 ~12 ~39 ~14 ~12 ~40 quartz_stairs 4  
fill ~14 ~12 ~41 ~18 ~12 ~41 quartz_stairs 7  
fill ~15 ~12 ~33 ~18 ~12 ~33 quartz_stairs 6   
fill ~15 ~12 ~35 ~19 ~12 ~35 quartz_stairs 7  
fill ~15 ~12 ~39 ~18 ~12 ~39 quartz_stairs 6  
fill ~16 ~12 ~34 ~18 ~12 ~34 stained_hardened_clay 3 
setblock ~17 ~12 ~22 stone_slab 7 
setblock ~17 ~12 ~52 stone_slab 7  
fill ~18 ~12 ~21 ~18 ~11 ~21 quartz_block 0 
setblock ~18 ~12 ~32 quartz_stairs 4 
setblock ~18 ~12 ~42 quartz_stairs 4  
fill ~18 ~12 ~53 ~18 ~11 ~53 quartz_block 0  
fill ~19 ~12 ~20 ~19 ~11 ~20 quartz_block 0  
fill ~19 ~12 ~32 ~20 ~12 ~32 quartz_stairs 6  
fill ~19 ~12 ~33 ~20 ~12 ~33 stained_hardened_clay 3 
setblock ~19 ~12 ~34 quartz_stairs 5 
setblock ~19 ~12 ~39 quartz_stairs 5  
fill ~19 ~12 ~40 ~20 ~12 ~40 quartz_stairs 6  
fill ~19 ~12 ~42 ~20 ~12 ~42 quartz_stairs 7  
fill ~19 ~12 ~54 ~19 ~11 ~54 quartz_block 0  
fill ~20 ~12 ~19 ~20 ~11 ~19 quartz_block 0 
setblock ~20 ~12 ~25 stone_slab 7 
setblock ~20 ~12 ~31 quartz_stairs 4 
setblock ~20 ~12 ~34 quartz_stairs 7 
setblock ~20 ~12 ~43 quartz_stairs 4 
setblock ~20 ~12 ~49 stone_slab 7 
setblock ~20 ~12 ~55 quartz_block 0  
fill ~21 ~12 ~18 ~21 ~11 ~18 quartz_block 0 
setblock ~21 ~12 ~23 stone_slab 7  
fill ~21 ~12 ~24 ~22 ~12 ~24 quartz_block 0  
fill ~21 ~12 ~29 ~21 ~12 ~30 quartz_stairs 4 
setblock ~21 ~12 ~31 quartz_stairs 6  
fill ~21 ~12 ~33 ~21 ~12 ~34 quartz_stairs 5 
setblock ~21 ~12 ~40 quartz_stairs 5 
setblock ~21 ~12 ~41 quartz_stairs 6 
setblock ~21 ~12 ~43 quartz_stairs 7  
fill ~21 ~12 ~44 ~21 ~12 ~45 quartz_stairs 4  
fill ~21 ~12 ~50 ~22 ~12 ~50 quartz_block 0 
setblock ~21 ~12 ~51 stone_slab 7  
fill ~21 ~12 ~56 ~21 ~11 ~56 quartz_block 0 
setblock ~22 ~12 ~17 stone_slab 7 
setblock ~22 ~12 ~22 stone_slab 7  
fill ~22 ~12 ~23 ~23 ~12 ~23 quartz_block 0  
fill ~22 ~12 ~25 ~22 ~12 ~28 quartz_stairs 4 
setblock ~22 ~12 ~29 quartz_stairs 6 
setblock ~22 ~12 ~32 quartz_stairs 5 
setblock ~22 ~12 ~33 quartz_stairs 7 
setblock ~22 ~12 ~41 quartz_stairs 5 
setblock ~22 ~12 ~42 quartz_stairs 6 
setblock ~22 ~12 ~45 quartz_stairs 7  
fill ~22 ~12 ~46 ~22 ~12 ~49 quartz_stairs 4  
fill ~22 ~12 ~51 ~23 ~12 ~51 quartz_block 0 
setblock ~22 ~12 ~52 stone_slab 7 
setblock ~22 ~12 ~57 stone_slab 7 
setblock ~23 ~12 ~21 stone_slab 7  
fill ~23 ~12 ~22 ~24 ~12 ~22 quartz_block 0  
fill ~23 ~12 ~30 ~23 ~12 ~31 quartz_stairs 5 
setblock ~23 ~12 ~32 quartz_stairs 7  
fill ~23 ~12 ~42 ~23 ~12 ~43 quartz_stairs 5 
setblock ~23 ~12 ~44 quartz_stairs 6  
fill ~23 ~12 ~52 ~24 ~12 ~52 quartz_block 0 
setblock ~23 ~12 ~53 stone_slab 7  
fill ~24 ~12 ~21 ~24 ~13 ~21 quartz_block 0  
fill ~24 ~12 ~23 ~26 ~12 ~23 stained_hardened_clay 3  
fill ~24 ~12 ~24 ~24 ~12 ~29 quartz_stairs 5 
setblock ~24 ~12 ~30 quartz_stairs 7  
fill ~24 ~12 ~44 ~24 ~12 ~49 quartz_stairs 5  
fill ~24 ~12 ~50 ~29 ~12 ~50 quartz_stairs 6  
fill ~24 ~12 ~51 ~29 ~12 ~51 stained_hardened_clay 3  
fill ~24 ~12 ~53 ~24 ~13 ~53 quartz_block 0 
setblock ~25 ~12 ~20 stone_slab 7  
fill ~25 ~12 ~22 ~28 ~12 ~22 quartz_stairs 6  
fill ~25 ~12 ~24 ~30 ~12 ~24 quartz_stairs 7  
fill ~25 ~12 ~52 ~28 ~12 ~52 quartz_stairs 7 
setblock ~25 ~12 ~54 stone_slab 7  
fill ~29 ~12 ~21 ~30 ~12 ~21 quartz_stairs 6 
setblock ~29 ~12 ~22 quartz_stairs 4 
setblock ~29 ~12 ~52 quartz_stairs 4  
fill ~29 ~12 ~53 ~30 ~12 ~53 quartz_stairs 7 
setblock ~30 ~12 ~23 quartz_stairs 5 
setblock ~30 ~12 ~50 quartz_stairs 5  
fill ~30 ~12 ~51 ~31 ~12 ~51 quartz_stairs 6  
fill ~30 ~12 ~52 ~31 ~12 ~52 stained_hardened_clay 3 
setblock ~31 ~12 ~20 quartz_stairs 6 
setblock ~31 ~12 ~21 quartz_stairs 4  
fill ~31 ~12 ~23 ~32 ~12 ~23 quartz_stairs 7 
setblock ~31 ~12 ~53 quartz_stairs 4 
setblock ~31 ~12 ~54 quartz_stairs 7 
setblock ~32 ~12 ~18 quartz_stairs 6  
fill ~32 ~12 ~19 ~32 ~12 ~20 quartz_stairs 4 
setblock ~32 ~12 ~22 quartz_stairs 5 
setblock ~32 ~12 ~51 quartz_stairs 5 
setblock ~32 ~12 ~52 quartz_stairs 6  
fill ~32 ~12 ~54 ~32 ~12 ~55 quartz_stairs 4 
setblock ~32 ~12 ~56 quartz_stairs 7  
fill ~33 ~12 ~14 ~33 ~12 ~18 quartz_stairs 4 
setblock ~33 ~12 ~21 quartz_stairs 5 
setblock ~33 ~12 ~22 quartz_stairs 7 
setblock ~33 ~12 ~52 quartz_stairs 5  
fill ~33 ~12 ~53 ~34 ~12 ~53 quartz_stairs 6  
fill ~33 ~12 ~56 ~33 ~12 ~59 quartz_stairs 4  
fill ~33 ~12 ~60 ~35 ~12 ~60 quartz_stairs 7  
fill ~34 ~12 ~14 ~35 ~12 ~14 quartz_stairs 6  
fill ~34 ~12 ~19 ~34 ~12 ~20 quartz_stairs 5 
setblock ~34 ~12 ~21 quartz_stairs 7 
setblock ~34 ~12 ~54 quartz_stairs 5 
setblock ~34 ~12 ~55 quartz_stairs 6  
fill ~35 ~12 ~15 ~35 ~12 ~18 quartz_stairs 5 
setblock ~35 ~12 ~19 quartz_stairs 7  
fill ~35 ~12 ~55 ~35 ~12 ~59 quartz_stairs 5  
fill ~39 ~12 ~14 ~41 ~12 ~14 quartz_stairs 6  
fill ~39 ~12 ~15 ~39 ~12 ~19 quartz_stairs 4 
setblock ~39 ~12 ~55 quartz_stairs 6  
fill ~39 ~12 ~56 ~39 ~12 ~59 quartz_stairs 4  
