fill ~14 ~0 ~41 ~15 ~0 ~41 dirt 0  
fill ~14 ~0 ~42 ~15 ~0 ~42 dirt 0  
fill ~14 ~0 ~46 ~15 ~0 ~46 dirt 0  
fill ~14 ~0 ~47 ~15 ~0 ~47 dirt 0  
fill ~14 ~0 ~48 ~15 ~0 ~48 dirt 0  
fill ~14 ~0 ~54 ~15 ~0 ~54 dirt 0  
fill ~14 ~0 ~55 ~15 ~0 ~55 dirt 0  
fill ~14 ~0 ~56 ~15 ~0 ~56 dirt 0  
fill ~14 ~0 ~60 ~15 ~0 ~60 dirt 0  
fill ~14 ~0 ~61 ~15 ~0 ~61 dirt 0  
fill ~15 ~0 ~40 ~22 ~0 ~40 dirt 0  
fill ~15 ~0 ~43 ~15 ~0 ~48 dirt 0  
fill ~15 ~0 ~49 ~15 ~0 ~53 double_stone_slab 0  
fill ~15 ~0 ~57 ~15 ~0 ~62 dirt 0  
fill ~16 ~0 ~39 ~17 ~0 ~39 dirt 0  
fill ~16 ~0 ~42 ~22 ~0 ~42 double_stone_slab 0  
fill ~16 ~0 ~43 ~17 ~0 ~43 double_stone_slab 0  
fill ~16 ~0 ~44 ~22 ~0 ~44 double_stone_slab 0  
fill ~16 ~0 ~45 ~17 ~0 ~45 double_stone_slab 0  
fill ~16 ~0 ~46 ~22 ~0 ~46 double_stone_slab 0  
fill ~16 ~0 ~47 ~16 ~0 ~42 double_stone_slab 0  
fill ~16 ~0 ~48 ~16 ~0 ~54 stonebrick 0  
fill ~16 ~0 ~55 ~16 ~0 ~60 double_stone_slab 0  
fill ~16 ~0 ~62 ~22 ~0 ~62 dirt 0  
fill ~16 ~0 ~63 ~17 ~0 ~63 dirt 0  
fill ~17 ~0 ~41 ~23 ~0 ~41 dirt 0  
fill ~17 ~0 ~47 ~22 ~0 ~47 stonebrick 0  
fill ~17 ~0 ~48 ~22 ~0 ~48 double_stone_slab 0  
fill ~17 ~0 ~49 ~17 ~0 ~54 double_stone_slab 0  
fill ~17 ~0 ~55 ~22 ~0 ~55 stonebrick 0  
fill ~17 ~0 ~56 ~22 ~0 ~56 double_stone_slab 0  
fill ~17 ~0 ~57 ~17 ~0 ~60 double_stone_slab 0  
fill ~17 ~0 ~61 ~23 ~0 ~61 dirt 0 
setblock ~18 ~0 ~43 stonebrick 0 
setblock ~18 ~0 ~45 stonebrick 0 
setblock ~18 ~0 ~49 stonebrick 0  
fill ~18 ~0 ~50 ~22 ~0 ~50 double_stone_slab 0  
fill ~18 ~0 ~51 ~22 ~0 ~51 double_stone_slab 0  
fill ~18 ~0 ~52 ~22 ~0 ~52 double_stone_slab 0 
setblock ~18 ~0 ~53 stonebrick 0  
fill ~18 ~0 ~54 ~22 ~0 ~54 double_stone_slab 0 
setblock ~18 ~0 ~57 stonebrick 0  
fill ~18 ~0 ~58 ~22 ~0 ~58 double_stone_slab 0 
setblock ~18 ~0 ~59 stonebrick 0  
fill ~18 ~0 ~60 ~22 ~0 ~60 double_stone_slab 0  
fill ~19 ~0 ~43 ~20 ~0 ~43 double_stone_slab 0  
fill ~19 ~0 ~45 ~20 ~0 ~45 double_stone_slab 0  
fill ~19 ~0 ~49 ~20 ~0 ~49 double_stone_slab 0  
fill ~19 ~0 ~53 ~20 ~0 ~53 double_stone_slab 0  
fill ~19 ~0 ~57 ~20 ~0 ~57 double_stone_slab 0  
fill ~19 ~0 ~59 ~20 ~0 ~59 double_stone_slab 0  
fill ~21 ~0 ~19 ~23 ~0 ~19 dirt 0  
fill ~21 ~0 ~20 ~32 ~0 ~20 dirt 0  
fill ~21 ~0 ~39 ~24 ~0 ~39 dirt 0 
setblock ~21 ~0 ~43 stonebrick 0 
setblock ~21 ~0 ~45 stonebrick 0 
setblock ~21 ~0 ~49 stonebrick 0 
setblock ~21 ~0 ~53 stonebrick 0 
setblock ~21 ~0 ~57 stonebrick 0 
setblock ~21 ~0 ~59 stonebrick 0  
fill ~21 ~0 ~63 ~24 ~0 ~63 dirt 0  
fill ~21 ~0 ~82 ~32 ~0 ~82 dirt 0  
fill ~21 ~0 ~83 ~23 ~0 ~83 dirt 0  
fill ~22 ~0 ~21 ~32 ~0 ~21 dirt 0  
fill ~22 ~0 ~22 ~24 ~0 ~22 dirt 0  
fill ~22 ~0 ~26 ~24 ~0 ~26 dirt 0  
fill ~22 ~0 ~27 ~24 ~0 ~27 dirt 0  
fill ~22 ~0 ~28 ~24 ~0 ~28 dirt 0  
fill ~22 ~0 ~32 ~24 ~0 ~32 dirt 0  
fill ~22 ~0 ~33 ~24 ~0 ~33 dirt 0  
fill ~22 ~0 ~34 ~24 ~0 ~34 dirt 0  
fill ~22 ~0 ~38 ~24 ~0 ~38 dirt 0 
setblock ~22 ~0 ~43 double_stone_slab 0 
setblock ~22 ~0 ~45 double_stone_slab 0 
setblock ~22 ~0 ~49 double_stone_slab 0 
setblock ~22 ~0 ~53 double_stone_slab 0 
setblock ~22 ~0 ~57 double_stone_slab 0 
setblock ~22 ~0 ~59 double_stone_slab 0  
fill ~22 ~0 ~64 ~24 ~0 ~64 dirt 0  
fill ~22 ~0 ~68 ~24 ~0 ~68 dirt 0  
fill ~22 ~0 ~69 ~24 ~0 ~69 dirt 0  
fill ~22 ~0 ~70 ~24 ~0 ~70 dirt 0  
fill ~22 ~0 ~74 ~24 ~0 ~74 dirt 0  
fill ~22 ~0 ~75 ~24 ~0 ~75 dirt 0  
fill ~22 ~0 ~76 ~24 ~0 ~76 dirt 0  
fill ~22 ~0 ~80 ~24 ~0 ~80 dirt 0  
fill ~22 ~0 ~81 ~32 ~0 ~81 dirt 0  
fill ~23 ~0 ~23 ~24 ~0 ~23 dirt 0  
fill ~23 ~0 ~24 ~24 ~0 ~24 dirt 0  
fill ~23 ~0 ~25 ~24 ~0 ~25 dirt 0  
fill ~23 ~0 ~29 ~24 ~0 ~29 dirt 0  
fill ~23 ~0 ~30 ~24 ~0 ~30 dirt 0  
fill ~23 ~0 ~31 ~24 ~0 ~31 dirt 0  
fill ~23 ~0 ~35 ~24 ~0 ~35 dirt 0  
fill ~23 ~0 ~36 ~24 ~0 ~36 dirt 0  
fill ~23 ~0 ~37 ~24 ~0 ~37 dirt 0  
fill ~23 ~0 ~42 ~23 ~0 ~46 stonebrick 0 
setblock ~23 ~0 ~47 double_stone_slab 0  
fill ~23 ~0 ~48 ~23 ~0 ~54 stonebrick 0 
setblock ~23 ~0 ~55 double_stone_slab 0  
fill ~23 ~0 ~56 ~23 ~0 ~60 stonebrick 0  
fill ~23 ~0 ~65 ~24 ~0 ~65 dirt 0  
fill ~23 ~0 ~66 ~24 ~0 ~66 dirt 0  
fill ~23 ~0 ~67 ~24 ~0 ~67 dirt 0  
fill ~23 ~0 ~71 ~24 ~0 ~71 dirt 0  
fill ~23 ~0 ~72 ~24 ~0 ~72 dirt 0  
fill ~23 ~0 ~73 ~24 ~0 ~73 dirt 0  
fill ~23 ~0 ~77 ~24 ~0 ~77 dirt 0  
fill ~23 ~0 ~78 ~24 ~0 ~78 dirt 0  
fill ~23 ~0 ~79 ~24 ~0 ~79 dirt 0 
setblock ~24 ~0 ~40 dirt 0  
fill ~24 ~0 ~41 ~24 ~0 ~46 double_stone_slab 0  
fill ~24 ~0 ~47 ~30 ~0 ~47 stonebrick 0  
fill ~24 ~0 ~48 ~30 ~0 ~48 double_stone_slab 0  
fill ~24 ~0 ~49 ~24 ~0 ~54 double_stone_slab 0  
fill ~24 ~0 ~55 ~30 ~0 ~55 stonebrick 0  
fill ~24 ~0 ~56 ~45 ~0 ~56 double_stone_slab 0  
fill ~24 ~0 ~57 ~24 ~0 ~61 double_stone_slab 0 
setblock ~24 ~0 ~62 dirt 0  
fill ~25 ~0 ~22 ~44 ~0 ~22 double_stone_slab 0  
fill ~25 ~0 ~23 ~32 ~0 ~23 double_stone_slab 0  
fill ~25 ~0 ~24 ~44 ~0 ~24 double_stone_slab 0  
fill ~25 ~0 ~25 ~32 ~0 ~25 double_stone_slab 0  
fill ~25 ~0 ~26 ~44 ~0 ~26 double_stone_slab 0  
fill ~25 ~0 ~27 ~31 ~0 ~27 double_stone_slab 0  
fill ~25 ~0 ~28 ~25 ~0 ~32 double_stone_slab 0  
fill ~25 ~0 ~33 ~30 ~0 ~33 stonebrick 0  
fill ~25 ~0 ~34 ~44 ~0 ~34 double_stone_slab 0  
fill ~25 ~0 ~35 ~25 ~0 ~40 double_stone_slab 0 
setblock ~25 ~0 ~41 stonebrick 0  
fill ~25 ~0 ~42 ~30 ~0 ~42 double_stone_slab 0  
fill ~25 ~0 ~43 ~30 ~0 ~43 double_stone_slab 0  
fill ~25 ~0 ~44 ~30 ~0 ~44 double_stone_slab 0 
setblock ~25 ~0 ~45 stonebrick 0  
fill ~25 ~0 ~46 ~45 ~0 ~46 double_stone_slab 0 
setblock ~25 ~0 ~49 stonebrick 0  
fill ~25 ~0 ~50 ~30 ~0 ~50 double_stone_slab 0  
fill ~25 ~0 ~51 ~30 ~0 ~51 double_stone_slab 0  
fill ~25 ~0 ~52 ~30 ~0 ~52 double_stone_slab 0 
setblock ~25 ~0 ~53 stonebrick 0  
fill ~25 ~0 ~54 ~30 ~0 ~54 double_stone_slab 0 
setblock ~25 ~0 ~57 stonebrick 0  
fill ~25 ~0 ~58 ~30 ~0 ~58 double_stone_slab 0  
fill ~25 ~0 ~59 ~30 ~0 ~59 double_stone_slab 0  
fill ~25 ~0 ~60 ~30 ~0 ~60 double_stone_slab 0 
setblock ~25 ~0 ~61 stonebrick 0  
fill ~25 ~0 ~62 ~44 ~0 ~62 double_stone_slab 0  
fill ~25 ~0 ~63 ~25 ~0 ~68 double_stone_slab 0  
fill ~25 ~0 ~69 ~30 ~0 ~69 stonebrick 0  
fill ~25 ~0 ~70 ~44 ~0 ~70 double_stone_slab 0  
fill ~25 ~0 ~71 ~25 ~0 ~80 double_stone_slab 0 
setblock ~26 ~0 ~28 stonebrick 0  
fill ~26 ~0 ~29 ~27 ~0 ~29 double_stone_slab 0  
fill ~26 ~0 ~30 ~30 ~0 ~30 double_stone_slab 0 
setblock ~26 ~0 ~31 stonebrick 0  
fill ~26 ~0 ~32 ~44 ~0 ~32 double_stone_slab 0 
setblock ~26 ~0 ~35 stonebrick 0  
fill ~26 ~0 ~36 ~30 ~0 ~36 double_stone_slab 0 
setblock ~26 ~0 ~37 stonebrick 0  
fill ~26 ~0 ~38 ~44 ~0 ~38 double_stone_slab 0  
fill ~26 ~0 ~39 ~29 ~0 ~39 stonebrick 0  
fill ~26 ~0 ~40 ~44 ~0 ~40 double_stone_slab 0  
fill ~26 ~0 ~41 ~28 ~0 ~41 double_stone_slab 0  
fill ~26 ~0 ~45 ~28 ~0 ~45 double_stone_slab 0  
fill ~26 ~0 ~49 ~28 ~0 ~49 double_stone_slab 0  
fill ~26 ~0 ~53 ~28 ~0 ~53 double_stone_slab 0  
fill ~26 ~0 ~57 ~28 ~0 ~57 double_stone_slab 0  
fill ~26 ~0 ~61 ~28 ~0 ~61 double_stone_slab 0  
fill ~26 ~0 ~63 ~29 ~0 ~63 stonebrick 0  
fill ~26 ~0 ~64 ~35 ~0 ~64 double_stone_slab 0 
setblock ~26 ~0 ~65 stonebrick 0  
fill ~26 ~0 ~66 ~30 ~0 ~66 double_stone_slab 0 
setblock ~26 ~0 ~67 stonebrick 0  
fill ~26 ~0 ~68 ~44 ~0 ~68 double_stone_slab 0 
setblock ~26 ~0 ~71 stonebrick 0  
fill ~26 ~0 ~72 ~30 ~0 ~72 double_stone_slab 0  
fill ~26 ~0 ~73 ~30 ~0 ~73 double_stone_slab 0 
setblock ~26 ~0 ~74 stonebrick 0  
fill ~26 ~0 ~75 ~31 ~0 ~75 double_stone_slab 0  
fill ~26 ~0 ~76 ~44 ~0 ~76 double_stone_slab 0  
fill ~26 ~0 ~77 ~32 ~0 ~77 double_stone_slab 0  
fill ~26 ~0 ~78 ~44 ~0 ~78 double_stone_slab 0  
fill ~26 ~0 ~79 ~32 ~0 ~79 double_stone_slab 0  
fill ~26 ~0 ~80 ~44 ~0 ~80 double_stone_slab 0  
fill ~27 ~0 ~19 ~28 ~0 ~19 dirt 0  
fill ~27 ~0 ~28 ~28 ~0 ~28 double_stone_slab 0  
fill ~27 ~0 ~31 ~28 ~0 ~31 double_stone_slab 0  
fill ~27 ~0 ~35 ~28 ~0 ~35 double_stone_slab 0  
fill ~27 ~0 ~37 ~28 ~0 ~37 double_stone_slab 0  
fill ~27 ~0 ~65 ~28 ~0 ~65 double_stone_slab 0  
fill ~27 ~0 ~67 ~28 ~0 ~67 double_stone_slab 0  
fill ~27 ~0 ~71 ~28 ~0 ~71 double_stone_slab 0  
fill ~27 ~0 ~74 ~28 ~0 ~74 double_stone_slab 0  
fill ~27 ~0 ~83 ~28 ~0 ~83 dirt 0 
setblock ~28 ~0 ~29 stone_slab 8 
setblock ~29 ~0 ~28 stonebrick 0  
fill ~29 ~0 ~29 ~30 ~0 ~29 double_stone_slab 0 
setblock ~29 ~0 ~31 stonebrick 0 
setblock ~29 ~0 ~35 stonebrick 0 
setblock ~29 ~0 ~37 stonebrick 0 
setblock ~29 ~0 ~41 stonebrick 0 
setblock ~29 ~0 ~45 stonebrick 0 
setblock ~29 ~0 ~49 stonebrick 0 
setblock ~29 ~0 ~53 stonebrick 0 
setblock ~29 ~0 ~57 stonebrick 0 
setblock ~29 ~0 ~61 stonebrick 0 
setblock ~29 ~0 ~65 stonebrick 0 
setblock ~29 ~0 ~67 stonebrick 0 
setblock ~29 ~0 ~71 stonebrick 0 
setblock ~29 ~0 ~74 stonebrick 0  
fill ~30 ~0 ~28 ~39 ~0 ~28 double_stone_slab 0 
setblock ~30 ~0 ~31 double_stone_slab 0 
setblock ~30 ~0 ~35 double_stone_slab 0 
setblock ~30 ~0 ~37 double_stone_slab 0  
fill ~30 ~0 ~39 ~31 ~0 ~39 double_stone_slab 0 
setblock ~30 ~0 ~41 double_stone_slab 0 
setblock ~30 ~0 ~45 double_stone_slab 0 
setblock ~30 ~0 ~49 double_stone_slab 0 
setblock ~30 ~0 ~53 double_stone_slab 0 
setblock ~30 ~0 ~57 double_stone_slab 0 
setblock ~30 ~0 ~61 double_stone_slab 0  
fill ~30 ~0 ~63 ~31 ~0 ~63 double_stone_slab 0 
setblock ~30 ~0 ~65 double_stone_slab 0 
setblock ~30 ~0 ~67 double_stone_slab 0 
setblock ~30 ~0 ~71 double_stone_slab 0  
fill ~30 ~0 ~74 ~39 ~0 ~74 double_stone_slab 0 
setblock ~31 ~0 ~19 dirt 0  
fill ~31 ~0 ~29 ~31 ~0 ~31 stonebrick 0 
setblock ~31 ~0 ~33 double_stone_slab 0  
fill ~31 ~0 ~35 ~31 ~0 ~37 stonebrick 0  
fill ~31 ~0 ~41 ~31 ~0 ~45 stonebrick 0 
setblock ~31 ~0 ~47 double_stone_slab 0  
fill ~31 ~0 ~48 ~31 ~0 ~54 stonebrick 0 
setblock ~31 ~0 ~55 double_stone_slab 0  
fill ~31 ~0 ~57 ~31 ~0 ~61 stonebrick 0  
fill ~31 ~0 ~65 ~31 ~0 ~67 stonebrick 0 
setblock ~31 ~0 ~69 double_stone_slab 0  
fill ~31 ~0 ~71 ~31 ~0 ~73 stonebrick 0 
setblock ~31 ~0 ~83 dirt 0  
fill ~32 ~0 ~27 ~37 ~0 ~27 stonebrick 0  
fill ~32 ~0 ~29 ~32 ~0 ~32 double_stone_slab 0  
fill ~32 ~0 ~33 ~37 ~0 ~33 stonebrick 0  
fill ~32 ~0 ~35 ~32 ~0 ~38 double_stone_slab 0  
fill ~32 ~0 ~39 ~37 ~0 ~39 stonebrick 0  
fill ~32 ~0 ~41 ~32 ~0 ~46 double_stone_slab 0  
fill ~32 ~0 ~47 ~37 ~0 ~47 stonebrick 0  
fill ~32 ~0 ~48 ~37 ~0 ~48 double_stone_slab 0  
fill ~32 ~0 ~49 ~32 ~0 ~54 double_stone_slab 0  
fill ~32 ~0 ~55 ~37 ~0 ~55 stonebrick 0  
fill ~32 ~0 ~57 ~32 ~0 ~62 double_stone_slab 0  
fill ~32 ~0 ~63 ~37 ~0 ~63 stonebrick 0  
fill ~32 ~0 ~65 ~32 ~0 ~68 double_stone_slab 0  
fill ~32 ~0 ~69 ~37 ~0 ~69 stonebrick 0  
fill ~32 ~0 ~71 ~32 ~0 ~74 double_stone_slab 0  
fill ~32 ~0 ~75 ~37 ~0 ~75 stonebrick 0  
fill ~33 ~0 ~21 ~36 ~0 ~21 stonebrick 0 
setblock ~33 ~0 ~23 stonebrick 0 
setblock ~33 ~0 ~25 stonebrick 0 
setblock ~33 ~0 ~29 stonebrick 0  
fill ~33 ~0 ~30 ~37 ~0 ~30 double_stone_slab 0 
setblock ~33 ~0 ~31 stonebrick 0 
setblock ~33 ~0 ~35 stonebrick 0  
fill ~33 ~0 ~36 ~37 ~0 ~36 double_stone_slab 0 
setblock ~33 ~0 ~37 stonebrick 0 
setblock ~33 ~0 ~41 stonebrick 0  
fill ~33 ~0 ~42 ~37 ~0 ~42 double_stone_slab 0  
fill ~33 ~0 ~43 ~37 ~0 ~43 double_stone_slab 0  
fill ~33 ~0 ~44 ~37 ~0 ~44 double_stone_slab 0 
setblock ~33 ~0 ~45 stonebrick 0 
setblock ~33 ~0 ~49 stonebrick 0 
setblock ~33 ~0 ~50 double_stone_slab 0  
fill ~33 ~0 ~51 ~36 ~0 ~51 stonebrick 0 
setblock ~33 ~0 ~52 double_stone_slab 0 
setblock ~33 ~0 ~53 stonebrick 0  
fill ~33 ~0 ~54 ~37 ~0 ~54 double_stone_slab 0 
setblock ~33 ~0 ~57 stonebrick 0  
fill ~33 ~0 ~58 ~37 ~0 ~58 double_stone_slab 0  
fill ~33 ~0 ~59 ~37 ~0 ~59 double_stone_slab 0  
fill ~33 ~0 ~60 ~37 ~0 ~60 double_stone_slab 0 
setblock ~33 ~0 ~61 stonebrick 0 
setblock ~33 ~0 ~65 stonebrick 0  
fill ~33 ~0 ~66 ~37 ~0 ~66 double_stone_slab 0 
setblock ~33 ~0 ~67 stonebrick 0 
setblock ~33 ~0 ~71 stonebrick 0  
fill ~33 ~0 ~72 ~37 ~0 ~72 double_stone_slab 0 
setblock ~33 ~0 ~73 stonebrick 0 
setblock ~33 ~0 ~77 stonebrick 0 
setblock ~33 ~0 ~79 stonebrick 0  
fill ~33 ~0 ~81 ~36 ~0 ~81 stonebrick 0  
fill ~34 ~0 ~23 ~35 ~0 ~23 double_stone_slab 0  
fill ~34 ~0 ~25 ~35 ~0 ~25 double_stone_slab 0  
fill ~34 ~0 ~29 ~35 ~0 ~29 double_stone_slab 0  
fill ~34 ~0 ~31 ~35 ~0 ~31 double_stone_slab 0  
fill ~34 ~0 ~35 ~35 ~0 ~35 double_stone_slab 0  
fill ~34 ~0 ~37 ~35 ~0 ~37 double_stone_slab 0  
fill ~34 ~0 ~41 ~35 ~0 ~41 double_stone_slab 0  
fill ~34 ~0 ~45 ~35 ~0 ~45 double_stone_slab 0  
fill ~34 ~0 ~49 ~35 ~0 ~49 double_stone_slab 0  
fill ~34 ~0 ~50 ~35 ~0 ~50 stonebrick 0  
fill ~34 ~0 ~52 ~35 ~0 ~52 stonebrick 0  
fill ~34 ~0 ~53 ~35 ~0 ~53 double_stone_slab 0  
fill ~34 ~0 ~57 ~35 ~0 ~57 double_stone_slab 0  
fill ~34 ~0 ~61 ~35 ~0 ~61 double_stone_slab 0  
fill ~34 ~0 ~65 ~35 ~0 ~65 double_stone_slab 0  
fill ~34 ~0 ~67 ~35 ~0 ~67 double_stone_slab 0  
fill ~34 ~0 ~71 ~35 ~0 ~71 double_stone_slab 0  
fill ~34 ~0 ~73 ~35 ~0 ~73 double_stone_slab 0  
fill ~34 ~0 ~77 ~35 ~0 ~77 double_stone_slab 0  
fill ~34 ~0 ~79 ~35 ~0 ~79 double_stone_slab 0 
setblock ~36 ~0 ~23 stonebrick 0 
setblock ~36 ~0 ~25 stonebrick 0 
setblock ~36 ~0 ~29 stonebrick 0 
setblock ~36 ~0 ~31 stonebrick 0 
setblock ~36 ~0 ~35 stonebrick 0 
setblock ~36 ~0 ~37 stonebrick 0 
setblock ~36 ~0 ~41 stonebrick 0 
setblock ~36 ~0 ~45 stonebrick 0 
setblock ~36 ~0 ~49 stonebrick 0  
fill ~36 ~0 ~50 ~37 ~0 ~50 double_stone_slab 0  
fill ~36 ~0 ~52 ~37 ~0 ~52 double_stone_slab 0 
setblock ~36 ~0 ~53 stonebrick 0 
setblock ~36 ~0 ~57 stonebrick 0 
setblock ~36 ~0 ~61 stonebrick 0 
setblock ~36 ~0 ~64 stone_slab 8 
setblock ~36 ~0 ~65 stonebrick 0 
setblock ~36 ~0 ~67 stonebrick 0 
setblock ~36 ~0 ~71 stonebrick 0 
setblock ~36 ~0 ~73 stonebrick 0 
setblock ~36 ~0 ~77 stonebrick 0 
setblock ~36 ~0 ~79 stonebrick 0  
fill ~37 ~0 ~20 ~48 ~0 ~20 dirt 0  
fill ~37 ~0 ~21 ~47 ~0 ~21 dirt 0  
fill ~37 ~0 ~23 ~44 ~0 ~23 double_stone_slab 0  
fill ~37 ~0 ~25 ~44 ~0 ~25 double_stone_slab 0 
setblock ~37 ~0 ~29 double_stone_slab 0 
setblock ~37 ~0 ~31 double_stone_slab 0 
setblock ~37 ~0 ~35 double_stone_slab 0 
setblock ~37 ~0 ~37 double_stone_slab 0 
setblock ~37 ~0 ~41 double_stone_slab 0 
setblock ~37 ~0 ~45 double_stone_slab 0 
setblock ~37 ~0 ~49 double_stone_slab 0 
setblock ~37 ~0 ~51 double_stone_slab 0 
setblock ~37 ~0 ~53 double_stone_slab 0 
setblock ~37 ~0 ~57 double_stone_slab 0 
setblock ~37 ~0 ~61 double_stone_slab 0  
fill ~37 ~0 ~64 ~44 ~0 ~64 double_stone_slab 0  
fill ~37 ~0 ~65 ~37 ~0 ~64 double_stone_slab 0 
setblock ~37 ~0 ~67 double_stone_slab 0 
setblock ~37 ~0 ~71 double_stone_slab 0 
setblock ~37 ~0 ~73 double_stone_slab 0  
fill ~37 ~0 ~77 ~44 ~0 ~77 double_stone_slab 0  
fill ~37 ~0 ~79 ~44 ~0 ~79 double_stone_slab 0  
fill ~37 ~0 ~81 ~47 ~0 ~81 dirt 0  
fill ~37 ~0 ~82 ~48 ~0 ~82 dirt 0 
setblock ~38 ~0 ~19 dirt 0  
fill ~38 ~0 ~27 ~44 ~0 ~27 double_stone_slab 0  
fill ~38 ~0 ~29 ~38 ~0 ~31 stonebrick 0 
setblock ~38 ~0 ~33 double_stone_slab 0  
fill ~38 ~0 ~35 ~38 ~0 ~37 stonebrick 0  
fill ~38 ~0 ~39 ~39 ~0 ~39 double_stone_slab 0  
fill ~38 ~0 ~41 ~38 ~0 ~45 stonebrick 0 
setblock ~38 ~0 ~47 double_stone_slab 0  
fill ~38 ~0 ~48 ~38 ~0 ~54 stonebrick 0 
setblock ~38 ~0 ~55 double_stone_slab 0  
fill ~38 ~0 ~57 ~38 ~0 ~61 stonebrick 0  
fill ~38 ~0 ~63 ~39 ~0 ~63 double_stone_slab 0  
fill ~38 ~0 ~65 ~38 ~0 ~67 stonebrick 0 
setblock ~38 ~0 ~69 double_stone_slab 0  
fill ~38 ~0 ~71 ~38 ~0 ~73 stonebrick 0  
fill ~38 ~0 ~75 ~44 ~0 ~75 double_stone_slab 0 
setblock ~38 ~0 ~83 dirt 0  
fill ~39 ~0 ~29 ~44 ~0 ~29 double_stone_slab 0  
fill ~39 ~0 ~30 ~44 ~0 ~30 double_stone_slab 0  
fill ~39 ~0 ~31 ~39 ~0 ~22 double_stone_slab 0  
fill ~39 ~0 ~33 ~44 ~0 ~33 stonebrick 0  
fill ~39 ~0 ~35 ~39 ~0 ~46 double_stone_slab 0  
fill ~39 ~0 ~47 ~45 ~0 ~47 stonebrick 0  
fill ~39 ~0 ~48 ~45 ~0 ~48 double_stone_slab 0  
fill ~39 ~0 ~49 ~39 ~0 ~54 double_stone_slab 0  
fill ~39 ~0 ~55 ~45 ~0 ~55 stonebrick 0  
fill ~39 ~0 ~57 ~39 ~0 ~68 double_stone_slab 0  
fill ~39 ~0 ~69 ~44 ~0 ~69 stonebrick 0  
fill ~39 ~0 ~71 ~39 ~0 ~80 double_stone_slab 0 
setblock ~40 ~0 ~28 stonebrick 0 
setblock ~40 ~0 ~31 stonebrick 0 
setblock ~40 ~0 ~35 stonebrick 0  
fill ~40 ~0 ~36 ~44 ~0 ~36 double_stone_slab 0 
setblock ~40 ~0 ~37 stonebrick 0  
fill ~40 ~0 ~39 ~43 ~0 ~39 stonebrick 0 
setblock ~40 ~0 ~41 stonebrick 0  
fill ~40 ~0 ~42 ~45 ~0 ~42 double_stone_slab 0  
fill ~40 ~0 ~43 ~45 ~0 ~43 double_stone_slab 0  
fill ~40 ~0 ~44 ~45 ~0 ~44 double_stone_slab 0 
setblock ~40 ~0 ~45 stonebrick 0 
setblock ~40 ~0 ~49 stonebrick 0  
fill ~40 ~0 ~50 ~45 ~0 ~50 double_stone_slab 0  
fill ~40 ~0 ~51 ~45 ~0 ~51 double_stone_slab 0  
fill ~40 ~0 ~52 ~45 ~0 ~52 double_stone_slab 0 
setblock ~40 ~0 ~53 stonebrick 0  
fill ~40 ~0 ~54 ~45 ~0 ~54 double_stone_slab 0 
setblock ~40 ~0 ~57 stonebrick 0  
fill ~40 ~0 ~58 ~45 ~0 ~58 double_stone_slab 0  
fill ~40 ~0 ~59 ~45 ~0 ~59 double_stone_slab 0  
fill ~40 ~0 ~60 ~45 ~0 ~60 double_stone_slab 0 
setblock ~40 ~0 ~61 stonebrick 0  
fill ~40 ~0 ~63 ~43 ~0 ~63 stonebrick 0 
setblock ~40 ~0 ~65 stonebrick 0  
fill ~40 ~0 ~66 ~44 ~0 ~66 double_stone_slab 0 
setblock ~40 ~0 ~67 stonebrick 0 
setblock ~40 ~0 ~71 stonebrick 0  
fill ~40 ~0 ~72 ~44 ~0 ~72 double_stone_slab 0  
fill ~40 ~0 ~73 ~44 ~0 ~73 double_stone_slab 0 
setblock ~40 ~0 ~74 stonebrick 0  
fill ~41 ~0 ~19 ~42 ~0 ~19 dirt 0  
fill ~41 ~0 ~28 ~42 ~0 ~28 double_stone_slab 0  
fill ~41 ~0 ~31 ~42 ~0 ~31 double_stone_slab 0  
fill ~41 ~0 ~35 ~42 ~0 ~35 double_stone_slab 0  
fill ~41 ~0 ~37 ~42 ~0 ~37 double_stone_slab 0  
fill ~41 ~0 ~41 ~43 ~0 ~41 double_stone_slab 0  
fill ~41 ~0 ~45 ~43 ~0 ~45 double_stone_slab 0  
fill ~41 ~0 ~49 ~43 ~0 ~49 double_stone_slab 0  
fill ~41 ~0 ~53 ~43 ~0 ~53 double_stone_slab 0  
fill ~41 ~0 ~57 ~43 ~0 ~57 double_stone_slab 0  
fill ~41 ~0 ~61 ~43 ~0 ~61 double_stone_slab 0  
fill ~41 ~0 ~65 ~42 ~0 ~65 double_stone_slab 0  
fill ~41 ~0 ~67 ~42 ~0 ~67 double_stone_slab 0  
fill ~41 ~0 ~71 ~42 ~0 ~71 double_stone_slab 0  
fill ~41 ~0 ~74 ~42 ~0 ~74 double_stone_slab 0  
fill ~41 ~0 ~83 ~42 ~0 ~83 dirt 0 
setblock ~43 ~0 ~28 stonebrick 0 
setblock ~43 ~0 ~31 stonebrick 0 
setblock ~43 ~0 ~35 stonebrick 0 
setblock ~43 ~0 ~37 stonebrick 0 
setblock ~43 ~0 ~65 stonebrick 0 
setblock ~43 ~0 ~67 stonebrick 0 
setblock ~43 ~0 ~71 stonebrick 0 
setblock ~43 ~0 ~74 stonebrick 0 
setblock ~44 ~0 ~28 double_stone_slab 0 
setblock ~44 ~0 ~31 double_stone_slab 0 
setblock ~44 ~0 ~35 double_stone_slab 0 
setblock ~44 ~0 ~37 double_stone_slab 0 
setblock ~44 ~0 ~39 double_stone_slab 0 
setblock ~44 ~0 ~41 stonebrick 0 
setblock ~44 ~0 ~45 stonebrick 0 
setblock ~44 ~0 ~49 stonebrick 0 
setblock ~44 ~0 ~53 stonebrick 0 
setblock ~44 ~0 ~57 stonebrick 0 
setblock ~44 ~0 ~61 stonebrick 0 
setblock ~44 ~0 ~63 double_stone_slab 0 
setblock ~44 ~0 ~65 double_stone_slab 0 
setblock ~44 ~0 ~67 double_stone_slab 0 
setblock ~44 ~0 ~71 double_stone_slab 0 
setblock ~44 ~0 ~74 double_stone_slab 0  
fill ~45 ~0 ~22 ~47 ~0 ~22 dirt 0  
fill ~45 ~0 ~23 ~46 ~0 ~23 dirt 0  
fill ~45 ~0 ~24 ~46 ~0 ~24 dirt 0  
fill ~45 ~0 ~25 ~46 ~0 ~25 dirt 0  
fill ~45 ~0 ~26 ~47 ~0 ~26 dirt 0  
fill ~45 ~0 ~27 ~47 ~0 ~27 dirt 0  
fill ~45 ~0 ~28 ~47 ~0 ~28 dirt 0  
fill ~45 ~0 ~29 ~46 ~0 ~29 dirt 0  
fill ~45 ~0 ~30 ~46 ~0 ~30 dirt 0  
fill ~45 ~0 ~31 ~46 ~0 ~31 dirt 0  
fill ~45 ~0 ~32 ~47 ~0 ~32 dirt 0  
fill ~45 ~0 ~33 ~47 ~0 ~33 dirt 0  
fill ~45 ~0 ~34 ~47 ~0 ~34 dirt 0  
fill ~45 ~0 ~35 ~46 ~0 ~35 dirt 0  
fill ~45 ~0 ~36 ~46 ~0 ~36 dirt 0  
fill ~45 ~0 ~37 ~46 ~0 ~37 dirt 0  
fill ~45 ~0 ~38 ~47 ~0 ~38 dirt 0  
fill ~45 ~0 ~39 ~48 ~0 ~39 dirt 0  
fill ~45 ~0 ~40 ~55 ~0 ~40 dirt 0 
setblock ~45 ~0 ~41 double_stone_slab 0 
setblock ~45 ~0 ~45 double_stone_slab 0 
setblock ~45 ~0 ~49 double_stone_slab 0 
setblock ~45 ~0 ~53 double_stone_slab 0 
setblock ~45 ~0 ~57 double_stone_slab 0 
setblock ~45 ~0 ~61 double_stone_slab 0  
fill ~45 ~0 ~62 ~55 ~0 ~62 dirt 0  
fill ~45 ~0 ~63 ~48 ~0 ~63 dirt 0  
fill ~45 ~0 ~64 ~47 ~0 ~64 dirt 0  
fill ~45 ~0 ~65 ~46 ~0 ~65 dirt 0  
fill ~45 ~0 ~66 ~46 ~0 ~66 dirt 0  
fill ~45 ~0 ~67 ~46 ~0 ~67 dirt 0  
fill ~45 ~0 ~68 ~47 ~0 ~68 dirt 0  
fill ~45 ~0 ~69 ~47 ~0 ~69 dirt 0  
fill ~45 ~0 ~70 ~47 ~0 ~70 dirt 0  
fill ~45 ~0 ~71 ~46 ~0 ~71 dirt 0  
fill ~45 ~0 ~72 ~46 ~0 ~72 dirt 0  
fill ~45 ~0 ~73 ~46 ~0 ~73 dirt 0  
fill ~45 ~0 ~74 ~47 ~0 ~74 dirt 0  
fill ~45 ~0 ~75 ~47 ~0 ~75 dirt 0  
fill ~45 ~0 ~76 ~47 ~0 ~76 dirt 0  
fill ~45 ~0 ~77 ~46 ~0 ~77 dirt 0  
fill ~45 ~0 ~78 ~46 ~0 ~78 dirt 0  
fill ~45 ~0 ~79 ~46 ~0 ~79 dirt 0  
fill ~45 ~0 ~80 ~47 ~0 ~80 dirt 0  
fill ~46 ~0 ~19 ~48 ~0 ~19 dirt 0  
fill ~46 ~0 ~41 ~56 ~0 ~41 dirt 0  
fill ~46 ~0 ~42 ~46 ~0 ~46 stonebrick 0 
setblock ~46 ~0 ~47 double_stone_slab 0  
fill ~46 ~0 ~48 ~46 ~0 ~54 stonebrick 0 
setblock ~46 ~0 ~55 double_stone_slab 0  
fill ~46 ~0 ~56 ~46 ~0 ~60 stonebrick 0  
fill ~46 ~0 ~61 ~56 ~0 ~61 dirt 0  
fill ~46 ~0 ~83 ~48 ~0 ~83 dirt 0  
fill ~47 ~0 ~42 ~52 ~0 ~42 double_stone_slab 0  
fill ~47 ~0 ~43 ~47 ~0 ~46 double_stone_slab 0  
fill ~47 ~0 ~47 ~52 ~0 ~47 stonebrick 0  
fill ~47 ~0 ~48 ~52 ~0 ~48 double_stone_slab 0  
fill ~47 ~0 ~49 ~47 ~0 ~54 double_stone_slab 0  
fill ~47 ~0 ~55 ~52 ~0 ~55 stonebrick 0  
fill ~47 ~0 ~56 ~52 ~0 ~56 double_stone_slab 0  
fill ~47 ~0 ~57 ~47 ~0 ~60 double_stone_slab 0 
setblock ~48 ~0 ~43 stonebrick 0  
fill ~48 ~0 ~44 ~52 ~0 ~44 double_stone_slab 0 
setblock ~48 ~0 ~45 stonebrick 0  
fill ~48 ~0 ~46 ~52 ~0 ~46 double_stone_slab 0 
setblock ~48 ~0 ~49 stonebrick 0  
fill ~48 ~0 ~50 ~52 ~0 ~50 double_stone_slab 0  
fill ~48 ~0 ~51 ~52 ~0 ~51 double_stone_slab 0  
fill ~48 ~0 ~52 ~52 ~0 ~52 double_stone_slab 0 
setblock ~48 ~0 ~53 stonebrick 0  
fill ~48 ~0 ~54 ~52 ~0 ~54 double_stone_slab 0 
setblock ~48 ~0 ~57 stonebrick 0  
fill ~48 ~0 ~58 ~52 ~0 ~58 double_stone_slab 0 
setblock ~48 ~0 ~59 stonebrick 0  
fill ~48 ~0 ~60 ~52 ~0 ~60 double_stone_slab 0  
fill ~49 ~0 ~43 ~50 ~0 ~43 double_stone_slab 0  
fill ~49 ~0 ~45 ~50 ~0 ~45 double_stone_slab 0  
fill ~49 ~0 ~49 ~50 ~0 ~49 double_stone_slab 0  
fill ~49 ~0 ~53 ~50 ~0 ~53 double_stone_slab 0  
fill ~49 ~0 ~57 ~50 ~0 ~57 double_stone_slab 0  
fill ~49 ~0 ~59 ~50 ~0 ~59 double_stone_slab 0 
setblock ~51 ~0 ~43 stonebrick 0 
setblock ~51 ~0 ~45 stonebrick 0 
setblock ~51 ~0 ~49 stonebrick 0 
setblock ~51 ~0 ~53 stonebrick 0 
setblock ~51 ~0 ~57 stonebrick 0 
setblock ~51 ~0 ~59 stonebrick 0  
fill ~52 ~0 ~39 ~54 ~0 ~39 dirt 0 
setblock ~52 ~0 ~43 double_stone_slab 0 
setblock ~52 ~0 ~45 double_stone_slab 0 
setblock ~52 ~0 ~49 double_stone_slab 0 
setblock ~52 ~0 ~53 double_stone_slab 0 
setblock ~52 ~0 ~57 double_stone_slab 0 
setblock ~52 ~0 ~59 double_stone_slab 0  
fill ~52 ~0 ~63 ~54 ~0 ~63 dirt 0  
fill ~53 ~0 ~42 ~55 ~0 ~42 dirt 0  
fill ~53 ~0 ~43 ~54 ~0 ~43 dirt 0  
fill ~53 ~0 ~44 ~54 ~0 ~44 dirt 0  
fill ~53 ~0 ~45 ~54 ~0 ~45 dirt 0  
fill ~53 ~0 ~46 ~55 ~0 ~46 dirt 0  
fill ~53 ~0 ~47 ~56 ~0 ~47 dirt 0  
fill ~53 ~0 ~48 ~53 ~0 ~54 stonebrick 0  
fill ~53 ~0 ~55 ~56 ~0 ~55 dirt 0  
fill ~53 ~0 ~56 ~55 ~0 ~56 dirt 0  
fill ~53 ~0 ~57 ~54 ~0 ~57 dirt 0  
fill ~53 ~0 ~58 ~54 ~0 ~58 dirt 0  
fill ~53 ~0 ~59 ~54 ~0 ~59 dirt 0  
fill ~53 ~0 ~60 ~55 ~0 ~60 dirt 0  
fill ~54 ~0 ~48 ~55 ~0 ~48 dirt 0  
fill ~54 ~0 ~49 ~54 ~0 ~53 double_stone_slab 0  
fill ~54 ~0 ~54 ~55 ~0 ~54 dirt 0 
setblock ~13 ~1 ~41 stone_slab 0 
setblock ~13 ~1 ~47 stone_slab 0 
setblock ~13 ~1 ~55 stone_slab 0 
setblock ~13 ~1 ~61 stone_slab 0 
setblock ~14 ~1 ~40 stone_slab 0 
setblock ~14 ~1 ~41 cobblestone 0 
setblock ~14 ~1 ~42 stone_slab 0 
setblock ~14 ~1 ~46 stone_slab 0 
setblock ~14 ~1 ~47 cobblestone 0 
setblock ~14 ~1 ~48 stone_slab 0 
setblock ~14 ~1 ~54 stone_slab 0 
setblock ~14 ~1 ~55 cobblestone 0 
setblock ~14 ~1 ~56 stone_slab 0 
setblock ~14 ~1 ~60 stone_slab 0 
setblock ~14 ~1 ~61 cobblestone 0 
setblock ~14 ~1 ~62 stone_slab 0 
setblock ~15 ~1 ~39 stone_slab 0 
setblock ~15 ~1 ~40 stonebrick 0  
fill ~15 ~1 ~41 ~15 ~13 ~41 log 0  
fill ~15 ~1 ~42 ~16 ~1 ~42 stonebrick 0  
fill ~15 ~1 ~43 ~16 ~1 ~43 stonebrick 0 
setblock ~15 ~1 ~44 stone_brick_stairs 0  
fill ~15 ~1 ~45 ~16 ~1 ~45 stonebrick 0  
fill ~15 ~1 ~46 ~16 ~1 ~46 stonebrick 0  
fill ~15 ~1 ~47 ~16 ~1 ~47 log 0  
fill ~15 ~1 ~48 ~15 ~21 ~48 planks 0  
fill ~15 ~1 ~54 ~15 ~21 ~54 planks 0  
fill ~15 ~1 ~55 ~16 ~1 ~55 log 0  
fill ~15 ~1 ~56 ~16 ~1 ~56 stonebrick 0  
fill ~15 ~1 ~57 ~16 ~1 ~57 stonebrick 0 
setblock ~15 ~1 ~58 stone_brick_stairs 0  
fill ~15 ~1 ~59 ~16 ~1 ~59 stonebrick 0  
fill ~15 ~1 ~60 ~16 ~1 ~60 stonebrick 0  
fill ~15 ~1 ~61 ~15 ~13 ~61 log 0 
setblock ~15 ~1 ~62 stonebrick 0 
setblock ~15 ~1 ~63 stone_slab 0 
setblock ~16 ~1 ~38 stone_slab 0 
setblock ~16 ~1 ~39 cobblestone 0  
fill ~16 ~1 ~40 ~16 ~13 ~40 log 0 
setblock ~16 ~1 ~44 stonebrick 0  
fill ~16 ~1 ~48 ~16 ~10 ~48 fence 0  
fill ~16 ~1 ~54 ~16 ~10 ~54 fence 0 
setblock ~16 ~1 ~58 stonebrick 0  
fill ~16 ~1 ~62 ~16 ~13 ~62 log 0 
setblock ~16 ~1 ~63 cobblestone 0 
setblock ~16 ~1 ~64 stone_slab 0 
setblock ~17 ~1 ~39 stone_slab 0  
fill ~17 ~1 ~40 ~18 ~1 ~40 stonebrick 0  
fill ~17 ~1 ~41 ~23 ~1 ~41 stonebrick 0  
fill ~17 ~1 ~47 ~17 ~7 ~47 fence 0  
fill ~17 ~1 ~55 ~17 ~7 ~55 fence 0  
fill ~17 ~1 ~61 ~23 ~1 ~61 stonebrick 0  
fill ~17 ~1 ~62 ~18 ~1 ~62 stonebrick 0 
setblock ~17 ~1 ~63 stone_slab 0 
setblock ~19 ~1 ~40 stone_brick_stairs 2 
setblock ~19 ~1 ~62 stone_brick_stairs 3 
setblock ~20 ~1 ~20 cobblestone_wall 0  
fill ~20 ~1 ~40 ~21 ~1 ~40 stonebrick 0  
fill ~20 ~1 ~62 ~21 ~1 ~62 stonebrick 0 
setblock ~20 ~1 ~82 cobblestone_wall 0 
setblock ~21 ~1 ~19 stone_slab 0 
setblock ~21 ~1 ~20 cobblestone 0 
setblock ~21 ~1 ~21 cobblestone_wall 0 
setblock ~21 ~1 ~27 cobblestone_wall 0 
setblock ~21 ~1 ~33 cobblestone_wall 0 
setblock ~21 ~1 ~39 stone_slab 0 
setblock ~21 ~1 ~63 stone_slab 0 
setblock ~21 ~1 ~69 cobblestone_wall 0 
setblock ~21 ~1 ~75 cobblestone_wall 0 
setblock ~21 ~1 ~81 cobblestone_wall 0 
setblock ~21 ~1 ~82 cobblestone 0 
setblock ~21 ~1 ~83 stone_slab 0 
setblock ~22 ~1 ~18 cobblestone_wall 0 
setblock ~22 ~1 ~19 cobblestone 0  
fill ~22 ~1 ~20 ~22 ~16 ~20 log 0 
setblock ~22 ~1 ~21 double_stone_slab 3 
setblock ~22 ~1 ~22 stone_slab 0 
setblock ~22 ~1 ~26 stone_slab 0 
setblock ~22 ~1 ~27 double_stone_slab 3 
setblock ~22 ~1 ~28 stone_slab 0 
setblock ~22 ~1 ~32 stone_slab 0 
setblock ~22 ~1 ~33 double_stone_slab 3 
setblock ~22 ~1 ~34 stone_slab 0 
setblock ~22 ~1 ~38 stone_slab 0 
setblock ~22 ~1 ~39 double_stone_slab 3  
fill ~22 ~1 ~40 ~22 ~8 ~40 log 0  
fill ~22 ~1 ~47 ~22 ~7 ~47 fence 0  
fill ~22 ~1 ~55 ~22 ~7 ~55 fence 0  
fill ~22 ~1 ~62 ~22 ~8 ~62 log 0 
setblock ~22 ~1 ~63 double_stone_slab 3 
setblock ~22 ~1 ~64 stone_slab 0 
setblock ~22 ~1 ~68 stone_slab 0 
setblock ~22 ~1 ~69 double_stone_slab 3 
setblock ~22 ~1 ~70 stone_slab 0 
setblock ~22 ~1 ~74 stone_slab 0 
setblock ~22 ~1 ~75 double_stone_slab 3 
setblock ~22 ~1 ~76 stone_slab 0 
setblock ~22 ~1 ~80 stone_slab 0 
setblock ~22 ~1 ~81 double_stone_slab 3  
fill ~22 ~1 ~82 ~22 ~16 ~82 log 0 
setblock ~22 ~1 ~83 cobblestone 0 
setblock ~22 ~1 ~84 cobblestone_wall 0 
setblock ~23 ~1 ~19 stone_slab 0  
fill ~23 ~1 ~20 ~23 ~1 ~23 stonebrick 0 
setblock ~23 ~1 ~24 stone_brick_stairs 0  
fill ~23 ~1 ~25 ~24 ~1 ~25 stonebrick 0  
fill ~23 ~1 ~26 ~24 ~1 ~26 stonebrick 0  
fill ~23 ~1 ~27 ~24 ~1 ~27 log 0  
fill ~23 ~1 ~28 ~24 ~1 ~28 stonebrick 0  
fill ~23 ~1 ~29 ~24 ~1 ~29 stonebrick 0 
setblock ~23 ~1 ~30 stone_brick_stairs 0  
fill ~23 ~1 ~31 ~24 ~1 ~31 stonebrick 0  
fill ~23 ~1 ~32 ~24 ~1 ~32 stonebrick 0  
fill ~23 ~1 ~33 ~24 ~1 ~33 log 0  
fill ~23 ~1 ~34 ~24 ~1 ~34 stonebrick 0  
fill ~23 ~1 ~35 ~24 ~1 ~35 stonebrick 0 
setblock ~23 ~1 ~36 stone_brick_stairs 0  
fill ~23 ~1 ~37 ~24 ~1 ~37 stonebrick 0  
fill ~23 ~1 ~38 ~24 ~1 ~38 stonebrick 0  
fill ~23 ~1 ~39 ~24 ~1 ~39 log 0  
fill ~23 ~1 ~47 ~23 ~27 ~47 log 0  
fill ~23 ~1 ~48 ~23 ~10 ~48 fence 0  
fill ~23 ~1 ~54 ~23 ~10 ~54 fence 0  
fill ~23 ~1 ~55 ~23 ~27 ~55 log 0  
fill ~23 ~1 ~63 ~24 ~1 ~63 log 0  
fill ~23 ~1 ~64 ~24 ~1 ~64 stonebrick 0  
fill ~23 ~1 ~65 ~24 ~1 ~65 stonebrick 0 
setblock ~23 ~1 ~66 stone_brick_stairs 0  
fill ~23 ~1 ~67 ~24 ~1 ~67 stonebrick 0  
fill ~23 ~1 ~68 ~24 ~1 ~68 stonebrick 0  
fill ~23 ~1 ~69 ~24 ~1 ~69 log 0  
fill ~23 ~1 ~70 ~24 ~1 ~70 stonebrick 0  
fill ~23 ~1 ~71 ~24 ~1 ~71 stonebrick 0 
setblock ~23 ~1 ~72 stone_brick_stairs 0  
fill ~23 ~1 ~73 ~24 ~1 ~73 stonebrick 0  
fill ~23 ~1 ~74 ~24 ~1 ~74 stonebrick 0  
fill ~23 ~1 ~75 ~24 ~1 ~75 log 0  
fill ~23 ~1 ~76 ~24 ~1 ~76 stonebrick 0  
fill ~23 ~1 ~77 ~24 ~1 ~77 stonebrick 0 
setblock ~23 ~1 ~78 stone_brick_stairs 0  
fill ~23 ~1 ~79 ~24 ~1 ~79 stonebrick 0  
fill ~23 ~1 ~80 ~26 ~1 ~80 stonebrick 0  
fill ~23 ~1 ~81 ~31 ~1 ~81 stonebrick 0  
fill ~23 ~1 ~82 ~23 ~1 ~79 stonebrick 0 
setblock ~23 ~1 ~83 stone_slab 0  
fill ~24 ~1 ~20 ~26 ~1 ~20 stone_slab 5  
fill ~24 ~1 ~21 ~31 ~1 ~21 stonebrick 0  
fill ~24 ~1 ~22 ~26 ~1 ~22 stonebrick 0  
fill ~24 ~1 ~23 ~24 ~1 ~26 stonebrick 0 
setblock ~24 ~1 ~30 stonebrick 0 
setblock ~24 ~1 ~36 stonebrick 0 
setblock ~24 ~1 ~40 stonebrick 0  
fill ~24 ~1 ~47 ~24 ~7 ~47 fence 0  
fill ~24 ~1 ~55 ~24 ~7 ~55 fence 0 
setblock ~24 ~1 ~62 stonebrick 0 
setblock ~24 ~1 ~66 stonebrick 0 
setblock ~24 ~1 ~72 stonebrick 0 
setblock ~24 ~1 ~78 stonebrick 0  
fill ~24 ~1 ~82 ~26 ~1 ~82 stone_slab 5  
fill ~25 ~1 ~26 ~31 ~1 ~26 planks 0  
fill ~25 ~1 ~27 ~25 ~8 ~27 planks 0  
fill ~25 ~1 ~39 ~25 ~8 ~39 planks 0  
fill ~25 ~1 ~63 ~25 ~8 ~63 planks 0  
fill ~25 ~1 ~75 ~25 ~8 ~75 planks 0  
fill ~25 ~1 ~76 ~31 ~1 ~76 planks 0 
setblock ~27 ~1 ~19 stone_slab 0 
setblock ~27 ~1 ~20 stonebrick 0  
fill ~27 ~1 ~22 ~31 ~1 ~22 planks 0  
fill ~27 ~1 ~80 ~31 ~1 ~80 planks 0 
setblock ~27 ~1 ~82 stonebrick 0 
setblock ~27 ~1 ~83 stone_slab 0 
setblock ~28 ~1 ~18 cobblestone_wall 0 
setblock ~28 ~1 ~19 cobblestone 0  
fill ~28 ~1 ~20 ~28 ~16 ~20 log 0  
fill ~28 ~1 ~82 ~28 ~16 ~82 log 0 
setblock ~28 ~1 ~83 cobblestone 0 
setblock ~28 ~1 ~84 cobblestone_wall 0  
fill ~29 ~1 ~20 ~30 ~1 ~20 stone_slab 0  
fill ~29 ~1 ~23 ~30 ~1 ~23 planks 0  
fill ~29 ~1 ~24 ~30 ~1 ~24 planks 0  
fill ~29 ~1 ~25 ~30 ~1 ~25 planks 0  
fill ~29 ~1 ~77 ~30 ~1 ~77 planks 0  
fill ~29 ~1 ~78 ~30 ~1 ~78 planks 0  
fill ~29 ~1 ~79 ~30 ~1 ~79 planks 0  
fill ~29 ~1 ~82 ~30 ~1 ~82 stone_slab 0  
fill ~30 ~1 ~27 ~30 ~8 ~27 planks 0  
fill ~30 ~1 ~39 ~30 ~8 ~39 planks 0  
fill ~30 ~1 ~47 ~30 ~7 ~47 fence 0  
fill ~30 ~1 ~55 ~30 ~7 ~55 fence 0  
fill ~30 ~1 ~63 ~30 ~8 ~63 planks 0  
fill ~30 ~1 ~75 ~30 ~8 ~75 planks 0 
setblock ~31 ~1 ~18 cobblestone_wall 0 
setblock ~31 ~1 ~19 cobblestone 0  
fill ~31 ~1 ~20 ~31 ~8 ~20 log 0  
fill ~31 ~1 ~23 ~31 ~1 ~25 oak_stairs 1  
fill ~31 ~1 ~27 ~31 ~14 ~27 log 0  
fill ~31 ~1 ~28 ~31 ~8 ~28 planks 0  
fill ~31 ~1 ~32 ~31 ~8 ~32 planks 0  
fill ~31 ~1 ~33 ~31 ~14 ~33 log 0  
fill ~31 ~1 ~34 ~31 ~8 ~34 planks 0  
fill ~31 ~1 ~38 ~31 ~8 ~38 planks 0  
fill ~31 ~1 ~39 ~31 ~20 ~39 log 0  
fill ~31 ~1 ~40 ~31 ~8 ~40 planks 0  
fill ~31 ~1 ~46 ~31 ~8 ~46 planks 0  
fill ~31 ~1 ~47 ~31 ~34 ~47 log 0  
fill ~31 ~1 ~48 ~31 ~10 ~48 fence 0  
fill ~31 ~1 ~54 ~31 ~10 ~54 fence 0  
fill ~31 ~1 ~55 ~31 ~34 ~55 log 0  
fill ~31 ~1 ~56 ~31 ~8 ~56 planks 0  
fill ~31 ~1 ~62 ~31 ~8 ~62 planks 0  
fill ~31 ~1 ~63 ~31 ~20 ~63 log 0  
fill ~31 ~1 ~64 ~31 ~8 ~64 planks 0  
fill ~31 ~1 ~68 ~31 ~8 ~68 planks 0  
fill ~31 ~1 ~69 ~31 ~14 ~69 log 0  
fill ~31 ~1 ~70 ~31 ~8 ~70 planks 0  
fill ~31 ~1 ~74 ~31 ~8 ~74 planks 0  
fill ~31 ~1 ~75 ~31 ~14 ~75 log 0  
fill ~31 ~1 ~77 ~31 ~1 ~79 oak_stairs 1  
fill ~31 ~1 ~82 ~31 ~8 ~82 log 0 
setblock ~31 ~1 ~83 cobblestone 0 
setblock ~31 ~1 ~84 cobblestone_wall 0 
setblock ~32 ~1 ~20 stone_slab 0  
fill ~32 ~1 ~21 ~32 ~8 ~21 log 0  
fill ~32 ~1 ~27 ~32 ~6 ~27 fence 0  
fill ~32 ~1 ~33 ~32 ~6 ~33 fence 0  
fill ~32 ~1 ~39 ~32 ~6 ~39 fence 0  
summon Bat ~9.5243222501 ~3.96256603874 ~70.2140989028 
summon Bat ~25.25 ~2.10000002384 ~23.5358620141 
summon Bat ~25.25 ~2.10000002384 ~25.75 
summon Bat ~25.25 ~2.10000002384 ~23.4863352812 
summon Bat ~36.6608709307 ~7.10000002384 ~60.5154377549 
summon Bat ~29.5489137592 ~19.1000000238 ~64.75 
summon Bat ~28.3232004462 ~2.10000002384 ~77.25 
summon Bat ~38.5005288008 ~1.0 ~94.6704248023 
summon Bat ~39.25 ~7.10000002384 ~28.4163572195 
summon Bat ~44.25 ~2.10000002384 ~26.75 
summon Bat ~42.25 ~2.10000002384 ~25.75 
summon Bat ~41.75 ~20.1000000238 ~39.4422786205 
summon Bat ~53.75 ~5.51076988487 ~41.75 
summon Bat ~45.3432389703 ~7.10000002384 ~57.4140739608 
summon Bat ~40.1200134575 ~7.10000002384 ~62.363250074 
summon Bat ~53.25 ~12.0921343377 ~61.75  
fill ~32 ~1 ~47 ~32 ~23 ~47 fence 0  
fill ~32 ~1 ~55 ~32 ~23 ~55 fence 0  
fill ~32 ~1 ~63 ~32 ~6 ~63 fence 0  
fill ~32 ~1 ~69 ~32 ~6 ~69 fence 0  
fill ~32 ~1 ~75 ~32 ~6 ~75 fence 0  
fill ~32 ~1 ~81 ~32 ~8 ~81 log 0 
setblock ~32 ~1 ~82 stone_slab 0 
setblock ~37 ~1 ~20 stone_slab 0  
fill ~37 ~1 ~21 ~37 ~8 ~21 log 0  
fill ~37 ~1 ~27 ~37 ~6 ~27 fence 0  
fill ~37 ~1 ~33 ~37 ~6 ~33 fence 0  
fill ~37 ~1 ~39 ~37 ~6 ~39 fence 0  
fill ~37 ~1 ~47 ~37 ~23 ~47 fence 0  
fill ~37 ~1 ~55 ~37 ~23 ~55 fence 0  
fill ~37 ~1 ~63 ~37 ~6 ~63 fence 0  
fill ~37 ~1 ~69 ~37 ~6 ~69 fence 0  
fill ~37 ~1 ~75 ~37 ~6 ~75 fence 0  
fill ~37 ~1 ~81 ~37 ~8 ~81 log 0 
setblock ~37 ~1 ~82 stone_slab 0 
setblock ~38 ~1 ~18 cobblestone_wall 0 
setblock ~38 ~1 ~19 cobblestone 0  
fill ~38 ~1 ~20 ~38 ~8 ~20 log 0  
fill ~38 ~1 ~21 ~46 ~1 ~21 stonebrick 0  
fill ~38 ~1 ~22 ~38 ~8 ~22 planks 0  
fill ~38 ~1 ~23 ~41 ~1 ~23 oak_stairs 0  
fill ~38 ~1 ~24 ~41 ~1 ~24 oak_stairs 0  
fill ~38 ~1 ~25 ~42 ~1 ~25 oak_stairs 0  
fill ~38 ~1 ~26 ~38 ~8 ~26 planks 0  
fill ~38 ~1 ~27 ~38 ~14 ~27 log 0  
fill ~38 ~1 ~28 ~38 ~8 ~28 planks 0  
fill ~38 ~1 ~32 ~38 ~8 ~32 planks 0  
fill ~38 ~1 ~33 ~38 ~14 ~33 log 0  
fill ~38 ~1 ~34 ~38 ~8 ~34 planks 0  
fill ~38 ~1 ~38 ~38 ~8 ~38 planks 0  
fill ~38 ~1 ~39 ~38 ~20 ~39 log 0  
fill ~38 ~1 ~40 ~38 ~8 ~40 planks 0  
fill ~38 ~1 ~46 ~38 ~8 ~46 planks 0  
fill ~38 ~1 ~47 ~38 ~34 ~47 log 0  
fill ~38 ~1 ~48 ~38 ~10 ~48 fence 0  
fill ~38 ~1 ~54 ~38 ~10 ~54 fence 0  
fill ~38 ~1 ~55 ~38 ~34 ~55 log 0  
fill ~38 ~1 ~56 ~38 ~8 ~56 planks 0  
fill ~38 ~1 ~62 ~38 ~8 ~62 planks 0  
fill ~38 ~1 ~63 ~38 ~20 ~63 log 0  
fill ~38 ~1 ~64 ~38 ~8 ~64 planks 0  
fill ~38 ~1 ~68 ~38 ~8 ~68 planks 0  
fill ~38 ~1 ~69 ~38 ~14 ~69 log 0  
fill ~38 ~1 ~70 ~38 ~8 ~70 planks 0  
fill ~38 ~1 ~74 ~38 ~8 ~74 planks 0  
fill ~38 ~1 ~75 ~38 ~14 ~75 log 0  
fill ~38 ~1 ~76 ~38 ~8 ~76 planks 0  
fill ~38 ~1 ~77 ~42 ~1 ~77 oak_stairs 0  
fill ~38 ~1 ~78 ~41 ~1 ~78 oak_stairs 0  
fill ~38 ~1 ~79 ~41 ~1 ~79 oak_stairs 0  
fill ~38 ~1 ~80 ~38 ~8 ~80 planks 0  
fill ~38 ~1 ~81 ~46 ~1 ~81 stonebrick 0  
fill ~38 ~1 ~82 ~38 ~8 ~82 log 0 
setblock ~38 ~1 ~83 cobblestone 0 
setblock ~38 ~1 ~84 cobblestone_wall 0  
fill ~39 ~1 ~20 ~40 ~1 ~20 stone_slab 0  
fill ~39 ~1 ~27 ~39 ~5 ~27 planks 0  
fill ~39 ~1 ~39 ~39 ~8 ~39 planks 0  
fill ~39 ~1 ~47 ~39 ~7 ~47 fence 0  
fill ~39 ~1 ~55 ~39 ~7 ~55 fence 0  
fill ~39 ~1 ~63 ~39 ~8 ~63 planks 0  
fill ~39 ~1 ~75 ~39 ~5 ~75 planks 0  
fill ~39 ~1 ~82 ~40 ~1 ~82 stone_slab 0  
fill ~40 ~1 ~26 ~44 ~1 ~26 planks 0  
fill ~40 ~1 ~76 ~44 ~1 ~76 planks 0 
setblock ~41 ~1 ~18 cobblestone_wall 0 
setblock ~41 ~1 ~19 cobblestone 0  
fill ~41 ~1 ~20 ~41 ~16 ~20 log 0  
fill ~41 ~1 ~82 ~41 ~16 ~82 log 0 
setblock ~41 ~1 ~83 cobblestone 0 
setblock ~41 ~1 ~84 cobblestone_wall 0 
setblock ~42 ~1 ~19 stone_slab 0 
setblock ~42 ~1 ~20 stonebrick 0 
setblock ~42 ~1 ~82 stonebrick 0 
setblock ~42 ~1 ~83 stone_slab 0  
fill ~43 ~1 ~20 ~45 ~1 ~20 stone_slab 5  
fill ~43 ~1 ~22 ~46 ~1 ~22 stonebrick 0  
fill ~43 ~1 ~80 ~46 ~1 ~80 stonebrick 0  
fill ~43 ~1 ~82 ~45 ~1 ~82 stone_slab 5  
fill ~44 ~1 ~27 ~44 ~8 ~27 planks 0  
fill ~44 ~1 ~39 ~44 ~8 ~39 planks 0  
fill ~44 ~1 ~63 ~44 ~8 ~63 planks 0  
fill ~44 ~1 ~75 ~44 ~8 ~75 planks 0  
fill ~45 ~1 ~23 ~46 ~1 ~23 stonebrick 0  
fill ~45 ~1 ~24 ~45 ~1 ~26 stonebrick 0  
fill ~45 ~1 ~27 ~46 ~1 ~27 log 0  
fill ~45 ~1 ~28 ~46 ~1 ~28 stonebrick 0  
fill ~45 ~1 ~29 ~46 ~1 ~29 stonebrick 0  
fill ~45 ~1 ~30 ~45 ~1 ~32 stonebrick 0  
fill ~45 ~1 ~33 ~46 ~1 ~33 log 0  
fill ~45 ~1 ~34 ~46 ~1 ~34 stonebrick 0  
fill ~45 ~1 ~35 ~46 ~1 ~35 stonebrick 0  
fill ~45 ~1 ~36 ~45 ~1 ~38 stonebrick 0  
fill ~45 ~1 ~39 ~46 ~1 ~39 log 0 
setblock ~45 ~1 ~40 stonebrick 0  
fill ~45 ~1 ~47 ~45 ~7 ~47 fence 0  
fill ~45 ~1 ~55 ~45 ~7 ~55 fence 0 
setblock ~45 ~1 ~62 stonebrick 0  
fill ~45 ~1 ~63 ~46 ~1 ~63 log 0  
fill ~45 ~1 ~64 ~46 ~1 ~64 stonebrick 0  
fill ~45 ~1 ~65 ~46 ~1 ~65 stonebrick 0  
fill ~45 ~1 ~66 ~45 ~1 ~68 stonebrick 0  
fill ~45 ~1 ~69 ~46 ~1 ~69 log 0  
fill ~45 ~1 ~70 ~46 ~1 ~70 stonebrick 0  
fill ~45 ~1 ~71 ~46 ~1 ~71 stonebrick 0  
fill ~45 ~1 ~72 ~45 ~1 ~74 stonebrick 0  
fill ~45 ~1 ~75 ~46 ~1 ~75 log 0  
fill ~45 ~1 ~76 ~46 ~1 ~76 stonebrick 0  
fill ~45 ~1 ~77 ~46 ~1 ~77 stonebrick 0  
fill ~45 ~1 ~78 ~45 ~1 ~81 stonebrick 0 
setblock ~46 ~1 ~19 stone_slab 0 
setblock ~46 ~1 ~20 stonebrick 0 
setblock ~46 ~1 ~24 stone_brick_stairs 1  
fill ~46 ~1 ~25 ~46 ~1 ~26 stonebrick 0 
setblock ~46 ~1 ~30 stone_brick_stairs 1  
fill ~46 ~1 ~31 ~46 ~1 ~32 stonebrick 0 
setblock ~46 ~1 ~36 stone_brick_stairs 1  
fill ~46 ~1 ~37 ~46 ~1 ~38 stonebrick 0  
fill ~46 ~1 ~41 ~52 ~1 ~41 stonebrick 0  
fill ~46 ~1 ~47 ~46 ~32 ~47 log 0  
fill ~46 ~1 ~48 ~46 ~10 ~48 fence 0  
fill ~46 ~1 ~54 ~46 ~10 ~54 fence 0  
fill ~46 ~1 ~55 ~46 ~32 ~55 log 0  
fill ~46 ~1 ~61 ~52 ~1 ~61 stonebrick 0 
setblock ~46 ~1 ~66 stone_brick_stairs 1  
fill ~46 ~1 ~67 ~46 ~1 ~68 stonebrick 0 
setblock ~46 ~1 ~72 stone_brick_stairs 1  
fill ~46 ~1 ~73 ~46 ~1 ~74 stonebrick 0 
setblock ~46 ~1 ~78 stone_brick_stairs 1 
setblock ~46 ~1 ~79 stonebrick 0 
setblock ~46 ~1 ~82 stonebrick 0 
setblock ~46 ~1 ~83 stone_slab 0 
setblock ~47 ~1 ~18 cobblestone_wall 0 
setblock ~47 ~1 ~19 cobblestone 0  
fill ~47 ~1 ~20 ~47 ~16 ~20 log 0 
setblock ~47 ~1 ~21 double_stone_slab 3 
setblock ~47 ~1 ~22 stone_slab 0 
setblock ~47 ~1 ~26 stone_slab 0 
setblock ~47 ~1 ~27 double_stone_slab 3 
setblock ~47 ~1 ~28 stone_slab 0 
setblock ~47 ~1 ~32 stone_slab 0 
setblock ~47 ~1 ~33 double_stone_slab 3 
setblock ~47 ~1 ~34 stone_slab 0 
setblock ~47 ~1 ~38 stone_slab 0 
setblock ~47 ~1 ~39 double_stone_slab 3  
fill ~47 ~1 ~40 ~47 ~8 ~40 log 0  
fill ~47 ~1 ~47 ~47 ~7 ~47 fence 0  
fill ~47 ~1 ~55 ~47 ~7 ~55 fence 0  
fill ~47 ~1 ~62 ~47 ~8 ~62 log 0 
setblock ~47 ~1 ~63 double_stone_slab 3 
setblock ~47 ~1 ~64 stone_slab 0 
setblock ~47 ~1 ~68 stone_slab 0 
setblock ~47 ~1 ~69 double_stone_slab 3 
setblock ~47 ~1 ~70 stone_slab 0 
setblock ~47 ~1 ~74 stone_slab 0 
setblock ~47 ~1 ~75 double_stone_slab 3 
setblock ~47 ~1 ~76 stone_slab 0 
setblock ~47 ~1 ~80 stone_slab 0 
setblock ~47 ~1 ~81 double_stone_slab 3  
fill ~47 ~1 ~82 ~47 ~16 ~82 log 0 
setblock ~47 ~1 ~83 cobblestone 0 
setblock ~47 ~1 ~84 cobblestone_wall 0 
setblock ~48 ~1 ~19 stone_slab 0 
setblock ~48 ~1 ~20 cobblestone 0 
setblock ~48 ~1 ~21 cobblestone_wall 0 
setblock ~48 ~1 ~27 cobblestone_wall 0 
setblock ~48 ~1 ~33 cobblestone_wall 0 
setblock ~48 ~1 ~39 stone_slab 0  
fill ~48 ~1 ~40 ~49 ~1 ~40 stonebrick 0  
fill ~48 ~1 ~62 ~49 ~1 ~62 stonebrick 0 
setblock ~48 ~1 ~63 stone_slab 0 
setblock ~48 ~1 ~69 cobblestone_wall 0 
setblock ~48 ~1 ~75 cobblestone_wall 0 
setblock ~48 ~1 ~81 cobblestone_wall 0 
setblock ~48 ~1 ~82 cobblestone 0 
setblock ~48 ~1 ~83 stone_slab 0 
setblock ~49 ~1 ~20 cobblestone_wall 0 
setblock ~49 ~1 ~82 cobblestone_wall 0 
setblock ~50 ~1 ~40 stone_brick_stairs 2 
setblock ~50 ~1 ~62 stone_brick_stairs 3  
fill ~51 ~1 ~40 ~52 ~1 ~40 stonebrick 0  
fill ~51 ~1 ~62 ~52 ~1 ~62 stonebrick 0 
setblock ~52 ~1 ~39 stone_slab 0  
fill ~52 ~1 ~47 ~52 ~7 ~47 fence 0  
fill ~52 ~1 ~55 ~52 ~7 ~55 fence 0 
setblock ~52 ~1 ~63 stone_slab 0 
setblock ~53 ~1 ~38 stone_slab 0 
setblock ~53 ~1 ~39 cobblestone 0  
fill ~53 ~1 ~40 ~53 ~13 ~40 log 0  
fill ~53 ~1 ~42 ~54 ~1 ~42 stonebrick 0  
fill ~53 ~1 ~43 ~54 ~1 ~43 stonebrick 0  
fill ~53 ~1 ~44 ~53 ~1 ~46 stonebrick 0  
fill ~53 ~1 ~47 ~54 ~1 ~47 log 0  
fill ~53 ~1 ~48 ~53 ~10 ~48 fence 0  
fill ~53 ~1 ~54 ~53 ~10 ~54 fence 0  
fill ~53 ~1 ~55 ~54 ~1 ~55 log 0  
fill ~53 ~1 ~56 ~54 ~1 ~56 stonebrick 0  
fill ~53 ~1 ~57 ~54 ~1 ~57 stonebrick 0  
fill ~53 ~1 ~58 ~53 ~1 ~60 stonebrick 0  
fill ~53 ~1 ~62 ~53 ~13 ~62 log 0 
setblock ~53 ~1 ~63 cobblestone 0 
setblock ~53 ~1 ~64 stone_slab 0 
setblock ~54 ~1 ~39 stone_slab 0 
setblock ~54 ~1 ~40 stonebrick 0  
fill ~54 ~1 ~41 ~54 ~13 ~41 log 0 
setblock ~54 ~1 ~44 stone_brick_stairs 1  
fill ~54 ~1 ~45 ~54 ~1 ~46 stonebrick 0  
fill ~54 ~1 ~48 ~54 ~21 ~48 planks 0  
fill ~54 ~1 ~54 ~54 ~21 ~54 planks 0 
setblock ~54 ~1 ~58 stone_brick_stairs 1  
fill ~54 ~1 ~59 ~54 ~1 ~60 stonebrick 0  
fill ~54 ~1 ~61 ~54 ~13 ~61 log 0 
setblock ~54 ~1 ~62 stonebrick 0 
setblock ~54 ~1 ~63 stone_slab 0 
setblock ~55 ~1 ~40 stone_slab 0 
setblock ~55 ~1 ~41 cobblestone 0 
setblock ~55 ~1 ~42 stone_slab 0 
setblock ~55 ~1 ~46 stone_slab 0 
setblock ~55 ~1 ~47 cobblestone 0 
setblock ~55 ~1 ~48 stone_slab 0 
setblock ~55 ~1 ~54 stone_slab 0 
setblock ~55 ~1 ~55 cobblestone 0 
setblock ~55 ~1 ~56 stone_slab 0 
setblock ~55 ~1 ~60 stone_slab 0 
setblock ~55 ~1 ~61 cobblestone 0 
setblock ~55 ~1 ~62 stone_slab 0 
setblock ~56 ~1 ~41 stone_slab 0 
setblock ~56 ~1 ~47 stone_slab 0 
setblock ~56 ~1 ~55 stone_slab 0 
setblock ~56 ~1 ~61 stone_slab 0  
fill ~14 ~2 ~41 ~14 ~5 ~41 cobblestone_wall 0  
fill ~14 ~2 ~47 ~14 ~5 ~47 cobblestone_wall 0  
fill ~14 ~2 ~55 ~14 ~5 ~55 cobblestone_wall 0  
fill ~14 ~2 ~61 ~14 ~5 ~61 cobblestone_wall 0  
fill ~15 ~2 ~42 ~15 ~1 ~42 stonebrick 0  
fill ~15 ~2 ~46 ~15 ~1 ~46 stonebrick 0  
fill ~15 ~2 ~47 ~16 ~2 ~47 log 0  
fill ~15 ~2 ~55 ~16 ~2 ~55 log 0  
fill ~15 ~2 ~56 ~15 ~1 ~56 stonebrick 0  
fill ~15 ~2 ~60 ~15 ~1 ~60 stonebrick 0  
fill ~16 ~2 ~39 ~16 ~5 ~39 cobblestone_wall 0  
fill ~16 ~2 ~42 ~16 ~14 ~42 planks 0  
fill ~16 ~2 ~43 ~16 ~2 ~46 planks 0  
fill ~16 ~2 ~56 ~16 ~14 ~56 planks 0  
fill ~16 ~2 ~57 ~16 ~2 ~60 planks 0  
fill ~16 ~2 ~63 ~16 ~5 ~63 cobblestone_wall 0  
fill ~17 ~2 ~40 ~17 ~1 ~40 stonebrick 0  
fill ~17 ~2 ~41 ~23 ~2 ~41 planks 0  
fill ~17 ~2 ~61 ~23 ~2 ~61 planks 0  
fill ~17 ~2 ~62 ~17 ~1 ~62 stonebrick 0  
fill ~21 ~2 ~20 ~21 ~5 ~20 cobblestone_wall 0 
setblock ~21 ~2 ~40 stonebrick 0 
setblock ~21 ~2 ~62 stonebrick 0  
fill ~21 ~2 ~82 ~21 ~5 ~82 cobblestone_wall 0  
fill ~22 ~2 ~19 ~22 ~5 ~19 cobblestone_wall 0  
fill ~22 ~2 ~21 ~22 ~5 ~21 cobblestone_wall 0  
fill ~22 ~2 ~27 ~22 ~5 ~27 cobblestone_wall 0  
fill ~22 ~2 ~33 ~22 ~5 ~33 cobblestone_wall 0  
fill ~22 ~2 ~39 ~22 ~5 ~39 cobblestone_wall 0  
fill ~22 ~2 ~63 ~22 ~5 ~63 cobblestone_wall 0  
fill ~22 ~2 ~69 ~22 ~5 ~69 cobblestone_wall 0  
fill ~22 ~2 ~75 ~22 ~5 ~75 cobblestone_wall 0  
fill ~22 ~2 ~81 ~22 ~5 ~81 cobblestone_wall 0  
fill ~22 ~2 ~83 ~22 ~5 ~83 cobblestone_wall 0  
fill ~23 ~2 ~20 ~23 ~8 ~20 fence 0  
fill ~23 ~2 ~21 ~23 ~18 ~21 planks 0 
setblock ~23 ~2 ~22 stonebrick 0 
setblock ~23 ~2 ~26 double_stone_slab 5  
fill ~23 ~2 ~27 ~24 ~2 ~27 log 0 
setblock ~23 ~2 ~28 double_stone_slab 5 
setblock ~23 ~2 ~32 double_stone_slab 5  
fill ~23 ~2 ~33 ~24 ~2 ~33 log 0 
setblock ~23 ~2 ~34 double_stone_slab 5 
setblock ~23 ~2 ~38 double_stone_slab 5  
fill ~23 ~2 ~39 ~24 ~2 ~39 log 0  
fill ~23 ~2 ~63 ~24 ~2 ~63 log 0 
setblock ~23 ~2 ~64 double_stone_slab 5 
setblock ~23 ~2 ~68 double_stone_slab 5  
fill ~23 ~2 ~69 ~24 ~2 ~69 log 0 
setblock ~23 ~2 ~70 double_stone_slab 5 
setblock ~23 ~2 ~74 double_stone_slab 5  
fill ~23 ~2 ~75 ~24 ~2 ~75 log 0 
setblock ~23 ~2 ~76 double_stone_slab 5 
setblock ~23 ~2 ~80 stonebrick 0  
fill ~23 ~2 ~81 ~23 ~18 ~81 planks 0  
fill ~23 ~2 ~82 ~23 ~8 ~82 fence 0  
fill ~24 ~2 ~22 ~31 ~2 ~22 planks 0  
fill ~24 ~2 ~23 ~24 ~2 ~26 planks 0  
fill ~24 ~2 ~28 ~24 ~8 ~28 planks 0  
fill ~24 ~2 ~29 ~24 ~2 ~32 planks 0  
fill ~24 ~2 ~34 ~24 ~8 ~34 planks 0  
fill ~24 ~2 ~35 ~24 ~2 ~38 planks 0  
fill ~24 ~2 ~40 ~24 ~8 ~40 planks 0  
fill ~24 ~2 ~62 ~24 ~8 ~62 planks 0  
fill ~24 ~2 ~64 ~24 ~8 ~64 planks 0  
fill ~24 ~2 ~65 ~24 ~2 ~68 planks 0  
fill ~24 ~2 ~70 ~24 ~8 ~70 planks 0  
fill ~24 ~2 ~71 ~24 ~2 ~74 planks 0  
fill ~24 ~2 ~76 ~31 ~2 ~76 planks 0  
fill ~24 ~2 ~77 ~24 ~2 ~80 planks 0  
fill ~25 ~2 ~21 ~25 ~8 ~21 fence 0  
fill ~25 ~2 ~26 ~31 ~2 ~26 planks 0  
fill ~25 ~2 ~80 ~31 ~2 ~80 planks 0  
fill ~25 ~2 ~81 ~25 ~8 ~81 fence 0  
fill ~27 ~2 ~20 ~27 ~8 ~20 fence 0  
fill ~27 ~2 ~21 ~31 ~2 ~21 planks 0  
fill ~27 ~2 ~81 ~31 ~2 ~81 planks 0  
fill ~27 ~2 ~82 ~27 ~8 ~82 fence 0  
fill ~28 ~2 ~19 ~28 ~5 ~19 cobblestone_wall 0  
fill ~28 ~2 ~83 ~28 ~5 ~83 cobblestone_wall 0  
fill ~29 ~2 ~23 ~29 ~1 ~23 planks 0  
fill ~29 ~2 ~24 ~29 ~1 ~24 planks 0  
fill ~29 ~2 ~25 ~29 ~1 ~25 planks 0  
fill ~29 ~2 ~77 ~29 ~1 ~77 planks 0  
fill ~29 ~2 ~78 ~29 ~1 ~78 planks 0  
fill ~29 ~2 ~79 ~29 ~1 ~79 planks 0  
fill ~30 ~2 ~23 ~30 ~2 ~25 oak_stairs 1  
fill ~30 ~2 ~77 ~30 ~2 ~79 oak_stairs 1  
fill ~31 ~2 ~19 ~31 ~7 ~19 cobblestone_wall 0  
fill ~31 ~2 ~83 ~31 ~7 ~83 cobblestone_wall 0  
fill ~38 ~2 ~19 ~38 ~7 ~19 cobblestone_wall 0  
fill ~38 ~2 ~21 ~42 ~2 ~21 planks 0  
fill ~38 ~2 ~81 ~42 ~2 ~81 planks 0  
fill ~38 ~2 ~83 ~38 ~7 ~83 cobblestone_wall 0  
fill ~39 ~2 ~22 ~40 ~2 ~22 planks 0  
fill ~39 ~2 ~23 ~41 ~2 ~23 oak_stairs 0  
fill ~39 ~2 ~24 ~41 ~2 ~24 oak_stairs 0  
fill ~39 ~2 ~25 ~41 ~2 ~25 oak_stairs 0  
fill ~39 ~2 ~26 ~43 ~2 ~26 planks 0  
fill ~39 ~2 ~76 ~43 ~2 ~76 planks 0  
fill ~39 ~2 ~77 ~41 ~2 ~77 oak_stairs 0  
fill ~39 ~2 ~78 ~41 ~2 ~78 oak_stairs 0  
fill ~39 ~2 ~79 ~41 ~2 ~79 oak_stairs 0  
fill ~39 ~2 ~80 ~40 ~2 ~80 planks 0  
fill ~41 ~2 ~19 ~41 ~5 ~19 cobblestone_wall 0  
fill ~41 ~2 ~83 ~41 ~5 ~83 cobblestone_wall 0  
fill ~42 ~2 ~20 ~42 ~8 ~20 fence 0  
fill ~42 ~2 ~82 ~42 ~8 ~82 fence 0  
fill ~43 ~2 ~22 ~45 ~2 ~22 planks 0  
fill ~43 ~2 ~80 ~45 ~2 ~80 planks 0  
fill ~44 ~2 ~21 ~44 ~8 ~21 fence 0  
fill ~44 ~2 ~81 ~44 ~8 ~81 fence 0  
fill ~45 ~2 ~23 ~45 ~2 ~26 planks 0  
fill ~45 ~2 ~27 ~46 ~2 ~27 log 0  
fill ~45 ~2 ~28 ~45 ~8 ~28 planks 0  
fill ~45 ~2 ~29 ~45 ~2 ~32 planks 0  
fill ~45 ~2 ~33 ~46 ~2 ~33 log 0  
fill ~45 ~2 ~34 ~45 ~8 ~34 planks 0  
fill ~45 ~2 ~35 ~45 ~2 ~38 planks 0  
fill ~45 ~2 ~39 ~46 ~2 ~39 log 0  
fill ~45 ~2 ~40 ~45 ~8 ~40 planks 0  
fill ~45 ~2 ~62 ~45 ~8 ~62 planks 0  
fill ~45 ~2 ~63 ~46 ~2 ~63 log 0  
fill ~45 ~2 ~64 ~45 ~8 ~64 planks 0  
fill ~45 ~2 ~65 ~45 ~2 ~68 planks 0  
fill ~45 ~2 ~69 ~46 ~2 ~69 log 0  
fill ~45 ~2 ~70 ~45 ~8 ~70 planks 0  
fill ~45 ~2 ~71 ~45 ~2 ~74 planks 0  
fill ~45 ~2 ~75 ~46 ~2 ~75 log 0  
fill ~45 ~2 ~76 ~45 ~8 ~76 planks 0  
fill ~45 ~2 ~77 ~45 ~2 ~80 planks 0  
fill ~46 ~2 ~20 ~46 ~8 ~20 fence 0  
fill ~46 ~2 ~21 ~46 ~16 ~21 planks 0 
setblock ~46 ~2 ~22 stonebrick 0 
setblock ~46 ~2 ~26 double_stone_slab 5 
setblock ~46 ~2 ~28 double_stone_slab 5 
setblock ~46 ~2 ~32 double_stone_slab 5 
setblock ~46 ~2 ~34 double_stone_slab 5 
setblock ~46 ~2 ~38 double_stone_slab 5  
fill ~46 ~2 ~41 ~52 ~2 ~41 planks 0  
fill ~46 ~2 ~61 ~52 ~2 ~61 planks 0 
setblock ~46 ~2 ~64 double_stone_slab 5 
setblock ~46 ~2 ~68 double_stone_slab 5 
setblock ~46 ~2 ~70 double_stone_slab 5 
setblock ~46 ~2 ~74 double_stone_slab 5 
setblock ~46 ~2 ~76 double_stone_slab 5 
setblock ~46 ~2 ~80 stonebrick 0  
fill ~46 ~2 ~81 ~46 ~16 ~81 planks 0  
fill ~46 ~2 ~82 ~46 ~8 ~82 fence 0  
fill ~47 ~2 ~19 ~47 ~5 ~19 cobblestone_wall 0  
fill ~47 ~2 ~21 ~47 ~5 ~21 cobblestone_wall 0  
fill ~47 ~2 ~27 ~47 ~5 ~27 cobblestone_wall 0  
fill ~47 ~2 ~33 ~47 ~5 ~33 cobblestone_wall 0  
fill ~47 ~2 ~39 ~47 ~5 ~39 cobblestone_wall 0  
fill ~47 ~2 ~63 ~47 ~5 ~63 cobblestone_wall 0  
fill ~47 ~2 ~69 ~47 ~5 ~69 cobblestone_wall 0  
fill ~47 ~2 ~75 ~47 ~5 ~75 cobblestone_wall 0  
fill ~47 ~2 ~81 ~47 ~5 ~81 cobblestone_wall 0  
fill ~47 ~2 ~83 ~47 ~5 ~83 cobblestone_wall 0  
fill ~48 ~2 ~20 ~48 ~5 ~20 cobblestone_wall 0  
fill ~48 ~2 ~40 ~48 ~1 ~40 stonebrick 0  
fill ~48 ~2 ~62 ~48 ~1 ~62 stonebrick 0  
fill ~48 ~2 ~82 ~48 ~5 ~82 cobblestone_wall 0 
setblock ~52 ~2 ~40 stonebrick 0 
setblock ~52 ~2 ~62 stonebrick 0  
fill ~53 ~2 ~39 ~53 ~5 ~39 cobblestone_wall 0  
fill ~53 ~2 ~42 ~53 ~14 ~42 planks 0  
fill ~53 ~2 ~43 ~53 ~2 ~46 planks 0  
fill ~53 ~2 ~47 ~54 ~2 ~47 log 0  
fill ~53 ~2 ~55 ~54 ~2 ~55 log 0  
fill ~53 ~2 ~56 ~53 ~14 ~56 planks 0  
fill ~53 ~2 ~57 ~53 ~2 ~60 planks 0  
fill ~53 ~2 ~63 ~53 ~5 ~63 cobblestone_wall 0 
setblock ~54 ~2 ~42 stonebrick 0 
setblock ~54 ~2 ~46 stonebrick 0 
setblock ~54 ~2 ~56 stonebrick 0 
setblock ~54 ~2 ~60 stonebrick 0  
fill ~55 ~2 ~41 ~55 ~5 ~41 cobblestone_wall 0  
fill ~55 ~2 ~47 ~55 ~5 ~47 cobblestone_wall 0  
fill ~55 ~2 ~55 ~55 ~5 ~55 cobblestone_wall 0  
fill ~55 ~2 ~61 ~55 ~5 ~61 cobblestone_wall 0  
fill ~15 ~3 ~42 ~15 ~6 ~42 fence 0  
fill ~15 ~3 ~46 ~15 ~6 ~46 fence 0  
fill ~15 ~3 ~47 ~16 ~3 ~47 log 0  
fill ~15 ~3 ~55 ~16 ~3 ~55 log 0  
fill ~15 ~3 ~56 ~15 ~6 ~56 fence 0  
fill ~15 ~3 ~60 ~15 ~6 ~60 fence 0  
fill ~16 ~3 ~43 ~16 ~7 ~43 glass 0  
fill ~16 ~3 ~44 ~16 ~11 ~44 planks 0  
fill ~16 ~3 ~45 ~16 ~7 ~45 glass 0  
fill ~16 ~3 ~46 ~16 ~14 ~46 planks 0  
fill ~16 ~3 ~57 ~16 ~7 ~57 glass 0  
fill ~16 ~3 ~58 ~16 ~11 ~58 planks 0  
fill ~16 ~3 ~59 ~16 ~7 ~59 glass 0  
fill ~16 ~3 ~60 ~16 ~14 ~60 planks 0  
fill ~17 ~3 ~40 ~17 ~6 ~40 fence 0  
fill ~17 ~3 ~41 ~17 ~16 ~41 planks 0  
fill ~17 ~3 ~61 ~17 ~16 ~61 planks 0  
fill ~17 ~3 ~62 ~17 ~6 ~62 fence 0  
fill ~18 ~3 ~41 ~20 ~3 ~41 glass 0  
fill ~18 ~3 ~61 ~20 ~3 ~61 glass 0  
fill ~21 ~3 ~40 ~21 ~6 ~40 fence 0  
fill ~21 ~3 ~41 ~23 ~3 ~41 planks 0  
fill ~21 ~3 ~61 ~23 ~3 ~61 planks 0  
fill ~21 ~3 ~62 ~21 ~6 ~62 fence 0  
fill ~23 ~3 ~22 ~23 ~6 ~22 fence 0  
fill ~23 ~3 ~26 ~23 ~6 ~26 fence 0  
fill ~23 ~3 ~27 ~24 ~3 ~27 log 0  
fill ~23 ~3 ~28 ~23 ~6 ~28 fence 0  
fill ~23 ~3 ~32 ~23 ~6 ~32 fence 0  
fill ~23 ~3 ~33 ~24 ~3 ~33 log 0  
fill ~23 ~3 ~34 ~23 ~6 ~34 fence 0  
fill ~23 ~3 ~38 ~23 ~6 ~38 fence 0  
fill ~23 ~3 ~39 ~24 ~3 ~39 log 0  
fill ~23 ~3 ~63 ~24 ~3 ~63 log 0  
fill ~23 ~3 ~64 ~23 ~6 ~64 fence 0  
fill ~23 ~3 ~68 ~23 ~6 ~68 fence 0  
fill ~23 ~3 ~69 ~24 ~3 ~69 log 0  
fill ~23 ~3 ~70 ~23 ~6 ~70 fence 0  
fill ~23 ~3 ~74 ~23 ~6 ~74 fence 0  
fill ~23 ~3 ~75 ~24 ~3 ~75 log 0  
fill ~23 ~3 ~76 ~23 ~6 ~76 fence 0  
fill ~23 ~3 ~80 ~23 ~6 ~80 fence 0  
fill ~24 ~3 ~22 ~31 ~3 ~22 planks 0  
fill ~24 ~3 ~23 ~24 ~5 ~23 glass 0  
fill ~24 ~3 ~24 ~24 ~6 ~24 glass 0  
fill ~24 ~3 ~25 ~24 ~5 ~25 glass 0  
fill ~24 ~3 ~26 ~28 ~3 ~26 planks 0  
fill ~24 ~3 ~29 ~24 ~5 ~29 glass 0  
fill ~24 ~3 ~30 ~24 ~6 ~30 glass 0  
fill ~24 ~3 ~31 ~24 ~5 ~31 glass 0  
fill ~24 ~3 ~32 ~24 ~8 ~32 planks 0  
fill ~24 ~3 ~35 ~24 ~5 ~35 glass 0  
fill ~24 ~3 ~36 ~24 ~6 ~36 glass 0  
fill ~24 ~3 ~37 ~24 ~5 ~37 glass 0  
fill ~24 ~3 ~38 ~24 ~8 ~38 planks 0  
fill ~24 ~3 ~65 ~24 ~5 ~65 glass 0  
fill ~24 ~3 ~66 ~24 ~6 ~66 glass 0  
fill ~24 ~3 ~67 ~24 ~5 ~67 glass 0  
fill ~24 ~3 ~68 ~24 ~8 ~68 planks 0  
fill ~24 ~3 ~71 ~24 ~5 ~71 glass 0  
fill ~24 ~3 ~72 ~24 ~6 ~72 glass 0  
fill ~24 ~3 ~73 ~24 ~5 ~73 glass 0  
fill ~24 ~3 ~74 ~24 ~8 ~74 planks 0  
fill ~24 ~3 ~76 ~28 ~3 ~76 planks 0  
fill ~24 ~3 ~77 ~24 ~5 ~77 glass 0  
fill ~24 ~3 ~78 ~24 ~6 ~78 glass 0  
fill ~24 ~3 ~79 ~24 ~5 ~79 glass 0  
fill ~24 ~3 ~80 ~31 ~3 ~80 planks 0  
fill ~25 ~3 ~23 ~28 ~3 ~23 planks 0  
fill ~25 ~3 ~24 ~28 ~3 ~24 planks 0  
fill ~25 ~3 ~25 ~28 ~3 ~25 planks 0  
fill ~25 ~3 ~77 ~28 ~3 ~77 planks 0  
fill ~25 ~3 ~78 ~28 ~3 ~78 planks 0  
fill ~25 ~3 ~79 ~28 ~3 ~79 planks 0  
fill ~26 ~3 ~27 ~26 ~4 ~27 planks 0  
fill ~26 ~3 ~75 ~26 ~4 ~75 planks 0  
fill ~27 ~3 ~21 ~31 ~3 ~21 planks 0  
fill ~27 ~3 ~81 ~31 ~3 ~81 planks 0  
fill ~29 ~3 ~23 ~29 ~3 ~25 oak_stairs 1  
fill ~29 ~3 ~26 ~29 ~8 ~26 log 0  
fill ~29 ~3 ~27 ~29 ~8 ~27 planks 0  
fill ~29 ~3 ~75 ~29 ~8 ~75 planks 0  
fill ~29 ~3 ~76 ~29 ~8 ~76 log 0  
fill ~29 ~3 ~77 ~29 ~3 ~79 oak_stairs 1  
fill ~30 ~3 ~26 ~31 ~3 ~26 planks 0  
fill ~30 ~3 ~76 ~31 ~3 ~76 planks 0  
fill ~38 ~3 ~21 ~42 ~3 ~21 planks 0  
fill ~38 ~3 ~81 ~42 ~3 ~81 planks 0  
fill ~39 ~3 ~22 ~45 ~3 ~22 planks 0  
fill ~39 ~3 ~26 ~39 ~8 ~26 planks 0  
fill ~39 ~3 ~76 ~39 ~8 ~76 planks 0  
fill ~39 ~3 ~80 ~45 ~3 ~80 planks 0  
fill ~40 ~3 ~23 ~40 ~3 ~25 oak_stairs 0  
fill ~40 ~3 ~26 ~40 ~8 ~26 log 0  
fill ~40 ~3 ~27 ~40 ~8 ~27 planks 0  
fill ~40 ~3 ~75 ~40 ~8 ~75 planks 0  
fill ~40 ~3 ~76 ~40 ~8 ~76 log 0  
fill ~40 ~3 ~77 ~40 ~3 ~79 oak_stairs 0  
fill ~41 ~3 ~23 ~44 ~3 ~23 planks 0  
fill ~41 ~3 ~24 ~44 ~3 ~24 planks 0  
fill ~41 ~3 ~25 ~44 ~3 ~25 planks 0 
setblock ~41 ~3 ~26 oak_stairs 6 
setblock ~41 ~3 ~76 oak_stairs 7  
fill ~41 ~3 ~77 ~44 ~3 ~77 planks 0  
fill ~41 ~3 ~78 ~44 ~3 ~78 planks 0  
fill ~41 ~3 ~79 ~44 ~3 ~79 planks 0  
fill ~42 ~3 ~26 ~45 ~3 ~26 planks 0  
fill ~42 ~3 ~76 ~45 ~3 ~76 planks 0  
fill ~43 ~3 ~27 ~43 ~4 ~27 planks 0  
fill ~43 ~3 ~75 ~43 ~4 ~75 planks 0  
fill ~45 ~3 ~23 ~45 ~5 ~23 glass 0  
fill ~45 ~3 ~24 ~45 ~6 ~24 glass 0  
fill ~45 ~3 ~25 ~45 ~5 ~25 glass 0  
fill ~45 ~3 ~27 ~46 ~3 ~27 log 0  
fill ~45 ~3 ~29 ~45 ~5 ~29 glass 0  
fill ~45 ~3 ~30 ~45 ~6 ~30 glass 0  
fill ~45 ~3 ~31 ~45 ~5 ~31 glass 0  
fill ~45 ~3 ~32 ~45 ~8 ~32 planks 0  
fill ~45 ~3 ~33 ~46 ~3 ~33 log 0  
fill ~45 ~3 ~35 ~45 ~5 ~35 glass 0  
fill ~45 ~3 ~36 ~45 ~6 ~36 glass 0  
fill ~45 ~3 ~37 ~45 ~5 ~37 glass 0  
fill ~45 ~3 ~38 ~45 ~8 ~38 planks 0  
fill ~45 ~3 ~39 ~46 ~3 ~39 log 0  
fill ~45 ~3 ~63 ~46 ~3 ~63 log 0  
fill ~45 ~3 ~65 ~45 ~5 ~65 glass 0  
fill ~45 ~3 ~66 ~45 ~6 ~66 glass 0  
fill ~45 ~3 ~67 ~45 ~5 ~67 glass 0  
fill ~45 ~3 ~68 ~45 ~8 ~68 planks 0  
fill ~45 ~3 ~69 ~46 ~3 ~69 log 0  
fill ~45 ~3 ~71 ~45 ~5 ~71 glass 0  
fill ~45 ~3 ~72 ~45 ~6 ~72 glass 0  
fill ~45 ~3 ~73 ~45 ~5 ~73 glass 0  
fill ~45 ~3 ~74 ~45 ~8 ~74 planks 0  
fill ~45 ~3 ~75 ~46 ~3 ~75 log 0  
fill ~45 ~3 ~77 ~45 ~5 ~77 glass 0  
fill ~45 ~3 ~78 ~45 ~6 ~78 glass 0  
fill ~45 ~3 ~79 ~45 ~5 ~79 glass 0  
fill ~46 ~3 ~22 ~46 ~6 ~22 fence 0  
fill ~46 ~3 ~26 ~46 ~6 ~26 fence 0  
fill ~46 ~3 ~28 ~46 ~6 ~28 fence 0  
fill ~46 ~3 ~32 ~46 ~6 ~32 fence 0  
fill ~46 ~3 ~34 ~46 ~6 ~34 fence 0  
fill ~46 ~3 ~38 ~46 ~6 ~38 fence 0  
fill ~46 ~3 ~41 ~48 ~3 ~41 planks 0  
fill ~46 ~3 ~61 ~48 ~3 ~61 planks 0  
fill ~46 ~3 ~64 ~46 ~6 ~64 fence 0  
fill ~46 ~3 ~68 ~46 ~6 ~68 fence 0  
fill ~46 ~3 ~70 ~46 ~6 ~70 fence 0  
fill ~46 ~3 ~74 ~46 ~6 ~74 fence 0  
fill ~46 ~3 ~76 ~46 ~6 ~76 fence 0  
fill ~46 ~3 ~80 ~46 ~6 ~80 fence 0  
fill ~48 ~3 ~40 ~48 ~6 ~40 fence 0  
fill ~48 ~3 ~62 ~48 ~6 ~62 fence 0  
fill ~49 ~3 ~41 ~51 ~3 ~41 glass 0  
fill ~49 ~3 ~61 ~51 ~3 ~61 glass 0  
fill ~52 ~3 ~40 ~52 ~6 ~40 fence 0  
fill ~52 ~3 ~41 ~52 ~16 ~41 planks 0  
fill ~52 ~3 ~61 ~52 ~16 ~61 planks 0  
fill ~52 ~3 ~62 ~52 ~6 ~62 fence 0  
fill ~53 ~3 ~43 ~53 ~7 ~43 glass 0  
fill ~53 ~3 ~44 ~53 ~11 ~44 planks 0  
fill ~53 ~3 ~45 ~53 ~7 ~45 glass 0  
fill ~53 ~3 ~46 ~53 ~14 ~46 planks 0  
fill ~53 ~3 ~47 ~54 ~3 ~47 log 0  
fill ~53 ~3 ~55 ~54 ~3 ~55 log 0  
fill ~53 ~3 ~57 ~53 ~7 ~57 glass 0  
fill ~53 ~3 ~58 ~53 ~11 ~58 planks 0  
fill ~53 ~3 ~59 ~53 ~7 ~59 glass 0  
fill ~53 ~3 ~60 ~53 ~14 ~60 planks 0  
fill ~54 ~3 ~42 ~54 ~6 ~42 fence 0  
fill ~54 ~3 ~46 ~54 ~6 ~46 fence 0  
fill ~54 ~3 ~56 ~54 ~6 ~56 fence 0  
fill ~54 ~3 ~60 ~54 ~6 ~60 fence 0  
fill ~15 ~4 ~47 ~16 ~4 ~47 log 0  
fill ~15 ~4 ~55 ~16 ~4 ~55 log 0 
setblock ~17 ~4 ~44 torch 1 
setblock ~17 ~4 ~58 torch 1  
fill ~18 ~4 ~41 ~20 ~4 ~41 glass 0  
fill ~18 ~4 ~61 ~20 ~4 ~61 glass 0  
fill ~21 ~4 ~41 ~23 ~4 ~41 planks 0  
fill ~21 ~4 ~61 ~23 ~4 ~61 planks 0  
fill ~23 ~4 ~27 ~24 ~4 ~27 log 0  
fill ~23 ~4 ~33 ~24 ~4 ~33 log 0  
fill ~23 ~4 ~39 ~24 ~4 ~39 log 0  
fill ~23 ~4 ~63 ~24 ~4 ~63 log 0  
fill ~23 ~4 ~69 ~24 ~4 ~69 log 0  
fill ~23 ~4 ~75 ~24 ~4 ~75 log 0  
fill ~24 ~4 ~22 ~31 ~4 ~22 planks 0  
fill ~24 ~4 ~26 ~24 ~8 ~26 planks 0  
fill ~24 ~4 ~76 ~24 ~8 ~76 planks 0  
fill ~24 ~4 ~80 ~31 ~4 ~80 planks 0  
fill ~25 ~4 ~26 ~25 ~8 ~26 log 0 
setblock ~25 ~4 ~28 torch 1 
setblock ~25 ~4 ~32 torch 1 
setblock ~25 ~4 ~34 torch 1 
setblock ~25 ~4 ~68 torch 1 
setblock ~25 ~4 ~70 torch 1 
setblock ~25 ~4 ~74 torch 1  
fill ~25 ~4 ~76 ~25 ~8 ~76 log 0  
fill ~26 ~4 ~26 ~28 ~4 ~26 oak_stairs 2  
fill ~26 ~4 ~76 ~28 ~4 ~76 oak_stairs 3  
fill ~27 ~4 ~21 ~31 ~4 ~21 planks 0  
fill ~27 ~4 ~27 ~30 ~4 ~27 planks 0  
fill ~27 ~4 ~75 ~30 ~4 ~75 planks 0  
fill ~27 ~4 ~81 ~31 ~4 ~81 planks 0  
fill ~30 ~4 ~26 ~31 ~4 ~26 planks 0 
setblock ~30 ~4 ~28 torch 2 
setblock ~30 ~4 ~32 torch 2 
setblock ~30 ~4 ~34 torch 2 
setblock ~30 ~4 ~38 torch 2 
setblock ~30 ~4 ~40 torch 2 
setblock ~30 ~4 ~46 torch 2 
setblock ~30 ~4 ~56 torch 2 
setblock ~30 ~4 ~62 torch 2 
setblock ~30 ~4 ~64 torch 2 
setblock ~30 ~4 ~68 torch 2 
setblock ~30 ~4 ~70 torch 2 
setblock ~30 ~4 ~74 torch 2  
fill ~30 ~4 ~76 ~31 ~4 ~76 planks 0 
setblock ~32 ~4 ~22 torch 1 
setblock ~32 ~4 ~26 torch 1 
setblock ~32 ~4 ~28 torch 1 
setblock ~32 ~4 ~32 torch 1 
setblock ~32 ~4 ~34 torch 1 
setblock ~32 ~4 ~38 torch 1 
setblock ~32 ~4 ~40 torch 1 
setblock ~32 ~4 ~46 torch 1 
setblock ~32 ~4 ~56 torch 1 
setblock ~32 ~4 ~62 torch 1 
setblock ~32 ~4 ~64 torch 1 
setblock ~32 ~4 ~68 torch 1 
setblock ~32 ~4 ~70 torch 1 
setblock ~32 ~4 ~74 torch 1 
setblock ~32 ~4 ~76 torch 1 
setblock ~32 ~4 ~80 torch 1 
setblock ~37 ~4 ~22 torch 2 
setblock ~37 ~4 ~26 torch 2 
setblock ~37 ~4 ~28 torch 2 
setblock ~37 ~4 ~32 torch 2 
setblock ~37 ~4 ~34 torch 2 
setblock ~37 ~4 ~38 torch 2 
setblock ~37 ~4 ~40 torch 2 
setblock ~37 ~4 ~46 torch 2 
setblock ~37 ~4 ~56 torch 2 
setblock ~37 ~4 ~62 torch 2 
setblock ~37 ~4 ~64 torch 2 
setblock ~37 ~4 ~68 torch 2 
setblock ~37 ~4 ~70 torch 2 
setblock ~37 ~4 ~74 torch 2 
setblock ~37 ~4 ~76 torch 2 
setblock ~37 ~4 ~80 torch 2  
fill ~38 ~4 ~21 ~42 ~4 ~21 planks 0  
fill ~38 ~4 ~81 ~42 ~4 ~81 planks 0  
fill ~39 ~4 ~22 ~45 ~4 ~22 planks 0 
setblock ~39 ~4 ~28 torch 1 
setblock ~39 ~4 ~32 torch 1 
setblock ~39 ~4 ~34 torch 1 
setblock ~39 ~4 ~38 torch 1 
setblock ~39 ~4 ~40 torch 1 
setblock ~39 ~4 ~46 torch 1 
setblock ~39 ~4 ~56 torch 1 
setblock ~39 ~4 ~62 torch 1 
setblock ~39 ~4 ~64 torch 1 
setblock ~39 ~4 ~68 torch 1 
setblock ~39 ~4 ~70 torch 1 
setblock ~39 ~4 ~74 torch 1  
fill ~39 ~4 ~80 ~45 ~4 ~80 planks 0  
fill ~41 ~4 ~26 ~43 ~4 ~26 oak_stairs 2  
fill ~41 ~4 ~27 ~44 ~4 ~27 planks 0  
fill ~41 ~4 ~75 ~44 ~4 ~75 planks 0  
fill ~41 ~4 ~76 ~43 ~4 ~76 oak_stairs 3  
fill ~44 ~4 ~26 ~44 ~8 ~26 log 0 
setblock ~44 ~4 ~28 torch 2 
setblock ~44 ~4 ~32 torch 2 
setblock ~44 ~4 ~34 torch 2 
setblock ~44 ~4 ~38 torch 2 
setblock ~44 ~4 ~40 torch 2 
setblock ~44 ~4 ~62 torch 2 
setblock ~44 ~4 ~64 torch 2 
setblock ~44 ~4 ~68 torch 2 
setblock ~44 ~4 ~70 torch 2 
setblock ~44 ~4 ~74 torch 2  
fill ~44 ~4 ~76 ~44 ~8 ~76 log 0  
fill ~45 ~4 ~26 ~45 ~8 ~26 planks 0  
fill ~45 ~4 ~27 ~46 ~4 ~27 log 0  
fill ~45 ~4 ~33 ~46 ~4 ~33 log 0  
fill ~45 ~4 ~39 ~46 ~4 ~39 log 0  
fill ~45 ~4 ~63 ~46 ~4 ~63 log 0  
fill ~45 ~4 ~69 ~46 ~4 ~69 log 0  
fill ~45 ~4 ~75 ~46 ~4 ~75 log 0  
fill ~46 ~4 ~41 ~48 ~4 ~41 planks 0  
fill ~46 ~4 ~61 ~48 ~4 ~61 planks 0  
fill ~49 ~4 ~41 ~51 ~4 ~41 glass 0  
fill ~49 ~4 ~61 ~51 ~4 ~61 glass 0 
setblock ~52 ~4 ~44 torch 2 
setblock ~52 ~4 ~58 torch 2  
fill ~53 ~4 ~47 ~54 ~4 ~47 log 0  
fill ~53 ~4 ~55 ~54 ~4 ~55 log 0  
fill ~15 ~5 ~47 ~16 ~5 ~47 log 0  
fill ~15 ~5 ~55 ~16 ~5 ~55 log 0  
fill ~18 ~5 ~41 ~20 ~5 ~41 glass 0  
fill ~18 ~5 ~61 ~20 ~5 ~61 glass 0  
fill ~21 ~5 ~41 ~23 ~5 ~41 planks 0  
fill ~21 ~5 ~61 ~23 ~5 ~61 planks 0  
fill ~23 ~5 ~27 ~24 ~5 ~27 log 0  
fill ~23 ~5 ~33 ~24 ~5 ~33 log 0  
fill ~23 ~5 ~39 ~24 ~5 ~39 log 0  
fill ~23 ~5 ~63 ~24 ~5 ~63 log 0  
fill ~23 ~5 ~69 ~24 ~5 ~69 log 0  
fill ~23 ~5 ~75 ~24 ~5 ~75 log 0  
fill ~24 ~5 ~22 ~31 ~5 ~22 planks 0  
fill ~24 ~5 ~80 ~31 ~5 ~80 planks 0  
fill ~25 ~5 ~28 ~31 ~5 ~28 planks 0  
fill ~25 ~5 ~74 ~31 ~5 ~74 planks 0  
fill ~26 ~5 ~27 ~28 ~5 ~27 oak_stairs 2  
fill ~26 ~5 ~75 ~28 ~5 ~75 oak_stairs 3  
fill ~27 ~5 ~21 ~31 ~5 ~21 planks 0  
fill ~27 ~5 ~81 ~31 ~5 ~81 planks 0  
fill ~30 ~5 ~26 ~31 ~5 ~26 planks 0  
fill ~30 ~5 ~76 ~31 ~5 ~76 planks 0  
fill ~38 ~5 ~21 ~42 ~5 ~21 planks 0  
fill ~38 ~5 ~81 ~42 ~5 ~81 planks 0  
fill ~39 ~5 ~22 ~45 ~5 ~22 planks 0  
fill ~39 ~5 ~28 ~45 ~5 ~28 planks 0  
fill ~39 ~5 ~74 ~45 ~5 ~74 planks 0  
fill ~39 ~5 ~80 ~45 ~5 ~80 planks 0  
fill ~41 ~5 ~27 ~43 ~5 ~27 oak_stairs 2  
fill ~41 ~5 ~75 ~43 ~5 ~75 oak_stairs 3  
fill ~45 ~5 ~27 ~46 ~5 ~27 log 0  
fill ~45 ~5 ~33 ~46 ~5 ~33 log 0  
fill ~45 ~5 ~39 ~46 ~5 ~39 log 0  
fill ~45 ~5 ~63 ~46 ~5 ~63 log 0  
fill ~45 ~5 ~69 ~46 ~5 ~69 log 0  
fill ~45 ~5 ~75 ~46 ~5 ~75 log 0  
fill ~46 ~5 ~41 ~48 ~5 ~41 planks 0  
fill ~46 ~5 ~61 ~48 ~5 ~61 planks 0  
fill ~49 ~5 ~41 ~51 ~5 ~41 glass 0  
fill ~49 ~5 ~61 ~51 ~5 ~61 glass 0  
fill ~53 ~5 ~47 ~54 ~5 ~47 log 0  
fill ~53 ~5 ~55 ~54 ~5 ~55 log 0  
fill ~14 ~6 ~41 ~14 ~8 ~41 planks 0  
fill ~14 ~6 ~47 ~14 ~8 ~47 planks 0  
fill ~14 ~6 ~55 ~14 ~8 ~55 planks 0  
fill ~14 ~6 ~61 ~14 ~8 ~61 planks 0  
fill ~15 ~6 ~47 ~16 ~6 ~47 log 0  
fill ~15 ~6 ~55 ~16 ~6 ~55 log 0  
fill ~16 ~6 ~39 ~16 ~8 ~39 planks 0  
fill ~16 ~6 ~63 ~16 ~8 ~63 planks 0 
setblock ~18 ~6 ~41 oak_stairs 5 
setblock ~18 ~6 ~61 oak_stairs 5 
setblock ~19 ~6 ~41 glass 0 
setblock ~19 ~6 ~61 glass 0 
setblock ~20 ~6 ~41 oak_stairs 4 
setblock ~20 ~6 ~61 oak_stairs 4  
fill ~21 ~6 ~20 ~21 ~7 ~20 planks 0  
fill ~21 ~6 ~41 ~23 ~6 ~41 planks 0  
fill ~21 ~6 ~61 ~23 ~6 ~61 planks 0  
fill ~21 ~6 ~82 ~21 ~7 ~82 planks 0  
fill ~22 ~6 ~19 ~22 ~7 ~19 planks 0 
setblock ~22 ~6 ~21 planks 0 
setblock ~22 ~6 ~27 planks 0 
setblock ~22 ~6 ~33 planks 0 
setblock ~22 ~6 ~39 planks 0 
setblock ~22 ~6 ~63 planks 0 
setblock ~22 ~6 ~69 planks 0 
setblock ~22 ~6 ~75 planks 0 
setblock ~22 ~6 ~81 planks 0  
fill ~22 ~6 ~83 ~22 ~7 ~83 planks 0  
fill ~23 ~6 ~27 ~24 ~6 ~27 log 0  
fill ~23 ~6 ~33 ~24 ~6 ~33 log 0  
fill ~23 ~6 ~39 ~24 ~6 ~39 log 0  
fill ~23 ~6 ~63 ~24 ~6 ~63 log 0  
fill ~23 ~6 ~69 ~24 ~6 ~69 log 0  
fill ~23 ~6 ~75 ~24 ~6 ~75 log 0  
fill ~24 ~6 ~22 ~31 ~6 ~22 planks 0 
setblock ~24 ~6 ~23 oak_stairs 7 
setblock ~24 ~6 ~25 oak_stairs 6 
setblock ~24 ~6 ~29 oak_stairs 7 
setblock ~24 ~6 ~31 oak_stairs 6 
setblock ~24 ~6 ~35 oak_stairs 7 
setblock ~24 ~6 ~37 oak_stairs 6 
setblock ~24 ~6 ~65 oak_stairs 7 
setblock ~24 ~6 ~67 oak_stairs 6 
setblock ~24 ~6 ~71 oak_stairs 7 
setblock ~24 ~6 ~73 oak_stairs 6 
setblock ~24 ~6 ~77 oak_stairs 7 
setblock ~24 ~6 ~79 oak_stairs 6  
fill ~24 ~6 ~80 ~31 ~6 ~80 planks 0 
setblock ~25 ~6 ~23 oak_stairs 5 
setblock ~25 ~6 ~25 oak_stairs 5  
fill ~25 ~6 ~28 ~25 ~8 ~28 planks 0  
fill ~25 ~6 ~29 ~30 ~6 ~29 planks 0  
fill ~25 ~6 ~73 ~30 ~6 ~73 planks 0  
fill ~25 ~6 ~74 ~25 ~8 ~74 planks 0 
setblock ~25 ~6 ~77 oak_stairs 5 
setblock ~25 ~6 ~79 oak_stairs 5  
fill ~26 ~6 ~28 ~28 ~6 ~28 oak_stairs 2  
fill ~26 ~6 ~74 ~28 ~6 ~74 oak_stairs 3  
fill ~27 ~6 ~21 ~31 ~6 ~21 planks 0  
fill ~27 ~6 ~81 ~31 ~6 ~81 planks 0  
fill ~28 ~6 ~19 ~28 ~7 ~19 planks 0  
fill ~28 ~6 ~83 ~28 ~7 ~83 planks 0  
fill ~29 ~6 ~28 ~31 ~6 ~28 planks 0  
fill ~29 ~6 ~74 ~31 ~6 ~74 planks 0  
fill ~30 ~6 ~26 ~31 ~6 ~26 planks 0  
fill ~30 ~6 ~76 ~31 ~6 ~76 planks 0  
fill ~38 ~6 ~21 ~42 ~6 ~21 planks 0  
fill ~38 ~6 ~81 ~42 ~6 ~81 planks 0  
fill ~39 ~6 ~22 ~45 ~6 ~22 planks 0  
fill ~39 ~6 ~28 ~40 ~6 ~28 planks 0  
fill ~39 ~6 ~29 ~44 ~6 ~29 planks 0  
fill ~39 ~6 ~73 ~44 ~6 ~73 planks 0  
fill ~39 ~6 ~74 ~40 ~6 ~74 planks 0  
fill ~39 ~6 ~80 ~45 ~6 ~80 planks 0  
fill ~41 ~6 ~19 ~41 ~7 ~19 planks 0  
fill ~41 ~6 ~28 ~43 ~6 ~28 oak_stairs 2  
fill ~41 ~6 ~74 ~43 ~6 ~74 oak_stairs 3  
fill ~41 ~6 ~83 ~41 ~7 ~83 planks 0  
fill ~44 ~6 ~23 ~45 ~6 ~23 oak_stairs 7  
fill ~44 ~6 ~25 ~45 ~6 ~25 oak_stairs 6  
fill ~44 ~6 ~28 ~44 ~8 ~28 planks 0  
fill ~44 ~6 ~74 ~44 ~8 ~74 planks 0  
fill ~44 ~6 ~77 ~45 ~6 ~77 oak_stairs 7  
fill ~44 ~6 ~79 ~45 ~6 ~79 oak_stairs 6  
fill ~45 ~6 ~27 ~46 ~6 ~27 log 0 
setblock ~45 ~6 ~29 oak_stairs 7 
setblock ~45 ~6 ~31 oak_stairs 6  
fill ~45 ~6 ~33 ~46 ~6 ~33 log 0 
setblock ~45 ~6 ~35 oak_stairs 7 
setblock ~45 ~6 ~37 oak_stairs 6  
fill ~45 ~6 ~39 ~46 ~6 ~39 log 0  
fill ~45 ~6 ~63 ~46 ~6 ~63 log 0 
setblock ~45 ~6 ~65 oak_stairs 7 
setblock ~45 ~6 ~67 oak_stairs 6  
fill ~45 ~6 ~69 ~46 ~6 ~69 log 0 
setblock ~45 ~6 ~71 oak_stairs 7 
setblock ~45 ~6 ~73 oak_stairs 6  
fill ~45 ~6 ~75 ~46 ~6 ~75 log 0   
fill ~46 ~6 ~41 ~48 ~6 ~41 planks 0  
fill ~46 ~6 ~61 ~48 ~6 ~61 planks 0  
fill ~47 ~6 ~19 ~47 ~7 ~19 planks 0 
setblock ~47 ~6 ~21 planks 0 
setblock ~47 ~6 ~27 planks 0 
setblock ~47 ~6 ~33 planks 0 
setblock ~47 ~6 ~39 planks 0 
setblock ~47 ~6 ~63 planks 0 
setblock ~47 ~6 ~69 planks 0 
setblock ~47 ~6 ~75 planks 0 
setblock ~47 ~6 ~81 planks 0  
fill ~47 ~6 ~83 ~47 ~7 ~83 planks 0  
fill ~48 ~6 ~20 ~48 ~7 ~20 planks 0  
fill ~48 ~6 ~82 ~48 ~7 ~82 planks 0 
setblock ~49 ~6 ~41 oak_stairs 5 
setblock ~49 ~6 ~61 oak_stairs 5 
setblock ~50 ~6 ~41 glass 0 
setblock ~50 ~6 ~61 glass 0 
setblock ~51 ~6 ~41 oak_stairs 4 
setblock ~51 ~6 ~61 oak_stairs 4  
fill ~53 ~6 ~39 ~53 ~8 ~39 planks 0  
fill ~53 ~6 ~47 ~54 ~6 ~47 log 0  
fill ~53 ~6 ~55 ~54 ~6 ~55 log 0  
fill ~53 ~6 ~63 ~53 ~8 ~63 planks 0  
fill ~55 ~6 ~41 ~55 ~8 ~41 planks 0  
fill ~55 ~6 ~47 ~55 ~8 ~47 planks 0  
fill ~55 ~6 ~55 ~55 ~8 ~55 planks 0  
fill ~55 ~6 ~61 ~55 ~8 ~61 planks 0  
fill ~13 ~7 ~40 ~15 ~7 ~40 oak_stairs 6 
setblock ~13 ~7 ~41 oak_stairs 4  
fill ~13 ~7 ~42 ~14 ~7 ~42 oak_stairs 7  
fill ~13 ~7 ~46 ~14 ~7 ~46 oak_stairs 6 
setblock ~13 ~7 ~47 oak_stairs 4  
fill ~13 ~7 ~48 ~14 ~7 ~48 oak_stairs 7  
fill ~13 ~7 ~54 ~14 ~7 ~54 oak_stairs 6 
setblock ~13 ~7 ~55 oak_stairs 4  
fill ~13 ~7 ~56 ~14 ~7 ~56 oak_stairs 7  
fill ~13 ~7 ~60 ~14 ~7 ~60 oak_stairs 6 
setblock ~13 ~7 ~61 oak_stairs 4  
fill ~13 ~7 ~62 ~15 ~7 ~62 oak_stairs 7  
fill ~15 ~7 ~38 ~17 ~7 ~38 oak_stairs 6 
setblock ~15 ~7 ~39 oak_stairs 4 
setblock ~15 ~7 ~42 planks 0 
setblock ~15 ~7 ~46 planks 0  
fill ~15 ~7 ~47 ~16 ~7 ~47 log 0  
fill ~15 ~7 ~55 ~16 ~7 ~55 log 0 
setblock ~15 ~7 ~56 planks 0 
setblock ~15 ~7 ~60 planks 0 
setblock ~15 ~7 ~63 oak_stairs 4  
fill ~15 ~7 ~64 ~17 ~7 ~64 oak_stairs 7  
fill ~17 ~7 ~39 ~17 ~7 ~40 oak_stairs 5  
fill ~17 ~7 ~62 ~17 ~7 ~63 oak_stairs 5  
fill ~18 ~7 ~41 ~18 ~16 ~41 planks 0  
fill ~18 ~7 ~61 ~18 ~16 ~61 planks 0 
setblock ~19 ~7 ~41 log 8 
setblock ~19 ~7 ~61 log 8 
setblock ~20 ~7 ~20 oak_stairs 4  
fill ~20 ~7 ~41 ~23 ~7 ~41 planks 0  
fill ~20 ~7 ~61 ~23 ~7 ~61 planks 0 
setblock ~20 ~7 ~82 oak_stairs 4 
setblock ~21 ~7 ~19 planks 0  
fill ~21 ~7 ~21 ~21 ~7 ~22 oak_stairs 4  
fill ~21 ~7 ~26 ~21 ~7 ~28 oak_stairs 4  
fill ~21 ~7 ~32 ~23 ~7 ~32 oak_stairs 6  
fill ~21 ~7 ~33 ~21 ~7 ~34 oak_stairs 4  
fill ~21 ~7 ~38 ~21 ~7 ~40 oak_stairs 4  
fill ~21 ~7 ~62 ~21 ~7 ~64 oak_stairs 4  
fill ~21 ~7 ~68 ~21 ~7 ~69 oak_stairs 4  
fill ~21 ~7 ~70 ~23 ~7 ~70 oak_stairs 7  
fill ~21 ~7 ~74 ~21 ~7 ~76 oak_stairs 4  
fill ~21 ~7 ~80 ~21 ~7 ~81 oak_stairs 4 
setblock ~21 ~7 ~83 planks 0 
setblock ~22 ~7 ~18 oak_stairs 6  
fill ~22 ~7 ~21 ~22 ~8 ~21 log 4  
fill ~22 ~7 ~22 ~23 ~7 ~22 oak_stairs 7  
fill ~22 ~7 ~26 ~23 ~7 ~26 oak_stairs 6  
fill ~22 ~7 ~27 ~23 ~7 ~27 log 4  
fill ~22 ~7 ~28 ~23 ~7 ~28 oak_stairs 7  
fill ~22 ~7 ~33 ~23 ~7 ~33 log 4  
fill ~22 ~7 ~34 ~23 ~7 ~34 oak_stairs 7  
fill ~22 ~7 ~38 ~23 ~7 ~38 oak_stairs 6  
fill ~22 ~7 ~39 ~23 ~7 ~39 log 4  
fill ~22 ~7 ~63 ~23 ~7 ~63 log 4  
fill ~22 ~7 ~64 ~23 ~7 ~64 oak_stairs 7  
fill ~22 ~7 ~68 ~23 ~7 ~68 oak_stairs 6  
fill ~22 ~7 ~69 ~23 ~7 ~69 log 4  
fill ~22 ~7 ~74 ~23 ~7 ~74 oak_stairs 6  
fill ~22 ~7 ~75 ~23 ~7 ~75 log 4  
fill ~22 ~7 ~76 ~23 ~7 ~76 oak_stairs 7  
fill ~22 ~7 ~80 ~23 ~7 ~80 oak_stairs 6  
fill ~22 ~7 ~81 ~22 ~8 ~81 log 4 
setblock ~22 ~7 ~84 oak_stairs 7  
fill ~23 ~7 ~24 ~24 ~7 ~24 log 4  
fill ~23 ~7 ~30 ~24 ~7 ~30 log 4  
fill ~23 ~7 ~36 ~24 ~7 ~36 log 4  
fill ~23 ~7 ~66 ~24 ~7 ~66 log 4  
fill ~23 ~7 ~72 ~24 ~7 ~72 log 4  
fill ~23 ~7 ~78 ~24 ~7 ~78 log 4  
fill ~24 ~7 ~22 ~31 ~7 ~22 planks 0  
fill ~24 ~7 ~23 ~25 ~7 ~23 planks 0  
fill ~24 ~7 ~25 ~25 ~7 ~25 planks 0 
setblock ~24 ~7 ~27 log 0  
fill ~24 ~7 ~29 ~24 ~8 ~29 planks 0  
fill ~24 ~7 ~31 ~24 ~8 ~31 planks 0 
setblock ~24 ~7 ~33 log 0  
fill ~24 ~7 ~35 ~24 ~8 ~35 planks 0  
fill ~24 ~7 ~37 ~24 ~8 ~37 planks 0 
setblock ~24 ~7 ~39 log 0 
setblock ~24 ~7 ~63 log 0  
fill ~24 ~7 ~65 ~24 ~8 ~65 planks 0  
fill ~24 ~7 ~67 ~24 ~8 ~67 planks 0 
setblock ~24 ~7 ~69 log 0  
fill ~24 ~7 ~71 ~24 ~8 ~71 planks 0  
fill ~24 ~7 ~73 ~24 ~8 ~73 planks 0 
setblock ~24 ~7 ~75 log 0  
fill ~24 ~7 ~77 ~25 ~7 ~77 planks 0  
fill ~24 ~7 ~79 ~25 ~7 ~79 planks 0  
fill ~24 ~7 ~80 ~31 ~7 ~80 planks 0 
setblock ~25 ~7 ~24 oak_stairs 5  
fill ~25 ~7 ~29 ~25 ~8 ~29 log 0  
fill ~25 ~7 ~30 ~30 ~7 ~30 planks 0  
fill ~25 ~7 ~72 ~30 ~7 ~72 planks 0  
fill ~25 ~7 ~73 ~25 ~8 ~73 log 0 
setblock ~25 ~7 ~78 oak_stairs 5  
fill ~26 ~7 ~29 ~28 ~7 ~29 oak_stairs 2 
setblock ~26 ~7 ~39 oak_stairs 5 
setblock ~26 ~7 ~63 oak_stairs 5  
fill ~26 ~7 ~73 ~28 ~7 ~73 oak_stairs 3  
fill ~27 ~7 ~21 ~31 ~7 ~21 planks 0  
fill ~27 ~7 ~81 ~31 ~7 ~81 planks 0 
setblock ~28 ~7 ~18 oak_stairs 6 
setblock ~28 ~7 ~84 oak_stairs 7  
fill ~29 ~7 ~28 ~31 ~7 ~28 planks 0  
fill ~29 ~7 ~29 ~29 ~8 ~29 log 0 
setblock ~29 ~7 ~39 oak_stairs 4 
setblock ~29 ~7 ~63 oak_stairs 4  
fill ~29 ~7 ~73 ~29 ~8 ~73 log 0  
fill ~29 ~7 ~74 ~31 ~7 ~74 planks 0  
fill ~30 ~7 ~26 ~31 ~7 ~26 planks 0  
fill ~30 ~7 ~29 ~30 ~8 ~29 planks 0  
fill ~30 ~7 ~73 ~30 ~8 ~73 planks 0  
fill ~30 ~7 ~76 ~31 ~7 ~76 planks 0 
setblock ~31 ~7 ~23 oak_stairs 7 
setblock ~31 ~7 ~25 oak_stairs 6 
setblock ~31 ~7 ~29 oak_stairs 7 
setblock ~31 ~7 ~31 oak_stairs 6 
setblock ~31 ~7 ~35 oak_stairs 7 
setblock ~31 ~7 ~37 oak_stairs 6 
setblock ~31 ~7 ~41 oak_stairs 7 
setblock ~31 ~7 ~45 oak_stairs 6 
setblock ~31 ~7 ~57 oak_stairs 7 
setblock ~31 ~7 ~61 oak_stairs 6 
setblock ~31 ~7 ~65 oak_stairs 7 
setblock ~31 ~7 ~67 oak_stairs 6 
setblock ~31 ~7 ~71 oak_stairs 7 
setblock ~31 ~7 ~73 oak_stairs 6 
setblock ~31 ~7 ~77 oak_stairs 7 
setblock ~31 ~7 ~79 oak_stairs 6 
setblock ~32 ~7 ~27 oak_stairs 5 
setblock ~32 ~7 ~33 oak_stairs 5 
setblock ~32 ~7 ~39 oak_stairs 5 
setblock ~32 ~7 ~63 oak_stairs 5 
setblock ~32 ~7 ~69 oak_stairs 5 
setblock ~32 ~7 ~75 oak_stairs 5 
setblock ~37 ~7 ~27 oak_stairs 4 
setblock ~37 ~7 ~33 oak_stairs 4 
setblock ~37 ~7 ~39 oak_stairs 4 
setblock ~37 ~7 ~63 oak_stairs 4 
setblock ~37 ~7 ~69 oak_stairs 4 
setblock ~37 ~7 ~75 oak_stairs 4  
fill ~38 ~7 ~21 ~42 ~7 ~21 planks 0 
setblock ~38 ~7 ~23 oak_stairs 7 
setblock ~38 ~7 ~25 oak_stairs 6 
setblock ~38 ~7 ~29 oak_stairs 7 
setblock ~38 ~7 ~31 oak_stairs 6 
setblock ~38 ~7 ~35 oak_stairs 7 
setblock ~38 ~7 ~37 oak_stairs 6 
setblock ~38 ~7 ~41 oak_stairs 7 
setblock ~38 ~7 ~45 oak_stairs 6 
setblock ~38 ~7 ~57 oak_stairs 7 
setblock ~38 ~7 ~61 oak_stairs 6 
setblock ~38 ~7 ~65 oak_stairs 7 
setblock ~38 ~7 ~67 oak_stairs 6 
setblock ~38 ~7 ~71 oak_stairs 7 
setblock ~38 ~7 ~73 oak_stairs 6 
setblock ~38 ~7 ~77 oak_stairs 7 
setblock ~38 ~7 ~79 oak_stairs 6  
fill ~38 ~7 ~81 ~42 ~7 ~81 planks 0  
fill ~39 ~7 ~22 ~45 ~7 ~22 planks 0  
fill ~39 ~7 ~29 ~39 ~8 ~29 planks 0  
fill ~39 ~7 ~30 ~44 ~7 ~30 planks 0  
fill ~39 ~7 ~72 ~44 ~7 ~72 planks 0  
fill ~39 ~7 ~73 ~39 ~8 ~73 planks 0  
fill ~39 ~7 ~80 ~45 ~7 ~80 planks 0  
fill ~40 ~7 ~28 ~40 ~8 ~28 planks 0  
fill ~40 ~7 ~29 ~40 ~8 ~29 log 0 
setblock ~40 ~7 ~39 oak_stairs 5 
setblock ~40 ~7 ~63 oak_stairs 5  
fill ~40 ~7 ~73 ~40 ~8 ~73 log 0  
fill ~40 ~7 ~74 ~40 ~8 ~74 planks 0 
setblock ~41 ~7 ~18 oak_stairs 6  
fill ~41 ~7 ~29 ~43 ~7 ~29 oak_stairs 2  
fill ~41 ~7 ~73 ~43 ~7 ~73 oak_stairs 3 
setblock ~41 ~7 ~84 oak_stairs 7 
setblock ~43 ~7 ~39 oak_stairs 4 
setblock ~43 ~7 ~63 oak_stairs 4  
fill ~44 ~7 ~23 ~45 ~7 ~23 planks 0 
setblock ~44 ~7 ~24 oak_stairs 4  
fill ~44 ~7 ~25 ~45 ~7 ~25 planks 0  
fill ~44 ~7 ~29 ~44 ~8 ~29 log 0  
fill ~44 ~7 ~73 ~44 ~8 ~73 log 0  
fill ~44 ~7 ~77 ~45 ~7 ~77 planks 0 
setblock ~44 ~7 ~78 oak_stairs 4  
fill ~44 ~7 ~79 ~45 ~7 ~79 planks 0  
fill ~45 ~7 ~24 ~46 ~7 ~24 log 4  
fill ~45 ~7 ~27 ~45 ~1 ~27 log 0  
fill ~45 ~7 ~29 ~45 ~8 ~29 planks 0  
fill ~45 ~7 ~30 ~46 ~7 ~30 log 4  
fill ~45 ~7 ~31 ~45 ~8 ~31 planks 0  
fill ~45 ~7 ~33 ~45 ~1 ~33 log 0  
fill ~45 ~7 ~35 ~45 ~8 ~35 planks 0  
fill ~45 ~7 ~36 ~46 ~7 ~36 log 4  
fill ~45 ~7 ~37 ~45 ~8 ~37 planks 0  
fill ~45 ~7 ~39 ~45 ~1 ~39 log 0  
fill ~45 ~7 ~63 ~45 ~1 ~63 log 0  
fill ~45 ~7 ~65 ~45 ~8 ~65 planks 0  
fill ~45 ~7 ~66 ~46 ~7 ~66 log 4  
fill ~45 ~7 ~67 ~45 ~8 ~67 planks 0  
fill ~45 ~7 ~69 ~45 ~1 ~69 log 0  
fill ~45 ~7 ~71 ~45 ~8 ~71 planks 0  
fill ~45 ~7 ~72 ~46 ~7 ~72 log 4  
fill ~45 ~7 ~73 ~45 ~8 ~73 planks 0  
fill ~45 ~7 ~75 ~45 ~1 ~75 log 0  
fill ~45 ~7 ~78 ~46 ~7 ~78 log 4  
fill ~46 ~7 ~22 ~47 ~7 ~22 oak_stairs 7  
fill ~46 ~7 ~26 ~47 ~7 ~26 oak_stairs 6  
fill ~46 ~7 ~27 ~47 ~7 ~27 log 4  
fill ~46 ~7 ~28 ~47 ~7 ~28 oak_stairs 7  
fill ~46 ~7 ~32 ~48 ~7 ~32 oak_stairs 6  
fill ~46 ~7 ~33 ~47 ~7 ~33 log 4  
fill ~46 ~7 ~34 ~47 ~7 ~34 oak_stairs 7  
fill ~46 ~7 ~38 ~47 ~7 ~38 oak_stairs 6  
fill ~46 ~7 ~39 ~47 ~7 ~39 log 4  
fill ~46 ~7 ~41 ~49 ~7 ~41 planks 0  
fill ~46 ~7 ~61 ~49 ~7 ~61 planks 0  
fill ~46 ~7 ~63 ~47 ~7 ~63 log 4  
fill ~46 ~7 ~64 ~47 ~7 ~64 oak_stairs 7  
fill ~46 ~7 ~68 ~47 ~7 ~68 oak_stairs 6  
fill ~46 ~7 ~69 ~47 ~7 ~69 log 4  
fill ~46 ~7 ~70 ~48 ~7 ~70 oak_stairs 7  
fill ~46 ~7 ~74 ~47 ~7 ~74 oak_stairs 6  
fill ~46 ~7 ~75 ~47 ~7 ~75 log 4  
fill ~46 ~7 ~76 ~47 ~7 ~76 oak_stairs 7  
fill ~46 ~7 ~80 ~47 ~7 ~80 oak_stairs 6 
setblock ~47 ~7 ~18 oak_stairs 6  
fill ~47 ~7 ~21 ~47 ~8 ~21 log 4  
fill ~47 ~7 ~81 ~47 ~8 ~81 log 4 
setblock ~47 ~7 ~84 oak_stairs 7 
setblock ~48 ~7 ~19 planks 0  
fill ~48 ~7 ~21 ~48 ~7 ~22 oak_stairs 5  
fill ~48 ~7 ~26 ~48 ~7 ~28 oak_stairs 5  
fill ~48 ~7 ~33 ~48 ~7 ~34 oak_stairs 5  
fill ~48 ~7 ~38 ~48 ~7 ~40 oak_stairs 5  
fill ~48 ~7 ~62 ~48 ~7 ~64 oak_stairs 5  
fill ~48 ~7 ~68 ~48 ~7 ~69 oak_stairs 5  
fill ~48 ~7 ~74 ~48 ~7 ~76 oak_stairs 5  
fill ~48 ~7 ~80 ~48 ~7 ~81 oak_stairs 5 
setblock ~48 ~7 ~83 planks 0 
setblock ~49 ~7 ~20 oak_stairs 5 
setblock ~49 ~7 ~82 oak_stairs 5 
setblock ~50 ~7 ~41 log 8 
setblock ~50 ~7 ~61 log 8  
fill ~51 ~7 ~41 ~51 ~16 ~41 planks 0  
fill ~51 ~7 ~61 ~51 ~16 ~61 planks 0  
fill ~52 ~7 ~38 ~54 ~7 ~38 oak_stairs 6  
fill ~52 ~7 ~39 ~52 ~7 ~40 oak_stairs 4  
fill ~52 ~7 ~62 ~52 ~7 ~63 oak_stairs 4  
fill ~52 ~7 ~64 ~54 ~7 ~64 oak_stairs 7  
fill ~53 ~7 ~47 ~54 ~7 ~47 log 0  
fill ~53 ~7 ~55 ~54 ~7 ~55 log 0 
setblock ~54 ~7 ~39 oak_stairs 5  
fill ~54 ~7 ~40 ~56 ~7 ~40 oak_stairs 6 
setblock ~54 ~7 ~42 planks 0 
setblock ~54 ~7 ~46 planks 0 
setblock ~54 ~7 ~56 planks 0 
setblock ~54 ~7 ~60 planks 0  
fill ~54 ~7 ~62 ~56 ~7 ~62 oak_stairs 7 
setblock ~54 ~7 ~63 oak_stairs 5  
fill ~55 ~7 ~42 ~56 ~7 ~42 oak_stairs 7  
fill ~55 ~7 ~46 ~56 ~7 ~46 oak_stairs 6  
fill ~55 ~7 ~48 ~56 ~7 ~48 oak_stairs 7  
fill ~55 ~7 ~54 ~56 ~7 ~54 oak_stairs 6  
fill ~55 ~7 ~56 ~56 ~7 ~56 oak_stairs 7  
fill ~55 ~7 ~60 ~56 ~7 ~60 oak_stairs 6 
setblock ~56 ~7 ~41 oak_stairs 5 
setblock ~56 ~7 ~47 oak_stairs 5 
setblock ~56 ~7 ~55 oak_stairs 5 
setblock ~56 ~7 ~61 oak_stairs 5 
setblock ~13 ~8 ~41 fence 0 
setblock ~13 ~8 ~47 fence 0 
setblock ~13 ~8 ~55 fence 0 
setblock ~13 ~8 ~61 fence 0 
setblock ~15 ~8 ~40 wooden_slab 0  
fill ~15 ~8 ~42 ~15 ~13 ~42 fence 0  
fill ~15 ~8 ~46 ~15 ~13 ~46 fence 0  
fill ~15 ~8 ~47 ~15 ~32 ~47 log 0  
fill ~15 ~8 ~55 ~15 ~32 ~55 log 0  
fill ~15 ~8 ~56 ~15 ~13 ~56 fence 0  
fill ~15 ~8 ~60 ~15 ~13 ~60 fence 0 
setblock ~15 ~8 ~62 wooden_slab 0  
fill ~16 ~8 ~43 ~53 ~8 ~43 planks 0  
fill ~16 ~8 ~45 ~31 ~8 ~45 planks 0  
fill ~16 ~8 ~47 ~22 ~8 ~47 planks 0  
fill ~16 ~8 ~55 ~22 ~8 ~55 planks 0  
fill ~16 ~8 ~57 ~31 ~8 ~57 planks 0  
fill ~16 ~8 ~59 ~53 ~8 ~59 planks 0  
fill ~17 ~8 ~38 ~17 ~8 ~39 wooden_slab 0 
setblock ~17 ~8 ~40 planks 0  
fill ~17 ~8 ~42 ~53 ~8 ~42 planks 0  
fill ~17 ~8 ~44 ~31 ~8 ~44 planks 0  
fill ~17 ~8 ~46 ~31 ~8 ~46 planks 0  
fill ~17 ~8 ~56 ~31 ~8 ~56 planks 0  
fill ~17 ~8 ~58 ~31 ~8 ~58 planks 0  
fill ~17 ~8 ~60 ~53 ~8 ~60 planks 0 
setblock ~17 ~8 ~62 planks 0  
fill ~17 ~8 ~63 ~17 ~8 ~64 wooden_slab 0 
setblock ~18 ~8 ~38 wooden_slab 8  
fill ~18 ~8 ~39 ~18 ~8 ~40 double_wooden_slab 0  
fill ~18 ~8 ~62 ~18 ~8 ~63 double_wooden_slab 0 
setblock ~18 ~8 ~64 wooden_slab 8  
fill ~19 ~8 ~39 ~19 ~8 ~40 wooden_slab 8  
fill ~19 ~8 ~41 ~52 ~8 ~41 planks 0  
fill ~19 ~8 ~61 ~52 ~8 ~61 planks 0  
fill ~19 ~8 ~62 ~19 ~8 ~63 wooden_slab 8 
setblock ~20 ~8 ~21 wooden_slab 8 
setblock ~20 ~8 ~27 wooden_slab 8 
setblock ~20 ~8 ~33 wooden_slab 8 
setblock ~20 ~8 ~38 wooden_slab 8  
fill ~20 ~8 ~39 ~20 ~8 ~40 double_wooden_slab 0  
fill ~20 ~8 ~62 ~20 ~8 ~63 double_wooden_slab 0 
setblock ~20 ~8 ~64 wooden_slab 8 
setblock ~20 ~8 ~69 wooden_slab 8 
setblock ~20 ~8 ~75 wooden_slab 8 
setblock ~20 ~8 ~81 wooden_slab 8  
fill ~21 ~8 ~20 ~21 ~8 ~22 log 4 
setblock ~21 ~8 ~23 wooden_slab 8 
setblock ~21 ~8 ~25 wooden_slab 8  
fill ~21 ~8 ~26 ~21 ~8 ~28 log 4 
setblock ~21 ~8 ~29 wooden_slab 8 
setblock ~21 ~8 ~31 wooden_slab 8  
fill ~21 ~8 ~32 ~21 ~8 ~34 log 4 
setblock ~21 ~8 ~35 wooden_slab 8 
setblock ~21 ~8 ~37 wooden_slab 8 
setblock ~21 ~8 ~38 log 0  
fill ~21 ~8 ~39 ~22 ~8 ~39 log 4  
fill ~21 ~8 ~40 ~21 ~14 ~40 planks 0  
fill ~21 ~8 ~62 ~21 ~14 ~62 planks 0  
fill ~21 ~8 ~63 ~22 ~8 ~63 log 4 
setblock ~21 ~8 ~64 log 0 
setblock ~21 ~8 ~65 wooden_slab 8 
setblock ~21 ~8 ~67 wooden_slab 8  
fill ~21 ~8 ~68 ~21 ~8 ~70 log 4 
setblock ~21 ~8 ~71 wooden_slab 8 
setblock ~21 ~8 ~73 wooden_slab 8  
fill ~21 ~8 ~74 ~21 ~8 ~76 log 4 
setblock ~21 ~8 ~77 wooden_slab 8 
setblock ~21 ~8 ~79 wooden_slab 8  
fill ~21 ~8 ~80 ~21 ~8 ~82 log 4 
setblock ~22 ~8 ~19 log 8  
fill ~22 ~8 ~22 ~23 ~8 ~22 double_wooden_slab 0  
fill ~22 ~8 ~23 ~23 ~8 ~23 double_wooden_slab 0  
fill ~22 ~8 ~24 ~23 ~8 ~24 wooden_slab 8  
fill ~22 ~8 ~25 ~23 ~8 ~25 double_wooden_slab 0  
fill ~22 ~8 ~26 ~23 ~8 ~26 double_wooden_slab 0  
fill ~22 ~8 ~27 ~22 ~7 ~27 log 4  
fill ~22 ~8 ~28 ~23 ~8 ~28 double_wooden_slab 0  
fill ~22 ~8 ~29 ~23 ~8 ~29 double_wooden_slab 0  
fill ~22 ~8 ~30 ~23 ~8 ~30 wooden_slab 8  
fill ~22 ~8 ~31 ~23 ~8 ~31 double_wooden_slab 0  
fill ~22 ~8 ~32 ~23 ~8 ~32 double_wooden_slab 0  
fill ~22 ~8 ~33 ~22 ~7 ~33 log 4  
fill ~22 ~8 ~34 ~23 ~8 ~34 double_wooden_slab 0  
fill ~22 ~8 ~35 ~23 ~8 ~35 double_wooden_slab 0  
fill ~22 ~8 ~36 ~23 ~8 ~36 wooden_slab 8  
fill ~22 ~8 ~37 ~23 ~8 ~37 double_wooden_slab 0  
fill ~22 ~8 ~38 ~23 ~8 ~38 double_wooden_slab 0  
fill ~22 ~8 ~64 ~23 ~8 ~64 double_wooden_slab 0  
fill ~22 ~8 ~65 ~23 ~8 ~65 double_wooden_slab 0  
fill ~22 ~8 ~66 ~23 ~8 ~66 wooden_slab 8  
fill ~22 ~8 ~67 ~23 ~8 ~67 double_wooden_slab 0  
fill ~22 ~8 ~68 ~23 ~8 ~68 double_wooden_slab 0  
fill ~22 ~8 ~69 ~22 ~7 ~69 log 4  
fill ~22 ~8 ~70 ~23 ~8 ~70 double_wooden_slab 0  
fill ~22 ~8 ~71 ~23 ~8 ~71 double_wooden_slab 0  
fill ~22 ~8 ~72 ~23 ~8 ~72 wooden_slab 8  
fill ~22 ~8 ~73 ~23 ~8 ~73 double_wooden_slab 0  
fill ~22 ~8 ~74 ~23 ~8 ~74 double_wooden_slab 0  
fill ~22 ~8 ~75 ~22 ~7 ~75 log 4  
fill ~22 ~8 ~76 ~23 ~8 ~76 double_wooden_slab 0  
fill ~22 ~8 ~77 ~23 ~8 ~77 double_wooden_slab 0  
fill ~22 ~8 ~78 ~23 ~8 ~78 wooden_slab 8  
fill ~22 ~8 ~79 ~23 ~8 ~79 double_wooden_slab 0  
fill ~22 ~8 ~80 ~23 ~8 ~80 double_wooden_slab 0 
setblock ~22 ~8 ~83 log 8 
setblock ~23 ~8 ~27 double_wooden_slab 0 
setblock ~23 ~8 ~33 double_wooden_slab 0  
fill ~23 ~8 ~39 ~30 ~8 ~39 planks 0  
fill ~23 ~8 ~40 ~23 ~8 ~39 planks 0  
fill ~23 ~8 ~62 ~23 ~8 ~63 planks 0 
setblock ~23 ~8 ~69 double_wooden_slab 0 
setblock ~23 ~8 ~75 double_wooden_slab 0 
setblock ~24 ~8 ~21 oak_stairs 5  
fill ~24 ~8 ~22 ~31 ~8 ~22 planks 0  
fill ~24 ~8 ~23 ~31 ~8 ~23 planks 0  
fill ~24 ~8 ~24 ~31 ~8 ~24 planks 0  
fill ~24 ~8 ~25 ~31 ~8 ~25 planks 0 
setblock ~24 ~8 ~27 planks 0  
fill ~24 ~8 ~30 ~25 ~8 ~30 planks 0  
fill ~24 ~8 ~33 ~30 ~8 ~33 planks 0  
fill ~24 ~8 ~36 ~31 ~8 ~36 planks 0  
fill ~24 ~8 ~47 ~30 ~8 ~47 planks 0  
fill ~24 ~8 ~55 ~30 ~8 ~55 planks 0 
setblock ~24 ~8 ~63 planks 0  
fill ~24 ~8 ~66 ~31 ~8 ~66 planks 0  
fill ~24 ~8 ~69 ~30 ~8 ~69 planks 0  
fill ~24 ~8 ~72 ~25 ~8 ~72 planks 0 
setblock ~24 ~8 ~75 planks 0  
fill ~24 ~8 ~77 ~31 ~8 ~77 planks 0  
fill ~24 ~8 ~78 ~31 ~8 ~78 planks 0  
fill ~24 ~8 ~79 ~31 ~8 ~79 planks 0  
fill ~24 ~8 ~80 ~31 ~8 ~80 planks 0 
setblock ~24 ~8 ~81 oak_stairs 5  
fill ~25 ~8 ~31 ~31 ~8 ~31 planks 0  
fill ~25 ~8 ~32 ~31 ~8 ~32 planks 0  
fill ~25 ~8 ~34 ~31 ~8 ~34 planks 0  
fill ~25 ~8 ~35 ~31 ~8 ~35 planks 0  
fill ~25 ~8 ~37 ~31 ~8 ~37 planks 0  
fill ~25 ~8 ~38 ~31 ~8 ~38 planks 0  
fill ~25 ~8 ~40 ~46 ~8 ~40 planks 0  
fill ~25 ~8 ~62 ~46 ~8 ~62 planks 0  
fill ~25 ~8 ~64 ~31 ~8 ~64 planks 0  
fill ~25 ~8 ~65 ~31 ~8 ~65 planks 0  
fill ~25 ~8 ~67 ~31 ~8 ~67 planks 0  
fill ~25 ~8 ~68 ~31 ~8 ~68 planks 0  
fill ~25 ~8 ~70 ~31 ~8 ~70 planks 0  
fill ~25 ~8 ~71 ~31 ~8 ~71 planks 0 
setblock ~26 ~8 ~21 oak_stairs 4  
fill ~26 ~8 ~30 ~28 ~8 ~30 oak_stairs 2  
fill ~26 ~8 ~63 ~30 ~8 ~63 planks 0  
fill ~26 ~8 ~72 ~28 ~8 ~72 oak_stairs 3 
setblock ~26 ~8 ~81 oak_stairs 4  
fill ~27 ~8 ~21 ~31 ~8 ~21 planks 0  
fill ~27 ~8 ~81 ~31 ~8 ~81 planks 0 
setblock ~28 ~8 ~19 log 8 
setblock ~28 ~8 ~83 log 8  
fill ~29 ~8 ~28 ~31 ~8 ~28 planks 0  
fill ~29 ~8 ~30 ~31 ~8 ~30 planks 0  
fill ~29 ~8 ~72 ~31 ~8 ~72 planks 0  
fill ~29 ~8 ~74 ~31 ~8 ~74 planks 0  
fill ~30 ~8 ~26 ~31 ~8 ~26 planks 0  
fill ~30 ~8 ~76 ~31 ~8 ~76 planks 0 
setblock ~31 ~8 ~19 double_wooden_slab 0 
setblock ~31 ~8 ~29 planks 0 
setblock ~31 ~8 ~73 planks 0 
setblock ~31 ~8 ~83 double_wooden_slab 0 
setblock ~32 ~8 ~27 planks 0 
setblock ~32 ~8 ~33 planks 0  
fill ~32 ~8 ~39 ~37 ~8 ~39 planks 0  
fill ~32 ~8 ~63 ~37 ~8 ~63 planks 0 
setblock ~32 ~8 ~69 planks 0 
setblock ~32 ~8 ~75 planks 0 
setblock ~33 ~8 ~27 oak_stairs 5 
setblock ~33 ~8 ~33 oak_stairs 5 
setblock ~33 ~8 ~69 oak_stairs 5 
setblock ~33 ~8 ~75 oak_stairs 5 
setblock ~36 ~8 ~27 oak_stairs 4 
setblock ~36 ~8 ~33 oak_stairs 4 
setblock ~36 ~8 ~69 oak_stairs 4 
setblock ~36 ~8 ~75 oak_stairs 4 
setblock ~37 ~8 ~27 planks 0 
setblock ~37 ~8 ~33 planks 0 
setblock ~37 ~8 ~69 planks 0 
setblock ~37 ~8 ~75 planks 0 
setblock ~38 ~8 ~19 double_wooden_slab 0  
fill ~38 ~8 ~21 ~42 ~8 ~21 planks 0  
fill ~38 ~8 ~23 ~45 ~8 ~23 planks 0  
fill ~38 ~8 ~24 ~45 ~8 ~24 planks 0  
fill ~38 ~8 ~25 ~45 ~8 ~25 planks 0  
fill ~38 ~8 ~29 ~38 ~8 ~32 planks 0  
fill ~38 ~8 ~35 ~45 ~8 ~35 planks 0  
fill ~38 ~8 ~36 ~45 ~8 ~36 planks 0  
fill ~38 ~8 ~37 ~45 ~8 ~37 planks 0  
fill ~38 ~8 ~44 ~53 ~8 ~44 planks 0  
fill ~38 ~8 ~45 ~53 ~8 ~45 planks 0  
fill ~38 ~8 ~57 ~53 ~8 ~57 planks 0  
fill ~38 ~8 ~58 ~53 ~8 ~58 planks 0  
fill ~38 ~8 ~65 ~45 ~8 ~65 planks 0  
fill ~38 ~8 ~66 ~45 ~8 ~66 planks 0  
fill ~38 ~8 ~67 ~45 ~8 ~67 planks 0  
fill ~38 ~8 ~71 ~45 ~8 ~71 planks 0  
fill ~38 ~8 ~72 ~40 ~8 ~72 planks 0  
fill ~38 ~8 ~73 ~38 ~8 ~70 planks 0  
fill ~38 ~8 ~77 ~45 ~8 ~77 planks 0  
fill ~38 ~8 ~78 ~45 ~8 ~78 planks 0  
fill ~38 ~8 ~79 ~45 ~8 ~79 planks 0  
fill ~38 ~8 ~81 ~42 ~8 ~81 planks 0 
setblock ~38 ~8 ~83 double_wooden_slab 0  
fill ~39 ~8 ~22 ~45 ~8 ~22 planks 0  
fill ~39 ~8 ~27 ~39 ~8 ~47 planks 0  
fill ~39 ~8 ~55 ~45 ~8 ~55 planks 0  
fill ~39 ~8 ~56 ~53 ~8 ~56 planks 0  
fill ~39 ~8 ~64 ~45 ~8 ~64 planks 0  
fill ~39 ~8 ~68 ~45 ~8 ~68 planks 0  
fill ~39 ~8 ~69 ~45 ~8 ~69 planks 0  
fill ~39 ~8 ~70 ~45 ~8 ~70 planks 0  
fill ~39 ~8 ~74 ~39 ~8 ~81 planks 0  
fill ~40 ~8 ~30 ~40 ~8 ~47 planks 0  
fill ~40 ~8 ~63 ~46 ~8 ~63 planks 0  
fill ~40 ~8 ~80 ~45 ~8 ~80 planks 0 
setblock ~41 ~8 ~19 log 8  
fill ~41 ~8 ~30 ~43 ~8 ~30 oak_stairs 2  
fill ~41 ~8 ~31 ~45 ~8 ~31 planks 0  
fill ~41 ~8 ~32 ~45 ~8 ~32 planks 0  
fill ~41 ~8 ~33 ~45 ~8 ~33 planks 0  
fill ~41 ~8 ~34 ~45 ~8 ~34 planks 0  
fill ~41 ~8 ~38 ~45 ~8 ~38 planks 0  
fill ~41 ~8 ~39 ~46 ~8 ~39 planks 0  
fill ~41 ~8 ~46 ~53 ~8 ~46 planks 0  
fill ~41 ~8 ~47 ~45 ~8 ~47 planks 0  
fill ~41 ~8 ~72 ~43 ~8 ~72 oak_stairs 3 
setblock ~41 ~8 ~83 log 8 
setblock ~43 ~8 ~21 oak_stairs 5 
setblock ~43 ~8 ~81 oak_stairs 5  
fill ~44 ~8 ~30 ~46 ~8 ~30 planks 0  
fill ~44 ~8 ~72 ~46 ~8 ~72 planks 0 
setblock ~45 ~8 ~21 oak_stairs 4 
setblock ~45 ~8 ~27 planks 0 
setblock ~45 ~8 ~75 planks 0 
setblock ~45 ~8 ~81 oak_stairs 4  
fill ~46 ~8 ~22 ~47 ~8 ~22 double_wooden_slab 0  
fill ~46 ~8 ~23 ~47 ~8 ~23 double_wooden_slab 0  
fill ~46 ~8 ~24 ~47 ~8 ~24 wooden_slab 8  
fill ~46 ~8 ~25 ~47 ~8 ~25 double_wooden_slab 0  
fill ~46 ~8 ~26 ~47 ~8 ~26 double_wooden_slab 0  
fill ~46 ~8 ~27 ~46 ~8 ~28 double_wooden_slab 0 
setblock ~46 ~8 ~29 planks 0  
fill ~46 ~8 ~31 ~47 ~8 ~31 double_wooden_slab 0  
fill ~46 ~8 ~32 ~47 ~8 ~32 double_wooden_slab 0  
fill ~46 ~8 ~33 ~46 ~8 ~35 double_wooden_slab 0  
fill ~46 ~8 ~36 ~47 ~8 ~36 wooden_slab 8  
fill ~46 ~8 ~37 ~47 ~8 ~37 double_wooden_slab 0  
fill ~46 ~8 ~38 ~47 ~8 ~38 double_wooden_slab 0  
fill ~46 ~8 ~64 ~47 ~8 ~64 double_wooden_slab 0  
fill ~46 ~8 ~65 ~47 ~8 ~65 double_wooden_slab 0  
fill ~46 ~8 ~66 ~47 ~8 ~66 wooden_slab 8  
fill ~46 ~8 ~67 ~47 ~8 ~67 double_wooden_slab 0  
fill ~46 ~8 ~68 ~47 ~8 ~68 double_wooden_slab 0  
fill ~46 ~8 ~69 ~46 ~8 ~71 double_wooden_slab 0 
setblock ~46 ~8 ~73 planks 0  
fill ~46 ~8 ~74 ~47 ~8 ~74 double_wooden_slab 0  
fill ~46 ~8 ~75 ~46 ~8 ~77 double_wooden_slab 0  
fill ~46 ~8 ~78 ~47 ~8 ~78 wooden_slab 8  
fill ~46 ~8 ~79 ~47 ~8 ~79 double_wooden_slab 0  
fill ~46 ~8 ~80 ~47 ~8 ~80 double_wooden_slab 0 
setblock ~47 ~8 ~19 log 8  
fill ~47 ~8 ~27 ~48 ~8 ~27 log 4  
fill ~47 ~8 ~28 ~47 ~8 ~29 double_wooden_slab 0 
setblock ~47 ~8 ~30 wooden_slab 8  
fill ~47 ~8 ~33 ~48 ~8 ~33 log 4  
fill ~47 ~8 ~34 ~47 ~8 ~35 double_wooden_slab 0  
fill ~47 ~8 ~39 ~48 ~8 ~39 log 4  
fill ~47 ~8 ~47 ~53 ~8 ~47 planks 0  
fill ~47 ~8 ~55 ~53 ~8 ~55 planks 0  
fill ~47 ~8 ~63 ~48 ~8 ~63 log 4  
fill ~47 ~8 ~69 ~48 ~8 ~69 log 4  
fill ~47 ~8 ~70 ~47 ~8 ~71 double_wooden_slab 0 
setblock ~47 ~8 ~72 wooden_slab 8 
setblock ~47 ~8 ~73 double_wooden_slab 0  
fill ~47 ~8 ~75 ~48 ~8 ~75 log 4  
fill ~47 ~8 ~76 ~47 ~8 ~77 double_wooden_slab 0 
setblock ~47 ~8 ~83 log 8  
fill ~48 ~8 ~20 ~48 ~8 ~22 log 4 
setblock ~48 ~8 ~23 wooden_slab 8 
setblock ~48 ~8 ~25 wooden_slab 8 
setblock ~48 ~8 ~26 log 4 
setblock ~48 ~8 ~28 log 4 
setblock ~48 ~8 ~29 wooden_slab 8 
setblock ~48 ~8 ~31 wooden_slab 8 
setblock ~48 ~8 ~32 log 4 
setblock ~48 ~8 ~34 log 4 
setblock ~48 ~8 ~35 wooden_slab 8 
setblock ~48 ~8 ~37 wooden_slab 8 
setblock ~48 ~8 ~38 log 0  
fill ~48 ~8 ~40 ~48 ~14 ~40 planks 0  
fill ~48 ~8 ~62 ~48 ~14 ~62 planks 0 
setblock ~48 ~8 ~64 log 0 
setblock ~48 ~8 ~65 wooden_slab 8 
setblock ~48 ~8 ~67 wooden_slab 8 
setblock ~48 ~8 ~68 log 4 
setblock ~48 ~8 ~70 log 4 
setblock ~48 ~8 ~71 wooden_slab 8 
setblock ~48 ~8 ~73 wooden_slab 8 
setblock ~48 ~8 ~74 log 4 
setblock ~48 ~8 ~76 log 4 
setblock ~48 ~8 ~77 wooden_slab 8 
setblock ~48 ~8 ~79 wooden_slab 8  
fill ~48 ~8 ~80 ~48 ~8 ~82 log 4 
setblock ~49 ~8 ~21 wooden_slab 8 
setblock ~49 ~8 ~27 wooden_slab 8 
setblock ~49 ~8 ~33 wooden_slab 8 
setblock ~49 ~8 ~38 wooden_slab 8  
fill ~49 ~8 ~39 ~49 ~8 ~40 double_wooden_slab 0  
fill ~49 ~8 ~62 ~49 ~8 ~63 double_wooden_slab 0 
setblock ~49 ~8 ~64 wooden_slab 8 
setblock ~49 ~8 ~69 wooden_slab 8 
setblock ~49 ~8 ~75 wooden_slab 8 
setblock ~49 ~8 ~81 wooden_slab 8  
fill ~50 ~8 ~39 ~50 ~8 ~40 wooden_slab 8  
fill ~50 ~8 ~62 ~50 ~8 ~63 wooden_slab 8 
setblock ~51 ~8 ~38 wooden_slab 8  
fill ~51 ~8 ~39 ~51 ~8 ~40 double_wooden_slab 0  
fill ~51 ~8 ~62 ~51 ~8 ~63 double_wooden_slab 0 
setblock ~51 ~8 ~64 wooden_slab 8  
fill ~52 ~8 ~38 ~52 ~8 ~39 wooden_slab 0 
setblock ~52 ~8 ~40 planks 0 
setblock ~52 ~8 ~62 planks 0  
fill ~52 ~8 ~63 ~52 ~8 ~64 wooden_slab 0 
setblock ~54 ~8 ~40 wooden_slab 0  
fill ~54 ~8 ~42 ~54 ~13 ~42 fence 0  
fill ~54 ~8 ~46 ~54 ~13 ~46 fence 0  
fill ~54 ~8 ~47 ~54 ~32 ~47 log 0  
fill ~54 ~8 ~55 ~54 ~32 ~55 log 0  
fill ~54 ~8 ~56 ~54 ~13 ~56 fence 0  
fill ~54 ~8 ~60 ~54 ~13 ~60 fence 0 
setblock ~54 ~8 ~62 wooden_slab 0 
setblock ~56 ~8 ~41 fence 0 
setblock ~56 ~8 ~47 fence 0 
setblock ~56 ~8 ~55 fence 0 
setblock ~56 ~8 ~61 fence 0  
fill ~14 ~9 ~41 ~14 ~12 ~41 cobblestone_wall 0  
fill ~14 ~9 ~47 ~14 ~12 ~47 cobblestone_wall 0  
fill ~14 ~9 ~55 ~14 ~12 ~55 cobblestone_wall 0  
fill ~14 ~9 ~61 ~14 ~12 ~61 cobblestone_wall 0 
setblock ~15 ~9 ~49 stone_slab 8 
setblock ~15 ~9 ~50 double_stone_slab 0 
setblock ~15 ~9 ~51 stone_slab 8 
setblock ~15 ~9 ~52 double_stone_slab 0 
setblock ~15 ~9 ~53 stone_slab 8  
fill ~16 ~9 ~39 ~16 ~12 ~39 cobblestone_wall 0  
fill ~16 ~9 ~43 ~16 ~12 ~43 glass 0  
fill ~16 ~9 ~45 ~16 ~12 ~45 glass 0  
fill ~16 ~9 ~47 ~16 ~14 ~47 log 0  
fill ~16 ~9 ~55 ~16 ~14 ~55 log 0  
fill ~16 ~9 ~57 ~16 ~12 ~57 glass 0  
fill ~16 ~9 ~59 ~16 ~12 ~59 glass 0  
fill ~16 ~9 ~63 ~16 ~12 ~63 cobblestone_wall 0  
fill ~17 ~9 ~42 ~17 ~13 ~42 fence 0  
fill ~17 ~9 ~44 ~17 ~11 ~44 fence 0  
fill ~17 ~9 ~46 ~17 ~13 ~46 fence 0  
fill ~17 ~9 ~47 ~22 ~9 ~47 fence 0  
fill ~17 ~9 ~55 ~22 ~9 ~55 fence 0  
fill ~17 ~9 ~56 ~17 ~13 ~56 fence 0  
fill ~17 ~9 ~58 ~17 ~11 ~58 fence 0  
fill ~17 ~9 ~60 ~17 ~13 ~60 fence 0  
fill ~19 ~9 ~38 ~19 ~9 ~39 wooden_slab 0  
fill ~19 ~9 ~41 ~20 ~9 ~41 planks 0  
fill ~19 ~9 ~61 ~20 ~9 ~61 planks 0  
fill ~19 ~9 ~63 ~19 ~9 ~64 wooden_slab 0  
fill ~20 ~9 ~21 ~20 ~12 ~21 cobblestone_wall 0  
fill ~20 ~9 ~27 ~20 ~12 ~27 cobblestone_wall 0  
fill ~20 ~9 ~33 ~20 ~12 ~33 cobblestone_wall 0  
fill ~20 ~9 ~39 ~20 ~12 ~39 cobblestone_wall 0  
fill ~20 ~9 ~63 ~20 ~12 ~63 cobblestone_wall 0  
fill ~20 ~9 ~69 ~20 ~12 ~69 cobblestone_wall 0  
fill ~20 ~9 ~75 ~20 ~12 ~75 cobblestone_wall 0  
fill ~20 ~9 ~81 ~20 ~12 ~81 cobblestone_wall 0  
fill ~21 ~9 ~21 ~22 ~9 ~21 log 0  
fill ~21 ~9 ~22 ~21 ~13 ~22 fence 0 
setblock ~21 ~9 ~24 wooden_slab 0  
fill ~21 ~9 ~26 ~21 ~13 ~26 fence 0  
fill ~21 ~9 ~27 ~22 ~9 ~27 log 0  
fill ~21 ~9 ~28 ~21 ~13 ~28 fence 0 
setblock ~21 ~9 ~30 wooden_slab 0  
fill ~21 ~9 ~32 ~21 ~13 ~32 fence 0  
fill ~21 ~9 ~33 ~22 ~9 ~33 log 0  
fill ~21 ~9 ~34 ~21 ~13 ~34 fence 0 
setblock ~21 ~9 ~36 wooden_slab 0  
fill ~21 ~9 ~38 ~21 ~13 ~38 fence 0  
fill ~21 ~9 ~39 ~22 ~9 ~39 log 0  
fill ~21 ~9 ~41 ~21 ~22 ~41 log 0  
fill ~21 ~9 ~61 ~21 ~22 ~61 log 0  
fill ~21 ~9 ~63 ~22 ~9 ~63 log 0  
fill ~21 ~9 ~64 ~21 ~13 ~64 fence 0 
setblock ~21 ~9 ~66 wooden_slab 0  
fill ~21 ~9 ~68 ~21 ~13 ~68 fence 0  
fill ~21 ~9 ~69 ~22 ~9 ~69 log 0  
fill ~21 ~9 ~70 ~21 ~13 ~70 fence 0 
setblock ~21 ~9 ~72 wooden_slab 0  
fill ~21 ~9 ~74 ~21 ~13 ~74 fence 0  
fill ~21 ~9 ~75 ~22 ~9 ~75 log 0  
fill ~21 ~9 ~76 ~21 ~13 ~76 fence 0 
setblock ~21 ~9 ~78 wooden_slab 0  
fill ~21 ~9 ~80 ~21 ~13 ~80 fence 0  
fill ~21 ~9 ~81 ~22 ~9 ~81 log 0  
fill ~22 ~9 ~19 ~22 ~16 ~19 cobblestone_wall 0  
fill ~22 ~9 ~22 ~22 ~15 ~22 planks 0  
fill ~22 ~9 ~23 ~22 ~9 ~26 planks 0  
fill ~22 ~9 ~28 ~22 ~15 ~28 planks 0  
fill ~22 ~9 ~29 ~22 ~9 ~32 planks 0  
fill ~22 ~9 ~34 ~22 ~15 ~34 planks 0  
fill ~22 ~9 ~35 ~22 ~9 ~38 planks 0  
fill ~22 ~9 ~40 ~22 ~23 ~40 stonebrick 0  
fill ~22 ~9 ~62 ~22 ~23 ~62 stonebrick 0  
fill ~22 ~9 ~64 ~22 ~15 ~64 planks 0  
fill ~22 ~9 ~65 ~22 ~9 ~68 planks 0  
fill ~22 ~9 ~70 ~22 ~15 ~70 planks 0  
fill ~22 ~9 ~71 ~22 ~9 ~74 planks 0  
fill ~22 ~9 ~76 ~22 ~15 ~76 planks 0  
fill ~22 ~9 ~77 ~22 ~9 ~80 planks 0  
fill ~22 ~9 ~83 ~22 ~16 ~83 cobblestone_wall 0 
setblock ~23 ~9 ~20 double_wooden_slab 0 
setblock ~23 ~9 ~82 double_wooden_slab 0  
fill ~24 ~9 ~20 ~26 ~9 ~20 wooden_slab 8  
fill ~24 ~9 ~21 ~32 ~9 ~21 planks 0  
fill ~24 ~9 ~47 ~30 ~9 ~47 fence 0  
fill ~24 ~9 ~55 ~30 ~9 ~55 fence 0  
fill ~24 ~9 ~81 ~32 ~9 ~81 planks 0  
fill ~24 ~9 ~82 ~26 ~9 ~82 wooden_slab 8 
setblock ~25 ~9 ~25 log 0  
fill ~25 ~9 ~26 ~25 ~9 ~29 fence 0 
setblock ~25 ~9 ~30 log 0 
setblock ~25 ~9 ~72 log 0  
fill ~25 ~9 ~73 ~25 ~9 ~76 fence 0 
setblock ~25 ~9 ~77 log 0  
fill ~26 ~9 ~25 ~28 ~9 ~25 fence 0  
fill ~26 ~9 ~77 ~28 ~9 ~77 fence 0 
setblock ~27 ~9 ~20 double_wooden_slab 0 
setblock ~27 ~9 ~82 double_wooden_slab 0  
fill ~28 ~9 ~19 ~28 ~16 ~19 cobblestone_wall 0  
fill ~28 ~9 ~22 ~28 ~14 ~22 log 0  
fill ~28 ~9 ~40 ~28 ~23 ~40 stonebrick 0  
fill ~28 ~9 ~62 ~28 ~23 ~62 stonebrick 0  
fill ~28 ~9 ~80 ~28 ~14 ~80 log 0  
fill ~28 ~9 ~83 ~28 ~16 ~83 cobblestone_wall 0 
setblock ~29 ~9 ~20 oak_stairs 5 
setblock ~29 ~9 ~25 log 0  
fill ~29 ~9 ~26 ~29 ~9 ~29 fence 0 
setblock ~29 ~9 ~30 log 0 
setblock ~29 ~9 ~72 log 0  
fill ~29 ~9 ~73 ~29 ~9 ~76 fence 0 
setblock ~29 ~9 ~77 log 0 
setblock ~29 ~9 ~82 oak_stairs 5 
setblock ~30 ~9 ~20 oak_stairs 4 
setblock ~30 ~9 ~82 oak_stairs 4  
fill ~31 ~9 ~19 ~31 ~9 ~21 planks 0  
fill ~31 ~9 ~22 ~31 ~9 ~26 fence 0  
fill ~31 ~9 ~28 ~31 ~9 ~32 fence 0  
fill ~31 ~9 ~34 ~31 ~9 ~38 fence 0  
fill ~31 ~9 ~43 ~38 ~9 ~43 fence 0  
fill ~31 ~9 ~44 ~31 ~9 ~46 fence 0  
fill ~31 ~9 ~56 ~31 ~9 ~59 fence 0  
fill ~31 ~9 ~64 ~31 ~9 ~68 fence 0  
fill ~31 ~9 ~70 ~31 ~9 ~74 fence 0  
fill ~31 ~9 ~76 ~31 ~9 ~80 fence 0  
fill ~31 ~9 ~82 ~31 ~9 ~83 planks 0 
setblock ~32 ~9 ~20 log 0  
fill ~32 ~9 ~39 ~37 ~9 ~39 fence 0  
fill ~32 ~9 ~59 ~38 ~9 ~59 fence 0  
fill ~32 ~9 ~63 ~37 ~9 ~63 fence 0 
setblock ~32 ~9 ~82 log 0 
setblock ~33 ~9 ~21 log 0 
setblock ~33 ~9 ~81 log 0  
fill ~34 ~9 ~27 ~35 ~9 ~27 wooden_slab 0  
fill ~34 ~9 ~33 ~35 ~9 ~33 wooden_slab 0  
fill ~34 ~9 ~40 ~35 ~9 ~40 stonebrick 0  
fill ~34 ~9 ~62 ~35 ~9 ~62 stonebrick 0  
fill ~34 ~9 ~69 ~35 ~9 ~69 wooden_slab 0  
fill ~34 ~9 ~75 ~35 ~9 ~75 wooden_slab 0 
setblock ~36 ~9 ~21 log 0 
setblock ~36 ~9 ~81 log 0 
setblock ~37 ~9 ~20 log 0  
fill ~37 ~9 ~21 ~46 ~9 ~21 planks 0  
fill ~37 ~9 ~81 ~46 ~9 ~81 planks 0 
setblock ~37 ~9 ~82 log 0  
fill ~38 ~9 ~19 ~38 ~9 ~21 planks 0  
fill ~38 ~9 ~22 ~38 ~9 ~26 fence 0  
fill ~38 ~9 ~28 ~38 ~9 ~32 fence 0  
fill ~38 ~9 ~34 ~38 ~9 ~38 fence 0  
fill ~38 ~9 ~44 ~38 ~9 ~46 fence 0  
fill ~38 ~9 ~56 ~38 ~9 ~59 fence 0  
fill ~38 ~9 ~64 ~38 ~9 ~68 fence 0  
fill ~38 ~9 ~70 ~38 ~9 ~74 fence 0  
fill ~38 ~9 ~76 ~38 ~9 ~80 fence 0  
fill ~38 ~9 ~82 ~38 ~9 ~83 planks 0 
setblock ~39 ~9 ~20 oak_stairs 5  
fill ~39 ~9 ~47 ~45 ~9 ~47 fence 0  
fill ~39 ~9 ~55 ~45 ~9 ~55 fence 0 
setblock ~39 ~9 ~82 oak_stairs 5 
setblock ~40 ~9 ~20 oak_stairs 4 
setblock ~40 ~9 ~25 log 0  
fill ~40 ~9 ~26 ~40 ~9 ~29 fence 0 
setblock ~40 ~9 ~30 log 0 
setblock ~40 ~9 ~72 log 0  
fill ~40 ~9 ~73 ~40 ~9 ~76 fence 0 
setblock ~40 ~9 ~77 log 0 
setblock ~40 ~9 ~82 oak_stairs 4  
fill ~41 ~9 ~19 ~41 ~16 ~19 cobblestone_wall 0  
fill ~41 ~9 ~22 ~41 ~14 ~22 log 0  
fill ~41 ~9 ~25 ~43 ~9 ~25 fence 0  
fill ~41 ~9 ~40 ~41 ~23 ~40 stonebrick 0  
fill ~41 ~9 ~62 ~41 ~23 ~62 stonebrick 0  
fill ~41 ~9 ~77 ~43 ~9 ~77 fence 0  
fill ~41 ~9 ~80 ~41 ~14 ~80 log 0  
fill ~41 ~9 ~83 ~41 ~16 ~83 cobblestone_wall 0 
setblock ~42 ~9 ~20 double_wooden_slab 0 
setblock ~42 ~9 ~82 double_wooden_slab 0  
fill ~43 ~9 ~20 ~45 ~9 ~20 wooden_slab 8  
fill ~43 ~9 ~82 ~45 ~9 ~82 wooden_slab 8 
setblock ~44 ~9 ~25 log 0  
fill ~44 ~9 ~26 ~44 ~9 ~29 fence 0 
setblock ~44 ~9 ~30 log 0 
setblock ~44 ~9 ~72 log 0  
fill ~44 ~9 ~73 ~44 ~9 ~76 fence 0 
setblock ~44 ~9 ~77 log 0 
setblock ~46 ~9 ~20 double_wooden_slab 0 
setblock ~46 ~9 ~82 double_wooden_slab 0  
fill ~47 ~9 ~19 ~47 ~16 ~19 cobblestone_wall 0  
fill ~47 ~9 ~21 ~48 ~9 ~21 log 0  
fill ~47 ~9 ~22 ~47 ~15 ~22 planks 0  
fill ~47 ~9 ~23 ~47 ~9 ~26 planks 0  
fill ~47 ~9 ~27 ~48 ~9 ~27 log 0  
fill ~47 ~9 ~28 ~47 ~15 ~28 planks 0  
fill ~47 ~9 ~29 ~47 ~9 ~32 planks 0  
fill ~47 ~9 ~33 ~48 ~9 ~33 log 0  
fill ~47 ~9 ~34 ~47 ~15 ~34 planks 0  
fill ~47 ~9 ~35 ~47 ~9 ~38 planks 0  
fill ~47 ~9 ~39 ~48 ~9 ~39 log 0  
fill ~47 ~9 ~40 ~47 ~23 ~40 stonebrick 0  
fill ~47 ~9 ~47 ~52 ~9 ~47 fence 0  
fill ~47 ~9 ~55 ~52 ~9 ~55 fence 0  
fill ~47 ~9 ~62 ~47 ~23 ~62 stonebrick 0  
fill ~47 ~9 ~63 ~48 ~9 ~63 log 0  
fill ~47 ~9 ~64 ~47 ~15 ~64 planks 0  
fill ~47 ~9 ~65 ~47 ~9 ~68 planks 0  
fill ~47 ~9 ~69 ~48 ~9 ~69 log 0  
fill ~47 ~9 ~70 ~47 ~15 ~70 planks 0  
fill ~47 ~9 ~71 ~47 ~9 ~74 planks 0  
fill ~47 ~9 ~75 ~48 ~9 ~75 log 0   
fill ~47 ~9 ~76 ~47 ~15 ~76 planks 0  
fill ~47 ~9 ~77 ~47 ~9 ~80 planks 0  
fill ~47 ~9 ~81 ~48 ~9 ~81 log 0  
fill ~47 ~9 ~83 ~47 ~16 ~83 cobblestone_wall 0  
fill ~48 ~9 ~22 ~48 ~13 ~22 fence 0 
setblock ~48 ~9 ~24 wooden_slab 0  
fill ~48 ~9 ~26 ~48 ~13 ~26 fence 0  
fill ~48 ~9 ~28 ~48 ~13 ~28 fence 0 
setblock ~48 ~9 ~30 wooden_slab 0  
fill ~48 ~9 ~32 ~48 ~13 ~32 fence 0  
fill ~48 ~9 ~34 ~48 ~13 ~34 fence 0 
setblock ~48 ~9 ~36 wooden_slab 0  
fill ~48 ~9 ~38 ~48 ~13 ~38 fence 0  
fill ~48 ~9 ~41 ~48 ~21 ~41 log 0  
fill ~48 ~9 ~61 ~48 ~21 ~61 log 0  
fill ~48 ~9 ~64 ~48 ~13 ~64 fence 0 
setblock ~48 ~9 ~66 wooden_slab 0  
fill ~48 ~9 ~68 ~48 ~13 ~68 fence 0  
fill ~48 ~9 ~70 ~48 ~13 ~70 fence 0 
setblock ~48 ~9 ~72 wooden_slab 0  
fill ~48 ~9 ~74 ~48 ~13 ~74 fence 0  
fill ~48 ~9 ~76 ~48 ~13 ~76 fence 0 
setblock ~48 ~9 ~78 wooden_slab 0  
fill ~48 ~9 ~80 ~48 ~13 ~80 fence 0  
fill ~49 ~9 ~21 ~49 ~12 ~21 cobblestone_wall 0  
fill ~49 ~9 ~27 ~49 ~12 ~27 cobblestone_wall 0  
fill ~49 ~9 ~33 ~49 ~12 ~33 cobblestone_wall 0  
fill ~49 ~9 ~39 ~49 ~12 ~39 cobblestone_wall 0  
fill ~49 ~9 ~41 ~52 ~9 ~41 planks 0  
fill ~49 ~9 ~61 ~52 ~9 ~61 planks 0  
fill ~49 ~9 ~63 ~49 ~12 ~63 cobblestone_wall 0  
fill ~49 ~9 ~69 ~49 ~12 ~69 cobblestone_wall 0  
fill ~49 ~9 ~75 ~49 ~12 ~75 cobblestone_wall 0  
fill ~49 ~9 ~81 ~49 ~12 ~81 cobblestone_wall 0  
fill ~50 ~9 ~38 ~50 ~9 ~39 wooden_slab 0  
fill ~50 ~9 ~63 ~50 ~9 ~64 wooden_slab 0  
fill ~52 ~9 ~42 ~52 ~13 ~42 fence 0  
fill ~52 ~9 ~44 ~52 ~11 ~44 fence 0  
fill ~52 ~9 ~46 ~52 ~13 ~46 fence 0  
fill ~52 ~9 ~56 ~52 ~13 ~56 fence 0  
fill ~52 ~9 ~58 ~52 ~11 ~58 fence 0  
fill ~52 ~9 ~60 ~52 ~13 ~60 fence 0  
fill ~53 ~9 ~39 ~53 ~12 ~39 cobblestone_wall 0  
fill ~53 ~9 ~43 ~53 ~12 ~43 glass 0  
fill ~53 ~9 ~45 ~53 ~12 ~45 glass 0  
fill ~53 ~9 ~47 ~53 ~14 ~47 log 0  
fill ~53 ~9 ~55 ~53 ~14 ~55 log 0  
fill ~53 ~9 ~57 ~53 ~12 ~57 glass 0  
fill ~53 ~9 ~59 ~53 ~12 ~59 glass 0  
fill ~53 ~9 ~63 ~53 ~12 ~63 cobblestone_wall 0 
setblock ~54 ~9 ~49 stone_slab 8 
setblock ~54 ~9 ~50 double_stone_slab 0 
setblock ~54 ~9 ~51 stone_slab 8 
setblock ~54 ~9 ~52 double_stone_slab 0 
setblock ~54 ~9 ~53 stone_slab 8  
fill ~55 ~9 ~41 ~55 ~12 ~41 cobblestone_wall 0  
fill ~55 ~9 ~47 ~55 ~12 ~47 cobblestone_wall 0  
fill ~55 ~9 ~55 ~55 ~12 ~55 cobblestone_wall 0  
fill ~55 ~9 ~61 ~55 ~12 ~61 cobblestone_wall 0 
setblock ~14 ~10 ~48 oak_stairs 4 
setblock ~14 ~10 ~54 oak_stairs 4  
fill ~15 ~10 ~49 ~15 ~10 ~53 iron_bars 0  
fill ~19 ~10 ~41 ~20 ~10 ~41 planks 0  
fill ~19 ~10 ~61 ~20 ~10 ~61 planks 0  
fill ~21 ~10 ~21 ~22 ~10 ~21 log 0  
fill ~21 ~10 ~27 ~22 ~10 ~27 log 0  
fill ~21 ~10 ~33 ~22 ~10 ~33 log 0  
fill ~21 ~10 ~39 ~22 ~10 ~39 log 0  
fill ~21 ~10 ~63 ~22 ~10 ~63 log 0  
fill ~21 ~10 ~69 ~22 ~10 ~69 log 0  
fill ~21 ~10 ~75 ~22 ~10 ~75 log 0  
fill ~21 ~10 ~81 ~22 ~10 ~81 log 0  
fill ~22 ~10 ~23 ~22 ~12 ~23 glass 0  
fill ~22 ~10 ~24 ~22 ~13 ~24 glass 0  
fill ~22 ~10 ~25 ~22 ~12 ~25 glass 0  
fill ~22 ~10 ~26 ~22 ~15 ~26 planks 0  
fill ~22 ~10 ~29 ~22 ~12 ~29 glass 0  
fill ~22 ~10 ~30 ~22 ~13 ~30 glass 0  
fill ~22 ~10 ~31 ~22 ~12 ~31 glass 0  
fill ~22 ~10 ~32 ~22 ~15 ~32 planks 0  
fill ~22 ~10 ~35 ~22 ~12 ~35 glass 0  
fill ~22 ~10 ~36 ~22 ~13 ~36 glass 0  
fill ~22 ~10 ~37 ~22 ~12 ~37 glass 0  
fill ~22 ~10 ~38 ~22 ~15 ~38 planks 0  
fill ~22 ~10 ~47 ~22 ~23 ~47 fence 0  
fill ~22 ~10 ~55 ~22 ~23 ~55 fence 0  
fill ~22 ~10 ~65 ~22 ~12 ~65 glass 0  
fill ~22 ~10 ~66 ~22 ~13 ~66 glass 0  
fill ~22 ~10 ~67 ~22 ~12 ~67 glass 0  
fill ~22 ~10 ~68 ~22 ~15 ~68 planks 0  
fill ~22 ~10 ~71 ~22 ~12 ~71 glass 0  
fill ~22 ~10 ~72 ~22 ~13 ~72 glass 0  
fill ~22 ~10 ~73 ~22 ~12 ~73 glass 0  
fill ~22 ~10 ~74 ~22 ~15 ~74 planks 0  
fill ~22 ~10 ~77 ~22 ~12 ~77 glass 0  
fill ~22 ~10 ~78 ~22 ~13 ~78 glass 0  
fill ~22 ~10 ~79 ~22 ~12 ~79 glass 0  
fill ~22 ~10 ~80 ~22 ~15 ~80 planks 0  
fill ~23 ~10 ~20 ~23 ~13 ~20 fence 0  
