    
fill ~2 ~0 ~24 ~3 ~0 ~24 cobblestone 0  
fill ~3 ~0 ~32 ~3 ~5 ~32 stone 0 
setblock ~31 ~0 ~47 cobblestone 0 
setblock ~33 ~0 ~47 cobblestone 0 
setblock ~37 ~0 ~2 cobblestone 0 
setblock ~38 ~0 ~1 cobblestone 0 
setblock ~1 ~1 ~24 cobblestone 0 
setblock ~4 ~1 ~25 cobblestone 0  
fill ~21 ~1 ~29 ~21 ~4 ~29 gold_block 0 
setblock ~30 ~1 ~46 cobblestone 0 
setblock ~32 ~1 ~46 cobblestone 0 
setblock ~32 ~1 ~48 cobblestone 0 
setblock ~37 ~1 ~3 cobblestone 0  
fill ~2 ~2 ~24 ~3 ~2 ~24 cobblestone 0 
setblock ~2 ~2 ~25 leaves 12 
setblock ~2 ~2 ~48 leaves 14 
setblock ~5 ~2 ~25 cobblestone 0 
setblock ~5 ~2 ~47 cobblestone 0  
fill ~29 ~2 ~43 ~30 ~2 ~43 cobblestone 0  
fill ~29 ~2 ~44 ~29 ~3 ~44 cobblestone 0 
setblock ~30 ~2 ~45 cobblestone 0 
setblock ~31 ~2 ~44 cobblestone 0 
setblock ~32 ~2 ~45 cobblestone 0 
setblock ~34 ~2 ~7 cobblestone 0 
setblock ~35 ~2 ~4 cobblestone 0 
setblock ~36 ~2 ~3 cobblestone 0 
setblock ~37 ~2 ~2 cobblestone 0  
fill ~37 ~2 ~4 ~37 ~2 ~5 cobblestone 0 
setblock ~38 ~2 ~1 cobblestone 0 
setblock ~38 ~2 ~3 cobblestone 0 
setblock ~2 ~3 ~24 leaves 12 
setblock ~3 ~3 ~48 cobblestone 0 
setblock ~4 ~3 ~25 cobblestone 0 
setblock ~4 ~3 ~47 cobblestone 0  
fill ~5 ~3 ~24 ~7 ~3 ~24 cobblestone 0  
fill ~5 ~3 ~26 ~7 ~3 ~26 cobblestone 0 
setblock ~5 ~3 ~48 cobblestone 0 
setblock ~6 ~3 ~46 cobblestone 0  
fill ~29 ~3 ~41 ~29 ~3 ~42 cobblestone 0 
setblock ~33 ~3 ~10 cobblestone 0 
setblock ~34 ~3 ~6 cobblestone 0  
fill ~34 ~3 ~8 ~34 ~3 ~9 cobblestone 0 
setblock ~35 ~3 ~5 cobblestone 0 
setblock ~35 ~3 ~7 cobblestone 0 
setblock ~36 ~3 ~6 cobblestone 0 
setblock ~36 ~3 ~7 leaves 14 
setblock ~2 ~4 ~24 leaves 4 
setblock ~5 ~4 ~47 cobblestone 0 
setblock ~7 ~4 ~27 leaves 6 
setblock ~7 ~4 ~45 cobblestone 0 
setblock ~8 ~4 ~25 cobblestone 0 
setblock ~8 ~4 ~27 cobblestone 0 
setblock ~8 ~4 ~44 cobblestone 0  
fill ~9 ~4 ~26 ~10 ~4 ~26 cobblestone 0  
fill ~20 ~4 ~28 ~20 ~5 ~28 gold_block 0  
fill ~20 ~4 ~30 ~20 ~7 ~30 glass 0  
fill ~22 ~4 ~28 ~22 ~7 ~28 glass 0  
fill ~22 ~4 ~30 ~22 ~7 ~30 glass 0 
setblock ~28 ~4 ~40 cobblestone 0 
setblock ~29 ~4 ~43 cobblestone 0 
setblock ~33 ~4 ~11 cobblestone 0 
setblock ~34 ~4 ~7 cobblestone 0 
setblock ~36 ~4 ~6 leaves 14 
setblock ~6 ~5 ~46 cobblestone 0  
fill ~8 ~5 ~26 ~8 ~6 ~26 cobblestone 0  
fill ~8 ~5 ~27 ~8 ~6 ~27 leaves 14 
setblock ~8 ~5 ~43 cobblestone 0  
fill ~11 ~5 ~27 ~12 ~5 ~27 cobblestone 0  
fill ~19 ~5 ~27 ~19 ~7 ~27 glass 0  
fill ~19 ~5 ~31 ~19 ~7 ~31 glass 0  
fill ~20 ~5 ~29 ~22 ~5 ~29 glass 0  
fill ~21 ~5 ~28 ~21 ~7 ~28 glass 0 
setblock ~21 ~5 ~30 gold_block 0  
fill ~23 ~5 ~27 ~23 ~7 ~27 glass 0  
fill ~23 ~5 ~31 ~23 ~7 ~31 glass 0  
fill ~24 ~5 ~29 ~24 ~7 ~29 glass 0  
fill ~28 ~5 ~39 ~28 ~6 ~39 cobblestone 0  
fill ~29 ~5 ~41 ~29 ~5 ~42 cobblestone 0 
setblock ~31 ~5 ~12 cobblestone 0 
setblock ~32 ~5 ~11 cobblestone 0 
setblock ~33 ~5 ~10 cobblestone 0 
setblock ~33 ~5 ~12 cobblestone 0  
fill ~34 ~5 ~8 ~34 ~5 ~9 cobblestone 0 
setblock ~36 ~5 ~6 leaves 6 
setblock ~7 ~6 ~43 cobblestone 0 
setblock ~7 ~6 ~45 cobblestone 0 
setblock ~8 ~6 ~29 gold_block 0 
setblock ~8 ~6 ~42 cobblestone 0 
setblock ~8 ~6 ~44 cobblestone 0 
setblock ~8 ~6 ~45 leaves 12  
fill ~9 ~6 ~26 ~10 ~6 ~26 cobblestone 0 
setblock ~9 ~6 ~43 cobblestone 0 
setblock ~11 ~6 ~40 cobblestone 0  
fill ~12 ~6 ~27 ~13 ~6 ~27 cobblestone 0  
fill ~17 ~6 ~25 ~17 ~7 ~25 glass 0  
fill ~17 ~6 ~29 ~25 ~6 ~29 glass 0  
fill ~17 ~6 ~33 ~17 ~7 ~33 glass 0  
fill ~18 ~6 ~26 ~24 ~6 ~26 glass 0  
fill ~18 ~6 ~27 ~18 ~6 ~26 glass 0 
setblock ~18 ~6 ~28 gold_block 0  
fill ~18 ~6 ~30 ~24 ~6 ~30 glass 0  
fill ~18 ~6 ~31 ~18 ~6 ~32 glass 0  
fill ~19 ~6 ~28 ~23 ~6 ~28 glass 0  
fill ~19 ~6 ~32 ~20 ~6 ~32 glass 0  
fill ~20 ~6 ~27 ~24 ~6 ~27 glass 0  
fill ~20 ~6 ~31 ~20 ~7 ~31 glass 0 
setblock ~21 ~6 ~16 gold_block 0  
fill ~21 ~6 ~25 ~21 ~7 ~25 glass 0  
fill ~21 ~6 ~31 ~21 ~6 ~33 gold_block 0 
setblock ~21 ~6 ~42 gold_block 0  
fill ~22 ~6 ~31 ~22 ~7 ~31 glass 0  
fill ~22 ~6 ~32 ~24 ~6 ~32 glass 0 
setblock ~24 ~6 ~31 glass 0  
fill ~25 ~6 ~25 ~25 ~7 ~25 glass 0  
fill ~25 ~6 ~33 ~25 ~9 ~33 glass 0 
setblock ~26 ~6 ~39 cobblestone 0  
fill ~27 ~6 ~40 ~28 ~6 ~40 cobblestone 0 
setblock ~29 ~6 ~14 leaves 14 
setblock ~29 ~6 ~15 cobblestone 0 
setblock ~29 ~6 ~17 cobblestone 0  
fill ~30 ~6 ~13 ~30 ~6 ~14 cobblestone 0 
setblock ~30 ~6 ~16 cobblestone 0 
setblock ~31 ~6 ~15 cobblestone 0  
fill ~32 ~6 ~13 ~32 ~6 ~14 cobblestone 0 
setblock ~33 ~6 ~11 cobblestone 0 
setblock ~34 ~6 ~29 gold_block 0 
setblock ~8 ~7 ~27 leaves 6  
fill ~8 ~7 ~44 ~8 ~8 ~44 leaves 12  
fill ~9 ~7 ~29 ~10 ~7 ~29 gold_block 0 
setblock ~9 ~7 ~41 cobblestone 0 
setblock ~10 ~7 ~40 cobblestone 0 
setblock ~10 ~7 ~42 cobblestone 0  
fill ~11 ~7 ~27 ~13 ~7 ~27 cobblestone 0 
setblock ~11 ~7 ~41 cobblestone 0 
setblock ~12 ~7 ~28 cobblestone 0 
setblock ~12 ~7 ~39 cobblestone 0  
fill ~13 ~7 ~26 ~13 ~8 ~26 cobblestone 0 
setblock ~13 ~7 ~38 cobblestone 0  
fill ~14 ~7 ~29 ~18 ~7 ~29 glass 0  
fill ~15 ~7 ~27 ~16 ~7 ~27 glass 0  
fill ~15 ~7 ~28 ~17 ~7 ~28 glass 0  
fill ~15 ~7 ~30 ~17 ~7 ~30 glass 0  
fill ~15 ~7 ~31 ~17 ~7 ~31 glass 0  
fill ~16 ~7 ~24 ~26 ~7 ~24 glass 0  
fill ~16 ~7 ~25 ~16 ~7 ~34 glass 0  
fill ~17 ~7 ~26 ~17 ~7 ~27 gold_block 0  
fill ~17 ~7 ~32 ~18 ~7 ~32 glass 0  
fill ~17 ~7 ~34 ~20 ~7 ~34 glass 0  
fill ~18 ~7 ~25 ~26 ~7 ~25 glass 0  
fill ~18 ~7 ~26 ~18 ~7 ~24 glass 0 
setblock ~18 ~7 ~30 lava 2  
fill ~18 ~7 ~31 ~18 ~34 ~31 lava 0  
fill ~18 ~7 ~33 ~26 ~7 ~33 glass 0  
fill ~19 ~7 ~23 ~23 ~7 ~23 glass 0  
fill ~19 ~7 ~28 ~23 ~7 ~28 glass 0 
setblock ~19 ~7 ~30 glass 0  
fill ~19 ~7 ~35 ~21 ~7 ~35 glass 0  
fill ~20 ~7 ~27 ~20 ~6 ~27 glass 0  
fill ~20 ~7 ~29 ~22 ~7 ~29 glass 0  
fill ~21 ~7 ~17 ~21 ~7 ~18 gold_block 0  
fill ~21 ~7 ~22 ~21 ~8 ~22 glass 0 
setblock ~21 ~7 ~26 glass 0  
fill ~21 ~7 ~27 ~21 ~34 ~27 lava 0 
setblock ~21 ~7 ~30 glass 0 
setblock ~21 ~7 ~32 glass 0 
setblock ~21 ~7 ~34 gold_block 0  
fill ~21 ~7 ~36 ~21 ~8 ~36 glass 0  
fill ~21 ~7 ~40 ~21 ~7 ~41 gold_block 0  
fill ~22 ~7 ~26 ~23 ~7 ~26 lava 0 
setblock ~22 ~7 ~27 glass 0  
fill ~22 ~7 ~34 ~26 ~7 ~34 glass 0 
setblock ~22 ~7 ~35 gold_block 0 
setblock ~23 ~7 ~30 glass 0 
setblock ~23 ~7 ~35 glass 0  
fill ~24 ~7 ~26 ~26 ~7 ~26 glass 0  
fill ~24 ~7 ~27 ~24 ~34 ~27 lava 0  
fill ~24 ~7 ~28 ~24 ~34 ~28 lava 0  
fill ~24 ~7 ~30 ~24 ~34 ~30 lava 0  
fill ~24 ~7 ~31 ~24 ~34 ~31 lava 0  
fill ~24 ~7 ~32 ~25 ~7 ~32 glass 0  
fill ~25 ~7 ~27 ~27 ~7 ~27 glass 0  
fill ~25 ~7 ~28 ~27 ~7 ~28 glass 0  
fill ~25 ~7 ~29 ~28 ~7 ~29 glass 0  
fill ~25 ~7 ~30 ~27 ~7 ~30 glass 0  
fill ~25 ~7 ~31 ~27 ~7 ~31 glass 0 
setblock ~26 ~7 ~32 gold_block 0 
setblock ~26 ~7 ~38 cobblestone 0 
setblock ~28 ~7 ~19 cobblestone 0 
setblock ~28 ~7 ~38 cobblestone 0 
setblock ~29 ~7 ~18 cobblestone 0  
fill ~30 ~7 ~14 ~30 ~8 ~14 leaves 14 
setblock ~30 ~7 ~15 cobblestone 0  
fill ~32 ~7 ~29 ~32 ~9 ~29 glass 0  
fill ~33 ~7 ~29 ~33 ~8 ~29 gold_block 0  
fill ~9 ~8 ~29 ~9 ~7 ~29 gold_block 0  
fill ~10 ~8 ~28 ~10 ~8 ~30 glass 0 
setblock ~11 ~8 ~29 gold_block 0 
setblock ~11 ~8 ~40 cobblestone 0  
fill ~12 ~8 ~26 ~12 ~8 ~27 cobblestone 0  
fill ~12 ~8 ~28 ~14 ~8 ~28 glass 0  
fill ~12 ~8 ~29 ~14 ~8 ~29 glass 0 
setblock ~12 ~8 ~30 gold_block 0  
fill ~13 ~8 ~27 ~14 ~8 ~27 glass 0  
fill ~13 ~8 ~30 ~14 ~8 ~30 glass 0 
setblock ~13 ~8 ~31 gold_block 0  
fill ~14 ~8 ~25 ~15 ~8 ~25 glass 0  
fill ~14 ~8 ~26 ~15 ~8 ~26 glass 0 
setblock ~14 ~8 ~31 glass 0 
setblock ~14 ~8 ~32 gold_block 0  
fill ~14 ~8 ~33 ~15 ~8 ~33 glass 0 
setblock ~14 ~8 ~37 cobblestone 0  
fill ~15 ~8 ~23 ~18 ~8 ~23 glass 0  
fill ~15 ~8 ~24 ~16 ~8 ~24 glass 0  
fill ~15 ~8 ~27 ~27 ~8 ~27 lava 0  
fill ~15 ~8 ~28 ~16 ~8 ~28 lava 0  
fill ~15 ~8 ~29 ~16 ~8 ~29 lava 0  
fill ~15 ~8 ~30 ~16 ~8 ~30 lava 0  
fill ~15 ~8 ~31 ~24 ~8 ~31 lava 0 
setblock ~15 ~8 ~32 glass 0  
fill ~15 ~8 ~34 ~16 ~8 ~34 glass 0  
fill ~15 ~8 ~35 ~18 ~8 ~35 glass 0  
fill ~16 ~8 ~25 ~19 ~8 ~25 lava 0  
fill ~16 ~8 ~26 ~17 ~8 ~26 lava 0  
fill ~16 ~8 ~32 ~17 ~8 ~32 lava 0  
fill ~16 ~8 ~33 ~19 ~8 ~33 lava 0 
setblock ~17 ~8 ~22 glass 0  
fill ~17 ~8 ~24 ~25 ~8 ~24 lava 0  
fill ~17 ~8 ~28 ~17 ~8 ~30 lava 2  
fill ~17 ~8 ~34 ~22 ~8 ~34 lava 0  
fill ~17 ~8 ~36 ~22 ~8 ~36 glass 0 
setblock ~18 ~8 ~22 gold_block 0 
setblock ~18 ~8 ~26 lava 2  
fill ~18 ~8 ~28 ~24 ~8 ~28 lava 0  
fill ~18 ~8 ~29 ~25 ~8 ~29 lava 0  
fill ~18 ~8 ~30 ~25 ~8 ~30 lava 0 
setblock ~18 ~8 ~32 lava 2  
fill ~19 ~8 ~21 ~20 ~8 ~21 gold_block 0  
fill ~19 ~8 ~22 ~25 ~8 ~22 glass 0  
fill ~19 ~8 ~23 ~21 ~8 ~23 lava 0  
fill ~19 ~8 ~26 ~26 ~8 ~26 lava 0  
fill ~19 ~8 ~32 ~23 ~8 ~32 lava 0  
fill ~19 ~8 ~35 ~23 ~8 ~35 lava 0  
fill ~19 ~8 ~37 ~23 ~8 ~37 glass 0  
fill ~20 ~8 ~18 ~21 ~8 ~18 glass 0  
fill ~20 ~8 ~20 ~20 ~9 ~20 glass 0  
fill ~20 ~8 ~25 ~22 ~8 ~25 lava 2  
fill ~20 ~8 ~33 ~23 ~8 ~33 lava 2  
fill ~20 ~8 ~38 ~22 ~8 ~38 glass 0  
fill ~20 ~8 ~40 ~22 ~8 ~40 glass 0 
setblock ~21 ~8 ~17 glass 0  
fill ~21 ~8 ~19 ~21 ~8 ~20 gold_block 0  
fill ~21 ~8 ~21 ~23 ~8 ~21 glass 0  
fill ~21 ~8 ~39 ~21 ~9 ~39 gold_block 0 
setblock ~21 ~8 ~41 glass 0 
setblock ~22 ~8 ~18 gold_block 0 
setblock ~22 ~8 ~20 glass 0 
setblock ~22 ~8 ~23 lava 2 
setblock ~23 ~8 ~23 lava 0  
fill ~23 ~8 ~25 ~26 ~8 ~25 lava 0 
setblock ~23 ~8 ~34 lava 2  
fill ~23 ~8 ~36 ~24 ~8 ~36 gold_block 0  
fill ~24 ~8 ~23 ~27 ~8 ~23 glass 0 
setblock ~24 ~8 ~32 lava 2  
fill ~24 ~8 ~33 ~24 ~33 ~33 lava 0  
fill ~24 ~8 ~34 ~24 ~33 ~34 lava 0  
fill ~24 ~8 ~35 ~26 ~8 ~35 glass 0 
setblock ~25 ~8 ~28 lava 2  
fill ~25 ~8 ~31 ~26 ~8 ~31 glass 0  
fill ~25 ~8 ~32 ~25 ~33 ~32 lava 0  
fill ~25 ~8 ~34 ~26 ~8 ~34 glass 0 
setblock ~25 ~8 ~36 glass 0 
setblock ~25 ~8 ~37 cobblestone 0  
fill ~26 ~8 ~24 ~27 ~8 ~24 glass 0  
fill ~26 ~8 ~28 ~27 ~8 ~28 lava 0  
fill ~26 ~8 ~29 ~27 ~8 ~29 lava 2 
setblock ~26 ~8 ~30 glass 0  
fill ~26 ~8 ~32 ~28 ~8 ~32 glass 0  
fill ~26 ~8 ~33 ~26 ~9 ~33 glass 0 
setblock ~26 ~8 ~36 cobblestone 0  
fill ~27 ~8 ~20 ~27 ~10 ~20 cobblestone 0  
fill ~27 ~8 ~25 ~28 ~8 ~25 glass 0  
fill ~27 ~8 ~26 ~28 ~8 ~26 glass 0  
fill ~27 ~8 ~33 ~27 ~8 ~35 gold_block 0 
setblock ~27 ~8 ~37 cobblestone 0  
fill ~28 ~8 ~27 ~29 ~8 ~27 glass 0  
fill ~28 ~8 ~28 ~30 ~8 ~28 glass 0  
fill ~28 ~8 ~29 ~32 ~8 ~29 glass 0  
fill ~28 ~8 ~30 ~30 ~8 ~30 glass 0  
fill ~28 ~8 ~31 ~29 ~8 ~31 glass 0 
setblock ~28 ~8 ~33 glass 0 
setblock ~29 ~8 ~17 cobblestone 0 
setblock ~30 ~8 ~16 cobblestone 0  
fill ~32 ~8 ~28 ~32 ~11 ~28 glass 0  
fill ~32 ~8 ~30 ~32 ~10 ~30 gold_block 0 
setblock ~8 ~9 ~44 leaves 4 
setblock ~9 ~9 ~17 gold_block 0 
setblock ~9 ~9 ~41 gold_block 0  
fill ~10 ~9 ~28 ~10 ~10 ~28 gold_block 0  
fill ~10 ~9 ~29 ~12 ~9 ~29 glass 0  
fill ~10 ~9 ~30 ~12 ~9 ~30 glass 0  
fill ~11 ~9 ~27 ~12 ~9 ~27 glass 0  
fill ~11 ~9 ~28 ~12 ~9 ~28 glass 0  
fill ~11 ~9 ~31 ~12 ~9 ~31 glass 0  
fill ~12 ~9 ~26 ~13 ~9 ~26 glass 0 
setblock ~12 ~9 ~32 gold_block 0 
setblock ~12 ~9 ~39 cobblestone 0  
fill ~13 ~9 ~24 ~14 ~9 ~24 glass 0  
fill ~13 ~9 ~25 ~13 ~9 ~24 glass 0  
fill ~13 ~9 ~32 ~13 ~9 ~34 glass 0 
setblock ~13 ~9 ~38 cobblestone 0  
fill ~14 ~9 ~22 ~16 ~9 ~22 glass 0  
fill ~14 ~9 ~23 ~15 ~9 ~23 glass 0  
fill ~14 ~9 ~25 ~14 ~9 ~26 lava 0  
fill ~14 ~9 ~27 ~14 ~9 ~30 lava 2  
fill ~14 ~9 ~32 ~15 ~9 ~32 lava 2 
setblock ~14 ~9 ~33 lava 0  
fill ~14 ~9 ~34 ~14 ~9 ~36 glass 0  
fill ~15 ~9 ~24 ~15 ~32 ~24 lava 0  
fill ~15 ~9 ~25 ~15 ~9 ~26 lava 2 
setblock ~15 ~9 ~27 lava 8  
fill ~15 ~9 ~28 ~27 ~9 ~28 lava 0  
fill ~15 ~9 ~29 ~27 ~9 ~29 lava 0  
fill ~15 ~9 ~30 ~27 ~9 ~30 lava 0 
setblock ~15 ~9 ~31 lava 8 
setblock ~15 ~9 ~33 lava 2  
fill ~15 ~9 ~34 ~15 ~32 ~34 lava 0  
fill ~15 ~9 ~35 ~15 ~8 ~35 glass 0  
fill ~15 ~9 ~36 ~16 ~9 ~36 glass 0  
fill ~16 ~9 ~21 ~18 ~9 ~21 glass 0  
fill ~16 ~9 ~23 ~16 ~32 ~23 lava 0 
setblock ~16 ~9 ~24 lava 2 
setblock ~16 ~9 ~25 lava 8  
fill ~16 ~9 ~26 ~26 ~9 ~26 lava 0  
fill ~16 ~9 ~27 ~26 ~9 ~27 lava 0  
fill ~16 ~9 ~31 ~26 ~9 ~31 lava 0  
fill ~16 ~9 ~32 ~26 ~9 ~32 lava 0 
setblock ~16 ~9 ~33 lava 8 
setblock ~16 ~9 ~34 lava 2  
fill ~16 ~9 ~35 ~17 ~9 ~35 lava 0  
fill ~16 ~9 ~37 ~18 ~9 ~37 glass 0 
setblock ~17 ~9 ~22 lava 0  
fill ~17 ~9 ~23 ~18 ~9 ~23 lava 2 
setblock ~17 ~9 ~24 lava 8  
fill ~17 ~9 ~25 ~25 ~9 ~25 lava 0  
fill ~17 ~9 ~33 ~24 ~9 ~33 lava 0 
setblock ~17 ~9 ~34 lava 8  
fill ~17 ~9 ~36 ~18 ~9 ~36 lava 0  
fill ~18 ~9 ~20 ~21 ~9 ~20 glass 0 
setblock ~18 ~9 ~22 lava 2  
fill ~18 ~9 ~24 ~24 ~9 ~24 lava 0  
fill ~18 ~9 ~34 ~24 ~9 ~34 lava 0 
setblock ~18 ~9 ~35 lava 2  
fill ~18 ~9 ~38 ~19 ~9 ~38 gold_block 0  
fill ~19 ~9 ~19 ~21 ~9 ~19 glass 0 
setblock ~19 ~9 ~21 lava 2  
fill ~19 ~9 ~22 ~21 ~9 ~22 lava 0 
setblock ~19 ~9 ~23 lava 8 
setblock ~19 ~9 ~35 lava 8 
setblock ~19 ~9 ~36 lava 2  
fill ~19 ~9 ~37 ~23 ~9 ~37 lava 0  
fill ~19 ~9 ~39 ~21 ~9 ~39 gold_block 0  
fill ~20 ~9 ~18 ~22 ~9 ~18 glass 0  
fill ~20 ~9 ~21 ~23 ~9 ~21 lava 0  
fill ~20 ~9 ~23 ~22 ~9 ~23 lava 0  
fill ~20 ~9 ~35 ~22 ~9 ~35 lava 0  
fill ~20 ~9 ~36 ~22 ~9 ~36 lava 0  
fill ~20 ~9 ~38 ~24 ~9 ~38 glass 0  
fill ~20 ~9 ~40 ~22 ~9 ~40 glass 0  
fill ~22 ~9 ~19 ~22 ~9 ~20 gold_block 0  
fill ~22 ~9 ~22 ~24 ~9 ~22 lava 2  
fill ~22 ~9 ~39 ~23 ~9 ~39 glass 0  
fill ~23 ~9 ~19 ~23 ~10 ~19 glass 0 
setblock ~23 ~9 ~20 gold_block 0 
setblock ~23 ~9 ~23 lava 8 
setblock ~23 ~9 ~35 lava 8 
setblock ~23 ~9 ~36 lava 2 
setblock ~24 ~9 ~20 glass 0  
fill ~24 ~9 ~21 ~25 ~9 ~21 gold_block 0  
fill ~24 ~9 ~23 ~24 ~32 ~23 lava 0 
setblock ~24 ~9 ~35 lava 2  
fill ~24 ~9 ~36 ~25 ~9 ~36 lava 0 
setblock ~24 ~9 ~37 glass 0 
setblock ~25 ~9 ~22 lava 0 
setblock ~25 ~9 ~23 lava 2 
setblock ~25 ~9 ~24 lava 8  
fill ~25 ~9 ~34 ~29 ~9 ~34 glass 0  
fill ~25 ~9 ~35 ~25 ~32 ~35 lava 0 
setblock ~25 ~9 ~37 gold_block 0 
setblock ~26 ~9 ~20 cobblestone 0  
fill ~26 ~9 ~21 ~26 ~9 ~22 glass 0  
fill ~26 ~9 ~23 ~26 ~32 ~23 lava 0  
fill ~26 ~9 ~24 ~27 ~9 ~24 lava 0 
setblock ~26 ~9 ~25 lava 8  
fill ~26 ~9 ~35 ~28 ~9 ~35 glass 0  
fill ~26 ~9 ~36 ~28 ~9 ~36 gold_block 0 
setblock ~26 ~9 ~37 glass 0  
fill ~27 ~9 ~19 ~28 ~9 ~19 cobblestone 0 
setblock ~27 ~9 ~21 cobblestone 0  
fill ~27 ~9 ~22 ~28 ~9 ~22 glass 0  
fill ~27 ~9 ~23 ~28 ~9 ~23 glass 0  
fill ~27 ~9 ~25 ~28 ~9 ~25 lava 2  
fill ~27 ~9 ~26 ~27 ~9 ~25 lava 2 
setblock ~27 ~9 ~27 lava 8  
fill ~27 ~9 ~31 ~27 ~9 ~32 lava 2 
setblock ~27 ~9 ~33 glass 0  
fill ~28 ~9 ~24 ~29 ~9 ~24 glass 0  
fill ~28 ~9 ~26 ~28 ~32 ~26 lava 0  
fill ~28 ~9 ~27 ~28 ~32 ~27 lava 0  
fill ~28 ~9 ~28 ~28 ~9 ~30 lava 2 
setblock ~29 ~9 ~18 cobblestone 0  
fill ~29 ~9 ~25 ~29 ~9 ~26 glass 0 
setblock ~29 ~9 ~27 lava 2  
fill ~29 ~9 ~32 ~30 ~9 ~32 glass 0  
fill ~29 ~9 ~33 ~29 ~9 ~32 glass 0 
setblock ~30 ~9 ~14 leaves 6  
fill ~30 ~9 ~26 ~30 ~9 ~32 glass 0  
fill ~31 ~9 ~27 ~31 ~10 ~27 glass 0  
fill ~31 ~9 ~28 ~31 ~10 ~28 glass 0  
fill ~31 ~9 ~29 ~31 ~10 ~29 glass 0  
fill ~31 ~9 ~30 ~31 ~10 ~30 glass 0  
fill ~31 ~9 ~31 ~31 ~10 ~31 glass 0 
setblock ~33 ~9 ~17 gold_block 0 
setblock ~33 ~9 ~41 gold_block 0  
fill ~9 ~10 ~29 ~9 ~13 ~29 glass 0 
setblock ~10 ~10 ~18 gold_block 0  
fill ~10 ~10 ~19 ~11 ~10 ~19 glass 0  
fill ~10 ~10 ~30 ~11 ~10 ~30 glass 0  
fill ~10 ~10 ~39 ~11 ~10 ~39 glass 0 
setblock ~10 ~10 ~40 gold_block 0 
setblock ~11 ~10 ~18 glass 0  
fill ~11 ~10 ~26 ~11 ~10 ~31 glass 0 
setblock ~11 ~10 ~32 gold_block 0 
setblock ~11 ~10 ~40 glass 0  
fill ~12 ~10 ~20 ~12 ~13 ~20 glass 0  
fill ~12 ~10 ~24 ~12 ~10 ~25 glass 0  
fill ~12 ~10 ~33 ~12 ~10 ~34 glass 0  
fill ~12 ~10 ~38 ~12 ~13 ~38 glass 0  
fill ~13 ~10 ~21 ~15 ~10 ~21 glass 0  
fill ~13 ~10 ~22 ~14 ~10 ~22 glass 0  
fill ~13 ~10 ~23 ~13 ~10 ~21 glass 0  
fill ~13 ~10 ~26 ~13 ~10 ~32 lava 2 
setblock ~13 ~10 ~34 lava 2  
fill ~13 ~10 ~35 ~13 ~10 ~37 glass 0 
setblock ~14 ~10 ~24 lava 2 
setblock ~14 ~10 ~25 lava 8  
fill ~14 ~10 ~26 ~30 ~10 ~26 lava 0  
fill ~14 ~10 ~27 ~28 ~10 ~27 lava 0  
fill ~14 ~10 ~28 ~28 ~10 ~28 lava 0  
fill ~14 ~10 ~29 ~28 ~10 ~29 lava 0  
fill ~14 ~10 ~30 ~28 ~10 ~30 lava 0  
fill ~14 ~10 ~31 ~28 ~10 ~31 lava 0  
fill ~14 ~10 ~32 ~28 ~10 ~32 lava 0 
setblock ~14 ~10 ~33 lava 8  
fill ~14 ~10 ~34 ~14 ~31 ~34 lava 0  
fill ~14 ~10 ~35 ~14 ~10 ~34 lava 0  
fill ~14 ~10 ~36 ~14 ~10 ~37 glass 0 
setblock ~15 ~10 ~23 lava 2  
fill ~15 ~10 ~25 ~27 ~10 ~25 lava 0  
fill ~15 ~10 ~33 ~27 ~10 ~33 lava 0 
setblock ~15 ~10 ~35 lava 2 
setblock ~15 ~10 ~37 glass 0  
fill ~16 ~10 ~20 ~17 ~10 ~20 glass 0 
setblock ~16 ~10 ~22 lava 2  
fill ~16 ~10 ~24 ~27 ~10 ~24 lava 0  
fill ~16 ~10 ~34 ~27 ~10 ~34 lava 0  
fill ~16 ~10 ~35 ~26 ~10 ~35 lava 0 
setblock ~16 ~10 ~36 lava 2  
fill ~16 ~10 ~38 ~17 ~10 ~38 glass 0 
setblock ~17 ~10 ~22 lava 8  
fill ~17 ~10 ~23 ~26 ~10 ~23 lava 0 
setblock ~17 ~10 ~36 lava 8  
fill ~18 ~10 ~19 ~24 ~10 ~19 glass 0 
setblock ~18 ~10 ~21 lava 2  
fill ~18 ~10 ~22 ~24 ~10 ~22 lava 0  
fill ~18 ~10 ~36 ~24 ~10 ~36 lava 0 
setblock ~18 ~10 ~37 lava 2  
fill ~18 ~10 ~39 ~24 ~10 ~39 glass 0 
setblock ~19 ~10 ~21 lava 10  
fill ~19 ~10 ~37 ~23 ~10 ~37 lava 8  
fill ~20 ~10 ~18 ~20 ~11 ~18 glass 0  
fill ~20 ~10 ~21 ~23 ~10 ~21 lava 8 
setblock ~20 ~10 ~38 lava 2  
fill ~20 ~10 ~40 ~20 ~11 ~40 gold_block 0  
fill ~21 ~10 ~17 ~21 ~13 ~17 glass 0  
fill ~21 ~10 ~38 ~24 ~10 ~38 lava 0  
fill ~21 ~10 ~41 ~21 ~13 ~41 glass 0  
fill ~22 ~10 ~18 ~22 ~11 ~18 glass 0 
setblock ~22 ~10 ~20 lava 2  
fill ~22 ~10 ~40 ~22 ~11 ~40 glass 0  
fill ~23 ~10 ~20 ~24 ~10 ~20 lava 0 
setblock ~24 ~10 ~21 lava 2  
fill ~24 ~10 ~37 ~26 ~10 ~37 lava 0 
setblock ~25 ~10 ~20 gold_block 0  
fill ~25 ~10 ~21 ~26 ~10 ~21 lava 0 
setblock ~25 ~10 ~22 lava 8 
setblock ~25 ~10 ~36 lava 8  
fill ~25 ~10 ~38 ~26 ~10 ~38 glass 0 
setblock ~26 ~10 ~20 glass 0  
fill ~26 ~10 ~22 ~26 ~31 ~22 lava 0 
setblock ~26 ~10 ~36 lava 2  
fill ~27 ~10 ~19 ~27 ~9 ~19 cobblestone 0  
fill ~27 ~10 ~21 ~29 ~10 ~21 glass 0  
fill ~27 ~10 ~22 ~27 ~10 ~23 lava 2 
setblock ~27 ~10 ~35 lava 2  
fill ~27 ~10 ~37 ~29 ~10 ~37 glass 0  
fill ~28 ~10 ~22 ~29 ~10 ~22 glass 0 
setblock ~28 ~10 ~23 lava 0 
setblock ~28 ~10 ~24 lava 2 
setblock ~28 ~10 ~25 lava 10  
fill ~28 ~10 ~33 ~28 ~10 ~34 lava 2  
fill ~28 ~10 ~36 ~29 ~10 ~36 glass 0 
setblock ~29 ~10 ~23 glass 0  
fill ~29 ~10 ~24 ~29 ~10 ~26 lava 0 
setblock ~29 ~10 ~27 lava 10  
fill ~29 ~10 ~28 ~30 ~10 ~28 lava 2  
fill ~29 ~10 ~29 ~29 ~10 ~32 lava 2  
fill ~29 ~10 ~33 ~29 ~31 ~33 lava 0  
fill ~29 ~10 ~34 ~29 ~10 ~33 lava 0 
setblock ~29 ~10 ~35 glass 0  
fill ~30 ~10 ~20 ~30 ~13 ~20 glass 0  
fill ~30 ~10 ~24 ~30 ~10 ~25 glass 0 
setblock ~30 ~10 ~27 lava 0  
fill ~30 ~10 ~29 ~30 ~31 ~29 lava 0 
setblock ~30 ~10 ~30 lava 2  
fill ~30 ~10 ~31 ~30 ~10 ~32 lava 0  
fill ~30 ~10 ~33 ~30 ~10 ~34 glass 0  
fill ~30 ~10 ~38 ~30 ~13 ~38 glass 0  
fill ~31 ~10 ~18 ~31 ~11 ~18 glass 0  
fill ~31 ~10 ~19 ~32 ~10 ~19 glass 0 
setblock ~31 ~10 ~26 glass 0 
setblock ~31 ~10 ~32 glass 0  
fill ~31 ~10 ~39 ~32 ~10 ~39 glass 0  
fill ~31 ~10 ~40 ~32 ~10 ~40 gold_block 0 
setblock ~32 ~10 ~18 gold_block 0  
fill ~33 ~10 ~29 ~33 ~13 ~29 glass 0  
fill ~10 ~11 ~19 ~12 ~11 ~19 glass 0  
fill ~10 ~11 ~25 ~11 ~11 ~25 glass 0  
fill ~10 ~11 ~26 ~10 ~11 ~25 glass 0 
setblock ~10 ~11 ~27 gold_block 0  
fill ~10 ~11 ~28 ~10 ~11 ~32 glass 0 
setblock ~10 ~11 ~33 gold_block 0  
fill ~10 ~11 ~39 ~12 ~11 ~39 glass 0 
setblock ~11 ~11 ~18 gold_block 0  
fill ~11 ~11 ~20 ~11 ~15 ~20 glass 0  
fill ~11 ~11 ~23 ~12 ~11 ~23 glass 0  
fill ~11 ~11 ~24 ~11 ~11 ~23 glass 0  
fill ~11 ~11 ~28 ~11 ~11 ~30 lava 2  
fill ~11 ~11 ~33 ~11 ~11 ~35 glass 0  
fill ~11 ~11 ~38 ~11 ~15 ~38 glass 0 
setblock ~11 ~11 ~40 gold_block 0  
fill ~12 ~11 ~21 ~13 ~11 ~21 glass 0  
fill ~12 ~11 ~22 ~12 ~11 ~19 glass 0  
fill ~12 ~11 ~25 ~12 ~11 ~27 lava 2  
fill ~12 ~11 ~28 ~30 ~11 ~28 lava 0  
fill ~12 ~11 ~29 ~31 ~11 ~29 lava 0  
fill ~12 ~11 ~30 ~31 ~11 ~30 lava 0  
fill ~12 ~11 ~31 ~12 ~11 ~33 lava 2  
fill ~12 ~11 ~35 ~12 ~11 ~39 glass 0  
fill ~13 ~11 ~20 ~15 ~11 ~20 glass 0 
setblock ~13 ~11 ~24 lava 2  
fill ~13 ~11 ~25 ~30 ~11 ~25 lava 0  
fill ~13 ~11 ~26 ~29 ~11 ~26 lava 0  
fill ~13 ~11 ~27 ~29 ~11 ~27 lava 0  
fill ~13 ~11 ~31 ~29 ~11 ~31 lava 0  
fill ~13 ~11 ~32 ~29 ~11 ~32 lava 0  
fill ~13 ~11 ~33 ~30 ~11 ~33 lava 0 
setblock ~13 ~11 ~34 lava 10  
fill ~13 ~11 ~37 ~13 ~11 ~38 glass 0 
setblock ~14 ~11 ~23 lava 2  
fill ~14 ~11 ~24 ~14 ~31 ~24 lava 0 
setblock ~14 ~11 ~35 lava 8  
fill ~14 ~11 ~38 ~15 ~11 ~38 glass 0  
fill ~15 ~11 ~19 ~17 ~11 ~19 glass 0 
setblock ~15 ~11 ~22 lava 2  
fill ~15 ~11 ~23 ~15 ~31 ~23 lava 0  
fill ~15 ~11 ~35 ~27 ~11 ~35 lava 0 
setblock ~15 ~11 ~36 lava 2  
fill ~15 ~11 ~39 ~17 ~11 ~39 glass 0 
setblock ~16 ~11 ~21 lava 2  
fill ~16 ~11 ~22 ~26 ~11 ~22 lava 0  
fill ~16 ~11 ~24 ~28 ~11 ~24 lava 0  
fill ~16 ~11 ~34 ~28 ~11 ~34 lava 0  
fill ~16 ~11 ~36 ~26 ~11 ~36 lava 0 
setblock ~16 ~11 ~37 lava 2  
fill ~17 ~11 ~18 ~25 ~11 ~18 glass 0  
fill ~17 ~11 ~20 ~19 ~11 ~20 lava 2  
fill ~17 ~11 ~21 ~25 ~11 ~21 lava 0  
fill ~17 ~11 ~23 ~27 ~11 ~23 lava 0  
fill ~17 ~11 ~37 ~25 ~11 ~37 lava 0  
fill ~17 ~11 ~38 ~19 ~11 ~38 lava 2  
fill ~17 ~11 ~40 ~19 ~11 ~40 glass 0  
fill ~20 ~11 ~19 ~23 ~11 ~19 lava 2  
fill ~20 ~11 ~20 ~22 ~11 ~20 lava 0  
fill ~20 ~11 ~38 ~22 ~11 ~38 lava 0 
setblock ~20 ~11 ~39 lava 2  
fill ~21 ~11 ~39 ~24 ~11 ~39 lava 0 
setblock ~21 ~11 ~40 glass 0  
fill ~23 ~11 ~20 ~24 ~11 ~20 lava 8  
fill ~23 ~11 ~38 ~24 ~11 ~38 lava 8  
fill ~23 ~11 ~40 ~25 ~11 ~40 glass 0 
setblock ~24 ~11 ~19 lava 0  
fill ~25 ~11 ~19 ~27 ~11 ~19 glass 0 
setblock ~25 ~11 ~20 lava 2  
fill ~25 ~11 ~38 ~26 ~11 ~38 lava 0  
fill ~25 ~11 ~39 ~27 ~11 ~39 glass 0 
setblock ~26 ~11 ~21 lava 8 
setblock ~26 ~11 ~37 lava 8  
fill ~27 ~11 ~20 ~31 ~11 ~20 glass 0 
setblock ~27 ~11 ~22 lava 10 
setblock ~27 ~11 ~36 lava 2  
fill ~27 ~11 ~38 ~31 ~11 ~38 glass 0 
setblock ~28 ~11 ~22 lava 2 
setblock ~28 ~11 ~23 lava 8 
setblock ~28 ~11 ~35 lava 2  
fill ~29 ~11 ~21 ~30 ~11 ~21 glass 0  
fill ~29 ~11 ~22 ~29 ~11 ~23 lava 0 
setblock ~29 ~11 ~24 lava 8 
setblock ~29 ~11 ~34 lava 8  
fill ~29 ~11 ~35 ~29 ~30 ~35 lava 0 
setblock ~29 ~11 ~36 lava 2  
fill ~29 ~11 ~37 ~30 ~11 ~37 glass 0  
fill ~30 ~11 ~19 ~31 ~11 ~19 glass 0  
fill ~30 ~11 ~22 ~30 ~11 ~23 glass 0 
setblock ~30 ~11 ~24 lava 0  
fill ~30 ~11 ~26 ~30 ~11 ~27 lava 8  
fill ~30 ~11 ~31 ~30 ~11 ~32 lava 8 
setblock ~30 ~11 ~34 lava 0  
fill ~30 ~11 ~35 ~31 ~11 ~35 glass 0  
fill ~30 ~11 ~36 ~30 ~11 ~35 glass 0  
fill ~30 ~11 ~39 ~32 ~11 ~39 glass 0  
fill ~31 ~11 ~23 ~31 ~11 ~25 glass 0  
fill ~31 ~11 ~26 ~31 ~11 ~27 lava 0 
setblock ~31 ~11 ~28 lava 2  
fill ~31 ~11 ~31 ~31 ~11 ~32 lava 0 
setblock ~31 ~11 ~33 glass 0 
setblock ~31 ~11 ~34 gold_block 0  
fill ~31 ~11 ~40 ~31 ~10 ~40 gold_block 0 
setblock ~32 ~11 ~19 gold_block 0 
setblock ~32 ~11 ~25 glass 0 
setblock ~32 ~11 ~26 gold_block 0 
setblock ~32 ~11 ~27 glass 0  
fill ~32 ~11 ~29 ~32 ~11 ~30 glass 0  
fill ~32 ~11 ~31 ~32 ~11 ~33 gold_block 0  
fill ~8 ~12 ~29 ~8 ~15 ~29 glass 0  
fill ~9 ~12 ~26 ~9 ~13 ~26 gold_block 0  
fill ~9 ~12 ~27 ~9 ~12 ~32 glass 0 
setblock ~10 ~12 ~20 glass 0  
fill ~10 ~12 ~23 ~10 ~13 ~23 glass 0  
fill ~10 ~12 ~24 ~10 ~12 ~25 glass 0  
fill ~10 ~12 ~28 ~10 ~12 ~30 lava 2  
fill ~10 ~12 ~33 ~10 ~12 ~35 glass 0 
setblock ~10 ~12 ~38 glass 0 
setblock ~11 ~12 ~19 gold_block 0  
fill ~11 ~12 ~21 ~12 ~12 ~21 glass 0  
fill ~11 ~12 ~22 ~11 ~12 ~20 glass 0  
fill ~11 ~12 ~25 ~11 ~12 ~27 lava 2  
fill ~11 ~12 ~28 ~31 ~12 ~28 lava 0  
fill ~11 ~12 ~29 ~31 ~12 ~29 lava 0  
fill ~11 ~12 ~30 ~31 ~12 ~30 lava 0  
fill ~11 ~12 ~31 ~11 ~12 ~33 lava 2  
fill ~11 ~12 ~36 ~11 ~12 ~39 glass 0  
fill ~12 ~12 ~18 ~12 ~12 ~21 glass 0  
fill ~12 ~12 ~23 ~12 ~12 ~24 lava 2  
fill ~12 ~12 ~25 ~30 ~12 ~25 lava 0  
fill ~12 ~12 ~26 ~30 ~12 ~26 lava 0  
fill ~12 ~12 ~27 ~30 ~12 ~27 lava 0  
fill ~12 ~12 ~31 ~30 ~12 ~31 lava 0  
fill ~12 ~12 ~32 ~30 ~12 ~32 lava 0  
fill ~12 ~12 ~33 ~30 ~12 ~33 lava 0  
fill ~12 ~12 ~34 ~12 ~12 ~35 lava 2 
setblock ~12 ~12 ~37 glass 0  
fill ~12 ~12 ~39 ~14 ~12 ~39 glass 0 
setblock ~12 ~12 ~40 gold_block 0  
fill ~13 ~12 ~19 ~14 ~12 ~19 glass 0  
fill ~13 ~12 ~20 ~13 ~11 ~20 glass 0 
setblock ~13 ~12 ~22 lava 2  
fill ~13 ~12 ~23 ~29 ~12 ~23 lava 0  
fill ~13 ~12 ~24 ~13 ~30 ~24 lava 0  
fill ~13 ~12 ~34 ~13 ~30 ~34 lava 0  
fill ~13 ~12 ~35 ~29 ~12 ~35 lava 0 
setblock ~13 ~12 ~36 lava 2 
setblock ~13 ~12 ~38 glass 0 
setblock ~14 ~12 ~21 lava 2  
fill ~14 ~12 ~22 ~28 ~12 ~22 lava 0  
fill ~14 ~12 ~36 ~28 ~12 ~36 lava 0 
setblock ~14 ~12 ~37 lava 2  
fill ~15 ~12 ~18 ~17 ~12 ~18 gold_block 0  
fill ~15 ~12 ~20 ~16 ~12 ~20 lava 2  
fill ~15 ~12 ~21 ~27 ~12 ~21 lava 0  
fill ~15 ~12 ~37 ~27 ~12 ~37 lava 0  
fill ~15 ~12 ~38 ~16 ~12 ~38 lava 2  
fill ~15 ~12 ~40 ~17 ~12 ~40 glass 0  
fill ~16 ~12 ~24 ~29 ~12 ~24 lava 0  
fill ~16 ~12 ~34 ~29 ~12 ~34 lava 0  
fill ~17 ~12 ~19 ~19 ~12 ~19 lava 2  
fill ~17 ~12 ~20 ~25 ~12 ~20 lava 0  
fill ~17 ~12 ~38 ~25 ~12 ~38 lava 0  
fill ~17 ~12 ~39 ~19 ~12 ~39 lava 2  
fill ~18 ~12 ~17 ~24 ~12 ~17 glass 0  
fill ~18 ~12 ~41 ~18 ~13 ~41 glass 0 
setblock ~19 ~12 ~41 gold_block 0  
fill ~20 ~12 ~18 ~23 ~12 ~18 lava 2  
fill ~20 ~12 ~19 ~22 ~12 ~19 lava 0  
fill ~20 ~12 ~39 ~22 ~12 ~39 lava 0 
setblock ~20 ~12 ~40 lava 2 
setblock ~20 ~12 ~41 glass 0  
fill ~21 ~12 ~16 ~21 ~15 ~16 glass 0  
fill ~21 ~12 ~40 ~24 ~12 ~40 lava 0 
setblock ~21 ~12 ~42 glass 0  
fill ~22 ~12 ~41 ~24 ~12 ~41 glass 0 
setblock ~23 ~12 ~19 lava 10  
fill ~23 ~12 ~39 ~24 ~12 ~39 lava 8 
setblock ~24 ~12 ~18 lava 0 
setblock ~24 ~12 ~19 lava 8  
fill ~25 ~12 ~18 ~27 ~12 ~18 glass 0  
fill ~25 ~12 ~19 ~27 ~12 ~19 lava 0  
fill ~25 ~12 ~39 ~27 ~12 ~39 lava 0  
fill ~25 ~12 ~40 ~27 ~12 ~40 glass 0 
setblock ~26 ~12 ~20 lava 2 
setblock ~26 ~12 ~38 lava 8  
fill ~27 ~12 ~20 ~28 ~12 ~20 lava 0 
setblock ~27 ~12 ~38 lava 2  
fill ~28 ~12 ~19 ~31 ~12 ~19 glass 0 
setblock ~28 ~12 ~21 lava 2 
setblock ~28 ~12 ~37 lava 2 
setblock ~28 ~12 ~38 lava 0  
fill ~28 ~12 ~39 ~31 ~12 ~39 glass 0 
setblock ~29 ~12 ~20 glass 0 
setblock ~29 ~12 ~22 lava 8 
setblock ~29 ~12 ~36 lava 10 
setblock ~29 ~12 ~37 lava 0 
setblock ~29 ~12 ~38 glass 0 
setblock ~30 ~12 ~18 glass 0  
fill ~30 ~12 ~21 ~31 ~12 ~21 glass 0 
setblock ~30 ~12 ~22 lava 0 
setblock ~30 ~12 ~23 lava 2 
setblock ~30 ~12 ~24 lava 8 
setblock ~30 ~12 ~34 lava 8 
setblock ~30 ~12 ~35 lava 2 
setblock ~30 ~12 ~36 lava 0  
fill ~30 ~12 ~37 ~31 ~12 ~37 glass 0 
setblock ~30 ~12 ~40 gold_block 0 
setblock ~31 ~12 ~20 glass 0 
setblock ~31 ~12 ~22 glass 0  
fill ~31 ~12 ~23 ~31 ~13 ~23 lava 0  
fill ~31 ~12 ~24 ~31 ~12 ~23 lava 0 
setblock ~31 ~12 ~25 lava 2  
fill ~31 ~12 ~26 ~31 ~12 ~27 lava 8  
fill ~31 ~12 ~31 ~31 ~12 ~32 lava 8 
setblock ~31 ~12 ~33 lava 2 
setblock ~31 ~12 ~36 glass 0  
fill ~31 ~12 ~38 ~32 ~12 ~38 glass 0 
setblock ~32 ~12 ~20 gold_block 0  
fill ~32 ~12 ~23 ~32 ~12 ~25 gold_block 0  
fill ~32 ~12 ~26 ~32 ~28 ~26 lava 0  
fill ~32 ~12 ~27 ~32 ~12 ~26 lava 0  
fill ~32 ~12 ~28 ~32 ~12 ~30 lava 2  
fill ~32 ~12 ~33 ~32 ~12 ~35 glass 0  
fill ~33 ~12 ~26 ~33 ~13 ~26 glass 0  
fill ~33 ~12 ~27 ~33 ~12 ~31 glass 0  
fill ~33 ~12 ~32 ~33 ~13 ~32 gold_block 0  
fill ~34 ~12 ~29 ~34 ~15 ~29 glass 0 
setblock ~8 ~13 ~27 gold_block 0 
setblock ~8 ~13 ~28 glass 0  
fill ~8 ~13 ~30 ~8 ~15 ~30 glass 0  
fill ~8 ~13 ~31 ~8 ~14 ~31 glass 0  
fill ~9 ~13 ~24 ~9 ~14 ~24 glass 0  
fill ~9 ~13 ~25 ~9 ~13 ~24 glass 0  
fill ~9 ~13 ~32 ~9 ~13 ~34 glass 0  
fill ~10 ~13 ~21 ~11 ~13 ~21 glass 0  
fill ~10 ~13 ~22 ~10 ~14 ~22 glass 0  
fill ~10 ~13 ~25 ~10 ~13 ~27 lava 2  
fill ~10 ~13 ~28 ~10 ~13 ~30 lava 10  
fill ~10 ~13 ~31 ~10 ~13 ~33 lava 2  
fill ~10 ~13 ~35 ~10 ~13 ~37 glass 0 
setblock ~11 ~13 ~19 glass 0  
fill ~11 ~13 ~23 ~11 ~13 ~24 lava 2  
fill ~11 ~13 ~25 ~32 ~13 ~25 lava 0  
fill ~11 ~13 ~26 ~32 ~13 ~26 lava 0  
fill ~11 ~13 ~27 ~31 ~13 ~27 lava 0  
fill ~11 ~13 ~28 ~31 ~13 ~28 lava 0  
fill ~11 ~13 ~29 ~31 ~13 ~29 lava 0  
fill ~11 ~13 ~30 ~31 ~13 ~30 lava 0  
fill ~11 ~13 ~31 ~31 ~13 ~31 lava 0  
fill ~11 ~13 ~32 ~31 ~13 ~32 lava 0  
fill ~11 ~13 ~33 ~31 ~13 ~33 lava 0  
fill ~11 ~13 ~34 ~11 ~13 ~35 lava 2 
setblock ~11 ~13 ~37 glass 0 
setblock ~11 ~13 ~39 glass 0  
fill ~12 ~13 ~19 ~12 ~15 ~19 gold_block 0 
setblock ~12 ~13 ~22 lava 2  
fill ~12 ~13 ~23 ~31 ~13 ~23 lava 0  
fill ~12 ~13 ~24 ~12 ~29 ~24 lava 0  
fill ~12 ~13 ~34 ~12 ~29 ~34 lava 0  
fill ~12 ~13 ~35 ~30 ~13 ~35 lava 0 
setblock ~12 ~13 ~36 lava 2  
fill ~12 ~13 ~39 ~12 ~14 ~39 gold_block 0  
fill ~13 ~13 ~18 ~14 ~13 ~18 glass 0  
fill ~13 ~13 ~19 ~13 ~12 ~19 glass 0 
setblock ~13 ~13 ~21 lava 2  
fill ~13 ~13 ~22 ~29 ~13 ~22 lava 0  
fill ~13 ~13 ~36 ~29 ~13 ~36 lava 0 
setblock ~13 ~13 ~37 lava 2  
fill ~13 ~13 ~39 ~13 ~13 ~40 glass 0 
setblock ~14 ~13 ~20 lava 2  
fill ~14 ~13 ~21 ~28 ~13 ~21 lava 0  
fill ~14 ~13 ~37 ~28 ~13 ~37 lava 0 
setblock ~14 ~13 ~38 lava 2  
fill ~14 ~13 ~40 ~15 ~13 ~40 glass 0  
fill ~15 ~13 ~18 ~15 ~12 ~18 gold_block 0  
fill ~15 ~13 ~19 ~16 ~13 ~19 lava 2  
fill ~15 ~13 ~20 ~27 ~13 ~20 lava 0  
fill ~15 ~13 ~38 ~27 ~13 ~38 lava 0  
fill ~15 ~13 ~39 ~16 ~13 ~39 lava 2  
fill ~16 ~13 ~17 ~17 ~13 ~17 glass 0  
fill ~16 ~13 ~24 ~30 ~13 ~24 lava 0  
fill ~16 ~13 ~34 ~30 ~13 ~34 lava 0  
fill ~16 ~13 ~41 ~18 ~13 ~41 glass 0  
fill ~17 ~13 ~18 ~19 ~13 ~18 lava 2  
fill ~17 ~13 ~19 ~25 ~13 ~19 lava 0  
fill ~17 ~13 ~39 ~25 ~13 ~39 lava 0  
fill ~17 ~13 ~40 ~19 ~13 ~40 lava 2 
setblock ~18 ~13 ~17 gold_block 0  
fill ~19 ~13 ~16 ~23 ~13 ~16 glass 0 
setblock ~19 ~13 ~42 gold_block 0  
fill ~20 ~13 ~18 ~23 ~13 ~18 lava 10 
setblock ~20 ~13 ~40 lava 10 
setblock ~20 ~13 ~42 glass 0  
fill ~21 ~13 ~40 ~24 ~13 ~40 lava 8 
setblock ~21 ~13 ~42 gold_block 0  
fill ~22 ~13 ~42 ~22 ~15 ~42 glass 0 
setblock ~23 ~13 ~42 gold_block 0  
fill ~24 ~13 ~17 ~26 ~13 ~17 glass 0 
setblock ~24 ~13 ~18 lava 8  
fill ~24 ~13 ~41 ~26 ~13 ~41 glass 0 
setblock ~25 ~13 ~18 lava 2 
setblock ~25 ~13 ~40 lava 2 
setblock ~26 ~13 ~19 lava 8  
fill ~26 ~13 ~39 ~27 ~13 ~39 lava 8  
fill ~27 ~13 ~18 ~29 ~13 ~18 glass 0  
fill ~27 ~13 ~19 ~28 ~13 ~19 lava 0  
fill ~27 ~13 ~40 ~28 ~13 ~40 glass 0 
setblock ~28 ~13 ~20 lava 8 
setblock ~28 ~13 ~38 lava 8  
fill ~29 ~13 ~19 ~31 ~13 ~19 glass 0 
setblock ~29 ~13 ~20 lava 0 
setblock ~29 ~13 ~21 lava 2 
setblock ~29 ~13 ~37 lava 8  
fill ~29 ~13 ~39 ~31 ~13 ~39 glass 0 
setblock ~29 ~13 ~40 gold_block 0 
setblock ~30 ~13 ~21 lava 0 
setblock ~30 ~13 ~22 lava 8 
setblock ~30 ~13 ~36 lava 8  
fill ~31 ~13 ~20 ~31 ~14 ~20 gold_block 0  
fill ~31 ~13 ~21 ~32 ~13 ~21 glass 0 
setblock ~31 ~13 ~22 lava 0 
setblock ~31 ~13 ~24 lava 8  
fill ~31 ~13 ~34 ~31 ~13 ~35 lava 2  
fill ~31 ~13 ~37 ~32 ~13 ~37 glass 0  
fill ~31 ~13 ~38 ~31 ~15 ~38 glass 0  
fill ~32 ~13 ~22 ~32 ~14 ~22 glass 0  
fill ~32 ~13 ~23 ~32 ~13 ~21 glass 0 
setblock ~32 ~13 ~24 lava 0 
setblock ~32 ~13 ~27 lava 8  
fill ~32 ~13 ~28 ~32 ~13 ~30 lava 10  
fill ~32 ~13 ~31 ~32 ~13 ~33 lava 2  
fill ~32 ~13 ~35 ~32 ~13 ~37 glass 0  
fill ~33 ~13 ~24 ~33 ~14 ~24 glass 0 
setblock ~33 ~13 ~25 gold_block 0 
setblock ~33 ~13 ~27 lava 0 
setblock ~33 ~13 ~28 lava 2  
fill ~33 ~13 ~33 ~33 ~13 ~34 glass 0  
fill ~34 ~13 ~27 ~34 ~14 ~27 glass 0  
fill ~34 ~13 ~28 ~34 ~15 ~28 glass 0  
fill ~34 ~13 ~30 ~34 ~15 ~30 glass 0  
fill ~34 ~13 ~31 ~34 ~14 ~31 glass 0 
setblock ~4 ~14 ~23 gold_block 0 
setblock ~4 ~14 ~35 gold_block 0 
setblock ~8 ~14 ~25 gold_block 0  
fill ~8 ~14 ~26 ~8 ~15 ~26 glass 0  
fill ~8 ~14 ~27 ~8 ~14 ~26 glass 0 
setblock ~8 ~14 ~28 gold_block 0  
fill ~8 ~14 ~32 ~8 ~15 ~32 glass 0  
fill ~8 ~14 ~33 ~8 ~15 ~33 glass 0  
fill ~9 ~14 ~23 ~9 ~15 ~23 glass 0  
fill ~9 ~14 ~26 ~9 ~14 ~32 lava 2  
fill ~9 ~14 ~34 ~9 ~14 ~36 glass 0  
fill ~10 ~14 ~21 ~10 ~15 ~21 glass 0 
setblock ~10 ~14 ~24 lava 2 
setblock ~10 ~14 ~25 lava 10  
fill ~10 ~14 ~26 ~32 ~14 ~26 lava 0  
fill ~10 ~14 ~27 ~32 ~14 ~27 lava 0   
fill ~10 ~14 ~28 ~32 ~14 ~28 lava 0  
fill ~10 ~14 ~29 ~32 ~14 ~29 lava 0  
fill ~10 ~14 ~30 ~32 ~14 ~30 lava 0  
fill ~10 ~14 ~31 ~32 ~14 ~31 lava 0  
fill ~10 ~14 ~32 ~33 ~14 ~32 lava 0 
setblock ~10 ~14 ~33 lava 10 
setblock ~10 ~14 ~34 lava 2  
fill ~10 ~14 ~36 ~10 ~14 ~37 glass 0 
setblock ~11 ~14 ~22 lava 2 
setblock ~11 ~14 ~23 lava 10  
fill ~11 ~14 ~24 ~11 ~28 ~24 lava 0  
fill ~11 ~14 ~25 ~31 ~14 ~25 lava 0  
fill ~11 ~14 ~33 ~31 ~14 ~33 lava 0  
fill ~11 ~14 ~34 ~11 ~28 ~34 lava 0 
setblock ~11 ~14 ~35 lava 10 
setblock ~11 ~14 ~36 lava 2 
setblock ~12 ~14 ~21 lava 2  
fill ~12 ~14 ~22 ~30 ~14 ~22 lava 0  
fill ~12 ~14 ~23 ~30 ~14 ~23 lava 0  
fill ~12 ~14 ~35 ~30 ~14 ~35 lava 0  
fill ~12 ~14 ~36 ~31 ~14 ~36 lava 0 
setblock ~12 ~14 ~37 lava 2  
fill ~13 ~14 ~18 ~14 ~14 ~18 glass 0 
setblock ~13 ~14 ~20 lava 2  
fill ~13 ~14 ~21 ~29 ~14 ~21 lava 0  
fill ~13 ~14 ~37 ~29 ~14 ~37 lava 0 
setblock ~13 ~14 ~38 lava 2  
fill ~13 ~14 ~40 ~14 ~14 ~40 glass 0  
fill ~14 ~14 ~17 ~16 ~14 ~17 glass 0 
setblock ~14 ~14 ~19 lava 2  
fill ~14 ~14 ~20 ~28 ~14 ~20 lava 0  
fill ~14 ~14 ~38 ~28 ~14 ~38 lava 0 
setblock ~14 ~14 ~39 lava 2 
setblock ~15 ~14 ~12 gold_block 0 
setblock ~15 ~14 ~19 lava 10 
setblock ~15 ~14 ~39 lava 10  
fill ~15 ~14 ~41 ~16 ~14 ~41 glass 0 
setblock ~15 ~14 ~46 gold_block 0 
setblock ~16 ~14 ~18 lava 2  
fill ~16 ~14 ~19 ~26 ~14 ~19 lava 0  
fill ~16 ~14 ~24 ~31 ~14 ~24 lava 0  
fill ~16 ~14 ~34 ~32 ~14 ~34 lava 0  
fill ~16 ~14 ~39 ~26 ~14 ~39 lava 0 
setblock ~16 ~14 ~40 lava 2 
setblock ~17 ~14 ~16 gold_block 0 
setblock ~17 ~14 ~18 lava 10 
setblock ~17 ~14 ~40 lava 10  
fill ~17 ~14 ~42 ~17 ~15 ~42 glass 0  
fill ~18 ~14 ~16 ~25 ~14 ~16 glass 0  
fill ~18 ~14 ~17 ~24 ~14 ~17 lava 2  
fill ~18 ~14 ~18 ~24 ~14 ~18 lava 0  
fill ~18 ~14 ~40 ~24 ~14 ~40 lava 0  
fill ~18 ~14 ~41 ~24 ~14 ~41 lava 2 
setblock ~18 ~14 ~42 gold_block 0 
setblock ~19 ~14 ~42 glass 0 
setblock ~20 ~14 ~42 gold_block 0 
setblock ~21 ~14 ~42 glass 0  
fill ~23 ~14 ~42 ~25 ~14 ~42 glass 0 
setblock ~25 ~14 ~18 lava 10 
setblock ~25 ~14 ~40 lava 10  
fill ~26 ~14 ~17 ~27 ~14 ~17 glass 0 
setblock ~26 ~14 ~18 lava 2 
setblock ~26 ~14 ~40 lava 2  
fill ~26 ~14 ~41 ~27 ~14 ~41 glass 0 
setblock ~27 ~14 ~12 gold_block 0  
fill ~27 ~14 ~19 ~28 ~14 ~19 lava 8 
setblock ~27 ~14 ~39 lava 8 
setblock ~27 ~14 ~46 gold_block 0  
fill ~28 ~14 ~18 ~29 ~14 ~18 glass 0 
setblock ~28 ~14 ~39 lava 2  
fill ~28 ~14 ~40 ~29 ~14 ~40 glass 0  
fill ~28 ~14 ~41 ~28 ~15 ~41 gold_block 0 
setblock ~29 ~14 ~20 lava 8 
setblock ~29 ~14 ~38 lava 2 
setblock ~30 ~14 ~19 glass 0 
setblock ~30 ~14 ~21 lava 8  
fill ~30 ~14 ~37 ~31 ~14 ~37 lava 2  
fill ~30 ~14 ~39 ~30 ~15 ~39 glass 0  
fill ~31 ~14 ~22 ~31 ~15 ~22 lava 8  
fill ~31 ~14 ~23 ~31 ~14 ~22 lava 8 
setblock ~31 ~14 ~35 lava 10  
fill ~32 ~14 ~21 ~32 ~15 ~21 glass 0  
fill ~32 ~14 ~24 ~32 ~14 ~25 lava 8 
setblock ~32 ~14 ~33 lava 10 
setblock ~32 ~14 ~35 lava 2  
fill ~32 ~14 ~36 ~32 ~14 ~37 glass 0  
fill ~33 ~14 ~22 ~33 ~16 ~22 glass 0  
fill ~33 ~14 ~23 ~33 ~15 ~23 glass 0 
setblock ~33 ~14 ~26 lava 2  
fill ~33 ~14 ~27 ~33 ~15 ~27 lava 8 
setblock ~33 ~14 ~28 lava 10  
fill ~33 ~14 ~29 ~33 ~14 ~31 lava 2 
setblock ~33 ~14 ~33 lava 2  
fill ~33 ~14 ~34 ~33 ~14 ~35 glass 0 
setblock ~34 ~14 ~25 gold_block 0  
fill ~34 ~14 ~26 ~34 ~15 ~26 glass 0 
setblock ~34 ~14 ~32 gold_block 0  
fill ~34 ~14 ~33 ~34 ~15 ~33 glass 0 
setblock ~38 ~14 ~23 gold_block 0 
setblock ~38 ~14 ~35 gold_block 0  
fill ~5 ~15 ~24 ~7 ~15 ~24 gold_block 0 
setblock ~5 ~15 ~34 gold_block 0  
fill ~6 ~15 ~25 ~8 ~15 ~25 glass 0  
fill ~6 ~15 ~33 ~8 ~15 ~33 glass 0  
fill ~6 ~15 ~34 ~8 ~15 ~34 glass 0  
fill ~7 ~15 ~23 ~9 ~15 ~23 glass 0  
fill ~7 ~15 ~26 ~7 ~18 ~26 glass 0  
fill ~7 ~15 ~27 ~7 ~17 ~27 glass 0  
fill ~7 ~15 ~31 ~7 ~17 ~31 glass 0  
fill ~7 ~15 ~32 ~7 ~18 ~32 glass 0  
fill ~7 ~15 ~35 ~9 ~15 ~35 glass 0  
fill ~8 ~15 ~24 ~8 ~16 ~24 glass 0 
setblock ~8 ~15 ~28 glass 0  
fill ~9 ~15 ~22 ~9 ~16 ~22 glass 0  
fill ~9 ~15 ~24 ~9 ~15 ~25 lava 2  
fill ~9 ~15 ~26 ~9 ~15 ~27 lava 10  
fill ~9 ~15 ~28 ~33 ~15 ~28 lava 0  
fill ~9 ~15 ~29 ~33 ~15 ~29 lava 0  
fill ~9 ~15 ~30 ~33 ~15 ~30 lava 0  
fill ~9 ~15 ~31 ~9 ~15 ~32 lava 10  
fill ~9 ~15 ~33 ~9 ~15 ~34 lava 2  
fill ~9 ~15 ~36 ~9 ~16 ~36 glass 0  
fill ~10 ~15 ~20 ~10 ~16 ~20 glass 0 
setblock ~10 ~15 ~23 lava 2  
fill ~10 ~15 ~24 ~10 ~27 ~24 lava 0  
fill ~10 ~15 ~25 ~32 ~15 ~25 lava 0  
fill ~10 ~15 ~26 ~32 ~15 ~26 lava 0  
fill ~10 ~15 ~27 ~32 ~15 ~27 lava 0  
fill ~10 ~15 ~31 ~32 ~15 ~31 lava 0  
fill ~10 ~15 ~32 ~32 ~15 ~32 lava 0  
fill ~10 ~15 ~33 ~32 ~15 ~33 lava 0  
fill ~10 ~15 ~34 ~10 ~27 ~34 lava 0 
setblock ~10 ~15 ~35 lava 2  
fill ~10 ~15 ~37 ~10 ~15 ~38 glass 0 
setblock ~11 ~15 ~21 lava 2 
setblock ~11 ~15 ~22 lava 10  
fill ~11 ~15 ~23 ~31 ~15 ~23 lava 0  
fill ~11 ~15 ~35 ~31 ~15 ~35 lava 0 
setblock ~11 ~15 ~36 lava 10 
setblock ~11 ~15 ~37 lava 2  
fill ~12 ~15 ~18 ~13 ~15 ~18 glass 0 
setblock ~12 ~15 ~20 lava 2  
fill ~12 ~15 ~21 ~30 ~15 ~21 lava 0  
fill ~12 ~15 ~22 ~30 ~15 ~22 lava 0  
fill ~12 ~15 ~36 ~30 ~15 ~36 lava 0  
fill ~12 ~15 ~37 ~30 ~15 ~37 lava 0 
setblock ~12 ~15 ~38 lava 2 
setblock ~12 ~15 ~39 glass 0 
setblock ~12 ~15 ~40 gold_block 0 
setblock ~13 ~15 ~19 lava 2  
fill ~13 ~15 ~20 ~29 ~15 ~20 lava 0  
fill ~13 ~15 ~38 ~30 ~15 ~38 lava 0 
setblock ~13 ~15 ~39 lava 2  
fill ~13 ~15 ~40 ~13 ~13 ~40 glass 0  
fill ~14 ~15 ~17 ~15 ~15 ~17 glass 0 
setblock ~14 ~15 ~19 lava 10 
setblock ~14 ~15 ~39 lava 10  
fill ~14 ~15 ~41 ~15 ~15 ~41 glass 0  
fill ~15 ~15 ~15 ~15 ~16 ~15 glass 0  
fill ~15 ~15 ~16 ~18 ~15 ~16 glass 0 
setblock ~15 ~15 ~18 lava 2  
fill ~15 ~15 ~19 ~27 ~15 ~19 lava 0  
fill ~15 ~15 ~39 ~27 ~15 ~39 lava 0 
setblock ~15 ~15 ~40 lava 2  
fill ~15 ~15 ~42 ~18 ~15 ~42 glass 0  
fill ~15 ~15 ~43 ~16 ~15 ~43 glass 0  
fill ~16 ~15 ~13 ~16 ~15 ~15 gold_block 0  
fill ~16 ~15 ~17 ~17 ~15 ~17 lava 2  
fill ~16 ~15 ~18 ~26 ~15 ~18 lava 0  
fill ~16 ~15 ~24 ~32 ~15 ~24 lava 0  
fill ~16 ~15 ~34 ~32 ~15 ~34 lava 0  
fill ~16 ~15 ~40 ~26 ~15 ~40 lava 0  
fill ~16 ~15 ~41 ~17 ~15 ~41 lava 2  
fill ~16 ~15 ~44 ~16 ~15 ~45 gold_block 0  
fill ~17 ~15 ~14 ~17 ~15 ~16 glass 0 
setblock ~17 ~15 ~43 gold_block 0  
fill ~17 ~15 ~44 ~17 ~19 ~44 glass 0  
fill ~18 ~15 ~15 ~19 ~15 ~15 glass 0  
fill ~18 ~15 ~17 ~19 ~15 ~17 lava 10  
fill ~18 ~15 ~41 ~19 ~15 ~41 lava 10  
fill ~18 ~15 ~43 ~19 ~15 ~43 glass 0 
setblock ~20 ~15 ~16 glass 0  
fill ~20 ~15 ~17 ~22 ~15 ~17 lava 0  
fill ~20 ~15 ~41 ~22 ~15 ~41 lava 0 
setblock ~20 ~15 ~42 glass 0 
setblock ~21 ~15 ~42 gold_block 0 
setblock ~22 ~15 ~16 glass 0  
fill ~23 ~15 ~15 ~27 ~15 ~15 glass 0  
fill ~23 ~15 ~17 ~24 ~15 ~17 lava 10  
fill ~23 ~15 ~41 ~24 ~15 ~41 lava 10  
fill ~23 ~15 ~43 ~27 ~15 ~43 glass 0  
fill ~24 ~15 ~16 ~27 ~15 ~16 glass 0  
fill ~24 ~15 ~42 ~26 ~15 ~42 glass 0  
fill ~25 ~15 ~14 ~25 ~17 ~14 gold_block 0  
fill ~25 ~15 ~17 ~26 ~15 ~17 lava 2  
fill ~25 ~15 ~41 ~26 ~15 ~41 lava 2  
fill ~25 ~15 ~44 ~26 ~15 ~44 glass 0 
setblock ~26 ~15 ~13 gold_block 0  
fill ~26 ~15 ~14 ~26 ~16 ~14 glass 0 
setblock ~26 ~15 ~45 gold_block 0  
fill ~27 ~15 ~17 ~28 ~15 ~17 glass 0 
setblock ~27 ~15 ~18 lava 2 
setblock ~27 ~15 ~40 lava 2 
setblock ~27 ~15 ~41 glass 0 
setblock ~27 ~15 ~42 gold_block 0 
setblock ~28 ~15 ~19 lava 8 
setblock ~28 ~15 ~39 lava 10  
fill ~29 ~15 ~18 ~30 ~15 ~18 glass 0 
setblock ~29 ~15 ~19 lava 2 
setblock ~29 ~15 ~39 lava 2 
setblock ~29 ~15 ~40 gold_block 0 
setblock ~30 ~15 ~19 gold_block 0 
setblock ~30 ~15 ~20 lava 2 
setblock ~30 ~15 ~40 glass 0  
fill ~31 ~15 ~20 ~32 ~15 ~20 glass 0 
setblock ~31 ~15 ~21 lava 2 
setblock ~31 ~15 ~36 lava 8  
fill ~31 ~15 ~37 ~31 ~16 ~37 lava 10 
setblock ~32 ~15 ~23 lava 2 
setblock ~32 ~15 ~35 lava 10  
fill ~32 ~15 ~37 ~32 ~15 ~38 glass 0  
fill ~33 ~15 ~24 ~33 ~15 ~25 lava 2 
setblock ~33 ~15 ~26 lava 10 
setblock ~33 ~15 ~31 lava 10 
setblock ~33 ~15 ~32 lava 8  
fill ~33 ~15 ~33 ~33 ~16 ~33 lava 10 
setblock ~33 ~15 ~34 lava 2  
fill ~33 ~15 ~35 ~35 ~15 ~35 glass 0  
fill ~33 ~15 ~36 ~33 ~16 ~36 glass 0  
fill ~34 ~15 ~23 ~35 ~15 ~23 glass 0  
fill ~34 ~15 ~24 ~37 ~15 ~24 gold_block 0  
fill ~34 ~15 ~25 ~36 ~15 ~25 glass 0  
fill ~34 ~15 ~32 ~35 ~15 ~32 glass 0  
fill ~34 ~15 ~34 ~36 ~15 ~34 glass 0  
fill ~35 ~15 ~26 ~35 ~18 ~26 glass 0  
fill ~35 ~15 ~27 ~35 ~17 ~27 glass 0 
setblock ~35 ~15 ~31 glass 0  
fill ~35 ~15 ~33 ~36 ~15 ~33 gold_block 0 
setblock ~37 ~15 ~34 gold_block 0  
fill ~6 ~16 ~23 ~8 ~16 ~23 glass 0  
fill ~6 ~16 ~24 ~8 ~16 ~24 glass 0  
fill ~6 ~16 ~25 ~7 ~16 ~25 glass 0 
setblock ~6 ~16 ~33 gold_block 0  
fill ~6 ~16 ~34 ~8 ~16 ~34 glass 0  
fill ~6 ~16 ~35 ~8 ~16 ~35 glass 0 
setblock ~7 ~16 ~22 glass 0  
fill ~7 ~16 ~28 ~7 ~17 ~28 glass 0  
fill ~7 ~16 ~29 ~7 ~16 ~36 glass 0  
fill ~8 ~16 ~26 ~8 ~16 ~32 lava 2  
fill ~9 ~16 ~21 ~9 ~18 ~21 glass 0 
setblock ~9 ~16 ~23 lava 2  
fill ~9 ~16 ~24 ~9 ~17 ~24 lava 10  
fill ~9 ~16 ~25 ~9 ~16 ~24 lava 10  
fill ~9 ~16 ~26 ~33 ~16 ~26 lava 0  
fill ~9 ~16 ~27 ~33 ~16 ~27 lava 0  
fill ~9 ~16 ~28 ~33 ~16 ~28 lava 0  
fill ~9 ~16 ~29 ~33 ~16 ~29 lava 0  
fill ~9 ~16 ~30 ~33 ~16 ~30 lava 0  
fill ~9 ~16 ~31 ~33 ~16 ~31 lava 0  
fill ~9 ~16 ~32 ~33 ~16 ~32 lava 0  
fill ~9 ~16 ~33 ~9 ~16 ~34 lava 10 
setblock ~9 ~16 ~35 lava 2  
fill ~9 ~16 ~37 ~9 ~17 ~37 gold_block 0 
setblock ~10 ~16 ~22 lava 2  
fill ~10 ~16 ~23 ~32 ~16 ~23 lava 0  
fill ~10 ~16 ~25 ~32 ~16 ~25 lava 0  
fill ~10 ~16 ~33 ~32 ~16 ~33 lava 0  
fill ~10 ~16 ~35 ~32 ~16 ~35 lava 0 
setblock ~10 ~16 ~36 lava 2 
setblock ~10 ~16 ~38 glass 0 
setblock ~11 ~16 ~19 gold_block 0 
setblock ~11 ~16 ~21 lava 10  
fill ~11 ~16 ~22 ~31 ~16 ~22 lava 0  
fill ~11 ~16 ~36 ~31 ~16 ~36 lava 0 
setblock ~11 ~16 ~37 lava 10  
fill ~11 ~16 ~39 ~11 ~18 ~39 gold_block 0  
fill ~12 ~16 ~18 ~12 ~15 ~18 glass 0 
setblock ~12 ~16 ~20 lava 10  
fill ~12 ~16 ~21 ~30 ~16 ~21 lava 0  
fill ~12 ~16 ~37 ~30 ~16 ~37 lava 0 
setblock ~12 ~16 ~38 lava 10  
fill ~12 ~16 ~40 ~12 ~18 ~40 glass 0  
fill ~13 ~16 ~17 ~14 ~16 ~17 glass 0 
setblock ~13 ~16 ~19 lava 10  
fill ~13 ~16 ~20 ~29 ~16 ~20 lava 0  
fill ~13 ~16 ~38 ~29 ~16 ~38 lava 0 
setblock ~13 ~16 ~39 lava 10  
fill ~13 ~16 ~41 ~14 ~16 ~41 glass 0 
setblock ~14 ~16 ~15 glass 0 
setblock ~14 ~16 ~18 lava 2  
fill ~14 ~16 ~19 ~28 ~16 ~19 lava 0  
fill ~14 ~16 ~39 ~28 ~16 ~39 lava 0 
setblock ~14 ~16 ~40 lava 2  
fill ~14 ~16 ~43 ~21 ~16 ~43 glass 0  
fill ~15 ~16 ~14 ~16 ~16 ~14 glass 0  
fill ~15 ~16 ~16 ~16 ~16 ~16 glass 0 
setblock ~15 ~16 ~17 lava 2  
fill ~15 ~16 ~18 ~27 ~16 ~18 lava 0  
fill ~15 ~16 ~40 ~27 ~16 ~40 lava 0 
setblock ~15 ~16 ~41 lava 2  
fill ~15 ~16 ~42 ~16 ~16 ~42 glass 0  
fill ~15 ~16 ~44 ~17 ~16 ~44 glass 0  
fill ~16 ~16 ~15 ~28 ~16 ~15 glass 0  
fill ~16 ~16 ~17 ~17 ~16 ~17 lava 10  
fill ~16 ~16 ~24 ~32 ~16 ~24 lava 0  
fill ~16 ~16 ~34 ~32 ~16 ~34 lava 0  
fill ~16 ~16 ~41 ~17 ~16 ~41 lava 10  
fill ~17 ~16 ~14 ~17 ~17 ~14 gold_block 0  
fill ~18 ~16 ~16 ~24 ~16 ~16 lava 2  
fill ~18 ~16 ~17 ~24 ~16 ~17 lava 0  
fill ~18 ~16 ~41 ~24 ~16 ~41 lava 0  
fill ~18 ~16 ~42 ~24 ~16 ~42 lava 2  
fill ~22 ~16 ~43 ~22 ~17 ~43 gold_block 0  
fill ~23 ~16 ~43 ~27 ~16 ~43 glass 0  
fill ~25 ~16 ~17 ~26 ~16 ~17 lava 10  
fill ~25 ~16 ~41 ~26 ~16 ~41 lava 10  
fill ~25 ~16 ~44 ~26 ~16 ~44 glass 0  
fill ~26 ~16 ~16 ~27 ~16 ~16 glass 0  
fill ~26 ~16 ~42 ~27 ~16 ~42 glass 0 
setblock ~27 ~16 ~14 glass 0 
setblock ~27 ~16 ~17 lava 2 
setblock ~27 ~16 ~41 lava 2 
setblock ~27 ~16 ~44 gold_block 0 
setblock ~28 ~16 ~17 glass 0 
setblock ~28 ~16 ~18 lava 2 
setblock ~28 ~16 ~40 lava 2  
fill ~28 ~16 ~41 ~29 ~16 ~41 glass 0 
setblock ~28 ~16 ~43 gold_block 0 
setblock ~29 ~16 ~17 gold_block 0 
setblock ~29 ~16 ~19 lava 10 
setblock ~29 ~16 ~39 lava 10 
setblock ~30 ~16 ~18 gold_block 0 
setblock ~30 ~16 ~20 lava 10 
setblock ~30 ~16 ~38 lava 8  
fill ~30 ~16 ~40 ~30 ~17 ~40 gold_block 0  
fill ~31 ~16 ~19 ~31 ~18 ~19 gold_block 0 
setblock ~31 ~16 ~21 lava 10  
fill ~31 ~16 ~39 ~31 ~18 ~39 glass 0  
fill ~32 ~16 ~20 ~32 ~18 ~20 glass 0 
setblock ~32 ~16 ~22 lava 2 
setblock ~32 ~16 ~36 lava 2  
fill ~32 ~16 ~38 ~32 ~18 ~38 glass 0  
fill ~33 ~16 ~21 ~33 ~18 ~21 glass 0 
setblock ~33 ~16 ~23 lava 2  
fill ~33 ~16 ~24 ~33 ~17 ~24 lava 10  
fill ~33 ~16 ~25 ~33 ~16 ~24 lava 10  
fill ~33 ~16 ~34 ~33 ~17 ~34 lava 10 
setblock ~33 ~16 ~35 lava 2  
fill ~33 ~16 ~37 ~33 ~18 ~37 glass 0  
fill ~34 ~16 ~23 ~36 ~16 ~23 glass 0  
fill ~34 ~16 ~24 ~36 ~16 ~24 glass 0  
fill ~34 ~16 ~26 ~34 ~16 ~32 lava 2  
fill ~34 ~16 ~34 ~36 ~16 ~34 glass 0  
fill ~34 ~16 ~35 ~36 ~16 ~35 glass 0 
setblock ~35 ~16 ~22 glass 0  
fill ~35 ~16 ~25 ~35 ~27 ~25 glass 0  
fill ~35 ~16 ~28 ~35 ~17 ~28 glass 0  
fill ~35 ~16 ~29 ~35 ~17 ~29 glass 0  
fill ~35 ~16 ~30 ~35 ~17 ~30 glass 0 
setblock ~35 ~16 ~31 gold_block 0  
fill ~35 ~16 ~32 ~35 ~18 ~32 glass 0  
fill ~35 ~16 ~33 ~35 ~19 ~33 glass 0 
setblock ~35 ~16 ~36 glass 0  
fill ~36 ~16 ~25 ~36 ~17 ~25 gold_block 0 
setblock ~36 ~16 ~33 gold_block 0  
fill ~6 ~17 ~25 ~7 ~17 ~25 glass 0  
fill ~6 ~17 ~26 ~6 ~25 ~26 glass 0  
fill ~6 ~17 ~27 ~6 ~19 ~27 glass 0  
fill ~6 ~17 ~31 ~6 ~17 ~32 gold_block 0  
fill ~6 ~17 ~33 ~7 ~17 ~33 glass 0  
fill ~7 ~17 ~24 ~7 ~23 ~24 glass 0  
fill ~7 ~17 ~29 ~7 ~17 ~30 gold_block 0  
fill ~7 ~17 ~34 ~7 ~22 ~34 glass 0  
fill ~8 ~17 ~22 ~8 ~23 ~22 glass 0  
fill ~8 ~17 ~23 ~8 ~18 ~23 glass 0 
setblock ~8 ~17 ~25 lava 2  
fill ~8 ~17 ~26 ~8 ~18 ~26 lava 10  
fill ~8 ~17 ~27 ~8 ~17 ~32 lava 10 
setblock ~8 ~17 ~33 lava 2  
fill ~8 ~17 ~35 ~8 ~18 ~35 glass 0  
fill ~8 ~17 ~36 ~8 ~24 ~36 glass 0  
fill ~9 ~17 ~23 ~9 ~19 ~23 lava 10  
fill ~9 ~17 ~25 ~33 ~17 ~25 lava 0  
fill ~9 ~17 ~26 ~33 ~17 ~26 lava 0  
fill ~9 ~17 ~27 ~33 ~17 ~27 lava 0  
fill ~9 ~17 ~28 ~33 ~17 ~28 lava 0  
fill ~9 ~17 ~29 ~33 ~17 ~29 lava 0  
fill ~9 ~17 ~30 ~33 ~17 ~30 lava 0  
fill ~9 ~17 ~31 ~33 ~17 ~31 lava 0  
fill ~9 ~17 ~32 ~33 ~17 ~32 lava 0  
fill ~9 ~17 ~33 ~33 ~17 ~33 lava 0  
fill ~9 ~17 ~34 ~9 ~17 ~35 lava 10 
setblock ~10 ~17 ~20 gold_block 0 
setblock ~10 ~17 ~21 lava 2 
setblock ~10 ~17 ~22 lava 10  
fill ~10 ~17 ~23 ~32 ~17 ~23 lava 0  
fill ~10 ~17 ~35 ~32 ~17 ~35 lava 0 
setblock ~10 ~17 ~36 lava 10 
setblock ~10 ~17 ~37 lava 2 
setblock ~10 ~17 ~38 gold_block 0  
fill ~11 ~17 ~19 ~11 ~18 ~19 glass 0 
setblock ~11 ~17 ~20 lava 2  
fill ~11 ~17 ~21 ~31 ~17 ~21 lava 0  
fill ~11 ~17 ~22 ~31 ~17 ~22 lava 0  
fill ~11 ~17 ~36 ~31 ~17 ~36 lava 0  
fill ~11 ~17 ~37 ~31 ~17 ~37 lava 0 
setblock ~11 ~17 ~38 lava 2 
setblock ~12 ~17 ~18 gold_block 0 
setblock ~12 ~17 ~19 lava 2  
fill ~12 ~17 ~20 ~30 ~17 ~20 lava 0  
fill ~12 ~17 ~38 ~30 ~17 ~38 lava 0 
setblock ~12 ~17 ~39 lava 2  
fill ~13 ~17 ~17 ~13 ~18 ~17 glass 0 
setblock ~13 ~17 ~18 lava 2  
fill ~13 ~17 ~19 ~29 ~17 ~19 lava 0  
fill ~13 ~17 ~39 ~29 ~17 ~39 lava 0 
setblock ~13 ~17 ~40 lava 2  
fill ~13 ~17 ~41 ~13 ~18 ~41 glass 0  
fill ~14 ~17 ~16 ~15 ~17 ~16 glass 0 
setblock ~14 ~17 ~18 lava 10 
setblock ~14 ~17 ~40 lava 10  
fill ~14 ~17 ~42 ~15 ~17 ~42 glass 0  
fill ~15 ~17 ~17 ~16 ~17 ~17 lava 10  
fill ~15 ~17 ~18 ~27 ~17 ~18 lava 0  
fill ~15 ~17 ~40 ~27 ~17 ~40 lava 0  
fill ~15 ~17 ~41 ~16 ~17 ~41 lava 10 
setblock ~16 ~17 ~15 gold_block 0  
fill ~16 ~17 ~24 ~32 ~17 ~24 lava 0  
fill ~16 ~17 ~34 ~32 ~17 ~34 lava 0  
fill ~16 ~17 ~43 ~21 ~17 ~43 glass 0  
fill ~17 ~17 ~15 ~26 ~17 ~15 glass 0 
setblock ~17 ~17 ~16 lava 2  
fill ~17 ~17 ~17 ~25 ~17 ~17 lava 0  
fill ~17 ~17 ~41 ~25 ~17 ~41 lava 0 
setblock ~17 ~17 ~42 lava 2  
fill ~18 ~17 ~14 ~19 ~17 ~14 gold_block 0  
fill ~18 ~17 ~16 ~24 ~17 ~16 lava 10  
fill ~18 ~17 ~42 ~24 ~17 ~42 lava 10  
fill ~18 ~17 ~44 ~19 ~17 ~44 glass 0  
fill ~23 ~17 ~14 ~23 ~19 ~14 glass 0  
fill ~23 ~17 ~43 ~26 ~17 ~43 glass 0  
fill ~23 ~17 ~44 ~25 ~17 ~44 glass 0 
setblock ~24 ~17 ~14 gold_block 0 
setblock ~25 ~17 ~16 lava 2 
setblock ~25 ~17 ~42 lava 2  
fill ~26 ~17 ~17 ~27 ~17 ~17 lava 10  
fill ~26 ~17 ~41 ~27 ~17 ~41 lava 10  
fill ~27 ~17 ~16 ~27 ~18 ~16 glass 0  
fill ~27 ~17 ~42 ~27 ~18 ~42 gold_block 0 
setblock ~28 ~17 ~16 gold_block 0 
setblock ~28 ~17 ~18 lava 10 
setblock ~28 ~17 ~40 lava 10  
fill ~28 ~17 ~42 ~28 ~25 ~42 glass 0  
fill ~29 ~17 ~17 ~29 ~18 ~17 glass 0 
setblock ~29 ~17 ~18 lava 2 
setblock ~29 ~17 ~40 lava 2  
fill ~29 ~17 ~41 ~29 ~18 ~41 glass 0  
fill ~30 ~17 ~18 ~30 ~18 ~18 glass 0 
setblock ~30 ~17 ~19 lava 2 
setblock ~30 ~17 ~39 lava 2 
setblock ~31 ~17 ~20 lava 2 
setblock ~31 ~17 ~38 lava 2 
setblock ~32 ~17 ~21 lava 2 
setblock ~32 ~17 ~22 lava 10 
setblock ~32 ~17 ~36 lava 10 
setblock ~32 ~17 ~37 lava 2  
fill ~33 ~17 ~23 ~33 ~19 ~23 lava 10  
fill ~33 ~17 ~35 ~33 ~19 ~35 lava 10  
fill ~34 ~17 ~22 ~34 ~25 ~22 glass 0  
fill ~34 ~17 ~23 ~34 ~18 ~23 glass 0 
setblock ~34 ~17 ~25 lava 2  
fill ~34 ~17 ~26 ~34 ~18 ~26 lava 10  
fill ~34 ~17 ~27 ~34 ~17 ~32 lava 10 
setblock ~34 ~17 ~33 lava 2  
fill ~34 ~17 ~35 ~34 ~18 ~35 glass 0  
fill ~34 ~17 ~36 ~34 ~25 ~36 glass 0  
fill ~35 ~17 ~24 ~35 ~21 ~24 glass 0  
fill ~35 ~17 ~31 ~36 ~17 ~31 glass 0  
fill ~35 ~17 ~34 ~35 ~19 ~34 glass 0  
fill ~36 ~17 ~26 ~36 ~17 ~27 glass 0  
fill ~36 ~17 ~32 ~36 ~18 ~32 gold_block 0  
fill ~36 ~17 ~33 ~36 ~19 ~33 glass 0  
fill ~6 ~18 ~25 ~7 ~18 ~25 glass 0 
setblock ~6 ~18 ~28 glass 0 
setblock ~6 ~18 ~29 gold_block 0  
fill ~6 ~18 ~30 ~6 ~18 ~31 glass 0  
fill ~6 ~18 ~32 ~6 ~20 ~32 gold_block 0  
fill ~6 ~18 ~33 ~7 ~18 ~33 glass 0  
fill ~7 ~18 ~27 ~7 ~18 ~31 lava 2 
setblock ~8 ~18 ~24 lava 2  
fill ~8 ~18 ~25 ~8 ~26 ~25 lava 10  
fill ~8 ~18 ~27 ~34 ~18 ~27 lava 0  
fill ~8 ~18 ~28 ~34 ~18 ~28 lava 0  
fill ~8 ~18 ~29 ~34 ~18 ~29 lava 0  
fill ~8 ~18 ~30 ~34 ~18 ~30 lava 0  
fill ~8 ~18 ~31 ~34 ~18 ~31 lava 0  
fill ~8 ~18 ~32 ~8 ~18 ~33 lava 10 
setblock ~8 ~18 ~34 lava 2 
setblock ~9 ~18 ~20 gold_block 0 
setblock ~9 ~18 ~22 lava 2  
fill ~9 ~18 ~24 ~9 ~24 ~24 lava 0  
fill ~9 ~18 ~25 ~33 ~18 ~25 lava 0  
fill ~9 ~18 ~26 ~33 ~18 ~26 lava 0  
fill ~9 ~18 ~32 ~33 ~18 ~32 lava 0  
fill ~9 ~18 ~33 ~33 ~18 ~33 lava 0  
fill ~9 ~18 ~34 ~9 ~24 ~34 lava 0  
fill ~9 ~18 ~35 ~9 ~19 ~35 lava 10 
setblock ~9 ~18 ~36 lava 2  
fill ~9 ~18 ~37 ~9 ~18 ~38 glass 0 
setblock ~10 ~18 ~20 glass 0  
fill ~10 ~18 ~21 ~10 ~26 ~21 lava 10  
fill ~10 ~18 ~22 ~32 ~18 ~22 lava 0  
fill ~10 ~18 ~23 ~32 ~18 ~23 lava 0  
fill ~10 ~18 ~35 ~32 ~18 ~35 lava 0  
fill ~10 ~18 ~36 ~32 ~18 ~36 lava 0  
fill ~10 ~18 ~37 ~10 ~26 ~37 lava 10 
setblock ~10 ~18 ~38 glass 0  
fill ~11 ~18 ~20 ~11 ~19 ~20 lava 10  
fill ~11 ~18 ~21 ~31 ~18 ~21 lava 0  
fill ~11 ~18 ~37 ~31 ~18 ~37 lava 0  
fill ~11 ~18 ~38 ~11 ~19 ~38 lava 10  
fill ~12 ~18 ~17 ~12 ~23 ~17 glass 0  
fill ~12 ~18 ~18 ~12 ~18 ~17 glass 0  
fill ~12 ~18 ~19 ~12 ~19 ~19 lava 10  
fill ~12 ~18 ~20 ~30 ~18 ~20 lava 0  
fill ~12 ~18 ~38 ~30 ~18 ~38 lava 0  
fill ~12 ~18 ~39 ~12 ~19 ~39 lava 10  
fill ~12 ~18 ~41 ~12 ~24 ~41 glass 0  
fill ~13 ~18 ~18 ~13 ~26 ~18 lava 10  
fill ~13 ~18 ~19 ~29 ~18 ~19 lava 0  
fill ~13 ~18 ~39 ~29 ~18 ~39 lava 0  
fill ~13 ~18 ~40 ~13 ~26 ~40 lava 10  
fill ~14 ~18 ~16 ~14 ~24 ~16 glass 0 
setblock ~14 ~18 ~17 lava 2  
fill ~14 ~18 ~18 ~28 ~18 ~18 lava 0  
fill ~14 ~18 ~40 ~28 ~18 ~40 lava 0 
setblock ~14 ~18 ~41 lava 2  
fill ~14 ~18 ~42 ~15 ~18 ~42 glass 0 
setblock ~15 ~18 ~16 gold_block 0  
fill ~15 ~18 ~17 ~15 ~19 ~17 lava 10  
fill ~15 ~18 ~41 ~15 ~19 ~41 lava 10  
fill ~16 ~18 ~15 ~18 ~18 ~15 glass 0 
setblock ~16 ~18 ~16 lava 2  
fill ~16 ~18 ~17 ~26 ~18 ~17 lava 0  
fill ~16 ~18 ~24 ~33 ~18 ~24 lava 0  
fill ~16 ~18 ~34 ~33 ~18 ~34 lava 0  
fill ~16 ~18 ~41 ~26 ~18 ~41 lava 0 
setblock ~16 ~18 ~42 lava 2  
fill ~16 ~18 ~43 ~18 ~18 ~43 glass 0  
fill ~17 ~18 ~14 ~25 ~18 ~14 glass 0  
fill ~17 ~18 ~16 ~18 ~18 ~16 lava 10  
fill ~17 ~18 ~42 ~18 ~18 ~42 lava 10  
fill ~18 ~18 ~44 ~25 ~18 ~44 glass 0  
fill ~19 ~18 ~15 ~23 ~18 ~15 lava 2  
fill ~19 ~18 ~16 ~23 ~18 ~16 lava 0  
fill ~19 ~18 ~42 ~23 ~18 ~42 lava 0  
fill ~19 ~18 ~43 ~23 ~18 ~43 lava 2  
fill ~24 ~18 ~15 ~25 ~18 ~15 glass 0  
fill ~24 ~18 ~16 ~25 ~18 ~16 lava 10  
fill ~24 ~18 ~42 ~25 ~18 ~42 lava 10  
fill ~24 ~18 ~43 ~26 ~18 ~43 glass 0 
setblock ~26 ~18 ~15 gold_block 0 
setblock ~26 ~18 ~16 lava 2 
setblock ~26 ~18 ~42 lava 2  
fill ~27 ~18 ~17 ~27 ~19 ~17 lava 10  
fill ~27 ~18 ~41 ~27 ~19 ~41 lava 10  
fill ~28 ~18 ~16 ~28 ~24 ~16 glass 0 
setblock ~28 ~18 ~17 lava 2 
setblock ~28 ~18 ~41 lava 2  
fill ~29 ~18 ~18 ~29 ~26 ~18 lava 10  
fill ~29 ~18 ~40 ~29 ~26 ~40 lava 10  
fill ~30 ~18 ~17 ~30 ~23 ~17 glass 0  
fill ~30 ~18 ~19 ~30 ~19 ~19 lava 10  
fill ~30 ~18 ~39 ~30 ~19 ~39 lava 10  
fill ~30 ~18 ~40 ~30 ~18 ~41 glass 0  
fill ~31 ~18 ~20 ~31 ~19 ~20 lava 10  
fill ~31 ~18 ~38 ~31 ~19 ~38 lava 10  
fill ~32 ~18 ~21 ~32 ~26 ~21 lava 10  
fill ~32 ~18 ~37 ~32 ~26 ~37 lava 10  
fill ~33 ~18 ~20 ~33 ~23 ~20 glass 0 
setblock ~33 ~18 ~22 lava 2 
setblock ~33 ~18 ~36 lava 2  
fill ~33 ~18 ~38 ~33 ~24 ~38 glass 0 
setblock ~34 ~18 ~24 lava 2  
fill ~34 ~18 ~25 ~34 ~26 ~25 lava 10  
fill ~34 ~18 ~32 ~34 ~18 ~33 lava 10 
setblock ~34 ~18 ~34 lava 2  
fill ~35 ~18 ~27 ~35 ~18 ~31 lava 2  
fill ~36 ~18 ~25 ~36 ~19 ~25 glass 0 
setblock ~36 ~18 ~26 gold_block 0  
fill ~36 ~18 ~27 ~36 ~19 ~27 glass 0  
fill ~36 ~18 ~28 ~36 ~18 ~31 glass 0  
fill ~6 ~19 ~25 ~7 ~19 ~25 glass 0 
setblock ~6 ~19 ~31 glass 0  
fill ~6 ~19 ~33 ~7 ~19 ~33 glass 0 
setblock ~7 ~19 ~23 glass 0 
setblock ~7 ~19 ~26 lava 2 
setblock ~7 ~19 ~27 lava 10  
fill ~7 ~19 ~28 ~7 ~23 ~28 glass 0  
fill ~7 ~19 ~29 ~7 ~23 ~29 glass 0  
fill ~7 ~19 ~30 ~7 ~23 ~30 glass 0 
setblock ~7 ~19 ~31 lava 10 
setblock ~7 ~19 ~32 lava 2  
fill ~7 ~19 ~35 ~7 ~20 ~35 glass 0  
fill ~8 ~19 ~21 ~8 ~20 ~21 glass 0  
fill ~8 ~19 ~24 ~8 ~25 ~24 lava 10  
fill ~8 ~19 ~26 ~34 ~19 ~26 lava 0  
fill ~8 ~19 ~27 ~34 ~19 ~27 lava 0  
fill ~8 ~19 ~28 ~34 ~19 ~28 lava 0  
fill ~8 ~19 ~29 ~34 ~19 ~29 lava 0  
fill ~8 ~19 ~30 ~34 ~19 ~30 lava 0  
fill ~8 ~19 ~31 ~34 ~19 ~31 lava 0  
fill ~8 ~19 ~32 ~34 ~19 ~32 lava 0  
fill ~8 ~19 ~33 ~8 ~26 ~33 lava 10  
fill ~8 ~19 ~34 ~8 ~25 ~34 lava 10 
setblock ~8 ~19 ~37 glass 0  
fill ~9 ~19 ~20 ~9 ~24 ~20 glass 0  
fill ~9 ~19 ~22 ~9 ~25 ~22 lava 10  
fill ~9 ~19 ~25 ~33 ~19 ~25 lava 0  
fill ~9 ~19 ~33 ~33 ~19 ~33 lava 0  
fill ~9 ~19 ~36 ~9 ~25 ~36 lava 10  
fill ~9 ~19 ~38 ~9 ~24 ~38 glass 0  
fill ~10 ~19 ~19 ~10 ~23 ~19 glass 0  
fill ~10 ~19 ~22 ~32 ~19 ~22 lava 0  
fill ~10 ~19 ~23 ~32 ~19 ~23 lava 0  
fill ~10 ~19 ~35 ~32 ~19 ~35 lava 0  
fill ~10 ~19 ~36 ~32 ~19 ~36 lava 0  
fill ~10 ~19 ~39 ~10 ~23 ~39 glass 0  
fill ~11 ~19 ~18 ~11 ~23 ~18 glass 0  
fill ~11 ~19 ~21 ~31 ~19 ~21 lava 0  
fill ~11 ~19 ~37 ~31 ~19 ~37 lava 0  
fill ~11 ~19 ~40 ~11 ~20 ~40 gold_block 0  
fill ~12 ~19 ~20 ~30 ~19 ~20 lava 0  
fill ~12 ~19 ~38 ~30 ~19 ~38 lava 0 
setblock ~13 ~19 ~16 glass 0  
fill ~13 ~19 ~19 ~29 ~19 ~19 lava 0  
fill ~13 ~19 ~39 ~29 ~19 ~39 lava 0  
fill ~13 ~19 ~42 ~14 ~19 ~42 glass 0  
fill ~14 ~19 ~17 ~14 ~25 ~17 lava 10  
fill ~14 ~19 ~18 ~28 ~19 ~18 lava 0  
fill ~14 ~19 ~40 ~28 ~19 ~40 lava 0  
fill ~14 ~19 ~41 ~14 ~25 ~41 lava 10  
fill ~15 ~19 ~15 ~17 ~19 ~15 glass 0  
fill ~15 ~19 ~43 ~17 ~19 ~43 glass 0  
fill ~16 ~19 ~16 ~17 ~19 ~16 lava 10  
fill ~16 ~19 ~17 ~26 ~19 ~17 lava 0  
fill ~16 ~19 ~24 ~33 ~19 ~24 lava 0  
fill ~16 ~19 ~34 ~33 ~19 ~34 lava 0  
fill ~16 ~19 ~41 ~26 ~19 ~41 lava 0  
fill ~16 ~19 ~42 ~17 ~19 ~42 lava 10  
fill ~17 ~19 ~14 ~19 ~19 ~14 glass 0 
setblock ~18 ~19 ~15 lava 2  
fill ~18 ~19 ~16 ~24 ~19 ~16 lava 0  
fill ~18 ~19 ~42 ~24 ~19 ~42 lava 0 
setblock ~18 ~19 ~43 lava 2  
fill ~18 ~19 ~44 ~19 ~19 ~44 glass 0 
setblock ~19 ~19 ~15 lava 10 
setblock ~19 ~19 ~43 lava 10  
fill ~20 ~19 ~15 ~22 ~19 ~15 glass 0  
fill ~20 ~19 ~43 ~22 ~19 ~43 glass 0 
setblock ~23 ~19 ~15 lava 10 
setblock ~23 ~19 ~43 lava 10  
fill ~23 ~19 ~44 ~25 ~19 ~44 glass 0  
fill ~24 ~19 ~14 ~25 ~19 ~14 glass 0 
setblock ~24 ~19 ~15 lava 2 
setblock ~24 ~19 ~43 lava 2  
fill ~25 ~19 ~15 ~26 ~19 ~15 glass 0  
fill ~25 ~19 ~16 ~26 ~19 ~16 lava 10  
fill ~25 ~19 ~42 ~26 ~19 ~42 lava 10  
fill ~25 ~19 ~43 ~26 ~19 ~43 glass 0 
setblock ~27 ~19 ~15 gold_block 0  
fill ~27 ~19 ~43 ~27 ~20 ~43 gold_block 0  
fill ~28 ~19 ~17 ~28 ~25 ~17 lava 10  
fill ~28 ~19 ~41 ~28 ~25 ~41 lava 10  
fill ~29 ~19 ~16 ~29 ~20 ~16 glass 0 
setblock ~29 ~19 ~42 glass 0  
fill ~30 ~19 ~41 ~30 ~21 ~41 glass 0  
fill ~31 ~19 ~18 ~31 ~23 ~18 glass 0  
fill ~31 ~19 ~40 ~31 ~21 ~40 glass 0  
fill ~32 ~19 ~19 ~32 ~23 ~19 glass 0  
fill ~32 ~19 ~39 ~32 ~21 ~39 glass 0  
fill ~33 ~19 ~22 ~33 ~25 ~22 lava 10  
fill ~33 ~19 ~36 ~33 ~25 ~36 lava 10 
setblock ~34 ~19 ~21 glass 0  
fill ~34 ~19 ~24 ~34 ~25 ~24 lava 10  
fill ~34 ~19 ~33 ~34 ~26 ~33 lava 10  
fill ~34 ~19 ~34 ~34 ~25 ~34 lava 10  
fill ~34 ~19 ~37 ~34 ~20 ~37 glass 0  
fill ~35 ~19 ~23 ~35 ~20 ~23 glass 0 
setblock ~35 ~19 ~26 lava 2 
setblock ~35 ~19 ~27 lava 10  
fill ~35 ~19 ~28 ~35 ~23 ~28 glass 0  
fill ~35 ~19 ~29 ~35 ~23 ~29 glass 0  
fill ~35 ~19 ~30 ~35 ~23 ~30 glass 0 
setblock ~35 ~19 ~31 lava 10 
setblock ~35 ~19 ~32 lava 2 
setblock ~35 ~19 ~35 glass 0  
fill ~36 ~19 ~26 ~36 ~22 ~26 glass 0  
fill ~36 ~19 ~31 ~36 ~19 ~33 glass 0  
fill ~7 ~20 ~25 ~7 ~27 ~25 glass 0  
fill ~7 ~20 ~26 ~7 ~23 ~26 lava 10  
fill ~7 ~20 ~27 ~7 ~22 ~27 glass 0  
fill ~7 ~20 ~31 ~7 ~22 ~31 glass 0  
fill ~7 ~20 ~32 ~7 ~23 ~32 lava 10  
fill ~7 ~20 ~33 ~7 ~27 ~33 glass 0  
fill ~8 ~20 ~23 ~8 ~22 ~23 glass 0  
fill ~8 ~20 ~26 ~34 ~20 ~26 lava 0  
fill ~8 ~20 ~27 ~34 ~20 ~27 lava 0  
fill ~8 ~20 ~28 ~34 ~20 ~28 lava 0  
fill ~8 ~20 ~29 ~34 ~20 ~29 lava 0  
fill ~8 ~20 ~30 ~34 ~20 ~30 lava 0  
fill ~8 ~20 ~31 ~34 ~20 ~31 lava 0  
fill ~8 ~20 ~32 ~34 ~20 ~32 lava 0  
fill ~9 ~20 ~23 ~33 ~20 ~23 lava 0  
fill ~9 ~20 ~25 ~33 ~20 ~25 lava 0  
fill ~9 ~20 ~33 ~33 ~20 ~33 lava 0  
fill ~9 ~20 ~35 ~33 ~20 ~35 lava 0  
fill ~9 ~20 ~37 ~9 ~22 ~37 glass 0 
setblock ~10 ~20 ~20 lava 2  
fill ~10 ~20 ~22 ~32 ~20 ~22 lava 0  
fill ~10 ~20 ~36 ~32 ~20 ~36 lava 0 
setblock ~10 ~20 ~38 lava 2 
setblock ~11 ~20 ~19 lava 2  
fill ~11 ~20 ~20 ~31 ~20 ~20 lava 0  
fill ~11 ~20 ~21 ~31 ~20 ~21 lava 0  
fill ~11 ~20 ~37 ~31 ~20 ~37 lava 0  
fill ~11 ~20 ~38 ~31 ~20 ~38 lava 0 
setblock ~11 ~20 ~39 lava 2 
setblock ~12 ~20 ~18 lava 2  
fill ~12 ~20 ~19 ~30 ~20 ~19 lava 0  
fill ~12 ~20 ~39 ~30 ~20 ~39 lava 0 
setblock ~12 ~20 ~40 lava 2 
setblock ~13 ~20 ~17 glass 0  
fill ~13 ~20 ~42 ~13 ~19 ~42 glass 0  
fill ~14 ~20 ~18 ~28 ~20 ~18 lava 0  
fill ~14 ~20 ~40 ~28 ~20 ~40 lava 0 
setblock ~14 ~20 ~42 gold_block 0  
fill ~15 ~20 ~15 ~17 ~20 ~15 glass 0  
fill ~15 ~20 ~17 ~27 ~20 ~17 lava 0  
fill ~15 ~20 ~41 ~27 ~20 ~41 lava 0  
fill ~15 ~20 ~42 ~15 ~22 ~42 glass 0  
fill ~16 ~20 ~16 ~17 ~20 ~16 lava 10  
fill ~16 ~20 ~24 ~33 ~20 ~24 lava 0  
fill ~16 ~20 ~34 ~33 ~20 ~34 lava 0  
fill ~16 ~20 ~42 ~17 ~20 ~42 lava 10  
fill ~16 ~20 ~43 ~17 ~20 ~43 glass 0  
fill ~18 ~20 ~14 ~18 ~25 ~14 glass 0  
fill ~18 ~20 ~15 ~18 ~23 ~15 lava 10  
fill ~18 ~20 ~16 ~24 ~20 ~16 lava 0  
fill ~18 ~20 ~42 ~24 ~20 ~42 lava 0  
fill ~18 ~20 ~43 ~18 ~23 ~43 lava 10  
fill ~18 ~20 ~44 ~18 ~21 ~44 glass 0  
fill ~19 ~20 ~15 ~23 ~20 ~15 glass 0  
fill ~19 ~20 ~43 ~22 ~20 ~43 glass 0 
setblock ~23 ~20 ~43 gold_block 0  
fill ~24 ~20 ~14 ~24 ~25 ~14 glass 0  
fill ~24 ~20 ~15 ~24 ~23 ~15 lava 10  
fill ~24 ~20 ~43 ~24 ~23 ~43 lava 10 
setblock ~24 ~20 ~44 glass 0  
fill ~25 ~20 ~15 ~26 ~20 ~15 glass 0  
fill ~25 ~20 ~16 ~26 ~20 ~16 lava 10  
fill ~25 ~20 ~42 ~26 ~20 ~42 lava 10  
fill ~25 ~20 ~43 ~25 ~15 ~43 glass 0 
setblock ~26 ~20 ~43 gold_block 0  
fill ~27 ~20 ~16 ~27 ~22 ~16 glass 0  
fill ~29 ~20 ~41 ~29 ~22 ~41 glass 0 
setblock ~30 ~20 ~18 lava 2 
setblock ~30 ~20 ~40 lava 2 
setblock ~31 ~20 ~19 lava 2 
setblock ~31 ~20 ~39 lava 2 
setblock ~32 ~20 ~20 lava 2 
setblock ~32 ~20 ~38 lava 2  
fill ~33 ~20 ~21 ~33 ~22 ~21 glass 0  
fill ~34 ~20 ~35 ~34 ~22 ~35 glass 0  
fill ~35 ~20 ~26 ~35 ~23 ~26 lava 10  
fill ~35 ~20 ~27 ~35 ~22 ~27 glass 0  
fill ~35 ~20 ~31 ~35 ~22 ~31 glass 0  
fill ~35 ~20 ~32 ~35 ~23 ~32 lava 10  
fill ~35 ~20 ~33 ~35 ~20 ~34 gold_block 0 
setblock ~36 ~20 ~32 gold_block 0  
fill ~6 ~21 ~32 ~6 ~25 ~32 glass 0  
fill ~8 ~21 ~26 ~34 ~21 ~26 lava 0  
fill ~8 ~21 ~27 ~34 ~21 ~27 lava 0  
fill ~8 ~21 ~28 ~34 ~21 ~28 lava 0  
fill ~8 ~21 ~29 ~34 ~21 ~29 lava 0  
fill ~8 ~21 ~30 ~34 ~21 ~30 lava 0  
fill ~8 ~21 ~31 ~34 ~21 ~31 lava 0  
fill ~8 ~21 ~32 ~34 ~21 ~32 lava 0 
setblock ~8 ~21 ~35 glass 0 
setblock ~9 ~21 ~21 glass 0  
fill ~9 ~21 ~23 ~33 ~21 ~23 lava 0  
fill ~9 ~21 ~25 ~33 ~21 ~25 lava 0  
fill ~9 ~21 ~33 ~33 ~21 ~33 lava 0  
fill ~9 ~21 ~35 ~33 ~21 ~35 lava 0  
fill ~10 ~21 ~20 ~10 ~23 ~20 lava 10  
fill ~10 ~21 ~22 ~32 ~21 ~22 lava 0  
fill ~10 ~21 ~36 ~32 ~21 ~36 lava 0  
fill ~10 ~21 ~38 ~10 ~23 ~38 lava 10  
fill ~11 ~21 ~19 ~11 ~23 ~19 lava 10  
fill ~11 ~21 ~20 ~31 ~21 ~20 lava 0  
fill ~11 ~21 ~21 ~31 ~21 ~21 lava 0  
fill ~11 ~21 ~37 ~31 ~21 ~37 lava 0  
fill ~11 ~21 ~38 ~31 ~21 ~38 lava 0  
fill ~11 ~21 ~39 ~11 ~23 ~39 lava 10  
fill ~11 ~21 ~40 ~11 ~23 ~40 glass 0  
fill ~12 ~21 ~18 ~12 ~23 ~18 lava 10  
fill ~12 ~21 ~19 ~30 ~21 ~19 lava 0  
fill ~12 ~21 ~39 ~30 ~21 ~39 lava 0  
fill ~12 ~21 ~40 ~12 ~23 ~40 lava 10  
fill ~13 ~21 ~17 ~13 ~22 ~17 gold_block 0 
setblock ~13 ~21 ~41 gold_block 0  
fill ~14 ~21 ~18 ~28 ~21 ~18 lava 0  
fill ~14 ~21 ~40 ~28 ~21 ~40 lava 0  
fill ~14 ~21 ~42 ~14 ~22 ~42 glass 0 
setblock ~15 ~21 ~16 glass 0  
fill ~15 ~21 ~17 ~27 ~21 ~17 lava 0  
fill ~15 ~21 ~41 ~27 ~21 ~41 lava 0  
fill ~16 ~21 ~15 ~17 ~21 ~15 glass 0  
fill ~16 ~21 ~16 ~17 ~21 ~16 lava 10  
fill ~16 ~21 ~24 ~33 ~21 ~24 lava 0  
fill ~16 ~21 ~34 ~33 ~21 ~34 lava 0  
fill ~16 ~21 ~42 ~17 ~21 ~42 lava 10  
fill ~16 ~21 ~43 ~17 ~21 ~43 glass 0  
fill ~18 ~21 ~16 ~24 ~21 ~16 lava 0  
fill ~18 ~21 ~42 ~24 ~21 ~42 lava 0  
fill ~19 ~21 ~15 ~23 ~21 ~15 glass 0  
fill ~19 ~21 ~43 ~23 ~21 ~43 glass 0 
setblock ~24 ~21 ~44 gold_block 0  
fill ~25 ~21 ~15 ~26 ~21 ~15 glass 0  
fill ~25 ~21 ~16 ~26 ~21 ~16 lava 10  
fill ~25 ~21 ~42 ~26 ~21 ~42 lava 10 
setblock ~25 ~21 ~43 gold_block 0  
fill ~26 ~21 ~43 ~26 ~27 ~43 glass 0 
setblock ~27 ~21 ~42 glass 0 
setblock ~29 ~21 ~17 glass 0  
fill ~30 ~21 ~18 ~30 ~23 ~18 lava 10  
fill ~30 ~21 ~40 ~30 ~23 ~40 lava 10  
fill ~31 ~21 ~19 ~31 ~23 ~19 lava 10  
fill ~31 ~21 ~39 ~31 ~23 ~39 lava 10  
fill ~32 ~21 ~20 ~32 ~23 ~20 lava 10  
fill ~32 ~21 ~38 ~32 ~23 ~38 lava 10 
setblock ~33 ~21 ~37 glass 0 
setblock ~34 ~21 ~23 glass 0  
fill ~35 ~21 ~33 ~35 ~27 ~33 glass 0  
fill ~35 ~21 ~34 ~35 ~23 ~34 gold_block 0  
fill ~36 ~21 ~32 ~36 ~23 ~32 glass 0  
fill ~7 ~22 ~35 ~7 ~23 ~35 glass 0 
setblock ~8 ~22 ~21 glass 0  
fill ~8 ~22 ~26 ~34 ~22 ~26 lava 0  
fill ~8 ~22 ~27 ~34 ~22 ~27 lava 0  
fill ~8 ~22 ~28 ~34 ~22 ~28 lava 0  
fill ~8 ~22 ~29 ~34 ~22 ~29 lava 0  
fill ~8 ~22 ~30 ~34 ~22 ~30 lava 0  
fill ~8 ~22 ~31 ~34 ~22 ~31 lava 0  
fill ~8 ~22 ~32 ~34 ~22 ~32 lava 0 
setblock ~8 ~22 ~35 lava 2  
fill ~9 ~22 ~23 ~33 ~22 ~23 lava 0  
fill ~9 ~22 ~25 ~33 ~22 ~25 lava 0  
fill ~9 ~22 ~33 ~33 ~22 ~33 lava 0  
fill ~9 ~22 ~35 ~33 ~22 ~35 lava 0  
fill ~10 ~22 ~22 ~32 ~22 ~22 lava 0  
fill ~10 ~22 ~36 ~32 ~22 ~36 lava 0  
fill ~11 ~22 ~20 ~31 ~22 ~20 lava 0  
fill ~11 ~22 ~21 ~31 ~22 ~21 lava 0  
fill ~11 ~22 ~37 ~31 ~22 ~37 lava 0  
fill ~11 ~22 ~38 ~31 ~22 ~38 lava 0  
fill ~12 ~22 ~19 ~30 ~22 ~19 lava 0  
fill ~12 ~22 ~39 ~30 ~22 ~39 lava 0  
fill ~13 ~22 ~42 ~13 ~23 ~42 gold_block 0  
fill ~14 ~22 ~18 ~28 ~22 ~18 lava 0  
fill ~14 ~22 ~40 ~28 ~22 ~40 lava 0  
fill ~15 ~22 ~15 ~17 ~22 ~15 glass 0 
setblock ~15 ~22 ~16 lava 2  
fill ~15 ~22 ~17 ~27 ~22 ~17 lava 0  
fill ~15 ~22 ~41 ~27 ~22 ~41 lava 0  
fill ~16 ~22 ~16 ~17 ~22 ~16 lava 10  
fill ~16 ~22 ~24 ~33 ~22 ~24 lava 0  
fill ~16 ~22 ~34 ~33 ~22 ~34 lava 0  
fill ~16 ~22 ~42 ~17 ~22 ~42 lava 10   
fill ~16 ~22 ~43 ~17 ~22 ~43 glass 0  
fill ~18 ~22 ~16 ~24 ~22 ~16 lava 0  
fill ~18 ~22 ~42 ~24 ~22 ~42 lava 0 
setblock ~18 ~22 ~44 gold_block 0  
fill ~19 ~22 ~15 ~23 ~22 ~15 glass 0  
fill ~19 ~22 ~43 ~23 ~22 ~43 glass 0  
fill ~24 ~22 ~44 ~24 ~25 ~44 glass 0  
fill ~25 ~22 ~15 ~26 ~22 ~15 glass 0  
fill ~25 ~22 ~16 ~26 ~22 ~16 lava 10  
fill ~25 ~22 ~42 ~26 ~22 ~42 lava 10  
fill ~25 ~22 ~43 ~25 ~27 ~43 glass 0 
setblock ~27 ~22 ~42 lava 2  
fill ~27 ~22 ~43 ~27 ~23 ~43 glass 0  
fill ~29 ~22 ~16 ~29 ~23 ~16 glass 0 
setblock ~30 ~22 ~41 gold_block 0 
setblock ~31 ~22 ~40 gold_block 0  
fill ~32 ~22 ~39 ~32 ~23 ~39 gold_block 0 
setblock ~34 ~22 ~23 lava 2  
fill ~34 ~22 ~37 ~34 ~23 ~37 glass 0  
fill ~35 ~22 ~23 ~35 ~23 ~23 glass 0 
setblock ~35 ~22 ~24 gold_block 0  
fill ~6 ~23 ~25 ~6 ~27 ~25 glass 0  
fill ~6 ~23 ~27 ~6 ~25 ~27 glass 0  
fill ~6 ~23 ~31 ~6 ~25 ~31 glass 0  
fill ~6 ~23 ~33 ~6 ~27 ~33 gold_block 0 
setblock ~7 ~23 ~23 glass 0 
setblock ~7 ~23 ~27 lava 2 
setblock ~7 ~23 ~31 lava 2 
setblock ~7 ~23 ~34 gold_block 0 
setblock ~8 ~23 ~21 gold_block 0  
fill ~8 ~23 ~26 ~34 ~23 ~26 lava 0  
fill ~8 ~23 ~27 ~34 ~23 ~27 lava 0  
fill ~8 ~23 ~28 ~34 ~23 ~28 lava 0  
fill ~8 ~23 ~29 ~34 ~23 ~29 lava 0  
fill ~8 ~23 ~30 ~34 ~23 ~30 lava 0  
fill ~8 ~23 ~31 ~34 ~23 ~31 lava 0  
fill ~8 ~23 ~32 ~34 ~23 ~32 lava 0 
setblock ~8 ~23 ~35 lava 10 
setblock ~8 ~23 ~37 glass 0  
fill ~9 ~23 ~23 ~9 ~26 ~23 lava 8  
fill ~9 ~23 ~25 ~33 ~23 ~25 lava 0  
fill ~9 ~23 ~33 ~33 ~23 ~33 lava 0  
fill ~9 ~23 ~35 ~9 ~26 ~35 lava 8  
fill ~10 ~23 ~22 ~32 ~23 ~22 lava 0  
fill ~10 ~23 ~23 ~32 ~23 ~23 lava 0  
fill ~10 ~23 ~35 ~32 ~23 ~35 lava 0  
fill ~10 ~23 ~36 ~32 ~23 ~36 lava 0  
fill ~11 ~23 ~20 ~11 ~26 ~20 lava 8  
fill ~11 ~23 ~21 ~31 ~23 ~21 lava 0  
fill ~11 ~23 ~37 ~31 ~23 ~37 lava 0  
fill ~11 ~23 ~38 ~11 ~26 ~38 lava 8  
fill ~12 ~23 ~19 ~12 ~26 ~19 lava 8  
fill ~12 ~23 ~20 ~30 ~23 ~20 lava 0  
fill ~12 ~23 ~38 ~30 ~23 ~38 lava 0  
fill ~12 ~23 ~39 ~12 ~26 ~39 lava 8 
setblock ~13 ~23 ~16 gold_block 0  
fill ~13 ~23 ~19 ~29 ~23 ~19 lava 0  
fill ~13 ~23 ~39 ~29 ~23 ~39 lava 0  
fill ~14 ~23 ~18 ~28 ~23 ~18 lava 0  
fill ~14 ~23 ~40 ~28 ~23 ~40 lava 0 
setblock ~14 ~23 ~42 gold_block 0  
fill ~15 ~23 ~15 ~17 ~23 ~15 glass 0  
fill ~15 ~23 ~16 ~17 ~23 ~16 lava 10  
fill ~15 ~23 ~17 ~15 ~26 ~17 lava 8  
fill ~15 ~23 ~41 ~15 ~26 ~41 lava 8 
setblock ~15 ~23 ~43 gold_block 0  
fill ~16 ~23 ~17 ~26 ~23 ~17 lava 0  
fill ~16 ~23 ~24 ~33 ~23 ~24 lava 0  
fill ~16 ~23 ~34 ~33 ~23 ~34 lava 0  
fill ~16 ~23 ~41 ~26 ~23 ~41 lava 0  
fill ~16 ~23 ~42 ~17 ~23 ~42 lava 10  
fill ~16 ~23 ~43 ~17 ~23 ~43 glass 0  
fill ~17 ~23 ~14 ~17 ~27 ~14 glass 0 
setblock ~17 ~23 ~44 gold_block 0  
fill ~18 ~23 ~16 ~24 ~23 ~16 lava 0  
fill ~18 ~23 ~42 ~24 ~23 ~42 lava 0  
fill ~18 ~23 ~44 ~19 ~23 ~44 glass 0  
fill ~19 ~23 ~14 ~19 ~25 ~14 glass 0 
setblock ~19 ~23 ~15 lava 2 
setblock ~19 ~23 ~43 lava 2  
fill ~20 ~23 ~15 ~22 ~23 ~15 glass 0  
fill ~20 ~23 ~43 ~22 ~23 ~43 glass 0  
fill ~23 ~23 ~14 ~23 ~25 ~14 glass 0 
setblock ~23 ~23 ~15 lava 2 
setblock ~23 ~23 ~43 lava 2  
fill ~23 ~23 ~44 ~23 ~25 ~44 glass 0  
fill ~25 ~23 ~14 ~25 ~27 ~14 glass 0  
fill ~25 ~23 ~15 ~27 ~23 ~15 glass 0  
fill ~25 ~23 ~16 ~26 ~23 ~16 lava 10  
fill ~25 ~23 ~42 ~27 ~23 ~42 lava 10  
fill ~25 ~23 ~44 ~25 ~27 ~44 glass 0  
fill ~27 ~23 ~17 ~27 ~26 ~17 lava 8  
fill ~27 ~23 ~41 ~27 ~26 ~41 lava 8 
setblock ~29 ~23 ~42 glass 0  
fill ~30 ~23 ~19 ~30 ~26 ~19 lava 8  
fill ~30 ~23 ~39 ~30 ~26 ~39 lava 8  
fill ~30 ~23 ~41 ~30 ~24 ~41 glass 0  
fill ~31 ~23 ~20 ~31 ~26 ~20 lava 8  
fill ~31 ~23 ~38 ~31 ~26 ~38 lava 8 
setblock ~31 ~23 ~40 glass 0  
fill ~33 ~23 ~23 ~33 ~26 ~23 lava 8  
fill ~33 ~23 ~35 ~33 ~26 ~35 lava 8 
setblock ~34 ~23 ~21 glass 0 
setblock ~34 ~23 ~23 lava 10  
fill ~35 ~23 ~24 ~35 ~27 ~24 glass 0 
setblock ~35 ~23 ~27 lava 2 
setblock ~35 ~23 ~31 lava 2 
setblock ~35 ~23 ~35 glass 0  
fill ~36 ~23 ~25 ~36 ~26 ~25 gold_block 0  
fill ~36 ~23 ~26 ~36 ~23 ~27 gold_block 0  
fill ~36 ~23 ~31 ~36 ~25 ~31 glass 0 
setblock ~36 ~23 ~33 gold_block 0  
fill ~6 ~24 ~28 ~6 ~24 ~32 glass 0 
setblock ~7 ~24 ~24 gold_block 0  
fill ~7 ~24 ~26 ~7 ~27 ~26 glass 0 
setblock ~7 ~24 ~27 lava 10  
fill ~7 ~24 ~28 ~7 ~24 ~30 lava 2 
setblock ~7 ~24 ~31 lava 10  
fill ~7 ~24 ~32 ~7 ~27 ~32 glass 0  
fill ~7 ~24 ~34 ~7 ~27 ~34 glass 0  
fill ~8 ~24 ~22 ~8 ~25 ~22 gold_block 0  
fill ~8 ~24 ~23 ~8 ~24 ~22 gold_block 0  
fill ~8 ~24 ~26 ~8 ~26 ~26 lava 8  
fill ~8 ~24 ~27 ~34 ~24 ~27 lava 0  
fill ~8 ~24 ~28 ~34 ~24 ~28 lava 0  
fill ~8 ~24 ~29 ~34 ~24 ~29 lava 0  
fill ~8 ~24 ~30 ~34 ~24 ~30 lava 0  
fill ~8 ~24 ~31 ~34 ~24 ~31 lava 0  
fill ~8 ~24 ~32 ~8 ~26 ~32 lava 8  
fill ~8 ~24 ~35 ~8 ~27 ~35 glass 0  
fill ~9 ~24 ~21 ~9 ~25 ~21 glass 0  
fill ~9 ~24 ~25 ~33 ~24 ~25 lava 0  
fill ~9 ~24 ~26 ~33 ~24 ~26 lava 0  
fill ~9 ~24 ~32 ~33 ~24 ~32 lava 0  
fill ~9 ~24 ~33 ~33 ~24 ~33 lava 0  
fill ~9 ~24 ~37 ~9 ~25 ~37 glass 0  
fill ~10 ~24 ~20 ~10 ~27 ~20 glass 0  
fill ~10 ~24 ~22 ~32 ~24 ~22 lava 0  
fill ~10 ~24 ~23 ~32 ~24 ~23 lava 0  
fill ~10 ~24 ~35 ~32 ~24 ~35 lava 0  
fill ~10 ~24 ~36 ~32 ~24 ~36 lava 0  
fill ~10 ~24 ~38 ~10 ~27 ~38 glass 0  
fill ~11 ~24 ~19 ~11 ~25 ~19 gold_block 0  
fill ~11 ~24 ~21 ~31 ~24 ~21 lava 0  
fill ~11 ~24 ~37 ~31 ~24 ~37 lava 0  
fill ~11 ~24 ~39 ~11 ~26 ~39 glass 0  
fill ~12 ~24 ~17 ~13 ~24 ~17 gold_block 0  
fill ~12 ~24 ~18 ~12 ~24 ~17 gold_block 0  
fill ~12 ~24 ~20 ~30 ~24 ~20 lava 0  
fill ~12 ~24 ~38 ~30 ~24 ~38 lava 0  
fill ~12 ~24 ~40 ~12 ~27 ~40 glass 0  
fill ~13 ~24 ~19 ~29 ~24 ~19 lava 0  
fill ~13 ~24 ~39 ~29 ~24 ~39 lava 0  
fill ~13 ~24 ~41 ~13 ~26 ~41 glass 0  
fill ~14 ~24 ~18 ~28 ~24 ~18 lava 0  
fill ~14 ~24 ~40 ~28 ~24 ~40 lava 0  
fill ~14 ~24 ~42 ~15 ~24 ~42 glass 0 
setblock ~15 ~24 ~16 glass 0  
fill ~16 ~24 ~15 ~18 ~24 ~15 glass 0  
fill ~16 ~24 ~16 ~17 ~24 ~16 lava 10  
fill ~16 ~24 ~17 ~26 ~24 ~17 lava 0  
fill ~16 ~24 ~24 ~33 ~24 ~24 lava 0  
fill ~16 ~24 ~34 ~33 ~24 ~34 lava 0  
fill ~16 ~24 ~41 ~26 ~24 ~41 lava 0  
fill ~16 ~24 ~42 ~17 ~24 ~42 lava 10  
fill ~16 ~24 ~43 ~16 ~25 ~43 gold_block 0  
fill ~17 ~24 ~43 ~18 ~24 ~43 glass 0  
fill ~17 ~24 ~44 ~25 ~24 ~44 glass 0  
fill ~18 ~24 ~16 ~18 ~26 ~16 lava 8  
fill ~18 ~24 ~42 ~18 ~26 ~42 lava 8 
setblock ~19 ~24 ~15 lava 10  
fill ~19 ~24 ~16 ~23 ~24 ~16 lava 0  
fill ~19 ~24 ~42 ~23 ~24 ~42 lava 0 
setblock ~19 ~24 ~43 lava 10  
fill ~20 ~24 ~14 ~25 ~24 ~14 glass 0  
fill ~20 ~24 ~15 ~22 ~24 ~15 lava 2  
fill ~20 ~24 ~43 ~22 ~24 ~43 lava 2 
setblock ~23 ~24 ~15 lava 10 
setblock ~23 ~24 ~43 lava 10  
fill ~24 ~24 ~15 ~26 ~24 ~15 glass 0  
fill ~24 ~24 ~16 ~24 ~26 ~16 lava 8  
fill ~24 ~24 ~42 ~24 ~26 ~42 lava 8  
fill ~24 ~24 ~43 ~24 ~27 ~43 glass 0  
fill ~25 ~24 ~16 ~26 ~24 ~16 lava 10  
fill ~25 ~24 ~42 ~26 ~24 ~42 lava 10  
fill ~27 ~24 ~16 ~27 ~27 ~16 glass 0  
fill ~27 ~24 ~42 ~27 ~27 ~42 glass 0 
setblock ~29 ~24 ~17 glass 0  
fill ~29 ~24 ~41 ~29 ~26 ~41 glass 0 
setblock ~30 ~24 ~17 gold_block 0  
fill ~30 ~24 ~18 ~30 ~27 ~18 glass 0  
fill ~30 ~24 ~40 ~30 ~26 ~40 glass 0  
fill ~31 ~24 ~19 ~31 ~26 ~19 glass 0 
setblock ~31 ~24 ~39 glass 0 
setblock ~32 ~24 ~20 glass 0 
setblock ~32 ~24 ~38 gold_block 0 
setblock ~33 ~24 ~20 gold_block 0  
fill ~33 ~24 ~21 ~33 ~26 ~21 glass 0  
fill ~33 ~24 ~37 ~33 ~26 ~37 glass 0  
fill ~34 ~24 ~23 ~34 ~26 ~23 glass 0  
fill ~34 ~24 ~26 ~34 ~26 ~26 lava 8  
fill ~34 ~24 ~32 ~34 ~26 ~32 lava 8  
fill ~34 ~24 ~35 ~34 ~27 ~35 glass 0  
fill ~35 ~24 ~26 ~36 ~24 ~26 glass 0 
setblock ~35 ~24 ~27 lava 10  
fill ~35 ~24 ~28 ~35 ~24 ~30 lava 2 
setblock ~35 ~24 ~31 lava 10  
fill ~35 ~24 ~32 ~35 ~27 ~32 glass 0  
fill ~35 ~24 ~34 ~35 ~26 ~34 glass 0  
fill ~36 ~24 ~27 ~36 ~25 ~27 glass 0  
fill ~36 ~24 ~28 ~36 ~24 ~31 glass 0  
fill ~36 ~24 ~32 ~36 ~25 ~32 gold_block 0  
fill ~36 ~24 ~33 ~36 ~25 ~33 glass 0  
fill ~7 ~25 ~24 ~7 ~27 ~24 glass 0  
fill ~7 ~25 ~27 ~7 ~27 ~27 glass 0  
fill ~7 ~25 ~28 ~7 ~26 ~28 glass 0  
fill ~7 ~25 ~29 ~7 ~26 ~29 glass 0  
fill ~7 ~25 ~30 ~7 ~26 ~30 glass 0  
fill ~7 ~25 ~31 ~7 ~27 ~31 glass 0  
fill ~8 ~25 ~23 ~8 ~26 ~23 glass 0  
fill ~8 ~25 ~27 ~8 ~27 ~27 lava 8  
fill ~8 ~25 ~28 ~8 ~26 ~28 lava 8  
fill ~8 ~25 ~29 ~8 ~26 ~29 lava 8  
fill ~8 ~25 ~30 ~8 ~26 ~30 lava 8  
fill ~8 ~25 ~31 ~8 ~27 ~31 lava 8 
setblock ~8 ~25 ~36 gold_block 0  
fill ~9 ~25 ~24 ~9 ~27 ~24 lava 8  
fill ~9 ~25 ~25 ~33 ~25 ~25 lava 0  
fill ~9 ~25 ~26 ~33 ~25 ~26 lava 0  
fill ~9 ~25 ~27 ~33 ~25 ~27 lava 0  
fill ~9 ~25 ~28 ~33 ~25 ~28 lava 0  
fill ~9 ~25 ~29 ~33 ~25 ~29 lava 0  
fill ~9 ~25 ~30 ~33 ~25 ~30 lava 0  
fill ~9 ~25 ~31 ~33 ~25 ~31 lava 0  
fill ~9 ~25 ~32 ~33 ~25 ~32 lava 0  
fill ~9 ~25 ~33 ~33 ~25 ~33 lava 0  
fill ~9 ~25 ~34 ~9 ~27 ~34 lava 8  
fill ~10 ~25 ~22 ~10 ~27 ~22 lava 8  
fill ~10 ~25 ~23 ~32 ~25 ~23 lava 0  
fill ~10 ~25 ~35 ~32 ~25 ~35 lava 0  
fill ~10 ~25 ~36 ~10 ~27 ~36 lava 8  
fill ~11 ~25 ~21 ~31 ~25 ~21 lava 0  
fill ~11 ~25 ~22 ~31 ~25 ~22 lava 0  
fill ~11 ~25 ~36 ~31 ~25 ~36 lava 0  
fill ~11 ~25 ~37 ~31 ~25 ~37 lava 0  
fill ~12 ~25 ~18 ~12 ~27 ~18 glass 0  
fill ~12 ~25 ~20 ~30 ~25 ~20 lava 0  
fill ~12 ~25 ~38 ~30 ~25 ~38 lava 0  
fill ~13 ~25 ~17 ~13 ~26 ~17 glass 0  
fill ~13 ~25 ~19 ~29 ~25 ~19 lava 0  
fill ~13 ~25 ~39 ~29 ~25 ~39 lava 0  
fill ~14 ~25 ~16 ~15 ~25 ~16 gold_block 0  
fill ~14 ~25 ~18 ~14 ~27 ~18 lava 8  
fill ~14 ~25 ~40 ~14 ~27 ~40 lava 8  
fill ~14 ~25 ~42 ~15 ~25 ~42 glass 0  
fill ~15 ~25 ~18 ~27 ~25 ~18 lava 0  
fill ~15 ~25 ~40 ~27 ~25 ~40 lava 0 
setblock ~16 ~25 ~15 gold_block 0  
fill ~16 ~25 ~16 ~17 ~25 ~16 lava 10  
fill ~16 ~25 ~17 ~16 ~27 ~17 lava 8  
fill ~16 ~25 ~24 ~32 ~25 ~24 lava 0  
fill ~16 ~25 ~34 ~32 ~25 ~34 lava 0  
fill ~16 ~25 ~41 ~16 ~27 ~41 lava 8  
fill ~16 ~25 ~42 ~17 ~25 ~42 lava 10  
fill ~17 ~25 ~15 ~26 ~25 ~15 glass 0  
fill ~17 ~25 ~17 ~25 ~25 ~17 lava 0  
fill ~17 ~25 ~41 ~25 ~25 ~41 lava 0  
fill ~17 ~25 ~43 ~26 ~25 ~43 glass 0  
fill ~17 ~25 ~44 ~19 ~25 ~44 glass 0  
fill ~19 ~25 ~16 ~24 ~25 ~16 lava 8  
fill ~19 ~25 ~42 ~24 ~25 ~42 lava 8  
fill ~25 ~25 ~16 ~26 ~25 ~16 lava 10  
fill ~25 ~25 ~42 ~26 ~25 ~42 lava 10  
fill ~26 ~25 ~17 ~26 ~27 ~17 lava 8  
fill ~26 ~25 ~41 ~26 ~27 ~41 lava 8 
setblock ~28 ~25 ~16 gold_block 0  
fill ~28 ~25 ~18 ~28 ~27 ~18 lava 8  
fill ~28 ~25 ~40 ~28 ~27 ~40 lava 8  
fill ~29 ~25 ~17 ~29 ~26 ~17 gold_block 0  
fill ~31 ~25 ~39 ~31 ~26 ~39 gold_block 0  
fill ~32 ~25 ~20 ~32 ~26 ~20 gold_block 0  
fill ~32 ~25 ~22 ~32 ~27 ~22 lava 8  
fill ~32 ~25 ~36 ~32 ~27 ~36 lava 8  
fill ~32 ~25 ~38 ~32 ~27 ~38 glass 0  
fill ~33 ~25 ~24 ~33 ~27 ~24 lava 8  
fill ~33 ~25 ~34 ~33 ~27 ~34 lava 8  
fill ~34 ~25 ~27 ~34 ~27 ~27 lava 8  
fill ~34 ~25 ~28 ~34 ~26 ~28 lava 8  
fill ~34 ~25 ~29 ~34 ~26 ~29 lava 8  
fill ~34 ~25 ~30 ~34 ~26 ~30 lava 8  
fill ~34 ~25 ~31 ~34 ~27 ~31 lava 8  
fill ~35 ~25 ~26 ~36 ~25 ~26 glass 0  
fill ~35 ~25 ~27 ~35 ~27 ~27 glass 0  
fill ~35 ~25 ~28 ~35 ~26 ~28 glass 0  
fill ~35 ~25 ~29 ~35 ~26 ~29 glass 0  
fill ~35 ~25 ~30 ~35 ~26 ~30 glass 0  
fill ~35 ~25 ~31 ~35 ~27 ~31 glass 0  
fill ~6 ~26 ~23 ~8 ~26 ~23 glass 0  
fill ~6 ~26 ~24 ~6 ~26 ~23 glass 0  
fill ~6 ~26 ~34 ~6 ~27 ~34 glass 0  
fill ~6 ~26 ~35 ~8 ~26 ~35 glass 0 
setblock ~7 ~26 ~22 glass 0 
setblock ~7 ~26 ~36 glass 0  
fill ~8 ~26 ~24 ~8 ~27 ~24 glass 0  
fill ~8 ~26 ~34 ~8 ~27 ~34 glass 0 
setblock ~9 ~26 ~21 gold_block 0 
setblock ~9 ~26 ~22 glass 0  
fill ~9 ~26 ~25 ~9 ~28 ~25 lava 8  
fill ~9 ~26 ~26 ~33 ~26 ~26 lava 0  
fill ~9 ~26 ~27 ~33 ~26 ~27 lava 0  
fill ~9 ~26 ~28 ~33 ~26 ~28 lava 0  
fill ~9 ~26 ~29 ~33 ~26 ~29 lava 0  
fill ~9 ~26 ~30 ~33 ~26 ~30 lava 0  
fill ~9 ~26 ~31 ~33 ~26 ~31 lava 0  
fill ~9 ~26 ~32 ~33 ~26 ~32 lava 0  
fill ~9 ~26 ~33 ~9 ~28 ~33 lava 8  
fill ~9 ~26 ~36 ~9 ~28 ~36 glass 0 
setblock ~9 ~26 ~37 gold_block 0  
fill ~10 ~26 ~23 ~32 ~26 ~23 lava 0  
fill ~10 ~26 ~25 ~32 ~26 ~25 lava 0  
fill ~10 ~26 ~33 ~32 ~26 ~33 lava 0  
fill ~10 ~26 ~35 ~32 ~26 ~35 lava 0 
setblock ~11 ~26 ~19 glass 0  
fill ~11 ~26 ~21 ~11 ~28 ~21 lava 8  
fill ~11 ~26 ~22 ~31 ~26 ~22 lava 0  
fill ~11 ~26 ~36 ~31 ~26 ~36 lava 0  
fill ~11 ~26 ~37 ~11 ~28 ~37 lava 8  
fill ~12 ~26 ~20 ~12 ~28 ~20 lava 8  
fill ~12 ~26 ~21 ~30 ~26 ~21 lava 0  
fill ~12 ~26 ~37 ~30 ~26 ~37 lava 0  
fill ~12 ~26 ~38 ~12 ~28 ~38 lava 8  
fill ~13 ~26 ~19 ~13 ~28 ~19 lava 8  
fill ~13 ~26 ~20 ~29 ~26 ~20 lava 0  
fill ~13 ~26 ~38 ~29 ~26 ~38 lava 0  
fill ~13 ~26 ~39 ~13 ~28 ~39 lava 8  
fill ~14 ~26 ~15 ~27 ~26 ~15 glass 0  
fill ~14 ~26 ~17 ~14 ~28 ~17 glass 0  
fill ~14 ~26 ~19 ~28 ~26 ~19 lava 0  
fill ~14 ~26 ~39 ~28 ~26 ~39 lava 0  
fill ~14 ~26 ~41 ~14 ~27 ~41 glass 0  
fill ~14 ~26 ~43 ~28 ~26 ~43 glass 0 
setblock ~15 ~26 ~14 gold_block 0  
fill ~15 ~26 ~16 ~16 ~26 ~16 glass 0  
fill ~15 ~26 ~18 ~27 ~26 ~18 lava 0  
fill ~15 ~26 ~40 ~27 ~26 ~40 lava 0  
fill ~15 ~26 ~42 ~16 ~26 ~42 glass 0 
setblock ~15 ~26 ~44 gold_block 0 
setblock ~16 ~26 ~14 glass 0  
fill ~16 ~26 ~24 ~32 ~26 ~24 lava 0  
fill ~16 ~26 ~34 ~32 ~26 ~34 lava 0  
fill ~16 ~26 ~44 ~17 ~26 ~44 glass 0 
setblock ~17 ~26 ~16 lava 10  
fill ~17 ~26 ~17 ~17 ~28 ~17 lava 8  
fill ~17 ~26 ~41 ~17 ~28 ~41 lava 8 
setblock ~17 ~26 ~42 lava 10  
fill ~18 ~26 ~17 ~24 ~26 ~17 lava 0  
fill ~18 ~26 ~41 ~24 ~26 ~41 lava 0  
fill ~19 ~26 ~16 ~24 ~26 ~16 lava 8  
fill ~19 ~26 ~42 ~24 ~26 ~42 lava 8  
fill ~25 ~26 ~16 ~25 ~18 ~16 lava 10  
fill ~25 ~26 ~17 ~25 ~28 ~17 lava 8  
fill ~25 ~26 ~41 ~25 ~28 ~41 lava 8  
fill ~25 ~26 ~42 ~25 ~18 ~42 lava 10  
fill ~26 ~26 ~14 ~27 ~26 ~14 glass 0  
fill ~26 ~26 ~16 ~26 ~27 ~16 glass 0  
fill ~26 ~26 ~42 ~26 ~27 ~42 glass 0  
fill ~26 ~26 ~44 ~27 ~26 ~44 glass 0 
setblock ~28 ~26 ~15 gold_block 0  
fill ~28 ~26 ~17 ~28 ~27 ~17 glass 0  
fill ~28 ~26 ~41 ~28 ~28 ~41 glass 0  
fill ~29 ~26 ~19 ~29 ~28 ~19 lava 8  
fill ~29 ~26 ~39 ~29 ~28 ~39 lava 8  
fill ~30 ~26 ~20 ~30 ~28 ~20 lava 8  
fill ~30 ~26 ~38 ~30 ~28 ~38 lava 8  
fill ~31 ~26 ~21 ~31 ~28 ~21 lava 8  
fill ~31 ~26 ~37 ~31 ~28 ~37 lava 8 
setblock ~33 ~26 ~22 glass 0  
fill ~33 ~26 ~25 ~33 ~28 ~25 lava 8  
fill ~33 ~26 ~33 ~33 ~28 ~33 lava 8  
fill ~33 ~26 ~36 ~33 ~27 ~36 glass 0  
fill ~34 ~26 ~24 ~34 ~27 ~24 glass 0 
setblock ~34 ~26 ~34 glass 0  
fill ~35 ~26 ~22 ~35 ~26 ~36 glass 0  
fill ~36 ~26 ~23 ~36 ~26 ~24 glass 0  
fill ~36 ~26 ~33 ~36 ~27 ~33 gold_block 0  
fill ~36 ~26 ~34 ~36 ~26 ~35 glass 0  
fill ~5 ~27 ~24 ~6 ~27 ~24 gold_block 0 
setblock ~5 ~27 ~34 gold_block 0  
fill ~7 ~27 ~23 ~8 ~27 ~23 gold_block 0 
setblock ~7 ~27 ~35 glass 0  
fill ~8 ~27 ~25 ~8 ~28 ~25 glass 0  
fill ~8 ~27 ~26 ~8 ~28 ~26 glass 0  
fill ~8 ~27 ~28 ~8 ~27 ~30 glass 0  
fill ~8 ~27 ~32 ~8 ~28 ~32 glass 0  
fill ~8 ~27 ~33 ~8 ~28 ~33 glass 0 
setblock ~9 ~27 ~22 gold_block 0  
fill ~9 ~27 ~23 ~9 ~28 ~23 glass 0  
fill ~9 ~27 ~26 ~9 ~28 ~26 lava 8  
fill ~9 ~27 ~27 ~9 ~29 ~27 lava 8  
fill ~9 ~27 ~28 ~33 ~27 ~28 lava 0  
fill ~9 ~27 ~29 ~33 ~27 ~29 lava 0  
fill ~9 ~27 ~30 ~33 ~27 ~30 lava 0  
fill ~9 ~27 ~31 ~9 ~29 ~31 lava 8  
fill ~9 ~27 ~32 ~9 ~28 ~32 lava 8  
fill ~9 ~27 ~35 ~9 ~28 ~35 glass 0  
fill ~10 ~27 ~21 ~10 ~29 ~21 glass 0  
fill ~10 ~27 ~23 ~10 ~28 ~23 lava 8  
fill ~10 ~27 ~25 ~32 ~27 ~25 lava 0  
fill ~10 ~27 ~26 ~32 ~27 ~26 lava 0  
fill ~10 ~27 ~27 ~32 ~27 ~27 lava 0  
fill ~10 ~27 ~31 ~32 ~27 ~31 lava 0  
fill ~10 ~27 ~32 ~32 ~27 ~32 lava 0  
fill ~10 ~27 ~33 ~32 ~27 ~33 lava 0  
fill ~10 ~27 ~35 ~10 ~28 ~35 lava 8  
fill ~10 ~27 ~37 ~10 ~29 ~37 gold_block 0  
fill ~11 ~27 ~20 ~11 ~31 ~20 glass 0  
fill ~11 ~27 ~22 ~11 ~29 ~22 lava 8  
fill ~11 ~27 ~23 ~31 ~27 ~23 lava 0  
fill ~11 ~27 ~35 ~31 ~27 ~35 lava 0  
fill ~11 ~27 ~36 ~11 ~29 ~36 lava 8  
fill ~11 ~27 ~38 ~11 ~31 ~38 glass 0  
fill ~12 ~27 ~19 ~12 ~30 ~19 glass 0  
fill ~12 ~27 ~21 ~30 ~27 ~21 lava 0  
fill ~12 ~27 ~22 ~30 ~27 ~22 lava 0  
fill ~12 ~27 ~36 ~30 ~27 ~36 lava 0  
fill ~12 ~27 ~37 ~30 ~27 ~37 lava 0  
fill ~12 ~27 ~39 ~12 ~31 ~39 glass 0  
fill ~13 ~27 ~18 ~13 ~29 ~18 glass 0  
fill ~13 ~27 ~20 ~29 ~27 ~20 lava 0  
fill ~13 ~27 ~38 ~29 ~27 ~38 lava 0  
fill ~13 ~27 ~40 ~13 ~29 ~40 glass 0  
fill ~14 ~27 ~19 ~14 ~29 ~19 lava 8  
fill ~14 ~27 ~39 ~14 ~29 ~39 lava 8  
fill ~15 ~27 ~15 ~19 ~27 ~15 glass 0  
fill ~15 ~27 ~16 ~18 ~27 ~16 glass 0  
fill ~15 ~27 ~17 ~15 ~28 ~17 glass 0  
fill ~15 ~27 ~18 ~15 ~28 ~18 lava 8  
fill ~15 ~27 ~19 ~27 ~27 ~19 lava 0  
fill ~15 ~27 ~39 ~27 ~27 ~39 lava 0  
fill ~15 ~27 ~40 ~15 ~28 ~40 lava 8  
fill ~15 ~27 ~41 ~15 ~28 ~41 glass 0  
fill ~15 ~27 ~42 ~18 ~27 ~42 glass 0  
fill ~15 ~27 ~43 ~19 ~27 ~43 glass 0  
fill ~16 ~27 ~13 ~16 ~27 ~14 gold_block 0  
fill ~16 ~27 ~18 ~26 ~27 ~18 lava 0  
fill ~16 ~27 ~24 ~32 ~27 ~24 lava 0  
fill ~16 ~27 ~34 ~32 ~27 ~34 lava 0  
fill ~16 ~27 ~40 ~26 ~27 ~40 lava 0  
fill ~16 ~27 ~44 ~17 ~27 ~44 glass 0 
setblock ~16 ~27 ~45 gold_block 0  
fill ~18 ~27 ~17 ~19 ~27 ~17 lava 8  
fill ~18 ~27 ~41 ~19 ~27 ~41 lava 8  
fill ~19 ~27 ~16 ~19 ~25 ~16 lava 8  
fill ~19 ~27 ~42 ~19 ~25 ~42 lava 8  
fill ~20 ~27 ~16 ~22 ~27 ~16 glass 0  
fill ~20 ~27 ~17 ~22 ~27 ~17 lava 0  
fill ~20 ~27 ~41 ~22 ~27 ~41 lava 0  
fill ~20 ~27 ~42 ~22 ~27 ~42 glass 0  
fill ~23 ~27 ~15 ~26 ~27 ~15 glass 0  
fill ~23 ~27 ~16 ~23 ~27 ~17 lava 8  
fill ~23 ~27 ~41 ~26 ~27 ~41 lava 8  
fill ~23 ~27 ~42 ~23 ~27 ~41 lava 8 
setblock ~23 ~27 ~43 glass 0  
fill ~24 ~27 ~16 ~27 ~27 ~16 glass 0  
fill ~24 ~27 ~17 ~24 ~28 ~17 lava 8  
fill ~24 ~27 ~42 ~27 ~27 ~42 glass 0  
fill ~26 ~27 ~13 ~26 ~27 ~14 gold_block 0  
fill ~26 ~27 ~44 ~26 ~26 ~44 glass 0  
fill ~26 ~27 ~45 ~26 ~27 ~42 glass 0 
setblock ~27 ~27 ~15 gold_block 0  
fill ~27 ~27 ~17 ~27 ~28 ~17 glass 0  
fill ~27 ~27 ~18 ~27 ~28 ~18 lava 8  
fill ~27 ~27 ~40 ~27 ~28 ~40 lava 8  
fill ~27 ~27 ~41 ~27 ~28 ~41 glass 0 
setblock ~27 ~27 ~43 glass 0  
fill ~28 ~27 ~19 ~28 ~29 ~19 lava 8  
fill ~28 ~27 ~39 ~28 ~29 ~39 lava 8 
setblock ~29 ~27 ~18 gold_block 0 
setblock ~29 ~27 ~40 glass 0  
fill ~30 ~27 ~19 ~30 ~31 ~19 glass 0  
fill ~30 ~27 ~39 ~30 ~31 ~39 glass 0 
setblock ~30 ~27 ~40 gold_block 0  
fill ~31 ~27 ~20 ~32 ~27 ~20 glass 0  
fill ~31 ~27 ~22 ~31 ~29 ~22 lava 8  
fill ~31 ~27 ~36 ~31 ~29 ~36 lava 8  
fill ~31 ~27 ~38 ~31 ~31 ~38 glass 0 
setblock ~32 ~27 ~21 gold_block 0  
fill ~32 ~27 ~23 ~32 ~28 ~23 lava 8  
fill ~32 ~27 ~35 ~32 ~28 ~35 lava 8  
fill ~32 ~27 ~37 ~32 ~28 ~37 glass 0 
setblock ~33 ~27 ~22 gold_block 0  
fill ~33 ~27 ~23 ~33 ~28 ~23 glass 0  
fill ~33 ~27 ~26 ~33 ~28 ~26 lava 8  
fill ~33 ~27 ~27 ~33 ~29 ~27 lava 8  
fill ~33 ~27 ~31 ~33 ~29 ~31 lava 8  
fill ~33 ~27 ~32 ~33 ~28 ~32 lava 8 
setblock ~33 ~27 ~35 glass 0  
fill ~34 ~27 ~23 ~35 ~27 ~23 gold_block 0  
fill ~34 ~27 ~25 ~34 ~27 ~26 glass 0  
fill ~34 ~27 ~28 ~34 ~29 ~28 glass 0  
fill ~34 ~27 ~29 ~34 ~28 ~29 glass 0  
fill ~34 ~27 ~30 ~34 ~29 ~30 glass 0  
fill ~34 ~27 ~32 ~34 ~28 ~32 glass 0  
fill ~34 ~27 ~33 ~34 ~28 ~33 glass 0  
fill ~34 ~27 ~34 ~37 ~27 ~34 gold_block 0 
setblock ~35 ~27 ~26 glass 0 
setblock ~35 ~27 ~35 glass 0  
fill ~36 ~27 ~24 ~37 ~27 ~24 gold_block 0 
setblock ~36 ~27 ~25 glass 0 
setblock ~4 ~28 ~23 gold_block 0 
setblock ~4 ~28 ~35 gold_block 0 
setblock ~8 ~28 ~27 glass 0 
setblock ~8 ~28 ~28 gold_block 0  
fill ~8 ~28 ~29 ~8 ~28 ~33 glass 0  
fill ~9 ~28 ~24 ~9 ~29 ~24 glass 0  
fill ~9 ~28 ~28 ~9 ~29 ~28 lava 8  
fill ~9 ~28 ~29 ~9 ~28 ~33 lava 8 
setblock ~9 ~28 ~34 glass 0  
fill ~10 ~28 ~22 ~10 ~29 ~22 gold_block 0  
fill ~10 ~28 ~24 ~10 ~29 ~24 lava 8  
fill ~10 ~28 ~25 ~10 ~29 ~25 lava 8  
fill ~10 ~28 ~26 ~32 ~28 ~26 lava 0  
fill ~10 ~28 ~27 ~32 ~28 ~27 lava 0  
fill ~10 ~28 ~28 ~32 ~28 ~28 lava 0  
fill ~10 ~28 ~29 ~32 ~28 ~29 lava 0  
fill ~10 ~28 ~30 ~32 ~28 ~30 lava 0  
fill ~10 ~28 ~31 ~32 ~28 ~31 lava 0  
fill ~10 ~28 ~32 ~32 ~28 ~32 lava 0  
fill ~10 ~28 ~33 ~10 ~29 ~33 lava 8  
fill ~10 ~28 ~34 ~10 ~29 ~34 lava 8  
fill ~10 ~28 ~36 ~10 ~29 ~36 glass 0  
fill ~11 ~28 ~23 ~11 ~30 ~23 lava 8  
fill ~11 ~28 ~25 ~31 ~28 ~25 lava 0  
fill ~11 ~28 ~33 ~31 ~28 ~33 lava 0  
fill ~11 ~28 ~35 ~11 ~30 ~35 lava 8  
fill ~12 ~28 ~21 ~12 ~29 ~21 lava 8  
fill ~12 ~28 ~22 ~30 ~28 ~22 lava 0  
fill ~12 ~28 ~23 ~30 ~28 ~23 lava 0  
fill ~12 ~28 ~35 ~30 ~28 ~35 lava 0  
fill ~12 ~28 ~36 ~30 ~28 ~36 lava 0  
fill ~12 ~28 ~37 ~12 ~29 ~37 lava 8  
fill ~13 ~28 ~20 ~13 ~29 ~20 lava 8  
fill ~13 ~28 ~21 ~29 ~28 ~21 lava 0  
fill ~13 ~28 ~37 ~29 ~28 ~37 lava 0  
fill ~13 ~28 ~38 ~13 ~29 ~38 lava 8  
fill ~14 ~28 ~18 ~14 ~29 ~18 glass 0  
fill ~14 ~28 ~20 ~28 ~28 ~20 lava 0  
fill ~14 ~28 ~38 ~28 ~28 ~38 lava 0  
fill ~14 ~28 ~40 ~14 ~29 ~40 glass 0 
setblock ~15 ~28 ~12 gold_block 0  
fill ~15 ~28 ~19 ~15 ~30 ~19 lava 8  
fill ~15 ~28 ~39 ~15 ~30 ~39 lava 8 
setblock ~15 ~28 ~46 gold_block 0  
fill ~16 ~28 ~17 ~16 ~29 ~17 glass 0  
fill ~16 ~28 ~18 ~17 ~28 ~18 lava 8  
fill ~16 ~28 ~19 ~26 ~28 ~19 lava 0  
fill ~16 ~28 ~24 ~31 ~28 ~24 lava 0  
fill ~16 ~28 ~34 ~31 ~28 ~34 lava 0  
fill ~16 ~28 ~39 ~26 ~28 ~39 lava 0  
fill ~16 ~28 ~40 ~17 ~28 ~40 lava 8  
fill ~16 ~28 ~41 ~16 ~29 ~41 glass 0  
fill ~17 ~28 ~16 ~25 ~28 ~16 glass 0  
fill ~17 ~28 ~42 ~19 ~28 ~42 glass 0  
fill ~18 ~28 ~17 ~25 ~28 ~17 lava 8  
fill ~18 ~28 ~18 ~24 ~28 ~18 lava 0  
fill ~18 ~28 ~40 ~24 ~28 ~40 lava 0  
fill ~18 ~28 ~41 ~25 ~28 ~41 lava 8 
setblock ~20 ~28 ~42 gold_block 0  
fill ~21 ~28 ~42 ~25 ~28 ~42 glass 0  
fill ~25 ~28 ~18 ~27 ~28 ~18 lava 8  
fill ~25 ~28 ~40 ~27 ~28 ~40 lava 8  
fill ~26 ~28 ~17 ~26 ~29 ~17 glass 0  
fill ~26 ~28 ~41 ~26 ~29 ~41 glass 0 
setblock ~27 ~28 ~12 gold_block 0  
fill ~27 ~28 ~19 ~27 ~30 ~19 lava 8  
fill ~27 ~28 ~39 ~27 ~30 ~39 lava 8 
setblock ~27 ~28 ~46 glass 0  
fill ~28 ~28 ~18 ~28 ~29 ~18 gold_block 0  
fill ~28 ~28 ~40 ~28 ~29 ~40 glass 0  
fill ~29 ~28 ~18 ~29 ~29 ~18 glass 0  
fill ~29 ~28 ~20 ~29 ~29 ~20 lava 8  
fill ~29 ~28 ~38 ~29 ~29 ~38 lava 8  
fill ~29 ~28 ~40 ~29 ~29 ~40 gold_block 0  
fill ~30 ~28 ~21 ~30 ~29 ~21 lava 8  
fill ~30 ~28 ~37 ~30 ~29 ~37 lava 8  
fill ~31 ~28 ~20 ~31 ~31 ~20 glass 0  
fill ~31 ~28 ~23 ~31 ~30 ~23 lava 8  
fill ~31 ~28 ~35 ~31 ~30 ~35 lava 8  
fill ~32 ~28 ~21 ~32 ~29 ~21 glass 0  
fill ~32 ~28 ~22 ~33 ~28 ~22 glass 0  
fill ~32 ~28 ~24 ~32 ~29 ~24 lava 8  
fill ~32 ~28 ~25 ~32 ~29 ~25 lava 8  
fill ~32 ~28 ~33 ~32 ~29 ~33 lava 8  
fill ~32 ~28 ~34 ~32 ~29 ~34 lava 8 
setblock ~32 ~28 ~36 glass 0  
fill ~33 ~28 ~24 ~33 ~29 ~24 glass 0  
fill ~33 ~28 ~28 ~33 ~29 ~28 lava 8  
fill ~33 ~28 ~29 ~33 ~28 ~33 lava 8  
fill ~33 ~28 ~34 ~33 ~28 ~35 gold_block 0  
fill ~34 ~28 ~25 ~34 ~28 ~27 gold_block 0  
fill ~34 ~28 ~31 ~34 ~29 ~31 glass 0 
setblock ~38 ~28 ~23 gold_block 0 
setblock ~38 ~28 ~35 gold_block 0 
setblock ~8 ~29 ~27 gold_block 0 
setblock ~8 ~29 ~28 glass 0  
fill ~8 ~29 ~30 ~8 ~29 ~31 glass 0  
fill ~9 ~29 ~25 ~9 ~29 ~26 glass 0  
fill ~9 ~29 ~29 ~9 ~32 ~29 glass 0  
fill ~9 ~29 ~30 ~10 ~29 ~30 lava 8  
fill ~9 ~29 ~32 ~9 ~30 ~32 glass 0  
fill ~9 ~29 ~33 ~9 ~29 ~32 glass 0 
setblock ~9 ~29 ~34 gold_block 0 
setblock ~10 ~29 ~23 glass 0  
fill ~10 ~29 ~26 ~10 ~30 ~26 lava 8  
fill ~10 ~29 ~27 ~10 ~30 ~27 lava 8  
fill ~10 ~29 ~28 ~10 ~30 ~28 lava 8  
fill ~10 ~29 ~29 ~10 ~30 ~29 lava 8  
fill ~10 ~29 ~31 ~10 ~30 ~31 lava 8  
fill ~10 ~29 ~32 ~10 ~30 ~32 lava 8 
setblock ~10 ~29 ~35 glass 0  
fill ~11 ~29 ~19 ~11 ~32 ~19 glass 0  
fill ~11 ~29 ~21 ~11 ~30 ~21 glass 0  
fill ~11 ~29 ~24 ~11 ~30 ~24 lava 8  
fill ~11 ~29 ~25 ~31 ~29 ~25 lava 0  
fill ~11 ~29 ~26 ~31 ~29 ~26 lava 0  
fill ~11 ~29 ~27 ~31 ~29 ~27 lava 0  
fill ~11 ~29 ~28 ~31 ~29 ~28 lava 0  
fill ~11 ~29 ~29 ~31 ~29 ~29 lava 0  
fill ~11 ~29 ~30 ~31 ~29 ~30 lava 0  
fill ~11 ~29 ~31 ~31 ~29 ~31 lava 0  
fill ~11 ~29 ~32 ~31 ~29 ~32 lava 0  
fill ~11 ~29 ~33 ~31 ~29 ~33 lava 0  
fill ~11 ~29 ~34 ~11 ~30 ~34 lava 8  
fill ~11 ~29 ~37 ~11 ~30 ~37 glass 0  
fill ~11 ~29 ~39 ~11 ~32 ~39 glass 0  
fill ~12 ~29 ~20 ~12 ~32 ~20 glass 0  
fill ~12 ~29 ~22 ~12 ~30 ~22 lava 8  
fill ~12 ~29 ~23 ~30 ~29 ~23 lava 0  
fill ~12 ~29 ~35 ~30 ~29 ~35 lava 0  
fill ~12 ~29 ~36 ~12 ~30 ~36 lava 8  
fill ~12 ~29 ~38 ~12 ~32 ~38 glass 0  
fill ~13 ~29 ~19 ~13 ~30 ~19 glass 0  
fill ~13 ~29 ~21 ~13 ~30 ~21 lava 8  
fill ~13 ~29 ~22 ~29 ~29 ~22 lava 0  
fill ~13 ~29 ~36 ~29 ~29 ~36 lava 0  
fill ~13 ~29 ~37 ~13 ~30 ~37 lava 8  
fill ~13 ~29 ~39 ~13 ~30 ~39 glass 0  
fill ~14 ~29 ~20 ~14 ~30 ~20 lava 8  
fill ~14 ~29 ~21 ~28 ~29 ~21 lava 0  
fill ~14 ~29 ~37 ~28 ~29 ~37 lava 0  
fill ~14 ~29 ~38 ~14 ~30 ~38 lava 8  
fill ~15 ~29 ~18 ~15 ~30 ~18 glass 0  
fill ~15 ~29 ~20 ~27 ~29 ~20 lava 0  
fill ~15 ~29 ~38 ~27 ~29 ~38 lava 0  
fill ~15 ~29 ~40 ~15 ~30 ~40 glass 0  
fill ~16 ~29 ~18 ~26 ~29 ~18 lava 8  
fill ~16 ~29 ~19 ~16 ~30 ~19 lava 8  
fill ~16 ~29 ~24 ~30 ~29 ~24 lava 0  
fill ~16 ~29 ~34 ~30 ~29 ~34 lava 0  
fill ~16 ~29 ~39 ~16 ~30 ~39 lava 8  
fill ~16 ~29 ~40 ~26 ~29 ~40 lava 8  
fill ~17 ~29 ~17 ~18 ~29 ~17 glass 0  
fill ~17 ~29 ~19 ~25 ~29 ~19 lava 0  
fill ~17 ~29 ~39 ~25 ~29 ~39 lava 0  
fill ~17 ~29 ~41 ~18 ~29 ~41 glass 0  
fill ~19 ~29 ~16 ~20 ~29 ~16 glass 0  
fill ~19 ~29 ~17 ~20 ~29 ~17 lava 8  
fill ~19 ~29 ~41 ~20 ~29 ~41 lava 8 
setblock ~19 ~29 ~42 gold_block 0 
setblock ~20 ~29 ~42 glass 0 
setblock ~21 ~29 ~17 gold_block 0  
fill ~21 ~29 ~41 ~21 ~31 ~41 glass 0  
fill ~22 ~29 ~16 ~23 ~29 ~16 glass 0  
fill ~22 ~29 ~17 ~23 ~29 ~17 lava 8  
fill ~22 ~29 ~41 ~23 ~29 ~41 lava 8  
fill ~22 ~29 ~42 ~23 ~29 ~42 glass 0  
fill ~24 ~29 ~17 ~26 ~29 ~17 glass 0  
fill ~24 ~29 ~41 ~26 ~29 ~41 glass 0  
fill ~26 ~29 ~19 ~26 ~30 ~19 lava 8  
fill ~26 ~29 ~39 ~26 ~30 ~39 lava 8 
setblock ~27 ~29 ~18 glass 0  
fill ~27 ~29 ~40 ~27 ~30 ~40 glass 0  
fill ~28 ~29 ~20 ~28 ~30 ~20 lava 8  
fill ~28 ~29 ~38 ~28 ~30 ~38 lava 8 
setblock ~29 ~29 ~19 glass 0  
fill ~29 ~29 ~21 ~29 ~30 ~21 lava 8  
fill ~29 ~29 ~37 ~29 ~30 ~37 lava 8  
fill ~29 ~29 ~39 ~29 ~30 ~39 glass 0  
fill ~30 ~29 ~20 ~30 ~32 ~20 glass 0  
fill ~30 ~29 ~22 ~30 ~30 ~22 lava 8  
fill ~30 ~29 ~36 ~30 ~30 ~36 lava 8  
fill ~30 ~29 ~38 ~30 ~32 ~38 glass 0  
fill ~31 ~29 ~19 ~31 ~32 ~19 glass 0  
fill ~31 ~29 ~21 ~31 ~30 ~21 glass 0  
fill ~31 ~29 ~24 ~31 ~30 ~24 lava 8  
fill ~31 ~29 ~34 ~31 ~30 ~34 lava 8  
fill ~31 ~29 ~37 ~31 ~30 ~37 glass 0  
fill ~31 ~29 ~39 ~31 ~32 ~39 glass 0  
fill ~32 ~29 ~22 ~32 ~28 ~22 glass 0  
fill ~32 ~29 ~23 ~32 ~30 ~23 glass 0  
fill ~32 ~29 ~26 ~32 ~30 ~26 lava 8  
fill ~32 ~29 ~27 ~32 ~30 ~27 lava 8  
fill ~32 ~29 ~28 ~32 ~30 ~28 lava 8  
fill ~32 ~29 ~29 ~32 ~30 ~29 lava 8  
fill ~32 ~29 ~30 ~33 ~29 ~30 lava 8  
fill ~32 ~29 ~31 ~32 ~30 ~31 lava 8  
fill ~32 ~29 ~32 ~32 ~30 ~32 lava 8  
fill ~32 ~29 ~35 ~32 ~30 ~35 gold_block 0  
fill ~32 ~29 ~36 ~32 ~29 ~37 gold_block 0 
setblock ~33 ~29 ~25 gold_block 0  
fill ~33 ~29 ~26 ~33 ~30 ~26 glass 0  
fill ~33 ~29 ~29 ~33 ~32 ~29 glass 0  
fill ~33 ~29 ~32 ~33 ~30 ~32 glass 0  
fill ~33 ~29 ~33 ~33 ~29 ~34 glass 0 
setblock ~34 ~29 ~27 glass 0 
setblock ~9 ~30 ~26 gold_block 0  
fill ~9 ~30 ~27 ~9 ~30 ~32 glass 0 
setblock ~10 ~30 ~20 glass 0  
fill ~10 ~30 ~23 ~10 ~30 ~24 gold_block 0 
setblock ~10 ~30 ~25 glass 0 
setblock ~10 ~30 ~30 lava 8 
setblock ~10 ~30 ~33 glass 0  
fill ~10 ~30 ~34 ~10 ~30 ~35 gold_block 0 
setblock ~10 ~30 ~38 gold_block 0 
setblock ~11 ~30 ~22 glass 0  
fill ~11 ~30 ~25 ~11 ~30 ~27 lava 8  
fill ~11 ~30 ~28 ~31 ~30 ~28 lava 0  
fill ~11 ~30 ~29 ~31 ~30 ~29 lava 0  
fill ~11 ~30 ~30 ~31 ~30 ~30 lava 0  
fill ~11 ~30 ~31 ~11 ~31 ~31 lava 8  
fill ~11 ~30 ~32 ~11 ~31 ~32 lava 8  
fill ~11 ~30 ~33 ~11 ~30 ~31 lava 8 
setblock ~11 ~30 ~36 gold_block 0 
setblock ~12 ~30 ~18 glass 0  
fill ~12 ~30 ~21 ~12 ~31 ~21 glass 0  
fill ~12 ~30 ~23 ~12 ~30 ~24 lava 8  
fill ~12 ~30 ~25 ~30 ~30 ~25 lava 0  
fill ~12 ~30 ~26 ~30 ~30 ~26 lava 0  
fill ~12 ~30 ~27 ~30 ~30 ~27 lava 0  
fill ~12 ~30 ~31 ~30 ~30 ~31 lava 0  
fill ~12 ~30 ~32 ~30 ~30 ~32 lava 0  
fill ~12 ~30 ~33 ~30 ~30 ~33 lava 0  
fill ~12 ~30 ~34 ~12 ~31 ~34 lava 8  
fill ~12 ~30 ~35 ~12 ~30 ~34 lava 8  
fill ~12 ~30 ~37 ~12 ~31 ~37 glass 0 
setblock ~12 ~30 ~40 glass 0 
setblock ~13 ~30 ~20 glass 0  
fill ~13 ~30 ~22 ~13 ~31 ~22 lava 8  
fill ~13 ~30 ~23 ~29 ~30 ~23 lava 0  
fill ~13 ~30 ~35 ~29 ~30 ~35 lava 0  
fill ~13 ~30 ~36 ~13 ~31 ~36 lava 8  
fill ~13 ~30 ~38 ~13 ~31 ~38 glass 0 
setblock ~14 ~30 ~19 glass 0  
fill ~14 ~30 ~21 ~14 ~31 ~21 lava 8  
fill ~14 ~30 ~22 ~28 ~30 ~22 lava 0  
fill ~14 ~30 ~36 ~28 ~30 ~36 lava 0  
fill ~14 ~30 ~37 ~14 ~31 ~37 lava 8 
setblock ~14 ~30 ~39 glass 0  
fill ~15 ~30 ~20 ~16 ~30 ~20 lava 8  
fill ~15 ~30 ~21 ~27 ~30 ~21 lava 0  
fill ~15 ~30 ~37 ~27 ~30 ~37 lava 0  
fill ~15 ~30 ~38 ~16 ~30 ~38 lava 8  
fill ~16 ~30 ~18 ~17 ~30 ~18 glass 0  
fill ~16 ~30 ~24 ~29 ~30 ~24 lava 0  
fill ~16 ~30 ~34 ~29 ~30 ~34 lava 0  
fill ~16 ~30 ~40 ~17 ~30 ~40 glass 0  
fill ~17 ~30 ~19 ~19 ~30 ~19 lava 8  
fill ~17 ~30 ~20 ~25 ~30 ~20 lava 0  
fill ~17 ~30 ~38 ~25 ~30 ~38 lava 0  
fill ~17 ~30 ~39 ~19 ~30 ~39 lava 8  
fill ~17 ~30 ~41 ~17 ~34 ~41 cobblestone 0  
fill ~18 ~30 ~17 ~21 ~30 ~17 glass 0  
fill ~18 ~30 ~18 ~24 ~30 ~18 lava 8  
fill ~18 ~30 ~40 ~24 ~30 ~40 lava 8 
setblock ~18 ~30 ~41 glass 0  
fill ~19 ~30 ~41 ~20 ~30 ~41 gold_block 0  
fill ~20 ~30 ~19 ~22 ~30 ~19 lava 0  
fill ~20 ~30 ~39 ~22 ~30 ~39 lava 0 
setblock ~22 ~30 ~17 gold_block 0  
fill ~22 ~30 ~41 ~24 ~30 ~41 glass 0  
fill ~23 ~30 ~17 ~24 ~30 ~17 glass 0  
fill ~23 ~30 ~19 ~27 ~30 ~19 lava 8  
fill ~23 ~30 ~39 ~27 ~30 ~39 lava 8  
fill ~25 ~30 ~18 ~26 ~30 ~18 glass 0  
fill ~25 ~30 ~40 ~27 ~30 ~40 glass 0  
fill ~26 ~30 ~20 ~28 ~30 ~20 lava 8  
fill ~26 ~30 ~38 ~28 ~30 ~38 lava 8 
setblock ~27 ~30 ~18 gold_block 0  
fill ~28 ~30 ~18 ~28 ~31 ~18 cobblestone 0  
fill ~28 ~30 ~19 ~29 ~30 ~19 gold_block 0  
fill ~28 ~30 ~21 ~28 ~31 ~21 lava 8  
fill ~28 ~30 ~37 ~28 ~31 ~37 lava 8 
setblock ~28 ~30 ~39 glass 0  
fill ~29 ~30 ~20 ~29 ~31 ~20 glass 0  
fill ~29 ~30 ~22 ~29 ~31 ~22 lava 8  
fill ~29 ~30 ~36 ~29 ~31 ~36 lava 8  
fill ~29 ~30 ~38 ~29 ~31 ~38 glass 0 
setblock ~30 ~30 ~18 gold_block 0  
fill ~30 ~30 ~21 ~30 ~31 ~21 glass 0  
fill ~30 ~30 ~23 ~30 ~30 ~24 lava 8  
fill ~30 ~30 ~34 ~30 ~30 ~36 lava 8  
fill ~30 ~30 ~37 ~30 ~31 ~37 glass 0 
setblock ~30 ~30 ~40 gold_block 0 
setblock ~31 ~30 ~22 glass 0  
fill ~31 ~30 ~25 ~31 ~30 ~27 lava 8  
fill ~31 ~30 ~31 ~31 ~31 ~31 lava 8  
fill ~31 ~30 ~32 ~31 ~31 ~32 lava 8  
fill ~31 ~30 ~33 ~31 ~30 ~31 lava 8 
setblock ~31 ~30 ~36 glass 0 
setblock ~32 ~30 ~20 glass 0 
setblock ~32 ~30 ~24 glass 0  
fill ~32 ~30 ~25 ~32 ~31 ~25 gold_block 0  
fill ~32 ~30 ~30 ~32 ~29 ~30 lava 8  
fill ~32 ~30 ~33 ~32 ~31 ~33 glass 0  
fill ~32 ~30 ~34 ~32 ~30 ~33 glass 0 
setblock ~32 ~30 ~38 gold_block 0  
fill ~33 ~30 ~27 ~33 ~30 ~32 glass 0  
fill ~10 ~31 ~19 ~10 ~32 ~19 glass 0  
fill ~10 ~31 ~25 ~10 ~31 ~26 gold_block 0  
fill ~10 ~31 ~27 ~10 ~31 ~32 glass 0  
fill ~10 ~31 ~33 ~11 ~31 ~33 gold_block 0  
fill ~10 ~31 ~39 ~10 ~32 ~39 gold_block 0 
setblock ~11 ~31 ~18 glass 0  
fill ~11 ~31 ~23 ~12 ~31 ~23 glass 0  
fill ~11 ~31 ~24 ~12 ~31 ~24 glass 0  
fill ~11 ~31 ~25 ~11 ~31 ~23 glass 0  
fill ~11 ~31 ~26 ~12 ~31 ~26 lava 8  
fill ~11 ~31 ~27 ~12 ~31 ~27 lava 8  
fill ~11 ~31 ~28 ~11 ~31 ~32 lava 8  
fill ~11 ~31 ~34 ~11 ~31 ~35 glass 0  
fill ~11 ~31 ~40 ~11 ~32 ~40 glass 0 
setblock ~12 ~31 ~19 gold_block 0 
setblock ~12 ~31 ~22 glass 0 
setblock ~12 ~31 ~25 lava 8  
fill ~12 ~31 ~28 ~30 ~31 ~28 lava 0  
fill ~12 ~31 ~29 ~30 ~31 ~29 lava 0  
fill ~12 ~31 ~30 ~30 ~31 ~30 lava 0  
fill ~12 ~31 ~31 ~12 ~32 ~31 lava 8  
fill ~12 ~31 ~32 ~12 ~32 ~32 lava 8  
fill ~12 ~31 ~33 ~12 ~31 ~31 lava 8  
fill ~12 ~31 ~35 ~12 ~31 ~39 glass 0  
fill ~13 ~31 ~20 ~14 ~31 ~20 gold_block 0  
fill ~13 ~31 ~21 ~13 ~32 ~21 glass 0  
fill ~13 ~31 ~23 ~14 ~31 ~23 lava 8  
fill ~13 ~31 ~24 ~13 ~32 ~24 lava 8  
fill ~13 ~31 ~25 ~29 ~31 ~25 lava 0  
fill ~13 ~31 ~26 ~29 ~31 ~26 lava 0  
fill ~13 ~31 ~27 ~29 ~31 ~27 lava 0   
fill ~13 ~31 ~31 ~29 ~31 ~31 lava 0  
fill ~13 ~31 ~32 ~29 ~31 ~32 lava 0  
fill ~13 ~31 ~33 ~29 ~31 ~33 lava 0  
fill ~13 ~31 ~34 ~13 ~32 ~34 lava 8  
fill ~13 ~31 ~35 ~14 ~31 ~35 lava 8  
fill ~13 ~31 ~37 ~13 ~32 ~37 glass 0  
fill ~14 ~31 ~22 ~15 ~31 ~22 lava 8  
fill ~14 ~31 ~36 ~15 ~31 ~36 lava 8  
fill ~14 ~31 ~38 ~16 ~31 ~38 glass 0  
fill ~15 ~31 ~19 ~17 ~31 ~19 glass 0  
fill ~15 ~31 ~20 ~15 ~31 ~19 glass 0  
fill ~15 ~31 ~21 ~16 ~31 ~21 lava 8  
fill ~15 ~31 ~35 ~27 ~31 ~35 lava 0  
fill ~15 ~31 ~37 ~16 ~31 ~37 lava 8  
fill ~15 ~31 ~39 ~17 ~31 ~39 glass 0  
fill ~16 ~31 ~20 ~19 ~31 ~20 lava 8  
fill ~16 ~31 ~22 ~26 ~31 ~22 lava 0  
fill ~16 ~31 ~24 ~28 ~31 ~24 lava 0  
fill ~16 ~31 ~34 ~28 ~31 ~34 lava 0  
fill ~16 ~31 ~36 ~26 ~31 ~36 lava 0  
fill ~17 ~31 ~18 ~21 ~31 ~18 glass 0  
fill ~17 ~31 ~21 ~25 ~31 ~21 lava 0  
fill ~17 ~31 ~23 ~27 ~31 ~23 lava 0  
fill ~17 ~31 ~37 ~25 ~31 ~37 lava 0  
fill ~17 ~31 ~38 ~19 ~31 ~38 lava 8 
setblock ~17 ~31 ~40 glass 0  
fill ~18 ~31 ~19 ~24 ~31 ~19 lava 8  
fill ~18 ~31 ~39 ~24 ~31 ~39 lava 8 
setblock ~18 ~31 ~40 gold_block 0 
setblock ~19 ~31 ~40 glass 0  
fill ~20 ~31 ~20 ~22 ~31 ~20 lava 0  
fill ~20 ~31 ~38 ~22 ~31 ~38 lava 0 
setblock ~20 ~31 ~40 gold_block 0  
fill ~21 ~31 ~17 ~21 ~32 ~17 glass 0  
fill ~21 ~31 ~40 ~22 ~31 ~40 glass 0  
fill ~22 ~31 ~18 ~22 ~34 ~18 gold_block 0  
fill ~23 ~31 ~18 ~25 ~31 ~18 glass 0  
fill ~23 ~31 ~20 ~25 ~31 ~20 lava 8  
fill ~23 ~31 ~38 ~26 ~31 ~38 lava 8 
setblock ~23 ~31 ~40 gold_block 0  
fill ~24 ~31 ~40 ~25 ~31 ~40 glass 0 
setblock ~25 ~31 ~19 glass 0  
fill ~25 ~31 ~39 ~27 ~31 ~39 glass 0 
setblock ~26 ~31 ~19 gold_block 0  
fill ~26 ~31 ~20 ~31 ~31 ~20 glass 0  
fill ~26 ~31 ~21 ~28 ~31 ~21 lava 8  
fill ~26 ~31 ~37 ~28 ~31 ~37 lava 8 
setblock ~27 ~31 ~19 glass 0  
fill ~27 ~31 ~22 ~29 ~31 ~22 lava 8  
fill ~27 ~31 ~36 ~29 ~31 ~36 lava 8  
fill ~27 ~31 ~38 ~31 ~31 ~38 glass 0 
setblock ~28 ~31 ~19 dirt 0  
fill ~28 ~31 ~23 ~29 ~31 ~23 lava 8  
fill ~28 ~31 ~35 ~29 ~31 ~35 lava 8  
fill ~29 ~31 ~21 ~29 ~32 ~21 glass 0  
fill ~29 ~31 ~24 ~30 ~31 ~24 lava 8  
fill ~29 ~31 ~34 ~29 ~32 ~34 lava 8  
fill ~29 ~31 ~37 ~29 ~32 ~37 glass 0 
setblock ~30 ~31 ~22 glass 0  
fill ~30 ~31 ~23 ~31 ~31 ~23 gold_block 0  
fill ~30 ~31 ~25 ~30 ~31 ~27 lava 8  
fill ~30 ~31 ~31 ~30 ~32 ~31 lava 8  
fill ~30 ~31 ~32 ~30 ~32 ~32 lava 8  
fill ~30 ~31 ~33 ~30 ~31 ~31 lava 8  
fill ~30 ~31 ~34 ~30 ~31 ~39 glass 0  
fill ~31 ~31 ~18 ~31 ~32 ~18 gold_block 0 
setblock ~31 ~31 ~24 gold_block 0 
setblock ~31 ~31 ~25 glass 0  
fill ~31 ~31 ~26 ~31 ~31 ~32 lava 8 
setblock ~31 ~31 ~33 glass 0 
setblock ~31 ~31 ~34 gold_block 0 
setblock ~31 ~31 ~35 glass 0  
fill ~31 ~31 ~40 ~31 ~32 ~40 gold_block 0  
fill ~32 ~31 ~19 ~32 ~32 ~19 glass 0  
fill ~32 ~31 ~26 ~32 ~31 ~27 gold_block 0  
fill ~32 ~31 ~28 ~32 ~31 ~31 glass 0 
setblock ~32 ~31 ~32 gold_block 0  
fill ~32 ~31 ~39 ~32 ~32 ~39 gold_block 0  
fill ~10 ~32 ~18 ~11 ~32 ~18 gold_block 0  
fill ~10 ~32 ~28 ~11 ~32 ~28 glass 0  
fill ~10 ~32 ~29 ~11 ~32 ~29 glass 0  
fill ~10 ~32 ~30 ~11 ~32 ~30 glass 0 
setblock ~10 ~32 ~40 gold_block 0 
setblock ~11 ~32 ~26 glass 0  
fill ~11 ~32 ~27 ~11 ~33 ~27 gold_block 0  
fill ~11 ~32 ~31 ~11 ~33 ~31 glass 0  
fill ~11 ~32 ~32 ~11 ~32 ~28 glass 0  
fill ~12 ~32 ~24 ~12 ~32 ~25 glass 0  
fill ~12 ~32 ~26 ~13 ~32 ~26 lava 8  
fill ~12 ~32 ~27 ~13 ~32 ~27 lava 8  
fill ~12 ~32 ~28 ~13 ~32 ~28 lava 8  
fill ~12 ~32 ~29 ~13 ~32 ~29 lava 8  
fill ~12 ~32 ~30 ~13 ~32 ~30 lava 8 
setblock ~12 ~32 ~33 gold_block 0 
setblock ~12 ~32 ~34 glass 0  
fill ~13 ~32 ~22 ~14 ~32 ~22 glass 0  
fill ~13 ~32 ~23 ~13 ~32 ~21 glass 0  
fill ~13 ~32 ~25 ~14 ~32 ~25 lava 8  
fill ~13 ~32 ~31 ~13 ~33 ~31 lava 8  
fill ~13 ~32 ~32 ~13 ~32 ~34 lava 8  
fill ~13 ~32 ~35 ~13 ~32 ~37 glass 0 
setblock ~14 ~32 ~21 gold_block 0  
fill ~14 ~32 ~23 ~15 ~32 ~23 lava 8  
fill ~14 ~32 ~24 ~14 ~32 ~23 lava 8  
fill ~14 ~32 ~26 ~28 ~32 ~26 lava 0  
fill ~14 ~32 ~27 ~28 ~32 ~27 lava 0  
fill ~14 ~32 ~28 ~28 ~32 ~28 lava 0  
fill ~14 ~32 ~29 ~28 ~32 ~29 lava 0  
fill ~14 ~32 ~30 ~28 ~32 ~30 lava 0  
fill ~14 ~32 ~31 ~28 ~32 ~31 lava 0  
fill ~14 ~32 ~32 ~28 ~32 ~32 lava 0  
fill ~14 ~32 ~33 ~14 ~33 ~33 lava 8  
fill ~14 ~32 ~34 ~14 ~32 ~35 lava 8  
fill ~14 ~32 ~36 ~14 ~33 ~36 glass 0  
fill ~14 ~32 ~37 ~15 ~32 ~37 glass 0 
setblock ~15 ~32 ~21 glass 0  
fill ~15 ~32 ~22 ~17 ~32 ~22 lava 8  
fill ~15 ~32 ~25 ~27 ~32 ~25 lava 0  
fill ~15 ~32 ~33 ~27 ~32 ~33 lava 0  
fill ~15 ~32 ~35 ~15 ~32 ~36 lava 8  
fill ~16 ~32 ~20 ~17 ~32 ~20 glass 0  
fill ~16 ~32 ~21 ~26 ~32 ~21 lava 8  
fill ~16 ~32 ~24 ~27 ~32 ~24 lava 0  
fill ~16 ~32 ~34 ~27 ~32 ~34 lava 0  
fill ~16 ~32 ~35 ~26 ~32 ~35 lava 0  
fill ~16 ~32 ~36 ~17 ~32 ~36 lava 8  
