setblock ~25 ~25 ~39 hopper 5  
setblock ~25 ~34 ~55 chest 2  
setblock ~20 ~24 ~56 hopper 0  
setblock ~20 ~24 ~52 hopper 0  
setblock ~20 ~24 ~54 hopper 0  
setblock ~33 ~63 ~21 chest 3  
setblock ~37 ~47 ~19 hopper 0  
setblock ~41 ~29 ~22 hopper 0  
setblock ~30 ~37 ~27 furnace 5  
setblock ~30 ~37 ~28 furnace 5  
setblock ~38 ~51 ~27 chest 5  
setblock ~38 ~51 ~26 chest 5  
setblock ~38 ~65 ~18 furnace 3  
setblock ~33 ~48 ~28 hopper 2  
setblock ~33 ~50 ~26 chest 2  
setblock ~38 ~62 ~18 furnace 3  
setblock ~35 ~48 ~28 hopper 0  
setblock ~39 ~62 ~18 furnace 4  
setblock ~36 ~43 ~28 chest 4  
setblock ~40 ~62 ~18 hopper 8  
setblock ~39 ~37 ~32 chest 2  
setblock ~30 ~43 ~33 chest 5  
setblock ~36 ~26 ~31 hopper 0  
setblock ~36 ~41 ~33 hopper 3  
setblock ~34 ~36 ~44 furnace 4  
setblock ~35 ~41 ~33 furnace 2  
setblock ~38 ~27 ~32 chest 5  
setblock ~38 ~27 ~31 trapped_chest 5  
setblock ~34 ~41 ~33 furnace 3  
setblock ~35 ~35 ~35 chest 5  
setblock ~34 ~48 ~33 hopper 0  
setblock ~36 ~43 ~29 chest 4  
setblock ~36 ~48 ~33 hopper 0  
setblock ~30 ~42 ~47 chest 3  
setblock ~33 ~44 ~49 chest 5  
setblock ~33 ~44 ~52 chest 5  
setblock ~33 ~44 ~51 chest 5  
setblock ~33 ~44 ~48 chest 5  
setblock ~33 ~42 ~49 chest 5  
setblock ~33 ~42 ~48 chest 5  
setblock ~33 ~42 ~52 chest 5  
setblock ~33 ~42 ~51 chest 5  
setblock ~31 ~44 ~48 chest 4  
setblock ~31 ~44 ~49 chest 4  
setblock ~34 ~38 ~54 hopper 6  
setblock ~34 ~38 ~55 hopper 6  
setblock ~29 ~44 ~47 chest 3  
setblock ~29 ~42 ~47 chest 3  
setblock ~31 ~42 ~48 chest 4  
setblock ~31 ~42 ~49 trapped_chest 4  
setblock ~26 ~36 ~48 furnace 3  
setblock ~33 ~38 ~54 hopper 6  
setblock ~30 ~44 ~47 chest 3  
setblock ~26 ~34 ~48 furnace 2  
setblock ~35 ~38 ~55 hopper 6  
setblock ~33 ~38 ~55 hopper 0  
setblock ~35 ~38 ~54 hopper 6  
setblock ~41 ~48 ~66 furnace 5  
setblock ~41 ~48 ~65 hopper 0  
setblock ~41 ~34 ~69 furnace 5  
setblock ~41 ~34 ~68 hopper 0  
setblock ~41 ~34 ~67 hopper 0  
setblock ~41 ~39 ~68 hopper 0  
setblock ~41 ~39 ~69 furnace 6  
setblock ~41 ~37 ~70 chest 5  
setblock ~41 ~37 ~68 furnace 5  
setblock ~41 ~37 ~69 furnace 5  
setblock ~41 ~51 ~69 chest 5  
setblock ~49 ~29 ~22 hopper 0  
setblock ~50 ~62 ~24 chest 2  
setblock ~57 ~44 ~28 furnace 5  
setblock ~57 ~44 ~27 furnace 5  
setblock ~43 ~42 ~20 furnace 4  
setblock ~43 ~41 ~20 lit_furnace 3  
setblock ~45 ~51 ~21 chest 3  
setblock ~52 ~69 ~26 chest 2  
setblock ~54 ~29 ~28 chest 3  
setblock ~57 ~41 ~26 hopper 8  
setblock ~57 ~41 ~28 furnace 4  
setblock ~49 ~43 ~22 chest 5  
setblock ~54 ~72 ~21 chest 4  
setblock ~49 ~43 ~26 chest 5  
setblock ~55 ~30 ~36 hopper 2  
setblock ~55 ~27 ~36 hopper 10  
setblock ~51 ~37 ~40 chest 2  
setblock ~53 ~27 ~36 furnace 3  
setblock ~43 ~34 ~34 chest 2  
setblock ~57 ~67 ~34 chest 3  
setblock ~52 ~85 ~39 hopper 0  
setblock ~42 ~26 ~32 hopper 5  
setblock ~51 ~30 ~36 chest 3  
setblock ~53 ~41 ~33 hopper 2  
setblock ~52 ~85 ~33 hopper 0  
setblock ~48 ~41 ~35 hopper 0  
setblock ~48 ~41 ~32 hopper 0  
setblock ~54 ~27 ~36 furnace 3  
setblock ~51 ~73 ~37 chest 5  
setblock ~54 ~27 ~38 chest 5  
setblock ~51 ~73 ~39 chest 5  
setblock ~51 ~73 ~40 chest 5  
setblock ~49 ~28 ~37 chest 5  
setblock ~42 ~34 ~34 chest 2  
setblock ~53 ~83 ~48 chest 4  
setblock ~51 ~26 ~53 hopper 0  
setblock ~49 ~26 ~54 hopper 0  
setblock ~42 ~55 ~63 chest 2  
setblock ~46 ~58 ~63 chest 2  
setblock ~45 ~58 ~63 chest 2  
setblock ~43 ~31 ~62 chest 4  
setblock ~43 ~31 ~63 chest 4  
setblock ~43 ~55 ~63 chest 2  
setblock ~42 ~58 ~63 chest 2  
setblock ~46 ~55 ~63 chest 2  
setblock ~45 ~55 ~63 chest 2  
setblock ~43 ~58 ~63 chest 2  
setblock ~57 ~27 ~68 hopper 0  
setblock ~58 ~41 ~38 hopper 0  
setblock ~61 ~48 ~44 chest 2  
setblock ~63 ~69 ~40 hopper 0  
setblock ~63 ~48 ~44 chest 4  
setblock ~63 ~48 ~43 chest 4  
setblock ~60 ~42 ~42 furnace 4  
setblock ~60 ~48 ~44 chest 2  
setblock ~59 ~44 ~40 trapped_chest 4  
setblock ~72 ~25 ~43 hopper 0  
setblock ~58 ~34 ~38 hopper 5  
setblock ~58 ~34 ~39 furnace 4  
setblock ~60 ~48 ~47 furnace 6  
setblock ~61 ~44 ~45 chest 3  
setblock ~60 ~48 ~48 furnace 6  
setblock ~60 ~48 ~49 furnace 6  
setblock ~60 ~49 ~49 furnace 5  
setblock ~60 ~49 ~48 furnace 5  
setblock ~63 ~69 ~45 hopper 0  
setblock ~68 ~24 ~56 hopper 0  
setblock ~60 ~50 ~47 furnace 5  
setblock ~63 ~42 ~59 furnace 4  
setblock ~60 ~50 ~48 furnace 5  
setblock ~60 ~50 ~49 furnace 5  
setblock ~64 ~26 ~49 chest 4  
setblock ~64 ~26 ~48 chest 4  
setblock ~72 ~25 ~47 hopper 0  
setblock ~72 ~25 ~45 hopper 0  
setblock ~60 ~51 ~47 furnace 5  
setblock ~72 ~25 ~49 hopper 0  
setblock ~60 ~51 ~49 furnace 5  
setblock ~60 ~51 ~48 furnace 5  
setblock ~63 ~41 ~55 chest 4  
setblock ~71 ~24 ~56 hopper 0  
setblock ~71 ~24 ~53 hopper 0  
setblock ~63 ~48 ~59 chest 4  
setblock ~63 ~48 ~58 chest 4  
setblock ~60 ~49 ~47 furnace 5  
setblock ~60 ~44 ~45 chest 3  
setblock ~59 ~27 ~67 hopper 0  
setblock ~65 ~27 ~63 hopper 0  
fill ~41 ~0 ~43 ~49 ~0 ~43 stonebrick 0  
fill ~41 ~0 ~44 ~49 ~0 ~44 stonebrick 0  
fill ~41 ~0 ~45 ~49 ~0 ~45 stonebrick 0  
fill ~41 ~0 ~46 ~49 ~0 ~46 stonebrick 0  
fill ~41 ~0 ~47 ~49 ~0 ~47 stonebrick 0  
fill ~42 ~0 ~42 ~48 ~0 ~42 stonebrick 0  
fill ~42 ~0 ~48 ~48 ~0 ~48 stonebrick 0  
fill ~43 ~0 ~41 ~47 ~0 ~41 stonebrick 0  
fill ~43 ~0 ~49 ~47 ~0 ~49 stonebrick 0  
fill ~37 ~1 ~43 ~53 ~1 ~43 stonebrick 0  
fill ~37 ~1 ~44 ~53 ~1 ~44 stonebrick 0  
fill ~37 ~1 ~45 ~53 ~1 ~45 stonebrick 0  
fill ~37 ~1 ~46 ~53 ~1 ~46 stonebrick 0  
fill ~37 ~1 ~47 ~53 ~1 ~47 stonebrick 0  
fill ~38 ~1 ~41 ~52 ~1 ~41 stonebrick 0  
fill ~38 ~1 ~42 ~52 ~1 ~42 stonebrick 0  
fill ~38 ~1 ~48 ~52 ~1 ~48 stonebrick 0  
fill ~38 ~1 ~49 ~52 ~1 ~49 stonebrick 0  
fill ~39 ~1 ~40 ~51 ~1 ~40 stonebrick 0  
fill ~39 ~1 ~50 ~51 ~1 ~50 stonebrick 0  
fill ~40 ~1 ~39 ~50 ~1 ~39 stonebrick 0  
fill ~40 ~1 ~51 ~50 ~1 ~51 stonebrick 0  
fill ~41 ~1 ~38 ~49 ~1 ~38 stonebrick 0  
fill ~41 ~1 ~52 ~49 ~1 ~52 stonebrick 0  
fill ~43 ~1 ~37 ~47 ~1 ~37 stonebrick 0  
fill ~43 ~1 ~53 ~47 ~1 ~53 stonebrick 0  
fill ~35 ~2 ~41 ~55 ~2 ~41 stonebrick 0  
fill ~35 ~2 ~42 ~55 ~2 ~42 stonebrick 0  
fill ~35 ~2 ~43 ~55 ~2 ~43 stonebrick 0  
fill ~35 ~2 ~44 ~55 ~2 ~44 stonebrick 0  
fill ~35 ~2 ~45 ~55 ~2 ~45 stonebrick 0  
fill ~35 ~2 ~46 ~55 ~2 ~46 stonebrick 0  
fill ~35 ~2 ~47 ~55 ~2 ~47 stonebrick 0  
fill ~35 ~2 ~48 ~55 ~2 ~48 stonebrick 0  
fill ~35 ~2 ~49 ~55 ~2 ~49 stonebrick 0  
fill ~36 ~2 ~40 ~54 ~2 ~40 stonebrick 0  
fill ~36 ~2 ~50 ~54 ~2 ~50 stonebrick 0  
fill ~37 ~2 ~38 ~53 ~2 ~38 stonebrick 0  
fill ~37 ~2 ~39 ~53 ~2 ~39 stonebrick 0  
fill ~37 ~2 ~51 ~53 ~2 ~51 stonebrick 0  
fill ~37 ~2 ~52 ~53 ~2 ~52 stonebrick 0  
fill ~38 ~2 ~37 ~52 ~2 ~37 stonebrick 0  
fill ~38 ~2 ~53 ~52 ~2 ~53 stonebrick 0  
fill ~40 ~2 ~36 ~50 ~2 ~36 stonebrick 0  
fill ~40 ~2 ~54 ~50 ~2 ~54 stonebrick 0  
fill ~41 ~2 ~35 ~49 ~2 ~35 stonebrick 0  
fill ~41 ~2 ~55 ~49 ~2 ~55 stonebrick 0  
fill ~33 ~3 ~42 ~57 ~3 ~42 stonebrick 0  
fill ~33 ~3 ~43 ~57 ~3 ~43 stonebrick 0  
fill ~33 ~3 ~44 ~57 ~3 ~44 stonebrick 0  
fill ~33 ~3 ~45 ~57 ~3 ~45 stonebrick 0  
fill ~33 ~3 ~46 ~57 ~3 ~46 stonebrick 0  
fill ~33 ~3 ~47 ~57 ~3 ~47 stonebrick 0  
fill ~33 ~3 ~48 ~57 ~3 ~48 stonebrick 0  
fill ~34 ~3 ~39 ~56 ~3 ~39 stonebrick 0  
fill ~34 ~3 ~40 ~56 ~3 ~40 stonebrick 0  
fill ~34 ~3 ~41 ~56 ~3 ~41 stonebrick 0  
fill ~34 ~3 ~49 ~56 ~3 ~49 stonebrick 0  
fill ~34 ~3 ~50 ~56 ~3 ~50 stonebrick 0  
fill ~34 ~3 ~51 ~56 ~3 ~51 stonebrick 0  
fill ~35 ~3 ~38 ~55 ~3 ~38 stonebrick 0  
fill ~35 ~3 ~52 ~55 ~3 ~52 stonebrick 0  
fill ~36 ~3 ~37 ~54 ~3 ~37 stonebrick 0  
fill ~36 ~3 ~53 ~54 ~3 ~53 stonebrick 0  
fill ~37 ~3 ~36 ~53 ~3 ~36 stonebrick 0  
fill ~37 ~3 ~54 ~53 ~3 ~54 stonebrick 0  
fill ~38 ~3 ~35 ~52 ~3 ~35 stonebrick 0  
fill ~38 ~3 ~55 ~52 ~3 ~55 stonebrick 0  
fill ~39 ~3 ~34 ~51 ~3 ~34 stonebrick 0  
fill ~39 ~3 ~56 ~51 ~3 ~56 stonebrick 0  
fill ~42 ~3 ~33 ~48 ~3 ~33 stonebrick 0  
fill ~42 ~3 ~57 ~48 ~3 ~57 stonebrick 0  
fill ~31 ~4 ~43 ~59 ~4 ~43 stonebrick 0  
fill ~31 ~4 ~44 ~59 ~4 ~44 stonebrick 0  
fill ~31 ~4 ~45 ~59 ~4 ~45 stonebrick 0  
fill ~31 ~4 ~46 ~59 ~4 ~46 stonebrick 0  
fill ~31 ~4 ~47 ~59 ~4 ~47 stonebrick 0  
fill ~32 ~4 ~40 ~58 ~4 ~40 stonebrick 0  
fill ~32 ~4 ~41 ~58 ~4 ~41 stonebrick 0  
fill ~32 ~4 ~42 ~58 ~4 ~42 stonebrick 0  
fill ~32 ~4 ~48 ~58 ~4 ~48 stonebrick 0  
fill ~32 ~4 ~49 ~58 ~4 ~49 stonebrick 0  
fill ~32 ~4 ~50 ~58 ~4 ~50 stonebrick 0  
fill ~33 ~4 ~38 ~57 ~4 ~38 stonebrick 0  
fill ~33 ~4 ~39 ~57 ~4 ~39 stonebrick 0  
fill ~33 ~4 ~51 ~57 ~4 ~51 stonebrick 0  
fill ~33 ~4 ~52 ~57 ~4 ~52 stonebrick 0  
fill ~34 ~4 ~37 ~56 ~4 ~37 stonebrick 0  
fill ~34 ~4 ~53 ~56 ~4 ~53 stonebrick 0  
fill ~35 ~4 ~35 ~55 ~4 ~35 stonebrick 0  
fill ~35 ~4 ~36 ~55 ~4 ~36 stonebrick 0  
fill ~35 ~4 ~54 ~55 ~4 ~54 stonebrick 0  
fill ~35 ~4 ~55 ~55 ~4 ~55 stonebrick 0  
fill ~37 ~4 ~34 ~53 ~4 ~34 stonebrick 0  
fill ~37 ~4 ~56 ~53 ~4 ~56 stonebrick 0  
fill ~38 ~4 ~33 ~52 ~4 ~33 stonebrick 0  
fill ~38 ~4 ~57 ~52 ~4 ~57 stonebrick 0  
fill ~40 ~4 ~32 ~50 ~4 ~32 stonebrick 0  
fill ~40 ~4 ~58 ~50 ~4 ~58 stonebrick 0  
fill ~43 ~4 ~31 ~47 ~4 ~31 stonebrick 0  
fill ~43 ~4 ~59 ~47 ~4 ~59 stonebrick 0  
fill ~30 ~5 ~42 ~60 ~5 ~42 stonebrick 0  
fill ~30 ~5 ~43 ~60 ~5 ~43 stonebrick 0  
fill ~30 ~5 ~44 ~60 ~5 ~44 stonebrick 0  
fill ~30 ~5 ~45 ~60 ~5 ~45 stonebrick 0  
fill ~30 ~5 ~46 ~60 ~5 ~46 stonebrick 0  
fill ~30 ~5 ~47 ~60 ~5 ~47 stonebrick 0  
fill ~30 ~5 ~48 ~60 ~5 ~48 stonebrick 0  
fill ~31 ~5 ~39 ~59 ~5 ~39 stonebrick 0  
fill ~31 ~5 ~40 ~59 ~5 ~40 stonebrick 0  
fill ~31 ~5 ~41 ~59 ~5 ~41 stonebrick 0  
fill ~31 ~5 ~49 ~59 ~5 ~49 stonebrick 0  
fill ~31 ~5 ~50 ~59 ~5 ~50 stonebrick 0  
fill ~31 ~5 ~51 ~59 ~5 ~51 stonebrick 0  
fill ~32 ~5 ~37 ~58 ~5 ~37 stonebrick 0  
fill ~32 ~5 ~38 ~58 ~5 ~38 stonebrick 0  
fill ~32 ~5 ~52 ~58 ~5 ~52 stonebrick 0  
fill ~32 ~5 ~53 ~58 ~5 ~53 stonebrick 0  
fill ~33 ~5 ~36 ~57 ~5 ~36 stonebrick 0  
fill ~33 ~5 ~54 ~57 ~5 ~54 stonebrick 0  
fill ~34 ~5 ~35 ~56 ~5 ~35 stonebrick 0  
fill ~34 ~5 ~55 ~56 ~5 ~55 stonebrick 0  
fill ~35 ~5 ~34 ~55 ~5 ~34 stonebrick 0  
fill ~35 ~5 ~56 ~55 ~5 ~56 stonebrick 0  
fill ~36 ~5 ~33 ~54 ~5 ~33 stonebrick 0  
fill ~36 ~5 ~57 ~54 ~5 ~57 stonebrick 0  
fill ~37 ~5 ~32 ~53 ~5 ~32 stonebrick 0  
fill ~37 ~5 ~58 ~53 ~5 ~58 stonebrick 0  
fill ~39 ~5 ~31 ~51 ~5 ~31 stonebrick 0  
fill ~39 ~5 ~59 ~51 ~5 ~59 stonebrick 0  
fill ~42 ~5 ~30 ~48 ~5 ~30 stonebrick 0  
fill ~42 ~5 ~60 ~48 ~5 ~60 stonebrick 0  
fill ~29 ~6 ~41 ~61 ~6 ~41 stonebrick 0  
fill ~29 ~6 ~42 ~61 ~6 ~42 stonebrick 0  
fill ~29 ~6 ~43 ~61 ~6 ~43 stonebrick 0  
fill ~29 ~6 ~44 ~61 ~6 ~44 stonebrick 0  
fill ~29 ~6 ~45 ~44 ~6 ~45 stonebrick 0  
fill ~29 ~6 ~46 ~61 ~6 ~46 stonebrick 0  
fill ~29 ~6 ~47 ~61 ~6 ~47 stonebrick 0  
fill ~29 ~6 ~48 ~61 ~6 ~48 stonebrick 0  
fill ~29 ~6 ~49 ~61 ~6 ~49 stonebrick 0  
fill ~30 ~6 ~38 ~60 ~6 ~38 stonebrick 0  
fill ~30 ~6 ~39 ~60 ~6 ~39 stonebrick 0  
fill ~30 ~6 ~40 ~60 ~6 ~40 stonebrick 0  
fill ~30 ~6 ~50 ~60 ~6 ~50 stonebrick 0  
fill ~30 ~6 ~51 ~60 ~6 ~51 stonebrick 0  
fill ~30 ~6 ~52 ~60 ~6 ~52 stonebrick 0  
fill ~31 ~6 ~37 ~59 ~6 ~37 stonebrick 0  
fill ~31 ~6 ~53 ~59 ~6 ~53 stonebrick 0  
fill ~32 ~6 ~35 ~58 ~6 ~35 stonebrick 0  
fill ~32 ~6 ~36 ~58 ~6 ~36 stonebrick 0  
fill ~32 ~6 ~54 ~58 ~6 ~54 stonebrick 0  
fill ~32 ~6 ~55 ~57 ~6 ~55 stonebrick 0  
fill ~33 ~6 ~34 ~57 ~6 ~34 stonebrick 0  
fill ~33 ~6 ~56 ~57 ~6 ~56 stonebrick 0  
fill ~34 ~6 ~33 ~56 ~6 ~33 stonebrick 0  
fill ~34 ~6 ~57 ~56 ~6 ~57 stonebrick 0  
fill ~35 ~6 ~32 ~55 ~6 ~32 stonebrick 0  
fill ~35 ~6 ~58 ~55 ~6 ~58 stonebrick 0  
fill ~37 ~6 ~31 ~53 ~6 ~31 stonebrick 0  
fill ~37 ~6 ~59 ~53 ~6 ~59 stonebrick 0  
fill ~38 ~6 ~30 ~52 ~6 ~30 stonebrick 0  
fill ~38 ~6 ~60 ~52 ~6 ~60 stonebrick 0  
fill ~41 ~6 ~29 ~49 ~6 ~29 stonebrick 0  
fill ~41 ~6 ~61 ~49 ~6 ~61 stonebrick 0  
fill ~45 ~6 ~45 ~45 ~18 ~45 wool 14  
fill ~46 ~6 ~45 ~61 ~6 ~45 stonebrick 0 
setblock ~29 ~7 ~41 stone_slab 5 
setblock ~29 ~7 ~43 stone_slab 5 
setblock ~29 ~7 ~45 stone_slab 5 
setblock ~29 ~7 ~47 stone_slab 5 
setblock ~29 ~7 ~49 stone_slab 5 
setblock ~30 ~7 ~38 stone_slab 5 
setblock ~30 ~7 ~40 stone_slab 5 
setblock ~30 ~7 ~50 stone_slab 5 
setblock ~30 ~7 ~52 stone_slab 5 
setblock ~32 ~7 ~36 stone_slab 5  
fill ~32 ~7 ~42 ~58 ~7 ~42 iron_block 0  
fill ~32 ~7 ~43 ~58 ~7 ~43 iron_block 0  
fill ~32 ~7 ~44 ~58 ~7 ~44 iron_block 0  
fill ~32 ~7 ~45 ~44 ~7 ~45 iron_block 0  
fill ~32 ~7 ~46 ~58 ~7 ~46 iron_block 0  
fill ~32 ~7 ~47 ~58 ~7 ~47 iron_block 0  
fill ~32 ~7 ~48 ~58 ~7 ~48 iron_block 0 
setblock ~32 ~7 ~53 stone_slab 5 
setblock ~32 ~7 ~55 stone_slab 5 
setblock ~33 ~7 ~34 stone_slab 5  
fill ~33 ~7 ~39 ~57 ~7 ~39 iron_block 0  
fill ~33 ~7 ~40 ~57 ~7 ~40 iron_block 0  
fill ~33 ~7 ~41 ~57 ~7 ~41 iron_block 0  
fill ~33 ~7 ~49 ~57 ~7 ~49 iron_block 0  
fill ~33 ~7 ~50 ~57 ~7 ~50 iron_block 0  
fill ~33 ~7 ~51 ~57 ~7 ~51 iron_block 0  
fill ~34 ~7 ~38 ~56 ~7 ~38 iron_block 0  
fill ~34 ~7 ~52 ~56 ~7 ~52 iron_block 0 
setblock ~34 ~7 ~57 stone_slab 5 
setblock ~35 ~7 ~32 stone_slab 5  
fill ~35 ~7 ~36 ~55 ~7 ~36 iron_block 0  
fill ~35 ~7 ~37 ~55 ~7 ~37 iron_block 0  
fill ~35 ~7 ~53 ~55 ~7 ~53 iron_block 0  
fill ~35 ~7 ~54 ~55 ~7 ~54 iron_block 0  
fill ~36 ~7 ~35 ~54 ~7 ~35 iron_block 0  
fill ~36 ~7 ~55 ~54 ~7 ~55 iron_block 0 
setblock ~36 ~7 ~58 stone_slab 5 
setblock ~37 ~7 ~31 stone_slab 5  
fill ~38 ~7 ~34 ~52 ~7 ~34 iron_block 0  
fill ~38 ~7 ~56 ~52 ~7 ~56 iron_block 0 
setblock ~38 ~7 ~60 stone_slab 5 
setblock ~39 ~7 ~30 stone_slab 5  
fill ~39 ~7 ~33 ~51 ~7 ~33 iron_block 0  
fill ~39 ~7 ~57 ~51 ~7 ~57 iron_block 0 
setblock ~40 ~7 ~60 stone_slab 5 
setblock ~41 ~7 ~29 stone_slab 5 
setblock ~41 ~7 ~61 stone_slab 5  
fill ~42 ~7 ~32 ~48 ~7 ~32 iron_block 0  
fill ~42 ~7 ~58 ~48 ~7 ~58 iron_block 0 
setblock ~43 ~7 ~29 stone_slab 5 
setblock ~43 ~7 ~61 stone_slab 5 
setblock ~45 ~7 ~29 stone_slab 5 
setblock ~45 ~7 ~61 stone_slab 5  
fill ~46 ~7 ~45 ~58 ~7 ~45 iron_block 0 
setblock ~47 ~7 ~29 stone_slab 5 
setblock ~47 ~7 ~61 stone_slab 5 
setblock ~49 ~7 ~29 stone_slab 5 
setblock ~49 ~7 ~61 stone_slab 5 
setblock ~51 ~7 ~30 stone_slab 5 
setblock ~51 ~7 ~60 stone_slab 5 
setblock ~53 ~7 ~31 stone_slab 5 
setblock ~53 ~7 ~59 stone_slab 5 
setblock ~55 ~7 ~32 stone_slab 5 
setblock ~55 ~7 ~58 stone_slab 5 
setblock ~57 ~7 ~34 stone_slab 5 
setblock ~57 ~7 ~56 stone_slab 5 
setblock ~58 ~7 ~36 stone_slab 5 
setblock ~58 ~7 ~54 stone_slab 5 
setblock ~60 ~7 ~38 stone_slab 5 
setblock ~60 ~7 ~40 stone_slab 5 
setblock ~60 ~7 ~50 stone_slab 5 
setblock ~60 ~7 ~52 stone_slab 5 
setblock ~61 ~7 ~41 stone_slab 5 
setblock ~61 ~7 ~43 stone_slab 5 
setblock ~61 ~7 ~45 stone_slab 5 
setblock ~61 ~7 ~47 stone_slab 5 
setblock ~61 ~7 ~49 stone_slab 5 
setblock ~14 ~8 ~14 stone_slab 13 
setblock ~14 ~8 ~76 stone_slab 13 
setblock ~15 ~8 ~15 stone_slab 13 
setblock ~15 ~8 ~75 stone_slab 13 
setblock ~16 ~8 ~16 stone_slab 13 
setblock ~16 ~8 ~74 stone_slab 13 
setblock ~17 ~8 ~17 stone_slab 13 
setblock ~17 ~8 ~73 stone_slab 13 
setblock ~18 ~8 ~18 stone_slab 13 
setblock ~18 ~8 ~72 stone_slab 13 
setblock ~19 ~8 ~19 stone_slab 13 
setblock ~19 ~8 ~71 stone_slab 13  
fill ~20 ~8 ~20 ~21 ~8 ~20 stone_slab 13  
fill ~20 ~8 ~21 ~20 ~8 ~20 stone_slab 13  
fill ~20 ~8 ~69 ~20 ~8 ~70 stone_slab 13 
setblock ~21 ~8 ~21 planks 9 
setblock ~21 ~8 ~22 stone_slab 13 
setblock ~21 ~8 ~68 stone_slab 13 
setblock ~21 ~8 ~69 planks 9 
setblock ~21 ~8 ~70 stone_slab 13 
setblock ~22 ~8 ~21 stone_slab 13 
setblock ~22 ~8 ~22 planks 9 
setblock ~22 ~8 ~23 stone_slab 13 
setblock ~22 ~8 ~67 stone_slab 13 
setblock ~22 ~8 ~68 planks 9 
setblock ~22 ~8 ~69 stone_slab 13 
setblock ~23 ~8 ~22 stone_slab 13 
setblock ~23 ~8 ~23 planks 9 
setblock ~23 ~8 ~24 stone_slab 13 
setblock ~23 ~8 ~66 stone_slab 13 
setblock ~23 ~8 ~67 planks 9 
setblock ~23 ~8 ~68 stone_slab 13 
setblock ~24 ~8 ~23 stone_slab 13 
setblock ~24 ~8 ~24 planks 9 
setblock ~24 ~8 ~25 stone_slab 13 
setblock ~24 ~8 ~65 stone_slab 13 
setblock ~24 ~8 ~66 planks 9 
setblock ~24 ~8 ~67 stone_slab 13 
setblock ~25 ~8 ~24 stone_slab 13 
setblock ~25 ~8 ~25 planks 9 
setblock ~25 ~8 ~26 stone_slab 13 
setblock ~25 ~8 ~64 stone_slab 13 
setblock ~25 ~8 ~65 planks 9 
setblock ~25 ~8 ~66 stone_slab 13 
setblock ~26 ~8 ~25 stone_slab 13 
setblock ~26 ~8 ~26 planks 9 
setblock ~26 ~8 ~27 stone_slab 5 
setblock ~26 ~8 ~63 stone_slab 13 
setblock ~26 ~8 ~64 planks 9 
setblock ~26 ~8 ~65 stone_slab 13 
setblock ~27 ~8 ~26 stone_slab 13 
setblock ~27 ~8 ~27 planks 9 
setblock ~27 ~8 ~28 stone_slab 13 
setblock ~27 ~8 ~62 stone_slab 13 
setblock ~27 ~8 ~63 planks 9 
setblock ~27 ~8 ~64 stone_slab 5 
setblock ~28 ~8 ~27 stone_slab 13 
setblock ~28 ~8 ~28 planks 9 
setblock ~28 ~8 ~29 stone_slab 13 
setblock ~28 ~8 ~61 stone_slab 13 
setblock ~28 ~8 ~62 planks 9 
setblock ~28 ~8 ~63 stone_slab 13 
setblock ~29 ~8 ~28 stone_slab 13 
setblock ~29 ~8 ~29 planks 9 
setblock ~29 ~8 ~30 stone_slab 13 
setblock ~29 ~8 ~60 stone_slab 13 
setblock ~29 ~8 ~61 planks 9 
setblock ~29 ~8 ~62 stone_slab 13 
setblock ~30 ~8 ~29 stone_slab 13 
setblock ~30 ~8 ~30 planks 9 
setblock ~30 ~8 ~31 stone_slab 13 
setblock ~30 ~8 ~59 stone_slab 13 
setblock ~30 ~8 ~60 planks 9 
setblock ~30 ~8 ~61 stone_slab 13 
setblock ~31 ~8 ~30 stone_slab 13 
setblock ~31 ~8 ~31 planks 9 
setblock ~31 ~8 ~32 stone_slab 13 
setblock ~31 ~8 ~58 stone_slab 13 
setblock ~31 ~8 ~59 planks 9 
setblock ~31 ~8 ~60 stone_slab 13 
setblock ~32 ~8 ~31 stone_slab 13 
setblock ~32 ~8 ~32 planks 9 
setblock ~32 ~8 ~33 stone_slab 13  
fill ~32 ~8 ~42 ~33 ~8 ~42 cobblestone_wall 3  
fill ~32 ~8 ~43 ~32 ~8 ~48 cobblestone_wall 3 
setblock ~32 ~8 ~57 stone_slab 13 
setblock ~32 ~8 ~58 planks 9 
setblock ~32 ~8 ~59 stone_slab 13 
setblock ~33 ~8 ~32 stone_slab 13 
setblock ~33 ~8 ~33 stone_slab 5  
fill ~33 ~8 ~39 ~34 ~8 ~39 cobblestone_wall 3  
fill ~33 ~8 ~40 ~33 ~8 ~42 cobblestone_wall 3  
fill ~33 ~8 ~43 ~57 ~8 ~43 iron_block 0  
fill ~33 ~8 ~44 ~57 ~8 ~44 iron_block 0  
fill ~33 ~8 ~45 ~44 ~8 ~45 iron_block 0  
fill ~33 ~8 ~46 ~57 ~8 ~46 iron_block 0  
fill ~33 ~8 ~47 ~57 ~8 ~47 iron_block 0  
fill ~33 ~8 ~48 ~33 ~8 ~51 cobblestone_wall 3 
setblock ~33 ~8 ~57 stone_slab 5 
setblock ~33 ~8 ~58 stone_slab 13 
setblock ~34 ~8 ~34 stone_slab 5  
fill ~34 ~8 ~38 ~35 ~8 ~38 cobblestone_wall 3  
fill ~34 ~8 ~40 ~56 ~8 ~40 iron_block 0  
fill ~34 ~8 ~41 ~56 ~8 ~41 iron_block 0  
fill ~34 ~8 ~42 ~56 ~8 ~42 iron_block 0  
fill ~34 ~8 ~48 ~56 ~8 ~48 iron_block 0  
fill ~34 ~8 ~49 ~56 ~8 ~49 iron_block 0  
fill ~34 ~8 ~50 ~56 ~8 ~50 iron_block 0  
fill ~34 ~8 ~51 ~34 ~8 ~52 cobblestone_wall 3 
setblock ~34 ~8 ~56 stone_slab 5 
setblock ~35 ~8 ~35 stone_slab 5  
fill ~35 ~8 ~36 ~36 ~8 ~36 cobblestone_wall 3  
fill ~35 ~8 ~37 ~35 ~8 ~36 cobblestone_wall 3  
fill ~35 ~8 ~39 ~55 ~8 ~39 iron_block 0  
fill ~35 ~8 ~51 ~55 ~8 ~51 iron_block 0  
fill ~35 ~8 ~52 ~35 ~8 ~54 cobblestone_wall 3 
setblock ~35 ~8 ~55 stone_slab 5  
fill ~36 ~8 ~35 ~38 ~8 ~35 cobblestone_wall 3  
fill ~36 ~8 ~37 ~54 ~8 ~37 iron_block 0  
fill ~36 ~8 ~38 ~54 ~8 ~38 iron_block 0  
fill ~36 ~8 ~52 ~54 ~8 ~52 iron_block 0  
fill ~36 ~8 ~53 ~54 ~8 ~53 iron_block 0  
fill ~36 ~8 ~54 ~36 ~8 ~55 cobblestone_wall 3  
fill ~37 ~8 ~36 ~53 ~8 ~36 iron_block 0  
fill ~37 ~8 ~54 ~53 ~8 ~54 iron_block 0  
fill ~37 ~8 ~55 ~38 ~8 ~55 cobblestone_wall 3  
fill ~38 ~8 ~34 ~39 ~8 ~34 cobblestone_wall 3  
fill ~38 ~8 ~56 ~39 ~8 ~56 cobblestone_wall 3  
fill ~39 ~8 ~33 ~42 ~8 ~33 cobblestone_wall 3  
fill ~39 ~8 ~35 ~51 ~8 ~35 iron_block 0  
fill ~39 ~8 ~55 ~51 ~8 ~55 iron_block 0  
fill ~39 ~8 ~57 ~42 ~8 ~57 cobblestone_wall 3  
fill ~40 ~8 ~34 ~50 ~8 ~34 iron_block 0  
fill ~40 ~8 ~56 ~50 ~8 ~56 iron_block 0  
fill ~42 ~8 ~32 ~48 ~8 ~32 cobblestone_wall 3  
fill ~42 ~8 ~58 ~48 ~8 ~58 cobblestone_wall 3  
fill ~43 ~8 ~33 ~47 ~8 ~33 iron_block 0  
fill ~43 ~8 ~57 ~47 ~8 ~57 iron_block 0  
fill ~46 ~8 ~45 ~57 ~8 ~45 iron_block 0  
fill ~48 ~8 ~33 ~51 ~8 ~33 cobblestone_wall 3  
fill ~48 ~8 ~57 ~51 ~8 ~57 cobblestone_wall 3  
fill ~51 ~8 ~34 ~52 ~8 ~34 cobblestone_wall 3  
fill ~51 ~8 ~56 ~52 ~8 ~56 cobblestone_wall 3  
fill ~52 ~8 ~35 ~54 ~8 ~35 cobblestone_wall 3  
fill ~52 ~8 ~55 ~54 ~8 ~55 cobblestone_wall 3  
fill ~54 ~8 ~36 ~55 ~8 ~36 cobblestone_wall 3  
fill ~54 ~8 ~54 ~55 ~8 ~54 cobblestone_wall 3 
setblock ~55 ~8 ~35 stone_slab 5  
fill ~55 ~8 ~37 ~55 ~8 ~38 cobblestone_wall 3  
fill ~55 ~8 ~52 ~56 ~8 ~52 cobblestone_wall 3  
fill ~55 ~8 ~53 ~55 ~8 ~52 cobblestone_wall 3 
setblock ~55 ~8 ~55 stone_slab 5 
setblock ~56 ~8 ~34 stone_slab 5  
fill ~56 ~8 ~38 ~56 ~8 ~39 cobblestone_wall 3  
fill ~56 ~8 ~51 ~57 ~8 ~51 cobblestone_wall 3 
setblock ~56 ~8 ~56 stone_slab 5 
setblock ~57 ~8 ~32 stone_slab 13 
setblock ~57 ~8 ~33 stone_slab 5  
fill ~57 ~8 ~39 ~57 ~8 ~42 cobblestone_wall 3  
fill ~57 ~8 ~48 ~58 ~8 ~48 cobblestone_wall 3  
fill ~57 ~8 ~49 ~57 ~8 ~51 cobblestone_wall 3 
setblock ~57 ~8 ~57 stone_slab 5 
setblock ~57 ~8 ~58 stone_slab 13 
setblock ~58 ~8 ~31 stone_slab 13 
setblock ~58 ~8 ~32 planks 9 
setblock ~58 ~8 ~33 stone_slab 13  
fill ~58 ~8 ~42 ~58 ~8 ~48 cobblestone_wall 3 
setblock ~58 ~8 ~57 stone_slab 13 
setblock ~58 ~8 ~58 planks 9 
setblock ~58 ~8 ~59 stone_slab 13 
setblock ~59 ~8 ~30 stone_slab 13 
setblock ~59 ~8 ~31 planks 9 
setblock ~59 ~8 ~32 stone_slab 13 
setblock ~59 ~8 ~58 stone_slab 13 
setblock ~59 ~8 ~59 planks 9 
setblock ~59 ~8 ~60 stone_slab 13 
setblock ~60 ~8 ~29 stone_slab 13 
setblock ~60 ~8 ~30 planks 9 
setblock ~60 ~8 ~31 stone_slab 13 
setblock ~60 ~8 ~59 stone_slab 13 
setblock ~60 ~8 ~60 planks 9 
setblock ~60 ~8 ~61 stone_slab 13 
setblock ~61 ~8 ~28 stone_slab 13 
setblock ~61 ~8 ~29 planks 9 
setblock ~61 ~8 ~30 stone_slab 13 
setblock ~61 ~8 ~60 stone_slab 13 
setblock ~61 ~8 ~61 planks 9 
setblock ~61 ~8 ~62 stone_slab 13 
setblock ~62 ~8 ~27 stone_slab 13 
setblock ~62 ~8 ~28 planks 9 
setblock ~62 ~8 ~29 stone_slab 13 
setblock ~62 ~8 ~61 stone_slab 13 
setblock ~62 ~8 ~62 planks 9 
setblock ~62 ~8 ~63 stone_slab 13 
setblock ~63 ~8 ~26 stone_slab 5 
setblock ~63 ~8 ~27 planks 9 
setblock ~63 ~8 ~28 stone_slab 13 
setblock ~63 ~8 ~62 stone_slab 13 
setblock ~63 ~8 ~63 planks 9 
setblock ~63 ~8 ~64 stone_slab 13 
setblock ~64 ~8 ~25 stone_slab 13 
setblock ~64 ~8 ~26 planks 9 
setblock ~64 ~8 ~27 stone_slab 13 
setblock ~64 ~8 ~63 stone_slab 5 
setblock ~64 ~8 ~64 planks 9 
setblock ~64 ~8 ~65 stone_slab 13 
setblock ~65 ~8 ~24 stone_slab 13 
setblock ~65 ~8 ~25 planks 9 
setblock ~65 ~8 ~26 stone_slab 13 
setblock ~65 ~8 ~64 stone_slab 13 
setblock ~65 ~8 ~65 planks 9 
setblock ~65 ~8 ~66 stone_slab 13 
setblock ~66 ~8 ~23 stone_slab 13 
setblock ~66 ~8 ~24 planks 9 
setblock ~66 ~8 ~25 stone_slab 13 
setblock ~66 ~8 ~65 stone_slab 13 
setblock ~66 ~8 ~66 planks 9 
setblock ~66 ~8 ~67 stone_slab 13 
setblock ~67 ~8 ~22 stone_slab 13 
setblock ~67 ~8 ~23 planks 9 
setblock ~67 ~8 ~24 stone_slab 13 
setblock ~67 ~8 ~66 stone_slab 13 
setblock ~67 ~8 ~67 planks 9 
setblock ~67 ~8 ~68 stone_slab 13 
setblock ~68 ~8 ~21 stone_slab 13 
setblock ~68 ~8 ~22 planks 9 
setblock ~68 ~8 ~23 stone_slab 13 
setblock ~68 ~8 ~67 stone_slab 13 
setblock ~68 ~8 ~68 planks 9 
setblock ~68 ~8 ~69 stone_slab 13  
fill ~69 ~8 ~20 ~70 ~8 ~20 stone_slab 13 
setblock ~69 ~8 ~21 planks 9 
setblock ~69 ~8 ~22 stone_slab 13 
setblock ~69 ~8 ~68 stone_slab 13 
setblock ~69 ~8 ~69 planks 9  
fill ~69 ~8 ~70 ~70 ~8 ~70 stone_slab 13 
setblock ~70 ~8 ~21 stone_slab 13 
setblock ~70 ~8 ~69 stone_slab 13 
setblock ~71 ~8 ~19 stone_slab 13 
setblock ~71 ~8 ~71 stone_slab 13 
setblock ~72 ~8 ~18 stone_slab 13 
setblock ~72 ~8 ~72 stone_slab 13 
setblock ~73 ~8 ~17 stone_slab 13 
setblock ~73 ~8 ~73 stone_slab 13 
setblock ~74 ~8 ~16 stone_slab 13 
setblock ~74 ~8 ~74 stone_slab 13 
setblock ~75 ~8 ~15 stone_slab 13 
setblock ~75 ~8 ~75 stone_slab 13 
setblock ~76 ~8 ~14 stone_slab 13 
setblock ~76 ~8 ~76 stone_slab 13 
setblock ~14 ~9 ~14 cobblestone_wall 13 
setblock ~14 ~9 ~76 cobblestone_wall 13 
setblock ~15 ~9 ~15 cobblestone_wall 13 
setblock ~15 ~9 ~75 cobblestone_wall 13 
setblock ~16 ~9 ~16 cobblestone_wall 13  
fill ~16 ~9 ~17 ~16 ~9 ~18 cobblestone_wall 14  
fill ~16 ~9 ~72 ~16 ~9 ~73 cobblestone_wall 14 
setblock ~16 ~9 ~74 cobblestone_wall 13  
fill ~17 ~9 ~16 ~18 ~9 ~16 cobblestone_wall 14  
fill ~17 ~9 ~17 ~18 ~9 ~17 sandstone 1  
fill ~17 ~9 ~18 ~19 ~9 ~18 sandstone 1 
setblock ~17 ~9 ~19 cobblestone_wall 14 
setblock ~17 ~9 ~71 cobblestone_wall 14  
fill ~17 ~9 ~72 ~19 ~9 ~72 sandstone 1  
fill ~17 ~9 ~73 ~18 ~9 ~73 sandstone 1  
fill ~17 ~9 ~74 ~18 ~9 ~74 cobblestone_wall 14  
fill ~18 ~9 ~19 ~21 ~9 ~19 sandstone 1  
fill ~18 ~9 ~20 ~18 ~9 ~21 cobblestone_wall 14  
fill ~18 ~9 ~69 ~18 ~9 ~70 cobblestone_wall 14  
fill ~18 ~9 ~71 ~21 ~9 ~71 sandstone 1 
setblock ~19 ~9 ~17 cobblestone_wall 14  
fill ~19 ~9 ~20 ~22 ~9 ~20 sandstone 1  
fill ~19 ~9 ~21 ~24 ~9 ~21 sandstone 1 
setblock ~19 ~9 ~22 cobblestone_wall 14 
setblock ~19 ~9 ~68 cobblestone_wall 14  
fill ~19 ~9 ~69 ~24 ~9 ~69 sandstone 1  
fill ~19 ~9 ~70 ~22 ~9 ~70 sandstone 1 
setblock ~19 ~9 ~73 cobblestone_wall 14  
fill ~20 ~9 ~18 ~21 ~9 ~18 cobblestone_wall 14  
fill ~20 ~9 ~22 ~26 ~9 ~22 sandstone 1  
fill ~20 ~9 ~23 ~20 ~9 ~24 cobblestone_wall 14  
fill ~20 ~9 ~66 ~20 ~9 ~67 cobblestone_wall 14  
fill ~20 ~9 ~68 ~26 ~9 ~68 sandstone 1  
fill ~20 ~9 ~72 ~21 ~9 ~72 cobblestone_wall 14  
fill ~21 ~9 ~23 ~28 ~9 ~23 sandstone 1  
fill ~21 ~9 ~24 ~29 ~9 ~24 sandstone 1  
fill ~21 ~9 ~25 ~21 ~9 ~26 cobblestone_wall 14  
fill ~21 ~9 ~64 ~21 ~9 ~65 cobblestone_wall 14  
fill ~21 ~9 ~66 ~29 ~9 ~66 sandstone 1  
fill ~21 ~9 ~67 ~28 ~9 ~67 sandstone 1 
setblock ~22 ~9 ~19 cobblestone_wall 14  
fill ~22 ~9 ~25 ~30 ~9 ~25 sandstone 1  
fill ~22 ~9 ~26 ~31 ~9 ~26 sandstone 1  
fill ~22 ~9 ~27 ~22 ~9 ~28 cobblestone_wall 14  
fill ~22 ~9 ~62 ~22 ~9 ~63 cobblestone_wall 14  
fill ~22 ~9 ~64 ~31 ~9 ~64 sandstone 1  
fill ~22 ~9 ~65 ~30 ~9 ~65 sandstone 1 
setblock ~22 ~9 ~71 cobblestone_wall 14  
fill ~23 ~9 ~20 ~24 ~9 ~20 cobblestone_wall 14  
fill ~23 ~9 ~27 ~32 ~9 ~27 sandstone 1  
fill ~23 ~9 ~28 ~32 ~9 ~28 sandstone 1 
setblock ~23 ~9 ~29 cobblestone_wall 14 
setblock ~23 ~9 ~61 cobblestone_wall 14  
fill ~23 ~9 ~62 ~32 ~9 ~62 sandstone 1  
fill ~23 ~9 ~63 ~32 ~9 ~63 sandstone 1  
fill ~23 ~9 ~70 ~24 ~9 ~70 cobblestone_wall 14  
fill ~24 ~9 ~29 ~33 ~9 ~29 sandstone 1 
setblock ~24 ~9 ~30 cobblestone_wall 14 
setblock ~24 ~9 ~60 cobblestone_wall 14  
fill ~24 ~9 ~61 ~33 ~9 ~61 sandstone 1  
fill ~25 ~9 ~21 ~26 ~9 ~21 cobblestone_wall 14  
fill ~25 ~9 ~30 ~33 ~9 ~30 sandstone 1 
setblock ~25 ~9 ~31 cobblestone_wall 14 
setblock ~25 ~9 ~59 cobblestone_wall 14  
fill ~25 ~9 ~60 ~33 ~9 ~60 sandstone 1  
fill ~25 ~9 ~69 ~26 ~9 ~69 cobblestone_wall 14  
fill ~26 ~9 ~31 ~34 ~9 ~31 sandstone 1 
setblock ~26 ~9 ~32 cobblestone_wall 14 
setblock ~26 ~9 ~58 cobblestone_wall 14  
fill ~26 ~9 ~59 ~34 ~9 ~59 sandstone 1  
fill ~27 ~9 ~22 ~28 ~9 ~22 cobblestone_wall 14  
fill ~27 ~9 ~32 ~34 ~9 ~32 sandstone 1  
fill ~27 ~9 ~33 ~28 ~9 ~33 cobblestone_wall 14  
fill ~27 ~9 ~57 ~28 ~9 ~57 cobblestone_wall 14  
fill ~27 ~9 ~58 ~34 ~9 ~58 sandstone 1  
fill ~27 ~9 ~68 ~28 ~9 ~68 cobblestone_wall 14 
setblock ~29 ~9 ~23 cobblestone_wall 14  
fill ~29 ~9 ~33 ~35 ~9 ~33 sandstone 1  
fill ~29 ~9 ~34 ~30 ~9 ~34 cobblestone_wall 14  
fill ~29 ~9 ~56 ~30 ~9 ~56 cobblestone_wall 14  
fill ~29 ~9 ~57 ~35 ~9 ~57 sandstone 1 
setblock ~29 ~9 ~67 cobblestone_wall 14 
setblock ~30 ~9 ~24 cobblestone_wall 14 
setblock ~30 ~9 ~66 cobblestone_wall 14 
setblock ~31 ~9 ~25 cobblestone_wall 14  
fill ~31 ~9 ~34 ~36 ~9 ~34 sandstone 1  
fill ~31 ~9 ~35 ~32 ~9 ~35 cobblestone_wall 14  
fill ~31 ~9 ~55 ~32 ~9 ~55 cobblestone_wall 14  
fill ~31 ~9 ~56 ~36 ~9 ~56 sandstone 1 
setblock ~31 ~9 ~65 cobblestone_wall 14 
setblock ~32 ~9 ~26 cobblestone_wall 14  
fill ~32 ~9 ~42 ~58 ~9 ~42 iron_block 0  
fill ~32 ~9 ~43 ~58 ~9 ~43 iron_block 0  
fill ~32 ~9 ~44 ~58 ~9 ~44 iron_block 0  
fill ~32 ~9 ~45 ~44 ~9 ~45 iron_block 0  
fill ~32 ~9 ~46 ~58 ~9 ~46 iron_block 0  
fill ~32 ~9 ~47 ~58 ~9 ~47 iron_block 0  
fill ~32 ~9 ~48 ~58 ~9 ~48 iron_block 0 
setblock ~32 ~9 ~64 cobblestone_wall 14  
fill ~33 ~9 ~27 ~33 ~9 ~28 cobblestone_wall 14  
fill ~33 ~9 ~35 ~35 ~9 ~35 sandstone 1 
setblock ~33 ~9 ~36 cobblestone_wall 14  
fill ~33 ~9 ~39 ~57 ~9 ~39 iron_block 0  
fill ~33 ~9 ~40 ~57 ~9 ~40 iron_block 0  
fill ~33 ~9 ~41 ~57 ~9 ~41 iron_block 0  
fill ~33 ~9 ~49 ~57 ~9 ~49 iron_block 0  
fill ~33 ~9 ~50 ~57 ~9 ~50 iron_block 0  
fill ~33 ~9 ~51 ~57 ~9 ~51 iron_block 0 
setblock ~33 ~9 ~54 cobblestone_wall 14  
fill ~33 ~9 ~55 ~35 ~9 ~55 sandstone 1  
fill ~33 ~9 ~62 ~33 ~9 ~63 cobblestone_wall 14  
fill ~34 ~9 ~29 ~34 ~9 ~30 cobblestone_wall 14 
setblock ~34 ~9 ~36 sandstone 1  
fill ~34 ~9 ~38 ~56 ~9 ~38 iron_block 0  
fill ~34 ~9 ~52 ~56 ~9 ~52 iron_block 0 
setblock ~34 ~9 ~54 sandstone 1  
fill ~34 ~9 ~60 ~34 ~9 ~61 cobblestone_wall 14  
fill ~35 ~9 ~31 ~35 ~9 ~32 cobblestone_wall 14  
fill ~35 ~9 ~36 ~55 ~9 ~36 iron_block 0  
fill ~35 ~9 ~37 ~55 ~9 ~37 iron_block 0  
fill ~35 ~9 ~53 ~55 ~9 ~53 iron_block 0  
fill ~35 ~9 ~54 ~55 ~9 ~54 iron_block 0  
fill ~35 ~9 ~58 ~35 ~9 ~59 cobblestone_wall 14 
setblock ~36 ~9 ~33 cobblestone_wall 14  
fill ~36 ~9 ~35 ~54 ~9 ~35 iron_block 0  
fill ~36 ~9 ~55 ~54 ~9 ~55 iron_block 0 
setblock ~36 ~9 ~57 cobblestone_wall 14  
fill ~38 ~9 ~34 ~52 ~9 ~34 iron_block 0  
fill ~38 ~9 ~56 ~52 ~9 ~56 iron_block 0  
fill ~39 ~9 ~33 ~51 ~9 ~33 iron_block 0  
fill ~39 ~9 ~57 ~51 ~9 ~57 iron_block 0  
fill ~42 ~9 ~32 ~48 ~9 ~32 iron_block 0  
fill ~42 ~9 ~58 ~48 ~9 ~58 iron_block 0  
fill ~46 ~9 ~45 ~58 ~9 ~45 iron_block 0 
setblock ~54 ~9 ~33 cobblestone_wall 14  
fill ~54 ~9 ~34 ~59 ~9 ~34 sandstone 1  
fill ~54 ~9 ~56 ~59 ~9 ~56 sandstone 1 
setblock ~54 ~9 ~57 cobblestone_wall 14  
fill ~55 ~9 ~31 ~55 ~9 ~32 cobblestone_wall 14  
fill ~55 ~9 ~33 ~61 ~9 ~33 sandstone 1  
fill ~55 ~9 ~35 ~57 ~9 ~35 sandstone 1  
fill ~55 ~9 ~55 ~57 ~9 ~55 sandstone 1  
fill ~55 ~9 ~57 ~61 ~9 ~57 sandstone 1  
fill ~55 ~9 ~58 ~55 ~9 ~59 cobblestone_wall 14  
fill ~56 ~9 ~29 ~56 ~9 ~30 cobblestone_wall 14  
fill ~56 ~9 ~31 ~64 ~9 ~31 sandstone 1  
fill ~56 ~9 ~32 ~63 ~9 ~32 sandstone 1 
setblock ~56 ~9 ~36 sandstone 1 
setblock ~56 ~9 ~54 sandstone 1  
fill ~56 ~9 ~58 ~63 ~9 ~58 sandstone 1  
fill ~56 ~9 ~59 ~64 ~9 ~59 sandstone 1  
fill ~56 ~9 ~60 ~56 ~9 ~61 cobblestone_wall 14  
fill ~57 ~9 ~27 ~57 ~9 ~28 cobblestone_wall 14  
fill ~57 ~9 ~29 ~66 ~9 ~29 sandstone 1  
fill ~57 ~9 ~30 ~65 ~9 ~30 sandstone 1 
setblock ~57 ~9 ~36 cobblestone_wall 14 
setblock ~57 ~9 ~54 cobblestone_wall 14  
fill ~57 ~9 ~60 ~65 ~9 ~60 sandstone 1  
fill ~57 ~9 ~61 ~66 ~9 ~61 sandstone 1  
fill ~57 ~9 ~62 ~57 ~9 ~63 cobblestone_wall 14 
setblock ~58 ~9 ~26 cobblestone_wall 14  
fill ~58 ~9 ~27 ~67 ~9 ~27 sandstone 1  
fill ~58 ~9 ~28 ~67 ~9 ~28 sandstone 1  
fill ~58 ~9 ~35 ~59 ~9 ~35 cobblestone_wall 14  
fill ~58 ~9 ~55 ~59 ~9 ~55 cobblestone_wall 14  
fill ~58 ~9 ~62 ~67 ~9 ~62 sandstone 1  
fill ~58 ~9 ~63 ~67 ~9 ~63 sandstone 1 
setblock ~58 ~9 ~64 cobblestone_wall 14 
setblock ~59 ~9 ~25 cobblestone_wall 14  
fill ~59 ~9 ~26 ~68 ~9 ~26 sandstone 1  
fill ~59 ~9 ~64 ~68 ~9 ~64 sandstone 1 
setblock ~59 ~9 ~65 cobblestone_wall 14 
setblock ~60 ~9 ~24 cobblestone_wall 14  
fill ~60 ~9 ~25 ~68 ~9 ~25 sandstone 1  
fill ~60 ~9 ~34 ~61 ~9 ~34 cobblestone_wall 14  
fill ~60 ~9 ~56 ~61 ~9 ~56 cobblestone_wall 14  
fill ~60 ~9 ~65 ~68 ~9 ~65 sandstone 1 
setblock ~60 ~9 ~66 cobblestone_wall 14 
setblock ~61 ~9 ~23 cobblestone_wall 14  
fill ~61 ~9 ~24 ~69 ~9 ~24 sandstone 1  
summon ItemFrame ~20.9375 ~22.5 ~31.5 
summon ItemFrame ~25.5 ~52.5 ~40.9375 
summon ItemFrame ~24.0625 ~52.5 ~40.5 
summon Painting ~22.0625 ~37.0 ~52.0 
summon Painting ~24.0 ~36.5 ~51.0625 
summon Painting ~25.5 ~37.0 ~55.9375 
summon Painting ~22.0625 ~38.5 ~53.5 
summon Painting ~20.0625 ~47.0 ~46.0 
summon Painting ~18.9375 ~47.0 ~46.0 
summon Painting ~30.0625 ~36.5 ~28.0 
summon Painting ~31.0625 ~37.5 ~26.5 
summon Painting ~35.5 ~36.5 ~23.0625 
summon Painting ~31.0625 ~35.5 ~26.5 
summon Painting ~38.5 ~37.0 ~27.0625 
summon Painting ~33.5 ~37.0 ~28.9375 
summon Painting ~39.5 ~49.5 ~21.0625 
summon ItemFrame ~35.9375 ~41.5 ~26.5 
summon ItemFrame ~35.9375 ~41.5 ~27.5 
summon ItemFrame ~35.9375 ~41.5 ~28.5 
summon ItemFrame ~35.9375 ~42.5 ~27.5 
summon ItemFrame ~35.9375 ~42.5 ~28.5 
summon Painting ~39.5 ~42.5 ~25.9375 
summon ItemFrame ~40.0625 ~42.5 ~23.5 
summon ItemFrame ~40.0625 ~42.5 ~21.5 
summon Painting ~36.9375 ~49.5 ~22.0 
summon Painting ~36.9375 ~50.5 ~23.0 
summon Painting ~36.9375 ~50.5 ~21.5 
summon ItemFrame ~37.5 ~48.5 ~19.9375 
summon ItemFrame ~40.9375 ~59.5 ~28.5 
summon ItemFrame ~38.0625 ~59.5 ~28.5 
summon Painting ~37.5 ~64.5 ~27.0625 
summon Painting ~38.0625 ~64.5 ~25.0 
summon ItemFrame ~40.0625 ~62.5 ~23.5 
summon ItemFrame ~40.0625 ~62.5 ~26.5 
summon Painting ~40.9375 ~65.0 ~23.0 
summon Painting ~40.9375 ~65.0 ~27.0 
summon Painting ~36.9375 ~65.5 ~25.5 
summon Painting ~38.0625 ~63.5 ~19.5 
summon Painting ~38.0625 ~64.5 ~19.0 
summon ItemFrame ~38.0625 ~62.5 ~19.5 
summon ItemFrame ~34.0625 ~62.5 ~28.5 
summon Painting ~38.0625 ~58.0 ~26.0 
summon Painting ~38.0625 ~58.0 ~22.0 
summon ItemFrame ~36.5 ~34.5 ~32.9375 
summon ItemFrame ~35.5 ~34.5 ~32.9375 
summon ItemFrame ~33.9375 ~35.5 ~30.5 
summon Painting ~35.0625 ~37.0 ~30.5 
summon Painting ~36.5 ~35.5 ~36.9375 
summon Painting ~36.0 ~37.0 ~38.0625 
summon Painting ~32.0 ~37.0 ~38.0625 
summon Painting ~36.0625 ~37.0 ~44.0 
summon ItemFrame ~34.9375 ~35.5 ~43.5 
summon ItemFrame ~34.9375 ~35.5 ~42.5 
summon ItemFrame ~34.9375 ~36.5 ~42.5 
summon ItemFrame ~34.9375 ~36.5 ~43.5 
summon Painting ~34.9375 ~36.5 ~41.5 
summon ItemFrame ~31.0625 ~35.5 ~44.5 
summon ItemFrame ~31.0625 ~36.5 ~44.5 
summon ItemFrame ~29.9375 ~35.5 ~44.5 
summon ItemFrame ~29.9375 ~36.5 ~44.5 
summon ItemFrame ~36.9375 ~27.5 ~31.5 
summon Painting ~34.0 ~44.0 ~41.0625 
summon ItemFrame ~37.5 ~52.5 ~42.0625 
summon ItemFrame ~26.0625 ~52.5 ~41.5 
summon ItemFrame ~30.9375 ~52.5 ~41.5 
summon ItemFrame ~31.5 ~52.5 ~40.9375 
summon ItemFrame ~28.9375 ~52.5 ~34.5 
summon ItemFrame ~27.0625 ~52.5 ~33.5 
summon ItemFrame ~29.5 ~52.5 ~35.0625 
summon ItemFrame ~36.5 ~50.5 ~35.0625 
summon ItemFrame ~34.5 ~48.5 ~35.0625 
summon ItemFrame ~32.5 ~46.5 ~35.0625 
summon ItemFrame ~30.5 ~44.5 ~35.0625 
summon ItemFrame ~30.5 ~42.5 ~29.0625 
summon ItemFrame ~31.5 ~42.5 ~29.0625 
summon ItemFrame ~30.5 ~43.5 ~29.0625 
summon ItemFrame ~31.5 ~43.5 ~29.0625 
summon ItemFrame ~30.5 ~44.5 ~29.0625 
summon ItemFrame ~31.5 ~44.5 ~29.0625 
summon ItemFrame ~31.5 ~41.5 ~32.0625 
summon ItemFrame ~31.5 ~41.5 ~30.9375 
summon Painting ~30.0625 ~43.5 ~31.0 
summon Painting ~34.5 ~42.5 ~33.9375 
summon ItemFrame ~33.5 ~43.5 ~32.9375 
summon ItemFrame ~35.9375 ~41.5 ~29.5 
summon ItemFrame ~35.9375 ~42.5 ~29.5 
summon Painting ~30.5 ~41.5 ~29.0625 
summon Painting ~36.9375 ~51.0 ~31.0 
summon ItemFrame ~41.5 ~59.5 ~38.0625 
summon ItemFrame ~37.5 ~59.5 ~35.0625 
summon ItemFrame ~38.0625 ~59.5 ~34.5 
summon ItemFrame ~40.9375 ~59.5 ~34.5 
summon ItemFrame ~40.9375 ~59.5 ~37.5 
summon ItemFrame ~28.0625 ~59.5 ~40.5 
summon ItemFrame ~28.0625 ~59.5 ~37.5 
summon ItemFrame ~30.5 ~59.5 ~35.0625 
summon Painting ~33.0625 ~64.5 ~29.5 
summon Painting ~39.0 ~65.0 ~29.9375 
summon Painting ~28.0625 ~58.0 ~44.0 
summon Painting ~38.0625 ~58.0 ~31.0 
summon ItemFrame ~40.5 ~34.5 ~58.0625 
summon Painting ~26.0 ~37.0 ~50.0625 
summon ItemFrame ~28.5 ~35.5 ~48.9375 
summon ItemFrame ~27.5 ~35.5 ~48.9375 
summon ItemFrame ~28.5 ~36.5 ~48.9375 
summon ItemFrame ~27.5 ~36.5 ~48.9375 
summon ItemFrame ~28.5 ~37.5 ~48.9375 
summon ItemFrame ~27.5 ~37.5 ~48.9375 
summon Painting ~28.5 ~37.0 ~55.9375 
summon ItemFrame ~34.9375 ~35.5 ~45.5 
summon ItemFrame ~34.9375 ~36.5 ~45.5 
summon ItemFrame ~34.9375 ~36.5 ~46.5 
summon ItemFrame ~34.9375 ~35.5 ~46.5 
summon ItemFrame ~31.0625 ~35.5 ~45.5 
summon ItemFrame ~31.0625 ~36.5 ~45.5 
summon ItemFrame ~29.9375 ~35.5 ~45.5 
summon ItemFrame ~29.9375 ~36.5 ~45.5 
summon ItemFrame ~37.9375 ~34.5 ~59.5 
summon ItemFrame ~37.9375 ~34.5 ~60.5 
summon ItemFrame ~37.9375 ~35.5 ~59.5 
summon ItemFrame ~37.9375 ~35.5 ~60.5 
summon ItemFrame ~37.9375 ~36.5 ~59.5 
summon ItemFrame ~37.9375 ~36.5 ~60.5 
summon Painting ~36.9375 ~36.5 ~56.5 
summon Painting ~36.9375 ~36.5 ~53.5 
summon Painting ~26.5 ~38.5 ~47.9375 
summon Painting ~27.0 ~42.5 ~47.0625 
summon Painting ~32.5 ~42.5 ~51.0625 
summon Painting ~32.5 ~43.5 ~51.0625 
summon Painting ~32.5 ~44.5 ~51.0625 
summon Painting ~32.5 ~45.5 ~51.0625 
summon Painting ~37.0625 ~42.5 ~60.5 
summon ItemFrame ~39.5 ~52.5 ~52.9375 
summon ItemFrame ~33.0625 ~52.5 ~50.5 
summon ItemFrame ~36.5 ~52.5 ~53.9375 
summon ItemFrame ~37.0625 ~52.5 ~54.5 
summon ItemFrame ~29.0625 ~52.5 ~46.5 
summon ItemFrame ~30.9375 ~52.5 ~45.5 
summon ItemFrame ~32.0625 ~52.5 ~45.5 
summon ItemFrame ~41.0625 ~52.5 ~58.5 
summon ItemFrame ~40.5 ~52.5 ~57.9375 
summon Painting ~36.9375 ~44.0 ~49.0 
summon Painting ~36.9375 ~44.0 ~52.0 
summon Painting ~36.9375 ~44.0 ~55.0 
summon ItemFrame ~28.0625 ~59.5 ~48.5 
summon ItemFrame ~31.5 ~59.5 ~51.9375 
summon ItemFrame ~32.0625 ~59.5 ~52.5 
summon ItemFrame ~35.5 ~59.5 ~55.9375 
summon ItemFrame ~36.0625 ~59.5 ~56.5 
summon ItemFrame ~39.5 ~59.5 ~59.9375 
summon Painting ~28.0625 ~58.0 ~47.0 
summon Painting ~41.0625 ~35.5 ~68.0 
summon Painting ~41.0625 ~36.5 ~69.5 
summon Painting ~38.0 ~31.0 ~62.9375 
summon Painting ~41.0625 ~30.0 ~63.0 
summon Painting ~41.0 ~37.0 ~63.9375 
summon Painting ~41.0625 ~50.5 ~65.5 
summon ItemFrame ~41.5 ~59.5 ~61.0625 
summon Painting ~47.9375 ~31.0 ~26.5 
summon Painting ~47.9375 ~31.0 ~27.5 
summon Painting ~47.9375 ~31.0 ~28.5 
summon Painting ~43.0 ~37.0 ~27.0625 
summon Painting ~51.9375 ~29.0 ~27.0 
summon ItemFrame ~53.0625 ~28.5 ~25.5 
summon Painting ~50.9375 ~50.5 ~27.0 
summon Painting ~46.0 ~49.5 ~26.0625 
summon Painting ~47.5 ~49.5 ~26.0625 
summon Painting ~48.5 ~50.5 ~26.0625 
summon Painting ~47.5 ~50.5 ~26.0625 
summon Painting ~43.5 ~45.5 ~22.0625 
summon Painting ~47.9375 ~44.0 ~23.0 
summon Painting ~46.9375 ~43.5 ~26.5 
summon Painting ~46.9375 ~44.5 ~26.5 
summon ItemFrame ~45.9375 ~41.5 ~26.5 
summon Painting ~44.0 ~44.0 ~26.9375 
summon Painting ~50.0625 ~44.0 ~24.0 
summon Painting ~55.0 ~43.5 ~21.0625 
summon ItemFrame ~53.5 ~41.5 ~22.0625 
summon ItemFrame ~53.5 ~41.5 ~22.9375 
summon ItemFrame ~53.5 ~41.5 ~24.0625 
summon ItemFrame ~56.5 ~41.5 ~24.0625 
summon ItemFrame ~56.5 ~41.5 ~22.0625 
summon ItemFrame ~56.5 ~41.5 ~22.9375 
summon Painting ~57.9375 ~42.5 ~27.5 
summon ItemFrame ~57.9375 ~42.5 ~26.5 
summon Painting ~57.9375 ~43.5 ~28.0 
summon Painting ~57.5 ~43.5 ~22.0625 
summon Painting ~46.0 ~43.5 ~28.0625 
summon ItemFrame ~48.5 ~55.5 ~25.9375 
summon ItemFrame ~44.5 ~55.5 ~25.9375 
summon ItemFrame ~44.5 ~55.5 ~28.9375 
summon ItemFrame ~44.5 ~55.5 ~27.0625 
summon ItemFrame ~48.5 ~55.5 ~28.9375 
summon ItemFrame ~48.5 ~55.5 ~27.0625 
summon Painting ~45.0 ~57.5 ~22.0625 
summon Painting ~48.0 ~58.0 ~22.0625 
summon Painting ~50.9375 ~59.5 ~28.5 
summon ItemFrame ~51.5 ~59.5 ~21.0625 
summon ItemFrame ~42.0625 ~59.5 ~28.5 
summon ItemFrame ~46.5 ~59.5 ~21.0625 
summon ItemFrame ~46.5 ~69.5 ~25.9375 
summon ItemFrame ~48.5 ~62.5 ~19.0625 
summon ItemFrame ~48.9375 ~62.5 ~19.5 
summon ItemFrame ~50.0625 ~62.5 ~19.5 
summon Painting ~50.5 ~63.5 ~18.0625 
summon Painting ~50.9375 ~65.0 ~19.0 
summon Painting ~46.0625 ~70.5 ~21.5 
summon Painting ~50.5 ~72.0 ~26.9375 
summon Painting ~50.5 ~72.0 ~21.0625 
summon Painting ~46.0625 ~73.0 ~22.0 
summon Painting ~56.0625 ~28.0 ~34.5 
summon Painting ~55.5 ~27.5 ~33.9375 
summon Painting ~55.5 ~28.5 ~33.9375 
summon Painting ~47.9375 ~31.0 ~33.0 
summon Painting ~47.9375 ~31.0 ~29.5 
summon Painting ~56.5 ~29.5 ~36.0625 
summon Painting ~55.0 ~29.5 ~36.0625 
summon ItemFrame ~55.5 ~28.5 ~36.0625 
summon Painting ~57.5 ~35.5 ~37.0625 
summon Painting ~57.5 ~36.5 ~37.0625 
summon Painting ~50.0625 ~37.0 ~39.0 
summon Painting ~42.5 ~37.0 ~34.9375 
summon ItemFrame ~57.0625 ~27.5 ~40.5 
summon ItemFrame ~55.9375 ~27.5 ~40.5 
summon ItemFrame ~55.0625 ~27.5 ~40.5 
summon ItemFrame ~53.9375 ~27.5 ~40.5 
summon ItemFrame ~53.0625 ~27.5 ~40.5 
summon ItemFrame ~51.9375 ~27.5 ~40.5 
summon ItemFrame ~51.5 ~34.5 ~39.9375 
summon ItemFrame ~52.5 ~34.5 ~39.9375 
summon ItemFrame ~42.9375 ~27.5 ~32.5 
summon ItemFrame ~48.0625 ~27.5 ~31.5 
summon Painting ~53.0 ~28.5 ~34.9375 
summon Painting ~48.0625 ~28.5 ~33.0 
summon ItemFrame ~52.0625 ~26.5 ~31.5 
summon ItemFrame ~52.9375 ~26.5 ~31.5 
summon ItemFrame ~54.0625 ~26.5 ~31.5 
summon ItemFrame ~54.0625 ~26.5 ~34.5 
summon ItemFrame ~50.9375 ~26.5 ~31.5 
summon ItemFrame ~50.9375 ~26.5 ~34.5 
summon ItemFrame ~52.9375 ~26.5 ~34.5 
summon ItemFrame ~52.0625 ~26.5 ~34.5 
summon Painting ~54.0 ~51.0 ~38.0625 
summon ItemFrame ~49.5 ~52.5 ~42.0625 
summon ItemFrame ~43.5 ~52.5 ~42.0625 
summon ItemFrame ~54.9375 ~52.5 ~44.5 
summon Painting ~48.0 ~50.5 ~31.9375 
summon Painting ~48.0 ~49.5 ~36.9375 
summon ItemFrame ~55.9375 ~42.5 ~31.5 
summon ItemFrame ~55.9375 ~43.5 ~31.5 
summon ItemFrame ~55.9375 ~41.5 ~35.5 
summon ItemFrame ~57.0625 ~41.5 ~35.5 
summon Painting ~54.0 ~44.0 ~43.9375 
summon ItemFrame ~54.5 ~42.5 ~43.9375 
summon Painting ~57.0 ~45.0 ~36.9375 
summon Painting ~57.0 ~45.0 ~38.0625 
summon ItemFrame ~56.0625 ~42.5 ~43.5 
summon ItemFrame ~56.0625 ~43.5 ~43.5 
summon ItemFrame ~56.0625 ~44.5 ~43.5 
summon ItemFrame ~55.5 ~45.5 ~33.0625 
summon ItemFrame ~53.5 ~42.5 ~33.0625 
summon Painting ~47.0 ~44.0 ~29.9375 
summon Painting ~43.0 ~44.0 ~29.9375 
summon Painting ~50.0625 ~44.0 ~38.5 
summon Painting ~50.0625 ~44.0 ~36.5 
summon ItemFrame ~44.5 ~55.5 ~31.9375 
summon ItemFrame ~44.5 ~55.5 ~30.0625 
summon ItemFrame ~44.5 ~55.5 ~33.0625 
summon ItemFrame ~48.5 ~55.5 ~33.0625 
summon ItemFrame ~48.5 ~55.5 ~30.0625 
summon ItemFrame ~48.5 ~55.5 ~31.9375 
summon ItemFrame ~45.9375 ~55.5 ~33.5 
summon ItemFrame ~47.0625 ~55.5 ~33.5 
summon Painting ~54.9375 ~67.5 ~35.0 
summon ItemFrame ~46.5 ~59.5 ~38.0625 
summon ItemFrame ~51.5 ~59.5 ~38.0625 
summon ItemFrame ~57.5 ~59.5 ~38.0625 
summon ItemFrame ~42.0625 ~59.5 ~34.5 
summon ItemFrame ~51.5 ~59.5 ~35.9375 
summon ItemFrame ~53.5 ~66.5 ~40.9375 
summon ItemFrame ~53.5 ~66.5 ~42.0625 
summon ItemFrame ~44.5 ~66.5 ~44.0625 
summon ItemFrame ~44.5 ~73.5 ~44.0625 
summon Painting ~43.0625 ~75.5 ~44.5 
summon ItemFrame ~53.0625 ~73.5 ~32.5 
summon ItemFrame ~51.9375 ~73.5 ~32.5 
summon Painting ~52.0 ~75.5 ~31.0625 
summon Painting ~56.0 ~75.5 ~31.0625 
summon Painting ~51.0625 ~75.5 ~39.5 
summon Painting ~51.0625 ~74.5 ~32.5 
summon ItemFrame ~52.5 ~34.5 ~59.0625 
summon ItemFrame ~49.5 ~34.5 ~59.0625 
summon ItemFrame ~48.5 ~34.5 ~59.0625 
summon ItemFrame ~45.5 ~34.5 ~59.0625 
summon Painting ~43.0 ~37.0 ~56.0625 
summon ItemFrame ~42.0625 ~34.5 ~60.5 
summon ItemFrame ~44.5 ~34.5 ~60.9375 
summon ItemFrame ~46.5 ~34.5 ~60.9375 
summon ItemFrame ~48.5 ~34.5 ~60.9375 
summon ItemFrame ~50.5 ~34.5 ~60.9375 
summon ItemFrame ~49.9375 ~27.5 ~55.5 
summon ItemFrame ~45.0625 ~26.5 ~53.5 
summon ItemFrame ~43.9375 ~26.5 ~53.5 
summon Painting ~49.9375 ~27.5 ~58.5 
summon Painting ~49.9375 ~27.5 ~59.5 
summon Painting ~45.5 ~27.5 ~57.0625 
summon Painting ~44.5 ~28.0 ~55.9375 
summon Painting ~44.5 ~31.0 ~55.9375 
summon Painting ~49.9375 ~31.0 ~55.0 
summon Painting ~43.5 ~27.5 ~59.9375 
summon Painting ~54.0 ~28.5 ~50.0625 
summon Painting ~55.5 ~28.5 ~50.0625 
summon ItemFrame ~56.0625 ~27.5 ~49.5 
summon ItemFrame ~56.0625 ~27.5 ~48.5 
summon ItemFrame ~56.0625 ~28.5 ~49.5 
summon ItemFrame ~56.0625 ~28.5 ~48.5 
summon ItemFrame ~54.9375 ~34.5 ~60.5 
summon ItemFrame ~56.9375 ~34.5 ~60.5 
summon ItemFrame ~56.0625 ~34.5 ~60.5 
summon ItemFrame ~56.9375 ~34.5 ~58.5 
summon ItemFrame ~57.5 ~34.5 ~55.0625 
summon ItemFrame ~55.5 ~34.5 ~55.0625 
summon ItemFrame ~55.5 ~34.5 ~55.9375 
summon ItemFrame ~55.5 ~34.5 ~57.0625 
summon ItemFrame ~53.5 ~34.5 ~57.0625 
summon Painting ~51.0625 ~29.0 ~60.0 
summon ItemFrame ~45.5 ~52.5 ~52.9375 
summon ItemFrame ~51.5 ~52.5 ~52.9375 
summon ItemFrame ~47.5 ~52.5 ~58.9375 
summon ItemFrame ~47.5 ~52.5 ~58.9375 
summon ItemFrame ~46.9375 ~52.5 ~59.5 
summon ItemFrame ~45.5 ~52.5 ~54.0625 
summon ItemFrame ~51.5 ~52.5 ~54.0625 
summon ItemFrame ~54.9375 ~52.5 ~53.5 
summon ItemFrame ~54.9375 ~52.5 ~58.5 
summon ItemFrame ~53.5 ~41.5 ~59.9375 
summon ItemFrame ~56.5 ~41.5 ~59.9375 
summon Painting ~54.9375 ~58.0 ~45.0 
summon Painting ~54.9375 ~58.0 ~50.0 
summon ItemFrame ~46.9375 ~59.5 ~57.5 
summon ItemFrame ~47.5 ~59.5 ~56.9375 
summon ItemFrame ~55.5 ~59.5 ~56.9375 
summon Painting ~54.5 ~65.5 ~54.0625 
summon Painting ~54.0 ~66.5 ~55.0625 
summon Painting ~54.9375 ~67.0 ~57.0 
summon Painting ~45.0 ~67.0 ~57.9375 
summon ItemFrame ~46.0625 ~67.5 ~48.5 
summon ItemFrame ~45.5 ~67.5 ~47.9375 
summon ItemFrame ~45.0625 ~67.5 ~47.5 
summon ItemFrame ~44.5 ~67.5 ~46.9375 
summon ItemFrame ~44.0625 ~67.5 ~46.5 
summon ItemFrame ~46.0625 ~68.5 ~48.5 
summon ItemFrame ~45.5 ~68.5 ~47.9375 
summon ItemFrame ~44.5 ~67.5 ~46.9375 
summon ItemFrame ~44.0625 ~68.5 ~46.5 
summon ItemFrame ~44.5 ~68.5 ~46.9375 
summon ItemFrame ~45.0625 ~68.5 ~47.5 
summon ItemFrame ~46.0625 ~69.5 ~48.5 
summon ItemFrame ~45.5 ~69.5 ~47.9375 
summon ItemFrame ~45.0625 ~69.5 ~47.5 
summon ItemFrame ~44.5 ~69.5 ~46.9375 
summon ItemFrame ~44.0625 ~69.5 ~46.5 
summon Painting ~44.0 ~58.0 ~59.9375 
summon Painting ~51.0 ~67.5 ~45.0625 
summon Painting ~43.0625 ~68.0 ~45.0 
summon ItemFrame ~46.0625 ~70.5 ~48.5 
summon ItemFrame ~45.5 ~70.5 ~47.9375 
summon ItemFrame ~45.0625 ~70.5 ~47.5 
summon ItemFrame ~44.5 ~70.5 ~46.9375 
summon ItemFrame ~44.0625 ~70.5 ~46.5 
summon Painting ~51.0 ~76.0 ~45.0625 
summon ItemFrame ~43.0625 ~77.5 ~45.5 
summon ItemFrame ~46.5 ~77.5 ~48.9375 
summon ItemFrame ~52.5 ~77.5 ~48.9375 
summon ItemFrame ~53.5 ~77.5 ~46.0625 
summon ItemFrame ~49.5 ~77.5 ~45.0625 
summon ItemFrame ~46.5 ~74.5 ~45.0625 
summon ItemFrame ~47.5 ~74.5 ~45.0625 
summon ItemFrame ~46.5 ~75.5 ~45.0625 
summon ItemFrame ~47.5 ~75.5 ~45.0625 
summon ItemFrame ~46.5 ~76.5 ~45.0625 
summon ItemFrame ~47.5 ~76.5 ~45.0625 
summon ItemFrame ~48.5 ~73.5 ~47.9375 
summon ItemFrame ~50.5 ~73.5 ~47.9375 
summon Painting ~52.9375 ~75.5 ~48.5 
summon ItemFrame ~52.9375 ~81.5 ~48.5 
summon ItemFrame ~52.9375 ~81.5 ~47.5 
summon ItemFrame ~52.9375 ~82.5 ~47.5 
summon ItemFrame ~52.9375 ~82.5 ~48.5 
summon Painting ~51.0 ~83.0 ~48.9375 
summon ItemFrame ~42.0625 ~34.5 ~63.5 
summon ItemFrame ~50.5 ~34.5 ~62.0625 
summon ItemFrame ~46.5 ~34.5 ~62.0625 
summon ItemFrame ~48.5 ~34.5 ~62.0625 
summon ItemFrame ~44.5 ~34.5 ~62.0625 
summon Painting ~49.9375 ~27.5 ~63.0 
summon Painting ~49.9375 ~28.5 ~62.0 
summon Painting ~45.5 ~27.5 ~61.0625 
summon Painting ~43.5 ~27.5 ~63.9375 
summon Painting ~42.0 ~27.5 ~64.9375 
summon ItemFrame ~51.5 ~34.5 ~62.9375 
summon ItemFrame ~53.5 ~34.5 ~62.9375 
summon ItemFrame ~54.9375 ~34.5 ~62.5 
summon ItemFrame ~45.5 ~34.5 ~64.9375 
summon ItemFrame ~45.5 ~34.5 ~66.9375 
summon ItemFrame ~45.5 ~34.5 ~68.9375 
summon ItemFrame ~45.5 ~34.5 ~66.0625 
summon ItemFrame ~45.5 ~34.5 ~68.0625 
summon ItemFrame ~45.5 ~34.5 ~70.0625 
summon Painting ~51.0625 ~27.5 ~63.0 
summon Painting ~54.5 ~28.0 ~64.0625 
summon Painting ~51.5 ~28.0 ~65.0625 
summon Painting ~42.5 ~29.5 ~66.0625 
summon Painting ~44.5 ~29.5 ~66.0625 
summon Painting ~46.5 ~29.5 ~66.0625 
summon Painting ~48.5 ~29.5 ~66.0625 
summon Painting ~42.0625 ~51.5 ~67.5 
summon ItemFrame ~44.9375 ~48.5 ~67.5 
summon ItemFrame ~44.5 ~48.5 ~67.0625 
summon ItemFrame ~46.5 ~48.5 ~67.0625 
summon ItemFrame ~46.0625 ~48.5 ~67.5 
summon ItemFrame ~46.0625 ~48.5 ~65.5 
summon ItemFrame ~46.5 ~48.5 ~65.9375 
summon ItemFrame ~44.5 ~48.5 ~65.9375 
summon ItemFrame ~44.9375 ~48.5 ~65.5 
summon Painting ~46.9375 ~51.0 ~67.0 
summon ItemFrame ~53.5 ~41.5 ~61.0625 
summon ItemFrame ~53.5 ~41.5 ~61.9375 
summon ItemFrame ~53.5 ~41.5 ~63.0625 
summon ItemFrame ~56.5 ~41.5 ~61.0625 
summon ItemFrame ~56.5 ~41.5 ~61.9375 
summon ItemFrame ~56.5 ~41.5 ~63.0625 
summon ItemFrame ~43.5 ~59.5 ~61.0625 
summon ItemFrame ~45.5 ~59.5 ~61.0625 
summon Painting ~62.9375 ~27.5 ~36.5 
summon Painting ~62.9375 ~27.5 ~37.5 
summon ItemFrame ~61.5 ~26.5 ~37.0625 
summon ItemFrame ~61.5 ~26.5 ~35.9375 
summon Painting ~62.0 ~27.5 ~39.9375 
summon ItemFrame ~58.9375 ~41.5 ~40.5 
summon ItemFrame ~58.9375 ~41.5 ~41.5 
summon Painting ~58.0 ~44.0 ~43.9375 
summon Painting ~59.9375 ~44.5 ~41.5 
summon Painting ~61.0 ~57.5 ~41.0625 
summon ItemFrame ~63.5 ~34.5 ~49.0625 
summon Painting ~63.0 ~37.0 ~52.9375 
summon ItemFrame ~58.9375 ~34.5 ~58.5 
summon ItemFrame ~58.0625 ~34.5 ~58.5 
summon ItemFrame ~58.9375 ~34.5 ~56.5 
summon ItemFrame ~60.0625 ~34.5 ~56.5 
summon Painting ~65.0 ~43.5 ~46.0625 
summon Painting ~62.9375 ~44.5 ~57.5 
summon Painting ~63.9375 ~44.0 ~54.5 
summon ItemFrame ~60.0625 ~49.5 ~52.5 
summon ItemFrame ~60.5 ~41.5 ~45.0625 
summon ItemFrame ~61.5 ~41.5 ~45.0625 
summon ItemFrame ~58.5 ~41.5 ~59.9375 
summon ItemFrame ~58.5 ~41.5 ~57.9375 
summon ItemFrame ~61.5 ~41.5 ~57.9375 
summon ItemFrame ~61.5 ~41.5 ~59.9375 
summon ItemFrame ~61.5 ~41.5 ~59.0625 
summon ItemFrame ~58.5 ~41.5 ~59.0625 
summon ItemFrame ~62.5 ~41.5 ~52.0625 
summon ItemFrame ~62.5 ~41.5 ~50.0625 
summon ItemFrame ~65.5 ~41.5 ~50.0625 
summon ItemFrame ~65.5 ~41.5 ~50.9375 
summon ItemFrame ~65.5 ~41.5 ~52.0625 
summon ItemFrame ~62.5 ~41.5 ~48.9375 
summon ItemFrame ~65.5 ~41.5 ~48.9375 
summon ItemFrame ~62.5 ~41.5 ~50.9375 
summon ItemFrame ~61.5 ~41.5 ~61.0625 
summon ItemFrame ~58.5 ~41.5 ~61.0625 
fill ~61 ~9 ~66 ~69 ~9 ~66 sandstone 1 
setblock ~61 ~9 ~67 cobblestone_wall 14  
fill ~62 ~9 ~22 ~63 ~9 ~22 cobblestone_wall 14  
fill ~62 ~9 ~23 ~69 ~9 ~23 sandstone 1  
fill ~62 ~9 ~33 ~63 ~9 ~33 cobblestone_wall 14  
fill ~62 ~9 ~57 ~63 ~9 ~57 cobblestone_wall 14  
fill ~62 ~9 ~67 ~69 ~9 ~67 sandstone 1  
fill ~62 ~9 ~68 ~63 ~9 ~68 cobblestone_wall 14  
fill ~64 ~9 ~21 ~65 ~9 ~21 cobblestone_wall 14  
fill ~64 ~9 ~22 ~70 ~9 ~22 sandstone 1 
setblock ~64 ~9 ~32 cobblestone_wall 14 
setblock ~64 ~9 ~58 cobblestone_wall 14  
fill ~64 ~9 ~68 ~70 ~9 ~68 sandstone 1  
fill ~64 ~9 ~69 ~65 ~9 ~69 cobblestone_wall 14 
setblock ~65 ~9 ~31 cobblestone_wall 14 
setblock ~65 ~9 ~59 cobblestone_wall 14  
fill ~66 ~9 ~20 ~67 ~9 ~20 cobblestone_wall 14  
fill ~66 ~9 ~21 ~71 ~9 ~21 sandstone 1 
setblock ~66 ~9 ~30 cobblestone_wall 14 
setblock ~66 ~9 ~60 cobblestone_wall 14  
fill ~66 ~9 ~69 ~71 ~9 ~69 sandstone 1  
fill ~66 ~9 ~70 ~67 ~9 ~70 cobblestone_wall 14 
setblock ~67 ~9 ~29 cobblestone_wall 14 
setblock ~67 ~9 ~61 cobblestone_wall 14 
setblock ~68 ~9 ~19 cobblestone_wall 14  
fill ~68 ~9 ~20 ~71 ~9 ~20 sandstone 1  
fill ~68 ~9 ~27 ~68 ~9 ~28 cobblestone_wall 14  
fill ~68 ~9 ~62 ~68 ~9 ~63 cobblestone_wall 14  
fill ~68 ~9 ~70 ~71 ~9 ~70 sandstone 1 
setblock ~68 ~9 ~71 cobblestone_wall 14  
fill ~69 ~9 ~18 ~70 ~9 ~18 cobblestone_wall 14  
fill ~69 ~9 ~19 ~72 ~9 ~19 sandstone 1  
fill ~69 ~9 ~25 ~69 ~9 ~26 cobblestone_wall 14  
fill ~69 ~9 ~64 ~69 ~9 ~65 cobblestone_wall 14  
fill ~69 ~9 ~71 ~72 ~9 ~71 sandstone 1  
fill ~69 ~9 ~72 ~70 ~9 ~72 cobblestone_wall 14  
fill ~70 ~9 ~23 ~70 ~9 ~24 cobblestone_wall 14  
fill ~70 ~9 ~66 ~70 ~9 ~67 cobblestone_wall 14 
setblock ~71 ~9 ~17 cobblestone_wall 14  
fill ~71 ~9 ~18 ~73 ~9 ~18 sandstone 1 
setblock ~71 ~9 ~22 cobblestone_wall 14 
setblock ~71 ~9 ~68 cobblestone_wall 14  
fill ~71 ~9 ~72 ~73 ~9 ~72 sandstone 1 
setblock ~71 ~9 ~73 cobblestone_wall 14  
fill ~72 ~9 ~16 ~73 ~9 ~16 cobblestone_wall 14  
fill ~72 ~9 ~17 ~73 ~9 ~17 sandstone 1  
fill ~72 ~9 ~20 ~72 ~9 ~21 cobblestone_wall 14  
fill ~72 ~9 ~69 ~72 ~9 ~70 cobblestone_wall 14  
fill ~72 ~9 ~73 ~73 ~9 ~73 sandstone 1  
fill ~72 ~9 ~74 ~73 ~9 ~74 cobblestone_wall 14 
setblock ~73 ~9 ~19 cobblestone_wall 14 
setblock ~73 ~9 ~71 cobblestone_wall 14 
setblock ~74 ~9 ~16 cobblestone_wall 13  
fill ~74 ~9 ~17 ~74 ~9 ~18 cobblestone_wall 14  
fill ~74 ~9 ~72 ~74 ~9 ~73 cobblestone_wall 14 
setblock ~74 ~9 ~74 cobblestone_wall 13 
setblock ~75 ~9 ~15 cobblestone_wall 13 
setblock ~75 ~9 ~75 cobblestone_wall 13 
setblock ~76 ~9 ~14 cobblestone_wall 13 
setblock ~76 ~9 ~76 cobblestone_wall 13 
setblock ~14 ~10 ~14 stone_slab 5 
setblock ~14 ~10 ~76 stone_slab 5 
setblock ~15 ~10 ~15 stone_slab 5 
setblock ~15 ~10 ~75 stone_slab 5 
setblock ~16 ~10 ~16 stone_slab 5 
setblock ~16 ~10 ~74 stone_slab 5 
setblock ~17 ~10 ~17 stone_slab 5 
setblock ~17 ~10 ~73 stone_slab 5 
setblock ~18 ~10 ~18 stone_slab 5 
setblock ~18 ~10 ~72 stone_slab 5 
setblock ~19 ~10 ~19 stone_slab 5 
setblock ~19 ~10 ~71 stone_slab 5  
fill ~20 ~10 ~20 ~21 ~10 ~20 stone_slab 5  
fill ~20 ~10 ~21 ~20 ~10 ~20 stone_slab 5  
fill ~20 ~10 ~69 ~20 ~10 ~70 stone_slab 5 
setblock ~21 ~10 ~21 planks 9 
setblock ~21 ~10 ~22 stone_slab 5 
setblock ~21 ~10 ~68 stone_slab 5 
setblock ~21 ~10 ~69 planks 9 
setblock ~21 ~10 ~70 stone_slab 5 
setblock ~22 ~10 ~21 stone_slab 5 
setblock ~22 ~10 ~22 planks 9 
setblock ~22 ~10 ~23 stone_slab 5 
setblock ~22 ~10 ~67 stone_slab 5 
setblock ~22 ~10 ~68 planks 9 
setblock ~22 ~10 ~69 stone_slab 5 
setblock ~23 ~10 ~22 stone_slab 5 
setblock ~23 ~10 ~23 planks 9 
setblock ~23 ~10 ~24 stone_slab 5 
setblock ~23 ~10 ~66 stone_slab 5 
setblock ~23 ~10 ~67 planks 9 
setblock ~23 ~10 ~68 stone_slab 5 
setblock ~24 ~10 ~23 stone_slab 5 
setblock ~24 ~10 ~24 planks 9 
setblock ~24 ~10 ~25 stone_slab 5 
setblock ~24 ~10 ~65 stone_slab 5 
setblock ~24 ~10 ~66 planks 9 
setblock ~24 ~10 ~67 stone_slab 5 
setblock ~25 ~10 ~24 stone_slab 5 
setblock ~25 ~10 ~25 planks 9 
setblock ~25 ~10 ~26 stone_slab 5 
setblock ~25 ~10 ~64 stone_slab 5 
setblock ~25 ~10 ~65 planks 9 
setblock ~25 ~10 ~66 stone_slab 5 
setblock ~26 ~10 ~25 stone_slab 5 
setblock ~26 ~10 ~26 planks 9 
setblock ~26 ~10 ~27 stone_slab 5 
setblock ~26 ~10 ~63 stone_slab 5 
setblock ~26 ~10 ~64 planks 9 
setblock ~26 ~10 ~65 stone_slab 5 
setblock ~27 ~10 ~26 stone_slab 5 
setblock ~27 ~10 ~27 planks 9 
setblock ~27 ~10 ~28 stone_slab 5 
setblock ~27 ~10 ~62 stone_slab 5 
setblock ~27 ~10 ~63 planks 9 
setblock ~27 ~10 ~64 stone_slab 5 
setblock ~28 ~10 ~27 stone_slab 5 
setblock ~28 ~10 ~28 planks 9 
setblock ~28 ~10 ~29 stone_slab 5 
setblock ~28 ~10 ~61 stone_slab 5 
setblock ~28 ~10 ~62 planks 9 
setblock ~28 ~10 ~63 stone_slab 5 
setblock ~29 ~10 ~28 stone_slab 5 
setblock ~29 ~10 ~29 planks 9 
setblock ~29 ~10 ~30 stone_slab 5 
setblock ~29 ~10 ~60 stone_slab 5 
setblock ~29 ~10 ~61 planks 9 
setblock ~29 ~10 ~62 stone_slab 5 
setblock ~30 ~10 ~29 stone_slab 5 
setblock ~30 ~10 ~30 planks 9 
setblock ~30 ~10 ~31 stone_slab 5 
setblock ~30 ~10 ~59 stone_slab 5 
setblock ~30 ~10 ~60 planks 9 
setblock ~30 ~10 ~61 stone_slab 5 
setblock ~31 ~10 ~30 stone_slab 5 
setblock ~31 ~10 ~31 planks 9 
setblock ~31 ~10 ~32 stone_slab 5 
setblock ~31 ~10 ~58 stone_slab 5 
setblock ~31 ~10 ~59 planks 9 
setblock ~31 ~10 ~60 stone_slab 5 
setblock ~32 ~10 ~31 stone_slab 5 
setblock ~32 ~10 ~32 planks 9 
setblock ~32 ~10 ~33 stone_slab 5  
fill ~32 ~10 ~42 ~58 ~10 ~42 iron_block 0  
fill ~32 ~10 ~43 ~58 ~10 ~43 iron_block 0  
fill ~32 ~10 ~44 ~58 ~10 ~44 iron_block 0  
fill ~32 ~10 ~45 ~44 ~10 ~45 iron_block 0  
fill ~32 ~10 ~46 ~58 ~10 ~46 iron_block 0  
fill ~32 ~10 ~47 ~58 ~10 ~47 iron_block 0  
fill ~32 ~10 ~48 ~58 ~10 ~48 iron_block 0 
setblock ~32 ~10 ~57 stone_slab 5 
setblock ~32 ~10 ~58 planks 9 
setblock ~32 ~10 ~59 stone_slab 5 
setblock ~33 ~10 ~32 stone_slab 5 
setblock ~33 ~10 ~33 stone_slab 13  
fill ~33 ~10 ~39 ~57 ~10 ~39 iron_block 0 
setblock ~33 ~10 ~40 beacon 0  
fill ~33 ~10 ~41 ~57 ~10 ~41 iron_block 0  
fill ~33 ~10 ~49 ~57 ~10 ~49 iron_block 0 
setblock ~33 ~10 ~50 beacon 0  
fill ~33 ~10 ~51 ~57 ~10 ~51 iron_block 0 
setblock ~33 ~10 ~57 stone_slab 13 
setblock ~33 ~10 ~58 stone_slab 5 
setblock ~34 ~10 ~34 stone_slab 13  
fill ~34 ~10 ~38 ~56 ~10 ~38 iron_block 0  
fill ~34 ~10 ~40 ~56 ~10 ~40 iron_block 0  
fill ~34 ~10 ~50 ~56 ~10 ~50 iron_block 0  
fill ~34 ~10 ~52 ~56 ~10 ~52 iron_block 0 
setblock ~34 ~10 ~56 stone_slab 13 
setblock ~35 ~10 ~35 stone_slab 13  
fill ~35 ~10 ~36 ~55 ~10 ~36 iron_block 0  
fill ~35 ~10 ~37 ~55 ~10 ~37 iron_block 0  
fill ~35 ~10 ~53 ~55 ~10 ~53 iron_block 0  
fill ~35 ~10 ~54 ~55 ~10 ~54 iron_block 0 
setblock ~35 ~10 ~55 stone_slab 13  
fill ~36 ~10 ~35 ~54 ~10 ~35 iron_block 0  
fill ~36 ~10 ~55 ~54 ~10 ~55 iron_block 0  
fill ~38 ~10 ~34 ~52 ~10 ~34 iron_block 0  
fill ~38 ~10 ~56 ~52 ~10 ~56 iron_block 0  
fill ~39 ~10 ~33 ~39 ~11 ~33 iron_block 0  
fill ~39 ~10 ~57 ~39 ~11 ~57 iron_block 0 
setblock ~40 ~10 ~33 beacon 0 
setblock ~40 ~10 ~57 beacon 0  
fill ~41 ~10 ~33 ~49 ~10 ~33 iron_block 0  
fill ~41 ~10 ~57 ~49 ~10 ~57 iron_block 0  
fill ~42 ~10 ~32 ~48 ~10 ~32 iron_block 0  
fill ~42 ~10 ~58 ~48 ~10 ~58 iron_block 0  
fill ~46 ~10 ~45 ~58 ~10 ~45 iron_block 0 
setblock ~50 ~10 ~33 beacon 0 
setblock ~50 ~10 ~57 beacon 0  
fill ~51 ~10 ~33 ~51 ~11 ~33 iron_block 0  
fill ~51 ~10 ~57 ~51 ~11 ~57 iron_block 0 
setblock ~55 ~10 ~35 stone_slab 13 
setblock ~55 ~10 ~55 stone_slab 13 
setblock ~56 ~10 ~34 stone_slab 13 
setblock ~56 ~10 ~56 stone_slab 13 
setblock ~57 ~10 ~32 stone_slab 5 
setblock ~57 ~10 ~33 stone_slab 13 
setblock ~57 ~10 ~40 beacon 0 
setblock ~57 ~10 ~50 beacon 0 
setblock ~57 ~10 ~57 stone_slab 13 
setblock ~57 ~10 ~58 stone_slab 5 
setblock ~58 ~10 ~31 stone_slab 5 
setblock ~58 ~10 ~32 planks 9 
setblock ~58 ~10 ~33 stone_slab 5 
setblock ~58 ~10 ~57 stone_slab 5 
setblock ~58 ~10 ~58 planks 9 
setblock ~58 ~10 ~59 stone_slab 5 
setblock ~59 ~10 ~30 stone_slab 5 
setblock ~59 ~10 ~31 planks 9 
setblock ~59 ~10 ~32 stone_slab 5 
setblock ~59 ~10 ~58 stone_slab 5 
setblock ~59 ~10 ~59 planks 9 
setblock ~59 ~10 ~60 stone_slab 5 
setblock ~60 ~10 ~29 stone_slab 5 
setblock ~60 ~10 ~30 planks 9 
setblock ~60 ~10 ~31 stone_slab 5 
setblock ~60 ~10 ~59 stone_slab 5 
setblock ~60 ~10 ~60 planks 9 
setblock ~60 ~10 ~61 stone_slab 5 
setblock ~61 ~10 ~28 stone_slab 5 
setblock ~61 ~10 ~29 planks 9 
setblock ~61 ~10 ~30 stone_slab 5 
setblock ~61 ~10 ~60 stone_slab 5 
setblock ~61 ~10 ~61 planks 9 
setblock ~61 ~10 ~62 stone_slab 5 
setblock ~62 ~10 ~27 stone_slab 5 
setblock ~62 ~10 ~28 planks 9 
setblock ~62 ~10 ~29 stone_slab 5 
setblock ~62 ~10 ~61 stone_slab 5 
setblock ~62 ~10 ~62 planks 9 
setblock ~62 ~10 ~63 stone_slab 5 
setblock ~63 ~10 ~26 stone_slab 5 
setblock ~63 ~10 ~27 planks 9 
setblock ~63 ~10 ~28 stone_slab 5 
setblock ~63 ~10 ~62 stone_slab 5 
setblock ~63 ~10 ~63 planks 9 
setblock ~63 ~10 ~64 stone_slab 5 
setblock ~64 ~10 ~25 stone_slab 5 
setblock ~64 ~10 ~26 planks 9 
setblock ~64 ~10 ~27 stone_slab 5 
setblock ~64 ~10 ~63 stone_slab 5 
setblock ~64 ~10 ~64 planks 9 
setblock ~64 ~10 ~65 stone_slab 5 
setblock ~65 ~10 ~24 stone_slab 5 
setblock ~65 ~10 ~25 planks 9 
setblock ~65 ~10 ~26 stone_slab 5 
setblock ~65 ~10 ~64 stone_slab 5 
setblock ~65 ~10 ~65 planks 9 
setblock ~65 ~10 ~66 stone_slab 5 
setblock ~66 ~10 ~23 stone_slab 5 
setblock ~66 ~10 ~24 planks 9 
setblock ~66 ~10 ~25 stone_slab 5 
setblock ~66 ~10 ~65 stone_slab 5 
setblock ~66 ~10 ~66 planks 9 
setblock ~66 ~10 ~67 stone_slab 5 
setblock ~67 ~10 ~22 stone_slab 5 
setblock ~67 ~10 ~23 planks 9 
setblock ~67 ~10 ~24 stone_slab 5 
setblock ~67 ~10 ~66 stone_slab 5 
setblock ~67 ~10 ~67 planks 9 
setblock ~67 ~10 ~68 stone_slab 5 
setblock ~68 ~10 ~21 stone_slab 5 
setblock ~68 ~10 ~22 planks 9 
setblock ~68 ~10 ~23 stone_slab 5 
setblock ~68 ~10 ~67 stone_slab 5 
setblock ~68 ~10 ~68 planks 9 
setblock ~68 ~10 ~69 stone_slab 5  
fill ~69 ~10 ~20 ~70 ~10 ~20 stone_slab 5 
setblock ~69 ~10 ~21 planks 9 
setblock ~69 ~10 ~22 stone_slab 5 
setblock ~69 ~10 ~68 stone_slab 5 
setblock ~69 ~10 ~69 planks 9  
fill ~69 ~10 ~70 ~70 ~10 ~70 stone_slab 5 
setblock ~70 ~10 ~21 stone_slab 5 
setblock ~70 ~10 ~69 stone_slab 5 
setblock ~71 ~10 ~19 stone_slab 5 
setblock ~71 ~10 ~71 stone_slab 5 
setblock ~72 ~10 ~18 stone_slab 5 
setblock ~72 ~10 ~72 stone_slab 5 
setblock ~73 ~10 ~17 stone_slab 5 
setblock ~73 ~10 ~73 stone_slab 5 
setblock ~74 ~10 ~16 stone_slab 5 
setblock ~74 ~10 ~74 stone_slab 5 
setblock ~75 ~10 ~15 stone_slab 5 
setblock ~75 ~10 ~75 stone_slab 5 
setblock ~76 ~10 ~14 stone_slab 5 
setblock ~76 ~10 ~76 stone_slab 5  
fill ~32 ~11 ~42 ~58 ~11 ~42 iron_block 0  
fill ~32 ~11 ~43 ~58 ~11 ~43 iron_block 0  
fill ~32 ~11 ~44 ~58 ~11 ~44 iron_block 0  
fill ~32 ~11 ~45 ~44 ~11 ~45 iron_block 0  
fill ~32 ~11 ~46 ~58 ~11 ~46 iron_block 0  
fill ~32 ~11 ~47 ~58 ~11 ~47 iron_block 0  
fill ~32 ~11 ~48 ~58 ~11 ~48 iron_block 0  
fill ~33 ~11 ~39 ~57 ~11 ~39 iron_block 0  
fill ~33 ~11 ~40 ~57 ~11 ~40 iron_block 0  
fill ~33 ~11 ~41 ~57 ~11 ~41 iron_block 0  
fill ~33 ~11 ~49 ~57 ~11 ~49 iron_block 0  
fill ~33 ~11 ~50 ~57 ~11 ~50 iron_block 0  
fill ~33 ~11 ~51 ~57 ~11 ~51 iron_block 0  
fill ~34 ~11 ~38 ~56 ~11 ~38 iron_block 0  
fill ~34 ~11 ~52 ~56 ~11 ~52 iron_block 0  
fill ~35 ~11 ~36 ~55 ~11 ~36 iron_block 0  
fill ~35 ~11 ~37 ~55 ~11 ~37 iron_block 0  
fill ~35 ~11 ~53 ~55 ~11 ~53 iron_block 0  
fill ~35 ~11 ~54 ~55 ~11 ~54 iron_block 0  
fill ~36 ~11 ~35 ~54 ~11 ~35 iron_block 0  
fill ~36 ~11 ~55 ~54 ~11 ~55 iron_block 0  
fill ~38 ~11 ~34 ~52 ~11 ~34 iron_block 0  
fill ~38 ~11 ~56 ~52 ~11 ~56 iron_block 0  
fill ~40 ~11 ~33 ~51 ~11 ~33 iron_block 0  
fill ~40 ~11 ~57 ~51 ~11 ~57 iron_block 0  
fill ~42 ~11 ~32 ~48 ~11 ~32 iron_block 0  
fill ~42 ~11 ~58 ~48 ~11 ~58 iron_block 0  
fill ~46 ~11 ~45 ~58 ~11 ~45 iron_block 0  
fill ~32 ~12 ~42 ~33 ~12 ~42 cobblestone_wall 3  
fill ~32 ~12 ~43 ~32 ~13 ~43 cobblestone_wall 3  
fill ~32 ~12 ~44 ~32 ~13 ~44 cobblestone_wall 3  
fill ~32 ~12 ~45 ~32 ~13 ~45 cobblestone_wall 3  
fill ~32 ~12 ~46 ~32 ~13 ~46 cobblestone_wall 3  
fill ~32 ~12 ~47 ~32 ~13 ~47 cobblestone_wall 3  
fill ~32 ~12 ~48 ~33 ~12 ~48 cobblestone_wall 3  
fill ~33 ~12 ~39 ~34 ~12 ~39 cobblestone_wall 3  
fill ~33 ~12 ~40 ~33 ~13 ~40 cobblestone_wall 3  
fill ~33 ~12 ~41 ~33 ~13 ~41 cobblestone_wall 3  
fill ~33 ~12 ~43 ~57 ~12 ~43 iron_block 0  
fill ~33 ~12 ~44 ~57 ~12 ~44 iron_block 0  
fill ~33 ~12 ~45 ~44 ~12 ~45 iron_block 0  
fill ~33 ~12 ~46 ~57 ~12 ~46 iron_block 0  
fill ~33 ~12 ~47 ~57 ~12 ~47 iron_block 0  
fill ~33 ~12 ~49 ~33 ~13 ~49 cobblestone_wall 3  
fill ~33 ~12 ~50 ~33 ~13 ~50 cobblestone_wall 3  
fill ~33 ~12 ~51 ~34 ~12 ~51 cobblestone_wall 3  
fill ~34 ~12 ~38 ~35 ~12 ~38 cobblestone_wall 3  
fill ~34 ~12 ~40 ~56 ~12 ~40 iron_block 0  
fill ~34 ~12 ~41 ~56 ~12 ~41 iron_block 0  
fill ~34 ~12 ~42 ~56 ~12 ~42 iron_block 0  
fill ~34 ~12 ~48 ~56 ~12 ~48 iron_block 0  
fill ~34 ~12 ~49 ~56 ~12 ~49 iron_block 0  
fill ~34 ~12 ~50 ~56 ~12 ~50 iron_block 0  
fill ~34 ~12 ~52 ~35 ~12 ~52 cobblestone_wall 3  
fill ~35 ~12 ~36 ~36 ~12 ~36 cobblestone_wall 3  
fill ~35 ~12 ~37 ~35 ~13 ~37 cobblestone_wall 3  
fill ~35 ~12 ~39 ~55 ~12 ~39 iron_block 0  
fill ~35 ~12 ~51 ~55 ~12 ~51 iron_block 0  
fill ~35 ~12 ~53 ~35 ~13 ~53 cobblestone_wall 3  
fill ~35 ~12 ~54 ~36 ~12 ~54 cobblestone_wall 3  
fill ~36 ~12 ~35 ~38 ~12 ~35 cobblestone_wall 3  
fill ~36 ~12 ~37 ~54 ~12 ~37 iron_block 0  
fill ~36 ~12 ~38 ~54 ~12 ~38 iron_block 0  
fill ~36 ~12 ~52 ~54 ~12 ~52 iron_block 0  
fill ~36 ~12 ~53 ~54 ~12 ~53 iron_block 0  
fill ~36 ~12 ~55 ~38 ~12 ~55 cobblestone_wall 3  
fill ~37 ~12 ~36 ~53 ~12 ~36 iron_block 0  
fill ~37 ~12 ~54 ~53 ~12 ~54 iron_block 0  
fill ~38 ~12 ~34 ~39 ~12 ~34 cobblestone_wall 3  
fill ~38 ~12 ~56 ~39 ~12 ~56 cobblestone_wall 3  
fill ~39 ~12 ~33 ~42 ~12 ~33 cobblestone_wall 3  
fill ~39 ~12 ~35 ~51 ~12 ~35 iron_block 0  
fill ~39 ~12 ~55 ~51 ~12 ~55 iron_block 0  
fill ~39 ~12 ~57 ~42 ~12 ~57 cobblestone_wall 3  
fill ~40 ~12 ~34 ~50 ~12 ~34 iron_block 0  
fill ~40 ~12 ~56 ~50 ~12 ~56 iron_block 0  
fill ~42 ~12 ~32 ~48 ~12 ~32 cobblestone_wall 3  
fill ~42 ~12 ~58 ~48 ~12 ~58 cobblestone_wall 3  
fill ~43 ~12 ~33 ~47 ~12 ~33 iron_block 0  
fill ~43 ~12 ~57 ~47 ~12 ~57 iron_block 0  
fill ~46 ~12 ~45 ~57 ~12 ~45 iron_block 0  
fill ~48 ~12 ~33 ~51 ~12 ~33 cobblestone_wall 3  
fill ~48 ~12 ~57 ~51 ~12 ~57 cobblestone_wall 3  
fill ~51 ~12 ~34 ~52 ~12 ~34 cobblestone_wall 3  
fill ~51 ~12 ~56 ~52 ~12 ~56 cobblestone_wall 3  
fill ~52 ~12 ~35 ~54 ~12 ~35 cobblestone_wall 3  
fill ~52 ~12 ~55 ~54 ~12 ~55 cobblestone_wall 3  
fill ~54 ~12 ~36 ~55 ~12 ~36 cobblestone_wall 3  
fill ~54 ~12 ~54 ~55 ~12 ~54 cobblestone_wall 3  
fill ~55 ~12 ~37 ~55 ~13 ~37 cobblestone_wall 3  
fill ~55 ~12 ~38 ~56 ~12 ~38 cobblestone_wall 3  
fill ~55 ~12 ~52 ~56 ~12 ~52 cobblestone_wall 3  
fill ~55 ~12 ~53 ~55 ~13 ~53 cobblestone_wall 3  
fill ~56 ~12 ~39 ~57 ~12 ~39 cobblestone_wall 3  
fill ~56 ~12 ~51 ~57 ~12 ~51 cobblestone_wall 3  
fill ~57 ~12 ~40 ~57 ~13 ~40 cobblestone_wall 3  
fill ~57 ~12 ~41 ~57 ~13 ~41 cobblestone_wall 3  
fill ~57 ~12 ~42 ~58 ~12 ~42 cobblestone_wall 3  
fill ~57 ~12 ~48 ~58 ~12 ~48 cobblestone_wall 3  
fill ~57 ~12 ~49 ~57 ~13 ~49 cobblestone_wall 3  
fill ~57 ~12 ~50 ~57 ~13 ~50 cobblestone_wall 3  
fill ~58 ~12 ~43 ~58 ~13 ~43 cobblestone_wall 3  
fill ~58 ~12 ~44 ~58 ~13 ~44 cobblestone_wall 3  
fill ~58 ~12 ~45 ~58 ~13 ~45 cobblestone_wall 3  
fill ~58 ~12 ~46 ~58 ~13 ~46 cobblestone_wall 3  
fill ~58 ~12 ~47 ~58 ~13 ~47 cobblestone_wall 3  
fill ~32 ~13 ~42 ~33 ~13 ~42 cobblestone_wall 3  
fill ~32 ~13 ~48 ~33 ~13 ~48 cobblestone_wall 3  
fill ~33 ~13 ~39 ~34 ~13 ~39 cobblestone_wall 3  
fill ~33 ~13 ~43 ~57 ~13 ~43 iron_block 0  
fill ~33 ~13 ~44 ~57 ~13 ~44 iron_block 0  
fill ~33 ~13 ~45 ~44 ~13 ~45 iron_block 0  
fill ~33 ~13 ~46 ~57 ~13 ~46 iron_block 0  
fill ~33 ~13 ~47 ~57 ~13 ~47 iron_block 0  
fill ~33 ~13 ~51 ~34 ~13 ~51 cobblestone_wall 3  
fill ~34 ~13 ~38 ~35 ~13 ~38 cobblestone_wall 3  
fill ~34 ~13 ~40 ~56 ~13 ~40 iron_block 0  
fill ~34 ~13 ~41 ~56 ~13 ~41 iron_block 0  
fill ~34 ~13 ~42 ~56 ~13 ~42 iron_block 0  
fill ~34 ~13 ~48 ~56 ~13 ~48 iron_block 0  
fill ~34 ~13 ~49 ~56 ~13 ~49 iron_block 0  
fill ~34 ~13 ~50 ~56 ~13 ~50 iron_block 0  
fill ~34 ~13 ~52 ~35 ~13 ~52 cobblestone_wall 3  
fill ~35 ~13 ~36 ~36 ~13 ~36 cobblestone_wall 3  
fill ~35 ~13 ~39 ~55 ~13 ~39 iron_block 0  
fill ~35 ~13 ~51 ~55 ~13 ~51 iron_block 0  
fill ~35 ~13 ~54 ~36 ~13 ~54 cobblestone_wall 3  
fill ~36 ~13 ~35 ~38 ~13 ~35 cobblestone_wall 3  
fill ~36 ~13 ~37 ~54 ~13 ~37 iron_block 0  
fill ~36 ~13 ~38 ~54 ~13 ~38 iron_block 0  
fill ~36 ~13 ~52 ~54 ~13 ~52 iron_block 0  
fill ~36 ~13 ~53 ~54 ~13 ~53 iron_block 0  
fill ~36 ~13 ~55 ~38 ~13 ~55 cobblestone_wall 3  
fill ~37 ~13 ~36 ~53 ~13 ~36 iron_block 0  
fill ~37 ~13 ~54 ~53 ~13 ~54 iron_block 0  
fill ~38 ~13 ~34 ~39 ~13 ~34 cobblestone_wall 3  
fill ~38 ~13 ~56 ~39 ~13 ~56 cobblestone_wall 3  
fill ~39 ~13 ~33 ~42 ~13 ~33 cobblestone_wall 3  
fill ~39 ~13 ~35 ~51 ~13 ~35 iron_block 0  
fill ~39 ~13 ~55 ~51 ~13 ~55 iron_block 0  
fill ~39 ~13 ~57 ~42 ~13 ~57 cobblestone_wall 3  
fill ~40 ~13 ~34 ~50 ~13 ~34 iron_block 0  
fill ~40 ~13 ~56 ~50 ~13 ~56 iron_block 0  
fill ~42 ~13 ~32 ~48 ~13 ~32 cobblestone_wall 3  
fill ~42 ~13 ~58 ~48 ~13 ~58 cobblestone_wall 3  
fill ~43 ~13 ~33 ~47 ~13 ~33 iron_block 0  
fill ~43 ~13 ~57 ~47 ~13 ~57 iron_block 0  
fill ~46 ~13 ~45 ~57 ~13 ~45 iron_block 0  
fill ~48 ~13 ~33 ~51 ~13 ~33 cobblestone_wall 3  
fill ~48 ~13 ~57 ~51 ~13 ~57 cobblestone_wall 3  
fill ~51 ~13 ~34 ~52 ~13 ~34 cobblestone_wall 3  
fill ~51 ~13 ~56 ~52 ~13 ~56 cobblestone_wall 3  
fill ~52 ~13 ~35 ~54 ~13 ~35 cobblestone_wall 3  
fill ~52 ~13 ~55 ~54 ~13 ~55 cobblestone_wall 3  
fill ~54 ~13 ~36 ~55 ~13 ~36 cobblestone_wall 3  
fill ~54 ~13 ~54 ~55 ~13 ~54 cobblestone_wall 3  
fill ~55 ~13 ~38 ~56 ~13 ~38 cobblestone_wall 3  
fill ~55 ~13 ~52 ~56 ~13 ~52 cobblestone_wall 3  
fill ~56 ~13 ~39 ~57 ~13 ~39 cobblestone_wall 3  
fill ~56 ~13 ~51 ~57 ~13 ~51 cobblestone_wall 3  
fill ~57 ~13 ~42 ~58 ~13 ~42 cobblestone_wall 3  
fill ~57 ~13 ~48 ~58 ~13 ~48 cobblestone_wall 3  
fill ~1 ~14 ~45 ~8 ~14 ~45 stone_slab 13  
fill ~9 ~14 ~44 ~31 ~14 ~44 stone_slab 13  
fill ~9 ~14 ~45 ~31 ~14 ~45 sandstone 2  
fill ~9 ~14 ~46 ~31 ~14 ~46 stone_slab 13  
fill ~32 ~14 ~42 ~58 ~14 ~42 iron_block 0  
fill ~32 ~14 ~43 ~58 ~14 ~43 iron_block 0  
fill ~32 ~14 ~44 ~58 ~14 ~44 iron_block 0  
fill ~32 ~14 ~45 ~44 ~14 ~45 iron_block 0  
fill ~32 ~14 ~46 ~58 ~14 ~46 iron_block 0  
fill ~32 ~14 ~47 ~58 ~14 ~47 iron_block 0  
fill ~32 ~14 ~48 ~58 ~14 ~48 iron_block 0  
fill ~33 ~14 ~39 ~57 ~14 ~39 iron_block 0  
fill ~33 ~14 ~40 ~57 ~14 ~40 iron_block 0  
fill ~33 ~14 ~41 ~57 ~14 ~41 iron_block 0  
fill ~33 ~14 ~49 ~57 ~14 ~49 iron_block 0  
fill ~33 ~14 ~50 ~57 ~14 ~50 iron_block 0  
fill ~33 ~14 ~51 ~57 ~14 ~51 iron_block 0  
fill ~34 ~14 ~38 ~56 ~14 ~38 iron_block 0  
fill ~34 ~14 ~52 ~56 ~14 ~52 iron_block 0  
fill ~35 ~14 ~36 ~55 ~14 ~36 iron_block 0  
fill ~35 ~14 ~37 ~55 ~14 ~37 iron_block 0  
fill ~35 ~14 ~53 ~55 ~14 ~53 iron_block 0  
fill ~35 ~14 ~54 ~55 ~14 ~54 iron_block 0  
fill ~36 ~14 ~35 ~54 ~14 ~35 iron_block 0  
fill ~36 ~14 ~55 ~54 ~14 ~55 iron_block 0  
fill ~38 ~14 ~34 ~52 ~14 ~34 iron_block 0  
fill ~38 ~14 ~56 ~52 ~14 ~56 iron_block 0  
fill ~39 ~14 ~33 ~51 ~14 ~33 iron_block 0  
fill ~39 ~14 ~57 ~51 ~14 ~57 iron_block 0  
fill ~42 ~14 ~32 ~48 ~14 ~32 iron_block 0  
fill ~42 ~14 ~58 ~48 ~14 ~58 iron_block 0  
fill ~44 ~14 ~9 ~44 ~14 ~31 stone_slab 13  
fill ~44 ~14 ~59 ~44 ~14 ~81 stone_slab 13  
fill ~45 ~14 ~1 ~45 ~14 ~8 stone_slab 13  
fill ~45 ~14 ~9 ~45 ~14 ~31 sandstone 2  
fill ~45 ~14 ~59 ~45 ~14 ~81 sandstone 2  
fill ~45 ~14 ~82 ~45 ~14 ~89 stone_slab 13  
fill ~46 ~14 ~9 ~46 ~14 ~31 stone_slab 13  
fill ~46 ~14 ~45 ~58 ~14 ~45 iron_block 0  
fill ~46 ~14 ~59 ~46 ~14 ~81 stone_slab 13  
fill ~59 ~14 ~44 ~81 ~14 ~44 stone_slab 13  
fill ~59 ~14 ~45 ~81 ~14 ~45 sandstone 2  
fill ~59 ~14 ~46 ~81 ~14 ~46 stone_slab 13  
fill ~82 ~14 ~45 ~89 ~14 ~45 stone_slab 13  
fill ~1 ~15 ~45 ~3 ~15 ~45 cobblestone_wall 13 
setblock ~3 ~15 ~44 cobblestone_wall 14 
setblock ~3 ~15 ~46 cobblestone_wall 14  
fill ~4 ~15 ~43 ~7 ~15 ~43 cobblestone_wall 14  
fill ~4 ~15 ~44 ~31 ~15 ~44 sandstone 1  
fill ~4 ~15 ~45 ~31 ~15 ~45 sandstone 1  
fill ~4 ~15 ~46 ~31 ~15 ~46 sandstone 1  
fill ~4 ~15 ~47 ~7 ~15 ~47 cobblestone_wall 14  
fill ~8 ~15 ~42 ~12 ~15 ~42 cobblestone_wall 14  
fill ~8 ~15 ~43 ~29 ~15 ~43 sandstone 1  
fill ~8 ~15 ~47 ~29 ~15 ~47 sandstone 1  
fill ~8 ~15 ~48 ~12 ~15 ~48 cobblestone_wall 14  
fill ~13 ~15 ~41 ~16 ~15 ~41 cobblestone_wall 14  
fill ~13 ~15 ~42 ~27 ~15 ~42 sandstone 1  
fill ~13 ~15 ~48 ~27 ~15 ~48 sandstone 1  
fill ~13 ~15 ~49 ~16 ~15 ~49 cobblestone_wall 14  
fill ~17 ~15 ~40 ~24 ~15 ~40 cobblestone_wall 14  
fill ~17 ~15 ~41 ~24 ~15 ~41 sandstone 1  
fill ~17 ~15 ~49 ~24 ~15 ~49 sandstone 1  
fill ~17 ~15 ~50 ~24 ~15 ~50 cobblestone_wall 14  
fill ~25 ~15 ~41 ~27 ~15 ~41 cobblestone_wall 14  
fill ~25 ~15 ~49 ~27 ~15 ~49 cobblestone_wall 14  
fill ~28 ~15 ~42 ~29 ~15 ~42 cobblestone_wall 14  
fill ~28 ~15 ~48 ~29 ~15 ~48 cobblestone_wall 14  
fill ~30 ~15 ~43 ~31 ~15 ~43 cobblestone_wall 14  
fill ~30 ~15 ~47 ~31 ~15 ~47 cobblestone_wall 14  
fill ~32 ~15 ~42 ~58 ~15 ~42 iron_block 0  
fill ~32 ~15 ~43 ~58 ~15 ~43 iron_block 0  
fill ~32 ~15 ~44 ~58 ~15 ~44 iron_block 0  
fill ~32 ~15 ~45 ~44 ~15 ~45 iron_block 0  
fill ~32 ~15 ~46 ~58 ~15 ~46 iron_block 0  
fill ~32 ~15 ~47 ~58 ~15 ~47 iron_block 0  
fill ~32 ~15 ~48 ~58 ~15 ~48 iron_block 0  
fill ~33 ~15 ~39 ~57 ~15 ~39 iron_block 0 
setblock ~33 ~15 ~40 beacon 0  
fill ~33 ~15 ~41 ~57 ~15 ~41 iron_block 0  
fill ~33 ~15 ~49 ~57 ~15 ~49 iron_block 0 
setblock ~33 ~15 ~50 beacon 0  
fill ~33 ~15 ~51 ~57 ~15 ~51 iron_block 0  
fill ~34 ~15 ~38 ~56 ~15 ~38 iron_block 0  
fill ~34 ~15 ~40 ~56 ~15 ~40 iron_block 0  
fill ~34 ~15 ~50 ~56 ~15 ~50 iron_block 0  
fill ~34 ~15 ~52 ~56 ~15 ~52 iron_block 0  
fill ~35 ~15 ~36 ~55 ~15 ~36 iron_block 0  
fill ~35 ~15 ~37 ~55 ~15 ~37 iron_block 0  
fill ~35 ~15 ~53 ~55 ~15 ~53 iron_block 0  
fill ~35 ~15 ~54 ~55 ~15 ~54 iron_block 0  
fill ~36 ~15 ~35 ~54 ~15 ~35 iron_block 0  
fill ~36 ~15 ~55 ~54 ~15 ~55 iron_block 0  
fill ~38 ~15 ~34 ~52 ~15 ~34 iron_block 0  
fill ~38 ~15 ~56 ~52 ~15 ~56 iron_block 0  
fill ~39 ~15 ~33 ~39 ~16 ~33 iron_block 0  
fill ~39 ~15 ~57 ~39 ~16 ~57 iron_block 0  
fill ~40 ~15 ~17 ~40 ~15 ~24 cobblestone_wall 14 
setblock ~40 ~15 ~33 beacon 0 
setblock ~40 ~15 ~57 beacon 0  
fill ~40 ~15 ~66 ~40 ~15 ~73 cobblestone_wall 14  
fill ~41 ~15 ~13 ~41 ~15 ~16 cobblestone_wall 14  
fill ~41 ~15 ~17 ~49 ~15 ~17 sandstone 1  
fill ~41 ~15 ~18 ~49 ~15 ~18 sandstone 1  
fill ~41 ~15 ~19 ~49 ~15 ~19 sandstone 1  
fill ~41 ~15 ~20 ~49 ~15 ~20 sandstone 1  
fill ~41 ~15 ~21 ~49 ~15 ~21 sandstone 1  
fill ~41 ~15 ~22 ~49 ~15 ~22 sandstone 1  
fill ~41 ~15 ~23 ~49 ~15 ~23 sandstone 1  
fill ~41 ~15 ~24 ~49 ~15 ~24 sandstone 1  
fill ~41 ~15 ~25 ~41 ~15 ~27 cobblestone_wall 14  
fill ~41 ~15 ~33 ~49 ~15 ~33 iron_block 0  
fill ~41 ~15 ~57 ~49 ~15 ~57 iron_block 0  
fill ~41 ~15 ~63 ~41 ~15 ~65 cobblestone_wall 14  
fill ~41 ~15 ~66 ~49 ~15 ~66 sandstone 1  
fill ~41 ~15 ~67 ~49 ~15 ~67 sandstone 1  
fill ~41 ~15 ~68 ~49 ~15 ~68 sandstone 1  
fill ~41 ~15 ~69 ~49 ~15 ~69 sandstone 1  
fill ~41 ~15 ~70 ~49 ~15 ~70 sandstone 1  
fill ~41 ~15 ~71 ~49 ~15 ~71 sandstone 1  
fill ~41 ~15 ~72 ~49 ~15 ~72 sandstone 1  
fill ~41 ~15 ~73 ~49 ~15 ~73 sandstone 1  
fill ~41 ~15 ~74 ~41 ~15 ~77 cobblestone_wall 14  
fill ~42 ~15 ~8 ~42 ~15 ~12 cobblestone_wall 14  
fill ~42 ~15 ~13 ~48 ~15 ~13 sandstone 1  
fill ~42 ~15 ~14 ~48 ~15 ~14 sandstone 1  
fill ~42 ~15 ~15 ~48 ~15 ~15 sandstone 1  
fill ~42 ~15 ~16 ~48 ~15 ~16 sandstone 1  
fill ~42 ~15 ~25 ~48 ~15 ~25 sandstone 1  
fill ~42 ~15 ~26 ~48 ~15 ~26 sandstone 1  
fill ~42 ~15 ~27 ~48 ~15 ~27 sandstone 1  
fill ~42 ~15 ~28 ~42 ~15 ~29 cobblestone_wall 14  
fill ~42 ~15 ~32 ~48 ~15 ~32 iron_block 0  
fill ~42 ~15 ~58 ~48 ~15 ~58 iron_block 0  
fill ~42 ~15 ~61 ~42 ~15 ~62 cobblestone_wall 14  
fill ~42 ~15 ~63 ~48 ~15 ~63 sandstone 1  
fill ~42 ~15 ~64 ~48 ~15 ~64 sandstone 1  
fill ~42 ~15 ~65 ~48 ~15 ~65 sandstone 1  
fill ~42 ~15 ~74 ~48 ~15 ~74 sandstone 1  
fill ~42 ~15 ~75 ~48 ~15 ~75 sandstone 1  
fill ~42 ~15 ~76 ~48 ~15 ~76 sandstone 1  
fill ~42 ~15 ~77 ~48 ~15 ~77 sandstone 1  
fill ~42 ~15 ~78 ~42 ~15 ~82 cobblestone_wall 14  
fill ~43 ~15 ~4 ~43 ~15 ~7 cobblestone_wall 14  
fill ~43 ~15 ~8 ~47 ~15 ~8 sandstone 1  
fill ~43 ~15 ~9 ~47 ~15 ~9 sandstone 1  
fill ~43 ~15 ~10 ~47 ~15 ~10 sandstone 1  
fill ~43 ~15 ~11 ~47 ~15 ~11 sandstone 1  
fill ~43 ~15 ~12 ~47 ~15 ~12 sandstone 1  
fill ~43 ~15 ~28 ~47 ~15 ~28 sandstone 1  
fill ~43 ~15 ~29 ~47 ~15 ~29 sandstone 1  
fill ~43 ~15 ~30 ~43 ~15 ~31 cobblestone_wall 14  
fill ~43 ~15 ~59 ~43 ~15 ~60 cobblestone_wall 14  
fill ~43 ~15 ~61 ~47 ~15 ~61 sandstone 1  
fill ~43 ~15 ~62 ~47 ~15 ~62 sandstone 1  
fill ~43 ~15 ~78 ~47 ~15 ~78 sandstone 1  
fill ~43 ~15 ~79 ~47 ~15 ~79 sandstone 1  
fill ~43 ~15 ~80 ~47 ~15 ~80 sandstone 1  
fill ~43 ~15 ~81 ~47 ~15 ~81 sandstone 1  
fill ~43 ~15 ~82 ~47 ~15 ~82 sandstone 1  
fill ~43 ~15 ~83 ~43 ~15 ~86 cobblestone_wall 14 
setblock ~44 ~15 ~3 cobblestone_wall 14  
fill ~44 ~15 ~4 ~46 ~15 ~4 sandstone 1  
fill ~44 ~15 ~5 ~46 ~15 ~5 sandstone 1  
fill ~44 ~15 ~6 ~46 ~15 ~6 sandstone 1  
fill ~44 ~15 ~7 ~46 ~15 ~7 sandstone 1  
fill ~44 ~15 ~30 ~46 ~15 ~30 sandstone 1  
fill ~44 ~15 ~31 ~46 ~15 ~31 sandstone 1  
fill ~44 ~15 ~59 ~46 ~15 ~59 sandstone 1  
fill ~44 ~15 ~60 ~46 ~15 ~60 sandstone 1  
fill ~44 ~15 ~83 ~46 ~15 ~83 sandstone 1  
fill ~44 ~15 ~84 ~46 ~15 ~84 sandstone 1  
fill ~44 ~15 ~85 ~46 ~15 ~85 sandstone 1  
fill ~44 ~15 ~86 ~46 ~15 ~86 sandstone 1 
setblock ~44 ~15 ~87 cobblestone_wall 14  
fill ~45 ~15 ~1 ~45 ~15 ~3 cobblestone_wall 13  
fill ~45 ~15 ~87 ~45 ~15 ~89 cobblestone_wall 13 
setblock ~46 ~15 ~3 cobblestone_wall 14  
fill ~46 ~15 ~45 ~58 ~15 ~45 iron_block 0 
setblock ~46 ~15 ~87 cobblestone_wall 14  
fill ~47 ~15 ~4 ~47 ~15 ~7 cobblestone_wall 14  
fill ~47 ~15 ~30 ~47 ~15 ~31 cobblestone_wall 14  
fill ~47 ~15 ~59 ~47 ~15 ~60 cobblestone_wall 14  
fill ~47 ~15 ~83 ~47 ~15 ~86 cobblestone_wall 14  
fill ~48 ~15 ~8 ~48 ~15 ~12 cobblestone_wall 14  
fill ~48 ~15 ~28 ~48 ~15 ~29 cobblestone_wall 14  
fill ~48 ~15 ~61 ~48 ~15 ~62 cobblestone_wall 14  
fill ~48 ~15 ~78 ~48 ~15 ~82 cobblestone_wall 14  
fill ~49 ~15 ~13 ~49 ~15 ~16 cobblestone_wall 14  
fill ~49 ~15 ~25 ~49 ~15 ~27 cobblestone_wall 14  
fill ~49 ~15 ~63 ~49 ~15 ~65 cobblestone_wall 14  
fill ~49 ~15 ~74 ~49 ~15 ~77 cobblestone_wall 14  
fill ~50 ~15 ~17 ~50 ~15 ~24 cobblestone_wall 14 
setblock ~50 ~15 ~33 beacon 0 
setblock ~50 ~15 ~57 beacon 0  
fill ~50 ~15 ~66 ~50 ~15 ~73 cobblestone_wall 14  
fill ~51 ~15 ~33 ~51 ~16 ~33 iron_block 0  
fill ~51 ~15 ~57 ~51 ~16 ~57 iron_block 0 
setblock ~57 ~15 ~40 beacon 0 
setblock ~57 ~15 ~50 beacon 0  
fill ~59 ~15 ~43 ~60 ~15 ~43 cobblestone_wall 14  
fill ~59 ~15 ~44 ~86 ~15 ~44 sandstone 1  
fill ~59 ~15 ~45 ~86 ~15 ~45 sandstone 1  
fill ~59 ~15 ~46 ~86 ~15 ~46 sandstone 1  
fill ~59 ~15 ~47 ~60 ~15 ~47 cobblestone_wall 14  
fill ~61 ~15 ~42 ~62 ~15 ~42 cobblestone_wall 14  
fill ~61 ~15 ~43 ~82 ~15 ~43 sandstone 1  
fill ~61 ~15 ~47 ~82 ~15 ~47 sandstone 1  
fill ~61 ~15 ~48 ~62 ~15 ~48 cobblestone_wall 14  
fill ~63 ~15 ~41 ~65 ~15 ~41 cobblestone_wall 14  
fill ~63 ~15 ~42 ~77 ~15 ~42 sandstone 1  
fill ~63 ~15 ~48 ~77 ~15 ~48 sandstone 1  
fill ~63 ~15 ~49 ~65 ~15 ~49 cobblestone_wall 14  
fill ~66 ~15 ~40 ~73 ~15 ~40 cobblestone_wall 14  
fill ~66 ~15 ~41 ~73 ~15 ~41 sandstone 1  
fill ~66 ~15 ~49 ~73 ~15 ~49 sandstone 1  
fill ~66 ~15 ~50 ~73 ~15 ~50 cobblestone_wall 14  
fill ~74 ~15 ~41 ~77 ~15 ~41 cobblestone_wall 14  
fill ~74 ~15 ~49 ~77 ~15 ~49 cobblestone_wall 14  
fill ~78 ~15 ~42 ~82 ~15 ~42 cobblestone_wall 14  
fill ~78 ~15 ~48 ~82 ~15 ~48 cobblestone_wall 14  
fill ~83 ~15 ~43 ~86 ~15 ~43 cobblestone_wall 14  
fill ~83 ~15 ~47 ~86 ~15 ~47 cobblestone_wall 14 
setblock ~87 ~15 ~44 cobblestone_wall 14  
fill ~87 ~15 ~45 ~89 ~15 ~45 cobblestone_wall 13 
setblock ~87 ~15 ~46 cobblestone_wall 14  
fill ~1 ~16 ~45 ~8 ~16 ~45 stone_slab 5  
fill ~9 ~16 ~44 ~28 ~16 ~44 stone_slab 5  
fill ~9 ~16 ~45 ~27 ~16 ~45 planks 9  
fill ~9 ~16 ~46 ~28 ~16 ~46 stone_slab 5  
fill ~26 ~16 ~36 ~26 ~18 ~36 cobblestone_wall 3  
fill ~28 ~16 ~45 ~31 ~16 ~45 stone_slab 13  
fill ~30 ~16 ~63 ~30 ~17 ~63 cobblestone_wall 3  
fill ~32 ~16 ~42 ~58 ~16 ~42 iron_block 0  
fill ~32 ~16 ~43 ~58 ~16 ~43 iron_block 0  
fill ~32 ~16 ~44 ~58 ~16 ~44 iron_block 0  
fill ~32 ~16 ~45 ~44 ~16 ~45 iron_block 0  
fill ~32 ~16 ~46 ~58 ~16 ~46 iron_block 0  
fill ~32 ~16 ~47 ~58 ~16 ~47 iron_block 0  
fill ~32 ~16 ~48 ~58 ~16 ~48 iron_block 0  
fill ~33 ~16 ~39 ~57 ~16 ~39 iron_block 0  
fill ~33 ~16 ~40 ~57 ~16 ~40 iron_block 0  
fill ~33 ~16 ~41 ~57 ~16 ~41 iron_block 0  
fill ~33 ~16 ~49 ~57 ~16 ~49 iron_block 0  
fill ~33 ~16 ~50 ~57 ~16 ~50 iron_block 0  
fill ~33 ~16 ~51 ~57 ~16 ~51 iron_block 0  
fill ~34 ~16 ~38 ~56 ~16 ~38 iron_block 0  
fill ~34 ~16 ~52 ~56 ~16 ~52 iron_block 0  
fill ~35 ~16 ~36 ~55 ~16 ~36 iron_block 0  
fill ~35 ~16 ~37 ~55 ~16 ~37 iron_block 0  
fill ~35 ~16 ~53 ~55 ~16 ~53 iron_block 0  
fill ~35 ~16 ~54 ~55 ~16 ~54 iron_block 0  
fill ~36 ~16 ~35 ~54 ~16 ~35 iron_block 0  
fill ~36 ~16 ~55 ~54 ~16 ~55 iron_block 0  
fill ~38 ~16 ~34 ~52 ~16 ~34 iron_block 0  
fill ~38 ~16 ~56 ~52 ~16 ~56 iron_block 0  
fill ~40 ~16 ~33 ~51 ~16 ~33 iron_block 0  
fill ~40 ~16 ~57 ~51 ~16 ~57 iron_block 0  
fill ~42 ~16 ~32 ~48 ~16 ~32 iron_block 0  
fill ~42 ~16 ~58 ~48 ~16 ~58 iron_block 0  
fill ~44 ~16 ~9 ~44 ~16 ~28 stone_slab 5  
fill ~44 ~16 ~62 ~44 ~16 ~81 stone_slab 5  
fill ~45 ~16 ~1 ~45 ~16 ~8 stone_slab 5  
fill ~45 ~16 ~9 ~45 ~16 ~27 planks 9  
fill ~45 ~16 ~28 ~45 ~16 ~31 stone_slab 13  
fill ~45 ~16 ~59 ~45 ~16 ~62 stone_slab 13  
fill ~45 ~16 ~63 ~45 ~16 ~81 planks 9  
fill ~45 ~16 ~82 ~45 ~16 ~89 stone_slab 5  
fill ~46 ~16 ~9 ~46 ~16 ~28 stone_slab 5  
fill ~46 ~16 ~45 ~58 ~16 ~45 iron_block 0  
fill ~46 ~16 ~62 ~46 ~16 ~81 stone_slab 5  
fill ~59 ~16 ~45 ~62 ~16 ~45 stone_slab 13  
fill ~62 ~16 ~44 ~81 ~16 ~44 stone_slab 5  
fill ~62 ~16 ~46 ~81 ~16 ~46 stone_slab 5  
fill ~63 ~16 ~45 ~81 ~16 ~45 planks 9  
fill ~82 ~16 ~45 ~89 ~16 ~45 stone_slab 5  
fill ~16 ~17 ~40 ~17 ~17 ~40 cobblestone_wall 3  
fill ~18 ~17 ~40 ~19 ~17 ~40 iron_block 0 
setblock ~19 ~17 ~39 cobblestone_wall 2 
setblock ~19 ~17 ~41 cobblestone_wall 2 
setblock ~20 ~17 ~40 cobblestone_wall 3 
setblock ~21 ~17 ~39 cobblestone_wall 2 
setblock ~21 ~17 ~40 iron_block 0 
setblock ~21 ~17 ~41 cobblestone_wall 2 
setblock ~22 ~17 ~30 nether_brick_stairs 7 
setblock ~22 ~17 ~31 cobblestone_wall 2 
setblock ~22 ~17 ~32 nether_brick_stairs 6 
setblock ~22 ~17 ~33 stone_stairs 4 
setblock ~22 ~17 ~34 cobblestone_wall 6  
fill ~22 ~17 ~35 ~22 ~17 ~37 cobblestone 0 
setblock ~22 ~17 ~38 cobblestone_wall 6 
setblock ~22 ~17 ~39 stone_stairs 7 
setblock ~23 ~17 ~32 stone_stairs 0 
setblock ~23 ~17 ~33 cobblestone_wall 6 
setblock ~23 ~17 ~34 cobblestone 0  
fill ~23 ~17 ~36 ~25 ~17 ~36 cobblestone 0 
setblock ~23 ~17 ~38 cobblestone 0 
setblock ~23 ~17 ~39 cobblestone_wall 6 
setblock ~23 ~17 ~40 stone_stairs 0 
setblock ~24 ~17 ~32 cobblestone_wall 6 
setblock ~24 ~17 ~33 cobblestone 0 
setblock ~24 ~17 ~39 cobblestone 0 
setblock ~24 ~17 ~40 cobblestone_wall 6  
fill ~24 ~17 ~60 ~28 ~17 ~60 cobblestone_wall 3  
fill ~25 ~17 ~31 ~27 ~17 ~31 cobblestone_wall 6  
fill ~25 ~17 ~32 ~27 ~17 ~32 cobblestone 0  
fill ~25 ~17 ~40 ~27 ~17 ~40 cobblestone 0  
fill ~25 ~17 ~41 ~27 ~17 ~41 cobblestone_wall 6  
fill ~26 ~17 ~33 ~26 ~17 ~35 cobblestone 0  
fill ~26 ~17 ~37 ~26 ~17 ~40 cobblestone 0  
fill ~27 ~17 ~36 ~30 ~17 ~36 cobblestone 0  
fill ~27 ~17 ~61 ~27 ~17 ~63 cobblestone_wall 3 
setblock ~28 ~17 ~32 cobblestone_wall 6 
setblock ~28 ~17 ~33 cobblestone 0 
setblock ~28 ~17 ~39 cobblestone 0 
setblock ~28 ~17 ~40 cobblestone_wall 6  
fill ~28 ~17 ~63 ~31 ~17 ~63 cobblestone_wall 3 
setblock ~29 ~17 ~32 stone_stairs 5 
setblock ~29 ~17 ~33 cobblestone_wall 6 
setblock ~29 ~17 ~34 cobblestone 0 
setblock ~29 ~17 ~38 cobblestone 0 
setblock ~29 ~17 ~39 cobblestone_wall 6 
setblock ~29 ~17 ~40 stone_stairs 5 
setblock ~30 ~17 ~33 stone_stairs 2 
setblock ~30 ~17 ~34 cobblestone_wall 6 
setblock ~30 ~17 ~35 cobblestone 0 
setblock ~30 ~17 ~37 cobblestone 0 
setblock ~30 ~17 ~38 cobblestone_wall 6 
setblock ~30 ~17 ~39 stone_stairs 3  
fill ~31 ~17 ~35 ~31 ~17 ~37 cobblestone_wall 6  
fill ~32 ~17 ~42 ~33 ~17 ~42 cobblestone_wall 3  
fill ~32 ~17 ~43 ~32 ~17 ~48 cobblestone_wall 3  
fill ~33 ~17 ~39 ~34 ~17 ~39 cobblestone_wall 3  
fill ~33 ~17 ~40 ~33 ~17 ~42 cobblestone_wall 3  
fill ~33 ~17 ~43 ~57 ~17 ~43 iron_block 0  
fill ~33 ~17 ~44 ~57 ~17 ~44 iron_block 0  
fill ~33 ~17 ~45 ~44 ~17 ~45 iron_block 0  
fill ~33 ~17 ~46 ~57 ~17 ~46 iron_block 0  
fill ~33 ~17 ~47 ~57 ~17 ~47 iron_block 0  
fill ~33 ~17 ~48 ~33 ~17 ~51 cobblestone_wall 3  
fill ~34 ~17 ~38 ~35 ~17 ~38 cobblestone_wall 3  
fill ~34 ~17 ~40 ~56 ~17 ~40 iron_block 0  
fill ~34 ~17 ~41 ~56 ~17 ~41 iron_block 0  
fill ~34 ~17 ~42 ~56 ~17 ~42 iron_block 0  
fill ~34 ~17 ~48 ~56 ~17 ~48 iron_block 0  
fill ~34 ~17 ~49 ~56 ~17 ~49 iron_block 0  
fill ~34 ~17 ~50 ~56 ~17 ~50 iron_block 0  
fill ~34 ~17 ~51 ~34 ~17 ~52 cobblestone_wall 3  
fill ~35 ~17 ~36 ~36 ~17 ~36 cobblestone_wall 3  
fill ~35 ~17 ~37 ~35 ~17 ~36 cobblestone_wall 3  
fill ~35 ~17 ~39 ~55 ~17 ~39 iron_block 0  
fill ~35 ~17 ~51 ~55 ~17 ~51 iron_block 0  
fill ~35 ~17 ~52 ~35 ~17 ~54 cobblestone_wall 3  
fill ~36 ~17 ~35 ~38 ~17 ~35 cobblestone_wall 3  
fill ~36 ~17 ~37 ~54 ~17 ~37 iron_block 0  
fill ~36 ~17 ~38 ~54 ~17 ~38 iron_block 0  
fill ~36 ~17 ~52 ~54 ~17 ~52 iron_block 0  
fill ~36 ~17 ~53 ~54 ~17 ~53 iron_block 0  
fill ~36 ~17 ~54 ~36 ~17 ~55 cobblestone_wall 3  
fill ~37 ~17 ~36 ~53 ~17 ~36 iron_block 0  
fill ~37 ~17 ~54 ~53 ~17 ~54 iron_block 0  
fill ~37 ~17 ~55 ~38 ~17 ~55 cobblestone_wall 3  
fill ~38 ~17 ~34 ~39 ~17 ~34 cobblestone_wall 3  
fill ~38 ~17 ~56 ~39 ~17 ~56 cobblestone_wall 3  
fill ~39 ~17 ~33 ~42 ~17 ~33 cobblestone_wall 3  
fill ~39 ~17 ~35 ~51 ~17 ~35 iron_block 0  
fill ~39 ~17 ~55 ~51 ~17 ~55 iron_block 0  
fill ~39 ~17 ~57 ~42 ~17 ~57 cobblestone_wall 3  
fill ~40 ~17 ~34 ~50 ~17 ~34 iron_block 0  
fill ~40 ~17 ~56 ~50 ~17 ~56 iron_block 0  
fill ~42 ~17 ~32 ~48 ~17 ~32 cobblestone_wall 3  
fill ~42 ~17 ~58 ~48 ~17 ~58 cobblestone_wall 3  
fill ~43 ~17 ~33 ~47 ~17 ~33 iron_block 0  
fill ~43 ~17 ~57 ~47 ~17 ~57 iron_block 0  
fill ~46 ~17 ~45 ~57 ~17 ~45 iron_block 0  
fill ~48 ~17 ~33 ~51 ~17 ~33 cobblestone_wall 3  
fill ~48 ~17 ~57 ~51 ~17 ~57 cobblestone_wall 3  
fill ~51 ~17 ~34 ~52 ~17 ~34 cobblestone_wall 3  
fill ~51 ~17 ~56 ~52 ~17 ~56 cobblestone_wall 3  
fill ~52 ~17 ~35 ~54 ~17 ~35 cobblestone_wall 3  
fill ~52 ~17 ~55 ~54 ~17 ~55 cobblestone_wall 3  
fill ~54 ~17 ~36 ~55 ~17 ~36 cobblestone_wall 3  
fill ~54 ~17 ~54 ~55 ~17 ~54 cobblestone_wall 3  
fill ~55 ~17 ~37 ~55 ~17 ~38 cobblestone_wall 3  
fill ~55 ~17 ~52 ~56 ~17 ~52 cobblestone_wall 3  
fill ~55 ~17 ~53 ~55 ~17 ~52 cobblestone_wall 3  
fill ~56 ~17 ~38 ~56 ~17 ~39 cobblestone_wall 3  
fill ~56 ~17 ~51 ~57 ~17 ~51 cobblestone_wall 3  
fill ~57 ~17 ~39 ~57 ~17 ~42 cobblestone_wall 3  
fill ~57 ~17 ~48 ~58 ~17 ~48 cobblestone_wall 3  
fill ~57 ~17 ~49 ~57 ~17 ~51 cobblestone_wall 3  
fill ~58 ~17 ~42 ~58 ~17 ~48 cobblestone_wall 3  
fill ~16 ~18 ~40 ~16 ~24 ~40 cobblestone_wall 3 
setblock ~19 ~18 ~40 cobblestone_wall 2 
setblock ~21 ~18 ~40 cobblestone_wall 2  
fill ~22 ~18 ~28 ~22 ~19 ~28 cobblestone_wall 2 
setblock ~22 ~18 ~29 nether_brick_stairs 2  
fill ~22 ~18 ~30 ~22 ~18 ~32 nether_brick 0 
setblock ~22 ~18 ~33 nether_brick_stairs 3  
fill ~22 ~18 ~34 ~22 ~19 ~34 cobblestone_wall 2 
setblock ~22 ~18 ~39 stone_slab 13 
setblock ~22 ~18 ~41 stone_slab 13 
setblock ~22 ~18 ~43 stone_slab 13 
setblock ~22 ~18 ~45 stone_slab 13 
setblock ~22 ~18 ~47 stone_slab 13 
setblock ~22 ~18 ~49 stone_slab 13 
setblock ~22 ~18 ~51 stone_slab 13 
setblock ~23 ~18 ~36 stone_slab 13 
setblock ~23 ~18 ~38 stone_slab 13 
setblock ~23 ~18 ~52 stone_slab 13 
setblock ~23 ~18 ~54 stone_slab 13 
setblock ~24 ~18 ~34 stone_slab 13 
setblock ~24 ~18 ~55 stone_slab 13  
fill ~24 ~18 ~60 ~24 ~19 ~60 nether_brick_fence 1 
setblock ~25 ~18 ~32 stone_slab 13 
setblock ~25 ~18 ~57 stone_slab 13 
setblock ~26 ~18 ~59 stone_slab 13 
setblock ~27 ~18 ~30 stone_slab 13  
fill ~27 ~18 ~63 ~27 ~23 ~63 nether_brick_fence 1 
setblock ~28 ~18 ~60 nether_brick_fence 1 
setblock ~28 ~18 ~61 stone_slab 13 
setblock ~29 ~18 ~28 stone_slab 13 
setblock ~30 ~18 ~63 stone_slab 13 
setblock ~31 ~18 ~26 stone_slab 13  
fill ~31 ~18 ~63 ~31 ~18 ~67 cobblestone_wall 3  
fill ~32 ~18 ~42 ~58 ~18 ~42 iron_block 0  
fill ~32 ~18 ~43 ~58 ~18 ~43 iron_block 0  
fill ~32 ~18 ~44 ~58 ~18 ~44 iron_block 0  
fill ~32 ~18 ~45 ~44 ~18 ~45 iron_block 0  
fill ~32 ~18 ~46 ~58 ~18 ~46 iron_block 0  
fill ~32 ~18 ~47 ~58 ~18 ~47 iron_block 0  
fill ~32 ~18 ~48 ~58 ~18 ~48 iron_block 0 
setblock ~32 ~18 ~65 stone_slab 13 
setblock ~33 ~18 ~25 stone_slab 13  
fill ~33 ~18 ~39 ~57 ~18 ~39 iron_block 0  
fill ~33 ~18 ~40 ~57 ~18 ~40 iron_block 0  
fill ~33 ~18 ~41 ~57 ~18 ~41 iron_block 0  
fill ~33 ~18 ~49 ~57 ~18 ~49 iron_block 0  
fill ~33 ~18 ~50 ~57 ~18 ~50 iron_block 0  
fill ~33 ~18 ~51 ~57 ~18 ~51 iron_block 0  
fill ~34 ~18 ~38 ~56 ~18 ~38 iron_block 0  
fill ~34 ~18 ~52 ~56 ~18 ~52 iron_block 0 
setblock ~34 ~18 ~66 stone_slab 13 
setblock ~35 ~18 ~24 stone_slab 13  
fill ~35 ~18 ~36 ~55 ~18 ~36 iron_block 0  
fill ~35 ~18 ~37 ~55 ~18 ~37 iron_block 0  
fill ~35 ~18 ~53 ~55 ~18 ~53 iron_block 0  
fill ~35 ~18 ~54 ~55 ~18 ~54 iron_block 0 
setblock ~36 ~18 ~23 stone_slab 13  
fill ~36 ~18 ~35 ~54 ~18 ~35 iron_block 0  
fill ~36 ~18 ~55 ~54 ~18 ~55 iron_block 0 
setblock ~36 ~18 ~67 stone_slab 13 
setblock ~38 ~18 ~23 stone_slab 13  
fill ~38 ~18 ~34 ~52 ~18 ~34 iron_block 0  
fill ~38 ~18 ~56 ~52 ~18 ~56 iron_block 0 
setblock ~38 ~18 ~67 stone_slab 13 
setblock ~39 ~18 ~22 stone_slab 13  
fill ~39 ~18 ~33 ~51 ~18 ~33 iron_block 0  
fill ~39 ~18 ~57 ~51 ~18 ~57 iron_block 0 
setblock ~39 ~18 ~68 stone_slab 13 
setblock ~41 ~18 ~22 stone_slab 13 
setblock ~41 ~18 ~68 stone_slab 13  
fill ~42 ~18 ~32 ~48 ~18 ~32 iron_block 0  
fill ~42 ~18 ~58 ~48 ~18 ~58 iron_block 0  
fill ~42 ~18 ~68 ~42 ~18 ~71 cobblestone_wall 3 
setblock ~43 ~18 ~22 stone_slab 13 
setblock ~43 ~18 ~68 stone_slab 13 
setblock ~45 ~18 ~22 stone_slab 13 
setblock ~45 ~18 ~68 stone_slab 13  
fill ~46 ~18 ~45 ~58 ~18 ~45 iron_block 0 
setblock ~47 ~18 ~22 stone_slab 13 
setblock ~47 ~18 ~68 stone_slab 13  
fill ~48 ~18 ~68 ~48 ~18 ~71 cobblestone_wall 3 
setblock ~49 ~18 ~22 stone_slab 13 
setblock ~49 ~18 ~68 stone_slab 13 
setblock ~51 ~18 ~22 stone_slab 13 
setblock ~51 ~18 ~68 stone_slab 13 
setblock ~52 ~18 ~23 stone_slab 13 
setblock ~52 ~18 ~67 stone_slab 13 
setblock ~54 ~18 ~23 stone_slab 13 
setblock ~54 ~18 ~67 stone_slab 13 
setblock ~55 ~18 ~24 stone_slab 13 
setblock ~56 ~18 ~66 stone_slab 13 
setblock ~57 ~18 ~25 stone_slab 13 
setblock ~58 ~18 ~65 stone_slab 13 
setblock ~59 ~18 ~26 stone_slab 13 
setblock ~60 ~18 ~63 stone_slab 13 
setblock ~61 ~18 ~28 stone_slab 13 
setblock ~61 ~18 ~61 beacon 0 
setblock ~62 ~18 ~61 stone_slab 13 
setblock ~63 ~18 ~30 stone_slab 13 
setblock ~64 ~18 ~59 stone_slab 13 
setblock ~65 ~18 ~32 stone_slab 13 
setblock ~65 ~18 ~57 stone_slab 13 
setblock ~66 ~18 ~34 stone_slab 13 
setblock ~66 ~18 ~55 stone_slab 13 
setblock ~67 ~18 ~36 stone_slab 13 
setblock ~67 ~18 ~38 stone_slab 13 
setblock ~67 ~18 ~52 stone_slab 13 
setblock ~67 ~18 ~54 stone_slab 13 
setblock ~68 ~18 ~39 stone_slab 13 
setblock ~68 ~18 ~41 stone_slab 13 
setblock ~68 ~18 ~43 stone_slab 13 
setblock ~68 ~18 ~45 stone_slab 13 
setblock ~68 ~18 ~47 stone_slab 13 
setblock ~68 ~18 ~49 stone_slab 13 
setblock ~68 ~18 ~51 stone_slab 13  
fill ~68 ~18 ~53 ~68 ~19 ~53 nether_brick_fence 1  
fill ~68 ~18 ~56 ~68 ~19 ~56 nether_brick_fence 1  
fill ~71 ~18 ~53 ~71 ~19 ~53 nether_brick_fence 1  
fill ~71 ~18 ~56 ~71 ~19 ~56 nether_brick_fence 1  
fill ~17 ~19 ~40 ~21 ~19 ~40 cobblestone_wall 3  
fill ~20 ~19 ~50 ~20 ~23 ~50 cobblestone_wall 3 
setblock ~22 ~19 ~27 cobblestone_wall 2 
setblock ~22 ~19 ~29 nether_brick 0  
fill ~22 ~19 ~31 ~22 ~21 ~31 nether_brick 0 
setblock ~22 ~19 ~33 nether_brick 0 
setblock ~22 ~19 ~35 cobblestone_wall 2  
fill ~22 ~19 ~39 ~68 ~19 ~39 stonebrick 0  
fill ~22 ~19 ~40 ~68 ~19 ~40 stonebrick 0  
fill ~22 ~19 ~41 ~68 ~19 ~41 stonebrick 0  
fill ~22 ~19 ~42 ~68 ~19 ~42 stonebrick 0  
fill ~22 ~19 ~43 ~68 ~19 ~43 stonebrick 0  
fill ~22 ~19 ~44 ~45 ~19 ~44 stonebrick 0  
fill ~22 ~19 ~45 ~68 ~19 ~45 stonebrick 0  
fill ~22 ~19 ~46 ~68 ~19 ~46 stonebrick 0  
fill ~22 ~19 ~47 ~68 ~19 ~47 stonebrick 0  
fill ~22 ~19 ~48 ~68 ~19 ~48 stonebrick 0  
fill ~22 ~19 ~49 ~68 ~19 ~49 stonebrick 0  
fill ~22 ~19 ~50 ~68 ~19 ~50 stonebrick 0  
fill ~22 ~19 ~51 ~68 ~19 ~51 stonebrick 0  
fill ~23 ~19 ~36 ~67 ~19 ~36 stonebrick 0  
fill ~23 ~19 ~37 ~67 ~19 ~37 stonebrick 0  
fill ~23 ~19 ~38 ~67 ~19 ~38 stonebrick 0  
fill ~23 ~19 ~52 ~67 ~19 ~52 stonebrick 0  
fill ~23 ~19 ~53 ~67 ~19 ~53 stonebrick 0  
fill ~23 ~19 ~54 ~67 ~19 ~54 stonebrick 0  
fill ~24 ~19 ~34 ~66 ~19 ~34 stonebrick 0  
fill ~24 ~19 ~35 ~66 ~19 ~35 stonebrick 0  
fill ~24 ~19 ~55 ~66 ~19 ~55 stonebrick 0  
fill ~24 ~19 ~56 ~66 ~19 ~56 stonebrick 0  
fill ~25 ~19 ~27 ~25 ~23 ~27 cobblestone_wall 3  
fill ~25 ~19 ~30 ~25 ~23 ~30 cobblestone_wall 3  
fill ~25 ~19 ~32 ~65 ~19 ~32 stonebrick 0  
fill ~25 ~19 ~33 ~65 ~19 ~33 stonebrick 0  
fill ~25 ~19 ~57 ~56 ~19 ~57 stonebrick 0  
fill ~25 ~19 ~58 ~56 ~19 ~58 stonebrick 0  
fill ~26 ~19 ~31 ~64 ~19 ~31 stonebrick 0  
fill ~26 ~19 ~59 ~56 ~19 ~59 stonebrick 0  
fill ~27 ~19 ~27 ~27 ~23 ~27 cobblestone_wall 3  
fill ~27 ~19 ~30 ~63 ~19 ~30 stonebrick 0  
fill ~27 ~19 ~60 ~56 ~19 ~60 stonebrick 0  
fill ~28 ~19 ~29 ~62 ~19 ~29 stonebrick 0  
fill ~28 ~19 ~61 ~62 ~19 ~61 stonebrick 0  
fill ~29 ~19 ~28 ~61 ~19 ~28 stonebrick 0  
fill ~29 ~19 ~62 ~61 ~19 ~62 stonebrick 0  
fill ~30 ~19 ~27 ~60 ~19 ~27 stonebrick 0  
fill ~30 ~19 ~63 ~60 ~19 ~63 stonebrick 0  
fill ~31 ~19 ~26 ~59 ~19 ~26 stonebrick 0  
fill ~31 ~19 ~64 ~59 ~19 ~64 stonebrick 0  
fill ~31 ~19 ~67 ~31 ~20 ~67 nether_brick_fence 1  
fill ~32 ~19 ~25 ~58 ~19 ~25 stonebrick 0  
fill ~32 ~19 ~65 ~58 ~19 ~65 stonebrick 0  
fill ~34 ~19 ~24 ~56 ~19 ~24 stonebrick 0  
fill ~34 ~19 ~66 ~56 ~19 ~66 stonebrick 0  
fill ~36 ~19 ~23 ~54 ~19 ~23 stonebrick 0  
fill ~36 ~19 ~67 ~54 ~19 ~67 stonebrick 0  
fill ~36 ~19 ~68 ~36 ~19 ~69 cobblestone_wall 3  
fill ~39 ~19 ~22 ~51 ~19 ~22 stonebrick 0  
fill ~39 ~19 ~68 ~51 ~19 ~68 stonebrick 0 
setblock ~39 ~19 ~73 cobblestone_wall 3  
fill ~42 ~19 ~71 ~42 ~21 ~71 nether_brick_fence 1 
setblock ~44 ~19 ~73 cobblestone_wall 3  
fill ~46 ~19 ~44 ~46 ~23 ~44 iron_block 0  
fill ~47 ~19 ~44 ~68 ~19 ~44 stonebrick 0  
fill ~48 ~19 ~71 ~48 ~21 ~71 nether_brick_fence 1 
setblock ~57 ~19 ~57 stone_slab 13 
setblock ~57 ~19 ~60 stone_slab 13 
setblock ~60 ~19 ~57 stone_slab 13 
setblock ~60 ~19 ~60 stone_slab 13  
fill ~61 ~19 ~57 ~65 ~19 ~57 stonebrick 0  
fill ~61 ~19 ~58 ~65 ~19 ~58 stonebrick 0  
fill ~61 ~19 ~59 ~64 ~19 ~59 stonebrick 0  
fill ~61 ~19 ~60 ~63 ~19 ~60 stonebrick 0  
fill ~65 ~19 ~63 ~65 ~26 ~63 cobblestone_wall 3  
fill ~69 ~19 ~54 ~70 ~19 ~54 stone_slab 8  
fill ~69 ~19 ~55 ~70 ~19 ~55 stone_slab 8  
fill ~19 ~20 ~47 ~19 ~23 ~47 cobblestone_wall 3  
fill ~21 ~20 ~43 ~69 ~20 ~43 stonebrick 0  
fill ~21 ~20 ~44 ~45 ~20 ~44 stonebrick 0  
fill ~21 ~20 ~45 ~69 ~20 ~45 stonebrick 0  
fill ~21 ~20 ~46 ~69 ~20 ~46 stonebrick 0  
fill ~21 ~20 ~47 ~69 ~20 ~47 stonebrick 0 
setblock ~22 ~20 ~27 nether_brick_stairs 7 
setblock ~22 ~20 ~28 nether_brick 0 
setblock ~22 ~20 ~34 nether_brick 0 
setblock ~22 ~20 ~35 nether_brick_stairs 6  
fill ~22 ~20 ~38 ~67 ~20 ~38 stonebrick 0  
fill ~22 ~20 ~39 ~68 ~20 ~39 stonebrick 0  
fill ~22 ~20 ~40 ~67 ~20 ~40 stonebrick 0  
fill ~22 ~20 ~41 ~68 ~20 ~41 stonebrick 0  
fill ~22 ~20 ~42 ~68 ~20 ~42 stonebrick 0  
fill ~22 ~20 ~48 ~68 ~20 ~48 stonebrick 0  
fill ~22 ~20 ~49 ~68 ~20 ~49 stonebrick 0  
fill ~22 ~20 ~50 ~68 ~20 ~50 stonebrick 0  
fill ~22 ~20 ~51 ~68 ~20 ~51 stonebrick 0  
fill ~22 ~20 ~52 ~68 ~20 ~52 stonebrick 0  
fill ~23 ~20 ~35 ~67 ~20 ~35 stonebrick 0  
fill ~23 ~20 ~36 ~67 ~20 ~36 stonebrick 0  
fill ~23 ~20 ~37 ~67 ~20 ~37 stonebrick 0  
fill ~23 ~20 ~53 ~67 ~20 ~53 stonebrick 0  
fill ~23 ~20 ~54 ~67 ~20 ~54 stonebrick 0  
fill ~23 ~20 ~55 ~67 ~20 ~55 stonebrick 0  
fill ~24 ~20 ~34 ~66 ~20 ~34 stonebrick 0  
fill ~24 ~20 ~56 ~66 ~20 ~56 stonebrick 0  
fill ~24 ~20 ~60 ~26 ~20 ~60 cobblestone_wall 3  
fill ~25 ~20 ~28 ~27 ~20 ~28 piston_extension 0  
fill ~25 ~20 ~29 ~25 ~20 ~28 piston_extension 0  
fill ~25 ~20 ~32 ~65 ~20 ~32 stonebrick 0  
fill ~25 ~20 ~33 ~65 ~20 ~33 stonebrick 0  
fill ~25 ~20 ~57 ~65 ~20 ~57 stonebrick 0  
fill ~25 ~20 ~58 ~57 ~20 ~58 stonebrick 0  
fill ~26 ~20 ~31 ~64 ~20 ~31 stonebrick 0  
fill ~26 ~20 ~59 ~57 ~20 ~59 stonebrick 0  
fill ~27 ~20 ~29 ~63 ~20 ~29 stonebrick 0  
fill ~27 ~20 ~30 ~63 ~20 ~30 stonebrick 0  
fill ~27 ~20 ~60 ~63 ~20 ~60 stonebrick 0  
fill ~27 ~20 ~61 ~63 ~20 ~61 stonebrick 0  
fill ~28 ~20 ~28 ~62 ~20 ~28 stonebrick 0  
fill ~28 ~20 ~62 ~62 ~20 ~62 stonebrick 0  
fill ~29 ~20 ~27 ~61 ~20 ~27 stonebrick 0  
fill ~29 ~20 ~63 ~61 ~20 ~63 stonebrick 0  
fill ~31 ~20 ~26 ~59 ~20 ~26 stonebrick 0  
fill ~31 ~20 ~64 ~59 ~20 ~64 stonebrick 0  
fill ~32 ~20 ~25 ~58 ~20 ~25 stonebrick 0  
fill ~32 ~20 ~65 ~58 ~20 ~65 stonebrick 0  
fill ~34 ~20 ~24 ~56 ~20 ~24 stonebrick 0  
fill ~34 ~20 ~66 ~56 ~20 ~66 stonebrick 0  
fill ~35 ~20 ~23 ~55 ~20 ~23 stonebrick 0  
fill ~35 ~20 ~67 ~55 ~20 ~67 stonebrick 0 
setblock ~36 ~20 ~69 nether_brick_fence 1  
fill ~38 ~20 ~22 ~52 ~20 ~22 stonebrick 0  
fill ~38 ~20 ~68 ~52 ~20 ~68 stonebrick 0  
fill ~39 ~20 ~69 ~39 ~20 ~71 cobblestone_wall 3 
setblock ~39 ~20 ~72 iron_block 5 
setblock ~39 ~20 ~73 nether_brick_fence 1  
fill ~43 ~20 ~21 ~47 ~20 ~21 stonebrick 0  
fill ~43 ~20 ~69 ~47 ~20 ~69 stonebrick 0  
fill ~44 ~20 ~70 ~44 ~20 ~71 cobblestone_wall 3 
setblock ~44 ~20 ~72 iron_block 5 
setblock ~44 ~20 ~73 nether_brick_fence 1  
fill ~47 ~20 ~44 ~69 ~20 ~44 stonebrick 0  
fill ~58 ~20 ~58 ~59 ~20 ~58 iron_block 0  
fill ~58 ~20 ~59 ~59 ~20 ~59 iron_block 0  
fill ~58 ~20 ~67 ~61 ~20 ~67 cobblestone_wall 3  
fill ~58 ~20 ~68 ~58 ~20 ~70 cobblestone_wall 3  
fill ~60 ~20 ~58 ~65 ~20 ~58 stonebrick 0  
fill ~60 ~20 ~59 ~64 ~20 ~59 stonebrick 0  
fill ~61 ~20 ~65 ~61 ~23 ~65 cobblestone_wall 3  
fill ~61 ~20 ~66 ~61 ~20 ~65 cobblestone_wall 3 
setblock ~68 ~20 ~38 stonebrick 1  
fill ~68 ~20 ~40 ~68 ~21 ~40 stonebrick 1  
fill ~68 ~20 ~53 ~68 ~21 ~53 cobblestone_wall 3  
fill ~68 ~20 ~54 ~71 ~20 ~54 iron_block 0  
fill ~68 ~20 ~55 ~71 ~20 ~55 iron_block 0  
fill ~68 ~20 ~56 ~68 ~23 ~56 cobblestone_wall 3  
fill ~69 ~20 ~53 ~70 ~20 ~53 iron_block 0  
fill ~69 ~20 ~56 ~70 ~20 ~56 iron_block 0  
fill ~71 ~20 ~53 ~71 ~23 ~53 cobblestone_wall 3  
fill ~71 ~20 ~56 ~71 ~23 ~56 cobblestone_wall 3  
fill ~19 ~21 ~45 ~19 ~24 ~45 cobblestone_wall 3 
setblock ~20 ~21 ~47 cobblestone_wall 3  
fill ~20 ~21 ~51 ~21 ~21 ~51 cobblestone_wall 3  
fill ~20 ~21 ~52 ~20 ~21 ~57 cobblestone_wall 3 
setblock ~21 ~21 ~31 nether_brick_stairs 6  
fill ~21 ~21 ~42 ~69 ~21 ~42 stonebrick 0  
fill ~21 ~21 ~43 ~69 ~21 ~43 stonebrick 0  
fill ~21 ~21 ~44 ~45 ~21 ~44 stonebrick 0  
fill ~21 ~21 ~45 ~69 ~21 ~45 stonebrick 0  
fill ~21 ~21 ~46 ~69 ~21 ~46 stonebrick 0  
fill ~21 ~21 ~47 ~69 ~21 ~47 stonebrick 0  
fill ~21 ~21 ~48 ~69 ~21 ~48 stonebrick 0  
fill ~21 ~21 ~57 ~23 ~21 ~57 cobblestone_wall 3 
setblock ~22 ~21 ~26 nether_brick_stairs 2  
fill ~22 ~21 ~27 ~22 ~23 ~27 nether_brick 0  
fill ~22 ~21 ~35 ~22 ~23 ~35 nether_brick 0 
setblock ~22 ~21 ~36 nether_brick_stairs 3  
fill ~22 ~21 ~38 ~68 ~21 ~38 stonebrick 0  
fill ~22 ~21 ~39 ~68 ~21 ~39 stonebrick 0  
fill ~22 ~21 ~40 ~67 ~21 ~40 stonebrick 0  
fill ~22 ~21 ~41 ~68 ~21 ~41 stonebrick 0  
fill ~22 ~21 ~49 ~68 ~21 ~49 stonebrick 0  
fill ~22 ~21 ~50 ~68 ~21 ~50 stonebrick 0  
fill ~22 ~21 ~51 ~68 ~21 ~51 stonebrick 0  
fill ~22 ~21 ~52 ~68 ~21 ~52 stonebrick 0 
setblock ~23 ~21 ~31 nether_brick_stairs 7  
fill ~23 ~21 ~35 ~66 ~21 ~35 stonebrick 0  
fill ~23 ~21 ~36 ~66 ~21 ~36 stonebrick 0  
fill ~23 ~21 ~37 ~67 ~21 ~37 stonebrick 0  
fill ~23 ~21 ~53 ~67 ~21 ~53 stonebrick 0  
fill ~23 ~21 ~54 ~67 ~21 ~54 stonebrick 0  
fill ~23 ~21 ~55 ~67 ~21 ~55 stonebrick 0  
fill ~24 ~21 ~33 ~65 ~21 ~33 stonebrick 0  
fill ~24 ~21 ~34 ~66 ~21 ~34 stonebrick 0  
fill ~24 ~21 ~56 ~66 ~21 ~56 stonebrick 0  
fill ~24 ~21 ~57 ~66 ~21 ~57 stonebrick 0 
setblock ~24 ~21 ~60 nether_brick_fence 1  
fill ~25 ~21 ~28 ~25 ~21 ~29 anvil 2  
fill ~25 ~21 ~31 ~64 ~21 ~31 stonebrick 0  
fill ~25 ~21 ~32 ~64 ~21 ~32 stonebrick 0  
fill ~25 ~21 ~58 ~65 ~21 ~58 stonebrick 0  
fill ~26 ~21 ~28 ~27 ~21 ~28 anvil 3  
fill ~26 ~21 ~30 ~63 ~21 ~30 stonebrick 0  
fill ~26 ~21 ~59 ~64 ~21 ~59 stonebrick 0  
fill ~26 ~21 ~60 ~64 ~21 ~60 stonebrick 0  
fill ~27 ~21 ~29 ~63 ~21 ~29 stonebrick 0  
fill ~27 ~21 ~61 ~63 ~21 ~61 stonebrick 0  
fill ~28 ~21 ~28 ~61 ~21 ~28 stonebrick 0  
fill ~28 ~21 ~62 ~62 ~21 ~62 stonebrick 0  
fill ~29 ~21 ~27 ~61 ~21 ~27 stonebrick 0  
fill ~29 ~21 ~63 ~61 ~21 ~63 stonebrick 0  
fill ~30 ~21 ~26 ~60 ~21 ~26 stonebrick 0  
fill ~30 ~21 ~64 ~60 ~21 ~64 stonebrick 0  
fill ~31 ~21 ~67 ~31 ~23 ~67 cobblestone_wall 3  
