setblock ~20 ~22 ~73 chest 0  
setblock ~30 ~22 ~69 chest 0  
setblock ~30 ~22 ~73 chest 0  
setblock ~44 ~22 ~45 chest 0  
setblock ~44 ~22 ~55 chest 0  
setblock ~39 ~24 ~76 chest 0  
setblock ~42 ~23 ~74 chest 0  
setblock ~44 ~23 ~127 chest 0  
setblock ~48 ~22 ~55 chest 0  
setblock ~47 ~22 ~125 chest 0  
setblock ~63 ~22 ~71 chest 0  
setblock ~63 ~22 ~81 chest 0  
setblock ~67 ~22 ~81 chest 0  
fill ~1 ~0 ~95 ~2 ~0 ~95 grass 0  
fill ~1 ~0 ~96 ~2 ~0 ~96 grass 0  
fill ~1 ~0 ~97 ~1 ~0 ~102 grass 0  
fill ~2 ~0 ~93 ~3 ~0 ~93 grass 0  
fill ~2 ~0 ~94 ~2 ~0 ~93 grass 0  
fill ~2 ~0 ~97 ~7 ~0 ~97 dirt 0  
fill ~2 ~0 ~98 ~7 ~0 ~98 dirt 0  
fill ~2 ~0 ~99 ~7 ~0 ~99 dirt 0  
fill ~2 ~0 ~100 ~8 ~0 ~100 dirt 0  
fill ~2 ~0 ~101 ~9 ~0 ~101 dirt 0  
fill ~2 ~0 ~102 ~10 ~0 ~102 dirt 0  
fill ~2 ~0 ~103 ~2 ~0 ~104 grass 0  
fill ~3 ~0 ~88 ~4 ~0 ~88 grass 0  
fill ~3 ~0 ~89 ~3 ~0 ~93 grass 0  
fill ~3 ~0 ~94 ~8 ~0 ~94 dirt 0  
fill ~3 ~0 ~95 ~8 ~0 ~95 dirt 0  
fill ~3 ~0 ~96 ~7 ~0 ~96 dirt 0  
fill ~3 ~0 ~103 ~10 ~0 ~103 dirt 0  
fill ~3 ~0 ~104 ~3 ~0 ~105 grass 0  
fill ~4 ~0 ~69 ~4 ~1 ~69 dirt 0  
fill ~4 ~0 ~70 ~8 ~0 ~70 stone 0  
fill ~4 ~0 ~71 ~8 ~0 ~71 stone 0  
fill ~4 ~0 ~72 ~8 ~0 ~72 stone 0  
fill ~4 ~0 ~73 ~9 ~0 ~73 stone 0  
fill ~4 ~0 ~74 ~9 ~0 ~74 stone 0  
fill ~4 ~0 ~75 ~4 ~1 ~75 dirt 0  
fill ~4 ~0 ~87 ~5 ~0 ~87 grass 0  
fill ~4 ~0 ~89 ~9 ~0 ~89 dirt 0  
fill ~4 ~0 ~90 ~9 ~0 ~90 dirt 0  
fill ~4 ~0 ~91 ~9 ~0 ~91 dirt 0  
fill ~4 ~0 ~92 ~8 ~0 ~92 dirt 0  
fill ~4 ~0 ~93 ~9 ~0 ~93 dirt 0  
fill ~4 ~0 ~104 ~11 ~0 ~104 dirt 0  
fill ~4 ~0 ~105 ~13 ~0 ~105 dirt 0  
fill ~4 ~0 ~106 ~4 ~0 ~107 grass 0  
fill ~5 ~0 ~68 ~5 ~0 ~68 dirt 0  
fill ~5 ~0 ~69 ~7 ~0 ~69 stone 0  
fill ~5 ~0 ~75 ~9 ~0 ~75 stone 0  
fill ~5 ~0 ~76 ~10 ~0 ~76 stone 0  
fill ~5 ~0 ~77 ~17 ~0 ~77 stone 0  
fill ~5 ~0 ~78 ~17 ~0 ~78 stone 0  
fill ~5 ~0 ~81 ~6 ~0 ~81 grass 0  
fill ~5 ~0 ~82 ~6 ~0 ~82 grass 0  
fill ~5 ~0 ~83 ~6 ~0 ~83 grass 0  
fill ~5 ~0 ~84 ~5 ~0 ~87 grass 0  
fill ~5 ~0 ~88 ~8 ~0 ~88 dirt 0  
fill ~5 ~0 ~106 ~13 ~0 ~106 dirt 0  
fill ~5 ~0 ~107 ~5 ~0 ~108 grass 0 
setblock ~6 ~0 ~68 stone 0  
fill ~6 ~0 ~79 ~6 ~6 ~79 stone 0 
setblock ~6 ~0 ~80 grass 0  
fill ~6 ~0 ~84 ~11 ~0 ~84 dirt 0  
fill ~6 ~0 ~85 ~11 ~0 ~85 dirt 0  
fill ~6 ~0 ~86 ~11 ~0 ~86 dirt 0  
fill ~6 ~0 ~87 ~11 ~0 ~87 dirt 0  
fill ~6 ~0 ~107 ~13 ~0 ~107 dirt 0  
fill ~6 ~0 ~108 ~13 ~0 ~108 dirt 0 
setblock ~6 ~0 ~109 grass 0  
fill ~6 ~0 ~117 ~6 ~0 ~121 grass 0  
fill ~7 ~0 ~68 ~7 ~0 ~68 dirt 0  
fill ~7 ~0 ~79 ~9 ~0 ~79 dirt 0  
fill ~7 ~0 ~80 ~10 ~0 ~80 dirt 0  
fill ~7 ~0 ~81 ~11 ~0 ~81 dirt 0  
fill ~7 ~0 ~82 ~11 ~0 ~82 dirt 0  
fill ~7 ~0 ~83 ~11 ~0 ~83 dirt 0  
fill ~7 ~0 ~109 ~11 ~0 ~109 dirt 0  
fill ~7 ~0 ~110 ~8 ~0 ~110 grass 0  
fill ~7 ~0 ~114 ~7 ~0 ~116 grass 0  
fill ~7 ~0 ~117 ~15 ~0 ~117 dirt 0  
fill ~7 ~0 ~118 ~15 ~0 ~118 dirt 0  
fill ~7 ~0 ~119 ~14 ~0 ~119 dirt 0  
fill ~7 ~0 ~120 ~14 ~0 ~120 dirt 0  
fill ~7 ~0 ~121 ~13 ~0 ~121 dirt 0 
setblock ~7 ~0 ~122 grass 0  
fill ~8 ~0 ~69 ~8 ~1 ~69 dirt 0  
fill ~8 ~0 ~96 ~14 ~0 ~96 stone 0  
fill ~8 ~0 ~97 ~14 ~0 ~97 stone 0  
fill ~8 ~0 ~98 ~14 ~0 ~98 stone 0  
fill ~8 ~0 ~99 ~14 ~0 ~99 stone 0  
fill ~8 ~0 ~111 ~8 ~0 ~113 grass 0  
fill ~8 ~0 ~114 ~16 ~0 ~114 dirt 0  
fill ~8 ~0 ~115 ~16 ~0 ~115 dirt 0  
fill ~8 ~0 ~116 ~16 ~0 ~116 dirt 0  
fill ~8 ~0 ~122 ~9 ~0 ~122 dirt 0 
setblock ~8 ~0 ~123 grass 0  
fill ~9 ~0 ~88 ~9 ~3 ~88 stone 0  
fill ~9 ~0 ~92 ~13 ~0 ~92 stone 0  
fill ~9 ~0 ~94 ~13 ~0 ~94 stone 0  
fill ~9 ~0 ~95 ~13 ~0 ~95 stone 0  
fill ~9 ~0 ~100 ~14 ~0 ~100 stone 0  
fill ~9 ~0 ~110 ~13 ~0 ~110 dirt 0  
fill ~9 ~0 ~111 ~11 ~0 ~111 dirt 0  
fill ~9 ~0 ~112 ~13 ~0 ~112 dirt 0  
fill ~9 ~0 ~113 ~13 ~0 ~113 dirt 0  
fill ~9 ~0 ~123 ~9 ~0 ~123 dirt 0 
setblock ~10 ~0 ~68 grass 0  
fill ~10 ~0 ~79 ~16 ~0 ~79 stone 0  
fill ~10 ~0 ~88 ~10 ~0 ~88 dirt 0  
fill ~10 ~0 ~89 ~15 ~0 ~89 stone 0  
fill ~10 ~0 ~90 ~15 ~0 ~90 stone 0  
fill ~10 ~0 ~91 ~14 ~0 ~91 stone 0  
fill ~10 ~0 ~93 ~13 ~0 ~93 stone 0  
fill ~10 ~0 ~101 ~14 ~0 ~101 stone 0  
fill ~10 ~0 ~122 ~10 ~10 ~122 stone 0  
fill ~10 ~0 ~123 ~10 ~10 ~123 stone 0  
fill ~10 ~0 ~124 ~90 ~0 ~124 stone 0  
fill ~10 ~0 ~125 ~15 ~0 ~125 stone 0  
fill ~10 ~0 ~126 ~16 ~0 ~126 stone 0  
fill ~10 ~0 ~127 ~17 ~0 ~127 stone 0  
fill ~10 ~0 ~128 ~32 ~0 ~128 stone 0  
fill ~10 ~0 ~129 ~10 ~1 ~129 dirt 0  
fill ~11 ~0 ~66 ~23 ~0 ~66 stone 0  
fill ~11 ~0 ~67 ~12 ~0 ~67 stone 0  
fill ~11 ~0 ~68 ~12 ~0 ~68 stone 0  
fill ~11 ~0 ~69 ~12 ~0 ~69 stone 0  
fill ~11 ~0 ~70 ~21 ~0 ~70 stone 0  
fill ~11 ~0 ~80 ~17 ~0 ~80 stone 0  
fill ~11 ~0 ~88 ~16 ~0 ~88 stone 0  
fill ~11 ~0 ~102 ~15 ~0 ~102 stone 0  
fill ~11 ~0 ~103 ~15 ~0 ~103 stone 0  
fill ~11 ~0 ~122 ~13 ~0 ~122 dirt 0  
fill ~11 ~0 ~123 ~11 ~0 ~123 dirt 0  
fill ~11 ~0 ~129 ~32 ~0 ~129 stone 0  
fill ~11 ~0 ~130 ~32 ~0 ~130 stone 0  
fill ~11 ~0 ~131 ~38 ~0 ~131 stone 0  
fill ~11 ~0 ~132 ~38 ~0 ~132 stone 0  
fill ~11 ~0 ~133 ~20 ~0 ~133 stone 0 
setblock ~12 ~0 ~63 grass 0  
fill ~12 ~0 ~64 ~23 ~0 ~64 stone 0  
fill ~12 ~0 ~65 ~23 ~0 ~65 stone 0  
fill ~12 ~0 ~81 ~17 ~0 ~81 stone 0  
fill ~12 ~0 ~82 ~17 ~0 ~82 stone 0  
fill ~12 ~0 ~83 ~18 ~0 ~83 stone 0  
fill ~12 ~0 ~84 ~18 ~0 ~84 stone 0  
fill ~12 ~0 ~85 ~19 ~0 ~85 stone 0  
fill ~12 ~0 ~86 ~18 ~0 ~86 stone 0  
fill ~12 ~0 ~87 ~16 ~0 ~87 stone 0  
fill ~12 ~0 ~104 ~15 ~0 ~104 stone 0  
fill ~12 ~0 ~109 ~12 ~5 ~109 stone 0  
fill ~12 ~0 ~111 ~12 ~5 ~111 stone 0  
fill ~12 ~0 ~123 ~86 ~0 ~123 stone 0  
fill ~12 ~0 ~134 ~20 ~0 ~134 stone 0  
fill ~12 ~0 ~135 ~21 ~0 ~135 stone 0  
fill ~13 ~0 ~63 ~23 ~0 ~63 stone 0  
fill ~13 ~0 ~67 ~13 ~0 ~69 dirt 0  
fill ~13 ~0 ~71 ~21 ~0 ~71 stone 0 
setblock ~13 ~0 ~72 grass 0 
setblock ~13 ~0 ~73 dirt 0  
fill ~13 ~0 ~74 ~16 ~0 ~74 stone 0  
fill ~13 ~0 ~76 ~13 ~1 ~76 dirt 0  
fill ~13 ~0 ~109 ~13 ~2 ~109 dirt 0  
fill ~13 ~0 ~111 ~13 ~2 ~111 dirt 0  
fill ~13 ~0 ~136 ~50 ~0 ~136 stone 0  
fill ~13 ~0 ~137 ~50 ~0 ~137 stone 0  
fill ~14 ~0 ~47 ~15 ~0 ~47 grass 0  
fill ~14 ~0 ~48 ~15 ~0 ~48 grass 0 
setblock ~14 ~0 ~62 grass 0  
fill ~14 ~0 ~67 ~23 ~0 ~67 stone 0  
fill ~14 ~0 ~68 ~23 ~0 ~68 stone 0  
fill ~14 ~0 ~69 ~22 ~0 ~69 stone 0  
fill ~14 ~0 ~72 ~20 ~0 ~72 stone 0  
fill ~14 ~0 ~73 ~16 ~0 ~73 stone 0  
fill ~14 ~0 ~75 ~17 ~0 ~75 stone 0  
fill ~14 ~0 ~76 ~18 ~0 ~76 stone 0  
fill ~14 ~0 ~92 ~14 ~0 ~92 sand 0  
fill ~14 ~0 ~95 ~14 ~0 ~95 sand 0  
fill ~14 ~0 ~105 ~17 ~0 ~105 stone 0  
fill ~14 ~0 ~106 ~14 ~1 ~106 sand 0  
fill ~14 ~0 ~107 ~15 ~0 ~107 sand 0  
fill ~14 ~0 ~108 ~15 ~0 ~108 sand 0  
fill ~14 ~0 ~109 ~16 ~0 ~109 sand 0  
fill ~14 ~0 ~110 ~15 ~0 ~110 sand 0  
fill ~14 ~0 ~111 ~15 ~0 ~111 sand 0  
fill ~14 ~0 ~112 ~16 ~0 ~112 sand 0  
fill ~14 ~0 ~113 ~16 ~0 ~113 sand 0  
fill ~14 ~0 ~121 ~84 ~0 ~121 stone 0  
fill ~14 ~0 ~122 ~62 ~0 ~122 stone 0  
fill ~14 ~0 ~138 ~49 ~0 ~138 stone 0 
setblock ~15 ~0 ~45 grass 0  
fill ~15 ~0 ~46 ~24 ~0 ~46 dirt 0 
setblock ~15 ~0 ~54 grass 0  
fill ~15 ~0 ~55 ~26 ~0 ~55 stone 0  
fill ~15 ~0 ~56 ~25 ~0 ~56 stone 0  
fill ~15 ~0 ~57 ~15 ~1 ~57 dirt 0 
setblock ~15 ~0 ~58 grass 0 
setblock ~15 ~0 ~61 grass 0  
fill ~15 ~0 ~62 ~23 ~0 ~62 stone 0  
fill ~15 ~0 ~91 ~15 ~0 ~91 sand 0  
fill ~15 ~0 ~97 ~15 ~0 ~97 sand 0  
fill ~15 ~0 ~98 ~15 ~0 ~98 sand 0  
fill ~15 ~0 ~99 ~15 ~0 ~99 sand 0  
fill ~15 ~0 ~100 ~15 ~0 ~100 sand 0  
fill ~15 ~0 ~101 ~15 ~0 ~101 sand 0  
fill ~15 ~0 ~106 ~17 ~0 ~106 stone 0  
fill ~15 ~0 ~119 ~84 ~0 ~119 stone 0  
fill ~15 ~0 ~120 ~84 ~0 ~120 stone 0  
fill ~15 ~0 ~139 ~49 ~0 ~139 stone 0  
fill ~16 ~0 ~44 ~25 ~0 ~44 dirt 0  
fill ~16 ~0 ~45 ~26 ~0 ~45 dirt 0  
fill ~16 ~0 ~47 ~22 ~0 ~47 dirt 0  
fill ~16 ~0 ~48 ~21 ~0 ~48 dirt 0  
fill ~16 ~0 ~49 ~21 ~0 ~49 dirt 0  
fill ~16 ~0 ~50 ~21 ~0 ~50 dirt 0  
fill ~16 ~0 ~51 ~21 ~0 ~51 dirt 0 
setblock ~16 ~0 ~52 grass 0  
fill ~16 ~0 ~53 ~27 ~0 ~53 stone 0  
fill ~16 ~0 ~54 ~26 ~0 ~54 stone 0  
fill ~16 ~0 ~57 ~25 ~0 ~57 stone 0  
fill ~16 ~0 ~58 ~24 ~0 ~58 stone 0  
fill ~16 ~0 ~59 ~24 ~0 ~59 stone 0  
fill ~16 ~0 ~60 ~24 ~0 ~60 stone 0  
fill ~16 ~0 ~61 ~24 ~0 ~61 stone 0  
fill ~16 ~0 ~107 ~18 ~0 ~107 stone 0  
fill ~16 ~0 ~108 ~53 ~0 ~108 stone 0  
fill ~16 ~0 ~110 ~76 ~0 ~110 stone 0  
fill ~16 ~0 ~111 ~34 ~0 ~111 stone 0  
fill ~16 ~0 ~117 ~44 ~0 ~117 stone 0  
fill ~16 ~0 ~118 ~44 ~0 ~118 stone 0 
setblock ~16 ~0 ~125 coal_ore 0  
fill ~16 ~0 ~140 ~16 ~1 ~140 dirt 0  
fill ~17 ~0 ~43 ~25 ~0 ~43 dirt 0  
fill ~17 ~0 ~52 ~22 ~0 ~52 stone 0  
fill ~17 ~0 ~73 ~18 ~0 ~73 coal_ore 0  
fill ~17 ~0 ~74 ~18 ~0 ~74 coal_ore 0  
fill ~17 ~0 ~79 ~63 ~0 ~79 sand 0  
fill ~17 ~0 ~109 ~84 ~0 ~109 stone 0  
fill ~17 ~0 ~112 ~36 ~0 ~112 stone 0  
fill ~17 ~0 ~113 ~38 ~0 ~113 stone 0  
fill ~17 ~0 ~114 ~82 ~0 ~114 stone 0  
fill ~17 ~0 ~115 ~82 ~0 ~115 stone 0  
fill ~17 ~0 ~116 ~44 ~0 ~116 stone 0  
fill ~17 ~0 ~125 ~91 ~0 ~125 stone 0 
setblock ~17 ~0 ~126 coal_ore 0  
fill ~17 ~0 ~140 ~48 ~0 ~140 stone 0 
setblock ~18 ~0 ~75 coal_ore 0  
fill ~18 ~0 ~77 ~64 ~0 ~77 sand 0  
fill ~18 ~0 ~78 ~64 ~0 ~78 sand 0  
fill ~18 ~0 ~80 ~62 ~0 ~80 sand 0  
fill ~18 ~0 ~81 ~27 ~0 ~81 sand 0  
fill ~18 ~0 ~82 ~60 ~0 ~82 sand 0  
fill ~18 ~0 ~126 ~96 ~0 ~126 stone 0  
fill ~18 ~0 ~127 ~18 ~1 ~127 coal_ore 0  
fill ~18 ~0 ~141 ~46 ~0 ~141 stone 0  
fill ~19 ~0 ~42 ~26 ~0 ~42 dirt 0  
fill ~19 ~0 ~73 ~19 ~2 ~73 stone 0  
fill ~19 ~0 ~74 ~19 ~2 ~74 stone 0  
fill ~19 ~0 ~75 ~65 ~0 ~75 sand 0  
fill ~19 ~0 ~76 ~65 ~0 ~76 sand 0  
fill ~19 ~0 ~83 ~25 ~0 ~83 sand 0  
fill ~19 ~0 ~84 ~26 ~0 ~84 sand 0  
fill ~19 ~0 ~127 ~70 ~0 ~127 stone 0  
fill ~20 ~0 ~73 ~65 ~0 ~73 sand 0  
fill ~20 ~0 ~74 ~65 ~0 ~74 sand 0  
fill ~20 ~0 ~85 ~24 ~0 ~85 sand 0  
fill ~20 ~0 ~107 ~20 ~2 ~107 sand 0  
fill ~21 ~0 ~41 ~26 ~0 ~41 dirt 0  
fill ~21 ~0 ~72 ~67 ~0 ~72 dirt 0  
fill ~21 ~0 ~106 ~21 ~0 ~106 sand 0  
fill ~21 ~0 ~107 ~52 ~0 ~107 stone 0  
fill ~21 ~0 ~133 ~22 ~0 ~133 iron_ore 0  
fill ~21 ~0 ~134 ~23 ~0 ~134 iron_ore 0  
fill ~21 ~0 ~142 ~22 ~0 ~142 grass 0  
fill ~22 ~0 ~40 ~28 ~0 ~40 dirt 0  
fill ~22 ~0 ~48 ~31 ~0 ~48 stone 0  
fill ~22 ~0 ~49 ~30 ~0 ~49 stone 0  
fill ~22 ~0 ~50 ~29 ~0 ~50 stone 0  
fill ~22 ~0 ~51 ~28 ~0 ~51 stone 0  
fill ~22 ~0 ~70 ~67 ~0 ~70 dirt 0  
fill ~22 ~0 ~71 ~67 ~0 ~71 dirt 0  
fill ~22 ~0 ~86 ~22 ~0 ~86 sand 0  
fill ~22 ~0 ~106 ~23 ~0 ~106 stone 0  
fill ~22 ~0 ~135 ~23 ~0 ~135 iron_ore 0  
fill ~23 ~0 ~39 ~23 ~1 ~39 dirt 0  
fill ~23 ~0 ~47 ~32 ~0 ~47 stone 0 
setblock ~23 ~0 ~52 coal_ore 0  
fill ~23 ~0 ~69 ~67 ~0 ~69 dirt 0 
setblock ~23 ~0 ~86 stone_stairs 0 
setblock ~23 ~0 ~87 stone_slab 3 
setblock ~23 ~0 ~92 stone_slab 3  
fill ~23 ~0 ~93 ~23 ~0 ~94 stone_stairs 0 
setblock ~23 ~0 ~95 stone_slab 3 
setblock ~23 ~0 ~100 stone_slab 3  
fill ~23 ~0 ~101 ~23 ~0 ~102 stone_stairs 0 
setblock ~23 ~0 ~103 stone_slab 3  
fill ~23 ~0 ~133 ~77 ~0 ~133 stone 0  
fill ~24 ~0 ~38 ~24 ~1 ~38 dirt 0 
setblock ~24 ~0 ~39 stone 0  
fill ~24 ~0 ~52 ~27 ~0 ~52 stone 0  
fill ~24 ~0 ~62 ~71 ~0 ~62 dirt 0  
fill ~24 ~0 ~63 ~68 ~0 ~63 dirt 0  
fill ~24 ~0 ~64 ~68 ~0 ~64 dirt 0  
fill ~24 ~0 ~65 ~68 ~0 ~65 dirt 0  
fill ~24 ~0 ~66 ~68 ~0 ~66 dirt 0  
fill ~24 ~0 ~67 ~68 ~0 ~67 dirt 0  
fill ~24 ~0 ~68 ~68 ~0 ~68 dirt 0  
fill ~24 ~0 ~86 ~25 ~0 ~86 cobblestone 0  
fill ~24 ~0 ~87 ~25 ~0 ~87 stone_stairs 3  
fill ~24 ~0 ~92 ~25 ~0 ~92 stone_stairs 2  
fill ~24 ~0 ~93 ~25 ~0 ~93 cobblestone 0  
fill ~24 ~0 ~94 ~25 ~0 ~94 cobblestone 0  
fill ~24 ~0 ~95 ~25 ~0 ~95 stone_stairs 3  
fill ~24 ~0 ~100 ~25 ~0 ~100 stone_stairs 2  
fill ~24 ~0 ~101 ~25 ~0 ~101 cobblestone 0  
fill ~24 ~0 ~102 ~25 ~0 ~102 cobblestone 0  
fill ~24 ~0 ~103 ~25 ~0 ~103 stone_stairs 3  
fill ~24 ~0 ~106 ~28 ~0 ~106 sand 0  
fill ~24 ~0 ~134 ~94 ~0 ~134 stone 0  
fill ~24 ~0 ~135 ~51 ~0 ~135 stone 0 
setblock ~25 ~0 ~37 grass 0 
setblock ~25 ~0 ~38 stone 0  
fill ~25 ~0 ~39 ~26 ~0 ~39 dirt 0  
fill ~25 ~0 ~46 ~34 ~0 ~46 stone 0  
fill ~25 ~0 ~58 ~67 ~0 ~58 dirt 0  
fill ~25 ~0 ~59 ~67 ~0 ~59 dirt 0  
fill ~25 ~0 ~60 ~67 ~0 ~60 dirt 0  
fill ~25 ~0 ~61 ~69 ~0 ~61 dirt 0  
fill ~25 ~0 ~85 ~25 ~16 ~85 cobblestone 0  
fill ~26 ~0 ~37 ~26 ~1 ~37 dirt 0  
fill ~26 ~0 ~38 ~27 ~0 ~38 dirt 0  
fill ~26 ~0 ~43 ~32 ~0 ~43 leaves 0  
fill ~26 ~0 ~44 ~30 ~0 ~44 leaves 0  
fill ~26 ~0 ~56 ~66 ~0 ~56 dirt 0  
fill ~26 ~0 ~57 ~66 ~0 ~57 dirt 0  
fill ~26 ~0 ~85 ~26 ~2 ~85 sand 0  
fill ~26 ~0 ~86 ~27 ~0 ~86 sand 0 
setblock ~26 ~0 ~87 stone_slab 3 
setblock ~26 ~0 ~92 stone_slab 3  
fill ~26 ~0 ~93 ~26 ~0 ~94 stone_stairs 1 
setblock ~26 ~0 ~95 stone_slab 3 
setblock ~26 ~0 ~100 stone_slab 3  
fill ~26 ~0 ~101 ~26 ~0 ~102 stone_stairs 1 
setblock ~26 ~0 ~103 stone_slab 3  
fill ~27 ~0 ~37 ~28 ~0 ~37 stone 0  
fill ~27 ~0 ~39 ~31 ~0 ~39 leaves 0  
fill ~27 ~0 ~41 ~35 ~0 ~41 leaves 0  
fill ~27 ~0 ~42 ~30 ~0 ~42 leaves 0  
fill ~27 ~0 ~45 ~28 ~0 ~45 leaves 0  
fill ~27 ~0 ~54 ~65 ~0 ~54 dirt 0  
fill ~27 ~0 ~55 ~65 ~0 ~55 dirt 0 
setblock ~27 ~0 ~85 stone 0 
setblock ~27 ~0 ~142 grass 0  
fill ~28 ~0 ~36 ~28 ~1 ~36 dirt 0  
fill ~28 ~0 ~38 ~30 ~0 ~38 leaves 0  
fill ~28 ~0 ~52 ~64 ~0 ~52 dirt 0  
fill ~28 ~0 ~53 ~64 ~0 ~53 dirt 0  
fill ~28 ~0 ~84 ~28 ~0 ~84 sand 0  
fill ~28 ~0 ~86 ~38 ~0 ~86 stone 0  
fill ~28 ~0 ~142 ~44 ~0 ~142 stone 0  
fill ~29 ~0 ~36 ~40 ~0 ~36 stone 0 
setblock ~29 ~0 ~37 leaves 0  
fill ~29 ~0 ~40 ~31 ~0 ~40 leaves 0  
fill ~29 ~0 ~45 ~29 ~1 ~45 dirt 0  
fill ~29 ~0 ~51 ~63 ~0 ~51 dirt 0  
fill ~29 ~0 ~81 ~61 ~0 ~81 sand 0  
fill ~29 ~0 ~83 ~29 ~0 ~83 sand 0  
fill ~29 ~0 ~85 ~36 ~0 ~85 stone 0  
fill ~29 ~0 ~87 ~29 ~2 ~87 sand 0  
fill ~29 ~0 ~106 ~38 ~0 ~106 stone 0  
fill ~30 ~0 ~35 ~30 ~1 ~35 dirt 0  
fill ~30 ~0 ~37 ~38 ~0 ~37 stone 0  
fill ~30 ~0 ~45 ~36 ~0 ~45 stone 0  
fill ~30 ~0 ~50 ~62 ~0 ~50 dirt 0  
fill ~30 ~0 ~84 ~34 ~0 ~84 stone 0  
fill ~30 ~0 ~87 ~40 ~0 ~87 stone 0  
fill ~30 ~0 ~88 ~30 ~1 ~88 sand 0  
fill ~31 ~0 ~34 ~31 ~0 ~34 dirt 0  
fill ~31 ~0 ~35 ~44 ~0 ~35 stone 0  
fill ~31 ~0 ~38 ~36 ~0 ~38 stone 0 
setblock ~31 ~0 ~42 log 0  
fill ~31 ~0 ~44 ~31 ~0 ~44 dirt 0  
fill ~31 ~0 ~49 ~61 ~0 ~49 dirt 0  
fill ~31 ~0 ~83 ~32 ~0 ~83 stone 0  
fill ~31 ~0 ~88 ~40 ~0 ~88 stone 0  
fill ~31 ~0 ~143 ~38 ~0 ~143 stone 0  
fill ~32 ~0 ~34 ~43 ~0 ~34 stone 0  
fill ~32 ~0 ~39 ~128 ~0 ~39 stone 0  
fill ~32 ~0 ~40 ~33 ~0 ~40 dirt 0  
fill ~32 ~0 ~42 ~35 ~0 ~42 leaves 0  
fill ~32 ~0 ~44 ~32 ~1 ~44 leaves 0  
fill ~32 ~0 ~48 ~61 ~0 ~48 dirt 0  
fill ~32 ~0 ~89 ~32 ~2 ~89 sand 0  
fill ~32 ~0 ~105 ~32 ~0 ~105 sand 0  
fill ~33 ~0 ~33 ~33 ~1 ~33 dirt 0  
fill ~33 ~0 ~43 ~33 ~4 ~43 log 0 
setblock ~33 ~0 ~44 grass 0  
fill ~33 ~0 ~47 ~59 ~0 ~47 dirt 0  
fill ~33 ~0 ~83 ~59 ~0 ~83 sand 0  
fill ~33 ~0 ~89 ~41 ~0 ~89 stone 0  
fill ~33 ~0 ~128 ~33 ~1 ~128 iron_ore 0  
fill ~33 ~0 ~129 ~33 ~1 ~129 iron_ore 0  
fill ~33 ~0 ~130 ~33 ~1 ~130 iron_ore 0  
fill ~34 ~0 ~33 ~42 ~0 ~33 stone 0 
setblock ~34 ~0 ~40 leaves 0  
fill ~34 ~0 ~43 ~34 ~9 ~43 leaves 0  
fill ~34 ~0 ~44 ~34 ~2 ~44 dirt 0  
fill ~34 ~0 ~90 ~43 ~0 ~90 stone 0  
fill ~34 ~0 ~128 ~69 ~0 ~128 stone 0  
fill ~34 ~0 ~129 ~69 ~0 ~129 stone 0  
fill ~34 ~0 ~130 ~56 ~0 ~130 stone 0  
fill ~35 ~0 ~32 ~44 ~0 ~32 stone 0  
fill ~35 ~0 ~40 ~35 ~1 ~40 dirt 0  
fill ~35 ~0 ~43 ~35 ~2 ~43 dirt 0  
fill ~35 ~0 ~44 ~38 ~0 ~44 stone 0  
fill ~35 ~0 ~46 ~57 ~0 ~46 dirt 0  
fill ~35 ~0 ~84 ~57 ~0 ~84 sand 0  
fill ~35 ~0 ~91 ~35 ~0 ~91 sand 0  
fill ~35 ~0 ~105 ~35 ~0 ~105 sand 0  
fill ~35 ~0 ~111 ~35 ~2 ~111 sand 0 
setblock ~36 ~0 ~31 grass 0  
fill ~36 ~0 ~40 ~42 ~0 ~40 stone 0  
fill ~36 ~0 ~41 ~37 ~0 ~41 stone 0  
fill ~36 ~0 ~42 ~36 ~4 ~42 stone 0  
fill ~36 ~0 ~43 ~42 ~0 ~43 stone 0  
fill ~36 ~0 ~91 ~43 ~0 ~91 stone 0  
fill ~36 ~0 ~111 ~75 ~0 ~111 stone 0  
fill ~37 ~0 ~31 ~44 ~0 ~31 stone 0  
fill ~37 ~0 ~38 ~37 ~0 ~38 dirt 0  
fill ~37 ~0 ~42 ~37 ~1 ~42 dirt 0  
fill ~37 ~0 ~45 ~55 ~0 ~45 dirt 0  
fill ~37 ~0 ~85 ~55 ~0 ~85 sand 0  
fill ~37 ~0 ~92 ~37 ~1 ~92 sand 0  
fill ~37 ~0 ~94 ~37 ~2 ~94 sand 0  
fill ~37 ~0 ~112 ~37 ~2 ~112 sand 0  
fill ~38 ~0 ~30 ~38 ~0 ~30 dirt 0  
fill ~38 ~0 ~38 ~46 ~0 ~38 stone 0  
fill ~38 ~0 ~41 ~41 ~0 ~41 dirt 0  
fill ~38 ~0 ~42 ~128 ~0 ~42 stone 0  
fill ~38 ~0 ~92 ~44 ~0 ~92 stone 0 
setblock ~38 ~0 ~94 stone 0  
fill ~38 ~0 ~95 ~39 ~0 ~95 sand 0  
fill ~38 ~0 ~112 ~81 ~0 ~112 stone 0  
fill ~39 ~0 ~30 ~127 ~0 ~30 stone 0  
fill ~39 ~0 ~37 ~39 ~0 ~37 dirt 0  
fill ~39 ~0 ~44 ~53 ~0 ~44 dirt 0  
fill ~39 ~0 ~86 ~53 ~0 ~86 sand 0  
fill ~39 ~0 ~94 ~40 ~0 ~94 sand 0  
fill ~39 ~0 ~106 ~50 ~0 ~106 sand 0  
fill ~39 ~0 ~113 ~39 ~2 ~113 sand 0  
fill ~39 ~0 ~131 ~40 ~0 ~131 coal_ore 0  
fill ~39 ~0 ~132 ~39 ~0 ~131 coal_ore 0  
fill ~39 ~0 ~143 ~39 ~0 ~143 dirt 0  
fill ~40 ~0 ~37 ~57 ~0 ~37 stone 0  
fill ~40 ~0 ~93 ~46 ~0 ~93 stone 0  
fill ~40 ~0 ~95 ~41 ~0 ~95 stone 0  
fill ~40 ~0 ~113 ~81 ~0 ~113 stone 0  
fill ~40 ~0 ~132 ~96 ~0 ~132 stone 0  
fill ~41 ~0 ~29 ~110 ~0 ~29 stone 0  
fill ~41 ~0 ~36 ~41 ~1 ~36 dirt 0  
fill ~41 ~0 ~87 ~54 ~0 ~87 sand 0  
fill ~41 ~0 ~88 ~54 ~0 ~88 sand 0  
fill ~41 ~0 ~96 ~41 ~2 ~96 sand 0  
fill ~41 ~0 ~131 ~55 ~0 ~131 stone 0  
fill ~42 ~0 ~36 ~73 ~0 ~36 stone 0  
fill ~42 ~0 ~41 ~127 ~0 ~41 stone 0  
fill ~42 ~0 ~89 ~55 ~0 ~89 sand 0  
fill ~42 ~0 ~94 ~42 ~0 ~94 sand 0  
fill ~42 ~0 ~96 ~49 ~0 ~96 stone 0  
fill ~43 ~0 ~28 ~45 ~0 ~28 dirt 0  
fill ~43 ~0 ~33 ~45 ~0 ~33 leaves 0  
fill ~43 ~0 ~40 ~47 ~0 ~40 dirt 0  
fill ~43 ~0 ~43 ~49 ~0 ~43 dirt 0  
fill ~43 ~0 ~95 ~48 ~0 ~95 stone 0  
fill ~43 ~0 ~97 ~43 ~2 ~97 sand 0  
fill ~44 ~0 ~34 ~46 ~0 ~34 leaves 0  
fill ~44 ~0 ~90 ~55 ~0 ~90 sand 0  
fill ~44 ~0 ~91 ~56 ~0 ~91 sand 0  
fill ~44 ~0 ~94 ~46 ~0 ~94 stone 0  
fill ~44 ~0 ~97 ~48 ~0 ~97 stone 0  
fill ~44 ~0 ~98 ~44 ~1 ~98 sand 0  
fill ~45 ~0 ~31 ~45 ~0 ~35 leaves 0  
fill ~45 ~0 ~98 ~47 ~0 ~98 stone 0  
fill ~45 ~0 ~116 ~46 ~0 ~116 coal_ore 0  
fill ~45 ~0 ~117 ~46 ~0 ~117 coal_ore 0  
fill ~45 ~0 ~118 ~45 ~0 ~116 coal_ore 0  
fill ~45 ~0 ~142 ~45 ~1 ~142 dirt 0  
fill ~46 ~0 ~24 ~46 ~0 ~24 dirt 0  
fill ~46 ~0 ~25 ~74 ~0 ~25 stone 0  
fill ~46 ~0 ~26 ~61 ~0 ~26 stone 0  
fill ~46 ~0 ~27 ~128 ~0 ~27 stone 0  
fill ~46 ~0 ~28 ~94 ~0 ~28 stone 0  
fill ~46 ~0 ~31 ~127 ~0 ~31 stone 0  
fill ~46 ~0 ~32 ~49 ~0 ~32 stone 0 
setblock ~46 ~0 ~33 grass 0  
fill ~46 ~0 ~35 ~128 ~0 ~35 stone 0  
fill ~46 ~0 ~92 ~56 ~0 ~92 sand 0  
fill ~46 ~0 ~99 ~46 ~2 ~99 sand 0  
fill ~46 ~0 ~118 ~84 ~0 ~118 stone 0  
fill ~47 ~0 ~22 ~123 ~0 ~22 stone 0  
fill ~47 ~0 ~23 ~122 ~0 ~23 stone 0  
fill ~47 ~0 ~24 ~74 ~0 ~24 stone 0  
fill ~47 ~0 ~33 ~125 ~0 ~33 stone 0  
fill ~47 ~0 ~34 ~127 ~0 ~34 stone 0  
fill ~47 ~0 ~38 ~47 ~1 ~38 dirt 0  
fill ~47 ~0 ~93 ~61 ~0 ~93 sand 0  
fill ~47 ~0 ~94 ~63 ~0 ~94 sand 0  
fill ~47 ~0 ~99 ~47 ~1 ~99 stone 0  
fill ~47 ~0 ~116 ~83 ~0 ~116 stone 0  
fill ~47 ~0 ~117 ~84 ~0 ~117 stone 0  
fill ~47 ~0 ~141 ~47 ~2 ~141 dirt 0  
fill ~48 ~0 ~19 ~127 ~0 ~19 stone 0  
fill ~48 ~0 ~20 ~127 ~0 ~20 stone 0  
fill ~48 ~0 ~21 ~122 ~0 ~21 stone 0  
fill ~48 ~0 ~38 ~128 ~0 ~38 stone 0  
fill ~48 ~0 ~40 ~128 ~0 ~40 stone 0  
fill ~49 ~0 ~18 ~82 ~0 ~18 stone 0  
fill ~49 ~0 ~95 ~65 ~0 ~95 sand 0  
fill ~49 ~0 ~98 ~49 ~0 ~98 sand 0  
fill ~50 ~0 ~17 ~81 ~0 ~17 stone 0 
setblock ~50 ~0 ~32 coal_ore 0  
fill ~50 ~0 ~43 ~128 ~0 ~43 stone 0  
fill ~50 ~0 ~99 ~50 ~0 ~99 sand 0  
fill ~50 ~0 ~101 ~50 ~0 ~101 sand 0  
fill ~50 ~0 ~138 ~50 ~2 ~138 dirt 0  
fill ~51 ~0 ~16 ~81 ~0 ~16 stone 0  
fill ~51 ~0 ~32 ~127 ~0 ~32 stone 0  
fill ~51 ~0 ~96 ~65 ~0 ~96 sand 0  
fill ~51 ~0 ~98 ~51 ~0 ~99 stone 0  
fill ~51 ~0 ~101 ~52 ~0 ~101 stone 0  
fill ~51 ~0 ~102 ~51 ~1 ~102 sand 0  
fill ~51 ~0 ~136 ~54 ~0 ~136 dirt 0  
fill ~51 ~0 ~137 ~51 ~0 ~137 dirt 0  
fill ~52 ~0 ~15 ~128 ~0 ~15 stone 0  
fill ~52 ~0 ~97 ~63 ~0 ~97 sand 0  
fill ~52 ~0 ~98 ~63 ~0 ~98 sand 0  
fill ~52 ~0 ~99 ~54 ~0 ~99 stone 0  
fill ~52 ~0 ~102 ~58 ~0 ~102 stone 0  
fill ~52 ~0 ~103 ~60 ~0 ~103 stone 0  
fill ~52 ~0 ~135 ~52 ~2 ~135 dirt 0  
fill ~52 ~0 ~137 ~53 ~0 ~137 grass 0  
fill ~53 ~0 ~14 ~53 ~1 ~14 dirt 0  
fill ~53 ~0 ~100 ~55 ~0 ~100 stone 0 
setblock ~53 ~0 ~101 leaves 2 
setblock ~53 ~0 ~107 gravel 0  
fill ~53 ~0 ~135 ~58 ~0 ~135 stone 0  
fill ~54 ~0 ~14 ~127 ~0 ~14 stone 0  
fill ~54 ~0 ~44 ~128 ~0 ~44 stone 0  
fill ~54 ~0 ~86 ~104 ~0 ~86 stone 0  
fill ~54 ~0 ~101 ~56 ~0 ~101 stone 0  
fill ~54 ~0 ~107 ~54 ~2 ~107 sand 0  
fill ~54 ~0 ~108 ~55 ~0 ~108 gravel 0  
fill ~54 ~0 ~137 ~55 ~0 ~137 dirt 0  
fill ~55 ~0 ~13 ~127 ~0 ~13 stone 0  
fill ~55 ~0 ~87 ~63 ~0 ~87 stone 0  
fill ~55 ~0 ~88 ~65 ~0 ~88 stone 0  
fill ~55 ~0 ~99 ~62 ~0 ~99 sand 0  
fill ~55 ~0 ~107 ~56 ~0 ~107 gravel 0 
setblock ~55 ~0 ~136 stone 0  
fill ~56 ~0 ~45 ~67 ~0 ~45 stone 0  
fill ~56 ~0 ~85 ~104 ~0 ~85 stone 0  
fill ~56 ~0 ~89 ~62 ~0 ~89 stone 0  
fill ~56 ~0 ~90 ~62 ~0 ~90 stone 0  
fill ~56 ~0 ~100 ~62 ~0 ~100 sand 0  
fill ~56 ~0 ~108 ~85 ~0 ~108 stone 0  
fill ~56 ~0 ~136 ~57 ~0 ~136 dirt 0 
setblock ~56 ~0 ~137 grass 0  
fill ~57 ~0 ~12 ~128 ~0 ~12 stone 0  
fill ~57 ~0 ~91 ~61 ~0 ~91 stone 0  
fill ~57 ~0 ~92 ~61 ~0 ~92 stone 0  
fill ~57 ~0 ~101 ~62 ~0 ~101 sand 0  
fill ~57 ~0 ~107 ~77 ~0 ~107 stone 0  
fill ~58 ~0 ~37 ~59 ~0 ~37 coal_ore 0  
fill ~58 ~0 ~46 ~128 ~0 ~46 stone 0  
fill ~58 ~0 ~84 ~105 ~0 ~84 stone 0  
fill ~58 ~0 ~106 ~77 ~0 ~106 stone 0  
fill ~58 ~0 ~131 ~77 ~0 ~131 stone 0  
fill ~58 ~0 ~136 ~60 ~0 ~136 grass 0  
fill ~59 ~0 ~11 ~59 ~1 ~11 dirt 0  
fill ~59 ~0 ~105 ~59 ~1 ~105 sand 0  
fill ~59 ~0 ~130 ~76 ~0 ~130 stone 0  
fill ~59 ~0 ~135 ~61 ~0 ~135 dirt 0  
fill ~59 ~0 ~142 ~59 ~3 ~142 log 2  
fill ~60 ~0 ~11 ~126 ~0 ~11 stone 0  
fill ~60 ~0 ~37 ~72 ~0 ~37 stone 0  
fill ~60 ~0 ~47 ~128 ~0 ~47 stone 0  
fill ~60 ~0 ~83 ~108 ~0 ~83 stone 0  
fill ~60 ~0 ~102 ~62 ~0 ~102 sand 0  
fill ~60 ~0 ~104 ~62 ~0 ~104 sand 0  
fill ~60 ~0 ~105 ~76 ~0 ~105 stone 0  
fill ~60 ~0 ~137 ~61 ~0 ~137 grass 0  
fill ~60 ~0 ~138 ~60 ~0 ~140 grass 0  
fill ~61 ~0 ~82 ~110 ~0 ~82 stone 0  
fill ~61 ~0 ~103 ~62 ~0 ~103 sand 0  
fill ~61 ~0 ~136 ~62 ~0 ~136 dirt 0  
fill ~61 ~0 ~138 ~63 ~0 ~138 dirt 0  
fill ~61 ~0 ~139 ~63 ~0 ~139 dirt 0  
fill ~61 ~0 ~140 ~61 ~0 ~141 grass 0 
setblock ~62 ~0 ~26 coal_ore 0  
fill ~62 ~0 ~48 ~84 ~0 ~48 stone 0  
fill ~62 ~0 ~49 ~63 ~0 ~49 leaves 0  
fill ~62 ~0 ~81 ~111 ~0 ~81 stone 0 
setblock ~62 ~0 ~91 gravel 0  
fill ~62 ~0 ~92 ~64 ~0 ~92 sand 0  
fill ~62 ~0 ~93 ~106 ~0 ~93 stone 0  
fill ~62 ~0 ~135 ~94 ~0 ~135 stone 0  
fill ~62 ~0 ~137 ~63 ~0 ~137 dirt 0  
fill ~62 ~0 ~140 ~66 ~0 ~140 dirt 0 
setblock ~62 ~0 ~141 grass 0  
fill ~63 ~0 ~26 ~107 ~0 ~26 stone 0  
fill ~63 ~0 ~50 ~64 ~0 ~50 leaves 0  
fill ~63 ~0 ~80 ~111 ~0 ~80 stone 0 
setblock ~63 ~0 ~89 gravel 0  
fill ~63 ~0 ~90 ~65 ~0 ~90 sand 0  
fill ~63 ~0 ~91 ~65 ~0 ~91 sand 0  
fill ~63 ~0 ~99 ~70 ~0 ~99 stone 0  
fill ~63 ~0 ~100 ~71 ~0 ~100 stone 0  
fill ~63 ~0 ~101 ~72 ~0 ~101 stone 0  
fill ~63 ~0 ~102 ~74 ~0 ~102 stone 0  
fill ~63 ~0 ~103 ~106 ~0 ~103 stone 0  
fill ~63 ~0 ~104 ~106 ~0 ~104 stone 0  
fill ~63 ~0 ~136 ~93 ~0 ~136 stone 0  
fill ~63 ~0 ~141 ~67 ~0 ~141 dirt 0  
fill ~63 ~0 ~142 ~67 ~0 ~142 grass 0  
fill ~64 ~0 ~6 ~64 ~0 ~9 grass 0  
fill ~64 ~0 ~10 ~65 ~0 ~10 dirt 0  
fill ~64 ~0 ~49 ~64 ~14 ~49 stone 0  
fill ~64 ~0 ~51 ~103 ~0 ~51 stone 0  
fill ~64 ~0 ~79 ~112 ~0 ~79 stone 0  
fill ~64 ~0 ~87 ~64 ~1 ~87 sand 0  
fill ~64 ~0 ~89 ~65 ~0 ~89 sand 0  
fill ~64 ~0 ~94 ~107 ~0 ~94 stone 0  
fill ~64 ~0 ~97 ~69 ~0 ~97 stone 0  
fill ~64 ~0 ~98 ~69 ~0 ~98 stone 0  
fill ~64 ~0 ~122 ~85 ~0 ~122 stone 0  
fill ~64 ~0 ~137 ~84 ~0 ~137 stone 0  
fill ~64 ~0 ~138 ~82 ~0 ~138 stone 0  
fill ~64 ~0 ~139 ~64 ~0 ~97 stone 0  
fill ~65 ~0 ~6 ~66 ~0 ~6 dirt 0  
fill ~65 ~0 ~7 ~66 ~0 ~7 dirt 0  
fill ~65 ~0 ~8 ~66 ~0 ~8 dirt 0  
fill ~65 ~0 ~9 ~66 ~0 ~9 dirt 0  
fill ~65 ~0 ~49 ~65 ~0 ~49 dirt 0  
fill ~65 ~0 ~50 ~73 ~0 ~50 stone 0  
fill ~65 ~0 ~52 ~101 ~0 ~52 stone 0  
fill ~65 ~0 ~53 ~67 ~0 ~53 stone 0  
fill ~65 ~0 ~77 ~112 ~0 ~77 stone 0  
fill ~65 ~0 ~78 ~112 ~0 ~78 stone 0  
fill ~65 ~0 ~87 ~66 ~0 ~87 stone 0  
fill ~65 ~0 ~92 ~106 ~0 ~92 stone 0  
fill ~65 ~0 ~139 ~65 ~1 ~139 dirt 0  
fill ~66 ~0 ~10 ~77 ~0 ~10 stone 0  
fill ~66 ~0 ~49 ~80 ~0 ~49 stone 0  
fill ~66 ~0 ~54 ~81 ~0 ~54 stone 0  
fill ~66 ~0 ~55 ~89 ~0 ~55 stone 0  
fill ~66 ~0 ~73 ~66 ~3 ~73 dirt 0  
fill ~66 ~0 ~74 ~66 ~2 ~74 dirt 0  
fill ~66 ~0 ~75 ~113 ~0 ~75 stone 0  
fill ~66 ~0 ~76 ~113 ~0 ~76 stone 0  
fill ~66 ~0 ~88 ~71 ~0 ~88 dirt 0  
fill ~66 ~0 ~89 ~69 ~0 ~89 dirt 0  
fill ~66 ~0 ~90 ~68 ~0 ~90 dirt 0  
fill ~66 ~0 ~91 ~66 ~1 ~91 dirt 0  
fill ~66 ~0 ~95 ~107 ~0 ~95 stone 0  
fill ~66 ~0 ~96 ~68 ~0 ~96 stone 0  
fill ~66 ~0 ~139 ~80 ~0 ~139 stone 0  
fill ~66 ~0 ~143 ~66 ~4 ~143 log 0  
fill ~67 ~0 ~5 ~67 ~0 ~5 dirt 0  
fill ~67 ~0 ~6 ~83 ~0 ~6 stone 0  
fill ~67 ~0 ~7 ~84 ~0 ~7 stone 0  
fill ~67 ~0 ~8 ~85 ~0 ~8 stone 0  
fill ~67 ~0 ~9 ~78 ~0 ~9 stone 0  
fill ~67 ~0 ~56 ~82 ~0 ~56 stone 0  
fill ~67 ~0 ~57 ~67 ~9 ~57 stone 0  
fill ~67 ~0 ~73 ~68 ~0 ~73 lapis_ore 0  
fill ~67 ~0 ~74 ~114 ~0 ~74 stone 0  
fill ~67 ~0 ~87 ~67 ~0 ~87 dirt 0  
fill ~67 ~0 ~91 ~105 ~0 ~91 stone 0  
fill ~67 ~0 ~140 ~75 ~0 ~140 stone 0  
fill ~68 ~0 ~5 ~83 ~0 ~5 stone 0 
setblock ~68 ~0 ~45 coal_ore 0 
setblock ~68 ~0 ~53 leaves 0 
setblock ~68 ~0 ~57 log 2  
fill ~68 ~0 ~58 ~100 ~0 ~58 stone 0  
fill ~68 ~0 ~59 ~100 ~0 ~59 stone 0  
fill ~68 ~0 ~60 ~100 ~0 ~60 stone 0  
fill ~68 ~0 ~69 ~112 ~0 ~69 stone 0  
fill ~68 ~0 ~70 ~113 ~0 ~70 stone 0  
fill ~68 ~0 ~71 ~112 ~0 ~71 stone 0  
fill ~68 ~0 ~72 ~95 ~0 ~72 stone 0  
fill ~68 ~0 ~87 ~71 ~0 ~87 stone 0  
fill ~68 ~0 ~141 ~73 ~0 ~141 stone 0  
fill ~68 ~0 ~142 ~68 ~0 ~142 dirt 0 
setblock ~69 ~0 ~4 grass 0  
fill ~69 ~0 ~45 ~128 ~0 ~45 stone 0  
fill ~69 ~0 ~53 ~81 ~0 ~53 stone 0  
fill ~69 ~0 ~57 ~81 ~0 ~57 stone 0  
fill ~69 ~0 ~63 ~100 ~0 ~63 stone 0  
fill ~69 ~0 ~64 ~100 ~0 ~64 stone 0  
fill ~69 ~0 ~65 ~100 ~0 ~65 stone 0  
fill ~69 ~0 ~66 ~105 ~0 ~66 stone 0  
fill ~69 ~0 ~67 ~107 ~0 ~67 stone 0  
fill ~69 ~0 ~68 ~110 ~0 ~68 stone 0  
fill ~69 ~0 ~73 ~95 ~0 ~73 stone 0  
fill ~69 ~0 ~90 ~105 ~0 ~90 stone 0  
fill ~69 ~0 ~96 ~69 ~1 ~96 coal_ore 0  
fill ~69 ~0 ~142 ~71 ~0 ~142 stone 0  
fill ~70 ~0 ~4 ~82 ~0 ~4 stone 0  
fill ~70 ~0 ~61 ~100 ~0 ~61 stone 0  
fill ~70 ~0 ~89 ~104 ~0 ~89 stone 0  
fill ~70 ~0 ~96 ~70 ~11 ~96 stone 0  
fill ~70 ~0 ~97 ~72 ~0 ~97 leaves 0  
fill ~70 ~0 ~98 ~70 ~0 ~98 dirt 0  
fill ~70 ~0 ~128 ~71 ~0 ~128 coal_ore 0  
fill ~70 ~0 ~129 ~71 ~0 ~129 coal_ore 0  
fill ~70 ~0 ~143 ~70 ~4 ~143 log 0 
setblock ~71 ~0 ~96 leaves 0  
fill ~71 ~0 ~98 ~73 ~0 ~98 leaves 0  
fill ~71 ~0 ~99 ~72 ~0 ~99 leaves 0  
fill ~71 ~0 ~127 ~71 ~4 ~127 coal_ore 0  
fill ~72 ~0 ~62 ~100 ~0 ~62 stone 0  
fill ~72 ~0 ~87 ~72 ~0 ~87 dirt 0  
fill ~72 ~0 ~88 ~104 ~0 ~88 stone 0  
fill ~72 ~0 ~96 ~101 ~0 ~96 stone 0  
fill ~72 ~0 ~100 ~72 ~0 ~100 dirt 0  
fill ~72 ~0 ~127 ~96 ~0 ~127 stone 0  
fill ~72 ~0 ~128 ~95 ~0 ~128 stone 0  
fill ~72 ~0 ~129 ~77 ~0 ~129 stone 0 
setblock ~73 ~0 ~37 coal_ore 0  
fill ~73 ~0 ~87 ~104 ~0 ~87 stone 0  
fill ~73 ~0 ~97 ~74 ~0 ~97 lapis_ore 0  
fill ~73 ~0 ~99 ~77 ~0 ~99 stone 0  
fill ~73 ~0 ~100 ~74 ~0 ~100 stone 0  
fill ~73 ~0 ~101 ~73 ~1 ~101 dirt 0  
fill ~74 ~0 ~36 ~74 ~1 ~36 coal_ore 0  
fill ~74 ~0 ~37 ~128 ~0 ~37 stone 0  
fill ~74 ~0 ~50 ~75 ~0 ~50 dirt 0  
fill ~74 ~0 ~98 ~107 ~0 ~98 stone 0  
fill ~74 ~0 ~101 ~76 ~0 ~101 leaves 0 
setblock ~75 ~0 ~3 grass 0  
fill ~75 ~0 ~24 ~75 ~0 ~25 iron_ore 0  
fill ~75 ~0 ~36 ~128 ~0 ~36 stone 0  
fill ~75 ~0 ~97 ~101 ~0 ~97 stone 0 
setblock ~75 ~0 ~100 leaves 0 
setblock ~75 ~0 ~102 leaves 0  
fill ~76 ~0 ~3 ~76 ~0 ~3 dirt 0  
fill ~76 ~0 ~24 ~123 ~0 ~24 stone 0  
fill ~76 ~0 ~25 ~107 ~0 ~25 stone 0  
fill ~76 ~0 ~50 ~86 ~0 ~50 stone 0  
fill ~76 ~0 ~100 ~76 ~1 ~100 stone 0  
fill ~76 ~0 ~102 ~106 ~0 ~102 stone 0  
fill ~76 ~0 ~111 ~77 ~0 ~111 coal_ore 0  
fill ~76 ~0 ~140 ~76 ~1 ~140 dirt 0  
fill ~77 ~0 ~3 ~82 ~0 ~3 stone 0  
fill ~77 ~0 ~100 ~78 ~0 ~100 leaves 0 
setblock ~77 ~0 ~101 stone 0  
fill ~77 ~0 ~105 ~77 ~12 ~105 dirt 0 
setblock ~77 ~0 ~110 coal_ore 0  
fill ~77 ~0 ~130 ~79 ~0 ~130 iron_ore 0  
fill ~78 ~0 ~10 ~79 ~0 ~10 coal_ore 0 
setblock ~78 ~0 ~99 leaves 0 
setblock ~78 ~0 ~101 leaves 0  
fill ~78 ~0 ~105 ~79 ~0 ~105 stone 0  
fill ~78 ~0 ~106 ~78 ~0 ~106 dirt 0 
setblock ~78 ~0 ~107 iron_ore 0  
fill ~78 ~0 ~110 ~80 ~0 ~110 stone 0  
fill ~78 ~0 ~111 ~81 ~0 ~111 stone 0  
fill ~78 ~0 ~129 ~79 ~0 ~129 iron_ore 0 
setblock ~78 ~0 ~131 iron_ore 0 
setblock ~78 ~0 ~133 iron_ore 0 
setblock ~79 ~0 ~9 coal_ore 0  
fill ~79 ~0 ~99 ~107 ~0 ~99 stone 0  
fill ~79 ~0 ~100 ~86 ~0 ~100 stone 0  
fill ~79 ~0 ~101 ~86 ~0 ~101 stone 0  
fill ~79 ~0 ~106 ~104 ~0 ~106 stone 0  
fill ~79 ~0 ~107 ~86 ~0 ~107 stone 0  
fill ~79 ~0 ~131 ~97 ~0 ~131 stone 0  
fill ~79 ~0 ~133 ~95 ~0 ~133 stone 0  
fill ~80 ~0 ~2 ~81 ~0 ~2 dirt 0  
fill ~80 ~0 ~9 ~125 ~0 ~9 stone 0  
fill ~80 ~0 ~10 ~127 ~0 ~10 stone 0 
setblock ~80 ~0 ~105 leaves 2  
fill ~80 ~0 ~129 ~96 ~0 ~129 stone 0  
fill ~80 ~0 ~130 ~97 ~0 ~130 stone 0  
fill ~81 ~0 ~49 ~83 ~0 ~49 dirt 0  
fill ~81 ~0 ~105 ~93 ~0 ~105 stone 0  
fill ~81 ~0 ~110 ~81 ~0 ~110 dirt 0  
fill ~81 ~0 ~139 ~81 ~0 ~139 dirt 0 
setblock ~82 ~0 ~2 stone 0  
fill ~82 ~0 ~16 ~82 ~0 ~17 coal_ore 0  
fill ~82 ~0 ~53 ~85 ~0 ~53 dirt 0  
fill ~82 ~0 ~57 ~85 ~0 ~57 leaves 0  
fill ~82 ~0 ~110 ~85 ~0 ~110 stone 0  
fill ~82 ~0 ~111 ~82 ~7 ~111 dirt 0  
fill ~82 ~0 ~113 ~82 ~0 ~113 dirt 0  
fill ~83 ~0 ~2 ~87 ~0 ~2 gravel 0  
fill ~83 ~0 ~3 ~87 ~0 ~3 gravel 0  
fill ~83 ~0 ~4 ~87 ~0 ~4 gravel 0  
fill ~83 ~0 ~16 ~127 ~0 ~16 stone 0  
fill ~83 ~0 ~17 ~83 ~1 ~17 coal_ore 0  
fill ~83 ~0 ~18 ~83 ~0 ~17 coal_ore 0  
fill ~83 ~0 ~54 ~92 ~0 ~54 stone 0  
fill ~83 ~0 ~56 ~84 ~0 ~56 leaves 0  
fill ~83 ~0 ~111 ~87 ~0 ~111 stone 0 
setblock ~83 ~0 ~115 grass 0  
fill ~83 ~0 ~138 ~83 ~0 ~138 dirt 0  
fill ~84 ~0 ~5 ~87 ~0 ~5 gravel 0  
fill ~84 ~0 ~6 ~87 ~0 ~6 gravel 0  
fill ~84 ~0 ~17 ~127 ~0 ~17 stone 0  
fill ~84 ~0 ~18 ~127 ~0 ~18 stone 0  
fill ~84 ~0 ~49 ~87 ~0 ~49 stone 0  
fill ~85 ~0 ~7 ~87 ~0 ~7 gravel 0  
fill ~85 ~0 ~48 ~89 ~0 ~48 dirt 0  
fill ~85 ~0 ~56 ~89 ~0 ~56 stone 0  
fill ~85 ~0 ~109 ~91 ~0 ~109 leaves 2  
fill ~85 ~0 ~121 ~85 ~0 ~121 dirt 0  
fill ~86 ~0 ~8 ~86 ~1 ~8 gravel 0  
fill ~86 ~0 ~53 ~97 ~0 ~53 stone 0  
fill ~86 ~0 ~57 ~90 ~0 ~57 stone 0  
fill ~86 ~0 ~108 ~90 ~0 ~108 leaves 2  
fill ~86 ~0 ~110 ~90 ~0 ~110 leaves 2  
fill ~86 ~0 ~112 ~86 ~0 ~112 dirt 0  
fill ~86 ~0 ~137 ~93 ~0 ~137 stone 0  
fill ~87 ~0 ~8 ~125 ~0 ~8 stone 0  
fill ~87 ~0 ~50 ~87 ~3 ~50 log 0  
fill ~87 ~0 ~100 ~87 ~1 ~100 coal_ore 0  
fill ~87 ~0 ~101 ~87 ~0 ~100 coal_ore 0 
setblock ~87 ~0 ~107 leaves 2  
fill ~87 ~0 ~112 ~87 ~2 ~112 stone 0  
fill ~87 ~0 ~138 ~94 ~0 ~138 stone 0  
fill ~88 ~0 ~2 ~88 ~0 ~2 dirt 0  
fill ~88 ~0 ~3 ~90 ~0 ~3 stone 0  
fill ~88 ~0 ~4 ~92 ~0 ~4 stone 0  
fill ~88 ~0 ~5 ~96 ~0 ~5 stone 0  
fill ~88 ~0 ~6 ~111 ~0 ~6 stone 0  
fill ~88 ~0 ~7 ~125 ~0 ~7 stone 0  
fill ~88 ~0 ~49 ~89 ~0 ~49 dirt 0  
fill ~88 ~0 ~50 ~119 ~0 ~50 stone 0  
fill ~88 ~0 ~100 ~89 ~0 ~100 stone 0  
fill ~88 ~0 ~101 ~89 ~0 ~101 stone 0  
fill ~88 ~0 ~107 ~103 ~0 ~107 stone 0  
fill ~88 ~0 ~111 ~88 ~1 ~111 leaves 2  
fill ~89 ~0 ~111 ~90 ~0 ~111 stone 0  
fill ~89 ~0 ~112 ~89 ~0 ~111 stone 0  
fill ~89 ~0 ~123 ~89 ~14 ~123 stone 0  
fill ~89 ~0 ~139 ~93 ~0 ~139 stone 0  
fill ~90 ~0 ~48 ~90 ~0 ~54 stone 0  
fill ~90 ~0 ~55 ~94 ~0 ~55 dirt 0  
fill ~90 ~0 ~56 ~94 ~0 ~56 dirt 0  
fill ~90 ~0 ~100 ~90 ~0 ~101 lapis_ore 0  
fill ~90 ~0 ~140 ~90 ~8 ~140 stone 0 
setblock ~91 ~0 ~48 iron_ore 0  
fill ~91 ~0 ~49 ~128 ~0 ~49 stone 0  
fill ~91 ~0 ~57 ~94 ~0 ~57 dirt 0  
fill ~91 ~0 ~100 ~107 ~0 ~100 stone 0 
setblock ~91 ~0 ~101 lapis_ore 0  
fill ~91 ~0 ~108 ~102 ~0 ~108 stone 0  
fill ~91 ~0 ~110 ~93 ~0 ~110 stone 0  
fill ~91 ~0 ~111 ~92 ~0 ~111 leaves 0  
fill ~92 ~0 ~48 ~128 ~0 ~48 stone 0  
fill ~92 ~0 ~101 ~101 ~0 ~101 stone 0  
summon Sheep ~9.2389030301 ~0.0 ~31.9782492303 
summon Sheep ~3.36428090881 ~0.0 ~40.4906124471 
summon Sheep ~4.58306531051 ~0.0 ~48.0188095481 
summon Sheep ~5.06831901494 ~0.0 ~42.1055130616 
summon Sheep ~18.9302945417 ~0.0 ~14.8771273463 
summon Squid ~27.4644610756 ~0.5 ~87.474999994 
summon Squid ~22.782843355 ~0.5 ~92.525000006 
summon Squid ~26.6921260978 ~0.5 ~92.3644957265 
summon Squid ~27.2904427344 ~0.5 ~95.474999994 
summon Squid ~22.6097149625 ~0.5 ~95.5439734198 
summon Squid ~22.7287939395 ~0.5 ~100.525000006 
summon Squid ~27.2106421497 ~0.5 ~103.904078843 
summon Squid ~22.8187917676 ~0.5 ~104.469459197 
summon Pig ~131.524564053 ~0.0 ~94.4067842743 
summon Pig ~132.900016592 ~0.0 ~98.8875928329  
fill ~92 ~0 ~109 ~93 ~0 ~109 stone 0  
fill ~93 ~0 ~4 ~93 ~0 ~4 dirt 0  
fill ~93 ~0 ~54 ~94 ~0 ~54 dirt 0  
fill ~93 ~0 ~111 ~98 ~0 ~111 stone 0  
fill ~93 ~0 ~112 ~95 ~0 ~112 stone 0  
fill ~93 ~0 ~123 ~93 ~15 ~123 stone 0  
fill ~93 ~0 ~125 ~95 ~0 ~125 stone 0  
fill ~94 ~0 ~105 ~95 ~0 ~105 redstone_ore 0  
fill ~94 ~0 ~109 ~94 ~1 ~109 lapis_ore 0 
setblock ~94 ~0 ~110 coal_ore 0  
fill ~94 ~0 ~124 ~94 ~15 ~124 stone 0 
setblock ~95 ~0 ~28 coal_ore 0  
fill ~95 ~0 ~54 ~99 ~0 ~54 stone 0  
fill ~95 ~0 ~55 ~100 ~0 ~55 stone 0  
fill ~95 ~0 ~56 ~100 ~0 ~56 stone 0  
fill ~95 ~0 ~57 ~100 ~0 ~57 stone 0  
fill ~95 ~0 ~109 ~101 ~0 ~109 stone 0  
fill ~95 ~0 ~110 ~99 ~0 ~110 stone 0  
fill ~96 ~0 ~28 ~110 ~0 ~28 stone 0  
fill ~96 ~0 ~72 ~96 ~1 ~72 lapis_ore 0  
fill ~96 ~0 ~73 ~96 ~1 ~73 lapis_ore 0  
fill ~96 ~0 ~105 ~105 ~0 ~105 stone 0  
fill ~97 ~0 ~5 ~98 ~0 ~5 dirt 0  
fill ~97 ~0 ~72 ~114 ~0 ~72 stone 0  
fill ~97 ~0 ~73 ~113 ~0 ~73 stone 0  
fill ~98 ~0 ~53 ~99 ~0 ~53 dirt 0  
fill ~99 ~0 ~4 ~108 ~0 ~4 stone 0  
fill ~99 ~0 ~5 ~109 ~0 ~5 stone 0  
fill ~99 ~0 ~111 ~99 ~1 ~111 dirt 0  
fill ~100 ~0 ~3 ~107 ~0 ~3 stone 0 
setblock ~100 ~0 ~53 stone 0  
fill ~100 ~0 ~54 ~101 ~0 ~54 leaves 0  
fill ~101 ~0 ~2 ~107 ~0 ~2 stone 0  
fill ~101 ~0 ~53 ~101 ~2 ~53 log 0  
fill ~101 ~0 ~55 ~102 ~0 ~55 grass 0  
fill ~101 ~0 ~56 ~127 ~0 ~56 dirt 0  
fill ~101 ~0 ~57 ~132 ~0 ~57 dirt 0  
fill ~101 ~0 ~58 ~132 ~0 ~58 dirt 0  
fill ~101 ~0 ~59 ~132 ~0 ~59 dirt 0  
fill ~101 ~0 ~60 ~113 ~0 ~60 dirt 0  
fill ~101 ~0 ~61 ~113 ~0 ~61 dirt 0  
fill ~101 ~0 ~62 ~132 ~0 ~62 dirt 0  
fill ~101 ~0 ~63 ~132 ~0 ~63 dirt 0  
fill ~101 ~0 ~64 ~132 ~0 ~64 dirt 0  
fill ~101 ~0 ~65 ~132 ~0 ~65 dirt 0  
fill ~102 ~0 ~1 ~106 ~0 ~1 stone 0  
fill ~102 ~0 ~52 ~102 ~0 ~52 dirt 0  
fill ~102 ~0 ~53 ~102 ~5 ~53 leaves 0  
fill ~102 ~0 ~54 ~103 ~0 ~54 grass 0  
fill ~102 ~0 ~96 ~103 ~0 ~96 lapis_ore 0  
fill ~102 ~0 ~97 ~102 ~1 ~97 lapis_ore 0  
fill ~102 ~0 ~101 ~103 ~0 ~101 redstone_ore 0 
setblock ~103 ~0 ~52 leaves 0  
fill ~103 ~0 ~53 ~108 ~0 ~53 dirt 0  
fill ~103 ~0 ~55 ~103 ~1 ~55 leaves 0  
fill ~103 ~0 ~97 ~107 ~0 ~97 stone 0  
fill ~104 ~0 ~51 ~104 ~1 ~51 dirt 0  
fill ~104 ~0 ~52 ~104 ~0 ~52 dirt 0  
fill ~104 ~0 ~54 ~104 ~1 ~54 leaves 0  
fill ~104 ~0 ~55 ~110 ~0 ~55 dirt 0  
fill ~104 ~0 ~96 ~107 ~0 ~96 stone 0  
fill ~104 ~0 ~101 ~107 ~0 ~101 stone 0  
fill ~105 ~0 ~51 ~117 ~0 ~51 stone 0  
fill ~105 ~0 ~54 ~108 ~0 ~54 dirt 0  
fill ~106 ~0 ~52 ~107 ~0 ~52 dirt 0  
fill ~106 ~0 ~66 ~132 ~0 ~66 dirt 0  
fill ~106 ~0 ~91 ~106 ~2 ~91 dirt 0 
setblock ~107 ~0 ~1 grass 0  
fill ~108 ~0 ~2 ~112 ~0 ~2 grass 0  
fill ~108 ~0 ~3 ~108 ~1 ~3 dirt 0  
fill ~108 ~0 ~25 ~108 ~3 ~25 coal_ore 0  
fill ~108 ~0 ~26 ~108 ~0 ~25 coal_ore 0  
fill ~108 ~0 ~52 ~116 ~0 ~52 stone 0  
fill ~108 ~0 ~67 ~131 ~0 ~67 dirt 0  
fill ~109 ~0 ~3 ~110 ~0 ~3 grass 0  
fill ~109 ~0 ~4 ~113 ~0 ~4 dirt 0  
fill ~109 ~0 ~25 ~127 ~0 ~25 stone 0  
fill ~109 ~0 ~26 ~128 ~0 ~26 stone 0  
fill ~109 ~0 ~53 ~116 ~0 ~53 stone 0  
fill ~109 ~0 ~54 ~119 ~0 ~54 stone 0  
fill ~110 ~0 ~5 ~112 ~0 ~5 dirt 0  
fill ~111 ~0 ~3 ~114 ~0 ~3 dirt 0  
fill ~111 ~0 ~28 ~111 ~0 ~29 iron_ore 0  
fill ~111 ~0 ~55 ~112 ~0 ~55 stone 0 
setblock ~111 ~0 ~68 grass 0  
fill ~112 ~0 ~6 ~112 ~1 ~6 dirt 0  
fill ~112 ~0 ~28 ~127 ~0 ~28 stone 0  
fill ~112 ~0 ~29 ~127 ~0 ~29 stone 0  
fill ~112 ~0 ~68 ~129 ~0 ~68 dirt 0  
fill ~113 ~0 ~2 ~116 ~0 ~2 dirt 0  
fill ~113 ~0 ~5 ~125 ~0 ~5 stone 0  
fill ~113 ~0 ~6 ~125 ~0 ~6 stone 0  
fill ~113 ~0 ~55 ~117 ~0 ~55 dirt 0  
fill ~113 ~0 ~69 ~127 ~0 ~69 dirt 0  
fill ~113 ~0 ~71 ~122 ~0 ~71 dirt 0  
fill ~113 ~0 ~77 ~113 ~0 ~78 grass 0  
fill ~114 ~0 ~1 ~116 ~0 ~1 grass 0  
fill ~114 ~0 ~4 ~124 ~0 ~4 stone 0  
fill ~114 ~0 ~60 ~115 ~0 ~60 grass 0  
fill ~114 ~0 ~61 ~114 ~0 ~60 grass 0  
fill ~114 ~0 ~70 ~123 ~0 ~70 dirt 0  
fill ~114 ~0 ~73 ~122 ~0 ~73 grass 0  
fill ~115 ~0 ~3 ~122 ~0 ~3 stone 0  
fill ~115 ~0 ~61 ~132 ~0 ~61 dirt 0  
fill ~115 ~0 ~72 ~119 ~0 ~72 dirt 0  
fill ~116 ~0 ~60 ~132 ~0 ~60 dirt 0  
fill ~117 ~0 ~1 ~119 ~0 ~1 dirt 0  
fill ~117 ~0 ~2 ~118 ~0 ~2 stone 0  
fill ~117 ~0 ~52 ~120 ~0 ~52 dirt 0  
fill ~117 ~0 ~53 ~119 ~0 ~53 dirt 0  
fill ~118 ~0 ~51 ~120 ~0 ~51 dirt 0  
fill ~118 ~0 ~55 ~119 ~0 ~55 grass 0  
fill ~119 ~0 ~2 ~121 ~0 ~2 dirt 0  
fill ~120 ~0 ~50 ~121 ~0 ~50 dirt 0  
fill ~120 ~0 ~53 ~128 ~0 ~53 stone 0  
fill ~120 ~0 ~54 ~120 ~0 ~54 dirt 0  
fill ~120 ~0 ~55 ~120 ~6 ~55 stone 0  
fill ~120 ~0 ~72 ~122 ~0 ~72 grass 0  
fill ~121 ~0 ~51 ~128 ~0 ~51 stone 0  
fill ~121 ~0 ~52 ~128 ~0 ~52 stone 0  
fill ~121 ~0 ~54 ~121 ~6 ~54 stone 0  
fill ~121 ~0 ~55 ~125 ~0 ~55 dirt 0 
setblock ~122 ~0 ~2 grass 0  
fill ~122 ~0 ~50 ~128 ~0 ~50 stone 0  
fill ~122 ~0 ~54 ~125 ~0 ~54 dirt 0  
fill ~123 ~0 ~3 ~123 ~2 ~3 dirt 0  
fill ~123 ~0 ~21 ~123 ~4 ~21 dirt 0  
fill ~123 ~0 ~23 ~123 ~4 ~23 dirt 0  
fill ~123 ~0 ~71 ~131 ~0 ~71 grass 0  
fill ~124 ~0 ~21 ~127 ~0 ~21 stone 0  
fill ~124 ~0 ~22 ~124 ~4 ~22 dirt 0  
fill ~124 ~0 ~23 ~127 ~0 ~23 stone 0  
fill ~124 ~0 ~24 ~124 ~4 ~24 dirt 0  
fill ~124 ~0 ~70 ~128 ~0 ~70 stone 0 
setblock ~125 ~0 ~4 grass 0  
fill ~125 ~0 ~22 ~127 ~0 ~22 stone 0  
fill ~125 ~0 ~24 ~127 ~0 ~24 stone 0  
fill ~126 ~0 ~6 ~126 ~2 ~6 dirt 0  
fill ~126 ~0 ~7 ~127 ~0 ~7 dirt 0  
fill ~126 ~0 ~8 ~127 ~0 ~8 dirt 0  
fill ~126 ~0 ~9 ~127 ~0 ~9 dirt 0  
fill ~126 ~0 ~33 ~127 ~0 ~33 iron_ore 0  
fill ~126 ~0 ~55 ~126 ~2 ~55 leaves 0  
fill ~127 ~0 ~11 ~128 ~0 ~11 dirt 0  
fill ~127 ~0 ~54 ~127 ~0 ~54 dirt 0  
fill ~128 ~0 ~7 ~128 ~0 ~9 grass 0  
fill ~128 ~0 ~10 ~128 ~0 ~10 dirt 0  
fill ~128 ~0 ~13 ~129 ~0 ~13 dirt 0  
fill ~128 ~0 ~14 ~129 ~0 ~14 dirt 0  
fill ~128 ~0 ~16 ~129 ~0 ~16 dirt 0  
fill ~128 ~0 ~17 ~129 ~0 ~17 dirt 0  
fill ~128 ~0 ~18 ~129 ~0 ~18 dirt 0  
fill ~128 ~0 ~19 ~129 ~0 ~19 dirt 0  
fill ~128 ~0 ~20 ~129 ~0 ~20 dirt 0  
fill ~128 ~0 ~21 ~129 ~0 ~21 dirt 0  
fill ~128 ~0 ~22 ~129 ~0 ~22 dirt 0  
fill ~128 ~0 ~23 ~129 ~0 ~23 dirt 0  
fill ~128 ~0 ~24 ~129 ~0 ~24 dirt 0  
fill ~128 ~0 ~25 ~129 ~0 ~25 dirt 0  
fill ~128 ~0 ~28 ~129 ~0 ~28 dirt 0  
fill ~128 ~0 ~29 ~129 ~0 ~29 dirt 0  
fill ~128 ~0 ~30 ~129 ~0 ~30 dirt 0  
fill ~128 ~0 ~31 ~130 ~0 ~31 dirt 0  
fill ~128 ~0 ~32 ~130 ~0 ~32 dirt 0  
fill ~128 ~0 ~33 ~130 ~0 ~33 dirt 0  
fill ~128 ~0 ~34 ~130 ~0 ~34 dirt 0 
setblock ~128 ~0 ~41 coal_ore 0 
setblock ~128 ~0 ~54 grass 0  
fill ~128 ~0 ~56 ~128 ~3 ~56 leaves 0  
fill ~128 ~0 ~69 ~128 ~1 ~69 stone 0  
fill ~129 ~0 ~10 ~129 ~0 ~11 grass 0  
fill ~129 ~0 ~12 ~129 ~0 ~12 dirt 0  
fill ~129 ~0 ~15 ~129 ~1 ~15 dirt 0  
fill ~129 ~0 ~26 ~129 ~0 ~26 dirt 0  
fill ~129 ~0 ~27 ~129 ~0 ~27 dirt 0  
fill ~129 ~0 ~35 ~131 ~0 ~35 dirt 0  
fill ~129 ~0 ~36 ~131 ~0 ~36 dirt 0  
fill ~129 ~0 ~37 ~132 ~0 ~37 dirt 0  
fill ~129 ~0 ~38 ~132 ~0 ~38 dirt 0  
fill ~129 ~0 ~39 ~133 ~0 ~39 dirt 0  
fill ~129 ~0 ~40 ~133 ~0 ~40 dirt 0  
fill ~129 ~0 ~41 ~133 ~0 ~41 dirt 0  
fill ~129 ~0 ~42 ~133 ~0 ~42 dirt 0  
fill ~129 ~0 ~43 ~133 ~0 ~43 dirt 0  
fill ~129 ~0 ~44 ~133 ~0 ~44 dirt 0  
fill ~129 ~0 ~45 ~134 ~0 ~45 dirt 0  
fill ~129 ~0 ~46 ~134 ~0 ~46 dirt 0  
fill ~129 ~0 ~47 ~134 ~0 ~47 dirt 0  
fill ~129 ~0 ~48 ~134 ~0 ~48 dirt 0  
fill ~129 ~0 ~49 ~132 ~0 ~49 dirt 0  
fill ~129 ~0 ~50 ~132 ~0 ~50 dirt 0  
fill ~129 ~0 ~51 ~132 ~0 ~51 dirt 0  
fill ~129 ~0 ~52 ~134 ~0 ~52 dirt 0  
fill ~129 ~0 ~53 ~133 ~0 ~53 dirt 0  
fill ~129 ~0 ~54 ~133 ~0 ~54 dirt 0  
fill ~129 ~0 ~55 ~133 ~0 ~55 dirt 0  
fill ~129 ~0 ~56 ~134 ~0 ~56 dirt 0  
fill ~129 ~0 ~69 ~132 ~0 ~69 dirt 0  
fill ~129 ~0 ~70 ~131 ~0 ~70 dirt 0  
fill ~130 ~0 ~12 ~130 ~0 ~30 grass 0  
fill ~130 ~0 ~68 ~132 ~0 ~68 stone 0  
fill ~131 ~0 ~31 ~131 ~0 ~34 grass 0  
fill ~132 ~0 ~33 ~132 ~0 ~36 grass 0  
fill ~132 ~0 ~67 ~133 ~0 ~67 stone 0  
fill ~132 ~0 ~70 ~134 ~0 ~70 grass 0  
fill ~133 ~0 ~36 ~134 ~0 ~36 grass 0  
fill ~133 ~0 ~37 ~134 ~0 ~37 grass 0  
fill ~133 ~0 ~38 ~134 ~0 ~38 grass 0  
fill ~133 ~0 ~49 ~133 ~0 ~51 stone 0  
fill ~133 ~0 ~57 ~133 ~0 ~58 stone 0 
setblock ~133 ~0 ~59 coal_ore 0  
fill ~133 ~0 ~60 ~133 ~0 ~67 stone 0  
fill ~133 ~0 ~68 ~133 ~0 ~68 dirt 0  
fill ~133 ~0 ~69 ~134 ~0 ~69 grass 0  
fill ~134 ~0 ~39 ~134 ~0 ~44 grass 0  
fill ~134 ~0 ~49 ~134 ~0 ~49 dirt 0  
fill ~134 ~0 ~50 ~134 ~0 ~50 dirt 0  
fill ~134 ~0 ~51 ~134 ~0 ~51 dirt 0  
fill ~134 ~0 ~53 ~134 ~0 ~55 grass 0  
fill ~134 ~0 ~57 ~134 ~0 ~57 dirt 0  
fill ~134 ~0 ~58 ~134 ~0 ~58 dirt 0  
fill ~134 ~0 ~59 ~134 ~0 ~59 dirt 0  
fill ~134 ~0 ~60 ~134 ~0 ~60 dirt 0  
fill ~134 ~0 ~61 ~134 ~0 ~61 dirt 0  
fill ~134 ~0 ~62 ~134 ~0 ~62 dirt 0  
fill ~134 ~0 ~63 ~134 ~0 ~63 dirt 0  
fill ~134 ~0 ~64 ~134 ~0 ~64 dirt 0  
fill ~134 ~0 ~65 ~134 ~0 ~65 dirt 0  
fill ~134 ~0 ~66 ~134 ~0 ~66 dirt 0  
fill ~134 ~0 ~67 ~134 ~0 ~67 dirt 0 
setblock ~134 ~0 ~68 grass 0  
fill ~2 ~1 ~97 ~5 ~1 ~97 grass 0  
fill ~2 ~1 ~98 ~4 ~1 ~98 grass 0  
fill ~2 ~1 ~99 ~2 ~1 ~102 grass 0  
fill ~3 ~1 ~94 ~6 ~1 ~94 grass 0  
fill ~3 ~1 ~95 ~6 ~1 ~95 grass 0  
fill ~3 ~1 ~96 ~5 ~1 ~96 grass 0  
fill ~3 ~1 ~99 ~7 ~1 ~99 dirt 0  
fill ~3 ~1 ~100 ~7 ~1 ~100 dirt 0  
fill ~3 ~1 ~101 ~7 ~1 ~101 dirt 0  
fill ~3 ~1 ~102 ~3 ~1 ~103 grass 0  
fill ~4 ~1 ~70 ~8 ~1 ~70 stone 0  
fill ~4 ~1 ~71 ~8 ~1 ~71 stone 0  
fill ~4 ~1 ~72 ~8 ~1 ~72 stone 0  
fill ~4 ~1 ~73 ~8 ~1 ~73 stone 0  
fill ~4 ~1 ~74 ~7 ~1 ~74 stone 0  
fill ~4 ~1 ~89 ~6 ~1 ~89 grass 0  
fill ~4 ~1 ~90 ~6 ~1 ~90 grass 0  
fill ~4 ~1 ~91 ~5 ~1 ~91 grass 0  
fill ~4 ~1 ~92 ~5 ~1 ~92 grass 0  
fill ~4 ~1 ~93 ~5 ~1 ~93 grass 0  
fill ~4 ~1 ~102 ~9 ~1 ~102 dirt 0  
fill ~4 ~1 ~103 ~10 ~1 ~103 dirt 0  
fill ~4 ~1 ~104 ~4 ~1 ~105 grass 0 
setblock ~5 ~1 ~68 grass 0  
fill ~5 ~1 ~69 ~7 ~1 ~69 stone 0  
fill ~5 ~1 ~75 ~8 ~1 ~75 stone 0  
fill ~5 ~1 ~76 ~9 ~1 ~76 stone 0  
fill ~5 ~1 ~77 ~18 ~1 ~77 stone 0  
fill ~5 ~1 ~78 ~17 ~1 ~78 stone 0  
fill ~5 ~1 ~88 ~6 ~1 ~88 grass 0  
fill ~5 ~1 ~98 ~6 ~1 ~98 dirt 0  
fill ~5 ~1 ~104 ~10 ~1 ~104 dirt 0  
fill ~5 ~1 ~105 ~5 ~1 ~106 grass 0 
setblock ~6 ~1 ~68 dirt 0  
fill ~6 ~1 ~84 ~8 ~1 ~84 grass 0  
fill ~6 ~1 ~85 ~7 ~1 ~85 grass 0  
fill ~6 ~1 ~86 ~7 ~1 ~86 grass 0  
fill ~6 ~1 ~87 ~6 ~1 ~84 grass 0  
fill ~6 ~1 ~91 ~8 ~1 ~91 dirt 0  
fill ~6 ~1 ~92 ~6 ~1 ~93 dirt 0 
setblock ~6 ~1 ~96 dirt 0  
fill ~6 ~1 ~97 ~14 ~1 ~97 stone 0  
fill ~6 ~1 ~105 ~12 ~1 ~105 dirt 0  
fill ~6 ~1 ~106 ~13 ~1 ~106 dirt 0  
fill ~6 ~1 ~107 ~6 ~1 ~108 grass 0 
setblock ~7 ~1 ~68 grass 0  
fill ~7 ~1 ~79 ~17 ~1 ~79 stone 0  
fill ~7 ~1 ~80 ~7 ~5 ~80 stone 0  
fill ~7 ~1 ~81 ~7 ~1 ~86 grass 0  
fill ~7 ~1 ~87 ~7 ~1 ~91 dirt 0  
fill ~7 ~1 ~92 ~13 ~1 ~92 stone 0  
fill ~7 ~1 ~93 ~8 ~1 ~93 dirt 0  
fill ~7 ~1 ~94 ~7 ~1 ~93 dirt 0  
fill ~7 ~1 ~95 ~13 ~1 ~95 stone 0  
fill ~7 ~1 ~96 ~13 ~1 ~96 stone 0  
fill ~7 ~1 ~98 ~14 ~1 ~98 stone 0  
fill ~7 ~1 ~107 ~13 ~1 ~107 dirt 0  
fill ~7 ~1 ~108 ~7 ~1 ~109 grass 0  
fill ~7 ~1 ~117 ~7 ~1 ~121 grass 0  
fill ~8 ~1 ~74 ~9 ~1 ~74 dirt 0  
fill ~8 ~1 ~80 ~8 ~1 ~82 dirt 0 
setblock ~8 ~1 ~83 grass 0  
fill ~8 ~1 ~85 ~8 ~1 ~86 dirt 0  
fill ~8 ~1 ~87 ~8 ~2 ~87 stone 0  
fill ~8 ~1 ~88 ~8 ~2 ~88 stone 0  
fill ~8 ~1 ~89 ~8 ~1 ~91 dirt 0  
fill ~8 ~1 ~94 ~12 ~1 ~94 stone 0  
fill ~8 ~1 ~99 ~14 ~1 ~99 stone 0  
fill ~8 ~1 ~100 ~14 ~1 ~100 stone 0  
fill ~8 ~1 ~101 ~14 ~1 ~101 stone 0  
fill ~8 ~1 ~108 ~13 ~1 ~108 dirt 0 
setblock ~8 ~1 ~109 grass 0  
fill ~8 ~1 ~114 ~8 ~1 ~116 grass 0  
fill ~8 ~1 ~117 ~15 ~1 ~117 dirt 0  
fill ~8 ~1 ~118 ~14 ~1 ~118 dirt 0  
fill ~8 ~1 ~119 ~14 ~1 ~119 dirt 0  
fill ~8 ~1 ~120 ~13 ~1 ~120 dirt 0  
fill ~8 ~1 ~121 ~13 ~1 ~121 dirt 0 
setblock ~8 ~1 ~122 grass 0  
fill ~9 ~1 ~73 ~9 ~2 ~73 dirt 0  
fill ~9 ~1 ~75 ~9 ~3 ~75 dirt 0  
fill ~9 ~1 ~80 ~17 ~1 ~80 stone 0  
fill ~9 ~1 ~81 ~9 ~1 ~84 dirt 0  
fill ~9 ~1 ~85 ~19 ~1 ~85 stone 0  
fill ~9 ~1 ~86 ~10 ~1 ~86 dirt 0  
fill ~9 ~1 ~87 ~9 ~1 ~86 dirt 0  
fill ~9 ~1 ~89 ~15 ~1 ~89 stone 0  
fill ~9 ~1 ~90 ~14 ~1 ~90 stone 0  
fill ~9 ~1 ~91 ~14 ~1 ~91 stone 0  
fill ~9 ~1 ~93 ~12 ~1 ~93 stone 0  
fill ~9 ~1 ~109 ~11 ~1 ~109 dirt 0  
fill ~9 ~1 ~110 ~9 ~1 ~113 grass 0  
fill ~9 ~1 ~114 ~15 ~1 ~114 dirt 0  
fill ~9 ~1 ~115 ~16 ~1 ~115 dirt 0  
fill ~9 ~1 ~116 ~15 ~1 ~116 dirt 0 
setblock ~9 ~1 ~122 dirt 0 
setblock ~9 ~1 ~123 grass 0 
setblock ~10 ~1 ~76 dirt 0  
fill ~10 ~1 ~81 ~18 ~1 ~81 stone 0  
fill ~10 ~1 ~82 ~10 ~5 ~82 dirt 0  
fill ~10 ~1 ~83 ~18 ~1 ~83 stone 0  
fill ~10 ~1 ~84 ~11 ~1 ~84 dirt 0  
fill ~10 ~1 ~87 ~16 ~1 ~87 stone 0  
fill ~10 ~1 ~88 ~15 ~1 ~88 stone 0  
fill ~10 ~1 ~102 ~14 ~1 ~102 stone 0  
fill ~10 ~1 ~110 ~13 ~1 ~110 dirt 0  
fill ~10 ~1 ~111 ~11 ~1 ~111 dirt 0  
fill ~10 ~1 ~112 ~13 ~1 ~112 dirt 0  
fill ~10 ~1 ~113 ~13 ~1 ~113 dirt 0  
fill ~10 ~1 ~124 ~12 ~1 ~124 stone 0  
fill ~10 ~1 ~125 ~57 ~1 ~125 stone 0  
fill ~10 ~1 ~126 ~15 ~1 ~126 stone 0  
fill ~10 ~1 ~127 ~16 ~1 ~127 stone 0  
fill ~10 ~1 ~128 ~32 ~1 ~128 stone 0  
fill ~11 ~1 ~66 ~23 ~1 ~66 stone 0  
fill ~11 ~1 ~67 ~23 ~1 ~67 stone 0  
fill ~11 ~1 ~68 ~12 ~1 ~68 stone 0  
fill ~11 ~1 ~69 ~15 ~1 ~69 stone 0  
fill ~11 ~1 ~70 ~16 ~1 ~70 stone 0  
fill ~11 ~1 ~82 ~18 ~1 ~82 stone 0  
fill ~11 ~1 ~86 ~17 ~1 ~86 stone 0  
fill ~11 ~1 ~103 ~15 ~1 ~103 stone 0  
fill ~11 ~1 ~104 ~15 ~1 ~104 stone 0  
fill ~11 ~1 ~122 ~12 ~1 ~122 dirt 0  
fill ~11 ~1 ~123 ~87 ~1 ~123 stone 0  
fill ~11 ~1 ~129 ~32 ~1 ~129 stone 0  
fill ~11 ~1 ~130 ~32 ~1 ~130 stone 0  
fill ~11 ~1 ~131 ~33 ~1 ~131 stone 0  
fill ~11 ~1 ~132 ~62 ~1 ~132 stone 0  
fill ~11 ~1 ~133 ~20 ~1 ~133 stone 0  
fill ~12 ~1 ~64 ~23 ~1 ~64 stone 0  
fill ~12 ~1 ~65 ~13 ~1 ~65 stone 0  
fill ~12 ~1 ~84 ~19 ~1 ~84 stone 0  
fill ~12 ~1 ~134 ~20 ~1 ~134 stone 0  
fill ~12 ~1 ~135 ~51 ~1 ~135 stone 0  
fill ~13 ~1 ~63 ~23 ~1 ~63 stone 0 
setblock ~13 ~1 ~68 dirt 0  
fill ~13 ~1 ~71 ~13 ~2 ~71 stone 0 
setblock ~13 ~1 ~73 grass 0 
setblock ~13 ~1 ~74 dirt 0  
fill ~13 ~1 ~105 ~16 ~1 ~105 stone 0  
fill ~13 ~1 ~122 ~85 ~1 ~122 stone 0 
setblock ~13 ~1 ~124 iron_ore 0  
fill ~13 ~1 ~136 ~50 ~1 ~136 stone 0  
fill ~13 ~1 ~137 ~13 ~3 ~137 dirt 0  
fill ~14 ~1 ~65 ~14 ~2 ~65 dirt 0  
fill ~14 ~1 ~68 ~24 ~1 ~68 stone 0  
fill ~14 ~1 ~71 ~14 ~3 ~71 dirt 0  
fill ~14 ~1 ~72 ~14 ~5 ~72 dirt 0  
fill ~14 ~1 ~73 ~20 ~1 ~73 stone 0  
fill ~14 ~1 ~74 ~19 ~1 ~74 stone 0  
fill ~14 ~1 ~75 ~19 ~1 ~75 stone 0  
fill ~14 ~1 ~76 ~19 ~1 ~76 stone 0  
fill ~14 ~1 ~107 ~18 ~1 ~107 stone 0  
fill ~14 ~1 ~108 ~15 ~1 ~108 sand 0  
fill ~14 ~1 ~109 ~15 ~1 ~109 sand 0  
fill ~14 ~1 ~110 ~15 ~1 ~110 sand 0  
fill ~14 ~1 ~111 ~15 ~1 ~111 sand 0  
fill ~14 ~1 ~112 ~15 ~1 ~112 sand 0  
fill ~14 ~1 ~113 ~16 ~1 ~113 sand 0  
fill ~14 ~1 ~120 ~84 ~1 ~120 stone 0  
fill ~14 ~1 ~121 ~84 ~1 ~121 stone 0  
fill ~14 ~1 ~124 ~57 ~1 ~124 stone 0  
fill ~14 ~1 ~137 ~50 ~1 ~137 stone 0  
fill ~14 ~1 ~138 ~49 ~1 ~138 stone 0  
fill ~15 ~1 ~46 ~23 ~1 ~46 grass 0  
fill ~15 ~1 ~55 ~15 ~2 ~55 dirt 0  
fill ~15 ~1 ~56 ~15 ~2 ~56 dirt 0  
fill ~15 ~1 ~62 ~15 ~2 ~62 dirt 0  
fill ~15 ~1 ~65 ~23 ~1 ~65 stone 0  
fill ~15 ~1 ~71 ~21 ~1 ~71 stone 0  
fill ~15 ~1 ~72 ~21 ~1 ~72 stone 0  
fill ~15 ~1 ~106 ~17 ~1 ~106 stone 0  
fill ~15 ~1 ~118 ~84 ~1 ~118 stone 0  
fill ~15 ~1 ~119 ~84 ~1 ~119 stone 0  
fill ~15 ~1 ~139 ~49 ~1 ~139 stone 0  
fill ~16 ~1 ~44 ~16 ~1 ~51 grass 0  
fill ~16 ~1 ~53 ~27 ~1 ~53 stone 0  
fill ~16 ~1 ~54 ~26 ~1 ~54 stone 0  
fill ~16 ~1 ~55 ~26 ~1 ~55 stone 0  
fill ~16 ~1 ~56 ~25 ~1 ~56 stone 0  
fill ~16 ~1 ~57 ~25 ~1 ~57 stone 0  
fill ~16 ~1 ~58 ~24 ~1 ~58 stone 0  
fill ~16 ~1 ~59 ~24 ~1 ~59 stone 0  
fill ~16 ~1 ~60 ~24 ~1 ~60 stone 0  
fill ~16 ~1 ~61 ~24 ~1 ~61 stone 0  
fill ~16 ~1 ~62 ~24 ~1 ~62 stone 0 
setblock ~16 ~1 ~69 coal_ore 0  
fill ~16 ~1 ~108 ~28 ~1 ~108 stone 0  
fill ~16 ~1 ~109 ~85 ~1 ~109 stone 0  
fill ~16 ~1 ~110 ~33 ~1 ~110 stone 0  
fill ~16 ~1 ~111 ~33 ~1 ~111 stone 0  
fill ~16 ~1 ~112 ~33 ~1 ~112 stone 0  
fill ~16 ~1 ~114 ~36 ~1 ~114 stone 0  
fill ~16 ~1 ~116 ~44 ~1 ~116 stone 0  
fill ~16 ~1 ~117 ~44 ~1 ~117 stone 0 
setblock ~16 ~1 ~126 coal_ore 0 
setblock ~17 ~1 ~43 grass 0  
fill ~17 ~1 ~44 ~26 ~1 ~44 dirt 0  
fill ~17 ~1 ~45 ~22 ~1 ~45 grass 0  
fill ~17 ~1 ~47 ~17 ~1 ~50 grass 0  
fill ~17 ~1 ~51 ~21 ~1 ~51 dirt 0  
fill ~17 ~1 ~52 ~28 ~1 ~52 stone 0  
fill ~17 ~1 ~69 ~23 ~1 ~69 stone 0 
setblock ~17 ~1 ~70 coal_ore 0  
fill ~17 ~1 ~113 ~34 ~1 ~113 stone 0  
fill ~17 ~1 ~115 ~28 ~1 ~115 stone 0  
fill ~17 ~1 ~126 ~58 ~1 ~126 stone 0  
fill ~17 ~1 ~127 ~17 ~3 ~127 coal_ore 0  
fill ~17 ~1 ~140 ~48 ~1 ~140 stone 0  
fill ~18 ~1 ~43 ~26 ~1 ~43 dirt 0  
fill ~18 ~1 ~47 ~20 ~1 ~47 dirt 0  
fill ~18 ~1 ~48 ~21 ~1 ~48 dirt 0  
fill ~18 ~1 ~49 ~21 ~1 ~49 dirt 0  
fill ~18 ~1 ~50 ~21 ~1 ~50 dirt 0  
fill ~18 ~1 ~70 ~22 ~1 ~70 stone 0  
fill ~18 ~1 ~78 ~63 ~1 ~78 sand 0  
fill ~18 ~1 ~79 ~63 ~1 ~79 sand 0  
fill ~18 ~1 ~80 ~62 ~1 ~80 sand 0  
fill ~18 ~1 ~141 ~46 ~1 ~141 stone 0 
setblock ~19 ~1 ~42 grass 0  
fill ~19 ~1 ~77 ~64 ~1 ~77 sand 0  
fill ~19 ~1 ~81 ~61 ~1 ~81 sand 0  
fill ~19 ~1 ~82 ~27 ~1 ~82 sand 0  
fill ~19 ~1 ~83 ~26 ~1 ~83 sand 0  
fill ~19 ~1 ~127 ~70 ~1 ~127 stone 0  
fill ~20 ~1 ~42 ~26 ~1 ~42 dirt 0  
fill ~20 ~1 ~74 ~65 ~1 ~74 sand 0  
fill ~20 ~1 ~75 ~65 ~1 ~75 sand 0  
fill ~20 ~1 ~76 ~65 ~1 ~76 sand 0  
fill ~20 ~1 ~84 ~27 ~1 ~84 sand 0  
fill ~21 ~1 ~41 ~27 ~1 ~41 dirt 0 
setblock ~21 ~1 ~47 grass 0  
fill ~21 ~1 ~73 ~65 ~1 ~73 sand 0  
fill ~21 ~1 ~85 ~23 ~1 ~85 sand 0  
fill ~21 ~1 ~107 ~52 ~1 ~107 stone 0  
fill ~21 ~1 ~133 ~21 ~0 ~133 iron_ore 0  
fill ~21 ~1 ~134 ~23 ~1 ~134 iron_ore 0  
fill ~22 ~1 ~40 ~28 ~1 ~40 dirt 0 
setblock ~22 ~1 ~47 dirt 0  
fill ~22 ~1 ~48 ~27 ~1 ~48 stone 0  
fill ~22 ~1 ~49 ~30 ~1 ~49 stone 0  
fill ~22 ~1 ~50 ~29 ~1 ~50 stone 0  
fill ~22 ~1 ~51 ~28 ~1 ~51 stone 0  
fill ~22 ~1 ~71 ~67 ~1 ~71 dirt 0  
fill ~22 ~1 ~72 ~67 ~1 ~72 dirt 0  
fill ~22 ~1 ~106 ~28 ~1 ~106 sand 0  
fill ~22 ~1 ~133 ~62 ~1 ~133 stone 0  
fill ~23 ~1 ~45 ~27 ~1 ~45 dirt 0  
fill ~23 ~1 ~47 ~33 ~1 ~47 stone 0  
fill ~23 ~1 ~70 ~67 ~1 ~70 dirt 0 
setblock ~23 ~1 ~86 stone_slab 3  
fill ~23 ~1 ~93 ~23 ~1 ~94 stone_slab 3  
fill ~23 ~1 ~101 ~23 ~1 ~102 stone_slab 3  
fill ~24 ~1 ~39 ~27 ~1 ~39 dirt 0 
setblock ~24 ~1 ~46 dirt 0  
fill ~24 ~1 ~63 ~68 ~1 ~63 dirt 0  
fill ~24 ~1 ~64 ~68 ~1 ~64 dirt 0  
fill ~24 ~1 ~65 ~68 ~1 ~65 dirt 0  
fill ~24 ~1 ~66 ~68 ~1 ~66 dirt 0  
fill ~24 ~1 ~67 ~68 ~1 ~67 dirt 0  
fill ~24 ~1 ~69 ~67 ~1 ~69 dirt 0  
fill ~24 ~1 ~85 ~24 ~16 ~85 cobblestone 0  
fill ~24 ~1 ~86 ~25 ~1 ~86 cobblestone 0  
fill ~24 ~1 ~87 ~25 ~1 ~87 stone_slab 3  
fill ~24 ~1 ~92 ~25 ~1 ~92 stone_slab 3  
fill ~24 ~1 ~93 ~25 ~1 ~93 cobblestone 0  
fill ~24 ~1 ~94 ~25 ~1 ~94 cobblestone 0  
fill ~24 ~1 ~95 ~25 ~1 ~95 stone_slab 3  
fill ~24 ~1 ~100 ~25 ~1 ~100 stone_slab 3  
fill ~24 ~1 ~101 ~25 ~1 ~101 cobblestone 0  
fill ~24 ~1 ~102 ~25 ~1 ~102 cobblestone 0  
fill ~24 ~1 ~103 ~25 ~1 ~103 stone_slab 3  
fill ~24 ~1 ~134 ~51 ~1 ~134 stone 0  
fill ~25 ~1 ~38 ~28 ~1 ~38 dirt 0  
fill ~25 ~1 ~46 ~34 ~1 ~46 stone 0  
fill ~25 ~1 ~58 ~67 ~1 ~58 dirt 0  
fill ~25 ~1 ~59 ~67 ~1 ~59 dirt 0  
fill ~25 ~1 ~60 ~67 ~1 ~60 dirt 0  
fill ~25 ~1 ~61 ~67 ~1 ~61 dirt 0  
fill ~25 ~1 ~62 ~67 ~1 ~62 dirt 0  
fill ~25 ~1 ~68 ~67 ~1 ~68 dirt 0  
fill ~26 ~1 ~56 ~66 ~1 ~56 dirt 0  
fill ~26 ~1 ~57 ~66 ~1 ~57 dirt 0  
fill ~26 ~1 ~86 ~32 ~1 ~86 sand 0  
fill ~26 ~1 ~93 ~26 ~1 ~94 stone_slab 3  
fill ~26 ~1 ~101 ~26 ~1 ~102 stone_slab 3  
fill ~27 ~1 ~37 ~34 ~1 ~37 dirt 0  
fill ~27 ~1 ~42 ~35 ~1 ~42 leaves 0  
fill ~27 ~1 ~43 ~32 ~1 ~43 leaves 0  
fill ~27 ~1 ~44 ~29 ~1 ~44 leaves 0  
fill ~27 ~1 ~54 ~65 ~1 ~54 dirt 0  
fill ~27 ~1 ~55 ~65 ~1 ~55 dirt 0  
fill ~27 ~1 ~85 ~33 ~1 ~85 sand 0 
setblock ~28 ~1 ~39 leaves 0  
fill ~28 ~1 ~41 ~34 ~1 ~41 leaves 0 
setblock ~28 ~1 ~45 leaves 0  
fill ~28 ~1 ~48 ~29 ~1 ~48 coal_ore 0  
fill ~28 ~1 ~53 ~64 ~1 ~53 dirt 0  
fill ~28 ~1 ~83 ~28 ~2 ~83 sand 0  
fill ~28 ~1 ~142 ~44 ~1 ~142 stone 0  
fill ~29 ~1 ~36 ~33 ~1 ~36 dirt 0 
setblock ~29 ~1 ~38 leaves 0 
setblock ~29 ~1 ~39 dirt 0  
fill ~29 ~1 ~40 ~31 ~1 ~40 leaves 0  
fill ~29 ~1 ~51 ~63 ~1 ~51 dirt 0  
fill ~29 ~1 ~52 ~63 ~1 ~52 dirt 0  
fill ~29 ~1 ~82 ~60 ~1 ~82 sand 0  
fill ~29 ~1 ~84 ~57 ~1 ~84 sand 0  
fill ~29 ~1 ~106 ~36 ~1 ~106 stone 0 
setblock ~29 ~1 ~108 iron_ore 0  
fill ~29 ~1 ~115 ~30 ~1 ~115 coal_ore 0  
fill ~30 ~1 ~38 ~35 ~1 ~38 dirt 0  
fill ~30 ~1 ~39 ~31 ~1 ~39 leaves 0 
setblock ~30 ~1 ~44 dirt 0  
fill ~30 ~1 ~45 ~32 ~1 ~45 stone 0  
fill ~30 ~1 ~48 ~31 ~1 ~48 stone 0  
fill ~30 ~1 ~50 ~62 ~1 ~50 dirt 0  
fill ~30 ~1 ~83 ~58 ~1 ~83 sand 0  
fill ~30 ~1 ~87 ~31 ~1 ~87 sand 0  
fill ~30 ~1 ~108 ~73 ~1 ~108 stone 0 
setblock ~31 ~1 ~34 grass 0  
fill ~31 ~1 ~35 ~32 ~1 ~35 dirt 0 
setblock ~31 ~1 ~44 grass 0  
fill ~31 ~1 ~49 ~61 ~1 ~49 dirt 0  
fill ~31 ~1 ~88 ~39 ~1 ~88 stone 0  
fill ~31 ~1 ~115 ~82 ~1 ~115 stone 0  
fill ~31 ~1 ~143 ~37 ~1 ~143 stone 0  
fill ~32 ~1 ~34 ~40 ~1 ~34 stone 0  
fill ~32 ~1 ~39 ~35 ~1 ~39 dirt 0  
fill ~32 ~1 ~40 ~36 ~1 ~40 dirt 0  
fill ~32 ~1 ~48 ~61 ~1 ~48 dirt 0  
fill ~32 ~1 ~87 ~39 ~1 ~87 stone 0  
fill ~33 ~1 ~35 ~40 ~1 ~35 stone 0  
fill ~33 ~1 ~44 ~33 ~10 ~44 leaves 0  
fill ~33 ~1 ~45 ~34 ~1 ~45 dirt 0  
fill ~33 ~1 ~86 ~38 ~1 ~86 stone 0  
fill ~33 ~1 ~89 ~39 ~1 ~89 stone 0  
fill ~34 ~1 ~33 ~40 ~1 ~33 stone 0  
fill ~34 ~1 ~36 ~40 ~1 ~36 stone 0  
fill ~34 ~1 ~47 ~60 ~1 ~47 dirt 0  
fill ~34 ~1 ~85 ~36 ~1 ~85 stone 0  
fill ~34 ~1 ~90 ~34 ~2 ~90 sand 0  
fill ~34 ~1 ~110 ~36 ~1 ~110 sand 0  
fill ~34 ~1 ~111 ~34 ~2 ~111 sand 0  
fill ~34 ~1 ~112 ~40 ~1 ~112 sand 0  
fill ~34 ~1 ~128 ~34 ~1 ~131 iron_ore 0 
setblock ~35 ~1 ~32 dirt 0  
fill ~35 ~1 ~37 ~39 ~1 ~37 stone 0 
setblock ~35 ~1 ~41 dirt 0  
fill ~35 ~1 ~44 ~38 ~1 ~44 stone 0  
fill ~35 ~1 ~45 ~36 ~1 ~45 stone 0  
fill ~35 ~1 ~46 ~57 ~1 ~46 dirt 0  
fill ~35 ~1 ~90 ~41 ~1 ~90 stone 0  
fill ~35 ~1 ~113 ~42 ~1 ~113 sand 0  
fill ~35 ~1 ~128 ~69 ~1 ~128 stone 0  
fill ~35 ~1 ~129 ~77 ~1 ~129 stone 0  
fill ~35 ~1 ~130 ~78 ~1 ~130 stone 0  
fill ~35 ~1 ~131 ~62 ~1 ~131 stone 0  
fill ~36 ~1 ~32 ~42 ~1 ~32 stone 0  
fill ~36 ~1 ~38 ~37 ~1 ~38 stone 0  
fill ~36 ~1 ~39 ~42 ~1 ~39 stone 0  
fill ~36 ~1 ~41 ~37 ~1 ~41 stone 0  
fill ~36 ~1 ~43 ~36 ~4 ~43 dirt 0  
fill ~36 ~1 ~91 ~41 ~1 ~91 stone 0  
fill ~36 ~1 ~111 ~38 ~1 ~111 sand 0  
fill ~37 ~1 ~31 ~42 ~1 ~31 stone 0  
fill ~37 ~1 ~40 ~42 ~1 ~40 stone 0  
fill ~37 ~1 ~43 ~43 ~1 ~43 stone 0  
fill ~37 ~1 ~45 ~55 ~1 ~45 dirt 0  
fill ~37 ~1 ~85 ~55 ~1 ~85 sand 0  
fill ~37 ~1 ~106 ~41 ~1 ~106 sand 0  
fill ~37 ~1 ~110 ~74 ~1 ~110 stone 0  
fill ~37 ~1 ~114 ~42 ~1 ~114 dirt 0 
setblock ~38 ~1 ~30 grass 0 
setblock ~38 ~1 ~38 dirt 0  
fill ~38 ~1 ~41 ~38 ~5 ~41 log 0  
fill ~38 ~1 ~42 ~38 ~3 ~42 dirt 0  
fill ~38 ~1 ~92 ~41 ~1 ~92 stone 0  
fill ~38 ~1 ~94 ~41 ~1 ~94 sand 0  
fill ~38 ~1 ~143 ~38 ~3 ~143 dirt 0  
fill ~39 ~1 ~30 ~42 ~1 ~30 stone 0  
fill ~39 ~1 ~38 ~43 ~1 ~38 stone 0  
fill ~39 ~1 ~41 ~43 ~1 ~41 dirt 0  
fill ~39 ~1 ~42 ~48 ~1 ~42 stone 0  
fill ~39 ~1 ~44 ~53 ~1 ~44 dirt 0  
fill ~39 ~1 ~86 ~53 ~1 ~86 sand 0  
fill ~39 ~1 ~95 ~64 ~1 ~95 sand 0  
fill ~39 ~1 ~111 ~74 ~1 ~111 stone 0 
setblock ~39 ~1 ~143 grass 0 
setblock ~40 ~1 ~37 dirt 0  
fill ~40 ~1 ~87 ~54 ~1 ~87 sand 0  
fill ~40 ~1 ~88 ~55 ~1 ~88 sand 0  
fill ~40 ~1 ~89 ~55 ~1 ~89 sand 0  
fill ~40 ~1 ~93 ~40 ~2 ~93 sand 0 
setblock ~41 ~1 ~29 dirt 0  
fill ~41 ~1 ~33 ~43 ~1 ~33 dirt 0  
fill ~41 ~1 ~34 ~44 ~1 ~34 dirt 0  
fill ~41 ~1 ~35 ~43 ~1 ~35 dirt 0  
fill ~41 ~1 ~37 ~129 ~1 ~37 stone 0 
setblock ~41 ~1 ~93 stone 0  
fill ~41 ~1 ~112 ~74 ~1 ~112 stone 0 
setblock ~42 ~1 ~29 stone 0  
fill ~42 ~1 ~36 ~43 ~1 ~36 dirt 0  
fill ~42 ~1 ~90 ~55 ~1 ~90 sand 0  
fill ~42 ~1 ~91 ~56 ~1 ~91 sand 0  
fill ~42 ~1 ~92 ~57 ~1 ~92 sand 0  
fill ~42 ~1 ~93 ~60 ~1 ~93 sand 0  
fill ~42 ~1 ~96 ~46 ~1 ~96 sand 0 
setblock ~43 ~1 ~28 grass 0  
fill ~43 ~1 ~29 ~45 ~1 ~29 dirt 0  
fill ~43 ~1 ~30 ~45 ~1 ~30 dirt 0  
fill ~43 ~1 ~31 ~45 ~1 ~31 dirt 0  
fill ~43 ~1 ~32 ~45 ~1 ~32 dirt 0  
fill ~43 ~1 ~39 ~43 ~4 ~39 log 0  
fill ~43 ~1 ~40 ~44 ~1 ~40 grass 0  
fill ~43 ~1 ~94 ~62 ~1 ~94 sand 0 
setblock ~43 ~1 ~106 cobblestone 0  
fill ~43 ~1 ~113 ~74 ~1 ~113 stone 0  
fill ~43 ~1 ~114 ~82 ~1 ~114 stone 0  
fill ~44 ~1 ~28 ~45 ~1 ~28 dirt 0  
fill ~44 ~1 ~33 ~46 ~1 ~33 leaves 0  
fill ~44 ~1 ~35 ~45 ~1 ~35 stone 0  
fill ~44 ~1 ~36 ~73 ~1 ~36 stone 0  
fill ~44 ~1 ~38 ~44 ~1 ~39 leaves 0 
setblock ~44 ~1 ~41 stone 0  
fill ~44 ~1 ~43 ~48 ~1 ~43 dirt 0  
fill ~44 ~1 ~97 ~45 ~1 ~97 sand 0  
fill ~45 ~1 ~34 ~46 ~1 ~34 leaves 0  
fill ~45 ~1 ~38 ~46 ~1 ~38 stone 0  
fill ~45 ~1 ~39 ~81 ~1 ~39 stone 0  
fill ~45 ~1 ~40 ~45 ~1 ~41 dirt 0  
fill ~45 ~1 ~98 ~48 ~1 ~98 stone 0  
fill ~45 ~1 ~106 ~49 ~1 ~106 sand 0  
fill ~45 ~1 ~116 ~45 ~1 ~117 coal_ore 0 
setblock ~46 ~1 ~24 grass 0  
fill ~46 ~1 ~25 ~107 ~1 ~25 stone 0  
fill ~46 ~1 ~26 ~73 ~1 ~26 stone 0  
fill ~46 ~1 ~27 ~61 ~1 ~27 stone 0  
fill ~46 ~1 ~28 ~69 ~1 ~28 stone 0  
fill ~46 ~1 ~29 ~69 ~1 ~29 stone 0  
fill ~46 ~1 ~30 ~82 ~1 ~30 stone 0  
fill ~46 ~1 ~31 ~127 ~1 ~31 stone 0  
fill ~46 ~1 ~32 ~125 ~1 ~32 stone 0  
fill ~46 ~1 ~35 ~46 ~6 ~35 leaves 0  
fill ~46 ~1 ~40 ~81 ~1 ~40 stone 0  
fill ~46 ~1 ~41 ~131 ~1 ~41 stone 0  
fill ~46 ~1 ~97 ~49 ~1 ~97 stone 0  
fill ~46 ~1 ~116 ~83 ~1 ~116 stone 0 
setblock ~46 ~1 ~117 coal_ore 0  
fill ~47 ~1 ~22 ~54 ~1 ~22 stone 0  
fill ~47 ~1 ~23 ~122 ~1 ~23 stone 0  
fill ~47 ~1 ~24 ~107 ~1 ~24 stone 0  
fill ~47 ~1 ~33 ~125 ~1 ~33 stone 0  
fill ~47 ~1 ~34 ~124 ~1 ~34 stone 0  
fill ~47 ~1 ~35 ~68 ~1 ~35 stone 0  
fill ~47 ~1 ~96 ~48 ~1 ~96 stone 0  
fill ~47 ~1 ~117 ~83 ~1 ~117 stone 0  
fill ~48 ~1 ~19 ~118 ~1 ~19 stone 0  
fill ~48 ~1 ~20 ~51 ~1 ~20 stone 0  
fill ~48 ~1 ~21 ~121 ~1 ~21 stone 0  
fill ~48 ~1 ~38 ~81 ~1 ~38 stone 0 
setblock ~48 ~1 ~99 stone 0  
fill ~49 ~1 ~18 ~118 ~1 ~18 stone 0 
setblock ~49 ~1 ~42 coal_ore 0  
fill ~49 ~1 ~43 ~85 ~1 ~43 stone 0  
fill ~49 ~1 ~96 ~65 ~1 ~96 sand 0  
fill ~50 ~1 ~17 ~82 ~1 ~17 stone 0  
fill ~50 ~1 ~42 ~131 ~1 ~42 stone 0  
fill ~50 ~1 ~97 ~63 ~1 ~97 sand 0 
setblock ~50 ~1 ~98 stone 0  
fill ~51 ~1 ~16 ~127 ~1 ~16 stone 0  
fill ~51 ~1 ~98 ~63 ~1 ~98 sand 0  
fill ~51 ~1 ~99 ~53 ~1 ~99 stone 0  
fill ~51 ~1 ~101 ~55 ~1 ~101 stone 0  
fill ~51 ~1 ~136 ~51 ~2 ~136 dirt 0 
setblock ~51 ~1 ~137 grass 0  
fill ~52 ~1 ~15 ~128 ~1 ~15 stone 0 
setblock ~52 ~1 ~20 iron_ore 0  
fill ~52 ~1 ~100 ~55 ~1 ~100 stone 0  
fill ~52 ~1 ~102 ~55 ~1 ~102 stone 0  
fill ~52 ~1 ~134 ~52 ~3 ~134 dirt 0 
setblock ~52 ~1 ~136 grass 0  
fill ~53 ~1 ~20 ~127 ~1 ~20 stone 0  
fill ~53 ~1 ~107 ~53 ~2 ~107 sand 0  
fill ~53 ~1 ~134 ~62 ~1 ~134 stone 0  
fill ~53 ~1 ~135 ~53 ~2 ~135 dirt 0  
fill ~53 ~1 ~136 ~56 ~1 ~136 dirt 0  
fill ~54 ~1 ~14 ~127 ~1 ~14 stone 0  
fill ~54 ~1 ~44 ~93 ~1 ~44 stone 0  
fill ~54 ~1 ~86 ~104 ~1 ~86 stone 0  
fill ~54 ~1 ~99 ~62 ~1 ~99 sand 0  
fill ~54 ~1 ~103 ~54 ~2 ~103 sand 0  
fill ~54 ~1 ~135 ~57 ~1 ~135 stone 0  
fill ~54 ~1 ~137 ~55 ~1 ~137 grass 0  
fill ~55 ~1 ~13 ~117 ~1 ~13 stone 0 
setblock ~55 ~1 ~22 coal_ore 0  
fill ~55 ~1 ~87 ~63 ~1 ~87 stone 0 
setblock ~55 ~1 ~103 stone 0  
fill ~55 ~1 ~107 ~55 ~2 ~107 sand 0  
fill ~56 ~1 ~22 ~123 ~1 ~22 stone 0  
fill ~56 ~1 ~45 ~120 ~1 ~45 stone 0  
fill ~56 ~1 ~85 ~67 ~1 ~85 stone 0  
fill ~56 ~1 ~88 ~66 ~1 ~88 stone 0  
fill ~56 ~1 ~89 ~63 ~1 ~89 stone 0  
fill ~56 ~1 ~90 ~62 ~1 ~90 stone 0  
fill ~56 ~1 ~100 ~62 ~1 ~100 sand 0  
fill ~56 ~1 ~101 ~62 ~1 ~101 sand 0  
fill ~56 ~1 ~102 ~62 ~1 ~102 sand 0  
fill ~56 ~1 ~103 ~62 ~1 ~103 sand 0  
fill ~56 ~1 ~107 ~57 ~1 ~107 stone 0  
fill ~57 ~1 ~12 ~76 ~1 ~12 stone 0  
fill ~57 ~1 ~91 ~62 ~1 ~91 stone 0 
setblock ~57 ~1 ~136 grass 0  
fill ~58 ~1 ~46 ~119 ~1 ~46 stone 0  
fill ~58 ~1 ~84 ~104 ~1 ~84 stone 0  
fill ~58 ~1 ~92 ~61 ~1 ~92 stone 0  
fill ~58 ~1 ~106 ~58 ~2 ~106 sand 0  
fill ~58 ~1 ~107 ~59 ~1 ~107 iron_ore 0  
fill ~58 ~1 ~124 ~58 ~1 ~125 coal_ore 0  
fill ~58 ~1 ~135 ~65 ~1 ~135 dirt 0  
fill ~59 ~1 ~83 ~107 ~1 ~83 stone 0  
fill ~59 ~1 ~106 ~73 ~1 ~106 stone 0  
fill ~59 ~1 ~124 ~90 ~1 ~124 stone 0  
fill ~59 ~1 ~125 ~59 ~1 ~126 coal_ore 0  
fill ~59 ~1 ~141 ~60 ~1 ~141 leaves 2  
fill ~60 ~1 ~11 ~63 ~1 ~11 dirt 0  
fill ~60 ~1 ~105 ~73 ~1 ~105 stone 0  
fill ~60 ~1 ~107 ~73 ~1 ~107 stone 0  
fill ~60 ~1 ~125 ~95 ~1 ~125 stone 0  
fill ~60 ~1 ~126 ~96 ~1 ~126 stone 0  
fill ~60 ~1 ~143 ~60 ~2 ~143 leaves 2  
fill ~61 ~1 ~47 ~89 ~1 ~47 stone 0  
fill ~61 ~1 ~82 ~109 ~1 ~82 stone 0  
fill ~61 ~1 ~93 ~106 ~1 ~93 stone 0  
fill ~61 ~1 ~104 ~62 ~1 ~104 sand 0 
setblock ~61 ~1 ~136 grass 0  
fill ~61 ~1 ~138 ~63 ~1 ~138 grass 0  
fill ~61 ~1 ~139 ~63 ~1 ~139 grass 0 
setblock ~62 ~1 ~27 coal_ore 0  
fill ~62 ~1 ~48 ~84 ~1 ~48 stone 0  
fill ~62 ~1 ~49 ~79 ~1 ~49 stone 0  
fill ~62 ~1 ~81 ~110 ~1 ~81 stone 0  
fill ~62 ~1 ~92 ~65 ~1 ~92 sand 0  
fill ~62 ~1 ~136 ~64 ~1 ~136 dirt 0  
fill ~62 ~1 ~137 ~63 ~1 ~137 grass 0  
fill ~62 ~1 ~140 ~65 ~1 ~140 grass 0  
fill ~63 ~1 ~27 ~73 ~1 ~27 stone 0  
fill ~63 ~1 ~50 ~73 ~1 ~50 stone 0  
fill ~63 ~1 ~80 ~111 ~1 ~80 stone 0  
fill ~63 ~1 ~90 ~65 ~1 ~90 sand 0  
fill ~63 ~1 ~91 ~65 ~1 ~91 sand 0  
fill ~63 ~1 ~94 ~107 ~1 ~94 stone 0  
fill ~63 ~1 ~99 ~106 ~1 ~99 stone 0  
fill ~63 ~1 ~100 ~77 ~1 ~100 stone 0  
fill ~63 ~1 ~101 ~72 ~1 ~101 stone 0  
fill ~63 ~1 ~102 ~75 ~1 ~102 stone 0  
fill ~63 ~1 ~103 ~75 ~1 ~103 stone 0  
fill ~63 ~1 ~104 ~75 ~1 ~104 stone 0  
fill ~63 ~1 ~131 ~65 ~1 ~131 dirt 0  
fill ~63 ~1 ~132 ~65 ~1 ~132 dirt 0  
fill ~63 ~1 ~133 ~65 ~1 ~133 dirt 0  
fill ~63 ~1 ~134 ~65 ~1 ~134 dirt 0  
fill ~63 ~1 ~141 ~66 ~1 ~141 grass 0 
setblock ~64 ~1 ~10 grass 0  
fill ~64 ~1 ~11 ~76 ~1 ~11 stone 0  
fill ~64 ~1 ~51 ~86 ~1 ~51 stone 0  
fill ~64 ~1 ~52 ~67 ~1 ~52 stone 0  
fill ~64 ~1 ~78 ~112 ~1 ~78 stone 0  
fill ~64 ~1 ~79 ~111 ~1 ~79 stone 0  
fill ~64 ~1 ~89 ~65 ~1 ~89 sand 0  
fill ~64 ~1 ~97 ~68 ~1 ~97 stone 0  
fill ~64 ~1 ~98 ~69 ~1 ~98 stone 0  
fill ~64 ~1 ~137 ~64 ~1 ~139 dirt 0  
fill ~65 ~1 ~6 ~65 ~1 ~9 grass 0  
fill ~65 ~1 ~10 ~66 ~1 ~10 dirt 0  
fill ~65 ~1 ~53 ~72 ~1 ~53 stone 0  
fill ~65 ~1 ~77 ~112 ~1 ~77 stone 0  
fill ~65 ~1 ~87 ~104 ~1 ~87 stone 0  
fill ~65 ~1 ~95 ~107 ~1 ~95 stone 0  
fill ~65 ~1 ~136 ~93 ~1 ~136 stone 0  
fill ~65 ~1 ~137 ~83 ~1 ~137 stone 0 
setblock ~65 ~1 ~138 dirt 0  
fill ~66 ~1 ~6 ~67 ~1 ~6 dirt 0  
fill ~66 ~1 ~7 ~68 ~1 ~7 dirt 0  
fill ~66 ~1 ~8 ~68 ~1 ~8 dirt 0  
fill ~66 ~1 ~9 ~68 ~1 ~9 dirt 0  
fill ~66 ~1 ~54 ~88 ~1 ~54 stone 0  
fill ~66 ~1 ~55 ~80 ~1 ~55 stone 0  
fill ~66 ~1 ~75 ~112 ~1 ~75 stone 0  
fill ~66 ~1 ~76 ~112 ~1 ~76 stone 0  
fill ~66 ~1 ~89 ~70 ~1 ~89 dirt 0  
fill ~66 ~1 ~90 ~68 ~1 ~90 dirt 0  
fill ~66 ~1 ~92 ~106 ~1 ~92 stone 0  
fill ~66 ~1 ~96 ~67 ~1 ~96 stone 0  
fill ~66 ~1 ~131 ~97 ~1 ~131 stone 0  
fill ~66 ~1 ~132 ~96 ~1 ~132 stone 0  
fill ~66 ~1 ~133 ~96 ~1 ~133 stone 0  
fill ~66 ~1 ~134 ~94 ~1 ~134 stone 0  
fill ~66 ~1 ~135 ~94 ~1 ~135 stone 0  
fill ~66 ~1 ~138 ~82 ~1 ~138 stone 0  
fill ~66 ~1 ~139 ~80 ~1 ~139 stone 0 
setblock ~66 ~1 ~140 dirt 0 
setblock ~67 ~1 ~5 grass 0  
fill ~67 ~1 ~10 ~77 ~1 ~10 stone 0  
fill ~67 ~1 ~56 ~80 ~1 ~56 stone 0  
fill ~67 ~1 ~73 ~67 ~13 ~73 stone 0  
fill ~67 ~1 ~74 ~113 ~1 ~74 stone 0  
fill ~67 ~1 ~88 ~71 ~1 ~88 dirt 0  
fill ~67 ~1 ~91 ~67 ~2 ~91 dirt 0  
fill ~67 ~1 ~140 ~75 ~1 ~140 stone 0 
setblock ~67 ~1 ~141 dirt 0  
fill ~68 ~1 ~5 ~68 ~2 ~5 dirt 0  
fill ~68 ~1 ~6 ~69 ~1 ~6 stone 0 
setblock ~68 ~1 ~52 coal_ore 0  
fill ~68 ~1 ~57 ~80 ~1 ~57 stone 0  
fill ~68 ~1 ~58 ~132 ~1 ~58 stone 0  
fill ~68 ~1 ~59 ~132 ~1 ~59 stone 0  
fill ~68 ~1 ~60 ~84 ~1 ~60 stone 0  
fill ~68 ~1 ~61 ~92 ~1 ~61 stone 0  
fill ~68 ~1 ~62 ~119 ~1 ~62 stone 0  
fill ~68 ~1 ~68 ~85 ~1 ~68 stone 0  
fill ~68 ~1 ~69 ~96 ~1 ~69 stone 0  
fill ~68 ~1 ~70 ~87 ~1 ~70 stone 0  
fill ~68 ~1 ~71 ~87 ~1 ~71 stone 0  
fill ~68 ~1 ~72 ~88 ~1 ~72 stone 0 
setblock ~68 ~1 ~73 lapis_ore 0 
setblock ~68 ~1 ~85 lava 0  
fill ~68 ~1 ~91 ~105 ~1 ~91 stone 0   
fill ~68 ~1 ~96 ~68 ~3 ~96 dirt 0  
fill ~68 ~1 ~141 ~72 ~1 ~141 stone 0 
setblock ~68 ~1 ~142 grass 0  
fill ~69 ~1 ~5 ~83 ~1 ~5 stone 0  
fill ~69 ~1 ~7 ~84 ~1 ~7 stone 0  
fill ~69 ~1 ~8 ~85 ~1 ~8 stone 0  
fill ~69 ~1 ~9 ~74 ~1 ~9 stone 0 
setblock ~69 ~1 ~35 coal_ore 0  
fill ~69 ~1 ~52 ~97 ~1 ~52 stone 0  
fill ~69 ~1 ~63 ~118 ~1 ~63 stone 0  
fill ~69 ~1 ~64 ~88 ~1 ~64 stone 0  
fill ~69 ~1 ~65 ~83 ~1 ~65 stone 0  
fill ~69 ~1 ~66 ~78 ~1 ~66 stone 0  
fill ~69 ~1 ~67 ~72 ~1 ~67 stone 0  
fill ~69 ~1 ~73 ~95 ~1 ~73 stone 0  
fill ~69 ~1 ~85 ~103 ~1 ~85 stone 0  
fill ~69 ~1 ~90 ~105 ~1 ~90 stone 0 
setblock ~69 ~1 ~97 dirt 0  
fill ~69 ~1 ~142 ~69 ~2 ~142 dirt 0  
fill ~70 ~1 ~4 ~70 ~2 ~4 dirt 0 
setblock ~70 ~1 ~6 iron_ore 0 
setblock ~70 ~1 ~28 lava 0 
setblock ~70 ~1 ~29 lava 2  
fill ~70 ~1 ~35 ~129 ~1 ~35 stone 0  
fill ~70 ~1 ~97 ~70 ~11 ~97 stone 0  
fill ~70 ~1 ~98 ~70 ~2 ~98 coal_ore 0  
fill ~70 ~1 ~128 ~71 ~1 ~128 coal_ore 0  
fill ~70 ~1 ~142 ~71 ~1 ~142 stone 0  
fill ~71 ~1 ~4 ~83 ~1 ~4 stone 0  
fill ~71 ~1 ~6 ~84 ~1 ~6 stone 0  
fill ~71 ~1 ~28 ~124 ~1 ~28 stone 0  
fill ~71 ~1 ~29 ~83 ~1 ~29 stone 0  
fill ~71 ~1 ~89 ~104 ~1 ~89 stone 0  
fill ~71 ~1 ~96 ~101 ~1 ~96 stone 0 
setblock ~71 ~1 ~97 leaves 0  
fill ~71 ~1 ~98 ~71 ~4 ~98 stone 0  
fill ~72 ~1 ~88 ~104 ~1 ~88 stone 0  
fill ~72 ~1 ~97 ~73 ~1 ~97 stone 0 
setblock ~72 ~1 ~98 leaves 0  
fill ~72 ~1 ~127 ~96 ~1 ~127 stone 0  
fill ~72 ~1 ~128 ~95 ~1 ~128 stone 0 
setblock ~73 ~1 ~53 coal_ore 0  
fill ~73 ~1 ~67 ~74 ~1 ~67 dirt 0  
fill ~73 ~1 ~98 ~106 ~1 ~98 stone 0  
fill ~73 ~1 ~141 ~73 ~2 ~141 dirt 0  
fill ~74 ~1 ~26 ~75 ~1 ~26 iron_ore 0  
fill ~74 ~1 ~27 ~75 ~1 ~27 iron_ore 0  
fill ~74 ~1 ~50 ~75 ~1 ~50 dirt 0  
fill ~74 ~1 ~53 ~88 ~1 ~53 stone 0 
setblock ~74 ~1 ~97 lapis_ore 0  
fill ~74 ~1 ~101 ~75 ~1 ~101 stone 0  
fill ~74 ~1 ~105 ~77 ~1 ~105 dirt 0  
fill ~74 ~1 ~106 ~77 ~1 ~106 dirt 0  
fill ~74 ~1 ~107 ~77 ~1 ~107 dirt 0  
fill ~74 ~1 ~108 ~77 ~1 ~108 dirt 0  
fill ~75 ~1 ~36 ~117 ~1 ~36 stone 0  
fill ~75 ~1 ~67 ~85 ~1 ~67 stone 0  
fill ~75 ~1 ~97 ~101 ~1 ~97 stone 0  
fill ~75 ~1 ~110 ~78 ~1 ~110 dirt 0  
fill ~75 ~1 ~111 ~78 ~1 ~111 dirt 0  
fill ~75 ~1 ~112 ~78 ~1 ~112 dirt 0  
fill ~75 ~1 ~113 ~78 ~1 ~113 dirt 0 
setblock ~76 ~1 ~3 grass 0  
fill ~76 ~1 ~9 ~114 ~1 ~9 stone 0  
fill ~76 ~1 ~26 ~123 ~1 ~26 stone 0  
fill ~76 ~1 ~27 ~123 ~1 ~27 stone 0  
fill ~76 ~1 ~50 ~86 ~1 ~50 stone 0  
fill ~76 ~1 ~101 ~79 ~1 ~101 dirt 0  
fill ~76 ~1 ~102 ~79 ~1 ~102 dirt 0  
fill ~76 ~1 ~103 ~79 ~1 ~103 dirt 0  
fill ~76 ~1 ~104 ~79 ~1 ~104 dirt 0  
fill ~77 ~1 ~3 ~83 ~1 ~3 stone 0  
fill ~77 ~1 ~11 ~78 ~1 ~11 coal_ore 0  
fill ~77 ~1 ~12 ~78 ~1 ~12 coal_ore 0  
fill ~78 ~1 ~10 ~78 ~0 ~10 coal_ore 0 
setblock ~78 ~1 ~100 leaves 0  
fill ~78 ~1 ~105 ~105 ~1 ~105 stone 0  
fill ~78 ~1 ~106 ~104 ~1 ~106 stone 0  
fill ~78 ~1 ~107 ~87 ~1 ~107 stone 0  
fill ~78 ~1 ~108 ~86 ~1 ~108 stone 0  
fill ~78 ~1 ~129 ~79 ~1 ~129 iron_ore 0  
fill ~79 ~1 ~10 ~114 ~1 ~10 stone 0  
fill ~79 ~1 ~11 ~115 ~1 ~11 stone 0  
fill ~79 ~1 ~12 ~116 ~1 ~12 stone 0  
fill ~79 ~1 ~66 ~81 ~1 ~66 dirt 0  
fill ~79 ~1 ~100 ~86 ~1 ~100 stone 0  
fill ~79 ~1 ~110 ~87 ~1 ~110 stone 0  
fill ~79 ~1 ~111 ~81 ~1 ~111 stone 0  
fill ~79 ~1 ~112 ~81 ~1 ~112 stone 0  
fill ~79 ~1 ~113 ~81 ~1 ~113 stone 0 
setblock ~79 ~1 ~130 iron_ore 0  
fill ~80 ~1 ~2 ~81 ~1 ~2 grass 0  
fill ~80 ~1 ~49 ~82 ~1 ~49 dirt 0  
fill ~80 ~1 ~101 ~89 ~1 ~101 stone 0  
fill ~80 ~1 ~102 ~106 ~1 ~102 stone 0  
fill ~80 ~1 ~103 ~106 ~1 ~103 stone 0  
fill ~80 ~1 ~104 ~106 ~1 ~104 stone 0  
fill ~80 ~1 ~129 ~96 ~1 ~129 stone 0  
fill ~80 ~1 ~130 ~97 ~1 ~130 stone 0  
fill ~81 ~1 ~55 ~81 ~1 ~57 coal_ore 0 
setblock ~81 ~1 ~139 grass 0 
setblock ~82 ~1 ~2 dirt 0  
fill ~82 ~1 ~38 ~82 ~1 ~40 coal_ore 0  
fill ~82 ~1 ~55 ~89 ~1 ~55 stone 0  
fill ~82 ~1 ~56 ~110 ~1 ~56 stone 0  
fill ~82 ~1 ~57 ~125 ~1 ~57 stone 0  
fill ~82 ~1 ~66 ~84 ~1 ~66 stone 0 
setblock ~82 ~1 ~113 grass 0  
fill ~83 ~1 ~2 ~87 ~1 ~2 stone 0 
setblock ~83 ~1 ~30 iron_ore 0  
fill ~83 ~1 ~38 ~130 ~1 ~38 stone 0  
fill ~83 ~1 ~39 ~126 ~1 ~39 stone 0  
fill ~83 ~1 ~40 ~126 ~1 ~40 stone 0  
fill ~83 ~1 ~49 ~85 ~1 ~49 stone 0  
fill ~83 ~1 ~111 ~87 ~1 ~111 stone 0 
setblock ~83 ~1 ~138 grass 0  
fill ~84 ~1 ~3 ~87 ~1 ~3 gravel 0  
fill ~84 ~1 ~4 ~87 ~1 ~4 gravel 0  
fill ~84 ~1 ~5 ~87 ~1 ~5 gravel 0  
fill ~84 ~1 ~17 ~127 ~1 ~17 stone 0  
fill ~84 ~1 ~29 ~84 ~2 ~29 coal_ore 0  
fill ~84 ~1 ~30 ~84 ~1 ~29 coal_ore 0  
fill ~84 ~1 ~65 ~89 ~1 ~65 dirt 0 
setblock ~84 ~1 ~117 grass 0  
fill ~84 ~1 ~137 ~84 ~2 ~137 dirt 0  
fill ~85 ~1 ~6 ~87 ~1 ~6 gravel 0  
fill ~85 ~1 ~7 ~87 ~1 ~7 gravel 0  
fill ~85 ~1 ~29 ~92 ~1 ~29 stone 0  
fill ~85 ~1 ~30 ~127 ~1 ~30 stone 0  
fill ~85 ~1 ~48 ~90 ~1 ~48 dirt 0 
setblock ~85 ~1 ~60 iron_ore 0  
fill ~85 ~1 ~66 ~85 ~3 ~66 leaves 0 
setblock ~85 ~1 ~121 grass 0  
fill ~85 ~1 ~137 ~93 ~1 ~137 stone 0 
setblock ~86 ~1 ~43 iron_ore 0  
fill ~86 ~1 ~49 ~86 ~5 ~49 leaves 0  
fill ~86 ~1 ~60 ~92 ~1 ~60 stone 0  
fill ~86 ~1 ~66 ~87 ~1 ~66 stone 0  
fill ~86 ~1 ~67 ~86 ~3 ~67 log 0 
setblock ~86 ~1 ~68 leaves 0  
fill ~86 ~1 ~109 ~89 ~1 ~109 leaves 2 
setblock ~86 ~1 ~112 grass 0 
setblock ~87 ~1 ~8 gravel 0  
fill ~87 ~1 ~43 ~93 ~1 ~43 stone 0  
fill ~87 ~1 ~49 ~88 ~1 ~49 stone 0 
setblock ~87 ~1 ~51 leaves 0  
fill ~87 ~1 ~67 ~87 ~2 ~67 stone 0  
fill ~87 ~1 ~68 ~87 ~1 ~66 stone 0  
fill ~87 ~1 ~108 ~88 ~1 ~108 leaves 2  
fill ~87 ~1 ~138 ~94 ~1 ~138 stone 0 
setblock ~88 ~1 ~2 grass 0  
fill ~88 ~1 ~3 ~89 ~1 ~3 stone 0  
fill ~88 ~1 ~4 ~92 ~1 ~4 stone 0  
fill ~88 ~1 ~5 ~95 ~1 ~5 stone 0  
fill ~88 ~1 ~6 ~110 ~1 ~6 stone 0  
fill ~88 ~1 ~7 ~114 ~1 ~7 stone 0  
fill ~88 ~1 ~8 ~113 ~1 ~8 stone 0  
fill ~88 ~1 ~50 ~88 ~2 ~50 stone 0  
fill ~88 ~1 ~51 ~88 ~1 ~49 stone 0 
setblock ~88 ~1 ~66 grass 0  
fill ~88 ~1 ~67 ~88 ~1 ~68 dirt 0  
fill ~88 ~1 ~70 ~88 ~2 ~70 dirt 0  
fill ~88 ~1 ~71 ~88 ~1 ~70 dirt 0  
fill ~88 ~1 ~100 ~107 ~1 ~100 stone 0 
setblock ~88 ~1 ~107 leaves 2  
fill ~88 ~1 ~110 ~89 ~1 ~110 leaves 2 
setblock ~89 ~1 ~49 grass 0  
fill ~89 ~1 ~50 ~89 ~1 ~51 dirt 0  
fill ~89 ~1 ~53 ~89 ~2 ~53 dirt 0  
fill ~89 ~1 ~54 ~89 ~1 ~53 dirt 0 
setblock ~89 ~1 ~64 coal_ore 0  
fill ~89 ~1 ~66 ~89 ~3 ~66 dirt 0  
fill ~89 ~1 ~67 ~107 ~1 ~67 stone 0  
fill ~89 ~1 ~68 ~96 ~1 ~68 stone 0  
fill ~89 ~1 ~70 ~93 ~1 ~70 stone 0  
fill ~89 ~1 ~71 ~91 ~1 ~71 stone 0  
fill ~89 ~1 ~72 ~89 ~2 ~72 log 0  
fill ~89 ~1 ~107 ~103 ~1 ~107 stone 0  
fill ~89 ~1 ~108 ~102 ~1 ~108 stone 0  
fill ~89 ~1 ~111 ~90 ~1 ~111 stone 0  
fill ~89 ~1 ~112 ~90 ~1 ~112 dirt 0  
fill ~89 ~1 ~139 ~93 ~1 ~139 stone 0 
setblock ~90 ~1 ~3 dirt 0 
setblock ~90 ~1 ~47 coal_ore 0  
fill ~90 ~1 ~49 ~90 ~3 ~49 dirt 0  
fill ~90 ~1 ~50 ~108 ~1 ~50 stone 0  
fill ~90 ~1 ~51 ~97 ~1 ~51 stone 0  
fill ~90 ~1 ~53 ~94 ~1 ~53 stone 0  
fill ~90 ~1 ~54 ~92 ~1 ~54 stone 0  
fill ~90 ~1 ~55 ~90 ~2 ~55 log 0  
fill ~90 ~1 ~64 ~114 ~1 ~64 stone 0  
fill ~90 ~1 ~65 ~90 ~2 ~65 stone 0  
fill ~90 ~1 ~66 ~108 ~1 ~66 stone 0  
fill ~90 ~1 ~72 ~95 ~1 ~72 stone 0 
setblock ~90 ~1 ~101 lapis_ore 0  
fill ~90 ~1 ~109 ~93 ~1 ~109 stone 0  
fill ~90 ~1 ~110 ~99 ~1 ~110 stone 0  
fill ~91 ~1 ~47 ~115 ~1 ~47 stone 0  
fill ~91 ~1 ~48 ~91 ~2 ~48 stone 0  
fill ~91 ~1 ~49 ~109 ~1 ~49 stone 0  
fill ~91 ~1 ~55 ~100 ~1 ~55 stone 0 
setblock ~91 ~1 ~65 iron_ore 0  
fill ~91 ~1 ~101 ~107 ~1 ~101 stone 0  
fill ~91 ~1 ~111 ~91 ~0 ~111 leaves 0  
fill ~91 ~1 ~140 ~91 ~9 ~140 stone 0 
setblock ~92 ~1 ~48 iron_ore 0  
fill ~92 ~1 ~65 ~110 ~1 ~65 stone 0 
setblock ~92 ~1 ~71 dirt 0  
fill ~92 ~1 ~111 ~97 ~1 ~111 stone 0  
fill ~92 ~1 ~112 ~95 ~1 ~112 stone 0 
setblock ~93 ~1 ~4 grass 0  
fill ~93 ~1 ~29 ~94 ~1 ~29 coal_ore 0  
fill ~93 ~1 ~48 ~111 ~1 ~48 stone 0  
fill ~93 ~1 ~54 ~93 ~0 ~54 dirt 0  
fill ~93 ~1 ~60 ~93 ~1 ~61 coal_ore 0  
fill ~93 ~1 ~71 ~112 ~1 ~71 stone 0  
fill ~93 ~1 ~124 ~93 ~14 ~124 stone 0  
fill ~94 ~1 ~43 ~94 ~1 ~44 coal_ore 0  
fill ~94 ~1 ~54 ~99 ~1 ~54 stone 0  
fill ~94 ~1 ~60 ~113 ~1 ~60 stone 0  
fill ~94 ~1 ~61 ~113 ~1 ~61 stone 0  
fill ~94 ~1 ~70 ~97 ~1 ~70 dirt 0  
fill ~95 ~1 ~29 ~127 ~1 ~29 stone 0  
fill ~95 ~1 ~43 ~131 ~1 ~43 stone 0  
fill ~95 ~1 ~44 ~122 ~1 ~44 stone 0  
fill ~95 ~1 ~53 ~99 ~1 ~53 dirt 0  
fill ~95 ~1 ~109 ~101 ~1 ~109 stone 0  
fill ~96 ~1 ~5 ~98 ~1 ~5 dirt 0  
fill ~97 ~1 ~68 ~97 ~1 ~69 coal_ore 0  
fill ~97 ~1 ~72 ~113 ~1 ~72 stone 0  
fill ~97 ~1 ~73 ~113 ~1 ~73 stone 0  
fill ~98 ~1 ~51 ~98 ~1 ~52 coal_ore 0  
fill ~98 ~1 ~68 ~109 ~1 ~68 stone 0  
fill ~98 ~1 ~69 ~112 ~1 ~69 stone 0  
fill ~98 ~1 ~70 ~112 ~1 ~70 stone 0  
fill ~98 ~1 ~111 ~98 ~2 ~111 dirt 0  
fill ~99 ~1 ~4 ~108 ~1 ~4 stone 0  
fill ~99 ~1 ~5 ~109 ~1 ~5 stone 0  
fill ~99 ~1 ~51 ~103 ~1 ~51 stone 0  
fill ~99 ~1 ~52 ~100 ~1 ~52 stone 0  
fill ~100 ~1 ~3 ~107 ~1 ~3 stone 0  
fill ~100 ~1 ~53 ~100 ~4 ~53 leaves 0  
fill ~100 ~1 ~54 ~100 ~0 ~54 leaves 0  
fill ~101 ~1 ~2 ~107 ~1 ~2 stone 0  
fill ~101 ~1 ~52 ~101 ~2 ~52 dirt 0 
setblock ~101 ~1 ~54 stone 0  
fill ~101 ~1 ~55 ~103 ~1 ~55 leaves 0  
fill ~102 ~1 ~1 ~102 ~2 ~1 dirt 0 
setblock ~102 ~1 ~52 grass 0  
fill ~102 ~1 ~54 ~104 ~1 ~54 leaves 0  
fill ~102 ~1 ~96 ~103 ~1 ~96 lapis_ore 0  
fill ~103 ~1 ~1 ~106 ~1 ~1 stone 0  
fill ~103 ~1 ~52 ~105 ~1 ~52 stone 0  
fill ~103 ~1 ~53 ~106 ~1 ~53 stone 0 
setblock ~103 ~1 ~97 lapis_ore 0  
fill ~104 ~1 ~55 ~108 ~1 ~55 stone 0  
fill ~104 ~1 ~96 ~107 ~1 ~96 stone 0  
fill ~104 ~1 ~97 ~107 ~1 ~97 stone 0  
fill ~105 ~1 ~51 ~105 ~2 ~51 dirt 0  
fill ~105 ~1 ~54 ~107 ~1 ~54 stone 0  
fill ~106 ~1 ~51 ~112 ~1 ~51 stone 0 
setblock ~106 ~1 ~52 grass 0  
fill ~107 ~1 ~52 ~111 ~1 ~52 dirt 0 
setblock ~107 ~1 ~53 grass 0  
fill ~107 ~1 ~98 ~107 ~2 ~98 dirt 0  
fill ~107 ~1 ~99 ~107 ~2 ~99 dirt 0  
fill ~108 ~1 ~24 ~109 ~1 ~24 coal_ore 0  
fill ~108 ~1 ~53 ~113 ~1 ~53 dirt 0 
setblock ~108 ~1 ~54 grass 0  
fill ~108 ~1 ~67 ~124 ~1 ~67 dirt 0  
fill ~109 ~1 ~4 ~109 ~0 ~4 dirt 0  
fill ~109 ~1 ~25 ~109 ~2 ~25 coal_ore 0  
fill ~109 ~1 ~50 ~125 ~1 ~50 dirt 0  
fill ~109 ~1 ~54 ~117 ~1 ~54 dirt 0  
fill ~109 ~1 ~55 ~113 ~1 ~55 dirt 0  
fill ~109 ~1 ~66 ~120 ~1 ~66 dirt 0 
setblock ~110 ~1 ~4 grass 0  
fill ~110 ~1 ~5 ~114 ~1 ~5 dirt 0  
fill ~110 ~1 ~24 ~118 ~1 ~24 stone 0  
fill ~110 ~1 ~25 ~119 ~1 ~25 stone 0  
fill ~110 ~1 ~49 ~121 ~1 ~49 dirt 0  
fill ~111 ~1 ~3 ~112 ~1 ~3 grass 0  
fill ~111 ~1 ~4 ~114 ~1 ~4 dirt 0  
fill ~111 ~1 ~6 ~111 ~2 ~6 dirt 0 
setblock ~111 ~1 ~56 dirt 0  
fill ~111 ~1 ~65 ~121 ~1 ~65 dirt 0  
fill ~112 ~1 ~48 ~122 ~1 ~48 dirt 0  
fill ~112 ~1 ~52 ~113 ~1 ~52 stone 0  
fill ~112 ~1 ~56 ~125 ~1 ~56 stone 0  
fill ~112 ~1 ~68 ~123 ~1 ~68 dirt 0  
fill ~113 ~1 ~2 ~114 ~1 ~2 grass 0  
fill ~113 ~1 ~3 ~115 ~1 ~3 dirt 0  
fill ~113 ~1 ~6 ~114 ~1 ~6 dirt 0  
fill ~113 ~1 ~51 ~124 ~1 ~51 dirt 0  
fill ~113 ~1 ~69 ~123 ~1 ~69 dirt 0  
fill ~113 ~1 ~70 ~130 ~1 ~70 dirt 0  
fill ~113 ~1 ~71 ~119 ~1 ~71 dirt 0  
fill ~114 ~1 ~8 ~116 ~1 ~8 dirt 0  
fill ~114 ~1 ~52 ~124 ~1 ~52 dirt 0 
setblock ~114 ~1 ~53 stone 0  
fill ~114 ~1 ~55 ~117 ~1 ~55 stone 0  
fill ~114 ~1 ~72 ~119 ~1 ~72 grass 0  
fill ~115 ~1 ~2 ~121 ~1 ~2 dirt 0  
fill ~115 ~1 ~4 ~124 ~1 ~4 stone 0  
fill ~115 ~1 ~5 ~125 ~1 ~5 stone 0  
fill ~115 ~1 ~6 ~125 ~1 ~6 stone 0  
fill ~115 ~1 ~7 ~115 ~3 ~7 dirt 0  
fill ~115 ~1 ~9 ~117 ~1 ~9 dirt 0  
fill ~115 ~1 ~10 ~118 ~1 ~10 dirt 0  
fill ~115 ~1 ~53 ~119 ~1 ~53 dirt 0  
fill ~115 ~1 ~61 ~121 ~1 ~61 stone 0  
fill ~115 ~1 ~64 ~121 ~1 ~64 dirt 0  
fill ~116 ~1 ~3 ~121 ~1 ~3 stone 0  
fill ~116 ~1 ~7 ~125 ~1 ~7 stone 0  
fill ~116 ~1 ~11 ~116 ~3 ~11 dirt 0  
fill ~116 ~1 ~47 ~122 ~1 ~47 dirt 0  
fill ~116 ~1 ~60 ~122 ~1 ~60 stone 0  
fill ~117 ~1 ~1 ~119 ~1 ~1 grass 0  
fill ~117 ~1 ~8 ~125 ~1 ~8 stone 0  
fill ~117 ~1 ~11 ~117 ~3 ~11 stone 0  
fill ~117 ~1 ~12 ~119 ~1 ~12 dirt 0  
fill ~118 ~1 ~9 ~125 ~1 ~9 stone 0  
fill ~118 ~1 ~11 ~119 ~1 ~11 dirt 0  
fill ~118 ~1 ~13 ~119 ~1 ~13 dirt 0 
setblock ~118 ~1 ~36 coal_ore 0  
fill ~118 ~1 ~54 ~125 ~1 ~54 stone 0  
fill ~119 ~1 ~10 ~126 ~1 ~10 stone 0  
fill ~119 ~1 ~18 ~119 ~2 ~18 coal_ore 0  
fill ~119 ~1 ~19 ~119 ~1 ~18 coal_ore 0 
setblock ~119 ~1 ~24 iron_ore 0  
fill ~119 ~1 ~36 ~128 ~1 ~36 stone 0  
fill ~119 ~1 ~63 ~122 ~1 ~63 dirt 0  
fill ~120 ~1 ~11 ~126 ~1 ~11 stone 0  
fill ~120 ~1 ~12 ~127 ~1 ~12 stone 0  
fill ~120 ~1 ~13 ~127 ~1 ~13 stone 0  
fill ~120 ~1 ~18 ~127 ~1 ~18 stone 0  
fill ~120 ~1 ~19 ~127 ~1 ~19 stone 0  
fill ~120 ~1 ~24 ~121 ~1 ~24 stone 0 
setblock ~120 ~1 ~25 iron_ore 0  
fill ~120 ~1 ~46 ~123 ~1 ~46 dirt 0  
fill ~120 ~1 ~53 ~121 ~1 ~53 stone 0  
fill ~120 ~1 ~62 ~123 ~1 ~62 dirt 0  
fill ~120 ~1 ~71 ~122 ~1 ~71 grass 0  
fill ~121 ~1 ~25 ~123 ~1 ~25 stone 0  
fill ~121 ~1 ~45 ~124 ~1 ~45 dirt 0  
fill ~121 ~1 ~55 ~125 ~1 ~55 stone 0 
setblock ~121 ~1 ~66 stone 0  
fill ~122 ~1 ~3 ~122 ~3 ~3 dirt 0  
fill ~122 ~1 ~21 ~122 ~5 ~21 dirt 0  
fill ~122 ~1 ~24 ~123 ~1 ~24 iron_ore 0 
setblock ~122 ~1 ~49 stone 0  
fill ~122 ~1 ~53 ~124 ~1 ~53 dirt 0  
fill ~122 ~1 ~61 ~123 ~1 ~61 dirt 0  
fill ~122 ~1 ~64 ~133 ~1 ~64 stone 0  
fill ~122 ~1 ~65 ~133 ~1 ~65 stone 0  
fill ~122 ~1 ~66 ~124 ~1 ~66 dirt 0  
fill ~123 ~1 ~44 ~124 ~1 ~44 dirt 0  
fill ~123 ~1 ~47 ~132 ~1 ~47 stone 0  
fill ~123 ~1 ~48 ~132 ~1 ~48 stone 0  
fill ~123 ~1 ~49 ~125 ~1 ~49 dirt 0  
fill ~123 ~1 ~60 ~123 ~4 ~60 dirt 0  
fill ~123 ~1 ~63 ~133 ~1 ~63 stone 0  
fill ~124 ~1 ~21 ~127 ~1 ~21 stone 0  
fill ~124 ~1 ~23 ~127 ~1 ~23 stone 0  
fill ~124 ~1 ~25 ~125 ~1 ~25 dirt 0  
fill ~124 ~1 ~26 ~125 ~1 ~26 dirt 0  
fill ~124 ~1 ~27 ~125 ~1 ~27 dirt 0  
fill ~124 ~1 ~46 ~132 ~1 ~46 stone 0  
fill ~124 ~1 ~60 ~132 ~1 ~60 stone 0  
fill ~124 ~1 ~61 ~132 ~1 ~61 stone 0  
fill ~124 ~1 ~62 ~133 ~1 ~62 stone 0  
fill ~124 ~1 ~68 ~131 ~1 ~68 stone 0  
fill ~124 ~1 ~69 ~128 ~1 ~69 stone 0  
fill ~125 ~1 ~22 ~127 ~1 ~22 stone 0  
fill ~125 ~1 ~24 ~125 ~3 ~24 dirt 0  
fill ~125 ~1 ~28 ~125 ~2 ~28 dirt 0  
fill ~125 ~1 ~34 ~126 ~1 ~34 dirt 0  
fill ~125 ~1 ~44 ~131 ~1 ~44 stone 0  
fill ~125 ~1 ~45 ~132 ~1 ~45 stone 0  
fill ~125 ~1 ~51 ~132 ~1 ~51 stone 0  
fill ~125 ~1 ~52 ~132 ~1 ~52 stone 0  
fill ~125 ~1 ~53 ~131 ~1 ~53 stone 0  
fill ~125 ~1 ~66 ~133 ~1 ~66 stone 0  
fill ~125 ~1 ~67 ~132 ~1 ~67 stone 0  
fill ~126 ~1 ~7 ~126 ~2 ~7 dirt 0  
fill ~126 ~1 ~8 ~127 ~1 ~8 dirt 0  
fill ~126 ~1 ~9 ~127 ~1 ~9 dirt 0  
fill ~126 ~1 ~24 ~127 ~1 ~24 stone 0  
fill ~126 ~1 ~25 ~127 ~1 ~25 stone 0  
fill ~126 ~1 ~26 ~127 ~1 ~26 stone 0  
fill ~126 ~1 ~27 ~127 ~1 ~27 stone 0  
fill ~126 ~1 ~28 ~127 ~1 ~28 stone 0  
fill ~126 ~1 ~32 ~126 ~5 ~32 dirt 0  
fill ~126 ~1 ~33 ~126 ~5 ~33 dirt 0  
fill ~126 ~1 ~49 ~132 ~1 ~49 stone 0  
fill ~126 ~1 ~50 ~132 ~1 ~50 stone 0  
fill ~126 ~1 ~56 ~126 ~1 ~57 coal_ore 0 
setblock ~127 ~1 ~7 grass 0  
fill ~127 ~1 ~10 ~127 ~2 ~10 dirt 0  
fill ~127 ~1 ~11 ~128 ~1 ~11 dirt 0  
fill ~127 ~1 ~32 ~127 ~2 ~32 stone 0  
fill ~127 ~1 ~33 ~127 ~1 ~38 stone 0  
fill ~127 ~1 ~39 ~127 ~1 ~40 coal_ore 0 
setblock ~127 ~1 ~54 grass 0  
fill ~127 ~1 ~55 ~128 ~1 ~55 leaves 0  
fill ~127 ~1 ~56 ~127 ~1 ~69 stone 0 
setblock ~128 ~1 ~10 grass 0  
fill ~128 ~1 ~12 ~128 ~2 ~12 dirt 0  
fill ~128 ~1 ~13 ~129 ~1 ~13 dirt 0  
fill ~128 ~1 ~14 ~129 ~1 ~14 dirt 0  
fill ~128 ~1 ~16 ~129 ~1 ~16 dirt 0  
fill ~128 ~1 ~17 ~129 ~1 ~17 dirt 0  
fill ~128 ~1 ~18 ~129 ~1 ~18 dirt 0  
fill ~128 ~1 ~19 ~129 ~1 ~19 dirt 0  
fill ~128 ~1 ~20 ~129 ~1 ~20 dirt 0  
fill ~128 ~1 ~21 ~129 ~1 ~21 dirt 0  
fill ~128 ~1 ~22 ~129 ~1 ~22 dirt 0  
fill ~128 ~1 ~23 ~129 ~1 ~23 dirt 0  
fill ~128 ~1 ~24 ~129 ~1 ~24 dirt 0  
fill ~128 ~1 ~25 ~129 ~1 ~25 dirt 0  
fill ~128 ~1 ~26 ~128 ~2 ~26 dirt 0  
fill ~128 ~1 ~27 ~128 ~2 ~27 dirt 0  
fill ~128 ~1 ~28 ~129 ~1 ~28 dirt 0  
fill ~128 ~1 ~29 ~129 ~1 ~29 dirt 0  
fill ~128 ~1 ~30 ~129 ~1 ~30 dirt 0  
fill ~128 ~1 ~31 ~129 ~1 ~31 dirt 0  
fill ~128 ~1 ~32 ~129 ~1 ~32 dirt 0  
fill ~128 ~1 ~33 ~129 ~1 ~33 dirt 0  
fill ~128 ~1 ~34 ~129 ~1 ~34 dirt 0  
fill ~128 ~1 ~39 ~130 ~1 ~39 stone 0  
fill ~128 ~1 ~40 ~130 ~1 ~40 stone 0  
fill ~128 ~1 ~54 ~128 ~9 ~54 leaves 0  
fill ~128 ~1 ~57 ~132 ~1 ~57 stone 0 
setblock ~129 ~1 ~12 grass 0  
fill ~129 ~1 ~26 ~129 ~1 ~27 grass 0  
fill ~129 ~1 ~36 ~130 ~1 ~36 dirt 0  
fill ~129 ~1 ~54 ~129 ~4 ~54 dirt 0  
fill ~129 ~1 ~55 ~132 ~1 ~55 stone 0  
fill ~129 ~1 ~56 ~132 ~1 ~56 stone 0  
fill ~129 ~1 ~69 ~131 ~1 ~69 dirt 0  
fill ~130 ~1 ~31 ~130 ~1 ~34 grass 0 
setblock ~130 ~1 ~35 dirt 0  
fill ~130 ~1 ~37 ~131 ~1 ~37 dirt 0  
fill ~130 ~1 ~54 ~132 ~1 ~54 stone 0  
fill ~131 ~1 ~35 ~131 ~1 ~36 grass 0  
fill ~131 ~1 ~38 ~131 ~2 ~38 dirt 0  
fill ~131 ~1 ~39 ~132 ~1 ~39 dirt 0  
fill ~131 ~1 ~40 ~132 ~1 ~40 dirt 0 
setblock ~131 ~1 ~70 grass 0  
fill ~132 ~1 ~37 ~132 ~1 ~38 grass 0  
fill ~132 ~1 ~41 ~132 ~2 ~41 dirt 0  
fill ~132 ~1 ~42 ~132 ~2 ~42 dirt 0  
fill ~132 ~1 ~43 ~133 ~1 ~43 dirt 0  
fill ~132 ~1 ~44 ~133 ~1 ~44 dirt 0  
fill ~132 ~1 ~53 ~133 ~1 ~53 dirt 0 
setblock ~132 ~1 ~68 dirt 0 
setblock ~132 ~1 ~69 grass 0  
fill ~133 ~1 ~39 ~133 ~1 ~42 grass 0  
fill ~133 ~1 ~45 ~133 ~2 ~45 dirt 0  
fill ~133 ~1 ~46 ~133 ~4 ~46 dirt 0  
fill ~133 ~1 ~47 ~133 ~4 ~47 dirt 0  
fill ~133 ~1 ~48 ~133 ~3 ~48 dirt 0  
fill ~133 ~1 ~49 ~133 ~2 ~49 dirt 0  
fill ~133 ~1 ~50 ~133 ~2 ~50 dirt 0  
fill ~133 ~1 ~51 ~133 ~2 ~51 dirt 0  
fill ~133 ~1 ~52 ~133 ~2 ~52 dirt 0  
fill ~133 ~1 ~54 ~133 ~1 ~61 dirt 0 
setblock ~133 ~1 ~67 dirt 0 
setblock ~133 ~1 ~68 grass 0  
fill ~134 ~1 ~45 ~134 ~1 ~52 grass 0  
fill ~134 ~1 ~56 ~134 ~1 ~67 grass 0  
fill ~3 ~2 ~99 ~6 ~2 ~99 grass 0  
fill ~3 ~2 ~100 ~6 ~2 ~100 grass 0  
fill ~3 ~2 ~101 ~6 ~2 ~101 grass 0 
setblock ~4 ~2 ~69 grass 0  
fill ~4 ~2 ~70 ~8 ~2 ~70 stone 0  
fill ~4 ~2 ~71 ~8 ~2 ~71 stone 0  
fill ~4 ~2 ~72 ~8 ~2 ~72 stone 0  
fill ~4 ~2 ~73 ~7 ~2 ~73 stone 0  
fill ~4 ~2 ~74 ~7 ~2 ~74 stone 0 
setblock ~4 ~2 ~75 grass 0  
fill ~4 ~2 ~102 ~6 ~2 ~102 grass 0  
fill ~4 ~2 ~103 ~7 ~2 ~103 grass 0  
fill ~5 ~2 ~69 ~7 ~2 ~69 stone 0  
fill ~5 ~2 ~75 ~7 ~2 ~75 stone 0  
fill ~5 ~2 ~76 ~9 ~2 ~76 stone 0  
fill ~5 ~2 ~77 ~20 ~2 ~77 stone 0  
fill ~5 ~2 ~78 ~19 ~2 ~78 stone 0 
setblock ~5 ~2 ~98 grass 0  
fill ~5 ~2 ~104 ~7 ~2 ~104 grass 0 
setblock ~6 ~2 ~68 grass 0  
fill ~6 ~2 ~91 ~13 ~2 ~91 stone 0  
fill ~6 ~2 ~92 ~12 ~2 ~92 stone 0  
fill ~6 ~2 ~93 ~11 ~2 ~93 stone 0  
fill ~6 ~2 ~96 ~13 ~2 ~96 stone 0  
fill ~6 ~2 ~97 ~13 ~2 ~97 stone 0  
fill ~6 ~2 ~98 ~13 ~2 ~98 stone 0  
fill ~6 ~2 ~105 ~7 ~2 ~105 grass 0  
fill ~6 ~2 ~106 ~8 ~2 ~106 grass 0  
fill ~7 ~2 ~79 ~18 ~2 ~79 stone 0 
setblock ~7 ~2 ~87 grass 0 
setblock ~7 ~2 ~88 stone 0 
setblock ~7 ~2 ~89 grass 0  
fill ~7 ~2 ~90 ~14 ~2 ~90 stone 0  
fill ~7 ~2 ~94 ~12 ~2 ~94 stone 0  
fill ~7 ~2 ~95 ~12 ~2 ~95 stone 0  
fill ~7 ~2 ~99 ~13 ~2 ~99 stone 0  
fill ~7 ~2 ~100 ~13 ~2 ~100 stone 0  
fill ~7 ~2 ~101 ~13 ~2 ~101 stone 0 
setblock ~7 ~2 ~102 dirt 0  
fill ~7 ~2 ~107 ~9 ~2 ~107 grass 0 
setblock ~8 ~2 ~69 grass 0  
fill ~8 ~2 ~73 ~8 ~4 ~73 dirt 0  
fill ~8 ~2 ~74 ~9 ~2 ~74 dirt 0  
fill ~8 ~2 ~75 ~8 ~2 ~73 dirt 0  
fill ~8 ~2 ~80 ~19 ~2 ~80 stone 0  
fill ~8 ~2 ~81 ~19 ~2 ~81 stone 0 
setblock ~8 ~2 ~82 grass 0 
setblock ~8 ~2 ~85 grass 0  
fill ~8 ~2 ~86 ~16 ~2 ~86 stone 0  
fill ~8 ~2 ~89 ~14 ~2 ~89 stone 0  
fill ~8 ~2 ~102 ~14 ~2 ~102 stone 0  
fill ~8 ~2 ~103 ~9 ~2 ~103 dirt 0  
fill ~8 ~2 ~104 ~8 ~2 ~105 dirt 0  
fill ~8 ~2 ~108 ~10 ~2 ~108 grass 0  
fill ~8 ~2 ~117 ~8 ~2 ~121 grass 0 
setblock ~9 ~2 ~82 dirt 0  
fill ~9 ~2 ~83 ~19 ~2 ~83 stone 0  
fill ~9 ~2 ~84 ~19 ~2 ~84 stone 0  
fill ~9 ~2 ~85 ~18 ~2 ~85 stone 0  
fill ~9 ~2 ~87 ~15 ~2 ~87 stone 0  
fill ~9 ~2 ~104 ~14 ~2 ~104 stone 0  
fill ~9 ~2 ~105 ~9 ~2 ~106 dirt 0  
fill ~9 ~2 ~109 ~10 ~2 ~109 grass 0  
fill ~9 ~2 ~114 ~9 ~2 ~116 grass 0  
fill ~9 ~2 ~117 ~14 ~2 ~117 dirt 0  
fill ~9 ~2 ~118 ~14 ~2 ~118 dirt 0  
fill ~9 ~2 ~119 ~13 ~2 ~119 dirt 0  
fill ~9 ~2 ~120 ~13 ~2 ~120 dirt 0  
fill ~9 ~2 ~121 ~12 ~2 ~121 dirt 0 
setblock ~9 ~2 ~122 grass 0 
setblock ~10 ~2 ~76 grass 0  
fill ~10 ~2 ~88 ~15 ~2 ~88 stone 0  
fill ~10 ~2 ~103 ~14 ~2 ~103 stone 0  
fill ~10 ~2 ~105 ~15 ~2 ~105 stone 0  
fill ~10 ~2 ~106 ~10 ~2 ~107 dirt 0  
fill ~10 ~2 ~110 ~10 ~2 ~113 grass 0  
fill ~10 ~2 ~114 ~15 ~2 ~114 dirt 0  
fill ~10 ~2 ~115 ~15 ~2 ~115 dirt 0  
fill ~10 ~2 ~116 ~15 ~2 ~116 dirt 0  
fill ~10 ~2 ~124 ~90 ~2 ~124 stone 0  
fill ~10 ~2 ~125 ~95 ~2 ~125 stone 0  
fill ~10 ~2 ~126 ~57 ~2 ~126 stone 0  
fill ~10 ~2 ~127 ~15 ~2 ~127 stone 0  
fill ~10 ~2 ~128 ~16 ~2 ~128 stone 0 
setblock ~10 ~2 ~129 grass 0  
fill ~11 ~2 ~66 ~24 ~2 ~66 stone 0  
fill ~11 ~2 ~67 ~24 ~2 ~67 stone 0 
setblock ~11 ~2 ~68 iron_ore 0  
fill ~11 ~2 ~69 ~24 ~2 ~69 stone 0  
fill ~11 ~2 ~70 ~13 ~2 ~70 stone 0  
fill ~11 ~2 ~82 ~19 ~2 ~82 stone 0  
fill ~11 ~2 ~106 ~17 ~2 ~106 stone 0  
fill ~11 ~2 ~107 ~12 ~2 ~107 dirt 0  
fill ~11 ~2 ~108 ~13 ~2 ~108 dirt 0  
fill ~11 ~2 ~109 ~11 ~2 ~107 dirt 0  
fill ~11 ~2 ~110 ~11 ~3 ~110 stone 0  
fill ~11 ~2 ~111 ~11 ~2 ~122 dirt 0  
fill ~11 ~2 ~123 ~87 ~2 ~123 stone 0  
fill ~11 ~2 ~129 ~96 ~2 ~129 stone 0  
fill ~11 ~2 ~130 ~62 ~2 ~130 stone 0  
fill ~11 ~2 ~131 ~62 ~2 ~131 stone 0  
fill ~11 ~2 ~132 ~61 ~2 ~132 stone 0  
fill ~11 ~2 ~133 ~61 ~2 ~133 stone 0  
fill ~12 ~2 ~64 ~24 ~2 ~64 stone 0  
fill ~12 ~2 ~65 ~13 ~2 ~65 stone 0  
fill ~12 ~2 ~68 ~24 ~2 ~68 stone 0  
fill ~12 ~2 ~110 ~13 ~2 ~110 dirt 0  
fill ~12 ~2 ~112 ~13 ~2 ~112 dirt 0  
fill ~12 ~2 ~113 ~13 ~2 ~113 dirt 0  
fill ~12 ~2 ~122 ~45 ~2 ~122 stone 0  
fill ~12 ~2 ~134 ~51 ~2 ~134 stone 0  
fill ~12 ~2 ~135 ~50 ~2 ~135 stone 0  
fill ~13 ~2 ~63 ~24 ~2 ~63 stone 0 
setblock ~13 ~2 ~74 grass 0 
setblock ~13 ~2 ~76 grass 0  
fill ~13 ~2 ~107 ~18 ~2 ~107 stone 0  
fill ~13 ~2 ~121 ~45 ~2 ~121 stone 0  
fill ~13 ~2 ~136 ~50 ~2 ~136 stone 0  
fill ~14 ~2 ~70 ~14 ~5 ~70 dirt 0  
fill ~14 ~2 ~73 ~21 ~2 ~73 stone 0  
fill ~14 ~2 ~74 ~21 ~2 ~74 stone 0  
fill ~14 ~2 ~75 ~20 ~2 ~75 stone 0  
fill ~14 ~2 ~76 ~21 ~2 ~76 stone 0  
fill ~14 ~2 ~108 ~70 ~2 ~108 stone 0  
fill ~14 ~2 ~109 ~14 ~0 ~109 sand 0  
fill ~14 ~2 ~110 ~32 ~2 ~110 stone 0  
fill ~14 ~2 ~111 ~14 ~0 ~111 sand 0  
fill ~14 ~2 ~112 ~15 ~2 ~112 sand 0  
fill ~14 ~2 ~113 ~15 ~2 ~113 sand 0  
fill ~14 ~2 ~119 ~33 ~2 ~119 stone 0  
fill ~14 ~2 ~120 ~84 ~2 ~120 stone 0  
fill ~14 ~2 ~137 ~50 ~2 ~137 stone 0  
fill ~14 ~2 ~138 ~49 ~2 ~138 stone 0 
setblock ~15 ~2 ~57 grass 0  
fill ~15 ~2 ~65 ~24 ~2 ~65 stone 0  
fill ~15 ~2 ~70 ~24 ~2 ~70 stone 0  
fill ~15 ~2 ~71 ~23 ~2 ~71 stone 0  
fill ~15 ~2 ~72 ~22 ~2 ~72 stone 0  
fill ~15 ~2 ~109 ~33 ~2 ~109 stone 0  
fill ~15 ~2 ~111 ~32 ~2 ~111 stone 0  
fill ~15 ~2 ~117 ~83 ~2 ~117 stone 0  
fill ~15 ~2 ~118 ~84 ~2 ~118 stone 0  
fill ~15 ~2 ~139 ~49 ~2 ~139 stone 0  
fill ~16 ~2 ~53 ~27 ~2 ~53 stone 0  
fill ~16 ~2 ~54 ~27 ~2 ~54 stone 0  
fill ~16 ~2 ~55 ~26 ~2 ~55 stone 0  
fill ~16 ~2 ~56 ~25 ~2 ~56 stone 0  
fill ~16 ~2 ~57 ~25 ~2 ~57 stone 0  
fill ~16 ~2 ~58 ~25 ~2 ~58 stone 0  
fill ~16 ~2 ~59 ~24 ~2 ~59 stone 0  
fill ~16 ~2 ~60 ~24 ~2 ~60 stone 0  
fill ~16 ~2 ~61 ~24 ~2 ~61 stone 0  
fill ~16 ~2 ~62 ~24 ~2 ~62 stone 0  
fill ~16 ~2 ~112 ~32 ~2 ~112 stone 0  
fill ~16 ~2 ~113 ~20 ~2 ~113 stone 0  
fill ~16 ~2 ~114 ~19 ~2 ~114 stone 0  
fill ~16 ~2 ~115 ~28 ~2 ~115 stone 0  
fill ~16 ~2 ~116 ~83 ~2 ~116 stone 0 
setblock ~16 ~2 ~127 coal_ore 0 
setblock ~16 ~2 ~140 grass 0  
fill ~17 ~2 ~44 ~27 ~2 ~44 grass 0  
fill ~17 ~2 ~51 ~17 ~0 ~51 dirt 0  
fill ~17 ~2 ~52 ~28 ~2 ~52 stone 0 
setblock ~17 ~2 ~128 coal_ore 0  
fill ~17 ~2 ~140 ~48 ~2 ~140 stone 0  
fill ~18 ~2 ~43 ~18 ~0 ~43 dirt 0  
fill ~18 ~2 ~47 ~20 ~2 ~47 dirt 0  
fill ~18 ~2 ~48 ~20 ~2 ~48 dirt 0  
fill ~18 ~2 ~49 ~20 ~2 ~49 dirt 0  
fill ~18 ~2 ~50 ~29 ~2 ~50 stone 0  
fill ~18 ~2 ~51 ~29 ~2 ~51 stone 0  
fill ~18 ~2 ~127 ~57 ~2 ~127 stone 0  
fill ~18 ~2 ~128 ~57 ~2 ~128 stone 0  
fill ~18 ~2 ~141 ~18 ~3 ~141 dirt 0  
fill ~19 ~2 ~43 ~26 ~2 ~43 grass 0  
fill ~19 ~2 ~79 ~62 ~2 ~79 sand 0  
fill ~19 ~2 ~141 ~46 ~2 ~141 stone 0  
fill ~20 ~2 ~42 ~29 ~2 ~42 grass 0  
fill ~20 ~2 ~78 ~63 ~2 ~78 sand 0  
fill ~20 ~2 ~80 ~62 ~2 ~80 sand 0  
fill ~20 ~2 ~82 ~27 ~2 ~82 sand 0  
fill ~20 ~2 ~114 ~21 ~2 ~114 coal_ore 0  
fill ~21 ~2 ~41 ~29 ~2 ~41 grass 0  
fill ~21 ~2 ~48 ~32 ~2 ~48 stone 0  
fill ~21 ~2 ~49 ~30 ~2 ~49 stone 0  
fill ~21 ~2 ~75 ~25 ~2 ~75 sand 0  
fill ~21 ~2 ~77 ~64 ~2 ~77 sand 0  
fill ~21 ~2 ~81 ~61 ~2 ~81 sand 0  
fill ~21 ~2 ~83 ~28 ~2 ~83 sand 0  
fill ~21 ~2 ~107 ~45 ~2 ~107 stone 0  
fill ~21 ~2 ~113 ~21 ~3 ~113 coal_ore 0  
fill ~22 ~2 ~40 ~30 ~2 ~40 grass 0 
setblock ~22 ~2 ~47 grass 0 
setblock ~22 ~2 ~73 coal_ore 0  
fill ~22 ~2 ~74 ~65 ~2 ~74 sand 0  
fill ~22 ~2 ~76 ~25 ~2 ~76 sand 0  
fill ~22 ~2 ~84 ~27 ~2 ~84 sand 0  
fill ~22 ~2 ~106 ~25 ~2 ~106 sand 0  
fill ~22 ~2 ~113 ~33 ~2 ~113 stone 0  
fill ~22 ~2 ~114 ~35 ~2 ~114 stone 0  
fill ~23 ~2 ~39 ~37 ~2 ~39 grass 0  
fill ~23 ~2 ~45 ~29 ~2 ~45 grass 0  
fill ~23 ~2 ~47 ~33 ~2 ~47 stone 0  
fill ~23 ~2 ~72 ~66 ~2 ~72 dirt 0  
fill ~23 ~2 ~73 ~65 ~2 ~73 sand 0  
fill ~24 ~2 ~38 ~36 ~2 ~38 grass 0 
setblock ~24 ~2 ~46 grass 0  
fill ~24 ~2 ~71 ~67 ~2 ~71 dirt 0  
fill ~24 ~2 ~86 ~25 ~2 ~86 cobblestone 0  
fill ~24 ~2 ~93 ~25 ~2 ~93 cobblestone 0  
fill ~24 ~2 ~94 ~25 ~2 ~94 cobblestone 0  
fill ~24 ~2 ~101 ~25 ~2 ~101 cobblestone 0  
fill ~24 ~2 ~102 ~25 ~2 ~102 cobblestone 0  
fill ~25 ~2 ~46 ~25 ~3 ~46 dirt 0  
fill ~25 ~2 ~59 ~67 ~2 ~59 dirt 0  
fill ~25 ~2 ~60 ~67 ~2 ~60 dirt 0  
fill ~25 ~2 ~61 ~67 ~2 ~61 dirt 0  
fill ~25 ~2 ~62 ~67 ~2 ~62 dirt 0  
fill ~25 ~2 ~63 ~67 ~2 ~63 dirt 0  
fill ~25 ~2 ~64 ~67 ~2 ~64 dirt 0  
fill ~25 ~2 ~65 ~67 ~2 ~65 dirt 0  
fill ~25 ~2 ~66 ~67 ~2 ~66 dirt 0  
fill ~25 ~2 ~67 ~68 ~2 ~67 dirt 0  
fill ~25 ~2 ~68 ~67 ~2 ~68 dirt 0  
fill ~25 ~2 ~69 ~67 ~2 ~69 dirt 0  
fill ~25 ~2 ~70 ~67 ~2 ~70 dirt 0  
fill ~26 ~2 ~37 ~41 ~2 ~37 grass 0  
fill ~26 ~2 ~46 ~35 ~2 ~46 stone 0  
fill ~26 ~2 ~56 ~66 ~2 ~56 dirt 0  
fill ~26 ~2 ~57 ~66 ~2 ~57 dirt 0  
fill ~26 ~2 ~58 ~66 ~2 ~58 dirt 0  
fill ~26 ~2 ~75 ~26 ~2 ~76 stone 0  
fill ~26 ~2 ~86 ~52 ~2 ~86 sand 0  
fill ~27 ~2 ~43 ~27 ~0 ~43 leaves 0  
fill ~27 ~2 ~55 ~65 ~2 ~55 dirt 0  
fill ~27 ~2 ~75 ~65 ~2 ~75 sand 0  
fill ~27 ~2 ~76 ~64 ~2 ~76 sand 0  
fill ~27 ~2 ~85 ~55 ~2 ~85 sand 0  
fill ~27 ~2 ~106 ~28 ~2 ~106 sand 0  
fill ~28 ~2 ~36 ~42 ~2 ~36 grass 0  
fill ~28 ~2 ~43 ~29 ~2 ~43 grass 0 
setblock ~28 ~2 ~44 leaves 0  
fill ~28 ~2 ~53 ~64 ~2 ~53 dirt 0  
fill ~28 ~2 ~54 ~64 ~2 ~54 dirt 0  
fill ~28 ~2 ~142 ~28 ~3 ~142 dirt 0  
fill ~29 ~2 ~44 ~30 ~2 ~44 grass 0  
fill ~29 ~2 ~52 ~63 ~2 ~52 dirt 0  
fill ~29 ~2 ~82 ~59 ~2 ~82 sand 0  
fill ~29 ~2 ~84 ~56 ~2 ~84 sand 0  
fill ~29 ~2 ~106 ~34 ~2 ~106 stone 0  
fill ~29 ~2 ~115 ~30 ~2 ~115 coal_ore 0  
fill ~29 ~2 ~142 ~43 ~2 ~142 stone 0  
fill ~30 ~2 ~35 ~43 ~2 ~35 grass 0  
fill ~30 ~2 ~41 ~31 ~2 ~41 leaves 0  
fill ~30 ~2 ~42 ~34 ~2 ~42 leaves 0  
fill ~30 ~2 ~43 ~32 ~2 ~43 leaves 0  
fill ~30 ~2 ~45 ~34 ~2 ~45 dirt 0  
fill ~30 ~2 ~50 ~62 ~2 ~50 dirt 0  
fill ~30 ~2 ~51 ~62 ~2 ~51 dirt 0  
fill ~30 ~2 ~83 ~58 ~2 ~83 sand 0  
fill ~30 ~2 ~87 ~54 ~2 ~87 sand 0 
setblock ~31 ~2 ~40 leaves 0 
setblock ~31 ~2 ~44 leaves 0  
fill ~31 ~2 ~49 ~61 ~2 ~49 dirt 0  
fill ~31 ~2 ~88 ~54 ~2 ~88 sand 0  
fill ~31 ~2 ~115 ~32 ~2 ~115 stone 0  
fill ~31 ~2 ~143 ~37 ~2 ~143 stone 0  
fill ~32 ~2 ~34 ~33 ~2 ~34 grass 0  
fill ~32 ~2 ~40 ~36 ~2 ~40 grass 0  
fill ~32 ~2 ~41 ~32 ~2 ~34 grass 0 
setblock ~32 ~2 ~44 grass 0  
fill ~33 ~2 ~33 ~37 ~2 ~33 grass 0  
fill ~33 ~2 ~41 ~33 ~6 ~41 leaves 0  
fill ~33 ~2 ~48 ~61 ~2 ~48 dirt 0  
fill ~33 ~2 ~89 ~36 ~2 ~89 sand 0  
fill ~33 ~2 ~110 ~38 ~2 ~110 sand 0  
fill ~33 ~2 ~111 ~33 ~2 ~112 sand 0  
fill ~33 ~2 ~115 ~33 ~4 ~115 iron_ore 0 
setblock ~34 ~2 ~34 dirt 0  
fill ~34 ~2 ~41 ~35 ~2 ~41 grass 0  
fill ~34 ~2 ~47 ~60 ~2 ~47 dirt 0  
fill ~34 ~2 ~109 ~36 ~2 ~109 sand 0  
fill ~34 ~2 ~112 ~42 ~2 ~112 sand 0  
fill ~34 ~2 ~113 ~45 ~2 ~113 sand 0  
fill ~34 ~2 ~115 ~42 ~2 ~115 stone 0 
setblock ~34 ~2 ~119 coal_ore 0  
fill ~35 ~2 ~32 ~36 ~2 ~32 grass 0  
fill ~35 ~2 ~34 ~42 ~2 ~34 grass 0 
setblock ~35 ~2 ~42 grass 0  
fill ~35 ~2 ~44 ~35 ~7 ~44 dirt 0  
fill ~35 ~2 ~45 ~36 ~2 ~45 stone 0 
setblock ~35 ~2 ~90 sand 0  
fill ~35 ~2 ~106 ~39 ~2 ~106 sand 0  
fill ~35 ~2 ~119 ~84 ~2 ~119 stone 0  
fill ~36 ~2 ~41 ~37 ~2 ~41 stone 0  
fill ~36 ~2 ~44 ~39 ~2 ~44 stone 0  
fill ~36 ~2 ~46 ~56 ~2 ~46 dirt 0  
fill ~36 ~2 ~90 ~39 ~2 ~90 stone 0 
setblock ~36 ~2 ~91 sand 0  
fill ~36 ~2 ~111 ~40 ~2 ~111 sand 0  
fill ~36 ~2 ~114 ~47 ~2 ~114 dirt 0 
setblock ~37 ~2 ~31 grass 0  
fill ~37 ~2 ~32 ~40 ~2 ~32 stone 0 
setblock ~37 ~2 ~38 dirt 0  
fill ~37 ~2 ~40 ~42 ~2 ~40 stone 0  
fill ~37 ~2 ~42 ~37 ~3 ~42 stone 0  
fill ~37 ~2 ~43 ~49 ~2 ~43 stone 0  
fill ~37 ~2 ~45 ~55 ~2 ~45 dirt 0  
fill ~37 ~2 ~89 ~39 ~2 ~89 stone 0  
fill ~37 ~2 ~91 ~39 ~2 ~91 stone 0  
fill ~37 ~2 ~109 ~61 ~2 ~109 stone 0  
fill ~38 ~2 ~31 ~40 ~2 ~31 stone 0  
fill ~38 ~2 ~33 ~40 ~2 ~33 stone 0 
setblock ~38 ~2 ~38 grass 0  
fill ~38 ~2 ~39 ~42 ~2 ~39 stone 0  
fill ~38 ~2 ~92 ~39 ~2 ~92 sand 0  
fill ~38 ~2 ~94 ~41 ~2 ~94 sand 0  
fill ~39 ~2 ~30 ~40 ~2 ~30 grass 0  
fill ~39 ~2 ~38 ~125 ~2 ~38 stone 0  
fill ~39 ~2 ~41 ~39 ~3 ~41 stone 0  
fill ~39 ~2 ~42 ~39 ~4 ~42 dirt 0  
fill ~39 ~2 ~95 ~63 ~2 ~95 sand 0  
fill ~39 ~2 ~110 ~66 ~2 ~110 stone 0  
fill ~40 ~2 ~41 ~45 ~2 ~41 dirt 0  
fill ~40 ~2 ~42 ~49 ~2 ~42 stone 0  
fill ~40 ~2 ~44 ~52 ~2 ~44 dirt 0  
fill ~40 ~2 ~89 ~55 ~2 ~89 sand 0  
fill ~40 ~2 ~90 ~55 ~2 ~90 sand 0  
fill ~40 ~2 ~91 ~56 ~2 ~91 sand 0 
setblock ~40 ~2 ~92 stone 0  
fill ~41 ~2 ~29 ~45 ~2 ~29 grass 0 
setblock ~41 ~2 ~30 stone 0  
fill ~41 ~2 ~31 ~45 ~2 ~31 grass 0  
fill ~41 ~2 ~32 ~45 ~2 ~32 grass 0  
fill ~41 ~2 ~33 ~44 ~2 ~33 grass 0  
fill ~41 ~2 ~92 ~56 ~2 ~92 sand 0  
fill ~41 ~2 ~93 ~57 ~2 ~93 sand 0  
fill ~41 ~2 ~111 ~70 ~2 ~111 stone 0  
fill ~42 ~2 ~30 ~45 ~2 ~30 grass 0  
fill ~42 ~2 ~37 ~43 ~2 ~37 stone 0  
fill ~42 ~2 ~96 ~65 ~2 ~96 sand 0 
setblock ~43 ~2 ~34 dirt 0  
fill ~43 ~2 ~36 ~43 ~3 ~36 stone 0  
fill ~43 ~2 ~40 ~44 ~2 ~40 leaves 0  
fill ~43 ~2 ~94 ~62 ~2 ~94 sand 0  
fill ~43 ~2 ~112 ~72 ~2 ~112 stone 0  
fill ~43 ~2 ~115 ~45 ~2 ~115 dirt 0  
fill ~44 ~2 ~28 ~45 ~2 ~28 grass 0 
setblock ~44 ~2 ~34 grass 0  
fill ~44 ~2 ~35 ~44 ~3 ~35 stone 0  
fill ~44 ~2 ~36 ~46 ~2 ~36 dirt 0  
fill ~44 ~2 ~37 ~44 ~5 ~37 leaves 0  
fill ~44 ~2 ~39 ~81 ~2 ~39 stone 0  
fill ~44 ~2 ~97 ~64 ~2 ~97 sand 0  
fill ~44 ~2 ~142 ~44 ~4 ~142 dirt 0  
fill ~45 ~2 ~33 ~46 ~2 ~33 leaves 0  
fill ~45 ~2 ~34 ~46 ~2 ~34 leaves 0  
fill ~45 ~2 ~35 ~45 ~3 ~35 leaves 0 
setblock ~45 ~2 ~37 stone 0  
fill ~45 ~2 ~40 ~124 ~2 ~40 stone 0  
fill ~45 ~2 ~98 ~48 ~2 ~98 sand 0 
setblock ~45 ~2 ~142 grass 0  
fill ~46 ~2 ~25 ~107 ~2 ~25 stone 0  
fill ~46 ~2 ~26 ~73 ~2 ~26 stone 0  
fill ~46 ~2 ~27 ~73 ~2 ~27 stone 0  
fill ~46 ~2 ~28 ~90 ~2 ~28 stone 0  
fill ~46 ~2 ~29 ~83 ~2 ~29 stone 0  
fill ~46 ~2 ~30 ~124 ~2 ~30 stone 0  
fill ~46 ~2 ~31 ~124 ~2 ~31 stone 0  
fill ~46 ~2 ~32 ~124 ~2 ~32 stone 0  
fill ~46 ~2 ~37 ~46 ~4 ~37 leaves 0  
fill ~46 ~2 ~41 ~123 ~2 ~41 stone 0  
fill ~46 ~2 ~107 ~46 ~4 ~107 iron_ore 0  
fill ~46 ~2 ~113 ~61 ~2 ~113 stone 0  
fill ~46 ~2 ~115 ~74 ~2 ~115 stone 0  
fill ~46 ~2 ~121 ~46 ~3 ~121 coal_ore 0  
fill ~46 ~2 ~122 ~46 ~4 ~122 coal_ore 0  
fill ~47 ~2 ~22 ~94 ~2 ~22 stone 0  
fill ~47 ~2 ~23 ~122 ~2 ~23 stone 0  
fill ~47 ~2 ~24 ~107 ~2 ~24 stone 0  
fill ~47 ~2 ~33 ~125 ~2 ~33 stone 0  
fill ~47 ~2 ~34 ~73 ~2 ~34 stone 0  
fill ~47 ~2 ~35 ~124 ~2 ~35 stone 0  
fill ~47 ~2 ~36 ~125 ~2 ~36 stone 0  
fill ~47 ~2 ~37 ~125 ~2 ~37 stone 0  
fill ~47 ~2 ~99 ~48 ~2 ~99 sand 0 
setblock ~47 ~2 ~106 sand 0  
fill ~47 ~2 ~107 ~52 ~2 ~107 stone 0  
fill ~47 ~2 ~121 ~84 ~2 ~121 stone 0  
fill ~47 ~2 ~122 ~57 ~2 ~122 stone 0  
fill ~48 ~2 ~19 ~119 ~2 ~19 stone 0  
fill ~48 ~2 ~20 ~127 ~2 ~20 stone 0  
fill ~48 ~2 ~21 ~121 ~2 ~21 stone 0   
fill ~48 ~2 ~114 ~61 ~2 ~114 stone 0  
fill ~49 ~2 ~18 ~118 ~2 ~18 stone 0  
fill ~50 ~2 ~17 ~127 ~2 ~17 stone 0  
fill ~50 ~2 ~42 ~50 ~2 ~43 coal_ore 0  
fill ~50 ~2 ~98 ~63 ~2 ~98 sand 0  
fill ~51 ~2 ~16 ~120 ~2 ~16 stone 0  
fill ~51 ~2 ~42 ~123 ~2 ~42 stone 0  
fill ~51 ~2 ~43 ~122 ~2 ~43 stone 0  
fill ~51 ~2 ~99 ~53 ~2 ~99 stone 0  
fill ~51 ~2 ~100 ~53 ~2 ~100 stone 0  
fill ~51 ~2 ~101 ~53 ~2 ~101 stone 0  
fill ~51 ~2 ~135 ~51 ~4 ~135 dirt 0  
fill ~52 ~2 ~15 ~118 ~2 ~15 stone 0  
fill ~52 ~2 ~102 ~53 ~2 ~102 sand 0 
setblock ~53 ~2 ~14 grass 0  
fill ~53 ~2 ~44 ~57 ~2 ~44 stone 0  
fill ~53 ~2 ~86 ~67 ~2 ~86 stone 0  
fill ~53 ~2 ~134 ~54 ~2 ~134 dirt 0  
fill ~53 ~2 ~136 ~54 ~2 ~136 grass 0  
fill ~54 ~2 ~14 ~94 ~2 ~14 stone 0  
fill ~54 ~2 ~99 ~62 ~2 ~99 sand 0  
fill ~54 ~2 ~100 ~62 ~2 ~100 sand 0  
fill ~54 ~2 ~101 ~62 ~2 ~101 sand 0 
setblock ~54 ~2 ~102 stone 0  
fill ~54 ~2 ~135 ~55 ~2 ~135 dirt 0  
fill ~55 ~2 ~13 ~107 ~2 ~13 stone 0  
fill ~55 ~2 ~87 ~103 ~2 ~87 stone 0  
fill ~55 ~2 ~88 ~103 ~2 ~88 stone 0  
fill ~55 ~2 ~102 ~61 ~2 ~102 sand 0  
fill ~55 ~2 ~103 ~62 ~2 ~103 sand 0  
fill ~55 ~2 ~134 ~61 ~2 ~134 stone 0 
setblock ~55 ~2 ~136 dirt 0  
fill ~56 ~2 ~45 ~57 ~2 ~45 stone 0  
fill ~56 ~2 ~85 ~103 ~2 ~85 stone 0  
fill ~56 ~2 ~89 ~69 ~2 ~89 stone 0  
fill ~56 ~2 ~90 ~68 ~2 ~90 stone 0 
setblock ~56 ~2 ~107 sand 0 
setblock ~56 ~2 ~135 stone 0 
setblock ~56 ~2 ~136 grass 0  
fill ~57 ~2 ~12 ~77 ~2 ~12 stone 0  
fill ~57 ~2 ~46 ~94 ~2 ~46 stone 0  
fill ~57 ~2 ~84 ~67 ~2 ~84 stone 0  
fill ~57 ~2 ~91 ~66 ~2 ~91 stone 0  
fill ~57 ~2 ~92 ~61 ~2 ~92 stone 0 
setblock ~57 ~2 ~107 stone 0  
fill ~57 ~2 ~135 ~58 ~2 ~135 dirt 0  
fill ~57 ~2 ~141 ~60 ~2 ~141 leaves 2  
fill ~57 ~2 ~143 ~60 ~2 ~143 leaves 2  
fill ~58 ~2 ~44 ~59 ~2 ~44 iron_ore 0  
fill ~58 ~2 ~45 ~59 ~2 ~45 iron_ore 0  
fill ~58 ~2 ~93 ~58 ~15 ~93 stone 0  
fill ~58 ~2 ~107 ~58 ~1 ~107 iron_ore 0  
fill ~58 ~2 ~122 ~59 ~2 ~122 iron_ore 0  
fill ~58 ~2 ~126 ~58 ~2 ~128 coal_ore 0 
setblock ~58 ~2 ~144 leaves 2 
setblock ~59 ~2 ~11 grass 0  
fill ~59 ~2 ~83 ~67 ~2 ~83 stone 0 
setblock ~59 ~2 ~93 sand 0 
setblock ~59 ~2 ~106 iron_ore 0  
fill ~59 ~2 ~107 ~71 ~2 ~107 stone 0  
fill ~59 ~2 ~126 ~96 ~2 ~126 stone 0 
setblock ~59 ~2 ~127 coal_ore 0  
fill ~59 ~2 ~128 ~69 ~2 ~128 stone 0  
fill ~59 ~2 ~135 ~61 ~2 ~135 grass 0  
fill ~60 ~2 ~11 ~64 ~2 ~11 dirt 0  
fill ~60 ~2 ~44 ~121 ~2 ~44 stone 0  
fill ~60 ~2 ~45 ~120 ~2 ~45 stone 0  
fill ~60 ~2 ~82 ~67 ~2 ~82 stone 0  
fill ~60 ~2 ~93 ~60 ~15 ~93 stone 0  
fill ~60 ~2 ~105 ~71 ~2 ~105 stone 0  
fill ~60 ~2 ~106 ~71 ~2 ~106 stone 0  
fill ~60 ~2 ~122 ~86 ~2 ~122 stone 0  
fill ~60 ~2 ~127 ~70 ~2 ~127 stone 0  
fill ~60 ~2 ~142 ~60 ~5 ~142 leaves 2 
setblock ~60 ~2 ~144 leaves 2  
fill ~61 ~2 ~47 ~86 ~2 ~47 stone 0  
fill ~61 ~2 ~93 ~62 ~2 ~93 sand 0  
fill ~61 ~2 ~104 ~63 ~2 ~104 sand 0  
fill ~62 ~2 ~48 ~84 ~2 ~48 stone 0  
fill ~62 ~2 ~49 ~78 ~2 ~49 stone 0  
fill ~62 ~2 ~81 ~110 ~2 ~81 stone 0  
fill ~62 ~2 ~92 ~62 ~0 ~92 sand 0 
setblock ~62 ~2 ~109 coal_ore 0  
fill ~62 ~2 ~113 ~62 ~2 ~114 coal_ore 0  
fill ~62 ~2 ~132 ~66 ~2 ~132 dirt 0  
fill ~62 ~2 ~133 ~66 ~2 ~133 dirt 0  
fill ~62 ~2 ~134 ~66 ~2 ~134 dirt 0  
fill ~62 ~2 ~135 ~66 ~2 ~135 dirt 0  
fill ~62 ~2 ~136 ~62 ~5 ~136 log 0  
fill ~63 ~2 ~50 ~68 ~2 ~50 stone 0  
fill ~63 ~2 ~51 ~72 ~2 ~51 stone 0  
fill ~63 ~2 ~79 ~111 ~2 ~79 stone 0  
fill ~63 ~2 ~80 ~110 ~2 ~80 stone 0  
fill ~63 ~2 ~92 ~64 ~2 ~92 stone 0  
fill ~63 ~2 ~93 ~106 ~2 ~93 stone 0  
fill ~63 ~2 ~94 ~106 ~2 ~94 stone 0  
fill ~63 ~2 ~99 ~75 ~2 ~99 stone 0  
fill ~63 ~2 ~100 ~74 ~2 ~100 stone 0  
fill ~63 ~2 ~101 ~73 ~2 ~101 stone 0  
fill ~63 ~2 ~102 ~73 ~2 ~102 stone 0  
fill ~63 ~2 ~103 ~73 ~2 ~103 stone 0  
fill ~63 ~2 ~109 ~70 ~2 ~109 stone 0  
fill ~63 ~2 ~113 ~72 ~2 ~113 stone 0  
fill ~63 ~2 ~114 ~73 ~2 ~114 stone 0  
fill ~63 ~2 ~130 ~66 ~2 ~130 dirt 0  
fill ~63 ~2 ~131 ~66 ~2 ~131 dirt 0 
setblock ~63 ~2 ~136 grass 0  
fill ~63 ~2 ~143 ~63 ~2 ~144 leaves 0  
