fill ~25 ~-3 ~2 ~30 ~-3 ~2 wool 15
fill ~25 ~-3 ~3 ~30 ~-3 ~3 wool 15
fill ~25 ~-3 ~4 ~30 ~-3 ~4 wool 15
fill ~25 ~-3 ~5 ~30 ~-3 ~5 wool 15
fill ~25 ~-3 ~6 ~30 ~-3 ~6 wool 15
fill ~25 ~-3 ~60 ~30 ~-3 ~60 wool 15
fill ~25 ~-3 ~61 ~30 ~-3 ~61 wool 15
fill ~25 ~-3 ~62 ~30 ~-3 ~62 wool 15
fill ~25 ~-3 ~63 ~30 ~-3 ~63 wool 15
fill ~25 ~-3 ~64 ~30 ~-3 ~64 wool 15
fill ~103 ~-3 ~2 ~108 ~-3 ~2 wool 15
fill ~103 ~-3 ~3 ~103 ~-3 ~7 wool 15
fill ~103 ~-3 ~59 ~103 ~-3 ~64 wool 15
fill ~104 ~-3 ~64 ~108 ~-3 ~64 wool 15
fill ~22 ~-2 ~2 ~33 ~-2 ~2 wool 15
fill ~22 ~-2 ~3 ~24 ~-2 ~3 wool 15
fill ~22 ~-2 ~4 ~24 ~-2 ~4 wool 15
fill ~22 ~-2 ~5 ~24 ~-2 ~5 wool 15
fill ~22 ~-2 ~6 ~24 ~-2 ~6 wool 15
fill ~22 ~-2 ~60 ~24 ~-2 ~60 wool 15
fill ~22 ~-2 ~61 ~24 ~-2 ~61 wool 15
fill ~22 ~-2 ~62 ~24 ~-2 ~62 wool 15
fill ~22 ~-2 ~63 ~24 ~-2 ~63 wool 15
fill ~22 ~-2 ~64 ~33 ~-2 ~64 wool 15
fill ~27 ~-2 ~3 ~28 ~-2 ~3 wool 7
fill ~27 ~-2 ~63 ~28 ~-2 ~63 wool 7
fill ~30 ~-2 ~3 ~33 ~-2 ~3 wool 15
fill ~30 ~-2 ~4 ~33 ~-2 ~4 wool 15
fill ~30 ~-2 ~5 ~33 ~-2 ~5 wool 15
fill ~30 ~-2 ~6 ~33 ~-2 ~6 wool 15
fill ~30 ~-2 ~60 ~33 ~-2 ~60 wool 15
fill ~30 ~-2 ~61 ~33 ~-2 ~61 wool 15
fill ~30 ~-2 ~62 ~33 ~-2 ~62 wool 15
fill ~30 ~-2 ~63 ~33 ~-2 ~63 wool 15
fill ~100 ~-2 ~2 ~111 ~-2 ~2 wool 15
fill ~100 ~-2 ~3 ~102 ~-2 ~3 wool 15
fill ~100 ~-2 ~4 ~102 ~-2 ~4 wool 15
fill ~100 ~-2 ~5 ~102 ~-2 ~5 wool 15
fill ~100 ~-2 ~6 ~102 ~-2 ~6 wool 15
fill ~100 ~-2 ~7 ~102 ~-2 ~7 wool 15
fill ~100 ~-2 ~59 ~102 ~-2 ~59 wool 15
fill ~100 ~-2 ~60 ~102 ~-2 ~60 wool 15
fill ~100 ~-2 ~61 ~102 ~-2 ~61 wool 15
fill ~100 ~-2 ~62 ~102 ~-2 ~62 wool 15
fill ~100 ~-2 ~63 ~102 ~-2 ~63 wool 15
fill ~100 ~-2 ~64 ~111 ~-2 ~64 wool 15
fill ~21 ~-1 ~2 ~25 ~-1 ~2 wool 15
fill ~21 ~-1 ~3 ~21 ~-1 ~6 wool 15
fill ~21 ~-1 ~60 ~21 ~-1 ~64 wool 15
fill ~22 ~-1 ~64 ~25 ~-1 ~64 wool 15
fill ~26 ~-1 ~2 ~29 ~-1 ~2 wool 7
fill ~26 ~-1 ~3 ~29 ~-1 ~3 wool 7
fill ~26 ~-1 ~63 ~29 ~-1 ~63 wool 7
fill ~26 ~-1 ~64 ~29 ~-1 ~64 wool 7
fill ~30 ~-1 ~2 ~34 ~-1 ~2 wool 15
fill ~30 ~-1 ~64 ~34 ~-1 ~64 wool 15
fill ~34 ~-1 ~3 ~34 ~-1 ~6 wool 15
fill ~34 ~-1 ~60 ~34 ~-1 ~64 wool 15
fill ~99 ~-1 ~2 ~103 ~-1 ~2 wool 15
fill ~99 ~-1 ~3 ~99 ~-1 ~7 wool 15
fill ~99 ~-1 ~59 ~99 ~-1 ~64 wool 15
fill ~100 ~-1 ~64 ~103 ~-1 ~64 wool 15
fill ~104 ~-1 ~2 ~107 ~-1 ~2 wool 7
fill ~104 ~-1 ~64 ~107 ~-1 ~64 wool 7
fill ~105 ~-1 ~3 ~106 ~-1 ~3 wool 7
fill ~105 ~-1 ~63 ~106 ~-1 ~63 wool 7
fill ~108 ~-1 ~2 ~112 ~-1 ~2 wool 15
fill ~108 ~-1 ~64 ~112 ~-1 ~64 wool 15
fill ~20 ~0 ~2 ~22 ~0 ~2 wool 15
fill ~20 ~0 ~3 ~20 ~0 ~6 wool 15
fill ~20 ~0 ~60 ~20 ~0 ~64 wool 15
fill ~21 ~0 ~64 ~22 ~0 ~64 wool 15
fill ~23 ~0 ~2 ~26 ~0 ~2 wool 7
fill ~23 ~0 ~64 ~26 ~0 ~64 wool 7
fill ~26 ~0 ~3 ~29 ~0 ~3 wool 7
fill ~26 ~0 ~63 ~29 ~0 ~63 wool 7
fill ~29 ~0 ~2 ~32 ~0 ~2 wool 7
fill ~29 ~0 ~64 ~32 ~0 ~64 wool 7
fill ~33 ~0 ~2 ~35 ~0 ~2 wool 15
fill ~33 ~0 ~64 ~35 ~0 ~64 wool 15
fill ~35 ~0 ~3 ~35 ~0 ~6 wool 15
fill ~35 ~0 ~60 ~35 ~0 ~64 wool 15
fill ~98 ~0 ~2 ~100 ~0 ~2 wool 15
fill ~98 ~0 ~3 ~98 ~0 ~7 wool 15
fill ~98 ~0 ~59 ~98 ~0 ~64 wool 15
fill ~99 ~0 ~64 ~100 ~0 ~64 wool 15
fill ~101 ~0 ~2 ~104 ~0 ~2 wool 7
fill ~101 ~0 ~64 ~104 ~0 ~64 wool 7
fill ~105 ~0 ~3 ~106 ~0 ~3 wool 7
fill ~105 ~0 ~63 ~106 ~0 ~63 wool 7
fill ~107 ~0 ~2 ~110 ~0 ~2 wool 7
fill ~107 ~0 ~64 ~110 ~0 ~64 wool 7
fill ~111 ~0 ~2 ~113 ~0 ~2 wool 15
fill ~111 ~0 ~64 ~113 ~0 ~64 wool 15
fill ~19 ~1 ~2 ~21 ~1 ~2 wool 15
fill ~19 ~1 ~3 ~19 ~1 ~6 wool 15
fill ~19 ~1 ~60 ~19 ~1 ~64 wool 15
fill ~20 ~1 ~64 ~21 ~1 ~64 wool 15
fill ~22 ~1 ~2 ~23 ~1 ~2 wool 7
fill ~22 ~1 ~64 ~23 ~1 ~64 wool 7
fill ~26 ~1 ~3 ~29 ~1 ~3 wool 7
fill ~26 ~1 ~63 ~29 ~1 ~63 wool 7
fill ~27 ~1 ~4 ~28 ~1 ~4 wool 7
fill ~27 ~1 ~62 ~28 ~1 ~62 wool 7
fill ~32 ~1 ~2 ~33 ~1 ~2 wool 7
fill ~32 ~1 ~64 ~33 ~1 ~64 wool 7
fill ~34 ~1 ~2 ~36 ~1 ~2 wool 15
fill ~34 ~1 ~64 ~36 ~1 ~64 wool 15
fill ~36 ~1 ~3 ~36 ~1 ~6 wool 15
fill ~36 ~1 ~60 ~36 ~1 ~64 wool 15
fill ~97 ~1 ~2 ~99 ~1 ~2 wool 15
fill ~97 ~1 ~3 ~97 ~1 ~7 wool 15
fill ~97 ~1 ~59 ~97 ~1 ~64 wool 15
fill ~98 ~1 ~64 ~99 ~1 ~64 wool 15
fill ~100 ~1 ~2 ~101 ~1 ~2 wool 7
fill ~100 ~1 ~64 ~101 ~1 ~64 wool 7
fill ~104 ~1 ~3 ~107 ~1 ~3 wool 7
fill ~104 ~1 ~4 ~104 ~2 ~4 wool 7
fill ~104 ~1 ~62 ~104 ~2 ~62 wool 7
fill ~104 ~1 ~63 ~107 ~1 ~63 wool 7
fill ~107 ~1 ~4 ~107 ~2 ~4 wool 7
fill ~107 ~1 ~62 ~107 ~2 ~62 wool 7
fill ~110 ~1 ~2 ~111 ~1 ~2 wool 7
fill ~110 ~1 ~64 ~111 ~1 ~64 wool 7
fill ~112 ~1 ~2 ~114 ~1 ~2 wool 15
fill ~112 ~1 ~64 ~114 ~1 ~64 wool 15
fill ~18 ~2 ~2 ~20 ~2 ~2 wool 15
fill ~18 ~2 ~3 ~18 ~4 ~3 wool 15
fill ~18 ~2 ~4 ~18 ~4 ~4 wool 15
fill ~18 ~2 ~5 ~18 ~4 ~5 wool 15
fill ~18 ~2 ~6 ~18 ~4 ~6 wool 15
fill ~18 ~2 ~60 ~18 ~4 ~60 wool 15
fill ~18 ~2 ~61 ~18 ~4 ~61 wool 15
fill ~18 ~2 ~62 ~18 ~4 ~62 wool 15
fill ~18 ~2 ~63 ~18 ~4 ~63 wool 15
fill ~18 ~2 ~64 ~20 ~2 ~64 wool 15
fill ~21 ~2 ~2 ~22 ~2 ~2 wool 7
fill ~21 ~2 ~64 ~22 ~2 ~64 wool 7
fill ~23 ~2 ~3 ~23 ~3 ~3 wool 7
fill ~23 ~2 ~63 ~23 ~3 ~63 wool 7
fill ~26 ~2 ~4 ~29 ~2 ~4 wool 7
fill ~26 ~2 ~62 ~29 ~2 ~62 wool 7
fill ~27 ~2 ~3 ~28 ~2 ~3 wool 7
fill ~27 ~2 ~63 ~28 ~2 ~63 wool 7
fill ~32 ~2 ~3 ~32 ~3 ~3 wool 7
fill ~32 ~2 ~63 ~32 ~3 ~63 wool 7
fill ~33 ~2 ~2 ~34 ~2 ~2 wool 7
fill ~33 ~2 ~64 ~34 ~2 ~64 wool 7
fill ~35 ~2 ~2 ~37 ~2 ~2 wool 15
fill ~35 ~2 ~64 ~37 ~2 ~64 wool 15
fill ~37 ~2 ~3 ~37 ~4 ~3 wool 15
fill ~37 ~2 ~4 ~37 ~4 ~4 wool 15
fill ~37 ~2 ~5 ~37 ~4 ~5 wool 15
fill ~37 ~2 ~6 ~37 ~4 ~6 wool 15
fill ~37 ~2 ~60 ~37 ~4 ~60 wool 15
fill ~37 ~2 ~61 ~37 ~4 ~61 wool 15
fill ~37 ~2 ~62 ~37 ~4 ~62 wool 15
fill ~37 ~2 ~63 ~37 ~4 ~63 wool 15
fill ~96 ~2 ~2 ~98 ~2 ~2 wool 15
fill ~96 ~2 ~3 ~96 ~4 ~3 wool 15
fill ~96 ~2 ~4 ~96 ~4 ~4 wool 15
fill ~96 ~2 ~5 ~96 ~4 ~5 wool 15
fill ~96 ~2 ~6 ~96 ~4 ~6 wool 15
fill ~96 ~2 ~7 ~96 ~4 ~7 wool 15
fill ~96 ~2 ~59 ~96 ~4 ~59 wool 15
fill ~96 ~2 ~60 ~96 ~4 ~60 wool 15
fill ~96 ~2 ~61 ~96 ~4 ~61 wool 15
fill ~96 ~2 ~62 ~96 ~4 ~62 wool 15
fill ~96 ~2 ~63 ~96 ~4 ~63 wool 15
fill ~96 ~2 ~64 ~98 ~2 ~64 wool 15
fill ~99 ~2 ~2 ~100 ~2 ~2 wool 7
fill ~99 ~2 ~64 ~100 ~2 ~64 wool 7
fill ~100 ~2 ~3 ~101 ~2 ~3 wool 7
fill ~100 ~2 ~63 ~101 ~2 ~63 wool 7
fill ~105 ~2 ~3 ~106 ~2 ~3 wool 7
fill ~105 ~2 ~4 ~107 ~2 ~4 wool 7
fill ~105 ~2 ~62 ~107 ~2 ~62 wool 7
fill ~105 ~2 ~63 ~106 ~2 ~63 wool 7
fill ~110 ~2 ~3 ~111 ~2 ~3 wool 7
fill ~110 ~2 ~63 ~111 ~2 ~63 wool 7
fill ~111 ~2 ~2 ~112 ~2 ~2 wool 7
fill ~111 ~2 ~64 ~112 ~2 ~64 wool 7
fill ~113 ~2 ~2 ~115 ~2 ~2 wool 15
fill ~113 ~2 ~64 ~115 ~2 ~64 wool 15
fill ~18 ~3 ~2 ~19 ~3 ~2 wool 15
fill ~18 ~3 ~64 ~19 ~3 ~64 wool 15
fill ~20 ~3 ~2 ~21 ~3 ~2 wool 7
fill ~20 ~3 ~64 ~21 ~3 ~64 wool 7
setblock ~22 ~3 ~3 wool 7
setblock ~22 ~3 ~63 wool 7
fill ~23 ~3 ~4 ~24 ~3 ~4 wool 7
fill ~23 ~3 ~62 ~24 ~3 ~62 wool 7
fill ~27 ~3 ~4 ~28 ~3 ~4 wool 7
fill ~27 ~3 ~62 ~28 ~3 ~62 wool 7
fill ~31 ~3 ~4 ~32 ~3 ~4 wool 7
fill ~31 ~3 ~62 ~32 ~3 ~62 wool 7
setblock ~33 ~3 ~3 wool 7
setblock ~33 ~3 ~63 wool 7
fill ~34 ~3 ~2 ~35 ~3 ~2 wool 7
fill ~34 ~3 ~64 ~35 ~3 ~64 wool 7
fill ~36 ~3 ~2 ~37 ~3 ~2 wool 15
fill ~36 ~3 ~64 ~37 ~3 ~64 wool 15
fill ~96 ~3 ~2 ~97 ~3 ~2 wool 15
fill ~96 ~3 ~64 ~97 ~3 ~64 wool 15
fill ~98 ~3 ~2 ~99 ~3 ~2 wool 7
fill ~98 ~3 ~64 ~99 ~3 ~64 wool 7
fill ~100 ~3 ~3 ~101 ~3 ~3 wool 7
fill ~100 ~3 ~63 ~101 ~3 ~63 wool 7
fill ~101 ~3 ~4 ~102 ~3 ~4 wool 7
fill ~101 ~3 ~62 ~102 ~3 ~62 wool 7
fill ~105 ~3 ~4 ~106 ~3 ~4 wool 7
fill ~105 ~3 ~62 ~106 ~3 ~62 wool 7
fill ~109 ~3 ~4 ~110 ~3 ~4 wool 7
fill ~109 ~3 ~62 ~110 ~3 ~62 wool 7
fill ~110 ~3 ~3 ~111 ~3 ~3 wool 7
fill ~110 ~3 ~63 ~111 ~3 ~63 wool 7
fill ~112 ~3 ~2 ~113 ~3 ~2 wool 7
fill ~112 ~3 ~64 ~113 ~3 ~64 wool 7
fill ~114 ~3 ~2 ~115 ~3 ~2 wool 15
fill ~114 ~3 ~64 ~115 ~3 ~64 wool 15
fill ~18 ~4 ~2 ~19 ~4 ~2 wool 15
fill ~18 ~4 ~64 ~19 ~4 ~64 wool 15
fill ~20 ~4 ~2 ~20 ~6 ~2 wool 7
fill ~20 ~4 ~64 ~20 ~6 ~64 wool 7
fill ~23 ~4 ~4 ~25 ~4 ~4 wool 7
fill ~23 ~4 ~62 ~25 ~4 ~62 wool 7
fill ~27 ~4 ~4 ~28 ~4 ~4 wool 7
fill ~27 ~4 ~62 ~28 ~4 ~62 wool 7
fill ~30 ~4 ~4 ~32 ~4 ~4 wool 7
fill ~30 ~4 ~62 ~32 ~4 ~62 wool 7
fill ~35 ~4 ~2 ~35 ~6 ~2 wool 7
fill ~35 ~4 ~58 ~39 ~4 ~58 wool 15
fill ~35 ~4 ~64 ~35 ~6 ~64 wool 7
fill ~36 ~4 ~2 ~37 ~4 ~2 wool 15
fill ~36 ~4 ~64 ~37 ~4 ~64 wool 15
fill ~37 ~4 ~8 ~39 ~4 ~8 wool 15
setblock ~39 ~4 ~3 wool 0
fill ~39 ~4 ~4 ~39 ~4 ~8 wool 15
fill ~39 ~4 ~59 ~39 ~4 ~62 wool 15
setblock ~39 ~4 ~63 wool 0
fill ~40 ~4 ~3 ~92 ~4 ~3 wool 15
fill ~40 ~4 ~63 ~92 ~4 ~63 wool 15
fill ~92 ~4 ~4 ~92 ~4 ~62 wool 7
fill ~93 ~4 ~3 ~93 ~7 ~3 wool 0
fill ~93 ~4 ~63 ~93 ~7 ~63 wool 0
fill ~96 ~4 ~2 ~97 ~4 ~2 wool 15
fill ~96 ~4 ~64 ~97 ~4 ~64 wool 15
fill ~98 ~4 ~2 ~98 ~6 ~2 wool 7
fill ~98 ~4 ~64 ~98 ~6 ~64 wool 7
fill ~101 ~4 ~4 ~103 ~4 ~4 wool 7
fill ~101 ~4 ~62 ~103 ~4 ~62 wool 7
fill ~105 ~4 ~4 ~106 ~4 ~4 wool 7
fill ~105 ~4 ~62 ~106 ~4 ~62 wool 7
fill ~108 ~4 ~4 ~110 ~4 ~4 wool 7
fill ~108 ~4 ~62 ~110 ~4 ~62 wool 7
fill ~113 ~4 ~2 ~113 ~6 ~2 wool 7
fill ~113 ~4 ~64 ~113 ~6 ~64 wool 7
fill ~114 ~4 ~2 ~115 ~4 ~2 wool 15
fill ~114 ~4 ~64 ~115 ~4 ~64 wool 15
fill ~17 ~5 ~2 ~19 ~5 ~2 wool 15
fill ~17 ~5 ~3 ~17 ~10 ~3 wool 15
fill ~17 ~5 ~4 ~17 ~10 ~4 wool 15
fill ~17 ~5 ~5 ~17 ~10 ~5 wool 15
fill ~17 ~5 ~6 ~17 ~10 ~6 wool 15
fill ~17 ~5 ~60 ~17 ~10 ~60 wool 15
fill ~17 ~5 ~61 ~17 ~10 ~61 wool 15
fill ~17 ~5 ~62 ~17 ~10 ~62 wool 15
fill ~17 ~5 ~63 ~17 ~10 ~63 wool 15
fill ~17 ~5 ~64 ~19 ~5 ~64 wool 15
fill ~24 ~5 ~4 ~25 ~5 ~4 wool 7
fill ~24 ~5 ~62 ~25 ~5 ~62 wool 7
fill ~27 ~5 ~4 ~28 ~5 ~4 wool 7
fill ~27 ~5 ~62 ~28 ~5 ~62 wool 7
fill ~30 ~5 ~4 ~31 ~5 ~4 wool 7
fill ~30 ~5 ~62 ~31 ~5 ~62 wool 7
fill ~35 ~5 ~58 ~40 ~5 ~58 wool 15
fill ~36 ~5 ~2 ~38 ~5 ~2 wool 15
fill ~36 ~5 ~64 ~38 ~5 ~64 wool 15
fill ~37 ~5 ~8 ~40 ~5 ~8 wool 15
fill ~38 ~5 ~3 ~38 ~10 ~3 wool 15
fill ~38 ~5 ~4 ~38 ~10 ~4 wool 15
fill ~38 ~5 ~5 ~38 ~10 ~5 wool 15
fill ~38 ~5 ~6 ~38 ~10 ~6 wool 15
fill ~38 ~5 ~60 ~38 ~10 ~60 wool 15
fill ~38 ~5 ~61 ~38 ~10 ~61 wool 15
fill ~38 ~5 ~62 ~38 ~10 ~62 wool 15
fill ~38 ~5 ~63 ~38 ~10 ~63 wool 15
fill ~40 ~5 ~3 ~40 ~7 ~3 wool 0
fill ~40 ~5 ~4 ~40 ~14 ~4 wool 15
fill ~40 ~5 ~5 ~40 ~14 ~5 wool 15
fill ~40 ~5 ~6 ~40 ~14 ~6 wool 15
fill ~40 ~5 ~7 ~40 ~14 ~7 wool 15
fill ~40 ~5 ~59 ~40 ~14 ~59 wool 15
fill ~40 ~5 ~60 ~40 ~14 ~60 wool 15
fill ~40 ~5 ~61 ~40 ~14 ~61 wool 15
fill ~40 ~5 ~62 ~40 ~14 ~62 wool 15
fill ~40 ~5 ~63 ~40 ~7 ~63 wool 0
fill ~41 ~5 ~3 ~92 ~5 ~3 wool 15
fill ~41 ~5 ~63 ~92 ~5 ~63 wool 15
fill ~92 ~5 ~33 ~92 ~9 ~33 wool 7
fill ~95 ~5 ~2 ~97 ~5 ~2 wool 15
fill ~95 ~5 ~3 ~95 ~10 ~3 wool 15
fill ~95 ~5 ~4 ~95 ~10 ~4 wool 15
fill ~95 ~5 ~5 ~95 ~10 ~5 wool 15
fill ~95 ~5 ~6 ~95 ~10 ~6 wool 15
fill ~95 ~5 ~7 ~95 ~11 ~7 wool 15
fill ~95 ~5 ~59 ~95 ~11 ~59 wool 15
fill ~95 ~5 ~60 ~95 ~10 ~60 wool 15
fill ~95 ~5 ~61 ~95 ~10 ~61 wool 15
fill ~95 ~5 ~62 ~95 ~10 ~62 wool 15
fill ~95 ~5 ~63 ~95 ~10 ~63 wool 15
fill ~95 ~5 ~64 ~97 ~5 ~64 wool 15
fill ~102 ~5 ~4 ~103 ~5 ~4 wool 7
fill ~102 ~5 ~62 ~103 ~5 ~62 wool 7
fill ~105 ~5 ~4 ~106 ~5 ~4 wool 7
fill ~105 ~5 ~62 ~106 ~5 ~62 wool 7
fill ~108 ~5 ~4 ~109 ~5 ~4 wool 7
fill ~108 ~5 ~62 ~109 ~5 ~62 wool 7
fill ~114 ~5 ~2 ~116 ~5 ~2 wool 15
fill ~114 ~5 ~64 ~116 ~5 ~64 wool 15
fill ~6 ~6 ~27 ~7 ~6 ~27 wool 0
fill ~6 ~6 ~28 ~6 ~7 ~28 wool 0
fill ~6 ~6 ~29 ~6 ~7 ~29 wool 0
fill ~6 ~6 ~30 ~6 ~7 ~30 wool 0
fill ~6 ~6 ~31 ~6 ~7 ~31 wool 0
fill ~6 ~6 ~32 ~6 ~7 ~32 wool 0
fill ~6 ~6 ~33 ~6 ~7 ~33 wool 0
fill ~6 ~6 ~34 ~6 ~7 ~34 wool 0
fill ~6 ~6 ~35 ~6 ~7 ~35 wool 0
fill ~6 ~6 ~36 ~6 ~7 ~36 wool 0
fill ~6 ~6 ~37 ~6 ~7 ~37 wool 0
fill ~6 ~6 ~38 ~6 ~7 ~38 wool 0
fill ~6 ~6 ~39 ~7 ~6 ~39 wool 0
fill ~7 ~6 ~22 ~8 ~6 ~22 wool 0
fill ~7 ~6 ~23 ~7 ~7 ~23 wool 0
fill ~7 ~6 ~24 ~7 ~7 ~24 wool 0
fill ~7 ~6 ~25 ~7 ~7 ~25 wool 0
fill ~7 ~6 ~26 ~7 ~7 ~26 wool 0
fill ~7 ~6 ~40 ~7 ~7 ~40 wool 0
fill ~7 ~6 ~41 ~7 ~7 ~41 wool 0
fill ~7 ~6 ~42 ~7 ~7 ~42 wool 0
fill ~7 ~6 ~43 ~7 ~7 ~43 wool 0
fill ~7 ~6 ~44 ~8 ~6 ~44 wool 0
fill ~8 ~6 ~3 ~10 ~6 ~3 wool 0
fill ~8 ~6 ~4 ~8 ~7 ~4 wool 0
fill ~8 ~6 ~5 ~8 ~7 ~5 wool 0
fill ~8 ~6 ~6 ~8 ~7 ~6 wool 0
fill ~8 ~6 ~7 ~8 ~7 ~7 wool 0
fill ~8 ~6 ~8 ~8 ~7 ~8 wool 0
fill ~8 ~6 ~9 ~8 ~7 ~9 wool 0
fill ~8 ~6 ~10 ~8 ~7 ~10 wool 0
fill ~8 ~6 ~11 ~8 ~7 ~11 wool 0
fill ~8 ~6 ~12 ~8 ~7 ~12 wool 0
fill ~8 ~6 ~13 ~8 ~7 ~13 wool 0
fill ~8 ~6 ~14 ~8 ~7 ~14 wool 0
fill ~8 ~6 ~15 ~8 ~7 ~15 wool 0
fill ~8 ~6 ~16 ~8 ~7 ~16 wool 0
fill ~8 ~6 ~17 ~8 ~7 ~17 wool 0
fill ~8 ~6 ~18 ~8 ~7 ~18 wool 0
fill ~8 ~6 ~19 ~8 ~7 ~19 wool 0
fill ~8 ~6 ~20 ~8 ~7 ~20 wool 0
fill ~8 ~6 ~21 ~8 ~7 ~21 wool 0
fill ~8 ~6 ~45 ~8 ~7 ~45 wool 0
fill ~8 ~6 ~46 ~8 ~7 ~46 wool 0
fill ~8 ~6 ~47 ~8 ~7 ~47 wool 0
fill ~8 ~6 ~48 ~8 ~7 ~48 wool 0
fill ~8 ~6 ~49 ~8 ~7 ~49 wool 0
fill ~8 ~6 ~50 ~8 ~7 ~50 wool 0
fill ~8 ~6 ~51 ~8 ~7 ~51 wool 0
fill ~8 ~6 ~52 ~8 ~7 ~52 wool 0
fill ~8 ~6 ~53 ~8 ~7 ~53 wool 0
fill ~8 ~6 ~54 ~8 ~7 ~54 wool 0
fill ~8 ~6 ~55 ~8 ~7 ~55 wool 0
fill ~8 ~6 ~56 ~8 ~7 ~56 wool 0
fill ~8 ~6 ~57 ~8 ~7 ~57 wool 0
fill ~8 ~6 ~58 ~8 ~7 ~58 wool 0
fill ~8 ~6 ~59 ~8 ~7 ~59 wool 0
fill ~8 ~6 ~60 ~8 ~7 ~60 wool 0
fill ~8 ~6 ~61 ~8 ~7 ~61 wool 0
fill ~8 ~6 ~62 ~8 ~7 ~62 wool 0
fill ~8 ~6 ~63 ~10 ~6 ~63 wool 0
fill ~11 ~6 ~3 ~14 ~6 ~3 wool 15
fill ~11 ~6 ~63 ~14 ~6 ~63 wool 15
fill ~15 ~6 ~3 ~15 ~10 ~3 wool 0
fill ~15 ~6 ~4 ~15 ~16 ~4 wool 15
fill ~15 ~6 ~5 ~15 ~16 ~5 wool 15
fill ~15 ~6 ~6 ~15 ~16 ~6 wool 15
fill ~15 ~6 ~7 ~15 ~16 ~7 wool 15
fill ~15 ~6 ~8 ~18 ~6 ~8 wool 15
fill ~15 ~6 ~58 ~20 ~6 ~58 wool 15
fill ~15 ~6 ~59 ~15 ~12 ~59 wool 15
fill ~15 ~6 ~60 ~15 ~15 ~60 wool 15
fill ~15 ~6 ~61 ~15 ~15 ~61 wool 15
fill ~15 ~6 ~62 ~15 ~15 ~62 wool 15
fill ~15 ~6 ~63 ~15 ~10 ~63 wool 0
fill ~17 ~6 ~2 ~18 ~6 ~2 wool 15
fill ~17 ~6 ~64 ~18 ~6 ~64 wool 15
fill ~19 ~6 ~2 ~19 ~9 ~2 wool 7
fill ~19 ~6 ~3 ~21 ~6 ~3 wool 7
fill ~19 ~6 ~63 ~21 ~6 ~63 wool 7
fill ~19 ~6 ~64 ~19 ~9 ~64 wool 7
fill ~22 ~6 ~4 ~22 ~9 ~4 wool 7
fill ~22 ~6 ~62 ~22 ~9 ~62 wool 7
setblock ~26 ~6 ~3 wool 15
setblock ~26 ~6 ~63 wool 15
fill ~27 ~6 ~3 ~28 ~6 ~3 wool 7
fill ~27 ~6 ~63 ~28 ~6 ~63 wool 7
setblock ~29 ~6 ~3 wool 15
setblock ~29 ~6 ~63 wool 15
fill ~33 ~6 ~4 ~33 ~9 ~4 wool 7
fill ~33 ~6 ~62 ~33 ~9 ~62 wool 7
fill ~34 ~6 ~3 ~34 ~9 ~3 wool 7
fill ~34 ~6 ~63 ~34 ~9 ~63 wool 7
fill ~35 ~6 ~58 ~40 ~6 ~58 wool 15
fill ~36 ~6 ~2 ~36 ~9 ~2 wool 7
fill ~36 ~6 ~64 ~36 ~9 ~64 wool 7
fill ~37 ~6 ~2 ~38 ~6 ~2 wool 15
fill ~37 ~6 ~8 ~40 ~6 ~8 wool 15
fill ~37 ~6 ~64 ~38 ~6 ~64 wool 15
fill ~41 ~6 ~3 ~92 ~6 ~3 wool 15
fill ~41 ~6 ~63 ~92 ~6 ~63 wool 15
fill ~55 ~6 ~4 ~77 ~6 ~4 wool 7
fill ~55 ~6 ~5 ~92 ~6 ~5 wool 7
fill ~55 ~6 ~6 ~92 ~6 ~6 wool 7
fill ~55 ~6 ~7 ~63 ~6 ~7 wool 7
fill ~55 ~6 ~8 ~63 ~6 ~8 wool 7
fill ~55 ~6 ~9 ~63 ~6 ~9 wool 7
fill ~55 ~6 ~10 ~63 ~6 ~10 wool 7
fill ~55 ~6 ~11 ~63 ~6 ~11 wool 7
fill ~55 ~6 ~12 ~63 ~6 ~12 wool 7
fill ~55 ~6 ~13 ~63 ~6 ~13 wool 7
fill ~55 ~6 ~14 ~63 ~6 ~14 wool 7
fill ~55 ~6 ~15 ~63 ~6 ~15 wool 7
fill ~55 ~6 ~16 ~63 ~6 ~16 wool 7
fill ~55 ~6 ~17 ~63 ~6 ~17 wool 7
fill ~55 ~6 ~18 ~63 ~6 ~18 wool 7
fill ~55 ~6 ~19 ~63 ~6 ~19 wool 7
fill ~55 ~6 ~20 ~63 ~6 ~20 wool 7
fill ~55 ~6 ~21 ~63 ~6 ~21 wool 7
fill ~55 ~6 ~22 ~63 ~6 ~22 wool 7
fill ~55 ~6 ~23 ~63 ~6 ~23 wool 7
fill ~55 ~6 ~24 ~63 ~6 ~24 wool 7
fill ~55 ~6 ~25 ~63 ~6 ~25 wool 7
fill ~55 ~6 ~26 ~63 ~6 ~26 wool 7
fill ~55 ~6 ~27 ~85 ~6 ~27 wool 7
fill ~55 ~6 ~28 ~85 ~6 ~28 wool 7
fill ~55 ~6 ~29 ~63 ~6 ~29 wool 7
fill ~55 ~6 ~30 ~63 ~6 ~30 wool 7
fill ~55 ~6 ~36 ~63 ~6 ~36 wool 7
fill ~55 ~6 ~37 ~63 ~6 ~37 wool 7
fill ~55 ~6 ~38 ~85 ~6 ~38 wool 7
fill ~55 ~6 ~39 ~85 ~6 ~39 wool 7
fill ~55 ~6 ~40 ~63 ~6 ~40 wool 7
fill ~55 ~6 ~41 ~63 ~6 ~41 wool 7
fill ~55 ~6 ~42 ~63 ~6 ~42 wool 7
fill ~55 ~6 ~43 ~63 ~6 ~43 wool 7
fill ~55 ~6 ~44 ~63 ~6 ~44 wool 7
fill ~55 ~6 ~45 ~63 ~6 ~45 wool 7
fill ~55 ~6 ~46 ~63 ~6 ~46 wool 7
fill ~55 ~6 ~47 ~63 ~6 ~47 wool 7
fill ~55 ~6 ~48 ~63 ~6 ~48 wool 7
fill ~55 ~6 ~49 ~63 ~6 ~49 wool 7
fill ~55 ~6 ~50 ~63 ~6 ~50 wool 7
fill ~55 ~6 ~51 ~63 ~6 ~51 wool 7
fill ~55 ~6 ~52 ~63 ~6 ~52 wool 7
fill ~55 ~6 ~53 ~63 ~6 ~53 wool 7
fill ~55 ~6 ~54 ~63 ~6 ~54 wool 7
fill ~55 ~6 ~55 ~63 ~6 ~55 wool 7
fill ~55 ~6 ~56 ~63 ~6 ~56 wool 7
fill ~55 ~6 ~57 ~63 ~6 ~57 wool 7
fill ~55 ~6 ~58 ~63 ~6 ~58 wool 7
fill ~55 ~6 ~59 ~63 ~6 ~59 wool 7
fill ~55 ~6 ~60 ~92 ~6 ~60 wool 7
fill ~55 ~6 ~61 ~92 ~6 ~61 wool 7
fill ~55 ~6 ~62 ~77 ~6 ~62 wool 7
fill ~62 ~6 ~31 ~63 ~6 ~31 wool 7
fill ~62 ~6 ~32 ~92 ~6 ~32 wool 7
fill ~62 ~6 ~33 ~92 ~6 ~33 wool 7
fill ~62 ~6 ~34 ~92 ~6 ~34 wool 7
fill ~62 ~6 ~35 ~63 ~6 ~35 wool 7
fill ~74 ~6 ~26 ~85 ~6 ~26 wool 7
fill ~74 ~6 ~40 ~85 ~6 ~40 wool 7
fill ~75 ~6 ~7 ~92 ~6 ~7 wool 7
fill ~75 ~6 ~59 ~92 ~6 ~59 wool 7
fill ~76 ~6 ~8 ~85 ~6 ~8 wool 7
fill ~76 ~6 ~9 ~85 ~6 ~9 wool 7
fill ~76 ~6 ~10 ~85 ~6 ~10 wool 7
fill ~76 ~6 ~11 ~85 ~6 ~11 wool 7
fill ~76 ~6 ~12 ~85 ~6 ~12 wool 7
fill ~76 ~6 ~13 ~85 ~6 ~13 wool 7
fill ~76 ~6 ~14 ~85 ~6 ~14 wool 7
fill ~76 ~6 ~15 ~85 ~6 ~15 wool 7
fill ~76 ~6 ~16 ~85 ~6 ~16 wool 7
fill ~76 ~6 ~17 ~85 ~6 ~17 wool 7
fill ~76 ~6 ~18 ~85 ~6 ~18 wool 7
fill ~76 ~6 ~19 ~85 ~6 ~19 wool 7
fill ~76 ~6 ~20 ~85 ~6 ~20 wool 7
fill ~76 ~6 ~21 ~85 ~6 ~21 wool 7
fill ~76 ~6 ~22 ~85 ~6 ~22 wool 7
fill ~76 ~6 ~23 ~85 ~6 ~23 wool 7
fill ~76 ~6 ~24 ~85 ~6 ~24 wool 7
fill ~76 ~6 ~25 ~85 ~6 ~25 wool 7
fill ~76 ~6 ~41 ~85 ~6 ~41 wool 7
fill ~76 ~6 ~42 ~85 ~6 ~42 wool 7
fill ~76 ~6 ~43 ~85 ~6 ~43 wool 7
fill ~76 ~6 ~44 ~85 ~6 ~44 wool 7
fill ~76 ~6 ~45 ~85 ~6 ~45 wool 7
fill ~76 ~6 ~46 ~85 ~6 ~46 wool 7
fill ~76 ~6 ~47 ~85 ~6 ~47 wool 7
fill ~76 ~6 ~48 ~85 ~6 ~48 wool 7
fill ~76 ~6 ~49 ~85 ~6 ~49 wool 7
fill ~76 ~6 ~50 ~85 ~6 ~50 wool 7
fill ~76 ~6 ~51 ~85 ~6 ~51 wool 7
fill ~76 ~6 ~52 ~85 ~6 ~52 wool 7
fill ~76 ~6 ~53 ~85 ~6 ~53 wool 7
fill ~76 ~6 ~54 ~85 ~6 ~54 wool 7
fill ~76 ~6 ~55 ~85 ~6 ~55 wool 7
fill ~76 ~6 ~56 ~85 ~6 ~56 wool 7
fill ~76 ~6 ~57 ~85 ~6 ~57 wool 7
fill ~76 ~6 ~58 ~85 ~6 ~58 wool 7
fill ~79 ~6 ~29 ~85 ~6 ~29 wool 7
fill ~79 ~6 ~30 ~85 ~6 ~30 wool 7
fill ~79 ~6 ~36 ~85 ~6 ~36 wool 7
fill ~79 ~6 ~37 ~85 ~6 ~37 wool 7
fill ~80 ~6 ~31 ~85 ~6 ~31 wool 7
fill ~80 ~6 ~35 ~85 ~6 ~35 wool 7
fill ~92 ~6 ~4 ~92 ~9 ~4 wool 7
fill ~92 ~6 ~8 ~92 ~9 ~8 wool 7
fill ~92 ~6 ~9 ~92 ~9 ~9 wool 7
fill ~92 ~6 ~10 ~92 ~9 ~10 wool 7
fill ~92 ~6 ~11 ~92 ~9 ~11 wool 7
fill ~92 ~6 ~12 ~92 ~9 ~12 wool 7
fill ~92 ~6 ~13 ~92 ~9 ~13 wool 7
fill ~92 ~6 ~14 ~92 ~9 ~14 wool 7
fill ~92 ~6 ~15 ~92 ~9 ~15 wool 7
fill ~92 ~6 ~16 ~92 ~9 ~16 wool 7
fill ~92 ~6 ~17 ~92 ~9 ~17 wool 7
fill ~92 ~6 ~18 ~92 ~9 ~18 wool 7
fill ~92 ~6 ~19 ~92 ~9 ~19 wool 7
fill ~92 ~6 ~20 ~92 ~9 ~20 wool 7
fill ~92 ~6 ~21 ~92 ~9 ~21 wool 7
fill ~92 ~6 ~22 ~92 ~9 ~22 wool 7
fill ~92 ~6 ~23 ~92 ~9 ~23 wool 7
fill ~92 ~6 ~24 ~92 ~9 ~24 wool 7
fill ~92 ~6 ~25 ~92 ~9 ~25 wool 7
fill ~92 ~6 ~26 ~92 ~9 ~26 wool 7
fill ~92 ~6 ~27 ~92 ~9 ~27 wool 7
fill ~92 ~6 ~28 ~92 ~9 ~28 wool 7
fill ~92 ~6 ~29 ~92 ~9 ~29 wool 7
fill ~92 ~6 ~30 ~92 ~9 ~30 wool 7
fill ~92 ~6 ~31 ~92 ~9 ~31 wool 7
fill ~92 ~6 ~35 ~92 ~9 ~35 wool 7
fill ~92 ~6 ~36 ~92 ~9 ~36 wool 7
fill ~92 ~6 ~37 ~92 ~9 ~37 wool 7
fill ~92 ~6 ~38 ~92 ~9 ~38 wool 7
fill ~92 ~6 ~39 ~92 ~9 ~39 wool 7
fill ~92 ~6 ~40 ~92 ~9 ~40 wool 7
fill ~92 ~6 ~41 ~92 ~9 ~41 wool 7
fill ~92 ~6 ~42 ~92 ~9 ~42 wool 7
fill ~92 ~6 ~43 ~92 ~9 ~43 wool 7
fill ~92 ~6 ~44 ~92 ~9 ~44 wool 7
fill ~92 ~6 ~45 ~92 ~9 ~45 wool 7
fill ~92 ~6 ~46 ~92 ~9 ~46 wool 7
fill ~92 ~6 ~47 ~92 ~9 ~47 wool 7
fill ~92 ~6 ~48 ~92 ~9 ~48 wool 7
fill ~92 ~6 ~49 ~92 ~9 ~49 wool 7
fill ~92 ~6 ~50 ~92 ~9 ~50 wool 7
fill ~92 ~6 ~51 ~92 ~9 ~51 wool 7
fill ~92 ~6 ~52 ~92 ~9 ~52 wool 7
fill ~92 ~6 ~53 ~92 ~9 ~53 wool 7
fill ~92 ~6 ~54 ~92 ~9 ~54 wool 7
fill ~92 ~6 ~55 ~92 ~9 ~55 wool 7
fill ~92 ~6 ~56 ~92 ~9 ~56 wool 7
fill ~92 ~6 ~57 ~92 ~9 ~57 wool 7
fill ~92 ~6 ~58 ~92 ~9 ~58 wool 7
fill ~92 ~6 ~62 ~92 ~9 ~62 wool 7
fill ~95 ~6 ~2 ~96 ~6 ~2 wool 15
fill ~95 ~6 ~64 ~96 ~6 ~64 wool 15
fill ~97 ~6 ~2 ~97 ~9 ~2 wool 7
fill ~97 ~6 ~64 ~97 ~9 ~64 wool 7
fill ~99 ~6 ~3 ~99 ~9 ~3 wool 7
fill ~99 ~6 ~4 ~100 ~6 ~4 wool 7
fill ~99 ~6 ~62 ~100 ~6 ~62 wool 7
fill ~99 ~6 ~63 ~99 ~9 ~63 wool 7
setblock ~104 ~6 ~3 wool 15
setblock ~104 ~6 ~63 wool 15
fill ~105 ~6 ~3 ~106 ~6 ~3 wool 7
fill ~105 ~6 ~4 ~106 ~6 ~4 wool 7
fill ~105 ~6 ~62 ~106 ~6 ~62 wool 7
fill ~105 ~6 ~63 ~106 ~6 ~63 wool 7
setblock ~107 ~6 ~3 wool 15
setblock ~107 ~6 ~63 wool 15
fill ~111 ~6 ~4 ~112 ~6 ~4 wool 7
fill ~111 ~6 ~62 ~112 ~6 ~62 wool 7
fill ~112 ~6 ~3 ~112 ~9 ~3 wool 7
fill ~112 ~6 ~63 ~112 ~9 ~63 wool 7
fill ~114 ~6 ~2 ~114 ~9 ~2 wool 7
fill ~114 ~6 ~64 ~114 ~9 ~64 wool 7
fill ~115 ~6 ~2 ~116 ~6 ~2 wool 15
fill ~115 ~6 ~8 ~118 ~6 ~8 wool 15
fill ~115 ~6 ~58 ~118 ~6 ~58 wool 15
fill ~115 ~6 ~64 ~116 ~6 ~64 wool 15
fill ~117 ~6 ~3 ~117 ~7 ~3 wool 0
fill ~117 ~6 ~63 ~117 ~7 ~63 wool 0
fill ~118 ~6 ~3 ~125 ~6 ~3 wool 15
fill ~118 ~6 ~4 ~118 ~13 ~4 wool 15
fill ~118 ~6 ~5 ~118 ~13 ~5 wool 15
fill ~118 ~6 ~6 ~118 ~13 ~6 wool 15
fill ~118 ~6 ~7 ~118 ~13 ~7 wool 15
fill ~118 ~6 ~59 ~118 ~13 ~59 wool 15
fill ~118 ~6 ~60 ~118 ~13 ~60 wool 15
fill ~118 ~6 ~61 ~118 ~13 ~61 wool 15
fill ~118 ~6 ~62 ~118 ~13 ~62 wool 15
fill ~118 ~6 ~63 ~125 ~6 ~63 wool 15
fill ~6 ~7 ~27 ~7 ~7 ~27 wool 0
fill ~6 ~7 ~39 ~7 ~7 ~39 wool 0
fill ~7 ~7 ~22 ~8 ~7 ~22 wool 0
fill ~7 ~7 ~44 ~8 ~7 ~44 wool 0
fill ~8 ~7 ~3 ~10 ~7 ~3 wool 0
fill ~8 ~7 ~63 ~10 ~7 ~63 wool 0
fill ~11 ~7 ~3 ~14 ~7 ~3 wool 15
fill ~11 ~7 ~63 ~14 ~7 ~63 wool 15
fill ~15 ~7 ~8 ~18 ~7 ~8 wool 15
fill ~15 ~7 ~58 ~20 ~7 ~58 wool 15
fill ~17 ~7 ~2 ~18 ~7 ~2 wool 15
fill ~17 ~7 ~64 ~18 ~7 ~64 wool 15
fill ~18 ~7 ~3 ~22 ~7 ~3 wool 7
fill ~18 ~7 ~63 ~22 ~7 ~63 wool 7
fill ~23 ~7 ~4 ~25 ~7 ~4 wool 7
fill ~23 ~7 ~62 ~25 ~7 ~62 wool 7
fill ~26 ~7 ~3 ~26 ~8 ~3 wool 7
fill ~26 ~7 ~63 ~26 ~8 ~63 wool 7
fill ~27 ~7 ~3 ~28 ~7 ~3 wool 15
fill ~27 ~7 ~63 ~28 ~7 ~63 wool 15
fill ~29 ~7 ~3 ~29 ~8 ~3 wool 7
fill ~29 ~7 ~63 ~29 ~8 ~63 wool 7
fill ~30 ~7 ~4 ~33 ~7 ~4 wool 7
fill ~30 ~7 ~62 ~33 ~7 ~62 wool 7
fill ~33 ~7 ~3 ~33 ~8 ~3 wool 7
fill ~33 ~7 ~63 ~33 ~8 ~63 wool 7
fill ~35 ~7 ~3 ~35 ~8 ~3 wool 7
fill ~35 ~7 ~58 ~40 ~7 ~58 wool 15
fill ~35 ~7 ~63 ~35 ~8 ~63 wool 7
fill ~37 ~7 ~2 ~38 ~7 ~2 wool 15
fill ~37 ~7 ~8 ~40 ~7 ~8 wool 15
fill ~37 ~7 ~64 ~38 ~7 ~64 wool 15
fill ~41 ~7 ~3 ~92 ~7 ~3 wool 15
fill ~41 ~7 ~63 ~92 ~7 ~63 wool 15
fill ~54 ~7 ~4 ~92 ~7 ~4 wool 7
fill ~54 ~7 ~5 ~54 ~8 ~5 wool 7
fill ~54 ~7 ~6 ~54 ~8 ~6 wool 7
fill ~54 ~7 ~7 ~54 ~8 ~7 wool 7
fill ~54 ~7 ~8 ~54 ~8 ~8 wool 7
fill ~54 ~7 ~9 ~54 ~8 ~9 wool 7
fill ~54 ~7 ~10 ~54 ~8 ~10 wool 7
fill ~54 ~7 ~11 ~54 ~8 ~11 wool 7
fill ~54 ~7 ~12 ~54 ~8 ~12 wool 7
fill ~54 ~7 ~13 ~54 ~8 ~13 wool 7
fill ~54 ~7 ~14 ~54 ~8 ~14 wool 7
fill ~54 ~7 ~15 ~54 ~8 ~15 wool 7
fill ~54 ~7 ~16 ~54 ~8 ~16 wool 7
fill ~54 ~7 ~17 ~54 ~8 ~17 wool 7
fill ~54 ~7 ~18 ~54 ~8 ~18 wool 7
fill ~54 ~7 ~19 ~54 ~8 ~19 wool 7
fill ~54 ~7 ~20 ~54 ~8 ~20 wool 7
fill ~54 ~7 ~21 ~54 ~8 ~21 wool 7
fill ~54 ~7 ~22 ~54 ~8 ~22 wool 7
fill ~54 ~7 ~23 ~54 ~8 ~23 wool 7
fill ~54 ~7 ~24 ~54 ~8 ~24 wool 7
fill ~54 ~7 ~25 ~54 ~8 ~25 wool 7
fill ~54 ~7 ~26 ~54 ~8 ~26 wool 7
fill ~54 ~7 ~27 ~54 ~8 ~27 wool 7
fill ~54 ~7 ~28 ~54 ~8 ~28 wool 7
fill ~54 ~7 ~29 ~78 ~7 ~29 wool 7
fill ~54 ~7 ~30 ~54 ~17 ~30 wool 7
fill ~54 ~7 ~36 ~54 ~17 ~36 wool 7
fill ~54 ~7 ~37 ~78 ~7 ~37 wool 7
fill ~54 ~7 ~38 ~54 ~8 ~38 wool 7
fill ~54 ~7 ~39 ~54 ~8 ~39 wool 7
fill ~54 ~7 ~40 ~54 ~8 ~40 wool 7
fill ~54 ~7 ~41 ~54 ~8 ~41 wool 7
fill ~54 ~7 ~42 ~54 ~8 ~42 wool 7
fill ~54 ~7 ~43 ~54 ~8 ~43 wool 7
fill ~54 ~7 ~44 ~54 ~8 ~44 wool 7
fill ~54 ~7 ~45 ~54 ~8 ~45 wool 7
fill ~54 ~7 ~46 ~54 ~8 ~46 wool 7
fill ~54 ~7 ~47 ~54 ~8 ~47 wool 7
fill ~54 ~7 ~48 ~54 ~8 ~48 wool 7
fill ~54 ~7 ~49 ~54 ~8 ~49 wool 7
fill ~54 ~7 ~50 ~54 ~8 ~50 wool 7
fill ~54 ~7 ~51 ~54 ~8 ~51 wool 7
fill ~54 ~7 ~52 ~54 ~8 ~52 wool 7
fill ~54 ~7 ~53 ~54 ~8 ~53 wool 7
fill ~54 ~7 ~54 ~54 ~8 ~54 wool 7
fill ~54 ~7 ~55 ~54 ~8 ~55 wool 7
fill ~54 ~7 ~56 ~54 ~8 ~56 wool 7
fill ~54 ~7 ~57 ~54 ~8 ~57 wool 7
fill ~54 ~7 ~58 ~54 ~8 ~58 wool 7
fill ~54 ~7 ~59 ~54 ~8 ~59 wool 7
fill ~54 ~7 ~60 ~54 ~8 ~60 wool 7
fill ~54 ~7 ~61 ~54 ~8 ~61 wool 7
fill ~54 ~7 ~62 ~92 ~7 ~62 wool 7
fill ~63 ~7 ~8 ~63 ~12 ~8 wool 15
fill ~63 ~7 ~9 ~63 ~12 ~9 wool 15
fill ~63 ~7 ~10 ~63 ~12 ~10 wool 15
fill ~63 ~7 ~11 ~63 ~12 ~11 wool 15
fill ~63 ~7 ~12 ~63 ~12 ~12 wool 15
fill ~63 ~7 ~13 ~63 ~12 ~13 wool 15
fill ~63 ~7 ~14 ~63 ~12 ~14 wool 15
fill ~63 ~7 ~15 ~63 ~12 ~15 wool 15
fill ~63 ~7 ~16 ~63 ~12 ~16 wool 15
fill ~63 ~7 ~17 ~63 ~12 ~17 wool 15
fill ~63 ~7 ~18 ~63 ~12 ~18 wool 15
fill ~63 ~7 ~19 ~63 ~12 ~19 wool 15
fill ~63 ~7 ~20 ~63 ~12 ~20 wool 15
fill ~63 ~7 ~21 ~63 ~12 ~21 wool 15
fill ~63 ~7 ~22 ~63 ~12 ~22 wool 15
fill ~63 ~7 ~23 ~63 ~12 ~23 wool 15
fill ~63 ~7 ~24 ~63 ~12 ~24 wool 15
fill ~63 ~7 ~25 ~64 ~7 ~25 wool 15
fill ~63 ~7 ~41 ~64 ~7 ~41 wool 15
fill ~63 ~7 ~42 ~63 ~12 ~42 wool 15
fill ~63 ~7 ~43 ~63 ~12 ~43 wool 15
fill ~63 ~7 ~44 ~63 ~12 ~44 wool 15
fill ~63 ~7 ~45 ~63 ~12 ~45 wool 15
fill ~63 ~7 ~46 ~63 ~12 ~46 wool 15
fill ~63 ~7 ~47 ~63 ~12 ~47 wool 15
fill ~63 ~7 ~48 ~63 ~12 ~48 wool 15
fill ~63 ~7 ~49 ~63 ~12 ~49 wool 15
fill ~63 ~7 ~50 ~63 ~12 ~50 wool 15
fill ~63 ~7 ~51 ~63 ~12 ~51 wool 15
fill ~63 ~7 ~52 ~63 ~12 ~52 wool 15
fill ~63 ~7 ~53 ~63 ~12 ~53 wool 15
fill ~63 ~7 ~54 ~63 ~12 ~54 wool 15
fill ~63 ~7 ~55 ~63 ~12 ~55 wool 15
fill ~63 ~7 ~56 ~63 ~12 ~56 wool 15
fill ~63 ~7 ~57 ~63 ~12 ~57 wool 15
fill ~63 ~7 ~58 ~63 ~12 ~58 wool 15
fill ~64 ~7 ~7 ~74 ~7 ~7 wool 15
fill ~64 ~7 ~26 ~74 ~7 ~26 wool 15
fill ~64 ~7 ~40 ~74 ~7 ~40 wool 15
fill ~64 ~7 ~59 ~74 ~7 ~59 wool 15
fill ~75 ~7 ~8 ~75 ~17 ~8 wool 15
fill ~75 ~7 ~9 ~75 ~17 ~9 wool 15
fill ~75 ~7 ~10 ~75 ~17 ~10 wool 15
fill ~75 ~7 ~11 ~75 ~12 ~11 wool 15
fill ~75 ~7 ~12 ~75 ~12 ~12 wool 15
fill ~75 ~7 ~13 ~75 ~12 ~13 wool 15
fill ~75 ~7 ~14 ~75 ~12 ~14 wool 15
fill ~75 ~7 ~15 ~75 ~12 ~15 wool 15
fill ~75 ~7 ~16 ~75 ~12 ~16 wool 15
fill ~75 ~7 ~17 ~75 ~12 ~17 wool 15
fill ~75 ~7 ~18 ~75 ~12 ~18 wool 15
fill ~75 ~7 ~19 ~75 ~12 ~19 wool 15
fill ~75 ~7 ~20 ~75 ~12 ~20 wool 15
fill ~75 ~7 ~21 ~75 ~12 ~21 wool 15
fill ~75 ~7 ~22 ~75 ~12 ~22 wool 15
fill ~75 ~7 ~23 ~75 ~17 ~23 wool 15
fill ~75 ~7 ~24 ~75 ~17 ~24 wool 15
fill ~75 ~7 ~25 ~75 ~17 ~25 wool 15
fill ~75 ~7 ~41 ~75 ~17 ~41 wool 15
fill ~75 ~7 ~42 ~75 ~17 ~42 wool 15
fill ~75 ~7 ~43 ~75 ~17 ~43 wool 15
fill ~75 ~7 ~44 ~75 ~12 ~44 wool 15
fill ~75 ~7 ~45 ~75 ~12 ~45 wool 15
fill ~75 ~7 ~46 ~75 ~12 ~46 wool 15
fill ~75 ~7 ~47 ~75 ~12 ~47 wool 15
fill ~75 ~7 ~48 ~75 ~12 ~48 wool 15
fill ~75 ~7 ~49 ~75 ~12 ~49 wool 15
fill ~75 ~7 ~50 ~75 ~12 ~50 wool 15
fill ~75 ~7 ~51 ~75 ~12 ~51 wool 15
fill ~75 ~7 ~52 ~75 ~12 ~52 wool 15
fill ~75 ~7 ~53 ~75 ~12 ~53 wool 15
fill ~75 ~7 ~54 ~75 ~12 ~54 wool 15
fill ~75 ~7 ~55 ~75 ~12 ~55 wool 15
fill ~75 ~7 ~56 ~75 ~17 ~56 wool 15
fill ~75 ~7 ~57 ~75 ~17 ~57 wool 15
fill ~75 ~7 ~58 ~75 ~17 ~58 wool 15
fill ~79 ~7 ~30 ~79 ~8 ~30 wool 7
fill ~79 ~7 ~31 ~79 ~8 ~31 wool 7
fill ~79 ~7 ~32 ~79 ~8 ~32 wool 7
fill ~79 ~7 ~33 ~79 ~8 ~33 wool 7
fill ~79 ~7 ~34 ~79 ~8 ~34 wool 7
fill ~79 ~7 ~35 ~79 ~8 ~35 wool 7
fill ~79 ~7 ~36 ~79 ~8 ~36 wool 7
fill ~86 ~7 ~8 ~91 ~7 ~8 wool 15
fill ~86 ~7 ~9 ~86 ~8 ~9 wool 15
fill ~86 ~7 ~10 ~86 ~7 ~58 wool 15
fill ~87 ~7 ~58 ~91 ~7 ~58 wool 15
fill ~92 ~7 ~5 ~92 ~9 ~5 wool 7
fill ~92 ~7 ~6 ~92 ~9 ~6 wool 7
fill ~92 ~7 ~7 ~92 ~9 ~7 wool 7
fill ~92 ~7 ~32 ~92 ~9 ~32 wool 7
fill ~92 ~7 ~34 ~92 ~9 ~34 wool 7
fill ~92 ~7 ~59 ~92 ~9 ~59 wool 7
fill ~92 ~7 ~60 ~92 ~9 ~60 wool 7
fill ~92 ~7 ~61 ~92 ~9 ~61 wool 7
fill ~95 ~7 ~2 ~96 ~7 ~2 wool 15
fill ~95 ~7 ~64 ~96 ~7 ~64 wool 15
fill ~97 ~7 ~3 ~100 ~7 ~3 wool 7
fill ~97 ~7 ~63 ~100 ~7 ~63 wool 7
fill ~100 ~7 ~4 ~104 ~7 ~4 wool 7
fill ~100 ~7 ~62 ~104 ~7 ~62 wool 7
fill ~104 ~7 ~3 ~104 ~8 ~3 wool 7
fill ~104 ~7 ~63 ~104 ~8 ~63 wool 7
fill ~105 ~7 ~3 ~106 ~7 ~3 wool 15
fill ~105 ~7 ~63 ~106 ~7 ~63 wool 15
fill ~107 ~7 ~3 ~107 ~8 ~3 wool 7
fill ~107 ~7 ~4 ~111 ~7 ~4 wool 7
fill ~107 ~7 ~62 ~111 ~7 ~62 wool 7
fill ~107 ~7 ~63 ~107 ~8 ~63 wool 7
fill ~111 ~7 ~3 ~111 ~8 ~3 wool 7
fill ~111 ~7 ~63 ~111 ~8 ~63 wool 7
fill ~113 ~7 ~3 ~114 ~7 ~3 wool 7
fill ~113 ~7 ~63 ~114 ~7 ~63 wool 7
fill ~114 ~7 ~8 ~118 ~7 ~8 wool 15
fill ~114 ~7 ~58 ~118 ~7 ~58 wool 15
fill ~115 ~7 ~2 ~116 ~7 ~2 wool 15
fill ~115 ~7 ~64 ~116 ~7 ~64 wool 15
fill ~118 ~7 ~3 ~133 ~7 ~3 wool 15
fill ~118 ~7 ~63 ~133 ~7 ~63 wool 15
fill ~5 ~8 ~26 ~6 ~8 ~26 wool 0
fill ~5 ~8 ~27 ~5 ~9 ~27 wool 0
fill ~5 ~8 ~28 ~5 ~9 ~28 wool 0
fill ~5 ~8 ~29 ~5 ~9 ~29 wool 0
fill ~5 ~8 ~30 ~5 ~9 ~30 wool 0
fill ~5 ~8 ~31 ~5 ~9 ~31 wool 0
fill ~5 ~8 ~32 ~5 ~9 ~32 wool 0
fill ~5 ~8 ~33 ~5 ~9 ~33 wool 0
fill ~5 ~8 ~34 ~5 ~9 ~34 wool 0
fill ~5 ~8 ~35 ~5 ~9 ~35 wool 0
fill ~5 ~8 ~36 ~5 ~9 ~36 wool 0
fill ~5 ~8 ~37 ~5 ~9 ~37 wool 0
fill ~5 ~8 ~38 ~5 ~9 ~38 wool 0
fill ~5 ~8 ~39 ~5 ~9 ~39 wool 0
fill ~5 ~8 ~40 ~6 ~8 ~40 wool 0
fill ~6 ~8 ~21 ~7 ~8 ~21 wool 0
fill ~6 ~8 ~22 ~6 ~9 ~22 wool 0
fill ~6 ~8 ~23 ~6 ~9 ~23 wool 0
fill ~6 ~8 ~24 ~6 ~9 ~24 wool 0
fill ~6 ~8 ~25 ~6 ~9 ~25 wool 0
fill ~6 ~8 ~41 ~6 ~9 ~41 wool 0
fill ~6 ~8 ~42 ~6 ~9 ~42 wool 0
fill ~6 ~8 ~43 ~6 ~9 ~43 wool 0
fill ~6 ~8 ~44 ~6 ~9 ~44 wool 0
fill ~6 ~8 ~45 ~7 ~8 ~45 wool 0
fill ~7 ~8 ~3 ~10 ~8 ~3 wool 0
fill ~7 ~8 ~4 ~7 ~9 ~4 wool 0
fill ~7 ~8 ~5 ~7 ~9 ~5 wool 0
fill ~7 ~8 ~6 ~7 ~9 ~6 wool 0
fill ~7 ~8 ~7 ~7 ~9 ~7 wool 0
fill ~7 ~8 ~8 ~7 ~9 ~8 wool 0
fill ~7 ~8 ~9 ~7 ~9 ~9 wool 0
fill ~7 ~8 ~10 ~7 ~9 ~10 wool 0
fill ~7 ~8 ~11 ~7 ~9 ~11 wool 0
fill ~7 ~8 ~12 ~7 ~9 ~12 wool 0
fill ~7 ~8 ~13 ~7 ~9 ~13 wool 0
fill ~7 ~8 ~14 ~7 ~9 ~14 wool 0
fill ~7 ~8 ~15 ~7 ~9 ~15 wool 0
fill ~7 ~8 ~16 ~7 ~9 ~16 wool 0
fill ~7 ~8 ~17 ~7 ~9 ~17 wool 0
fill ~7 ~8 ~18 ~7 ~9 ~18 wool 0
fill ~7 ~8 ~19 ~7 ~9 ~19 wool 0
fill ~7 ~8 ~20 ~7 ~9 ~20 wool 0
fill ~7 ~8 ~46 ~7 ~9 ~46 wool 0
fill ~7 ~8 ~47 ~7 ~9 ~47 wool 0
fill ~7 ~8 ~48 ~7 ~9 ~48 wool 0
fill ~7 ~8 ~49 ~7 ~9 ~49 wool 0
fill ~7 ~8 ~50 ~7 ~9 ~50 wool 0
fill ~7 ~8 ~51 ~7 ~9 ~51 wool 0
fill ~7 ~8 ~52 ~7 ~9 ~52 wool 0
fill ~7 ~8 ~53 ~7 ~9 ~53 wool 0
fill ~7 ~8 ~54 ~7 ~9 ~54 wool 0
fill ~7 ~8 ~55 ~7 ~9 ~55 wool 0
fill ~7 ~8 ~56 ~7 ~9 ~56 wool 0
fill ~7 ~8 ~57 ~7 ~9 ~57 wool 0
fill ~7 ~8 ~58 ~7 ~9 ~58 wool 0
fill ~7 ~8 ~59 ~7 ~9 ~59 wool 0
fill ~7 ~8 ~60 ~7 ~9 ~60 wool 0
fill ~7 ~8 ~61 ~7 ~9 ~61 wool 0
fill ~7 ~8 ~62 ~7 ~9 ~62 wool 0
fill ~7 ~8 ~63 ~10 ~8 ~63 wool 0
fill ~11 ~8 ~3 ~14 ~8 ~3 wool 15
fill ~11 ~8 ~63 ~14 ~8 ~63 wool 15
fill ~15 ~8 ~8 ~18 ~8 ~8 wool 15
fill ~15 ~8 ~58 ~20 ~8 ~58 wool 15
fill ~17 ~8 ~2 ~18 ~8 ~2 wool 15
fill ~17 ~8 ~64 ~18 ~8 ~64 wool 15
fill ~18 ~8 ~3 ~22 ~8 ~3 wool 7
fill ~18 ~8 ~63 ~22 ~8 ~63 wool 7
fill ~23 ~8 ~4 ~25 ~8 ~4 wool 7
fill ~23 ~8 ~62 ~25 ~8 ~62 wool 7
fill ~27 ~8 ~3 ~28 ~8 ~3 wool 15
fill ~27 ~8 ~63 ~28 ~8 ~63 wool 15
fill ~30 ~8 ~4 ~33 ~8 ~4 wool 7
fill ~30 ~8 ~62 ~33 ~8 ~62 wool 7
fill ~35 ~8 ~58 ~40 ~8 ~58 wool 15
fill ~37 ~8 ~2 ~38 ~8 ~2 wool 15
fill ~37 ~8 ~8 ~40 ~8 ~8 wool 15
fill ~37 ~8 ~64 ~38 ~8 ~64 wool 15
fill ~40 ~8 ~2 ~40 ~12 ~2 wool 0
fill ~40 ~8 ~3 ~40 ~14 ~3 wool 15
fill ~40 ~8 ~63 ~40 ~14 ~63 wool 15
fill ~40 ~8 ~64 ~40 ~12 ~64 wool 0
fill ~41 ~8 ~2 ~92 ~8 ~2 wool 15
fill ~41 ~8 ~64 ~92 ~8 ~64 wool 15
fill ~54 ~8 ~3 ~76 ~8 ~3 wool 7
fill ~54 ~8 ~4 ~54 ~7 ~4 wool 7
fill ~54 ~8 ~29 ~77 ~8 ~29 wool 7
fill ~54 ~8 ~37 ~77 ~8 ~37 wool 7
fill ~54 ~8 ~62 ~54 ~7 ~62 wool 7
fill ~54 ~8 ~63 ~76 ~8 ~63 wool 7
fill ~63 ~8 ~25 ~63 ~12 ~25 wool 15
fill ~63 ~8 ~41 ~63 ~12 ~41 wool 15
fill ~64 ~8 ~7 ~74 ~8 ~7 wool 15
fill ~64 ~8 ~26 ~74 ~8 ~26 wool 15
fill ~64 ~8 ~40 ~74 ~8 ~40 wool 15
fill ~64 ~8 ~59 ~74 ~8 ~59 wool 15
fill ~78 ~8 ~3 ~92 ~8 ~3 wool 7
fill ~78 ~8 ~30 ~78 ~10 ~30 wool 7
fill ~78 ~8 ~36 ~78 ~10 ~36 wool 7
fill ~78 ~8 ~63 ~92 ~8 ~63 wool 7
fill ~85 ~8 ~8 ~85 ~8 ~58 wool 15
fill ~86 ~8 ~7 ~91 ~8 ~7 wool 15
setblock ~86 ~8 ~57 wool 15
fill ~86 ~8 ~59 ~91 ~8 ~59 wool 15
fill ~93 ~8 ~2 ~93 ~9 ~2 wool 0
fill ~93 ~8 ~64 ~93 ~9 ~64 wool 0
fill ~95 ~8 ~2 ~96 ~8 ~2 wool 15
fill ~95 ~8 ~64 ~96 ~8 ~64 wool 15
setblock ~98 ~8 ~3 wool 7
setblock ~98 ~8 ~63 wool 7
fill ~100 ~8 ~3 ~100 ~8 ~4 wool 7
fill ~100 ~8 ~62 ~104 ~8 ~62 wool 7
fill ~100 ~8 ~63 ~100 ~8 ~62 wool 7
fill ~101 ~8 ~4 ~104 ~8 ~4 wool 7
fill ~105 ~8 ~3 ~106 ~8 ~3 wool 15
fill ~105 ~8 ~63 ~106 ~8 ~63 wool 15
fill ~107 ~8 ~4 ~111 ~8 ~4 wool 7
fill ~107 ~8 ~62 ~111 ~8 ~62 wool 7
fill ~113 ~8 ~3 ~114 ~8 ~3 wool 7
fill ~113 ~8 ~63 ~114 ~8 ~63 wool 7
fill ~114 ~8 ~8 ~118 ~8 ~8 wool 15
fill ~114 ~8 ~58 ~118 ~8 ~58 wool 15
fill ~115 ~8 ~2 ~116 ~8 ~2 wool 15
fill ~115 ~8 ~64 ~116 ~8 ~64 wool 15
fill ~117 ~8 ~2 ~117 ~9 ~2 wool 0
fill ~117 ~8 ~64 ~117 ~9 ~64 wool 0
fill ~118 ~8 ~2 ~141 ~8 ~2 wool 15
fill ~118 ~8 ~3 ~118 ~13 ~3 wool 15
fill ~118 ~8 ~63 ~118 ~13 ~63 wool 15
fill ~118 ~8 ~64 ~141 ~8 ~64 wool 15
fill ~134 ~8 ~3 ~141 ~8 ~3 wool 15
fill ~134 ~8 ~63 ~141 ~8 ~63 wool 15
fill ~142 ~8 ~3 ~143 ~8 ~3 wool 0
fill ~142 ~8 ~63 ~143 ~8 ~63 wool 0
fill ~143 ~8 ~4 ~143 ~10 ~4 wool 0
fill ~143 ~8 ~5 ~143 ~10 ~5 wool 0
fill ~143 ~8 ~6 ~143 ~10 ~6 wool 0
fill ~143 ~8 ~7 ~143 ~10 ~7 wool 0
fill ~143 ~8 ~8 ~143 ~10 ~8 wool 0
fill ~143 ~8 ~9 ~143 ~10 ~9 wool 0
fill ~143 ~8 ~10 ~143 ~10 ~10 wool 0
fill ~143 ~8 ~11 ~143 ~10 ~11 wool 0
fill ~143 ~8 ~12 ~143 ~10 ~12 wool 0
fill ~143 ~8 ~13 ~143 ~10 ~13 wool 0
fill ~143 ~8 ~14 ~143 ~10 ~14 wool 0
fill ~143 ~8 ~15 ~143 ~10 ~15 wool 0
fill ~143 ~8 ~16 ~143 ~10 ~16 wool 0
fill ~143 ~8 ~17 ~143 ~10 ~17 wool 0
fill ~143 ~8 ~18 ~143 ~10 ~18 wool 0
fill ~143 ~8 ~19 ~143 ~10 ~19 wool 0
fill ~143 ~8 ~20 ~143 ~10 ~20 wool 0
fill ~143 ~8 ~21 ~143 ~10 ~21 wool 0
fill ~143 ~8 ~22 ~143 ~10 ~22 wool 0
fill ~143 ~8 ~23 ~143 ~10 ~23 wool 0
fill ~143 ~8 ~24 ~143 ~10 ~24 wool 0
fill ~143 ~8 ~25 ~143 ~10 ~25 wool 0
fill ~143 ~8 ~26 ~143 ~10 ~26 wool 0
fill ~143 ~8 ~27 ~143 ~10 ~27 wool 0
fill ~143 ~8 ~28 ~143 ~10 ~28 wool 0
fill ~143 ~8 ~29 ~143 ~10 ~29 wool 0
fill ~143 ~8 ~30 ~143 ~10 ~30 wool 0
fill ~143 ~8 ~31 ~143 ~10 ~31 wool 0
fill ~143 ~8 ~32 ~143 ~10 ~32 wool 0
fill ~143 ~8 ~33 ~143 ~10 ~33 wool 0
fill ~143 ~8 ~34 ~143 ~10 ~34 wool 0
fill ~143 ~8 ~35 ~143 ~10 ~35 wool 0
fill ~143 ~8 ~36 ~143 ~10 ~36 wool 0
fill ~143 ~8 ~37 ~143 ~10 ~37 wool 0
fill ~143 ~8 ~38 ~143 ~10 ~38 wool 0
fill ~143 ~8 ~39 ~143 ~10 ~39 wool 0
fill ~143 ~8 ~40 ~143 ~10 ~40 wool 0
fill ~143 ~8 ~41 ~143 ~10 ~41 wool 0
fill ~143 ~8 ~42 ~143 ~10 ~42 wool 0
fill ~143 ~8 ~43 ~143 ~10 ~43 wool 0
fill ~143 ~8 ~44 ~143 ~10 ~44 wool 0
fill ~143 ~8 ~45 ~143 ~10 ~45 wool 0
fill ~143 ~8 ~46 ~143 ~10 ~46 wool 0
fill ~143 ~8 ~47 ~143 ~10 ~47 wool 0
fill ~143 ~8 ~48 ~143 ~10 ~48 wool 0
fill ~143 ~8 ~49 ~143 ~10 ~49 wool 0
fill ~143 ~8 ~50 ~143 ~10 ~50 wool 0
fill ~143 ~8 ~51 ~143 ~10 ~51 wool 0
fill ~143 ~8 ~52 ~143 ~10 ~52 wool 0
fill ~143 ~8 ~53 ~143 ~10 ~53 wool 0
fill ~143 ~8 ~54 ~143 ~10 ~54 wool 0
fill ~143 ~8 ~55 ~143 ~10 ~55 wool 0
fill ~143 ~8 ~56 ~143 ~10 ~56 wool 0
fill ~143 ~8 ~57 ~143 ~10 ~57 wool 0
fill ~143 ~8 ~58 ~143 ~10 ~58 wool 0
fill ~143 ~8 ~59 ~143 ~10 ~59 wool 0
fill ~143 ~8 ~60 ~143 ~10 ~60 wool 0
fill ~143 ~8 ~61 ~143 ~10 ~61 wool 0
fill ~143 ~8 ~62 ~143 ~10 ~62 wool 0
fill ~5 ~9 ~19 ~7 ~9 ~19 wool 0
fill ~5 ~9 ~20 ~6 ~9 ~20 wool 15
fill ~5 ~9 ~21 ~7 ~9 ~21 wool 0
fill ~5 ~9 ~26 ~6 ~9 ~26 wool 0
fill ~5 ~9 ~40 ~6 ~9 ~40 wool 0
fill ~5 ~9 ~45 ~7 ~9 ~45 wool 0
fill ~5 ~9 ~46 ~6 ~9 ~46 wool 15
fill ~5 ~9 ~47 ~7 ~9 ~47 wool 0
fill ~7 ~9 ~3 ~10 ~9 ~3 wool 0
fill ~7 ~9 ~63 ~10 ~9 ~63 wool 0
fill ~11 ~9 ~3 ~14 ~9 ~3 wool 15
fill ~11 ~9 ~63 ~14 ~9 ~63 wool 15
fill ~15 ~9 ~8 ~18 ~9 ~8 wool 15
fill ~15 ~9 ~58 ~20 ~9 ~58 wool 15
fill ~17 ~9 ~2 ~18 ~9 ~2 wool 15
fill ~17 ~9 ~64 ~18 ~9 ~64 wool 15
fill ~18 ~9 ~3 ~21 ~9 ~3 wool 7
fill ~18 ~9 ~63 ~21 ~9 ~63 wool 7
fill ~20 ~9 ~2 ~20 ~12 ~2 wool 7
fill ~20 ~9 ~64 ~20 ~12 ~64 wool 7
setblock ~26 ~9 ~3 wool 15
setblock ~26 ~9 ~63 wool 15
fill ~27 ~9 ~3 ~28 ~9 ~3 wool 7
fill ~27 ~9 ~63 ~28 ~9 ~63 wool 7
setblock ~29 ~9 ~3 wool 15
setblock ~29 ~9 ~63 wool 15
fill ~35 ~9 ~2 ~35 ~12 ~2 wool 7
fill ~35 ~9 ~58 ~40 ~9 ~58 wool 15
fill ~35 ~9 ~64 ~35 ~12 ~64 wool 7
fill ~37 ~9 ~2 ~38 ~9 ~2 wool 15
fill ~37 ~9 ~8 ~40 ~9 ~8 wool 15
fill ~37 ~9 ~64 ~38 ~9 ~64 wool 15
fill ~41 ~9 ~2 ~92 ~9 ~2 wool 15
fill ~41 ~9 ~64 ~92 ~9 ~64 wool 15
fill ~53 ~9 ~3 ~76 ~9 ~3 wool 7
fill ~53 ~9 ~4 ~53 ~10 ~4 wool 7
fill ~53 ~9 ~5 ~53 ~10 ~5 wool 7
fill ~53 ~9 ~6 ~53 ~10 ~6 wool 7
fill ~53 ~9 ~7 ~53 ~10 ~7 wool 7
fill ~53 ~9 ~8 ~53 ~10 ~8 wool 7
fill ~53 ~9 ~9 ~53 ~10 ~9 wool 7
fill ~53 ~9 ~10 ~53 ~10 ~10 wool 7
fill ~53 ~9 ~11 ~53 ~10 ~11 wool 7
fill ~53 ~9 ~12 ~53 ~10 ~12 wool 7
fill ~53 ~9 ~13 ~53 ~10 ~13 wool 7
fill ~53 ~9 ~14 ~53 ~10 ~14 wool 7
fill ~53 ~9 ~15 ~53 ~10 ~15 wool 7
fill ~53 ~9 ~16 ~53 ~10 ~16 wool 7
fill ~53 ~9 ~17 ~53 ~10 ~17 wool 7
fill ~53 ~9 ~18 ~53 ~10 ~18 wool 7
fill ~53 ~9 ~19 ~53 ~10 ~19 wool 7
fill ~53 ~9 ~20 ~53 ~10 ~20 wool 7
fill ~53 ~9 ~21 ~53 ~10 ~21 wool 7
fill ~53 ~9 ~22 ~53 ~10 ~22 wool 7
fill ~53 ~9 ~23 ~53 ~10 ~23 wool 7
fill ~53 ~9 ~24 ~53 ~10 ~24 wool 7
fill ~53 ~9 ~25 ~53 ~10 ~25 wool 7
fill ~53 ~9 ~26 ~53 ~10 ~26 wool 7
fill ~53 ~9 ~27 ~53 ~10 ~27 wool 7
fill ~53 ~9 ~28 ~53 ~10 ~28 wool 7
fill ~53 ~9 ~29 ~53 ~10 ~29 wool 7
fill ~53 ~9 ~30 ~53 ~17 ~30 wool 7
fill ~53 ~9 ~36 ~53 ~17 ~36 wool 7
fill ~53 ~9 ~37 ~53 ~10 ~37 wool 7
fill ~53 ~9 ~38 ~53 ~10 ~38 wool 7
fill ~53 ~9 ~39 ~53 ~10 ~39 wool 7
fill ~53 ~9 ~40 ~53 ~10 ~40 wool 7
fill ~53 ~9 ~41 ~53 ~10 ~41 wool 7
fill ~53 ~9 ~42 ~53 ~10 ~42 wool 7
fill ~53 ~9 ~43 ~53 ~10 ~43 wool 7
fill ~53 ~9 ~44 ~53 ~10 ~44 wool 7
fill ~53 ~9 ~45 ~53 ~10 ~45 wool 7
fill ~53 ~9 ~46 ~53 ~10 ~46 wool 7
fill ~53 ~9 ~47 ~53 ~10 ~47 wool 7
fill ~53 ~9 ~48 ~53 ~10 ~48 wool 7
fill ~53 ~9 ~49 ~53 ~10 ~49 wool 7
fill ~53 ~9 ~50 ~53 ~10 ~50 wool 7
fill ~53 ~9 ~51 ~53 ~10 ~51 wool 7
fill ~53 ~9 ~52 ~53 ~10 ~52 wool 7
fill ~53 ~9 ~53 ~53 ~10 ~53 wool 7
fill ~53 ~9 ~54 ~53 ~10 ~54 wool 7
fill ~53 ~9 ~55 ~53 ~10 ~55 wool 7
fill ~53 ~9 ~56 ~53 ~10 ~56 wool 7
fill ~53 ~9 ~57 ~53 ~10 ~57 wool 7
fill ~53 ~9 ~58 ~53 ~10 ~58 wool 7
fill ~53 ~9 ~59 ~53 ~10 ~59 wool 7
fill ~53 ~9 ~60 ~53 ~10 ~60 wool 7
fill ~53 ~9 ~61 ~53 ~10 ~61 wool 7
fill ~53 ~9 ~62 ~53 ~10 ~62 wool 7
fill ~53 ~9 ~63 ~76 ~9 ~63 wool 7
fill ~55 ~9 ~30 ~78 ~9 ~30 wool 7
fill ~55 ~9 ~36 ~78 ~9 ~36 wool 7
fill ~64 ~9 ~7 ~74 ~9 ~7 wool 15
fill ~64 ~9 ~26 ~74 ~9 ~26 wool 15
fill ~64 ~9 ~40 ~74 ~9 ~40 wool 15
fill ~64 ~9 ~59 ~74 ~9 ~59 wool 15
fill ~78 ~9 ~3 ~92 ~9 ~3 wool 7
fill ~78 ~9 ~31 ~78 ~10 ~31 wool 7
fill ~78 ~9 ~32 ~78 ~10 ~32 wool 7
fill ~78 ~9 ~33 ~78 ~10 ~33 wool 7
fill ~78 ~9 ~34 ~78 ~10 ~34 wool 7
fill ~78 ~9 ~35 ~78 ~10 ~35 wool 7
fill ~78 ~9 ~63 ~92 ~9 ~63 wool 7
fill ~84 ~9 ~8 ~84 ~11 ~8 wool 15
fill ~84 ~9 ~9 ~85 ~9 ~9 wool 15
fill ~84 ~9 ~10 ~84 ~11 ~10 wool 15
fill ~84 ~9 ~11 ~84 ~11 ~11 wool 15
fill ~84 ~9 ~12 ~84 ~11 ~12 wool 15
fill ~84 ~9 ~13 ~84 ~11 ~13 wool 15
fill ~84 ~9 ~14 ~84 ~11 ~14 wool 15
fill ~84 ~9 ~15 ~84 ~11 ~15 wool 15
fill ~84 ~9 ~16 ~84 ~11 ~16 wool 15
fill ~84 ~9 ~17 ~84 ~11 ~17 wool 15
fill ~84 ~9 ~18 ~84 ~11 ~18 wool 15
fill ~84 ~9 ~19 ~84 ~11 ~19 wool 15
fill ~84 ~9 ~20 ~84 ~11 ~20 wool 15
fill ~84 ~9 ~21 ~84 ~11 ~21 wool 15
fill ~84 ~9 ~22 ~84 ~11 ~22 wool 15
fill ~84 ~9 ~23 ~84 ~11 ~23 wool 15
fill ~84 ~9 ~24 ~84 ~11 ~24 wool 15
fill ~84 ~9 ~25 ~84 ~11 ~25 wool 15
fill ~84 ~9 ~26 ~84 ~11 ~26 wool 15
fill ~84 ~9 ~27 ~84 ~11 ~27 wool 15
fill ~84 ~9 ~28 ~84 ~11 ~28 wool 15
fill ~84 ~9 ~29 ~84 ~11 ~29 wool 15
fill ~84 ~9 ~30 ~84 ~11 ~30 wool 15
fill ~84 ~9 ~31 ~84 ~11 ~31 wool 15
fill ~84 ~9 ~32 ~84 ~11 ~32 wool 15
fill ~84 ~9 ~33 ~84 ~11 ~33 wool 15
fill ~84 ~9 ~34 ~84 ~11 ~34 wool 15
fill ~84 ~9 ~35 ~84 ~11 ~35 wool 15
fill ~84 ~9 ~36 ~84 ~11 ~36 wool 15
fill ~84 ~9 ~37 ~84 ~11 ~37 wool 15
fill ~84 ~9 ~38 ~84 ~11 ~38 wool 15
fill ~84 ~9 ~39 ~84 ~11 ~39 wool 15
fill ~84 ~9 ~40 ~84 ~11 ~40 wool 15
fill ~84 ~9 ~41 ~84 ~11 ~41 wool 15
fill ~84 ~9 ~42 ~84 ~11 ~42 wool 15
fill ~84 ~9 ~43 ~84 ~11 ~43 wool 15
fill ~84 ~9 ~44 ~84 ~11 ~44 wool 15
fill ~84 ~9 ~45 ~84 ~11 ~45 wool 15
fill ~84 ~9 ~46 ~84 ~11 ~46 wool 15
fill ~84 ~9 ~47 ~84 ~11 ~47 wool 15
fill ~84 ~9 ~48 ~84 ~11 ~48 wool 15
fill ~84 ~9 ~49 ~84 ~11 ~49 wool 15
fill ~84 ~9 ~50 ~84 ~11 ~50 wool 15
fill ~84 ~9 ~51 ~84 ~11 ~51 wool 15
fill ~84 ~9 ~52 ~84 ~11 ~52 wool 15
fill ~84 ~9 ~53 ~84 ~11 ~53 wool 15
fill ~84 ~9 ~54 ~84 ~11 ~54 wool 15
fill ~84 ~9 ~55 ~84 ~11 ~55 wool 15
fill ~84 ~9 ~56 ~84 ~11 ~56 wool 15
fill ~84 ~9 ~57 ~85 ~9 ~57 wool 15
fill ~84 ~9 ~58 ~84 ~11 ~58 wool 15
fill ~85 ~9 ~7 ~91 ~9 ~7 wool 15
fill ~85 ~9 ~59 ~91 ~9 ~59 wool 15
fill ~95 ~9 ~2 ~96 ~9 ~2 wool 15
fill ~95 ~9 ~64 ~96 ~9 ~64 wool 15
fill ~98 ~9 ~2 ~98 ~12 ~2 wool 7
fill ~98 ~9 ~64 ~98 ~12 ~64 wool 7
fill ~99 ~9 ~4 ~100 ~9 ~4 wool 7
fill ~99 ~9 ~62 ~100 ~9 ~62 wool 7
setblock ~104 ~9 ~3 wool 15
setblock ~104 ~9 ~63 wool 15
fill ~105 ~9 ~3 ~106 ~9 ~3 wool 7
fill ~105 ~9 ~4 ~106 ~9 ~4 wool 7
fill ~105 ~9 ~62 ~106 ~9 ~62 wool 7
fill ~105 ~9 ~63 ~106 ~9 ~63 wool 7
setblock ~107 ~9 ~3 wool 15
setblock ~107 ~9 ~63 wool 15
fill ~111 ~9 ~4 ~112 ~9 ~4 wool 7
fill ~111 ~9 ~62 ~112 ~9 ~62 wool 7
fill ~113 ~9 ~2 ~113 ~12 ~2 wool 7
fill ~113 ~9 ~64 ~113 ~12 ~64 wool 7
fill ~115 ~9 ~2 ~116 ~9 ~2 wool 15
fill ~115 ~9 ~64 ~116 ~9 ~64 wool 15
fill ~116 ~9 ~3 ~116 ~10 ~3 wool 15
fill ~116 ~9 ~4 ~116 ~10 ~4 wool 15
fill ~116 ~9 ~5 ~116 ~10 ~5 wool 15
fill ~116 ~9 ~6 ~116 ~10 ~6 wool 15
fill ~116 ~9 ~7 ~116 ~10 ~7 wool 15
fill ~116 ~9 ~59 ~116 ~10 ~59 wool 15
fill ~116 ~9 ~60 ~116 ~10 ~60 wool 15
fill ~116 ~9 ~61 ~116 ~10 ~61 wool 15
fill ~116 ~9 ~62 ~116 ~10 ~62 wool 15
fill ~116 ~9 ~63 ~116 ~10 ~63 wool 15
fill ~117 ~9 ~8 ~118 ~9 ~8 wool 15
fill ~117 ~9 ~58 ~118 ~9 ~58 wool 15
fill ~118 ~9 ~2 ~141 ~9 ~2 wool 15
fill ~118 ~9 ~64 ~141 ~9 ~64 wool 15
fill ~142 ~9 ~2 ~143 ~9 ~2 wool 0
fill ~142 ~9 ~3 ~143 ~9 ~3 wool 0
fill ~142 ~9 ~63 ~143 ~9 ~63 wool 0
fill ~142 ~9 ~64 ~143 ~9 ~64 wool 0
fill ~4 ~10 ~19 ~4 ~11 ~19 wool 0
setblock ~4 ~10 ~20 wool 15
fill ~4 ~10 ~21 ~4 ~11 ~21 wool 0
fill ~4 ~10 ~29 ~4 ~10 ~37 wool 0
fill ~4 ~10 ~45 ~4 ~11 ~45 wool 0
setblock ~4 ~10 ~46 wool 15
fill ~4 ~10 ~47 ~4 ~11 ~47 wool 0
fill ~6 ~10 ~3 ~7 ~10 ~3 wool 0
fill ~6 ~10 ~4 ~6 ~10 ~5 wool 0
fill ~6 ~10 ~6 ~6 ~10 ~9 stained_hardened_clay 1
fill ~6 ~10 ~57 ~6 ~10 ~60 stained_hardened_clay 1
fill ~6 ~10 ~61 ~6 ~10 ~63 wool 0
fill ~7 ~10 ~2 ~9 ~10 ~2 wool 0
fill ~7 ~10 ~63 ~7 ~8 ~63 wool 0
fill ~7 ~10 ~64 ~9 ~10 ~64 wool 0
fill ~10 ~10 ~2 ~14 ~10 ~2 wool 15
fill ~10 ~10 ~64 ~14 ~10 ~64 wool 15
fill ~15 ~10 ~2 ~15 ~13 ~2 wool 0
fill ~15 ~10 ~8 ~18 ~10 ~8 wool 15
fill ~15 ~10 ~58 ~20 ~10 ~58 wool 15
fill ~15 ~10 ~64 ~15 ~13 ~64 wool 0
fill ~17 ~10 ~2 ~19 ~10 ~2 wool 15
fill ~17 ~10 ~64 ~19 ~10 ~64 wool 15
fill ~24 ~10 ~4 ~25 ~10 ~4 wool 7
fill ~24 ~10 ~62 ~25 ~10 ~62 wool 7
fill ~27 ~10 ~4 ~28 ~10 ~4 wool 7
fill ~27 ~10 ~62 ~28 ~10 ~62 wool 7
fill ~30 ~10 ~4 ~31 ~10 ~4 wool 7
fill ~30 ~10 ~62 ~31 ~10 ~62 wool 7
fill ~35 ~10 ~58 ~40 ~10 ~58 wool 15
fill ~36 ~10 ~2 ~38 ~10 ~2 wool 15
fill ~36 ~10 ~64 ~38 ~10 ~64 wool 15
fill ~37 ~10 ~8 ~40 ~10 ~8 wool 15
fill ~41 ~10 ~2 ~80 ~10 ~2 wool 15
fill ~41 ~10 ~64 ~80 ~10 ~64 wool 15
fill ~53 ~10 ~3 ~76 ~10 ~3 wool 7
fill ~53 ~10 ~63 ~76 ~10 ~63 wool 7
fill ~55 ~10 ~30 ~78 ~10 ~30 wool 7
fill ~55 ~10 ~36 ~78 ~10 ~36 wool 7
fill ~59 ~10 ~4 ~75 ~10 ~4 wool 7
fill ~59 ~10 ~62 ~75 ~10 ~62 wool 7
fill ~64 ~10 ~7 ~74 ~10 ~7 wool 15
fill ~64 ~10 ~26 ~74 ~10 ~26 wool 15
fill ~64 ~10 ~40 ~74 ~10 ~40 wool 15
fill ~64 ~10 ~59 ~74 ~10 ~59 wool 15
fill ~78 ~10 ~3 ~93 ~10 ~3 wool 7
fill ~78 ~10 ~63 ~93 ~10 ~63 wool 7
fill ~79 ~10 ~4 ~89 ~10 ~4 wool 7
fill ~79 ~10 ~62 ~89 ~10 ~62 wool 7
fill ~81 ~10 ~1 ~93 ~10 ~1 wool 15
fill ~81 ~10 ~65 ~93 ~10 ~65 wool 15
fill ~84 ~10 ~9 ~84 ~11 ~9 wool 15
fill ~84 ~10 ~57 ~84 ~11 ~57 wool 15
fill ~85 ~10 ~7 ~92 ~10 ~7 wool 15
fill ~85 ~10 ~59 ~92 ~10 ~59 wool 15
fill ~93 ~10 ~2 ~93 ~13 ~2 wool 7
fill ~93 ~10 ~4 ~93 ~13 ~4 wool 7
fill ~93 ~10 ~5 ~93 ~13 ~5 wool 7
fill ~93 ~10 ~6 ~93 ~13 ~6 wool 7
fill ~93 ~10 ~7 ~93 ~13 ~7 wool 7
fill ~93 ~10 ~8 ~93 ~13 ~8 wool 7
fill ~93 ~10 ~9 ~93 ~13 ~9 wool 7
fill ~93 ~10 ~10 ~93 ~13 ~10 wool 7
fill ~93 ~10 ~11 ~93 ~13 ~11 wool 7
fill ~93 ~10 ~12 ~93 ~13 ~12 wool 7
fill ~93 ~10 ~13 ~93 ~13 ~13 wool 7
fill ~93 ~10 ~14 ~93 ~13 ~14 wool 7
fill ~93 ~10 ~15 ~93 ~13 ~15 wool 7
fill ~93 ~10 ~16 ~93 ~13 ~16 wool 7
fill ~93 ~10 ~17 ~93 ~13 ~17 wool 7
fill ~93 ~10 ~18 ~93 ~13 ~18 wool 7
fill ~93 ~10 ~19 ~93 ~13 ~19 wool 7
fill ~93 ~10 ~20 ~93 ~13 ~20 wool 7
fill ~93 ~10 ~21 ~93 ~13 ~21 wool 7
fill ~93 ~10 ~22 ~93 ~13 ~22 wool 7
fill ~93 ~10 ~23 ~93 ~13 ~23 wool 7
fill ~93 ~10 ~24 ~93 ~13 ~24 wool 7
fill ~93 ~10 ~25 ~93 ~13 ~25 wool 7
fill ~93 ~10 ~26 ~93 ~13 ~26 wool 7
fill ~93 ~10 ~27 ~93 ~13 ~27 wool 7
fill ~93 ~10 ~28 ~93 ~13 ~28 wool 7
fill ~93 ~10 ~29 ~93 ~13 ~29 wool 7
fill ~93 ~10 ~30 ~93 ~13 ~30 wool 7
fill ~93 ~10 ~31 ~93 ~13 ~31 wool 7
fill ~93 ~10 ~32 ~93 ~13 ~32 wool 7
fill ~93 ~10 ~33 ~93 ~13 ~33 wool 7
fill ~93 ~10 ~34 ~93 ~13 ~34 wool 7
fill ~93 ~10 ~35 ~93 ~13 ~35 wool 7
fill ~93 ~10 ~36 ~93 ~13 ~36 wool 7
fill ~93 ~10 ~37 ~93 ~13 ~37 wool 7
fill ~93 ~10 ~38 ~93 ~13 ~38 wool 7
fill ~93 ~10 ~39 ~93 ~13 ~39 wool 7
fill ~93 ~10 ~40 ~93 ~13 ~40 wool 7
fill ~93 ~10 ~41 ~93 ~13 ~41 wool 7
fill ~93 ~10 ~42 ~93 ~13 ~42 wool 7
fill ~93 ~10 ~43 ~93 ~13 ~43 wool 7
fill ~93 ~10 ~44 ~93 ~13 ~44 wool 7
fill ~93 ~10 ~45 ~93 ~13 ~45 wool 7
fill ~93 ~10 ~46 ~93 ~13 ~46 wool 7
fill ~93 ~10 ~47 ~93 ~13 ~47 wool 7
fill ~93 ~10 ~48 ~93 ~13 ~48 wool 7
fill ~93 ~10 ~49 ~93 ~13 ~49 wool 7
fill ~93 ~10 ~50 ~93 ~13 ~50 wool 7
fill ~93 ~10 ~51 ~93 ~13 ~51 wool 7
fill ~93 ~10 ~52 ~93 ~13 ~52 wool 7
fill ~93 ~10 ~53 ~93 ~13 ~53 wool 7
fill ~93 ~10 ~54 ~93 ~13 ~54 wool 7
fill ~93 ~10 ~55 ~93 ~13 ~55 wool 7
fill ~93 ~10 ~56 ~93 ~13 ~56 wool 7
fill ~93 ~10 ~57 ~93 ~13 ~57 wool 7
fill ~93 ~10 ~58 ~93 ~13 ~58 wool 7
fill ~93 ~10 ~59 ~93 ~13 ~59 wool 7
fill ~93 ~10 ~60 ~93 ~13 ~60 wool 7
fill ~93 ~10 ~61 ~93 ~13 ~61 wool 7
fill ~93 ~10 ~62 ~93 ~13 ~62 wool 7
fill ~93 ~10 ~64 ~93 ~13 ~64 wool 7
fill ~94 ~10 ~1 ~94 ~12 ~1 wool 0
fill ~94 ~10 ~65 ~94 ~12 ~65 wool 0
fill ~95 ~10 ~2 ~97 ~10 ~2 wool 15
fill ~95 ~10 ~64 ~97 ~10 ~64 wool 15
fill ~96 ~10 ~3 ~96 ~13 ~3 wool 15
fill ~96 ~10 ~63 ~96 ~13 ~63 wool 15
fill ~102 ~10 ~4 ~103 ~10 ~4 wool 7
fill ~102 ~10 ~62 ~103 ~10 ~62 wool 7
fill ~105 ~10 ~4 ~106 ~10 ~4 wool 7
fill ~105 ~10 ~62 ~106 ~10 ~62 wool 7
fill ~108 ~10 ~4 ~109 ~10 ~4 wool 7
fill ~108 ~10 ~62 ~109 ~10 ~62 wool 7
fill ~114 ~10 ~2 ~116 ~10 ~2 wool 15
fill ~114 ~10 ~64 ~116 ~10 ~64 wool 15
fill ~117 ~10 ~1 ~117 ~12 ~1 wool 0
fill ~117 ~10 ~8 ~118 ~10 ~8 wool 15
fill ~117 ~10 ~58 ~118 ~10 ~58 wool 15
fill ~117 ~10 ~65 ~117 ~12 ~65 wool 0
fill ~118 ~10 ~1 ~142 ~10 ~1 wool 15
fill ~118 ~10 ~2 ~118 ~13 ~2 wool 15
fill ~118 ~10 ~64 ~118 ~13 ~64 wool 15
fill ~118 ~10 ~65 ~142 ~10 ~65 wool 15
fill ~142 ~10 ~3 ~143 ~10 ~3 wool 0
fill ~142 ~10 ~63 ~143 ~10 ~63 wool 0
fill ~143 ~10 ~2 ~143 ~11 ~2 wool 0
fill ~143 ~10 ~64 ~143 ~11 ~64 wool 0
fill ~3 ~11 ~19 ~3 ~15 ~19 wool 0
setblock ~3 ~11 ~20 wool 15
fill ~3 ~11 ~21 ~3 ~15 ~21 wool 0
fill ~3 ~11 ~24 ~4 ~11 ~24 wool 0
fill ~3 ~11 ~25 ~3 ~11 ~42 wool 0
fill ~3 ~11 ~45 ~3 ~15 ~45 wool 0
setblock ~3 ~11 ~46 wool 15
fill ~3 ~11 ~47 ~3 ~15 ~47 wool 0
setblock ~4 ~11 ~20 wool 0
fill ~4 ~11 ~22 ~4 ~11 ~24 wool 0
fill ~4 ~11 ~42 ~4 ~11 ~47 wool 0
fill ~5 ~11 ~3 ~6 ~11 ~3 wool 0
fill ~5 ~11 ~4 ~5 ~11 ~19 wool 0
fill ~5 ~11 ~47 ~5 ~11 ~63 wool 0
fill ~6 ~11 ~63 ~6 ~12 ~63 wool 0
fill ~7 ~11 ~2 ~9 ~11 ~2 wool 0
fill ~7 ~11 ~64 ~9 ~11 ~64 wool 0
fill ~10 ~11 ~2 ~14 ~11 ~2 wool 15
fill ~10 ~11 ~64 ~14 ~11 ~64 wool 15
fill ~15 ~11 ~3 ~15 ~16 ~3 wool 15
fill ~15 ~11 ~8 ~18 ~11 ~8 wool 15
fill ~15 ~11 ~58 ~20 ~11 ~58 wool 15
fill ~15 ~11 ~63 ~15 ~15 ~63 wool 15
fill ~18 ~11 ~2 ~19 ~11 ~2 wool 15
fill ~18 ~11 ~3 ~18 ~13 ~3 wool 15
fill ~18 ~11 ~4 ~18 ~13 ~4 wool 15
fill ~18 ~11 ~5 ~18 ~13 ~5 wool 15
fill ~18 ~11 ~6 ~18 ~13 ~6 wool 15
fill ~18 ~11 ~60 ~18 ~13 ~60 wool 15
fill ~18 ~11 ~61 ~18 ~13 ~61 wool 15
fill ~18 ~11 ~62 ~18 ~13 ~62 wool 15
fill ~18 ~11 ~63 ~18 ~13 ~63 wool 15
fill ~18 ~11 ~64 ~19 ~11 ~64 wool 15
fill ~23 ~11 ~4 ~25 ~11 ~4 wool 7
fill ~23 ~11 ~62 ~25 ~11 ~62 wool 7
fill ~27 ~11 ~4 ~28 ~11 ~4 wool 7
fill ~27 ~11 ~62 ~28 ~11 ~62 wool 7
fill ~30 ~11 ~4 ~32 ~11 ~4 wool 7
fill ~30 ~11 ~62 ~32 ~11 ~62 wool 7
fill ~35 ~11 ~58 ~40 ~11 ~58 wool 15
fill ~36 ~11 ~2 ~37 ~11 ~2 wool 15
fill ~36 ~11 ~64 ~37 ~11 ~64 wool 15
fill ~37 ~11 ~3 ~37 ~13 ~3 wool 15
fill ~37 ~11 ~4 ~37 ~13 ~4 wool 15
fill ~37 ~11 ~5 ~37 ~13 ~5 wool 15
fill ~37 ~11 ~6 ~37 ~13 ~6 wool 15
fill ~37 ~11 ~8 ~40 ~11 ~8 wool 15
fill ~37 ~11 ~60 ~37 ~13 ~60 wool 15
fill ~37 ~11 ~61 ~37 ~13 ~61 wool 15
fill ~37 ~11 ~62 ~37 ~13 ~62 wool 15
fill ~37 ~11 ~63 ~37 ~13 ~63 wool 15
fill ~41 ~11 ~2 ~79 ~11 ~2 wool 15
fill ~41 ~11 ~64 ~79 ~11 ~64 wool 15
fill ~52 ~11 ~3 ~76 ~11 ~3 wool 7
fill ~52 ~11 ~4 ~52 ~12 ~4 wool 7
fill ~52 ~11 ~5 ~52 ~12 ~5 wool 7
fill ~52 ~11 ~6 ~52 ~12 ~6 wool 7
fill ~52 ~11 ~7 ~52 ~12 ~7 wool 7
fill ~52 ~11 ~8 ~52 ~12 ~8 wool 7
fill ~52 ~11 ~9 ~52 ~12 ~9 wool 7
fill ~52 ~11 ~10 ~52 ~12 ~10 wool 7
fill ~52 ~11 ~11 ~52 ~12 ~11 wool 7
fill ~52 ~11 ~12 ~52 ~12 ~12 wool 7
fill ~52 ~11 ~13 ~52 ~12 ~13 wool 7
fill ~52 ~11 ~14 ~52 ~12 ~14 wool 7
fill ~52 ~11 ~15 ~52 ~12 ~15 wool 7
fill ~52 ~11 ~16 ~52 ~12 ~16 wool 7
fill ~52 ~11 ~17 ~52 ~12 ~17 wool 7
fill ~52 ~11 ~18 ~52 ~12 ~18 wool 7
fill ~52 ~11 ~19 ~52 ~12 ~19 wool 7
fill ~52 ~11 ~20 ~52 ~12 ~20 wool 7
fill ~52 ~11 ~21 ~52 ~12 ~21 wool 7
fill ~52 ~11 ~22 ~52 ~12 ~22 wool 7
fill ~52 ~11 ~23 ~52 ~12 ~23 wool 7
fill ~52 ~11 ~24 ~52 ~12 ~24 wool 7
fill ~52 ~11 ~25 ~52 ~12 ~25 wool 7
fill ~52 ~11 ~26 ~52 ~12 ~26 wool 7
fill ~52 ~11 ~27 ~52 ~12 ~27 wool 7
fill ~52 ~11 ~28 ~52 ~12 ~28 wool 7
fill ~52 ~11 ~29 ~52 ~12 ~29 wool 7
fill ~52 ~11 ~30 ~52 ~17 ~30 wool 7
fill ~52 ~11 ~36 ~52 ~17 ~36 wool 7
fill ~52 ~11 ~37 ~52 ~12 ~37 wool 7
fill ~52 ~11 ~38 ~52 ~12 ~38 wool 7
fill ~52 ~11 ~39 ~52 ~12 ~39 wool 7
fill ~52 ~11 ~40 ~52 ~12 ~40 wool 7
fill ~52 ~11 ~41 ~52 ~12 ~41 wool 7
fill ~52 ~11 ~42 ~52 ~12 ~42 wool 7
fill ~52 ~11 ~43 ~52 ~12 ~43 wool 7
fill ~52 ~11 ~44 ~52 ~12 ~44 wool 7
fill ~52 ~11 ~45 ~52 ~12 ~45 wool 7
fill ~52 ~11 ~46 ~52 ~12 ~46 wool 7
fill ~52 ~11 ~47 ~52 ~12 ~47 wool 7
fill ~52 ~11 ~48 ~52 ~12 ~48 wool 7
fill ~52 ~11 ~49 ~52 ~12 ~49 wool 7
fill ~52 ~11 ~50 ~52 ~12 ~50 wool 7
fill ~52 ~11 ~51 ~52 ~12 ~51 wool 7
fill ~52 ~11 ~52 ~52 ~12 ~52 wool 7
fill ~52 ~11 ~53 ~52 ~12 ~53 wool 7
fill ~52 ~11 ~54 ~52 ~12 ~54 wool 7
fill ~52 ~11 ~55 ~52 ~12 ~55 wool 7
fill ~52 ~11 ~56 ~52 ~12 ~56 wool 7
fill ~52 ~11 ~57 ~52 ~12 ~57 wool 7
fill ~52 ~11 ~58 ~52 ~12 ~58 wool 7
fill ~52 ~11 ~59 ~52 ~12 ~59 wool 7
fill ~52 ~11 ~60 ~52 ~12 ~60 wool 7
fill ~52 ~11 ~61 ~52 ~12 ~61 wool 7
fill ~52 ~11 ~62 ~52 ~12 ~62 wool 7
fill ~52 ~11 ~63 ~76 ~11 ~63 wool 7
fill ~55 ~11 ~30 ~77 ~11 ~30 wool 7
fill ~55 ~11 ~36 ~77 ~11 ~36 wool 7
fill ~59 ~11 ~4 ~75 ~11 ~4 wool 7
fill ~59 ~11 ~62 ~75 ~11 ~62 wool 7
fill ~64 ~11 ~7 ~74 ~11 ~7 wool 15
fill ~64 ~11 ~26 ~74 ~11 ~26 wool 15
fill ~64 ~11 ~40 ~74 ~11 ~40 wool 15
fill ~64 ~11 ~59 ~74 ~11 ~59 wool 15
fill ~77 ~11 ~31 ~77 ~12 ~31 wool 7
fill ~77 ~11 ~32 ~77 ~12 ~32 wool 7
fill ~77 ~11 ~33 ~77 ~12 ~33 wool 7
fill ~77 ~11 ~34 ~77 ~12 ~34 wool 7
fill ~77 ~11 ~35 ~77 ~12 ~35 wool 7
fill ~78 ~11 ~3 ~93 ~11 ~3 wool 7
fill ~78 ~11 ~63 ~93 ~11 ~63 wool 7
fill ~79 ~11 ~4 ~90 ~11 ~4 wool 7
fill ~79 ~11 ~62 ~90 ~11 ~62 wool 7
fill ~80 ~11 ~1 ~93 ~11 ~1 wool 15
fill ~80 ~11 ~65 ~93 ~11 ~65 wool 15
fill ~85 ~11 ~8 ~85 ~13 ~8 wool 15
fill ~85 ~11 ~9 ~85 ~13 ~9 wool 15
fill ~85 ~11 ~10 ~85 ~13 ~10 wool 15
fill ~85 ~11 ~56 ~85 ~13 ~56 wool 15
fill ~85 ~11 ~57 ~85 ~13 ~57 wool 15
fill ~85 ~11 ~58 ~85 ~13 ~58 wool 15
fill ~86 ~11 ~7 ~92 ~11 ~7 wool 15
fill ~86 ~11 ~59 ~92 ~11 ~59 wool 15
fill ~96 ~11 ~2 ~97 ~11 ~2 wool 15
fill ~96 ~11 ~4 ~96 ~13 ~4 wool 15
fill ~96 ~11 ~5 ~96 ~13 ~5 wool 15
fill ~96 ~11 ~6 ~96 ~13 ~6 wool 15
fill ~96 ~11 ~7 ~96 ~13 ~7 wool 15
fill ~96 ~11 ~59 ~96 ~13 ~59 wool 15
fill ~96 ~11 ~60 ~96 ~13 ~60 wool 15
fill ~96 ~11 ~61 ~96 ~13 ~61 wool 15
fill ~96 ~11 ~62 ~96 ~13 ~62 wool 15
fill ~96 ~11 ~64 ~97 ~11 ~64 wool 15
fill ~101 ~11 ~4 ~103 ~11 ~4 wool 7
fill ~101 ~11 ~62 ~103 ~11 ~62 wool 7
fill ~105 ~11 ~4 ~106 ~11 ~4 wool 7
fill ~105 ~11 ~62 ~106 ~11 ~62 wool 7
fill ~108 ~11 ~4 ~110 ~11 ~4 wool 7
fill ~108 ~11 ~62 ~110 ~11 ~62 wool 7
fill ~114 ~11 ~2 ~115 ~11 ~2 wool 15
fill ~114 ~11 ~64 ~115 ~11 ~64 wool 15
fill ~115 ~11 ~3 ~115 ~13 ~3 wool 15
fill ~115 ~11 ~4 ~115 ~13 ~4 wool 15
fill ~115 ~11 ~5 ~115 ~13 ~5 wool 15
fill ~115 ~11 ~6 ~115 ~13 ~6 wool 15
fill ~115 ~11 ~7 ~115 ~13 ~7 wool 15
fill ~115 ~11 ~59 ~115 ~13 ~59 wool 15
fill ~115 ~11 ~60 ~115 ~13 ~60 wool 15
fill ~115 ~11 ~61 ~115 ~13 ~61 wool 15
fill ~115 ~11 ~62 ~115 ~13 ~62 wool 15
fill ~115 ~11 ~63 ~115 ~13 ~63 wool 15
fill ~116 ~11 ~8 ~118 ~11 ~8 wool 15
fill ~116 ~11 ~58 ~118 ~11 ~58 wool 15
fill ~118 ~11 ~1 ~142 ~11 ~1 wool 15
fill ~118 ~11 ~65 ~142 ~11 ~65 wool 15
fill ~143 ~11 ~1 ~143 ~13 ~1 wool 0
fill ~143 ~11 ~3 ~144 ~11 ~3 wool 0
fill ~143 ~11 ~63 ~144 ~11 ~63 wool 0
fill ~143 ~11 ~65 ~143 ~13 ~65 wool 0
fill ~144 ~11 ~2 ~144 ~13 ~2 wool 0
fill ~144 ~11 ~4 ~144 ~13 ~4 wool 0
fill ~144 ~11 ~5 ~144 ~13 ~5 wool 0
fill ~144 ~11 ~6 ~144 ~13 ~6 wool 0
fill ~144 ~11 ~7 ~144 ~13 ~7 wool 0
fill ~144 ~11 ~8 ~144 ~13 ~8 wool 0
fill ~144 ~11 ~9 ~144 ~13 ~9 wool 0
fill ~144 ~11 ~10 ~145 ~11 ~10 wool 0
fill ~144 ~11 ~11 ~144 ~13 ~11 wool 0
fill ~144 ~11 ~12 ~144 ~13 ~12 wool 0
fill ~144 ~11 ~13 ~144 ~13 ~13 wool 0
fill ~144 ~11 ~14 ~144 ~13 ~14 wool 0
fill ~144 ~11 ~15 ~144 ~13 ~15 wool 0
fill ~144 ~11 ~16 ~144 ~13 ~16 wool 0
fill ~144 ~11 ~17 ~144 ~13 ~17 wool 0
fill ~144 ~11 ~18 ~144 ~13 ~18 wool 0
fill ~144 ~11 ~19 ~144 ~13 ~19 wool 0
fill ~144 ~11 ~20 ~144 ~13 ~20 wool 0
fill ~144 ~11 ~21 ~144 ~13 ~21 wool 0
fill ~144 ~11 ~22 ~144 ~13 ~22 wool 0
fill ~144 ~11 ~23 ~144 ~13 ~23 wool 0
fill ~144 ~11 ~24 ~144 ~13 ~24 wool 0
fill ~144 ~11 ~25 ~144 ~13 ~25 wool 0
fill ~144 ~11 ~26 ~144 ~13 ~26 wool 0
fill ~144 ~11 ~27 ~144 ~13 ~27 wool 0
fill ~144 ~11 ~28 ~145 ~11 ~28 wool 0
fill ~144 ~11 ~29 ~145 ~11 ~29 wool 0
fill ~144 ~11 ~30 ~145 ~11 ~30 wool 0
fill ~144 ~11 ~31 ~145 ~11 ~31 wool 0
fill ~144 ~11 ~32 ~145 ~11 ~32 wool 0
fill ~144 ~11 ~33 ~145 ~11 ~33 wool 0
fill ~144 ~11 ~34 ~145 ~11 ~34 wool 0
fill ~144 ~11 ~35 ~145 ~11 ~35 wool 0
fill ~144 ~11 ~36 ~145 ~11 ~36 wool 0
fill ~144 ~11 ~37 ~145 ~11 ~37 wool 0
fill ~144 ~11 ~38 ~145 ~11 ~38 wool 0
fill ~144 ~11 ~39 ~144 ~13 ~39 wool 0
fill ~144 ~11 ~40 ~144 ~13 ~40 wool 0
fill ~144 ~11 ~41 ~144 ~13 ~41 wool 0
fill ~144 ~11 ~42 ~144 ~13 ~42 wool 0
fill ~144 ~11 ~43 ~144 ~13 ~43 wool 0
fill ~144 ~11 ~44 ~144 ~13 ~44 wool 0
fill ~144 ~11 ~45 ~144 ~13 ~45 wool 0
fill ~144 ~11 ~46 ~144 ~13 ~46 wool 0
fill ~144 ~11 ~47 ~144 ~13 ~47 wool 0
fill ~144 ~11 ~48 ~144 ~13 ~48 wool 0
fill ~144 ~11 ~49 ~144 ~13 ~49 wool 0
fill ~144 ~11 ~50 ~144 ~13 ~50 wool 0
fill ~144 ~11 ~51 ~144 ~13 ~51 wool 0
fill ~144 ~11 ~52 ~144 ~13 ~52 wool 0
fill ~144 ~11 ~53 ~144 ~13 ~53 wool 0
fill ~144 ~11 ~54 ~144 ~13 ~54 wool 0
fill ~144 ~11 ~55 ~144 ~13 ~55 wool 0
fill ~144 ~11 ~56 ~145 ~11 ~56 wool 0
fill ~144 ~11 ~57 ~144 ~13 ~57 wool 0
fill ~144 ~11 ~58 ~144 ~13 ~58 wool 0
fill ~144 ~11 ~59 ~144 ~13 ~59 wool 0
fill ~144 ~11 ~60 ~144 ~13 ~60 wool 0
fill ~144 ~11 ~61 ~144 ~13 ~61 wool 0
fill ~144 ~11 ~62 ~144 ~13 ~62 wool 0
fill ~144 ~11 ~64 ~144 ~13 ~64 wool 0
fill ~2 ~12 ~19 ~2 ~15 ~19 wool 0
fill ~2 ~12 ~20 ~2 ~15 ~20 wool 15
fill ~2 ~12 ~21 ~2 ~15 ~21 wool 0
fill ~2 ~12 ~23 ~3 ~12 ~23 wool 0
fill ~2 ~12 ~24 ~2 ~14 ~24 wool 0
fill ~2 ~12 ~25 ~2 ~14 ~25 wool 0
fill ~2 ~12 ~26 ~2 ~14 ~26 wool 0
fill ~2 ~12 ~27 ~2 ~14 ~27 wool 0
fill ~2 ~12 ~28 ~2 ~14 ~28 wool 0
fill ~2 ~12 ~29 ~2 ~14 ~29 wool 0
fill ~2 ~12 ~30 ~2 ~14 ~30 wool 0
fill ~2 ~12 ~31 ~2 ~14 ~31 wool 0
fill ~2 ~12 ~32 ~2 ~14 ~32 wool 0
fill ~2 ~12 ~33 ~2 ~15 ~33 wool 0
fill ~2 ~12 ~34 ~2 ~14 ~34 wool 0
fill ~2 ~12 ~35 ~2 ~14 ~35 wool 0
fill ~2 ~12 ~36 ~2 ~14 ~36 wool 0
fill ~2 ~12 ~37 ~2 ~14 ~37 wool 0
fill ~2 ~12 ~38 ~2 ~14 ~38 wool 0
fill ~2 ~12 ~39 ~2 ~14 ~39 wool 0
fill ~2 ~12 ~40 ~2 ~14 ~40 wool 0
fill ~2 ~12 ~41 ~2 ~14 ~41 wool 0
fill ~2 ~12 ~42 ~2 ~14 ~42 wool 0
fill ~2 ~12 ~43 ~3 ~12 ~43 wool 0
fill ~2 ~12 ~45 ~2 ~15 ~45 wool 0
fill ~2 ~12 ~46 ~2 ~15 ~46 wool 15
fill ~2 ~12 ~47 ~2 ~15 ~47 wool 0
fill ~3 ~12 ~20 ~3 ~14 ~20 wool 0
fill ~3 ~12 ~22 ~3 ~14 ~22 wool 0
fill ~3 ~12 ~44 ~3 ~14 ~44 wool 0
fill ~3 ~12 ~46 ~3 ~14 ~46 wool 0
fill ~4 ~12 ~3 ~6 ~12 ~3 wool 0
fill ~4 ~12 ~4 ~4 ~14 ~4 wool 0
fill ~4 ~12 ~5 ~4 ~14 ~5 wool 0
fill ~4 ~12 ~6 ~4 ~14 ~6 wool 0
fill ~4 ~12 ~7 ~4 ~14 ~7 wool 0
fill ~4 ~12 ~8 ~4 ~14 ~8 wool 0
fill ~4 ~12 ~9 ~4 ~14 ~9 wool 0
fill ~4 ~12 ~10 ~4 ~14 ~10 wool 0
fill ~4 ~12 ~11 ~4 ~14 ~11 wool 0
fill ~4 ~12 ~12 ~4 ~14 ~12 wool 0
fill ~4 ~12 ~13 ~4 ~14 ~13 wool 0
fill ~4 ~12 ~14 ~4 ~14 ~14 wool 0
fill ~4 ~12 ~15 ~4 ~14 ~15 wool 0
fill ~4 ~12 ~16 ~4 ~14 ~16 wool 0
fill ~4 ~12 ~17 ~4 ~14 ~17 wool 0
fill ~4 ~12 ~18 ~4 ~14 ~18 wool 0
fill ~4 ~12 ~48 ~4 ~14 ~48 wool 0
fill ~4 ~12 ~49 ~4 ~14 ~49 wool 0
fill ~4 ~12 ~50 ~4 ~14 ~50 wool 0
fill ~4 ~12 ~51 ~4 ~14 ~51 wool 0
fill ~4 ~12 ~52 ~4 ~14 ~52 wool 0
fill ~4 ~12 ~53 ~4 ~14 ~53 wool 0
fill ~4 ~12 ~54 ~4 ~14 ~54 wool 0
fill ~4 ~12 ~55 ~4 ~14 ~55 wool 0
fill ~4 ~12 ~56 ~4 ~14 ~56 wool 0
fill ~4 ~12 ~57 ~4 ~14 ~57 wool 0
fill ~4 ~12 ~58 ~4 ~14 ~58 wool 0
fill ~4 ~12 ~59 ~4 ~14 ~59 wool 0
fill ~4 ~12 ~60 ~4 ~14 ~60 wool 0
fill ~4 ~12 ~61 ~4 ~14 ~61 wool 0
fill ~4 ~12 ~62 ~4 ~14 ~62 wool 0
fill ~4 ~12 ~63 ~6 ~12 ~63 wool 0
fill ~5 ~12 ~2 ~9 ~12 ~2 wool 0
fill ~5 ~12 ~64 ~9 ~12 ~64 wool 0
fill ~6 ~12 ~1 ~9 ~12 ~1 wool 0
fill ~6 ~12 ~65 ~9 ~12 ~65 wool 0
fill ~10 ~12 ~2 ~14 ~12 ~2 wool 15
fill ~10 ~12 ~64 ~14 ~12 ~64 wool 15
fill ~15 ~12 ~8 ~19 ~12 ~8 wool 15
fill ~15 ~12 ~58 ~20 ~12 ~58 wool 15
fill ~18 ~12 ~2 ~19 ~12 ~2 wool 15
fill ~18 ~12 ~64 ~19 ~12 ~64 wool 15
fill ~21 ~12 ~2 ~21 ~13 ~2 wool 7
fill ~21 ~12 ~64 ~21 ~13 ~64 wool 7
fill ~22 ~12 ~3 ~23 ~12 ~3 wool 7
fill ~22 ~12 ~63 ~23 ~12 ~63 wool 7
setblock ~24 ~12 ~4 wool 7
setblock ~24 ~12 ~62 wool 7
fill ~27 ~12 ~4 ~28 ~12 ~4 wool 7
fill ~27 ~12 ~62 ~28 ~12 ~62 wool 7
fill ~31 ~12 ~4 ~32 ~12 ~4 wool 7
fill ~31 ~12 ~62 ~32 ~12 ~62 wool 7
fill ~32 ~12 ~3 ~33 ~12 ~3 wool 7
fill ~32 ~12 ~63 ~33 ~12 ~63 wool 7
fill ~34 ~12 ~2 ~34 ~13 ~2 wool 7
fill ~34 ~12 ~8 ~40 ~12 ~8 wool 15
fill ~34 ~12 ~64 ~34 ~13 ~64 wool 7
fill ~35 ~12 ~58 ~40 ~12 ~58 wool 15
fill ~36 ~12 ~2 ~37 ~12 ~2 wool 15
fill ~36 ~12 ~64 ~37 ~12 ~64 wool 15
fill ~41 ~12 ~2 ~80 ~12 ~2 wool 15
fill ~41 ~12 ~64 ~80 ~12 ~64 wool 15
fill ~52 ~12 ~3 ~76 ~12 ~3 wool 7
fill ~52 ~12 ~63 ~76 ~12 ~63 wool 7
fill ~55 ~12 ~30 ~77 ~12 ~30 wool 7
fill ~55 ~12 ~36 ~77 ~12 ~36 wool 7
fill ~59 ~12 ~4 ~75 ~12 ~4 wool 7
fill ~59 ~12 ~62 ~75 ~12 ~62 wool 7
fill ~63 ~12 ~37 ~63 ~13 ~37 wool 7
fill ~64 ~12 ~7 ~74 ~12 ~7 wool 15
fill ~64 ~12 ~11 ~64 ~12 ~22 wool 15
fill ~64 ~12 ~24 ~64 ~13 ~24 wool 15
fill ~64 ~12 ~25 ~64 ~13 ~25 wool 15
fill ~64 ~12 ~26 ~74 ~12 ~26 wool 15
fill ~64 ~12 ~38 ~67 ~12 ~38 wool 7
fill ~64 ~12 ~40 ~74 ~12 ~40 wool 15
fill ~64 ~12 ~41 ~64 ~13 ~41 wool 15
fill ~64 ~12 ~42 ~64 ~13 ~42 wool 15
fill ~64 ~12 ~44 ~64 ~12 ~55 wool 15
fill ~64 ~12 ~59 ~74 ~12 ~59 wool 15
fill ~68 ~12 ~37 ~68 ~13 ~37 wool 7
fill ~69 ~12 ~21 ~75 ~12 ~21 wool 15
fill ~69 ~12 ~22 ~75 ~12 ~22 wool 15
fill ~69 ~12 ~44 ~75 ~12 ~44 wool 15
fill ~69 ~12 ~45 ~75 ~12 ~45 wool 15
fill ~70 ~12 ~11 ~75 ~12 ~11 wool 15
fill ~70 ~12 ~12 ~75 ~12 ~12 wool 15
fill ~70 ~12 ~13 ~75 ~12 ~13 wool 15
fill ~70 ~12 ~14 ~75 ~12 ~14 wool 15
fill ~70 ~12 ~15 ~75 ~12 ~15 wool 15
fill ~70 ~12 ~16 ~75 ~12 ~16 wool 15
fill ~70 ~12 ~17 ~75 ~12 ~17 wool 15
fill ~70 ~12 ~18 ~75 ~12 ~18 wool 15
fill ~70 ~12 ~19 ~75 ~12 ~19 wool 15
fill ~70 ~12 ~20 ~75 ~12 ~20 wool 15
fill ~70 ~12 ~46 ~75 ~12 ~46 wool 15
fill ~70 ~12 ~47 ~75 ~12 ~47 wool 15
fill ~70 ~12 ~48 ~75 ~12 ~48 wool 15
fill ~70 ~12 ~49 ~75 ~12 ~49 wool 15
fill ~70 ~12 ~50 ~75 ~12 ~50 wool 15
fill ~70 ~12 ~51 ~75 ~12 ~51 wool 15
fill ~70 ~12 ~52 ~75 ~12 ~52 wool 15
fill ~70 ~12 ~53 ~75 ~12 ~53 wool 15
fill ~70 ~12 ~54 ~75 ~12 ~54 wool 15
fill ~70 ~12 ~55 ~75 ~12 ~55 wool 15
fill ~78 ~12 ~3 ~93 ~12 ~3 wool 7
fill ~78 ~12 ~63 ~93 ~12 ~63 wool 7
fill ~79 ~12 ~4 ~90 ~12 ~4 wool 7
fill ~79 ~12 ~62 ~90 ~12 ~62 wool 7
fill ~80 ~12 ~1 ~93 ~12 ~1 wool 15
fill ~80 ~12 ~65 ~93 ~12 ~65 wool 15
fill ~85 ~12 ~11 ~85 ~13 ~11 wool 15
fill ~85 ~12 ~12 ~85 ~13 ~12 wool 15
fill ~85 ~12 ~13 ~85 ~13 ~13 wool 15
fill ~85 ~12 ~14 ~85 ~13 ~14 wool 15
fill ~85 ~12 ~15 ~85 ~13 ~15 wool 15
fill ~85 ~12 ~16 ~85 ~13 ~16 wool 15
fill ~85 ~12 ~17 ~85 ~13 ~17 wool 15
fill ~85 ~12 ~18 ~85 ~13 ~18 wool 15
fill ~85 ~12 ~19 ~85 ~13 ~19 wool 15
fill ~85 ~12 ~20 ~85 ~13 ~20 wool 15
fill ~85 ~12 ~21 ~85 ~13 ~21 wool 15
fill ~85 ~12 ~22 ~85 ~13 ~22 wool 15
fill ~85 ~12 ~23 ~85 ~13 ~23 wool 15
fill ~85 ~12 ~24 ~85 ~13 ~24 wool 15
fill ~85 ~12 ~25 ~85 ~13 ~25 wool 15
fill ~85 ~12 ~26 ~85 ~13 ~26 wool 15
fill ~85 ~12 ~27 ~85 ~13 ~27 wool 15
fill ~85 ~12 ~28 ~85 ~13 ~28 wool 15
fill ~85 ~12 ~29 ~85 ~13 ~29 wool 15
fill ~85 ~12 ~30 ~85 ~13 ~30 wool 15
fill ~85 ~12 ~31 ~85 ~13 ~31 wool 15
fill ~85 ~12 ~32 ~85 ~13 ~32 wool 15
fill ~85 ~12 ~33 ~85 ~13 ~33 wool 15
fill ~85 ~12 ~34 ~85 ~13 ~34 wool 15
fill ~85 ~12 ~35 ~85 ~13 ~35 wool 15
fill ~85 ~12 ~36 ~85 ~13 ~36 wool 15
fill ~85 ~12 ~37 ~85 ~13 ~37 wool 15
fill ~85 ~12 ~38 ~85 ~13 ~38 wool 15
fill ~85 ~12 ~39 ~85 ~13 ~39 wool 15
fill ~85 ~12 ~40 ~85 ~13 ~40 wool 15
fill ~85 ~12 ~41 ~85 ~13 ~41 wool 15
fill ~85 ~12 ~42 ~85 ~13 ~42 wool 15
fill ~85 ~12 ~43 ~85 ~13 ~43 wool 15
fill ~85 ~12 ~44 ~85 ~13 ~44 wool 15
fill ~85 ~12 ~45 ~85 ~13 ~45 wool 15
fill ~85 ~12 ~46 ~85 ~13 ~46 wool 15
fill ~85 ~12 ~47 ~85 ~13 ~47 wool 15
fill ~85 ~12 ~48 ~85 ~13 ~48 wool 15
fill ~85 ~12 ~49 ~85 ~13 ~49 wool 15
fill ~85 ~12 ~50 ~85 ~13 ~50 wool 15
fill ~85 ~12 ~51 ~85 ~13 ~51 wool 15
fill ~85 ~12 ~52 ~85 ~13 ~52 wool 15
fill ~85 ~12 ~53 ~85 ~13 ~53 wool 15
fill ~85 ~12 ~54 ~85 ~13 ~54 wool 15
fill ~85 ~12 ~55 ~85 ~13 ~55 wool 15
fill ~86 ~12 ~7 ~92 ~12 ~7 wool 15
fill ~86 ~12 ~59 ~92 ~12 ~59 wool 15
fill ~96 ~12 ~2 ~97 ~12 ~2 wool 15
fill ~96 ~12 ~64 ~97 ~12 ~64 wool 15
fill ~99 ~12 ~2 ~99 ~13 ~2 wool 7
fill ~99 ~12 ~64 ~99 ~13 ~64 wool 7
fill ~100 ~12 ~3 ~101 ~12 ~3 wool 7
fill ~100 ~12 ~63 ~101 ~12 ~63 wool 7
setblock ~102 ~12 ~4 wool 7
setblock ~102 ~12 ~62 wool 7
fill ~105 ~12 ~4 ~106 ~12 ~4 wool 7
fill ~105 ~12 ~62 ~106 ~12 ~62 wool 7
fill ~109 ~12 ~4 ~110 ~12 ~4 wool 7
fill ~109 ~12 ~62 ~110 ~12 ~62 wool 7
fill ~110 ~12 ~3 ~111 ~12 ~3 wool 7
fill ~110 ~12 ~63 ~111 ~12 ~63 wool 7
fill ~112 ~12 ~2 ~112 ~13 ~2 wool 7
fill ~112 ~12 ~64 ~112 ~13 ~64 wool 7
fill ~114 ~12 ~2 ~115 ~12 ~2 wool 15
fill ~114 ~12 ~64 ~115 ~12 ~64 wool 15
fill ~116 ~12 ~8 ~118 ~12 ~8 wool 15
fill ~116 ~12 ~58 ~118 ~12 ~58 wool 15
fill ~118 ~12 ~1 ~142 ~12 ~1 wool 15
fill ~118 ~12 ~65 ~142 ~12 ~65 wool 15
fill ~143 ~12 ~3 ~144 ~12 ~3 wool 0
fill ~143 ~12 ~63 ~144 ~12 ~63 wool 0
fill ~144 ~12 ~10 ~144 ~13 ~10 wool 0
fill ~144 ~12 ~28 ~145 ~12 ~28 wool 0
fill ~144 ~12 ~29 ~144 ~13 ~29 wool 0
fill ~144 ~12 ~30 ~144 ~13 ~30 wool 0
fill ~144 ~12 ~31 ~144 ~13 ~31 wool 0
fill ~144 ~12 ~32 ~144 ~13 ~32 wool 0
fill ~144 ~12 ~33 ~144 ~13 ~33 wool 0
fill ~144 ~12 ~34 ~144 ~13 ~34 wool 0
fill ~144 ~12 ~35 ~144 ~13 ~35 wool 0
fill ~144 ~12 ~36 ~144 ~13 ~36 wool 0
fill ~144 ~12 ~37 ~144 ~13 ~37 wool 0
fill ~144 ~12 ~38 ~145 ~12 ~38 wool 0
fill ~144 ~12 ~56 ~144 ~13 ~56 wool 0
fill ~145 ~12 ~9 ~145 ~17 ~9 wool 0
fill ~145 ~12 ~10 ~145 ~13 ~10 wool 15
fill ~145 ~12 ~11 ~145 ~17 ~11 wool 0
fill ~145 ~12 ~55 ~145 ~17 ~55 wool 0
fill ~145 ~12 ~56 ~145 ~13 ~56 wool 15
fill ~145 ~12 ~57 ~145 ~17 ~57 wool 0
fill ~2 ~13 ~23 ~3 ~13 ~23 wool 0
fill ~2 ~13 ~43 ~3 ~13 ~43 wool 0
fill ~4 ~13 ~3 ~4 ~14 ~3 wool 0
fill ~4 ~13 ~63 ~4 ~14 ~63 wool 0
fill ~5 ~13 ~2 ~9 ~13 ~2 wool 0
fill ~5 ~13 ~64 ~9 ~13 ~64 wool 0
fill ~6 ~13 ~1 ~9 ~13 ~1 wool 0
fill ~6 ~13 ~65 ~9 ~13 ~65 wool 0
fill ~7 ~13 ~3 ~7 ~13 ~13 wool 0
fill ~7 ~13 ~53 ~7 ~15 ~53 wool 0
fill ~7 ~13 ~54 ~7 ~14 ~54 wool 0
fill ~7 ~13 ~55 ~7 ~14 ~55 wool 0
fill ~7 ~13 ~56 ~7 ~14 ~56 wool 0
fill ~7 ~13 ~57 ~7 ~15 ~57 wool 0
fill ~7 ~13 ~58 ~7 ~15 ~58 wool 0
fill ~7 ~13 ~59 ~7 ~14 ~59 wool 0
fill ~7 ~13 ~60 ~7 ~14 ~60 wool 0
fill ~7 ~13 ~61 ~7 ~14 ~61 wool 0
fill ~7 ~13 ~62 ~7 ~15 ~62 wool 0
fill ~7 ~13 ~63 ~7 ~13 ~53 wool 0
fill ~10 ~13 ~2 ~14 ~13 ~2 wool 15
fill ~10 ~13 ~64 ~14 ~13 ~64 wool 15
fill ~15 ~13 ~8 ~19 ~13 ~8 wool 15
fill ~15 ~13 ~58 ~20 ~13 ~58 wool 15
fill ~18 ~13 ~2 ~20 ~13 ~2 wool 15
fill ~18 ~13 ~64 ~20 ~13 ~64 wool 15
fill ~22 ~13 ~2 ~22 ~14 ~2 wool 7
fill ~22 ~13 ~3 ~23 ~13 ~3 wool 7
fill ~22 ~13 ~63 ~23 ~13 ~63 wool 7
fill ~22 ~13 ~64 ~22 ~14 ~64 wool 7
setblock ~26 ~13 ~4 wool 7
setblock ~26 ~13 ~62 wool 7
fill ~27 ~13 ~3 ~28 ~13 ~3 wool 7
fill ~27 ~13 ~63 ~28 ~13 ~63 wool 7
setblock ~29 ~13 ~4 wool 7
setblock ~29 ~13 ~62 wool 7
fill ~32 ~13 ~3 ~33 ~13 ~3 wool 7
fill ~32 ~13 ~63 ~33 ~13 ~63 wool 7
fill ~33 ~13 ~2 ~33 ~14 ~2 wool 7
fill ~33 ~13 ~64 ~33 ~14 ~64 wool 7
fill ~34 ~13 ~8 ~40 ~13 ~8 wool 15
fill ~35 ~13 ~2 ~37 ~13 ~2 wool 15
fill ~35 ~13 ~58 ~40 ~13 ~58 wool 15
fill ~35 ~13 ~64 ~37 ~13 ~64 wool 15
fill ~40 ~13 ~1 ~40 ~14 ~1 wool 0
fill ~40 ~13 ~2 ~40 ~14 ~2 wool 15
fill ~40 ~13 ~64 ~40 ~14 ~64 wool 15
fill ~40 ~13 ~65 ~40 ~14 ~65 wool 0
fill ~41 ~13 ~1 ~41 ~20 ~1 wool 15
fill ~41 ~13 ~65 ~41 ~20 ~65 wool 15
fill ~42 ~13 ~1 ~53 ~13 ~1 wool 0
fill ~42 ~13 ~65 ~53 ~13 ~65 wool 0
fill ~51 ~13 ~2 ~51 ~14 ~2 wool 7
fill ~51 ~13 ~3 ~76 ~13 ~3 wool 7
fill ~51 ~13 ~4 ~51 ~14 ~4 wool 7
fill ~51 ~13 ~5 ~51 ~14 ~5 wool 7
fill ~51 ~13 ~6 ~51 ~14 ~6 wool 7
fill ~51 ~13 ~7 ~51 ~14 ~7 wool 7
fill ~51 ~13 ~8 ~51 ~14 ~8 wool 7
fill ~51 ~13 ~9 ~51 ~14 ~9 wool 7
fill ~51 ~13 ~10 ~51 ~14 ~10 wool 7
fill ~51 ~13 ~11 ~51 ~14 ~11 wool 7
fill ~51 ~13 ~12 ~51 ~14 ~12 wool 7
fill ~51 ~13 ~13 ~51 ~14 ~13 wool 7
fill ~51 ~13 ~14 ~51 ~14 ~14 wool 7
fill ~51 ~13 ~15 ~51 ~14 ~15 wool 7
fill ~51 ~13 ~16 ~51 ~14 ~16 wool 7
fill ~51 ~13 ~17 ~51 ~14 ~17 wool 7
fill ~51 ~13 ~18 ~51 ~14 ~18 wool 7
fill ~51 ~13 ~19 ~51 ~14 ~19 wool 7
fill ~51 ~13 ~20 ~51 ~14 ~20 wool 7
fill ~51 ~13 ~21 ~51 ~14 ~21 wool 7
fill ~51 ~13 ~22 ~51 ~14 ~22 wool 7
fill ~51 ~13 ~23 ~51 ~14 ~23 wool 7
fill ~51 ~13 ~24 ~51 ~14 ~24 wool 7
fill ~51 ~13 ~25 ~51 ~14 ~25 wool 7
fill ~51 ~13 ~26 ~51 ~14 ~26 wool 7
fill ~51 ~13 ~27 ~51 ~14 ~27 wool 7
fill ~51 ~13 ~28 ~51 ~14 ~28 wool 7
fill ~51 ~13 ~29 ~51 ~14 ~29 wool 7
fill ~51 ~13 ~30 ~51 ~17 ~30 wool 7
fill ~51 ~13 ~36 ~51 ~17 ~36 wool 7
fill ~51 ~13 ~37 ~51 ~14 ~37 wool 7
fill ~51 ~13 ~38 ~51 ~14 ~38 wool 7
fill ~51 ~13 ~39 ~51 ~14 ~39 wool 7
fill ~51 ~13 ~40 ~51 ~14 ~40 wool 7
fill ~51 ~13 ~41 ~51 ~14 ~41 wool 7
fill ~51 ~13 ~42 ~51 ~14 ~42 wool 7
fill ~51 ~13 ~43 ~51 ~14 ~43 wool 7
fill ~51 ~13 ~44 ~51 ~14 ~44 wool 7
fill ~51 ~13 ~45 ~51 ~14 ~45 wool 7
fill ~51 ~13 ~46 ~51 ~14 ~46 wool 7
fill ~51 ~13 ~47 ~51 ~14 ~47 wool 7
fill ~51 ~13 ~48 ~51 ~14 ~48 wool 7
fill ~51 ~13 ~49 ~51 ~14 ~49 wool 7
fill ~51 ~13 ~50 ~51 ~14 ~50 wool 7
fill ~51 ~13 ~51 ~51 ~14 ~51 wool 7
fill ~51 ~13 ~52 ~51 ~14 ~52 wool 7
fill ~51 ~13 ~53 ~51 ~14 ~53 wool 7
fill ~51 ~13 ~54 ~51 ~14 ~54 wool 7
fill ~51 ~13 ~55 ~51 ~14 ~55 wool 7
fill ~51 ~13 ~56 ~51 ~14 ~56 wool 7
fill ~51 ~13 ~57 ~51 ~14 ~57 wool 7
fill ~51 ~13 ~58 ~51 ~14 ~58 wool 7
fill ~51 ~13 ~59 ~51 ~14 ~59 wool 7
fill ~51 ~13 ~60 ~51 ~14 ~60 wool 7
fill ~51 ~13 ~61 ~51 ~14 ~61 wool 7
fill ~51 ~13 ~62 ~51 ~14 ~62 wool 7
fill ~51 ~13 ~63 ~76 ~13 ~63 wool 7
fill ~51 ~13 ~64 ~51 ~14 ~64 wool 7
fill ~54 ~13 ~1 ~54 ~20 ~1 wool 15
fill ~54 ~13 ~65 ~54 ~20 ~65 wool 15
fill ~55 ~13 ~1 ~76 ~13 ~1 wool 0
fill ~55 ~13 ~30 ~76 ~13 ~30 wool 7
fill ~55 ~13 ~36 ~76 ~13 ~36 wool 7
fill ~55 ~13 ~65 ~76 ~13 ~65 wool 0
fill ~59 ~13 ~4 ~75 ~13 ~4 wool 7
fill ~59 ~13 ~62 ~75 ~13 ~62 wool 7
fill ~61 ~13 ~31 ~76 ~13 ~31 wool 7
fill ~61 ~13 ~32 ~76 ~13 ~32 wool 7
fill ~61 ~13 ~33 ~76 ~13 ~33 wool 7
fill ~61 ~13 ~34 ~76 ~13 ~34 wool 7
fill ~61 ~13 ~35 ~76 ~13 ~35 wool 7
fill ~64 ~13 ~8 ~76 ~13 ~8 wool 15
fill ~64 ~13 ~9 ~76 ~13 ~9 wool 15
fill ~64 ~13 ~10 ~76 ~13 ~10 wool 15
fill ~64 ~13 ~23 ~76 ~13 ~23 wool 15
fill ~64 ~13 ~37 ~67 ~13 ~37 iron_block 0
fill ~64 ~13 ~38 ~67 ~13 ~38 wool 7
fill ~64 ~13 ~43 ~76 ~13 ~43 wool 15
fill ~64 ~13 ~56 ~76 ~13 ~56 wool 15
fill ~64 ~13 ~57 ~76 ~13 ~57 wool 15
fill ~64 ~13 ~58 ~76 ~13 ~58 wool 15
fill ~65 ~13 ~11 ~69 ~13 ~11 wool 15
fill ~65 ~13 ~12 ~69 ~13 ~12 wool 15
fill ~65 ~13 ~13 ~69 ~13 ~13 wool 15
fill ~65 ~13 ~14 ~69 ~13 ~14 wool 15
fill ~65 ~13 ~15 ~69 ~13 ~15 wool 15
fill ~65 ~13 ~16 ~69 ~13 ~16 wool 15
fill ~65 ~13 ~17 ~69 ~13 ~17 wool 15
fill ~65 ~13 ~18 ~69 ~13 ~18 wool 15
fill ~65 ~13 ~19 ~69 ~13 ~19 wool 15
fill ~65 ~13 ~20 ~69 ~13 ~20 wool 15
fill ~65 ~13 ~21 ~69 ~13 ~21 wool 15
fill ~65 ~13 ~22 ~69 ~13 ~22 wool 15
fill ~65 ~13 ~24 ~76 ~13 ~24 wool 15
fill ~65 ~13 ~25 ~76 ~13 ~25 wool 15
fill ~65 ~13 ~41 ~76 ~13 ~41 wool 15
fill ~65 ~13 ~42 ~76 ~13 ~42 wool 15
fill ~65 ~13 ~44 ~69 ~13 ~44 wool 15
fill ~65 ~13 ~45 ~69 ~13 ~45 wool 15
fill ~65 ~13 ~46 ~69 ~13 ~46 wool 15
fill ~65 ~13 ~47 ~69 ~13 ~47 wool 15
fill ~65 ~13 ~48 ~69 ~13 ~48 wool 15
fill ~65 ~13 ~49 ~69 ~13 ~49 wool 15
fill ~65 ~13 ~50 ~69 ~13 ~50 wool 15
fill ~65 ~13 ~51 ~69 ~13 ~51 wool 15
fill ~65 ~13 ~52 ~69 ~13 ~52 wool 15
fill ~65 ~13 ~53 ~69 ~13 ~53 wool 15
fill ~65 ~13 ~54 ~69 ~13 ~54 wool 15
fill ~65 ~13 ~55 ~69 ~13 ~55 wool 15
fill ~76 ~13 ~2 ~76 ~20 ~2 wool 7
fill ~76 ~13 ~11 ~77 ~13 ~11 wool 15
fill ~76 ~13 ~12 ~77 ~13 ~12 wool 15
fill ~76 ~13 ~13 ~77 ~13 ~13 wool 15
fill ~76 ~13 ~14 ~77 ~13 ~14 wool 15
fill ~76 ~13 ~15 ~77 ~13 ~15 wool 15
fill ~76 ~13 ~16 ~77 ~13 ~16 wool 15
fill ~76 ~13 ~17 ~77 ~13 ~17 wool 15
fill ~76 ~13 ~18 ~77 ~13 ~18 wool 15
fill ~76 ~13 ~19 ~77 ~13 ~19 wool 15
fill ~76 ~13 ~20 ~77 ~13 ~20 wool 15
fill ~76 ~13 ~21 ~77 ~13 ~21 wool 15
fill ~76 ~13 ~22 ~77 ~13 ~22 wool 15
fill ~76 ~13 ~44 ~77 ~13 ~44 wool 15
fill ~76 ~13 ~45 ~77 ~13 ~45 wool 15
fill ~76 ~13 ~46 ~77 ~13 ~46 wool 15
fill ~76 ~13 ~47 ~77 ~13 ~47 wool 15
fill ~76 ~13 ~48 ~77 ~13 ~48 wool 15
fill ~76 ~13 ~49 ~77 ~13 ~49 wool 15
fill ~76 ~13 ~50 ~77 ~13 ~50 wool 15
fill ~76 ~13 ~51 ~77 ~13 ~51 wool 15
fill ~76 ~13 ~52 ~77 ~13 ~52 wool 15
fill ~76 ~13 ~53 ~77 ~13 ~53 wool 15
fill ~76 ~13 ~54 ~77 ~13 ~54 wool 15
fill ~76 ~13 ~55 ~77 ~13 ~55 wool 15
fill ~76 ~13 ~64 ~76 ~20 ~64 wool 7
fill ~77 ~13 ~1 ~77 ~20 ~1 wool 15
fill ~77 ~13 ~65 ~77 ~20 ~65 wool 15
fill ~78 ~13 ~1 ~79 ~13 ~1 wool 0
fill ~78 ~13 ~2 ~78 ~20 ~2 wool 7
fill ~78 ~13 ~3 ~93 ~13 ~3 wool 7
fill ~78 ~13 ~63 ~93 ~13 ~63 wool 7
fill ~78 ~13 ~64 ~78 ~20 ~64 wool 7
fill ~78 ~13 ~65 ~79 ~13 ~65 wool 0
fill ~79 ~13 ~4 ~90 ~13 ~4 wool 7
fill ~79 ~13 ~62 ~90 ~13 ~62 wool 7
fill ~80 ~13 ~0 ~92 ~13 ~0 wool 0
fill ~80 ~13 ~66 ~92 ~13 ~66 wool 0
fill ~86 ~13 ~7 ~92 ~13 ~7 wool 15
fill ~86 ~13 ~8 ~86 ~14 ~8 wool 15
fill ~86 ~13 ~9 ~86 ~14 ~9 wool 15
fill ~86 ~13 ~11 ~92 ~13 ~11 wool 15
fill ~86 ~13 ~12 ~92 ~13 ~12 wool 15
fill ~86 ~13 ~13 ~92 ~13 ~13 wool 15
fill ~86 ~13 ~14 ~92 ~13 ~14 wool 15
fill ~86 ~13 ~15 ~92 ~13 ~15 wool 15
fill ~86 ~13 ~16 ~92 ~13 ~16 wool 15
fill ~86 ~13 ~17 ~92 ~13 ~17 wool 15
fill ~86 ~13 ~18 ~92 ~13 ~18 wool 15
fill ~86 ~13 ~19 ~92 ~13 ~19 wool 15
fill ~86 ~13 ~20 ~92 ~13 ~20 wool 15
fill ~86 ~13 ~21 ~92 ~13 ~21 wool 15
fill ~86 ~13 ~22 ~92 ~13 ~22 wool 15
fill ~86 ~13 ~23 ~92 ~13 ~23 wool 15
fill ~86 ~13 ~24 ~92 ~13 ~24 wool 15
fill ~86 ~13 ~25 ~92 ~13 ~25 wool 15
fill ~86 ~13 ~26 ~92 ~13 ~26 wool 15
fill ~86 ~13 ~27 ~92 ~13 ~27 wool 15
fill ~86 ~13 ~28 ~92 ~13 ~28 wool 15
fill ~86 ~13 ~29 ~92 ~13 ~29 wool 15
fill ~86 ~13 ~30 ~92 ~13 ~30 wool 15
fill ~86 ~13 ~31 ~92 ~13 ~31 wool 15
fill ~86 ~13 ~32 ~92 ~13 ~32 wool 15
fill ~86 ~13 ~33 ~92 ~13 ~33 wool 15
fill ~86 ~13 ~34 ~92 ~13 ~34 wool 15
fill ~86 ~13 ~35 ~92 ~13 ~35 wool 15
fill ~86 ~13 ~36 ~92 ~13 ~36 wool 15
fill ~86 ~13 ~37 ~92 ~13 ~37 wool 15
fill ~86 ~13 ~38 ~92 ~13 ~38 wool 15
fill ~86 ~13 ~39 ~92 ~13 ~39 wool 15
fill ~86 ~13 ~40 ~92 ~13 ~40 wool 15
fill ~86 ~13 ~41 ~92 ~13 ~41 wool 15
fill ~86 ~13 ~42 ~92 ~13 ~42 wool 15
fill ~86 ~13 ~43 ~92 ~13 ~43 wool 15
fill ~86 ~13 ~44 ~92 ~13 ~44 wool 15
fill ~86 ~13 ~45 ~92 ~13 ~45 wool 15
fill ~86 ~13 ~46 ~92 ~13 ~46 wool 15
fill ~86 ~13 ~47 ~92 ~13 ~47 wool 15
fill ~86 ~13 ~48 ~92 ~13 ~48 wool 15
fill ~86 ~13 ~49 ~92 ~13 ~49 wool 15
fill ~86 ~13 ~50 ~92 ~13 ~50 wool 15
fill ~86 ~13 ~51 ~92 ~13 ~51 wool 15
fill ~86 ~13 ~52 ~92 ~13 ~52 wool 15
fill ~86 ~13 ~53 ~92 ~13 ~53 wool 15
fill ~86 ~13 ~54 ~92 ~13 ~54 wool 15
fill ~86 ~13 ~55 ~92 ~13 ~55 wool 15
fill ~86 ~13 ~57 ~86 ~14 ~57 wool 15
fill ~86 ~13 ~58 ~86 ~14 ~58 wool 15
fill ~86 ~13 ~59 ~92 ~13 ~59 wool 15
setblock ~93 ~13 ~0 wool 15
setblock ~93 ~13 ~1 wool 7
setblock ~93 ~13 ~65 wool 7
setblock ~93 ~13 ~66 wool 15
fill ~94 ~13 ~0 ~95 ~13 ~0 wool 0
fill ~94 ~13 ~66 ~95 ~13 ~66 wool 0
fill ~96 ~13 ~2 ~98 ~13 ~2 wool 15
fill ~96 ~13 ~64 ~98 ~13 ~64 wool 15
fill ~100 ~13 ~2 ~100 ~14 ~2 wool 7
fill ~100 ~13 ~3 ~101 ~13 ~3 wool 7
fill ~100 ~13 ~63 ~101 ~13 ~63 wool 7
fill ~100 ~13 ~64 ~100 ~14 ~64 wool 7
fill ~104 ~13 ~4 ~104 ~14 ~4 wool 7
fill ~104 ~13 ~62 ~104 ~14 ~62 wool 7
fill ~105 ~13 ~3 ~106 ~13 ~3 wool 7
fill ~105 ~13 ~63 ~106 ~13 ~63 wool 7
fill ~107 ~13 ~4 ~107 ~14 ~4 wool 7
fill ~107 ~13 ~62 ~107 ~14 ~62 wool 7
fill ~110 ~13 ~3 ~111 ~13 ~3 wool 7
fill ~110 ~13 ~63 ~111 ~13 ~63 wool 7
fill ~111 ~13 ~2 ~111 ~14 ~2 wool 7
fill ~111 ~13 ~64 ~111 ~14 ~64 wool 7
fill ~113 ~13 ~2 ~115 ~13 ~2 wool 15
fill ~113 ~13 ~64 ~115 ~13 ~64 wool 15
fill ~116 ~13 ~8 ~118 ~13 ~8 wool 15
fill ~116 ~13 ~58 ~118 ~13 ~58 wool 15
setblock ~117 ~13 ~0 wool 0
setblock ~117 ~13 ~66 wool 0
fill ~118 ~13 ~0 ~118 ~20 ~0 wool 15
fill ~118 ~13 ~1 ~118 ~10 ~1 wool 15
fill ~118 ~13 ~65 ~118 ~10 ~65 wool 15
fill ~118 ~13 ~66 ~118 ~20 ~66 wool 15
fill ~119 ~13 ~0 ~141 ~13 ~0 wool 0
fill ~119 ~13 ~66 ~141 ~13 ~66 wool 0
fill ~142 ~13 ~0 ~142 ~17 ~0 wool 15
fill ~142 ~13 ~66 ~142 ~17 ~66 wool 15
setblock ~144 ~13 ~3 wool 0
fill ~144 ~13 ~28 ~145 ~13 ~28 wool 0
fill ~144 ~13 ~38 ~145 ~13 ~38 wool 0
setblock ~144 ~13 ~63 wool 0
fill ~2 ~14 ~23 ~4 ~14 ~23 wool 0
fill ~2 ~14 ~43 ~4 ~14 ~43 wool 0
fill ~3 ~14 ~24 ~3 ~14 ~29 wool 0
fill ~3 ~14 ~37 ~3 ~14 ~47 wool 0
fill ~4 ~14 ~19 ~5 ~14 ~19 wool 0
fill ~4 ~14 ~20 ~4 ~15 ~20 wool 0
fill ~4 ~14 ~21 ~4 ~14 ~23 wool 0
fill ~4 ~14 ~44 ~4 ~14 ~63 wool 0
fill ~5 ~14 ~2 ~6 ~14 ~2 wool 0
fill ~5 ~14 ~3 ~6 ~14 ~3 wool 0
fill ~5 ~14 ~4 ~7 ~14 ~4 wool 0
fill ~5 ~14 ~5 ~7 ~14 ~5 wool 0
fill ~5 ~14 ~6 ~7 ~14 ~6 wool 0
fill ~5 ~14 ~7 ~7 ~14 ~7 wool 0
fill ~5 ~14 ~8 ~7 ~14 ~8 wool 0
fill ~5 ~14 ~9 ~7 ~14 ~9 wool 0
fill ~5 ~14 ~10 ~7 ~14 ~10 wool 0
fill ~5 ~14 ~11 ~7 ~14 ~11 wool 0
fill ~5 ~14 ~12 ~7 ~14 ~12 wool 0
fill ~5 ~14 ~13 ~7 ~14 ~13 wool 0
fill ~5 ~14 ~14 ~6 ~14 ~14 wool 0
fill ~5 ~14 ~15 ~6 ~14 ~15 wool 0
fill ~5 ~14 ~16 ~6 ~14 ~16 wool 0
fill ~5 ~14 ~17 ~5 ~14 ~19 wool 0
fill ~5 ~14 ~47 ~5 ~14 ~64 wool 0
fill ~6 ~14 ~1 ~8 ~14 ~1 wool 0
fill ~6 ~14 ~50 ~6 ~14 ~65 wool 0
fill ~7 ~14 ~65 ~8 ~14 ~65 wool 0
fill ~9 ~14 ~1 ~14 ~14 ~1 wool 15
fill ~9 ~14 ~65 ~14 ~14 ~65 wool 15
fill ~14 ~14 ~2 ~15 ~14 ~2 wool 15
fill ~14 ~14 ~64 ~15 ~14 ~64 wool 15
fill ~15 ~14 ~1 ~15 ~15 ~1 wool 0
fill ~15 ~14 ~8 ~20 ~14 ~8 wool 15
fill ~15 ~14 ~59 ~15 ~15 ~59 wool 15
fill ~15 ~14 ~65 ~15 ~15 ~65 wool 0
fill ~16 ~14 ~58 ~20 ~14 ~58 wool 15
fill ~19 ~14 ~2 ~21 ~14 ~2 wool 15
fill ~19 ~14 ~3 ~19 ~14 ~6 wool 15
fill ~19 ~14 ~60 ~19 ~14 ~64 wool 15
fill ~20 ~14 ~64 ~21 ~14 ~64 wool 15
fill ~23 ~14 ~2 ~23 ~15 ~2 wool 7
fill ~23 ~14 ~64 ~23 ~15 ~64 wool 7
fill ~26 ~14 ~3 ~29 ~14 ~3 wool 7
fill ~26 ~14 ~63 ~29 ~14 ~63 wool 7
fill ~32 ~14 ~2 ~32 ~15 ~2 wool 7
fill ~32 ~14 ~64 ~32 ~15 ~64 wool 7
fill ~33 ~14 ~8 ~40 ~14 ~8 wool 15
fill ~34 ~14 ~2 ~36 ~14 ~2 wool 15
fill ~34 ~14 ~64 ~36 ~14 ~64 wool 15
fill ~35 ~14 ~58 ~40 ~14 ~58 wool 15
fill ~36 ~14 ~3 ~36 ~14 ~6 wool 15
fill ~36 ~14 ~60 ~36 ~14 ~64 wool 15
fill ~42 ~14 ~1 ~53 ~14 ~1 wool 0
fill ~42 ~14 ~65 ~53 ~14 ~65 wool 0
fill ~51 ~14 ~3 ~76 ~14 ~3 wool 7
fill ~51 ~14 ~63 ~76 ~14 ~63 wool 7
fill ~55 ~14 ~1 ~76 ~14 ~1 wool 0
fill ~55 ~14 ~30 ~60 ~14 ~30 wool 7
fill ~55 ~14 ~36 ~60 ~14 ~36 wool 7
fill ~55 ~14 ~65 ~76 ~14 ~65 wool 0
fill ~60 ~14 ~31 ~60 ~14 ~36 wool 7
fill ~65 ~14 ~9 ~69 ~14 ~9 wool 15
fill ~65 ~14 ~10 ~69 ~14 ~10 wool 15
fill ~65 ~14 ~23 ~69 ~14 ~23 wool 15
fill ~65 ~14 ~24 ~69 ~14 ~24 wool 15
fill ~65 ~14 ~37 ~65 ~15 ~37 iron_block 0
fill ~65 ~14 ~42 ~69 ~14 ~42 wool 15
fill ~65 ~14 ~43 ~69 ~14 ~43 wool 15
fill ~65 ~14 ~56 ~69 ~14 ~56 wool 15
fill ~65 ~14 ~57 ~69 ~14 ~57 wool 15
fill ~76 ~14 ~8 ~76 ~21 ~8 wool 15
fill ~76 ~14 ~9 ~76 ~21 ~9 wool 15
fill ~76 ~14 ~10 ~76 ~21 ~10 wool 15
fill ~76 ~14 ~11 ~77 ~14 ~11 wool 15
fill ~76 ~14 ~12 ~77 ~14 ~12 wool 15
fill ~76 ~14 ~13 ~77 ~14 ~13 wool 15
fill ~76 ~14 ~14 ~77 ~14 ~14 wool 15
fill ~76 ~14 ~15 ~77 ~14 ~15 wool 15
fill ~76 ~14 ~16 ~77 ~14 ~16 wool 15
fill ~76 ~14 ~17 ~77 ~14 ~17 wool 15
fill ~76 ~14 ~18 ~77 ~14 ~18 wool 15
fill ~76 ~14 ~19 ~77 ~14 ~19 wool 15
fill ~76 ~14 ~20 ~77 ~14 ~20 wool 15
fill ~76 ~14 ~21 ~77 ~14 ~21 wool 15
fill ~76 ~14 ~22 ~77 ~14 ~22 wool 15
fill ~76 ~14 ~23 ~76 ~21 ~23 wool 15
fill ~76 ~14 ~24 ~76 ~21 ~24 wool 15
fill ~76 ~14 ~25 ~76 ~21 ~25 wool 15
fill ~76 ~14 ~41 ~76 ~21 ~41 wool 15
fill ~76 ~14 ~42 ~76 ~21 ~42 wool 15
fill ~76 ~14 ~43 ~76 ~21 ~43 wool 15
fill ~76 ~14 ~44 ~77 ~14 ~44 wool 15
fill ~76 ~14 ~45 ~77 ~14 ~45 wool 15
fill ~76 ~14 ~46 ~77 ~14 ~46 wool 15
fill ~76 ~14 ~47 ~77 ~14 ~47 wool 15
fill ~76 ~14 ~48 ~77 ~14 ~48 wool 15
fill ~76 ~14 ~49 ~77 ~14 ~49 wool 15
fill ~76 ~14 ~50 ~77 ~14 ~50 wool 15
fill ~76 ~14 ~51 ~77 ~14 ~51 wool 15
fill ~76 ~14 ~52 ~77 ~14 ~52 wool 15
fill ~76 ~14 ~53 ~77 ~14 ~53 wool 15
fill ~76 ~14 ~54 ~77 ~14 ~54 wool 15
fill ~76 ~14 ~55 ~77 ~14 ~55 wool 15
fill ~76 ~14 ~56 ~76 ~21 ~56 wool 15
fill ~76 ~14 ~57 ~76 ~21 ~57 wool 15
fill ~76 ~14 ~58 ~76 ~21 ~58 wool 15
fill ~78 ~14 ~1 ~79 ~14 ~1 wool 0
fill ~78 ~14 ~3 ~94 ~14 ~3 wool 7
fill ~78 ~14 ~63 ~94 ~14 ~63 wool 7
fill ~78 ~14 ~65 ~79 ~14 ~65 wool 0
fill ~80 ~14 ~0 ~93 ~14 ~0 wool 0
fill ~80 ~14 ~66 ~93 ~14 ~66 wool 0
fill ~86 ~14 ~10 ~93 ~14 ~10 wool 15
fill ~86 ~14 ~24 ~93 ~14 ~24 wool 15
fill ~86 ~14 ~25 ~93 ~14 ~25 wool 15
fill ~86 ~14 ~26 ~93 ~14 ~26 wool 15
fill ~86 ~14 ~40 ~93 ~14 ~40 wool 15
fill ~86 ~14 ~41 ~93 ~14 ~41 wool 15
fill ~86 ~14 ~42 ~93 ~14 ~42 wool 15
fill ~86 ~14 ~56 ~93 ~14 ~56 wool 15
fill ~87 ~14 ~8 ~93 ~14 ~8 wool 15
fill ~87 ~14 ~9 ~93 ~14 ~9 wool 15
fill ~87 ~14 ~57 ~93 ~14 ~57 wool 15
fill ~87 ~14 ~58 ~93 ~14 ~58 wool 15
fill ~93 ~14 ~11 ~93 ~14 ~58 wool 15
fill ~94 ~14 ~0 ~94 ~20 ~0 wool 15
fill ~94 ~14 ~1 ~94 ~14 ~65 wool 7
fill ~94 ~14 ~66 ~94 ~20 ~66 wool 15
fill ~95 ~14 ~0 ~97 ~14 ~0 wool 0
fill ~95 ~14 ~66 ~97 ~14 ~66 wool 0
fill ~97 ~14 ~2 ~99 ~14 ~2 wool 15
fill ~97 ~14 ~3 ~97 ~14 ~7 wool 15
fill ~97 ~14 ~59 ~97 ~14 ~64 wool 15
fill ~98 ~14 ~64 ~99 ~14 ~64 wool 15
fill ~101 ~14 ~2 ~101 ~15 ~2 wool 7
fill ~101 ~14 ~64 ~101 ~15 ~64 wool 7
fill ~104 ~14 ~3 ~107 ~14 ~3 wool 7
fill ~104 ~14 ~63 ~107 ~14 ~63 wool 7
fill ~110 ~14 ~2 ~110 ~15 ~2 wool 7
fill ~110 ~14 ~64 ~110 ~15 ~64 wool 7
fill ~112 ~14 ~2 ~114 ~14 ~2 wool 15
fill ~112 ~14 ~64 ~114 ~14 ~64 wool 15
fill ~114 ~14 ~3 ~114 ~14 ~7 wool 15
fill ~114 ~14 ~59 ~114 ~14 ~64 wool 15
fill ~115 ~14 ~8 ~116 ~14 ~8 wool 15
fill ~115 ~14 ~58 ~116 ~14 ~58 wool 15
setblock ~116 ~14 ~0 wool 0
setblock ~116 ~14 ~66 wool 0
fill ~117 ~14 ~0 ~117 ~20 ~0 wool 15
fill ~117 ~14 ~1 ~117 ~14 ~7 wool 15
fill ~117 ~14 ~59 ~117 ~15 ~59 wool 15
fill ~117 ~14 ~60 ~117 ~14 ~66 wool 15
fill ~119 ~14 ~0 ~141 ~14 ~0 wool 0
fill ~119 ~14 ~66 ~141 ~14 ~66 wool 0
fill ~143 ~14 ~0 ~143 ~17 ~0 wool 0
fill ~143 ~14 ~66 ~143 ~17 ~66 wool 0
fill ~144 ~14 ~1 ~144 ~17 ~1 wool 0
fill ~144 ~14 ~65 ~144 ~17 ~65 wool 0
fill ~145 ~14 ~2 ~145 ~17 ~2 wool 0
fill ~145 ~14 ~3 ~145 ~17 ~3 wool 0
fill ~145 ~14 ~4 ~145 ~16 ~4 wool 0
fill ~145 ~14 ~5 ~145 ~16 ~5 wool 0
fill ~145 ~14 ~6 ~145 ~16 ~6 wool 0
fill ~145 ~14 ~7 ~145 ~16 ~7 wool 0
fill ~145 ~14 ~8 ~145 ~16 ~8 wool 0
fill ~145 ~14 ~10 ~145 ~16 ~10 wool 0
fill ~145 ~14 ~12 ~145 ~16 ~12 wool 0
fill ~145 ~14 ~13 ~145 ~16 ~13 wool 0
fill ~145 ~14 ~14 ~145 ~16 ~14 wool 0
fill ~145 ~14 ~15 ~145 ~16 ~15 wool 0
fill ~145 ~14 ~16 ~145 ~16 ~16 wool 0
fill ~145 ~14 ~17 ~145 ~16 ~17 wool 0
fill ~145 ~14 ~18 ~145 ~17 ~18 wool 0
fill ~145 ~14 ~19 ~145 ~17 ~19 wool 0
fill ~145 ~14 ~20 ~145 ~17 ~20 wool 0
fill ~145 ~14 ~21 ~145 ~17 ~21 wool 0
fill ~145 ~14 ~22 ~145 ~17 ~22 wool 0
fill ~145 ~14 ~23 ~145 ~17 ~23 wool 0
fill ~145 ~14 ~24 ~145 ~17 ~24 wool 0
fill ~145 ~14 ~25 ~145 ~17 ~25 wool 0
fill ~145 ~14 ~26 ~145 ~17 ~26 wool 0
fill ~145 ~14 ~27 ~145 ~17 ~27 wool 0
fill ~145 ~14 ~28 ~146 ~14 ~28 wool 0
fill ~145 ~14 ~29 ~145 ~17 ~29 wool 0
fill ~145 ~14 ~30 ~145 ~17 ~30 wool 0
fill ~145 ~14 ~31 ~145 ~16 ~31 wool 0
fill ~145 ~14 ~32 ~145 ~16 ~32 wool 0
fill ~145 ~14 ~33 ~145 ~16 ~33 wool 0
fill ~145 ~14 ~34 ~145 ~16 ~34 wool 0
fill ~145 ~14 ~35 ~145 ~16 ~35 wool 0
fill ~145 ~14 ~36 ~145 ~17 ~36 wool 0
fill ~145 ~14 ~37 ~145 ~17 ~37 wool 0
fill ~145 ~14 ~38 ~146 ~14 ~38 wool 0
fill ~145 ~14 ~39 ~145 ~17 ~39 wool 0
fill ~145 ~14 ~40 ~145 ~17 ~40 wool 0
fill ~145 ~14 ~41 ~145 ~17 ~41 wool 0
fill ~145 ~14 ~42 ~145 ~17 ~42 wool 0
fill ~145 ~14 ~43 ~145 ~17 ~43 wool 0
fill ~145 ~14 ~44 ~145 ~17 ~44 wool 0
fill ~145 ~14 ~45 ~145 ~17 ~45 wool 0
fill ~145 ~14 ~46 ~145 ~17 ~46 wool 0
fill ~145 ~14 ~47 ~145 ~17 ~47 wool 0
fill ~145 ~14 ~48 ~145 ~17 ~48 wool 0
fill ~145 ~14 ~49 ~145 ~16 ~49 wool 0
fill ~145 ~14 ~50 ~145 ~16 ~50 wool 0
fill ~145 ~14 ~51 ~145 ~16 ~51 wool 0
fill ~145 ~14 ~52 ~145 ~16 ~52 wool 0
fill ~145 ~14 ~53 ~145 ~16 ~53 wool 0
fill ~145 ~14 ~54 ~145 ~16 ~54 wool 0
fill ~145 ~14 ~56 ~145 ~16 ~56 wool 0
fill ~145 ~14 ~58 ~145 ~16 ~58 wool 0
fill ~145 ~14 ~59 ~145 ~16 ~59 wool 0
fill ~145 ~14 ~60 ~145 ~16 ~60 wool 0
fill ~145 ~14 ~61 ~145 ~16 ~61 wool 0
fill ~145 ~14 ~62 ~145 ~16 ~62 wool 0
fill ~145 ~14 ~63 ~145 ~17 ~63 wool 0
fill ~145 ~14 ~64 ~145 ~17 ~64 wool 0
fill ~146 ~14 ~9 ~146 ~16 ~9 wool 0
fill ~146 ~14 ~10 ~146 ~16 ~10 wool 15
fill ~146 ~14 ~11 ~146 ~16 ~11 wool 0
fill ~146 ~14 ~55 ~146 ~16 ~55 wool 0
fill ~146 ~14 ~56 ~146 ~16 ~56 wool 15
fill ~146 ~14 ~57 ~146 ~16 ~57 wool 0
fill ~3 ~15 ~30 ~4 ~15 ~30 wool 0
fill ~3 ~15 ~31 ~3 ~15 ~36 wool 0
fill ~4 ~15 ~24 ~5 ~15 ~24 wool 0
fill ~4 ~15 ~25 ~4 ~15 ~30 wool 0
fill ~4 ~15 ~36 ~4 ~15 ~42 wool 0
fill ~4 ~15 ~46 ~6 ~15 ~46 wool 0
fill ~5 ~15 ~20 ~6 ~15 ~20 wool 0
fill ~5 ~15 ~21 ~5 ~15 ~24 wool 0
fill ~5 ~15 ~42 ~5 ~15 ~46 wool 0
fill ~6 ~15 ~2 ~6 ~16 ~2 glass 0
fill ~6 ~15 ~17 ~7 ~15 ~17 wool 0
fill ~6 ~15 ~18 ~6 ~15 ~20 wool 0
fill ~6 ~15 ~47 ~6 ~15 ~49 wool 0
fill ~6 ~15 ~64 ~6 ~16 ~64 glass 0
fill ~7 ~15 ~1 ~7 ~16 ~1 glass 0
setblock ~7 ~15 ~2 wool 8
fill ~7 ~15 ~3 ~7 ~16 ~3 glass 0
setblock ~7 ~15 ~4 wool 0
fill ~7 ~15 ~8 ~8 ~15 ~8 wool 0
fill ~7 ~15 ~9 ~8 ~15 ~9 wool 0
fill ~7 ~15 ~13 ~7 ~15 ~17 wool 0
fill ~7 ~15 ~49 ~7 ~15 ~53 wool 0
fill ~7 ~15 ~63 ~7 ~16 ~63 glass 0
setblock ~7 ~15 ~64 wool 8
fill ~7 ~15 ~65 ~7 ~16 ~65 glass 0
fill ~8 ~15 ~1 ~8 ~16 ~1 wool 0
setblock ~8 ~15 ~3 wool 8
fill ~8 ~15 ~5 ~8 ~16 ~5 glass 0
fill ~8 ~15 ~6 ~8 ~16 ~6 glass 0
fill ~8 ~15 ~7 ~8 ~16 ~7 glass 0
fill ~8 ~15 ~10 ~8 ~16 ~10 glass 0
fill ~8 ~15 ~11 ~8 ~16 ~11 glass 0
fill ~8 ~15 ~12 ~8 ~16 ~12 glass 0
fill ~8 ~15 ~54 ~8 ~16 ~54 glass 0
fill ~8 ~15 ~55 ~8 ~16 ~55 glass 0
fill ~8 ~15 ~56 ~8 ~16 ~56 glass 0
fill ~8 ~15 ~57 ~8 ~15 ~58 wool 0
fill ~8 ~15 ~59 ~8 ~16 ~59 glass 0
fill ~8 ~15 ~60 ~8 ~16 ~60 glass 0
fill ~8 ~15 ~61 ~8 ~16 ~61 glass 0
setblock ~8 ~15 ~63 wool 8
fill ~8 ~15 ~65 ~8 ~16 ~65 wool 0
fill ~9 ~15 ~1 ~14 ~15 ~1 wool 15
fill ~9 ~15 ~65 ~14 ~15 ~65 wool 15
fill ~14 ~15 ~2 ~15 ~15 ~2 wool 15
fill ~14 ~15 ~64 ~15 ~15 ~64 wool 15
fill ~15 ~15 ~8 ~21 ~15 ~8 wool 15
fill ~16 ~15 ~58 ~21 ~15 ~58 wool 15
fill ~20 ~15 ~2 ~22 ~15 ~2 wool 15
fill ~20 ~15 ~3 ~20 ~15 ~6 wool 15
fill ~20 ~15 ~60 ~20 ~15 ~64 wool 15
fill ~21 ~15 ~64 ~22 ~15 ~64 wool 15
fill ~24 ~15 ~2 ~26 ~15 ~2 wool 7
fill ~24 ~15 ~64 ~26 ~15 ~64 wool 7
fill ~26 ~15 ~3 ~29 ~15 ~3 wool 7
fill ~26 ~15 ~63 ~29 ~15 ~63 wool 7
fill ~29 ~15 ~2 ~32 ~15 ~2 wool 7
fill ~29 ~15 ~64 ~32 ~15 ~64 wool 7
fill ~33 ~15 ~2 ~35 ~15 ~2 wool 15
fill ~33 ~15 ~8 ~39 ~15 ~8 wool 15
fill ~33 ~15 ~64 ~35 ~15 ~64 wool 15
fill ~35 ~15 ~3 ~35 ~15 ~6 wool 15
fill ~35 ~15 ~58 ~39 ~15 ~58 wool 15
fill ~35 ~15 ~60 ~35 ~15 ~64 wool 15
setblock ~39 ~15 ~1 wool 0
fill ~39 ~15 ~2 ~39 ~16 ~2 wool 15
fill ~39 ~15 ~3 ~39 ~16 ~3 wool 15
fill ~39 ~15 ~4 ~39 ~16 ~4 wool 15
fill ~39 ~15 ~5 ~39 ~16 ~5 wool 15
fill ~39 ~15 ~6 ~39 ~16 ~6 wool 15
fill ~39 ~15 ~7 ~39 ~16 ~7 wool 15
fill ~39 ~15 ~59 ~39 ~15 ~64 wool 15
setblock ~39 ~15 ~65 wool 0
fill ~40 ~15 ~1 ~40 ~20 ~1 wool 15
fill ~40 ~15 ~65 ~40 ~20 ~65 wool 15
fill ~42 ~15 ~1 ~80 ~15 ~1 wool 15
fill ~42 ~15 ~65 ~80 ~15 ~65 wool 15
fill ~52 ~15 ~2 ~53 ~15 ~2 wool 7
fill ~52 ~15 ~3 ~76 ~15 ~3 wool 7
fill ~52 ~15 ~4 ~53 ~15 ~4 wool 7
fill ~52 ~15 ~5 ~53 ~15 ~5 wool 7
fill ~52 ~15 ~6 ~53 ~15 ~6 wool 7
fill ~52 ~15 ~7 ~53 ~15 ~7 wool 7
fill ~52 ~15 ~8 ~53 ~15 ~8 wool 7
fill ~52 ~15 ~9 ~53 ~15 ~9 wool 7
fill ~52 ~15 ~10 ~53 ~15 ~10 wool 7
fill ~52 ~15 ~11 ~53 ~15 ~11 wool 7
fill ~52 ~15 ~12 ~53 ~15 ~12 wool 7
fill ~52 ~15 ~13 ~53 ~15 ~13 wool 7
fill ~52 ~15 ~14 ~53 ~15 ~14 wool 7
fill ~52 ~15 ~15 ~53 ~15 ~15 wool 7
fill ~52 ~15 ~16 ~53 ~15 ~16 wool 7
fill ~52 ~15 ~17 ~53 ~15 ~17 wool 7
fill ~52 ~15 ~18 ~53 ~15 ~18 wool 7
fill ~52 ~15 ~19 ~53 ~15 ~19 wool 7
fill ~52 ~15 ~20 ~53 ~15 ~20 wool 7
fill ~52 ~15 ~21 ~53 ~15 ~21 wool 7
fill ~52 ~15 ~22 ~53 ~15 ~22 wool 7
fill ~52 ~15 ~23 ~53 ~15 ~23 wool 7
fill ~52 ~15 ~24 ~53 ~15 ~24 wool 7
fill ~52 ~15 ~25 ~53 ~15 ~25 wool 7
fill ~52 ~15 ~26 ~53 ~15 ~26 wool 7
fill ~52 ~15 ~27 ~53 ~15 ~27 wool 7
fill ~52 ~15 ~28 ~53 ~15 ~28 wool 7
fill ~52 ~15 ~29 ~53 ~15 ~29 wool 7
fill ~52 ~15 ~37 ~53 ~15 ~37 wool 7
fill ~52 ~15 ~38 ~53 ~15 ~38 wool 7
fill ~52 ~15 ~39 ~53 ~15 ~39 wool 7
fill ~52 ~15 ~40 ~53 ~15 ~40 wool 7
fill ~52 ~15 ~41 ~53 ~15 ~41 wool 7
fill ~52 ~15 ~42 ~53 ~15 ~42 wool 7
fill ~52 ~15 ~43 ~53 ~15 ~43 wool 7
fill ~52 ~15 ~44 ~53 ~15 ~44 wool 7
fill ~52 ~15 ~45 ~53 ~15 ~45 wool 7
fill ~52 ~15 ~46 ~53 ~15 ~46 wool 7
fill ~52 ~15 ~47 ~53 ~15 ~47 wool 7
fill ~52 ~15 ~48 ~53 ~15 ~48 wool 7
fill ~52 ~15 ~49 ~53 ~15 ~49 wool 7
fill ~52 ~15 ~50 ~53 ~15 ~50 wool 7
fill ~52 ~15 ~51 ~53 ~15 ~51 wool 7
fill ~52 ~15 ~52 ~53 ~15 ~52 wool 7
fill ~52 ~15 ~53 ~53 ~15 ~53 wool 7
fill ~52 ~15 ~54 ~53 ~15 ~54 wool 7
fill ~52 ~15 ~55 ~53 ~15 ~55 wool 7
fill ~52 ~15 ~56 ~53 ~15 ~56 wool 7
fill ~52 ~15 ~57 ~53 ~15 ~57 wool 7
fill ~52 ~15 ~58 ~53 ~15 ~58 wool 7
fill ~52 ~15 ~59 ~53 ~15 ~59 wool 7
fill ~52 ~15 ~60 ~53 ~15 ~60 wool 7
fill ~52 ~15 ~61 ~53 ~15 ~61 wool 7
fill ~52 ~15 ~62 ~53 ~15 ~62 wool 7
fill ~52 ~15 ~63 ~76 ~15 ~63 wool 7
fill ~52 ~15 ~64 ~53 ~15 ~64 wool 7
fill ~55 ~15 ~30 ~59 ~15 ~30 wool 7
fill ~55 ~15 ~36 ~59 ~15 ~36 wool 7
setblock ~59 ~15 ~31 iron_block 0
setblock ~59 ~15 ~32 wool 7
setblock ~59 ~15 ~33 iron_block 0
setblock ~59 ~15 ~34 wool 7
setblock ~59 ~15 ~35 iron_block 0
fill ~61 ~15 ~47 ~61 ~16 ~47 wool 15
fill ~61 ~15 ~48 ~61 ~15 ~51 wool 15
fill ~66 ~15 ~37 ~66 ~17 ~37 iron_block 0
fill ~76 ~15 ~11 ~77 ~15 ~11 wool 15
fill ~76 ~15 ~12 ~77 ~15 ~12 wool 15
fill ~76 ~15 ~13 ~77 ~15 ~13 wool 15
fill ~76 ~15 ~14 ~77 ~15 ~14 wool 15
fill ~76 ~15 ~15 ~77 ~15 ~15 wool 15
fill ~76 ~15 ~16 ~77 ~15 ~16 wool 15
fill ~76 ~15 ~17 ~77 ~15 ~17 wool 15
fill ~76 ~15 ~18 ~77 ~15 ~18 wool 15
fill ~76 ~15 ~19 ~77 ~15 ~19 wool 15
fill ~76 ~15 ~20 ~77 ~15 ~20 wool 15
fill ~76 ~15 ~21 ~77 ~15 ~21 wool 15
fill ~76 ~15 ~22 ~77 ~15 ~22 wool 15
fill ~76 ~15 ~44 ~77 ~15 ~44 wool 15
fill ~76 ~15 ~45 ~77 ~15 ~45 wool 15
fill ~76 ~15 ~46 ~77 ~15 ~46 wool 15
fill ~76 ~15 ~47 ~77 ~15 ~47 wool 15
fill ~76 ~15 ~48 ~77 ~15 ~48 wool 15
fill ~76 ~15 ~49 ~77 ~15 ~49 wool 15
fill ~76 ~15 ~50 ~77 ~15 ~50 wool 15
fill ~76 ~15 ~51 ~77 ~15 ~51 wool 15
fill ~76 ~15 ~52 ~77 ~15 ~52 wool 15
fill ~76 ~15 ~53 ~77 ~15 ~53 wool 15
fill ~76 ~15 ~54 ~77 ~15 ~54 wool 15
fill ~76 ~15 ~55 ~77 ~15 ~55 wool 15
fill ~78 ~15 ~3 ~96 ~15 ~3 wool 7
fill ~78 ~15 ~63 ~96 ~15 ~63 wool 7
fill ~80 ~15 ~0 ~96 ~15 ~0 wool 15
fill ~80 ~15 ~66 ~96 ~15 ~66 wool 15
fill ~93 ~15 ~8 ~94 ~15 ~8 wool 15
fill ~93 ~15 ~9 ~94 ~15 ~9 wool 15
fill ~93 ~15 ~10 ~94 ~15 ~10 wool 15
fill ~93 ~15 ~24 ~94 ~15 ~24 wool 15
fill ~93 ~15 ~25 ~94 ~15 ~25 wool 15
fill ~93 ~15 ~26 ~94 ~15 ~26 wool 15
fill ~93 ~15 ~40 ~94 ~15 ~40 wool 15
fill ~93 ~15 ~41 ~94 ~15 ~41 wool 15
fill ~93 ~15 ~42 ~94 ~15 ~42 wool 15
fill ~93 ~15 ~56 ~94 ~15 ~56 wool 15
fill ~93 ~15 ~57 ~94 ~15 ~57 wool 15
fill ~93 ~15 ~58 ~94 ~15 ~58 wool 15
fill ~94 ~15 ~11 ~94 ~17 ~11 wool 15
fill ~94 ~15 ~12 ~94 ~17 ~12 wool 15
fill ~94 ~15 ~13 ~94 ~17 ~13 wool 15
fill ~94 ~15 ~14 ~94 ~17 ~14 wool 15
fill ~94 ~15 ~15 ~94 ~17 ~15 wool 15
fill ~94 ~15 ~16 ~94 ~17 ~16 wool 15
fill ~94 ~15 ~17 ~94 ~17 ~17 wool 15
fill ~94 ~15 ~18 ~94 ~17 ~18 wool 15
fill ~94 ~15 ~19 ~94 ~17 ~19 wool 15
fill ~94 ~15 ~20 ~94 ~17 ~20 wool 15
fill ~94 ~15 ~21 ~94 ~17 ~21 wool 15
fill ~94 ~15 ~22 ~94 ~17 ~22 wool 15
fill ~94 ~15 ~23 ~94 ~17 ~23 wool 15
fill ~94 ~15 ~27 ~94 ~17 ~27 wool 15
fill ~94 ~15 ~28 ~94 ~17 ~28 wool 15
fill ~94 ~15 ~29 ~94 ~17 ~29 wool 15
fill ~94 ~15 ~30 ~94 ~17 ~30 wool 15
fill ~94 ~15 ~31 ~94 ~17 ~31 wool 15
fill ~94 ~15 ~32 ~94 ~17 ~32 wool 15
fill ~94 ~15 ~33 ~94 ~17 ~33 wool 15
fill ~94 ~15 ~34 ~94 ~17 ~34 wool 15
fill ~94 ~15 ~35 ~94 ~17 ~35 wool 15
fill ~94 ~15 ~36 ~94 ~17 ~36 wool 15
fill ~94 ~15 ~37 ~94 ~17 ~37 wool 15
fill ~94 ~15 ~38 ~94 ~17 ~38 wool 15
fill ~94 ~15 ~39 ~94 ~17 ~39 wool 15
fill ~94 ~15 ~43 ~94 ~17 ~43 wool 15
fill ~94 ~15 ~44 ~94 ~17 ~44 wool 15
fill ~94 ~15 ~45 ~94 ~17 ~45 wool 15
fill ~94 ~15 ~46 ~94 ~17 ~46 wool 15
fill ~94 ~15 ~47 ~94 ~17 ~47 wool 15
fill ~94 ~15 ~48 ~94 ~17 ~48 wool 15
fill ~94 ~15 ~49 ~94 ~17 ~49 wool 15
fill ~94 ~15 ~50 ~94 ~17 ~50 wool 15
fill ~94 ~15 ~51 ~94 ~17 ~51 wool 15
fill ~94 ~15 ~52 ~94 ~17 ~52 wool 15
fill ~94 ~15 ~53 ~94 ~17 ~53 wool 15
fill ~94 ~15 ~54 ~94 ~17 ~54 wool 15
fill ~94 ~15 ~55 ~94 ~17 ~55 wool 15
fill ~95 ~15 ~1 ~96 ~15 ~1 wool 7
fill ~95 ~15 ~2 ~96 ~15 ~2 wool 7
fill ~95 ~15 ~4 ~96 ~15 ~4 wool 7
fill ~95 ~15 ~5 ~96 ~15 ~5 wool 7
fill ~95 ~15 ~6 ~96 ~15 ~6 wool 7
fill ~95 ~15 ~7 ~96 ~15 ~7 wool 7
fill ~95 ~15 ~8 ~96 ~15 ~8 wool 7
fill ~95 ~15 ~9 ~96 ~15 ~9 wool 7
fill ~95 ~15 ~10 ~96 ~15 ~10 wool 7
fill ~95 ~15 ~11 ~96 ~15 ~11 wool 7
fill ~95 ~15 ~12 ~96 ~15 ~12 wool 7
fill ~95 ~15 ~13 ~96 ~15 ~13 wool 7
fill ~95 ~15 ~14 ~96 ~15 ~14 wool 7
fill ~95 ~15 ~15 ~96 ~15 ~15 wool 7
fill ~95 ~15 ~16 ~96 ~15 ~16 wool 7
fill ~95 ~15 ~17 ~96 ~15 ~17 wool 7
fill ~95 ~15 ~18 ~96 ~15 ~18 wool 7
fill ~95 ~15 ~19 ~96 ~15 ~19 wool 7
fill ~95 ~15 ~20 ~96 ~15 ~20 wool 7
fill ~95 ~15 ~21 ~96 ~15 ~21 wool 7
fill ~95 ~15 ~22 ~96 ~15 ~22 wool 7
fill ~95 ~15 ~23 ~96 ~15 ~23 wool 7
fill ~95 ~15 ~24 ~96 ~15 ~24 wool 7
fill ~95 ~15 ~25 ~96 ~15 ~25 wool 7
fill ~95 ~15 ~26 ~96 ~15 ~26 wool 7
fill ~95 ~15 ~27 ~96 ~15 ~27 wool 7
fill ~95 ~15 ~28 ~96 ~15 ~28 wool 7
fill ~95 ~15 ~29 ~96 ~15 ~29 wool 7
fill ~95 ~15 ~30 ~96 ~15 ~30 wool 7
fill ~95 ~15 ~31 ~96 ~15 ~31 wool 7
fill ~95 ~15 ~32 ~96 ~15 ~32 wool 7
fill ~95 ~15 ~33 ~96 ~15 ~33 wool 7
fill ~95 ~15 ~34 ~96 ~15 ~34 wool 7
fill ~95 ~15 ~35 ~96 ~15 ~35 wool 7
fill ~95 ~15 ~36 ~96 ~15 ~36 wool 7
fill ~95 ~15 ~37 ~96 ~15 ~37 wool 7
fill ~95 ~15 ~38 ~96 ~15 ~38 wool 7
fill ~95 ~15 ~39 ~96 ~15 ~39 wool 7
fill ~95 ~15 ~40 ~96 ~15 ~40 wool 7
fill ~95 ~15 ~41 ~96 ~15 ~41 wool 7
fill ~95 ~15 ~42 ~96 ~15 ~42 wool 7
fill ~95 ~15 ~43 ~96 ~15 ~43 wool 7
fill ~95 ~15 ~44 ~96 ~15 ~44 wool 7
fill ~95 ~15 ~45 ~96 ~15 ~45 wool 7
fill ~95 ~15 ~46 ~96 ~15 ~46 wool 7
fill ~95 ~15 ~47 ~96 ~15 ~47 wool 7
fill ~95 ~15 ~48 ~96 ~15 ~48 wool 7
fill ~95 ~15 ~49 ~96 ~15 ~49 wool 7
fill ~95 ~15 ~50 ~96 ~15 ~50 wool 7
fill ~95 ~15 ~51 ~96 ~15 ~51 wool 7
fill ~95 ~15 ~52 ~96 ~15 ~52 wool 7
fill ~95 ~15 ~53 ~96 ~15 ~53 wool 7
fill ~95 ~15 ~54 ~96 ~15 ~54 wool 7
fill ~95 ~15 ~55 ~96 ~15 ~55 wool 7
fill ~95 ~15 ~56 ~96 ~15 ~56 wool 7
fill ~95 ~15 ~57 ~96 ~15 ~57 wool 7
fill ~95 ~15 ~58 ~96 ~15 ~58 wool 7
fill ~95 ~15 ~59 ~96 ~15 ~59 wool 7
fill ~95 ~15 ~60 ~96 ~15 ~60 wool 7
fill ~95 ~15 ~61 ~96 ~15 ~61 wool 7
fill ~95 ~15 ~62 ~96 ~15 ~62 wool 7
fill ~95 ~15 ~64 ~96 ~15 ~64 wool 7
fill ~95 ~15 ~65 ~96 ~15 ~65 wool 7
fill ~97 ~15 ~0 ~98 ~15 ~0 wool 0
fill ~97 ~15 ~66 ~98 ~15 ~66 wool 0
fill ~98 ~15 ~2 ~100 ~15 ~2 wool 15
fill ~98 ~15 ~3 ~98 ~15 ~7 wool 15
fill ~98 ~15 ~59 ~98 ~15 ~64 wool 15
fill ~99 ~15 ~64 ~100 ~15 ~64 wool 15
fill ~102 ~15 ~2 ~104 ~15 ~2 wool 7
fill ~102 ~15 ~64 ~104 ~15 ~64 wool 7
fill ~105 ~15 ~3 ~106 ~15 ~3 wool 7
fill ~105 ~15 ~63 ~106 ~15 ~63 wool 7
fill ~107 ~15 ~2 ~110 ~15 ~2 wool 7
fill ~107 ~15 ~64 ~110 ~15 ~64 wool 7
fill ~111 ~15 ~2 ~113 ~15 ~2 wool 15
fill ~111 ~15 ~64 ~113 ~15 ~64 wool 15
fill ~113 ~15 ~3 ~113 ~15 ~7 wool 15
fill ~113 ~15 ~9 ~116 ~15 ~9 wool 15
fill ~113 ~15 ~57 ~116 ~15 ~57 wool 15
fill ~113 ~15 ~59 ~113 ~15 ~64 wool 15
setblock ~115 ~15 ~0 wool 0
setblock ~115 ~15 ~66 wool 0
fill ~116 ~15 ~0 ~116 ~20 ~0 wool 15
fill ~116 ~15 ~1 ~116 ~15 ~9 wool 15
fill ~116 ~15 ~58 ~116 ~15 ~66 wool 15
setblock ~117 ~15 ~7 wool 15
fill ~117 ~15 ~66 ~117 ~20 ~66 wool 15
fill ~119 ~15 ~0 ~142 ~15 ~0 wool 15
fill ~119 ~15 ~66 ~142 ~15 ~66 wool 15
fill ~144 ~15 ~2 ~144 ~18 ~2 wool 15
fill ~144 ~15 ~64 ~144 ~18 ~64 wool 15
fill ~145 ~15 ~28 ~146 ~15 ~28 wool 0
fill ~145 ~15 ~38 ~146 ~15 ~38 wool 0
fill ~2 ~16 ~20 ~3 ~16 ~20 wool 0
fill ~2 ~16 ~46 ~3 ~16 ~46 wool 0
fill ~4 ~16 ~25 ~4 ~16 ~41 wool 15
fill ~5 ~16 ~21 ~5 ~16 ~24 wool 15
fill ~5 ~16 ~42 ~5 ~16 ~45 wool 15
fill ~6 ~16 ~18 ~6 ~16 ~20 wool 15
fill ~6 ~16 ~46 ~6 ~16 ~48 wool 15
setblock ~7 ~16 ~2 wool 7
setblock ~7 ~16 ~14 wool 0
fill ~7 ~16 ~15 ~7 ~16 ~17 wool 15
fill ~7 ~16 ~49 ~7 ~16 ~51 wool 15
setblock ~7 ~16 ~52 wool 0
setblock ~7 ~16 ~64 wool 7
setblock ~8 ~16 ~3 wool 7
setblock ~8 ~16 ~4 glass 0
fill ~8 ~16 ~8 ~8 ~16 ~13 glass 0
setblock ~8 ~16 ~53 glass 0
fill ~8 ~16 ~57 ~8 ~16 ~62 glass 0
setblock ~8 ~16 ~63 wool 7
fill ~9 ~16 ~1 ~15 ~16 ~1 wool 15
fill ~9 ~16 ~65 ~15 ~16 ~65 wool 15
fill ~14 ~16 ~2 ~15 ~16 ~2 wool 15
fill ~14 ~16 ~64 ~14 ~18 ~64 wool 15
fill ~15 ~16 ~8 ~22 ~16 ~8 wool 15
setblock ~16 ~16 ~1 wool 0
fill ~16 ~16 ~58 ~21 ~16 ~58 wool 15
fill ~16 ~16 ~59 ~16 ~16 ~64 wool 15
setblock ~16 ~16 ~65 wool 0
fill ~21 ~16 ~2 ~25 ~16 ~2 wool 15
fill ~21 ~16 ~3 ~21 ~16 ~6 wool 15
fill ~21 ~16 ~60 ~21 ~16 ~64 wool 15
fill ~22 ~16 ~64 ~25 ~16 ~64 wool 15
fill ~26 ~16 ~2 ~29 ~16 ~2 wool 7
fill ~26 ~16 ~64 ~29 ~16 ~64 wool 7
fill ~30 ~16 ~2 ~34 ~16 ~2 wool 15
fill ~30 ~16 ~8 ~39 ~16 ~8 wool 15
fill ~30 ~16 ~64 ~34 ~16 ~64 wool 15
fill ~34 ~16 ~3 ~34 ~16 ~6 wool 15
fill ~34 ~16 ~58 ~38 ~16 ~58 wool 15
fill ~34 ~16 ~60 ~34 ~16 ~64 wool 15
fill ~37 ~16 ~1 ~38 ~16 ~1 wool 0
fill ~37 ~16 ~59 ~38 ~16 ~59 wool 15
fill ~37 ~16 ~60 ~38 ~16 ~60 wool 15
fill ~37 ~16 ~61 ~38 ~16 ~61 wool 15
fill ~37 ~16 ~62 ~38 ~16 ~62 wool 15
fill ~37 ~16 ~63 ~38 ~16 ~63 wool 15
fill ~37 ~16 ~64 ~38 ~16 ~64 wool 15
fill ~37 ~16 ~65 ~38 ~16 ~65 wool 0
fill ~39 ~16 ~1 ~39 ~20 ~1 wool 15
fill ~39 ~16 ~65 ~39 ~20 ~65 wool 15
fill ~42 ~16 ~1 ~80 ~16 ~1 wool 15
fill ~42 ~16 ~65 ~80 ~16 ~65 wool 15
fill ~54 ~16 ~2 ~55 ~16 ~2 wool 7
fill ~54 ~16 ~3 ~76 ~16 ~3 wool 7
fill ~54 ~16 ~4 ~55 ~16 ~4 wool 7
fill ~54 ~16 ~5 ~55 ~16 ~5 wool 7
fill ~54 ~16 ~6 ~55 ~16 ~6 wool 7
fill ~54 ~16 ~7 ~55 ~16 ~7 wool 7
fill ~54 ~16 ~8 ~55 ~16 ~8 wool 7
fill ~54 ~16 ~9 ~55 ~16 ~9 wool 7
fill ~54 ~16 ~10 ~55 ~16 ~10 wool 7
fill ~54 ~16 ~11 ~55 ~16 ~11 wool 7
fill ~54 ~16 ~12 ~55 ~16 ~12 wool 7
fill ~54 ~16 ~13 ~55 ~16 ~13 wool 7
fill ~54 ~16 ~14 ~55 ~16 ~14 wool 7
fill ~54 ~16 ~15 ~55 ~16 ~15 wool 7
fill ~54 ~16 ~16 ~55 ~16 ~16 wool 7
fill ~54 ~16 ~17 ~55 ~16 ~17 wool 7
fill ~54 ~16 ~18 ~55 ~16 ~18 wool 7
fill ~54 ~16 ~19 ~55 ~16 ~19 wool 7
fill ~54 ~16 ~20 ~55 ~16 ~20 wool 7
fill ~54 ~16 ~21 ~55 ~16 ~21 wool 7
fill ~54 ~16 ~22 ~55 ~16 ~22 wool 7
fill ~54 ~16 ~23 ~55 ~16 ~23 wool 7
fill ~54 ~16 ~24 ~55 ~16 ~24 wool 7
fill ~54 ~16 ~25 ~55 ~16 ~25 wool 7
fill ~54 ~16 ~26 ~55 ~16 ~26 wool 7
fill ~54 ~16 ~27 ~55 ~16 ~27 wool 7
fill ~54 ~16 ~28 ~55 ~16 ~28 wool 7
fill ~54 ~16 ~29 ~55 ~16 ~29 wool 7
fill ~54 ~16 ~37 ~55 ~16 ~37 wool 7
fill ~54 ~16 ~38 ~55 ~16 ~38 wool 7
fill ~54 ~16 ~39 ~55 ~16 ~39 wool 7
fill ~54 ~16 ~40 ~55 ~16 ~40 wool 7
fill ~54 ~16 ~41 ~55 ~16 ~41 wool 7
fill ~54 ~16 ~42 ~55 ~16 ~42 wool 7
fill ~54 ~16 ~43 ~55 ~16 ~43 wool 7
fill ~54 ~16 ~44 ~55 ~16 ~44 wool 7
fill ~54 ~16 ~45 ~55 ~16 ~45 wool 7
fill ~54 ~16 ~46 ~55 ~16 ~46 wool 7
fill ~54 ~16 ~47 ~55 ~16 ~47 wool 7
fill ~54 ~16 ~48 ~55 ~16 ~48 wool 7
fill ~54 ~16 ~49 ~55 ~16 ~49 wool 7
fill ~54 ~16 ~50 ~55 ~16 ~50 wool 7
fill ~54 ~16 ~51 ~55 ~16 ~51 wool 7
fill ~54 ~16 ~52 ~55 ~16 ~52 wool 7
fill ~54 ~16 ~53 ~55 ~16 ~53 wool 7
fill ~54 ~16 ~54 ~55 ~16 ~54 wool 7
fill ~54 ~16 ~55 ~55 ~16 ~55 wool 7
fill ~54 ~16 ~56 ~55 ~16 ~56 wool 7
fill ~54 ~16 ~57 ~55 ~16 ~57 wool 7
fill ~54 ~16 ~58 ~55 ~16 ~58 wool 7
fill ~54 ~16 ~59 ~55 ~16 ~59 wool 7
fill ~54 ~16 ~60 ~55 ~16 ~60 wool 7
fill ~54 ~16 ~61 ~55 ~16 ~61 wool 7
fill ~54 ~16 ~62 ~55 ~16 ~62 wool 7
fill ~54 ~16 ~63 ~76 ~16 ~63 wool 7
fill ~54 ~16 ~64 ~55 ~16 ~64 wool 7
fill ~55 ~16 ~30 ~58 ~16 ~30 wool 7
fill ~55 ~16 ~36 ~58 ~16 ~36 wool 7
fill ~58 ~16 ~31 ~58 ~16 ~36 wool 7
fill ~60 ~16 ~49 ~60 ~17 ~49 iron_block 0
fill ~61 ~16 ~45 ~61 ~16 ~47 wool 15
fill ~61 ~16 ~51 ~61 ~16 ~53 wool 15
fill ~76 ~16 ~11 ~77 ~16 ~11 wool 15
fill ~76 ~16 ~12 ~77 ~16 ~12 wool 15
fill ~76 ~16 ~13 ~77 ~16 ~13 wool 15
fill ~76 ~16 ~14 ~77 ~16 ~14 wool 15
fill ~76 ~16 ~15 ~77 ~16 ~15 wool 15
fill ~76 ~16 ~16 ~77 ~16 ~16 wool 15
fill ~76 ~16 ~17 ~77 ~16 ~17 wool 15
fill ~76 ~16 ~18 ~77 ~16 ~18 wool 15
fill ~76 ~16 ~19 ~77 ~16 ~19 wool 15
fill ~76 ~16 ~20 ~77 ~16 ~20 wool 15
fill ~76 ~16 ~21 ~77 ~16 ~21 wool 15
fill ~76 ~16 ~22 ~77 ~16 ~22 wool 15
fill ~76 ~16 ~44 ~77 ~16 ~44 wool 15
fill ~76 ~16 ~45 ~77 ~16 ~45 wool 15
fill ~76 ~16 ~46 ~77 ~16 ~46 wool 15
fill ~76 ~16 ~47 ~77 ~16 ~47 wool 15
fill ~76 ~16 ~48 ~77 ~16 ~48 wool 15
fill ~76 ~16 ~49 ~77 ~16 ~49 wool 15
fill ~76 ~16 ~50 ~77 ~16 ~50 wool 15
fill ~76 ~16 ~51 ~77 ~16 ~51 wool 15
fill ~76 ~16 ~52 ~77 ~16 ~52 wool 15
fill ~76 ~16 ~53 ~77 ~16 ~53 wool 15
fill ~76 ~16 ~54 ~77 ~16 ~54 wool 15
fill ~76 ~16 ~55 ~77 ~16 ~55 wool 15
fill ~78 ~16 ~3 ~98 ~16 ~3 wool 7
fill ~78 ~16 ~63 ~98 ~16 ~63 wool 7
setblock ~79 ~16 ~2 wool 7
setblock ~79 ~16 ~64 wool 7
fill ~81 ~16 ~0 ~98 ~16 ~0 wool 15
fill ~81 ~16 ~66 ~98 ~16 ~66 wool 15
fill ~93 ~16 ~8 ~95 ~16 ~8 wool 15
fill ~93 ~16 ~9 ~95 ~16 ~9 wool 15
fill ~93 ~16 ~10 ~95 ~16 ~10 wool 15
fill ~93 ~16 ~24 ~96 ~16 ~24 wool 15
fill ~93 ~16 ~25 ~96 ~16 ~25 wool 15
fill ~93 ~16 ~26 ~96 ~16 ~26 wool 15
fill ~93 ~16 ~40 ~96 ~16 ~40 wool 15
fill ~93 ~16 ~41 ~96 ~16 ~41 wool 15
fill ~93 ~16 ~42 ~96 ~16 ~42 wool 15
fill ~93 ~16 ~56 ~95 ~16 ~56 wool 15
fill ~93 ~16 ~57 ~95 ~16 ~57 wool 15
fill ~93 ~16 ~58 ~95 ~16 ~58 wool 15
fill ~95 ~16 ~11 ~96 ~16 ~11 wool 15
fill ~95 ~16 ~12 ~96 ~16 ~12 wool 15
fill ~95 ~16 ~13 ~96 ~16 ~13 wool 15
fill ~95 ~16 ~14 ~96 ~16 ~14 wool 15
fill ~95 ~16 ~15 ~96 ~16 ~15 wool 15
fill ~95 ~16 ~16 ~96 ~16 ~16 wool 15
fill ~95 ~16 ~17 ~96 ~16 ~17 wool 15
fill ~95 ~16 ~18 ~96 ~16 ~18 wool 15
fill ~95 ~16 ~19 ~96 ~16 ~19 wool 15
fill ~95 ~16 ~20 ~96 ~16 ~20 wool 15
fill ~95 ~16 ~21 ~96 ~16 ~21 wool 15
fill ~95 ~16 ~22 ~96 ~16 ~22 wool 15
fill ~95 ~16 ~23 ~96 ~16 ~23 wool 15
fill ~95 ~16 ~27 ~96 ~16 ~27 wool 15
fill ~95 ~16 ~28 ~96 ~16 ~28 wool 15
fill ~95 ~16 ~29 ~96 ~16 ~29 wool 15
fill ~95 ~16 ~30 ~96 ~16 ~30 wool 15
fill ~95 ~16 ~31 ~96 ~16 ~31 wool 15
fill ~95 ~16 ~32 ~96 ~16 ~32 wool 15
fill ~95 ~16 ~33 ~96 ~16 ~33 wool 15
fill ~95 ~16 ~34 ~96 ~16 ~34 wool 15
fill ~95 ~16 ~35 ~96 ~16 ~35 wool 15
fill ~95 ~16 ~36 ~96 ~16 ~36 wool 15
fill ~95 ~16 ~37 ~96 ~16 ~37 wool 15
fill ~95 ~16 ~38 ~96 ~16 ~38 wool 15
fill ~95 ~16 ~39 ~96 ~16 ~39 wool 15
fill ~95 ~16 ~43 ~96 ~16 ~43 wool 15
fill ~95 ~16 ~44 ~96 ~16 ~44 wool 15
fill ~95 ~16 ~45 ~96 ~16 ~45 wool 15
fill ~95 ~16 ~46 ~96 ~16 ~46 wool 15
fill ~95 ~16 ~47 ~96 ~16 ~47 wool 15
fill ~95 ~16 ~48 ~96 ~16 ~48 wool 15
fill ~95 ~16 ~49 ~96 ~16 ~49 wool 15
fill ~95 ~16 ~50 ~96 ~16 ~50 wool 15
fill ~95 ~16 ~51 ~96 ~16 ~51 wool 15
fill ~95 ~16 ~52 ~96 ~16 ~52 wool 15
fill ~95 ~16 ~53 ~96 ~16 ~53 wool 15
fill ~95 ~16 ~54 ~96 ~16 ~54 wool 15
