setblock ~7 ~0 ~73 brown_glazed_terracotta 0
setblock ~7 ~0 ~74 dirt 1
setblock ~7 ~0 ~75 stained_hardened_clay 8
setblock ~7 ~0 ~76 dirt 1
setblock ~7 ~0 ~77 stained_hardened_clay 8
setblock ~7 ~0 ~78 mycelium 0
setblock ~8 ~0 ~68 gold_ore 0
setblock ~8 ~0 ~69 stained_hardened_clay 8
setblock ~8 ~0 ~70 gold_ore 0
fill ~8 ~0 ~71 ~8 ~0 ~72 stained_hardened_clay 8
fill ~8 ~0 ~79 ~8 ~1 ~79 brown_glazed_terracotta 0
fill ~8 ~0 ~80 ~8 ~1 ~80 brown_glazed_terracotta 0
fill ~8 ~0 ~81 ~8 ~0 ~79 brown_glazed_terracotta 0
setblock ~9 ~0 ~64 mycelium 0
setblock ~9 ~0 ~65 brown_glazed_terracotta 0
setblock ~9 ~0 ~66 mycelium 0
setblock ~9 ~0 ~67 gold_ore 0
setblock ~9 ~0 ~82 mycelium 0
setblock ~9 ~0 ~83 gold_ore 0
setblock ~10 ~0 ~60 stained_hardened_clay 8
fill ~10 ~0 ~61 ~10 ~2 ~61 brown_glazed_terracotta 0
fill ~10 ~0 ~62 ~10 ~2 ~62 stained_hardened_clay 8
setblock ~10 ~0 ~63 brown_glazed_terracotta 0
setblock ~10 ~0 ~84 stained_hardened_clay 8
setblock ~11 ~0 ~56 mycelium 0
setblock ~11 ~0 ~57 stained_hardened_clay 8
setblock ~11 ~0 ~58 dirt 1
setblock ~11 ~0 ~59 stained_hardened_clay 8
setblock ~11 ~0 ~85 gold_ore 0
setblock ~12 ~0 ~51 brown_mushroom_block 0
setblock ~12 ~0 ~52 gold_ore 0
setblock ~12 ~0 ~53 brown_glazed_terracotta 0
setblock ~12 ~0 ~54 gold_ore 0
fill ~12 ~0 ~55 ~12 ~2 ~55 brown_glazed_terracotta 0
setblock ~12 ~0 ~86 stained_hardened_clay 8
setblock ~13 ~0 ~47 stained_hardened_clay 8
setblock ~13 ~0 ~48 bookshelf 0
setblock ~13 ~0 ~49 gold_ore 0
setblock ~13 ~0 ~50 log2 0
setblock ~13 ~0 ~87 stained_hardened_clay 8
fill ~14 ~0 ~44 ~14 ~2 ~44 stained_hardened_clay 8
setblock ~14 ~0 ~45 brown_mushroom_block 0
fill ~14 ~0 ~46 ~14 ~1 ~46 stained_hardened_clay 8
setblock ~14 ~0 ~88 stained_hardened_clay 8
setblock ~15 ~0 ~38 log 3
setblock ~15 ~0 ~39 brown_glazed_terracotta 0
setblock ~15 ~0 ~40 dirt 1
setblock ~15 ~0 ~41 brown_glazed_terracotta 0
setblock ~15 ~0 ~42 log2 0
setblock ~15 ~0 ~43 brown_glazed_terracotta 0
setblock ~15 ~0 ~89 stained_hardened_clay 8
fill ~16 ~0 ~32 ~16 ~1 ~32 brown_glazed_terracotta 0
setblock ~16 ~0 ~33 mycelium 0
fill ~16 ~0 ~34 ~16 ~1 ~34 brown_glazed_terracotta 0
setblock ~16 ~0 ~35 log2 0
setblock ~16 ~0 ~36 stained_hardened_clay 8
fill ~16 ~0 ~37 ~16 ~2 ~37 log2 0
setblock ~16 ~0 ~90 gold_ore 0
setblock ~17 ~0 ~30 log2 0
setblock ~17 ~0 ~31 gold_ore 0
setblock ~17 ~0 ~91 stained_hardened_clay 8
fill ~18 ~0 ~28 ~18 ~1 ~28 stained_hardened_clay 8
setblock ~18 ~0 ~29 brown_mushroom_block 0
setblock ~18 ~0 ~92 stained_hardened_clay 8
setblock ~19 ~0 ~26 dirt 1
setblock ~19 ~0 ~27 stained_hardened_clay 8
setblock ~19 ~0 ~93 stained_hardened_clay 8
setblock ~20 ~0 ~25 brown_glazed_terracotta 0
setblock ~20 ~0 ~93 brown_glazed_terracotta 0
setblock ~21 ~0 ~24 log2 0
setblock ~21 ~0 ~94 mycelium 0
setblock ~22 ~0 ~23 mycelium 0
setblock ~22 ~0 ~95 dirt 1
setblock ~23 ~0 ~22 mycelium 0
setblock ~23 ~0 ~96 log 3
setblock ~24 ~0 ~21 stained_hardened_clay 8
fill ~24 ~0 ~97 ~24 ~2 ~97 brown_glazed_terracotta 0
setblock ~25 ~0 ~20 dirt 1
setblock ~25 ~0 ~98 dirt 1
setblock ~26 ~0 ~19 log2 0
fill ~26 ~0 ~98 ~26 ~1 ~98 stained_hardened_clay 8
setblock ~27 ~0 ~19 stained_hardened_clay 8
fill ~27 ~0 ~99 ~28 ~0 ~99 stained_hardened_clay 8
setblock ~28 ~0 ~18 gold_ore 0
setblock ~29 ~0 ~17 stained_hardened_clay 8
setblock ~29 ~0 ~100 brown_glazed_terracotta 0
setblock ~30 ~0 ~16 brown_glazed_terracotta 0
setblock ~30 ~0 ~100 gold_ore 0
setblock ~31 ~0 ~15 stained_hardened_clay 8
setblock ~31 ~0 ~100 dirt 1
fill ~32 ~0 ~14 ~32 ~1 ~14 stained_hardened_clay 8
fill ~32 ~0 ~100 ~32 ~1 ~100 stained_hardened_clay 8
setblock ~33 ~0 ~13 gold_ore 0
setblock ~33 ~0 ~100 brown_glazed_terracotta 0
setblock ~34 ~0 ~13 stained_hardened_clay 8
setblock ~34 ~0 ~100 stained_hardened_clay 8
setblock ~35 ~0 ~12 mycelium 0
setblock ~35 ~0 ~100 log2 0
fill ~36 ~0 ~11 ~36 ~1 ~11 log2 0
fill ~36 ~0 ~99 ~36 ~1 ~99 log2 0
setblock ~37 ~0 ~11 brown_glazed_terracotta 0
setblock ~37 ~0 ~99 brown_glazed_terracotta 0
setblock ~38 ~0 ~10 gold_ore 0
setblock ~38 ~0 ~99 log2 0
fill ~39 ~0 ~10 ~39 ~3 ~10 log2 0
setblock ~39 ~0 ~99 stained_hardened_clay 8
setblock ~40 ~0 ~9 brown_mushroom_block 0
setblock ~40 ~0 ~99 log2 0
setblock ~41 ~0 ~9 stained_hardened_clay 8
setblock ~41 ~0 ~99 stained_hardened_clay 8
setblock ~42 ~0 ~8 gold_ore 0
setblock ~42 ~0 ~99 brown_glazed_terracotta 0
setblock ~43 ~0 ~8 dirt 1
setblock ~43 ~0 ~100 mycelium 0
setblock ~44 ~0 ~7 log2 0
setblock ~44 ~0 ~100 stained_hardened_clay 8
setblock ~45 ~0 ~7 stained_hardened_clay 8
setblock ~45 ~0 ~100 log2 0
setblock ~46 ~0 ~6 brown_glazed_terracotta 0
setblock ~46 ~0 ~101 brown_glazed_terracotta 0
fill ~47 ~0 ~6 ~47 ~1 ~6 log2 0
setblock ~47 ~0 ~101 stained_hardened_clay 8
setblock ~48 ~0 ~6 gold_ore 0
setblock ~48 ~0 ~101 brown_glazed_terracotta 0
setblock ~49 ~0 ~5 stained_hardened_clay 8
setblock ~49 ~0 ~101 brown_mushroom_block 0
setblock ~50 ~0 ~5 brown_glazed_terracotta 0
fill ~50 ~0 ~102 ~50 ~3 ~102 stained_hardened_clay 8
setblock ~51 ~0 ~5 mycelium 0
setblock ~51 ~0 ~102 planks 1
setblock ~52 ~0 ~4 log2 0
setblock ~52 ~0 ~102 brown_glazed_terracotta 0
fill ~53 ~0 ~4 ~53 ~1 ~4 mycelium 0
setblock ~53 ~0 ~102 dirt 1
setblock ~54 ~0 ~4 brown_glazed_terracotta 0
setblock ~54 ~0 ~102 log2 0
fill ~55 ~0 ~3 ~56 ~0 ~3 log2 0
setblock ~55 ~0 ~103 brown_glazed_terracotta 0
fill ~56 ~0 ~103 ~58 ~0 ~103 log2 0
setblock ~57 ~0 ~3 brown_glazed_terracotta 0
fill ~58 ~0 ~3 ~58 ~1 ~3 log2 0
setblock ~59 ~0 ~2 dirt 1
fill ~59 ~0 ~103 ~62 ~0 ~103 brown_glazed_terracotta 0
setblock ~60 ~0 ~2 gold_ore 0
setblock ~61 ~0 ~2 mycelium 0
setblock ~62 ~0 ~2 gold_ore 0
setblock ~63 ~0 ~2 brown_glazed_terracotta 0
setblock ~63 ~0 ~103 stained_hardened_clay 8
setblock ~64 ~0 ~2 stained_hardened_clay 8
setblock ~64 ~0 ~103 brown_glazed_terracotta 0
setblock ~65 ~0 ~1 stained_hardened_clay 8
setblock ~65 ~0 ~103 stained_hardened_clay 8
fill ~66 ~0 ~1 ~67 ~0 ~1 gold_ore 0
fill ~66 ~0 ~104 ~66 ~1 ~104 gold_ore 0
setblock ~67 ~0 ~104 log2 0
fill ~68 ~0 ~1 ~71 ~0 ~1 stained_hardened_clay 8
setblock ~68 ~0 ~104 gold_ore 0
setblock ~69 ~0 ~104 log2 0
setblock ~70 ~0 ~104 stained_hardened_clay 8
setblock ~71 ~0 ~104 log2 0
fill ~72 ~0 ~1 ~72 ~1 ~1 log2 0
setblock ~72 ~0 ~104 stained_hardened_clay 8
fill ~73 ~0 ~1 ~77 ~0 ~1 brown_glazed_terracotta 0
setblock ~73 ~0 ~104 brown_glazed_terracotta 0
setblock ~74 ~0 ~104 gold_ore 0
setblock ~75 ~0 ~104 mycelium 0
setblock ~76 ~0 ~104 gold_ore 0
setblock ~77 ~0 ~104 log2 0
setblock ~78 ~0 ~1 stained_hardened_clay 8
setblock ~78 ~0 ~104 gold_ore 0
setblock ~79 ~0 ~1 brown_mushroom_block 0
setblock ~79 ~0 ~104 log2 0
setblock ~80 ~0 ~1 brown_glazed_terracotta 0
setblock ~80 ~0 ~104 gold_ore 0
setblock ~81 ~0 ~1 stained_hardened_clay 8
setblock ~81 ~0 ~104 mycelium 0
fill ~82 ~0 ~1 ~82 ~1 ~1 brown_glazed_terracotta 0
setblock ~82 ~0 ~104 gold_ore 0
setblock ~83 ~0 ~1 stained_hardened_clay 8
fill ~83 ~0 ~104 ~83 ~1 ~104 log2 0
setblock ~84 ~0 ~1 brown_glazed_terracotta 0
setblock ~84 ~0 ~104 gold_ore 0
setblock ~85 ~0 ~1 gold_ore 0
setblock ~85 ~0 ~104 mycelium 0
setblock ~86 ~0 ~2 gold_ore 0
fill ~86 ~0 ~104 ~86 ~1 ~104 stained_hardened_clay 8
setblock ~87 ~0 ~2 log2 0
setblock ~87 ~0 ~104 log2 0
setblock ~88 ~0 ~2 stained_hardened_clay 8
setblock ~88 ~0 ~104 gold_ore 0
setblock ~89 ~0 ~2 mycelium 0
setblock ~89 ~0 ~104 log2 0
fill ~90 ~0 ~3 ~92 ~0 ~3 brown_glazed_terracotta 0
fill ~90 ~0 ~105 ~92 ~0 ~105 brown_glazed_terracotta 0
setblock ~93 ~0 ~4 mycelium 0
setblock ~93 ~0 ~105 stained_hardened_clay 8
fill ~94 ~0 ~4 ~94 ~1 ~4 brown_glazed_terracotta 0
fill ~94 ~0 ~105 ~95 ~0 ~105 brown_glazed_terracotta 0
setblock ~95 ~0 ~4 planks 1
fill ~96 ~0 ~5 ~97 ~0 ~5 log2 0
setblock ~96 ~0 ~105 log2 0
setblock ~97 ~0 ~105 brown_glazed_terracotta 0
fill ~98 ~0 ~5 ~98 ~1 ~5 mycelium 0
fill ~98 ~0 ~105 ~98 ~1 ~105 log2 0
setblock ~99 ~0 ~6 mycelium 0
setblock ~99 ~0 ~105 brown_glazed_terracotta 0
setblock ~100 ~0 ~6 log2 0
fill ~100 ~0 ~104 ~101 ~0 ~104 brown_glazed_terracotta 0
setblock ~101 ~0 ~6 brown_glazed_terracotta 0
setblock ~102 ~0 ~6 gold_ore 0
setblock ~102 ~0 ~103 brown_glazed_terracotta 0
setblock ~103 ~0 ~7 brown_mushroom_block 0
fill ~103 ~0 ~102 ~103 ~1 ~102 dirt 1
setblock ~104 ~0 ~7 stained_hardened_clay 8
setblock ~104 ~0 ~101 brown_glazed_terracotta 0
setblock ~105 ~0 ~7 brown_mushroom_block 0
setblock ~105 ~0 ~100 dirt 1
setblock ~106 ~0 ~7 stained_hardened_clay 8
fill ~106 ~0 ~99 ~106 ~3 ~99 brown_glazed_terracotta 0
setblock ~107 ~0 ~8 log2 0
setblock ~107 ~0 ~97 gold_ore 0
setblock ~107 ~0 ~98 log2 0
setblock ~108 ~0 ~8 stained_hardened_clay 8
setblock ~108 ~0 ~96 stained_hardened_clay 8
fill ~109 ~0 ~8 ~109 ~1 ~8 brown_mushroom_block 0
setblock ~109 ~0 ~95 log2 0
setblock ~110 ~0 ~9 stained_hardened_clay 8
setblock ~110 ~0 ~94 stained_hardened_clay 8
setblock ~111 ~0 ~9 brown_mushroom_block 0
setblock ~111 ~0 ~93 brown_mushroom_block 0
fill ~112 ~0 ~10 ~112 ~1 ~10 stained_hardened_clay 8
fill ~112 ~0 ~93 ~112 ~3 ~93 brown_glazed_terracotta 0
fill ~113 ~0 ~10 ~113 ~1 ~10 brown_glazed_terracotta 0
setblock ~113 ~0 ~92 log2 0
setblock ~114 ~0 ~11 brown_glazed_terracotta 0
fill ~114 ~0 ~92 ~114 ~1 ~92 brown_glazed_terracotta 0
setblock ~115 ~0 ~12 dirt 1
setblock ~115 ~0 ~92 dirt 1
fill ~116 ~0 ~12 ~116 ~0 ~13 brown_glazed_terracotta 0
setblock ~116 ~0 ~91 brown_glazed_terracotta 0
setblock ~117 ~0 ~14 dirt 1
setblock ~117 ~0 ~91 stained_hardened_clay 8
setblock ~118 ~0 ~15 brown_mushroom_block 0
setblock ~118 ~0 ~16 stained_hardened_clay 8
fill ~118 ~0 ~91 ~118 ~2 ~91 brown_glazed_terracotta 0
setblock ~119 ~0 ~17 stained_hardened_clay 8
setblock ~119 ~0 ~18 log2 0
setblock ~119 ~0 ~91 brown_mushroom_block 0
setblock ~120 ~0 ~19 brown_glazed_terracotta 0
setblock ~120 ~0 ~20 stained_hardened_clay 8
setblock ~120 ~0 ~21 brown_glazed_terracotta 0
fill ~120 ~0 ~91 ~120 ~2 ~91 brown_glazed_terracotta 0
setblock ~121 ~0 ~22 dirt 1
setblock ~121 ~0 ~23 stained_hardened_clay 8
setblock ~121 ~0 ~24 log2 0
setblock ~121 ~0 ~91 brown_mushroom_block 0
setblock ~122 ~0 ~25 brown_glazed_terracotta 0
setblock ~122 ~0 ~26 stained_hardened_clay 8
setblock ~122 ~0 ~27 brown_glazed_terracotta 0
setblock ~122 ~0 ~91 stained_hardened_clay 8
setblock ~123 ~0 ~28 mycelium 0
setblock ~123 ~0 ~29 stained_hardened_clay 8
fill ~123 ~0 ~91 ~124 ~0 ~91 brown_glazed_terracotta 0
setblock ~124 ~0 ~30 stained_hardened_clay 8
fill ~124 ~0 ~31 ~124 ~1 ~31 brown_glazed_terracotta 0
setblock ~125 ~0 ~32 log2 0
setblock ~125 ~0 ~91 brown_mushroom_block 0
setblock ~126 ~0 ~33 mycelium 0
setblock ~126 ~0 ~34 brown_glazed_terracotta 0
setblock ~126 ~0 ~90 brown_mushroom_block 0
setblock ~127 ~0 ~35 stained_hardened_clay 8
fill ~127 ~0 ~36 ~127 ~1 ~36 mycelium 0
setblock ~127 ~0 ~89 log2 0
fill ~128 ~0 ~37 ~128 ~0 ~38 brown_glazed_terracotta 0
fill ~128 ~0 ~39 ~128 ~1 ~39 log2 0
fill ~128 ~0 ~88 ~128 ~1 ~88 brown_glazed_terracotta 0
setblock ~129 ~0 ~40 dirt 1
setblock ~129 ~0 ~41 stained_hardened_clay 8
setblock ~129 ~0 ~86 planks 1
setblock ~129 ~0 ~87 brown_glazed_terracotta 0
setblock ~129 ~0 ~88 dirt 1
setblock ~130 ~0 ~42 stained_hardened_clay 8
setblock ~130 ~0 ~43 brown_glazed_terracotta 0
fill ~130 ~0 ~44 ~130 ~2 ~44 stained_hardened_clay 8
fill ~130 ~0 ~45 ~130 ~1 ~45 brown_glazed_terracotta 0
setblock ~130 ~0 ~84 stained_hardened_clay 8
setblock ~130 ~0 ~85 brown_glazed_terracotta 0
setblock ~131 ~0 ~46 bookshelf 0
setblock ~131 ~0 ~47 gold_ore 0
setblock ~131 ~0 ~48 brown_glazed_terracotta 0
setblock ~131 ~0 ~77 brown_glazed_terracotta 0
setblock ~131 ~0 ~78 dirt 1
setblock ~131 ~0 ~79 stained_hardened_clay 8
setblock ~131 ~0 ~80 dirt 1
setblock ~131 ~0 ~81 brown_glazed_terracotta 0
setblock ~131 ~0 ~82 planks 1
setblock ~131 ~0 ~83 gold_ore 0
setblock ~132 ~0 ~49 brown_glazed_terracotta 0
fill ~132 ~0 ~50 ~132 ~1 ~50 gold_ore 0
setblock ~132 ~0 ~51 brown_mushroom_block 0
fill ~132 ~0 ~52 ~132 ~2 ~52 gold_ore 0
fill ~132 ~0 ~53 ~132 ~3 ~53 brown_glazed_terracotta 0
fill ~132 ~0 ~67 ~132 ~1 ~67 brown_glazed_terracotta 0
setblock ~132 ~0 ~68 gold_ore 0
setblock ~132 ~0 ~69 brown_glazed_terracotta 0
setblock ~132 ~0 ~70 stained_hardened_clay 8
fill ~132 ~0 ~71 ~132 ~0 ~72 brown_glazed_terracotta 0
setblock ~132 ~0 ~73 log2 0
fill ~132 ~0 ~74 ~132 ~1 ~74 stained_hardened_clay 8
setblock ~132 ~0 ~75 brown_glazed_terracotta 0
setblock ~132 ~0 ~76 gold_ore 0
setblock ~133 ~0 ~54 bookshelf 0
setblock ~133 ~0 ~55 stained_hardened_clay 8
setblock ~133 ~0 ~56 mycelium 0
setblock ~133 ~0 ~57 brown_glazed_terracotta 0
setblock ~133 ~0 ~58 mycelium 0
setblock ~133 ~0 ~59 gold_ore 0
setblock ~133 ~0 ~60 mycelium 0
setblock ~133 ~0 ~61 gold_ore 0
setblock ~133 ~0 ~62 log2 0
setblock ~133 ~0 ~63 brown_mushroom_block 0
setblock ~133 ~0 ~64 dirt 1
setblock ~133 ~0 ~65 stained_hardened_clay 8
setblock ~133 ~0 ~66 dirt 1
setblock ~7 ~1 ~73 dirt 1
setblock ~7 ~1 ~74 brown_glazed_terracotta 0
setblock ~7 ~1 ~75 log 3
fill ~7 ~1 ~76 ~7 ~1 ~77 mycelium 0
setblock ~7 ~1 ~78 log2 0
setblock ~8 ~1 ~68 brown_mushroom_block 0
fill ~8 ~1 ~69 ~8 ~2 ~69 brown_glazed_terracotta 0
fill ~8 ~1 ~70 ~8 ~1 ~69 brown_glazed_terracotta 0
setblock ~8 ~1 ~71 log2 0
fill ~8 ~1 ~72 ~8 ~3 ~72 stained_hardened_clay 8
setblock ~8 ~1 ~81 mycelium 0
setblock ~9 ~1 ~64 log2 0
setblock ~9 ~1 ~65 dirt 1
fill ~9 ~1 ~66 ~9 ~2 ~66 log2 0
fill ~9 ~1 ~67 ~9 ~1 ~66 log2 0
setblock ~9 ~1 ~82 brown_glazed_terracotta 0
setblock ~9 ~1 ~83 bookshelf 0
setblock ~10 ~1 ~60 brown_glazed_terracotta 0
setblock ~10 ~1 ~63 log2 0
setblock ~10 ~1 ~84 brown_glazed_terracotta 0
setblock ~11 ~1 ~56 brown_glazed_terracotta 0
setblock ~11 ~1 ~57 dirt 1
fill ~11 ~1 ~58 ~11 ~2 ~58 log2 0
setblock ~11 ~1 ~59 dirt 1
setblock ~11 ~1 ~85 log 3
fill ~12 ~1 ~52 ~12 ~2 ~52 stained_hardened_clay 8
setblock ~12 ~1 ~53 log2 0
setblock ~12 ~1 ~54 stained_hardened_clay 8
setblock ~12 ~1 ~86 log2 0
setblock ~13 ~1 ~48 brown_glazed_terracotta 0
setblock ~13 ~1 ~49 mycelium 0
setblock ~13 ~1 ~50 brown_glazed_terracotta 0
setblock ~13 ~1 ~51 mycelium 0
setblock ~13 ~1 ~87 mycelium 0
setblock ~14 ~1 ~45 brown_glazed_terracotta 0
fill ~14 ~1 ~47 ~14 ~3 ~47 brown_glazed_terracotta 0
fill ~14 ~1 ~88 ~14 ~3 ~88 brown_glazed_terracotta 0
setblock ~15 ~1 ~38 dirt 1
setblock ~15 ~1 ~39 log 3
setblock ~15 ~1 ~40 log2 0
setblock ~15 ~1 ~41 dirt 1
setblock ~15 ~1 ~42 brown_glazed_terracotta 0
setblock ~15 ~1 ~43 mycelium 0
setblock ~15 ~1 ~89 soul_sand 0
setblock ~16 ~1 ~33 log2 0
setblock ~16 ~1 ~35 soul_sand 0
setblock ~16 ~1 ~36 brown_glazed_terracotta 0
setblock ~16 ~1 ~90 brown_glazed_terracotta 0
setblock ~17 ~1 ~30 brown_glazed_terracotta 0
setblock ~17 ~1 ~31 planks 1
setblock ~17 ~1 ~91 mycelium 0
setblock ~18 ~1 ~29 log2 0
setblock ~18 ~1 ~92 brown_glazed_terracotta 0
setblock ~19 ~1 ~27 log2 0
setblock ~19 ~1 ~93 dirt 1
setblock ~20 ~1 ~26 stained_hardened_clay 8
setblock ~20 ~1 ~93 log2 0
setblock ~21 ~1 ~24 mycelium 0
setblock ~21 ~1 ~25 log 3
setblock ~21 ~1 ~94 dirt 1
setblock ~22 ~1 ~23 log2 0
setblock ~22 ~1 ~95 log2 0
setblock ~23 ~1 ~22 brown_glazed_terracotta 0
fill ~23 ~1 ~96 ~23 ~2 ~96 log2 0
setblock ~24 ~1 ~21 dirt 1
setblock ~25 ~1 ~21 log 3
setblock ~25 ~1 ~97 planks 1
setblock ~26 ~1 ~20 brown_glazed_terracotta 0
setblock ~27 ~1 ~19 log2 0
setblock ~27 ~1 ~99 log2 0
setblock ~28 ~1 ~18 stained_hardened_clay 8
setblock ~28 ~1 ~99 brown_glazed_terracotta 0
setblock ~29 ~1 ~17 dirt 1
fill ~29 ~1 ~100 ~29 ~2 ~100 log2 0
setblock ~30 ~1 ~16 brown_mushroom_block 0
fill ~30 ~1 ~100 ~30 ~4 ~100 stained_hardened_clay 8
setblock ~31 ~1 ~15 bookshelf 0
setblock ~31 ~1 ~100 log2 0
fill ~33 ~1 ~14 ~33 ~2 ~14 brown_glazed_terracotta 0
fill ~33 ~1 ~100 ~33 ~3 ~100 log2 0
setblock ~34 ~1 ~13 brown_glazed_terracotta 0
setblock ~34 ~1 ~100 gold_ore 0
setblock ~35 ~1 ~12 log2 0
setblock ~35 ~1 ~100 brown_glazed_terracotta 0
setblock ~37 ~1 ~11 planks 1
setblock ~37 ~1 ~99 soul_sand 0
setblock ~38 ~1 ~10 brown_glazed_terracotta 0
setblock ~38 ~1 ~99 mycelium 0
setblock ~39 ~1 ~99 dirt 1
setblock ~40 ~1 ~9 mycelium 0
fill ~40 ~1 ~99 ~40 ~3 ~99 brown_glazed_terracotta 0
setblock ~41 ~1 ~9 log2 0
setblock ~41 ~1 ~99 dirt 1
setblock ~42 ~1 ~8 stained_hardened_clay 8
fill ~42 ~1 ~99 ~42 ~3 ~99 log2 0
fill ~43 ~1 ~8 ~43 ~2 ~8 log2 0
setblock ~43 ~1 ~100 brown_glazed_terracotta 0
setblock ~44 ~1 ~7 mycelium 0
setblock ~44 ~1 ~100 brown_mushroom_block 0
setblock ~45 ~1 ~7 planks 1
setblock ~45 ~1 ~100 brown_glazed_terracotta 0
setblock ~46 ~1 ~6 stained_hardened_clay 8
fill ~46 ~1 ~101 ~48 ~1 ~101 log2 0
setblock ~48 ~1 ~6 brown_glazed_terracotta 0
setblock ~49 ~1 ~5 mycelium 0
setblock ~49 ~1 ~102 brown_glazed_terracotta 0
setblock ~50 ~1 ~5 log2 0
setblock ~51 ~1 ~5 log 3
fill ~51 ~1 ~102 ~52 ~1 ~102 log2 0
setblock ~52 ~1 ~4 brown_glazed_terracotta 0
setblock ~53 ~1 ~102 mycelium 0
setblock ~54 ~1 ~4 log2 0
setblock ~54 ~1 ~103 log2 0
setblock ~55 ~1 ~4 brown_glazed_terracotta 0
setblock ~55 ~1 ~103 dirt 1
fill ~56 ~1 ~3 ~57 ~1 ~3 dirt 1
setblock ~56 ~1 ~103 planks 1
setblock ~57 ~1 ~103 dirt 1
fill ~58 ~1 ~103 ~60 ~1 ~103 log2 0
setblock ~59 ~1 ~3 dirt 1
setblock ~60 ~1 ~2 stained_hardened_clay 8
setblock ~61 ~1 ~2 log2 0
setblock ~61 ~1 ~103 dirt 1
setblock ~62 ~1 ~2 stained_hardened_clay 8
fill ~62 ~1 ~103 ~62 ~2 ~103 log2 0
setblock ~63 ~1 ~2 brown_mushroom_block 0
setblock ~63 ~1 ~104 brown_glazed_terracotta 0
fill ~64 ~1 ~2 ~64 ~2 ~2 gold_ore 0
setblock ~64 ~1 ~104 brown_mushroom_block 0
setblock ~65 ~1 ~2 brown_mushroom_block 0
setblock ~65 ~1 ~104 stained_hardened_clay 8
setblock ~66 ~1 ~1 brown_glazed_terracotta 0
setblock ~67 ~1 ~1 log2 0
setblock ~67 ~1 ~104 brown_glazed_terracotta 0
setblock ~68 ~1 ~1 brown_glazed_terracotta 0
fill ~68 ~1 ~105 ~69 ~1 ~105 log2 0
fill ~69 ~1 ~1 ~70 ~1 ~1 log2 0
setblock ~70 ~1 ~105 brown_glazed_terracotta 0
setblock ~71 ~1 ~1 dirt 1
setblock ~71 ~1 ~105 mycelium 0
setblock ~72 ~1 ~105 brown_glazed_terracotta 0
setblock ~73 ~1 ~1 dirt 1
setblock ~73 ~1 ~105 mycelium 0
setblock ~74 ~1 ~1 mycelium 0
setblock ~74 ~1 ~105 brown_glazed_terracotta 0
setblock ~75 ~1 ~1 dirt 1
setblock ~75 ~1 ~105 planks 1
fill ~76 ~1 ~1 ~77 ~1 ~1 log2 0
fill ~76 ~1 ~105 ~76 ~2 ~105 brown_glazed_terracotta 0
setblock ~77 ~1 ~105 log2 0
fill ~78 ~1 ~1 ~78 ~2 ~1 brown_glazed_terracotta 0
setblock ~78 ~1 ~105 brown_glazed_terracotta 0
fill ~79 ~1 ~1 ~80 ~1 ~1 log2 0
setblock ~79 ~1 ~104 stained_hardened_clay 8
setblock ~80 ~1 ~104 brown_glazed_terracotta 0
setblock ~81 ~1 ~1 mycelium 0
fill ~81 ~1 ~104 ~81 ~3 ~104 log2 0
setblock ~82 ~1 ~104 brown_glazed_terracotta 0
fill ~83 ~1 ~1 ~84 ~1 ~1 log2 0
setblock ~84 ~1 ~104 stained_hardened_clay 8
setblock ~85 ~1 ~2 stained_hardened_clay 8
setblock ~85 ~1 ~104 brown_glazed_terracotta 0
setblock ~86 ~1 ~2 brown_mushroom_block 0
fill ~87 ~1 ~2 ~88 ~1 ~2 brown_glazed_terracotta 0
setblock ~87 ~1 ~104 brown_glazed_terracotta 0
fill ~88 ~1 ~104 ~88 ~2 ~104 stained_hardened_clay 8
setblock ~89 ~1 ~3 mycelium 0
setblock ~89 ~1 ~104 brown_glazed_terracotta 0
fill ~90 ~1 ~3 ~90 ~0 ~3 brown_glazed_terracotta 0
fill ~90 ~1 ~105 ~91 ~1 ~105 log2 0
fill ~91 ~1 ~3 ~92 ~1 ~3 mycelium 0
setblock ~92 ~1 ~105 mycelium 0
setblock ~93 ~1 ~4 log2 0
setblock ~93 ~1 ~105 log 3
fill ~94 ~1 ~105 ~96 ~1 ~105 dirt 1
setblock ~95 ~1 ~4 dirt 1
setblock ~96 ~1 ~5 dirt 1
setblock ~97 ~1 ~5 planks 1
setblock ~97 ~1 ~105 log2 0
setblock ~99 ~1 ~6 dirt 1
setblock ~99 ~1 ~105 dirt 1
setblock ~100 ~1 ~6 brown_glazed_terracotta 0
setblock ~100 ~1 ~104 log2 0
setblock ~101 ~1 ~6 stained_hardened_clay 8
setblock ~101 ~1 ~104 brown_glazed_terracotta 0
setblock ~102 ~1 ~7 log 3
setblock ~102 ~1 ~103 dirt 1
setblock ~103 ~1 ~7 mycelium 0
setblock ~104 ~1 ~7 log2 0
setblock ~104 ~1 ~101 dirt 1
setblock ~105 ~1 ~7 bookshelf 0
setblock ~105 ~1 ~100 stained_hardened_clay 8
setblock ~106 ~1 ~8 brown_mushroom_block 0
setblock ~107 ~1 ~8 bookshelf 0
setblock ~107 ~1 ~97 log2 0
setblock ~107 ~1 ~98 brown_mushroom_block 0
setblock ~108 ~1 ~8 brown_mushroom_block 0
setblock ~108 ~1 ~96 brown_glazed_terracotta 0
setblock ~109 ~1 ~95 dirt 1
fill ~110 ~1 ~9 ~110 ~2 ~9 brown_glazed_terracotta 0
setblock ~110 ~1 ~94 brown_glazed_terracotta 0
setblock ~111 ~1 ~9 log 0
setblock ~111 ~1 ~93 log2 0
setblock ~113 ~1 ~92 brown_glazed_terracotta 0
setblock ~114 ~1 ~11 mycelium 0
fill ~115 ~1 ~12 ~115 ~2 ~12 log2 0
setblock ~115 ~1 ~92 mycelium 0
setblock ~116 ~1 ~13 log2 0
setblock ~116 ~1 ~91 planks 1
setblock ~117 ~1 ~14 brown_glazed_terracotta 0
setblock ~117 ~1 ~91 log2 0
setblock ~118 ~1 ~15 brown_glazed_terracotta 0
setblock ~118 ~1 ~16 brown_mushroom_block 0
setblock ~119 ~1 ~17 dirt 1
setblock ~119 ~1 ~18 brown_glazed_terracotta 0
setblock ~119 ~1 ~19 planks 1
setblock ~119 ~1 ~91 dirt 1
setblock ~120 ~1 ~20 brown_glazed_terracotta 0
setblock ~120 ~1 ~21 dirt 1
setblock ~120 ~1 ~22 log2 0
setblock ~121 ~1 ~23 mycelium 0
setblock ~121 ~1 ~24 brown_mushroom_block 0
setblock ~121 ~1 ~25 dirt 1
fill ~121 ~1 ~91 ~123 ~1 ~91 log2 0
setblock ~122 ~1 ~26 brown_glazed_terracotta 0
setblock ~122 ~1 ~27 log2 0
setblock ~123 ~1 ~28 brown_glazed_terracotta 0
setblock ~123 ~1 ~29 bookshelf 0
setblock ~124 ~1 ~30 brown_glazed_terracotta 0
fill ~124 ~1 ~91 ~124 ~3 ~91 brown_glazed_terracotta 0
setblock ~125 ~1 ~32 brown_glazed_terracotta 0
setblock ~125 ~1 ~33 dirt 1
setblock ~125 ~1 ~91 log2 0
setblock ~126 ~1 ~34 brown_mushroom_block 0
setblock ~126 ~1 ~35 log2 0
fill ~126 ~1 ~90 ~126 ~2 ~90 stained_hardened_clay 8
setblock ~127 ~1 ~37 planks 1
setblock ~127 ~1 ~89 log 3
setblock ~128 ~1 ~38 log2 0
setblock ~129 ~1 ~40 brown_glazed_terracotta 0
setblock ~129 ~1 ~41 dirt 1
setblock ~129 ~1 ~42 brown_glazed_terracotta 0
setblock ~129 ~1 ~86 brown_glazed_terracotta 0
setblock ~129 ~1 ~87 planks 1
setblock ~130 ~1 ~43 log2 0
setblock ~130 ~1 ~84 brown_glazed_terracotta 0
setblock ~130 ~1 ~85 dirt 1
setblock ~131 ~1 ~46 brown_glazed_terracotta 0
setblock ~131 ~1 ~47 log2 0
setblock ~131 ~1 ~48 brown_mushroom_block 0
setblock ~131 ~1 ~49 dirt 1
setblock ~131 ~1 ~75 dirt 1
setblock ~131 ~1 ~76 mycelium 0
setblock ~131 ~1 ~77 dirt 1
fill ~131 ~1 ~78 ~131 ~2 ~78 log2 0
setblock ~131 ~1 ~79 dirt 1
fill ~131 ~1 ~80 ~131 ~2 ~80 log2 0
setblock ~131 ~1 ~81 log 3
setblock ~131 ~1 ~82 mycelium 0
setblock ~131 ~1 ~83 log2 0
setblock ~132 ~1 ~51 log2 0
setblock ~132 ~1 ~54 brown_glazed_terracotta 0
setblock ~132 ~1 ~66 brown_mushroom_block 0
setblock ~132 ~1 ~68 stained_hardened_clay 8
setblock ~132 ~1 ~69 log2 0
setblock ~132 ~1 ~70 brown_glazed_terracotta 0
setblock ~132 ~1 ~71 dirt 1
setblock ~132 ~1 ~72 log2 0
setblock ~132 ~1 ~73 mycelium 0
fill ~133 ~1 ~55 ~133 ~1 ~60 log2 0
setblock ~133 ~1 ~61 planks 1
setblock ~133 ~1 ~62 brown_glazed_terracotta 0
setblock ~133 ~1 ~63 planks 1
setblock ~133 ~1 ~64 stained_hardened_clay 8
setblock ~133 ~1 ~65 mycelium 0
setblock ~7 ~2 ~74 dirt 1
setblock ~7 ~2 ~75 brown_mushroom_block 0
setblock ~7 ~2 ~76 dirt 1
setblock ~7 ~2 ~77 stained_hardened_clay 8
setblock ~7 ~2 ~78 mycelium 0
setblock ~8 ~2 ~70 gold_ore 0
setblock ~8 ~2 ~71 brown_glazed_terracotta 0
setblock ~8 ~2 ~73 log2 0
setblock ~8 ~2 ~79 brown_mushroom_block 0
setblock ~8 ~2 ~80 gold_ore 0
setblock ~8 ~2 ~81 stained_hardened_clay 8
setblock ~9 ~2 ~65 brown_glazed_terracotta 0
fill ~9 ~2 ~67 ~9 ~2 ~68 stained_hardened_clay 8
fill ~9 ~2 ~82 ~9 ~3 ~82 log2 0
setblock ~9 ~2 ~83 stained_hardened_clay 8
setblock ~10 ~2 ~63 mycelium 0
fill ~10 ~2 ~64 ~10 ~3 ~64 brown_glazed_terracotta 0
fill ~10 ~2 ~84 ~10 ~3 ~84 stained_hardened_clay 8
setblock ~11 ~2 ~56 log2 0
setblock ~11 ~2 ~57 brown_glazed_terracotta 0
setblock ~11 ~2 ~59 stained_hardened_clay 8
setblock ~11 ~2 ~60 log2 0
setblock ~11 ~2 ~85 brown_glazed_terracotta 0
fill ~12 ~2 ~53 ~12 ~3 ~53 brown_glazed_terracotta 0
setblock ~12 ~2 ~54 gold_ore 0
setblock ~12 ~2 ~86 stained_hardened_clay 8
setblock ~13 ~2 ~48 log2 0
setblock ~13 ~2 ~49 gold_ore 0
setblock ~13 ~2 ~50 log2 0
setblock ~13 ~2 ~51 stained_hardened_clay 8
setblock ~13 ~2 ~87 gold_ore 0
setblock ~14 ~2 ~45 stained_hardened_clay 8
setblock ~14 ~2 ~46 gold_ore 0
setblock ~15 ~2 ~40 brown_glazed_terracotta 0
setblock ~15 ~2 ~41 stained_hardened_clay 8
setblock ~15 ~2 ~42 log2 0
setblock ~15 ~2 ~43 stained_hardened_clay 8
setblock ~15 ~2 ~89 gold_ore 0
setblock ~16 ~2 ~33 brown_glazed_terracotta 0
setblock ~16 ~2 ~34 gold_ore 0
setblock ~16 ~2 ~35 brown_glazed_terracotta 0
fill ~16 ~2 ~36 ~16 ~3 ~36 stained_hardened_clay 8
setblock ~16 ~2 ~38 brown_glazed_terracotta 0
setblock ~16 ~2 ~39 log2 0
setblock ~16 ~2 ~90 gold_ore 0
setblock ~17 ~2 ~30 log2 0
setblock ~17 ~2 ~31 stained_hardened_clay 8
setblock ~17 ~2 ~32 mycelium 0
setblock ~17 ~2 ~91 stained_hardened_clay 8
setblock ~18 ~2 ~29 brown_glazed_terracotta 0
setblock ~18 ~2 ~92 stained_hardened_clay 8
setblock ~19 ~2 ~27 stained_hardened_clay 8
fill ~19 ~2 ~28 ~19 ~3 ~28 brown_glazed_terracotta 0
fill ~19 ~2 ~92 ~19 ~3 ~92 log2 0
setblock ~20 ~2 ~26 gold_ore 0
setblock ~20 ~2 ~93 brown_glazed_terracotta 0
setblock ~21 ~2 ~25 stained_hardened_clay 8
setblock ~21 ~2 ~94 mycelium 0
setblock ~22 ~2 ~24 brown_glazed_terracotta 0
setblock ~22 ~2 ~95 brown_glazed_terracotta 0
setblock ~23 ~2 ~23 gold_ore 0
setblock ~24 ~2 ~22 gold_ore 0
setblock ~25 ~2 ~21 stained_hardened_clay 8
setblock ~25 ~2 ~97 brown_glazed_terracotta 0
setblock ~26 ~2 ~20 gold_ore 0
setblock ~26 ~2 ~98 gold_ore 0
setblock ~27 ~2 ~19 stained_hardened_clay 8
fill ~27 ~2 ~99 ~28 ~2 ~99 brown_mushroom_block 0
setblock ~28 ~2 ~18 gold_ore 0
setblock ~29 ~2 ~17 gold_ore 0
setblock ~30 ~2 ~16 stained_hardened_clay 8
setblock ~31 ~2 ~15 gold_ore 0
setblock ~31 ~2 ~100 bookshelf 0
fill ~32 ~2 ~15 ~32 ~3 ~15 stained_hardened_clay 8
setblock ~32 ~2 ~100 gold_ore 0
setblock ~34 ~2 ~13 log2 0
setblock ~34 ~2 ~100 stained_hardened_clay 8
setblock ~35 ~2 ~12 brown_glazed_terracotta 0
fill ~35 ~2 ~100 ~35 ~3 ~100 log2 0
setblock ~36 ~2 ~12 gold_ore 0
setblock ~36 ~2 ~99 brown_mushroom_block 0
setblock ~37 ~2 ~11 stained_hardened_clay 8
setblock ~37 ~2 ~99 stained_hardened_clay 8
setblock ~38 ~2 ~10 gold_ore 0
setblock ~38 ~2 ~99 brown_glazed_terracotta 0
setblock ~39 ~2 ~99 log2 0
setblock ~40 ~2 ~9 brown_glazed_terracotta 0
setblock ~41 ~2 ~9 gold_ore 0
setblock ~41 ~2 ~99 brown_mushroom_block 0
setblock ~42 ~2 ~8 gold_ore 0
setblock ~43 ~2 ~100 log2 0
setblock ~44 ~2 ~8 stained_hardened_clay 8
setblock ~44 ~2 ~100 stained_hardened_clay 8
setblock ~45 ~2 ~7 stained_hardened_clay 8
setblock ~45 ~2 ~100 planks 1
setblock ~46 ~2 ~7 brown_glazed_terracotta 0
fill ~46 ~2 ~101 ~46 ~3 ~101 log2 0
setblock ~47 ~2 ~6 mycelium 0
setblock ~47 ~2 ~101 gold_ore 0
setblock ~48 ~2 ~6 gold_ore 0
setblock ~48 ~2 ~101 brown_glazed_terracotta 0
setblock ~49 ~2 ~6 log2 0
setblock ~49 ~2 ~102 log2 0
fill ~50 ~2 ~5 ~52 ~2 ~5 brown_glazed_terracotta 0
setblock ~51 ~2 ~102 planks 1
fill ~52 ~2 ~102 ~52 ~3 ~102 brown_glazed_terracotta 0
setblock ~53 ~2 ~4 dirt 1
setblock ~53 ~2 ~102 dirt 1
fill ~54 ~2 ~4 ~54 ~3 ~4 stained_hardened_clay 8
setblock ~54 ~2 ~103 mycelium 0
setblock ~55 ~2 ~4 log2 0
setblock ~55 ~2 ~103 brown_glazed_terracotta 0
setblock ~56 ~2 ~4 stained_hardened_clay 8
setblock ~56 ~2 ~103 log2 0
fill ~57 ~2 ~3 ~58 ~2 ~3 brown_glazed_terracotta 0
setblock ~57 ~2 ~103 mycelium 0
setblock ~58 ~2 ~103 brown_mushroom_block 0
setblock ~59 ~2 ~3 stained_hardened_clay 8
fill ~59 ~2 ~103 ~60 ~2 ~103 brown_glazed_terracotta 0
setblock ~60 ~2 ~3 brown_mushroom_block 0
setblock ~61 ~2 ~2 dirt 1
setblock ~61 ~2 ~103 stained_hardened_clay 8
setblock ~62 ~2 ~2 gold_ore 0
setblock ~63 ~2 ~2 log2 0
setblock ~63 ~2 ~104 log2 0
fill ~64 ~2 ~104 ~64 ~3 ~104 gold_ore 0
setblock ~65 ~2 ~2 mycelium 0
setblock ~65 ~2 ~104 brown_glazed_terracotta 0
setblock ~66 ~2 ~2 gold_ore 0
fill ~66 ~2 ~105 ~67 ~2 ~105 gold_ore 0
setblock ~67 ~2 ~2 bookshelf 0
setblock ~68 ~2 ~1 brown_mushroom_block 0
setblock ~68 ~2 ~105 brown_glazed_terracotta 0
fill ~69 ~2 ~1 ~70 ~2 ~1 stained_hardened_clay 8
setblock ~69 ~2 ~105 log2 0
setblock ~70 ~2 ~105 stained_hardened_clay 8
setblock ~71 ~2 ~1 gold_ore 0
setblock ~71 ~2 ~105 gold_ore 0
setblock ~72 ~2 ~1 brown_mushroom_block 0
setblock ~72 ~2 ~105 stained_hardened_clay 8
setblock ~73 ~2 ~1 stained_hardened_clay 8
fill ~73 ~2 ~105 ~74 ~2 ~105 brown_mushroom_block 0
setblock ~74 ~2 ~1 brown_glazed_terracotta 0
setblock ~75 ~2 ~1 stained_hardened_clay 8
setblock ~75 ~2 ~105 stained_hardened_clay 8
setblock ~76 ~2 ~1 brown_mushroom_block 0
setblock ~77 ~2 ~1 gold_ore 0
setblock ~77 ~2 ~105 gold_ore 0
setblock ~78 ~2 ~105 log2 0
setblock ~79 ~2 ~1 gold_ore 0
fill ~79 ~2 ~104 ~79 ~3 ~104 dirt 1
setblock ~80 ~2 ~1 brown_glazed_terracotta 0
setblock ~80 ~2 ~104 gold_ore 0
setblock ~81 ~2 ~1 stained_hardened_clay 8
fill ~82 ~2 ~2 ~82 ~3 ~2 stained_hardened_clay 8
setblock ~82 ~2 ~104 gold_ore 0
setblock ~83 ~2 ~2 dirt 1
setblock ~83 ~2 ~104 dirt 1
setblock ~84 ~2 ~2 stained_hardened_clay 8
setblock ~84 ~2 ~104 gold_ore 0
fill ~85 ~2 ~2 ~85 ~3 ~2 brown_glazed_terracotta 0
setblock ~85 ~2 ~104 log2 0
setblock ~86 ~2 ~2 stained_hardened_clay 8
setblock ~86 ~2 ~104 gold_ore 0
setblock ~87 ~2 ~2 log2 0
setblock ~87 ~2 ~104 log2 0
fill ~88 ~2 ~3 ~89 ~2 ~3 brown_glazed_terracotta 0
setblock ~89 ~2 ~104 dirt 1
setblock ~90 ~2 ~3 mycelium 0
setblock ~90 ~2 ~105 mycelium 0
setblock ~91 ~2 ~3 brown_glazed_terracotta 0
setblock ~91 ~2 ~105 stained_hardened_clay 8
setblock ~92 ~2 ~4 stained_hardened_clay 8
setblock ~92 ~2 ~105 brown_glazed_terracotta 0
setblock ~93 ~2 ~4 mycelium 0
setblock ~93 ~2 ~105 stained_hardened_clay 8
setblock ~94 ~2 ~4 gold_ore 0
fill ~94 ~2 ~105 ~96 ~2 ~105 brown_glazed_terracotta 0
setblock ~95 ~2 ~5 gold_ore 0
fill ~96 ~2 ~5 ~96 ~3 ~5 log2 0
setblock ~97 ~2 ~5 stained_hardened_clay 8
setblock ~97 ~2 ~105 stained_hardened_clay 8
setblock ~98 ~2 ~6 stained_hardened_clay 8
setblock ~98 ~2 ~105 brown_glazed_terracotta 0
fill ~99 ~2 ~6 ~99 ~3 ~6 brown_glazed_terracotta 0
setblock ~99 ~2 ~105 gold_ore 0
setblock ~100 ~2 ~6 gold_ore 0
setblock ~100 ~2 ~104 gold_ore 0
setblock ~101 ~2 ~7 gold_ore 0
fill ~101 ~2 ~104 ~101 ~3 ~104 log2 0
setblock ~102 ~2 ~7 brown_glazed_terracotta 0
fill ~102 ~2 ~103 ~102 ~3 ~103 log2 0
setblock ~103 ~2 ~7 stained_hardened_clay 8
setblock ~103 ~2 ~102 mycelium 0
setblock ~104 ~2 ~7 brown_glazed_terracotta 0
fill ~104 ~2 ~101 ~104 ~3 ~101 mycelium 0
setblock ~105 ~2 ~8 log2 0
fill ~105 ~2 ~100 ~105 ~3 ~100 brown_glazed_terracotta 0
setblock ~106 ~2 ~8 gold_ore 0
setblock ~107 ~2 ~8 log2 0
setblock ~107 ~2 ~97 stained_hardened_clay 8
setblock ~107 ~2 ~98 log2 0
setblock ~108 ~2 ~9 brown_mushroom_block 0
setblock ~108 ~2 ~96 gold_ore 0
setblock ~109 ~2 ~9 gold_ore 0
setblock ~109 ~2 ~95 stained_hardened_clay 8
fill ~110 ~2 ~94 ~110 ~4 ~94 gold_ore 0
fill ~111 ~2 ~10 ~111 ~3 ~10 brown_glazed_terracotta 0
setblock ~111 ~2 ~93 brown_mushroom_block 0
setblock ~112 ~2 ~10 gold_ore 0
setblock ~113 ~2 ~11 stained_hardened_clay 8
fill ~113 ~2 ~92 ~113 ~4 ~92 log2 0
setblock ~114 ~2 ~11 brown_glazed_terracotta 0
fill ~114 ~2 ~92 ~114 ~4 ~92 stained_hardened_clay 8
setblock ~115 ~2 ~92 dirt 1
setblock ~116 ~2 ~13 brown_glazed_terracotta 0
setblock ~116 ~2 ~14 gold_ore 0
fill ~116 ~2 ~91 ~118 ~2 ~91 brown_glazed_terracotta 0
setblock ~117 ~2 ~15 stained_hardened_clay 8
setblock ~118 ~2 ~16 gold_ore 0
setblock ~118 ~2 ~17 log2 0
setblock ~119 ~2 ~18 log2 0
setblock ~119 ~2 ~19 stained_hardened_clay 8
setblock ~119 ~2 ~91 brown_mushroom_block 0
setblock ~120 ~2 ~20 gold_ore 0
setblock ~120 ~2 ~21 log2 0
setblock ~120 ~2 ~22 stained_hardened_clay 8
setblock ~121 ~2 ~23 gold_ore 0
setblock ~121 ~2 ~24 brown_glazed_terracotta 0
setblock ~121 ~2 ~25 stained_hardened_clay 8
setblock ~121 ~2 ~91 gold_ore 0
setblock ~122 ~2 ~26 stained_hardened_clay 8
setblock ~122 ~2 ~27 brown_glazed_terracotta 0
fill ~122 ~2 ~28 ~122 ~3 ~28 stained_hardened_clay 8
setblock ~122 ~2 ~91 stained_hardened_clay 8
setblock ~123 ~2 ~29 stained_hardened_clay 8
fill ~123 ~2 ~30 ~123 ~3 ~30 log2 0
setblock ~123 ~2 ~91 brown_glazed_terracotta 0
fill ~124 ~2 ~31 ~124 ~3 ~31 log2 0
setblock ~125 ~2 ~32 log2 0
setblock ~125 ~2 ~33 stained_hardened_clay 8
setblock ~125 ~2 ~91 stained_hardened_clay 8
setblock ~126 ~2 ~34 stained_hardened_clay 8
fill ~126 ~2 ~35 ~126 ~3 ~35 brown_glazed_terracotta 0
setblock ~127 ~2 ~36 dirt 1
setblock ~127 ~2 ~37 brown_glazed_terracotta 0
setblock ~127 ~2 ~89 brown_glazed_terracotta 0
setblock ~128 ~2 ~38 stained_hardened_clay 8
setblock ~128 ~2 ~39 mycelium 0
fill ~128 ~2 ~40 ~128 ~3 ~40 stained_hardened_clay 8
setblock ~128 ~2 ~88 stained_hardened_clay 8
setblock ~129 ~2 ~41 stained_hardened_clay 8
fill ~129 ~2 ~42 ~129 ~3 ~42 mycelium 0
setblock ~129 ~2 ~43 stained_hardened_clay 8
setblock ~129 ~2 ~86 dirt 1
setblock ~129 ~2 ~87 brown_glazed_terracotta 0
setblock ~130 ~2 ~45 stained_hardened_clay 8
setblock ~130 ~2 ~46 gold_ore 0
setblock ~130 ~2 ~82 gold_ore 0
setblock ~130 ~2 ~83 brown_mushroom_block 0
fill ~130 ~2 ~84 ~130 ~3 ~84 stained_hardened_clay 8
setblock ~130 ~2 ~85 brown_glazed_terracotta 0
setblock ~131 ~2 ~47 gold_ore 0
setblock ~131 ~2 ~48 log2 0
setblock ~131 ~2 ~49 stained_hardened_clay 8
setblock ~131 ~2 ~50 log2 0
setblock ~131 ~2 ~72 log 3
setblock ~131 ~2 ~73 brown_glazed_terracotta 0
setblock ~131 ~2 ~74 log2 0
setblock ~131 ~2 ~75 brown_glazed_terracotta 0
setblock ~131 ~2 ~76 dirt 1
setblock ~131 ~2 ~77 brown_glazed_terracotta 0
setblock ~131 ~2 ~79 stained_hardened_clay 8
setblock ~131 ~2 ~81 stained_hardened_clay 8
setblock ~132 ~2 ~51 brown_glazed_terracotta 0
setblock ~132 ~2 ~54 gold_ore 0
setblock ~132 ~2 ~55 brown_glazed_terracotta 0
setblock ~132 ~2 ~56 stained_hardened_clay 8
setblock ~132 ~2 ~64 stained_hardened_clay 8
setblock ~132 ~2 ~65 brown_glazed_terracotta 0
setblock ~132 ~2 ~66 gold_ore 0
setblock ~132 ~2 ~67 stained_hardened_clay 8
setblock ~132 ~2 ~68 gold_ore 0
fill ~132 ~2 ~69 ~132 ~3 ~69 brown_glazed_terracotta 0
setblock ~132 ~2 ~70 stained_hardened_clay 8
setblock ~132 ~2 ~71 brown_glazed_terracotta 0
setblock ~133 ~2 ~57 stained_hardened_clay 8
setblock ~133 ~2 ~58 brown_glazed_terracotta 0
setblock ~133 ~2 ~59 gold_ore 0
setblock ~133 ~2 ~60 dirt 1
setblock ~133 ~2 ~61 stained_hardened_clay 8
setblock ~133 ~2 ~62 mycelium 0
setblock ~133 ~2 ~63 stained_hardened_clay 8
setblock ~7 ~3 ~76 mycelium 0
fill ~7 ~3 ~77 ~7 ~3 ~78 log2 0
setblock ~8 ~3 ~70 stained_hardened_clay 8
setblock ~8 ~3 ~71 dirt 1
fill ~8 ~3 ~73 ~8 ~4 ~73 brown_glazed_terracotta 0
fill ~8 ~3 ~74 ~8 ~3 ~75 brown_glazed_terracotta 0
setblock ~8 ~3 ~79 log2 0
setblock ~8 ~3 ~80 stained_hardened_clay 8
setblock ~8 ~3 ~81 brown_glazed_terracotta 0
setblock ~9 ~3 ~66 brown_glazed_terracotta 0
setblock ~9 ~3 ~67 log2 0
setblock ~9 ~3 ~68 brown_mushroom_block 0
setblock ~9 ~3 ~69 dirt 1
setblock ~10 ~3 ~61 mycelium 0
setblock ~10 ~3 ~62 brown_glazed_terracotta 0
setblock ~10 ~3 ~63 log2 0
setblock ~10 ~3 ~65 mycelium 0
fill ~10 ~3 ~83 ~10 ~4 ~83 brown_glazed_terracotta 0
setblock ~11 ~3 ~57 dirt 1
setblock ~11 ~3 ~58 brown_glazed_terracotta 0
setblock ~11 ~3 ~59 mycelium 0
setblock ~11 ~3 ~60 brown_glazed_terracotta 0
setblock ~11 ~3 ~85 log 3
setblock ~12 ~3 ~54 brown_mushroom_block 0
setblock ~12 ~3 ~55 log2 0
setblock ~12 ~3 ~56 brown_glazed_terracotta 0
setblock ~12 ~3 ~86 brown_glazed_terracotta 0
setblock ~13 ~3 ~49 log2 0
setblock ~13 ~3 ~50 brown_glazed_terracotta 0
fill ~13 ~3 ~51 ~13 ~3 ~52 log2 0
setblock ~13 ~3 ~87 dirt 1
setblock ~14 ~3 ~45 brown_glazed_terracotta 0
setblock ~14 ~3 ~46 stained_hardened_clay 8
setblock ~14 ~3 ~48 gold_ore 0
setblock ~15 ~3 ~41 log2 0
setblock ~15 ~3 ~42 brown_glazed_terracotta 0
setblock ~15 ~3 ~43 mycelium 0
setblock ~15 ~3 ~44 brown_glazed_terracotta 0
setblock ~15 ~3 ~89 planks 1
setblock ~16 ~3 ~35 log2 0
setblock ~16 ~3 ~37 mycelium 0
setblock ~16 ~3 ~38 log2 0
fill ~16 ~3 ~39 ~16 ~4 ~39 brown_glazed_terracotta 0
setblock ~16 ~3 ~40 stained_hardened_clay 8
fill ~16 ~3 ~90 ~17 ~3 ~90 brown_glazed_terracotta 0
setblock ~17 ~3 ~31 log2 0
setblock ~17 ~3 ~32 brown_glazed_terracotta 0
setblock ~17 ~3 ~33 dirt 1
setblock ~17 ~3 ~34 log2 0
setblock ~18 ~3 ~29 log2 0
setblock ~18 ~3 ~30 brown_glazed_terracotta 0
fill ~18 ~3 ~91 ~18 ~4 ~91 brown_glazed_terracotta 0
setblock ~20 ~3 ~26 stained_hardened_clay 8
setblock ~20 ~3 ~27 log2 0
setblock ~20 ~3 ~93 log2 0
setblock ~21 ~3 ~25 log 3
setblock ~21 ~3 ~94 brown_glazed_terracotta 0
setblock ~22 ~3 ~24 stained_hardened_clay 8
setblock ~22 ~3 ~95 mycelium 0
setblock ~23 ~3 ~23 log2 0
setblock ~23 ~3 ~95 log2 0
setblock ~24 ~3 ~22 brown_glazed_terracotta 0
setblock ~24 ~3 ~96 brown_glazed_terracotta 0
setblock ~25 ~3 ~21 dirt 1
setblock ~25 ~3 ~97 mycelium 0
setblock ~26 ~3 ~20 brown_glazed_terracotta 0
setblock ~26 ~3 ~98 stained_hardened_clay 8
setblock ~27 ~3 ~19 dirt 1
setblock ~27 ~3 ~98 brown_glazed_terracotta 0
fill ~28 ~3 ~19 ~28 ~4 ~19 brown_glazed_terracotta 0
setblock ~28 ~3 ~99 brown_glazed_terracotta 0
fill ~29 ~3 ~18 ~29 ~4 ~18 brown_glazed_terracotta 0
setblock ~29 ~3 ~100 brown_glazed_terracotta 0
setblock ~30 ~3 ~17 log2 0
setblock ~31 ~3 ~16 brown_glazed_terracotta 0
fill ~31 ~3 ~100 ~32 ~3 ~100 brown_glazed_terracotta 0
setblock ~33 ~3 ~14 log2 0
setblock ~34 ~3 ~14 brown_glazed_terracotta 0
setblock ~34 ~3 ~100 brown_glazed_terracotta 0
setblock ~35 ~3 ~13 mycelium 0
setblock ~36 ~3 ~12 stained_hardened_clay 8
setblock ~36 ~3 ~99 brown_glazed_terracotta 0
setblock ~37 ~3 ~12 brown_glazed_terracotta 0
setblock ~37 ~3 ~99 log2 0
setblock ~38 ~3 ~11 mycelium 0
setblock ~38 ~3 ~99 dirt 1
setblock ~39 ~3 ~99 planks 1
setblock ~40 ~3 ~10 stained_hardened_clay 8
setblock ~41 ~3 ~9 log2 0
setblock ~41 ~3 ~99 log2 0
fill ~42 ~3 ~9 ~42 ~4 ~9 brown_glazed_terracotta 0
fill ~43 ~3 ~8 ~45 ~3 ~8 brown_glazed_terracotta 0
setblock ~43 ~3 ~99 dirt 1
fill ~44 ~3 ~100 ~45 ~3 ~100 brown_glazed_terracotta 0
setblock ~46 ~3 ~7 log2 0
setblock ~47 ~3 ~7 dirt 1
setblock ~47 ~3 ~101 planks 1
setblock ~48 ~3 ~6 brown_mushroom_block 0
fill ~48 ~3 ~101 ~49 ~3 ~101 mycelium 0
setblock ~49 ~3 ~6 brown_glazed_terracotta 0
setblock ~50 ~3 ~6 brown_mushroom_block 0
setblock ~51 ~3 ~5 dirt 1
setblock ~51 ~3 ~102 log2 0
fill ~52 ~3 ~5 ~53 ~3 ~5 mycelium 0
fill ~53 ~3 ~102 ~54 ~3 ~102 log2 0
fill ~55 ~3 ~4 ~56 ~3 ~4 brown_glazed_terracotta 0
setblock ~55 ~3 ~103 log 3
fill ~56 ~3 ~103 ~57 ~3 ~103 dirt 1
fill ~57 ~3 ~4 ~57 ~4 ~4 log2 0
setblock ~58 ~3 ~3 log2 0
fill ~58 ~3 ~103 ~58 ~4 ~103 mycelium 0
setblock ~59 ~3 ~3 dirt 1
setblock ~59 ~3 ~103 log2 0
fill ~60 ~3 ~3 ~62 ~3 ~3 log2 0
setblock ~60 ~3 ~103 mycelium 0
setblock ~61 ~3 ~103 brown_glazed_terracotta 0
setblock ~62 ~3 ~103 dirt 1
setblock ~63 ~3 ~2 brown_glazed_terracotta 0
setblock ~63 ~3 ~104 brown_glazed_terracotta 0
setblock ~64 ~3 ~2 stained_hardened_clay 8
setblock ~65 ~3 ~2 log2 0
setblock ~65 ~3 ~104 log2 0
fill ~66 ~3 ~2 ~67 ~3 ~2 brown_glazed_terracotta 0
fill ~66 ~3 ~104 ~66 ~5 ~104 stained_hardened_clay 8
fill ~67 ~3 ~105 ~68 ~3 ~105 log2 0
setblock ~68 ~3 ~2 stained_hardened_clay 8
fill ~69 ~3 ~2 ~70 ~3 ~2 brown_glazed_terracotta 0
setblock ~69 ~3 ~105 dirt 1
fill ~70 ~3 ~105 ~71 ~3 ~105 log2 0
setblock ~71 ~3 ~2 log2 0
setblock ~72 ~3 ~2 stained_hardened_clay 8
setblock ~72 ~3 ~105 brown_glazed_terracotta 0
setblock ~73 ~3 ~1 dirt 1
setblock ~73 ~3 ~105 log2 0
setblock ~74 ~3 ~2 brown_glazed_terracotta 0
fill ~74 ~3 ~105 ~75 ~3 ~105 dirt 1
setblock ~75 ~3 ~2 log2 0
fill ~76 ~3 ~2 ~81 ~3 ~2 brown_glazed_terracotta 0
fill ~76 ~3 ~105 ~77 ~3 ~105 log2 0
setblock ~78 ~3 ~105 brown_glazed_terracotta 0
setblock ~80 ~3 ~104 stained_hardened_clay 8
setblock ~82 ~3 ~104 brown_glazed_terracotta 0
setblock ~83 ~3 ~2 mycelium 0
setblock ~83 ~3 ~104 log2 0
setblock ~84 ~3 ~2 log2 0
fill ~84 ~3 ~104 ~85 ~3 ~104 brown_glazed_terracotta 0
fill ~86 ~3 ~3 ~86 ~4 ~3 log2 0
setblock ~86 ~3 ~104 stained_hardened_clay 8
fill ~87 ~3 ~3 ~88 ~3 ~3 planks 1
fill ~87 ~3 ~104 ~89 ~3 ~104 brown_glazed_terracotta 0
setblock ~89 ~3 ~3 log 3
setblock ~90 ~3 ~3 dirt 1
setblock ~90 ~3 ~105 dirt 1
fill ~91 ~3 ~4 ~92 ~3 ~4 brown_glazed_terracotta 0
setblock ~91 ~3 ~105 planks 1
fill ~92 ~3 ~105 ~93 ~3 ~105 mycelium 0
setblock ~93 ~3 ~4 stained_hardened_clay 8
fill ~94 ~3 ~5 ~94 ~4 ~5 log2 0
fill ~94 ~3 ~105 ~94 ~4 ~105 brown_glazed_terracotta 0
setblock ~95 ~3 ~5 dirt 1
setblock ~95 ~3 ~105 mycelium 0
setblock ~96 ~3 ~105 log2 0
fill ~97 ~3 ~6 ~98 ~3 ~6 log2 0
setblock ~97 ~3 ~105 mycelium 0
setblock ~98 ~3 ~105 log2 0
setblock ~99 ~3 ~105 log 3
setblock ~100 ~3 ~7 log2 0
setblock ~100 ~3 ~104 brown_glazed_terracotta 0
setblock ~101 ~3 ~7 bookshelf 0
setblock ~102 ~3 ~7 log2 0
setblock ~103 ~3 ~8 brown_glazed_terracotta 0
setblock ~103 ~3 ~102 log2 0
setblock ~104 ~3 ~8 brown_mushroom_block 0
setblock ~105 ~3 ~8 brown_glazed_terracotta 0
setblock ~106 ~3 ~8 stained_hardened_clay 8
setblock ~106 ~3 ~98 stained_hardened_clay 8
setblock ~107 ~3 ~9 bookshelf 0
setblock ~107 ~3 ~97 mycelium 0
setblock ~108 ~3 ~9 brown_glazed_terracotta 0
setblock ~108 ~3 ~96 log2 0
setblock ~109 ~3 ~9 log2 0
setblock ~109 ~3 ~95 bookshelf 0
fill ~110 ~3 ~10 ~110 ~4 ~10 gold_ore 0
setblock ~111 ~3 ~93 log 3
setblock ~112 ~3 ~11 mycelium 0
setblock ~113 ~3 ~11 dirt 1
setblock ~114 ~3 ~12 brown_glazed_terracotta 0
setblock ~115 ~3 ~13 log2 0
setblock ~115 ~3 ~92 brown_glazed_terracotta 0
setblock ~116 ~3 ~14 brown_glazed_terracotta 0
setblock ~116 ~3 ~91 mycelium 0
setblock ~117 ~3 ~15 mycelium 0
setblock ~117 ~3 ~16 brown_glazed_terracotta 0
setblock ~117 ~3 ~91 dirt 1
setblock ~118 ~3 ~17 mycelium 0
setblock ~118 ~3 ~18 stained_hardened_clay 8
fill ~118 ~3 ~91 ~121 ~3 ~91 log2 0
setblock ~119 ~3 ~19 dirt 1
setblock ~119 ~3 ~20 stained_hardened_clay 8
fill ~120 ~3 ~21 ~120 ~3 ~23 brown_glazed_terracotta 0
fill ~120 ~3 ~24 ~120 ~4 ~24 stained_hardened_clay 8
setblock ~121 ~3 ~25 dirt 1
setblock ~121 ~3 ~26 log2 0
setblock ~122 ~3 ~27 log2 0
setblock ~122 ~3 ~91 brown_glazed_terracotta 0
setblock ~123 ~3 ~29 dirt 1
setblock ~123 ~3 ~91 dirt 1
setblock ~124 ~3 ~32 brown_glazed_terracotta 0
setblock ~125 ~3 ~33 dirt 1
setblock ~125 ~3 ~34 brown_glazed_terracotta 0
fill ~125 ~3 ~90 ~126 ~3 ~90 brown_glazed_terracotta 0
setblock ~126 ~3 ~36 brown_glazed_terracotta 0
setblock ~127 ~3 ~37 dirt 1
setblock ~127 ~3 ~38 brown_glazed_terracotta 0
setblock ~127 ~3 ~89 mycelium 0
setblock ~128 ~3 ~39 log2 0
setblock ~128 ~3 ~41 dirt 1
setblock ~128 ~3 ~87 log2 0
setblock ~128 ~3 ~88 brown_glazed_terracotta 0
setblock ~129 ~3 ~43 planks 1
fill ~129 ~3 ~44 ~129 ~4 ~44 log2 0
fill ~129 ~3 ~85 ~129 ~3 ~86 log2 0
setblock ~130 ~3 ~45 brown_glazed_terracotta 0
setblock ~130 ~3 ~46 stained_hardened_clay 8
fill ~130 ~3 ~47 ~130 ~4 ~47 brown_glazed_terracotta 0
setblock ~130 ~3 ~80 log2 0
fill ~130 ~3 ~81 ~130 ~4 ~81 brown_glazed_terracotta 0
fill ~130 ~3 ~82 ~130 ~3 ~83 brown_glazed_terracotta 0
setblock ~131 ~3 ~48 brown_glazed_terracotta 0
setblock ~131 ~3 ~49 log2 0
setblock ~131 ~3 ~50 brown_glazed_terracotta 0
setblock ~131 ~3 ~51 dirt 1
fill ~131 ~3 ~70 ~131 ~4 ~70 log2 0
setblock ~131 ~3 ~71 planks 1
setblock ~131 ~3 ~72 brown_glazed_terracotta 0
setblock ~131 ~3 ~73 log2 0
setblock ~131 ~3 ~74 brown_glazed_terracotta 0
setblock ~131 ~3 ~75 mycelium 0
fill ~131 ~3 ~76 ~131 ~3 ~77 log2 0
setblock ~131 ~3 ~78 brown_glazed_terracotta 0
setblock ~131 ~3 ~79 mycelium 0
setblock ~132 ~3 ~52 stained_hardened_clay 8
setblock ~132 ~3 ~54 stained_hardened_clay 8
setblock ~132 ~3 ~55 log2 0
fill ~132 ~3 ~56 ~132 ~3 ~57 brown_glazed_terracotta 0
setblock ~132 ~3 ~58 stained_hardened_clay 8
fill ~132 ~3 ~59 ~132 ~4 ~59 brown_glazed_terracotta 0
fill ~132 ~3 ~60 ~132 ~3 ~59 brown_glazed_terracotta 0
fill ~132 ~3 ~61 ~132 ~4 ~61 log2 0
fill ~132 ~3 ~62 ~132 ~3 ~64 brown_glazed_terracotta 0
setblock ~132 ~3 ~65 log2 0
setblock ~132 ~3 ~66 brown_mushroom_block 0
setblock ~132 ~3 ~67 log2 0
setblock ~132 ~3 ~68 stained_hardened_clay 8
setblock ~8 ~4 ~72 brown_glazed_terracotta 0
setblock ~8 ~4 ~74 stained_hardened_clay 8
setblock ~8 ~4 ~75 log2 0
setblock ~8 ~4 ~76 gold_ore 0
setblock ~8 ~4 ~77 log2 0
setblock ~8 ~4 ~78 stained_hardened_clay 8
setblock ~8 ~4 ~79 brown_glazed_terracotta 0
setblock ~9 ~4 ~67 stained_hardened_clay 8
setblock ~9 ~4 ~68 log2 0
setblock ~9 ~4 ~69 gold_ore 0
setblock ~9 ~4 ~70 bookshelf 0
setblock ~9 ~4 ~71 stained_hardened_clay 8
setblock ~9 ~4 ~80 dirt 1
setblock ~9 ~4 ~81 brown_glazed_terracotta 0
setblock ~10 ~4 ~63 brown_glazed_terracotta 0
setblock ~10 ~4 ~64 gold_ore 0
setblock ~10 ~4 ~65 log2 0
setblock ~10 ~4 ~66 stained_hardened_clay 8
fill ~10 ~4 ~82 ~10 ~5 ~82 stained_hardened_clay 8
setblock ~11 ~4 ~59 brown_glazed_terracotta 0
setblock ~11 ~4 ~60 log2 0
setblock ~11 ~4 ~61 brown_glazed_terracotta 0
fill ~11 ~4 ~62 ~11 ~5 ~62 log2 0
setblock ~11 ~4 ~84 dirt 1
setblock ~12 ~4 ~55 brown_glazed_terracotta 0
setblock ~12 ~4 ~56 stained_hardened_clay 8
setblock ~12 ~4 ~57 brown_glazed_terracotta 0
setblock ~12 ~4 ~58 stained_hardened_clay 8
setblock ~12 ~4 ~85 log2 0
setblock ~13 ~4 ~51 stained_hardened_clay 8
setblock ~13 ~4 ~52 bookshelf 0
setblock ~13 ~4 ~53 stained_hardened_clay 8
setblock ~13 ~4 ~54 mycelium 0
setblock ~13 ~4 ~86 mycelium 0
fill ~14 ~4 ~47 ~14 ~4 ~48 stained_hardened_clay 8
fill ~14 ~4 ~49 ~14 ~5 ~49 log2 0
fill ~14 ~4 ~50 ~14 ~5 ~50 stained_hardened_clay 8
setblock ~14 ~4 ~87 log2 0
setblock ~15 ~4 ~43 stained_hardened_clay 8
setblock ~15 ~4 ~44 log2 0
setblock ~15 ~4 ~45 stained_hardened_clay 8
setblock ~15 ~4 ~46 log2 0
setblock ~15 ~4 ~88 log2 0
setblock ~16 ~4 ~38 stained_hardened_clay 8
fill ~16 ~4 ~40 ~16 ~4 ~41 brown_glazed_terracotta 0
setblock ~16 ~4 ~42 gold_ore 0
setblock ~16 ~4 ~89 brown_glazed_terracotta 0
setblock ~17 ~4 ~33 stained_hardened_clay 8
setblock ~17 ~4 ~34 brown_glazed_terracotta 0
setblock ~17 ~4 ~35 gold_ore 0
setblock ~17 ~4 ~36 mycelium 0
setblock ~17 ~4 ~37 stained_hardened_clay 8
setblock ~17 ~4 ~90 log2 0
setblock ~18 ~4 ~30 stained_hardened_clay 8
setblock ~18 ~4 ~31 brown_glazed_terracotta 0
setblock ~18 ~4 ~32 stained_hardened_clay 8
setblock ~19 ~4 ~29 gold_ore 0
setblock ~19 ~4 ~92 mycelium 0
setblock ~20 ~4 ~27 brown_glazed_terracotta 0
setblock ~20 ~4 ~28 stained_hardened_clay 8
setblock ~20 ~4 ~92 stained_hardened_clay 8
setblock ~21 ~4 ~26 brown_mushroom_block 0
setblock ~21 ~4 ~93 stained_hardened_clay 8
setblock ~22 ~4 ~25 brown_glazed_terracotta 0
setblock ~22 ~4 ~94 stained_hardened_clay 8
setblock ~23 ~4 ~24 dirt 1
setblock ~23 ~4 ~95 stained_hardened_clay 8
setblock ~24 ~4 ~23 brown_glazed_terracotta 0
setblock ~24 ~4 ~96 stained_hardened_clay 8
setblock ~25 ~4 ~22 log2 0
setblock ~25 ~4 ~97 stained_hardened_clay 8
setblock ~26 ~4 ~21 brown_glazed_terracotta 0
fill ~26 ~4 ~97 ~26 ~5 ~97 log2 0
setblock ~27 ~4 ~20 mycelium 0
setblock ~27 ~4 ~98 mycelium 0
setblock ~28 ~4 ~99 brown_mushroom_block 0
setblock ~29 ~4 ~99 stained_hardened_clay 8
setblock ~30 ~4 ~18 gold_ore 0
setblock ~31 ~4 ~17 stained_hardened_clay 8
setblock ~31 ~4 ~100 dirt 1
setblock ~32 ~4 ~16 brown_mushroom_block 0
fill ~32 ~4 ~100 ~32 ~5 ~100 gold_ore 0
setblock ~33 ~4 ~15 gold_ore 0
setblock ~33 ~4 ~100 dirt 1
setblock ~34 ~4 ~14 stained_hardened_clay 8
fill ~34 ~4 ~100 ~34 ~5 ~100 stained_hardened_clay 8
setblock ~35 ~4 ~14 log2 0
setblock ~35 ~4 ~100 planks 1
setblock ~36 ~4 ~13 log2 0
fill ~36 ~4 ~99 ~37 ~4 ~99 stained_hardened_clay 8
setblock ~37 ~4 ~12 log2 0
fill ~38 ~4 ~12 ~38 ~5 ~12 stained_hardened_clay 8
fill ~38 ~4 ~99 ~39 ~4 ~99 brown_glazed_terracotta 0
setblock ~39 ~4 ~11 gold_ore 0
fill ~40 ~4 ~11 ~40 ~5 ~11 brown_glazed_terracotta 0
setblock ~40 ~4 ~98 stained_hardened_clay 8
setblock ~41 ~4 ~10 bookshelf 0
setblock ~41 ~4 ~98 dirt 1
fill ~42 ~4 ~99 ~43 ~4 ~99 brown_glazed_terracotta 0
setblock ~43 ~4 ~9 brown_glazed_terracotta 0
fill ~44 ~4 ~9 ~44 ~5 ~9 log2 0
setblock ~44 ~4 ~99 gold_ore 0
setblock ~45 ~4 ~8 brown_glazed_terracotta 0
setblock ~45 ~4 ~100 log2 0
setblock ~46 ~4 ~8 stained_hardened_clay 8
setblock ~46 ~4 ~100 gold_ore 0
setblock ~47 ~4 ~7 stained_hardened_clay 8
setblock ~47 ~4 ~101 brown_glazed_terracotta 0
setblock ~48 ~4 ~7 brown_glazed_terracotta 0
fill ~48 ~4 ~101 ~48 ~5 ~101 log2 0
setblock ~49 ~4 ~7 stained_hardened_clay 8
setblock ~49 ~4 ~101 brown_glazed_terracotta 0
setblock ~50 ~4 ~6 stained_hardened_clay 8
setblock ~50 ~4 ~101 log2 0
setblock ~51 ~4 ~6 bookshelf 0
setblock ~51 ~4 ~102 log 3
setblock ~52 ~4 ~6 stained_hardened_clay 8
fill ~52 ~4 ~102 ~52 ~5 ~102 stained_hardened_clay 8
setblock ~53 ~4 ~5 stained_hardened_clay 8
setblock ~53 ~4 ~102 dirt 1
setblock ~54 ~4 ~5 log2 0
setblock ~54 ~4 ~102 stained_hardened_clay 8
setblock ~55 ~4 ~5 stained_hardened_clay 8
setblock ~55 ~4 ~102 planks 1
setblock ~56 ~4 ~5 brown_glazed_terracotta 0
fill ~56 ~4 ~102 ~56 ~6 ~102 brown_glazed_terracotta 0
setblock ~57 ~4 ~103 stained_hardened_clay 8
setblock ~58 ~4 ~4 brown_glazed_terracotta 0
setblock ~59 ~4 ~4 log 3
fill ~59 ~4 ~103 ~60 ~4 ~103 brown_glazed_terracotta 0
setblock ~60 ~4 ~4 stained_hardened_clay 8
setblock ~61 ~4 ~3 stained_hardened_clay 8
setblock ~61 ~4 ~103 stained_hardened_clay 8
setblock ~62 ~4 ~3 brown_glazed_terracotta 0
setblock ~62 ~4 ~103 brown_glazed_terracotta 0
setblock ~63 ~4 ~3 stained_hardened_clay 8
setblock ~63 ~4 ~104 log2 0
setblock ~64 ~4 ~3 log2 0
setblock ~64 ~4 ~104 stained_hardened_clay 8
setblock ~65 ~4 ~3 stained_hardened_clay 8
setblock ~65 ~4 ~104 bookshelf 0
setblock ~66 ~4 ~3 brown_glazed_terracotta 0
setblock ~67 ~4 ~3 gold_ore 0
fill ~67 ~4 ~104 ~67 ~5 ~104 log2 0
fill ~68 ~4 ~3 ~68 ~5 ~3 brown_glazed_terracotta 0
setblock ~68 ~4 ~104 gold_ore 0
setblock ~69 ~4 ~2 dirt 1
setblock ~69 ~4 ~104 log2 0
setblock ~70 ~4 ~2 gold_ore 0
setblock ~70 ~4 ~104 gold_ore 0
setblock ~71 ~4 ~2 dirt 1
setblock ~71 ~4 ~104 log2 0
setblock ~72 ~4 ~2 gold_ore 0
setblock ~72 ~4 ~104 stained_hardened_clay 8
setblock ~73 ~4 ~2 log2 0
setblock ~73 ~4 ~104 mycelium 0
setblock ~74 ~4 ~2 stained_hardened_clay 8
setblock ~74 ~4 ~105 log2 0
setblock ~75 ~4 ~2 dirt 1
fill ~75 ~4 ~105 ~77 ~4 ~105 brown_glazed_terracotta 0
setblock ~76 ~4 ~2 stained_hardened_clay 8
setblock ~77 ~4 ~2 log2 0
setblock ~78 ~4 ~2 gold_ore 0
setblock ~78 ~4 ~104 stained_hardened_clay 8
setblock ~79 ~4 ~2 dirt 1
setblock ~79 ~4 ~104 log2 0
setblock ~80 ~4 ~2 stained_hardened_clay 8
setblock ~80 ~4 ~104 gold_ore 0
fill ~81 ~4 ~3 ~82 ~4 ~3 brown_glazed_terracotta 0
setblock ~81 ~4 ~103 stained_hardened_clay 8
setblock ~82 ~4 ~103 brown_glazed_terracotta 0
setblock ~83 ~4 ~3 stained_hardened_clay 8
setblock ~83 ~4 ~103 gold_ore 0
setblock ~84 ~4 ~3 mycelium 0
setblock ~84 ~4 ~104 gold_ore 0
setblock ~85 ~4 ~3 brown_glazed_terracotta 0
setblock ~85 ~4 ~104 log2 0
setblock ~86 ~4 ~104 gold_ore 0
setblock ~87 ~4 ~3 stained_hardened_clay 8
setblock ~87 ~4 ~104 log2 0
setblock ~88 ~4 ~4 gold_ore 0
setblock ~88 ~4 ~104 gold_ore 0
setblock ~89 ~4 ~4 dirt 1
setblock ~89 ~4 ~104 brown_glazed_terracotta 0
setblock ~90 ~4 ~4 stained_hardened_clay 8
setblock ~90 ~4 ~104 brown_mushroom_block 0
setblock ~91 ~4 ~4 log2 0
fill ~91 ~4 ~105 ~92 ~4 ~105 brown_glazed_terracotta 0
fill ~92 ~4 ~5 ~93 ~4 ~5 brown_glazed_terracotta 0
setblock ~93 ~4 ~105 log2 0
setblock ~95 ~4 ~6 dirt 1
setblock ~95 ~4 ~105 stained_hardened_clay 8
setblock ~96 ~4 ~6 stained_hardened_clay 8
fill ~96 ~4 ~105 ~98 ~4 ~105 brown_glazed_terracotta 0
setblock ~97 ~4 ~6 mycelium 0
setblock ~98 ~4 ~7 log2 0
setblock ~99 ~4 ~7 stained_hardened_clay 8
fill ~99 ~4 ~104 ~99 ~5 ~104 log2 0
setblock ~100 ~4 ~7 brown_mushroom_block 0
setblock ~100 ~4 ~104 gold_ore 0
fill ~101 ~4 ~8 ~101 ~5 ~8 log2 0
setblock ~101 ~4 ~103 stained_hardened_clay 8
setblock ~102 ~4 ~8 stained_hardened_clay 8
setblock ~102 ~4 ~103 brown_glazed_terracotta 0
setblock ~103 ~4 ~8 log2 0
setblock ~103 ~4 ~102 dirt 1
setblock ~104 ~4 ~8 gold_ore 0
setblock ~104 ~4 ~100 gold_ore 0
setblock ~104 ~4 ~101 log2 0
setblock ~105 ~4 ~9 stained_hardened_clay 8
setblock ~105 ~4 ~99 gold_ore 0
setblock ~106 ~4 ~9 brown_mushroom_block 0
setblock ~106 ~4 ~98 gold_ore 0
setblock ~107 ~4 ~9 gold_ore 0
setblock ~107 ~4 ~97 brown_glazed_terracotta 0
fill ~108 ~4 ~10 ~108 ~5 ~10 stained_hardened_clay 8
setblock ~108 ~4 ~95 brown_glazed_terracotta 0
setblock ~108 ~4 ~96 stained_hardened_clay 8
setblock ~109 ~4 ~10 log2 0
setblock ~109 ~4 ~94 dirt 1
setblock ~111 ~4 ~11 gold_ore 0
setblock ~111 ~4 ~93 stained_hardened_clay 8
setblock ~112 ~4 ~11 brown_glazed_terracotta 0
setblock ~112 ~4 ~92 stained_hardened_clay 8
setblock ~113 ~4 ~12 log2 0
setblock ~114 ~4 ~13 brown_glazed_terracotta 0
setblock ~115 ~4 ~14 dirt 1
setblock ~115 ~4 ~91 brown_glazed_terracotta 0
setblock ~116 ~4 ~15 brown_glazed_terracotta 0
setblock ~116 ~4 ~91 stained_hardened_clay 8
setblock ~117 ~4 ~16 dirt 1
setblock ~117 ~4 ~17 gold_ore 0
setblock ~117 ~4 ~91 gold_ore 0
fill ~118 ~4 ~18 ~118 ~4 ~19 brown_glazed_terracotta 0
setblock ~118 ~4 ~20 gold_ore 0
fill ~118 ~4 ~91 ~119 ~4 ~91 brown_glazed_terracotta 0
setblock ~119 ~4 ~21 gold_ore 0
setblock ~119 ~4 ~22 mycelium 0
setblock ~120 ~4 ~23 brown_mushroom_block 0
setblock ~120 ~4 ~25 brown_glazed_terracotta 0
setblock ~120 ~4 ~26 gold_ore 0
fill ~120 ~4 ~91 ~123 ~4 ~91 stained_hardened_clay 8
setblock ~121 ~4 ~27 brown_glazed_terracotta 0
fill ~121 ~4 ~28 ~121 ~5 ~28 log2 0
setblock ~122 ~4 ~29 stained_hardened_clay 8
fill ~122 ~4 ~30 ~122 ~5 ~30 brown_glazed_terracotta 0
setblock ~123 ~4 ~31 brown_glazed_terracotta 0
setblock ~123 ~4 ~32 dirt 1
setblock ~124 ~4 ~33 brown_glazed_terracotta 0
fill ~124 ~4 ~90 ~124 ~5 ~90 brown_glazed_terracotta 0
setblock ~125 ~4 ~34 log2 0
setblock ~125 ~4 ~35 brown_mushroom_block 0
setblock ~125 ~4 ~90 dirt 1
setblock ~126 ~4 ~36 stained_hardened_clay 8
setblock ~126 ~4 ~37 brown_glazed_terracotta 0
setblock ~126 ~4 ~38 gold_ore 0
setblock ~126 ~4 ~89 brown_glazed_terracotta 0
setblock ~127 ~4 ~39 stained_hardened_clay 8
setblock ~127 ~4 ~40 dirt 1
setblock ~127 ~4 ~88 log2 0
setblock ~128 ~4 ~41 log2 0
setblock ~128 ~4 ~42 brown_glazed_terracotta 0
setblock ~128 ~4 ~43 log2 0
fill ~128 ~4 ~86 ~128 ~4 ~87 stained_hardened_clay 8
setblock ~129 ~4 ~45 stained_hardened_clay 8
fill ~129 ~4 ~46 ~129 ~5 ~46 log2 0
setblock ~129 ~4 ~83 gold_ore 0
setblock ~129 ~4 ~84 log2 0
setblock ~129 ~4 ~85 stained_hardened_clay 8
setblock ~130 ~4 ~48 brown_glazed_terracotta 0
setblock ~130 ~4 ~49 log2 0
setblock ~130 ~4 ~50 brown_glazed_terracotta 0
fill ~130 ~4 ~73 ~130 ~5 ~73 log2 0
setblock ~130 ~4 ~74 stained_hardened_clay 8
fill ~130 ~4 ~75 ~130 ~5 ~75 brown_glazed_terracotta 0
setblock ~130 ~4 ~76 gold_ore 0
setblock ~130 ~4 ~77 brown_mushroom_block 0
setblock ~130 ~4 ~78 gold_ore 0
setblock ~130 ~4 ~79 stained_hardened_clay 8
setblock ~130 ~4 ~80 gold_ore 0
setblock ~130 ~4 ~82 stained_hardened_clay 8
setblock ~131 ~4 ~51 brown_glazed_terracotta 0
setblock ~131 ~4 ~52 mycelium 0
setblock ~131 ~4 ~53 brown_glazed_terracotta 0
setblock ~131 ~4 ~54 log2 0
setblock ~131 ~4 ~55 stained_hardened_clay 8
setblock ~131 ~4 ~56 dirt 1
setblock ~131 ~4 ~65 log2 0
setblock ~131 ~4 ~66 dirt 1
setblock ~131 ~4 ~67 brown_glazed_terracotta 0
setblock ~131 ~4 ~68 log2 0
setblock ~131 ~4 ~69 brown_mushroom_block 0
setblock ~131 ~4 ~71 stained_hardened_clay 8
setblock ~131 ~4 ~72 mycelium 0
setblock ~132 ~4 ~57 brown_glazed_terracotta 0
setblock ~132 ~4 ~58 gold_ore 0
setblock ~132 ~4 ~60 stained_hardened_clay 8
setblock ~132 ~4 ~62 stained_hardened_clay 8
fill ~132 ~4 ~63 ~132 ~4 ~64 brown_glazed_terracotta 0
setblock ~8 ~5 ~76 stained_hardened_clay 8
setblock ~8 ~5 ~77 dirt 1
setblock ~9 ~5 ~70 brown_glazed_terracotta 0
setblock ~9 ~5 ~71 planks 1
fill ~9 ~5 ~72 ~9 ~5 ~73 log2 0
setblock ~9 ~5 ~74 brown_mushroom_block 0
setblock ~9 ~5 ~75 log2 0
setblock ~9 ~5 ~78 brown_glazed_terracotta 0
setblock ~9 ~5 ~79 planks 1
setblock ~9 ~5 ~80 mycelium 0
setblock ~9 ~5 ~81 log2 0
setblock ~10 ~5 ~65 mycelium 0
setblock ~10 ~5 ~66 brown_glazed_terracotta 0
setblock ~10 ~5 ~67 mycelium 0
fill ~10 ~5 ~68 ~10 ~5 ~69 brown_glazed_terracotta 0
setblock ~11 ~5 ~61 dirt 1
setblock ~11 ~5 ~63 dirt 1
setblock ~11 ~5 ~64 log2 0
setblock ~11 ~5 ~83 log2 0
setblock ~12 ~5 ~57 log2 0
setblock ~12 ~5 ~58 brown_glazed_terracotta 0
setblock ~12 ~5 ~59 mycelium 0
fill ~12 ~5 ~60 ~12 ~6 ~60 stained_hardened_clay 8
setblock ~12 ~5 ~84 stained_hardened_clay 8
setblock ~13 ~5 ~53 planks 1
setblock ~13 ~5 ~54 brown_glazed_terracotta 0
setblock ~13 ~5 ~55 dirt 1
fill ~13 ~5 ~56 ~13 ~6 ~56 mycelium 0
setblock ~13 ~5 ~85 log 3
fill ~14 ~5 ~51 ~14 ~5 ~52 brown_glazed_terracotta 0
setblock ~14 ~5 ~86 brown_glazed_terracotta 0
setblock ~15 ~5 ~46 brown_glazed_terracotta 0
setblock ~15 ~5 ~47 log2 0
setblock ~15 ~5 ~48 brown_glazed_terracotta 0
setblock ~15 ~5 ~87 dirt 1
setblock ~16 ~5 ~41 log2 0
fill ~16 ~5 ~42 ~16 ~5 ~43 brown_glazed_terracotta 0
setblock ~16 ~5 ~44 stained_hardened_clay 8
setblock ~16 ~5 ~45 log2 0
setblock ~16 ~5 ~88 stained_hardened_clay 8
setblock ~17 ~5 ~35 dirt 1
setblock ~17 ~5 ~36 brown_glazed_terracotta 0
setblock ~17 ~5 ~37 dirt 1
setblock ~17 ~5 ~38 brown_glazed_terracotta 0
setblock ~17 ~5 ~39 dirt 1
fill ~17 ~5 ~40 ~17 ~6 ~40 log2 0
setblock ~17 ~5 ~89 dirt 1
setblock ~18 ~5 ~32 brown_glazed_terracotta 0
setblock ~18 ~5 ~33 log2 0
fill ~18 ~5 ~34 ~18 ~6 ~34 stained_hardened_clay 8
setblock ~18 ~5 ~90 brown_glazed_terracotta 0
setblock ~19 ~5 ~30 brown_glazed_terracotta 0
setblock ~19 ~5 ~31 log2 0
setblock ~19 ~5 ~91 log2 0
setblock ~20 ~5 ~28 brown_glazed_terracotta 0
setblock ~20 ~5 ~29 mycelium 0
setblock ~20 ~5 ~92 brown_glazed_terracotta 0
setblock ~21 ~5 ~27 dirt 1
setblock ~21 ~5 ~93 dirt 1
setblock ~22 ~5 ~26 brown_glazed_terracotta 0
setblock ~22 ~5 ~94 log2 0
setblock ~23 ~5 ~25 log 3
setblock ~23 ~5 ~94 brown_glazed_terracotta 0
setblock ~24 ~5 ~24 brown_mushroom_block 0
setblock ~24 ~5 ~95 brown_glazed_terracotta 0
setblock ~25 ~5 ~23 planks 1
setblock ~25 ~5 ~96 log2 0
setblock ~26 ~5 ~22 brown_glazed_terracotta 0
setblock ~27 ~5 ~21 log 3
setblock ~27 ~5 ~98 brown_glazed_terracotta 0
setblock ~28 ~5 ~20 log2 0
setblock ~28 ~5 ~98 brown_mushroom_block 0
setblock ~29 ~5 ~19 dirt 1
fill ~29 ~5 ~99 ~30 ~5 ~99 brown_glazed_terracotta 0
fill ~30 ~5 ~18 ~31 ~5 ~18 brown_glazed_terracotta 0
fill ~30 ~5 ~19 ~30 ~5 ~18 brown_glazed_terracotta 0
setblock ~31 ~5 ~100 log2 0
setblock ~32 ~5 ~17 log2 0
setblock ~33 ~5 ~16 log2 0
fill ~33 ~5 ~100 ~33 ~6 ~100 brown_glazed_terracotta 0
setblock ~34 ~5 ~15 log2 0
fill ~35 ~5 ~14 ~36 ~5 ~14 brown_glazed_terracotta 0
setblock ~35 ~5 ~100 brown_glazed_terracotta 0
setblock ~36 ~5 ~99 mycelium 0
setblock ~37 ~5 ~13 mycelium 0
setblock ~37 ~5 ~99 dirt 1
fill ~38 ~5 ~99 ~38 ~6 ~99 log2 0
setblock ~39 ~5 ~12 brown_glazed_terracotta 0
setblock ~39 ~5 ~98 log2 0
setblock ~40 ~5 ~98 brown_glazed_terracotta 0
setblock ~41 ~5 ~11 log2 0
setblock ~41 ~5 ~98 log2 0
fill ~42 ~5 ~10 ~43 ~5 ~10 brown_glazed_terracotta 0
setblock ~42 ~5 ~98 brown_glazed_terracotta 0
fill ~43 ~5 ~99 ~45 ~5 ~99 log2 0
setblock ~45 ~5 ~9 log2 0
setblock ~46 ~5 ~9 dirt 1
setblock ~46 ~5 ~100 stained_hardened_clay 8
setblock ~47 ~5 ~8 brown_glazed_terracotta 0
fill ~47 ~5 ~100 ~47 ~6 ~100 log2 0
setblock ~48 ~5 ~8 gold_ore 0
setblock ~49 ~5 ~7 brown_glazed_terracotta 0
setblock ~49 ~5 ~101 dirt 1
setblock ~50 ~5 ~7 log2 0
setblock ~50 ~5 ~101 mycelium 0
setblock ~51 ~5 ~7 planks 1
setblock ~51 ~5 ~101 planks 1
setblock ~52 ~5 ~6 brown_glazed_terracotta 0
setblock ~53 ~5 ~6 mycelium 0
setblock ~53 ~5 ~102 log2 0
setblock ~54 ~5 ~6 log2 0
setblock ~54 ~5 ~102 brown_glazed_terracotta 0
setblock ~55 ~5 ~6 brown_glazed_terracotta 0
fill ~55 ~5 ~102 ~55 ~6 ~102 dirt 1
setblock ~56 ~5 ~5 log2 0
setblock ~57 ~5 ~5 planks 1
setblock ~57 ~5 ~102 dirt 1
setblock ~58 ~5 ~5 mycelium 0
fill ~58 ~5 ~102 ~60 ~5 ~102 brown_glazed_terracotta 0
setblock ~59 ~5 ~5 dirt 1
setblock ~60 ~5 ~4 brown_glazed_terracotta 0
setblock ~61 ~5 ~4 dirt 1
fill ~61 ~5 ~102 ~61 ~6 ~102 log2 0
setblock ~62 ~5 ~4 brown_glazed_terracotta 0
fill ~62 ~5 ~103 ~62 ~6 ~103 log2 0
setblock ~63 ~5 ~4 log2 0
setblock ~63 ~5 ~104 brown_glazed_terracotta 0
setblock ~64 ~5 ~4 brown_glazed_terracotta 0
setblock ~64 ~5 ~104 log2 0
setblock ~65 ~5 ~4 log2 0
setblock ~65 ~5 ~104 brown_glazed_terracotta 0
setblock ~66 ~5 ~4 brown_glazed_terracotta 0
setblock ~67 ~5 ~3 dirt 1
fill ~68 ~5 ~104 ~69 ~5 ~104 stained_hardened_clay 8
setblock ~69 ~5 ~3 planks 1
setblock ~70 ~5 ~3 brown_glazed_terracotta 0
fill ~70 ~5 ~104 ~73 ~5 ~104 brown_glazed_terracotta 0
setblock ~71 ~5 ~3 planks 1
setblock ~72 ~5 ~3 log2 0
setblock ~73 ~5 ~3 bookshelf 0
setblock ~74 ~5 ~3 brown_glazed_terracotta 0
setblock ~74 ~5 ~104 brown_mushroom_block 0
setblock ~75 ~5 ~3 dirt 1
setblock ~75 ~5 ~104 brown_glazed_terracotta 0
setblock ~76 ~5 ~3 log2 0
setblock ~76 ~5 ~104 brown_mushroom_block 0
setblock ~77 ~5 ~3 planks 1
fill ~77 ~5 ~104 ~77 ~6 ~104 log2 0
setblock ~78 ~5 ~3 dirt 1
setblock ~78 ~5 ~104 brown_glazed_terracotta 0
setblock ~79 ~5 ~3 log 3
setblock ~79 ~5 ~103 dirt 1
setblock ~80 ~5 ~3 mycelium 0
setblock ~80 ~5 ~103 log2 0
setblock ~81 ~5 ~3 planks 1
setblock ~81 ~5 ~103 mycelium 0
setblock ~82 ~5 ~3 mycelium 0
setblock ~82 ~5 ~103 log2 0
setblock ~83 ~5 ~4 mycelium 0
setblock ~83 ~5 ~103 mycelium 0
setblock ~84 ~5 ~4 brown_glazed_terracotta 0
fill ~84 ~5 ~103 ~84 ~6 ~103 brown_glazed_terracotta 0
setblock ~85 ~5 ~4 mycelium 0
setblock ~85 ~5 ~103 dirt 1
setblock ~86 ~5 ~4 stained_hardened_clay 8
setblock ~86 ~5 ~103 log2 0
fill ~87 ~5 ~4 ~88 ~5 ~4 brown_glazed_terracotta 0
setblock ~87 ~5 ~104 brown_glazed_terracotta 0
setblock ~88 ~5 ~104 stained_hardened_clay 8
setblock ~89 ~5 ~5 planks 1
fill ~89 ~5 ~104 ~89 ~6 ~104 log2 0
setblock ~90 ~5 ~5 log2 0
setblock ~90 ~5 ~104 stained_hardened_clay 8
setblock ~91 ~5 ~5 dirt 1
setblock ~91 ~5 ~104 brown_glazed_terracotta 0
fill ~92 ~5 ~6 ~93 ~5 ~6 log2 0
setblock ~92 ~5 ~104 log2 0
fill ~93 ~5 ~104 ~93 ~6 ~104 mycelium 0
setblock ~94 ~5 ~6 brown_glazed_terracotta 0
fill ~94 ~5 ~105 ~95 ~5 ~105 dirt 1
setblock ~95 ~5 ~7 dirt 1
setblock ~96 ~5 ~7 mycelium 0
fill ~96 ~5 ~104 ~96 ~6 ~104 gold_ore 0
setblock ~97 ~5 ~7 dirt 1
fill ~97 ~5 ~104 ~98 ~5 ~104 brown_glazed_terracotta 0
setblock ~98 ~5 ~8 brown_glazed_terracotta 0
setblock ~99 ~5 ~8 log2 0
setblock ~100 ~5 ~8 brown_glazed_terracotta 0
fill ~100 ~5 ~103 ~101 ~5 ~103 log2 0
setblock ~102 ~5 ~9 log2 0
setblock ~102 ~5 ~102 stained_hardened_clay 8
setblock ~103 ~5 ~9 planks 1
setblock ~103 ~5 ~101 dirt 1
setblock ~104 ~5 ~9 log2 0
setblock ~104 ~5 ~100 stained_hardened_clay 8
setblock ~105 ~5 ~9 dirt 1
setblock ~105 ~5 ~98 brown_glazed_terracotta 0
setblock ~105 ~5 ~99 log2 0
setblock ~106 ~5 ~10 stained_hardened_clay 8
setblock ~106 ~5 ~97 mycelium 0
setblock ~107 ~5 ~10 log2 0
setblock ~107 ~5 ~96 brown_glazed_terracotta 0
setblock ~108 ~5 ~95 log2 0
setblock ~109 ~5 ~11 dirt 1
setblock ~109 ~5 ~94 log2 0
setblock ~110 ~5 ~11 mycelium 0
setblock ~110 ~5 ~93 brown_glazed_terracotta 0
setblock ~111 ~5 ~12 mycelium 0
setblock ~111 ~5 ~92 log2 0
setblock ~112 ~5 ~12 brown_glazed_terracotta 0
fill ~112 ~5 ~92 ~113 ~5 ~92 brown_glazed_terracotta 0
setblock ~113 ~5 ~13 mycelium 0
setblock ~114 ~5 ~14 brown_glazed_terracotta 0
setblock ~114 ~5 ~91 log2 0
setblock ~115 ~5 ~15 dirt 1
setblock ~115 ~5 ~91 log 3
setblock ~116 ~5 ~16 stained_hardened_clay 8
setblock ~116 ~5 ~17 brown_glazed_terracotta 0
setblock ~116 ~5 ~91 mycelium 0
setblock ~117 ~5 ~18 brown_glazed_terracotta 0
setblock ~117 ~5 ~19 dirt 1
setblock ~117 ~5 ~91 dirt 1
setblock ~118 ~5 ~20 stained_hardened_clay 8
setblock ~118 ~5 ~21 log2 0
setblock ~118 ~5 ~91 log2 0
setblock ~119 ~5 ~22 brown_glazed_terracotta 0
setblock ~119 ~5 ~23 mycelium 0
setblock ~119 ~5 ~24 brown_glazed_terracotta 0
fill ~119 ~5 ~25 ~119 ~6 ~25 log2 0
setblock ~119 ~5 ~91 bookshelf 0
setblock ~120 ~5 ~26 brown_mushroom_block 0
setblock ~120 ~5 ~27 log2 0
setblock ~120 ~5 ~91 brown_mushroom_block 0
setblock ~121 ~5 ~29 log2 0
fill ~121 ~5 ~91 ~122 ~5 ~91 log2 0
setblock ~122 ~5 ~31 mycelium 0
fill ~123 ~5 ~32 ~123 ~5 ~33 log2 0
setblock ~123 ~5 ~90 brown_glazed_terracotta 0
setblock ~124 ~5 ~34 stained_hardened_clay 8
setblock ~124 ~5 ~35 log2 0
setblock ~125 ~5 ~36 brown_glazed_terracotta 0
setblock ~125 ~5 ~37 dirt 1
setblock ~125 ~5 ~89 log2 0
setblock ~126 ~5 ~38 brown_mushroom_block 0
setblock ~126 ~5 ~39 log2 0
setblock ~126 ~5 ~88 stained_hardened_clay 8
setblock ~127 ~5 ~40 mycelium 0
fill ~127 ~5 ~41 ~127 ~5 ~42 dirt 1
setblock ~127 ~5 ~87 dirt 1
setblock ~128 ~5 ~43 mycelium 0
fill ~128 ~5 ~44 ~128 ~5 ~45 log2 0
setblock ~128 ~5 ~84 brown_glazed_terracotta 0
fill ~128 ~5 ~85 ~128 ~5 ~86 log2 0
setblock ~129 ~5 ~47 mycelium 0
setblock ~129 ~5 ~48 log2 0
setblock ~129 ~5 ~49 dirt 1
setblock ~129 ~5 ~78 brown_mushroom_block 0
setblock ~129 ~5 ~79 log2 0
setblock ~129 ~5 ~80 brown_glazed_terracotta 0
setblock ~129 ~5 ~81 log2 0
setblock ~129 ~5 ~82 brown_glazed_terracotta 0
setblock ~129 ~5 ~83 dirt 1
setblock ~130 ~5 ~50 stained_hardened_clay 8
setblock ~130 ~5 ~51 mycelium 0
setblock ~130 ~5 ~52 stained_hardened_clay 8
setblock ~130 ~5 ~53 dirt 1
setblock ~130 ~5 ~67 brown_mushroom_block 0
setblock ~130 ~5 ~68 stained_hardened_clay 8
setblock ~130 ~5 ~69 log2 0
setblock ~130 ~5 ~70 brown_glazed_terracotta 0
setblock ~130 ~5 ~71 log2 0
setblock ~130 ~5 ~72 gold_ore 0
setblock ~130 ~5 ~74 brown_glazed_terracotta 0
setblock ~130 ~5 ~76 stained_hardened_clay 8
setblock ~130 ~5 ~77 log2 0
setblock ~131 ~5 ~54 mycelium 0
setblock ~131 ~5 ~55 dirt 1
setblock ~131 ~5 ~56 brown_glazed_terracotta 0
setblock ~131 ~5 ~57 planks 1
setblock ~131 ~5 ~58 log2 0
setblock ~131 ~5 ~59 dirt 1
setblock ~131 ~5 ~60 mycelium 0
setblock ~131 ~5 ~61 dirt 1
setblock ~131 ~5 ~62 mycelium 0
setblock ~131 ~5 ~63 planks 1
setblock ~131 ~5 ~64 brown_glazed_terracotta 0
setblock ~131 ~5 ~65 planks 1
setblock ~131 ~5 ~66 brown_glazed_terracotta 0
setblock ~9 ~6 ~73 stained_hardened_clay 8
setblock ~9 ~6 ~74 mycelium 0
setblock ~9 ~6 ~75 brown_glazed_terracotta 0
setblock ~9 ~6 ~76 dirt 1
setblock ~9 ~6 ~77 stained_hardened_clay 8
setblock ~9 ~6 ~78 log2 0
setblock ~10 ~6 ~69 brown_glazed_terracotta 0
setblock ~10 ~6 ~70 stained_hardened_clay 8
setblock ~10 ~6 ~71 brown_glazed_terracotta 0
setblock ~10 ~6 ~72 stained_hardened_clay 8
setblock ~10 ~6 ~79 brown_glazed_terracotta 0
setblock ~10 ~6 ~80 stained_hardened_clay 8
setblock ~10 ~6 ~81 log2 0
setblock ~11 ~6 ~64 mycelium 0
setblock ~11 ~6 ~65 stained_hardened_clay 8
setblock ~11 ~6 ~66 log2 0
setblock ~11 ~6 ~67 stained_hardened_clay 8
fill ~11 ~6 ~68 ~11 ~7 ~68 log2 0
setblock ~11 ~6 ~82 mycelium 0
setblock ~12 ~6 ~61 brown_glazed_terracotta 0
setblock ~12 ~6 ~62 gold_ore 0
setblock ~12 ~6 ~63 brown_glazed_terracotta 0
setblock ~12 ~6 ~83 brown_glazed_terracotta 0
setblock ~13 ~6 ~57 stained_hardened_clay 8
setblock ~13 ~6 ~58 log2 0
setblock ~13 ~6 ~59 brown_glazed_terracotta 0
setblock ~13 ~6 ~84 log2 0
setblock ~14 ~6 ~52 gold_ore 0
setblock ~14 ~6 ~53 log2 0
setblock ~14 ~6 ~54 stained_hardened_clay 8
setblock ~14 ~6 ~55 brown_glazed_terracotta 0
setblock ~14 ~6 ~85 stained_hardened_clay 8
setblock ~15 ~6 ~48 mycelium 0
setblock ~15 ~6 ~49 stained_hardened_clay 8
setblock ~15 ~6 ~50 brown_glazed_terracotta 0
setblock ~15 ~6 ~51 stained_hardened_clay 8
setblock ~15 ~6 ~86 dirt 1
setblock ~16 ~6 ~45 brown_glazed_terracotta 0
setblock ~16 ~6 ~46 stained_hardened_clay 8
setblock ~16 ~6 ~47 brown_glazed_terracotta 0
setblock ~16 ~6 ~87 log2 0
setblock ~17 ~6 ~39 stained_hardened_clay 8
setblock ~17 ~6 ~41 brown_glazed_terracotta 0
setblock ~17 ~6 ~42 dirt 1
setblock ~17 ~6 ~43 stained_hardened_clay 8
fill ~17 ~6 ~44 ~17 ~7 ~44 brown_glazed_terracotta 0
setblock ~17 ~6 ~88 mycelium 0
fill ~18 ~6 ~35 ~18 ~6 ~37 brown_glazed_terracotta 0
fill ~18 ~6 ~38 ~18 ~7 ~38 stained_hardened_clay 8
setblock ~18 ~6 ~89 brown_glazed_terracotta 0
setblock ~19 ~6 ~32 log2 0
setblock ~19 ~6 ~33 brown_glazed_terracotta 0
setblock ~19 ~6 ~90 mycelium 0
setblock ~20 ~6 ~30 stained_hardened_clay 8
setblock ~20 ~6 ~31 brown_glazed_terracotta 0
setblock ~20 ~6 ~91 brown_glazed_terracotta 0
setblock ~21 ~6 ~28 log2 0
setblock ~21 ~6 ~29 brown_glazed_terracotta 0
setblock ~21 ~6 ~92 dirt 1
fill ~22 ~6 ~27 ~23 ~6 ~27 brown_glazed_terracotta 0
fill ~22 ~6 ~28 ~22 ~6 ~27 brown_glazed_terracotta 0
setblock ~22 ~6 ~93 log2 0
setblock ~23 ~6 ~26 mycelium 0
setblock ~23 ~6 ~94 log2 0
fill ~24 ~6 ~25 ~25 ~6 ~25 brown_glazed_terracotta 0
setblock ~24 ~6 ~26 stained_hardened_clay 8
setblock ~24 ~6 ~94 brown_glazed_terracotta 0
setblock ~25 ~6 ~24 log 3
setblock ~25 ~6 ~95 brown_glazed_terracotta 0
setblock ~26 ~6 ~23 log2 0
setblock ~26 ~6 ~24 brown_glazed_terracotta 0
setblock ~26 ~6 ~96 stained_hardened_clay 8
setblock ~27 ~6 ~22 mycelium 0
setblock ~27 ~6 ~23 brown_glazed_terracotta 0
setblock ~27 ~6 ~97 stained_hardened_clay 8
fill ~28 ~6 ~21 ~28 ~6 ~22 stained_hardened_clay 8
setblock ~28 ~6 ~98 stained_hardened_clay 8
setblock ~29 ~6 ~20 log2 0
setblock ~29 ~6 ~21 brown_glazed_terracotta 0
setblock ~29 ~6 ~98 log2 0
setblock ~30 ~6 ~20 gold_ore 0
fill ~30 ~6 ~99 ~31 ~6 ~99 stained_hardened_clay 8
setblock ~31 ~6 ~19 stained_hardened_clay 8
setblock ~32 ~6 ~18 gold_ore 0
fill ~32 ~6 ~99 ~32 ~8 ~99 brown_glazed_terracotta 0
setblock ~33 ~6 ~17 gold_ore 0
setblock ~34 ~6 ~16 stained_hardened_clay 8
setblock ~34 ~6 ~100 gold_ore 0
fill ~35 ~6 ~15 ~35 ~6 ~16 log2 0
setblock ~35 ~6 ~100 log2 0
setblock ~36 ~6 ~15 brown_glazed_terracotta 0
fill ~36 ~6 ~99 ~36 ~7 ~99 log2 0
setblock ~37 ~6 ~14 brown_glazed_terracotta 0
setblock ~37 ~6 ~99 stained_hardened_clay 8
fill ~38 ~6 ~13 ~38 ~6 ~14 stained_hardened_clay 8
setblock ~39 ~6 ~13 gold_ore 0
setblock ~39 ~6 ~98 mycelium 0
setblock ~40 ~6 ~12 gold_ore 0
setblock ~40 ~6 ~98 stained_hardened_clay 8
setblock ~41 ~6 ~12 log2 0
setblock ~41 ~6 ~98 brown_glazed_terracotta 0
setblock ~42 ~6 ~11 brown_mushroom_block 0
setblock ~42 ~6 ~98 stained_hardened_clay 8
setblock ~43 ~6 ~11 stained_hardened_clay 8
setblock ~43 ~6 ~98 log2 0
setblock ~44 ~6 ~10 gold_ore 0
setblock ~44 ~6 ~98 stained_hardened_clay 8
setblock ~45 ~6 ~10 log2 0
setblock ~45 ~6 ~99 stained_hardened_clay 8
setblock ~46 ~6 ~9 brown_glazed_terracotta 0
setblock ~46 ~6 ~10 stained_hardened_clay 8
setblock ~46 ~6 ~99 log2 0
setblock ~47 ~6 ~9 stained_hardened_clay 8
setblock ~48 ~6 ~9 brown_mushroom_block 0
setblock ~48 ~6 ~100 stained_hardened_clay 8
setblock ~49 ~6 ~8 log2 0
setblock ~49 ~6 ~100 dirt 1
setblock ~50 ~6 ~8 stained_hardened_clay 8
fill ~50 ~6 ~101 ~52 ~6 ~101 brown_glazed_terracotta 0
setblock ~51 ~6 ~8 brown_mushroom_block 0
setblock ~52 ~6 ~7 brown_glazed_terracotta 0
setblock ~53 ~6 ~7 stained_hardened_clay 8
setblock ~53 ~6 ~101 gold_ore 0
setblock ~54 ~6 ~7 brown_glazed_terracotta 0
setblock ~54 ~6 ~101 mycelium 0
setblock ~55 ~6 ~7 gold_ore 0
setblock ~56 ~6 ~6 gold_ore 0
setblock ~57 ~6 ~6 log2 0
setblock ~57 ~6 ~102 log2 0
setblock ~58 ~6 ~6 stained_hardened_clay 8
setblock ~58 ~6 ~102 stained_hardened_clay 8
setblock ~59 ~6 ~6 dirt 1
setblock ~59 ~6 ~102 mycelium 0
fill ~60 ~6 ~5 ~64 ~6 ~5 brown_glazed_terracotta 0
setblock ~60 ~6 ~6 stained_hardened_clay 8
setblock ~60 ~6 ~102 stained_hardened_clay 8
setblock ~62 ~6 ~102 log2 0
fill ~63 ~6 ~103 ~64 ~6 ~103 brown_glazed_terracotta 0
setblock ~65 ~6 ~5 stained_hardened_clay 8
setblock ~65 ~6 ~103 stained_hardened_clay 8
fill ~66 ~6 ~5 ~69 ~6 ~5 brown_glazed_terracotta 0
setblock ~66 ~6 ~103 brown_glazed_terracotta 0
setblock ~67 ~6 ~4 log2 0
setblock ~67 ~6 ~103 stained_hardened_clay 8
setblock ~68 ~6 ~4 stained_hardened_clay 8
setblock ~68 ~6 ~103 brown_glazed_terracotta 0
setblock ~69 ~6 ~4 dirt 1
setblock ~69 ~6 ~103 stained_hardened_clay 8
setblock ~70 ~6 ~4 brown_glazed_terracotta 0
setblock ~70 ~6 ~103 brown_glazed_terracotta 0
setblock ~71 ~6 ~4 log2 0
setblock ~71 ~6 ~104 log2 0
setblock ~72 ~6 ~4 stained_hardened_clay 8
fill ~72 ~6 ~104 ~73 ~6 ~104 brown_glazed_terracotta 0
setblock ~73 ~6 ~4 log2 0
setblock ~74 ~6 ~4 gold_ore 0
setblock ~74 ~6 ~104 gold_ore 0
setblock ~75 ~6 ~4 mycelium 0
setblock ~75 ~6 ~104 mycelium 0
setblock ~76 ~6 ~4 stained_hardened_clay 8
setblock ~76 ~6 ~104 brown_glazed_terracotta 0
setblock ~77 ~6 ~4 dirt 1
setblock ~78 ~6 ~4 brown_glazed_terracotta 0
setblock ~78 ~6 ~103 brown_glazed_terracotta 0
setblock ~79 ~6 ~4 dirt 1
setblock ~79 ~6 ~103 brown_mushroom_block 0
fill ~80 ~6 ~4 ~81 ~6 ~4 log2 0
fill ~80 ~6 ~5 ~80 ~6 ~4 log2 0
fill ~80 ~6 ~103 ~82 ~6 ~103 stained_hardened_clay 8
setblock ~81 ~6 ~5 stained_hardened_clay 8
setblock ~82 ~6 ~4 brown_glazed_terracotta 0
setblock ~82 ~6 ~5 log2 0
setblock ~83 ~6 ~5 brown_glazed_terracotta 0
setblock ~83 ~6 ~103 brown_mushroom_block 0
setblock ~84 ~6 ~5 log2 0
fill ~85 ~6 ~5 ~87 ~6 ~5 brown_glazed_terracotta 0
setblock ~85 ~6 ~103 stained_hardened_clay 8
setblock ~86 ~6 ~103 brown_glazed_terracotta 0
setblock ~87 ~6 ~103 stained_hardened_clay 8
setblock ~88 ~6 ~5 mycelium 0
setblock ~88 ~6 ~6 brown_glazed_terracotta 0
setblock ~88 ~6 ~103 brown_glazed_terracotta 0
setblock ~89 ~6 ~6 log2 0
setblock ~90 ~6 ~6 stained_hardened_clay 8
setblock ~90 ~6 ~104 gold_ore 0
setblock ~91 ~6 ~6 dirt 1
setblock ~91 ~6 ~104 log2 0
setblock ~92 ~6 ~7 brown_glazed_terracotta 0
setblock ~92 ~6 ~104 brown_mushroom_block 0
setblock ~93 ~6 ~7 stained_hardened_clay 8
setblock ~94 ~6 ~7 gold_ore 0
setblock ~94 ~6 ~104 stained_hardened_clay 8
setblock ~95 ~6 ~8 log2 0
setblock ~95 ~6 ~104 dirt 1
setblock ~96 ~6 ~8 brown_glazed_terracotta 0
setblock ~97 ~6 ~8 planks 1
fill ~97 ~6 ~104 ~97 ~5 ~104 brown_glazed_terracotta 0
fill ~98 ~6 ~9 ~99 ~6 ~9 brown_glazed_terracotta 0
setblock ~98 ~6 ~104 stained_hardened_clay 8
setblock ~99 ~6 ~103 gold_ore 0
fill ~100 ~6 ~9 ~101 ~6 ~9 stained_hardened_clay 8
setblock ~100 ~6 ~103 mycelium 0
setblock ~101 ~6 ~102 log2 0
setblock ~102 ~6 ~10 stained_hardened_clay 8
setblock ~102 ~6 ~101 brown_glazed_terracotta 0
setblock ~103 ~6 ~10 bookshelf 0
setblock ~103 ~6 ~100 dirt 1
setblock ~104 ~6 ~10 brown_glazed_terracotta 0
setblock ~104 ~6 ~99 log2 0
setblock ~105 ~6 ~10 mycelium 0
setblock ~105 ~6 ~11 log2 0
setblock ~105 ~6 ~98 mycelium 0
fill ~106 ~6 ~11 ~108 ~6 ~11 brown_glazed_terracotta 0
setblock ~106 ~6 ~96 gold_ore 0
setblock ~106 ~6 ~97 brown_glazed_terracotta 0
setblock ~107 ~6 ~95 stained_hardened_clay 8
setblock ~108 ~6 ~94 brown_glazed_terracotta 0
setblock ~109 ~6 ~12 log2 0
setblock ~109 ~6 ~93 gold_ore 0
setblock ~110 ~6 ~12 stained_hardened_clay 8
setblock ~110 ~6 ~13 log2 0
setblock ~110 ~6 ~93 stained_hardened_clay 8
setblock ~111 ~6 ~13 gold_ore 0
setblock ~111 ~6 ~92 dirt 1
setblock ~112 ~6 ~13 brown_glazed_terracotta 0
fill ~112 ~6 ~14 ~113 ~6 ~14 log2 0
fill ~112 ~6 ~92 ~112 ~5 ~92 brown_glazed_terracotta 0
setblock ~113 ~6 ~15 brown_glazed_terracotta 0
setblock ~113 ~6 ~91 gold_ore 0
setblock ~114 ~6 ~15 log2 0
setblock ~114 ~6 ~16 brown_glazed_terracotta 0
fill ~114 ~6 ~91 ~114 ~7 ~91 brown_glazed_terracotta 0
setblock ~115 ~6 ~16 dirt 1
setblock ~115 ~6 ~17 brown_glazed_terracotta 0
setblock ~115 ~6 ~91 stained_hardened_clay 8
setblock ~116 ~6 ~18 stained_hardened_clay 8
setblock ~116 ~6 ~19 brown_glazed_terracotta 0
setblock ~116 ~6 ~91 log2 0
setblock ~117 ~6 ~20 mycelium 0
setblock ~117 ~6 ~21 brown_glazed_terracotta 0
setblock ~117 ~6 ~22 dirt 1
fill ~117 ~6 ~91 ~118 ~6 ~91 brown_glazed_terracotta 0
setblock ~118 ~6 ~22 stained_hardened_clay 8
setblock ~118 ~6 ~23 log2 0
setblock ~118 ~6 ~24 stained_hardened_clay 8
setblock ~118 ~6 ~25 log2 0
setblock ~119 ~6 ~26 dirt 1
setblock ~119 ~6 ~27 stained_hardened_clay 8
setblock ~119 ~6 ~28 log2 0
setblock ~119 ~6 ~91 gold_ore 0
setblock ~120 ~6 ~28 stained_hardened_clay 8
setblock ~120 ~6 ~29 log2 0
setblock ~120 ~6 ~30 brown_glazed_terracotta 0
setblock ~120 ~6 ~90 gold_ore 0
setblock ~121 ~6 ~30 dirt 1
setblock ~121 ~6 ~31 brown_glazed_terracotta 0
setblock ~121 ~6 ~32 dirt 1
setblock ~121 ~6 ~90 mycelium 0
setblock ~122 ~6 ~32 stained_hardened_clay 8
setblock ~122 ~6 ~33 brown_glazed_terracotta 0
setblock ~122 ~6 ~90 gold_ore 0
setblock ~123 ~6 ~34 log2 0
setblock ~123 ~6 ~35 stained_hardened_clay 8
setblock ~123 ~6 ~90 log2 0
setblock ~124 ~6 ~36 gold_ore 0
setblock ~124 ~6 ~37 stained_hardened_clay 8
setblock ~124 ~6 ~89 log2 0
setblock ~125 ~6 ~38 log2 0
setblock ~125 ~6 ~39 brown_glazed_terracotta 0
setblock ~125 ~6 ~40 planks 1
setblock ~125 ~6 ~88 dirt 1
setblock ~126 ~6 ~40 brown_glazed_terracotta 0
setblock ~126 ~6 ~41 log2 0
setblock ~126 ~6 ~42 brown_glazed_terracotta 0
setblock ~126 ~6 ~87 brown_glazed_terracotta 0
setblock ~127 ~6 ~43 brown_glazed_terracotta 0
setblock ~127 ~6 ~44 dirt 1
setblock ~127 ~6 ~45 brown_glazed_terracotta 0
setblock ~127 ~6 ~85 gold_ore 0
setblock ~127 ~6 ~86 log2 0
setblock ~128 ~6 ~46 stained_hardened_clay 8
setblock ~128 ~6 ~47 brown_glazed_terracotta 0
fill ~128 ~6 ~48 ~128 ~6 ~49 stained_hardened_clay 8
fill ~128 ~6 ~79 ~128 ~6 ~80 stained_hardened_clay 8
setblock ~128 ~6 ~81 brown_glazed_terracotta 0
fill ~128 ~6 ~82 ~128 ~6 ~84 stained_hardened_clay 8
setblock ~129 ~6 ~49 brown_glazed_terracotta 0
setblock ~129 ~6 ~50 dirt 1
setblock ~129 ~6 ~51 gold_ore 0
setblock ~129 ~6 ~52 dirt 1
setblock ~129 ~6 ~53 brown_glazed_terracotta 0
setblock ~129 ~6 ~68 log2 0
setblock ~129 ~6 ~69 stained_hardened_clay 8
setblock ~129 ~6 ~70 mycelium 0
setblock ~129 ~6 ~71 stained_hardened_clay 8
setblock ~129 ~6 ~72 log2 0
setblock ~129 ~6 ~73 gold_ore 0
setblock ~129 ~6 ~74 log2 0
setblock ~129 ~6 ~75 brown_mushroom_block 0
setblock ~129 ~6 ~76 log2 0
setblock ~129 ~6 ~77 gold_ore 0
setblock ~129 ~6 ~78 brown_glazed_terracotta 0
setblock ~130 ~6 ~54 stained_hardened_clay 8
setblock ~130 ~6 ~55 brown_glazed_terracotta 0
setblock ~130 ~6 ~56 gold_ore 0
setblock ~130 ~6 ~57 brown_glazed_terracotta 0
setblock ~130 ~6 ~58 stained_hardened_clay 8
setblock ~130 ~6 ~59 log2 0
setblock ~130 ~6 ~60 gold_ore 0
setblock ~130 ~6 ~61 log2 0
setblock ~130 ~6 ~62 brown_glazed_terracotta 0
fill ~130 ~6 ~63 ~130 ~6 ~64 stained_hardened_clay 8
setblock ~130 ~6 ~65 brown_glazed_terracotta 0
fill ~130 ~6 ~66 ~130 ~6 ~67 stained_hardened_clay 8
fill ~10 ~7 ~72 ~10 ~7 ~73 log2 0
setblock ~10 ~7 ~74 brown_glazed_terracotta 0
fill ~10 ~7 ~75 ~10 ~7 ~76 log2 0
setblock ~10 ~7 ~77 mycelium 0
setblock ~10 ~7 ~78 brown_glazed_terracotta 0
setblock ~11 ~7 ~69 planks 1
setblock ~11 ~7 ~70 mycelium 0
setblock ~11 ~7 ~71 dirt 1
setblock ~11 ~7 ~79 planks 1
setblock ~11 ~7 ~80 mycelium 0
setblock ~11 ~7 ~81 planks 1
setblock ~12 ~7 ~63 log2 0
setblock ~12 ~7 ~64 stained_hardened_clay 8
setblock ~12 ~7 ~65 log2 0
fill ~12 ~7 ~66 ~12 ~7 ~67 brown_glazed_terracotta 0
setblock ~12 ~7 ~81 dirt 1
setblock ~12 ~7 ~82 stained_hardened_clay 8
setblock ~13 ~7 ~59 dirt 1
setblock ~13 ~7 ~60 brown_glazed_terracotta 0
setblock ~13 ~7 ~61 dirt 1
setblock ~13 ~7 ~62 log2 0
setblock ~13 ~7 ~83 dirt 1
setblock ~14 ~7 ~55 log2 0
setblock ~14 ~7 ~56 brown_glazed_terracotta 0
setblock ~14 ~7 ~57 mycelium 0
setblock ~14 ~7 ~58 brown_glazed_terracotta 0
setblock ~14 ~7 ~84 log2 0
setblock ~15 ~7 ~51 dirt 1
setblock ~15 ~7 ~52 brown_glazed_terracotta 0
setblock ~15 ~7 ~53 mycelium 0
setblock ~15 ~7 ~54 log2 0
setblock ~15 ~7 ~85 mycelium 0
setblock ~16 ~7 ~48 brown_glazed_terracotta 0
setblock ~16 ~7 ~49 mycelium 0
setblock ~16 ~7 ~50 brown_glazed_terracotta 0
setblock ~16 ~7 ~86 stained_hardened_clay 8
setblock ~17 ~7 ~45 planks 1
setblock ~17 ~7 ~46 brown_glazed_terracotta 0
setblock ~17 ~7 ~47 log2 0
setblock ~17 ~7 ~87 dirt 1
setblock ~18 ~7 ~39 log2 0
setblock ~18 ~7 ~40 stained_hardened_clay 8
setblock ~18 ~7 ~41 log2 0
setblock ~18 ~7 ~42 brown_glazed_terracotta 0
setblock ~18 ~7 ~43 dirt 1
setblock ~18 ~7 ~88 brown_glazed_terracotta 0
fill ~19 ~7 ~34 ~20 ~7 ~34 brown_glazed_terracotta 0
setblock ~19 ~7 ~35 dirt 1
setblock ~19 ~7 ~36 stained_hardened_clay 8
setblock ~19 ~7 ~37 dirt 1
setblock ~19 ~7 ~89 dirt 1
setblock ~20 ~7 ~32 brown_glazed_terracotta 0
setblock ~20 ~7 ~33 mycelium 0
setblock ~20 ~7 ~90 log2 0
fill ~21 ~7 ~30 ~22 ~7 ~30 log2 0
setblock ~21 ~7 ~31 log 3
setblock ~21 ~7 ~91 log 3
setblock ~22 ~7 ~29 log2 0
setblock ~22 ~7 ~92 brown_glazed_terracotta 0
setblock ~23 ~7 ~28 brown_glazed_terracotta 0
setblock ~23 ~7 ~93 planks 1
setblock ~24 ~7 ~27 brown_glazed_terracotta 0
setblock ~24 ~7 ~93 log2 0
setblock ~25 ~7 ~26 brown_glazed_terracotta 0
setblock ~25 ~7 ~94 dirt 1
setblock ~26 ~7 ~25 dirt 1
setblock ~26 ~7 ~95 log2 0
setblock ~27 ~7 ~24 log2 0
setblock ~27 ~7 ~96 mycelium 0
setblock ~28 ~7 ~23 log2 0
setblock ~28 ~7 ~97 log2 0
setblock ~29 ~7 ~22 brown_glazed_terracotta 0
setblock ~29 ~7 ~97 dirt 1
setblock ~30 ~7 ~21 brown_glazed_terracotta 0
setblock ~30 ~7 ~98 stained_hardened_clay 8
setblock ~31 ~7 ~20 log2 0
setblock ~31 ~7 ~99 dirt 1
fill ~32 ~7 ~19 ~33 ~7 ~19 log2 0
setblock ~32 ~7 ~20 gold_ore 0
setblock ~33 ~7 ~18 brown_glazed_terracotta 0
setblock ~33 ~7 ~99 dirt 1
fill ~34 ~7 ~17 ~35 ~7 ~17 brown_glazed_terracotta 0
setblock ~34 ~7 ~18 stained_hardened_clay 8
setblock ~34 ~7 ~99 brown_glazed_terracotta 0
setblock ~35 ~7 ~99 dirt 1
setblock ~36 ~7 ~16 brown_glazed_terracotta 0
setblock ~37 ~7 ~15 dirt 1
setblock ~37 ~7 ~99 planks 1
setblock ~38 ~7 ~15 log2 0
setblock ~38 ~7 ~99 dirt 1
setblock ~39 ~7 ~14 brown_glazed_terracotta 0
setblock ~39 ~7 ~98 stained_hardened_clay 8
setblock ~40 ~7 ~13 brown_glazed_terracotta 0
setblock ~40 ~7 ~14 stained_hardened_clay 8
fill ~40 ~7 ~98 ~41 ~7 ~98 log2 0
setblock ~41 ~7 ~13 log2 0
fill ~42 ~7 ~12 ~43 ~7 ~12 brown_glazed_terracotta 0
fill ~42 ~7 ~13 ~42 ~7 ~12 brown_glazed_terracotta 0
setblock ~42 ~7 ~97 log2 0
setblock ~43 ~7 ~97 mycelium 0
setblock ~44 ~7 ~11 log2 0
setblock ~44 ~7 ~12 brown_mushroom_block 0
setblock ~44 ~7 ~98 brown_glazed_terracotta 0
setblock ~45 ~7 ~11 mycelium 0
setblock ~45 ~7 ~98 log2 0
setblock ~46 ~7 ~11 log2 0
setblock ~46 ~7 ~98 brown_glazed_terracotta 0
setblock ~47 ~7 ~10 mycelium 0
setblock ~47 ~7 ~99 bookshelf 0
setblock ~48 ~7 ~10 stained_hardened_clay 8
setblock ~48 ~7 ~99 mycelium 0
fill ~49 ~7 ~9 ~50 ~7 ~9 log2 0
setblock ~49 ~7 ~10 brown_glazed_terracotta 0
setblock ~49 ~7 ~100 log2 0
fill ~50 ~7 ~100 ~51 ~7 ~100 brown_glazed_terracotta 0
fill ~51 ~7 ~9 ~52 ~7 ~9 planks 1
setblock ~52 ~7 ~8 brown_mushroom_block 0
fill ~52 ~7 ~100 ~52 ~8 ~100 stained_hardened_clay 8
setblock ~53 ~7 ~8 brown_glazed_terracotta 0
fill ~53 ~7 ~101 ~56 ~7 ~101 dirt 1
setblock ~54 ~7 ~8 gold_ore 0
setblock ~55 ~7 ~8 brown_glazed_terracotta 0
setblock ~56 ~7 ~7 log2 0
setblock ~57 ~7 ~7 mycelium 0
setblock ~57 ~7 ~101 mycelium 0
setblock ~58 ~7 ~7 log2 0
setblock ~58 ~7 ~101 log2 0
setblock ~59 ~7 ~7 dirt 1
setblock ~59 ~7 ~101 planks 1
setblock ~60 ~7 ~7 log2 0
setblock ~60 ~7 ~101 mycelium 0
setblock ~61 ~7 ~6 mycelium 0
setblock ~61 ~7 ~7 log 3
setblock ~61 ~7 ~101 planks 1
setblock ~62 ~7 ~6 brown_glazed_terracotta 0
setblock ~62 ~7 ~102 stained_hardened_clay 8
setblock ~63 ~7 ~6 log2 0
setblock ~63 ~7 ~103 log 3
setblock ~64 ~7 ~6 brown_glazed_terracotta 0
fill ~64 ~7 ~102 ~64 ~8 ~102 stained_hardened_clay 8
setblock ~65 ~7 ~6 mycelium 0
setblock ~65 ~7 ~103 dirt 1
setblock ~66 ~7 ~6 brown_glazed_terracotta 0
setblock ~66 ~7 ~103 log2 0
setblock ~67 ~7 ~6 log2 0
setblock ~67 ~7 ~103 log 0
setblock ~68 ~7 ~6 brown_glazed_terracotta 0
fill ~68 ~7 ~103 ~72 ~7 ~103 log2 0
setblock ~69 ~7 ~6 mycelium 0
setblock ~70 ~7 ~5 mycelium 0
setblock ~70 ~7 ~6 stained_hardened_clay 8
setblock ~71 ~7 ~5 planks 1
setblock ~71 ~7 ~6 brown_glazed_terracotta 0
fill ~72 ~7 ~5 ~72 ~7 ~6 log2 0
setblock ~73 ~7 ~5 planks 1
setblock ~73 ~7 ~6 log2 0
setblock ~73 ~7 ~103 bookshelf 0
setblock ~74 ~7 ~5 mycelium 0
setblock ~74 ~7 ~6 brown_glazed_terracotta 0
setblock ~74 ~7 ~103 brown_glazed_terracotta 0
fill ~75 ~7 ~5 ~76 ~7 ~5 log2 0
fill ~75 ~7 ~6 ~76 ~7 ~6 log2 0
setblock ~75 ~7 ~103 dirt 1
setblock ~76 ~7 ~103 log2 0
setblock ~77 ~7 ~5 planks 1
setblock ~77 ~7 ~6 mycelium 0
setblock ~77 ~7 ~103 dirt 1
setblock ~78 ~7 ~5 dirt 1
setblock ~78 ~7 ~6 brown_glazed_terracotta 0
setblock ~78 ~7 ~102 log2 0
setblock ~79 ~7 ~5 log 3
setblock ~79 ~7 ~6 log2 0
setblock ~79 ~7 ~102 brown_glazed_terracotta 0
setblock ~80 ~7 ~6 brown_glazed_terracotta 0
setblock ~80 ~7 ~102 brown_mushroom_block 0
setblock ~81 ~7 ~6 dirt 1
fill ~81 ~7 ~102 ~83 ~7 ~102 stained_hardened_clay 8
setblock ~82 ~7 ~6 brown_glazed_terracotta 0
setblock ~83 ~7 ~6 dirt 1
setblock ~84 ~7 ~6 brown_glazed_terracotta 0
setblock ~84 ~7 ~102 gold_ore 0
setblock ~85 ~7 ~6 mycelium 0
fill ~85 ~7 ~103 ~86 ~7 ~103 log2 0
setblock ~86 ~7 ~6 brown_glazed_terracotta 0
setblock ~87 ~7 ~6 log2 0
setblock ~87 ~7 ~7 dirt 1
setblock ~87 ~7 ~103 mycelium 0
setblock ~88 ~7 ~7 mycelium 0
setblock ~88 ~7 ~103 log2 0
setblock ~89 ~7 ~7 dirt 1
setblock ~89 ~7 ~103 dirt 1
setblock ~90 ~7 ~7 log2 0
fill ~90 ~7 ~103 ~90 ~8 ~103 brown_glazed_terracotta 0
setblock ~91 ~7 ~7 planks 1
fill ~91 ~7 ~8 ~92 ~7 ~8 log2 0
setblock ~91 ~7 ~103 planks 1
setblock ~92 ~7 ~103 brown_glazed_terracotta 0
fill ~93 ~7 ~8 ~94 ~7 ~8 brown_mushroom_block 0
setblock ~93 ~7 ~104 log2 0
setblock ~94 ~7 ~9 log2 0
setblock ~94 ~7 ~104 brown_mushroom_block 0
fill ~95 ~7 ~9 ~96 ~7 ~9 log 3
setblock ~95 ~7 ~103 planks 1
setblock ~96 ~7 ~103 mycelium 0
setblock ~97 ~7 ~9 planks 1
setblock ~97 ~7 ~10 log2 0
fill ~97 ~7 ~103 ~98 ~7 ~103 log2 0
setblock ~98 ~7 ~10 brown_glazed_terracotta 0
setblock ~99 ~7 ~10 mycelium 0
setblock ~99 ~7 ~102 brown_glazed_terracotta 0
setblock ~100 ~7 ~10 brown_glazed_terracotta 0
setblock ~100 ~7 ~102 brown_mushroom_block 0
setblock ~101 ~7 ~10 log2 0
setblock ~101 ~7 ~11 mycelium 0
setblock ~101 ~7 ~101 dirt 1
setblock ~102 ~7 ~11 dirt 1
setblock ~102 ~7 ~100 brown_glazed_terracotta 0
setblock ~103 ~7 ~11 soul_sand 0
setblock ~103 ~7 ~99 log 3
setblock ~104 ~7 ~11 mycelium 0
setblock ~104 ~7 ~98 brown_glazed_terracotta 0
setblock ~105 ~7 ~12 mycelium 0
setblock ~105 ~7 ~97 dirt 1
fill ~106 ~7 ~12 ~107 ~7 ~12 log2 0
setblock ~106 ~7 ~95 log2 0
setblock ~106 ~7 ~96 brown_glazed_terracotta 0
setblock ~107 ~7 ~94 log2 0
setblock ~108 ~7 ~12 brown_glazed_terracotta 0
setblock ~108 ~7 ~13 planks 1
fill ~108 ~7 ~93 ~108 ~8 ~93 log2 0
setblock ~109 ~7 ~13 dirt 1
setblock ~109 ~7 ~93 mycelium 0
setblock ~110 ~7 ~14 gold_ore 0
setblock ~110 ~7 ~92 brown_glazed_terracotta 0
setblock ~111 ~7 ~14 log2 0
setblock ~111 ~7 ~15 planks 1
setblock ~111 ~7 ~92 log2 0
setblock ~112 ~7 ~15 log2 0
setblock ~112 ~7 ~91 log2 0
setblock ~113 ~7 ~16 brown_glazed_terracotta 0
setblock ~113 ~7 ~91 dirt 1
setblock ~114 ~7 ~17 mycelium 0
fill ~114 ~7 ~18 ~115 ~7 ~18 stained_hardened_clay 8
setblock ~115 ~7 ~19 log2 0
setblock ~115 ~7 ~91 dirt 1
setblock ~116 ~7 ~20 stained_hardened_clay 8
setblock ~116 ~7 ~21 brown_glazed_terracotta 0
setblock ~116 ~7 ~22 log2 0
setblock ~116 ~7 ~91 mycelium 0
setblock ~117 ~7 ~23 dirt 1
setblock ~117 ~7 ~24 log2 0
setblock ~117 ~7 ~25 dirt 1
setblock ~117 ~7 ~90 log2 0
setblock ~118 ~7 ~26 stained_hardened_clay 8
fill ~118 ~7 ~27 ~118 ~7 ~28 brown_glazed_terracotta 0
setblock ~118 ~7 ~90 brown_glazed_terracotta 0
setblock ~119 ~7 ~29 soul_sand 0
setblock ~119 ~7 ~30 mycelium 0
setblock ~119 ~7 ~90 stained_hardened_clay 8
setblock ~120 ~7 ~31 mycelium 0
setblock ~120 ~7 ~32 stained_hardened_clay 8
fill ~120 ~7 ~90 ~122 ~7 ~90 brown_glazed_terracotta 0
setblock ~121 ~7 ~33 log 3
setblock ~121 ~7 ~34 log2 0
setblock ~122 ~7 ~34 brown_glazed_terracotta 0
fill ~122 ~7 ~35 ~122 ~7 ~36 stained_hardened_clay 8
setblock ~123 ~7 ~36 brown_glazed_terracotta 0
setblock ~123 ~7 ~37 mycelium 0
setblock ~123 ~7 ~38 log2 0
setblock ~123 ~7 ~89 dirt 1
setblock ~124 ~7 ~38 brown_glazed_terracotta 0
setblock ~124 ~7 ~39 log2 0
setblock ~124 ~7 ~40 brown_glazed_terracotta 0
setblock ~124 ~7 ~88 brown_glazed_terracotta 0
setblock ~125 ~7 ~41 planks 1
setblock ~125 ~7 ~42 log2 0
setblock ~125 ~7 ~43 dirt 1
setblock ~125 ~7 ~87 log2 0
setblock ~126 ~7 ~43 log2 0
setblock ~126 ~7 ~44 brown_glazed_terracotta 0
setblock ~126 ~7 ~45 dirt 1
setblock ~126 ~7 ~85 brown_glazed_terracotta 0
setblock ~126 ~7 ~86 stained_hardened_clay 8
setblock ~127 ~7 ~46 log2 0
setblock ~127 ~7 ~47 log 3
fill ~127 ~7 ~48 ~127 ~7 ~49 dirt 1
setblock ~127 ~7 ~80 brown_glazed_terracotta 0
setblock ~127 ~7 ~81 dirt 1
setblock ~127 ~7 ~82 brown_mushroom_block 0
setblock ~127 ~7 ~83 dirt 1
setblock ~127 ~7 ~84 log2 0
setblock ~128 ~7 ~50 log2 0
setblock ~128 ~7 ~51 dirt 1
setblock ~128 ~7 ~52 log2 0
setblock ~128 ~7 ~53 log 3
setblock ~128 ~7 ~54 brown_glazed_terracotta 0
fill ~128 ~7 ~68 ~128 ~7 ~71 brown_glazed_terracotta 0
setblock ~128 ~7 ~72 stained_hardened_clay 8
setblock ~128 ~7 ~73 brown_glazed_terracotta 0
setblock ~128 ~7 ~74 stained_hardened_clay 8
setblock ~128 ~7 ~75 brown_glazed_terracotta 0
setblock ~128 ~7 ~76 stained_hardened_clay 8
setblock ~128 ~7 ~77 log2 0
setblock ~128 ~7 ~78 brown_glazed_terracotta 0
setblock ~128 ~7 ~79 log2 0
setblock ~129 ~7 ~54 mycelium 0
setblock ~129 ~7 ~55 dirt 1
setblock ~129 ~7 ~56 brown_glazed_terracotta 0
setblock ~129 ~7 ~57 dirt 1
setblock ~129 ~7 ~58 log2 0
setblock ~129 ~7 ~59 dirt 1
setblock ~129 ~7 ~60 brown_mushroom_block 0
setblock ~129 ~7 ~61 dirt 1
setblock ~129 ~7 ~62 brown_glazed_terracotta 0
setblock ~129 ~7 ~63 dirt 1
setblock ~129 ~7 ~64 log2 0
setblock ~129 ~7 ~65 mycelium 0
setblock ~129 ~7 ~66 log2 0
setblock ~129 ~7 ~67 dirt 1
setblock ~11 ~8 ~72 dirt 1
setblock ~11 ~8 ~73 brown_glazed_terracotta 0
setblock ~11 ~8 ~74 log 3
setblock ~11 ~8 ~75 gold_ore 0
setblock ~11 ~8 ~76 log 3
setblock ~11 ~8 ~77 brown_glazed_terracotta 0
setblock ~11 ~8 ~78 soul_sand 0
fill ~12 ~8 ~67 ~12 ~8 ~68 stained_hardened_clay 8
setblock ~12 ~8 ~69 log2 0
setblock ~12 ~8 ~70 brown_glazed_terracotta 0
setblock ~12 ~8 ~71 stained_hardened_clay 8
setblock ~12 ~8 ~78 brown_glazed_terracotta 0
setblock ~12 ~8 ~79 log2 0
setblock ~12 ~8 ~80 brown_glazed_terracotta 0
setblock ~13 ~8 ~63 log2 0
setblock ~13 ~8 ~64 mycelium 0
setblock ~13 ~8 ~65 brown_glazed_terracotta 0
setblock ~13 ~8 ~66 log2 0
setblock ~13 ~8 ~81 brown_glazed_terracotta 0
setblock ~13 ~8 ~82 planks 1
setblock ~14 ~8 ~59 log2 0
setblock ~14 ~8 ~60 stained_hardened_clay 8
setblock ~14 ~8 ~61 brown_glazed_terracotta 0
setblock ~14 ~8 ~62 gold_ore 0
setblock ~14 ~8 ~82 stained_hardened_clay 8
setblock ~14 ~8 ~83 log2 0
setblock ~15 ~8 ~55 brown_glazed_terracotta 0
setblock ~15 ~8 ~56 log2 0
setblock ~15 ~8 ~57 brown_glazed_terracotta 0
setblock ~15 ~8 ~58 dirt 1
setblock ~15 ~8 ~84 planks 1
setblock ~16 ~8 ~51 brown_glazed_terracotta 0
setblock ~16 ~8 ~52 stained_hardened_clay 8
setblock ~16 ~8 ~53 log2 0
setblock ~16 ~8 ~54 brown_glazed_terracotta 0
setblock ~16 ~8 ~85 log2 0
setblock ~17 ~8 ~47 gold_ore 0
setblock ~17 ~8 ~48 log2 0
setblock ~17 ~8 ~49 gold_ore 0
setblock ~17 ~8 ~50 log2 0
setblock ~17 ~8 ~86 dirt 1
setblock ~18 ~8 ~43 brown_glazed_terracotta 0
setblock ~18 ~8 ~44 stained_hardened_clay 8
setblock ~18 ~8 ~45 log2 0
setblock ~18 ~8 ~46 stained_hardened_clay 8
setblock ~18 ~8 ~87 log2 0
setblock ~19 ~8 ~38 mycelium 0
setblock ~19 ~8 ~39 brown_glazed_terracotta 0
setblock ~19 ~8 ~40 mycelium 0
setblock ~19 ~8 ~41 brown_mushroom_block 0
setblock ~19 ~8 ~42 dirt 1
setblock ~19 ~8 ~88 mycelium 0
setblock ~20 ~8 ~35 brown_glazed_terracotta 0
setblock ~20 ~8 ~36 stained_hardened_clay 8
setblock ~20 ~8 ~37 log2 0
setblock ~20 ~8 ~89 mycelium 0
setblock ~21 ~8 ~32 log2 0
setblock ~21 ~8 ~33 stained_hardened_clay 8
setblock ~21 ~8 ~34 log2 0
setblock ~21 ~8 ~90 log 3
fill ~22 ~8 ~31 ~23 ~8 ~31 stained_hardened_clay 8
setblock ~22 ~8 ~32 gold_ore 0
fill ~22 ~8 ~90 ~22 ~8 ~91 brown_glazed_terracotta 0
fill ~23 ~8 ~29 ~24 ~8 ~29 brown_glazed_terracotta 0
setblock ~23 ~8 ~30 log2 0
setblock ~23 ~8 ~91 stained_hardened_clay 8
setblock ~23 ~8 ~92 log2 0
setblock ~24 ~8 ~28 stained_hardened_clay 8
setblock ~24 ~8 ~92 stained_hardened_clay 8
setblock ~25 ~8 ~27 brown_glazed_terracotta 0
setblock ~25 ~8 ~28 mycelium 0
setblock ~25 ~8 ~93 brown_glazed_terracotta 0
setblock ~26 ~8 ~26 stained_hardened_clay 8
setblock ~26 ~8 ~27 log2 0
setblock ~26 ~8 ~94 brown_glazed_terracotta 0
setblock ~27 ~8 ~25 log2 0
setblock ~27 ~8 ~26 dirt 1
setblock ~27 ~8 ~95 brown_glazed_terracotta 0
setblock ~28 ~8 ~24 brown_glazed_terracotta 0
setblock ~28 ~8 ~25 dirt 1
setblock ~28 ~8 ~96 gold_ore 0
fill ~29 ~8 ~23 ~30 ~8 ~23 brown_glazed_terracotta 0
setblock ~29 ~8 ~24 planks 1
setblock ~29 ~8 ~97 stained_hardened_clay 8
setblock ~30 ~8 ~22 gold_ore 0
setblock ~30 ~8 ~97 brown_glazed_terracotta 0
setblock ~31 ~8 ~21 stained_hardened_clay 8
setblock ~31 ~8 ~22 mycelium 0
setblock ~31 ~8 ~98 log2 0
setblock ~32 ~8 ~21 brown_glazed_terracotta 0
setblock ~33 ~8 ~20 dirt 1
fill ~33 ~8 ~99 ~35 ~8 ~99 stained_hardened_clay 8
setblock ~34 ~8 ~19 stained_hardened_clay 8
setblock ~35 ~8 ~18 log2 0
setblock ~36 ~8 ~17 log2 0
setblock ~36 ~8 ~18 gold_ore 0
fill ~36 ~8 ~99 ~38 ~8 ~99 brown_glazed_terracotta 0
fill ~37 ~8 ~16 ~39 ~8 ~16 log2 0
setblock ~37 ~8 ~17 stained_hardened_clay 8
setblock ~39 ~8 ~15 gold_ore 0
setblock ~39 ~8 ~98 dirt 1
setblock ~40 ~8 ~15 brown_glazed_terracotta 0
setblock ~40 ~8 ~98 stained_hardened_clay 8
setblock ~41 ~8 ~14 mycelium 0
fill ~41 ~8 ~97 ~45 ~8 ~97 brown_glazed_terracotta 0
setblock ~42 ~8 ~14 gold_ore 0
setblock ~43 ~8 ~13 stained_hardened_clay 8
setblock ~44 ~8 ~13 brown_glazed_terracotta 0
setblock ~45 ~8 ~12 log2 0
setblock ~46 ~8 ~12 stained_hardened_clay 8
setblock ~46 ~8 ~98 stained_hardened_clay 8
setblock ~47 ~8 ~11 stained_hardened_clay 8
setblock ~47 ~8 ~12 dirt 1
setblock ~47 ~8 ~98 dirt 1
fill ~48 ~8 ~11 ~49 ~8 ~11 brown_glazed_terracotta 0
setblock ~48 ~8 ~99 log2 0
fill ~49 ~8 ~99 ~50 ~8 ~99 brown_glazed_terracotta 0
setblock ~50 ~8 ~10 stained_hardened_clay 8
setblock ~51 ~8 ~10 log2 0
setblock ~51 ~8 ~100 log2 0
setblock ~52 ~8 ~10 gold_ore 0
setblock ~53 ~8 ~9 brown_mushroom_block 0
setblock ~53 ~8 ~100 log2 0
fill ~54 ~8 ~9 ~56 ~8 ~9 brown_glazed_terracotta 0
setblock ~54 ~8 ~100 brown_glazed_terracotta 0
setblock ~55 ~8 ~100 dirt 1
setblock ~56 ~8 ~8 gold_ore 0
setblock ~56 ~8 ~101 log2 0
setblock ~57 ~8 ~8 dirt 1
setblock ~57 ~8 ~9 log2 0
fill ~57 ~8 ~101 ~58 ~8 ~101 brown_glazed_terracotta 0
setblock ~58 ~8 ~8 brown_glazed_terracotta 0
setblock ~59 ~8 ~8 dirt 1
fill ~59 ~8 ~101 ~60 ~8 ~101 log2 0
setblock ~60 ~8 ~8 gold_ore 0
setblock ~61 ~8 ~8 dirt 1
setblock ~61 ~8 ~101 brown_glazed_terracotta 0
setblock ~62 ~8 ~7 log2 0
setblock ~62 ~8 ~8 gold_ore 0
fill ~62 ~8 ~101 ~62 ~9 ~101 log2 0
setblock ~63 ~8 ~7 stained_hardened_clay 8
setblock ~63 ~8 ~8 mycelium 0
setblock ~63 ~8 ~102 log2 0
setblock ~64 ~8 ~7 mycelium 0
setblock ~64 ~8 ~8 stained_hardened_clay 8
fill ~65 ~8 ~7 ~66 ~8 ~7 brown_glazed_terracotta 0
setblock ~65 ~8 ~8 planks 1
setblock ~65 ~8 ~102 log2 0
setblock ~66 ~8 ~8 gold_ore 0
setblock ~66 ~8 ~102 stained_hardened_clay 8
setblock ~67 ~8 ~7 stained_hardened_clay 8
setblock ~67 ~8 ~8 mycelium 0
setblock ~67 ~8 ~102 log2 0
setblock ~68 ~8 ~7 mycelium 0
setblock ~68 ~8 ~102 gold_ore 0
setblock ~69 ~8 ~7 log2 0
setblock ~69 ~8 ~102 dirt 1
setblock ~70 ~8 ~7 brown_glazed_terracotta 0
fill ~70 ~8 ~102 ~70 ~9 ~102 gold_ore 0
setblock ~71 ~8 ~7 stained_hardened_clay 8
fill ~71 ~8 ~102 ~71 ~9 ~102 log2 0
setblock ~72 ~8 ~7 brown_glazed_terracotta 0
setblock ~72 ~8 ~102 gold_ore 0
fill ~73 ~8 ~7 ~75 ~8 ~7 stained_hardened_clay 8
setblock ~73 ~8 ~102 brown_glazed_terracotta 0
fill ~74 ~8 ~102 ~74 ~9 ~102 stained_hardened_clay 8
setblock ~75 ~8 ~102 brown_glazed_terracotta 0
setblock ~76 ~8 ~7 mycelium 0
setblock ~76 ~8 ~102 stained_hardened_clay 8
setblock ~77 ~8 ~7 brown_glazed_terracotta 0
fill ~77 ~8 ~102 ~77 ~9 ~102 brown_glazed_terracotta 0
setblock ~78 ~8 ~7 mycelium 0
setblock ~78 ~8 ~102 stained_hardened_clay 8
setblock ~79 ~8 ~7 brown_glazed_terracotta 0
setblock ~79 ~8 ~102 log2 0
setblock ~80 ~8 ~7 dirt 1
setblock ~80 ~8 ~102 gold_ore 0
setblock ~81 ~8 ~7 brown_glazed_terracotta 0
setblock ~81 ~8 ~102 log2 0
setblock ~82 ~8 ~7 mycelium 0
setblock ~82 ~8 ~102 stained_hardened_clay 8
setblock ~83 ~8 ~7 brown_glazed_terracotta 0
setblock ~83 ~8 ~102 log2 0
fill ~84 ~8 ~7 ~85 ~8 ~7 mycelium 0
setblock ~84 ~8 ~8 brown_glazed_terracotta 0
fill ~84 ~8 ~102 ~84 ~9 ~102 stained_hardened_clay 8
setblock ~85 ~8 ~8 dirt 1
fill ~85 ~8 ~102 ~85 ~9 ~102 log2 0
setblock ~86 ~8 ~7 log2 0
setblock ~86 ~8 ~8 brown_glazed_terracotta 0
setblock ~86 ~8 ~102 gold_ore 0
setblock ~87 ~8 ~8 dirt 1
setblock ~87 ~8 ~102 bookshelf 0
setblock ~88 ~8 ~8 brown_glazed_terracotta 0
setblock ~88 ~8 ~103 brown_glazed_terracotta 0
setblock ~89 ~8 ~8 mycelium 0
setblock ~89 ~8 ~103 stained_hardened_clay 8
setblock ~90 ~8 ~8 stained_hardened_clay 8
setblock ~90 ~8 ~9 log2 0
fill ~91 ~8 ~9 ~93 ~8 ~9 brown_glazed_terracotta 0
setblock ~91 ~8 ~103 gold_ore 0
setblock ~92 ~8 ~103 stained_hardened_clay 8
setblock ~93 ~8 ~10 log 3
setblock ~93 ~8 ~103 gold_ore 0
setblock ~94 ~8 ~10 brown_glazed_terracotta 0
setblock ~94 ~8 ~103 brown_glazed_terracotta 0
setblock ~95 ~8 ~10 mycelium 0
setblock ~95 ~8 ~103 gold_ore 0
setblock ~96 ~8 ~10 brown_glazed_terracotta 0
setblock ~96 ~8 ~11 log2 0
setblock ~96 ~8 ~103 brown_glazed_terracotta 0
setblock ~97 ~8 ~11 stained_hardened_clay 8
setblock ~97 ~8 ~102 dirt 1
setblock ~98 ~8 ~11 log2 0
setblock ~98 ~8 ~102 brown_glazed_terracotta 0
setblock ~99 ~8 ~11 brown_glazed_terracotta 0
fill ~99 ~8 ~101 ~100 ~8 ~101 brown_glazed_terracotta 0
setblock ~100 ~8 ~11 log2 0
setblock ~100 ~8 ~12 brown_glazed_terracotta 0
setblock ~101 ~8 ~12 mycelium 0
setblock ~101 ~8 ~100 log2 0
setblock ~102 ~8 ~12 brown_glazed_terracotta 0
setblock ~102 ~8 ~99 brown_glazed_terracotta 0
setblock ~103 ~8 ~12 dirt 1
setblock ~103 ~8 ~98 dirt 1
setblock ~104 ~8 ~12 brown_glazed_terracotta 0
fill ~104 ~8 ~13 ~105 ~8 ~13 log2 0
setblock ~104 ~8 ~97 mycelium 0
setblock ~105 ~8 ~95 brown_glazed_terracotta 0
setblock ~105 ~8 ~96 dirt 1
setblock ~106 ~8 ~13 brown_glazed_terracotta 0
setblock ~106 ~8 ~94 brown_glazed_terracotta 0
setblock ~107 ~8 ~13 mycelium 0
setblock ~107 ~8 ~14 planks 1
setblock ~107 ~8 ~93 gold_ore 0
setblock ~108 ~8 ~14 brown_glazed_terracotta 0
setblock ~109 ~8 ~14 log2 0
setblock ~109 ~8 ~15 brown_glazed_terracotta 0
setblock ~109 ~8 ~92 brown_glazed_terracotta 0
setblock ~110 ~8 ~15 stained_hardened_clay 8
setblock ~110 ~8 ~91 brown_glazed_terracotta 0
setblock ~111 ~8 ~16 mycelium 0
setblock ~111 ~8 ~91 stained_hardened_clay 8
setblock ~112 ~8 ~16 stained_hardened_clay 8
fill ~112 ~8 ~17 ~113 ~8 ~17 brown_glazed_terracotta 0
setblock ~112 ~8 ~91 mycelium 0
setblock ~113 ~8 ~18 log2 0
setblock ~113 ~8 ~19 stained_hardened_clay 8
setblock ~113 ~8 ~90 dirt 1
setblock ~114 ~8 ~19 log2 0
setblock ~114 ~8 ~20 brown_glazed_terracotta 0
setblock ~114 ~8 ~90 stained_hardened_clay 8
setblock ~115 ~8 ~20 mycelium 0
setblock ~115 ~8 ~21 brown_glazed_terracotta 0
setblock ~115 ~8 ~22 mycelium 0
setblock ~115 ~8 ~23 gold_ore 0
setblock ~115 ~8 ~90 planks 1
setblock ~116 ~8 ~23 log2 0
setblock ~116 ~8 ~24 brown_glazed_terracotta 0
setblock ~116 ~8 ~25 stained_hardened_clay 8
fill ~116 ~8 ~90 ~116 ~9 ~90 brown_glazed_terracotta 0
setblock ~117 ~8 ~26 log2 0
setblock ~117 ~8 ~27 stained_hardened_clay 8
setblock ~117 ~8 ~28 log2 0
setblock ~117 ~8 ~29 brown_mushroom_block 0
setblock ~117 ~8 ~90 mycelium 0
setblock ~118 ~8 ~29 brown_glazed_terracotta 0
setblock ~118 ~8 ~30 stained_hardened_clay 8
setblock ~118 ~8 ~31 brown_glazed_terracotta 0
setblock ~118 ~8 ~90 brown_mushroom_block 0
setblock ~119 ~8 ~31 stained_hardened_clay 8
setblock ~119 ~8 ~32 planks 1
fill ~119 ~8 ~33 ~120 ~8 ~33 brown_glazed_terracotta 0
setblock ~119 ~8 ~90 mycelium 0
setblock ~120 ~8 ~34 brown_glazed_terracotta 0
setblock ~120 ~8 ~90 gold_ore 0
setblock ~121 ~8 ~35 stained_hardened_clay 8
setblock ~121 ~8 ~36 dirt 1
setblock ~121 ~8 ~90 log2 0
setblock ~122 ~8 ~37 brown_glazed_terracotta 0
setblock ~122 ~8 ~38 stained_hardened_clay 8
setblock ~122 ~8 ~89 brown_glazed_terracotta 0
setblock ~123 ~8 ~39 brown_glazed_terracotta 0
setblock ~123 ~8 ~40 dirt 1
fill ~123 ~8 ~41 ~124 ~8 ~41 brown_glazed_terracotta 0
setblock ~123 ~8 ~88 brown_glazed_terracotta 0
fill ~124 ~8 ~42 ~124 ~8 ~43 brown_glazed_terracotta 0
setblock ~124 ~8 ~87 brown_mushroom_block 0
setblock ~125 ~8 ~44 planks 1
setblock ~125 ~8 ~45 brown_glazed_terracotta 0
setblock ~125 ~8 ~46 dirt 1
setblock ~125 ~8 ~84 log2 0
