fill ~61 ~0 ~71 ~62 ~0 ~71 obsidian 0
fill ~61 ~0 ~72 ~64 ~0 ~72 obsidian 0
fill ~61 ~0 ~73 ~64 ~0 ~73 obsidian 0
fill ~61 ~0 ~74 ~64 ~0 ~74 obsidian 0
fill ~59 ~1 ~73 ~67 ~1 ~73 concrete 11
fill ~60 ~1 ~70 ~64 ~1 ~70 obsidian 0
fill ~60 ~1 ~71 ~61 ~1 ~71 obsidian 0
fill ~60 ~1 ~74 ~64 ~1 ~74 obsidian 0
fill ~60 ~1 ~75 ~64 ~1 ~75 obsidian 0
setblock ~61 ~1 ~69 obsidian 0
fill ~61 ~1 ~72 ~64 ~1 ~72 obsidian 0
fill ~63 ~1 ~71 ~64 ~1 ~71 obsidian 0
fill ~53 ~2 ~74 ~71 ~2 ~74 concrete 11
fill ~55 ~2 ~73 ~58 ~2 ~73 concrete 11
fill ~56 ~2 ~72 ~69 ~2 ~72 concrete 11
fill ~58 ~2 ~71 ~66 ~2 ~71 concrete 11
fill ~60 ~2 ~67 ~60 ~4 ~67 obsidian 0
fill ~60 ~2 ~68 ~63 ~2 ~68 obsidian 0
fill ~60 ~2 ~69 ~60 ~2 ~67 obsidian 0
fill ~60 ~2 ~76 ~64 ~2 ~76 obsidian 0
fill ~61 ~2 ~70 ~64 ~2 ~70 obsidian 0
fill ~61 ~2 ~75 ~64 ~2 ~75 obsidian 0
fill ~62 ~2 ~69 ~64 ~2 ~69 obsidian 0
fill ~68 ~2 ~73 ~71 ~2 ~73 concrete 11
fill ~50 ~3 ~75 ~64 ~3 ~75 concrete 11
fill ~50 ~3 ~76 ~51 ~3 ~76 concrete 11
setblock ~51 ~3 ~74 wool 11
fill ~52 ~3 ~73 ~54 ~3 ~73 concrete 11
fill ~52 ~3 ~74 ~52 ~3 ~73 concrete 11
setblock ~53 ~3 ~72 wool 11
fill ~54 ~3 ~71 ~57 ~3 ~71 concrete 11
fill ~54 ~3 ~72 ~55 ~3 ~72 concrete 11
setblock ~56 ~3 ~70 concrete 11
setblock ~57 ~3 ~70 wool 11
setblock ~57 ~3 ~74 wool 11
fill ~58 ~3 ~69 ~63 ~3 ~69 concrete 11
fill ~58 ~3 ~70 ~58 ~3 ~69 concrete 11
setblock ~58 ~3 ~74 concrete 11
setblock ~59 ~3 ~70 wool 11
fill ~59 ~3 ~73 ~66 ~3 ~73 concrete 11
setblock ~59 ~3 ~74 wool 11
fill ~60 ~3 ~66 ~62 ~3 ~66 obsidian 0
fill ~60 ~3 ~68 ~64 ~3 ~68 obsidian 0
setblock ~60 ~3 ~70 concrete 11
setblock ~60 ~3 ~74 concrete 11
fill ~60 ~3 ~76 ~64 ~3 ~76 obsidian 0
fill ~60 ~3 ~77 ~64 ~3 ~77 obsidian 0
fill ~61 ~3 ~67 ~63 ~3 ~67 obsidian 0
setblock ~61 ~3 ~70 wool 11
setblock ~61 ~3 ~74 wool 11
setblock ~62 ~3 ~70 concrete 11
setblock ~62 ~3 ~74 concrete 11
setblock ~63 ~3 ~70 wool 11
setblock ~63 ~3 ~74 wool 11
setblock ~64 ~3 ~70 concrete 11
fill ~64 ~3 ~74 ~64 ~4 ~74 concrete 11
setblock ~65 ~3 ~70 wool 11
setblock ~65 ~3 ~74 wool 11
setblock ~66 ~3 ~70 concrete 11
fill ~66 ~3 ~74 ~66 ~4 ~74 concrete 11
setblock ~67 ~3 ~70 wool 11
fill ~67 ~3 ~71 ~70 ~3 ~71 concrete 11
setblock ~67 ~3 ~74 wool 11
setblock ~68 ~3 ~74 concrete 11
setblock ~69 ~3 ~74 wool 11
fill ~70 ~3 ~72 ~71 ~3 ~72 concrete 11
fill ~70 ~3 ~75 ~71 ~3 ~75 concrete 11
fill ~72 ~3 ~73 ~73 ~3 ~73 concrete 11
fill ~72 ~3 ~74 ~72 ~3 ~73 concrete 11
setblock ~73 ~3 ~74 wool 11
fill ~74 ~3 ~74 ~74 ~4 ~74 concrete 11
fill ~47 ~4 ~76 ~49 ~4 ~76 concrete 11
fill ~47 ~4 ~77 ~50 ~4 ~77 concrete 11
fill ~48 ~4 ~75 ~49 ~4 ~75 concrete 11
fill ~49 ~4 ~73 ~51 ~4 ~73 concrete 11
fill ~49 ~4 ~74 ~50 ~4 ~74 concrete 11
fill ~50 ~4 ~72 ~52 ~4 ~72 concrete 11
fill ~51 ~4 ~71 ~53 ~4 ~71 concrete 11
fill ~51 ~4 ~76 ~69 ~4 ~76 concrete 11
fill ~52 ~4 ~70 ~55 ~4 ~70 concrete 11
fill ~52 ~4 ~75 ~54 ~4 ~75 concrete 11
fill ~53 ~4 ~74 ~56 ~4 ~74 concrete 11
fill ~54 ~4 ~69 ~57 ~4 ~69 concrete 11
fill ~54 ~4 ~73 ~64 ~4 ~73 concrete 11
fill ~56 ~4 ~68 ~65 ~4 ~68 concrete 11
fill ~57 ~4 ~72 ~67 ~4 ~72 concrete 11
fill ~60 ~4 ~64 ~60 ~4 ~67 obsidian 0
fill ~60 ~4 ~71 ~64 ~4 ~71 concrete 11
fill ~60 ~4 ~77 ~60 ~3 ~77 obsidian 0
fill ~61 ~4 ~65 ~63 ~4 ~65 obsidian 0
fill ~61 ~4 ~66 ~61 ~4 ~67 obsidian 0
fill ~61 ~4 ~78 ~63 ~4 ~78 obsidian 0
fill ~62 ~4 ~67 ~64 ~4 ~67 obsidian 0
fill ~63 ~4 ~66 ~64 ~4 ~66 obsidian 0
setblock ~63 ~4 ~74 concrete 11
fill ~64 ~4 ~69 ~68 ~4 ~69 concrete 11
fill ~64 ~4 ~77 ~64 ~5 ~77 obsidian 0
fill ~65 ~4 ~74 ~65 ~4 ~76 concrete 11
fill ~66 ~4 ~75 ~68 ~4 ~75 concrete 11
fill ~67 ~4 ~73 ~69 ~4 ~73 concrete 11
fill ~68 ~4 ~70 ~70 ~4 ~70 concrete 11
fill ~69 ~4 ~74 ~71 ~4 ~74 concrete 11
fill ~71 ~4 ~71 ~72 ~4 ~71 concrete 11
fill ~72 ~4 ~72 ~73 ~4 ~72 concrete 11
fill ~72 ~4 ~75 ~73 ~4 ~75 concrete 11
setblock ~74 ~4 ~73 concrete 11
fill ~75 ~4 ~74 ~75 ~5 ~74 concrete 11
fill ~45 ~5 ~77 ~46 ~5 ~77 concrete 11
fill ~45 ~5 ~78 ~46 ~5 ~78 concrete 11
fill ~46 ~5 ~75 ~47 ~5 ~75 concrete 11
fill ~46 ~5 ~76 ~46 ~5 ~75 concrete 11
fill ~47 ~5 ~73 ~48 ~5 ~73 concrete 11
setblock ~47 ~5 ~74 wool 11
setblock ~47 ~5 ~78 wool 11
fill ~48 ~5 ~72 ~49 ~5 ~72 concrete 11
fill ~48 ~5 ~74 ~48 ~7 ~74 concrete 11
fill ~48 ~5 ~77 ~60 ~5 ~77 concrete 11
fill ~48 ~5 ~78 ~50 ~5 ~78 concrete 11
fill ~49 ~5 ~71 ~50 ~5 ~71 concrete 11
setblock ~49 ~5 ~76 wool 11
fill ~50 ~5 ~70 ~51 ~5 ~70 concrete 11
fill ~50 ~5 ~74 ~52 ~5 ~74 concrete 11
fill ~50 ~5 ~75 ~51 ~5 ~75 concrete 11
fill ~50 ~5 ~76 ~50 ~5 ~74 concrete 11
fill ~51 ~5 ~69 ~53 ~5 ~69 concrete 11
setblock ~51 ~5 ~76 wool 11
setblock ~52 ~5 ~68 concrete 11
fill ~52 ~5 ~73 ~54 ~5 ~73 concrete 11
setblock ~53 ~5 ~68 wool 11
setblock ~53 ~5 ~72 wool 11
fill ~54 ~5 ~67 ~66 ~5 ~67 concrete 11
fill ~54 ~5 ~68 ~55 ~5 ~68 concrete 11
fill ~54 ~5 ~71 ~63 ~5 ~71 concrete 11
fill ~54 ~5 ~72 ~54 ~5 ~71 concrete 11
fill ~54 ~5 ~76 ~54 ~6 ~76 concrete 11
setblock ~55 ~5 ~72 wool 11
fill ~55 ~5 ~75 ~64 ~5 ~75 concrete 11
setblock ~55 ~5 ~76 wool 11
setblock ~56 ~5 ~72 concrete 11
setblock ~56 ~5 ~76 concrete 11
setblock ~57 ~5 ~70 wool 11
setblock ~57 ~5 ~76 wool 11
fill ~58 ~5 ~66 ~60 ~5 ~66 concrete 11
fill ~58 ~5 ~70 ~60 ~5 ~70 concrete 11
fill ~58 ~5 ~74 ~60 ~5 ~74 concrete 11
setblock ~58 ~5 ~76 concrete 11
setblock ~59 ~5 ~64 obsidian 0
fill ~60 ~5 ~63 ~61 ~5 ~63 obsidian 0
fill ~60 ~5 ~65 ~62 ~5 ~65 obsidian 0
fill ~60 ~5 ~76 ~63 ~5 ~76 obsidian 0
fill ~61 ~5 ~64 ~63 ~5 ~64 obsidian 0
setblock ~61 ~5 ~66 wool 11
setblock ~61 ~5 ~70 wool 11
fill ~61 ~5 ~77 ~64 ~5 ~77 obsidian 0
setblock ~62 ~5 ~66 concrete 11
fill ~62 ~5 ~70 ~64 ~5 ~70 concrete 11
setblock ~62 ~5 ~72 concrete 11
fill ~63 ~5 ~66 ~63 ~4 ~66 obsidian 0
setblock ~63 ~5 ~72 wool 11
setblock ~64 ~5 ~65 obsidian 0
fill ~64 ~5 ~72 ~65 ~5 ~72 concrete 11
fill ~64 ~5 ~76 ~64 ~6 ~76 concrete 11
setblock ~65 ~5 ~70 wool 11
fill ~65 ~5 ~71 ~68 ~5 ~71 concrete 11
fill ~65 ~5 ~73 ~67 ~5 ~73 concrete 11
setblock ~65 ~5 ~76 wool 11
setblock ~66 ~5 ~68 concrete 11
fill ~66 ~5 ~76 ~67 ~5 ~76 concrete 11
setblock ~67 ~5 ~68 wool 11
fill ~67 ~5 ~74 ~69 ~5 ~74 concrete 11
setblock ~68 ~5 ~68 concrete 11
fill ~68 ~5 ~72 ~68 ~6 ~72 concrete 11
fill ~68 ~5 ~77 ~70 ~5 ~77 concrete 11
fill ~69 ~5 ~69 ~70 ~5 ~69 concrete 11
setblock ~69 ~5 ~72 wool 11
fill ~69 ~5 ~75 ~70 ~5 ~75 concrete 11
fill ~70 ~5 ~72 ~70 ~5 ~73 concrete 11
fill ~70 ~5 ~76 ~72 ~5 ~76 concrete 11
fill ~71 ~5 ~70 ~72 ~5 ~70 concrete 11
setblock ~71 ~5 ~73 concrete 11
setblock ~72 ~5 ~74 concrete 11
setblock ~73 ~5 ~71 concrete 11
setblock ~73 ~5 ~74 wool 11
setblock ~74 ~5 ~72 concrete 11
setblock ~74 ~5 ~75 concrete 11
fill ~75 ~5 ~73 ~76 ~5 ~73 concrete 11
fill ~76 ~5 ~74 ~76 ~8 ~74 concrete 11
fill ~43 ~6 ~78 ~44 ~6 ~78 concrete 11
fill ~43 ~6 ~79 ~45 ~6 ~79 concrete 11
fill ~44 ~6 ~75 ~45 ~6 ~75 concrete 11
fill ~44 ~6 ~76 ~45 ~6 ~76 concrete 11
fill ~44 ~6 ~77 ~44 ~6 ~75 concrete 11
fill ~45 ~6 ~73 ~46 ~6 ~73 concrete 11
fill ~45 ~6 ~74 ~46 ~6 ~74 concrete 11
fill ~46 ~6 ~72 ~47 ~6 ~72 concrete 11
fill ~46 ~6 ~78 ~47 ~6 ~78 concrete 11
fill ~47 ~6 ~71 ~48 ~6 ~71 concrete 11
fill ~47 ~6 ~76 ~48 ~6 ~76 concrete 11
fill ~47 ~6 ~77 ~48 ~6 ~77 concrete 11
fill ~47 ~6 ~79 ~48 ~6 ~79 concrete 11
fill ~48 ~6 ~69 ~50 ~6 ~69 concrete 11
fill ~48 ~6 ~70 ~49 ~6 ~70 concrete 11
fill ~48 ~6 ~75 ~49 ~6 ~75 concrete 11
fill ~49 ~6 ~68 ~51 ~6 ~68 concrete 11
fill ~49 ~6 ~73 ~51 ~6 ~73 concrete 11
fill ~49 ~6 ~74 ~50 ~6 ~74 concrete 11
fill ~49 ~6 ~78 ~50 ~6 ~78 concrete 11
fill ~50 ~6 ~67 ~53 ~6 ~67 concrete 11
fill ~50 ~6 ~72 ~52 ~6 ~72 concrete 11
fill ~50 ~6 ~77 ~53 ~6 ~77 concrete 11
fill ~51 ~6 ~71 ~53 ~6 ~71 concrete 11
fill ~51 ~6 ~76 ~54 ~6 ~76 concrete 11
fill ~52 ~6 ~66 ~55 ~6 ~66 concrete 11
fill ~52 ~6 ~70 ~56 ~6 ~70 concrete 11
fill ~52 ~6 ~75 ~59 ~6 ~75 concrete 11
fill ~52 ~6 ~78 ~69 ~6 ~78 concrete 11
fill ~53 ~6 ~74 ~57 ~6 ~74 concrete 11
fill ~54 ~6 ~65 ~55 ~6 ~65 concrete 11
fill ~54 ~6 ~69 ~66 ~6 ~69 concrete 11
fill ~55 ~6 ~73 ~63 ~6 ~73 concrete 11
fill ~56 ~6 ~67 ~58 ~6 ~67 concrete 11
fill ~56 ~6 ~68 ~63 ~6 ~68 concrete 11
fill ~58 ~6 ~65 ~63 ~6 ~65 concrete 11
fill ~58 ~6 ~66 ~58 ~8 ~66 concrete 11
fill ~59 ~6 ~62 ~61 ~6 ~62 obsidian 0
fill ~59 ~6 ~63 ~60 ~6 ~63 obsidian 0
fill ~59 ~6 ~76 ~69 ~6 ~76 concrete 11
fill ~60 ~6 ~64 ~63 ~6 ~64 obsidian 0
fill ~60 ~6 ~70 ~64 ~6 ~70 concrete 11
fill ~60 ~6 ~74 ~60 ~6 ~75 obsidian 0
fill ~61 ~6 ~74 ~65 ~6 ~74 concrete 11
fill ~61 ~6 ~77 ~74 ~6 ~77 concrete 11
fill ~62 ~6 ~63 ~63 ~6 ~63 obsidian 0
fill ~63 ~6 ~66 ~66 ~6 ~66 concrete 11
setblock ~63 ~6 ~75 obsidian 0
fill ~64 ~6 ~71 ~66 ~6 ~71 concrete 11
fill ~65 ~6 ~75 ~67 ~6 ~75 concrete 11
fill ~66 ~6 ~70 ~68 ~6 ~70 concrete 11
fill ~66 ~6 ~72 ~68 ~6 ~72 concrete 11
fill ~67 ~6 ~67 ~68 ~6 ~67 concrete 11
fill ~68 ~6 ~73 ~69 ~6 ~73 concrete 11
fill ~69 ~6 ~68 ~70 ~6 ~68 concrete 11
fill ~69 ~6 ~71 ~70 ~6 ~71 concrete 11
fill ~70 ~6 ~74 ~71 ~6 ~74 concrete 11
fill ~71 ~6 ~69 ~72 ~6 ~69 concrete 11
fill ~71 ~6 ~72 ~72 ~6 ~72 concrete 11
fill ~71 ~6 ~75 ~72 ~6 ~75 concrete 11
fill ~72 ~6 ~73 ~73 ~6 ~73 concrete 11
setblock ~73 ~6 ~70 concrete 11
setblock ~73 ~6 ~76 concrete 11
setblock ~74 ~6 ~71 concrete 11
setblock ~74 ~6 ~74 concrete 11
fill ~75 ~6 ~72 ~76 ~6 ~72 concrete 11
setblock ~75 ~6 ~75 concrete 11
fill ~77 ~6 ~73 ~77 ~6 ~74 concrete 11
setblock ~40 ~7 ~82 concrete 0
setblock ~40 ~7 ~83 quartz_block 0
fill ~41 ~7 ~79 ~42 ~7 ~79 concrete 11
fill ~41 ~7 ~80 ~42 ~7 ~80 concrete 11
setblock ~41 ~7 ~82 snow 0
fill ~41 ~7 ~83 ~43 ~7 ~83 concrete 0
fill ~42 ~7 ~76 ~42 ~7 ~80 concrete 11
setblock ~42 ~7 ~82 concrete 0
setblock ~43 ~7 ~74 wool 11
setblock ~43 ~7 ~75 concrete 11
setblock ~43 ~7 ~76 wool 11
setblock ~43 ~7 ~77 concrete 11
setblock ~43 ~7 ~80 wool 11
fill ~43 ~7 ~81 ~45 ~7 ~81 concrete 0
setblock ~43 ~7 ~82 snow 0
fill ~44 ~7 ~72 ~45 ~7 ~72 concrete 11
fill ~44 ~7 ~73 ~44 ~7 ~74 concrete 11
setblock ~44 ~7 ~79 concrete 11
fill ~44 ~7 ~82 ~44 ~8 ~82 concrete 0
setblock ~44 ~7 ~83 quartz_block 0
fill ~45 ~7 ~71 ~46 ~7 ~71 concrete 11
fill ~45 ~7 ~77 ~46 ~7 ~77 concrete 11
setblock ~45 ~7 ~78 wool 11
setblock ~45 ~7 ~82 snow 0
fill ~46 ~7 ~69 ~47 ~7 ~69 concrete 11
fill ~46 ~7 ~70 ~46 ~7 ~69 concrete 11
fill ~46 ~7 ~75 ~47 ~7 ~75 concrete 11
fill ~46 ~7 ~76 ~46 ~7 ~75 concrete 11
fill ~46 ~7 ~78 ~46 ~5 ~78 concrete 11
fill ~46 ~7 ~79 ~47 ~7 ~79 concrete 11
fill ~46 ~7 ~80 ~46 ~7 ~75 concrete 11
setblock ~46 ~7 ~81 quartz_block 0
fill ~46 ~7 ~82 ~46 ~8 ~82 concrete 0
setblock ~47 ~7 ~68 wool 11
setblock ~47 ~7 ~70 wool 11
fill ~47 ~7 ~73 ~49 ~7 ~73 concrete 11
setblock ~47 ~7 ~74 wool 11
setblock ~47 ~7 ~80 snow 0
fill ~47 ~7 ~81 ~48 ~7 ~81 concrete 0
setblock ~47 ~7 ~82 snow 0
fill ~48 ~7 ~67 ~49 ~7 ~67 concrete 11
fill ~48 ~7 ~68 ~48 ~7 ~67 concrete 11
fill ~48 ~7 ~72 ~49 ~7 ~72 concrete 11
setblock ~48 ~7 ~78 concrete 11
setblock ~48 ~7 ~79 wool 10
setblock ~48 ~7 ~80 concrete 0
fill ~48 ~7 ~82 ~48 ~8 ~82 concrete 0
setblock ~49 ~7 ~66 wool 11
fill ~49 ~7 ~71 ~50 ~7 ~71 concrete 11
fill ~49 ~7 ~76 ~50 ~7 ~76 concrete 11
fill ~49 ~7 ~77 ~49 ~7 ~76 concrete 11
setblock ~49 ~7 ~78 wool 11
fill ~50 ~7 ~65 ~53 ~7 ~65 concrete 11
fill ~50 ~7 ~66 ~50 ~7 ~65 concrete 11
setblock ~50 ~7 ~70 concrete 11
fill ~50 ~7 ~75 ~51 ~7 ~75 concrete 11
setblock ~51 ~7 ~66 wool 11
fill ~51 ~7 ~69 ~53 ~7 ~69 concrete 11
setblock ~51 ~7 ~70 wool 11
setblock ~51 ~7 ~74 wool 11
setblock ~51 ~7 ~78 wool 11
fill ~51 ~7 ~79 ~54 ~7 ~79 concrete 11
setblock ~52 ~7 ~64 concrete 11
fill ~52 ~7 ~68 ~52 ~8 ~68 concrete 11
fill ~52 ~7 ~70 ~52 ~6 ~70 concrete 11
fill ~52 ~7 ~73 ~59 ~7 ~73 concrete 11
fill ~52 ~7 ~74 ~52 ~8 ~74 concrete 11
fill ~52 ~7 ~76 ~52 ~7 ~77 concrete 11
setblock ~53 ~7 ~64 wool 11
setblock ~53 ~7 ~68 wool 11
setblock ~53 ~7 ~72 wool 11
setblock ~53 ~7 ~74 wool 11
setblock ~53 ~7 ~75 concrete 11
fill ~54 ~7 ~63 ~60 ~7 ~63 concrete 11
fill ~54 ~7 ~64 ~56 ~7 ~64 concrete 11
fill ~54 ~7 ~67 ~64 ~7 ~67 concrete 11
fill ~54 ~7 ~68 ~56 ~7 ~68 concrete 11
fill ~54 ~7 ~72 ~56 ~7 ~72 concrete 11
setblock ~54 ~7 ~74 concrete 11
setblock ~54 ~7 ~78 concrete 11
fill ~55 ~7 ~71 ~61 ~7 ~71 concrete 11
fill ~55 ~7 ~77 ~59 ~7 ~77 concrete 11
setblock ~55 ~7 ~78 wool 11
fill ~56 ~7 ~65 ~57 ~7 ~65 concrete 11
fill ~56 ~7 ~66 ~56 ~8 ~66 concrete 11
setblock ~56 ~7 ~76 concrete 11
setblock ~57 ~7 ~64 wool 11
setblock ~57 ~7 ~68 wool 11
setblock ~57 ~7 ~72 wool 11
setblock ~57 ~7 ~76 wool 11
fill ~58 ~7 ~64 ~60 ~7 ~64 concrete 11
fill ~58 ~7 ~68 ~60 ~7 ~68 concrete 11
fill ~58 ~7 ~72 ~64 ~7 ~72 concrete 11
setblock ~58 ~7 ~74 concrete 11
setblock ~58 ~7 ~78 concrete 11
fill ~59 ~7 ~61 ~62 ~7 ~61 obsidian 0
fill ~59 ~7 ~62 ~60 ~7 ~62 obsidian 0
setblock ~59 ~7 ~74 wool 11
setblock ~59 ~7 ~78 wool 11
fill ~60 ~7 ~74 ~61 ~7 ~74 concrete 11
fill ~60 ~7 ~75 ~69 ~7 ~75 concrete 11
setblock ~60 ~7 ~78 concrete 11
fill ~61 ~7 ~63 ~63 ~7 ~63 obsidian 0
setblock ~61 ~7 ~64 wool 11
setblock ~61 ~7 ~68 wool 11
fill ~61 ~7 ~73 ~63 ~7 ~73 obsidian 0
setblock ~61 ~7 ~78 wool 11
fill ~62 ~7 ~62 ~63 ~7 ~62 obsidian 0
fill ~62 ~7 ~64 ~64 ~7 ~64 concrete 11
fill ~62 ~7 ~68 ~62 ~7 ~69 concrete 11
fill ~62 ~7 ~74 ~63 ~7 ~74 obsidian 0
fill ~62 ~7 ~78 ~62 ~7 ~79 concrete 11
fill ~63 ~7 ~69 ~64 ~7 ~69 concrete 11
setblock ~63 ~7 ~78 wool 11
fill ~64 ~7 ~65 ~66 ~7 ~65 concrete 11
fill ~64 ~7 ~68 ~64 ~8 ~68 concrete 11
fill ~64 ~7 ~73 ~66 ~7 ~73 concrete 11
fill ~64 ~7 ~74 ~64 ~7 ~72 concrete 11
setblock ~64 ~7 ~78 concrete 11
setblock ~65 ~7 ~68 wool 11
setblock ~65 ~7 ~70 wool 11
setblock ~65 ~7 ~74 wool 11
setblock ~65 ~7 ~78 wool 11
setblock ~66 ~7 ~68 concrete 11
fill ~66 ~7 ~70 ~66 ~6 ~70 concrete 11
setblock ~66 ~7 ~74 concrete 11
setblock ~66 ~7 ~78 concrete 11
setblock ~67 ~7 ~66 wool 11
fill ~67 ~7 ~69 ~68 ~7 ~69 concrete 11
fill ~67 ~7 ~71 ~68 ~7 ~71 concrete 11
setblock ~67 ~7 ~74 wool 11
setblock ~67 ~7 ~78 wool 11
setblock ~68 ~7 ~66 concrete 11
setblock ~68 ~7 ~78 concrete 11
fill ~69 ~7 ~67 ~70 ~7 ~67 concrete 11
setblock ~69 ~7 ~70 wool 11
setblock ~69 ~7 ~72 wool 11
setblock ~69 ~7 ~76 wool 11
setblock ~69 ~7 ~78 wool 11
setblock ~70 ~7 ~70 concrete 11
fill ~70 ~7 ~72 ~70 ~7 ~73 concrete 11
setblock ~70 ~7 ~76 concrete 11
fill ~70 ~7 ~78 ~70 ~8 ~78 concrete 11
fill ~71 ~7 ~68 ~72 ~7 ~68 concrete 11
fill ~71 ~7 ~71 ~72 ~7 ~71 concrete 11
setblock ~71 ~7 ~73 concrete 11
fill ~71 ~7 ~77 ~72 ~7 ~77 concrete 11
setblock ~71 ~7 ~78 wool 11
setblock ~72 ~7 ~74 concrete 11
setblock ~72 ~7 ~78 concrete 11
setblock ~73 ~7 ~69 concrete 11
setblock ~73 ~7 ~72 wool 11
setblock ~73 ~7 ~75 concrete 11
setblock ~73 ~7 ~78 wool 11
setblock ~74 ~7 ~70 concrete 11
setblock ~74 ~7 ~73 concrete 11
setblock ~74 ~7 ~76 concrete 11
fill ~74 ~7 ~78 ~74 ~8 ~78 concrete 11
fill ~75 ~7 ~71 ~76 ~7 ~71 concrete 11
setblock ~75 ~7 ~74 wool 11
setblock ~75 ~7 ~77 concrete 11
setblock ~75 ~7 ~78 wool 11
setblock ~76 ~7 ~78 concrete 11
setblock ~77 ~7 ~72 wool 11
setblock ~77 ~7 ~74 wool 11
fill ~78 ~7 ~73 ~78 ~7 ~74 concrete 11
fill ~35 ~8 ~82 ~39 ~8 ~82 concrete 0
fill ~35 ~8 ~83 ~39 ~8 ~83 concrete 0
fill ~37 ~8 ~84 ~41 ~8 ~84 concrete 0
setblock ~39 ~8 ~81 concrete 11
fill ~40 ~8 ~78 ~41 ~8 ~78 concrete 11
fill ~40 ~8 ~79 ~40 ~8 ~80 concrete 11
fill ~40 ~8 ~81 ~42 ~8 ~81 wool 10
fill ~41 ~8 ~75 ~42 ~8 ~75 concrete 11
fill ~41 ~8 ~76 ~41 ~8 ~78 concrete 11
fill ~42 ~8 ~73 ~43 ~8 ~73 concrete 11
fill ~42 ~8 ~74 ~42 ~8 ~73 concrete 11
setblock ~42 ~8 ~80 concrete 11
fill ~42 ~8 ~83 ~46 ~8 ~83 concrete 0
setblock ~43 ~8 ~72 concrete 11
fill ~43 ~8 ~78 ~45 ~8 ~78 concrete 11
fill ~43 ~8 ~79 ~43 ~8 ~78 concrete 11
fill ~43 ~8 ~81 ~45 ~8 ~81 concrete 0
fill ~44 ~8 ~71 ~44 ~9 ~71 concrete 11
fill ~44 ~8 ~76 ~45 ~8 ~76 concrete 11
fill ~44 ~8 ~77 ~45 ~8 ~77 concrete 11
fill ~45 ~8 ~68 ~46 ~8 ~68 concrete 11
fill ~45 ~8 ~69 ~45 ~10 ~69 concrete 11
fill ~45 ~8 ~70 ~45 ~9 ~70 concrete 11
fill ~45 ~8 ~74 ~46 ~8 ~74 concrete 11
fill ~45 ~8 ~75 ~45 ~9 ~75 concrete 11
fill ~45 ~8 ~79 ~45 ~10 ~79 concrete 11
fill ~45 ~8 ~80 ~45 ~8 ~74 concrete 11
setblock ~45 ~8 ~82 concrete 0
fill ~46 ~8 ~67 ~47 ~8 ~67 concrete 11
fill ~46 ~8 ~72 ~47 ~8 ~72 concrete 11
fill ~46 ~8 ~73 ~47 ~8 ~73 concrete 11
setblock ~46 ~8 ~81 wool 10
fill ~47 ~8 ~66 ~48 ~8 ~66 concrete 11
fill ~47 ~8 ~71 ~48 ~8 ~71 concrete 11
setblock ~47 ~8 ~77 concrete 11
fill ~47 ~8 ~78 ~47 ~8 ~79 wool 10
setblock ~47 ~8 ~80 stone 3
fill ~47 ~8 ~81 ~49 ~8 ~81 concrete 0
fill ~47 ~8 ~82 ~47 ~8 ~81 concrete 0
fill ~48 ~8 ~65 ~49 ~8 ~65 concrete 11
fill ~48 ~8 ~70 ~49 ~8 ~70 concrete 11
fill ~48 ~8 ~75 ~49 ~8 ~75 concrete 11
fill ~48 ~8 ~76 ~48 ~8 ~75 concrete 11
setblock ~48 ~8 ~77 light_blue_glazed_terracotta 0
fill ~48 ~8 ~78 ~49 ~8 ~78 concrete 0
fill ~49 ~8 ~64 ~51 ~8 ~64 concrete 11
fill ~49 ~8 ~69 ~50 ~8 ~69 concrete 11
fill ~49 ~8 ~74 ~50 ~8 ~74 concrete 11
fill ~49 ~8 ~79 ~49 ~8 ~81 concrete 0
fill ~50 ~8 ~63 ~53 ~8 ~63 concrete 11
fill ~50 ~8 ~68 ~52 ~8 ~68 concrete 11
fill ~50 ~8 ~72 ~54 ~8 ~72 concrete 11
fill ~50 ~8 ~73 ~53 ~8 ~73 concrete 11
fill ~50 ~8 ~78 ~50 ~8 ~80 concrete 11
fill ~51 ~8 ~67 ~54 ~8 ~67 concrete 11
fill ~51 ~8 ~71 ~58 ~8 ~71 concrete 11
fill ~51 ~8 ~75 ~52 ~8 ~75 concrete 11
fill ~51 ~8 ~76 ~51 ~8 ~77 concrete 11
fill ~51 ~8 ~80 ~52 ~8 ~80 concrete 11
fill ~52 ~8 ~62 ~61 ~8 ~62 concrete 11
fill ~52 ~8 ~66 ~64 ~8 ~66 concrete 11
fill ~53 ~8 ~70 ~62 ~8 ~70 concrete 11
fill ~53 ~8 ~77 ~54 ~8 ~77 concrete 11
fill ~53 ~8 ~78 ~53 ~8 ~79 concrete 11
fill ~54 ~8 ~76 ~55 ~8 ~76 concrete 11
fill ~55 ~8 ~65 ~61 ~8 ~65 concrete 11
fill ~55 ~8 ~75 ~58 ~8 ~75 concrete 11
fill ~56 ~8 ~69 ~59 ~8 ~69 concrete 11
setblock ~56 ~8 ~74 concrete 11
fill ~58 ~8 ~72 ~60 ~8 ~72 concrete 11
fill ~58 ~8 ~76 ~60 ~8 ~76 concrete 11
fill ~59 ~8 ~60 ~62 ~8 ~60 obsidian 0
fill ~59 ~8 ~71 ~62 ~8 ~71 obsidian 0
setblock ~60 ~8 ~59 obsidian 0
fill ~60 ~8 ~61 ~61 ~8 ~61 obsidian 0
fill ~60 ~8 ~67 ~63 ~8 ~67 concrete 11
fill ~60 ~8 ~73 ~68 ~8 ~73 concrete 11
fill ~60 ~8 ~77 ~68 ~8 ~77 concrete 11
fill ~61 ~8 ~63 ~64 ~8 ~63 concrete 11
setblock ~61 ~8 ~72 obsidian 0
fill ~62 ~8 ~62 ~63 ~8 ~62 obsidian 0
fill ~62 ~8 ~74 ~63 ~8 ~74 concrete 11
fill ~63 ~8 ~61 ~63 ~9 ~61 obsidian 0
setblock ~63 ~8 ~68 concrete 11
fill ~63 ~8 ~71 ~64 ~8 ~71 concrete 11
setblock ~63 ~8 ~72 obsidian 0
fill ~65 ~8 ~64 ~66 ~8 ~64 concrete 11
fill ~65 ~8 ~67 ~67 ~8 ~67 concrete 11
fill ~65 ~8 ~68 ~65 ~8 ~69 concrete 11
fill ~65 ~8 ~72 ~66 ~8 ~72 concrete 11
fill ~65 ~8 ~76 ~66 ~8 ~76 concrete 11
fill ~66 ~8 ~69 ~67 ~8 ~69 concrete 11
fill ~67 ~8 ~65 ~68 ~8 ~65 concrete 11
fill ~67 ~8 ~68 ~73 ~8 ~68 concrete 11
fill ~67 ~8 ~70 ~68 ~8 ~70 concrete 11
fill ~67 ~8 ~74 ~69 ~8 ~74 concrete 11
fill ~69 ~8 ~66 ~70 ~8 ~66 concrete 11
fill ~69 ~8 ~69 ~70 ~8 ~69 concrete 11
fill ~69 ~8 ~71 ~70 ~8 ~71 concrete 11
setblock ~69 ~8 ~78 concrete 11
fill ~70 ~8 ~67 ~70 ~10 ~67 concrete 11
fill ~70 ~8 ~75 ~71 ~8 ~75 concrete 11
fill ~70 ~8 ~79 ~78 ~8 ~79 concrete 11
fill ~71 ~8 ~70 ~72 ~8 ~70 concrete 11
setblock ~71 ~8 ~72 concrete 11
fill ~71 ~8 ~76 ~72 ~8 ~76 concrete 11
setblock ~72 ~8 ~73 concrete 11
fill ~72 ~8 ~77 ~73 ~8 ~77 concrete 11
setblock ~73 ~8 ~71 concrete 11
setblock ~73 ~8 ~74 concrete 11
setblock ~73 ~8 ~78 concrete 11
setblock ~74 ~8 ~69 concrete 11
setblock ~74 ~8 ~72 concrete 11
setblock ~74 ~8 ~75 concrete 11
setblock ~75 ~8 ~70 concrete 11
setblock ~75 ~8 ~73 concrete 11
fill ~75 ~8 ~76 ~76 ~8 ~76 concrete 11
fill ~76 ~8 ~71 ~77 ~8 ~71 concrete 11
fill ~76 ~8 ~77 ~77 ~8 ~77 concrete 11
fill ~77 ~8 ~74 ~79 ~8 ~74 concrete 11
setblock ~77 ~8 ~78 concrete 11
fill ~78 ~8 ~72 ~78 ~9 ~72 concrete 11
setblock ~79 ~8 ~73 concrete 11
fill ~33 ~9 ~81 ~35 ~9 ~81 concrete 0
fill ~34 ~9 ~79 ~34 ~12 ~79 concrete 0
fill ~34 ~9 ~80 ~34 ~9 ~79 concrete 0
fill ~34 ~9 ~82 ~34 ~11 ~82 concrete 0
fill ~34 ~9 ~83 ~34 ~9 ~79 concrete 0
fill ~35 ~9 ~71 ~35 ~10 ~71 concrete 0
setblock ~35 ~9 ~80 snow 0
setblock ~35 ~9 ~84 snow 0
fill ~36 ~9 ~70 ~36 ~10 ~70 concrete 0
setblock ~36 ~9 ~71 quartz_block 0
setblock ~36 ~9 ~82 concrete 0
setblock ~36 ~9 ~83 quartz_block 0
setblock ~36 ~9 ~84 concrete 0
setblock ~37 ~9 ~70 quartz_block 0
fill ~37 ~9 ~71 ~39 ~9 ~71 concrete 0
setblock ~37 ~9 ~82 quartz_block 0
fill ~37 ~9 ~83 ~39 ~9 ~83 concrete 0
setblock ~37 ~9 ~84 snow 0
fill ~38 ~9 ~69 ~43 ~9 ~69 concrete 0
fill ~38 ~9 ~70 ~38 ~10 ~70 concrete 0
fill ~38 ~9 ~80 ~38 ~9 ~81 concrete 11
setblock ~38 ~9 ~82 light_blue_glazed_terracotta 0
setblock ~39 ~9 ~70 snow 0
fill ~39 ~9 ~77 ~40 ~9 ~77 concrete 11
setblock ~39 ~9 ~78 wool 11
setblock ~39 ~9 ~79 concrete 11
setblock ~39 ~9 ~80 wool 11
fill ~39 ~9 ~82 ~40 ~9 ~82 wool 10
setblock ~40 ~9 ~70 concrete 0
fill ~40 ~9 ~75 ~40 ~9 ~77 concrete 11
setblock ~40 ~9 ~83 quartz_block 0
setblock ~41 ~9 ~70 quartz_block 0
fill ~41 ~9 ~73 ~41 ~9 ~74 concrete 11
fill ~41 ~9 ~79 ~42 ~9 ~79 concrete 11
setblock ~41 ~9 ~80 wool 11
setblock ~41 ~9 ~81 concrete 11
setblock ~41 ~9 ~82 quartz_block 0
setblock ~41 ~9 ~83 concrete 0
setblock ~42 ~9 ~70 concrete 0
setblock ~42 ~9 ~71 wool 10
setblock ~42 ~9 ~72 concrete 11
fill ~42 ~9 ~77 ~43 ~9 ~77 concrete 11
fill ~42 ~9 ~78 ~42 ~9 ~77 concrete 11
setblock ~42 ~9 ~82 concrete 0
setblock ~43 ~9 ~70 snow 0
fill ~43 ~9 ~71 ~43 ~11 ~71 concrete 11
fill ~43 ~9 ~75 ~45 ~9 ~75 concrete 11
setblock ~43 ~9 ~76 wool 11
setblock ~43 ~9 ~82 snow 0
fill ~44 ~9 ~67 ~45 ~9 ~67 concrete 11
fill ~44 ~9 ~68 ~44 ~9 ~67 concrete 11
fill ~44 ~9 ~70 ~44 ~10 ~70 concrete 0
fill ~44 ~9 ~73 ~45 ~9 ~73 concrete 11
fill ~44 ~9 ~74 ~45 ~9 ~74 concrete 11
fill ~45 ~9 ~66 ~46 ~9 ~66 concrete 11
fill ~45 ~9 ~71 ~46 ~9 ~71 concrete 11
setblock ~45 ~9 ~72 wool 11
setblock ~45 ~9 ~76 wool 11
fill ~45 ~9 ~77 ~46 ~9 ~77 concrete 11
fill ~45 ~9 ~78 ~45 ~10 ~78 concrete 11
setblock ~45 ~9 ~80 wool 11
setblock ~45 ~9 ~81 concrete 11
fill ~46 ~9 ~65 ~47 ~9 ~65 concrete 11
setblock ~46 ~9 ~70 concrete 11
fill ~46 ~9 ~72 ~46 ~8 ~72 concrete 11
setblock ~46 ~9 ~82 concrete 11
setblock ~47 ~9 ~64 wool 11
fill ~47 ~9 ~69 ~48 ~9 ~69 concrete 11
setblock ~47 ~9 ~70 wool 11
setblock ~47 ~9 ~74 wool 11
setblock ~47 ~9 ~75 wool 10
setblock ~47 ~9 ~76 purpur_pillar 0
fill ~47 ~9 ~77 ~47 ~10 ~77 concrete 0
setblock ~47 ~9 ~78 stone 4
setblock ~47 ~9 ~79 wool 10
setblock ~47 ~9 ~80 wool 11
fill ~47 ~9 ~81 ~51 ~9 ~81 concrete 11
setblock ~47 ~9 ~82 wool 11
fill ~48 ~9 ~63 ~49 ~9 ~63 concrete 11
fill ~48 ~9 ~64 ~48 ~9 ~63 concrete 11
fill ~48 ~9 ~67 ~50 ~9 ~67 concrete 11
fill ~48 ~9 ~68 ~49 ~9 ~68 concrete 11
fill ~48 ~9 ~73 ~49 ~9 ~73 concrete 11
fill ~48 ~9 ~74 ~48 ~9 ~73 concrete 11
setblock ~48 ~9 ~75 quartz_block 0
fill ~48 ~9 ~76 ~48 ~10 ~76 concrete 0
setblock ~48 ~9 ~79 quartz_block 0
setblock ~48 ~9 ~80 wool 10
fill ~49 ~9 ~62 ~51 ~9 ~62 concrete 11
fill ~49 ~9 ~71 ~50 ~9 ~71 concrete 11
setblock ~49 ~9 ~72 wool 11
setblock ~49 ~9 ~77 concrete 0
fill ~49 ~9 ~78 ~49 ~9 ~79 wool 10
setblock ~49 ~9 ~80 wool 11
fill ~50 ~9 ~66 ~52 ~9 ~66 concrete 11
fill ~50 ~9 ~70 ~52 ~9 ~70 concrete 11
fill ~50 ~9 ~75 ~50 ~9 ~77 concrete 11
fill ~51 ~9 ~61 ~61 ~9 ~61 concrete 11
fill ~51 ~9 ~65 ~64 ~9 ~65 concrete 11
fill ~51 ~9 ~69 ~57 ~9 ~69 concrete 11
fill ~51 ~9 ~73 ~51 ~9 ~74 concrete 11
setblock ~51 ~9 ~80 wool 11
fill ~52 ~9 ~71 ~53 ~9 ~71 concrete 11
fill ~52 ~9 ~72 ~52 ~9 ~69 concrete 11
fill ~52 ~9 ~77 ~52 ~9 ~79 concrete 11
setblock ~53 ~9 ~64 wool 11
setblock ~53 ~9 ~68 wool 11
setblock ~53 ~9 ~70 wool 11
fill ~53 ~9 ~75 ~54 ~9 ~75 concrete 11
setblock ~53 ~9 ~76 wool 11
fill ~54 ~9 ~60 ~56 ~9 ~60 concrete 11
setblock ~54 ~9 ~64 concrete 11
fill ~54 ~9 ~68 ~54 ~10 ~68 concrete 11
fill ~54 ~9 ~70 ~56 ~9 ~70 concrete 11
fill ~54 ~9 ~74 ~55 ~9 ~74 concrete 11
setblock ~55 ~9 ~64 wool 11
setblock ~55 ~9 ~68 wool 11
fill ~55 ~9 ~73 ~57 ~9 ~73 concrete 11
setblock ~56 ~9 ~64 concrete 11
fill ~56 ~9 ~68 ~56 ~10 ~68 concrete 11
setblock ~57 ~9 ~60 wool 11
setblock ~57 ~9 ~64 wool 11
setblock ~57 ~9 ~68 wool 11
setblock ~57 ~9 ~70 wool 11
setblock ~57 ~9 ~74 wool 11
fill ~58 ~9 ~64 ~60 ~9 ~64 concrete 11
setblock ~58 ~9 ~68 concrete 11
setblock ~58 ~9 ~70 concrete 11
fill ~58 ~9 ~74 ~59 ~9 ~74 concrete 11
fill ~59 ~9 ~58 ~60 ~9 ~58 obsidian 0
fill ~59 ~9 ~59 ~59 ~9 ~58 obsidian 0
setblock ~59 ~9 ~68 wool 11
fill ~59 ~9 ~69 ~59 ~9 ~70 obsidian 0
fill ~59 ~9 ~71 ~61 ~9 ~71 concrete 11
fill ~59 ~9 ~75 ~67 ~9 ~75 concrete 11
fill ~60 ~9 ~60 ~61 ~9 ~60 obsidian 0
fill ~60 ~9 ~68 ~60 ~9 ~69 concrete 11
fill ~61 ~9 ~59 ~62 ~9 ~59 obsidian 0
setblock ~61 ~9 ~64 wool 11
setblock ~61 ~9 ~66 wool 11
fill ~61 ~9 ~69 ~63 ~9 ~69 concrete 11
fill ~61 ~9 ~70 ~62 ~9 ~70 obsidian 0
setblock ~61 ~9 ~72 wool 11
setblock ~61 ~9 ~76 wool 11
setblock ~62 ~9 ~61 obsidian 0
fill ~62 ~9 ~62 ~64 ~9 ~62 concrete 11
fill ~62 ~9 ~66 ~63 ~9 ~66 concrete 11
fill ~62 ~9 ~71 ~63 ~9 ~71 obsidian 0
fill ~62 ~9 ~72 ~64 ~9 ~72 concrete 11
setblock ~62 ~9 ~76 concrete 11
fill ~63 ~9 ~60 ~63 ~10 ~60 obsidian 0
fill ~63 ~9 ~70 ~64 ~9 ~70 concrete 11
setblock ~63 ~9 ~76 wool 11
fill ~64 ~9 ~67 ~65 ~9 ~67 concrete 11
setblock ~64 ~9 ~76 concrete 11
fill ~65 ~9 ~63 ~66 ~9 ~63 concrete 11
setblock ~65 ~9 ~66 wool 11
setblock ~65 ~9 ~70 wool 11
fill ~65 ~9 ~71 ~66 ~9 ~71 concrete 11
setblock ~65 ~9 ~72 wool 11
fill ~66 ~9 ~66 ~67 ~9 ~66 concrete 11
fill ~66 ~9 ~68 ~67 ~9 ~68 concrete 11
setblock ~66 ~9 ~72 concrete 11
setblock ~67 ~9 ~64 wool 11
setblock ~67 ~9 ~72 wool 11
setblock ~67 ~9 ~76 wool 11
setblock ~68 ~9 ~64 concrete 11
fill ~68 ~9 ~67 ~73 ~9 ~67 concrete 11
setblock ~68 ~9 ~69 concrete 11
fill ~68 ~9 ~72 ~68 ~9 ~73 concrete 11
setblock ~68 ~9 ~76 concrete 11
setblock ~69 ~9 ~65 concrete 11
setblock ~69 ~9 ~70 wool 11
setblock ~69 ~9 ~73 concrete 11
setblock ~69 ~9 ~76 wool 11
fill ~69 ~9 ~77 ~70 ~9 ~77 concrete 11
fill ~70 ~9 ~66 ~71 ~9 ~66 concrete 11
setblock ~70 ~9 ~70 concrete 11
fill ~70 ~9 ~74 ~71 ~9 ~74 concrete 11
fill ~71 ~9 ~69 ~72 ~9 ~69 concrete 11
setblock ~71 ~9 ~71 concrete 11
fill ~71 ~9 ~75 ~72 ~9 ~75 concrete 11
setblock ~71 ~9 ~78 concrete 11
setblock ~72 ~9 ~68 concrete 11
setblock ~72 ~9 ~72 concrete 11
setblock ~72 ~9 ~76 concrete 11
setblock ~72 ~9 ~79 concrete 11
setblock ~73 ~9 ~70 wool 11
setblock ~73 ~9 ~73 concrete 11
setblock ~73 ~9 ~76 wool 11
setblock ~73 ~9 ~80 wool 11
setblock ~74 ~9 ~68 concrete 11
setblock ~74 ~9 ~71 concrete 11
fill ~74 ~9 ~74 ~75 ~9 ~74 concrete 11
setblock ~74 ~9 ~77 concrete 11
fill ~74 ~9 ~80 ~74 ~10 ~80 concrete 11
setblock ~75 ~9 ~69 concrete 11
setblock ~75 ~9 ~72 wool 11
fill ~75 ~9 ~75 ~76 ~9 ~75 concrete 11
fill ~75 ~9 ~78 ~75 ~9 ~79 concrete 11
setblock ~75 ~9 ~80 wool 11
setblock ~76 ~9 ~70 concrete 11
setblock ~76 ~9 ~73 concrete 11
fill ~76 ~9 ~79 ~76 ~9 ~80 concrete 11
setblock ~77 ~9 ~71 concrete 11
setblock ~77 ~9 ~74 wool 11
setblock ~77 ~9 ~76 concrete 11
setblock ~77 ~9 ~80 wool 11
setblock ~78 ~9 ~75 concrete 11
fill ~78 ~9 ~77 ~78 ~10 ~77 concrete 11
fill ~78 ~9 ~78 ~78 ~9 ~77 concrete 11
fill ~78 ~9 ~80 ~78 ~11 ~80 concrete 11
fill ~79 ~9 ~72 ~79 ~10 ~72 concrete 11
fill ~79 ~9 ~74 ~80 ~9 ~74 concrete 11
setblock ~79 ~9 ~79 concrete 11
setblock ~79 ~9 ~80 wool 11
fill ~80 ~9 ~73 ~80 ~10 ~73 concrete 11
setblock ~80 ~9 ~80 concrete 11
fill ~33 ~10 ~72 ~35 ~10 ~72 concrete 0
fill ~33 ~10 ~77 ~34 ~10 ~77 concrete 0
fill ~33 ~10 ~78 ~35 ~10 ~78 concrete 0
fill ~33 ~10 ~79 ~33 ~12 ~79 concrete 0
fill ~33 ~10 ~80 ~33 ~10 ~82 concrete 0
fill ~34 ~10 ~71 ~34 ~11 ~71 concrete 0
setblock ~35 ~10 ~70 concrete 0
fill ~35 ~10 ~79 ~35 ~11 ~79 concrete 0
fill ~35 ~10 ~80 ~35 ~10 ~83 concrete 0
setblock ~36 ~10 ~71 concrete 0
fill ~36 ~10 ~83 ~38 ~10 ~83 concrete 11
setblock ~37 ~10 ~70 concrete 0
fill ~37 ~10 ~79 ~38 ~10 ~79 concrete 11
fill ~37 ~10 ~80 ~37 ~10 ~83 concrete 11
fill ~38 ~10 ~77 ~38 ~10 ~79 concrete 11
fill ~39 ~10 ~74 ~40 ~10 ~74 concrete 11
fill ~39 ~10 ~75 ~39 ~10 ~76 concrete 11
fill ~39 ~10 ~81 ~40 ~10 ~81 concrete 11
fill ~39 ~10 ~82 ~39 ~10 ~81 concrete 11
fill ~40 ~10 ~72 ~41 ~10 ~72 concrete 11
fill ~40 ~10 ~73 ~40 ~10 ~72 concrete 11
fill ~40 ~10 ~79 ~40 ~10 ~81 concrete 11
fill ~41 ~10 ~70 ~41 ~10 ~72 concrete 11
fill ~41 ~10 ~76 ~42 ~10 ~76 concrete 11
fill ~41 ~10 ~77 ~41 ~10 ~78 concrete 11
fill ~42 ~10 ~68 ~43 ~10 ~68 concrete 11
fill ~42 ~10 ~69 ~43 ~10 ~69 concrete 11
setblock ~42 ~10 ~70 wool 10
fill ~42 ~10 ~74 ~44 ~10 ~74 concrete 11
fill ~42 ~10 ~75 ~42 ~10 ~74 concrete 11
setblock ~43 ~10 ~67 concrete 11
setblock ~43 ~10 ~70 concrete 0
fill ~43 ~10 ~72 ~44 ~10 ~72 concrete 11
fill ~43 ~10 ~73 ~44 ~10 ~73 concrete 11
fill ~44 ~10 ~65 ~45 ~10 ~65 concrete 11
fill ~44 ~10 ~66 ~44 ~10 ~65 concrete 11
setblock ~44 ~10 ~69 concrete 10
setblock ~44 ~10 ~71 concrete 0
fill ~44 ~10 ~75 ~44 ~12 ~75 concrete 11
fill ~44 ~10 ~76 ~44 ~11 ~76 concrete 11
fill ~44 ~10 ~77 ~44 ~10 ~72 concrete 11
fill ~45 ~10 ~64 ~46 ~10 ~64 concrete 11
fill ~45 ~10 ~70 ~45 ~10 ~71 light_blue_glazed_terracotta 0
setblock ~45 ~10 ~80 concrete 11
fill ~46 ~10 ~63 ~47 ~10 ~63 concrete 11
fill ~46 ~10 ~68 ~47 ~10 ~68 concrete 11
fill ~46 ~10 ~69 ~46 ~10 ~68 concrete 11
setblock ~46 ~10 ~71 concrete 0
fill ~46 ~10 ~74 ~46 ~10 ~77 concrete 11
setblock ~46 ~10 ~81 concrete 11
fill ~47 ~10 ~62 ~48 ~10 ~62 concrete 11
fill ~47 ~10 ~67 ~48 ~10 ~67 concrete 11
fill ~47 ~10 ~72 ~48 ~10 ~72 concrete 11
setblock ~47 ~10 ~73 wool 10
fill ~47 ~10 ~74 ~48 ~10 ~74 concrete 0
fill ~47 ~10 ~75 ~48 ~10 ~75 concrete 0
fill ~47 ~10 ~76 ~47 ~10 ~74 concrete 0
setblock ~47 ~10 ~78 concrete 11
fill ~47 ~10 ~82 ~49 ~10 ~82 concrete 11
fill ~48 ~10 ~61 ~50 ~10 ~61 concrete 11
fill ~48 ~10 ~65 ~51 ~10 ~65 concrete 11
fill ~48 ~10 ~66 ~49 ~10 ~66 concrete 11
fill ~48 ~10 ~70 ~49 ~10 ~70 concrete 11
fill ~48 ~10 ~71 ~48 ~10 ~70 concrete 11
setblock ~48 ~10 ~77 concrete 0
setblock ~48 ~10 ~78 wool 11
setblock ~48 ~10 ~79 concrete 11
fill ~49 ~10 ~60 ~53 ~10 ~60 concrete 11
fill ~49 ~10 ~69 ~50 ~10 ~69 concrete 11
fill ~49 ~10 ~75 ~49 ~10 ~77 concrete 11
fill ~50 ~10 ~64 ~53 ~10 ~64 concrete 11
fill ~50 ~10 ~68 ~57 ~10 ~68 concrete 11
fill ~50 ~10 ~72 ~51 ~10 ~72 concrete 11
fill ~50 ~10 ~73 ~50 ~10 ~74 concrete 11
fill ~50 ~10 ~80 ~50 ~10 ~81 concrete 11
fill ~51 ~10 ~63 ~62 ~10 ~63 concrete 11
setblock ~51 ~10 ~71 concrete 11
fill ~51 ~10 ~77 ~51 ~10 ~79 concrete 11
fill ~52 ~10 ~59 ~58 ~10 ~59 concrete 11
fill ~52 ~10 ~67 ~61 ~10 ~67 concrete 11
fill ~52 ~10 ~69 ~53 ~10 ~69 concrete 11
fill ~52 ~10 ~70 ~52 ~10 ~67 concrete 11
fill ~52 ~10 ~74 ~53 ~10 ~74 concrete 11
fill ~52 ~10 ~75 ~52 ~10 ~76 concrete 11
fill ~53 ~10 ~73 ~54 ~10 ~73 concrete 11
fill ~54 ~10 ~66 ~58 ~10 ~66 concrete 11
fill ~54 ~10 ~72 ~58 ~10 ~72 concrete 11
fill ~55 ~10 ~71 ~56 ~10 ~71 concrete 11
fill ~56 ~10 ~62 ~57 ~10 ~62 concrete 11
fill ~58 ~10 ~60 ~61 ~10 ~60 concrete 11
fill ~58 ~10 ~69 ~59 ~10 ~69 concrete 11
fill ~58 ~10 ~73 ~60 ~10 ~73 concrete 11
fill ~59 ~10 ~57 ~59 ~12 ~57 obsidian 0
fill ~59 ~10 ~58 ~61 ~10 ~58 obsidian 0
fill ~59 ~10 ~64 ~64 ~10 ~64 concrete 11
fill ~59 ~10 ~68 ~60 ~10 ~68 obsidian 0
fill ~59 ~10 ~70 ~67 ~10 ~70 concrete 11
fill ~60 ~10 ~59 ~63 ~10 ~59 obsidian 0
setblock ~60 ~10 ~69 obsidian 0
fill ~60 ~10 ~74 ~67 ~10 ~74 concrete 11
fill ~61 ~10 ~68 ~63 ~10 ~68 concrete 11
setblock ~62 ~10 ~60 obsidian 0
fill ~62 ~10 ~61 ~64 ~10 ~61 concrete 11
fill ~62 ~10 ~65 ~63 ~10 ~65 concrete 11
fill ~62 ~10 ~71 ~68 ~10 ~71 concrete 11
setblock ~63 ~10 ~69 obsidian 0
fill ~64 ~10 ~66 ~65 ~10 ~66 concrete 11
fill ~64 ~10 ~69 ~65 ~10 ~69 concrete 11
fill ~65 ~10 ~62 ~66 ~10 ~62 concrete 11
fill ~65 ~10 ~65 ~66 ~10 ~65 concrete 11
fill ~66 ~10 ~67 ~67 ~10 ~67 concrete 11
fill ~67 ~10 ~63 ~68 ~10 ~63 concrete 11
fill ~67 ~10 ~66 ~68 ~10 ~66 concrete 11
setblock ~68 ~10 ~68 concrete 11
fill ~68 ~10 ~75 ~69 ~10 ~75 concrete 11
setblock ~69 ~10 ~64 concrete 11
setblock ~69 ~10 ~67 concrete 11
fill ~69 ~10 ~69 ~70 ~10 ~69 concrete 11
setblock ~69 ~10 ~72 concrete 11
fill ~70 ~10 ~65 ~71 ~10 ~65 concrete 11
fill ~70 ~10 ~73 ~71 ~10 ~73 concrete 11
setblock ~70 ~10 ~76 concrete 11
fill ~71 ~10 ~67 ~71 ~11 ~67 concrete 11
fill ~71 ~10 ~68 ~71 ~10 ~67 concrete 11
setblock ~71 ~10 ~70 concrete 11
fill ~71 ~10 ~74 ~72 ~10 ~74 concrete 11
setblock ~71 ~10 ~77 concrete 11
setblock ~72 ~10 ~66 concrete 11
fill ~72 ~10 ~69 ~73 ~10 ~69 concrete 11
setblock ~72 ~10 ~71 concrete 11
setblock ~72 ~10 ~78 concrete 11
fill ~73 ~10 ~67 ~74 ~10 ~67 concrete 11
setblock ~73 ~10 ~72 concrete 11
setblock ~73 ~10 ~75 concrete 11
setblock ~73 ~10 ~79 concrete 11
setblock ~74 ~10 ~70 concrete 11
setblock ~74 ~10 ~73 concrete 11
setblock ~74 ~10 ~76 concrete 11
fill ~75 ~10 ~68 ~75 ~11 ~68 concrete 11
setblock ~75 ~10 ~71 concrete 11
fill ~75 ~10 ~74 ~76 ~10 ~74 concrete 11
setblock ~75 ~10 ~77 concrete 11
fill ~75 ~10 ~81 ~77 ~10 ~81 concrete 11
setblock ~76 ~10 ~69 concrete 11
setblock ~76 ~10 ~72 concrete 11
setblock ~76 ~10 ~78 concrete 11
setblock ~77 ~10 ~70 concrete 11
setblock ~77 ~10 ~73 concrete 11
fill ~77 ~10 ~75 ~77 ~11 ~75 concrete 11
fill ~77 ~10 ~79 ~77 ~11 ~79 concrete 11
fill ~77 ~10 ~80 ~77 ~10 ~79 concrete 11
setblock ~78 ~10 ~71 concrete 11
fill ~78 ~10 ~74 ~80 ~10 ~74 concrete 11
fill ~78 ~10 ~76 ~78 ~11 ~76 concrete 11
setblock ~79 ~10 ~78 concrete 11
fill ~79 ~10 ~81 ~81 ~10 ~81 concrete 11
setblock ~80 ~10 ~79 concrete 11
setblock ~81 ~10 ~80 concrete 11
fill ~32 ~11 ~72 ~32 ~14 ~72 concrete 0
fill ~32 ~11 ~73 ~33 ~11 ~73 concrete 0
fill ~32 ~11 ~77 ~33 ~11 ~77 concrete 0
fill ~32 ~11 ~78 ~32 ~12 ~78 concrete 0
setblock ~32 ~11 ~79 quartz_block 0
setblock ~33 ~11 ~71 concrete 0
setblock ~33 ~11 ~72 snow 0
fill ~33 ~11 ~75 ~33 ~12 ~75 concrete 0
setblock ~33 ~11 ~76 snow 0
setblock ~33 ~11 ~78 snow 0
setblock ~33 ~11 ~80 snow 0
setblock ~33 ~11 ~81 concrete 0
setblock ~34 ~11 ~72 concrete 0
fill ~34 ~11 ~76 ~34 ~13 ~76 concrete 0
setblock ~34 ~11 ~77 quartz_block 0
fill ~34 ~11 ~78 ~34 ~12 ~78 concrete 0
fill ~34 ~11 ~80 ~34 ~12 ~80 concrete 0
setblock ~34 ~11 ~81 quartz_block 0
setblock ~35 ~11 ~77 concrete 0
setblock ~35 ~11 ~78 snow 0
setblock ~35 ~11 ~80 snow 0
setblock ~35 ~11 ~81 concrete 0
setblock ~35 ~11 ~82 wool 11
setblock ~35 ~11 ~83 concrete 11
setblock ~35 ~11 ~84 wool 11
fill ~36 ~11 ~79 ~36 ~11 ~82 concrete 11
fill ~36 ~11 ~84 ~37 ~11 ~84 concrete 11
fill ~37 ~11 ~76 ~38 ~11 ~76 concrete 11
fill ~37 ~11 ~77 ~37 ~11 ~76 concrete 11
setblock ~37 ~11 ~78 wool 11
fill ~38 ~11 ~74 ~38 ~11 ~76 concrete 11
fill ~38 ~11 ~81 ~38 ~11 ~83 concrete 11
setblock ~39 ~11 ~72 wool 11
setblock ~39 ~11 ~73 concrete 11
setblock ~39 ~11 ~78 wool 11
setblock ~39 ~11 ~79 concrete 11
setblock ~39 ~11 ~80 wool 11
fill ~40 ~11 ~69 ~41 ~11 ~69 concrete 11
fill ~40 ~11 ~70 ~40 ~11 ~71 concrete 11
fill ~40 ~11 ~76 ~40 ~11 ~78 concrete 11
fill ~41 ~11 ~67 ~42 ~11 ~67 concrete 11
setblock ~41 ~11 ~68 wool 11
setblock ~41 ~11 ~74 wool 11
setblock ~41 ~11 ~75 concrete 11
setblock ~42 ~11 ~66 concrete 11
fill ~42 ~11 ~72 ~42 ~11 ~73 concrete 11
setblock ~43 ~11 ~64 wool 11
setblock ~43 ~11 ~65 concrete 11
setblock ~43 ~11 ~66 wool 11
setblock ~43 ~11 ~70 wool 11
fill ~44 ~11 ~63 ~45 ~11 ~63 concrete 11
fill ~44 ~11 ~64 ~44 ~11 ~63 concrete 11
fill ~44 ~11 ~68 ~45 ~11 ~68 concrete 11
fill ~44 ~11 ~69 ~44 ~12 ~69 concrete 11
fill ~44 ~11 ~70 ~44 ~12 ~70 concrete 11
fill ~44 ~11 ~71 ~44 ~14 ~71 concrete 11
fill ~44 ~11 ~72 ~44 ~13 ~72 concrete 11
fill ~44 ~11 ~73 ~44 ~13 ~73 concrete 11
fill ~44 ~11 ~74 ~44 ~12 ~74 concrete 11
setblock ~45 ~11 ~62 wool 11
fill ~45 ~11 ~67 ~46 ~11 ~67 concrete 11
setblock ~45 ~11 ~70 snow 0
setblock ~45 ~11 ~71 concrete 0
setblock ~45 ~11 ~77 concrete 11
setblock ~45 ~11 ~78 wool 11
setblock ~45 ~11 ~79 concrete 0
setblock ~45 ~11 ~80 snow 0
setblock ~45 ~11 ~81 concrete 0
setblock ~45 ~11 ~82 stained_hardened_clay 0
fill ~46 ~11 ~61 ~47 ~11 ~61 concrete 11
fill ~46 ~11 ~62 ~46 ~11 ~61 concrete 11
setblock ~46 ~11 ~66 concrete 11
setblock ~46 ~11 ~70 concrete 0
setblock ~46 ~11 ~71 light_blue_glazed_terracotta 0
fill ~46 ~11 ~72 ~46 ~11 ~73 wool 10
setblock ~46 ~11 ~74 wool 11
setblock ~46 ~11 ~75 concrete 11
setblock ~46 ~11 ~78 concrete 0
setblock ~46 ~11 ~79 wool 10
setblock ~46 ~11 ~80 wool 11
setblock ~46 ~11 ~81 stained_hardened_clay 0
setblock ~46 ~11 ~82 mossy_cobblestone 0
setblock ~47 ~11 ~60 wool 11
fill ~47 ~11 ~65 ~48 ~11 ~65 concrete 11
setblock ~47 ~11 ~66 wool 11
fill ~47 ~11 ~69 ~48 ~11 ~69 concrete 11
setblock ~47 ~11 ~70 wool 11
setblock ~47 ~11 ~71 stone 4
setblock ~47 ~11 ~72 snow 0
setblock ~47 ~11 ~75 concrete 0
setblock ~47 ~11 ~76 wool 10
setblock ~47 ~11 ~77 concrete 11
setblock ~47 ~11 ~78 snow 0
setblock ~47 ~11 ~79 concrete 0
setblock ~47 ~11 ~80 light_blue_glazed_terracotta 0
setblock ~47 ~11 ~81 stained_hardened_clay 3
setblock ~47 ~11 ~82 wool 8
setblock ~47 ~11 ~83 glowstone 0
fill ~48 ~11 ~60 ~48 ~12 ~60 concrete 11
fill ~48 ~11 ~64 ~49 ~11 ~64 concrete 11
fill ~48 ~11 ~68 ~49 ~11 ~68 concrete 11
fill ~48 ~11 ~72 ~48 ~12 ~72 concrete 0
fill ~48 ~11 ~73 ~48 ~11 ~74 concrete 0
setblock ~48 ~11 ~75 purpur_pillar 0
setblock ~48 ~11 ~76 wool 11
setblock ~48 ~11 ~77 light_blue_glazed_terracotta 0
setblock ~48 ~11 ~78 concrete 0
setblock ~48 ~11 ~79 quartz_block 0
setblock ~48 ~11 ~80 wool 11
setblock ~48 ~11 ~81 concrete 10
setblock ~48 ~11 ~82 mossy_cobblestone 0
setblock ~48 ~11 ~83 wool 8
setblock ~48 ~11 ~84 mossy_cobblestone 0
fill ~49 ~11 ~59 ~53 ~11 ~59 concrete 11
fill ~49 ~11 ~63 ~51 ~11 ~63 concrete 11
fill ~49 ~11 ~67 ~54 ~11 ~67 concrete 11
setblock ~49 ~11 ~73 concrete 11
setblock ~49 ~11 ~74 wool 11
setblock ~49 ~11 ~78 snow 0
setblock ~49 ~11 ~79 purpur_pillar 0
setblock ~49 ~11 ~80 wool 10
setblock ~49 ~11 ~81 wool 11
setblock ~49 ~11 ~82 planks 2
setblock ~49 ~11 ~83 glowstone 0
setblock ~49 ~11 ~84 wool 8
fill ~50 ~11 ~62 ~50 ~12 ~62 concrete 11
fill ~50 ~11 ~70 ~50 ~11 ~72 concrete 11
setblock ~50 ~11 ~77 concrete 11
setblock ~50 ~11 ~78 wool 11
setblock ~50 ~11 ~79 wool 10
fill ~50 ~11 ~80 ~50 ~11 ~81 clay 0
setblock ~50 ~11 ~82 mossy_cobblestone 0
setblock ~50 ~11 ~83 wool 8
setblock ~50 ~11 ~84 mossy_cobblestone 0
setblock ~51 ~11 ~62 wool 11
setblock ~51 ~11 ~66 wool 11
fill ~51 ~11 ~68 ~52 ~11 ~68 concrete 11
fill ~51 ~11 ~69 ~51 ~11 ~67 concrete 11
setblock ~51 ~11 ~70 wool 11
setblock ~51 ~11 ~74 wool 11
fill ~51 ~11 ~75 ~51 ~11 ~76 concrete 11
setblock ~51 ~11 ~78 snow 0
fill ~51 ~11 ~79 ~53 ~11 ~79 concrete 0
fill ~51 ~11 ~80 ~52 ~11 ~80 concrete 0
setblock ~51 ~11 ~81 planks 2
setblock ~51 ~11 ~82 wool 8
setblock ~51 ~11 ~83 glowstone 0
setblock ~51 ~11 ~84 wool 8
fill ~52 ~11 ~61 ~58 ~11 ~61 concrete 11
fill ~52 ~11 ~62 ~52 ~11 ~61 concrete 11
fill ~52 ~11 ~66 ~52 ~12 ~66 concrete 11
fill ~52 ~11 ~72 ~52 ~11 ~73 concrete 11
setblock ~52 ~11 ~78 concrete 0
setblock ~52 ~11 ~81 stained_hardened_clay 0
setblock ~52 ~11 ~82 mossy_cobblestone 0
setblock ~52 ~11 ~83 wool 8
setblock ~52 ~11 ~84 mossy_cobblestone 0
setblock ~53 ~11 ~62 wool 11
fill ~53 ~11 ~65 ~59 ~11 ~65 concrete 11
setblock ~53 ~11 ~66 wool 11
fill ~53 ~11 ~71 ~54 ~11 ~71 concrete 11
setblock ~53 ~11 ~72 wool 11
setblock ~53 ~11 ~78 snow 0
setblock ~53 ~11 ~80 snow 0
setblock ~53 ~11 ~81 sandstone 2
setblock ~53 ~11 ~82 wool 8
setblock ~53 ~11 ~83 glowstone 0
setblock ~53 ~11 ~84 wool 8
setblock ~53 ~11 ~85 glowstone 0
fill ~54 ~11 ~58 ~56 ~11 ~58 concrete 11
setblock ~54 ~11 ~62 concrete 11
fill ~54 ~11 ~66 ~54 ~10 ~66 concrete 11
setblock ~54 ~11 ~70 concrete 11
setblock ~54 ~11 ~79 snow 0
fill ~54 ~11 ~80 ~60 ~11 ~80 concrete 0
fill ~54 ~11 ~81 ~54 ~11 ~80 concrete 0
setblock ~54 ~11 ~82 mossy_cobblestone 0
fill ~54 ~11 ~83 ~58 ~11 ~83 wool 8
setblock ~54 ~11 ~84 mossy_cobblestone 0
fill ~54 ~11 ~85 ~56 ~11 ~85 wool 8
setblock ~55 ~11 ~62 wool 11
setblock ~55 ~11 ~66 wool 11
setblock ~55 ~11 ~70 wool 11
setblock ~55 ~11 ~79 concrete 0
setblock ~55 ~11 ~81 stained_hardened_clay 0
setblock ~55 ~11 ~82 planks 2
setblock ~55 ~11 ~84 wool 8
fill ~56 ~11 ~62 ~56 ~10 ~62 concrete 11
fill ~56 ~11 ~66 ~56 ~11 ~67 concrete 11
setblock ~56 ~11 ~70 concrete 11
setblock ~56 ~11 ~79 quartz_block 1
fill ~56 ~11 ~81 ~58 ~11 ~81 clay 0
setblock ~56 ~11 ~82 cobblestone 0
setblock ~56 ~11 ~84 mossy_cobblestone 0
setblock ~57 ~11 ~58 wool 11
setblock ~57 ~11 ~62 wool 11
fill ~57 ~11 ~67 ~58 ~11 ~67 concrete 11
setblock ~57 ~11 ~70 wool 11
fill ~57 ~11 ~71 ~59 ~11 ~71 concrete 11
fill ~57 ~11 ~79 ~59 ~11 ~79 concrete 0
setblock ~57 ~11 ~82 wool 8
setblock ~57 ~11 ~84 wool 8
setblock ~57 ~11 ~85 glowstone 0
setblock ~58 ~11 ~58 concrete 11
setblock ~58 ~11 ~62 concrete 11
fill ~58 ~11 ~68 ~60 ~11 ~68 concrete 11
setblock ~58 ~11 ~82 cobblestone 0
setblock ~58 ~11 ~84 mossy_cobblestone 0
fill ~59 ~11 ~58 ~63 ~11 ~58 obsidian 0
fill ~59 ~11 ~59 ~61 ~11 ~59 concrete 11
setblock ~59 ~11 ~62 wool 11
fill ~59 ~11 ~66 ~60 ~11 ~66 concrete 11
fill ~59 ~11 ~67 ~61 ~11 ~67 obsidian 0
fill ~59 ~11 ~72 ~60 ~11 ~72 concrete 11
setblock ~59 ~11 ~78 snow 0
fill ~59 ~11 ~81 ~60 ~11 ~81 concrete 0
setblock ~59 ~11 ~82 clay 0
setblock ~59 ~11 ~83 mossy_cobblestone 0
setblock ~59 ~11 ~84 wool 8
fill ~60 ~11 ~57 ~60 ~12 ~57 obsidian 0
fill ~60 ~11 ~62 ~60 ~12 ~62 concrete 11
fill ~60 ~11 ~63 ~61 ~11 ~63 concrete 11
fill ~60 ~11 ~69 ~67 ~11 ~69 concrete 11
setblock ~60 ~11 ~78 concrete 0
setblock ~60 ~11 ~79 snow 0
fill ~60 ~11 ~82 ~60 ~11 ~83 wool 8
setblock ~60 ~11 ~84 mossy_cobblestone 0
setblock ~61 ~11 ~62 wool 11
setblock ~61 ~11 ~66 wool 11
setblock ~61 ~11 ~68 obsidian 0
setblock ~61 ~11 ~72 wool 11
fill ~61 ~11 ~73 ~68 ~11 ~73 concrete 11
setblock ~61 ~11 ~78 snow 0
fill ~61 ~11 ~79 ~65 ~11 ~79 concrete 0
setblock ~61 ~11 ~80 quartz_block 0
setblock ~61 ~11 ~81 sandstone 2
setblock ~61 ~11 ~82 planks 2
fill ~61 ~11 ~83 ~62 ~11 ~83 wool 8
fill ~61 ~11 ~84 ~61 ~11 ~83 wool 8
fill ~62 ~11 ~59 ~63 ~11 ~59 obsidian 0
setblock ~62 ~11 ~60 concrete 11
setblock ~62 ~11 ~62 concrete 11
fill ~62 ~11 ~64 ~63 ~11 ~64 concrete 11
fill ~62 ~11 ~67 ~63 ~11 ~67 concrete 11
fill ~62 ~11 ~72 ~64 ~11 ~72 concrete 11
setblock ~62 ~11 ~77 snow 0
setblock ~62 ~11 ~78 concrete 0
fill ~62 ~11 ~80 ~63 ~11 ~80 clay 0
fill ~62 ~11 ~81 ~62 ~11 ~80 clay 0
setblock ~62 ~11 ~82 mossy_cobblestone 0
setblock ~62 ~11 ~84 mossy_cobblestone 0
setblock ~63 ~11 ~60 wool 11
fill ~63 ~11 ~63 ~64 ~11 ~63 concrete 11
setblock ~63 ~11 ~68 obsidian 0
setblock ~63 ~11 ~77 concrete 0
setblock ~63 ~11 ~78 quartz_block 0
fill ~63 ~11 ~81 ~69 ~11 ~81 wool 8
fill ~63 ~11 ~82 ~63 ~11 ~81 wool 8
setblock ~63 ~11 ~83 glowstone 0
setblock ~63 ~11 ~84 wool 8
fill ~64 ~11 ~61 ~65 ~11 ~61 concrete 11
fill ~64 ~11 ~65 ~65 ~11 ~65 concrete 11
fill ~64 ~11 ~68 ~64 ~12 ~68 concrete 11
setblock ~64 ~11 ~77 snow 0
setblock ~64 ~11 ~78 concrete 0
setblock ~64 ~11 ~80 wool 8
setblock ~64 ~11 ~82 mossy_cobblestone 0
fill ~64 ~11 ~83 ~66 ~11 ~83 wool 8
setblock ~65 ~11 ~64 wool 11
setblock ~65 ~11 ~68 wool 11
setblock ~65 ~11 ~72 wool 11
setblock ~65 ~11 ~77 concrete 0
setblock ~65 ~11 ~78 quartz_block 0
setblock ~65 ~11 ~80 clay 0
setblock ~65 ~11 ~82 wool 8
setblock ~66 ~11 ~62 concrete 11
setblock ~66 ~11 ~64 concrete 11
setblock ~66 ~11 ~66 concrete 11
setblock ~66 ~11 ~70 concrete 11
setblock ~66 ~11 ~72 concrete 11
setblock ~66 ~11 ~77 quartz_block 0
setblock ~66 ~11 ~78 sandstone 2
setblock ~66 ~11 ~79 clay 0
setblock ~66 ~11 ~80 mossy_cobblestone 0
setblock ~66 ~11 ~82 mossy_cobblestone 0
setblock ~67 ~11 ~62 wool 11
fill ~67 ~11 ~65 ~68 ~11 ~65 concrete 11
fill ~67 ~11 ~67 ~68 ~11 ~67 concrete 11
setblock ~67 ~11 ~70 wool 11
fill ~67 ~11 ~77 ~67 ~11 ~78 concrete 0
fill ~67 ~11 ~79 ~67 ~11 ~82 wool 8
fill ~68 ~11 ~63 ~69 ~11 ~63 concrete 11
setblock ~68 ~11 ~70 concrete 11
setblock ~68 ~11 ~74 concrete 11
setblock ~68 ~11 ~77 wool 0
setblock ~68 ~11 ~78 clay 0
setblock ~68 ~11 ~79 planks 2
setblock ~68 ~11 ~80 mossy_cobblestone 0
setblock ~69 ~11 ~66 wool 11
setblock ~69 ~11 ~68 wool 11
setblock ~69 ~11 ~71 concrete 11
setblock ~69 ~11 ~74 wool 11
setblock ~69 ~11 ~78 concrete 0
setblock ~69 ~11 ~79 clay 0
setblock ~69 ~11 ~80 wool 8
setblock ~70 ~11 ~64 concrete 11
fill ~70 ~11 ~66 ~70 ~12 ~66 concrete 11
fill ~70 ~11 ~69 ~71 ~11 ~69 concrete 11
fill ~70 ~11 ~72 ~71 ~11 ~72 concrete 11
setblock ~70 ~11 ~75 concrete 11
fill ~71 ~11 ~65 ~72 ~11 ~65 concrete 11
fill ~71 ~11 ~73 ~72 ~11 ~73 concrete 11
setblock ~71 ~11 ~76 concrete 11
setblock ~72 ~11 ~68 concrete 11
setblock ~72 ~11 ~70 concrete 11
setblock ~72 ~11 ~77 concrete 11
setblock ~73 ~11 ~66 wool 11
fill ~73 ~11 ~69 ~74 ~11 ~69 concrete 11
setblock ~73 ~11 ~71 concrete 11
setblock ~73 ~11 ~74 wool 11
setblock ~73 ~11 ~78 wool 11
setblock ~74 ~11 ~67 concrete 11
setblock ~74 ~11 ~72 concrete 11
setblock ~74 ~11 ~75 concrete 11
setblock ~74 ~11 ~79 concrete 11
setblock ~75 ~11 ~70 wool 11
setblock ~75 ~11 ~73 concrete 11
setblock ~75 ~11 ~76 concrete 11
setblock ~75 ~11 ~80 concrete 11
fill ~76 ~11 ~68 ~76 ~12 ~68 concrete 11
setblock ~76 ~11 ~71 concrete 11
setblock ~76 ~11 ~74 concrete 11
setblock ~76 ~11 ~77 concrete 11
fill ~76 ~11 ~81 ~77 ~11 ~81 concrete 11
fill ~77 ~11 ~69 ~77 ~12 ~69 concrete 11
setblock ~77 ~11 ~72 wool 11
setblock ~77 ~11 ~78 wool 11
setblock ~77 ~11 ~82 wool 11
setblock ~78 ~11 ~70 concrete 11
setblock ~78 ~11 ~73 concrete 11
fill ~78 ~11 ~79 ~78 ~12 ~79 concrete 11
setblock ~79 ~11 ~71 concrete 11
setblock ~79 ~11 ~74 wool 11
setblock ~79 ~11 ~77 concrete 11
fill ~79 ~11 ~80 ~79 ~12 ~80 concrete 11
fill ~79 ~11 ~81 ~80 ~11 ~81 concrete 11
setblock ~80 ~11 ~72 concrete 11
fill ~80 ~11 ~74 ~80 ~13 ~74 concrete 11
setblock ~80 ~11 ~78 concrete 11
setblock ~81 ~11 ~73 concrete 11
setblock ~81 ~11 ~74 wool 11
fill ~81 ~11 ~79 ~81 ~12 ~79 concrete 11
fill ~81 ~11 ~82 ~82 ~11 ~82 concrete 11
fill ~82 ~11 ~80 ~82 ~12 ~80 concrete 11
fill ~82 ~11 ~81 ~82 ~11 ~80 concrete 11
fill ~31 ~12 ~72 ~31 ~12 ~74 concrete 0
fill ~32 ~12 ~73 ~33 ~12 ~73 concrete 0
fill ~32 ~12 ~74 ~34 ~12 ~74 concrete 0
fill ~32 ~12 ~75 ~32 ~12 ~78 concrete 0
setblock ~33 ~12 ~78 concrete 0
setblock ~33 ~12 ~80 concrete 0
fill ~34 ~12 ~75 ~34 ~14 ~75 concrete 0
fill ~34 ~12 ~77 ~34 ~13 ~77 concrete 0
fill ~34 ~12 ~82 ~34 ~13 ~82 concrete 11
fill ~34 ~12 ~83 ~34 ~12 ~85 concrete 11
fill ~35 ~12 ~79 ~35 ~12 ~81 concrete 11
fill ~35 ~12 ~85 ~36 ~12 ~85 concrete 11
fill ~36 ~12 ~76 ~36 ~12 ~78 concrete 11
fill ~36 ~12 ~84 ~36 ~11 ~84 concrete 11
fill ~37 ~12 ~73 ~38 ~12 ~73 concrete 11
fill ~37 ~12 ~74 ~37 ~12 ~75 concrete 11
fill ~37 ~12 ~81 ~37 ~12 ~83 concrete 11
fill ~38 ~12 ~71 ~39 ~12 ~71 concrete 11
fill ~38 ~12 ~72 ~38 ~12 ~71 concrete 11
fill ~38 ~12 ~78 ~38 ~12 ~80 concrete 11
fill ~39 ~12 ~69 ~39 ~12 ~71 concrete 11
fill ~39 ~12 ~75 ~40 ~12 ~75 concrete 11
fill ~39 ~12 ~76 ~39 ~12 ~77 concrete 11
fill ~40 ~12 ~67 ~40 ~12 ~68 concrete 11
fill ~40 ~12 ~73 ~41 ~12 ~73 concrete 11
fill ~40 ~12 ~74 ~40 ~12 ~73 concrete 11
fill ~41 ~12 ~65 ~42 ~12 ~65 concrete 11
fill ~41 ~12 ~66 ~41 ~12 ~65 concrete 11
fill ~41 ~12 ~71 ~42 ~12 ~71 concrete 11
fill ~41 ~12 ~72 ~41 ~12 ~71 concrete 11
setblock ~42 ~12 ~64 concrete 11
fill ~42 ~12 ~69 ~44 ~12 ~69 concrete 11
fill ~42 ~12 ~70 ~42 ~12 ~69 concrete 11
fill ~42 ~12 ~80 ~42 ~12 ~82 concrete 0
fill ~42 ~12 ~83 ~43 ~12 ~83 clay 0
fill ~42 ~12 ~84 ~45 ~12 ~84 wool 8
setblock ~43 ~12 ~63 concrete 11
fill ~43 ~12 ~68 ~44 ~12 ~68 concrete 11
setblock ~43 ~12 ~78 wool 0
fill ~43 ~12 ~79 ~44 ~12 ~79 concrete 0
setblock ~43 ~12 ~80 wool 0
fill ~43 ~12 ~81 ~44 ~12 ~81 concrete 0
fill ~43 ~12 ~82 ~43 ~12 ~81 concrete 0
fill ~44 ~12 ~61 ~45 ~12 ~61 concrete 11
fill ~44 ~12 ~62 ~44 ~12 ~61 concrete 11
fill ~44 ~12 ~66 ~45 ~12 ~66 concrete 11
fill ~44 ~12 ~67 ~44 ~13 ~67 concrete 11
fill ~44 ~12 ~76 ~44 ~12 ~81 concrete 0
setblock ~44 ~12 ~82 stained_hardened_clay 0
fill ~44 ~12 ~83 ~45 ~12 ~83 wool 8
fill ~44 ~12 ~85 ~48 ~12 ~85 mossy_cobblestone 0
fill ~45 ~12 ~65 ~46 ~12 ~65 concrete 11
fill ~45 ~12 ~75 ~46 ~12 ~75 concrete 0
setblock ~45 ~12 ~76 wool 10
setblock ~45 ~12 ~77 light_blue_glazed_terracotta 0
setblock ~45 ~12 ~78 quartz_block 0
setblock ~45 ~12 ~86 wool 8
fill ~46 ~12 ~60 ~59 ~12 ~60 concrete 11
fill ~46 ~12 ~64 ~47 ~12 ~64 concrete 11
setblock ~46 ~12 ~69 concrete 11
setblock ~46 ~12 ~70 light_blue_glazed_terracotta 0
fill ~46 ~12 ~71 ~46 ~13 ~71 stone 3
setblock ~46 ~12 ~72 light_blue_glazed_terracotta 0
setblock ~46 ~12 ~73 wool 11
setblock ~46 ~12 ~74 concrete 11
fill ~46 ~12 ~76 ~46 ~12 ~77 concrete 0
fill ~46 ~12 ~78 ~49 ~12 ~78 concrete 11
setblock ~46 ~12 ~83 log2 0
setblock ~46 ~12 ~84 mossy_cobblestone 0
setblock ~46 ~12 ~86 glowstone 0
fill ~47 ~12 ~63 ~48 ~12 ~63 concrete 11
fill ~47 ~12 ~67 ~48 ~12 ~67 concrete 11
fill ~47 ~12 ~68 ~47 ~12 ~67 concrete 11
fill ~47 ~12 ~69 ~47 ~12 ~73 concrete 0
fill ~47 ~12 ~74 ~47 ~12 ~75 light_blue_glazed_terracotta 0
setblock ~47 ~12 ~76 quartz_block 0
setblock ~47 ~12 ~77 concrete 0
fill ~47 ~12 ~79 ~48 ~12 ~79 concrete 11
setblock ~47 ~12 ~84 wool 8
setblock ~47 ~12 ~86 wool 8
fill ~47 ~12 ~87 ~49 ~12 ~87 mossy_cobblestone 0
fill ~48 ~12 ~62 ~50 ~12 ~62 concrete 11
fill ~48 ~12 ~66 ~50 ~12 ~66 concrete 11
setblock ~48 ~12 ~71 concrete 0
setblock ~48 ~12 ~73 wool 10
setblock ~48 ~12 ~74 concrete 11
fill ~48 ~12 ~75 ~49 ~12 ~75 concrete 0
fill ~48 ~12 ~76 ~48 ~12 ~75 concrete 0
setblock ~48 ~12 ~86 mossy_cobblestone 0
fill ~49 ~12 ~61 ~53 ~12 ~61 concrete 11
fill ~49 ~12 ~70 ~49 ~13 ~70 concrete 11
fill ~49 ~12 ~71 ~49 ~12 ~72 concrete 11
setblock ~49 ~12 ~74 quartz_block 0
setblock ~49 ~12 ~76 quartz_block 0
setblock ~49 ~12 ~77 wool 10
setblock ~49 ~12 ~85 glowstone 0
setblock ~49 ~12 ~86 wool 8
fill ~50 ~12 ~65 ~57 ~12 ~65 concrete 11
fill ~50 ~12 ~68 ~50 ~12 ~69 concrete 11
fill ~50 ~12 ~75 ~50 ~12 ~76 wool 10
fill ~50 ~12 ~77 ~61 ~12 ~77 concrete 0
fill ~50 ~12 ~85 ~52 ~12 ~85 mossy_cobblestone 0
setblock ~50 ~12 ~86 glowstone 0
setblock ~50 ~12 ~87 log2 0
fill ~51 ~12 ~64 ~59 ~12 ~64 concrete 11
setblock ~51 ~12 ~67 concrete 11
fill ~51 ~12 ~72 ~51 ~12 ~74 concrete 11
fill ~51 ~12 ~75 ~51 ~12 ~77 concrete 0
setblock ~51 ~12 ~86 wool 8
fill ~51 ~12 ~87 ~53 ~12 ~87 mossy_cobblestone 0
fill ~52 ~12 ~59 ~63 ~12 ~59 concrete 11
fill ~52 ~12 ~70 ~53 ~12 ~70 concrete 11
fill ~52 ~12 ~71 ~52 ~12 ~70 concrete 11
setblock ~52 ~12 ~76 concrete 0
setblock ~52 ~12 ~86 glowstone 0
fill ~53 ~12 ~69 ~58 ~12 ~69 concrete 11
setblock ~53 ~12 ~76 snow 0
setblock ~53 ~12 ~86 wool 8
fill ~54 ~12 ~68 ~56 ~12 ~68 concrete 11
fill ~54 ~12 ~76 ~56 ~12 ~76 concrete 0
setblock ~54 ~12 ~78 concrete 0
setblock ~54 ~12 ~86 glowstone 0
setblock ~54 ~12 ~87 log2 0
fill ~55 ~12 ~63 ~55 ~13 ~63 concrete 11
setblock ~55 ~12 ~78 snow 0
setblock ~55 ~12 ~86 wool 8
fill ~55 ~12 ~87 ~61 ~12 ~87 mossy_cobblestone 0
setblock ~56 ~12 ~78 concrete 0
setblock ~56 ~12 ~86 glowstone 0
fill ~57 ~12 ~61 ~62 ~12 ~61 concrete 11
fill ~57 ~12 ~66 ~58 ~12 ~66 concrete 11
setblock ~57 ~12 ~76 snow 0
setblock ~57 ~12 ~78 snow 0
setblock ~57 ~12 ~86 wool 8
fill ~58 ~12 ~70 ~60 ~12 ~70 concrete 11
fill ~58 ~12 ~75 ~69 ~12 ~75 concrete 0
fill ~58 ~12 ~76 ~60 ~12 ~76 concrete 0
setblock ~58 ~12 ~78 concrete 0
fill ~58 ~12 ~85 ~67 ~12 ~85 mossy_cobblestone 0
fill ~58 ~12 ~86 ~58 ~12 ~85 mossy_cobblestone 0
fill ~59 ~12 ~58 ~63 ~12 ~58 obsidian 0
fill ~59 ~12 ~65 ~59 ~12 ~66 obsidian 0
fill ~59 ~12 ~67 ~60 ~12 ~67 concrete 11
setblock ~59 ~12 ~86 wool 8
fill ~60 ~12 ~65 ~62 ~12 ~65 concrete 11
fill ~60 ~12 ~71 ~66 ~12 ~71 concrete 11
setblock ~60 ~12 ~86 mossy_cobblestone 0
setblock ~61 ~12 ~62 concrete 11
fill ~61 ~12 ~66 ~61 ~13 ~66 obsidian 0
fill ~61 ~12 ~67 ~61 ~12 ~66 obsidian 0
fill ~61 ~12 ~68 ~67 ~12 ~68 concrete 11
setblock ~61 ~12 ~76 snow 0
fill ~61 ~12 ~86 ~63 ~12 ~86 wool 8
fill ~62 ~12 ~63 ~63 ~12 ~63 concrete 11
fill ~62 ~12 ~66 ~63 ~12 ~66 concrete 11
setblock ~62 ~12 ~76 concrete 0
setblock ~62 ~12 ~87 log2 0
fill ~63 ~12 ~62 ~64 ~12 ~62 concrete 11
setblock ~63 ~12 ~67 obsidian 0
setblock ~63 ~12 ~74 snow 0
setblock ~63 ~12 ~76 snow 0
setblock ~63 ~12 ~87 mossy_cobblestone 0
fill ~64 ~12 ~60 ~65 ~12 ~60 concrete 11
fill ~64 ~12 ~64 ~65 ~12 ~64 concrete 11
fill ~64 ~12 ~67 ~65 ~12 ~67 concrete 11
fill ~64 ~12 ~73 ~64 ~12 ~76 concrete 0
setblock ~64 ~12 ~84 glowstone 0
setblock ~64 ~12 ~86 glowstone 0
fill ~65 ~12 ~63 ~66 ~12 ~63 concrete 11
fill ~65 ~12 ~74 ~68 ~12 ~74 concrete 0
setblock ~65 ~12 ~76 snow 0
setblock ~65 ~12 ~84 wool 8
setblock ~65 ~12 ~86 wool 8
fill ~66 ~12 ~61 ~67 ~12 ~61 concrete 11
setblock ~66 ~12 ~65 concrete 11
fill ~66 ~12 ~69 ~68 ~12 ~69 concrete 11
setblock ~66 ~12 ~73 concrete 0
fill ~66 ~12 ~76 ~70 ~12 ~76 concrete 0
setblock ~66 ~12 ~84 mossy_cobblestone 0
setblock ~66 ~12 ~86 glowstone 0
fill ~67 ~12 ~64 ~68 ~12 ~64 concrete 11
fill ~67 ~12 ~66 ~68 ~12 ~66 concrete 11
fill ~67 ~12 ~72 ~68 ~12 ~72 concrete 11
fill ~67 ~12 ~83 ~71 ~12 ~83 mossy_cobblestone 0
setblock ~67 ~12 ~84 wool 8
setblock ~67 ~12 ~86 wool 8
setblock ~68 ~12 ~62 concrete 11
setblock ~68 ~12 ~82 glowstone 0
setblock ~68 ~12 ~84 glowstone 0
setblock ~68 ~12 ~85 log2 0
fill ~69 ~12 ~63 ~70 ~12 ~63 concrete 11
setblock ~69 ~12 ~65 concrete 11
setblock ~69 ~12 ~67 concrete 11
setblock ~69 ~12 ~70 concrete 11
setblock ~69 ~12 ~73 concrete 11
fill ~69 ~12 ~77 ~71 ~12 ~77 concrete 0
setblock ~69 ~12 ~82 wool 8
setblock ~69 ~12 ~84 wool 8
fill ~70 ~12 ~68 ~71 ~12 ~68 concrete 11
fill ~70 ~12 ~71 ~71 ~12 ~71 concrete 11
setblock ~70 ~12 ~74 concrete 11
fill ~70 ~12 ~78 ~71 ~12 ~78 concrete 0
setblock ~70 ~12 ~79 clay 0
setblock ~70 ~12 ~80 wool 8
setblock ~70 ~12 ~81 mossy_cobblestone 0
setblock ~70 ~12 ~82 glowstone 0
setblock ~70 ~12 ~84 mossy_cobblestone 0
setblock ~71 ~12 ~64 concrete 11
fill ~71 ~12 ~66 ~71 ~13 ~66 concrete 11
fill ~71 ~12 ~72 ~72 ~12 ~72 concrete 11
setblock ~71 ~12 ~75 concrete 11
fill ~71 ~12 ~79 ~71 ~12 ~80 stained_hardened_clay 0
setblock ~71 ~12 ~81 glowstone 0
setblock ~71 ~12 ~82 wool 8
fill ~72 ~12 ~65 ~73 ~12 ~65 concrete 11
setblock ~72 ~12 ~67 concrete 11
fill ~72 ~12 ~69 ~72 ~13 ~69 concrete 11
setblock ~72 ~12 ~76 concrete 11
setblock ~72 ~12 ~79 concrete 0
setblock ~72 ~12 ~80 stained_hardened_clay 0
setblock ~72 ~12 ~81 wool 8
setblock ~72 ~12 ~82 glowstone 0
setblock ~73 ~12 ~68 concrete 11
setblock ~73 ~12 ~70 concrete 11
setblock ~73 ~12 ~73 concrete 11
setblock ~73 ~12 ~77 concrete 11
fill ~74 ~12 ~66 ~74 ~13 ~66 concrete 11
fill ~74 ~12 ~69 ~75 ~12 ~69 concrete 11
setblock ~74 ~12 ~71 concrete 11
setblock ~74 ~12 ~74 concrete 11
setblock ~74 ~12 ~78 concrete 11
setblock ~75 ~12 ~67 concrete 11
setblock ~75 ~12 ~72 concrete 11
setblock ~75 ~12 ~75 concrete 11
setblock ~75 ~12 ~79 concrete 11
fill ~76 ~12 ~70 ~76 ~13 ~70 concrete 11
setblock ~76 ~12 ~73 concrete 11
setblock ~76 ~12 ~76 concrete 11
fill ~76 ~12 ~80 ~77 ~12 ~80 concrete 11
fill ~77 ~12 ~71 ~77 ~13 ~71 concrete 11
setblock ~77 ~12 ~74 concrete 11
fill ~77 ~12 ~77 ~77 ~13 ~77 concrete 11
fill ~77 ~12 ~78 ~78 ~12 ~78 concrete 11
setblock ~77 ~12 ~81 concrete 11
fill ~78 ~12 ~69 ~78 ~13 ~69 concrete 11
fill ~78 ~12 ~72 ~78 ~13 ~72 concrete 11
setblock ~78 ~12 ~75 concrete 11
fill ~79 ~12 ~70 ~79 ~13 ~70 concrete 11
fill ~79 ~12 ~73 ~79 ~13 ~73 concrete 11
setblock ~79 ~12 ~76 concrete 11
fill ~79 ~12 ~79 ~79 ~13 ~79 concrete 11
fill ~80 ~12 ~71 ~80 ~13 ~71 concrete 11
setblock ~80 ~12 ~77 concrete 11
setblock ~80 ~12 ~81 concrete 11
setblock ~81 ~12 ~72 concrete 11
fill ~81 ~12 ~74 ~81 ~13 ~74 concrete 11
setblock ~81 ~12 ~78 concrete 11
fill ~81 ~12 ~82 ~81 ~11 ~82 concrete 11
fill ~82 ~12 ~73 ~82 ~14 ~73 concrete 11
fill ~82 ~12 ~83 ~84 ~12 ~83 concrete 11
fill ~83 ~12 ~81 ~83 ~13 ~81 concrete 11
fill ~83 ~12 ~82 ~84 ~12 ~82 concrete 11
fill ~31 ~13 ~73 ~34 ~13 ~73 concrete 0
setblock ~31 ~13 ~74 snow 0
setblock ~31 ~13 ~75 concrete 0
fill ~32 ~13 ~74 ~32 ~15 ~74 concrete 0
setblock ~32 ~13 ~75 quartz_block 0
fill ~32 ~13 ~76 ~32 ~14 ~76 concrete 0
fill ~32 ~13 ~77 ~34 ~13 ~77 concrete 0
setblock ~33 ~13 ~72 snow 0
setblock ~33 ~13 ~76 snow 0
setblock ~33 ~13 ~78 quartz_block 0
setblock ~33 ~13 ~83 concrete 11
setblock ~33 ~13 ~84 wool 11
fill ~33 ~13 ~85 ~33 ~13 ~86 concrete 11
fill ~34 ~13 ~74 ~34 ~14 ~74 concrete 0
fill ~34 ~13 ~79 ~34 ~13 ~82 concrete 11
fill ~34 ~13 ~86 ~34 ~14 ~86 concrete 11
setblock ~35 ~13 ~76 wool 11
setblock ~35 ~13 ~77 concrete 11
setblock ~35 ~13 ~78 wool 11
setblock ~35 ~13 ~84 wool 11
fill ~35 ~13 ~85 ~35 ~12 ~85 concrete 11
setblock ~35 ~13 ~86 wool 11
fill ~36 ~13 ~73 ~36 ~13 ~75 concrete 11
fill ~36 ~13 ~81 ~36 ~13 ~83 concrete 11
setblock ~37 ~13 ~71 concrete 11
setblock ~37 ~13 ~72 wool 11
fill ~37 ~13 ~78 ~37 ~13 ~79 concrete 11
setblock ~37 ~13 ~80 wool 11
fill ~38 ~13 ~69 ~38 ~13 ~70 concrete 11
fill ~38 ~13 ~75 ~38 ~13 ~77 concrete 11
setblock ~39 ~13 ~67 concrete 11
setblock ~39 ~13 ~68 wool 11
setblock ~39 ~13 ~73 concrete 11
setblock ~39 ~13 ~74 wool 11
fill ~40 ~13 ~65 ~40 ~13 ~66 concrete 11
fill ~40 ~13 ~71 ~40 ~13 ~72 concrete 11
fill ~40 ~13 ~82 ~40 ~13 ~85 concrete 0
fill ~41 ~13 ~63 ~42 ~13 ~63 concrete 11
setblock ~41 ~13 ~64 wool 11
fill ~41 ~13 ~69 ~41 ~13 ~70 concrete 11
setblock ~41 ~13 ~79 concrete 0
setblock ~41 ~13 ~80 snow 0
setblock ~41 ~13 ~81 concrete 0
setblock ~41 ~13 ~82 snow 0
fill ~41 ~13 ~83 ~41 ~13 ~84 concrete 0
setblock ~41 ~13 ~85 planks 2
setblock ~41 ~13 ~86 wool 8
setblock ~41 ~13 ~87 glowstone 0
fill ~42 ~13 ~62 ~42 ~14 ~62 concrete 11
fill ~42 ~13 ~67 ~44 ~13 ~67 concrete 11
fill ~42 ~13 ~68 ~42 ~13 ~67 concrete 11
setblock ~42 ~13 ~77 snow 0
setblock ~42 ~13 ~78 concrete 0
setblock ~42 ~13 ~79 snow 0
setblock ~42 ~13 ~85 wool 8
setblock ~42 ~13 ~86 mossy_cobblestone 0
fill ~42 ~13 ~87 ~46 ~13 ~87 wool 8
fill ~43 ~13 ~61 ~51 ~13 ~61 concrete 11
setblock ~43 ~13 ~62 wool 11
setblock ~43 ~13 ~66 wool 11
setblock ~43 ~13 ~68 wool 11
fill ~43 ~13 ~69 ~43 ~15 ~69 concrete 11
setblock ~43 ~13 ~70 wool 11
setblock ~43 ~13 ~75 concrete 0
setblock ~43 ~13 ~76 snow 0
setblock ~43 ~13 ~77 concrete 0
setblock ~43 ~13 ~85 glowstone 0
setblock ~43 ~13 ~86 wool 8
setblock ~43 ~13 ~88 wool 8
fill ~44 ~13 ~64 ~44 ~14 ~64 concrete 11
fill ~44 ~13 ~65 ~44 ~13 ~67 concrete 11
setblock ~44 ~13 ~74 stone 3
setblock ~44 ~13 ~75 snow 0
setblock ~44 ~13 ~86 mossy_cobblestone 0
setblock ~44 ~13 ~88 mossy_cobblestone 0
setblock ~44 ~13 ~89 wool 8
fill ~45 ~13 ~63 ~46 ~13 ~63 concrete 11
setblock ~45 ~13 ~64 wool 11
fill ~45 ~13 ~69 ~45 ~14 ~69 concrete 11
fill ~45 ~13 ~70 ~45 ~13 ~69 concrete 11
setblock ~45 ~13 ~73 concrete 0
setblock ~45 ~13 ~74 snow 0
setblock ~45 ~13 ~75 concrete 11
setblock ~45 ~13 ~88 wool 8
setblock ~45 ~13 ~89 glowstone 0
fill ~46 ~13 ~62 ~46 ~14 ~62 concrete 11
setblock ~46 ~13 ~67 concrete 11
setblock ~46 ~13 ~68 light_blue_glazed_terracotta 0
fill ~46 ~13 ~69 ~46 ~14 ~69 concrete 0
fill ~46 ~13 ~70 ~46 ~13 ~69 concrete 0
setblock ~46 ~13 ~72 concrete 11
setblock ~46 ~13 ~73 quartz_block 0
setblock ~46 ~13 ~74 concrete 0
fill ~46 ~13 ~76 ~46 ~13 ~77 concrete 11
setblock ~46 ~13 ~88 mossy_cobblestone 0
setblock ~46 ~13 ~89 wool 8
setblock ~47 ~13 ~62 wool 11
setblock ~47 ~13 ~66 wool 11
setblock ~47 ~13 ~68 snow 0
setblock ~47 ~13 ~72 concrete 0
setblock ~47 ~13 ~73 wool 10
setblock ~47 ~13 ~76 wool 11
fill ~47 ~13 ~77 ~48 ~13 ~77 concrete 11
setblock ~47 ~13 ~88 wool 8
setblock ~47 ~13 ~89 glowstone 0
fill ~48 ~13 ~65 ~49 ~13 ~65 concrete 11
fill ~48 ~13 ~69 ~48 ~13 ~70 concrete 0
setblock ~48 ~13 ~71 wool 10
setblock ~48 ~13 ~72 concrete 11
setblock ~48 ~13 ~73 quartz_block 0
setblock ~48 ~13 ~74 concrete 0
setblock ~48 ~13 ~76 concrete 11
setblock ~48 ~13 ~88 mossy_cobblestone 0
setblock ~48 ~13 ~89 wool 8
setblock ~49 ~13 ~64 wool 11
setblock ~49 ~13 ~68 wool 11
setblock ~49 ~13 ~69 concrete 11
setblock ~49 ~13 ~73 concrete 0
setblock ~49 ~13 ~75 concrete 11
setblock ~49 ~13 ~76 wool 11
setblock ~49 ~13 ~88 wool 8
setblock ~49 ~13 ~89 glowstone 0
fill ~50 ~13 ~63 ~60 ~13 ~63 concrete 11
fill ~50 ~13 ~64 ~50 ~13 ~63 concrete 11
fill ~50 ~13 ~66 ~51 ~13 ~66 concrete 11
fill ~50 ~13 ~67 ~50 ~13 ~66 concrete 11
setblock ~50 ~13 ~72 concrete 11
fill ~50 ~13 ~73 ~50 ~13 ~74 wool 10
setblock ~50 ~13 ~88 mossy_cobblestone 0
setblock ~50 ~13 ~89 wool 8
fill ~51 ~13 ~65 ~52 ~13 ~65 concrete 11
fill ~51 ~13 ~70 ~51 ~13 ~71 concrete 11
setblock ~51 ~13 ~74 snow 0
setblock ~51 ~13 ~88 wool 8
setblock ~51 ~13 ~89 glowstone 0
setblock ~52 ~13 ~60 concrete 11
setblock ~52 ~13 ~64 concrete 11
setblock ~52 ~13 ~69 concrete 11
setblock ~52 ~13 ~74 concrete 0
setblock ~52 ~13 ~75 snow 0
setblock ~52 ~13 ~88 mossy_cobblestone 0
setblock ~52 ~13 ~89 wool 8
setblock ~53 ~13 ~60 wool 11
setblock ~53 ~13 ~62 wool 11
setblock ~53 ~13 ~64 wool 11
fill ~53 ~13 ~67 ~56 ~13 ~67 concrete 11
setblock ~53 ~13 ~68 wool 11
setblock ~53 ~13 ~74 snow 0
setblock ~53 ~13 ~75 concrete 0
setblock ~53 ~13 ~88 wool 8
setblock ~53 ~13 ~89 glowstone 0
fill ~54 ~13 ~60 ~56 ~13 ~60 concrete 11
fill ~54 ~13 ~62 ~56 ~13 ~62 concrete 11
setblock ~54 ~13 ~74 concrete 0
setblock ~54 ~13 ~75 snow 0
setblock ~54 ~13 ~88 mossy_cobblestone 0
setblock ~55 ~13 ~74 snow 0
setblock ~55 ~13 ~75 concrete 0
setblock ~55 ~13 ~88 wool 8
setblock ~56 ~13 ~64 concrete 11
setblock ~56 ~13 ~74 concrete 0
setblock ~56 ~13 ~75 snow 0
setblock ~56 ~13 ~88 mossy_cobblestone 0
setblock ~57 ~13 ~60 wool 11
setblock ~57 ~13 ~64 wool 11
setblock ~57 ~13 ~68 wool 11
setblock ~57 ~13 ~74 snow 0
setblock ~57 ~13 ~75 concrete 0
setblock ~57 ~13 ~88 wool 8
fill ~58 ~13 ~60 ~60 ~13 ~60 concrete 11
fill ~58 ~13 ~65 ~59 ~13 ~65 concrete 11
setblock ~58 ~13 ~68 concrete 11
setblock ~58 ~13 ~73 snow 0
setblock ~58 ~13 ~74 concrete 0
setblock ~58 ~13 ~88 mossy_cobblestone 0
fill ~59 ~13 ~58 ~62 ~13 ~58 obsidian 0
fill ~59 ~13 ~59 ~63 ~13 ~59 obsidian 0
setblock ~59 ~13 ~64 obsidian 0
fill ~59 ~13 ~66 ~60 ~13 ~66 concrete 11
fill ~59 ~13 ~69 ~60 ~13 ~69 concrete 11
setblock ~59 ~13 ~74 snow 0
setblock ~59 ~13 ~88 wool 8
fill ~60 ~13 ~61 ~61 ~13 ~61 concrete 11
setblock ~60 ~13 ~64 concrete 11
setblock ~60 ~13 ~73 snow 0
setblock ~60 ~13 ~74 concrete 0
setblock ~60 ~13 ~88 mossy_cobblestone 0
setblock ~61 ~13 ~60 wool 11
setblock ~61 ~13 ~64 wool 11
fill ~61 ~13 ~65 ~62 ~13 ~65 obsidian 0
fill ~61 ~13 ~67 ~67 ~13 ~67 concrete 11
setblock ~61 ~13 ~70 wool 11
setblock ~61 ~13 ~73 concrete 0
setblock ~61 ~13 ~74 snow 0
setblock ~61 ~13 ~88 wool 8
fill ~62 ~13 ~60 ~66 ~13 ~60 concrete 11
fill ~62 ~13 ~62 ~63 ~13 ~62 concrete 11
setblock ~62 ~13 ~64 concrete 11
fill ~62 ~13 ~66 ~63 ~13 ~66 obsidian 0
fill ~62 ~13 ~70 ~64 ~13 ~70 concrete 11
setblock ~62 ~13 ~73 snow 0
setblock ~62 ~13 ~74 concrete 0
setblock ~62 ~13 ~88 mossy_cobblestone 0
fill ~63 ~13 ~61 ~64 ~13 ~61 concrete 11
setblock ~63 ~13 ~65 concrete 11
setblock ~63 ~13 ~72 snow 0
setblock ~63 ~13 ~73 concrete 0
setblock ~63 ~13 ~88 wool 8
fill ~64 ~13 ~63 ~65 ~13 ~63 concrete 11
fill ~64 ~13 ~66 ~64 ~14 ~66 concrete 11
setblock ~64 ~13 ~71 snow 0
setblock ~64 ~13 ~72 concrete 0
fill ~64 ~13 ~87 ~66 ~13 ~87 wool 8
setblock ~64 ~13 ~88 mossy_cobblestone 0
setblock ~65 ~13 ~62 wool 11
setblock ~65 ~13 ~66 wool 11
setblock ~65 ~13 ~70 wool 11
setblock ~65 ~13 ~71 concrete 0
setblock ~65 ~13 ~72 snow 0
setblock ~65 ~13 ~73 concrete 0
setblock ~65 ~13 ~88 wool 8
fill ~66 ~13 ~62 ~66 ~15 ~62 concrete 11
setblock ~66 ~13 ~64 concrete 11
setblock ~66 ~13 ~68 concrete 11
setblock ~66 ~13 ~70 concrete 11
setblock ~66 ~13 ~72 concrete 0
setblock ~66 ~13 ~88 mossy_cobblestone 0
fill ~67 ~13 ~61 ~68 ~13 ~61 concrete 11
setblock ~67 ~13 ~63 concrete 11
setblock ~67 ~13 ~65 concrete 11
setblock ~67 ~13 ~68 wool 11
fill ~67 ~13 ~71 ~68 ~13 ~71 concrete 11
setblock ~67 ~13 ~72 snow 0
setblock ~67 ~13 ~73 concrete 0
setblock ~67 ~13 ~87 glowstone 0
setblock ~67 ~13 ~88 wool 8
fill ~68 ~13 ~64 ~69 ~13 ~64 concrete 11
fill ~68 ~13 ~66 ~69 ~13 ~66 concrete 11
fill ~68 ~13 ~68 ~68 ~14 ~68 concrete 11
setblock ~68 ~13 ~72 concrete 0
setblock ~68 ~13 ~73 snow 0
setblock ~68 ~13 ~86 mossy_cobblestone 0
fill ~68 ~13 ~87 ~70 ~13 ~87 wool 8
setblock ~68 ~13 ~88 mossy_cobblestone 0
setblock ~69 ~13 ~62 wool 11
setblock ~69 ~13 ~69 concrete 11
setblock ~69 ~13 ~72 wool 10
setblock ~69 ~13 ~73 concrete 0
setblock ~69 ~13 ~74 snow 0
setblock ~69 ~13 ~85 glowstone 0
setblock ~69 ~13 ~86 wool 8
setblock ~69 ~13 ~88 wool 8
fill ~70 ~13 ~63 ~71 ~13 ~63 concrete 11
setblock ~70 ~13 ~65 concrete 11
setblock ~70 ~13 ~67 concrete 11
fill ~70 ~13 ~70 ~71 ~13 ~70 concrete 11
setblock ~70 ~13 ~73 wool 10
setblock ~70 ~13 ~74 concrete 0
setblock ~70 ~13 ~75 wool 0
setblock ~70 ~13 ~85 wool 8
setblock ~70 ~13 ~86 mossy_cobblestone 0
setblock ~70 ~13 ~88 mossy_cobblestone 0
setblock ~71 ~13 ~68 wool 11
fill ~71 ~13 ~71 ~72 ~13 ~71 concrete 11
setblock ~71 ~13 ~74 concrete 11
setblock ~71 ~13 ~75 concrete 0
setblock ~71 ~13 ~76 snow 0
setblock ~71 ~13 ~84 wool 8
setblock ~71 ~13 ~85 glowstone 0
setblock ~71 ~13 ~86 wool 8
setblock ~71 ~13 ~87 glowstone 0
fill ~72 ~13 ~64 ~72 ~14 ~64 concrete 11
fill ~72 ~13 ~66 ~72 ~14 ~66 concrete 11
fill ~72 ~13 ~72 ~73 ~13 ~72 concrete 11
setblock ~72 ~13 ~75 concrete 11
setblock ~72 ~13 ~76 concrete 0
setblock ~72 ~13 ~77 quartz_block 0
setblock ~72 ~13 ~78 concrete 0
fill ~72 ~13 ~83 ~73 ~13 ~83 wool 8
setblock ~72 ~13 ~84 mossy_cobblestone 0
setblock ~72 ~13 ~85 wool 8
setblock ~72 ~13 ~86 mossy_cobblestone 0
setblock ~73 ~13 ~65 concrete 11
setblock ~73 ~13 ~67 concrete 11
fill ~73 ~13 ~69 ~73 ~14 ~69 concrete 11
setblock ~73 ~13 ~76 wool 11
setblock ~73 ~13 ~78 snow 0
fill ~73 ~13 ~79 ~73 ~13 ~81 concrete 0
setblock ~73 ~13 ~82 planks 2
setblock ~73 ~13 ~84 wool 8
setblock ~73 ~13 ~85 glowstone 0
setblock ~74 ~13 ~68 concrete 11
setblock ~74 ~13 ~70 concrete 11
fill ~74 ~13 ~73 ~74 ~14 ~73 concrete 11
setblock ~74 ~13 ~77 concrete 11
setblock ~74 ~13 ~79 quartz_block 0
fill ~74 ~13 ~80 ~74 ~13 ~81 concrete 0
setblock ~74 ~13 ~82 stained_hardened_clay 0
setblock ~74 ~13 ~83 clay 0
setblock ~74 ~13 ~84 mossy_cobblestone 0
fill ~75 ~13 ~66 ~75 ~14 ~66 concrete 11
setblock ~75 ~13 ~69 concrete 11
setblock ~75 ~13 ~71 concrete 11
fill ~75 ~13 ~74 ~75 ~14 ~74 concrete 11
setblock ~75 ~13 ~78 concrete 11
fill ~76 ~13 ~67 ~76 ~14 ~67 concrete 11
setblock ~76 ~13 ~72 concrete 11
fill ~76 ~13 ~75 ~76 ~14 ~75 concrete 11
fill ~76 ~13 ~79 ~77 ~13 ~79 concrete 11
setblock ~77 ~13 ~68 wool 11
setblock ~77 ~13 ~73 concrete 11
setblock ~77 ~13 ~76 wool 11
setblock ~78 ~13 ~74 concrete 11
fill ~78 ~13 ~77 ~78 ~14 ~77 concrete 11
fill ~78 ~13 ~78 ~79 ~13 ~78 concrete 11
setblock ~79 ~13 ~75 concrete 11
fill ~80 ~13 ~76 ~80 ~14 ~76 concrete 11
setblock ~80 ~13 ~80 concrete 11
setblock ~81 ~13 ~72 wool 11
fill ~81 ~13 ~77 ~81 ~14 ~77 concrete 11
setblock ~81 ~13 ~78 wool 11
fill ~81 ~13 ~81 ~81 ~14 ~81 concrete 11
setblock ~82 ~13 ~79 concrete 11
fill ~82 ~13 ~82 ~82 ~14 ~82 concrete 11
fill ~82 ~13 ~83 ~82 ~12 ~83 concrete 11
setblock ~83 ~13 ~80 wool 11
setblock ~83 ~13 ~84 wool 11
setblock ~84 ~13 ~82 concrete 11
fill ~84 ~13 ~84 ~84 ~16 ~84 concrete 11
fill ~85 ~13 ~83 ~85 ~14 ~83 concrete 11
fill ~31 ~14 ~71 ~33 ~14 ~71 concrete 0
fill ~31 ~14 ~72 ~31 ~14 ~74 concrete 0
fill ~32 ~14 ~70 ~33 ~14 ~70 concrete 0
fill ~32 ~14 ~73 ~34 ~14 ~73 concrete 0
fill ~32 ~14 ~75 ~34 ~14 ~75 concrete 0
fill ~32 ~14 ~83 ~32 ~15 ~83 concrete 11
fill ~32 ~14 ~84 ~32 ~14 ~87 concrete 11
fill ~33 ~14 ~72 ~34 ~14 ~72 concrete 0
setblock ~33 ~14 ~74 concrete 0
setblock ~33 ~14 ~76 concrete 0
fill ~33 ~14 ~79 ~33 ~15 ~79 concrete 11
fill ~33 ~14 ~80 ~33 ~14 ~82 concrete 11
fill ~33 ~14 ~87 ~33 ~15 ~87 concrete 11
fill ~34 ~14 ~76 ~34 ~15 ~76 concrete 11
fill ~34 ~14 ~77 ~34 ~14 ~78 concrete 11
fill ~34 ~14 ~85 ~34 ~15 ~85 concrete 11
fill ~35 ~14 ~73 ~35 ~15 ~73 concrete 11
fill ~35 ~14 ~74 ~35 ~14 ~75 concrete 11
fill ~35 ~14 ~81 ~35 ~14 ~84 concrete 11
fill ~36 ~14 ~71 ~36 ~14 ~72 concrete 11
fill ~36 ~14 ~78 ~36 ~14 ~80 concrete 11
fill ~37 ~14 ~69 ~37 ~14 ~70 concrete 11
fill ~37 ~14 ~75 ~37 ~14 ~77 concrete 11
fill ~38 ~14 ~67 ~38 ~14 ~68 concrete 11
fill ~38 ~14 ~73 ~38 ~14 ~74 concrete 11
fill ~38 ~14 ~85 ~39 ~14 ~85 concrete 0
fill ~38 ~14 ~86 ~39 ~14 ~86 concrete 0
fill ~38 ~14 ~87 ~38 ~14 ~85 concrete 0
fill ~39 ~14 ~65 ~39 ~14 ~66 concrete 11
fill ~39 ~14 ~71 ~39 ~14 ~72 concrete 11
fill ~39 ~14 ~81 ~40 ~14 ~81 concrete 0
fill ~39 ~14 ~82 ~39 ~14 ~83 concrete 0
setblock ~39 ~14 ~84 quartz_block 1
setblock ~39 ~14 ~87 planks 2
setblock ~39 ~14 ~88 wool 8
setblock ~39 ~14 ~89 mossy_cobblestone 0
fill ~40 ~14 ~63 ~40 ~15 ~63 concrete 11
fill ~40 ~14 ~64 ~40 ~14 ~63 concrete 11
fill ~40 ~14 ~69 ~40 ~14 ~70 concrete 11
fill ~40 ~14 ~78 ~41 ~14 ~78 concrete 0
fill ~40 ~14 ~79 ~40 ~14 ~81 concrete 0
setblock ~40 ~14 ~86 wool 8
setblock ~40 ~14 ~87 mossy_cobblestone 0
setblock ~40 ~14 ~88 glowstone 0
setblock ~40 ~14 ~89 log2 0
setblock ~41 ~14 ~62 concrete 11
fill ~41 ~14 ~67 ~41 ~14 ~68 concrete 11
setblock ~41 ~14 ~76 quartz_block 1
setblock ~41 ~14 ~77 concrete 0
setblock ~41 ~14 ~88 wool 8
setblock ~41 ~14 ~89 mossy_cobblestone 0
setblock ~41 ~14 ~90 glowstone 0
fill ~42 ~14 ~65 ~43 ~14 ~65 concrete 11
fill ~42 ~14 ~66 ~43 ~14 ~66 concrete 11
fill ~42 ~14 ~74 ~42 ~14 ~76 concrete 0
setblock ~42 ~14 ~88 glowstone 0
setblock ~42 ~14 ~89 log2 0
fill ~42 ~14 ~90 ~42 ~14 ~91 mossy_cobblestone 0
fill ~43 ~14 ~62 ~60 ~14 ~62 concrete 11
setblock ~43 ~14 ~64 concrete 11
fill ~43 ~14 ~67 ~43 ~16 ~67 concrete 11
fill ~43 ~14 ~68 ~43 ~14 ~64 concrete 11
setblock ~43 ~14 ~70 concrete 11
setblock ~43 ~14 ~73 concrete 0
setblock ~43 ~14 ~74 snow 0
setblock ~43 ~14 ~89 mossy_cobblestone 0
setblock ~43 ~14 ~90 wool 8
fill ~43 ~14 ~91 ~49 ~14 ~91 mossy_cobblestone 0
fill ~44 ~14 ~63 ~44 ~15 ~63 concrete 11
setblock ~44 ~14 ~72 wool 11
setblock ~44 ~14 ~73 light_blue_glazed_terracotta 0
setblock ~44 ~14 ~90 glowstone 0
fill ~45 ~14 ~67 ~45 ~16 ~67 concrete 11
fill ~45 ~14 ~68 ~45 ~15 ~68 concrete 11
setblock ~45 ~14 ~72 quartz_block 1
fill ~45 ~14 ~74 ~46 ~14 ~74 concrete 11
setblock ~45 ~14 ~90 wool 8
fill ~46 ~14 ~65 ~47 ~14 ~65 concrete 11
setblock ~46 ~14 ~66 wool 10
fill ~46 ~14 ~67 ~47 ~14 ~67 concrete 0
fill ~46 ~14 ~68 ~46 ~15 ~68 concrete 0
setblock ~46 ~14 ~70 light_blue_glazed_terracotta 0
setblock ~46 ~14 ~71 concrete 11
setblock ~46 ~14 ~72 concrete 0
fill ~46 ~14 ~75 ~48 ~14 ~75 concrete 11
setblock ~46 ~14 ~90 mossy_cobblestone 0
fill ~47 ~14 ~64 ~48 ~14 ~64 concrete 11
setblock ~47 ~14 ~66 concrete 0
setblock ~47 ~14 ~70 concrete 0
setblock ~47 ~14 ~71 light_blue_glazed_terracotta 0
setblock ~47 ~14 ~90 wool 8
fill ~48 ~14 ~63 ~49 ~14 ~63 concrete 11
setblock ~48 ~14 ~68 concrete 0
setblock ~48 ~14 ~69 wool 11
setblock ~48 ~14 ~70 concrete 11
fill ~48 ~14 ~71 ~49 ~14 ~71 concrete 0
fill ~48 ~14 ~72 ~48 ~14 ~71 concrete 0
fill ~48 ~14 ~74 ~49 ~14 ~74 concrete 11
setblock ~48 ~14 ~90 mossy_cobblestone 0
fill ~49 ~14 ~66 ~49 ~14 ~68 concrete 11
setblock ~49 ~14 ~72 quartz_block 0
setblock ~49 ~14 ~73 concrete 11
setblock ~49 ~14 ~90 wool 8
setblock ~50 ~14 ~65 concrete 11
fill ~50 ~14 ~70 ~50 ~15 ~70 concrete 11
fill ~50 ~14 ~71 ~50 ~14 ~70 concrete 11
setblock ~50 ~14 ~72 light_blue_glazed_terracotta 0
setblock ~50 ~14 ~90 mossy_cobblestone 0
setblock ~50 ~14 ~91 log2 0
fill ~51 ~14 ~61 ~63 ~14 ~61 concrete 11
fill ~51 ~14 ~63 ~52 ~14 ~63 concrete 11
fill ~51 ~14 ~64 ~51 ~14 ~61 concrete 11
setblock ~51 ~14 ~69 concrete 11
fill ~51 ~14 ~72 ~51 ~14 ~73 concrete 0
setblock ~51 ~14 ~90 wool 8
fill ~52 ~14 ~67 ~52 ~14 ~68 concrete 11
fill ~52 ~14 ~73 ~57 ~14 ~73 concrete 0
setblock ~52 ~14 ~90 mossy_cobblestone 0
fill ~53 ~14 ~66 ~57 ~14 ~66 concrete 11
setblock ~53 ~14 ~90 wool 8
fill ~54 ~14 ~65 ~55 ~14 ~65 concrete 11
setblock ~54 ~14 ~89 log2 0
setblock ~54 ~14 ~90 mossy_cobblestone 0
setblock ~55 ~14 ~89 mossy_cobblestone 0
setblock ~55 ~14 ~90 wool 8
fill ~56 ~14 ~63 ~57 ~14 ~63 concrete 11
setblock ~56 ~14 ~89 log2 0
setblock ~56 ~14 ~90 glowstone 0
fill ~57 ~14 ~67 ~58 ~14 ~67 concrete 11
setblock ~57 ~14 ~89 mossy_cobblestone 0
setblock ~57 ~14 ~90 wool 8
fill ~58 ~14 ~63 ~60 ~14 ~63 obsidian 0
fill ~58 ~14 ~64 ~59 ~14 ~64 concrete 11
fill ~58 ~14 ~72 ~58 ~15 ~72 concrete 0
setblock ~58 ~14 ~89 log2 0
setblock ~58 ~14 ~90 mossy_cobblestone 0
fill ~59 ~14 ~59 ~63 ~14 ~59 obsidian 0
fill ~59 ~14 ~60 ~62 ~14 ~60 obsidian 0
fill ~59 ~14 ~68 ~61 ~14 ~68 concrete 11
setblock ~59 ~14 ~72 snow 0
setblock ~59 ~14 ~73 concrete 0
setblock ~59 ~14 ~89 mossy_cobblestone 0
setblock ~59 ~14 ~90 glowstone 0
fill ~60 ~14 ~65 ~61 ~14 ~65 concrete 11
setblock ~60 ~14 ~72 concrete 0
setblock ~60 ~14 ~89 log2 0
setblock ~60 ~14 ~90 mossy_cobblestone 0
fill ~61 ~14 ~63 ~62 ~14 ~63 concrete 11
fill ~61 ~14 ~64 ~62 ~14 ~64 obsidian 0
fill ~61 ~14 ~66 ~66 ~14 ~66 concrete 11
fill ~61 ~14 ~69 ~66 ~14 ~69 concrete 11
setblock ~61 ~14 ~72 snow 0
setblock ~61 ~14 ~89 mossy_cobblestone 0
setblock ~61 ~14 ~90 wool 8
fill ~62 ~14 ~65 ~63 ~14 ~65 obsidian 0
setblock ~62 ~14 ~72 concrete 0
setblock ~62 ~14 ~89 log2 0
setblock ~62 ~14 ~90 mossy_cobblestone 0
setblock ~63 ~14 ~64 concrete 11
setblock ~63 ~14 ~71 concrete 0
fill ~63 ~14 ~89 ~65 ~14 ~89 mossy_cobblestone 0
fill ~63 ~14 ~90 ~64 ~14 ~90 glowstone 0
fill ~64 ~14 ~62 ~64 ~15 ~62 concrete 11
fill ~64 ~14 ~65 ~65 ~14 ~65 concrete 11
fill ~64 ~14 ~70 ~66 ~14 ~70 concrete 0
fill ~65 ~14 ~61 ~69 ~14 ~61 concrete 11
fill ~65 ~14 ~63 ~66 ~14 ~63 concrete 11
setblock ~65 ~14 ~90 wool 8
fill ~66 ~14 ~67 ~68 ~14 ~67 concrete 11
fill ~66 ~14 ~71 ~68 ~14 ~71 concrete 0
setblock ~66 ~14 ~89 log2 0
setblock ~66 ~14 ~90 mossy_cobblestone 0
setblock ~67 ~14 ~62 concrete 11
setblock ~67 ~14 ~64 concrete 11
setblock ~67 ~14 ~70 wool 10
fill ~67 ~14 ~89 ~69 ~14 ~89 mossy_cobblestone 0
setblock ~67 ~14 ~90 wool 8
setblock ~68 ~14 ~63 concrete 11
fill ~68 ~14 ~65 ~69 ~14 ~65 concrete 11
setblock ~68 ~14 ~70 concrete 11
setblock ~68 ~14 ~90 mossy_cobblestone 0
fill ~69 ~14 ~64 ~70 ~14 ~64 concrete 11
setblock ~69 ~14 ~68 concrete 11
setblock ~69 ~14 ~71 wool 10
setblock ~69 ~14 ~90 glowstone 0
fill ~70 ~14 ~62 ~70 ~16 ~62 concrete 11
fill ~70 ~14 ~66 ~70 ~15 ~66 concrete 11
setblock ~70 ~14 ~69 concrete 11
setblock ~70 ~14 ~72 wool 10
setblock ~70 ~14 ~89 log2 0
setblock ~70 ~14 ~90 mossy_cobblestone 0
setblock ~71 ~14 ~63 concrete 11
setblock ~71 ~14 ~65 concrete 11
setblock ~71 ~14 ~67 concrete 11
fill ~71 ~14 ~70 ~72 ~14 ~70 concrete 11
setblock ~71 ~14 ~72 concrete 0
setblock ~71 ~14 ~73 wool 10
setblock ~71 ~14 ~74 concrete 0
setblock ~71 ~14 ~88 wool 8
setblock ~71 ~14 ~89 mossy_cobblestone 0
setblock ~71 ~14 ~90 wool 8
setblock ~72 ~14 ~68 concrete 11
fill ~72 ~14 ~71 ~73 ~14 ~71 concrete 11
setblock ~72 ~14 ~74 light_blue_glazed_terracotta 0
setblock ~72 ~14 ~75 concrete 0
fill ~72 ~14 ~87 ~75 ~14 ~87 mossy_cobblestone 0
setblock ~72 ~14 ~88 glowstone 0
setblock ~72 ~14 ~89 log2 0
setblock ~73 ~14 ~64 concrete 11
setblock ~73 ~14 ~66 concrete 11
fill ~73 ~14 ~72 ~74 ~14 ~72 concrete 11
setblock ~73 ~14 ~75 wool 11
setblock ~73 ~14 ~76 quartz_block 0
fill ~73 ~14 ~77 ~74 ~14 ~77 concrete 0
setblock ~73 ~14 ~86 wool 8
setblock ~73 ~14 ~88 wool 8
setblock ~73 ~14 ~89 mossy_cobblestone 0
fill ~74 ~14 ~65 ~74 ~15 ~65 concrete 11
fill ~74 ~14 ~67 ~74 ~15 ~67 concrete 11
fill ~74 ~14 ~69 ~74 ~15 ~69 concrete 11
setblock ~74 ~14 ~76 concrete 11
setblock ~74 ~14 ~78 concrete 0
fill ~74 ~14 ~85 ~74 ~14 ~87 mossy_cobblestone 0
setblock ~74 ~14 ~88 glowstone 0
fill ~75 ~14 ~68 ~75 ~15 ~68 concrete 11
setblock ~75 ~14 ~70 concrete 11
fill ~75 ~14 ~73 ~75 ~15 ~73 concrete 11
setblock ~75 ~14 ~77 concrete 11
fill ~75 ~14 ~79 ~75 ~14 ~83 concrete 0
setblock ~75 ~14 ~84 stained_hardened_clay 0
fill ~75 ~14 ~85 ~75 ~14 ~86 wool 8
setblock ~76 ~14 ~69 concrete 11
fill ~76 ~14 ~71 ~76 ~15 ~71 concrete 11
fill ~76 ~14 ~74 ~76 ~15 ~74 concrete 11
fill ~76 ~14 ~78 ~77 ~14 ~78 concrete 11
fill ~76 ~14 ~82 ~76 ~14 ~84 concrete 0
setblock ~76 ~14 ~85 clay 0
setblock ~76 ~14 ~86 wool 8
fill ~77 ~14 ~68 ~78 ~14 ~68 concrete 11
setblock ~77 ~14 ~70 concrete 11
setblock ~77 ~14 ~72 concrete 11
fill ~77 ~14 ~75 ~77 ~15 ~75 concrete 11
fill ~77 ~14 ~76 ~78 ~14 ~76 concrete 11
setblock ~78 ~14 ~71 concrete 11
fill ~78 ~14 ~73 ~78 ~15 ~73 concrete 11
fill ~79 ~14 ~69 ~79 ~15 ~69 concrete 11
setblock ~79 ~14 ~72 concrete 11
setblock ~79 ~14 ~74 concrete 11
fill ~79 ~14 ~77 ~79 ~15 ~77 concrete 11
fill ~79 ~14 ~78 ~79 ~14 ~77 concrete 11
fill ~80 ~14 ~70 ~80 ~15 ~70 concrete 11
fill ~80 ~14 ~73 ~82 ~14 ~73 concrete 11
fill ~80 ~14 ~75 ~80 ~15 ~75 concrete 11
setblock ~80 ~14 ~79 concrete 11
fill ~81 ~14 ~71 ~81 ~15 ~71 concrete 11
setblock ~81 ~14 ~80 concrete 11
fill ~82 ~14 ~72 ~82 ~15 ~72 concrete 11
fill ~82 ~14 ~78 ~82 ~15 ~78 concrete 11
fill ~83 ~14 ~79 ~83 ~15 ~79 concrete 11
fill ~83 ~14 ~80 ~83 ~14 ~79 concrete 11
fill ~83 ~14 ~83 ~83 ~15 ~83 concrete 11
fill ~83 ~14 ~84 ~83 ~14 ~83 concrete 11
fill ~84 ~14 ~81 ~84 ~15 ~81 concrete 11
setblock ~85 ~14 ~82 concrete 11
fill ~85 ~14 ~84 ~86 ~14 ~84 concrete 11
fill ~85 ~14 ~85 ~85 ~18 ~85 concrete 11
fill ~31 ~15 ~69 ~33 ~15 ~69 concrete 0
setblock ~31 ~15 ~70 snow 0
fill ~31 ~15 ~71 ~31 ~17 ~71 concrete 0
setblock ~31 ~15 ~72 snow 0
fill ~31 ~15 ~73 ~33 ~15 ~73 concrete 0
setblock ~31 ~15 ~84 wool 11
fill ~31 ~15 ~85 ~31 ~16 ~85 concrete 11
fill ~31 ~15 ~86 ~31 ~15 ~87 concrete 11
setblock ~31 ~15 ~88 wool 11
fill ~32 ~15 ~68 ~32 ~16 ~68 concrete 0
fill ~32 ~15 ~70 ~32 ~14 ~70 concrete 0
fill ~32 ~15 ~80 ~32 ~16 ~80 concrete 11
fill ~32 ~15 ~81 ~32 ~15 ~83 concrete 11
fill ~32 ~15 ~88 ~33 ~15 ~88 concrete 11
setblock ~33 ~15 ~70 snow 0
fill ~33 ~15 ~71 ~34 ~15 ~71 concrete 0
setblock ~33 ~15 ~72 snow 0
setblock ~33 ~15 ~74 snow 0
setblock ~33 ~15 ~77 concrete 11
setblock ~33 ~15 ~78 wool 11
setblock ~33 ~15 ~86 wool 11
setblock ~34 ~15 ~72 concrete 0
fill ~34 ~15 ~74 ~34 ~15 ~76 concrete 11
fill ~34 ~15 ~81 ~34 ~16 ~81 concrete 11
fill ~34 ~15 ~82 ~34 ~15 ~85 concrete 11
fill ~35 ~15 ~71 ~35 ~16 ~71 concrete 11
setblock ~35 ~15 ~72 wool 11
fill ~35 ~15 ~78 ~35 ~15 ~79 concrete 11
setblock ~35 ~15 ~80 wool 11
fill ~36 ~15 ~69 ~36 ~15 ~70 concrete 11
fill ~36 ~15 ~75 ~36 ~16 ~75 concrete 11
fill ~36 ~15 ~76 ~36 ~15 ~77 concrete 11
fill ~37 ~15 ~67 ~37 ~15 ~68 concrete 11
setblock ~37 ~15 ~73 concrete 11
setblock ~37 ~15 ~74 wool 11
setblock ~37 ~15 ~84 snow 0
setblock ~37 ~15 ~85 concrete 0
setblock ~37 ~15 ~86 snow 0
fill ~37 ~15 ~87 ~37 ~15 ~88 concrete 0
setblock ~37 ~15 ~89 stained_hardened_clay 0
setblock ~37 ~15 ~90 wool 8
fill ~38 ~15 ~65 ~38 ~15 ~66 concrete 11
fill ~38 ~15 ~71 ~38 ~15 ~72 concrete 11
setblock ~38 ~15 ~81 snow 0
setblock ~38 ~15 ~82 concrete 0
setblock ~38 ~15 ~83 quartz_block 0
setblock ~38 ~15 ~84 concrete 0
fill ~38 ~15 ~88 ~38 ~15 ~89 clay 0
setblock ~38 ~15 ~90 mossy_cobblestone 0
fill ~38 ~15 ~91 ~40 ~15 ~91 wool 8
setblock ~39 ~15 ~64 wool 11
fill ~39 ~15 ~69 ~39 ~15 ~70 concrete 11
setblock ~39 ~15 ~78 snow 0
setblock ~39 ~15 ~79 concrete 0
setblock ~39 ~15 ~80 snow 0
setblock ~39 ~15 ~90 wool 8
setblock ~39 ~15 ~92 wool 8
fill ~40 ~15 ~67 ~40 ~15 ~68 concrete 11
setblock ~40 ~15 ~76 concrete 0
setblock ~40 ~15 ~77 snow 0
setblock ~40 ~15 ~90 mossy_cobblestone 0
setblock ~40 ~15 ~92 mossy_cobblestone 0
fill ~41 ~15 ~63 ~47 ~15 ~63 concrete 11
setblock ~41 ~15 ~65 concrete 11
setblock ~41 ~15 ~66 wool 11
setblock ~41 ~15 ~74 snow 0
setblock ~41 ~15 ~75 concrete 0
setblock ~41 ~15 ~91 glowstone 0
setblock ~41 ~15 ~92 wool 8
setblock ~41 ~15 ~93 glowstone 0
setblock ~42 ~15 ~64 concrete 11
setblock ~42 ~15 ~73 snow 0
setblock ~42 ~15 ~92 mossy_cobblestone 0
setblock ~42 ~15 ~93 wool 8
setblock ~43 ~15 ~64 wool 11
fill ~43 ~15 ~65 ~43 ~16 ~65 concrete 11
setblock ~43 ~15 ~66 wool 11
setblock ~43 ~15 ~68 wool 11
setblock ~43 ~15 ~72 snow 0
setblock ~43 ~15 ~92 wool 8
setblock ~43 ~15 ~93 glowstone 0
setblock ~43 ~15 ~94 wool 8
setblock ~44 ~15 ~70 concrete 11
setblock ~44 ~15 ~71 wool 10
setblock ~44 ~15 ~92 mossy_cobblestone 0
fill ~44 ~15 ~93 ~51 ~15 ~93 wool 8
setblock ~44 ~15 ~94 mossy_cobblestone 0
setblock ~45 ~15 ~65 concrete 11
setblock ~45 ~15 ~66 wool 10
setblock ~45 ~15 ~71 concrete 0
fill ~45 ~15 ~72 ~45 ~15 ~73 concrete 11
setblock ~45 ~15 ~92 wool 8
setblock ~45 ~15 ~94 wool 8
setblock ~46 ~15 ~64 concrete 11
setblock ~46 ~15 ~65 quartz_block 0
fill ~46 ~15 ~67 ~47 ~15 ~67 concrete 0
setblock ~46 ~15 ~69 concrete 11
fill ~46 ~15 ~70 ~46 ~16 ~70 concrete 0
setblock ~46 ~15 ~71 quartz_block 0
fill ~46 ~15 ~73 ~48 ~15 ~73 concrete 11
setblock ~46 ~15 ~92 mossy_cobblestone 0
setblock ~46 ~15 ~94 mossy_cobblestone 0
fill ~47 ~15 ~65 ~47 ~17 ~65 concrete 0
setblock ~47 ~15 ~66 snow 0
setblock ~47 ~15 ~68 snow 0
setblock ~47 ~15 ~69 wool 10
setblock ~47 ~15 ~70 stone 3
setblock ~47 ~15 ~74 wool 11
setblock ~47 ~15 ~92 wool 8
fill ~48 ~15 ~67 ~48 ~15 ~68 concrete 11
fill ~48 ~15 ~70 ~48 ~16 ~70 concrete 0
fill ~48 ~15 ~72 ~49 ~15 ~72 concrete 11
setblock ~48 ~15 ~92 mossy_cobblestone 0
setblock ~49 ~15 ~65 concrete 11
setblock ~49 ~15 ~66 wool 11
setblock ~49 ~15 ~71 wool 10
setblock ~49 ~15 ~92 wool 8
fill ~50 ~15 ~63 ~51 ~15 ~63 concrete 11
fill ~50 ~15 ~64 ~50 ~15 ~63 concrete 11
setblock ~50 ~15 ~69 concrete 11
setblock ~50 ~15 ~71 snow 0
setblock ~50 ~15 ~92 mossy_cobblestone 0
fill ~51 ~15 ~67 ~51 ~15 ~68 concrete 11
setblock ~51 ~15 ~71 concrete 0
setblock ~51 ~15 ~91 glowstone 0
setblock ~51 ~15 ~92 wool 8
setblock ~52 ~15 ~62 concrete 11
setblock ~52 ~15 ~66 concrete 11
setblock ~52 ~15 ~71 snow 0
setblock ~52 ~15 ~72 concrete 0
fill ~52 ~15 ~91 ~54 ~15 ~91 wool 8
setblock ~52 ~15 ~92 mossy_cobblestone 0
setblock ~53 ~15 ~62 wool 11
setblock ~53 ~15 ~65 concrete 11
setblock ~53 ~15 ~71 concrete 0
setblock ~53 ~15 ~72 snow 0
setblock ~53 ~15 ~92 wool 8
setblock ~54 ~15 ~62 concrete 11
fill ~54 ~15 ~64 ~55 ~15 ~64 concrete 11
setblock ~54 ~15 ~71 snow 0
setblock ~54 ~15 ~72 concrete 0
setblock ~54 ~15 ~92 mossy_cobblestone 0
setblock ~55 ~15 ~62 wool 11
setblock ~55 ~15 ~71 concrete 0
setblock ~55 ~15 ~72 snow 0
setblock ~55 ~15 ~91 glowstone 0
setblock ~55 ~15 ~92 wool 8
setblock ~56 ~15 ~62 concrete 11
fill ~56 ~15 ~65 ~57 ~15 ~65 concrete 11
setblock ~56 ~15 ~72 concrete 0
fill ~56 ~15 ~91 ~58 ~15 ~91 wool 8
setblock ~56 ~15 ~92 mossy_cobblestone 0
setblock ~57 ~15 ~62 wool 11
setblock ~57 ~15 ~71 concrete 0
setblock ~57 ~15 ~72 snow 0
setblock ~57 ~15 ~92 wool 8
fill ~58 ~15 ~61 ~58 ~15 ~62 obsidian 0
fill ~58 ~15 ~63 ~59 ~15 ~63 concrete 11
setblock ~58 ~15 ~66 concrete 11
setblock ~58 ~15 ~71 snow 0
setblock ~58 ~15 ~92 mossy_cobblestone 0
fill ~59 ~15 ~60 ~63 ~15 ~60 obsidian 0
fill ~59 ~15 ~62 ~60 ~15 ~62 obsidian 0
setblock ~59 ~15 ~66 wool 11
fill ~59 ~15 ~67 ~61 ~15 ~67 concrete 11
setblock ~59 ~15 ~71 concrete 0
setblock ~59 ~15 ~91 glowstone 0
fill ~60 ~15 ~61 ~62 ~15 ~61 obsidian 0
setblock ~60 ~15 ~63 obsidian 0
fill ~60 ~15 ~64 ~61 ~15 ~64 concrete 11
setblock ~60 ~15 ~71 snow 0
setblock ~60 ~15 ~91 wool 8
setblock ~60 ~15 ~92 mossy_cobblestone 0
fill ~61 ~15 ~62 ~62 ~15 ~62 concrete 11
setblock ~61 ~15 ~71 concrete 0
setblock ~61 ~15 ~91 glowstone 0
setblock ~61 ~15 ~92 wool 8
fill ~62 ~15 ~63 ~62 ~16 ~63 obsidian 0
fill ~62 ~15 ~64 ~63 ~15 ~64 obsidian 0
fill ~62 ~15 ~65 ~66 ~15 ~65 concrete 11
fill ~62 ~15 ~68 ~64 ~15 ~68 concrete 11
setblock ~62 ~15 ~70 concrete 0
setblock ~62 ~15 ~71 snow 0
setblock ~62 ~15 ~91 wool 8
setblock ~62 ~15 ~92 mossy_cobblestone 0
setblock ~63 ~15 ~62 wool 11
setblock ~63 ~15 ~63 concrete 11
setblock ~63 ~15 ~69 concrete 0
setblock ~63 ~15 ~70 snow 0
setblock ~63 ~15 ~91 glowstone 0
setblock ~63 ~15 ~92 wool 8
fill ~64 ~15 ~64 ~64 ~17 ~64 concrete 11
setblock ~64 ~15 ~69 snow 0
fill ~64 ~15 ~91 ~66 ~15 ~91 wool 8
setblock ~64 ~15 ~92 mossy_cobblestone 0
setblock ~65 ~15 ~62 wool 11
setblock ~65 ~15 ~64 wool 11
setblock ~65 ~15 ~68 wool 11
setblock ~65 ~15 ~69 concrete 0
setblock ~65 ~15 ~92 wool 8
setblock ~66 ~15 ~66 concrete 11
setblock ~66 ~15 ~68 concrete 11
setblock ~66 ~15 ~69 snow 0
setblock ~66 ~15 ~92 mossy_cobblestone 0
fill ~67 ~15 ~61 ~69 ~15 ~61 concrete 11
fill ~67 ~15 ~63 ~67 ~17 ~63 concrete 11
setblock ~67 ~15 ~66 wool 11
setblock ~67 ~15 ~69 wool 10
setblock ~67 ~15 ~91 glowstone 0
setblock ~67 ~15 ~92 wool 8
setblock ~68 ~15 ~62 concrete 11
setblock ~68 ~15 ~64 concrete 11
fill ~68 ~15 ~66 ~68 ~16 ~66 concrete 11
fill ~68 ~15 ~67 ~69 ~15 ~67 concrete 11
setblock ~68 ~15 ~69 light_blue_glazed_terracotta 0
setblock ~68 ~15 ~70 concrete 0
fill ~68 ~15 ~91 ~70 ~15 ~91 wool 8
setblock ~68 ~15 ~92 mossy_cobblestone 0
setblock ~69 ~15 ~63 concrete 11
setblock ~69 ~15 ~65 concrete 11
setblock ~69 ~15 ~70 light_blue_glazed_terracotta 0
setblock ~69 ~15 ~92 wool 8
fill ~70 ~15 ~64 ~71 ~15 ~64 concrete 11
setblock ~70 ~15 ~68 concrete 11
setblock ~70 ~15 ~70 concrete 0
setblock ~70 ~15 ~71 wool 10
setblock ~70 ~15 ~92 mossy_cobblestone 0
setblock ~71 ~15 ~62 wool 11
setblock ~71 ~15 ~66 wool 11
setblock ~71 ~15 ~69 concrete 11
setblock ~71 ~15 ~71 concrete 0
setblock ~71 ~15 ~72 wool 10
setblock ~71 ~15 ~91 glowstone 0
setblock ~71 ~15 ~92 wool 8
fill ~72 ~15 ~63 ~72 ~17 ~63 concrete 11
fill ~72 ~15 ~65 ~72 ~16 ~65 concrete 11
setblock ~72 ~15 ~67 concrete 11
setblock ~72 ~15 ~70 concrete 11
setblock ~72 ~15 ~73 light_blue_glazed_terracotta 0
setblock ~72 ~15 ~90 mossy_cobblestone 0
fill ~72 ~15 ~91 ~74 ~15 ~91 wool 8
setblock ~72 ~15 ~92 mossy_cobblestone 0
setblock ~73 ~15 ~64 wool 11
setblock ~73 ~15 ~66 wool 11
setblock ~73 ~15 ~68 wool 11
fill ~73 ~15 ~71 ~74 ~15 ~71 concrete 11
setblock ~73 ~15 ~74 light_blue_glazed_terracotta 0
setblock ~73 ~15 ~90 wool 8
setblock ~73 ~15 ~92 wool 8
fill ~74 ~15 ~72 ~75 ~15 ~72 concrete 11
setblock ~74 ~15 ~75 wool 10
setblock ~74 ~15 ~76 concrete 0
setblock ~74 ~15 ~89 wool 8
setblock ~74 ~15 ~90 mossy_cobblestone 0
fill ~75 ~15 ~65 ~75 ~17 ~65 concrete 11
setblock ~75 ~15 ~70 wool 11
setblock ~75 ~15 ~76 concrete 11
setblock ~75 ~15 ~77 concrete 0
setblock ~75 ~15 ~78 snow 0
setblock ~75 ~15 ~88 wool 8
setblock ~75 ~15 ~89 glowstone 0
setblock ~75 ~15 ~90 wool 8
setblock ~75 ~15 ~91 glowstone 0
fill ~76 ~15 ~66 ~76 ~17 ~66 concrete 11
fill ~76 ~15 ~68 ~76 ~16 ~68 concrete 11
fill ~76 ~15 ~73 ~76 ~16 ~73 concrete 11
fill ~76 ~15 ~77 ~77 ~15 ~77 concrete 11
setblock ~76 ~15 ~79 snow 0
setblock ~76 ~15 ~80 concrete 0
setblock ~76 ~15 ~81 snow 0
fill ~76 ~15 ~87 ~77 ~15 ~87 wool 8
setblock ~76 ~15 ~88 mossy_cobblestone 0
setblock ~76 ~15 ~89 wool 8
setblock ~76 ~15 ~90 mossy_cobblestone 0
fill ~77 ~15 ~67 ~77 ~17 ~67 concrete 11
fill ~77 ~15 ~69 ~77 ~16 ~69 concrete 11
setblock ~77 ~15 ~72 wool 11
setblock ~77 ~15 ~74 wool 11
setblock ~77 ~15 ~82 snow 0
setblock ~77 ~15 ~83 concrete 0
setblock ~77 ~15 ~84 snow 0
fill ~77 ~15 ~85 ~77 ~15 ~86 concrete 0
setblock ~77 ~15 ~88 wool 8
setblock ~77 ~15 ~89 glowstone 0
setblock ~78 ~15 ~68 concrete 11
fill ~78 ~15 ~70 ~78 ~16 ~70 concrete 11
setblock ~78 ~15 ~76 concrete 11
setblock ~78 ~15 ~84 concrete 0
setblock ~78 ~15 ~85 wool 0
setblock ~78 ~15 ~86 concrete 0
setblock ~78 ~15 ~87 stained_hardened_clay 0
setblock ~78 ~15 ~88 mossy_cobblestone 0
fill ~79 ~15 ~71 ~79 ~16 ~71 concrete 11
setblock ~79 ~15 ~74 wool 11
fill ~80 ~15 ~72 ~80 ~16 ~72 concrete 11
setblock ~80 ~15 ~78 concrete 11
setblock ~81 ~15 ~73 concrete 11
setblock ~81 ~15 ~76 wool 11
fill ~81 ~15 ~79 ~81 ~16 ~79 concrete 11
setblock ~81 ~15 ~80 wool 11
fill ~82 ~15 ~77 ~82 ~16 ~77 concrete 11
setblock ~82 ~15 ~81 concrete 11
setblock ~83 ~15 ~82 wool 11
fill ~84 ~15 ~80 ~84 ~16 ~80 concrete 11
setblock ~84 ~15 ~85 concrete 11
setblock ~85 ~15 ~82 wool 11
fill ~86 ~15 ~83 ~86 ~17 ~83 concrete 11
fill ~86 ~15 ~84 ~86 ~15 ~85 concrete 11
fill ~87 ~15 ~85 ~87 ~17 ~85 concrete 11
fill ~30 ~16 ~86 ~30 ~17 ~86 concrete 11
fill ~30 ~16 ~87 ~30 ~17 ~87 concrete 11
fill ~30 ~16 ~88 ~30 ~16 ~89 concrete 11
fill ~31 ~16 ~67 ~32 ~16 ~67 concrete 0
fill ~31 ~16 ~68 ~31 ~16 ~72 concrete 0
fill ~31 ~16 ~81 ~31 ~17 ~81 concrete 11
fill ~31 ~16 ~82 ~31 ~16 ~85 concrete 11
fill ~31 ~16 ~89 ~32 ~16 ~89 concrete 11
fill ~32 ~16 ~71 ~33 ~16 ~71 concrete 0
fill ~32 ~16 ~72 ~33 ~16 ~72 concrete 0
fill ~32 ~16 ~73 ~32 ~16 ~71 concrete 0
fill ~32 ~16 ~77 ~32 ~17 ~77 concrete 11
fill ~32 ~16 ~78 ~32 ~16 ~80 concrete 11
fill ~32 ~16 ~87 ~32 ~17 ~87 concrete 11
fill ~32 ~16 ~88 ~32 ~17 ~88 concrete 11
fill ~33 ~16 ~68 ~33 ~16 ~72 concrete 0
fill ~33 ~16 ~74 ~33 ~17 ~74 concrete 11
fill ~33 ~16 ~75 ~33 ~16 ~76 concrete 11
fill ~33 ~16 ~82 ~33 ~17 ~82 concrete 11
fill ~33 ~16 ~83 ~33 ~16 ~86 concrete 11
fill ~34 ~16 ~72 ~34 ~16 ~73 concrete 11
fill ~34 ~16 ~78 ~34 ~17 ~78 concrete 11
fill ~34 ~16 ~79 ~34 ~16 ~81 concrete 11
fill ~35 ~16 ~69 ~35 ~17 ~69 concrete 11
fill ~35 ~16 ~70 ~35 ~16 ~69 concrete 11
fill ~35 ~16 ~76 ~35 ~16 ~77 concrete 11
fill ~35 ~16 ~87 ~36 ~16 ~87 concrete 0
setblock ~35 ~16 ~88 quartz_block 0
fill ~35 ~16 ~89 ~36 ~16 ~89 concrete 0
setblock ~35 ~16 ~90 snow 0
setblock ~35 ~16 ~91 concrete 0
fill ~36 ~16 ~67 ~36 ~16 ~68 concrete 11
fill ~36 ~16 ~73 ~36 ~16 ~75 concrete 11
fill ~36 ~16 ~84 ~36 ~16 ~89 concrete 0
setblock ~36 ~16 ~90 stained_hardened_clay 0
fill ~36 ~16 ~91 ~36 ~16 ~92 wool 8
fill ~37 ~16 ~65 ~37 ~16 ~66 concrete 11
fill ~37 ~16 ~71 ~37 ~16 ~72 concrete 11
setblock ~37 ~16 ~81 concrete 0
setblock ~37 ~16 ~82 snow 0
setblock ~37 ~16 ~83 concrete 0
setblock ~37 ~16 ~91 cobblestone 0
setblock ~37 ~16 ~92 wool 8
fill ~37 ~16 ~93 ~40 ~16 ~93 mossy_cobblestone 0
fill ~38 ~16 ~64 ~41 ~16 ~64 concrete 11
fill ~38 ~16 ~69 ~38 ~16 ~70 concrete 11
fill ~38 ~16 ~78 ~38 ~17 ~78 concrete 0
fill ~38 ~16 ~79 ~38 ~16 ~80 concrete 0
setblock ~38 ~16 ~92 mossy_cobblestone 0
setblock ~38 ~16 ~94 mossy_cobblestone 0
fill ~39 ~16 ~67 ~39 ~16 ~68 concrete 11
setblock ~39 ~16 ~76 snow 0
setblock ~39 ~16 ~77 concrete 0
setblock ~39 ~16 ~94 wool 8
fill ~40 ~16 ~65 ~40 ~16 ~66 concrete 11
fill ~40 ~16 ~74 ~40 ~16 ~75 concrete 0
fill ~40 ~16 ~94 ~40 ~16 ~95 mossy_cobblestone 0
setblock ~41 ~16 ~73 concrete 0
setblock ~41 ~16 ~94 wool 8
setblock ~41 ~16 ~95 mossy_cobblestone 0
setblock ~42 ~16 ~72 concrete 0
setblock ~42 ~16 ~94 glowstone 0
setblock ~42 ~16 ~95 log2 0
setblock ~42 ~16 ~96 cobblestone 0
fill ~43 ~16 ~63 ~46 ~16 ~63 concrete 0
setblock ~43 ~16 ~64 light_blue_glazed_terracotta 0
setblock ~43 ~16 ~66 concrete 11
setblock ~43 ~16 ~71 concrete 0
fill ~43 ~16 ~95 ~51 ~16 ~95 mossy_cobblestone 0
setblock ~43 ~16 ~96 wool 8
setblock ~44 ~16 ~64 wool 10
fill ~44 ~16 ~68 ~44 ~17 ~68 concrete 11
fill ~44 ~16 ~69 ~44 ~16 ~68 concrete 11
setblock ~44 ~16 ~70 wool 10
fill ~44 ~16 ~96 ~45 ~16 ~96 glowstone 0
setblock ~45 ~16 ~64 light_blue_glazed_terracotta 0
setblock ~45 ~16 ~65 wool 10
setblock ~45 ~16 ~66 concrete 11
setblock ~45 ~16 ~70 quartz_block 0
fill ~45 ~16 ~71 ~48 ~16 ~71 concrete 11
fill ~46 ~16 ~64 ~47 ~16 ~64 concrete 0
fill ~46 ~16 ~66 ~47 ~16 ~66 concrete 0
setblock ~46 ~16 ~67 stone 3
fill ~46 ~16 ~68 ~47 ~16 ~68 concrete 11
fill ~46 ~16 ~72 ~47 ~16 ~72 concrete 11
setblock ~46 ~16 ~96 mossy_cobblestone 0
setblock ~47 ~16 ~67 light_blue_glazed_terracotta 0
setblock ~47 ~16 ~70 quartz_block 0
setblock ~47 ~16 ~94 wool 8
setblock ~47 ~16 ~96 wool 8
fill ~48 ~16 ~65 ~48 ~17 ~65 concrete 11
fill ~48 ~16 ~66 ~48 ~16 ~65 concrete 11
setblock ~48 ~16 ~69 concrete 0
setblock ~48 ~16 ~94 glowstone 0
setblock ~48 ~16 ~96 glowstone 0
setblock ~49 ~16 ~64 concrete 11
setblock ~49 ~16 ~69 concrete 11
setblock ~49 ~16 ~70 wool 10
setblock ~49 ~16 ~94 wool 8
fill ~50 ~16 ~63 ~61 ~16 ~63 concrete 11
fill ~50 ~16 ~67 ~50 ~17 ~67 concrete 11
fill ~50 ~16 ~68 ~50 ~16 ~67 concrete 11
setblock ~50 ~16 ~70 concrete 0
setblock ~50 ~16 ~94 glowstone 0
fill ~51 ~16 ~65 ~52 ~16 ~65 concrete 11
fill ~51 ~16 ~66 ~51 ~16 ~65 concrete 11
setblock ~51 ~16 ~70 snow 0
setblock ~51 ~16 ~94 wool 8
fill ~52 ~16 ~64 ~53 ~16 ~64 concrete 11
setblock ~52 ~16 ~70 concrete 0
fill ~52 ~16 ~93 ~76 ~16 ~93 mossy_cobblestone 0
fill ~52 ~16 ~94 ~52 ~16 ~93 mossy_cobblestone 0
setblock ~53 ~16 ~70 snow 0
setblock ~53 ~16 ~94 wool 8
setblock ~54 ~16 ~70 concrete 0
setblock ~54 ~16 ~94 glowstone 0
setblock ~55 ~16 ~70 snow 0
setblock ~55 ~16 ~94 wool 8
fill ~56 ~16 ~64 ~57 ~16 ~64 concrete 11
fill ~56 ~16 ~70 ~56 ~17 ~70 concrete 0
fill ~56 ~16 ~71 ~56 ~16 ~70 concrete 0
setblock ~56 ~16 ~94 glowstone 0
setblock ~57 ~16 ~70 snow 0
fill ~58 ~16 ~65 ~59 ~16 ~65 concrete 11
setblock ~58 ~16 ~70 concrete 0
fill ~59 ~16 ~61 ~63 ~16 ~61 obsidian 0
setblock ~59 ~16 ~70 snow 0
setblock ~59 ~16 ~92 wool 8
fill ~60 ~16 ~62 ~63 ~16 ~62 obsidian 0
fill ~60 ~16 ~66 ~61 ~16 ~66 concrete 11
fill ~60 ~16 ~69 ~62 ~16 ~69 concrete 0
fill ~60 ~16 ~70 ~60 ~16 ~69 concrete 0
setblock ~61 ~16 ~70 snow 0
fill ~62 ~16 ~64 ~66 ~16 ~64 concrete 11
fill ~62 ~16 ~67 ~64 ~16 ~67 concrete 11
fill ~62 ~16 ~68 ~64 ~16 ~68 concrete 0
setblock ~62 ~16 ~94 glowstone 0
setblock ~63 ~16 ~63 obsidian 0
setblock ~63 ~16 ~94 wool 8
fill ~64 ~16 ~63 ~68 ~16 ~63 concrete 11
setblock ~64 ~16 ~94 glowstone 0
setblock ~65 ~16 ~67 light_blue_glazed_terracotta 0
setblock ~65 ~16 ~68 quartz_block 0
setblock ~65 ~16 ~94 wool 8
fill ~66 ~16 ~65 ~67 ~16 ~65 concrete 11
setblock ~66 ~16 ~67 wool 10
setblock ~66 ~16 ~68 concrete 0
setblock ~66 ~16 ~94 glowstone 0
setblock ~67 ~16 ~68 wool 10
setblock ~67 ~16 ~94 wool 8
setblock ~68 ~16 ~68 concrete 0
setblock ~68 ~16 ~69 concrete 11
setblock ~68 ~16 ~94 glowstone 0
setblock ~69 ~16 ~62 concrete 11
fill ~69 ~16 ~64 ~69 ~18 ~64 concrete 11
fill ~69 ~16 ~66 ~69 ~17 ~66 concrete 11
fill ~69 ~16 ~67 ~70 ~16 ~67 concrete 11
setblock ~69 ~16 ~69 wool 10
setblock ~69 ~16 ~94 wool 8
setblock ~69 ~16 ~95 mossy_cobblestone 0
setblock ~70 ~16 ~63 concrete 11
setblock ~70 ~16 ~65 concrete 11
setblock ~70 ~16 ~70 light_blue_glazed_terracotta 0
setblock ~70 ~16 ~94 glowstone 0
setblock ~70 ~16 ~95 log2 0
setblock ~71 ~16 ~62 concrete 11
setblock ~71 ~16 ~64 concrete 11
fill ~71 ~16 ~66 ~72 ~16 ~66 concrete 11
setblock ~71 ~16 ~68 concrete 11
setblock ~71 ~16 ~71 wool 11
setblock ~71 ~16 ~94 wool 8
setblock ~71 ~16 ~95 mossy_cobblestone 0
setblock ~72 ~16 ~69 concrete 11
setblock ~72 ~16 ~71 concrete 0
setblock ~72 ~16 ~72 wool 10
setblock ~72 ~16 ~94 mossy_cobblestone 0
setblock ~73 ~16 ~63 concrete 11
fill ~73 ~16 ~65 ~73 ~17 ~65 concrete 11
fill ~73 ~16 ~67 ~73 ~17 ~67 concrete 11
setblock ~73 ~16 ~70 concrete 11
setblock ~73 ~16 ~72 snow 0
setblock ~73 ~16 ~73 wool 10
setblock ~73 ~16 ~94 wool 8
fill ~74 ~16 ~64 ~74 ~17 ~64 concrete 11
fill ~74 ~16 ~66 ~74 ~17 ~66 concrete 11
fill ~74 ~16 ~68 ~74 ~17 ~68 concrete 11
setblock ~74 ~16 ~71 concrete 11
setblock ~74 ~16 ~74 light_blue_glazed_terracotta 0
setblock ~74 ~16 ~92 mossy_cobblestone 0
setblock ~74 ~16 ~94 glowstone 0
setblock ~75 ~16 ~67 concrete 11
setblock ~75 ~16 ~69 concrete 11
setblock ~75 ~16 ~72 concrete 11
setblock ~75 ~16 ~75 wool 11
setblock ~75 ~16 ~76 concrete 0
setblock ~75 ~16 ~92 wool 8
setblock ~76 ~16 ~70 concrete 11
fill ~76 ~16 ~76 ~77 ~16 ~76 concrete 11
fill ~76 ~16 ~77 ~76 ~16 ~78 concrete 0
fill ~76 ~16 ~91 ~77 ~16 ~91 mossy_cobblestone 0
fill ~76 ~16 ~92 ~76 ~16 ~91 mossy_cobblestone 0
setblock ~77 ~16 ~71 concrete 11
setblock ~77 ~16 ~74 concrete 11
setblock ~77 ~16 ~79 concrete 0
setblock ~77 ~16 ~80 snow 0
fill ~77 ~16 ~81 ~78 ~16 ~81 concrete 0
fill ~77 ~16 ~90 ~78 ~16 ~90 glowstone 0
setblock ~77 ~16 ~92 wool 8
fill ~78 ~16 ~67 ~78 ~17 ~67 concrete 11
setblock ~78 ~16 ~72 concrete 11
fill ~78 ~16 ~75 ~78 ~17 ~75 concrete 11
fill ~78 ~16 ~82 ~78 ~16 ~83 concrete 0
fill ~78 ~16 ~89 ~80 ~16 ~89 mossy_cobblestone 0
setblock ~78 ~16 ~91 log2 0
setblock ~79 ~16 ~68 concrete 11
setblock ~79 ~16 ~73 concrete 11
setblock ~79 ~16 ~76 concrete 11
setblock ~79 ~16 ~84 quartz_block 1
fill ~79 ~16 ~85 ~79 ~16 ~86 concrete 0
fill ~79 ~16 ~87 ~80 ~16 ~87 stained_hardened_clay 0
setblock ~79 ~16 ~88 wool 8
setblock ~79 ~16 ~90 wool 8
fill ~80 ~16 ~69 ~80 ~17 ~69 concrete 11
fill ~80 ~16 ~74 ~80 ~17 ~74 concrete 11
fill ~80 ~16 ~77 ~80 ~17 ~77 concrete 11
setblock ~80 ~16 ~86 concrete 0
setblock ~80 ~16 ~88 planks 2
setblock ~81 ~16 ~70 concrete 11
setblock ~81 ~16 ~72 concrete 11
fill ~81 ~16 ~75 ~81 ~17 ~75 concrete 11
fill ~81 ~16 ~76 ~81 ~16 ~75 concrete 11
setblock ~81 ~16 ~78 concrete 11
setblock ~82 ~16 ~71 concrete 11
setblock ~82 ~16 ~80 concrete 11
fill ~83 ~16 ~78 ~83 ~17 ~78 concrete 11
fill ~83 ~16 ~81 ~83 ~18 ~81 concrete 11
fill ~83 ~16 ~82 ~83 ~16 ~81 concrete 11
fill ~84 ~16 ~79 ~84 ~17 ~79 concrete 11
fill ~84 ~16 ~83 ~84 ~17 ~83 concrete 11
fill ~85 ~16 ~81 ~85 ~17 ~81 concrete 11
fill ~85 ~16 ~86 ~87 ~16 ~86 concrete 11
fill ~86 ~16 ~82 ~86 ~18 ~82 concrete 11
setblock ~87 ~16 ~84 concrete 11
fill ~29 ~17 ~88 ~29 ~18 ~88 concrete 11
fill ~29 ~17 ~89 ~29 ~18 ~89 concrete 11
fill ~29 ~17 ~90 ~30 ~17 ~90 concrete 11
fill ~30 ~17 ~68 ~30 ~18 ~68 concrete 0
fill ~30 ~17 ~82 ~30 ~18 ~82 concrete 11
fill ~30 ~17 ~83 ~30 ~18 ~83 concrete 11
fill ~30 ~17 ~84 ~30 ~17 ~87 concrete 11
fill ~31 ~17 ~67 ~31 ~18 ~67 concrete 0
setblock ~31 ~17 ~68 snow 0
fill ~31 ~17 ~69 ~31 ~18 ~69 concrete 0
setblock ~31 ~17 ~70 snow 0
fill ~31 ~17 ~78 ~31 ~18 ~78 concrete 11
fill ~31 ~17 ~79 ~31 ~21 ~79 concrete 11
setblock ~31 ~17 ~80 wool 11
fill ~31 ~17 ~89 ~31 ~18 ~89 concrete 11
setblock ~31 ~17 ~90 wool 11
setblock ~32 ~17 ~66 concrete 0
setblock ~32 ~17 ~67 quartz_block 0
fill ~32 ~17 ~70 ~32 ~18 ~70 concrete 0
setblock ~32 ~17 ~71 quartz_block 0
fill ~32 ~17 ~75 ~32 ~18 ~75 concrete 11
fill ~32 ~17 ~76 ~32 ~17 ~75 concrete 11
fill ~32 ~17 ~83 ~32 ~18 ~83 concrete 11
fill ~32 ~17 ~84 ~32 ~18 ~84 concrete 11
fill ~32 ~17 ~85 ~32 ~17 ~88 concrete 11
fill ~33 ~17 ~65 ~36 ~17 ~65 concrete 0
setblock ~33 ~17 ~66 quartz_block 0
fill ~33 ~17 ~67 ~33 ~18 ~67 concrete 0
setblock ~33 ~17 ~68 snow 0
setblock ~33 ~17 ~69 concrete 0
setblock ~33 ~17 ~70 quartz_block 0
fill ~33 ~17 ~72 ~33 ~18 ~72 concrete 11
fill ~33 ~17 ~73 ~33 ~17 ~72 concrete 11
fill ~33 ~17 ~79 ~33 ~18 ~79 concrete 11
setblock ~33 ~17 ~80 wool 11
setblock ~33 ~17 ~81 concrete 11
fill ~34 ~17 ~70 ~34 ~17 ~71 concrete 11
fill ~34 ~17 ~76 ~34 ~18 ~76 concrete 11
fill ~34 ~17 ~77 ~34 ~17 ~76 concrete 11
setblock ~34 ~17 ~87 snow 0
setblock ~34 ~17 ~88 concrete 0
setblock ~34 ~17 ~89 quartz_block 0
fill ~34 ~17 ~90 ~34 ~17 ~91 concrete 0
fill ~34 ~17 ~92 ~35 ~17 ~92 stained_hardened_clay 0
fill ~34 ~17 ~93 ~34 ~17 ~92 stained_hardened_clay 0
setblock ~35 ~17 ~64 snow 0
fill ~35 ~17 ~67 ~35 ~19 ~67 concrete 11
setblock ~35 ~17 ~68 wool 11
fill ~35 ~17 ~73 ~35 ~18 ~73 concrete 11
fill ~35 ~17 ~74 ~35 ~17 ~75 concrete 11
fill ~35 ~17 ~84 ~35 ~18 ~84 snow 0
setblock ~35 ~17 ~85 concrete 0
setblock ~35 ~17 ~86 snow 0
fill ~35 ~17 ~93 ~36 ~17 ~93 wool 8
fill ~35 ~17 ~94 ~35 ~17 ~93 wool 8
fill ~36 ~17 ~64 ~36 ~19 ~64 concrete 0
setblock ~36 ~17 ~66 concrete 11
fill ~36 ~17 ~71 ~36 ~17 ~72 concrete 11
setblock ~36 ~17 ~81 snow 0
setblock ~36 ~17 ~82 concrete 0
setblock ~36 ~17 ~83 snow 0
setblock ~36 ~17 ~94 mossy_cobblestone 0
fill ~36 ~17 ~95 ~39 ~17 ~95 wool 8
setblock ~37 ~17 ~64 snow 0
setblock ~37 ~17 ~65 wool 10
fill ~37 ~17 ~69 ~37 ~17 ~70 concrete 11
setblock ~37 ~17 ~79 concrete 0
setblock ~37 ~17 ~80 snow 0
setblock ~37 ~17 ~94 wool 8
setblock ~38 ~17 ~64 concrete 0
setblock ~38 ~17 ~65 light_blue_glazed_terracotta 0
fill ~38 ~17 ~67 ~38 ~17 ~68 concrete 11
setblock ~38 ~17 ~76 concrete 0
setblock ~38 ~17 ~77 quartz_block 0
setblock ~38 ~17 ~96 mossy_cobblestone 0
fill ~39 ~17 ~63 ~39 ~18 ~63 concrete 0
setblock ~39 ~17 ~64 snow 0
setblock ~39 ~17 ~65 wool 10
setblock ~39 ~17 ~66 wool 11
setblock ~39 ~17 ~74 snow 0
setblock ~39 ~17 ~75 concrete 0
fill ~39 ~17 ~96 ~39 ~17 ~97 wool 8
setblock ~40 ~17 ~63 quartz_block 0
fill ~40 ~17 ~64 ~40 ~17 ~65 concrete 0
setblock ~40 ~17 ~73 snow 0
setblock ~40 ~17 ~96 mossy_cobblestone 0
fill ~40 ~17 ~97 ~44 ~17 ~97 wool 8
setblock ~40 ~17 ~98 mossy_cobblestone 0
fill ~41 ~17 ~63 ~43 ~17 ~63 concrete 0
setblock ~41 ~17 ~64 snow 0
fill ~41 ~17 ~65 ~42 ~17 ~65 concrete 0
setblock ~41 ~17 ~72 snow 0
setblock ~41 ~17 ~96 wool 8
setblock ~41 ~17 ~98 wool 8
fill ~42 ~17 ~64 ~42 ~18 ~64 concrete 0
setblock ~42 ~17 ~71 snow 0
setblock ~42 ~17 ~98 mossy_cobblestone 0
setblock ~43 ~17 ~65 light_blue_glazed_terracotta 0
setblock ~43 ~17 ~66 wool 11
setblock ~43 ~17 ~70 snow 0
setblock ~43 ~17 ~98 wool 8
setblock ~44 ~17 ~62 concrete 0
setblock ~44 ~17 ~65 wool 10
fill ~44 ~17 ~67 ~44 ~18 ~67 concrete 11
setblock ~44 ~17 ~70 concrete 0
setblock ~44 ~17 ~98 mossy_cobblestone 0
fill ~45 ~17 ~63 ~46 ~17 ~63 concrete 0
setblock ~45 ~17 ~65 light_blue_glazed_terracotta 0
setblock ~45 ~17 ~69 light_blue_glazed_terracotta 0
