setblock ~43 ~45 ~35 chest 5
setblock ~43 ~45 ~33 chest 5
setblock ~43 ~45 ~32 chest 5
setblock ~43 ~44 ~33 chest 5
setblock ~43 ~44 ~32 chest 5
setblock ~43 ~44 ~35 chest 5
setblock ~43 ~44 ~36 chest 5
setblock ~43 ~44 ~39 chest 5
setblock ~43 ~44 ~38 chest 5
setblock ~43 ~45 ~36 chest 5
setblock ~43 ~45 ~38 chest 5
setblock ~43 ~45 ~39 chest 5
setblock ~46 ~44 ~35 chest 5
setblock ~46 ~44 ~32 chest 5
setblock ~46 ~44 ~33 chest 5
setblock ~46 ~44 ~38 chest 5
setblock ~46 ~44 ~39 chest 5
setblock ~46 ~44 ~36 chest 5
setblock ~44 ~44 ~44 chest 3
setblock ~43 ~44 ~47 chest 5
setblock ~43 ~44 ~46 chest 5
setblock ~44 ~45 ~44 chest 3
setblock ~43 ~45 ~47 chest 5
setblock ~45 ~44 ~41 chest 2
setblock ~43 ~45 ~46 chest 5
setblock ~44 ~44 ~41 chest 2
setblock ~45 ~44 ~44 chest 3
setblock ~44 ~45 ~41 chest 2
setblock ~45 ~45 ~41 chest 2
setblock ~45 ~45 ~44 chest 3
setblock ~46 ~44 ~46 chest 5
setblock ~46 ~44 ~47 chest 5
setblock ~43 ~44 ~49 chest 5
setblock ~43 ~44 ~50 chest 5
setblock ~43 ~45 ~50 chest 5
setblock ~43 ~45 ~49 chest 5
setblock ~43 ~44 ~53 chest 5
setblock ~43 ~44 ~52 chest 5
setblock ~43 ~45 ~52 chest 5
setblock ~43 ~45 ~53 chest 5
setblock ~46 ~44 ~50 chest 5
setblock ~46 ~44 ~49 chest 5
setblock ~46 ~44 ~53 chest 5
setblock ~46 ~44 ~52 chest 5
setblock ~48 ~44 ~33 chest 4
setblock ~48 ~44 ~32 chest 4
setblock ~48 ~44 ~35 chest 4
setblock ~48 ~44 ~36 chest 4
setblock ~48 ~44 ~39 chest 4
setblock ~48 ~44 ~38 chest 4
setblock ~51 ~44 ~33 chest 4
setblock ~51 ~45 ~32 chest 4
setblock ~51 ~44 ~32 chest 4
setblock ~51 ~44 ~35 chest 4
setblock ~51 ~45 ~35 chest 4
setblock ~51 ~45 ~33 chest 4
setblock ~51 ~44 ~36 chest 4
setblock ~51 ~44 ~39 chest 4
setblock ~51 ~44 ~38 chest 4
setblock ~51 ~45 ~39 chest 4
setblock ~51 ~45 ~38 chest 4
setblock ~51 ~45 ~36 chest 4
setblock ~48 ~44 ~47 chest 4
setblock ~48 ~44 ~46 chest 4
setblock ~48 ~44 ~50 chest 4
setblock ~48 ~44 ~49 chest 4
setblock ~48 ~44 ~53 chest 4
setblock ~48 ~44 ~52 chest 4
setblock ~50 ~45 ~44 chest 3
setblock ~49 ~44 ~44 chest 3
setblock ~49 ~44 ~41 chest 2
setblock ~50 ~45 ~41 chest 2
setblock ~49 ~45 ~44 chest 3
setblock ~49 ~45 ~41 chest 2
setblock ~51 ~44 ~47 chest 4
setblock ~51 ~44 ~46 chest 4
setblock ~50 ~44 ~41 chest 2
setblock ~50 ~44 ~44 chest 3
setblock ~51 ~45 ~47 chest 4
setblock ~51 ~45 ~46 chest 4
setblock ~51 ~44 ~49 chest 4
setblock ~51 ~44 ~50 chest 4
setblock ~51 ~45 ~49 chest 4
setblock ~51 ~45 ~50 chest 4
setblock ~51 ~45 ~53 chest 4
setblock ~51 ~45 ~52 chest 4
setblock ~51 ~44 ~53 chest 4
setblock ~51 ~44 ~52 chest 4
fill ~1 ~-3 ~0 ~43 ~-3 ~0 grass 0
fill ~1 ~-3 ~1 ~35 ~-3 ~1 grass 0
fill ~1 ~-3 ~2 ~28 ~-3 ~2 grass 0
fill ~1 ~-3 ~3 ~27 ~-3 ~3 grass 0
fill ~1 ~-3 ~4 ~23 ~-3 ~4 grass 0
fill ~1 ~-3 ~5 ~22 ~-3 ~5 grass 0
fill ~1 ~-3 ~6 ~21 ~-3 ~6 grass 0
fill ~1 ~-3 ~7 ~20 ~-3 ~7 grass 0
fill ~1 ~-3 ~8 ~19 ~-3 ~8 grass 0
fill ~1 ~-3 ~9 ~19 ~-3 ~9 grass 0
fill ~1 ~-3 ~10 ~18 ~-3 ~10 grass 0
fill ~1 ~-3 ~11 ~17 ~-3 ~11 grass 0
fill ~1 ~-3 ~12 ~16 ~-3 ~12 grass 0
fill ~1 ~-3 ~13 ~16 ~-3 ~13 grass 0
fill ~1 ~-3 ~14 ~15 ~-3 ~14 grass 0
fill ~1 ~-3 ~15 ~14 ~-3 ~15 grass 0
fill ~1 ~-3 ~16 ~14 ~-3 ~16 grass 0
fill ~1 ~-3 ~17 ~13 ~-3 ~17 grass 0
fill ~1 ~-3 ~18 ~12 ~-3 ~18 grass 0
fill ~1 ~-3 ~19 ~11 ~-3 ~19 grass 0
fill ~1 ~-3 ~20 ~10 ~-3 ~20 grass 0
fill ~1 ~-3 ~21 ~9 ~-3 ~21 grass 0
fill ~1 ~-3 ~22 ~8 ~-3 ~22 grass 0
fill ~1 ~-3 ~23 ~7 ~-3 ~23 grass 0
fill ~1 ~-3 ~24 ~7 ~-3 ~24 grass 0
fill ~1 ~-3 ~25 ~6 ~-3 ~25 grass 0
fill ~1 ~-3 ~26 ~5 ~-3 ~26 grass 0
fill ~1 ~-3 ~27 ~4 ~-3 ~27 grass 0
fill ~1 ~-3 ~28 ~3 ~-3 ~28 grass 0
fill ~1 ~-3 ~29 ~3 ~-3 ~29 grass 0
fill ~1 ~-3 ~30 ~3 ~-3 ~30 grass 0
fill ~1 ~-3 ~31 ~3 ~-3 ~31 grass 0
fill ~1 ~-3 ~32 ~3 ~-3 ~32 grass 0
fill ~1 ~-3 ~33 ~2 ~-3 ~33 grass 0
fill ~1 ~-3 ~34 ~2 ~-3 ~34 grass 0
fill ~1 ~-3 ~35 ~2 ~-3 ~35 grass 0
fill ~1 ~-3 ~36 ~2 ~-3 ~36 grass 0
fill ~1 ~-3 ~37 ~2 ~-3 ~37 grass 0
fill ~1 ~-3 ~38 ~1 ~-3 ~88 grass 0
fill ~2 ~-3 ~38 ~15 ~-3 ~38 water 0
fill ~2 ~-3 ~39 ~15 ~-3 ~39 water 0
fill ~2 ~-3 ~40 ~15 ~-3 ~40 water 0
fill ~2 ~-3 ~41 ~15 ~-3 ~41 water 0
fill ~2 ~-3 ~42 ~15 ~-3 ~42 water 0
fill ~2 ~-3 ~43 ~15 ~-3 ~43 water 0
fill ~2 ~-3 ~44 ~15 ~-3 ~44 water 0
fill ~2 ~-3 ~45 ~15 ~-3 ~45 water 0
fill ~2 ~-3 ~46 ~15 ~-3 ~46 water 0
fill ~2 ~-3 ~47 ~15 ~-3 ~47 water 0
fill ~2 ~-3 ~48 ~15 ~-3 ~48 water 0
fill ~2 ~-3 ~49 ~15 ~-3 ~49 water 0
fill ~2 ~-3 ~50 ~14 ~-3 ~50 water 0
fill ~2 ~-3 ~51 ~15 ~-3 ~51 water 0
fill ~2 ~-3 ~52 ~15 ~-3 ~52 water 0
fill ~2 ~-3 ~53 ~15 ~-3 ~53 water 0
fill ~2 ~-3 ~54 ~15 ~-3 ~54 water 0
fill ~2 ~-3 ~55 ~15 ~-3 ~55 water 0
fill ~2 ~-3 ~56 ~15 ~-3 ~56 water 0
fill ~2 ~-3 ~57 ~15 ~-3 ~57 water 0
fill ~2 ~-3 ~58 ~15 ~-3 ~58 water 0
fill ~2 ~-3 ~59 ~15 ~-3 ~59 water 0
fill ~2 ~-3 ~60 ~2 ~-3 ~88 grass 0
fill ~3 ~-3 ~33 ~17 ~-3 ~33 water 0
fill ~3 ~-3 ~34 ~16 ~-3 ~34 water 0
fill ~3 ~-3 ~35 ~16 ~-3 ~35 water 0
fill ~3 ~-3 ~36 ~16 ~-3 ~36 water 0
fill ~3 ~-3 ~37 ~15 ~-3 ~37 water 0
fill ~3 ~-3 ~60 ~15 ~-3 ~60 water 0
fill ~3 ~-3 ~61 ~15 ~-3 ~61 water 0
fill ~3 ~-3 ~62 ~16 ~-3 ~62 water 0
fill ~3 ~-3 ~63 ~18 ~-3 ~63 water 0
fill ~3 ~-3 ~64 ~18 ~-3 ~64 water 0
fill ~3 ~-3 ~65 ~19 ~-3 ~65 water 0
fill ~3 ~-3 ~66 ~3 ~-3 ~88 grass 0
fill ~4 ~-3 ~28 ~19 ~-3 ~28 water 0
fill ~4 ~-3 ~29 ~19 ~-3 ~29 water 0
fill ~4 ~-3 ~30 ~19 ~-3 ~30 water 0
fill ~4 ~-3 ~31 ~18 ~-3 ~31 water 0
fill ~4 ~-3 ~32 ~18 ~-3 ~32 water 0
fill ~4 ~-3 ~66 ~19 ~-3 ~66 water 0
fill ~4 ~-3 ~67 ~20 ~-3 ~67 water 0
fill ~4 ~-3 ~68 ~26 ~-3 ~68 water 0
fill ~4 ~-3 ~69 ~30 ~-3 ~69 water 0
fill ~4 ~-3 ~70 ~4 ~-3 ~88 grass 0
fill ~5 ~-3 ~27 ~19 ~-3 ~27 water 0
fill ~5 ~-3 ~70 ~38 ~-3 ~70 water 0
fill ~5 ~-3 ~71 ~44 ~-3 ~71 water 0
fill ~5 ~-3 ~72 ~5 ~-3 ~88 grass 0
fill ~6 ~-3 ~26 ~20 ~-3 ~26 water 0
fill ~6 ~-3 ~72 ~93 ~-3 ~72 water 0
fill ~6 ~-3 ~73 ~6 ~-3 ~88 grass 0
fill ~7 ~-3 ~25 ~18 ~-3 ~25 water 0
fill ~7 ~-3 ~73 ~93 ~-3 ~73 water 0
fill ~7 ~-3 ~74 ~7 ~-3 ~88 grass 0
fill ~8 ~-3 ~23 ~17 ~-3 ~23 water 0
fill ~8 ~-3 ~24 ~17 ~-3 ~24 water 0
fill ~8 ~-3 ~74 ~92 ~-3 ~74 water 0
fill ~8 ~-3 ~75 ~8 ~-3 ~88 grass 0
fill ~9 ~-3 ~22 ~17 ~-3 ~22 water 0
fill ~9 ~-3 ~75 ~92 ~-3 ~75 water 0
fill ~9 ~-3 ~76 ~9 ~-3 ~88 grass 0
fill ~10 ~-3 ~21 ~18 ~-3 ~21 water 0
fill ~10 ~-3 ~76 ~92 ~-3 ~76 water 0
fill ~10 ~-3 ~77 ~10 ~-3 ~88 grass 0
fill ~11 ~-3 ~20 ~20 ~-3 ~20 water 0
fill ~11 ~-3 ~77 ~92 ~-3 ~77 water 0
fill ~11 ~-3 ~78 ~11 ~-3 ~88 grass 0
fill ~12 ~-3 ~19 ~19 ~-3 ~19 water 0
fill ~12 ~-3 ~78 ~91 ~-3 ~78 water 0
fill ~12 ~-3 ~79 ~12 ~-3 ~88 grass 0
fill ~13 ~-3 ~18 ~19 ~-3 ~18 water 0
fill ~13 ~-3 ~79 ~91 ~-3 ~79 water 0
fill ~13 ~-3 ~80 ~13 ~-3 ~88 grass 0
fill ~14 ~-3 ~17 ~19 ~-3 ~17 water 0
fill ~14 ~-3 ~80 ~91 ~-3 ~80 water 0
fill ~14 ~-3 ~81 ~14 ~-3 ~88 grass 0
fill ~15 ~-3 ~15 ~26 ~-3 ~15 water 0
fill ~15 ~-3 ~16 ~20 ~-3 ~16 water 0 
setblock ~15 ~-3 ~50 grass 0
fill ~15 ~-3 ~81 ~90 ~-3 ~81 water 0
fill ~15 ~-3 ~82 ~16 ~-3 ~82 grass 0
fill ~15 ~-3 ~83 ~17 ~-3 ~83 grass 0
fill ~15 ~-3 ~84 ~21 ~-3 ~84 grass 0
fill ~15 ~-3 ~85 ~35 ~-3 ~85 grass 0
fill ~15 ~-3 ~86 ~42 ~-3 ~86 grass 0
fill ~15 ~-3 ~87 ~45 ~-3 ~87 grass 0
fill ~15 ~-3 ~88 ~97 ~-3 ~88 grass 0
fill ~16 ~-3 ~14 ~32 ~-3 ~14 water 0
fill ~16 ~-3 ~37 ~16 ~-3 ~40 grass 0
fill ~16 ~-3 ~41 ~82 ~-3 ~41 dirt 0
fill ~16 ~-3 ~42 ~82 ~-3 ~42 dirt 0
fill ~16 ~-3 ~43 ~82 ~-3 ~43 dirt 0
fill ~16 ~-3 ~44 ~81 ~-3 ~44 dirt 0
fill ~16 ~-3 ~45 ~83 ~-3 ~45 dirt 0
fill ~16 ~-3 ~46 ~83 ~-3 ~46 dirt 0
fill ~16 ~-3 ~47 ~82 ~-3 ~47 dirt 0
fill ~16 ~-3 ~48 ~81 ~-3 ~48 dirt 0
fill ~16 ~-3 ~49 ~82 ~-3 ~49 dirt 0
fill ~16 ~-3 ~50 ~82 ~-3 ~50 dirt 0
fill ~16 ~-3 ~51 ~81 ~-3 ~51 dirt 0
fill ~16 ~-3 ~52 ~77 ~-3 ~52 dirt 0
fill ~16 ~-3 ~53 ~78 ~-3 ~53 dirt 0
fill ~16 ~-3 ~54 ~78 ~-3 ~54 dirt 0
fill ~16 ~-3 ~55 ~77 ~-3 ~55 dirt 0
fill ~16 ~-3 ~56 ~81 ~-3 ~56 dirt 0
fill ~16 ~-3 ~57 ~81 ~-3 ~57 dirt 0
fill ~16 ~-3 ~58 ~81 ~-3 ~58 dirt 0
fill ~16 ~-3 ~59 ~81 ~-3 ~59 dirt 0
fill ~16 ~-3 ~60 ~16 ~-3 ~61 grass 0
fill ~17 ~-3 ~12 ~37 ~-3 ~12 water 0
fill ~17 ~-3 ~13 ~37 ~-3 ~13 water 0
fill ~17 ~-3 ~34 ~17 ~-3 ~36 grass 0
fill ~17 ~-3 ~37 ~83 ~-3 ~37 dirt 0
fill ~17 ~-3 ~38 ~83 ~-3 ~38 dirt 0
fill ~17 ~-3 ~39 ~81 ~-3 ~39 dirt 0
fill ~17 ~-3 ~40 ~82 ~-3 ~40 dirt 0
fill ~17 ~-3 ~60 ~80 ~-3 ~60 dirt 0
fill ~17 ~-3 ~61 ~17 ~-3 ~62 grass 0
fill ~17 ~-3 ~82 ~89 ~-3 ~82 water 0
fill ~18 ~-3 ~11 ~37 ~-3 ~11 water 0
fill ~18 ~-3 ~22 ~24 ~-3 ~22 dirt 0
fill ~18 ~-3 ~23 ~76 ~-3 ~23 dirt 0
fill ~18 ~-3 ~24 ~76 ~-3 ~24 dirt 0 
setblock ~18 ~-3 ~33 grass 0
fill ~18 ~-3 ~34 ~82 ~-3 ~34 dirt 0
fill ~18 ~-3 ~35 ~83 ~-3 ~35 dirt 0
fill ~18 ~-3 ~36 ~83 ~-3 ~36 dirt 0
fill ~18 ~-3 ~61 ~80 ~-3 ~61 dirt 0
fill ~18 ~-3 ~62 ~80 ~-3 ~62 dirt 0
fill ~18 ~-3 ~83 ~87 ~-3 ~83 water 0
fill ~19 ~-3 ~10 ~37 ~-3 ~10 water 0
fill ~19 ~-3 ~21 ~76 ~-3 ~21 dirt 0
fill ~19 ~-3 ~25 ~76 ~-3 ~25 dirt 0
fill ~19 ~-3 ~31 ~19 ~-3 ~32 grass 0
fill ~19 ~-3 ~33 ~82 ~-3 ~33 dirt 0
fill ~19 ~-3 ~63 ~19 ~-3 ~64 grass 0
fill ~20 ~-3 ~8 ~37 ~-3 ~8 water 0
fill ~20 ~-3 ~9 ~37 ~-3 ~9 water 0
fill ~20 ~-3 ~17 ~20 ~-3 ~19 grass 0
fill ~20 ~-3 ~27 ~20 ~-3 ~29 grass 0
fill ~20 ~-3 ~30 ~22 ~-3 ~30 dirt 0
fill ~20 ~-3 ~31 ~22 ~-3 ~31 dirt 0
fill ~20 ~-3 ~32 ~81 ~-3 ~32 dirt 0
fill ~20 ~-3 ~63 ~79 ~-3 ~63 dirt 0
fill ~20 ~-3 ~64 ~80 ~-3 ~64 dirt 0
fill ~20 ~-3 ~65 ~79 ~-3 ~65 dirt 0
fill ~20 ~-3 ~66 ~79 ~-3 ~66 dirt 0
fill ~21 ~-3 ~7 ~37 ~-3 ~7 water 0
fill ~21 ~-3 ~16 ~23 ~-3 ~16 grass 0
fill ~21 ~-3 ~17 ~74 ~-3 ~17 dirt 0
fill ~21 ~-3 ~18 ~68 ~-3 ~18 dirt 0
fill ~21 ~-3 ~19 ~74 ~-3 ~19 dirt 0
fill ~21 ~-3 ~20 ~74 ~-3 ~20 dirt 0
fill ~21 ~-3 ~26 ~79 ~-3 ~26 dirt 0
fill ~21 ~-3 ~27 ~79 ~-3 ~27 dirt 0
fill ~21 ~-3 ~28 ~23 ~-3 ~28 dirt 0
fill ~21 ~-3 ~29 ~22 ~-3 ~29 dirt 0
fill ~21 ~-3 ~67 ~23 ~-3 ~67 dirt 0
fill ~22 ~-3 ~6 ~37 ~-3 ~6 water 0
fill ~22 ~-3 ~84 ~78 ~-3 ~84 water 0
fill ~23 ~-3 ~5 ~37 ~-3 ~5 water 0
fill ~23 ~-3 ~29 ~24 ~-3 ~29 grass 0
fill ~23 ~-3 ~30 ~23 ~-3 ~31 grass 0
fill ~24 ~-3 ~4 ~37 ~-3 ~4 water 0
fill ~24 ~-3 ~16 ~25 ~-3 ~16 water 0 
setblock ~24 ~-3 ~28 grass 0
fill ~24 ~-3 ~30 ~80 ~-3 ~30 dirt 0
fill ~24 ~-3 ~31 ~80 ~-3 ~31 dirt 0
fill ~24 ~-3 ~67 ~26 ~-3 ~67 grass 0
fill ~25 ~-3 ~28 ~79 ~-3 ~28 dirt 0
fill ~25 ~-3 ~29 ~80 ~-3 ~29 dirt 0
fill ~26 ~-3 ~16 ~71 ~-3 ~16 dirt 0
fill ~26 ~-3 ~22 ~76 ~-3 ~22 dirt 0
fill ~27 ~-3 ~15 ~29 ~-3 ~15 dirt 0
fill ~27 ~-3 ~67 ~78 ~-3 ~67 dirt 0
fill ~27 ~-3 ~68 ~30 ~-3 ~68 grass 0
fill ~28 ~-3 ~3 ~37 ~-3 ~3 water 0 
setblock ~29 ~-3 ~2 water 0 
setblock ~30 ~-3 ~2 water 1
fill ~30 ~-3 ~15 ~31 ~-3 ~15 water 0
fill ~31 ~-3 ~2 ~37 ~-3 ~2 water 0
fill ~31 ~-3 ~68 ~75 ~-3 ~68 dirt 0
fill ~31 ~-3 ~69 ~37 ~-3 ~69 grass 0 
setblock ~32 ~-3 ~15 grass 0
fill ~33 ~-3 ~14 ~37 ~-3 ~14 grass 0
fill ~33 ~-3 ~15 ~69 ~-3 ~15 dirt 0
fill ~36 ~-3 ~1 ~37 ~-3 ~1 water 0
fill ~36 ~-3 ~85 ~76 ~-3 ~85 water 0
fill ~38 ~-3 ~1 ~43 ~-3 ~1 grass 0
fill ~38 ~-3 ~2 ~43 ~-3 ~2 grass 0
fill ~38 ~-3 ~3 ~38 ~-3 ~3 dirt 0
fill ~38 ~-3 ~4 ~38 ~-3 ~4 dirt 0
fill ~38 ~-3 ~5 ~38 ~-3 ~5 dirt 0
fill ~38 ~-3 ~6 ~38 ~-3 ~6 dirt 0
fill ~38 ~-3 ~7 ~38 ~-3 ~7 dirt 0
fill ~38 ~-3 ~8 ~38 ~-3 ~8 dirt 0
fill ~38 ~-3 ~9 ~38 ~-3 ~9 dirt 0
fill ~38 ~-3 ~10 ~38 ~-3 ~10 dirt 0
fill ~38 ~-3 ~11 ~38 ~-3 ~11 dirt 0
fill ~38 ~-3 ~12 ~38 ~-3 ~12 dirt 0
fill ~38 ~-3 ~13 ~38 ~-3 ~13 dirt 0
fill ~38 ~-3 ~14 ~66 ~-3 ~14 dirt 0
fill ~38 ~-3 ~69 ~67 ~-3 ~69 dirt 0
fill ~39 ~-3 ~3 ~39 ~3 ~3 cobblestone 0
fill ~39 ~-3 ~4 ~55 ~-3 ~4 stonebrick 0
fill ~39 ~-3 ~5 ~55 ~-3 ~5 stonebrick 0
fill ~39 ~-3 ~6 ~55 ~-3 ~6 stonebrick 0
fill ~39 ~-3 ~7 ~55 ~-3 ~7 stonebrick 0
fill ~39 ~-3 ~8 ~55 ~-3 ~8 stonebrick 0
fill ~39 ~-3 ~9 ~55 ~-3 ~9 stonebrick 0
fill ~39 ~-3 ~10 ~55 ~-3 ~10 stonebrick 0
fill ~39 ~-3 ~11 ~55 ~-3 ~11 stonebrick 0
fill ~39 ~-3 ~12 ~55 ~-3 ~12 stonebrick 0
fill ~39 ~-3 ~13 ~55 ~-3 ~13 stonebrick 0
fill ~39 ~-3 ~70 ~44 ~-3 ~70 grass 0
fill ~40 ~-3 ~3 ~56 ~-3 ~3 dirt 0
fill ~43 ~-3 ~86 ~64 ~-3 ~86 water 0 
setblock ~44 ~-3 ~0 stonebrick 3
fill ~44 ~-3 ~1 ~50 ~-3 ~1 dirt 0
fill ~44 ~-3 ~2 ~50 ~-3 ~2 dirt 0
fill ~45 ~-3 ~0 ~49 ~-3 ~0 clay 0
fill ~45 ~-3 ~70 ~61 ~-3 ~70 dirt 0
fill ~45 ~-3 ~71 ~61 ~-3 ~71 grass 0
fill ~46 ~-3 ~87 ~59 ~-3 ~87 water 0
fill ~50 ~-3 ~0 ~50 ~-2 ~0 double_stone_slab 0
fill ~51 ~-3 ~0 ~97 ~-3 ~0 grass 0
fill ~51 ~-3 ~1 ~56 ~-3 ~1 grass 0
fill ~51 ~-3 ~2 ~56 ~-3 ~2 grass 0
fill ~56 ~-3 ~4 ~56 ~-3 ~4 dirt 0
fill ~56 ~-3 ~5 ~56 ~-3 ~5 dirt 0
fill ~56 ~-3 ~6 ~56 ~-3 ~6 dirt 0
fill ~56 ~-3 ~7 ~56 ~-3 ~7 dirt 0
fill ~56 ~-3 ~8 ~56 ~-3 ~8 dirt 0
fill ~56 ~-3 ~9 ~56 ~-3 ~9 dirt 0
fill ~56 ~-3 ~10 ~56 ~-3 ~10 dirt 0
fill ~56 ~-3 ~11 ~56 ~-3 ~11 dirt 0
fill ~56 ~-3 ~12 ~56 ~-3 ~12 dirt 0
fill ~56 ~-3 ~13 ~56 ~-3 ~13 dirt 0
fill ~57 ~-3 ~1 ~64 ~-3 ~1 water 0
fill ~57 ~-3 ~2 ~57 ~-3 ~13 water 0 
setblock ~58 ~-3 ~2 water 1
fill ~58 ~-3 ~3 ~68 ~-3 ~3 water 0
fill ~58 ~-3 ~4 ~58 ~-3 ~13 water 0
fill ~59 ~-3 ~2 ~66 ~-3 ~2 water 0 
setblock ~59 ~-3 ~4 water 1
fill ~59 ~-3 ~5 ~70 ~-3 ~5 water 0
fill ~59 ~-3 ~6 ~72 ~-3 ~6 water 0
fill ~59 ~-3 ~7 ~74 ~-3 ~7 water 0
fill ~59 ~-3 ~8 ~81 ~-3 ~8 water 0
fill ~59 ~-3 ~9 ~81 ~-3 ~9 water 0
fill ~59 ~-3 ~10 ~82 ~-3 ~10 water 0
fill ~59 ~-3 ~11 ~82 ~-3 ~11 water 0
fill ~59 ~-3 ~12 ~85 ~-3 ~12 water 0
fill ~59 ~-3 ~13 ~67 ~-3 ~13 grass 0
fill ~60 ~-3 ~4 ~69 ~-3 ~4 water 0
fill ~60 ~-3 ~87 ~97 ~-3 ~87 grass 0
fill ~62 ~-3 ~70 ~71 ~-3 ~70 grass 0
fill ~62 ~-3 ~71 ~93 ~-3 ~71 water 0
fill ~65 ~-3 ~1 ~97 ~-3 ~1 grass 0
fill ~65 ~-3 ~86 ~97 ~-3 ~86 grass 0
fill ~67 ~-3 ~2 ~97 ~-3 ~2 grass 0
fill ~67 ~-3 ~14 ~70 ~-3 ~14 grass 0
fill ~68 ~-3 ~13 ~86 ~-3 ~13 water 0
fill ~69 ~-3 ~3 ~97 ~-3 ~3 grass 0 
setblock ~69 ~-3 ~18 water 0
fill ~70 ~-3 ~4 ~97 ~-3 ~4 grass 0
fill ~70 ~-3 ~15 ~72 ~-3 ~15 grass 0
fill ~70 ~-3 ~18 ~71 ~-3 ~18 dirt 0
fill ~71 ~-3 ~5 ~97 ~-3 ~5 grass 0
fill ~71 ~-3 ~14 ~86 ~-3 ~14 water 0
fill ~71 ~-3 ~69 ~75 ~-3 ~69 grass 0
fill ~72 ~-3 ~16 ~74 ~-3 ~16 grass 0 
setblock ~72 ~-3 ~18 grass 0
fill ~72 ~-3 ~70 ~93 ~-3 ~70 water 0
fill ~73 ~-3 ~6 ~97 ~-3 ~6 grass 0
fill ~73 ~-3 ~15 ~87 ~-3 ~15 water 0 
setblock ~74 ~-3 ~18 water 0
fill ~75 ~-3 ~7 ~97 ~-3 ~7 grass 0
fill ~75 ~-3 ~16 ~88 ~-3 ~16 water 0 
setblock ~75 ~-3 ~17 grass 0
fill ~75 ~-3 ~18 ~75 ~-3 ~18 dirt 0
fill ~75 ~-3 ~19 ~75 ~-3 ~20 water 0
fill ~76 ~-3 ~17 ~89 ~-3 ~17 water 0 
setblock ~76 ~-3 ~18 grass 0
fill ~76 ~-3 ~19 ~76 ~-3 ~19 dirt 0 
setblock ~76 ~-3 ~20 water 0
fill ~76 ~-3 ~68 ~78 ~-3 ~68 grass 0
fill ~76 ~-3 ~69 ~94 ~-3 ~69 water 0
fill ~77 ~-3 ~18 ~90 ~-3 ~18 water 0 
setblock ~77 ~-3 ~19 grass 0
fill ~77 ~-3 ~20 ~77 ~-3 ~20 dirt 0 
setblock ~77 ~-3 ~21 water 1 
setblock ~77 ~-3 ~22 water 0 
setblock ~77 ~-3 ~23 water 1
fill ~77 ~-3 ~24 ~77 ~-3 ~25 grass 0
fill ~77 ~-3 ~85 ~97 ~-3 ~85 grass 0
fill ~78 ~-3 ~19 ~90 ~-3 ~19 water 0
fill ~78 ~-3 ~20 ~78 ~-3 ~21 grass 0
fill ~78 ~-3 ~22 ~78 ~-3 ~22 dirt 0
fill ~78 ~-3 ~23 ~79 ~-3 ~23 dirt 0
fill ~78 ~-3 ~24 ~79 ~-3 ~24 dirt 0
fill ~78 ~-3 ~25 ~79 ~-3 ~25 dirt 0 
setblock ~78 ~-3 ~52 grass 0 
setblock ~78 ~-3 ~55 grass 0
fill ~79 ~-3 ~20 ~91 ~-3 ~20 water 0
fill ~79 ~-3 ~21 ~91 ~-3 ~21 water 0 
setblock ~79 ~-3 ~22 grass 0
fill ~79 ~-3 ~55 ~81 ~-3 ~55 dirt 0 
setblock ~79 ~-3 ~67 grass 0
fill ~79 ~-3 ~68 ~94 ~-3 ~68 water 0
fill ~79 ~-3 ~84 ~97 ~-3 ~84 grass 0
fill ~80 ~-3 ~22 ~92 ~-3 ~22 water 0
fill ~80 ~-3 ~23 ~92 ~-3 ~23 water 0
fill ~80 ~-3 ~24 ~93 ~-3 ~24 water 0
fill ~80 ~-3 ~25 ~93 ~-3 ~25 water 0
fill ~80 ~-3 ~26 ~94 ~-3 ~26 water 0
fill ~80 ~-3 ~27 ~94 ~-3 ~27 water 0
fill ~80 ~-3 ~28 ~81 ~-3 ~28 grass 0
fill ~80 ~-3 ~52 ~81 ~-3 ~52 dirt 0
fill ~80 ~-3 ~53 ~81 ~-3 ~53 dirt 0
fill ~80 ~-3 ~54 ~81 ~-3 ~54 dirt 0
fill ~80 ~-3 ~65 ~80 ~-3 ~66 grass 0
fill ~80 ~-3 ~67 ~94 ~-3 ~67 water 0 
setblock ~81 ~-3 ~29 grass 0 
setblock ~81 ~-3 ~30 water 1
fill ~81 ~-3 ~31 ~82 ~-3 ~31 grass 0
fill ~81 ~-3 ~60 ~81 ~-3 ~64 grass 0
fill ~81 ~-3 ~65 ~94 ~-3 ~65 water 0
fill ~81 ~-3 ~66 ~94 ~-3 ~66 water 0
fill ~82 ~-3 ~8 ~97 ~-3 ~8 grass 0
fill ~82 ~-3 ~9 ~97 ~-3 ~9 grass 0
fill ~82 ~-3 ~28 ~95 ~-3 ~28 water 0
fill ~82 ~-3 ~29 ~96 ~-3 ~29 water 0
fill ~82 ~-3 ~30 ~96 ~-3 ~30 water 0 
setblock ~82 ~-3 ~32 grass 0
fill ~82 ~-3 ~51 ~82 ~-3 ~58 grass 0
fill ~82 ~-3 ~59 ~94 ~-3 ~59 water 0
fill ~82 ~-3 ~60 ~94 ~-3 ~60 water 0
fill ~82 ~-3 ~61 ~94 ~-3 ~61 water 0
fill ~82 ~-3 ~62 ~94 ~-3 ~62 water 0
fill ~82 ~-3 ~63 ~94 ~-3 ~63 water 0
fill ~82 ~-3 ~64 ~94 ~-3 ~64 water 0
fill ~83 ~-3 ~10 ~97 ~-3 ~10 grass 0
fill ~83 ~-3 ~11 ~97 ~-3 ~11 grass 0
fill ~83 ~-3 ~31 ~96 ~-3 ~31 water 0
fill ~83 ~-3 ~32 ~96 ~-3 ~32 water 0
fill ~83 ~-3 ~33 ~83 ~-3 ~34 grass 0
fill ~83 ~-3 ~39 ~83 ~-3 ~39 dirt 0
fill ~83 ~-3 ~40 ~83 ~-3 ~43 grass 0
fill ~83 ~-3 ~44 ~83 ~-3 ~44 dirt 0
fill ~83 ~-3 ~47 ~83 ~-3 ~49 grass 0
fill ~83 ~-3 ~50 ~94 ~-3 ~50 water 0
fill ~83 ~-3 ~51 ~93 ~-3 ~51 water 0
fill ~83 ~-3 ~52 ~93 ~-3 ~52 water 0
fill ~83 ~-3 ~53 ~93 ~-3 ~53 water 0
fill ~83 ~-3 ~54 ~93 ~-3 ~54 water 0
fill ~83 ~-3 ~55 ~93 ~-3 ~55 water 0
fill ~83 ~-3 ~56 ~94 ~-3 ~56 water 0
fill ~83 ~-3 ~57 ~94 ~-3 ~57 water 0
fill ~83 ~-3 ~58 ~94 ~-3 ~58 water 0
fill ~84 ~-3 ~33 ~96 ~-3 ~33 water 0
fill ~84 ~-3 ~34 ~96 ~-3 ~34 water 0
fill ~84 ~-3 ~35 ~96 ~-3 ~35 water 0
fill ~84 ~-3 ~36 ~96 ~-3 ~36 water 0
fill ~84 ~-3 ~37 ~96 ~-3 ~37 water 0
fill ~84 ~-3 ~38 ~96 ~-3 ~38 water 0
fill ~84 ~-3 ~39 ~96 ~-3 ~39 water 0
fill ~84 ~-3 ~40 ~96 ~-3 ~40 water 0
fill ~84 ~-3 ~41 ~96 ~-3 ~41 water 0
fill ~84 ~-3 ~42 ~96 ~-3 ~42 water 0
fill ~84 ~-3 ~43 ~96 ~-3 ~43 water 0
fill ~84 ~-3 ~44 ~96 ~-3 ~44 water 0
fill ~84 ~-3 ~45 ~95 ~-3 ~45 water 0
fill ~84 ~-3 ~46 ~95 ~-3 ~46 water 0
fill ~84 ~-3 ~47 ~94 ~-3 ~47 water 0
fill ~84 ~-3 ~48 ~94 ~-3 ~48 water 0
fill ~84 ~-3 ~49 ~94 ~-3 ~49 water 0
fill ~86 ~-3 ~12 ~97 ~-3 ~12 grass 0
fill ~87 ~-3 ~13 ~97 ~-3 ~13 grass 0
fill ~87 ~-3 ~14 ~97 ~-3 ~14 grass 0
fill ~88 ~-3 ~15 ~97 ~-3 ~15 grass 0
fill ~88 ~-3 ~83 ~97 ~-3 ~83 grass 0
fill ~89 ~-3 ~16 ~97 ~-3 ~16 grass 0
fill ~90 ~-3 ~17 ~97 ~-3 ~17 grass 0
fill ~90 ~-3 ~82 ~97 ~-3 ~82 grass 0
fill ~91 ~-3 ~18 ~97 ~-3 ~18 grass 0
fill ~91 ~-3 ~19 ~97 ~-3 ~19 grass 0
fill ~91 ~-3 ~81 ~97 ~-3 ~81 grass 0
fill ~92 ~-3 ~20 ~97 ~-3 ~20 grass 0
fill ~92 ~-3 ~21 ~97 ~-3 ~21 grass 0
fill ~92 ~-3 ~78 ~97 ~-3 ~78 grass 0
fill ~92 ~-3 ~79 ~97 ~-3 ~79 grass 0
fill ~92 ~-3 ~80 ~97 ~-3 ~80 grass 0
fill ~93 ~-3 ~22 ~97 ~-3 ~22 grass 0
fill ~93 ~-3 ~23 ~97 ~-3 ~23 grass 0
fill ~93 ~-3 ~74 ~97 ~-3 ~74 grass 0
fill ~93 ~-3 ~75 ~97 ~-3 ~75 grass 0
fill ~93 ~-3 ~76 ~97 ~-3 ~76 grass 0
fill ~93 ~-3 ~77 ~97 ~-3 ~77 grass 0
fill ~94 ~-3 ~24 ~97 ~-3 ~24 grass 0
fill ~94 ~-3 ~25 ~97 ~-3 ~25 grass 0
fill ~94 ~-3 ~51 ~97 ~-3 ~51 grass 0
fill ~94 ~-3 ~52 ~97 ~-3 ~52 grass 0
fill ~94 ~-3 ~53 ~97 ~-3 ~53 grass 0
fill ~94 ~-3 ~54 ~97 ~-3 ~54 grass 0
fill ~94 ~-3 ~55 ~97 ~-3 ~55 grass 0
fill ~94 ~-3 ~70 ~97 ~-3 ~70 grass 0
fill ~94 ~-3 ~71 ~97 ~-3 ~71 grass 0
fill ~94 ~-3 ~72 ~97 ~-3 ~72 grass 0
fill ~94 ~-3 ~73 ~97 ~-3 ~73 grass 0
fill ~95 ~-3 ~26 ~97 ~-3 ~26 grass 0
fill ~95 ~-3 ~27 ~97 ~-3 ~27 grass 0
fill ~95 ~-3 ~47 ~97 ~-3 ~47 grass 0
fill ~95 ~-3 ~48 ~97 ~-3 ~48 grass 0
fill ~95 ~-3 ~49 ~97 ~-3 ~49 grass 0
fill ~95 ~-3 ~50 ~97 ~-3 ~50 grass 0
fill ~95 ~-3 ~56 ~97 ~-3 ~56 grass 0
fill ~95 ~-3 ~57 ~97 ~-3 ~57 grass 0
fill ~95 ~-3 ~58 ~97 ~-3 ~58 grass 0
fill ~95 ~-3 ~59 ~97 ~-3 ~59 grass 0
fill ~95 ~-3 ~60 ~97 ~-3 ~60 grass 0
fill ~95 ~-3 ~61 ~97 ~-3 ~61 grass 0
fill ~95 ~-3 ~62 ~97 ~-3 ~62 grass 0
fill ~95 ~-3 ~63 ~97 ~-3 ~63 grass 0
fill ~95 ~-3 ~64 ~97 ~-3 ~64 grass 0
fill ~95 ~-3 ~65 ~97 ~-3 ~65 grass 0
fill ~95 ~-3 ~66 ~97 ~-3 ~66 grass 0
fill ~95 ~-3 ~67 ~97 ~-3 ~67 grass 0
fill ~95 ~-3 ~68 ~97 ~-3 ~68 grass 0
fill ~95 ~-3 ~69 ~97 ~-3 ~69 grass 0
fill ~96 ~-3 ~28 ~97 ~-3 ~28 grass 0
fill ~96 ~-3 ~45 ~97 ~-3 ~45 grass 0
fill ~96 ~-3 ~46 ~97 ~-3 ~46 grass 0
fill ~97 ~-3 ~29 ~97 ~-3 ~88 grass 0 
setblock ~1 ~-2 ~69 tallgrass 1 
setblock ~2 ~-2 ~35 tallgrass 1 
setblock ~4 ~-2 ~75 tallgrass 1 
setblock ~5 ~-2 ~33 waterlily 0 
setblock ~6 ~-2 ~21 tallgrass 1 
setblock ~6 ~-2 ~24 tallgrass 1 
setblock ~6 ~-2 ~50 waterlily 0 
setblock ~6 ~-2 ~64 waterlily 0 
setblock ~6 ~-2 ~76 tallgrass 1 
setblock ~7 ~-2 ~34 waterlily 0 
setblock ~7 ~-2 ~46 waterlily 0 
setblock ~8 ~-2 ~21 tallgrass 1 
setblock ~8 ~-2 ~30 waterlily 0 
setblock ~8 ~-2 ~53 waterlily 0 
setblock ~8 ~-2 ~79 tallgrass 1 
setblock ~9 ~-2 ~43 waterlily 0 
setblock ~9 ~-2 ~60 waterlily 0 
setblock ~10 ~-2 ~17 tallgrass 1 
setblock ~10 ~-2 ~66 waterlily 0 
setblock ~11 ~-2 ~24 waterlily 0 
setblock ~11 ~-2 ~53 waterlily 0 
setblock ~12 ~-2 ~15 tallgrass 1 
setblock ~12 ~-2 ~17 tallgrass 1 
setblock ~12 ~-2 ~28 waterlily 0 
setblock ~12 ~-2 ~36 waterlily 0 
setblock ~12 ~-2 ~40 waterlily 0 
setblock ~12 ~-2 ~56 waterlily 0 
setblock ~12 ~-2 ~83 tallgrass 1 
setblock ~13 ~-2 ~20 waterlily 0 
setblock ~15 ~-2 ~73 waterlily 0 
setblock ~16 ~-2 ~18 waterlily 0 
setblock ~16 ~-2 ~26 waterlily 0
fill ~16 ~-2 ~41 ~16 ~-2 ~59 grass 0 
setblock ~16 ~-2 ~66 waterlily 0 
setblock ~16 ~-2 ~69 waterlily 0 
setblock ~16 ~-2 ~83 tallgrass 1
fill ~17 ~-2 ~37 ~17 ~-2 ~39 grass 0
fill ~17 ~-2 ~40 ~82 ~-2 ~40 dirt 0
fill ~17 ~-2 ~41 ~82 ~-2 ~41 dirt 0
fill ~17 ~-2 ~42 ~82 ~-2 ~42 dirt 0
fill ~17 ~-2 ~43 ~82 ~-2 ~43 dirt 0
fill ~17 ~-2 ~44 ~82 ~-2 ~44 dirt 0
fill ~17 ~-2 ~45 ~82 ~-2 ~45 dirt 0
fill ~17 ~-2 ~46 ~82 ~-2 ~46 dirt 0
fill ~17 ~-2 ~47 ~82 ~-2 ~47 dirt 0
fill ~17 ~-2 ~48 ~82 ~-2 ~48 dirt 0
fill ~17 ~-2 ~49 ~81 ~-2 ~49 dirt 0
fill ~17 ~-2 ~50 ~81 ~-2 ~50 dirt 0
fill ~17 ~-2 ~51 ~81 ~-2 ~51 dirt 0
fill ~17 ~-2 ~52 ~77 ~-2 ~52 dirt 0
fill ~17 ~-2 ~53 ~77 ~-2 ~53 dirt 0
fill ~17 ~-2 ~54 ~77 ~-2 ~54 dirt 0
fill ~17 ~-2 ~55 ~77 ~-2 ~55 dirt 0
fill ~17 ~-2 ~56 ~80 ~-2 ~56 dirt 0
fill ~17 ~-2 ~57 ~80 ~-2 ~57 dirt 0
fill ~17 ~-2 ~58 ~80 ~-2 ~58 dirt 0
fill ~17 ~-2 ~59 ~80 ~-2 ~59 dirt 0 
setblock ~17 ~-2 ~60 grass 0 
setblock ~17 ~-2 ~80 waterlily 0 
setblock ~18 ~-2 ~9 tallgrass 1
fill ~18 ~-2 ~22 ~18 ~-2 ~24 grass 0
fill ~18 ~-2 ~34 ~18 ~-2 ~36 grass 0
fill ~18 ~-2 ~37 ~82 ~-2 ~37 dirt 0
fill ~18 ~-2 ~38 ~82 ~-2 ~38 dirt 0
fill ~18 ~-2 ~39 ~82 ~-2 ~39 dirt 0
fill ~18 ~-2 ~60 ~80 ~-2 ~60 dirt 0
fill ~18 ~-2 ~61 ~19 ~-2 ~61 grass 0
fill ~18 ~-2 ~62 ~20 ~-2 ~62 grass 0 
setblock ~19 ~-2 ~16 waterlily 0
fill ~19 ~-2 ~21 ~20 ~-2 ~21 grass 0
fill ~19 ~-2 ~22 ~76 ~-2 ~22 dirt 0
fill ~19 ~-2 ~23 ~77 ~-2 ~23 dirt 0
fill ~19 ~-2 ~24 ~76 ~-2 ~24 dirt 0
fill ~19 ~-2 ~25 ~20 ~-2 ~25 grass 0 
setblock ~19 ~-2 ~33 grass 0
fill ~19 ~-2 ~34 ~81 ~-2 ~34 dirt 0
fill ~19 ~-2 ~35 ~82 ~-2 ~35 dirt 0
fill ~19 ~-2 ~36 ~82 ~-2 ~36 dirt 0
fill ~20 ~-2 ~30 ~20 ~-2 ~31 grass 0
fill ~20 ~-2 ~32 ~81 ~-2 ~32 dirt 0
fill ~20 ~-2 ~33 ~81 ~-2 ~33 dirt 0
fill ~20 ~-2 ~61 ~80 ~-2 ~61 dirt 0
fill ~20 ~-2 ~63 ~21 ~-2 ~63 grass 0
fill ~20 ~-2 ~64 ~20 ~-2 ~66 grass 0
fill ~21 ~-2 ~17 ~26 ~-2 ~17 grass 0
fill ~21 ~-2 ~18 ~21 ~-2 ~17 grass 0
fill ~21 ~-2 ~19 ~74 ~-2 ~19 dirt 0
fill ~21 ~-2 ~20 ~75 ~-2 ~20 dirt 0
fill ~21 ~-2 ~21 ~76 ~-2 ~21 dirt 0
fill ~21 ~-2 ~25 ~76 ~-2 ~25 dirt 0
fill ~21 ~-2 ~26 ~21 ~-2 ~27 grass 0
fill ~21 ~-2 ~28 ~23 ~-2 ~28 dirt 0
fill ~21 ~-2 ~29 ~22 ~-2 ~29 dirt 0
fill ~21 ~-2 ~30 ~22 ~-2 ~30 dirt 0
fill ~21 ~-2 ~31 ~22 ~-2 ~31 dirt 0
fill ~21 ~-2 ~62 ~80 ~-2 ~62 dirt 0
fill ~21 ~-2 ~64 ~79 ~-2 ~64 dirt 0
fill ~21 ~-2 ~65 ~79 ~-2 ~65 dirt 0
fill ~21 ~-2 ~66 ~23 ~-2 ~66 dirt 0
fill ~21 ~-2 ~67 ~23 ~-2 ~67 grass 0 
setblock ~22 ~-2 ~11 waterlily 0
fill ~22 ~-2 ~18 ~34 ~-2 ~18 dirt 0
fill ~22 ~-2 ~26 ~79 ~-2 ~26 dirt 0
fill ~22 ~-2 ~27 ~79 ~-2 ~27 dirt 0
fill ~22 ~-2 ~63 ~79 ~-2 ~63 dirt 0 
setblock ~22 ~-2 ~76 waterlily 0 
setblock ~23 ~-2 ~87 tallgrass 1
fill ~24 ~-2 ~30 ~79 ~-2 ~30 dirt 0
fill ~24 ~-2 ~31 ~80 ~-2 ~31 dirt 0
fill ~24 ~-2 ~66 ~26 ~-2 ~66 grass 0 
setblock ~24 ~-2 ~72 waterlily 0
fill ~25 ~-2 ~28 ~79 ~-2 ~28 dirt 0
fill ~25 ~-2 ~29 ~79 ~-2 ~29 dirt 0 
setblock ~26 ~-2 ~16 grass 0 
setblock ~27 ~-2 ~10 waterlily 0
fill ~27 ~-2 ~15 ~29 ~-2 ~15 grass 0
fill ~27 ~-2 ~16 ~29 ~-2 ~16 dirt 0
fill ~27 ~-2 ~17 ~71 ~-2 ~17 dirt 0
fill ~27 ~-2 ~66 ~78 ~-2 ~66 dirt 0
fill ~27 ~-2 ~67 ~28 ~-2 ~67 grass 0 
setblock ~27 ~-2 ~85 tallgrass 1 
setblock ~28 ~-2 ~7 waterlily 0 
setblock ~28 ~-2 ~73 waterlily 0 
setblock ~28 ~-2 ~78 waterlily 0
fill ~29 ~-2 ~67 ~76 ~-2 ~67 dirt 0 
setblock ~30 ~-2 ~4 waterlily 0
fill ~30 ~-2 ~16 ~32 ~-2 ~16 grass 0 
setblock ~30 ~-2 ~87 tallgrass 1
fill ~31 ~-2 ~68 ~70 ~-2 ~68 dirt 0 
setblock ~32 ~-2 ~81 waterlily 0
fill ~33 ~-2 ~15 ~35 ~-2 ~15 grass 0
fill ~33 ~-2 ~16 ~69 ~-2 ~16 dirt 0 
setblock ~33 ~-2 ~86 tallgrass 1 
setblock ~34 ~-2 ~9 waterlily 0 
setblock ~35 ~-2 ~3 waterlily 0 
setblock ~35 ~-2 ~18 grass 0 
setblock ~35 ~-2 ~78 waterlily 0
fill ~36 ~-2 ~15 ~66 ~-2 ~15 dirt 0
fill ~36 ~-2 ~18 ~69 ~-2 ~18 dirt 0 
setblock ~37 ~-2 ~7 waterlily 0 
setblock ~37 ~-2 ~75 waterlily 0
fill ~38 ~-2 ~3 ~38 ~4 ~3 double_stone_slab 0
fill ~38 ~-2 ~4 ~38 ~3 ~4 cobblestone 0
fill ~38 ~-2 ~5 ~38 ~3 ~5 cobblestone 0
fill ~38 ~-2 ~6 ~38 ~3 ~6 cobblestone 0
fill ~38 ~-2 ~7 ~38 ~3 ~7 cobblestone 0
fill ~38 ~-2 ~8 ~38 ~3 ~8 cobblestone 0
fill ~38 ~-2 ~9 ~38 ~3 ~9 cobblestone 0
fill ~38 ~-2 ~10 ~38 ~3 ~10 cobblestone 0
fill ~38 ~-2 ~11 ~38 ~3 ~11 cobblestone 0
fill ~38 ~-2 ~12 ~38 ~3 ~12 cobblestone 0
fill ~38 ~-2 ~13 ~38 ~3 ~13 cobblestone 0
fill ~38 ~-2 ~14 ~38 ~4 ~14 double_stone_slab 0
fill ~38 ~-2 ~69 ~41 ~-2 ~69 dirt 0
fill ~39 ~-2 ~4 ~55 ~-2 ~4 stonebrick 0
fill ~39 ~-2 ~5 ~55 ~-2 ~5 stonebrick 0
fill ~39 ~-2 ~6 ~55 ~-2 ~6 stonebrick 0
fill ~39 ~-2 ~7 ~55 ~-2 ~7 stonebrick 0
fill ~39 ~-2 ~8 ~55 ~-2 ~8 stonebrick 0
fill ~39 ~-2 ~9 ~55 ~-2 ~9 stonebrick 0
fill ~39 ~-2 ~10 ~55 ~-2 ~10 stonebrick 0
fill ~39 ~-2 ~11 ~55 ~-2 ~11 stonebrick 0
fill ~39 ~-2 ~12 ~55 ~-2 ~12 stonebrick 0
fill ~39 ~-2 ~13 ~55 ~-2 ~13 stonebrick 0
fill ~39 ~-2 ~14 ~56 ~-2 ~14 dirt 0 
setblock ~39 ~-2 ~87 tallgrass 1
fill ~40 ~-2 ~3 ~43 ~-2 ~3 cobblestone 0 
setblock ~40 ~-2 ~75 waterlily 0 
setblock ~41 ~-2 ~79 waterlily 0
fill ~42 ~-2 ~69 ~43 ~-2 ~69 grass 0
fill ~44 ~-2 ~0 ~44 ~-2 ~1 double_stone_slab 0 
setblock ~44 ~-2 ~2 cobblestone 0
fill ~44 ~-2 ~3 ~44 ~1 ~3 double_stone_slab 0
fill ~44 ~-2 ~69 ~60 ~-2 ~69 dirt 0 
setblock ~44 ~-2 ~83 waterlily 0 
setblock ~44 ~-2 ~87 tallgrass 1
fill ~45 ~-2 ~1 ~49 ~-2 ~1 stone_brick_stairs 2
fill ~45 ~-2 ~2 ~49 ~-2 ~2 stonebrick 0
fill ~45 ~-2 ~3 ~49 ~-2 ~3 stonebrick 0
fill ~45 ~-2 ~70 ~61 ~-2 ~70 grass 0 
setblock ~47 ~-2 ~82 waterlily 0 
setblock ~48 ~-2 ~78 waterlily 0 
setblock ~48 ~-2 ~88 tallgrass 1 
setblock ~50 ~-2 ~1 double_stone_slab 0 
setblock ~50 ~-2 ~2 cobblestone 0
fill ~50 ~-2 ~3 ~50 ~1 ~3 double_stone_slab 0
fill ~51 ~-2 ~3 ~55 ~-2 ~3 cobblestone 0 
setblock ~52 ~-2 ~1 tallgrass 1 
setblock ~53 ~-2 ~76 waterlily 0 
setblock ~54 ~-2 ~1 tallgrass 1 
setblock ~55 ~-2 ~81 waterlily 0
fill ~56 ~-2 ~3 ~56 ~4 ~3 double_stone_slab 0
fill ~56 ~-2 ~4 ~56 ~3 ~4 cobblestone 0
fill ~56 ~-2 ~5 ~56 ~3 ~5 cobblestone 0
fill ~56 ~-2 ~6 ~56 ~3 ~6 cobblestone 0
fill ~56 ~-2 ~7 ~56 ~3 ~7 cobblestone 0
fill ~56 ~-2 ~8 ~56 ~3 ~8 cobblestone 0
fill ~56 ~-2 ~9 ~56 ~3 ~9 cobblestone 0
fill ~56 ~-2 ~10 ~56 ~3 ~10 cobblestone 0
fill ~56 ~-2 ~11 ~56 ~3 ~11 cobblestone 0
fill ~56 ~-2 ~12 ~56 ~3 ~12 cobblestone 0
fill ~56 ~-2 ~13 ~56 ~3 ~13 cobblestone 0
fill ~57 ~-2 ~14 ~66 ~-2 ~14 grass 0 
setblock ~58 ~-2 ~7 waterlily 0 
setblock ~58 ~-2 ~84 waterlily 0
fill ~61 ~-2 ~69 ~70 ~-2 ~69 grass 0 
setblock ~62 ~-2 ~7 waterlily 0 
setblock ~62 ~-2 ~82 waterlily 0 
setblock ~63 ~-2 ~5 waterlily 0 
setblock ~63 ~-2 ~78 waterlily 0 
setblock ~65 ~-2 ~8 waterlily 0 
setblock ~66 ~-2 ~0 tallgrass 1 
setblock ~66 ~-2 ~75 waterlily 0 
setblock ~66 ~-2 ~86 tallgrass 1
fill ~67 ~-2 ~15 ~69 ~-2 ~15 grass 0 
setblock ~68 ~-2 ~0 tallgrass 1 
setblock ~69 ~-2 ~2 tallgrass 1 
setblock ~69 ~-2 ~11 waterlily 0 
setblock ~69 ~-2 ~77 waterlily 0 
setblock ~69 ~-2 ~81 waterlily 0
fill ~70 ~-2 ~16 ~71 ~-2 ~16 grass 0 
setblock ~70 ~-2 ~18 grass 0
fill ~71 ~-2 ~18 ~71 ~-1 ~18 dirt 0
fill ~71 ~-2 ~68 ~75 ~-2 ~68 grass 0 
setblock ~71 ~-2 ~83 waterlily 0 
setblock ~72 ~-2 ~3 tallgrass 1 
setblock ~72 ~-2 ~10 waterlily 0
fill ~72 ~-2 ~17 ~74 ~-2 ~17 grass 0 
setblock ~73 ~-2 ~18 dirt 0 
setblock ~74 ~-2 ~82 waterlily 0 
setblock ~75 ~-2 ~18 grass 0 
setblock ~75 ~-2 ~88 tallgrass 1 
setblock ~76 ~-2 ~19 grass 0 
setblock ~76 ~-2 ~74 waterlily 0 
setblock ~76 ~-2 ~78 waterlily 0
fill ~77 ~-2 ~20 ~77 ~-2 ~21 grass 0
fill ~77 ~-2 ~67 ~78 ~-2 ~67 grass 0
fill ~78 ~-2 ~22 ~78 ~-2 ~23 grass 0
fill ~78 ~-2 ~24 ~78 ~-3 ~24 dirt 0
fill ~78 ~-2 ~25 ~78 ~-3 ~25 dirt 0
fill ~78 ~-2 ~53 ~78 ~-2 ~54 grass 0 
setblock ~79 ~-2 ~15 waterlily 0
fill ~79 ~-2 ~23 ~79 ~-2 ~25 grass 0
fill ~79 ~-2 ~55 ~80 ~-2 ~55 dirt 0 
setblock ~79 ~-2 ~66 grass 0 
setblock ~79 ~-2 ~73 waterlily 0 
setblock ~79 ~-2 ~87 tallgrass 1 
setblock ~80 ~-2 ~18 waterlily 0
fill ~80 ~-2 ~29 ~80 ~-2 ~30 grass 0
fill ~80 ~-2 ~52 ~80 ~1 ~52 dirt 0
fill ~80 ~-2 ~53 ~80 ~1 ~53 dirt 0
fill ~80 ~-2 ~54 ~80 ~0 ~54 dirt 0
fill ~80 ~-2 ~63 ~80 ~-2 ~64 grass 0
fill ~81 ~-2 ~52 ~81 ~-2 ~59 grass 0 
setblock ~81 ~-2 ~76 waterlily 0
fill ~82 ~-2 ~33 ~82 ~-2 ~34 grass 0
fill ~82 ~-2 ~49 ~82 ~-2 ~50 grass 0
fill ~83 ~-2 ~35 ~83 ~-2 ~39 grass 0
fill ~83 ~-2 ~44 ~83 ~-2 ~46 grass 0 
setblock ~84 ~-2 ~80 waterlily 0 
setblock ~85 ~-2 ~19 waterlily 0 
setblock ~85 ~-2 ~28 waterlily 0 
setblock ~85 ~-2 ~55 waterlily 0 
setblock ~85 ~-2 ~69 waterlily 0 
setblock ~87 ~-2 ~31 waterlily 0
setblock ~87 ~-2 ~42 waterlily 0 
setblock ~87 ~-2 ~64 waterlily 0 
setblock ~87 ~-2 ~73 waterlily 0 
setblock ~88 ~-2 ~26 waterlily 0 
setblock ~88 ~-2 ~38 waterlily 0 
setblock ~88 ~-2 ~49 waterlily 0 
setblock ~88 ~-2 ~53 waterlily 0 
setblock ~88 ~-2 ~81 waterlily 0 
setblock ~88 ~-2 ~86 tallgrass 1 
setblock ~89 ~-2 ~22 waterlily 0 
setblock ~89 ~-2 ~46 waterlily 0 
setblock ~89 ~-2 ~77 waterlily 0 
setblock ~89 ~-2 ~83 tallgrass 1 
setblock ~90 ~-2 ~58 waterlily 0 
setblock ~91 ~-2 ~32 waterlily 0 
setblock ~91 ~-2 ~35 waterlily 0 
setblock ~91 ~-2 ~67 waterlily 0 
setblock ~91 ~-2 ~83 tallgrass 1 
setblock ~92 ~-2 ~81 tallgrass 1 
setblock ~95 ~-2 ~52 tallgrass 1 
setblock ~95 ~-2 ~56 tallgrass 1 
setblock ~95 ~-2 ~60 tallgrass 1 
setblock ~95 ~-2 ~73 tallgrass 1 
setblock ~95 ~-2 ~80 tallgrass 1 
setblock ~96 ~-2 ~64 tallgrass 1
fill ~17 ~-1 ~40 ~17 ~-1 ~43 grass 0
fill ~17 ~-1 ~44 ~81 ~-1 ~44 dirt 0
fill ~17 ~-1 ~45 ~81 ~-1 ~45 dirt 0
fill ~17 ~-1 ~46 ~81 ~-1 ~46 dirt 0
fill ~17 ~-1 ~47 ~81 ~-1 ~47 dirt 0
fill ~17 ~-1 ~48 ~81 ~-1 ~48 dirt 0
fill ~17 ~-1 ~49 ~81 ~-1 ~49 dirt 0
fill ~17 ~-1 ~50 ~80 ~-1 ~50 dirt 0
fill ~17 ~-1 ~51 ~80 ~-1 ~51 dirt 0
fill ~17 ~-1 ~52 ~78 ~-1 ~52 dirt 0
fill ~17 ~-1 ~53 ~77 ~-1 ~53 dirt 0
fill ~17 ~-1 ~54 ~77 ~-1 ~54 dirt 0
fill ~17 ~-1 ~55 ~77 ~-1 ~55 dirt 0
fill ~17 ~-1 ~56 ~80 ~-1 ~56 dirt 0
fill ~17 ~-1 ~57 ~80 ~-1 ~57 dirt 0
fill ~17 ~-1 ~58 ~80 ~-1 ~58 dirt 0
fill ~17 ~-1 ~59 ~80 ~-1 ~59 dirt 0
fill ~18 ~-1 ~37 ~18 ~-1 ~38 grass 0
fill ~18 ~-1 ~39 ~81 ~-1 ~39 dirt 0
fill ~18 ~-1 ~40 ~81 ~-1 ~40 dirt 0
fill ~18 ~-1 ~41 ~81 ~-1 ~41 dirt 0
fill ~18 ~-1 ~42 ~81 ~-1 ~42 dirt 0
fill ~18 ~-1 ~43 ~81 ~-1 ~43 dirt 0
fill ~18 ~-1 ~60 ~80 ~-1 ~60 dirt 0
fill ~19 ~-1 ~22 ~21 ~-1 ~22 grass 0
fill ~19 ~-1 ~23 ~20 ~-1 ~23 grass 0
fill ~19 ~-1 ~24 ~20 ~-1 ~24 grass 0 
setblock ~19 ~-1 ~34 grass 0
fill ~19 ~-1 ~35 ~81 ~-1 ~35 dirt 0
fill ~19 ~-1 ~36 ~82 ~-1 ~36 dirt 0
fill ~19 ~-1 ~37 ~82 ~-1 ~37 dirt 0
fill ~19 ~-1 ~38 ~82 ~-1 ~38 dirt 0
fill ~20 ~-1 ~32 ~20 ~-1 ~33 grass 0
fill ~20 ~-1 ~34 ~81 ~-1 ~34 dirt 0
fill ~20 ~-1 ~61 ~80 ~-1 ~61 dirt 0
fill ~21 ~-1 ~19 ~21 ~-1 ~22 grass 0
fill ~21 ~-1 ~23 ~76 ~-1 ~23 dirt 0
fill ~21 ~-1 ~24 ~77 ~-1 ~24 dirt 0
fill ~21 ~-1 ~25 ~76 ~-1 ~25 dirt 0
fill ~21 ~-1 ~28 ~21 ~-1 ~30 grass 0
fill ~21 ~-1 ~31 ~22 ~-1 ~31 dirt 0
fill ~21 ~-1 ~32 ~22 ~-1 ~32 dirt 0
fill ~21 ~-1 ~33 ~80 ~-1 ~33 dirt 0 
setblock ~21 ~-1 ~62 grass 0
fill ~21 ~-1 ~64 ~21 ~-1 ~66 grass 0
fill ~22 ~-1 ~18 ~24 ~-1 ~18 grass 0
fill ~22 ~-1 ~19 ~74 ~-1 ~19 dirt 0
fill ~22 ~-1 ~20 ~75 ~-1 ~20 dirt 0
fill ~22 ~-1 ~21 ~75 ~-1 ~21 dirt 0
fill ~22 ~-1 ~22 ~76 ~-1 ~22 dirt 0
fill ~22 ~-1 ~26 ~77 ~-1 ~26 dirt 0
fill ~22 ~-1 ~27 ~78 ~-1 ~27 dirt 0
fill ~22 ~-1 ~28 ~78 ~-1 ~28 dirt 0
fill ~22 ~-1 ~29 ~22 ~-1 ~64 dirt 0
fill ~22 ~-1 ~65 ~22 ~-1 ~66 grass 0
fill ~23 ~-1 ~30 ~79 ~-1 ~30 dirt 0 
setblock ~23 ~-1 ~32 grass 0
fill ~23 ~-1 ~62 ~80 ~-1 ~62 dirt 0
fill ~23 ~-1 ~63 ~79 ~-1 ~63 dirt 0
fill ~23 ~-1 ~64 ~79 ~-1 ~64 dirt 0
fill ~23 ~-1 ~65 ~78 ~-1 ~65 dirt 0 
setblock ~23 ~-1 ~66 grass 0
fill ~24 ~-1 ~29 ~78 ~-1 ~29 dirt 0
fill ~24 ~-1 ~31 ~79 ~-1 ~31 dirt 0
fill ~24 ~-1 ~32 ~80 ~-1 ~32 dirt 0
fill ~25 ~-1 ~18 ~34 ~-1 ~18 dirt 0
fill ~27 ~-1 ~16 ~29 ~-1 ~16 grass 0
fill ~27 ~-1 ~17 ~27 ~-1 ~16 grass 0 
setblock ~27 ~-1 ~66 grass 0
fill ~28 ~-1 ~17 ~30 ~-1 ~17 dirt 0
fill ~28 ~-1 ~66 ~77 ~-1 ~66 dirt 0
fill ~29 ~-1 ~67 ~31 ~-1 ~67 grass 0 
setblock ~31 ~-1 ~17 grass 0
fill ~31 ~-1 ~68 ~32 ~-1 ~68 grass 0
fill ~32 ~-1 ~17 ~69 ~-1 ~17 dirt 0
fill ~32 ~-1 ~67 ~76 ~-1 ~67 dirt 0 
setblock ~33 ~-1 ~16 grass 0
fill ~33 ~-1 ~68 ~70 ~-1 ~68 dirt 0
fill ~34 ~-1 ~16 ~67 ~-1 ~16 dirt 0
fill ~36 ~-1 ~15 ~39 ~-1 ~15 grass 0
fill ~36 ~-1 ~18 ~69 ~-1 ~18 dirt 0
fill ~37 ~-1 ~69 ~41 ~-1 ~69 dirt 0
fill ~39 ~-1 ~4 ~55 ~-1 ~4 stonebrick 0
fill ~39 ~-1 ~5 ~55 ~-1 ~5 stonebrick 0
fill ~39 ~-1 ~6 ~55 ~-1 ~6 stonebrick 0
fill ~39 ~-1 ~7 ~55 ~-1 ~7 stonebrick 0
fill ~39 ~-1 ~8 ~55 ~-1 ~8 stonebrick 0
fill ~39 ~-1 ~9 ~55 ~-1 ~9 stonebrick 0
fill ~39 ~-1 ~10 ~55 ~-1 ~10 stonebrick 0
fill ~39 ~-1 ~11 ~55 ~-1 ~11 stonebrick 0
fill ~39 ~-1 ~12 ~55 ~-1 ~12 stonebrick 0
fill ~39 ~-1 ~13 ~55 ~-1 ~13 stonebrick 0
fill ~39 ~-1 ~14 ~55 ~-1 ~14 cobblestone 0
fill ~40 ~-1 ~3 ~43 ~-1 ~3 cobblestone 0
fill ~40 ~-1 ~15 ~63 ~-1 ~15 dirt 0 
setblock ~44 ~-1 ~0 torch 5 
setblock ~44 ~-1 ~1 stone_slab 0 
setblock ~44 ~-1 ~2 double_stone_slab 0
fill ~44 ~-1 ~69 ~60 ~-1 ~69 dirt 0
fill ~45 ~-1 ~2 ~49 ~-1 ~2 stone_brick_stairs 2
fill ~45 ~-1 ~3 ~49 ~-1 ~3 stonebrick 0 
setblock ~50 ~-1 ~0 torch 5 
setblock ~50 ~-1 ~1 stone_slab 0 
setblock ~50 ~-1 ~2 double_stone_slab 0
fill ~51 ~-1 ~3 ~55 ~-1 ~3 cobblestone 0
fill ~56 ~-1 ~14 ~56 ~4 ~14 double_stone_slab 0
fill ~64 ~-1 ~15 ~66 ~-1 ~15 grass 0
fill ~68 ~-1 ~16 ~69 ~-1 ~16 grass 0
fill ~70 ~-1 ~17 ~71 ~-1 ~17 grass 0 
setblock ~72 ~-1 ~18 dirt 0
fill ~73 ~-1 ~18 ~74 ~-1 ~18 grass 0 
setblock ~75 ~-1 ~19 grass 0
fill ~76 ~-1 ~20 ~76 ~-1 ~21 grass 0
fill ~77 ~-1 ~22 ~77 ~-1 ~23 grass 0
fill ~78 ~-1 ~24 ~78 ~-1 ~26 grass 0 
setblock ~78 ~-1 ~66 grass 0
fill ~79 ~-1 ~26 ~79 ~-1 ~29 grass 0
fill ~79 ~-1 ~55 ~80 ~-1 ~55 dirt 0 
setblock ~79 ~-1 ~65 grass 0 
setblock ~80 ~-1 ~31 grass 0
fill ~81 ~-1 ~32 ~81 ~-1 ~33 grass 0
fill ~81 ~-1 ~50 ~81 ~-1 ~51 grass 0 
setblock ~82 ~-1 ~35 grass 0
fill ~82 ~-1 ~39 ~82 ~-1 ~48 grass 0
fill ~17 ~0 ~44 ~17 ~0 ~59 grass 0
fill ~18 ~0 ~39 ~18 ~0 ~40 grass 0
fill ~18 ~0 ~41 ~80 ~0 ~41 dirt 0
fill ~18 ~0 ~42 ~80 ~0 ~42 dirt 0
fill ~18 ~0 ~43 ~80 ~0 ~43 dirt 0
fill ~18 ~0 ~44 ~81 ~0 ~44 dirt 0
fill ~18 ~0 ~45 ~81 ~0 ~45 dirt 0
fill ~18 ~0 ~46 ~81 ~0 ~46 dirt 0
fill ~18 ~0 ~47 ~81 ~0 ~47 dirt 0
fill ~18 ~0 ~48 ~80 ~0 ~48 dirt 0
fill ~18 ~0 ~49 ~80 ~0 ~49 dirt 0
fill ~18 ~0 ~50 ~80 ~0 ~50 dirt 0
fill ~18 ~0 ~51 ~80 ~0 ~51 dirt 0
fill ~18 ~0 ~52 ~78 ~0 ~52 dirt 0
fill ~18 ~0 ~53 ~78 ~0 ~53 dirt 0
fill ~18 ~0 ~54 ~78 ~0 ~54 dirt 0
fill ~18 ~0 ~55 ~77 ~0 ~55 dirt 0
fill ~18 ~0 ~56 ~80 ~0 ~56 dirt 0
fill ~18 ~0 ~57 ~79 ~0 ~57 dirt 0
fill ~18 ~0 ~58 ~79 ~0 ~58 dirt 0
fill ~18 ~0 ~59 ~79 ~0 ~59 dirt 0
fill ~18 ~0 ~60 ~79 ~0 ~60 dirt 0
fill ~19 ~0 ~35 ~81 ~0 ~35 dirt 0
fill ~19 ~0 ~36 ~81 ~0 ~36 dirt 0
fill ~19 ~0 ~37 ~81 ~0 ~37 dirt 0
fill ~19 ~0 ~38 ~81 ~0 ~38 dirt 0
fill ~19 ~0 ~39 ~81 ~0 ~39 dirt 0
fill ~19 ~0 ~40 ~80 ~0 ~40 dirt 0 
setblock ~20 ~0 ~34 grass 0
fill ~20 ~0 ~61 ~79 ~0 ~61 dirt 0
fill ~21 ~0 ~23 ~21 ~0 ~25 grass 0
fill ~21 ~0 ~31 ~21 ~0 ~32 grass 0
fill ~21 ~0 ~33 ~22 ~0 ~33 dirt 0
fill ~21 ~0 ~34 ~80 ~0 ~34 dirt 0
fill ~22 ~0 ~19 ~23 ~0 ~19 grass 0
fill ~22 ~0 ~20 ~22 ~0 ~22 grass 0
fill ~22 ~0 ~23 ~76 ~0 ~23 dirt 0
fill ~22 ~0 ~24 ~76 ~0 ~24 dirt 0
fill ~22 ~0 ~25 ~76 ~0 ~25 dirt 0
fill ~22 ~0 ~26 ~22 ~0 ~29 grass 0
fill ~22 ~0 ~30 ~78 ~0 ~30 dirt 0
fill ~22 ~0 ~31 ~22 ~0 ~64 dirt 0
fill ~23 ~0 ~20 ~74 ~0 ~20 dirt 0
fill ~23 ~0 ~21 ~75 ~0 ~21 dirt 0
fill ~23 ~0 ~22 ~75 ~0 ~22 dirt 0
fill ~23 ~0 ~26 ~77 ~0 ~26 dirt 0
fill ~23 ~0 ~27 ~77 ~0 ~27 dirt 0
fill ~23 ~0 ~28 ~77 ~0 ~28 dirt 0 
setblock ~23 ~0 ~33 grass 0
fill ~23 ~0 ~62 ~78 ~0 ~62 dirt 0
fill ~23 ~0 ~63 ~78 ~0 ~63 dirt 0
fill ~23 ~0 ~64 ~77 ~0 ~64 dirt 0
fill ~23 ~0 ~65 ~76 ~0 ~65 dirt 0
fill ~24 ~0 ~19 ~73 ~0 ~19 dirt 0
fill ~24 ~0 ~29 ~78 ~0 ~29 dirt 0
fill ~24 ~0 ~31 ~78 ~0 ~31 dirt 0
fill ~24 ~0 ~32 ~79 ~0 ~32 dirt 0
fill ~24 ~0 ~33 ~80 ~0 ~33 dirt 0
fill ~25 ~0 ~18 ~34 ~0 ~18 dirt 0
fill ~28 ~0 ~17 ~30 ~0 ~17 dirt 0
fill ~28 ~0 ~66 ~30 ~0 ~66 dirt 0 
setblock ~31 ~0 ~66 grass 0 
setblock ~32 ~0 ~17 grass 0
fill ~32 ~0 ~66 ~75 ~0 ~66 dirt 0
fill ~32 ~0 ~67 ~33 ~0 ~67 grass 0
fill ~33 ~0 ~17 ~67 ~0 ~17 dirt 0 
setblock ~33 ~0 ~68 grass 0
fill ~34 ~0 ~16 ~36 ~0 ~16 grass 0
fill ~34 ~0 ~67 ~70 ~0 ~67 dirt 0
fill ~34 ~0 ~68 ~68 ~0 ~68 dirt 0
fill ~36 ~0 ~18 ~70 ~0 ~18 dirt 0
fill ~37 ~0 ~16 ~65 ~0 ~16 dirt 0
fill ~37 ~0 ~69 ~41 ~0 ~69 dirt 0
fill ~39 ~0 ~4 ~55 ~0 ~4 stonebrick 0
fill ~39 ~0 ~5 ~55 ~0 ~5 stonebrick 0
fill ~39 ~0 ~6 ~55 ~0 ~6 stonebrick 0 
setblock ~39 ~0 ~7 cobblestone 0
fill ~39 ~0 ~8 ~44 ~0 ~8 stonebrick 0
fill ~39 ~0 ~9 ~44 ~0 ~9 stonebrick 0
fill ~39 ~0 ~10 ~55 ~0 ~10 stonebrick 0
fill ~39 ~0 ~11 ~55 ~0 ~11 stonebrick 0
fill ~39 ~0 ~12 ~55 ~0 ~12 stonebrick 0
fill ~39 ~0 ~13 ~55 ~0 ~13 stonebrick 0
fill ~39 ~0 ~14 ~55 ~0 ~14 cobblestone 0
fill ~40 ~0 ~3 ~43 ~0 ~3 cobblestone 0
fill ~40 ~0 ~7 ~55 ~0 ~7 stonebrick 0
fill ~40 ~0 ~15 ~44 ~0 ~15 grass 0 
setblock ~44 ~0 ~2 stone_slab 0
fill ~44 ~0 ~69 ~59 ~0 ~69 dirt 0
fill ~45 ~0 ~3 ~49 ~0 ~3 stone_brick_stairs 2
fill ~45 ~0 ~8 ~49 ~0 ~8 lapis_block 0
fill ~45 ~0 ~9 ~49 ~0 ~9 lapis_block 0 
setblock ~45 ~0 ~15 dirt 0
fill ~46 ~0 ~15 ~48 ~0 ~15 grass 0 
setblock ~49 ~0 ~15 dirt 0 
setblock ~50 ~0 ~2 stone_slab 0
fill ~50 ~0 ~8 ~55 ~0 ~8 stonebrick 0
fill ~50 ~0 ~9 ~55 ~0 ~9 stonebrick 0
fill ~50 ~0 ~15 ~63 ~0 ~15 grass 0
fill ~51 ~0 ~3 ~55 ~0 ~3 cobblestone 0 
setblock ~60 ~0 ~69 grass 0
fill ~66 ~0 ~16 ~67 ~0 ~16 grass 0
fill ~68 ~0 ~17 ~69 ~0 ~17 grass 0
fill ~69 ~0 ~68 ~70 ~0 ~68 grass 0
fill ~71 ~0 ~18 ~72 ~0 ~18 grass 0
fill ~71 ~0 ~67 ~76 ~0 ~67 grass 0 
setblock ~74 ~0 ~19 grass 0 
setblock ~75 ~0 ~20 grass 0 
setblock ~76 ~0 ~22 grass 0
fill ~76 ~0 ~66 ~77 ~0 ~66 grass 0
fill ~77 ~0 ~24 ~77 ~0 ~25 grass 0
fill ~77 ~0 ~65 ~78 ~0 ~65 grass 0
fill ~78 ~0 ~27 ~78 ~0 ~28 grass 0
fill ~78 ~0 ~64 ~79 ~0 ~64 grass 0
fill ~79 ~0 ~30 ~79 ~0 ~31 grass 0
fill ~79 ~0 ~55 ~80 ~0 ~55 dirt 0
fill ~79 ~0 ~62 ~80 ~0 ~62 grass 0
fill ~79 ~0 ~63 ~79 ~0 ~62 grass 0 
setblock ~80 ~0 ~32 grass 0
fill ~80 ~0 ~57 ~80 ~0 ~62 grass 0 
setblock ~81 ~0 ~34 grass 0
fill ~81 ~0 ~40 ~81 ~0 ~43 grass 0
fill ~81 ~0 ~48 ~81 ~0 ~49 grass 0
fill ~82 ~0 ~36 ~82 ~0 ~38 grass 0
fill ~18 ~1 ~41 ~18 ~1 ~60 grass 0 
setblock ~19 ~1 ~35 grass 0
fill ~19 ~1 ~36 ~80 ~1 ~36 dirt 0
fill ~19 ~1 ~37 ~80 ~1 ~37 dirt 0
fill ~19 ~1 ~38 ~80 ~1 ~38 dirt 0
fill ~19 ~1 ~39 ~80 ~1 ~39 dirt 0
fill ~19 ~1 ~40 ~80 ~1 ~40 dirt 0
fill ~19 ~1 ~41 ~80 ~1 ~41 dirt 0
fill ~19 ~1 ~42 ~80 ~1 ~42 dirt 0
fill ~19 ~1 ~43 ~80 ~1 ~43 dirt 0
fill ~19 ~1 ~44 ~80 ~1 ~44 dirt 0
fill ~19 ~1 ~45 ~80 ~1 ~45 dirt 0
fill ~19 ~1 ~46 ~80 ~1 ~46 dirt 0
fill ~19 ~1 ~47 ~80 ~1 ~47 dirt 0
fill ~19 ~1 ~48 ~80 ~1 ~48 dirt 0
fill ~19 ~1 ~49 ~80 ~1 ~49 dirt 0
fill ~19 ~1 ~50 ~80 ~1 ~50 dirt 0
fill ~19 ~1 ~51 ~80 ~1 ~51 dirt 0
fill ~19 ~1 ~52 ~80 ~1 ~52 dirt 0
fill ~19 ~1 ~53 ~80 ~1 ~53 dirt 0
fill ~19 ~1 ~54 ~79 ~1 ~54 dirt 0
fill ~19 ~1 ~55 ~79 ~1 ~55 dirt 0
fill ~19 ~1 ~56 ~78 ~1 ~56 dirt 0
fill ~19 ~1 ~57 ~78 ~1 ~57 dirt 0
fill ~19 ~1 ~58 ~78 ~1 ~58 dirt 0
fill ~19 ~1 ~59 ~78 ~1 ~59 dirt 0
fill ~19 ~1 ~60 ~78 ~1 ~60 dirt 0
fill ~20 ~1 ~35 ~80 ~1 ~35 dirt 0
fill ~20 ~1 ~61 ~21 ~1 ~61 grass 0
fill ~21 ~1 ~33 ~21 ~1 ~34 grass 0
fill ~22 ~1 ~23 ~22 ~1 ~25 grass 0
fill ~22 ~1 ~30 ~22 ~1 ~31 grass 0
fill ~22 ~1 ~32 ~78 ~1 ~32 dirt 0
fill ~22 ~1 ~33 ~22 ~1 ~61 dirt 0
fill ~22 ~1 ~62 ~22 ~1 ~64 grass 0
fill ~23 ~1 ~20 ~73 ~1 ~20 dirt 0
fill ~23 ~1 ~21 ~74 ~1 ~21 dirt 0
fill ~23 ~1 ~22 ~75 ~1 ~22 dirt 0
fill ~23 ~1 ~23 ~75 ~1 ~23 dirt 0
fill ~23 ~1 ~24 ~75 ~1 ~24 dirt 0
fill ~23 ~1 ~25 ~76 ~1 ~25 dirt 0
fill ~23 ~1 ~26 ~76 ~1 ~26 dirt 0
fill ~23 ~1 ~27 ~76 ~1 ~27 dirt 0
fill ~23 ~1 ~28 ~77 ~1 ~28 dirt 0
fill ~23 ~1 ~29 ~77 ~1 ~29 dirt 0
fill ~23 ~1 ~30 ~77 ~1 ~30 dirt 0
fill ~23 ~1 ~31 ~78 ~1 ~31 dirt 0
fill ~23 ~1 ~34 ~79 ~1 ~34 dirt 0
fill ~23 ~1 ~61 ~78 ~1 ~61 dirt 0
fill ~23 ~1 ~62 ~77 ~1 ~62 dirt 0
fill ~23 ~1 ~63 ~77 ~1 ~63 dirt 0
fill ~23 ~1 ~64 ~77 ~1 ~64 dirt 0
fill ~23 ~1 ~65 ~25 ~1 ~65 grass 0
fill ~24 ~1 ~19 ~71 ~1 ~19 dirt 0
fill ~24 ~1 ~33 ~79 ~1 ~33 dirt 0 
setblock ~25 ~1 ~18 grass 0
fill ~26 ~1 ~18 ~34 ~1 ~18 dirt 0
fill ~26 ~1 ~65 ~76 ~1 ~65 dirt 0
fill ~28 ~1 ~17 ~30 ~1 ~17 grass 0
fill ~28 ~1 ~66 ~30 ~1 ~66 dirt 0 
setblock ~32 ~1 ~66 grass 0
fill ~33 ~1 ~17 ~34 ~1 ~17 grass 0
fill ~33 ~1 ~66 ~75 ~1 ~66 dirt 0
fill ~34 ~1 ~67 ~34 ~1 ~68 grass 0
fill ~35 ~1 ~17 ~46 ~1 ~17 dirt 0
fill ~35 ~1 ~67 ~67 ~1 ~67 dirt 0 
setblock ~35 ~1 ~68 grass 0
fill ~36 ~1 ~18 ~68 ~1 ~18 dirt 0
fill ~36 ~1 ~68 ~64 ~1 ~68 dirt 0
fill ~37 ~1 ~16 ~41 ~1 ~16 grass 0 
setblock ~37 ~1 ~69 grass 0
fill ~38 ~1 ~69 ~41 ~1 ~69 dirt 0
fill ~39 ~1 ~4 ~39 ~3 ~4 stonebrick 0
fill ~39 ~1 ~5 ~43 ~1 ~5 stonebrick 0
fill ~39 ~1 ~6 ~43 ~1 ~6 stonebrick 0
fill ~39 ~1 ~7 ~42 ~1 ~7 stonebrick 0
fill ~39 ~1 ~8 ~41 ~1 ~8 stonebrick 0
fill ~39 ~1 ~9 ~41 ~1 ~9 stonebrick 0
fill ~39 ~1 ~10 ~44 ~1 ~10 stonebrick 0
fill ~39 ~1 ~11 ~55 ~1 ~11 stonebrick 0
fill ~39 ~1 ~12 ~55 ~1 ~12 stonebrick 0
fill ~39 ~1 ~13 ~55 ~1 ~13 stonebrick 0
fill ~39 ~1 ~14 ~55 ~1 ~14 cobblestone 0
fill ~40 ~1 ~3 ~43 ~1 ~3 cobblestone 0
fill ~40 ~1 ~4 ~40 ~2 ~4 lit_pumpkin 3
fill ~41 ~1 ~4 ~41 ~2 ~4 lit_pumpkin 1
fill ~42 ~1 ~4 ~43 ~1 ~4 stonebrick 0
fill ~42 ~1 ~8 ~44 ~1 ~8 cobblestone 0
fill ~42 ~1 ~9 ~44 ~1 ~9 cobblestone 0
fill ~42 ~1 ~16 ~61 ~1 ~16 dirt 0 
setblock ~43 ~1 ~7 cobblestone 0 
setblock ~44 ~1 ~2 torch 4
fill ~44 ~1 ~4 ~44 ~1 ~6 stone_brick_stairs 1 
setblock ~44 ~1 ~7 double_stone_slab 0
fill ~44 ~1 ~69 ~48 ~1 ~69 dirt 0
fill ~45 ~1 ~7 ~49 ~1 ~7 stone_stairs 2
fill ~45 ~1 ~8 ~49 ~1 ~8 water 0
fill ~45 ~1 ~9 ~49 ~1 ~9 water 0
fill ~45 ~1 ~10 ~47 ~1 ~10 lit_pumpkin 1
fill ~45 ~1 ~15 ~45 ~8 ~15 cobblestone 0
fill ~47 ~1 ~15 ~47 ~3 ~15 glowstone 0
fill ~47 ~1 ~17 ~51 ~1 ~17 grass 0 
setblock ~48 ~1 ~10 lit_pumpkin 3 
setblock ~49 ~1 ~10 lit_pumpkin 1
fill ~49 ~1 ~15 ~49 ~8 ~15 cobblestone 0
fill ~49 ~1 ~69 ~51 ~1 ~69 grass 0 
setblock ~50 ~1 ~2 torch 4
fill ~50 ~1 ~4 ~50 ~1 ~6 stone_brick_stairs 0 
setblock ~50 ~1 ~7 double_stone_slab 0
fill ~50 ~1 ~8 ~52 ~1 ~8 cobblestone 0
fill ~50 ~1 ~9 ~52 ~1 ~9 cobblestone 0
fill ~50 ~1 ~10 ~55 ~1 ~10 stonebrick 0
fill ~51 ~1 ~3 ~55 ~1 ~3 cobblestone 0
fill ~51 ~1 ~4 ~52 ~1 ~4 stonebrick 0
fill ~51 ~1 ~5 ~55 ~1 ~5 stonebrick 0
fill ~51 ~1 ~6 ~55 ~1 ~6 stonebrick 0 
setblock ~51 ~1 ~7 cobblestone 0
fill ~52 ~1 ~7 ~55 ~1 ~7 stonebrick 0
fill ~52 ~1 ~17 ~66 ~1 ~17 dirt 0
fill ~52 ~1 ~69 ~54 ~1 ~69 dirt 0
fill ~53 ~1 ~4 ~53 ~2 ~4 lit_pumpkin 3
fill ~53 ~1 ~8 ~55 ~1 ~8 stonebrick 0
fill ~53 ~1 ~9 ~55 ~1 ~9 stonebrick 0
fill ~54 ~1 ~4 ~54 ~2 ~4 lit_pumpkin 1
fill ~55 ~1 ~4 ~55 ~3 ~4 stonebrick 0
fill ~55 ~1 ~69 ~59 ~1 ~69 grass 0
fill ~62 ~1 ~16 ~65 ~1 ~16 grass 0
fill ~65 ~1 ~68 ~68 ~1 ~68 grass 0 
setblock ~67 ~1 ~17 grass 0
fill ~68 ~1 ~67 ~70 ~1 ~67 grass 0
fill ~69 ~1 ~18 ~70 ~1 ~18 grass 0
fill ~72 ~1 ~19 ~73 ~1 ~19 grass 0 
setblock ~74 ~1 ~20 grass 0 
setblock ~75 ~1 ~21 grass 0
fill ~76 ~1 ~23 ~76 ~1 ~24 grass 0
fill ~77 ~1 ~26 ~77 ~1 ~27 grass 0
fill ~78 ~1 ~29 ~78 ~1 ~30 grass 0
fill ~78 ~1 ~62 ~78 ~1 ~63 grass 0 
setblock ~79 ~1 ~32 grass 0
fill ~79 ~1 ~56 ~80 ~1 ~56 grass 0
fill ~79 ~1 ~57 ~79 ~1 ~61 grass 0
fill ~80 ~1 ~33 ~80 ~1 ~34 grass 0
fill ~80 ~1 ~54 ~80 ~1 ~56 grass 0
fill ~81 ~1 ~35 ~81 ~1 ~39 grass 0
fill ~81 ~1 ~44 ~81 ~1 ~47 grass 0
fill ~19 ~2 ~36 ~20 ~2 ~36 grass 0
fill ~19 ~2 ~37 ~20 ~2 ~37 grass 0
fill ~19 ~2 ~38 ~19 ~2 ~60 grass 0 
setblock ~20 ~2 ~35 grass 0
fill ~20 ~2 ~38 ~80 ~2 ~38 dirt 0
fill ~20 ~2 ~39 ~79 ~2 ~39 dirt 0
fill ~20 ~2 ~40 ~79 ~2 ~40 dirt 0
fill ~20 ~2 ~41 ~79 ~2 ~41 dirt 0
fill ~20 ~2 ~42 ~79 ~2 ~42 dirt 0
fill ~20 ~2 ~43 ~79 ~2 ~43 dirt 0
fill ~20 ~2 ~44 ~79 ~2 ~44 dirt 0
fill ~20 ~2 ~45 ~79 ~2 ~45 dirt 0
fill ~20 ~2 ~46 ~79 ~2 ~46 dirt 0
fill ~20 ~2 ~47 ~79 ~2 ~47 dirt 0
fill ~20 ~2 ~48 ~79 ~2 ~48 dirt 0
fill ~20 ~2 ~49 ~79 ~2 ~49 dirt 0
fill ~20 ~2 ~50 ~79 ~2 ~50 dirt 0
fill ~20 ~2 ~51 ~79 ~2 ~51 dirt 0
fill ~20 ~2 ~52 ~79 ~2 ~52 dirt 0
fill ~20 ~2 ~53 ~78 ~2 ~53 dirt 0
fill ~20 ~2 ~54 ~78 ~2 ~54 dirt 0
fill ~20 ~2 ~55 ~78 ~2 ~55 dirt 0
fill ~20 ~2 ~56 ~77 ~2 ~56 dirt 0
fill ~20 ~2 ~57 ~77 ~2 ~57 dirt 0
fill ~20 ~2 ~58 ~20 ~2 ~60 grass 0
fill ~21 ~2 ~35 ~79 ~2 ~35 dirt 0
fill ~21 ~2 ~36 ~79 ~2 ~36 dirt 0
fill ~21 ~2 ~37 ~80 ~2 ~37 dirt 0
fill ~21 ~2 ~58 ~77 ~2 ~58 dirt 0
fill ~21 ~2 ~59 ~77 ~2 ~59 dirt 0
fill ~21 ~2 ~60 ~77 ~2 ~60 dirt 0
fill ~22 ~2 ~32 ~22 ~2 ~33 grass 0
fill ~22 ~2 ~34 ~79 ~2 ~34 dirt 0
fill ~22 ~2 ~61 ~23 ~2 ~61 grass 0
fill ~23 ~2 ~20 ~72 ~2 ~20 dirt 0
fill ~23 ~2 ~21 ~73 ~2 ~21 dirt 0
fill ~23 ~2 ~22 ~74 ~2 ~22 dirt 0
fill ~23 ~2 ~23 ~74 ~2 ~23 dirt 0
fill ~23 ~2 ~24 ~75 ~2 ~24 dirt 0
fill ~23 ~2 ~25 ~75 ~2 ~25 dirt 0
fill ~23 ~2 ~26 ~75 ~2 ~26 dirt 0
fill ~23 ~2 ~27 ~75 ~2 ~27 dirt 0
fill ~23 ~2 ~28 ~76 ~2 ~28 dirt 0
fill ~23 ~2 ~29 ~23 ~2 ~30 grass 0
fill ~23 ~2 ~31 ~77 ~2 ~31 dirt 0
fill ~23 ~2 ~32 ~77 ~2 ~32 dirt 0
fill ~23 ~2 ~62 ~23 ~2 ~64 grass 0
fill ~24 ~2 ~19 ~69 ~2 ~19 dirt 0
fill ~24 ~2 ~29 ~76 ~2 ~29 dirt 0
fill ~24 ~2 ~30 ~76 ~2 ~30 dirt 0
fill ~24 ~2 ~33 ~78 ~2 ~33 dirt 0
fill ~24 ~2 ~61 ~77 ~2 ~61 dirt 0
fill ~24 ~2 ~62 ~77 ~2 ~62 dirt 0
fill ~24 ~2 ~63 ~76 ~2 ~63 dirt 0 
setblock ~24 ~2 ~64 grass 0
fill ~25 ~2 ~64 ~75 ~2 ~64 dirt 0
fill ~26 ~2 ~18 ~28 ~2 ~18 dirt 0
fill ~26 ~2 ~65 ~27 ~2 ~65 grass 0
fill ~28 ~2 ~65 ~30 ~2 ~65 dirt 0
fill ~28 ~2 ~66 ~30 ~2 ~66 grass 0 
setblock ~29 ~2 ~18 grass 0
fill ~30 ~2 ~18 ~32 ~2 ~18 dirt 0
fill ~31 ~2 ~65 ~32 ~2 ~65 grass 0 
setblock ~33 ~2 ~18 grass 0
fill ~33 ~2 ~65 ~73 ~2 ~65 dirt 0
fill ~33 ~2 ~66 ~72 ~2 ~66 dirt 0 
setblock ~34 ~2 ~18 dirt 0
fill ~35 ~2 ~17 ~38 ~2 ~17 grass 0 
setblock ~35 ~2 ~67 grass 0
fill ~36 ~2 ~18 ~66 ~2 ~18 dirt 0
fill ~36 ~2 ~67 ~64 ~2 ~67 dirt 0 
setblock ~36 ~2 ~68 grass 0
fill ~37 ~2 ~68 ~46 ~2 ~68 dirt 0
fill ~38 ~2 ~69 ~41 ~2 ~69 grass 0 
setblock ~39 ~2 ~5 cobblestone 0
fill ~39 ~2 ~6 ~42 ~2 ~6 stonebrick 0
fill ~39 ~2 ~7 ~41 ~2 ~7 stonebrick 0
fill ~39 ~2 ~8 ~41 ~2 ~8 stonebrick 0
fill ~39 ~2 ~9 ~41 ~2 ~9 stonebrick 0
fill ~39 ~2 ~10 ~55 ~2 ~10 stonebrick 0
fill ~39 ~2 ~11 ~55 ~2 ~11 stonebrick 0
fill ~39 ~2 ~12 ~55 ~2 ~12 stonebrick 0
fill ~39 ~2 ~13 ~55 ~2 ~13 stonebrick 0
fill ~39 ~2 ~14 ~55 ~2 ~14 cobblestone 0
fill ~39 ~2 ~17 ~46 ~2 ~17 dirt 0
fill ~40 ~2 ~3 ~42 ~2 ~3 cobblestone 0
fill ~40 ~2 ~5 ~42 ~2 ~5 stonebrick 0
fill ~42 ~2 ~4 ~42 ~-3 ~4 stonebrick 0
fill ~42 ~2 ~7 ~43 ~2 ~7 double_stone_slab 0
fill ~42 ~2 ~8 ~42 ~3 ~8 cobblestone 0
fill ~42 ~2 ~9 ~42 ~3 ~9 cobblestone 0
fill ~42 ~2 ~16 ~44 ~2 ~16 grass 0 
setblock ~43 ~2 ~3 double_stone_slab 0
fill ~43 ~2 ~4 ~43 ~2 ~6 stone_brick_stairs 1
fill ~43 ~2 ~8 ~43 ~2 ~9 stone_stairs 1 
setblock ~44 ~2 ~3 stone_slab 0 
setblock ~44 ~2 ~7 stone_slab 0
fill ~44 ~2 ~69 ~48 ~2 ~69 grass 0 
setblock ~45 ~2 ~16 dirt 0 
setblock ~46 ~2 ~8 waterlily 0
fill ~46 ~2 ~16 ~48 ~2 ~16 grass 0 
setblock ~47 ~2 ~9 wool 4
fill ~47 ~2 ~68 ~50 ~2 ~68 grass 0 
setblock ~48 ~2 ~9 waterlily 0 
setblock ~49 ~2 ~16 dirt 0 
setblock ~50 ~2 ~3 stone_slab 0 
setblock ~50 ~2 ~7 stone_slab 0
fill ~50 ~2 ~16 ~61 ~2 ~16 grass 0 
setblock ~51 ~2 ~3 double_stone_slab 0
fill ~51 ~2 ~4 ~51 ~2 ~6 stone_brick_stairs 0 
setblock ~51 ~2 ~7 double_stone_slab 0
fill ~51 ~2 ~8 ~51 ~2 ~9 stone_stairs 0
fill ~51 ~2 ~68 ~55 ~2 ~68 dirt 0
fill ~52 ~2 ~3 ~55 ~2 ~3 cobblestone 0
fill ~52 ~2 ~4 ~52 ~2 ~7 stonebrick 0
fill ~52 ~2 ~8 ~52 ~3 ~8 cobblestone 0
fill ~52 ~2 ~9 ~52 ~3 ~9 cobblestone 0
fill ~52 ~2 ~17 ~63 ~2 ~17 dirt 0
fill ~52 ~2 ~69 ~54 ~2 ~69 dirt 0
fill ~53 ~2 ~5 ~55 ~2 ~5 stonebrick 0
fill ~53 ~2 ~6 ~55 ~2 ~6 stonebrick 0
fill ~53 ~2 ~7 ~55 ~2 ~7 stonebrick 0
fill ~53 ~2 ~8 ~55 ~2 ~8 stonebrick 0
fill ~53 ~2 ~9 ~55 ~2 ~9 stonebrick 0 
setblock ~56 ~2 ~68 grass 0
fill ~57 ~2 ~68 ~58 ~2 ~68 dirt 0
fill ~59 ~2 ~68 ~64 ~2 ~68 grass 0
fill ~64 ~2 ~17 ~66 ~2 ~17 grass 0
fill ~65 ~2 ~67 ~67 ~2 ~67 grass 0
fill ~67 ~2 ~18 ~68 ~2 ~18 grass 0
fill ~70 ~2 ~19 ~71 ~2 ~19 grass 0 
setblock ~73 ~2 ~20 grass 0
fill ~73 ~2 ~66 ~75 ~2 ~66 grass 0 
setblock ~74 ~2 ~21 grass 0
fill ~74 ~2 ~65 ~76 ~2 ~65 grass 0
fill ~75 ~2 ~22 ~75 ~2 ~23 grass 0
fill ~76 ~2 ~25 ~76 ~2 ~27 grass 0
fill ~76 ~2 ~64 ~77 ~2 ~64 grass 0
fill ~77 ~2 ~28 ~77 ~2 ~30 grass 0 
setblock ~77 ~2 ~63 grass 0
fill ~78 ~2 ~31 ~78 ~2 ~32 grass 0
fill ~78 ~2 ~56 ~78 ~2 ~61 grass 0 
setblock ~79 ~2 ~33 grass 0
fill ~79 ~2 ~53 ~80 ~2 ~53 grass 0
fill ~79 ~2 ~54 ~79 ~2 ~55 grass 0
fill ~80 ~2 ~35 ~80 ~2 ~36 grass 0
fill ~80 ~2 ~39 ~80 ~2 ~53 grass 0
fill ~20 ~3 ~38 ~21 ~3 ~38 grass 0
fill ~20 ~3 ~39 ~20 ~3 ~57 grass 0
fill ~21 ~3 ~35 ~21 ~3 ~38 grass 0
fill ~21 ~3 ~39 ~79 ~3 ~39 dirt 0
fill ~21 ~3 ~40 ~78 ~3 ~40 dirt 0
fill ~21 ~3 ~41 ~78 ~3 ~41 dirt 0
fill ~21 ~3 ~42 ~78 ~3 ~42 dirt 0
fill ~21 ~3 ~43 ~78 ~3 ~43 dirt 0
fill ~21 ~3 ~44 ~78 ~3 ~44 dirt 0
fill ~21 ~3 ~45 ~78 ~3 ~45 dirt 0
fill ~21 ~3 ~46 ~79 ~3 ~46 dirt 0
fill ~21 ~3 ~47 ~79 ~3 ~47 dirt 0
fill ~21 ~3 ~48 ~78 ~3 ~48 dirt 0
fill ~21 ~3 ~49 ~78 ~3 ~49 dirt 0
fill ~21 ~3 ~50 ~78 ~3 ~50 dirt 0
fill ~21 ~3 ~51 ~78 ~3 ~51 dirt 0
fill ~21 ~3 ~52 ~77 ~3 ~52 dirt 0
fill ~21 ~3 ~53 ~77 ~3 ~53 dirt 0
fill ~21 ~3 ~54 ~77 ~3 ~54 dirt 0
fill ~21 ~3 ~55 ~77 ~3 ~55 dirt 0
fill ~21 ~3 ~56 ~77 ~3 ~56 dirt 0
fill ~21 ~3 ~57 ~77 ~3 ~57 dirt 0
fill ~21 ~3 ~58 ~21 ~3 ~60 grass 0 
setblock ~22 ~3 ~34 grass 0
fill ~22 ~3 ~35 ~78 ~3 ~35 dirt 0
fill ~22 ~3 ~36 ~79 ~3 ~36 dirt 0
fill ~22 ~3 ~37 ~79 ~3 ~37 dirt 0
fill ~22 ~3 ~38 ~79 ~3 ~38 dirt 0
fill ~22 ~3 ~58 ~77 ~3 ~58 dirt 0
fill ~22 ~3 ~59 ~22 ~3 ~60 grass 0 
setblock ~23 ~3 ~20 grass 0
fill ~23 ~3 ~21 ~72 ~3 ~21 dirt 0
fill ~23 ~3 ~22 ~73 ~3 ~22 dirt 0
fill ~23 ~3 ~23 ~74 ~3 ~23 dirt 0
fill ~23 ~3 ~24 ~23 ~3 ~28 grass 0
fill ~23 ~3 ~31 ~23 ~3 ~33 grass 0
fill ~23 ~3 ~34 ~78 ~3 ~34 dirt 0
fill ~23 ~3 ~59 ~77 ~3 ~59 dirt 0 
setblock ~23 ~3 ~60 grass 0 
setblock ~24 ~3 ~19 grass 0
fill ~24 ~3 ~20 ~65 ~3 ~20 dirt 0
fill ~24 ~3 ~24 ~74 ~3 ~24 dirt 0
fill ~24 ~3 ~25 ~74 ~3 ~25 dirt 0
fill ~24 ~3 ~26 ~75 ~3 ~26 dirt 0
fill ~24 ~3 ~27 ~75 ~3 ~27 dirt 0
fill ~24 ~3 ~28 ~75 ~3 ~28 dirt 0
fill ~24 ~3 ~29 ~75 ~3 ~29 dirt 0
fill ~24 ~3 ~30 ~76 ~3 ~30 dirt 0
fill ~24 ~3 ~31 ~76 ~3 ~31 dirt 0
fill ~24 ~3 ~32 ~76 ~3 ~32 dirt 0
fill ~24 ~3 ~33 ~77 ~3 ~33 dirt 0
fill ~24 ~3 ~60 ~77 ~3 ~60 dirt 0
fill ~24 ~3 ~61 ~76 ~3 ~61 dirt 0
fill ~24 ~3 ~62 ~75 ~3 ~62 dirt 0
fill ~24 ~3 ~63 ~74 ~3 ~63 dirt 0
fill ~25 ~3 ~19 ~40 ~3 ~19 dirt 0
fill ~25 ~3 ~64 ~27 ~3 ~64 dirt 0
fill ~26 ~3 ~18 ~28 ~3 ~18 dirt 0
fill ~28 ~3 ~64 ~28 ~3 ~65 grass 0
fill ~29 ~3 ~64 ~73 ~3 ~64 dirt 0
fill ~29 ~3 ~65 ~30 ~3 ~65 grass 0
fill ~30 ~3 ~18 ~32 ~3 ~18 dirt 0
fill ~33 ~3 ~65 ~33 ~3 ~66 grass 0
fill ~34 ~3 ~18 ~36 ~3 ~18 grass 0
fill ~34 ~3 ~65 ~73 ~3 ~65 dirt 0
fill ~34 ~3 ~66 ~35 ~3 ~66 grass 0
fill ~36 ~3 ~66 ~70 ~3 ~66 dirt 0
fill ~36 ~3 ~67 ~45 ~3 ~67 dirt 0
fill ~37 ~3 ~18 ~64 ~3 ~18 dirt 0
fill ~37 ~3 ~68 ~46 ~3 ~68 grass 0
fill ~39 ~3 ~5 ~41 ~3 ~5 stonebrick 0
fill ~39 ~3 ~6 ~41 ~3 ~6 stonebrick 0
fill ~39 ~3 ~7 ~41 ~3 ~7 stonebrick 0
fill ~39 ~3 ~8 ~41 ~3 ~8 stonebrick 0
fill ~39 ~3 ~9 ~41 ~3 ~9 stonebrick 0
fill ~39 ~3 ~10 ~55 ~3 ~10 stonebrick 0
fill ~39 ~3 ~11 ~55 ~3 ~11 stonebrick 0
fill ~39 ~3 ~12 ~55 ~3 ~12 stonebrick 0
fill ~39 ~3 ~13 ~55 ~3 ~13 stonebrick 0
fill ~39 ~3 ~14 ~55 ~3 ~14 cobblestone 0
fill ~39 ~3 ~17 ~43 ~3 ~17 grass 0
fill ~40 ~3 ~3 ~41 ~3 ~3 cobblestone 0
fill ~40 ~3 ~4 ~41 ~3 ~4 stonebrick 0 
setblock ~41 ~3 ~19 grass 0
fill ~42 ~3 ~3 ~42 ~4 ~3 double_stone_slab 0
fill ~42 ~3 ~4 ~42 ~3 ~6 stone_brick_stairs 1
fill ~42 ~3 ~7 ~42 ~4 ~7 double_stone_slab 0
fill ~42 ~3 ~19 ~67 ~3 ~19 dirt 0 
setblock ~43 ~3 ~3 stone_slab 0 
setblock ~43 ~3 ~7 stone_slab 0
fill ~44 ~3 ~17 ~46 ~3 ~17 dirt 0
fill ~45 ~3 ~9 ~45 ~7 ~9 fence 0
fill ~45 ~3 ~16 ~45 ~9 ~16 cobblestone 0
fill ~46 ~3 ~9 ~46 ~4 ~9 wool 4
fill ~46 ~3 ~67 ~50 ~3 ~67 grass 0
fill ~47 ~3 ~9 ~47 ~7 ~9 wool 14 
setblock ~47 ~3 ~16 glowstone 0
fill ~48 ~3 ~9 ~48 ~4 ~9 wool 4
fill ~49 ~3 ~9 ~49 ~7 ~9 fence 0
fill ~49 ~3 ~16 ~49 ~9 ~16 cobblestone 0 
setblock ~51 ~3 ~3 stone_slab 0 
setblock ~51 ~3 ~7 stone_slab 0
fill ~51 ~3 ~67 ~59 ~3 ~67 dirt 0 
setblock ~51 ~3 ~68 grass 0
fill ~52 ~3 ~3 ~52 ~4 ~3 double_stone_slab 0
fill ~52 ~3 ~4 ~52 ~3 ~6 stone_brick_stairs 0
fill ~52 ~3 ~7 ~52 ~4 ~7 double_stone_slab 0
fill ~52 ~3 ~17 ~53 ~3 ~17 dirt 0
fill ~52 ~3 ~68 ~54 ~3 ~68 dirt 0
fill ~52 ~3 ~69 ~54 ~3 ~69 grass 0
fill ~53 ~3 ~3 ~55 ~3 ~3 cobblestone 0
fill ~53 ~3 ~4 ~55 ~3 ~4 stonebrick 0
fill ~53 ~3 ~5 ~55 ~3 ~5 stonebrick 0
fill ~53 ~3 ~6 ~55 ~3 ~6 stonebrick 0
fill ~53 ~3 ~7 ~55 ~3 ~7 stonebrick 0
fill ~53 ~3 ~8 ~55 ~3 ~8 stonebrick 0
fill ~53 ~3 ~9 ~55 ~3 ~9 stonebrick 0 
setblock ~54 ~3 ~17 grass 0
fill ~55 ~3 ~17 ~59 ~3 ~17 dirt 0 
setblock ~55 ~3 ~68 grass 0
fill ~57 ~3 ~68 ~58 ~3 ~68 dirt 0
fill ~60 ~3 ~17 ~63 ~3 ~17 grass 0
fill ~60 ~3 ~67 ~64 ~3 ~67 grass 0
fill ~65 ~3 ~18 ~66 ~3 ~18 grass 0 
setblock ~66 ~3 ~20 grass 0
fill ~67 ~3 ~20 ~70 ~3 ~20 dirt 0
fill ~68 ~3 ~19 ~69 ~3 ~19 grass 0
fill ~71 ~3 ~20 ~72 ~3 ~20 grass 0
fill ~71 ~3 ~66 ~72 ~3 ~66 grass 0 
setblock ~73 ~3 ~21 grass 0 
setblock ~74 ~3 ~22 grass 0
fill ~74 ~3 ~64 ~75 ~3 ~64 grass 0
fill ~75 ~3 ~24 ~75 ~3 ~25 grass 0
fill ~75 ~3 ~63 ~76 ~3 ~63 grass 0
fill ~76 ~3 ~28 ~76 ~3 ~29 grass 0
fill ~76 ~3 ~62 ~77 ~3 ~62 grass 0
fill ~77 ~3 ~31 ~77 ~3 ~32 grass 0 
setblock ~77 ~3 ~61 grass 0 
setblock ~78 ~3 ~33 grass 0
fill ~78 ~3 ~52 ~79 ~3 ~52 grass 0
fill ~78 ~3 ~53 ~78 ~3 ~55 grass 0
fill ~79 ~3 ~34 ~79 ~3 ~35 grass 0
fill ~79 ~3 ~40 ~79 ~3 ~45 grass 0
fill ~79 ~3 ~48 ~79 ~3 ~52 grass 0
fill ~80 ~3 ~37 ~80 ~3 ~38 grass 0
fill ~21 ~4 ~39 ~22 ~4 ~39 grass 0
fill ~21 ~4 ~40 ~21 ~4 ~57 grass 0
fill ~22 ~4 ~35 ~23 ~4 ~35 grass 0
fill ~22 ~4 ~36 ~22 ~4 ~39 grass 0
fill ~22 ~4 ~40 ~26 ~4 ~40 dirt 0
fill ~22 ~4 ~41 ~26 ~4 ~41 dirt 0
fill ~22 ~4 ~42 ~26 ~4 ~42 dirt 0
fill ~22 ~4 ~43 ~26 ~4 ~43 dirt 0
fill ~22 ~4 ~44 ~26 ~4 ~44 dirt 0
fill ~22 ~4 ~45 ~26 ~4 ~45 dirt 0
fill ~22 ~4 ~46 ~26 ~4 ~46 dirt 0
fill ~22 ~4 ~47 ~26 ~4 ~47 dirt 0
fill ~22 ~4 ~48 ~26 ~4 ~48 dirt 0
fill ~22 ~4 ~49 ~26 ~4 ~49 dirt 0
fill ~22 ~4 ~50 ~26 ~4 ~50 dirt 0
fill ~22 ~4 ~51 ~26 ~4 ~51 dirt 0
fill ~22 ~4 ~52 ~26 ~4 ~52 dirt 0
fill ~22 ~4 ~53 ~26 ~4 ~53 dirt 0
fill ~22 ~4 ~54 ~26 ~4 ~54 dirt 0
fill ~22 ~4 ~55 ~26 ~4 ~55 dirt 0
fill ~22 ~4 ~56 ~26 ~4 ~56 dirt 0
fill ~22 ~4 ~57 ~22 ~4 ~58 grass 0
fill ~23 ~4 ~21 ~71 ~4 ~21 dirt 0
fill ~23 ~4 ~22 ~72 ~4 ~22 dirt 0
fill ~23 ~4 ~23 ~73 ~4 ~23 dirt 0 
setblock ~23 ~4 ~34 grass 0
fill ~23 ~4 ~36 ~26 ~4 ~36 dirt 0
fill ~23 ~4 ~37 ~26 ~4 ~37 dirt 0
fill ~23 ~4 ~38 ~26 ~4 ~38 dirt 0
fill ~23 ~4 ~39 ~26 ~4 ~39 dirt 0
fill ~23 ~4 ~57 ~26 ~4 ~57 dirt 0
fill ~23 ~4 ~58 ~23 ~4 ~59 grass 0
fill ~24 ~4 ~20 ~28 ~4 ~20 dirt 0
fill ~24 ~4 ~24 ~29 ~4 ~24 dirt 0
fill ~24 ~4 ~25 ~29 ~4 ~25 dirt 0
fill ~24 ~4 ~26 ~28 ~4 ~26 dirt 0
fill ~24 ~4 ~27 ~27 ~4 ~27 dirt 0
fill ~24 ~4 ~28 ~28 ~4 ~28 dirt 0
fill ~24 ~4 ~29 ~28 ~4 ~29 dirt 0
fill ~24 ~4 ~30 ~28 ~4 ~30 dirt 0
fill ~24 ~4 ~31 ~27 ~4 ~31 dirt 0
fill ~24 ~4 ~32 ~27 ~4 ~32 dirt 0
fill ~24 ~4 ~33 ~27 ~4 ~33 dirt 0
fill ~24 ~4 ~34 ~26 ~4 ~34 dirt 0
fill ~24 ~4 ~35 ~26 ~4 ~35 dirt 0
fill ~24 ~4 ~58 ~26 ~4 ~58 dirt 0
fill ~24 ~4 ~59 ~24 ~4 ~63 grass 0 
setblock ~25 ~4 ~19 grass 0
fill ~25 ~4 ~59 ~26 ~4 ~59 dirt 0
fill ~25 ~4 ~60 ~36 ~4 ~60 dirt 0
fill ~25 ~4 ~61 ~36 ~4 ~61 dirt 0
fill ~25 ~4 ~62 ~74 ~4 ~62 dirt 0
fill ~25 ~4 ~63 ~73 ~4 ~63 dirt 0
fill ~25 ~4 ~64 ~27 ~4 ~64 grass 0
fill ~26 ~4 ~18 ~28 ~4 ~18 grass 0
fill ~26 ~4 ~19 ~28 ~4 ~19 dirt 0
fill ~27 ~4 ~34 ~67 ~4 ~34 double_stone_slab 0
fill ~27 ~4 ~35 ~67 ~4 ~35 double_stone_slab 0
fill ~27 ~4 ~36 ~67 ~4 ~36 double_stone_slab 0
fill ~27 ~4 ~37 ~67 ~4 ~37 double_stone_slab 0
fill ~27 ~4 ~38 ~67 ~4 ~38 double_stone_slab 0
fill ~27 ~4 ~39 ~67 ~4 ~39 double_stone_slab 0
fill ~27 ~4 ~40 ~67 ~4 ~40 double_stone_slab 0
fill ~27 ~4 ~41 ~67 ~4 ~41 double_stone_slab 0
fill ~27 ~4 ~42 ~67 ~4 ~42 double_stone_slab 0
fill ~27 ~4 ~43 ~67 ~4 ~43 double_stone_slab 0
fill ~27 ~4 ~44 ~67 ~4 ~44 double_stone_slab 0
fill ~27 ~4 ~45 ~67 ~4 ~45 double_stone_slab 0
fill ~27 ~4 ~46 ~67 ~4 ~46 double_stone_slab 0
fill ~27 ~4 ~47 ~67 ~4 ~47 double_stone_slab 0
fill ~27 ~4 ~48 ~67 ~4 ~48 double_stone_slab 0
fill ~27 ~4 ~49 ~67 ~4 ~49 double_stone_slab 0
fill ~27 ~4 ~50 ~67 ~4 ~50 double_stone_slab 0
fill ~27 ~4 ~51 ~67 ~4 ~51 double_stone_slab 0
fill ~27 ~4 ~52 ~67 ~4 ~52 double_stone_slab 0
fill ~27 ~4 ~53 ~67 ~4 ~53 double_stone_slab 0
fill ~27 ~4 ~54 ~67 ~4 ~54 double_stone_slab 0
fill ~27 ~4 ~55 ~67 ~4 ~55 double_stone_slab 0
fill ~27 ~4 ~56 ~67 ~4 ~56 double_stone_slab 0
fill ~27 ~4 ~57 ~67 ~4 ~57 double_stone_slab 0
fill ~27 ~4 ~58 ~67 ~4 ~58 double_stone_slab 0
fill ~27 ~4 ~59 ~30 ~4 ~59 double_stone_slab 0
fill ~28 ~4 ~27 ~67 ~4 ~27 double_stone_slab 0
fill ~28 ~4 ~31 ~67 ~4 ~31 double_stone_slab 0
fill ~28 ~4 ~32 ~67 ~4 ~32 double_stone_slab 0
fill ~28 ~4 ~33 ~67 ~4 ~33 double_stone_slab 0
fill ~29 ~4 ~19 ~29 ~4 ~20 grass 0
fill ~29 ~4 ~26 ~67 ~4 ~26 double_stone_slab 0
fill ~29 ~4 ~28 ~67 ~4 ~28 double_stone_slab 0
fill ~29 ~4 ~29 ~67 ~4 ~29 double_stone_slab 0
fill ~29 ~4 ~30 ~67 ~4 ~30 double_stone_slab 0
fill ~29 ~4 ~64 ~31 ~4 ~64 dirt 0
fill ~30 ~4 ~18 ~32 ~4 ~18 grass 0
fill ~30 ~4 ~19 ~40 ~4 ~19 dirt 0
fill ~30 ~4 ~20 ~58 ~4 ~20 dirt 0
fill ~30 ~4 ~24 ~30 ~4 ~59 double_stone_slab 0
fill ~31 ~4 ~24 ~33 ~4 ~24 dirt 0
fill ~31 ~4 ~25 ~67 ~4 ~25 double_stone_slab 0
fill ~31 ~4 ~59 ~33 ~4 ~59 dirt 0
fill ~32 ~4 ~64 ~35 ~4 ~64 grass 0
fill ~34 ~4 ~24 ~67 ~4 ~24 double_stone_slab 0
fill ~34 ~4 ~59 ~67 ~4 ~59 double_stone_slab 0
fill ~34 ~4 ~65 ~37 ~4 ~65 grass 0
fill ~36 ~4 ~64 ~73 ~4 ~64 dirt 0
fill ~36 ~4 ~66 ~38 ~4 ~66 grass 0
fill ~36 ~4 ~67 ~45 ~4 ~67 grass 0
fill ~37 ~4 ~18 ~42 ~4 ~18 grass 0
fill ~37 ~4 ~60 ~67 ~4 ~60 double_stone_slab 0
fill ~37 ~4 ~61 ~67 ~4 ~61 double_stone_slab 0
fill ~38 ~4 ~4 ~38 ~4 ~14 double_stone_slab 0
fill ~38 ~4 ~65 ~71 ~4 ~65 dirt 0
fill ~39 ~4 ~3 ~42 ~4 ~3 double_stone_slab 0
fill ~39 ~4 ~14 ~42 ~4 ~14 double_stone_slab 0
fill ~39 ~4 ~66 ~44 ~4 ~66 dirt 0
fill ~42 ~4 ~8 ~42 ~4 ~10 double_stone_slab 0
fill ~42 ~4 ~11 ~42 ~4 ~13 stone_brick_stairs 0
fill ~42 ~4 ~19 ~53 ~4 ~19 dirt 0
fill ~43 ~4 ~10 ~51 ~4 ~10 stonebrick 0
fill ~43 ~4 ~11 ~51 ~4 ~11 stonebrick 0
fill ~43 ~4 ~12 ~51 ~4 ~12 stonebrick 0
fill ~43 ~4 ~13 ~51 ~4 ~13 stonebrick 0
fill ~43 ~4 ~14 ~51 ~4 ~14 cobblestone 0
fill ~43 ~4 ~18 ~61 ~4 ~18 dirt 0 
setblock ~44 ~4 ~17 grass 0 
setblock ~45 ~4 ~17 dirt 0
fill ~45 ~4 ~66 ~49 ~4 ~66 grass 0
fill ~46 ~4 ~17 ~48 ~4 ~17 grass 0 
setblock ~49 ~4 ~17 dirt 0
fill ~50 ~4 ~17 ~53 ~4 ~17 grass 0
fill ~50 ~4 ~66 ~70 ~4 ~66 dirt 0
fill ~51 ~4 ~67 ~53 ~4 ~67 dirt 0
fill ~52 ~4 ~8 ~52 ~4 ~10 double_stone_slab 0
fill ~52 ~4 ~11 ~52 ~4 ~13 stone_brick_stairs 1
fill ~52 ~4 ~14 ~56 ~4 ~14 double_stone_slab 0
fill ~52 ~4 ~68 ~54 ~4 ~68 grass 0
fill ~53 ~4 ~3 ~56 ~4 ~3 double_stone_slab 0 
setblock ~54 ~4 ~19 grass 0 
setblock ~54 ~4 ~67 grass 0
fill ~55 ~4 ~17 ~59 ~4 ~17 grass 0
fill ~55 ~4 ~67 ~59 ~4 ~67 dirt 0
fill ~56 ~4 ~4 ~56 ~4 ~14 double_stone_slab 0
fill ~56 ~4 ~68 ~58 ~4 ~68 dirt 0
fill ~57 ~4 ~19 ~58 ~4 ~19 grass 0
fill ~59 ~4 ~19 ~65 ~4 ~19 dirt 0 
setblock ~59 ~4 ~20 grass 0
fill ~60 ~4 ~20 ~61 ~4 ~20 dirt 0
fill ~62 ~4 ~18 ~64 ~4 ~18 grass 0 
setblock ~62 ~4 ~20 grass 0
fill ~63 ~4 ~20 ~65 ~4 ~20 dirt 0
fill ~66 ~4 ~19 ~67 ~4 ~19 grass 0
fill ~67 ~4 ~20 ~68 ~4 ~20 dirt 0
fill ~68 ~4 ~24 ~73 ~4 ~24 dirt 0
fill ~68 ~4 ~25 ~74 ~4 ~25 dirt 0
fill ~68 ~4 ~26 ~74 ~4 ~26 dirt 0
fill ~68 ~4 ~27 ~74 ~4 ~27 dirt 0
fill ~68 ~4 ~28 ~74 ~4 ~28 dirt 0
fill ~68 ~4 ~29 ~74 ~4 ~29 dirt 0
fill ~68 ~4 ~30 ~74 ~4 ~30 dirt 0
fill ~68 ~4 ~31 ~75 ~4 ~31 dirt 0
fill ~68 ~4 ~32 ~75 ~4 ~32 dirt 0
fill ~68 ~4 ~33 ~76 ~4 ~33 dirt 0
fill ~68 ~4 ~34 ~77 ~4 ~34 dirt 0
fill ~68 ~4 ~35 ~77 ~4 ~35 dirt 0
fill ~68 ~4 ~36 ~78 ~4 ~36 dirt 0
fill ~68 ~4 ~37 ~78 ~4 ~37 dirt 0
fill ~68 ~4 ~38 ~78 ~4 ~38 dirt 0
fill ~68 ~4 ~39 ~78 ~4 ~39 dirt 0
fill ~68 ~4 ~40 ~78 ~4 ~40 dirt 0
fill ~68 ~4 ~41 ~77 ~4 ~41 dirt 0
fill ~68 ~4 ~42 ~77 ~4 ~42 dirt 0
fill ~68 ~4 ~43 ~77 ~4 ~43 dirt 0
fill ~68 ~4 ~44 ~77 ~4 ~44 dirt 0
fill ~68 ~4 ~45 ~78 ~4 ~45 dirt 0
fill ~68 ~4 ~46 ~78 ~4 ~46 dirt 0
fill ~68 ~4 ~47 ~78 ~4 ~47 dirt 0
fill ~68 ~4 ~48 ~78 ~4 ~48 dirt 0
fill ~68 ~4 ~49 ~78 ~4 ~49 dirt 0
fill ~68 ~4 ~50 ~77 ~4 ~50 dirt 0
fill ~68 ~4 ~51 ~77 ~4 ~51 dirt 0
fill ~68 ~4 ~52 ~77 ~4 ~52 dirt 0
fill ~68 ~4 ~53 ~77 ~4 ~53 dirt 0
fill ~68 ~4 ~54 ~77 ~4 ~54 dirt 0
fill ~68 ~4 ~55 ~77 ~4 ~55 dirt 0
fill ~68 ~4 ~56 ~77 ~4 ~56 dirt 0
fill ~68 ~4 ~57 ~76 ~4 ~57 dirt 0
fill ~68 ~4 ~58 ~76 ~4 ~58 dirt 0
fill ~68 ~4 ~59 ~76 ~4 ~59 dirt 0
fill ~68 ~4 ~60 ~75 ~4 ~60 dirt 0
fill ~68 ~4 ~61 ~75 ~4 ~61 dirt 0
fill ~69 ~4 ~20 ~70 ~4 ~20 grass 0 
setblock ~72 ~4 ~21 grass 0
fill ~72 ~4 ~65 ~73 ~4 ~65 grass 0 
setblock ~73 ~4 ~22 grass 0
fill ~74 ~4 ~23 ~74 ~4 ~24 grass 0 
setblock ~74 ~4 ~63 grass 0
fill ~75 ~4 ~26 ~75 ~4 ~30 grass 0 
setblock ~75 ~4 ~62 grass 0
fill ~76 ~4 ~30 ~76 ~4 ~32 grass 0
fill ~76 ~4 ~60 ~77 ~4 ~60 grass 0
fill ~76 ~4 ~61 ~76 ~4 ~60 grass 0 
setblock ~77 ~4 ~33 grass 0
fill ~77 ~4 ~57 ~77 ~4 ~60 grass 0
fill ~78 ~4 ~34 ~78 ~4 ~35 grass 0
fill ~78 ~4 ~41 ~78 ~4 ~44 grass 0
fill ~78 ~4 ~50 ~78 ~4 ~51 grass 0
fill ~79 ~4 ~36 ~79 ~4 ~39 grass 0
fill ~79 ~4 ~46 ~79 ~4 ~47 grass 0
fill ~22 ~5 ~40 ~23 ~5 ~40 grass 0
fill ~22 ~5 ~41 ~23 ~5 ~41 grass 0
fill ~22 ~5 ~42 ~23 ~5 ~42 grass 0
fill ~22 ~5 ~43 ~23 ~5 ~43 grass 0
fill ~22 ~5 ~44 ~23 ~5 ~44 grass 0
fill ~22 ~5 ~45 ~22 ~5 ~56 grass 0
fill ~23 ~5 ~21 ~23 ~5 ~23 grass 0
fill ~23 ~5 ~36 ~23 ~5 ~44 grass 0
fill ~23 ~5 ~45 ~26 ~5 ~45 dirt 0
fill ~23 ~5 ~46 ~26 ~5 ~46 dirt 0
fill ~23 ~5 ~47 ~26 ~5 ~47 dirt 0
fill ~23 ~5 ~48 ~26 ~5 ~48 dirt 0
fill ~23 ~5 ~49 ~26 ~5 ~49 dirt 0
fill ~23 ~5 ~50 ~26 ~5 ~50 dirt 0
fill ~23 ~5 ~51 ~26 ~5 ~51 dirt 0
fill ~23 ~5 ~52 ~26 ~5 ~52 dirt 0
fill ~23 ~5 ~53 ~26 ~5 ~53 dirt 0
fill ~23 ~5 ~54 ~26 ~5 ~54 dirt 0
fill ~23 ~5 ~55 ~26 ~5 ~55 dirt 0
fill ~23 ~5 ~56 ~23 ~5 ~57 grass 0 
setblock ~24 ~5 ~20 grass 0
fill ~24 ~5 ~21 ~69 ~5 ~21 dirt 0
fill ~24 ~5 ~22 ~71 ~5 ~22 dirt 0
fill ~24 ~5 ~23 ~72 ~5 ~23 dirt 0
fill ~24 ~5 ~24 ~34 ~5 ~24 dirt 0
fill ~24 ~5 ~25 ~33 ~5 ~25 dirt 0
fill ~24 ~5 ~26 ~29 ~5 ~26 dirt 0
fill ~24 ~5 ~27 ~28 ~5 ~27 dirt 0
fill ~24 ~5 ~28 ~28 ~5 ~28 dirt 0
fill ~24 ~5 ~29 ~28 ~5 ~29 dirt 0
fill ~24 ~5 ~30 ~28 ~5 ~30 dirt 0
fill ~24 ~5 ~31 ~28 ~5 ~31 dirt 0
fill ~24 ~5 ~32 ~28 ~5 ~32 dirt 0
fill ~24 ~5 ~33 ~28 ~5 ~33 dirt 0
fill ~24 ~5 ~34 ~24 ~5 ~35 grass 0
fill ~24 ~5 ~36 ~26 ~5 ~36 dirt 0
fill ~24 ~5 ~37 ~26 ~5 ~37 dirt 0
fill ~24 ~5 ~38 ~26 ~5 ~38 dirt 0
fill ~24 ~5 ~39 ~26 ~5 ~39 dirt 0
fill ~24 ~5 ~40 ~26 ~5 ~40 dirt 0
fill ~24 ~5 ~41 ~26 ~5 ~41 dirt 0
fill ~24 ~5 ~42 ~26 ~5 ~42 dirt 0
fill ~24 ~5 ~43 ~26 ~5 ~43 dirt 0
fill ~24 ~5 ~44 ~26 ~5 ~44 dirt 0
fill ~24 ~5 ~56 ~26 ~5 ~56 dirt 0
fill ~24 ~5 ~57 ~24 ~5 ~58 grass 0
fill ~25 ~5 ~20 ~27 ~5 ~20 dirt 0
fill ~25 ~5 ~34 ~27 ~5 ~34 dirt 0
fill ~25 ~5 ~35 ~26 ~5 ~35 dirt 0
fill ~25 ~5 ~57 ~26 ~5 ~57 dirt 0
fill ~25 ~5 ~58 ~25 ~5 ~59 grass 0
fill ~25 ~5 ~60 ~40 ~5 ~60 dirt 0
fill ~25 ~5 ~61 ~40 ~5 ~61 dirt 0
fill ~25 ~5 ~62 ~73 ~5 ~62 dirt 0 
setblock ~25 ~5 ~63 grass 0
fill ~26 ~5 ~19 ~28 ~5 ~19 grass 0
fill ~26 ~5 ~58 ~26 ~5 ~63 dirt 0
fill ~27 ~5 ~35 ~30 ~5 ~35 double_stone_slab 0
fill ~27 ~5 ~36 ~30 ~5 ~36 double_stone_slab 0
fill ~27 ~5 ~37 ~30 ~5 ~37 double_stone_slab 0
fill ~27 ~5 ~38 ~30 ~5 ~38 double_stone_slab 0
fill ~27 ~5 ~39 ~30 ~5 ~39 double_stone_slab 0
fill ~27 ~5 ~40 ~30 ~5 ~40 double_stone_slab 0
fill ~27 ~5 ~41 ~30 ~5 ~41 double_stone_slab 0
fill ~27 ~5 ~42 ~30 ~5 ~42 double_stone_slab 0
fill ~27 ~5 ~43 ~30 ~5 ~43 double_stone_slab 0
fill ~27 ~5 ~44 ~30 ~5 ~44 double_stone_slab 0
fill ~27 ~5 ~45 ~30 ~5 ~45 double_stone_slab 0
fill ~27 ~5 ~46 ~30 ~5 ~46 double_stone_slab 0
fill ~27 ~5 ~47 ~30 ~5 ~47 double_stone_slab 0
fill ~27 ~5 ~48 ~30 ~5 ~48 double_stone_slab 0
fill ~27 ~5 ~49 ~30 ~5 ~49 double_stone_slab 0
fill ~27 ~5 ~50 ~30 ~5 ~50 double_stone_slab 0
fill ~27 ~5 ~51 ~30 ~5 ~51 double_stone_slab 0
fill ~27 ~5 ~52 ~30 ~5 ~52 double_stone_slab 0
fill ~27 ~5 ~53 ~30 ~5 ~53 double_stone_slab 0
fill ~27 ~5 ~54 ~30 ~5 ~54 double_stone_slab 0
fill ~27 ~5 ~55 ~30 ~5 ~55 double_stone_slab 0
fill ~27 ~5 ~56 ~30 ~5 ~56 double_stone_slab 0
fill ~27 ~5 ~57 ~30 ~5 ~57 double_stone_slab 0
fill ~27 ~5 ~58 ~67 ~5 ~58 double_stone_slab 0
fill ~27 ~5 ~59 ~28 ~5 ~59 dirt 0
fill ~27 ~5 ~63 ~36 ~5 ~63 dirt 0 
setblock ~28 ~5 ~20 grass 0
fill ~28 ~5 ~34 ~30 ~5 ~34 double_stone_slab 0
fill ~29 ~5 ~27 ~67 ~5 ~27 double_stone_slab 0
fill ~29 ~5 ~28 ~30 ~5 ~28 double_stone_slab 0
fill ~29 ~5 ~29 ~30 ~5 ~29 double_stone_slab 0
fill ~29 ~5 ~30 ~30 ~5 ~30 double_stone_slab 0
fill ~29 ~5 ~31 ~30 ~5 ~31 double_stone_slab 0
fill ~29 ~5 ~32 ~30 ~5 ~32 double_stone_slab 0
fill ~29 ~5 ~33 ~30 ~5 ~33 double_stone_slab 0
fill ~29 ~5 ~59 ~30 ~5 ~59 double_stone_slab 0
fill ~29 ~5 ~64 ~31 ~5 ~64 grass 0
fill ~30 ~5 ~19 ~32 ~5 ~19 grass 0
fill ~30 ~5 ~20 ~58 ~5 ~20 dirt 0
fill ~30 ~5 ~26 ~67 ~5 ~26 double_stone_slab 0
fill ~31 ~5 ~28 ~34 ~5 ~28 stonebrick 1
fill ~31 ~5 ~29 ~31 ~8 ~29 stonebrick 1
fill ~31 ~5 ~30 ~31 ~9 ~30 stonebrick 1
fill ~31 ~5 ~31 ~31 ~11 ~31 stonebrick 1
fill ~31 ~5 ~32 ~31 ~10 ~32 stonebrick 1
fill ~31 ~5 ~33 ~31 ~6 ~33 stonebrick 1
fill ~31 ~5 ~34 ~31 ~8 ~34 stonebrick 1
fill ~31 ~5 ~35 ~31 ~9 ~35 stonebrick 1
fill ~31 ~5 ~36 ~31 ~7 ~36 stonebrick 1
fill ~31 ~5 ~37 ~31 ~11 ~37 stonebrick 1
fill ~31 ~5 ~38 ~31 ~11 ~38 stonebrick 1
fill ~31 ~5 ~39 ~31 ~5 ~41 stonebrick 2
fill ~31 ~5 ~42 ~31 ~12 ~42 stonebrick 1
fill ~31 ~5 ~43 ~31 ~10 ~43 stonebrick 1
fill ~31 ~5 ~44 ~31 ~8 ~44 stonebrick 1
fill ~31 ~5 ~45 ~31 ~7 ~45 stonebrick 1
fill ~31 ~5 ~46 ~31 ~13 ~46 stonebrick 1
fill ~31 ~5 ~47 ~31 ~7 ~47 stonebrick 1
fill ~31 ~5 ~48 ~31 ~11 ~48 stonebrick 1
fill ~31 ~5 ~49 ~31 ~13 ~49 stonebrick 1
fill ~31 ~5 ~50 ~31 ~5 ~57 stonebrick 1
fill ~31 ~5 ~59 ~36 ~5 ~59 dirt 0
fill ~32 ~5 ~29 ~62 ~5 ~29 stone_slab 5
fill ~32 ~5 ~30 ~62 ~5 ~30 stone_slab 5
fill ~32 ~5 ~31 ~62 ~5 ~31 stone_slab 5
fill ~32 ~5 ~32 ~62 ~5 ~32 stone_slab 5
fill ~32 ~5 ~33 ~62 ~5 ~33 stone_slab 5
fill ~32 ~5 ~34 ~62 ~5 ~34 stone_slab 5
fill ~32 ~5 ~35 ~62 ~5 ~35 stone_slab 5
fill ~32 ~5 ~36 ~62 ~5 ~36 stone_slab 5
fill ~32 ~5 ~37 ~62 ~5 ~37 stone_slab 5
fill ~32 ~5 ~38 ~62 ~5 ~38 stone_slab 5
fill ~32 ~5 ~39 ~62 ~5 ~39 stone_slab 5
fill ~32 ~5 ~40 ~62 ~5 ~40 stone_slab 5
fill ~32 ~5 ~41 ~62 ~5 ~41 stone_slab 5
fill ~32 ~5 ~42 ~33 ~5 ~42 double_stone_slab 5
fill ~32 ~5 ~43 ~33 ~5 ~43 stone_brick_stairs 3
fill ~32 ~5 ~44 ~62 ~5 ~44 stone_slab 5
fill ~32 ~5 ~45 ~62 ~5 ~45 stone_slab 5
fill ~32 ~5 ~46 ~62 ~5 ~46 stone_slab 5
fill ~32 ~5 ~47 ~62 ~5 ~47 stone_slab 5
fill ~32 ~5 ~48 ~62 ~5 ~48 stone_slab 5
fill ~32 ~5 ~49 ~62 ~5 ~49 stone_slab 5
fill ~32 ~5 ~50 ~62 ~5 ~50 stone_slab 5
fill ~32 ~5 ~51 ~62 ~5 ~51 stone_slab 5
fill ~32 ~5 ~52 ~62 ~5 ~52 stone_slab 5
fill ~32 ~5 ~53 ~62 ~5 ~53 stone_slab 5
fill ~32 ~5 ~54 ~62 ~5 ~54 stone_slab 5
fill ~32 ~5 ~55 ~62 ~5 ~55 stone_slab 5
fill ~32 ~5 ~56 ~62 ~5 ~56 stone_slab 5
fill ~32 ~5 ~57 ~52 ~5 ~57 stonebrick 1
fill ~33 ~5 ~19 ~35 ~5 ~19 dirt 0
fill ~34 ~5 ~25 ~67 ~5 ~25 double_stone_slab 0
fill ~34 ~5 ~42 ~62 ~5 ~42 stone_slab 5
fill ~34 ~5 ~43 ~62 ~5 ~43 stone_slab 5
fill ~35 ~5 ~24 ~67 ~5 ~24 double_stone_slab 0 
setblock ~35 ~5 ~28 stonebrick 2
fill ~36 ~5 ~19 ~41 ~5 ~19 grass 0
fill ~36 ~5 ~28 ~48 ~5 ~28 stonebrick 1
fill ~36 ~5 ~64 ~40 ~5 ~64 grass 0
fill ~37 ~5 ~59 ~67 ~5 ~59 double_stone_slab 0 
setblock ~37 ~5 ~63 grass 0 
setblock ~38 ~5 ~3 torch 5 
setblock ~38 ~5 ~7 torch 5 
setblock ~38 ~5 ~14 torch 5
fill ~38 ~5 ~63 ~71 ~5 ~63 dirt 0
fill ~38 ~5 ~65 ~49 ~5 ~65 grass 0
fill ~39 ~5 ~66 ~44 ~5 ~66 grass 0
fill ~41 ~5 ~60 ~67 ~5 ~60 double_stone_slab 0
fill ~41 ~5 ~61 ~66 ~5 ~61 double_stone_slab 0
fill ~41 ~5 ~64 ~69 ~5 ~64 dirt 0 
setblock ~42 ~5 ~3 torch 5 
setblock ~42 ~5 ~7 torch 5 
setblock ~42 ~5 ~10 stone_slab 0 
setblock ~42 ~5 ~14 stone_slab 0
fill ~42 ~5 ~19 ~53 ~5 ~19 dirt 0 
setblock ~43 ~5 ~10 double_stone_slab 0
fill ~43 ~5 ~11 ~43 ~5 ~13 stone_brick_stairs 0 
setblock ~43 ~5 ~14 double_stone_slab 0
fill ~43 ~5 ~18 ~44 ~5 ~18 grass 0
fill ~44 ~5 ~10 ~50 ~5 ~10 stonebrick 0
fill ~44 ~5 ~11 ~50 ~5 ~11 stonebrick 0
fill ~44 ~5 ~12 ~50 ~5 ~12 stonebrick 0
fill ~44 ~5 ~13 ~50 ~5 ~13 stonebrick 0
fill ~44 ~5 ~14 ~50 ~5 ~14 cobblestone 0
fill ~45 ~5 ~17 ~45 ~10 ~17 cobblestone 0 
setblock ~45 ~5 ~18 dirt 0 
setblock ~46 ~5 ~9 wool 14
fill ~46 ~5 ~18 ~48 ~5 ~18 grass 0 
setblock ~47 ~5 ~17 glowstone 0 
setblock ~48 ~5 ~9 wool 14
fill ~49 ~5 ~17 ~49 ~10 ~17 cobblestone 0
fill ~49 ~5 ~18 ~55 ~5 ~18 dirt 0 
setblock ~49 ~5 ~28 stonebrick 2
fill ~50 ~5 ~28 ~50 ~13 ~28 stonebrick 1
fill ~50 ~5 ~65 ~67 ~5 ~65 dirt 0
fill ~50 ~5 ~66 ~59 ~5 ~66 dirt 0 
setblock ~51 ~5 ~10 double_stone_slab 0
fill ~51 ~5 ~11 ~51 ~5 ~13 stone_brick_stairs 1 
setblock ~51 ~5 ~14 double_stone_slab 0 
setblock ~51 ~5 ~28 stonebrick 2
fill ~51 ~5 ~67 ~53 ~5 ~67 dirt 0 
setblock ~52 ~5 ~3 torch 5 
setblock ~52 ~5 ~7 torch 5 
setblock ~52 ~5 ~10 stone_slab 0 
setblock ~52 ~5 ~14 stone_slab 0
fill ~52 ~5 ~28 ~58 ~5 ~28 stonebrick 1 
setblock ~53 ~5 ~57 stonebrick 2
fill ~54 ~5 ~57 ~55 ~5 ~57 stonebrick 1
fill ~55 ~5 ~19 ~56 ~5 ~19 dirt 0
fill ~55 ~5 ~67 ~59 ~5 ~67 dirt 0 
setblock ~56 ~5 ~3 torch 5 
setblock ~56 ~5 ~7 torch 5 
setblock ~56 ~5 ~10 torch 5 
setblock ~56 ~5 ~14 torch 5
fill ~56 ~5 ~18 ~61 ~5 ~18 grass 0 
setblock ~56 ~5 ~57 stonebrick 2
fill ~56 ~5 ~68 ~58 ~5 ~68 dirt 0
fill ~57 ~5 ~57 ~62 ~5 ~57 stonebrick 1
fill ~59 ~5 ~19 ~62 ~5 ~19 dirt 0 
setblock ~59 ~5 ~28 stonebrick 2
fill ~60 ~5 ~20 ~61 ~5 ~20 dirt 0
fill ~60 ~5 ~28 ~60 ~9 ~28 stonebrick 1
fill ~60 ~5 ~66 ~70 ~5 ~66 grass 0 
setblock ~61 ~5 ~28 stonebrick 2 
setblock ~62 ~5 ~28 stonebrick 1
fill ~63 ~5 ~19 ~65 ~5 ~19 grass 0
fill ~63 ~5 ~20 ~65 ~5 ~20 dirt 0
fill ~63 ~5 ~28 ~63 ~6 ~28 stonebrick 2
fill ~63 ~5 ~29 ~63 ~6 ~29 stonebrick 1
fill ~63 ~5 ~30 ~63 ~6 ~30 stonebrick 1
fill ~63 ~5 ~31 ~63 ~6 ~31 stonebrick 1 
setblock ~63 ~5 ~32 stonebrick 2
fill ~63 ~5 ~33 ~63 ~7 ~33 stonebrick 1
fill ~63 ~5 ~34 ~63 ~13 ~34 stonebrick 1
fill ~63 ~5 ~35 ~63 ~6 ~35 stonebrick 1
fill ~63 ~5 ~36 ~63 ~12 ~36 stonebrick 1 
setblock ~63 ~5 ~37 stonebrick 2
fill ~63 ~5 ~38 ~63 ~10 ~38 stonebrick 1
fill ~63 ~5 ~39 ~63 ~5 ~40 stonebrick 1
fill ~63 ~5 ~41 ~63 ~9 ~41 obsidian 0
fill ~63 ~5 ~42 ~63 ~5 ~44 obsidian 0
fill ~63 ~5 ~45 ~63 ~13 ~45 stonebrick 1
fill ~63 ~5 ~46 ~63 ~6 ~46 stonebrick 1
fill ~63 ~5 ~47 ~63 ~9 ~47 stonebrick 1
fill ~63 ~5 ~48 ~63 ~5 ~49 stonebrick 1 
setblock ~63 ~5 ~50 stonebrick 2
fill ~63 ~5 ~51 ~63 ~9 ~51 stonebrick 1
fill ~63 ~5 ~52 ~63 ~5 ~56 stonebrick 1 
setblock ~63 ~5 ~57 stonebrick 2
fill ~64 ~5 ~28 ~67 ~5 ~28 double_stone_slab 0
fill ~64 ~5 ~29 ~67 ~5 ~29 double_stone_slab 0
fill ~64 ~5 ~30 ~67 ~5 ~30 double_stone_slab 0
fill ~64 ~5 ~31 ~67 ~5 ~31 double_stone_slab 0
fill ~64 ~5 ~32 ~67 ~5 ~32 double_stone_slab 0
fill ~64 ~5 ~33 ~67 ~5 ~33 double_stone_slab 0
fill ~64 ~5 ~34 ~67 ~5 ~34 double_stone_slab 0
fill ~64 ~5 ~35 ~67 ~5 ~35 double_stone_slab 0
fill ~64 ~5 ~36 ~67 ~5 ~36 double_stone_slab 0
fill ~64 ~5 ~37 ~67 ~5 ~37 double_stone_slab 0
fill ~64 ~5 ~38 ~67 ~5 ~38 double_stone_slab 0
fill ~64 ~5 ~39 ~67 ~5 ~39 double_stone_slab 0
fill ~64 ~5 ~40 ~67 ~5 ~40 double_stone_slab 0
fill ~64 ~5 ~41 ~67 ~5 ~41 double_stone_slab 0
fill ~64 ~5 ~42 ~67 ~5 ~42 double_stone_slab 0
fill ~64 ~5 ~43 ~67 ~5 ~43 double_stone_slab 0
fill ~64 ~5 ~44 ~67 ~5 ~44 double_stone_slab 0
fill ~64 ~5 ~45 ~67 ~5 ~45 double_stone_slab 0
fill ~64 ~5 ~46 ~67 ~5 ~46 double_stone_slab 0
fill ~64 ~5 ~47 ~67 ~5 ~47 double_stone_slab 0
fill ~64 ~5 ~48 ~67 ~5 ~48 double_stone_slab 0
fill ~64 ~5 ~49 ~67 ~5 ~49 double_stone_slab 0
fill ~64 ~5 ~50 ~67 ~5 ~50 double_stone_slab 0
fill ~64 ~5 ~51 ~67 ~5 ~51 double_stone_slab 0
fill ~64 ~5 ~52 ~67 ~5 ~52 double_stone_slab 0
fill ~64 ~5 ~53 ~67 ~5 ~53 double_stone_slab 0
fill ~64 ~5 ~54 ~67 ~5 ~54 double_stone_slab 0
fill ~64 ~5 ~55 ~67 ~5 ~55 double_stone_slab 0
fill ~64 ~5 ~56 ~67 ~5 ~56 double_stone_slab 0
fill ~64 ~5 ~57 ~67 ~5 ~57 double_stone_slab 0
fill ~66 ~5 ~20 ~68 ~5 ~20 grass 0
fill ~67 ~5 ~61 ~73 ~5 ~61 dirt 0
fill ~68 ~5 ~24 ~72 ~5 ~24 dirt 0
fill ~68 ~5 ~25 ~73 ~5 ~25 dirt 0
fill ~68 ~5 ~26 ~73 ~5 ~26 dirt 0
fill ~68 ~5 ~27 ~73 ~5 ~27 dirt 0
fill ~68 ~5 ~28 ~73 ~5 ~28 dirt 0
fill ~68 ~5 ~29 ~73 ~5 ~29 dirt 0
fill ~68 ~5 ~30 ~73 ~5 ~30 dirt 0
fill ~68 ~5 ~31 ~73 ~5 ~31 dirt 0
fill ~68 ~5 ~32 ~74 ~5 ~32 dirt 0
fill ~68 ~5 ~33 ~75 ~5 ~33 dirt 0
fill ~68 ~5 ~34 ~75 ~5 ~34 dirt 0
fill ~68 ~5 ~35 ~76 ~5 ~35 dirt 0
fill ~68 ~5 ~36 ~77 ~5 ~36 dirt 0
fill ~68 ~5 ~37 ~77 ~5 ~37 dirt 0
fill ~68 ~5 ~38 ~77 ~5 ~38 dirt 0
fill ~68 ~5 ~39 ~77 ~5 ~39 dirt 0
fill ~68 ~5 ~40 ~77 ~5 ~40 dirt 0
fill ~68 ~5 ~41 ~76 ~5 ~41 dirt 0
fill ~68 ~5 ~42 ~76 ~5 ~42 dirt 0
fill ~68 ~5 ~43 ~76 ~5 ~43 dirt 0
fill ~68 ~5 ~44 ~76 ~5 ~44 dirt 0
fill ~68 ~5 ~45 ~77 ~5 ~45 dirt 0
fill ~68 ~5 ~46 ~77 ~5 ~46 dirt 0
fill ~68 ~5 ~47 ~77 ~5 ~47 dirt 0
fill ~68 ~5 ~48 ~77 ~5 ~48 dirt 0
fill ~68 ~5 ~49 ~77 ~5 ~49 dirt 0
fill ~68 ~5 ~50 ~77 ~5 ~50 dirt 0
fill ~68 ~5 ~51 ~76 ~5 ~51 dirt 0
fill ~68 ~5 ~52 ~77 ~5 ~52 dirt 0
fill ~68 ~5 ~53 ~77 ~5 ~53 dirt 0
fill ~68 ~5 ~54 ~76 ~5 ~54 dirt 0
fill ~68 ~5 ~55 ~75 ~5 ~55 dirt 0
fill ~68 ~5 ~56 ~75 ~5 ~56 dirt 0
fill ~68 ~5 ~57 ~75 ~5 ~57 dirt 0
fill ~68 ~5 ~58 ~75 ~5 ~58 dirt 0
fill ~68 ~5 ~59 ~74 ~5 ~59 dirt 0
fill ~68 ~5 ~60 ~74 ~5 ~60 dirt 0
fill ~68 ~5 ~65 ~71 ~5 ~65 grass 0
fill ~70 ~5 ~21 ~71 ~5 ~21 grass 0
fill ~70 ~5 ~64 ~73 ~5 ~64 grass 0 
setblock ~72 ~5 ~22 grass 0
fill ~72 ~5 ~63 ~73 ~5 ~63 grass 0
fill ~73 ~5 ~23 ~73 ~5 ~24 grass 0
fill ~74 ~5 ~25 ~74 ~5 ~31 grass 0
fill ~74 ~5 ~61 ~75 ~5 ~61 grass 0
fill ~74 ~5 ~62 ~74 ~5 ~61 grass 0
fill ~75 ~5 ~31 ~75 ~5 ~32 grass 0
fill ~75 ~5 ~59 ~76 ~5 ~59 grass 0
fill ~75 ~5 ~60 ~75 ~5 ~59 grass 0
fill ~76 ~5 ~33 ~76 ~5 ~34 grass 0
fill ~76 ~5 ~55 ~77 ~5 ~55 grass 0
fill ~76 ~5 ~56 ~77 ~5 ~56 grass 0
fill ~76 ~5 ~57 ~76 ~5 ~59 grass 0
fill ~77 ~5 ~34 ~77 ~5 ~35 grass 0
fill ~77 ~5 ~41 ~77 ~5 ~44 grass 0 
setblock ~77 ~5 ~51 grass 0 
setblock ~77 ~5 ~54 grass 0
fill ~78 ~5 ~36 ~78 ~5 ~40 grass 0
fill ~78 ~5 ~45 ~78 ~5 ~49 grass 0
fill ~23 ~6 ~45 ~23 ~6 ~55 grass 0
fill ~24 ~6 ~21 ~68 ~6 ~21 dirt 0
fill ~24 ~6 ~22 ~70 ~6 ~22 dirt 0
fill ~24 ~6 ~23 ~70 ~6 ~23 dirt 0
fill ~24 ~6 ~24 ~34 ~6 ~24 dirt 0
fill ~24 ~6 ~25 ~33 ~6 ~25 dirt 0
fill ~24 ~6 ~26 ~29 ~6 ~26 dirt 0
fill ~24 ~6 ~27 ~28 ~6 ~27 dirt 0
fill ~24 ~6 ~28 ~28 ~6 ~28 dirt 0
fill ~24 ~6 ~29 ~24 ~6 ~30 grass 0
fill ~24 ~6 ~31 ~28 ~6 ~31 dirt 0
fill ~24 ~6 ~32 ~28 ~6 ~32 dirt 0
fill ~24 ~6 ~33 ~28 ~6 ~33 dirt 0
fill ~24 ~6 ~36 ~24 ~6 ~43 grass 0
fill ~24 ~6 ~44 ~27 ~6 ~44 dirt 0
fill ~24 ~6 ~45 ~27 ~6 ~45 dirt 0
fill ~24 ~6 ~46 ~27 ~6 ~46 dirt 0
fill ~24 ~6 ~47 ~26 ~6 ~47 dirt 0
fill ~24 ~6 ~48 ~26 ~6 ~48 dirt 0
fill ~24 ~6 ~49 ~26 ~6 ~49 dirt 0
fill ~24 ~6 ~50 ~28 ~6 ~50 dirt 0
fill ~24 ~6 ~51 ~28 ~6 ~51 dirt 0
fill ~24 ~6 ~52 ~28 ~6 ~52 dirt 0
fill ~24 ~6 ~53 ~26 ~6 ~53 dirt 0
fill ~24 ~6 ~54 ~24 ~6 ~56 grass 0
fill ~25 ~6 ~20 ~27 ~6 ~20 dirt 0
fill ~25 ~6 ~29 ~28 ~6 ~29 dirt 0
fill ~25 ~6 ~30 ~28 ~6 ~30 dirt 0
fill ~25 ~6 ~34 ~28 ~6 ~34 dirt 0
fill ~25 ~6 ~35 ~28 ~6 ~35 dirt 0
fill ~25 ~6 ~36 ~28 ~6 ~36 dirt 0 
setblock ~25 ~6 ~37 grass 0
fill ~25 ~6 ~38 ~26 ~6 ~38 dirt 0
fill ~25 ~6 ~39 ~28 ~6 ~39 dirt 0
fill ~25 ~6 ~40 ~28 ~6 ~40 dirt 0
fill ~25 ~6 ~41 ~28 ~6 ~41 dirt 0
fill ~25 ~6 ~42 ~26 ~6 ~42 dirt 0
fill ~25 ~6 ~43 ~26 ~6 ~43 dirt 0
fill ~25 ~6 ~54 ~26 ~6 ~54 dirt 0
fill ~25 ~6 ~55 ~26 ~6 ~55 dirt 0
fill ~25 ~6 ~56 ~28 ~6 ~56 dirt 0
fill ~25 ~6 ~57 ~28 ~6 ~57 dirt 0
fill ~25 ~6 ~60 ~41 ~6 ~60 dirt 0
fill ~25 ~6 ~61 ~41 ~6 ~61 dirt 0
fill ~25 ~6 ~62 ~67 ~6 ~62 dirt 0
fill ~26 ~6 ~37 ~26 ~8 ~37 dirt 0 
setblock ~26 ~6 ~58 double_stone_slab 0
fill ~26 ~6 ~59 ~26 ~18 ~59 stone 0
fill ~26 ~6 ~63 ~28 ~6 ~63 dirt 0
fill ~27 ~6 ~37 ~30 ~6 ~37 double_stone_slab 0
fill ~27 ~6 ~38 ~30 ~6 ~38 double_stone_slab 0
fill ~27 ~6 ~42 ~30 ~6 ~42 double_stone_slab 0
fill ~27 ~6 ~43 ~30 ~6 ~43 double_stone_slab 0
fill ~27 ~6 ~47 ~30 ~6 ~47 double_stone_slab 0
fill ~27 ~6 ~48 ~30 ~6 ~48 double_stone_slab 0
fill ~27 ~6 ~49 ~30 ~6 ~49 double_stone_slab 0
fill ~27 ~6 ~53 ~30 ~6 ~53 double_stone_slab 0
fill ~27 ~6 ~54 ~30 ~6 ~54 double_stone_slab 0
fill ~27 ~6 ~55 ~30 ~6 ~55 double_stone_slab 0
fill ~27 ~6 ~58 ~28 ~6 ~58 dirt 0
fill ~27 ~6 ~59 ~28 ~6 ~59 dirt 0
fill ~28 ~6 ~44 ~30 ~6 ~44 double_stone_slab 0
fill ~28 ~6 ~45 ~30 ~6 ~45 double_stone_slab 0
fill ~28 ~6 ~46 ~30 ~6 ~46 double_stone_slab 0
fill ~29 ~6 ~20 ~36 ~6 ~20 dirt 0
fill ~29 ~6 ~27 ~67 ~6 ~27 double_stone_slab 0
fill ~29 ~6 ~28 ~30 ~6 ~28 double_stone_slab 0
fill ~29 ~6 ~29 ~30 ~6 ~29 double_stone_slab 0
fill ~29 ~6 ~30 ~30 ~6 ~30 double_stone_slab 0
fill ~29 ~6 ~31 ~30 ~6 ~31 double_stone_slab 0
fill ~29 ~6 ~32 ~30 ~6 ~32 double_stone_slab 0
fill ~29 ~6 ~33 ~30 ~6 ~33 double_stone_slab 0
fill ~29 ~6 ~34 ~30 ~6 ~34 double_stone_slab 0
fill ~29 ~6 ~35 ~30 ~6 ~35 double_stone_slab 0
fill ~29 ~6 ~36 ~30 ~6 ~36 double_stone_slab 0
fill ~29 ~6 ~39 ~30 ~6 ~39 double_stone_slab 0
fill ~29 ~6 ~40 ~30 ~6 ~40 double_stone_slab 0
fill ~29 ~6 ~41 ~30 ~6 ~41 double_stone_slab 0
fill ~29 ~6 ~50 ~30 ~6 ~50 double_stone_slab 0
fill ~29 ~6 ~51 ~30 ~6 ~51 double_stone_slab 0
fill ~29 ~6 ~52 ~30 ~6 ~52 double_stone_slab 0
fill ~29 ~6 ~56 ~30 ~6 ~56 double_stone_slab 0
fill ~29 ~6 ~57 ~30 ~6 ~57 double_stone_slab 0
fill ~29 ~6 ~58 ~67 ~6 ~58 double_stone_slab 0
fill ~29 ~6 ~59 ~30 ~6 ~59 double_stone_slab 0
fill ~29 ~6 ~63 ~33 ~6 ~63 grass 0
fill ~30 ~6 ~26 ~67 ~6 ~26 double_stone_slab 0
fill ~31 ~6 ~28 ~31 ~8 ~28 stonebrick 1
fill ~31 ~6 ~39 ~31 ~8 ~39 stonebrick 1 
setblock ~31 ~6 ~40 stonebrick 2 
setblock ~31 ~6 ~41 stonebrick 1 
setblock ~31 ~6 ~50 stonebrick 2
fill ~31 ~6 ~51 ~31 ~9 ~51 stonebrick 1
fill ~31 ~6 ~52 ~31 ~6 ~57 stonebrick 1
fill ~31 ~6 ~59 ~36 ~6 ~59 dirt 0 
setblock ~32 ~6 ~28 stonebrick 2
fill ~32 ~6 ~41 ~33 ~6 ~41 stone_brick_stairs 6
fill ~32 ~6 ~42 ~33 ~6 ~42 stone_brick_stairs 3
fill ~32 ~6 ~57 ~35 ~6 ~57 stonebrick 1
fill ~33 ~6 ~19 ~35 ~6 ~19 dirt 0
fill ~33 ~6 ~28 ~36 ~6 ~28 stonebrick 1
fill ~34 ~6 ~25 ~67 ~6 ~25 double_stone_slab 0
fill ~34 ~6 ~63 ~36 ~6 ~63 dirt 0
fill ~35 ~6 ~24 ~67 ~6 ~24 double_stone_slab 0
fill ~36 ~6 ~57 ~36 ~7 ~57 stonebrick 2
fill ~37 ~6 ~20 ~41 ~6 ~20 grass 0 
setblock ~37 ~6 ~28 stonebrick 2
fill ~37 ~6 ~57 ~39 ~6 ~57 stonebrick 1
fill ~37 ~6 ~59 ~37 ~15 ~59 double_stone_slab 0
fill ~38 ~6 ~28 ~46 ~6 ~28 stonebrick 1
fill ~38 ~6 ~59 ~40 ~6 ~59 dirt 0
fill ~38 ~6 ~63 ~70 ~6 ~63 dirt 0
fill ~40 ~6 ~57 ~40 ~8 ~57 stonebrick 2
fill ~41 ~6 ~57 ~41 ~10 ~57 stonebrick 1
fill ~41 ~6 ~59 ~67 ~6 ~59 double_stone_slab 0
fill ~41 ~6 ~64 ~42 ~6 ~64 grass 0
fill ~42 ~6 ~19 ~44 ~6 ~19 grass 0
fill ~42 ~6 ~20 ~64 ~6 ~20 dirt 0 
setblock ~42 ~6 ~57 stonebrick 2
fill ~42 ~6 ~60 ~48 ~6 ~60 double_stone_slab 0
fill ~42 ~6 ~61 ~42 ~6 ~58 double_stone_slab 0 
setblock ~43 ~6 ~10 stone_slab 0 
setblock ~43 ~6 ~14 stone_slab 0
fill ~43 ~6 ~57 ~46 ~6 ~57 stonebrick 1
fill ~43 ~6 ~61 ~45 ~6 ~61 dirt 0
fill ~43 ~6 ~64 ~45 ~6 ~64 dirt 0 
setblock ~44 ~6 ~10 double_stone_slab 0
fill ~44 ~6 ~11 ~44 ~6 ~13 stone_brick_stairs 0 
setblock ~44 ~6 ~14 double_stone_slab 0
fill ~45 ~6 ~10 ~49 ~6 ~10 stonebrick 0
fill ~45 ~6 ~11 ~49 ~6 ~11 stonebrick 0
fill ~45 ~6 ~12 ~49 ~6 ~12 stonebrick 0
fill ~45 ~6 ~13 ~49 ~6 ~13 stonebrick 0
fill ~45 ~6 ~14 ~49 ~6 ~14 cobblestone 0
fill ~45 ~6 ~18 ~45 ~11 ~18 cobblestone 0 
setblock ~45 ~6 ~19 dirt 0
fill ~46 ~6 ~9 ~46 ~7 ~9 wool 4
fill ~46 ~6 ~19 ~47 ~6 ~19 grass 0
fill ~46 ~6 ~61 ~48 ~6 ~61 double_stone_slab 0
fill ~46 ~6 ~64 ~50 ~6 ~64 grass 0 
setblock ~47 ~6 ~18 glowstone 0 
setblock ~47 ~6 ~28 stonebrick 2 
setblock ~47 ~6 ~57 stonebrick 2
fill ~48 ~6 ~9 ~48 ~7 ~9 wool 4
fill ~48 ~6 ~19 ~53 ~6 ~19 dirt 0
fill ~48 ~6 ~28 ~52 ~6 ~28 stonebrick 1
fill ~48 ~6 ~57 ~51 ~6 ~57 stonebrick 1
fill ~49 ~6 ~18 ~49 ~-3 ~18 dirt 0
fill ~49 ~6 ~60 ~51 ~6 ~60 dirt 0
fill ~49 ~6 ~61 ~51 ~6 ~61 dirt 0 
setblock ~50 ~6 ~10 double_stone_slab 0
fill ~50 ~6 ~11 ~50 ~6 ~13 stone_brick_stairs 1 
setblock ~50 ~6 ~14 double_stone_slab 0
fill ~50 ~6 ~18 ~55 ~6 ~18 grass 0
fill ~50 ~6 ~65 ~50 ~6 ~66 grass 0 
setblock ~51 ~6 ~10 stone_slab 0 
setblock ~51 ~6 ~14 stone_slab 0
fill ~51 ~6 ~64 ~55 ~6 ~64 dirt 0
fill ~51 ~6 ~65 ~58 ~6 ~65 dirt 0
fill ~51 ~6 ~66 ~53 ~6 ~66 dirt 0
fill ~51 ~6 ~67 ~53 ~6 ~67 grass 0 
setblock ~52 ~6 ~57 stonebrick 2
fill ~52 ~6 ~60 ~66 ~6 ~60 double_stone_slab 0
fill ~52 ~6 ~61 ~52 ~6 ~58 double_stone_slab 0
fill ~53 ~6 ~28 ~54 ~6 ~28 stonebrick 2
fill ~53 ~6 ~57 ~53 ~13 ~57 stonebrick 1
fill ~53 ~6 ~61 ~55 ~6 ~61 dirt 0 
setblock ~54 ~6 ~57 stonebrick 2
fill ~54 ~6 ~66 ~55 ~6 ~66 grass 0
fill ~55 ~6 ~19 ~57 ~6 ~19 dirt 0
fill ~55 ~6 ~28 ~61 ~6 ~28 stonebrick 1
fill ~55 ~6 ~57 ~63 ~6 ~57 stonebrick 1 
setblock ~55 ~6 ~67 grass 0
fill ~56 ~6 ~61 ~57 ~6 ~61 double_stone_slab 0
fill ~56 ~6 ~64 ~57 ~6 ~64 grass 0
fill ~56 ~6 ~66 ~58 ~6 ~66 dirt 0
fill ~56 ~6 ~67 ~58 ~6 ~67 dirt 0
fill ~56 ~6 ~68 ~58 ~6 ~68 grass 0
fill ~58 ~6 ~61 ~60 ~6 ~61 dirt 0
fill ~58 ~6 ~64 ~69 ~6 ~64 dirt 0
fill ~59 ~6 ~19 ~62 ~6 ~19 grass 0
fill ~59 ~6 ~65 ~67 ~6 ~65 grass 0
fill ~59 ~6 ~66 ~59 ~6 ~67 grass 0
fill ~61 ~6 ~61 ~65 ~6 ~61 double_stone_slab 0
fill ~62 ~6 ~28 ~62 ~7 ~28 stonebrick 2
fill ~63 ~6 ~32 ~63 ~13 ~32 stonebrick 1
fill ~63 ~6 ~37 ~63 ~7 ~37 stonebrick 1 
setblock ~63 ~6 ~39 stonebrick 2
fill ~63 ~6 ~40 ~63 ~13 ~40 stonebrick 1
fill ~63 ~6 ~42 ~63 ~8 ~42 portal 0
fill ~63 ~6 ~43 ~63 ~8 ~43 portal 0
fill ~63 ~6 ~44 ~63 ~9 ~44 obsidian 0
fill ~63 ~6 ~48 ~63 ~7 ~48 stonebrick 2
fill ~63 ~6 ~49 ~63 ~13 ~49 stonebrick 1
fill ~63 ~6 ~50 ~63 ~8 ~50 stonebrick 1 
setblock ~63 ~6 ~52 stonebrick 2
fill ~63 ~6 ~53 ~63 ~10 ~53 stonebrick 1
fill ~63 ~6 ~54 ~63 ~13 ~54 stonebrick 1
fill ~63 ~6 ~55 ~63 ~9 ~55 stonebrick 1
fill ~63 ~6 ~56 ~63 ~13 ~56 stonebrick 1
fill ~64 ~6 ~28 ~67 ~6 ~28 double_stone_slab 0
fill ~64 ~6 ~29 ~67 ~6 ~29 double_stone_slab 0
fill ~64 ~6 ~30 ~67 ~6 ~30 double_stone_slab 0
fill ~64 ~6 ~31 ~67 ~6 ~31 double_stone_slab 0
fill ~64 ~6 ~32 ~67 ~6 ~32 double_stone_slab 0
fill ~64 ~6 ~33 ~67 ~6 ~33 double_stone_slab 0
fill ~64 ~6 ~34 ~67 ~6 ~34 double_stone_slab 0
fill ~64 ~6 ~35 ~67 ~6 ~35 double_stone_slab 0
fill ~64 ~6 ~36 ~67 ~6 ~36 double_stone_slab 0
fill ~64 ~6 ~37 ~67 ~6 ~37 double_stone_slab 0
fill ~64 ~6 ~38 ~67 ~6 ~38 double_stone_slab 0
fill ~64 ~6 ~39 ~67 ~6 ~39 double_stone_slab 0
fill ~64 ~6 ~40 ~67 ~6 ~40 double_stone_slab 0
fill ~64 ~6 ~41 ~64 ~9 ~41 soul_sand 0
fill ~64 ~6 ~42 ~64 ~9 ~42 soul_sand 0
fill ~64 ~6 ~43 ~64 ~8 ~43 soul_sand 0
fill ~64 ~6 ~44 ~67 ~6 ~44 double_stone_slab 0
fill ~64 ~6 ~45 ~67 ~6 ~45 double_stone_slab 0
fill ~64 ~6 ~46 ~67 ~6 ~46 double_stone_slab 0
fill ~64 ~6 ~47 ~67 ~6 ~47 double_stone_slab 0
fill ~64 ~6 ~48 ~67 ~6 ~48 double_stone_slab 0
fill ~64 ~6 ~49 ~67 ~6 ~49 double_stone_slab 0
fill ~64 ~6 ~50 ~67 ~6 ~50 double_stone_slab 0
fill ~64 ~6 ~51 ~67 ~6 ~51 double_stone_slab 0
fill ~64 ~6 ~52 ~67 ~6 ~52 double_stone_slab 0
fill ~64 ~6 ~53 ~67 ~6 ~53 double_stone_slab 0
fill ~64 ~6 ~54 ~67 ~6 ~54 double_stone_slab 0
fill ~64 ~6 ~55 ~67 ~6 ~55 double_stone_slab 0
fill ~64 ~6 ~56 ~67 ~6 ~56 double_stone_slab 0
fill ~64 ~6 ~57 ~67 ~6 ~57 double_stone_slab 0 
setblock ~65 ~6 ~20 grass 0
fill ~65 ~6 ~41 ~67 ~6 ~41 double_stone_slab 0
fill ~65 ~6 ~42 ~67 ~6 ~42 double_stone_slab 0
fill ~65 ~6 ~43 ~67 ~6 ~43 double_stone_slab 0
fill ~66 ~6 ~61 ~72 ~6 ~61 dirt 0
fill ~67 ~6 ~60 ~73 ~6 ~60 dirt 0
fill ~68 ~6 ~24 ~71 ~6 ~24 dirt 0
fill ~68 ~6 ~25 ~72 ~6 ~25 dirt 0
fill ~68 ~6 ~26 ~72 ~6 ~26 dirt 0
fill ~68 ~6 ~27 ~73 ~6 ~27 dirt 0
fill ~68 ~6 ~28 ~73 ~6 ~28 dirt 0
fill ~68 ~6 ~29 ~73 ~6 ~29 dirt 0
fill ~68 ~6 ~30 ~73 ~6 ~30 dirt 0
fill ~68 ~6 ~31 ~73 ~6 ~31 dirt 0
fill ~68 ~6 ~32 ~73 ~6 ~32 dirt 0
fill ~68 ~6 ~33 ~73 ~6 ~33 dirt 0
fill ~68 ~6 ~34 ~74 ~6 ~34 dirt 0
fill ~68 ~6 ~35 ~74 ~6 ~35 dirt 0
fill ~68 ~6 ~36 ~75 ~6 ~36 dirt 0
fill ~68 ~6 ~37 ~76 ~6 ~37 dirt 0
fill ~68 ~6 ~38 ~76 ~6 ~38 dirt 0
fill ~68 ~6 ~39 ~76 ~6 ~39 dirt 0
fill ~68 ~6 ~40 ~75 ~6 ~40 dirt 0
fill ~68 ~6 ~41 ~75 ~6 ~41 dirt 0
fill ~68 ~6 ~42 ~75 ~6 ~42 dirt 0
fill ~68 ~6 ~43 ~75 ~6 ~43 dirt 0
fill ~68 ~6 ~44 ~75 ~6 ~44 dirt 0
fill ~68 ~6 ~45 ~75 ~6 ~45 dirt 0
fill ~68 ~6 ~46 ~76 ~6 ~46 dirt 0
fill ~68 ~6 ~47 ~76 ~6 ~47 dirt 0
fill ~68 ~6 ~48 ~76 ~6 ~48 dirt 0
fill ~68 ~6 ~49 ~76 ~6 ~49 dirt 0
fill ~68 ~6 ~50 ~76 ~6 ~50 dirt 0
fill ~68 ~6 ~51 ~75 ~6 ~51 dirt 0
fill ~68 ~6 ~52 ~75 ~6 ~52 dirt 0
fill ~68 ~6 ~53 ~75 ~6 ~53 dirt 0
fill ~68 ~6 ~54 ~74 ~6 ~54 dirt 0
fill ~68 ~6 ~55 ~74 ~6 ~55 dirt 0
fill ~68 ~6 ~56 ~74 ~6 ~56 dirt 0
fill ~68 ~6 ~57 ~74 ~6 ~57 dirt 0
fill ~68 ~6 ~58 ~74 ~6 ~58 dirt 0
fill ~68 ~6 ~59 ~73 ~6 ~59 dirt 0
fill ~68 ~6 ~62 ~68 ~19 ~62 double_stone_slab 0 
setblock ~69 ~6 ~21 grass 0
fill ~69 ~6 ~62 ~70 ~6 ~62 dirt 0
fill ~71 ~6 ~22 ~71 ~6 ~23 grass 0
fill ~71 ~6 ~62 ~73 ~6 ~62 grass 0
fill ~71 ~6 ~63 ~71 ~6 ~62 grass 0
fill ~72 ~6 ~23 ~72 ~6 ~24 grass 0
fill ~73 ~6 ~25 ~73 ~6 ~26 grass 0 
setblock ~73 ~6 ~61 grass 0
fill ~74 ~6 ~32 ~74 ~6 ~33 grass 0
fill ~74 ~6 ~59 ~74 ~6 ~60 grass 0
fill ~75 ~6 ~33 ~75 ~6 ~35 grass 0
fill ~75 ~6 ~54 ~76 ~6 ~54 grass 0
fill ~75 ~6 ~55 ~75 ~6 ~58 grass 0
fill ~76 ~6 ~35 ~76 ~6 ~36 grass 0
fill ~76 ~6 ~40 ~77 ~6 ~40 grass 0
fill ~76 ~6 ~41 ~76 ~6 ~45 grass 0
fill ~76 ~6 ~51 ~76 ~6 ~54 grass 0
fill ~77 ~6 ~36 ~77 ~6 ~40 grass 0
fill ~77 ~6 ~45 ~77 ~6 ~50 grass 0
fill ~77 ~6 ~52 ~77 ~6 ~53 grass 0
fill ~24 ~7 ~21 ~35 ~7 ~21 dirt 0
fill ~24 ~7 ~22 ~68 ~7 ~22 dirt 0
fill ~24 ~7 ~23 ~69 ~7 ~23 dirt 0
fill ~24 ~7 ~24 ~34 ~7 ~24 dirt 0
fill ~24 ~7 ~25 ~34 ~7 ~25 dirt 0
fill ~24 ~7 ~26 ~29 ~7 ~26 dirt 0
fill ~24 ~7 ~27 ~24 ~7 ~28 grass 0
fill ~24 ~7 ~31 ~24 ~7 ~33 grass 0
fill ~24 ~7 ~44 ~28 ~7 ~44 dirt 0
fill ~24 ~7 ~45 ~28 ~7 ~45 dirt 0
fill ~24 ~7 ~46 ~28 ~7 ~46 dirt 0
fill ~24 ~7 ~47 ~24 ~7 ~53 grass 0
fill ~25 ~7 ~20 ~27 ~7 ~20 dirt 0
fill ~25 ~7 ~27 ~28 ~7 ~27 dirt 0
fill ~25 ~7 ~28 ~28 ~7 ~28 dirt 0
fill ~25 ~7 ~29 ~29 ~7 ~29 dirt 0
fill ~25 ~7 ~30 ~29 ~7 ~30 dirt 0
fill ~25 ~7 ~31 ~29 ~7 ~31 dirt 0
fill ~25 ~7 ~32 ~28 ~7 ~32 dirt 0
fill ~25 ~7 ~33 ~28 ~7 ~33 dirt 0
fill ~25 ~7 ~34 ~29 ~7 ~34 dirt 0
fill ~25 ~7 ~35 ~29 ~7 ~35 dirt 0
fill ~25 ~7 ~36 ~29 ~7 ~36 dirt 0 
setblock ~25 ~7 ~38 grass 0
fill ~25 ~7 ~39 ~29 ~7 ~39 dirt 0
fill ~25 ~7 ~40 ~29 ~7 ~40 dirt 0
fill ~25 ~7 ~41 ~29 ~7 ~41 dirt 0 
setblock ~25 ~7 ~42 grass 0
fill ~25 ~7 ~43 ~27 ~7 ~43 dirt 0
fill ~25 ~7 ~47 ~27 ~7 ~47 dirt 0
fill ~25 ~7 ~48 ~25 ~7 ~49 grass 0
fill ~25 ~7 ~50 ~29 ~7 ~50 dirt 0
fill ~25 ~7 ~51 ~29 ~7 ~51 dirt 0
fill ~25 ~7 ~52 ~29 ~7 ~52 dirt 0
fill ~25 ~7 ~53 ~25 ~7 ~55 grass 0
fill ~25 ~7 ~56 ~29 ~7 ~56 dirt 0
fill ~25 ~7 ~57 ~29 ~7 ~57 dirt 0
fill ~25 ~7 ~58 ~29 ~7 ~58 dirt 0
fill ~25 ~7 ~60 ~25 ~7 ~62 grass 0
fill ~26 ~7 ~38 ~28 ~7 ~38 dirt 0
fill ~26 ~7 ~42 ~28 ~7 ~42 dirt 0
fill ~26 ~7 ~48 ~26 ~7 ~53 dirt 0 
setblock ~26 ~7 ~54 grass 0
fill ~26 ~7 ~55 ~28 ~7 ~55 dirt 0
fill ~26 ~7 ~60 ~29 ~7 ~60 dirt 0
fill ~26 ~7 ~61 ~29 ~7 ~61 dirt 0
fill ~26 ~7 ~62 ~28 ~7 ~62 dirt 0
fill ~26 ~7 ~63 ~28 ~7 ~63 grass 0
fill ~27 ~7 ~37 ~28 ~7 ~37 dirt 0
fill ~27 ~7 ~48 ~30 ~7 ~48 double_stone_slab 0
fill ~27 ~7 ~49 ~28 ~7 ~49 dirt 0
fill ~27 ~7 ~53 ~28 ~7 ~53 dirt 0
fill ~27 ~7 ~54 ~30 ~7 ~54 double_stone_slab 0
fill ~27 ~7 ~59 ~28 ~7 ~59 dirt 0
fill ~28 ~7 ~43 ~30 ~7 ~43 double_stone_slab 0
fill ~28 ~7 ~47 ~30 ~7 ~47 double_stone_slab 0
fill ~29 ~7 ~20 ~31 ~7 ~20 dirt 0
fill ~29 ~7 ~27 ~67 ~7 ~27 double_stone_slab 0
fill ~29 ~7 ~28 ~30 ~7 ~28 double_stone_slab 0
fill ~29 ~7 ~32 ~30 ~7 ~32 double_stone_slab 0
fill ~29 ~7 ~33 ~30 ~7 ~33 double_stone_slab 0
fill ~29 ~7 ~37 ~30 ~7 ~37 double_stone_slab 0
fill ~29 ~7 ~38 ~30 ~7 ~38 double_stone_slab 0
fill ~29 ~7 ~42 ~30 ~7 ~42 double_stone_slab 0
fill ~29 ~7 ~44 ~30 ~7 ~44 double_stone_slab 0
fill ~29 ~7 ~45 ~30 ~7 ~45 double_stone_slab 0
fill ~29 ~7 ~46 ~30 ~7 ~46 double_stone_slab 0
fill ~29 ~7 ~49 ~30 ~7 ~49 double_stone_slab 0
fill ~29 ~7 ~53 ~30 ~7 ~53 double_stone_slab 0
fill ~29 ~7 ~55 ~30 ~7 ~55 double_stone_slab 0
fill ~29 ~7 ~59 ~33 ~7 ~59 double_stone_slab 0
fill ~29 ~7 ~62 ~29 ~18 ~62 stone 0
fill ~30 ~7 ~26 ~67 ~7 ~26 double_stone_slab 0
fill ~30 ~7 ~29 ~30 ~15 ~29 double_stone_slab 0
fill ~30 ~7 ~30 ~30 ~15 ~30 double_stone_slab 0
fill ~30 ~7 ~31 ~30 ~24 ~31 double_stone_slab 0
fill ~30 ~7 ~34 ~30 ~15 ~34 double_stone_slab 0
fill ~30 ~7 ~35 ~30 ~15 ~35 double_stone_slab 0
fill ~30 ~7 ~36 ~30 ~15 ~36 double_stone_slab 0
fill ~30 ~7 ~39 ~30 ~24 ~39 double_stone_slab 0
fill ~30 ~7 ~40 ~30 ~15 ~40 double_stone_slab 0
fill ~30 ~7 ~41 ~30 ~15 ~41 double_stone_slab 0
fill ~30 ~7 ~50 ~30 ~15 ~50 double_stone_slab 0
fill ~30 ~7 ~51 ~30 ~15 ~51 double_stone_slab 0
fill ~30 ~7 ~52 ~30 ~15 ~52 double_stone_slab 0
fill ~30 ~7 ~56 ~30 ~15 ~56 double_stone_slab 0
fill ~30 ~7 ~57 ~30 ~15 ~57 double_stone_slab 0
fill ~30 ~7 ~58 ~67 ~7 ~58 double_stone_slab 0
fill ~30 ~7 ~60 ~30 ~15 ~60 double_stone_slab 0
fill ~30 ~7 ~61 ~30 ~15 ~61 double_stone_slab 0
fill ~30 ~7 ~62 ~30 ~19 ~62 double_stone_slab 0 
setblock ~31 ~7 ~33 stonebrick 2 
setblock ~31 ~7 ~40 stonebrick 1
fill ~31 ~7 ~41 ~31 ~9 ~41 stonebrick 2
fill ~31 ~7 ~50 ~31 ~11 ~50 stonebrick 1 
setblock ~31 ~7 ~52 stonebrick 2
fill ~31 ~7 ~53 ~31 ~8 ~53 stonebrick 1
fill ~31 ~7 ~54 ~31 ~10 ~54 stonebrick 1
fill ~31 ~7 ~55 ~31 ~13 ~55 stonebrick 1
fill ~31 ~7 ~56 ~31 ~13 ~56 stonebrick 1
fill ~31 ~7 ~57 ~33 ~7 ~57 stonebrick 2
fill ~31 ~7 ~60 ~41 ~7 ~60 dirt 0
fill ~31 ~7 ~61 ~46 ~7 ~61 dirt 0
fill ~31 ~7 ~62 ~33 ~7 ~62 grass 0 
setblock ~32 ~7 ~20 grass 0
fill ~32 ~7 ~28 ~32 ~9 ~28 stonebrick 1
fill ~32 ~7 ~40 ~33 ~7 ~40 stone_brick_stairs 6
fill ~32 ~7 ~41 ~33 ~7 ~41 stone_brick_stairs 3
fill ~33 ~7 ~19 ~35 ~7 ~19 grass 0
fill ~33 ~7 ~20 ~35 ~7 ~20 dirt 0 
setblock ~33 ~7 ~28 stonebrick 2
fill ~34 ~7 ~28 ~41 ~7 ~28 stonebrick 1
fill ~34 ~7 ~57 ~35 ~7 ~57 stonebrick 1
fill ~34 ~7 ~59 ~36 ~7 ~59 dirt 0
fill ~34 ~7 ~62 ~67 ~7 ~62 dirt 0
fill ~34 ~7 ~63 ~36 ~7 ~63 grass 0
fill ~35 ~7 ~24 ~67 ~7 ~24 double_stone_slab 0
fill ~35 ~7 ~25 ~67 ~7 ~25 double_stone_slab 0
fill ~36 ~7 ~20 ~36 ~7 ~21 grass 0
fill ~37 ~7 ~21 ~41 ~7 ~21 grass 0
fill ~37 ~7 ~57 ~37 ~8 ~57 stonebrick 1
fill ~38 ~7 ~57 ~38 ~8 ~57 stonebrick 2
fill ~38 ~7 ~59 ~40 ~7 ~59 dirt 0
fill ~38 ~7 ~63 ~40 ~7 ~63 dirt 0
fill ~39 ~7 ~57 ~39 ~9 ~57 stonebrick 1
fill ~41 ~7 ~59 ~48 ~7 ~59 double_stone_slab 0 
setblock ~41 ~7 ~63 grass 0
fill ~42 ~7 ~20 ~44 ~7 ~20 grass 0
fill ~42 ~7 ~21 ~68 ~7 ~21 dirt 0
fill ~42 ~7 ~28 ~43 ~7 ~28 stonebrick 2
fill ~42 ~7 ~57 ~45 ~7 ~57 stonebrick 1
fill ~42 ~7 ~60 ~42 ~15 ~60 double_stone_slab 0
fill ~42 ~7 ~63 ~46 ~7 ~63 dirt 0
fill ~43 ~7 ~60 ~45 ~7 ~60 dirt 0
fill ~43 ~7 ~64 ~45 ~7 ~64 dirt 0 
setblock ~44 ~7 ~10 stone_slab 0 
setblock ~44 ~7 ~14 stone_slab 0
fill ~44 ~7 ~28 ~52 ~7 ~28 stonebrick 1 
setblock ~45 ~7 ~10 double_stone_slab 0
fill ~45 ~7 ~11 ~45 ~7 ~13 stone_brick_stairs 0
fill ~45 ~7 ~14 ~45 ~8 ~14 double_stone_slab 0
fill ~45 ~7 ~19 ~45 ~12 ~19 cobblestone 0 
setblock ~45 ~7 ~20 dirt 0
fill ~46 ~7 ~10 ~48 ~7 ~10 stonebrick 0
fill ~46 ~7 ~11 ~48 ~7 ~11 stonebrick 0
fill ~46 ~7 ~12 ~48 ~7 ~12 stonebrick 0
fill ~46 ~7 ~13 ~48 ~7 ~13 stonebrick 0
fill ~46 ~7 ~14 ~48 ~7 ~14 cobblestone 0
fill ~46 ~7 ~20 ~47 ~7 ~20 grass 0 
setblock ~46 ~7 ~57 stonebrick 2
fill ~46 ~7 ~60 ~47 ~7 ~60 double_stone_slab 0
fill ~47 ~7 ~57 ~47 ~13 ~57 stonebrick 1
fill ~47 ~7 ~61 ~47 ~15 ~61 double_stone_slab 0
fill ~47 ~7 ~63 ~48 ~7 ~63 grass 0 
setblock ~48 ~7 ~19 grass 0
fill ~48 ~7 ~20 ~59 ~7 ~20 dirt 0 
setblock ~48 ~7 ~57 stonebrick 2
fill ~48 ~7 ~60 ~55 ~7 ~60 dirt 0
fill ~48 ~7 ~61 ~61 ~7 ~61 dirt 0 
setblock ~49 ~7 ~10 double_stone_slab 0
fill ~49 ~7 ~11 ~49 ~7 ~13 stone_brick_stairs 1
fill ~49 ~7 ~14 ~49 ~8 ~14 double_stone_slab 0
fill ~49 ~7 ~18 ~49 ~11 ~18 cobblestone 0 
setblock ~49 ~7 ~19 dirt 0
fill ~49 ~7 ~57 ~49 ~10 ~57 stonebrick 1
fill ~49 ~7 ~59 ~51 ~7 ~59 dirt 0
fill ~49 ~7 ~63 ~70 ~7 ~63 dirt 0 
setblock ~50 ~7 ~10 stone_slab 0 
setblock ~50 ~7 ~14 stone_slab 0
fill ~50 ~7 ~19 ~58 ~7 ~19 grass 0
fill ~50 ~7 ~57 ~51 ~7 ~57 stonebrick 2
fill ~51 ~7 ~64 ~51 ~7 ~66 grass 0 
setblock ~52 ~7 ~57 stonebrick 1
fill ~52 ~7 ~59 ~66 ~7 ~59 double_stone_slab 0
fill ~52 ~7 ~64 ~55 ~7 ~64 dirt 0
fill ~52 ~7 ~65 ~56 ~7 ~65 dirt 0 
setblock ~52 ~7 ~66 grass 0
fill ~53 ~7 ~28 ~53 ~6 ~28 stonebrick 2
fill ~53 ~7 ~66 ~53 ~9 ~66 dirt 0
fill ~54 ~7 ~28 ~55 ~7 ~28 stonebrick 1
fill ~54 ~7 ~57 ~63 ~7 ~57 stonebrick 1
fill ~56 ~7 ~28 ~56 ~8 ~28 stonebrick 2
fill ~56 ~7 ~60 ~57 ~7 ~60 double_stone_slab 0
fill ~56 ~7 ~66 ~58 ~7 ~66 grass 0
fill ~56 ~7 ~67 ~58 ~7 ~67 grass 0
fill ~57 ~7 ~28 ~61 ~7 ~28 stonebrick 1
fill ~57 ~7 ~65 ~58 ~7 ~65 grass 0
fill ~58 ~7 ~60 ~60 ~7 ~60 dirt 0
fill ~58 ~7 ~64 ~60 ~7 ~64 dirt 0
fill ~60 ~7 ~20 ~64 ~7 ~20 grass 0
fill ~61 ~7 ~60 ~63 ~7 ~60 double_stone_slab 0
fill ~61 ~7 ~64 ~66 ~7 ~64 grass 0
fill ~62 ~7 ~61 ~63 ~7 ~61 double_stone_slab 0
fill ~63 ~7 ~28 ~63 ~13 ~28 stonebrick 1
fill ~63 ~7 ~29 ~63 ~7 ~31 stonebrick 2 
setblock ~63 ~7 ~35 stonebrick 2
fill ~63 ~7 ~39 ~63 ~8 ~39 stonebrick 1 
setblock ~63 ~7 ~46 stonebrick 2
fill ~63 ~7 ~52 ~63 ~13 ~52 stonebrick 1
fill ~64 ~7 ~28 ~67 ~7 ~28 double_stone_slab 0
fill ~64 ~7 ~29 ~67 ~7 ~29 double_stone_slab 0
fill ~64 ~7 ~30 ~67 ~7 ~30 double_stone_slab 0
fill ~64 ~7 ~31 ~67 ~7 ~31 double_stone_slab 0
fill ~64 ~7 ~32 ~67 ~7 ~32 double_stone_slab 0
fill ~64 ~7 ~33 ~67 ~7 ~33 double_stone_slab 0
fill ~64 ~7 ~34 ~67 ~7 ~34 double_stone_slab 0
fill ~64 ~7 ~35 ~67 ~7 ~35 double_stone_slab 0
fill ~64 ~7 ~36 ~67 ~7 ~36 double_stone_slab 0
fill ~64 ~7 ~37 ~67 ~7 ~37 double_stone_slab 0
fill ~64 ~7 ~38 ~67 ~7 ~38 double_stone_slab 0
fill ~64 ~7 ~39 ~67 ~7 ~39 double_stone_slab 0
fill ~64 ~7 ~40 ~67 ~7 ~40 double_stone_slab 0
fill ~64 ~7 ~44 ~67 ~7 ~44 double_stone_slab 0
fill ~64 ~7 ~45 ~67 ~7 ~45 double_stone_slab 0
fill ~64 ~7 ~46 ~67 ~7 ~46 double_stone_slab 0
fill ~64 ~7 ~47 ~67 ~7 ~47 double_stone_slab 0
fill ~64 ~7 ~48 ~67 ~7 ~48 double_stone_slab 0
fill ~64 ~7 ~49 ~67 ~7 ~49 double_stone_slab 0
fill ~64 ~7 ~50 ~67 ~7 ~50 double_stone_slab 0
fill ~64 ~7 ~51 ~67 ~7 ~51 double_stone_slab 0
fill ~64 ~7 ~52 ~67 ~7 ~52 double_stone_slab 0
fill ~64 ~7 ~53 ~67 ~7 ~53 double_stone_slab 0
fill ~64 ~7 ~54 ~67 ~7 ~54 double_stone_slab 0
fill ~64 ~7 ~55 ~67 ~7 ~55 double_stone_slab 0
fill ~64 ~7 ~56 ~67 ~7 ~56 double_stone_slab 0
fill ~64 ~7 ~57 ~67 ~7 ~57 double_stone_slab 0
fill ~64 ~7 ~60 ~70 ~7 ~60 dirt 0
fill ~64 ~7 ~61 ~70 ~7 ~61 dirt 0
fill ~65 ~7 ~41 ~67 ~7 ~41 double_stone_slab 0
fill ~65 ~7 ~42 ~67 ~7 ~42 double_stone_slab 0
fill ~65 ~7 ~43 ~67 ~7 ~43 double_stone_slab 0
fill ~67 ~7 ~59 ~72 ~7 ~59 dirt 0
fill ~67 ~7 ~64 ~69 ~7 ~64 dirt 0
fill ~68 ~7 ~24 ~71 ~7 ~24 dirt 0
fill ~68 ~7 ~25 ~71 ~7 ~25 dirt 0
fill ~68 ~7 ~26 ~71 ~7 ~26 dirt 0
fill ~68 ~7 ~27 ~71 ~7 ~27 dirt 0
fill ~68 ~7 ~28 ~72 ~7 ~28 dirt 0
fill ~68 ~7 ~29 ~72 ~7 ~29 dirt 0
fill ~68 ~7 ~30 ~72 ~7 ~30 dirt 0
fill ~68 ~7 ~31 ~72 ~7 ~31 dirt 0
fill ~68 ~7 ~32 ~72 ~7 ~32 dirt 0
fill ~68 ~7 ~33 ~72 ~7 ~33 dirt 0
fill ~68 ~7 ~34 ~73 ~7 ~34 dirt 0
fill ~68 ~7 ~35 ~73 ~7 ~35 dirt 0
fill ~68 ~7 ~36 ~73 ~7 ~36 dirt 0
fill ~68 ~7 ~37 ~73 ~7 ~37 dirt 0
fill ~68 ~7 ~38 ~73 ~7 ~38 dirt 0
fill ~68 ~7 ~39 ~74 ~7 ~39 dirt 0
fill ~68 ~7 ~40 ~74 ~7 ~40 dirt 0
fill ~68 ~7 ~41 ~74 ~7 ~41 dirt 0
fill ~68 ~7 ~42 ~74 ~7 ~42 dirt 0
fill ~68 ~7 ~43 ~74 ~7 ~43 dirt 0
fill ~68 ~7 ~44 ~74 ~7 ~44 dirt 0
fill ~68 ~7 ~45 ~74 ~7 ~45 dirt 0
fill ~68 ~7 ~46 ~74 ~7 ~46 dirt 0
fill ~68 ~7 ~47 ~74 ~7 ~47 dirt 0
fill ~68 ~7 ~48 ~74 ~7 ~48 dirt 0
fill ~68 ~7 ~49 ~74 ~7 ~49 dirt 0
fill ~68 ~7 ~50 ~74 ~7 ~50 dirt 0
fill ~68 ~7 ~51 ~74 ~7 ~51 dirt 0
fill ~68 ~7 ~52 ~74 ~7 ~52 dirt 0
fill ~68 ~7 ~53 ~73 ~7 ~53 dirt 0
fill ~68 ~7 ~54 ~73 ~7 ~54 dirt 0
fill ~68 ~7 ~55 ~73 ~7 ~55 dirt 0
fill ~68 ~7 ~56 ~73 ~7 ~56 dirt 0
fill ~68 ~7 ~57 ~73 ~7 ~57 dirt 0
fill ~68 ~7 ~58 ~73 ~7 ~58 dirt 0
fill ~69 ~7 ~22 ~70 ~7 ~22 grass 0
fill ~69 ~7 ~62 ~70 ~7 ~62 dirt 0 
setblock ~70 ~7 ~23 grass 0
fill ~71 ~7 ~60 ~73 ~7 ~60 grass 0
fill ~71 ~7 ~61 ~72 ~7 ~61 grass 0
fill ~72 ~7 ~25 ~72 ~7 ~27 grass 0
fill ~73 ~7 ~27 ~73 ~7 ~33 grass 0 
setblock ~73 ~7 ~59 grass 0
fill ~74 ~7 ~34 ~74 ~7 ~38 grass 0
fill ~74 ~7 ~53 ~75 ~7 ~53 grass 0
fill ~74 ~7 ~54 ~74 ~7 ~58 grass 0
fill ~75 ~7 ~36 ~75 ~7 ~53 grass 0
fill ~76 ~7 ~37 ~76 ~7 ~39 grass 0
fill ~76 ~7 ~46 ~76 ~7 ~50 grass 0
fill ~24 ~8 ~21 ~24 ~8 ~26 grass 0
fill ~24 ~8 ~44 ~28 ~8 ~44 dirt 0
fill ~24 ~8 ~45 ~28 ~8 ~45 dirt 0
fill ~24 ~8 ~46 ~28 ~8 ~46 dirt 0
fill ~25 ~8 ~20 ~27 ~8 ~20 grass 0
fill ~25 ~8 ~21 ~27 ~8 ~21 dirt 0
fill ~25 ~8 ~22 ~27 ~8 ~22 dirt 0
fill ~25 ~8 ~23 ~29 ~8 ~23 dirt 0
fill ~25 ~8 ~24 ~35 ~8 ~24 dirt 0
fill ~25 ~8 ~25 ~29 ~8 ~25 dirt 0
fill ~25 ~8 ~26 ~28 ~8 ~26 dirt 0
fill ~25 ~8 ~27 ~25 ~8 ~28 grass 0
fill ~25 ~8 ~29 ~29 ~8 ~29 dirt 0
fill ~25 ~8 ~30 ~29 ~8 ~30 dirt 0
fill ~25 ~8 ~31 ~29 ~8 ~31 dirt 0
fill ~25 ~8 ~32 ~25 ~8 ~33 grass 0
fill ~25 ~8 ~34 ~29 ~8 ~34 dirt 0
fill ~25 ~8 ~35 ~29 ~8 ~35 dirt 0
fill ~25 ~8 ~36 ~29 ~8 ~36 dirt 0
fill ~25 ~8 ~39 ~29 ~8 ~39 dirt 0
fill ~25 ~8 ~40 ~29 ~8 ~40 dirt 0
fill ~25 ~8 ~41 ~29 ~8 ~41 dirt 0
fill ~25 ~8 ~43 ~27 ~8 ~43 dirt 0
fill ~25 ~8 ~47 ~27 ~8 ~47 dirt 0
fill ~25 ~8 ~50 ~29 ~8 ~50 dirt 0
fill ~25 ~8 ~51 ~29 ~8 ~51 dirt 0
fill ~25 ~8 ~52 ~29 ~8 ~52 dirt 0
fill ~25 ~8 ~56 ~29 ~8 ~56 dirt 0
fill ~25 ~8 ~57 ~29 ~8 ~57 dirt 0
fill ~25 ~8 ~58 ~25 ~7 ~58 dirt 0
fill ~26 ~8 ~27 ~27 ~8 ~27 dirt 0
fill ~26 ~8 ~28 ~28 ~8 ~28 dirt 0
fill ~26 ~8 ~32 ~28 ~8 ~32 dirt 0
fill ~26 ~8 ~33 ~28 ~8 ~33 dirt 0
fill ~26 ~8 ~38 ~28 ~8 ~38 dirt 0
fill ~26 ~8 ~42 ~28 ~8 ~42 dirt 0 
setblock ~26 ~8 ~48 grass 0
fill ~26 ~8 ~49 ~28 ~8 ~49 dirt 0
fill ~26 ~8 ~53 ~28 ~8 ~53 dirt 0
fill ~26 ~8 ~55 ~28 ~8 ~55 dirt 0
fill ~26 ~8 ~58 ~26 ~19 ~58 double_stone_slab 0
fill ~26 ~8 ~60 ~26 ~18 ~60 stone 0
fill ~26 ~8 ~61 ~26 ~18 ~61 stone 0
fill ~26 ~8 ~62 ~26 ~19 ~62 double_stone_slab 0
fill ~27 ~8 ~37 ~28 ~8 ~37 dirt 0
fill ~27 ~8 ~48 ~30 ~8 ~48 double_stone_slab 0
fill ~27 ~8 ~54 ~30 ~8 ~54 double_stone_slab 0
fill ~27 ~8 ~58 ~29 ~8 ~58 dirt 0
fill ~27 ~8 ~59 ~28 ~8 ~59 dirt 0
fill ~27 ~8 ~60 ~28 ~8 ~60 dirt 0
fill ~27 ~8 ~61 ~28 ~8 ~61 dirt 0
fill ~27 ~8 ~62 ~29 ~8 ~62 stone 0
fill ~28 ~8 ~21 ~28 ~8 ~22 grass 0
fill ~28 ~8 ~27 ~67 ~8 ~27 double_stone_slab 0
fill ~28 ~8 ~43 ~30 ~8 ~43 double_stone_slab 0
fill ~28 ~8 ~47 ~30 ~8 ~47 double_stone_slab 0
fill ~29 ~8 ~20 ~31 ~8 ~20 grass 0
fill ~29 ~8 ~21 ~31 ~8 ~21 dirt 0
fill ~29 ~8 ~22 ~34 ~8 ~22 dirt 0
fill ~29 ~8 ~26 ~31 ~8 ~26 double_stone_slab 0
fill ~29 ~8 ~28 ~30 ~8 ~28 double_stone_slab 0
fill ~29 ~8 ~32 ~30 ~8 ~32 double_stone_slab 0
fill ~29 ~8 ~33 ~30 ~8 ~33 double_stone_slab 0
fill ~29 ~8 ~37 ~30 ~8 ~37 double_stone_slab 0
fill ~29 ~8 ~38 ~30 ~8 ~38 double_stone_slab 0
fill ~29 ~8 ~42 ~30 ~8 ~42 double_stone_slab 0
fill ~29 ~8 ~44 ~30 ~8 ~44 double_stone_slab 0
fill ~29 ~8 ~45 ~30 ~8 ~45 double_stone_slab 0
fill ~29 ~8 ~46 ~30 ~8 ~46 double_stone_slab 0
fill ~29 ~8 ~49 ~30 ~8 ~49 double_stone_slab 0
fill ~29 ~8 ~53 ~30 ~8 ~53 double_stone_slab 0
fill ~29 ~8 ~55 ~30 ~8 ~55 double_stone_slab 0
fill ~29 ~8 ~59 ~37 ~8 ~59 double_stone_slab 0
fill ~29 ~8 ~60 ~29 ~18 ~60 double_stone_slab 0
fill ~29 ~8 ~61 ~29 ~18 ~61 double_stone_slab 0
fill ~30 ~8 ~23 ~30 ~19 ~23 double_stone_slab 0
fill ~30 ~8 ~25 ~30 ~14 ~25 double_stone_slab 0
fill ~30 ~8 ~58 ~66 ~8 ~58 double_stone_slab 0
fill ~31 ~8 ~23 ~35 ~8 ~23 dirt 0
fill ~31 ~8 ~25 ~35 ~8 ~25 dirt 0
fill ~31 ~8 ~33 ~31 ~11 ~33 stonebrick 1 
setblock ~31 ~8 ~36 stonebrick 2
