fill ~9 ~0 ~57 ~14 ~0 ~57 yellow_glazed_terracotta 0
fill ~9 ~0 ~58 ~9 ~0 ~59 yellow_glazed_terracotta 0
setblock ~9 ~0 ~60 sponge 0
fill ~9 ~0 ~61 ~14 ~0 ~61 yellow_glazed_terracotta 0
fill ~9 ~0 ~62 ~9 ~0 ~63 yellow_glazed_terracotta 0
setblock ~9 ~0 ~64 sponge 0
fill ~9 ~0 ~65 ~12 ~0 ~65 yellow_glazed_terracotta 0
setblock ~9 ~0 ~68 sponge 0
fill ~9 ~0 ~69 ~11 ~0 ~69 yellow_glazed_terracotta 0
fill ~9 ~0 ~71 ~10 ~0 ~71 yellow_glazed_terracotta 0
setblock ~9 ~0 ~72 sponge 0
fill ~9 ~0 ~73 ~10 ~0 ~73 yellow_glazed_terracotta 0
fill ~9 ~0 ~74 ~9 ~0 ~75 yellow_glazed_terracotta 0
fill ~10 ~0 ~55 ~14 ~0 ~55 yellow_glazed_terracotta 0
setblock ~10 ~0 ~56 glowstone 0
setblock ~10 ~0 ~58 glowstone 0
fill ~10 ~0 ~59 ~14 ~0 ~59 yellow_glazed_terracotta 0
setblock ~10 ~0 ~60 glowstone 0
setblock ~10 ~0 ~62 glowstone 0
fill ~10 ~0 ~63 ~13 ~0 ~63 yellow_glazed_terracotta 0
setblock ~10 ~0 ~64 glowstone 0
setblock ~10 ~0 ~66 glowstone 0
fill ~10 ~0 ~67 ~12 ~0 ~67 yellow_glazed_terracotta 0
setblock ~10 ~0 ~68 glowstone 0
setblock ~10 ~0 ~70 glowstone 0
setblock ~10 ~0 ~72 glowstone 0
fill ~11 ~0 ~53 ~14 ~0 ~53 yellow_glazed_terracotta 0
setblock ~11 ~0 ~54 sponge 0
setblock ~11 ~0 ~56 sponge 0
setblock ~11 ~0 ~58 sponge 0
setblock ~11 ~0 ~60 sponge 0
setblock ~11 ~0 ~62 sponge 0
setblock ~11 ~0 ~64 sponge 0
setblock ~11 ~0 ~66 sponge 0
setblock ~11 ~0 ~68 sponge 0
setblock ~11 ~0 ~70 sponge 0
setblock ~12 ~0 ~54 glowstone 0
setblock ~12 ~0 ~56 glowstone 0
setblock ~12 ~0 ~58 glowstone 0
setblock ~12 ~0 ~60 glowstone 0
setblock ~12 ~0 ~62 glowstone 0
setblock ~12 ~0 ~64 glowstone 0
setblock ~12 ~0 ~66 glowstone 0
setblock ~12 ~0 ~68 glowstone 0
setblock ~13 ~0 ~54 yellow_glazed_terracotta 0
setblock ~13 ~0 ~56 sponge 0
setblock ~13 ~0 ~58 yellow_glazed_terracotta 0
setblock ~13 ~0 ~60 sponge 0
setblock ~13 ~0 ~62 yellow_glazed_terracotta 0
setblock ~13 ~0 ~64 sponge 0
setblock ~14 ~0 ~54 glowstone 0
setblock ~14 ~0 ~56 glowstone 0
setblock ~14 ~0 ~58 glowstone 0
setblock ~14 ~0 ~60 glowstone 0
setblock ~19 ~0 ~34 sponge 0
fill ~19 ~0 ~35 ~28 ~0 ~35 yellow_glazed_terracotta 0
setblock ~19 ~0 ~36 sponge 0
fill ~19 ~0 ~37 ~26 ~0 ~37 yellow_glazed_terracotta 0
setblock ~20 ~0 ~32 glowstone 0
fill ~20 ~0 ~33 ~30 ~0 ~33 yellow_glazed_terracotta 0
setblock ~20 ~0 ~34 glowstone 0
setblock ~20 ~0 ~36 glowstone 0
setblock ~20 ~0 ~38 glowstone 0
fill ~20 ~0 ~39 ~23 ~0 ~39 yellow_glazed_terracotta 0
fill ~21 ~0 ~30 ~21 ~0 ~31 yellow_glazed_terracotta 0
setblock ~21 ~0 ~32 sponge 0
setblock ~21 ~0 ~34 yellow_glazed_terracotta 0
setblock ~21 ~0 ~36 sponge 0
setblock ~21 ~0 ~38 yellow_glazed_terracotta 0
fill ~22 ~0 ~29 ~32 ~0 ~29 yellow_glazed_terracotta 0
setblock ~22 ~0 ~30 glowstone 0
fill ~22 ~0 ~31 ~31 ~0 ~31 yellow_glazed_terracotta 0
setblock ~22 ~0 ~32 glowstone 0
setblock ~22 ~0 ~34 glowstone 0
setblock ~22 ~0 ~36 glowstone 0
setblock ~22 ~0 ~38 glowstone 0
setblock ~23 ~0 ~28 sponge 0
setblock ~23 ~0 ~30 sponge 0
setblock ~23 ~0 ~32 sponge 0
setblock ~23 ~0 ~34 sponge 0
setblock ~23 ~0 ~36 sponge 0
setblock ~23 ~0 ~38 sponge 0
setblock ~24 ~0 ~28 glowstone 0
setblock ~24 ~0 ~30 glowstone 0
setblock ~24 ~0 ~32 glowstone 0
setblock ~24 ~0 ~34 glowstone 0
setblock ~24 ~0 ~36 glowstone 0
setblock ~24 ~0 ~38 glowstone 0
fill ~25 ~0 ~27 ~32 ~0 ~27 yellow_glazed_terracotta 0
setblock ~25 ~0 ~28 sponge 0
setblock ~25 ~0 ~30 yellow_glazed_terracotta 0
setblock ~25 ~0 ~32 sponge 0
setblock ~25 ~0 ~34 yellow_glazed_terracotta 0
setblock ~25 ~0 ~36 sponge 0
setblock ~25 ~0 ~38 yellow_glazed_terracotta 0
setblock ~26 ~0 ~28 glowstone 0
setblock ~26 ~0 ~30 glowstone 0
setblock ~26 ~0 ~32 glowstone 0
setblock ~26 ~0 ~34 glowstone 0
setblock ~26 ~0 ~36 glowstone 0
setblock ~27 ~0 ~26 sponge 0
setblock ~27 ~0 ~28 sponge 0
setblock ~27 ~0 ~30 sponge 0
setblock ~27 ~0 ~32 sponge 0
setblock ~27 ~0 ~34 sponge 0
setblock ~27 ~0 ~36 sponge 0
setblock ~28 ~0 ~26 glowstone 0
setblock ~28 ~0 ~28 glowstone 0
setblock ~28 ~0 ~30 glowstone 0
setblock ~28 ~0 ~32 glowstone 0
setblock ~28 ~0 ~34 glowstone 0
setblock ~29 ~0 ~26 yellow_glazed_terracotta 0
setblock ~29 ~0 ~28 sponge 0
setblock ~29 ~0 ~30 yellow_glazed_terracotta 0
setblock ~29 ~0 ~32 sponge 0
setblock ~29 ~0 ~34 yellow_glazed_terracotta 0
setblock ~30 ~0 ~26 glowstone 0
setblock ~30 ~0 ~28 glowstone 0
setblock ~30 ~0 ~30 glowstone 0
setblock ~30 ~0 ~32 glowstone 0
setblock ~31 ~0 ~26 sponge 0
setblock ~31 ~0 ~28 sponge 0
setblock ~31 ~0 ~30 sponge 0
setblock ~31 ~0 ~32 sponge 0
setblock ~32 ~0 ~26 glowstone 0
setblock ~32 ~0 ~28 glowstone 0
setblock ~32 ~0 ~30 glowstone 0
fill ~5 ~1 ~75 ~5 ~1 ~81 yellow_glazed_terracotta 0
fill ~6 ~1 ~68 ~8 ~1 ~68 yellow_glazed_terracotta 0
setblock ~6 ~1 ~69 sponge 0
fill ~6 ~1 ~70 ~9 ~1 ~70 yellow_glazed_terracotta 0
setblock ~6 ~1 ~71 sponge 0
fill ~6 ~1 ~72 ~8 ~1 ~72 yellow_glazed_terracotta 0
setblock ~6 ~1 ~73 sponge 0
fill ~6 ~1 ~74 ~8 ~1 ~74 yellow_glazed_terracotta 0
setblock ~6 ~1 ~75 sponge 0
fill ~6 ~1 ~76 ~13 ~1 ~76 yellow_glazed_terracotta 0
setblock ~6 ~1 ~77 sponge 0
fill ~6 ~1 ~78 ~12 ~1 ~78 yellow_glazed_terracotta 0
setblock ~6 ~1 ~79 sponge 0
fill ~6 ~1 ~80 ~12 ~1 ~80 yellow_glazed_terracotta 0
setblock ~6 ~1 ~81 sponge 0
fill ~6 ~1 ~82 ~10 ~1 ~82 yellow_glazed_terracotta 0
setblock ~6 ~1 ~83 sponge 0
fill ~7 ~1 ~58 ~8 ~1 ~58 yellow_glazed_terracotta 0
fill ~7 ~1 ~59 ~7 ~1 ~84 yellow_glazed_terracotta 0
fill ~8 ~1 ~54 ~10 ~1 ~54 yellow_glazed_terracotta 0
setblock ~8 ~1 ~55 sponge 0
fill ~8 ~1 ~56 ~9 ~1 ~56 yellow_glazed_terracotta 0
setblock ~8 ~1 ~57 sponge 0
setblock ~8 ~1 ~59 sponge 0
setblock ~8 ~1 ~60 yellow_glazed_terracotta 0
setblock ~8 ~1 ~61 sponge 0
setblock ~8 ~1 ~62 yellow_glazed_terracotta 0
setblock ~8 ~1 ~63 sponge 0
setblock ~8 ~1 ~64 yellow_glazed_terracotta 0
setblock ~8 ~1 ~65 sponge 0
fill ~8 ~1 ~66 ~9 ~1 ~66 yellow_glazed_terracotta 0
setblock ~8 ~1 ~67 sponge 0
setblock ~8 ~1 ~69 sponge 0
setblock ~8 ~1 ~71 sponge 0
setblock ~8 ~1 ~73 sponge 0
setblock ~8 ~1 ~75 sponge 0
setblock ~8 ~1 ~77 sponge 0
setblock ~8 ~1 ~79 sponge 0
setblock ~8 ~1 ~81 sponge 0
setblock ~8 ~1 ~83 sponge 0
setblock ~8 ~1 ~84 yellow_glazed_terracotta 0
fill ~9 ~1 ~52 ~18 ~1 ~52 yellow_glazed_terracotta 0
fill ~9 ~1 ~53 ~9 ~1 ~52 yellow_glazed_terracotta 0
setblock ~9 ~1 ~55 yellow_glazed_terracotta 0
setblock ~9 ~1 ~67 yellow_glazed_terracotta 0
setblock ~9 ~1 ~77 yellow_glazed_terracotta 0
setblock ~9 ~1 ~79 yellow_glazed_terracotta 0
setblock ~9 ~1 ~81 yellow_glazed_terracotta 0
setblock ~9 ~1 ~83 yellow_glazed_terracotta 0
fill ~10 ~1 ~50 ~18 ~1 ~50 yellow_glazed_terracotta 0
setblock ~10 ~1 ~51 sponge 0
setblock ~10 ~1 ~53 sponge 0
fill ~10 ~1 ~74 ~14 ~1 ~74 yellow_glazed_terracotta 0
setblock ~10 ~1 ~75 sponge 0
setblock ~10 ~1 ~77 sponge 0
setblock ~10 ~1 ~79 sponge 0
setblock ~10 ~1 ~81 sponge 0
setblock ~11 ~1 ~49 yellow_glazed_terracotta 0
setblock ~11 ~1 ~51 yellow_glazed_terracotta 0
fill ~11 ~1 ~71 ~11 ~1 ~81 yellow_glazed_terracotta 0
fill ~12 ~1 ~48 ~18 ~1 ~48 yellow_glazed_terracotta 0
setblock ~12 ~1 ~49 sponge 0
setblock ~12 ~1 ~51 sponge 0
setblock ~12 ~1 ~69 sponge 0
fill ~12 ~1 ~70 ~15 ~1 ~70 yellow_glazed_terracotta 0
setblock ~12 ~1 ~71 sponge 0
fill ~12 ~1 ~72 ~14 ~1 ~72 yellow_glazed_terracotta 0
setblock ~12 ~1 ~73 sponge 0
setblock ~12 ~1 ~75 sponge 0
setblock ~12 ~1 ~77 sponge 0
setblock ~12 ~1 ~79 sponge 0
fill ~13 ~1 ~46 ~20 ~1 ~46 yellow_glazed_terracotta 0
fill ~13 ~1 ~47 ~13 ~1 ~46 yellow_glazed_terracotta 0
setblock ~13 ~1 ~49 yellow_glazed_terracotta 0
setblock ~13 ~1 ~51 yellow_glazed_terracotta 0
fill ~13 ~1 ~65 ~13 ~1 ~77 yellow_glazed_terracotta 0
setblock ~14 ~1 ~45 sponge 0
setblock ~14 ~1 ~47 sponge 0
setblock ~14 ~1 ~49 sponge 0
setblock ~14 ~1 ~51 sponge 0
fill ~14 ~1 ~62 ~17 ~1 ~62 yellow_glazed_terracotta 0
setblock ~14 ~1 ~63 sponge 0
fill ~14 ~1 ~64 ~17 ~1 ~64 yellow_glazed_terracotta 0
setblock ~14 ~1 ~65 sponge 0
fill ~14 ~1 ~66 ~16 ~1 ~66 yellow_glazed_terracotta 0
setblock ~14 ~1 ~67 sponge 0
fill ~14 ~1 ~68 ~16 ~1 ~68 yellow_glazed_terracotta 0
setblock ~14 ~1 ~69 sponge 0
setblock ~14 ~1 ~71 sponge 0
setblock ~14 ~1 ~73 sponge 0
fill ~15 ~1 ~40 ~26 ~1 ~40 yellow_glazed_terracotta 0
fill ~15 ~1 ~41 ~15 ~1 ~71 yellow_glazed_terracotta 0
setblock ~16 ~1 ~35 sponge 0
fill ~16 ~1 ~36 ~18 ~1 ~36 yellow_glazed_terracotta 0
setblock ~16 ~1 ~37 sponge 0
fill ~16 ~1 ~38 ~19 ~1 ~38 yellow_glazed_terracotta 0
setblock ~16 ~1 ~39 sponge 0
setblock ~16 ~1 ~41 sponge 0
fill ~16 ~1 ~42 ~24 ~1 ~42 yellow_glazed_terracotta 0
setblock ~16 ~1 ~43 sponge 0
fill ~16 ~1 ~44 ~21 ~1 ~44 yellow_glazed_terracotta 0
setblock ~16 ~1 ~45 sponge 0
setblock ~16 ~1 ~47 sponge 0
setblock ~16 ~1 ~49 sponge 0
setblock ~16 ~1 ~51 sponge 0
setblock ~16 ~1 ~53 sponge 0
fill ~16 ~1 ~54 ~18 ~1 ~54 yellow_glazed_terracotta 0
setblock ~16 ~1 ~55 sponge 0
fill ~16 ~1 ~56 ~18 ~1 ~56 yellow_glazed_terracotta 0
setblock ~16 ~1 ~57 sponge 0
fill ~16 ~1 ~58 ~17 ~1 ~58 yellow_glazed_terracotta 0
setblock ~16 ~1 ~59 sponge 0
fill ~16 ~1 ~60 ~17 ~1 ~60 yellow_glazed_terracotta 0
setblock ~16 ~1 ~61 sponge 0
setblock ~16 ~1 ~63 sponge 0
setblock ~16 ~1 ~65 sponge 0
setblock ~16 ~1 ~67 sponge 0
fill ~17 ~1 ~33 ~17 ~1 ~64 yellow_glazed_terracotta 0
setblock ~18 ~1 ~31 sponge 0
fill ~18 ~1 ~32 ~19 ~1 ~32 yellow_glazed_terracotta 0
setblock ~18 ~1 ~33 sponge 0
setblock ~18 ~1 ~34 yellow_glazed_terracotta 0
setblock ~18 ~1 ~35 sponge 0
setblock ~18 ~1 ~37 sponge 0
setblock ~18 ~1 ~39 sponge 0
setblock ~18 ~1 ~41 sponge 0
setblock ~18 ~1 ~43 sponge 0
setblock ~18 ~1 ~45 sponge 0
setblock ~18 ~1 ~47 sponge 0
setblock ~18 ~1 ~49 sponge 0
setblock ~18 ~1 ~51 sponge 0
setblock ~18 ~1 ~53 sponge 0
setblock ~18 ~1 ~55 sponge 0
fill ~19 ~1 ~30 ~20 ~1 ~30 yellow_glazed_terracotta 0
fill ~19 ~1 ~31 ~19 ~1 ~30 yellow_glazed_terracotta 0
setblock ~19 ~1 ~33 yellow_glazed_terracotta 0
setblock ~19 ~1 ~39 yellow_glazed_terracotta 0
setblock ~19 ~1 ~41 yellow_glazed_terracotta 0
setblock ~19 ~1 ~43 yellow_glazed_terracotta 0
setblock ~19 ~1 ~45 yellow_glazed_terracotta 0
setblock ~19 ~1 ~47 yellow_glazed_terracotta 0
setblock ~20 ~1 ~29 sponge 0
setblock ~20 ~1 ~31 sponge 0
setblock ~20 ~1 ~41 sponge 0
setblock ~20 ~1 ~43 sponge 0
setblock ~20 ~1 ~45 sponge 0
fill ~21 ~1 ~28 ~22 ~1 ~28 yellow_glazed_terracotta 0
fill ~21 ~1 ~29 ~21 ~1 ~28 yellow_glazed_terracotta 0
setblock ~21 ~1 ~41 yellow_glazed_terracotta 0
setblock ~21 ~1 ~43 yellow_glazed_terracotta 0
setblock ~22 ~1 ~27 sponge 0
setblock ~22 ~1 ~41 sponge 0
setblock ~22 ~1 ~43 sponge 0
fill ~23 ~1 ~26 ~26 ~1 ~26 yellow_glazed_terracotta 0
fill ~23 ~1 ~27 ~23 ~1 ~26 yellow_glazed_terracotta 0
setblock ~23 ~1 ~41 yellow_glazed_terracotta 0
setblock ~23 ~1 ~43 yellow_glazed_terracotta 0
setblock ~24 ~1 ~25 sponge 0
setblock ~24 ~1 ~27 sponge 0
setblock ~24 ~1 ~39 sponge 0
setblock ~24 ~1 ~41 sponge 0
setblock ~25 ~1 ~25 yellow_glazed_terracotta 0
setblock ~25 ~1 ~39 yellow_glazed_terracotta 0
setblock ~25 ~1 ~41 yellow_glazed_terracotta 0
fill ~26 ~1 ~24 ~36 ~1 ~24 yellow_glazed_terracotta 0
setblock ~26 ~1 ~25 sponge 0
fill ~26 ~1 ~38 ~29 ~1 ~38 yellow_glazed_terracotta 0
setblock ~26 ~1 ~39 sponge 0
setblock ~27 ~1 ~25 yellow_glazed_terracotta 0
setblock ~27 ~1 ~37 yellow_glazed_terracotta 0
setblock ~27 ~1 ~39 yellow_glazed_terracotta 0
setblock ~28 ~1 ~23 sponge 0
setblock ~28 ~1 ~25 sponge 0
fill ~28 ~1 ~36 ~31 ~1 ~36 yellow_glazed_terracotta 0
setblock ~28 ~1 ~37 sponge 0
setblock ~28 ~1 ~39 sponge 0
setblock ~29 ~1 ~23 yellow_glazed_terracotta 0
setblock ~29 ~1 ~25 yellow_glazed_terracotta 0
setblock ~29 ~1 ~35 yellow_glazed_terracotta 0
setblock ~29 ~1 ~37 yellow_glazed_terracotta 0
setblock ~30 ~1 ~23 sponge 0
setblock ~30 ~1 ~25 sponge 0
fill ~30 ~1 ~34 ~32 ~1 ~34 yellow_glazed_terracotta 0
setblock ~30 ~1 ~35 sponge 0
setblock ~30 ~1 ~37 sponge 0
fill ~31 ~1 ~22 ~34 ~1 ~22 yellow_glazed_terracotta 0
fill ~31 ~1 ~23 ~31 ~1 ~22 yellow_glazed_terracotta 0
setblock ~31 ~1 ~25 yellow_glazed_terracotta 0
setblock ~31 ~1 ~33 yellow_glazed_terracotta 0
setblock ~31 ~1 ~35 yellow_glazed_terracotta 0
setblock ~32 ~1 ~23 sponge 0
setblock ~32 ~1 ~25 sponge 0
setblock ~32 ~1 ~31 sponge 0
fill ~32 ~1 ~32 ~34 ~1 ~32 yellow_glazed_terracotta 0
setblock ~32 ~1 ~33 sponge 0
setblock ~33 ~1 ~23 yellow_glazed_terracotta 0
fill ~33 ~1 ~25 ~33 ~1 ~33 yellow_glazed_terracotta 0
setblock ~34 ~1 ~23 sponge 0
setblock ~34 ~1 ~25 sponge 0
fill ~34 ~1 ~26 ~36 ~1 ~26 yellow_glazed_terracotta 0
setblock ~34 ~1 ~27 sponge 0
fill ~34 ~1 ~28 ~36 ~1 ~28 yellow_glazed_terracotta 0
setblock ~34 ~1 ~29 sponge 0
fill ~34 ~1 ~30 ~35 ~1 ~30 yellow_glazed_terracotta 0
setblock ~34 ~1 ~31 sponge 0
setblock ~35 ~1 ~23 yellow_glazed_terracotta 0
setblock ~35 ~1 ~25 yellow_glazed_terracotta 0
setblock ~35 ~1 ~27 yellow_glazed_terracotta 0
setblock ~35 ~1 ~29 yellow_glazed_terracotta 0
setblock ~36 ~1 ~23 sponge 0
setblock ~36 ~1 ~25 sponge 0
setblock ~36 ~1 ~27 sponge 0
setblock ~4 ~2 ~72 glowstone 0
fill ~4 ~2 ~73 ~5 ~2 ~73 yellow_glazed_terracotta 0
setblock ~4 ~2 ~74 glowstone 0
setblock ~4 ~2 ~75 yellow_glazed_terracotta 0
setblock ~4 ~2 ~76 glowstone 0
setblock ~4 ~2 ~77 yellow_glazed_terracotta 0
setblock ~4 ~2 ~78 glowstone 0
setblock ~4 ~2 ~79 yellow_glazed_terracotta 0
setblock ~4 ~2 ~80 glowstone 0
setblock ~4 ~2 ~81 yellow_glazed_terracotta 0
setblock ~4 ~2 ~82 glowstone 0
fill ~4 ~2 ~83 ~5 ~2 ~83 yellow_glazed_terracotta 0
fill ~5 ~2 ~64 ~5 ~2 ~74 yellow_glazed_terracotta 0
setblock ~5 ~2 ~82 yellow_glazed_terracotta 0
fill ~5 ~2 ~84 ~5 ~2 ~85 yellow_glazed_terracotta 0
setblock ~6 ~2 ~56 glowstone 0
fill ~6 ~2 ~57 ~7 ~2 ~57 yellow_glazed_terracotta 0
setblock ~6 ~2 ~58 glowstone 0
setblock ~6 ~2 ~59 yellow_glazed_terracotta 0
setblock ~6 ~2 ~60 glowstone 0
setblock ~6 ~2 ~61 yellow_glazed_terracotta 0
setblock ~6 ~2 ~62 glowstone 0
setblock ~6 ~2 ~63 yellow_glazed_terracotta 0
setblock ~6 ~2 ~64 glowstone 0
setblock ~6 ~2 ~65 yellow_glazed_terracotta 0
setblock ~6 ~2 ~66 glowstone 0
setblock ~6 ~2 ~67 yellow_glazed_terracotta 0
setblock ~6 ~2 ~84 glowstone 0
fill ~6 ~2 ~85 ~12 ~2 ~85 yellow_glazed_terracotta 0
setblock ~6 ~2 ~86 glowstone 0
fill ~7 ~2 ~53 ~8 ~2 ~53 yellow_glazed_terracotta 0
setblock ~7 ~2 ~54 sponge 0
fill ~7 ~2 ~55 ~7 ~2 ~57 yellow_glazed_terracotta 0
setblock ~7 ~2 ~86 sponge 0
fill ~7 ~2 ~87 ~11 ~2 ~87 yellow_glazed_terracotta 0
fill ~8 ~2 ~51 ~9 ~2 ~51 yellow_glazed_terracotta 0
setblock ~8 ~2 ~52 glowstone 0
setblock ~8 ~2 ~86 glowstone 0
fill ~9 ~2 ~49 ~10 ~2 ~49 yellow_glazed_terracotta 0
fill ~9 ~2 ~50 ~9 ~2 ~49 yellow_glazed_terracotta 0
setblock ~9 ~2 ~84 yellow_glazed_terracotta 0
setblock ~9 ~2 ~86 yellow_glazed_terracotta 0
fill ~10 ~2 ~47 ~12 ~2 ~47 yellow_glazed_terracotta 0
setblock ~10 ~2 ~48 glowstone 0
fill ~10 ~2 ~83 ~13 ~2 ~83 yellow_glazed_terracotta 0
setblock ~10 ~2 ~84 glowstone 0
setblock ~10 ~2 ~86 glowstone 0
fill ~11 ~2 ~45 ~13 ~2 ~45 yellow_glazed_terracotta 0
setblock ~11 ~2 ~46 sponge 0
setblock ~11 ~2 ~48 yellow_glazed_terracotta 0
setblock ~11 ~2 ~82 sponge 0
setblock ~11 ~2 ~84 yellow_glazed_terracotta 0
setblock ~11 ~2 ~86 sponge 0
setblock ~12 ~2 ~44 glowstone 0
setblock ~12 ~2 ~46 glowstone 0
fill ~12 ~2 ~81 ~14 ~2 ~81 yellow_glazed_terracotta 0
setblock ~12 ~2 ~82 glowstone 0
setblock ~12 ~2 ~84 glowstone 0
setblock ~12 ~2 ~86 glowstone 0
fill ~13 ~2 ~41 ~14 ~2 ~41 yellow_glazed_terracotta 0
fill ~13 ~2 ~42 ~13 ~2 ~45 yellow_glazed_terracotta 0
fill ~13 ~2 ~78 ~13 ~2 ~84 yellow_glazed_terracotta 0
fill ~14 ~2 ~37 ~15 ~2 ~37 yellow_glazed_terracotta 0
setblock ~14 ~2 ~38 glowstone 0
fill ~14 ~2 ~39 ~15 ~2 ~39 yellow_glazed_terracotta 0
setblock ~14 ~2 ~40 glowstone 0
setblock ~14 ~2 ~42 glowstone 0
setblock ~14 ~2 ~43 yellow_glazed_terracotta 0
setblock ~14 ~2 ~44 glowstone 0
fill ~14 ~2 ~75 ~16 ~2 ~75 yellow_glazed_terracotta 0
setblock ~14 ~2 ~76 glowstone 0
fill ~14 ~2 ~77 ~16 ~2 ~77 yellow_glazed_terracotta 0
setblock ~14 ~2 ~78 glowstone 0
fill ~14 ~2 ~79 ~15 ~2 ~79 yellow_glazed_terracotta 0
setblock ~14 ~2 ~80 glowstone 0
setblock ~14 ~2 ~82 glowstone 0
setblock ~15 ~2 ~34 sponge 0
fill ~15 ~2 ~35 ~15 ~2 ~37 yellow_glazed_terracotta 0
setblock ~15 ~2 ~38 sponge 0
fill ~15 ~2 ~72 ~15 ~2 ~73 yellow_glazed_terracotta 0
setblock ~15 ~2 ~74 sponge 0
setblock ~15 ~2 ~76 yellow_glazed_terracotta 0
setblock ~15 ~2 ~78 sponge 0
setblock ~15 ~2 ~80 yellow_glazed_terracotta 0
setblock ~16 ~2 ~32 glowstone 0
setblock ~16 ~2 ~33 yellow_glazed_terracotta 0
setblock ~16 ~2 ~34 glowstone 0
fill ~16 ~2 ~69 ~19 ~2 ~69 yellow_glazed_terracotta 0
setblock ~16 ~2 ~70 glowstone 0
fill ~16 ~2 ~71 ~18 ~2 ~71 yellow_glazed_terracotta 0
setblock ~16 ~2 ~72 glowstone 0
fill ~16 ~2 ~73 ~17 ~2 ~73 yellow_glazed_terracotta 0
setblock ~16 ~2 ~74 glowstone 0
setblock ~16 ~2 ~76 glowstone 0
fill ~17 ~2 ~30 ~17 ~2 ~32 yellow_glazed_terracotta 0
fill ~17 ~2 ~65 ~19 ~2 ~65 yellow_glazed_terracotta 0
fill ~17 ~2 ~66 ~17 ~2 ~74 yellow_glazed_terracotta 0
fill ~18 ~2 ~29 ~19 ~2 ~29 yellow_glazed_terracotta 0
setblock ~18 ~2 ~30 glowstone 0
fill ~18 ~2 ~57 ~20 ~2 ~57 yellow_glazed_terracotta 0
setblock ~18 ~2 ~58 glowstone 0
fill ~18 ~2 ~59 ~20 ~2 ~59 yellow_glazed_terracotta 0
setblock ~18 ~2 ~60 glowstone 0
fill ~18 ~2 ~61 ~20 ~2 ~61 yellow_glazed_terracotta 0
setblock ~18 ~2 ~62 glowstone 0
fill ~18 ~2 ~63 ~20 ~2 ~63 yellow_glazed_terracotta 0
setblock ~18 ~2 ~64 glowstone 0
setblock ~18 ~2 ~66 glowstone 0
fill ~18 ~2 ~67 ~19 ~2 ~67 yellow_glazed_terracotta 0
setblock ~18 ~2 ~68 glowstone 0
setblock ~18 ~2 ~70 glowstone 0
setblock ~18 ~2 ~72 glowstone 0
setblock ~19 ~2 ~28 yellow_glazed_terracotta 0
fill ~19 ~2 ~48 ~19 ~2 ~49 yellow_glazed_terracotta 0
setblock ~19 ~2 ~50 sponge 0
fill ~19 ~2 ~51 ~21 ~2 ~51 yellow_glazed_terracotta 0
fill ~19 ~2 ~52 ~19 ~2 ~53 yellow_glazed_terracotta 0
setblock ~19 ~2 ~54 sponge 0
fill ~19 ~2 ~55 ~20 ~2 ~55 yellow_glazed_terracotta 0
fill ~19 ~2 ~56 ~19 ~2 ~55 yellow_glazed_terracotta 0
setblock ~19 ~2 ~58 sponge 0
setblock ~19 ~2 ~60 yellow_glazed_terracotta 0
setblock ~19 ~2 ~62 sponge 0
setblock ~19 ~2 ~64 yellow_glazed_terracotta 0
setblock ~19 ~2 ~66 sponge 0
setblock ~19 ~2 ~68 yellow_glazed_terracotta 0
fill ~20 ~2 ~27 ~21 ~2 ~27 yellow_glazed_terracotta 0
setblock ~20 ~2 ~28 glowstone 0
fill ~20 ~2 ~47 ~23 ~2 ~47 yellow_glazed_terracotta 0
setblock ~20 ~2 ~48 glowstone 0
fill ~20 ~2 ~49 ~21 ~2 ~49 yellow_glazed_terracotta 0
setblock ~20 ~2 ~50 glowstone 0
setblock ~20 ~2 ~52 glowstone 0
setblock ~20 ~2 ~53 yellow_glazed_terracotta 0
setblock ~20 ~2 ~54 glowstone 0
setblock ~20 ~2 ~56 glowstone 0
setblock ~20 ~2 ~58 glowstone 0
setblock ~20 ~2 ~60 glowstone 0
setblock ~20 ~2 ~62 glowstone 0
setblock ~20 ~2 ~64 glowstone 0
setblock ~21 ~2 ~26 yellow_glazed_terracotta 0
fill ~21 ~2 ~45 ~24 ~2 ~45 yellow_glazed_terracotta 0
fill ~21 ~2 ~46 ~21 ~2 ~45 yellow_glazed_terracotta 0
setblock ~21 ~2 ~48 yellow_glazed_terracotta 0
setblock ~21 ~2 ~50 yellow_glazed_terracotta 0
fill ~22 ~2 ~25 ~23 ~2 ~25 yellow_glazed_terracotta 0
setblock ~22 ~2 ~26 glowstone 0
setblock ~22 ~2 ~44 glowstone 0
setblock ~22 ~2 ~46 glowstone 0
setblock ~22 ~2 ~48 glowstone 0
setblock ~23 ~2 ~24 yellow_glazed_terracotta 0
setblock ~23 ~2 ~44 yellow_glazed_terracotta 0
setblock ~23 ~2 ~46 sponge 0
setblock ~24 ~2 ~24 glowstone 0
fill ~24 ~2 ~43 ~26 ~2 ~43 yellow_glazed_terracotta 0
setblock ~24 ~2 ~44 glowstone 0
fill ~25 ~2 ~23 ~27 ~2 ~23 yellow_glazed_terracotta 0
fill ~25 ~2 ~24 ~25 ~2 ~23 yellow_glazed_terracotta 0
setblock ~25 ~2 ~42 yellow_glazed_terracotta 0
setblock ~25 ~2 ~44 yellow_glazed_terracotta 0
setblock ~26 ~2 ~22 glowstone 0
fill ~26 ~2 ~41 ~28 ~2 ~41 yellow_glazed_terracotta 0
setblock ~26 ~2 ~42 glowstone 0
setblock ~27 ~2 ~22 sponge 0
setblock ~27 ~2 ~40 yellow_glazed_terracotta 0
setblock ~27 ~2 ~42 sponge 0
fill ~28 ~2 ~21 ~40 ~2 ~21 yellow_glazed_terracotta 0
setblock ~28 ~2 ~22 glowstone 0
setblock ~28 ~2 ~40 glowstone 0
setblock ~29 ~2 ~22 yellow_glazed_terracotta 0
fill ~29 ~2 ~39 ~30 ~2 ~39 yellow_glazed_terracotta 0
fill ~29 ~2 ~40 ~29 ~2 ~39 yellow_glazed_terracotta 0
setblock ~30 ~2 ~22 glowstone 0
setblock ~30 ~2 ~38 glowstone 0
setblock ~30 ~2 ~40 glowstone 0
setblock ~31 ~2 ~20 yellow_glazed_terracotta 0
fill ~31 ~2 ~37 ~32 ~2 ~37 yellow_glazed_terracotta 0
setblock ~31 ~2 ~38 sponge 0
setblock ~32 ~2 ~20 glowstone 0
fill ~32 ~2 ~35 ~34 ~2 ~35 yellow_glazed_terracotta 0
setblock ~32 ~2 ~36 glowstone 0
setblock ~33 ~2 ~20 yellow_glazed_terracotta 0
setblock ~33 ~2 ~34 yellow_glazed_terracotta 0
setblock ~33 ~2 ~36 yellow_glazed_terracotta 0
fill ~34 ~2 ~19 ~38 ~2 ~19 yellow_glazed_terracotta 0
setblock ~34 ~2 ~20 glowstone 0
fill ~34 ~2 ~33 ~35 ~2 ~33 yellow_glazed_terracotta 0
setblock ~34 ~2 ~34 glowstone 0
setblock ~35 ~2 ~20 yellow_glazed_terracotta 0
setblock ~35 ~2 ~22 sponge 0
fill ~35 ~2 ~31 ~36 ~2 ~31 yellow_glazed_terracotta 0
fill ~35 ~2 ~32 ~35 ~2 ~31 yellow_glazed_terracotta 0
setblock ~36 ~2 ~20 glowstone 0
setblock ~36 ~2 ~22 glowstone 0
fill ~36 ~2 ~29 ~38 ~2 ~29 yellow_glazed_terracotta 0
setblock ~36 ~2 ~30 glowstone 0
setblock ~36 ~2 ~32 glowstone 0
setblock ~37 ~2 ~20 yellow_glazed_terracotta 0
fill ~37 ~2 ~22 ~37 ~2 ~30 yellow_glazed_terracotta 0
setblock ~38 ~2 ~20 glowstone 0
setblock ~38 ~2 ~22 glowstone 0
fill ~38 ~2 ~23 ~40 ~2 ~23 yellow_glazed_terracotta 0
setblock ~38 ~2 ~24 glowstone 0
fill ~38 ~2 ~25 ~40 ~2 ~25 yellow_glazed_terracotta 0
setblock ~38 ~2 ~26 glowstone 0
fill ~38 ~2 ~27 ~39 ~2 ~27 yellow_glazed_terracotta 0
setblock ~38 ~2 ~28 glowstone 0
setblock ~39 ~2 ~20 yellow_glazed_terracotta 0
setblock ~39 ~2 ~22 sponge 0
setblock ~39 ~2 ~24 yellow_glazed_terracotta 0
setblock ~39 ~2 ~26 sponge 0
setblock ~40 ~2 ~20 glowstone 0
setblock ~40 ~2 ~22 glowstone 0
setblock ~40 ~2 ~24 glowstone 0
fill ~3 ~3 ~72 ~3 ~3 ~83 yellow_glazed_terracotta 0
setblock ~4 ~3 ~64 yellow_glazed_terracotta 0
setblock ~4 ~3 ~65 sponge 0
setblock ~4 ~3 ~66 yellow_glazed_terracotta 0
setblock ~4 ~3 ~67 glowstone 0
setblock ~4 ~3 ~68 yellow_glazed_terracotta 0
setblock ~4 ~3 ~69 glowstone 0
setblock ~4 ~3 ~70 yellow_glazed_terracotta 0
setblock ~4 ~3 ~71 sponge 0
setblock ~4 ~3 ~84 yellow_glazed_terracotta 0
setblock ~4 ~3 ~85 glowstone 0
fill ~5 ~3 ~56 ~5 ~3 ~63 yellow_glazed_terracotta 0
fill ~5 ~3 ~86 ~5 ~3 ~87 yellow_glazed_terracotta 0
setblock ~6 ~3 ~53 sponge 0
setblock ~6 ~3 ~54 yellow_glazed_terracotta 0
setblock ~6 ~3 ~55 sponge 0
setblock ~6 ~3 ~87 sponge 0
fill ~6 ~3 ~88 ~14 ~3 ~88 yellow_glazed_terracotta 0
fill ~7 ~3 ~50 ~8 ~3 ~50 yellow_glazed_terracotta 0
fill ~7 ~3 ~51 ~7 ~3 ~52 yellow_glazed_terracotta 0
setblock ~7 ~3 ~89 yellow_glazed_terracotta 0
setblock ~8 ~3 ~49 sponge 0
setblock ~8 ~3 ~89 glowstone 0
fill ~8 ~3 ~90 ~13 ~3 ~90 yellow_glazed_terracotta 0
fill ~9 ~3 ~46 ~10 ~3 ~46 yellow_glazed_terracotta 0
fill ~9 ~3 ~47 ~9 ~3 ~48 yellow_glazed_terracotta 0
setblock ~9 ~3 ~89 yellow_glazed_terracotta 0
setblock ~10 ~3 ~45 sponge 0
setblock ~10 ~3 ~89 sponge 0
fill ~11 ~3 ~43 ~11 ~3 ~44 yellow_glazed_terracotta 0
setblock ~11 ~3 ~89 yellow_glazed_terracotta 0
setblock ~11 ~3 ~91 yellow_glazed_terracotta 0
fill ~12 ~3 ~40 ~13 ~3 ~40 yellow_glazed_terracotta 0
setblock ~12 ~3 ~41 sponge 0
setblock ~12 ~3 ~42 yellow_glazed_terracotta 0
setblock ~12 ~3 ~43 glowstone 0
setblock ~12 ~3 ~87 sponge 0
setblock ~12 ~3 ~89 glowstone 0
fill ~13 ~3 ~36 ~14 ~3 ~36 yellow_glazed_terracotta 0
fill ~13 ~3 ~37 ~13 ~3 ~40 yellow_glazed_terracotta 0
fill ~13 ~3 ~85 ~13 ~3 ~90 yellow_glazed_terracotta 0
setblock ~14 ~3 ~34 yellow_glazed_terracotta 0
setblock ~14 ~3 ~35 sponge 0
setblock ~14 ~3 ~83 sponge 0
fill ~14 ~3 ~84 ~16 ~3 ~84 yellow_glazed_terracotta 0
setblock ~14 ~3 ~85 sponge 0
fill ~14 ~3 ~86 ~15 ~3 ~86 yellow_glazed_terracotta 0
setblock ~14 ~3 ~87 sponge 0
setblock ~14 ~3 ~89 sponge 0
fill ~15 ~3 ~32 ~15 ~3 ~33 yellow_glazed_terracotta 0
fill ~15 ~3 ~81 ~15 ~3 ~87 yellow_glazed_terracotta 0
setblock ~16 ~3 ~30 yellow_glazed_terracotta 0
setblock ~16 ~3 ~31 glowstone 0
fill ~16 ~3 ~78 ~19 ~3 ~78 yellow_glazed_terracotta 0
setblock ~16 ~3 ~79 sponge 0
fill ~16 ~3 ~80 ~18 ~3 ~80 yellow_glazed_terracotta 0
setblock ~16 ~3 ~81 glowstone 0
fill ~16 ~3 ~82 ~17 ~3 ~82 yellow_glazed_terracotta 0
setblock ~16 ~3 ~83 sponge 0
setblock ~17 ~3 ~29 yellow_glazed_terracotta 0
fill ~17 ~3 ~75 ~17 ~3 ~82 yellow_glazed_terracotta 0
setblock ~18 ~3 ~28 yellow_glazed_terracotta 0
setblock ~18 ~3 ~73 sponge 0
fill ~18 ~3 ~74 ~21 ~3 ~74 yellow_glazed_terracotta 0
setblock ~18 ~3 ~75 sponge 0
fill ~18 ~3 ~76 ~20 ~3 ~76 yellow_glazed_terracotta 0
setblock ~18 ~3 ~77 sponge 0
setblock ~18 ~3 ~79 sponge 0
setblock ~19 ~3 ~27 yellow_glazed_terracotta 0
fill ~19 ~3 ~70 ~22 ~3 ~70 yellow_glazed_terracotta 0
fill ~19 ~3 ~71 ~19 ~3 ~78 yellow_glazed_terracotta 0
setblock ~20 ~3 ~26 yellow_glazed_terracotta 0
setblock ~20 ~3 ~65 sponge 0
fill ~20 ~3 ~66 ~23 ~3 ~66 yellow_glazed_terracotta 0
setblock ~20 ~3 ~67 glowstone 0
fill ~20 ~3 ~68 ~23 ~3 ~68 yellow_glazed_terracotta 0
setblock ~20 ~3 ~69 glowstone 0
setblock ~20 ~3 ~71 sponge 0
fill ~20 ~3 ~72 ~21 ~3 ~72 yellow_glazed_terracotta 0
setblock ~20 ~3 ~73 glowstone 0
setblock ~20 ~3 ~75 sponge 0
setblock ~21 ~3 ~25 yellow_glazed_terracotta 0
fill ~21 ~3 ~52 ~24 ~3 ~52 yellow_glazed_terracotta 0
fill ~21 ~3 ~53 ~21 ~3 ~74 yellow_glazed_terracotta 0
setblock ~22 ~3 ~24 yellow_glazed_terracotta 0
setblock ~22 ~3 ~49 sponge 0
fill ~22 ~3 ~50 ~24 ~3 ~50 yellow_glazed_terracotta 0
setblock ~22 ~3 ~51 sponge 0
setblock ~22 ~3 ~53 sponge 0
fill ~22 ~3 ~54 ~23 ~3 ~54 yellow_glazed_terracotta 0
setblock ~22 ~3 ~55 sponge 0
fill ~22 ~3 ~56 ~23 ~3 ~56 yellow_glazed_terracotta 0
setblock ~22 ~3 ~57 sponge 0
fill ~22 ~3 ~58 ~23 ~3 ~58 yellow_glazed_terracotta 0
setblock ~22 ~3 ~59 sponge 0
fill ~22 ~3 ~60 ~23 ~3 ~60 yellow_glazed_terracotta 0
setblock ~22 ~3 ~61 sponge 0
fill ~22 ~3 ~62 ~23 ~3 ~62 yellow_glazed_terracotta 0
setblock ~22 ~3 ~63 sponge 0
fill ~22 ~3 ~64 ~23 ~3 ~64 yellow_glazed_terracotta 0
setblock ~22 ~3 ~65 sponge 0
setblock ~22 ~3 ~67 sponge 0
setblock ~22 ~3 ~69 sponge 0
setblock ~22 ~3 ~71 sponge 0
setblock ~23 ~3 ~23 yellow_glazed_terracotta 0
fill ~23 ~3 ~48 ~25 ~3 ~48 yellow_glazed_terracotta 0
fill ~23 ~3 ~49 ~23 ~3 ~48 yellow_glazed_terracotta 0
setblock ~23 ~3 ~51 yellow_glazed_terracotta 0
setblock ~23 ~3 ~53 yellow_glazed_terracotta 0
setblock ~23 ~3 ~55 yellow_glazed_terracotta 0
setblock ~23 ~3 ~57 yellow_glazed_terracotta 0
setblock ~23 ~3 ~59 yellow_glazed_terracotta 0
setblock ~23 ~3 ~61 yellow_glazed_terracotta 0
setblock ~23 ~3 ~63 yellow_glazed_terracotta 0
setblock ~23 ~3 ~65 yellow_glazed_terracotta 0
setblock ~23 ~3 ~67 yellow_glazed_terracotta 0
fill ~24 ~3 ~22 ~25 ~3 ~22 yellow_glazed_terracotta 0
setblock ~24 ~3 ~23 glowstone 0
fill ~24 ~3 ~46 ~27 ~3 ~46 yellow_glazed_terracotta 0
setblock ~24 ~3 ~47 glowstone 0
setblock ~24 ~3 ~49 sponge 0
setblock ~24 ~3 ~51 glowstone 0
setblock ~25 ~3 ~45 yellow_glazed_terracotta 0
setblock ~25 ~3 ~47 yellow_glazed_terracotta 0
setblock ~26 ~3 ~21 sponge 0
fill ~26 ~3 ~44 ~28 ~3 ~44 yellow_glazed_terracotta 0
setblock ~26 ~3 ~45 sponge 0
setblock ~26 ~3 ~47 sponge 0
fill ~27 ~3 ~20 ~30 ~3 ~20 yellow_glazed_terracotta 0
fill ~27 ~3 ~21 ~27 ~3 ~20 yellow_glazed_terracotta 0
setblock ~27 ~3 ~43 yellow_glazed_terracotta 0
setblock ~27 ~3 ~45 yellow_glazed_terracotta 0
fill ~28 ~3 ~42 ~30 ~3 ~42 yellow_glazed_terracotta 0
setblock ~28 ~3 ~43 glowstone 0
setblock ~29 ~3 ~41 yellow_glazed_terracotta 0
setblock ~29 ~3 ~43 yellow_glazed_terracotta 0
setblock ~30 ~3 ~19 sponge 0
setblock ~30 ~3 ~41 sponge 0
fill ~31 ~3 ~18 ~44 ~3 ~18 yellow_glazed_terracotta 0
fill ~31 ~3 ~19 ~31 ~3 ~18 yellow_glazed_terracotta 0
fill ~31 ~3 ~39 ~31 ~3 ~41 yellow_glazed_terracotta 0
setblock ~32 ~3 ~19 glowstone 0
fill ~32 ~3 ~38 ~34 ~3 ~38 yellow_glazed_terracotta 0
setblock ~32 ~3 ~39 glowstone 0
setblock ~32 ~3 ~40 yellow_glazed_terracotta 0
setblock ~33 ~3 ~19 yellow_glazed_terracotta 0
setblock ~33 ~3 ~37 yellow_glazed_terracotta 0
setblock ~33 ~3 ~39 yellow_glazed_terracotta 0
fill ~34 ~3 ~36 ~35 ~3 ~36 yellow_glazed_terracotta 0
setblock ~34 ~3 ~37 sponge 0
setblock ~35 ~3 ~17 yellow_glazed_terracotta 0
fill ~35 ~3 ~34 ~36 ~3 ~34 yellow_glazed_terracotta 0
fill ~35 ~3 ~35 ~35 ~3 ~34 yellow_glazed_terracotta 0
setblock ~36 ~3 ~17 sponge 0
setblock ~36 ~3 ~33 sponge 0
setblock ~36 ~3 ~35 glowstone 0
setblock ~37 ~3 ~17 yellow_glazed_terracotta 0
fill ~37 ~3 ~31 ~37 ~3 ~33 yellow_glazed_terracotta 0
setblock ~38 ~3 ~17 sponge 0
fill ~38 ~3 ~30 ~39 ~3 ~30 yellow_glazed_terracotta 0
setblock ~38 ~3 ~31 sponge 0
setblock ~38 ~3 ~32 yellow_glazed_terracotta 0
setblock ~39 ~3 ~17 yellow_glazed_terracotta 0
setblock ~39 ~3 ~19 yellow_glazed_terracotta 0
fill ~39 ~3 ~28 ~40 ~3 ~28 yellow_glazed_terracotta 0
fill ~39 ~3 ~29 ~39 ~3 ~28 yellow_glazed_terracotta 0
setblock ~40 ~3 ~17 sponge 0
setblock ~40 ~3 ~19 glowstone 0
fill ~40 ~3 ~26 ~42 ~3 ~26 yellow_glazed_terracotta 0
setblock ~40 ~3 ~27 glowstone 0
setblock ~40 ~3 ~29 sponge 0
setblock ~41 ~3 ~17 yellow_glazed_terracotta 0
fill ~41 ~3 ~19 ~41 ~3 ~27 yellow_glazed_terracotta 0
setblock ~42 ~3 ~17 sponge 0
setblock ~42 ~3 ~19 sponge 0
fill ~42 ~3 ~20 ~44 ~3 ~20 yellow_glazed_terracotta 0
setblock ~42 ~3 ~21 sponge 0
fill ~42 ~3 ~22 ~44 ~3 ~22 yellow_glazed_terracotta 0
setblock ~42 ~3 ~23 sponge 0
fill ~42 ~3 ~24 ~43 ~3 ~24 yellow_glazed_terracotta 0
setblock ~42 ~3 ~25 sponge 0
setblock ~43 ~3 ~17 yellow_glazed_terracotta 0
setblock ~43 ~3 ~19 yellow_glazed_terracotta 0
setblock ~43 ~3 ~21 yellow_glazed_terracotta 0
setblock ~43 ~3 ~23 yellow_glazed_terracotta 0
setblock ~44 ~3 ~19 glowstone 0
setblock ~44 ~3 ~21 sponge 0
setblock ~2 ~4 ~75 yellow_glazed_terracotta 0
setblock ~2 ~4 ~76 glowstone 0
setblock ~2 ~4 ~77 yellow_glazed_terracotta 0
setblock ~2 ~4 ~78 glowstone 0
setblock ~2 ~4 ~79 yellow_glazed_terracotta 0
setblock ~2 ~4 ~80 glowstone 0
setblock ~2 ~4 ~81 yellow_glazed_terracotta 0
setblock ~2 ~4 ~82 glowstone 0
setblock ~2 ~4 ~83 yellow_glazed_terracotta 0
setblock ~3 ~4 ~66 sponge 0
fill ~3 ~4 ~67 ~3 ~5 ~67 yellow_glazed_terracotta 0
setblock ~3 ~4 ~68 sponge 0
setblock ~3 ~4 ~69 yellow_glazed_terracotta 0
setblock ~3 ~4 ~70 sponge 0
setblock ~3 ~4 ~71 yellow_glazed_terracotta 0
setblock ~3 ~4 ~72 sponge 0
setblock ~3 ~4 ~73 yellow_glazed_terracotta 0
setblock ~3 ~4 ~74 sponge 0
setblock ~3 ~4 ~84 sponge 0
setblock ~3 ~4 ~85 yellow_glazed_terracotta 0
setblock ~4 ~4 ~58 glowstone 0
setblock ~4 ~4 ~59 yellow_glazed_terracotta 0
setblock ~4 ~4 ~60 glowstone 0
setblock ~4 ~4 ~61 yellow_glazed_terracotta 0
setblock ~4 ~4 ~62 glowstone 0
setblock ~4 ~4 ~63 yellow_glazed_terracotta 0
setblock ~4 ~4 ~64 glowstone 0
setblock ~4 ~4 ~65 yellow_glazed_terracotta 0
setblock ~4 ~4 ~86 glowstone 0
setblock ~4 ~4 ~87 yellow_glazed_terracotta 0
fill ~5 ~4 ~53 ~5 ~6 ~53 yellow_glazed_terracotta 0
fill ~5 ~4 ~54 ~5 ~5 ~54 yellow_glazed_terracotta 0
fill ~5 ~4 ~55 ~5 ~4 ~53 yellow_glazed_terracotta 0
setblock ~5 ~4 ~56 sponge 0
setblock ~5 ~4 ~57 yellow_glazed_terracotta 0
setblock ~5 ~4 ~88 sponge 0
setblock ~6 ~4 ~51 yellow_glazed_terracotta 0
setblock ~6 ~4 ~52 glowstone 0
setblock ~6 ~4 ~89 yellow_glazed_terracotta 0
fill ~7 ~4 ~49 ~7 ~5 ~49 yellow_glazed_terracotta 0
setblock ~7 ~4 ~50 sponge 0
setblock ~7 ~4 ~90 sponge 0
setblock ~8 ~4 ~47 yellow_glazed_terracotta 0
setblock ~8 ~4 ~48 glowstone 0
fill ~8 ~4 ~91 ~10 ~4 ~91 yellow_glazed_terracotta 0
fill ~9 ~4 ~45 ~9 ~5 ~45 yellow_glazed_terracotta 0
fill ~9 ~4 ~46 ~9 ~3 ~46 yellow_glazed_terracotta 0
setblock ~9 ~4 ~92 sponge 0
setblock ~10 ~4 ~43 yellow_glazed_terracotta 0
setblock ~10 ~4 ~44 glowstone 0
setblock ~10 ~4 ~92 glowstone 0
fill ~10 ~4 ~93 ~17 ~4 ~93 yellow_glazed_terracotta 0
setblock ~11 ~4 ~40 sponge 0
setblock ~11 ~4 ~41 yellow_glazed_terracotta 0
setblock ~11 ~4 ~42 sponge 0
setblock ~11 ~4 ~92 sponge 0
setblock ~11 ~4 ~94 sponge 0
setblock ~12 ~4 ~37 yellow_glazed_terracotta 0
setblock ~12 ~4 ~38 glowstone 0
setblock ~12 ~4 ~39 yellow_glazed_terracotta 0
fill ~12 ~4 ~91 ~17 ~4 ~91 yellow_glazed_terracotta 0
setblock ~12 ~4 ~92 glowstone 0
setblock ~12 ~4 ~94 glowstone 0
fill ~12 ~4 ~95 ~17 ~4 ~95 yellow_glazed_terracotta 0
fill ~13 ~4 ~34 ~13 ~6 ~34 yellow_glazed_terracotta 0
fill ~13 ~4 ~35 ~13 ~4 ~34 yellow_glazed_terracotta 0
setblock ~13 ~4 ~36 sponge 0
setblock ~13 ~4 ~92 sponge 0
setblock ~13 ~4 ~94 yellow_glazed_terracotta 0
setblock ~13 ~4 ~96 sponge 0
setblock ~14 ~4 ~32 glowstone 0
setblock ~14 ~4 ~33 yellow_glazed_terracotta 0
setblock ~14 ~4 ~90 glowstone 0
setblock ~14 ~4 ~92 glowstone 0
setblock ~14 ~4 ~94 glowstone 0
setblock ~14 ~4 ~96 glowstone 0
fill ~14 ~4 ~97 ~17 ~4 ~97 yellow_glazed_terracotta 0
setblock ~15 ~4 ~31 yellow_glazed_terracotta 0
setblock ~15 ~4 ~88 sponge 0
fill ~15 ~4 ~89 ~17 ~4 ~89 yellow_glazed_terracotta 0
setblock ~15 ~4 ~90 sponge 0
setblock ~15 ~4 ~92 sponge 0
setblock ~15 ~4 ~94 sponge 0
setblock ~15 ~4 ~96 sponge 0
setblock ~15 ~4 ~98 sponge 0
setblock ~16 ~4 ~29 yellow_glazed_terracotta 0
setblock ~16 ~4 ~30 glowstone 0
fill ~16 ~4 ~85 ~19 ~4 ~85 yellow_glazed_terracotta 0
setblock ~16 ~4 ~86 glowstone 0
fill ~16 ~4 ~87 ~18 ~4 ~87 yellow_glazed_terracotta 0
setblock ~16 ~4 ~88 glowstone 0
setblock ~16 ~4 ~90 glowstone 0
setblock ~16 ~4 ~92 glowstone 0
setblock ~16 ~4 ~94 glowstone 0
setblock ~16 ~4 ~96 glowstone 0
setblock ~16 ~4 ~98 glowstone 0
setblock ~17 ~4 ~28 sponge 0
fill ~17 ~4 ~83 ~20 ~4 ~83 yellow_glazed_terracotta 0
setblock ~17 ~4 ~84 sponge 0
setblock ~17 ~4 ~86 yellow_glazed_terracotta 0
setblock ~17 ~4 ~88 sponge 0
setblock ~17 ~4 ~90 yellow_glazed_terracotta 0
setblock ~17 ~4 ~92 sponge 0
setblock ~17 ~4 ~94 yellow_glazed_terracotta 0
setblock ~17 ~4 ~96 sponge 0
setblock ~18 ~4 ~27 yellow_glazed_terracotta 0
fill ~18 ~4 ~81 ~21 ~4 ~81 yellow_glazed_terracotta 0
setblock ~18 ~4 ~82 glowstone 0
setblock ~18 ~4 ~84 glowstone 0
setblock ~18 ~4 ~86 glowstone 0
setblock ~18 ~4 ~88 glowstone 0
setblock ~19 ~4 ~26 sponge 0
fill ~19 ~4 ~79 ~22 ~4 ~79 yellow_glazed_terracotta 0
setblock ~19 ~4 ~80 sponge 0
setblock ~19 ~4 ~82 sponge 0
setblock ~19 ~4 ~84 sponge 0
setblock ~20 ~4 ~25 yellow_glazed_terracotta 0
fill ~20 ~4 ~77 ~23 ~4 ~77 yellow_glazed_terracotta 0
setblock ~20 ~4 ~78 glowstone 0
setblock ~20 ~4 ~80 glowstone 0
setblock ~20 ~4 ~82 glowstone 0
setblock ~21 ~4 ~24 sponge 0
fill ~21 ~4 ~75 ~24 ~4 ~75 yellow_glazed_terracotta 0
setblock ~21 ~4 ~76 sponge 0
setblock ~21 ~4 ~78 yellow_glazed_terracotta 0
setblock ~21 ~4 ~80 sponge 0
setblock ~22 ~4 ~23 yellow_glazed_terracotta 0
setblock ~22 ~4 ~72 glowstone 0
fill ~22 ~4 ~73 ~25 ~4 ~73 yellow_glazed_terracotta 0
setblock ~22 ~4 ~74 glowstone 0
setblock ~22 ~4 ~76 glowstone 0
setblock ~22 ~4 ~78 glowstone 0
setblock ~23 ~4 ~22 sponge 0
fill ~23 ~4 ~69 ~27 ~4 ~69 yellow_glazed_terracotta 0
setblock ~23 ~4 ~70 sponge 0
fill ~23 ~4 ~71 ~26 ~4 ~71 yellow_glazed_terracotta 0
setblock ~23 ~4 ~72 sponge 0
setblock ~23 ~4 ~74 sponge 0
setblock ~23 ~4 ~76 sponge 0
setblock ~23 ~4 ~78 sponge 0
fill ~24 ~4 ~21 ~25 ~4 ~21 yellow_glazed_terracotta 0
fill ~24 ~4 ~53 ~27 ~4 ~53 yellow_glazed_terracotta 0
setblock ~24 ~4 ~54 glowstone 0
fill ~24 ~4 ~55 ~27 ~4 ~55 yellow_glazed_terracotta 0
setblock ~24 ~4 ~56 glowstone 0
fill ~24 ~4 ~57 ~27 ~4 ~57 yellow_glazed_terracotta 0
setblock ~24 ~4 ~58 glowstone 0
fill ~24 ~4 ~59 ~27 ~4 ~59 yellow_glazed_terracotta 0
setblock ~24 ~4 ~60 glowstone 0
fill ~24 ~4 ~61 ~27 ~4 ~61 yellow_glazed_terracotta 0
setblock ~24 ~4 ~62 glowstone 0
fill ~24 ~4 ~63 ~28 ~4 ~63 yellow_glazed_terracotta 0
setblock ~24 ~4 ~64 glowstone 0
fill ~24 ~4 ~65 ~28 ~4 ~65 yellow_glazed_terracotta 0
setblock ~24 ~4 ~66 glowstone 0
fill ~24 ~4 ~67 ~27 ~4 ~67 yellow_glazed_terracotta 0
setblock ~24 ~4 ~68 glowstone 0
setblock ~24 ~4 ~70 glowstone 0
setblock ~24 ~4 ~72 glowstone 0
setblock ~24 ~4 ~74 glowstone 0
setblock ~24 ~4 ~76 glowstone 0
fill ~25 ~4 ~49 ~28 ~4 ~49 yellow_glazed_terracotta 0
fill ~25 ~4 ~50 ~25 ~4 ~51 yellow_glazed_terracotta 0
setblock ~25 ~4 ~52 sponge 0
setblock ~25 ~4 ~54 yellow_glazed_terracotta 0
setblock ~25 ~4 ~56 sponge 0
setblock ~25 ~4 ~58 yellow_glazed_terracotta 0
setblock ~25 ~4 ~60 sponge 0
setblock ~25 ~4 ~62 yellow_glazed_terracotta 0
setblock ~25 ~4 ~64 sponge 0
setblock ~25 ~4 ~66 yellow_glazed_terracotta 0
setblock ~25 ~4 ~68 sponge 0
setblock ~25 ~4 ~70 yellow_glazed_terracotta 0
setblock ~25 ~4 ~72 sponge 0
setblock ~25 ~4 ~74 yellow_glazed_terracotta 0
setblock ~26 ~4 ~20 glowstone 0
setblock ~26 ~4 ~48 glowstone 0
setblock ~26 ~4 ~50 glowstone 0
fill ~26 ~4 ~51 ~27 ~4 ~51 yellow_glazed_terracotta 0
setblock ~26 ~4 ~52 glowstone 0
setblock ~26 ~4 ~54 glowstone 0
setblock ~26 ~4 ~56 glowstone 0
setblock ~26 ~4 ~58 glowstone 0
setblock ~26 ~4 ~60 glowstone 0
setblock ~26 ~4 ~62 glowstone 0
setblock ~26 ~4 ~64 glowstone 0
setblock ~26 ~4 ~66 glowstone 0
setblock ~26 ~4 ~68 glowstone 0
setblock ~26 ~4 ~70 glowstone 0
setblock ~26 ~4 ~72 glowstone 0
fill ~27 ~4 ~19 ~29 ~4 ~19 yellow_glazed_terracotta 0
fill ~27 ~4 ~47 ~29 ~4 ~47 yellow_glazed_terracotta 0
setblock ~27 ~4 ~48 sponge 0
setblock ~27 ~4 ~50 sponge 0
setblock ~27 ~4 ~52 sponge 0
setblock ~27 ~4 ~54 sponge 0
setblock ~27 ~4 ~56 sponge 0
setblock ~27 ~4 ~58 sponge 0
setblock ~27 ~4 ~60 sponge 0
setblock ~27 ~4 ~62 sponge 0
setblock ~27 ~4 ~64 sponge 0
setblock ~27 ~4 ~66 sponge 0
setblock ~27 ~4 ~68 sponge 0
setblock ~27 ~4 ~70 sponge 0
fill ~28 ~4 ~45 ~31 ~4 ~45 yellow_glazed_terracotta 0
setblock ~28 ~4 ~46 glowstone 0
setblock ~28 ~4 ~48 glowstone 0
setblock ~28 ~4 ~64 glowstone 0
setblock ~29 ~4 ~18 yellow_glazed_terracotta 0
setblock ~29 ~4 ~44 sponge 0
setblock ~29 ~4 ~46 yellow_glazed_terracotta 0
setblock ~29 ~4 ~48 sponge 0
setblock ~30 ~4 ~18 glowstone 0
fill ~30 ~4 ~43 ~32 ~4 ~43 yellow_glazed_terracotta 0
setblock ~30 ~4 ~44 glowstone 0
setblock ~30 ~4 ~46 glowstone 0
fill ~31 ~4 ~17 ~34 ~4 ~17 yellow_glazed_terracotta 0
setblock ~31 ~4 ~42 sponge 0
setblock ~31 ~4 ~44 sponge 0
fill ~32 ~4 ~41 ~34 ~4 ~41 yellow_glazed_terracotta 0
setblock ~32 ~4 ~42 glowstone 0
setblock ~33 ~4 ~16 sponge 0
setblock ~33 ~4 ~40 sponge 0
setblock ~33 ~4 ~42 yellow_glazed_terracotta 0
setblock ~34 ~4 ~16 glowstone 0
fill ~34 ~4 ~39 ~35 ~4 ~39 yellow_glazed_terracotta 0
setblock ~34 ~4 ~40 glowstone 0
setblock ~35 ~4 ~16 sponge 0
fill ~35 ~4 ~37 ~36 ~4 ~37 yellow_glazed_terracotta 0
setblock ~35 ~4 ~38 sponge 0
fill ~36 ~4 ~15 ~46 ~4 ~15 yellow_glazed_terracotta 0
setblock ~36 ~4 ~16 glowstone 0
setblock ~36 ~4 ~36 glowstone 0
setblock ~36 ~4 ~38 glowstone 0
setblock ~37 ~4 ~16 sponge 0
fill ~37 ~4 ~34 ~37 ~4 ~35 yellow_glazed_terracotta 0
setblock ~37 ~4 ~36 sponge 0
setblock ~38 ~4 ~16 glowstone 0
fill ~38 ~4 ~33 ~39 ~4 ~33 yellow_glazed_terracotta 0
setblock ~38 ~4 ~34 glowstone 0
setblock ~38 ~4 ~35 yellow_glazed_terracotta 0
setblock ~39 ~4 ~14 sponge 0
setblock ~39 ~4 ~16 sponge 0
fill ~39 ~4 ~31 ~40 ~4 ~31 yellow_glazed_terracotta 0
setblock ~39 ~4 ~32 sponge 0
setblock ~40 ~4 ~14 glowstone 0
setblock ~40 ~4 ~16 glowstone 0
setblock ~40 ~4 ~30 glowstone 0
setblock ~40 ~4 ~32 glowstone 0
setblock ~41 ~4 ~14 yellow_glazed_terracotta 0
setblock ~41 ~4 ~16 sponge 0
setblock ~41 ~4 ~28 sponge 0
fill ~41 ~4 ~29 ~42 ~4 ~29 yellow_glazed_terracotta 0
fill ~41 ~4 ~30 ~41 ~4 ~29 yellow_glazed_terracotta 0
setblock ~42 ~4 ~14 glowstone 0
setblock ~42 ~4 ~16 glowstone 0
fill ~42 ~4 ~27 ~43 ~4 ~27 yellow_glazed_terracotta 0
setblock ~42 ~4 ~28 glowstone 0
setblock ~43 ~4 ~14 sponge 0
setblock ~43 ~4 ~16 sponge 0
fill ~43 ~4 ~25 ~45 ~4 ~25 yellow_glazed_terracotta 0
setblock ~43 ~4 ~26 sponge 0
setblock ~44 ~4 ~16 glowstone 0
fill ~44 ~4 ~17 ~48 ~4 ~17 yellow_glazed_terracotta 0
fill ~44 ~4 ~23 ~46 ~4 ~23 yellow_glazed_terracotta 0
setblock ~44 ~4 ~24 glowstone 0
setblock ~44 ~4 ~26 glowstone 0
setblock ~45 ~4 ~16 sponge 0
fill ~45 ~4 ~18 ~45 ~4 ~19 yellow_glazed_terracotta 0
setblock ~45 ~4 ~20 sponge 0
fill ~45 ~4 ~21 ~47 ~4 ~21 yellow_glazed_terracotta 0
fill ~45 ~4 ~22 ~45 ~4 ~21 yellow_glazed_terracotta 0
setblock ~45 ~4 ~24 sponge 0
setblock ~46 ~4 ~16 glowstone 0
setblock ~46 ~4 ~18 glowstone 0
fill ~46 ~4 ~19 ~48 ~4 ~19 yellow_glazed_terracotta 0
setblock ~46 ~4 ~20 glowstone 0
setblock ~46 ~4 ~22 glowstone 0
setblock ~47 ~4 ~16 sponge 0
setblock ~47 ~4 ~18 sponge 0
setblock ~47 ~4 ~20 sponge 0
setblock ~48 ~4 ~18 glowstone 0
setblock ~2 ~5 ~69 sponge 0
setblock ~2 ~5 ~70 yellow_glazed_terracotta 0
setblock ~2 ~5 ~71 sponge 0
setblock ~2 ~5 ~72 yellow_glazed_terracotta 0
setblock ~2 ~5 ~73 sponge 0
setblock ~2 ~5 ~74 yellow_glazed_terracotta 0
setblock ~2 ~5 ~75 sponge 0
setblock ~2 ~5 ~76 yellow_glazed_terracotta 0
setblock ~2 ~5 ~77 sponge 0
setblock ~2 ~5 ~78 yellow_glazed_terracotta 0
setblock ~2 ~5 ~79 sponge 0
setblock ~2 ~5 ~80 yellow_glazed_terracotta 0
setblock ~2 ~5 ~81 sponge 0
setblock ~2 ~5 ~82 yellow_glazed_terracotta 0
setblock ~2 ~5 ~83 sponge 0
setblock ~2 ~5 ~84 yellow_glazed_terracotta 0
setblock ~2 ~5 ~85 sponge 0
fill ~3 ~5 ~61 ~3 ~11 ~61 yellow_glazed_terracotta 0
fill ~3 ~5 ~62 ~3 ~5 ~68 yellow_glazed_terracotta 0
setblock ~3 ~5 ~86 yellow_glazed_terracotta 0
setblock ~4 ~5 ~55 sponge 0
setblock ~4 ~5 ~56 yellow_glazed_terracotta 0
setblock ~4 ~5 ~57 sponge 0
setblock ~4 ~5 ~58 yellow_glazed_terracotta 0
setblock ~4 ~5 ~59 sponge 0
setblock ~4 ~5 ~60 yellow_glazed_terracotta 0
setblock ~4 ~5 ~87 sponge 0
setblock ~4 ~5 ~88 yellow_glazed_terracotta 0
fill ~5 ~5 ~52 ~5 ~7 ~52 yellow_glazed_terracotta 0
setblock ~5 ~5 ~89 yellow_glazed_terracotta 0
setblock ~6 ~5 ~50 yellow_glazed_terracotta 0
setblock ~6 ~5 ~51 sponge 0
setblock ~6 ~5 ~90 yellow_glazed_terracotta 0
setblock ~6 ~5 ~91 sponge 0
fill ~7 ~5 ~48 ~7 ~7 ~48 yellow_glazed_terracotta 0
fill ~7 ~5 ~91 ~7 ~5 ~92 yellow_glazed_terracotta 0
setblock ~8 ~5 ~46 yellow_glazed_terracotta 0
setblock ~8 ~5 ~47 sponge 0
setblock ~8 ~5 ~92 yellow_glazed_terracotta 0
setblock ~8 ~5 ~93 sponge 0
fill ~9 ~5 ~44 ~9 ~6 ~44 yellow_glazed_terracotta 0
fill ~9 ~5 ~93 ~9 ~5 ~94 yellow_glazed_terracotta 0
setblock ~10 ~5 ~41 sponge 0
setblock ~10 ~5 ~42 yellow_glazed_terracotta 0
setblock ~10 ~5 ~43 sponge 0
setblock ~10 ~5 ~94 yellow_glazed_terracotta 0
setblock ~10 ~5 ~95 sponge 0
fill ~11 ~5 ~39 ~11 ~10 ~39 yellow_glazed_terracotta 0
fill ~11 ~5 ~40 ~11 ~5 ~39 yellow_glazed_terracotta 0
fill ~11 ~5 ~95 ~11 ~5 ~97 yellow_glazed_terracotta 0
setblock ~12 ~5 ~35 sponge 0
setblock ~12 ~5 ~36 yellow_glazed_terracotta 0
setblock ~12 ~5 ~37 sponge 0
setblock ~12 ~5 ~38 yellow_glazed_terracotta 0
setblock ~12 ~5 ~96 yellow_glazed_terracotta 0
setblock ~12 ~5 ~97 sponge 0
fill ~12 ~5 ~98 ~14 ~5 ~98 yellow_glazed_terracotta 0
fill ~13 ~5 ~33 ~13 ~10 ~33 yellow_glazed_terracotta 0
setblock ~13 ~5 ~97 yellow_glazed_terracotta 0
fill ~13 ~5 ~99 ~13 ~5 ~100 yellow_glazed_terracotta 0
setblock ~14 ~5 ~31 sponge 0
setblock ~14 ~5 ~32 yellow_glazed_terracotta 0
setblock ~14 ~5 ~99 sponge 0
fill ~14 ~5 ~100 ~24 ~5 ~100 yellow_glazed_terracotta 0
setblock ~14 ~5 ~101 sponge 0
setblock ~15 ~5 ~30 yellow_glazed_terracotta 0
setblock ~15 ~5 ~99 yellow_glazed_terracotta 0
fill ~15 ~5 ~101 ~15 ~5 ~103 yellow_glazed_terracotta 0
setblock ~16 ~5 ~28 yellow_glazed_terracotta 0
setblock ~16 ~5 ~29 sponge 0
setblock ~16 ~5 ~99 sponge 0
setblock ~16 ~5 ~101 sponge 0
fill ~16 ~5 ~102 ~24 ~5 ~102 yellow_glazed_terracotta 0
setblock ~16 ~5 ~103 sponge 0
fill ~16 ~5 ~104 ~24 ~5 ~104 yellow_glazed_terracotta 0
fill ~17 ~5 ~27 ~17 ~6 ~27 yellow_glazed_terracotta 0
fill ~17 ~5 ~98 ~23 ~5 ~98 yellow_glazed_terracotta 0
fill ~17 ~5 ~99 ~17 ~5 ~98 yellow_glazed_terracotta 0
setblock ~17 ~5 ~101 yellow_glazed_terracotta 0
setblock ~17 ~5 ~103 yellow_glazed_terracotta 0
setblock ~17 ~5 ~105 yellow_glazed_terracotta 0
setblock ~18 ~5 ~26 yellow_glazed_terracotta 0
setblock ~18 ~5 ~89 sponge 0
fill ~18 ~5 ~90 ~22 ~5 ~90 yellow_glazed_terracotta 0
setblock ~18 ~5 ~91 sponge 0
fill ~18 ~5 ~92 ~22 ~5 ~92 yellow_glazed_terracotta 0
setblock ~18 ~5 ~93 sponge 0
fill ~18 ~5 ~94 ~22 ~5 ~94 yellow_glazed_terracotta 0
setblock ~18 ~5 ~95 sponge 0
fill ~18 ~5 ~96 ~23 ~5 ~96 yellow_glazed_terracotta 0
setblock ~18 ~5 ~97 sponge 0
setblock ~18 ~5 ~99 sponge 0
setblock ~18 ~5 ~101 sponge 0
setblock ~18 ~5 ~103 sponge 0
setblock ~18 ~5 ~105 sponge 0
fill ~18 ~5 ~106 ~24 ~5 ~106 yellow_glazed_terracotta 0
fill ~19 ~5 ~25 ~19 ~6 ~25 yellow_glazed_terracotta 0
fill ~19 ~5 ~86 ~23 ~5 ~86 yellow_glazed_terracotta 0
fill ~19 ~5 ~87 ~19 ~5 ~107 yellow_glazed_terracotta 0
setblock ~20 ~5 ~24 yellow_glazed_terracotta 0
fill ~20 ~5 ~84 ~25 ~5 ~84 yellow_glazed_terracotta 0
setblock ~20 ~5 ~85 sponge 0
setblock ~20 ~5 ~87 sponge 0
fill ~20 ~5 ~88 ~23 ~5 ~88 yellow_glazed_terracotta 0
setblock ~20 ~5 ~89 sponge 0
setblock ~20 ~5 ~91 sponge 0
setblock ~20 ~5 ~93 sponge 0
setblock ~20 ~5 ~95 sponge 0
setblock ~20 ~5 ~97 sponge 0
setblock ~20 ~5 ~99 sponge 0
setblock ~20 ~5 ~101 sponge 0
setblock ~20 ~5 ~103 sponge 0
setblock ~20 ~5 ~105 sponge 0
setblock ~20 ~5 ~107 sponge 0
fill ~20 ~5 ~108 ~24 ~5 ~108 yellow_glazed_terracotta 0
setblock ~21 ~5 ~23 yellow_glazed_terracotta 0
fill ~21 ~5 ~82 ~26 ~5 ~82 yellow_glazed_terracotta 0
fill ~21 ~5 ~83 ~21 ~5 ~82 yellow_glazed_terracotta 0
setblock ~21 ~5 ~85 yellow_glazed_terracotta 0
setblock ~21 ~5 ~87 yellow_glazed_terracotta 0
setblock ~21 ~5 ~89 yellow_glazed_terracotta 0
setblock ~21 ~5 ~91 yellow_glazed_terracotta 0
setblock ~21 ~5 ~93 yellow_glazed_terracotta 0
setblock ~21 ~5 ~95 yellow_glazed_terracotta 0
setblock ~21 ~5 ~97 yellow_glazed_terracotta 0
setblock ~21 ~5 ~99 yellow_glazed_terracotta 0
setblock ~21 ~5 ~101 yellow_glazed_terracotta 0
setblock ~21 ~5 ~103 yellow_glazed_terracotta 0
setblock ~21 ~5 ~105 yellow_glazed_terracotta 0
setblock ~21 ~5 ~107 yellow_glazed_terracotta 0
setblock ~22 ~5 ~22 yellow_glazed_terracotta 0
fill ~22 ~5 ~80 ~27 ~5 ~80 yellow_glazed_terracotta 0
setblock ~22 ~5 ~81 sponge 0
setblock ~22 ~5 ~83 sponge 0
setblock ~22 ~5 ~85 sponge 0
setblock ~22 ~5 ~87 sponge 0
setblock ~22 ~5 ~89 sponge 0
setblock ~22 ~5 ~91 sponge 0
setblock ~22 ~5 ~93 sponge 0
setblock ~22 ~5 ~95 sponge 0
setblock ~22 ~5 ~97 sponge 0
setblock ~22 ~5 ~99 sponge 0
setblock ~22 ~5 ~101 sponge 0
setblock ~22 ~5 ~103 sponge 0
setblock ~22 ~5 ~105 sponge 0
setblock ~22 ~5 ~107 sponge 0
setblock ~22 ~5 ~109 sponge 0
fill ~23 ~5 ~21 ~23 ~6 ~21 yellow_glazed_terracotta 0
setblock ~23 ~5 ~79 yellow_glazed_terracotta 0
setblock ~23 ~5 ~81 yellow_glazed_terracotta 0
setblock ~23 ~5 ~83 yellow_glazed_terracotta 0
setblock ~23 ~5 ~85 yellow_glazed_terracotta 0
setblock ~23 ~5 ~87 yellow_glazed_terracotta 0
setblock ~23 ~5 ~95 yellow_glazed_terracotta 0
setblock ~23 ~5 ~97 yellow_glazed_terracotta 0
setblock ~23 ~5 ~99 yellow_glazed_terracotta 0
setblock ~23 ~5 ~101 yellow_glazed_terracotta 0
setblock ~23 ~5 ~103 yellow_glazed_terracotta 0
setblock ~23 ~5 ~105 yellow_glazed_terracotta 0
setblock ~23 ~5 ~107 yellow_glazed_terracotta 0
setblock ~23 ~5 ~109 yellow_glazed_terracotta 0
fill ~24 ~5 ~20 ~25 ~5 ~20 yellow_glazed_terracotta 0
setblock ~24 ~5 ~77 sponge 0
fill ~24 ~5 ~78 ~28 ~5 ~78 yellow_glazed_terracotta 0
setblock ~24 ~5 ~79 sponge 0
setblock ~24 ~5 ~81 sponge 0
setblock ~24 ~5 ~83 sponge 0
setblock ~24 ~5 ~85 sponge 0
setblock ~24 ~5 ~101 sponge 0
setblock ~24 ~5 ~103 sponge 0
setblock ~24 ~5 ~105 sponge 0
setblock ~24 ~5 ~107 sponge 0
setblock ~24 ~5 ~109 sponge 0
fill ~25 ~5 ~75 ~25 ~5 ~84 yellow_glazed_terracotta 0
setblock ~26 ~5 ~19 sponge 0
setblock ~26 ~5 ~73 sponge 0
fill ~26 ~5 ~74 ~30 ~5 ~74 yellow_glazed_terracotta 0
setblock ~26 ~5 ~75 sponge 0
fill ~26 ~5 ~76 ~29 ~5 ~76 yellow_glazed_terracotta 0
setblock ~26 ~5 ~77 sponge 0
setblock ~26 ~5 ~79 sponge 0
setblock ~26 ~5 ~81 sponge 0
fill ~27 ~5 ~18 ~28 ~5 ~18 yellow_glazed_terracotta 0
fill ~27 ~5 ~71 ~27 ~5 ~80 yellow_glazed_terracotta 0
fill ~28 ~5 ~50 ~31 ~5 ~50 yellow_glazed_terracotta 0
setblock ~28 ~5 ~51 sponge 0
fill ~28 ~5 ~52 ~31 ~5 ~52 yellow_glazed_terracotta 0
setblock ~28 ~5 ~53 sponge 0
fill ~28 ~5 ~54 ~31 ~5 ~54 yellow_glazed_terracotta 0
setblock ~28 ~5 ~55 sponge 0
fill ~28 ~5 ~56 ~31 ~5 ~56 yellow_glazed_terracotta 0
setblock ~28 ~5 ~57 sponge 0
fill ~28 ~5 ~58 ~32 ~5 ~58 yellow_glazed_terracotta 0
setblock ~28 ~5 ~59 sponge 0
fill ~28 ~5 ~60 ~32 ~5 ~60 yellow_glazed_terracotta 0
setblock ~28 ~5 ~61 sponge 0
fill ~28 ~5 ~62 ~32 ~5 ~62 yellow_glazed_terracotta 0
fill ~28 ~5 ~66 ~32 ~5 ~66 yellow_glazed_terracotta 0
setblock ~28 ~5 ~67 sponge 0
fill ~28 ~5 ~68 ~32 ~5 ~68 yellow_glazed_terracotta 0
setblock ~28 ~5 ~69 sponge 0
fill ~28 ~5 ~70 ~31 ~5 ~70 yellow_glazed_terracotta 0
setblock ~28 ~5 ~71 sponge 0
fill ~28 ~5 ~72 ~31 ~5 ~72 yellow_glazed_terracotta 0
setblock ~28 ~5 ~73 sponge 0
setblock ~28 ~5 ~75 sponge 0
setblock ~28 ~5 ~77 sponge 0
setblock ~28 ~5 ~79 sponge 0
setblock ~29 ~5 ~17 yellow_glazed_terracotta 0
setblock ~29 ~5 ~49 yellow_glazed_terracotta 0
setblock ~29 ~5 ~51 yellow_glazed_terracotta 0
setblock ~29 ~5 ~53 yellow_glazed_terracotta 0
setblock ~29 ~5 ~55 yellow_glazed_terracotta 0
setblock ~29 ~5 ~57 yellow_glazed_terracotta 0
setblock ~29 ~5 ~59 yellow_glazed_terracotta 0
setblock ~29 ~5 ~61 yellow_glazed_terracotta 0
fill ~29 ~5 ~63 ~29 ~5 ~77 yellow_glazed_terracotta 0
setblock ~30 ~5 ~17 sponge 0
setblock ~30 ~5 ~47 sponge 0
fill ~30 ~5 ~48 ~32 ~5 ~48 yellow_glazed_terracotta 0
setblock ~30 ~5 ~49 sponge 0
setblock ~30 ~5 ~51 sponge 0
setblock ~30 ~5 ~53 sponge 0
setblock ~30 ~5 ~55 sponge 0
setblock ~30 ~5 ~57 sponge 0
setblock ~30 ~5 ~59 sponge 0
setblock ~30 ~5 ~61 sponge 0
setblock ~30 ~5 ~63 sponge 0
fill ~30 ~5 ~64 ~33 ~5 ~64 yellow_glazed_terracotta 0
setblock ~30 ~5 ~65 sponge 0
setblock ~30 ~5 ~67 sponge 0
setblock ~30 ~5 ~69 sponge 0
setblock ~30 ~5 ~71 sponge 0
setblock ~30 ~5 ~73 sponge 0
fill ~31 ~5 ~16 ~32 ~5 ~16 yellow_glazed_terracotta 0
fill ~31 ~5 ~46 ~33 ~5 ~46 yellow_glazed_terracotta 0
fill ~31 ~5 ~47 ~31 ~5 ~46 yellow_glazed_terracotta 0
setblock ~31 ~5 ~49 yellow_glazed_terracotta 0
setblock ~31 ~5 ~51 yellow_glazed_terracotta 0
setblock ~31 ~5 ~53 yellow_glazed_terracotta 0
setblock ~31 ~5 ~55 yellow_glazed_terracotta 0
setblock ~31 ~5 ~57 yellow_glazed_terracotta 0
setblock ~31 ~5 ~59 yellow_glazed_terracotta 0
setblock ~31 ~5 ~61 yellow_glazed_terracotta 0
setblock ~31 ~5 ~63 yellow_glazed_terracotta 0
setblock ~31 ~5 ~65 yellow_glazed_terracotta 0
setblock ~31 ~5 ~67 yellow_glazed_terracotta 0
setblock ~31 ~5 ~69 yellow_glazed_terracotta 0
setblock ~31 ~5 ~71 yellow_glazed_terracotta 0
setblock ~32 ~5 ~15 sponge 0
fill ~32 ~5 ~44 ~35 ~5 ~44 yellow_glazed_terracotta 0
setblock ~32 ~5 ~45 sponge 0
setblock ~32 ~5 ~47 sponge 0
setblock ~32 ~5 ~49 sponge 0
setblock ~32 ~5 ~59 sponge 0
setblock ~32 ~5 ~61 sponge 0
setblock ~32 ~5 ~63 sponge 0
setblock ~32 ~5 ~65 sponge 0
setblock ~32 ~5 ~67 sponge 0
setblock ~33 ~5 ~15 yellow_glazed_terracotta 0
setblock ~33 ~5 ~43 yellow_glazed_terracotta 0
setblock ~33 ~5 ~45 yellow_glazed_terracotta 0
setblock ~33 ~5 ~47 yellow_glazed_terracotta 0
fill ~34 ~5 ~14 ~38 ~5 ~14 yellow_glazed_terracotta 0
setblock ~34 ~5 ~15 sponge 0
fill ~34 ~5 ~42 ~36 ~5 ~42 yellow_glazed_terracotta 0
setblock ~34 ~5 ~43 sponge 0
setblock ~34 ~5 ~45 sponge 0
setblock ~35 ~5 ~15 yellow_glazed_terracotta 0
fill ~35 ~5 ~40 ~37 ~5 ~40 yellow_glazed_terracotta 0
fill ~35 ~5 ~41 ~35 ~5 ~40 yellow_glazed_terracotta 0
setblock ~35 ~5 ~43 yellow_glazed_terracotta 0
setblock ~36 ~5 ~39 sponge 0
setblock ~36 ~5 ~41 sponge 0
setblock ~37 ~5 ~13 yellow_glazed_terracotta 0
fill ~37 ~5 ~37 ~37 ~5 ~40 yellow_glazed_terracotta 0
setblock ~38 ~5 ~13 sponge 0
fill ~38 ~5 ~36 ~39 ~5 ~36 yellow_glazed_terracotta 0
setblock ~38 ~5 ~37 sponge 0
setblock ~38 ~5 ~38 yellow_glazed_terracotta 0
setblock ~39 ~5 ~13 yellow_glazed_terracotta 0
fill ~39 ~5 ~34 ~40 ~5 ~34 yellow_glazed_terracotta 0
fill ~39 ~5 ~35 ~39 ~5 ~34 yellow_glazed_terracotta 0
setblock ~40 ~5 ~13 sponge 0
setblock ~40 ~5 ~33 sponge 0
setblock ~40 ~5 ~35 sponge 0
setblock ~41 ~5 ~13 yellow_glazed_terracotta 0
fill ~41 ~5 ~31 ~41 ~5 ~33 yellow_glazed_terracotta 0
setblock ~42 ~5 ~13 sponge 0
fill ~42 ~5 ~30 ~43 ~5 ~30 yellow_glazed_terracotta 0
setblock ~42 ~5 ~31 sponge 0
fill ~43 ~5 ~12 ~43 ~5 ~13 yellow_glazed_terracotta 0
fill ~43 ~5 ~28 ~44 ~5 ~28 yellow_glazed_terracotta 0
fill ~43 ~5 ~29 ~43 ~5 ~28 yellow_glazed_terracotta 0
setblock ~44 ~5 ~13 sponge 0
fill ~44 ~5 ~14 ~52 ~5 ~14 yellow_glazed_terracotta 0
setblock ~44 ~5 ~27 sponge 0
setblock ~45 ~5 ~13 yellow_glazed_terracotta 0
fill ~45 ~5 ~26 ~46 ~5 ~26 yellow_glazed_terracotta 0
fill ~45 ~5 ~27 ~45 ~5 ~26 yellow_glazed_terracotta 0
setblock ~46 ~5 ~13 sponge 0
fill ~46 ~5 ~24 ~47 ~5 ~24 yellow_glazed_terracotta 0
setblock ~46 ~5 ~25 sponge 0
fill ~47 ~5 ~12 ~49 ~5 ~12 yellow_glazed_terracotta 0
fill ~47 ~5 ~13 ~47 ~5 ~12 yellow_glazed_terracotta 0
setblock ~47 ~5 ~15 yellow_glazed_terracotta 0
fill ~47 ~5 ~22 ~49 ~5 ~22 yellow_glazed_terracotta 0
fill ~47 ~5 ~23 ~47 ~5 ~22 yellow_glazed_terracotta 0
setblock ~47 ~5 ~25 yellow_glazed_terracotta 0
setblock ~48 ~5 ~13 sponge 0
setblock ~48 ~5 ~15 sponge 0
fill ~48 ~5 ~16 ~52 ~5 ~16 yellow_glazed_terracotta 0
fill ~48 ~5 ~20 ~50 ~5 ~20 yellow_glazed_terracotta 0
setblock ~48 ~5 ~21 sponge 0
setblock ~48 ~5 ~23 sponge 0
setblock ~49 ~5 ~13 yellow_glazed_terracotta 0
setblock ~49 ~5 ~15 yellow_glazed_terracotta 0
fill ~49 ~5 ~17 ~49 ~5 ~22 yellow_glazed_terracotta 0
setblock ~50 ~5 ~13 sponge 0
setblock ~50 ~5 ~15 sponge 0
setblock ~50 ~5 ~17 sponge 0
fill ~50 ~5 ~18 ~51 ~5 ~18 yellow_glazed_terracotta 0
setblock ~50 ~5 ~19 sponge 0
setblock ~50 ~5 ~21 sponge 0
setblock ~51 ~5 ~13 yellow_glazed_terracotta 0
setblock ~51 ~5 ~15 yellow_glazed_terracotta 0
setblock ~51 ~5 ~17 yellow_glazed_terracotta 0
setblock ~51 ~5 ~19 yellow_glazed_terracotta 0
setblock ~52 ~5 ~15 sponge 0
setblock ~52 ~5 ~17 sponge 0
fill ~1 ~6 ~80 ~1 ~7 ~80 yellow_glazed_terracotta 0
fill ~1 ~6 ~81 ~1 ~10 ~81 yellow_glazed_terracotta 0
fill ~1 ~6 ~82 ~1 ~10 ~82 yellow_glazed_terracotta 0
setblock ~2 ~6 ~67 yellow_glazed_terracotta 0
setblock ~2 ~6 ~68 glowstone 0
setblock ~2 ~6 ~69 yellow_glazed_terracotta 0
setblock ~2 ~6 ~70 glowstone 0
setblock ~2 ~6 ~71 yellow_glazed_terracotta 0
setblock ~2 ~6 ~72 glowstone 0
setblock ~2 ~6 ~73 yellow_glazed_terracotta 0
setblock ~2 ~6 ~74 glowstone 0
setblock ~2 ~6 ~75 yellow_glazed_terracotta 0
setblock ~2 ~6 ~76 glowstone 0
setblock ~2 ~6 ~77 yellow_glazed_terracotta 0
setblock ~2 ~6 ~78 glowstone 0
setblock ~2 ~6 ~79 yellow_glazed_terracotta 0
setblock ~2 ~6 ~83 yellow_glazed_terracotta 0
setblock ~2 ~6 ~84 glowstone 0
setblock ~2 ~6 ~85 yellow_glazed_terracotta 0
setblock ~2 ~6 ~86 glowstone 0
setblock ~3 ~6 ~58 sponge 0
fill ~3 ~6 ~59 ~3 ~10 ~59 yellow_glazed_terracotta 0
fill ~3 ~6 ~60 ~3 ~7 ~60 yellow_glazed_terracotta 0
setblock ~3 ~6 ~62 sponge 0
fill ~3 ~6 ~63 ~3 ~7 ~63 yellow_glazed_terracotta 0
fill ~3 ~6 ~64 ~3 ~7 ~64 yellow_glazed_terracotta 0
fill ~3 ~6 ~65 ~3 ~6 ~63 yellow_glazed_terracotta 0
setblock ~3 ~6 ~66 sponge 0
fill ~3 ~6 ~87 ~3 ~11 ~87 yellow_glazed_terracotta 0
setblock ~4 ~6 ~54 glowstone 0
setblock ~4 ~6 ~55 yellow_glazed_terracotta 0
setblock ~4 ~6 ~56 glowstone 0
setblock ~4 ~6 ~57 yellow_glazed_terracotta 0
setblock ~4 ~6 ~88 glowstone 0
setblock ~4 ~6 ~89 yellow_glazed_terracotta 0
fill ~5 ~6 ~51 ~5 ~10 ~51 yellow_glazed_terracotta 0
fill ~5 ~6 ~90 ~5 ~7 ~90 yellow_glazed_terracotta 0
setblock ~6 ~6 ~49 yellow_glazed_terracotta 0
setblock ~6 ~6 ~50 glowstone 0
setblock ~6 ~6 ~91 yellow_glazed_terracotta 0
fill ~7 ~6 ~47 ~7 ~10 ~47 yellow_glazed_terracotta 0
fill ~7 ~6 ~92 ~7 ~6 ~93 yellow_glazed_terracotta 0
setblock ~8 ~6 ~45 yellow_glazed_terracotta 0
setblock ~8 ~6 ~46 glowstone 0
setblock ~8 ~6 ~94 glowstone 0
fill ~9 ~6 ~43 ~9 ~9 ~43 yellow_glazed_terracotta 0
setblock ~9 ~6 ~95 yellow_glazed_terracotta 0
setblock ~10 ~6 ~40 glowstone 0
setblock ~10 ~6 ~41 yellow_glazed_terracotta 0
setblock ~10 ~6 ~42 glowstone 0
setblock ~10 ~6 ~96 glowstone 0
setblock ~10 ~6 ~97 yellow_glazed_terracotta 0
setblock ~11 ~6 ~38 sponge 0
setblock ~11 ~6 ~98 sponge 0
fill ~11 ~6 ~99 ~12 ~6 ~99 yellow_glazed_terracotta 0
setblock ~12 ~6 ~35 yellow_glazed_terracotta 0
setblock ~12 ~6 ~36 glowstone 0
setblock ~12 ~6 ~37 yellow_glazed_terracotta 0
setblock ~12 ~6 ~100 glowstone 0
fill ~13 ~6 ~101 ~13 ~6 ~102 yellow_glazed_terracotta 0
setblock ~14 ~6 ~31 yellow_glazed_terracotta 0
setblock ~14 ~6 ~32 glowstone 0
setblock ~14 ~6 ~102 glowstone 0
setblock ~14 ~6 ~103 yellow_glazed_terracotta 0
fill ~15 ~6 ~29 ~15 ~10 ~29 yellow_glazed_terracotta 0
setblock ~15 ~6 ~30 sponge 0
setblock ~15 ~6 ~104 yellow_glazed_terracotta 0
setblock ~16 ~6 ~28 glowstone 0
setblock ~16 ~6 ~105 yellow_glazed_terracotta 0
fill ~17 ~6 ~26 ~17 ~10 ~26 yellow_glazed_terracotta 0
fill ~17 ~6 ~106 ~17 ~6 ~107 yellow_glazed_terracotta 0
setblock ~18 ~6 ~25 yellow_glazed_terracotta 0
setblock ~18 ~6 ~107 yellow_glazed_terracotta 0
setblock ~18 ~6 ~108 glowstone 0
fill ~19 ~6 ~108 ~19 ~6 ~109 yellow_glazed_terracotta 0
setblock ~20 ~6 ~23 yellow_glazed_terracotta 0
setblock ~20 ~6 ~24 glowstone 0
fill ~20 ~6 ~109 ~21 ~6 ~109 yellow_glazed_terracotta 0
setblock ~20 ~6 ~110 glowstone 0
fill ~21 ~6 ~22 ~21 ~13 ~22 yellow_glazed_terracotta 0
fill ~21 ~6 ~110 ~21 ~6 ~111 yellow_glazed_terracotta 0
setblock ~22 ~6 ~22 glowstone 0
setblock ~22 ~6 ~110 glowstone 0
fill ~22 ~6 ~111 ~29 ~6 ~111 yellow_glazed_terracotta 0
setblock ~22 ~6 ~112 glowstone 0
fill ~23 ~6 ~89 ~29 ~6 ~89 yellow_glazed_terracotta 0
setblock ~23 ~6 ~90 sponge 0
fill ~23 ~6 ~91 ~29 ~6 ~91 yellow_glazed_terracotta 0
fill ~23 ~6 ~92 ~23 ~6 ~93 yellow_glazed_terracotta 0
setblock ~23 ~6 ~94 sponge 0
setblock ~23 ~6 ~110 sponge 0
fill ~23 ~6 ~112 ~23 ~6 ~113 yellow_glazed_terracotta 0
setblock ~24 ~6 ~20 glowstone 0
setblock ~24 ~6 ~86 glowstone 0
fill ~24 ~6 ~87 ~30 ~6 ~87 yellow_glazed_terracotta 0
setblock ~24 ~6 ~88 glowstone 0
setblock ~24 ~6 ~90 glowstone 0
setblock ~24 ~6 ~92 glowstone 0
fill ~24 ~6 ~93 ~28 ~6 ~93 yellow_glazed_terracotta 0
setblock ~24 ~6 ~94 glowstone 0
fill ~24 ~6 ~95 ~28 ~6 ~95 yellow_glazed_terracotta 0
setblock ~24 ~6 ~96 glowstone 0
fill ~24 ~6 ~97 ~28 ~6 ~97 yellow_glazed_terracotta 0
setblock ~24 ~6 ~98 glowstone 0
fill ~24 ~6 ~99 ~28 ~6 ~99 yellow_glazed_terracotta 0
setblock ~24 ~6 ~110 glowstone 0
setblock ~24 ~6 ~112 glowstone 0
fill ~24 ~6 ~113 ~29 ~6 ~113 yellow_glazed_terracotta 0
setblock ~24 ~6 ~114 glowstone 0
setblock ~25 ~6 ~19 yellow_glazed_terracotta 0
fill ~25 ~6 ~85 ~30 ~6 ~85 yellow_glazed_terracotta 0
fill ~25 ~6 ~86 ~25 ~6 ~85 yellow_glazed_terracotta 0
setblock ~25 ~6 ~88 yellow_glazed_terracotta 0
setblock ~25 ~6 ~90 yellow_glazed_terracotta 0
setblock ~25 ~6 ~92 yellow_glazed_terracotta 0
setblock ~25 ~6 ~94 yellow_glazed_terracotta 0
setblock ~25 ~6 ~96 yellow_glazed_terracotta 0
setblock ~25 ~6 ~98 yellow_glazed_terracotta 0
fill ~25 ~6 ~100 ~25 ~6 ~115 yellow_glazed_terracotta 0
setblock ~26 ~6 ~18 glowstone 0
fill ~26 ~6 ~83 ~31 ~6 ~83 yellow_glazed_terracotta 0
setblock ~26 ~6 ~84 glowstone 0
setblock ~26 ~6 ~86 glowstone 0
setblock ~26 ~6 ~88 glowstone 0
setblock ~26 ~6 ~90 glowstone 0
setblock ~26 ~6 ~92 glowstone 0
setblock ~26 ~6 ~94 glowstone 0
setblock ~26 ~6 ~96 glowstone 0
setblock ~26 ~6 ~98 glowstone 0
setblock ~26 ~6 ~100 glowstone 0
fill ~26 ~6 ~101 ~28 ~6 ~101 yellow_glazed_terracotta 0
setblock ~26 ~6 ~102 glowstone 0
fill ~26 ~6 ~103 ~28 ~6 ~103 yellow_glazed_terracotta 0
setblock ~26 ~6 ~104 glowstone 0
fill ~26 ~6 ~105 ~28 ~6 ~105 yellow_glazed_terracotta 0
setblock ~26 ~6 ~106 glowstone 0
fill ~26 ~6 ~107 ~29 ~6 ~107 yellow_glazed_terracotta 0
setblock ~26 ~6 ~108 glowstone 0
fill ~26 ~6 ~109 ~29 ~6 ~109 yellow_glazed_terracotta 0
setblock ~26 ~6 ~110 glowstone 0
setblock ~26 ~6 ~112 glowstone 0
setblock ~26 ~6 ~114 glowstone 0
fill ~26 ~6 ~115 ~29 ~6 ~115 yellow_glazed_terracotta 0
fill ~27 ~6 ~17 ~28 ~6 ~17 yellow_glazed_terracotta 0
fill ~27 ~6 ~81 ~32 ~6 ~81 yellow_glazed_terracotta 0
setblock ~27 ~6 ~82 sponge 0
setblock ~27 ~6 ~84 yellow_glazed_terracotta 0
setblock ~27 ~6 ~86 sponge 0
setblock ~27 ~6 ~88 yellow_glazed_terracotta 0
setblock ~27 ~6 ~90 sponge 0
setblock ~27 ~6 ~92 yellow_glazed_terracotta 0
setblock ~27 ~6 ~94 sponge 0
setblock ~27 ~6 ~96 yellow_glazed_terracotta 0
setblock ~27 ~6 ~98 sponge 0
setblock ~27 ~6 ~100 yellow_glazed_terracotta 0
setblock ~27 ~6 ~102 sponge 0
setblock ~27 ~6 ~104 yellow_glazed_terracotta 0
setblock ~27 ~6 ~106 sponge 0
setblock ~27 ~6 ~108 yellow_glazed_terracotta 0
setblock ~27 ~6 ~110 sponge 0
setblock ~27 ~6 ~112 yellow_glazed_terracotta 0
setblock ~27 ~6 ~114 sponge 0
setblock ~27 ~6 ~116 yellow_glazed_terracotta 0
setblock ~28 ~6 ~80 glowstone 0
setblock ~28 ~6 ~82 glowstone 0
setblock ~28 ~6 ~84 glowstone 0
setblock ~28 ~6 ~86 glowstone 0
setblock ~28 ~6 ~88 glowstone 0
setblock ~28 ~6 ~90 glowstone 0
setblock ~28 ~6 ~92 glowstone 0
setblock ~28 ~6 ~94 glowstone 0
setblock ~28 ~6 ~96 glowstone 0
setblock ~28 ~6 ~98 glowstone 0
setblock ~28 ~6 ~100 glowstone 0
setblock ~28 ~6 ~102 glowstone 0
setblock ~28 ~6 ~104 glowstone 0
setblock ~28 ~6 ~106 glowstone 0
setblock ~28 ~6 ~108 glowstone 0
setblock ~28 ~6 ~110 glowstone 0
setblock ~28 ~6 ~112 glowstone 0
setblock ~28 ~6 ~114 glowstone 0
setblock ~28 ~6 ~116 glowstone 0
fill ~28 ~6 ~117 ~30 ~6 ~117 yellow_glazed_terracotta 0
setblock ~29 ~6 ~16 yellow_glazed_terracotta 0
fill ~29 ~6 ~78 ~29 ~6 ~91 yellow_glazed_terracotta 0
setblock ~29 ~6 ~108 yellow_glazed_terracotta 0
setblock ~29 ~6 ~110 yellow_glazed_terracotta 0
setblock ~29 ~6 ~112 yellow_glazed_terracotta 0
setblock ~29 ~6 ~114 yellow_glazed_terracotta 0
setblock ~29 ~6 ~116 yellow_glazed_terracotta 0
setblock ~30 ~6 ~16 glowstone 0
fill ~30 ~6 ~75 ~34 ~6 ~75 yellow_glazed_terracotta 0
setblock ~30 ~6 ~76 glowstone 0
fill ~30 ~6 ~77 ~33 ~6 ~77 yellow_glazed_terracotta 0
setblock ~30 ~6 ~78 glowstone 0
fill ~30 ~6 ~79 ~32 ~6 ~79 yellow_glazed_terracotta 0
setblock ~30 ~6 ~80 glowstone 0
setblock ~30 ~6 ~82 glowstone 0
setblock ~30 ~6 ~84 glowstone 0
setblock ~30 ~6 ~86 glowstone 0
setblock ~30 ~6 ~116 glowstone 0
setblock ~31 ~6 ~15 yellow_glazed_terracotta 0
fill ~31 ~6 ~73 ~35 ~6 ~73 yellow_glazed_terracotta 0
setblock ~31 ~6 ~74 sponge 0
setblock ~31 ~6 ~76 yellow_glazed_terracotta 0
setblock ~31 ~6 ~78 sponge 0
setblock ~31 ~6 ~80 yellow_glazed_terracotta 0
setblock ~31 ~6 ~82 sponge 0
setblock ~31 ~6 ~84 yellow_glazed_terracotta 0
setblock ~32 ~6 ~14 glowstone 0
setblock ~32 ~6 ~50 glowstone 0
fill ~32 ~6 ~51 ~36 ~6 ~51 yellow_glazed_terracotta 0
setblock ~32 ~6 ~52 glowstone 0
fill ~32 ~6 ~53 ~36 ~6 ~53 yellow_glazed_terracotta 0
setblock ~32 ~6 ~54 glowstone 0
fill ~32 ~6 ~55 ~36 ~6 ~55 yellow_glazed_terracotta 0
setblock ~32 ~6 ~56 glowstone 0
fill ~32 ~6 ~57 ~36 ~6 ~57 yellow_glazed_terracotta 0
fill ~32 ~6 ~69 ~36 ~6 ~69 yellow_glazed_terracotta 0
setblock ~32 ~6 ~70 glowstone 0
fill ~32 ~6 ~71 ~35 ~6 ~71 yellow_glazed_terracotta 0
setblock ~32 ~6 ~72 glowstone 0
setblock ~32 ~6 ~74 glowstone 0
setblock ~32 ~6 ~76 glowstone 0
setblock ~32 ~6 ~78 glowstone 0
setblock ~32 ~6 ~80 glowstone 0
setblock ~33 ~6 ~14 yellow_glazed_terracotta 0
fill ~33 ~6 ~48 ~33 ~6 ~63 yellow_glazed_terracotta 0
fill ~33 ~6 ~65 ~36 ~6 ~65 yellow_glazed_terracotta 0
fill ~33 ~6 ~66 ~33 ~6 ~78 yellow_glazed_terracotta 0
fill ~34 ~6 ~13 ~36 ~6 ~13 yellow_glazed_terracotta 0
setblock ~34 ~6 ~46 glowstone 0
fill ~34 ~6 ~47 ~36 ~6 ~47 yellow_glazed_terracotta 0
setblock ~34 ~6 ~48 glowstone 0
fill ~34 ~6 ~49 ~36 ~6 ~49 yellow_glazed_terracotta 0
setblock ~34 ~6 ~50 glowstone 0
setblock ~34 ~6 ~52 glowstone 0
setblock ~34 ~6 ~54 glowstone 0
setblock ~34 ~6 ~56 glowstone 0
setblock ~34 ~6 ~58 glowstone 0
fill ~34 ~6 ~59 ~36 ~6 ~59 yellow_glazed_terracotta 0
setblock ~34 ~6 ~60 glowstone 0
fill ~34 ~6 ~61 ~36 ~6 ~61 yellow_glazed_terracotta 0
setblock ~34 ~6 ~62 glowstone 0
fill ~34 ~6 ~63 ~36 ~6 ~63 yellow_glazed_terracotta 0
setblock ~34 ~6 ~64 glowstone 0
setblock ~34 ~6 ~66 glowstone 0
fill ~34 ~6 ~67 ~36 ~6 ~67 yellow_glazed_terracotta 0
setblock ~34 ~6 ~68 glowstone 0
setblock ~34 ~6 ~70 glowstone 0
setblock ~34 ~6 ~72 glowstone 0
setblock ~34 ~6 ~74 glowstone 0
setblock ~34 ~6 ~76 glowstone 0
fill ~35 ~6 ~45 ~37 ~6 ~45 yellow_glazed_terracotta 0
setblock ~35 ~6 ~46 sponge 0
setblock ~35 ~6 ~48 yellow_glazed_terracotta 0
setblock ~35 ~6 ~50 sponge 0
setblock ~35 ~6 ~52 yellow_glazed_terracotta 0
setblock ~35 ~6 ~54 sponge 0
setblock ~35 ~6 ~56 yellow_glazed_terracotta 0
setblock ~35 ~6 ~58 sponge 0
setblock ~35 ~6 ~60 yellow_glazed_terracotta 0
setblock ~35 ~6 ~62 sponge 0
setblock ~35 ~6 ~64 yellow_glazed_terracotta 0
setblock ~35 ~6 ~66 sponge 0
setblock ~35 ~6 ~68 yellow_glazed_terracotta 0
setblock ~35 ~6 ~70 sponge 0
setblock ~35 ~6 ~72 yellow_glazed_terracotta 0
setblock ~36 ~6 ~12 glowstone 0
fill ~36 ~6 ~43 ~38 ~6 ~43 yellow_glazed_terracotta 0
setblock ~36 ~6 ~44 glowstone 0
setblock ~36 ~6 ~46 glowstone 0
setblock ~36 ~6 ~48 glowstone 0
setblock ~36 ~6 ~50 glowstone 0
setblock ~36 ~6 ~54 glowstone 0
setblock ~36 ~6 ~56 glowstone 0
setblock ~36 ~6 ~58 glowstone 0
setblock ~36 ~6 ~60 glowstone 0
setblock ~36 ~6 ~62 glowstone 0
setblock ~36 ~6 ~64 glowstone 0
setblock ~36 ~6 ~66 glowstone 0
setblock ~36 ~6 ~68 glowstone 0
setblock ~37 ~6 ~12 yellow_glazed_terracotta 0
fill ~37 ~6 ~41 ~39 ~6 ~41 yellow_glazed_terracotta 0
fill ~37 ~6 ~42 ~37 ~6 ~41 yellow_glazed_terracotta 0
setblock ~37 ~6 ~44 yellow_glazed_terracotta 0
setblock ~37 ~6 ~46 yellow_glazed_terracotta 0
setblock ~38 ~6 ~12 glowstone 0
fill ~38 ~6 ~39 ~40 ~6 ~39 yellow_glazed_terracotta 0
setblock ~38 ~6 ~40 glowstone 0
setblock ~38 ~6 ~42 glowstone 0
setblock ~38 ~6 ~44 glowstone 0
setblock ~39 ~6 ~12 yellow_glazed_terracotta 0
fill ~39 ~6 ~37 ~41 ~6 ~37 yellow_glazed_terracotta 0
setblock ~39 ~6 ~38 sponge 0
setblock ~39 ~6 ~40 yellow_glazed_terracotta 0
fill ~40 ~6 ~11 ~56 ~6 ~11 yellow_glazed_terracotta 0
setblock ~40 ~6 ~12 glowstone 0
setblock ~40 ~6 ~36 glowstone 0
setblock ~40 ~6 ~38 glowstone 0
setblock ~41 ~6 ~12 yellow_glazed_terracotta 0
fill ~41 ~6 ~34 ~41 ~6 ~37 yellow_glazed_terracotta 0
setblock ~42 ~6 ~12 glowstone 0
setblock ~42 ~6 ~32 glowstone 0
fill ~42 ~6 ~33 ~43 ~6 ~33 yellow_glazed_terracotta 0
setblock ~42 ~6 ~34 glowstone 0
setblock ~42 ~6 ~35 yellow_glazed_terracotta 0
fill ~43 ~6 ~31 ~44 ~6 ~31 yellow_glazed_terracotta 0
fill ~43 ~6 ~32 ~43 ~6 ~31 yellow_glazed_terracotta 0
setblock ~44 ~6 ~12 glowstone 0
fill ~44 ~6 ~29 ~45 ~6 ~29 yellow_glazed_terracotta 0
setblock ~44 ~6 ~30 glowstone 0
setblock ~45 ~6 ~10 yellow_glazed_terracotta 0
setblock ~45 ~6 ~12 yellow_glazed_terracotta 0
setblock ~45 ~6 ~28 yellow_glazed_terracotta 0
setblock ~45 ~6 ~30 yellow_glazed_terracotta 0
setblock ~46 ~6 ~10 glowstone 0
setblock ~46 ~6 ~12 glowstone 0
fill ~46 ~6 ~27 ~47 ~6 ~27 yellow_glazed_terracotta 0
setblock ~46 ~6 ~28 glowstone 0
setblock ~47 ~6 ~10 sponge 0
setblock ~47 ~6 ~26 sponge 0
setblock ~48 ~6 ~10 glowstone 0
setblock ~48 ~6 ~24 glowstone 0
fill ~48 ~6 ~25 ~49 ~6 ~25 yellow_glazed_terracotta 0
setblock ~48 ~6 ~26 glowstone 0
setblock ~49 ~6 ~10 yellow_glazed_terracotta 0
fill ~49 ~6 ~23 ~50 ~6 ~23 yellow_glazed_terracotta 0
fill ~49 ~6 ~24 ~49 ~6 ~23 yellow_glazed_terracotta 0
setblock ~50 ~6 ~10 glowstone 0
setblock ~50 ~6 ~12 glowstone 0
setblock ~50 ~6 ~22 glowstone 0
setblock ~51 ~6 ~10 sponge 0
setblock ~51 ~6 ~12 yellow_glazed_terracotta 0
fill ~51 ~6 ~20 ~51 ~6 ~21 yellow_glazed_terracotta 0
setblock ~51 ~6 ~22 sponge 0
setblock ~52 ~6 ~10 glowstone 0
setblock ~52 ~6 ~12 glowstone 0
fill ~52 ~6 ~13 ~57 ~6 ~13 yellow_glazed_terracotta 0
setblock ~52 ~6 ~18 glowstone 0
fill ~52 ~6 ~19 ~54 ~6 ~19 yellow_glazed_terracotta 0
setblock ~52 ~6 ~20 glowstone 0
setblock ~52 ~6 ~21 yellow_glazed_terracotta 0
setblock ~53 ~6 ~10 yellow_glazed_terracotta 0
setblock ~53 ~6 ~12 yellow_glazed_terracotta 0
fill ~53 ~6 ~14 ~53 ~6 ~20 yellow_glazed_terracotta 0
setblock ~54 ~6 ~10 glowstone 0
setblock ~54 ~6 ~12 glowstone 0
setblock ~54 ~6 ~14 glowstone 0
fill ~54 ~6 ~15 ~57 ~6 ~15 yellow_glazed_terracotta 0
setblock ~54 ~6 ~16 glowstone 0
fill ~54 ~6 ~17 ~55 ~6 ~17 yellow_glazed_terracotta 0
setblock ~54 ~6 ~18 glowstone 0
setblock ~55 ~6 ~10 sponge 0
setblock ~55 ~6 ~12 yellow_glazed_terracotta 0
setblock ~55 ~6 ~14 sponge 0
setblock ~55 ~6 ~16 yellow_glazed_terracotta 0
setblock ~55 ~6 ~18 sponge 0
setblock ~56 ~6 ~12 glowstone 0
setblock ~56 ~6 ~14 glowstone 0
setblock ~56 ~6 ~16 glowstone 0
setblock ~57 ~6 ~12 yellow_glazed_terracotta 0
setblock ~57 ~6 ~14 yellow_glazed_terracotta 0
fill ~1 ~7 ~77 ~1 ~10 ~77 yellow_glazed_terracotta 0
fill ~1 ~7 ~78 ~1 ~10 ~78 yellow_glazed_terracotta 0
fill ~1 ~7 ~79 ~1 ~10 ~79 yellow_glazed_terracotta 0
fill ~1 ~7 ~83 ~1 ~9 ~83 yellow_glazed_terracotta 0
fill ~1 ~7 ~84 ~1 ~7 ~77 yellow_glazed_terracotta 0
setblock ~2 ~7 ~65 sponge 0
setblock ~2 ~7 ~66 yellow_glazed_terracotta 0
setblock ~2 ~7 ~67 sponge 0
setblock ~2 ~7 ~68 yellow_glazed_terracotta 0
setblock ~2 ~7 ~69 sponge 0
setblock ~2 ~7 ~70 yellow_glazed_terracotta 0
setblock ~2 ~7 ~71 sponge 0
setblock ~2 ~7 ~72 yellow_glazed_terracotta 0
setblock ~2 ~7 ~73 sponge 0
setblock ~2 ~7 ~74 yellow_glazed_terracotta 0
setblock ~2 ~7 ~75 sponge 0
setblock ~2 ~7 ~76 yellow_glazed_terracotta 0
setblock ~2 ~7 ~85 sponge 0
setblock ~2 ~7 ~86 yellow_glazed_terracotta 0
fill ~3 ~7 ~57 ~3 ~9 ~57 yellow_glazed_terracotta 0
fill ~3 ~7 ~58 ~3 ~7 ~57 yellow_glazed_terracotta 0
setblock ~3 ~7 ~62 yellow_glazed_terracotta 0
setblock ~3 ~7 ~88 yellow_glazed_terracotta 0
setblock ~4 ~7 ~53 sponge 0
setblock ~4 ~7 ~54 yellow_glazed_terracotta 0
setblock ~4 ~7 ~55 glowstone 0
setblock ~4 ~7 ~56 yellow_glazed_terracotta 0
setblock ~4 ~7 ~89 glowstone 0
fill ~5 ~7 ~50 ~5 ~8 ~50 yellow_glazed_terracotta 0
fill ~5 ~7 ~91 ~5 ~11 ~91 yellow_glazed_terracotta 0
setblock ~6 ~7 ~49 sponge 0
setblock ~6 ~7 ~92 yellow_glazed_terracotta 0
setblock ~7 ~7 ~46 yellow_glazed_terracotta 0
fill ~7 ~7 ~93 ~7 ~7 ~94 yellow_glazed_terracotta 0
setblock ~8 ~7 ~44 yellow_glazed_terracotta 0
setblock ~8 ~7 ~45 sponge 0
setblock ~8 ~7 ~95 sponge 0
fill ~9 ~7 ~96 ~9 ~7 ~97 yellow_glazed_terracotta 0
setblock ~10 ~7 ~40 yellow_glazed_terracotta 0
setblock ~10 ~7 ~41 sponge 0
setblock ~10 ~7 ~42 yellow_glazed_terracotta 0
setblock ~10 ~7 ~98 yellow_glazed_terracotta 0
setblock ~11 ~7 ~38 yellow_glazed_terracotta 0
fill ~11 ~7 ~99 ~11 ~6 ~99 yellow_glazed_terracotta 0
fill ~11 ~7 ~100 ~11 ~7 ~99 yellow_glazed_terracotta 0
setblock ~12 ~7 ~34 yellow_glazed_terracotta 0
setblock ~12 ~7 ~35 glowstone 0
setblock ~12 ~7 ~36 yellow_glazed_terracotta 0
setblock ~12 ~7 ~37 sponge 0
setblock ~12 ~7 ~101 glowstone 0
setblock ~13 ~7 ~32 yellow_glazed_terracotta 0
fill ~13 ~7 ~102 ~13 ~7 ~103 yellow_glazed_terracotta 0
setblock ~14 ~7 ~31 sponge 0
setblock ~14 ~7 ~104 yellow_glazed_terracotta 0
setblock ~15 ~7 ~30 yellow_glazed_terracotta 0
setblock ~15 ~7 ~105 yellow_glazed_terracotta 0
setblock ~16 ~7 ~27 glowstone 0
setblock ~16 ~7 ~28 yellow_glazed_terracotta 0
setblock ~16 ~7 ~106 yellow_glazed_terracotta 0
setblock ~16 ~7 ~107 sponge 0
setblock ~17 ~7 ~108 yellow_glazed_terracotta 0
setblock ~18 ~7 ~25 sponge 0
setblock ~18 ~7 ~109 sponge 0
setblock ~19 ~7 ~24 yellow_glazed_terracotta 0
setblock ~19 ~7 ~110 yellow_glazed_terracotta 0
setblock ~20 ~7 ~23 glowstone 0
setblock ~20 ~7 ~111 sponge 0
fill ~21 ~7 ~112 ~21 ~7 ~113 yellow_glazed_terracotta 0
setblock ~22 ~7 ~21 sponge 0
setblock ~22 ~7 ~113 sponge 0
fill ~22 ~7 ~114 ~23 ~7 ~114 yellow_glazed_terracotta 0
setblock ~23 ~7 ~20 yellow_glazed_terracotta 0
setblock ~23 ~7 ~115 yellow_glazed_terracotta 0
setblock ~24 ~7 ~19 glowstone 0
setblock ~24 ~7 ~115 sponge 0
fill ~25 ~7 ~18 ~26 ~7 ~18 yellow_glazed_terracotta 0
fill ~25 ~7 ~116 ~26 ~7 ~116 yellow_glazed_terracotta 0
setblock ~26 ~7 ~117 sponge 0
fill ~27 ~7 ~17 ~27 ~6 ~17 yellow_glazed_terracotta 0
fill ~27 ~7 ~117 ~27 ~7 ~118 yellow_glazed_terracotta 0
setblock ~28 ~7 ~16 yellow_glazed_terracotta 0
fill ~28 ~7 ~118 ~35 ~7 ~118 yellow_glazed_terracotta 0
setblock ~28 ~7 ~119 sponge 0
fill ~29 ~7 ~15 ~29 ~8 ~15 yellow_glazed_terracotta 0
fill ~29 ~7 ~92 ~33 ~7 ~92 yellow_glazed_terracotta 0
fill ~29 ~7 ~93 ~29 ~7 ~106 yellow_glazed_terracotta 0
fill ~29 ~7 ~119 ~29 ~7 ~120 yellow_glazed_terracotta 0
setblock ~30 ~7 ~15 sponge 0
fill ~30 ~7 ~88 ~34 ~7 ~88 yellow_glazed_terracotta 0
setblock ~30 ~7 ~89 sponge 0
fill ~30 ~7 ~90 ~34 ~7 ~90 yellow_glazed_terracotta 0
setblock ~30 ~7 ~91 sponge 0
setblock ~30 ~7 ~93 sponge 0
fill ~30 ~7 ~94 ~33 ~7 ~94 yellow_glazed_terracotta 0
setblock ~30 ~7 ~95 sponge 0
fill ~30 ~7 ~96 ~33 ~7 ~96 yellow_glazed_terracotta 0
setblock ~30 ~7 ~97 sponge 0
fill ~30 ~7 ~98 ~32 ~7 ~98 yellow_glazed_terracotta 0
setblock ~30 ~7 ~99 sponge 0
fill ~30 ~7 ~100 ~32 ~7 ~100 yellow_glazed_terracotta 0
setblock ~30 ~7 ~101 sponge 0
fill ~30 ~7 ~102 ~32 ~7 ~102 yellow_glazed_terracotta 0
setblock ~30 ~7 ~103 sponge 0
fill ~30 ~7 ~104 ~31 ~7 ~104 yellow_glazed_terracotta 0
setblock ~30 ~7 ~105 sponge 0
fill ~30 ~7 ~106 ~32 ~7 ~106 yellow_glazed_terracotta 0
setblock ~30 ~7 ~107 sponge 0
fill ~30 ~7 ~108 ~32 ~7 ~108 yellow_glazed_terracotta 0
setblock ~30 ~7 ~109 sponge 0
fill ~30 ~7 ~110 ~32 ~7 ~110 yellow_glazed_terracotta 0
setblock ~30 ~7 ~111 sponge 0
fill ~30 ~7 ~112 ~33 ~7 ~112 yellow_glazed_terracotta 0
setblock ~30 ~7 ~113 sponge 0
fill ~30 ~7 ~114 ~33 ~7 ~114 yellow_glazed_terracotta 0
setblock ~30 ~7 ~115 sponge 0
setblock ~30 ~7 ~119 sponge 0
fill ~30 ~7 ~120 ~36 ~7 ~120 yellow_glazed_terracotta 0
setblock ~30 ~7 ~121 sponge 0
setblock ~31 ~7 ~14 yellow_glazed_terracotta 0
fill ~31 ~7 ~85 ~31 ~7 ~122 yellow_glazed_terracotta 0
setblock ~32 ~7 ~13 sponge 0
fill ~32 ~7 ~82 ~36 ~7 ~82 yellow_glazed_terracotta 0
setblock ~32 ~7 ~83 sponge 0
fill ~32 ~7 ~84 ~35 ~7 ~84 yellow_glazed_terracotta 0
setblock ~32 ~7 ~85 glowstone 0
fill ~32 ~7 ~86 ~35 ~7 ~86 yellow_glazed_terracotta 0
setblock ~32 ~7 ~87 sponge 0
setblock ~32 ~7 ~89 glowstone 0
setblock ~32 ~7 ~91 sponge 0
setblock ~32 ~7 ~93 glowstone 0
setblock ~32 ~7 ~95 sponge 0
setblock ~32 ~7 ~97 glowstone 0
setblock ~32 ~7 ~99 sponge 0
setblock ~32 ~7 ~101 glowstone 0
setblock ~32 ~7 ~103 sponge 0
setblock ~32 ~7 ~105 glowstone 0
setblock ~32 ~7 ~107 sponge 0
setblock ~32 ~7 ~109 glowstone 0
setblock ~32 ~7 ~111 sponge 0
setblock ~32 ~7 ~113 glowstone 0
setblock ~32 ~7 ~115 sponge 0
fill ~32 ~7 ~116 ~34 ~7 ~116 yellow_glazed_terracotta 0
setblock ~32 ~7 ~117 glowstone 0
setblock ~32 ~7 ~119 sponge 0
setblock ~32 ~7 ~121 glowstone 0
fill ~32 ~7 ~122 ~36 ~7 ~122 yellow_glazed_terracotta 0
setblock ~32 ~7 ~123 sponge 0
setblock ~33 ~7 ~13 yellow_glazed_terracotta 0
fill ~33 ~7 ~79 ~33 ~7 ~96 yellow_glazed_terracotta 0
setblock ~33 ~7 ~113 yellow_glazed_terracotta 0
setblock ~33 ~7 ~115 yellow_glazed_terracotta 0
setblock ~33 ~7 ~117 yellow_glazed_terracotta 0
setblock ~33 ~7 ~119 yellow_glazed_terracotta 0
setblock ~33 ~7 ~121 yellow_glazed_terracotta 0
setblock ~33 ~7 ~123 yellow_glazed_terracotta 0
fill ~34 ~7 ~12 ~35 ~7 ~12 yellow_glazed_terracotta 0
setblock ~34 ~7 ~77 sponge 0
fill ~34 ~7 ~78 ~37 ~7 ~78 yellow_glazed_terracotta 0
setblock ~34 ~7 ~79 sponge 0
fill ~34 ~7 ~80 ~36 ~7 ~80 yellow_glazed_terracotta 0
setblock ~34 ~7 ~81 sponge 0
setblock ~34 ~7 ~83 sponge 0
setblock ~34 ~7 ~85 sponge 0
setblock ~34 ~7 ~87 sponge 0
setblock ~34 ~7 ~89 sponge 0
setblock ~34 ~7 ~91 sponge 0
setblock ~34 ~7 ~117 sponge 0
setblock ~34 ~7 ~119 sponge 0
setblock ~34 ~7 ~121 sponge 0
setblock ~34 ~7 ~123 sponge 0
fill ~34 ~7 ~124 ~36 ~7 ~124 yellow_glazed_terracotta 0
fill ~35 ~7 ~74 ~38 ~7 ~74 yellow_glazed_terracotta 0
fill ~35 ~7 ~75 ~35 ~7 ~86 yellow_glazed_terracotta 0
setblock ~35 ~7 ~119 yellow_glazed_terracotta 0
setblock ~35 ~7 ~121 yellow_glazed_terracotta 0
setblock ~35 ~7 ~123 yellow_glazed_terracotta 0
setblock ~36 ~7 ~11 glowstone 0
fill ~36 ~7 ~52 ~40 ~7 ~52 yellow_glazed_terracotta 0
fill ~36 ~7 ~70 ~40 ~7 ~70 yellow_glazed_terracotta 0
setblock ~36 ~7 ~71 sponge 0
fill ~36 ~7 ~72 ~39 ~7 ~72 yellow_glazed_terracotta 0
setblock ~36 ~7 ~73 glowstone 0
setblock ~36 ~7 ~75 sponge 0
fill ~36 ~7 ~76 ~38 ~7 ~76 yellow_glazed_terracotta 0
setblock ~36 ~7 ~77 glowstone 0
setblock ~36 ~7 ~79 sponge 0
setblock ~36 ~7 ~81 glowstone 0
setblock ~36 ~7 ~83 sponge 0
setblock ~36 ~7 ~121 glowstone 0
setblock ~36 ~7 ~123 sponge 0
setblock ~37 ~7 ~11 yellow_glazed_terracotta 0
fill ~37 ~7 ~47 ~37 ~7 ~79 yellow_glazed_terracotta 0
setblock ~38 ~7 ~11 sponge 0
setblock ~38 ~7 ~45 sponge 0
fill ~38 ~7 ~46 ~40 ~7 ~46 yellow_glazed_terracotta 0
setblock ~38 ~7 ~47 sponge 0
fill ~38 ~7 ~48 ~40 ~7 ~48 yellow_glazed_terracotta 0
setblock ~38 ~7 ~49 sponge 0
fill ~38 ~7 ~50 ~40 ~7 ~50 yellow_glazed_terracotta 0
setblock ~38 ~7 ~51 sponge 0
setblock ~38 ~7 ~53 sponge 0
fill ~38 ~7 ~54 ~40 ~7 ~54 yellow_glazed_terracotta 0
setblock ~38 ~7 ~55 sponge 0
fill ~38 ~7 ~56 ~40 ~7 ~56 yellow_glazed_terracotta 0
setblock ~38 ~7 ~57 sponge 0
fill ~38 ~7 ~58 ~40 ~7 ~58 yellow_glazed_terracotta 0
setblock ~38 ~7 ~59 sponge 0
fill ~38 ~7 ~60 ~40 ~7 ~60 yellow_glazed_terracotta 0
setblock ~38 ~7 ~61 sponge 0
fill ~38 ~7 ~62 ~40 ~7 ~62 yellow_glazed_terracotta 0
setblock ~38 ~7 ~63 sponge 0
fill ~38 ~7 ~64 ~40 ~7 ~64 yellow_glazed_terracotta 0
setblock ~38 ~7 ~65 sponge 0
fill ~38 ~7 ~66 ~40 ~7 ~66 yellow_glazed_terracotta 0
setblock ~38 ~7 ~67 sponge 0
fill ~38 ~7 ~68 ~40 ~7 ~68 yellow_glazed_terracotta 0
setblock ~38 ~7 ~69 sponge 0
setblock ~38 ~7 ~71 sponge 0
setblock ~38 ~7 ~73 sponge 0
setblock ~38 ~7 ~75 sponge 0
fill ~39 ~7 ~10 ~44 ~7 ~10 yellow_glazed_terracotta 0
fill ~39 ~7 ~11 ~39 ~7 ~10 yellow_glazed_terracotta 0
fill ~39 ~7 ~42 ~41 ~7 ~42 yellow_glazed_terracotta 0
fill ~39 ~7 ~43 ~39 ~7 ~73 yellow_glazed_terracotta 0
fill ~40 ~7 ~40 ~42 ~7 ~40 yellow_glazed_terracotta 0
setblock ~40 ~7 ~41 sponge 0
setblock ~40 ~7 ~43 glowstone 0
fill ~40 ~7 ~44 ~41 ~7 ~44 yellow_glazed_terracotta 0
setblock ~40 ~7 ~45 sponge 0
setblock ~40 ~7 ~47 glowstone 0
setblock ~40 ~7 ~49 sponge 0
setblock ~40 ~7 ~51 glowstone 0
setblock ~40 ~7 ~53 sponge 0
setblock ~40 ~7 ~55 glowstone 0
setblock ~40 ~7 ~57 sponge 0
setblock ~40 ~7 ~59 glowstone 0
setblock ~40 ~7 ~61 sponge 0
setblock ~40 ~7 ~63 glowstone 0
setblock ~40 ~7 ~65 sponge 0
setblock ~40 ~7 ~67 glowstone 0
setblock ~40 ~7 ~69 glowstone 0
fill ~41 ~7 ~38 ~43 ~7 ~38 yellow_glazed_terracotta 0
fill ~41 ~7 ~39 ~41 ~7 ~38 yellow_glazed_terracotta 0
setblock ~41 ~7 ~41 yellow_glazed_terracotta 0
setblock ~41 ~7 ~43 yellow_glazed_terracotta 0
setblock ~41 ~7 ~45 yellow_glazed_terracotta 0
fill ~42 ~7 ~36 ~43 ~7 ~36 yellow_glazed_terracotta 0
setblock ~42 ~7 ~37 sponge 0
setblock ~42 ~7 ~39 sponge 0
setblock ~42 ~7 ~41 sponge 0
setblock ~43 ~7 ~9 yellow_glazed_terracotta 0
fill ~43 ~7 ~34 ~44 ~7 ~34 yellow_glazed_terracotta 0
fill ~43 ~7 ~35 ~43 ~7 ~34 yellow_glazed_terracotta 0
setblock ~43 ~7 ~37 yellow_glazed_terracotta 0
setblock ~44 ~7 ~9 sponge 0
fill ~44 ~7 ~32 ~46 ~7 ~32 yellow_glazed_terracotta 0
setblock ~44 ~7 ~33 sponge 0
setblock ~44 ~7 ~35 glowstone 0
setblock ~45 ~7 ~9 yellow_glazed_terracotta 0
setblock ~45 ~7 ~31 yellow_glazed_terracotta 0
setblock ~45 ~7 ~33 yellow_glazed_terracotta 0
setblock ~46 ~7 ~9 sponge 0
setblock ~46 ~7 ~29 sponge 0
fill ~46 ~7 ~30 ~47 ~7 ~30 yellow_glazed_terracotta 0
setblock ~46 ~7 ~31 sponge 0
fill ~47 ~7 ~8 ~60 ~7 ~8 yellow_glazed_terracotta 0
fill ~47 ~7 ~9 ~47 ~7 ~8 yellow_glazed_terracotta 0
fill ~47 ~7 ~28 ~48 ~7 ~28 yellow_glazed_terracotta 0
fill ~47 ~7 ~29 ~47 ~7 ~28 yellow_glazed_terracotta 0
setblock ~48 ~7 ~9 sponge 0
setblock ~48 ~7 ~27 glowstone 0
setblock ~49 ~7 ~9 yellow_glazed_terracotta 0
fill ~49 ~7 ~26 ~50 ~7 ~26 yellow_glazed_terracotta 0
fill ~49 ~7 ~27 ~49 ~7 ~26 yellow_glazed_terracotta 0
setblock ~50 ~7 ~9 sponge 0
fill ~50 ~7 ~24 ~52 ~7 ~24 yellow_glazed_terracotta 0
setblock ~50 ~7 ~25 sponge 0
setblock ~51 ~7 ~9 yellow_glazed_terracotta 0
setblock ~51 ~7 ~23 yellow_glazed_terracotta 0
setblock ~51 ~7 ~25 yellow_glazed_terracotta 0
setblock ~52 ~7 ~9 sponge 0
fill ~52 ~7 ~22 ~54 ~7 ~22 yellow_glazed_terracotta 0
setblock ~52 ~7 ~23 glowstone 0
setblock ~53 ~7 ~9 yellow_glazed_terracotta 0
setblock ~53 ~7 ~21 yellow_glazed_terracotta 0
setblock ~53 ~7 ~23 yellow_glazed_terracotta 0
setblock ~54 ~7 ~9 sponge 0
fill ~54 ~7 ~20 ~56 ~7 ~20 yellow_glazed_terracotta 0
setblock ~54 ~7 ~21 sponge 0
setblock ~55 ~7 ~9 yellow_glazed_terracotta 0
setblock ~55 ~7 ~19 yellow_glazed_terracotta 0
setblock ~55 ~7 ~21 yellow_glazed_terracotta 0
setblock ~56 ~7 ~9 sponge 0
fill ~56 ~7 ~10 ~63 ~7 ~10 yellow_glazed_terracotta 0
setblock ~56 ~7 ~17 sponge 0
fill ~56 ~7 ~18 ~59 ~7 ~18 yellow_glazed_terracotta 0
setblock ~56 ~7 ~19 glowstone 0
setblock ~57 ~7 ~9 yellow_glazed_terracotta 0
setblock ~57 ~7 ~11 yellow_glazed_terracotta 0
fill ~57 ~7 ~16 ~61 ~7 ~16 yellow_glazed_terracotta 0
fill ~57 ~7 ~17 ~57 ~7 ~16 yellow_glazed_terracotta 0
setblock ~57 ~7 ~19 yellow_glazed_terracotta 0
setblock ~58 ~7 ~9 sponge 0
setblock ~58 ~7 ~11 sponge 0
fill ~58 ~7 ~12 ~64 ~7 ~12 yellow_glazed_terracotta 0
setblock ~58 ~7 ~13 sponge 0
fill ~58 ~7 ~14 ~62 ~7 ~14 yellow_glazed_terracotta 0
setblock ~58 ~7 ~15 sponge 0
setblock ~58 ~7 ~17 sponge 0
setblock ~59 ~7 ~9 yellow_glazed_terracotta 0
setblock ~59 ~7 ~11 yellow_glazed_terracotta 0
setblock ~59 ~7 ~13 yellow_glazed_terracotta 0
setblock ~59 ~7 ~15 yellow_glazed_terracotta 0
setblock ~59 ~7 ~17 yellow_glazed_terracotta 0
setblock ~60 ~7 ~9 sponge 0
setblock ~60 ~7 ~11 glowstone 0
setblock ~60 ~7 ~13 sponge 0
setblock ~60 ~7 ~15 glowstone 0
setblock ~60 ~7 ~17 sponge 0
setblock ~61 ~7 ~9 yellow_glazed_terracotta 0
setblock ~61 ~7 ~11 yellow_glazed_terracotta 0
setblock ~61 ~7 ~13 yellow_glazed_terracotta 0
setblock ~61 ~7 ~15 yellow_glazed_terracotta 0
setblock ~62 ~7 ~11 sponge 0
setblock ~62 ~7 ~13 sponge 0
setblock ~62 ~7 ~15 sponge 0
setblock ~63 ~7 ~11 yellow_glazed_terracotta 0
setblock ~63 ~7 ~13 yellow_glazed_terracotta 0
fill ~1 ~8 ~75 ~1 ~9 ~75 yellow_glazed_terracotta 0
setblock ~1 ~8 ~76 sponge 0
setblock ~1 ~8 ~80 sponge 0
setblock ~1 ~8 ~84 sponge 0
setblock ~2 ~8 ~63 yellow_glazed_terracotta 0
setblock ~2 ~8 ~64 glowstone 0
setblock ~2 ~8 ~65 yellow_glazed_terracotta 0
setblock ~2 ~8 ~66 glowstone 0
setblock ~2 ~8 ~67 yellow_glazed_terracotta 0
setblock ~2 ~8 ~68 glowstone 0
setblock ~2 ~8 ~69 yellow_glazed_terracotta 0
setblock ~2 ~8 ~70 glowstone 0
setblock ~2 ~8 ~71 yellow_glazed_terracotta 0
setblock ~2 ~8 ~72 glowstone 0
setblock ~2 ~8 ~73 yellow_glazed_terracotta 0
setblock ~2 ~8 ~74 glowstone 0
setblock ~2 ~8 ~85 yellow_glazed_terracotta 0
setblock ~2 ~8 ~86 glowstone 0
setblock ~3 ~8 ~58 sponge 0
setblock ~3 ~8 ~60 sponge 0
setblock ~3 ~8 ~62 sponge 0
setblock ~3 ~8 ~88 sponge 0
setblock ~4 ~8 ~53 yellow_glazed_terracotta 0
setblock ~4 ~8 ~54 glowstone 0
setblock ~4 ~8 ~55 yellow_glazed_terracotta 0
setblock ~4 ~8 ~56 glowstone 0
setblock ~4 ~8 ~89 yellow_glazed_terracotta 0
setblock ~4 ~8 ~90 glowstone 0
setblock ~5 ~8 ~52 sponge 0
setblock ~6 ~8 ~49 yellow_glazed_terracotta 0
setblock ~6 ~8 ~92 glowstone 0
setblock ~6 ~8 ~93 yellow_glazed_terracotta 0
setblock ~7 ~8 ~46 sponge 0
setblock ~7 ~8 ~48 sponge 0
setblock ~7 ~8 ~94 sponge 0
setblock ~8 ~8 ~45 yellow_glazed_terracotta 0
setblock ~8 ~8 ~95 yellow_glazed_terracotta 0
setblock ~8 ~8 ~96 glowstone 0
setblock ~9 ~8 ~44 sponge 0
fill ~9 ~8 ~97 ~9 ~13 ~97 yellow_glazed_terracotta 0
fill ~9 ~8 ~98 ~9 ~12 ~98 yellow_glazed_terracotta 0
setblock ~10 ~8 ~40 glowstone 0
setblock ~10 ~8 ~41 yellow_glazed_terracotta 0
setblock ~10 ~8 ~42 glowstone 0
setblock ~10 ~8 ~99 yellow_glazed_terracotta 0
setblock ~11 ~8 ~38 sponge 0
setblock ~11 ~8 ~100 sponge 0
fill ~11 ~8 ~101 ~11 ~13 ~101 yellow_glazed_terracotta 0
setblock ~12 ~8 ~34 glowstone 0
setblock ~12 ~8 ~35 yellow_glazed_terracotta 0
setblock ~12 ~8 ~36 glowstone 0
setblock ~12 ~8 ~37 yellow_glazed_terracotta 0
setblock ~12 ~8 ~102 glowstone 0
setblock ~13 ~8 ~32 sponge 0
setblock ~13 ~8 ~103 yellow_glazed_terracotta 0
setblock ~13 ~8 ~104 sponge 0
setblock ~14 ~8 ~31 yellow_glazed_terracotta 0
setblock ~14 ~8 ~105 yellow_glazed_terracotta 0
setblock ~15 ~8 ~30 sponge 0
setblock ~15 ~8 ~106 sponge 0
setblock ~16 ~8 ~27 yellow_glazed_terracotta 0
setblock ~16 ~8 ~28 glowstone 0
setblock ~16 ~8 ~107 yellow_glazed_terracotta 0
setblock ~16 ~8 ~108 glowstone 0
fill ~17 ~8 ~109 ~17 ~14 ~109 yellow_glazed_terracotta 0
setblock ~18 ~8 ~25 yellow_glazed_terracotta 0
setblock ~18 ~8 ~110 glowstone 0
setblock ~19 ~8 ~24 sponge 0
setblock ~19 ~8 ~111 yellow_glazed_terracotta 0
setblock ~20 ~8 ~23 yellow_glazed_terracotta 0
setblock ~20 ~8 ~112 glowstone 0
fill ~21 ~8 ~113 ~21 ~8 ~114 yellow_glazed_terracotta 0
setblock ~22 ~8 ~21 yellow_glazed_terracotta 0
setblock ~22 ~8 ~115 yellow_glazed_terracotta 0
setblock ~23 ~8 ~20 sponge 0
setblock ~23 ~8 ~116 sponge 0
setblock ~24 ~8 ~19 yellow_glazed_terracotta 0
setblock ~24 ~8 ~116 glowstone 0
fill ~25 ~8 ~18 ~25 ~9 ~18 yellow_glazed_terracotta 0
setblock ~25 ~8 ~117 yellow_glazed_terracotta 0
setblock ~26 ~8 ~17 yellow_glazed_terracotta 0
setblock ~26 ~8 ~118 glowstone 0
fill ~26 ~8 ~119 ~27 ~8 ~119 yellow_glazed_terracotta 0
setblock ~27 ~8 ~16 sponge 0
setblock ~27 ~8 ~120 sponge 0
setblock ~28 ~8 ~16 glowstone 0
setblock ~28 ~8 ~120 glowstone 0
fill ~28 ~8 ~121 ~29 ~8 ~121 yellow_glazed_terracotta 0
setblock ~29 ~8 ~122 yellow_glazed_terracotta 0
setblock ~30 ~8 ~14 glowstone 0
setblock ~30 ~8 ~122 glowstone 0
fill ~30 ~8 ~123 ~31 ~8 ~123 yellow_glazed_terracotta 0
fill ~31 ~8 ~13 ~32 ~8 ~13 yellow_glazed_terracotta 0
setblock ~32 ~8 ~104 glowstone 0
setblock ~32 ~8 ~124 glowstone 0
setblock ~33 ~8 ~12 sponge 0
fill ~33 ~8 ~97 ~36 ~8 ~97 yellow_glazed_terracotta 0
fill ~33 ~8 ~98 ~33 ~8 ~99 yellow_glazed_terracotta 0
setblock ~33 ~8 ~100 sponge 0
fill ~33 ~8 ~101 ~35 ~8 ~101 yellow_glazed_terracotta 0
fill ~33 ~8 ~102 ~33 ~8 ~103 yellow_glazed_terracotta 0
setblock ~33 ~8 ~104 sponge 0
fill ~33 ~8 ~105 ~35 ~8 ~105 yellow_glazed_terracotta 0
fill ~33 ~8 ~106 ~33 ~8 ~107 yellow_glazed_terracotta 0
setblock ~33 ~8 ~108 sponge 0
fill ~33 ~8 ~109 ~35 ~8 ~109 yellow_glazed_terracotta 0
fill ~33 ~8 ~110 ~33 ~8 ~111 yellow_glazed_terracotta 0
setblock ~33 ~8 ~124 sponge 0
fill ~33 ~8 ~125 ~40 ~8 ~125 yellow_glazed_terracotta 0
fill ~34 ~8 ~11 ~35 ~8 ~11 yellow_glazed_terracotta 0
setblock ~34 ~8 ~92 glowstone 0
fill ~34 ~8 ~93 ~37 ~8 ~93 yellow_glazed_terracotta 0
setblock ~34 ~8 ~94 glowstone 0
fill ~34 ~8 ~95 ~37 ~8 ~95 yellow_glazed_terracotta 0
setblock ~34 ~8 ~96 glowstone 0
setblock ~34 ~8 ~98 glowstone 0
fill ~34 ~8 ~99 ~36 ~8 ~99 yellow_glazed_terracotta 0
setblock ~34 ~8 ~100 glowstone 0
setblock ~34 ~8 ~102 glowstone 0
fill ~34 ~8 ~103 ~35 ~8 ~103 yellow_glazed_terracotta 0
setblock ~34 ~8 ~104 glowstone 0
setblock ~34 ~8 ~106 glowstone 0
fill ~34 ~8 ~107 ~35 ~8 ~107 yellow_glazed_terracotta 0
setblock ~34 ~8 ~108 glowstone 0
setblock ~34 ~8 ~110 glowstone 0
fill ~34 ~8 ~111 ~35 ~8 ~111 yellow_glazed_terracotta 0
setblock ~34 ~8 ~112 glowstone 0
fill ~34 ~8 ~113 ~35 ~8 ~113 yellow_glazed_terracotta 0
setblock ~34 ~8 ~114 glowstone 0
fill ~34 ~8 ~115 ~36 ~8 ~115 yellow_glazed_terracotta 0
fill ~35 ~8 ~87 ~39 ~8 ~87 yellow_glazed_terracotta 0
setblock ~35 ~8 ~88 sponge 0
fill ~35 ~8 ~89 ~38 ~8 ~89 yellow_glazed_terracotta 0
setblock ~35 ~8 ~90 sponge 0
fill ~35 ~8 ~91 ~38 ~8 ~91 yellow_glazed_terracotta 0
setblock ~35 ~8 ~92 sponge 0
setblock ~35 ~8 ~94 sponge 0
setblock ~35 ~8 ~96 sponge 0
setblock ~35 ~8 ~98 sponge 0
setblock ~35 ~8 ~100 sponge 0
setblock ~35 ~8 ~102 sponge 0
setblock ~35 ~8 ~104 sponge 0
setblock ~35 ~8 ~106 sponge 0
setblock ~35 ~8 ~108 sponge 0
setblock ~35 ~8 ~110 sponge 0
setblock ~35 ~8 ~112 sponge 0
setblock ~35 ~8 ~114 sponge 0
setblock ~35 ~8 ~116 sponge 0
fill ~35 ~8 ~117 ~37 ~8 ~117 yellow_glazed_terracotta 0
setblock ~35 ~8 ~126 sponge 0
setblock ~36 ~8 ~10 glowstone 0
setblock ~36 ~8 ~84 glowstone 0
fill ~36 ~8 ~85 ~39 ~8 ~85 yellow_glazed_terracotta 0
setblock ~36 ~8 ~86 glowstone 0
setblock ~36 ~8 ~88 glowstone 0
setblock ~36 ~8 ~90 glowstone 0
setblock ~36 ~8 ~92 glowstone 0
setblock ~36 ~8 ~94 glowstone 0
setblock ~36 ~8 ~96 glowstone 0
setblock ~36 ~8 ~98 glowstone 0
setblock ~36 ~8 ~114 glowstone 0
setblock ~36 ~8 ~116 glowstone 0
setblock ~36 ~8 ~118 glowstone 0
fill ~36 ~8 ~119 ~38 ~8 ~119 yellow_glazed_terracotta 0
setblock ~36 ~8 ~126 glowstone 0
setblock ~37 ~8 ~10 yellow_glazed_terracotta 0
setblock ~37 ~8 ~80 sponge 0
fill ~37 ~8 ~81 ~40 ~8 ~81 yellow_glazed_terracotta 0
fill ~37 ~8 ~82 ~37 ~8 ~83 yellow_glazed_terracotta 0
setblock ~37 ~8 ~84 sponge 0
setblock ~37 ~8 ~86 yellow_glazed_terracotta 0
setblock ~37 ~8 ~88 sponge 0
setblock ~37 ~8 ~90 yellow_glazed_terracotta 0
setblock ~37 ~8 ~92 sponge 0
setblock ~37 ~8 ~94 yellow_glazed_terracotta 0
setblock ~37 ~8 ~118 yellow_glazed_terracotta 0
setblock ~37 ~8 ~120 sponge 0
fill ~37 ~8 ~121 ~39 ~8 ~121 yellow_glazed_terracotta 0
fill ~37 ~8 ~122 ~37 ~8 ~123 yellow_glazed_terracotta 0
setblock ~37 ~8 ~124 sponge 0
setblock ~37 ~8 ~126 yellow_glazed_terracotta 0
setblock ~38 ~8 ~10 glowstone 0
fill ~38 ~8 ~77 ~42 ~8 ~77 yellow_glazed_terracotta 0
setblock ~38 ~8 ~78 glowstone 0
fill ~38 ~8 ~79 ~41 ~8 ~79 yellow_glazed_terracotta 0
setblock ~38 ~8 ~80 glowstone 0
setblock ~38 ~8 ~82 glowstone 0
fill ~38 ~8 ~83 ~40 ~8 ~83 yellow_glazed_terracotta 0
setblock ~38 ~8 ~84 glowstone 0
setblock ~38 ~8 ~86 glowstone 0
setblock ~38 ~8 ~88 glowstone 0
setblock ~38 ~8 ~90 glowstone 0
setblock ~38 ~8 ~120 glowstone 0
setblock ~38 ~8 ~122 glowstone 0
fill ~38 ~8 ~123 ~40 ~8 ~123 yellow_glazed_terracotta 0
setblock ~38 ~8 ~124 glowstone 0
setblock ~38 ~8 ~126 glowstone 0
fill ~38 ~8 ~127 ~39 ~8 ~127 yellow_glazed_terracotta 0
fill ~39 ~8 ~9 ~42 ~8 ~9 yellow_glazed_terracotta 0
setblock ~39 ~8 ~74 sponge 0
fill ~39 ~8 ~75 ~42 ~8 ~75 yellow_glazed_terracotta 0
setblock ~39 ~8 ~76 sponge 0
setblock ~39 ~8 ~78 sponge 0
setblock ~39 ~8 ~80 sponge 0
setblock ~39 ~8 ~82 sponge 0
setblock ~39 ~8 ~84 sponge 0
setblock ~39 ~8 ~86 sponge 0
setblock ~39 ~8 ~122 sponge 0
setblock ~39 ~8 ~124 sponge 0
setblock ~39 ~8 ~126 sponge 0
fill ~40 ~8 ~71 ~44 ~8 ~71 yellow_glazed_terracotta 0
setblock ~40 ~8 ~72 glowstone 0
fill ~40 ~8 ~73 ~43 ~8 ~73 yellow_glazed_terracotta 0
setblock ~40 ~8 ~74 glowstone 0
setblock ~40 ~8 ~76 glowstone 0
setblock ~40 ~8 ~78 glowstone 0
setblock ~40 ~8 ~80 glowstone 0
setblock ~40 ~8 ~82 glowstone 0
setblock ~40 ~8 ~124 glowstone 0
setblock ~40 ~8 ~126 glowstone 0
fill ~41 ~8 ~46 ~41 ~8 ~47 yellow_glazed_terracotta 0
setblock ~41 ~8 ~48 sponge 0
fill ~41 ~8 ~49 ~44 ~8 ~49 yellow_glazed_terracotta 0
fill ~41 ~8 ~50 ~41 ~8 ~51 yellow_glazed_terracotta 0
setblock ~41 ~8 ~52 sponge 0
fill ~41 ~8 ~53 ~44 ~8 ~53 yellow_glazed_terracotta 0
fill ~41 ~8 ~54 ~41 ~8 ~55 yellow_glazed_terracotta 0
setblock ~41 ~8 ~56 sponge 0
fill ~41 ~8 ~57 ~45 ~8 ~57 yellow_glazed_terracotta 0
fill ~41 ~8 ~58 ~41 ~8 ~59 yellow_glazed_terracotta 0
setblock ~41 ~8 ~60 sponge 0
fill ~41 ~8 ~61 ~45 ~8 ~61 yellow_glazed_terracotta 0
fill ~41 ~8 ~62 ~41 ~8 ~63 yellow_glazed_terracotta 0
setblock ~41 ~8 ~64 sponge 0
fill ~41 ~8 ~65 ~45 ~8 ~65 yellow_glazed_terracotta 0
fill ~41 ~8 ~66 ~41 ~8 ~67 yellow_glazed_terracotta 0
setblock ~41 ~8 ~68 sponge 0
fill ~41 ~8 ~69 ~44 ~8 ~69 yellow_glazed_terracotta 0
fill ~41 ~8 ~70 ~41 ~8 ~69 yellow_glazed_terracotta 0
setblock ~41 ~8 ~72 sponge 0
setblock ~41 ~8 ~74 yellow_glazed_terracotta 0
setblock ~41 ~8 ~76 sponge 0
setblock ~41 ~8 ~78 yellow_glazed_terracotta 0
setblock ~41 ~8 ~80 sponge 0
setblock ~42 ~8 ~42 glowstone 0
fill ~42 ~8 ~43 ~44 ~8 ~43 yellow_glazed_terracotta 0
setblock ~42 ~8 ~44 glowstone 0
fill ~42 ~8 ~45 ~44 ~8 ~45 yellow_glazed_terracotta 0
setblock ~42 ~8 ~46 glowstone 0
fill ~42 ~8 ~47 ~44 ~8 ~47 yellow_glazed_terracotta 0
setblock ~42 ~8 ~48 glowstone 0
setblock ~42 ~8 ~50 glowstone 0
fill ~42 ~8 ~51 ~44 ~8 ~51 yellow_glazed_terracotta 0
setblock ~42 ~8 ~52 glowstone 0
setblock ~42 ~8 ~54 glowstone 0
fill ~42 ~8 ~55 ~45 ~8 ~55 yellow_glazed_terracotta 0
setblock ~42 ~8 ~56 glowstone 0
setblock ~42 ~8 ~58 glowstone 0
fill ~42 ~8 ~59 ~45 ~8 ~59 yellow_glazed_terracotta 0
setblock ~42 ~8 ~60 glowstone 0
setblock ~42 ~8 ~62 glowstone 0
fill ~42 ~8 ~63 ~45 ~8 ~63 yellow_glazed_terracotta 0
setblock ~42 ~8 ~64 glowstone 0
setblock ~42 ~8 ~66 glowstone 0
fill ~42 ~8 ~67 ~45 ~8 ~67 yellow_glazed_terracotta 0
setblock ~42 ~8 ~68 glowstone 0
setblock ~42 ~8 ~70 glowstone 0
setblock ~42 ~8 ~72 glowstone 0
setblock ~42 ~8 ~74 glowstone 0
setblock ~42 ~8 ~76 glowstone 0
setblock ~43 ~8 ~8 sponge 0
fill ~43 ~8 ~39 ~45 ~8 ~39 yellow_glazed_terracotta 0
setblock ~43 ~8 ~40 sponge 0
fill ~43 ~8 ~41 ~45 ~8 ~41 yellow_glazed_terracotta 0
setblock ~43 ~8 ~42 sponge 0
setblock ~43 ~8 ~44 sponge 0
setblock ~43 ~8 ~46 sponge 0
setblock ~43 ~8 ~48 sponge 0
setblock ~43 ~8 ~50 sponge 0
setblock ~43 ~8 ~52 sponge 0
setblock ~43 ~8 ~54 sponge 0
setblock ~43 ~8 ~56 sponge 0
setblock ~43 ~8 ~58 sponge 0
setblock ~43 ~8 ~60 sponge 0
setblock ~43 ~8 ~62 sponge 0
setblock ~43 ~8 ~64 sponge 0
setblock ~43 ~8 ~66 sponge 0
setblock ~43 ~8 ~68 sponge 0
setblock ~43 ~8 ~70 sponge 0
setblock ~43 ~8 ~72 sponge 0
setblock ~43 ~8 ~74 sponge 0
setblock ~44 ~8 ~8 glowstone 0
setblock ~44 ~8 ~36 glowstone 0
fill ~44 ~8 ~37 ~46 ~8 ~37 yellow_glazed_terracotta 0
setblock ~44 ~8 ~38 glowstone 0
setblock ~44 ~8 ~40 glowstone 0
setblock ~44 ~8 ~42 glowstone 0
setblock ~44 ~8 ~44 glowstone 0
setblock ~44 ~8 ~46 glowstone 0
setblock ~44 ~8 ~48 glowstone 0
setblock ~44 ~8 ~50 glowstone 0
setblock ~44 ~8 ~52 glowstone 0
setblock ~44 ~8 ~54 glowstone 0
setblock ~44 ~8 ~56 glowstone 0
setblock ~44 ~8 ~58 glowstone 0
setblock ~44 ~8 ~60 glowstone 0
setblock ~44 ~8 ~62 glowstone 0
setblock ~44 ~8 ~64 glowstone 0
setblock ~44 ~8 ~66 glowstone 0
setblock ~44 ~8 ~68 glowstone 0
setblock ~44 ~8 ~70 glowstone 0
setblock ~45 ~8 ~8 sponge 0
fill ~45 ~8 ~34 ~45 ~8 ~35 yellow_glazed_terracotta 0
setblock ~45 ~8 ~36 sponge 0
setblock ~45 ~8 ~38 yellow_glazed_terracotta 0
setblock ~45 ~8 ~40 sponge 0
setblock ~45 ~8 ~42 yellow_glazed_terracotta 0
setblock ~45 ~8 ~56 sponge 0
setblock ~45 ~8 ~58 yellow_glazed_terracotta 0
setblock ~45 ~8 ~60 sponge 0
setblock ~45 ~8 ~62 yellow_glazed_terracotta 0
setblock ~45 ~8 ~64 sponge 0
setblock ~45 ~8 ~66 yellow_glazed_terracotta 0
setblock ~45 ~8 ~68 sponge 0
fill ~46 ~8 ~7 ~66 ~8 ~7 yellow_glazed_terracotta 0
setblock ~46 ~8 ~8 glowstone 0
fill ~46 ~8 ~33 ~47 ~8 ~33 yellow_glazed_terracotta 0
setblock ~46 ~8 ~34 glowstone 0
setblock ~46 ~8 ~35 yellow_glazed_terracotta 0
setblock ~46 ~8 ~36 glowstone 0
setblock ~46 ~8 ~38 glowstone 0
fill ~47 ~8 ~31 ~48 ~8 ~31 yellow_glazed_terracotta 0
setblock ~47 ~8 ~32 sponge 0
setblock ~47 ~8 ~34 sponge 0
fill ~48 ~8 ~29 ~50 ~8 ~29 yellow_glazed_terracotta 0
setblock ~48 ~8 ~30 glowstone 0
setblock ~48 ~8 ~32 glowstone 0
setblock ~49 ~8 ~28 sponge 0
setblock ~49 ~8 ~30 yellow_glazed_terracotta 0
setblock ~50 ~8 ~6 glowstone 0
fill ~50 ~8 ~27 ~52 ~8 ~27 yellow_glazed_terracotta 0
setblock ~50 ~8 ~28 glowstone 0
setblock ~51 ~8 ~6 sponge 0
setblock ~51 ~8 ~26 sponge 0
setblock ~51 ~8 ~28 sponge 0
setblock ~52 ~8 ~6 glowstone 0
fill ~52 ~8 ~25 ~54 ~8 ~25 yellow_glazed_terracotta 0
setblock ~52 ~8 ~26 glowstone 0
setblock ~53 ~8 ~6 yellow_glazed_terracotta 0
setblock ~53 ~8 ~24 sponge 0
setblock ~53 ~8 ~26 yellow_glazed_terracotta 0
setblock ~54 ~8 ~6 glowstone 0
fill ~54 ~8 ~23 ~56 ~8 ~23 yellow_glazed_terracotta 0
setblock ~54 ~8 ~24 glowstone 0
setblock ~55 ~8 ~6 sponge 0
setblock ~55 ~8 ~22 sponge 0
setblock ~55 ~8 ~24 sponge 0
setblock ~56 ~8 ~6 glowstone 0
fill ~56 ~8 ~21 ~59 ~8 ~21 yellow_glazed_terracotta 0
setblock ~56 ~8 ~22 glowstone 0
setblock ~57 ~8 ~6 yellow_glazed_terracotta 0
setblock ~57 ~8 ~20 sponge 0
setblock ~57 ~8 ~22 yellow_glazed_terracotta 0
setblock ~58 ~8 ~6 glowstone 0
fill ~58 ~8 ~19 ~62 ~8 ~19 yellow_glazed_terracotta 0
setblock ~58 ~8 ~20 glowstone 0
setblock ~58 ~8 ~22 glowstone 0
setblock ~59 ~8 ~6 sponge 0
setblock ~59 ~8 ~20 sponge 0
setblock ~60 ~8 ~6 glowstone 0
setblock ~60 ~8 ~18 glowstone 0
setblock ~60 ~8 ~20 glowstone 0
setblock ~61 ~8 ~6 yellow_glazed_terracotta 0
setblock ~61 ~8 ~8 sponge 0
fill ~61 ~8 ~17 ~66 ~8 ~17 yellow_glazed_terracotta 0
fill ~61 ~8 ~18 ~61 ~8 ~17 yellow_glazed_terracotta 0
setblock ~61 ~8 ~20 sponge 0
setblock ~62 ~8 ~6 glowstone 0
setblock ~62 ~8 ~8 glowstone 0
fill ~62 ~8 ~9 ~68 ~8 ~9 yellow_glazed_terracotta 0
setblock ~62 ~8 ~16 glowstone 0
setblock ~62 ~8 ~18 glowstone 0
setblock ~63 ~8 ~6 sponge 0
setblock ~63 ~8 ~8 sponge 0
setblock ~63 ~8 ~14 sponge 0
fill ~63 ~8 ~15 ~68 ~8 ~15 yellow_glazed_terracotta 0
setblock ~63 ~8 ~16 sponge 0
setblock ~63 ~8 ~18 sponge 0
setblock ~64 ~8 ~8 glowstone 0
setblock ~64 ~8 ~10 glowstone 0
fill ~64 ~8 ~11 ~69 ~8 ~11 yellow_glazed_terracotta 0
fill ~64 ~8 ~13 ~70 ~8 ~13 yellow_glazed_terracotta 0
setblock ~64 ~8 ~14 glowstone 0
setblock ~64 ~8 ~16 glowstone 0
setblock ~64 ~8 ~18 glowstone 0
setblock ~65 ~8 ~8 sponge 0
setblock ~65 ~8 ~10 yellow_glazed_terracotta 0
setblock ~65 ~8 ~12 sponge 0
setblock ~65 ~8 ~14 yellow_glazed_terracotta 0
setblock ~65 ~8 ~16 sponge 0
setblock ~66 ~8 ~8 glowstone 0
setblock ~66 ~8 ~10 glowstone 0
setblock ~66 ~8 ~12 glowstone 0
setblock ~66 ~8 ~14 glowstone 0
setblock ~66 ~8 ~16 glowstone 0
setblock ~67 ~8 ~8 sponge 0
setblock ~67 ~8 ~10 sponge 0
setblock ~67 ~8 ~12 sponge 0
setblock ~67 ~8 ~14 sponge 0
setblock ~67 ~8 ~16 sponge 0
setblock ~68 ~8 ~10 glowstone 0
setblock ~68 ~8 ~12 glowstone 0
setblock ~68 ~8 ~14 glowstone 0
setblock ~69 ~8 ~10 sponge 0
setblock ~69 ~8 ~12 sponge 0
setblock ~69 ~8 ~14 sponge 0
setblock ~70 ~8 ~12 glowstone 0
setblock ~1 ~9 ~74 yellow_glazed_terracotta 0
fill ~1 ~9 ~76 ~1 ~10 ~76 yellow_glazed_terracotta 0
fill ~1 ~9 ~80 ~1 ~10 ~80 yellow_glazed_terracotta 0
setblock ~2 ~9 ~64 yellow_glazed_terracotta 0
setblock ~2 ~9 ~65 sponge 0
setblock ~2 ~9 ~66 yellow_glazed_terracotta 0
setblock ~2 ~9 ~67 sponge 0
setblock ~2 ~9 ~68 yellow_glazed_terracotta 0
setblock ~2 ~9 ~69 sponge 0
setblock ~2 ~9 ~70 yellow_glazed_terracotta 0
setblock ~2 ~9 ~71 sponge 0
setblock ~2 ~9 ~72 yellow_glazed_terracotta 0
setblock ~2 ~9 ~73 sponge 0
setblock ~2 ~9 ~84 yellow_glazed_terracotta 0
setblock ~2 ~9 ~85 sponge 0
setblock ~2 ~9 ~86 yellow_glazed_terracotta 0
setblock ~3 ~9 ~58 yellow_glazed_terracotta 0
fill ~3 ~9 ~60 ~3 ~11 ~60 yellow_glazed_terracotta 0
fill ~3 ~9 ~62 ~3 ~9 ~63 yellow_glazed_terracotta 0
fill ~3 ~9 ~88 ~3 ~10 ~88 yellow_glazed_terracotta 0
setblock ~4 ~9 ~53 sponge 0
setblock ~4 ~9 ~54 yellow_glazed_terracotta 0
setblock ~4 ~9 ~55 sponge 0
setblock ~4 ~9 ~56 yellow_glazed_terracotta 0
setblock ~4 ~9 ~89 sponge 0
setblock ~4 ~9 ~90 yellow_glazed_terracotta 0
fill ~5 ~9 ~52 ~5 ~11 ~52 yellow_glazed_terracotta 0
setblock ~5 ~9 ~92 yellow_glazed_terracotta 0
setblock ~6 ~9 ~49 sponge 0
setblock ~6 ~9 ~50 yellow_glazed_terracotta 0
setblock ~6 ~9 ~93 sponge 0
fill ~7 ~9 ~48 ~7 ~11 ~48 yellow_glazed_terracotta 0
setblock ~7 ~9 ~94 yellow_glazed_terracotta 0
setblock ~8 ~9 ~45 sponge 0
setblock ~8 ~9 ~46 yellow_glazed_terracotta 0
setblock ~8 ~9 ~95 sponge 0
setblock ~8 ~9 ~96 yellow_glazed_terracotta 0
fill ~9 ~9 ~44 ~9 ~11 ~44 yellow_glazed_terracotta 0
setblock ~10 ~9 ~41 sponge 0
setblock ~10 ~9 ~42 yellow_glazed_terracotta 0
setblock ~10 ~9 ~99 sponge 0
setblock ~10 ~9 ~100 yellow_glazed_terracotta 0
setblock ~11 ~9 ~38 yellow_glazed_terracotta 0
fill ~11 ~9 ~40 ~11 ~11 ~40 yellow_glazed_terracotta 0
setblock ~12 ~9 ~35 sponge 0
setblock ~12 ~9 ~36 yellow_glazed_terracotta 0
setblock ~12 ~9 ~37 sponge 0
setblock ~12 ~9 ~102 yellow_glazed_terracotta 0
setblock ~12 ~9 ~103 sponge 0
setblock ~13 ~9 ~32 yellow_glazed_terracotta 0
fill ~13 ~9 ~34 ~13 ~11 ~34 yellow_glazed_terracotta 0
fill ~13 ~9 ~104 ~13 ~11 ~104 yellow_glazed_terracotta 0
setblock ~14 ~9 ~31 sponge 0
setblock ~14 ~9 ~105 sponge 0
setblock ~15 ~9 ~30 yellow_glazed_terracotta 0
fill ~15 ~9 ~106 ~15 ~9 ~107 yellow_glazed_terracotta 0
setblock ~16 ~9 ~27 sponge 0
