fill ~25 ~0 ~18 ~38 ~0 ~18 netherrack 0
fill ~25 ~0 ~19 ~40 ~0 ~19 netherrack 0
fill ~25 ~0 ~20 ~63 ~0 ~20 netherrack 0
fill ~26 ~0 ~17 ~35 ~0 ~17 netherrack 0
fill ~26 ~0 ~21 ~62 ~0 ~21 netherrack 0
fill ~26 ~0 ~22 ~62 ~0 ~22 netherrack 0
fill ~26 ~0 ~23 ~62 ~0 ~23 netherrack 0
fill ~26 ~0 ~24 ~62 ~0 ~24 netherrack 0
fill ~27 ~0 ~25 ~61 ~0 ~25 netherrack 0
fill ~28 ~0 ~16 ~32 ~0 ~16 netherrack 0
fill ~28 ~0 ~26 ~60 ~0 ~26 netherrack 0
fill ~28 ~0 ~27 ~60 ~0 ~27 netherrack 0
fill ~29 ~0 ~28 ~59 ~0 ~28 netherrack 0
fill ~29 ~0 ~32 ~59 ~0 ~32 netherrack 0
fill ~29 ~0 ~33 ~59 ~0 ~33 netherrack 0
fill ~29 ~0 ~34 ~59 ~0 ~34 netherrack 0
fill ~29 ~0 ~35 ~59 ~0 ~35 netherrack 0
fill ~29 ~0 ~36 ~59 ~0 ~36 netherrack 0
fill ~30 ~0 ~29 ~58 ~0 ~29 netherrack 0
fill ~30 ~0 ~31 ~58 ~0 ~31 netherrack 0
fill ~30 ~0 ~37 ~58 ~0 ~37 netherrack 0
fill ~31 ~0 ~30 ~57 ~0 ~30 netherrack 0
fill ~32 ~0 ~38 ~56 ~0 ~38 netherrack 0
fill ~34 ~0 ~39 ~54 ~0 ~39 netherrack 0
fill ~37 ~0 ~40 ~51 ~0 ~40 netherrack 0
fill ~48 ~0 ~19 ~63 ~0 ~19 netherrack 0
fill ~50 ~0 ~18 ~63 ~0 ~18 netherrack 0
fill ~53 ~0 ~17 ~62 ~0 ~17 netherrack 0
fill ~56 ~0 ~16 ~60 ~0 ~16 netherrack 0
fill ~23 ~1 ~18 ~24 ~1 ~18 netherrack 0
fill ~23 ~1 ~19 ~24 ~1 ~19 netherrack 0
fill ~23 ~1 ~20 ~24 ~1 ~20 netherrack 0
fill ~23 ~1 ~21 ~25 ~1 ~21 netherrack 0
fill ~24 ~1 ~16 ~27 ~1 ~16 netherrack 0
fill ~24 ~1 ~17 ~25 ~1 ~17 netherrack 0
fill ~24 ~1 ~22 ~25 ~1 ~22 netherrack 0
fill ~24 ~1 ~23 ~25 ~1 ~23 netherrack 0
fill ~24 ~1 ~25 ~26 ~1 ~25 netherrack 0
fill ~24 ~1 ~26 ~27 ~1 ~26 netherrack 0
fill ~24 ~1 ~27 ~27 ~1 ~27 netherrack 0
fill ~24 ~1 ~28 ~28 ~1 ~28 netherrack 0
fill ~24 ~1 ~29 ~29 ~1 ~29 netherrack 0
fill ~25 ~1 ~15 ~33 ~1 ~15 netherrack 0
setblock ~25 ~1 ~24 netherrack 0
fill ~25 ~1 ~30 ~30 ~1 ~30 netherrack 0
fill ~25 ~1 ~31 ~29 ~1 ~31 netherrack 0
fill ~25 ~1 ~32 ~28 ~1 ~32 netherrack 0
fill ~25 ~1 ~33 ~28 ~1 ~33 netherrack 0
fill ~25 ~1 ~34 ~28 ~1 ~34 netherrack 0
fill ~26 ~1 ~14 ~31 ~1 ~14 netherrack 0
fill ~26 ~1 ~35 ~28 ~1 ~35 netherrack 0
fill ~26 ~1 ~36 ~28 ~1 ~36 netherrack 0
fill ~27 ~1 ~37 ~29 ~1 ~37 netherrack 0
fill ~28 ~1 ~38 ~31 ~1 ~38 netherrack 0
fill ~29 ~1 ~39 ~33 ~1 ~39 netherrack 0
fill ~31 ~1 ~40 ~36 ~1 ~40 netherrack 0
fill ~33 ~1 ~16 ~36 ~1 ~16 netherrack 0
fill ~33 ~1 ~41 ~55 ~1 ~41 netherrack 0
fill ~36 ~1 ~17 ~38 ~1 ~17 netherrack 0
fill ~37 ~1 ~42 ~51 ~1 ~42 netherrack 0
fill ~39 ~1 ~18 ~42 ~1 ~18 netherrack 0
fill ~41 ~1 ~19 ~47 ~1 ~19 netherrack 0
fill ~46 ~1 ~18 ~49 ~1 ~18 netherrack 0
fill ~50 ~1 ~17 ~52 ~1 ~17 netherrack 0
fill ~52 ~1 ~40 ~57 ~1 ~40 netherrack 0
fill ~53 ~1 ~16 ~55 ~1 ~16 netherrack 0
fill ~55 ~1 ~15 ~63 ~1 ~15 netherrack 0
fill ~55 ~1 ~39 ~59 ~1 ~39 netherrack 0
fill ~57 ~1 ~14 ~62 ~1 ~14 netherrack 0
fill ~57 ~1 ~38 ~60 ~1 ~38 netherrack 0
fill ~58 ~1 ~30 ~63 ~1 ~30 netherrack 0
fill ~59 ~1 ~29 ~64 ~1 ~29 netherrack 0
fill ~59 ~1 ~31 ~63 ~1 ~31 netherrack 0
fill ~59 ~1 ~37 ~61 ~1 ~37 netherrack 0
fill ~60 ~1 ~28 ~64 ~1 ~28 netherrack 0
fill ~60 ~1 ~32 ~63 ~1 ~32 netherrack 0
fill ~60 ~1 ~33 ~63 ~1 ~33 netherrack 0
fill ~60 ~1 ~34 ~63 ~1 ~34 netherrack 0
fill ~60 ~1 ~35 ~62 ~1 ~35 netherrack 0
fill ~60 ~1 ~36 ~62 ~1 ~36 netherrack 0
fill ~61 ~1 ~16 ~64 ~1 ~16 netherrack 0
fill ~61 ~1 ~26 ~64 ~1 ~26 netherrack 0
fill ~61 ~1 ~27 ~64 ~1 ~27 netherrack 0
fill ~62 ~1 ~25 ~64 ~1 ~25 netherrack 0
fill ~63 ~1 ~17 ~65 ~1 ~17 netherrack 0
fill ~63 ~1 ~21 ~65 ~1 ~21 netherrack 0
fill ~63 ~1 ~22 ~64 ~1 ~22 netherrack 0
fill ~63 ~1 ~23 ~64 ~1 ~23 netherrack 0
fill ~63 ~1 ~24 ~64 ~1 ~24 netherrack 0
fill ~64 ~1 ~18 ~65 ~1 ~18 netherrack 0
fill ~64 ~1 ~19 ~65 ~1 ~19 netherrack 0
fill ~64 ~1 ~20 ~65 ~1 ~20 netherrack 0
fill ~21 ~2 ~23 ~23 ~2 ~23 netherrack 0
fill ~21 ~2 ~24 ~24 ~2 ~24 netherrack 0
fill ~21 ~2 ~25 ~23 ~2 ~25 netherrack 0
fill ~21 ~2 ~26 ~23 ~2 ~26 netherrack 0
fill ~21 ~2 ~27 ~23 ~2 ~27 netherrack 0
fill ~21 ~2 ~28 ~23 ~2 ~28 netherrack 0
fill ~21 ~2 ~29 ~23 ~2 ~29 netherrack 0
fill ~21 ~2 ~30 ~24 ~2 ~30 netherrack 0
fill ~22 ~2 ~17 ~23 ~2 ~17 netherrack 0
fill ~22 ~2 ~18 ~22 ~2 ~32 netherrack 0
fill ~23 ~2 ~14 ~25 ~2 ~14 netherrack 0
fill ~23 ~2 ~15 ~24 ~2 ~15 netherrack 0
fill ~23 ~2 ~16 ~23 ~2 ~14 netherrack 0
setblock ~23 ~2 ~22 netherrack 0
fill ~23 ~2 ~31 ~24 ~2 ~31 netherrack 0
fill ~23 ~2 ~32 ~24 ~2 ~32 netherrack 0
fill ~23 ~2 ~33 ~24 ~2 ~33 netherrack 0
fill ~23 ~2 ~34 ~24 ~2 ~34 netherrack 0
fill ~23 ~2 ~35 ~25 ~2 ~35 netherrack 0
fill ~24 ~2 ~36 ~25 ~2 ~36 netherrack 0
fill ~24 ~2 ~37 ~26 ~2 ~37 netherrack 0
fill ~25 ~2 ~13 ~32 ~2 ~13 netherrack 0
fill ~26 ~2 ~38 ~27 ~2 ~38 netherrack 0
fill ~27 ~2 ~12 ~30 ~2 ~12 netherrack 0
fill ~27 ~2 ~39 ~28 ~2 ~39 netherrack 0
fill ~28 ~2 ~40 ~30 ~2 ~40 netherrack 0
fill ~31 ~2 ~41 ~32 ~2 ~41 netherrack 0
fill ~32 ~2 ~14 ~33 ~2 ~14 netherrack 0
fill ~33 ~2 ~42 ~36 ~2 ~42 netherrack 0
fill ~34 ~2 ~15 ~35 ~2 ~15 netherrack 0
fill ~36 ~2 ~16 ~38 ~2 ~16 netherrack 0
fill ~37 ~2 ~43 ~51 ~2 ~43 netherrack 0
fill ~39 ~2 ~17 ~49 ~2 ~17 netherrack 0
fill ~39 ~2 ~19 ~49 ~2 ~19 netherrack 0
fill ~39 ~2 ~20 ~49 ~2 ~20 netherrack 0
fill ~39 ~2 ~21 ~49 ~2 ~21 netherrack 0
fill ~39 ~2 ~22 ~49 ~2 ~22 netherrack 0
fill ~39 ~2 ~23 ~49 ~2 ~23 netherrack 0
fill ~39 ~2 ~24 ~55 ~2 ~24 netherrack 0
fill ~39 ~2 ~25 ~55 ~2 ~25 netherrack 0
fill ~39 ~2 ~26 ~55 ~2 ~26 netherrack 0
fill ~39 ~2 ~27 ~55 ~2 ~27 netherrack 0
fill ~39 ~2 ~28 ~55 ~2 ~28 netherrack 0
fill ~39 ~2 ~29 ~55 ~2 ~29 netherrack 0
fill ~39 ~2 ~30 ~55 ~2 ~30 netherrack 0
fill ~39 ~2 ~31 ~55 ~2 ~31 netherrack 0
fill ~39 ~2 ~32 ~55 ~2 ~32 netherrack 0
fill ~39 ~2 ~33 ~55 ~2 ~33 netherrack 0
fill ~39 ~2 ~34 ~55 ~2 ~34 netherrack 0
fill ~39 ~2 ~35 ~49 ~2 ~35 netherrack 0
fill ~39 ~2 ~36 ~49 ~2 ~36 netherrack 0
fill ~39 ~2 ~37 ~49 ~2 ~37 netherrack 0
fill ~39 ~2 ~38 ~49 ~2 ~38 netherrack 0
fill ~39 ~2 ~39 ~49 ~2 ~39 netherrack 0
fill ~39 ~2 ~40 ~49 ~2 ~40 netherrack 0
fill ~39 ~2 ~41 ~49 ~2 ~41 netherrack 0
fill ~43 ~2 ~18 ~45 ~2 ~18 netherrack 0
fill ~50 ~2 ~16 ~52 ~2 ~16 netherrack 0
fill ~52 ~2 ~42 ~55 ~2 ~42 netherrack 0
fill ~53 ~2 ~15 ~54 ~2 ~15 netherrack 0
fill ~55 ~2 ~14 ~56 ~2 ~14 netherrack 0
fill ~56 ~2 ~41 ~57 ~2 ~41 netherrack 0
fill ~57 ~2 ~13 ~63 ~2 ~13 netherrack 0
fill ~58 ~2 ~12 ~61 ~2 ~12 netherrack 0
fill ~58 ~2 ~40 ~60 ~2 ~40 netherrack 0
fill ~60 ~2 ~39 ~61 ~2 ~39 netherrack 0
fill ~61 ~2 ~38 ~63 ~2 ~38 netherrack 0
fill ~62 ~2 ~37 ~64 ~2 ~37 netherrack 0
fill ~63 ~2 ~14 ~65 ~2 ~14 netherrack 0
fill ~63 ~2 ~35 ~65 ~2 ~35 netherrack 0
fill ~63 ~2 ~36 ~64 ~2 ~36 netherrack 0
fill ~64 ~2 ~15 ~66 ~2 ~15 netherrack 0
fill ~64 ~2 ~30 ~67 ~2 ~30 netherrack 0
fill ~64 ~2 ~31 ~67 ~2 ~31 netherrack 0
fill ~64 ~2 ~32 ~66 ~2 ~32 netherrack 0
fill ~64 ~2 ~33 ~66 ~2 ~33 netherrack 0
fill ~64 ~2 ~34 ~66 ~2 ~34 netherrack 0
fill ~65 ~2 ~16 ~66 ~2 ~16 netherrack 0
fill ~65 ~2 ~22 ~67 ~2 ~22 netherrack 0
fill ~65 ~2 ~23 ~67 ~2 ~23 netherrack 0
fill ~65 ~2 ~24 ~67 ~2 ~24 netherrack 0
fill ~65 ~2 ~25 ~67 ~2 ~25 netherrack 0
fill ~65 ~2 ~26 ~67 ~2 ~26 netherrack 0
fill ~65 ~2 ~27 ~67 ~2 ~27 netherrack 0
fill ~65 ~2 ~28 ~67 ~2 ~28 netherrack 0
fill ~65 ~2 ~29 ~67 ~2 ~29 netherrack 0
fill ~66 ~2 ~17 ~66 ~2 ~34 netherrack 0
fill ~19 ~3 ~21 ~21 ~3 ~21 netherrack 0
fill ~19 ~3 ~22 ~21 ~3 ~22 netherrack 0
fill ~19 ~3 ~23 ~20 ~3 ~23 netherrack 0
fill ~19 ~3 ~24 ~20 ~3 ~24 netherrack 0
fill ~19 ~3 ~25 ~20 ~3 ~25 netherrack 0
fill ~19 ~3 ~26 ~20 ~3 ~26 netherrack 0
fill ~19 ~3 ~27 ~20 ~3 ~27 netherrack 0
fill ~19 ~3 ~28 ~20 ~3 ~28 netherrack 0
fill ~20 ~3 ~20 ~21 ~3 ~20 netherrack 0
fill ~20 ~3 ~29 ~20 ~3 ~30 netherrack 0
fill ~21 ~3 ~15 ~22 ~3 ~15 netherrack 0
fill ~21 ~3 ~16 ~22 ~3 ~16 netherrack 0
fill ~21 ~3 ~17 ~21 ~3 ~22 netherrack 0
fill ~21 ~3 ~31 ~21 ~3 ~34 netherrack 0
fill ~22 ~3 ~13 ~24 ~3 ~13 netherrack 0
fill ~22 ~3 ~14 ~22 ~3 ~13 netherrack 0
fill ~22 ~3 ~33 ~22 ~3 ~35 netherrack 0
fill ~23 ~3 ~36 ~23 ~3 ~37 netherrack 0
fill ~24 ~3 ~12 ~26 ~3 ~12 netherrack 0
fill ~24 ~3 ~38 ~25 ~3 ~38 netherrack 0
fill ~25 ~3 ~11 ~29 ~3 ~11 netherrack 0
setblock ~26 ~3 ~39 netherrack 0
fill ~27 ~3 ~40 ~28 ~3 ~40 netherrack 0
fill ~29 ~3 ~41 ~30 ~3 ~41 netherrack 0
fill ~30 ~3 ~12 ~31 ~3 ~12 netherrack 0
fill ~31 ~3 ~42 ~33 ~3 ~42 netherrack 0
fill ~32 ~3 ~13 ~33 ~3 ~13 netherrack 0
fill ~34 ~3 ~14 ~36 ~3 ~14 netherrack 0
fill ~34 ~3 ~43 ~37 ~3 ~43 netherrack 0
fill ~36 ~3 ~15 ~40 ~3 ~15 netherrack 0
fill ~38 ~3 ~19 ~38 ~55 ~19 netherrack 0
fill ~38 ~3 ~20 ~38 ~55 ~20 netherrack 0
fill ~38 ~3 ~21 ~38 ~22 ~21 netherrack 0
fill ~38 ~3 ~22 ~38 ~22 ~22 netherrack 0
fill ~38 ~3 ~23 ~38 ~22 ~23 netherrack 0
fill ~38 ~3 ~24 ~38 ~15 ~24 netherrack 0
fill ~38 ~3 ~25 ~38 ~15 ~25 netherrack 0
fill ~38 ~3 ~26 ~38 ~15 ~26 netherrack 0
fill ~38 ~3 ~27 ~38 ~15 ~27 netherrack 0
fill ~38 ~3 ~28 ~38 ~15 ~28 netherrack 0
fill ~38 ~3 ~29 ~38 ~15 ~29 netherrack 0
fill ~38 ~3 ~30 ~38 ~8 ~30 netherrack 0
fill ~38 ~3 ~31 ~38 ~8 ~31 netherrack 0
fill ~38 ~3 ~32 ~38 ~8 ~32 netherrack 0
fill ~38 ~3 ~33 ~38 ~8 ~33 netherrack 0
fill ~38 ~3 ~34 ~38 ~8 ~34 netherrack 0
fill ~38 ~3 ~35 ~38 ~8 ~35 netherrack 0
fill ~38 ~3 ~36 ~38 ~8 ~36 netherrack 0
fill ~38 ~3 ~37 ~38 ~8 ~37 netherrack 0
fill ~38 ~3 ~38 ~38 ~8 ~38 netherrack 0
fill ~38 ~3 ~39 ~38 ~8 ~39 netherrack 0
fill ~38 ~3 ~40 ~38 ~8 ~40 netherrack 0
fill ~38 ~3 ~41 ~38 ~25 ~41 netherrack 0
fill ~38 ~3 ~44 ~50 ~3 ~44 netherrack 0
fill ~39 ~3 ~16 ~49 ~3 ~16 netherrack 0
fill ~39 ~3 ~18 ~49 ~3 ~18 netherrack 0
fill ~39 ~3 ~19 ~49 ~3 ~19 lava 0
fill ~39 ~3 ~20 ~49 ~3 ~20 lava 0
fill ~39 ~3 ~21 ~49 ~3 ~21 lava 0
fill ~39 ~3 ~22 ~49 ~3 ~22 lava 0
fill ~39 ~3 ~23 ~49 ~3 ~23 lava 0
fill ~39 ~3 ~24 ~55 ~3 ~24 lava 0
fill ~39 ~3 ~25 ~55 ~3 ~25 lava 0
fill ~39 ~3 ~26 ~55 ~3 ~26 lava 0
fill ~39 ~3 ~27 ~55 ~3 ~27 lava 0
fill ~39 ~3 ~28 ~55 ~3 ~28 lava 0
fill ~39 ~3 ~29 ~55 ~3 ~29 lava 0
fill ~39 ~3 ~30 ~55 ~3 ~30 lava 0
fill ~39 ~3 ~31 ~55 ~3 ~31 lava 0
fill ~39 ~3 ~32 ~55 ~3 ~32 lava 0
fill ~39 ~3 ~33 ~55 ~3 ~33 lava 0
fill ~39 ~3 ~34 ~55 ~3 ~34 lava 0
fill ~39 ~3 ~35 ~49 ~3 ~35 lava 0
fill ~39 ~3 ~36 ~49 ~3 ~36 lava 0
fill ~39 ~3 ~37 ~49 ~3 ~37 lava 0
fill ~39 ~3 ~38 ~49 ~3 ~38 lava 0
fill ~39 ~3 ~39 ~49 ~3 ~39 lava 0
fill ~39 ~3 ~40 ~49 ~3 ~40 lava 0
fill ~39 ~3 ~41 ~49 ~3 ~41 lava 0
fill ~39 ~3 ~42 ~49 ~3 ~42 netherrack 0
fill ~48 ~3 ~15 ~52 ~3 ~15 netherrack 0
fill ~50 ~3 ~19 ~50 ~55 ~19 netherrack 0
fill ~50 ~3 ~20 ~50 ~55 ~20 netherrack 0
fill ~50 ~3 ~21 ~50 ~55 ~21 netherrack 0
fill ~50 ~3 ~22 ~50 ~13 ~22 netherrack 0
fill ~50 ~3 ~23 ~55 ~3 ~23 netherrack 0
fill ~50 ~3 ~35 ~55 ~3 ~35 netherrack 0
fill ~50 ~3 ~36 ~50 ~13 ~36 netherrack 0
fill ~50 ~3 ~37 ~50 ~13 ~37 netherrack 0
fill ~50 ~3 ~38 ~50 ~13 ~38 netherrack 0
fill ~50 ~3 ~39 ~50 ~13 ~39 netherrack 0
fill ~50 ~3 ~40 ~50 ~13 ~40 netherrack 0
fill ~50 ~3 ~41 ~50 ~13 ~41 netherrack 0
fill ~51 ~3 ~43 ~54 ~3 ~43 netherrack 0
fill ~52 ~3 ~14 ~54 ~3 ~14 netherrack 0
fill ~55 ~3 ~13 ~56 ~3 ~13 netherrack 0
fill ~55 ~3 ~42 ~57 ~3 ~42 netherrack 0
fill ~56 ~3 ~24 ~56 ~30 ~24 netherrack 0
fill ~56 ~3 ~25 ~56 ~30 ~25 netherrack 0
fill ~56 ~3 ~26 ~56 ~30 ~26 netherrack 0
fill ~56 ~3 ~27 ~56 ~30 ~27 netherrack 0
fill ~56 ~3 ~28 ~56 ~30 ~28 netherrack 0
fill ~56 ~3 ~29 ~56 ~30 ~29 netherrack 0
fill ~56 ~3 ~30 ~56 ~30 ~30 netherrack 0
fill ~56 ~3 ~31 ~56 ~30 ~31 netherrack 0
fill ~56 ~3 ~32 ~56 ~30 ~32 netherrack 0
fill ~56 ~3 ~33 ~56 ~13 ~33 netherrack 0
fill ~56 ~3 ~34 ~56 ~13 ~34 netherrack 0
fill ~57 ~3 ~12 ~58 ~3 ~12 netherrack 0
fill ~58 ~3 ~41 ~59 ~3 ~41 netherrack 0
fill ~59 ~3 ~11 ~63 ~3 ~11 netherrack 0
fill ~60 ~3 ~40 ~61 ~3 ~40 netherrack 0
fill ~62 ~3 ~12 ~64 ~3 ~12 netherrack 0
setblock ~62 ~3 ~39 netherrack 0
fill ~63 ~3 ~38 ~64 ~3 ~38 netherrack 0
fill ~64 ~3 ~13 ~66 ~3 ~13 netherrack 0
fill ~65 ~3 ~36 ~66 ~3 ~36 netherrack 0
fill ~65 ~3 ~37 ~65 ~3 ~36 netherrack 0
fill ~66 ~3 ~14 ~67 ~3 ~14 netherrack 0
fill ~66 ~3 ~35 ~67 ~3 ~35 netherrack 0
fill ~67 ~3 ~15 ~67 ~3 ~21 netherrack 0
fill ~67 ~3 ~32 ~68 ~3 ~32 netherrack 0
fill ~67 ~3 ~33 ~67 ~3 ~35 netherrack 0
fill ~68 ~3 ~19 ~68 ~3 ~32 netherrack 0
fill ~69 ~3 ~21 ~69 ~3 ~29 netherrack 0
fill ~18 ~4 ~20 ~19 ~4 ~20 netherrack 0
fill ~18 ~4 ~21 ~18 ~5 ~21 netherrack 0
fill ~18 ~4 ~22 ~18 ~4 ~28 netherrack 0
fill ~19 ~4 ~17 ~20 ~4 ~17 netherrack 0
fill ~19 ~4 ~18 ~20 ~4 ~18 netherrack 0
fill ~19 ~4 ~19 ~20 ~4 ~19 netherrack 0
fill ~19 ~4 ~29 ~19 ~4 ~31 netherrack 0
fill ~20 ~4 ~15 ~20 ~4 ~19 netherrack 0
fill ~20 ~4 ~31 ~20 ~4 ~33 netherrack 0
fill ~21 ~4 ~13 ~21 ~5 ~13 netherrack 0
fill ~21 ~4 ~14 ~21 ~4 ~13 netherrack 0
fill ~21 ~4 ~34 ~21 ~4 ~35 netherrack 0
fill ~22 ~4 ~12 ~23 ~4 ~12 netherrack 0
setblock ~22 ~4 ~36 netherrack 0
fill ~23 ~4 ~37 ~23 ~4 ~38 netherrack 0
setblock ~24 ~4 ~11 netherrack 0
fill ~24 ~4 ~38 ~24 ~3 ~38 netherrack 0
fill ~25 ~4 ~10 ~29 ~4 ~10 netherrack 0
setblock ~25 ~4 ~39 netherrack 0
fill ~26 ~4 ~40 ~27 ~4 ~40 netherrack 0
fill ~28 ~4 ~41 ~29 ~4 ~41 netherrack 0
fill ~30 ~4 ~11 ~31 ~4 ~11 netherrack 0
fill ~30 ~4 ~42 ~31 ~4 ~42 netherrack 0
setblock ~32 ~4 ~12 netherrack 0
fill ~32 ~4 ~43 ~34 ~4 ~43 netherrack 0
fill ~33 ~4 ~13 ~37 ~4 ~13 netherrack 0
fill ~35 ~4 ~44 ~53 ~4 ~44 netherrack 0
fill ~37 ~4 ~14 ~51 ~4 ~14 netherrack 0
fill ~39 ~4 ~18 ~49 ~4 ~18 netherrack 0
fill ~39 ~4 ~19 ~49 ~4 ~19 lava 0
fill ~39 ~4 ~20 ~49 ~4 ~20 lava 0
fill ~39 ~4 ~21 ~49 ~4 ~21 lava 0
fill ~39 ~4 ~22 ~49 ~4 ~22 lava 0
fill ~39 ~4 ~23 ~49 ~4 ~23 lava 0
fill ~39 ~4 ~24 ~55 ~4 ~24 lava 0
fill ~39 ~4 ~25 ~55 ~4 ~25 lava 0
fill ~39 ~4 ~26 ~55 ~4 ~26 lava 0
fill ~39 ~4 ~27 ~55 ~4 ~27 lava 0
fill ~39 ~4 ~28 ~55 ~4 ~28 lava 0
fill ~39 ~4 ~29 ~55 ~4 ~29 lava 0
fill ~39 ~4 ~30 ~55 ~4 ~30 lava 0
fill ~39 ~4 ~31 ~55 ~4 ~31 lava 0
fill ~39 ~4 ~32 ~55 ~4 ~32 lava 0
fill ~39 ~4 ~33 ~55 ~4 ~33 lava 0
fill ~39 ~4 ~34 ~55 ~4 ~34 lava 0
fill ~39 ~4 ~35 ~49 ~4 ~35 lava 0
fill ~39 ~4 ~36 ~49 ~4 ~36 lava 0
fill ~39 ~4 ~37 ~49 ~4 ~37 lava 0
fill ~39 ~4 ~38 ~49 ~4 ~38 lava 0
fill ~39 ~4 ~39 ~49 ~4 ~39 lava 0
fill ~39 ~4 ~40 ~49 ~4 ~40 lava 0
fill ~39 ~4 ~41 ~49 ~4 ~41 lava 0
fill ~39 ~4 ~42 ~49 ~4 ~42 netherrack 0
fill ~41 ~4 ~15 ~47 ~4 ~15 netherrack 0
fill ~50 ~4 ~23 ~55 ~4 ~23 netherrack 0
fill ~50 ~4 ~35 ~55 ~4 ~35 netherrack 0
fill ~52 ~4 ~13 ~55 ~4 ~13 netherrack 0
fill ~54 ~4 ~43 ~56 ~4 ~43 netherrack 0
setblock ~56 ~4 ~12 netherrack 0
fill ~57 ~4 ~11 ~58 ~4 ~11 netherrack 0
fill ~57 ~4 ~42 ~59 ~4 ~42 netherrack 0
fill ~59 ~4 ~10 ~63 ~4 ~10 netherrack 0
fill ~60 ~4 ~41 ~61 ~4 ~41 netherrack 0
fill ~62 ~4 ~40 ~62 ~5 ~40 netherrack 0
setblock ~63 ~4 ~39 netherrack 0
setblock ~64 ~4 ~11 netherrack 0
fill ~64 ~4 ~38 ~65 ~4 ~38 netherrack 0
fill ~65 ~4 ~12 ~66 ~4 ~12 netherrack 0
fill ~66 ~4 ~37 ~66 ~5 ~37 netherrack 0
setblock ~67 ~4 ~13 netherrack 0
fill ~67 ~4 ~35 ~67 ~4 ~36 netherrack 0
fill ~68 ~4 ~14 ~68 ~4 ~18 netherrack 0
fill ~68 ~4 ~33 ~68 ~4 ~34 netherrack 0
fill ~69 ~4 ~16 ~69 ~5 ~16 netherrack 0
fill ~69 ~4 ~17 ~69 ~5 ~17 netherrack 0
fill ~69 ~4 ~18 ~69 ~4 ~20 netherrack 0
fill ~69 ~4 ~29 ~69 ~4 ~32 netherrack 0
fill ~70 ~4 ~20 ~70 ~5 ~20 netherrack 0
fill ~70 ~4 ~21 ~70 ~5 ~21 netherrack 0
fill ~70 ~4 ~22 ~70 ~4 ~28 netherrack 0
fill ~17 ~5 ~22 ~17 ~6 ~22 netherrack 0
fill ~17 ~5 ~23 ~17 ~6 ~23 netherrack 0
fill ~17 ~5 ~24 ~17 ~6 ~24 netherrack 0
fill ~17 ~5 ~25 ~17 ~6 ~25 netherrack 0
fill ~17 ~5 ~26 ~17 ~6 ~26 netherrack 0
fill ~18 ~5 ~18 ~18 ~6 ~18 netherrack 0
fill ~18 ~5 ~19 ~18 ~5 ~21 netherrack 0
fill ~18 ~5 ~27 ~18 ~5 ~30 netherrack 0
fill ~19 ~5 ~14 ~20 ~5 ~14 netherrack 0
fill ~19 ~5 ~15 ~19 ~6 ~15 netherrack 0
fill ~19 ~5 ~16 ~19 ~5 ~17 netherrack 0
fill ~19 ~5 ~31 ~19 ~5 ~33 netherrack 0
fill ~20 ~5 ~34 ~20 ~5 ~35 netherrack 0
fill ~21 ~5 ~12 ~21 ~6 ~12 netherrack 0
fill ~21 ~5 ~36 ~21 ~6 ~36 netherrack 0
fill ~22 ~5 ~11 ~23 ~5 ~11 netherrack 0
fill ~22 ~5 ~37 ~22 ~6 ~37 netherrack 0
fill ~23 ~5 ~10 ~24 ~5 ~10 netherrack 0
setblock ~23 ~5 ~38 netherrack 0
setblock ~24 ~5 ~39 netherrack 0
fill ~25 ~5 ~9 ~28 ~5 ~9 netherrack 0
fill ~25 ~5 ~40 ~26 ~5 ~40 netherrack 0
setblock ~27 ~5 ~41 netherrack 0
fill ~28 ~5 ~42 ~29 ~5 ~42 netherrack 0
fill ~29 ~5 ~10 ~31 ~5 ~10 netherrack 0
fill ~30 ~5 ~43 ~32 ~5 ~43 netherrack 0
setblock ~32 ~5 ~11 netherrack 0
fill ~33 ~5 ~12 ~36 ~5 ~12 netherrack 0
fill ~33 ~5 ~44 ~36 ~5 ~44 netherrack 0
fill ~37 ~5 ~13 ~51 ~5 ~13 netherrack 0
fill ~37 ~5 ~45 ~51 ~5 ~45 netherrack 0
fill ~39 ~5 ~18 ~49 ~5 ~18 netherrack 0
fill ~39 ~5 ~19 ~49 ~5 ~19 lava 0
fill ~39 ~5 ~20 ~49 ~5 ~20 lava 0
fill ~39 ~5 ~21 ~49 ~5 ~21 lava 0
fill ~39 ~5 ~22 ~49 ~5 ~22 lava 0
fill ~39 ~5 ~23 ~49 ~5 ~23 lava 0
fill ~39 ~5 ~24 ~55 ~5 ~24 lava 0
fill ~39 ~5 ~25 ~55 ~5 ~25 lava 0
fill ~39 ~5 ~26 ~55 ~5 ~26 lava 0
fill ~39 ~5 ~27 ~55 ~5 ~27 lava 0
fill ~39 ~5 ~28 ~55 ~5 ~28 lava 0
fill ~39 ~5 ~29 ~55 ~5 ~29 lava 0
fill ~39 ~5 ~30 ~55 ~5 ~30 lava 0
fill ~39 ~5 ~31 ~55 ~5 ~31 lava 0
fill ~39 ~5 ~32 ~55 ~5 ~32 lava 0
fill ~39 ~5 ~33 ~55 ~5 ~33 lava 0
fill ~39 ~5 ~34 ~55 ~5 ~34 lava 0
fill ~39 ~5 ~35 ~49 ~5 ~35 lava 0
fill ~39 ~5 ~36 ~49 ~5 ~36 lava 0
fill ~39 ~5 ~37 ~49 ~5 ~37 lava 0
fill ~39 ~5 ~38 ~49 ~5 ~38 lava 0
fill ~39 ~5 ~39 ~49 ~5 ~39 lava 0
fill ~39 ~5 ~40 ~49 ~5 ~40 lava 0
fill ~39 ~5 ~41 ~42 ~5 ~41 lava 0
fill ~39 ~5 ~42 ~42 ~5 ~42 netherrack 0
setblock ~43 ~5 ~41 netherrack 0
fill ~44 ~5 ~41 ~49 ~5 ~41 lava 0
fill ~44 ~5 ~42 ~49 ~5 ~42 netherrack 0
fill ~50 ~5 ~23 ~55 ~5 ~23 netherrack 0
fill ~50 ~5 ~35 ~55 ~5 ~35 netherrack 0
fill ~52 ~5 ~12 ~55 ~5 ~12 netherrack 0
fill ~52 ~5 ~44 ~55 ~5 ~44 netherrack 0
setblock ~56 ~5 ~11 netherrack 0
fill ~56 ~5 ~43 ~58 ~5 ~43 netherrack 0
fill ~57 ~5 ~10 ~59 ~5 ~10 netherrack 0
fill ~59 ~5 ~42 ~60 ~5 ~42 netherrack 0
fill ~60 ~5 ~9 ~63 ~5 ~9 netherrack 0
setblock ~61 ~5 ~41 netherrack 0
fill ~63 ~5 ~40 ~63 ~6 ~40 netherrack 0
fill ~64 ~5 ~10 ~65 ~5 ~10 netherrack 0
setblock ~64 ~5 ~39 netherrack 0
fill ~65 ~5 ~11 ~66 ~5 ~11 netherrack 0
fill ~65 ~5 ~38 ~66 ~5 ~38 netherrack 0
setblock ~67 ~5 ~12 netherrack 0
setblock ~67 ~5 ~36 netherrack 0
setblock ~68 ~5 ~13 netherrack 0
fill ~68 ~5 ~34 ~68 ~5 ~35 netherrack 0
fill ~69 ~5 ~14 ~69 ~6 ~14 netherrack 0
fill ~69 ~5 ~15 ~69 ~6 ~15 netherrack 0
fill ~69 ~5 ~32 ~69 ~5 ~33 netherrack 0
fill ~70 ~5 ~18 ~70 ~5 ~21 netherrack 0
fill ~70 ~5 ~28 ~70 ~5 ~31 netherrack 0
fill ~71 ~5 ~22 ~71 ~6 ~22 netherrack 0
fill ~71 ~5 ~23 ~71 ~6 ~23 netherrack 0
fill ~71 ~5 ~24 ~71 ~6 ~24 netherrack 0
fill ~71 ~5 ~25 ~71 ~6 ~25 netherrack 0
fill ~71 ~5 ~26 ~71 ~6 ~26 netherrack 0
fill ~71 ~5 ~27 ~71 ~6 ~27 netherrack 0
fill ~17 ~6 ~19 ~17 ~8 ~19 netherrack 0
fill ~17 ~6 ~20 ~17 ~8 ~20 netherrack 0
fill ~17 ~6 ~21 ~17 ~6 ~19 netherrack 0
fill ~17 ~6 ~27 ~17 ~8 ~27 netherrack 0
fill ~17 ~6 ~28 ~17 ~9 ~28 netherrack 0
fill ~17 ~6 ~29 ~17 ~16 ~29 netherrack 0
fill ~18 ~6 ~16 ~18 ~8 ~16 netherrack 0
fill ~18 ~6 ~17 ~18 ~6 ~16 netherrack 0
fill ~18 ~6 ~30 ~18 ~6 ~32 netherrack 0
fill ~19 ~6 ~13 ~20 ~6 ~13 netherrack 0
fill ~19 ~6 ~14 ~19 ~5 ~14 netherrack 0
fill ~19 ~6 ~33 ~19 ~6 ~34 netherrack 0
setblock ~20 ~6 ~35 netherrack 0
setblock ~21 ~6 ~11 netherrack 0
fill ~22 ~6 ~10 ~23 ~6 ~10 netherrack 0
fill ~22 ~6 ~38 ~22 ~8 ~38 netherrack 0
fill ~23 ~6 ~39 ~23 ~8 ~39 netherrack 0
setblock ~24 ~6 ~9 netherrack 0
fill ~24 ~6 ~40 ~25 ~6 ~40 netherrack 0
fill ~25 ~6 ~8 ~28 ~6 ~8 netherrack 0
fill ~26 ~6 ~41 ~26 ~8 ~41 netherrack 0
fill ~27 ~6 ~42 ~28 ~6 ~42 netherrack 0
fill ~29 ~6 ~9 ~31 ~6 ~9 netherrack 0
fill ~29 ~6 ~43 ~30 ~6 ~43 netherrack 0
fill ~31 ~6 ~44 ~34 ~6 ~44 netherrack 0
setblock ~32 ~6 ~10 netherrack 0
fill ~33 ~6 ~11 ~36 ~6 ~11 netherrack 0
fill ~35 ~6 ~45 ~54 ~6 ~45 netherrack 0
fill ~37 ~6 ~12 ~51 ~6 ~12 netherrack 0
fill ~39 ~6 ~18 ~49 ~6 ~18 netherrack 0
fill ~39 ~6 ~19 ~49 ~6 ~19 lava 0
fill ~39 ~6 ~20 ~49 ~6 ~20 lava 0
fill ~39 ~6 ~21 ~49 ~6 ~21 lava 0
fill ~39 ~6 ~22 ~49 ~6 ~22 lava 0
fill ~39 ~6 ~23 ~49 ~6 ~23 lava 0
fill ~39 ~6 ~24 ~55 ~6 ~24 lava 0
fill ~39 ~6 ~25 ~55 ~6 ~25 lava 0
fill ~39 ~6 ~26 ~55 ~6 ~26 lava 0
fill ~39 ~6 ~27 ~55 ~6 ~27 lava 0
fill ~39 ~6 ~28 ~55 ~6 ~28 lava 0
fill ~39 ~6 ~29 ~55 ~6 ~29 lava 0
fill ~39 ~6 ~30 ~55 ~6 ~30 lava 0
fill ~39 ~6 ~31 ~55 ~6 ~31 lava 0
fill ~39 ~6 ~32 ~55 ~6 ~32 lava 0
fill ~39 ~6 ~33 ~55 ~6 ~33 lava 0
fill ~39 ~6 ~34 ~55 ~6 ~34 lava 0
fill ~39 ~6 ~35 ~49 ~6 ~35 lava 0
fill ~39 ~6 ~36 ~49 ~6 ~36 lava 0
fill ~39 ~6 ~37 ~49 ~6 ~37 lava 0
fill ~39 ~6 ~38 ~49 ~6 ~38 lava 0
fill ~39 ~6 ~39 ~49 ~6 ~39 lava 0
fill ~39 ~6 ~40 ~49 ~6 ~40 lava 0
fill ~39 ~6 ~41 ~43 ~6 ~41 lava 0
fill ~39 ~6 ~42 ~49 ~6 ~42 netherrack 0
fill ~43 ~6 ~43 ~45 ~6 ~43 netherrack 0
setblock ~44 ~6 ~41 netherrack 0
setblock ~44 ~6 ~44 netherrack 0
fill ~45 ~6 ~41 ~49 ~6 ~41 lava 0
fill ~50 ~6 ~23 ~55 ~6 ~23 netherrack 0
fill ~50 ~6 ~35 ~55 ~6 ~35 netherrack 0
fill ~52 ~6 ~11 ~55 ~6 ~11 netherrack 0
fill ~55 ~6 ~44 ~57 ~6 ~44 netherrack 0
setblock ~56 ~6 ~10 netherrack 0
fill ~57 ~6 ~9 ~59 ~6 ~9 netherrack 0
fill ~58 ~6 ~43 ~59 ~6 ~43 netherrack 0
fill ~60 ~6 ~8 ~63 ~6 ~8 netherrack 0
fill ~60 ~6 ~42 ~61 ~6 ~42 netherrack 0
setblock ~62 ~6 ~41 netherrack 0
fill ~64 ~6 ~9 ~65 ~6 ~9 netherrack 0
fill ~64 ~6 ~40 ~64 ~8 ~40 netherrack 0
fill ~65 ~6 ~39 ~65 ~8 ~39 netherrack 0
setblock ~66 ~6 ~10 netherrack 0
setblock ~66 ~6 ~38 netherrack 0
setblock ~67 ~6 ~11 netherrack 0
fill ~67 ~6 ~37 ~67 ~8 ~37 netherrack 0
setblock ~68 ~6 ~12 netherrack 0
fill ~68 ~6 ~35 ~68 ~6 ~36 netherrack 0
fill ~69 ~6 ~13 ~69 ~8 ~13 netherrack 0
fill ~69 ~6 ~33 ~69 ~6 ~34 netherrack 0
fill ~70 ~6 ~16 ~70 ~8 ~16 netherrack 0
fill ~70 ~6 ~17 ~70 ~6 ~16 netherrack 0
fill ~70 ~6 ~30 ~70 ~6 ~32 netherrack 0
fill ~71 ~6 ~18 ~71 ~8 ~18 netherrack 0
fill ~71 ~6 ~19 ~71 ~8 ~19 netherrack 0
fill ~71 ~6 ~20 ~71 ~8 ~20 netherrack 0
fill ~71 ~6 ~21 ~71 ~6 ~18 netherrack 0
fill ~71 ~6 ~28 ~71 ~8 ~28 netherrack 0
fill ~71 ~6 ~29 ~71 ~16 ~29 netherrack 0
fill ~16 ~7 ~21 ~16 ~14 ~21 netherrack 0
fill ~16 ~7 ~22 ~16 ~14 ~22 netherrack 0
fill ~16 ~7 ~23 ~16 ~14 ~23 netherrack 0
fill ~16 ~7 ~24 ~16 ~14 ~24 netherrack 0
fill ~16 ~7 ~25 ~16 ~14 ~25 netherrack 0
fill ~16 ~7 ~26 ~16 ~13 ~26 netherrack 0
fill ~17 ~7 ~17 ~17 ~16 ~17 netherrack 0
fill ~17 ~7 ~18 ~17 ~8 ~18 netherrack 0
fill ~17 ~7 ~30 ~17 ~16 ~30 netherrack 0
fill ~18 ~7 ~14 ~18 ~16 ~14 netherrack 0
fill ~18 ~7 ~15 ~18 ~9 ~15 netherrack 0
fill ~18 ~7 ~31 ~18 ~8 ~31 netherrack 0
fill ~18 ~7 ~32 ~18 ~9 ~32 netherrack 0
fill ~18 ~7 ~33 ~18 ~15 ~33 netherrack 0
fill ~19 ~7 ~12 ~20 ~7 ~12 netherrack 0
fill ~19 ~7 ~13 ~19 ~8 ~13 netherrack 0
fill ~19 ~7 ~34 ~19 ~8 ~34 netherrack 0
fill ~19 ~7 ~35 ~19 ~14 ~35 netherrack 0
fill ~20 ~7 ~11 ~20 ~8 ~11 netherrack 0
fill ~20 ~7 ~36 ~20 ~8 ~36 netherrack 0
fill ~21 ~7 ~10 ~21 ~8 ~10 netherrack 0
fill ~21 ~7 ~37 ~21 ~8 ~37 netherrack 0
fill ~22 ~7 ~9 ~23 ~7 ~9 netherrack 0
fill ~24 ~7 ~8 ~25 ~7 ~8 netherrack 0
fill ~24 ~7 ~40 ~24 ~8 ~40 netherrack 0
fill ~25 ~7 ~41 ~25 ~9 ~41 netherrack 0
fill ~26 ~7 ~7 ~27 ~7 ~7 netherrack 0
fill ~27 ~7 ~42 ~27 ~8 ~42 netherrack 0
fill ~28 ~7 ~8 ~30 ~7 ~8 netherrack 0
fill ~28 ~7 ~43 ~29 ~7 ~43 netherrack 0
fill ~30 ~7 ~44 ~32 ~7 ~44 netherrack 0
fill ~31 ~7 ~9 ~32 ~7 ~9 netherrack 0
fill ~33 ~7 ~10 ~36 ~7 ~10 netherrack 0
fill ~33 ~7 ~45 ~43 ~7 ~45 netherrack 0
fill ~37 ~7 ~11 ~51 ~7 ~11 netherrack 0
fill ~39 ~7 ~18 ~49 ~7 ~18 netherrack 0
fill ~39 ~7 ~42 ~42 ~7 ~42 netherrack 0
fill ~42 ~7 ~43 ~42 ~10 ~43 netherrack 0
fill ~43 ~7 ~44 ~43 ~12 ~44 netherrack 0
setblock ~45 ~7 ~16 netherrack 0
fill ~45 ~7 ~44 ~45 ~12 ~44 netherrack 0
fill ~45 ~7 ~45 ~55 ~7 ~45 netherrack 0
fill ~46 ~7 ~42 ~49 ~7 ~42 netherrack 0
fill ~46 ~7 ~43 ~46 ~10 ~43 netherrack 0
fill ~50 ~7 ~23 ~55 ~7 ~23 netherrack 0
fill ~50 ~7 ~35 ~55 ~7 ~35 netherrack 0
fill ~52 ~7 ~10 ~55 ~7 ~10 netherrack 0
fill ~56 ~7 ~9 ~57 ~7 ~9 netherrack 0
fill ~56 ~7 ~44 ~58 ~7 ~44 netherrack 0
fill ~58 ~7 ~8 ~60 ~7 ~8 netherrack 0
fill ~59 ~7 ~43 ~60 ~7 ~43 netherrack 0
fill ~61 ~7 ~7 ~62 ~7 ~7 netherrack 0
fill ~61 ~7 ~42 ~62 ~7 ~42 netherrack 0
fill ~63 ~7 ~8 ~64 ~7 ~8 netherrack 0
fill ~63 ~7 ~41 ~63 ~9 ~41 netherrack 0
fill ~65 ~7 ~9 ~66 ~7 ~9 netherrack 0
fill ~66 ~7 ~39 ~66 ~9 ~39 netherrack 0
fill ~67 ~7 ~10 ~67 ~8 ~10 netherrack 0
fill ~67 ~7 ~38 ~67 ~14 ~38 netherrack 0
fill ~68 ~7 ~11 ~68 ~8 ~11 netherrack 0
fill ~68 ~7 ~36 ~68 ~8 ~36 netherrack 0
fill ~69 ~7 ~12 ~69 ~8 ~12 netherrack 0
fill ~69 ~7 ~34 ~69 ~8 ~34 netherrack 0
fill ~69 ~7 ~35 ~69 ~15 ~35 netherrack 0
fill ~70 ~7 ~14 ~70 ~17 ~14 netherrack 0
fill ~70 ~7 ~15 ~70 ~9 ~15 netherrack 0
fill ~70 ~7 ~31 ~70 ~8 ~31 netherrack 0
fill ~70 ~7 ~32 ~70 ~8 ~32 netherrack 0
fill ~70 ~7 ~33 ~70 ~15 ~33 netherrack 0
fill ~71 ~7 ~17 ~71 ~10 ~17 netherrack 0
fill ~71 ~7 ~30 ~71 ~16 ~30 netherrack 0
fill ~72 ~7 ~21 ~72 ~14 ~21 netherrack 0
fill ~72 ~7 ~22 ~72 ~14 ~22 netherrack 0
fill ~72 ~7 ~23 ~72 ~14 ~23 netherrack 0
fill ~72 ~7 ~24 ~72 ~14 ~24 netherrack 0
fill ~72 ~7 ~25 ~72 ~14 ~25 netherrack 0
fill ~72 ~7 ~26 ~72 ~13 ~26 netherrack 0
fill ~72 ~7 ~27 ~72 ~13 ~27 netherrack 0
fill ~16 ~8 ~20 ~16 ~14 ~20 netherrack 0
fill ~16 ~8 ~27 ~16 ~13 ~27 netherrack 0
fill ~17 ~8 ~16 ~17 ~16 ~16 netherrack 0
fill ~17 ~8 ~21 ~38 ~8 ~21 netherrack 0
fill ~17 ~8 ~22 ~38 ~8 ~22 netherrack 0
fill ~17 ~8 ~23 ~38 ~8 ~23 netherrack 0
fill ~17 ~8 ~24 ~38 ~8 ~24 netherrack 0
fill ~17 ~8 ~25 ~38 ~8 ~25 netherrack 0
fill ~17 ~8 ~26 ~38 ~8 ~26 netherrack 0
fill ~17 ~8 ~31 ~17 ~15 ~31 netherrack 0
fill ~18 ~8 ~13 ~18 ~15 ~13 netherrack 0
fill ~18 ~8 ~17 ~37 ~8 ~17 netherrack 0
fill ~18 ~8 ~18 ~37 ~8 ~18 netherrack 0
fill ~18 ~8 ~19 ~38 ~8 ~19 netherrack 0
fill ~18 ~8 ~20 ~38 ~8 ~20 netherrack 0
fill ~18 ~8 ~27 ~38 ~8 ~27 netherrack 0
fill ~18 ~8 ~28 ~38 ~8 ~28 netherrack 0
fill ~18 ~8 ~29 ~38 ~8 ~29 netherrack 0
fill ~18 ~8 ~30 ~36 ~8 ~30 netherrack 0
fill ~19 ~8 ~11 ~19 ~15 ~11 netherrack 0
fill ~19 ~8 ~12 ~69 ~8 ~12 netherrack 0
fill ~19 ~8 ~14 ~70 ~8 ~14 netherrack 0
fill ~19 ~8 ~15 ~38 ~8 ~15 netherrack 0
fill ~19 ~8 ~16 ~37 ~8 ~16 netherrack 0
fill ~19 ~8 ~31 ~36 ~8 ~31 netherrack 0
fill ~19 ~8 ~32 ~36 ~8 ~32 netherrack 0
fill ~19 ~8 ~33 ~36 ~8 ~33 netherrack 0
fill ~20 ~8 ~13 ~70 ~8 ~13 netherrack 0
fill ~20 ~8 ~34 ~36 ~8 ~34 netherrack 0
fill ~20 ~8 ~35 ~36 ~8 ~35 netherrack 0
fill ~21 ~8 ~11 ~69 ~8 ~11 netherrack 0
fill ~21 ~8 ~36 ~36 ~8 ~36 netherrack 0
fill ~22 ~8 ~9 ~35 ~8 ~9 netherrack 0
fill ~22 ~8 ~10 ~68 ~8 ~10 netherrack 0
fill ~22 ~8 ~37 ~36 ~8 ~37 netherrack 0
fill ~22 ~8 ~39 ~22 ~13 ~39 netherrack 0
fill ~23 ~8 ~8 ~32 ~8 ~8 netherrack 0
fill ~23 ~8 ~38 ~36 ~8 ~38 netherrack 0
fill ~23 ~8 ~40 ~23 ~13 ~40 netherrack 0
fill ~24 ~8 ~39 ~36 ~8 ~39 netherrack 0
fill ~25 ~8 ~7 ~30 ~8 ~7 netherrack 0
fill ~25 ~8 ~40 ~36 ~8 ~40 netherrack 0
fill ~26 ~8 ~42 ~26 ~12 ~42 netherrack 0
fill ~27 ~8 ~41 ~38 ~8 ~41 netherrack 0
fill ~27 ~8 ~43 ~42 ~8 ~43 netherrack 0
fill ~28 ~8 ~42 ~42 ~8 ~42 netherrack 0
fill ~29 ~8 ~44 ~43 ~8 ~44 netherrack 0
fill ~33 ~8 ~45 ~43 ~8 ~45 netherrack 0
fill ~39 ~8 ~16 ~44 ~8 ~16 netherrack 0
fill ~39 ~8 ~17 ~49 ~8 ~17 netherrack 0
fill ~39 ~8 ~18 ~49 ~8 ~18 netherrack 0
fill ~45 ~8 ~15 ~45 ~14 ~15 netherrack 0
fill ~45 ~8 ~16 ~45 ~14 ~16 lava 8
fill ~45 ~8 ~45 ~55 ~8 ~45 netherrack 0
fill ~46 ~8 ~16 ~49 ~8 ~16 netherrack 0
fill ~46 ~8 ~42 ~62 ~8 ~42 netherrack 0
fill ~46 ~8 ~44 ~59 ~8 ~44 netherrack 0
fill ~47 ~8 ~43 ~61 ~8 ~43 netherrack 0
fill ~50 ~8 ~15 ~70 ~8 ~15 netherrack 0
fill ~50 ~8 ~23 ~72 ~8 ~23 netherrack 0
fill ~50 ~8 ~35 ~69 ~8 ~35 netherrack 0
fill ~51 ~8 ~16 ~71 ~8 ~16 netherrack 0
fill ~51 ~8 ~17 ~71 ~8 ~17 netherrack 0
fill ~51 ~8 ~18 ~71 ~8 ~18 netherrack 0
fill ~51 ~8 ~19 ~72 ~8 ~19 netherrack 0
fill ~51 ~8 ~20 ~72 ~8 ~20 netherrack 0
fill ~51 ~8 ~21 ~72 ~8 ~21 netherrack 0
fill ~51 ~8 ~22 ~72 ~8 ~22 netherrack 0
fill ~51 ~8 ~36 ~68 ~8 ~36 netherrack 0
fill ~51 ~8 ~37 ~68 ~8 ~37 netherrack 0
fill ~51 ~8 ~38 ~67 ~8 ~38 netherrack 0
fill ~51 ~8 ~39 ~66 ~8 ~39 netherrack 0
fill ~51 ~8 ~40 ~65 ~8 ~40 netherrack 0
fill ~51 ~8 ~41 ~63 ~8 ~41 netherrack 0
fill ~53 ~8 ~9 ~67 ~8 ~9 netherrack 0
fill ~56 ~8 ~8 ~65 ~8 ~8 netherrack 0
fill ~57 ~8 ~24 ~72 ~8 ~24 netherrack 0
fill ~57 ~8 ~25 ~72 ~8 ~25 netherrack 0
fill ~57 ~8 ~26 ~72 ~8 ~26 netherrack 0
fill ~57 ~8 ~27 ~72 ~8 ~27 netherrack 0
fill ~57 ~8 ~28 ~71 ~8 ~28 netherrack 0
fill ~57 ~8 ~29 ~71 ~8 ~29 netherrack 0
fill ~57 ~8 ~30 ~71 ~8 ~30 netherrack 0
fill ~57 ~8 ~31 ~71 ~8 ~31 netherrack 0
fill ~57 ~8 ~32 ~70 ~8 ~32 netherrack 0
fill ~57 ~8 ~33 ~70 ~8 ~33 netherrack 0
fill ~57 ~8 ~34 ~70 ~8 ~34 netherrack 0
fill ~58 ~8 ~7 ~63 ~8 ~7 netherrack 0
fill ~16 ~9 ~18 ~16 ~14 ~18 netherrack 0
fill ~16 ~9 ~19 ~16 ~14 ~19 netherrack 0
fill ~18 ~9 ~12 ~18 ~11 ~12 netherrack 0
fill ~18 ~9 ~34 ~18 ~14 ~34 netherrack 0
fill ~19 ~9 ~36 ~19 ~13 ~36 netherrack 0
fill ~20 ~9 ~10 ~20 ~12 ~10 netherrack 0
fill ~20 ~9 ~37 ~20 ~13 ~37 netherrack 0
fill ~21 ~9 ~9 ~22 ~9 ~9 netherrack 0
fill ~21 ~9 ~38 ~21 ~13 ~38 netherrack 0
fill ~23 ~9 ~8 ~23 ~8 ~8 netherrack 0
fill ~24 ~9 ~7 ~26 ~9 ~7 netherrack 0
fill ~24 ~9 ~41 ~24 ~12 ~41 netherrack 0
fill ~27 ~9 ~6 ~28 ~9 ~6 netherrack 0
fill ~27 ~9 ~43 ~28 ~9 ~43 netherrack 0
fill ~29 ~9 ~7 ~32 ~9 ~7 netherrack 0
fill ~29 ~9 ~44 ~32 ~9 ~44 netherrack 0
fill ~33 ~9 ~8 ~35 ~9 ~8 netherrack 0
fill ~33 ~9 ~45 ~55 ~9 ~45 netherrack 0
fill ~36 ~9 ~9 ~52 ~9 ~9 netherrack 0
fill ~37 ~9 ~30 ~37 ~15 ~30 netherrack 0
fill ~37 ~9 ~31 ~37 ~15 ~31 netherrack 0
fill ~37 ~9 ~32 ~37 ~15 ~32 netherrack 0
fill ~37 ~9 ~33 ~37 ~15 ~33 netherrack 0
fill ~37 ~9 ~34 ~37 ~15 ~34 netherrack 0
fill ~37 ~9 ~35 ~37 ~26 ~35 netherrack 0
fill ~37 ~9 ~36 ~37 ~19 ~36 netherrack 0
fill ~37 ~9 ~37 ~37 ~19 ~37 netherrack 0
fill ~37 ~9 ~38 ~37 ~19 ~38 netherrack 0
fill ~37 ~9 ~39 ~37 ~19 ~39 netherrack 0
fill ~37 ~9 ~40 ~37 ~19 ~40 netherrack 0
fill ~38 ~9 ~16 ~38 ~55 ~16 netherrack 0
fill ~38 ~9 ~17 ~38 ~55 ~17 netherrack 0
fill ~38 ~9 ~18 ~38 ~55 ~18 netherrack 0
fill ~39 ~9 ~15 ~49 ~9 ~15 netherrack 0
fill ~39 ~9 ~42 ~42 ~9 ~42 netherrack 0
fill ~44 ~9 ~44 ~44 ~12 ~44 netherrack 0
fill ~46 ~9 ~42 ~49 ~9 ~42 netherrack 0
fill ~50 ~9 ~16 ~50 ~55 ~16 netherrack 0
fill ~50 ~9 ~17 ~50 ~55 ~17 netherrack 0
fill ~50 ~9 ~18 ~50 ~55 ~18 netherrack 0
fill ~50 ~9 ~23 ~55 ~9 ~23 netherrack 0
fill ~50 ~9 ~35 ~55 ~9 ~35 netherrack 0
fill ~53 ~9 ~8 ~55 ~9 ~8 netherrack 0
fill ~56 ~9 ~7 ~59 ~9 ~7 netherrack 0
fill ~56 ~9 ~44 ~59 ~9 ~44 netherrack 0
setblock ~60 ~9 ~6 netherrack 0
fill ~60 ~9 ~43 ~61 ~9 ~43 netherrack 0
setblock ~62 ~9 ~6 netherrack 0
fill ~62 ~9 ~42 ~62 ~12 ~42 netherrack 0
fill ~63 ~9 ~7 ~64 ~9 ~7 netherrack 0
fill ~64 ~9 ~41 ~64 ~12 ~41 netherrack 0
fill ~65 ~9 ~8 ~66 ~9 ~8 netherrack 0
fill ~65 ~9 ~40 ~66 ~9 ~40 netherrack 0
fill ~67 ~9 ~9 ~67 ~10 ~9 netherrack 0
fill ~68 ~9 ~10 ~68 ~10 ~10 netherrack 0
fill ~68 ~9 ~37 ~68 ~14 ~37 netherrack 0
fill ~69 ~9 ~11 ~69 ~15 ~11 netherrack 0
fill ~69 ~9 ~36 ~69 ~13 ~36 netherrack 0
fill ~70 ~9 ~12 ~70 ~11 ~12 netherrack 0
fill ~70 ~9 ~13 ~70 ~15 ~13 netherrack 0
fill ~70 ~9 ~34 ~70 ~14 ~34 netherrack 0
fill ~71 ~9 ~16 ~71 ~16 ~16 netherrack 0
fill ~71 ~9 ~31 ~71 ~15 ~31 netherrack 0
fill ~71 ~9 ~32 ~71 ~13 ~32 netherrack 0
fill ~72 ~9 ~18 ~72 ~14 ~18 netherrack 0
fill ~72 ~9 ~19 ~72 ~14 ~19 netherrack 0
fill ~72 ~9 ~20 ~72 ~14 ~20 netherrack 0
fill ~72 ~9 ~28 ~72 ~13 ~28 netherrack 0
fill ~16 ~10 ~28 ~16 ~12 ~28 netherrack 0
fill ~17 ~10 ~15 ~17 ~15 ~15 netherrack 0
fill ~17 ~10 ~32 ~17 ~12 ~32 netherrack 0
fill ~21 ~10 ~9 ~21 ~12 ~9 netherrack 0
fill ~22 ~10 ~8 ~22 ~11 ~8 netherrack 0
fill ~23 ~10 ~7 ~24 ~10 ~7 netherrack 0
fill ~25 ~10 ~6 ~26 ~10 ~6 netherrack 0
fill ~25 ~10 ~42 ~25 ~11 ~42 netherrack 0
fill ~27 ~10 ~43 ~29 ~10 ~43 netherrack 0
fill ~29 ~10 ~6 ~32 ~10 ~6 netherrack 0
fill ~30 ~10 ~44 ~35 ~10 ~44 netherrack 0
fill ~33 ~10 ~7 ~34 ~10 ~7 netherrack 0
fill ~35 ~10 ~8 ~37 ~10 ~8 netherrack 0
fill ~36 ~10 ~45 ~52 ~10 ~45 netherrack 0
fill ~38 ~10 ~9 ~39 ~10 ~9 netherrack 0
fill ~39 ~10 ~15 ~49 ~10 ~15 netherrack 0
fill ~39 ~10 ~42 ~42 ~10 ~42 netherrack 0
fill ~40 ~10 ~8 ~48 ~10 ~8 netherrack 0
fill ~46 ~10 ~42 ~49 ~10 ~42 netherrack 0
fill ~49 ~10 ~9 ~50 ~10 ~9 netherrack 0
fill ~50 ~10 ~23 ~55 ~10 ~23 netherrack 0
fill ~50 ~10 ~35 ~55 ~10 ~35 netherrack 0
fill ~51 ~10 ~8 ~53 ~10 ~8 netherrack 0
fill ~53 ~10 ~44 ~58 ~10 ~44 netherrack 0
fill ~54 ~10 ~7 ~55 ~10 ~7 netherrack 0
fill ~56 ~10 ~6 ~59 ~10 ~6 netherrack 0
fill ~59 ~10 ~43 ~61 ~10 ~43 netherrack 0
setblock ~63 ~10 ~6 netherrack 0
fill ~63 ~10 ~42 ~63 ~11 ~42 netherrack 0
fill ~64 ~10 ~7 ~65 ~10 ~7 netherrack 0
fill ~65 ~10 ~40 ~66 ~10 ~40 netherrack 0
fill ~66 ~10 ~8 ~67 ~10 ~8 netherrack 0
fill ~67 ~10 ~39 ~67 ~12 ~39 netherrack 0
fill ~71 ~10 ~15 ~71 ~15 ~15 netherrack 0
fill ~19 ~11 ~10 ~19 ~13 ~10 netherrack 0
fill ~23 ~11 ~7 ~23 ~18 ~7 netherrack 0
fill ~24 ~11 ~6 ~24 ~19 ~6 netherrack 0
fill ~27 ~11 ~5 ~32 ~11 ~5 netherrack 0
fill ~27 ~11 ~42 ~27 ~12 ~42 netherrack 0
fill ~28 ~11 ~43 ~31 ~11 ~43 netherrack 0
fill ~32 ~11 ~44 ~56 ~11 ~44 netherrack 0
fill ~33 ~11 ~6 ~34 ~11 ~6 netherrack 0
fill ~35 ~11 ~7 ~36 ~11 ~7 netherrack 0
fill ~37 ~11 ~8 ~51 ~11 ~8 netherrack 0
fill ~39 ~11 ~15 ~49 ~11 ~15 netherrack 0
fill ~39 ~11 ~42 ~49 ~11 ~42 netherrack 0
fill ~43 ~11 ~43 ~45 ~11 ~43 netherrack 0
fill ~50 ~11 ~23 ~55 ~11 ~23 netherrack 0
fill ~50 ~11 ~35 ~55 ~11 ~35 netherrack 0
fill ~52 ~11 ~7 ~53 ~11 ~7 netherrack 0
fill ~54 ~11 ~6 ~55 ~11 ~6 netherrack 0
fill ~56 ~11 ~5 ~61 ~11 ~5 netherrack 0
fill ~57 ~11 ~43 ~60 ~11 ~43 netherrack 0
fill ~61 ~11 ~42 ~61 ~12 ~42 netherrack 0
fill ~64 ~11 ~6 ~64 ~19 ~6 netherrack 0
fill ~65 ~11 ~7 ~66 ~11 ~7 netherrack 0
fill ~65 ~11 ~40 ~66 ~11 ~40 netherrack 0
fill ~67 ~11 ~8 ~67 ~16 ~8 netherrack 0
fill ~68 ~11 ~9 ~68 ~15 ~9 netherrack 0
fill ~69 ~11 ~10 ~69 ~13 ~10 netherrack 0
fill ~72 ~11 ~17 ~72 ~13 ~17 netherrack 0
fill ~19 ~12 ~12 ~19 ~17 ~12 netherrack 0
fill ~21 ~12 ~8 ~21 ~15 ~8 netherrack 0
fill ~22 ~12 ~7 ~22 ~16 ~7 netherrack 0
fill ~25 ~12 ~41 ~25 ~13 ~41 netherrack 0
fill ~26 ~12 ~5 ~35 ~12 ~5 netherrack 0
fill ~28 ~12 ~42 ~29 ~12 ~42 netherrack 0
fill ~30 ~12 ~43 ~34 ~12 ~43 netherrack 0
fill ~35 ~12 ~6 ~36 ~12 ~6 netherrack 0
fill ~35 ~12 ~44 ~54 ~12 ~44 netherrack 0
fill ~37 ~12 ~7 ~51 ~12 ~7 netherrack 0
fill ~39 ~12 ~15 ~49 ~12 ~15 netherrack 0
fill ~39 ~12 ~42 ~49 ~12 ~42 netherrack 0
fill ~50 ~12 ~23 ~55 ~12 ~23 netherrack 0
fill ~50 ~12 ~35 ~55 ~12 ~35 netherrack 0
fill ~52 ~12 ~6 ~53 ~12 ~6 netherrack 0
setblock ~52 ~12 ~22 netherrack 0
fill ~54 ~12 ~5 ~62 ~12 ~5 netherrack 0
fill ~55 ~12 ~43 ~58 ~12 ~43 netherrack 0
fill ~59 ~12 ~42 ~62 ~12 ~42 netherrack 0
fill ~63 ~12 ~41 ~63 ~13 ~41 netherrack 0
fill ~65 ~12 ~7 ~66 ~12 ~7 netherrack 0
fill ~65 ~12 ~40 ~66 ~12 ~40 netherrack 0
fill ~69 ~12 ~12 ~69 ~17 ~12 netherrack 0
fill ~17 ~13 ~28 ~17 ~16 ~28 netherrack 0
fill ~18 ~13 ~32 ~18 ~16 ~32 netherrack 0
setblock ~20 ~13 ~9 netherrack 0
fill ~24 ~13 ~40 ~24 ~14 ~40 netherrack 0
fill ~26 ~13 ~5 ~36 ~13 ~5 netherrack 0
fill ~26 ~13 ~41 ~27 ~13 ~41 netherrack 0
fill ~28 ~13 ~42 ~31 ~13 ~42 netherrack 0
fill ~29 ~13 ~4 ~35 ~13 ~4 netherrack 0
fill ~31 ~13 ~3 ~33 ~13 ~3 netherrack 0
fill ~32 ~13 ~43 ~56 ~13 ~43 netherrack 0
fill ~37 ~13 ~6 ~39 ~13 ~6 netherrack 0
fill ~39 ~13 ~15 ~49 ~13 ~15 netherrack 0
fill ~39 ~13 ~42 ~49 ~13 ~42 netherrack 0
setblock ~40 ~13 ~7 netherrack 0
setblock ~41 ~13 ~6 netherrack 0
fill ~42 ~13 ~7 ~46 ~13 ~7 netherrack 0
setblock ~47 ~13 ~6 netherrack 0
setblock ~48 ~13 ~7 netherrack 0
fill ~49 ~13 ~6 ~51 ~13 ~6 netherrack 0
fill ~50 ~13 ~23 ~55 ~13 ~23 netherrack 0
fill ~50 ~13 ~35 ~55 ~13 ~35 netherrack 0
setblock ~51 ~13 ~22 netherrack 0
fill ~52 ~13 ~5 ~63 ~13 ~5 netherrack 0
fill ~52 ~13 ~21 ~52 ~18 ~21 netherrack 0
fill ~52 ~13 ~22 ~52 ~18 ~22 lava 8
fill ~53 ~13 ~4 ~60 ~13 ~4 netherrack 0
fill ~53 ~13 ~22 ~55 ~13 ~22 netherrack 0
fill ~55 ~13 ~3 ~57 ~13 ~3 netherrack 0
fill ~57 ~13 ~42 ~60 ~13 ~42 netherrack 0
fill ~61 ~13 ~41 ~63 ~13 ~41 netherrack 0
fill ~64 ~13 ~40 ~65 ~13 ~40 netherrack 0
fill ~65 ~13 ~7 ~66 ~13 ~7 netherrack 0
fill ~66 ~13 ~39 ~66 ~14 ~39 netherrack 0
fill ~17 ~14 ~26 ~17 ~16 ~26 netherrack 0
fill ~17 ~14 ~27 ~17 ~16 ~27 netherrack 0
fill ~20 ~14 ~10 ~20 ~15 ~10 netherrack 0
setblock ~20 ~14 ~36 netherrack 0
fill ~21 ~14 ~9 ~21 ~16 ~9 netherrack 0
fill ~21 ~14 ~37 ~21 ~15 ~37 netherrack 0
fill ~22 ~14 ~38 ~22 ~15 ~38 netherrack 0
setblock ~23 ~14 ~39 netherrack 0
fill ~25 ~14 ~5 ~38 ~14 ~5 netherrack 0
fill ~25 ~14 ~40 ~25 ~15 ~40 netherrack 0
fill ~26 ~14 ~41 ~29 ~14 ~41 netherrack 0
fill ~27 ~14 ~4 ~28 ~14 ~4 netherrack 0
fill ~29 ~14 ~3 ~36 ~14 ~3 netherrack 0
fill ~30 ~14 ~42 ~33 ~14 ~42 netherrack 0
setblock ~33 ~14 ~26 netherrack 0
fill ~34 ~14 ~43 ~54 ~14 ~43 netherrack 0
setblock ~36 ~14 ~4 netherrack 0
fill ~39 ~14 ~15 ~49 ~14 ~15 netherrack 0
fill ~39 ~14 ~41 ~49 ~14 ~41 netherrack 0
setblock ~40 ~14 ~6 netherrack 0
fill ~42 ~14 ~6 ~46 ~14 ~6 netherrack 0
setblock ~48 ~14 ~6 netherrack 0
fill ~49 ~14 ~33 ~55 ~14 ~33 netherrack 0
fill ~49 ~14 ~34 ~55 ~14 ~34 netherrack 0
fill ~49 ~14 ~35 ~49 ~14 ~41 netherrack 0
fill ~50 ~14 ~5 ~63 ~14 ~5 netherrack 0
fill ~51 ~14 ~21 ~51 ~44 ~21 netherrack 0
fill ~52 ~14 ~3 ~59 ~14 ~3 netherrack 0
fill ~52 ~14 ~4 ~52 ~14 ~3 netherrack 0
fill ~53 ~14 ~21 ~55 ~14 ~21 netherrack 0
fill ~55 ~14 ~42 ~58 ~14 ~42 netherrack 0
fill ~56 ~14 ~22 ~56 ~30 ~22 netherrack 0
fill ~56 ~14 ~23 ~56 ~30 ~23 netherrack 0
fill ~59 ~14 ~41 ~62 ~14 ~41 netherrack 0
fill ~60 ~14 ~4 ~61 ~14 ~4 netherrack 0
fill ~63 ~14 ~40 ~64 ~14 ~40 netherrack 0
fill ~65 ~14 ~7 ~66 ~14 ~7 netherrack 0
setblock ~65 ~14 ~39 netherrack 0
fill ~68 ~14 ~10 ~68 ~17 ~10 netherrack 0
fill ~68 ~14 ~36 ~68 ~15 ~36 netherrack 0
fill ~70 ~14 ~32 ~70 ~16 ~32 netherrack 0
fill ~71 ~14 ~17 ~71 ~16 ~17 netherrack 0
fill ~71 ~14 ~26 ~71 ~16 ~26 netherrack 0
fill ~71 ~14 ~27 ~71 ~16 ~27 netherrack 0
fill ~71 ~14 ~28 ~71 ~16 ~28 netherrack 0
fill ~17 ~15 ~18 ~17 ~16 ~18 netherrack 0
fill ~17 ~15 ~19 ~17 ~16 ~19 netherrack 0
fill ~17 ~15 ~20 ~17 ~16 ~20 netherrack 0
fill ~17 ~15 ~21 ~17 ~16 ~21 netherrack 0
fill ~17 ~15 ~22 ~17 ~16 ~22 netherrack 0
fill ~17 ~15 ~23 ~17 ~16 ~23 netherrack 0
fill ~17 ~15 ~24 ~17 ~16 ~24 netherrack 0
fill ~17 ~15 ~25 ~17 ~16 ~25 netherrack 0
fill ~19 ~15 ~34 ~19 ~16 ~34 netherrack 0
setblock ~20 ~15 ~35 netherrack 0
fill ~21 ~15 ~36 ~21 ~16 ~36 netherrack 0
fill ~23 ~15 ~38 ~23 ~16 ~38 netherrack 0
setblock ~24 ~15 ~39 netherrack 0
fill ~25 ~15 ~5 ~40 ~15 ~5 netherrack 0
fill ~26 ~15 ~40 ~27 ~15 ~40 netherrack 0
fill ~27 ~15 ~4 ~27 ~16 ~4 netherrack 0
fill ~28 ~15 ~3 ~32 ~15 ~3 netherrack 0
fill ~28 ~15 ~41 ~30 ~15 ~41 netherrack 0
fill ~31 ~15 ~42 ~37 ~15 ~42 netherrack 0
fill ~32 ~15 ~26 ~32 ~23 ~26 netherrack 0
fill ~33 ~15 ~2 ~34 ~15 ~2 netherrack 0
fill ~33 ~15 ~24 ~38 ~15 ~24 netherrack 0
fill ~33 ~15 ~25 ~38 ~15 ~25 netherrack 0
fill ~33 ~15 ~26 ~33 ~23 ~26 lava 8
fill ~33 ~15 ~27 ~38 ~15 ~27 netherrack 0
fill ~33 ~15 ~28 ~38 ~15 ~28 netherrack 0
fill ~33 ~15 ~29 ~38 ~15 ~29 netherrack 0
fill ~33 ~15 ~30 ~37 ~15 ~30 netherrack 0
fill ~33 ~15 ~31 ~37 ~15 ~31 netherrack 0
fill ~33 ~15 ~32 ~37 ~15 ~32 netherrack 0
fill ~33 ~15 ~33 ~37 ~15 ~33 netherrack 0
fill ~33 ~15 ~34 ~37 ~15 ~34 netherrack 0
fill ~34 ~15 ~26 ~38 ~15 ~26 netherrack 0
fill ~35 ~15 ~3 ~37 ~15 ~3 netherrack 0
setblock ~37 ~15 ~4 netherrack 0
fill ~38 ~15 ~43 ~50 ~15 ~43 netherrack 0
fill ~39 ~15 ~15 ~44 ~15 ~15 netherrack 0
fill ~39 ~15 ~42 ~49 ~15 ~42 netherrack 0
setblock ~45 ~15 ~14 netherrack 0
setblock ~45 ~15 ~15 lava 0
setblock ~45 ~15 ~16 lava 2
fill ~46 ~15 ~15 ~49 ~15 ~15 netherrack 0
fill ~48 ~15 ~5 ~63 ~15 ~5 netherrack 0
fill ~50 ~15 ~33 ~55 ~15 ~33 netherrack 0
fill ~50 ~15 ~34 ~50 ~38 ~34 netherrack 0
fill ~50 ~15 ~35 ~50 ~28 ~35 netherrack 0
fill ~50 ~15 ~36 ~50 ~38 ~36 netherrack 0
fill ~50 ~15 ~37 ~50 ~38 ~37 netherrack 0
fill ~50 ~15 ~38 ~50 ~38 ~38 netherrack 0
fill ~50 ~15 ~39 ~50 ~25 ~39 netherrack 0
fill ~50 ~15 ~40 ~50 ~25 ~40 netherrack 0
fill ~50 ~15 ~41 ~50 ~25 ~41 netherrack 0
fill ~51 ~15 ~3 ~53 ~15 ~3 netherrack 0
fill ~51 ~15 ~4 ~51 ~15 ~3 netherrack 0
fill ~51 ~15 ~42 ~57 ~15 ~42 netherrack 0
fill ~53 ~15 ~21 ~55 ~15 ~21 netherrack 0
fill ~54 ~15 ~2 ~55 ~15 ~2 netherrack 0
fill ~56 ~15 ~3 ~60 ~15 ~3 netherrack 0
fill ~58 ~15 ~41 ~60 ~15 ~41 netherrack 0
setblock ~61 ~15 ~4 netherrack 0
fill ~61 ~15 ~40 ~63 ~15 ~40 netherrack 0
setblock ~64 ~15 ~39 netherrack 0
fill ~65 ~15 ~7 ~66 ~15 ~7 netherrack 0
fill ~65 ~15 ~38 ~66 ~15 ~38 netherrack 0
setblock ~67 ~15 ~37 netherrack 0
fill ~69 ~15 ~34 ~69 ~16 ~34 netherrack 0
fill ~71 ~15 ~18 ~71 ~16 ~18 netherrack 0
fill ~71 ~15 ~19 ~71 ~16 ~19 netherrack 0
fill ~71 ~15 ~20 ~71 ~16 ~20 netherrack 0
fill ~71 ~15 ~21 ~71 ~16 ~21 netherrack 0
fill ~71 ~15 ~22 ~71 ~16 ~22 netherrack 0
fill ~71 ~15 ~23 ~71 ~16 ~23 netherrack 0
fill ~71 ~15 ~24 ~71 ~16 ~24 netherrack 0
fill ~71 ~15 ~25 ~71 ~16 ~25 netherrack 0
fill ~18 ~16 ~15 ~18 ~17 ~15 netherrack 0
fill ~18 ~16 ~31 ~18 ~17 ~31 netherrack 0
fill ~19 ~16 ~13 ~19 ~18 ~13 netherrack 0
fill ~19 ~16 ~33 ~19 ~17 ~33 netherrack 0
fill ~20 ~16 ~11 ~20 ~17 ~11 netherrack 0
fill ~20 ~16 ~34 ~20 ~17 ~34 netherrack 0
fill ~21 ~16 ~10 ~21 ~17 ~10 netherrack 0
fill ~21 ~16 ~35 ~21 ~17 ~35 netherrack 0
fill ~22 ~16 ~8 ~22 ~17 ~8 netherrack 0
setblock ~22 ~16 ~37 netherrack 0
fill ~24 ~16 ~38 ~24 ~17 ~38 netherrack 0
fill ~25 ~16 ~5 ~63 ~16 ~5 netherrack 0
fill ~25 ~16 ~39 ~26 ~16 ~39 netherrack 0
fill ~27 ~16 ~40 ~28 ~16 ~40 netherrack 0
fill ~28 ~16 ~3 ~30 ~16 ~3 netherrack 0
fill ~29 ~16 ~41 ~32 ~16 ~41 netherrack 0
fill ~31 ~16 ~2 ~36 ~16 ~2 netherrack 0
fill ~32 ~16 ~24 ~32 ~26 ~24 netherrack 0
fill ~32 ~16 ~25 ~32 ~26 ~25 netherrack 0
fill ~32 ~16 ~27 ~32 ~26 ~27 netherrack 0
fill ~32 ~16 ~28 ~32 ~26 ~28 netherrack 0
fill ~32 ~16 ~29 ~32 ~26 ~29 netherrack 0
fill ~32 ~16 ~30 ~32 ~26 ~30 netherrack 0
fill ~32 ~16 ~31 ~32 ~26 ~31 netherrack 0
fill ~32 ~16 ~32 ~32 ~26 ~32 netherrack 0
fill ~32 ~16 ~33 ~32 ~26 ~33 netherrack 0
fill ~32 ~16 ~34 ~32 ~26 ~34 netherrack 0
fill ~33 ~16 ~23 ~38 ~16 ~23 netherrack 0
fill ~33 ~16 ~35 ~37 ~16 ~35 netherrack 0
fill ~33 ~16 ~42 ~55 ~16 ~42 netherrack 0
fill ~37 ~16 ~3 ~38 ~16 ~3 netherrack 0
fill ~38 ~16 ~4 ~39 ~16 ~4 netherrack 0
fill ~39 ~16 ~15 ~49 ~16 ~15 netherrack 0
fill ~39 ~16 ~43 ~41 ~16 ~43 netherrack 0
fill ~42 ~16 ~44 ~47 ~16 ~44 netherrack 0
fill ~48 ~16 ~43 ~49 ~16 ~43 netherrack 0
fill ~50 ~16 ~3 ~51 ~16 ~3 netherrack 0
fill ~50 ~16 ~4 ~50 ~16 ~3 netherrack 0
fill ~50 ~16 ~33 ~55 ~16 ~33 netherrack 0
fill ~52 ~16 ~2 ~57 ~16 ~2 netherrack 0
fill ~53 ~16 ~21 ~55 ~16 ~21 netherrack 0
fill ~56 ~16 ~41 ~59 ~16 ~41 netherrack 0
fill ~58 ~16 ~3 ~61 ~16 ~3 netherrack 0
fill ~60 ~16 ~40 ~61 ~16 ~40 netherrack 0
fill ~62 ~16 ~4 ~62 ~20 ~4 netherrack 0
fill ~62 ~16 ~39 ~63 ~16 ~39 netherrack 0
fill ~64 ~16 ~38 ~65 ~16 ~38 netherrack 0
fill ~65 ~16 ~7 ~66 ~16 ~7 netherrack 0
fill ~66 ~16 ~37 ~66 ~17 ~37 netherrack 0
fill ~67 ~16 ~9 ~67 ~17 ~9 netherrack 0
fill ~67 ~16 ~36 ~67 ~17 ~36 netherrack 0
fill ~68 ~16 ~11 ~68 ~18 ~11 netherrack 0
setblock ~68 ~16 ~35 netherrack 0
fill ~69 ~16 ~13 ~69 ~18 ~13 netherrack 0
fill ~69 ~16 ~33 ~69 ~17 ~33 netherrack 0
fill ~70 ~16 ~15 ~70 ~17 ~15 netherrack 0
fill ~70 ~16 ~31 ~70 ~17 ~31 netherrack 0
fill ~18 ~17 ~16 ~18 ~17 ~31 netherrack 0
fill ~19 ~17 ~14 ~19 ~19 ~14 netherrack 0
fill ~19 ~17 ~32 ~19 ~18 ~32 netherrack 0
fill ~22 ~17 ~9 ~22 ~19 ~9 netherrack 0
setblock ~22 ~17 ~36 netherrack 0
setblock ~23 ~17 ~37 netherrack 0
fill ~25 ~17 ~5 ~63 ~17 ~5 netherrack 0
fill ~25 ~17 ~38 ~25 ~18 ~38 netherrack 0
fill ~26 ~17 ~4 ~26 ~19 ~4 netherrack 0
fill ~26 ~17 ~39 ~27 ~17 ~39 netherrack 0
fill ~27 ~17 ~3 ~29 ~17 ~3 netherrack 0
fill ~28 ~17 ~40 ~30 ~17 ~40 netherrack 0
fill ~30 ~17 ~2 ~38 ~17 ~2 netherrack 0
fill ~31 ~17 ~41 ~36 ~17 ~41 netherrack 0
fill ~33 ~17 ~23 ~38 ~17 ~23 netherrack 0
fill ~33 ~17 ~35 ~37 ~17 ~35 netherrack 0
setblock ~37 ~17 ~42 netherrack 0
fill ~38 ~17 ~43 ~39 ~17 ~43 netherrack 0
fill ~39 ~17 ~3 ~39 ~19 ~3 netherrack 0
fill ~39 ~17 ~15 ~49 ~17 ~15 netherrack 0
fill ~39 ~17 ~42 ~49 ~17 ~42 netherrack 0
fill ~40 ~17 ~4 ~40 ~18 ~4 netherrack 0
fill ~40 ~17 ~44 ~49 ~17 ~44 netherrack 0
fill ~48 ~17 ~4 ~49 ~17 ~4 netherrack 0
fill ~49 ~17 ~3 ~50 ~17 ~3 netherrack 0
fill ~50 ~17 ~33 ~55 ~17 ~33 netherrack 0
fill ~50 ~17 ~43 ~50 ~18 ~43 netherrack 0
fill ~51 ~17 ~2 ~58 ~17 ~2 netherrack 0
setblock ~51 ~17 ~42 netherrack 0
fill ~52 ~17 ~41 ~57 ~17 ~41 netherrack 0
fill ~53 ~17 ~21 ~55 ~17 ~21 netherrack 0
fill ~58 ~17 ~40 ~60 ~17 ~40 netherrack 0
fill ~59 ~17 ~3 ~61 ~17 ~3 netherrack 0
fill ~61 ~17 ~39 ~62 ~17 ~39 netherrack 0
fill ~63 ~17 ~38 ~64 ~17 ~38 netherrack 0
fill ~65 ~17 ~7 ~66 ~17 ~7 netherrack 0
setblock ~65 ~17 ~37 netherrack 0
fill ~66 ~17 ~8 ~66 ~19 ~8 netherrack 0
fill ~67 ~17 ~35 ~67 ~19 ~35 netherrack 0
fill ~68 ~17 ~34 ~68 ~18 ~34 netherrack 0
fill ~69 ~17 ~32 ~69 ~19 ~32 netherrack 0
fill ~70 ~17 ~16 ~70 ~17 ~31 netherrack 0
fill ~18 ~18 ~21 ~18 ~18 ~29 netherrack 0
fill ~19 ~18 ~15 ~19 ~19 ~15 netherrack 0
fill ~19 ~18 ~16 ~19 ~18 ~20 netherrack 0
fill ~19 ~18 ~30 ~19 ~20 ~30 netherrack 0
fill ~19 ~18 ~31 ~19 ~19 ~31 netherrack 0
setblock ~20 ~18 ~12 netherrack 0
setblock ~20 ~18 ~33 netherrack 0
fill ~21 ~18 ~11 ~21 ~19 ~11 netherrack 0
fill ~21 ~18 ~34 ~21 ~19 ~34 netherrack 0
fill ~22 ~18 ~10 ~22 ~20 ~10 netherrack 0
fill ~22 ~18 ~35 ~22 ~19 ~35 netherrack 0
fill ~23 ~18 ~8 ~23 ~20 ~8 netherrack 0
fill ~23 ~18 ~36 ~23 ~19 ~36 netherrack 0
setblock ~24 ~18 ~37 netherrack 0
fill ~25 ~18 ~5 ~63 ~18 ~5 netherrack 0
fill ~26 ~18 ~38 ~27 ~18 ~38 netherrack 0
fill ~27 ~18 ~3 ~29 ~18 ~3 netherrack 0
fill ~28 ~18 ~39 ~28 ~19 ~39 netherrack 0
fill ~29 ~18 ~40 ~33 ~18 ~40 netherrack 0
fill ~30 ~18 ~2 ~38 ~18 ~2 netherrack 0
fill ~33 ~18 ~23 ~38 ~18 ~23 netherrack 0
fill ~33 ~18 ~35 ~37 ~18 ~35 netherrack 0
fill ~34 ~18 ~41 ~35 ~18 ~41 netherrack 0
fill ~36 ~18 ~42 ~36 ~19 ~42 netherrack 0
fill ~37 ~18 ~43 ~38 ~18 ~43 netherrack 0
fill ~39 ~18 ~15 ~49 ~18 ~15 netherrack 0
fill ~39 ~18 ~42 ~49 ~18 ~42 netherrack 0
fill ~39 ~18 ~44 ~40 ~18 ~44 netherrack 0
fill ~41 ~18 ~45 ~47 ~18 ~45 netherrack 0
fill ~48 ~18 ~4 ~48 ~17 ~4 netherrack 0
fill ~48 ~18 ~44 ~49 ~18 ~44 netherrack 0
fill ~49 ~18 ~3 ~49 ~19 ~3 netherrack 0
fill ~50 ~18 ~2 ~59 ~18 ~2 netherrack 0
fill ~50 ~18 ~33 ~55 ~18 ~33 netherrack 0
fill ~51 ~18 ~43 ~51 ~19 ~43 netherrack 0
fill ~52 ~18 ~42 ~52 ~19 ~42 netherrack 0
fill ~53 ~18 ~21 ~55 ~18 ~21 netherrack 0
fill ~53 ~18 ~41 ~54 ~18 ~41 netherrack 0
fill ~55 ~18 ~40 ~59 ~18 ~40 netherrack 0
fill ~60 ~18 ~3 ~61 ~18 ~3 netherrack 0
fill ~60 ~18 ~39 ~61 ~18 ~39 netherrack 0
fill ~62 ~18 ~38 ~63 ~18 ~38 netherrack 0
setblock ~64 ~18 ~37 netherrack 0
fill ~65 ~18 ~7 ~65 ~19 ~7 netherrack 0
fill ~65 ~18 ~36 ~66 ~18 ~36 netherrack 0
fill ~66 ~18 ~9 ~66 ~20 ~9 netherrack 0
fill ~67 ~18 ~10 ~67 ~19 ~10 netherrack 0
fill ~68 ~18 ~12 ~68 ~19 ~12 netherrack 0
fill ~68 ~18 ~33 ~68 ~19 ~33 netherrack 0
fill ~69 ~18 ~14 ~69 ~19 ~14 netherrack 0
fill ~69 ~18 ~15 ~69 ~19 ~15 netherrack 0
fill ~69 ~18 ~16 ~69 ~19 ~16 netherrack 0
fill ~69 ~18 ~17 ~69 ~19 ~17 netherrack 0
fill ~69 ~18 ~18 ~69 ~19 ~18 netherrack 0
fill ~69 ~18 ~19 ~69 ~19 ~19 netherrack 0
fill ~69 ~18 ~31 ~69 ~20 ~31 netherrack 0
fill ~70 ~18 ~20 ~70 ~18 ~30 netherrack 0
fill ~18 ~19 ~23 ~18 ~19 ~28 netherrack 0
fill ~19 ~19 ~17 ~20 ~19 ~17 netherrack 0
fill ~19 ~19 ~18 ~20 ~19 ~18 netherrack 0
fill ~19 ~19 ~19 ~19 ~19 ~22 netherrack 0
fill ~19 ~19 ~29 ~19 ~20 ~29 netherrack 0
fill ~20 ~19 ~13 ~20 ~19 ~18 netherrack 0
setblock ~20 ~19 ~32 netherrack 0
fill ~21 ~19 ~12 ~21 ~20 ~12 netherrack 0
fill ~21 ~19 ~33 ~21 ~20 ~33 netherrack 0
fill ~24 ~19 ~7 ~24 ~20 ~7 netherrack 0
setblock ~24 ~19 ~36 netherrack 0
fill ~25 ~19 ~5 ~63 ~19 ~5 netherrack 0
setblock ~25 ~19 ~37 netherrack 0
fill ~26 ~19 ~38 ~27 ~19 ~38 netherrack 0
fill ~27 ~19 ~3 ~28 ~19 ~3 netherrack 0
fill ~29 ~19 ~2 ~38 ~19 ~2 netherrack 0
fill ~29 ~19 ~39 ~29 ~20 ~39 netherrack 0
fill ~30 ~19 ~40 ~33 ~19 ~40 netherrack 0
fill ~33 ~19 ~23 ~38 ~19 ~23 netherrack 0
fill ~33 ~19 ~35 ~37 ~19 ~35 netherrack 0
fill ~34 ~19 ~41 ~35 ~19 ~41 netherrack 0
fill ~37 ~19 ~43 ~37 ~18 ~43 netherrack 0
setblock ~38 ~19 ~44 netherrack 0
fill ~39 ~19 ~15 ~49 ~19 ~15 netherrack 0
fill ~39 ~19 ~42 ~49 ~19 ~42 netherrack 0
fill ~39 ~19 ~45 ~49 ~19 ~45 netherrack 0
fill ~40 ~19 ~3 ~40 ~25 ~3 netherrack 0
fill ~41 ~19 ~4 ~41 ~20 ~4 netherrack 0
fill ~47 ~19 ~4 ~47 ~20 ~4 netherrack 0
fill ~48 ~19 ~3 ~48 ~24 ~3 netherrack 0
fill ~50 ~19 ~2 ~59 ~19 ~2 netherrack 0
fill ~50 ~19 ~33 ~55 ~19 ~33 netherrack 0
setblock ~50 ~19 ~44 netherrack 0
setblock ~52 ~19 ~20 netherrack 0
setblock ~52 ~19 ~21 lava 0
setblock ~52 ~19 ~22 lava 2
fill ~52 ~19 ~43 ~52 ~20 ~43 netherrack 0
fill ~53 ~19 ~21 ~55 ~19 ~21 netherrack 0
fill ~53 ~19 ~41 ~54 ~19 ~41 netherrack 0
fill ~55 ~19 ~40 ~58 ~19 ~40 netherrack 0
fill ~59 ~19 ~39 ~60 ~19 ~39 netherrack 0
fill ~60 ~19 ~3 ~61 ~19 ~3 netherrack 0
fill ~61 ~19 ~38 ~62 ~19 ~38 netherrack 0
setblock ~63 ~19 ~37 netherrack 0
fill ~64 ~19 ~36 ~65 ~19 ~36 netherrack 0
setblock ~66 ~19 ~35 netherrack 0
fill ~67 ~19 ~11 ~67 ~20 ~11 netherrack 0
setblock ~67 ~19 ~34 netherrack 0
fill ~68 ~19 ~13 ~68 ~20 ~13 netherrack 0
fill ~69 ~19 ~20 ~69 ~20 ~20 netherrack 0
fill ~69 ~19 ~21 ~69 ~20 ~21 netherrack 0
fill ~69 ~19 ~29 ~69 ~20 ~29 netherrack 0
fill ~69 ~19 ~30 ~69 ~20 ~30 netherrack 0
fill ~70 ~19 ~22 ~70 ~19 ~28 netherrack 0
fill ~19 ~20 ~20 ~19 ~20 ~30 netherrack 0
setblock ~20 ~20 ~19 netherrack 0
fill ~20 ~20 ~30 ~20 ~20 ~31 netherrack 0
fill ~21 ~20 ~13 ~21 ~20 ~18 netherrack 0
setblock ~21 ~20 ~32 netherrack 0
setblock ~22 ~20 ~11 netherrack 0
fill ~22 ~20 ~33 ~22 ~20 ~34 netherrack 0
fill ~23 ~20 ~9 ~23 ~21 ~9 netherrack 0
fill ~23 ~20 ~34 ~23 ~20 ~35 netherrack 0
fill ~24 ~20 ~35 ~25 ~20 ~35 netherrack 0
fill ~25 ~20 ~5 ~63 ~20 ~5 netherrack 0
fill ~25 ~20 ~6 ~25 ~21 ~6 netherrack 0
setblock ~25 ~20 ~36 netherrack 0
fill ~26 ~20 ~37 ~27 ~20 ~37 netherrack 0
fill ~27 ~20 ~3 ~27 ~22 ~3 netherrack 0
fill ~27 ~20 ~4 ~27 ~22 ~4 netherrack 0
fill ~28 ~20 ~2 ~39 ~20 ~2 netherrack 0
fill ~28 ~20 ~38 ~28 ~21 ~38 netherrack 0
fill ~30 ~20 ~39 ~32 ~20 ~39 netherrack 0
fill ~33 ~20 ~23 ~38 ~20 ~23 netherrack 0
fill ~33 ~20 ~35 ~38 ~20 ~35 netherrack 0
setblock ~33 ~20 ~40 netherrack 0
fill ~34 ~20 ~41 ~34 ~17 ~41 netherrack 0
fill ~35 ~20 ~42 ~35 ~20 ~43 netherrack 0
setblock ~36 ~20 ~43 netherrack 0
setblock ~37 ~20 ~44 netherrack 0
fill ~38 ~20 ~36 ~38 ~33 ~36 netherrack 0
fill ~38 ~20 ~37 ~38 ~33 ~37 netherrack 0
fill ~38 ~20 ~38 ~38 ~39 ~38 netherrack 0
fill ~38 ~20 ~39 ~38 ~25 ~39 netherrack 0
fill ~38 ~20 ~40 ~38 ~25 ~40 netherrack 0
fill ~38 ~20 ~45 ~39 ~20 ~45 netherrack 0
fill ~39 ~20 ~15 ~49 ~20 ~15 netherrack 0
fill ~39 ~20 ~42 ~49 ~20 ~42 netherrack 0
fill ~40 ~20 ~46 ~48 ~20 ~46 netherrack 0
fill ~49 ~20 ~2 ~60 ~20 ~2 netherrack 0
fill ~49 ~20 ~45 ~50 ~20 ~45 netherrack 0
fill ~50 ~20 ~33 ~55 ~20 ~33 netherrack 0
setblock ~51 ~20 ~44 netherrack 0
fill ~52 ~20 ~21 ~55 ~20 ~21 netherrack 0
fill ~53 ~20 ~42 ~53 ~20 ~43 netherrack 0
setblock ~54 ~20 ~41 netherrack 0
fill ~55 ~20 ~40 ~55 ~18 ~40 netherrack 0
fill ~56 ~20 ~39 ~59 ~20 ~39 netherrack 0
fill ~60 ~20 ~38 ~60 ~21 ~38 netherrack 0
fill ~61 ~20 ~3 ~61 ~22 ~3 netherrack 0
fill ~61 ~20 ~37 ~62 ~20 ~37 netherrack 0
fill ~63 ~20 ~6 ~63 ~21 ~6 netherrack 0
fill ~63 ~20 ~35 ~65 ~20 ~35 netherrack 0
fill ~63 ~20 ~36 ~63 ~20 ~35 netherrack 0
fill ~64 ~20 ~7 ~64 ~21 ~7 netherrack 0
setblock ~65 ~20 ~8 netherrack 0
fill ~65 ~20 ~34 ~66 ~20 ~34 netherrack 0
fill ~66 ~20 ~10 ~66 ~21 ~10 netherrack 0
setblock ~67 ~20 ~12 netherrack 0
setblock ~67 ~20 ~33 netherrack 0
fill ~68 ~20 ~14 ~68 ~20 ~19 netherrack 0
setblock ~68 ~20 ~32 netherrack 0
fill ~69 ~20 ~22 ~69 ~21 ~22 netherrack 0
fill ~69 ~20 ~23 ~69 ~21 ~23 netherrack 0
fill ~69 ~20 ~24 ~69 ~21 ~24 netherrack 0
fill ~69 ~20 ~25 ~69 ~21 ~25 netherrack 0
fill ~69 ~20 ~26 ~69 ~21 ~26 netherrack 0
fill ~69 ~20 ~27 ~69 ~21 ~27 netherrack 0
fill ~69 ~20 ~28 ~69 ~21 ~28 netherrack 0
fill ~19 ~21 ~22 ~20 ~21 ~22 netherrack 0
fill ~19 ~21 ~23 ~20 ~21 ~23 netherrack 0
fill ~19 ~21 ~24 ~20 ~21 ~24 netherrack 0
fill ~19 ~21 ~25 ~20 ~21 ~25 netherrack 0
fill ~19 ~21 ~26 ~20 ~21 ~26 netherrack 0
fill ~19 ~21 ~27 ~20 ~21 ~27 netherrack 0
fill ~19 ~21 ~28 ~20 ~21 ~28 netherrack 0
fill ~20 ~21 ~20 ~20 ~21 ~29 netherrack 0
fill ~21 ~21 ~17 ~21 ~21 ~19 netherrack 0
fill ~21 ~21 ~29 ~21 ~21 ~31 netherrack 0
fill ~22 ~21 ~12 ~22 ~21 ~16 netherrack 0
fill ~22 ~21 ~30 ~22 ~21 ~32 netherrack 0
fill ~23 ~21 ~10 ~23 ~21 ~11 netherrack 0
fill ~23 ~21 ~32 ~23 ~21 ~33 netherrack 0
setblock ~24 ~21 ~8 netherrack 0
fill ~24 ~21 ~33 ~24 ~21 ~34 netherrack 0
fill ~25 ~21 ~7 ~25 ~22 ~7 netherrack 0
setblock ~25 ~21 ~34 netherrack 0
fill ~26 ~21 ~5 ~62 ~21 ~5 netherrack 0
fill ~26 ~21 ~35 ~26 ~22 ~35 netherrack 0
fill ~26 ~21 ~36 ~26 ~21 ~35 netherrack 0
setblock ~27 ~21 ~37 netherrack 0
fill ~28 ~21 ~2 ~39 ~21 ~2 netherrack 0
fill ~29 ~21 ~38 ~29 ~22 ~38 netherrack 0
fill ~30 ~21 ~39 ~31 ~21 ~39 netherrack 0
fill ~32 ~21 ~40 ~32 ~22 ~40 netherrack 0
fill ~33 ~21 ~23 ~38 ~21 ~23 netherrack 0
fill ~33 ~21 ~35 ~38 ~21 ~35 netherrack 0
setblock ~33 ~21 ~41 netherrack 0
fill ~34 ~21 ~42 ~34 ~21 ~43 netherrack 0
fill ~35 ~21 ~44 ~36 ~21 ~44 netherrack 0
setblock ~37 ~21 ~22 netherrack 0
setblock ~37 ~21 ~45 netherrack 0
fill ~38 ~21 ~15 ~38 ~49 ~15 netherrack 0
fill ~38 ~21 ~46 ~39 ~21 ~46 netherrack 0
fill ~39 ~21 ~14 ~49 ~21 ~14 netherrack 0
fill ~39 ~21 ~42 ~49 ~21 ~42 netherrack 0
fill ~40 ~21 ~47 ~48 ~21 ~47 netherrack 0
fill ~41 ~21 ~3 ~41 ~23 ~3 netherrack 0
fill ~41 ~21 ~65 ~47 ~21 ~65 netherrack 0
fill ~41 ~21 ~66 ~47 ~21 ~66 netherrack 0
fill ~41 ~21 ~67 ~47 ~21 ~67 netherrack 0
fill ~42 ~21 ~4 ~42 ~23 ~4 netherrack 0
fill ~42 ~21 ~48 ~43 ~21 ~48 netherrack 0
fill ~42 ~21 ~68 ~46 ~21 ~68 netherrack 0
fill ~43 ~21 ~69 ~45 ~21 ~69 netherrack 0
fill ~44 ~21 ~64 ~45 ~21 ~64 netherrack 0
fill ~46 ~21 ~4 ~46 ~23 ~4 netherrack 0
setblock ~46 ~21 ~48 netherrack 0
fill ~47 ~21 ~3 ~47 ~23 ~3 netherrack 0
fill ~49 ~21 ~2 ~60 ~21 ~2 netherrack 0
fill ~49 ~21 ~46 ~50 ~21 ~46 netherrack 0
fill ~50 ~21 ~15 ~50 ~49 ~15 netherrack 0
fill ~50 ~21 ~33 ~55 ~21 ~33 netherrack 0
setblock ~51 ~21 ~45 netherrack 0
fill ~52 ~21 ~21 ~55 ~21 ~21 netherrack 0
fill ~52 ~21 ~44 ~53 ~21 ~44 netherrack 0
fill ~54 ~21 ~42 ~54 ~21 ~43 netherrack 0
setblock ~55 ~21 ~41 netherrack 0
fill ~56 ~21 ~40 ~56 ~23 ~40 netherrack 0
fill ~57 ~21 ~39 ~58 ~21 ~39 netherrack 0
fill ~59 ~21 ~38 ~59 ~22 ~38 netherrack 0
fill ~61 ~21 ~4 ~61 ~22 ~4 netherrack 0
fill ~61 ~21 ~37 ~61 ~20 ~37 netherrack 0
fill ~62 ~21 ~35 ~62 ~22 ~35 netherrack 0
fill ~62 ~21 ~36 ~62 ~21 ~35 netherrack 0
fill ~63 ~21 ~34 ~64 ~21 ~34 netherrack 0
fill ~64 ~21 ~8 ~64 ~22 ~8 netherrack 0
fill ~64 ~21 ~33 ~66 ~21 ~33 netherrack 0
fill ~65 ~21 ~9 ~65 ~21 ~10 netherrack 0
fill ~65 ~21 ~32 ~67 ~21 ~32 netherrack 0
fill ~66 ~21 ~11 ~66 ~21 ~13 netherrack 0
fill ~66 ~21 ~31 ~68 ~21 ~31 netherrack 0
fill ~67 ~21 ~13 ~67 ~21 ~18 netherrack 0
fill ~67 ~21 ~30 ~68 ~21 ~30 netherrack 0
fill ~68 ~21 ~19 ~68 ~21 ~21 netherrack 0
fill ~68 ~21 ~28 ~68 ~21 ~31 netherrack 0
fill ~21 ~22 ~19 ~21 ~22 ~28 netherrack 0
fill ~22 ~22 ~17 ~22 ~22 ~18 netherrack 0
fill ~22 ~22 ~25 ~22 ~22 ~29 netherrack 0
fill ~23 ~22 ~11 ~23 ~22 ~16 netherrack 0
fill ~23 ~22 ~28 ~23 ~22 ~31 netherrack 0
fill ~24 ~22 ~9 ~24 ~22 ~10 netherrack 0
fill ~24 ~22 ~30 ~24 ~22 ~32 netherrack 0
fill ~25 ~22 ~8 ~25 ~23 ~8 netherrack 0
setblock ~25 ~22 ~33 netherrack 0
fill ~26 ~22 ~5 ~62 ~22 ~5 netherrack 0
fill ~26 ~22 ~6 ~26 ~23 ~6 netherrack 0
fill ~26 ~22 ~34 ~26 ~23 ~34 netherrack 0
setblock ~27 ~22 ~36 netherrack 0
fill ~28 ~22 ~3 ~28 ~23 ~3 netherrack 0
setblock ~28 ~22 ~37 netherrack 0
fill ~29 ~22 ~2 ~39 ~22 ~2 netherrack 0
fill ~30 ~22 ~38 ~30 ~24 ~38 netherrack 0
fill ~31 ~22 ~39 ~31 ~23 ~39 netherrack 0
fill ~32 ~22 ~41 ~32 ~23 ~41 netherrack 0
fill ~33 ~22 ~23 ~38 ~22 ~23 netherrack 0
fill ~33 ~22 ~35 ~38 ~22 ~35 netherrack 0
setblock ~33 ~22 ~42 netherrack 0
fill ~34 ~22 ~43 ~34 ~22 ~44 netherrack 0
fill ~35 ~22 ~44 ~35 ~21 ~44 netherrack 0
fill ~36 ~22 ~22 ~36 ~25 ~22 netherrack 0
setblock ~36 ~22 ~45 netherrack 0
setblock ~37 ~22 ~21 netherrack 0
fill ~37 ~22 ~22 ~37 ~25 ~22 lava 8
fill ~37 ~22 ~46 ~38 ~22 ~46 netherrack 0
fill ~39 ~22 ~14 ~49 ~22 ~14 netherrack 0
fill ~39 ~22 ~42 ~49 ~22 ~42 netherrack 0
setblock ~39 ~22 ~47 netherrack 0
fill ~40 ~22 ~48 ~41 ~22 ~48 netherrack 0
fill ~40 ~22 ~49 ~48 ~22 ~49 netherrack 0
fill ~40 ~22 ~64 ~43 ~22 ~64 netherrack 0
fill ~40 ~22 ~65 ~40 ~22 ~68 netherrack 0
fill ~41 ~22 ~63 ~47 ~22 ~63 netherrack 0
fill ~41 ~22 ~68 ~41 ~22 ~69 netherrack 0
fill ~42 ~22 ~50 ~46 ~22 ~50 netherrack 0
setblock ~42 ~22 ~69 netherrack 0
fill ~43 ~22 ~62 ~46 ~22 ~62 netherrack 0
fill ~43 ~22 ~70 ~45 ~22 ~70 netherrack 0
fill ~44 ~22 ~48 ~45 ~22 ~48 netherrack 0
fill ~46 ~22 ~64 ~48 ~22 ~64 netherrack 0
fill ~46 ~22 ~69 ~47 ~22 ~69 netherrack 0
fill ~47 ~22 ~48 ~48 ~22 ~48 netherrack 0
fill ~47 ~22 ~68 ~48 ~22 ~68 netherrack 0
fill ~48 ~22 ~65 ~48 ~23 ~65 netherrack 0
fill ~48 ~22 ~66 ~48 ~23 ~66 netherrack 0
fill ~48 ~22 ~67 ~48 ~23 ~67 netherrack 0
fill ~49 ~22 ~2 ~59 ~22 ~2 netherrack 0
fill ~49 ~22 ~47 ~50 ~22 ~47 netherrack 0
fill ~50 ~22 ~33 ~55 ~22 ~33 netherrack 0
fill ~51 ~22 ~46 ~51 ~23 ~46 netherrack 0
fill ~52 ~22 ~21 ~55 ~22 ~21 netherrack 0
fill ~52 ~22 ~45 ~52 ~23 ~45 netherrack 0
fill ~53 ~22 ~44 ~54 ~22 ~44 netherrack 0
fill ~55 ~22 ~42 ~55 ~23 ~42 netherrack 0
fill ~55 ~22 ~43 ~55 ~23 ~43 netherrack 0
fill ~56 ~22 ~41 ~56 ~23 ~41 netherrack 0
fill ~57 ~22 ~39 ~57 ~23 ~39 netherrack 0
fill ~58 ~22 ~38 ~58 ~24 ~38 netherrack 0
fill ~60 ~22 ~3 ~60 ~23 ~3 netherrack 0
setblock ~60 ~22 ~37 netherrack 0
setblock ~61 ~22 ~36 netherrack 0
fill ~62 ~22 ~6 ~62 ~23 ~6 netherrack 0
fill ~62 ~22 ~34 ~62 ~23 ~34 netherrack 0
setblock ~63 ~22 ~7 netherrack 0
setblock ~63 ~22 ~33 netherrack 0
fill ~64 ~22 ~9 ~64 ~22 ~10 netherrack 0
fill ~64 ~22 ~30 ~66 ~22 ~30 netherrack 0
fill ~64 ~22 ~31 ~65 ~22 ~31 netherrack 0
fill ~64 ~22 ~32 ~64 ~22 ~30 netherrack 0
fill ~65 ~22 ~11 ~65 ~22 ~15 netherrack 0
fill ~65 ~22 ~28 ~67 ~22 ~28 netherrack 0
fill ~65 ~22 ~29 ~67 ~22 ~29 netherrack 0
fill ~66 ~22 ~14 ~66 ~22 ~17 netherrack 0
fill ~66 ~22 ~26 ~68 ~22 ~26 netherrack 0
fill ~66 ~22 ~27 ~68 ~22 ~27 netherrack 0
fill ~67 ~22 ~18 ~67 ~22 ~29 netherrack 0
fill ~68 ~22 ~20 ~68 ~22 ~27 netherrack 0
fill ~22 ~23 ~19 ~22 ~23 ~24 netherrack 0
fill ~23 ~23 ~17 ~23 ~23 ~18 netherrack 0
fill ~23 ~23 ~24 ~23 ~23 ~27 netherrack 0
fill ~24 ~23 ~10 ~24 ~23 ~16 netherrack 0
fill ~24 ~23 ~27 ~24 ~23 ~29 netherrack 0
setblock ~25 ~23 ~9 netherrack 0
setblock ~25 ~23 ~13 netherrack 0
fill ~25 ~23 ~30 ~25 ~24 ~30 netherrack 0
fill ~25 ~23 ~31 ~25 ~23 ~32 netherrack 0
fill ~26 ~23 ~7 ~26 ~24 ~7 netherrack 0
fill ~26 ~23 ~33 ~26 ~24 ~33 netherrack 0
fill ~27 ~23 ~5 ~45 ~23 ~5 netherrack 0
fill ~27 ~23 ~35 ~27 ~24 ~35 netherrack 0
fill ~28 ~23 ~4 ~28 ~24 ~4 netherrack 0
fill ~28 ~23 ~36 ~28 ~24 ~36 netherrack 0
fill ~29 ~23 ~2 ~39 ~23 ~2 netherrack 0
setblock ~29 ~23 ~37 netherrack 0
setblock ~31 ~23 ~40 netherrack 0
setblock ~32 ~23 ~42 netherrack 0
fill ~33 ~23 ~23 ~36 ~23 ~23 netherrack 0
fill ~33 ~23 ~35 ~38 ~23 ~35 netherrack 0
setblock ~33 ~23 ~43 netherrack 0
fill ~34 ~23 ~44 ~34 ~23 ~45 netherrack 0
setblock ~35 ~23 ~45 netherrack 0
fill ~36 ~23 ~21 ~36 ~45 ~21 netherrack 0
setblock ~36 ~23 ~46 netherrack 0
fill ~37 ~23 ~20 ~37 ~45 ~20 netherrack 0
fill ~37 ~23 ~47 ~38 ~23 ~47 netherrack 0
fill ~38 ~23 ~61 ~50 ~23 ~61 netherrack 0
fill ~38 ~23 ~62 ~42 ~23 ~62 netherrack 0
fill ~38 ~23 ~63 ~40 ~23 ~63 netherrack 0
fill ~38 ~23 ~64 ~39 ~23 ~64 netherrack 0
fill ~38 ~23 ~65 ~39 ~23 ~65 netherrack 0
fill ~38 ~23 ~66 ~39 ~23 ~66 netherrack 0
fill ~39 ~23 ~14 ~62 ~23 ~14 netherrack 0
fill ~39 ~23 ~42 ~56 ~23 ~42 netherrack 0
fill ~39 ~23 ~48 ~39 ~23 ~49 netherrack 0
fill ~39 ~23 ~67 ~39 ~23 ~68 netherrack 0
fill ~40 ~23 ~50 ~41 ~23 ~50 netherrack 0
fill ~40 ~23 ~51 ~48 ~23 ~51 netherrack 0
fill ~40 ~23 ~69 ~41 ~23 ~69 netherrack 0
fill ~42 ~23 ~52 ~46 ~23 ~52 netherrack 0
fill ~42 ~23 ~70 ~46 ~23 ~70 netherrack 0
fill ~44 ~23 ~6 ~60 ~23 ~6 netherrack 0
fill ~44 ~23 ~7 ~62 ~23 ~7 netherrack 0
fill ~44 ~23 ~8 ~61 ~23 ~8 netherrack 0
fill ~44 ~23 ~9 ~63 ~23 ~9 netherrack 0
fill ~44 ~23 ~10 ~62 ~23 ~10 netherrack 0
fill ~44 ~23 ~11 ~62 ~23 ~11 netherrack 0
fill ~44 ~23 ~12 ~62 ~23 ~12 netherrack 0
fill ~44 ~23 ~13 ~61 ~23 ~13 netherrack 0
fill ~44 ~23 ~43 ~55 ~23 ~43 netherrack 0
fill ~44 ~23 ~44 ~54 ~23 ~44 netherrack 0
fill ~44 ~23 ~45 ~54 ~23 ~45 netherrack 0
fill ~44 ~23 ~46 ~52 ~23 ~46 netherrack 0
fill ~44 ~23 ~47 ~51 ~23 ~47 netherrack 0
fill ~44 ~23 ~48 ~50 ~23 ~48 netherrack 0
fill ~44 ~23 ~49 ~49 ~23 ~49 netherrack 0
fill ~44 ~23 ~50 ~48 ~23 ~50 netherrack 0
fill ~44 ~23 ~62 ~50 ~23 ~62 netherrack 0
fill ~44 ~23 ~63 ~50 ~23 ~63 netherrack 0
fill ~44 ~23 ~64 ~50 ~23 ~64 netherrack 0
fill ~44 ~23 ~65 ~50 ~23 ~65 netherrack 0
fill ~45 ~23 ~66 ~50 ~23 ~66 netherrack 0
fill ~46 ~23 ~67 ~49 ~23 ~67 netherrack 0
fill ~46 ~23 ~68 ~49 ~23 ~68 netherrack 0
fill ~46 ~23 ~69 ~48 ~23 ~69 netherrack 0
fill ~47 ~23 ~5 ~59 ~23 ~5 netherrack 0
fill ~48 ~23 ~4 ~60 ~23 ~4 netherrack 0
fill ~49 ~23 ~2 ~59 ~23 ~2 netherrack 0
fill ~50 ~23 ~3 ~58 ~23 ~3 netherrack 0
fill ~50 ~23 ~33 ~62 ~23 ~33 netherrack 0
fill ~51 ~23 ~15 ~62 ~23 ~15 netherrack 0
fill ~51 ~23 ~16 ~62 ~23 ~16 netherrack 0
fill ~51 ~23 ~17 ~63 ~23 ~17 netherrack 0
fill ~51 ~23 ~18 ~64 ~23 ~18 netherrack 0
fill ~51 ~23 ~19 ~64 ~23 ~19 netherrack 0
fill ~51 ~23 ~20 ~64 ~23 ~20 netherrack 0
fill ~51 ~23 ~34 ~60 ~23 ~34 netherrack 0
fill ~51 ~23 ~35 ~61 ~23 ~35 netherrack 0
fill ~51 ~23 ~36 ~60 ~23 ~36 netherrack 0
fill ~51 ~23 ~37 ~59 ~23 ~37 netherrack 0
fill ~51 ~23 ~38 ~58 ~23 ~38 netherrack 0
fill ~51 ~23 ~39 ~57 ~23 ~39 netherrack 0
fill ~51 ~23 ~40 ~57 ~23 ~40 netherrack 0
fill ~51 ~23 ~41 ~57 ~23 ~41 netherrack 0
fill ~52 ~23 ~21 ~64 ~23 ~21 netherrack 0
fill ~57 ~23 ~22 ~64 ~23 ~22 netherrack 0
fill ~57 ~23 ~23 ~64 ~23 ~23 netherrack 0
fill ~57 ~23 ~24 ~63 ~23 ~24 netherrack 0
fill ~57 ~23 ~25 ~63 ~23 ~25 netherrack 0
fill ~57 ~23 ~26 ~63 ~23 ~26 netherrack 0
fill ~57 ~23 ~27 ~62 ~23 ~27 netherrack 0
fill ~57 ~23 ~28 ~62 ~23 ~28 netherrack 0
fill ~57 ~23 ~29 ~62 ~23 ~29 netherrack 0
fill ~57 ~23 ~30 ~63 ~23 ~30 netherrack 0
fill ~57 ~23 ~31 ~61 ~23 ~31 netherrack 0
fill ~57 ~23 ~32 ~61 ~23 ~32 netherrack 0
setblock ~61 ~23 ~5 netherrack 0
setblock ~63 ~23 ~8 netherrack 0
fill ~63 ~23 ~13 ~64 ~23 ~13 netherrack 0
fill ~63 ~23 ~31 ~63 ~23 ~32 netherrack 0
fill ~64 ~23 ~10 ~64 ~23 ~15 netherrack 0
fill ~64 ~23 ~27 ~65 ~23 ~27 netherrack 0
fill ~64 ~23 ~28 ~64 ~23 ~29 netherrack 0
fill ~65 ~23 ~16 ~65 ~23 ~17 netherrack 0
fill ~65 ~23 ~24 ~66 ~23 ~24 netherrack 0
fill ~65 ~23 ~25 ~66 ~23 ~25 netherrack 0
fill ~65 ~23 ~26 ~65 ~23 ~24 netherrack 0
fill ~66 ~23 ~17 ~66 ~23 ~25 netherrack 0
fill ~23 ~24 ~19 ~23 ~24 ~23 netherrack 0
fill ~24 ~24 ~16 ~25 ~24 ~16 netherrack 0
fill ~24 ~24 ~17 ~24 ~24 ~18 netherrack 0
fill ~24 ~24 ~24 ~24 ~24 ~26 netherrack 0
fill ~25 ~24 ~10 ~25 ~24 ~12 netherrack 0
fill ~25 ~24 ~14 ~26 ~24 ~14 netherrack 0
fill ~25 ~24 ~15 ~25 ~24 ~14 netherrack 0
fill ~25 ~24 ~27 ~25 ~25 ~27 netherrack 0
fill ~25 ~24 ~28 ~25 ~25 ~28 netherrack 0
fill ~25 ~24 ~29 ~25 ~24 ~27 netherrack 0
fill ~26 ~24 ~8 ~26 ~24 ~9 netherrack 0
fill ~26 ~24 ~12 ~26 ~24 ~14 netherrack 0
fill ~26 ~24 ~31 ~26 ~25 ~31 netherrack 0
fill ~26 ~24 ~32 ~26 ~24 ~31 netherrack 0
setblock ~27 ~24 ~6 netherrack 0
fill ~27 ~24 ~34 ~27 ~25 ~34 netherrack 0
fill ~28 ~24 ~5 ~46 ~24 ~5 netherrack 0
setblock ~29 ~24 ~3 netherrack 0
fill ~29 ~24 ~36 ~29 ~26 ~36 netherrack 0
fill ~30 ~24 ~2 ~38 ~24 ~2 netherrack 0
setblock ~30 ~24 ~37 netherrack 0
fill ~30 ~24 ~39 ~30 ~25 ~39 netherrack 0
fill ~30 ~24 ~40 ~30 ~25 ~40 netherrack 0
setblock ~31 ~24 ~26 netherrack 0
fill ~31 ~24 ~41 ~31 ~24 ~42 netherrack 0
setblock ~32 ~24 ~26 lava 0
setblock ~32 ~24 ~43 netherrack 0
fill ~33 ~24 ~23 ~36 ~24 ~23 netherrack 0
setblock ~33 ~24 ~26 lava 2
fill ~33 ~24 ~35 ~38 ~24 ~35 netherrack 0
setblock ~33 ~24 ~44 netherrack 0
fill ~34 ~24 ~45 ~34 ~24 ~46 netherrack 0
setblock ~35 ~24 ~46 netherrack 0
setblock ~36 ~24 ~47 netherrack 0
fill ~36 ~24 ~59 ~40 ~24 ~59 netherrack 0
fill ~36 ~24 ~60 ~47 ~24 ~60 netherrack 0
fill ~36 ~24 ~61 ~37 ~24 ~61 netherrack 0
fill ~36 ~24 ~62 ~37 ~24 ~62 netherrack 0
fill ~36 ~24 ~63 ~37 ~24 ~63 netherrack 0
fill ~36 ~24 ~64 ~37 ~24 ~64 netherrack 0
fill ~36 ~24 ~65 ~37 ~24 ~65 netherrack 0
fill ~37 ~24 ~48 ~38 ~24 ~48 netherrack 0
fill ~37 ~24 ~66 ~37 ~24 ~67 netherrack 0
fill ~38 ~24 ~49 ~38 ~24 ~50 netherrack 0
fill ~38 ~24 ~67 ~38 ~24 ~68 netherrack 0
fill ~39 ~24 ~3 ~39 ~26 ~3 netherrack 0
fill ~39 ~24 ~14 ~49 ~24 ~14 netherrack 0
fill ~39 ~24 ~42 ~49 ~24 ~42 netherrack 0
fill ~39 ~24 ~50 ~39 ~24 ~51 netherrack 0
fill ~39 ~24 ~69 ~40 ~24 ~69 netherrack 0
fill ~40 ~24 ~52 ~41 ~24 ~52 netherrack 0
setblock ~41 ~24 ~4 netherrack 0
fill ~41 ~24 ~53 ~47 ~24 ~53 netherrack 0
fill ~41 ~24 ~70 ~44 ~24 ~70 netherrack 0
fill ~43 ~24 ~6 ~43 ~24 ~14 netherrack 0
fill ~43 ~24 ~43 ~43 ~103 ~43 netherrack 0
fill ~43 ~24 ~44 ~43 ~103 ~44 netherrack 0
fill ~43 ~24 ~45 ~43 ~86 ~45 netherrack 0
fill ~43 ~24 ~46 ~43 ~103 ~46 netherrack 0
fill ~43 ~24 ~47 ~43 ~102 ~47 netherrack 0
fill ~43 ~24 ~48 ~43 ~102 ~48 netherrack 0
fill ~43 ~24 ~49 ~43 ~102 ~49 netherrack 0
fill ~43 ~24 ~50 ~43 ~102 ~50 netherrack 0
fill ~43 ~24 ~51 ~43 ~102 ~51 netherrack 0
fill ~43 ~24 ~52 ~43 ~102 ~52 netherrack 0
fill ~43 ~24 ~61 ~43 ~98 ~61 netherrack 0
fill ~43 ~24 ~62 ~43 ~97 ~62 netherrack 0
fill ~43 ~24 ~63 ~43 ~97 ~63 netherrack 0
fill ~43 ~24 ~64 ~43 ~28 ~64 netherrack 0
fill ~43 ~24 ~65 ~43 ~27 ~65 netherrack 0
setblock ~44 ~24 ~66 netherrack 0
fill ~45 ~24 ~67 ~45 ~24 ~69 netherrack 0
setblock ~47 ~24 ~4 netherrack 0
setblock ~47 ~24 ~70 netherrack 0
setblock ~48 ~24 ~52 netherrack 0
fill ~48 ~24 ~59 ~52 ~24 ~59 netherrack 0
fill ~48 ~24 ~69 ~49 ~24 ~69 netherrack 0
fill ~49 ~24 ~3 ~49 ~26 ~3 netherrack 0
setblock ~49 ~24 ~51 netherrack 0
fill ~50 ~24 ~2 ~58 ~24 ~2 netherrack 0
fill ~50 ~24 ~33 ~55 ~24 ~33 netherrack 0
fill ~50 ~24 ~49 ~50 ~24 ~50 netherrack 0
setblock ~50 ~24 ~68 netherrack 0
setblock ~51 ~24 ~48 netherrack 0
fill ~51 ~24 ~66 ~51 ~24 ~67 netherrack 0
fill ~52 ~24 ~21 ~55 ~24 ~21 netherrack 0
setblock ~52 ~24 ~47 netherrack 0
fill ~52 ~24 ~60 ~52 ~24 ~61 netherrack 0
fill ~52 ~24 ~64 ~52 ~24 ~65 netherrack 0
fill ~53 ~24 ~46 ~54 ~24 ~46 netherrack 0
fill ~53 ~24 ~62 ~53 ~24 ~63 netherrack 0
setblock ~54 ~24 ~45 netherrack 0
setblock ~55 ~24 ~44 netherrack 0
setblock ~56 ~24 ~43 netherrack 0
fill ~57 ~24 ~41 ~57 ~24 ~42 netherrack 0
fill ~58 ~24 ~39 ~58 ~24 ~40 netherrack 0
setblock ~59 ~24 ~3 netherrack 0
fill ~59 ~24 ~37 ~59 ~26 ~37 netherrack 0
fill ~60 ~24 ~4 ~60 ~24 ~5 netherrack 0
setblock ~60 ~24 ~36 netherrack 0
setblock ~61 ~24 ~6 netherrack 0
fill ~61 ~24 ~34 ~61 ~25 ~34 netherrack 0
fill ~61 ~24 ~35 ~61 ~24 ~34 netherrack 0
fill ~62 ~24 ~7 ~62 ~24 ~8 netherrack 0
setblock ~62 ~24 ~13 netherrack 0
fill ~62 ~24 ~31 ~62 ~25 ~31 netherrack 0
fill ~62 ~24 ~32 ~62 ~25 ~32 netherrack 0
fill ~62 ~24 ~33 ~62 ~24 ~31 netherrack 0
fill ~63 ~24 ~9 ~63 ~24 ~12 netherrack 0
fill ~63 ~24 ~14 ~63 ~24 ~16 netherrack 0
fill ~63 ~24 ~27 ~63 ~25 ~27 netherrack 0
fill ~63 ~24 ~28 ~63 ~25 ~28 netherrack 0
fill ~63 ~24 ~29 ~63 ~24 ~30 netherrack 0
fill ~64 ~24 ~16 ~64 ~24 ~17 netherrack 0
fill ~64 ~24 ~24 ~64 ~24 ~26 netherrack 0
fill ~65 ~24 ~18 ~65 ~24 ~23 netherrack 0
fill ~24 ~25 ~19 ~24 ~25 ~23 netherrack 0
fill ~25 ~25 ~17 ~25 ~25 ~18 netherrack 0
fill ~25 ~25 ~24 ~25 ~27 ~24 netherrack 0
fill ~25 ~25 ~25 ~25 ~26 ~25 netherrack 0
fill ~25 ~25 ~26 ~25 ~25 ~24 netherrack 0
fill ~26 ~25 ~9 ~26 ~25 ~11 netherrack 0
fill ~26 ~25 ~15 ~26 ~25 ~16 netherrack 0
fill ~26 ~25 ~29 ~26 ~28 ~29 netherrack 0
fill ~26 ~25 ~30 ~26 ~26 ~30 netherrack 0
fill ~27 ~25 ~7 ~27 ~25 ~8 netherrack 0
fill ~27 ~25 ~12 ~27 ~26 ~12 netherrack 0
fill ~27 ~25 ~13 ~27 ~26 ~13 netherrack 0
fill ~27 ~25 ~14 ~27 ~26 ~14 netherrack 0
fill ~27 ~25 ~32 ~27 ~31 ~32 netherrack 0
fill ~27 ~25 ~33 ~27 ~26 ~33 netherrack 0
fill ~28 ~25 ~5 ~42 ~25 ~5 netherrack 0
fill ~28 ~25 ~6 ~28 ~26 ~6 netherrack 0
fill ~28 ~25 ~35 ~28 ~29 ~35 netherrack 0
setblock ~29 ~25 ~4 netherrack 0
fill ~29 ~25 ~37 ~29 ~26 ~37 netherrack 0
fill ~29 ~25 ~38 ~29 ~27 ~38 netherrack 0
setblock ~30 ~25 ~3 netherrack 0
setblock ~30 ~25 ~41 netherrack 0
fill ~31 ~25 ~2 ~36 ~25 ~2 netherrack 0
fill ~31 ~25 ~42 ~31 ~25 ~43 netherrack 0
fill ~32 ~25 ~26 ~32 ~26 ~26 netherrack 0
fill ~32 ~25 ~44 ~32 ~26 ~44 netherrack 0
fill ~33 ~25 ~23 ~36 ~25 ~23 netherrack 0
fill ~33 ~25 ~35 ~38 ~25 ~35 netherrack 0
fill ~33 ~25 ~45 ~33 ~26 ~45 netherrack 0
setblock ~34 ~25 ~46 netherrack 0
fill ~34 ~25 ~58 ~41 ~25 ~58 netherrack 0
fill ~34 ~25 ~59 ~35 ~25 ~59 netherrack 0
fill ~34 ~25 ~60 ~35 ~25 ~60 netherrack 0
fill ~34 ~25 ~61 ~35 ~25 ~61 netherrack 0
fill ~34 ~25 ~62 ~35 ~25 ~62 netherrack 0
fill ~34 ~25 ~63 ~35 ~25 ~63 netherrack 0
setblock ~35 ~25 ~47 netherrack 0
fill ~35 ~25 ~57 ~39 ~25 ~57 netherrack 0
fill ~35 ~25 ~64 ~35 ~25 ~66 netherrack 0
setblock ~36 ~25 ~48 netherrack 0
fill ~36 ~25 ~66 ~36 ~25 ~67 netherrack 0
fill ~37 ~25 ~3 ~40 ~25 ~3 netherrack 0
fill ~37 ~25 ~49 ~37 ~25 ~50 netherrack 0
fill ~37 ~25 ~56 ~38 ~25 ~56 netherrack 0
fill ~37 ~25 ~68 ~37 ~32 ~68 netherrack 0
setblock ~38 ~25 ~51 netherrack 0
fill ~38 ~25 ~69 ~39 ~25 ~69 netherrack 0
fill ~39 ~25 ~14 ~49 ~25 ~14 netherrack 0
fill ~39 ~25 ~42 ~49 ~25 ~42 netherrack 0
setblock ~39 ~25 ~52 netherrack 0
setblock ~40 ~25 ~4 netherrack 0
setblock ~40 ~25 ~53 netherrack 0
fill ~40 ~25 ~70 ~43 ~25 ~70 netherrack 0
fill ~41 ~25 ~54 ~47 ~25 ~54 netherrack 0
fill ~41 ~25 ~59 ~47 ~25 ~59 netherrack 0
fill ~43 ~25 ~7 ~43 ~28 ~7 netherrack 0
fill ~43 ~25 ~8 ~43 ~33 ~8 netherrack 0
fill ~43 ~25 ~9 ~43 ~36 ~9 netherrack 0
fill ~43 ~25 ~10 ~43 ~41 ~10 netherrack 0
fill ~43 ~25 ~11 ~43 ~95 ~11 netherrack 0
fill ~43 ~25 ~12 ~43 ~97 ~12 netherrack 0
fill ~43 ~25 ~13 ~43 ~96 ~13 netherrack 0
fill ~43 ~25 ~53 ~43 ~101 ~53 netherrack 0
fill ~43 ~25 ~60 ~43 ~97 ~60 netherrack 0
fill ~43 ~25 ~66 ~43 ~28 ~66 netherrack 0
fill ~44 ~25 ~6 ~45 ~25 ~6 netherrack 0
fill ~44 ~25 ~67 ~44 ~25 ~69 netherrack 0
fill ~46 ~25 ~5 ~47 ~25 ~5 netherrack 0
fill ~47 ~25 ~58 ~54 ~25 ~58 netherrack 0
setblock ~48 ~25 ~4 netherrack 0
setblock ~48 ~25 ~53 netherrack 0
fill ~48 ~25 ~70 ~48 ~26 ~70 netherrack 0
setblock ~49 ~25 ~52 netherrack 0
fill ~49 ~25 ~57 ~53 ~25 ~57 netherrack 0
fill ~49 ~25 ~69 ~50 ~25 ~69 netherrack 0
fill ~50 ~25 ~3 ~51 ~25 ~3 netherrack 0
fill ~50 ~25 ~33 ~55 ~25 ~33 netherrack 0
setblock ~50 ~25 ~51 netherrack 0
fill ~50 ~25 ~56 ~51 ~25 ~56 netherrack 0
fill ~51 ~25 ~49 ~51 ~25 ~50 netherrack 0
fill ~51 ~25 ~68 ~51 ~32 ~68 netherrack 0
fill ~52 ~25 ~2 ~57 ~25 ~2 netherrack 0
fill ~52 ~25 ~21 ~55 ~25 ~21 netherrack 0
setblock ~52 ~25 ~48 netherrack 0
fill ~52 ~25 ~66 ~53 ~25 ~66 netherrack 0
fill ~52 ~25 ~67 ~52 ~25 ~66 netherrack 0
setblock ~53 ~25 ~47 netherrack 0
fill ~53 ~25 ~59 ~54 ~25 ~59 netherrack 0
fill ~53 ~25 ~60 ~54 ~25 ~60 netherrack 0
fill ~53 ~25 ~61 ~54 ~25 ~61 netherrack 0
fill ~53 ~25 ~64 ~54 ~25 ~64 netherrack 0
fill ~53 ~25 ~65 ~53 ~25 ~64 netherrack 0
setblock ~54 ~25 ~46 netherrack 0
fill ~54 ~25 ~62 ~54 ~25 ~64 netherrack 0
setblock ~55 ~25 ~45 netherrack 0
setblock ~56 ~25 ~44 netherrack 0
fill ~57 ~25 ~42 ~57 ~25 ~43 netherrack 0
setblock ~58 ~25 ~3 netherrack 0
fill ~58 ~25 ~40 ~58 ~25 ~41 netherrack 0
setblock ~59 ~25 ~4 netherrack 0
fill ~59 ~25 ~36 ~59 ~26 ~36 netherrack 0
fill ~59 ~25 ~38 ~59 ~27 ~38 netherrack 0
fill ~59 ~25 ~39 ~59 ~27 ~39 netherrack 0
fill ~60 ~25 ~5 ~60 ~25 ~6 netherrack 0
fill ~60 ~25 ~35 ~60 ~29 ~35 netherrack 0
setblock ~61 ~25 ~7 netherrack 0
fill ~61 ~25 ~13 ~61 ~26 ~13 netherrack 0
fill ~61 ~25 ~33 ~61 ~31 ~33 netherrack 0
fill ~62 ~25 ~8 ~62 ~25 ~12 netherrack 0
fill ~62 ~25 ~14 ~62 ~25 ~16 netherrack 0
fill ~62 ~25 ~29 ~62 ~28 ~29 netherrack 0
fill ~62 ~25 ~30 ~62 ~27 ~30 netherrack 0
setblock ~63 ~25 ~17 netherrack 0
fill ~63 ~25 ~24 ~63 ~28 ~24 netherrack 0
fill ~63 ~25 ~25 ~63 ~27 ~25 netherrack 0
fill ~63 ~25 ~26 ~63 ~26 ~26 netherrack 0
fill ~64 ~25 ~18 ~64 ~25 ~23 netherrack 0
fill ~24 ~26 ~21 ~24 ~26 ~22 netherrack 0
fill ~25 ~26 ~18 ~25 ~26 ~20 netherrack 0
fill ~25 ~26 ~23 ~25 ~28 ~23 netherrack 0
setblock ~26 ~26 ~17 netherrack 0
fill ~26 ~26 ~26 ~26 ~36 ~26 netherrack 0
fill ~26 ~26 ~27 ~26 ~35 ~27 netherrack 0
fill ~26 ~26 ~28 ~26 ~35 ~28 netherrack 0
fill ~27 ~26 ~8 ~27 ~26 ~16 netherrack 0
fill ~27 ~26 ~31 ~27 ~31 ~31 netherrack 0
setblock ~28 ~26 ~7 netherrack 0
fill ~28 ~26 ~34 ~28 ~29 ~34 netherrack 0
fill ~29 ~26 ~5 ~41 ~26 ~5 netherrack 0
fill ~29 ~26 ~39 ~29 ~27 ~39 netherrack 0
fill ~29 ~26 ~40 ~29 ~28 ~40 netherrack 0
fill ~29 ~26 ~41 ~29 ~29 ~41 netherrack 0
fill ~30 ~26 ~4 ~31 ~26 ~4 netherrack 0
setblock ~30 ~26 ~42 netherrack 0
fill ~31 ~26 ~3 ~39 ~26 ~3 netherrack 0
fill ~31 ~26 ~43 ~31 ~26 ~44 netherrack 0
fill ~33 ~26 ~23 ~36 ~26 ~23 netherrack 0
fill ~33 ~26 ~35 ~38 ~26 ~35 netherrack 0
fill ~33 ~26 ~46 ~33 ~27 ~46 netherrack 0
fill ~33 ~26 ~56 ~36 ~26 ~56 netherrack 0
fill ~33 ~26 ~57 ~34 ~26 ~57 netherrack 0
fill ~33 ~26 ~58 ~33 ~26 ~63 netherrack 0
setblock ~34 ~26 ~47 netherrack 0
fill ~34 ~26 ~53 ~39 ~26 ~53 netherrack 0
fill ~34 ~26 ~54 ~40 ~26 ~54 netherrack 0
fill ~34 ~26 ~55 ~55 ~26 ~55 netherrack 0
fill ~34 ~26 ~64 ~34 ~26 ~66 netherrack 0
setblock ~35 ~26 ~22 netherrack 0
setblock ~35 ~26 ~48 netherrack 0
fill ~35 ~26 ~52 ~38 ~26 ~52 netherrack 0
fill ~35 ~26 ~67 ~35 ~32 ~67 netherrack 0
setblock ~36 ~26 ~22 lava 0
fill ~36 ~26 ~49 ~36 ~26 ~50 netherrack 0
fill ~36 ~26 ~68 ~36 ~31 ~68 netherrack 0
setblock ~37 ~26 ~22 lava 2
setblock ~37 ~26 ~51 netherrack 0
fill ~38 ~26 ~69 ~39 ~26 ~69 netherrack 0
fill ~39 ~26 ~4 ~39 ~27 ~4 netherrack 0
fill ~39 ~26 ~14 ~49 ~26 ~14 netherrack 0
fill ~39 ~26 ~39 ~49 ~26 ~39 netherrack 0
fill ~39 ~26 ~40 ~49 ~26 ~40 netherrack 0
fill ~39 ~26 ~41 ~49 ~26 ~41 netherrack 0
fill ~39 ~26 ~56 ~49 ~26 ~56 netherrack 0
fill ~40 ~26 ~57 ~48 ~26 ~57 netherrack 0
fill ~40 ~26 ~70 ~43 ~26 ~70 netherrack 0
fill ~42 ~26 ~58 ~46 ~26 ~58 netherrack 0
fill ~43 ~26 ~6 ~46 ~26 ~6 netherrack 0
fill ~43 ~26 ~42 ~43 ~104 ~42 netherrack 0
fill ~43 ~26 ~54 ~43 ~101 ~54 netherrack 0
fill ~43 ~26 ~59 ~43 ~99 ~59 netherrack 0
fill ~43 ~26 ~67 ~43 ~29 ~67 netherrack 0
fill ~43 ~26 ~68 ~43 ~30 ~68 netherrack 0
fill ~43 ~26 ~69 ~43 ~31 ~69 netherrack 0
fill ~47 ~26 ~5 ~48 ~26 ~5 netherrack 0
fill ~48 ~26 ~54 ~54 ~26 ~54 netherrack 0
fill ~49 ~26 ~4 ~49 ~27 ~4 netherrack 0
fill ~49 ~26 ~53 ~54 ~26 ~53 netherrack 0
fill ~49 ~26 ~69 ~50 ~26 ~69 netherrack 0
fill ~50 ~26 ~3 ~57 ~26 ~3 netherrack 0
fill ~50 ~26 ~33 ~55 ~26 ~33 netherrack 0
fill ~50 ~26 ~52 ~54 ~26 ~52 netherrack 0
setblock ~51 ~26 ~51 netherrack 0
fill ~52 ~26 ~21 ~55 ~26 ~21 netherrack 0
fill ~52 ~26 ~49 ~52 ~26 ~50 netherrack 0
fill ~52 ~26 ~56 ~55 ~26 ~56 netherrack 0
fill ~52 ~26 ~68 ~52 ~31 ~68 netherrack 0
setblock ~53 ~26 ~48 netherrack 0
fill ~53 ~26 ~67 ~53 ~32 ~67 netherrack 0
setblock ~54 ~26 ~47 netherrack 0
fill ~54 ~26 ~57 ~55 ~26 ~57 netherrack 0
fill ~54 ~26 ~64 ~54 ~26 ~66 netherrack 0
fill ~55 ~26 ~46 ~55 ~27 ~46 netherrack 0
fill ~55 ~26 ~58 ~55 ~26 ~63 netherrack 0
fill ~56 ~26 ~45 ~56 ~28 ~45 netherrack 0
fill ~57 ~26 ~4 ~58 ~26 ~4 netherrack 0
fill ~57 ~26 ~43 ~57 ~26 ~44 netherrack 0
setblock ~58 ~26 ~42 netherrack 0
setblock ~59 ~26 ~5 netherrack 0
fill ~59 ~26 ~40 ~59 ~27 ~40 netherrack 0
fill ~59 ~26 ~41 ~59 ~29 ~41 netherrack 0
fill ~60 ~26 ~6 ~60 ~26 ~7 netherrack 0
fill ~60 ~26 ~34 ~60 ~28 ~34 netherrack 0
fill ~61 ~26 ~8 ~61 ~26 ~15 netherrack 0
fill ~61 ~26 ~31 ~61 ~30 ~31 netherrack 0
fill ~61 ~26 ~32 ~61 ~31 ~32 netherrack 0
fill ~62 ~26 ~16 ~62 ~26 ~17 netherrack 0
fill ~62 ~26 ~27 ~62 ~35 ~27 netherrack 0
fill ~62 ~26 ~28 ~62 ~35 ~28 netherrack 0
fill ~63 ~26 ~18 ~63 ~26 ~20 netherrack 0
fill ~63 ~26 ~23 ~63 ~28 ~23 netherrack 0
fill ~64 ~26 ~21 ~64 ~26 ~22 netherrack 0
fill ~25 ~27 ~20 ~25 ~27 ~24 netherrack 0
fill ~26 ~27 ~18 ~26 ~28 ~18 netherrack 0
fill ~26 ~27 ~19 ~26 ~31 ~19 netherrack 0
fill ~26 ~27 ~25 ~26 ~36 ~25 netherrack 0
fill ~27 ~27 ~15 ~27 ~27 ~17 netherrack 0
fill ~27 ~27 ~30 ~27 ~30 ~30 netherrack 0
fill ~28 ~27 ~8 ~28 ~27 ~14 netherrack 0
setblock ~28 ~27 ~33 netherrack 0
fill ~28 ~27 ~36 ~28 ~29 ~36 netherrack 0
fill ~28 ~27 ~37 ~28 ~29 ~37 netherrack 0
fill ~29 ~27 ~6 ~29 ~27 ~7 netherrack 0
fill ~29 ~27 ~42 ~29 ~30 ~42 netherrack 0
fill ~30 ~27 ~5 ~40 ~27 ~5 netherrack 0
fill ~30 ~27 ~43 ~30 ~29 ~43 netherrack 0
fill ~30 ~27 ~50 ~35 ~27 ~50 netherrack 0
fill ~30 ~27 ~51 ~36 ~27 ~51 netherrack 0
fill ~30 ~27 ~52 ~34 ~27 ~52 netherrack 0
fill ~31 ~27 ~44 ~31 ~28 ~44 netherrack 0
fill ~31 ~27 ~48 ~34 ~27 ~48 netherrack 0
fill ~31 ~27 ~49 ~35 ~27 ~49 netherrack 0
fill ~31 ~27 ~53 ~33 ~27 ~53 netherrack 0
fill ~32 ~27 ~4 ~39 ~27 ~4 netherrack 0
fill ~32 ~27 ~45 ~32 ~28 ~45 netherrack 0
fill ~32 ~27 ~54 ~33 ~27 ~54 netherrack 0
fill ~32 ~27 ~55 ~33 ~27 ~55 netherrack 0
fill ~32 ~27 ~56 ~32 ~27 ~61 netherrack 0
fill ~33 ~27 ~24 ~36 ~27 ~24 netherrack 0
fill ~33 ~27 ~25 ~36 ~27 ~25 netherrack 0
fill ~33 ~27 ~26 ~36 ~27 ~26 netherrack 0
fill ~33 ~27 ~27 ~36 ~27 ~27 netherrack 0
fill ~33 ~27 ~28 ~36 ~27 ~28 netherrack 0
fill ~33 ~27 ~29 ~36 ~27 ~29 netherrack 0
fill ~33 ~27 ~30 ~36 ~27 ~30 netherrack 0
fill ~33 ~27 ~31 ~36 ~27 ~31 netherrack 0
fill ~33 ~27 ~32 ~38 ~27 ~32 netherrack 0
fill ~33 ~27 ~33 ~38 ~27 ~33 netherrack 0
fill ~33 ~27 ~34 ~38 ~27 ~34 netherrack 0
setblock ~33 ~27 ~47 netherrack 0
fill ~33 ~27 ~62 ~33 ~27 ~65 netherrack 0
fill ~34 ~27 ~66 ~34 ~32 ~66 netherrack 0
fill ~36 ~27 ~22 ~36 ~45 ~22 netherrack 0
fill ~36 ~27 ~23 ~36 ~45 ~23 netherrack 0
fill ~38 ~27 ~35 ~38 ~33 ~35 netherrack 0
fill ~38 ~27 ~69 ~40 ~27 ~69 netherrack 0
fill ~39 ~27 ~14 ~49 ~27 ~14 netherrack 0
fill ~39 ~27 ~39 ~49 ~27 ~39 netherrack 0
fill ~41 ~27 ~6 ~42 ~27 ~6 netherrack 0
setblock ~41 ~27 ~26 redstone_block 0
fill ~41 ~27 ~70 ~43 ~27 ~70 netherrack 0
fill ~43 ~27 ~40 ~43 ~104 ~40 netherrack 0
fill ~43 ~27 ~41 ~43 ~104 ~41 netherrack 0
fill ~43 ~27 ~55 ~43 ~101 ~55 netherrack 0
fill ~43 ~27 ~56 ~43 ~100 ~56 netherrack 0
fill ~43 ~27 ~57 ~43 ~100 ~57 netherrack 0
fill ~43 ~27 ~58 ~43 ~100 ~58 netherrack 0
fill ~44 ~27 ~7 ~46 ~27 ~7 netherrack 0
fill ~46 ~27 ~70 ~47 ~27 ~70 netherrack 0
setblock ~47 ~27 ~6 netherrack 0
setblock ~48 ~27 ~5 netherrack 0
fill ~48 ~27 ~69 ~50 ~27 ~69 netherrack 0
fill ~50 ~27 ~4 ~56 ~27 ~4 netherrack 0
fill ~50 ~27 ~33 ~55 ~27 ~33 netherrack 0
fill ~52 ~27 ~21 ~55 ~27 ~21 netherrack 0
fill ~52 ~27 ~51 ~58 ~27 ~51 netherrack 0
fill ~53 ~27 ~49 ~58 ~27 ~49 netherrack 0
fill ~53 ~27 ~50 ~58 ~27 ~50 netherrack 0
fill ~54 ~27 ~48 ~57 ~27 ~48 netherrack 0
fill ~54 ~27 ~66 ~54 ~32 ~66 netherrack 0
fill ~54 ~27 ~67 ~54 ~29 ~67 netherrack 0
setblock ~55 ~27 ~47 netherrack 0
fill ~55 ~27 ~52 ~58 ~27 ~52 netherrack 0
fill ~55 ~27 ~53 ~57 ~27 ~53 netherrack 0
fill ~55 ~27 ~54 ~56 ~27 ~54 netherrack 0
fill ~55 ~27 ~63 ~55 ~27 ~65 netherrack 0
fill ~56 ~27 ~55 ~56 ~27 ~62 netherrack 0
fill ~57 ~27 ~5 ~58 ~27 ~5 netherrack 0
fill ~57 ~27 ~44 ~57 ~28 ~44 netherrack 0
fill ~58 ~27 ~43 ~58 ~29 ~43 netherrack 0
fill ~59 ~27 ~6 ~59 ~27 ~7 netherrack 0
fill ~59 ~27 ~42 ~59 ~30 ~42 netherrack 0
fill ~60 ~27 ~7 ~60 ~27 ~9 netherrack 0
fill ~60 ~27 ~12 ~60 ~43 ~12 netherrack 0
fill ~60 ~27 ~13 ~60 ~39 ~13 netherrack 0
fill ~60 ~27 ~14 ~60 ~34 ~14 netherrack 0
fill ~60 ~27 ~36 ~60 ~29 ~36 netherrack 0
fill ~60 ~27 ~37 ~60 ~29 ~37 netherrack 0
fill ~61 ~27 ~10 ~61 ~27 ~11 netherrack 0
fill ~61 ~27 ~15 ~61 ~27 ~16 netherrack 0
fill ~62 ~27 ~17 ~62 ~27 ~18 netherrack 0
fill ~62 ~27 ~26 ~62 ~36 ~26 netherrack 0
fill ~63 ~27 ~19 ~63 ~27 ~25 netherrack 0
fill ~25 ~28 ~21 ~25 ~28 ~23 netherrack 0
fill ~26 ~28 ~20 ~26 ~31 ~20 netherrack 0
fill ~26 ~28 ~24 ~26 ~37 ~24 netherrack 0
fill ~27 ~28 ~16 ~27 ~29 ~16 netherrack 0
fill ~27 ~28 ~17 ~27 ~36 ~17 netherrack 0
fill ~27 ~28 ~33 ~27 ~32 ~33 netherrack 0
fill ~28 ~28 ~9 ~28 ~28 ~15 netherrack 0
fill ~28 ~28 ~38 ~28 ~30 ~38 netherrack 0
fill ~28 ~28 ~39 ~28 ~31 ~39 netherrack 0
fill ~28 ~28 ~49 ~30 ~28 ~49 netherrack 0
fill ~28 ~28 ~50 ~29 ~28 ~50 netherrack 0
fill ~28 ~28 ~51 ~29 ~28 ~51 netherrack 0
fill ~28 ~28 ~52 ~29 ~28 ~52 netherrack 0
setblock ~29 ~28 ~8 netherrack 0
fill ~29 ~28 ~47 ~32 ~28 ~47 netherrack 0
fill ~29 ~28 ~48 ~30 ~28 ~48 netherrack 0
fill ~29 ~28 ~53 ~30 ~28 ~53 netherrack 0
fill ~30 ~28 ~6 ~31 ~28 ~6 netherrack 0
fill ~30 ~28 ~7 ~30 ~28 ~6 netherrack 0
fill ~30 ~28 ~46 ~32 ~28 ~46 netherrack 0
fill ~30 ~28 ~54 ~31 ~28 ~54 netherrack 0
fill ~31 ~28 ~55 ~31 ~28 ~58 netherrack 0
fill ~32 ~28 ~5 ~39 ~28 ~5 netherrack 0
fill ~32 ~28 ~59 ~32 ~28 ~63 netherrack 0
fill ~33 ~28 ~64 ~33 ~28 ~65 netherrack 0
fill ~34 ~28 ~67 ~34 ~29 ~67 netherrack 0
fill ~36 ~28 ~24 ~36 ~45 ~24 netherrack 0
fill ~36 ~28 ~25 ~36 ~45 ~25 netherrack 0
fill ~36 ~28 ~26 ~36 ~45 ~26 netherrack 0
fill ~36 ~28 ~27 ~36 ~45 ~27 netherrack 0
fill ~36 ~28 ~28 ~36 ~32 ~28 netherrack 0
fill ~36 ~28 ~29 ~36 ~57 ~29 netherrack 0
fill ~36 ~28 ~30 ~36 ~57 ~30 netherrack 0
fill ~36 ~28 ~31 ~36 ~57 ~31 netherrack 0
fill ~37 ~28 ~32 ~38 ~28 ~32 netherrack 0
fill ~38 ~28 ~33 ~38 ~33 ~33 netherrack 0
fill ~38 ~28 ~34 ~38 ~33 ~34 netherrack 0
fill ~38 ~28 ~69 ~43 ~28 ~69 netherrack 0
fill ~39 ~28 ~14 ~49 ~28 ~14 netherrack 0
fill ~39 ~28 ~39 ~49 ~28 ~39 netherrack 0
setblock ~40 ~28 ~6 netherrack 0
fill ~41 ~28 ~7 ~47 ~28 ~7 netherrack 0
fill ~43 ~28 ~70 ~45 ~28 ~70 netherrack 0
fill ~44 ~28 ~65 ~45 ~28 ~65 netherrack 0
fill ~46 ~28 ~69 ~50 ~28 ~69 netherrack 0
setblock ~48 ~28 ~6 netherrack 0
fill ~49 ~28 ~5 ~56 ~28 ~5 netherrack 0
setblock ~49 ~28 ~23 redstone_block 0
fill ~50 ~28 ~33 ~55 ~28 ~33 netherrack 0
fill ~52 ~28 ~21 ~55 ~28 ~21 netherrack 0
fill ~55 ~28 ~64 ~55 ~28 ~65 netherrack 0
fill ~56 ~28 ~46 ~58 ~28 ~46 netherrack 0
fill ~56 ~28 ~47 ~59 ~28 ~47 netherrack 0
fill ~56 ~28 ~60 ~56 ~28 ~63 netherrack 0
fill ~57 ~28 ~6 ~58 ~28 ~6 netherrack 0
fill ~57 ~28 ~54 ~58 ~28 ~54 netherrack 0
fill ~57 ~28 ~55 ~57 ~28 ~59 netherrack 0
fill ~58 ~28 ~7 ~58 ~29 ~7 netherrack 0
fill ~58 ~28 ~48 ~59 ~28 ~48 netherrack 0
fill ~58 ~28 ~53 ~59 ~28 ~53 netherrack 0
setblock ~59 ~28 ~8 netherrack 0
fill ~59 ~28 ~49 ~60 ~28 ~49 netherrack 0
fill ~59 ~28 ~50 ~60 ~28 ~50 netherrack 0
fill ~59 ~28 ~51 ~60 ~28 ~51 netherrack 0
fill ~59 ~28 ~52 ~60 ~28 ~52 netherrack 0
fill ~60 ~28 ~9 ~60 ~28 ~15 netherrack 0
fill ~60 ~28 ~38 ~60 ~30 ~38 netherrack 0
fill ~60 ~28 ~39 ~60 ~31 ~39 netherrack 0
fill ~60 ~28 ~40 ~60 ~31 ~40 netherrack 0
fill ~61 ~28 ~16 ~61 ~37 ~16 netherrack 0
fill ~61 ~28 ~17 ~61 ~36 ~17 netherrack 0
fill ~61 ~28 ~30 ~61 ~30 ~30 netherrack 0
fill ~62 ~28 ~18 ~62 ~29 ~18 netherrack 0
fill ~62 ~28 ~19 ~62 ~31 ~19 netherrack 0
fill ~62 ~28 ~20 ~62 ~32 ~20 netherrack 0
fill ~62 ~28 ~25 ~62 ~36 ~25 netherrack 0
fill ~63 ~28 ~21 ~63 ~28 ~24 netherrack 0
fill ~26 ~29 ~21 ~26 ~32 ~21 netherrack 0
fill ~26 ~29 ~22 ~26 ~38 ~22 netherrack 0
fill ~26 ~29 ~23 ~26 ~37 ~23 netherrack 0
fill ~27 ~29 ~18 ~27 ~35 ~18 netherrack 0
fill ~27 ~29 ~29 ~27 ~30 ~29 netherrack 0
fill ~27 ~29 ~47 ~28 ~29 ~47 netherrack 0
fill ~27 ~29 ~48 ~28 ~29 ~48 netherrack 0
fill ~27 ~29 ~49 ~27 ~29 ~53 netherrack 0
fill ~28 ~29 ~10 ~28 ~29 ~15 netherrack 0
fill ~28 ~29 ~40 ~28 ~31 ~40 netherrack 0
fill ~28 ~29 ~46 ~29 ~29 ~46 netherrack 0
fill ~28 ~29 ~53 ~28 ~29 ~54 netherrack 0
setblock ~29 ~29 ~9 netherrack 0
fill ~29 ~29 ~45 ~31 ~29 ~45 netherrack 0
fill ~29 ~29 ~54 ~29 ~29 ~55 netherrack 0
setblock ~30 ~29 ~8 netherrack 0
setblock ~30 ~29 ~44 netherrack 0
fill ~30 ~29 ~55 ~30 ~29 ~57 netherrack 0
setblock ~31 ~29 ~7 netherrack 0
fill ~31 ~29 ~58 ~31 ~29 ~61 netherrack 0
fill ~32 ~29 ~6 ~33 ~29 ~6 netherrack 0
fill ~32 ~29 ~62 ~32 ~30 ~62 netherrack 0
fill ~32 ~29 ~63 ~32 ~37 ~63 netherrack 0
fill ~32 ~29 ~64 ~32 ~32 ~64 netherrack 0
fill ~33 ~29 ~65 ~33 ~32 ~65 netherrack 0
fill ~34 ~29 ~5 ~36 ~29 ~5 netherrack 0
fill ~37 ~29 ~32 ~38 ~29 ~32 netherrack 0
fill ~38 ~29 ~6 ~39 ~29 ~6 netherrack 0
fill ~38 ~29 ~69 ~50 ~29 ~69 netherrack 0
fill ~39 ~29 ~14 ~49 ~29 ~14 netherrack 0
fill ~39 ~29 ~39 ~49 ~29 ~39 netherrack 0
setblock ~40 ~29 ~7 netherrack 0
fill ~41 ~29 ~8 ~47 ~29 ~8 netherrack 0
setblock ~41 ~29 ~26 redstone_block 0
fill ~44 ~29 ~64 ~45 ~29 ~64 netherrack 0
fill ~44 ~29 ~66 ~45 ~29 ~66 netherrack 0
fill ~46 ~29 ~65 ~46 ~32 ~65 coal_block 0
setblock ~48 ~29 ~7 netherrack 0
fill ~49 ~29 ~6 ~51 ~29 ~6 netherrack 0
setblock ~49 ~29 ~35 redstone_block 0
fill ~50 ~29 ~33 ~55 ~29 ~33 netherrack 0
fill ~52 ~29 ~5 ~54 ~29 ~5 netherrack 0
fill ~52 ~29 ~21 ~55 ~29 ~21 netherrack 0
fill ~55 ~29 ~6 ~56 ~29 ~6 netherrack 0
fill ~55 ~29 ~65 ~55 ~32 ~65 netherrack 0
fill ~56 ~29 ~62 ~56 ~29 ~64 netherrack 0
setblock ~57 ~29 ~7 netherrack 0
fill ~57 ~29 ~45 ~59 ~29 ~45 netherrack 0
fill ~57 ~29 ~58 ~57 ~29 ~61 netherrack 0
setblock ~58 ~29 ~8 netherrack 0
setblock ~58 ~29 ~44 netherrack 0
fill ~58 ~29 ~55 ~59 ~29 ~55 netherrack 0
fill ~58 ~29 ~56 ~58 ~29 ~57 netherrack 0
fill ~59 ~29 ~9 ~59 ~30 ~9 netherrack 0
fill ~59 ~29 ~46 ~60 ~29 ~46 netherrack 0
fill ~59 ~29 ~54 ~60 ~29 ~54 netherrack 0
fill ~60 ~29 ~10 ~60 ~29 ~15 netherrack 0
fill ~60 ~29 ~47 ~61 ~29 ~47 netherrack 0
fill ~60 ~29 ~48 ~61 ~29 ~48 netherrack 0
fill ~60 ~29 ~53 ~61 ~29 ~53 netherrack 0
setblock ~61 ~29 ~29 netherrack 0
fill ~61 ~29 ~34 ~61 ~32 ~34 netherrack 0
fill ~61 ~29 ~49 ~61 ~29 ~53 netherrack 0
fill ~62 ~29 ~21 ~62 ~39 ~21 netherrack 0
fill ~62 ~29 ~22 ~62 ~38 ~22 netherrack 0
fill ~62 ~29 ~23 ~62 ~37 ~23 netherrack 0
fill ~62 ~29 ~24 ~62 ~37 ~24 netherrack 0
fill ~25 ~30 ~50 ~26 ~30 ~50 netherrack 0
fill ~25 ~30 ~51 ~26 ~30 ~51 netherrack 0
fill ~26 ~30 ~47 ~26 ~31 ~47 netherrack 0
fill ~26 ~30 ~48 ~26 ~30 ~53 netherrack 0
fill ~27 ~30 ~34 ~27 ~32 ~34 netherrack 0
fill ~27 ~30 ~35 ~27 ~32 ~35 netherrack 0
fill ~27 ~30 ~36 ~27 ~32 ~36 netherrack 0
fill ~27 ~30 ~37 ~27 ~32 ~37 netherrack 0
fill ~27 ~30 ~44 ~29 ~30 ~44 netherrack 0
fill ~27 ~30 ~45 ~28 ~30 ~45 netherrack 0
fill ~27 ~30 ~46 ~27 ~30 ~44 netherrack 0
setblock ~27 ~30 ~54 netherrack 0
fill ~28 ~30 ~11 ~28 ~31 ~11 netherrack 0
fill ~28 ~30 ~12 ~28 ~43 ~12 netherrack 0
fill ~28 ~30 ~13 ~28 ~39 ~13 netherrack 0
fill ~28 ~30 ~14 ~28 ~34 ~14 netherrack 0
fill ~28 ~30 ~15 ~28 ~33 ~15 netherrack 0
fill ~28 ~30 ~16 ~28 ~31 ~16 netherrack 0
fill ~28 ~30 ~41 ~28 ~31 ~41 netherrack 0
fill ~28 ~30 ~43 ~29 ~30 ~43 netherrack 0
setblock ~28 ~30 ~55 netherrack 0
fill ~29 ~30 ~10 ~29 ~32 ~10 netherrack 0
fill ~29 ~30 ~56 ~29 ~30 ~57 netherrack 0
fill ~30 ~30 ~9 ~30 ~31 ~9 netherrack 0
fill ~30 ~30 ~58 ~30 ~30 ~59 netherrack 0
setblock ~31 ~30 ~8 netherrack 0
fill ~31 ~30 ~60 ~31 ~30 ~61 netherrack 0
fill ~32 ~30 ~7 ~33 ~30 ~7 netherrack 0
fill ~34 ~30 ~6 ~37 ~30 ~6 netherrack 0
fill ~37 ~30 ~32 ~38 ~30 ~32 netherrack 0
fill ~38 ~30 ~7 ~39 ~30 ~7 netherrack 0
fill ~38 ~30 ~69 ~50 ~30 ~69 netherrack 0
fill ~39 ~30 ~14 ~49 ~30 ~14 netherrack 0
fill ~39 ~30 ~39 ~42 ~30 ~39 netherrack 0
fill ~40 ~30 ~8 ~48 ~30 ~8 netherrack 0
setblock ~43 ~30 ~38 redstone_block 0
fill ~44 ~30 ~39 ~49 ~30 ~39 netherrack 0
fill ~44 ~30 ~64 ~45 ~30 ~64 netherrack 0
fill ~44 ~30 ~67 ~45 ~30 ~67 netherrack 0
fill ~46 ~30 ~66 ~46 ~33 ~66 coal_block 0
fill ~49 ~30 ~7 ~50 ~30 ~7 netherrack 0
setblock ~49 ~30 ~23 redstone_block 0
fill ~50 ~30 ~33 ~55 ~30 ~33 netherrack 0
fill ~50 ~30 ~35 ~50 ~31 ~35 netherrack 0
fill ~51 ~30 ~6 ~54 ~30 ~6 netherrack 0
fill ~52 ~30 ~21 ~55 ~30 ~21 netherrack 0
fill ~55 ~30 ~7 ~56 ~30 ~7 netherrack 0
fill ~56 ~30 ~63 ~56 ~37 ~63 netherrack 0
fill ~56 ~30 ~64 ~56 ~32 ~64 netherrack 0
setblock ~57 ~30 ~8 netherrack 0
fill ~57 ~30 ~60 ~57 ~30 ~62 netherrack 0
fill ~58 ~30 ~9 ~58 ~31 ~9 netherrack 0
fill ~58 ~30 ~58 ~58 ~30 ~59 netherrack 0
fill ~59 ~30 ~10 ~59 ~32 ~10 netherrack 0
fill ~59 ~30 ~43 ~60 ~30 ~43 netherrack 0
fill ~59 ~30 ~44 ~61 ~30 ~44 netherrack 0
fill ~59 ~30 ~56 ~59 ~30 ~57 netherrack 0
fill ~60 ~30 ~11 ~60 ~31 ~11 netherrack 0
fill ~60 ~30 ~15 ~60 ~33 ~15 netherrack 0
fill ~60 ~30 ~41 ~60 ~31 ~41 netherrack 0
fill ~60 ~30 ~45 ~61 ~30 ~45 netherrack 0
setblock ~60 ~30 ~55 netherrack 0
fill ~61 ~30 ~18 ~61 ~35 ~18 netherrack 0
fill ~61 ~30 ~35 ~61 ~32 ~35 netherrack 0
fill ~61 ~30 ~36 ~61 ~32 ~36 netherrack 0
fill ~61 ~30 ~37 ~61 ~32 ~37 netherrack 0
setblock ~61 ~30 ~46 netherrack 0
setblock ~61 ~30 ~54 netherrack 0
fill ~62 ~30 ~29 ~62 ~35 ~29 netherrack 0
fill ~62 ~30 ~47 ~62 ~31 ~47 netherrack 0
fill ~62 ~30 ~48 ~62 ~30 ~53 netherrack 0
fill ~63 ~30 ~50 ~63 ~32 ~50 netherrack 0
fill ~63 ~30 ~51 ~63 ~31 ~51 netherrack 0
fill ~25 ~31 ~48 ~25 ~32 ~48 netherrack 0
fill ~25 ~31 ~49 ~25 ~32 ~49 netherrack 0
fill ~25 ~31 ~50 ~25 ~32 ~50 netherrack 0
fill ~25 ~31 ~51 ~25 ~30 ~51 netherrack 0
fill ~25 ~31 ~52 ~25 ~31 ~53 netherrack 0
fill ~26 ~31 ~29 ~26 ~35 ~29 netherrack 0
fill ~26 ~31 ~30 ~26 ~35 ~30 netherrack 0
fill ~26 ~31 ~42 ~28 ~31 ~42 netherrack 0
fill ~26 ~31 ~43 ~27 ~31 ~43 netherrack 0
fill ~26 ~31 ~44 ~26 ~31 ~47 netherrack 0
setblock ~26 ~31 ~54 netherrack 0
fill ~27 ~31 ~38 ~27 ~33 ~38 netherrack 0
setblock ~27 ~31 ~55 netherrack 0
setblock ~28 ~31 ~56 netherrack 0
fill ~29 ~31 ~57 ~29 ~31 ~58 netherrack 0
fill ~30 ~31 ~59 ~30 ~33 ~59 netherrack 0
fill ~30 ~31 ~60 ~30 ~35 ~60 netherrack 0
fill ~31 ~31 ~9 ~31 ~47 ~9 netherrack 0
fill ~31 ~31 ~61 ~31 ~34 ~61 netherrack 0
fill ~31 ~31 ~62 ~31 ~36 ~62 netherrack 0
fill ~32 ~31 ~8 ~33 ~31 ~8 netherrack 0
fill ~34 ~31 ~7 ~38 ~31 ~7 netherrack 0
fill ~37 ~31 ~32 ~38 ~31 ~32 netherrack 0
fill ~38 ~31 ~68 ~38 ~33 ~68 netherrack 0
fill ~39 ~31 ~8 ~49 ~31 ~8 netherrack 0
fill ~39 ~31 ~14 ~43 ~31 ~14 netherrack 0
fill ~39 ~31 ~39 ~49 ~31 ~39 netherrack 0
fill ~39 ~31 ~69 ~49 ~31 ~69 netherrack 0
fill ~41 ~31 ~26 ~41 ~32 ~26 redstone_block 0
fill ~43 ~31 ~36 ~43 ~32 ~36 redstone_block 0
fill ~43 ~31 ~37 ~43 ~31 ~36 redstone_block 0
setblock ~43 ~31 ~64 netherrack 0
setblock ~44 ~31 ~15 redstone_block 0
setblock ~44 ~31 ~65 mrg_watermark 0
fill ~44 ~31 ~68 ~45 ~31 ~68 netherrack 0
fill ~45 ~31 ~14 ~49 ~31 ~14 netherrack 0
fill ~45 ~31 ~64 ~45 ~32 ~64 netherrack 0
setblock ~46 ~31 ~67 coal_block 0
fill ~48 ~31 ~24 ~48 ~32 ~24 redstone_block 0
fill ~50 ~31 ~7 ~55 ~31 ~7 netherrack 0
fill ~50 ~31 ~33 ~53 ~31 ~33 netherrack 0
fill ~50 ~31 ~68 ~50 ~33 ~68 netherrack 0
fill ~52 ~31 ~21 ~53 ~31 ~21 netherrack 0
fill ~54 ~31 ~22 ~55 ~31 ~22 netherrack 0
fill ~54 ~31 ~23 ~55 ~31 ~23 netherrack 0
fill ~54 ~31 ~24 ~55 ~31 ~24 netherrack 0
fill ~54 ~31 ~25 ~55 ~31 ~25 netherrack 0
fill ~54 ~31 ~26 ~55 ~31 ~26 netherrack 0
fill ~54 ~31 ~27 ~55 ~31 ~27 netherrack 0
fill ~54 ~31 ~28 ~55 ~31 ~28 netherrack 0
fill ~54 ~31 ~29 ~55 ~31 ~29 netherrack 0
fill ~54 ~31 ~30 ~55 ~31 ~30 netherrack 0
fill ~54 ~31 ~31 ~55 ~31 ~31 netherrack 0
fill ~54 ~31 ~32 ~55 ~31 ~32 netherrack 0
setblock ~56 ~31 ~8 netherrack 0
fill ~57 ~31 ~9 ~57 ~47 ~9 netherrack 0
fill ~57 ~31 ~61 ~57 ~34 ~61 netherrack 0
fill ~57 ~31 ~62 ~57 ~36 ~62 netherrack 0
fill ~58 ~31 ~59 ~58 ~32 ~59 netherrack 0
fill ~58 ~31 ~60 ~58 ~35 ~60 netherrack 0
fill ~59 ~31 ~57 ~59 ~31 ~58 netherrack 0
fill ~60 ~31 ~42 ~62 ~31 ~42 netherrack 0
setblock ~60 ~31 ~56 netherrack 0
fill ~61 ~31 ~38 ~61 ~33 ~38 netherrack 0
fill ~61 ~31 ~43 ~62 ~31 ~43 netherrack 0
setblock ~61 ~31 ~55 netherrack 0
fill ~62 ~31 ~30 ~62 ~35 ~30 netherrack 0
fill ~62 ~31 ~31 ~62 ~35 ~31 netherrack 0
fill ~62 ~31 ~44 ~62 ~31 ~47 netherrack 0
setblock ~62 ~31 ~54 netherrack 0
fill ~63 ~31 ~48 ~63 ~32 ~48 netherrack 0
fill ~63 ~31 ~49 ~63 ~32 ~49 netherrack 0
fill ~63 ~31 ~52 ~63 ~31 ~53 netherrack 0
fill ~24 ~32 ~51 ~24 ~35 ~51 netherrack 0
fill ~24 ~32 ~52 ~24 ~39 ~52 netherrack 0
fill ~24 ~32 ~53 ~24 ~40 ~53 netherrack 0
fill ~25 ~32 ~41 ~27 ~32 ~41 netherrack 0
fill ~25 ~32 ~42 ~25 ~32 ~50 netherrack 0
fill ~25 ~32 ~54 ~25 ~33 ~54 netherrack 0
fill ~26 ~32 ~31 ~26 ~35 ~31 netherrack 0
fill ~26 ~32 ~32 ~26 ~35 ~32 netherrack 0
fill ~26 ~32 ~55 ~26 ~34 ~55 netherrack 0
fill ~27 ~32 ~16 ~27 ~37 ~16 netherrack 0
fill ~27 ~32 ~19 ~27 ~34 ~19 netherrack 0
fill ~27 ~32 ~20 ~27 ~34 ~20 netherrack 0
fill ~27 ~32 ~39 ~27 ~32 ~41 netherrack 0
fill ~27 ~32 ~56 ~27 ~34 ~56 netherrack 0
fill ~28 ~32 ~57 ~28 ~34 ~57 netherrack 0
fill ~29 ~32 ~11 ~29 ~44 ~11 netherrack 0
fill ~29 ~32 ~58 ~29 ~34 ~58 netherrack 0
fill ~30 ~32 ~10 ~30 ~47 ~10 netherrack 0
fill ~32 ~32 ~9 ~32 ~38 ~9 netherrack 0
fill ~33 ~32 ~8 ~33 ~41 ~8 netherrack 0
fill ~34 ~32 ~7 ~38 ~32 ~7 netherrack 0
fill ~36 ~32 ~67 ~36 ~33 ~67 netherrack 0
fill ~37 ~32 ~32 ~38 ~32 ~32 netherrack 0
fill ~37 ~32 ~33 ~37 ~32 ~32 netherrack 0
fill ~39 ~32 ~8 ~39 ~31 ~8 netherrack 0
fill ~39 ~32 ~14 ~49 ~32 ~14 netherrack 0
fill ~39 ~32 ~39 ~49 ~32 ~39 netherrack 0
fill ~39 ~32 ~68 ~39 ~35 ~68 netherrack 0
fill ~40 ~32 ~9 ~40 ~35 ~9 netherrack 0
fill ~40 ~32 ~69 ~42 ~32 ~69 netherrack 0
fill ~41 ~32 ~8 ~47 ~32 ~8 netherrack 0
fill ~43 ~32 ~32 ~43 ~33 ~32 redstone_block 0
fill ~43 ~32 ~33 ~43 ~32 ~36 redstone_block 0
fill ~43 ~32 ~68 ~45 ~32 ~68 netherrack 0
fill ~43 ~32 ~69 ~45 ~32 ~69 mrg_watermark 0
setblock ~44 ~32 ~16 redstone_block 0
setblock ~44 ~32 ~64 netherrack 0
setblock ~46 ~32 ~67 mrg_watermark 0
fill ~46 ~32 ~69 ~48 ~32 ~69 netherrack 0
fill ~48 ~32 ~9 ~48 ~35 ~9 netherrack 0
fill ~48 ~32 ~25 ~48 ~33 ~25 redstone_block 0
fill ~48 ~32 ~34 ~48 ~33 ~34 redstone_block 0
fill ~48 ~32 ~35 ~49 ~32 ~35 redstone_block 0
setblock ~49 ~32 ~8 netherrack 0
fill ~49 ~32 ~68 ~49 ~35 ~68 netherrack 0
fill ~50 ~32 ~7 ~54 ~32 ~7 netherrack 0
fill ~50 ~32 ~33 ~53 ~32 ~33 netherrack 0
fill ~51 ~32 ~29 ~53 ~32 ~29 redstone_block 0
fill ~52 ~32 ~21 ~53 ~32 ~21 netherrack 0
fill ~52 ~32 ~67 ~52 ~33 ~67 netherrack 0
fill ~54 ~32 ~22 ~54 ~44 ~22 netherrack 0
fill ~54 ~32 ~23 ~54 ~44 ~23 netherrack 0
fill ~54 ~32 ~24 ~54 ~44 ~24 netherrack 0
fill ~54 ~32 ~25 ~54 ~44 ~25 netherrack 0
fill ~54 ~32 ~26 ~54 ~44 ~26 netherrack 0
fill ~54 ~32 ~27 ~54 ~44 ~27 netherrack 0
fill ~54 ~32 ~28 ~54 ~44 ~28 netherrack 0
fill ~54 ~32 ~30 ~54 ~44 ~30 netherrack 0
fill ~54 ~32 ~31 ~54 ~44 ~31 netherrack 0
fill ~54 ~32 ~32 ~54 ~44 ~32 netherrack 0
fill ~55 ~32 ~8 ~55 ~41 ~8 netherrack 0
fill ~56 ~32 ~9 ~56 ~37 ~9 netherrack 0
fill ~58 ~32 ~10 ~58 ~46 ~10 netherrack 0
fill ~59 ~32 ~11 ~59 ~43 ~11 netherrack 0
fill ~59 ~32 ~58 ~59 ~34 ~58 netherrack 0
fill ~60 ~32 ~57 ~60 ~34 ~57 netherrack 0
fill ~61 ~32 ~19 ~61 ~34 ~19 netherrack 0
fill ~61 ~32 ~39 ~61 ~32 ~41 netherrack 0
fill ~61 ~32 ~56 ~61 ~34 ~56 netherrack 0
fill ~62 ~32 ~32 ~62 ~35 ~32 netherrack 0
fill ~62 ~32 ~33 ~62 ~35 ~33 netherrack 0
fill ~62 ~32 ~41 ~63 ~32 ~41 netherrack 0
fill ~62 ~32 ~55 ~62 ~33 ~55 netherrack 0
fill ~63 ~32 ~42 ~63 ~32 ~50 netherrack 0
fill ~63 ~32 ~54 ~63 ~33 ~54 netherrack 0
fill ~64 ~32 ~44 ~64 ~33 ~44 netherrack 0
fill ~64 ~32 ~51 ~64 ~35 ~51 netherrack 0
fill ~64 ~32 ~52 ~64 ~38 ~52 netherrack 0
fill ~64 ~32 ~53 ~64 ~39 ~53 netherrack 0
fill ~24 ~33 ~41 ~24 ~33 ~54 netherrack 0
fill ~25 ~33 ~40 ~26 ~33 ~40 netherrack 0
fill ~26 ~33 ~33 ~26 ~35 ~33 netherrack 0
fill ~26 ~33 ~34 ~26 ~35 ~34 netherrack 0
fill ~26 ~33 ~35 ~26 ~34 ~35 netherrack 0
fill ~26 ~33 ~36 ~26 ~34 ~36 netherrack 0
fill ~26 ~33 ~37 ~26 ~34 ~37 netherrack 0
setblock ~26 ~33 ~39 netherrack 0
setblock ~27 ~33 ~21 netherrack 0
fill ~33 ~33 ~64 ~33 ~38 ~64 netherrack 0
fill ~34 ~33 ~8 ~34 ~41 ~8 netherrack 0
fill ~34 ~33 ~65 ~34 ~38 ~65 netherrack 0
fill ~35 ~33 ~7 ~37 ~33 ~7 netherrack 0
fill ~35 ~33 ~66 ~35 ~34 ~66 netherrack 0
fill ~36 ~33 ~33 ~36 ~36 ~33 netherrack 0
fill ~37 ~33 ~28 ~39 ~33 ~28 redstone_block 0
fill ~37 ~33 ~32 ~38 ~33 ~32 netherrack 0
fill ~37 ~33 ~33 ~37 ~36 ~33 lava 8
fill ~37 ~33 ~34 ~37 ~33 ~37 netherrack 0
fill ~37 ~33 ~67 ~37 ~36 ~67 netherrack 0
fill ~38 ~33 ~8 ~38 ~34 ~8 netherrack 0
fill ~39 ~33 ~9 ~39 ~35 ~9 netherrack 0
fill ~39 ~33 ~14 ~49 ~33 ~14 netherrack 0
fill ~39 ~33 ~39 ~49 ~33 ~39 netherrack 0
fill ~40 ~33 ~68 ~40 ~34 ~68 netherrack 0
fill ~41 ~33 ~9 ~41 ~35 ~9 netherrack 0
fill ~41 ~33 ~69 ~42 ~33 ~69 mrg_watermark 0
setblock ~42 ~33 ~8 netherrack 0
fill ~42 ~33 ~26 ~42 ~33 ~27 redstone_block 0
fill ~42 ~33 ~68 ~42 ~34 ~68 mrg_watermark 0
setblock ~43 ~33 ~31 redstone_block 0
fill ~43 ~33 ~64 ~43 ~94 ~64 netherrack 0
fill ~43 ~33 ~67 ~45 ~33 ~67 mrg_watermark 0
fill ~44 ~33 ~8 ~46 ~33 ~8 netherrack 0
fill ~44 ~33 ~17 ~44 ~33 ~22 redstone_block 0
fill ~44 ~33 ~65 ~45 ~33 ~65 coal_block 0
fill ~46 ~33 ~31 ~46 ~34 ~31 redstone_block 0
fill ~46 ~33 ~32 ~47 ~33 ~32 redstone_block 0
fill ~46 ~33 ~68 ~46 ~34 ~68 mrg_watermark 0
fill ~46 ~33 ~69 ~47 ~33 ~69 mrg_watermark 0
fill ~47 ~33 ~9 ~47 ~36 ~9 netherrack 0
fill ~47 ~33 ~25 ~47 ~34 ~25 redstone_block 0
fill ~47 ~33 ~33 ~48 ~33 ~33 redstone_block 0
fill ~48 ~33 ~68 ~48 ~34 ~68 netherrack 0
fill ~49 ~33 ~9 ~49 ~35 ~9 netherrack 0
fill ~49 ~33 ~29 ~51 ~33 ~29 redstone_block 0
fill ~50 ~33 ~8 ~50 ~34 ~8 netherrack 0
fill ~50 ~33 ~33 ~53 ~33 ~33 netherrack 0
fill ~50 ~33 ~35 ~50 ~38 ~35 netherrack 0
fill ~51 ~33 ~7 ~53 ~33 ~7 netherrack 0
fill ~51 ~33 ~67 ~51 ~36 ~67 netherrack 0
fill ~52 ~33 ~21 ~53 ~33 ~21 netherrack 0
fill ~53 ~33 ~66 ~53 ~34 ~66 netherrack 0
fill ~54 ~33 ~8 ~54 ~41 ~8 netherrack 0
fill ~54 ~33 ~29 ~54 ~44 ~29 netherrack 0
fill ~54 ~33 ~65 ~54 ~38 ~65 netherrack 0
fill ~55 ~33 ~64 ~55 ~38 ~64 netherrack 0
fill ~59 ~33 ~59 ~59 ~36 ~59 netherrack 0
setblock ~61 ~33 ~20 netherrack 0
fill ~62 ~33 ~34 ~62 ~34 ~34 netherrack 0
fill ~62 ~33 ~35 ~62 ~34 ~35 netherrack 0
fill ~62 ~33 ~36 ~62 ~34 ~36 netherrack 0
fill ~62 ~33 ~37 ~62 ~34 ~37 netherrack 0
fill ~62 ~33 ~39 ~62 ~33 ~40 netherrack 0
setblock ~63 ~33 ~40 netherrack 0
fill ~64 ~33 ~41 ~64 ~33 ~54 netherrack 0
fill ~23 ~34 ~41 ~23 ~34 ~46 netherrack 0
fill ~24 ~34 ~39 ~25 ~34 ~39 netherrack 0
fill ~24 ~34 ~40 ~24 ~34 ~39 netherrack 0
fill ~24 ~34 ~47 ~24 ~34 ~54 netherrack 0
fill ~25 ~34 ~38 ~26 ~34 ~38 netherrack 0
fill ~25 ~34 ~55 ~25 ~40 ~55 netherrack 0
fill ~26 ~34 ~21 ~26 ~39 ~21 netherrack 0
fill ~27 ~34 ~15 ~27 ~39 ~15 netherrack 0
fill ~29 ~34 ~59 ~29 ~36 ~59 netherrack 0
fill ~35 ~34 ~8 ~38 ~34 ~8 netherrack 0
fill ~36 ~34 ~28 ~36 ~57 ~28 netherrack 0
fill ~36 ~34 ~32 ~36 ~57 ~32 netherrack 0
fill ~36 ~34 ~34 ~36 ~56 ~34 netherrack 0
fill ~36 ~34 ~35 ~36 ~56 ~35 netherrack 0
fill ~36 ~34 ~36 ~36 ~56 ~36 netherrack 0
fill ~36 ~34 ~37 ~36 ~56 ~37 netherrack 0
fill ~36 ~34 ~66 ~36 ~37 ~66 netherrack 0
fill ~37 ~34 ~38 ~37 ~39 ~38 netherrack 0
setblock ~38 ~34 ~67 netherrack 0
fill ~39 ~34 ~14 ~49 ~34 ~14 netherrack 0
fill ~39 ~34 ~28 ~40 ~34 ~28 redstone_block 0
fill ~39 ~34 ~39 ~49 ~34 ~39 netherrack 0
setblock ~41 ~34 ~68 netherrack 0
fill ~41 ~34 ~69 ~42 ~34 ~69 end_rod 0
fill ~42 ~34 ~9 ~42 ~36 ~9 netherrack 0
setblock ~42 ~34 ~27 redstone_block 0
fill ~42 ~34 ~28 ~46 ~34 ~28 obsidian 0
fill ~42 ~34 ~29 ~46 ~34 ~29 obsidian 0
fill ~42 ~34 ~30 ~46 ~34 ~30 obsidian 0
fill ~43 ~34 ~27 ~45 ~34 ~27 obsidian 0
fill ~43 ~34 ~31 ~45 ~34 ~31 obsidian 0
fill ~43 ~34 ~65 ~43 ~95 ~65 netherrack 0
fill ~43 ~34 ~67 ~45 ~34 ~67 mrg_watermark 0
fill ~43 ~34 ~70 ~45 ~34 ~70 end_rod 0
fill ~44 ~34 ~9 ~49 ~34 ~9 netherrack 0
fill ~44 ~34 ~22 ~44 ~34 ~23 redstone_block 0
setblock ~44 ~34 ~66 coal_block 0
setblock ~45 ~34 ~65 netherrack 0
setblock ~46 ~34 ~66 netherrack 0
fill ~46 ~34 ~69 ~47 ~34 ~69 end_rod 0
fill ~47 ~34 ~26 ~47 ~35 ~26 redstone_block 0
fill ~47 ~34 ~29 ~49 ~34 ~29 redstone_block 0
setblock ~47 ~34 ~68 netherrack 0
fill ~50 ~34 ~33 ~53 ~34 ~33 netherrack 0
setblock ~50 ~34 ~67 netherrack 0
fill ~51 ~34 ~8 ~55 ~34 ~8 netherrack 0
fill ~52 ~34 ~21 ~53 ~34 ~21 netherrack 0
fill ~52 ~34 ~66 ~52 ~37 ~66 netherrack 0
fill ~61 ~34 ~15 ~61 ~39 ~15 netherrack 0
fill ~62 ~34 ~20 ~62 ~39 ~20 netherrack 0
fill ~62 ~34 ~38 ~63 ~34 ~38 netherrack 0
fill ~62 ~34 ~56 ~62 ~38 ~56 netherrack 0
fill ~63 ~34 ~39 ~64 ~34 ~39 netherrack 0
fill ~63 ~34 ~55 ~63 ~39 ~55 netherrack 0
setblock ~64 ~34 ~40 netherrack 0
fill ~64 ~34 ~47 ~64 ~34 ~54 netherrack 0
fill ~65 ~34 ~41 ~66 ~34 ~41 netherrack 0
fill ~65 ~34 ~42 ~66 ~34 ~42 netherrack 0
fill ~65 ~34 ~43 ~66 ~34 ~43 netherrack 0
fill ~65 ~34 ~44 ~66 ~34 ~44 netherrack 0
fill ~65 ~34 ~45 ~65 ~34 ~46 netherrack 0
