fill ~1 ~-3 ~0 ~6 ~-3 ~0 air 0
fill ~1 ~-3 ~1 ~6 ~-3 ~1 air 0
fill ~1 ~-3 ~2 ~6 ~-3 ~2 air 0
fill ~1 ~-3 ~3 ~6 ~-3 ~3 air 0
fill ~1 ~-3 ~4 ~6 ~-3 ~4 air 0
fill ~1 ~-3 ~5 ~6 ~-3 ~5 air 0
fill ~1 ~-3 ~6 ~6 ~-3 ~6 air 0
fill ~1 ~-3 ~7 ~6 ~-3 ~7 air 0
fill ~1 ~-3 ~8 ~6 ~-3 ~8 air 0
fill ~1 ~-3 ~9 ~6 ~-3 ~9 air 0
fill ~1 ~-3 ~10 ~6 ~-3 ~10 air 0
fill ~1 ~-3 ~11 ~6 ~-3 ~11 air 0
fill ~1 ~-3 ~12 ~6 ~-3 ~12 air 0
fill ~1 ~-3 ~13 ~6 ~-3 ~13 air 0
fill ~1 ~-3 ~14 ~6 ~-3 ~14 air 0
fill ~1 ~-3 ~15 ~6 ~-3 ~15 air 0
fill ~1 ~-3 ~16 ~6 ~-3 ~16 air 0
fill ~1 ~-3 ~17 ~6 ~-3 ~17 air 0
fill ~1 ~-3 ~18 ~6 ~-3 ~18 air 0
fill ~1 ~-3 ~19 ~6 ~-3 ~19 air 0
fill ~1 ~-3 ~20 ~6 ~-3 ~20 air 0
fill ~1 ~-3 ~21 ~6 ~-3 ~21 air 0
fill ~1 ~-3 ~22 ~6 ~-3 ~22 air 0
fill ~1 ~-3 ~23 ~6 ~-3 ~23 air 0
fill ~1 ~-3 ~24 ~6 ~-3 ~24 air 0
fill ~1 ~-3 ~25 ~6 ~-3 ~25 air 0
fill ~1 ~-3 ~26 ~6 ~-3 ~26 air 0
fill ~1 ~-3 ~27 ~6 ~-3 ~27 air 0
fill ~1 ~-3 ~28 ~6 ~-3 ~28 air 0
fill ~1 ~-3 ~29 ~6 ~-3 ~29 air 0
fill ~1 ~-3 ~30 ~6 ~-3 ~30 air 0
fill ~1 ~-3 ~31 ~6 ~-3 ~31 air 0
fill ~1 ~-3 ~32 ~6 ~-3 ~32 air 0
fill ~1 ~-3 ~33 ~6 ~-3 ~33 air 0
fill ~1 ~-3 ~34 ~6 ~-3 ~34 air 0
fill ~1 ~-3 ~35 ~6 ~-3 ~35 air 0
fill ~1 ~-3 ~36 ~6 ~-3 ~36 air 0
fill ~1 ~-3 ~37 ~6 ~-3 ~37 air 0
fill ~1 ~-3 ~38 ~6 ~-3 ~38 air 0
fill ~1 ~-3 ~39 ~6 ~-3 ~39 air 0
fill ~1 ~-3 ~40 ~6 ~-3 ~40 air 0
fill ~1 ~-3 ~41 ~6 ~-3 ~41 air 0
fill ~1 ~-3 ~42 ~6 ~-3 ~42 air 0
fill ~1 ~-3 ~43 ~6 ~-3 ~43 air 0
fill ~1 ~-3 ~44 ~6 ~-3 ~44 air 0
fill ~1 ~-3 ~45 ~6 ~-3 ~45 air 0
fill ~1 ~-3 ~46 ~6 ~-3 ~46 air 0
fill ~1 ~-3 ~47 ~6 ~-3 ~47 air 0
fill ~1 ~-3 ~48 ~6 ~-3 ~48 air 0
fill ~1 ~-3 ~49 ~6 ~-3 ~49 air 0
fill ~1 ~-3 ~50 ~6 ~-3 ~50 air 0
fill ~1 ~-3 ~51 ~6 ~-3 ~51 air 0
fill ~1 ~-3 ~52 ~6 ~-3 ~52 air 0
fill ~1 ~-3 ~53 ~6 ~-3 ~53 air 0
fill ~1 ~-3 ~54 ~6 ~-3 ~54 air 0
fill ~1 ~-3 ~55 ~6 ~-3 ~55 air 0
fill ~1 ~-3 ~56 ~6 ~-3 ~56 air 0
fill ~1 ~-3 ~57 ~6 ~-3 ~57 air 0
fill ~1 ~-3 ~58 ~6 ~-3 ~58 air 0
fill ~1 ~-3 ~59 ~6 ~-3 ~59 air 0
fill ~1 ~-3 ~60 ~6 ~-3 ~60 air 0
fill ~1 ~-3 ~61 ~6 ~-3 ~61 air 0
fill ~1 ~-3 ~62 ~6 ~-3 ~62 air 0
fill ~1 ~-3 ~63 ~6 ~-3 ~63 air 0
fill ~1 ~-3 ~64 ~6 ~-3 ~64 air 0
fill ~1 ~-3 ~65 ~6 ~-3 ~65 air 0
fill ~1 ~-3 ~66 ~6 ~-3 ~66 air 0
fill ~1 ~-3 ~67 ~6 ~-3 ~67 air 0
fill ~1 ~-3 ~68 ~6 ~-3 ~68 air 0
fill ~1 ~-3 ~69 ~6 ~-3 ~69 air 0
fill ~1 ~-3 ~70 ~6 ~-3 ~70 air 0
fill ~1 ~-3 ~71 ~6 ~-3 ~71 air 0
fill ~1 ~-3 ~72 ~6 ~-3 ~72 air 0
fill ~1 ~-3 ~73 ~6 ~-3 ~73 air 0
fill ~1 ~-3 ~74 ~6 ~-3 ~74 air 0
fill ~1 ~-3 ~75 ~6 ~-3 ~75 air 0
fill ~1 ~-3 ~76 ~6 ~-3 ~76 air 0
fill ~1 ~-3 ~77 ~6 ~-3 ~77 air 0
fill ~1 ~-3 ~78 ~6 ~-3 ~78 air 0
fill ~1 ~-3 ~79 ~6 ~-3 ~79 air 0
fill ~1 ~-3 ~80 ~6 ~-3 ~80 air 0
fill ~1 ~-3 ~81 ~6 ~-3 ~81 air 0
fill ~1 ~-3 ~82 ~6 ~-3 ~82 air 0
fill ~1 ~-3 ~83 ~6 ~-3 ~83 air 0
fill ~1 ~-3 ~84 ~6 ~-3 ~84 air 0
fill ~1 ~-3 ~85 ~6 ~-3 ~85 air 0
fill ~1 ~-3 ~86 ~6 ~-3 ~86 air 0
fill ~1 ~-3 ~87 ~6 ~-3 ~87 air 0
fill ~1 ~-3 ~88 ~6 ~-3 ~88 air 0
fill ~1 ~-3 ~89 ~6 ~-3 ~89 air 0
fill ~1 ~-3 ~90 ~6 ~-3 ~90 air 0
fill ~1 ~-3 ~91 ~6 ~-3 ~91 air 0
fill ~1 ~-3 ~92 ~6 ~-3 ~92 air 0
fill ~1 ~-3 ~93 ~6 ~-3 ~93 air 0
fill ~1 ~-3 ~94 ~6 ~-3 ~94 air 0
fill ~1 ~-3 ~95 ~6 ~-3 ~95 air 0
fill ~1 ~-3 ~96 ~6 ~-3 ~96 air 0
fill ~1 ~-3 ~97 ~6 ~-3 ~97 air 0
fill ~1 ~-3 ~98 ~6 ~-3 ~98 air 0
fill ~1 ~-3 ~99 ~6 ~-3 ~99 air 0
fill ~1 ~-3 ~100 ~6 ~-3 ~100 air 0
fill ~1 ~-3 ~101 ~6 ~-3 ~101 air 0
fill ~1 ~-3 ~102 ~6 ~-3 ~102 air 0
fill ~1 ~-3 ~103 ~6 ~-3 ~103 air 0
fill ~1 ~-3 ~104 ~6 ~-3 ~104 air 0
fill ~1 ~-3 ~105 ~6 ~-3 ~105 air 0
fill ~1 ~-3 ~106 ~6 ~-3 ~106 air 0
fill ~1 ~-3 ~107 ~6 ~-3 ~107 air 0
fill ~1 ~-3 ~108 ~6 ~-3 ~108 air 0
fill ~1 ~-3 ~109 ~6 ~-3 ~109 air 0
fill ~1 ~-3 ~110 ~6 ~-3 ~110 air 0
fill ~1 ~-3 ~111 ~6 ~-3 ~111 air 0
fill ~1 ~-3 ~112 ~6 ~-3 ~112 air 0
fill ~1 ~-3 ~113 ~6 ~-3 ~113 air 0
fill ~1 ~-3 ~114 ~6 ~-3 ~114 air 0
fill ~1 ~-3 ~115 ~6 ~-3 ~115 air 0
fill ~1 ~-3 ~116 ~6 ~-3 ~116 air 0
fill ~1 ~-3 ~117 ~6 ~-3 ~117 air 0
fill ~1 ~-3 ~118 ~6 ~-3 ~118 air 0
fill ~20 ~5 ~76 ~20 ~5 ~77 wool 15
fill ~38 ~5 ~76 ~38 ~5 ~77 wool 15
setblock ~16 ~6 ~73 wool 15
fill ~20 ~6 ~77 ~20 ~8 ~77 wool 15
fill ~22 ~6 ~53 ~22 ~9 ~53 wool 15
fill ~22 ~6 ~54 ~22 ~10 ~54 wool 15
fill ~24 ~6 ~12 ~34 ~6 ~12 wool 0
fill ~24 ~6 ~13 ~24 ~9 ~13 wool 0
fill ~24 ~6 ~74 ~24 ~7 ~74 wool 15
fill ~26 ~6 ~13 ~32 ~6 ~13 wool 0
fill ~34 ~6 ~13 ~35 ~6 ~13 wool 0
fill ~34 ~6 ~74 ~34 ~7 ~74 wool 15
fill ~36 ~6 ~53 ~37 ~6 ~53 wool 15
fill ~37 ~6 ~54 ~37 ~10 ~54 wool 15
fill ~38 ~6 ~77 ~38 ~8 ~77 wool 15
setblock ~42 ~6 ~73 wool 15
fill ~15 ~7 ~74 ~16 ~7 ~74 wool 15
fill ~18 ~7 ~15 ~22 ~7 ~15 wool 0
fill ~20 ~7 ~14 ~39 ~7 ~14 wool 0
fill ~20 ~7 ~76 ~20 ~8 ~76 wool 15
setblock ~20 ~7 ~78 wool 15
fill ~21 ~7 ~13 ~38 ~7 ~13 wool 0
fill ~23 ~7 ~12 ~35 ~7 ~12 wool 0
fill ~25 ~7 ~74 ~25 ~8 ~74 wool 15
fill ~25 ~7 ~75 ~25 ~8 ~75 wool 15
fill ~33 ~7 ~75 ~34 ~7 ~75 wool 15
fill ~36 ~7 ~15 ~40 ~7 ~15 wool 0
fill ~36 ~7 ~53 ~37 ~7 ~53 wool 15
setblock ~38 ~7 ~76 wool 15
setblock ~38 ~7 ~78 wool 15
fill ~42 ~7 ~74 ~43 ~7 ~74 wool 15
fill ~15 ~8 ~74 ~16 ~8 ~74 wool 15
fill ~15 ~8 ~75 ~15 ~8 ~74 wool 15
fill ~17 ~8 ~16 ~22 ~8 ~16 wool 0
fill ~17 ~8 ~17 ~18 ~8 ~17 wool 0
fill ~19 ~8 ~15 ~40 ~8 ~15 wool 0
fill ~20 ~8 ~14 ~38 ~8 ~14 wool 0
fill ~20 ~8 ~75 ~21 ~8 ~75 wool 4
fill ~22 ~8 ~13 ~37 ~8 ~13 wool 0
fill ~33 ~8 ~74 ~34 ~8 ~74 wool 4
fill ~33 ~8 ~75 ~34 ~8 ~75 wool 15
fill ~36 ~8 ~16 ~41 ~8 ~16 wool 0
fill ~36 ~8 ~53 ~37 ~8 ~53 wool 15
fill ~36 ~8 ~54 ~36 ~10 ~54 wool 15
fill ~37 ~8 ~75 ~39 ~8 ~75 wool 4
fill ~38 ~8 ~76 ~38 ~10 ~76 wool 4
fill ~40 ~8 ~17 ~41 ~8 ~17 wool 0
fill ~43 ~8 ~74 ~43 ~10 ~74 wool 15
fill ~43 ~8 ~75 ~43 ~8 ~74 wool 15
fill ~15 ~9 ~72 ~16 ~9 ~72 wool 4
fill ~15 ~9 ~73 ~16 ~9 ~73 wool 4
setblock ~15 ~9 ~74 wool 15
fill ~16 ~9 ~17 ~23 ~9 ~17 wool 0
fill ~16 ~9 ~18 ~18 ~9 ~18 wool 0
fill ~16 ~9 ~74 ~16 ~11 ~74 wool 4
fill ~18 ~9 ~16 ~40 ~9 ~16 wool 0
fill ~19 ~9 ~15 ~39 ~9 ~15 wool 0
fill ~19 ~9 ~75 ~21 ~9 ~75 wool 4
fill ~20 ~9 ~74 ~21 ~9 ~74 wool 4
fill ~20 ~9 ~76 ~21 ~9 ~76 wool 4
fill ~20 ~9 ~77 ~20 ~9 ~74 wool 4
fill ~21 ~9 ~14 ~37 ~9 ~14 wool 0
fill ~21 ~9 ~54 ~21 ~10 ~54 wool 15
fill ~21 ~9 ~55 ~22 ~9 ~55 wool 15
fill ~21 ~9 ~56 ~22 ~9 ~56 wool 15
fill ~24 ~9 ~73 ~25 ~9 ~73 wool 4
fill ~24 ~9 ~74 ~25 ~9 ~74 wool 4
fill ~25 ~9 ~13 ~34 ~9 ~13 wool 0
fill ~25 ~9 ~75 ~25 ~10 ~75 wool 4
fill ~33 ~9 ~73 ~34 ~9 ~73 wool 4
fill ~33 ~9 ~74 ~34 ~9 ~74 wool 4
fill ~33 ~9 ~75 ~33 ~10 ~75 wool 4
setblock ~34 ~9 ~75 wool 15
fill ~36 ~9 ~17 ~42 ~9 ~17 wool 0
fill ~36 ~9 ~53 ~37 ~9 ~53 wool 15
fill ~36 ~9 ~55 ~37 ~9 ~55 wool 15
fill ~36 ~9 ~56 ~37 ~9 ~56 wool 15
fill ~37 ~9 ~75 ~39 ~9 ~75 wool 4
fill ~37 ~9 ~76 ~37 ~10 ~76 wool 4
fill ~38 ~9 ~74 ~39 ~9 ~74 wool 4
setblock ~38 ~9 ~77 wool 4
fill ~39 ~9 ~76 ~39 ~10 ~76 wool 4
fill ~40 ~9 ~18 ~42 ~9 ~18 wool 0
fill ~42 ~9 ~72 ~43 ~9 ~72 wool 4
fill ~42 ~9 ~73 ~42 ~11 ~73 wool 4
setblock ~43 ~9 ~73 wool 15
fill ~15 ~10 ~72 ~16 ~10 ~72 wool 4
fill ~15 ~10 ~73 ~16 ~10 ~73 wool 4
fill ~15 ~10 ~74 ~15 ~11 ~74 wool 4
fill ~16 ~10 ~18 ~23 ~10 ~18 wool 0
fill ~16 ~10 ~19 ~18 ~10 ~19 wool 0
fill ~16 ~10 ~71 ~16 ~12 ~71 wool 4
fill ~17 ~10 ~17 ~41 ~10 ~17 wool 0
fill ~19 ~10 ~16 ~40 ~10 ~16 wool 0
fill ~20 ~10 ~15 ~38 ~10 ~15 wool 0
fill ~20 ~10 ~73 ~21 ~10 ~73 wool 4
fill ~20 ~10 ~74 ~21 ~10 ~74 wool 4
fill ~20 ~10 ~75 ~21 ~10 ~75 wool 4
fill ~20 ~10 ~76 ~21 ~10 ~76 wool 4
fill ~21 ~10 ~55 ~22 ~10 ~55 wool 15
fill ~21 ~10 ~56 ~22 ~10 ~56 wool 15
fill ~21 ~10 ~57 ~21 ~10 ~59 wool 4
fill ~22 ~10 ~14 ~36 ~10 ~14 wool 0
setblock ~22 ~10 ~57 wool 15
fill ~22 ~10 ~58 ~22 ~12 ~58 wool 4
fill ~24 ~10 ~72 ~25 ~10 ~72 wool 4
fill ~24 ~10 ~73 ~25 ~10 ~73 wool 4
fill ~24 ~10 ~74 ~25 ~10 ~74 wool 4
fill ~33 ~10 ~72 ~34 ~10 ~72 wool 4
fill ~33 ~10 ~73 ~34 ~10 ~73 wool 4
fill ~33 ~10 ~74 ~34 ~10 ~74 wool 4
fill ~36 ~10 ~18 ~42 ~10 ~18 wool 0
fill ~36 ~10 ~55 ~37 ~10 ~55 wool 15
fill ~36 ~10 ~56 ~37 ~10 ~56 wool 15
fill ~36 ~10 ~57 ~37 ~10 ~57 wool 15
fill ~37 ~10 ~58 ~37 ~10 ~59 wool 15
fill ~37 ~10 ~73 ~39 ~10 ~73 wool 4
fill ~37 ~10 ~74 ~39 ~10 ~74 wool 4
fill ~37 ~10 ~75 ~39 ~10 ~75 wool 4
fill ~40 ~10 ~19 ~43 ~10 ~19 wool 0
fill ~42 ~10 ~71 ~43 ~10 ~71 wool 4
fill ~42 ~10 ~72 ~43 ~10 ~72 wool 4
setblock ~42 ~10 ~74 wool 4
fill ~43 ~10 ~73 ~44 ~10 ~73 wool 4
fill ~15 ~11 ~71 ~15 ~11 ~74 wool 4
fill ~16 ~11 ~19 ~23 ~11 ~19 wool 0
fill ~16 ~11 ~20 ~18 ~11 ~20 wool 0
fill ~16 ~11 ~68 ~18 ~11 ~68 wool 4
fill ~16 ~11 ~69 ~18 ~11 ~69 wool 4
fill ~16 ~11 ~70 ~17 ~11 ~70 wool 4
fill ~16 ~11 ~72 ~17 ~11 ~72 wool 4
fill ~16 ~11 ~73 ~16 ~11 ~68 wool 4
fill ~17 ~11 ~18 ~42 ~11 ~18 wool 0
fill ~17 ~11 ~65 ~24 ~11 ~65 wool 4
fill ~17 ~11 ~66 ~24 ~11 ~66 wool 4
fill ~17 ~11 ~67 ~18 ~11 ~67 wool 4
fill ~17 ~11 ~71 ~17 ~12 ~71 wool 4
fill ~18 ~11 ~17 ~40 ~11 ~17 wool 0
fill ~18 ~11 ~63 ~23 ~11 ~63 wool 4
fill ~18 ~11 ~64 ~23 ~11 ~64 wool 4
fill ~19 ~11 ~16 ~39 ~11 ~16 wool 0
fill ~19 ~11 ~62 ~23 ~11 ~62 wool 4
fill ~20 ~11 ~60 ~22 ~11 ~60 wool 4
fill ~20 ~11 ~61 ~23 ~11 ~61 wool 4
fill ~20 ~11 ~67 ~21 ~11 ~67 wool 4
fill ~20 ~11 ~68 ~21 ~11 ~68 wool 4
fill ~20 ~11 ~69 ~21 ~11 ~69 wool 4
fill ~20 ~11 ~70 ~21 ~11 ~70 wool 4
fill ~20 ~11 ~71 ~21 ~11 ~71 wool 4
fill ~20 ~11 ~72 ~21 ~11 ~72 wool 4
fill ~20 ~11 ~73 ~21 ~11 ~73 wool 4
fill ~20 ~11 ~74 ~21 ~11 ~74 wool 4
fill ~20 ~11 ~75 ~21 ~11 ~75 wool 4
fill ~21 ~11 ~55 ~23 ~11 ~55 wool 15
fill ~21 ~11 ~56 ~22 ~11 ~56 wool 15
fill ~21 ~11 ~57 ~21 ~11 ~55 wool 15
fill ~21 ~11 ~58 ~21 ~12 ~58 wool 4
fill ~21 ~11 ~59 ~22 ~11 ~59 wool 4
fill ~22 ~11 ~15 ~37 ~11 ~15 wool 0
fill ~22 ~11 ~57 ~22 ~12 ~57 wool 4
fill ~23 ~11 ~67 ~24 ~11 ~67 wool 4
fill ~23 ~11 ~68 ~24 ~11 ~68 wool 4
fill ~23 ~11 ~69 ~25 ~11 ~69 wool 4
fill ~23 ~11 ~70 ~25 ~11 ~70 wool 4
fill ~23 ~11 ~71 ~25 ~11 ~71 wool 4
fill ~24 ~11 ~72 ~25 ~11 ~72 wool 4
fill ~24 ~11 ~73 ~25 ~11 ~73 wool 4
fill ~24 ~11 ~74 ~25 ~11 ~74 wool 4
fill ~26 ~11 ~14 ~32 ~11 ~14 wool 0
fill ~33 ~11 ~70 ~35 ~11 ~70 wool 4
fill ~33 ~11 ~71 ~35 ~11 ~71 wool 4
fill ~33 ~11 ~72 ~35 ~11 ~72 wool 4
fill ~33 ~11 ~73 ~34 ~11 ~73 wool 4
fill ~33 ~11 ~74 ~34 ~11 ~74 wool 4
fill ~34 ~11 ~66 ~41 ~11 ~66 wool 4
fill ~34 ~11 ~67 ~42 ~11 ~67 wool 4
fill ~34 ~11 ~68 ~35 ~11 ~68 wool 4
fill ~34 ~11 ~69 ~35 ~11 ~69 wool 4
fill ~35 ~11 ~19 ~43 ~11 ~19 wool 0
fill ~35 ~11 ~62 ~39 ~11 ~62 wool 4
fill ~35 ~11 ~63 ~40 ~11 ~63 wool 4
fill ~35 ~11 ~64 ~40 ~11 ~64 wool 4
fill ~35 ~11 ~65 ~41 ~11 ~65 wool 4
fill ~36 ~11 ~55 ~37 ~11 ~55 wool 15
fill ~36 ~11 ~56 ~37 ~11 ~56 wool 15
fill ~36 ~11 ~57 ~37 ~11 ~57 wool 4
fill ~36 ~11 ~58 ~38 ~11 ~58 wool 4
fill ~36 ~11 ~59 ~38 ~11 ~59 wool 4
fill ~36 ~11 ~60 ~38 ~11 ~60 wool 4
fill ~36 ~11 ~61 ~39 ~11 ~61 wool 4
fill ~37 ~11 ~68 ~38 ~11 ~68 wool 4
fill ~37 ~11 ~69 ~38 ~11 ~69 wool 4
fill ~37 ~11 ~70 ~38 ~11 ~70 wool 4
fill ~37 ~11 ~71 ~39 ~11 ~71 wool 4
fill ~37 ~11 ~72 ~39 ~11 ~72 wool 4
fill ~37 ~11 ~73 ~39 ~11 ~73 wool 4
fill ~37 ~11 ~74 ~39 ~11 ~74 wool 4
setblock ~38 ~11 ~75 wool 4
fill ~40 ~11 ~20 ~43 ~11 ~20 wool 0
fill ~40 ~11 ~68 ~42 ~11 ~68 wool 4
fill ~41 ~11 ~69 ~42 ~11 ~69 wool 4
fill ~41 ~11 ~70 ~43 ~11 ~70 wool 4
fill ~41 ~11 ~71 ~43 ~11 ~71 wool 4
fill ~42 ~11 ~72 ~43 ~11 ~72 wool 4
fill ~43 ~11 ~73 ~43 ~10 ~73 wool 4
fill ~43 ~11 ~74 ~43 ~11 ~70 wool 4
fill ~16 ~12 ~20 ~23 ~12 ~20 wool 0
fill ~16 ~12 ~21 ~19 ~12 ~21 wool 0
fill ~16 ~12 ~68 ~18 ~12 ~68 wool 4
fill ~16 ~12 ~69 ~18 ~12 ~69 wool 4
fill ~16 ~12 ~70 ~17 ~12 ~70 wool 4
setblock ~16 ~12 ~72 wool 4
fill ~17 ~12 ~19 ~42 ~12 ~19 wool 0
fill ~17 ~12 ~65 ~24 ~12 ~65 wool 4
fill ~17 ~12 ~66 ~24 ~12 ~66 wool 4
fill ~17 ~12 ~67 ~18 ~12 ~67 wool 4
fill ~18 ~12 ~18 ~40 ~12 ~18 wool 0
fill ~18 ~12 ~63 ~24 ~12 ~63 wool 4
fill ~18 ~12 ~64 ~24 ~12 ~64 wool 4
fill ~19 ~12 ~17 ~39 ~12 ~17 wool 0
fill ~19 ~12 ~61 ~23 ~12 ~61 wool 4
fill ~19 ~12 ~62 ~23 ~12 ~62 wool 4
fill ~20 ~12 ~60 ~22 ~12 ~60 wool 4
fill ~20 ~12 ~67 ~21 ~12 ~67 wool 4
fill ~20 ~12 ~68 ~21 ~12 ~68 wool 4
fill ~20 ~12 ~69 ~21 ~12 ~69 wool 4
fill ~20 ~12 ~70 ~21 ~12 ~70 wool 4
fill ~20 ~12 ~71 ~21 ~12 ~71 wool 4
fill ~20 ~12 ~72 ~21 ~12 ~72 wool 4
fill ~20 ~12 ~73 ~21 ~12 ~73 wool 4
fill ~20 ~12 ~74 ~20 ~9 ~74 wool 4
fill ~21 ~12 ~16 ~37 ~12 ~16 wool 0
setblock ~21 ~12 ~57 wool 4
fill ~21 ~12 ~59 ~22 ~12 ~59 wool 4
fill ~23 ~12 ~67 ~24 ~12 ~67 wool 4
fill ~23 ~12 ~68 ~24 ~12 ~68 wool 4
fill ~23 ~12 ~69 ~25 ~12 ~69 wool 4
fill ~23 ~12 ~70 ~25 ~12 ~70 wool 4
fill ~23 ~12 ~71 ~25 ~12 ~71 wool 4
fill ~24 ~12 ~15 ~34 ~12 ~15 wool 0
fill ~24 ~12 ~72 ~25 ~12 ~72 wool 4
fill ~24 ~12 ~73 ~25 ~12 ~73 wool 4
fill ~33 ~12 ~70 ~35 ~12 ~70 wool 4
fill ~33 ~12 ~71 ~35 ~12 ~71 wool 4
fill ~33 ~12 ~72 ~34 ~12 ~72 wool 4
fill ~34 ~12 ~65 ~41 ~12 ~65 wool 4
fill ~34 ~12 ~66 ~41 ~12 ~66 wool 4
fill ~34 ~12 ~67 ~42 ~12 ~67 wool 4
fill ~34 ~12 ~68 ~35 ~12 ~68 wool 4
fill ~34 ~12 ~69 ~35 ~12 ~69 wool 4
setblock ~34 ~12 ~73 wool 4
fill ~35 ~12 ~20 ~42 ~12 ~20 wool 0
fill ~35 ~12 ~62 ~40 ~12 ~62 wool 4
fill ~35 ~12 ~63 ~40 ~12 ~63 wool 4
fill ~35 ~12 ~64 ~41 ~12 ~64 wool 4
fill ~36 ~12 ~57 ~37 ~12 ~57 wool 4
fill ~36 ~12 ~58 ~38 ~12 ~58 wool 4
fill ~36 ~12 ~59 ~38 ~12 ~59 wool 4
fill ~36 ~12 ~60 ~38 ~12 ~60 wool 4
fill ~36 ~12 ~61 ~39 ~12 ~61 wool 4
fill ~37 ~12 ~68 ~42 ~12 ~68 wool 4
fill ~37 ~12 ~69 ~39 ~12 ~69 wool 4
fill ~37 ~12 ~70 ~39 ~12 ~70 wool 4
fill ~37 ~12 ~71 ~39 ~12 ~71 wool 4
fill ~37 ~12 ~72 ~39 ~12 ~72 wool 4
fill ~37 ~12 ~73 ~39 ~12 ~73 wool 4
setblock ~38 ~12 ~74 wool 4
fill ~40 ~12 ~21 ~42 ~12 ~21 wool 0
fill ~41 ~12 ~69 ~42 ~12 ~69 wool 4
fill ~41 ~12 ~70 ~43 ~12 ~70 wool 4
fill ~41 ~12 ~71 ~43 ~12 ~71 wool 4
fill ~42 ~12 ~72 ~43 ~12 ~72 wool 4
fill ~16 ~13 ~21 ~24 ~13 ~21 wool 0
fill ~16 ~13 ~69 ~17 ~13 ~69 wool 4
fill ~16 ~13 ~70 ~17 ~13 ~70 wool 4
fill ~17 ~13 ~20 ~41 ~13 ~20 wool 0
fill ~17 ~13 ~22 ~18 ~13 ~22 wool 0
fill ~17 ~13 ~66 ~24 ~13 ~66 wool 4
fill ~17 ~13 ~67 ~18 ~13 ~67 wool 4
fill ~17 ~13 ~68 ~18 ~13 ~68 wool 4
fill ~18 ~13 ~19 ~40 ~13 ~19 wool 0
fill ~18 ~13 ~63 ~24 ~13 ~63 wool 4
fill ~18 ~13 ~64 ~24 ~13 ~64 wool 4
fill ~18 ~13 ~65 ~24 ~13 ~65 wool 4
fill ~19 ~13 ~18 ~39 ~13 ~18 wool 0
fill ~19 ~13 ~62 ~23 ~13 ~62 wool 4
fill ~20 ~13 ~61 ~23 ~13 ~61 wool 4
fill ~20 ~13 ~67 ~21 ~13 ~67 wool 4
fill ~20 ~13 ~68 ~21 ~13 ~68 wool 4
fill ~20 ~13 ~69 ~21 ~13 ~69 wool 4
fill ~20 ~13 ~70 ~21 ~13 ~70 wool 4
fill ~20 ~13 ~71 ~21 ~13 ~71 wool 4
fill ~20 ~13 ~72 ~21 ~13 ~72 wool 4
fill ~21 ~13 ~17 ~37 ~13 ~17 wool 0
fill ~21 ~13 ~60 ~22 ~13 ~60 wool 4
fill ~23 ~13 ~67 ~24 ~13 ~67 wool 4
fill ~23 ~13 ~68 ~24 ~13 ~68 wool 4
fill ~24 ~13 ~16 ~35 ~13 ~16 wool 0
fill ~24 ~13 ~69 ~24 ~13 ~70 wool 4
fill ~34 ~13 ~65 ~41 ~13 ~65 wool 4
fill ~34 ~13 ~66 ~41 ~13 ~66 wool 4
fill ~34 ~13 ~67 ~41 ~13 ~67 wool 4
fill ~34 ~13 ~68 ~35 ~13 ~68 wool 4
fill ~34 ~13 ~69 ~35 ~13 ~69 wool 4
fill ~34 ~13 ~70 ~34 ~13 ~65 wool 4
fill ~35 ~13 ~21 ~42 ~13 ~21 wool 0
fill ~35 ~13 ~62 ~39 ~13 ~62 wool 4
fill ~35 ~13 ~63 ~40 ~13 ~63 wool 4
fill ~35 ~13 ~64 ~40 ~13 ~64 wool 4
fill ~36 ~13 ~60 ~38 ~13 ~60 wool 4
fill ~36 ~13 ~61 ~39 ~13 ~61 wool 4
fill ~37 ~13 ~68 ~38 ~13 ~68 wool 4
fill ~37 ~13 ~69 ~38 ~13 ~69 wool 4
fill ~37 ~13 ~70 ~38 ~13 ~70 wool 4
fill ~37 ~13 ~71 ~38 ~13 ~71 wool 4
fill ~37 ~13 ~72 ~38 ~13 ~72 wool 4
fill ~39 ~13 ~22 ~42 ~13 ~22 wool 0
fill ~41 ~13 ~68 ~42 ~13 ~68 wool 4
fill ~41 ~13 ~69 ~42 ~13 ~69 wool 4
fill ~41 ~13 ~70 ~42 ~13 ~70 wool 4
fill ~17 ~14 ~21 ~41 ~14 ~21 wool 0
fill ~17 ~14 ~22 ~24 ~14 ~22 wool 0
fill ~18 ~14 ~20 ~40 ~14 ~20 wool 0
fill ~18 ~14 ~23 ~18 ~17 ~23 wool 0
fill ~19 ~14 ~19 ~39 ~14 ~19 wool 0
fill ~19 ~14 ~63 ~23 ~14 ~63 wool 4
fill ~19 ~14 ~64 ~23 ~14 ~64 wool 4
fill ~19 ~14 ~65 ~23 ~14 ~65 wool 4
fill ~20 ~14 ~61 ~23 ~14 ~61 wool 4
fill ~20 ~14 ~62 ~23 ~14 ~62 wool 4
fill ~20 ~14 ~66 ~21 ~14 ~66 wool 4
fill ~21 ~14 ~18 ~37 ~14 ~18 wool 0
fill ~23 ~14 ~17 ~35 ~14 ~17 wool 0
fill ~35 ~14 ~22 ~42 ~14 ~22 wool 0
fill ~35 ~14 ~62 ~39 ~14 ~62 wool 4
fill ~35 ~14 ~63 ~39 ~14 ~63 wool 4
fill ~35 ~14 ~64 ~39 ~14 ~64 wool 4
fill ~35 ~14 ~65 ~39 ~14 ~65 wool 4
fill ~36 ~14 ~61 ~38 ~14 ~61 wool 4
fill ~37 ~14 ~66 ~38 ~14 ~66 wool 4
fill ~41 ~14 ~23 ~41 ~16 ~23 wool 0
fill ~17 ~15 ~22 ~41 ~15 ~22 wool 0
fill ~17 ~15 ~23 ~17 ~15 ~22 wool 0
fill ~18 ~15 ~21 ~40 ~15 ~21 wool 0
fill ~19 ~15 ~20 ~39 ~15 ~20 wool 0
fill ~19 ~15 ~23 ~24 ~15 ~23 wool 0
fill ~20 ~15 ~61 ~20 ~48 ~61 wool 15
fill ~20 ~15 ~62 ~20 ~15 ~65 wool 15
fill ~21 ~15 ~19 ~37 ~15 ~19 wool 0
fill ~21 ~15 ~60 ~22 ~15 ~60 wool 15
fill ~21 ~15 ~61 ~21 ~17 ~61 wool 4
fill ~21 ~15 ~62 ~21 ~17 ~62 wool 4
fill ~21 ~15 ~63 ~21 ~17 ~63 wool 4
fill ~21 ~15 ~64 ~21 ~17 ~64 wool 4
fill ~21 ~15 ~65 ~21 ~51 ~65 wool 15
fill ~22 ~15 ~61 ~22 ~15 ~64 wool 15
fill ~23 ~15 ~18 ~35 ~15 ~18 wool 0
fill ~25 ~15 ~17 ~33 ~15 ~17 wool 0
fill ~34 ~15 ~23 ~41 ~15 ~23 wool 0
fill ~36 ~15 ~60 ~38 ~15 ~60 wool 15
fill ~36 ~15 ~61 ~36 ~36 ~61 wool 15
fill ~36 ~15 ~62 ~36 ~17 ~62 wool 15
fill ~36 ~15 ~63 ~36 ~17 ~63 wool 15
fill ~36 ~15 ~64 ~36 ~18 ~64 wool 15
fill ~37 ~15 ~61 ~37 ~17 ~61 wool 4
fill ~37 ~15 ~62 ~38 ~15 ~62 wool 4
fill ~37 ~15 ~63 ~38 ~15 ~63 wool 4
fill ~37 ~15 ~64 ~38 ~15 ~64 wool 4
fill ~37 ~15 ~65 ~38 ~15 ~65 wool 15
fill ~38 ~15 ~61 ~38 ~16 ~61 wool 15
fill ~39 ~15 ~62 ~39 ~50 ~62 wool 15
fill ~39 ~15 ~63 ~39 ~50 ~63 wool 15
fill ~39 ~15 ~64 ~39 ~50 ~64 wool 15
fill ~18 ~16 ~22 ~40 ~16 ~22 wool 0
fill ~18 ~16 ~24 ~24 ~16 ~24 wool 0
fill ~19 ~16 ~21 ~39 ~16 ~21 wool 0
fill ~19 ~16 ~23 ~41 ~16 ~23 wool 0
fill ~19 ~16 ~62 ~19 ~49 ~62 wool 15
fill ~19 ~16 ~63 ~19 ~19 ~63 wool 15
fill ~19 ~16 ~64 ~19 ~51 ~64 wool 15
fill ~20 ~16 ~60 ~20 ~48 ~60 wool 15
fill ~20 ~16 ~62 ~20 ~18 ~62 wool 4
fill ~20 ~16 ~63 ~20 ~18 ~63 wool 4
fill ~20 ~16 ~64 ~20 ~18 ~64 wool 4
fill ~20 ~16 ~65 ~20 ~51 ~65 wool 15
fill ~21 ~16 ~20 ~37 ~16 ~20 wool 0
fill ~21 ~16 ~59 ~22 ~16 ~59 wool 15
fill ~21 ~16 ~60 ~21 ~17 ~60 wool 4
fill ~22 ~16 ~60 ~22 ~43 ~60 wool 15
fill ~22 ~16 ~61 ~22 ~16 ~63 wool 4
fill ~22 ~16 ~64 ~22 ~49 ~64 wool 15
fill ~22 ~16 ~65 ~22 ~50 ~65 wool 15
fill ~23 ~16 ~19 ~36 ~16 ~19 wool 0
fill ~23 ~16 ~61 ~23 ~37 ~61 wool 15
fill ~23 ~16 ~62 ~23 ~35 ~62 wool 15
fill ~23 ~16 ~63 ~23 ~36 ~63 wool 15
fill ~25 ~16 ~18 ~34 ~16 ~18 wool 0
fill ~34 ~16 ~24 ~41 ~16 ~24 wool 0
fill ~36 ~16 ~59 ~37 ~16 ~59 wool 15
fill ~36 ~16 ~60 ~36 ~36 ~60 wool 15
fill ~36 ~16 ~65 ~38 ~16 ~65 wool 15
fill ~37 ~16 ~60 ~37 ~17 ~60 wool 4
fill ~37 ~16 ~62 ~38 ~16 ~62 wool 4
fill ~37 ~16 ~63 ~38 ~16 ~63 wool 4
fill ~37 ~16 ~64 ~38 ~16 ~64 wool 4
fill ~38 ~16 ~60 ~38 ~48 ~60 wool 15
fill ~18 ~17 ~24 ~40 ~17 ~24 wool 0
fill ~18 ~17 ~25 ~24 ~17 ~25 wool 0
fill ~19 ~17 ~22 ~39 ~17 ~22 wool 0
fill ~19 ~17 ~23 ~40 ~17 ~23 wool 0
fill ~19 ~17 ~65 ~19 ~52 ~65 wool 15
fill ~21 ~17 ~21 ~37 ~17 ~21 wool 0
fill ~21 ~17 ~59 ~22 ~17 ~59 wool 15
fill ~22 ~17 ~20 ~36 ~17 ~20 wool 0
fill ~22 ~17 ~61 ~22 ~44 ~61 wool 15
fill ~22 ~17 ~62 ~22 ~44 ~62 wool 15
fill ~22 ~17 ~63 ~22 ~44 ~63 wool 15
fill ~23 ~17 ~64 ~23 ~36 ~64 wool 15
fill ~24 ~17 ~19 ~34 ~17 ~19 wool 0
fill ~34 ~17 ~25 ~40 ~17 ~25 wool 0
fill ~36 ~17 ~59 ~38 ~17 ~59 wool 15
fill ~36 ~17 ~65 ~39 ~17 ~65 wool 15
fill ~37 ~17 ~62 ~38 ~17 ~62 wool 4
fill ~37 ~17 ~63 ~38 ~17 ~63 wool 4
fill ~37 ~17 ~64 ~38 ~17 ~64 wool 4
setblock ~38 ~17 ~61 wool 4
fill ~39 ~17 ~61 ~39 ~49 ~61 wool 15
fill ~18 ~18 ~25 ~40 ~18 ~25 wool 0
fill ~19 ~18 ~24 ~40 ~18 ~24 wool 0
fill ~19 ~18 ~26 ~25 ~18 ~26 wool 0
fill ~20 ~18 ~23 ~39 ~18 ~23 wool 0
fill ~20 ~18 ~59 ~22 ~18 ~59 wool 15
fill ~21 ~18 ~22 ~37 ~18 ~22 wool 0
fill ~21 ~18 ~58 ~22 ~18 ~58 wool 15
fill ~21 ~18 ~60 ~21 ~47 ~60 wool 15
fill ~21 ~18 ~61 ~21 ~47 ~61 wool 15
fill ~21 ~18 ~62 ~21 ~46 ~62 wool 15
fill ~21 ~18 ~63 ~21 ~49 ~63 wool 15
fill ~21 ~18 ~64 ~21 ~50 ~64 wool 15
fill ~22 ~18 ~21 ~36 ~18 ~21 wool 0
fill ~23 ~18 ~65 ~23 ~36 ~65 wool 15
fill ~24 ~18 ~20 ~34 ~18 ~20 wool 0
fill ~27 ~18 ~19 ~32 ~18 ~19 wool 0
fill ~34 ~18 ~26 ~39 ~18 ~26 wool 0
fill ~35 ~18 ~62 ~35 ~38 ~62 wool 15
fill ~35 ~18 ~63 ~35 ~39 ~63 wool 15
fill ~36 ~18 ~58 ~37 ~18 ~58 wool 15
fill ~36 ~18 ~59 ~38 ~18 ~59 wool 15
fill ~36 ~18 ~62 ~38 ~18 ~62 wool 4
fill ~36 ~18 ~63 ~38 ~18 ~63 wool 4
fill ~36 ~18 ~65 ~39 ~18 ~65 wool 15
fill ~37 ~18 ~60 ~37 ~47 ~60 wool 15
fill ~37 ~18 ~61 ~39 ~18 ~61 wool 15
fill ~37 ~18 ~64 ~38 ~18 ~64 wool 4
fill ~19 ~19 ~25 ~39 ~19 ~25 wool 0
fill ~19 ~19 ~26 ~39 ~19 ~26 wool 0
fill ~19 ~19 ~27 ~25 ~19 ~27 wool 0
fill ~19 ~19 ~61 ~19 ~49 ~61 wool 15
fill ~20 ~19 ~24 ~39 ~19 ~24 wool 0
fill ~20 ~19 ~59 ~22 ~19 ~59 wool 15
fill ~20 ~19 ~62 ~20 ~48 ~62 wool 15
fill ~20 ~19 ~63 ~20 ~50 ~63 wool 15
fill ~20 ~19 ~64 ~20 ~51 ~64 wool 15
fill ~20 ~19 ~66 ~22 ~19 ~66 wool 15
fill ~21 ~19 ~23 ~37 ~19 ~23 wool 0
fill ~21 ~19 ~58 ~22 ~19 ~58 wool 15
fill ~22 ~19 ~22 ~36 ~19 ~22 wool 0
fill ~24 ~19 ~21 ~34 ~19 ~21 wool 0
fill ~26 ~19 ~20 ~32 ~19 ~20 wool 0
fill ~33 ~19 ~27 ~39 ~19 ~27 wool 0
fill ~35 ~19 ~64 ~35 ~39 ~64 wool 15
fill ~36 ~19 ~58 ~37 ~19 ~58 wool 15
fill ~36 ~19 ~59 ~38 ~19 ~59 wool 15
fill ~36 ~19 ~62 ~39 ~19 ~62 wool 15
fill ~36 ~19 ~63 ~37 ~19 ~63 wool 4
fill ~36 ~19 ~64 ~38 ~19 ~64 wool 4
fill ~36 ~19 ~65 ~36 ~49 ~65 wool 15
fill ~36 ~19 ~66 ~38 ~19 ~66 wool 15
fill ~37 ~19 ~61 ~39 ~19 ~61 wool 15
fill ~37 ~19 ~65 ~38 ~19 ~65 wool 4
fill ~38 ~19 ~63 ~38 ~49 ~63 wool 15
fill ~39 ~19 ~65 ~39 ~51 ~65 wool 15
fill ~40 ~19 ~64 ~40 ~51 ~64 wool 15
fill ~19 ~20 ~26 ~39 ~20 ~26 wool 0
fill ~19 ~20 ~27 ~39 ~20 ~27 wool 0
fill ~20 ~20 ~25 ~39 ~20 ~25 wool 0
fill ~20 ~20 ~28 ~25 ~20 ~28 wool 0
fill ~20 ~20 ~59 ~22 ~20 ~59 wool 15
fill ~20 ~20 ~66 ~23 ~20 ~66 wool 15
fill ~21 ~20 ~24 ~37 ~20 ~24 wool 0
fill ~21 ~20 ~58 ~22 ~20 ~58 wool 15
fill ~22 ~20 ~23 ~36 ~20 ~23 wool 0
fill ~23 ~20 ~60 ~23 ~38 ~60 wool 15
fill ~24 ~20 ~22 ~34 ~20 ~22 wool 0
fill ~26 ~20 ~21 ~33 ~20 ~21 wool 0
fill ~33 ~20 ~28 ~39 ~20 ~28 wool 0
fill ~35 ~20 ~65 ~35 ~39 ~65 wool 15
fill ~36 ~20 ~58 ~37 ~20 ~58 wool 15
fill ~36 ~20 ~59 ~38 ~20 ~59 wool 15
fill ~36 ~20 ~62 ~39 ~20 ~62 wool 15
fill ~36 ~20 ~63 ~40 ~20 ~63 wool 15
fill ~36 ~20 ~64 ~40 ~20 ~64 wool 15
fill ~36 ~20 ~66 ~39 ~20 ~66 wool 15
fill ~37 ~20 ~61 ~39 ~20 ~61 wool 15
fill ~37 ~20 ~65 ~39 ~20 ~65 wool 15
fill ~39 ~20 ~60 ~39 ~49 ~60 wool 15
fill ~19 ~21 ~27 ~39 ~21 ~27 wool 0
fill ~19 ~21 ~28 ~39 ~21 ~28 wool 0
fill ~19 ~21 ~63 ~19 ~50 ~63 wool 15
fill ~19 ~21 ~66 ~23 ~21 ~66 wool 15
fill ~20 ~21 ~26 ~39 ~21 ~26 wool 0
fill ~20 ~21 ~29 ~28 ~21 ~29 wool 0
fill ~20 ~21 ~59 ~23 ~21 ~59 wool 15
fill ~21 ~21 ~25 ~38 ~21 ~25 wool 0
fill ~21 ~21 ~58 ~22 ~21 ~58 wool 15
fill ~22 ~21 ~24 ~36 ~21 ~24 wool 0
fill ~22 ~21 ~57 ~22 ~39 ~57 wool 15
fill ~24 ~21 ~23 ~35 ~21 ~23 wool 0
fill ~25 ~21 ~22 ~33 ~21 ~22 wool 0
fill ~28 ~21 ~21 ~30 ~21 ~21 wool 0
fill ~31 ~21 ~29 ~38 ~21 ~29 wool 0
fill ~35 ~21 ~66 ~39 ~21 ~66 wool 15
fill ~36 ~21 ~57 ~37 ~21 ~57 wool 15
fill ~36 ~21 ~58 ~38 ~21 ~58 wool 15
fill ~36 ~21 ~59 ~38 ~21 ~59 wool 15
fill ~36 ~21 ~62 ~40 ~21 ~62 wool 15
fill ~36 ~21 ~63 ~40 ~21 ~63 wool 15
fill ~36 ~21 ~64 ~40 ~21 ~64 wool 15
fill ~37 ~21 ~61 ~39 ~21 ~61 wool 15
fill ~37 ~21 ~65 ~40 ~21 ~65 wool 15
fill ~18 ~22 ~63 ~18 ~50 ~63 wool 15
fill ~18 ~22 ~64 ~18 ~51 ~64 wool 15
fill ~19 ~22 ~28 ~39 ~22 ~28 wool 0
fill ~19 ~22 ~66 ~23 ~22 ~66 wool 15
fill ~20 ~22 ~26 ~38 ~22 ~26 wool 0
fill ~20 ~22 ~27 ~39 ~22 ~27 wool 0
fill ~20 ~22 ~29 ~39 ~22 ~29 wool 0
fill ~20 ~22 ~59 ~23 ~22 ~59 wool 15
fill ~20 ~22 ~67 ~21 ~22 ~67 wool 15
fill ~21 ~22 ~25 ~37 ~22 ~25 wool 0
fill ~21 ~22 ~30 ~37 ~22 ~30 wool 0
fill ~21 ~22 ~57 ~21 ~45 ~57 wool 15
fill ~21 ~22 ~58 ~23 ~22 ~58 wool 15
fill ~23 ~22 ~24 ~35 ~22 ~24 wool 0
fill ~24 ~22 ~63 ~24 ~36 ~63 wool 15
fill ~24 ~22 ~64 ~24 ~36 ~64 wool 15
fill ~25 ~22 ~23 ~33 ~22 ~23 wool 0
fill ~27 ~22 ~22 ~32 ~22 ~22 wool 0
fill ~35 ~22 ~61 ~35 ~37 ~61 wool 15
fill ~35 ~22 ~66 ~39 ~22 ~66 wool 15
fill ~36 ~22 ~57 ~37 ~22 ~57 wool 15
fill ~36 ~22 ~58 ~38 ~22 ~58 wool 15
fill ~36 ~22 ~59 ~38 ~22 ~59 wool 15
fill ~36 ~22 ~62 ~40 ~22 ~62 wool 15
fill ~36 ~22 ~63 ~40 ~22 ~63 wool 15
fill ~36 ~22 ~64 ~40 ~22 ~64 wool 15
fill ~37 ~22 ~61 ~39 ~22 ~61 wool 15
fill ~37 ~22 ~65 ~40 ~22 ~65 wool 15
fill ~37 ~22 ~67 ~38 ~22 ~67 wool 15
fill ~18 ~23 ~65 ~18 ~52 ~65 wool 15
fill ~19 ~23 ~60 ~19 ~49 ~60 wool 15
fill ~19 ~23 ~66 ~23 ~23 ~66 wool 15
fill ~20 ~23 ~27 ~38 ~23 ~27 wool 0
fill ~20 ~23 ~28 ~39 ~23 ~28 wool 0
fill ~20 ~23 ~29 ~39 ~23 ~29 wool 0
fill ~20 ~23 ~30 ~38 ~23 ~30 wool 0
fill ~20 ~23 ~58 ~23 ~23 ~58 wool 15
fill ~20 ~23 ~59 ~23 ~23 ~59 wool 15
fill ~20 ~23 ~67 ~22 ~23 ~67 wool 15
fill ~21 ~23 ~26 ~37 ~23 ~26 wool 0
fill ~21 ~23 ~31 ~37 ~23 ~31 wool 0
fill ~23 ~23 ~25 ~36 ~23 ~25 wool 0
fill ~23 ~23 ~57 ~23 ~37 ~57 wool 15
fill ~24 ~23 ~24 ~34 ~23 ~24 wool 0
fill ~24 ~23 ~65 ~24 ~36 ~65 wool 15
fill ~26 ~23 ~23 ~32 ~23 ~23 wool 0
fill ~34 ~23 ~32 ~34 ~35 ~32 wool 0
fill ~35 ~23 ~59 ~38 ~23 ~59 wool 15
fill ~35 ~23 ~60 ~35 ~37 ~60 wool 15
fill ~35 ~23 ~66 ~40 ~23 ~66 wool 15
fill ~36 ~23 ~57 ~37 ~23 ~57 wool 15
fill ~36 ~23 ~58 ~38 ~23 ~58 wool 15
fill ~36 ~23 ~62 ~40 ~23 ~62 wool 15
fill ~36 ~23 ~63 ~40 ~23 ~63 wool 15
fill ~36 ~23 ~64 ~40 ~23 ~64 wool 15
fill ~36 ~23 ~67 ~39 ~23 ~67 wool 15
fill ~37 ~23 ~61 ~40 ~23 ~61 wool 15
fill ~37 ~23 ~65 ~40 ~23 ~65 wool 15
fill ~18 ~24 ~62 ~18 ~49 ~62 wool 15
fill ~19 ~24 ~66 ~23 ~24 ~66 wool 15
fill ~19 ~24 ~67 ~23 ~24 ~67 wool 15
fill ~20 ~24 ~28 ~38 ~24 ~28 wool 0
fill ~20 ~24 ~29 ~38 ~24 ~29 wool 0
fill ~20 ~24 ~30 ~38 ~24 ~30 wool 0
fill ~20 ~24 ~31 ~38 ~24 ~31 wool 0
fill ~20 ~24 ~58 ~23 ~24 ~58 wool 15
fill ~20 ~24 ~59 ~23 ~24 ~59 wool 15
fill ~21 ~24 ~27 ~37 ~24 ~27 wool 0
fill ~21 ~24 ~56 ~22 ~24 ~56 wool 15
fill ~22 ~24 ~26 ~36 ~24 ~26 wool 0
fill ~22 ~24 ~32 ~31 ~24 ~32 wool 0
fill ~24 ~24 ~25 ~35 ~24 ~25 wool 0
fill ~25 ~24 ~24 ~33 ~24 ~24 wool 0
fill ~25 ~24 ~33 ~25 ~39 ~33 wool 0
fill ~27 ~24 ~23 ~31 ~24 ~23 wool 0
fill ~32 ~24 ~32 ~32 ~28 ~32 wool 15
fill ~33 ~24 ~32 ~33 ~36 ~32 wool 0
fill ~33 ~24 ~33 ~34 ~24 ~33 wool 15
fill ~35 ~24 ~32 ~37 ~24 ~32 wool 0
fill ~35 ~24 ~57 ~38 ~24 ~57 wool 15
fill ~35 ~24 ~58 ~38 ~24 ~58 wool 15
fill ~35 ~24 ~59 ~39 ~24 ~59 wool 15
fill ~35 ~24 ~66 ~40 ~24 ~66 wool 15
fill ~36 ~24 ~56 ~37 ~24 ~56 wool 15
fill ~36 ~24 ~62 ~40 ~24 ~62 wool 15
fill ~36 ~24 ~63 ~40 ~24 ~63 wool 15
fill ~36 ~24 ~64 ~40 ~24 ~64 wool 15
fill ~36 ~24 ~67 ~39 ~24 ~67 wool 15
fill ~37 ~24 ~61 ~40 ~24 ~61 wool 15
fill ~37 ~24 ~65 ~40 ~24 ~65 wool 15
fill ~18 ~25 ~61 ~18 ~50 ~61 wool 15
fill ~18 ~25 ~66 ~24 ~25 ~66 wool 15
fill ~19 ~25 ~59 ~23 ~25 ~59 wool 15
fill ~19 ~25 ~67 ~23 ~25 ~67 wool 15
fill ~20 ~25 ~29 ~38 ~25 ~29 wool 0
fill ~20 ~25 ~30 ~38 ~25 ~30 wool 0
fill ~20 ~25 ~31 ~38 ~25 ~31 wool 0
fill ~20 ~25 ~56 ~23 ~25 ~56 wool 15
fill ~20 ~25 ~57 ~20 ~47 ~57 wool 15
fill ~20 ~25 ~58 ~23 ~25 ~58 wool 15
fill ~21 ~25 ~28 ~38 ~25 ~28 wool 0
fill ~21 ~25 ~32 ~25 ~25 ~32 wool 0
fill ~22 ~25 ~27 ~37 ~25 ~27 wool 0
fill ~22 ~25 ~33 ~26 ~25 ~33 wool 0
fill ~23 ~25 ~26 ~35 ~25 ~26 wool 0
fill ~25 ~25 ~25 ~34 ~25 ~25 wool 0
fill ~25 ~25 ~34 ~26 ~25 ~34 wool 0
fill ~26 ~25 ~24 ~32 ~25 ~24 wool 0
fill ~26 ~25 ~32 ~32 ~25 ~32 wool 15
fill ~27 ~25 ~33 ~33 ~25 ~33 wool 15
fill ~27 ~25 ~34 ~34 ~25 ~34 wool 15
fill ~34 ~25 ~33 ~36 ~25 ~33 wool 0
fill ~34 ~25 ~64 ~34 ~40 ~64 wool 15
fill ~34 ~25 ~65 ~34 ~40 ~65 wool 15
fill ~35 ~25 ~32 ~38 ~25 ~32 wool 0
fill ~35 ~25 ~57 ~38 ~25 ~57 wool 15
fill ~35 ~25 ~58 ~39 ~25 ~58 wool 15
fill ~35 ~25 ~59 ~39 ~25 ~59 wool 15
fill ~35 ~25 ~66 ~40 ~25 ~66 wool 15
fill ~35 ~25 ~67 ~39 ~25 ~67 wool 15
fill ~36 ~25 ~56 ~38 ~25 ~56 wool 15
fill ~36 ~25 ~62 ~40 ~25 ~62 wool 15
fill ~36 ~25 ~63 ~40 ~25 ~63 wool 15
fill ~36 ~25 ~64 ~40 ~25 ~64 wool 15
fill ~37 ~25 ~61 ~40 ~25 ~61 wool 15
fill ~37 ~25 ~65 ~40 ~25 ~65 wool 15
fill ~40 ~25 ~60 ~40 ~50 ~60 wool 15
fill ~18 ~26 ~60 ~18 ~50 ~60 wool 15
fill ~18 ~26 ~66 ~24 ~26 ~66 wool 15
fill ~19 ~26 ~58 ~23 ~26 ~58 wool 15
fill ~19 ~26 ~59 ~23 ~26 ~59 wool 15
fill ~19 ~26 ~67 ~24 ~26 ~67 wool 15
fill ~20 ~26 ~30 ~38 ~26 ~30 wool 0
fill ~20 ~26 ~31 ~28 ~26 ~31 wool 0
fill ~20 ~26 ~32 ~26 ~26 ~32 wool 0
fill ~20 ~26 ~56 ~23 ~26 ~56 wool 15
fill ~20 ~26 ~68 ~22 ~26 ~68 wool 15
fill ~21 ~26 ~28 ~37 ~26 ~28 wool 0
fill ~21 ~26 ~29 ~38 ~26 ~29 wool 0
fill ~21 ~26 ~33 ~26 ~26 ~33 wool 0
fill ~22 ~26 ~34 ~26 ~26 ~34 wool 0
fill ~23 ~26 ~27 ~36 ~26 ~27 wool 0
fill ~24 ~26 ~26 ~34 ~26 ~26 wool 0
fill ~24 ~26 ~61 ~24 ~36 ~61 wool 15
fill ~24 ~26 ~62 ~24 ~36 ~62 wool 15
fill ~25 ~26 ~35 ~26 ~26 ~35 wool 0
fill ~26 ~26 ~25 ~33 ~26 ~25 wool 0
fill ~27 ~26 ~32 ~32 ~26 ~32 wool 15
fill ~27 ~26 ~33 ~33 ~26 ~33 wool 15
fill ~27 ~26 ~34 ~36 ~26 ~34 wool 15
fill ~27 ~26 ~35 ~34 ~26 ~35 wool 15
fill ~28 ~26 ~24 ~30 ~26 ~24 wool 0
fill ~29 ~26 ~31 ~31 ~26 ~31 wool 15
fill ~32 ~26 ~31 ~38 ~26 ~31 wool 0
fill ~34 ~26 ~33 ~38 ~26 ~33 wool 0
fill ~34 ~26 ~66 ~40 ~26 ~66 wool 15
fill ~35 ~26 ~32 ~38 ~26 ~32 wool 0
fill ~35 ~26 ~56 ~38 ~26 ~56 wool 15
fill ~35 ~26 ~57 ~38 ~26 ~57 wool 15
fill ~35 ~26 ~58 ~39 ~26 ~58 wool 15
fill ~35 ~26 ~59 ~39 ~26 ~59 wool 15
fill ~35 ~26 ~67 ~40 ~26 ~67 wool 15
fill ~36 ~26 ~62 ~40 ~26 ~62 wool 15
fill ~36 ~26 ~63 ~40 ~26 ~63 wool 15
fill ~36 ~26 ~64 ~40 ~26 ~64 wool 15
fill ~36 ~26 ~68 ~39 ~26 ~68 wool 15
fill ~37 ~26 ~61 ~40 ~26 ~61 wool 15
fill ~37 ~26 ~65 ~40 ~26 ~65 wool 15
fill ~18 ~27 ~66 ~24 ~27 ~66 wool 15
fill ~18 ~27 ~67 ~24 ~27 ~67 wool 15
fill ~19 ~27 ~58 ~24 ~27 ~58 wool 15
fill ~19 ~27 ~59 ~24 ~27 ~59 wool 15
fill ~19 ~27 ~68 ~23 ~27 ~68 wool 15
fill ~20 ~27 ~31 ~28 ~27 ~31 wool 0
fill ~20 ~27 ~32 ~26 ~27 ~32 wool 0
fill ~20 ~27 ~55 ~23 ~27 ~55 wool 15
fill ~20 ~27 ~56 ~23 ~27 ~56 wool 15
fill ~21 ~27 ~29 ~37 ~27 ~29 wool 0
fill ~21 ~27 ~30 ~38 ~27 ~30 wool 0
fill ~21 ~27 ~33 ~26 ~27 ~33 wool 0
fill ~21 ~27 ~34 ~26 ~27 ~34 wool 0
fill ~22 ~27 ~28 ~36 ~27 ~28 wool 0
fill ~22 ~27 ~35 ~26 ~27 ~35 wool 0
fill ~24 ~27 ~27 ~35 ~27 ~27 wool 0
fill ~24 ~27 ~36 ~26 ~27 ~36 wool 0
fill ~24 ~27 ~57 ~24 ~37 ~57 wool 15
fill ~24 ~27 ~60 ~24 ~37 ~60 wool 15
fill ~25 ~27 ~26 ~33 ~27 ~26 wool 0
fill ~27 ~27 ~25 ~32 ~27 ~25 wool 0
fill ~27 ~27 ~32 ~32 ~27 ~32 wool 15
fill ~27 ~27 ~33 ~33 ~27 ~33 wool 15
fill ~27 ~27 ~34 ~34 ~27 ~34 wool 15
fill ~27 ~27 ~35 ~36 ~27 ~35 wool 15
fill ~27 ~27 ~36 ~34 ~27 ~36 wool 15
fill ~29 ~27 ~31 ~31 ~27 ~31 wool 15
fill ~32 ~27 ~31 ~38 ~27 ~31 wool 0
fill ~34 ~27 ~33 ~38 ~27 ~33 wool 0
fill ~34 ~27 ~63 ~34 ~40 ~63 wool 15
fill ~34 ~27 ~66 ~40 ~27 ~66 wool 15
fill ~34 ~27 ~67 ~40 ~27 ~67 wool 15
fill ~35 ~27 ~32 ~38 ~27 ~32 wool 0
fill ~35 ~27 ~34 ~37 ~27 ~34 wool 0
fill ~35 ~27 ~56 ~38 ~27 ~56 wool 15
fill ~35 ~27 ~57 ~39 ~27 ~57 wool 15
fill ~35 ~27 ~58 ~39 ~27 ~58 wool 15
fill ~35 ~27 ~59 ~40 ~27 ~59 wool 15
fill ~35 ~27 ~68 ~39 ~27 ~68 wool 15
fill ~36 ~27 ~55 ~38 ~27 ~55 wool 15
fill ~36 ~27 ~62 ~40 ~27 ~62 wool 15
fill ~36 ~27 ~63 ~40 ~27 ~63 wool 15
fill ~36 ~27 ~64 ~41 ~27 ~64 wool 15
fill ~37 ~27 ~61 ~40 ~27 ~61 wool 15
fill ~37 ~27 ~65 ~41 ~27 ~65 wool 15
fill ~18 ~28 ~59 ~24 ~28 ~59 wool 15
fill ~18 ~28 ~66 ~24 ~28 ~66 wool 15
fill ~18 ~28 ~67 ~24 ~28 ~67 wool 15
fill ~19 ~28 ~56 ~24 ~28 ~56 wool 15
fill ~19 ~28 ~57 ~19 ~48 ~57 wool 15
fill ~19 ~28 ~58 ~24 ~28 ~58 wool 15
fill ~19 ~28 ~68 ~24 ~28 ~68 wool 15
fill ~20 ~28 ~31 ~30 ~28 ~31 wool 0
fill ~20 ~28 ~32 ~26 ~28 ~32 wool 0
fill ~20 ~28 ~55 ~23 ~28 ~55 wool 15
fill ~21 ~28 ~30 ~37 ~28 ~30 wool 0
fill ~21 ~28 ~33 ~26 ~28 ~33 wool 0
fill ~21 ~28 ~34 ~26 ~28 ~34 wool 0
fill ~21 ~28 ~35 ~26 ~28 ~35 wool 0
fill ~22 ~28 ~29 ~36 ~28 ~29 wool 0
fill ~22 ~28 ~36 ~26 ~28 ~36 wool 0
fill ~23 ~28 ~28 ~35 ~28 ~28 wool 0
fill ~24 ~28 ~27 ~34 ~28 ~27 wool 0
fill ~24 ~28 ~37 ~25 ~28 ~37 wool 0
fill ~26 ~28 ~26 ~32 ~28 ~26 wool 0
fill ~26 ~28 ~37 ~34 ~28 ~37 wool 15
fill ~27 ~28 ~32 ~32 ~28 ~32 wool 15
fill ~27 ~28 ~33 ~32 ~28 ~33 wool 15
fill ~27 ~28 ~34 ~32 ~28 ~34 wool 15
fill ~27 ~28 ~35 ~33 ~28 ~35 wool 15
fill ~27 ~28 ~36 ~36 ~28 ~36 wool 15
fill ~29 ~28 ~38 ~29 ~34 ~38 wool 15
setblock ~31 ~28 ~31 wool 15
fill ~32 ~28 ~31 ~38 ~28 ~31 wool 0
fill ~33 ~28 ~33 ~38 ~28 ~33 wool 0
fill ~33 ~28 ~34 ~37 ~28 ~34 wool 0
fill ~34 ~28 ~35 ~37 ~28 ~35 wool 0
fill ~34 ~28 ~57 ~39 ~28 ~57 wool 15
fill ~34 ~28 ~58 ~40 ~28 ~58 wool 15
fill ~34 ~28 ~61 ~34 ~38 ~61 wool 15
fill ~34 ~28 ~62 ~34 ~39 ~62 wool 15
fill ~34 ~28 ~66 ~40 ~28 ~66 wool 15
fill ~34 ~28 ~67 ~40 ~28 ~67 wool 15
fill ~35 ~28 ~32 ~38 ~28 ~32 wool 0
fill ~35 ~28 ~55 ~39 ~28 ~55 wool 15
fill ~35 ~28 ~56 ~39 ~28 ~56 wool 15
fill ~35 ~28 ~59 ~40 ~28 ~59 wool 15
fill ~35 ~28 ~68 ~39 ~28 ~68 wool 15
fill ~36 ~28 ~62 ~40 ~28 ~62 wool 15
fill ~36 ~28 ~63 ~41 ~28 ~63 wool 15
fill ~36 ~28 ~64 ~41 ~28 ~64 wool 15
fill ~37 ~28 ~61 ~40 ~28 ~61 wool 15
fill ~37 ~28 ~65 ~41 ~28 ~65 wool 15
fill ~17 ~29 ~65 ~17 ~42 ~65 wool 15
fill ~18 ~29 ~58 ~24 ~29 ~58 wool 15
fill ~18 ~29 ~59 ~24 ~29 ~59 wool 15
fill ~18 ~29 ~66 ~24 ~29 ~66 wool 15
fill ~18 ~29 ~67 ~24 ~29 ~67 wool 15
fill ~19 ~29 ~55 ~23 ~29 ~55 wool 15
fill ~19 ~29 ~56 ~24 ~29 ~56 wool 15
fill ~19 ~29 ~68 ~24 ~29 ~68 wool 15
fill ~20 ~29 ~31 ~38 ~29 ~31 wool 0
fill ~20 ~29 ~32 ~38 ~29 ~32 wool 0
fill ~20 ~29 ~33 ~27 ~29 ~33 wool 0
fill ~20 ~29 ~54 ~22 ~29 ~54 wool 15
fill ~21 ~29 ~34 ~26 ~29 ~34 wool 0
fill ~21 ~29 ~35 ~26 ~29 ~35 wool 0
fill ~21 ~29 ~69 ~23 ~29 ~69 wool 15
fill ~22 ~29 ~30 ~36 ~29 ~30 wool 0
fill ~22 ~29 ~36 ~25 ~29 ~36 wool 0
fill ~23 ~29 ~29 ~36 ~29 ~29 wool 0
fill ~23 ~29 ~37 ~25 ~29 ~37 wool 0
fill ~24 ~29 ~28 ~34 ~29 ~28 wool 0
fill ~24 ~29 ~38 ~24 ~45 ~38 wool 0
fill ~25 ~29 ~27 ~33 ~29 ~27 wool 0
fill ~25 ~29 ~38 ~34 ~29 ~38 wool 15
fill ~26 ~29 ~36 ~33 ~29 ~36 wool 15
fill ~26 ~29 ~37 ~36 ~29 ~37 wool 15
fill ~27 ~29 ~26 ~31 ~29 ~26 wool 0
fill ~27 ~29 ~34 ~31 ~29 ~34 wool 15
fill ~27 ~29 ~35 ~32 ~29 ~35 wool 15
fill ~28 ~29 ~33 ~31 ~29 ~33 wool 15
fill ~28 ~29 ~39 ~30 ~29 ~39 wool 15
fill ~32 ~29 ~33 ~38 ~29 ~33 wool 0
fill ~32 ~29 ~34 ~37 ~29 ~34 wool 0
fill ~33 ~29 ~35 ~37 ~29 ~35 wool 0
fill ~34 ~29 ~36 ~37 ~29 ~36 wool 0
fill ~34 ~29 ~56 ~39 ~29 ~56 wool 15
fill ~34 ~29 ~57 ~39 ~29 ~57 wool 15
fill ~34 ~29 ~58 ~40 ~29 ~58 wool 15
fill ~34 ~29 ~59 ~40 ~29 ~59 wool 15
fill ~34 ~29 ~60 ~34 ~38 ~60 wool 15
fill ~34 ~29 ~66 ~41 ~29 ~66 wool 15
fill ~34 ~29 ~67 ~40 ~29 ~67 wool 15
fill ~34 ~29 ~68 ~40 ~29 ~68 wool 15
fill ~35 ~29 ~55 ~39 ~29 ~55 wool 15
fill ~36 ~29 ~54 ~39 ~29 ~54 wool 15
fill ~36 ~29 ~62 ~41 ~29 ~62 wool 15
fill ~36 ~29 ~63 ~41 ~29 ~63 wool 15
fill ~36 ~29 ~64 ~41 ~29 ~64 wool 15
fill ~36 ~29 ~69 ~37 ~29 ~69 wool 15
fill ~37 ~29 ~61 ~40 ~29 ~61 wool 15
fill ~37 ~29 ~65 ~41 ~29 ~65 wool 15
fill ~17 ~30 ~64 ~17 ~41 ~64 wool 15
fill ~18 ~30 ~58 ~25 ~30 ~58 wool 15
fill ~18 ~30 ~59 ~25 ~30 ~59 wool 15
fill ~18 ~30 ~66 ~25 ~30 ~66 wool 15
fill ~18 ~30 ~67 ~25 ~30 ~67 wool 15
fill ~18 ~30 ~68 ~24 ~30 ~68 wool 15
fill ~19 ~30 ~54 ~23 ~30 ~54 wool 15
fill ~19 ~30 ~55 ~24 ~30 ~55 wool 15
fill ~19 ~30 ~56 ~24 ~30 ~56 wool 15
fill ~20 ~30 ~32 ~38 ~30 ~32 wool 0
fill ~20 ~30 ~33 ~38 ~30 ~33 wool 0
fill ~20 ~30 ~34 ~27 ~30 ~34 wool 0
fill ~20 ~30 ~69 ~23 ~30 ~69 wool 15
fill ~21 ~30 ~35 ~26 ~30 ~35 wool 0
fill ~21 ~30 ~36 ~25 ~30 ~36 wool 0
fill ~22 ~30 ~31 ~37 ~30 ~31 wool 0
fill ~22 ~30 ~37 ~25 ~30 ~37 wool 0
fill ~23 ~30 ~30 ~36 ~30 ~30 wool 0
fill ~23 ~30 ~38 ~23 ~44 ~38 wool 0
fill ~24 ~30 ~29 ~35 ~30 ~29 wool 0
fill ~24 ~30 ~39 ~24 ~47 ~39 wool 0
fill ~25 ~30 ~28 ~33 ~30 ~28 wool 0
fill ~25 ~30 ~38 ~25 ~44 ~38 wool 0
fill ~25 ~30 ~39 ~35 ~30 ~39 wool 15
fill ~25 ~30 ~57 ~25 ~38 ~57 wool 15
fill ~25 ~30 ~60 ~25 ~38 ~60 wool 15
fill ~25 ~30 ~61 ~25 ~37 ~61 wool 15
fill ~25 ~30 ~62 ~25 ~37 ~62 wool 15
fill ~25 ~30 ~63 ~25 ~36 ~63 wool 15
fill ~25 ~30 ~64 ~25 ~36 ~64 wool 15
fill ~25 ~30 ~65 ~25 ~39 ~65 wool 15
fill ~26 ~30 ~36 ~32 ~30 ~36 wool 15
fill ~26 ~30 ~37 ~34 ~30 ~37 wool 15
fill ~26 ~30 ~38 ~36 ~30 ~38 wool 15
fill ~27 ~30 ~27 ~32 ~30 ~27 wool 0
fill ~27 ~30 ~35 ~31 ~30 ~35 wool 15
fill ~27 ~30 ~40 ~32 ~30 ~40 wool 15
fill ~28 ~30 ~34 ~30 ~30 ~34 wool 15
fill ~31 ~30 ~34 ~38 ~30 ~34 wool 0
fill ~32 ~30 ~35 ~37 ~30 ~35 wool 0
fill ~33 ~30 ~36 ~37 ~30 ~36 wool 0
fill ~34 ~30 ~56 ~39 ~30 ~56 wool 15
fill ~34 ~30 ~57 ~40 ~30 ~57 wool 15
fill ~34 ~30 ~58 ~40 ~30 ~58 wool 15
fill ~34 ~30 ~59 ~40 ~30 ~59 wool 15
fill ~34 ~30 ~66 ~41 ~30 ~66 wool 15
fill ~34 ~30 ~67 ~40 ~30 ~67 wool 15
fill ~34 ~30 ~68 ~40 ~30 ~68 wool 15
fill ~35 ~30 ~37 ~37 ~30 ~37 wool 0
fill ~35 ~30 ~54 ~39 ~30 ~54 wool 15
fill ~35 ~30 ~55 ~39 ~30 ~55 wool 15
fill ~35 ~30 ~69 ~39 ~30 ~69 wool 15
fill ~36 ~30 ~62 ~41 ~30 ~62 wool 15
fill ~36 ~30 ~63 ~41 ~30 ~63 wool 15
fill ~36 ~30 ~64 ~41 ~30 ~64 wool 15
fill ~37 ~30 ~61 ~41 ~30 ~61 wool 15
fill ~37 ~30 ~65 ~41 ~30 ~65 wool 15
fill ~17 ~31 ~63 ~17 ~40 ~63 wool 15
fill ~17 ~31 ~66 ~25 ~31 ~66 wool 15
fill ~18 ~31 ~57 ~18 ~49 ~57 wool 15
fill ~18 ~31 ~58 ~25 ~31 ~58 wool 15
fill ~18 ~31 ~59 ~25 ~31 ~59 wool 15
fill ~18 ~31 ~67 ~25 ~31 ~67 wool 15
fill ~18 ~31 ~68 ~25 ~31 ~68 wool 15
fill ~19 ~31 ~54 ~24 ~31 ~54 wool 15
fill ~19 ~31 ~55 ~24 ~31 ~55 wool 15
fill ~19 ~31 ~56 ~25 ~31 ~56 wool 15
fill ~19 ~31 ~69 ~24 ~31 ~69 wool 15
fill ~20 ~31 ~33 ~39 ~31 ~33 wool 0
fill ~20 ~31 ~34 ~39 ~31 ~34 wool 0
fill ~21 ~31 ~32 ~37 ~31 ~32 wool 0
fill ~21 ~31 ~35 ~26 ~31 ~35 wool 0
fill ~21 ~31 ~36 ~25 ~31 ~36 wool 0
fill ~21 ~31 ~37 ~25 ~31 ~37 wool 0
fill ~21 ~31 ~38 ~25 ~31 ~38 wool 0
fill ~23 ~31 ~30 ~35 ~31 ~30 wool 0
fill ~23 ~31 ~31 ~36 ~31 ~31 wool 0
fill ~23 ~31 ~39 ~23 ~46 ~39 wool 0
fill ~23 ~31 ~40 ~24 ~31 ~40 wool 0
fill ~25 ~31 ~29 ~34 ~31 ~29 wool 0
fill ~25 ~31 ~39 ~25 ~33 ~39 wool 0
fill ~25 ~31 ~40 ~35 ~31 ~40 wool 15
fill ~25 ~31 ~41 ~33 ~31 ~41 wool 15
fill ~26 ~31 ~28 ~32 ~31 ~28 wool 0
fill ~26 ~31 ~36 ~31 ~31 ~36 wool 15
fill ~26 ~31 ~37 ~33 ~31 ~37 wool 15
fill ~26 ~31 ~38 ~37 ~31 ~38 wool 15
fill ~26 ~31 ~39 ~36 ~31 ~39 wool 15
fill ~27 ~31 ~35 ~30 ~31 ~35 wool 15
fill ~27 ~31 ~42 ~31 ~31 ~42 wool 15
fill ~28 ~31 ~27 ~31 ~31 ~27 wool 0
fill ~31 ~31 ~35 ~38 ~31 ~35 wool 0
fill ~32 ~31 ~36 ~37 ~31 ~36 wool 0
fill ~33 ~31 ~56 ~40 ~31 ~56 wool 15
fill ~33 ~31 ~57 ~40 ~31 ~57 wool 15
fill ~33 ~31 ~58 ~41 ~31 ~58 wool 15
fill ~33 ~31 ~59 ~41 ~31 ~59 wool 15
fill ~33 ~31 ~60 ~33 ~39 ~60 wool 15
fill ~33 ~31 ~61 ~33 ~39 ~61 wool 15
fill ~33 ~31 ~62 ~33 ~40 ~62 wool 15
fill ~33 ~31 ~63 ~33 ~40 ~63 wool 15
fill ~33 ~31 ~64 ~33 ~41 ~64 wool 15
fill ~33 ~31 ~65 ~33 ~41 ~65 wool 15
fill ~33 ~31 ~66 ~41 ~31 ~66 wool 15
fill ~33 ~31 ~67 ~41 ~31 ~67 wool 15
fill ~34 ~31 ~37 ~38 ~31 ~37 wool 0
fill ~34 ~31 ~55 ~40 ~31 ~55 wool 15
fill ~34 ~31 ~68 ~40 ~31 ~68 wool 15
fill ~34 ~31 ~69 ~39 ~31 ~69 wool 15
fill ~35 ~31 ~54 ~39 ~31 ~54 wool 15
fill ~36 ~31 ~62 ~41 ~31 ~62 wool 15
fill ~36 ~31 ~63 ~41 ~31 ~63 wool 15
fill ~36 ~31 ~64 ~41 ~31 ~64 wool 15
fill ~37 ~31 ~61 ~41 ~31 ~61 wool 15
fill ~37 ~31 ~65 ~41 ~31 ~65 wool 15
fill ~41 ~31 ~60 ~41 ~39 ~60 wool 15
fill ~17 ~32 ~62 ~17 ~39 ~62 wool 15
fill ~17 ~32 ~66 ~25 ~32 ~66 wool 15
fill ~18 ~32 ~55 ~25 ~32 ~55 wool 15
fill ~18 ~32 ~56 ~25 ~32 ~56 wool 15
fill ~18 ~32 ~58 ~25 ~32 ~58 wool 15
fill ~18 ~32 ~59 ~25 ~32 ~59 wool 15
fill ~18 ~32 ~67 ~25 ~32 ~67 wool 15
fill ~18 ~32 ~68 ~25 ~32 ~68 wool 15
fill ~19 ~32 ~53 ~22 ~32 ~53 wool 15
fill ~19 ~32 ~54 ~24 ~32 ~54 wool 15
fill ~19 ~32 ~69 ~25 ~32 ~69 wool 15
fill ~20 ~32 ~33 ~38 ~32 ~33 wool 0
fill ~20 ~32 ~34 ~39 ~32 ~34 wool 0
fill ~20 ~32 ~35 ~26 ~32 ~35 wool 0
fill ~20 ~32 ~36 ~26 ~32 ~36 wool 0
fill ~20 ~32 ~37 ~25 ~32 ~37 wool 0
fill ~20 ~32 ~38 ~25 ~32 ~38 wool 0
fill ~21 ~32 ~39 ~25 ~32 ~39 wool 0
fill ~22 ~32 ~32 ~36 ~32 ~32 wool 0
fill ~22 ~32 ~40 ~24 ~32 ~40 wool 0
fill ~22 ~32 ~70 ~24 ~32 ~70 wool 15
fill ~23 ~32 ~31 ~35 ~32 ~31 wool 0
fill ~23 ~32 ~41 ~23 ~34 ~41 wool 0
fill ~24 ~32 ~30 ~34 ~32 ~30 wool 0
fill ~24 ~32 ~41 ~35 ~32 ~41 wool 15
fill ~24 ~32 ~42 ~34 ~32 ~42 wool 15
fill ~25 ~32 ~29 ~33 ~32 ~29 wool 0
fill ~25 ~32 ~40 ~36 ~32 ~40 wool 15
fill ~26 ~32 ~37 ~32 ~32 ~37 wool 15
fill ~26 ~32 ~38 ~37 ~32 ~38 wool 15
fill ~26 ~32 ~39 ~37 ~32 ~39 wool 15
fill ~26 ~32 ~43 ~32 ~32 ~43 wool 15
fill ~26 ~32 ~60 ~26 ~38 ~60 wool 15
fill ~26 ~32 ~61 ~26 ~38 ~61 wool 15
fill ~27 ~32 ~28 ~31 ~32 ~28 wool 0
fill ~27 ~32 ~35 ~30 ~32 ~35 wool 15
fill ~27 ~32 ~36 ~31 ~32 ~36 wool 15
fill ~31 ~32 ~35 ~38 ~32 ~35 wool 0
setblock ~32 ~32 ~36 stone 0
fill ~33 ~32 ~36 ~38 ~32 ~36 wool 0
fill ~33 ~32 ~37 ~38 ~32 ~37 wool 0
fill ~33 ~32 ~56 ~40 ~32 ~56 wool 15
fill ~33 ~32 ~57 ~40 ~32 ~57 wool 15
fill ~33 ~32 ~58 ~41 ~32 ~58 wool 15
fill ~33 ~32 ~59 ~41 ~32 ~59 wool 15
fill ~33 ~32 ~66 ~41 ~32 ~66 wool 15
fill ~33 ~32 ~67 ~41 ~32 ~67 wool 15
fill ~33 ~32 ~68 ~40 ~32 ~68 wool 15
fill ~34 ~32 ~55 ~40 ~32 ~55 wool 15
fill ~34 ~32 ~69 ~39 ~32 ~69 wool 15
fill ~35 ~32 ~54 ~40 ~32 ~54 wool 15
fill ~35 ~32 ~70 ~36 ~32 ~70 wool 15
fill ~36 ~32 ~53 ~39 ~32 ~53 wool 15
fill ~36 ~32 ~62 ~41 ~32 ~62 wool 15
fill ~36 ~32 ~63 ~41 ~32 ~63 wool 15
fill ~36 ~32 ~64 ~41 ~32 ~64 wool 15
fill ~37 ~32 ~61 ~41 ~32 ~61 wool 15
fill ~37 ~32 ~65 ~41 ~32 ~65 wool 15
fill ~38 ~32 ~38 ~38 ~42 ~38 wool 0
fill ~17 ~33 ~60 ~17 ~37 ~60 wool 15
fill ~17 ~33 ~61 ~17 ~38 ~61 wool 15
fill ~17 ~33 ~66 ~25 ~33 ~66 wool 15
fill ~17 ~33 ~67 ~25 ~33 ~67 wool 15
fill ~18 ~33 ~54 ~26 ~33 ~54 wool 15
fill ~18 ~33 ~55 ~27 ~33 ~55 wool 15
fill ~18 ~33 ~56 ~27 ~33 ~56 wool 15
fill ~18 ~33 ~58 ~26 ~33 ~58 wool 15
fill ~18 ~33 ~59 ~26 ~33 ~59 wool 15
fill ~18 ~33 ~68 ~25 ~33 ~68 wool 15
fill ~18 ~33 ~69 ~25 ~33 ~69 wool 15
fill ~19 ~33 ~35 ~28 ~33 ~35 wool 0
fill ~19 ~33 ~36 ~26 ~33 ~36 wool 0
fill ~19 ~33 ~37 ~26 ~33 ~37 wool 0
fill ~19 ~33 ~38 ~25 ~33 ~38 wool 0
fill ~19 ~33 ~53 ~26 ~33 ~53 wool 15
fill ~20 ~33 ~34 ~38 ~33 ~34 wool 0
fill ~20 ~33 ~39 ~25 ~33 ~39 wool 0
fill ~20 ~33 ~70 ~24 ~33 ~70 wool 15
fill ~21 ~33 ~40 ~24 ~33 ~40 wool 0
fill ~22 ~33 ~33 ~37 ~33 ~33 wool 0
fill ~22 ~33 ~41 ~22 ~48 ~41 wool 0
fill ~22 ~33 ~42 ~22 ~49 ~42 wool 0
fill ~23 ~33 ~32 ~35 ~33 ~32 wool 0
fill ~23 ~33 ~42 ~36 ~33 ~42 wool 15
fill ~23 ~33 ~43 ~36 ~33 ~43 wool 15
fill ~23 ~33 ~44 ~35 ~33 ~44 wool 15
fill ~23 ~33 ~52 ~25 ~33 ~52 wool 15
fill ~24 ~33 ~31 ~34 ~33 ~31 wool 0
fill ~24 ~33 ~41 ~36 ~33 ~41 wool 15
fill ~24 ~33 ~45 ~35 ~33 ~45 wool 15
fill ~25 ~33 ~30 ~33 ~33 ~30 wool 0
fill ~25 ~33 ~40 ~36 ~33 ~40 wool 15
fill ~25 ~33 ~46 ~34 ~33 ~46 wool 15
fill ~26 ~33 ~29 ~32 ~33 ~29 wool 0
fill ~26 ~33 ~38 ~33 ~33 ~38 wool 15
fill ~26 ~33 ~39 ~36 ~33 ~39 wool 15
fill ~26 ~33 ~47 ~27 ~33 ~47 wool 15
fill ~26 ~33 ~57 ~27 ~33 ~57 wool 15
fill ~26 ~33 ~62 ~26 ~38 ~62 wool 15
fill ~26 ~33 ~63 ~26 ~38 ~63 wool 15
fill ~27 ~33 ~36 ~27 ~27 ~36 wool 15
fill ~27 ~33 ~37 ~31 ~33 ~37 wool 15
fill ~28 ~33 ~36 ~30 ~33 ~36 stone 0
setblock ~29 ~33 ~35 stone 0
fill ~30 ~33 ~35 ~39 ~33 ~35 wool 0
fill ~31 ~33 ~36 ~39 ~33 ~36 wool 0
fill ~31 ~33 ~47 ~32 ~33 ~47 wool 15
fill ~31 ~33 ~55 ~40 ~33 ~55 wool 15
fill ~31 ~33 ~56 ~40 ~33 ~56 wool 15
fill ~32 ~33 ~37 ~39 ~33 ~37 wool 0
fill ~32 ~33 ~53 ~39 ~33 ~53 wool 15
fill ~32 ~33 ~54 ~40 ~33 ~54 wool 15
fill ~32 ~33 ~57 ~41 ~33 ~57 wool 15
fill ~32 ~33 ~58 ~41 ~33 ~58 wool 15
fill ~32 ~33 ~61 ~32 ~40 ~61 wool 15
fill ~32 ~33 ~62 ~32 ~40 ~62 wool 15
fill ~33 ~33 ~52 ~35 ~33 ~52 wool 15
fill ~33 ~33 ~59 ~41 ~33 ~59 wool 15
fill ~33 ~33 ~66 ~41 ~33 ~66 wool 15
fill ~33 ~33 ~67 ~41 ~33 ~67 wool 15
fill ~33 ~33 ~68 ~41 ~33 ~68 wool 15
fill ~33 ~33 ~69 ~40 ~33 ~69 wool 15
fill ~34 ~33 ~38 ~39 ~33 ~38 wool 0
fill ~34 ~33 ~70 ~38 ~33 ~70 wool 15
fill ~36 ~33 ~62 ~41 ~33 ~62 wool 15
fill ~36 ~33 ~63 ~41 ~33 ~63 wool 15
fill ~36 ~33 ~64 ~41 ~33 ~64 wool 15
fill ~37 ~33 ~39 ~38 ~33 ~39 wool 0
fill ~37 ~33 ~40 ~37 ~45 ~40 wool 0
fill ~37 ~33 ~41 ~37 ~46 ~41 wool 0
fill ~37 ~33 ~61 ~41 ~33 ~61 wool 15
fill ~37 ~33 ~65 ~41 ~33 ~65 wool 15
fill ~17 ~34 ~58 ~28 ~34 ~58 wool 15
fill ~17 ~34 ~59 ~27 ~34 ~59 wool 15
fill ~17 ~34 ~66 ~25 ~34 ~66 wool 15
fill ~17 ~34 ~67 ~25 ~34 ~67 wool 15
fill ~17 ~34 ~68 ~25 ~34 ~68 wool 15
fill ~18 ~34 ~37 ~26 ~34 ~37 wool 0
fill ~18 ~34 ~38 ~25 ~34 ~38 wool 0
fill ~18 ~34 ~54 ~40 ~34 ~54 wool 15
fill ~18 ~34 ~55 ~40 ~34 ~55 wool 15
fill ~18 ~34 ~56 ~28 ~34 ~56 wool 15
fill ~18 ~34 ~69 ~25 ~34 ~69 wool 15
fill ~19 ~34 ~35 ~39 ~34 ~35 wool 0
fill ~19 ~34 ~36 ~27 ~34 ~36 wool 0
fill ~19 ~34 ~39 ~24 ~34 ~39 wool 0
fill ~19 ~34 ~53 ~40 ~34 ~53 wool 15
fill ~19 ~34 ~70 ~25 ~34 ~70 wool 15
fill ~20 ~34 ~34 ~38 ~34 ~34 wool 0
fill ~20 ~34 ~40 ~24 ~34 ~40 wool 0
fill ~20 ~34 ~52 ~38 ~34 ~52 wool 15
fill ~21 ~34 ~41 ~21 ~46 ~41 wool 0
fill ~21 ~34 ~42 ~21 ~47 ~42 wool 0
fill ~21 ~34 ~43 ~22 ~34 ~43 wool 0
fill ~21 ~34 ~44 ~22 ~34 ~44 wool 0
fill ~21 ~34 ~45 ~22 ~34 ~45 wool 0
fill ~21 ~34 ~46 ~21 ~47 ~46 wool 0
fill ~22 ~34 ~46 ~37 ~34 ~46 wool 15
fill ~22 ~34 ~47 ~36 ~34 ~47 wool 15
fill ~23 ~34 ~33 ~36 ~34 ~33 wool 0
fill ~23 ~34 ~42 ~36 ~34 ~42 wool 15
fill ~23 ~34 ~43 ~37 ~34 ~43 wool 15
fill ~23 ~34 ~44 ~37 ~34 ~44 wool 15
fill ~23 ~34 ~45 ~37 ~34 ~45 wool 15
fill ~24 ~34 ~32 ~34 ~34 ~32 wool 0
fill ~24 ~34 ~41 ~36 ~34 ~41 wool 15
fill ~24 ~34 ~48 ~34 ~34 ~48 wool 15
fill ~24 ~34 ~49 ~34 ~34 ~49 wool 15
fill ~24 ~34 ~50 ~34 ~34 ~50 wool 15
fill ~24 ~34 ~51 ~34 ~34 ~51 wool 15
fill ~25 ~34 ~31 ~34 ~34 ~31 wool 0
fill ~25 ~34 ~39 ~35 ~34 ~39 wool 15
fill ~25 ~34 ~40 ~35 ~34 ~40 wool 15
fill ~26 ~34 ~30 ~32 ~34 ~30 wool 0
fill ~26 ~34 ~38 ~32 ~34 ~38 wool 15
fill ~26 ~34 ~57 ~28 ~34 ~57 wool 15
fill ~26 ~34 ~64 ~26 ~39 ~64 wool 15
fill ~26 ~34 ~65 ~26 ~40 ~65 wool 15
fill ~27 ~34 ~29 ~31 ~34 ~29 wool 0
fill ~27 ~34 ~37 ~27 ~35 ~37 wool 15
fill ~27 ~34 ~60 ~27 ~39 ~60 wool 15
setblock ~28 ~34 ~36 wool 15
fill ~28 ~34 ~37 ~31 ~34 ~37 stone 0
setblock ~29 ~34 ~36 stone 0
fill ~30 ~34 ~36 ~30 ~35 ~36 wool 15
fill ~30 ~34 ~56 ~41 ~34 ~56 wool 15
fill ~30 ~34 ~57 ~41 ~34 ~57 wool 15
fill ~31 ~34 ~36 ~40 ~34 ~36 wool 0
fill ~31 ~34 ~58 ~41 ~34 ~58 wool 15
fill ~31 ~34 ~59 ~41 ~34 ~59 wool 15
fill ~32 ~34 ~37 ~40 ~34 ~37 wool 0
fill ~32 ~34 ~60 ~32 ~40 ~60 wool 15
fill ~32 ~34 ~63 ~32 ~41 ~63 wool 15
fill ~32 ~34 ~64 ~32 ~41 ~64 wool 15
fill ~33 ~34 ~38 ~40 ~34 ~38 wool 0
fill ~33 ~34 ~66 ~41 ~34 ~66 wool 15
fill ~33 ~34 ~67 ~41 ~34 ~67 wool 15
fill ~33 ~34 ~68 ~41 ~34 ~68 wool 15
fill ~33 ~34 ~69 ~40 ~34 ~69 wool 15
fill ~33 ~34 ~70 ~39 ~34 ~70 wool 15
fill ~36 ~34 ~39 ~39 ~34 ~39 wool 0
fill ~36 ~34 ~40 ~36 ~47 ~40 wool 0
fill ~36 ~34 ~62 ~41 ~34 ~62 wool 15
fill ~36 ~34 ~63 ~41 ~34 ~63 wool 15
fill ~36 ~34 ~64 ~41 ~34 ~64 wool 15
fill ~37 ~34 ~42 ~37 ~49 ~42 wool 0
fill ~37 ~34 ~61 ~41 ~34 ~61 wool 15
fill ~37 ~34 ~65 ~41 ~34 ~65 wool 15
fill ~38 ~34 ~40 ~39 ~34 ~40 wool 0
fill ~38 ~34 ~41 ~38 ~47 ~41 wool 0
fill ~17 ~35 ~59 ~41 ~35 ~59 wool 15
fill ~17 ~35 ~66 ~26 ~35 ~66 wool 15
fill ~17 ~35 ~67 ~26 ~35 ~67 wool 15
fill ~17 ~35 ~68 ~25 ~35 ~68 wool 15
fill ~18 ~35 ~36 ~28 ~35 ~36 wool 0
fill ~18 ~35 ~37 ~26 ~35 ~37 wool 0
fill ~18 ~35 ~38 ~25 ~35 ~38 wool 0
fill ~18 ~35 ~39 ~24 ~35 ~39 wool 0
fill ~18 ~35 ~53 ~40 ~35 ~53 wool 15
fill ~18 ~35 ~54 ~40 ~35 ~54 wool 15
fill ~18 ~35 ~55 ~41 ~35 ~55 wool 15
fill ~18 ~35 ~56 ~41 ~35 ~56 wool 15
fill ~18 ~35 ~58 ~41 ~35 ~58 wool 15
fill ~18 ~35 ~69 ~25 ~35 ~69 wool 15
fill ~18 ~35 ~70 ~25 ~35 ~70 wool 15
fill ~19 ~35 ~35 ~39 ~35 ~35 wool 0
fill ~19 ~35 ~40 ~23 ~35 ~40 wool 0
fill ~19 ~35 ~41 ~22 ~35 ~41 wool 0
fill ~20 ~35 ~42 ~20 ~46 ~42 wool 0
fill ~20 ~35 ~43 ~23 ~35 ~43 wool 0
fill ~20 ~35 ~44 ~23 ~35 ~44 wool 0
fill ~20 ~35 ~45 ~22 ~35 ~45 wool 0
fill ~20 ~35 ~46 ~20 ~48 ~46 wool 0
fill ~20 ~35 ~47 ~21 ~35 ~47 wool 0
fill ~20 ~35 ~52 ~39 ~35 ~52 wool 15
fill ~21 ~35 ~34 ~38 ~35 ~34 wool 0
fill ~22 ~35 ~46 ~22 ~39 ~46 wool 0
fill ~22 ~35 ~47 ~38 ~35 ~47 wool 15
fill ~22 ~35 ~48 ~36 ~35 ~48 wool 15
fill ~22 ~35 ~49 ~36 ~35 ~49 wool 15
fill ~22 ~35 ~50 ~36 ~35 ~50 wool 15
fill ~22 ~35 ~51 ~36 ~35 ~51 wool 15
fill ~22 ~35 ~71 ~24 ~35 ~71 wool 15
fill ~23 ~35 ~33 ~35 ~35 ~33 wool 0
fill ~23 ~35 ~41 ~35 ~35 ~41 wool 15
fill ~23 ~35 ~42 ~23 ~38 ~42 wool 0
fill ~23 ~35 ~45 ~36 ~35 ~45 wool 15
fill ~23 ~35 ~46 ~37 ~35 ~46 wool 15
fill ~24 ~35 ~40 ~35 ~35 ~40 wool 15
fill ~24 ~35 ~42 ~36 ~35 ~42 wool 15
fill ~24 ~35 ~43 ~36 ~35 ~43 wool 15
fill ~24 ~35 ~44 ~36 ~35 ~44 wool 15
fill ~25 ~35 ~32 ~34 ~35 ~32 wool 0
fill ~25 ~35 ~39 ~35 ~35 ~39 wool 15
fill ~26 ~35 ~31 ~33 ~35 ~31 wool 0
fill ~26 ~35 ~38 ~26 ~36 ~38 wool 15
fill ~26 ~35 ~57 ~41 ~35 ~57 wool 15
fill ~27 ~35 ~30 ~31 ~35 ~30 wool 0
fill ~27 ~35 ~38 ~32 ~35 ~38 stone 0
fill ~27 ~35 ~61 ~28 ~35 ~61 wool 15
fill ~27 ~35 ~62 ~27 ~39 ~62 wool 15
fill ~28 ~35 ~37 ~30 ~35 ~37 stone 0
fill ~28 ~35 ~60 ~41 ~35 ~60 wool 15
setblock ~29 ~35 ~36 wool 15
fill ~30 ~35 ~61 ~41 ~35 ~61 wool 15
fill ~31 ~35 ~36 ~40 ~35 ~36 wool 0
fill ~31 ~35 ~37 ~31 ~36 ~37 wool 15
fill ~31 ~35 ~62 ~31 ~40 ~62 wool 15
fill ~32 ~35 ~37 ~40 ~35 ~37 wool 0
fill ~32 ~35 ~65 ~32 ~41 ~65 wool 15
fill ~32 ~35 ~66 ~41 ~35 ~66 wool 15
fill ~33 ~35 ~38 ~40 ~35 ~38 wool 0
fill ~33 ~35 ~67 ~41 ~35 ~67 wool 15
fill ~33 ~35 ~68 ~41 ~35 ~68 wool 15
fill ~33 ~35 ~69 ~41 ~35 ~69 wool 15
fill ~33 ~35 ~70 ~40 ~35 ~70 wool 15
fill ~34 ~35 ~71 ~36 ~35 ~71 wool 15
fill ~36 ~35 ~39 ~40 ~35 ~39 wool 0
fill ~36 ~35 ~41 ~36 ~47 ~41 wool 0
fill ~36 ~35 ~62 ~41 ~35 ~62 wool 15
fill ~36 ~35 ~63 ~41 ~35 ~63 wool 15
fill ~36 ~35 ~64 ~41 ~35 ~64 wool 15
fill ~37 ~35 ~43 ~38 ~35 ~43 wool 0
fill ~37 ~35 ~44 ~38 ~35 ~44 wool 0
fill ~37 ~35 ~45 ~38 ~35 ~45 wool 0
fill ~37 ~35 ~65 ~41 ~35 ~65 wool 15
fill ~38 ~35 ~40 ~40 ~35 ~40 wool 0
fill ~38 ~35 ~42 ~38 ~48 ~42 wool 0
fill ~38 ~35 ~46 ~38 ~48 ~46 wool 0
fill ~39 ~35 ~41 ~39 ~45 ~41 wool 0
fill ~17 ~36 ~66 ~27 ~36 ~66 wool 15
fill ~17 ~36 ~67 ~27 ~36 ~67 wool 15
fill ~17 ~36 ~68 ~26 ~36 ~68 wool 15
fill ~18 ~36 ~36 ~40 ~36 ~36 wool 0
fill ~18 ~36 ~37 ~27 ~36 ~37 wool 0
fill ~18 ~36 ~38 ~25 ~36 ~38 wool 0
fill ~18 ~36 ~39 ~24 ~36 ~39 wool 0
fill ~18 ~36 ~40 ~23 ~36 ~40 wool 0
fill ~18 ~36 ~41 ~23 ~36 ~41 wool 0
fill ~18 ~36 ~53 ~40 ~36 ~53 wool 15
fill ~18 ~36 ~54 ~40 ~36 ~54 wool 15
fill ~18 ~36 ~55 ~41 ~36 ~55 wool 15
fill ~18 ~36 ~56 ~41 ~36 ~56 wool 15
fill ~18 ~36 ~58 ~34 ~36 ~58 wool 15
fill ~18 ~36 ~59 ~35 ~36 ~59 wool 15
fill ~18 ~36 ~69 ~26 ~36 ~69 wool 15
fill ~18 ~36 ~70 ~25 ~36 ~70 wool 15
fill ~19 ~36 ~35 ~39 ~36 ~35 wool 0
fill ~19 ~36 ~42 ~19 ~46 ~42 wool 0
fill ~19 ~36 ~43 ~23 ~36 ~43 wool 0
fill ~19 ~36 ~44 ~23 ~36 ~44 wool 0
fill ~19 ~36 ~52 ~39 ~36 ~52 wool 15
fill ~20 ~36 ~45 ~23 ~36 ~45 wool 0
fill ~20 ~36 ~47 ~21 ~36 ~47 wool 0
fill ~20 ~36 ~48 ~20 ~38 ~48 wool 0
fill ~20 ~36 ~49 ~38 ~36 ~49 wool 15
fill ~20 ~36 ~71 ~25 ~36 ~71 wool 15
fill ~21 ~36 ~34 ~37 ~36 ~34 wool 0
fill ~21 ~36 ~48 ~39 ~36 ~48 wool 15
fill ~21 ~36 ~50 ~38 ~36 ~50 wool 15
fill ~21 ~36 ~51 ~38 ~36 ~51 wool 15
fill ~22 ~36 ~47 ~37 ~36 ~47 wool 15
fill ~23 ~36 ~46 ~36 ~36 ~46 wool 15
fill ~23 ~36 ~62 ~23 ~38 ~62 stone 0
fill ~24 ~36 ~33 ~24 ~37 ~33 wool 0
fill ~24 ~36 ~40 ~35 ~36 ~40 wool 15
fill ~24 ~36 ~41 ~35 ~36 ~41 wool 15
fill ~24 ~36 ~42 ~35 ~36 ~42 wool 15
fill ~24 ~36 ~43 ~35 ~36 ~43 wool 15
fill ~24 ~36 ~44 ~35 ~36 ~44 wool 15
fill ~24 ~36 ~45 ~36 ~36 ~45 wool 15
fill ~25 ~36 ~32 ~33 ~36 ~32 wool 0
fill ~25 ~36 ~39 ~25 ~34 ~39 wool 15
fill ~26 ~36 ~31 ~32 ~36 ~31 wool 0
fill ~26 ~36 ~33 ~34 ~36 ~33 wool 0
fill ~26 ~36 ~39 ~31 ~36 ~39 stone 0
fill ~26 ~36 ~57 ~35 ~36 ~57 wool 15
fill ~27 ~36 ~38 ~34 ~36 ~38 stone 0
fill ~27 ~36 ~61 ~41 ~36 ~61 wool 15
fill ~27 ~36 ~63 ~41 ~36 ~63 wool 15
fill ~27 ~36 ~64 ~41 ~36 ~64 wool 15
fill ~27 ~36 ~65 ~27 ~41 ~65 wool 15
fill ~28 ~36 ~30 ~31 ~36 ~30 wool 0
fill ~28 ~36 ~37 ~30 ~36 ~37 stone 0
fill ~28 ~36 ~60 ~41 ~36 ~60 wool 15
fill ~28 ~36 ~62 ~41 ~36 ~62 wool 15
fill ~29 ~36 ~65 ~29 ~41 ~65 wool 15
fill ~31 ~36 ~65 ~31 ~41 ~65 wool 15
fill ~32 ~36 ~37 ~41 ~36 ~37 wool 0
fill ~32 ~36 ~39 ~34 ~36 ~39 wool 15
fill ~32 ~36 ~66 ~41 ~36 ~66 wool 15
fill ~32 ~36 ~67 ~41 ~36 ~67 wool 15
fill ~32 ~36 ~68 ~41 ~36 ~68 wool 15
fill ~33 ~36 ~69 ~41 ~36 ~69 wool 15
fill ~33 ~36 ~70 ~40 ~36 ~70 wool 15
fill ~34 ~36 ~71 ~38 ~36 ~71 wool 15
fill ~35 ~36 ~38 ~41 ~36 ~38 wool 0
fill ~35 ~36 ~39 ~41 ~36 ~39 wool 0
fill ~35 ~36 ~58 ~36 ~36 ~58 stone 0
fill ~36 ~36 ~42 ~36 ~48 ~42 wool 0
fill ~36 ~36 ~43 ~39 ~36 ~43 wool 0
fill ~36 ~36 ~44 ~39 ~36 ~44 wool 0
fill ~36 ~36 ~57 ~36 ~37 ~57 stone 0
fill ~36 ~36 ~59 ~36 ~37 ~59 stone 0
fill ~37 ~36 ~45 ~39 ~36 ~45 wool 0
fill ~37 ~36 ~46 ~37 ~40 ~46 wool 0
fill ~37 ~36 ~57 ~41 ~36 ~57 wool 15
fill ~37 ~36 ~58 ~41 ~36 ~58 wool 15
fill ~37 ~36 ~59 ~41 ~36 ~59 wool 15
fill ~37 ~36 ~65 ~41 ~36 ~65 wool 15
fill ~38 ~36 ~40 ~41 ~36 ~40 wool 0
fill ~38 ~36 ~47 ~39 ~36 ~47 wool 0
fill ~39 ~36 ~42 ~40 ~36 ~42 wool 0
fill ~39 ~36 ~46 ~39 ~49 ~46 wool 0
fill ~40 ~36 ~41 ~40 ~44 ~41 wool 0
fill ~17 ~37 ~40 ~23 ~37 ~40 wool 0
fill ~17 ~37 ~41 ~23 ~37 ~41 wool 0
fill ~17 ~37 ~42 ~23 ~37 ~42 wool 0
fill ~17 ~37 ~66 ~41 ~37 ~66 wool 15
fill ~17 ~37 ~67 ~41 ~37 ~67 wool 15
fill ~17 ~37 ~68 ~41 ~37 ~68 wool 15
fill ~17 ~37 ~69 ~27 ~37 ~69 wool 15
fill ~18 ~37 ~36 ~40 ~37 ~36 wool 0
fill ~18 ~37 ~37 ~27 ~37 ~37 wool 0
fill ~18 ~37 ~38 ~26 ~37 ~38 wool 0
fill ~18 ~37 ~39 ~24 ~37 ~39 wool 0
fill ~18 ~37 ~43 ~23 ~37 ~43 wool 0
fill ~18 ~37 ~44 ~23 ~37 ~44 wool 0
fill ~18 ~37 ~53 ~40 ~37 ~53 wool 15
fill ~18 ~37 ~54 ~35 ~37 ~54 wool 15
fill ~18 ~37 ~55 ~35 ~37 ~55 wool 15
fill ~18 ~37 ~56 ~34 ~37 ~56 wool 15
fill ~18 ~37 ~58 ~34 ~37 ~58 wool 15
fill ~18 ~37 ~59 ~34 ~37 ~59 wool 15
fill ~18 ~37 ~70 ~26 ~37 ~70 wool 15
fill ~18 ~37 ~71 ~25 ~37 ~71 wool 15
fill ~19 ~37 ~35 ~39 ~37 ~35 wool 0
fill ~19 ~37 ~45 ~23 ~37 ~45 wool 0
fill ~19 ~37 ~46 ~19 ~48 ~46 wool 0
fill ~19 ~37 ~49 ~39 ~37 ~49 wool 15
fill ~19 ~37 ~50 ~39 ~37 ~50 wool 15
fill ~19 ~37 ~51 ~39 ~37 ~51 wool 15
fill ~19 ~37 ~52 ~40 ~37 ~52 wool 15
fill ~20 ~37 ~47 ~21 ~37 ~47 wool 0
fill ~21 ~37 ~34 ~37 ~37 ~34 wool 0
fill ~21 ~37 ~48 ~38 ~37 ~48 wool 15
fill ~21 ~37 ~72 ~24 ~37 ~72 wool 15
fill ~22 ~37 ~47 ~37 ~37 ~47 wool 15
fill ~23 ~37 ~46 ~36 ~37 ~46 wool 15
fill ~23 ~37 ~63 ~25 ~37 ~63 stone 0
fill ~23 ~37 ~64 ~25 ~37 ~64 stone 0
fill ~23 ~37 ~65 ~24 ~37 ~65 stone 0
fill ~24 ~37 ~40 ~31 ~37 ~40 stone 0
fill ~24 ~37 ~41 ~35 ~37 ~41 wool 15
fill ~24 ~37 ~42 ~35 ~37 ~42 wool 15
fill ~24 ~37 ~43 ~35 ~37 ~43 wool 15
fill ~24 ~37 ~44 ~35 ~37 ~44 wool 15
fill ~24 ~37 ~45 ~35 ~37 ~45 wool 15
fill ~24 ~37 ~61 ~24 ~65 ~61 stone 0
fill ~24 ~37 ~62 ~24 ~66 ~62 stone 0
fill ~25 ~37 ~39 ~34 ~37 ~39 stone 0
fill ~26 ~37 ~32 ~32 ~37 ~32 wool 0
fill ~26 ~37 ~33 ~34 ~37 ~33 wool 0
fill ~26 ~37 ~57 ~33 ~37 ~57 wool 15
fill ~27 ~37 ~31 ~31 ~37 ~31 wool 0
fill ~27 ~37 ~38 ~31 ~37 ~38 stone 0
fill ~27 ~37 ~61 ~35 ~37 ~61 wool 15
fill ~27 ~37 ~63 ~41 ~37 ~63 wool 15
fill ~27 ~37 ~64 ~41 ~37 ~64 wool 15
fill ~28 ~37 ~37 ~30 ~37 ~37 stone 0
fill ~28 ~37 ~60 ~35 ~37 ~60 wool 15
fill ~28 ~37 ~62 ~35 ~37 ~62 wool 15
fill ~28 ~37 ~65 ~28 ~41 ~65 wool 15
fill ~30 ~37 ~65 ~30 ~41 ~65 wool 15
fill ~31 ~37 ~37 ~41 ~37 ~37 wool 0
fill ~32 ~37 ~38 ~41 ~37 ~38 wool 0
fill ~32 ~37 ~40 ~34 ~37 ~40 wool 15
fill ~32 ~37 ~69 ~41 ~37 ~69 wool 15
fill ~32 ~37 ~70 ~41 ~37 ~70 wool 15
fill ~33 ~37 ~71 ~40 ~37 ~71 wool 15
fill ~34 ~37 ~57 ~36 ~37 ~57 stone 0
fill ~35 ~37 ~39 ~41 ~37 ~39 wool 0
fill ~35 ~37 ~40 ~35 ~48 ~40 wool 0
fill ~35 ~37 ~56 ~36 ~37 ~56 stone 0
fill ~35 ~37 ~58 ~36 ~37 ~58 stone 0
fill ~35 ~37 ~59 ~35 ~38 ~59 stone 0
fill ~35 ~37 ~72 ~37 ~37 ~72 wool 15
fill ~36 ~37 ~43 ~41 ~37 ~43 wool 0
fill ~36 ~37 ~44 ~40 ~37 ~44 wool 0
fill ~36 ~37 ~45 ~40 ~37 ~45 wool 0
fill ~36 ~37 ~54 ~36 ~37 ~62 stone 0
fill ~37 ~37 ~54 ~40 ~37 ~54 wool 15
fill ~37 ~37 ~55 ~41 ~37 ~55 wool 15
fill ~37 ~37 ~56 ~41 ~37 ~56 wool 15
fill ~37 ~37 ~57 ~41 ~37 ~57 wool 15
fill ~37 ~37 ~58 ~41 ~37 ~58 wool 15
fill ~37 ~37 ~59 ~41 ~37 ~59 wool 15
fill ~37 ~37 ~61 ~41 ~37 ~61 wool 15
fill ~37 ~37 ~62 ~41 ~37 ~62 wool 15
fill ~37 ~37 ~65 ~41 ~37 ~65 wool 15
fill ~38 ~37 ~40 ~41 ~37 ~40 wool 0
fill ~38 ~37 ~47 ~39 ~37 ~47 wool 0
fill ~39 ~37 ~42 ~41 ~37 ~42 wool 0
fill ~39 ~37 ~48 ~39 ~39 ~48 wool 0
fill ~41 ~37 ~41 ~41 ~41 ~41 wool 0
fill ~17 ~38 ~40 ~23 ~38 ~40 wool 0
fill ~17 ~38 ~41 ~22 ~38 ~41 wool 0
fill ~17 ~38 ~42 ~23 ~38 ~42 wool 0
fill ~17 ~38 ~43 ~23 ~38 ~43 wool 0
fill ~17 ~38 ~44 ~23 ~38 ~44 wool 0
fill ~17 ~38 ~66 ~41 ~38 ~66 wool 15
fill ~17 ~38 ~67 ~41 ~38 ~67 wool 15
fill ~17 ~38 ~68 ~41 ~38 ~68 wool 15
fill ~17 ~38 ~69 ~41 ~38 ~69 wool 15
fill ~18 ~38 ~37 ~27 ~38 ~37 wool 0
fill ~18 ~38 ~38 ~25 ~38 ~38 wool 0
fill ~18 ~38 ~39 ~25 ~38 ~39 wool 0
fill ~18 ~38 ~45 ~23 ~38 ~45 wool 0
fill ~18 ~38 ~46 ~18 ~49 ~46 wool 0
fill ~18 ~38 ~53 ~34 ~38 ~53 wool 15
fill ~18 ~38 ~54 ~34 ~38 ~54 wool 15
fill ~18 ~38 ~55 ~23 ~38 ~55 wool 15
fill ~18 ~38 ~56 ~22 ~38 ~56 wool 15
fill ~18 ~38 ~58 ~23 ~38 ~58 wool 15
fill ~18 ~38 ~59 ~23 ~38 ~59 wool 15
fill ~18 ~38 ~70 ~26 ~38 ~70 wool 15
fill ~18 ~38 ~71 ~26 ~38 ~71 wool 15
fill ~19 ~38 ~36 ~39 ~38 ~36 wool 0
fill ~19 ~38 ~47 ~21 ~38 ~47 wool 0
fill ~19 ~38 ~48 ~19 ~39 ~48 wool 0
fill ~19 ~38 ~49 ~39 ~38 ~49 wool 15
fill ~19 ~38 ~50 ~24 ~38 ~50 wool 15
fill ~19 ~38 ~51 ~24 ~38 ~51 wool 15
fill ~19 ~38 ~52 ~39 ~38 ~52 wool 15
fill ~19 ~38 ~72 ~24 ~38 ~72 wool 15
fill ~20 ~38 ~35 ~39 ~38 ~35 wool 0
fill ~21 ~38 ~48 ~38 ~38 ~48 wool 15
fill ~22 ~38 ~34 ~36 ~38 ~34 wool 0
fill ~22 ~38 ~47 ~37 ~38 ~47 wool 15
fill ~23 ~38 ~41 ~32 ~38 ~41 stone 0
fill ~23 ~38 ~46 ~36 ~38 ~46 wool 15
fill ~23 ~38 ~56 ~24 ~38 ~56 stone 0
fill ~23 ~38 ~57 ~24 ~38 ~57 stone 0
fill ~23 ~38 ~61 ~23 ~39 ~61 stone 0
fill ~23 ~38 ~63 ~25 ~38 ~63 stone 0
fill ~23 ~38 ~64 ~25 ~38 ~64 stone 0
fill ~23 ~38 ~65 ~24 ~38 ~65 stone 0
fill ~24 ~38 ~40 ~24 ~39 ~40 wool 15
fill ~24 ~38 ~42 ~24 ~32 ~42 wool 15
fill ~24 ~38 ~43 ~25 ~38 ~43 wool 15
fill ~24 ~38 ~44 ~35 ~38 ~44 wool 15
fill ~24 ~38 ~45 ~35 ~38 ~45 wool 15
fill ~24 ~38 ~55 ~24 ~60 ~55 stone 0
fill ~24 ~38 ~58 ~24 ~63 ~58 stone 0
fill ~24 ~38 ~59 ~24 ~63 ~59 stone 0
fill ~24 ~38 ~60 ~24 ~64 ~60 stone 0
fill ~25 ~38 ~40 ~34 ~38 ~40 stone 0
fill ~25 ~38 ~42 ~27 ~38 ~42 stone 0
fill ~25 ~38 ~50 ~25 ~52 ~50 stone 0
fill ~25 ~38 ~51 ~25 ~53 ~51 stone 0
fill ~25 ~38 ~55 ~33 ~38 ~55 wool 15
fill ~25 ~38 ~56 ~31 ~38 ~56 wool 15
fill ~25 ~38 ~58 ~33 ~38 ~58 wool 15
fill ~25 ~38 ~59 ~34 ~38 ~59 wool 15
fill ~25 ~38 ~61 ~25 ~65 ~61 stone 0
fill ~25 ~38 ~62 ~25 ~67 ~62 stone 0
fill ~26 ~38 ~32 ~32 ~38 ~32 wool 0
fill ~26 ~38 ~33 ~34 ~38 ~33 wool 0
fill ~26 ~38 ~38 ~30 ~38 ~38 stone 0
fill ~26 ~38 ~39 ~32 ~38 ~39 stone 0
fill ~26 ~38 ~43 ~26 ~45 ~43 stone 0
fill ~26 ~38 ~50 ~39 ~38 ~50 wool 15
fill ~26 ~38 ~51 ~39 ~38 ~51 wool 15
fill ~26 ~38 ~57 ~32 ~38 ~57 wool 15
fill ~27 ~38 ~43 ~35 ~38 ~43 wool 15
fill ~27 ~38 ~61 ~34 ~38 ~61 wool 15
fill ~27 ~38 ~63 ~41 ~38 ~63 wool 15
fill ~27 ~38 ~64 ~41 ~38 ~64 wool 15
fill ~28 ~38 ~37 ~29 ~38 ~37 stone 0
fill ~28 ~38 ~42 ~30 ~38 ~42 wool 15
fill ~28 ~38 ~60 ~34 ~38 ~60 wool 15
fill ~28 ~38 ~62 ~41 ~38 ~62 wool 15
fill ~29 ~38 ~31 ~30 ~38 ~31 wool 0
fill ~29 ~38 ~70 ~30 ~38 ~70 wool 15
fill ~30 ~38 ~37 ~40 ~38 ~37 wool 0
fill ~31 ~38 ~38 ~41 ~38 ~38 wool 0
fill ~31 ~38 ~42 ~31 ~42 ~42 stone 0
fill ~32 ~38 ~42 ~35 ~38 ~42 wool 15
fill ~32 ~38 ~56 ~35 ~38 ~56 stone 0
fill ~32 ~38 ~70 ~41 ~38 ~70 wool 15
fill ~32 ~38 ~71 ~40 ~38 ~71 wool 15
fill ~33 ~38 ~39 ~41 ~38 ~39 wool 0
fill ~33 ~38 ~41 ~34 ~38 ~41 wool 15
fill ~33 ~38 ~57 ~35 ~38 ~57 stone 0
fill ~34 ~38 ~55 ~35 ~38 ~55 stone 0
fill ~34 ~38 ~58 ~35 ~38 ~58 stone 0
fill ~34 ~38 ~72 ~39 ~38 ~72 wool 15
setblock ~35 ~38 ~41 wool 0
fill ~35 ~38 ~53 ~35 ~38 ~61 stone 0
fill ~36 ~38 ~43 ~41 ~38 ~43 wool 0
fill ~36 ~38 ~44 ~41 ~38 ~44 wool 0
fill ~36 ~38 ~45 ~41 ~38 ~45 wool 0
fill ~36 ~38 ~53 ~40 ~38 ~53 wool 15
fill ~36 ~38 ~54 ~40 ~38 ~54 wool 15
fill ~36 ~38 ~55 ~40 ~38 ~55 wool 15
fill ~36 ~38 ~56 ~40 ~38 ~56 wool 15
fill ~36 ~38 ~57 ~41 ~38 ~57 wool 15
fill ~36 ~38 ~58 ~41 ~38 ~58 wool 15
fill ~36 ~38 ~59 ~41 ~38 ~59 wool 15
fill ~36 ~38 ~60 ~36 ~46 ~60 wool 15
setblock ~36 ~38 ~61 stone 0
fill ~37 ~38 ~61 ~41 ~38 ~61 wool 15
fill ~37 ~38 ~65 ~41 ~38 ~65 wool 15
fill ~38 ~38 ~40 ~41 ~38 ~40 wool 0
fill ~38 ~38 ~47 ~40 ~38 ~47 wool 0
fill ~39 ~38 ~42 ~41 ~38 ~42 wool 0
fill ~40 ~38 ~46 ~40 ~50 ~46 wool 0
fill ~17 ~39 ~40 ~23 ~39 ~40 wool 0
fill ~17 ~39 ~41 ~23 ~39 ~41 wool 0
fill ~17 ~39 ~42 ~22 ~39 ~42 wool 0
fill ~17 ~39 ~43 ~22 ~39 ~43 wool 0
fill ~17 ~39 ~44 ~21 ~39 ~44 wool 0
fill ~17 ~39 ~45 ~21 ~39 ~45 wool 0
fill ~17 ~39 ~46 ~17 ~47 ~46 wool 0
fill ~17 ~39 ~66 ~22 ~39 ~66 wool 15
fill ~17 ~39 ~67 ~41 ~39 ~67 wool 15
fill ~17 ~39 ~68 ~41 ~39 ~68 wool 15
fill ~17 ~39 ~69 ~41 ~39 ~69 wool 15
fill ~17 ~39 ~70 ~41 ~39 ~70 wool 15
fill ~18 ~39 ~38 ~26 ~39 ~38 wool 0
fill ~18 ~39 ~39 ~25 ~39 ~39 wool 0
fill ~18 ~39 ~47 ~21 ~39 ~47 wool 0
fill ~18 ~39 ~48 ~18 ~39 ~38 wool 0
fill ~18 ~39 ~54 ~24 ~39 ~54 wool 15
fill ~18 ~39 ~55 ~23 ~39 ~55 wool 15
fill ~18 ~39 ~56 ~22 ~39 ~56 wool 15
fill ~18 ~39 ~58 ~22 ~39 ~58 wool 15
fill ~18 ~39 ~59 ~22 ~39 ~59 wool 15
fill ~18 ~39 ~71 ~26 ~39 ~71 wool 15
fill ~18 ~39 ~72 ~26 ~39 ~72 wool 15
fill ~19 ~39 ~37 ~26 ~39 ~37 wool 0
fill ~19 ~39 ~49 ~24 ~39 ~49 wool 15
fill ~19 ~39 ~50 ~24 ~39 ~50 wool 15
fill ~19 ~39 ~51 ~24 ~39 ~51 wool 15
fill ~19 ~39 ~52 ~24 ~39 ~52 wool 15
fill ~19 ~39 ~53 ~24 ~39 ~53 wool 15
fill ~20 ~39 ~36 ~38 ~39 ~36 wool 0
fill ~20 ~39 ~48 ~23 ~39 ~48 wool 15
fill ~20 ~39 ~73 ~24 ~39 ~73 wool 15
fill ~21 ~39 ~35 ~38 ~39 ~35 wool 0
fill ~22 ~39 ~44 ~35 ~39 ~44 stone 0
fill ~22 ~39 ~45 ~34 ~39 ~45 stone 0
fill ~22 ~39 ~47 ~23 ~39 ~47 wool 15
fill ~23 ~39 ~34 ~35 ~39 ~34 wool 0
fill ~23 ~39 ~42 ~35 ~39 ~42 stone 0
fill ~23 ~39 ~43 ~36 ~39 ~43 stone 0
fill ~23 ~39 ~46 ~34 ~39 ~46 stone 0
fill ~23 ~39 ~56 ~26 ~39 ~56 stone 0
fill ~23 ~39 ~57 ~25 ~39 ~57 stone 0
fill ~23 ~39 ~58 ~23 ~63 ~58 stone 0
fill ~23 ~39 ~59 ~23 ~63 ~59 stone 0
fill ~23 ~39 ~60 ~23 ~64 ~60 stone 0
fill ~23 ~39 ~62 ~23 ~43 ~62 wool 15
fill ~23 ~39 ~63 ~23 ~43 ~63 wool 15
fill ~23 ~39 ~64 ~23 ~43 ~64 wool 15
fill ~23 ~39 ~65 ~24 ~39 ~65 stone 0
fill ~23 ~39 ~66 ~24 ~39 ~66 stone 0
fill ~24 ~39 ~41 ~35 ~39 ~41 stone 0
fill ~24 ~39 ~47 ~33 ~39 ~47 stone 0
fill ~24 ~39 ~48 ~27 ~39 ~48 stone 0
fill ~24 ~39 ~63 ~26 ~39 ~63 stone 0
fill ~24 ~39 ~64 ~25 ~39 ~64 stone 0
fill ~25 ~39 ~40 ~32 ~39 ~40 stone 0
fill ~25 ~39 ~49 ~26 ~39 ~49 stone 0
fill ~25 ~39 ~52 ~26 ~39 ~52 stone 0
fill ~25 ~39 ~53 ~25 ~57 ~53 stone 0
fill ~25 ~39 ~54 ~25 ~59 ~54 stone 0
fill ~25 ~39 ~55 ~25 ~60 ~55 stone 0
fill ~25 ~39 ~58 ~25 ~63 ~58 stone 0
fill ~25 ~39 ~59 ~25 ~64 ~59 stone 0
fill ~25 ~39 ~60 ~26 ~39 ~60 stone 0
fill ~25 ~39 ~66 ~41 ~39 ~66 wool 15
fill ~26 ~39 ~33 ~33 ~39 ~33 wool 0
fill ~26 ~39 ~39 ~31 ~39 ~39 stone 0
fill ~26 ~39 ~50 ~26 ~52 ~50 stone 0
fill ~26 ~39 ~51 ~26 ~54 ~51 stone 0
fill ~26 ~39 ~53 ~30 ~39 ~53 wool 15
fill ~26 ~39 ~54 ~30 ~39 ~54 wool 15
fill ~26 ~39 ~55 ~30 ~39 ~55 wool 15
fill ~26 ~39 ~57 ~30 ~39 ~57 wool 15
fill ~26 ~39 ~58 ~32 ~39 ~58 wool 15
fill ~26 ~39 ~59 ~33 ~39 ~59 wool 15
fill ~26 ~39 ~61 ~26 ~66 ~61 stone 0
fill ~26 ~39 ~62 ~26 ~67 ~62 stone 0
fill ~27 ~39 ~37 ~28 ~39 ~37 stone 0
fill ~27 ~39 ~38 ~29 ~39 ~38 stone 0
fill ~27 ~39 ~49 ~39 ~39 ~49 wool 15
fill ~27 ~39 ~50 ~39 ~39 ~50 wool 15
fill ~27 ~39 ~51 ~33 ~39 ~51 wool 15
fill ~27 ~39 ~52 ~32 ~39 ~52 wool 15
fill ~27 ~39 ~56 ~29 ~39 ~56 wool 15
fill ~27 ~39 ~61 ~33 ~39 ~61 wool 15
fill ~27 ~39 ~63 ~41 ~39 ~63 wool 15
fill ~27 ~39 ~64 ~41 ~39 ~64 wool 15
fill ~28 ~39 ~32 ~31 ~39 ~32 wool 0
fill ~28 ~39 ~48 ~32 ~39 ~48 wool 15
fill ~28 ~39 ~60 ~33 ~39 ~60 wool 15
fill ~28 ~39 ~62 ~34 ~39 ~62 wool 15
fill ~28 ~39 ~71 ~30 ~39 ~71 wool 15
fill ~29 ~39 ~37 ~39 ~39 ~37 wool 0
fill ~29 ~39 ~72 ~29 ~46 ~72 wool 15
fill ~30 ~39 ~38 ~40 ~39 ~38 wool 0
fill ~30 ~39 ~56 ~35 ~39 ~56 stone 0
fill ~31 ~39 ~53 ~34 ~39 ~53 stone 0
fill ~31 ~39 ~54 ~34 ~39 ~54 stone 0
fill ~31 ~39 ~55 ~34 ~39 ~55 stone 0
fill ~31 ~39 ~57 ~34 ~39 ~57 stone 0
fill ~32 ~39 ~39 ~41 ~39 ~39 wool 0
fill ~32 ~39 ~71 ~41 ~39 ~71 wool 15
fill ~33 ~39 ~40 ~41 ~39 ~40 wool 0
fill ~33 ~39 ~48 ~33 ~50 ~48 stone 0
fill ~33 ~39 ~52 ~34 ~39 ~52 stone 0
fill ~33 ~39 ~58 ~34 ~39 ~58 stone 0
fill ~33 ~39 ~72 ~40 ~39 ~72 wool 15
fill ~34 ~39 ~47 ~37 ~39 ~47 wool 15
fill ~34 ~39 ~48 ~38 ~39 ~48 wool 15
fill ~34 ~39 ~51 ~34 ~52 ~51 stone 0
fill ~34 ~39 ~59 ~34 ~64 ~59 stone 0
fill ~34 ~39 ~60 ~35 ~39 ~60 stone 0
fill ~34 ~39 ~61 ~35 ~39 ~61 stone 0
fill ~35 ~39 ~45 ~35 ~39 ~55 wool 15
fill ~35 ~39 ~57 ~40 ~39 ~57 wool 15
fill ~35 ~39 ~58 ~40 ~39 ~58 wool 15
fill ~35 ~39 ~59 ~41 ~39 ~59 wool 15
fill ~35 ~39 ~62 ~35 ~41 ~62 stone 0
fill ~35 ~39 ~73 ~38 ~39 ~73 wool 15
fill ~36 ~39 ~44 ~41 ~39 ~44 wool 0
fill ~36 ~39 ~45 ~41 ~39 ~45 wool 0
fill ~36 ~39 ~46 ~36 ~42 ~46 wool 15
fill ~36 ~39 ~51 ~39 ~39 ~51 wool 15
fill ~36 ~39 ~52 ~39 ~39 ~52 wool 15
fill ~36 ~39 ~53 ~40 ~39 ~53 wool 15
fill ~36 ~39 ~54 ~40 ~39 ~54 wool 15
fill ~36 ~39 ~55 ~40 ~39 ~55 wool 15
fill ~36 ~39 ~56 ~40 ~39 ~56 wool 15
fill ~36 ~39 ~61 ~41 ~39 ~61 wool 15
fill ~36 ~39 ~62 ~41 ~39 ~62 wool 15
fill ~37 ~39 ~43 ~41 ~39 ~43 wool 0
fill ~37 ~39 ~65 ~41 ~39 ~65 wool 15
fill ~38 ~39 ~47 ~41 ~39 ~47 wool 0
fill ~39 ~39 ~42 ~41 ~39 ~42 wool 0
fill ~40 ~39 ~48 ~40 ~49 ~48 wool 0
fill ~41 ~39 ~46 ~41 ~50 ~46 wool 0
fill ~17 ~40 ~41 ~24 ~40 ~41 wool 0
fill ~17 ~40 ~42 ~22 ~40 ~42 wool 0
fill ~17 ~40 ~43 ~21 ~40 ~43 wool 0
fill ~17 ~40 ~44 ~21 ~40 ~44 wool 0
fill ~17 ~40 ~45 ~21 ~40 ~45 wool 0
fill ~17 ~40 ~47 ~20 ~40 ~47 wool 0
fill ~17 ~40 ~48 ~23 ~40 ~48 wool 15
fill ~17 ~40 ~49 ~23 ~40 ~49 wool 15
fill ~17 ~40 ~66 ~22 ~40 ~66 wool 15
fill ~17 ~40 ~67 ~21 ~40 ~67 wool 15
fill ~17 ~40 ~68 ~41 ~40 ~68 wool 15
fill ~17 ~40 ~69 ~41 ~40 ~69 wool 15
fill ~17 ~40 ~70 ~41 ~40 ~70 wool 15
fill ~18 ~40 ~39 ~25 ~40 ~39 wool 0
fill ~18 ~40 ~40 ~24 ~40 ~40 wool 0
fill ~18 ~40 ~50 ~24 ~40 ~50 wool 15
fill ~18 ~40 ~54 ~24 ~40 ~54 wool 15
fill ~18 ~40 ~55 ~23 ~40 ~55 wool 15
fill ~18 ~40 ~56 ~22 ~40 ~56 wool 15
fill ~18 ~40 ~58 ~21 ~40 ~58 wool 15
fill ~18 ~40 ~59 ~21 ~40 ~59 wool 15
fill ~18 ~40 ~71 ~41 ~40 ~71 wool 15
fill ~18 ~40 ~72 ~40 ~40 ~72 wool 15
fill ~19 ~40 ~38 ~26 ~40 ~38 wool 0
fill ~19 ~40 ~51 ~24 ~40 ~51 wool 15
fill ~19 ~40 ~52 ~24 ~40 ~52 wool 15
fill ~19 ~40 ~53 ~24 ~40 ~53 wool 15
fill ~19 ~40 ~73 ~26 ~40 ~73 wool 15
fill ~20 ~40 ~37 ~26 ~40 ~37 wool 0
fill ~21 ~40 ~36 ~26 ~40 ~36 wool 0
fill ~21 ~40 ~47 ~22 ~40 ~47 wool 15
fill ~22 ~40 ~35 ~36 ~40 ~35 wool 0
fill ~22 ~40 ~43 ~36 ~40 ~43 stone 0
fill ~22 ~40 ~44 ~36 ~40 ~44 stone 0
fill ~22 ~40 ~45 ~35 ~40 ~45 stone 0
fill ~22 ~40 ~46 ~34 ~40 ~46 stone 0
fill ~22 ~40 ~57 ~34 ~40 ~57 stone 0
fill ~22 ~40 ~58 ~22 ~63 ~58 stone 0
fill ~22 ~40 ~59 ~22 ~63 ~59 stone 0
fill ~22 ~40 ~67 ~24 ~40 ~67 stone 0
fill ~22 ~40 ~74 ~23 ~40 ~74 wool 15
fill ~23 ~40 ~42 ~35 ~40 ~42 stone 0
fill ~23 ~40 ~47 ~34 ~40 ~47 stone 0
fill ~23 ~40 ~56 ~34 ~40 ~56 stone 0
fill ~23 ~40 ~61 ~23 ~42 ~61 wool 15
fill ~23 ~40 ~65 ~23 ~48 ~65 wool 15
fill ~23 ~40 ~66 ~24 ~40 ~66 stone 0
fill ~24 ~40 ~48 ~34 ~40 ~48 stone 0
fill ~24 ~40 ~49 ~34 ~40 ~49 stone 0
fill ~24 ~40 ~63 ~27 ~40 ~63 stone 0
fill ~24 ~40 ~64 ~26 ~40 ~64 stone 0
fill ~24 ~40 ~65 ~25 ~40 ~65 stone 0
fill ~25 ~40 ~34 ~34 ~40 ~34 wool 0
setblock ~25 ~40 ~40 wool 15
fill ~25 ~40 ~41 ~32 ~40 ~41 stone 0
fill ~25 ~40 ~52 ~34 ~40 ~52 stone 0
fill ~25 ~40 ~60 ~27 ~40 ~60 stone 0
fill ~25 ~40 ~66 ~34 ~40 ~66 wool 15
fill ~25 ~40 ~67 ~41 ~40 ~67 wool 15
fill ~26 ~40 ~39 ~28 ~40 ~39 stone 0
fill ~26 ~40 ~40 ~31 ~40 ~40 stone 0
fill ~26 ~40 ~53 ~34 ~40 ~53 stone 0
fill ~26 ~40 ~54 ~34 ~40 ~54 stone 0
fill ~26 ~40 ~55 ~34 ~40 ~55 stone 0
fill ~26 ~40 ~58 ~34 ~40 ~58 stone 0
fill ~26 ~40 ~59 ~28 ~40 ~59 stone 0
fill ~27 ~40 ~33 ~32 ~40 ~33 wool 0
fill ~27 ~40 ~36 ~27 ~40 ~63 stone 0
fill ~27 ~40 ~64 ~34 ~40 ~64 wool 15
fill ~28 ~40 ~36 ~38 ~40 ~36 wool 0
fill ~28 ~40 ~37 ~38 ~40 ~37 wool 0
fill ~28 ~40 ~38 ~39 ~40 ~38 wool 0
fill ~28 ~40 ~50 ~34 ~40 ~50 stone 0
fill ~28 ~40 ~51 ~34 ~40 ~51 stone 0
fill ~28 ~40 ~60 ~32 ~40 ~60 wool 15
fill ~28 ~40 ~61 ~32 ~40 ~61 wool 15
fill ~28 ~40 ~62 ~33 ~40 ~62 wool 15
fill ~28 ~40 ~63 ~34 ~40 ~63 wool 15
fill ~29 ~40 ~39 ~30 ~40 ~39 wool 15
fill ~29 ~40 ~59 ~31 ~40 ~59 wool 15
fill ~29 ~40 ~73 ~30 ~40 ~73 wool 15
fill ~31 ~40 ~39 ~40 ~40 ~39 wool 0
fill ~32 ~40 ~40 ~41 ~40 ~40 wool 0
fill ~32 ~40 ~59 ~34 ~40 ~59 stone 0
setblock ~33 ~40 ~41 wool 15
fill ~33 ~40 ~60 ~34 ~40 ~60 stone 0
fill ~33 ~40 ~61 ~35 ~40 ~61 stone 0
fill ~33 ~40 ~73 ~39 ~40 ~73 wool 15
fill ~34 ~40 ~41 ~41 ~40 ~41 wool 0
fill ~34 ~40 ~62 ~34 ~67 ~62 stone 0
fill ~35 ~40 ~46 ~35 ~40 ~60 wool 15
fill ~35 ~40 ~63 ~35 ~41 ~63 stone 0
fill ~35 ~40 ~64 ~35 ~41 ~64 stone 0
fill ~35 ~40 ~65 ~35 ~42 ~65 stone 0
fill ~35 ~40 ~66 ~35 ~42 ~66 stone 0
fill ~36 ~40 ~45 ~36 ~42 ~45 wool 15
fill ~36 ~40 ~47 ~37 ~40 ~47 wool 15
fill ~36 ~40 ~48 ~39 ~40 ~48 wool 15
fill ~36 ~40 ~49 ~41 ~40 ~49 wool 15
fill ~36 ~40 ~50 ~40 ~40 ~50 wool 15
fill ~36 ~40 ~51 ~40 ~40 ~51 wool 15
fill ~36 ~40 ~52 ~39 ~40 ~52 wool 15
fill ~36 ~40 ~53 ~40 ~40 ~53 wool 15
fill ~36 ~40 ~54 ~40 ~40 ~54 wool 15
fill ~36 ~40 ~55 ~40 ~40 ~55 wool 15
fill ~36 ~40 ~56 ~40 ~40 ~56 wool 15
fill ~36 ~40 ~57 ~40 ~40 ~57 wool 15
fill ~36 ~40 ~58 ~40 ~40 ~58 wool 15
fill ~36 ~40 ~59 ~40 ~40 ~59 wool 15
fill ~36 ~40 ~61 ~41 ~40 ~61 wool 15
fill ~36 ~40 ~62 ~41 ~40 ~62 wool 15
fill ~36 ~40 ~63 ~41 ~40 ~63 wool 15
fill ~36 ~40 ~64 ~41 ~40 ~64 wool 15
fill ~36 ~40 ~66 ~41 ~40 ~66 wool 15
fill ~36 ~40 ~74 ~36 ~52 ~74 wool 15
fill ~37 ~40 ~43 ~41 ~40 ~43 wool 0
fill ~37 ~40 ~44 ~41 ~40 ~44 wool 0
fill ~37 ~40 ~45 ~41 ~40 ~45 wool 0
fill ~37 ~40 ~65 ~41 ~40 ~65 wool 15
fill ~38 ~40 ~47 ~41 ~40 ~47 wool 0
fill ~39 ~40 ~42 ~41 ~40 ~42 wool 0
fill ~41 ~40 ~48 ~41 ~49 ~48 wool 0
fill ~42 ~40 ~48 ~42 ~43 ~48 wool 15
fill ~16 ~41 ~50 ~24 ~41 ~50 wool 15
fill ~16 ~41 ~51 ~24 ~41 ~51 wool 15
fill ~17 ~41 ~42 ~24 ~41 ~42 wool 0
fill ~17 ~41 ~43 ~21 ~41 ~43 wool 0
fill ~17 ~41 ~44 ~21 ~41 ~44 wool 0
fill ~17 ~41 ~45 ~21 ~41 ~45 wool 0
fill ~17 ~41 ~47 ~20 ~41 ~47 wool 0
fill ~17 ~41 ~48 ~19 ~41 ~48 wool 0
fill ~17 ~41 ~49 ~23 ~41 ~49 wool 15
fill ~17 ~41 ~52 ~24 ~41 ~52 wool 15
fill ~17 ~41 ~66 ~22 ~41 ~66 wool 15
fill ~17 ~41 ~67 ~22 ~41 ~67 wool 15
fill ~17 ~41 ~68 ~41 ~41 ~68 wool 15
fill ~17 ~41 ~69 ~41 ~41 ~69 wool 15
fill ~17 ~41 ~70 ~41 ~41 ~70 wool 15
fill ~18 ~41 ~40 ~25 ~41 ~40 wool 0
fill ~18 ~41 ~41 ~25 ~41 ~41 wool 0
fill ~18 ~41 ~53 ~24 ~41 ~53 wool 15
fill ~18 ~41 ~55 ~23 ~41 ~55 wool 15
fill ~18 ~41 ~56 ~22 ~41 ~56 wool 15
fill ~18 ~41 ~58 ~21 ~41 ~58 wool 15
fill ~18 ~41 ~59 ~21 ~41 ~59 wool 15
fill ~18 ~41 ~71 ~41 ~41 ~71 wool 15
fill ~18 ~41 ~72 ~40 ~41 ~72 wool 15
fill ~18 ~41 ~73 ~40 ~41 ~73 wool 15
fill ~19 ~41 ~39 ~26 ~41 ~39 wool 0
fill ~19 ~41 ~54 ~24 ~41 ~54 wool 15
fill ~20 ~41 ~38 ~39 ~41 ~38 wool 0
fill ~20 ~41 ~48 ~22 ~41 ~48 wool 15
fill ~20 ~41 ~74 ~25 ~41 ~74 wool 15
fill ~21 ~41 ~37 ~37 ~41 ~37 wool 0
fill ~21 ~41 ~47 ~22 ~41 ~47 wool 15
fill ~22 ~41 ~36 ~36 ~41 ~36 wool 0
fill ~22 ~41 ~43 ~35 ~41 ~43 stone 0
fill ~22 ~41 ~44 ~35 ~41 ~44 stone 0
fill ~22 ~41 ~45 ~22 ~41 ~57 wool 15
fill ~23 ~41 ~45 ~35 ~41 ~45 stone 0
fill ~23 ~41 ~46 ~35 ~41 ~46 stone 0
fill ~23 ~41 ~47 ~34 ~41 ~47 stone 0
fill ~23 ~41 ~48 ~34 ~41 ~48 stone 0
fill ~23 ~41 ~56 ~34 ~41 ~56 stone 0
fill ~23 ~41 ~57 ~34 ~41 ~57 stone 0
fill ~23 ~41 ~66 ~25 ~41 ~66 stone 0
fill ~23 ~41 ~67 ~25 ~41 ~67 stone 0
fill ~24 ~41 ~35 ~34 ~41 ~35 wool 0
fill ~24 ~41 ~49 ~34 ~41 ~49 stone 0
fill ~24 ~41 ~63 ~29 ~41 ~63 stone 0
fill ~24 ~41 ~64 ~28 ~41 ~64 stone 0
fill ~24 ~41 ~65 ~26 ~41 ~65 stone 0
fill ~25 ~41 ~42 ~33 ~41 ~42 stone 0
fill ~25 ~41 ~52 ~34 ~41 ~52 stone 0
fill ~25 ~41 ~60 ~34 ~41 ~60 stone 0
fill ~26 ~41 ~34 ~32 ~41 ~34 wool 0
setblock ~26 ~41 ~40 wool 15
fill ~26 ~41 ~41 ~31 ~41 ~41 stone 0
fill ~26 ~41 ~53 ~34 ~41 ~53 stone 0
fill ~26 ~41 ~54 ~34 ~41 ~54 stone 0
fill ~26 ~41 ~55 ~34 ~41 ~55 stone 0
fill ~26 ~41 ~58 ~34 ~41 ~58 stone 0
fill ~26 ~41 ~59 ~34 ~41 ~59 stone 0
fill ~26 ~41 ~66 ~33 ~41 ~66 wool 15
fill ~26 ~41 ~67 ~41 ~41 ~67 wool 15
fill ~27 ~41 ~39 ~27 ~41 ~64 stone 0
fill ~28 ~41 ~33 ~30 ~41 ~33 wool 0
fill ~28 ~41 ~39 ~40 ~41 ~39 wool 0
setblock ~28 ~41 ~40 stone 0
fill ~28 ~41 ~50 ~35 ~41 ~50 stone 0
fill ~28 ~41 ~51 ~35 ~41 ~51 stone 0
fill ~28 ~41 ~61 ~35 ~41 ~61 stone 0
fill ~28 ~41 ~62 ~35 ~41 ~62 stone 0
fill ~28 ~41 ~74 ~30 ~41 ~74 wool 15
fill ~29 ~41 ~40 ~30 ~41 ~40 wool 15
fill ~29 ~41 ~64 ~33 ~41 ~64 wool 15
fill ~30 ~41 ~63 ~32 ~41 ~63 wool 15
fill ~31 ~41 ~40 ~40 ~41 ~40 wool 0
fill ~32 ~41 ~41 ~41 ~41 ~41 wool 0
fill ~33 ~41 ~63 ~35 ~41 ~63 stone 0
fill ~33 ~41 ~74 ~39 ~41 ~74 wool 15
fill ~34 ~41 ~42 ~41 ~41 ~42 wool 0
fill ~34 ~41 ~64 ~34 ~69 ~64 stone 0
fill ~34 ~41 ~65 ~34 ~73 ~65 stone 0
fill ~34 ~41 ~66 ~34 ~73 ~66 stone 0
fill ~35 ~41 ~47 ~38 ~41 ~47 wool 15
fill ~35 ~41 ~48 ~39 ~41 ~48 wool 15
fill ~35 ~41 ~49 ~42 ~41 ~49 wool 15
fill ~35 ~41 ~52 ~41 ~41 ~52 wool 15
fill ~35 ~41 ~53 ~40 ~41 ~53 wool 15
fill ~35 ~41 ~54 ~40 ~41 ~54 wool 15
fill ~35 ~41 ~55 ~40 ~41 ~55 wool 15
fill ~35 ~41 ~56 ~40 ~41 ~56 wool 15
fill ~35 ~41 ~57 ~40 ~41 ~57 wool 15
fill ~35 ~41 ~58 ~40 ~41 ~58 wool 15
fill ~35 ~41 ~59 ~40 ~41 ~59 wool 15
fill ~35 ~41 ~60 ~35 ~42 ~60 wool 15
fill ~36 ~41 ~43 ~41 ~41 ~43 wool 0
setblock ~36 ~41 ~44 wool 15
fill ~36 ~41 ~50 ~42 ~41 ~50 wool 15
fill ~36 ~41 ~51 ~42 ~41 ~51 wool 15
fill ~36 ~41 ~61 ~40 ~41 ~61 wool 15
fill ~36 ~41 ~62 ~41 ~41 ~62 wool 15
fill ~36 ~41 ~63 ~41 ~41 ~63 wool 15
fill ~36 ~41 ~64 ~41 ~41 ~64 wool 15
fill ~36 ~41 ~66 ~41 ~41 ~66 wool 15
fill ~37 ~41 ~44 ~41 ~41 ~44 wool 0
fill ~37 ~41 ~45 ~42 ~41 ~45 wool 0
fill ~37 ~41 ~46 ~37 ~42 ~46 wool 15
fill ~37 ~41 ~65 ~41 ~41 ~65 wool 15
fill ~39 ~41 ~47 ~42 ~41 ~47 wool 0
fill ~42 ~41 ~46 ~42 ~48 ~46 wool 0
fill ~16 ~42 ~48 ~16 ~45 ~48 wool 15
fill ~16 ~42 ~49 ~16 ~44 ~49 wool 15
fill ~16 ~42 ~50 ~23 ~42 ~50 wool 15
fill ~16 ~42 ~51 ~24 ~42 ~51 wool 15
fill ~16 ~42 ~52 ~24 ~42 ~52 wool 15
fill ~16 ~42 ~53 ~24 ~42 ~53 wool 15
fill ~16 ~42 ~54 ~23 ~42 ~54 wool 15
fill ~17 ~42 ~43 ~23 ~42 ~43 wool 0
fill ~17 ~42 ~44 ~22 ~42 ~44 wool 0
fill ~17 ~42 ~45 ~22 ~42 ~45 wool 0
fill ~17 ~42 ~47 ~21 ~42 ~47 wool 0
fill ~17 ~42 ~48 ~20 ~42 ~48 wool 0
fill ~17 ~42 ~49 ~18 ~42 ~49 wool 0
fill ~17 ~42 ~55 ~23 ~42 ~55 wool 15
fill ~17 ~42 ~66 ~23 ~42 ~66 wool 15
fill ~17 ~42 ~67 ~23 ~42 ~67 wool 15
fill ~17 ~42 ~68 ~41 ~42 ~68 wool 15
fill ~17 ~42 ~69 ~41 ~42 ~69 wool 15
fill ~18 ~42 ~40 ~26 ~42 ~40 wool 0
fill ~18 ~42 ~41 ~25 ~42 ~41 wool 0
fill ~18 ~42 ~42 ~18 ~43 ~42 wool 0
fill ~18 ~42 ~56 ~22 ~42 ~56 wool 15
fill ~18 ~42 ~58 ~21 ~42 ~58 wool 15
fill ~18 ~42 ~59 ~21 ~42 ~59 wool 15
fill ~18 ~42 ~70 ~41 ~42 ~70 wool 15
fill ~18 ~42 ~71 ~41 ~42 ~71 wool 15
fill ~18 ~42 ~72 ~40 ~42 ~72 wool 15
fill ~18 ~42 ~73 ~40 ~42 ~73 wool 15
fill ~19 ~42 ~39 ~39 ~42 ~39 wool 0
fill ~19 ~42 ~49 ~23 ~42 ~49 wool 15
fill ~19 ~42 ~74 ~40 ~42 ~74 wool 15
fill ~20 ~42 ~38 ~38 ~42 ~38 wool 0
fill ~20 ~42 ~75 ~25 ~42 ~75 wool 15
fill ~21 ~42 ~48 ~22 ~42 ~48 wool 15
fill ~22 ~42 ~37 ~37 ~42 ~37 wool 0
fill ~22 ~42 ~46 ~22 ~42 ~57 wool 15
fill ~23 ~42 ~42 ~25 ~42 ~42 wool 0
fill ~23 ~42 ~44 ~35 ~42 ~44 stone 0
fill ~23 ~42 ~45 ~35 ~42 ~45 stone 0
fill ~23 ~42 ~46 ~35 ~42 ~46 stone 0
fill ~23 ~42 ~47 ~35 ~42 ~47 stone 0
fill ~23 ~42 ~48 ~35 ~42 ~48 stone 0
fill ~23 ~42 ~56 ~34 ~42 ~56 stone 0
fill ~23 ~42 ~57 ~34 ~42 ~57 stone 0
fill ~24 ~42 ~36 ~33 ~42 ~36 wool 0
fill ~24 ~42 ~43 ~34 ~42 ~43 stone 0
fill ~24 ~42 ~49 ~35 ~42 ~49 stone 0
fill ~24 ~42 ~50 ~24 ~52 ~50 stone 0
fill ~24 ~42 ~54 ~24 ~59 ~54 stone 0
fill ~24 ~42 ~63 ~34 ~42 ~63 stone 0
fill ~24 ~42 ~64 ~34 ~42 ~64 stone 0
fill ~24 ~42 ~65 ~35 ~42 ~65 stone 0
fill ~24 ~42 ~66 ~27 ~42 ~66 stone 0
fill ~24 ~42 ~67 ~26 ~42 ~67 stone 0
fill ~25 ~42 ~52 ~34 ~42 ~52 stone 0
fill ~25 ~42 ~60 ~34 ~42 ~60 stone 0
fill ~26 ~42 ~35 ~33 ~42 ~35 wool 0
setblock ~26 ~42 ~41 wool 15
fill ~26 ~42 ~42 ~32 ~42 ~42 stone 0
fill ~26 ~42 ~53 ~34 ~42 ~53 stone 0
fill ~26 ~42 ~54 ~34 ~42 ~54 stone 0
fill ~26 ~42 ~55 ~34 ~42 ~55 stone 0
fill ~26 ~42 ~58 ~34 ~42 ~58 stone 0
fill ~26 ~42 ~59 ~34 ~42 ~59 stone 0
fill ~27 ~42 ~34 ~31 ~42 ~34 wool 0
fill ~27 ~42 ~40 ~27 ~42 ~66 stone 0
fill ~27 ~42 ~67 ~31 ~42 ~67 wool 15
fill ~27 ~42 ~75 ~31 ~42 ~75 wool 15
fill ~28 ~42 ~40 ~40 ~42 ~40 wool 0
fill ~28 ~42 ~41 ~29 ~42 ~41 stone 0
fill ~28 ~42 ~50 ~35 ~42 ~50 stone 0
fill ~28 ~42 ~51 ~35 ~42 ~51 stone 0
fill ~28 ~42 ~61 ~35 ~42 ~61 stone 0
fill ~28 ~42 ~62 ~34 ~42 ~62 stone 0
fill ~28 ~42 ~66 ~30 ~42 ~66 wool 15
fill ~29 ~42 ~76 ~29 ~48 ~76 wool 15
setblock ~30 ~42 ~41 wool 15
fill ~31 ~42 ~41 ~40 ~42 ~41 wool 0
fill ~31 ~42 ~66 ~35 ~42 ~66 stone 0
fill ~32 ~42 ~67 ~35 ~42 ~67 stone 0
fill ~33 ~42 ~42 ~41 ~42 ~42 wool 0
fill ~33 ~42 ~75 ~38 ~42 ~75 wool 15
setblock ~34 ~42 ~36 wool 15
setblock ~35 ~42 ~36 wool 0
fill ~35 ~42 ~43 ~41 ~42 ~43 wool 0
fill ~35 ~42 ~52 ~42 ~42 ~52 wool 15
fill ~35 ~42 ~53 ~42 ~42 ~53 wool 15
fill ~35 ~42 ~54 ~42 ~42 ~54 wool 15
fill ~35 ~42 ~55 ~41 ~42 ~55 wool 15
fill ~35 ~42 ~56 ~40 ~42 ~56 wool 15
fill ~35 ~42 ~57 ~40 ~42 ~57 wool 15
fill ~35 ~42 ~58 ~40 ~42 ~58 wool 15
fill ~35 ~42 ~59 ~40 ~42 ~59 wool 15
fill ~35 ~42 ~62 ~40 ~42 ~62 wool 15
fill ~35 ~42 ~63 ~40 ~42 ~63 wool 15
fill ~35 ~42 ~64 ~41 ~42 ~64 wool 15
fill ~36 ~42 ~44 ~41 ~42 ~44 wool 0
fill ~36 ~42 ~47 ~37 ~42 ~47 wool 15
fill ~36 ~42 ~48 ~38 ~42 ~48 wool 15
fill ~36 ~42 ~49 ~39 ~42 ~49 wool 15
fill ~36 ~42 ~50 ~42 ~42 ~50 wool 15
fill ~36 ~42 ~51 ~42 ~42 ~51 wool 15
fill ~36 ~42 ~61 ~40 ~42 ~61 wool 15
fill ~36 ~42 ~66 ~41 ~42 ~66 wool 15
fill ~36 ~42 ~67 ~41 ~42 ~67 wool 15
fill ~37 ~42 ~45 ~42 ~42 ~45 wool 0
fill ~37 ~42 ~65 ~41 ~42 ~65 wool 15
fill ~38 ~42 ~47 ~42 ~42 ~47 wool 0
fill ~39 ~42 ~48 ~39 ~48 ~48 wool 0
fill ~40 ~42 ~49 ~41 ~42 ~49 wool 0
fill ~42 ~42 ~49 ~42 ~43 ~49 wool 15
fill ~15 ~43 ~53 ~23 ~43 ~53 wool 15
fill ~15 ~43 ~54 ~23 ~43 ~54 wool 15
fill ~15 ~43 ~55 ~22 ~43 ~55 wool 15
fill ~16 ~43 ~47 ~16 ~46 ~47 wool 15
fill ~16 ~43 ~50 ~23 ~43 ~50 wool 15
fill ~16 ~43 ~51 ~23 ~43 ~51 wool 15
fill ~16 ~43 ~52 ~23 ~43 ~52 wool 15
fill ~16 ~43 ~56 ~22 ~43 ~56 wool 15
fill ~17 ~43 ~43 ~24 ~43 ~43 wool 0
fill ~17 ~43 ~44 ~23 ~43 ~44 wool 0
fill ~17 ~43 ~45 ~22 ~43 ~45 wool 0
fill ~17 ~43 ~47 ~21 ~43 ~47 wool 0
fill ~17 ~43 ~48 ~20 ~43 ~48 wool 0
fill ~17 ~43 ~49 ~19 ~43 ~49 wool 0
fill ~17 ~43 ~57 ~17 ~69 ~57 wool 15
fill ~17 ~43 ~67 ~23 ~43 ~67 wool 15
fill ~17 ~43 ~68 ~23 ~43 ~68 wool 15
fill ~18 ~43 ~41 ~26 ~43 ~41 wool 0
fill ~18 ~43 ~58 ~21 ~43 ~58 wool 15
fill ~18 ~43 ~59 ~21 ~43 ~59 wool 15
fill ~18 ~43 ~66 ~23 ~43 ~66 wool 15
fill ~18 ~43 ~69 ~41 ~43 ~69 wool 15
fill ~18 ~43 ~70 ~41 ~43 ~70 wool 15
fill ~18 ~43 ~71 ~41 ~43 ~71 wool 15
fill ~18 ~43 ~72 ~41 ~43 ~72 wool 15
fill ~18 ~43 ~73 ~40 ~43 ~73 wool 15
fill ~19 ~43 ~40 ~39 ~43 ~40 wool 0
fill ~19 ~43 ~74 ~40 ~43 ~74 wool 15
fill ~19 ~43 ~75 ~39 ~43 ~75 wool 15
fill ~20 ~43 ~39 ~38 ~43 ~39 wool 0
fill ~20 ~43 ~49 ~22 ~43 ~49 wool 15
fill ~21 ~43 ~38 ~37 ~43 ~38 wool 0
fill ~21 ~43 ~48 ~22 ~43 ~48 wool 15
fill ~21 ~43 ~76 ~22 ~43 ~76 wool 15
fill ~22 ~43 ~46 ~22 ~45 ~46 wool 0
fill ~22 ~43 ~47 ~22 ~45 ~47 wool 15
setblock ~22 ~43 ~57 wool 15
fill ~23 ~43 ~37 ~34 ~43 ~37 wool 0
fill ~23 ~43 ~42 ~25 ~43 ~42 wool 0
fill ~23 ~43 ~45 ~35 ~43 ~45 stone 0
fill ~23 ~43 ~46 ~36 ~43 ~46 stone 0
fill ~23 ~43 ~47 ~36 ~43 ~47 stone 0
fill ~23 ~43 ~48 ~36 ~43 ~48 stone 0
fill ~23 ~43 ~49 ~36 ~43 ~49 stone 0
fill ~23 ~43 ~55 ~23 ~60 ~55 stone 0
fill ~23 ~43 ~56 ~35 ~43 ~56 stone 0
fill ~23 ~43 ~57 ~34 ~43 ~57 stone 0
fill ~23 ~43 ~61 ~23 ~65 ~61 stone 0
fill ~24 ~43 ~44 ~34 ~43 ~44 stone 0
fill ~24 ~43 ~51 ~24 ~53 ~51 stone 0
fill ~24 ~43 ~52 ~35 ~43 ~52 stone 0
fill ~24 ~43 ~53 ~24 ~57 ~53 stone 0
fill ~24 ~43 ~63 ~34 ~43 ~63 stone 0
fill ~24 ~43 ~64 ~34 ~43 ~64 stone 0
fill ~24 ~43 ~65 ~34 ~43 ~65 stone 0
fill ~24 ~43 ~66 ~34 ~43 ~66 stone 0
fill ~24 ~43 ~67 ~35 ~43 ~67 stone 0
fill ~24 ~43 ~68 ~27 ~43 ~68 stone 0
fill ~25 ~43 ~36 ~33 ~43 ~36 wool 0
setblock ~25 ~43 ~43 stone 0
fill ~25 ~43 ~60 ~35 ~43 ~60 stone 0
fill ~26 ~43 ~42 ~29 ~43 ~42 stone 0
fill ~26 ~43 ~53 ~34 ~43 ~53 stone 0
fill ~26 ~43 ~54 ~34 ~43 ~54 stone 0
fill ~26 ~43 ~55 ~34 ~43 ~55 stone 0
fill ~26 ~43 ~58 ~34 ~43 ~58 stone 0
fill ~26 ~43 ~59 ~34 ~43 ~59 stone 0
fill ~27 ~43 ~35 ~31 ~43 ~35 wool 0
fill ~27 ~43 ~41 ~28 ~43 ~41 stone 0
fill ~27 ~43 ~43 ~34 ~43 ~43 stone 0
fill ~27 ~43 ~50 ~36 ~43 ~50 stone 0
fill ~27 ~43 ~51 ~35 ~43 ~51 stone 0
fill ~27 ~43 ~61 ~34 ~43 ~61 stone 0
fill ~27 ~43 ~62 ~34 ~43 ~62 stone 0
fill ~27 ~43 ~76 ~32 ~43 ~76 wool 15
fill ~28 ~43 ~68 ~30 ~43 ~68 wool 15
fill ~28 ~43 ~77 ~30 ~43 ~77 wool 15
fill ~29 ~43 ~41 ~40 ~43 ~41 wool 0
fill ~30 ~43 ~42 ~31 ~43 ~42 wool 15
fill ~31 ~43 ~68 ~35 ~43 ~68 stone 0
fill ~32 ~43 ~42 ~40 ~43 ~42 wool 0
setblock ~35 ~43 ~37 wool 15
fill ~35 ~43 ~43 ~41 ~43 ~43 wool 0
fill ~35 ~43 ~44 ~41 ~43 ~44 wool 0
fill ~35 ~43 ~53 ~43 ~43 ~53 wool 15
fill ~35 ~43 ~54 ~43 ~43 ~54 wool 15
fill ~35 ~43 ~55 ~43 ~43 ~55 wool 15
fill ~35 ~43 ~57 ~41 ~43 ~57 wool 15
fill ~35 ~43 ~58 ~41 ~43 ~58 wool 15
fill ~35 ~43 ~59 ~40 ~43 ~59 wool 15
fill ~35 ~43 ~61 ~40 ~43 ~61 wool 15
fill ~35 ~43 ~62 ~40 ~43 ~62 wool 15
fill ~35 ~43 ~63 ~40 ~43 ~63 wool 15
fill ~35 ~43 ~64 ~40 ~43 ~64 wool 15
fill ~35 ~43 ~65 ~35 ~47 ~65 wool 15
fill ~35 ~43 ~66 ~41 ~43 ~66 wool 15
fill ~36 ~43 ~45 ~42 ~43 ~45 wool 0
fill ~36 ~43 ~51 ~43 ~43 ~51 wool 15
fill ~36 ~43 ~52 ~43 ~43 ~52 wool 15
fill ~36 ~43 ~56 ~42 ~43 ~56 wool 15
fill ~36 ~43 ~67 ~41 ~43 ~67 wool 15
fill ~36 ~43 ~68 ~41 ~43 ~68 wool 15
fill ~36 ~43 ~76 ~37 ~43 ~76 wool 15
fill ~37 ~43 ~46 ~37 ~47 ~46 wool 0
fill ~37 ~43 ~47 ~37 ~43 ~76 wool 15
fill ~38 ~43 ~47 ~42 ~43 ~47 wool 0
fill ~38 ~43 ~48 ~38 ~47 ~48 wool 0
fill ~38 ~43 ~49 ~38 ~44 ~49 wool 15
fill ~38 ~43 ~50 ~40 ~43 ~50 wool 15
fill ~38 ~43 ~65 ~38 ~50 ~65 wool 15
fill ~39 ~43 ~49 ~41 ~43 ~49 wool 0
fill ~40 ~43 ~65 ~41 ~43 ~65 wool 15
fill ~41 ~43 ~50 ~41 ~47 ~50 wool 0
setblock ~42 ~43 ~50 wool 15
fill ~15 ~44 ~50 ~22 ~44 ~50 wool 15
fill ~15 ~44 ~51 ~22 ~44 ~51 wool 15
fill ~15 ~44 ~52 ~22 ~44 ~52 wool 15
fill ~15 ~44 ~53 ~22 ~44 ~53 wool 15
fill ~15 ~44 ~54 ~22 ~44 ~54 wool 15
fill ~15 ~44 ~55 ~22 ~44 ~55 wool 15
fill ~15 ~44 ~56 ~22 ~44 ~56 wool 15
fill ~15 ~44 ~57 ~21 ~44 ~57 wool 15
fill ~16 ~44 ~58 ~21 ~44 ~58 wool 15
fill ~17 ~44 ~44 ~24 ~44 ~44 wool 0
fill ~17 ~44 ~45 ~22 ~44 ~45 wool 0
fill ~17 ~44 ~47 ~21 ~44 ~47 wool 0
fill ~17 ~44 ~48 ~20 ~44 ~48 wool 0
fill ~17 ~44 ~49 ~19 ~44 ~49 wool 0
fill ~17 ~44 ~59 ~21 ~44 ~59 wool 15
fill ~18 ~44 ~42 ~18 ~44 ~43 wool 15
fill ~18 ~44 ~66 ~23 ~44 ~66 wool 15
fill ~18 ~44 ~67 ~23 ~44 ~67 wool 15
fill ~18 ~44 ~68 ~23 ~44 ~68 wool 15
fill ~18 ~44 ~69 ~23 ~44 ~69 wool 15
fill ~18 ~44 ~70 ~26 ~44 ~70 wool 15
fill ~18 ~44 ~71 ~41 ~44 ~71 wool 15
fill ~18 ~44 ~72 ~40 ~44 ~72 wool 15
fill ~18 ~44 ~73 ~40 ~44 ~73 wool 15
fill ~18 ~44 ~74 ~40 ~44 ~74 wool 15
fill ~19 ~44 ~41 ~26 ~44 ~41 wool 0
fill ~19 ~44 ~43 ~25 ~44 ~43 wool 0
fill ~19 ~44 ~75 ~39 ~44 ~75 wool 15
fill ~20 ~44 ~40 ~39 ~44 ~40 wool 0
fill ~20 ~44 ~49 ~21 ~44 ~49 wool 15
fill ~20 ~44 ~76 ~38 ~44 ~76 wool 15
fill ~21 ~44 ~39 ~37 ~44 ~39 wool 0
fill ~21 ~44 ~48 ~22 ~44 ~48 wool 15
setblock ~22 ~44 ~38 wool 0
fill ~22 ~44 ~49 ~37 ~44 ~49 stone 0
fill ~22 ~44 ~57 ~35 ~44 ~57 stone 0
fill ~22 ~44 ~60 ~22 ~64 ~60 stone 0
fill ~23 ~44 ~42 ~25 ~44 ~42 wool 0
setblock ~23 ~44 ~45 wool 15
fill ~23 ~44 ~46 ~36 ~44 ~46 stone 0
fill ~23 ~44 ~47 ~37 ~44 ~47 stone 0
fill ~23 ~44 ~48 ~37 ~44 ~48 stone 0
fill ~23 ~44 ~50 ~23 ~52 ~50 stone 0
fill ~23 ~44 ~51 ~23 ~53 ~51 stone 0
fill ~23 ~44 ~52 ~35 ~44 ~52 stone 0
fill ~23 ~44 ~53 ~23 ~57 ~53 stone 0
fill ~23 ~44 ~54 ~23 ~59 ~54 stone 0
fill ~23 ~44 ~56 ~35 ~44 ~56 stone 0
fill ~23 ~44 ~62 ~23 ~66 ~62 stone 0
fill ~23 ~44 ~63 ~34 ~44 ~63 stone 0
fill ~23 ~44 ~64 ~34 ~44 ~64 stone 0
fill ~24 ~44 ~45 ~35 ~44 ~45 stone 0
fill ~24 ~44 ~65 ~34 ~44 ~65 stone 0
fill ~24 ~44 ~66 ~34 ~44 ~66 stone 0
fill ~24 ~44 ~67 ~34 ~44 ~67 stone 0
fill ~24 ~44 ~68 ~34 ~44 ~68 stone 0
fill ~24 ~44 ~69 ~34 ~44 ~69 stone 0
fill ~25 ~44 ~37 ~32 ~44 ~37 wool 0
fill ~25 ~44 ~44 ~34 ~44 ~44 stone 0
fill ~25 ~44 ~60 ~35 ~44 ~60 stone 0
fill ~26 ~44 ~38 ~36 ~44 ~38 wool 0
fill ~26 ~44 ~42 ~28 ~44 ~42 stone 0
fill ~26 ~44 ~53 ~35 ~44 ~53 stone 0
fill ~26 ~44 ~54 ~35 ~44 ~54 stone 0
fill ~26 ~44 ~55 ~35 ~44 ~55 stone 0
fill ~26 ~44 ~58 ~35 ~44 ~58 stone 0
fill ~26 ~44 ~59 ~35 ~44 ~59 stone 0
fill ~26 ~44 ~77 ~33 ~44 ~77 wool 15
fill ~27 ~44 ~36 ~30 ~44 ~36 wool 0
fill ~27 ~44 ~41 ~27 ~46 ~41 stone 0
fill ~27 ~44 ~43 ~30 ~44 ~43 stone 0
fill ~27 ~44 ~50 ~36 ~44 ~50 stone 0
fill ~27 ~44 ~51 ~36 ~44 ~51 stone 0
fill ~27 ~44 ~61 ~34 ~44 ~61 stone 0
fill ~27 ~44 ~62 ~34 ~44 ~62 stone 0
fill ~27 ~44 ~70 ~31 ~44 ~70 stone 0
fill ~28 ~44 ~41 ~40 ~44 ~41 wool 0
fill ~28 ~44 ~78 ~31 ~44 ~78 wool 15
setblock ~29 ~44 ~35 wool 0
fill ~29 ~44 ~42 ~29 ~49 ~42 wool 0
fill ~30 ~44 ~42 ~31 ~44 ~42 wool 15
setblock ~31 ~44 ~36 wool 15
fill ~31 ~44 ~43 ~33 ~44 ~43 wool 15
fill ~32 ~44 ~42 ~40 ~44 ~42 wool 0
fill ~32 ~44 ~70 ~41 ~44 ~70 wool 15
fill ~33 ~44 ~37 ~34 ~44 ~37 wool 15
fill ~34 ~44 ~43 ~41 ~44 ~43 wool 0
fill ~35 ~44 ~44 ~41 ~44 ~44 wool 0
fill ~35 ~44 ~61 ~40 ~44 ~61 wool 15
fill ~35 ~44 ~62 ~40 ~44 ~62 wool 15
fill ~35 ~44 ~63 ~40 ~44 ~63 wool 15
fill ~35 ~44 ~64 ~40 ~44 ~64 wool 15
fill ~35 ~44 ~66 ~40 ~44 ~66 wool 15
fill ~35 ~44 ~67 ~41 ~44 ~67 wool 15
fill ~35 ~44 ~68 ~41 ~44 ~68 wool 15
fill ~35 ~44 ~69 ~41 ~44 ~69 wool 15
fill ~36 ~44 ~45 ~41 ~44 ~45 wool 0
fill ~36 ~44 ~52 ~43 ~44 ~52 wool 15
fill ~36 ~44 ~53 ~43 ~44 ~53 wool 15
fill ~36 ~44 ~54 ~43 ~44 ~54 wool 15
fill ~36 ~44 ~55 ~44 ~44 ~55 wool 15
fill ~36 ~44 ~56 ~44 ~44 ~56 wool 15
fill ~36 ~44 ~57 ~43 ~44 ~57 wool 15
fill ~36 ~44 ~58 ~42 ~44 ~58 wool 15
fill ~36 ~44 ~59 ~42 ~44 ~59 wool 15
fill ~37 ~44 ~50 ~39 ~44 ~50 wool 15
fill ~37 ~44 ~51 ~43 ~44 ~51 wool 15
fill ~37 ~44 ~65 ~37 ~50 ~65 wool 15
setblock ~38 ~44 ~39 wool 15
fill ~38 ~44 ~47 ~42 ~44 ~47 wool 0
fill ~39 ~44 ~49 ~42 ~44 ~49 wool 0
fill ~40 ~44 ~50 ~40 ~46 ~50 wool 0
fill ~40 ~44 ~65 ~40 ~51 ~65 wool 15
fill ~41 ~44 ~60 ~41 ~53 ~60 wool 15
fill ~42 ~44 ~48 ~42 ~49 ~48 wool 0
fill ~42 ~44 ~50 ~42 ~47 ~50 wool 0
fill ~43 ~44 ~49 ~43 ~47 ~49 wool 15
fill ~43 ~44 ~50 ~43 ~46 ~50 wool 15
fill ~14 ~45 ~53 ~21 ~45 ~53 wool 15
fill ~14 ~45 ~54 ~21 ~45 ~54 wool 15
fill ~14 ~45 ~55 ~21 ~45 ~55 wool 15
fill ~14 ~45 ~56 ~21 ~45 ~56 wool 15
fill ~14 ~45 ~57 ~21 ~45 ~57 wool 15
fill ~15 ~45 ~49 ~15 ~51 ~49 wool 15
fill ~15 ~45 ~50 ~20 ~45 ~50 wool 15
fill ~15 ~45 ~51 ~21 ~45 ~51 wool 15
fill ~15 ~45 ~52 ~21 ~45 ~52 wool 15
fill ~15 ~45 ~58 ~21 ~45 ~58 wool 15
fill ~16 ~45 ~46 ~16 ~48 ~46 wool 15
fill ~16 ~45 ~49 ~19 ~45 ~49 wool 0
fill ~16 ~45 ~59 ~21 ~45 ~59 wool 15
fill ~16 ~45 ~60 ~21 ~45 ~60 wool 15
setblock ~17 ~45 ~44 wool 15
fill ~17 ~45 ~45 ~23 ~45 ~45 wool 0
fill ~17 ~45 ~47 ~21 ~45 ~47 wool 0
fill ~17 ~45 ~48 ~20 ~45 ~48 wool 0
fill ~17 ~45 ~61 ~17 ~52 ~61 wool 15
fill ~18 ~45 ~43 ~18 ~46 ~43 wool 15
fill ~18 ~45 ~44 ~25 ~45 ~44 wool 0
fill ~18 ~45 ~66 ~23 ~45 ~66 wool 15
fill ~18 ~45 ~67 ~23 ~45 ~67 wool 15
fill ~18 ~45 ~68 ~23 ~45 ~68 wool 15
fill ~18 ~45 ~69 ~23 ~45 ~69 wool 15
fill ~18 ~45 ~70 ~23 ~45 ~70 wool 15
fill ~18 ~45 ~71 ~40 ~45 ~71 wool 15
fill ~18 ~45 ~72 ~40 ~45 ~72 wool 15
fill ~18 ~45 ~73 ~40 ~45 ~73 wool 15
fill ~18 ~45 ~74 ~40 ~45 ~74 wool 15
fill ~19 ~45 ~41 ~26 ~45 ~41 wool 0
fill ~19 ~45 ~43 ~25 ~45 ~43 wool 0
fill ~19 ~45 ~75 ~40 ~45 ~75 wool 15
fill ~19 ~45 ~76 ~39 ~45 ~76 wool 15
setblock ~20 ~45 ~40 wool 15
fill ~20 ~45 ~49 ~21 ~45 ~49 wool 15
fill ~21 ~45 ~40 ~37 ~45 ~40 wool 0
fill ~21 ~45 ~48 ~21 ~58 ~48 wool 15
fill ~21 ~45 ~50 ~37 ~45 ~50 stone 0
fill ~21 ~45 ~77 ~37 ~45 ~77 wool 15
setblock ~22 ~45 ~39 wool 0
fill ~22 ~45 ~48 ~37 ~45 ~48 stone 0
fill ~22 ~45 ~49 ~38 ~45 ~49 stone 0
fill ~22 ~45 ~51 ~22 ~54 ~51 stone 0
fill ~22 ~45 ~52 ~36 ~45 ~52 stone 0
fill ~22 ~45 ~53 ~22 ~58 ~53 stone 0
fill ~22 ~45 ~54 ~22 ~59 ~54 stone 0
fill ~22 ~45 ~55 ~22 ~61 ~55 stone 0
fill ~22 ~45 ~56 ~36 ~45 ~56 stone 0
fill ~22 ~45 ~57 ~36 ~45 ~57 stone 0
fill ~22 ~45 ~61 ~22 ~65 ~61 stone 0
fill ~22 ~45 ~62 ~22 ~66 ~62 stone 0
fill ~22 ~45 ~63 ~34 ~45 ~63 stone 0
fill ~23 ~45 ~42 ~26 ~45 ~42 wool 0
fill ~23 ~45 ~46 ~36 ~45 ~46 stone 0
fill ~23 ~45 ~47 ~36 ~45 ~47 stone 0
fill ~23 ~45 ~64 ~34 ~45 ~64 stone 0
setblock ~24 ~45 ~45 wool 15
fill ~24 ~45 ~65 ~34 ~45 ~65 stone 0
fill ~24 ~45 ~66 ~34 ~45 ~66 stone 0
fill ~24 ~45 ~67 ~34 ~45 ~67 stone 0
fill ~24 ~45 ~68 ~34 ~45 ~68 stone 0
fill ~24 ~45 ~69 ~34 ~45 ~69 stone 0
fill ~24 ~45 ~70 ~34 ~45 ~70 stone 0
fill ~25 ~45 ~38 ~25 ~46 ~38 wool 15
fill ~25 ~45 ~39 ~37 ~45 ~39 wool 0
fill ~25 ~45 ~45 ~35 ~45 ~45 stone 0
fill ~25 ~45 ~60 ~35 ~45 ~60 stone 0
fill ~25 ~45 ~78 ~33 ~45 ~78 wool 15
fill ~26 ~45 ~37 ~30 ~45 ~37 wool 0
fill ~26 ~45 ~38 ~32 ~45 ~38 wool 0
fill ~26 ~45 ~44 ~34 ~45 ~44 stone 0
fill ~26 ~45 ~53 ~36 ~45 ~53 stone 0
fill ~26 ~45 ~54 ~36 ~45 ~54 stone 0
fill ~26 ~45 ~55 ~36 ~45 ~55 stone 0
fill ~26 ~45 ~58 ~36 ~45 ~58 stone 0
fill ~26 ~45 ~59 ~36 ~45 ~59 stone 0
fill ~27 ~45 ~42 ~28 ~45 ~42 stone 0
fill ~27 ~45 ~43 ~29 ~45 ~43 stone 0
fill ~27 ~45 ~51 ~36 ~45 ~51 stone 0
fill ~27 ~45 ~61 ~34 ~45 ~61 stone 0
fill ~27 ~45 ~62 ~34 ~45 ~62 stone 0
fill ~27 ~45 ~79 ~31 ~45 ~79 wool 15
fill ~28 ~45 ~41 ~39 ~45 ~41 wool 0
setblock ~29 ~45 ~36 wool 0
fill ~29 ~45 ~80 ~29 ~52 ~80 wool 15
setblock ~30 ~45 ~36 wool 15
fill ~30 ~45 ~42 ~30 ~47 ~42 wool 0
fill ~30 ~45 ~43 ~33 ~45 ~43 wool 15
fill ~31 ~45 ~37 ~31 ~46 ~37 wool 15
fill ~31 ~45 ~42 ~31 ~53 ~42 wool 15
setblock ~32 ~45 ~37 wool 0
fill ~32 ~45 ~42 ~39 ~45 ~42 wool 0
fill ~33 ~45 ~38 ~34 ~45 ~38 wool 15
fill ~34 ~45 ~43 ~40 ~45 ~43 wool 0
setblock ~35 ~45 ~38 wool 0
fill ~35 ~45 ~44 ~41 ~45 ~44 wool 0
fill ~35 ~45 ~61 ~42 ~45 ~61 wool 15
fill ~35 ~45 ~62 ~41 ~45 ~62 wool 15
fill ~35 ~45 ~63 ~40 ~45 ~63 wool 15
fill ~35 ~45 ~64 ~40 ~45 ~64 wool 15
fill ~35 ~45 ~66 ~40 ~45 ~66 wool 15
fill ~35 ~45 ~67 ~40 ~45 ~67 wool 15
fill ~35 ~45 ~68 ~40 ~45 ~68 wool 15
fill ~35 ~45 ~69 ~40 ~45 ~69 wool 15
fill ~35 ~45 ~70 ~40 ~45 ~70 wool 15
fill ~36 ~45 ~45 ~42 ~45 ~45 wool 0
fill ~37 ~45 ~47 ~42 ~45 ~47 wool 0
fill ~37 ~45 ~51 ~44 ~45 ~51 wool 15
fill ~37 ~45 ~52 ~44 ~45 ~52 wool 15
fill ~37 ~45 ~53 ~44 ~45 ~53 wool 15
fill ~37 ~45 ~54 ~44 ~45 ~54 wool 15
fill ~37 ~45 ~55 ~44 ~45 ~55 wool 15
fill ~37 ~45 ~56 ~44 ~45 ~56 wool 15
fill ~37 ~45 ~57 ~44 ~45 ~57 wool 15
fill ~37 ~45 ~58 ~43 ~45 ~58 wool 15
fill ~37 ~45 ~59 ~43 ~45 ~59 wool 15
setblock ~38 ~45 ~40 wool 15
fill ~38 ~45 ~50 ~39 ~45 ~50 wool 15
fill ~39 ~45 ~49 ~42 ~45 ~49 wool 0
setblock ~40 ~45 ~42 wool 15
fill ~42 ~45 ~60 ~42 ~71 ~60 wool 15
fill ~43 ~45 ~48 ~43 ~50 ~48 wool 15
fill ~13 ~46 ~58 ~21 ~46 ~58 wool 15
fill ~14 ~46 ~51 ~16 ~46 ~51 wool 15
fill ~14 ~46 ~52 ~19 ~46 ~52 wool 15
fill ~14 ~46 ~53 ~20 ~46 ~53 wool 15
fill ~14 ~46 ~54 ~20 ~46 ~54 wool 15
fill ~14 ~46 ~55 ~20 ~46 ~55 wool 15
fill ~14 ~46 ~56 ~20 ~46 ~56 wool 15
fill ~14 ~46 ~57 ~20 ~46 ~57 wool 15
fill ~14 ~46 ~59 ~21 ~46 ~59 wool 15
fill ~15 ~46 ~48 ~15 ~49 ~48 wool 15
fill ~15 ~46 ~50 ~19 ~46 ~50 wool 15
fill ~15 ~46 ~60 ~21 ~46 ~60 wool 15
fill ~15 ~46 ~61 ~21 ~46 ~61 wool 15
fill ~15 ~46 ~62 ~21 ~46 ~62 wool 15
fill ~16 ~46 ~48 ~20 ~46 ~48 wool 0
fill ~16 ~46 ~49 ~18 ~46 ~49 wool 0
fill ~16 ~46 ~63 ~21 ~46 ~63 wool 15
fill ~17 ~46 ~45 ~17 ~47 ~45 wool 15
fill ~17 ~46 ~47 ~21 ~46 ~47 wool 0
fill ~17 ~46 ~51 ~37 ~46 ~51 stone 0
setblock ~18 ~46 ~44 wool 15
fill ~18 ~46 ~45 ~24 ~46 ~45 wool 0
fill ~18 ~46 ~66 ~23 ~46 ~66 wool 15
fill ~18 ~46 ~67 ~23 ~46 ~67 wool 15
fill ~18 ~46 ~68 ~23 ~46 ~68 wool 15
fill ~18 ~46 ~69 ~23 ~46 ~69 wool 15
fill ~18 ~46 ~70 ~23 ~46 ~70 wool 15
fill ~18 ~46 ~71 ~27 ~46 ~71 wool 15
fill ~18 ~46 ~72 ~40 ~46 ~72 wool 15
fill ~18 ~46 ~73 ~40 ~46 ~73 wool 15
fill ~18 ~46 ~74 ~40 ~46 ~74 wool 15
fill ~18 ~46 ~75 ~40 ~46 ~75 wool 15
fill ~19 ~46 ~43 ~26 ~46 ~43 wool 0
fill ~19 ~46 ~44 ~25 ~46 ~44 wool 0
fill ~19 ~46 ~49 ~20 ~46 ~49 wool 15
fill ~19 ~46 ~76 ~39 ~46 ~76 wool 15
setblock ~20 ~46 ~41 wool 15
fill ~20 ~46 ~50 ~38 ~46 ~50 stone 0
fill ~20 ~46 ~52 ~37 ~46 ~52 stone 0
fill ~20 ~46 ~77 ~39 ~46 ~77 wool 15
fill ~21 ~46 ~40 ~36 ~46 ~40 wool 0
fill ~21 ~46 ~49 ~38 ~46 ~49 stone 0
fill ~21 ~46 ~53 ~21 ~57 ~53 stone 0
fill ~21 ~46 ~54 ~21 ~60 ~54 stone 0
fill ~21 ~46 ~55 ~21 ~62 ~55 stone 0
fill ~21 ~46 ~56 ~37 ~46 ~56 stone 0
fill ~21 ~46 ~57 ~37 ~46 ~57 stone 0
fill ~22 ~46 ~46 ~23 ~46 ~46 wool 15
fill ~22 ~46 ~47 ~36 ~46 ~47 stone 0
fill ~22 ~46 ~48 ~37 ~46 ~48 stone 0
fill ~22 ~46 ~63 ~34 ~46 ~63 stone 0
fill ~22 ~46 ~78 ~37 ~46 ~78 wool 15
fill ~23 ~46 ~41 ~26 ~46 ~41 wool 0
fill ~23 ~46 ~42 ~26 ~46 ~42 wool 0
fill ~23 ~46 ~64 ~34 ~46 ~64 stone 0
fill ~24 ~46 ~46 ~36 ~46 ~46 stone 0
fill ~24 ~46 ~65 ~34 ~46 ~65 stone 0
fill ~24 ~46 ~66 ~34 ~46 ~66 stone 0
fill ~24 ~46 ~67 ~34 ~46 ~67 stone 0
fill ~24 ~46 ~68 ~34 ~46 ~68 stone 0
fill ~24 ~46 ~69 ~34 ~46 ~69 stone 0
fill ~24 ~46 ~70 ~34 ~46 ~70 stone 0
fill ~24 ~46 ~79 ~34 ~46 ~79 wool 15
fill ~25 ~46 ~39 ~33 ~46 ~39 wool 0
fill ~25 ~46 ~45 ~35 ~46 ~45 stone 0
fill ~25 ~46 ~60 ~35 ~46 ~60 stone 0
fill ~26 ~46 ~38 ~26 ~47 ~38 wool 15
fill ~26 ~46 ~44 ~30 ~46 ~44 stone 0
fill ~26 ~46 ~53 ~37 ~46 ~53 stone 0
fill ~26 ~46 ~54 ~37 ~46 ~54 stone 0
fill ~26 ~46 ~55 ~37 ~46 ~55 stone 0
fill ~26 ~46 ~58 ~37 ~46 ~58 stone 0
fill ~26 ~46 ~59 ~36 ~46 ~59 stone 0
fill ~26 ~46 ~80 ~32 ~46 ~80 wool 15
fill ~27 ~46 ~37 ~28 ~46 ~37 wool 0
fill ~27 ~46 ~38 ~32 ~46 ~38 wool 0
fill ~27 ~46 ~42 ~28 ~46 ~42 stone 0
fill ~27 ~46 ~43 ~29 ~46 ~43 stone 0
fill ~27 ~46 ~61 ~35 ~46 ~61 stone 0
fill ~27 ~46 ~62 ~34 ~46 ~62 stone 0
fill ~28 ~46 ~41 ~38 ~46 ~41 wool 0
fill ~28 ~46 ~71 ~34 ~46 ~71 stone 0
fill ~28 ~46 ~81 ~30 ~46 ~81 wool 15
fill ~29 ~46 ~37 ~31 ~46 ~37 wool 15
fill ~30 ~46 ~43 ~33 ~46 ~43 wool 15
fill ~31 ~46 ~44 ~34 ~46 ~44 wool 15
fill ~32 ~46 ~42 ~32 ~52 ~42 wool 15
fill ~33 ~46 ~38 ~33 ~45 ~38 wool 15
fill ~33 ~46 ~42 ~39 ~46 ~42 wool 0
fill ~34 ~46 ~39 ~34 ~47 ~39 wool 15
fill ~34 ~46 ~43 ~39 ~46 ~43 wool 0
setblock ~35 ~46 ~39 wool 0
fill ~35 ~46 ~44 ~40 ~46 ~44 wool 0
fill ~35 ~46 ~62 ~43 ~46 ~62 wool 15
fill ~35 ~46 ~63 ~42 ~46 ~63 wool 15
fill ~35 ~46 ~64 ~40 ~46 ~64 wool 15
fill ~35 ~46 ~66 ~40 ~46 ~66 wool 15
fill ~35 ~46 ~67 ~40 ~46 ~67 wool 15
fill ~35 ~46 ~68 ~40 ~46 ~68 wool 15
fill ~35 ~46 ~69 ~40 ~46 ~69 wool 15
fill ~35 ~46 ~70 ~40 ~46 ~70 wool 15
fill ~35 ~46 ~71 ~40 ~46 ~71 wool 15
fill ~36 ~46 ~45 ~42 ~46 ~45 wool 0
fill ~36 ~46 ~61 ~43 ~46 ~61 wool 15
setblock ~37 ~46 ~40 wool 15
fill ~37 ~46 ~47 ~42 ~46 ~47 wool 0
fill ~37 ~46 ~59 ~44 ~46 ~59 wool 15
fill ~38 ~46 ~51 ~44 ~46 ~51 wool 15
fill ~38 ~46 ~52 ~44 ~46 ~52 wool 15
fill ~38 ~46 ~53 ~44 ~46 ~53 wool 15
fill ~38 ~46 ~54 ~45 ~46 ~54 wool 15
fill ~38 ~46 ~55 ~45 ~46 ~55 wool 15
fill ~38 ~46 ~56 ~45 ~46 ~56 wool 15
fill ~38 ~46 ~57 ~45 ~46 ~57 wool 15
fill ~38 ~46 ~58 ~45 ~46 ~58 wool 15
fill ~39 ~46 ~49 ~42 ~46 ~49 wool 0
fill ~39 ~46 ~50 ~39 ~61 ~50 wool 15
fill ~40 ~46 ~43 ~40 ~47 ~43 wool 15
setblock ~41 ~46 ~44 wool 15
fill ~43 ~46 ~47 ~43 ~48 ~47 wool 15
fill ~43 ~46 ~60 ~43 ~71 ~60 wool 15
fill ~13 ~47 ~54 ~19 ~47 ~54 wool 15
fill ~13 ~47 ~55 ~19 ~47 ~55 wool 15
fill ~13 ~47 ~56 ~19 ~47 ~56 wool 15
fill ~13 ~47 ~57 ~20 ~47 ~57 wool 15
fill ~13 ~47 ~58 ~20 ~47 ~58 wool 15
fill ~13 ~47 ~59 ~21 ~47 ~59 wool 15
fill ~14 ~47 ~51 ~17 ~47 ~51 wool 15
fill ~14 ~47 ~52 ~17 ~47 ~52 wool 15
fill ~14 ~47 ~53 ~18 ~47 ~53 wool 15
fill ~14 ~47 ~60 ~21 ~47 ~60 wool 15
fill ~14 ~47 ~61 ~21 ~47 ~61 wool 15
fill ~14 ~47 ~62 ~20 ~47 ~62 wool 15
fill ~15 ~47 ~47 ~15 ~48 ~47 wool 15
fill ~15 ~47 ~50 ~17 ~47 ~50 wool 15
fill ~15 ~47 ~63 ~21 ~47 ~63 wool 15
fill ~15 ~47 ~64 ~22 ~47 ~64 wool 15
fill ~16 ~47 ~47 ~20 ~47 ~47 wool 0
fill ~16 ~47 ~48 ~19 ~47 ~48 wool 0
fill ~16 ~47 ~49 ~19 ~47 ~49 wool 15
fill ~18 ~47 ~44 ~25 ~47 ~44 wool 0
fill ~18 ~47 ~45 ~24 ~47 ~45 wool 0
fill ~18 ~47 ~50 ~38 ~47 ~50 stone 0
fill ~18 ~47 ~51 ~39 ~47 ~51 stone 0
fill ~18 ~47 ~52 ~38 ~47 ~52 stone 0
fill ~18 ~47 ~66 ~23 ~47 ~66 wool 15
fill ~18 ~47 ~67 ~23 ~47 ~67 wool 15
fill ~18 ~47 ~68 ~23 ~47 ~68 wool 15
fill ~18 ~47 ~69 ~23 ~47 ~69 wool 15
fill ~18 ~47 ~70 ~23 ~47 ~70 wool 15
fill ~18 ~47 ~71 ~23 ~47 ~71 wool 15
fill ~18 ~47 ~72 ~28 ~47 ~72 wool 15
fill ~18 ~47 ~73 ~32 ~47 ~73 wool 15
fill ~18 ~47 ~74 ~40 ~47 ~74 wool 15
fill ~18 ~47 ~75 ~40 ~47 ~75 wool 15
fill ~19 ~47 ~43 ~28 ~47 ~43 wool 0
fill ~19 ~47 ~53 ~38 ~47 ~53 stone 0
fill ~19 ~47 ~76 ~40 ~47 ~76 wool 15
fill ~19 ~47 ~77 ~39 ~47 ~77 wool 15
fill ~20 ~47 ~42 ~20 ~48 ~42 wool 15
fill ~20 ~47 ~48 ~20 ~57 ~48 wool 15
fill ~20 ~47 ~49 ~38 ~47 ~49 stone 0
fill ~20 ~47 ~54 ~20 ~56 ~54 stone 0
fill ~20 ~47 ~55 ~20 ~60 ~55 stone 0
fill ~20 ~47 ~56 ~38 ~47 ~56 stone 0
fill ~20 ~47 ~78 ~38 ~47 ~78 wool 15
setblock ~21 ~47 ~41 wool 15
fill ~21 ~47 ~47 ~22 ~47 ~47 wool 15
fill ~21 ~47 ~57 ~39 ~47 ~57 stone 0
fill ~21 ~47 ~58 ~21 ~63 ~58 stone 0
fill ~21 ~47 ~62 ~21 ~67 ~62 stone 0
fill ~22 ~47 ~40 ~36 ~47 ~40 wool 0
fill ~22 ~47 ~46 ~23 ~47 ~46 wool 15
fill ~22 ~47 ~48 ~37 ~47 ~48 stone 0
fill ~22 ~47 ~63 ~35 ~47 ~63 stone 0
fill ~22 ~47 ~79 ~37 ~47 ~79 wool 15
fill ~23 ~47 ~41 ~36 ~47 ~41 wool 0
fill ~23 ~47 ~42 ~30 ~47 ~42 wool 0
fill ~23 ~47 ~47 ~36 ~47 ~47 stone 0
fill ~23 ~47 ~64 ~34 ~47 ~64 stone 0
fill ~24 ~47 ~46 ~36 ~47 ~46 stone 0
fill ~24 ~47 ~65 ~34 ~47 ~65 stone 0
fill ~24 ~47 ~66 ~34 ~47 ~66 stone 0
fill ~24 ~47 ~67 ~34 ~47 ~67 stone 0
fill ~24 ~47 ~68 ~34 ~47 ~68 stone 0
fill ~24 ~47 ~69 ~34 ~47 ~69 stone 0
fill ~24 ~47 ~70 ~34 ~47 ~70 stone 0
fill ~24 ~47 ~71 ~34 ~47 ~71 stone 0
fill ~24 ~47 ~80 ~34 ~47 ~80 wool 15
fill ~25 ~47 ~39 ~32 ~47 ~39 wool 0
fill ~25 ~47 ~45 ~31 ~47 ~45 stone 0
fill ~25 ~47 ~60 ~36 ~47 ~60 stone 0
fill ~26 ~47 ~44 ~34 ~47 ~44 wool 15
fill ~26 ~47 ~54 ~38 ~47 ~54 stone 0
fill ~26 ~47 ~55 ~38 ~47 ~55 stone 0
fill ~26 ~47 ~58 ~38 ~47 ~58 stone 0
fill ~26 ~47 ~59 ~37 ~47 ~59 stone 0
fill ~26 ~47 ~81 ~33 ~47 ~81 wool 15
fill ~27 ~47 ~38 ~32 ~47 ~38 wool 0
fill ~27 ~47 ~61 ~35 ~47 ~61 stone 0
fill ~27 ~47 ~62 ~35 ~47 ~62 stone 0
setblock ~28 ~47 ~37 wool 0
fill ~28 ~47 ~82 ~31 ~47 ~82 wool 15
fill ~29 ~47 ~37 ~30 ~47 ~37 wool 15
fill ~29 ~47 ~43 ~34 ~47 ~43 wool 15
fill ~29 ~47 ~72 ~34 ~47 ~72 stone 0
fill ~32 ~47 ~45 ~34 ~47 ~45 wool 15
fill ~33 ~47 ~39 ~33 ~48 ~39 wool 15
fill ~33 ~47 ~42 ~33 ~51 ~42 wool 15
fill ~33 ~47 ~73 ~33 ~76 ~73 stone 0
fill ~34 ~47 ~42 ~39 ~47 ~42 wool 0
fill ~34 ~47 ~73 ~40 ~47 ~73 wool 15
fill ~35 ~47 ~43 ~39 ~47 ~43 wool 0
fill ~35 ~47 ~44 ~40 ~47 ~44 wool 0
setblock ~35 ~47 ~45 stone 0
fill ~35 ~47 ~64 ~43 ~47 ~64 wool 15
fill ~35 ~47 ~66 ~40 ~47 ~66 wool 15
fill ~35 ~47 ~67 ~40 ~47 ~67 wool 15
fill ~35 ~47 ~68 ~40 ~47 ~68 wool 15
fill ~35 ~47 ~69 ~40 ~47 ~69 wool 15
fill ~35 ~47 ~70 ~40 ~47 ~70 wool 15
fill ~35 ~47 ~71 ~40 ~47 ~71 wool 15
fill ~35 ~47 ~72 ~40 ~47 ~72 wool 15
fill ~36 ~47 ~45 ~41 ~47 ~45 wool 0
fill ~36 ~47 ~61 ~44 ~47 ~61 wool 15
fill ~36 ~47 ~62 ~44 ~47 ~62 wool 15
fill ~36 ~47 ~63 ~44 ~47 ~63 wool 15
fill ~37 ~47 ~41 ~37 ~48 ~41 wool 15
fill ~37 ~47 ~47 ~37 ~56 ~47 wool 15
fill ~38 ~47 ~47 ~42 ~47 ~47 wool 0
fill ~38 ~47 ~59 ~45 ~47 ~59 wool 15
fill ~39 ~47 ~49 ~42 ~47 ~49 wool 0
fill ~39 ~47 ~52 ~44 ~47 ~52 wool 15
fill ~39 ~47 ~53 ~45 ~47 ~53 wool 15
fill ~39 ~47 ~54 ~45 ~47 ~54 wool 15
fill ~39 ~47 ~55 ~45 ~47 ~55 wool 15
fill ~39 ~47 ~56 ~45 ~47 ~56 wool 15
fill ~39 ~47 ~58 ~45 ~47 ~58 wool 15
fill ~40 ~47 ~50 ~40 ~60 ~50 wool 15
fill ~40 ~47 ~51 ~44 ~47 ~51 wool 15
fill ~40 ~47 ~57 ~45 ~47 ~57 wool 15
fill ~41 ~47 ~65 ~42 ~47 ~65 wool 15
setblock ~43 ~47 ~50 wool 0
fill ~44 ~47 ~50 ~44 ~52 ~50 wool 15
fill ~44 ~47 ~60 ~45 ~47 ~60 wool 15
fill ~13 ~48 ~53 ~18 ~48 ~53 wool 15
fill ~13 ~48 ~54 ~18 ~48 ~54 wool 15
fill ~13 ~48 ~55 ~18 ~48 ~55 wool 15
fill ~13 ~48 ~56 ~18 ~48 ~56 wool 15
fill ~13 ~48 ~57 ~19 ~48 ~57 wool 15
fill ~13 ~48 ~58 ~20 ~48 ~58 wool 15
fill ~13 ~48 ~59 ~20 ~48 ~59 wool 15
fill ~13 ~48 ~60 ~20 ~48 ~60 wool 15
fill ~13 ~48 ~61 ~20 ~48 ~61 wool 15
fill ~13 ~48 ~62 ~20 ~48 ~62 wool 15
fill ~14 ~48 ~51 ~18 ~48 ~51 wool 15
fill ~14 ~48 ~52 ~18 ~48 ~52 wool 15
fill ~14 ~48 ~63 ~21 ~48 ~63 wool 15
fill ~14 ~48 ~64 ~22 ~48 ~64 wool 15
fill ~15 ~48 ~50 ~18 ~48 ~50 wool 15
fill ~15 ~48 ~65 ~23 ~48 ~65 wool 15
fill ~15 ~48 ~66 ~23 ~48 ~66 wool 15
fill ~16 ~48 ~47 ~19 ~48 ~47 wool 0
fill ~16 ~48 ~48 ~22 ~48 ~48 wool 15
fill ~16 ~48 ~49 ~21 ~48 ~49 wool 15
fill ~17 ~48 ~46 ~17 ~50 ~46 wool 15
fill ~18 ~48 ~44 ~25 ~48 ~44 wool 0
fill ~18 ~48 ~45 ~18 ~50 ~45 wool 15
fill ~18 ~48 ~67 ~23 ~48 ~67 wool 15
fill ~18 ~48 ~68 ~23 ~48 ~68 wool 15
