fill ~48 ~-3 ~72 ~53 ~-3 ~72 wool 15
fill ~48 ~-3 ~73 ~53 ~-3 ~73 wool 15
fill ~49 ~-3 ~10 ~54 ~-3 ~10 wool 15
fill ~49 ~-3 ~11 ~54 ~-3 ~11 wool 15
fill ~151 ~-3 ~10 ~156 ~-3 ~10 wool 15
fill ~151 ~-3 ~11 ~156 ~-3 ~11 wool 15
fill ~151 ~-3 ~72 ~156 ~-3 ~72 wool 15
fill ~151 ~-3 ~73 ~156 ~-3 ~73 wool 15
fill ~45 ~-2 ~72 ~47 ~-2 ~72 wool 15
fill ~45 ~-2 ~73 ~47 ~-2 ~73 wool 15
fill ~46 ~-2 ~10 ~48 ~-2 ~10 wool 15
fill ~46 ~-2 ~11 ~48 ~-2 ~11 wool 15
fill ~46 ~-2 ~71 ~55 ~-2 ~71 wool 15
fill ~46 ~-2 ~74 ~55 ~-2 ~74 wool 15
fill ~47 ~-2 ~9 ~56 ~-2 ~9 wool 15
fill ~47 ~-2 ~12 ~56 ~-2 ~12 wool 15
fill ~54 ~-2 ~72 ~56 ~-2 ~72 wool 15
fill ~54 ~-2 ~73 ~56 ~-2 ~73 wool 15
fill ~55 ~-2 ~10 ~57 ~-2 ~10 wool 15
fill ~55 ~-2 ~11 ~57 ~-2 ~11 wool 15
fill ~148 ~-2 ~10 ~150 ~-2 ~10 wool 15
fill ~148 ~-2 ~11 ~150 ~-2 ~11 wool 15
fill ~148 ~-2 ~72 ~150 ~-2 ~72 wool 15
fill ~148 ~-2 ~73 ~150 ~-2 ~73 wool 15
fill ~149 ~-2 ~9 ~158 ~-2 ~9 wool 15
fill ~149 ~-2 ~12 ~158 ~-2 ~12 wool 15
fill ~149 ~-2 ~71 ~158 ~-2 ~71 wool 15
fill ~149 ~-2 ~74 ~158 ~-2 ~74 wool 15
fill ~157 ~-2 ~10 ~159 ~-2 ~10 wool 15
fill ~157 ~-2 ~11 ~159 ~-2 ~11 wool 15
fill ~157 ~-2 ~72 ~159 ~-2 ~72 wool 15
fill ~157 ~-2 ~73 ~159 ~-2 ~73 wool 15
fill ~44 ~-1 ~72 ~44 ~-1 ~73 wool 15
fill ~45 ~-1 ~10 ~45 ~-1 ~11 wool 15
fill ~45 ~-1 ~71 ~46 ~-1 ~71 wool 15
fill ~45 ~-1 ~74 ~46 ~-1 ~74 wool 15
fill ~46 ~-1 ~9 ~47 ~-1 ~9 wool 15
fill ~46 ~-1 ~12 ~47 ~-1 ~12 wool 15
fill ~47 ~-1 ~70 ~54 ~-1 ~70 wool 15
fill ~47 ~-1 ~75 ~48 ~-1 ~75 wool 15
fill ~48 ~-1 ~8 ~49 ~-1 ~8 wool 15
fill ~48 ~-1 ~13 ~55 ~-1 ~13 wool 15
fill ~49 ~-1 ~75 ~52 ~-1 ~75 wool 0
fill ~50 ~-1 ~8 ~53 ~-1 ~8 wool 0
fill ~53 ~-1 ~75 ~54 ~-1 ~75 wool 15
fill ~54 ~-1 ~8 ~55 ~-1 ~8 wool 15
fill ~55 ~-1 ~71 ~56 ~-1 ~71 wool 15
fill ~55 ~-1 ~74 ~56 ~-1 ~74 wool 15
fill ~56 ~-1 ~9 ~57 ~-1 ~9 wool 15
fill ~56 ~-1 ~12 ~57 ~-1 ~12 wool 15
fill ~57 ~-1 ~72 ~57 ~-1 ~73 wool 15
fill ~58 ~-1 ~10 ~58 ~-1 ~11 wool 15
fill ~147 ~-1 ~10 ~147 ~-1 ~11 wool 15
fill ~147 ~-1 ~72 ~147 ~-1 ~73 wool 15
fill ~148 ~-1 ~9 ~149 ~-1 ~9 wool 15
fill ~148 ~-1 ~12 ~149 ~-1 ~12 wool 15
fill ~148 ~-1 ~71 ~149 ~-1 ~71 wool 15
fill ~148 ~-1 ~74 ~149 ~-1 ~74 wool 15
fill ~150 ~-1 ~8 ~151 ~-1 ~8 wool 15
fill ~150 ~-1 ~13 ~157 ~-1 ~13 wool 15
fill ~150 ~-1 ~70 ~157 ~-1 ~70 wool 15
fill ~150 ~-1 ~75 ~151 ~-1 ~75 wool 15
fill ~152 ~-1 ~8 ~155 ~-1 ~8 wool 0
fill ~152 ~-1 ~75 ~155 ~-1 ~75 wool 0
fill ~156 ~-1 ~8 ~157 ~-1 ~8 wool 15
fill ~156 ~-1 ~75 ~157 ~-1 ~75 wool 15
fill ~158 ~-1 ~9 ~159 ~-1 ~9 wool 15
fill ~158 ~-1 ~12 ~159 ~-1 ~12 wool 15
fill ~158 ~-1 ~71 ~159 ~-1 ~71 wool 15
fill ~158 ~-1 ~74 ~159 ~-1 ~74 wool 15
fill ~160 ~-1 ~10 ~160 ~-1 ~11 wool 15
fill ~160 ~-1 ~72 ~160 ~-1 ~73 wool 15
fill ~43 ~0 ~71 ~44 ~0 ~71 wool 15
fill ~43 ~0 ~72 ~43 ~0 ~74 wool 15
fill ~44 ~0 ~9 ~45 ~0 ~9 wool 15
fill ~44 ~0 ~10 ~44 ~0 ~12 wool 15
setblock ~44 ~0 ~74 wool 15
setblock ~45 ~0 ~12 wool 15
fill ~45 ~0 ~70 ~49 ~0 ~70 wool 15
setblock ~45 ~0 ~75 wool 15
setblock ~46 ~0 ~8 wool 15
fill ~46 ~0 ~13 ~50 ~0 ~13 wool 15
fill ~46 ~0 ~75 ~49 ~0 ~75 wool 0
fill ~47 ~0 ~8 ~50 ~0 ~8 wool 0
fill ~49 ~0 ~74 ~53 ~0 ~74 wool 8
fill ~50 ~0 ~9 ~54 ~0 ~9 wool 8
fill ~50 ~0 ~69 ~51 ~0 ~69 wool 15
fill ~51 ~0 ~14 ~52 ~0 ~14 wool 15
fill ~52 ~0 ~70 ~56 ~0 ~70 wool 15
fill ~52 ~0 ~75 ~55 ~0 ~75 wool 0
fill ~53 ~0 ~8 ~56 ~0 ~8 wool 0
fill ~53 ~0 ~13 ~57 ~0 ~13 wool 15
setblock ~56 ~0 ~75 wool 15
setblock ~57 ~0 ~8 wool 15
fill ~57 ~0 ~71 ~58 ~0 ~71 wool 15
fill ~57 ~0 ~74 ~58 ~0 ~74 wool 15
fill ~58 ~0 ~9 ~59 ~0 ~9 wool 15
fill ~58 ~0 ~12 ~59 ~0 ~12 wool 15
fill ~58 ~0 ~72 ~58 ~0 ~74 wool 15
fill ~59 ~0 ~10 ~59 ~0 ~12 wool 15
fill ~146 ~0 ~9 ~147 ~0 ~9 wool 15
fill ~146 ~0 ~10 ~146 ~0 ~12 wool 15
fill ~146 ~0 ~71 ~147 ~0 ~71 wool 15
fill ~146 ~0 ~72 ~146 ~0 ~74 wool 15
setblock ~147 ~0 ~12 wool 15
setblock ~147 ~0 ~74 wool 15
setblock ~148 ~0 ~8 wool 15
fill ~148 ~0 ~13 ~152 ~0 ~13 wool 15
fill ~148 ~0 ~70 ~152 ~0 ~70 wool 15
setblock ~148 ~0 ~75 wool 15
fill ~149 ~0 ~8 ~152 ~0 ~8 wool 0
fill ~149 ~0 ~75 ~152 ~0 ~75 wool 0
fill ~151 ~0 ~74 ~155 ~0 ~74 wool 8
fill ~152 ~0 ~9 ~156 ~0 ~9 wool 8
fill ~153 ~0 ~14 ~154 ~0 ~14 wool 15
fill ~153 ~0 ~69 ~154 ~0 ~69 wool 15
fill ~155 ~0 ~8 ~158 ~0 ~8 wool 0
fill ~155 ~0 ~13 ~159 ~0 ~13 wool 15
fill ~155 ~0 ~70 ~159 ~0 ~70 wool 15
fill ~155 ~0 ~75 ~158 ~0 ~75 wool 0
setblock ~159 ~0 ~8 wool 15
setblock ~159 ~0 ~75 wool 15
fill ~160 ~0 ~9 ~161 ~0 ~9 wool 15
fill ~160 ~0 ~12 ~161 ~0 ~12 wool 15
fill ~160 ~0 ~71 ~161 ~0 ~71 wool 15
fill ~160 ~0 ~74 ~161 ~0 ~74 wool 15
fill ~161 ~0 ~10 ~161 ~0 ~12 wool 15
fill ~161 ~0 ~72 ~161 ~0 ~74 wool 15
fill ~42 ~1 ~71 ~43 ~1 ~71 wool 15
fill ~42 ~1 ~72 ~42 ~1 ~74 wool 15
fill ~43 ~1 ~9 ~44 ~1 ~9 wool 15
fill ~43 ~1 ~10 ~43 ~1 ~12 wool 15
setblock ~43 ~1 ~74 wool 15
setblock ~44 ~1 ~12 wool 15
fill ~44 ~1 ~70 ~46 ~1 ~70 wool 15
fill ~44 ~1 ~75 ~46 ~1 ~75 wool 0
fill ~45 ~1 ~8 ~47 ~1 ~8 wool 0
fill ~45 ~1 ~13 ~47 ~1 ~13 wool 15
fill ~46 ~1 ~74 ~49 ~1 ~74 wool 8
fill ~47 ~1 ~9 ~50 ~1 ~9 wool 8
fill ~47 ~1 ~69 ~54 ~1 ~69 wool 15
fill ~48 ~1 ~14 ~55 ~1 ~14 wool 15
fill ~52 ~1 ~74 ~55 ~1 ~74 wool 8
fill ~53 ~1 ~9 ~56 ~1 ~9 wool 8
fill ~55 ~1 ~70 ~57 ~1 ~70 wool 15
fill ~55 ~1 ~75 ~57 ~1 ~75 wool 0
fill ~56 ~1 ~8 ~58 ~1 ~8 wool 0
fill ~56 ~1 ~13 ~58 ~1 ~13 wool 15
fill ~58 ~1 ~71 ~59 ~1 ~71 wool 15
fill ~58 ~1 ~74 ~59 ~1 ~74 wool 15
fill ~59 ~1 ~9 ~60 ~1 ~9 wool 15
fill ~59 ~1 ~12 ~60 ~1 ~12 wool 15
fill ~59 ~1 ~72 ~59 ~1 ~74 wool 15
fill ~60 ~1 ~10 ~60 ~1 ~12 wool 15
fill ~145 ~1 ~9 ~146 ~1 ~9 wool 15
fill ~145 ~1 ~10 ~145 ~1 ~12 wool 15
fill ~145 ~1 ~71 ~146 ~1 ~71 wool 15
fill ~145 ~1 ~72 ~145 ~1 ~74 wool 15
setblock ~146 ~1 ~12 wool 15
setblock ~146 ~1 ~74 wool 15
fill ~147 ~1 ~8 ~149 ~1 ~8 wool 0
fill ~147 ~1 ~13 ~149 ~1 ~13 wool 15
fill ~147 ~1 ~70 ~149 ~1 ~70 wool 15
fill ~147 ~1 ~75 ~149 ~1 ~75 wool 0
fill ~149 ~1 ~9 ~152 ~1 ~9 wool 8
fill ~149 ~1 ~74 ~152 ~1 ~74 wool 8
fill ~150 ~1 ~14 ~157 ~1 ~14 wool 15
fill ~150 ~1 ~69 ~157 ~1 ~69 wool 15
fill ~155 ~1 ~9 ~158 ~1 ~9 wool 8
fill ~155 ~1 ~74 ~158 ~1 ~74 wool 8
fill ~158 ~1 ~8 ~160 ~1 ~8 wool 0
fill ~158 ~1 ~13 ~160 ~1 ~13 wool 15
fill ~158 ~1 ~70 ~160 ~1 ~70 wool 15
fill ~158 ~1 ~75 ~160 ~1 ~75 wool 0
fill ~161 ~1 ~9 ~162 ~1 ~9 wool 15
fill ~161 ~1 ~12 ~162 ~1 ~12 wool 15
fill ~161 ~1 ~71 ~162 ~1 ~71 wool 15
fill ~161 ~1 ~74 ~162 ~1 ~74 wool 15
fill ~162 ~1 ~10 ~162 ~1 ~12 wool 15
fill ~162 ~1 ~72 ~162 ~1 ~74 wool 15
fill ~41 ~2 ~72 ~41 ~2 ~73 wool 15
fill ~42 ~2 ~10 ~42 ~2 ~11 wool 15
fill ~42 ~2 ~71 ~42 ~1 ~71 wool 15
setblock ~42 ~2 ~74 wool 15
fill ~43 ~2 ~9 ~43 ~1 ~9 wool 15
setblock ~43 ~2 ~12 wool 15
fill ~43 ~2 ~70 ~44 ~2 ~70 wool 15
fill ~43 ~2 ~75 ~44 ~2 ~75 wool 0
fill ~44 ~2 ~8 ~45 ~2 ~8 wool 0
fill ~44 ~2 ~13 ~45 ~2 ~13 wool 15
fill ~44 ~2 ~74 ~46 ~2 ~74 wool 8
fill ~45 ~2 ~9 ~47 ~2 ~9 wool 8
fill ~45 ~2 ~69 ~56 ~2 ~69 wool 15
fill ~46 ~2 ~14 ~57 ~2 ~14 wool 15
fill ~55 ~2 ~74 ~57 ~2 ~74 wool 8
fill ~56 ~2 ~9 ~58 ~2 ~9 wool 8
fill ~57 ~2 ~70 ~58 ~2 ~70 wool 15
fill ~57 ~2 ~75 ~58 ~2 ~75 wool 0
fill ~58 ~2 ~8 ~59 ~2 ~8 wool 0
fill ~58 ~2 ~13 ~59 ~2 ~13 wool 15
setblock ~59 ~2 ~71 wool 15
setblock ~59 ~2 ~74 wool 15
setblock ~60 ~2 ~9 wool 15
setblock ~60 ~2 ~12 wool 15
fill ~60 ~2 ~72 ~60 ~2 ~73 wool 15
fill ~61 ~2 ~10 ~61 ~2 ~11 wool 15
fill ~68 ~2 ~73 ~136 ~2 ~73 wool 0
fill ~69 ~2 ~10 ~136 ~2 ~10 wool 0
fill ~144 ~2 ~10 ~144 ~2 ~11 wool 15
fill ~144 ~2 ~72 ~144 ~2 ~73 wool 15
fill ~145 ~2 ~9 ~145 ~1 ~9 wool 15
setblock ~145 ~2 ~12 wool 15
fill ~145 ~2 ~71 ~145 ~1 ~71 wool 15
setblock ~145 ~2 ~74 wool 15
fill ~146 ~2 ~8 ~147 ~2 ~8 wool 0
fill ~146 ~2 ~13 ~147 ~2 ~13 wool 15
fill ~146 ~2 ~70 ~147 ~2 ~70 wool 15
fill ~146 ~2 ~75 ~147 ~2 ~75 wool 0
fill ~147 ~2 ~9 ~149 ~2 ~9 wool 8
fill ~147 ~2 ~74 ~149 ~2 ~74 wool 8
fill ~148 ~2 ~14 ~159 ~2 ~14 wool 15
fill ~148 ~2 ~69 ~159 ~2 ~69 wool 15
fill ~158 ~2 ~9 ~160 ~2 ~9 wool 8
fill ~158 ~2 ~74 ~160 ~2 ~74 wool 8
fill ~160 ~2 ~8 ~161 ~2 ~8 wool 0
fill ~160 ~2 ~13 ~161 ~2 ~13 wool 15
fill ~160 ~2 ~70 ~161 ~2 ~70 wool 15
fill ~160 ~2 ~75 ~161 ~2 ~75 wool 0
setblock ~162 ~2 ~9 wool 15
setblock ~162 ~2 ~12 wool 15
setblock ~162 ~2 ~71 wool 15
setblock ~162 ~2 ~74 wool 15
fill ~163 ~2 ~10 ~163 ~2 ~11 wool 15
fill ~163 ~2 ~72 ~163 ~2 ~73 wool 15
fill ~40 ~3 ~72 ~40 ~5 ~72 wool 15
fill ~40 ~3 ~73 ~40 ~5 ~73 wool 15
fill ~41 ~3 ~10 ~41 ~5 ~10 wool 15
fill ~41 ~3 ~11 ~41 ~5 ~11 wool 15
fill ~41 ~3 ~71 ~41 ~4 ~71 wool 15
fill ~41 ~3 ~74 ~41 ~4 ~74 wool 15
fill ~42 ~3 ~9 ~42 ~4 ~9 wool 15
fill ~42 ~3 ~12 ~42 ~4 ~12 wool 15
fill ~42 ~3 ~70 ~43 ~3 ~70 wool 15
setblock ~42 ~3 ~75 wool 15
setblock ~43 ~3 ~8 wool 15
fill ~43 ~3 ~13 ~44 ~3 ~13 wool 15
fill ~43 ~3 ~74 ~44 ~3 ~74 wool 8
fill ~43 ~3 ~75 ~43 ~19 ~75 wool 0
fill ~44 ~3 ~8 ~44 ~19 ~8 wool 0
fill ~44 ~3 ~9 ~45 ~3 ~9 wool 8
fill ~44 ~3 ~69 ~57 ~3 ~69 wool 15
fill ~45 ~3 ~14 ~58 ~3 ~14 wool 15
fill ~45 ~3 ~73 ~47 ~3 ~73 wool 8
fill ~46 ~3 ~10 ~48 ~3 ~10 wool 8
fill ~54 ~3 ~73 ~56 ~3 ~73 wool 8
fill ~55 ~3 ~10 ~57 ~3 ~10 wool 8
fill ~57 ~3 ~74 ~57 ~4 ~74 wool 8
fill ~58 ~3 ~9 ~58 ~4 ~9 wool 8
fill ~58 ~3 ~70 ~59 ~3 ~70 wool 15
fill ~58 ~3 ~75 ~58 ~19 ~75 wool 0
fill ~59 ~3 ~8 ~59 ~19 ~8 wool 0
fill ~59 ~3 ~13 ~60 ~3 ~13 wool 15
setblock ~59 ~3 ~75 wool 15
setblock ~60 ~3 ~8 wool 15
fill ~60 ~3 ~71 ~60 ~4 ~71 wool 15
fill ~60 ~3 ~74 ~60 ~4 ~74 wool 15
fill ~61 ~3 ~9 ~61 ~4 ~9 wool 15
fill ~61 ~3 ~12 ~61 ~4 ~12 wool 15
fill ~61 ~3 ~72 ~61 ~5 ~72 wool 15
fill ~61 ~3 ~73 ~61 ~5 ~73 wool 15
fill ~62 ~3 ~10 ~62 ~5 ~10 wool 15
fill ~62 ~3 ~11 ~62 ~5 ~11 wool 15
fill ~68 ~3 ~73 ~136 ~3 ~73 wool 0
fill ~69 ~3 ~10 ~136 ~3 ~10 wool 0
fill ~143 ~3 ~10 ~143 ~5 ~10 wool 15
fill ~143 ~3 ~11 ~143 ~5 ~11 wool 15
fill ~143 ~3 ~72 ~143 ~5 ~72 wool 15
fill ~143 ~3 ~73 ~143 ~5 ~73 wool 15
fill ~144 ~3 ~9 ~144 ~4 ~9 wool 15
fill ~144 ~3 ~12 ~144 ~4 ~12 wool 15
fill ~144 ~3 ~71 ~144 ~4 ~71 wool 15
fill ~144 ~3 ~74 ~144 ~4 ~74 wool 15
setblock ~145 ~3 ~8 wool 15
fill ~145 ~3 ~13 ~146 ~3 ~13 wool 15
fill ~145 ~3 ~70 ~146 ~3 ~70 wool 15
setblock ~145 ~3 ~75 wool 15
fill ~146 ~3 ~8 ~146 ~4 ~8 wool 0
fill ~146 ~3 ~9 ~147 ~3 ~9 wool 8
fill ~146 ~3 ~75 ~146 ~4 ~75 wool 0
fill ~147 ~3 ~14 ~160 ~3 ~14 wool 15
fill ~147 ~3 ~69 ~160 ~3 ~69 wool 15
fill ~147 ~3 ~74 ~147 ~4 ~74 wool 8
fill ~148 ~3 ~10 ~150 ~3 ~10 wool 8
fill ~148 ~3 ~73 ~150 ~3 ~73 wool 8
fill ~157 ~3 ~10 ~159 ~3 ~10 wool 8
fill ~157 ~3 ~73 ~159 ~3 ~73 wool 8
fill ~160 ~3 ~9 ~160 ~4 ~9 wool 8
fill ~160 ~3 ~74 ~161 ~3 ~74 wool 8
fill ~161 ~3 ~8 ~161 ~4 ~8 wool 0
fill ~161 ~3 ~13 ~162 ~3 ~13 wool 15
fill ~161 ~3 ~70 ~162 ~3 ~70 wool 15
fill ~161 ~3 ~75 ~161 ~4 ~75 wool 0
setblock ~162 ~3 ~8 wool 15
setblock ~162 ~3 ~75 wool 15
fill ~163 ~3 ~9 ~163 ~4 ~9 wool 15
fill ~163 ~3 ~12 ~163 ~4 ~12 wool 15
fill ~163 ~3 ~71 ~163 ~4 ~71 wool 15
fill ~163 ~3 ~74 ~163 ~4 ~74 wool 15
fill ~164 ~3 ~10 ~164 ~5 ~10 wool 15
fill ~164 ~3 ~11 ~164 ~5 ~11 wool 15
fill ~164 ~3 ~72 ~164 ~5 ~72 wool 15
fill ~164 ~3 ~73 ~164 ~5 ~73 wool 15
fill ~40 ~4 ~71 ~40 ~13 ~71 wool 15
fill ~40 ~4 ~74 ~40 ~13 ~74 wool 15
fill ~41 ~4 ~9 ~41 ~13 ~9 wool 15
fill ~41 ~4 ~12 ~41 ~13 ~12 wool 15
fill ~42 ~4 ~70 ~43 ~4 ~70 wool 15
fill ~42 ~4 ~75 ~42 ~19 ~75 wool 0
fill ~43 ~4 ~8 ~43 ~19 ~8 wool 0
fill ~43 ~4 ~13 ~44 ~4 ~13 wool 15
fill ~43 ~4 ~74 ~44 ~4 ~74 wool 8
fill ~44 ~4 ~9 ~45 ~4 ~9 wool 8
fill ~44 ~4 ~69 ~47 ~4 ~69 wool 15
fill ~45 ~4 ~14 ~48 ~4 ~14 wool 15
fill ~45 ~4 ~73 ~48 ~4 ~73 wool 8
fill ~46 ~4 ~10 ~49 ~4 ~10 wool 8
fill ~48 ~4 ~68 ~53 ~4 ~68 wool 15
fill ~49 ~4 ~15 ~54 ~4 ~15 wool 15
fill ~53 ~4 ~73 ~56 ~4 ~73 wool 8
fill ~54 ~4 ~10 ~57 ~4 ~10 wool 8
fill ~54 ~4 ~69 ~57 ~4 ~69 wool 15
fill ~55 ~4 ~14 ~58 ~4 ~14 wool 15
fill ~58 ~4 ~70 ~59 ~4 ~70 wool 15
fill ~58 ~4 ~74 ~58 ~7 ~74 wool 8
fill ~59 ~4 ~9 ~59 ~7 ~9 wool 8
fill ~59 ~4 ~13 ~60 ~4 ~13 wool 15
fill ~59 ~4 ~75 ~59 ~19 ~75 wool 0
fill ~60 ~4 ~8 ~60 ~19 ~8 wool 0
fill ~61 ~4 ~71 ~61 ~13 ~71 wool 15
fill ~61 ~4 ~74 ~61 ~13 ~74 wool 15
fill ~62 ~4 ~9 ~62 ~13 ~9 wool 15
fill ~62 ~4 ~12 ~62 ~13 ~12 wool 15
fill ~68 ~4 ~73 ~136 ~4 ~73 wool 0
fill ~69 ~4 ~10 ~136 ~4 ~10 wool 0
fill ~143 ~4 ~9 ~143 ~13 ~9 wool 15
fill ~143 ~4 ~12 ~143 ~13 ~12 wool 15
fill ~143 ~4 ~71 ~143 ~13 ~71 wool 15
fill ~143 ~4 ~74 ~143 ~13 ~74 wool 15
fill ~145 ~4 ~8 ~145 ~7 ~8 wool 0
fill ~145 ~4 ~13 ~146 ~4 ~13 wool 15
fill ~145 ~4 ~70 ~146 ~4 ~70 wool 15
fill ~145 ~4 ~75 ~145 ~7 ~75 wool 0
fill ~146 ~4 ~9 ~147 ~4 ~9 wool 8
fill ~146 ~4 ~74 ~146 ~7 ~74 wool 8
fill ~147 ~4 ~14 ~150 ~4 ~14 wool 15
fill ~147 ~4 ~69 ~150 ~4 ~69 wool 15
fill ~148 ~4 ~10 ~151 ~4 ~10 wool 8
fill ~148 ~4 ~73 ~151 ~4 ~73 wool 8
fill ~151 ~4 ~15 ~156 ~4 ~15 wool 15
fill ~151 ~4 ~68 ~156 ~4 ~68 wool 15
fill ~156 ~4 ~10 ~159 ~4 ~10 wool 8
fill ~156 ~4 ~73 ~159 ~4 ~73 wool 8
fill ~157 ~4 ~14 ~160 ~4 ~14 wool 15
fill ~157 ~4 ~69 ~160 ~4 ~69 wool 15
fill ~160 ~4 ~74 ~161 ~4 ~74 wool 8
fill ~161 ~4 ~9 ~161 ~7 ~9 wool 8
fill ~161 ~4 ~13 ~162 ~4 ~13 wool 15
fill ~161 ~4 ~70 ~162 ~4 ~70 wool 15
fill ~162 ~4 ~8 ~162 ~7 ~8 wool 0
fill ~162 ~4 ~75 ~162 ~7 ~75 wool 0
fill ~164 ~4 ~9 ~164 ~13 ~9 wool 15
fill ~164 ~4 ~12 ~164 ~13 ~12 wool 15
fill ~164 ~4 ~71 ~164 ~13 ~71 wool 15
fill ~164 ~4 ~74 ~164 ~13 ~74 wool 15
fill ~16 ~5 ~10 ~34 ~5 ~10 wool 15
fill ~16 ~5 ~11 ~34 ~5 ~11 wool 15
fill ~16 ~5 ~12 ~34 ~5 ~12 wool 15
fill ~16 ~5 ~13 ~34 ~5 ~13 wool 15
fill ~16 ~5 ~14 ~34 ~5 ~14 wool 15
fill ~16 ~5 ~15 ~34 ~5 ~15 wool 15
fill ~16 ~5 ~16 ~34 ~5 ~16 wool 15
fill ~16 ~5 ~17 ~69 ~5 ~17 wool 15
fill ~16 ~5 ~18 ~69 ~5 ~18 wool 15
fill ~16 ~5 ~19 ~69 ~5 ~19 wool 15
fill ~16 ~5 ~20 ~69 ~5 ~20 wool 15
fill ~16 ~5 ~21 ~69 ~5 ~21 wool 15
fill ~16 ~5 ~22 ~69 ~5 ~22 wool 15
fill ~16 ~5 ~23 ~69 ~5 ~23 wool 15
fill ~16 ~5 ~24 ~69 ~5 ~24 wool 15
fill ~16 ~5 ~25 ~69 ~5 ~25 wool 15
fill ~16 ~5 ~26 ~69 ~5 ~26 wool 15
fill ~16 ~5 ~27 ~69 ~5 ~27 wool 15
fill ~16 ~5 ~28 ~69 ~5 ~28 wool 15
fill ~16 ~5 ~29 ~69 ~5 ~29 wool 15
fill ~16 ~5 ~30 ~69 ~5 ~30 wool 15
fill ~16 ~5 ~31 ~69 ~5 ~31 wool 15
fill ~16 ~5 ~32 ~69 ~5 ~32 wool 15
fill ~16 ~5 ~33 ~69 ~5 ~33 wool 15
fill ~16 ~5 ~34 ~69 ~5 ~34 wool 15
fill ~16 ~5 ~35 ~69 ~5 ~35 wool 15
fill ~16 ~5 ~36 ~69 ~5 ~36 wool 15
fill ~16 ~5 ~37 ~69 ~5 ~37 wool 15
fill ~16 ~5 ~38 ~69 ~5 ~38 wool 15
fill ~16 ~5 ~39 ~69 ~5 ~39 wool 15
fill ~16 ~5 ~40 ~69 ~5 ~40 wool 15
fill ~16 ~5 ~41 ~69 ~5 ~41 wool 15
fill ~16 ~5 ~42 ~69 ~5 ~42 wool 15
fill ~16 ~5 ~43 ~69 ~5 ~43 wool 15
fill ~16 ~5 ~44 ~69 ~5 ~44 wool 15
fill ~16 ~5 ~45 ~69 ~5 ~45 wool 15
fill ~16 ~5 ~46 ~69 ~5 ~46 wool 15
fill ~16 ~5 ~47 ~69 ~5 ~47 wool 15
fill ~16 ~5 ~48 ~69 ~5 ~48 wool 15
fill ~16 ~5 ~49 ~69 ~5 ~49 wool 15
fill ~16 ~5 ~50 ~69 ~5 ~50 wool 15
fill ~16 ~5 ~51 ~69 ~5 ~51 wool 15
fill ~16 ~5 ~52 ~69 ~5 ~52 wool 15
fill ~16 ~5 ~53 ~69 ~5 ~53 wool 15
fill ~16 ~5 ~54 ~69 ~5 ~54 wool 15
fill ~16 ~5 ~55 ~69 ~5 ~55 wool 15
fill ~16 ~5 ~56 ~69 ~5 ~56 wool 15
fill ~16 ~5 ~57 ~69 ~5 ~57 wool 15
fill ~16 ~5 ~58 ~69 ~5 ~58 wool 15
fill ~16 ~5 ~59 ~69 ~5 ~59 wool 15
fill ~16 ~5 ~60 ~18 ~5 ~60 wool 15
fill ~16 ~5 ~61 ~69 ~5 ~61 wool 15
fill ~16 ~5 ~62 ~18 ~5 ~62 wool 15
fill ~16 ~5 ~63 ~69 ~5 ~63 wool 15
fill ~16 ~5 ~64 ~69 ~5 ~64 wool 15
fill ~16 ~5 ~65 ~69 ~5 ~65 wool 15
fill ~16 ~5 ~66 ~69 ~5 ~66 wool 15
fill ~16 ~5 ~67 ~33 ~5 ~67 wool 15
fill ~16 ~5 ~68 ~33 ~5 ~68 wool 15
fill ~16 ~5 ~69 ~33 ~5 ~69 wool 15
fill ~16 ~5 ~70 ~33 ~5 ~70 wool 15
fill ~16 ~5 ~71 ~33 ~5 ~71 wool 15
fill ~16 ~5 ~72 ~33 ~5 ~72 wool 15
fill ~16 ~5 ~73 ~33 ~5 ~73 wool 15
fill ~19 ~5 ~60 ~86 ~5 ~60 wool 7
fill ~19 ~5 ~62 ~86 ~5 ~62 wool 7
fill ~27 ~5 ~74 ~33 ~5 ~74 wool 0
fill ~28 ~5 ~9 ~34 ~5 ~9 wool 0
fill ~33 ~5 ~75 ~67 ~5 ~75 wool 0
fill ~34 ~5 ~8 ~68 ~5 ~8 wool 0
fill ~41 ~5 ~70 ~42 ~5 ~70 wool 15
fill ~42 ~5 ~13 ~43 ~5 ~13 wool 15
fill ~43 ~5 ~69 ~46 ~5 ~69 wool 15
fill ~43 ~5 ~74 ~43 ~7 ~74 wool 8
fill ~44 ~5 ~9 ~44 ~7 ~9 wool 8
fill ~44 ~5 ~14 ~47 ~5 ~14 wool 15
fill ~46 ~5 ~73 ~48 ~5 ~73 wool 8
fill ~47 ~5 ~10 ~49 ~5 ~10 wool 8
fill ~47 ~5 ~68 ~54 ~5 ~68 wool 15
fill ~48 ~5 ~15 ~55 ~5 ~15 wool 15
fill ~53 ~5 ~73 ~55 ~5 ~73 wool 8
fill ~54 ~5 ~10 ~56 ~5 ~10 wool 8
fill ~55 ~5 ~69 ~58 ~5 ~69 wool 15
fill ~56 ~5 ~14 ~59 ~5 ~14 wool 15
fill ~59 ~5 ~70 ~60 ~5 ~70 wool 15
fill ~60 ~5 ~13 ~61 ~5 ~13 wool 15
fill ~68 ~5 ~73 ~68 ~2 ~73 wool 0
fill ~68 ~5 ~74 ~136 ~5 ~74 wool 0
fill ~69 ~5 ~9 ~136 ~5 ~9 wool 0
fill ~69 ~5 ~10 ~136 ~5 ~10 wool 15
fill ~69 ~5 ~11 ~136 ~5 ~11 wool 15
fill ~69 ~5 ~12 ~99 ~5 ~12 wool 7
fill ~69 ~5 ~13 ~86 ~5 ~13 wool 7
fill ~69 ~5 ~14 ~86 ~5 ~14 wool 7
fill ~69 ~5 ~15 ~86 ~5 ~15 wool 7
fill ~69 ~5 ~16 ~86 ~5 ~16 wool 7
fill ~69 ~5 ~67 ~99 ~5 ~67 wool 7
fill ~69 ~5 ~68 ~136 ~5 ~68 wool 15
fill ~69 ~5 ~69 ~136 ~5 ~69 wool 15
fill ~69 ~5 ~70 ~136 ~5 ~70 wool 15
fill ~69 ~5 ~71 ~136 ~5 ~71 wool 15
fill ~69 ~5 ~72 ~136 ~5 ~72 wool 15
fill ~69 ~5 ~73 ~136 ~5 ~73 wool 15
fill ~70 ~5 ~17 ~86 ~5 ~17 wool 7
fill ~70 ~5 ~18 ~86 ~5 ~18 wool 7
fill ~70 ~5 ~19 ~86 ~5 ~19 wool 7
fill ~70 ~5 ~20 ~86 ~5 ~20 wool 7
fill ~70 ~5 ~21 ~86 ~5 ~21 wool 7
fill ~70 ~5 ~22 ~86 ~5 ~22 wool 7
fill ~70 ~5 ~23 ~86 ~5 ~23 wool 7
fill ~70 ~5 ~24 ~86 ~5 ~24 wool 7
fill ~70 ~5 ~25 ~86 ~5 ~25 wool 7
fill ~70 ~5 ~26 ~86 ~5 ~26 wool 7
fill ~70 ~5 ~27 ~86 ~5 ~27 wool 7
fill ~70 ~5 ~28 ~86 ~5 ~28 wool 7
fill ~70 ~5 ~29 ~86 ~5 ~29 wool 7
fill ~70 ~5 ~30 ~86 ~5 ~30 wool 7
fill ~70 ~5 ~31 ~86 ~5 ~31 wool 7
fill ~70 ~5 ~32 ~86 ~5 ~32 wool 7
fill ~70 ~5 ~33 ~86 ~5 ~33 wool 7
fill ~70 ~5 ~34 ~86 ~5 ~34 wool 7
fill ~70 ~5 ~35 ~86 ~5 ~35 wool 7
fill ~70 ~5 ~36 ~86 ~5 ~36 wool 7
fill ~70 ~5 ~37 ~86 ~5 ~37 wool 7
fill ~70 ~5 ~38 ~86 ~5 ~38 wool 7
fill ~70 ~5 ~39 ~86 ~5 ~39 wool 7
fill ~70 ~5 ~40 ~86 ~5 ~40 wool 7
fill ~70 ~5 ~41 ~86 ~5 ~41 wool 7
fill ~70 ~5 ~42 ~86 ~5 ~42 wool 7
fill ~70 ~5 ~43 ~86 ~5 ~43 wool 7
fill ~70 ~5 ~44 ~86 ~5 ~44 wool 7
fill ~70 ~5 ~45 ~86 ~5 ~45 wool 7
fill ~70 ~5 ~46 ~86 ~5 ~46 wool 7
fill ~70 ~5 ~47 ~86 ~5 ~47 wool 7
fill ~70 ~5 ~48 ~86 ~5 ~48 wool 7
fill ~70 ~5 ~49 ~86 ~5 ~49 wool 7
fill ~70 ~5 ~50 ~86 ~5 ~50 wool 7
fill ~70 ~5 ~51 ~86 ~5 ~51 wool 7
fill ~70 ~5 ~52 ~86 ~5 ~52 wool 7
fill ~70 ~5 ~53 ~86 ~5 ~53 wool 7
fill ~70 ~5 ~54 ~86 ~5 ~54 wool 7
fill ~70 ~5 ~55 ~86 ~5 ~55 wool 7
fill ~70 ~5 ~56 ~86 ~5 ~56 wool 7
fill ~70 ~5 ~57 ~86 ~5 ~57 wool 7
fill ~70 ~5 ~58 ~86 ~5 ~58 wool 7
fill ~70 ~5 ~59 ~86 ~5 ~59 wool 7
fill ~70 ~5 ~61 ~86 ~5 ~61 wool 7
fill ~70 ~5 ~63 ~86 ~5 ~63 wool 7
fill ~70 ~5 ~64 ~86 ~5 ~64 wool 7
fill ~70 ~5 ~65 ~86 ~5 ~65 wool 7
fill ~70 ~5 ~66 ~86 ~5 ~66 wool 7
fill ~87 ~5 ~13 ~96 ~5 ~13 wool 15
fill ~87 ~5 ~14 ~96 ~5 ~14 wool 15
fill ~87 ~5 ~15 ~96 ~5 ~15 wool 15
fill ~87 ~5 ~16 ~96 ~5 ~16 wool 15
fill ~87 ~5 ~17 ~96 ~5 ~17 wool 15
fill ~87 ~5 ~18 ~96 ~5 ~18 wool 15
fill ~87 ~5 ~19 ~96 ~5 ~19 wool 15
fill ~87 ~5 ~20 ~96 ~5 ~20 wool 15
fill ~87 ~5 ~21 ~96 ~5 ~21 wool 15
fill ~87 ~5 ~22 ~96 ~5 ~22 wool 15
fill ~87 ~5 ~23 ~96 ~5 ~23 wool 15
fill ~87 ~5 ~24 ~96 ~5 ~24 wool 15
fill ~87 ~5 ~25 ~96 ~5 ~25 wool 15
fill ~87 ~5 ~26 ~96 ~5 ~26 wool 15
fill ~87 ~5 ~27 ~96 ~5 ~27 wool 15
fill ~87 ~5 ~28 ~96 ~5 ~28 wool 15
fill ~87 ~5 ~29 ~96 ~5 ~29 wool 15
fill ~87 ~5 ~30 ~96 ~5 ~30 wool 15
fill ~87 ~5 ~31 ~96 ~5 ~31 wool 15
fill ~87 ~5 ~32 ~96 ~5 ~32 wool 15
fill ~87 ~5 ~33 ~96 ~5 ~33 wool 15
fill ~87 ~5 ~34 ~96 ~5 ~34 wool 15
fill ~87 ~5 ~35 ~96 ~5 ~35 wool 15
fill ~87 ~5 ~36 ~96 ~5 ~36 wool 15
fill ~87 ~5 ~37 ~96 ~5 ~37 wool 15
fill ~87 ~5 ~38 ~96 ~5 ~38 wool 15
fill ~87 ~5 ~39 ~96 ~5 ~39 wool 15
fill ~87 ~5 ~40 ~96 ~5 ~40 wool 15
fill ~87 ~5 ~41 ~96 ~5 ~41 wool 15
fill ~87 ~5 ~42 ~96 ~5 ~42 wool 15
fill ~87 ~5 ~43 ~96 ~5 ~43 wool 15
fill ~87 ~5 ~44 ~96 ~5 ~44 wool 15
fill ~87 ~5 ~45 ~96 ~5 ~45 wool 15
fill ~87 ~5 ~46 ~96 ~5 ~46 wool 15
fill ~87 ~5 ~47 ~96 ~5 ~47 wool 15
fill ~87 ~5 ~48 ~96 ~5 ~48 wool 15
fill ~87 ~5 ~49 ~96 ~5 ~49 wool 15
fill ~87 ~5 ~50 ~96 ~5 ~50 wool 15
fill ~87 ~5 ~51 ~96 ~5 ~51 wool 15
fill ~87 ~5 ~52 ~96 ~5 ~52 wool 15
fill ~87 ~5 ~53 ~96 ~5 ~53 wool 15
fill ~87 ~5 ~54 ~96 ~5 ~54 wool 15
fill ~87 ~5 ~55 ~96 ~5 ~55 wool 15
fill ~87 ~5 ~56 ~96 ~5 ~56 wool 15
fill ~87 ~5 ~57 ~96 ~5 ~57 wool 15
fill ~87 ~5 ~58 ~96 ~5 ~58 wool 15
fill ~87 ~5 ~59 ~96 ~5 ~59 wool 15
fill ~87 ~5 ~60 ~96 ~5 ~60 wool 15
fill ~87 ~5 ~61 ~87 ~5 ~66 wool 15
setblock ~88 ~5 ~61 wool 7
fill ~88 ~5 ~62 ~96 ~5 ~62 wool 15
fill ~88 ~5 ~63 ~96 ~5 ~63 wool 15
fill ~88 ~5 ~64 ~96 ~5 ~64 wool 15
fill ~88 ~5 ~65 ~96 ~5 ~65 wool 15
fill ~88 ~5 ~66 ~96 ~5 ~66 wool 15
fill ~89 ~5 ~61 ~96 ~5 ~61 wool 15
fill ~97 ~5 ~13 ~135 ~5 ~13 wool 7
fill ~97 ~5 ~14 ~118 ~5 ~14 wool 7
fill ~97 ~5 ~15 ~118 ~5 ~15 wool 7
fill ~97 ~5 ~16 ~118 ~5 ~16 wool 7
fill ~97 ~5 ~17 ~118 ~5 ~17 wool 7
fill ~97 ~5 ~18 ~118 ~5 ~18 wool 7
fill ~97 ~5 ~19 ~118 ~5 ~19 wool 7
fill ~97 ~5 ~20 ~118 ~5 ~20 wool 7
fill ~97 ~5 ~21 ~118 ~5 ~21 wool 7
fill ~97 ~5 ~22 ~118 ~5 ~22 wool 7
fill ~97 ~5 ~23 ~118 ~5 ~23 wool 7
fill ~97 ~5 ~24 ~118 ~5 ~24 wool 7
fill ~97 ~5 ~25 ~118 ~5 ~25 wool 7
fill ~97 ~5 ~26 ~118 ~5 ~26 wool 7
fill ~97 ~5 ~27 ~118 ~5 ~27 wool 7
fill ~97 ~5 ~28 ~118 ~5 ~28 wool 7
fill ~97 ~5 ~29 ~118 ~5 ~29 wool 7
fill ~97 ~5 ~30 ~118 ~5 ~30 wool 7
fill ~97 ~5 ~31 ~118 ~5 ~31 wool 7
fill ~97 ~5 ~32 ~118 ~5 ~32 wool 7
fill ~97 ~5 ~33 ~118 ~5 ~33 wool 7
fill ~97 ~5 ~34 ~118 ~5 ~34 wool 7
fill ~97 ~5 ~35 ~135 ~5 ~35 wool 7
fill ~97 ~5 ~36 ~135 ~5 ~36 wool 7
fill ~97 ~5 ~37 ~135 ~5 ~37 wool 7
fill ~97 ~5 ~38 ~135 ~5 ~38 wool 7
fill ~97 ~5 ~39 ~135 ~5 ~39 wool 7
fill ~97 ~5 ~40 ~135 ~5 ~40 wool 7
fill ~97 ~5 ~41 ~135 ~5 ~41 wool 7
fill ~97 ~5 ~42 ~135 ~5 ~42 wool 7
fill ~97 ~5 ~43 ~135 ~5 ~43 wool 7
fill ~97 ~5 ~44 ~135 ~5 ~44 wool 7
fill ~97 ~5 ~45 ~118 ~5 ~45 wool 7
fill ~97 ~5 ~46 ~118 ~5 ~46 wool 7
fill ~97 ~5 ~47 ~118 ~5 ~47 wool 7
fill ~97 ~5 ~48 ~118 ~5 ~48 wool 7
fill ~97 ~5 ~49 ~118 ~5 ~49 wool 7
fill ~97 ~5 ~50 ~118 ~5 ~50 wool 7
fill ~97 ~5 ~51 ~118 ~5 ~51 wool 7
fill ~97 ~5 ~52 ~118 ~5 ~52 wool 7
fill ~97 ~5 ~53 ~118 ~5 ~53 wool 7
fill ~97 ~5 ~54 ~118 ~5 ~54 wool 7
fill ~97 ~5 ~55 ~118 ~5 ~55 wool 7
fill ~97 ~5 ~56 ~118 ~5 ~56 wool 7
fill ~97 ~5 ~57 ~118 ~5 ~57 wool 7
fill ~97 ~5 ~58 ~118 ~5 ~58 wool 7
fill ~97 ~5 ~59 ~118 ~5 ~59 wool 7
fill ~97 ~5 ~60 ~118 ~5 ~60 wool 7
fill ~97 ~5 ~61 ~118 ~5 ~61 wool 7
fill ~97 ~5 ~62 ~118 ~5 ~62 wool 7
fill ~97 ~5 ~63 ~118 ~5 ~63 wool 7
fill ~97 ~5 ~64 ~118 ~5 ~64 wool 7
fill ~97 ~5 ~65 ~118 ~5 ~65 wool 7
fill ~97 ~5 ~66 ~135 ~5 ~66 wool 7
setblock ~100 ~5 ~12 wool 8
setblock ~100 ~5 ~67 wool 8
fill ~101 ~5 ~12 ~135 ~5 ~12 wool 7
fill ~101 ~5 ~67 ~135 ~5 ~67 wool 7
fill ~119 ~5 ~14 ~132 ~5 ~14 wool 15
fill ~119 ~5 ~15 ~132 ~5 ~15 wool 15
fill ~119 ~5 ~16 ~132 ~5 ~16 wool 15
fill ~119 ~5 ~17 ~132 ~5 ~17 wool 15
fill ~119 ~5 ~18 ~132 ~5 ~18 wool 15
fill ~119 ~5 ~19 ~132 ~5 ~19 wool 15
fill ~119 ~5 ~20 ~132 ~5 ~20 wool 15
fill ~119 ~5 ~21 ~132 ~5 ~21 wool 15
fill ~119 ~5 ~22 ~132 ~5 ~22 wool 15
fill ~119 ~5 ~23 ~132 ~5 ~23 wool 15
fill ~119 ~5 ~24 ~132 ~5 ~24 wool 15
fill ~119 ~5 ~25 ~132 ~5 ~25 wool 15
fill ~119 ~5 ~26 ~132 ~5 ~26 wool 15
fill ~119 ~5 ~27 ~132 ~5 ~27 wool 15
fill ~119 ~5 ~28 ~132 ~5 ~28 wool 15
fill ~119 ~5 ~29 ~132 ~5 ~29 wool 15
fill ~119 ~5 ~30 ~132 ~5 ~30 wool 15
fill ~119 ~5 ~31 ~132 ~5 ~31 wool 15
fill ~119 ~5 ~32 ~132 ~5 ~32 wool 15
fill ~119 ~5 ~33 ~132 ~5 ~33 wool 15
fill ~119 ~5 ~34 ~132 ~5 ~34 wool 15
fill ~119 ~5 ~45 ~132 ~5 ~45 wool 15
fill ~119 ~5 ~46 ~132 ~5 ~46 wool 15
fill ~119 ~5 ~47 ~132 ~5 ~47 wool 15
fill ~119 ~5 ~48 ~132 ~5 ~48 wool 15
fill ~119 ~5 ~49 ~132 ~5 ~49 wool 15
fill ~119 ~5 ~50 ~132 ~5 ~50 wool 15
fill ~119 ~5 ~51 ~132 ~5 ~51 wool 15
fill ~119 ~5 ~52 ~132 ~5 ~52 wool 15
fill ~119 ~5 ~53 ~132 ~5 ~53 wool 15
fill ~119 ~5 ~54 ~132 ~5 ~54 wool 15
fill ~119 ~5 ~55 ~132 ~5 ~55 wool 15
fill ~119 ~5 ~56 ~132 ~5 ~56 wool 15
fill ~119 ~5 ~57 ~132 ~5 ~57 wool 15
fill ~119 ~5 ~58 ~132 ~5 ~58 wool 15
fill ~119 ~5 ~59 ~132 ~5 ~59 wool 15
fill ~119 ~5 ~60 ~132 ~5 ~60 wool 15
fill ~119 ~5 ~61 ~132 ~5 ~61 wool 15
fill ~119 ~5 ~62 ~132 ~5 ~62 wool 15
fill ~119 ~5 ~63 ~132 ~5 ~63 wool 15
fill ~119 ~5 ~64 ~132 ~5 ~64 wool 15
fill ~119 ~5 ~65 ~132 ~5 ~65 wool 15
fill ~133 ~5 ~14 ~135 ~5 ~14 wool 7
fill ~133 ~5 ~15 ~135 ~5 ~15 wool 7
fill ~133 ~5 ~16 ~135 ~5 ~16 wool 7
fill ~133 ~5 ~17 ~135 ~5 ~17 wool 7
fill ~133 ~5 ~18 ~135 ~5 ~18 wool 7
fill ~133 ~5 ~19 ~135 ~5 ~19 wool 7
fill ~133 ~5 ~20 ~135 ~5 ~20 wool 7
fill ~133 ~5 ~21 ~135 ~5 ~21 wool 7
fill ~133 ~5 ~22 ~135 ~5 ~22 wool 7
fill ~133 ~5 ~23 ~135 ~5 ~23 wool 7
fill ~133 ~5 ~24 ~135 ~5 ~24 wool 7
fill ~133 ~5 ~25 ~135 ~5 ~25 wool 7
fill ~133 ~5 ~26 ~135 ~5 ~26 wool 7
fill ~133 ~5 ~27 ~135 ~5 ~27 wool 7
fill ~133 ~5 ~28 ~135 ~5 ~28 wool 7
fill ~133 ~5 ~29 ~135 ~5 ~29 wool 7
fill ~133 ~5 ~30 ~135 ~5 ~30 wool 7
fill ~133 ~5 ~31 ~135 ~5 ~31 wool 7
fill ~133 ~5 ~32 ~135 ~5 ~32 wool 7
fill ~133 ~5 ~33 ~135 ~5 ~33 wool 7
fill ~133 ~5 ~34 ~135 ~5 ~34 wool 7
fill ~133 ~5 ~45 ~135 ~5 ~45 wool 7
fill ~133 ~5 ~46 ~135 ~5 ~46 wool 7
fill ~133 ~5 ~47 ~135 ~5 ~47 wool 7
fill ~133 ~5 ~48 ~135 ~5 ~48 wool 7
fill ~133 ~5 ~49 ~135 ~5 ~49 wool 7
fill ~133 ~5 ~50 ~135 ~5 ~50 wool 7
fill ~133 ~5 ~51 ~135 ~5 ~51 wool 7
fill ~133 ~5 ~52 ~135 ~5 ~52 wool 7
fill ~133 ~5 ~53 ~135 ~5 ~53 wool 7
fill ~133 ~5 ~54 ~135 ~5 ~54 wool 7
fill ~133 ~5 ~55 ~135 ~5 ~55 wool 7
fill ~133 ~5 ~56 ~135 ~5 ~56 wool 7
fill ~133 ~5 ~57 ~135 ~5 ~57 wool 7
fill ~133 ~5 ~58 ~135 ~5 ~58 wool 7
fill ~133 ~5 ~59 ~135 ~5 ~59 wool 7
fill ~133 ~5 ~60 ~135 ~5 ~60 wool 7
fill ~133 ~5 ~61 ~135 ~5 ~61 wool 7
fill ~133 ~5 ~62 ~135 ~5 ~62 wool 7
fill ~133 ~5 ~63 ~135 ~5 ~63 wool 7
fill ~133 ~5 ~64 ~135 ~5 ~64 wool 7
fill ~133 ~5 ~65 ~135 ~5 ~65 wool 7
fill ~136 ~5 ~12 ~136 ~25 ~12 wool 15
fill ~136 ~5 ~13 ~136 ~25 ~13 wool 15
fill ~136 ~5 ~14 ~136 ~25 ~14 wool 15
fill ~136 ~5 ~15 ~136 ~25 ~15 wool 15
fill ~136 ~5 ~16 ~136 ~25 ~16 wool 15
fill ~136 ~5 ~17 ~136 ~25 ~17 wool 15
fill ~136 ~5 ~18 ~136 ~25 ~18 wool 15
fill ~136 ~5 ~19 ~136 ~25 ~19 wool 15
fill ~136 ~5 ~20 ~136 ~25 ~20 wool 15
fill ~136 ~5 ~21 ~136 ~25 ~21 wool 15
fill ~136 ~5 ~22 ~136 ~25 ~22 wool 15
fill ~136 ~5 ~23 ~136 ~25 ~23 wool 15
fill ~136 ~5 ~24 ~136 ~25 ~24 wool 15
fill ~136 ~5 ~25 ~136 ~25 ~25 wool 15
fill ~136 ~5 ~26 ~136 ~25 ~26 wool 15
fill ~136 ~5 ~27 ~136 ~25 ~27 wool 15
fill ~136 ~5 ~28 ~136 ~25 ~28 wool 15
fill ~136 ~5 ~29 ~136 ~25 ~29 wool 15
fill ~136 ~5 ~30 ~136 ~25 ~30 wool 15
fill ~136 ~5 ~31 ~136 ~25 ~31 wool 15
fill ~136 ~5 ~32 ~136 ~25 ~32 wool 15
fill ~136 ~5 ~33 ~136 ~25 ~33 wool 15
fill ~136 ~5 ~34 ~136 ~25 ~34 wool 15
fill ~136 ~5 ~35 ~136 ~25 ~35 wool 15
fill ~136 ~5 ~36 ~136 ~25 ~36 wool 15
fill ~136 ~5 ~37 ~136 ~25 ~37 wool 15
fill ~136 ~5 ~38 ~136 ~25 ~38 wool 15
fill ~136 ~5 ~39 ~136 ~25 ~39 wool 15
fill ~136 ~5 ~40 ~136 ~25 ~40 wool 15
fill ~136 ~5 ~41 ~136 ~25 ~41 wool 15
fill ~136 ~5 ~42 ~136 ~25 ~42 wool 15
fill ~136 ~5 ~43 ~136 ~25 ~43 wool 15
fill ~136 ~5 ~44 ~136 ~25 ~44 wool 15
fill ~136 ~5 ~45 ~136 ~25 ~45 wool 15
fill ~136 ~5 ~46 ~136 ~25 ~46 wool 15
fill ~136 ~5 ~47 ~136 ~25 ~47 wool 15
fill ~136 ~5 ~48 ~136 ~25 ~48 wool 15
fill ~136 ~5 ~49 ~136 ~25 ~49 wool 15
fill ~136 ~5 ~50 ~136 ~25 ~50 wool 15
fill ~136 ~5 ~51 ~136 ~25 ~51 wool 15
fill ~136 ~5 ~52 ~136 ~25 ~52 wool 15
fill ~136 ~5 ~53 ~136 ~25 ~53 wool 15
fill ~136 ~5 ~54 ~136 ~25 ~54 wool 15
fill ~136 ~5 ~55 ~136 ~25 ~55 wool 15
fill ~136 ~5 ~56 ~136 ~25 ~56 wool 15
fill ~136 ~5 ~57 ~136 ~25 ~57 wool 15
fill ~136 ~5 ~58 ~136 ~25 ~58 wool 15
fill ~136 ~5 ~59 ~136 ~25 ~59 wool 15
fill ~136 ~5 ~60 ~136 ~25 ~60 wool 15
fill ~136 ~5 ~61 ~136 ~25 ~61 wool 15
fill ~136 ~5 ~62 ~136 ~25 ~62 wool 15
fill ~136 ~5 ~63 ~136 ~25 ~63 wool 15
fill ~136 ~5 ~64 ~136 ~25 ~64 wool 15
fill ~136 ~5 ~65 ~136 ~25 ~65 wool 15
fill ~136 ~5 ~66 ~136 ~25 ~66 wool 15
fill ~136 ~5 ~67 ~136 ~25 ~67 wool 15
setblock ~144 ~5 ~8 wool 15
fill ~144 ~5 ~13 ~145 ~5 ~13 wool 15
fill ~144 ~5 ~70 ~145 ~5 ~70 wool 15
fill ~144 ~5 ~75 ~144 ~6 ~75 wool 15
fill ~146 ~5 ~9 ~146 ~7 ~9 wool 8
fill ~146 ~5 ~14 ~149 ~5 ~14 wool 15
fill ~146 ~5 ~69 ~149 ~5 ~69 wool 15
fill ~149 ~5 ~10 ~151 ~5 ~10 wool 8
fill ~149 ~5 ~73 ~151 ~5 ~73 wool 8
fill ~150 ~5 ~15 ~157 ~5 ~15 wool 15
fill ~150 ~5 ~68 ~157 ~5 ~68 wool 15
fill ~156 ~5 ~10 ~158 ~5 ~10 wool 8
fill ~156 ~5 ~73 ~158 ~5 ~73 wool 8
fill ~158 ~5 ~14 ~161 ~5 ~14 wool 15
fill ~158 ~5 ~69 ~161 ~5 ~69 wool 15
fill ~161 ~5 ~74 ~161 ~7 ~74 wool 8
fill ~162 ~5 ~13 ~163 ~5 ~13 wool 15
fill ~162 ~5 ~70 ~163 ~5 ~70 wool 15
setblock ~163 ~5 ~8 wool 15
fill ~163 ~5 ~75 ~163 ~6 ~75 wool 15
fill ~171 ~5 ~9 ~173 ~5 ~9 wool 0
fill ~171 ~5 ~74 ~173 ~5 ~74 wool 0
fill ~174 ~5 ~9 ~174 ~8 ~9 wool 8
fill ~174 ~5 ~10 ~176 ~5 ~10 wool 8
fill ~174 ~5 ~73 ~176 ~5 ~73 wool 8
fill ~174 ~5 ~74 ~174 ~8 ~74 wool 8
fill ~177 ~5 ~11 ~177 ~8 ~11 wool 8
fill ~177 ~5 ~12 ~177 ~6 ~12 wool 8
fill ~177 ~5 ~13 ~177 ~6 ~13 wool 8
fill ~177 ~5 ~14 ~177 ~6 ~14 wool 8
fill ~177 ~5 ~15 ~177 ~6 ~15 wool 8
fill ~177 ~5 ~16 ~177 ~6 ~16 wool 8
fill ~177 ~5 ~17 ~177 ~6 ~17 wool 8
fill ~177 ~5 ~18 ~177 ~6 ~18 wool 8
fill ~177 ~5 ~19 ~177 ~6 ~19 wool 8
fill ~177 ~5 ~20 ~177 ~6 ~20 wool 8
fill ~177 ~5 ~21 ~177 ~6 ~21 wool 8
fill ~177 ~5 ~22 ~177 ~6 ~22 wool 8
fill ~177 ~5 ~23 ~177 ~6 ~23 wool 8
fill ~177 ~5 ~24 ~177 ~6 ~24 wool 8
fill ~177 ~5 ~25 ~177 ~6 ~25 wool 8
fill ~177 ~5 ~26 ~177 ~6 ~26 wool 8
fill ~177 ~5 ~27 ~177 ~6 ~27 wool 8
fill ~177 ~5 ~28 ~177 ~6 ~28 wool 8
fill ~177 ~5 ~29 ~177 ~6 ~29 wool 8
fill ~177 ~5 ~30 ~177 ~6 ~30 wool 8
fill ~177 ~5 ~31 ~177 ~6 ~31 wool 8
fill ~177 ~5 ~32 ~177 ~6 ~32 wool 8
fill ~177 ~5 ~33 ~177 ~6 ~33 wool 8
fill ~177 ~5 ~34 ~177 ~6 ~34 wool 8
fill ~177 ~5 ~35 ~177 ~6 ~35 wool 8
fill ~177 ~5 ~36 ~177 ~5 ~46 wool 0
fill ~177 ~5 ~47 ~177 ~7 ~47 wool 15
fill ~177 ~5 ~48 ~177 ~6 ~48 wool 8
fill ~177 ~5 ~49 ~177 ~6 ~49 wool 8
fill ~177 ~5 ~50 ~177 ~6 ~50 wool 8
fill ~177 ~5 ~51 ~177 ~6 ~51 wool 8
fill ~177 ~5 ~52 ~177 ~6 ~52 wool 8
fill ~177 ~5 ~53 ~177 ~6 ~53 wool 8
fill ~177 ~5 ~54 ~177 ~6 ~54 wool 8
fill ~177 ~5 ~55 ~177 ~6 ~55 wool 8
fill ~177 ~5 ~56 ~177 ~6 ~56 wool 8
fill ~177 ~5 ~57 ~177 ~6 ~57 wool 8
fill ~177 ~5 ~58 ~177 ~6 ~58 wool 8
fill ~177 ~5 ~59 ~177 ~6 ~59 wool 8
fill ~177 ~5 ~60 ~177 ~6 ~60 wool 8
fill ~177 ~5 ~61 ~177 ~6 ~61 wool 8
fill ~177 ~5 ~62 ~177 ~6 ~62 wool 8
fill ~177 ~5 ~63 ~177 ~6 ~63 wool 8
fill ~177 ~5 ~64 ~177 ~6 ~64 wool 8
fill ~177 ~5 ~65 ~177 ~6 ~65 wool 8
fill ~177 ~5 ~66 ~177 ~6 ~66 wool 8
fill ~177 ~5 ~67 ~177 ~6 ~67 wool 8
fill ~177 ~5 ~68 ~177 ~6 ~68 wool 8
fill ~177 ~5 ~69 ~177 ~6 ~69 wool 8
fill ~177 ~5 ~70 ~177 ~6 ~70 wool 8
fill ~177 ~5 ~71 ~177 ~6 ~71 wool 8
fill ~177 ~5 ~72 ~177 ~8 ~72 wool 8
fill ~15 ~6 ~11 ~15 ~8 ~11 wool 8
fill ~15 ~6 ~12 ~15 ~7 ~12 wool 8
fill ~15 ~6 ~13 ~15 ~7 ~13 wool 8
fill ~15 ~6 ~14 ~15 ~7 ~14 wool 8
fill ~15 ~6 ~15 ~15 ~7 ~15 wool 8
fill ~15 ~6 ~16 ~15 ~7 ~16 wool 8
fill ~15 ~6 ~17 ~15 ~7 ~17 wool 8
fill ~15 ~6 ~18 ~15 ~7 ~18 wool 8
fill ~15 ~6 ~19 ~15 ~7 ~19 wool 8
fill ~15 ~6 ~20 ~15 ~7 ~20 wool 8
fill ~15 ~6 ~21 ~15 ~7 ~21 wool 8
fill ~15 ~6 ~22 ~15 ~7 ~22 wool 8
fill ~15 ~6 ~23 ~15 ~7 ~23 wool 8
fill ~15 ~6 ~24 ~15 ~7 ~24 wool 8
fill ~15 ~6 ~25 ~15 ~7 ~25 wool 8
fill ~15 ~6 ~26 ~15 ~7 ~26 wool 8
fill ~15 ~6 ~27 ~15 ~7 ~27 wool 8
fill ~15 ~6 ~28 ~15 ~7 ~28 wool 8
fill ~15 ~6 ~29 ~15 ~7 ~29 wool 8
fill ~15 ~6 ~30 ~15 ~7 ~30 wool 8
fill ~15 ~6 ~31 ~15 ~7 ~31 wool 8
fill ~15 ~6 ~32 ~15 ~7 ~32 wool 8
fill ~15 ~6 ~33 ~15 ~7 ~33 wool 8
fill ~15 ~6 ~34 ~15 ~7 ~34 wool 8
fill ~15 ~6 ~35 ~15 ~7 ~35 wool 8
fill ~15 ~6 ~36 ~15 ~7 ~36 wool 8
fill ~15 ~6 ~37 ~15 ~7 ~37 wool 8
fill ~15 ~6 ~38 ~15 ~7 ~38 wool 8
fill ~15 ~6 ~39 ~15 ~7 ~39 wool 8
fill ~15 ~6 ~40 ~15 ~7 ~40 wool 8
fill ~15 ~6 ~41 ~15 ~7 ~41 wool 8
fill ~15 ~6 ~42 ~15 ~7 ~42 wool 8
fill ~15 ~6 ~43 ~15 ~7 ~43 wool 8
fill ~15 ~6 ~44 ~15 ~7 ~44 wool 8
fill ~15 ~6 ~45 ~15 ~7 ~45 wool 8
fill ~15 ~6 ~46 ~15 ~7 ~46 wool 8
fill ~15 ~6 ~47 ~15 ~7 ~47 wool 8
fill ~15 ~6 ~48 ~15 ~7 ~48 wool 8
fill ~15 ~6 ~49 ~15 ~7 ~49 wool 8
fill ~15 ~6 ~50 ~15 ~7 ~50 wool 8
fill ~15 ~6 ~51 ~15 ~7 ~51 wool 8
fill ~15 ~6 ~52 ~15 ~7 ~52 wool 8
fill ~15 ~6 ~53 ~15 ~7 ~53 wool 8
fill ~15 ~6 ~54 ~15 ~7 ~54 wool 8
fill ~15 ~6 ~55 ~15 ~7 ~55 wool 8
fill ~15 ~6 ~56 ~15 ~7 ~56 wool 8
fill ~15 ~6 ~57 ~15 ~7 ~57 wool 8
fill ~15 ~6 ~58 ~15 ~7 ~58 wool 8
fill ~15 ~6 ~59 ~15 ~7 ~59 wool 8
fill ~15 ~6 ~60 ~15 ~7 ~60 wool 8
fill ~15 ~6 ~61 ~15 ~7 ~61 wool 8
fill ~15 ~6 ~62 ~15 ~7 ~62 wool 8
fill ~15 ~6 ~63 ~15 ~7 ~63 wool 8
fill ~15 ~6 ~64 ~15 ~7 ~64 wool 8
fill ~15 ~6 ~65 ~15 ~7 ~65 wool 8
fill ~15 ~6 ~66 ~15 ~7 ~66 wool 8
fill ~15 ~6 ~67 ~15 ~7 ~67 wool 8
fill ~15 ~6 ~68 ~15 ~7 ~68 wool 8
fill ~15 ~6 ~69 ~15 ~7 ~69 wool 8
fill ~15 ~6 ~70 ~15 ~7 ~70 wool 8
fill ~15 ~6 ~71 ~15 ~7 ~71 wool 8
fill ~15 ~6 ~72 ~15 ~8 ~72 wool 8
fill ~16 ~6 ~11 ~17 ~6 ~11 wool 14
fill ~16 ~6 ~72 ~17 ~6 ~72 wool 14
fill ~16 ~6 ~73 ~17 ~6 ~73 wool 8
fill ~17 ~6 ~12 ~17 ~23 ~12 wool 15
fill ~17 ~6 ~13 ~17 ~23 ~13 wool 15
fill ~17 ~6 ~14 ~17 ~23 ~14 wool 15
fill ~17 ~6 ~15 ~17 ~23 ~15 wool 15
fill ~17 ~6 ~16 ~17 ~23 ~16 wool 15
fill ~17 ~6 ~17 ~17 ~23 ~17 wool 15
fill ~17 ~6 ~18 ~17 ~23 ~18 wool 15
fill ~17 ~6 ~19 ~17 ~23 ~19 wool 15
fill ~17 ~6 ~20 ~17 ~23 ~20 wool 15
fill ~17 ~6 ~21 ~17 ~23 ~21 wool 15
fill ~17 ~6 ~22 ~17 ~23 ~22 wool 15
fill ~17 ~6 ~23 ~17 ~23 ~23 wool 15
fill ~17 ~6 ~24 ~17 ~23 ~24 wool 15
fill ~17 ~6 ~25 ~17 ~23 ~25 wool 15
fill ~17 ~6 ~26 ~17 ~23 ~26 wool 15
fill ~17 ~6 ~27 ~17 ~23 ~27 wool 15
fill ~17 ~6 ~28 ~17 ~23 ~28 wool 15
fill ~17 ~6 ~29 ~17 ~23 ~29 wool 15
fill ~17 ~6 ~30 ~17 ~23 ~30 wool 15
fill ~17 ~6 ~31 ~17 ~23 ~31 wool 15
fill ~17 ~6 ~32 ~17 ~23 ~32 wool 15
fill ~17 ~6 ~33 ~17 ~23 ~33 wool 15
fill ~17 ~6 ~34 ~17 ~23 ~34 wool 15
fill ~17 ~6 ~35 ~17 ~23 ~35 wool 15
fill ~17 ~6 ~36 ~17 ~8 ~36 wool 15
fill ~17 ~6 ~37 ~17 ~23 ~37 wool 15
fill ~17 ~6 ~38 ~17 ~23 ~38 wool 15
fill ~17 ~6 ~39 ~17 ~23 ~39 wool 15
fill ~17 ~6 ~40 ~17 ~23 ~40 wool 15
fill ~17 ~6 ~41 ~17 ~23 ~41 wool 15
fill ~17 ~6 ~42 ~17 ~23 ~42 wool 15
fill ~17 ~6 ~43 ~17 ~23 ~43 wool 15
fill ~17 ~6 ~44 ~17 ~23 ~44 wool 15
fill ~17 ~6 ~45 ~17 ~23 ~45 wool 15
fill ~17 ~6 ~46 ~17 ~23 ~46 wool 15
fill ~17 ~6 ~47 ~17 ~23 ~47 wool 15
fill ~17 ~6 ~48 ~17 ~8 ~48 wool 15
fill ~17 ~6 ~49 ~17 ~23 ~49 wool 15
fill ~17 ~6 ~50 ~17 ~23 ~50 wool 15
fill ~17 ~6 ~51 ~17 ~23 ~51 wool 15
fill ~17 ~6 ~52 ~17 ~23 ~52 wool 15
fill ~17 ~6 ~53 ~17 ~23 ~53 wool 15
fill ~17 ~6 ~54 ~17 ~23 ~54 wool 15
fill ~17 ~6 ~55 ~17 ~23 ~55 wool 15
fill ~17 ~6 ~56 ~17 ~23 ~56 wool 15
fill ~17 ~6 ~57 ~17 ~23 ~57 wool 15
fill ~17 ~6 ~58 ~17 ~23 ~58 wool 15
fill ~17 ~6 ~59 ~17 ~23 ~59 wool 15
fill ~17 ~6 ~60 ~17 ~23 ~60 wool 15
fill ~17 ~6 ~61 ~17 ~23 ~61 wool 15
fill ~17 ~6 ~62 ~17 ~23 ~62 wool 15
fill ~17 ~6 ~63 ~17 ~23 ~63 wool 15
fill ~17 ~6 ~64 ~17 ~23 ~64 wool 15
fill ~17 ~6 ~65 ~17 ~23 ~65 wool 15
fill ~17 ~6 ~66 ~17 ~23 ~66 wool 15
fill ~17 ~6 ~67 ~17 ~23 ~67 wool 15
fill ~17 ~6 ~68 ~17 ~23 ~68 wool 15
fill ~17 ~6 ~69 ~17 ~23 ~69 wool 15
fill ~17 ~6 ~70 ~17 ~23 ~70 wool 15
fill ~17 ~6 ~71 ~17 ~23 ~71 wool 15
fill ~18 ~6 ~10 ~34 ~6 ~10 wool 15
fill ~18 ~6 ~11 ~18 ~23 ~11 wool 15
fill ~18 ~6 ~72 ~18 ~23 ~72 wool 15
fill ~18 ~6 ~73 ~33 ~6 ~73 wool 15
fill ~19 ~6 ~60 ~86 ~6 ~60 wool 7
fill ~19 ~6 ~62 ~86 ~6 ~62 wool 7
fill ~21 ~6 ~74 ~33 ~6 ~74 wool 0
fill ~22 ~6 ~9 ~34 ~6 ~9 wool 0
fill ~27 ~6 ~18 ~60 ~6 ~18 wool 7
fill ~27 ~6 ~19 ~60 ~6 ~19 wool 7
fill ~27 ~6 ~20 ~60 ~6 ~20 wool 7
fill ~27 ~6 ~21 ~60 ~6 ~21 wool 7
fill ~27 ~6 ~22 ~60 ~6 ~22 wool 7
fill ~27 ~6 ~23 ~60 ~6 ~23 wool 7
fill ~27 ~6 ~24 ~60 ~6 ~24 wool 7
fill ~27 ~6 ~25 ~60 ~6 ~25 wool 7
fill ~27 ~6 ~26 ~60 ~6 ~26 wool 7
fill ~27 ~6 ~27 ~60 ~6 ~27 wool 7
fill ~27 ~6 ~28 ~60 ~6 ~28 wool 7
fill ~27 ~6 ~29 ~60 ~6 ~29 wool 7
fill ~27 ~6 ~30 ~60 ~6 ~30 wool 7
fill ~27 ~6 ~31 ~60 ~6 ~31 wool 7
fill ~27 ~6 ~32 ~60 ~6 ~32 wool 7
fill ~33 ~6 ~75 ~67 ~6 ~75 wool 0
fill ~34 ~6 ~8 ~68 ~6 ~8 wool 0
fill ~34 ~6 ~11 ~34 ~23 ~11 wool 15
fill ~34 ~6 ~12 ~34 ~21 ~12 wool 15
fill ~34 ~6 ~13 ~34 ~21 ~13 wool 15
fill ~34 ~6 ~14 ~34 ~21 ~14 wool 15
fill ~34 ~6 ~15 ~34 ~21 ~15 wool 15
fill ~34 ~6 ~16 ~34 ~21 ~16 wool 15
fill ~34 ~6 ~17 ~62 ~6 ~17 wool 15
fill ~34 ~6 ~66 ~68 ~6 ~66 wool 15
fill ~34 ~6 ~67 ~34 ~21 ~67 wool 15
fill ~34 ~6 ~68 ~34 ~21 ~68 wool 15
fill ~34 ~6 ~69 ~34 ~21 ~69 wool 15
fill ~34 ~6 ~70 ~34 ~21 ~70 wool 15
fill ~34 ~6 ~71 ~34 ~21 ~71 wool 15
fill ~34 ~6 ~72 ~34 ~23 ~72 wool 15
fill ~39 ~6 ~72 ~39 ~11 ~72 wool 15
fill ~39 ~6 ~73 ~39 ~11 ~73 wool 15
fill ~40 ~6 ~10 ~40 ~11 ~10 wool 15
fill ~40 ~6 ~11 ~40 ~11 ~11 wool 15
fill ~41 ~6 ~70 ~42 ~6 ~70 wool 15
fill ~42 ~6 ~13 ~43 ~6 ~13 wool 15
fill ~43 ~6 ~69 ~45 ~6 ~69 wool 15
fill ~44 ~6 ~14 ~46 ~6 ~14 wool 15
fill ~46 ~6 ~68 ~55 ~6 ~68 wool 15
fill ~47 ~6 ~15 ~56 ~6 ~15 wool 15
fill ~47 ~6 ~73 ~54 ~6 ~73 wool 8
fill ~48 ~6 ~10 ~55 ~6 ~10 wool 8
fill ~50 ~6 ~74 ~51 ~6 ~74 wool 8
fill ~51 ~6 ~9 ~52 ~6 ~9 wool 8
fill ~56 ~6 ~69 ~58 ~6 ~69 wool 15
fill ~57 ~6 ~14 ~59 ~6 ~14 wool 15
fill ~59 ~6 ~70 ~60 ~6 ~70 wool 15
fill ~60 ~6 ~13 ~61 ~6 ~13 wool 15
fill ~62 ~6 ~72 ~62 ~11 ~72 wool 15
fill ~62 ~6 ~73 ~62 ~11 ~73 wool 15
fill ~63 ~6 ~10 ~63 ~11 ~10 wool 15
fill ~63 ~6 ~11 ~63 ~11 ~11 wool 15
fill ~68 ~6 ~67 ~68 ~21 ~67 wool 15
fill ~68 ~6 ~68 ~68 ~21 ~68 wool 15
fill ~68 ~6 ~69 ~68 ~21 ~69 wool 15
fill ~68 ~6 ~70 ~68 ~21 ~70 wool 15
fill ~68 ~6 ~71 ~68 ~21 ~71 wool 15
fill ~68 ~6 ~72 ~68 ~23 ~72 wool 15
fill ~68 ~6 ~73 ~136 ~6 ~73 wool 15
fill ~68 ~6 ~74 ~136 ~6 ~74 wool 0
fill ~69 ~6 ~9 ~136 ~6 ~9 wool 0
fill ~69 ~6 ~10 ~136 ~6 ~10 wool 15
fill ~136 ~6 ~11 ~136 ~25 ~11 wool 15
fill ~136 ~6 ~68 ~136 ~25 ~68 wool 15
fill ~136 ~6 ~69 ~136 ~25 ~69 wool 15
fill ~136 ~6 ~70 ~136 ~25 ~70 wool 15
fill ~136 ~6 ~71 ~136 ~25 ~71 wool 15
fill ~136 ~6 ~72 ~136 ~23 ~72 wool 15
fill ~142 ~6 ~10 ~142 ~11 ~10 wool 15
fill ~142 ~6 ~11 ~142 ~11 ~11 wool 15
fill ~142 ~6 ~72 ~142 ~11 ~72 wool 15
fill ~142 ~6 ~73 ~142 ~11 ~73 wool 15
fill ~144 ~6 ~8 ~144 ~11 ~8 wool 0
fill ~144 ~6 ~13 ~145 ~6 ~13 wool 15
fill ~144 ~6 ~70 ~145 ~6 ~70 wool 15
fill ~146 ~6 ~14 ~148 ~6 ~14 wool 15
fill ~146 ~6 ~69 ~148 ~6 ~69 wool 15
fill ~149 ~6 ~15 ~158 ~6 ~15 wool 15
fill ~149 ~6 ~68 ~158 ~6 ~68 wool 15
fill ~150 ~6 ~10 ~157 ~6 ~10 wool 8
fill ~150 ~6 ~73 ~157 ~6 ~73 wool 8
fill ~153 ~6 ~9 ~154 ~6 ~9 wool 8
fill ~153 ~6 ~74 ~154 ~6 ~74 wool 8
fill ~159 ~6 ~14 ~161 ~6 ~14 wool 15
fill ~159 ~6 ~69 ~161 ~6 ~69 wool 15
fill ~162 ~6 ~13 ~163 ~6 ~13 wool 15
fill ~162 ~6 ~70 ~163 ~6 ~70 wool 15
fill ~163 ~6 ~8 ~163 ~11 ~8 wool 0
fill ~165 ~6 ~10 ~165 ~11 ~10 wool 15
fill ~165 ~6 ~11 ~165 ~11 ~11 wool 15
fill ~165 ~6 ~72 ~165 ~11 ~72 wool 15
fill ~165 ~6 ~73 ~165 ~11 ~73 wool 15
fill ~171 ~6 ~9 ~173 ~6 ~9 wool 0
fill ~171 ~6 ~74 ~173 ~6 ~74 wool 0
fill ~174 ~6 ~10 ~176 ~6 ~10 wool 8
fill ~174 ~6 ~73 ~176 ~6 ~73 wool 8
fill ~177 ~6 ~36 ~177 ~7 ~36 wool 15
fill ~177 ~6 ~37 ~177 ~10 ~37 wool 0
fill ~177 ~6 ~38 ~177 ~10 ~38 wool 0
fill ~177 ~6 ~39 ~177 ~10 ~39 wool 0
fill ~177 ~6 ~40 ~177 ~10 ~40 wool 0
fill ~177 ~6 ~41 ~177 ~10 ~41 wool 0
fill ~177 ~6 ~42 ~177 ~10 ~42 wool 0
fill ~177 ~6 ~43 ~177 ~10 ~43 wool 0
fill ~177 ~6 ~44 ~177 ~10 ~44 wool 0
fill ~177 ~6 ~45 ~177 ~10 ~45 wool 0
fill ~177 ~6 ~46 ~177 ~10 ~46 wool 0
fill ~178 ~6 ~14 ~179 ~6 ~14 wool 8
fill ~178 ~6 ~15 ~179 ~6 ~15 wool 8
fill ~178 ~6 ~16 ~179 ~6 ~16 wool 8
fill ~178 ~6 ~17 ~179 ~6 ~17 wool 8
fill ~178 ~6 ~18 ~179 ~6 ~18 wool 8
fill ~178 ~6 ~19 ~179 ~6 ~19 wool 8
fill ~178 ~6 ~20 ~179 ~6 ~20 wool 8
fill ~178 ~6 ~63 ~179 ~6 ~63 wool 8
fill ~178 ~6 ~64 ~179 ~6 ~64 wool 8
fill ~178 ~6 ~65 ~179 ~6 ~65 wool 8
fill ~178 ~6 ~66 ~179 ~6 ~66 wool 8
fill ~178 ~6 ~67 ~179 ~6 ~67 wool 8
fill ~178 ~6 ~68 ~179 ~6 ~68 wool 8
fill ~178 ~6 ~69 ~179 ~6 ~69 wool 8
fill ~14 ~7 ~74 ~14 ~9 ~74 wool 8
fill ~15 ~7 ~9 ~15 ~9 ~9 wool 8
fill ~15 ~7 ~74 ~33 ~7 ~74 wool 0
fill ~15 ~7 ~75 ~16 ~7 ~75 wool 8
fill ~16 ~7 ~8 ~17 ~7 ~8 wool 8
fill ~16 ~7 ~9 ~34 ~7 ~9 wool 0
fill ~16 ~7 ~11 ~17 ~7 ~11 wool 14
fill ~16 ~7 ~72 ~17 ~7 ~72 wool 14
fill ~16 ~7 ~73 ~17 ~7 ~73 wool 8
fill ~18 ~7 ~10 ~34 ~7 ~10 wool 15
fill ~18 ~7 ~73 ~33 ~7 ~73 wool 15
fill ~27 ~7 ~18 ~60 ~7 ~18 wool 7
fill ~27 ~7 ~19 ~27 ~20 ~19 wool 7
fill ~27 ~7 ~20 ~27 ~20 ~20 wool 7
fill ~27 ~7 ~21 ~27 ~20 ~21 wool 7
fill ~27 ~7 ~22 ~27 ~20 ~22 wool 7
fill ~27 ~7 ~23 ~27 ~20 ~23 wool 7
fill ~27 ~7 ~24 ~27 ~20 ~24 wool 7
fill ~27 ~7 ~25 ~27 ~20 ~25 wool 7
fill ~27 ~7 ~26 ~27 ~20 ~26 wool 7
fill ~27 ~7 ~27 ~27 ~20 ~27 wool 7
fill ~27 ~7 ~28 ~27 ~20 ~28 wool 7
fill ~27 ~7 ~29 ~27 ~20 ~29 wool 7
fill ~27 ~7 ~30 ~27 ~20 ~30 wool 7
fill ~27 ~7 ~31 ~27 ~20 ~31 wool 7
fill ~27 ~7 ~32 ~60 ~7 ~32 wool 7
fill ~33 ~7 ~75 ~67 ~7 ~75 wool 0
fill ~34 ~7 ~8 ~68 ~7 ~8 wool 0
fill ~34 ~7 ~17 ~62 ~7 ~17 wool 15
fill ~34 ~7 ~66 ~68 ~7 ~66 wool 15
fill ~40 ~7 ~54 ~86 ~7 ~54 wool 7
fill ~40 ~7 ~55 ~86 ~7 ~55 wool 7
fill ~40 ~7 ~56 ~86 ~7 ~56 wool 7
fill ~40 ~7 ~57 ~86 ~7 ~57 wool 7
fill ~40 ~7 ~58 ~86 ~7 ~58 wool 7
fill ~40 ~7 ~59 ~86 ~7 ~59 wool 7
fill ~40 ~7 ~60 ~86 ~7 ~60 wool 7
fill ~40 ~7 ~61 ~86 ~7 ~61 wool 7
fill ~40 ~7 ~62 ~86 ~7 ~62 wool 7
fill ~41 ~7 ~70 ~42 ~7 ~70 wool 15
fill ~42 ~7 ~13 ~43 ~7 ~13 wool 15
fill ~42 ~7 ~74 ~42 ~10 ~74 wool 8
fill ~43 ~7 ~9 ~43 ~10 ~9 wool 8
fill ~43 ~7 ~69 ~45 ~7 ~69 wool 15
fill ~44 ~7 ~14 ~46 ~7 ~14 wool 15
fill ~46 ~7 ~68 ~55 ~7 ~68 wool 15
fill ~47 ~7 ~15 ~56 ~7 ~15 wool 15
fill ~48 ~7 ~73 ~48 ~11 ~73 wool 8
fill ~49 ~7 ~10 ~49 ~11 ~10 wool 8
setblock ~49 ~7 ~74 wool 8
setblock ~50 ~7 ~9 wool 8
setblock ~52 ~7 ~74 wool 8
setblock ~53 ~7 ~9 wool 8
fill ~53 ~7 ~73 ~53 ~11 ~73 wool 8
fill ~54 ~7 ~10 ~54 ~11 ~10 wool 8
fill ~56 ~7 ~69 ~58 ~7 ~69 wool 15
fill ~57 ~7 ~14 ~59 ~7 ~14 wool 15
fill ~59 ~7 ~70 ~60 ~7 ~70 wool 15
fill ~59 ~7 ~74 ~59 ~10 ~74 wool 8
fill ~60 ~7 ~9 ~60 ~10 ~9 wool 8
fill ~60 ~7 ~13 ~61 ~7 ~13 wool 15
fill ~60 ~7 ~19 ~60 ~20 ~19 wool 7
fill ~60 ~7 ~20 ~60 ~20 ~20 wool 7
fill ~60 ~7 ~21 ~60 ~20 ~21 wool 7
fill ~60 ~7 ~22 ~60 ~20 ~22 wool 7
fill ~60 ~7 ~23 ~60 ~20 ~23 wool 7
fill ~60 ~7 ~24 ~60 ~20 ~24 wool 7
fill ~60 ~7 ~25 ~60 ~20 ~25 wool 7
fill ~60 ~7 ~26 ~60 ~20 ~26 wool 7
fill ~60 ~7 ~27 ~60 ~20 ~27 wool 7
fill ~60 ~7 ~28 ~60 ~20 ~28 wool 7
fill ~60 ~7 ~29 ~60 ~20 ~29 wool 7
fill ~60 ~7 ~30 ~60 ~20 ~30 wool 7
fill ~60 ~7 ~31 ~60 ~20 ~31 wool 7
fill ~68 ~7 ~73 ~136 ~7 ~73 wool 15
fill ~68 ~7 ~74 ~136 ~7 ~74 wool 0
fill ~69 ~7 ~9 ~136 ~7 ~9 wool 0
fill ~69 ~7 ~10 ~136 ~7 ~10 wool 15
fill ~144 ~7 ~13 ~145 ~7 ~13 wool 15
fill ~144 ~7 ~70 ~145 ~7 ~70 wool 15
fill ~144 ~7 ~75 ~144 ~10 ~75 wool 0
fill ~145 ~7 ~9 ~145 ~10 ~9 wool 8
fill ~145 ~7 ~74 ~145 ~10 ~74 wool 8
fill ~146 ~7 ~14 ~148 ~7 ~14 wool 15
fill ~146 ~7 ~69 ~148 ~7 ~69 wool 15
fill ~149 ~7 ~15 ~158 ~7 ~15 wool 15
fill ~149 ~7 ~68 ~158 ~7 ~68 wool 15
fill ~151 ~7 ~10 ~151 ~11 ~10 wool 8
fill ~151 ~7 ~73 ~151 ~11 ~73 wool 8
setblock ~152 ~7 ~9 wool 8
setblock ~152 ~7 ~74 wool 8
fill ~153 ~7 ~8 ~154 ~7 ~8 wool 8
fill ~153 ~7 ~75 ~154 ~7 ~75 wool 8
setblock ~155 ~7 ~9 wool 8
setblock ~155 ~7 ~74 wool 8
fill ~156 ~7 ~10 ~156 ~11 ~10 wool 8
fill ~156 ~7 ~73 ~156 ~11 ~73 wool 8
fill ~159 ~7 ~14 ~161 ~7 ~14 wool 15
fill ~159 ~7 ~69 ~161 ~7 ~69 wool 15
fill ~162 ~7 ~9 ~162 ~10 ~9 wool 8
fill ~162 ~7 ~13 ~163 ~7 ~13 wool 15
fill ~162 ~7 ~70 ~163 ~7 ~70 wool 15
fill ~162 ~7 ~74 ~162 ~10 ~74 wool 8
fill ~163 ~7 ~75 ~163 ~10 ~75 wool 0
fill ~171 ~7 ~9 ~173 ~7 ~9 wool 0
fill ~171 ~7 ~74 ~173 ~7 ~74 wool 0
fill ~174 ~7 ~10 ~177 ~7 ~10 wool 8
fill ~174 ~7 ~73 ~177 ~7 ~73 wool 8
fill ~178 ~7 ~11 ~178 ~11 ~11 wool 8
fill ~178 ~7 ~12 ~178 ~11 ~12 wool 8
fill ~178 ~7 ~13 ~179 ~7 ~13 wool 8
fill ~178 ~7 ~14 ~178 ~9 ~14 wool 1
fill ~178 ~7 ~15 ~178 ~9 ~15 wool 1
fill ~178 ~7 ~16 ~178 ~9 ~16 wool 1
fill ~178 ~7 ~17 ~178 ~9 ~17 wool 1
fill ~178 ~7 ~18 ~178 ~9 ~18 wool 1
fill ~178 ~7 ~19 ~178 ~9 ~19 wool 1
fill ~178 ~7 ~20 ~178 ~9 ~20 wool 1
fill ~178 ~7 ~21 ~179 ~7 ~21 wool 8
fill ~178 ~7 ~22 ~178 ~11 ~22 wool 8
fill ~178 ~7 ~23 ~178 ~11 ~23 wool 8
fill ~178 ~7 ~24 ~178 ~7 ~35 wool 8
fill ~178 ~7 ~48 ~178 ~11 ~48 wool 8
fill ~178 ~7 ~49 ~178 ~11 ~49 wool 8
fill ~178 ~7 ~50 ~178 ~7 ~62 wool 8
fill ~178 ~7 ~63 ~178 ~9 ~63 wool 1
fill ~178 ~7 ~64 ~178 ~9 ~64 wool 1
fill ~178 ~7 ~65 ~178 ~9 ~65 wool 1
fill ~178 ~7 ~66 ~178 ~9 ~66 wool 1
fill ~178 ~7 ~67 ~178 ~9 ~67 wool 1
fill ~178 ~7 ~68 ~178 ~9 ~68 wool 1
fill ~178 ~7 ~69 ~178 ~9 ~69 wool 1
fill ~178 ~7 ~70 ~179 ~7 ~70 wool 8
fill ~178 ~7 ~71 ~178 ~11 ~71 wool 8
fill ~178 ~7 ~72 ~178 ~11 ~72 wool 8
fill ~179 ~7 ~62 ~179 ~9 ~62 wool 8
fill ~14 ~8 ~9 ~14 ~19 ~9 wool 0
fill ~15 ~8 ~12 ~16 ~8 ~12 wool 7
fill ~15 ~8 ~13 ~16 ~8 ~13 wool 7
fill ~15 ~8 ~14 ~16 ~8 ~14 wool 7
fill ~15 ~8 ~15 ~16 ~8 ~15 wool 7
fill ~15 ~8 ~16 ~16 ~8 ~16 wool 7
fill ~15 ~8 ~17 ~16 ~8 ~17 wool 7
fill ~15 ~8 ~18 ~16 ~8 ~18 wool 7
fill ~15 ~8 ~19 ~16 ~8 ~19 wool 7
fill ~15 ~8 ~20 ~16 ~8 ~20 wool 7
fill ~15 ~8 ~21 ~16 ~8 ~21 wool 7
fill ~15 ~8 ~22 ~16 ~8 ~22 wool 7
fill ~15 ~8 ~23 ~16 ~8 ~23 wool 7
fill ~15 ~8 ~24 ~16 ~8 ~24 wool 7
fill ~15 ~8 ~25 ~16 ~8 ~25 wool 7
fill ~15 ~8 ~26 ~16 ~8 ~26 wool 7
fill ~15 ~8 ~27 ~16 ~8 ~27 wool 7
fill ~15 ~8 ~28 ~16 ~8 ~28 wool 7
fill ~15 ~8 ~29 ~16 ~8 ~29 wool 7
fill ~15 ~8 ~30 ~16 ~8 ~30 wool 7
fill ~15 ~8 ~31 ~16 ~8 ~31 wool 7
fill ~15 ~8 ~32 ~16 ~8 ~32 wool 7
fill ~15 ~8 ~33 ~16 ~8 ~33 wool 7
fill ~15 ~8 ~34 ~16 ~8 ~34 wool 7
fill ~15 ~8 ~35 ~15 ~14 ~35 double_stone_slab 0
fill ~15 ~8 ~36 ~15 ~8 ~49 double_stone_slab 0
fill ~15 ~8 ~50 ~16 ~8 ~50 wool 7
fill ~15 ~8 ~51 ~16 ~8 ~51 wool 7
fill ~15 ~8 ~52 ~16 ~8 ~52 wool 7
fill ~15 ~8 ~53 ~16 ~8 ~53 wool 7
fill ~15 ~8 ~54 ~16 ~8 ~54 wool 7
fill ~15 ~8 ~55 ~16 ~8 ~55 wool 7
fill ~15 ~8 ~56 ~16 ~8 ~56 wool 7
fill ~15 ~8 ~57 ~16 ~8 ~57 wool 7
fill ~15 ~8 ~58 ~16 ~8 ~58 wool 7
fill ~15 ~8 ~59 ~16 ~8 ~59 wool 7
fill ~15 ~8 ~60 ~16 ~8 ~60 wool 7
fill ~15 ~8 ~61 ~16 ~8 ~61 wool 7
fill ~15 ~8 ~62 ~16 ~8 ~62 wool 7
fill ~15 ~8 ~63 ~16 ~8 ~63 wool 7
fill ~15 ~8 ~64 ~16 ~8 ~64 wool 7
fill ~15 ~8 ~65 ~16 ~8 ~65 wool 7
fill ~15 ~8 ~66 ~16 ~8 ~66 wool 7
fill ~15 ~8 ~67 ~16 ~8 ~67 wool 7
fill ~15 ~8 ~68 ~16 ~8 ~68 wool 7
fill ~15 ~8 ~69 ~16 ~8 ~69 wool 7
fill ~15 ~8 ~70 ~16 ~8 ~70 wool 7
fill ~15 ~8 ~71 ~16 ~8 ~71 wool 7
fill ~15 ~8 ~74 ~33 ~8 ~74 wool 0
fill ~15 ~8 ~75 ~16 ~8 ~75 wool 8
fill ~16 ~8 ~8 ~17 ~8 ~8 wool 8
fill ~16 ~8 ~9 ~34 ~8 ~9 wool 0
fill ~16 ~8 ~11 ~17 ~8 ~11 wool 14
fill ~16 ~8 ~35 ~16 ~8 ~37 wool 7
fill ~16 ~8 ~38 ~16 ~8 ~40 iron_block 0
fill ~16 ~8 ~41 ~16 ~8 ~71 wool 7
fill ~16 ~8 ~72 ~17 ~8 ~72 wool 14
fill ~16 ~8 ~73 ~17 ~8 ~73 wool 8
fill ~18 ~8 ~10 ~34 ~8 ~10 wool 15
fill ~18 ~8 ~73 ~33 ~8 ~73 wool 15
fill ~27 ~8 ~18 ~60 ~8 ~18 wool 7
fill ~27 ~8 ~32 ~60 ~8 ~32 wool 7
fill ~33 ~8 ~75 ~67 ~8 ~75 wool 0
fill ~34 ~8 ~8 ~68 ~8 ~8 wool 0
fill ~34 ~8 ~17 ~62 ~8 ~17 wool 15
fill ~34 ~8 ~66 ~68 ~8 ~66 wool 15
fill ~41 ~8 ~70 ~41 ~12 ~70 wool 15
fill ~42 ~8 ~13 ~42 ~12 ~13 wool 15
setblock ~42 ~8 ~56 wool 15
setblock ~42 ~8 ~60 wool 15
fill ~42 ~8 ~69 ~45 ~8 ~69 wool 15
fill ~43 ~8 ~14 ~46 ~8 ~14 wool 15
fill ~46 ~8 ~68 ~55 ~8 ~68 wool 15
fill ~47 ~8 ~15 ~56 ~8 ~15 wool 15
fill ~48 ~8 ~74 ~48 ~9 ~74 wool 8
fill ~49 ~8 ~9 ~49 ~9 ~9 wool 8
setblock ~49 ~8 ~56 wool 15
setblock ~49 ~8 ~60 wool 15
fill ~53 ~8 ~74 ~53 ~9 ~74 wool 8
fill ~54 ~8 ~9 ~54 ~9 ~9 wool 8
fill ~56 ~8 ~54 ~60 ~8 ~54 wool 15
fill ~56 ~8 ~55 ~61 ~8 ~55 wool 15
fill ~56 ~8 ~56 ~61 ~8 ~56 wool 15
fill ~56 ~8 ~57 ~61 ~8 ~57 wool 15
fill ~56 ~8 ~58 ~61 ~8 ~58 wool 15
fill ~56 ~8 ~59 ~61 ~8 ~59 wool 15
fill ~56 ~8 ~60 ~61 ~8 ~60 wool 15
fill ~56 ~8 ~61 ~60 ~8 ~61 wool 15
fill ~56 ~8 ~62 ~60 ~8 ~62 wool 15
fill ~56 ~8 ~69 ~59 ~8 ~69 wool 15
fill ~57 ~8 ~14 ~60 ~8 ~14 wool 15
fill ~57 ~8 ~63 ~59 ~8 ~63 wool 15
fill ~60 ~8 ~70 ~60 ~12 ~70 wool 15
fill ~61 ~8 ~13 ~61 ~12 ~13 wool 15
fill ~68 ~8 ~73 ~136 ~8 ~73 wool 15
fill ~68 ~8 ~74 ~102 ~8 ~74 wool 0
fill ~69 ~8 ~9 ~103 ~8 ~9 wool 0
fill ~69 ~8 ~10 ~136 ~8 ~10 wool 15
fill ~71 ~8 ~53 ~75 ~8 ~53 wool 15
fill ~71 ~8 ~54 ~76 ~8 ~54 wool 15
fill ~71 ~8 ~55 ~76 ~8 ~55 wool 15
fill ~71 ~8 ~56 ~76 ~8 ~56 wool 15
fill ~71 ~8 ~57 ~76 ~8 ~57 wool 15
fill ~71 ~8 ~58 ~76 ~8 ~58 wool 15
fill ~71 ~8 ~59 ~76 ~8 ~59 wool 15
fill ~71 ~8 ~60 ~75 ~8 ~60 wool 15
fill ~71 ~8 ~61 ~75 ~8 ~61 wool 15
fill ~72 ~8 ~62 ~74 ~8 ~62 wool 15
fill ~103 ~8 ~74 ~107 ~8 ~74 wool 14
fill ~104 ~8 ~9 ~108 ~8 ~9 wool 14
fill ~108 ~8 ~74 ~136 ~8 ~74 wool 0
fill ~109 ~8 ~9 ~136 ~8 ~9 wool 0
fill ~144 ~8 ~13 ~144 ~12 ~13 wool 15
fill ~144 ~8 ~70 ~144 ~12 ~70 wool 15
fill ~145 ~8 ~14 ~148 ~8 ~14 wool 15
fill ~145 ~8 ~69 ~148 ~8 ~69 wool 15
fill ~149 ~8 ~15 ~158 ~8 ~15 wool 15
fill ~149 ~8 ~68 ~158 ~8 ~68 wool 15
fill ~151 ~8 ~9 ~151 ~9 ~9 wool 8
fill ~151 ~8 ~74 ~151 ~9 ~74 wool 8
fill ~152 ~8 ~8 ~155 ~8 ~8 wool 8
fill ~152 ~8 ~75 ~155 ~8 ~75 wool 8
fill ~156 ~8 ~9 ~156 ~9 ~9 wool 8
fill ~156 ~8 ~74 ~156 ~9 ~74 wool 8
fill ~159 ~8 ~14 ~162 ~8 ~14 wool 15
fill ~159 ~8 ~69 ~162 ~8 ~69 wool 15
fill ~163 ~8 ~13 ~163 ~12 ~13 wool 15
fill ~163 ~8 ~70 ~163 ~12 ~70 wool 15
fill ~171 ~8 ~9 ~173 ~8 ~9 wool 0
fill ~171 ~8 ~74 ~173 ~8 ~74 wool 0
fill ~174 ~8 ~10 ~177 ~8 ~10 wool 8
fill ~174 ~8 ~73 ~177 ~8 ~73 wool 8
fill ~177 ~8 ~23 ~177 ~9 ~23 wool 15
fill ~177 ~8 ~24 ~177 ~9 ~24 wool 15
fill ~177 ~8 ~25 ~177 ~9 ~25 wool 15
fill ~177 ~8 ~26 ~177 ~9 ~26 wool 15
fill ~177 ~8 ~27 ~177 ~9 ~27 wool 15
fill ~177 ~8 ~28 ~177 ~9 ~28 wool 15
fill ~177 ~8 ~29 ~177 ~9 ~29 wool 15
fill ~177 ~8 ~30 ~177 ~9 ~30 wool 15
fill ~177 ~8 ~31 ~177 ~9 ~31 wool 15
fill ~177 ~8 ~32 ~177 ~9 ~32 wool 15
fill ~177 ~8 ~33 ~177 ~9 ~33 wool 15
fill ~177 ~8 ~36 ~177 ~9 ~36 wool 0
fill ~177 ~8 ~47 ~177 ~9 ~47 wool 0
fill ~177 ~8 ~50 ~177 ~9 ~50 wool 15
fill ~177 ~8 ~51 ~177 ~9 ~51 wool 15
fill ~177 ~8 ~52 ~177 ~9 ~52 wool 15
fill ~177 ~8 ~53 ~177 ~9 ~53 wool 15
fill ~177 ~8 ~54 ~177 ~9 ~54 wool 15
fill ~177 ~8 ~55 ~177 ~9 ~55 wool 15
fill ~177 ~8 ~56 ~177 ~9 ~56 wool 15
fill ~177 ~8 ~57 ~177 ~9 ~57 wool 15
fill ~177 ~8 ~58 ~177 ~9 ~58 wool 15
fill ~177 ~8 ~59 ~177 ~9 ~59 wool 15
fill ~177 ~8 ~60 ~177 ~9 ~60 wool 15
fill ~178 ~8 ~13 ~179 ~8 ~13 wool 8
fill ~178 ~8 ~21 ~179 ~8 ~21 wool 8
fill ~178 ~8 ~34 ~178 ~11 ~34 wool 8
fill ~178 ~8 ~35 ~178 ~11 ~35 wool 8
fill ~178 ~8 ~60 ~178 ~11 ~60 wool 8
fill ~178 ~8 ~61 ~178 ~11 ~61 wool 8
fill ~178 ~8 ~62 ~178 ~11 ~62 wool 8
fill ~178 ~8 ~70 ~179 ~8 ~70 wool 8
fill ~14 ~9 ~10 ~14 ~11 ~10 wool 0
fill ~14 ~9 ~11 ~14 ~11 ~11 wool 8
fill ~14 ~9 ~12 ~14 ~11 ~12 wool 8
fill ~14 ~9 ~13 ~14 ~11 ~13 wool 8
fill ~14 ~9 ~14 ~14 ~11 ~14 wool 8
fill ~14 ~9 ~15 ~14 ~11 ~15 wool 8
fill ~14 ~9 ~16 ~14 ~11 ~16 wool 8
fill ~14 ~9 ~17 ~14 ~11 ~17 wool 8
fill ~14 ~9 ~18 ~14 ~11 ~18 wool 8
fill ~14 ~9 ~19 ~14 ~11 ~19 wool 8
fill ~14 ~9 ~20 ~14 ~11 ~20 wool 8
fill ~14 ~9 ~21 ~14 ~11 ~21 wool 8
fill ~14 ~9 ~22 ~14 ~11 ~22 wool 8
fill ~14 ~9 ~23 ~14 ~11 ~23 wool 8
fill ~14 ~9 ~24 ~14 ~11 ~24 wool 8
fill ~14 ~9 ~25 ~14 ~11 ~25 wool 8
fill ~14 ~9 ~26 ~14 ~11 ~26 wool 8
fill ~14 ~9 ~27 ~14 ~11 ~27 wool 8
fill ~14 ~9 ~28 ~14 ~11 ~28 wool 8
fill ~14 ~9 ~29 ~14 ~11 ~29 wool 8
fill ~14 ~9 ~30 ~14 ~11 ~30 wool 8
fill ~14 ~9 ~31 ~14 ~11 ~31 wool 8
fill ~14 ~9 ~32 ~14 ~11 ~32 wool 8
fill ~14 ~9 ~33 ~14 ~11 ~33 wool 8
fill ~14 ~9 ~34 ~14 ~11 ~34 wool 8
fill ~14 ~9 ~50 ~14 ~11 ~50 wool 8
fill ~14 ~9 ~51 ~14 ~11 ~51 wool 8
fill ~14 ~9 ~52 ~14 ~11 ~52 wool 8
fill ~14 ~9 ~53 ~14 ~11 ~53 wool 8
fill ~14 ~9 ~54 ~14 ~11 ~54 wool 8
fill ~14 ~9 ~55 ~14 ~11 ~55 wool 8
fill ~14 ~9 ~56 ~14 ~11 ~56 wool 8
fill ~14 ~9 ~57 ~14 ~11 ~57 wool 8
fill ~14 ~9 ~58 ~14 ~11 ~58 wool 8
fill ~14 ~9 ~59 ~14 ~11 ~59 wool 8
fill ~14 ~9 ~60 ~14 ~11 ~60 wool 8
fill ~14 ~9 ~61 ~14 ~11 ~61 wool 8
fill ~14 ~9 ~62 ~14 ~11 ~62 wool 8
fill ~14 ~9 ~63 ~14 ~11 ~63 wool 8
fill ~14 ~9 ~64 ~14 ~11 ~64 wool 8
fill ~14 ~9 ~65 ~14 ~11 ~65 wool 8
fill ~14 ~9 ~66 ~14 ~11 ~66 wool 8
fill ~14 ~9 ~67 ~14 ~11 ~67 wool 8
fill ~14 ~9 ~68 ~14 ~11 ~68 wool 8
fill ~14 ~9 ~69 ~14 ~11 ~69 wool 8
fill ~14 ~9 ~70 ~14 ~11 ~70 wool 8
fill ~14 ~9 ~71 ~14 ~11 ~71 wool 8
fill ~14 ~9 ~72 ~14 ~11 ~72 wool 8
fill ~15 ~9 ~11 ~17 ~9 ~11 wool 14
fill ~15 ~9 ~36 ~15 ~13 ~36 wool 0
fill ~15 ~9 ~37 ~15 ~13 ~37 wool 0
fill ~15 ~9 ~38 ~15 ~13 ~38 wool 0
fill ~15 ~9 ~39 ~15 ~13 ~39 wool 0
fill ~15 ~9 ~40 ~15 ~13 ~40 wool 0
fill ~15 ~9 ~41 ~15 ~13 ~41 wool 0
fill ~15 ~9 ~42 ~15 ~13 ~42 wool 0
fill ~15 ~9 ~43 ~15 ~13 ~43 wool 0
fill ~15 ~9 ~44 ~15 ~13 ~44 wool 0
fill ~15 ~9 ~45 ~15 ~13 ~45 wool 0
fill ~15 ~9 ~46 ~15 ~13 ~46 wool 0
fill ~15 ~9 ~47 ~15 ~13 ~47 wool 0
fill ~15 ~9 ~48 ~15 ~13 ~48 wool 0
fill ~15 ~9 ~49 ~15 ~14 ~49 double_stone_slab 0
fill ~15 ~9 ~72 ~17 ~9 ~72 wool 14
fill ~15 ~9 ~73 ~17 ~9 ~73 wool 8
fill ~15 ~9 ~74 ~34 ~9 ~74 wool 0
fill ~15 ~9 ~75 ~16 ~9 ~75 wool 8
fill ~16 ~9 ~8 ~17 ~9 ~8 wool 8
fill ~16 ~9 ~9 ~35 ~9 ~9 wool 0
fill ~16 ~9 ~36 ~17 ~9 ~36 wool 8
fill ~16 ~9 ~48 ~17 ~9 ~48 wool 8
fill ~18 ~9 ~10 ~34 ~9 ~10 wool 15
fill ~18 ~9 ~73 ~33 ~9 ~73 wool 15
fill ~27 ~9 ~18 ~60 ~9 ~18 wool 7
fill ~27 ~9 ~32 ~60 ~9 ~32 wool 7
fill ~33 ~9 ~75 ~67 ~9 ~75 wool 0
fill ~34 ~9 ~8 ~68 ~9 ~8 wool 0
fill ~34 ~9 ~17 ~62 ~9 ~17 wool 15
fill ~34 ~9 ~66 ~68 ~9 ~66 wool 15
fill ~42 ~9 ~69 ~45 ~9 ~69 wool 15
fill ~43 ~9 ~14 ~46 ~9 ~14 wool 15
fill ~46 ~9 ~68 ~55 ~9 ~68 wool 15
fill ~47 ~9 ~15 ~56 ~9 ~15 wool 15
fill ~56 ~9 ~53 ~59 ~9 ~53 wool 15
fill ~56 ~9 ~54 ~56 ~8 ~54 wool 15
fill ~56 ~9 ~55 ~56 ~8 ~55 wool 15
fill ~56 ~9 ~56 ~56 ~28 ~56 wool 15
fill ~56 ~9 ~57 ~56 ~27 ~57 wool 15
fill ~56 ~9 ~58 ~56 ~27 ~58 wool 15
fill ~56 ~9 ~59 ~56 ~27 ~59 wool 15
fill ~56 ~9 ~60 ~56 ~27 ~60 wool 15
fill ~56 ~9 ~61 ~56 ~8 ~61 wool 15
fill ~56 ~9 ~62 ~56 ~8 ~62 wool 15
fill ~56 ~9 ~63 ~59 ~9 ~63 wool 15
fill ~56 ~9 ~69 ~59 ~9 ~69 wool 15
fill ~57 ~9 ~14 ~60 ~9 ~14 wool 15
fill ~60 ~9 ~53 ~60 ~12 ~53 wool 7
fill ~60 ~9 ~54 ~61 ~9 ~54 wool 15
fill ~60 ~9 ~55 ~61 ~9 ~55 wool 15
fill ~60 ~9 ~56 ~61 ~9 ~56 wool 15
fill ~60 ~9 ~57 ~61 ~9 ~57 wool 15
fill ~60 ~9 ~58 ~61 ~9 ~58 wool 15
fill ~60 ~9 ~59 ~61 ~9 ~59 wool 15
fill ~60 ~9 ~60 ~61 ~9 ~60 wool 15
fill ~60 ~9 ~61 ~61 ~9 ~61 wool 15
fill ~60 ~9 ~62 ~60 ~27 ~62 wool 15
fill ~60 ~9 ~63 ~60 ~12 ~63 wool 7
fill ~62 ~9 ~18 ~86 ~9 ~18 wool 12
fill ~62 ~9 ~19 ~86 ~9 ~19 wool 12
fill ~62 ~9 ~20 ~86 ~9 ~20 wool 12
fill ~62 ~9 ~21 ~86 ~9 ~21 wool 12
fill ~62 ~9 ~22 ~86 ~9 ~22 wool 12
fill ~62 ~9 ~23 ~86 ~9 ~23 wool 12
fill ~62 ~9 ~24 ~86 ~9 ~24 wool 12
fill ~62 ~9 ~25 ~86 ~9 ~25 wool 12
fill ~62 ~9 ~26 ~86 ~9 ~26 wool 12
fill ~62 ~9 ~27 ~86 ~9 ~27 wool 12
fill ~62 ~9 ~28 ~86 ~9 ~28 wool 12
fill ~62 ~9 ~29 ~86 ~9 ~29 wool 12
fill ~62 ~9 ~30 ~86 ~9 ~30 wool 12
fill ~62 ~9 ~31 ~86 ~9 ~31 wool 12
fill ~62 ~9 ~32 ~86 ~9 ~32 wool 12
fill ~62 ~9 ~33 ~86 ~9 ~33 wool 12
fill ~62 ~9 ~34 ~86 ~9 ~34 wool 12
fill ~62 ~9 ~35 ~86 ~9 ~35 wool 12
fill ~67 ~9 ~74 ~100 ~9 ~74 wool 0
fill ~68 ~9 ~9 ~101 ~9 ~9 wool 0
fill ~68 ~9 ~73 ~136 ~9 ~73 wool 15
fill ~69 ~9 ~10 ~136 ~9 ~10 wool 15
fill ~71 ~9 ~52 ~74 ~9 ~52 wool 15
fill ~71 ~9 ~53 ~71 ~8 ~53 wool 15
fill ~71 ~9 ~54 ~71 ~8 ~54 wool 15
fill ~71 ~9 ~55 ~71 ~28 ~55 wool 15
fill ~71 ~9 ~56 ~71 ~27 ~56 wool 15
fill ~71 ~9 ~57 ~71 ~27 ~57 wool 15
fill ~71 ~9 ~58 ~71 ~27 ~58 wool 15
fill ~71 ~9 ~59 ~71 ~27 ~59 wool 15
fill ~71 ~9 ~60 ~71 ~8 ~60 wool 15
fill ~71 ~9 ~61 ~71 ~8 ~61 wool 15
fill ~71 ~9 ~62 ~74 ~9 ~62 wool 15
fill ~75 ~9 ~52 ~75 ~12 ~52 wool 7
fill ~75 ~9 ~53 ~76 ~9 ~53 wool 15
fill ~75 ~9 ~54 ~76 ~9 ~54 wool 15
fill ~75 ~9 ~55 ~76 ~9 ~55 wool 15
fill ~75 ~9 ~56 ~76 ~9 ~56 wool 15
fill ~75 ~9 ~57 ~76 ~9 ~57 wool 15
fill ~75 ~9 ~58 ~76 ~9 ~58 wool 15
fill ~75 ~9 ~59 ~76 ~9 ~59 wool 15
fill ~75 ~9 ~60 ~76 ~9 ~60 wool 15
fill ~75 ~9 ~61 ~75 ~27 ~61 wool 15
fill ~75 ~9 ~62 ~75 ~12 ~62 wool 7
fill ~91 ~9 ~16 ~108 ~9 ~16 wool 12
fill ~91 ~9 ~17 ~108 ~9 ~17 wool 12
fill ~91 ~9 ~18 ~108 ~9 ~18 wool 12
fill ~91 ~9 ~19 ~108 ~9 ~19 wool 12
fill ~91 ~9 ~20 ~108 ~9 ~20 wool 12
fill ~91 ~9 ~21 ~108 ~9 ~21 wool 12
fill ~91 ~9 ~22 ~108 ~9 ~22 wool 12
fill ~91 ~9 ~23 ~108 ~9 ~23 wool 12
fill ~91 ~9 ~24 ~108 ~9 ~24 wool 12
fill ~91 ~9 ~25 ~108 ~9 ~25 wool 12
fill ~91 ~9 ~26 ~108 ~9 ~26 wool 12
fill ~91 ~9 ~27 ~108 ~9 ~27 wool 12
fill ~91 ~9 ~28 ~108 ~9 ~28 wool 12
fill ~91 ~9 ~29 ~108 ~9 ~29 wool 12
fill ~91 ~9 ~30 ~108 ~9 ~30 wool 12
fill ~91 ~9 ~31 ~108 ~9 ~31 wool 12
fill ~91 ~9 ~32 ~108 ~9 ~32 wool 12
fill ~91 ~9 ~33 ~108 ~9 ~33 wool 12
fill ~91 ~9 ~34 ~108 ~9 ~34 wool 12
fill ~91 ~9 ~35 ~108 ~9 ~35 wool 12
fill ~91 ~9 ~36 ~108 ~9 ~36 wool 12
fill ~91 ~9 ~37 ~108 ~9 ~37 wool 12
fill ~91 ~9 ~38 ~108 ~9 ~38 wool 12
fill ~91 ~9 ~39 ~108 ~9 ~39 wool 12
fill ~91 ~9 ~40 ~108 ~9 ~40 wool 12
fill ~91 ~9 ~41 ~108 ~9 ~41 wool 12
fill ~91 ~9 ~42 ~108 ~9 ~42 wool 12
fill ~91 ~9 ~43 ~108 ~9 ~43 wool 12
fill ~91 ~9 ~44 ~108 ~9 ~44 wool 12
fill ~91 ~9 ~45 ~108 ~9 ~45 wool 12
fill ~91 ~9 ~46 ~108 ~9 ~46 wool 12
fill ~91 ~9 ~47 ~108 ~9 ~47 wool 12
fill ~91 ~9 ~48 ~108 ~9 ~48 wool 12
fill ~91 ~9 ~49 ~108 ~9 ~49 wool 12
fill ~91 ~9 ~50 ~108 ~9 ~50 wool 12
fill ~91 ~9 ~51 ~108 ~9 ~51 wool 12
fill ~91 ~9 ~52 ~108 ~9 ~52 wool 12
fill ~91 ~9 ~53 ~108 ~9 ~53 wool 12
fill ~91 ~9 ~54 ~108 ~9 ~54 wool 12
fill ~91 ~9 ~55 ~108 ~9 ~55 wool 12
fill ~91 ~9 ~56 ~108 ~9 ~56 wool 12
fill ~91 ~9 ~57 ~108 ~9 ~57 wool 12
fill ~91 ~9 ~58 ~108 ~9 ~58 wool 12
fill ~91 ~9 ~59 ~108 ~9 ~59 wool 12
fill ~91 ~9 ~60 ~108 ~9 ~60 wool 12
fill ~91 ~9 ~61 ~108 ~9 ~61 wool 12
fill ~91 ~9 ~62 ~108 ~9 ~62 wool 12
fill ~91 ~9 ~63 ~108 ~9 ~63 wool 12
fill ~91 ~9 ~64 ~108 ~9 ~64 wool 12
fill ~91 ~9 ~65 ~108 ~9 ~65 wool 12
fill ~91 ~9 ~66 ~108 ~9 ~66 wool 12
fill ~91 ~9 ~67 ~108 ~9 ~67 wool 12
fill ~101 ~9 ~74 ~109 ~9 ~74 wool 14
fill ~102 ~9 ~9 ~110 ~9 ~9 wool 14
fill ~110 ~9 ~74 ~137 ~9 ~74 wool 0
fill ~111 ~9 ~9 ~137 ~9 ~9 wool 0
fill ~137 ~9 ~8 ~137 ~11 ~8 wool 0
fill ~137 ~9 ~75 ~137 ~11 ~75 wool 0
fill ~145 ~9 ~14 ~148 ~9 ~14 wool 15
fill ~145 ~9 ~69 ~148 ~9 ~69 wool 15
fill ~149 ~9 ~15 ~158 ~9 ~15 wool 15
fill ~149 ~9 ~68 ~158 ~9 ~68 wool 15
fill ~152 ~9 ~8 ~155 ~9 ~8 wool 8
fill ~152 ~9 ~75 ~155 ~9 ~75 wool 8
fill ~159 ~9 ~14 ~162 ~9 ~14 wool 15
fill ~159 ~9 ~69 ~162 ~9 ~69 wool 15
fill ~170 ~9 ~8 ~170 ~11 ~8 wool 0
fill ~170 ~9 ~9 ~174 ~9 ~9 wool 0
fill ~170 ~9 ~74 ~174 ~9 ~74 wool 0
fill ~170 ~9 ~75 ~170 ~11 ~75 wool 0
fill ~175 ~9 ~9 ~175 ~11 ~9 wool 8
fill ~175 ~9 ~10 ~178 ~9 ~10 wool 8
fill ~175 ~9 ~73 ~178 ~9 ~73 wool 8
fill ~175 ~9 ~74 ~175 ~11 ~74 wool 8
fill ~178 ~9 ~13 ~179 ~9 ~13 wool 8
fill ~178 ~9 ~21 ~179 ~9 ~21 wool 8
fill ~178 ~9 ~70 ~179 ~9 ~70 wool 8
fill ~179 ~9 ~11 ~179 ~11 ~11 wool 8
fill ~179 ~9 ~72 ~179 ~11 ~72 wool 8
fill ~14 ~10 ~74 ~34 ~10 ~74 wool 0
fill ~14 ~10 ~75 ~16 ~10 ~75 wool 8
fill ~15 ~10 ~8 ~17 ~10 ~8 wool 8
fill ~15 ~10 ~9 ~35 ~10 ~9 wool 0
fill ~15 ~10 ~11 ~17 ~10 ~11 wool 14
fill ~15 ~10 ~72 ~17 ~10 ~72 wool 14
fill ~15 ~10 ~73 ~17 ~10 ~73 wool 8
setblock ~16 ~10 ~26 wool 0
fill ~16 ~10 ~36 ~17 ~10 ~36 wool 8
fill ~16 ~10 ~48 ~17 ~10 ~48 wool 8
fill ~18 ~10 ~10 ~34 ~10 ~10 wool 15
fill ~18 ~10 ~73 ~33 ~10 ~73 wool 15
fill ~27 ~10 ~18 ~60 ~10 ~18 wool 7
fill ~27 ~10 ~32 ~60 ~10 ~32 wool 7
fill ~34 ~10 ~17 ~62 ~10 ~17 wool 15
fill ~34 ~10 ~66 ~68 ~10 ~66 wool 15
fill ~34 ~10 ~75 ~67 ~10 ~75 wool 0
fill ~35 ~10 ~8 ~47 ~10 ~8 wool 0
fill ~42 ~10 ~70 ~42 ~14 ~70 wool 15
fill ~43 ~10 ~13 ~43 ~14 ~13 wool 15
fill ~43 ~10 ~69 ~45 ~10 ~69 wool 15
fill ~43 ~10 ~74 ~43 ~13 ~74 wool 8
fill ~44 ~10 ~9 ~44 ~13 ~9 wool 8
fill ~44 ~10 ~14 ~46 ~10 ~14 wool 15
fill ~46 ~10 ~68 ~55 ~10 ~68 wool 15
fill ~46 ~10 ~73 ~48 ~10 ~73 wool 8
fill ~47 ~10 ~10 ~49 ~10 ~10 wool 8
fill ~47 ~10 ~15 ~56 ~10 ~15 wool 15
fill ~48 ~10 ~8 ~55 ~10 ~8 wool 7
setblock ~49 ~10 ~74 wool 8
setblock ~50 ~10 ~9 wool 8
setblock ~52 ~10 ~74 wool 8
setblock ~53 ~10 ~9 wool 8
fill ~54 ~10 ~73 ~55 ~10 ~73 wool 8
fill ~55 ~10 ~10 ~56 ~10 ~10 wool 8
fill ~56 ~10 ~8 ~68 ~10 ~8 wool 0
fill ~56 ~10 ~53 ~59 ~10 ~53 wool 15
fill ~56 ~10 ~54 ~56 ~10 ~55 wool 7
fill ~56 ~10 ~61 ~56 ~10 ~62 wool 7
fill ~56 ~10 ~63 ~59 ~10 ~63 wool 15
fill ~56 ~10 ~69 ~58 ~10 ~69 wool 15
fill ~57 ~10 ~14 ~59 ~10 ~14 wool 15
fill ~58 ~10 ~74 ~58 ~13 ~74 wool 8
fill ~59 ~10 ~9 ~59 ~13 ~9 wool 8
fill ~59 ~10 ~70 ~59 ~14 ~70 wool 15
fill ~60 ~10 ~13 ~60 ~14 ~13 wool 15
fill ~60 ~10 ~49 ~60 ~10 ~52 wool 15
fill ~60 ~10 ~54 ~61 ~10 ~54 wool 15
fill ~60 ~10 ~55 ~61 ~10 ~55 wool 15
fill ~60 ~10 ~56 ~61 ~10 ~56 wool 15
fill ~60 ~10 ~57 ~61 ~10 ~57 wool 15
fill ~60 ~10 ~58 ~61 ~10 ~58 wool 15
fill ~60 ~10 ~59 ~61 ~10 ~59 wool 15
fill ~60 ~10 ~60 ~61 ~10 ~60 wool 15
fill ~60 ~10 ~61 ~61 ~10 ~61 wool 15
fill ~61 ~10 ~53 ~61 ~12 ~53 wool 15
fill ~61 ~10 ~62 ~61 ~12 ~62 wool 15
fill ~62 ~10 ~18 ~86 ~10 ~18 wool 12
fill ~62 ~10 ~19 ~86 ~10 ~19 wool 12
fill ~62 ~10 ~20 ~86 ~10 ~20 wool 12
fill ~62 ~10 ~21 ~86 ~10 ~21 wool 12
fill ~62 ~10 ~22 ~86 ~10 ~22 wool 12
fill ~62 ~10 ~23 ~86 ~10 ~23 wool 12
fill ~62 ~10 ~24 ~86 ~10 ~24 wool 12
fill ~62 ~10 ~25 ~86 ~10 ~25 wool 12
fill ~62 ~10 ~26 ~86 ~10 ~26 wool 12
fill ~62 ~10 ~27 ~86 ~10 ~27 wool 12
fill ~62 ~10 ~28 ~86 ~10 ~28 wool 12
fill ~62 ~10 ~29 ~86 ~10 ~29 wool 12
fill ~62 ~10 ~30 ~86 ~10 ~30 wool 12
fill ~62 ~10 ~31 ~86 ~10 ~31 wool 12
fill ~62 ~10 ~32 ~86 ~10 ~32 wool 12
fill ~62 ~10 ~33 ~86 ~10 ~33 wool 12
fill ~62 ~10 ~34 ~86 ~10 ~34 wool 12
fill ~62 ~10 ~35 ~86 ~10 ~35 wool 12
fill ~67 ~10 ~74 ~99 ~10 ~74 wool 0
fill ~68 ~10 ~9 ~100 ~10 ~9 wool 0
fill ~68 ~10 ~73 ~136 ~10 ~73 wool 15
fill ~69 ~10 ~10 ~136 ~10 ~10 wool 15
fill ~71 ~10 ~52 ~74 ~10 ~52 wool 15
fill ~71 ~10 ~53 ~71 ~10 ~54 wool 7
fill ~71 ~10 ~60 ~71 ~10 ~61 wool 7
fill ~71 ~10 ~62 ~74 ~10 ~62 wool 15
fill ~75 ~10 ~48 ~75 ~10 ~51 wool 15
fill ~75 ~10 ~53 ~76 ~10 ~53 wool 15
fill ~75 ~10 ~54 ~76 ~10 ~54 wool 15
fill ~75 ~10 ~55 ~76 ~10 ~55 wool 15
fill ~75 ~10 ~56 ~76 ~10 ~56 wool 15
fill ~75 ~10 ~57 ~76 ~10 ~57 wool 15
fill ~75 ~10 ~58 ~76 ~10 ~58 wool 15
fill ~75 ~10 ~59 ~76 ~10 ~59 wool 15
fill ~75 ~10 ~60 ~76 ~10 ~60 wool 15
fill ~76 ~10 ~52 ~76 ~12 ~52 wool 15
fill ~76 ~10 ~61 ~76 ~12 ~61 wool 15
fill ~91 ~10 ~16 ~108 ~10 ~16 wool 12
fill ~91 ~10 ~17 ~108 ~10 ~17 wool 12
fill ~91 ~10 ~18 ~108 ~10 ~18 wool 12
fill ~91 ~10 ~19 ~108 ~10 ~19 wool 12
fill ~91 ~10 ~20 ~108 ~10 ~20 wool 12
fill ~91 ~10 ~21 ~108 ~10 ~21 wool 12
fill ~91 ~10 ~22 ~108 ~10 ~22 wool 12
fill ~91 ~10 ~23 ~108 ~10 ~23 wool 12
fill ~91 ~10 ~24 ~108 ~10 ~24 wool 12
fill ~91 ~10 ~25 ~108 ~10 ~25 wool 12
fill ~91 ~10 ~26 ~108 ~10 ~26 wool 12
fill ~91 ~10 ~27 ~108 ~10 ~27 wool 12
fill ~91 ~10 ~28 ~108 ~10 ~28 wool 12
fill ~91 ~10 ~29 ~108 ~10 ~29 wool 12
fill ~91 ~10 ~30 ~108 ~10 ~30 wool 12
fill ~91 ~10 ~31 ~108 ~10 ~31 wool 12
fill ~91 ~10 ~32 ~108 ~10 ~32 wool 12
fill ~91 ~10 ~33 ~108 ~10 ~33 wool 12
fill ~91 ~10 ~34 ~108 ~10 ~34 wool 12
fill ~91 ~10 ~35 ~108 ~10 ~35 wool 12
fill ~91 ~10 ~36 ~108 ~10 ~36 wool 12
fill ~91 ~10 ~37 ~108 ~10 ~37 wool 12
fill ~91 ~10 ~38 ~108 ~10 ~38 wool 12
fill ~91 ~10 ~39 ~108 ~10 ~39 wool 12
fill ~91 ~10 ~40 ~108 ~10 ~40 wool 12
fill ~91 ~10 ~41 ~108 ~10 ~41 wool 12
fill ~91 ~10 ~42 ~108 ~10 ~42 wool 12
fill ~91 ~10 ~43 ~108 ~10 ~43 wool 12
fill ~91 ~10 ~44 ~108 ~10 ~44 wool 12
fill ~91 ~10 ~45 ~108 ~10 ~45 wool 12
fill ~91 ~10 ~46 ~108 ~10 ~46 wool 12
fill ~91 ~10 ~47 ~108 ~10 ~47 wool 12
fill ~91 ~10 ~48 ~108 ~10 ~48 wool 12
fill ~91 ~10 ~49 ~108 ~10 ~49 wool 12
fill ~91 ~10 ~50 ~108 ~10 ~50 wool 12
fill ~91 ~10 ~51 ~108 ~10 ~51 wool 12
fill ~91 ~10 ~52 ~108 ~10 ~52 wool 12
fill ~91 ~10 ~53 ~108 ~10 ~53 wool 12
fill ~91 ~10 ~54 ~108 ~10 ~54 wool 12
fill ~91 ~10 ~55 ~108 ~10 ~55 wool 12
fill ~91 ~10 ~56 ~108 ~10 ~56 wool 12
fill ~91 ~10 ~57 ~108 ~10 ~57 wool 12
fill ~91 ~10 ~58 ~108 ~10 ~58 wool 12
fill ~91 ~10 ~59 ~108 ~10 ~59 wool 12
fill ~91 ~10 ~60 ~108 ~10 ~60 wool 12
fill ~91 ~10 ~61 ~108 ~10 ~61 wool 12
fill ~91 ~10 ~62 ~108 ~10 ~62 wool 12
fill ~91 ~10 ~63 ~108 ~10 ~63 wool 12
fill ~91 ~10 ~64 ~108 ~10 ~64 wool 12
fill ~91 ~10 ~65 ~108 ~10 ~65 wool 12
fill ~91 ~10 ~66 ~108 ~10 ~66 wool 12
fill ~91 ~10 ~67 ~108 ~10 ~67 wool 12
setblock ~100 ~10 ~74 wool 15
setblock ~101 ~10 ~9 wool 15
fill ~101 ~10 ~74 ~110 ~10 ~74 wool 14
fill ~102 ~10 ~9 ~111 ~10 ~9 wool 14
fill ~111 ~10 ~74 ~137 ~10 ~74 wool 0
fill ~112 ~10 ~9 ~137 ~10 ~9 wool 0
fill ~145 ~10 ~8 ~145 ~13 ~8 wool 0
fill ~145 ~10 ~13 ~145 ~14 ~13 wool 15
fill ~145 ~10 ~70 ~145 ~14 ~70 wool 15
fill ~145 ~10 ~75 ~145 ~13 ~75 wool 0
fill ~146 ~10 ~9 ~146 ~13 ~9 wool 8
fill ~146 ~10 ~14 ~148 ~10 ~14 wool 15
fill ~146 ~10 ~69 ~148 ~10 ~69 wool 15
fill ~146 ~10 ~74 ~146 ~13 ~74 wool 8
fill ~149 ~10 ~10 ~151 ~10 ~10 wool 8
fill ~149 ~10 ~15 ~158 ~10 ~15 wool 15
fill ~149 ~10 ~68 ~158 ~10 ~68 wool 15
fill ~149 ~10 ~73 ~151 ~10 ~73 wool 8
setblock ~152 ~10 ~9 wool 8
setblock ~152 ~10 ~74 wool 8
fill ~153 ~10 ~8 ~154 ~10 ~8 wool 8
fill ~153 ~10 ~75 ~154 ~10 ~75 wool 8
setblock ~155 ~10 ~9 wool 8
setblock ~155 ~10 ~74 wool 8
fill ~157 ~10 ~10 ~158 ~10 ~10 wool 8
fill ~157 ~10 ~73 ~158 ~10 ~73 wool 8
fill ~159 ~10 ~14 ~161 ~10 ~14 wool 15
fill ~159 ~10 ~69 ~161 ~10 ~69 wool 15
fill ~161 ~10 ~9 ~161 ~13 ~9 wool 8
fill ~161 ~10 ~74 ~161 ~13 ~74 wool 8
fill ~162 ~10 ~8 ~162 ~13 ~8 wool 0
fill ~162 ~10 ~13 ~162 ~14 ~13 wool 15
fill ~162 ~10 ~70 ~162 ~14 ~70 wool 15
fill ~162 ~10 ~75 ~162 ~13 ~75 wool 0
fill ~170 ~10 ~9 ~174 ~10 ~9 wool 0
fill ~170 ~10 ~74 ~174 ~10 ~74 wool 0
fill ~175 ~10 ~10 ~178 ~10 ~10 wool 8
fill ~175 ~10 ~73 ~178 ~10 ~73 wool 8
setblock ~177 ~10 ~36 wool 15
setblock ~177 ~10 ~47 wool 15
fill ~178 ~10 ~13 ~178 ~11 ~13 wool 8
fill ~178 ~10 ~14 ~179 ~10 ~14 wool 8
fill ~178 ~10 ~15 ~179 ~10 ~15 wool 8
fill ~178 ~10 ~16 ~180 ~10 ~16 wool 8
fill ~178 ~10 ~17 ~180 ~10 ~17 wool 8
fill ~178 ~10 ~18 ~180 ~10 ~18 wool 8
fill ~178 ~10 ~19 ~179 ~10 ~19 wool 8
fill ~178 ~10 ~20 ~179 ~10 ~20 wool 8
fill ~178 ~10 ~21 ~178 ~11 ~21 wool 8
fill ~178 ~10 ~24 ~178 ~11 ~24 wool 8
fill ~178 ~10 ~25 ~178 ~11 ~25 wool 8
fill ~178 ~10 ~26 ~178 ~11 ~26 wool 8
fill ~178 ~10 ~27 ~178 ~11 ~27 wool 8
fill ~178 ~10 ~28 ~178 ~11 ~28 wool 8
fill ~178 ~10 ~29 ~178 ~11 ~29 wool 8
fill ~178 ~10 ~30 ~178 ~11 ~30 wool 8
fill ~178 ~10 ~31 ~178 ~11 ~31 wool 8
fill ~178 ~10 ~32 ~178 ~11 ~32 wool 8
fill ~178 ~10 ~33 ~178 ~11 ~33 wool 8
fill ~178 ~10 ~50 ~178 ~11 ~50 wool 8
fill ~178 ~10 ~51 ~178 ~11 ~51 wool 8
fill ~178 ~10 ~52 ~178 ~11 ~52 wool 8
fill ~178 ~10 ~53 ~178 ~11 ~53 wool 8
fill ~178 ~10 ~54 ~178 ~11 ~54 wool 8
fill ~178 ~10 ~55 ~178 ~11 ~55 wool 8
fill ~178 ~10 ~56 ~178 ~11 ~56 wool 8
fill ~178 ~10 ~57 ~178 ~11 ~57 wool 8
fill ~178 ~10 ~58 ~178 ~11 ~58 wool 8
fill ~178 ~10 ~59 ~178 ~11 ~59 wool 8
fill ~178 ~10 ~63 ~179 ~10 ~63 wool 8
fill ~178 ~10 ~64 ~179 ~10 ~64 wool 8
fill ~178 ~10 ~65 ~180 ~10 ~65 wool 8
fill ~178 ~10 ~66 ~180 ~10 ~66 wool 8
fill ~178 ~10 ~67 ~180 ~10 ~67 wool 8
fill ~178 ~10 ~68 ~179 ~10 ~68 wool 8
fill ~178 ~10 ~69 ~179 ~10 ~69 wool 8
fill ~178 ~10 ~70 ~178 ~11 ~70 wool 8
fill ~14 ~11 ~74 ~34 ~11 ~74 wool 0
fill ~14 ~11 ~75 ~16 ~11 ~75 wool 8
fill ~15 ~11 ~8 ~17 ~11 ~8 wool 8
fill ~15 ~11 ~9 ~35 ~11 ~9 wool 0
fill ~15 ~11 ~11 ~17 ~11 ~11 wool 14
fill ~15 ~11 ~72 ~17 ~11 ~72 wool 14
fill ~15 ~11 ~73 ~17 ~11 ~73 wool 8
fill ~16 ~11 ~36 ~17 ~11 ~36 wool 8
fill ~16 ~11 ~48 ~17 ~11 ~48 wool 8
fill ~18 ~11 ~10 ~34 ~11 ~10 wool 15
fill ~18 ~11 ~73 ~33 ~11 ~73 wool 15
fill ~27 ~11 ~18 ~60 ~11 ~18 wool 7
fill ~27 ~11 ~32 ~60 ~11 ~32 wool 7
fill ~34 ~11 ~17 ~62 ~11 ~17 wool 15
fill ~34 ~11 ~66 ~68 ~11 ~66 wool 15
fill ~34 ~11 ~75 ~67 ~11 ~75 wool 0
fill ~35 ~11 ~8 ~47 ~11 ~8 wool 0
fill ~43 ~11 ~69 ~45 ~11 ~69 wool 15
fill ~44 ~11 ~14 ~46 ~11 ~14 wool 15
fill ~44 ~11 ~73 ~57 ~11 ~73 wool 8
fill ~45 ~11 ~10 ~58 ~11 ~10 wool 8
fill ~46 ~11 ~68 ~55 ~11 ~68 wool 15
fill ~47 ~11 ~15 ~56 ~11 ~15 wool 15
fill ~48 ~11 ~8 ~55 ~11 ~8 wool 7
fill ~50 ~11 ~74 ~51 ~11 ~74 wool 8
fill ~51 ~11 ~6 ~52 ~11 ~6 wool 15
fill ~51 ~11 ~9 ~52 ~11 ~9 wool 8
fill ~55 ~11 ~54 ~55 ~11 ~55 wool 7
fill ~55 ~11 ~61 ~55 ~11 ~62 wool 7
fill ~56 ~11 ~8 ~68 ~11 ~8 wool 0
fill ~56 ~11 ~53 ~59 ~11 ~53 wool 15
fill ~56 ~11 ~54 ~56 ~17 ~54 wool 15
fill ~56 ~11 ~55 ~56 ~17 ~55 wool 15
fill ~56 ~11 ~61 ~56 ~27 ~61 wool 15
fill ~56 ~11 ~62 ~56 ~27 ~62 wool 15
fill ~56 ~11 ~63 ~56 ~26 ~63 wool 15
fill ~56 ~11 ~69 ~58 ~11 ~69 wool 15
fill ~57 ~11 ~14 ~59 ~11 ~14 wool 15
setblock ~57 ~11 ~63 wool 7
fill ~58 ~11 ~63 ~59 ~11 ~63 wool 15
fill ~60 ~11 ~48 ~61 ~11 ~48 wool 15
fill ~60 ~11 ~54 ~61 ~11 ~54 wool 15
fill ~60 ~11 ~55 ~61 ~11 ~55 wool 15
fill ~60 ~11 ~56 ~60 ~28 ~56 wool 15
fill ~60 ~11 ~57 ~61 ~11 ~57 wool 15
fill ~60 ~11 ~58 ~61 ~11 ~58 wool 15
fill ~60 ~11 ~59 ~60 ~27 ~59 wool 15
fill ~60 ~11 ~60 ~61 ~11 ~60 wool 15
fill ~60 ~11 ~61 ~61 ~11 ~61 wool 15
fill ~61 ~11 ~52 ~61 ~12 ~52 wool 15
setblock ~61 ~11 ~56 wool 7
setblock ~61 ~11 ~59 wool 7
fill ~61 ~11 ~63 ~61 ~12 ~63 wool 15
fill ~62 ~11 ~18 ~86 ~11 ~18 wool 12
fill ~62 ~11 ~19 ~86 ~11 ~19 wool 12
fill ~62 ~11 ~20 ~86 ~11 ~20 wool 12
fill ~62 ~11 ~21 ~86 ~11 ~21 wool 12
fill ~62 ~11 ~22 ~86 ~11 ~22 wool 12
fill ~62 ~11 ~23 ~86 ~11 ~23 wool 12
fill ~62 ~11 ~24 ~86 ~11 ~24 wool 12
fill ~62 ~11 ~25 ~86 ~11 ~25 wool 12
fill ~62 ~11 ~26 ~86 ~11 ~26 wool 12
fill ~62 ~11 ~27 ~86 ~11 ~27 wool 12
fill ~62 ~11 ~28 ~86 ~11 ~28 wool 12
fill ~62 ~11 ~29 ~86 ~11 ~29 wool 12
fill ~62 ~11 ~30 ~86 ~11 ~30 wool 12
fill ~62 ~11 ~31 ~86 ~11 ~31 wool 12
fill ~62 ~11 ~32 ~86 ~11 ~32 wool 12
fill ~62 ~11 ~33 ~86 ~11 ~33 wool 12
fill ~62 ~11 ~34 ~86 ~11 ~34 wool 12
fill ~62 ~11 ~35 ~86 ~11 ~35 wool 12
fill ~67 ~11 ~74 ~97 ~11 ~74 wool 0
fill ~68 ~11 ~9 ~98 ~11 ~9 wool 0
fill ~68 ~11 ~73 ~136 ~11 ~73 wool 15
fill ~69 ~11 ~10 ~136 ~11 ~10 wool 15
fill ~70 ~11 ~53 ~70 ~11 ~54 wool 7
fill ~70 ~11 ~60 ~70 ~11 ~61 wool 7
fill ~71 ~11 ~52 ~74 ~11 ~52 wool 15
fill ~71 ~11 ~53 ~71 ~17 ~53 wool 15
fill ~71 ~11 ~54 ~71 ~17 ~54 wool 15
fill ~71 ~11 ~60 ~71 ~17 ~60 wool 15
fill ~71 ~11 ~61 ~71 ~17 ~61 wool 15
fill ~71 ~11 ~62 ~71 ~26 ~62 wool 15
setblock ~72 ~11 ~62 wool 7
fill ~73 ~11 ~62 ~74 ~11 ~62 wool 15
fill ~75 ~11 ~47 ~76 ~11 ~47 wool 15
fill ~75 ~11 ~53 ~76 ~11 ~53 wool 15
fill ~75 ~11 ~54 ~76 ~11 ~54 wool 15
fill ~75 ~11 ~55 ~75 ~28 ~55 wool 15
fill ~75 ~11 ~56 ~76 ~11 ~56 wool 15
fill ~75 ~11 ~57 ~76 ~11 ~57 wool 15
fill ~75 ~11 ~58 ~75 ~27 ~58 wool 15
fill ~75 ~11 ~59 ~76 ~11 ~59 wool 15
fill ~75 ~11 ~60 ~76 ~11 ~60 wool 15
fill ~76 ~11 ~51 ~76 ~12 ~51 wool 15
setblock ~76 ~11 ~55 wool 7
setblock ~76 ~11 ~58 wool 7
fill ~76 ~11 ~62 ~76 ~12 ~62 wool 15
fill ~91 ~11 ~16 ~108 ~11 ~16 wool 12
fill ~91 ~11 ~17 ~108 ~11 ~17 wool 12
fill ~91 ~11 ~18 ~108 ~11 ~18 wool 12
fill ~91 ~11 ~19 ~108 ~11 ~19 wool 12
fill ~91 ~11 ~20 ~108 ~11 ~20 wool 12
fill ~91 ~11 ~21 ~108 ~11 ~21 wool 12
fill ~91 ~11 ~22 ~108 ~11 ~22 wool 12
fill ~91 ~11 ~23 ~108 ~11 ~23 wool 12
fill ~91 ~11 ~24 ~108 ~11 ~24 wool 12
fill ~91 ~11 ~25 ~108 ~11 ~25 wool 12
fill ~91 ~11 ~26 ~108 ~11 ~26 wool 12
fill ~91 ~11 ~27 ~108 ~11 ~27 wool 12
fill ~91 ~11 ~28 ~108 ~11 ~28 wool 12
fill ~91 ~11 ~29 ~108 ~11 ~29 wool 12
fill ~91 ~11 ~30 ~108 ~11 ~30 wool 12
fill ~91 ~11 ~31 ~108 ~11 ~31 wool 12
fill ~91 ~11 ~32 ~108 ~11 ~32 wool 12
fill ~91 ~11 ~33 ~108 ~11 ~33 wool 12
fill ~91 ~11 ~34 ~108 ~11 ~34 wool 12
fill ~91 ~11 ~35 ~108 ~11 ~35 wool 12
fill ~91 ~11 ~36 ~108 ~11 ~36 wool 12
fill ~91 ~11 ~37 ~108 ~11 ~37 wool 12
fill ~91 ~11 ~38 ~108 ~11 ~38 wool 12
fill ~91 ~11 ~39 ~108 ~11 ~39 wool 12
fill ~91 ~11 ~40 ~108 ~11 ~40 wool 12
fill ~91 ~11 ~41 ~108 ~11 ~41 wool 12
fill ~91 ~11 ~42 ~108 ~11 ~42 wool 12
fill ~91 ~11 ~43 ~108 ~11 ~43 wool 12
fill ~91 ~11 ~44 ~108 ~11 ~44 wool 12
fill ~91 ~11 ~45 ~108 ~11 ~45 wool 12
fill ~91 ~11 ~46 ~108 ~11 ~46 wool 12
fill ~91 ~11 ~47 ~108 ~11 ~47 wool 12
fill ~91 ~11 ~48 ~108 ~11 ~48 wool 12
fill ~91 ~11 ~49 ~108 ~11 ~49 wool 12
fill ~91 ~11 ~50 ~108 ~11 ~50 wool 12
fill ~91 ~11 ~51 ~108 ~11 ~51 wool 12
fill ~91 ~11 ~52 ~108 ~11 ~52 wool 12
fill ~91 ~11 ~53 ~108 ~11 ~53 wool 12
fill ~91 ~11 ~54 ~108 ~11 ~54 wool 12
fill ~91 ~11 ~55 ~108 ~11 ~55 wool 12
fill ~91 ~11 ~56 ~108 ~11 ~56 wool 12
fill ~91 ~11 ~57 ~108 ~11 ~57 wool 12
fill ~91 ~11 ~58 ~108 ~11 ~58 wool 12
fill ~91 ~11 ~59 ~108 ~11 ~59 wool 12
fill ~91 ~11 ~60 ~108 ~11 ~60 wool 12
fill ~91 ~11 ~61 ~108 ~11 ~61 wool 12
fill ~91 ~11 ~62 ~108 ~11 ~62 wool 12
fill ~91 ~11 ~63 ~108 ~11 ~63 wool 12
fill ~91 ~11 ~64 ~108 ~11 ~64 wool 12
fill ~91 ~11 ~65 ~108 ~11 ~65 wool 12
fill ~91 ~11 ~66 ~108 ~11 ~66 wool 12
fill ~91 ~11 ~67 ~108 ~11 ~67 wool 12
fill ~98 ~11 ~74 ~99 ~11 ~74 wool 15
fill ~99 ~11 ~9 ~100 ~11 ~9 wool 15
fill ~100 ~11 ~74 ~100 ~13 ~74 wool 0
fill ~101 ~11 ~9 ~101 ~13 ~9 wool 0
fill ~101 ~11 ~74 ~101 ~12 ~74 wool 15
fill ~102 ~11 ~9 ~102 ~12 ~9 wool 15
setblock ~102 ~11 ~74 wool 14
setblock ~103 ~11 ~9 wool 14
fill ~103 ~11 ~74 ~106 ~11 ~74 wool 0
fill ~104 ~11 ~9 ~107 ~11 ~9 wool 0
fill ~107 ~11 ~74 ~107 ~12 ~74 wool 15
fill ~108 ~11 ~9 ~108 ~12 ~9 wool 15
fill ~108 ~11 ~74 ~111 ~11 ~74 wool 14
fill ~109 ~11 ~9 ~112 ~11 ~9 wool 14
fill ~112 ~11 ~74 ~137 ~11 ~74 wool 0
fill ~113 ~11 ~9 ~137 ~11 ~9 wool 0
fill ~144 ~11 ~75 ~144 ~12 ~75 wool 15
fill ~146 ~11 ~14 ~148 ~11 ~14 wool 15
fill ~146 ~11 ~69 ~148 ~11 ~69 wool 15
fill ~147 ~11 ~10 ~160 ~11 ~10 wool 8
fill ~147 ~11 ~73 ~160 ~11 ~73 wool 8
fill ~149 ~11 ~15 ~158 ~11 ~15 wool 15
fill ~149 ~11 ~68 ~158 ~11 ~68 wool 15
fill ~153 ~11 ~9 ~154 ~11 ~9 wool 8
fill ~153 ~11 ~74 ~154 ~11 ~74 wool 8
fill ~159 ~11 ~14 ~161 ~11 ~14 wool 15
fill ~159 ~11 ~69 ~161 ~11 ~69 wool 15
fill ~163 ~11 ~75 ~163 ~12 ~75 wool 15
fill ~170 ~11 ~9 ~174 ~11 ~9 wool 0
fill ~170 ~11 ~74 ~174 ~11 ~74 wool 0
fill ~175 ~11 ~10 ~178 ~11 ~10 wool 8
fill ~175 ~11 ~73 ~178 ~11 ~73 wool 8
fill ~177 ~11 ~11 ~177 ~11 ~73 wool 8
fill ~178 ~11 ~14 ~178 ~10 ~14 wool 8
fill ~178 ~11 ~15 ~178 ~10 ~15 wool 8
fill ~178 ~11 ~16 ~178 ~10 ~16 wool 8
fill ~178 ~11 ~17 ~178 ~10 ~17 wool 8
fill ~178 ~11 ~18 ~178 ~10 ~18 wool 8
fill ~178 ~11 ~19 ~178 ~10 ~19 wool 8
fill ~178 ~11 ~20 ~178 ~10 ~20 wool 8
fill ~178 ~11 ~36 ~178 ~11 ~73 wool 8
fill ~13 ~12 ~10 ~13 ~14 ~10 wool 0
fill ~13 ~12 ~11 ~13 ~21 ~11 wool 8
fill ~13 ~12 ~12 ~13 ~13 ~12 wool 14
fill ~13 ~12 ~13 ~13 ~13 ~13 wool 14
fill ~13 ~12 ~14 ~13 ~13 ~14 wool 14
fill ~13 ~12 ~15 ~13 ~13 ~15 wool 14
fill ~13 ~12 ~16 ~13 ~13 ~16 wool 14
fill ~13 ~12 ~17 ~13 ~13 ~17 wool 14
fill ~13 ~12 ~18 ~13 ~13 ~18 wool 14
fill ~13 ~12 ~19 ~13 ~13 ~19 wool 14
fill ~13 ~12 ~20 ~13 ~13 ~20 wool 14
fill ~13 ~12 ~21 ~13 ~13 ~21 wool 14
fill ~13 ~12 ~22 ~13 ~13 ~22 wool 14
fill ~13 ~12 ~23 ~13 ~14 ~23 wool 8
fill ~13 ~12 ~24 ~13 ~14 ~24 wool 8
fill ~13 ~12 ~25 ~13 ~14 ~25 wool 8
fill ~13 ~12 ~26 ~13 ~14 ~26 wool 8
fill ~13 ~12 ~27 ~13 ~14 ~27 wool 8
fill ~13 ~12 ~28 ~13 ~14 ~28 wool 8
fill ~13 ~12 ~29 ~13 ~14 ~29 wool 8
fill ~13 ~12 ~30 ~13 ~14 ~30 wool 8
fill ~13 ~12 ~31 ~13 ~14 ~31 wool 8
fill ~13 ~12 ~32 ~13 ~14 ~32 wool 8
fill ~13 ~12 ~33 ~13 ~14 ~33 wool 8
fill ~13 ~12 ~34 ~13 ~14 ~34 wool 8
fill ~13 ~12 ~50 ~13 ~14 ~50 wool 8
fill ~13 ~12 ~51 ~13 ~14 ~51 wool 8
fill ~13 ~12 ~52 ~13 ~14 ~52 wool 8
fill ~13 ~12 ~53 ~13 ~14 ~53 wool 8
fill ~13 ~12 ~54 ~13 ~14 ~54 wool 8
fill ~13 ~12 ~55 ~13 ~14 ~55 wool 8
fill ~13 ~12 ~56 ~13 ~14 ~56 wool 8
fill ~13 ~12 ~57 ~13 ~14 ~57 wool 8
fill ~13 ~12 ~58 ~13 ~14 ~58 wool 8
fill ~13 ~12 ~59 ~13 ~14 ~59 wool 8
fill ~13 ~12 ~60 ~13 ~14 ~60 wool 8
fill ~13 ~12 ~61 ~13 ~13 ~61 wool 14
fill ~13 ~12 ~62 ~13 ~13 ~62 wool 14
fill ~13 ~12 ~63 ~13 ~13 ~63 wool 14
fill ~13 ~12 ~64 ~13 ~13 ~64 wool 14
fill ~13 ~12 ~65 ~13 ~13 ~65 wool 14
fill ~13 ~12 ~66 ~13 ~13 ~66 wool 14
fill ~13 ~12 ~67 ~13 ~13 ~67 wool 14
fill ~13 ~12 ~68 ~13 ~13 ~68 wool 14
fill ~13 ~12 ~69 ~13 ~13 ~69 wool 14
fill ~13 ~12 ~70 ~13 ~13 ~70 wool 14
fill ~13 ~12 ~71 ~13 ~13 ~71 wool 14
fill ~13 ~12 ~72 ~13 ~14 ~72 wool 8
fill ~13 ~12 ~73 ~13 ~14 ~73 wool 0
fill ~13 ~12 ~74 ~35 ~12 ~74 wool 0
fill ~14 ~12 ~11 ~17 ~12 ~11 wool 14
fill ~14 ~12 ~34 ~14 ~16 ~34 wool 0
fill ~14 ~12 ~50 ~14 ~16 ~50 wool 0
fill ~14 ~12 ~72 ~17 ~12 ~72 wool 14
fill ~14 ~12 ~75 ~16 ~12 ~75 wool 8
fill ~15 ~12 ~8 ~17 ~12 ~8 wool 8
fill ~15 ~12 ~9 ~36 ~12 ~9 wool 0
fill ~16 ~12 ~36 ~17 ~12 ~36 wool 8
fill ~16 ~12 ~48 ~17 ~12 ~48 wool 8
fill ~18 ~12 ~10 ~34 ~12 ~10 wool 15
fill ~18 ~12 ~73 ~33 ~12 ~73 wool 15
fill ~27 ~12 ~18 ~60 ~12 ~18 wool 7
fill ~27 ~12 ~32 ~60 ~12 ~32 wool 7
fill ~34 ~12 ~17 ~62 ~12 ~17 wool 15
fill ~34 ~12 ~66 ~68 ~12 ~66 wool 15
fill ~35 ~12 ~75 ~66 ~12 ~75 wool 0
fill ~36 ~12 ~8 ~47 ~12 ~8 wool 0
fill ~40 ~12 ~72 ~40 ~14 ~72 wool 15
fill ~40 ~12 ~73 ~40 ~14 ~73 wool 15
fill ~41 ~12 ~10 ~41 ~14 ~10 wool 15
fill ~41 ~12 ~11 ~41 ~14 ~11 wool 15
fill ~43 ~12 ~69 ~46 ~12 ~69 wool 15
fill ~44 ~12 ~14 ~47 ~12 ~14 wool 15
fill ~44 ~12 ~73 ~46 ~12 ~73 wool 8
fill ~45 ~12 ~10 ~47 ~12 ~10 wool 8
fill ~47 ~12 ~68 ~54 ~12 ~68 wool 15
fill ~48 ~12 ~8 ~55 ~12 ~8 wool 7
fill ~48 ~12 ~15 ~55 ~12 ~15 wool 15
fill ~50 ~12 ~6 ~53 ~12 ~6 wool 15
fill ~50 ~12 ~73 ~51 ~12 ~73 wool 8
fill ~51 ~12 ~10 ~52 ~12 ~10 wool 8
fill ~54 ~12 ~54 ~54 ~13 ~54 wool 7
fill ~54 ~12 ~55 ~54 ~13 ~55 wool 7
fill ~54 ~12 ~61 ~54 ~13 ~61 wool 7
fill ~54 ~12 ~62 ~54 ~13 ~62 wool 7
fill ~55 ~12 ~69 ~58 ~12 ~69 wool 15
fill ~55 ~12 ~73 ~57 ~12 ~73 wool 8
fill ~56 ~12 ~8 ~67 ~12 ~8 wool 0
fill ~56 ~12 ~10 ~58 ~12 ~10 wool 8
fill ~56 ~12 ~14 ~59 ~12 ~14 wool 15
fill ~56 ~12 ~53 ~59 ~12 ~53 wool 15
fill ~57 ~12 ~63 ~59 ~12 ~63 wool 15
fill ~60 ~12 ~54 ~61 ~12 ~54 wool 15
fill ~60 ~12 ~55 ~60 ~28 ~55 wool 15
fill ~60 ~12 ~57 ~62 ~12 ~57 wool 15
fill ~60 ~12 ~58 ~62 ~12 ~58 wool 15
fill ~60 ~12 ~60 ~60 ~27 ~60 wool 15
fill ~60 ~12 ~61 ~61 ~12 ~61 wool 15
fill ~61 ~12 ~48 ~61 ~13 ~48 wool 15
fill ~61 ~12 ~55 ~61 ~15 ~55 wool 7
setblock ~61 ~12 ~56 wool 14
setblock ~61 ~12 ~59 wool 14
fill ~61 ~12 ~60 ~61 ~15 ~60 wool 7
fill ~61 ~12 ~72 ~61 ~14 ~72 wool 15
fill ~61 ~12 ~73 ~61 ~14 ~73 wool 15
fill ~62 ~12 ~10 ~62 ~14 ~10 wool 15
fill ~62 ~12 ~11 ~62 ~14 ~11 wool 15
fill ~62 ~12 ~18 ~86 ~12 ~18 wool 12
fill ~62 ~12 ~19 ~86 ~12 ~19 wool 12
fill ~62 ~12 ~20 ~86 ~12 ~20 wool 12
fill ~62 ~12 ~21 ~86 ~12 ~21 wool 12
fill ~62 ~12 ~22 ~86 ~12 ~22 wool 12
fill ~62 ~12 ~23 ~86 ~12 ~23 wool 12
fill ~62 ~12 ~24 ~86 ~12 ~24 wool 12
fill ~62 ~12 ~25 ~86 ~12 ~25 wool 12
fill ~62 ~12 ~26 ~86 ~12 ~26 wool 12
fill ~62 ~12 ~27 ~86 ~12 ~27 wool 12
fill ~62 ~12 ~28 ~86 ~12 ~28 wool 12
fill ~62 ~12 ~29 ~86 ~12 ~29 wool 12
fill ~62 ~12 ~30 ~86 ~12 ~30 wool 12
fill ~62 ~12 ~31 ~86 ~12 ~31 wool 12
fill ~62 ~12 ~32 ~86 ~12 ~32 wool 12
fill ~62 ~12 ~33 ~86 ~12 ~33 wool 12
fill ~62 ~12 ~34 ~86 ~12 ~34 wool 12
fill ~62 ~12 ~35 ~86 ~12 ~35 wool 12
fill ~66 ~12 ~74 ~96 ~12 ~74 wool 0
fill ~67 ~12 ~9 ~97 ~12 ~9 wool 0
fill ~68 ~12 ~73 ~136 ~12 ~73 wool 15
fill ~69 ~12 ~10 ~136 ~12 ~10 wool 15
fill ~69 ~12 ~53 ~69 ~13 ~53 wool 7
fill ~69 ~12 ~54 ~69 ~13 ~54 wool 7
fill ~69 ~12 ~60 ~69 ~13 ~60 wool 7
fill ~69 ~12 ~61 ~69 ~13 ~61 wool 7
fill ~71 ~12 ~52 ~74 ~12 ~52 wool 15
fill ~72 ~12 ~62 ~74 ~12 ~62 wool 15
fill ~75 ~12 ~53 ~76 ~12 ~53 wool 15
fill ~75 ~12 ~54 ~75 ~28 ~54 wool 15
fill ~75 ~12 ~56 ~77 ~12 ~56 wool 15
fill ~75 ~12 ~57 ~77 ~12 ~57 wool 15
fill ~75 ~12 ~59 ~75 ~27 ~59 wool 15
fill ~75 ~12 ~60 ~76 ~12 ~60 wool 15
fill ~76 ~12 ~47 ~76 ~13 ~47 wool 15
fill ~76 ~12 ~54 ~76 ~15 ~54 wool 7
setblock ~76 ~12 ~55 wool 14
setblock ~76 ~12 ~58 wool 14
fill ~76 ~12 ~59 ~76 ~15 ~59 wool 7
fill ~91 ~12 ~16 ~108 ~12 ~16 wool 12
fill ~91 ~12 ~17 ~108 ~12 ~17 wool 12
fill ~91 ~12 ~18 ~108 ~12 ~18 wool 12
fill ~91 ~12 ~19 ~108 ~12 ~19 wool 12
fill ~91 ~12 ~20 ~108 ~12 ~20 wool 12
fill ~91 ~12 ~21 ~108 ~12 ~21 wool 12
fill ~91 ~12 ~22 ~108 ~12 ~22 wool 12
fill ~91 ~12 ~23 ~108 ~12 ~23 wool 12
fill ~91 ~12 ~24 ~108 ~12 ~24 wool 12
fill ~91 ~12 ~25 ~108 ~12 ~25 wool 12
fill ~91 ~12 ~26 ~108 ~12 ~26 wool 12
fill ~91 ~12 ~27 ~108 ~12 ~27 wool 12
fill ~91 ~12 ~28 ~108 ~12 ~28 wool 12
fill ~91 ~12 ~29 ~108 ~12 ~29 wool 12
fill ~91 ~12 ~30 ~108 ~12 ~30 wool 12
fill ~91 ~12 ~31 ~108 ~12 ~31 wool 12
fill ~91 ~12 ~32 ~108 ~12 ~32 wool 12
fill ~91 ~12 ~33 ~108 ~12 ~33 wool 12
fill ~91 ~12 ~34 ~108 ~12 ~34 wool 12
fill ~91 ~12 ~35 ~108 ~12 ~35 wool 12
fill ~91 ~12 ~36 ~108 ~12 ~36 wool 12
fill ~91 ~12 ~37 ~108 ~12 ~37 wool 12
fill ~91 ~12 ~38 ~108 ~12 ~38 wool 12
fill ~91 ~12 ~39 ~108 ~12 ~39 wool 12
fill ~91 ~12 ~40 ~108 ~12 ~40 wool 12
fill ~91 ~12 ~41 ~108 ~12 ~41 wool 12
fill ~91 ~12 ~42 ~108 ~12 ~42 wool 12
fill ~91 ~12 ~43 ~108 ~12 ~43 wool 12
fill ~91 ~12 ~44 ~108 ~12 ~44 wool 12
fill ~91 ~12 ~45 ~108 ~12 ~45 wool 12
fill ~91 ~12 ~46 ~108 ~12 ~46 wool 12
fill ~91 ~12 ~47 ~108 ~12 ~47 wool 12
fill ~91 ~12 ~48 ~108 ~12 ~48 wool 12
fill ~91 ~12 ~49 ~108 ~12 ~49 wool 12
fill ~91 ~12 ~50 ~108 ~12 ~50 wool 12
fill ~91 ~12 ~51 ~108 ~12 ~51 wool 12
fill ~91 ~12 ~52 ~108 ~12 ~52 wool 12
fill ~91 ~12 ~53 ~108 ~12 ~53 wool 12
fill ~91 ~12 ~54 ~108 ~12 ~54 wool 12
fill ~91 ~12 ~55 ~108 ~12 ~55 wool 12
fill ~91 ~12 ~56 ~108 ~12 ~56 wool 12
fill ~91 ~12 ~57 ~108 ~12 ~57 wool 12
fill ~91 ~12 ~58 ~108 ~12 ~58 wool 12
fill ~91 ~12 ~59 ~108 ~12 ~59 wool 12
fill ~91 ~12 ~60 ~108 ~12 ~60 wool 12
fill ~91 ~12 ~61 ~108 ~12 ~61 wool 12
fill ~91 ~12 ~62 ~108 ~12 ~62 wool 12
fill ~91 ~12 ~63 ~108 ~12 ~63 wool 12
fill ~91 ~12 ~64 ~108 ~12 ~64 wool 12
fill ~91 ~12 ~65 ~108 ~12 ~65 wool 12
fill ~91 ~12 ~66 ~108 ~12 ~66 wool 12
fill ~91 ~12 ~67 ~108 ~12 ~67 wool 12
setblock ~97 ~12 ~74 wool 15
setblock ~98 ~12 ~9 wool 15
fill ~98 ~12 ~74 ~100 ~12 ~74 wool 0
fill ~99 ~12 ~9 ~101 ~12 ~9 wool 0
fill ~102 ~12 ~74 ~105 ~12 ~74 wool 0
fill ~103 ~12 ~9 ~106 ~12 ~9 wool 0
setblock ~106 ~12 ~74 wool 15
setblock ~107 ~12 ~9 wool 15
setblock ~108 ~12 ~74 wool 0
setblock ~109 ~12 ~9 wool 0
fill ~109 ~12 ~74 ~111 ~12 ~74 wool 14
fill ~110 ~12 ~9 ~112 ~12 ~9 wool 14
fill ~112 ~12 ~74 ~138 ~12 ~74 wool 0
fill ~113 ~12 ~9 ~138 ~12 ~9 wool 0
fill ~120 ~12 ~26 ~120 ~13 ~26 wool 15
fill ~120 ~12 ~27 ~120 ~12 ~30 wool 15
fill ~138 ~12 ~8 ~138 ~13 ~8 wool 0
fill ~138 ~12 ~75 ~138 ~13 ~75 wool 0
fill ~143 ~12 ~10 ~143 ~14 ~10 wool 15
fill ~143 ~12 ~11 ~143 ~14 ~11 wool 15
fill ~143 ~12 ~72 ~143 ~14 ~72 wool 15
fill ~143 ~12 ~73 ~143 ~14 ~73 wool 15
setblock ~144 ~12 ~8 wool 15
fill ~146 ~12 ~14 ~149 ~12 ~14 wool 15
fill ~146 ~12 ~69 ~149 ~12 ~69 wool 15
fill ~147 ~12 ~10 ~149 ~12 ~10 wool 8
fill ~147 ~12 ~73 ~149 ~12 ~73 wool 8
fill ~150 ~12 ~15 ~157 ~12 ~15 wool 15
fill ~150 ~12 ~68 ~157 ~12 ~68 wool 15
fill ~153 ~12 ~10 ~154 ~12 ~10 wool 8
fill ~153 ~12 ~73 ~154 ~12 ~73 wool 8
fill ~158 ~12 ~10 ~160 ~12 ~10 wool 8
fill ~158 ~12 ~14 ~161 ~12 ~14 wool 15
fill ~158 ~12 ~69 ~161 ~12 ~69 wool 15
fill ~158 ~12 ~73 ~160 ~12 ~73 wool 8
setblock ~163 ~12 ~8 wool 15
fill ~164 ~12 ~10 ~164 ~14 ~10 wool 15
fill ~164 ~12 ~11 ~164 ~14 ~11 wool 15
fill ~164 ~12 ~72 ~164 ~14 ~72 wool 15
fill ~164 ~12 ~73 ~164 ~14 ~73 wool 15
fill ~169 ~12 ~8 ~169 ~13 ~8 wool 0
fill ~169 ~12 ~9 ~175 ~12 ~9 wool 0
fill ~169 ~12 ~74 ~175 ~12 ~74 wool 0
fill ~169 ~12 ~75 ~169 ~13 ~75 wool 0
fill ~176 ~12 ~9 ~176 ~14 ~9 wool 8
fill ~176 ~12 ~10 ~176 ~14 ~10 wool 8
fill ~176 ~12 ~11 ~176 ~12 ~72 wool 0
fill ~176 ~12 ~73 ~176 ~14 ~73 wool 8
fill ~176 ~12 ~74 ~176 ~14 ~74 wool 8
fill ~12 ~13 ~74 ~35 ~13 ~74 wool 0
fill ~13 ~13 ~9 ~13 ~16 ~9 wool 0
fill ~14 ~13 ~11 ~17 ~13 ~11 wool 14
fill ~14 ~13 ~72 ~17 ~13 ~72 wool 14
fill ~15 ~13 ~9 ~36 ~13 ~9 wool 0
fill ~16 ~13 ~36 ~17 ~13 ~36 wool 8
fill ~16 ~13 ~48 ~17 ~13 ~48 wool 8
setblock ~17 ~13 ~10 wool 0
fill ~18 ~13 ~10 ~34 ~13 ~10 wool 15
fill ~18 ~13 ~73 ~33 ~13 ~73 wool 15
fill ~27 ~13 ~18 ~60 ~13 ~18 wool 7
fill ~27 ~13 ~32 ~60 ~13 ~32 wool 7
fill ~34 ~13 ~17 ~62 ~13 ~17 wool 15
fill ~34 ~13 ~66 ~68 ~13 ~66 wool 15
fill ~35 ~13 ~75 ~66 ~13 ~75 wool 0
fill ~36 ~13 ~8 ~47 ~13 ~8 wool 0
fill ~41 ~13 ~71 ~41 ~14 ~71 wool 15
fill ~41 ~13 ~74 ~41 ~14 ~74 wool 15
fill ~42 ~13 ~9 ~42 ~14 ~9 wool 15
fill ~42 ~13 ~12 ~42 ~14 ~12 wool 15
fill ~43 ~13 ~70 ~43 ~15 ~70 wool 15
fill ~44 ~13 ~13 ~44 ~15 ~13 wool 15
fill ~44 ~13 ~69 ~47 ~13 ~69 wool 15
fill ~44 ~13 ~74 ~44 ~15 ~74 wool 8
fill ~45 ~13 ~9 ~45 ~15 ~9 wool 8
fill ~45 ~13 ~14 ~48 ~13 ~14 wool 15
setblock ~45 ~13 ~73 wool 8
setblock ~46 ~13 ~10 wool 8
fill ~48 ~13 ~8 ~55 ~13 ~8 wool 7
fill ~48 ~13 ~68 ~53 ~13 ~68 wool 15
fill ~49 ~13 ~15 ~54 ~13 ~15 wool 15
fill ~50 ~13 ~6 ~53 ~13 ~6 wool 15
fill ~50 ~13 ~73 ~51 ~13 ~73 wool 8
fill ~51 ~13 ~10 ~52 ~13 ~10 wool 8
fill ~54 ~13 ~69 ~57 ~13 ~69 wool 15
fill ~55 ~13 ~14 ~58 ~13 ~14 wool 15
fill ~56 ~13 ~8 ~67 ~13 ~8 wool 0
fill ~56 ~13 ~53 ~60 ~13 ~53 wool 15
setblock ~56 ~13 ~73 wool 8
setblock ~57 ~13 ~10 wool 8
fill ~57 ~13 ~63 ~60 ~13 ~63 wool 15
fill ~57 ~13 ~74 ~57 ~15 ~74 wool 8
fill ~58 ~13 ~9 ~58 ~15 ~9 wool 8
fill ~58 ~13 ~70 ~58 ~15 ~70 wool 15
fill ~59 ~13 ~13 ~59 ~15 ~13 wool 15
fill ~60 ~13 ~54 ~60 ~27 ~54 wool 15
fill ~60 ~13 ~57 ~61 ~13 ~57 wool 15
fill ~60 ~13 ~58 ~61 ~13 ~58 wool 15
fill ~60 ~13 ~61 ~60 ~27 ~61 wool 15
fill ~60 ~13 ~71 ~60 ~14 ~71 wool 15
fill ~60 ~13 ~74 ~60 ~14 ~74 wool 15
fill ~61 ~13 ~9 ~61 ~14 ~9 wool 15
fill ~61 ~13 ~12 ~61 ~14 ~12 wool 15
fill ~61 ~13 ~52 ~61 ~14 ~52 wool 7
fill ~61 ~13 ~53 ~61 ~14 ~53 wool 7
fill ~61 ~13 ~54 ~61 ~14 ~54 wool 11
fill ~61 ~13 ~56 ~62 ~13 ~56 wool 15
fill ~61 ~13 ~59 ~62 ~13 ~59 wool 15
fill ~61 ~13 ~61 ~61 ~14 ~61 wool 7
fill ~61 ~13 ~62 ~61 ~14 ~62 wool 7
fill ~61 ~13 ~63 ~61 ~14 ~63 wool 7
fill ~62 ~13 ~15 ~86 ~13 ~15 wool 12
fill ~62 ~13 ~16 ~86 ~13 ~16 wool 12
fill ~62 ~13 ~18 ~86 ~13 ~18 wool 12
fill ~62 ~13 ~19 ~86 ~13 ~19 wool 12
fill ~62 ~13 ~20 ~86 ~13 ~20 wool 12
fill ~62 ~13 ~21 ~86 ~13 ~21 wool 12
fill ~62 ~13 ~22 ~86 ~13 ~22 wool 12
fill ~62 ~13 ~23 ~86 ~13 ~23 wool 12
fill ~62 ~13 ~24 ~86 ~13 ~24 wool 12
fill ~62 ~13 ~25 ~86 ~13 ~25 wool 12
fill ~62 ~13 ~26 ~86 ~13 ~26 wool 12
fill ~62 ~13 ~27 ~86 ~13 ~27 wool 12
fill ~62 ~13 ~28 ~86 ~13 ~28 wool 12
fill ~62 ~13 ~29 ~86 ~13 ~29 wool 12
fill ~62 ~13 ~30 ~86 ~13 ~30 wool 12
fill ~62 ~13 ~31 ~86 ~13 ~31 wool 12
fill ~62 ~13 ~32 ~86 ~13 ~32 wool 12
fill ~62 ~13 ~33 ~86 ~13 ~33 wool 12
fill ~62 ~13 ~34 ~86 ~13 ~34 wool 12
fill ~62 ~13 ~35 ~86 ~13 ~35 wool 12
fill ~62 ~13 ~48 ~62 ~16 ~48 wool 15
fill ~62 ~13 ~57 ~62 ~14 ~57 wool 7
fill ~62 ~13 ~58 ~62 ~14 ~58 wool 7
fill ~63 ~13 ~17 ~86 ~13 ~17 wool 12
fill ~66 ~13 ~74 ~97 ~13 ~74 wool 0
fill ~67 ~13 ~9 ~98 ~13 ~9 wool 0
fill ~68 ~13 ~73 ~136 ~13 ~73 wool 15
fill ~69 ~13 ~10 ~136 ~13 ~10 wool 15
fill ~71 ~13 ~52 ~75 ~13 ~52 wool 15
fill ~72 ~13 ~62 ~75 ~13 ~62 wool 15
fill ~75 ~13 ~53 ~75 ~27 ~53 wool 15
fill ~75 ~13 ~56 ~76 ~13 ~56 wool 15
fill ~75 ~13 ~57 ~76 ~13 ~57 wool 15
fill ~75 ~13 ~60 ~75 ~27 ~60 wool 15
fill ~76 ~13 ~51 ~76 ~14 ~51 wool 7
fill ~76 ~13 ~52 ~76 ~14 ~52 wool 7
fill ~76 ~13 ~53 ~76 ~14 ~53 wool 11
fill ~76 ~13 ~55 ~77 ~13 ~55 wool 15
fill ~76 ~13 ~58 ~77 ~13 ~58 wool 15
fill ~76 ~13 ~60 ~76 ~14 ~60 wool 7
fill ~76 ~13 ~61 ~76 ~14 ~61 wool 7
fill ~76 ~13 ~62 ~76 ~14 ~62 wool 7
fill ~77 ~13 ~47 ~77 ~16 ~47 wool 15
fill ~77 ~13 ~56 ~77 ~14 ~56 wool 7
fill ~77 ~13 ~57 ~77 ~14 ~57 wool 7
fill ~88 ~13 ~16 ~108 ~13 ~16 wool 12
fill ~88 ~13 ~17 ~108 ~13 ~17 wool 12
fill ~88 ~13 ~18 ~108 ~13 ~18 wool 12
fill ~88 ~13 ~19 ~108 ~13 ~19 wool 12
fill ~88 ~13 ~20 ~108 ~13 ~20 wool 12
fill ~88 ~13 ~21 ~108 ~13 ~21 wool 12
fill ~88 ~13 ~22 ~108 ~13 ~22 wool 12
fill ~88 ~13 ~23 ~108 ~13 ~23 wool 12
fill ~88 ~13 ~24 ~108 ~13 ~24 wool 12
fill ~88 ~13 ~25 ~108 ~13 ~25 wool 12
fill ~88 ~13 ~26 ~108 ~13 ~26 wool 12
fill ~88 ~13 ~27 ~108 ~13 ~27 wool 12
fill ~88 ~13 ~28 ~108 ~13 ~28 wool 12
fill ~88 ~13 ~29 ~108 ~13 ~29 wool 12
fill ~88 ~13 ~30 ~108 ~13 ~30 wool 12
fill ~88 ~13 ~31 ~108 ~13 ~31 wool 12
fill ~88 ~13 ~32 ~108 ~13 ~32 wool 12
fill ~88 ~13 ~33 ~108 ~13 ~33 wool 12
fill ~88 ~13 ~34 ~108 ~13 ~34 wool 12
fill ~88 ~13 ~35 ~108 ~13 ~35 wool 12
fill ~88 ~13 ~36 ~108 ~13 ~36 wool 12
fill ~88 ~13 ~37 ~108 ~13 ~37 wool 12
fill ~88 ~13 ~38 ~108 ~13 ~38 wool 12
fill ~88 ~13 ~39 ~108 ~13 ~39 wool 12
fill ~88 ~13 ~40 ~108 ~13 ~40 wool 12
fill ~88 ~13 ~41 ~108 ~13 ~41 wool 12
fill ~88 ~13 ~42 ~108 ~13 ~42 wool 12
fill ~88 ~13 ~43 ~108 ~13 ~43 wool 12
fill ~88 ~13 ~44 ~108 ~13 ~44 wool 12
fill ~88 ~13 ~45 ~108 ~13 ~45 wool 12
fill ~88 ~13 ~46 ~108 ~13 ~46 wool 12
fill ~88 ~13 ~47 ~108 ~13 ~47 wool 12
fill ~88 ~13 ~48 ~108 ~13 ~48 wool 12
fill ~88 ~13 ~49 ~108 ~13 ~49 wool 12
fill ~88 ~13 ~50 ~108 ~13 ~50 wool 12
fill ~88 ~13 ~51 ~108 ~13 ~51 wool 12
fill ~88 ~13 ~52 ~108 ~13 ~52 wool 12
fill ~88 ~13 ~53 ~108 ~13 ~53 wool 12
fill ~88 ~13 ~54 ~108 ~13 ~54 wool 12
fill ~88 ~13 ~55 ~108 ~13 ~55 wool 12
fill ~88 ~13 ~56 ~108 ~13 ~56 wool 12
fill ~88 ~13 ~57 ~108 ~13 ~57 wool 12
fill ~88 ~13 ~58 ~108 ~13 ~58 wool 12
fill ~88 ~13 ~59 ~108 ~13 ~59 wool 12
fill ~88 ~13 ~60 ~108 ~13 ~60 wool 12
fill ~88 ~13 ~61 ~108 ~13 ~61 wool 12
fill ~88 ~13 ~62 ~108 ~13 ~62 wool 12
fill ~88 ~13 ~63 ~108 ~13 ~63 wool 12
fill ~88 ~13 ~64 ~108 ~13 ~64 wool 12
fill ~88 ~13 ~65 ~108 ~13 ~65 wool 12
fill ~88 ~13 ~66 ~108 ~13 ~66 wool 12
fill ~88 ~13 ~67 ~108 ~13 ~67 wool 12
fill ~98 ~13 ~74 ~99 ~13 ~74 wool 15
fill ~99 ~13 ~9 ~100 ~13 ~9 wool 15
fill ~101 ~13 ~74 ~101 ~14 ~74 wool 0
fill ~102 ~13 ~9 ~102 ~14 ~9 wool 0
fill ~102 ~13 ~74 ~102 ~14 ~74 wool 15
fill ~103 ~13 ~9 ~103 ~14 ~9 wool 15
fill ~103 ~13 ~74 ~107 ~13 ~74 wool 0
fill ~104 ~13 ~9 ~108 ~13 ~9 wool 0
setblock ~108 ~13 ~74 wool 15
setblock ~109 ~13 ~9 wool 15
setblock ~109 ~13 ~74 wool 0
setblock ~110 ~13 ~9 wool 0
fill ~110 ~13 ~74 ~112 ~13 ~74 wool 14
fill ~111 ~13 ~9 ~113 ~13 ~9 wool 14
fill ~113 ~13 ~74 ~130 ~13 ~74 wool 0
fill ~114 ~13 ~9 ~138 ~13 ~9 wool 0
fill ~120 ~13 ~24 ~120 ~14 ~24 wool 15
fill ~120 ~13 ~25 ~120 ~13 ~24 wool 15
fill ~120 ~13 ~30 ~120 ~13 ~32 wool 15
fill ~131 ~13 ~74 ~133 ~13 ~74 wool 8
fill ~134 ~13 ~74 ~138 ~13 ~74 wool 0
fill ~144 ~13 ~9 ~144 ~14 ~9 wool 15
fill ~144 ~13 ~12 ~144 ~14 ~12 wool 15
fill ~144 ~13 ~71 ~144 ~14 ~71 wool 15
fill ~144 ~13 ~74 ~144 ~14 ~74 wool 15
fill ~146 ~13 ~8 ~146 ~15 ~8 wool 0
fill ~146 ~13 ~13 ~146 ~15 ~13 wool 15
fill ~146 ~13 ~70 ~146 ~15 ~70 wool 15
fill ~146 ~13 ~75 ~146 ~15 ~75 wool 0
fill ~147 ~13 ~9 ~147 ~15 ~9 wool 8
fill ~147 ~13 ~14 ~150 ~13 ~14 wool 15
fill ~147 ~13 ~69 ~150 ~13 ~69 wool 15
fill ~147 ~13 ~74 ~147 ~15 ~74 wool 8
setblock ~148 ~13 ~10 wool 8
setblock ~148 ~13 ~73 wool 8
fill ~151 ~13 ~15 ~156 ~13 ~15 wool 15
fill ~151 ~13 ~68 ~156 ~13 ~68 wool 15
fill ~153 ~13 ~10 ~154 ~13 ~10 wool 8
fill ~153 ~13 ~73 ~154 ~13 ~73 wool 8
fill ~157 ~13 ~14 ~160 ~13 ~14 wool 15
fill ~157 ~13 ~69 ~160 ~13 ~69 wool 15
setblock ~159 ~13 ~10 wool 8
setblock ~159 ~13 ~73 wool 8
fill ~160 ~13 ~9 ~160 ~15 ~9 wool 8
fill ~160 ~13 ~74 ~160 ~15 ~74 wool 8
fill ~161 ~13 ~8 ~161 ~15 ~8 wool 0
fill ~161 ~13 ~13 ~161 ~15 ~13 wool 15
fill ~161 ~13 ~70 ~161 ~15 ~70 wool 15
fill ~161 ~13 ~75 ~161 ~15 ~75 wool 0
fill ~163 ~13 ~9 ~163 ~14 ~9 wool 15
fill ~163 ~13 ~12 ~163 ~14 ~12 wool 15
fill ~163 ~13 ~71 ~163 ~14 ~71 wool 15
fill ~163 ~13 ~74 ~163 ~14 ~74 wool 15
fill ~169 ~13 ~9 ~175 ~13 ~9 wool 0
fill ~169 ~13 ~74 ~175 ~13 ~74 wool 0
fill ~175 ~13 ~10 ~175 ~13 ~73 wool 8
fill ~176 ~13 ~11 ~176 ~13 ~74 wool 8
fill ~12 ~14 ~74 ~36 ~14 ~74 wool 0
fill ~13 ~14 ~12 ~13 ~21 ~12 wool 8
fill ~13 ~14 ~13 ~13 ~21 ~13 wool 8
fill ~13 ~14 ~14 ~13 ~14 ~34 wool 8
fill ~13 ~14 ~61 ~13 ~14 ~72 wool 8
fill ~14 ~14 ~11 ~17 ~14 ~11 wool 14
fill ~14 ~14 ~72 ~17 ~14 ~72 wool 14
fill ~15 ~14 ~9 ~37 ~14 ~9 wool 0
fill ~15 ~14 ~36 ~15 ~14 ~49 double_stone_slab 0
fill ~16 ~14 ~36 ~17 ~14 ~36 wool 8
fill ~16 ~14 ~48 ~17 ~14 ~48 wool 8
fill ~18 ~14 ~10 ~34 ~14 ~10 wool 15
fill ~18 ~14 ~73 ~33 ~14 ~73 wool 15
fill ~27 ~14 ~18 ~60 ~14 ~18 wool 7
fill ~27 ~14 ~32 ~60 ~14 ~32 wool 7
fill ~34 ~14 ~17 ~62 ~14 ~17 wool 15
fill ~34 ~14 ~66 ~68 ~14 ~66 wool 15
fill ~36 ~14 ~75 ~65 ~14 ~75 wool 0
fill ~37 ~14 ~8 ~47 ~14 ~8 wool 0
fill ~44 ~14 ~69 ~57 ~14 ~69 wool 15
fill ~45 ~14 ~14 ~58 ~14 ~14 wool 15
fill ~48 ~14 ~8 ~55 ~14 ~8 wool 7
fill ~50 ~14 ~6 ~53 ~14 ~6 wool 15
fill ~50 ~14 ~73 ~51 ~14 ~73 wool 8
fill ~51 ~14 ~10 ~52 ~14 ~10 wool 8
fill ~55 ~14 ~54 ~55 ~17 ~54 wool 7
fill ~55 ~14 ~55 ~55 ~17 ~55 wool 7
fill ~55 ~14 ~61 ~55 ~17 ~61 wool 7
fill ~55 ~14 ~62 ~55 ~17 ~62 wool 7
fill ~56 ~14 ~8 ~66 ~14 ~8 wool 0
fill ~56 ~14 ~53 ~60 ~14 ~53 wool 15
fill ~57 ~14 ~63 ~60 ~14 ~63 wool 15
fill ~60 ~14 ~57 ~61 ~14 ~57 wool 15
fill ~60 ~14 ~58 ~61 ~14 ~58 wool 15
fill ~61 ~14 ~56 ~62 ~14 ~56 wool 15
fill ~61 ~14 ~59 ~62 ~14 ~59 wool 15
fill ~62 ~14 ~14 ~86 ~14 ~14 wool 12
fill ~62 ~14 ~15 ~86 ~14 ~15 wool 12
fill ~62 ~14 ~16 ~91 ~14 ~16 wool 12
fill ~62 ~14 ~18 ~107 ~14 ~18 wool 12
fill ~63 ~14 ~17 ~107 ~14 ~17 wool 12
fill ~63 ~14 ~19 ~107 ~14 ~19 wool 12
fill ~63 ~14 ~20 ~107 ~14 ~20 wool 12
fill ~63 ~14 ~21 ~107 ~14 ~21 wool 12
fill ~63 ~14 ~22 ~107 ~14 ~22 wool 12
fill ~63 ~14 ~23 ~107 ~14 ~23 wool 12
fill ~63 ~14 ~24 ~107 ~14 ~24 wool 12
fill ~63 ~14 ~25 ~107 ~14 ~25 wool 12
fill ~63 ~14 ~26 ~107 ~14 ~26 wool 12
fill ~63 ~14 ~27 ~107 ~14 ~27 wool 12
fill ~63 ~14 ~28 ~107 ~14 ~28 wool 12
fill ~63 ~14 ~29 ~107 ~14 ~29 wool 12
fill ~63 ~14 ~30 ~107 ~14 ~30 wool 12
fill ~63 ~14 ~31 ~107 ~14 ~31 wool 12
fill ~63 ~14 ~32 ~107 ~14 ~32 wool 12
fill ~63 ~14 ~33 ~107 ~14 ~33 wool 12
fill ~63 ~14 ~34 ~107 ~14 ~34 wool 12
fill ~65 ~14 ~74 ~97 ~14 ~74 wool 0
fill ~66 ~14 ~9 ~98 ~14 ~9 wool 0
fill ~68 ~14 ~73 ~136 ~14 ~73 wool 15
fill ~69 ~14 ~10 ~136 ~14 ~10 wool 15
fill ~70 ~14 ~53 ~70 ~17 ~53 wool 7
fill ~70 ~14 ~54 ~70 ~17 ~54 wool 7
fill ~70 ~14 ~60 ~70 ~17 ~60 wool 7
fill ~70 ~14 ~61 ~70 ~17 ~61 wool 7
fill ~71 ~14 ~52 ~75 ~14 ~52 wool 15
fill ~72 ~14 ~62 ~75 ~14 ~62 wool 15
fill ~75 ~14 ~56 ~76 ~14 ~56 wool 15
fill ~75 ~14 ~57 ~76 ~14 ~57 wool 15
fill ~76 ~14 ~55 ~77 ~14 ~55 wool 15
fill ~76 ~14 ~58 ~77 ~14 ~58 wool 15
fill ~87 ~14 ~35 ~107 ~14 ~35 wool 12
fill ~87 ~14 ~36 ~107 ~14 ~36 wool 12
fill ~87 ~14 ~37 ~107 ~14 ~37 wool 12
fill ~87 ~14 ~38 ~107 ~14 ~38 wool 12
fill ~87 ~14 ~39 ~107 ~14 ~39 wool 12
fill ~87 ~14 ~40 ~107 ~14 ~40 wool 12
fill ~87 ~14 ~41 ~107 ~14 ~41 wool 12
fill ~87 ~14 ~42 ~107 ~14 ~42 wool 12
fill ~87 ~14 ~43 ~107 ~14 ~43 wool 12
fill ~87 ~14 ~44 ~107 ~14 ~44 wool 12
fill ~87 ~14 ~45 ~107 ~14 ~45 wool 12
fill ~87 ~14 ~46 ~107 ~14 ~46 wool 12
fill ~87 ~14 ~47 ~107 ~14 ~47 wool 12
fill ~87 ~14 ~48 ~107 ~14 ~48 wool 12
fill ~87 ~14 ~49 ~107 ~14 ~49 wool 12
fill ~87 ~14 ~50 ~107 ~14 ~50 wool 12
fill ~87 ~14 ~51 ~107 ~14 ~51 wool 12
fill ~87 ~14 ~52 ~107 ~14 ~52 wool 12
fill ~87 ~14 ~53 ~107 ~14 ~53 wool 12
fill ~87 ~14 ~54 ~107 ~14 ~54 wool 12
fill ~87 ~14 ~55 ~107 ~14 ~55 wool 12
fill ~87 ~14 ~56 ~107 ~14 ~56 wool 12
fill ~87 ~14 ~57 ~107 ~14 ~57 wool 12
fill ~87 ~14 ~58 ~107 ~14 ~58 wool 12
fill ~87 ~14 ~59 ~107 ~14 ~59 wool 12
fill ~87 ~14 ~60 ~107 ~14 ~60 wool 12
fill ~87 ~14 ~61 ~107 ~14 ~61 wool 12
fill ~87 ~14 ~62 ~107 ~14 ~62 wool 12
fill ~87 ~14 ~63 ~107 ~14 ~63 wool 12
fill ~87 ~14 ~64 ~107 ~14 ~64 wool 12
fill ~87 ~14 ~65 ~107 ~14 ~65 wool 12
fill ~87 ~14 ~66 ~107 ~14 ~66 wool 12
fill ~87 ~14 ~67 ~91 ~14 ~67 wool 12
fill ~98 ~14 ~74 ~99 ~14 ~74 wool 14
fill ~99 ~14 ~9 ~100 ~14 ~9 wool 14
setblock ~100 ~14 ~74 wool 15
setblock ~101 ~14 ~9 wool 15
fill ~103 ~14 ~74 ~104 ~14 ~74 wool 0
fill ~104 ~14 ~9 ~105 ~14 ~9 wool 0
fill ~105 ~14 ~74 ~111 ~14 ~74 wool 14
fill ~106 ~14 ~9 ~112 ~14 ~9 wool 14
setblock ~112 ~14 ~74 wool 15
setblock ~113 ~14 ~9 wool 15
fill ~113 ~14 ~74 ~139 ~14 ~74 wool 0
fill ~114 ~14 ~9 ~139 ~14 ~9 wool 0
fill ~120 ~14 ~22 ~120 ~16 ~22 wool 15
fill ~120 ~14 ~23 ~120 ~14 ~22 wool 15
fill ~120 ~14 ~32 ~120 ~14 ~34 wool 15
setblock ~139 ~14 ~8 wool 0
setblock ~139 ~14 ~75 wool 0
setblock ~145 ~14 ~8 wool 15
setblock ~145 ~14 ~75 wool 15
fill ~147 ~14 ~14 ~160 ~14 ~14 wool 15
fill ~147 ~14 ~69 ~160 ~14 ~69 wool 15
fill ~153 ~14 ~10 ~154 ~14 ~10 wool 8
fill ~153 ~14 ~73 ~154 ~14 ~73 wool 8
setblock ~162 ~14 ~8 wool 15
setblock ~162 ~14 ~75 wool 15
fill ~168 ~14 ~8 ~168 ~14 ~9 wool 0
fill ~168 ~14 ~74 ~175 ~14 ~74 wool 0
fill ~168 ~14 ~75 ~168 ~14 ~74 wool 0
fill ~169 ~14 ~9 ~175 ~14 ~9 wool 0
fill ~175 ~14 ~14 ~175 ~15 ~14 wool 15
fill ~175 ~14 ~15 ~175 ~14 ~14 wool 15
fill ~175 ~14 ~16 ~175 ~20 ~16 glowstone 0
fill ~175 ~14 ~17 ~175 ~20 ~17 glowstone 0
fill ~175 ~14 ~18 ~175 ~20 ~18 glowstone 0
fill ~175 ~14 ~19 ~175 ~14 ~20 wool 15
fill ~175 ~14 ~63 ~175 ~15 ~63 wool 15
fill ~175 ~14 ~64 ~175 ~14 ~63 wool 15
fill ~175 ~14 ~65 ~175 ~20 ~65 glowstone 0
fill ~175 ~14 ~66 ~175 ~20 ~66 glowstone 0
fill ~175 ~14 ~67 ~175 ~20 ~67 glowstone 0
fill ~175 ~14 ~68 ~175 ~14 ~69 wool 15
fill ~176 ~14 ~11 ~176 ~16 ~11 wool 15
fill ~176 ~14 ~12 ~176 ~16 ~12 wool 15
fill ~176 ~14 ~13 ~176 ~21 ~13 wool 8
fill ~176 ~14 ~21 ~176 ~21 ~21 wool 8
fill ~176 ~14 ~22 ~176 ~21 ~22 wool 15
fill ~176 ~14 ~23 ~176 ~21 ~23 wool 15
fill ~176 ~14 ~24 ~176 ~21 ~24 wool 15
fill ~176 ~14 ~25 ~176 ~21 ~25 wool 15
fill ~176 ~14 ~26 ~176 ~21 ~26 wool 15
fill ~176 ~14 ~27 ~176 ~21 ~27 wool 15
fill ~176 ~14 ~28 ~176 ~21 ~28 wool 15
fill ~176 ~14 ~29 ~176 ~21 ~29 wool 15
fill ~176 ~14 ~30 ~176 ~21 ~30 wool 15
fill ~176 ~14 ~31 ~176 ~21 ~31 wool 15
fill ~176 ~14 ~32 ~176 ~21 ~32 wool 15
fill ~176 ~14 ~33 ~176 ~21 ~33 wool 15
fill ~176 ~14 ~34 ~176 ~21 ~34 wool 15
fill ~176 ~14 ~35 ~176 ~21 ~35 wool 15
fill ~176 ~14 ~36 ~176 ~21 ~36 wool 15
fill ~176 ~14 ~37 ~176 ~21 ~37 wool 15
fill ~176 ~14 ~38 ~176 ~21 ~38 wool 15
fill ~176 ~14 ~39 ~176 ~21 ~39 wool 15
fill ~176 ~14 ~40 ~176 ~21 ~40 wool 15
fill ~176 ~14 ~41 ~176 ~21 ~41 wool 15
fill ~176 ~14 ~42 ~176 ~21 ~42 wool 15
fill ~176 ~14 ~43 ~176 ~21 ~43 wool 15
fill ~176 ~14 ~44 ~176 ~21 ~44 wool 15
fill ~176 ~14 ~45 ~176 ~21 ~45 wool 15
fill ~176 ~14 ~46 ~176 ~21 ~46 wool 15
fill ~176 ~14 ~47 ~176 ~21 ~47 wool 15
fill ~176 ~14 ~48 ~176 ~21 ~48 wool 15
fill ~176 ~14 ~49 ~176 ~21 ~49 wool 15
fill ~176 ~14 ~50 ~176 ~21 ~50 wool 15
fill ~176 ~14 ~51 ~176 ~21 ~51 wool 15
fill ~176 ~14 ~52 ~176 ~21 ~52 wool 15
fill ~176 ~14 ~53 ~176 ~21 ~53 wool 15
fill ~176 ~14 ~54 ~176 ~21 ~54 wool 15
fill ~176 ~14 ~55 ~176 ~21 ~55 wool 15
fill ~176 ~14 ~56 ~176 ~21 ~56 wool 15
fill ~176 ~14 ~57 ~176 ~21 ~57 wool 15
fill ~176 ~14 ~58 ~176 ~21 ~58 wool 15
fill ~176 ~14 ~59 ~176 ~21 ~59 wool 15
fill ~176 ~14 ~60 ~176 ~21 ~60 wool 15
fill ~176 ~14 ~61 ~176 ~21 ~61 wool 15
fill ~176 ~14 ~62 ~176 ~21 ~62 wool 8
fill ~176 ~14 ~70 ~176 ~21 ~70 wool 8
fill ~176 ~14 ~71 ~176 ~16 ~71 wool 15
fill ~176 ~14 ~72 ~176 ~16 ~72 wool 15
fill ~10 ~15 ~70 ~12 ~15 ~70 wool 8
fill ~10 ~15 ~71 ~12 ~15 ~71 wool 8
fill ~10 ~15 ~72 ~12 ~15 ~72 wool 8
fill ~11 ~15 ~11 ~13 ~15 ~11 wool 8
fill ~11 ~15 ~12 ~13 ~15 ~12 wool 8
fill ~11 ~15 ~13 ~13 ~15 ~13 wool 8
fill ~12 ~15 ~74 ~37 ~15 ~74 wool 0
fill ~14 ~15 ~11 ~14 ~15 ~72 wool 0
fill ~15 ~15 ~9 ~38 ~15 ~9 wool 0
fill ~15 ~15 ~11 ~17 ~15 ~11 wool 14
fill ~15 ~15 ~26 ~15 ~23 ~26 wool 0
fill ~15 ~15 ~27 ~15 ~23 ~27 wool 0
fill ~15 ~15 ~28 ~15 ~23 ~28 wool 0
fill ~15 ~15 ~29 ~15 ~23 ~29 wool 0
fill ~15 ~15 ~30 ~15 ~23 ~30 wool 0
fill ~15 ~15 ~31 ~15 ~23 ~31 wool 0
fill ~15 ~15 ~32 ~15 ~23 ~32 wool 0
fill ~15 ~15 ~33 ~15 ~23 ~33 wool 0
fill ~15 ~15 ~34 ~15 ~21 ~34 wool 0
fill ~15 ~15 ~35 ~15 ~19 ~35 wool 0
fill ~15 ~15 ~36 ~15 ~17 ~36 wool 0
fill ~15 ~15 ~37 ~15 ~16 ~37 wool 0
fill ~15 ~15 ~38 ~15 ~15 ~39 wool 0
fill ~15 ~15 ~40 ~15 ~17 ~40 wool 14
fill ~15 ~15 ~41 ~15 ~17 ~41 wool 14
fill ~15 ~15 ~42 ~15 ~17 ~42 wool 14
fill ~15 ~15 ~43 ~15 ~17 ~43 wool 14
fill ~15 ~15 ~44 ~15 ~17 ~44 wool 14
fill ~15 ~15 ~45 ~15 ~15 ~55 wool 0
fill ~15 ~15 ~72 ~17 ~15 ~72 wool 14
fill ~17 ~15 ~36 ~17 ~23 ~36 wool 15
fill ~17 ~15 ~48 ~17 ~23 ~48 wool 15
fill ~18 ~15 ~10 ~34 ~15 ~10 wool 15
fill ~18 ~15 ~73 ~33 ~15 ~73 wool 15
fill ~27 ~15 ~18 ~60 ~15 ~18 wool 7
fill ~27 ~15 ~32 ~60 ~15 ~32 wool 7
fill ~34 ~15 ~17 ~62 ~15 ~17 wool 15
fill ~34 ~15 ~66 ~68 ~15 ~66 wool 15
fill ~37 ~15 ~75 ~64 ~15 ~75 wool 0
fill ~38 ~15 ~8 ~65 ~15 ~8 wool 0
fill ~41 ~15 ~72 ~41 ~15 ~73 wool 15
fill ~42 ~15 ~10 ~42 ~15 ~11 wool 15
fill ~42 ~15 ~71 ~42 ~16 ~71 wool 15
fill ~42 ~15 ~74 ~42 ~16 ~74 wool 15
fill ~43 ~15 ~9 ~43 ~16 ~9 wool 15
fill ~43 ~15 ~12 ~43 ~16 ~12 wool 15
fill ~44 ~15 ~70 ~44 ~16 ~70 wool 15
fill ~45 ~15 ~13 ~45 ~16 ~13 wool 15
fill ~45 ~15 ~69 ~56 ~15 ~69 wool 15
fill ~45 ~15 ~74 ~46 ~15 ~74 wool 8
fill ~46 ~15 ~9 ~47 ~15 ~9 wool 8
fill ~46 ~15 ~14 ~57 ~15 ~14 wool 15
fill ~49 ~15 ~73 ~52 ~15 ~73 wool 8
fill ~50 ~15 ~6 ~53 ~15 ~6 wool 15
fill ~50 ~15 ~10 ~53 ~15 ~10 wool 8
setblock ~50 ~15 ~72 wool 8
setblock ~51 ~15 ~11 wool 8
fill ~55 ~15 ~74 ~57 ~15 ~74 wool 8
fill ~56 ~15 ~9 ~58 ~15 ~9 wool 8
fill ~56 ~15 ~53 ~59 ~15 ~53 wool 15
fill ~57 ~15 ~63 ~59 ~15 ~63 wool 15
fill ~57 ~15 ~70 ~57 ~16 ~70 wool 15
fill ~58 ~15 ~13 ~58 ~16 ~13 wool 15
fill ~59 ~15 ~71 ~59 ~16 ~71 wool 15
fill ~59 ~15 ~74 ~59 ~16 ~74 wool 15
fill ~60 ~15 ~9 ~60 ~16 ~9 wool 15
fill ~60 ~15 ~12 ~60 ~16 ~12 wool 15
fill ~60 ~15 ~53 ~60 ~26 ~53 wool 7
fill ~60 ~15 ~57 ~62 ~15 ~57 wool 15
fill ~60 ~15 ~58 ~62 ~15 ~58 wool 15
fill ~60 ~15 ~63 ~60 ~26 ~63 wool 7
