setblock ~4 ~-3 ~35 torch 5
setblock ~4 ~-3 ~40 torch 5
setblock ~4 ~-3 ~68 torch 5
setblock ~4 ~-3 ~100 torch 5
setblock ~4 ~-3 ~130 torch 5
setblock ~5 ~-3 ~17 torch 5
setblock ~5 ~-3 ~44 torch 5
setblock ~5 ~-3 ~48 torch 5
setblock ~5 ~-3 ~57 torch 5
setblock ~5 ~-3 ~61 torch 5
setblock ~5 ~-3 ~78 torch 5
setblock ~5 ~-3 ~83 torch 5
setblock ~5 ~-3 ~89 torch 5
setblock ~5 ~-3 ~94 torch 5
fill ~6 ~-3 ~38 ~12 ~-3 ~38 wool 15
fill ~6 ~-3 ~39 ~6 ~-2 ~39 wool 15
fill ~6 ~-3 ~40 ~6 ~-2 ~40 wool 15
fill ~6 ~-3 ~41 ~6 ~-2 ~41 wool 15
fill ~6 ~-3 ~42 ~6 ~-2 ~42 wool 15
fill ~6 ~-3 ~43 ~12 ~-3 ~43 wool 15
fill ~6 ~-3 ~113 ~12 ~-3 ~113 wool 15
fill ~6 ~-3 ~114 ~6 ~-2 ~114 wool 15
fill ~6 ~-3 ~115 ~6 ~-2 ~115 wool 15
fill ~6 ~-3 ~116 ~6 ~-2 ~116 wool 15
fill ~6 ~-3 ~117 ~6 ~-2 ~117 wool 15
fill ~6 ~-3 ~118 ~12 ~-3 ~118 wool 15
setblock ~6 ~-3 ~137 torch 5
setblock ~7 ~-3 ~13 torch 5
setblock ~7 ~-3 ~33 torch 5
fill ~7 ~-3 ~39 ~11 ~-3 ~39 dirt 0
fill ~7 ~-3 ~40 ~11 ~-3 ~40 dirt 0
fill ~7 ~-3 ~41 ~11 ~-3 ~41 dirt 0
fill ~7 ~-3 ~42 ~11 ~-3 ~42 dirt 0
setblock ~7 ~-3 ~52 torch 5
setblock ~7 ~-3 ~63 torch 5
fill ~7 ~-3 ~114 ~11 ~-3 ~114 dirt 0
fill ~7 ~-3 ~115 ~11 ~-3 ~115 dirt 0
fill ~7 ~-3 ~116 ~11 ~-3 ~116 dirt 0
fill ~7 ~-3 ~117 ~11 ~-3 ~117 dirt 0
setblock ~7 ~-3 ~129 torch 5
setblock ~9 ~-3 ~18 torch 5
setblock ~9 ~-3 ~62 torch 5
setblock ~9 ~-3 ~66 torch 5
setblock ~9 ~-3 ~71 torch 5
setblock ~9 ~-3 ~75 torch 5
setblock ~9 ~-3 ~102 torch 5
setblock ~9 ~-3 ~105 tallgrass 1
setblock ~9 ~-3 ~110 torch 5
setblock ~10 ~-3 ~55 torch 5
setblock ~10 ~-3 ~58 torch 5
setblock ~10 ~-3 ~128 torch 5
setblock ~11 ~-3 ~28 torch 5
setblock ~11 ~-3 ~52 torch 5
setblock ~11 ~-3 ~91 torch 5
setblock ~12 ~-3 ~24 torch 5
setblock ~12 ~-3 ~31 torch 5
fill ~12 ~-3 ~39 ~12 ~-2 ~39 wool 15
fill ~12 ~-3 ~40 ~12 ~-2 ~40 wool 15
fill ~12 ~-3 ~41 ~12 ~-2 ~41 wool 15
fill ~12 ~-3 ~42 ~12 ~-2 ~42 wool 15
setblock ~12 ~-3 ~49 torch 5
setblock ~12 ~-3 ~64 torch 5
setblock ~12 ~-3 ~80 torch 5
setblock ~12 ~-3 ~84 torch 5
setblock ~12 ~-3 ~96 torch 5
setblock ~12 ~-3 ~102 torch 5
fill ~12 ~-3 ~114 ~12 ~-2 ~114 wool 15
fill ~12 ~-3 ~115 ~12 ~-2 ~115 wool 15
fill ~12 ~-3 ~116 ~12 ~-2 ~116 wool 15
fill ~12 ~-3 ~117 ~12 ~-2 ~117 wool 15
setblock ~12 ~-3 ~126 torch 5
setblock ~13 ~-3 ~15 torch 5
setblock ~13 ~-3 ~20 torch 5
setblock ~13 ~-3 ~58 torch 5
setblock ~13 ~-3 ~67 torch 5
setblock ~13 ~-3 ~74 torch 5
setblock ~13 ~-3 ~94 torch 5
setblock ~14 ~-3 ~46 torch 5
setblock ~14 ~-3 ~64 torch 5
setblock ~14 ~-3 ~106 torch 5
setblock ~14 ~-3 ~118 torch 5
setblock ~15 ~-3 ~36 torch 5
setblock ~15 ~-3 ~52 torch 5
setblock ~15 ~-3 ~56 torch 5
setblock ~15 ~-3 ~71 torch 5
setblock ~15 ~-3 ~76 torch 5
setblock ~15 ~-3 ~90 torch 5
setblock ~15 ~-3 ~100 torch 5
setblock ~15 ~-3 ~112 torch 5
setblock ~15 ~-3 ~125 torch 5
setblock ~16 ~-3 ~19 torch 5
setblock ~16 ~-3 ~32 torch 5
setblock ~16 ~-3 ~64 torch 5
setblock ~16 ~-3 ~118 torch 5
setblock ~16 ~-3 ~135 torch 5
setblock ~17 ~-3 ~12 torch 5
setblock ~17 ~-3 ~23 torch 5
setblock ~17 ~-3 ~29 torch 5
setblock ~17 ~-3 ~41 torch 5
setblock ~17 ~-3 ~69 torch 5
setblock ~17 ~-3 ~81 torch 5
setblock ~17 ~-3 ~97 torch 5
setblock ~18 ~-3 ~16 torch 5
setblock ~18 ~-3 ~55 torch 5
setblock ~18 ~-3 ~60 torch 5
setblock ~18 ~-3 ~64 torch 5
setblock ~18 ~-3 ~72 torch 5
setblock ~18 ~-3 ~103 torch 5
setblock ~18 ~-3 ~118 torch 5
setblock ~18 ~-3 ~123 torch 5
setblock ~19 ~-3 ~35 torch 5
setblock ~19 ~-3 ~47 torch 5
setblock ~19 ~-3 ~87 torch 5
setblock ~19 ~-3 ~93 torch 5
setblock ~19 ~-3 ~107 torch 5
setblock ~19 ~-3 ~111 torch 5
setblock ~19 ~-3 ~116 torch 5
setblock ~19 ~-3 ~130 torch 5
setblock ~20 ~-3 ~19 torch 5
setblock ~20 ~-3 ~41 torch 5
setblock ~20 ~-3 ~64 torch 5
setblock ~20 ~-3 ~71 torch 5
setblock ~20 ~-3 ~77 torch 5
setblock ~20 ~-3 ~118 torch 5
setblock ~20 ~-3 ~122 torch 5
setblock ~21 ~-3 ~13 torch 5
setblock ~21 ~-3 ~24 torch 5
setblock ~21 ~-3 ~29 torch 5
setblock ~21 ~-3 ~51 torch 5
setblock ~21 ~-3 ~58 torch 5
setblock ~21 ~-3 ~99 torch 5
setblock ~21 ~-3 ~133 torch 5
setblock ~22 ~-3 ~26 torch 5
setblock ~22 ~-3 ~37 torch 5
setblock ~22 ~-3 ~64 torch 5
setblock ~22 ~-3 ~67 torch 5
setblock ~22 ~-3 ~105 torch 5
setblock ~22 ~-3 ~112 torch 5
setblock ~22 ~-3 ~118 torch 5
setblock ~22 ~-3 ~130 torch 5
setblock ~22 ~-3 ~137 torch 5
setblock ~23 ~-3 ~20 torch 5
setblock ~23 ~-3 ~31 torch 5
setblock ~23 ~-3 ~124 torch 5
setblock ~24 ~-3 ~17 torch 5
setblock ~24 ~-3 ~41 torch 5
setblock ~24 ~-3 ~48 torch 5
setblock ~24 ~-3 ~64 torch 5
setblock ~24 ~-3 ~70 torch 5
setblock ~24 ~-3 ~77 torch 5
setblock ~24 ~-3 ~81 torch 5
setblock ~24 ~-3 ~89 torch 5
setblock ~24 ~-3 ~97 torch 5
setblock ~24 ~-3 ~118 torch 5
setblock ~25 ~-3 ~23 torch 5
setblock ~25 ~-3 ~60 torch 5
setblock ~25 ~-3 ~134 torch 5
setblock ~26 ~-3 ~14 torch 5
setblock ~26 ~-3 ~19 torch 5
setblock ~26 ~-3 ~29 torch 5
setblock ~26 ~-3 ~34 torch 5
setblock ~26 ~-3 ~38 torch 5
setblock ~26 ~-3 ~55 torch 5
setblock ~26 ~-3 ~64 torch 5
setblock ~26 ~-3 ~101 torch 5
setblock ~26 ~-3 ~118 torch 5
setblock ~26 ~-3 ~127 torch 5
setblock ~27 ~-3 ~46 torch 5
setblock ~27 ~-3 ~51 torch 5
setblock ~27 ~-3 ~71 torch 5
setblock ~27 ~-3 ~86 torch 5
setblock ~27 ~-3 ~95 torch 5
setblock ~27 ~-3 ~112 torch 5
setblock ~28 ~-3 ~28 torch 5
setblock ~28 ~-3 ~43 torch 5
setblock ~28 ~-3 ~58 torch 5
setblock ~28 ~-3 ~64 torch 5
setblock ~28 ~-3 ~106 torch 5
setblock ~28 ~-3 ~118 torch 5
fill ~28 ~-3 ~122 ~32 ~-3 ~122 tallgrass 1
fill ~28 ~-3 ~123 ~28 ~-3 ~122 tallgrass 1
setblock ~28 ~-3 ~131 torch 5
setblock ~28 ~-3 ~138 torch 5
setblock ~29 ~-3 ~14 torch 5
setblock ~29 ~-3 ~19 torch 5
setblock ~29 ~-3 ~76 torch 5
setblock ~29 ~-3 ~120 tallgrass 1
setblock ~29 ~-3 ~123 torch 5
setblock ~30 ~-3 ~24 torch 5
setblock ~30 ~-3 ~32 torch 5
setblock ~30 ~-3 ~36 torch 5
setblock ~30 ~-3 ~64 torch 5
setblock ~30 ~-3 ~68 torch 5
setblock ~30 ~-3 ~72 torch 5
setblock ~30 ~-3 ~118 torch 5
fill ~30 ~-3 ~121 ~32 ~-3 ~121 tallgrass 1
fill ~30 ~-3 ~123 ~31 ~-3 ~123 tallgrass 1
fill ~30 ~-3 ~124 ~32 ~-3 ~124 tallgrass 1
setblock ~30 ~-3 ~135 torch 5
setblock ~31 ~-3 ~46 torch 5
setblock ~31 ~-3 ~50 torch 5
setblock ~31 ~-3 ~61 torch 5
setblock ~31 ~-3 ~113 torch 5
setblock ~31 ~-3 ~128 torch 5
setblock ~32 ~-3 ~17 torch 5
setblock ~32 ~-3 ~22 torch 5
setblock ~32 ~-3 ~54 torch 5
setblock ~32 ~-3 ~118 torch 5
setblock ~33 ~-3 ~27 torch 5
setblock ~33 ~-3 ~34 torch 5
setblock ~33 ~-3 ~40 torch 5
setblock ~33 ~-3 ~66 torch 5
setblock ~33 ~-3 ~72 torch 5
setblock ~33 ~-3 ~120 tallgrass 1
setblock ~33 ~-3 ~123 tallgrass 1
setblock ~33 ~-3 ~132 torch 5
setblock ~33 ~-3 ~138 torch 5
setblock ~34 ~-3 ~19 torch 5
setblock ~34 ~-3 ~57 torch 5
setblock ~34 ~-3 ~61 torch 5
setblock ~34 ~-3 ~74 torch 5
setblock ~34 ~-3 ~79 torch 5
setblock ~34 ~-3 ~84 torch 5
setblock ~34 ~-3 ~89 torch 5
setblock ~34 ~-3 ~118 torch 5
setblock ~34 ~-3 ~125 torch 5
setblock ~35 ~-3 ~48 torch 5
setblock ~35 ~-3 ~70 torch 5
setblock ~35 ~-3 ~113 torch 5
setblock ~36 ~-3 ~13 torch 5
setblock ~36 ~-3 ~32 torch 5
setblock ~36 ~-3 ~41 grass 0
fill ~36 ~-3 ~42 ~36 ~-3 ~42 dirt 0
setblock ~36 ~-3 ~43 torch 3
setblock ~36 ~-3 ~52 torch 5
setblock ~36 ~-3 ~64 torch 5
setblock ~36 ~-3 ~118 torch 5
setblock ~37 ~-3 ~26 torch 5
setblock ~37 ~-3 ~67 torch 5
setblock ~37 ~-3 ~73 torch 5
setblock ~37 ~-3 ~87 torch 5
setblock ~37 ~-3 ~138 torch 5
setblock ~38 ~-3 ~18 torch 5
setblock ~38 ~-3 ~56 torch 5
setblock ~38 ~-3 ~60 torch 5
setblock ~38 ~-3 ~78 torch 5
setblock ~38 ~-3 ~118 torch 5
setblock ~38 ~-3 ~128 torch 5
setblock ~38 ~-3 ~133 torch 5
setblock ~39 ~-3 ~15 torch 5
setblock ~39 ~-3 ~22 torch 5
setblock ~39 ~-3 ~30 torch 5
setblock ~39 ~-3 ~35 torch 5
setblock ~39 ~-3 ~47 torch 5
setblock ~39 ~-3 ~65 torch 5
setblock ~39 ~-3 ~71 torch 5
setblock ~40 ~-3 ~88 torch 5
setblock ~41 ~-3 ~11 torch 5
setblock ~41 ~-3 ~18 torch 5
setblock ~41 ~-3 ~79 torch 5
setblock ~41 ~-3 ~82 torch 5
setblock ~41 ~-3 ~107 torch 5
setblock ~42 ~-3 ~54 torch 5
setblock ~42 ~-3 ~57 torch 5
setblock ~42 ~-3 ~61 torch 5
setblock ~42 ~-3 ~67 torch 5
setblock ~42 ~-3 ~87 torch 5
setblock ~42 ~-3 ~123 torch 5
setblock ~42 ~-3 ~137 torch 5
setblock ~43 ~-3 ~26 torch 5
setblock ~43 ~-3 ~39 torch 5
setblock ~43 ~-3 ~43 torch 5
setblock ~43 ~-3 ~76 torch 5
setblock ~43 ~-3 ~109 torch 5
setblock ~43 ~-3 ~116 torch 5
setblock ~44 ~-3 ~17 torch 5
setblock ~44 ~-3 ~21 torch 5
setblock ~44 ~-3 ~64 torch 5
setblock ~44 ~-3 ~71 torch 5
setblock ~44 ~-3 ~121 torch 5
setblock ~45 ~-3 ~30 torch 5
setblock ~45 ~-3 ~49 torch 5
setblock ~45 ~-3 ~57 torch 5
setblock ~45 ~-3 ~82 torch 5
setblock ~45 ~-3 ~127 torch 5
setblock ~45 ~-3 ~132 torch 5
setblock ~46 ~-3 ~14 torch 5
setblock ~46 ~-3 ~22 torch 5
setblock ~46 ~-3 ~38 torch 5
setblock ~46 ~-3 ~44 torch 5
setblock ~46 ~-3 ~53 torch 5
setblock ~46 ~-3 ~60 torch 5
setblock ~46 ~-3 ~64 torch 5
setblock ~46 ~-3 ~68 torch 5
setblock ~46 ~-3 ~75 torch 5
setblock ~46 ~-3 ~85 torch 5
fill ~46 ~-3 ~121 ~46 ~0 ~121 dirt 0
fill ~46 ~-3 ~122 ~46 ~0 ~122 dirt 0
setblock ~46 ~-3 ~137 torch 5
setblock ~47 ~-3 ~19 torch 5
setblock ~47 ~-3 ~26 torch 5
setblock ~47 ~-3 ~34 torch 5
setblock ~47 ~-3 ~111 torch 5
fill ~47 ~-3 ~122 ~47 ~1 ~122 ladder 5
setblock ~48 ~-3 ~64 torch 5
setblock ~48 ~-3 ~72 torch 5
setblock ~48 ~-3 ~78 torch 5
setblock ~48 ~-3 ~89 torch 5
setblock ~48 ~-3 ~105 torch 5
setblock ~48 ~-3 ~113 torch 5
setblock ~48 ~-3 ~118 torch 5
setblock ~48 ~-3 ~121 torch 5
fill ~49 ~-3 ~38 ~55 ~-3 ~38 wool 15
fill ~49 ~-3 ~39 ~49 ~-2 ~39 wool 15
fill ~49 ~-3 ~40 ~49 ~-2 ~40 wool 15
fill ~49 ~-3 ~41 ~49 ~-2 ~41 wool 15
fill ~49 ~-3 ~42 ~49 ~-2 ~42 wool 15
fill ~49 ~-3 ~43 ~55 ~-3 ~43 wool 15
setblock ~49 ~-3 ~61 torch 5
setblock ~49 ~-3 ~94 torch 5
fill ~49 ~-3 ~113 ~55 ~-3 ~113 wool 15
fill ~49 ~-3 ~114 ~49 ~-2 ~114 wool 15
fill ~49 ~-3 ~115 ~49 ~-2 ~115 wool 15
fill ~49 ~-3 ~116 ~49 ~-2 ~116 wool 15
fill ~49 ~-3 ~117 ~49 ~-2 ~117 wool 15
fill ~49 ~-3 ~118 ~55 ~-3 ~118 wool 15
setblock ~49 ~-3 ~130 torch 5
setblock ~50 ~-3 ~14 torch 5
setblock ~50 ~-3 ~21 torch 5
setblock ~50 ~-3 ~30 torch 5
setblock ~50 ~-3 ~35 torch 5
fill ~50 ~-3 ~39 ~54 ~-3 ~39 dirt 0
fill ~50 ~-3 ~40 ~54 ~-3 ~40 dirt 0
fill ~50 ~-3 ~41 ~54 ~-3 ~41 dirt 0
fill ~50 ~-3 ~42 ~54 ~-3 ~42 dirt 0
setblock ~50 ~-3 ~64 torch 5
fill ~50 ~-3 ~114 ~54 ~-3 ~114 dirt 0
fill ~50 ~-3 ~115 ~54 ~-3 ~115 dirt 0
fill ~50 ~-3 ~116 ~54 ~-3 ~116 dirt 0
fill ~50 ~-3 ~117 ~54 ~-3 ~117 dirt 0
setblock ~50 ~-3 ~137 torch 5
setblock ~51 ~-3 ~121 torch 5
setblock ~51 ~-3 ~124 torch 5
setblock ~51 ~-3 ~133 torch 5
setblock ~52 ~-3 ~25 torch 5
setblock ~52 ~-3 ~52 torch 5
setblock ~52 ~-3 ~54 torch 5
setblock ~52 ~-3 ~56 torch 5
setblock ~52 ~-3 ~58 torch 5
setblock ~52 ~-3 ~62 torch 5
setblock ~52 ~-3 ~64 torch 5
setblock ~52 ~-3 ~66 torch 5
setblock ~52 ~-3 ~68 torch 5
setblock ~52 ~-3 ~70 torch 5
setblock ~52 ~-3 ~72 torch 5
setblock ~52 ~-3 ~74 torch 5
setblock ~52 ~-3 ~76 torch 5
setblock ~52 ~-3 ~78 torch 5
setblock ~52 ~-3 ~80 torch 5
setblock ~52 ~-3 ~82 torch 5
setblock ~52 ~-3 ~84 torch 5
setblock ~52 ~-3 ~86 torch 5
setblock ~52 ~-3 ~88 torch 5
setblock ~52 ~-3 ~90 torch 5
setblock ~52 ~-3 ~100 torch 5
setblock ~52 ~-3 ~102 torch 5
setblock ~52 ~-3 ~104 torch 5
setblock ~52 ~-3 ~108 torch 5
setblock ~52 ~-3 ~110 torch 5
setblock ~53 ~-3 ~21 torch 5
setblock ~53 ~-3 ~35 torch 5
setblock ~53 ~-3 ~137 torch 5
setblock ~54 ~-3 ~29 torch 5
setblock ~54 ~-3 ~64 torch 5
setblock ~54 ~-3 ~95 torch 5
setblock ~54 ~-3 ~130 torch 5
fill ~55 ~-3 ~39 ~55 ~-2 ~39 wool 15
fill ~55 ~-3 ~40 ~55 ~-2 ~40 wool 15
fill ~55 ~-3 ~41 ~55 ~-2 ~41 wool 15
fill ~55 ~-3 ~42 ~55 ~-2 ~42 wool 15
setblock ~55 ~-3 ~59 torch 5
fill ~55 ~-3 ~114 ~55 ~-2 ~114 wool 15
fill ~55 ~-3 ~115 ~55 ~-2 ~115 wool 15
fill ~55 ~-3 ~116 ~55 ~-2 ~116 wool 15
fill ~55 ~-3 ~117 ~55 ~-2 ~117 wool 15
setblock ~55 ~-3 ~120 torch 5
setblock ~56 ~-3 ~18 torch 5
setblock ~56 ~-3 ~54 torch 5
setblock ~56 ~-3 ~64 torch 5
setblock ~56 ~-3 ~81 torch 5
setblock ~56 ~-3 ~123 torch 5
setblock ~57 ~-3 ~12 torch 5
setblock ~57 ~-3 ~25 torch 5
setblock ~57 ~-3 ~49 torch 5
setblock ~57 ~-3 ~73 torch 5
setblock ~57 ~-3 ~86 torch 5
setblock ~57 ~-3 ~138 torch 5
fill ~6 ~-2 ~36 ~12 ~-2 ~36 wool 15
fill ~6 ~-2 ~37 ~12 ~-2 ~37 wool 15
fill ~6 ~-2 ~38 ~6 ~-1 ~38 wool 15
fill ~6 ~-2 ~43 ~6 ~-1 ~43 wool 15
fill ~6 ~-2 ~44 ~12 ~-2 ~44 wool 15
fill ~6 ~-2 ~45 ~12 ~-2 ~45 wool 15
fill ~6 ~-2 ~111 ~12 ~-2 ~111 wool 15
fill ~6 ~-2 ~112 ~12 ~-2 ~112 wool 15
fill ~6 ~-2 ~113 ~6 ~-1 ~113 wool 15
fill ~6 ~-2 ~118 ~6 ~-1 ~118 wool 15
fill ~6 ~-2 ~119 ~12 ~-2 ~119 wool 15
fill ~6 ~-2 ~120 ~12 ~-2 ~120 wool 15
fill ~7 ~-2 ~38 ~11 ~-2 ~38 dirt 0
fill ~7 ~-2 ~39 ~11 ~-2 ~39 dirt 0
fill ~7 ~-2 ~40 ~11 ~-2 ~40 dirt 0
fill ~7 ~-2 ~41 ~11 ~-2 ~41 dirt 0
fill ~7 ~-2 ~42 ~11 ~-2 ~42 dirt 0
fill ~7 ~-2 ~43 ~11 ~-2 ~43 dirt 0
fill ~7 ~-2 ~113 ~11 ~-2 ~113 dirt 0
fill ~7 ~-2 ~114 ~11 ~-2 ~114 dirt 0
fill ~7 ~-2 ~115 ~11 ~-2 ~115 dirt 0
fill ~7 ~-2 ~116 ~11 ~-2 ~116 dirt 0
fill ~7 ~-2 ~117 ~11 ~-2 ~117 dirt 0
fill ~7 ~-2 ~118 ~11 ~-2 ~118 dirt 0
fill ~12 ~-2 ~38 ~12 ~-1 ~38 wool 15
fill ~12 ~-2 ~43 ~12 ~-1 ~43 wool 15
fill ~12 ~-2 ~113 ~12 ~-1 ~113 wool 15
fill ~12 ~-2 ~118 ~12 ~-1 ~118 wool 15
setblock ~36 ~-2 ~42 grass 0
setblock ~36 ~-2 ~43 dirt 0
setblock ~36 ~-2 ~44 torch 3
fill ~49 ~-2 ~36 ~55 ~-2 ~36 wool 15
fill ~49 ~-2 ~37 ~55 ~-2 ~37 wool 15
fill ~49 ~-2 ~38 ~49 ~-1 ~38 wool 15
fill ~49 ~-2 ~43 ~49 ~-1 ~43 wool 15
fill ~49 ~-2 ~44 ~55 ~-2 ~44 wool 15
fill ~49 ~-2 ~45 ~55 ~-2 ~45 wool 15
fill ~49 ~-2 ~111 ~55 ~-2 ~111 wool 15
fill ~49 ~-2 ~112 ~55 ~-2 ~112 wool 15
fill ~49 ~-2 ~113 ~49 ~-1 ~113 wool 15
fill ~49 ~-2 ~118 ~49 ~-1 ~118 wool 15
fill ~49 ~-2 ~119 ~55 ~-2 ~119 wool 15
fill ~49 ~-2 ~120 ~55 ~-2 ~120 wool 15
fill ~50 ~-2 ~38 ~54 ~-2 ~38 dirt 0
fill ~50 ~-2 ~39 ~54 ~-2 ~39 dirt 0
fill ~50 ~-2 ~40 ~54 ~-2 ~40 dirt 0
fill ~50 ~-2 ~41 ~54 ~-2 ~41 dirt 0
fill ~50 ~-2 ~42 ~54 ~-2 ~42 dirt 0
fill ~50 ~-2 ~43 ~54 ~-2 ~43 dirt 0
fill ~50 ~-2 ~113 ~54 ~-2 ~113 dirt 0
fill ~50 ~-2 ~114 ~54 ~-2 ~114 dirt 0
fill ~50 ~-2 ~115 ~54 ~-2 ~115 dirt 0
fill ~50 ~-2 ~116 ~54 ~-2 ~116 dirt 0
fill ~50 ~-2 ~117 ~54 ~-2 ~117 dirt 0
fill ~50 ~-2 ~118 ~54 ~-2 ~118 dirt 0
fill ~55 ~-2 ~38 ~55 ~-1 ~38 wool 15
fill ~55 ~-2 ~43 ~55 ~-1 ~43 wool 15
fill ~55 ~-2 ~113 ~55 ~-1 ~113 wool 15
fill ~55 ~-2 ~118 ~55 ~-1 ~118 wool 15
fill ~6 ~-1 ~35 ~12 ~-1 ~35 wool 15
fill ~6 ~-1 ~36 ~6 ~0 ~36 wool 15
fill ~6 ~-1 ~37 ~6 ~-2 ~37 wool 15
fill ~6 ~-1 ~44 ~6 ~-2 ~44 wool 15
fill ~6 ~-1 ~45 ~6 ~0 ~45 wool 15
fill ~6 ~-1 ~46 ~12 ~-1 ~46 wool 15
fill ~6 ~-1 ~110 ~12 ~-1 ~110 wool 15
fill ~6 ~-1 ~111 ~6 ~0 ~111 wool 15
fill ~6 ~-1 ~112 ~6 ~-2 ~112 wool 15
fill ~6 ~-1 ~119 ~6 ~-2 ~119 wool 15
fill ~6 ~-1 ~120 ~6 ~0 ~120 wool 15
fill ~6 ~-1 ~121 ~12 ~-1 ~121 wool 15
fill ~7 ~-1 ~36 ~11 ~-1 ~36 dirt 0
fill ~7 ~-1 ~37 ~11 ~-1 ~37 dirt 0
fill ~7 ~-1 ~38 ~11 ~-1 ~38 dirt 0
fill ~7 ~-1 ~39 ~11 ~-1 ~39 wool 8
fill ~7 ~-1 ~40 ~11 ~-1 ~40 wool 8
fill ~7 ~-1 ~41 ~11 ~-1 ~41 wool 8
fill ~7 ~-1 ~42 ~11 ~-1 ~42 wool 8
fill ~7 ~-1 ~43 ~11 ~-1 ~43 dirt 0
fill ~7 ~-1 ~44 ~11 ~-1 ~44 dirt 0
fill ~7 ~-1 ~45 ~11 ~-1 ~45 dirt 0
fill ~7 ~-1 ~111 ~11 ~-1 ~111 dirt 0
fill ~7 ~-1 ~112 ~11 ~-1 ~112 dirt 0
fill ~7 ~-1 ~113 ~11 ~-1 ~113 dirt 0
fill ~7 ~-1 ~114 ~11 ~-1 ~114 wool 8
fill ~7 ~-1 ~115 ~11 ~-1 ~115 wool 8
fill ~7 ~-1 ~116 ~11 ~-1 ~116 wool 8
fill ~7 ~-1 ~117 ~11 ~-1 ~117 wool 8
fill ~7 ~-1 ~118 ~11 ~-1 ~118 dirt 0
fill ~7 ~-1 ~119 ~11 ~-1 ~119 dirt 0
fill ~7 ~-1 ~120 ~11 ~-1 ~120 dirt 0
fill ~12 ~-1 ~36 ~12 ~0 ~36 wool 15
fill ~12 ~-1 ~37 ~12 ~-1 ~35 wool 15
fill ~12 ~-1 ~44 ~12 ~-1 ~46 wool 15
fill ~12 ~-1 ~111 ~12 ~0 ~111 wool 15
fill ~12 ~-1 ~112 ~12 ~-1 ~110 wool 15
fill ~12 ~-1 ~119 ~12 ~-1 ~121 wool 15
setblock ~36 ~-1 ~43 grass 0
setblock ~36 ~-1 ~44 dirt 0
setblock ~36 ~-1 ~45 torch 3
fill ~49 ~-1 ~35 ~55 ~-1 ~35 wool 15
fill ~49 ~-1 ~36 ~49 ~0 ~36 wool 15
fill ~49 ~-1 ~37 ~49 ~-2 ~37 wool 15
fill ~49 ~-1 ~44 ~49 ~-2 ~44 wool 15
fill ~49 ~-1 ~45 ~49 ~0 ~45 wool 15
fill ~49 ~-1 ~46 ~55 ~-1 ~46 wool 15
fill ~49 ~-1 ~110 ~55 ~-1 ~110 wool 15
fill ~49 ~-1 ~111 ~49 ~0 ~111 wool 15
fill ~49 ~-1 ~112 ~49 ~-2 ~112 wool 15
fill ~49 ~-1 ~119 ~49 ~-2 ~119 wool 15
fill ~49 ~-1 ~120 ~49 ~0 ~120 wool 15
fill ~49 ~-1 ~121 ~55 ~-1 ~121 wool 15
fill ~50 ~-1 ~36 ~54 ~-1 ~36 dirt 0
fill ~50 ~-1 ~37 ~54 ~-1 ~37 dirt 0
fill ~50 ~-1 ~38 ~54 ~-1 ~38 dirt 0
fill ~50 ~-1 ~39 ~54 ~-1 ~39 wool 8
fill ~50 ~-1 ~40 ~54 ~-1 ~40 wool 8
fill ~50 ~-1 ~41 ~54 ~-1 ~41 wool 8
fill ~50 ~-1 ~42 ~54 ~-1 ~42 wool 8
fill ~50 ~-1 ~43 ~54 ~-1 ~43 dirt 0
fill ~50 ~-1 ~44 ~54 ~-1 ~44 dirt 0
fill ~50 ~-1 ~45 ~54 ~-1 ~45 dirt 0
fill ~50 ~-1 ~111 ~54 ~-1 ~111 grass 0
fill ~50 ~-1 ~112 ~54 ~-1 ~112 dirt 0
fill ~50 ~-1 ~113 ~54 ~-1 ~113 dirt 0
fill ~50 ~-1 ~114 ~54 ~-1 ~114 wool 8
fill ~50 ~-1 ~115 ~52 ~-1 ~115 wool 8
fill ~50 ~-1 ~116 ~52 ~-1 ~116 wool 8
fill ~50 ~-1 ~117 ~54 ~-1 ~117 wool 8
fill ~50 ~-1 ~118 ~54 ~-1 ~118 dirt 0
fill ~50 ~-1 ~119 ~54 ~-1 ~119 dirt 0
fill ~50 ~-1 ~120 ~54 ~-1 ~120 grass 0
fill ~53 ~-1 ~115 ~53 ~-1 ~116 dirt 0
fill ~54 ~-1 ~115 ~54 ~-1 ~117 wool 8
fill ~55 ~-1 ~36 ~55 ~0 ~36 wool 15
fill ~55 ~-1 ~37 ~55 ~-1 ~35 wool 15
fill ~55 ~-1 ~44 ~55 ~-1 ~46 wool 15
fill ~55 ~-1 ~111 ~55 ~0 ~111 wool 15
fill ~55 ~-1 ~112 ~55 ~-1 ~110 wool 15
fill ~55 ~-1 ~119 ~55 ~-1 ~121 wool 15
fill ~6 ~0 ~34 ~12 ~0 ~34 wool 15
fill ~6 ~0 ~35 ~6 ~1 ~35 wool 15
fill ~6 ~0 ~46 ~6 ~1 ~46 wool 15
fill ~6 ~0 ~47 ~12 ~0 ~47 wool 15
fill ~6 ~0 ~51 ~14 ~0 ~51 wool 15
fill ~6 ~0 ~52 ~6 ~0 ~105 wool 15
fill ~6 ~0 ~109 ~12 ~0 ~109 wool 15
fill ~6 ~0 ~110 ~6 ~1 ~110 wool 15
fill ~6 ~0 ~121 ~6 ~1 ~121 wool 15
fill ~6 ~0 ~122 ~12 ~0 ~122 wool 15
fill ~7 ~0 ~35 ~11 ~0 ~35 dirt 0
fill ~7 ~0 ~36 ~11 ~0 ~36 dirt 0
fill ~7 ~0 ~37 ~11 ~0 ~37 wool 8
fill ~7 ~0 ~38 ~11 ~0 ~38 wool 8
fill ~7 ~0 ~43 ~11 ~0 ~43 wool 8
fill ~7 ~0 ~44 ~11 ~0 ~44 wool 8
fill ~7 ~0 ~45 ~11 ~0 ~45 dirt 0
fill ~7 ~0 ~46 ~11 ~0 ~46 dirt 0
fill ~7 ~0 ~52 ~13 ~0 ~52 cobblestone 0
fill ~7 ~0 ~53 ~13 ~0 ~53 cobblestone 0
fill ~7 ~0 ~54 ~13 ~0 ~54 cobblestone 0
fill ~7 ~0 ~55 ~13 ~0 ~55 cobblestone 0
fill ~7 ~0 ~56 ~13 ~0 ~56 cobblestone 0
fill ~7 ~0 ~57 ~13 ~0 ~57 cobblestone 0
fill ~7 ~0 ~58 ~13 ~0 ~58 cobblestone 0
fill ~7 ~0 ~59 ~13 ~0 ~59 cobblestone 0
fill ~7 ~0 ~60 ~13 ~0 ~60 cobblestone 0
fill ~7 ~0 ~61 ~54 ~0 ~61 cobblestone 0
fill ~7 ~0 ~62 ~54 ~0 ~62 cobblestone 0
fill ~7 ~0 ~63 ~54 ~0 ~63 cobblestone 0
fill ~7 ~0 ~64 ~54 ~0 ~64 cobblestone 0
fill ~7 ~0 ~65 ~54 ~0 ~65 cobblestone 0
fill ~7 ~0 ~66 ~54 ~0 ~66 cobblestone 0
fill ~7 ~0 ~67 ~54 ~0 ~67 cobblestone 0
fill ~7 ~0 ~68 ~54 ~0 ~68 cobblestone 0
fill ~7 ~0 ~69 ~54 ~0 ~69 cobblestone 0
fill ~7 ~0 ~70 ~54 ~0 ~70 cobblestone 0
fill ~7 ~0 ~71 ~54 ~0 ~71 cobblestone 0
fill ~7 ~0 ~72 ~54 ~0 ~72 cobblestone 0
fill ~7 ~0 ~73 ~54 ~0 ~73 cobblestone 0
fill ~7 ~0 ~74 ~54 ~0 ~74 cobblestone 0
fill ~7 ~0 ~75 ~54 ~0 ~75 cobblestone 0
fill ~7 ~0 ~76 ~54 ~0 ~76 cobblestone 0
fill ~7 ~0 ~77 ~54 ~0 ~77 cobblestone 0
fill ~7 ~0 ~78 ~54 ~0 ~78 cobblestone 0
fill ~7 ~0 ~79 ~54 ~0 ~79 cobblestone 0
fill ~7 ~0 ~80 ~54 ~0 ~80 cobblestone 0
fill ~7 ~0 ~81 ~54 ~0 ~81 cobblestone 0
fill ~7 ~0 ~82 ~54 ~0 ~82 cobblestone 0
fill ~7 ~0 ~83 ~54 ~0 ~83 cobblestone 0
fill ~7 ~0 ~84 ~54 ~0 ~84 cobblestone 0
fill ~7 ~0 ~85 ~54 ~0 ~85 cobblestone 0
fill ~7 ~0 ~86 ~54 ~0 ~86 cobblestone 0
fill ~7 ~0 ~87 ~54 ~0 ~87 cobblestone 0
fill ~7 ~0 ~88 ~54 ~0 ~88 cobblestone 0
fill ~7 ~0 ~89 ~54 ~0 ~89 cobblestone 0
fill ~7 ~0 ~90 ~54 ~0 ~90 cobblestone 0
fill ~7 ~0 ~91 ~54 ~0 ~91 cobblestone 0
fill ~7 ~0 ~92 ~54 ~0 ~92 cobblestone 0
fill ~7 ~0 ~93 ~54 ~0 ~93 cobblestone 0
fill ~7 ~0 ~94 ~54 ~0 ~94 cobblestone 0
fill ~7 ~0 ~95 ~54 ~0 ~95 cobblestone 0
fill ~7 ~0 ~96 ~54 ~0 ~96 cobblestone 0
fill ~7 ~0 ~97 ~54 ~0 ~97 cobblestone 0
fill ~7 ~0 ~98 ~54 ~0 ~98 cobblestone 0
fill ~7 ~0 ~99 ~54 ~0 ~99 cobblestone 0
fill ~7 ~0 ~100 ~54 ~0 ~100 cobblestone 0
fill ~7 ~0 ~101 ~54 ~0 ~101 cobblestone 0
fill ~7 ~0 ~102 ~54 ~0 ~102 cobblestone 0
fill ~7 ~0 ~103 ~54 ~0 ~103 cobblestone 0
fill ~7 ~0 ~104 ~44 ~0 ~104 cobblestone 0
fill ~7 ~0 ~105 ~16 ~0 ~105 wool 15
fill ~7 ~0 ~110 ~11 ~0 ~110 dirt 0
fill ~7 ~0 ~111 ~7 ~-1 ~111 dirt 0
fill ~7 ~0 ~112 ~11 ~0 ~112 wool 8
fill ~7 ~0 ~113 ~11 ~0 ~113 wool 8
fill ~7 ~0 ~118 ~11 ~0 ~118 wool 8
fill ~7 ~0 ~119 ~11 ~0 ~119 wool 8
fill ~7 ~0 ~120 ~7 ~-1 ~120 dirt 0
fill ~7 ~0 ~121 ~11 ~0 ~121 dirt 0
fill ~8 ~0 ~40 ~8 ~0 ~41 wool 8
fill ~8 ~0 ~111 ~10 ~0 ~111 wool 8
fill ~8 ~0 ~120 ~10 ~0 ~120 wool 8
setblock ~10 ~0 ~39 torch 5
setblock ~11 ~0 ~111 dirt 0
setblock ~11 ~0 ~120 dirt 0
fill ~12 ~0 ~35 ~12 ~1 ~35 wool 15
fill ~12 ~0 ~45 ~12 ~0 ~47 wool 15
fill ~12 ~0 ~110 ~12 ~1 ~110 wool 15
fill ~12 ~0 ~120 ~12 ~0 ~122 wool 15
fill ~15 ~0 ~34 ~15 ~12 ~34 wool 15
fill ~15 ~0 ~35 ~15 ~5 ~35 wool 15
fill ~15 ~0 ~36 ~15 ~5 ~36 wool 15
fill ~15 ~0 ~37 ~15 ~5 ~37 wool 15
fill ~15 ~0 ~38 ~15 ~5 ~38 wool 15
fill ~15 ~0 ~39 ~15 ~5 ~39 wool 15
fill ~15 ~0 ~40 ~15 ~4 ~40 wool 15
fill ~15 ~0 ~41 ~15 ~4 ~41 wool 15
fill ~15 ~0 ~42 ~15 ~5 ~42 wool 15
fill ~15 ~0 ~43 ~15 ~5 ~43 wool 15
fill ~15 ~0 ~44 ~15 ~5 ~44 wool 15
fill ~15 ~0 ~45 ~15 ~13 ~45 wool 15
fill ~15 ~0 ~46 ~15 ~17 ~46 wool 15
fill ~15 ~0 ~47 ~15 ~13 ~47 wool 15
fill ~15 ~0 ~48 ~15 ~10 ~48 wool 15
fill ~15 ~0 ~49 ~15 ~10 ~49 wool 15
fill ~15 ~0 ~50 ~15 ~6 ~50 wool 15
fill ~19 ~0 ~53 ~40 ~0 ~53 cobblestone 0
fill ~19 ~0 ~54 ~40 ~0 ~54 cobblestone 0
fill ~19 ~0 ~55 ~40 ~0 ~55 cobblestone 0
fill ~19 ~0 ~56 ~40 ~0 ~56 cobblestone 0
fill ~19 ~0 ~57 ~40 ~0 ~57 cobblestone 0
fill ~19 ~0 ~58 ~40 ~0 ~58 cobblestone 0
fill ~19 ~0 ~59 ~40 ~0 ~59 cobblestone 0
fill ~19 ~0 ~60 ~40 ~0 ~60 cobblestone 0
setblock ~36 ~0 ~44 grass 0
fill ~45 ~0 ~104 ~55 ~0 ~104 wool 15
fill ~46 ~0 ~34 ~46 ~12 ~34 wool 15
fill ~46 ~0 ~35 ~46 ~5 ~35 wool 15
fill ~46 ~0 ~36 ~46 ~5 ~36 wool 15
fill ~46 ~0 ~37 ~46 ~5 ~37 wool 15
fill ~46 ~0 ~38 ~46 ~5 ~38 wool 15
fill ~46 ~0 ~39 ~46 ~5 ~39 wool 15
fill ~46 ~0 ~40 ~46 ~4 ~40 wool 15
fill ~46 ~0 ~41 ~46 ~4 ~41 wool 15
fill ~46 ~0 ~42 ~46 ~5 ~42 wool 15
fill ~46 ~0 ~43 ~46 ~5 ~43 wool 15
fill ~46 ~0 ~44 ~46 ~5 ~44 wool 15
fill ~46 ~0 ~45 ~46 ~15 ~45 wool 15
fill ~46 ~0 ~46 ~46 ~17 ~46 wool 15
fill ~46 ~0 ~47 ~46 ~13 ~47 wool 15
fill ~46 ~0 ~48 ~46 ~10 ~48 wool 15
fill ~46 ~0 ~49 ~46 ~10 ~49 wool 15
fill ~46 ~0 ~50 ~46 ~9 ~50 wool 15
fill ~46 ~0 ~51 ~55 ~0 ~51 wool 15
fill ~46 ~0 ~52 ~54 ~0 ~52 cobblestone 0
fill ~46 ~0 ~53 ~54 ~0 ~53 cobblestone 0
fill ~46 ~0 ~54 ~54 ~0 ~54 cobblestone 0
fill ~46 ~0 ~55 ~54 ~0 ~55 cobblestone 0
fill ~46 ~0 ~56 ~54 ~0 ~56 cobblestone 0
fill ~46 ~0 ~57 ~54 ~0 ~57 cobblestone 0
fill ~46 ~0 ~58 ~54 ~0 ~58 cobblestone 0
fill ~46 ~0 ~59 ~54 ~0 ~59 cobblestone 0
fill ~46 ~0 ~60 ~54 ~0 ~60 cobblestone 0
setblock ~47 ~0 ~121 torch 1
fill ~49 ~0 ~34 ~55 ~0 ~34 wool 15
fill ~49 ~0 ~35 ~49 ~1 ~35 wool 15
fill ~49 ~0 ~46 ~49 ~1 ~46 wool 15
fill ~49 ~0 ~47 ~55 ~0 ~47 wool 15
fill ~49 ~0 ~109 ~55 ~0 ~109 wool 15
fill ~49 ~0 ~110 ~49 ~1 ~110 wool 15
fill ~49 ~0 ~121 ~49 ~1 ~121 wool 15
fill ~49 ~0 ~122 ~55 ~0 ~122 wool 15
fill ~50 ~0 ~35 ~54 ~0 ~35 dirt 0
fill ~50 ~0 ~36 ~54 ~0 ~36 dirt 0
fill ~50 ~0 ~37 ~54 ~0 ~37 wool 8
fill ~50 ~0 ~38 ~54 ~0 ~38 wool 8
fill ~50 ~0 ~43 ~54 ~0 ~43 wool 8
fill ~50 ~0 ~44 ~54 ~0 ~44 wool 8
fill ~50 ~0 ~45 ~54 ~0 ~45 dirt 0
fill ~50 ~0 ~46 ~54 ~0 ~46 dirt 0
fill ~50 ~0 ~112 ~54 ~0 ~112 wool 8
fill ~50 ~0 ~113 ~54 ~0 ~113 wool 8
fill ~50 ~0 ~118 ~54 ~0 ~118 wool 8
fill ~50 ~0 ~119 ~54 ~0 ~119 wool 8
fill ~53 ~0 ~115 ~53 ~0 ~116 wool 8
setblock ~54 ~0 ~120 torch 5
fill ~55 ~0 ~35 ~55 ~1 ~35 wool 15
fill ~55 ~0 ~45 ~55 ~0 ~47 wool 15
fill ~55 ~0 ~52 ~55 ~0 ~105 wool 15
fill ~55 ~0 ~110 ~55 ~1 ~110 wool 15
fill ~55 ~0 ~120 ~55 ~0 ~122 wool 15
fill ~6 ~1 ~33 ~12 ~1 ~33 wool 15
fill ~6 ~1 ~34 ~6 ~3 ~34 wool 15
fill ~6 ~1 ~47 ~6 ~3 ~47 wool 15
fill ~6 ~1 ~48 ~12 ~1 ~48 wool 15
fill ~6 ~1 ~51 ~6 ~1 ~105 wool 11
fill ~6 ~1 ~108 ~12 ~1 ~108 wool 15
fill ~6 ~1 ~109 ~6 ~3 ~109 wool 15
fill ~6 ~1 ~122 ~6 ~3 ~122 wool 15
fill ~6 ~1 ~123 ~12 ~1 ~123 wool 15
fill ~7 ~1 ~34 ~11 ~1 ~34 dirt 0
fill ~7 ~1 ~35 ~11 ~1 ~35 dirt 0
fill ~7 ~1 ~36 ~11 ~1 ~36 wool 8
fill ~7 ~1 ~45 ~11 ~1 ~45 wool 8
fill ~7 ~1 ~46 ~11 ~1 ~46 dirt 0
fill ~7 ~1 ~47 ~11 ~1 ~47 dirt 0
fill ~7 ~1 ~51 ~14 ~1 ~51 wool 15
fill ~7 ~1 ~97 ~14 ~1 ~97 wool 15
fill ~7 ~1 ~105 ~16 ~1 ~105 wool 15
fill ~7 ~1 ~109 ~8 ~1 ~109 dirt 0
fill ~7 ~1 ~110 ~7 ~0 ~110 dirt 0
fill ~7 ~1 ~111 ~11 ~1 ~111 wool 8
fill ~7 ~1 ~120 ~11 ~1 ~120 wool 8
fill ~7 ~1 ~121 ~7 ~0 ~121 dirt 0
fill ~7 ~1 ~122 ~7 ~3 ~122 dirt 0
fill ~7 ~1 ~127 ~15 ~1 ~127 wool 15
setblock ~8 ~1 ~58 torch 5
fill ~8 ~1 ~65 ~15 ~1 ~65 wool 15
fill ~8 ~1 ~66 ~15 ~1 ~66 wool 15
setblock ~8 ~1 ~77 torch 5
fill ~8 ~1 ~112 ~8 ~1 ~113 wool 8
fill ~8 ~1 ~118 ~8 ~1 ~120 wool 8
setblock ~8 ~1 ~128 wool 15
fill ~9 ~1 ~40 ~9 ~3 ~40 wool 8
fill ~9 ~1 ~41 ~9 ~3 ~41 wool 8
setblock ~9 ~1 ~54 torch 5
setblock ~9 ~1 ~62 torch 5
setblock ~9 ~1 ~72 torch 5
setblock ~9 ~1 ~82 torch 5
setblock ~9 ~1 ~86 torch 5
setblock ~9 ~1 ~91 torch 5
setblock ~9 ~1 ~94 torch 5
fill ~9 ~1 ~102 ~9 ~1 ~103 torch 5
setblock ~9 ~1 ~109 grass 0
fill ~9 ~1 ~122 ~11 ~1 ~122 dirt 0
setblock ~9 ~1 ~128 dirt 0
fill ~9 ~1 ~129 ~9 ~1 ~130 wool 15
setblock ~10 ~1 ~37 torch 3
fill ~10 ~1 ~39 ~10 ~10 ~39 wool 7
fill ~10 ~1 ~40 ~10 ~10 ~40 wool 7
fill ~10 ~1 ~41 ~10 ~10 ~41 wool 7
fill ~10 ~1 ~42 ~10 ~10 ~42 wool 7
setblock ~10 ~1 ~43 torch 5
setblock ~10 ~1 ~69 torch 5
fill ~10 ~1 ~109 ~11 ~1 ~109 dirt 0
fill ~10 ~1 ~114 ~10 ~10 ~114 wool 7
fill ~10 ~1 ~115 ~10 ~10 ~115 wool 7
fill ~10 ~1 ~116 ~10 ~10 ~116 wool 7
fill ~10 ~1 ~117 ~10 ~10 ~117 wool 7
fill ~10 ~1 ~128 ~51 ~1 ~128 grass 0
fill ~10 ~1 ~129 ~10 ~1 ~130 dirt 0
setblock ~10 ~1 ~131 wool 15
setblock ~11 ~1 ~53 torch 5
setblock ~11 ~1 ~84 grass 0
setblock ~11 ~1 ~121 dirt 0
fill ~11 ~1 ~129 ~50 ~1 ~129 grass 0
fill ~11 ~1 ~130 ~50 ~1 ~130 grass 0
setblock ~11 ~1 ~131 dirt 0
setblock ~11 ~1 ~132 wool 15
fill ~12 ~1 ~34 ~12 ~3 ~34 wool 15
fill ~12 ~1 ~46 ~12 ~1 ~48 wool 15
setblock ~12 ~1 ~69 torch 5
setblock ~12 ~1 ~74 torch 5
setblock ~12 ~1 ~79 torch 5
setblock ~12 ~1 ~94 torch 5
setblock ~12 ~1 ~99 torch 5
fill ~12 ~1 ~109 ~12 ~3 ~109 wool 15
fill ~12 ~1 ~121 ~12 ~1 ~123 wool 15
fill ~12 ~1 ~131 ~49 ~1 ~131 grass 0
setblock ~12 ~1 ~132 dirt 0
setblock ~12 ~1 ~133 wool 15
setblock ~13 ~1 ~53 torch 5
setblock ~13 ~1 ~58 torch 5
fill ~13 ~1 ~62 ~28 ~1 ~62 wool 15
fill ~13 ~1 ~63 ~15 ~1 ~63 wool 15
fill ~13 ~1 ~64 ~15 ~1 ~64 wool 15
fill ~13 ~1 ~67 ~15 ~1 ~67 wool 15
fill ~13 ~1 ~68 ~15 ~1 ~68 wool 15
fill ~13 ~1 ~69 ~27 ~1 ~69 wool 15
fill ~13 ~1 ~70 ~27 ~1 ~70 wool 15
fill ~13 ~1 ~71 ~27 ~1 ~71 wool 15
fill ~13 ~1 ~72 ~27 ~1 ~72 wool 15
fill ~13 ~1 ~73 ~27 ~1 ~73 wool 15
fill ~13 ~1 ~74 ~27 ~1 ~74 wool 15
fill ~13 ~1 ~75 ~27 ~1 ~75 wool 15
fill ~13 ~1 ~76 ~27 ~1 ~76 wool 15
fill ~13 ~1 ~77 ~27 ~1 ~77 wool 15
fill ~13 ~1 ~78 ~27 ~1 ~78 wool 15
fill ~13 ~1 ~79 ~27 ~1 ~79 wool 15
fill ~13 ~1 ~80 ~27 ~1 ~80 wool 15
fill ~13 ~1 ~81 ~27 ~1 ~81 wool 15
fill ~13 ~1 ~82 ~27 ~1 ~82 wool 15
fill ~13 ~1 ~83 ~27 ~1 ~83 wool 15
fill ~13 ~1 ~84 ~27 ~1 ~84 wool 15
fill ~13 ~1 ~85 ~27 ~1 ~85 wool 15
fill ~13 ~1 ~86 ~14 ~1 ~86 wool 15
fill ~13 ~1 ~87 ~14 ~1 ~87 wool 15
fill ~13 ~1 ~88 ~14 ~1 ~88 wool 15
fill ~13 ~1 ~89 ~14 ~1 ~89 wool 15
fill ~13 ~1 ~90 ~14 ~1 ~90 wool 15
fill ~13 ~1 ~91 ~14 ~1 ~91 wool 15
fill ~13 ~1 ~92 ~14 ~1 ~92 wool 15
fill ~13 ~1 ~93 ~14 ~1 ~93 wool 15
fill ~13 ~1 ~94 ~14 ~1 ~94 wool 15
fill ~13 ~1 ~95 ~14 ~1 ~95 wool 15
fill ~13 ~1 ~96 ~14 ~1 ~96 wool 15
fill ~13 ~1 ~98 ~14 ~1 ~98 wool 15
fill ~13 ~1 ~132 ~48 ~1 ~132 grass 0
fill ~13 ~1 ~133 ~15 ~1 ~133 dirt 0
fill ~13 ~1 ~134 ~15 ~1 ~134 wool 15
setblock ~14 ~1 ~102 torch 5
fill ~15 ~1 ~33 ~15 ~12 ~33 wool 15
fill ~15 ~1 ~61 ~28 ~1 ~61 wool 15
fill ~15 ~1 ~86 ~26 ~1 ~86 wool 11
fill ~15 ~1 ~87 ~15 ~1 ~98 wool 11
fill ~15 ~1 ~135 ~16 ~1 ~135 wool 15
fill ~16 ~1 ~33 ~16 ~1 ~52 grass 0
fill ~16 ~1 ~63 ~26 ~1 ~63 wool 11
fill ~16 ~1 ~64 ~16 ~1 ~68 wool 11
fill ~16 ~1 ~87 ~25 ~1 ~87 wool 7
fill ~16 ~1 ~88 ~25 ~1 ~88 wool 7
fill ~16 ~1 ~89 ~25 ~1 ~89 wool 7
fill ~16 ~1 ~90 ~25 ~1 ~90 wool 7
fill ~16 ~1 ~91 ~25 ~1 ~91 wool 7
fill ~16 ~1 ~92 ~25 ~1 ~92 wool 7
fill ~16 ~1 ~93 ~24 ~1 ~93 wool 7
fill ~16 ~1 ~94 ~24 ~1 ~94 wool 7
fill ~16 ~1 ~95 ~23 ~1 ~95 wool 7
fill ~16 ~1 ~96 ~23 ~1 ~96 wool 7
fill ~16 ~1 ~97 ~23 ~1 ~97 wool 7
fill ~16 ~1 ~98 ~23 ~1 ~98 wool 7
setblock ~16 ~1 ~102 torch 5
fill ~16 ~1 ~106 ~16 ~9 ~106 wool 15
fill ~16 ~1 ~107 ~16 ~11 ~107 wool 15
fill ~16 ~1 ~108 ~16 ~12 ~108 wool 15
fill ~16 ~1 ~109 ~16 ~13 ~109 wool 15
fill ~16 ~1 ~110 ~16 ~14 ~110 wool 15
fill ~16 ~1 ~111 ~16 ~14 ~111 wool 15
fill ~16 ~1 ~112 ~16 ~15 ~112 wool 15
fill ~16 ~1 ~113 ~16 ~15 ~113 wool 15
fill ~16 ~1 ~114 ~16 ~15 ~114 wool 15
fill ~16 ~1 ~115 ~16 ~15 ~115 wool 15
fill ~16 ~1 ~116 ~16 ~15 ~116 wool 15
fill ~16 ~1 ~117 ~16 ~15 ~117 wool 15
fill ~16 ~1 ~118 ~16 ~15 ~118 wool 15
fill ~16 ~1 ~119 ~16 ~15 ~119 wool 15
fill ~16 ~1 ~120 ~16 ~14 ~120 wool 15
fill ~16 ~1 ~121 ~16 ~14 ~121 wool 15
fill ~16 ~1 ~122 ~16 ~13 ~122 wool 15
fill ~16 ~1 ~123 ~16 ~12 ~123 wool 15
fill ~16 ~1 ~124 ~16 ~11 ~124 wool 15
fill ~16 ~1 ~125 ~16 ~9 ~125 wool 15
fill ~16 ~1 ~126 ~16 ~7 ~126 wool 15
fill ~16 ~1 ~127 ~44 ~1 ~127 grass 0
fill ~16 ~1 ~133 ~45 ~1 ~133 grass 0
setblock ~16 ~1 ~134 dirt 0
fill ~17 ~1 ~34 ~44 ~1 ~34 grass 0
fill ~17 ~1 ~35 ~29 ~1 ~35 grass 0
fill ~17 ~1 ~36 ~44 ~1 ~36 grass 0
fill ~17 ~1 ~37 ~44 ~1 ~37 grass 0
fill ~17 ~1 ~38 ~44 ~1 ~38 grass 0
fill ~17 ~1 ~39 ~44 ~1 ~39 grass 0
fill ~17 ~1 ~40 ~44 ~1 ~40 grass 0
fill ~17 ~1 ~41 ~44 ~1 ~41 grass 0
fill ~17 ~1 ~42 ~35 ~1 ~42 grass 0
fill ~17 ~1 ~43 ~35 ~1 ~43 grass 0
fill ~17 ~1 ~44 ~35 ~1 ~44 grass 0
fill ~17 ~1 ~45 ~44 ~1 ~45 grass 0
fill ~17 ~1 ~46 ~44 ~1 ~46 grass 0
fill ~17 ~1 ~47 ~44 ~1 ~47 grass 0
fill ~17 ~1 ~48 ~44 ~1 ~48 grass 0
fill ~17 ~1 ~49 ~44 ~1 ~49 grass 0
fill ~17 ~1 ~50 ~44 ~1 ~50 grass 0
fill ~17 ~1 ~51 ~44 ~1 ~51 grass 0
fill ~17 ~1 ~52 ~45 ~1 ~52 grass 0
fill ~17 ~1 ~64 ~25 ~1 ~64 wool 7
fill ~17 ~1 ~65 ~25 ~1 ~65 wool 7
fill ~17 ~1 ~66 ~25 ~1 ~66 wool 7
fill ~17 ~1 ~67 ~25 ~1 ~67 wool 7
fill ~17 ~1 ~68 ~26 ~1 ~68 wool 11
fill ~17 ~1 ~105 ~44 ~1 ~105 grass 0
fill ~17 ~1 ~106 ~44 ~1 ~106 grass 0
fill ~17 ~1 ~107 ~44 ~1 ~107 grass 0
fill ~17 ~1 ~108 ~31 ~1 ~108 cobblestone 0
fill ~17 ~1 ~109 ~31 ~1 ~109 cobblestone 0
fill ~17 ~1 ~110 ~44 ~1 ~110 cobblestone 0
fill ~17 ~1 ~111 ~44 ~1 ~111 cobblestone 0
fill ~17 ~1 ~112 ~44 ~1 ~112 cobblestone 0
fill ~17 ~1 ~113 ~44 ~1 ~113 cobblestone 0
fill ~17 ~1 ~114 ~44 ~1 ~114 cobblestone 0
fill ~17 ~1 ~115 ~44 ~1 ~115 cobblestone 0
fill ~17 ~1 ~116 ~44 ~1 ~116 cobblestone 0
fill ~17 ~1 ~117 ~44 ~1 ~117 cobblestone 0
fill ~17 ~1 ~118 ~44 ~1 ~118 cobblestone 0
fill ~17 ~1 ~119 ~44 ~1 ~119 cobblestone 0
fill ~17 ~1 ~120 ~44 ~1 ~120 cobblestone 0
fill ~17 ~1 ~121 ~32 ~1 ~121 cobblestone 0
fill ~17 ~1 ~122 ~44 ~1 ~122 cobblestone 0
fill ~17 ~1 ~123 ~44 ~1 ~123 grass 0
fill ~17 ~1 ~124 ~44 ~1 ~124 grass 0
fill ~17 ~1 ~125 ~44 ~1 ~125 grass 0
fill ~17 ~1 ~126 ~44 ~1 ~126 grass 0
fill ~17 ~1 ~134 ~44 ~1 ~134 grass 0
fill ~17 ~1 ~135 ~19 ~1 ~135 dirt 0
fill ~17 ~1 ~136 ~19 ~1 ~136 wool 15
setblock ~18 ~1 ~100 torch 5
setblock ~19 ~1 ~53 torch 5
setblock ~19 ~1 ~103 torch 5
setblock ~20 ~1 ~58 torch 5
fill ~20 ~1 ~135 ~41 ~1 ~135 grass 0
fill ~20 ~1 ~136 ~23 ~1 ~136 dirt 0
fill ~20 ~1 ~137 ~23 ~1 ~137 wool 15
fill ~22 ~1 ~33 ~25 ~1 ~33 grass 0
setblock ~22 ~1 ~56 torch 5
setblock ~22 ~1 ~100 torch 5
setblock ~22 ~1 ~102 torch 5
setblock ~24 ~1 ~60 torch 5
fill ~24 ~1 ~95 ~25 ~1 ~95 wool 11
fill ~24 ~1 ~96 ~24 ~1 ~98 wool 11
fill ~24 ~1 ~136 ~37 ~1 ~136 grass 0
fill ~24 ~1 ~137 ~37 ~1 ~137 dirt 0
fill ~24 ~1 ~138 ~37 ~1 ~138 wool 15
setblock ~25 ~1 ~55 torch 5
fill ~25 ~1 ~93 ~26 ~1 ~93 wool 11
fill ~25 ~1 ~94 ~25 ~1 ~93 wool 11
fill ~25 ~1 ~96 ~26 ~1 ~96 wool 15
fill ~25 ~1 ~97 ~25 ~1 ~98 wool 15
fill ~26 ~1 ~64 ~26 ~1 ~68 wool 11
fill ~26 ~1 ~87 ~26 ~1 ~93 wool 11
fill ~26 ~1 ~94 ~27 ~1 ~94 wool 15
fill ~26 ~1 ~95 ~26 ~1 ~94 wool 15
fill ~27 ~1 ~63 ~28 ~1 ~63 wool 15
fill ~27 ~1 ~64 ~28 ~1 ~64 wool 15
fill ~27 ~1 ~65 ~28 ~1 ~65 wool 15
fill ~27 ~1 ~66 ~28 ~1 ~66 wool 15
fill ~27 ~1 ~67 ~28 ~1 ~67 wool 15
fill ~27 ~1 ~68 ~28 ~1 ~68 wool 15
fill ~27 ~1 ~86 ~27 ~1 ~94 wool 15
setblock ~27 ~1 ~102 torch 5
setblock ~29 ~1 ~56 torch 5
fill ~29 ~1 ~58 ~31 ~1 ~58 torch 5
setblock ~29 ~1 ~83 torch 5
setblock ~29 ~1 ~87 torch 5
fill ~30 ~1 ~35 ~30 ~23 ~35 dirt 0
setblock ~30 ~1 ~53 torch 5
setblock ~30 ~1 ~71 torch 5
setblock ~30 ~1 ~74 torch 5
setblock ~30 ~1 ~77 torch 5
setblock ~30 ~1 ~80 torch 5
setblock ~30 ~1 ~82 torch 5
setblock ~30 ~1 ~86 torch 5
setblock ~30 ~1 ~92 torch 5
setblock ~30 ~1 ~101 torch 5
fill ~31 ~1 ~35 ~44 ~1 ~35 grass 0
setblock ~31 ~1 ~99 torch 5
setblock ~32 ~1 ~55 torch 5
setblock ~32 ~1 ~77 torch 5
fill ~32 ~1 ~108 ~33 ~1 ~108 grass 0
fill ~32 ~1 ~109 ~33 ~1 ~109 grass 0
fill ~33 ~1 ~61 ~49 ~1 ~61 wool 15
fill ~33 ~1 ~62 ~49 ~1 ~62 wool 15
fill ~33 ~1 ~63 ~34 ~1 ~63 wool 15
fill ~33 ~1 ~64 ~34 ~1 ~64 wool 15
fill ~33 ~1 ~65 ~34 ~1 ~65 wool 15
fill ~33 ~1 ~66 ~34 ~1 ~66 wool 15
fill ~33 ~1 ~67 ~34 ~1 ~67 wool 15
setblock ~33 ~1 ~101 torch 5
fill ~33 ~1 ~121 ~34 ~1 ~121 dirt 0
fill ~34 ~1 ~68 ~34 ~1 ~94 wool 15
fill ~34 ~1 ~108 ~44 ~1 ~108 cobblestone 0
fill ~34 ~1 ~109 ~44 ~1 ~109 cobblestone 0
setblock ~35 ~1 ~57 torch 5
setblock ~35 ~1 ~59 torch 5
fill ~35 ~1 ~63 ~45 ~1 ~63 wool 11
fill ~35 ~1 ~64 ~35 ~1 ~68 wool 11
fill ~35 ~1 ~69 ~48 ~1 ~69 wool 15
fill ~35 ~1 ~70 ~48 ~1 ~70 wool 15
fill ~35 ~1 ~71 ~48 ~1 ~71 wool 15
fill ~35 ~1 ~72 ~48 ~1 ~72 wool 15
fill ~35 ~1 ~73 ~48 ~1 ~73 wool 15
fill ~35 ~1 ~74 ~48 ~1 ~74 wool 15
fill ~35 ~1 ~75 ~48 ~1 ~75 wool 15
fill ~35 ~1 ~76 ~48 ~1 ~76 wool 15
fill ~35 ~1 ~77 ~48 ~1 ~77 wool 15
fill ~35 ~1 ~78 ~48 ~1 ~78 wool 15
fill ~35 ~1 ~79 ~48 ~1 ~79 wool 15
fill ~35 ~1 ~80 ~48 ~1 ~80 wool 15
fill ~35 ~1 ~81 ~48 ~1 ~81 wool 15
fill ~35 ~1 ~82 ~48 ~1 ~82 wool 15
fill ~35 ~1 ~83 ~48 ~1 ~83 wool 15
fill ~35 ~1 ~84 ~48 ~1 ~84 wool 15
fill ~35 ~1 ~85 ~48 ~1 ~85 wool 15
fill ~35 ~1 ~86 ~46 ~1 ~86 wool 11
fill ~35 ~1 ~87 ~35 ~1 ~93 wool 11
fill ~35 ~1 ~94 ~35 ~1 ~96 wool 15
fill ~35 ~1 ~121 ~44 ~1 ~121 cobblestone 0
fill ~36 ~1 ~33 ~39 ~1 ~33 grass 0
fill ~36 ~1 ~64 ~44 ~1 ~64 wool 7
fill ~36 ~1 ~65 ~44 ~1 ~65 wool 7
fill ~36 ~1 ~66 ~44 ~1 ~66 wool 7
fill ~36 ~1 ~67 ~44 ~1 ~67 wool 7
fill ~36 ~1 ~68 ~45 ~1 ~68 wool 11
fill ~36 ~1 ~87 ~45 ~1 ~87 wool 7
fill ~36 ~1 ~88 ~45 ~1 ~88 wool 7
fill ~36 ~1 ~89 ~45 ~1 ~89 wool 7
fill ~36 ~1 ~90 ~45 ~1 ~90 wool 7
fill ~36 ~1 ~91 ~45 ~1 ~91 wool 7
fill ~36 ~1 ~92 ~45 ~1 ~92 wool 7
fill ~36 ~1 ~93 ~36 ~1 ~95 wool 11
fill ~36 ~1 ~96 ~36 ~1 ~98 wool 15
setblock ~36 ~1 ~103 torch 5
fill ~37 ~1 ~42 ~44 ~1 ~42 grass 0
fill ~37 ~1 ~43 ~44 ~1 ~43 grass 0
fill ~37 ~1 ~44 ~44 ~1 ~44 grass 0
setblock ~37 ~1 ~55 torch 5
fill ~37 ~1 ~93 ~45 ~1 ~93 wool 7
fill ~37 ~1 ~94 ~45 ~1 ~94 wool 7
fill ~37 ~1 ~95 ~37 ~1 ~98 wool 11
setblock ~37 ~1 ~101 torch 5
setblock ~38 ~1 ~57 torch 5
fill ~38 ~1 ~95 ~45 ~1 ~95 wool 7
fill ~38 ~1 ~96 ~45 ~1 ~96 wool 7
fill ~38 ~1 ~97 ~45 ~1 ~97 wool 7
fill ~38 ~1 ~98 ~45 ~1 ~98 wool 7
fill ~38 ~1 ~136 ~41 ~1 ~136 dirt 0
fill ~38 ~1 ~137 ~41 ~1 ~137 wool 15
setblock ~40 ~1 ~55 torch 5
setblock ~40 ~1 ~60 torch 5
fill ~42 ~1 ~135 ~44 ~1 ~135 dirt 0
fill ~42 ~1 ~136 ~44 ~1 ~136 wool 15
setblock ~43 ~1 ~100 torch 5
fill ~45 ~1 ~64 ~45 ~1 ~68 wool 11
setblock ~45 ~1 ~104 grass 0
fill ~45 ~1 ~105 ~45 ~8 ~105 wool 15
fill ~45 ~1 ~106 ~45 ~9 ~106 wool 15
fill ~45 ~1 ~107 ~45 ~11 ~107 wool 15
fill ~45 ~1 ~108 ~45 ~12 ~108 wool 15
fill ~45 ~1 ~109 ~45 ~13 ~109 wool 15
fill ~45 ~1 ~110 ~45 ~14 ~110 wool 15
fill ~45 ~1 ~111 ~45 ~14 ~111 wool 15
fill ~45 ~1 ~112 ~45 ~15 ~112 wool 15
fill ~45 ~1 ~113 ~45 ~15 ~113 wool 15
fill ~45 ~1 ~114 ~45 ~15 ~114 wool 15
fill ~45 ~1 ~115 ~45 ~15 ~115 wool 15
fill ~45 ~1 ~116 ~45 ~15 ~116 wool 15
fill ~45 ~1 ~117 ~45 ~15 ~117 wool 15
fill ~45 ~1 ~118 ~45 ~15 ~118 wool 15
fill ~45 ~1 ~119 ~45 ~15 ~119 wool 15
fill ~45 ~1 ~120 ~46 ~1 ~120 grass 0
fill ~45 ~1 ~121 ~46 ~1 ~121 grass 0
fill ~45 ~1 ~122 ~46 ~1 ~122 grass 0
fill ~45 ~1 ~123 ~45 ~12 ~123 wool 15
fill ~45 ~1 ~124 ~45 ~11 ~124 wool 15
fill ~45 ~1 ~125 ~45 ~9 ~125 wool 15
fill ~45 ~1 ~126 ~45 ~6 ~126 wool 15
fill ~45 ~1 ~127 ~54 ~1 ~127 wool 15
setblock ~45 ~1 ~134 dirt 0
setblock ~45 ~1 ~135 wool 15
fill ~46 ~1 ~33 ~46 ~12 ~33 wool 15
fill ~46 ~1 ~51 ~54 ~1 ~51 wool 15
fill ~46 ~1 ~63 ~48 ~1 ~63 wool 15
fill ~46 ~1 ~64 ~48 ~1 ~64 wool 15
fill ~46 ~1 ~65 ~53 ~1 ~65 wool 15
fill ~46 ~1 ~66 ~53 ~1 ~66 wool 15
fill ~46 ~1 ~67 ~48 ~1 ~67 wool 15
fill ~46 ~1 ~68 ~48 ~1 ~68 wool 15
fill ~46 ~1 ~87 ~46 ~1 ~98 wool 11
fill ~46 ~1 ~104 ~54 ~1 ~104 wool 15
fill ~46 ~1 ~133 ~48 ~1 ~133 dirt 0
fill ~46 ~1 ~134 ~48 ~1 ~134 wool 15
fill ~47 ~1 ~86 ~48 ~1 ~86 wool 15
fill ~47 ~1 ~87 ~48 ~1 ~87 wool 15
fill ~47 ~1 ~88 ~48 ~1 ~88 wool 15
fill ~47 ~1 ~89 ~48 ~1 ~89 wool 15
fill ~47 ~1 ~90 ~48 ~1 ~90 wool 15
fill ~47 ~1 ~91 ~48 ~1 ~91 wool 15
fill ~47 ~1 ~92 ~48 ~1 ~92 wool 15
fill ~47 ~1 ~93 ~48 ~1 ~93 wool 15
fill ~47 ~1 ~94 ~48 ~1 ~94 wool 15
fill ~47 ~1 ~95 ~48 ~1 ~95 wool 15
fill ~47 ~1 ~96 ~48 ~1 ~96 wool 15
fill ~47 ~1 ~97 ~54 ~1 ~97 wool 15
fill ~47 ~1 ~98 ~48 ~1 ~98 wool 15
setblock ~48 ~1 ~59 torch 5
fill ~49 ~1 ~33 ~55 ~1 ~33 wool 15
fill ~49 ~1 ~34 ~49 ~3 ~34 wool 15
fill ~49 ~1 ~47 ~49 ~3 ~47 wool 15
fill ~49 ~1 ~48 ~55 ~1 ~48 wool 15
setblock ~49 ~1 ~67 torch 5
fill ~49 ~1 ~108 ~55 ~1 ~108 wool 15
fill ~49 ~1 ~109 ~49 ~3 ~109 wool 15
fill ~49 ~1 ~122 ~49 ~3 ~122 wool 15
fill ~49 ~1 ~123 ~55 ~1 ~123 wool 15
setblock ~49 ~1 ~132 dirt 0
setblock ~49 ~1 ~133 wool 15
fill ~50 ~1 ~34 ~54 ~1 ~34 dirt 0
fill ~50 ~1 ~35 ~54 ~1 ~35 dirt 0
fill ~50 ~1 ~36 ~54 ~1 ~36 wool 8
fill ~50 ~1 ~45 ~54 ~1 ~45 wool 8
fill ~50 ~1 ~46 ~54 ~1 ~46 dirt 0
fill ~50 ~1 ~47 ~54 ~1 ~47 dirt 0
setblock ~50 ~1 ~99 torch 5
fill ~50 ~1 ~111 ~54 ~1 ~111 wool 8
fill ~50 ~1 ~120 ~54 ~1 ~120 wool 8
setblock ~50 ~1 ~131 dirt 0
setblock ~50 ~1 ~132 wool 15
fill ~51 ~1 ~39 ~51 ~2 ~39 wool 7
fill ~51 ~1 ~40 ~51 ~10 ~40 wool 7
fill ~51 ~1 ~41 ~51 ~10 ~41 wool 7
fill ~51 ~1 ~42 ~51 ~9 ~42 wool 7
setblock ~51 ~1 ~54 torch 5
setblock ~51 ~1 ~56 torch 5
setblock ~51 ~1 ~61 torch 5
setblock ~51 ~1 ~86 torch 5
setblock ~51 ~1 ~92 torch 5
fill ~51 ~1 ~114 ~51 ~10 ~114 wool 7
fill ~51 ~1 ~115 ~51 ~10 ~115 wool 7
fill ~51 ~1 ~116 ~51 ~10 ~116 wool 7
fill ~51 ~1 ~117 ~51 ~10 ~117 wool 7
setblock ~51 ~1 ~129 dirt 0
setblock ~51 ~1 ~131 wool 15
setblock ~52 ~1 ~67 torch 5
setblock ~52 ~1 ~71 torch 5
setblock ~52 ~1 ~77 torch 5
setblock ~52 ~1 ~82 torch 5
fill ~52 ~1 ~115 ~52 ~3 ~115 wool 8
fill ~52 ~1 ~116 ~52 ~3 ~116 wool 8
setblock ~52 ~1 ~128 dirt 0
fill ~52 ~1 ~129 ~52 ~1 ~130 wool 15
fill ~53 ~1 ~38 ~53 ~1 ~39 wool 8
fill ~53 ~1 ~42 ~53 ~1 ~43 wool 8
setblock ~53 ~1 ~128 wool 15
fill ~55 ~1 ~34 ~55 ~3 ~34 wool 15
fill ~55 ~1 ~46 ~55 ~1 ~48 wool 15
fill ~55 ~1 ~51 ~55 ~1 ~105 wool 11
fill ~55 ~1 ~109 ~55 ~3 ~109 wool 15
fill ~55 ~1 ~121 ~55 ~1 ~123 wool 15
fill ~6 ~2 ~33 ~12 ~2 ~33 wool 15
fill ~6 ~2 ~48 ~12 ~2 ~48 wool 15
fill ~6 ~2 ~108 ~12 ~2 ~108 wool 15
fill ~6 ~2 ~123 ~12 ~2 ~123 wool 15
fill ~7 ~2 ~27 ~8 ~2 ~27 wool 15
fill ~7 ~2 ~28 ~7 ~2 ~30 wool 15
fill ~7 ~2 ~34 ~11 ~2 ~34 dirt 0
fill ~7 ~2 ~35 ~11 ~2 ~35 wool 8
fill ~7 ~2 ~46 ~11 ~2 ~46 wool 8
fill ~7 ~2 ~47 ~11 ~2 ~47 dirt 0
fill ~7 ~2 ~51 ~7 ~2 ~64 wool 11
fill ~7 ~2 ~65 ~7 ~2 ~96 wool 15
fill ~7 ~2 ~97 ~7 ~2 ~105 wool 11
fill ~7 ~2 ~109 ~7 ~3 ~109 dirt 0
fill ~7 ~2 ~110 ~11 ~2 ~110 wool 8
fill ~7 ~2 ~121 ~11 ~2 ~121 wool 8
fill ~8 ~2 ~24 ~9 ~2 ~24 wool 15
fill ~8 ~2 ~25 ~8 ~2 ~27 wool 15
fill ~8 ~2 ~30 ~15 ~2 ~30 wool 15
fill ~8 ~2 ~51 ~14 ~2 ~51 wool 15
fill ~8 ~2 ~96 ~12 ~2 ~96 wool 7
fill ~8 ~2 ~97 ~8 ~2 ~98 wool 15
fill ~8 ~2 ~105 ~16 ~2 ~105 wool 15
setblock ~8 ~2 ~109 grass 0
fill ~8 ~2 ~127 ~8 ~3 ~127 wool 11
fill ~9 ~2 ~20 ~10 ~2 ~20 wool 15
fill ~9 ~2 ~21 ~9 ~2 ~24 wool 15
fill ~9 ~2 ~28 ~52 ~2 ~28 grass 0
setblock ~9 ~2 ~44 wool 14
fill ~9 ~2 ~64 ~12 ~2 ~64 wool 7
fill ~9 ~2 ~67 ~12 ~2 ~67 wool 7
setblock ~9 ~2 ~97 torch 1
fill ~9 ~2 ~98 ~12 ~2 ~98 wool 15
setblock ~9 ~2 ~109 torch 3
fill ~9 ~2 ~111 ~9 ~2 ~113 wool 8
fill ~9 ~2 ~118 ~9 ~4 ~118 wool 8
fill ~9 ~2 ~119 ~9 ~3 ~119 wool 8
fill ~9 ~2 ~120 ~9 ~2 ~118 wool 8
fill ~9 ~2 ~127 ~15 ~2 ~127 wool 15
setblock ~9 ~2 ~128 wool 11
fill ~10 ~2 ~19 ~13 ~2 ~19 wool 15
fill ~10 ~2 ~27 ~51 ~2 ~27 grass 0
fill ~10 ~2 ~37 ~10 ~7 ~37 wool 7
fill ~10 ~2 ~38 ~10 ~9 ~38 wool 7
fill ~10 ~2 ~43 ~10 ~9 ~43 wool 7
fill ~10 ~2 ~44 ~10 ~9 ~44 wool 7
fill ~10 ~2 ~109 ~11 ~2 ~109 grass 0
fill ~10 ~2 ~112 ~10 ~2 ~119 wool 7
fill ~10 ~2 ~129 ~10 ~2 ~130 wool 11
fill ~11 ~2 ~122 ~11 ~3 ~122 dirt 0
setblock ~11 ~2 ~131 wool 11
fill ~12 ~2 ~47 ~12 ~3 ~47 wool 15
fill ~12 ~2 ~68 ~12 ~2 ~96 wool 7
setblock ~12 ~2 ~97 wool 15
fill ~12 ~2 ~99 ~14 ~2 ~99 wool 15
fill ~12 ~2 ~100 ~25 ~2 ~100 wool 15
fill ~12 ~2 ~122 ~12 ~3 ~122 wool 15
setblock ~12 ~2 ~132 wool 11
fill ~13 ~2 ~18 ~16 ~2 ~18 wool 15
fill ~13 ~2 ~20 ~13 ~2 ~21 wool 15
fill ~13 ~2 ~61 ~13 ~5 ~61 wool 7
fill ~13 ~2 ~62 ~13 ~4 ~62 wool 7
fill ~13 ~2 ~63 ~13 ~2 ~61 wool 7
fill ~13 ~2 ~98 ~13 ~4 ~98 sand 0
fill ~13 ~2 ~133 ~15 ~2 ~133 wool 11
fill ~14 ~2 ~61 ~29 ~2 ~61 wool 15
fill ~14 ~2 ~98 ~14 ~16 ~98 ladder 5
setblock ~14 ~2 ~129 torch 5
fill ~15 ~2 ~31 ~15 ~9 ~31 wool 15
fill ~15 ~2 ~32 ~15 ~11 ~32 wool 15
setblock ~15 ~2 ~69 torch 5
setblock ~15 ~2 ~75 torch 5
setblock ~15 ~2 ~80 torch 5
setblock ~15 ~2 ~84 torch 5
fill ~15 ~2 ~99 ~24 ~2 ~99 wool 11
fill ~15 ~2 ~134 ~16 ~2 ~134 wool 11
fill ~16 ~2 ~17 ~17 ~2 ~17 wool 15
setblock ~16 ~2 ~37 torch 5
setblock ~16 ~2 ~40 torch 5
setblock ~16 ~2 ~44 torch 5
fill ~17 ~2 ~16 ~22 ~2 ~16 wool 15
fill ~17 ~2 ~29 ~44 ~2 ~29 grass 0
fill ~17 ~2 ~30 ~17 ~2 ~32 dirt 0
fill ~17 ~2 ~33 ~21 ~2 ~33 grass 0
setblock ~17 ~2 ~48 torch 5
fill ~17 ~2 ~70 ~17 ~2 ~82 wool 8
setblock ~17 ~2 ~132 torch 5
fill ~17 ~2 ~135 ~19 ~2 ~135 wool 11
fill ~18 ~2 ~30 ~44 ~2 ~30 grass 0
fill ~18 ~2 ~31 ~44 ~2 ~31 grass 0
fill ~18 ~2 ~32 ~44 ~2 ~32 grass 0
setblock ~18 ~2 ~51 torch 5
setblock ~18 ~2 ~77 torch 5
setblock ~18 ~2 ~82 torch 5
setblock ~18 ~2 ~105 torch 5
setblock ~18 ~2 ~112 torch 5
setblock ~18 ~2 ~115 torch 5
setblock ~18 ~2 ~120 torch 5
setblock ~19 ~2 ~36 torch 5
setblock ~19 ~2 ~123 torch 5
setblock ~20 ~2 ~41 torch 5
setblock ~20 ~2 ~129 torch 5
fill ~20 ~2 ~136 ~22 ~2 ~136 wool 11
setblock ~21 ~2 ~69 torch 5
setblock ~21 ~2 ~75 torch 5
setblock ~21 ~2 ~105 torch 5
setblock ~21 ~2 ~116 torch 5
setblock ~21 ~2 ~119 torch 5
setblock ~21 ~2 ~126 torch 5
fill ~22 ~2 ~15 ~39 ~2 ~15 wool 15
setblock ~22 ~2 ~72 torch 5
setblock ~22 ~2 ~79 torch 5
setblock ~22 ~2 ~82 torch 5
setblock ~22 ~2 ~109 torch 5
setblock ~22 ~2 ~113 torch 5
setblock ~23 ~2 ~36 torch 5
setblock ~23 ~2 ~47 torch 5
setblock ~23 ~2 ~51 torch 5
setblock ~23 ~2 ~136 wool 0
setblock ~24 ~2 ~40 torch 5
fill ~24 ~2 ~70 ~24 ~2 ~82 wool 8
setblock ~24 ~2 ~107 torch 5
setblock ~24 ~2 ~128 torch 5
setblock ~24 ~2 ~131 torch 5
setblock ~24 ~2 ~133 torch 5
fill ~24 ~2 ~137 ~29 ~2 ~137 wool 0
setblock ~25 ~2 ~70 torch 5
setblock ~25 ~2 ~99 wool 15
setblock ~25 ~2 ~116 torch 5
setblock ~25 ~2 ~127 torch 5
fill ~26 ~2 ~33 ~35 ~2 ~33 grass 0
setblock ~26 ~2 ~47 torch 5
setblock ~26 ~2 ~73 torch 5
setblock ~26 ~2 ~75 torch 5
setblock ~26 ~2 ~78 torch 5
setblock ~26 ~2 ~82 torch 5
setblock ~26 ~2 ~85 torch 5
fill ~26 ~2 ~97 ~26 ~13 ~97 wool 15
fill ~26 ~2 ~98 ~26 ~12 ~98 wool 15
setblock ~27 ~2 ~36 torch 5
setblock ~27 ~2 ~42 torch 5
setblock ~27 ~2 ~94 torch 5
fill ~27 ~2 ~95 ~27 ~14 ~95 wool 15
fill ~27 ~2 ~96 ~27 ~14 ~96 wool 15
setblock ~27 ~2 ~108 torch 5
setblock ~27 ~2 ~112 torch 5
setblock ~27 ~2 ~121 torch 5
setblock ~27 ~2 ~132 torch 5
setblock ~28 ~2 ~51 torch 5
setblock ~28 ~2 ~62 torch 3
fill ~28 ~2 ~68 ~28 ~2 ~94 wool 15
setblock ~28 ~2 ~130 torch 5
fill ~29 ~2 ~62 ~29 ~4 ~62 wool 15
fill ~29 ~2 ~63 ~29 ~3 ~63 wool 15
fill ~29 ~2 ~64 ~29 ~3 ~64 wool 15
fill ~29 ~2 ~65 ~29 ~3 ~65 wool 15
fill ~29 ~2 ~66 ~29 ~3 ~66 wool 15
fill ~29 ~2 ~67 ~29 ~3 ~67 wool 15
setblock ~29 ~2 ~107 torch 5
setblock ~29 ~2 ~126 torch 5
fill ~30 ~2 ~36 ~30 ~24 ~36 ladder 3
setblock ~30 ~2 ~37 torch 5
fill ~30 ~2 ~40 ~31 ~2 ~40 torch 5
fill ~30 ~2 ~41 ~31 ~2 ~41 torch 5
fill ~30 ~2 ~42 ~31 ~2 ~42 torch 5
fill ~30 ~2 ~43 ~31 ~2 ~43 torch 5
fill ~30 ~2 ~44 ~31 ~2 ~44 torch 5
setblock ~30 ~2 ~46 torch 5
setblock ~30 ~2 ~49 torch 5
setblock ~30 ~2 ~51 torch 5
setblock ~30 ~2 ~105 torch 5
setblock ~30 ~2 ~110 torch 5
setblock ~30 ~2 ~116 torch 5
setblock ~30 ~2 ~120 torch 5
setblock ~30 ~2 ~127 torch 5
setblock ~30 ~2 ~135 torch 5
fill ~30 ~2 ~137 ~31 ~2 ~137 wool 11
setblock ~31 ~2 ~36 torch 5
setblock ~31 ~2 ~124 torch 5
setblock ~31 ~2 ~132 torch 5
setblock ~32 ~2 ~46 torch 5
fill ~32 ~2 ~61 ~48 ~2 ~61 wool 15
fill ~32 ~2 ~62 ~32 ~4 ~62 wool 15
fill ~32 ~2 ~63 ~32 ~3 ~63 wool 15
fill ~32 ~2 ~64 ~32 ~3 ~64 wool 15
fill ~32 ~2 ~65 ~32 ~3 ~65 wool 15
fill ~32 ~2 ~66 ~32 ~3 ~66 wool 15
fill ~32 ~2 ~67 ~32 ~3 ~67 wool 15
setblock ~32 ~2 ~130 torch 5
fill ~32 ~2 ~137 ~37 ~2 ~137 wool 0
setblock ~33 ~2 ~51 torch 5
setblock ~33 ~2 ~62 torch 1
fill ~33 ~2 ~68 ~33 ~2 ~94 wool 15
setblock ~34 ~2 ~69 torch 5
setblock ~34 ~2 ~74 torch 5
setblock ~34 ~2 ~78 torch 5
setblock ~34 ~2 ~83 torch 5
setblock ~34 ~2 ~88 torch 5
fill ~34 ~2 ~95 ~34 ~14 ~95 wool 15
fill ~34 ~2 ~96 ~34 ~13 ~96 wool 15
setblock ~34 ~2 ~107 torch 5
setblock ~34 ~2 ~114 torch 5
setblock ~34 ~2 ~119 torch 5
setblock ~34 ~2 ~127 torch 5
setblock ~35 ~2 ~36 torch 5
setblock ~35 ~2 ~41 torch 5
setblock ~35 ~2 ~49 torch 5
fill ~35 ~2 ~97 ~35 ~13 ~97 wool 15
fill ~35 ~2 ~98 ~35 ~12 ~98 wool 15
fill ~35 ~2 ~99 ~36 ~2 ~99 wool 15
setblock ~35 ~2 ~110 torch 5
setblock ~35 ~2 ~123 torch 5
setblock ~35 ~2 ~134 torch 5
fill ~36 ~2 ~100 ~48 ~2 ~100 wool 15
setblock ~36 ~2 ~132 torch 5
setblock ~37 ~2 ~46 torch 5
fill ~37 ~2 ~70 ~37 ~2 ~82 wool 8
fill ~37 ~2 ~99 ~46 ~2 ~99 wool 11
setblock ~37 ~2 ~106 torch 5
setblock ~38 ~2 ~50 torch 5
setblock ~38 ~2 ~52 torch 5
setblock ~38 ~2 ~85 torch 5
setblock ~38 ~2 ~94 torch 5
setblock ~38 ~2 ~117 torch 5
setblock ~38 ~2 ~126 torch 5
setblock ~38 ~2 ~135 torch 5
setblock ~38 ~2 ~136 wool 0
fill ~39 ~2 ~16 ~44 ~2 ~16 wool 15
setblock ~39 ~2 ~36 torch 5
setblock ~39 ~2 ~69 torch 5
setblock ~39 ~2 ~121 torch 5
setblock ~39 ~2 ~129 torch 5
fill ~39 ~2 ~136 ~41 ~2 ~136 wool 11
fill ~40 ~2 ~33 ~44 ~2 ~33 grass 0
setblock ~40 ~2 ~39 torch 5
setblock ~40 ~2 ~43 torch 5
setblock ~40 ~2 ~45 torch 5
setblock ~40 ~2 ~79 torch 5
setblock ~40 ~2 ~108 torch 5
setblock ~40 ~2 ~112 torch 5
setblock ~40 ~2 ~131 torch 5
setblock ~41 ~2 ~76 torch 5
setblock ~42 ~2 ~42 torch 5
setblock ~42 ~2 ~118 torch 5
setblock ~42 ~2 ~128 torch 5
fill ~42 ~2 ~135 ~44 ~2 ~135 wool 11
setblock ~43 ~2 ~49 torch 5
setblock ~43 ~2 ~51 torch 5
setblock ~43 ~2 ~71 torch 5
setblock ~43 ~2 ~90 torch 5
setblock ~43 ~2 ~123 torch 5
fill ~44 ~2 ~17 ~50 ~2 ~17 wool 15
setblock ~44 ~2 ~36 torch 5
fill ~44 ~2 ~70 ~44 ~2 ~82 wool 8
setblock ~44 ~2 ~132 torch 5
setblock ~45 ~2 ~18 wool 15
setblock ~45 ~2 ~134 wool 11
fill ~46 ~2 ~30 ~56 ~2 ~30 wool 15
fill ~46 ~2 ~31 ~46 ~9 ~31 wool 15
fill ~46 ~2 ~32 ~46 ~11 ~32 wool 15
fill ~46 ~2 ~51 ~53 ~2 ~51 wool 15
fill ~46 ~2 ~104 ~53 ~2 ~104 wool 15
fill ~46 ~2 ~127 ~52 ~2 ~127 wool 15
fill ~46 ~2 ~133 ~48 ~2 ~133 wool 11
fill ~47 ~2 ~99 ~48 ~2 ~99 wool 15
setblock ~47 ~2 ~130 torch 5
setblock ~48 ~2 ~62 torch 3
fill ~48 ~2 ~101 ~48 ~2 ~104 wool 15
fill ~49 ~2 ~33 ~55 ~2 ~33 wool 15
fill ~49 ~2 ~48 ~55 ~2 ~48 wool 15
fill ~49 ~2 ~62 ~49 ~2 ~64 wool 7
fill ~49 ~2 ~67 ~53 ~2 ~67 wool 7
fill ~49 ~2 ~68 ~49 ~2 ~96 wool 7
fill ~49 ~2 ~98 ~53 ~2 ~98 wool 7
fill ~49 ~2 ~108 ~55 ~2 ~108 wool 15
setblock ~49 ~2 ~110 torch 2
setblock ~49 ~2 ~121 torch 2
fill ~49 ~2 ~123 ~55 ~2 ~123 wool 15
setblock ~49 ~2 ~132 wool 11
fill ~50 ~2 ~34 ~54 ~2 ~34 dirt 0
fill ~50 ~2 ~35 ~54 ~2 ~35 wool 8
fill ~50 ~2 ~46 ~54 ~2 ~46 wool 8
fill ~50 ~2 ~47 ~54 ~2 ~47 dirt 0
fill ~50 ~2 ~64 ~52 ~2 ~64 wool 7
fill ~50 ~2 ~96 ~53 ~2 ~96 wool 7
fill ~50 ~2 ~110 ~54 ~2 ~110 wool 8
fill ~50 ~2 ~121 ~54 ~2 ~121 wool 8
setblock ~50 ~2 ~131 wool 11
setblock ~51 ~2 ~18 wool 15
fill ~51 ~2 ~37 ~51 ~9 ~37 wool 7
fill ~51 ~2 ~38 ~51 ~9 ~38 wool 7
fill ~51 ~2 ~43 ~51 ~3 ~43 wool 7
fill ~51 ~2 ~44 ~51 ~9 ~44 wool 7
fill ~51 ~2 ~112 ~51 ~9 ~112 wool 7
fill ~51 ~2 ~113 ~51 ~9 ~113 wool 7
fill ~51 ~2 ~118 ~51 ~9 ~118 wool 7
fill ~51 ~2 ~119 ~51 ~9 ~119 wool 7
setblock ~51 ~2 ~128 torch 2
fill ~51 ~2 ~129 ~51 ~2 ~130 wool 11
setblock ~52 ~2 ~19 wool 15
fill ~52 ~2 ~38 ~52 ~2 ~39 wool 8
fill ~52 ~2 ~42 ~52 ~3 ~42 wool 8
fill ~52 ~2 ~43 ~52 ~2 ~42 wool 8
setblock ~52 ~2 ~128 wool 11
fill ~53 ~2 ~20 ~53 ~2 ~21 wool 15
setblock ~53 ~2 ~97 wool 15
fill ~53 ~2 ~127 ~53 ~3 ~127 wool 11
fill ~54 ~2 ~22 ~54 ~2 ~26 wool 15
fill ~54 ~2 ~51 ~54 ~2 ~64 wool 11
fill ~54 ~2 ~65 ~54 ~2 ~96 wool 15
fill ~54 ~2 ~97 ~54 ~2 ~105 wool 11
fill ~55 ~2 ~26 ~55 ~2 ~27 wool 15
fill ~55 ~2 ~47 ~55 ~3 ~47 wool 15
fill ~55 ~2 ~122 ~55 ~3 ~122 wool 15
fill ~56 ~2 ~27 ~56 ~2 ~30 wool 15
fill ~6 ~3 ~32 ~12 ~3 ~32 wool 15
fill ~6 ~3 ~33 ~6 ~10 ~33 wool 15
fill ~6 ~3 ~48 ~6 ~10 ~48 wool 15
fill ~6 ~3 ~49 ~12 ~3 ~49 wool 15
fill ~6 ~3 ~51 ~6 ~3 ~63 wool 0
fill ~6 ~3 ~65 ~6 ~3 ~96 wool 0
fill ~6 ~3 ~98 ~6 ~3 ~105 wool 0
fill ~6 ~3 ~107 ~12 ~3 ~107 wool 15
fill ~6 ~3 ~108 ~6 ~10 ~108 wool 15
fill ~6 ~3 ~123 ~6 ~8 ~123 wool 15
fill ~6 ~3 ~124 ~12 ~3 ~124 wool 15
fill ~7 ~3 ~33 ~11 ~3 ~33 dirt 0
fill ~7 ~3 ~34 ~11 ~3 ~34 dirt 0
fill ~7 ~3 ~35 ~11 ~3 ~35 wool 8
fill ~7 ~3 ~46 ~11 ~3 ~46 wool 8
fill ~7 ~3 ~47 ~11 ~3 ~47 dirt 0
fill ~7 ~3 ~48 ~11 ~3 ~48 dirt 0
fill ~7 ~3 ~51 ~14 ~3 ~51 wool 15
fill ~7 ~3 ~63 ~12 ~3 ~63 wool 7
fill ~7 ~3 ~64 ~7 ~4 ~64 wool 15
fill ~7 ~3 ~65 ~12 ~3 ~65 wool 7
fill ~7 ~3 ~66 ~13 ~3 ~66 wool 7
fill ~7 ~3 ~96 ~11 ~3 ~96 dirt 0
fill ~7 ~3 ~97 ~7 ~4 ~97 wool 15
fill ~7 ~3 ~98 ~7 ~6 ~98 wool 15
fill ~7 ~3 ~99 ~13 ~3 ~99 wool 7
fill ~7 ~3 ~105 ~16 ~3 ~105 wool 15
fill ~7 ~3 ~110 ~11 ~3 ~110 wool 8
fill ~7 ~3 ~121 ~11 ~3 ~121 wool 8
fill ~8 ~3 ~28 ~8 ~17 ~28 wool 11
fill ~8 ~3 ~29 ~8 ~17 ~29 wool 11
fill ~8 ~3 ~30 ~15 ~3 ~30 wool 15
setblock ~8 ~3 ~36 wool 8
setblock ~8 ~3 ~45 wool 8
fill ~8 ~3 ~97 ~13 ~3 ~97 wool 7
setblock ~8 ~3 ~98 torch 1
fill ~8 ~3 ~108 ~11 ~3 ~108 dirt 0
fill ~8 ~3 ~123 ~8 ~5 ~123 gravel 0
setblock ~8 ~3 ~128 wool 11
fill ~9 ~3 ~25 ~9 ~7 ~25 wool 11
fill ~9 ~3 ~26 ~9 ~6 ~26 wool 11
fill ~9 ~3 ~27 ~9 ~3 ~25 wool 11
fill ~9 ~3 ~29 ~16 ~3 ~29 grass 0
fill ~9 ~3 ~37 ~9 ~5 ~37 wool 8
fill ~9 ~3 ~44 ~9 ~5 ~44 wool 8
fill ~9 ~3 ~112 ~9 ~3 ~114 wool 8
fill ~9 ~3 ~117 ~9 ~4 ~117 wool 8
setblock ~9 ~3 ~123 torch 4
fill ~9 ~3 ~127 ~15 ~3 ~127 wool 15
fill ~9 ~3 ~129 ~9 ~3 ~130 wool 11
fill ~10 ~3 ~21 ~12 ~3 ~21 wool 11
fill ~10 ~3 ~22 ~10 ~3 ~24 wool 11
fill ~10 ~3 ~25 ~51 ~3 ~25 grass 0
fill ~10 ~3 ~26 ~51 ~3 ~26 grass 0
fill ~10 ~3 ~118 ~10 ~9 ~118 wool 7
fill ~10 ~3 ~119 ~10 ~9 ~119 wool 7
fill ~10 ~3 ~123 ~11 ~3 ~123 dirt 0
fill ~10 ~3 ~131 ~10 ~4 ~131 wool 11
fill ~11 ~3 ~20 ~12 ~3 ~20 wool 11
fill ~11 ~3 ~22 ~12 ~3 ~22 grass 0
fill ~11 ~3 ~23 ~51 ~3 ~23 grass 0
fill ~11 ~3 ~24 ~51 ~3 ~24 grass 0
fill ~11 ~3 ~132 ~11 ~5 ~132 wool 11
fill ~12 ~3 ~33 ~12 ~9 ~33 wool 15
fill ~12 ~3 ~48 ~12 ~10 ~48 wool 15
fill ~12 ~3 ~108 ~12 ~10 ~108 wool 15
fill ~12 ~3 ~123 ~12 ~10 ~123 wool 15
fill ~12 ~3 ~133 ~13 ~3 ~133 wool 11
fill ~13 ~3 ~22 ~14 ~3 ~22 wool 11
setblock ~13 ~3 ~60 wool 7
fill ~13 ~3 ~67 ~13 ~7 ~67 wool 7
fill ~13 ~3 ~68 ~13 ~6 ~68 wool 7
fill ~13 ~3 ~69 ~13 ~4 ~69 wool 7
fill ~13 ~3 ~70 ~13 ~3 ~97 wool 7
fill ~13 ~3 ~100 ~13 ~9 ~100 wool 7
fill ~13 ~3 ~134 ~15 ~3 ~134 wool 11
fill ~14 ~3 ~19 ~14 ~5 ~19 wool 11
fill ~14 ~3 ~20 ~14 ~3 ~22 wool 11
fill ~14 ~3 ~60 ~28 ~3 ~60 wool 15
fill ~14 ~3 ~101 ~25 ~3 ~101 wool 15
fill ~15 ~3 ~14 ~15 ~3 ~18 wool 8
fill ~15 ~3 ~19 ~15 ~3 ~26 grass 0
fill ~15 ~3 ~135 ~17 ~3 ~135 wool 11
fill ~16 ~3 ~19 ~16 ~5 ~19 wool 11
fill ~16 ~3 ~20 ~47 ~3 ~20 grass 0
fill ~16 ~3 ~21 ~47 ~3 ~21 grass 0
fill ~16 ~3 ~22 ~47 ~3 ~22 grass 0
fill ~16 ~3 ~70 ~16 ~7 ~70 wool 15
fill ~16 ~3 ~71 ~16 ~3 ~83 wool 15
fill ~17 ~3 ~18 ~17 ~5 ~18 wool 11
fill ~17 ~3 ~19 ~44 ~3 ~19 grass 0
fill ~17 ~3 ~30 ~17 ~3 ~32 grass 0
fill ~17 ~3 ~69 ~26 ~3 ~69 wool 15
setblock ~17 ~3 ~70 dirt 0
setblock ~17 ~3 ~82 dirt 0
fill ~17 ~3 ~83 ~26 ~3 ~83 wool 15
fill ~18 ~3 ~17 ~22 ~3 ~17 wool 11
fill ~18 ~3 ~18 ~43 ~3 ~18 grass 0
fill ~18 ~3 ~52 ~18 ~3 ~53 dirt 0
fill ~18 ~3 ~136 ~20 ~3 ~136 wool 11
setblock ~19 ~3 ~28 torch 5
fill ~19 ~3 ~51 ~27 ~3 ~51 wool 11
fill ~19 ~3 ~52 ~27 ~3 ~52 wool 11
setblock ~20 ~3 ~31 torch 5
fill ~21 ~3 ~136 ~23 ~3 ~136 wool 7
fill ~23 ~3 ~16 ~29 ~3 ~16 wool 0
fill ~23 ~3 ~17 ~38 ~3 ~17 grass 0
setblock ~23 ~3 ~28 torch 5
setblock ~24 ~3 ~70 dirt 0
setblock ~24 ~3 ~82 dirt 0
fill ~24 ~3 ~137 ~37 ~3 ~137 wool 7
setblock ~25 ~3 ~31 torch 5
fill ~26 ~3 ~70 ~26 ~7 ~70 wool 15
fill ~26 ~3 ~71 ~26 ~7 ~71 wool 15
fill ~26 ~3 ~72 ~26 ~6 ~72 wool 15
fill ~26 ~3 ~73 ~26 ~6 ~73 wool 15
fill ~26 ~3 ~74 ~26 ~6 ~74 wool 15
fill ~26 ~3 ~75 ~26 ~6 ~75 wool 15
fill ~26 ~3 ~76 ~26 ~6 ~76 wool 15
fill ~26 ~3 ~77 ~26 ~6 ~77 wool 15
fill ~26 ~3 ~78 ~26 ~6 ~78 wool 15
fill ~26 ~3 ~79 ~26 ~6 ~79 wool 15
fill ~26 ~3 ~80 ~26 ~6 ~80 wool 15
fill ~26 ~3 ~81 ~26 ~6 ~81 wool 15
fill ~26 ~3 ~82 ~26 ~6 ~82 wool 15
fill ~26 ~3 ~99 ~26 ~12 ~99 wool 15
fill ~26 ~3 ~100 ~26 ~12 ~100 wool 15
setblock ~27 ~3 ~53 dirt 0
setblock ~28 ~3 ~28 torch 5
setblock ~28 ~3 ~52 dirt 0
fill ~28 ~3 ~69 ~28 ~5 ~69 wool 15
fill ~28 ~3 ~70 ~28 ~6 ~70 wool 15
fill ~28 ~3 ~71 ~28 ~7 ~71 wool 15
fill ~28 ~3 ~72 ~28 ~8 ~72 wool 15
fill ~28 ~3 ~73 ~28 ~8 ~73 wool 15
fill ~28 ~3 ~74 ~28 ~8 ~74 wool 15
fill ~28 ~3 ~75 ~28 ~8 ~75 wool 15
fill ~28 ~3 ~76 ~28 ~8 ~76 wool 15
fill ~28 ~3 ~77 ~28 ~8 ~77 wool 15
fill ~28 ~3 ~78 ~28 ~8 ~78 wool 15
fill ~28 ~3 ~79 ~28 ~8 ~79 wool 15
fill ~28 ~3 ~80 ~28 ~8 ~80 wool 15
fill ~28 ~3 ~81 ~28 ~8 ~81 wool 15
fill ~28 ~3 ~82 ~28 ~8 ~82 wool 15
fill ~28 ~3 ~83 ~28 ~8 ~83 wool 15
fill ~28 ~3 ~84 ~28 ~8 ~84 wool 15
fill ~28 ~3 ~85 ~28 ~8 ~85 wool 15
fill ~28 ~3 ~86 ~28 ~8 ~86 wool 15
fill ~28 ~3 ~87 ~28 ~8 ~87 wool 15
fill ~28 ~3 ~88 ~28 ~8 ~88 wool 15
fill ~28 ~3 ~89 ~28 ~8 ~89 wool 15
fill ~28 ~3 ~90 ~28 ~9 ~90 wool 15
fill ~28 ~3 ~91 ~28 ~10 ~91 wool 15
fill ~28 ~3 ~92 ~28 ~10 ~92 wool 15
fill ~28 ~3 ~93 ~28 ~14 ~93 wool 15
fill ~28 ~3 ~94 ~28 ~15 ~94 wool 15
setblock ~29 ~3 ~31 torch 5
setblock ~29 ~3 ~60 dirt 0
setblock ~29 ~3 ~61 wool 15
setblock ~29 ~3 ~68 wool 15
fill ~30 ~3 ~16 ~31 ~3 ~16 wool 11
setblock ~30 ~3 ~28 torch 5
setblock ~30 ~3 ~33 torch 5
setblock ~30 ~3 ~62 torch 1
setblock ~31 ~3 ~29 torch 5
fill ~32 ~3 ~16 ~38 ~3 ~16 wool 0
setblock ~32 ~3 ~60 dirt 0
fill ~32 ~3 ~61 ~32 ~2 ~61 wool 15
fill ~32 ~3 ~68 ~32 ~3 ~69 wool 15
setblock ~33 ~3 ~52 dirt 0
fill ~33 ~3 ~60 ~47 ~3 ~60 wool 15
fill ~33 ~3 ~69 ~33 ~5 ~69 wool 15
fill ~33 ~3 ~70 ~33 ~6 ~70 wool 15
fill ~33 ~3 ~71 ~33 ~7 ~71 wool 15
fill ~33 ~3 ~72 ~33 ~7 ~72 wool 15
fill ~33 ~3 ~73 ~33 ~8 ~73 wool 15
fill ~33 ~3 ~74 ~33 ~8 ~74 wool 15
fill ~33 ~3 ~75 ~33 ~8 ~75 wool 15
fill ~33 ~3 ~76 ~33 ~8 ~76 wool 15
fill ~33 ~3 ~77 ~33 ~8 ~77 wool 15
fill ~33 ~3 ~78 ~33 ~8 ~78 wool 15
fill ~33 ~3 ~79 ~33 ~8 ~79 wool 15
fill ~33 ~3 ~80 ~33 ~8 ~80 wool 15
fill ~33 ~3 ~81 ~33 ~8 ~81 wool 15
fill ~33 ~3 ~82 ~33 ~8 ~82 wool 15
fill ~33 ~3 ~83 ~33 ~9 ~83 wool 15
fill ~33 ~3 ~84 ~33 ~9 ~84 wool 15
fill ~33 ~3 ~85 ~33 ~8 ~85 wool 15
fill ~33 ~3 ~86 ~33 ~8 ~86 wool 15
fill ~33 ~3 ~87 ~33 ~8 ~87 wool 15
fill ~33 ~3 ~88 ~33 ~8 ~88 wool 15
fill ~33 ~3 ~89 ~33 ~8 ~89 wool 15
fill ~33 ~3 ~90 ~33 ~10 ~90 wool 15
fill ~33 ~3 ~91 ~33 ~16 ~91 wool 15
fill ~33 ~3 ~92 ~33 ~19 ~92 wool 15
fill ~33 ~3 ~93 ~33 ~14 ~93 wool 15
fill ~33 ~3 ~94 ~33 ~14 ~94 wool 15
setblock ~34 ~3 ~32 torch 5
fill ~34 ~3 ~51 ~42 ~3 ~51 wool 11
fill ~34 ~3 ~52 ~42 ~3 ~52 wool 11
fill ~35 ~3 ~69 ~44 ~3 ~69 wool 15
fill ~35 ~3 ~70 ~35 ~6 ~70 wool 15
fill ~35 ~3 ~71 ~35 ~6 ~71 wool 15
fill ~35 ~3 ~72 ~35 ~6 ~72 wool 15
fill ~35 ~3 ~73 ~35 ~6 ~73 wool 15
fill ~35 ~3 ~74 ~35 ~6 ~74 wool 15
fill ~35 ~3 ~75 ~35 ~6 ~75 wool 15
fill ~35 ~3 ~76 ~35 ~6 ~76 wool 15
fill ~35 ~3 ~77 ~35 ~6 ~77 wool 15
fill ~35 ~3 ~78 ~35 ~6 ~78 wool 15
fill ~35 ~3 ~79 ~35 ~6 ~79 wool 15
fill ~35 ~3 ~80 ~35 ~6 ~80 wool 15
fill ~35 ~3 ~81 ~35 ~6 ~81 wool 15
fill ~35 ~3 ~82 ~35 ~6 ~82 wool 15
fill ~35 ~3 ~83 ~45 ~3 ~83 wool 15
fill ~35 ~3 ~99 ~35 ~12 ~99 wool 15
fill ~35 ~3 ~100 ~35 ~12 ~100 wool 15
fill ~36 ~3 ~101 ~47 ~3 ~101 wool 15
setblock ~37 ~3 ~29 torch 5
setblock ~37 ~3 ~70 dirt 0
setblock ~37 ~3 ~82 dirt 0
fill ~38 ~3 ~136 ~40 ~3 ~136 wool 7
fill ~39 ~3 ~17 ~43 ~3 ~17 wool 11
setblock ~41 ~3 ~29 torch 5
fill ~41 ~3 ~136 ~43 ~3 ~136 wool 11
setblock ~42 ~3 ~31 torch 5
setblock ~42 ~3 ~50 dirt 0
setblock ~43 ~3 ~51 dirt 0
fill ~44 ~3 ~18 ~44 ~5 ~18 wool 11
setblock ~44 ~3 ~70 dirt 0
setblock ~44 ~3 ~82 dirt 0
setblock ~44 ~3 ~105 torch 2
setblock ~44 ~3 ~109 torch 2
setblock ~44 ~3 ~112 torch 2
setblock ~44 ~3 ~115 torch 2
setblock ~44 ~3 ~119 torch 2
setblock ~44 ~3 ~123 torch 2
setblock ~44 ~3 ~125 torch 2
fill ~44 ~3 ~135 ~46 ~3 ~135 wool 11
fill ~45 ~3 ~19 ~45 ~5 ~19 wool 11
fill ~45 ~3 ~29 ~52 ~3 ~29 grass 0
setblock ~45 ~3 ~42 torch 2
setblock ~45 ~3 ~47 torch 2
fill ~45 ~3 ~70 ~45 ~4 ~70 wool 15
fill ~45 ~3 ~71 ~45 ~3 ~83 wool 15
fill ~46 ~3 ~14 ~46 ~3 ~18 wool 8
setblock ~46 ~3 ~19 grass 0
setblock ~46 ~3 ~28 torch 5
fill ~46 ~3 ~30 ~54 ~3 ~30 wool 15
fill ~46 ~3 ~104 ~54 ~3 ~104 wool 15
fill ~46 ~3 ~127 ~52 ~3 ~127 wool 15
fill ~46 ~3 ~134 ~48 ~3 ~134 wool 11
fill ~47 ~3 ~18 ~50 ~3 ~18 wool 11
setblock ~47 ~3 ~19 dirt 0
fill ~47 ~3 ~51 ~54 ~3 ~51 wool 15
fill ~47 ~3 ~102 ~47 ~4 ~102 wool 15
fill ~48 ~3 ~19 ~51 ~3 ~19 wool 11
fill ~48 ~3 ~20 ~48 ~4 ~20 wool 11
fill ~48 ~3 ~61 ~48 ~3 ~62 wool 7
fill ~48 ~3 ~66 ~54 ~3 ~66 wool 7
fill ~48 ~3 ~67 ~48 ~7 ~67 wool 7
fill ~48 ~3 ~68 ~48 ~6 ~68 wool 7
fill ~48 ~3 ~69 ~48 ~4 ~69 wool 7
fill ~48 ~3 ~70 ~49 ~3 ~70 wool 7
fill ~48 ~3 ~71 ~49 ~3 ~71 wool 7
fill ~48 ~3 ~72 ~49 ~3 ~72 wool 7
fill ~48 ~3 ~73 ~49 ~3 ~73 wool 7
fill ~48 ~3 ~74 ~49 ~3 ~74 wool 7
fill ~48 ~3 ~75 ~49 ~3 ~75 wool 7
fill ~48 ~3 ~76 ~49 ~3 ~76 wool 7
fill ~48 ~3 ~77 ~49 ~3 ~77 wool 7
fill ~48 ~3 ~78 ~49 ~3 ~78 wool 7
fill ~48 ~3 ~79 ~49 ~3 ~79 wool 7
fill ~48 ~3 ~80 ~49 ~3 ~80 wool 7
fill ~48 ~3 ~81 ~49 ~3 ~81 wool 7
fill ~48 ~3 ~82 ~49 ~3 ~82 wool 7
fill ~48 ~3 ~83 ~49 ~3 ~83 wool 7
fill ~48 ~3 ~84 ~48 ~3 ~97 wool 7
fill ~48 ~3 ~99 ~54 ~3 ~99 wool 7
fill ~48 ~3 ~100 ~48 ~9 ~100 wool 7
fill ~48 ~3 ~103 ~48 ~4 ~103 wool 15
fill ~48 ~3 ~133 ~49 ~3 ~133 wool 11
fill ~49 ~3 ~20 ~50 ~3 ~20 grass 0
fill ~49 ~3 ~21 ~50 ~3 ~21 grass 0
fill ~49 ~3 ~22 ~51 ~3 ~22 grass 0
fill ~49 ~3 ~32 ~55 ~3 ~32 wool 15
fill ~49 ~3 ~33 ~49 ~10 ~33 wool 15
fill ~49 ~3 ~48 ~49 ~5 ~48 wool 15
fill ~49 ~3 ~49 ~55 ~3 ~49 wool 15
fill ~49 ~3 ~63 ~54 ~3 ~63 wool 7
fill ~49 ~3 ~65 ~54 ~3 ~65 wool 7
fill ~49 ~3 ~97 ~53 ~3 ~97 wool 7
fill ~49 ~3 ~107 ~55 ~3 ~107 wool 15
fill ~49 ~3 ~108 ~49 ~10 ~108 wool 15
fill ~49 ~3 ~123 ~49 ~7 ~123 wool 15
fill ~49 ~3 ~124 ~55 ~3 ~124 wool 15
setblock ~50 ~3 ~28 torch 5
fill ~50 ~3 ~33 ~54 ~3 ~33 dirt 0
fill ~50 ~3 ~34 ~54 ~3 ~34 dirt 0
fill ~50 ~3 ~35 ~54 ~3 ~35 wool 8
fill ~50 ~3 ~46 ~54 ~3 ~46 wool 8
fill ~50 ~3 ~47 ~54 ~3 ~47 dirt 0
fill ~50 ~3 ~48 ~54 ~3 ~48 dirt 0
setblock ~50 ~3 ~108 dirt 0
fill ~50 ~3 ~110 ~54 ~3 ~110 wool 8
fill ~50 ~3 ~121 ~54 ~3 ~121 wool 8
fill ~50 ~3 ~132 ~50 ~5 ~132 wool 11
fill ~51 ~3 ~20 ~52 ~3 ~20 wool 11
setblock ~51 ~3 ~21 dirt 0
fill ~51 ~3 ~131 ~51 ~4 ~131 wool 11
fill ~52 ~3 ~21 ~52 ~3 ~24 wool 11
fill ~52 ~3 ~25 ~52 ~3 ~26 dirt 0
setblock ~52 ~3 ~27 grass 0
fill ~52 ~3 ~37 ~52 ~4 ~37 wool 14
fill ~52 ~3 ~39 ~52 ~3 ~42 wool 8
setblock ~52 ~3 ~98 torch 5
setblock ~52 ~3 ~108 torch 3
fill ~52 ~3 ~112 ~52 ~4 ~112 wool 14
fill ~52 ~3 ~129 ~52 ~3 ~130 wool 11
fill ~53 ~3 ~22 ~53 ~3 ~27 wool 11
fill ~53 ~3 ~28 ~53 ~3 ~29 dirt 0
setblock ~53 ~3 ~128 wool 11
fill ~54 ~3 ~27 ~54 ~3 ~29 wool 11
fill ~54 ~3 ~64 ~54 ~4 ~64 wool 15
fill ~54 ~3 ~97 ~54 ~4 ~97 wool 15
fill ~54 ~3 ~98 ~54 ~6 ~98 wool 15
setblock ~54 ~3 ~108 torch 3
fill ~55 ~3 ~28 ~55 ~3 ~30 wool 11
fill ~55 ~3 ~33 ~55 ~10 ~33 wool 15
fill ~55 ~3 ~48 ~55 ~10 ~48 wool 15
fill ~55 ~3 ~51 ~55 ~3 ~63 wool 0
fill ~55 ~3 ~65 ~55 ~3 ~96 wool 0
fill ~55 ~3 ~98 ~55 ~3 ~105 wool 0
fill ~55 ~3 ~108 ~55 ~10 ~108 wool 15
fill ~55 ~3 ~123 ~55 ~10 ~123 wool 15
fill ~6 ~4 ~28 ~8 ~4 ~28 wool 11
fill ~6 ~4 ~29 ~8 ~4 ~29 wool 11
fill ~6 ~4 ~30 ~7 ~4 ~30 wool 11
fill ~6 ~4 ~32 ~12 ~4 ~32 wool 15
fill ~6 ~4 ~49 ~12 ~4 ~49 wool 15
fill ~6 ~4 ~51 ~6 ~4 ~63 wool 11
fill ~6 ~4 ~65 ~6 ~4 ~96 wool 11
fill ~6 ~4 ~98 ~6 ~4 ~105 wool 11
fill ~6 ~4 ~107 ~12 ~4 ~107 wool 15
fill ~6 ~4 ~124 ~12 ~4 ~124 wool 15
fill ~7 ~4 ~27 ~8 ~4 ~27 wool 11
fill ~7 ~4 ~33 ~11 ~4 ~33 dirt 0
fill ~7 ~4 ~34 ~11 ~4 ~34 wool 8
fill ~7 ~4 ~47 ~11 ~4 ~47 wool 8
fill ~7 ~4 ~48 ~11 ~4 ~48 dirt 0
fill ~7 ~4 ~51 ~14 ~4 ~51 wool 15
setblock ~7 ~4 ~52 torch 1
setblock ~7 ~4 ~55 torch 1
setblock ~7 ~4 ~61 torch 1
fill ~7 ~4 ~63 ~12 ~4 ~63 wool 7
fill ~7 ~4 ~65 ~12 ~4 ~65 wool 7
fill ~7 ~4 ~66 ~13 ~4 ~66 wool 7
setblock ~7 ~4 ~68 torch 1
setblock ~7 ~4 ~72 torch 1
setblock ~7 ~4 ~78 torch 1
setblock ~7 ~4 ~82 torch 1
setblock ~7 ~4 ~87 torch 1
setblock ~7 ~4 ~92 torch 1
fill ~7 ~4 ~96 ~12 ~4 ~96 dirt 0
fill ~7 ~4 ~99 ~13 ~4 ~99 wool 7
setblock ~7 ~4 ~102 torch 1
fill ~7 ~4 ~105 ~16 ~4 ~105 wool 15
fill ~7 ~4 ~109 ~11 ~4 ~109 wool 8
fill ~7 ~4 ~122 ~11 ~4 ~122 wool 8
fill ~7 ~4 ~127 ~7 ~10 ~127 wool 11
fill ~7 ~4 ~128 ~7 ~10 ~128 wool 11
fill ~8 ~4 ~30 ~14 ~4 ~30 wool 15
setblock ~8 ~4 ~35 wool 8
fill ~8 ~4 ~40 ~8 ~4 ~41 wool 8
setblock ~8 ~4 ~46 wool 8
fill ~8 ~4 ~97 ~13 ~4 ~97 wool 7
fill ~8 ~4 ~108 ~11 ~4 ~108 dirt 0
fill ~8 ~4 ~115 ~8 ~4 ~116 wool 8
fill ~8 ~4 ~127 ~15 ~4 ~127 wool 15
fill ~8 ~4 ~129 ~8 ~6 ~129 wool 11
fill ~8 ~4 ~130 ~8 ~10 ~130 wool 11
fill ~9 ~4 ~22 ~9 ~8 ~22 wool 11
fill ~9 ~4 ~23 ~9 ~8 ~23 wool 11
fill ~9 ~4 ~24 ~9 ~7 ~24 wool 11
setblock ~9 ~4 ~36 wool 8
fill ~9 ~4 ~38 ~9 ~5 ~38 wool 8
fill ~9 ~4 ~43 ~9 ~5 ~43 wool 8
setblock ~9 ~4 ~45 wool 8
fill ~9 ~4 ~111 ~9 ~6 ~111 wool 14
fill ~9 ~4 ~112 ~9 ~5 ~112 wool 14
setblock ~9 ~4 ~114 wool 8
setblock ~9 ~4 ~129 torch 1
fill ~9 ~4 ~131 ~9 ~7 ~131 wool 11
fill ~10 ~4 ~19 ~14 ~4 ~19 wool 11
fill ~10 ~4 ~20 ~10 ~5 ~20 wool 11
fill ~10 ~4 ~21 ~10 ~5 ~21 wool 11
setblock ~10 ~4 ~29 torch 5
fill ~10 ~4 ~36 ~10 ~7 ~36 wool 7
fill ~10 ~4 ~45 ~10 ~7 ~45 wool 7
fill ~10 ~4 ~111 ~10 ~7 ~111 wool 7
fill ~10 ~4 ~112 ~10 ~9 ~112 wool 7
fill ~10 ~4 ~113 ~10 ~9 ~113 wool 7
fill ~10 ~4 ~120 ~10 ~7 ~120 wool 7
fill ~11 ~4 ~18 ~13 ~4 ~18 wool 11
fill ~11 ~4 ~40 ~11 ~7 ~40 cobblestone 0
fill ~11 ~4 ~41 ~11 ~7 ~41 cobblestone 0
setblock ~11 ~4 ~82 torch 2
setblock ~11 ~4 ~123 dirt 0
setblock ~12 ~4 ~17 wool 11
setblock ~12 ~4 ~25 torch 5
fill ~12 ~4 ~70 ~12 ~5 ~70 wool 11
fill ~12 ~4 ~71 ~12 ~4 ~83 wool 11
fill ~12 ~4 ~84 ~12 ~4 ~85 wool 7
setblock ~12 ~4 ~89 torch 2
setblock ~12 ~4 ~92 torch 2
fill ~12 ~4 ~132 ~13 ~4 ~132 glowstone 0
fill ~13 ~4 ~20 ~13 ~4 ~22 wool 11
fill ~13 ~4 ~86 ~13 ~4 ~97 wool 7
fill ~13 ~4 ~102 ~25 ~4 ~102 wool 15
fill ~14 ~4 ~14 ~14 ~4 ~18 wool 8
fill ~14 ~4 ~61 ~18 ~4 ~61 wool 15
fill ~14 ~4 ~101 ~14 ~9 ~101 wool 7
fill ~14 ~4 ~133 ~14 ~5 ~133 wool 8
fill ~14 ~4 ~134 ~14 ~5 ~134 wool 11
fill ~15 ~4 ~18 ~16 ~4 ~18 wool 8
setblock ~15 ~4 ~23 torch 5
fill ~15 ~4 ~71 ~15 ~17 ~71 wool 15
fill ~15 ~4 ~72 ~15 ~14 ~72 wool 15
fill ~15 ~4 ~73 ~15 ~10 ~73 wool 15
fill ~15 ~4 ~74 ~15 ~9 ~74 wool 15
fill ~15 ~4 ~75 ~15 ~8 ~75 wool 15
fill ~15 ~4 ~76 ~15 ~9 ~76 wool 15
fill ~15 ~4 ~77 ~15 ~9 ~77 wool 15
fill ~15 ~4 ~78 ~15 ~9 ~78 wool 15
fill ~15 ~4 ~79 ~15 ~9 ~79 wool 15
fill ~15 ~4 ~80 ~15 ~9 ~80 wool 15
fill ~15 ~4 ~81 ~15 ~9 ~81 wool 15
fill ~15 ~4 ~82 ~16 ~4 ~82 wool 15
fill ~15 ~4 ~135 ~16 ~4 ~135 wool 11
fill ~16 ~4 ~14 ~16 ~4 ~18 wool 8
fill ~16 ~4 ~83 ~16 ~6 ~83 wool 15
fill ~16 ~4 ~84 ~26 ~4 ~84 wool 15
setblock ~16 ~4 ~134 torch 4
fill ~17 ~4 ~16 ~22 ~4 ~16 wool 11
fill ~17 ~4 ~17 ~17 ~5 ~17 wool 11
setblock ~17 ~4 ~20 torch 5
setblock ~17 ~4 ~53 dirt 0
fill ~17 ~4 ~69 ~26 ~4 ~69 wool 15
setblock ~17 ~4 ~105 torch 1
setblock ~17 ~4 ~136 wool 11
fill ~18 ~4 ~49 ~18 ~5 ~49 dirt 0
fill ~18 ~4 ~50 ~18 ~4 ~49 dirt 0
fill ~18 ~4 ~51 ~18 ~6 ~51 wool 15
fill ~18 ~4 ~52 ~18 ~5 ~52 wool 15
fill ~18 ~4 ~53 ~18 ~4 ~57 wool 15
fill ~18 ~4 ~135 ~19 ~4 ~135 wool 7
fill ~19 ~4 ~15 ~22 ~4 ~15 wool 11
setblock ~19 ~4 ~23 torch 5
fill ~19 ~4 ~50 ~27 ~4 ~50 wool 11
fill ~19 ~4 ~53 ~27 ~4 ~53 wool 11
fill ~19 ~4 ~54 ~27 ~4 ~54 wool 11
fill ~19 ~4 ~61 ~27 ~4 ~61 wool 11
fill ~20 ~4 ~14 ~20 ~5 ~14 wool 11
setblock ~20 ~4 ~25 torch 5
fill ~20 ~4 ~136 ~28 ~4 ~136 wool 7
setblock ~21 ~4 ~19 torch 5
fill ~23 ~4 ~15 ~29 ~4 ~15 wool 0
setblock ~23 ~4 ~21 torch 5
setblock ~23 ~4 ~135 torch 4
setblock ~24 ~4 ~83 dirt 0
setblock ~25 ~4 ~24 torch 5
setblock ~26 ~4 ~18 torch 5
setblock ~26 ~4 ~51 torch 5
fill ~26 ~4 ~83 ~26 ~6 ~83 wool 15
fill ~26 ~4 ~101 ~26 ~12 ~101 wool 15
fill ~27 ~4 ~13 ~27 ~5 ~13 wool 0
fill ~27 ~4 ~14 ~27 ~4 ~13 wool 0
setblock ~27 ~4 ~55 dirt 0
setblock ~28 ~4 ~50 dirt 0
fill ~28 ~4 ~51 ~28 ~6 ~51 wool 15
fill ~28 ~4 ~52 ~28 ~5 ~52 wool 15
fill ~28 ~4 ~53 ~28 ~4 ~57 wool 15
fill ~28 ~4 ~61 ~28 ~5 ~61 wool 15
setblock ~29 ~4 ~20 torch 5
setblock ~29 ~4 ~65 torch 2
fill ~29 ~4 ~69 ~33 ~4 ~69 wool 15
fill ~29 ~4 ~137 ~32 ~4 ~137 wool 7
fill ~30 ~4 ~15 ~31 ~4 ~15 wool 11
setblock ~30 ~4 ~16 torch 3
fill ~30 ~4 ~18 ~31 ~4 ~18 torch 5
setblock ~30 ~4 ~22 torch 5
setblock ~30 ~4 ~24 torch 5
fill ~30 ~4 ~39 ~31 ~4 ~39 cobblestone 0
fill ~30 ~4 ~40 ~31 ~4 ~40 cobblestone 0
fill ~30 ~4 ~41 ~31 ~4 ~41 cobblestone 0
fill ~30 ~4 ~42 ~31 ~4 ~42 cobblestone 0
fill ~30 ~4 ~62 ~32 ~4 ~62 wool 15
fill ~30 ~4 ~63 ~31 ~4 ~63 wool 15
fill ~30 ~4 ~64 ~31 ~4 ~64 wool 15
fill ~30 ~4 ~65 ~31 ~4 ~65 wool 15
fill ~30 ~4 ~66 ~31 ~4 ~66 wool 15
fill ~30 ~4 ~67 ~31 ~4 ~67 wool 15
fill ~30 ~4 ~68 ~31 ~4 ~68 wool 15
fill ~30 ~4 ~136 ~31 ~4 ~136 torch 4
setblock ~31 ~4 ~61 dirt 0
fill ~32 ~4 ~15 ~38 ~4 ~15 wool 0
setblock ~32 ~4 ~53 dirt 0
setblock ~33 ~4 ~50 dirt 0
fill ~33 ~4 ~51 ~33 ~6 ~51 wool 15
fill ~33 ~4 ~52 ~33 ~5 ~52 wool 15
fill ~33 ~4 ~53 ~33 ~4 ~57 wool 15
fill ~33 ~4 ~61 ~33 ~5 ~61 wool 15
fill ~33 ~4 ~136 ~41 ~4 ~136 wool 7
fill ~34 ~4 ~13 ~34 ~5 ~13 wool 0
fill ~34 ~4 ~14 ~34 ~4 ~13 wool 0
setblock ~34 ~4 ~23 torch 5
fill ~34 ~4 ~50 ~42 ~4 ~50 wool 11
setblock ~34 ~4 ~51 torch 1
fill ~34 ~4 ~53 ~42 ~4 ~53 wool 11
fill ~34 ~4 ~54 ~42 ~4 ~54 wool 11
fill ~34 ~4 ~61 ~42 ~4 ~61 wool 11
fill ~35 ~4 ~69 ~45 ~4 ~69 wool 15
fill ~35 ~4 ~83 ~35 ~6 ~83 wool 15
fill ~35 ~4 ~84 ~45 ~4 ~84 wool 15
fill ~35 ~4 ~101 ~35 ~12 ~101 wool 15
setblock ~36 ~4 ~18 torch 5
fill ~36 ~4 ~102 ~37 ~4 ~102 wool 15
setblock ~38 ~4 ~21 torch 5
fill ~38 ~4 ~101 ~38 ~5 ~101 wool 7
fill ~39 ~4 ~15 ~42 ~4 ~15 wool 11
fill ~39 ~4 ~16 ~44 ~4 ~16 wool 11
setblock ~39 ~4 ~24 torch 5
fill ~39 ~4 ~102 ~40 ~4 ~102 wool 15
fill ~41 ~4 ~14 ~41 ~5 ~14 wool 11
setblock ~41 ~4 ~19 torch 5
fill ~41 ~4 ~101 ~41 ~5 ~101 wool 7
setblock ~42 ~4 ~26 torch 5
setblock ~42 ~4 ~49 dirt 0
fill ~42 ~4 ~102 ~43 ~4 ~102 wool 15
fill ~42 ~4 ~135 ~43 ~4 ~135 wool 7
fill ~43 ~4 ~51 ~43 ~6 ~51 wool 15
fill ~43 ~4 ~52 ~43 ~5 ~52 wool 15
fill ~43 ~4 ~53 ~43 ~4 ~57 wool 15
fill ~43 ~4 ~61 ~47 ~4 ~61 wool 15
fill ~44 ~4 ~17 ~44 ~5 ~17 wool 11
setblock ~44 ~4 ~24 torch 5
fill ~44 ~4 ~52 ~44 ~5 ~52 dirt 0
setblock ~44 ~4 ~54 dirt 0
fill ~44 ~4 ~101 ~44 ~5 ~101 wool 7
setblock ~44 ~4 ~135 torch 5
setblock ~44 ~4 ~136 wool 11
fill ~45 ~4 ~14 ~45 ~4 ~18 wool 8
setblock ~45 ~4 ~37 torch 2
setblock ~45 ~4 ~83 wool 15
fill ~45 ~4 ~102 ~47 ~4 ~102 wool 15
fill ~45 ~4 ~120 ~45 ~14 ~120 wool 15
fill ~45 ~4 ~121 ~45 ~14 ~121 wool 15
fill ~45 ~4 ~122 ~45 ~13 ~122 wool 15
fill ~45 ~4 ~135 ~46 ~4 ~135 wool 11
fill ~46 ~4 ~18 ~47 ~4 ~18 wool 8
setblock ~46 ~4 ~21 torch 5
fill ~46 ~4 ~30 ~54 ~4 ~30 wool 15
fill ~46 ~4 ~70 ~46 ~20 ~70 wool 15
fill ~46 ~4 ~71 ~46 ~17 ~71 wool 15
fill ~46 ~4 ~72 ~46 ~14 ~72 wool 15
fill ~46 ~4 ~73 ~46 ~11 ~73 wool 15
fill ~46 ~4 ~74 ~46 ~9 ~74 wool 15
fill ~46 ~4 ~75 ~46 ~8 ~75 wool 15
fill ~46 ~4 ~76 ~46 ~9 ~76 wool 15
fill ~46 ~4 ~77 ~46 ~9 ~77 wool 15
fill ~46 ~4 ~78 ~46 ~9 ~78 wool 15
fill ~46 ~4 ~79 ~46 ~9 ~79 wool 15
fill ~46 ~4 ~80 ~46 ~9 ~80 wool 15
fill ~46 ~4 ~81 ~46 ~9 ~81 wool 15
fill ~46 ~4 ~82 ~46 ~9 ~82 wool 15
fill ~46 ~4 ~104 ~54 ~4 ~104 wool 15
fill ~46 ~4 ~127 ~53 ~4 ~127 wool 15
fill ~47 ~4 ~14 ~47 ~4 ~18 wool 8
fill ~47 ~4 ~19 ~50 ~4 ~19 wool 11
fill ~47 ~4 ~51 ~54 ~4 ~51 wool 15
fill ~47 ~4 ~101 ~47 ~9 ~101 wool 7
fill ~47 ~4 ~133 ~47 ~5 ~133 wool 8
fill ~47 ~4 ~134 ~47 ~5 ~134 wool 11
fill ~48 ~4 ~17 ~49 ~4 ~17 wool 11
fill ~48 ~4 ~18 ~49 ~4 ~18 wool 11
fill ~48 ~4 ~21 ~48 ~4 ~22 wool 11
setblock ~48 ~4 ~24 torch 5
setblock ~48 ~4 ~62 wool 7
fill ~48 ~4 ~66 ~54 ~4 ~66 wool 7
fill ~48 ~4 ~86 ~48 ~4 ~97 wool 7
fill ~48 ~4 ~99 ~54 ~4 ~99 wool 7
fill ~48 ~4 ~132 ~49 ~4 ~132 glowstone 0
fill ~49 ~4 ~32 ~55 ~4 ~32 wool 15
fill ~49 ~4 ~49 ~55 ~4 ~49 wool 15
fill ~49 ~4 ~63 ~54 ~4 ~63 wool 7
fill ~49 ~4 ~65 ~54 ~4 ~65 wool 7
fill ~49 ~4 ~67 ~49 ~7 ~67 wool 7
fill ~49 ~4 ~68 ~49 ~6 ~68 wool 7
fill ~49 ~4 ~69 ~49 ~4 ~65 wool 7
fill ~49 ~4 ~70 ~49 ~5 ~70 wool 11
fill ~49 ~4 ~71 ~49 ~4 ~83 wool 11
fill ~49 ~4 ~84 ~49 ~4 ~85 wool 7
fill ~49 ~4 ~97 ~53 ~4 ~97 wool 7
fill ~49 ~4 ~107 ~55 ~4 ~107 wool 15
fill ~49 ~4 ~124 ~55 ~4 ~124 wool 15
fill ~50 ~4 ~33 ~54 ~4 ~33 dirt 0
fill ~50 ~4 ~34 ~54 ~4 ~34 wool 8
fill ~50 ~4 ~40 ~50 ~7 ~40 cobblestone 0
fill ~50 ~4 ~41 ~50 ~7 ~41 cobblestone 0
fill ~50 ~4 ~47 ~54 ~4 ~47 wool 8
fill ~50 ~4 ~48 ~54 ~4 ~48 dirt 0
fill ~50 ~4 ~109 ~54 ~4 ~109 wool 8
fill ~50 ~4 ~122 ~54 ~4 ~122 wool 8
fill ~51 ~4 ~20 ~51 ~5 ~20 wool 11
fill ~51 ~4 ~21 ~51 ~5 ~21 wool 11
fill ~51 ~4 ~36 ~51 ~7 ~36 wool 7
fill ~51 ~4 ~39 ~51 ~10 ~39 wool 7
fill ~51 ~4 ~45 ~51 ~7 ~45 wool 7
fill ~51 ~4 ~111 ~51 ~7 ~111 wool 7
fill ~51 ~4 ~120 ~51 ~7 ~120 wool 7
fill ~52 ~4 ~22 ~52 ~8 ~22 wool 11
fill ~52 ~4 ~23 ~52 ~8 ~23 wool 11
fill ~52 ~4 ~24 ~52 ~7 ~24 wool 11
fill ~52 ~4 ~25 ~52 ~6 ~25 wool 11
fill ~52 ~4 ~26 ~52 ~6 ~26 wool 11
fill ~52 ~4 ~36 ~52 ~7 ~36 wool 14
fill ~52 ~4 ~111 ~52 ~7 ~111 wool 14
fill ~52 ~4 ~130 ~53 ~4 ~130 wool 11
fill ~53 ~4 ~27 ~53 ~17 ~27 wool 11
fill ~53 ~4 ~28 ~53 ~17 ~28 wool 11
fill ~53 ~4 ~29 ~54 ~4 ~29 wool 11
fill ~53 ~4 ~40 ~53 ~4 ~41 wool 8
fill ~53 ~4 ~110 ~53 ~4 ~111 wool 8
fill ~53 ~4 ~115 ~53 ~4 ~116 wool 8
fill ~53 ~4 ~120 ~53 ~5 ~120 wool 8
fill ~53 ~4 ~121 ~53 ~4 ~120 wool 8
fill ~53 ~4 ~129 ~53 ~6 ~129 wool 11
setblock ~54 ~4 ~53 torch 2
setblock ~54 ~4 ~55 torch 2
setblock ~54 ~4 ~59 torch 2
setblock ~54 ~4 ~62 torch 2
setblock ~54 ~4 ~70 torch 2
setblock ~54 ~4 ~74 torch 2
setblock ~54 ~4 ~77 torch 2
setblock ~54 ~4 ~81 torch 2
setblock ~54 ~4 ~85 torch 2
setblock ~54 ~4 ~88 torch 2
setblock ~54 ~4 ~91 torch 2
setblock ~54 ~4 ~95 torch 2
fill ~54 ~4 ~100 ~54 ~4 ~101 torch 2
fill ~54 ~4 ~127 ~54 ~4 ~128 wool 11
fill ~55 ~4 ~30 ~55 ~9 ~30 wool 11
fill ~55 ~4 ~51 ~55 ~4 ~63 wool 11
fill ~55 ~4 ~65 ~55 ~4 ~96 wool 11
fill ~55 ~4 ~98 ~55 ~4 ~105 wool 11
fill ~6 ~5 ~30 ~6 ~10 ~30 wool 11
fill ~6 ~5 ~32 ~12 ~5 ~32 wool 15
fill ~6 ~5 ~49 ~12 ~5 ~49 wool 15
fill ~6 ~5 ~51 ~6 ~5 ~62 wool 0
fill ~6 ~5 ~64 ~6 ~5 ~97 wool 0
fill ~6 ~5 ~99 ~6 ~5 ~105 wool 0
fill ~6 ~5 ~107 ~12 ~5 ~107 wool 15
fill ~6 ~5 ~124 ~12 ~5 ~124 wool 15
fill ~6 ~5 ~127 ~6 ~7 ~127 wool 11
fill ~7 ~5 ~29 ~7 ~10 ~29 wool 11
fill ~7 ~5 ~30 ~14 ~5 ~30 wool 15
fill ~7 ~5 ~33 ~11 ~5 ~33 dirt 0
fill ~7 ~5 ~34 ~11 ~5 ~34 wool 8
fill ~7 ~5 ~40 ~10 ~5 ~40 wool 7
fill ~7 ~5 ~41 ~10 ~5 ~41 wool 7
fill ~7 ~5 ~47 ~11 ~5 ~47 wool 8
fill ~7 ~5 ~48 ~11 ~5 ~48 dirt 0
fill ~7 ~5 ~51 ~14 ~5 ~51 wool 15
fill ~7 ~5 ~62 ~12 ~5 ~62 wool 7
fill ~7 ~5 ~63 ~7 ~6 ~63 wool 15
fill ~7 ~5 ~64 ~12 ~5 ~64 wool 7
fill ~7 ~5 ~65 ~13 ~5 ~65 wool 7
fill ~7 ~5 ~96 ~12 ~5 ~96 dirt 0
fill ~7 ~5 ~97 ~12 ~5 ~97 dirt 0
fill ~7 ~5 ~99 ~7 ~6 ~99 wool 15
fill ~7 ~5 ~100 ~13 ~5 ~100 wool 7
fill ~7 ~5 ~105 ~16 ~5 ~105 wool 15
fill ~7 ~5 ~108 ~11 ~5 ~108 dirt 0
fill ~7 ~5 ~109 ~11 ~5 ~109 wool 8
fill ~7 ~5 ~115 ~7 ~6 ~115 wool 7
fill ~7 ~5 ~116 ~7 ~6 ~116 wool 7
fill ~7 ~5 ~122 ~11 ~5 ~122 wool 8
fill ~8 ~5 ~27 ~8 ~17 ~27 wool 11
fill ~8 ~5 ~39 ~8 ~6 ~39 wool 8
fill ~8 ~5 ~42 ~8 ~6 ~42 wool 8
fill ~8 ~5 ~98 ~13 ~5 ~98 wool 7
setblock ~8 ~5 ~99 torch 1
fill ~8 ~5 ~114 ~8 ~6 ~114 wool 8
fill ~8 ~5 ~117 ~8 ~6 ~117 wool 8
fill ~8 ~5 ~127 ~15 ~5 ~127 wool 15
fill ~9 ~5 ~45 ~9 ~7 ~45 wool 14
fill ~10 ~5 ~18 ~10 ~7 ~18 wool 11
fill ~10 ~5 ~19 ~10 ~6 ~19 wool 11
setblock ~10 ~5 ~26 torch 1
fill ~10 ~5 ~132 ~10 ~7 ~132 wool 11
setblock ~11 ~5 ~17 wool 11
fill ~11 ~5 ~39 ~11 ~6 ~39 cobblestone 0
fill ~11 ~5 ~42 ~11 ~6 ~42 cobblestone 0
setblock ~11 ~5 ~72 torch 2
setblock ~11 ~5 ~77 torch 2
fill ~12 ~5 ~16 ~13 ~5 ~16 wool 11
setblock ~12 ~5 ~18 torch 5
fill ~12 ~5 ~40 ~50 ~5 ~40 cobblestone 0
fill ~12 ~5 ~41 ~50 ~5 ~41 cobblestone 0
fill ~12 ~5 ~69 ~12 ~7 ~69 wool 11
fill ~12 ~5 ~71 ~12 ~7 ~71 wool 7
fill ~12 ~5 ~72 ~12 ~6 ~72 wool 7
fill ~12 ~5 ~73 ~12 ~6 ~73 wool 7
fill ~12 ~5 ~74 ~12 ~6 ~74 wool 7
fill ~12 ~5 ~75 ~12 ~6 ~75 wool 7
fill ~12 ~5 ~76 ~12 ~6 ~76 wool 7
fill ~12 ~5 ~77 ~12 ~6 ~77 wool 7
fill ~12 ~5 ~78 ~12 ~6 ~78 wool 7
fill ~12 ~5 ~79 ~12 ~6 ~79 wool 7
fill ~12 ~5 ~80 ~12 ~6 ~80 wool 7
fill ~12 ~5 ~81 ~12 ~6 ~81 wool 7
fill ~12 ~5 ~82 ~12 ~11 ~82 wool 7
fill ~12 ~5 ~83 ~12 ~9 ~83 wool 7
fill ~12 ~5 ~84 ~12 ~5 ~85 wool 11
setblock ~12 ~5 ~86 wool 7
fill ~12 ~5 ~132 ~13 ~5 ~132 glowstone 0
fill ~13 ~5 ~17 ~13 ~5 ~18 wool 11
fill ~13 ~5 ~66 ~13 ~9 ~66 wool 7
fill ~13 ~5 ~87 ~13 ~5 ~92 wool 7
fill ~13 ~5 ~93 ~13 ~5 ~95 wool 8
fill ~13 ~5 ~96 ~13 ~5 ~98 wool 7
fill ~13 ~5 ~103 ~25 ~5 ~103 wool 15
fill ~13 ~5 ~104 ~25 ~5 ~104 wool 15
fill ~14 ~5 ~53 ~17 ~5 ~53 wool 15
fill ~14 ~5 ~54 ~17 ~5 ~54 wool 15
fill ~14 ~5 ~55 ~17 ~5 ~55 wool 15
fill ~14 ~5 ~56 ~17 ~5 ~56 wool 15
fill ~14 ~5 ~57 ~17 ~5 ~57 wool 15
fill ~14 ~5 ~61 ~18 ~5 ~61 wool 15
setblock ~14 ~5 ~94 wool 8
fill ~14 ~5 ~102 ~14 ~12 ~102 wool 7
fill ~15 ~5 ~14 ~15 ~5 ~18 wool 8
fill ~15 ~5 ~82 ~16 ~5 ~82 wool 15
fill ~15 ~5 ~83 ~15 ~8 ~83 wool 15
fill ~15 ~5 ~135 ~15 ~3 ~135 wool 11
fill ~16 ~5 ~39 ~17 ~5 ~39 cobblestone 0
fill ~16 ~5 ~84 ~16 ~6 ~84 wool 15
fill ~16 ~5 ~85 ~26 ~5 ~85 wool 15
fill ~16 ~5 ~136 ~16 ~6 ~136 wool 11
fill ~17 ~5 ~15 ~18 ~5 ~15 wool 11
fill ~17 ~5 ~16 ~17 ~4 ~16 wool 11
setblock ~17 ~5 ~52 dirt 0
setblock ~17 ~5 ~58 dirt 0
fill ~17 ~5 ~69 ~26 ~5 ~69 wool 15
setblock ~17 ~5 ~102 torch 4
setblock ~17 ~5 ~109 torch 1
fill ~17 ~5 ~136 ~24 ~5 ~136 wool 7
fill ~18 ~5 ~50 ~18 ~6 ~50 wool 15
fill ~18 ~5 ~58 ~18 ~5 ~61 wool 15
setblock ~19 ~5 ~14 wool 11
fill ~19 ~5 ~49 ~27 ~5 ~49 wool 11
fill ~19 ~5 ~55 ~27 ~5 ~55 wool 11
fill ~19 ~5 ~56 ~27 ~5 ~56 wool 11
fill ~19 ~5 ~57 ~27 ~5 ~57 wool 11
setblock ~19 ~5 ~58 dirt 0
fill ~19 ~5 ~61 ~27 ~5 ~61 wool 11
setblock ~20 ~5 ~15 torch 5
fill ~21 ~5 ~14 ~22 ~5 ~14 wool 11
fill ~23 ~5 ~14 ~26 ~5 ~14 wool 0
setblock ~23 ~5 ~102 torch 4
setblock ~24 ~5 ~84 dirt 0
setblock ~25 ~5 ~136 torch 4
fill ~25 ~5 ~137 ~36 ~5 ~137 wool 7
fill ~26 ~5 ~84 ~26 ~6 ~84 wool 15
fill ~26 ~5 ~102 ~26 ~8 ~102 wool 15
setblock ~27 ~5 ~58 dirt 0
fill ~28 ~5 ~13 ~29 ~5 ~13 wool 0
fill ~28 ~5 ~14 ~29 ~5 ~14 wool 0
fill ~28 ~5 ~50 ~28 ~7 ~50 wool 15
fill ~28 ~5 ~58 ~28 ~5 ~61 wool 15
fill ~29 ~5 ~39 ~32 ~5 ~39 cobblestone 0
fill ~29 ~5 ~42 ~32 ~5 ~42 cobblestone 0
setblock ~29 ~5 ~52 dirt 0
fill ~29 ~5 ~53 ~32 ~5 ~53 wool 15
fill ~29 ~5 ~54 ~32 ~5 ~54 wool 15
fill ~29 ~5 ~55 ~32 ~5 ~55 wool 15
fill ~29 ~5 ~56 ~32 ~5 ~56 wool 15
fill ~29 ~5 ~57 ~32 ~5 ~57 wool 15
setblock ~29 ~5 ~58 dirt 0
fill ~29 ~5 ~61 ~33 ~5 ~61 wool 15
fill ~29 ~5 ~69 ~33 ~5 ~69 wool 15
setblock ~29 ~5 ~85 torch 1
setblock ~29 ~5 ~87 torch 1
setblock ~29 ~5 ~89 torch 1
setblock ~29 ~5 ~92 torch 1
fill ~30 ~5 ~13 ~31 ~5 ~13 wool 11
fill ~30 ~5 ~14 ~31 ~5 ~14 wool 11
setblock ~30 ~5 ~15 torch 3
fill ~30 ~5 ~38 ~31 ~5 ~38 cobblestone 0
fill ~31 ~5 ~43 ~31 ~6 ~43 cobblestone 0
fill ~32 ~5 ~13 ~34 ~5 ~13 wool 0
fill ~32 ~5 ~14 ~33 ~5 ~14 wool 0
setblock ~32 ~5 ~52 dirt 0
setblock ~32 ~5 ~58 dirt 0
setblock ~32 ~5 ~82 torch 2
setblock ~32 ~5 ~85 torch 2
setblock ~32 ~5 ~88 torch 2
setblock ~33 ~5 ~49 dirt 0
fill ~33 ~5 ~50 ~33 ~7 ~50 wool 15
fill ~33 ~5 ~58 ~33 ~5 ~61 wool 15
fill ~34 ~5 ~49 ~42 ~5 ~49 wool 11
fill ~34 ~5 ~55 ~42 ~5 ~55 wool 11
fill ~34 ~5 ~56 ~42 ~5 ~56 wool 11
fill ~34 ~5 ~57 ~42 ~5 ~57 wool 11
setblock ~34 ~5 ~58 dirt 0
fill ~34 ~5 ~61 ~42 ~5 ~61 wool 11
fill ~35 ~5 ~14 ~38 ~5 ~14 wool 0
fill ~35 ~5 ~69 ~45 ~5 ~69 wool 15
fill ~35 ~5 ~84 ~35 ~6 ~84 wool 15
fill ~35 ~5 ~85 ~45 ~5 ~85 wool 15
fill ~35 ~5 ~102 ~35 ~8 ~102 wool 15
fill ~35 ~5 ~103 ~37 ~5 ~103 wool 15
fill ~36 ~5 ~104 ~54 ~5 ~104 wool 15
setblock ~36 ~5 ~136 torch 4
fill ~37 ~5 ~136 ~44 ~5 ~136 wool 7
fill ~38 ~5 ~100 ~38 ~6 ~100 wool 7
fill ~39 ~5 ~14 ~42 ~5 ~14 wool 11
fill ~39 ~5 ~103 ~40 ~5 ~103 wool 15
setblock ~41 ~5 ~53 torch 5
fill ~41 ~5 ~100 ~41 ~6 ~100 wool 7
setblock ~42 ~5 ~58 dirt 0
fill ~42 ~5 ~103 ~43 ~5 ~103 wool 15
fill ~43 ~5 ~15 ~44 ~5 ~15 wool 11
fill ~43 ~5 ~50 ~43 ~7 ~50 wool 15
fill ~43 ~5 ~58 ~43 ~5 ~61 wool 15
setblock ~44 ~5 ~16 wool 11
fill ~44 ~5 ~39 ~45 ~5 ~39 cobblestone 0
fill ~44 ~5 ~53 ~47 ~5 ~53 wool 15
fill ~44 ~5 ~54 ~47 ~5 ~54 wool 15
fill ~44 ~5 ~55 ~47 ~5 ~55 wool 15
fill ~44 ~5 ~56 ~47 ~5 ~56 wool 15
fill ~44 ~5 ~57 ~47 ~5 ~57 wool 15
setblock ~44 ~5 ~58 dirt 0
fill ~44 ~5 ~61 ~47 ~5 ~61 wool 15
fill ~44 ~5 ~100 ~44 ~6 ~100 wool 7
setblock ~45 ~5 ~84 wool 15
fill ~45 ~5 ~103 ~47 ~5 ~103 wool 15
fill ~45 ~5 ~136 ~45 ~6 ~136 wool 11
fill ~46 ~5 ~14 ~46 ~5 ~18 wool 8
fill ~46 ~5 ~83 ~46 ~8 ~83 wool 15
fill ~46 ~5 ~127 ~54 ~5 ~127 wool 15
setblock ~46 ~5 ~135 wool 11
fill ~47 ~5 ~19 ~47 ~4 ~19 wool 11
fill ~47 ~5 ~30 ~54 ~5 ~30 wool 15
fill ~47 ~5 ~51 ~54 ~5 ~51 wool 15
setblock ~47 ~5 ~94 wool 8
fill ~47 ~5 ~102 ~47 ~12 ~102 wool 7
fill ~48 ~5 ~16 ~49 ~5 ~16 wool 11
fill ~48 ~5 ~17 ~48 ~4 ~17 wool 11
fill ~48 ~5 ~18 ~48 ~3 ~18 wool 11
setblock ~48 ~5 ~61 wool 7
fill ~48 ~5 ~65 ~54 ~5 ~65 wool 7
fill ~48 ~5 ~66 ~49 ~5 ~66 wool 7
fill ~48 ~5 ~87 ~49 ~5 ~87 wool 7
fill ~48 ~5 ~88 ~49 ~5 ~88 wool 7
fill ~48 ~5 ~89 ~48 ~7 ~89 wool 7
fill ~48 ~5 ~90 ~48 ~8 ~90 wool 7
fill ~48 ~5 ~91 ~48 ~6 ~91 wool 7
fill ~48 ~5 ~92 ~48 ~5 ~87 wool 7
setblock ~48 ~5 ~93 wool 8
setblock ~48 ~5 ~95 wool 8
fill ~48 ~5 ~96 ~48 ~5 ~98 wool 7
setblock ~48 ~5 ~128 torch 3
fill ~48 ~5 ~132 ~49 ~5 ~132 glowstone 0
fill ~49 ~5 ~32 ~55 ~5 ~32 wool 15
fill ~49 ~5 ~49 ~55 ~5 ~49 wool 15
fill ~49 ~5 ~62 ~54 ~5 ~62 wool 7
fill ~49 ~5 ~64 ~54 ~5 ~64 wool 7
fill ~49 ~5 ~69 ~49 ~7 ~69 wool 11
fill ~49 ~5 ~71 ~49 ~7 ~71 wool 7
fill ~49 ~5 ~72 ~49 ~6 ~72 wool 7
fill ~49 ~5 ~73 ~49 ~6 ~73 wool 7
fill ~49 ~5 ~74 ~49 ~6 ~74 wool 7
fill ~49 ~5 ~75 ~49 ~6 ~75 wool 7
fill ~49 ~5 ~76 ~49 ~6 ~76 wool 7
fill ~49 ~5 ~77 ~49 ~6 ~77 wool 7
fill ~49 ~5 ~78 ~49 ~6 ~78 wool 7
fill ~49 ~5 ~79 ~49 ~6 ~79 wool 7
fill ~49 ~5 ~80 ~49 ~6 ~80 wool 7
fill ~49 ~5 ~81 ~49 ~6 ~81 wool 7
fill ~49 ~5 ~82 ~49 ~11 ~82 wool 7
fill ~49 ~5 ~83 ~49 ~9 ~83 wool 7
fill ~49 ~5 ~84 ~49 ~5 ~85 wool 11
setblock ~49 ~5 ~86 wool 7
fill ~49 ~5 ~98 ~53 ~5 ~98 wool 7
fill ~49 ~5 ~100 ~54 ~5 ~100 wool 7
fill ~49 ~5 ~107 ~55 ~5 ~107 wool 15
fill ~49 ~5 ~124 ~55 ~5 ~124 wool 15
fill ~50 ~5 ~17 ~50 ~5 ~19 wool 11
fill ~50 ~5 ~33 ~54 ~5 ~33 dirt 0
fill ~50 ~5 ~34 ~54 ~5 ~34 wool 8
fill ~50 ~5 ~39 ~50 ~6 ~39 cobblestone 0
fill ~50 ~5 ~42 ~50 ~6 ~42 cobblestone 0
fill ~50 ~5 ~47 ~54 ~5 ~47 wool 8
fill ~50 ~5 ~48 ~54 ~5 ~48 dirt 0
fill ~50 ~5 ~109 ~54 ~5 ~109 wool 8
fill ~50 ~5 ~122 ~54 ~5 ~122 wool 8
fill ~51 ~5 ~43 ~51 ~9 ~43 wool 7
fill ~51 ~5 ~132 ~51 ~7 ~132 wool 11
fill ~52 ~5 ~37 ~52 ~6 ~37 wool 8
fill ~52 ~5 ~38 ~52 ~6 ~38 wool 8
fill ~52 ~5 ~40 ~54 ~5 ~40 wool 7
fill ~52 ~5 ~41 ~54 ~5 ~41 wool 7
fill ~52 ~5 ~43 ~52 ~6 ~43 wool 8
fill ~52 ~5 ~44 ~52 ~6 ~44 wool 8
fill ~52 ~5 ~112 ~52 ~6 ~112 wool 8
fill ~52 ~5 ~113 ~52 ~6 ~113 wool 8
fill ~52 ~5 ~118 ~52 ~6 ~118 wool 8
fill ~52 ~5 ~119 ~52 ~6 ~119 wool 8
fill ~52 ~5 ~131 ~52 ~7 ~131 wool 11
fill ~53 ~5 ~29 ~54 ~5 ~29 wool 11
fill ~53 ~5 ~39 ~53 ~6 ~39 wool 8
fill ~53 ~5 ~42 ~53 ~6 ~42 wool 8
setblock ~53 ~5 ~99 torch 5
setblock ~53 ~5 ~111 wool 8
fill ~53 ~5 ~114 ~53 ~6 ~114 wool 8
fill ~53 ~5 ~117 ~53 ~6 ~117 wool 8
fill ~53 ~5 ~130 ~53 ~10 ~130 wool 11
fill ~54 ~5 ~63 ~54 ~6 ~63 wool 15
fill ~54 ~5 ~99 ~54 ~6 ~99 wool 15
fill ~54 ~5 ~115 ~54 ~6 ~115 wool 7
fill ~54 ~5 ~116 ~54 ~6 ~116 wool 7
fill ~54 ~5 ~128 ~54 ~10 ~128 wool 11
fill ~55 ~5 ~51 ~55 ~5 ~62 wool 0
fill ~55 ~5 ~64 ~55 ~5 ~97 wool 0
fill ~55 ~5 ~99 ~55 ~5 ~105 wool 0
fill ~55 ~5 ~127 ~55 ~7 ~127 wool 11
fill ~6 ~6 ~32 ~12 ~6 ~32 wool 15
fill ~6 ~6 ~49 ~12 ~6 ~49 wool 15
fill ~6 ~6 ~51 ~6 ~9 ~51 wool 11
fill ~6 ~6 ~52 ~6 ~6 ~62 wool 11
fill ~6 ~6 ~64 ~6 ~6 ~97 wool 11
fill ~6 ~6 ~99 ~6 ~6 ~105 wool 11
fill ~6 ~6 ~107 ~12 ~6 ~107 wool 15
fill ~6 ~6 ~124 ~12 ~6 ~124 wool 15
fill ~7 ~6 ~30 ~14 ~6 ~30 wool 15
fill ~7 ~6 ~33 ~11 ~6 ~33 dirt 0
fill ~7 ~6 ~34 ~11 ~6 ~34 wool 8
fill ~7 ~6 ~40 ~10 ~6 ~40 wool 7
fill ~7 ~6 ~41 ~10 ~6 ~41 wool 7
fill ~7 ~6 ~47 ~11 ~6 ~47 wool 8
fill ~7 ~6 ~48 ~11 ~6 ~48 dirt 0
fill ~7 ~6 ~51 ~14 ~6 ~51 wool 15
fill ~7 ~6 ~61 ~12 ~6 ~61 wool 7
setblock ~7 ~6 ~62 wool 15
fill ~7 ~6 ~64 ~12 ~6 ~64 wool 7
fill ~7 ~6 ~65 ~13 ~6 ~65 wool 7
fill ~7 ~6 ~96 ~12 ~6 ~96 dirt 0
fill ~7 ~6 ~97 ~12 ~6 ~97 dirt 0
fill ~7 ~6 ~100 ~13 ~6 ~100 wool 7
fill ~7 ~6 ~105 ~25 ~6 ~105 wool 15
fill ~7 ~6 ~108 ~11 ~6 ~108 dirt 0
fill ~7 ~6 ~109 ~11 ~6 ~109 wool 8
fill ~7 ~6 ~122 ~11 ~6 ~122 wool 8
fill ~8 ~6 ~98 ~13 ~6 ~98 wool 7
fill ~8 ~6 ~127 ~15 ~6 ~127 wool 15
fill ~9 ~6 ~20 ~9 ~11 ~20 wool 11
fill ~9 ~6 ~21 ~9 ~9 ~21 wool 11
fill ~9 ~6 ~44 ~9 ~7 ~44 wool 14
fill ~9 ~6 ~112 ~9 ~8 ~112 wool 8
fill ~9 ~6 ~113 ~9 ~7 ~113 wool 8
fill ~9 ~6 ~118 ~9 ~7 ~118 wool 8
fill ~9 ~6 ~119 ~9 ~8 ~119 wool 8
fill ~10 ~6 ~17 ~10 ~8 ~17 wool 11
setblock ~11 ~6 ~16 wool 11
setblock ~11 ~6 ~70 torch 2
fill ~11 ~6 ~133 ~13 ~6 ~133 wool 11
fill ~12 ~6 ~15 ~14 ~6 ~15 wool 11
fill ~12 ~6 ~40 ~50 ~6 ~40 cobblestone 0
fill ~12 ~6 ~41 ~50 ~6 ~41 cobblestone 0
fill ~12 ~6 ~70 ~12 ~8 ~70 wool 7
fill ~12 ~6 ~84 ~12 ~6 ~85 wool 7
setblock ~12 ~6 ~86 wool 11
setblock ~12 ~6 ~87 wool 7
fill ~13 ~6 ~52 ~13 ~10 ~52 wool 7
fill ~13 ~6 ~53 ~13 ~10 ~53 wool 7
fill ~13 ~6 ~54 ~13 ~10 ~54 wool 7
fill ~13 ~6 ~55 ~13 ~10 ~55 wool 7
fill ~13 ~6 ~56 ~13 ~10 ~56 wool 7
fill ~13 ~6 ~57 ~13 ~10 ~57 wool 7
fill ~13 ~6 ~58 ~13 ~10 ~58 wool 7
fill ~13 ~6 ~59 ~13 ~10 ~59 wool 7
fill ~13 ~6 ~60 ~13 ~9 ~60 wool 7
fill ~13 ~6 ~88 ~13 ~6 ~91 wool 7
fill ~13 ~6 ~92 ~14 ~6 ~92 wool 8
fill ~13 ~6 ~93 ~13 ~10 ~93 wool 7
fill ~13 ~6 ~94 ~13 ~10 ~94 wool 7
fill ~13 ~6 ~95 ~13 ~10 ~95 wool 7
fill ~13 ~6 ~96 ~14 ~6 ~96 wool 8
setblock ~13 ~6 ~97 wool 7
setblock ~13 ~6 ~134 wool 11
fill ~14 ~6 ~14 ~18 ~6 ~14 wool 11
fill ~14 ~6 ~16 ~14 ~6 ~18 wool 11
fill ~14 ~6 ~35 ~14 ~14 ~35 wool 15
fill ~14 ~6 ~36 ~14 ~14 ~36 wool 15
fill ~14 ~6 ~37 ~14 ~15 ~37 wool 15
fill ~14 ~6 ~38 ~14 ~15 ~38 wool 15
fill ~14 ~6 ~39 ~14 ~15 ~39 wool 15
fill ~14 ~6 ~42 ~14 ~15 ~42 wool 15
fill ~14 ~6 ~43 ~14 ~15 ~43 wool 15
fill ~14 ~6 ~44 ~14 ~15 ~44 wool 15
fill ~14 ~6 ~52 ~17 ~6 ~52 wool 15
fill ~14 ~6 ~53 ~14 ~7 ~53 wool 8
fill ~14 ~6 ~54 ~14 ~6 ~53 wool 8
fill ~14 ~6 ~58 ~17 ~6 ~58 wool 15
fill ~14 ~6 ~59 ~17 ~6 ~59 wool 15
fill ~14 ~6 ~60 ~17 ~6 ~60 wool 15
fill ~14 ~6 ~93 ~14 ~10 ~93 wool 15
fill ~14 ~6 ~94 ~14 ~10 ~94 wool 15
fill ~14 ~6 ~95 ~14 ~10 ~95 wool 15
fill ~14 ~6 ~103 ~14 ~11 ~103 wool 7
fill ~14 ~6 ~104 ~14 ~10 ~104 wool 7
setblock ~14 ~6 ~135 wool 11
setblock ~15 ~6 ~15 torch 5
fill ~15 ~6 ~82 ~16 ~6 ~82 wool 15
fill ~15 ~6 ~84 ~15 ~8 ~84 wool 15
setblock ~15 ~6 ~136 wool 11
fill ~16 ~6 ~15 ~16 ~6 ~18 wool 11
fill ~16 ~6 ~38 ~17 ~6 ~38 cobblestone 0
fill ~16 ~6 ~39 ~17 ~6 ~39 wool 15
fill ~16 ~6 ~85 ~26 ~6 ~85 wool 15
setblock ~17 ~6 ~51 dirt 0
fill ~17 ~6 ~69 ~26 ~6 ~69 wool 15
setblock ~17 ~6 ~122 torch 1
fill ~17 ~6 ~136 ~21 ~6 ~136 wool 11
fill ~18 ~6 ~48 ~18 ~6 ~51 wool 15
fill ~19 ~6 ~13 ~22 ~6 ~13 wool 11
fill ~19 ~6 ~49 ~27 ~6 ~49 wool 11
fill ~19 ~6 ~58 ~27 ~6 ~58 wool 11
fill ~19 ~6 ~59 ~27 ~6 ~59 wool 11
fill ~19 ~6 ~60 ~27 ~6 ~60 wool 11
setblock ~22 ~6 ~137 wool 11
fill ~23 ~6 ~13 ~26 ~6 ~13 wool 0
setblock ~23 ~6 ~56 torch 5
fill ~23 ~6 ~137 ~29 ~6 ~137 wool 0
fill ~26 ~6 ~103 ~26 ~8 ~103 wool 15
fill ~26 ~6 ~104 ~26 ~8 ~104 wool 15
fill ~27 ~6 ~12 ~29 ~6 ~12 wool 0
setblock ~28 ~6 ~47 dirt 0
fill ~28 ~6 ~48 ~28 ~7 ~48 wool 15
fill ~28 ~6 ~49 ~28 ~7 ~49 wool 15
setblock ~28 ~6 ~69 torch 4
fill ~29 ~6 ~39 ~32 ~6 ~39 cobblestone 0
fill ~29 ~6 ~42 ~32 ~6 ~42 cobblestone 0
setblock ~29 ~6 ~51 dirt 0
fill ~29 ~6 ~52 ~32 ~6 ~52 wool 15
fill ~29 ~6 ~58 ~32 ~6 ~58 wool 15
fill ~29 ~6 ~59 ~32 ~6 ~59 wool 15
fill ~29 ~6 ~60 ~32 ~6 ~60 wool 15
fill ~29 ~6 ~70 ~33 ~6 ~70 wool 15
fill ~30 ~6 ~12 ~31 ~6 ~12 wool 11
setblock ~30 ~6 ~13 torch 3
fill ~30 ~6 ~38 ~31 ~6 ~38 cobblestone 0
setblock ~30 ~6 ~43 cobblestone 0
fill ~30 ~6 ~137 ~31 ~6 ~137 wool 11
fill ~32 ~6 ~12 ~34 ~6 ~12 wool 0
setblock ~32 ~6 ~51 dirt 0
setblock ~32 ~6 ~54 torch 5
fill ~32 ~6 ~137 ~38 ~6 ~137 wool 0
setblock ~33 ~6 ~69 torch 4
fill ~34 ~6 ~49 ~42 ~6 ~49 wool 11
fill ~34 ~6 ~58 ~42 ~6 ~58 wool 11
fill ~34 ~6 ~59 ~42 ~6 ~59 wool 11
fill ~34 ~6 ~60 ~42 ~6 ~60 wool 11
fill ~35 ~6 ~13 ~38 ~6 ~13 wool 0
fill ~35 ~6 ~69 ~45 ~6 ~69 wool 15
fill ~35 ~6 ~85 ~45 ~6 ~85 wool 15
fill ~35 ~6 ~103 ~35 ~8 ~103 wool 15
fill ~35 ~6 ~104 ~35 ~8 ~104 wool 15
fill ~36 ~6 ~105 ~45 ~6 ~105 wool 15
fill ~37 ~6 ~99 ~38 ~6 ~99 wool 8
setblock ~38 ~6 ~101 torch 3
fill ~39 ~6 ~13 ~42 ~6 ~13 wool 11
setblock ~39 ~6 ~137 wool 11
fill ~40 ~6 ~99 ~41 ~6 ~99 wool 8
fill ~40 ~6 ~136 ~46 ~6 ~136 wool 11
setblock ~41 ~6 ~101 torch 3
setblock ~42 ~6 ~48 dirt 0
fill ~43 ~6 ~14 ~47 ~6 ~14 wool 11
fill ~43 ~6 ~99 ~44 ~6 ~99 wool 8
fill ~44 ~6 ~38 ~45 ~6 ~38 cobblestone 0
fill ~44 ~6 ~39 ~45 ~6 ~39 wool 15
setblock ~44 ~6 ~51 dirt 0
fill ~44 ~6 ~52 ~47 ~6 ~52 wool 15
fill ~44 ~6 ~58 ~47 ~6 ~58 wool 15
fill ~44 ~6 ~59 ~47 ~6 ~59 wool 15
fill ~44 ~6 ~60 ~47 ~6 ~60 wool 15
setblock ~44 ~6 ~101 torch 3
fill ~45 ~6 ~15 ~45 ~6 ~18 wool 11
setblock ~46 ~6 ~15 torch 5
fill ~46 ~6 ~84 ~46 ~8 ~84 wool 15
fill ~46 ~6 ~104 ~54 ~6 ~104 wool 15
fill ~46 ~6 ~127 ~54 ~6 ~127 wool 15
fill ~47 ~6 ~15 ~49 ~6 ~15 wool 11
fill ~47 ~6 ~16 ~47 ~6 ~18 wool 11
fill ~47 ~6 ~30 ~54 ~6 ~30 wool 15
fill ~47 ~6 ~35 ~47 ~14 ~35 wool 15
fill ~47 ~6 ~36 ~47 ~14 ~36 wool 15
fill ~47 ~6 ~37 ~47 ~15 ~37 wool 15
fill ~47 ~6 ~38 ~47 ~15 ~38 wool 15
fill ~47 ~6 ~39 ~47 ~15 ~39 wool 15
fill ~47 ~6 ~42 ~47 ~15 ~42 wool 15
fill ~47 ~6 ~43 ~47 ~15 ~43 wool 15
fill ~47 ~6 ~44 ~47 ~15 ~44 wool 15
setblock ~47 ~6 ~48 torch 1
fill ~47 ~6 ~51 ~54 ~6 ~51 wool 15
fill ~47 ~6 ~53 ~47 ~7 ~53 wool 8
fill ~47 ~6 ~54 ~47 ~6 ~53 wool 8
setblock ~47 ~6 ~92 wool 8
fill ~47 ~6 ~93 ~47 ~10 ~93 wool 15
fill ~47 ~6 ~94 ~47 ~10 ~94 wool 15
fill ~47 ~6 ~95 ~47 ~10 ~95 wool 15
fill ~47 ~6 ~96 ~48 ~6 ~96 wool 8
fill ~47 ~6 ~103 ~47 ~11 ~103 wool 7
setblock ~47 ~6 ~135 wool 11
fill ~48 ~6 ~53 ~48 ~10 ~53 wool 7
fill ~48 ~6 ~54 ~48 ~10 ~54 wool 7
fill ~48 ~6 ~55 ~48 ~10 ~55 wool 7
fill ~48 ~6 ~56 ~48 ~10 ~56 wool 7
fill ~48 ~6 ~57 ~48 ~10 ~57 wool 7
fill ~48 ~6 ~60 ~48 ~9 ~60 wool 7
fill ~48 ~6 ~65 ~54 ~6 ~65 wool 7
fill ~48 ~6 ~66 ~49 ~6 ~66 wool 7
fill ~48 ~6 ~88 ~49 ~6 ~88 wool 7
fill ~48 ~6 ~97 ~48 ~6 ~98 wool 7
fill ~48 ~6 ~133 ~50 ~6 ~133 wool 11
fill ~48 ~6 ~134 ~48 ~6 ~133 wool 11
fill ~49 ~6 ~32 ~55 ~6 ~32 wool 15
fill ~49 ~6 ~49 ~55 ~6 ~49 wool 15
fill ~49 ~6 ~61 ~54 ~6 ~61 wool 7
fill ~49 ~6 ~64 ~54 ~6 ~64 wool 7
fill ~49 ~6 ~70 ~49 ~8 ~70 wool 7
fill ~49 ~6 ~84 ~49 ~9 ~84 wool 7
fill ~49 ~6 ~85 ~49 ~11 ~85 wool 7
setblock ~49 ~6 ~86 wool 11
setblock ~49 ~6 ~87 wool 7
setblock ~49 ~6 ~91 torch 1
setblock ~49 ~6 ~97 torch 4
fill ~49 ~6 ~98 ~53 ~6 ~98 wool 7
fill ~49 ~6 ~100 ~54 ~6 ~100 wool 7
fill ~49 ~6 ~107 ~55 ~6 ~107 wool 15
fill ~49 ~6 ~124 ~55 ~6 ~124 wool 15
setblock ~50 ~6 ~16 wool 11
setblock ~50 ~6 ~19 torch 5
fill ~50 ~6 ~33 ~54 ~6 ~33 dirt 0
fill ~50 ~6 ~34 ~54 ~6 ~34 wool 8
fill ~50 ~6 ~47 ~54 ~6 ~47 wool 8
fill ~50 ~6 ~48 ~54 ~6 ~48 dirt 0
setblock ~50 ~6 ~69 torch 1
fill ~50 ~6 ~109 ~54 ~6 ~109 wool 8
fill ~50 ~6 ~122 ~54 ~6 ~122 wool 8
fill ~51 ~6 ~17 ~51 ~8 ~17 wool 11
fill ~51 ~6 ~18 ~51 ~7 ~18 wool 11
fill ~51 ~6 ~19 ~51 ~6 ~17 wool 11
fill ~52 ~6 ~20 ~52 ~11 ~20 wool 11
fill ~52 ~6 ~21 ~52 ~9 ~21 wool 11
fill ~52 ~6 ~40 ~54 ~6 ~40 wool 7
fill ~52 ~6 ~41 ~54 ~6 ~41 wool 7
fill ~53 ~6 ~29 ~54 ~6 ~29 wool 11
fill ~53 ~6 ~36 ~53 ~7 ~36 wool 8
fill ~53 ~6 ~45 ~53 ~7 ~45 wool 8
setblock ~53 ~6 ~128 torch 2
setblock ~54 ~6 ~62 wool 15
fill ~55 ~6 ~51 ~55 ~9 ~51 wool 11
fill ~55 ~6 ~52 ~55 ~6 ~62 wool 11
fill ~55 ~6 ~64 ~55 ~6 ~97 wool 11
fill ~55 ~6 ~99 ~55 ~6 ~105 wool 11
fill ~6 ~7 ~32 ~12 ~7 ~32 wool 15
fill ~6 ~7 ~49 ~12 ~7 ~49 wool 15
fill ~6 ~7 ~55 ~7 ~7 ~55 wool 11
fill ~6 ~7 ~56 ~7 ~7 ~56 wool 11
fill ~6 ~7 ~57 ~7 ~7 ~57 wool 11
fill ~6 ~7 ~58 ~7 ~7 ~58 wool 11
fill ~6 ~7 ~59 ~7 ~7 ~59 wool 11
fill ~6 ~7 ~104 ~7 ~7 ~104 wool 11
fill ~6 ~7 ~105 ~7 ~7 ~105 wool 11
fill ~6 ~7 ~107 ~12 ~7 ~107 wool 15
fill ~6 ~7 ~124 ~12 ~7 ~124 wool 15
fill ~6 ~7 ~126 ~6 ~10 ~126 wool 11
fill ~7 ~7 ~30 ~14 ~7 ~30 wool 15
fill ~7 ~7 ~33 ~11 ~7 ~33 dirt 0
fill ~7 ~7 ~34 ~11 ~7 ~34 wool 8
fill ~7 ~7 ~47 ~11 ~7 ~47 wool 8
fill ~7 ~7 ~48 ~11 ~7 ~48 dirt 0
fill ~7 ~7 ~51 ~17 ~7 ~51 wool 15
fill ~7 ~7 ~52 ~7 ~13 ~52 wool 11
fill ~7 ~7 ~53 ~7 ~13 ~53 wool 11
fill ~7 ~7 ~54 ~7 ~13 ~54 wool 11
fill ~7 ~7 ~60 ~7 ~12 ~60 wool 11
fill ~7 ~7 ~61 ~7 ~9 ~61 wool 11
fill ~7 ~7 ~63 ~7 ~13 ~63 wool 11
fill ~7 ~7 ~64 ~7 ~13 ~64 wool 11
fill ~7 ~7 ~65 ~7 ~13 ~65 wool 11
fill ~7 ~7 ~66 ~7 ~13 ~66 wool 11
fill ~7 ~7 ~67 ~7 ~13 ~67 wool 11
fill ~7 ~7 ~68 ~7 ~13 ~68 wool 11
fill ~7 ~7 ~69 ~7 ~13 ~69 wool 11
fill ~7 ~7 ~70 ~7 ~13 ~70 wool 11
fill ~7 ~7 ~71 ~7 ~13 ~71 wool 11
fill ~7 ~7 ~72 ~7 ~13 ~72 wool 11
fill ~7 ~7 ~73 ~7 ~13 ~73 wool 11
fill ~7 ~7 ~74 ~7 ~13 ~74 wool 11
fill ~7 ~7 ~75 ~7 ~13 ~75 wool 11
fill ~7 ~7 ~76 ~7 ~13 ~76 wool 11
fill ~7 ~7 ~77 ~7 ~13 ~77 wool 11
fill ~7 ~7 ~78 ~7 ~13 ~78 wool 11
fill ~7 ~7 ~79 ~7 ~13 ~79 wool 11
fill ~7 ~7 ~80 ~7 ~13 ~80 wool 11
fill ~7 ~7 ~81 ~7 ~13 ~81 wool 11
fill ~7 ~7 ~82 ~7 ~13 ~82 wool 11
fill ~7 ~7 ~83 ~7 ~13 ~83 wool 11
fill ~7 ~7 ~84 ~7 ~13 ~84 wool 11
fill ~7 ~7 ~85 ~7 ~13 ~85 wool 11
fill ~7 ~7 ~86 ~7 ~13 ~86 wool 11
fill ~7 ~7 ~87 ~7 ~13 ~87 wool 11
fill ~7 ~7 ~88 ~7 ~13 ~88 wool 11
fill ~7 ~7 ~89 ~7 ~13 ~89 wool 11
fill ~7 ~7 ~90 ~7 ~13 ~90 wool 11
fill ~7 ~7 ~91 ~7 ~13 ~91 wool 11
fill ~7 ~7 ~92 ~7 ~13 ~92 wool 11
fill ~7 ~7 ~93 ~7 ~13 ~93 wool 11
fill ~7 ~7 ~94 ~7 ~13 ~94 wool 11
fill ~7 ~7 ~95 ~7 ~13 ~95 wool 11
fill ~7 ~7 ~96 ~7 ~13 ~96 wool 11
fill ~7 ~7 ~97 ~7 ~13 ~97 wool 11
fill ~7 ~7 ~99 ~7 ~9 ~99 wool 11
fill ~7 ~7 ~100 ~7 ~13 ~100 wool 11
fill ~7 ~7 ~101 ~7 ~13 ~101 wool 11
fill ~7 ~7 ~102 ~7 ~13 ~102 wool 11
fill ~7 ~7 ~103 ~7 ~13 ~103 wool 11
fill ~7 ~7 ~108 ~11 ~7 ~108 dirt 0
fill ~7 ~7 ~109 ~11 ~7 ~109 wool 8
fill ~7 ~7 ~122 ~11 ~7 ~122 wool 8
fill ~7 ~7 ~126 ~16 ~7 ~126 wool 15
fill ~7 ~7 ~129 ~7 ~8 ~129 wool 11
fill ~8 ~7 ~26 ~8 ~17 ~26 wool 11
fill ~8 ~7 ~40 ~8 ~7 ~41 wool 8
fill ~8 ~7 ~61 ~12 ~7 ~61 wool 7
fill ~8 ~7 ~62 ~8 ~9 ~62 wool 15
fill ~8 ~7 ~63 ~12 ~7 ~63 wool 7
fill ~8 ~7 ~64 ~13 ~7 ~64 wool 7
fill ~8 ~7 ~96 ~12 ~7 ~96 dirt 0
fill ~8 ~7 ~97 ~12 ~7 ~97 dirt 0
fill ~8 ~7 ~98 ~8 ~9 ~98 wool 15
fill ~8 ~7 ~99 ~8 ~13 ~99 wool 15
fill ~8 ~7 ~100 ~13 ~7 ~100 wool 7
fill ~8 ~7 ~105 ~16 ~7 ~105 wool 15
fill ~8 ~7 ~110 ~8 ~9 ~110 wool 8
fill ~8 ~7 ~115 ~8 ~7 ~116 wool 8
fill ~8 ~7 ~121 ~8 ~9 ~121 wool 8
fill ~9 ~7 ~19 ~9 ~13 ~19 wool 11
fill ~9 ~7 ~38 ~9 ~9 ~38 wool 8
fill ~9 ~7 ~39 ~9 ~8 ~39 wool 8
fill ~9 ~7 ~42 ~9 ~8 ~42 wool 8
fill ~9 ~7 ~43 ~9 ~9 ~43 wool 8
setblock ~9 ~7 ~62 torch 1
fill ~9 ~7 ~98 ~13 ~7 ~98 wool 7
setblock ~9 ~7 ~99 torch 1
setblock ~9 ~7 ~111 wool 8
setblock ~9 ~7 ~120 wool 8
fill ~10 ~7 ~16 ~10 ~8 ~16 wool 11
setblock ~11 ~7 ~15 wool 11
fill ~11 ~7 ~72 ~11 ~8 ~72 wool 7
fill ~11 ~7 ~73 ~11 ~8 ~73 wool 7
fill ~11 ~7 ~74 ~11 ~8 ~74 wool 7
fill ~11 ~7 ~75 ~11 ~8 ~75 wool 7
fill ~11 ~7 ~76 ~11 ~8 ~76 wool 7
fill ~11 ~7 ~77 ~11 ~8 ~77 wool 7
fill ~11 ~7 ~78 ~11 ~8 ~78 wool 7
fill ~11 ~7 ~79 ~11 ~8 ~79 wool 7
fill ~11 ~7 ~80 ~11 ~8 ~80 wool 7
fill ~11 ~7 ~81 ~11 ~8 ~81 wool 7
fill ~11 ~7 ~133 ~11 ~6 ~133 wool 11
fill ~12 ~7 ~14 ~14 ~7 ~14 wool 11
fill ~12 ~7 ~67 ~12 ~11 ~67 wool 11
fill ~12 ~7 ~68 ~12 ~7 ~67 wool 11
setblock ~12 ~7 ~72 torch 3
setblock ~12 ~7 ~81 torch 4
fill ~12 ~7 ~85 ~12 ~7 ~86 wool 7
setblock ~12 ~7 ~87 wool 11
setblock ~12 ~7 ~88 wool 7
setblock ~12 ~7 ~134 wool 11
fill ~13 ~7 ~65 ~13 ~9 ~65 wool 7
fill ~13 ~7 ~72 ~13 ~11 ~72 wool 7
fill ~13 ~7 ~73 ~13 ~11 ~73 wool 7
fill ~13 ~7 ~74 ~13 ~11 ~74 wool 7
fill ~13 ~7 ~75 ~13 ~11 ~75 wool 7
fill ~13 ~7 ~76 ~13 ~11 ~76 wool 7
fill ~13 ~7 ~77 ~13 ~11 ~77 wool 7
fill ~13 ~7 ~78 ~13 ~11 ~78 wool 7
fill ~13 ~7 ~79 ~13 ~11 ~79 wool 7
fill ~13 ~7 ~80 ~13 ~11 ~80 wool 7
fill ~13 ~7 ~81 ~13 ~11 ~81 wool 7
fill ~13 ~7 ~82 ~13 ~11 ~82 wool 7
fill ~13 ~7 ~83 ~13 ~11 ~83 wool 7
fill ~13 ~7 ~84 ~13 ~11 ~84 wool 7
fill ~13 ~7 ~89 ~13 ~7 ~90 wool 7
fill ~13 ~7 ~91 ~13 ~9 ~91 wool 8
fill ~13 ~7 ~92 ~13 ~9 ~92 wool 7
fill ~13 ~7 ~96 ~13 ~9 ~96 wool 7
fill ~13 ~7 ~97 ~13 ~9 ~97 wool 8
setblock ~13 ~7 ~135 wool 11
fill ~14 ~7 ~40 ~14 ~15 ~40 wool 15
fill ~14 ~7 ~41 ~14 ~15 ~41 wool 15
fill ~14 ~7 ~52 ~14 ~8 ~52 wool 8
fill ~14 ~7 ~92 ~14 ~9 ~92 wool 15
fill ~14 ~7 ~96 ~14 ~9 ~96 wool 15
setblock ~14 ~7 ~136 wool 11
fill ~15 ~7 ~13 ~19 ~7 ~13 wool 11
fill ~15 ~7 ~82 ~15 ~8 ~82 wool 15
fill ~15 ~7 ~85 ~15 ~8 ~85 wool 15
fill ~15 ~7 ~137 ~21 ~7 ~137 wool 11
fill ~16 ~7 ~38 ~17 ~7 ~38 wool 15
fill ~16 ~7 ~39 ~17 ~7 ~39 wool 15
setblock ~16 ~7 ~59 torch 5
fill ~16 ~7 ~86 ~26 ~7 ~86 wool 15
fill ~17 ~7 ~48 ~17 ~10 ~48 wool 15
fill ~17 ~7 ~49 ~17 ~10 ~49 wool 15
fill ~17 ~7 ~50 ~17 ~9 ~50 wool 15
fill ~17 ~7 ~69 ~26 ~7 ~69 wool 15
fill ~17 ~7 ~70 ~17 ~7 ~69 wool 15
fill ~17 ~7 ~106 ~25 ~7 ~106 wool 15
setblock ~17 ~7 ~119 torch 1
setblock ~17 ~7 ~125 torch 1
fill ~18 ~7 ~38 ~18 ~12 ~38 torch 1
fill ~18 ~7 ~47 ~18 ~10 ~47 wool 15
fill ~18 ~7 ~75 ~24 ~7 ~75 wool 11
fill ~18 ~7 ~76 ~24 ~7 ~76 wool 11
fill ~18 ~7 ~77 ~24 ~7 ~77 wool 11
fill ~18 ~7 ~78 ~24 ~7 ~78 wool 11
fill ~18 ~7 ~79 ~24 ~7 ~79 wool 11
fill ~18 ~7 ~80 ~24 ~7 ~80 wool 11
setblock ~18 ~7 ~81 dirt 0
fill ~19 ~7 ~48 ~27 ~7 ~48 wool 11
fill ~20 ~7 ~12 ~22 ~7 ~12 wool 11
fill ~20 ~7 ~138 ~22 ~7 ~138 wool 11
setblock ~21 ~7 ~41 torch 5
setblock ~22 ~7 ~59 torch 5
fill ~23 ~7 ~12 ~29 ~7 ~12 wool 0
fill ~23 ~7 ~138 ~29 ~7 ~138 wool 0
setblock ~24 ~7 ~41 torch 5
setblock ~24 ~7 ~85 dirt 0
fill ~24 ~7 ~139 ~29 ~7 ~139 wool 0
fill ~26 ~7 ~105 ~26 ~9 ~105 wool 15
setblock ~27 ~7 ~41 torch 5
fill ~27 ~7 ~71 ~27 ~17 ~71 wool 15
fill ~27 ~7 ~72 ~27 ~14 ~72 wool 15
fill ~27 ~7 ~73 ~27 ~11 ~73 wool 15
fill ~27 ~7 ~74 ~27 ~8 ~74 wool 15
fill ~27 ~7 ~75 ~27 ~8 ~75 wool 15
fill ~27 ~7 ~76 ~27 ~9 ~76 wool 15
fill ~27 ~7 ~77 ~27 ~9 ~77 wool 15
fill ~27 ~7 ~78 ~27 ~9 ~78 wool 15
fill ~27 ~7 ~79 ~27 ~9 ~79 wool 15
fill ~27 ~7 ~80 ~27 ~9 ~80 wool 15
fill ~27 ~7 ~81 ~27 ~9 ~81 wool 15
fill ~27 ~7 ~82 ~27 ~8 ~82 wool 15
fill ~27 ~7 ~83 ~27 ~8 ~83 wool 15
fill ~27 ~7 ~84 ~27 ~8 ~84 wool 15
fill ~27 ~7 ~85 ~27 ~8 ~85 wool 15
fill ~28 ~7 ~47 ~28 ~10 ~47 wool 15
setblock ~28 ~7 ~70 torch 4
fill ~29 ~7 ~48 ~29 ~10 ~48 wool 15
fill ~29 ~7 ~49 ~29 ~7 ~50 wool 14
fill ~29 ~7 ~51 ~32 ~7 ~51 wool 15
setblock ~29 ~7 ~58 torch 5
fill ~29 ~7 ~71 ~34 ~7 ~71 wool 15
fill ~30 ~7 ~12 ~31 ~7 ~12 wool 11
setblock ~30 ~7 ~40 torch 5
fill ~30 ~7 ~49 ~31 ~7 ~49 wool 15
fill ~30 ~7 ~50 ~31 ~7 ~50 wool 15
fill ~30 ~7 ~137 ~31 ~7 ~137 torch 4
fill ~30 ~7 ~138 ~31 ~7 ~138 wool 11
fill ~30 ~7 ~139 ~31 ~7 ~139 wool 11
fill ~31 ~7 ~39 ~31 ~7 ~40 cobblestone 0
fill ~32 ~7 ~12 ~38 ~7 ~12 wool 0
setblock ~32 ~7 ~48 dirt 0
fill ~32 ~7 ~49 ~32 ~7 ~50 wool 14
fill ~32 ~7 ~138 ~38 ~7 ~138 wool 0
fill ~32 ~7 ~139 ~37 ~7 ~139 wool 0
fill ~33 ~7 ~47 ~33 ~10 ~47 wool 15
fill ~33 ~7 ~48 ~33 ~7 ~50 wool 15
setblock ~33 ~7 ~70 torch 4
setblock ~34 ~7 ~41 torch 5
fill ~34 ~7 ~48 ~42 ~7 ~48 wool 11
fill ~34 ~7 ~70 ~34 ~19 ~70 wool 15
fill ~34 ~7 ~72 ~34 ~13 ~72 wool 15
fill ~34 ~7 ~73 ~34 ~11 ~73 wool 15
fill ~34 ~7 ~74 ~34 ~8 ~74 wool 15
fill ~34 ~7 ~82 ~34 ~8 ~82 wool 15
fill ~34 ~7 ~83 ~34 ~8 ~83 wool 15
fill ~34 ~7 ~84 ~34 ~8 ~84 wool 15
fill ~35 ~7 ~69 ~45 ~7 ~69 wool 15
fill ~35 ~7 ~85 ~35 ~5 ~85 wool 15
fill ~35 ~7 ~86 ~45 ~7 ~86 wool 15
fill ~35 ~7 ~105 ~35 ~9 ~105 wool 15
fill ~36 ~7 ~80 ~36 ~9 ~80 wool 15
fill ~36 ~7 ~106 ~45 ~7 ~106 wool 15
fill ~37 ~7 ~75 ~43 ~7 ~75 wool 11
fill ~37 ~7 ~76 ~43 ~7 ~76 wool 11
fill ~37 ~7 ~77 ~43 ~7 ~77 wool 11
fill ~37 ~7 ~78 ~43 ~7 ~78 wool 11
fill ~37 ~7 ~79 ~43 ~7 ~79 wool 11
fill ~37 ~7 ~80 ~43 ~7 ~80 wool 11
fill ~37 ~7 ~100 ~38 ~7 ~100 wool 8
setblock ~38 ~7 ~40 torch 5
setblock ~38 ~7 ~49 torch 3
fill ~39 ~7 ~12 ~41 ~7 ~12 wool 11
setblock ~39 ~7 ~59 torch 5
setblock ~39 ~7 ~137 torch 4
fill ~39 ~7 ~138 ~41 ~7 ~138 wool 11
fill ~40 ~7 ~100 ~41 ~7 ~100 wool 8
fill ~40 ~7 ~137 ~46 ~7 ~137 wool 11
setblock ~41 ~7 ~40 torch 5
fill ~42 ~7 ~13 ~46 ~7 ~13 wool 11
fill ~43 ~7 ~48 ~43 ~7 ~50 wool 15
fill ~43 ~7 ~100 ~44 ~7 ~100 wool 8
setblock ~43 ~7 ~136 torch 4
fill ~44 ~7 ~38 ~45 ~7 ~38 wool 15
fill ~44 ~7 ~39 ~45 ~7 ~39 wool 15
setblock ~44 ~7 ~41 torch 5
setblock ~44 ~7 ~48 dirt 0
setblock ~44 ~7 ~50 dirt 0
fill ~44 ~7 ~51 ~54 ~7 ~51 wool 15
setblock ~44 ~7 ~110 torch 2
setblock ~44 ~7 ~114 torch 2
setblock ~44 ~7 ~118 torch 2
setblock ~44 ~7 ~121 torch 2
setblock ~44 ~7 ~124 torch 2
fill ~45 ~7 ~85 ~46 ~7 ~85 wool 15
fill ~46 ~7 ~104 ~54 ~7 ~104 wool 15
fill ~46 ~7 ~126 ~54 ~7 ~126 wool 15
fill ~47 ~7 ~14 ~49 ~7 ~14 wool 11
fill ~47 ~7 ~30 ~54 ~7 ~30 wool 15
fill ~47 ~7 ~40 ~47 ~15 ~40 wool 15
fill ~47 ~7 ~41 ~47 ~15 ~41 wool 15
fill ~47 ~7 ~52 ~47 ~8 ~52 wool 8
fill ~47 ~7 ~92 ~47 ~9 ~92 wool 15
fill ~47 ~7 ~96 ~47 ~9 ~96 wool 15
setblock ~47 ~7 ~136 wool 11
fill ~48 ~7 ~52 ~48 ~10 ~52 wool 7
fill ~48 ~7 ~58 ~48 ~10 ~58 wool 7
fill ~48 ~7 ~59 ~48 ~10 ~59 wool 7
fill ~48 ~7 ~64 ~53 ~7 ~64 wool 7
fill ~48 ~7 ~65 ~49 ~7 ~65 wool 7
fill ~48 ~7 ~66 ~49 ~7 ~66 wool 7
fill ~48 ~7 ~72 ~48 ~11 ~72 wool 7
fill ~48 ~7 ~73 ~48 ~11 ~73 wool 7
fill ~48 ~7 ~74 ~48 ~11 ~74 wool 7
fill ~48 ~7 ~75 ~48 ~11 ~75 wool 7
fill ~48 ~7 ~76 ~48 ~11 ~76 wool 7
fill ~48 ~7 ~77 ~48 ~11 ~77 wool 7
fill ~48 ~7 ~78 ~48 ~11 ~78 wool 7
fill ~48 ~7 ~79 ~48 ~11 ~79 wool 7
fill ~48 ~7 ~80 ~48 ~11 ~80 wool 7
fill ~48 ~7 ~81 ~48 ~11 ~81 wool 7
fill ~48 ~7 ~82 ~48 ~11 ~82 wool 7
fill ~48 ~7 ~83 ~48 ~11 ~83 wool 7
fill ~48 ~7 ~84 ~48 ~11 ~84 wool 7
setblock ~48 ~7 ~91 wool 8
setblock ~48 ~7 ~97 wool 8
fill ~48 ~7 ~98 ~52 ~7 ~98 wool 7
setblock ~48 ~7 ~134 torch 2
setblock ~48 ~7 ~135 wool 11
fill ~49 ~7 ~32 ~55 ~7 ~32 wool 15
fill ~49 ~7 ~48 ~49 ~10 ~48 wool 15
fill ~49 ~7 ~49 ~55 ~7 ~49 wool 15
fill ~49 ~7 ~61 ~53 ~7 ~61 wool 7
fill ~49 ~7 ~63 ~53 ~7 ~63 wool 7
setblock ~49 ~7 ~68 wool 11
setblock ~49 ~7 ~72 torch 3
setblock ~49 ~7 ~81 torch 4
fill ~49 ~7 ~86 ~49 ~10 ~86 wool 7
setblock ~49 ~7 ~87 wool 11
fill ~49 ~7 ~88 ~49 ~7 ~89 wool 7
fill ~49 ~7 ~100 ~53 ~7 ~100 wool 7
fill ~49 ~7 ~107 ~55 ~7 ~107 wool 15
fill ~49 ~7 ~124 ~55 ~7 ~124 wool 15
fill ~49 ~7 ~133 ~50 ~7 ~133 wool 11
fill ~49 ~7 ~134 ~49 ~7 ~133 wool 11
setblock ~50 ~7 ~15 wool 11
fill ~50 ~7 ~33 ~54 ~7 ~33 dirt 0
fill ~50 ~7 ~34 ~54 ~7 ~34 wool 8
fill ~50 ~7 ~47 ~54 ~7 ~47 wool 8
fill ~50 ~7 ~48 ~54 ~7 ~48 dirt 0
fill ~50 ~7 ~72 ~50 ~8 ~72 wool 7
fill ~50 ~7 ~73 ~50 ~8 ~73 wool 7
fill ~50 ~7 ~74 ~50 ~8 ~74 wool 7
fill ~50 ~7 ~75 ~50 ~8 ~75 wool 7
fill ~50 ~7 ~76 ~50 ~8 ~76 wool 7
fill ~50 ~7 ~77 ~50 ~8 ~77 wool 7
fill ~50 ~7 ~78 ~50 ~8 ~78 wool 7
fill ~50 ~7 ~79 ~50 ~8 ~79 wool 7
fill ~50 ~7 ~80 ~50 ~8 ~80 wool 7
fill ~50 ~7 ~81 ~50 ~8 ~81 wool 7
fill ~50 ~7 ~82 ~50 ~11 ~82 wool 7
fill ~50 ~7 ~83 ~50 ~8 ~83 dirt 0
fill ~50 ~7 ~84 ~50 ~8 ~84 dirt 0
setblock ~50 ~7 ~85 wool 7
fill ~50 ~7 ~109 ~54 ~7 ~109 wool 8
fill ~50 ~7 ~122 ~54 ~7 ~122 wool 8
fill ~51 ~7 ~16 ~51 ~8 ~16 wool 11
