fill ~1 ~-3 ~54 ~3 ~-3 ~54 wool 15
fill ~1 ~-3 ~55 ~4 ~-3 ~55 wool 15
setblock ~1 ~-3 ~56 wool 14
fill ~1 ~-3 ~57 ~1 ~-3 ~57 wool 15
fill ~1 ~-3 ~58 ~2 ~-3 ~58 wool 15
fill ~1 ~-3 ~59 ~2 ~-3 ~59 wool 14
fill ~1 ~-3 ~60 ~1 ~-3 ~59 wool 14
fill ~1 ~-3 ~61 ~1 ~-3 ~61 wool 15
fill ~1 ~-3 ~62 ~2 ~-3 ~62 wool 15
fill ~1 ~-3 ~63 ~1 ~-3 ~61 wool 15
fill ~1 ~-3 ~64 ~3 ~-3 ~64 wool 14
fill ~1 ~-3 ~65 ~3 ~-3 ~65 wool 15
fill ~1 ~-3 ~66 ~2 ~-3 ~66 wool 14
fill ~1 ~-3 ~67 ~1 ~-3 ~67 wool 15
fill ~1 ~-3 ~68 ~1 ~-3 ~68 wool 14
fill ~1 ~-3 ~69 ~1 ~-3 ~71 wool 14
setblock ~1 ~-3 ~72 wool 15
fill ~1 ~-3 ~73 ~1 ~-3 ~73 wool 14
fill ~1 ~-3 ~74 ~1 ~-3 ~74 wool 15
fill ~1 ~-3 ~75 ~3 ~-3 ~75 wool 14
fill ~1 ~-3 ~76 ~1 ~-3 ~85 wool 14
fill ~1 ~-3 ~86 ~3 ~-3 ~86 wool 15
fill ~2 ~-3 ~56 ~5 ~-3 ~56 wool 15
setblock ~2 ~-3 ~57 wool 14
fill ~2 ~-3 ~60 ~3 ~-3 ~60 wool 15
setblock ~2 ~-3 ~61 wool 14
setblock ~2 ~-3 ~63 wool 14
setblock ~2 ~-3 ~67 wool 14
fill ~2 ~-3 ~68 ~2 ~-3 ~70 wool 15
fill ~2 ~-3 ~71 ~2 ~-3 ~72 wool 14
setblock ~2 ~-3 ~73 wool 15
fill ~2 ~-3 ~74 ~3 ~-3 ~74 wool 14
setblock ~2 ~-3 ~76 wool 15
fill ~2 ~-3 ~77 ~2 ~-3 ~85 wool 14
fill ~3 ~-3 ~57 ~5 ~-3 ~57 wool 15
setblock ~3 ~-3 ~58 wool 14
setblock ~3 ~-3 ~59 wool 15
fill ~3 ~-3 ~61 ~5 ~-3 ~61 wool 15
fill ~3 ~-3 ~62 ~4 ~-3 ~62 wool 14
fill ~3 ~-3 ~63 ~5 ~-3 ~63 wool 15
fill ~3 ~-3 ~66 ~5 ~-3 ~66 wool 15
fill ~3 ~-3 ~67 ~3 ~-3 ~65 wool 15
fill ~3 ~-3 ~68 ~3 ~-3 ~70 wool 14
setblock ~3 ~-3 ~71 wool 15
fill ~3 ~-3 ~72 ~4 ~-3 ~72 wool 14
fill ~3 ~-3 ~73 ~4 ~-3 ~73 wool 14
fill ~3 ~-3 ~76 ~4 ~-3 ~76 wool 14
setblock ~3 ~-3 ~77 wool 15
fill ~3 ~-3 ~78 ~4 ~-3 ~78 wool 14
fill ~3 ~-3 ~79 ~4 ~-3 ~79 wool 14
fill ~3 ~-3 ~80 ~4 ~-3 ~80 wool 14
fill ~3 ~-3 ~81 ~4 ~-3 ~81 wool 14
fill ~3 ~-3 ~82 ~4 ~-3 ~82 wool 14
fill ~3 ~-3 ~83 ~4 ~-3 ~83 wool 14
fill ~3 ~-3 ~84 ~4 ~-3 ~84 wool 14
fill ~3 ~-3 ~85 ~3 ~-3 ~78 wool 14
fill ~4 ~-3 ~58 ~5 ~-3 ~58 wool 15
fill ~4 ~-3 ~59 ~4 ~-3 ~60 wool 14
fill ~4 ~-3 ~64 ~5 ~-3 ~64 wool 15
setblock ~4 ~-3 ~65 wool 14
setblock ~4 ~-3 ~67 wool 14
fill ~4 ~-3 ~68 ~5 ~-3 ~68 wool 15
fill ~4 ~-3 ~69 ~5 ~-3 ~69 wool 15
fill ~4 ~-3 ~70 ~4 ~-3 ~73 wool 14
fill ~4 ~-3 ~74 ~5 ~-3 ~74 wool 15
fill ~4 ~-3 ~75 ~5 ~-3 ~75 wool 15
setblock ~4 ~-3 ~77 wool 14
setblock ~4 ~-3 ~85 wool 15
fill ~5 ~-3 ~59 ~5 ~-3 ~84 wool 15
fill ~8 ~-3 ~0 ~39 ~-3 ~0 wool 7
fill ~8 ~-3 ~1 ~39 ~-3 ~1 wool 7
fill ~8 ~-3 ~2 ~39 ~-3 ~2 wool 7
fill ~8 ~-3 ~3 ~39 ~-3 ~3 wool 7
fill ~8 ~-3 ~4 ~39 ~-3 ~4 wool 7
fill ~8 ~-3 ~5 ~39 ~-3 ~5 wool 7
fill ~8 ~-3 ~6 ~39 ~-3 ~6 wool 7
fill ~8 ~-3 ~7 ~39 ~-3 ~7 wool 7
fill ~8 ~-3 ~8 ~39 ~-3 ~8 wool 7
fill ~8 ~-3 ~9 ~39 ~-3 ~9 wool 7
fill ~8 ~-3 ~10 ~39 ~-3 ~10 wool 7
fill ~8 ~-3 ~11 ~39 ~-3 ~11 wool 7
fill ~8 ~-3 ~12 ~39 ~-3 ~12 wool 7
fill ~8 ~-3 ~13 ~39 ~-3 ~13 wool 7
fill ~8 ~-3 ~14 ~39 ~-3 ~14 wool 7
fill ~8 ~-3 ~15 ~39 ~-3 ~15 wool 7
fill ~8 ~-3 ~16 ~39 ~-3 ~16 wool 7
fill ~8 ~-3 ~17 ~39 ~-3 ~17 wool 7
fill ~8 ~-3 ~18 ~39 ~-3 ~18 wool 7
fill ~8 ~-3 ~19 ~39 ~-3 ~19 wool 7
fill ~8 ~-3 ~20 ~39 ~-3 ~20 wool 7
fill ~8 ~-3 ~21 ~39 ~-3 ~21 wool 7
fill ~8 ~-3 ~22 ~39 ~-3 ~22 wool 7
fill ~8 ~-3 ~23 ~39 ~-3 ~23 wool 7
fill ~8 ~-3 ~24 ~39 ~-3 ~24 wool 7
fill ~8 ~-3 ~25 ~39 ~-3 ~25 wool 7
fill ~8 ~-3 ~26 ~39 ~-3 ~26 wool 7
fill ~8 ~-3 ~27 ~39 ~-3 ~27 wool 7
fill ~8 ~-3 ~28 ~39 ~-3 ~28 wool 7
fill ~8 ~-3 ~29 ~39 ~-3 ~29 wool 7
fill ~8 ~-3 ~30 ~39 ~-3 ~30 wool 7
fill ~8 ~-3 ~31 ~39 ~-3 ~31 wool 7
fill ~8 ~-3 ~32 ~39 ~-3 ~32 wool 7
fill ~8 ~-3 ~33 ~39 ~-3 ~33 wool 7
fill ~8 ~-3 ~34 ~39 ~-3 ~34 wool 7
fill ~8 ~-3 ~35 ~39 ~-3 ~35 wool 7
fill ~8 ~-3 ~36 ~39 ~-3 ~36 wool 7
fill ~8 ~-3 ~37 ~39 ~-3 ~37 wool 7
fill ~8 ~-3 ~38 ~39 ~-3 ~38 wool 7
fill ~8 ~-3 ~39 ~39 ~-3 ~39 wool 7
fill ~8 ~-3 ~40 ~39 ~-3 ~40 wool 7
fill ~8 ~-3 ~41 ~39 ~-3 ~41 wool 7
fill ~8 ~-3 ~42 ~39 ~-3 ~42 wool 7
fill ~8 ~-3 ~43 ~39 ~-3 ~43 wool 7
fill ~8 ~-3 ~44 ~39 ~-3 ~44 wool 7
fill ~8 ~-3 ~45 ~39 ~-3 ~45 wool 7
fill ~8 ~-3 ~46 ~39 ~-3 ~46 wool 7
fill ~8 ~-3 ~47 ~39 ~-3 ~47 wool 7
fill ~8 ~-3 ~48 ~39 ~-3 ~48 wool 7
fill ~8 ~-3 ~49 ~39 ~-3 ~49 wool 7
fill ~8 ~-3 ~50 ~39 ~-3 ~50 wool 7
fill ~8 ~-3 ~51 ~39 ~-3 ~51 wool 7
fill ~8 ~-3 ~52 ~39 ~-3 ~52 wool 7
fill ~8 ~-3 ~53 ~39 ~-3 ~53 wool 7
fill ~8 ~-3 ~54 ~39 ~-3 ~54 wool 7
fill ~8 ~-3 ~55 ~39 ~-3 ~55 wool 7
fill ~8 ~-3 ~56 ~39 ~-3 ~56 wool 7
fill ~8 ~-3 ~57 ~39 ~-3 ~57 wool 7
fill ~8 ~-3 ~58 ~39 ~-3 ~58 wool 7
fill ~8 ~-3 ~59 ~39 ~-3 ~59 wool 7
fill ~8 ~-3 ~60 ~39 ~-3 ~60 wool 7
fill ~8 ~-3 ~61 ~39 ~-3 ~61 wool 7
fill ~8 ~-3 ~62 ~39 ~-3 ~62 wool 7
fill ~8 ~-3 ~63 ~39 ~-3 ~63 wool 7
fill ~8 ~-3 ~64 ~39 ~-3 ~64 wool 7
fill ~8 ~-3 ~65 ~39 ~-3 ~65 wool 7
fill ~8 ~-3 ~66 ~39 ~-3 ~66 wool 7
fill ~8 ~-3 ~67 ~39 ~-3 ~67 wool 7
fill ~8 ~-3 ~68 ~39 ~-3 ~68 wool 7
fill ~8 ~-3 ~69 ~39 ~-3 ~69 wool 7
fill ~8 ~-3 ~70 ~39 ~-3 ~70 wool 7
fill ~8 ~-3 ~71 ~39 ~-3 ~71 wool 7
fill ~8 ~-3 ~72 ~39 ~-3 ~72 wool 7
fill ~8 ~-3 ~73 ~39 ~-3 ~73 wool 7
fill ~8 ~-3 ~74 ~39 ~-3 ~74 wool 7
fill ~8 ~-3 ~75 ~39 ~-3 ~75 wool 7
fill ~8 ~-3 ~76 ~39 ~-3 ~76 wool 7
fill ~8 ~-3 ~77 ~39 ~-3 ~77 wool 7
fill ~8 ~-3 ~78 ~39 ~-3 ~78 wool 7
fill ~8 ~-3 ~79 ~39 ~-3 ~79 wool 7
fill ~8 ~-3 ~80 ~39 ~-3 ~80 wool 7
fill ~8 ~-3 ~81 ~39 ~-3 ~81 wool 7
fill ~8 ~-3 ~82 ~39 ~-3 ~82 wool 7
fill ~9 ~-3 ~83 ~38 ~-3 ~83 wool 7
fill ~10 ~-3 ~84 ~37 ~-3 ~84 wool 7
fill ~8 ~-2 ~0 ~39 ~-2 ~0 wool 7
fill ~8 ~-2 ~1 ~8 ~73 ~1 wool 7
fill ~8 ~-2 ~2 ~8 ~73 ~2 wool 7
fill ~8 ~-2 ~3 ~8 ~73 ~3 wool 7
fill ~8 ~-2 ~4 ~8 ~9 ~4 wool 7
fill ~8 ~-2 ~5 ~8 ~7 ~5 wool 7
fill ~8 ~-2 ~6 ~8 ~6 ~6 wool 7
fill ~8 ~-2 ~7 ~8 ~5 ~7 wool 7
fill ~8 ~-2 ~8 ~8 ~5 ~8 wool 7
fill ~8 ~-2 ~9 ~8 ~4 ~9 wool 7
fill ~8 ~-2 ~10 ~8 ~4 ~10 wool 7
fill ~8 ~-2 ~11 ~8 ~4 ~11 wool 7
fill ~8 ~-2 ~12 ~8 ~4 ~12 wool 7
fill ~8 ~-2 ~13 ~8 ~4 ~13 wool 7
fill ~8 ~-2 ~14 ~8 ~4 ~14 wool 7
fill ~8 ~-2 ~15 ~8 ~4 ~15 wool 7
fill ~8 ~-2 ~16 ~8 ~4 ~16 wool 7
fill ~8 ~-2 ~17 ~8 ~4 ~17 wool 7
fill ~8 ~-2 ~18 ~8 ~4 ~18 wool 7
fill ~8 ~-2 ~19 ~8 ~4 ~19 wool 7
fill ~8 ~-2 ~20 ~8 ~4 ~20 wool 7
fill ~8 ~-2 ~21 ~8 ~4 ~21 wool 7
fill ~8 ~-2 ~22 ~8 ~4 ~22 wool 7
fill ~8 ~-2 ~23 ~8 ~4 ~23 wool 7
fill ~8 ~-2 ~24 ~8 ~4 ~24 wool 7
fill ~8 ~-2 ~25 ~8 ~4 ~25 wool 7
fill ~8 ~-2 ~26 ~8 ~4 ~26 wool 7
fill ~8 ~-2 ~27 ~8 ~4 ~27 wool 7
fill ~8 ~-2 ~28 ~8 ~4 ~28 wool 7
fill ~8 ~-2 ~29 ~8 ~4 ~29 wool 7
fill ~8 ~-2 ~30 ~8 ~4 ~30 wool 7
fill ~8 ~-2 ~31 ~8 ~4 ~31 wool 7
fill ~8 ~-2 ~32 ~8 ~4 ~32 wool 7
fill ~8 ~-2 ~33 ~8 ~4 ~33 wool 7
fill ~8 ~-2 ~34 ~8 ~4 ~34 wool 7
fill ~8 ~-2 ~35 ~8 ~4 ~35 wool 7
fill ~8 ~-2 ~36 ~8 ~4 ~36 wool 7
fill ~8 ~-2 ~37 ~8 ~4 ~37 wool 7
fill ~8 ~-2 ~38 ~8 ~4 ~38 wool 7
fill ~8 ~-2 ~39 ~8 ~4 ~39 wool 7
fill ~8 ~-2 ~40 ~8 ~4 ~40 wool 7
fill ~8 ~-2 ~41 ~8 ~4 ~41 wool 7
fill ~8 ~-2 ~42 ~8 ~4 ~42 wool 7
fill ~8 ~-2 ~43 ~8 ~4 ~43 wool 7
fill ~8 ~-2 ~44 ~8 ~4 ~44 wool 7
fill ~8 ~-2 ~45 ~8 ~4 ~45 wool 7
fill ~8 ~-2 ~46 ~8 ~4 ~46 wool 7
fill ~8 ~-2 ~47 ~8 ~4 ~47 wool 7
fill ~8 ~-2 ~48 ~8 ~4 ~48 wool 7
fill ~8 ~-2 ~49 ~8 ~4 ~49 wool 7
fill ~8 ~-2 ~50 ~8 ~4 ~50 wool 7
fill ~8 ~-2 ~51 ~8 ~4 ~51 wool 7
fill ~8 ~-2 ~52 ~8 ~4 ~52 wool 7
fill ~8 ~-2 ~53 ~8 ~4 ~53 wool 7
fill ~8 ~-2 ~54 ~8 ~4 ~54 wool 7
fill ~8 ~-2 ~55 ~8 ~4 ~55 wool 7
fill ~8 ~-2 ~56 ~8 ~4 ~56 wool 7
fill ~8 ~-2 ~57 ~8 ~4 ~57 wool 7
fill ~8 ~-2 ~58 ~8 ~4 ~58 wool 7
fill ~8 ~-2 ~59 ~8 ~4 ~59 wool 7
fill ~8 ~-2 ~60 ~8 ~4 ~60 wool 7
fill ~8 ~-2 ~61 ~8 ~4 ~61 wool 7
fill ~8 ~-2 ~62 ~8 ~4 ~62 wool 7
fill ~8 ~-2 ~63 ~8 ~4 ~63 wool 7
fill ~8 ~-2 ~64 ~8 ~4 ~64 wool 7
fill ~8 ~-2 ~65 ~8 ~4 ~65 wool 7
fill ~8 ~-2 ~66 ~8 ~4 ~66 wool 7
fill ~8 ~-2 ~67 ~8 ~4 ~67 wool 7
fill ~8 ~-2 ~68 ~8 ~4 ~68 wool 7
fill ~8 ~-2 ~69 ~8 ~4 ~69 wool 7
fill ~8 ~-2 ~70 ~8 ~5 ~70 wool 7
fill ~8 ~-2 ~71 ~8 ~6 ~71 wool 7
fill ~8 ~-2 ~72 ~8 ~7 ~72 wool 7
fill ~8 ~-2 ~73 ~8 ~8 ~73 wool 7
fill ~8 ~-2 ~74 ~8 ~9 ~74 wool 7
fill ~8 ~-2 ~75 ~8 ~10 ~75 wool 7
fill ~8 ~-2 ~76 ~8 ~11 ~76 wool 7
fill ~8 ~-2 ~77 ~8 ~12 ~77 wool 7
fill ~8 ~-2 ~78 ~8 ~13 ~78 wool 7
fill ~8 ~-2 ~79 ~8 ~14 ~79 wool 7
fill ~8 ~-2 ~80 ~8 ~73 ~80 wool 7
fill ~8 ~-2 ~81 ~8 ~76 ~81 wool 7
fill ~8 ~-2 ~82 ~8 ~73 ~82 wool 7
fill ~9 ~-2 ~83 ~12 ~-2 ~83 wool 7
fill ~10 ~-2 ~84 ~37 ~-2 ~84 wool 7
fill ~13 ~-2 ~59 ~37 ~-2 ~59 wool 15
fill ~13 ~-2 ~60 ~13 ~-2 ~80 wool 15
fill ~13 ~-2 ~82 ~34 ~-2 ~82 wool 15
fill ~13 ~-2 ~83 ~34 ~-2 ~83 wool 15
fill ~13 ~-2 ~85 ~34 ~-2 ~85 wool 7
fill ~14 ~-2 ~80 ~37 ~-2 ~80 wool 15
fill ~35 ~-2 ~83 ~38 ~-2 ~83 wool 7
fill ~37 ~-2 ~60 ~37 ~-2 ~80 wool 15
fill ~39 ~-2 ~1 ~39 ~73 ~1 wool 7
fill ~39 ~-2 ~2 ~39 ~73 ~2 wool 7
fill ~39 ~-2 ~3 ~39 ~73 ~3 wool 7
fill ~39 ~-2 ~4 ~39 ~9 ~4 wool 7
fill ~39 ~-2 ~5 ~39 ~7 ~5 wool 7
fill ~39 ~-2 ~6 ~39 ~6 ~6 wool 7
fill ~39 ~-2 ~7 ~39 ~5 ~7 wool 7
fill ~39 ~-2 ~8 ~39 ~5 ~8 wool 7
fill ~39 ~-2 ~9 ~39 ~4 ~9 wool 7
fill ~39 ~-2 ~10 ~39 ~4 ~10 wool 7
fill ~39 ~-2 ~11 ~39 ~4 ~11 wool 7
fill ~39 ~-2 ~12 ~39 ~4 ~12 wool 7
fill ~39 ~-2 ~13 ~39 ~4 ~13 wool 7
fill ~39 ~-2 ~14 ~39 ~4 ~14 wool 7
fill ~39 ~-2 ~15 ~39 ~4 ~15 wool 7
fill ~39 ~-2 ~16 ~39 ~4 ~16 wool 7
fill ~39 ~-2 ~17 ~39 ~4 ~17 wool 7
fill ~39 ~-2 ~18 ~39 ~4 ~18 wool 7
fill ~39 ~-2 ~19 ~39 ~4 ~19 wool 7
fill ~39 ~-2 ~20 ~39 ~4 ~20 wool 7
fill ~39 ~-2 ~21 ~39 ~4 ~21 wool 7
fill ~39 ~-2 ~22 ~39 ~4 ~22 wool 7
fill ~39 ~-2 ~23 ~39 ~4 ~23 wool 7
fill ~39 ~-2 ~24 ~39 ~4 ~24 wool 7
fill ~39 ~-2 ~25 ~39 ~4 ~25 wool 7
fill ~39 ~-2 ~26 ~39 ~4 ~26 wool 7
fill ~39 ~-2 ~27 ~39 ~4 ~27 wool 7
fill ~39 ~-2 ~28 ~39 ~4 ~28 wool 7
fill ~39 ~-2 ~29 ~39 ~4 ~29 wool 7
fill ~39 ~-2 ~30 ~39 ~4 ~30 wool 7
fill ~39 ~-2 ~31 ~39 ~4 ~31 wool 7
fill ~39 ~-2 ~32 ~39 ~4 ~32 wool 7
fill ~39 ~-2 ~33 ~39 ~4 ~33 wool 7
fill ~39 ~-2 ~34 ~39 ~4 ~34 wool 7
fill ~39 ~-2 ~35 ~39 ~4 ~35 wool 7
fill ~39 ~-2 ~36 ~39 ~4 ~36 wool 7
fill ~39 ~-2 ~37 ~39 ~4 ~37 wool 7
fill ~39 ~-2 ~38 ~39 ~4 ~38 wool 7
fill ~39 ~-2 ~39 ~39 ~4 ~39 wool 7
fill ~39 ~-2 ~40 ~39 ~4 ~40 wool 7
fill ~39 ~-2 ~41 ~39 ~4 ~41 wool 7
fill ~39 ~-2 ~42 ~39 ~4 ~42 wool 7
fill ~39 ~-2 ~43 ~39 ~4 ~43 wool 7
fill ~39 ~-2 ~44 ~39 ~4 ~44 wool 7
fill ~39 ~-2 ~45 ~39 ~4 ~45 wool 7
fill ~39 ~-2 ~46 ~39 ~4 ~46 wool 7
fill ~39 ~-2 ~47 ~39 ~4 ~47 wool 7
fill ~39 ~-2 ~48 ~39 ~4 ~48 wool 7
fill ~39 ~-2 ~49 ~39 ~4 ~49 wool 7
fill ~39 ~-2 ~50 ~39 ~4 ~50 wool 7
fill ~39 ~-2 ~51 ~39 ~4 ~51 wool 7
fill ~39 ~-2 ~52 ~39 ~4 ~52 wool 7
fill ~39 ~-2 ~53 ~39 ~4 ~53 wool 7
fill ~39 ~-2 ~54 ~39 ~4 ~54 wool 7
fill ~39 ~-2 ~55 ~39 ~4 ~55 wool 7
fill ~39 ~-2 ~56 ~39 ~4 ~56 wool 7
fill ~39 ~-2 ~57 ~39 ~4 ~57 wool 7
fill ~39 ~-2 ~58 ~39 ~4 ~58 wool 7
fill ~39 ~-2 ~59 ~39 ~4 ~59 wool 7
fill ~39 ~-2 ~60 ~39 ~4 ~60 wool 7
fill ~39 ~-2 ~61 ~39 ~4 ~61 wool 7
fill ~39 ~-2 ~62 ~39 ~4 ~62 wool 7
fill ~39 ~-2 ~63 ~39 ~4 ~63 wool 7
fill ~39 ~-2 ~64 ~39 ~4 ~64 wool 7
fill ~39 ~-2 ~65 ~39 ~4 ~65 wool 7
fill ~39 ~-2 ~66 ~39 ~4 ~66 wool 7
fill ~39 ~-2 ~67 ~39 ~4 ~67 wool 7
fill ~39 ~-2 ~68 ~39 ~4 ~68 wool 7
fill ~39 ~-2 ~69 ~39 ~4 ~69 wool 7
fill ~39 ~-2 ~70 ~39 ~5 ~70 wool 7
fill ~39 ~-2 ~71 ~39 ~6 ~71 wool 7
fill ~39 ~-2 ~72 ~39 ~7 ~72 wool 7
fill ~39 ~-2 ~73 ~39 ~8 ~73 wool 7
fill ~39 ~-2 ~74 ~39 ~9 ~74 wool 7
fill ~39 ~-2 ~75 ~39 ~10 ~75 wool 7
fill ~39 ~-2 ~76 ~39 ~11 ~76 wool 7
fill ~39 ~-2 ~77 ~39 ~12 ~77 wool 7
fill ~39 ~-2 ~78 ~39 ~13 ~78 wool 7
fill ~39 ~-2 ~79 ~39 ~14 ~79 wool 7
fill ~39 ~-2 ~80 ~39 ~73 ~80 wool 7
fill ~39 ~-2 ~81 ~39 ~76 ~81 wool 7
fill ~39 ~-2 ~82 ~39 ~73 ~82 wool 7
fill ~8 ~-1 ~0 ~9 ~-1 ~0 wool 7
fill ~9 ~-1 ~83 ~12 ~-1 ~83 wool 7
fill ~10 ~-1 ~0 ~36 ~-1 ~0 wool 15
fill ~10 ~-1 ~1 ~36 ~-1 ~1 wool 15
fill ~10 ~-1 ~2 ~36 ~-1 ~2 wool 15
fill ~10 ~-1 ~3 ~36 ~-1 ~3 wool 15
fill ~10 ~-1 ~4 ~36 ~-1 ~4 wool 15
fill ~10 ~-1 ~5 ~36 ~-1 ~5 wool 15
fill ~10 ~-1 ~6 ~36 ~-1 ~6 wool 15
fill ~10 ~-1 ~7 ~36 ~-1 ~7 wool 15
fill ~10 ~-1 ~8 ~36 ~-1 ~8 wool 15
fill ~10 ~-1 ~9 ~36 ~-1 ~9 wool 15
fill ~10 ~-1 ~10 ~36 ~-1 ~10 wool 15
fill ~10 ~-1 ~11 ~36 ~-1 ~11 wool 15
fill ~10 ~-1 ~12 ~36 ~-1 ~12 wool 15
fill ~10 ~-1 ~13 ~36 ~-1 ~13 wool 15
fill ~10 ~-1 ~14 ~36 ~-1 ~14 wool 15
fill ~10 ~-1 ~15 ~36 ~-1 ~15 wool 15
fill ~10 ~-1 ~16 ~36 ~-1 ~16 wool 15
fill ~10 ~-1 ~17 ~36 ~-1 ~17 wool 15
fill ~10 ~-1 ~18 ~36 ~-1 ~18 wool 15
fill ~10 ~-1 ~19 ~36 ~-1 ~19 wool 15
fill ~10 ~-1 ~20 ~36 ~-1 ~20 wool 15
fill ~10 ~-1 ~21 ~36 ~-1 ~21 wool 15
fill ~10 ~-1 ~22 ~36 ~-1 ~22 wool 15
fill ~10 ~-1 ~23 ~36 ~-1 ~23 wool 15
fill ~10 ~-1 ~24 ~36 ~-1 ~24 wool 15
fill ~10 ~-1 ~25 ~36 ~-1 ~25 wool 15
fill ~10 ~-1 ~26 ~36 ~-1 ~26 wool 15
fill ~10 ~-1 ~27 ~36 ~-1 ~27 wool 15
fill ~10 ~-1 ~28 ~36 ~-1 ~28 wool 15
fill ~10 ~-1 ~29 ~36 ~-1 ~29 wool 15
fill ~10 ~-1 ~30 ~10 ~13 ~30 wool 15
fill ~10 ~-1 ~31 ~10 ~13 ~31 wool 15
fill ~10 ~-1 ~32 ~10 ~13 ~32 wool 15
fill ~10 ~-1 ~33 ~10 ~13 ~33 wool 15
fill ~10 ~-1 ~34 ~10 ~13 ~34 wool 15
fill ~10 ~-1 ~35 ~10 ~13 ~35 wool 15
fill ~10 ~-1 ~36 ~10 ~13 ~36 wool 15
fill ~10 ~-1 ~37 ~10 ~13 ~37 wool 15
fill ~10 ~-1 ~38 ~10 ~13 ~38 wool 15
fill ~10 ~-1 ~39 ~10 ~13 ~39 wool 15
fill ~10 ~-1 ~40 ~10 ~13 ~40 wool 15
fill ~10 ~-1 ~41 ~10 ~13 ~41 wool 15
fill ~10 ~-1 ~42 ~10 ~13 ~42 wool 15
fill ~10 ~-1 ~43 ~10 ~13 ~43 wool 15
fill ~10 ~-1 ~44 ~10 ~13 ~44 wool 15
fill ~10 ~-1 ~45 ~10 ~13 ~45 wool 15
fill ~10 ~-1 ~46 ~10 ~13 ~46 wool 15
fill ~10 ~-1 ~47 ~10 ~13 ~47 wool 15
fill ~10 ~-1 ~48 ~10 ~13 ~48 wool 15
fill ~10 ~-1 ~49 ~10 ~13 ~49 wool 15
fill ~10 ~-1 ~50 ~10 ~13 ~50 wool 15
fill ~10 ~-1 ~51 ~10 ~13 ~51 wool 15
fill ~10 ~-1 ~52 ~10 ~13 ~52 wool 15
fill ~10 ~-1 ~53 ~10 ~13 ~53 wool 15
fill ~10 ~-1 ~54 ~10 ~13 ~54 wool 15
fill ~10 ~-1 ~55 ~36 ~-1 ~55 wool 15
fill ~13 ~-1 ~59 ~13 ~32 ~59 wool 15
fill ~13 ~-1 ~80 ~13 ~32 ~80 wool 15
fill ~13 ~-1 ~82 ~13 ~34 ~82 wool 15
fill ~13 ~-1 ~83 ~13 ~69 ~83 wool 15
fill ~13 ~-1 ~84 ~13 ~69 ~84 wool 7
fill ~13 ~-1 ~85 ~13 ~1 ~85 wool 7
fill ~14 ~-1 ~82 ~33 ~-1 ~82 wool 14
fill ~14 ~-1 ~84 ~33 ~-1 ~84 wool 15
fill ~34 ~-1 ~82 ~34 ~34 ~82 wool 15
fill ~34 ~-1 ~83 ~34 ~69 ~83 wool 15
fill ~34 ~-1 ~84 ~34 ~69 ~84 wool 7
fill ~34 ~-1 ~85 ~34 ~1 ~85 wool 7
fill ~35 ~-1 ~83 ~38 ~-1 ~83 wool 7
fill ~36 ~-1 ~30 ~36 ~13 ~30 wool 15
fill ~36 ~-1 ~31 ~36 ~13 ~31 wool 15
fill ~36 ~-1 ~32 ~36 ~13 ~32 wool 15
fill ~36 ~-1 ~33 ~36 ~13 ~33 wool 15
fill ~36 ~-1 ~34 ~36 ~13 ~34 wool 15
fill ~36 ~-1 ~35 ~36 ~13 ~35 wool 15
fill ~36 ~-1 ~36 ~36 ~13 ~36 wool 15
fill ~36 ~-1 ~37 ~36 ~13 ~37 wool 15
fill ~36 ~-1 ~38 ~36 ~13 ~38 wool 15
fill ~36 ~-1 ~39 ~36 ~13 ~39 wool 15
fill ~36 ~-1 ~40 ~36 ~13 ~40 wool 15
fill ~36 ~-1 ~41 ~36 ~13 ~41 wool 15
fill ~36 ~-1 ~42 ~36 ~13 ~42 wool 15
fill ~36 ~-1 ~43 ~36 ~13 ~43 wool 15
fill ~36 ~-1 ~44 ~36 ~13 ~44 wool 15
fill ~36 ~-1 ~45 ~36 ~13 ~45 wool 15
fill ~36 ~-1 ~46 ~36 ~13 ~46 wool 15
fill ~36 ~-1 ~47 ~36 ~13 ~47 wool 15
fill ~36 ~-1 ~48 ~36 ~13 ~48 wool 15
fill ~36 ~-1 ~49 ~36 ~13 ~49 wool 15
fill ~36 ~-1 ~50 ~36 ~13 ~50 wool 15
fill ~36 ~-1 ~51 ~36 ~13 ~51 wool 15
fill ~36 ~-1 ~52 ~36 ~13 ~52 wool 15
fill ~36 ~-1 ~53 ~36 ~13 ~53 wool 15
fill ~36 ~-1 ~54 ~36 ~13 ~54 wool 15
fill ~37 ~-1 ~0 ~39 ~-1 ~0 wool 7
fill ~37 ~-1 ~59 ~37 ~66 ~59 wool 15
fill ~37 ~-1 ~80 ~37 ~32 ~80 wool 15
fill ~8 ~0 ~0 ~9 ~0 ~0 wool 7
fill ~9 ~0 ~83 ~12 ~0 ~83 wool 7
fill ~10 ~0 ~0 ~10 ~9 ~0 wool 15
fill ~10 ~0 ~1 ~10 ~9 ~1 wool 15
fill ~10 ~0 ~2 ~35 ~0 ~2 wool 8
fill ~10 ~0 ~3 ~10 ~3 ~3 wool 8
fill ~10 ~0 ~4 ~10 ~8 ~4 snow 0
fill ~10 ~0 ~5 ~10 ~3 ~5 wool 8
fill ~10 ~0 ~6 ~10 ~1 ~6 wool 8
fill ~10 ~0 ~7 ~10 ~0 ~5 wool 8
fill ~10 ~0 ~8 ~10 ~0 ~9 snow 0
fill ~10 ~0 ~10 ~10 ~0 ~14 wool 8
fill ~10 ~0 ~15 ~10 ~0 ~16 snow 0
fill ~10 ~0 ~17 ~10 ~0 ~21 wool 8
fill ~10 ~0 ~22 ~10 ~0 ~23 snow 0
fill ~10 ~0 ~24 ~10 ~0 ~26 wool 8
fill ~10 ~0 ~27 ~10 ~9 ~27 wool 15
fill ~10 ~0 ~28 ~10 ~9 ~28 wool 15
fill ~10 ~0 ~29 ~36 ~0 ~29 wool 15
fill ~10 ~0 ~55 ~36 ~0 ~55 wool 15
fill ~11 ~0 ~0 ~35 ~0 ~0 iron_bars 0
fill ~14 ~0 ~82 ~33 ~0 ~82 wool 14
fill ~14 ~0 ~84 ~14 ~31 ~84 wool 15
setblock ~15 ~0 ~84 iron_bars 14
fill ~16 ~0 ~84 ~17 ~0 ~84 iron_bars 0
setblock ~18 ~0 ~84 iron_bars 15
fill ~19 ~0 ~84 ~21 ~0 ~84 iron_bars 0
setblock ~22 ~0 ~84 iron_bars 15
fill ~23 ~0 ~84 ~24 ~0 ~84 iron_bars 0
setblock ~25 ~0 ~84 iron_bars 15
fill ~26 ~0 ~84 ~28 ~0 ~84 iron_bars 0
setblock ~29 ~0 ~84 iron_bars 15
fill ~30 ~0 ~84 ~31 ~0 ~84 iron_bars 0
setblock ~32 ~0 ~84 iron_bars 15
fill ~33 ~0 ~84 ~33 ~31 ~84 wool 15
fill ~35 ~0 ~83 ~38 ~0 ~83 wool 7
fill ~36 ~0 ~0 ~36 ~9 ~0 wool 15
fill ~36 ~0 ~1 ~36 ~9 ~1 wool 15
fill ~36 ~0 ~2 ~36 ~9 ~2 wool 15
fill ~36 ~0 ~3 ~36 ~9 ~3 wool 15
fill ~36 ~0 ~4 ~36 ~9 ~4 wool 15
fill ~36 ~0 ~5 ~36 ~9 ~5 wool 15
fill ~36 ~0 ~6 ~36 ~9 ~6 wool 15
fill ~36 ~0 ~7 ~36 ~9 ~7 wool 15
fill ~36 ~0 ~8 ~36 ~9 ~8 wool 15
fill ~36 ~0 ~9 ~36 ~9 ~9 wool 15
fill ~36 ~0 ~10 ~36 ~9 ~10 wool 15
fill ~36 ~0 ~11 ~36 ~9 ~11 wool 15
fill ~36 ~0 ~12 ~36 ~9 ~12 wool 15
fill ~36 ~0 ~13 ~36 ~9 ~13 wool 15
fill ~36 ~0 ~14 ~36 ~9 ~14 wool 15
fill ~36 ~0 ~15 ~36 ~9 ~15 wool 15
fill ~36 ~0 ~16 ~36 ~9 ~16 wool 15
fill ~36 ~0 ~17 ~36 ~9 ~17 wool 15
fill ~36 ~0 ~18 ~36 ~9 ~18 wool 15
fill ~36 ~0 ~19 ~36 ~9 ~19 wool 15
fill ~36 ~0 ~20 ~36 ~9 ~20 wool 15
fill ~36 ~0 ~21 ~36 ~9 ~21 wool 15
fill ~36 ~0 ~22 ~36 ~9 ~22 wool 15
fill ~36 ~0 ~23 ~36 ~9 ~23 wool 15
fill ~36 ~0 ~24 ~36 ~9 ~24 wool 15
fill ~36 ~0 ~25 ~36 ~9 ~25 wool 15
fill ~36 ~0 ~26 ~36 ~9 ~26 wool 15
fill ~36 ~0 ~27 ~36 ~9 ~27 wool 15
fill ~36 ~0 ~28 ~36 ~9 ~28 wool 15
fill ~37 ~0 ~0 ~39 ~0 ~0 wool 7
fill ~8 ~1 ~0 ~9 ~1 ~0 wool 7
fill ~9 ~1 ~83 ~12 ~1 ~83 wool 7
fill ~10 ~1 ~2 ~35 ~1 ~2 wool 8
setblock ~10 ~1 ~7 snow 0
fill ~10 ~1 ~8 ~10 ~3 ~8 wool 8
fill ~10 ~1 ~9 ~10 ~3 ~9 wool 8
setblock ~10 ~1 ~10 snow 0
fill ~10 ~1 ~11 ~10 ~1 ~13 wool 8
setblock ~10 ~1 ~14 snow 0
fill ~10 ~1 ~15 ~10 ~3 ~15 wool 8
fill ~10 ~1 ~16 ~10 ~3 ~16 wool 8
setblock ~10 ~1 ~17 snow 0
fill ~10 ~1 ~18 ~10 ~1 ~20 wool 8
setblock ~10 ~1 ~21 snow 0
fill ~10 ~1 ~22 ~10 ~3 ~22 wool 8
fill ~10 ~1 ~23 ~10 ~3 ~23 wool 8
setblock ~10 ~1 ~24 snow 0
fill ~10 ~1 ~25 ~10 ~1 ~26 wool 8
fill ~10 ~1 ~29 ~36 ~1 ~29 wool 15
fill ~10 ~1 ~55 ~36 ~1 ~55 wool 15
fill ~11 ~1 ~0 ~35 ~1 ~0 iron_bars 0
fill ~14 ~1 ~59 ~37 ~1 ~59 wool 15
fill ~14 ~1 ~80 ~37 ~1 ~80 wool 15
fill ~14 ~1 ~82 ~33 ~1 ~82 wool 14
fill ~15 ~1 ~84 ~18 ~1 ~84 iron_bars 0
setblock ~19 ~1 ~84 iron_bars 15
setblock ~20 ~1 ~84 iron_bars 0
setblock ~21 ~1 ~84 iron_bars 15
fill ~22 ~1 ~84 ~25 ~1 ~84 iron_bars 0
setblock ~26 ~1 ~84 iron_bars 15
setblock ~27 ~1 ~84 iron_bars 0
setblock ~28 ~1 ~84 iron_bars 15
fill ~29 ~1 ~84 ~32 ~1 ~84 iron_bars 0
fill ~35 ~1 ~83 ~38 ~1 ~83 wool 7
fill ~37 ~1 ~0 ~39 ~1 ~0 wool 7
fill ~37 ~1 ~60 ~37 ~1 ~80 wool 15
fill ~7 ~2 ~82 ~7 ~7 ~82 wool 15
fill ~8 ~2 ~0 ~9 ~2 ~0 wool 7
fill ~8 ~2 ~83 ~8 ~7 ~83 wool 15
fill ~9 ~2 ~83 ~11 ~2 ~83 wool 7
fill ~9 ~2 ~84 ~12 ~2 ~84 wool 15
fill ~10 ~2 ~2 ~35 ~2 ~2 wool 8
fill ~10 ~2 ~6 ~10 ~6 ~6 snow 0
fill ~10 ~2 ~7 ~10 ~3 ~7 wool 8
fill ~10 ~2 ~10 ~10 ~3 ~10 wool 8
fill ~10 ~2 ~11 ~10 ~6 ~11 snow 0
fill ~10 ~2 ~12 ~10 ~3 ~12 wool 8
fill ~10 ~2 ~13 ~10 ~6 ~13 snow 0
fill ~10 ~2 ~14 ~10 ~3 ~14 wool 8
fill ~10 ~2 ~17 ~10 ~3 ~17 wool 8
fill ~10 ~2 ~18 ~10 ~6 ~18 snow 0
fill ~10 ~2 ~19 ~10 ~3 ~19 wool 8
fill ~10 ~2 ~20 ~10 ~6 ~20 snow 0
fill ~10 ~2 ~21 ~10 ~3 ~21 wool 8
fill ~10 ~2 ~24 ~10 ~3 ~24 wool 8
fill ~10 ~2 ~25 ~10 ~6 ~25 snow 0
fill ~10 ~2 ~26 ~10 ~3 ~26 wool 8
fill ~10 ~2 ~29 ~36 ~2 ~29 wool 15
fill ~10 ~2 ~55 ~36 ~2 ~55 wool 15
fill ~11 ~2 ~0 ~35 ~2 ~0 iron_bars 0
fill ~12 ~2 ~57 ~12 ~4 ~57 wool 7
fill ~12 ~2 ~58 ~12 ~4 ~58 wool 7
fill ~12 ~2 ~59 ~12 ~4 ~59 wool 7
fill ~12 ~2 ~60 ~12 ~4 ~60 wool 7
fill ~12 ~2 ~61 ~12 ~4 ~61 wool 7
fill ~12 ~2 ~62 ~12 ~4 ~62 wool 7
fill ~12 ~2 ~63 ~12 ~4 ~63 wool 7
fill ~12 ~2 ~64 ~12 ~4 ~64 wool 7
fill ~12 ~2 ~65 ~12 ~4 ~65 wool 7
fill ~12 ~2 ~66 ~12 ~4 ~66 wool 7
fill ~12 ~2 ~67 ~12 ~4 ~67 wool 7
fill ~12 ~2 ~68 ~12 ~4 ~68 wool 7
fill ~12 ~2 ~69 ~12 ~4 ~69 wool 7
fill ~12 ~2 ~70 ~12 ~4 ~70 wool 7
fill ~12 ~2 ~71 ~12 ~4 ~71 wool 7
fill ~12 ~2 ~72 ~12 ~4 ~72 wool 7
fill ~12 ~2 ~73 ~12 ~4 ~73 wool 7
fill ~12 ~2 ~74 ~12 ~4 ~74 wool 7
fill ~12 ~2 ~75 ~12 ~4 ~75 wool 7
fill ~12 ~2 ~76 ~12 ~4 ~76 wool 7
fill ~12 ~2 ~77 ~12 ~4 ~77 wool 7
fill ~12 ~2 ~78 ~12 ~4 ~78 wool 7
fill ~12 ~2 ~79 ~12 ~4 ~79 wool 7
setblock ~12 ~2 ~83 wool 15
fill ~12 ~2 ~85 ~16 ~2 ~85 wool 15
fill ~14 ~2 ~59 ~14 ~4 ~59 wool 8
fill ~14 ~2 ~80 ~14 ~4 ~80 wool 8
fill ~14 ~2 ~82 ~33 ~2 ~82 wool 14
fill ~15 ~2 ~84 ~16 ~2 ~84 iron_bars 0
fill ~17 ~2 ~84 ~17 ~7 ~84 wool 15
fill ~18 ~2 ~84 ~19 ~2 ~84 iron_bars 0
fill ~20 ~2 ~84 ~20 ~3 ~84 iron_bars 15
fill ~21 ~2 ~84 ~26 ~2 ~84 iron_bars 0
fill ~24 ~2 ~59 ~24 ~4 ~59 wool 8
fill ~24 ~2 ~80 ~24 ~4 ~80 wool 8
fill ~25 ~2 ~59 ~25 ~5 ~59 wool 15
fill ~25 ~2 ~80 ~25 ~5 ~80 wool 15
fill ~26 ~2 ~59 ~26 ~4 ~59 wool 8
fill ~26 ~2 ~80 ~26 ~4 ~80 wool 8
fill ~27 ~2 ~84 ~27 ~3 ~84 iron_bars 15
fill ~28 ~2 ~84 ~32 ~2 ~84 iron_bars 0
fill ~30 ~2 ~85 ~35 ~2 ~85 wool 15
fill ~35 ~2 ~83 ~38 ~2 ~83 wool 7
fill ~35 ~2 ~84 ~38 ~2 ~84 wool 15
fill ~36 ~2 ~59 ~36 ~4 ~59 wool 8
fill ~36 ~2 ~80 ~36 ~4 ~80 wool 8
fill ~37 ~2 ~0 ~39 ~2 ~0 wool 7
fill ~39 ~2 ~83 ~39 ~7 ~83 wool 15
fill ~40 ~2 ~82 ~40 ~7 ~82 wool 15
fill ~8 ~3 ~0 ~9 ~3 ~0 wool 7
fill ~9 ~3 ~83 ~12 ~3 ~83 wool 7
fill ~9 ~3 ~84 ~12 ~3 ~84 wool 15
fill ~10 ~3 ~2 ~35 ~3 ~2 wool 8
fill ~10 ~3 ~29 ~36 ~3 ~29 wool 15
fill ~10 ~3 ~55 ~36 ~3 ~55 wool 15
fill ~11 ~3 ~0 ~35 ~3 ~0 iron_bars 0
fill ~12 ~3 ~85 ~16 ~3 ~85 wool 15
fill ~14 ~3 ~82 ~33 ~3 ~82 wool 14
fill ~15 ~3 ~84 ~16 ~3 ~84 iron_bars 0
fill ~18 ~3 ~84 ~19 ~3 ~84 iron_bars 0
fill ~21 ~3 ~84 ~26 ~3 ~84 iron_bars 0
fill ~28 ~3 ~84 ~32 ~3 ~84 iron_bars 0
fill ~30 ~3 ~85 ~35 ~3 ~85 wool 15
fill ~35 ~3 ~83 ~38 ~3 ~83 wool 7
fill ~35 ~3 ~84 ~38 ~3 ~84 wool 15
fill ~37 ~3 ~0 ~39 ~3 ~0 wool 7
fill ~8 ~4 ~0 ~9 ~4 ~0 wool 7
fill ~9 ~4 ~83 ~9 ~73 ~83 wool 7
fill ~9 ~4 ~84 ~12 ~4 ~84 wool 15
fill ~10 ~4 ~2 ~10 ~4 ~3 wool 15
setblock ~10 ~4 ~5 wool 15
fill ~10 ~4 ~7 ~10 ~4 ~10 wool 15
setblock ~10 ~4 ~12 wool 15
fill ~10 ~4 ~14 ~10 ~4 ~17 wool 15
setblock ~10 ~4 ~19 wool 15
fill ~10 ~4 ~21 ~10 ~4 ~24 wool 15
setblock ~10 ~4 ~26 wool 15
fill ~10 ~4 ~29 ~36 ~4 ~29 wool 15
fill ~10 ~4 ~55 ~36 ~4 ~55 wool 15
fill ~10 ~4 ~83 ~13 ~4 ~83 wool 15
fill ~11 ~4 ~0 ~35 ~4 ~0 iron_bars 0
fill ~11 ~4 ~2 ~35 ~4 ~2 wool 8
fill ~12 ~4 ~85 ~16 ~4 ~85 wool 15
fill ~14 ~4 ~82 ~33 ~4 ~82 wool 14
fill ~15 ~4 ~84 ~16 ~4 ~84 iron_bars 0
fill ~18 ~4 ~84 ~18 ~1 ~84 iron_bars 0
setblock ~19 ~4 ~84 iron_bars 15
fill ~20 ~4 ~84 ~20 ~8 ~84 iron_bars 0
setblock ~21 ~4 ~84 iron_bars 15
fill ~22 ~4 ~84 ~25 ~4 ~84 iron_bars 0
setblock ~26 ~4 ~84 iron_bars 15
fill ~27 ~4 ~84 ~27 ~8 ~84 iron_bars 0
setblock ~28 ~4 ~84 iron_bars 15
fill ~29 ~4 ~84 ~32 ~4 ~84 iron_bars 0
fill ~30 ~4 ~85 ~35 ~4 ~85 wool 15
fill ~35 ~4 ~83 ~38 ~4 ~83 wool 7
fill ~35 ~4 ~84 ~38 ~4 ~84 wool 15
fill ~37 ~4 ~0 ~39 ~4 ~0 wool 7
fill ~8 ~5 ~0 ~9 ~5 ~0 wool 7
fill ~8 ~5 ~9 ~8 ~5 ~69 wool 14
fill ~9 ~5 ~84 ~12 ~5 ~84 wool 15
fill ~10 ~5 ~2 ~10 ~5 ~3 wool 7
setblock ~10 ~5 ~5 wool 7
fill ~10 ~5 ~7 ~10 ~5 ~10 wool 7
setblock ~10 ~5 ~12 wool 7
fill ~10 ~5 ~14 ~10 ~5 ~17 wool 7
setblock ~10 ~5 ~19 wool 7
fill ~10 ~5 ~21 ~10 ~5 ~24 wool 7
setblock ~10 ~5 ~26 wool 7
fill ~10 ~5 ~29 ~36 ~5 ~29 wool 15
fill ~10 ~5 ~55 ~36 ~5 ~55 wool 15
fill ~10 ~5 ~83 ~13 ~5 ~83 wool 15
fill ~11 ~5 ~0 ~35 ~5 ~0 iron_bars 0
fill ~11 ~5 ~2 ~35 ~5 ~2 wool 8
fill ~12 ~5 ~85 ~16 ~5 ~85 wool 15
fill ~14 ~5 ~59 ~37 ~5 ~59 wool 15
fill ~14 ~5 ~80 ~37 ~5 ~80 wool 15
fill ~14 ~5 ~82 ~33 ~5 ~82 wool 14
setblock ~15 ~5 ~84 iron_bars 15
setblock ~16 ~5 ~84 iron_bars 0
setblock ~18 ~5 ~84 iron_bars 15
fill ~19 ~5 ~84 ~19 ~7 ~84 iron_bars 0
fill ~21 ~5 ~84 ~21 ~7 ~84 iron_bars 0
setblock ~22 ~5 ~84 iron_bars 15
fill ~23 ~5 ~84 ~24 ~5 ~84 iron_bars 0
setblock ~25 ~5 ~84 iron_bars 15
fill ~26 ~5 ~84 ~26 ~7 ~84 iron_bars 0
fill ~28 ~5 ~84 ~28 ~7 ~84 iron_bars 0
setblock ~29 ~5 ~84 iron_bars 15
fill ~30 ~5 ~84 ~31 ~5 ~84 iron_bars 0
fill ~30 ~5 ~85 ~35 ~5 ~85 wool 15
setblock ~32 ~5 ~84 iron_bars 15
fill ~35 ~5 ~83 ~38 ~5 ~83 wool 7
fill ~35 ~5 ~84 ~38 ~5 ~84 wool 15
fill ~37 ~5 ~0 ~39 ~5 ~0 wool 7
fill ~37 ~5 ~60 ~37 ~5 ~80 wool 15
fill ~39 ~5 ~9 ~39 ~5 ~69 wool 14
fill ~8 ~6 ~0 ~9 ~6 ~0 wool 7
fill ~8 ~6 ~7 ~8 ~6 ~8 wool 14
fill ~8 ~6 ~9 ~8 ~14 ~9 wool 7
fill ~8 ~6 ~10 ~8 ~12 ~10 wool 7
fill ~8 ~6 ~11 ~8 ~11 ~11 wool 7
fill ~8 ~6 ~12 ~8 ~10 ~12 wool 7
fill ~8 ~6 ~13 ~8 ~10 ~13 wool 7
fill ~8 ~6 ~14 ~8 ~9 ~14 wool 7
fill ~8 ~6 ~15 ~8 ~9 ~15 wool 7
fill ~8 ~6 ~16 ~8 ~9 ~16 wool 7
fill ~8 ~6 ~17 ~8 ~9 ~17 wool 7
fill ~8 ~6 ~18 ~8 ~9 ~18 wool 7
fill ~8 ~6 ~19 ~8 ~9 ~19 wool 7
fill ~8 ~6 ~20 ~8 ~9 ~20 wool 7
fill ~8 ~6 ~21 ~8 ~9 ~21 wool 7
fill ~8 ~6 ~22 ~8 ~9 ~22 wool 7
fill ~8 ~6 ~23 ~8 ~9 ~23 wool 7
fill ~8 ~6 ~24 ~8 ~9 ~24 wool 7
fill ~8 ~6 ~25 ~8 ~9 ~25 wool 7
fill ~8 ~6 ~26 ~8 ~9 ~26 wool 7
fill ~8 ~6 ~27 ~8 ~9 ~27 wool 7
fill ~8 ~6 ~28 ~8 ~9 ~28 wool 7
fill ~8 ~6 ~29 ~8 ~9 ~29 wool 7
fill ~8 ~6 ~30 ~8 ~9 ~30 wool 7
fill ~8 ~6 ~31 ~8 ~9 ~31 wool 7
fill ~8 ~6 ~32 ~8 ~9 ~32 wool 7
fill ~8 ~6 ~33 ~8 ~9 ~33 wool 7
fill ~8 ~6 ~34 ~8 ~9 ~34 wool 7
fill ~8 ~6 ~35 ~8 ~9 ~35 wool 7
fill ~8 ~6 ~36 ~8 ~9 ~36 wool 7
fill ~8 ~6 ~37 ~8 ~9 ~37 wool 7
fill ~8 ~6 ~38 ~8 ~9 ~38 wool 7
fill ~8 ~6 ~39 ~8 ~9 ~39 wool 7
fill ~8 ~6 ~40 ~8 ~9 ~40 wool 7
fill ~8 ~6 ~41 ~8 ~9 ~41 wool 7
fill ~8 ~6 ~42 ~8 ~9 ~42 wool 7
fill ~8 ~6 ~43 ~8 ~9 ~43 wool 7
fill ~8 ~6 ~44 ~8 ~9 ~44 wool 7
fill ~8 ~6 ~45 ~8 ~9 ~45 wool 7
fill ~8 ~6 ~46 ~8 ~9 ~46 wool 7
fill ~8 ~6 ~47 ~8 ~9 ~47 wool 7
fill ~8 ~6 ~48 ~8 ~9 ~48 wool 7
fill ~8 ~6 ~49 ~8 ~9 ~49 wool 7
fill ~8 ~6 ~50 ~8 ~9 ~50 wool 7
fill ~8 ~6 ~51 ~8 ~9 ~51 wool 7
fill ~8 ~6 ~52 ~8 ~9 ~52 wool 7
fill ~8 ~6 ~53 ~8 ~9 ~53 wool 7
fill ~8 ~6 ~54 ~8 ~9 ~54 wool 7
fill ~8 ~6 ~55 ~8 ~9 ~55 wool 7
fill ~8 ~6 ~56 ~8 ~9 ~56 wool 7
fill ~8 ~6 ~57 ~8 ~9 ~57 wool 7
fill ~8 ~6 ~58 ~8 ~9 ~58 wool 7
fill ~8 ~6 ~59 ~8 ~9 ~59 wool 7
fill ~8 ~6 ~60 ~8 ~9 ~60 wool 7
fill ~8 ~6 ~61 ~8 ~9 ~61 wool 7
fill ~8 ~6 ~62 ~8 ~9 ~62 wool 7
fill ~8 ~6 ~63 ~8 ~9 ~63 wool 7
fill ~8 ~6 ~64 ~8 ~9 ~64 wool 7
fill ~8 ~6 ~65 ~8 ~10 ~65 wool 7
fill ~8 ~6 ~66 ~8 ~11 ~66 wool 7
fill ~8 ~6 ~67 ~8 ~12 ~67 wool 7
fill ~8 ~6 ~68 ~8 ~13 ~68 wool 7
fill ~8 ~6 ~69 ~8 ~14 ~69 wool 7
setblock ~8 ~6 ~70 wool 14
fill ~9 ~6 ~84 ~12 ~6 ~84 wool 15
fill ~10 ~6 ~2 ~10 ~9 ~2 wool 15
fill ~10 ~6 ~3 ~10 ~9 ~3 wool 15
fill ~10 ~6 ~5 ~10 ~9 ~5 wool 15
fill ~10 ~6 ~7 ~10 ~6 ~10 wool 15
fill ~10 ~6 ~12 ~10 ~9 ~12 wool 15
fill ~10 ~6 ~14 ~10 ~6 ~17 wool 15
fill ~10 ~6 ~19 ~10 ~9 ~19 wool 15
fill ~10 ~6 ~21 ~10 ~6 ~24 wool 15
fill ~10 ~6 ~26 ~10 ~9 ~26 wool 15
fill ~10 ~6 ~29 ~36 ~6 ~29 wool 15
fill ~10 ~6 ~55 ~36 ~6 ~55 wool 15
fill ~10 ~6 ~83 ~12 ~6 ~83 wool 7
fill ~11 ~6 ~0 ~12 ~6 ~0 iron_bars 0
fill ~11 ~6 ~2 ~13 ~6 ~2 wool 8
fill ~12 ~6 ~85 ~16 ~6 ~85 wool 15
fill ~13 ~6 ~0 ~19 ~6 ~0 wool 15
fill ~13 ~6 ~1 ~19 ~6 ~1 wool 15
fill ~14 ~6 ~2 ~18 ~6 ~2 wool 15
fill ~14 ~6 ~3 ~18 ~6 ~3 wool 15
fill ~14 ~6 ~4 ~18 ~6 ~4 wool 15
fill ~14 ~6 ~82 ~33 ~6 ~82 wool 14
setblock ~15 ~6 ~84 iron_bars 0
setblock ~16 ~6 ~84 iron_bars 15
setblock ~18 ~6 ~84 iron_bars 0
fill ~19 ~6 ~2 ~35 ~6 ~2 wool 8
fill ~20 ~6 ~0 ~35 ~6 ~0 iron_bars 0
setblock ~22 ~6 ~84 iron_bars 0
fill ~23 ~6 ~84 ~24 ~6 ~84 iron_bars 15
setblock ~25 ~6 ~84 iron_bars 0
setblock ~29 ~6 ~84 iron_bars 0
fill ~30 ~6 ~84 ~31 ~6 ~84 iron_bars 15
fill ~30 ~6 ~85 ~35 ~6 ~85 wool 15
setblock ~32 ~6 ~84 iron_bars 0
fill ~35 ~6 ~83 ~38 ~6 ~83 wool 7
fill ~35 ~6 ~84 ~38 ~6 ~84 wool 15
fill ~37 ~6 ~0 ~39 ~6 ~0 wool 7
fill ~39 ~6 ~7 ~39 ~6 ~8 wool 14
fill ~39 ~6 ~9 ~39 ~14 ~9 wool 7
fill ~39 ~6 ~10 ~39 ~12 ~10 wool 7
fill ~39 ~6 ~11 ~39 ~11 ~11 wool 7
fill ~39 ~6 ~12 ~39 ~10 ~12 wool 7
fill ~39 ~6 ~13 ~39 ~10 ~13 wool 7
fill ~39 ~6 ~14 ~39 ~9 ~14 wool 7
fill ~39 ~6 ~15 ~39 ~9 ~15 wool 7
fill ~39 ~6 ~16 ~39 ~9 ~16 wool 7
fill ~39 ~6 ~17 ~39 ~9 ~17 wool 7
fill ~39 ~6 ~18 ~39 ~9 ~18 wool 7
fill ~39 ~6 ~19 ~39 ~9 ~19 wool 7
fill ~39 ~6 ~20 ~39 ~9 ~20 wool 7
fill ~39 ~6 ~21 ~39 ~9 ~21 wool 7
fill ~39 ~6 ~22 ~39 ~9 ~22 wool 7
fill ~39 ~6 ~23 ~39 ~9 ~23 wool 7
fill ~39 ~6 ~24 ~39 ~9 ~24 wool 7
fill ~39 ~6 ~25 ~39 ~9 ~25 wool 7
fill ~39 ~6 ~26 ~39 ~9 ~26 wool 7
fill ~39 ~6 ~27 ~39 ~9 ~27 wool 7
fill ~39 ~6 ~28 ~39 ~9 ~28 wool 7
fill ~39 ~6 ~29 ~39 ~9 ~29 wool 7
fill ~39 ~6 ~30 ~39 ~9 ~30 wool 7
fill ~39 ~6 ~31 ~39 ~9 ~31 wool 7
fill ~39 ~6 ~32 ~39 ~9 ~32 wool 7
fill ~39 ~6 ~33 ~39 ~9 ~33 wool 7
fill ~39 ~6 ~34 ~39 ~9 ~34 wool 7
fill ~39 ~6 ~35 ~39 ~9 ~35 wool 7
fill ~39 ~6 ~36 ~39 ~9 ~36 wool 7
fill ~39 ~6 ~37 ~39 ~9 ~37 wool 7
fill ~39 ~6 ~38 ~39 ~9 ~38 wool 7
fill ~39 ~6 ~39 ~39 ~9 ~39 wool 7
fill ~39 ~6 ~40 ~39 ~9 ~40 wool 7
fill ~39 ~6 ~41 ~39 ~9 ~41 wool 7
fill ~39 ~6 ~42 ~39 ~9 ~42 wool 7
fill ~39 ~6 ~43 ~39 ~9 ~43 wool 7
fill ~39 ~6 ~44 ~39 ~9 ~44 wool 7
fill ~39 ~6 ~45 ~39 ~9 ~45 wool 7
fill ~39 ~6 ~46 ~39 ~9 ~46 wool 7
fill ~39 ~6 ~47 ~39 ~9 ~47 wool 7
fill ~39 ~6 ~48 ~39 ~9 ~48 wool 7
fill ~39 ~6 ~49 ~39 ~9 ~49 wool 7
fill ~39 ~6 ~50 ~39 ~9 ~50 wool 7
fill ~39 ~6 ~51 ~39 ~9 ~51 wool 7
fill ~39 ~6 ~52 ~39 ~9 ~52 wool 7
fill ~39 ~6 ~53 ~39 ~9 ~53 wool 7
fill ~39 ~6 ~54 ~39 ~9 ~54 wool 7
fill ~39 ~6 ~55 ~39 ~9 ~55 wool 7
fill ~39 ~6 ~56 ~39 ~9 ~56 wool 7
fill ~39 ~6 ~57 ~39 ~9 ~57 wool 7
fill ~39 ~6 ~58 ~39 ~9 ~58 wool 7
fill ~39 ~6 ~59 ~39 ~9 ~59 wool 7
fill ~39 ~6 ~60 ~39 ~9 ~60 wool 7
fill ~39 ~6 ~61 ~39 ~9 ~61 wool 7
fill ~39 ~6 ~62 ~39 ~9 ~62 wool 7
fill ~39 ~6 ~63 ~39 ~9 ~63 wool 7
fill ~39 ~6 ~64 ~39 ~9 ~64 wool 7
fill ~39 ~6 ~65 ~39 ~10 ~65 wool 7
fill ~39 ~6 ~66 ~39 ~11 ~66 wool 7
fill ~39 ~6 ~67 ~39 ~12 ~67 wool 7
fill ~39 ~6 ~68 ~39 ~13 ~68 wool 7
fill ~39 ~6 ~69 ~39 ~14 ~69 wool 7
setblock ~39 ~6 ~70 wool 14
fill ~8 ~7 ~0 ~9 ~7 ~0 wool 7
setblock ~8 ~7 ~6 wool 14
fill ~8 ~7 ~7 ~8 ~58 ~7 wool 7
fill ~8 ~7 ~8 ~8 ~59 ~8 wool 7
fill ~8 ~7 ~70 ~8 ~15 ~70 wool 7
setblock ~8 ~7 ~71 wool 14
fill ~9 ~7 ~84 ~12 ~7 ~84 wool 15
fill ~10 ~7 ~6 ~10 ~9 ~6 wool 15
setblock ~10 ~7 ~7 snow 0
fill ~10 ~7 ~8 ~10 ~7 ~9 wool 15
setblock ~10 ~7 ~10 snow 0
fill ~10 ~7 ~11 ~10 ~9 ~11 wool 15
fill ~10 ~7 ~13 ~10 ~9 ~13 wool 15
setblock ~10 ~7 ~14 snow 0
fill ~10 ~7 ~15 ~10 ~7 ~16 wool 15
setblock ~10 ~7 ~17 snow 0
fill ~10 ~7 ~18 ~10 ~9 ~18 wool 15
fill ~10 ~7 ~20 ~10 ~9 ~20 wool 15
setblock ~10 ~7 ~21 snow 0
fill ~10 ~7 ~22 ~10 ~7 ~23 wool 15
setblock ~10 ~7 ~24 snow 0
fill ~10 ~7 ~25 ~10 ~9 ~25 wool 15
fill ~10 ~7 ~29 ~36 ~7 ~29 wool 15
fill ~10 ~7 ~55 ~36 ~7 ~55 wool 15
fill ~10 ~7 ~83 ~11 ~7 ~83 wool 7
fill ~11 ~7 ~0 ~12 ~7 ~0 iron_bars 0
fill ~11 ~7 ~2 ~12 ~7 ~2 wool 8
setblock ~12 ~7 ~83 wool 15
fill ~12 ~7 ~85 ~16 ~7 ~85 wool 15
fill ~13 ~7 ~0 ~13 ~8 ~0 wool 15
fill ~13 ~7 ~1 ~13 ~8 ~1 wool 15
fill ~13 ~7 ~2 ~13 ~8 ~2 wool 15
fill ~13 ~7 ~3 ~13 ~8 ~3 wool 15
fill ~13 ~7 ~4 ~13 ~8 ~4 wool 15
fill ~14 ~7 ~5 ~18 ~7 ~5 wool 15
fill ~14 ~7 ~82 ~33 ~7 ~82 wool 14
fill ~15 ~7 ~1 ~15 ~7 ~4 wool 8
setblock ~15 ~7 ~84 iron_bars 15
fill ~16 ~7 ~84 ~16 ~12 ~84 iron_bars 0
fill ~17 ~7 ~1 ~17 ~7 ~4 wool 8
setblock ~18 ~7 ~84 iron_bars 15
fill ~19 ~7 ~0 ~19 ~8 ~0 wool 15
fill ~19 ~7 ~1 ~19 ~8 ~1 wool 15
fill ~19 ~7 ~2 ~19 ~8 ~2 wool 15
fill ~19 ~7 ~3 ~19 ~8 ~3 wool 15
fill ~19 ~7 ~4 ~19 ~8 ~4 wool 15
fill ~20 ~7 ~0 ~35 ~7 ~0 iron_bars 0
fill ~20 ~7 ~2 ~35 ~7 ~2 wool 8
setblock ~22 ~7 ~84 iron_bars 15
fill ~23 ~7 ~84 ~24 ~7 ~84 iron_bars 0
setblock ~25 ~7 ~84 iron_bars 15 summon
setblock ~29 ~7 ~84 iron_bars 15
fill ~30 ~7 ~84 ~31 ~7 ~84 iron_bars 0
fill ~30 ~7 ~85 ~35 ~7 ~85 wool 15
setblock ~32 ~7 ~84 iron_bars 15
fill ~35 ~7 ~83 ~38 ~7 ~83 wool 7
fill ~35 ~7 ~84 ~38 ~7 ~84 wool 15
fill ~37 ~7 ~0 ~39 ~7 ~0 wool 7
setblock ~39 ~7 ~6 wool 14
fill ~39 ~7 ~7 ~39 ~58 ~7 wool 7
fill ~39 ~7 ~8 ~39 ~59 ~8 wool 7
fill ~39 ~7 ~70 ~39 ~15 ~70 wool 7
setblock ~39 ~7 ~71 wool 14
fill ~8 ~8 ~0 ~9 ~8 ~0 wool 7
fill ~8 ~8 ~5 ~8 ~9 ~5 wool 14
fill ~8 ~8 ~6 ~8 ~57 ~6 wool 7
fill ~8 ~8 ~71 ~8 ~16 ~71 wool 7
setblock ~8 ~8 ~72 wool 14
fill ~10 ~8 ~7 ~10 ~9 ~7 wool 15
fill ~10 ~8 ~8 ~10 ~8 ~9 snow 0
fill ~10 ~8 ~10 ~10 ~9 ~10 wool 15
fill ~10 ~8 ~14 ~10 ~9 ~14 wool 15
fill ~10 ~8 ~15 ~10 ~8 ~16 snow 0
fill ~10 ~8 ~17 ~10 ~9 ~17 wool 15
fill ~10 ~8 ~21 ~10 ~9 ~21 wool 15
fill ~10 ~8 ~22 ~10 ~8 ~23 snow 0
fill ~10 ~8 ~24 ~10 ~9 ~24 wool 15
fill ~10 ~8 ~29 ~36 ~8 ~29 wool 15
fill ~10 ~8 ~55 ~36 ~8 ~55 wool 15
fill ~10 ~8 ~83 ~12 ~8 ~83 wool 7
fill ~11 ~8 ~0 ~12 ~8 ~0 iron_bars 0
fill ~11 ~8 ~2 ~12 ~8 ~2 wool 8
fill ~13 ~8 ~85 ~13 ~12 ~85 wool 7
fill ~14 ~8 ~5 ~18 ~8 ~5 wool 15
fill ~14 ~8 ~59 ~37 ~8 ~59 wool 15
fill ~14 ~8 ~80 ~37 ~8 ~80 wool 15
fill ~14 ~8 ~82 ~33 ~8 ~82 wool 14
fill ~15 ~8 ~84 ~15 ~11 ~84 iron_bars 0
fill ~17 ~8 ~84 ~18 ~8 ~84 iron_bars 0
setblock ~19 ~8 ~84 iron_bars 15
fill ~20 ~8 ~0 ~35 ~8 ~0 iron_bars 0
fill ~20 ~8 ~2 ~35 ~8 ~2 wool 8
setblock ~21 ~8 ~84 iron_bars 15
fill ~22 ~8 ~84 ~25 ~8 ~84 iron_bars 0
setblock ~26 ~8 ~84 iron_bars 15
setblock ~28 ~8 ~84 iron_bars 15
fill ~29 ~8 ~84 ~32 ~8 ~84 iron_bars 0
fill ~34 ~8 ~85 ~34 ~12 ~85 wool 7
fill ~35 ~8 ~83 ~38 ~8 ~83 wool 7
fill ~37 ~8 ~0 ~39 ~8 ~0 wool 7
fill ~37 ~8 ~60 ~37 ~8 ~80 wool 15
fill ~39 ~8 ~5 ~39 ~9 ~5 wool 14
fill ~39 ~8 ~6 ~39 ~57 ~6 wool 7
fill ~39 ~8 ~71 ~39 ~16 ~71 wool 7
setblock ~39 ~8 ~72 wool 14
fill ~8 ~9 ~0 ~9 ~9 ~0 wool 7
fill ~8 ~9 ~72 ~8 ~17 ~72 wool 7
setblock ~8 ~9 ~73 wool 14
setblock ~10 ~9 ~4 wool 15
fill ~10 ~9 ~8 ~10 ~9 ~55 wool 15
fill ~10 ~9 ~83 ~12 ~9 ~83 wool 7
fill ~11 ~9 ~0 ~13 ~9 ~0 iron_bars 0
fill ~11 ~9 ~2 ~13 ~9 ~2 wool 8
fill ~11 ~9 ~29 ~36 ~9 ~29 wool 15
fill ~11 ~9 ~55 ~36 ~9 ~55 wool 15
fill ~12 ~9 ~57 ~12 ~12 ~57 wool 7
fill ~12 ~9 ~58 ~12 ~12 ~58 wool 7
fill ~12 ~9 ~59 ~12 ~12 ~59 wool 7
fill ~12 ~9 ~60 ~12 ~12 ~60 wool 7
fill ~12 ~9 ~61 ~12 ~12 ~61 wool 7
fill ~12 ~9 ~62 ~12 ~12 ~62 wool 7
fill ~12 ~9 ~63 ~12 ~12 ~63 wool 7
fill ~12 ~9 ~64 ~12 ~12 ~64 wool 7
fill ~12 ~9 ~65 ~12 ~12 ~65 wool 7
fill ~12 ~9 ~66 ~12 ~12 ~66 wool 7
fill ~12 ~9 ~67 ~12 ~12 ~67 wool 7
fill ~12 ~9 ~68 ~12 ~12 ~68 wool 7
fill ~12 ~9 ~69 ~12 ~12 ~69 wool 7
fill ~12 ~9 ~70 ~12 ~12 ~70 wool 7
fill ~12 ~9 ~71 ~12 ~12 ~71 wool 7
fill ~12 ~9 ~72 ~12 ~12 ~72 wool 7
fill ~12 ~9 ~73 ~12 ~12 ~73 wool 7
fill ~12 ~9 ~74 ~12 ~12 ~74 wool 7
fill ~12 ~9 ~75 ~12 ~12 ~75 wool 7
fill ~12 ~9 ~76 ~12 ~12 ~76 wool 7
fill ~12 ~9 ~77 ~12 ~12 ~77 wool 7
fill ~12 ~9 ~78 ~12 ~12 ~78 wool 7
fill ~12 ~9 ~79 ~12 ~12 ~79 wool 7
fill ~14 ~9 ~0 ~14 ~9 ~4 wool 15
fill ~14 ~9 ~59 ~14 ~12 ~59 wool 8
fill ~14 ~9 ~80 ~14 ~12 ~80 wool 8
fill ~14 ~9 ~82 ~33 ~9 ~82 wool 14
fill ~15 ~9 ~5 ~17 ~9 ~5 wool 15
fill ~16 ~9 ~1 ~16 ~9 ~4 wool 8
fill ~17 ~9 ~84 ~19 ~9 ~84 iron_bars 0
fill ~18 ~9 ~0 ~18 ~9 ~4 wool 15
fill ~19 ~9 ~0 ~35 ~9 ~0 iron_bars 0
fill ~19 ~9 ~2 ~35 ~9 ~2 wool 8
fill ~20 ~9 ~84 ~20 ~10 ~84 iron_bars 15
fill ~21 ~9 ~84 ~26 ~9 ~84 iron_bars 0
fill ~24 ~9 ~59 ~24 ~12 ~59 wool 8
fill ~24 ~9 ~80 ~24 ~12 ~80 wool 8
fill ~25 ~9 ~59 ~25 ~13 ~59 wool 15
fill ~25 ~9 ~80 ~25 ~13 ~80 wool 15
fill ~26 ~9 ~59 ~26 ~12 ~59 wool 8
fill ~26 ~9 ~80 ~26 ~12 ~80 wool 8
fill ~27 ~9 ~84 ~27 ~10 ~84 iron_bars 15
fill ~28 ~9 ~84 ~32 ~9 ~84 iron_bars 0
fill ~35 ~9 ~83 ~38 ~9 ~83 wool 7
fill ~36 ~9 ~59 ~36 ~12 ~59 wool 8
fill ~36 ~9 ~80 ~36 ~12 ~80 wool 8
fill ~37 ~9 ~0 ~39 ~9 ~0 wool 7
fill ~39 ~9 ~72 ~39 ~17 ~72 wool 7
setblock ~39 ~9 ~73 wool 14
fill ~8 ~10 ~0 ~10 ~10 ~0 wool 7
fill ~8 ~10 ~4 ~8 ~56 ~4 wool 14
fill ~8 ~10 ~5 ~8 ~56 ~5 wool 7
fill ~8 ~10 ~14 ~8 ~10 ~64 wool 14
fill ~8 ~10 ~73 ~8 ~18 ~73 wool 7
setblock ~8 ~10 ~74 wool 14
fill ~10 ~10 ~29 ~36 ~10 ~29 wool 15
fill ~10 ~10 ~55 ~36 ~10 ~55 wool 15
fill ~10 ~10 ~83 ~12 ~10 ~83 wool 7
fill ~11 ~10 ~0 ~11 ~11 ~0 wool 15
fill ~11 ~10 ~1 ~11 ~11 ~1 wool 15
fill ~11 ~10 ~2 ~11 ~11 ~2 wool 15
fill ~11 ~10 ~3 ~11 ~11 ~3 wool 15
fill ~11 ~10 ~4 ~11 ~11 ~4 wool 15
fill ~11 ~10 ~5 ~11 ~11 ~5 wool 15
fill ~11 ~10 ~6 ~11 ~11 ~6 wool 15
fill ~11 ~10 ~7 ~11 ~11 ~7 wool 15
fill ~11 ~10 ~8 ~11 ~11 ~8 wool 15
fill ~11 ~10 ~9 ~11 ~11 ~9 wool 15
fill ~11 ~10 ~10 ~11 ~11 ~10 wool 15
fill ~11 ~10 ~11 ~11 ~11 ~11 wool 15
fill ~11 ~10 ~12 ~11 ~11 ~12 wool 15
fill ~11 ~10 ~13 ~11 ~11 ~13 wool 15
fill ~11 ~10 ~14 ~11 ~11 ~14 wool 15
fill ~11 ~10 ~15 ~11 ~11 ~15 wool 15
fill ~11 ~10 ~16 ~11 ~11 ~16 wool 15
fill ~11 ~10 ~17 ~11 ~11 ~17 wool 15
fill ~11 ~10 ~18 ~11 ~11 ~18 wool 15
fill ~11 ~10 ~19 ~11 ~11 ~19 wool 15
fill ~11 ~10 ~20 ~11 ~11 ~20 wool 15
fill ~11 ~10 ~21 ~11 ~11 ~21 wool 15
fill ~11 ~10 ~22 ~11 ~11 ~22 wool 15
fill ~11 ~10 ~23 ~11 ~11 ~23 wool 15
fill ~11 ~10 ~24 ~11 ~11 ~24 wool 15
fill ~11 ~10 ~25 ~11 ~11 ~25 wool 15
fill ~11 ~10 ~26 ~11 ~11 ~26 wool 15
fill ~11 ~10 ~27 ~11 ~11 ~27 wool 15
fill ~11 ~10 ~28 ~11 ~11 ~28 wool 15
fill ~12 ~10 ~0 ~14 ~10 ~0 iron_bars 0
fill ~12 ~10 ~2 ~14 ~10 ~2 wool 8
fill ~14 ~10 ~82 ~33 ~10 ~82 wool 14
fill ~15 ~10 ~0 ~17 ~10 ~0 wool 15
fill ~15 ~10 ~1 ~17 ~10 ~1 wool 15
fill ~15 ~10 ~2 ~17 ~10 ~2 wool 15
fill ~15 ~10 ~3 ~17 ~10 ~3 wool 15
fill ~15 ~10 ~4 ~17 ~10 ~4 wool 15
fill ~17 ~10 ~84 ~19 ~10 ~84 iron_bars 0
fill ~18 ~10 ~0 ~34 ~10 ~0 iron_bars 0
fill ~18 ~10 ~2 ~34 ~10 ~2 wool 8
fill ~21 ~10 ~84 ~24 ~10 ~84 iron_bars 14
fill ~25 ~10 ~84 ~26 ~10 ~84 iron_bars 0
fill ~28 ~10 ~84 ~32 ~10 ~84 iron_bars 0
fill ~35 ~10 ~0 ~35 ~11 ~0 wool 15
fill ~35 ~10 ~1 ~35 ~11 ~1 wool 15
fill ~35 ~10 ~2 ~35 ~11 ~2 wool 15
fill ~35 ~10 ~3 ~35 ~11 ~3 wool 15
fill ~35 ~10 ~4 ~35 ~11 ~4 wool 15
fill ~35 ~10 ~5 ~35 ~11 ~5 wool 15
fill ~35 ~10 ~6 ~35 ~11 ~6 wool 15
fill ~35 ~10 ~7 ~35 ~11 ~7 wool 15
fill ~35 ~10 ~8 ~35 ~11 ~8 wool 15
fill ~35 ~10 ~9 ~35 ~11 ~9 wool 15
fill ~35 ~10 ~10 ~35 ~11 ~10 wool 15
fill ~35 ~10 ~11 ~35 ~11 ~11 wool 15
fill ~35 ~10 ~12 ~35 ~11 ~12 wool 15
fill ~35 ~10 ~13 ~35 ~11 ~13 wool 15
fill ~35 ~10 ~14 ~35 ~11 ~14 wool 15
fill ~35 ~10 ~15 ~35 ~11 ~15 wool 15
fill ~35 ~10 ~16 ~35 ~11 ~16 wool 15
fill ~35 ~10 ~17 ~35 ~11 ~17 wool 15
fill ~35 ~10 ~18 ~35 ~11 ~18 wool 15
fill ~35 ~10 ~19 ~35 ~11 ~19 wool 15
fill ~35 ~10 ~20 ~35 ~11 ~20 wool 15
fill ~35 ~10 ~21 ~35 ~11 ~21 wool 15
fill ~35 ~10 ~22 ~35 ~11 ~22 wool 15
fill ~35 ~10 ~23 ~35 ~11 ~23 wool 15
fill ~35 ~10 ~24 ~35 ~11 ~24 wool 15
fill ~35 ~10 ~25 ~35 ~11 ~25 wool 15
fill ~35 ~10 ~26 ~35 ~11 ~26 wool 15
fill ~35 ~10 ~27 ~35 ~11 ~27 wool 15
fill ~35 ~10 ~28 ~35 ~11 ~28 wool 15
fill ~35 ~10 ~83 ~38 ~10 ~83 wool 7
fill ~36 ~10 ~0 ~39 ~10 ~0 wool 7
fill ~39 ~10 ~4 ~39 ~56 ~4 wool 14
fill ~39 ~10 ~5 ~39 ~56 ~5 wool 7
fill ~39 ~10 ~14 ~39 ~10 ~64 wool 14
fill ~39 ~10 ~73 ~39 ~18 ~73 wool 7
setblock ~39 ~10 ~74 wool 14
fill ~8 ~11 ~0 ~10 ~11 ~0 wool 7
fill ~8 ~11 ~12 ~8 ~11 ~13 wool 14
fill ~8 ~11 ~14 ~8 ~30 ~14 glass 0
fill ~8 ~11 ~15 ~8 ~56 ~15 glass 0
fill ~8 ~11 ~16 ~8 ~57 ~16 glass 0
fill ~8 ~11 ~17 ~8 ~58 ~17 glass 0
fill ~8 ~11 ~18 ~8 ~59 ~18 glass 0
fill ~8 ~11 ~19 ~8 ~41 ~19 glass 0
fill ~8 ~11 ~20 ~8 ~41 ~20 glass 0
fill ~8 ~11 ~21 ~8 ~33 ~21 glass 0
fill ~8 ~11 ~22 ~8 ~33 ~22 glass 0
fill ~8 ~11 ~23 ~8 ~33 ~23 glass 0
fill ~8 ~11 ~24 ~8 ~34 ~24 glass 0
fill ~8 ~11 ~25 ~8 ~28 ~25 glass 0
fill ~8 ~11 ~26 ~8 ~28 ~26 glass 0
fill ~8 ~11 ~27 ~8 ~29 ~27 glass 0
fill ~8 ~11 ~28 ~8 ~30 ~28 glass 0
fill ~8 ~11 ~29 ~8 ~29 ~29 glass 0
fill ~8 ~11 ~30 ~8 ~29 ~30 glass 0
fill ~8 ~11 ~31 ~8 ~19 ~31 glass 0
fill ~8 ~11 ~32 ~8 ~18 ~32 glass 0
fill ~8 ~11 ~33 ~8 ~16 ~33 glass 0
fill ~8 ~11 ~34 ~8 ~13 ~34 glass 0
fill ~8 ~11 ~35 ~8 ~12 ~35 glass 0
fill ~8 ~11 ~36 ~8 ~12 ~36 glass 0
fill ~8 ~11 ~37 ~8 ~12 ~37 glass 0
fill ~8 ~11 ~38 ~8 ~11 ~64 glass 0
setblock ~8 ~11 ~65 wool 14
fill ~8 ~11 ~74 ~8 ~19 ~74 wool 7
setblock ~8 ~11 ~75 wool 14
fill ~10 ~11 ~29 ~36 ~11 ~29 wool 15
fill ~10 ~11 ~55 ~36 ~11 ~55 wool 15
fill ~10 ~11 ~83 ~12 ~11 ~83 wool 7
fill ~12 ~11 ~0 ~34 ~11 ~0 iron_bars 0
fill ~12 ~11 ~2 ~34 ~11 ~2 wool 8
fill ~14 ~11 ~82 ~33 ~11 ~82 wool 14
fill ~17 ~11 ~84 ~18 ~11 ~84 iron_bars 0
setblock ~19 ~11 ~84 iron_bars 15
setblock ~20 ~11 ~84 iron_bars 14
setblock ~21 ~11 ~84 iron_bars 15
fill ~22 ~11 ~84 ~25 ~11 ~84 iron_bars 0
setblock ~26 ~11 ~84 iron_bars 15
setblock ~27 ~11 ~84 iron_bars 14
setblock ~28 ~11 ~84 iron_bars 15
fill ~29 ~11 ~84 ~32 ~11 ~84 iron_bars 0
fill ~35 ~11 ~83 ~38 ~11 ~83 wool 7
fill ~36 ~11 ~0 ~39 ~11 ~0 wool 7
fill ~39 ~11 ~12 ~39 ~11 ~13 wool 14
fill ~39 ~11 ~14 ~39 ~55 ~14 wool 7
fill ~39 ~11 ~15 ~39 ~56 ~15 wool 7
fill ~39 ~11 ~16 ~39 ~57 ~16 wool 7
fill ~39 ~11 ~17 ~39 ~58 ~17 wool 7
fill ~39 ~11 ~18 ~39 ~59 ~18 wool 7
fill ~39 ~11 ~19 ~39 ~41 ~19 wool 7
fill ~39 ~11 ~20 ~39 ~41 ~20 wool 7
fill ~39 ~11 ~21 ~39 ~33 ~21 wool 7
fill ~39 ~11 ~22 ~39 ~33 ~22 wool 7
fill ~39 ~11 ~23 ~39 ~33 ~23 wool 7
fill ~39 ~11 ~24 ~39 ~34 ~24 wool 7
fill ~39 ~11 ~25 ~39 ~28 ~25 wool 7
fill ~39 ~11 ~26 ~39 ~28 ~26 wool 7
fill ~39 ~11 ~27 ~39 ~29 ~27 wool 7
fill ~39 ~11 ~28 ~39 ~30 ~28 wool 7
fill ~39 ~11 ~29 ~39 ~29 ~29 wool 7
fill ~39 ~11 ~30 ~39 ~29 ~30 wool 7
fill ~39 ~11 ~31 ~39 ~19 ~31 wool 7
fill ~39 ~11 ~32 ~39 ~18 ~32 wool 7
fill ~39 ~11 ~33 ~39 ~16 ~33 wool 7
fill ~39 ~11 ~34 ~39 ~13 ~34 wool 7
fill ~39 ~11 ~35 ~39 ~12 ~35 wool 7
fill ~39 ~11 ~36 ~39 ~12 ~36 wool 7
fill ~39 ~11 ~37 ~39 ~12 ~37 wool 7
fill ~39 ~11 ~38 ~39 ~11 ~64 wool 7
setblock ~39 ~11 ~65 wool 14
fill ~39 ~11 ~74 ~39 ~19 ~74 wool 7
setblock ~39 ~11 ~75 wool 14
fill ~8 ~12 ~0 ~11 ~12 ~0 wool 7
setblock ~8 ~12 ~11 wool 14
fill ~8 ~12 ~12 ~8 ~30 ~12 glass 0
fill ~8 ~12 ~13 ~8 ~30 ~13 glass 0
fill ~8 ~12 ~38 ~8 ~18 ~38 wool 14
fill ~8 ~12 ~39 ~8 ~18 ~39 wool 14
fill ~8 ~12 ~40 ~8 ~16 ~40 wool 14
fill ~8 ~12 ~41 ~8 ~15 ~41 wool 14
fill ~8 ~12 ~42 ~8 ~15 ~42 wool 14
fill ~8 ~12 ~43 ~8 ~14 ~43 wool 14
fill ~8 ~12 ~44 ~8 ~12 ~65 glass 0
setblock ~8 ~12 ~66 wool 14
fill ~8 ~12 ~75 ~8 ~64 ~75 wool 7
setblock ~8 ~12 ~76 wool 14
fill ~10 ~12 ~29 ~36 ~12 ~29 wool 15
fill ~10 ~12 ~55 ~36 ~12 ~55 wool 15
fill ~10 ~12 ~83 ~12 ~12 ~83 wool 7
fill ~12 ~12 ~0 ~13 ~12 ~0 wool 15
fill ~12 ~12 ~1 ~13 ~12 ~1 wool 15
fill ~12 ~12 ~2 ~13 ~12 ~2 wool 15
fill ~12 ~12 ~3 ~13 ~12 ~3 wool 15
fill ~12 ~12 ~4 ~13 ~12 ~4 wool 15
fill ~12 ~12 ~5 ~13 ~12 ~5 wool 15
fill ~12 ~12 ~6 ~13 ~12 ~6 wool 15
fill ~12 ~12 ~7 ~13 ~12 ~7 wool 15
fill ~12 ~12 ~8 ~13 ~12 ~8 wool 15
fill ~12 ~12 ~9 ~13 ~12 ~9 wool 15
fill ~12 ~12 ~10 ~13 ~12 ~10 wool 15
fill ~12 ~12 ~11 ~13 ~12 ~11 wool 15
fill ~12 ~12 ~12 ~13 ~12 ~12 wool 15
fill ~12 ~12 ~13 ~13 ~12 ~13 wool 15
fill ~12 ~12 ~14 ~13 ~12 ~14 wool 15
fill ~12 ~12 ~15 ~13 ~12 ~15 wool 15
fill ~12 ~12 ~16 ~13 ~12 ~16 wool 15
fill ~12 ~12 ~17 ~13 ~12 ~17 wool 15
fill ~12 ~12 ~18 ~13 ~12 ~18 wool 15
fill ~12 ~12 ~19 ~13 ~12 ~19 wool 15
fill ~12 ~12 ~20 ~13 ~12 ~20 wool 15
fill ~12 ~12 ~21 ~13 ~12 ~21 wool 15
fill ~12 ~12 ~22 ~13 ~12 ~22 wool 15
fill ~12 ~12 ~23 ~13 ~12 ~23 wool 15
fill ~12 ~12 ~24 ~13 ~12 ~24 wool 15
fill ~12 ~12 ~25 ~13 ~12 ~25 wool 15
fill ~12 ~12 ~26 ~13 ~12 ~26 wool 15
fill ~12 ~12 ~27 ~13 ~12 ~27 wool 15
fill ~12 ~12 ~28 ~13 ~12 ~28 wool 15
fill ~14 ~12 ~0 ~32 ~12 ~0 iron_bars 0
fill ~14 ~12 ~2 ~32 ~12 ~2 wool 8
fill ~14 ~12 ~82 ~33 ~12 ~82 wool 14
setblock ~15 ~12 ~84 iron_bars 15
fill ~17 ~12 ~84 ~17 ~8 ~84 iron_bars 0
setblock ~18 ~12 ~84 iron_bars 15
setblock ~19 ~12 ~84 iron_bars 14
fill ~20 ~12 ~84 ~24 ~12 ~84 iron_bars 0
setblock ~25 ~12 ~84 iron_bars 15
fill ~26 ~12 ~84 ~27 ~12 ~84 iron_bars 0
setblock ~28 ~12 ~84 iron_bars 14
setblock ~29 ~12 ~84 iron_bars 15
fill ~30 ~12 ~84 ~31 ~12 ~84 iron_bars 0
setblock ~32 ~12 ~84 iron_bars 15
fill ~33 ~12 ~0 ~34 ~12 ~0 wool 15
fill ~33 ~12 ~1 ~34 ~12 ~1 wool 15
fill ~33 ~12 ~2 ~34 ~12 ~2 wool 15
fill ~33 ~12 ~3 ~34 ~12 ~3 wool 15
fill ~33 ~12 ~4 ~34 ~12 ~4 wool 15
fill ~33 ~12 ~5 ~34 ~12 ~5 wool 15
fill ~33 ~12 ~6 ~34 ~12 ~6 wool 15
fill ~33 ~12 ~7 ~34 ~12 ~7 wool 15
fill ~33 ~12 ~8 ~34 ~12 ~8 wool 15
fill ~33 ~12 ~9 ~34 ~12 ~9 wool 15
fill ~33 ~12 ~10 ~34 ~12 ~10 wool 15
fill ~33 ~12 ~11 ~34 ~12 ~11 wool 15
fill ~33 ~12 ~12 ~34 ~12 ~12 wool 15
fill ~33 ~12 ~13 ~34 ~12 ~13 wool 15
fill ~33 ~12 ~14 ~34 ~12 ~14 wool 15
fill ~33 ~12 ~15 ~34 ~12 ~15 wool 15
fill ~33 ~12 ~16 ~34 ~12 ~16 wool 15
fill ~33 ~12 ~17 ~34 ~12 ~17 wool 15
fill ~33 ~12 ~18 ~34 ~12 ~18 wool 15
fill ~33 ~12 ~19 ~34 ~12 ~19 wool 15
fill ~33 ~12 ~20 ~34 ~12 ~20 wool 15
fill ~33 ~12 ~21 ~34 ~12 ~21 wool 15
fill ~33 ~12 ~22 ~34 ~12 ~22 wool 15
fill ~33 ~12 ~23 ~34 ~12 ~23 wool 15
fill ~33 ~12 ~24 ~34 ~12 ~24 wool 15
fill ~33 ~12 ~25 ~34 ~12 ~25 wool 15
fill ~33 ~12 ~26 ~34 ~12 ~26 wool 15
fill ~33 ~12 ~27 ~34 ~12 ~27 wool 15
fill ~33 ~12 ~28 ~34 ~12 ~28 wool 15
fill ~35 ~12 ~0 ~39 ~12 ~0 wool 7
fill ~35 ~12 ~83 ~38 ~12 ~83 wool 7
setblock ~39 ~12 ~11 wool 14
fill ~39 ~12 ~12 ~39 ~53 ~12 wool 7
fill ~39 ~12 ~13 ~39 ~54 ~13 wool 7
fill ~39 ~12 ~38 ~39 ~18 ~38 wool 14
fill ~39 ~12 ~39 ~39 ~18 ~39 wool 14
fill ~39 ~12 ~40 ~39 ~16 ~40 wool 14
fill ~39 ~12 ~41 ~39 ~15 ~41 wool 14
fill ~39 ~12 ~42 ~39 ~15 ~42 wool 14
fill ~39 ~12 ~43 ~39 ~14 ~43 wool 14
fill ~39 ~12 ~44 ~39 ~12 ~65 wool 7
setblock ~39 ~12 ~66 wool 14
fill ~39 ~12 ~75 ~39 ~64 ~75 wool 7
setblock ~39 ~12 ~76 wool 14
fill ~7 ~13 ~82 ~7 ~18 ~82 wool 15
fill ~8 ~13 ~0 ~13 ~13 ~0 wool 7
fill ~8 ~13 ~10 ~8 ~14 ~10 wool 14
fill ~8 ~13 ~11 ~8 ~30 ~11 glass 0
fill ~8 ~13 ~35 ~8 ~18 ~35 wool 14
fill ~8 ~13 ~36 ~8 ~17 ~36 wool 14
fill ~8 ~13 ~37 ~8 ~18 ~37 wool 14
fill ~8 ~13 ~44 ~8 ~14 ~44 wool 14
fill ~8 ~13 ~45 ~8 ~14 ~45 wool 14
fill ~8 ~13 ~46 ~8 ~15 ~46 wool 14
fill ~8 ~13 ~47 ~8 ~13 ~66 glass 0
setblock ~8 ~13 ~67 wool 14
fill ~8 ~13 ~76 ~8 ~64 ~76 wool 7
setblock ~8 ~13 ~77 wool 14
fill ~8 ~13 ~83 ~8 ~18 ~83 wool 15
fill ~9 ~13 ~84 ~12 ~13 ~84 wool 15
fill ~10 ~13 ~29 ~36 ~13 ~29 wool 15
fill ~10 ~13 ~55 ~36 ~13 ~55 wool 15
fill ~10 ~13 ~83 ~12 ~13 ~83 wool 7
fill ~11 ~13 ~30 ~36 ~13 ~30 wool 15
fill ~11 ~13 ~31 ~36 ~13 ~31 wool 15
fill ~11 ~13 ~32 ~36 ~13 ~32 wool 15
fill ~11 ~13 ~33 ~36 ~13 ~33 wool 15
fill ~11 ~13 ~34 ~36 ~13 ~34 wool 15
fill ~11 ~13 ~35 ~36 ~13 ~35 wool 15
fill ~11 ~13 ~36 ~36 ~13 ~36 wool 15
fill ~11 ~13 ~37 ~36 ~13 ~37 wool 15
fill ~11 ~13 ~38 ~36 ~13 ~38 wool 15
fill ~11 ~13 ~39 ~36 ~13 ~39 wool 15
fill ~11 ~13 ~40 ~36 ~13 ~40 wool 15
fill ~11 ~13 ~41 ~36 ~13 ~41 wool 15
fill ~11 ~13 ~42 ~36 ~13 ~42 wool 15
fill ~11 ~13 ~43 ~36 ~13 ~43 wool 15
fill ~11 ~13 ~44 ~36 ~13 ~44 wool 15
fill ~11 ~13 ~45 ~36 ~13 ~45 wool 15
fill ~11 ~13 ~46 ~36 ~13 ~46 wool 15
fill ~11 ~13 ~47 ~36 ~13 ~47 wool 15
fill ~11 ~13 ~48 ~36 ~13 ~48 wool 15
fill ~11 ~13 ~49 ~36 ~13 ~49 wool 15
fill ~11 ~13 ~50 ~36 ~13 ~50 wool 15
fill ~11 ~13 ~51 ~36 ~13 ~51 wool 15
fill ~11 ~13 ~52 ~36 ~13 ~52 wool 15
fill ~11 ~13 ~53 ~36 ~13 ~53 wool 15
fill ~11 ~13 ~54 ~36 ~13 ~54 wool 15
fill ~12 ~13 ~85 ~16 ~13 ~85 wool 15
fill ~14 ~13 ~0 ~32 ~13 ~0 wool 15
fill ~14 ~13 ~1 ~32 ~13 ~1 wool 15
fill ~14 ~13 ~2 ~32 ~13 ~2 wool 15
fill ~14 ~13 ~3 ~32 ~13 ~3 wool 15
fill ~14 ~13 ~4 ~32 ~13 ~4 wool 15
fill ~14 ~13 ~5 ~32 ~13 ~5 wool 15
fill ~14 ~13 ~6 ~32 ~13 ~6 wool 15
fill ~14 ~13 ~7 ~32 ~13 ~7 wool 15
fill ~14 ~13 ~8 ~32 ~13 ~8 wool 15
fill ~14 ~13 ~9 ~32 ~13 ~9 wool 15
fill ~14 ~13 ~10 ~32 ~13 ~10 wool 15
fill ~14 ~13 ~11 ~32 ~13 ~11 wool 15
fill ~14 ~13 ~12 ~32 ~13 ~12 wool 15
fill ~14 ~13 ~13 ~32 ~13 ~13 wool 15
fill ~14 ~13 ~14 ~32 ~13 ~14 wool 15
fill ~14 ~13 ~15 ~32 ~13 ~15 wool 15
fill ~14 ~13 ~16 ~32 ~13 ~16 wool 15
fill ~14 ~13 ~17 ~32 ~13 ~17 wool 15
fill ~14 ~13 ~18 ~32 ~13 ~18 wool 15
fill ~14 ~13 ~19 ~32 ~13 ~19 wool 15
fill ~14 ~13 ~20 ~32 ~13 ~20 wool 15
fill ~14 ~13 ~21 ~32 ~13 ~21 wool 15
fill ~14 ~13 ~22 ~32 ~13 ~22 wool 15
fill ~14 ~13 ~23 ~32 ~13 ~23 wool 15
fill ~14 ~13 ~24 ~32 ~13 ~24 wool 15
fill ~14 ~13 ~25 ~32 ~13 ~25 wool 15
fill ~14 ~13 ~26 ~32 ~13 ~26 wool 15
fill ~14 ~13 ~27 ~32 ~13 ~27 wool 15
fill ~14 ~13 ~28 ~32 ~13 ~28 wool 15
fill ~14 ~13 ~59 ~37 ~13 ~59 wool 15
fill ~14 ~13 ~80 ~37 ~13 ~80 wool 15
fill ~14 ~13 ~82 ~33 ~13 ~82 wool 14
setblock ~15 ~13 ~84 iron_bars 0
setblock ~16 ~13 ~84 iron_bars 15
fill ~17 ~13 ~84 ~17 ~18 ~84 wool 15
fill ~18 ~13 ~84 ~18 ~17 ~84 iron_bars 14
fill ~19 ~13 ~84 ~22 ~13 ~84 iron_bars 0
fill ~23 ~13 ~84 ~24 ~13 ~84 iron_bars 15
fill ~25 ~13 ~84 ~28 ~13 ~84 iron_bars 0
fill ~29 ~13 ~84 ~29 ~17 ~84 iron_bars 14
fill ~30 ~13 ~84 ~31 ~13 ~84 iron_bars 15
fill ~30 ~13 ~85 ~35 ~13 ~85 wool 15
setblock ~32 ~13 ~84 iron_bars 0
fill ~33 ~13 ~0 ~39 ~13 ~0 wool 7
fill ~35 ~13 ~83 ~38 ~13 ~83 wool 7
fill ~35 ~13 ~84 ~38 ~13 ~84 wool 15
fill ~37 ~13 ~60 ~37 ~13 ~80 wool 15
fill ~39 ~13 ~10 ~39 ~14 ~10 wool 14
fill ~39 ~13 ~11 ~39 ~52 ~11 wool 7
fill ~39 ~13 ~35 ~39 ~18 ~35 wool 14
fill ~39 ~13 ~36 ~39 ~17 ~36 wool 14
fill ~39 ~13 ~37 ~39 ~18 ~37 wool 14
fill ~39 ~13 ~44 ~39 ~14 ~44 wool 14
fill ~39 ~13 ~45 ~39 ~14 ~45 wool 14
fill ~39 ~13 ~46 ~39 ~15 ~46 wool 14
fill ~39 ~13 ~47 ~39 ~13 ~66 wool 7
setblock ~39 ~13 ~67 wool 14
fill ~39 ~13 ~76 ~39 ~64 ~76 wool 7
setblock ~39 ~13 ~77 wool 14
fill ~39 ~13 ~83 ~39 ~18 ~83 wool 15
fill ~8 ~14 ~0 ~39 ~14 ~0 wool 7
fill ~8 ~14 ~34 ~8 ~19 ~34 wool 14
fill ~8 ~14 ~47 ~8 ~15 ~47 wool 14
fill ~8 ~14 ~48 ~8 ~14 ~67 glass 0
setblock ~8 ~14 ~68 wool 14
fill ~8 ~14 ~77 ~8 ~63 ~77 wool 7
setblock ~8 ~14 ~78 wool 14
fill ~9 ~14 ~84 ~12 ~14 ~84 wool 15
fill ~10 ~14 ~83 ~13 ~14 ~83 wool 15
fill ~12 ~14 ~85 ~16 ~14 ~85 wool 15
fill ~14 ~14 ~82 ~33 ~14 ~82 wool 14
setblock ~15 ~14 ~84 iron_bars 15
fill ~16 ~14 ~84 ~16 ~19 ~84 iron_bars 0
fill ~19 ~14 ~84 ~21 ~14 ~84 iron_bars 0
setblock ~22 ~14 ~84 iron_bars 15
fill ~23 ~14 ~84 ~24 ~14 ~84 iron_bars 0
setblock ~25 ~14 ~84 iron_bars 15
fill ~26 ~14 ~84 ~28 ~14 ~84 iron_bars 0
fill ~30 ~14 ~84 ~31 ~14 ~84 iron_bars 0
fill ~30 ~14 ~85 ~35 ~14 ~85 wool 15
setblock ~32 ~14 ~84 iron_bars 15
fill ~35 ~14 ~83 ~38 ~14 ~83 wool 7
fill ~35 ~14 ~84 ~38 ~14 ~84 wool 15
fill ~39 ~14 ~34 ~39 ~19 ~34 wool 14
fill ~39 ~14 ~47 ~39 ~15 ~47 wool 14
fill ~39 ~14 ~48 ~39 ~14 ~67 wool 7
setblock ~39 ~14 ~68 wool 14
fill ~39 ~14 ~77 ~39 ~63 ~77 wool 7
setblock ~39 ~14 ~78 wool 14
fill ~40 ~14 ~82 ~40 ~18 ~82 wool 15
fill ~8 ~15 ~0 ~39 ~15 ~0 wool 7
fill ~8 ~15 ~9 ~8 ~51 ~9 wool 14
fill ~8 ~15 ~10 ~8 ~30 ~10 glass 0
fill ~8 ~15 ~43 ~8 ~20 ~43 glass 0
fill ~8 ~15 ~44 ~8 ~20 ~44 glass 0
fill ~8 ~15 ~45 ~8 ~19 ~45 glass 0
setblock ~8 ~15 ~48 wool 14
fill ~8 ~15 ~49 ~8 ~15 ~68 glass 0
setblock ~8 ~15 ~69 wool 14
fill ~8 ~15 ~78 ~8 ~61 ~78 wool 7
fill ~8 ~15 ~79 ~8 ~61 ~79 wool 14
fill ~9 ~15 ~84 ~12 ~15 ~84 wool 15
fill ~10 ~15 ~83 ~13 ~15 ~83 wool 15
fill ~12 ~15 ~85 ~16 ~15 ~85 wool 15
fill ~14 ~15 ~82 ~33 ~15 ~82 wool 14
fill ~15 ~15 ~84 ~15 ~18 ~84 iron_bars 0
setblock ~19 ~15 ~84 iron_bars 15
setblock ~20 ~15 ~84 iron_bars 0
setblock ~21 ~15 ~84 iron_bars 15
fill ~22 ~15 ~84 ~25 ~15 ~84 iron_bars 0
setblock ~26 ~15 ~84 iron_bars 15
setblock ~27 ~15 ~84 iron_bars 0
setblock ~28 ~15 ~84 iron_bars 15
fill ~30 ~15 ~84 ~32 ~15 ~84 iron_bars 0
fill ~30 ~15 ~85 ~35 ~15 ~85 wool 15
fill ~35 ~15 ~83 ~38 ~15 ~83 wool 7
fill ~35 ~15 ~84 ~38 ~15 ~84 wool 15
fill ~36 ~15 ~47 ~38 ~15 ~47 wool 15
fill ~36 ~15 ~48 ~38 ~15 ~48 wool 15
fill ~36 ~15 ~49 ~38 ~15 ~49 wool 15
fill ~36 ~15 ~50 ~38 ~15 ~50 wool 15
fill ~36 ~15 ~51 ~38 ~15 ~51 wool 15
fill ~36 ~15 ~52 ~38 ~15 ~52 wool 15
fill ~36 ~15 ~53 ~38 ~15 ~53 wool 15
fill ~36 ~15 ~54 ~38 ~15 ~54 wool 15
fill ~36 ~15 ~55 ~38 ~15 ~55 wool 15
fill ~36 ~15 ~56 ~38 ~15 ~56 wool 15
fill ~36 ~15 ~57 ~38 ~15 ~57 wool 15
fill ~39 ~15 ~9 ~39 ~51 ~9 wool 14
fill ~39 ~15 ~10 ~39 ~51 ~10 wool 7
fill ~39 ~15 ~43 ~39 ~20 ~43 wool 7
fill ~39 ~15 ~44 ~39 ~20 ~44 wool 7
fill ~39 ~15 ~45 ~39 ~19 ~45 wool 7
setblock ~39 ~15 ~48 wool 14
fill ~39 ~15 ~49 ~39 ~15 ~68 wool 7
setblock ~39 ~15 ~69 wool 14
fill ~39 ~15 ~78 ~39 ~61 ~78 wool 7
fill ~39 ~15 ~79 ~39 ~61 ~79 wool 14
fill ~8 ~16 ~0 ~39 ~16 ~0 wool 7
fill ~8 ~16 ~41 ~8 ~18 ~41 glass 0
fill ~8 ~16 ~42 ~8 ~21 ~42 glass 0
fill ~8 ~16 ~46 ~8 ~19 ~46 glass 0
fill ~8 ~16 ~47 ~8 ~22 ~47 glass 0
fill ~8 ~16 ~48 ~8 ~22 ~48 glass 0
setblock ~8 ~16 ~49 wool 14
fill ~8 ~16 ~50 ~8 ~21 ~50 glass 0
fill ~8 ~16 ~51 ~8 ~24 ~51 glass 0
fill ~8 ~16 ~52 ~8 ~26 ~52 glass 0
fill ~8 ~16 ~53 ~8 ~27 ~53 glass 0
fill ~8 ~16 ~54 ~8 ~16 ~69 glass 0
setblock ~8 ~16 ~70 wool 14
fill ~9 ~16 ~1 ~16 ~16 ~1 wool 15
fill ~9 ~16 ~84 ~12 ~16 ~84 wool 15
fill ~10 ~16 ~83 ~12 ~16 ~83 wool 7
fill ~12 ~16 ~85 ~16 ~16 ~85 wool 15
fill ~14 ~16 ~59 ~37 ~16 ~59 wool 15
fill ~14 ~16 ~80 ~37 ~16 ~80 wool 15
fill ~14 ~16 ~82 ~33 ~16 ~82 wool 14
fill ~18 ~16 ~1 ~38 ~16 ~1 wool 15
fill ~19 ~16 ~84 ~19 ~17 ~84 iron_bars 0
fill ~20 ~16 ~84 ~20 ~17 ~84 iron_bars 15
fill ~21 ~16 ~84 ~26 ~16 ~84 iron_bars 0
fill ~27 ~16 ~84 ~27 ~17 ~84 iron_bars 15
fill ~28 ~16 ~84 ~28 ~17 ~84 iron_bars 0
fill ~30 ~16 ~84 ~32 ~16 ~84 iron_bars 0
fill ~30 ~16 ~85 ~35 ~16 ~85 wool 15
fill ~35 ~16 ~83 ~38 ~16 ~83 wool 7
fill ~35 ~16 ~84 ~38 ~16 ~84 wool 15
fill ~36 ~16 ~47 ~38 ~16 ~47 wool 15
fill ~36 ~16 ~49 ~36 ~15 ~49 wool 15
fill ~36 ~16 ~51 ~36 ~15 ~51 wool 15
fill ~36 ~16 ~53 ~36 ~15 ~53 wool 15
fill ~36 ~16 ~55 ~36 ~15 ~55 wool 15
fill ~36 ~16 ~57 ~38 ~16 ~57 wool 15
setblock ~37 ~16 ~48 wool 15
fill ~37 ~16 ~49 ~37 ~20 ~49 wool 1
setblock ~37 ~16 ~50 wool 15
setblock ~37 ~16 ~51 wool 4
setblock ~37 ~16 ~52 wool 15
setblock ~37 ~16 ~54 wool 15
setblock ~37 ~16 ~56 wool 15
fill ~37 ~16 ~60 ~37 ~16 ~80 wool 15
fill ~38 ~16 ~5 ~38 ~40 ~5 obsidian 0
fill ~38 ~16 ~6 ~38 ~40 ~6 obsidian 0
fill ~38 ~16 ~7 ~38 ~40 ~7 obsidian 0
fill ~38 ~16 ~8 ~38 ~40 ~8 obsidian 0
fill ~38 ~16 ~9 ~38 ~65 ~9 obsidian 0
fill ~38 ~16 ~10 ~38 ~65 ~10 obsidian 0
fill ~38 ~16 ~11 ~38 ~65 ~11 obsidian 0
fill ~38 ~16 ~12 ~38 ~65 ~12 obsidian 0
fill ~38 ~16 ~13 ~38 ~65 ~13 obsidian 0
fill ~38 ~16 ~14 ~38 ~65 ~14 obsidian 0
fill ~38 ~16 ~15 ~38 ~65 ~15 obsidian 0
fill ~38 ~16 ~16 ~38 ~65 ~16 obsidian 0
fill ~38 ~16 ~17 ~38 ~65 ~17 obsidian 0
fill ~38 ~16 ~18 ~38 ~65 ~18 obsidian 0
fill ~38 ~16 ~19 ~38 ~65 ~19 obsidian 0
fill ~38 ~16 ~20 ~38 ~65 ~20 obsidian 0
fill ~38 ~16 ~21 ~38 ~65 ~21 obsidian 0
fill ~38 ~16 ~22 ~38 ~65 ~22 obsidian 0
fill ~38 ~16 ~23 ~38 ~65 ~23 obsidian 0
fill ~38 ~16 ~24 ~38 ~65 ~24 obsidian 0
fill ~38 ~16 ~25 ~38 ~65 ~25 obsidian 0
fill ~38 ~16 ~26 ~38 ~65 ~26 obsidian 0
fill ~38 ~16 ~27 ~38 ~65 ~27 obsidian 0
fill ~38 ~16 ~28 ~38 ~65 ~28 obsidian 0
fill ~38 ~16 ~29 ~38 ~65 ~29 obsidian 0
fill ~38 ~16 ~30 ~38 ~65 ~30 obsidian 0
fill ~38 ~16 ~31 ~38 ~65 ~31 obsidian 0
fill ~38 ~16 ~32 ~38 ~65 ~32 obsidian 0
fill ~38 ~16 ~33 ~38 ~65 ~33 obsidian 0
fill ~38 ~16 ~34 ~38 ~65 ~34 obsidian 0
fill ~38 ~16 ~35 ~38 ~65 ~35 obsidian 0
fill ~38 ~16 ~36 ~38 ~65 ~36 obsidian 0
fill ~38 ~16 ~37 ~38 ~65 ~37 obsidian 0
fill ~38 ~16 ~38 ~38 ~65 ~38 obsidian 0
fill ~38 ~16 ~39 ~38 ~65 ~39 obsidian 0
fill ~38 ~16 ~40 ~38 ~65 ~40 obsidian 0
fill ~38 ~16 ~41 ~38 ~65 ~41 obsidian 0
fill ~38 ~16 ~42 ~38 ~65 ~42 obsidian 0
fill ~38 ~16 ~43 ~38 ~65 ~43 obsidian 0
fill ~38 ~16 ~44 ~38 ~65 ~44 obsidian 0
fill ~38 ~16 ~45 ~38 ~65 ~45 obsidian 0
fill ~38 ~16 ~48 ~38 ~21 ~48 wool 14
setblock ~38 ~16 ~49 wool 15
fill ~38 ~16 ~50 ~38 ~20 ~50 wool 11
setblock ~38 ~16 ~51 wool 15
setblock ~38 ~16 ~53 wool 15
setblock ~38 ~16 ~55 wool 15
fill ~39 ~16 ~41 ~39 ~18 ~41 wool 7
fill ~39 ~16 ~42 ~39 ~21 ~42 wool 7
fill ~39 ~16 ~46 ~39 ~19 ~46 wool 7
fill ~39 ~16 ~47 ~39 ~22 ~47 wool 7
fill ~39 ~16 ~48 ~39 ~22 ~48 wool 7
setblock ~39 ~16 ~49 wool 14
fill ~39 ~16 ~50 ~39 ~21 ~50 wool 7
fill ~39 ~16 ~51 ~39 ~24 ~51 wool 7
fill ~39 ~16 ~52 ~39 ~26 ~52 wool 7
fill ~39 ~16 ~53 ~39 ~27 ~53 wool 7
fill ~39 ~16 ~54 ~39 ~16 ~69 wool 7
setblock ~39 ~16 ~70 wool 14
fill ~8 ~17 ~0 ~9 ~17 ~0 wool 7
setblock ~8 ~17 ~33 wool 14
setblock ~8 ~17 ~40 glass 0
fill ~8 ~17 ~49 ~8 ~21 ~49 glass 0
fill ~8 ~17 ~54 ~8 ~17 ~55 wool 14
fill ~8 ~17 ~56 ~8 ~17 ~70 glass 0
setblock ~8 ~17 ~71 wool 14
fill ~9 ~17 ~1 ~9 ~40 ~1 wool 15
fill ~9 ~17 ~84 ~12 ~17 ~84 wool 15
fill ~10 ~17 ~1 ~15 ~17 ~1 web 0
fill ~10 ~17 ~83 ~11 ~17 ~83 wool 7
fill ~12 ~17 ~57 ~12 ~20 ~57 wool 7
fill ~12 ~17 ~58 ~12 ~20 ~58 wool 7
fill ~12 ~17 ~59 ~12 ~20 ~59 wool 7
fill ~12 ~17 ~60 ~12 ~20 ~60 wool 7
fill ~12 ~17 ~61 ~12 ~20 ~61 wool 7
fill ~12 ~17 ~62 ~12 ~20 ~62 wool 7
fill ~12 ~17 ~63 ~12 ~20 ~63 wool 7
fill ~12 ~17 ~64 ~12 ~20 ~64 wool 7
fill ~12 ~17 ~65 ~12 ~20 ~65 wool 7
fill ~12 ~17 ~66 ~12 ~20 ~66 wool 7
fill ~12 ~17 ~67 ~12 ~20 ~67 wool 7
fill ~12 ~17 ~68 ~12 ~20 ~68 wool 7
fill ~12 ~17 ~69 ~12 ~20 ~69 wool 7
fill ~12 ~17 ~70 ~12 ~20 ~70 wool 7
fill ~12 ~17 ~71 ~12 ~20 ~71 wool 7
fill ~12 ~17 ~72 ~12 ~20 ~72 wool 7
fill ~12 ~17 ~73 ~12 ~20 ~73 wool 7
fill ~12 ~17 ~74 ~12 ~20 ~74 wool 7
fill ~12 ~17 ~75 ~12 ~20 ~75 wool 7
fill ~12 ~17 ~76 ~12 ~20 ~76 wool 7
fill ~12 ~17 ~77 ~12 ~20 ~77 wool 7
fill ~12 ~17 ~78 ~12 ~20 ~78 wool 7
fill ~12 ~17 ~79 ~12 ~20 ~79 wool 7
setblock ~12 ~17 ~83 wool 15
fill ~12 ~17 ~85 ~16 ~17 ~85 wool 15
fill ~14 ~17 ~59 ~14 ~20 ~59 wool 8
fill ~14 ~17 ~60 ~36 ~17 ~60 iron_block 0
fill ~14 ~17 ~61 ~36 ~17 ~61 iron_block 0
fill ~14 ~17 ~62 ~36 ~17 ~62 iron_block 0
fill ~14 ~17 ~63 ~36 ~17 ~63 iron_block 0
fill ~14 ~17 ~64 ~36 ~17 ~64 iron_block 0
fill ~14 ~17 ~65 ~36 ~17 ~65 iron_block 0
fill ~14 ~17 ~66 ~36 ~17 ~66 iron_block 0
fill ~14 ~17 ~67 ~36 ~17 ~67 iron_block 0
fill ~14 ~17 ~68 ~36 ~17 ~68 iron_block 0
fill ~14 ~17 ~69 ~36 ~17 ~69 iron_block 0
fill ~14 ~17 ~70 ~36 ~17 ~70 iron_block 0
fill ~14 ~17 ~71 ~36 ~17 ~71 iron_block 0
fill ~14 ~17 ~72 ~36 ~17 ~72 iron_block 0
fill ~14 ~17 ~73 ~36 ~17 ~73 iron_block 0
fill ~14 ~17 ~74 ~36 ~17 ~74 iron_block 0
fill ~14 ~17 ~75 ~36 ~17 ~75 iron_block 0
fill ~14 ~17 ~76 ~36 ~17 ~76 iron_block 0
fill ~14 ~17 ~77 ~36 ~17 ~77 iron_block 0
fill ~14 ~17 ~78 ~36 ~17 ~78 iron_block 0
fill ~14 ~17 ~79 ~36 ~17 ~79 iron_block 0
fill ~14 ~17 ~80 ~14 ~20 ~80 wool 8
fill ~14 ~17 ~82 ~33 ~17 ~82 wool 14
fill ~16 ~17 ~0 ~18 ~17 ~0 wool 7
fill ~16 ~17 ~1 ~16 ~40 ~1 wool 15
fill ~18 ~17 ~1 ~18 ~40 ~1 wool 15
fill ~18 ~17 ~4 ~34 ~17 ~4 wool 15
fill ~18 ~17 ~5 ~34 ~17 ~5 wool 15
fill ~18 ~17 ~6 ~34 ~17 ~6 wool 15
fill ~18 ~17 ~7 ~34 ~17 ~7 wool 15
fill ~18 ~17 ~8 ~34 ~17 ~8 wool 15
fill ~18 ~17 ~9 ~34 ~17 ~9 wool 15
fill ~18 ~17 ~10 ~34 ~17 ~10 wool 15
fill ~18 ~17 ~11 ~34 ~17 ~11 wool 15
fill ~18 ~17 ~12 ~34 ~17 ~12 wool 15
fill ~18 ~17 ~13 ~34 ~17 ~13 wool 15
fill ~18 ~17 ~14 ~34 ~17 ~14 wool 15
fill ~18 ~17 ~15 ~34 ~17 ~15 wool 15
fill ~18 ~17 ~16 ~34 ~17 ~16 wool 15
fill ~18 ~17 ~17 ~34 ~17 ~17 wool 15
fill ~18 ~17 ~18 ~34 ~17 ~18 wool 15
fill ~18 ~17 ~19 ~34 ~17 ~19 wool 15
fill ~18 ~17 ~20 ~34 ~17 ~20 wool 15
fill ~18 ~17 ~21 ~34 ~17 ~21 wool 15
fill ~18 ~17 ~22 ~34 ~17 ~22 wool 15
fill ~18 ~17 ~23 ~34 ~17 ~23 wool 15
fill ~18 ~17 ~24 ~34 ~17 ~24 wool 15
fill ~18 ~17 ~25 ~34 ~17 ~25 wool 15
fill ~18 ~17 ~26 ~34 ~17 ~26 wool 15
fill ~18 ~17 ~27 ~34 ~17 ~27 wool 15
fill ~18 ~17 ~28 ~34 ~17 ~28 wool 15
fill ~18 ~17 ~29 ~34 ~17 ~29 wool 15
fill ~18 ~17 ~30 ~34 ~17 ~30 wool 15
fill ~18 ~17 ~31 ~34 ~17 ~31 wool 15
fill ~18 ~17 ~32 ~34 ~17 ~32 wool 15
fill ~18 ~17 ~33 ~34 ~17 ~33 wool 15
fill ~18 ~17 ~34 ~34 ~17 ~34 wool 15
fill ~18 ~17 ~35 ~34 ~17 ~35 wool 15
fill ~18 ~17 ~36 ~34 ~17 ~36 wool 15
fill ~18 ~17 ~37 ~34 ~17 ~37 wool 15
fill ~18 ~17 ~38 ~34 ~17 ~38 wool 15
fill ~18 ~17 ~39 ~34 ~17 ~39 wool 15
fill ~18 ~17 ~40 ~34 ~17 ~40 wool 15
fill ~18 ~17 ~41 ~18 ~31 ~41 wool 7
fill ~18 ~17 ~42 ~18 ~17 ~45 wool 7
fill ~18 ~17 ~46 ~34 ~17 ~46 wool 15
fill ~19 ~17 ~2 ~19 ~19 ~2 wool 8
fill ~19 ~17 ~3 ~19 ~19 ~3 wool 15
fill ~19 ~17 ~41 ~34 ~17 ~41 wool 15
fill ~19 ~17 ~42 ~34 ~17 ~42 wool 15
fill ~19 ~17 ~43 ~34 ~17 ~43 wool 15
fill ~19 ~17 ~44 ~34 ~17 ~44 wool 15
fill ~19 ~17 ~45 ~34 ~17 ~45 wool 15
fill ~20 ~17 ~2 ~27 ~17 ~2 gold_block 0
fill ~20 ~17 ~3 ~27 ~17 ~3 gold_block 0
fill ~21 ~17 ~84 ~26 ~17 ~84 iron_bars 0
fill ~24 ~17 ~59 ~24 ~20 ~59 wool 8
fill ~24 ~17 ~80 ~24 ~20 ~80 wool 8
fill ~25 ~17 ~59 ~25 ~21 ~59 wool 15
fill ~25 ~17 ~80 ~25 ~21 ~80 wool 15
fill ~26 ~17 ~59 ~26 ~20 ~59 wool 8
fill ~26 ~17 ~80 ~26 ~20 ~80 wool 8
fill ~28 ~17 ~2 ~30 ~17 ~2 wool 8
fill ~28 ~17 ~3 ~36 ~17 ~3 wool 15
fill ~29 ~17 ~1 ~30 ~17 ~1 wool 8
fill ~30 ~17 ~84 ~32 ~17 ~84 iron_bars 0
fill ~30 ~17 ~85 ~35 ~17 ~85 wool 15
fill ~31 ~17 ~1 ~36 ~17 ~1 gold_block 0
fill ~31 ~17 ~2 ~36 ~17 ~2 gold_block 0
fill ~35 ~17 ~83 ~38 ~17 ~83 wool 7
fill ~35 ~17 ~84 ~38 ~17 ~84 wool 15
fill ~36 ~17 ~35 ~36 ~19 ~35 snow 0
fill ~36 ~17 ~59 ~36 ~20 ~59 wool 8
fill ~36 ~17 ~80 ~36 ~20 ~80 wool 8
fill ~37 ~17 ~1 ~37 ~17 ~2 wool 8
fill ~37 ~17 ~7 ~37 ~17 ~32 wool 14
setblock ~37 ~17 ~33 snow 0
fill ~38 ~17 ~0 ~39 ~17 ~0 wool 7
fill ~38 ~17 ~1 ~38 ~40 ~1 wool 15
fill ~38 ~17 ~51 ~38 ~19 ~51 wool 4
setblock ~39 ~17 ~33 wool 14
setblock ~39 ~17 ~40 wool 7
fill ~39 ~17 ~49 ~39 ~21 ~49 wool 7
fill ~39 ~17 ~54 ~39 ~17 ~55 wool 14
fill ~39 ~17 ~56 ~39 ~17 ~70 wool 7
setblock ~39 ~17 ~71 wool 14
fill ~8 ~18 ~0 ~9 ~18 ~0 wool 7
setblock ~8 ~18 ~33 glass 0
fill ~8 ~18 ~36 ~8 ~21 ~36 glass 0
setblock ~8 ~18 ~40 wool 14
fill ~8 ~18 ~54 ~8 ~21 ~54 glass 0
fill ~8 ~18 ~55 ~8 ~18 ~57 wool 14
fill ~8 ~18 ~58 ~8 ~18 ~71 glass 0
setblock ~8 ~18 ~72 wool 14
fill ~9 ~18 ~84 ~12 ~18 ~84 wool 15
fill ~10 ~18 ~1 ~15 ~18 ~1 web 0
fill ~10 ~18 ~83 ~12 ~18 ~83 wool 7
fill ~12 ~18 ~85 ~16 ~18 ~85 wool 15
fill ~14 ~18 ~60 ~36 ~18 ~60 iron_block 0
fill ~14 ~18 ~61 ~14 ~17 ~61 iron_block 0
fill ~14 ~18 ~62 ~14 ~17 ~62 iron_block 0
fill ~14 ~18 ~63 ~14 ~17 ~63 iron_block 0
fill ~14 ~18 ~64 ~14 ~17 ~64 iron_block 0
fill ~14 ~18 ~65 ~14 ~17 ~65 iron_block 0
fill ~14 ~18 ~66 ~14 ~17 ~66 iron_block 0
fill ~14 ~18 ~67 ~14 ~17 ~67 iron_block 0
fill ~14 ~18 ~68 ~14 ~17 ~68 iron_block 0
fill ~14 ~18 ~69 ~14 ~17 ~69 iron_block 0
fill ~14 ~18 ~70 ~14 ~17 ~70 iron_block 0
fill ~14 ~18 ~71 ~14 ~17 ~71 iron_block 0
fill ~14 ~18 ~72 ~14 ~17 ~72 iron_block 0
fill ~14 ~18 ~73 ~14 ~17 ~73 iron_block 0
fill ~14 ~18 ~74 ~14 ~17 ~74 iron_block 0
fill ~14 ~18 ~75 ~14 ~17 ~75 iron_block 0
fill ~14 ~18 ~76 ~14 ~17 ~76 iron_block 0
fill ~14 ~18 ~77 ~14 ~17 ~77 iron_block 0
fill ~14 ~18 ~78 ~14 ~17 ~78 iron_block 0
fill ~14 ~18 ~79 ~36 ~18 ~79 iron_block 0
fill ~14 ~18 ~82 ~33 ~18 ~82 wool 14
fill ~16 ~18 ~0 ~18 ~18 ~0 wool 7
fill ~18 ~18 ~3 ~18 ~18 ~5 wool 15
fill ~18 ~18 ~9 ~19 ~18 ~9 wool 15
fill ~18 ~18 ~13 ~18 ~19 ~13 wool 15
fill ~18 ~18 ~14 ~18 ~19 ~14 wool 15
fill ~18 ~18 ~15 ~18 ~19 ~15 wool 15
fill ~18 ~18 ~16 ~18 ~18 ~21 wool 8
fill ~18 ~18 ~22 ~18 ~19 ~22 wool 15
fill ~18 ~18 ~23 ~18 ~19 ~23 wool 15
fill ~18 ~18 ~24 ~18 ~18 ~38 wool 8
fill ~18 ~18 ~39 ~18 ~19 ~39 wool 15
fill ~18 ~18 ~40 ~18 ~19 ~40 wool 15
fill ~18 ~18 ~42 ~18 ~29 ~42 gold_block 0
fill ~18 ~18 ~43 ~18 ~31 ~43 wool 7
fill ~18 ~18 ~44 ~18 ~29 ~44 snow 0
fill ~18 ~18 ~45 ~18 ~31 ~45 wool 7
fill ~18 ~18 ~46 ~34 ~18 ~46 wool 15
setblock ~18 ~18 ~84 iron_bars 0
fill ~19 ~18 ~4 ~36 ~18 ~4 wool 15
fill ~19 ~18 ~5 ~19 ~19 ~5 wool 15
fill ~19 ~18 ~6 ~19 ~18 ~8 double_stone_slab 0
fill ~19 ~18 ~10 ~19 ~18 ~12 double_stone_slab 0
fill ~19 ~18 ~30 ~34 ~18 ~30 wool 15
fill ~19 ~18 ~31 ~23 ~18 ~31 wool 15
fill ~19 ~18 ~32 ~21 ~18 ~32 wool 15
fill ~19 ~18 ~33 ~20 ~18 ~33 wool 15
fill ~19 ~18 ~34 ~19 ~19 ~34 wool 15
fill ~19 ~18 ~35 ~19 ~19 ~35 wool 15
fill ~19 ~18 ~36 ~22 ~18 ~36 wool 8
fill ~19 ~18 ~37 ~24 ~18 ~37 wool 8
fill ~19 ~18 ~41 ~19 ~19 ~41 wool 15
fill ~19 ~18 ~42 ~19 ~19 ~42 wool 15
fill ~19 ~18 ~43 ~20 ~18 ~43 wool 15
fill ~19 ~18 ~44 ~21 ~18 ~44 wool 15
fill ~19 ~18 ~45 ~23 ~18 ~45 wool 15
setblock ~19 ~18 ~84 iron_bars 14
fill ~20 ~18 ~6 ~20 ~19 ~6 wool 15
fill ~20 ~18 ~7 ~20 ~19 ~7 wool 15
fill ~20 ~18 ~8 ~20 ~18 ~6 wool 15
setblock ~20 ~18 ~10 wool 15
setblock ~20 ~18 ~11 gold_block 0
setblock ~20 ~18 ~12 wool 15
setblock ~20 ~18 ~13 gold_block 0
setblock ~20 ~18 ~15 gold_block 0
setblock ~20 ~18 ~17 gold_block 0
setblock ~20 ~18 ~19 gold_block 0
setblock ~20 ~18 ~21 gold_block 0
fill ~20 ~18 ~34 ~21 ~18 ~34 wool 8
fill ~20 ~18 ~35 ~21 ~18 ~35 wool 8
setblock ~20 ~18 ~84 iron_bars 0
setblock ~21 ~18 ~8 gold_block 0
setblock ~21 ~18 ~10 gold_block 0
fill ~21 ~18 ~12 ~31 ~18 ~12 wool 8
fill ~21 ~18 ~13 ~21 ~19 ~13 wool 8
fill ~21 ~18 ~14 ~21 ~19 ~14 wool 8
fill ~21 ~18 ~15 ~21 ~19 ~15 wool 8
fill ~21 ~18 ~16 ~21 ~19 ~16 wool 8
fill ~21 ~18 ~17 ~21 ~19 ~17 wool 8
fill ~21 ~18 ~18 ~21 ~19 ~18 wool 8
fill ~21 ~18 ~19 ~21 ~19 ~19 wool 8
fill ~21 ~18 ~20 ~21 ~19 ~20 wool 8
fill ~21 ~18 ~21 ~31 ~18 ~21 wool 8
setblock ~21 ~18 ~22 gold_block 0
setblock ~21 ~18 ~24 gold_block 0
setblock ~21 ~18 ~26 gold_block 0
setblock ~21 ~18 ~33 wool 8
fill ~21 ~18 ~43 ~25 ~18 ~43 wool 8
setblock ~21 ~18 ~84 iron_bars 15
setblock ~22 ~18 ~7 gold_block 0
setblock ~22 ~18 ~27 gold_block 0
fill ~22 ~18 ~38 ~25 ~18 ~38 wool 8
fill ~22 ~18 ~44 ~25 ~18 ~44 wool 8
fill ~22 ~18 ~84 ~25 ~18 ~84 iron_bars 0
setblock ~23 ~18 ~6 gold_block 0
setblock ~23 ~18 ~27 wool 5
setblock ~23 ~18 ~28 gold_block 0
fill ~24 ~18 ~42 ~26 ~18 ~42 wool 8
fill ~24 ~18 ~45 ~25 ~18 ~45 wool 8
setblock ~25 ~18 ~6 gold_block 0
fill ~25 ~18 ~27 ~26 ~18 ~27 wool 5
setblock ~25 ~18 ~28 gold_block 0
fill ~25 ~18 ~40 ~26 ~18 ~40 wool 8
fill ~25 ~18 ~41 ~26 ~18 ~41 wool 8
setblock ~26 ~18 ~18 wool 15
fill ~26 ~18 ~34 ~28 ~18 ~34 wool 8
fill ~26 ~18 ~35 ~27 ~18 ~35 wool 8
fill ~26 ~18 ~36 ~27 ~18 ~36 wool 8
fill ~26 ~18 ~37 ~26 ~18 ~34 wool 8
setblock ~26 ~18 ~38 glowstone 0
setblock ~26 ~18 ~39 wool 8
setblock ~26 ~18 ~84 iron_bars 15
setblock ~27 ~18 ~6 gold_block 0
setblock ~27 ~18 ~28 gold_block 0
fill ~27 ~18 ~31 ~28 ~18 ~31 wool 8
fill ~27 ~18 ~32 ~30 ~18 ~32 wool 8
fill ~27 ~18 ~33 ~31 ~18 ~33 wool 8
fill ~27 ~18 ~38 ~30 ~18 ~38 wool 8
setblock ~27 ~18 ~84 iron_bars 0
fill ~28 ~18 ~2 ~29 ~18 ~2 wool 8
fill ~28 ~18 ~3 ~30 ~18 ~3 wool 15
fill ~28 ~18 ~39 ~33 ~18 ~39 wool 8
setblock ~28 ~18 ~84 iron_bars 14
fill ~29 ~18 ~1 ~29 ~19 ~1 wool 8
setblock ~29 ~18 ~6 gold_block 0
setblock ~29 ~18 ~28 gold_block 0
fill ~29 ~18 ~31 ~34 ~18 ~31 wool 15
fill ~29 ~18 ~45 ~34 ~18 ~45 wool 15
fill ~29 ~18 ~84 ~32 ~18 ~84 iron_bars 0
fill ~30 ~18 ~1 ~30 ~18 ~2 gold_block 0
setblock ~30 ~18 ~7 gold_block 0
setblock ~30 ~18 ~27 gold_block 0
fill ~30 ~18 ~40 ~33 ~18 ~40 wool 8
fill ~30 ~18 ~85 ~35 ~18 ~85 wool 15
setblock ~31 ~18 ~8 gold_block 0
setblock ~31 ~18 ~10 gold_block 0
fill ~31 ~18 ~13 ~31 ~19 ~13 wool 8
fill ~31 ~18 ~14 ~31 ~19 ~14 wool 8
fill ~31 ~18 ~15 ~31 ~19 ~15 wool 8
fill ~31 ~18 ~16 ~31 ~19 ~16 wool 8
fill ~31 ~18 ~17 ~31 ~19 ~17 wool 8
fill ~31 ~18 ~18 ~31 ~19 ~18 wool 8
fill ~31 ~18 ~19 ~31 ~19 ~19 wool 8
fill ~31 ~18 ~20 ~31 ~19 ~20 wool 8
setblock ~31 ~18 ~22 gold_block 0
setblock ~31 ~18 ~24 gold_block 0
setblock ~31 ~18 ~26 gold_block 0
fill ~31 ~18 ~32 ~34 ~18 ~32 wool 15
fill ~31 ~18 ~41 ~32 ~18 ~41 wool 8
fill ~31 ~18 ~42 ~32 ~18 ~42 wool 8
fill ~31 ~18 ~43 ~31 ~18 ~39 wool 8
fill ~31 ~18 ~44 ~34 ~18 ~44 wool 15
setblock ~32 ~18 ~11 gold_block 0
setblock ~32 ~18 ~13 gold_block 0
setblock ~32 ~18 ~15 gold_block 0
setblock ~32 ~18 ~17 gold_block 0
setblock ~32 ~18 ~19 gold_block 0
setblock ~32 ~18 ~21 gold_block 0
fill ~32 ~18 ~33 ~34 ~18 ~33 wool 15
fill ~32 ~18 ~43 ~34 ~18 ~43 wool 15
fill ~33 ~18 ~34 ~34 ~18 ~34 wool 15
fill ~33 ~18 ~35 ~34 ~18 ~35 wool 15
fill ~33 ~18 ~41 ~34 ~18 ~41 wool 15
fill ~33 ~18 ~42 ~34 ~18 ~42 wool 15
fill ~34 ~18 ~5 ~34 ~19 ~5 wool 15
fill ~34 ~18 ~6 ~34 ~19 ~6 wool 15
fill ~34 ~18 ~7 ~34 ~19 ~7 wool 15
fill ~34 ~18 ~8 ~34 ~19 ~8 wool 15
fill ~34 ~18 ~9 ~34 ~19 ~9 wool 15
fill ~34 ~18 ~10 ~34 ~19 ~10 wool 15
fill ~34 ~18 ~11 ~34 ~19 ~11 wool 15
fill ~34 ~18 ~12 ~34 ~19 ~12 wool 15
fill ~34 ~18 ~13 ~34 ~19 ~13 wool 15
fill ~34 ~18 ~14 ~34 ~19 ~14 wool 15
fill ~34 ~18 ~15 ~34 ~19 ~15 wool 15
fill ~34 ~18 ~16 ~34 ~19 ~16 wool 15
fill ~34 ~18 ~17 ~34 ~19 ~17 wool 15
fill ~34 ~18 ~18 ~34 ~19 ~18 wool 15
fill ~34 ~18 ~19 ~34 ~19 ~19 wool 15
fill ~34 ~18 ~20 ~34 ~19 ~20 wool 15
fill ~34 ~18 ~21 ~34 ~19 ~21 wool 15
fill ~34 ~18 ~22 ~34 ~19 ~22 wool 15
fill ~34 ~18 ~23 ~34 ~19 ~23 wool 15
fill ~34 ~18 ~24 ~34 ~19 ~24 wool 15
fill ~34 ~18 ~25 ~34 ~19 ~25 wool 15
fill ~34 ~18 ~26 ~34 ~19 ~26 wool 15
fill ~34 ~18 ~27 ~34 ~19 ~27 wool 15
fill ~34 ~18 ~28 ~34 ~19 ~28 wool 15
fill ~34 ~18 ~29 ~34 ~19 ~29 wool 15
fill ~34 ~18 ~36 ~34 ~19 ~36 wool 15
fill ~34 ~18 ~37 ~34 ~19 ~37 wool 15
fill ~34 ~18 ~38 ~34 ~19 ~38 wool 15
fill ~34 ~18 ~39 ~34 ~19 ~39 wool 15
fill ~34 ~18 ~40 ~34 ~19 ~40 wool 15
fill ~35 ~18 ~7 ~35 ~18 ~35 wool 7
fill ~35 ~18 ~61 ~35 ~18 ~66 wool 15
fill ~35 ~18 ~69 ~35 ~18 ~72 wool 15
fill ~35 ~18 ~83 ~38 ~18 ~83 wool 7
fill ~35 ~18 ~84 ~38 ~18 ~84 wool 15
fill ~36 ~18 ~7 ~37 ~18 ~7 wool 13
fill ~36 ~18 ~8 ~37 ~18 ~8 wool 13
fill ~36 ~18 ~9 ~37 ~18 ~9 wool 13
fill ~36 ~18 ~10 ~37 ~18 ~10 wool 13
fill ~36 ~18 ~11 ~37 ~18 ~11 wool 13
fill ~36 ~18 ~12 ~37 ~18 ~12 wool 13
fill ~36 ~18 ~13 ~37 ~18 ~13 wool 13
fill ~36 ~18 ~14 ~37 ~18 ~14 wool 13
fill ~36 ~18 ~15 ~37 ~18 ~15 wool 13
fill ~36 ~18 ~16 ~37 ~18 ~16 wool 13
fill ~36 ~18 ~17 ~37 ~18 ~17 wool 13
fill ~36 ~18 ~18 ~37 ~18 ~18 wool 13
fill ~36 ~18 ~19 ~37 ~18 ~19 wool 13
fill ~36 ~18 ~20 ~37 ~18 ~20 wool 13
fill ~36 ~18 ~21 ~37 ~18 ~21 wool 13
fill ~36 ~18 ~22 ~37 ~18 ~22 wool 13
fill ~36 ~18 ~23 ~37 ~18 ~23 wool 13
fill ~36 ~18 ~24 ~37 ~18 ~24 wool 13
fill ~36 ~18 ~25 ~37 ~18 ~25 wool 13
fill ~36 ~18 ~26 ~37 ~18 ~26 wool 13
fill ~36 ~18 ~27 ~37 ~18 ~27 wool 13
fill ~36 ~18 ~28 ~37 ~18 ~28 wool 13
fill ~36 ~18 ~29 ~37 ~18 ~29 wool 13
fill ~36 ~18 ~30 ~37 ~18 ~30 wool 13
fill ~36 ~18 ~31 ~37 ~18 ~31 wool 13
fill ~36 ~18 ~32 ~37 ~18 ~32 wool 13
fill ~36 ~18 ~33 ~36 ~18 ~35 snow 0
fill ~36 ~18 ~61 ~38 ~18 ~61 wool 1
fill ~36 ~18 ~62 ~36 ~18 ~66 wool 1
fill ~36 ~18 ~67 ~36 ~18 ~68 iron_block 0
fill ~36 ~18 ~69 ~37 ~18 ~69 wool 4
fill ~36 ~18 ~70 ~36 ~18 ~72 wool 4
fill ~36 ~18 ~73 ~36 ~18 ~79 iron_block 0
fill ~37 ~18 ~1 ~37 ~18 ~2 gold_block 0
setblock ~37 ~18 ~3 wool 15
setblock ~37 ~18 ~6 wool 14
setblock ~37 ~18 ~33 wool 14
setblock ~37 ~18 ~34 snow 0
fill ~38 ~18 ~0 ~39 ~18 ~0 wool 7
fill ~38 ~18 ~62 ~38 ~20 ~62 wool 4
fill ~38 ~18 ~63 ~38 ~18 ~68 wool 4
setblock ~39 ~18 ~33 wool 7
fill ~39 ~18 ~36 ~39 ~21 ~36 wool 7
setblock ~39 ~18 ~40 wool 14
fill ~39 ~18 ~54 ~39 ~21 ~54 wool 7
fill ~39 ~18 ~55 ~39 ~18 ~57 wool 14
fill ~39 ~18 ~58 ~39 ~18 ~71 wool 7
setblock ~39 ~18 ~72 wool 14
fill ~8 ~19 ~0 ~9 ~19 ~0 wool 7
fill ~8 ~19 ~32 ~8 ~24 ~32 wool 14
fill ~8 ~19 ~33 ~8 ~21 ~33 wool 14
fill ~8 ~19 ~35 ~8 ~21 ~35 glass 0
fill ~8 ~19 ~37 ~8 ~20 ~37 glass 0
fill ~8 ~19 ~38 ~8 ~20 ~38 glass 0
fill ~8 ~19 ~39 ~8 ~20 ~39 glass 0
fill ~8 ~19 ~40 ~8 ~20 ~40 glass 0
setblock ~8 ~19 ~41 wool 14
fill ~8 ~19 ~55 ~8 ~22 ~55 glass 0
fill ~8 ~19 ~56 ~8 ~19 ~59 wool 14
fill ~8 ~19 ~60 ~8 ~19 ~72 glass 0
setblock ~8 ~19 ~73 wool 14
fill ~10 ~19 ~1 ~15 ~19 ~1 web 0
fill ~10 ~19 ~83 ~12 ~19 ~83 wool 7
fill ~13 ~19 ~85 ~13 ~23 ~85 wool 7
fill ~14 ~19 ~60 ~36 ~19 ~60 stone_slab 0
fill ~14 ~19 ~61 ~36 ~19 ~61 stone_slab 0
fill ~14 ~19 ~62 ~36 ~19 ~62 stone_slab 0
fill ~14 ~19 ~63 ~36 ~19 ~63 stone_slab 0
fill ~14 ~19 ~64 ~36 ~19 ~64 stone_slab 0
fill ~14 ~19 ~65 ~36 ~19 ~65 stone_slab 0
fill ~14 ~19 ~66 ~36 ~19 ~66 stone_slab 0
fill ~14 ~19 ~67 ~36 ~19 ~67 stone_slab 0
fill ~14 ~19 ~68 ~36 ~19 ~68 stone_slab 0
fill ~14 ~19 ~69 ~36 ~19 ~69 stone_slab 0
fill ~14 ~19 ~70 ~36 ~19 ~70 stone_slab 0
fill ~14 ~19 ~71 ~36 ~19 ~71 stone_slab 0
fill ~14 ~19 ~72 ~36 ~19 ~72 stone_slab 0
fill ~14 ~19 ~73 ~36 ~19 ~73 stone_slab 0
fill ~14 ~19 ~74 ~36 ~19 ~74 stone_slab 0
fill ~14 ~19 ~75 ~36 ~19 ~75 stone_slab 0
fill ~14 ~19 ~76 ~36 ~19 ~76 stone_slab 0
fill ~14 ~19 ~77 ~36 ~19 ~77 stone_slab 0
fill ~14 ~19 ~78 ~36 ~19 ~78 stone_slab 0
fill ~14 ~19 ~79 ~36 ~19 ~79 stone_slab 0
fill ~14 ~19 ~82 ~33 ~19 ~82 wool 14
setblock ~15 ~19 ~84 iron_bars 15
fill ~16 ~19 ~0 ~18 ~19 ~0 wool 7
setblock ~17 ~19 ~84 iron_bars 0
fill ~18 ~19 ~4 ~34 ~19 ~4 wool 15
fill ~18 ~19 ~5 ~18 ~19 ~40 wool 15
fill ~18 ~19 ~46 ~34 ~19 ~46 wool 15
setblock ~18 ~19 ~84 iron_bars 15
fill ~19 ~19 ~6 ~19 ~19 ~10 wool 15
fill ~19 ~19 ~11 ~19 ~19 ~22 wool 7
fill ~19 ~19 ~23 ~19 ~19 ~35 wool 15
fill ~19 ~19 ~43 ~20 ~19 ~43 wool 15
fill ~19 ~19 ~44 ~21 ~19 ~44 wool 15
fill ~19 ~19 ~45 ~23 ~19 ~45 wool 15
fill ~19 ~19 ~84 ~19 ~21 ~84 iron_bars 0
fill ~20 ~19 ~2 ~30 ~19 ~2 wool 8
fill ~20 ~19 ~3 ~36 ~19 ~3 wool 15
setblock ~20 ~19 ~5 wool 15
fill ~20 ~19 ~8 ~20 ~19 ~10 wool 7
setblock ~20 ~19 ~12 wool 7
setblock ~20 ~19 ~14 wool 7
setblock ~20 ~19 ~16 wool 7
setblock ~20 ~19 ~18 wool 7
setblock ~20 ~19 ~20 wool 7
fill ~20 ~19 ~22 ~20 ~19 ~26 wool 7
fill ~20 ~19 ~27 ~20 ~19 ~33 wool 15
setblock ~20 ~19 ~84 iron_bars 14
fill ~21 ~19 ~5 ~31 ~19 ~5 wool 7
fill ~21 ~19 ~6 ~22 ~19 ~6 wool 7
fill ~21 ~19 ~7 ~21 ~19 ~5 wool 7
setblock ~21 ~19 ~9 wool 7
setblock ~21 ~19 ~11 wool 7
fill ~21 ~19 ~12 ~31 ~19 ~12 wool 8
fill ~21 ~19 ~21 ~31 ~19 ~21 wool 8
setblock ~21 ~19 ~23 wool 7
setblock ~21 ~19 ~25 wool 7
fill ~21 ~19 ~27 ~21 ~19 ~29 wool 7
fill ~21 ~19 ~30 ~34 ~19 ~30 wool 15
fill ~21 ~19 ~31 ~23 ~19 ~31 wool 15
fill ~21 ~19 ~32 ~21 ~19 ~30 wool 15
setblock ~21 ~19 ~84 iron_bars 0
setblock ~22 ~19 ~8 wool 7
fill ~22 ~19 ~9 ~30 ~19 ~9 wool 8
fill ~22 ~19 ~10 ~30 ~19 ~10 wool 8
fill ~22 ~19 ~11 ~30 ~19 ~11 wool 8
setblock ~22 ~19 ~13 wool 8
fill ~22 ~19 ~14 ~30 ~19 ~14 glass 0
fill ~22 ~19 ~15 ~30 ~19 ~15 glass 0
fill ~22 ~19 ~16 ~30 ~19 ~16 glass 0
fill ~22 ~19 ~17 ~30 ~19 ~17 glass 0
fill ~22 ~19 ~18 ~30 ~19 ~18 glass 0
fill ~22 ~19 ~19 ~30 ~19 ~19 glass 0
setblock ~22 ~19 ~20 wool 8
fill ~22 ~19 ~22 ~30 ~19 ~22 wool 8
fill ~22 ~19 ~23 ~30 ~19 ~23 wool 8
fill ~22 ~19 ~24 ~30 ~19 ~24 wool 8
fill ~22 ~19 ~25 ~30 ~19 ~25 wool 8
setblock ~22 ~19 ~26 wool 7
fill ~22 ~19 ~28 ~22 ~19 ~29 wool 7
setblock ~22 ~19 ~84 iron_bars 15
fill ~23 ~19 ~7 ~29 ~19 ~7 wool 8
fill ~23 ~19 ~8 ~29 ~19 ~8 wool 8
fill ~23 ~19 ~13 ~29 ~19 ~13 glass 0
fill ~23 ~19 ~20 ~29 ~19 ~20 glass 0
fill ~23 ~19 ~26 ~29 ~19 ~26 wool 8
fill ~23 ~19 ~27 ~29 ~19 ~27 wool 8
fill ~23 ~19 ~29 ~31 ~19 ~29 wool 7
fill ~23 ~19 ~84 ~24 ~19 ~84 iron_bars 0
setblock ~24 ~19 ~6 wool 7
setblock ~24 ~19 ~28 wool 7
setblock ~25 ~19 ~84 iron_bars 15
setblock ~26 ~19 ~6 wool 7
setblock ~26 ~19 ~28 wool 7
setblock ~26 ~19 ~84 iron_bars 0
setblock ~27 ~19 ~84 iron_bars 14
setblock ~28 ~19 ~6 wool 7
setblock ~28 ~19 ~28 wool 7
fill ~28 ~19 ~84 ~28 ~21 ~84 iron_bars 0
fill ~29 ~19 ~31 ~34 ~19 ~31 wool 15
fill ~29 ~19 ~45 ~34 ~19 ~45 wool 15
setblock ~29 ~19 ~84 iron_bars 15
setblock ~30 ~19 ~1 wool 8
fill ~30 ~19 ~6 ~31 ~19 ~6 wool 7
setblock ~30 ~19 ~8 wool 7
setblock ~30 ~19 ~13 wool 8
setblock ~30 ~19 ~20 wool 8
setblock ~30 ~19 ~26 wool 7
fill ~30 ~19 ~28 ~31 ~19 ~28 wool 7
fill ~30 ~19 ~84 ~31 ~19 ~84 iron_bars 0
fill ~31 ~19 ~1 ~36 ~19 ~1 gold_block 0
fill ~31 ~19 ~2 ~36 ~19 ~2 gold_block 0
setblock ~31 ~19 ~7 wool 7
fill ~31 ~19 ~9 ~32 ~19 ~9 wool 7
setblock ~31 ~19 ~11 wool 7
fill ~31 ~19 ~23 ~32 ~19 ~23 wool 7
fill ~31 ~19 ~25 ~32 ~19 ~25 wool 7
setblock ~31 ~19 ~27 wool 7
fill ~31 ~19 ~32 ~34 ~19 ~32 wool 15
fill ~31 ~19 ~44 ~34 ~19 ~44 wool 15
fill ~32 ~19 ~5 ~34 ~19 ~5 wool 15
fill ~32 ~19 ~6 ~34 ~19 ~6 wool 15
fill ~32 ~19 ~7 ~34 ~19 ~7 wool 15
setblock ~32 ~19 ~8 wool 7
setblock ~32 ~19 ~10 wool 7
fill ~32 ~19 ~12 ~33 ~19 ~12 wool 7
fill ~32 ~19 ~14 ~33 ~19 ~14 wool 7
fill ~32 ~19 ~16 ~33 ~19 ~16 wool 7
fill ~32 ~19 ~18 ~33 ~19 ~18 wool 7
fill ~32 ~19 ~20 ~33 ~19 ~20 wool 7
fill ~32 ~19 ~22 ~33 ~19 ~22 wool 7
setblock ~32 ~19 ~24 wool 7
setblock ~32 ~19 ~26 wool 7
fill ~32 ~19 ~27 ~34 ~19 ~27 wool 15
fill ~32 ~19 ~28 ~34 ~19 ~28 wool 15
fill ~32 ~19 ~29 ~34 ~19 ~29 wool 15
fill ~32 ~19 ~33 ~34 ~19 ~33 wool 15
fill ~32 ~19 ~43 ~34 ~19 ~43 wool 15
setblock ~32 ~19 ~84 iron_bars 15
fill ~33 ~19 ~8 ~33 ~19 ~10 wool 15
setblock ~33 ~19 ~11 wool 7
setblock ~33 ~19 ~13 wool 7
setblock ~33 ~19 ~15 wool 7
setblock ~33 ~19 ~17 wool 7
setblock ~33 ~19 ~19 wool 7
setblock ~33 ~19 ~21 wool 7
fill ~33 ~19 ~23 ~33 ~19 ~35 wool 15
fill ~33 ~19 ~41 ~34 ~19 ~41 wool 15
fill ~33 ~19 ~42 ~34 ~19 ~42 wool 15
fill ~34 ~19 ~34 ~34 ~19 ~46 wool 15
fill ~34 ~19 ~85 ~34 ~23 ~85 wool 7
fill ~35 ~19 ~83 ~38 ~19 ~83 wool 7
fill ~37 ~19 ~1 ~37 ~19 ~2 wool 8
fill ~37 ~19 ~7 ~37 ~19 ~32 wool 14
setblock ~37 ~19 ~33 snow 0
fill ~38 ~19 ~0 ~39 ~19 ~0 wool 7
fill ~38 ~19 ~46 ~38 ~65 ~46 obsidian 0
fill ~38 ~19 ~47 ~38 ~22 ~47 obsidian 0
fill ~38 ~19 ~52 ~38 ~19 ~55 wool 4
fill ~38 ~19 ~61 ~38 ~20 ~61 wool 1
fill ~39 ~19 ~32 ~39 ~24 ~32 wool 14
fill ~39 ~19 ~33 ~39 ~21 ~33 wool 14
fill ~39 ~19 ~35 ~39 ~21 ~35 wool 7
fill ~39 ~19 ~37 ~39 ~20 ~37 wool 7
fill ~39 ~19 ~38 ~39 ~20 ~38 wool 7
fill ~39 ~19 ~39 ~39 ~20 ~39 wool 7
fill ~39 ~19 ~40 ~39 ~20 ~40 wool 7
setblock ~39 ~19 ~41 wool 14
fill ~39 ~19 ~55 ~39 ~22 ~55 wool 7
fill ~39 ~19 ~56 ~39 ~19 ~59 wool 14
fill ~39 ~19 ~60 ~39 ~19 ~72 wool 7
setblock ~39 ~19 ~73 wool 14
fill ~8 ~20 ~0 ~9 ~20 ~0 wool 7
fill ~8 ~20 ~31 ~8 ~23 ~31 wool 14
fill ~8 ~20 ~34 ~8 ~22 ~34 glass 0
setblock ~8 ~20 ~41 glass 0
fill ~8 ~20 ~45 ~8 ~22 ~45 wool 14
fill ~8 ~20 ~46 ~8 ~21 ~46 wool 14
fill ~8 ~20 ~56 ~8 ~23 ~56 glass 0
fill ~8 ~20 ~57 ~8 ~27 ~57 wool 14
fill ~8 ~20 ~58 ~8 ~28 ~58 wool 14
fill ~8 ~20 ~59 ~8 ~29 ~59 wool 14
fill ~8 ~20 ~60 ~8 ~24 ~60 wool 14
fill ~8 ~20 ~61 ~8 ~21 ~61 glass 0
fill ~8 ~20 ~62 ~8 ~60 ~62 glass 0
fill ~8 ~20 ~63 ~8 ~60 ~63 glass 0
fill ~8 ~20 ~64 ~8 ~60 ~64 glass 0
fill ~8 ~20 ~65 ~8 ~60 ~65 glass 0
fill ~8 ~20 ~66 ~8 ~60 ~66 glass 0
fill ~8 ~20 ~67 ~8 ~60 ~67 glass 0
fill ~8 ~20 ~68 ~8 ~60 ~68 glass 0
fill ~8 ~20 ~69 ~8 ~60 ~69 glass 0
fill ~8 ~20 ~70 ~8 ~59 ~70 glass 0
fill ~8 ~20 ~71 ~8 ~59 ~71 glass 0
fill ~8 ~20 ~72 ~8 ~58 ~72 glass 0
fill ~8 ~20 ~73 ~8 ~56 ~73 glass 0
fill ~8 ~20 ~74 ~8 ~56 ~74 wool 14
fill ~10 ~20 ~1 ~15 ~20 ~1 web 0
fill ~10 ~20 ~83 ~12 ~20 ~83 wool 7
fill ~14 ~20 ~82 ~33 ~20 ~82 wool 14
setblock ~15 ~20 ~84 iron_bars 0
fill ~16 ~20 ~0 ~39 ~20 ~0 wool 7
fill ~16 ~20 ~84 ~17 ~20 ~84 iron_bars 15
fill ~18 ~20 ~84 ~18 ~25 ~84 iron_bars 0
fill ~19 ~20 ~1 ~38 ~20 ~1 wool 15
fill ~20 ~20 ~84 ~20 ~22 ~84 iron_bars 0
fill ~21 ~20 ~84 ~26 ~20 ~84 iron_bars 14
fill ~27 ~20 ~84 ~27 ~22 ~84 iron_bars 0
setblock ~29 ~20 ~84 iron_bars 0
fill ~30 ~20 ~84 ~31 ~20 ~84 iron_bars 15
setblock ~32 ~20 ~84 iron_bars 0
fill ~35 ~20 ~83 ~38 ~20 ~83 wool 7
fill ~37 ~20 ~50 ~37 ~20 ~51 wool 1
setblock ~37 ~20 ~55 wool 4
fill ~38 ~20 ~51 ~38 ~21 ~51 wool 11
fill ~38 ~20 ~52 ~38 ~20 ~61 wool 1
fill ~39 ~20 ~31 ~39 ~23 ~31 wool 14
fill ~39 ~20 ~34 ~39 ~22 ~34 wool 7
setblock ~39 ~20 ~41 wool 7
fill ~39 ~20 ~45 ~39 ~22 ~45 wool 14
fill ~39 ~20 ~46 ~39 ~21 ~46 wool 14
fill ~39 ~20 ~56 ~39 ~23 ~56 wool 7
fill ~39 ~20 ~57 ~39 ~27 ~57 wool 14
fill ~39 ~20 ~58 ~39 ~28 ~58 wool 14
fill ~39 ~20 ~59 ~39 ~29 ~59 wool 14
fill ~39 ~20 ~60 ~39 ~24 ~60 wool 14
fill ~39 ~20 ~61 ~39 ~21 ~61 wool 7
fill ~39 ~20 ~62 ~39 ~60 ~62 wool 7
fill ~39 ~20 ~63 ~39 ~60 ~63 wool 7
fill ~39 ~20 ~64 ~39 ~60 ~64 wool 7
fill ~39 ~20 ~65 ~39 ~60 ~65 wool 7
fill ~39 ~20 ~66 ~39 ~60 ~66 wool 7
fill ~39 ~20 ~67 ~39 ~60 ~67 wool 7
fill ~39 ~20 ~68 ~39 ~60 ~68 wool 7
fill ~39 ~20 ~69 ~39 ~60 ~69 wool 7
fill ~39 ~20 ~70 ~39 ~59 ~70 wool 7
fill ~39 ~20 ~71 ~39 ~59 ~71 wool 7
fill ~39 ~20 ~72 ~39 ~58 ~72 wool 7
fill ~39 ~20 ~73 ~39 ~56 ~73 wool 7
fill ~39 ~20 ~74 ~39 ~56 ~74 wool 14
fill ~8 ~21 ~0 ~9 ~21 ~0 wool 7
fill ~8 ~21 ~37 ~8 ~23 ~37 wool 14
fill ~8 ~21 ~38 ~8 ~23 ~38 wool 14
fill ~8 ~21 ~39 ~8 ~22 ~39 wool 14
fill ~8 ~21 ~40 ~8 ~21 ~41 wool 14
fill ~8 ~21 ~43 ~8 ~33 ~43 wool 14
fill ~8 ~21 ~44 ~8 ~27 ~44 wool 14
fill ~10 ~21 ~1 ~15 ~21 ~1 web 0
fill ~10 ~21 ~83 ~12 ~21 ~83 wool 7
fill ~14 ~21 ~59 ~37 ~21 ~59 wool 15
fill ~14 ~21 ~80 ~37 ~21 ~80 wool 15
fill ~14 ~21 ~82 ~33 ~21 ~82 wool 14
setblock ~15 ~21 ~84 iron_bars 15
fill ~16 ~21 ~0 ~18 ~21 ~0 wool 7
fill ~16 ~21 ~84 ~21 ~21 ~84 iron_bars 0
fill ~18 ~21 ~4 ~34 ~21 ~4 wool 15
fill ~18 ~21 ~5 ~34 ~21 ~5 wool 15
fill ~18 ~21 ~6 ~34 ~21 ~6 wool 15
fill ~18 ~21 ~7 ~34 ~21 ~7 wool 15
fill ~18 ~21 ~8 ~34 ~21 ~8 wool 15
fill ~18 ~21 ~9 ~34 ~21 ~9 wool 15
fill ~18 ~21 ~10 ~34 ~21 ~10 wool 15
fill ~18 ~21 ~11 ~34 ~21 ~11 wool 15
fill ~18 ~21 ~12 ~34 ~21 ~12 wool 15
fill ~18 ~21 ~13 ~34 ~21 ~13 wool 15
fill ~18 ~21 ~14 ~34 ~21 ~14 wool 15
fill ~18 ~21 ~15 ~34 ~21 ~15 wool 15
fill ~18 ~21 ~16 ~34 ~21 ~16 wool 15
fill ~18 ~21 ~17 ~34 ~21 ~17 wool 15
fill ~18 ~21 ~18 ~34 ~21 ~18 wool 15
fill ~18 ~21 ~19 ~34 ~21 ~19 wool 15
fill ~18 ~21 ~20 ~34 ~21 ~20 wool 15
fill ~18 ~21 ~21 ~34 ~21 ~21 wool 15
fill ~18 ~21 ~22 ~34 ~21 ~22 wool 15
fill ~18 ~21 ~23 ~34 ~21 ~23 wool 15
fill ~18 ~21 ~24 ~34 ~21 ~24 wool 15
fill ~18 ~21 ~25 ~34 ~21 ~25 wool 15
fill ~18 ~21 ~26 ~34 ~21 ~26 wool 15
fill ~18 ~21 ~27 ~34 ~21 ~27 wool 15
fill ~18 ~21 ~28 ~34 ~21 ~28 wool 15
fill ~18 ~21 ~29 ~34 ~21 ~29 wool 15
fill ~18 ~21 ~30 ~34 ~21 ~30 wool 15
fill ~18 ~21 ~31 ~34 ~21 ~31 wool 15
fill ~18 ~21 ~32 ~34 ~21 ~32 wool 15
fill ~18 ~21 ~33 ~34 ~21 ~33 wool 15
fill ~18 ~21 ~34 ~34 ~21 ~34 wool 15
fill ~18 ~21 ~35 ~34 ~21 ~35 wool 15
fill ~18 ~21 ~36 ~34 ~21 ~36 wool 15
fill ~18 ~21 ~37 ~34 ~21 ~37 wool 15
fill ~18 ~21 ~38 ~34 ~21 ~38 wool 15
fill ~18 ~21 ~39 ~34 ~21 ~39 wool 15
fill ~18 ~21 ~40 ~34 ~21 ~40 wool 15
fill ~18 ~21 ~46 ~34 ~21 ~46 wool 15
fill ~19 ~21 ~2 ~19 ~23 ~2 wool 8
fill ~19 ~21 ~3 ~19 ~23 ~3 wool 15
fill ~19 ~21 ~41 ~34 ~21 ~41 wool 15
fill ~19 ~21 ~42 ~34 ~21 ~42 wool 15
fill ~19 ~21 ~43 ~34 ~21 ~43 wool 15
fill ~19 ~21 ~44 ~34 ~21 ~44 wool 15
fill ~19 ~21 ~45 ~34 ~21 ~45 wool 15
fill ~20 ~21 ~2 ~27 ~21 ~2 gold_block 0
fill ~20 ~21 ~3 ~27 ~21 ~3 gold_block 0
setblock ~22 ~21 ~84 iron_bars 15
fill ~23 ~21 ~84 ~24 ~21 ~84 iron_bars 0
setblock ~25 ~21 ~84 iron_bars 15
setblock ~26 ~21 ~84 iron_bars 0
fill ~28 ~21 ~2 ~30 ~21 ~2 wool 8
fill ~28 ~21 ~3 ~36 ~21 ~3 wool 15
fill ~29 ~21 ~1 ~30 ~21 ~1 wool 8
setblock ~29 ~21 ~84 iron_bars 15
fill ~30 ~21 ~84 ~31 ~21 ~84 iron_bars 0
fill ~31 ~21 ~1 ~36 ~21 ~1 gold_block 0
fill ~31 ~21 ~2 ~36 ~21 ~2 gold_block 0
setblock ~32 ~21 ~84 iron_bars 15
fill ~35 ~21 ~83 ~38 ~21 ~83 wool 7
fill ~36 ~21 ~35 ~36 ~23 ~35 snow 0
fill ~37 ~21 ~1 ~37 ~21 ~2 wool 8
fill ~37 ~21 ~7 ~37 ~21 ~32 wool 14
setblock ~37 ~21 ~33 snow 0
fill ~37 ~21 ~60 ~37 ~21 ~80 wool 15
fill ~38 ~21 ~0 ~39 ~21 ~0 wool 7
fill ~38 ~21 ~49 ~38 ~21 ~50 wool 14
fill ~38 ~21 ~52 ~38 ~21 ~54 wool 11
fill ~38 ~21 ~55 ~38 ~21 ~61 wool 4
fill ~39 ~21 ~37 ~39 ~23 ~37 wool 14
fill ~39 ~21 ~38 ~39 ~23 ~38 wool 14
fill ~39 ~21 ~39 ~39 ~22 ~39 wool 14
fill ~39 ~21 ~40 ~39 ~21 ~41 wool 14
fill ~39 ~21 ~43 ~39 ~33 ~43 wool 14
fill ~39 ~21 ~44 ~39 ~27 ~44 wool 14
fill ~8 ~22 ~0 ~9 ~22 ~0 wool 7
fill ~8 ~22 ~33 ~8 ~23 ~33 glass 0
fill ~8 ~22 ~35 ~8 ~24 ~35 wool 14
fill ~8 ~22 ~36 ~8 ~24 ~36 wool 14
fill ~8 ~22 ~40 ~8 ~23 ~40 glass 0
fill ~8 ~22 ~41 ~8 ~22 ~40 glass 0
fill ~8 ~22 ~42 ~8 ~26 ~42 wool 14
fill ~8 ~22 ~46 ~8 ~23 ~46 glass 0
fill ~8 ~22 ~49 ~8 ~28 ~49 wool 14
fill ~8 ~22 ~50 ~8 ~28 ~50 wool 14
setblock ~8 ~22 ~54 wool 14
fill ~8 ~22 ~61 ~8 ~23 ~61 wool 14
fill ~10 ~22 ~1 ~15 ~22 ~1 web 0
fill ~10 ~22 ~83 ~12 ~22 ~83 wool 7
fill ~14 ~22 ~82 ~33 ~22 ~82 wool 14
fill ~15 ~22 ~84 ~18 ~22 ~84 iron_bars 0
fill ~16 ~22 ~0 ~18 ~22 ~0 wool 7
fill ~18 ~22 ~3 ~18 ~22 ~5 wool 15
fill ~18 ~22 ~9 ~19 ~22 ~9 wool 15
fill ~18 ~22 ~13 ~18 ~23 ~13 wool 15
fill ~18 ~22 ~14 ~18 ~23 ~14 wool 15
fill ~18 ~22 ~15 ~18 ~23 ~15 wool 15
fill ~18 ~22 ~16 ~18 ~22 ~21 wool 8
fill ~18 ~22 ~22 ~18 ~23 ~22 wool 15
fill ~18 ~22 ~23 ~18 ~23 ~23 wool 15
fill ~18 ~22 ~24 ~18 ~22 ~38 wool 8
fill ~18 ~22 ~39 ~18 ~23 ~39 wool 15
fill ~18 ~22 ~40 ~18 ~23 ~40 wool 15
fill ~18 ~22 ~46 ~34 ~22 ~46 wool 15
fill ~19 ~22 ~4 ~36 ~22 ~4 wool 15
fill ~19 ~22 ~5 ~19 ~23 ~5 wool 15
fill ~19 ~22 ~6 ~19 ~22 ~8 double_stone_slab 0
fill ~19 ~22 ~10 ~19 ~22 ~12 double_stone_slab 0
fill ~19 ~22 ~30 ~34 ~22 ~30 wool 15
fill ~19 ~22 ~31 ~23 ~22 ~31 wool 15
fill ~19 ~22 ~32 ~21 ~22 ~32 wool 15
fill ~19 ~22 ~33 ~20 ~22 ~33 wool 15
fill ~19 ~22 ~34 ~19 ~23 ~34 wool 15
fill ~19 ~22 ~35 ~19 ~23 ~35 wool 15
fill ~19 ~22 ~36 ~22 ~22 ~36 wool 8
fill ~19 ~22 ~37 ~24 ~22 ~37 wool 8
fill ~19 ~22 ~41 ~19 ~23 ~41 wool 15
fill ~19 ~22 ~42 ~19 ~23 ~42 wool 15
fill ~19 ~22 ~43 ~20 ~22 ~43 wool 15
fill ~19 ~22 ~44 ~21 ~22 ~44 wool 15
fill ~19 ~22 ~45 ~23 ~22 ~45 wool 15
setblock ~19 ~22 ~84 iron_bars 15
fill ~20 ~22 ~6 ~20 ~23 ~6 wool 15
fill ~20 ~22 ~7 ~20 ~23 ~7 wool 15
fill ~20 ~22 ~8 ~20 ~22 ~6 wool 15
setblock ~20 ~22 ~10 wool 15
setblock ~20 ~22 ~11 gold_block 0
setblock ~20 ~22 ~12 wool 15
setblock ~20 ~22 ~13 gold_block 0
setblock ~20 ~22 ~15 gold_block 0
setblock ~20 ~22 ~17 gold_block 0
setblock ~20 ~22 ~19 gold_block 0
setblock ~20 ~22 ~21 gold_block 0
fill ~20 ~22 ~34 ~21 ~22 ~34 wool 8
fill ~20 ~22 ~35 ~21 ~22 ~35 wool 8
setblock ~21 ~22 ~8 gold_block 0
setblock ~21 ~22 ~10 gold_block 0
fill ~21 ~22 ~12 ~31 ~22 ~12 wool 8
fill ~21 ~22 ~13 ~21 ~23 ~13 wool 8
fill ~21 ~22 ~14 ~21 ~23 ~14 wool 8
fill ~21 ~22 ~15 ~21 ~23 ~15 wool 8
fill ~21 ~22 ~16 ~21 ~23 ~16 wool 8
fill ~21 ~22 ~17 ~21 ~23 ~17 wool 8
fill ~21 ~22 ~18 ~21 ~23 ~18 wool 8
fill ~21 ~22 ~19 ~21 ~23 ~19 wool 8
fill ~21 ~22 ~20 ~21 ~23 ~20 wool 8
fill ~21 ~22 ~21 ~31 ~22 ~21 wool 8
setblock ~21 ~22 ~22 gold_block 0
setblock ~21 ~22 ~24 gold_block 0
setblock ~21 ~22 ~26 gold_block 0
setblock ~21 ~22 ~33 wool 8
fill ~21 ~22 ~43 ~25 ~22 ~43 wool 8
setblock ~21 ~22 ~84 iron_bars 15
setblock ~22 ~22 ~7 gold_block 0
setblock ~22 ~22 ~27 gold_block 0
fill ~22 ~22 ~38 ~25 ~22 ~38 wool 8
fill ~22 ~22 ~44 ~25 ~22 ~44 wool 8
fill ~22 ~22 ~84 ~25 ~22 ~84 iron_bars 0
setblock ~23 ~22 ~6 gold_block 0
setblock ~23 ~22 ~27 wool 5
setblock ~23 ~22 ~28 gold_block 0
fill ~24 ~22 ~42 ~26 ~22 ~42 wool 8
fill ~24 ~22 ~45 ~25 ~22 ~45 wool 8
setblock ~25 ~22 ~6 gold_block 0
fill ~25 ~22 ~27 ~26 ~22 ~27 wool 5
setblock ~25 ~22 ~28 gold_block 0
fill ~25 ~22 ~40 ~26 ~22 ~40 wool 8
fill ~25 ~22 ~41 ~26 ~22 ~41 wool 8
setblock ~26 ~22 ~18 wool 15
fill ~26 ~22 ~34 ~28 ~22 ~34 wool 8
fill ~26 ~22 ~35 ~27 ~22 ~35 wool 8
fill ~26 ~22 ~36 ~27 ~22 ~36 wool 8
fill ~26 ~22 ~37 ~26 ~22 ~34 wool 8
setblock ~26 ~22 ~38 glowstone 0
setblock ~26 ~22 ~39 wool 8
setblock ~26 ~22 ~84 iron_bars 15
setblock ~27 ~22 ~6 gold_block 0
setblock ~27 ~22 ~28 gold_block 0
fill ~27 ~22 ~31 ~28 ~22 ~31 wool 8
fill ~27 ~22 ~32 ~30 ~22 ~32 wool 8
fill ~27 ~22 ~33 ~31 ~22 ~33 wool 8
fill ~27 ~22 ~38 ~30 ~22 ~38 wool 8
fill ~28 ~22 ~2 ~29 ~22 ~2 wool 8
fill ~28 ~22 ~3 ~31 ~22 ~3 wool 15
fill ~28 ~22 ~39 ~33 ~22 ~39 wool 8
setblock ~28 ~22 ~84 iron_bars 15
fill ~29 ~22 ~1 ~29 ~23 ~1 wool 8
setblock ~29 ~22 ~6 gold_block 0
setblock ~29 ~22 ~28 gold_block 0
fill ~29 ~22 ~31 ~34 ~22 ~31 wool 15
fill ~29 ~22 ~45 ~34 ~22 ~45 wool 15
fill ~29 ~22 ~84 ~32 ~22 ~84 iron_bars 0
fill ~30 ~22 ~1 ~30 ~22 ~2 gold_block 0
setblock ~30 ~22 ~7 gold_block 0
setblock ~30 ~22 ~27 gold_block 0
fill ~30 ~22 ~40 ~33 ~22 ~40 wool 8
fill ~31 ~22 ~0 ~36 ~22 ~0 wool 15
fill ~31 ~22 ~1 ~36 ~22 ~1 wool 15
fill ~31 ~22 ~2 ~36 ~22 ~2 wool 15
setblock ~31 ~22 ~8 gold_block 0
setblock ~31 ~22 ~10 gold_block 0
fill ~31 ~22 ~13 ~31 ~23 ~13 wool 8
fill ~31 ~22 ~14 ~31 ~23 ~14 wool 8
fill ~31 ~22 ~15 ~31 ~23 ~15 wool 8
fill ~31 ~22 ~16 ~31 ~23 ~16 wool 8
fill ~31 ~22 ~17 ~31 ~23 ~17 wool 8
fill ~31 ~22 ~18 ~31 ~23 ~18 wool 8
fill ~31 ~22 ~19 ~31 ~23 ~19 wool 8
fill ~31 ~22 ~20 ~31 ~23 ~20 wool 8
setblock ~31 ~22 ~22 gold_block 0
setblock ~31 ~22 ~24 gold_block 0
setblock ~31 ~22 ~26 gold_block 0
fill ~31 ~22 ~32 ~34 ~22 ~32 wool 15
fill ~31 ~22 ~41 ~32 ~22 ~41 wool 8
fill ~31 ~22 ~42 ~32 ~22 ~42 wool 8
fill ~31 ~22 ~43 ~31 ~22 ~39 wool 8
fill ~31 ~22 ~44 ~34 ~22 ~44 wool 15
setblock ~32 ~22 ~11 gold_block 0
setblock ~32 ~22 ~13 gold_block 0
setblock ~32 ~22 ~15 gold_block 0
setblock ~32 ~22 ~17 gold_block 0
setblock ~32 ~22 ~19 gold_block 0
setblock ~32 ~22 ~21 gold_block 0
fill ~32 ~22 ~33 ~34 ~22 ~33 wool 15
fill ~32 ~22 ~43 ~34 ~22 ~43 wool 15
fill ~33 ~22 ~3 ~35 ~22 ~3 wool 15
fill ~33 ~22 ~34 ~34 ~22 ~34 wool 15
fill ~33 ~22 ~35 ~34 ~22 ~35 wool 15
fill ~33 ~22 ~41 ~34 ~22 ~41 wool 15
fill ~33 ~22 ~42 ~34 ~22 ~42 wool 15
fill ~34 ~22 ~5 ~34 ~23 ~5 wool 15
fill ~34 ~22 ~6 ~34 ~23 ~6 wool 15
fill ~34 ~22 ~7 ~34 ~23 ~7 wool 15
fill ~34 ~22 ~8 ~34 ~23 ~8 wool 15
fill ~34 ~22 ~9 ~34 ~23 ~9 wool 15
fill ~34 ~22 ~10 ~34 ~23 ~10 wool 15
fill ~34 ~22 ~11 ~34 ~23 ~11 wool 15
fill ~34 ~22 ~12 ~34 ~23 ~12 wool 15
fill ~34 ~22 ~13 ~34 ~23 ~13 wool 15
fill ~34 ~22 ~14 ~34 ~23 ~14 wool 15
fill ~34 ~22 ~15 ~34 ~23 ~15 wool 15
fill ~34 ~22 ~16 ~34 ~23 ~16 wool 15
fill ~34 ~22 ~17 ~34 ~23 ~17 wool 15
fill ~34 ~22 ~18 ~34 ~23 ~18 wool 15
fill ~34 ~22 ~19 ~34 ~23 ~19 wool 15
fill ~34 ~22 ~20 ~34 ~23 ~20 wool 15
fill ~34 ~22 ~21 ~34 ~23 ~21 wool 15
fill ~34 ~22 ~22 ~34 ~23 ~22 wool 15
fill ~34 ~22 ~23 ~34 ~23 ~23 wool 15
fill ~34 ~22 ~24 ~34 ~23 ~24 wool 15
fill ~34 ~22 ~25 ~34 ~23 ~25 wool 15
fill ~34 ~22 ~26 ~34 ~23 ~26 wool 15
fill ~34 ~22 ~27 ~34 ~23 ~27 wool 15
fill ~34 ~22 ~28 ~34 ~23 ~28 wool 15
fill ~34 ~22 ~29 ~34 ~23 ~29 wool 15
fill ~34 ~22 ~36 ~34 ~23 ~36 wool 15
fill ~34 ~22 ~37 ~34 ~23 ~37 wool 15
fill ~34 ~22 ~38 ~34 ~23 ~38 wool 15
fill ~34 ~22 ~39 ~34 ~23 ~39 wool 15
fill ~34 ~22 ~40 ~34 ~23 ~40 wool 15
fill ~35 ~22 ~7 ~35 ~22 ~35 wool 7
fill ~35 ~22 ~83 ~38 ~22 ~83 wool 7
fill ~36 ~22 ~7 ~37 ~22 ~7 wool 13
fill ~36 ~22 ~8 ~37 ~22 ~8 wool 13
fill ~36 ~22 ~9 ~37 ~22 ~9 wool 13
fill ~36 ~22 ~10 ~37 ~22 ~10 wool 13
fill ~36 ~22 ~11 ~37 ~22 ~11 wool 13
fill ~36 ~22 ~12 ~37 ~22 ~12 wool 13
fill ~36 ~22 ~13 ~37 ~22 ~13 wool 13
fill ~36 ~22 ~14 ~37 ~22 ~14 wool 13
fill ~36 ~22 ~15 ~37 ~22 ~15 wool 13
fill ~36 ~22 ~16 ~37 ~22 ~16 wool 13
fill ~36 ~22 ~17 ~37 ~22 ~17 wool 13
fill ~36 ~22 ~18 ~37 ~22 ~18 wool 13
fill ~36 ~22 ~19 ~37 ~22 ~19 wool 13
fill ~36 ~22 ~20 ~37 ~22 ~20 wool 13
fill ~36 ~22 ~21 ~37 ~22 ~21 wool 13
fill ~36 ~22 ~22 ~37 ~22 ~22 wool 13
fill ~36 ~22 ~23 ~37 ~22 ~23 wool 13
fill ~36 ~22 ~24 ~37 ~22 ~24 wool 13
fill ~36 ~22 ~25 ~37 ~22 ~25 wool 13
fill ~36 ~22 ~26 ~37 ~22 ~26 wool 13
fill ~36 ~22 ~27 ~37 ~22 ~27 wool 13
fill ~36 ~22 ~28 ~37 ~22 ~28 wool 13
fill ~36 ~22 ~29 ~37 ~22 ~29 wool 13
fill ~36 ~22 ~30 ~37 ~22 ~30 wool 13
fill ~36 ~22 ~31 ~37 ~22 ~31 wool 13
fill ~36 ~22 ~32 ~37 ~22 ~32 wool 13
fill ~36 ~22 ~33 ~36 ~22 ~35 snow 0
fill ~37 ~22 ~1 ~37 ~22 ~2 gold_block 0
setblock ~37 ~22 ~3 wool 15
setblock ~37 ~22 ~6 wool 14
setblock ~37 ~22 ~33 wool 14
setblock ~37 ~22 ~34 snow 0
fill ~37 ~22 ~47 ~37 ~38 ~47 wool 15
fill ~38 ~22 ~0 ~39 ~22 ~0 wool 7
setblock ~38 ~22 ~48 wool 15
fill ~38 ~22 ~50 ~39 ~22 ~50 wool 14
fill ~38 ~22 ~51 ~38 ~22 ~53 wool 14
fill ~38 ~22 ~54 ~38 ~26 ~54 wool 11
fill ~39 ~22 ~33 ~39 ~23 ~33 wool 7
fill ~39 ~22 ~35 ~39 ~24 ~35 wool 14
fill ~39 ~22 ~36 ~39 ~24 ~36 wool 14
fill ~39 ~22 ~40 ~39 ~23 ~40 wool 7
fill ~39 ~22 ~41 ~39 ~22 ~40 wool 7
fill ~39 ~22 ~42 ~39 ~26 ~42 wool 14
fill ~39 ~22 ~46 ~39 ~23 ~46 wool 7
fill ~39 ~22 ~49 ~39 ~28 ~49 wool 14
setblock ~39 ~22 ~54 wool 14
fill ~39 ~22 ~61 ~39 ~23 ~61 wool 14
fill ~8 ~23 ~0 ~9 ~23 ~0 wool 7
fill ~8 ~23 ~34 ~8 ~24 ~34 wool 14
setblock ~8 ~23 ~39 glass 0
fill ~8 ~23 ~41 ~8 ~25 ~41 wool 14
setblock ~8 ~23 ~45 glass 0
fill ~8 ~23 ~47 ~8 ~28 ~47 wool 14
fill ~8 ~23 ~48 ~8 ~28 ~48 wool 14
fill ~8 ~23 ~54 ~8 ~33 ~54 glass 0
fill ~8 ~23 ~55 ~8 ~24 ~55 wool 14
fill ~10 ~23 ~1 ~15 ~23 ~1 web 0
fill ~10 ~23 ~83 ~12 ~23 ~83 wool 7
fill ~14 ~23 ~82 ~33 ~23 ~82 wool 14
fill ~15 ~23 ~84 ~19 ~23 ~84 iron_bars 0
fill ~16 ~23 ~0 ~18 ~23 ~0 wool 7
fill ~18 ~23 ~4 ~34 ~23 ~4 wool 15
fill ~18 ~23 ~5 ~18 ~23 ~40 wool 15
fill ~18 ~23 ~46 ~34 ~23 ~46 wool 15
fill ~19 ~23 ~6 ~19 ~23 ~10 wool 15
fill ~19 ~23 ~11 ~19 ~23 ~22 wool 7
fill ~19 ~23 ~23 ~19 ~23 ~35 wool 15
fill ~19 ~23 ~43 ~20 ~23 ~43 wool 15
fill ~19 ~23 ~44 ~21 ~23 ~44 wool 15
fill ~19 ~23 ~45 ~23 ~23 ~45 wool 15
fill ~20 ~23 ~2 ~30 ~23 ~2 wool 8
fill ~20 ~23 ~3 ~36 ~23 ~3 wool 15
setblock ~20 ~23 ~5 wool 15
fill ~20 ~23 ~8 ~20 ~23 ~10 wool 7
setblock ~20 ~23 ~12 wool 7
setblock ~20 ~23 ~14 wool 7
setblock ~20 ~23 ~16 wool 7
setblock ~20 ~23 ~18 wool 7
setblock ~20 ~23 ~20 wool 7
fill ~20 ~23 ~22 ~20 ~23 ~26 wool 7
fill ~20 ~23 ~27 ~20 ~23 ~33 wool 15
fill ~20 ~23 ~84 ~20 ~24 ~84 iron_bars 15
fill ~21 ~23 ~5 ~31 ~23 ~5 wool 7
fill ~21 ~23 ~6 ~22 ~23 ~6 wool 7
fill ~21 ~23 ~7 ~21 ~23 ~5 wool 7
setblock ~21 ~23 ~9 wool 7
setblock ~21 ~23 ~11 wool 7
fill ~21 ~23 ~12 ~31 ~23 ~12 wool 8
fill ~21 ~23 ~21 ~31 ~23 ~21 wool 8
setblock ~21 ~23 ~23 wool 7
setblock ~21 ~23 ~25 wool 7
fill ~21 ~23 ~27 ~21 ~23 ~29 wool 7
fill ~21 ~23 ~30 ~34 ~23 ~30 wool 15
fill ~21 ~23 ~31 ~23 ~23 ~31 wool 15
fill ~21 ~23 ~32 ~21 ~23 ~30 wool 15
fill ~21 ~23 ~84 ~26 ~23 ~84 iron_bars 0
setblock ~22 ~23 ~8 wool 7
fill ~22 ~23 ~9 ~30 ~23 ~9 wool 8
fill ~22 ~23 ~10 ~30 ~23 ~10 wool 8
fill ~22 ~23 ~11 ~30 ~23 ~11 wool 8
setblock ~22 ~23 ~13 wool 8
fill ~22 ~23 ~14 ~30 ~23 ~14 glass 0
fill ~22 ~23 ~15 ~30 ~23 ~15 glass 0
fill ~22 ~23 ~16 ~30 ~23 ~16 glass 0
fill ~22 ~23 ~17 ~30 ~23 ~17 glass 0
fill ~22 ~23 ~18 ~30 ~23 ~18 glass 0
fill ~22 ~23 ~19 ~30 ~23 ~19 glass 0
setblock ~22 ~23 ~20 wool 8
fill ~22 ~23 ~22 ~30 ~23 ~22 wool 8
fill ~22 ~23 ~23 ~30 ~23 ~23 wool 8
fill ~22 ~23 ~24 ~30 ~23 ~24 wool 8
fill ~22 ~23 ~25 ~30 ~23 ~25 wool 8
setblock ~22 ~23 ~26 wool 7
fill ~22 ~23 ~28 ~22 ~23 ~29 wool 7
fill ~23 ~23 ~7 ~29 ~23 ~7 wool 8
fill ~23 ~23 ~8 ~29 ~23 ~8 wool 8
fill ~23 ~23 ~13 ~29 ~23 ~13 glass 0
fill ~23 ~23 ~20 ~29 ~23 ~20 glass 0
fill ~23 ~23 ~26 ~29 ~23 ~26 wool 8
fill ~23 ~23 ~27 ~29 ~23 ~27 wool 8
fill ~23 ~23 ~29 ~31 ~23 ~29 wool 7
setblock ~24 ~23 ~6 wool 7
setblock ~24 ~23 ~28 wool 7
setblock ~26 ~23 ~6 wool 7
setblock ~26 ~23 ~28 wool 7
fill ~27 ~23 ~84 ~27 ~24 ~84 iron_bars 15
setblock ~28 ~23 ~6 wool 7
setblock ~28 ~23 ~28 wool 7
fill ~28 ~23 ~84 ~32 ~23 ~84 iron_bars 0
fill ~29 ~23 ~31 ~34 ~23 ~31 wool 15
fill ~29 ~23 ~45 ~34 ~23 ~45 wool 15
setblock ~30 ~23 ~1 wool 8
fill ~30 ~23 ~6 ~31 ~23 ~6 wool 7
setblock ~30 ~23 ~8 wool 7
setblock ~30 ~23 ~13 wool 8
setblock ~30 ~23 ~20 wool 8
setblock ~30 ~23 ~26 wool 7
fill ~30 ~23 ~28 ~31 ~23 ~28 wool 7
fill ~31 ~23 ~1 ~36 ~23 ~1 gold_block 0
fill ~31 ~23 ~2 ~36 ~23 ~2 gold_block 0
setblock ~31 ~23 ~7 wool 7
fill ~31 ~23 ~9 ~32 ~23 ~9 wool 7
setblock ~31 ~23 ~11 wool 7
fill ~31 ~23 ~23 ~32 ~23 ~23 wool 7
fill ~31 ~23 ~25 ~32 ~23 ~25 wool 7
setblock ~31 ~23 ~27 wool 7
fill ~31 ~23 ~32 ~34 ~23 ~32 wool 15
fill ~31 ~23 ~44 ~34 ~23 ~44 wool 15
fill ~32 ~23 ~5 ~34 ~23 ~5 wool 15
fill ~32 ~23 ~6 ~34 ~23 ~6 wool 15
fill ~32 ~23 ~7 ~34 ~23 ~7 wool 15
setblock ~32 ~23 ~8 wool 7
setblock ~32 ~23 ~10 wool 7
fill ~32 ~23 ~12 ~33 ~23 ~12 wool 7
fill ~32 ~23 ~14 ~33 ~23 ~14 wool 7
fill ~32 ~23 ~16 ~33 ~23 ~16 wool 7
fill ~32 ~23 ~18 ~33 ~23 ~18 wool 7
fill ~32 ~23 ~20 ~33 ~23 ~20 wool 7
fill ~32 ~23 ~22 ~33 ~23 ~22 wool 7
setblock ~32 ~23 ~24 wool 7
setblock ~32 ~23 ~26 wool 7
fill ~32 ~23 ~27 ~34 ~23 ~27 wool 15
fill ~32 ~23 ~28 ~34 ~23 ~28 wool 15
fill ~32 ~23 ~29 ~34 ~23 ~29 wool 15
fill ~32 ~23 ~33 ~34 ~23 ~33 wool 15
fill ~32 ~23 ~43 ~34 ~23 ~43 wool 15
fill ~33 ~23 ~8 ~33 ~23 ~10 wool 15
setblock ~33 ~23 ~11 wool 7
setblock ~33 ~23 ~13 wool 7
setblock ~33 ~23 ~15 wool 7
setblock ~33 ~23 ~17 wool 7
setblock ~33 ~23 ~19 wool 7
setblock ~33 ~23 ~21 wool 7
fill ~33 ~23 ~23 ~33 ~23 ~35 wool 15
fill ~33 ~23 ~41 ~34 ~23 ~41 wool 15
fill ~33 ~23 ~42 ~34 ~23 ~42 wool 15
fill ~34 ~23 ~34 ~34 ~23 ~46 wool 15
fill ~35 ~23 ~83 ~38 ~23 ~83 wool 7
fill ~37 ~23 ~1 ~37 ~23 ~2 wool 8
fill ~37 ~23 ~7 ~37 ~23 ~32 wool 14
setblock ~37 ~23 ~33 snow 0
setblock ~37 ~23 ~48 wool 15
fill ~38 ~23 ~0 ~39 ~23 ~0 wool 7
setblock ~38 ~23 ~47 wool 11
fill ~38 ~23 ~53 ~38 ~27 ~53 wool 14
fill ~39 ~23 ~34 ~39 ~24 ~34 wool 14
setblock ~39 ~23 ~39 wool 7
fill ~39 ~23 ~41 ~39 ~25 ~41 wool 14
setblock ~39 ~23 ~45 wool 7
fill ~39 ~23 ~47 ~39 ~28 ~47 wool 14
fill ~39 ~23 ~48 ~39 ~28 ~48 wool 14
fill ~39 ~23 ~50 ~39 ~28 ~50 wool 14
fill ~39 ~23 ~54 ~39 ~33 ~54 wool 7
fill ~39 ~23 ~55 ~39 ~24 ~55 wool 14
fill ~7 ~24 ~82 ~7 ~29 ~82 wool 15
fill ~8 ~24 ~0 ~9 ~24 ~0 wool 7
fill ~8 ~24 ~31 ~8 ~32 ~31 glass 0
setblock ~8 ~24 ~33 wool 14
fill ~8 ~24 ~37 ~8 ~28 ~37 glass 0
fill ~8 ~24 ~38 ~8 ~24 ~37 glass 0
fill ~8 ~24 ~39 ~8 ~34 ~39 wool 14
fill ~8 ~24 ~40 ~8 ~34 ~40 wool 14
fill ~8 ~24 ~45 ~8 ~31 ~45 wool 14
fill ~8 ~24 ~46 ~8 ~28 ~46 wool 14
fill ~8 ~24 ~56 ~8 ~27 ~56 wool 14
fill ~8 ~24 ~61 ~8 ~60 ~61 glass 0
fill ~8 ~24 ~83 ~8 ~29 ~83 wool 15
fill ~9 ~24 ~84 ~12 ~24 ~84 wool 15
fill ~10 ~24 ~1 ~15 ~24 ~1 web 0
fill ~10 ~24 ~83 ~13 ~24 ~83 wool 15
fill ~12 ~24 ~85 ~17 ~24 ~85 wool 15
fill ~14 ~24 ~59 ~37 ~24 ~59 wool 15
fill ~14 ~24 ~60 ~36 ~24 ~60 stone_slab 0
fill ~14 ~24 ~79 ~36 ~24 ~79 stone_slab 0
fill ~14 ~24 ~80 ~37 ~24 ~80 wool 15
fill ~14 ~24 ~82 ~33 ~24 ~82 wool 14
fill ~15 ~24 ~84 ~19 ~24 ~84 iron_bars 0
fill ~16 ~24 ~0 ~39 ~24 ~0 wool 7
fill ~19 ~24 ~1 ~38 ~24 ~1 wool 15
fill ~21 ~24 ~84 ~26 ~24 ~84 iron_bars 0
fill ~28 ~24 ~84 ~32 ~24 ~84 iron_bars 0
fill ~30 ~24 ~85 ~35 ~24 ~85 wool 15
fill ~35 ~24 ~83 ~38 ~24 ~83 wool 7
fill ~35 ~24 ~84 ~38 ~24 ~84 wool 15
fill ~37 ~24 ~60 ~37 ~24 ~80 wool 15
setblock ~38 ~24 ~47 obsidian 0
setblock ~38 ~24 ~48 wool 15
fill ~39 ~24 ~31 ~39 ~32 ~31 wool 7
setblock ~39 ~24 ~33 wool 14
fill ~39 ~24 ~37 ~39 ~28 ~37 wool 7
fill ~39 ~24 ~38 ~39 ~24 ~37 wool 7
fill ~39 ~24 ~39 ~39 ~34 ~39 wool 14
fill ~39 ~24 ~40 ~39 ~34 ~40 wool 14
fill ~39 ~24 ~45 ~39 ~31 ~45 wool 14
fill ~39 ~24 ~46 ~39 ~28 ~46 wool 14
fill ~39 ~24 ~56 ~39 ~27 ~56 wool 14
fill ~39 ~24 ~61 ~39 ~60 ~61 wool 7
fill ~39 ~24 ~83 ~39 ~29 ~83 wool 15
fill ~40 ~24 ~82 ~40 ~29 ~82 wool 15
fill ~8 ~25 ~0 ~9 ~25 ~0 wool 7
fill ~8 ~25 ~32 ~8 ~30 ~32 glass 0
fill ~8 ~25 ~33 ~8 ~29 ~33 glass 0
fill ~8 ~25 ~34 ~8 ~30 ~34 glass 0
fill ~8 ~25 ~35 ~8 ~27 ~35 glass 0
fill ~8 ~25 ~36 ~8 ~26 ~36 glass 0
fill ~8 ~25 ~38 ~8 ~29 ~38 wool 14
fill ~8 ~25 ~51 ~8 ~27 ~51 wool 14
fill ~8 ~25 ~55 ~8 ~31 ~55 glass 0
fill ~8 ~25 ~60 ~8 ~27 ~60 glass 0
fill ~9 ~25 ~84 ~12 ~25 ~84 wool 15
fill ~10 ~25 ~1 ~15 ~25 ~1 web 0
fill ~10 ~25 ~83 ~13 ~25 ~83 wool 15
fill ~12 ~25 ~57 ~12 ~28 ~57 wool 7
fill ~12 ~25 ~58 ~12 ~28 ~58 wool 7
fill ~12 ~25 ~59 ~12 ~28 ~59 wool 7
fill ~12 ~25 ~60 ~12 ~28 ~60 wool 7
fill ~12 ~25 ~61 ~12 ~28 ~61 wool 7
fill ~12 ~25 ~62 ~12 ~28 ~62 wool 7
fill ~12 ~25 ~63 ~12 ~28 ~63 wool 7
fill ~12 ~25 ~64 ~12 ~28 ~64 wool 7
fill ~12 ~25 ~65 ~12 ~28 ~65 wool 7
fill ~12 ~25 ~66 ~12 ~28 ~66 wool 7
fill ~12 ~25 ~67 ~12 ~28 ~67 wool 7
fill ~12 ~25 ~68 ~12 ~28 ~68 wool 7
fill ~12 ~25 ~69 ~12 ~28 ~69 wool 7
fill ~12 ~25 ~70 ~12 ~28 ~70 wool 7
fill ~12 ~25 ~71 ~12 ~28 ~71 wool 7
fill ~12 ~25 ~72 ~12 ~28 ~72 wool 7
fill ~12 ~25 ~73 ~12 ~28 ~73 wool 7
fill ~12 ~25 ~74 ~12 ~28 ~74 wool 7
fill ~12 ~25 ~75 ~12 ~28 ~75 wool 7
fill ~12 ~25 ~76 ~12 ~28 ~76 wool 7
fill ~12 ~25 ~77 ~12 ~28 ~77 wool 7
fill ~12 ~25 ~78 ~12 ~28 ~78 wool 7
fill ~12 ~25 ~79 ~12 ~28 ~79 wool 7
fill ~12 ~25 ~85 ~17 ~25 ~85 wool 15
fill ~14 ~25 ~59 ~14 ~28 ~59 wool 8
fill ~14 ~25 ~60 ~15 ~25 ~60 wool 15
fill ~14 ~25 ~61 ~14 ~27 ~61 wool 15
fill ~14 ~25 ~62 ~36 ~25 ~62 wool 13
fill ~14 ~25 ~63 ~36 ~25 ~63 wool 13
fill ~14 ~25 ~64 ~36 ~25 ~64 wool 13
fill ~14 ~25 ~65 ~36 ~25 ~65 wool 13
fill ~14 ~25 ~66 ~36 ~25 ~66 wool 13
fill ~14 ~25 ~67 ~36 ~25 ~67 wool 13
fill ~14 ~25 ~68 ~36 ~25 ~68 wool 13
fill ~14 ~25 ~69 ~36 ~25 ~69 wool 13
fill ~14 ~25 ~70 ~36 ~25 ~70 wool 13
fill ~14 ~25 ~71 ~36 ~25 ~71 wool 13
fill ~14 ~25 ~72 ~36 ~25 ~72 wool 13
fill ~14 ~25 ~73 ~36 ~25 ~73 wool 13
fill ~14 ~25 ~74 ~36 ~25 ~74 wool 13
fill ~14 ~25 ~75 ~36 ~25 ~75 wool 13
fill ~14 ~25 ~76 ~36 ~25 ~76 wool 13
fill ~14 ~25 ~77 ~36 ~25 ~77 wool 13
fill ~14 ~25 ~78 ~14 ~27 ~78 wool 15
fill ~14 ~25 ~79 ~15 ~25 ~79 wool 15
fill ~14 ~25 ~80 ~14 ~28 ~80 wool 8
fill ~14 ~25 ~82 ~33 ~25 ~82 wool 14
fill ~15 ~25 ~61 ~35 ~25 ~61 wool 13
fill ~15 ~25 ~78 ~35 ~25 ~78 wool 13
fill ~15 ~25 ~84 ~18 ~25 ~84 iron_bars 0
fill ~16 ~25 ~0 ~18 ~25 ~0 wool 7
fill ~16 ~25 ~60 ~34 ~25 ~60 wool 13
fill ~16 ~25 ~79 ~34 ~25 ~79 wool 13
fill ~18 ~25 ~4 ~34 ~25 ~4 wool 15
fill ~18 ~25 ~5 ~34 ~25 ~5 wool 15
fill ~18 ~25 ~6 ~34 ~25 ~6 wool 15
fill ~18 ~25 ~7 ~34 ~25 ~7 wool 15
fill ~18 ~25 ~8 ~34 ~25 ~8 wool 15
fill ~18 ~25 ~9 ~34 ~25 ~9 wool 15
fill ~18 ~25 ~10 ~34 ~25 ~10 wool 15
fill ~18 ~25 ~11 ~34 ~25 ~11 wool 15
fill ~18 ~25 ~12 ~34 ~25 ~12 wool 15
fill ~18 ~25 ~13 ~34 ~25 ~13 wool 15
fill ~18 ~25 ~14 ~34 ~25 ~14 wool 15
fill ~18 ~25 ~15 ~34 ~25 ~15 wool 15
fill ~18 ~25 ~16 ~34 ~25 ~16 wool 15
fill ~18 ~25 ~17 ~34 ~25 ~17 wool 15
fill ~18 ~25 ~18 ~34 ~25 ~18 wool 15
fill ~18 ~25 ~19 ~34 ~25 ~19 wool 15
fill ~18 ~25 ~20 ~34 ~25 ~20 wool 15
fill ~18 ~25 ~21 ~34 ~25 ~21 wool 15
fill ~18 ~25 ~22 ~34 ~25 ~22 wool 15
fill ~18 ~25 ~23 ~34 ~25 ~23 wool 15
fill ~18 ~25 ~24 ~34 ~25 ~24 wool 15
fill ~18 ~25 ~25 ~34 ~25 ~25 wool 15
fill ~18 ~25 ~26 ~34 ~25 ~26 wool 15
fill ~18 ~25 ~27 ~34 ~25 ~27 wool 15
fill ~18 ~25 ~28 ~34 ~25 ~28 wool 15
fill ~18 ~25 ~29 ~34 ~25 ~29 wool 15
fill ~18 ~25 ~30 ~34 ~25 ~30 wool 15
fill ~18 ~25 ~31 ~34 ~25 ~31 wool 15
fill ~18 ~25 ~32 ~34 ~25 ~32 wool 15
fill ~18 ~25 ~33 ~34 ~25 ~33 wool 15
fill ~18 ~25 ~34 ~34 ~25 ~34 wool 15
fill ~18 ~25 ~35 ~34 ~25 ~35 wool 15
fill ~18 ~25 ~36 ~34 ~25 ~36 wool 15
