fill ~43 ~0 ~45 ~57 ~0 ~45 concrete 15
setblock ~43 ~0 ~46 coal_block
fill ~43 ~0 ~47 ~61 ~0 ~47 concrete 15
setblock ~43 ~0 ~48 coal_block
setblock ~44 ~0 ~44 concrete 15
setblock ~44 ~0 ~46 concrete 15
fill ~44 ~0 ~48 ~44 ~0 ~49 concrete 15
fill ~45 ~0 ~43 ~59 ~0 ~43 concrete 15
setblock ~45 ~0 ~44 coal_block
setblock ~45 ~0 ~46 coal_block
setblock ~45 ~0 ~48 coal_block
fill ~45 ~0 ~49 ~61 ~0 ~49 concrete 15
setblock ~45 ~0 ~50 coal_block
fill ~45 ~0 ~51 ~61 ~0 ~51 concrete 15
fill ~46 ~0 ~44 ~48 ~0 ~44 concrete 15
setblock ~46 ~0 ~46 concrete 15
fill ~46 ~0 ~48 ~48 ~0 ~48 concrete 15
setblock ~46 ~0 ~50 concrete 15
setblock ~47 ~0 ~46 coal_block
setblock ~47 ~0 ~50 coal_block
fill ~47 ~0 ~52 ~48 ~0 ~52 concrete 15
setblock ~48 ~0 ~46 concrete 15
setblock ~48 ~0 ~50 concrete 15
fill ~48 ~0 ~53 ~60 ~0 ~53 concrete 15
setblock ~49 ~0 ~42 coal_block
setblock ~49 ~0 ~44 coal_block
setblock ~49 ~0 ~46 coal_block
setblock ~49 ~0 ~48 coal_block
setblock ~49 ~0 ~50 coal_block
setblock ~49 ~0 ~52 coal_block
fill ~50 ~0 ~42 ~52 ~0 ~42 concrete 15
fill ~50 ~0 ~44 ~52 ~0 ~44 concrete 15
setblock ~50 ~0 ~46 concrete 15
fill ~50 ~0 ~48 ~52 ~0 ~48 concrete 15
setblock ~50 ~0 ~50 concrete 15
fill ~50 ~0 ~52 ~52 ~0 ~52 concrete 15
setblock ~51 ~0 ~46 coal_block
setblock ~51 ~0 ~50 coal_block
setblock ~52 ~0 ~46 concrete 15
setblock ~52 ~0 ~50 concrete 15
setblock ~52 ~0 ~54 concrete 15
fill ~53 ~0 ~41 ~57 ~0 ~41 concrete 15
setblock ~53 ~0 ~42 coal_block
setblock ~53 ~0 ~44 coal_block
setblock ~53 ~0 ~46 coal_block
setblock ~53 ~0 ~48 coal_block
setblock ~53 ~0 ~50 coal_block
setblock ~53 ~0 ~52 coal_block
setblock ~53 ~0 ~54 coal_block
fill ~54 ~0 ~42 ~58 ~0 ~42 concrete 15
fill ~54 ~0 ~44 ~56 ~0 ~44 concrete 15
setblock ~54 ~0 ~46 concrete 15
fill ~54 ~0 ~48 ~58 ~0 ~48 concrete 15
setblock ~54 ~0 ~50 concrete 15
fill ~54 ~0 ~52 ~56 ~0 ~52 concrete 15
setblock ~54 ~0 ~54 concrete 15
setblock ~55 ~0 ~46 coal_block
setblock ~55 ~0 ~50 coal_block
setblock ~55 ~0 ~54 coal_block
setblock ~56 ~0 ~46 concrete 15
setblock ~56 ~0 ~50 concrete 15
setblock ~56 ~0 ~54 concrete 15
setblock ~57 ~0 ~44 coal_block
setblock ~57 ~0 ~46 coal_block
setblock ~57 ~0 ~50 coal_block
setblock ~57 ~0 ~52 stained_hardened_clay 7
setblock ~57 ~0 ~54 wool 15
setblock ~58 ~0 ~44 concrete 15
setblock ~58 ~0 ~45 stone 4
setblock ~58 ~0 ~46 concrete 15
setblock ~58 ~0 ~50 concrete 15
setblock ~58 ~0 ~52 concrete 15
setblock ~59 ~0 ~42 stained_hardened_clay 7
setblock ~59 ~0 ~44 wool 8
setblock ~59 ~0 ~45 stained_hardened_clay 9
setblock ~59 ~0 ~46 coal_block
setblock ~59 ~0 ~48 coal_block
setblock ~59 ~0 ~50 coal_block
setblock ~59 ~0 ~52 coal_block
setblock ~60 ~0 ~42 clay
setblock ~60 ~0 ~43 stone 3
setblock ~60 ~0 ~44 nether_brick
fill ~60 ~0 ~45 ~61 ~0 ~45 concrete 15
fill ~60 ~0 ~46 ~60 ~0 ~45 concrete 15
fill ~60 ~0 ~48 ~61 ~0 ~48 concrete 15
setblock ~60 ~0 ~50 concrete 15
fill ~60 ~0 ~52 ~62 ~0 ~52 concrete 15
setblock ~61 ~0 ~42 snow
setblock ~61 ~0 ~43 concrete 15
fill ~61 ~0 ~44 ~62 ~0 ~44 coal_block
setblock ~61 ~0 ~46 coal_block
setblock ~61 ~0 ~50 coal_block
setblock ~62 ~0 ~43 clay
setblock ~62 ~0 ~45 concrete
setblock ~62 ~0 ~46 wool 8
setblock ~62 ~0 ~47 wool 15
setblock ~62 ~0 ~48 concrete 7
fill ~62 ~0 ~49 ~62 ~0 ~50 concrete
setblock ~62 ~0 ~51 cobblestone
setblock ~63 ~0 ~43 stained_hardened_clay 7
setblock ~63 ~0 ~44 wool 15
fill ~63 ~0 ~45 ~65 ~0 ~45 concrete 15
setblock ~63 ~0 ~46 coal_block
setblock ~63 ~0 ~47 concrete 15
setblock ~63 ~0 ~48 coal_block
setblock ~63 ~0 ~49 iron_block
fill ~63 ~0 ~50 ~63 ~0 ~51 wool 15
fill ~64 ~0 ~44 ~65 ~0 ~44 concrete 15
setblock ~64 ~0 ~46 concrete 15
setblock ~64 ~0 ~47 wool 7
fill ~64 ~0 ~48 ~64 ~0 ~50 concrete 15
setblock ~65 ~0 ~46 stone 4
fill ~65 ~0 ~47 ~65 ~0 ~48 coal_block
setblock ~65 ~0 ~49 concrete 15
setblock ~66 ~0 ~45 double_stone_slab 8
fill ~66 ~0 ~46 ~66 ~0 ~47 concrete 15
setblock ~32 ~1 ~43 concrete 15
setblock ~32 ~1 ~44 coal_block
setblock ~32 ~1 ~45 concrete 15
fill ~33 ~1 ~41 ~52 ~1 ~41 concrete 15
setblock ~33 ~1 ~42 wool 15
setblock ~33 ~1 ~43 coal_block
setblock ~33 ~1 ~44 wool 15
setblock ~33 ~1 ~45 coal_block
fill ~33 ~1 ~46 ~35 ~1 ~46 wool 15
setblock ~33 ~1 ~47 coal_block
setblock ~33 ~1 ~48 wool 15
fill ~34 ~1 ~40 ~57 ~1 ~40 concrete 15
fill ~34 ~1 ~42 ~35 ~1 ~42 coal_block
fill ~34 ~1 ~43 ~44 ~1 ~43 concrete 15
setblock ~34 ~1 ~44 coal_block
setblock ~34 ~1 ~45 concrete 15
fill ~34 ~1 ~47 ~36 ~1 ~47 concrete 15
setblock ~34 ~1 ~48 coal_block
fill ~34 ~1 ~49 ~43 ~1 ~49 concrete 15
fill ~34 ~1 ~50 ~34 ~1 ~49 concrete 15
fill ~35 ~1 ~39 ~57 ~1 ~39 concrete 15
setblock ~35 ~1 ~44 wool 15
setblock ~35 ~1 ~45 coal_block
setblock ~35 ~1 ~48 wool 15
setblock ~35 ~1 ~50 coal_block
fill ~35 ~1 ~51 ~44 ~1 ~51 concrete 15
fill ~35 ~1 ~52 ~46 ~1 ~52 concrete 15
setblock ~36 ~1 ~42 concrete 15
setblock ~36 ~1 ~44 coal_block
setblock ~36 ~1 ~45 concrete 15
setblock ~36 ~1 ~46 coal_block
setblock ~36 ~1 ~48 coal_block
setblock ~36 ~1 ~50 concrete 15
fill ~36 ~1 ~53 ~47 ~1 ~53 concrete 15
fill ~37 ~1 ~38 ~62 ~1 ~38 concrete 15
setblock ~37 ~1 ~42 coal_block
setblock ~37 ~1 ~44 wool 15
setblock ~37 ~1 ~45 coal_block
setblock ~37 ~1 ~46 wool 15
setblock ~37 ~1 ~47 coal_block
setblock ~37 ~1 ~48 wool 15
setblock ~37 ~1 ~50 coal_block
fill ~37 ~1 ~54 ~51 ~1 ~54 concrete 15
fill ~38 ~1 ~42 ~48 ~1 ~42 concrete 15
fill ~38 ~1 ~44 ~38 ~1 ~45 concrete 15
setblock ~38 ~1 ~46 coal_block
fill ~38 ~1 ~47 ~42 ~1 ~47 concrete 15
setblock ~38 ~1 ~48 coal_block
setblock ~38 ~1 ~50 concrete 15
fill ~38 ~1 ~55 ~71 ~1 ~55 concrete 15
setblock ~39 ~1 ~44 wool 15
fill ~39 ~1 ~45 ~42 ~1 ~45 concrete 15
setblock ~39 ~1 ~46 wool 15
setblock ~39 ~1 ~48 wool 15
setblock ~39 ~1 ~50 coal_block
fill ~39 ~1 ~56 ~56 ~1 ~56 concrete 15
fill ~40 ~1 ~44 ~43 ~1 ~44 concrete 15
setblock ~40 ~1 ~46 concrete 15
fill ~40 ~1 ~48 ~42 ~1 ~48 concrete 15
fill ~40 ~1 ~50 ~44 ~1 ~50 concrete 15
fill ~40 ~1 ~57 ~69 ~1 ~57 concrete 15
fill ~41 ~1 ~37 ~42 ~1 ~37 concrete 15
setblock ~41 ~1 ~46 coal_block
setblock ~42 ~1 ~46 concrete 15
fill ~42 ~1 ~58 ~56 ~1 ~58 concrete 15
setblock ~43 ~1 ~37 bedrock
fill ~43 ~1 ~59 ~56 ~1 ~59 concrete 15
setblock ~44 ~1 ~37 concrete 15
fill ~44 ~1 ~60 ~56 ~1 ~60 concrete 15
setblock ~45 ~1 ~36 wool 15
setblock ~45 ~1 ~37 stonebrick 2
fill ~46 ~1 ~36 ~60 ~1 ~36 concrete 15
fill ~46 ~1 ~37 ~62 ~1 ~37 concrete 15
fill ~46 ~1 ~61 ~64 ~1 ~61 concrete 15
fill ~48 ~1 ~62 ~62 ~1 ~62 concrete 15
fill ~50 ~1 ~63 ~60 ~1 ~63 concrete 15
fill ~51 ~1 ~35 ~54 ~1 ~35 concrete 15
fill ~54 ~1 ~64 ~57 ~1 ~64 concrete 15
setblock ~55 ~1 ~35 stained_hardened_clay 9
setblock ~56 ~1 ~35 concrete 7
setblock ~57 ~1 ~35 concrete 15
setblock ~57 ~1 ~56 coal_block
setblock ~57 ~1 ~58 stained_hardened_clay 7
setblock ~57 ~1 ~59 wool 7
setblock ~57 ~1 ~60 wool 15
setblock ~58 ~1 ~35 bedrock
setblock ~58 ~1 ~39 wool 15
setblock ~58 ~1 ~40 stone 3
setblock ~58 ~1 ~41 double_stone_slab 8
fill ~58 ~1 ~54 ~72 ~1 ~54 concrete 15
fill ~58 ~1 ~56 ~70 ~1 ~56 concrete 15
fill ~58 ~1 ~58 ~68 ~1 ~58 concrete 15
fill ~58 ~1 ~59 ~67 ~1 ~59 concrete 15
fill ~58 ~1 ~60 ~66 ~1 ~60 concrete 15
setblock ~59 ~1 ~35 concrete
setblock ~59 ~1 ~39 concrete 15
setblock ~59 ~1 ~40 stonebrick 2
setblock ~59 ~1 ~41 stone 4
setblock ~60 ~1 ~35 stone 3
setblock ~60 ~1 ~39 coal_ore
fill ~60 ~1 ~40 ~61 ~1 ~40 concrete 15
setblock ~60 ~1 ~41 concrete 7
setblock ~61 ~1 ~36 concrete 7
setblock ~61 ~1 ~39 concrete 15
fill ~61 ~1 ~41 ~62 ~1 ~41 concrete 15
fill ~61 ~1 ~53 ~73 ~1 ~53 concrete 15
setblock ~62 ~1 ~36 stained_hardened_clay 9
setblock ~62 ~1 ~39 stonebrick 3
setblock ~62 ~1 ~40 concrete
fill ~62 ~1 ~42 ~63 ~1 ~42 wool 7
setblock ~63 ~1 ~36 snow
setblock ~63 ~1 ~37 concrete
setblock ~63 ~1 ~38 coal_ore
setblock ~63 ~1 ~39 wool
fill ~63 ~1 ~40 ~63 ~1 ~42 wool 7
fill ~63 ~1 ~52 ~74 ~1 ~52 concrete 15
setblock ~64 ~1 ~36 wool 15
fill ~64 ~1 ~37 ~65 ~1 ~37 concrete 15
fill ~64 ~1 ~38 ~66 ~1 ~38 concrete 15
fill ~64 ~1 ~39 ~70 ~1 ~39 concrete 15
setblock ~64 ~1 ~40 double_stone_slab 8
fill ~64 ~1 ~41 ~64 ~1 ~42 concrete 15
setblock ~64 ~1 ~43 quartz_block
fill ~64 ~1 ~51 ~74 ~1 ~51 concrete 15
setblock ~65 ~1 ~36 concrete 15
setblock ~65 ~1 ~40 snow
setblock ~65 ~1 ~41 bedrock
fill ~65 ~1 ~42 ~70 ~1 ~42 concrete 15
fill ~65 ~1 ~43 ~69 ~1 ~43 concrete 15
fill ~65 ~1 ~50 ~75 ~1 ~50 concrete 15
setblock ~66 ~1 ~37 concrete
fill ~66 ~1 ~40 ~71 ~1 ~40 concrete 15
fill ~66 ~1 ~41 ~74 ~1 ~41 concrete 15
setblock ~66 ~1 ~44 concrete 15
fill ~66 ~1 ~48 ~76 ~1 ~48 concrete 15
fill ~66 ~1 ~49 ~75 ~1 ~49 concrete 15
fill ~67 ~1 ~37 ~68 ~1 ~37 wool 15
setblock ~67 ~1 ~38 stained_hardened_clay 7
setblock ~67 ~1 ~44 stained_hardened_clay 9
setblock ~67 ~1 ~45 iron_block
fill ~67 ~1 ~46 ~76 ~1 ~46 concrete 15
fill ~67 ~1 ~47 ~76 ~1 ~47 concrete 15
setblock ~68 ~1 ~38 concrete
setblock ~68 ~1 ~44 quartz_block
fill ~68 ~1 ~45 ~76 ~1 ~45 concrete 15
setblock ~69 ~1 ~37 concrete 15
setblock ~69 ~1 ~38 concrete 7
setblock ~69 ~1 ~44 coal_block
fill ~70 ~1 ~38 ~72 ~1 ~38 concrete 15
setblock ~70 ~1 ~43 stone 5
fill ~70 ~1 ~44 ~76 ~1 ~44 concrete 15
setblock ~71 ~1 ~39 concrete 7
fill ~71 ~1 ~42 ~72 ~1 ~42 concrete 7
fill ~71 ~1 ~43 ~76 ~1 ~43 concrete 15
fill ~72 ~1 ~39 ~73 ~1 ~39 concrete 15
setblock ~72 ~1 ~40 concrete 7
setblock ~73 ~1 ~40 quartz_block
setblock ~73 ~1 ~42 stone 4
fill ~74 ~1 ~40 ~75 ~1 ~40 concrete 15
setblock ~74 ~1 ~42 double_stone_slab 8
setblock ~75 ~1 ~41 snow
setblock ~75 ~1 ~42 concrete
fill ~76 ~1 ~41 ~76 ~1 ~48 concrete 15
setblock ~25 ~2 ~39 concrete 15
setblock ~25 ~2 ~40 wool 15
setblock ~25 ~2 ~41 concrete 15
setblock ~25 ~2 ~42 wool 15
setblock ~25 ~2 ~43 concrete 15
setblock ~25 ~2 ~44 wool 15
fill ~25 ~2 ~45 ~25 ~2 ~46 coal_block
setblock ~26 ~2 ~38 concrete 15
setblock ~26 ~2 ~39 wool 15
setblock ~26 ~2 ~40 concrete 15
setblock ~26 ~2 ~41 wool 15
setblock ~26 ~2 ~42 concrete 15
fill ~26 ~2 ~43 ~29 ~2 ~43 wool 15
setblock ~26 ~2 ~44 concrete 15
setblock ~26 ~2 ~45 wool 15
setblock ~26 ~2 ~46 concrete 15
setblock ~26 ~2 ~47 coal_block
setblock ~26 ~2 ~48 concrete 15
setblock ~27 ~2 ~37 concrete 15
setblock ~27 ~2 ~38 wool 15
setblock ~27 ~2 ~39 coal_block
setblock ~27 ~2 ~40 wool 15
setblock ~27 ~2 ~41 coal_block
setblock ~27 ~2 ~42 wool 15
setblock ~27 ~2 ~44 nether_brick
setblock ~27 ~2 ~45 coal_block
setblock ~27 ~2 ~46 wool 15
setblock ~27 ~2 ~47 concrete 15
setblock ~27 ~2 ~48 wool 15
setblock ~27 ~2 ~49 concrete 15
setblock ~28 ~2 ~36 concrete 15
setblock ~28 ~2 ~37 wool 15
setblock ~28 ~2 ~38 concrete 15
setblock ~28 ~2 ~39 wool 15
setblock ~28 ~2 ~40 concrete 15
fill ~28 ~2 ~41 ~29 ~2 ~41 wool 15
setblock ~28 ~2 ~42 concrete 15
setblock ~28 ~2 ~44 concrete 15
fill ~28 ~2 ~45 ~31 ~2 ~45 wool 15
setblock ~28 ~2 ~46 concrete 15
setblock ~28 ~2 ~47 wool 15
setblock ~28 ~2 ~48 concrete 15
setblock ~28 ~2 ~49 coal_block
setblock ~28 ~2 ~50 concrete 15
setblock ~28 ~2 ~51 coal_block
setblock ~29 ~2 ~36 wool 15
setblock ~29 ~2 ~37 coal_block
setblock ~29 ~2 ~38 wool 15
setblock ~29 ~2 ~39 coal_block
setblock ~29 ~2 ~40 nether_brick
setblock ~29 ~2 ~42 stained_hardened_clay 7
setblock ~29 ~2 ~44 nether_brick
setblock ~29 ~2 ~46 nether_brick
setblock ~29 ~2 ~47 coal_block
setblock ~29 ~2 ~48 wool 15
setblock ~29 ~2 ~49 concrete 15
setblock ~29 ~2 ~50 wool 15
setblock ~29 ~2 ~51 concrete 15
setblock ~29 ~2 ~52 coal_block
setblock ~30 ~2 ~35 coal_block
setblock ~30 ~2 ~36 concrete 15
setblock ~30 ~2 ~37 wool 15
setblock ~30 ~2 ~38 concrete 15
setblock ~30 ~2 ~39 wool 15
setblock ~30 ~2 ~40 concrete 15
setblock ~30 ~2 ~41 nether_brick
setblock ~30 ~2 ~42 coal_block
setblock ~30 ~2 ~43 nether_brick
setblock ~30 ~2 ~44 coal_block
setblock ~30 ~2 ~46 coal_block
fill ~30 ~2 ~47 ~32 ~2 ~47 wool 15
setblock ~30 ~2 ~48 concrete 15
setblock ~30 ~2 ~49 wool 15
setblock ~30 ~2 ~50 concrete 15
setblock ~30 ~2 ~51 coal_block
setblock ~30 ~2 ~52 concrete 15
setblock ~30 ~2 ~53 coal_block
setblock ~30 ~2 ~54 concrete 15
setblock ~31 ~2 ~35 concrete 15
setblock ~31 ~2 ~36 coal_block
setblock ~31 ~2 ~37 concrete 15
setblock ~31 ~2 ~38 wool 15
setblock ~31 ~2 ~39 coal_block
setblock ~31 ~2 ~40 nether_brick
fill ~31 ~2 ~41 ~32 ~2 ~41 wool 15
setblock ~31 ~2 ~42 stained_hardened_clay 7
setblock ~31 ~2 ~43 wool 15
setblock ~31 ~2 ~44 stained_hardened_clay 7
setblock ~31 ~2 ~46 nether_brick
setblock ~31 ~2 ~48 wool 15
setblock ~31 ~2 ~49 concrete 15
setblock ~31 ~2 ~50 wool 15
setblock ~31 ~2 ~51 concrete 15
setblock ~31 ~2 ~52 wool 15
setblock ~31 ~2 ~53 concrete 15
setblock ~31 ~2 ~54 coal_block
setblock ~31 ~2 ~55 concrete 15
setblock ~32 ~2 ~34 concrete 15
setblock ~32 ~2 ~35 coal_block
setblock ~32 ~2 ~36 concrete 15
setblock ~32 ~2 ~37 coal_block
setblock ~32 ~2 ~38 concrete 15
setblock ~32 ~2 ~39 wool 15
setblock ~32 ~2 ~40 concrete 15
setblock ~32 ~2 ~42 coal_block
setblock ~32 ~2 ~46 coal_block
setblock ~32 ~2 ~48 concrete 15
setblock ~32 ~2 ~49 wool 15
setblock ~32 ~2 ~50 concrete 15
setblock ~32 ~2 ~51 wool 15
setblock ~32 ~2 ~52 concrete 15
setblock ~32 ~2 ~53 coal_block
setblock ~32 ~2 ~54 concrete 15
setblock ~32 ~2 ~55 coal_block
setblock ~32 ~2 ~56 concrete 15
setblock ~33 ~2 ~34 coal_block
fill ~33 ~2 ~35 ~41 ~2 ~35 concrete 15
setblock ~33 ~2 ~36 coal_block
setblock ~33 ~2 ~37 concrete 15
setblock ~33 ~2 ~38 wool 15
setblock ~33 ~2 ~39 coal_block
setblock ~33 ~2 ~40 wool 15
setblock ~33 ~2 ~49 coal_block
setblock ~33 ~2 ~50 wool 15
setblock ~33 ~2 ~51 concrete 15
setblock ~33 ~2 ~52 wool 15
setblock ~33 ~2 ~53 concrete 15
setblock ~33 ~2 ~54 wool 15
setblock ~33 ~2 ~55 concrete 15
setblock ~33 ~2 ~56 coal_block
setblock ~33 ~2 ~57 concrete 15
setblock ~33 ~2 ~58 wool 15
setblock ~34 ~2 ~34 concrete 15
setblock ~34 ~2 ~36 concrete 15
setblock ~34 ~2 ~37 coal_block
setblock ~34 ~2 ~38 concrete 15
setblock ~34 ~2 ~39 wool 15
setblock ~34 ~2 ~51 coal_block
setblock ~34 ~2 ~52 concrete 15
setblock ~34 ~2 ~53 coal_block
setblock ~34 ~2 ~54 concrete 15
setblock ~34 ~2 ~55 coal_block
setblock ~34 ~2 ~56 concrete 15
setblock ~34 ~2 ~57 coal_block
setblock ~34 ~2 ~58 concrete 15
setblock ~34 ~2 ~59 coal_block
fill ~35 ~2 ~33 ~42 ~2 ~33 concrete 15
setblock ~35 ~2 ~34 coal_block
setblock ~35 ~2 ~36 coal_block
fill ~35 ~2 ~37 ~40 ~2 ~37 concrete 15
setblock ~35 ~2 ~38 coal_block
setblock ~35 ~2 ~53 concrete 15
setblock ~35 ~2 ~54 coal_block
fill ~35 ~2 ~55 ~37 ~2 ~55 concrete 15
setblock ~35 ~2 ~56 coal_block
fill ~35 ~2 ~57 ~39 ~2 ~57 concrete 15
setblock ~35 ~2 ~58 coal_block
fill ~35 ~2 ~59 ~42 ~2 ~59 concrete 15
setblock ~35 ~2 ~60 coal_block
setblock ~36 ~2 ~34 concrete 15
setblock ~36 ~2 ~36 concrete 15
setblock ~36 ~2 ~38 concrete 15
setblock ~36 ~2 ~54 concrete 15
setblock ~36 ~2 ~56 concrete 15
setblock ~36 ~2 ~58 concrete 15
fill ~36 ~2 ~60 ~36 ~2 ~61 concrete 15
setblock ~37 ~2 ~34 coal_block
setblock ~37 ~2 ~36 coal_block
setblock ~37 ~2 ~56 coal_block
setblock ~37 ~2 ~58 coal_block
setblock ~37 ~2 ~60 coal_block
fill ~37 ~2 ~61 ~45 ~2 ~61 concrete 15
setblock ~37 ~2 ~62 coal_block
setblock ~38 ~2 ~34 concrete 15
fill ~38 ~2 ~36 ~40 ~2 ~36 concrete 15
setblock ~38 ~2 ~56 concrete 15
fill ~38 ~2 ~58 ~40 ~2 ~58 concrete 15
setblock ~38 ~2 ~60 concrete 15
fill ~38 ~2 ~62 ~40 ~2 ~62 concrete 15
fill ~38 ~2 ~63 ~49 ~2 ~63 concrete 15
setblock ~39 ~2 ~34 coal_block
setblock ~39 ~2 ~60 coal_block
setblock ~39 ~2 ~64 coal_block
setblock ~40 ~2 ~32 concrete 15
setblock ~40 ~2 ~34 concrete 15
setblock ~40 ~2 ~60 concrete 15
fill ~40 ~2 ~64 ~40 ~2 ~65 concrete 15
setblock ~41 ~2 ~32 coal_block
setblock ~41 ~2 ~34 coal_block
setblock ~41 ~2 ~36 coal_block
setblock ~41 ~2 ~58 coal_block
setblock ~41 ~2 ~60 coal_block
setblock ~41 ~2 ~62 coal_block
setblock ~41 ~2 ~64 coal_block
fill ~41 ~2 ~65 ~70 ~2 ~65 concrete 15
setblock ~41 ~2 ~66 coal_block
setblock ~42 ~2 ~32 concrete 15
setblock ~42 ~2 ~34 concrete 15
setblock ~42 ~2 ~35 stone
setblock ~42 ~2 ~36 concrete 15
setblock ~42 ~2 ~60 concrete 15
fill ~42 ~2 ~62 ~44 ~2 ~62 concrete 15
setblock ~42 ~2 ~64 concrete 15
fill ~42 ~2 ~66 ~44 ~2 ~66 concrete 15
setblock ~43 ~2 ~32 snow
setblock ~43 ~2 ~33 concrete 7
setblock ~43 ~2 ~34 coal_block
setblock ~43 ~2 ~35 wool 7
setblock ~43 ~2 ~36 coal_block
setblock ~43 ~2 ~60 coal_block
setblock ~43 ~2 ~64 coal_block
fill ~43 ~2 ~67 ~68 ~2 ~67 concrete 15
fill ~44 ~2 ~32 ~45 ~2 ~32 coal_block
setblock ~44 ~2 ~33 wool 7
setblock ~44 ~2 ~34 bedrock
setblock ~44 ~2 ~35 double_stone_slab 8
setblock ~44 ~2 ~36 stained_hardened_clay 7
setblock ~44 ~2 ~64 concrete 15
setblock ~44 ~2 ~68 concrete 15
fill ~45 ~2 ~33 ~47 ~2 ~33 snow
setblock ~45 ~2 ~34 coal_block
setblock ~45 ~2 ~35 wool 15
setblock ~45 ~2 ~62 coal_block
setblock ~45 ~2 ~64 coal_block
setblock ~45 ~2 ~66 coal_block
setblock ~45 ~2 ~68 coal_block
setblock ~46 ~2 ~32 concrete 15
fill ~46 ~2 ~34 ~46 ~2 ~35 concrete 15
fill ~46 ~2 ~62 ~47 ~2 ~62 concrete 15
setblock ~46 ~2 ~64 concrete 15
fill ~46 ~2 ~66 ~48 ~2 ~66 concrete 15
setblock ~46 ~2 ~68 concrete 15
setblock ~46 ~2 ~69 coal_block
setblock ~47 ~2 ~32 wool 15
setblock ~47 ~2 ~34 coal_block
fill ~47 ~2 ~35 ~50 ~2 ~35 concrete 15
setblock ~47 ~2 ~64 coal_block
setblock ~47 ~2 ~68 coal_block
fill ~47 ~2 ~69 ~57 ~2 ~69 concrete 15
fill ~48 ~2 ~31 ~55 ~2 ~31 concrete 15
fill ~48 ~2 ~32 ~48 ~2 ~31 concrete 15
setblock ~48 ~2 ~33 concrete 7
setblock ~48 ~2 ~34 nether_brick
setblock ~48 ~2 ~64 concrete 15
setblock ~48 ~2 ~68 concrete 15
setblock ~48 ~2 ~70 concrete 15
setblock ~49 ~2 ~32 coal_block
setblock ~49 ~2 ~33 stained_hardened_clay 9
setblock ~49 ~2 ~34 stained_hardened_clay 7
setblock ~49 ~2 ~64 coal_block
setblock ~49 ~2 ~66 coal_block
setblock ~49 ~2 ~68 coal_block
setblock ~49 ~2 ~70 coal_block
fill ~50 ~2 ~32 ~52 ~2 ~32 concrete 15
setblock ~50 ~2 ~33 wool 15
setblock ~50 ~2 ~34 wool 7
setblock ~50 ~2 ~64 concrete 15
fill ~50 ~2 ~66 ~52 ~2 ~66 concrete 15
setblock ~50 ~2 ~68 concrete 15
fill ~50 ~2 ~70 ~52 ~2 ~70 concrete 15
fill ~51 ~2 ~33 ~55 ~2 ~33 concrete 15
setblock ~51 ~2 ~34 snow
setblock ~51 ~2 ~64 coal_block
setblock ~51 ~2 ~68 coal_block
fill ~51 ~2 ~71 ~60 ~2 ~71 concrete 15
setblock ~52 ~2 ~34 clay
setblock ~52 ~2 ~64 concrete 15
setblock ~52 ~2 ~68 concrete 15
setblock ~53 ~2 ~32 coal_block
setblock ~53 ~2 ~34 wool
setblock ~53 ~2 ~64 coal_block
setblock ~53 ~2 ~66 coal_block
setblock ~53 ~2 ~68 coal_block
setblock ~53 ~2 ~70 coal_block
setblock ~54 ~2 ~30 concrete 15
fill ~54 ~2 ~32 ~55 ~2 ~32 concrete 15
setblock ~54 ~2 ~34 bedrock
fill ~54 ~2 ~66 ~58 ~2 ~66 concrete 15
setblock ~54 ~2 ~68 concrete 15
fill ~54 ~2 ~70 ~58 ~2 ~70 concrete 15
setblock ~55 ~2 ~30 coal_block
setblock ~55 ~2 ~34 wool 7
setblock ~55 ~2 ~68 coal_block
setblock ~56 ~2 ~30 concrete 15
setblock ~56 ~2 ~31 coal_block
setblock ~56 ~2 ~32 stained_hardened_clay 7
setblock ~56 ~2 ~33 coal_block
setblock ~56 ~2 ~34 concrete 15
setblock ~56 ~2 ~68 concrete 15
setblock ~57 ~2 ~30 coal_block
fill ~57 ~2 ~31 ~63 ~2 ~31 concrete 15
fill ~57 ~2 ~32 ~58 ~2 ~32 concrete 15
fill ~57 ~2 ~33 ~62 ~2 ~33 concrete 15
setblock ~57 ~2 ~34 wool 7
setblock ~57 ~2 ~68 coal_block
setblock ~58 ~2 ~30 concrete 15
setblock ~58 ~2 ~34 concrete 15
setblock ~58 ~2 ~64 concrete 15
setblock ~58 ~2 ~68 concrete 15
setblock ~58 ~2 ~69 coal_block
setblock ~59 ~2 ~32 coal_block
setblock ~59 ~2 ~34 coal_block
setblock ~59 ~2 ~64 coal_block
setblock ~59 ~2 ~66 coal_block
setblock ~59 ~2 ~68 coal_block
fill ~59 ~2 ~69 ~65 ~2 ~69 concrete 15
setblock ~59 ~2 ~70 coal_block
fill ~60 ~2 ~32 ~62 ~2 ~32 concrete 15
setblock ~60 ~2 ~34 concrete 15
setblock ~60 ~2 ~64 concrete 15
fill ~60 ~2 ~66 ~62 ~2 ~66 concrete 15
setblock ~60 ~2 ~68 concrete 15
fill ~60 ~2 ~70 ~62 ~2 ~70 concrete 15
setblock ~61 ~2 ~34 coal_block
setblock ~61 ~2 ~35 double_stone_slab 8
fill ~61 ~2 ~63 ~72 ~2 ~63 concrete 15
setblock ~61 ~2 ~64 coal_block
setblock ~61 ~2 ~68 coal_block
fill ~62 ~2 ~34 ~62 ~2 ~35 concrete 15
setblock ~62 ~2 ~64 concrete 15
setblock ~62 ~2 ~68 concrete 15
setblock ~63 ~2 ~32 wool 15
fill ~63 ~2 ~33 ~63 ~2 ~34 concrete
setblock ~63 ~2 ~35 concrete 15
setblock ~63 ~2 ~62 coal_block
setblock ~63 ~2 ~64 coal_block
setblock ~63 ~2 ~66 coal_block
setblock ~63 ~2 ~68 coal_block
setblock ~63 ~2 ~70 coal_block
setblock ~64 ~2 ~32 concrete 7
fill ~64 ~2 ~33 ~74 ~2 ~33 concrete 15
fill ~64 ~2 ~34 ~64 ~2 ~33 concrete 15
setblock ~64 ~2 ~35 coal_block
fill ~64 ~2 ~62 ~66 ~2 ~62 concrete 15
setblock ~64 ~2 ~64 concrete 15
fill ~64 ~2 ~66 ~66 ~2 ~66 concrete 15
setblock ~64 ~2 ~68 concrete 15
fill ~65 ~2 ~32 ~66 ~2 ~32 concrete 15
setblock ~65 ~2 ~34 coal_block
fill ~65 ~2 ~35 ~79 ~2 ~35 concrete 15
fill ~65 ~2 ~61 ~73 ~2 ~61 concrete 15
setblock ~65 ~2 ~64 coal_block
setblock ~65 ~2 ~68 coal_block
setblock ~66 ~2 ~34 concrete 15
setblock ~66 ~2 ~36 concrete 15
setblock ~66 ~2 ~64 concrete 15
setblock ~66 ~2 ~68 concrete 15
setblock ~67 ~2 ~32 coal_block
setblock ~67 ~2 ~34 coal_block
setblock ~67 ~2 ~36 coal_block
setblock ~67 ~2 ~60 coal_block
setblock ~67 ~2 ~62 coal_block
setblock ~67 ~2 ~64 coal_block
setblock ~67 ~2 ~66 coal_block
fill ~68 ~2 ~32 ~69 ~2 ~32 concrete 15
setblock ~68 ~2 ~34 concrete 15
fill ~68 ~2 ~36 ~70 ~2 ~36 concrete 15
fill ~68 ~2 ~59 ~75 ~2 ~59 concrete 15
fill ~68 ~2 ~60 ~68 ~2 ~59 concrete 15
fill ~68 ~2 ~62 ~70 ~2 ~62 concrete 15
setblock ~68 ~2 ~64 concrete 15
fill ~68 ~2 ~66 ~69 ~2 ~66 concrete 15
setblock ~69 ~2 ~34 coal_block
fill ~69 ~2 ~58 ~70 ~2 ~58 concrete 15
setblock ~69 ~2 ~60 coal_block
setblock ~69 ~2 ~64 coal_block
setblock ~70 ~2 ~34 concrete 15
fill ~70 ~2 ~37 ~81 ~2 ~37 concrete 15
fill ~70 ~2 ~57 ~77 ~2 ~57 concrete 15
setblock ~70 ~2 ~60 concrete 15
setblock ~70 ~2 ~64 concrete 15
setblock ~71 ~2 ~34 coal_block
setblock ~71 ~2 ~36 coal_block
setblock ~71 ~2 ~56 coal_block
setblock ~71 ~2 ~58 coal_block
setblock ~71 ~2 ~60 coal_block
setblock ~71 ~2 ~62 coal_block
setblock ~71 ~2 ~64 coal_block
setblock ~72 ~2 ~34 concrete 15
fill ~72 ~2 ~36 ~74 ~2 ~36 concrete 15
fill ~72 ~2 ~55 ~77 ~2 ~55 concrete 15
fill ~72 ~2 ~56 ~72 ~2 ~55 concrete 15
fill ~72 ~2 ~58 ~74 ~2 ~58 concrete 15
setblock ~72 ~2 ~60 concrete 15
fill ~72 ~2 ~62 ~73 ~2 ~62 concrete 15
setblock ~73 ~2 ~34 coal_block
setblock ~73 ~2 ~38 coal_block
fill ~73 ~2 ~54 ~74 ~2 ~54 concrete 15
setblock ~73 ~2 ~56 coal_block
setblock ~73 ~2 ~60 coal_block
setblock ~74 ~2 ~34 concrete 15
fill ~74 ~2 ~38 ~74 ~2 ~39 concrete 15
fill ~74 ~2 ~53 ~79 ~2 ~53 concrete 15
setblock ~74 ~2 ~56 concrete 15
setblock ~74 ~2 ~60 concrete 15
setblock ~75 ~2 ~34 coal_block
setblock ~75 ~2 ~36 coal_block
setblock ~75 ~2 ~38 coal_block
fill ~75 ~2 ~39 ~79 ~2 ~39 concrete 15
fill ~75 ~2 ~51 ~80 ~2 ~51 concrete 15
setblock ~75 ~2 ~52 coal_block
setblock ~75 ~2 ~54 coal_block
setblock ~75 ~2 ~56 coal_block
setblock ~75 ~2 ~58 coal_block
setblock ~76 ~2 ~34 concrete 15
fill ~76 ~2 ~36 ~78 ~2 ~36 concrete 15
setblock ~76 ~2 ~38 concrete 15
fill ~76 ~2 ~40 ~78 ~2 ~40 concrete 15
fill ~76 ~2 ~49 ~81 ~2 ~49 concrete 15
fill ~76 ~2 ~50 ~78 ~2 ~50 concrete 15
setblock ~76 ~2 ~52 concrete 15
fill ~76 ~2 ~54 ~78 ~2 ~54 concrete 15
setblock ~76 ~2 ~56 concrete 15
setblock ~76 ~2 ~58 concrete 15
setblock ~77 ~2 ~34 coal_block
setblock ~77 ~2 ~38 coal_block
fill ~77 ~2 ~41 ~81 ~2 ~41 concrete 15
setblock ~77 ~2 ~42 coal_block
fill ~77 ~2 ~43 ~81 ~2 ~43 concrete 15
setblock ~77 ~2 ~44 coal_block
fill ~77 ~2 ~45 ~81 ~2 ~45 concrete 15
fill ~77 ~2 ~46 ~78 ~2 ~46 concrete 15
fill ~77 ~2 ~47 ~79 ~2 ~47 concrete 15
setblock ~77 ~2 ~48 coal_block
setblock ~77 ~2 ~52 coal_block
setblock ~77 ~2 ~56 coal_block
setblock ~78 ~2 ~38 concrete 15
setblock ~78 ~2 ~42 concrete 15
setblock ~78 ~2 ~44 concrete 15
setblock ~78 ~2 ~48 concrete 15
setblock ~78 ~2 ~52 concrete 15
setblock ~78 ~2 ~55 coal_block
setblock ~79 ~2 ~36 coal_block
setblock ~79 ~2 ~38 coal_block
setblock ~79 ~2 ~40 coal_block
setblock ~79 ~2 ~42 coal_block
setblock ~79 ~2 ~44 coal_block
setblock ~79 ~2 ~46 coal_block
setblock ~79 ~2 ~48 coal_block
setblock ~79 ~2 ~50 coal_block
setblock ~79 ~2 ~52 coal_block
setblock ~79 ~2 ~54 coal_block
setblock ~80 ~2 ~36 concrete 15
setblock ~80 ~2 ~38 concrete 15
setblock ~80 ~2 ~39 coal_block
setblock ~80 ~2 ~40 concrete 15
setblock ~80 ~2 ~42 concrete 15
setblock ~80 ~2 ~44 concrete 15
setblock ~80 ~2 ~46 concrete 15
setblock ~80 ~2 ~47 coal_block
setblock ~80 ~2 ~48 concrete 15
setblock ~80 ~2 ~50 concrete 15
setblock ~80 ~2 ~52 concrete 15
setblock ~81 ~2 ~36 wool 15
setblock ~81 ~2 ~38 wool 15
setblock ~81 ~2 ~39 concrete 15
setblock ~81 ~2 ~40 coal_block
setblock ~81 ~2 ~42 coal_block
setblock ~81 ~2 ~44 coal_block
setblock ~81 ~2 ~46 coal_block
setblock ~81 ~2 ~47 concrete 15
setblock ~81 ~2 ~48 coal_block
setblock ~81 ~2 ~50 coal_block
setblock ~82 ~2 ~38 concrete 15
setblock ~82 ~2 ~39 wool 15
setblock ~82 ~2 ~40 concrete 15
setblock ~82 ~2 ~41 wool 15
setblock ~82 ~2 ~42 concrete 15
setblock ~82 ~2 ~43 coal_block
setblock ~82 ~2 ~44 concrete 15
setblock ~82 ~2 ~45 coal_block
setblock ~82 ~2 ~46 concrete 15
setblock ~82 ~2 ~47 coal_block
setblock ~82 ~2 ~48 concrete 15
setblock ~83 ~2 ~39 coal_block
setblock ~83 ~2 ~40 wool 15
setblock ~83 ~2 ~41 coal_block
setblock ~83 ~2 ~42 wool 15
setblock ~83 ~2 ~43 concrete 15
setblock ~83 ~2 ~44 wool 15
setblock ~83 ~2 ~45 concrete 15
fill ~17 ~3 ~41 ~24 ~3 ~41 concrete 15
setblock ~17 ~3 ~42 coal_block
fill ~18 ~3 ~38 ~18 ~3 ~43 concrete 15
fill ~18 ~3 ~44 ~18 ~3 ~45 coal_block
fill ~19 ~3 ~37 ~26 ~3 ~37 concrete 15
setblock ~19 ~3 ~38 coal_block
fill ~19 ~3 ~39 ~24 ~3 ~39 concrete 15
fill ~19 ~3 ~40 ~24 ~3 ~40 concrete 15
setblock ~19 ~3 ~42 coal_block
fill ~19 ~3 ~43 ~24 ~3 ~43 concrete 15
fill ~19 ~3 ~44 ~24 ~3 ~44 concrete 15
fill ~19 ~3 ~45 ~24 ~3 ~45 concrete 15
setblock ~19 ~3 ~46 wool 15
setblock ~20 ~3 ~36 concrete 15
setblock ~20 ~3 ~38 concrete 15
fill ~20 ~3 ~42 ~22 ~3 ~42 concrete 15
fill ~20 ~3 ~46 ~24 ~3 ~46 concrete 15
fill ~20 ~3 ~47 ~25 ~3 ~47 concrete 15
setblock ~20 ~3 ~48 coal_block
fill ~21 ~3 ~35 ~29 ~3 ~35 concrete 15
setblock ~21 ~3 ~36 coal_block
setblock ~21 ~3 ~38 coal_block
fill ~21 ~3 ~48 ~25 ~3 ~48 concrete 15
fill ~21 ~3 ~49 ~26 ~3 ~49 concrete 15
setblock ~22 ~3 ~34 concrete 15
fill ~22 ~3 ~36 ~24 ~3 ~36 concrete 15
setblock ~22 ~3 ~38 concrete 15
fill ~22 ~3 ~50 ~27 ~3 ~50 concrete 15
fill ~22 ~3 ~51 ~27 ~3 ~51 concrete 15
fill ~23 ~3 ~33 ~34 ~3 ~33 concrete 15
setblock ~23 ~3 ~34 coal_block
setblock ~23 ~3 ~38 coal_block
setblock ~23 ~3 ~42 coal_block
fill ~23 ~3 ~52 ~28 ~3 ~52 concrete 15
fill ~24 ~3 ~34 ~26 ~3 ~34 concrete 15
setblock ~24 ~3 ~38 concrete 15
setblock ~24 ~3 ~42 concrete 15
fill ~24 ~3 ~53 ~29 ~3 ~53 concrete 15
setblock ~25 ~3 ~32 coal_block
setblock ~25 ~3 ~36 coal_block
setblock ~25 ~3 ~38 coal_block
fill ~25 ~3 ~54 ~28 ~3 ~54 concrete 15
fill ~25 ~3 ~55 ~30 ~3 ~55 concrete 15
fill ~26 ~3 ~32 ~39 ~3 ~32 concrete 15
fill ~26 ~3 ~36 ~27 ~3 ~36 concrete 15
fill ~26 ~3 ~56 ~30 ~3 ~56 concrete 15
fill ~27 ~3 ~31 ~47 ~3 ~31 concrete 15
setblock ~27 ~3 ~34 coal_block
fill ~27 ~3 ~57 ~32 ~3 ~57 concrete 15
fill ~28 ~3 ~34 ~31 ~3 ~34 concrete 15
fill ~28 ~3 ~58 ~32 ~3 ~58 concrete 15
fill ~28 ~3 ~59 ~33 ~3 ~59 concrete 15
setblock ~29 ~3 ~54 coal_block
setblock ~29 ~3 ~60 coal_block
setblock ~30 ~3 ~30 concrete 15
fill ~30 ~3 ~60 ~30 ~3 ~62 concrete 15
setblock ~31 ~3 ~30 coal_block
setblock ~31 ~3 ~56 coal_block
setblock ~31 ~3 ~60 coal_block
fill ~31 ~3 ~61 ~35 ~3 ~61 concrete 15
setblock ~31 ~3 ~62 coal_block
setblock ~31 ~3 ~63 stained_hardened_clay 15
fill ~32 ~3 ~30 ~34 ~3 ~30 concrete 15
setblock ~32 ~3 ~60 concrete 15
fill ~32 ~3 ~62 ~32 ~3 ~63 concrete 15
setblock ~32 ~3 ~64 wool 15
setblock ~33 ~3 ~60 coal_block
setblock ~33 ~3 ~62 coal_block
fill ~33 ~3 ~63 ~37 ~3 ~63 concrete 15
setblock ~33 ~3 ~64 coal_block
setblock ~33 ~3 ~65 nether_brick
setblock ~34 ~3 ~60 concrete 15
setblock ~34 ~3 ~62 concrete 15
setblock ~34 ~3 ~64 concrete 15
setblock ~34 ~3 ~65 coal_block
fill ~34 ~3 ~66 ~35 ~3 ~66 soul_sand
setblock ~34 ~3 ~67 stained_hardened_clay 7
fill ~35 ~3 ~29 ~63 ~3 ~29 concrete 15
setblock ~35 ~3 ~30 coal_block
setblock ~35 ~3 ~62 coal_block
setblock ~35 ~3 ~64 coal_block
fill ~35 ~3 ~65 ~39 ~3 ~65 concrete 15
setblock ~35 ~3 ~67 stained_hardened_clay 12
setblock ~35 ~3 ~68 soul_sand
fill ~36 ~3 ~30 ~53 ~3 ~30 concrete 15
setblock ~36 ~3 ~62 concrete 15
setblock ~36 ~3 ~64 concrete 15
setblock ~36 ~3 ~66 nether_brick
fill ~36 ~3 ~67 ~37 ~3 ~67 stained_hardened_clay 7
setblock ~36 ~3 ~68 stained_hardened_clay 12
setblock ~36 ~3 ~69 stained_hardened_clay 7
setblock ~37 ~3 ~64 coal_block
setblock ~37 ~3 ~66 wool 15
setblock ~37 ~3 ~68 soul_sand
setblock ~37 ~3 ~69 stained_hardened_clay 12
setblock ~37 ~3 ~70 soul_sand
setblock ~38 ~3 ~64 concrete 15
fill ~38 ~3 ~66 ~40 ~3 ~66 concrete 15
fill ~38 ~3 ~67 ~40 ~3 ~67 coal_block
fill ~38 ~3 ~68 ~38 ~3 ~69 stained_hardened_clay 7
setblock ~38 ~3 ~70 concrete 7
fill ~38 ~3 ~71 ~39 ~3 ~71 stained_hardened_clay 7
fill ~38 ~3 ~72 ~38 ~3 ~71 stained_hardened_clay 7
setblock ~39 ~3 ~68 concrete 7
setblock ~39 ~3 ~69 stained_hardened_clay 7
setblock ~39 ~3 ~70 soul_sand
setblock ~39 ~3 ~72 concrete 7
fill ~40 ~3 ~68 ~40 ~3 ~69 stained_hardened_clay 15
fill ~40 ~3 ~70 ~41 ~3 ~70 stained_hardened_clay 7
fill ~40 ~3 ~71 ~41 ~3 ~71 nether_brick
fill ~40 ~3 ~72 ~41 ~3 ~72 stained_hardened_clay 7
setblock ~40 ~3 ~73 stained_hardened_clay 15
fill ~41 ~3 ~67 ~42 ~3 ~67 concrete 15
setblock ~41 ~3 ~68 stained_hardened_clay 7
setblock ~41 ~3 ~69 nether_brick
setblock ~41 ~3 ~73 nether_brick
setblock ~41 ~3 ~74 stained_hardened_clay 7
fill ~42 ~3 ~68 ~43 ~3 ~68 concrete 15
setblock ~42 ~3 ~69 coal_block
fill ~42 ~3 ~70 ~43 ~3 ~70 nether_brick
setblock ~42 ~3 ~71 coal_block
setblock ~42 ~3 ~72 stained_hardened_clay 15
fill ~42 ~3 ~73 ~43 ~3 ~73 coal_block
fill ~42 ~3 ~74 ~43 ~3 ~74 stained_hardened_clay 15
setblock ~42 ~3 ~75 concrete 15
fill ~43 ~3 ~28 ~63 ~3 ~28 concrete 15
fill ~43 ~3 ~69 ~45 ~3 ~69 concrete 15
setblock ~43 ~3 ~71 stained_hardened_clay 15
setblock ~43 ~3 ~72 nether_brick
setblock ~43 ~3 ~75 coal_block
fill ~44 ~3 ~70 ~45 ~3 ~70 coal_block
fill ~44 ~3 ~71 ~44 ~3 ~70 coal_block
fill ~44 ~3 ~72 ~45 ~3 ~72 stained_hardened_clay 15
setblock ~44 ~3 ~73 concrete 15
setblock ~44 ~3 ~74 coal_block
fill ~44 ~3 ~75 ~66 ~3 ~75 concrete 15
fill ~44 ~3 ~76 ~45 ~3 ~76 coal_block
fill ~45 ~3 ~71 ~50 ~3 ~71 concrete 15
setblock ~45 ~3 ~73 coal_block
setblock ~45 ~3 ~74 wool 15
fill ~46 ~3 ~70 ~47 ~3 ~70 concrete 15
fill ~46 ~3 ~72 ~46 ~3 ~73 concrete 15
fill ~46 ~3 ~74 ~47 ~3 ~74 coal_block
setblock ~46 ~3 ~76 concrete 15
setblock ~47 ~3 ~72 coal_block
fill ~47 ~3 ~73 ~70 ~3 ~73 concrete 15
setblock ~47 ~3 ~76 coal_block
fill ~48 ~3 ~72 ~68 ~3 ~72 concrete 15
fill ~48 ~3 ~74 ~68 ~3 ~74 concrete 15
fill ~48 ~3 ~76 ~63 ~3 ~76 concrete 15
fill ~48 ~3 ~77 ~58 ~3 ~77 concrete 15
fill ~51 ~3 ~27 ~61 ~3 ~27 concrete 15
fill ~59 ~3 ~30 ~80 ~3 ~30 concrete 15
fill ~61 ~3 ~71 ~70 ~3 ~71 concrete 15
setblock ~64 ~3 ~28 stone 5
setblock ~64 ~3 ~29 bedrock
fill ~64 ~3 ~31 ~83 ~3 ~31 concrete 15
fill ~64 ~3 ~70 ~66 ~3 ~70 concrete 15
fill ~65 ~3 ~28 ~69 ~3 ~28 concrete 15
fill ~65 ~3 ~29 ~77 ~3 ~29 concrete 15
fill ~66 ~3 ~69 ~70 ~3 ~69 concrete 15
fill ~67 ~3 ~68 ~70 ~3 ~68 concrete 15
setblock ~67 ~3 ~70 coal_block
setblock ~68 ~3 ~70 concrete 15
fill ~69 ~3 ~67 ~72 ~3 ~67 concrete 15
fill ~69 ~3 ~70 ~70 ~3 ~70 coal_block
fill ~69 ~3 ~72 ~70 ~3 ~72 coal_block
fill ~70 ~3 ~32 ~85 ~3 ~32 concrete 15
fill ~70 ~3 ~66 ~74 ~3 ~66 concrete 15
fill ~71 ~3 ~65 ~76 ~3 ~65 concrete 15
fill ~71 ~3 ~68 ~72 ~3 ~68 coal_block
fill ~71 ~3 ~69 ~72 ~3 ~69 coal_block
fill ~71 ~3 ~70 ~72 ~3 ~70 stained_hardened_clay 15
fill ~71 ~3 ~71 ~72 ~3 ~71 coal_block
setblock ~71 ~3 ~72 stained_hardened_clay 15
fill ~72 ~3 ~64 ~78 ~3 ~64 concrete 15
fill ~73 ~3 ~63 ~76 ~3 ~63 concrete 15
setblock ~73 ~3 ~67 coal_block
fill ~73 ~3 ~68 ~75 ~3 ~68 stained_hardened_clay 7
fill ~73 ~3 ~69 ~74 ~3 ~69 stained_hardened_clay 15
setblock ~73 ~3 ~70 nether_brick
fill ~74 ~3 ~61 ~80 ~3 ~61 concrete 15
fill ~74 ~3 ~62 ~78 ~3 ~62 concrete 15
setblock ~74 ~3 ~67 concrete 15
fill ~75 ~3 ~33 ~86 ~3 ~33 concrete 15
fill ~75 ~3 ~60 ~78 ~3 ~60 concrete 15
setblock ~75 ~3 ~66 wool 15
fill ~75 ~3 ~67 ~76 ~3 ~67 nether_brick
fill ~76 ~3 ~59 ~81 ~3 ~59 concrete 15
setblock ~76 ~3 ~66 stained_hardened_clay 7
fill ~77 ~3 ~58 ~78 ~3 ~58 concrete 15
setblock ~77 ~3 ~63 coal_block
setblock ~77 ~3 ~65 coal_block
fill ~78 ~3 ~34 ~80 ~3 ~34 concrete 15
fill ~78 ~3 ~56 ~83 ~3 ~56 concrete 15
fill ~78 ~3 ~57 ~82 ~3 ~57 concrete 15
setblock ~78 ~3 ~63 concrete 15
fill ~79 ~3 ~55 ~83 ~3 ~55 concrete 15
setblock ~79 ~3 ~58 coal_block
setblock ~79 ~3 ~60 coal_block
setblock ~79 ~3 ~62 coal_block
fill ~80 ~3 ~35 ~88 ~3 ~35 concrete 15
fill ~80 ~3 ~53 ~84 ~3 ~53 concrete 15
fill ~80 ~3 ~54 ~84 ~3 ~54 concrete 15
fill ~80 ~3 ~58 ~81 ~3 ~58 concrete 15
setblock ~80 ~3 ~60 concrete 15
setblock ~81 ~3 ~34 coal_block
fill ~81 ~3 ~51 ~85 ~3 ~51 concrete 15
fill ~81 ~3 ~52 ~85 ~3 ~52 concrete 15
setblock ~82 ~3 ~34 concrete 15
fill ~82 ~3 ~36 ~82 ~3 ~37 concrete 15
fill ~82 ~3 ~49 ~86 ~3 ~49 concrete 15
fill ~82 ~3 ~50 ~86 ~3 ~50 concrete 15
setblock ~83 ~3 ~34 coal_block
setblock ~83 ~3 ~36 wool 15
fill ~83 ~3 ~37 ~89 ~3 ~37 concrete 15
fill ~83 ~3 ~38 ~85 ~3 ~38 wool 15
setblock ~83 ~3 ~46 coal_block
fill ~83 ~3 ~47 ~87 ~3 ~47 concrete 15
fill ~83 ~3 ~48 ~87 ~3 ~48 concrete 15
setblock ~84 ~3 ~34 concrete 15
setblock ~84 ~3 ~36 concrete 15
setblock ~84 ~3 ~39 concrete 15
fill ~84 ~3 ~40 ~87 ~3 ~40 coal_block
fill ~84 ~3 ~41 ~89 ~3 ~41 concrete 15
fill ~84 ~3 ~42 ~84 ~3 ~54 concrete 15
setblock ~85 ~3 ~34 coal_block
setblock ~85 ~3 ~36 wool 15
setblock ~85 ~3 ~39 coal_block
setblock ~85 ~3 ~42 coal_block
fill ~85 ~3 ~43 ~89 ~3 ~43 concrete 15
setblock ~85 ~3 ~44 coal_block
fill ~85 ~3 ~45 ~88 ~3 ~45 concrete 15
fill ~85 ~3 ~46 ~88 ~3 ~46 concrete 15
setblock ~86 ~3 ~34 concrete 15
fill ~86 ~3 ~36 ~88 ~3 ~36 concrete 15
fill ~86 ~3 ~38 ~86 ~3 ~39 concrete 15
fill ~86 ~3 ~42 ~89 ~3 ~42 concrete 15
fill ~86 ~3 ~44 ~89 ~3 ~44 concrete 15
setblock ~87 ~3 ~34 coal_block
setblock ~87 ~3 ~38 coal_block
fill ~87 ~3 ~39 ~89 ~3 ~39 concrete 15
fill ~88 ~3 ~38 ~89 ~3 ~38 concrete 15
fill ~88 ~3 ~40 ~89 ~3 ~40 concrete 15
setblock ~9 ~4 ~40 wool 15
setblock ~10 ~4 ~36 concrete 15
setblock ~10 ~4 ~37 coal_block
setblock ~10 ~4 ~38 concrete 15
setblock ~10 ~4 ~39 coal_block
setblock ~10 ~4 ~40 concrete 15
setblock ~10 ~4 ~41 nether_brick
setblock ~10 ~4 ~42 coal_block
setblock ~10 ~4 ~43 stained_hardened_clay 7
setblock ~10 ~4 ~44 stained_hardened_clay 15
fill ~11 ~4 ~35 ~12 ~4 ~35 coal_block
setblock ~11 ~4 ~36 wool 15
setblock ~11 ~4 ~37 concrete 15
setblock ~11 ~4 ~38 coal_block
setblock ~11 ~4 ~39 concrete 15
setblock ~11 ~4 ~40 stained_hardened_clay 15
setblock ~11 ~4 ~41 coal_block
setblock ~11 ~4 ~42 nether_brick
setblock ~11 ~4 ~43 stained_hardened_clay 15
setblock ~11 ~4 ~44 concrete 7
setblock ~11 ~4 ~45 stained_hardened_clay 7
setblock ~11 ~4 ~46 concrete 7
setblock ~12 ~4 ~36 concrete 15
setblock ~12 ~4 ~37 coal_block
setblock ~12 ~4 ~38 concrete 15
setblock ~12 ~4 ~39 coal_block
setblock ~12 ~4 ~40 concrete 15
setblock ~12 ~4 ~41 wool 15
setblock ~12 ~4 ~42 coal_block
setblock ~12 ~4 ~43 stained_hardened_clay 7
setblock ~12 ~4 ~44 wool 15
setblock ~12 ~4 ~45 concrete 7
setblock ~12 ~4 ~46 nether_brick
setblock ~12 ~4 ~47 concrete 7
setblock ~13 ~4 ~34 coal_block
setblock ~13 ~4 ~35 concrete 15
setblock ~13 ~4 ~36 wool 15
setblock ~13 ~4 ~37 concrete 15
setblock ~13 ~4 ~38 wool 15
setblock ~13 ~4 ~39 concrete 15
setblock ~13 ~4 ~40 stained_hardened_clay 15
setblock ~13 ~4 ~41 coal_block
setblock ~13 ~4 ~42 nether_brick
setblock ~13 ~4 ~43 stained_hardened_clay 15
fill ~13 ~4 ~44 ~13 ~4 ~45 stained_hardened_clay 7
setblock ~13 ~4 ~46 concrete 7
setblock ~13 ~4 ~47 stained_hardened_clay 7
setblock ~13 ~4 ~48 wool 7
setblock ~13 ~4 ~49 concrete 7
setblock ~14 ~4 ~34 concrete 15
setblock ~14 ~4 ~35 coal_block
setblock ~14 ~4 ~36 concrete 15
setblock ~14 ~4 ~37 coal_block
setblock ~14 ~4 ~38 concrete 15
setblock ~14 ~4 ~39 coal_block
setblock ~14 ~4 ~40 concrete 15
setblock ~14 ~4 ~41 stained_hardened_clay 15
setblock ~14 ~4 ~42 coal_block
setblock ~14 ~4 ~43 stained_hardened_clay 7
setblock ~14 ~4 ~44 coal_block
fill ~14 ~4 ~45 ~16 ~4 ~45 stained_hardened_clay 7
setblock ~14 ~4 ~46 nether_brick
setblock ~14 ~4 ~47 concrete 7
setblock ~14 ~4 ~48 stained_hardened_clay 7
fill ~14 ~4 ~49 ~16 ~4 ~49 soul_sand
setblock ~14 ~4 ~50 stained_hardened_clay 7
setblock ~15 ~4 ~33 concrete 15
setblock ~15 ~4 ~34 coal_block
fill ~15 ~4 ~35 ~16 ~4 ~35 concrete 15
setblock ~15 ~4 ~36 wool 15
fill ~15 ~4 ~37 ~17 ~4 ~37 concrete 15
setblock ~15 ~4 ~38 coal_block
setblock ~15 ~4 ~39 concrete 15
setblock ~15 ~4 ~40 wool 15
setblock ~15 ~4 ~41 coal_block
setblock ~15 ~4 ~42 nether_brick
fill ~15 ~4 ~43 ~16 ~4 ~43 stained_hardened_clay 15
setblock ~15 ~4 ~44 stained_hardened_clay 7
setblock ~15 ~4 ~46 concrete 7
fill ~15 ~4 ~47 ~18 ~4 ~47 stained_hardened_clay 7
setblock ~15 ~4 ~48 soul_sand
fill ~15 ~4 ~50 ~15 ~4 ~51 soul_sand
setblock ~16 ~4 ~33 coal_block
setblock ~16 ~4 ~34 concrete 15
setblock ~16 ~4 ~36 concrete 15
setblock ~16 ~4 ~38 concrete 15
setblock ~16 ~4 ~39 coal_block
setblock ~16 ~4 ~40 concrete 15
setblock ~16 ~4 ~41 wool 15
setblock ~16 ~4 ~42 concrete 15
setblock ~16 ~4 ~44 coal_block
setblock ~16 ~4 ~46 stained_hardened_clay 15
setblock ~16 ~4 ~48 stained_hardened_clay 7
setblock ~16 ~4 ~50 stained_hardened_clay 7
fill ~16 ~4 ~51 ~20 ~4 ~51 soul_sand
setblock ~16 ~4 ~52 stained_hardened_clay 12
setblock ~17 ~4 ~32 coal_block
setblock ~17 ~4 ~33 concrete 15
setblock ~17 ~4 ~34 wool 15
setblock ~17 ~4 ~35 coal_block
setblock ~17 ~4 ~36 wool 15
setblock ~17 ~4 ~38 coal_block
setblock ~17 ~4 ~39 concrete 15
setblock ~17 ~4 ~40 coal_block
setblock ~17 ~4 ~43 coal_block
setblock ~17 ~4 ~44 nether_brick
setblock ~17 ~4 ~45 stained_hardened_clay 15
setblock ~17 ~4 ~46 stained_hardened_clay 7
setblock ~17 ~4 ~48 soul_sand
setblock ~17 ~4 ~49 concrete 7
setblock ~17 ~4 ~50 bedrock
setblock ~17 ~4 ~52 bedrock
setblock ~17 ~4 ~53 soul_sand
setblock ~18 ~4 ~32 concrete 15
setblock ~18 ~4 ~33 wool 15
setblock ~18 ~4 ~34 concrete 15
setblock ~18 ~4 ~35 wool 15
setblock ~18 ~4 ~36 concrete 15
setblock ~18 ~4 ~37 coal_block
setblock ~18 ~4 ~46 coal_block
setblock ~18 ~4 ~48 nether_brick
setblock ~18 ~4 ~49 soul_sand
setblock ~18 ~4 ~50 stained_hardened_clay 7
setblock ~18 ~4 ~52 stained_hardened_clay 7
setblock ~18 ~4 ~53 bedrock
setblock ~18 ~4 ~54 soul_sand
setblock ~19 ~4 ~31 concrete 15
setblock ~19 ~4 ~32 wool 15
setblock ~19 ~4 ~33 coal_block
setblock ~19 ~4 ~34 wool 15
setblock ~19 ~4 ~35 coal_block
setblock ~19 ~4 ~36 wool 15
setblock ~19 ~4 ~47 coal_block
fill ~19 ~4 ~48 ~19 ~4 ~49 stained_hardened_clay 7
setblock ~19 ~4 ~50 soul_sand
fill ~19 ~4 ~52 ~19 ~4 ~53 soul_sand
setblock ~19 ~4 ~54 bedrock
setblock ~19 ~4 ~55 soul_sand
setblock ~20 ~4 ~31 wool 15
setblock ~20 ~4 ~32 concrete 15
setblock ~20 ~4 ~33 wool 15
setblock ~20 ~4 ~34 concrete 15
setblock ~20 ~4 ~35 wool 15
fill ~20 ~4 ~49 ~20 ~4 ~50 nether_brick
setblock ~20 ~4 ~52 stained_hardened_clay 7
fill ~20 ~4 ~53 ~22 ~4 ~53 soul_sand
fill ~20 ~4 ~54 ~20 ~4 ~53 soul_sand
setblock ~20 ~4 ~55 bedrock
setblock ~20 ~4 ~56 stained_hardened_clay 12
setblock ~21 ~4 ~30 wool 15
setblock ~21 ~4 ~31 coal_block
setblock ~21 ~4 ~32 wool 15
setblock ~21 ~4 ~33 coal_block
setblock ~21 ~4 ~34 wool 15
fill ~21 ~4 ~50 ~21 ~4 ~51 nether_brick
setblock ~21 ~4 ~52 soul_sand
setblock ~21 ~4 ~54 bedrock
fill ~21 ~4 ~55 ~23 ~4 ~55 soul_sand
setblock ~21 ~4 ~56 bedrock
setblock ~21 ~4 ~57 soul_sand
setblock ~22 ~4 ~30 concrete 15
setblock ~22 ~4 ~31 wool 15
setblock ~22 ~4 ~32 concrete 15
setblock ~22 ~4 ~33 wool 15
setblock ~22 ~4 ~52 nether_brick
setblock ~22 ~4 ~54 stained_hardened_clay 7
setblock ~22 ~4 ~56 stained_hardened_clay 7
setblock ~22 ~4 ~57 bedrock
setblock ~22 ~4 ~58 soul_sand
setblock ~23 ~4 ~29 coal_block
setblock ~23 ~4 ~30 wool 15
setblock ~23 ~4 ~31 coal_block
setblock ~23 ~4 ~32 wool 15
setblock ~23 ~4 ~53 concrete 15
setblock ~23 ~4 ~54 soul_sand
fill ~23 ~4 ~56 ~23 ~4 ~57 soul_sand
setblock ~23 ~4 ~58 bedrock
fill ~23 ~4 ~59 ~26 ~4 ~59 soul_sand
setblock ~24 ~4 ~29 wool 15
setblock ~24 ~4 ~30 concrete 15
setblock ~24 ~4 ~31 wool 15
setblock ~24 ~4 ~32 concrete 15
setblock ~24 ~4 ~54 concrete 15
setblock ~24 ~4 ~55 stained_hardened_clay 7
setblock ~24 ~4 ~56 nether_brick
setblock ~24 ~4 ~57 soul_sand
setblock ~24 ~4 ~58 stained_hardened_clay 7
setblock ~24 ~4 ~60 stained_hardened_clay 7
fill ~24 ~4 ~61 ~28 ~4 ~61 soul_sand
setblock ~25 ~4 ~28 wool 15
setblock ~25 ~4 ~29 coal_block
setblock ~25 ~4 ~30 wool 15
setblock ~25 ~4 ~31 coal_block
setblock ~25 ~4 ~56 stained_hardened_clay 15
setblock ~25 ~4 ~57 stained_hardened_clay 7
setblock ~25 ~4 ~58 soul_sand
setblock ~25 ~4 ~60 soul_sand
setblock ~25 ~4 ~62 soul_sand
setblock ~26 ~4 ~28 concrete 15
setblock ~26 ~4 ~29 wool 15
setblock ~26 ~4 ~30 concrete 15
setblock ~26 ~4 ~31 wool 15
setblock ~26 ~4 ~57 stained_hardened_clay 15
setblock ~26 ~4 ~58 nether_brick
setblock ~26 ~4 ~60 stained_hardened_clay 7
setblock ~26 ~4 ~62 stained_hardened_clay 7
fill ~26 ~4 ~63 ~30 ~4 ~63 soul_sand
setblock ~26 ~4 ~64 stained_hardened_clay 7
setblock ~27 ~4 ~28 wool 15
setblock ~27 ~4 ~29 coal_block
setblock ~27 ~4 ~30 wool 15
fill ~27 ~4 ~58 ~27 ~4 ~59 stained_hardened_clay 7
setblock ~27 ~4 ~60 soul_sand
setblock ~27 ~4 ~62 soul_sand
fill ~27 ~4 ~64 ~27 ~4 ~65 soul_sand
setblock ~28 ~4 ~28 concrete 15
setblock ~28 ~4 ~29 wool 15
setblock ~28 ~4 ~30 concrete 15
setblock ~28 ~4 ~60 nether_brick
setblock ~28 ~4 ~62 stained_hardened_clay 7
setblock ~28 ~4 ~64 stained_hardened_clay 7
fill ~28 ~4 ~65 ~29 ~4 ~65 soul_sand
setblock ~28 ~4 ~66 stained_hardened_clay 7
fill ~28 ~4 ~67 ~33 ~4 ~67 soul_sand
setblock ~29 ~4 ~27 coal_block
setblock ~29 ~4 ~28 wool 15
setblock ~29 ~4 ~29 coal_block
setblock ~29 ~4 ~30 wool 15
setblock ~29 ~4 ~61 stained_hardened_clay 7
setblock ~29 ~4 ~62 bedrock
setblock ~29 ~4 ~64 bedrock
fill ~29 ~4 ~66 ~30 ~4 ~66 soul_sand
setblock ~29 ~4 ~68 soul_sand
setblock ~30 ~4 ~27 wool 15
setblock ~30 ~4 ~28 concrete 15
setblock ~30 ~4 ~29 wool 15
setblock ~30 ~4 ~64 stained_hardened_clay 12
setblock ~30 ~4 ~65 bedrock
setblock ~30 ~4 ~68 stained_hardened_clay 7
setblock ~30 ~4 ~69 concrete 7
setblock ~30 ~4 ~70 stained_hardened_clay 15
setblock ~31 ~4 ~27 coal_block
setblock ~31 ~4 ~28 wool 15
setblock ~31 ~4 ~29 concrete 15
fill ~31 ~4 ~64 ~31 ~4 ~65 soul_sand
setblock ~31 ~4 ~66 bedrock
setblock ~31 ~4 ~68 soul_sand
setblock ~31 ~4 ~69 stained_hardened_clay 7
setblock ~31 ~4 ~70 concrete 7
setblock ~31 ~4 ~71 nether_brick
setblock ~32 ~4 ~27 wool 15
setblock ~32 ~4 ~28 concrete 15
setblock ~32 ~4 ~29 wool 15
setblock ~32 ~4 ~65 soul_sand
setblock ~32 ~4 ~66 stained_hardened_clay 7
setblock ~32 ~4 ~68 stained_hardened_clay 7
fill ~32 ~4 ~69 ~35 ~4 ~69 soul_sand
fill ~32 ~4 ~70 ~32 ~4 ~71 stained_hardened_clay 7
setblock ~32 ~4 ~72 stained_hardened_clay 15
setblock ~32 ~4 ~73 stained_hardened_clay 7
setblock ~33 ~4 ~26 wool 15
setblock ~33 ~4 ~27 coal_block
setblock ~33 ~4 ~28 wool 15
setblock ~33 ~4 ~29 concrete 15
setblock ~33 ~4 ~66 bedrock
setblock ~33 ~4 ~68 bedrock
setblock ~33 ~4 ~70 soul_sand
fill ~33 ~4 ~71 ~33 ~4 ~72 stained_hardened_clay 7
setblock ~33 ~4 ~73 nether_brick
setblock ~33 ~4 ~74 stained_hardened_clay 7
setblock ~34 ~4 ~26 concrete 15
setblock ~34 ~4 ~27 wool 15
setblock ~34 ~4 ~28 concrete 15
setblock ~34 ~4 ~29 coal_block
setblock ~34 ~4 ~68 stained_hardened_clay 7
setblock ~34 ~4 ~70 stained_hardened_clay 7
setblock ~34 ~4 ~71 soul_sand
setblock ~34 ~4 ~72 stained_hardened_clay 15
fill ~34 ~4 ~73 ~39 ~4 ~73 stained_hardened_clay 7
setblock ~34 ~4 ~74 coal_block
setblock ~34 ~4 ~75 nether_brick
setblock ~35 ~4 ~26 wool 15
setblock ~35 ~4 ~27 concrete 15
setblock ~35 ~4 ~28 coal_block
setblock ~35 ~4 ~70 soul_sand
setblock ~35 ~4 ~71 concrete 7
setblock ~35 ~4 ~72 stained_hardened_clay 7
setblock ~35 ~4 ~74 stained_hardened_clay 7
setblock ~35 ~4 ~75 stained_hardened_clay 15
setblock ~35 ~4 ~76 nether_brick
setblock ~35 ~4 ~77 stained_hardened_clay 15
setblock ~36 ~4 ~26 concrete 15
setblock ~36 ~4 ~27 coal_block
setblock ~36 ~4 ~28 concrete 15
setblock ~36 ~4 ~70 stained_hardened_clay 7
setblock ~36 ~4 ~71 soul_sand
setblock ~36 ~4 ~72 stained_hardened_clay 15
setblock ~36 ~4 ~74 stained_hardened_clay 15
setblock ~36 ~4 ~75 stained_hardened_clay 7
setblock ~36 ~4 ~76 coal_block
setblock ~36 ~4 ~77 nether_brick
setblock ~36 ~4 ~78 concrete 15
setblock ~37 ~4 ~26 wool 15
setblock ~37 ~4 ~27 concrete 15
setblock ~37 ~4 ~28 wool 15
setblock ~37 ~4 ~71 stained_hardened_clay 7
setblock ~37 ~4 ~72 soul_sand
setblock ~37 ~4 ~74 stained_hardened_clay 7
setblock ~37 ~4 ~75 nether_brick
setblock ~37 ~4 ~76 stained_hardened_clay 7
setblock ~37 ~4 ~77 stained_hardened_clay 15
setblock ~37 ~4 ~78 nether_brick
setblock ~37 ~4 ~79 coal_block
setblock ~38 ~4 ~26 concrete 15
setblock ~38 ~4 ~27 coal_block
setblock ~38 ~4 ~28 concrete 15
setblock ~38 ~4 ~74 stained_hardened_clay 15
setblock ~38 ~4 ~75 stained_hardened_clay 7
setblock ~38 ~4 ~76 coal_block
setblock ~38 ~4 ~77 nether_brick
setblock ~38 ~4 ~78 concrete 15
setblock ~38 ~4 ~79 wool 15
setblock ~38 ~4 ~80 concrete 15
setblock ~39 ~4 ~26 coal_block
fill ~39 ~4 ~27 ~50 ~4 ~27 concrete 15
setblock ~39 ~4 ~28 coal_block
setblock ~39 ~4 ~74 stained_hardened_clay 7
setblock ~39 ~4 ~75 stained_hardened_clay 15
setblock ~39 ~4 ~76 stained_hardened_clay 7
fill ~39 ~4 ~77 ~40 ~4 ~77 stained_hardened_clay 15
setblock ~39 ~4 ~78 nether_brick
setblock ~39 ~4 ~79 coal_block
setblock ~39 ~4 ~80 wool 15
setblock ~40 ~4 ~26 concrete 15
setblock ~40 ~4 ~28 concrete 15
setblock ~40 ~4 ~74 stained_hardened_clay 15
setblock ~40 ~4 ~75 nether_brick
setblock ~40 ~4 ~76 coal_block
setblock ~40 ~4 ~78 concrete 15
setblock ~40 ~4 ~79 wool 15
setblock ~40 ~4 ~80 concrete 15
fill ~40 ~4 ~81 ~41 ~4 ~81 coal_block
setblock ~41 ~4 ~26 coal_block
setblock ~41 ~4 ~28 coal_block
setblock ~41 ~4 ~75 stained_hardened_clay 15
setblock ~41 ~4 ~76 nether_brick
setblock ~41 ~4 ~77 wool 15
setblock ~41 ~4 ~78 nether_brick
setblock ~41 ~4 ~79 coal_block
setblock ~41 ~4 ~80 wool 15
fill ~42 ~4 ~26 ~44 ~4 ~26 concrete 15
setblock ~42 ~4 ~28 concrete 15
setblock ~42 ~4 ~76 concrete 15
setblock ~42 ~4 ~77 stained_hardened_clay 15
setblock ~42 ~4 ~78 concrete 15
setblock ~42 ~4 ~79 wool 15
setblock ~42 ~4 ~80 concrete 15
setblock ~42 ~4 ~81 wool 15
fill ~43 ~4 ~25 ~63 ~4 ~25 concrete 15
setblock ~43 ~4 ~76 nether_brick
setblock ~43 ~4 ~77 coal_block
setblock ~43 ~4 ~78 wool 15
setblock ~43 ~4 ~79 concrete 15
setblock ~43 ~4 ~80 wool 15
fill ~43 ~4 ~81 ~44 ~4 ~81 coal_block
setblock ~43 ~4 ~82 wool 15
setblock ~44 ~4 ~77 wool 15
setblock ~44 ~4 ~78 concrete 15
setblock ~44 ~4 ~79 coal_block
setblock ~44 ~4 ~80 concrete 15
setblock ~44 ~4 ~82 concrete 15
setblock ~45 ~4 ~26 coal_block
fill ~45 ~4 ~77 ~46 ~4 ~77 coal_block
setblock ~45 ~4 ~78 wool 15
setblock ~45 ~4 ~79 concrete 15
setblock ~45 ~4 ~80 coal_block
setblock ~45 ~4 ~81 concrete 15
setblock ~45 ~4 ~82 wool 15
fill ~46 ~4 ~26 ~48 ~4 ~26 concrete 15
setblock ~46 ~4 ~78 concrete 15
setblock ~46 ~4 ~79 coal_block
setblock ~46 ~4 ~80 concrete 15
setblock ~46 ~4 ~81 coal_block
setblock ~46 ~4 ~82 concrete 15
setblock ~47 ~4 ~77 concrete 15
setblock ~47 ~4 ~78 coal_block
fill ~47 ~4 ~79 ~69 ~4 ~79 concrete 15
setblock ~47 ~4 ~80 coal_block
fill ~47 ~4 ~81 ~49 ~4 ~81 concrete 15
setblock ~47 ~4 ~82 wool 15
setblock ~48 ~4 ~78 concrete 15
setblock ~48 ~4 ~80 concrete 15
setblock ~48 ~4 ~82 concrete 15
setblock ~49 ~4 ~26 coal_block
setblock ~49 ~4 ~78 coal_block
setblock ~49 ~4 ~80 coal_block
setblock ~49 ~4 ~82 coal_block
fill ~50 ~4 ~26 ~52 ~4 ~26 concrete 15
setblock ~50 ~4 ~78 concrete 15
fill ~50 ~4 ~80 ~52 ~4 ~80 concrete 15
setblock ~50 ~4 ~81 coal_block
setblock ~50 ~4 ~82 concrete 15
setblock ~51 ~4 ~78 coal_block
fill ~51 ~4 ~81 ~55 ~4 ~81 concrete 15
setblock ~51 ~4 ~82 coal_block
setblock ~52 ~4 ~24 concrete 15
setblock ~52 ~4 ~78 concrete 15
setblock ~53 ~4 ~24 coal_block
setblock ~53 ~4 ~26 coal_block
setblock ~53 ~4 ~78 coal_block
setblock ~53 ~4 ~80 coal_block
setblock ~54 ~4 ~24 concrete 15
fill ~54 ~4 ~26 ~58 ~4 ~26 concrete 15
setblock ~54 ~4 ~78 concrete 15
fill ~54 ~4 ~80 ~58 ~4 ~80 concrete 15
setblock ~55 ~4 ~24 coal_block
setblock ~55 ~4 ~78 coal_block
setblock ~56 ~4 ~24 concrete 15
setblock ~56 ~4 ~78 concrete 15
setblock ~56 ~4 ~81 coal_block
setblock ~57 ~4 ~24 coal_block
setblock ~57 ~4 ~78 coal_block
setblock ~57 ~4 ~81 concrete 15
setblock ~58 ~4 ~24 concrete 15
setblock ~58 ~4 ~78 concrete 15
setblock ~58 ~4 ~81 coal_block
setblock ~59 ~4 ~24 coal_block
setblock ~59 ~4 ~26 coal_block
fill ~59 ~4 ~77 ~69 ~4 ~77 concrete 15
setblock ~59 ~4 ~78 coal_block
setblock ~59 ~4 ~80 coal_block
setblock ~59 ~4 ~81 concrete 15
setblock ~60 ~4 ~24 concrete 15
fill ~60 ~4 ~26 ~62 ~4 ~26 concrete 15
setblock ~60 ~4 ~78 concrete 15
setblock ~60 ~4 ~80 concrete 15
setblock ~60 ~4 ~81 coal_block
setblock ~61 ~4 ~24 coal_block
setblock ~61 ~4 ~78 coal_block
setblock ~61 ~4 ~80 coal_block
setblock ~61 ~4 ~81 concrete 15
fill ~62 ~4 ~27 ~63 ~4 ~27 concrete 15
setblock ~62 ~4 ~78 concrete 15
setblock ~62 ~4 ~80 concrete 15
setblock ~63 ~4 ~26 coal_block
setblock ~63 ~4 ~78 coal_block
setblock ~63 ~4 ~80 coal_block
setblock ~64 ~4 ~25 stone
setblock ~64 ~4 ~26 clay
setblock ~64 ~4 ~27 stone
fill ~64 ~4 ~76 ~66 ~4 ~76 concrete 15
setblock ~64 ~4 ~78 concrete 15
setblock ~64 ~4 ~80 concrete 15
fill ~65 ~4 ~25 ~71 ~4 ~25 concrete 15
fill ~65 ~4 ~26 ~66 ~4 ~26 concrete 15
fill ~65 ~4 ~27 ~73 ~4 ~27 concrete 15
setblock ~65 ~4 ~78 coal_block
setblock ~65 ~4 ~80 coal_block
setblock ~66 ~4 ~78 concrete 15
setblock ~66 ~4 ~80 concrete 15
setblock ~67 ~4 ~26 coal_block
setblock ~67 ~4 ~75 concrete 15
setblock ~67 ~4 ~76 coal_block
setblock ~67 ~4 ~78 coal_block
fill ~68 ~4 ~26 ~70 ~4 ~26 concrete 15
setblock ~68 ~4 ~75 coal_block
setblock ~68 ~4 ~76 concrete 15
setblock ~68 ~4 ~78 concrete 15
setblock ~69 ~4 ~74 wool 15
setblock ~69 ~4 ~75 concrete 15
setblock ~69 ~4 ~76 coal_block
setblock ~69 ~4 ~78 coal_block
setblock ~70 ~4 ~28 concrete 15
setblock ~70 ~4 ~74 concrete 15
fill ~70 ~4 ~75 ~71 ~4 ~75 coal_block
setblock ~70 ~4 ~76 concrete 15
setblock ~70 ~4 ~77 coal_block
setblock ~70 ~4 ~78 concrete 15
setblock ~70 ~4 ~79 coal_block
setblock ~71 ~4 ~26 coal_block
setblock ~71 ~4 ~28 coal_block
setblock ~71 ~4 ~73 coal_block
setblock ~71 ~4 ~74 stained_hardened_clay 15
setblock ~71 ~4 ~76 wool 15
setblock ~71 ~4 ~77 concrete 15
setblock ~71 ~4 ~78 coal_block
setblock ~71 ~4 ~79 concrete 15
setblock ~72 ~4 ~25 coal_block
setblock ~72 ~4 ~26 concrete 15
setblock ~72 ~4 ~28 concrete 15
setblock ~72 ~4 ~72 coal_block
setblock ~72 ~4 ~73 stained_hardened_clay 15
setblock ~72 ~4 ~74 concrete 15
setblock ~72 ~4 ~75 wool 15
setblock ~72 ~4 ~76 concrete 15
fill ~72 ~4 ~77 ~73 ~4 ~77 coal_block
setblock ~72 ~4 ~78 concrete 15
setblock ~73 ~4 ~25 concrete 15
setblock ~73 ~4 ~26 coal_block
setblock ~73 ~4 ~28 coal_block
setblock ~73 ~4 ~71 stained_hardened_clay 15
setblock ~73 ~4 ~72 nether_brick
setblock ~73 ~4 ~73 wool 15
setblock ~73 ~4 ~74 nether_brick
setblock ~73 ~4 ~75 coal_block
setblock ~73 ~4 ~76 wool 15
setblock ~73 ~4 ~78 wool 15
setblock ~74 ~4 ~25 wool 15
setblock ~74 ~4 ~26 concrete 15
setblock ~74 ~4 ~27 coal_block
setblock ~74 ~4 ~28 concrete 15
setblock ~74 ~4 ~70 stained_hardened_clay 15
fill ~74 ~4 ~71 ~79 ~4 ~71 stained_hardened_clay 7
setblock ~74 ~4 ~72 coal_block
setblock ~74 ~4 ~73 nether_brick
setblock ~74 ~4 ~74 coal_block
setblock ~74 ~4 ~75 stained_hardened_clay 15
setblock ~74 ~4 ~76 concrete 15
setblock ~74 ~4 ~77 wool 15
setblock ~74 ~4 ~78 concrete 15
setblock ~75 ~4 ~25 coal_block
setblock ~75 ~4 ~26 wool 15
setblock ~75 ~4 ~27 concrete 15
setblock ~75 ~4 ~28 coal_block
setblock ~75 ~4 ~69 stained_hardened_clay 7
setblock ~75 ~4 ~70 concrete 7
setblock ~75 ~4 ~72 stained_hardened_clay 7
setblock ~75 ~4 ~73 stained_hardened_clay 15
setblock ~75 ~4 ~74 nether_brick
setblock ~75 ~4 ~75 coal_block
setblock ~75 ~4 ~76 stained_hardened_clay 15
setblock ~75 ~4 ~77 coal_block
setblock ~76 ~4 ~25 wool 15
setblock ~76 ~4 ~26 concrete 15
setblock ~76 ~4 ~27 coal_block
setblock ~76 ~4 ~28 concrete 15
setblock ~76 ~4 ~68 nether_brick
setblock ~76 ~4 ~69 concrete 7
setblock ~76 ~4 ~70 nether_brick
setblock ~76 ~4 ~72 stained_hardened_clay 15
setblock ~76 ~4 ~73 nether_brick
setblock ~76 ~4 ~74 coal_block
setblock ~76 ~4 ~75 stained_hardened_clay 15
setblock ~76 ~4 ~76 concrete 15
setblock ~77 ~4 ~25 coal_block
setblock ~77 ~4 ~26 wool 15
setblock ~77 ~4 ~27 concrete 15
setblock ~77 ~4 ~28 wool 15
setblock ~77 ~4 ~66 soul_sand
setblock ~77 ~4 ~67 stained_hardened_clay 7
setblock ~77 ~4 ~68 soul_sand
setblock ~77 ~4 ~69 stained_hardened_clay 7
setblock ~77 ~4 ~70 soul_sand
setblock ~77 ~4 ~72 stained_hardened_clay 7
setblock ~77 ~4 ~73 stained_hardened_clay 15
setblock ~77 ~4 ~74 nether_brick
setblock ~77 ~4 ~75 coal_block
setblock ~78 ~4 ~26 concrete 15
setblock ~78 ~4 ~27 wool 15
fill ~78 ~4 ~28 ~78 ~4 ~29 concrete 15
fill ~78 ~4 ~65 ~78 ~4 ~66 stained_hardened_clay 7
fill ~78 ~4 ~67 ~82 ~4 ~67 soul_sand
setblock ~78 ~4 ~68 stained_hardened_clay 7
fill ~78 ~4 ~69 ~80 ~4 ~69 soul_sand
setblock ~78 ~4 ~70 stained_hardened_clay 7
setblock ~78 ~4 ~72 stained_hardened_clay 15
setblock ~78 ~4 ~73 stained_hardened_clay 7
setblock ~78 ~4 ~74 coal_block
setblock ~79 ~4 ~26 wool 15
setblock ~79 ~4 ~27 concrete 15
setblock ~79 ~4 ~28 wool 15
fill ~79 ~4 ~29 ~81 ~4 ~29 concrete 15
setblock ~79 ~4 ~63 concrete 15
fill ~79 ~4 ~64 ~80 ~4 ~64 stained_hardened_clay 7
setblock ~79 ~4 ~65 concrete 7
setblock ~79 ~4 ~66 bedrock
setblock ~79 ~4 ~68 soul_sand
setblock ~79 ~4 ~70 soul_sand
setblock ~79 ~4 ~72 stained_hardened_clay 7
setblock ~80 ~4 ~26 concrete 15
setblock ~80 ~4 ~27 coal_block
setblock ~80 ~4 ~28 concrete 15
setblock ~80 ~4 ~62 concrete 15
setblock ~80 ~4 ~63 stained_hardened_clay 15
fill ~80 ~4 ~65 ~82 ~4 ~65 soul_sand
setblock ~80 ~4 ~66 stained_hardened_clay 7
setblock ~80 ~4 ~68 stained_hardened_clay 7
setblock ~80 ~4 ~70 stained_hardened_clay 15
setblock ~81 ~4 ~27 concrete 15
setblock ~81 ~4 ~28 coal_block
setblock ~81 ~4 ~30 coal_block
setblock ~81 ~4 ~60 wool 15
setblock ~81 ~4 ~61 concrete 15
setblock ~81 ~4 ~62 nether_brick
fill ~81 ~4 ~63 ~84 ~4 ~63 soul_sand
fill ~81 ~4 ~64 ~81 ~4 ~63 soul_sand
setblock ~81 ~4 ~66 bedrock
setblock ~81 ~4 ~68 soul_sand
setblock ~81 ~4 ~69 stained_hardened_clay 7
setblock ~82 ~4 ~27 coal_block
setblock ~82 ~4 ~28 concrete 15
setblock ~82 ~4 ~29 coal_block
setblock ~82 ~4 ~30 concrete 15
setblock ~82 ~4 ~58 concrete 15
setblock ~82 ~4 ~59 coal_block
setblock ~82 ~4 ~60 concrete 15
setblock ~82 ~4 ~61 wool 15
setblock ~82 ~4 ~62 stained_hardened_clay 15
setblock ~82 ~4 ~64 stained_hardened_clay 7
setblock ~82 ~4 ~66 stained_hardened_clay 7
setblock ~83 ~4 ~27 concrete 15
setblock ~83 ~4 ~28 coal_block
setblock ~83 ~4 ~29 concrete 15
setblock ~83 ~4 ~30 coal_block
setblock ~83 ~4 ~57 coal_block
setblock ~83 ~4 ~58 wool 15
setblock ~83 ~4 ~59 concrete 15
fill ~83 ~4 ~60 ~83 ~4 ~61 nether_brick
setblock ~83 ~4 ~62 soul_sand
setblock ~83 ~4 ~64 soul_sand
setblock ~84 ~4 ~27 coal_block
setblock ~84 ~4 ~28 concrete 15
setblock ~84 ~4 ~29 coal_block
fill ~84 ~4 ~30 ~84 ~4 ~31 concrete 15
fill ~84 ~4 ~55 ~87 ~4 ~55 concrete 15
fill ~84 ~4 ~56 ~84 ~4 ~55 concrete 15
setblock ~84 ~4 ~57 wool 15
setblock ~84 ~4 ~58 concrete 15
setblock ~84 ~4 ~59 wool 15
setblock ~84 ~4 ~60 stained_hardened_clay 15
fill ~84 ~4 ~61 ~85 ~4 ~61 soul_sand
setblock ~84 ~4 ~62 stained_hardened_clay 7
setblock ~85 ~4 ~28 wool 15
setblock ~85 ~4 ~29 concrete 15
setblock ~85 ~4 ~30 coal_block
setblock ~85 ~4 ~31 concrete 15
fill ~85 ~4 ~53 ~87 ~4 ~53 concrete 15
setblock ~85 ~4 ~54 coal_block
setblock ~85 ~4 ~56 wool 15
setblock ~85 ~4 ~57 coal_block
fill ~85 ~4 ~58 ~85 ~4 ~59 stained_hardened_clay 7
setblock ~85 ~4 ~60 soul_sand
setblock ~86 ~4 ~28 concrete 15
setblock ~86 ~4 ~29 coal_block
setblock ~86 ~4 ~30 concrete 15
setblock ~86 ~4 ~31 coal_block
setblock ~86 ~4 ~32 concrete 15
fill ~86 ~4 ~51 ~89 ~4 ~51 concrete 15
fill ~86 ~4 ~52 ~86 ~4 ~51 concrete 15
setblock ~86 ~4 ~54 concrete 15
setblock ~86 ~4 ~56 concrete 15
setblock ~86 ~4 ~57 stained_hardened_clay 7
setblock ~86 ~4 ~58 nether_brick
setblock ~86 ~4 ~59 soul_sand
setblock ~87 ~4 ~29 concrete 15
setblock ~87 ~4 ~30 coal_block
setblock ~87 ~4 ~31 concrete 15
setblock ~87 ~4 ~32 wool 15
setblock ~87 ~4 ~33 concrete 15
fill ~87 ~4 ~49 ~89 ~4 ~49 concrete 15
setblock ~87 ~4 ~50 coal_block
setblock ~87 ~4 ~52 coal_block
setblock ~87 ~4 ~54 wool 15
setblock ~87 ~4 ~56 nether_brick
setblock ~87 ~4 ~57 soul_sand
setblock ~88 ~4 ~29 wool 15
setblock ~88 ~4 ~30 concrete 15
setblock ~88 ~4 ~31 coal_block
setblock ~88 ~4 ~32 concrete 15
setblock ~88 ~4 ~33 coal_block
setblock ~88 ~4 ~34 concrete 15
fill ~88 ~4 ~47 ~91 ~4 ~47 concrete 15
fill ~88 ~4 ~48 ~90 ~4 ~48 concrete 15
setblock ~88 ~4 ~50 concrete 15
setblock ~88 ~4 ~52 concrete 15
setblock ~88 ~4 ~53 nether_brick
setblock ~88 ~4 ~54 concrete 15
setblock ~88 ~4 ~55 soul_sand
setblock ~89 ~4 ~30 wool 15
setblock ~89 ~4 ~31 concrete 15
setblock ~89 ~4 ~32 coal_block
setblock ~89 ~4 ~33 concrete 15
setblock ~89 ~4 ~34 coal_block
setblock ~89 ~4 ~35 concrete 15
setblock ~89 ~4 ~36 coal_block
setblock ~89 ~4 ~45 concrete 15
setblock ~89 ~4 ~46 coal_block
setblock ~89 ~4 ~50 coal_block
setblock ~89 ~4 ~52 wool 15
setblock ~89 ~4 ~53 stained_hardened_clay 7
setblock ~90 ~4 ~31 coal_block
setblock ~90 ~4 ~32 concrete 15
fill ~90 ~4 ~33 ~92 ~4 ~33 coal_block
setblock ~90 ~4 ~34 concrete 15
setblock ~90 ~4 ~35 coal_block
setblock ~90 ~4 ~36 concrete 15
setblock ~90 ~4 ~37 coal_block
fill ~90 ~4 ~38 ~90 ~4 ~40 concrete 15
setblock ~90 ~4 ~41 coal_block
fill ~90 ~4 ~42 ~90 ~4 ~44 concrete 15
setblock ~90 ~4 ~45 coal_block
setblock ~90 ~4 ~46 concrete 15
setblock ~90 ~4 ~49 coal_block
setblock ~90 ~4 ~50 concrete 15
setblock ~90 ~4 ~51 stained_hardened_clay 7
setblock ~91 ~4 ~31 concrete 15
setblock ~91 ~4 ~32 wool 15
setblock ~91 ~4 ~34 wool 15
setblock ~91 ~4 ~35 concrete 15
setblock ~91 ~4 ~36 coal_block
fill ~91 ~4 ~37 ~94 ~4 ~37 concrete 15
setblock ~91 ~4 ~38 coal_block
fill ~91 ~4 ~39 ~93 ~4 ~39 concrete 15
setblock ~91 ~4 ~40 coal_block
fill ~91 ~4 ~41 ~93 ~4 ~41 concrete 15
setblock ~91 ~4 ~42 coal_block
fill ~91 ~4 ~43 ~93 ~4 ~43 concrete 15
setblock ~91 ~4 ~44 coal_block
setblock ~91 ~4 ~45 concrete 15
fill ~91 ~4 ~46 ~92 ~4 ~46 coal_block
setblock ~91 ~4 ~48 stained_hardened_clay 15
setblock ~91 ~4 ~49 stained_hardened_clay 7
setblock ~91 ~4 ~50 soul_sand
setblock ~92 ~4 ~32 concrete 15
setblock ~92 ~4 ~34 concrete 15
setblock ~92 ~4 ~35 coal_block
setblock ~92 ~4 ~36 concrete 15
setblock ~92 ~4 ~38 concrete 15
setblock ~92 ~4 ~40 concrete 15
setblock ~92 ~4 ~42 concrete 15
setblock ~92 ~4 ~44 concrete 15
setblock ~92 ~4 ~45 coal_block
setblock ~92 ~4 ~47 stained_hardened_clay 7
setblock ~92 ~4 ~48 nether_brick
setblock ~93 ~4 ~33 concrete 15
setblock ~93 ~4 ~34 coal_block
setblock ~93 ~4 ~35 concrete 15
setblock ~93 ~4 ~36 coal_block
setblock ~93 ~4 ~38 coal_block
setblock ~93 ~4 ~40 coal_block
setblock ~93 ~4 ~42 coal_block
setblock ~93 ~4 ~44 nether_brick
setblock ~93 ~4 ~45 stained_hardened_clay 7
setblock ~93 ~4 ~46 soul_sand
setblock ~94 ~4 ~34 concrete 15
setblock ~94 ~4 ~35 coal_block
setblock ~94 ~4 ~36 concrete 15
setblock ~94 ~4 ~38 concrete 15
fill ~94 ~4 ~39 ~95 ~4 ~39 coal_block
setblock ~94 ~4 ~40 concrete 15
setblock ~94 ~4 ~41 nether_brick
setblock ~94 ~4 ~42 concrete 15
setblock ~94 ~4 ~43 nether_brick
setblock ~94 ~4 ~44 stained_hardened_clay 15
fill ~95 ~4 ~36 ~95 ~4 ~37 coal_block
setblock ~95 ~4 ~38 stained_hardened_clay 15
setblock ~95 ~4 ~40 nether_brick
setblock ~95 ~4 ~41 stained_hardened_clay 15
setblock ~95 ~4 ~42 stained_hardened_clay 7
fill ~6 ~5 ~38 ~8 ~5 ~38 concrete 15
fill ~6 ~5 ~39 ~9 ~5 ~39 concrete 15
fill ~6 ~5 ~40 ~6 ~5 ~42 concrete 15
fill ~7 ~5 ~35 ~10 ~5 ~35 concrete 15
fill ~7 ~5 ~36 ~8 ~5 ~36 concrete 15
fill ~7 ~5 ~37 ~9 ~5 ~37 concrete 15
setblock ~7 ~5 ~40 coal_block
fill ~7 ~5 ~41 ~8 ~5 ~41 concrete 15
setblock ~7 ~5 ~42 coal_block
fill ~7 ~5 ~43 ~8 ~5 ~43 concrete 15
setblock ~7 ~5 ~44 wool 15
setblock ~7 ~5 ~45 coal_block
fill ~8 ~5 ~33 ~14 ~5 ~33 concrete 15
fill ~8 ~5 ~34 ~8 ~5 ~33 concrete 15
setblock ~8 ~5 ~40 concrete 15
setblock ~8 ~5 ~42 concrete 15
setblock ~8 ~5 ~44 coal_block
setblock ~8 ~5 ~45 concrete 15
setblock ~8 ~5 ~46 stained_hardened_clay 15
setblock ~8 ~5 ~47 coal_block
setblock ~9 ~5 ~32 coal_block
setblock ~9 ~5 ~34 coal_block
setblock ~9 ~5 ~36 coal_block
setblock ~9 ~5 ~38 coal_block
setblock ~9 ~5 ~41 coal_block
setblock ~9 ~5 ~42 wool 15
setblock ~9 ~5 ~43 coal_block
setblock ~9 ~5 ~44 stained_hardened_clay 15
setblock ~9 ~5 ~45 coal_block
fill ~9 ~5 ~46 ~10 ~5 ~46 nether_brick
setblock ~9 ~5 ~47 stained_hardened_clay 15
fill ~9 ~5 ~48 ~10 ~5 ~48 nether_brick
fill ~9 ~5 ~49 ~10 ~5 ~49 stained_hardened_clay 15
fill ~10 ~5 ~31 ~18 ~5 ~31 concrete 15
fill ~10 ~5 ~32 ~10 ~5 ~31 concrete 15
setblock ~10 ~5 ~34 concrete 15
setblock ~10 ~5 ~45 stained_hardened_clay 15
setblock ~10 ~5 ~47 coal_block
setblock ~10 ~5 ~50 nether_brick
setblock ~11 ~5 ~32 coal_block
setblock ~11 ~5 ~34 coal_block
setblock ~11 ~5 ~47 nether_brick
fill ~11 ~5 ~48 ~12 ~5 ~48 stained_hardened_clay 7
fill ~11 ~5 ~49 ~12 ~5 ~49 stained_hardened_clay 7
fill ~11 ~5 ~50 ~12 ~5 ~50 stained_hardened_clay 7
setblock ~11 ~5 ~51 nether_brick
fill ~12 ~5 ~30 ~20 ~5 ~30 concrete 15
setblock ~12 ~5 ~32 concrete 15
setblock ~12 ~5 ~34 concrete 15
setblock ~12 ~5 ~51 stained_hardened_clay 15
setblock ~12 ~5 ~52 stained_hardened_clay 7
setblock ~12 ~5 ~53 stained_hardened_clay 15
setblock ~13 ~5 ~32 coal_block
setblock ~13 ~5 ~50 soul_sand
fill ~13 ~5 ~51 ~14 ~5 ~51 stained_hardened_clay 7
fill ~13 ~5 ~52 ~14 ~5 ~52 concrete 7
fill ~13 ~5 ~53 ~14 ~5 ~53 stained_hardened_clay 7
fill ~13 ~5 ~54 ~14 ~5 ~54 stained_hardened_clay 7
fill ~14 ~5 ~29 ~22 ~5 ~29 concrete 15
fill ~14 ~5 ~32 ~16 ~5 ~32 concrete 15
setblock ~14 ~5 ~55 stained_hardened_clay 15
setblock ~15 ~5 ~52 soul_sand
setblock ~15 ~5 ~53 concrete 7
fill ~15 ~5 ~54 ~17 ~5 ~54 soul_sand
fill ~15 ~5 ~55 ~16 ~5 ~55 stained_hardened_clay 7
fill ~15 ~5 ~56 ~16 ~5 ~56 stained_hardened_clay 7
setblock ~16 ~5 ~53 stained_hardened_clay 7
setblock ~16 ~5 ~57 nether_brick
fill ~17 ~5 ~28 ~20 ~5 ~28 concrete 15
fill ~17 ~5 ~55 ~17 ~5 ~56 soul_sand
fill ~17 ~5 ~57 ~18 ~5 ~57 stained_hardened_clay 7
fill ~17 ~5 ~58 ~17 ~5 ~57 stained_hardened_clay 7
setblock ~18 ~5 ~55 stained_hardened_clay 12
fill ~18 ~5 ~56 ~19 ~5 ~56 soul_sand
setblock ~18 ~5 ~58 stained_hardened_clay 12
setblock ~18 ~5 ~59 nether_brick
fill ~19 ~5 ~57 ~19 ~5 ~58 soul_sand
fill ~19 ~5 ~59 ~22 ~5 ~59 stained_hardened_clay 7
fill ~19 ~5 ~60 ~20 ~5 ~60 stained_hardened_clay 7
fill ~20 ~5 ~27 ~28 ~5 ~27 concrete 15
setblock ~20 ~5 ~57 stained_hardened_clay 7
fill ~20 ~5 ~58 ~21 ~5 ~58 soul_sand
setblock ~20 ~5 ~61 stained_hardened_clay 15
setblock ~21 ~5 ~28 coal_block
setblock ~21 ~5 ~60 soul_sand
fill ~21 ~5 ~61 ~23 ~5 ~61 stained_hardened_clay 7
fill ~21 ~5 ~62 ~22 ~5 ~62 stained_hardened_clay 7
fill ~21 ~5 ~63 ~22 ~5 ~63 stained_hardened_clay 15
setblock ~22 ~5 ~28 concrete 15
setblock ~22 ~5 ~60 stained_hardened_clay 7
setblock ~22 ~5 ~64 stained_hardened_clay 15
fill ~23 ~5 ~26 ~24 ~5 ~26 concrete 15
fill ~23 ~5 ~28 ~24 ~5 ~28 coal_block
setblock ~23 ~5 ~60 soul_sand
setblock ~23 ~5 ~62 soul_sand
fill ~23 ~5 ~63 ~25 ~5 ~63 stained_hardened_clay 7
fill ~23 ~5 ~64 ~24 ~5 ~64 stained_hardened_clay 7
fill ~23 ~5 ~65 ~24 ~5 ~65 stained_hardened_clay 15
setblock ~24 ~5 ~62 stained_hardened_clay 7
setblock ~24 ~5 ~66 nether_brick
setblock ~24 ~5 ~67 coal_block
setblock ~25 ~5 ~26 coal_block
setblock ~25 ~5 ~64 concrete 7
fill ~25 ~5 ~65 ~26 ~5 ~65 stained_hardened_clay 7
fill ~25 ~5 ~66 ~26 ~5 ~66 stained_hardened_clay 7
fill ~25 ~5 ~67 ~26 ~5 ~67 stained_hardened_clay 15
fill ~25 ~5 ~68 ~26 ~5 ~68 nether_brick
fill ~26 ~5 ~25 ~42 ~5 ~25 concrete 15
fill ~26 ~5 ~26 ~26 ~5 ~25 concrete 15
setblock ~26 ~5 ~69 coal_block
setblock ~27 ~5 ~26 wool 15
setblock ~27 ~5 ~66 soul_sand
fill ~27 ~5 ~67 ~27 ~5 ~68 stained_hardened_clay 7
fill ~27 ~5 ~69 ~28 ~5 ~69 stained_hardened_clay 15
setblock ~27 ~5 ~70 nether_brick
fill ~27 ~5 ~71 ~28 ~5 ~71 coal_block
setblock ~28 ~5 ~26 coal_block
setblock ~28 ~5 ~68 stained_hardened_clay 7
setblock ~28 ~5 ~70 stained_hardened_clay 15
setblock ~28 ~5 ~72 stained_hardened_clay 15
setblock ~29 ~5 ~26 wool 15
setblock ~29 ~5 ~69 nether_brick
setblock ~29 ~5 ~70 stained_hardened_clay 7
setblock ~29 ~5 ~71 stained_hardened_clay 15
setblock ~29 ~5 ~72 nether_brick
fill ~29 ~5 ~73 ~31 ~5 ~73 coal_block
fill ~29 ~5 ~74 ~32 ~5 ~74 stained_hardened_clay 15
fill ~30 ~5 ~24 ~31 ~5 ~24 coal_block
fill ~30 ~5 ~26 ~31 ~5 ~26 coal_block
setblock ~30 ~5 ~71 coal_block
setblock ~30 ~5 ~72 stained_hardened_clay 15
setblock ~30 ~5 ~75 concrete 15
setblock ~31 ~5 ~72 nether_brick
setblock ~31 ~5 ~75 coal_block
setblock ~31 ~5 ~76 stained_hardened_clay 15
setblock ~32 ~5 ~24 concrete 15
setblock ~32 ~5 ~26 concrete 15
setblock ~32 ~5 ~75 concrete 15
setblock ~32 ~5 ~76 coal_block
setblock ~32 ~5 ~77 concrete 15
setblock ~32 ~5 ~78 coal_block
setblock ~33 ~5 ~24 wool 15
setblock ~33 ~5 ~75 coal_block
setblock ~33 ~5 ~76 stained_hardened_clay 15
setblock ~33 ~5 ~77 coal_block
setblock ~33 ~5 ~78 stained_hardened_clay 15
fill ~33 ~5 ~79 ~34 ~5 ~79 concrete 15
fill ~34 ~5 ~24 ~35 ~5 ~24 coal_block
setblock ~34 ~5 ~76 coal_block
setblock ~34 ~5 ~77 concrete 15
setblock ~34 ~5 ~78 coal_block
setblock ~34 ~5 ~80 coal_block
setblock ~35 ~5 ~78 wool 15
setblock ~35 ~5 ~79 coal_block
setblock ~35 ~5 ~80 wool 15
fill ~36 ~5 ~23 ~80 ~5 ~23 concrete 15
fill ~36 ~5 ~24 ~36 ~5 ~23 concrete 15
fill ~36 ~5 ~79 ~36 ~5 ~81 concrete 15
setblock ~37 ~5 ~24 coal_block
setblock ~37 ~5 ~80 wool 15
fill ~37 ~5 ~81 ~39 ~5 ~81 concrete 15
setblock ~37 ~5 ~82 wool 15
setblock ~38 ~5 ~24 concrete 15
fill ~38 ~5 ~82 ~39 ~5 ~82 coal_block
setblock ~39 ~5 ~24 coal_block
fill ~39 ~5 ~83 ~58 ~5 ~83 concrete 15
fill ~40 ~5 ~24 ~51 ~5 ~24 concrete 15
setblock ~40 ~5 ~82 concrete 15
setblock ~41 ~5 ~82 coal_block
setblock ~42 ~5 ~82 concrete 15
setblock ~43 ~5 ~84 coal_block
fill ~44 ~5 ~84 ~44 ~6 ~84 concrete 15
setblock ~45 ~5 ~84 coal_block
setblock ~46 ~5 ~84 concrete 15
setblock ~47 ~5 ~84 coal_block
fill ~48 ~5 ~22 ~72 ~5 ~22 concrete 15
setblock ~48 ~5 ~84 concrete 15
setblock ~49 ~5 ~84 coal_block
fill ~50 ~5 ~84 ~52 ~5 ~84 concrete 15
fill ~52 ~5 ~82 ~56 ~5 ~82 concrete 15
setblock ~53 ~5 ~84 coal_block
setblock ~54 ~5 ~84 concrete 15
setblock ~55 ~5 ~84 coal_block
fill ~56 ~5 ~84 ~60 ~5 ~84 concrete 15
setblock ~57 ~5 ~82 coal_block
setblock ~58 ~5 ~82 concrete 15
setblock ~59 ~5 ~82 concrete 7
setblock ~59 ~5 ~83 nether_brick
fill ~60 ~5 ~82 ~60 ~5 ~84 concrete 15
setblock ~61 ~5 ~82 coal_block
fill ~61 ~5 ~83 ~68 ~5 ~83 concrete 15
fill ~62 ~5 ~24 ~72 ~5 ~24 concrete 15
fill ~62 ~5 ~81 ~76 ~5 ~81 concrete 15
fill ~62 ~5 ~82 ~62 ~5 ~81 concrete 15
setblock ~63 ~5 ~82 coal_block
setblock ~64 ~5 ~82 concrete 15
setblock ~65 ~5 ~82 coal_block
setblock ~66 ~5 ~82 concrete 15
fill ~67 ~5 ~80 ~74 ~5 ~80 concrete 15
setblock ~67 ~5 ~82 coal_block
fill ~68 ~5 ~82 ~70 ~5 ~82 concrete 15
setblock ~71 ~5 ~82 coal_block
fill ~72 ~5 ~79 ~79 ~5 ~79 concrete 15
setblock ~72 ~5 ~82 concrete 15
setblock ~73 ~5 ~22 coal_block
setblock ~73 ~5 ~24 coal_block
fill ~73 ~5 ~82 ~73 ~6 ~82 coal_block
setblock ~74 ~5 ~22 concrete 15
setblock ~74 ~5 ~24 concrete 15
setblock ~75 ~5 ~22 wool 15
setblock ~75 ~5 ~24 wool 15
setblock ~75 ~5 ~78 coal_block
setblock ~75 ~5 ~80 coal_block
setblock ~76 ~5 ~22 coal_block
setblock ~76 ~5 ~24 concrete 15
fill ~76 ~5 ~77 ~78 ~5 ~77 concrete 15
fill ~76 ~5 ~78 ~76 ~5 ~77 concrete 15
setblock ~76 ~5 ~80 concrete 15
setblock ~77 ~5 ~22 wool 15
setblock ~77 ~5 ~24 wool 15
setblock ~77 ~5 ~76 wool 15
fill ~77 ~5 ~78 ~78 ~5 ~78 coal_block
setblock ~77 ~5 ~80 coal_block
setblock ~78 ~5 ~24 coal_block
setblock ~78 ~5 ~25 concrete 15
setblock ~78 ~5 ~75 concrete 15
setblock ~78 ~5 ~76 coal_block
setblock ~79 ~5 ~24 wool 15
setblock ~79 ~5 ~25 coal_block
fill ~79 ~5 ~73 ~79 ~5 ~74 stained_hardened_clay 15
setblock ~79 ~5 ~75 coal_block
setblock ~79 ~5 ~76 wool 15
setblock ~79 ~5 ~77 coal_block
setblock ~79 ~5 ~78 wool 15
fill ~80 ~5 ~24 ~80 ~5 ~25 concrete 15
fill ~80 ~5 ~71 ~81 ~5 ~71 stained_hardened_clay 15
fill ~80 ~5 ~72 ~80 ~5 ~71 stained_hardened_clay 15
setblock ~80 ~5 ~73 concrete 15
setblock ~80 ~5 ~74 coal_block
fill ~80 ~5 ~75 ~80 ~5 ~77 concrete 15
setblock ~80 ~5 ~78 coal_block
setblock ~81 ~5 ~24 wool 15
fill ~81 ~5 ~25 ~87 ~5 ~25 concrete 15
setblock ~81 ~5 ~26 coal_block
setblock ~81 ~5 ~70 stained_hardened_clay 7
setblock ~81 ~5 ~72 nether_brick
setblock ~81 ~5 ~73 coal_block
setblock ~81 ~5 ~74 stained_hardened_clay 15
setblock ~81 ~5 ~75 coal_block
setblock ~81 ~5 ~76 stained_hardened_clay 15
setblock ~81 ~5 ~77 coal_block
setblock ~82 ~5 ~24 concrete 15
setblock ~82 ~5 ~26 concrete 15
fill ~82 ~5 ~68 ~83 ~5 ~68 stained_hardened_clay 7
fill ~82 ~5 ~69 ~83 ~5 ~69 stained_hardened_clay 15
setblock ~82 ~5 ~70 nether_brick
setblock ~82 ~5 ~71 coal_block
fill ~82 ~5 ~72 ~83 ~5 ~72 stained_hardened_clay 15
setblock ~82 ~5 ~73 concrete 15
setblock ~82 ~5 ~74 coal_block
setblock ~82 ~5 ~75 concrete 15
setblock ~83 ~5 ~24 wool 15
setblock ~83 ~5 ~26 coal_block
setblock ~83 ~5 ~65 stained_hardened_clay 12
setblock ~83 ~5 ~66 soul_sand
setblock ~83 ~5 ~67 stained_hardened_clay 7
setblock ~83 ~5 ~70 stained_hardened_clay 7
setblock ~83 ~5 ~71 stained_hardened_clay 15
setblock ~83 ~5 ~73 coal_block
setblock ~83 ~5 ~74 stained_hardened_clay 15
setblock ~84 ~5 ~24 coal_block
setblock ~84 ~5 ~26 concrete 15
fill ~84 ~5 ~64 ~85 ~5 ~64 soul_sand
fill ~84 ~5 ~65 ~85 ~5 ~65 stained_hardened_clay 7
fill ~84 ~5 ~66 ~87 ~5 ~66 stained_hardened_clay 7
fill ~84 ~5 ~67 ~86 ~5 ~67 stained_hardened_clay 15
setblock ~84 ~5 ~68 nether_brick
setblock ~84 ~5 ~69 coal_block
setblock ~84 ~5 ~70 stained_hardened_clay 15
fill ~84 ~5 ~71 ~84 ~5 ~72 coal_block
setblock ~85 ~5 ~26 coal_block
fill ~85 ~5 ~27 ~92 ~5 ~27 concrete 15
fill ~85 ~5 ~62 ~87 ~5 ~62 soul_sand
fill ~85 ~5 ~63 ~87 ~5 ~63 stained_hardened_clay 7
setblock ~85 ~5 ~68 stained_hardened_clay 7
setblock ~85 ~5 ~69 stained_hardened_clay 15
setblock ~85 ~5 ~70 nether_brick
setblock ~86 ~5 ~26 concrete 15
setblock ~86 ~5 ~60 stained_hardened_clay 12
setblock ~86 ~5 ~61 stained_hardened_clay 7
fill ~86 ~5 ~64 ~87 ~5 ~64 stained_hardened_clay 7
fill ~86 ~5 ~65 ~87 ~5 ~65 nether_brick
setblock ~87 ~5 ~26 coal_block
fill ~87 ~5 ~28 ~88 ~5 ~28 coal_block
setblock ~87 ~5 ~58 soul_sand
setblock ~87 ~5 ~59 stained_hardened_clay 12
fill ~87 ~5 ~60 ~87 ~5 ~62 soul_sand
setblock ~88 ~5 ~26 concrete 15
fill ~88 ~5 ~56 ~88 ~5 ~57 stained_hardened_clay 7
setblock ~88 ~5 ~58 stained_hardened_clay 12
fill ~88 ~5 ~59 ~90 ~5 ~59 stained_hardened_clay 7
fill ~88 ~5 ~60 ~88 ~5 ~62 stained_hardened_clay 7
setblock ~88 ~5 ~63 stained_hardened_clay 15
fill ~89 ~5 ~26 ~90 ~5 ~26 coal_block
setblock ~89 ~5 ~28 wool 15
fill ~89 ~5 ~29 ~96 ~5 ~29 concrete 15
fill ~89 ~5 ~54 ~93 ~5 ~54 soul_sand
fill ~89 ~5 ~55 ~90 ~5 ~55 stained_hardened_clay 7
fill ~89 ~5 ~56 ~92 ~5 ~56 soul_sand
setblock ~89 ~5 ~57 stained_hardened_clay 12
fill ~89 ~5 ~58 ~90 ~5 ~58 soul_sand
setblock ~89 ~5 ~60 soul_sand
setblock ~89 ~5 ~61 stained_hardened_clay 7
setblock ~90 ~5 ~28 coal_block
setblock ~90 ~5 ~30 concrete 15
fill ~90 ~5 ~52 ~90 ~5 ~53 stained_hardened_clay 7
setblock ~90 ~5 ~57 stained_hardened_clay 7
setblock ~91 ~5 ~28 wool 15
setblock ~91 ~5 ~30 coal_block
setblock ~91 ~5 ~51 stained_hardened_clay 12
fill ~91 ~5 ~52 ~94 ~5 ~52 soul_sand
fill ~91 ~5 ~53 ~91 ~5 ~52 soul_sand
setblock ~91 ~5 ~55 soul_sand
setblock ~91 ~5 ~57 soul_sand
fill ~92 ~5 ~28 ~94 ~5 ~28 concrete 15
fill ~92 ~5 ~30 ~92 ~5 ~31 concrete 15
setblock ~92 ~5 ~49 stained_hardened_clay 7
fill ~92 ~5 ~50 ~94 ~5 ~50 soul_sand
setblock ~92 ~5 ~51 stained_hardened_clay 7
setblock ~92 ~5 ~53 stained_hardened_clay 12
setblock ~92 ~5 ~55 stained_hardened_clay 7
setblock ~93 ~5 ~30 wool 15
fill ~93 ~5 ~31 ~99 ~5 ~31 concrete 15
setblock ~93 ~5 ~32 coal_block
fill ~93 ~5 ~47 ~94 ~5 ~47 stained_hardened_clay 7
fill ~93 ~5 ~48 ~97 ~5 ~48 soul_sand
fill ~93 ~5 ~49 ~93 ~5 ~48 soul_sand
fill ~93 ~5 ~51 ~95 ~5 ~51 soul_sand
setblock ~93 ~5 ~53 soul_sand
fill ~94 ~5 ~30 ~97 ~5 ~30 concrete 15
fill ~94 ~5 ~32 ~98 ~5 ~32 concrete 15
fill ~94 ~5 ~33 ~101 ~5 ~33 concrete 15
setblock ~94 ~5 ~45 nether_brick
setblock ~94 ~5 ~46 stained_hardened_clay 7
setblock ~94 ~5 ~49 stained_hardened_clay 12
setblock ~95 ~5 ~34 coal_block
fill ~95 ~5 ~35 ~102 ~5 ~35 concrete 15
setblock ~95 ~5 ~43 nether_brick
fill ~95 ~5 ~44 ~96 ~5 ~44 stained_hardened_clay 7
fill ~95 ~5 ~45 ~99 ~5 ~45 stained_hardened_clay 7
fill ~95 ~5 ~46 ~98 ~5 ~46 soul_sand
setblock ~95 ~5 ~47 stained_hardened_clay 12
fill ~95 ~5 ~49 ~96 ~5 ~49 soul_sand
setblock ~95 ~5 ~50 bedrock
setblock ~96 ~5 ~34 concrete 15
fill ~96 ~5 ~36 ~96 ~5 ~37 concrete 15
setblock ~96 ~5 ~38 coal_block
setblock ~96 ~5 ~39 concrete 15
fill ~96 ~5 ~40 ~98 ~5 ~40 nether_brick
setblock ~96 ~5 ~41 stained_hardened_clay 15
fill ~96 ~5 ~42 ~98 ~5 ~42 stained_hardened_clay 7
setblock ~96 ~5 ~43 stained_hardened_clay 15
setblock ~96 ~5 ~47 stained_hardened_clay 7
setblock ~96 ~5 ~50 soul_sand
setblock ~97 ~5 ~34 coal_block
setblock ~97 ~5 ~36 wool 15
fill ~97 ~5 ~37 ~99 ~5 ~37 coal_block
fill ~97 ~5 ~38 ~98 ~5 ~38 stained_hardened_clay 15
fill ~97 ~5 ~39 ~98 ~5 ~39 coal_block
fill ~97 ~5 ~41 ~98 ~5 ~41 nether_brick
fill ~97 ~5 ~43 ~100 ~5 ~43 stained_hardened_clay 7
setblock ~97 ~5 ~44 soul_sand
setblock ~97 ~5 ~47 soul_sand
setblock ~98 ~5 ~34 concrete 15
setblock ~98 ~5 ~36 coal_block
setblock ~98 ~5 ~44 concrete 7
setblock ~98 ~5 ~47 stained_hardened_clay 7
setblock ~99 ~5 ~32 coal_block
setblock ~99 ~5 ~34 coal_block
setblock ~99 ~5 ~36 stained_hardened_clay 15
setblock ~99 ~5 ~38 nether_brick
setblock ~99 ~5 ~39 stained_hardened_clay 15
fill ~99 ~5 ~40 ~101 ~5 ~40 stained_hardened_clay 7
fill ~99 ~5 ~41 ~99 ~5 ~40 stained_hardened_clay 7
setblock ~99 ~5 ~42 concrete 7
setblock ~99 ~5 ~44 soul_sand
setblock ~100 ~5 ~32 concrete 15
setblock ~100 ~5 ~34 concrete 15
setblock ~100 ~5 ~36 coal_block
setblock ~100 ~5 ~37 concrete 15
setblock ~100 ~5 ~38 stained_hardened_clay 15
setblock ~100 ~5 ~39 coal_block
setblock ~100 ~5 ~41 nether_brick
fill ~100 ~5 ~42 ~101 ~5 ~42 stained_hardened_clay 7
setblock ~101 ~5 ~34 wool 15
fill ~101 ~5 ~36 ~102 ~5 ~36 wool 15
fill ~101 ~5 ~37 ~102 ~5 ~37 coal_block
setblock ~101 ~5 ~38 nether_brick
setblock ~101 ~5 ~39 stained_hardened_clay 15
setblock ~101 ~5 ~41 stained_hardened_clay 7
setblock ~102 ~5 ~34 coal_block
setblock ~102 ~5 ~38 stained_hardened_clay 15
setblock ~102 ~5 ~39 wool 15
fill ~4 ~6 ~36 ~4 ~6 ~38 concrete 15
setblock ~4 ~6 ~39 coal_block
setblock ~4 ~6 ~40 concrete 15
setblock ~4 ~6 ~41 coal_block
setblock ~4 ~6 ~42 concrete 15
setblock ~5 ~6 ~33 concrete 15
setblock ~5 ~6 ~34 coal_block
setblock ~5 ~6 ~35 concrete 15
setblock ~5 ~6 ~36 coal_block
setblock ~5 ~6 ~37 concrete 15
setblock ~5 ~6 ~38 coal_block
setblock ~5 ~6 ~39 concrete 15
setblock ~5 ~6 ~40 wool 15
setblock ~5 ~6 ~41 concrete 15
setblock ~5 ~6 ~42 wool 15
setblock ~5 ~6 ~43 coal_block
setblock ~5 ~6 ~44 wool 15
setblock ~5 ~6 ~45 coal_block
setblock ~6 ~6 ~32 concrete 15
setblock ~6 ~6 ~33 coal_block
setblock ~6 ~6 ~34 concrete 15
setblock ~6 ~6 ~35 coal_block
setblock ~6 ~6 ~36 concrete 15
setblock ~6 ~6 ~37 coal_block
setblock ~6 ~6 ~43 wool 15
setblock ~6 ~6 ~44 concrete 15
setblock ~6 ~6 ~45 stained_hardened_clay 15
setblock ~6 ~6 ~46 coal_block
setblock ~6 ~6 ~47 nether_brick
setblock ~7 ~6 ~30 wool 15
setblock ~7 ~6 ~31 concrete 15
setblock ~7 ~6 ~32 coal_block
setblock ~7 ~6 ~33 concrete 15
setblock ~7 ~6 ~34 wool 15
setblock ~7 ~6 ~46 nether_brick
setblock ~7 ~6 ~47 stained_hardened_clay 15
setblock ~7 ~6 ~48 stained_hardened_clay 7
setblock ~7 ~6 ~49 stained_hardened_clay 15
setblock ~8 ~6 ~29 coal_block
setblock ~8 ~6 ~30 concrete 15
setblock ~8 ~6 ~31 coal_block
setblock ~8 ~6 ~32 concrete 15
setblock ~8 ~6 ~48 coal_block
setblock ~8 ~6 ~49 nether_brick
setblock ~8 ~6 ~50 coal_block
setblock ~8 ~6 ~51 stained_hardened_clay 7
setblock ~9 ~6 ~29 concrete 15
setblock ~9 ~6 ~30 stained_hardened_clay 7
setblock ~9 ~6 ~31 concrete 15
setblock ~9 ~6 ~50 stained_hardened_clay 7
setblock ~9 ~6 ~51 nether_brick
setblock ~9 ~6 ~52 stained_hardened_clay 7
setblock ~10 ~6 ~28 concrete 15
setblock ~10 ~6 ~29 coal_block
setblock ~10 ~6 ~30 concrete 15
setblock ~10 ~6 ~51 stained_hardened_clay 7
setblock ~10 ~6 ~52 stained_hardened_clay 15
fill ~10 ~6 ~53 ~11 ~6 ~53 stained_hardened_clay 7
setblock ~11 ~6 ~27 concrete 15
setblock ~11 ~6 ~28 coal_block
setblock ~11 ~6 ~29 concrete 15
setblock ~11 ~6 ~30 wool 15
setblock ~11 ~6 ~52 concrete 7
setblock ~11 ~6 ~54 stained_hardened_clay 7
setblock ~11 ~6 ~55 nether_brick
setblock ~12 ~6 ~27 coal_block
setblock ~12 ~6 ~28 concrete 15
setblock ~12 ~6 ~29 coal_block
setblock ~12 ~6 ~54 stained_hardened_clay 15
fill ~12 ~6 ~55 ~13 ~6 ~55 stained_hardened_clay 7
setblock ~12 ~6 ~56 stained_hardened_clay 15
setblock ~13 ~6 ~27 concrete 15
setblock ~13 ~6 ~28 wool 15
setblock ~13 ~6 ~29 concrete 15
setblock ~13 ~6 ~56 concrete 7
fill ~13 ~6 ~57 ~15 ~6 ~57 stained_hardened_clay 7
setblock ~14 ~6 ~26 concrete 15
setblock ~14 ~6 ~27 coal_block
setblock ~14 ~6 ~28 concrete 15
setblock ~14 ~6 ~56 nether_brick
setblock ~14 ~6 ~58 stained_hardened_clay 15
setblock ~15 ~6 ~26 coal_block
setblock ~15 ~6 ~27 concrete 15
setblock ~15 ~6 ~28 coal_block
fill ~15 ~6 ~58 ~15 ~6 ~59 stained_hardened_clay 7
setblock ~16 ~6 ~26 concrete 15
setblock ~16 ~6 ~27 coal_block
setblock ~16 ~6 ~28 concrete 15
setblock ~16 ~6 ~58 stained_hardened_clay 15
fill ~16 ~6 ~59 ~17 ~6 ~59 stained_hardened_clay 7
setblock ~16 ~6 ~60 stained_hardened_clay 15
fill ~17 ~6 ~25 ~21 ~6 ~25 concrete 15
setblock ~17 ~6 ~26 coal_block
fill ~17 ~6 ~27 ~19 ~6 ~27 concrete 15
setblock ~17 ~6 ~60 stained_hardened_clay 7
setblock ~17 ~6 ~61 nether_brick
setblock ~18 ~6 ~26 concrete 15
setblock ~18 ~6 ~60 stained_hardened_clay 15
setblock ~18 ~6 ~61 stained_hardened_clay 7
setblock ~18 ~6 ~62 stained_hardened_clay 15
setblock ~19 ~6 ~26 coal_block
setblock ~19 ~6 ~61 nether_brick
setblock ~19 ~6 ~62 stained_hardened_clay 7
setblock ~19 ~6 ~63 stained_hardened_clay 15
setblock ~19 ~6 ~64 stained_hardened_clay 7
setblock ~20 ~6 ~24 concrete 15
setblock ~20 ~6 ~26 concrete 15
setblock ~20 ~6 ~62 stained_hardened_clay 15
setblock ~20 ~6 ~63 stained_hardened_clay 7
setblock ~20 ~6 ~64 coal_block
fill ~20 ~6 ~65 ~21 ~6 ~65 stained_hardened_clay 15
setblock ~21 ~6 ~24 coal_block
setblock ~21 ~6 ~26 coal_block
setblock ~21 ~6 ~64 stained_hardened_clay 7
setblock ~21 ~6 ~66 nether_brick
setblock ~22 ~6 ~24 concrete 15
setblock ~22 ~6 ~25 coal_block
setblock ~22 ~6 ~26 concrete 15
setblock ~22 ~6 ~65 stained_hardened_clay 7
setblock ~22 ~6 ~66 coal_block
setblock ~22 ~6 ~67 nether_brick
setblock ~23 ~6 ~24 coal_block
setblock ~23 ~6 ~25 concrete 15
setblock ~23 ~6 ~66 stained_hardened_clay 7
setblock ~23 ~6 ~67 stained_hardened_clay 15
setblock ~23 ~6 ~68 stained_hardened_clay 7
setblock ~23 ~6 ~69 wool 15
setblock ~24 ~6 ~23 coal_block
setblock ~24 ~6 ~24 concrete 15
fill ~24 ~6 ~25 ~25 ~6 ~25 coal_block
setblock ~24 ~6 ~68 coal_block
setblock ~24 ~6 ~69 nether_brick
setblock ~24 ~6 ~70 coal_block
setblock ~25 ~6 ~23 concrete 15
setblock ~25 ~6 ~24 wool 15
setblock ~25 ~6 ~69 stained_hardened_clay 15
setblock ~25 ~6 ~70 stained_hardened_clay 7
setblock ~25 ~6 ~71 stained_hardened_clay 15
setblock ~26 ~6 ~23 coal_block
setblock ~26 ~6 ~24 concrete 15
setblock ~26 ~6 ~70 coal_block
setblock ~26 ~6 ~71 nether_brick
setblock ~26 ~6 ~72 concrete 15
setblock ~26 ~6 ~73 stained_hardened_clay 15
setblock ~27 ~6 ~23 concrete 15
setblock ~27 ~6 ~24 coal_block
setblock ~27 ~6 ~72 nether_brick
setblock ~27 ~6 ~73 wool 15
setblock ~27 ~6 ~74 nether_brick
setblock ~28 ~6 ~23 wool 15
setblock ~28 ~6 ~24 concrete 15
setblock ~28 ~6 ~73 stained_hardened_clay 15
setblock ~28 ~6 ~74 concrete 15
setblock ~28 ~6 ~75 stained_hardened_clay 15
setblock ~29 ~6 ~22 wool 15
setblock ~29 ~6 ~23 concrete 15
setblock ~29 ~6 ~24 wool 15
setblock ~29 ~6 ~75 coal_block
setblock ~29 ~6 ~76 wool 15
setblock ~30 ~6 ~22 concrete 15
setblock ~30 ~6 ~23 wool 15
setblock ~30 ~6 ~76 concrete 15
setblock ~30 ~6 ~77 stained_hardened_clay 15
setblock ~31 ~6 ~22 wool 15
fill ~31 ~6 ~23 ~33 ~6 ~23 coal_block
setblock ~31 ~6 ~77 wool 15
setblock ~31 ~6 ~78 nether_brick
setblock ~32 ~6 ~22 concrete 15
setblock ~32 ~6 ~79 stained_hardened_clay 15
setblock ~33 ~6 ~22 wool 15
setblock ~33 ~6 ~80 stained_hardened_clay 15
setblock ~34 ~6 ~22 concrete 15
setblock ~34 ~6 ~23 wool 15
setblock ~34 ~6 ~81 wool 15
setblock ~35 ~6 ~21 concrete 15
setblock ~35 ~6 ~22 wool 15
setblock ~35 ~6 ~23 coal_block
setblock ~35 ~6 ~81 coal_block
setblock ~36 ~6 ~21 coal_block
setblock ~36 ~6 ~22 concrete 15
setblock ~36 ~6 ~82 concrete 15
setblock ~37 ~6 ~21 concrete 15
setblock ~37 ~6 ~22 wool 15
setblock ~37 ~6 ~83 coal_block
setblock ~38 ~6 ~21 coal_block
setblock ~38 ~6 ~22 concrete 15
setblock ~38 ~6 ~83 wool 15
setblock ~39 ~6 ~21 concrete 15
setblock ~39 ~6 ~22 wool 15
fill ~39 ~6 ~83 ~39 ~7 ~83 concrete 15
fill ~40 ~6 ~21 ~41 ~6 ~21 coal_block
setblock ~40 ~6 ~22 concrete 15
fill ~40 ~6 ~84 ~40 ~8 ~84 concrete 15
setblock ~41 ~6 ~22 wool 15
setblock ~41 ~6 ~84 wool 15
setblock ~42 ~6 ~21 wool 15
setblock ~42 ~6 ~22 concrete 15
fill ~42 ~6 ~84 ~42 ~8 ~84 concrete 15
fill ~43 ~6 ~21 ~44 ~6 ~21 coal_block
setblock ~43 ~6 ~22 wool 15
setblock ~43 ~6 ~84 stained_hardened_clay 15
setblock ~44 ~6 ~22 concrete 15
setblock ~45 ~6 ~21 concrete 15
setblock ~45 ~6 ~22 wool 15
fill ~45 ~6 ~85 ~45 ~8 ~85 concrete 15
setblock ~46 ~6 ~21 coal_block
setblock ~46 ~6 ~22 concrete 15
setblock ~46 ~6 ~85 coal_block
setblock ~47 ~6 ~20 wool 15
setblock ~47 ~6 ~21 concrete 15
setblock ~47 ~6 ~22 coal_block
fill ~47 ~6 ~85 ~47 ~9 ~85 concrete 15
setblock ~48 ~6 ~20 concrete 15
setblock ~48 ~6 ~21 coal_block
setblock ~48 ~6 ~85 coal_block
setblock ~49 ~6 ~20 wool 15
setblock ~49 ~6 ~21 concrete 15
fill ~49 ~6 ~85 ~49 ~8 ~85 concrete 15
setblock ~50 ~6 ~20 concrete 15
setblock ~50 ~6 ~21 coal_block
setblock ~50 ~6 ~85 coal_block
setblock ~51 ~6 ~20 wool 15
setblock ~51 ~6 ~21 concrete 15
fill ~51 ~6 ~85 ~53 ~6 ~85 concrete 15
setblock ~52 ~6 ~20 concrete 15
setblock ~52 ~6 ~21 coal_block
setblock ~53 ~6 ~20 wool 15
setblock ~53 ~6 ~21 concrete 15
setblock ~54 ~6 ~20 concrete 15
setblock ~54 ~6 ~21 coal_block
setblock ~54 ~6 ~85 coal_block
setblock ~55 ~6 ~20 coal_block
setblock ~55 ~6 ~21 concrete 15
fill ~55 ~6 ~85 ~57 ~6 ~85 concrete 15
setblock ~56 ~6 ~20 concrete 15
setblock ~56 ~6 ~21 coal_block
setblock ~57 ~6 ~20 coal_block
setblock ~57 ~6 ~21 concrete 15
setblock ~58 ~6 ~20 concrete 15
setblock ~58 ~6 ~21 coal_block
setblock ~58 ~6 ~85 coal_block
setblock ~59 ~6 ~20 wool 15
fill ~59 ~6 ~21 ~61 ~6 ~21 concrete 15
setblock ~59 ~6 ~84 coal_block
setblock ~60 ~6 ~20 concrete 15
setblock ~60 ~6 ~84 concrete 15
setblock ~61 ~6 ~20 wool 15
setblock ~61 ~6 ~84 coal_block
setblock ~62 ~6 ~20 concrete 15
setblock ~62 ~6 ~21 coal_block
fill ~62 ~6 ~84 ~62 ~10 ~84 concrete 15
setblock ~63 ~6 ~20 wool 15
fill ~63 ~6 ~21 ~65 ~6 ~21 concrete 15
setblock ~63 ~6 ~84 coal_block
setblock ~64 ~6 ~20 concrete 15
fill ~64 ~6 ~84 ~64 ~9 ~84 concrete 15
setblock ~65 ~6 ~20 coal_block
setblock ~65 ~6 ~84 wool 15
setblock ~66 ~6 ~20 concrete 15
setblock ~66 ~6 ~21 coal_block
fill ~66 ~6 ~84 ~66 ~9 ~84 concrete 15
setblock ~67 ~6 ~20 coal_block
fill ~67 ~6 ~21 ~69 ~6 ~21 concrete 15
setblock ~67 ~6 ~84 wool 15
setblock ~68 ~6 ~20 concrete 15
fill ~68 ~6 ~84 ~68 ~8 ~84 concrete 15
setblock ~69 ~6 ~20 wool 15
setblock ~69 ~6 ~83 concrete 15
setblock ~70 ~6 ~20 concrete 15
fill ~70 ~6 ~21 ~73 ~6 ~21 coal_block
fill ~70 ~6 ~83 ~72 ~6 ~83 coal_block
setblock ~71 ~6 ~20 wool 15
setblock ~72 ~6 ~20 concrete 15
setblock ~73 ~6 ~20 wool 15
setblock ~74 ~6 ~20 concrete 15
fill ~74 ~6 ~21 ~80 ~6 ~21 wool 15
fill ~74 ~6 ~82 ~74 ~7 ~82 concrete 15
setblock ~75 ~6 ~20 wool 15
setblock ~75 ~6 ~82 wool 15
setblock ~76 ~6 ~20 concrete 15
fill ~76 ~6 ~82 ~76 ~10 ~82 concrete 15
setblock ~77 ~6 ~20 wool 15
setblock ~77 ~6 ~81 concrete 15
setblock ~78 ~6 ~20 concrete 15
setblock ~78 ~6 ~22 concrete 15
setblock ~78 ~6 ~80 concrete 15
setblock ~78 ~6 ~81 wool 15
setblock ~79 ~6 ~20 nether_brick
setblock ~79 ~6 ~22 nether_brick
setblock ~79 ~6 ~80 wool 15
setblock ~80 ~6 ~22 concrete 15
setblock ~80 ~6 ~79 wool 15
fill ~80 ~6 ~80 ~80 ~8 ~80 concrete 15
setblock ~81 ~6 ~21 coal_block
setblock ~81 ~6 ~22 stained_hardened_clay 7
fill ~81 ~6 ~23 ~83 ~6 ~23 wool 15
setblock ~81 ~6 ~78 nether_brick
setblock ~81 ~6 ~79 coal_block
setblock ~82 ~6 ~21 wool 15
setblock ~82 ~6 ~22 concrete 15
setblock ~82 ~6 ~76 concrete 15
setblock ~82 ~6 ~77 stained_hardened_clay 15
setblock ~82 ~6 ~78 concrete 15
setblock ~83 ~6 ~21 coal_block
setblock ~83 ~6 ~22 nether_brick
setblock ~83 ~6 ~75 wool 15
setblock ~83 ~6 ~76 nether_brick
setblock ~83 ~6 ~77 wool 15
setblock ~84 ~6 ~22 concrete 15
setblock ~84 ~6 ~23 nether_brick
setblock ~84 ~6 ~73 stained_hardened_clay 15
setblock ~84 ~6 ~74 concrete 15
fill ~84 ~6 ~75 ~85 ~6 ~75 stained_hardened_clay 15
setblock ~84 ~6 ~76 concrete 15
fill ~85 ~6 ~22 ~85 ~6 ~24 wool 15
setblock ~85 ~6 ~71 stained_hardened_clay 15
setblock ~85 ~6 ~72 stained_hardened_clay 7
setblock ~85 ~6 ~73 wool 15
setblock ~85 ~6 ~74 nether_brick
setblock ~86 ~6 ~22 concrete 15
setblock ~86 ~6 ~23 wool 15
setblock ~86 ~6 ~24 concrete 15
setblock ~86 ~6 ~68 coal_block
setblock ~86 ~6 ~69 stained_hardened_clay 7
setblock ~86 ~6 ~70 coal_block
setblock ~86 ~6 ~71 nether_brick
setblock ~86 ~6 ~72 coal_block
setblock ~86 ~6 ~73 nether_brick
setblock ~87 ~6 ~22 wool 15
setblock ~87 ~6 ~23 coal_block
setblock ~87 ~6 ~24 wool 15
setblock ~87 ~6 ~67 nether_brick
setblock ~87 ~6 ~68 stained_hardened_clay 7
setblock ~87 ~6 ~69 stained_hardened_clay 15
setblock ~87 ~6 ~70 stained_hardened_clay 7
setblock ~87 ~6 ~71 stained_hardened_clay 15
setblock ~88 ~6 ~23 wool 15
setblock ~88 ~6 ~24 concrete 15
setblock ~88 ~6 ~25 wool 15
setblock ~88 ~6 ~64 stained_hardened_clay 15
setblock ~88 ~6 ~65 stained_hardened_clay 7
setblock ~88 ~6 ~66 stained_hardened_clay 15
setblock ~88 ~6 ~67 stained_hardened_clay 7
setblock ~88 ~6 ~68 coal_block
setblock ~88 ~6 ~69 nether_brick
setblock ~89 ~6 ~23 coal_block
setblock ~89 ~6 ~24 wool 15
setblock ~89 ~6 ~25 concrete 15
setblock ~89 ~6 ~62 concrete 7
fill ~89 ~6 ~63 ~90 ~6 ~63 stained_hardened_clay 7
fill ~89 ~6 ~64 ~89 ~6 ~63 stained_hardened_clay 7
fill ~89 ~6 ~65 ~90 ~6 ~65 nether_brick
setblock ~89 ~6 ~66 stained_hardened_clay 7
setblock ~89 ~6 ~67 nether_brick
setblock ~90 ~6 ~23 wool 15
setblock ~90 ~6 ~24 concrete 15
setblock ~90 ~6 ~25 wool 15
setblock ~90 ~6 ~60 stained_hardened_clay 7
setblock ~90 ~6 ~61 concrete 7
setblock ~90 ~6 ~62 stained_hardened_clay 15
setblock ~90 ~6 ~64 stained_hardened_clay 15
setblock ~90 ~6 ~66 coal_block
setblock ~91 ~6 ~24 wool 15
fill ~91 ~6 ~25 ~92 ~6 ~25 coal_block
setblock ~91 ~6 ~26 wool 15
setblock ~91 ~6 ~58 soul_sand
setblock ~91 ~6 ~59 stained_hardened_clay 12
setblock ~91 ~6 ~60 soul_sand
fill ~91 ~6 ~61 ~92 ~6 ~61 stained_hardened_clay 7
fill ~91 ~6 ~62 ~91 ~6 ~61 stained_hardened_clay 7
setblock ~91 ~6 ~63 nether_brick
setblock ~91 ~6 ~64 stained_hardened_clay 7
setblock ~92 ~6 ~24 concrete 15
setblock ~92 ~6 ~26 concrete 15
setblock ~92 ~6 ~57 soul_sand
setblock ~92 ~6 ~58 stained_hardened_clay 7
setblock ~92 ~6 ~59 soul_sand
setblock ~92 ~6 ~60 nether_brick
setblock ~92 ~6 ~62 coal_block
setblock ~93 ~6 ~24 coal_block
setblock ~93 ~6 ~25 concrete 15
setblock ~93 ~6 ~26 coal_block
fill ~93 ~6 ~27 ~95 ~6 ~27 concrete 15
fill ~93 ~6 ~55 ~96 ~6 ~55 soul_sand
setblock ~93 ~6 ~56 bedrock
setblock ~93 ~6 ~57 stained_hardened_clay 12
setblock ~93 ~6 ~58 soul_sand
fill ~93 ~6 ~59 ~93 ~6 ~60 stained_hardened_clay 7
setblock ~94 ~6 ~25 coal_block
setblock ~94 ~6 ~26 concrete 15
setblock ~94 ~6 ~53 bedrock
setblock ~94 ~6 ~54 soul_sand
setblock ~94 ~6 ~56 stained_hardened_clay 7
setblock ~94 ~6 ~57 soul_sand
setblock ~94 ~6 ~58 nether_brick
fill ~95 ~6 ~25 ~96 ~6 ~25 concrete 15
setblock ~95 ~6 ~26 coal_block
setblock ~95 ~6 ~28 coal_block
setblock ~95 ~6 ~52 bedrock
fill ~95 ~6 ~53 ~97 ~6 ~53 soul_sand
setblock ~95 ~6 ~54 bedrock
setblock ~95 ~6 ~56 soul_sand
setblock ~95 ~6 ~57 stained_hardened_clay 7
setblock ~96 ~6 ~26 concrete 15
setblock ~96 ~6 ~27 coal_block
setblock ~96 ~6 ~28 concrete 15
setblock ~96 ~6 ~51 bedrock
setblock ~96 ~6 ~52 soul_sand
setblock ~96 ~6 ~54 stained_hardened_clay 7
setblock ~97 ~6 ~26 wool 15
setblock ~97 ~6 ~27 concrete 15
setblock ~97 ~6 ~28 coal_block
setblock ~97 ~6 ~29 concrete 15
setblock ~97 ~6 ~49 soul_sand
setblock ~97 ~6 ~50 bedrock
fill ~97 ~6 ~51 ~98 ~6 ~51 soul_sand
setblock ~97 ~6 ~52 bedrock
setblock ~97 ~6 ~54 soul_sand
setblock ~98 ~6 ~26 concrete 15
setblock ~98 ~6 ~27 coal_block
setblock ~98 ~6 ~28 concrete 15
setblock ~98 ~6 ~29 coal_block
setblock ~98 ~6 ~30 concrete 15
setblock ~98 ~6 ~48 soul_sand
setblock ~98 ~6 ~49 bedrock
setblock ~98 ~6 ~50 stained_hardened_clay 12
setblock ~98 ~6 ~52 stained_hardened_clay 7
setblock ~99 ~6 ~26 wool 15
setblock ~99 ~6 ~27 concrete 15
setblock ~99 ~6 ~28 wool 15
setblock ~99 ~6 ~29 concrete 15
setblock ~99 ~6 ~30 wool 15
setblock ~99 ~6 ~46 bedrock
fill ~99 ~6 ~47 ~100 ~6 ~47 soul_sand
setblock ~99 ~6 ~48 bedrock
fill ~99 ~6 ~49 ~100 ~6 ~49 soul_sand
fill ~99 ~6 ~50 ~99 ~6 ~49 soul_sand
setblock ~99 ~6 ~51 stained_hardened_clay 7
setblock ~100 ~6 ~27 wool 15
setblock ~100 ~6 ~28 concrete 15
setblock ~100 ~6 ~29 coal_block
setblock ~100 ~6 ~30 concrete 15
setblock ~100 ~6 ~31 wool 15
setblock ~100 ~6 ~44 stained_hardened_clay 7
setblock ~100 ~6 ~45 soul_sand
setblock ~100 ~6 ~46 stained_hardened_clay 7
setblock ~100 ~6 ~48 stained_hardened_clay 7
setblock ~101 ~6 ~27 coal_block
setblock ~101 ~6 ~28 wool 15
setblock ~101 ~6 ~29 concrete 15
setblock ~101 ~6 ~30 stained_hardened_clay 15
setblock ~101 ~6 ~31 coal_block
setblock ~101 ~6 ~32 wool 15
fill ~101 ~6 ~43 ~102 ~6 ~43 concrete 7
setblock ~101 ~6 ~44 soul_sand
setblock ~101 ~6 ~45 stained_hardened_clay 7
setblock ~101 ~6 ~46 soul_sand
setblock ~101 ~6 ~47 stained_hardened_clay 7
setblock ~101 ~6 ~48 soul_sand
setblock ~102 ~6 ~28 concrete 15
setblock ~102 ~6 ~29 wool 15
setblock ~102 ~6 ~30 concrete 15
setblock ~102 ~6 ~31 wool 15
setblock ~102 ~6 ~32 concrete 15
setblock ~102 ~6 ~33 wool 15
setblock ~102 ~6 ~40 nether_brick
setblock ~102 ~6 ~41 concrete 7
setblock ~102 ~6 ~42 nether_brick
setblock ~102 ~6 ~44 nether_brick
setblock ~102 ~6 ~45 concrete 7
setblock ~102 ~6 ~46 nether_brick
setblock ~103 ~6 ~29 coal_block
setblock ~103 ~6 ~30 wool 15
setblock ~103 ~6 ~31 coal_block
setblock ~103 ~6 ~32 wool 15
setblock ~103 ~6 ~33 coal_block
setblock ~103 ~6 ~34 wool 15
setblock ~103 ~6 ~35 coal_block
setblock ~103 ~6 ~36 nether_brick
fill ~103 ~6 ~37 ~104 ~6 ~37 stained_hardened_clay 15
setblock ~103 ~6 ~38 stained_hardened_clay 7
fill ~103 ~6 ~39 ~104 ~6 ~39 nether_brick
setblock ~103 ~6 ~40 stained_hardened_clay 7
setblock ~103 ~6 ~41 nether_brick
setblock ~103 ~6 ~42 stained_hardened_clay 7
setblock ~103 ~6 ~43 nether_brick
fill ~103 ~6 ~44 ~103 ~6 ~45 stained_hardened_clay 7
setblock ~104 ~6 ~31 wool 15
setblock ~104 ~6 ~32 concrete 15
setblock ~104 ~6 ~33 wool 15
setblock ~104 ~6 ~34 concrete 15
setblock ~104 ~6 ~35 wool 15
setblock ~104 ~6 ~36 concrete 15
setblock ~104 ~6 ~38 coal_block
setblock ~104 ~6 ~40 coal_block
setblock ~104 ~6 ~41 stained_hardened_clay 7
setblock ~104 ~6 ~42 coal_block
setblock ~104 ~6 ~43 stained_hardened_clay 7
setblock ~105 ~6 ~33 concrete 15
setblock ~105 ~6 ~34 wool 15
setblock ~105 ~6 ~35 coal_block
setblock ~105 ~6 ~36 stained_hardened_clay 15
setblock ~105 ~6 ~37 coal_block
setblock ~105 ~6 ~38 nether_brick
setblock ~105 ~6 ~39 wool 15
setblock ~105 ~6 ~40 stained_hardened_clay 7
fill ~3 ~7 ~34 ~4 ~7 ~34 concrete 15
fill ~3 ~7 ~35 ~4 ~7 ~35 concrete 15
fill ~3 ~7 ~36 ~3 ~7 ~41 concrete 15
setblock ~3 ~7 ~42 coal_block
fill ~3 ~7 ~43 ~4 ~7 ~43 concrete 15
fill ~4 ~7 ~32 ~5 ~7 ~32 concrete 15
fill ~4 ~7 ~33 ~4 ~7 ~32 concrete 15
fill ~4 ~7 ~44 ~4 ~7 ~45 concrete 15
setblock ~4 ~7 ~46 coal_block
fill ~5 ~7 ~30 ~6 ~7 ~30 concrete 15
fill ~5 ~7 ~31 ~6 ~7 ~31 concrete 15
setblock ~5 ~7 ~46 wool 15
setblock ~5 ~7 ~47 coal_block
setblock ~5 ~7 ~48 stained_hardened_clay 15
fill ~6 ~7 ~29 ~7 ~7 ~29 concrete 15
setblock ~6 ~7 ~48 coal_block
setblock ~6 ~7 ~49 concrete 15
setblock ~6 ~7 ~50 wool 15
fill ~7 ~7 ~28 ~9 ~7 ~28 concrete 15
setblock ~7 ~7 ~50 nether_brick
setblock ~7 ~7 ~51 coal_block
setblock ~7 ~7 ~52 nether_brick
fill ~8 ~7 ~27 ~10 ~7 ~27 concrete 15
setblock ~8 ~7 ~52 stained_hardened_clay 15
setblock ~8 ~7 ~53 coal_block
fill ~9 ~7 ~26 ~13 ~7 ~26 concrete 15
setblock ~9 ~7 ~53 stained_hardened_clay 15
setblock ~9 ~7 ~54 stained_hardened_clay 7
setblock ~10 ~7 ~54 nether_brick
setblock ~10 ~7 ~55 coal_block
setblock ~10 ~7 ~56 stained_hardened_clay 15
fill ~11 ~7 ~25 ~16 ~7 ~25 concrete 15
setblock ~11 ~7 ~56 stained_hardened_clay 7
setblock ~11 ~7 ~57 stained_hardened_clay 15
setblock ~12 ~7 ~57 coal_block
setblock ~12 ~7 ~58 stained_hardened_clay 15
fill ~13 ~7 ~24 ~19 ~7 ~24 concrete 15
setblock ~13 ~7 ~58 stained_hardened_clay 7
setblock ~13 ~7 ~59 stained_hardened_clay 15
setblock ~14 ~7 ~59 coal_block
setblock ~14 ~7 ~60 stained_hardened_clay 15
fill ~15 ~7 ~23 ~23 ~7 ~23 concrete 15
setblock ~15 ~7 ~60 stained_hardened_clay 7
fill ~15 ~7 ~61 ~16 ~7 ~61 coal_block
setblock ~16 ~7 ~62 stained_hardened_clay 15
setblock ~17 ~7 ~62 nether_brick
fill ~17 ~7 ~63 ~18 ~7 ~63 coal_block
setblock ~17 ~7 ~64 stained_hardened_clay 15
setblock ~18 ~7 ~64 coal_block
setblock ~18 ~7 ~65 concrete 15
fill ~19 ~7 ~22 ~26 ~7 ~22 concrete 15
setblock ~19 ~7 ~65 coal_block
setblock ~19 ~7 ~66 stained_hardened_clay 15
setblock ~20 ~7 ~66 coal_block
setblock ~20 ~7 ~67 concrete 15
setblock ~21 ~7 ~67 coal_block
setblock ~21 ~7 ~68 wool 15
setblock ~22 ~7 ~68 coal_block
setblock ~22 ~7 ~69 concrete 15
setblock ~22 ~7 ~70 coal_block
fill ~23 ~7 ~21 ~34 ~7 ~21 concrete 15
setblock ~23 ~7 ~70 stained_hardened_clay 15
setblock ~23 ~7 ~71 coal_block
setblock ~24 ~7 ~71 concrete 15
setblock ~24 ~7 ~72 coal_block
setblock ~25 ~7 ~72 wool 15
setblock ~25 ~7 ~73 coal_block
setblock ~26 ~7 ~74 coal_block
setblock ~26 ~7 ~75 concrete 15
setblock ~27 ~7 ~22 coal_block
setblock ~27 ~7 ~75 coal_block
fill ~27 ~7 ~76 ~27 ~8 ~76 stained_hardened_clay 15
setblock ~28 ~7 ~20 concrete 15
setblock ~28 ~7 ~22 concrete 15
setblock ~28 ~7 ~76 coal_block
setblock ~28 ~7 ~77 concrete 15
setblock ~29 ~7 ~20 coal_block
setblock ~29 ~7 ~77 coal_block
setblock ~29 ~7 ~78 wool 15
fill ~30 ~7 ~20 ~32 ~7 ~20 concrete 15
setblock ~30 ~7 ~78 coal_block
setblock ~31 ~7 ~79 concrete 15
setblock ~32 ~7 ~80 coal_block
setblock ~33 ~7 ~20 coal_block
fill ~33 ~7 ~81 ~34 ~7 ~81 concrete 15
fill ~34 ~7 ~20 ~36 ~7 ~20 concrete 15
fill ~35 ~7 ~82 ~36 ~7 ~82 coal_block
fill ~37 ~7 ~19 ~46 ~7 ~19 concrete 15
setblock ~37 ~7 ~20 coal_block
fill ~37 ~7 ~83 ~39 ~7 ~83 concrete 15
setblock ~38 ~7 ~20 concrete 15
setblock ~39 ~7 ~20 coal_block
setblock ~40 ~7 ~20 concrete 15
setblock ~41 ~7 ~20 wool 15
setblock ~41 ~7 ~84 coal_block
setblock ~42 ~7 ~20 concrete 15
setblock ~43 ~7 ~20 coal_block
setblock ~43 ~7 ~84 coal_block
setblock ~44 ~7 ~20 concrete 15
setblock ~44 ~7 ~85 concrete 15
setblock ~45 ~7 ~20 coal_block
setblock ~46 ~7 ~20 concrete 15
setblock ~46 ~7 ~85 concrete 15
setblock ~47 ~7 ~19 coal_block
setblock ~48 ~7 ~18 coal_block
fill ~48 ~7 ~19 ~76 ~7 ~19 concrete 15
setblock ~48 ~7 ~85 concrete 15
setblock ~49 ~7 ~18 wool 15
setblock ~50 ~7 ~18 concrete 15
fill ~50 ~7 ~85 ~60 ~7 ~85 concrete 15
setblock ~51 ~7 ~18 coal_block
fill ~52 ~7 ~18 ~58 ~7 ~18 concrete 15
setblock ~59 ~7 ~18 coal_block
setblock ~60 ~7 ~18 concrete 15
fill ~61 ~7 ~18 ~62 ~7 ~18 coal_block
fill ~61 ~7 ~84 ~61 ~9 ~84 concrete 15
setblock ~63 ~7 ~18 wool 15
setblock ~63 ~7 ~84 concrete 15
setblock ~64 ~7 ~18 coal_block
setblock ~65 ~7 ~18 stained_hardened_clay 15
setblock ~65 ~7 ~84 concrete 15
setblock ~66 ~7 ~18 coal_block
setblock ~67 ~7 ~18 wool 15
setblock ~67 ~7 ~84 concrete 15
setblock ~68 ~7 ~18 coal_block
setblock ~69 ~7 ~18 wool 15
setblock ~69 ~7 ~84 concrete 15
fill ~70 ~7 ~18 ~71 ~7 ~18 coal_block
fill ~70 ~7 ~83 ~73 ~7 ~83 concrete 15
setblock ~72 ~7 ~18 concrete 15
setblock ~73 ~7 ~18 wool 15
setblock ~74 ~7 ~18 concrete 15
fill ~75 ~7 ~18 ~76 ~7 ~18 coal_block
setblock ~75 ~7 ~82 coal_block
setblock ~77 ~7 ~18 wool 15
setblock ~77 ~7 ~19 coal_block
setblock ~77 ~7 ~82 coal_block
setblock ~78 ~7 ~18 coal_block
fill ~78 ~7 ~19 ~84 ~7 ~19 concrete 15
fill ~78 ~7 ~81 ~79 ~7 ~81 concrete 15
setblock ~79 ~7 ~18 wool 15
setblock ~80 ~7 ~18 concrete 15
setblock ~80 ~7 ~20 coal_block
setblock ~81 ~7 ~20 wool 15
setblock ~81 ~7 ~80 coal_block
setblock ~82 ~7 ~20 concrete 15
setblock ~82 ~7 ~79 concrete 15
setblock ~83 ~7 ~20 coal_block
setblock ~83 ~7 ~78 coal_block
fill ~84 ~7 ~20 ~84 ~7 ~21 concrete 15
setblock ~84 ~7 ~77 concrete 15
setblock ~85 ~7 ~20 coal_block
fill ~85 ~7 ~21 ~93 ~7 ~21 concrete 15
setblock ~85 ~7 ~76 coal_block
setblock ~86 ~7 ~20 concrete 15
setblock ~86 ~7 ~74 coal_block
setblock ~86 ~7 ~75 concrete 15
setblock ~87 ~7 ~20 coal_block
setblock ~87 ~7 ~72 stained_hardened_clay 15
setblock ~87 ~7 ~73 coal_block
setblock ~87 ~7 ~74 stained_hardened_clay 15
fill ~88 ~7 ~20 ~89 ~7 ~20 concrete 15
fill ~88 ~7 ~22 ~97 ~7 ~22 concrete 15
fill ~88 ~7 ~70 ~88 ~7 ~71 coal_block
setblock ~88 ~7 ~72 wool 15
setblock ~88 ~7 ~73 concrete 15
setblock ~89 ~7 ~68 nether_brick
setblock ~89 ~7 ~69 coal_block
setblock ~89 ~7 ~70 stained_hardened_clay 15
setblock ~89 ~7 ~71 coal_block
fill ~90 ~7 ~67 ~91 ~7 ~67 coal_block
fill ~90 ~7 ~68 ~90 ~7 ~67 coal_block
setblock ~90 ~7 ~69 concrete 15
fill ~91 ~7 ~23 ~100 ~7 ~23 concrete 15
setblock ~91 ~7 ~65 coal_block
setblock ~91 ~7 ~66 stained_hardened_clay 15
fill ~92 ~7 ~63 ~93 ~7 ~63 coal_block
fill ~92 ~7 ~64 ~92 ~7 ~63 coal_block
setblock ~92 ~7 ~65 concrete 15
setblock ~92 ~7 ~66 coal_block
fill ~93 ~7 ~61 ~93 ~7 ~62 stained_hardened_clay 15
setblock ~93 ~7 ~64 stained_hardened_clay 15
fill ~94 ~7 ~24 ~98 ~7 ~24 concrete 15
fill ~94 ~7 ~59 ~95 ~7 ~59 stained_hardened_clay 15
fill ~94 ~7 ~60 ~94 ~7 ~59 stained_hardened_clay 15
fill ~94 ~7 ~61 ~95 ~7 ~61 coal_block
setblock ~94 ~7 ~62 wool 15
setblock ~95 ~7 ~58 stained_hardened_clay 7
setblock ~95 ~7 ~60 nether_brick
fill ~96 ~7 ~56 ~97 ~7 ~56 stained_hardened_clay 7
fill ~96 ~7 ~57 ~97 ~7 ~57 stained_hardened_clay 15
fill ~96 ~7 ~58 ~96 ~7 ~57 stained_hardened_clay 15
setblock ~96 ~7 ~59 coal_block
fill ~97 ~7 ~25 ~103 ~7 ~25 concrete 15
setblock ~97 ~7 ~55 stained_hardened_clay 7
setblock ~98 ~7 ~53 nether_brick
fill ~98 ~7 ~54 ~99 ~7 ~54 stained_hardened_clay 7
setblock ~98 ~7 ~55 stained_hardened_clay 15
setblock ~98 ~7 ~56 nether_brick
setblock ~99 ~7 ~24 coal_block
fill ~99 ~7 ~52 ~101 ~7 ~52 stained_hardened_clay 7
fill ~99 ~7 ~53 ~99 ~7 ~52 stained_hardened_clay 7
fill ~100 ~7 ~24 ~101 ~7 ~24 concrete 15
fill ~100 ~7 ~26 ~102 ~7 ~26 concrete 15
fill ~100 ~7 ~50 ~102 ~7 ~50 stained_hardened_clay 7
setblock ~100 ~7 ~51 nether_brick
setblock ~100 ~7 ~53 stained_hardened_clay 15
setblock ~101 ~7 ~49 stained_hardened_clay 7
setblock ~101 ~7 ~51 stained_hardened_clay 7
fill ~102 ~7 ~27 ~105 ~7 ~27 concrete 15
setblock ~102 ~7 ~47 stained_hardened_clay 15
fill ~102 ~7 ~48 ~103 ~7 ~48 stained_hardened_clay 7
setblock ~102 ~7 ~49 stained_hardened_clay 15
setblock ~103 ~7 ~26 coal_block
setblock ~103 ~7 ~28 coal_block
setblock ~103 ~7 ~46 stained_hardened_clay 7
setblock ~103 ~7 ~47 nether_brick
setblock ~104 ~7 ~26 concrete 15
