setblock ~100 ~0 ~12 concrete 0
setblock ~100 ~0 ~13 stone 4
setblock ~101 ~0 ~12 stone 3
setblock ~101 ~0 ~13 concrete 0
setblock ~102 ~0 ~12 concrete 0
fill ~102 ~0 ~13 ~104 ~0 ~13 stone 4
setblock ~103 ~0 ~12 stone 3
setblock ~104 ~0 ~12 concrete 0
setblock ~105 ~0 ~12 stone 3
setblock ~105 ~0 ~13 concrete 0
setblock ~106 ~0 ~12 concrete 0
setblock ~106 ~0 ~13 stone 4
setblock ~107 ~0 ~12 stone 3
setblock ~108 ~0 ~12 concrete 0
setblock ~109 ~0 ~12 stone 3
setblock ~110 ~0 ~12 concrete 0
setblock ~95 ~1 ~13 clay 0
fill ~96 ~1 ~13 ~97 ~1 ~13 stone 3
setblock ~110 ~1 ~12 stone 4
setblock ~111 ~1 ~12 stone 3
setblock ~112 ~1 ~12 stone 4
setblock ~93 ~2 ~13 concrete 0
setblock ~94 ~2 ~13 stone 4
setblock ~95 ~2 ~13 concrete 0
setblock ~113 ~2 ~12 stone 3
setblock ~92 ~3 ~13 stone 3
setblock ~92 ~3 ~14 stone 4
setblock ~115 ~3 ~12 stone 4
setblock ~115 ~3 ~13 stone 3
setblock ~89 ~4 ~14 stone 3
setblock ~90 ~4 ~14 concrete 0
setblock ~116 ~4 ~13 stone 4
setblock ~117 ~4 ~13 concrete 0
setblock ~88 ~5 ~15 stone 3
setblock ~117 ~5 ~13 stone 3
setblock ~117 ~5 ~14 stone 4
setblock ~86 ~6 ~16 concrete 0
setblock ~87 ~6 ~15 stone 4
setblock ~87 ~6 ~16 stone 3
setblock ~99 ~6 ~54 stone 3
setblock ~100 ~6 ~54 concrete 0
setblock ~101 ~6 ~55 concrete 0
fill ~102 ~6 ~55 ~103 ~6 ~55 stone 4
setblock ~105 ~6 ~56 stone 3
setblock ~106 ~6 ~56 concrete 0
setblock ~108 ~6 ~56 concrete 0
setblock ~108 ~6 ~57 stone 4
setblock ~109 ~6 ~57 concrete 0
setblock ~110 ~6 ~57 stone 4
setblock ~118 ~6 ~14 concrete 0
fill ~85 ~7 ~17 ~86 ~7 ~17 stone 3
setblock ~86 ~7 ~16 stone 4
setblock ~98 ~7 ~53 stone 3
fill ~98 ~7 ~54 ~100 ~7 ~54 stone 4
setblock ~113 ~7 ~57 stone 3
fill ~113 ~7 ~58 ~115 ~7 ~58 stone 4
setblock ~119 ~7 ~15 stone 3
setblock ~85 ~8 ~17 concrete 0
setblock ~85 ~8 ~18 stone 3
setblock ~96 ~8 ~52 concrete 0
setblock ~97 ~8 ~52 stone 3
setblock ~115 ~8 ~58 stone 3
setblock ~116 ~8 ~58 concrete 0
setblock ~117 ~8 ~58 stone 3
setblock ~118 ~8 ~58 concrete 0
setblock ~119 ~8 ~15 concrete 0
setblock ~84 ~9 ~18 stone 4
setblock ~84 ~9 ~19 stone 3
fill ~95 ~9 ~50 ~95 ~9 ~51 stone 3
setblock ~118 ~9 ~58 stone 4
setblock ~119 ~9 ~58 stone 3
setblock ~120 ~9 ~16 stone 4
setblock ~120 ~9 ~58 stone 4
setblock ~94 ~10 ~49 stone 4
setblock ~122 ~10 ~57 stone 4
setblock ~123 ~10 ~57 concrete 0
setblock ~83 ~11 ~20 stone 4
setblock ~93 ~11 ~47 stone 3
setblock ~121 ~11 ~17 stone 3
setblock ~123 ~11 ~57 stone 3
fill ~124 ~11 ~56 ~125 ~11 ~56 stone 4
fill ~82 ~12 ~21 ~83 ~12 ~21 stone 4
setblock ~93 ~12 ~45 concrete 0
setblock ~93 ~12 ~46 stone 3
setblock ~121 ~12 ~18 stone 3
setblock ~122 ~12 ~18 concrete 0
setblock ~126 ~12 ~55 stone 4
fill ~127 ~12 ~54 ~127 ~13 ~54 stone 3
setblock ~19 ~13 ~21 nether_brick 0
setblock ~19 ~13 ~22 log2 1
fill ~20 ~13 ~21 ~21 ~13 ~21 stained_hardened_clay 7
setblock ~20 ~13 ~22 soul_sand 0
fill ~20 ~13 ~23 ~22 ~13 ~23 stained_hardened_clay 7
setblock ~20 ~13 ~24 soul_sand 0
fill ~20 ~13 ~25 ~22 ~13 ~25 stained_hardened_clay 7
setblock ~21 ~13 ~22 stained_hardened_clay 7
fill ~21 ~13 ~24 ~22 ~13 ~24 stained_hardened_clay 7
fill ~21 ~13 ~26 ~21 ~13 ~27 stained_hardened_clay 7
setblock ~22 ~13 ~26 soul_sand 0
setblock ~22 ~13 ~27 stained_hardened_clay 7
setblock ~22 ~13 ~28 stained_hardened_clay 12
setblock ~82 ~13 ~22 stone 4
fill ~92 ~13 ~44 ~93 ~13 ~44 stone 4
setblock ~99 ~13 ~39 clay 0
setblock ~122 ~13 ~19 stone 3
setblock ~125 ~13 ~21 clay 0
setblock ~126 ~13 ~21 sea_lantern 0
setblock ~127 ~13 ~21 clay 0
setblock ~128 ~13 ~53 stone 3
setblock ~129 ~13 ~52 stone 4
setblock ~18 ~14 ~21 stained_hardened_clay 12
setblock ~18 ~14 ~22 soul_sand 0
fill ~19 ~14 ~20 ~19 ~15 ~20 stained_hardened_clay 7
setblock ~19 ~14 ~23 soul_sand 0
setblock ~19 ~14 ~24 stained_hardened_clay 7
setblock ~19 ~14 ~25 soul_sand 0
setblock ~20 ~14 ~20 soul_sand 0
fill ~20 ~14 ~26 ~20 ~14 ~27 soul_sand 0
fill ~21 ~14 ~20 ~21 ~17 ~20 stained_hardened_clay 7
setblock ~21 ~14 ~28 stained_hardened_clay 7
setblock ~21 ~14 ~29 soul_sand 0
setblock ~21 ~14 ~30 stained_hardened_clay 7
fill ~22 ~14 ~21 ~22 ~14 ~22 soul_sand 0
fill ~22 ~14 ~29 ~23 ~14 ~29 stained_hardened_clay 12
setblock ~22 ~14 ~30 soul_sand 0
fill ~22 ~14 ~31 ~23 ~14 ~31 stained_hardened_clay 12
setblock ~22 ~14 ~32 soul_sand 0
setblock ~23 ~14 ~23 stained_hardened_clay 7
setblock ~23 ~14 ~24 nether_brick 0
setblock ~23 ~14 ~25 stained_hardened_clay 12
setblock ~23 ~14 ~26 nether_brick 0
setblock ~23 ~14 ~27 soul_sand 0
setblock ~23 ~14 ~28 stained_hardened_clay 7
setblock ~23 ~14 ~30 stained_hardened_clay 7
setblock ~23 ~14 ~32 stained_hardened_clay 7
setblock ~23 ~14 ~33 soul_sand 0
setblock ~82 ~14 ~22 concrete 0
setblock ~82 ~14 ~23 stone 4
setblock ~89 ~14 ~37 white_glazed_terracotta 0
fill ~90 ~14 ~37 ~90 ~15 ~37 sea_lantern 0
setblock ~91 ~14 ~38 clay 0
setblock ~92 ~14 ~38 sea_lantern 0
setblock ~92 ~14 ~41 stone 4
setblock ~92 ~14 ~42 concrete 0
setblock ~93 ~14 ~38 clay 0
setblock ~93 ~14 ~42 stone 3
fill ~94 ~14 ~38 ~94 ~16 ~38 white_glazed_terracotta 0
setblock ~95 ~14 ~38 clay 0
fill ~96 ~14 ~38 ~96 ~15 ~38 sea_lantern 0
setblock ~97 ~14 ~38 clay 0
fill ~98 ~14 ~39 ~100 ~14 ~39 sea_lantern 0
setblock ~101 ~14 ~39 concrete 0
fill ~102 ~14 ~39 ~103 ~14 ~39 sea_lantern 0
setblock ~104 ~14 ~40 white_glazed_terracotta 0
setblock ~105 ~14 ~40 clay 0
setblock ~106 ~14 ~40 wool 0
setblock ~107 ~14 ~40 sea_lantern 0
setblock ~108 ~14 ~41 stone 4
fill ~109 ~14 ~22 ~109 ~15 ~22 sea_lantern 0
fill ~109 ~14 ~41 ~109 ~16 ~41 white_glazed_terracotta 0
setblock ~110 ~14 ~22 white_glazed_terracotta 0
setblock ~110 ~14 ~41 sea_lantern 0
setblock ~111 ~14 ~22 clay 0
setblock ~111 ~14 ~41 white_glazed_terracotta 0
setblock ~112 ~14 ~22 white_glazed_terracotta 0
setblock ~112 ~14 ~42 concrete 0
setblock ~113 ~14 ~22 sea_lantern 0
fill ~113 ~14 ~42 ~113 ~15 ~42 sea_lantern 0
setblock ~114 ~14 ~22 concrete 0
fill ~114 ~14 ~42 ~114 ~16 ~42 white_glazed_terracotta 0
fill ~115 ~14 ~21 ~117 ~14 ~21 concrete 0
fill ~115 ~14 ~42 ~115 ~15 ~42 sea_lantern 0
setblock ~116 ~14 ~42 concrete 0
setblock ~117 ~14 ~42 clay 0
fill ~118 ~14 ~21 ~119 ~14 ~21 white_glazed_terracotta 0
fill ~118 ~14 ~42 ~118 ~15 ~42 concrete 0
setblock ~119 ~14 ~43 white_glazed_terracotta 0
setblock ~120 ~14 ~21 sea_lantern 0
fill ~120 ~14 ~43 ~121 ~14 ~43 sea_lantern 0
setblock ~121 ~14 ~21 white_glazed_terracotta 0
setblock ~122 ~14 ~19 stone 4
fill ~122 ~14 ~21 ~122 ~15 ~21 sea_lantern 0
fill ~122 ~14 ~43 ~123 ~14 ~43 white_glazed_terracotta 0
setblock ~123 ~14 ~21 concrete 0
fill ~124 ~14 ~21 ~127 ~14 ~21 white_glazed_terracotta 0
setblock ~124 ~14 ~43 sea_lantern 0
setblock ~125 ~14 ~43 white_glazed_terracotta 0
fill ~126 ~14 ~43 ~128 ~14 ~43 sea_lantern 0
setblock ~129 ~14 ~43 white_glazed_terracotta 0
setblock ~129 ~14 ~52 stone 3
setblock ~130 ~14 ~43 sea_lantern 0
setblock ~130 ~14 ~51 stone 4
setblock ~17 ~15 ~21 log2 1
setblock ~18 ~15 ~20 soul_sand 0
setblock ~18 ~15 ~22 stained_hardened_clay 12
setblock ~18 ~15 ~23 stained_hardened_clay 7
fill ~18 ~15 ~24 ~18 ~16 ~24 soul_sand 0
fill ~19 ~15 ~25 ~19 ~15 ~26 stained_hardened_clay 7
setblock ~19 ~15 ~27 nether_brick 0
fill ~20 ~15 ~20 ~20 ~16 ~20 stained_hardened_clay 12
setblock ~20 ~15 ~28 soul_sand 0
setblock ~20 ~15 ~29 stained_hardened_clay 7
fill ~20 ~15 ~30 ~20 ~16 ~30 soul_sand 0
fill ~21 ~15 ~31 ~21 ~15 ~32 stained_hardened_clay 7
setblock ~22 ~15 ~21 stained_hardened_clay 7
setblock ~22 ~15 ~33 stained_hardened_clay 7
setblock ~22 ~15 ~34 soul_sand 0
fill ~22 ~15 ~35 ~24 ~15 ~35 stained_hardened_clay 7
setblock ~23 ~15 ~22 stained_hardened_clay 7
setblock ~23 ~15 ~23 nether_brick 0
setblock ~23 ~15 ~24 stained_hardened_clay 7
setblock ~23 ~15 ~34 stained_hardened_clay 7
setblock ~23 ~15 ~36 stained_hardened_clay 7
setblock ~24 ~15 ~25 stained_hardened_clay 15
setblock ~24 ~15 ~26 stained_hardened_clay 12
setblock ~24 ~15 ~27 nether_brick 0
setblock ~24 ~15 ~28 stained_hardened_clay 7
setblock ~24 ~15 ~29 nether_brick 0
fill ~24 ~15 ~30 ~24 ~15 ~31 stained_hardened_clay 7
fill ~24 ~15 ~32 ~24 ~16 ~32 stained_hardened_clay 12
setblock ~24 ~15 ~33 stained_hardened_clay 7
fill ~24 ~15 ~34 ~24 ~16 ~34 stained_hardened_clay 12
setblock ~82 ~15 ~23 stone 3
fill ~88 ~15 ~25 ~88 ~16 ~25 sea_lantern 0
setblock ~89 ~15 ~25 clay 0
setblock ~89 ~15 ~37 sea_lantern 0
setblock ~90 ~15 ~24 white_glazed_terracotta 0
setblock ~91 ~15 ~24 sea_lantern 0
fill ~91 ~15 ~37 ~91 ~16 ~37 sea_lantern 0
setblock ~92 ~15 ~24 white_glazed_terracotta 0
setblock ~92 ~15 ~37 white_glazed_terracotta 0
setblock ~92 ~15 ~40 stone 4
setblock ~92 ~15 ~41 stone 3
fill ~93 ~15 ~24 ~94 ~15 ~24 sea_lantern 0
setblock ~93 ~15 ~38 white_glazed_terracotta 0
fill ~95 ~15 ~23 ~96 ~15 ~23 sea_lantern 0
setblock ~95 ~15 ~38 sea_lantern 0
fill ~97 ~15 ~23 ~97 ~16 ~23 stone 4
setblock ~97 ~15 ~38 sea_lantern 0
setblock ~98 ~15 ~23 white_glazed_terracotta 0
fill ~98 ~15 ~38 ~98 ~16 ~38 white_glazed_terracotta 0
setblock ~99 ~15 ~23 clay 0
fill ~99 ~15 ~39 ~101 ~15 ~39 clay 0
fill ~100 ~15 ~23 ~101 ~15 ~23 sea_lantern 0
fill ~102 ~15 ~23 ~104 ~15 ~23 clay 0
fill ~102 ~15 ~39 ~102 ~14 ~39 sea_lantern 0
setblock ~103 ~15 ~39 clay 0
setblock ~104 ~15 ~40 sea_lantern 0
setblock ~105 ~15 ~22 sea_lantern 0
setblock ~105 ~15 ~40 white_glazed_terracotta 0
setblock ~106 ~15 ~22 concrete 0
setblock ~106 ~15 ~40 stone 4
setblock ~107 ~15 ~22 white_glazed_terracotta 0
setblock ~107 ~15 ~40 clay 0
setblock ~108 ~15 ~22 stone 4
setblock ~108 ~15 ~41 sea_lantern 0
setblock ~110 ~15 ~22 stone 4
setblock ~110 ~15 ~41 stone 4
fill ~111 ~15 ~22 ~112 ~15 ~22 sea_lantern 0
fill ~111 ~15 ~41 ~112 ~15 ~41 sea_lantern 0
setblock ~113 ~15 ~22 white_glazed_terracotta 0
setblock ~114 ~15 ~22 iron_block 0
fill ~115 ~15 ~22 ~115 ~16 ~22 sea_lantern 0
setblock ~116 ~15 ~21 stone 4
setblock ~116 ~15 ~42 white_glazed_terracotta 0
setblock ~117 ~15 ~21 clay 0
setblock ~117 ~15 ~42 stone 4
fill ~118 ~15 ~21 ~118 ~16 ~21 stone 4
setblock ~119 ~15 ~21 clay 0
setblock ~119 ~15 ~42 white_glazed_terracotta 0
setblock ~120 ~15 ~21 stone 4
setblock ~120 ~15 ~42 stone 4
setblock ~121 ~15 ~21 clay 0
fill ~121 ~15 ~43 ~122 ~15 ~43 sea_lantern 0
fill ~122 ~15 ~20 ~123 ~15 ~20 stone 4
setblock ~123 ~15 ~21 sea_lantern 0
setblock ~123 ~15 ~43 clay 0
setblock ~124 ~15 ~21 clay 0
setblock ~124 ~15 ~43 white_glazed_terracotta 0
setblock ~125 ~15 ~21 sea_lantern 0
setblock ~125 ~15 ~43 clay 0
setblock ~126 ~15 ~21 white_glazed_terracotta 0
fill ~126 ~15 ~43 ~128 ~15 ~43 sea_lantern 0
setblock ~127 ~15 ~21 sea_lantern 0
fill ~129 ~15 ~43 ~130 ~15 ~43 clay 0
fill ~130 ~15 ~50 ~131 ~15 ~50 stone 4
fill ~131 ~15 ~43 ~131 ~17 ~43 sea_lantern 0
setblock ~131 ~15 ~49 stone 3
setblock ~132 ~15 ~43 clay 0
fill ~133 ~15 ~43 ~134 ~15 ~43 sea_lantern 0
setblock ~135 ~15 ~43 clay 0
fill ~136 ~15 ~43 ~137 ~15 ~43 sea_lantern 0
setblock ~17 ~16 ~20 stained_hardened_clay 7
setblock ~17 ~16 ~21 soul_sand 0
setblock ~17 ~16 ~22 stained_hardened_clay 7
setblock ~17 ~16 ~23 soul_sand 0
setblock ~18 ~16 ~20 stained_hardened_clay 12
setblock ~18 ~16 ~25 stained_hardened_clay 7
fill ~18 ~16 ~26 ~18 ~17 ~26 soul_sand 0
setblock ~19 ~16 ~20 nether_brick 0
setblock ~19 ~16 ~27 soul_sand 0
setblock ~19 ~16 ~28 stained_hardened_clay 7
setblock ~19 ~16 ~29 soul_sand 0
setblock ~20 ~16 ~31 stained_hardened_clay 12
setblock ~21 ~16 ~32 stained_hardened_clay 7
setblock ~21 ~16 ~33 soul_sand 0
fill ~21 ~16 ~34 ~21 ~17 ~34 stained_hardened_clay 7
setblock ~22 ~16 ~20 soul_sand 0
setblock ~22 ~16 ~35 stained_hardened_clay 12
setblock ~22 ~16 ~36 soul_sand 0
setblock ~23 ~16 ~21 stained_hardened_clay 7
setblock ~23 ~16 ~37 soul_sand 0
setblock ~23 ~16 ~38 stained_hardened_clay 7
setblock ~24 ~16 ~22 soul_sand 0
setblock ~24 ~16 ~23 stained_hardened_clay 7
setblock ~24 ~16 ~24 stained_hardened_clay 12
setblock ~24 ~16 ~25 stained_hardened_clay 7
setblock ~24 ~16 ~26 soul_sand 0
setblock ~24 ~16 ~27 stained_hardened_clay 7
setblock ~24 ~16 ~28 stained_hardened_clay 12
setblock ~24 ~16 ~29 stained_hardened_clay 7
setblock ~24 ~16 ~30 stained_hardened_clay 12
setblock ~24 ~16 ~31 stained_hardened_clay 7
setblock ~24 ~16 ~33 stained_hardened_clay 12
setblock ~24 ~16 ~35 stained_hardened_clay 7
setblock ~24 ~16 ~36 soul_sand 0
setblock ~24 ~16 ~37 stained_hardened_clay 12
setblock ~79 ~16 ~29 sea_lantern 0
setblock ~80 ~16 ~28 white_glazed_terracotta 0
setblock ~81 ~16 ~24 stone 3
setblock ~81 ~16 ~28 clay 0
setblock ~82 ~16 ~24 concrete 0
setblock ~82 ~16 ~27 sea_lantern 0
fill ~83 ~16 ~27 ~84 ~16 ~27 white_glazed_terracotta 0
fill ~85 ~16 ~26 ~85 ~17 ~26 sea_lantern 0
fill ~86 ~16 ~26 ~86 ~22 ~26 white_glazed_terracotta 0
setblock ~87 ~16 ~26 clay 0
setblock ~89 ~16 ~25 sea_lantern 0
setblock ~89 ~16 ~37 white_glazed_terracotta 0
setblock ~90 ~16 ~24 sea_lantern 0
fill ~90 ~16 ~37 ~90 ~17 ~37 stone 4
setblock ~91 ~16 ~24 double_stone_slab 8
fill ~92 ~16 ~24 ~95 ~16 ~24 sea_lantern 0
fill ~92 ~16 ~37 ~93 ~16 ~37 sea_lantern 0
setblock ~92 ~16 ~39 stone 4
setblock ~95 ~16 ~38 clay 0
setblock ~96 ~16 ~23 sea_lantern 0
fill ~96 ~16 ~38 ~96 ~17 ~38 white_glazed_terracotta 0
setblock ~97 ~16 ~38 clay 0
fill ~98 ~16 ~23 ~98 ~17 ~23 sea_lantern 0
setblock ~99 ~16 ~23 white_glazed_terracotta 0
setblock ~99 ~16 ~38 sea_lantern 0
fill ~100 ~16 ~23 ~100 ~17 ~23 sea_lantern 0
setblock ~100 ~16 ~39 sea_lantern 0
setblock ~101 ~16 ~23 stone 4
setblock ~101 ~16 ~39 concrete 0
fill ~102 ~16 ~23 ~102 ~17 ~23 sea_lantern 0
fill ~102 ~16 ~39 ~103 ~16 ~39 white_glazed_terracotta 0
setblock ~103 ~16 ~23 white_glazed_terracotta 0
fill ~104 ~16 ~23 ~104 ~17 ~23 sea_lantern 0
setblock ~104 ~16 ~39 sea_lantern 0
setblock ~105 ~16 ~22 stone 4
setblock ~105 ~16 ~40 sea_lantern 0
fill ~106 ~16 ~22 ~106 ~17 ~22 white_glazed_terracotta 0
setblock ~106 ~16 ~40 iron_block 0
fill ~107 ~16 ~22 ~107 ~17 ~22 sea_lantern 0
fill ~107 ~16 ~40 ~107 ~21 ~40 sea_lantern 0
fill ~108 ~16 ~22 ~108 ~17 ~22 concrete 0
fill ~108 ~16 ~40 ~108 ~18 ~40 white_glazed_terracotta 0
setblock ~109 ~16 ~22 clay 0
setblock ~110 ~16 ~22 concrete 0
fill ~110 ~16 ~41 ~110 ~17 ~41 sea_lantern 0
setblock ~111 ~16 ~22 clay 0
setblock ~111 ~16 ~41 white_glazed_terracotta 0
setblock ~112 ~16 ~22 concrete 0
setblock ~112 ~16 ~41 stone 4
setblock ~113 ~16 ~22 clay 0
setblock ~113 ~16 ~41 iron_block 0
setblock ~114 ~16 ~22 concrete 0
setblock ~115 ~16 ~42 stone 4
setblock ~116 ~16 ~22 concrete 0
setblock ~116 ~16 ~42 concrete 0
setblock ~117 ~16 ~21 white_glazed_terracotta 0
setblock ~117 ~16 ~42 sea_lantern 0
fill ~118 ~16 ~42 ~118 ~20 ~42 white_glazed_terracotta 0
setblock ~119 ~16 ~21 concrete 0
setblock ~119 ~16 ~42 stone 4
setblock ~120 ~16 ~21 sea_lantern 0
setblock ~120 ~16 ~42 concrete 0
setblock ~121 ~16 ~21 white_glazed_terracotta 0
setblock ~121 ~16 ~42 clay 0
fill ~122 ~16 ~21 ~124 ~16 ~21 stone 4
setblock ~122 ~16 ~43 stone 4
setblock ~123 ~16 ~43 white_glazed_terracotta 0
setblock ~124 ~16 ~43 sea_lantern 0
setblock ~125 ~16 ~21 white_glazed_terracotta 0
fill ~125 ~16 ~43 ~126 ~16 ~43 concrete 0
fill ~126 ~16 ~21 ~126 ~17 ~21 sea_lantern 0
setblock ~127 ~16 ~21 concrete 0
fill ~127 ~16 ~43 ~127 ~17 ~43 sea_lantern 0
fill ~128 ~16 ~43 ~129 ~16 ~43 white_glazed_terracotta 0
setblock ~130 ~16 ~43 sea_lantern 0
setblock ~131 ~16 ~48 stone 3
setblock ~131 ~16 ~49 stone 4
setblock ~132 ~16 ~43 sea_lantern 0
setblock ~133 ~16 ~43 white_glazed_terracotta 0
setblock ~134 ~16 ~43 sea_lantern 0
setblock ~135 ~16 ~43 concrete 0
fill ~136 ~16 ~43 ~137 ~16 ~43 white_glazed_terracotta 0
setblock ~16 ~17 ~20 soul_sand 0
fill ~16 ~17 ~21 ~16 ~17 ~22 stained_hardened_clay 12
setblock ~16 ~17 ~23 stained_hardened_clay 7
fill ~17 ~17 ~20 ~18 ~17 ~20 log2 1
fill ~17 ~17 ~24 ~17 ~17 ~25 stained_hardened_clay 7
setblock ~18 ~17 ~27 stained_hardened_clay 7
fill ~18 ~17 ~28 ~18 ~18 ~28 soul_sand 0
fill ~19 ~17 ~20 ~23 ~17 ~20 stained_hardened_clay 7
fill ~19 ~17 ~29 ~19 ~17 ~31 stained_hardened_clay 7
setblock ~20 ~17 ~32 soul_sand 0
setblock ~20 ~17 ~33 stained_hardened_clay 7
fill ~21 ~17 ~35 ~21 ~17 ~36 stained_hardened_clay 7
setblock ~22 ~17 ~37 stained_hardened_clay 7
setblock ~22 ~17 ~38 stained_hardened_clay 12
fill ~23 ~17 ~39 ~24 ~17 ~39 stained_hardened_clay 7
fill ~24 ~17 ~21 ~24 ~18 ~21 stained_hardened_clay 7
setblock ~24 ~17 ~38 stained_hardened_clay 12
setblock ~25 ~17 ~22 stained_hardened_clay 7
setblock ~25 ~17 ~23 stained_hardened_clay 15
setblock ~25 ~17 ~24 nether_brick 0
setblock ~25 ~17 ~25 stained_hardened_clay 15
setblock ~25 ~17 ~26 stained_hardened_clay 7
setblock ~25 ~17 ~27 stained_hardened_clay 15
setblock ~25 ~17 ~28 nether_brick 0
setblock ~25 ~17 ~29 stained_hardened_clay 15
setblock ~25 ~17 ~30 nether_brick 0
setblock ~25 ~17 ~31 stained_hardened_clay 15
setblock ~25 ~17 ~32 stained_hardened_clay 7
setblock ~25 ~17 ~33 nether_brick 0
fill ~25 ~17 ~34 ~25 ~17 ~36 stained_hardened_clay 7
setblock ~25 ~17 ~37 nether_brick 0
setblock ~25 ~17 ~38 stained_hardened_clay 7
setblock ~80 ~17 ~28 sea_lantern 0
setblock ~81 ~17 ~28 white_glazed_terracotta 0
setblock ~82 ~17 ~28 sea_lantern 0
fill ~83 ~17 ~27 ~83 ~19 ~27 white_glazed_terracotta 0
setblock ~84 ~17 ~27 sea_lantern 0
fill ~87 ~17 ~26 ~87 ~18 ~26 sea_lantern 0
fill ~88 ~17 ~25 ~89 ~17 ~25 clay 0
setblock ~89 ~17 ~37 clay 0
setblock ~90 ~17 ~25 sea_lantern 0
setblock ~91 ~17 ~24 sea_lantern 0
fill ~91 ~17 ~37 ~92 ~17 ~37 clay 0
setblock ~92 ~17 ~24 white_glazed_terracotta 0
setblock ~93 ~17 ~24 sea_lantern 0
setblock ~93 ~17 ~37 white_glazed_terracotta 0
setblock ~94 ~17 ~24 concrete 0
fill ~94 ~17 ~37 ~94 ~19 ~37 sea_lantern 0
setblock ~95 ~17 ~24 sea_lantern 0
setblock ~95 ~17 ~38 sea_lantern 0
fill ~96 ~17 ~23 ~97 ~17 ~23 clay 0
fill ~97 ~17 ~38 ~97 ~23 ~38 sea_lantern 0
setblock ~98 ~17 ~38 stone 4
setblock ~99 ~17 ~23 clay 0
fill ~99 ~17 ~38 ~100 ~17 ~38 white_glazed_terracotta 0
setblock ~101 ~17 ~23 clay 0
setblock ~101 ~17 ~39 clay 0
fill ~102 ~17 ~39 ~102 ~21 ~39 sea_lantern 0
setblock ~103 ~17 ~23 clay 0
setblock ~103 ~17 ~39 clay 0
fill ~104 ~17 ~39 ~104 ~18 ~39 white_glazed_terracotta 0
setblock ~105 ~17 ~23 sea_lantern 0
setblock ~105 ~17 ~39 clay 0
setblock ~106 ~17 ~40 sea_lantern 0
fill ~109 ~17 ~22 ~109 ~19 ~22 sea_lantern 0
setblock ~109 ~17 ~40 white_glazed_terracotta 0
setblock ~110 ~17 ~22 stone 4
setblock ~111 ~17 ~22 white_glazed_terracotta 0
fill ~111 ~17 ~41 ~111 ~18 ~41 stone 4
setblock ~112 ~17 ~22 stone 4
fill ~112 ~17 ~41 ~113 ~17 ~41 sea_lantern 0
fill ~113 ~17 ~22 ~113 ~19 ~22 sea_lantern 0
fill ~114 ~17 ~22 ~115 ~17 ~22 stone 4
fill ~114 ~17 ~41 ~114 ~18 ~41 white_glazed_terracotta 0
setblock ~115 ~17 ~41 clay 0
fill ~116 ~17 ~22 ~117 ~17 ~22 sea_lantern 0
setblock ~116 ~17 ~42 white_glazed_terracotta 0
setblock ~117 ~17 ~42 concrete 0
setblock ~118 ~17 ~22 stone 4
fill ~119 ~17 ~21 ~120 ~17 ~21 white_glazed_terracotta 0
fill ~119 ~17 ~42 ~120 ~17 ~42 sea_lantern 0
setblock ~121 ~17 ~21 sea_lantern 0
fill ~121 ~17 ~42 ~122 ~17 ~42 white_glazed_terracotta 0
setblock ~122 ~17 ~21 white_glazed_terracotta 0
setblock ~123 ~17 ~21 stone 4
fill ~123 ~17 ~42 ~124 ~17 ~42 stone 4
fill ~124 ~17 ~21 ~126 ~17 ~21 sea_lantern 0
setblock ~125 ~17 ~43 stone 4
setblock ~126 ~17 ~43 white_glazed_terracotta 0
setblock ~127 ~17 ~21 clay 0
fill ~128 ~17 ~43 ~128 ~16 ~43 white_glazed_terracotta 0
setblock ~129 ~17 ~43 clay 0
fill ~130 ~17 ~43 ~130 ~18 ~43 white_glazed_terracotta 0
setblock ~132 ~17 ~43 clay 0
setblock ~132 ~17 ~47 stone 3
setblock ~133 ~17 ~43 sea_lantern 0
fill ~134 ~17 ~43 ~134 ~18 ~43 white_glazed_terracotta 0
setblock ~135 ~17 ~43 clay 0
fill ~136 ~17 ~43 ~137 ~17 ~43 sea_lantern 0
setblock ~15 ~18 ~21 soul_sand 0
fill ~15 ~18 ~22 ~15 ~19 ~22 stained_hardened_clay 7
fill ~16 ~18 ~20 ~16 ~19 ~20 stained_hardened_clay 12
fill ~16 ~18 ~23 ~16 ~18 ~24 soul_sand 0
fill ~17 ~18 ~20 ~17 ~23 ~20 stained_hardened_clay 7
setblock ~17 ~18 ~25 soul_sand 0
setblock ~17 ~18 ~26 stained_hardened_clay 7
setblock ~17 ~18 ~27 soul_sand 0
setblock ~18 ~18 ~20 stained_hardened_clay 12
setblock ~18 ~18 ~29 stained_hardened_clay 12
fill ~18 ~18 ~30 ~18 ~19 ~30 soul_sand 0
setblock ~19 ~18 ~20 nether_brick 0
setblock ~19 ~18 ~31 soul_sand 0
setblock ~19 ~18 ~32 stained_hardened_clay 7
setblock ~19 ~18 ~33 soul_sand 0
setblock ~20 ~18 ~20 stained_hardened_clay 12
setblock ~20 ~18 ~34 soul_sand 0
setblock ~20 ~18 ~35 stained_hardened_clay 12
setblock ~21 ~18 ~20 stained_hardened_clay 15
setblock ~21 ~18 ~36 stained_hardened_clay 7
setblock ~21 ~18 ~37 soul_sand 0
fill ~21 ~18 ~38 ~21 ~19 ~38 stained_hardened_clay 7
setblock ~22 ~18 ~20 soul_sand 0
setblock ~22 ~18 ~39 stained_hardened_clay 12
fill ~23 ~18 ~20 ~23 ~19 ~20 stained_hardened_clay 7
fill ~23 ~18 ~40 ~23 ~20 ~40 stained_hardened_clay 7
setblock ~24 ~18 ~39 stained_hardened_clay 12
setblock ~25 ~18 ~21 soul_sand 0
setblock ~25 ~18 ~22 nether_brick 0
setblock ~25 ~18 ~39 soul_sand 0
fill ~26 ~18 ~23 ~26 ~19 ~23 nether_brick 0
setblock ~26 ~18 ~24 stained_hardened_clay 12
setblock ~26 ~18 ~25 stained_hardened_clay 7
setblock ~26 ~18 ~26 stained_hardened_clay 12
setblock ~26 ~18 ~27 stained_hardened_clay 7
setblock ~26 ~18 ~28 stained_hardened_clay 12
setblock ~26 ~18 ~29 stained_hardened_clay 7
setblock ~26 ~18 ~30 soul_sand 0
setblock ~26 ~18 ~31 log2 1
setblock ~26 ~18 ~32 soul_sand 0
setblock ~26 ~18 ~33 stained_hardened_clay 7
setblock ~26 ~18 ~34 soul_sand 0
setblock ~26 ~18 ~35 stained_hardened_clay 12
fill ~26 ~18 ~36 ~26 ~18 ~38 soul_sand 0
setblock ~80 ~18 ~28 white_glazed_terracotta 0
setblock ~81 ~18 ~25 concrete 0
setblock ~81 ~18 ~26 stone 3
setblock ~81 ~18 ~28 clay 0
setblock ~82 ~18 ~26 concrete 0
setblock ~82 ~18 ~28 iron_block 0
setblock ~84 ~18 ~27 concrete 0
setblock ~85 ~18 ~26 concrete 0
fill ~88 ~18 ~25 ~90 ~18 ~25 white_glazed_terracotta 0
setblock ~89 ~18 ~36 clay 0
setblock ~90 ~18 ~36 concrete 0
setblock ~91 ~18 ~24 clay 0
fill ~91 ~18 ~37 ~92 ~18 ~37 white_glazed_terracotta 0
setblock ~92 ~18 ~24 iron_block 0
fill ~93 ~18 ~24 ~93 ~20 ~24 clay 0
setblock ~93 ~18 ~37 concrete 0
fill ~94 ~18 ~24 ~94 ~19 ~24 white_glazed_terracotta 0
setblock ~95 ~18 ~24 clay 0
setblock ~95 ~18 ~37 white_glazed_terracotta 0
setblock ~96 ~18 ~24 iron_block 0
setblock ~96 ~18 ~38 concrete 0
fill ~97 ~18 ~23 ~98 ~18 ~23 white_glazed_terracotta 0
fill ~98 ~18 ~38 ~98 ~20 ~38 white_glazed_terracotta 0
setblock ~99 ~18 ~23 sea_lantern 0
setblock ~99 ~18 ~38 clay 0
setblock ~100 ~18 ~23 concrete 0
fill ~100 ~18 ~38 ~100 ~20 ~38 white_glazed_terracotta 0
setblock ~101 ~18 ~23 stone 4
setblock ~101 ~18 ~39 sea_lantern 0
fill ~102 ~18 ~23 ~103 ~18 ~23 white_glazed_terracotta 0
setblock ~103 ~18 ~39 white_glazed_terracotta 0
fill ~104 ~18 ~23 ~105 ~18 ~23 concrete 0
setblock ~105 ~18 ~39 white_glazed_terracotta 0
setblock ~106 ~18 ~23 stone 4
setblock ~106 ~18 ~40 white_glazed_terracotta 0
setblock ~107 ~18 ~22 clay 0
setblock ~108 ~18 ~22 white_glazed_terracotta 0
setblock ~109 ~18 ~40 clay 0
setblock ~110 ~18 ~22 concrete 0
fill ~110 ~18 ~41 ~110 ~19 ~41 white_glazed_terracotta 0
fill ~111 ~18 ~22 ~111 ~19 ~22 sea_lantern 0
setblock ~112 ~18 ~22 concrete 0
fill ~112 ~18 ~41 ~112 ~17 ~41 sea_lantern 0
setblock ~113 ~18 ~41 concrete 0
setblock ~114 ~18 ~22 concrete 0
setblock ~115 ~18 ~22 sea_lantern 0
setblock ~115 ~18 ~41 concrete 0
setblock ~116 ~18 ~22 concrete 0
setblock ~116 ~18 ~42 concrete 0
setblock ~117 ~18 ~22 sea_lantern 0
setblock ~117 ~18 ~42 sea_lantern 0
fill ~118 ~18 ~22 ~118 ~19 ~22 white_glazed_terracotta 0
fill ~119 ~18 ~22 ~120 ~18 ~22 concrete 0
fill ~119 ~18 ~42 ~119 ~17 ~42 sea_lantern 0
setblock ~120 ~18 ~42 concrete 0
setblock ~121 ~18 ~21 white_glazed_terracotta 0
setblock ~121 ~18 ~42 clay 0
fill ~122 ~18 ~21 ~122 ~19 ~21 stone 3
fill ~122 ~18 ~42 ~122 ~20 ~42 white_glazed_terracotta 0
fill ~123 ~18 ~21 ~124 ~18 ~21 white_glazed_terracotta 0
fill ~123 ~18 ~42 ~123 ~17 ~42 stone 4
setblock ~124 ~18 ~42 wool 0
setblock ~125 ~18 ~21 concrete 0
fill ~125 ~18 ~42 ~125 ~19 ~42 stone 4
setblock ~126 ~18 ~21 white_glazed_terracotta 0
setblock ~126 ~18 ~42 concrete 0
setblock ~127 ~18 ~21 concrete 0
setblock ~127 ~18 ~42 stone 3
fill ~128 ~18 ~42 ~128 ~20 ~42 concrete 0
setblock ~129 ~18 ~43 concrete 0
setblock ~131 ~18 ~43 concrete 0
setblock ~132 ~18 ~43 white_glazed_terracotta 0
setblock ~133 ~18 ~43 concrete 0
setblock ~133 ~18 ~44 stone 3
setblock ~133 ~18 ~45 concrete 0
setblock ~133 ~18 ~46 stone 3
setblock ~135 ~18 ~43 white_glazed_terracotta 0
setblock ~136 ~18 ~43 stone 4
fill ~137 ~18 ~43 ~137 ~19 ~43 sea_lantern 0
setblock ~15 ~19 ~20 stained_hardened_clay 12
setblock ~15 ~19 ~21 stained_hardened_clay 7
setblock ~15 ~19 ~23 nether_brick 0
fill ~15 ~19 ~24 ~15 ~20 ~24 stained_hardened_clay 7
setblock ~16 ~19 ~25 stained_hardened_clay 7
setblock ~16 ~19 ~26 soul_sand 0
fill ~17 ~19 ~27 ~17 ~19 ~29 stained_hardened_clay 7
fill ~18 ~19 ~20 ~19 ~19 ~20 stained_hardened_clay 7
setblock ~18 ~19 ~31 stained_hardened_clay 7
setblock ~18 ~19 ~32 stained_hardened_clay 12
fill ~19 ~19 ~33 ~19 ~19 ~34 stained_hardened_clay 7
fill ~20 ~19 ~20 ~21 ~19 ~20 log2 1
setblock ~20 ~19 ~35 stained_hardened_clay 7
setblock ~20 ~19 ~36 soul_sand 0
fill ~20 ~19 ~37 ~20 ~20 ~37 stained_hardened_clay 7
setblock ~21 ~19 ~39 stained_hardened_clay 7
setblock ~22 ~19 ~20 stained_hardened_clay 12
fill ~22 ~19 ~40 ~22 ~20 ~40 soul_sand 0
fill ~24 ~19 ~20 ~24 ~20 ~20 soul_sand 0
fill ~24 ~19 ~40 ~24 ~21 ~40 soul_sand 0
setblock ~25 ~19 ~21 stained_hardened_clay 7
fill ~25 ~19 ~40 ~25 ~23 ~40 stained_hardened_clay 7
setblock ~26 ~19 ~22 stained_hardened_clay 12
setblock ~26 ~19 ~38 soul_sand 0
setblock ~26 ~19 ~39 stained_hardened_clay 7
setblock ~27 ~19 ~24 nether_brick 0
setblock ~27 ~19 ~25 stained_hardened_clay 15
setblock ~27 ~19 ~26 log2 1
setblock ~27 ~19 ~27 stained_hardened_clay 15
setblock ~27 ~19 ~28 stained_hardened_clay 7
setblock ~27 ~19 ~29 stained_hardened_clay 15
setblock ~27 ~19 ~30 stained_hardened_clay 7
setblock ~27 ~19 ~31 stained_hardened_clay 15
fill ~27 ~19 ~32 ~27 ~20 ~32 nether_brick 0
fill ~27 ~19 ~33 ~27 ~19 ~32 nether_brick 0
setblock ~27 ~19 ~34 stained_hardened_clay 7
setblock ~27 ~19 ~35 nether_brick 0
setblock ~27 ~19 ~36 log2 1
setblock ~27 ~19 ~37 stained_hardened_clay 7
fill ~80 ~19 ~28 ~81 ~19 ~28 sea_lantern 0
setblock ~82 ~19 ~28 white_glazed_terracotta 0
fill ~84 ~19 ~27 ~84 ~20 ~27 white_glazed_terracotta 0
setblock ~85 ~19 ~27 sea_lantern 0
setblock ~87 ~19 ~26 white_glazed_terracotta 0
setblock ~88 ~19 ~25 sea_lantern 0
setblock ~88 ~19 ~36 stone 4
setblock ~89 ~19 ~25 clay 0
setblock ~89 ~19 ~36 sea_lantern 0
fill ~90 ~19 ~25 ~90 ~21 ~25 sea_lantern 0
fill ~90 ~19 ~36 ~90 ~21 ~36 white_glazed_terracotta 0
fill ~91 ~19 ~24 ~91 ~20 ~24 sea_lantern 0
fill ~91 ~19 ~37 ~91 ~18 ~37 white_glazed_terracotta 0
fill ~92 ~19 ~24 ~92 ~20 ~24 white_glazed_terracotta 0
fill ~92 ~19 ~37 ~94 ~19 ~37 sea_lantern 0
setblock ~95 ~19 ~24 sea_lantern 0
setblock ~95 ~19 ~37 stone 4
setblock ~96 ~19 ~24 concrete 0
fill ~96 ~19 ~38 ~96 ~20 ~38 white_glazed_terracotta 0
setblock ~97 ~19 ~24 sea_lantern 0
fill ~98 ~19 ~23 ~98 ~20 ~23 white_glazed_terracotta 0
setblock ~99 ~19 ~23 clay 0
setblock ~99 ~19 ~38 concrete 0
setblock ~100 ~19 ~23 white_glazed_terracotta 0
setblock ~101 ~19 ~23 clay 0
setblock ~101 ~19 ~39 clay 0
setblock ~102 ~19 ~23 sea_lantern 0
fill ~103 ~19 ~23 ~104 ~19 ~23 clay 0
setblock ~103 ~19 ~39 clay 0
fill ~104 ~19 ~39 ~105 ~19 ~39 sea_lantern 0
fill ~105 ~19 ~23 ~106 ~19 ~23 sea_lantern 0
setblock ~106 ~19 ~40 stone 4
setblock ~107 ~19 ~23 clay 0
setblock ~108 ~19 ~23 sea_lantern 0
setblock ~108 ~19 ~40 iron_block 0
setblock ~109 ~19 ~40 sea_lantern 0
setblock ~110 ~19 ~22 stone 4
setblock ~111 ~19 ~41 clay 0
setblock ~112 ~19 ~22 stone 4
setblock ~112 ~19 ~41 white_glazed_terracotta 0
setblock ~113 ~19 ~41 clay 0
setblock ~114 ~19 ~22 white_glazed_terracotta 0
fill ~114 ~19 ~41 ~115 ~19 ~41 sea_lantern 0
setblock ~115 ~19 ~22 concrete 0
fill ~116 ~19 ~22 ~120 ~19 ~22 white_glazed_terracotta 0
setblock ~116 ~19 ~41 stone 4
setblock ~117 ~19 ~42 stone 4
setblock ~119 ~19 ~42 concrete 0
setblock ~120 ~19 ~42 stone 4
setblock ~121 ~19 ~22 stone 4
fill ~121 ~19 ~42 ~121 ~20 ~42 sea_lantern 0
fill ~123 ~19 ~21 ~125 ~19 ~21 stone 3
setblock ~123 ~19 ~42 sea_lantern 0
setblock ~124 ~19 ~42 iron_block 0
fill ~126 ~19 ~21 ~126 ~20 ~21 stone 4
fill ~126 ~19 ~42 ~127 ~19 ~42 white_glazed_terracotta 0
setblock ~127 ~19 ~21 clay 0
setblock ~128 ~19 ~21 sea_lantern 0
setblock ~129 ~19 ~42 concrete 0
fill ~130 ~19 ~42 ~131 ~19 ~42 white_glazed_terracotta 0
setblock ~132 ~19 ~42 iron_block 0
fill ~133 ~19 ~43 ~134 ~19 ~43 stone 3
fill ~135 ~19 ~43 ~137 ~19 ~43 sea_lantern 0
setblock ~14 ~20 ~20 soul_sand 0
setblock ~14 ~20 ~21 stained_hardened_clay 7
setblock ~14 ~20 ~22 soul_sand 0
setblock ~14 ~20 ~23 stained_hardened_clay 12
fill ~15 ~20 ~20 ~15 ~21 ~20 stained_hardened_clay 7
setblock ~15 ~20 ~25 soul_sand 0
fill ~15 ~20 ~26 ~15 ~21 ~26 stained_hardened_clay 7
fill ~16 ~20 ~20 ~16 ~24 ~20 soul_sand 0
setblock ~16 ~20 ~27 stained_hardened_clay 12
fill ~16 ~20 ~28 ~16 ~21 ~28 soul_sand 0
setblock ~17 ~20 ~29 soul_sand 0
setblock ~17 ~20 ~30 stained_hardened_clay 7
setblock ~17 ~20 ~31 soul_sand 0
setblock ~18 ~20 ~20 soul_sand 0
setblock ~18 ~20 ~32 soul_sand 0
setblock ~18 ~20 ~33 stained_hardened_clay 7
setblock ~18 ~20 ~34 soul_sand 0
setblock ~19 ~20 ~20 stained_hardened_clay 15
setblock ~19 ~20 ~35 soul_sand 0
fill ~19 ~20 ~36 ~19 ~21 ~36 stained_hardened_clay 7
setblock ~20 ~20 ~20 soul_sand 0
setblock ~20 ~20 ~38 soul_sand 0
setblock ~20 ~20 ~39 stained_hardened_clay 12
fill ~21 ~20 ~20 ~21 ~23 ~20 stained_hardened_clay 7
fill ~21 ~20 ~40 ~21 ~21 ~40 stained_hardened_clay 7
setblock ~22 ~20 ~20 soul_sand 0
setblock ~23 ~20 ~20 nether_brick 0
fill ~25 ~20 ~20 ~25 ~23 ~20 stained_hardened_clay 7
fill ~26 ~20 ~21 ~26 ~21 ~21 stained_hardened_clay 7
setblock ~26 ~20 ~39 stained_hardened_clay 12
fill ~27 ~20 ~22 ~27 ~20 ~23 stained_hardened_clay 7
setblock ~27 ~20 ~24 stained_hardened_clay 15
setblock ~27 ~20 ~25 stained_hardened_clay 12
setblock ~27 ~20 ~26 nether_brick 0
setblock ~27 ~20 ~27 soul_sand 0
setblock ~27 ~20 ~28 stained_hardened_clay 15
setblock ~27 ~20 ~29 stained_hardened_clay 7
setblock ~27 ~20 ~30 stained_hardened_clay 15
setblock ~27 ~20 ~31 stained_hardened_clay 7
setblock ~27 ~20 ~37 soul_sand 0
setblock ~27 ~20 ~38 stained_hardened_clay 7
setblock ~28 ~20 ~33 stained_hardened_clay 7
setblock ~28 ~20 ~34 soul_sand 0
setblock ~28 ~20 ~35 stained_hardened_clay 12
setblock ~28 ~20 ~36 soul_sand 0
setblock ~80 ~20 ~28 white_glazed_terracotta 0
fill ~81 ~20 ~28 ~81 ~22 ~28 clay 0
setblock ~82 ~20 ~28 concrete 0
setblock ~83 ~20 ~27 concrete 0
setblock ~85 ~20 ~27 concrete 0
fill ~87 ~20 ~26 ~87 ~25 ~26 sea_lantern 0
setblock ~88 ~20 ~26 concrete 0
setblock ~88 ~20 ~36 white_glazed_terracotta 0
setblock ~89 ~20 ~25 iron_block 0 KittysCommands:
setblock ~89 ~20 ~36 clay 0
setblock ~91 ~20 ~36 concrete 0
setblock ~92 ~20 ~37 stone 4
setblock ~93 ~20 ~37 concrete 0
setblock ~94 ~20 ~24 iron_block 0
setblock ~94 ~20 ~37 stone 4
setblock ~95 ~20 ~24 stone 4
setblock ~95 ~20 ~37 white_glazed_terracotta 0
setblock ~96 ~20 ~24 white_glazed_terracotta 0
setblock ~97 ~20 ~24 clay 0
setblock ~99 ~20 ~23 white_glazed_terracotta 0
fill ~99 ~20 ~38 ~99 ~21 ~38 clay 0
setblock ~100 ~20 ~23 sea_lantern 0
fill ~101 ~20 ~23 ~102 ~20 ~23 white_glazed_terracotta 0
setblock ~101 ~20 ~39 white_glazed_terracotta 0
setblock ~103 ~20 ~23 concrete 0
setblock ~103 ~20 ~39 white_glazed_terracotta 0
fill ~104 ~20 ~23 ~104 ~26 ~23 sea_lantern 0
setblock ~104 ~20 ~39 iron_block 0
fill ~105 ~20 ~23 ~108 ~20 ~23 white_glazed_terracotta 0
setblock ~105 ~20 ~39 white_glazed_terracotta 0
setblock ~106 ~20 ~40 white_glazed_terracotta 0
setblock ~108 ~20 ~40 stone 4
setblock ~109 ~20 ~23 concrete 0
setblock ~109 ~20 ~40 white_glazed_terracotta 0
setblock ~110 ~20 ~22 concrete 0
setblock ~110 ~20 ~40 concrete 0
setblock ~111 ~20 ~22 clay 0
setblock ~111 ~20 ~41 white_glazed_terracotta 0
setblock ~112 ~20 ~22 concrete 0
setblock ~112 ~20 ~41 sea_lantern 0
setblock ~113 ~20 ~22 clay 0
setblock ~113 ~20 ~41 iron_block 0
setblock ~114 ~20 ~22 concrete 0
fill ~114 ~20 ~41 ~114 ~19 ~41 sea_lantern 0
setblock ~115 ~20 ~22 stone 4
fill ~115 ~20 ~41 ~116 ~20 ~41 white_glazed_terracotta 0
fill ~116 ~20 ~22 ~116 ~22 ~22 white_glazed_terracotta 0
fill ~117 ~20 ~22 ~118 ~20 ~22 concrete 0
setblock ~117 ~20 ~41 concrete 0
setblock ~119 ~20 ~22 sea_lantern 0
setblock ~119 ~20 ~42 white_glazed_terracotta 0
fill ~120 ~20 ~22 ~120 ~21 ~22 iron_block 0
setblock ~120 ~20 ~42 concrete 0
setblock ~121 ~20 ~22 sea_lantern 0
fill ~122 ~20 ~22 ~122 ~22 ~22 concrete 0
setblock ~123 ~20 ~22 stone 3
setblock ~123 ~20 ~42 clay 0
setblock ~124 ~20 ~21 stone 4
setblock ~124 ~20 ~42 concrete 0
setblock ~125 ~20 ~21 white_glazed_terracotta 0
setblock ~125 ~20 ~42 sea_lantern 0
setblock ~126 ~20 ~42 iron_block 0
setblock ~127 ~20 ~21 white_glazed_terracotta 0
setblock ~127 ~20 ~42 stone 4
setblock ~128 ~20 ~21 stone 4
fill ~129 ~20 ~42 ~129 ~21 ~42 stone 3
setblock ~130 ~20 ~42 concrete 0
setblock ~131 ~20 ~42 stone 3
fill ~132 ~20 ~42 ~132 ~22 ~42 concrete 0
setblock ~133 ~20 ~42 stone 3
setblock ~134 ~20 ~42 iron_block 0
setblock ~135 ~20 ~42 stone 3
setblock ~136 ~20 ~42 white_glazed_terracotta 0
setblock ~137 ~20 ~43 white_glazed_terracotta 0
setblock ~13 ~21 ~21 nether_brick 0
fill ~13 ~21 ~22 ~13 ~22 ~22 stained_hardened_clay 7
fill ~14 ~21 ~20 ~14 ~23 ~20 stained_hardened_clay 12
setblock ~14 ~21 ~23 stained_hardened_clay 7
setblock ~14 ~21 ~24 stained_hardened_clay 12
setblock ~14 ~21 ~25 stained_hardened_clay 7
setblock ~15 ~21 ~27 stained_hardened_clay 7
setblock ~16 ~21 ~29 stained_hardened_clay 7
setblock ~16 ~21 ~30 stained_hardened_clay 12
fill ~17 ~21 ~31 ~17 ~21 ~33 stained_hardened_clay 7
setblock ~18 ~21 ~20 stained_hardened_clay 12
setblock ~18 ~21 ~34 stained_hardened_clay 12
fill ~18 ~21 ~35 ~18 ~22 ~35 stained_hardened_clay 7
fill ~19 ~21 ~20 ~22 ~21 ~20 stained_hardened_clay 7
fill ~19 ~21 ~37 ~19 ~21 ~38 stained_hardened_clay 7
setblock ~20 ~21 ~39 stained_hardened_clay 7
setblock ~22 ~21 ~40 stained_hardened_clay 7
setblock ~23 ~21 ~20 log2 1
setblock ~23 ~21 ~41 nether_brick 0
setblock ~24 ~21 ~20 stained_hardened_clay 12
setblock ~26 ~21 ~40 stained_hardened_clay 12
setblock ~27 ~21 ~21 nether_brick 0
setblock ~27 ~21 ~39 stained_hardened_clay 7
fill ~28 ~21 ~22 ~28 ~22 ~22 soul_sand 0
setblock ~28 ~21 ~23 nether_brick 0
setblock ~28 ~21 ~24 stained_hardened_clay 12
setblock ~28 ~21 ~25 log2 1
setblock ~28 ~21 ~26 stained_hardened_clay 7
setblock ~28 ~21 ~27 log2 1
setblock ~28 ~21 ~28 stained_hardened_clay 12
setblock ~28 ~21 ~29 nether_brick 0
setblock ~28 ~21 ~30 stained_hardened_clay 12
setblock ~28 ~21 ~31 nether_brick 0
setblock ~28 ~21 ~32 log2 1
setblock ~28 ~21 ~33 nether_brick 0
setblock ~28 ~21 ~34 stained_hardened_clay 12
setblock ~28 ~21 ~35 stained_hardened_clay 7
setblock ~28 ~21 ~36 stained_hardened_clay 12
setblock ~28 ~21 ~37 stained_hardened_clay 7
setblock ~28 ~21 ~38 stained_hardened_clay 12
setblock ~80 ~21 ~28 sea_lantern 0
setblock ~82 ~21 ~28 sea_lantern 0
setblock ~83 ~21 ~27 sea_lantern 0
setblock ~84 ~21 ~27 clay 0
setblock ~85 ~21 ~27 white_glazed_terracotta 0
setblock ~88 ~21 ~26 white_glazed_terracotta 0
fill ~88 ~21 ~35 ~88 ~24 ~35 sea_lantern 0
setblock ~89 ~21 ~25 sea_lantern 0
setblock ~89 ~21 ~36 sea_lantern 0
setblock ~91 ~21 ~25 clay 0
fill ~91 ~21 ~36 ~92 ~21 ~36 white_glazed_terracotta 0
fill ~92 ~21 ~24 ~93 ~21 ~24 sea_lantern 0
setblock ~93 ~21 ~37 clay 0
setblock ~94 ~21 ~24 white_glazed_terracotta 0
setblock ~94 ~21 ~37 white_glazed_terracotta 0
fill ~95 ~21 ~24 ~98 ~21 ~24 sea_lantern 0
setblock ~95 ~21 ~37 clay 0
setblock ~96 ~21 ~37 sea_lantern 0
fill ~98 ~21 ~38 ~98 ~22 ~38 concrete 0
setblock ~99 ~21 ~23 clay 0
setblock ~100 ~21 ~23 white_glazed_terracotta 0
setblock ~100 ~21 ~38 sea_lantern 0
fill ~101 ~21 ~23 ~106 ~21 ~23 sea_lantern 0
setblock ~101 ~21 ~39 clay 0
setblock ~103 ~21 ~39 clay 0
setblock ~104 ~21 ~39 white_glazed_terracotta 0
setblock ~105 ~21 ~39 sea_lantern 0
setblock ~106 ~21 ~40 concrete 0
fill ~107 ~21 ~23 ~109 ~21 ~23 clay 0
setblock ~108 ~21 ~40 white_glazed_terracotta 0
setblock ~109 ~21 ~40 sea_lantern 0
setblock ~110 ~21 ~23 sea_lantern 0
fill ~110 ~21 ~40 ~110 ~22 ~40 white_glazed_terracotta 0
setblock ~111 ~21 ~23 clay 0
fill ~111 ~21 ~41 ~113 ~21 ~41 clay 0
setblock ~112 ~21 ~22 white_glazed_terracotta 0
setblock ~113 ~21 ~22 sea_lantern 0
fill ~114 ~21 ~22 ~114 ~22 ~22 white_glazed_terracotta 0
fill ~114 ~21 ~41 ~116 ~21 ~41 white_glazed_terracotta 0
setblock ~115 ~21 ~22 sea_lantern 0
setblock ~117 ~21 ~22 sea_lantern 0
setblock ~117 ~21 ~41 clay 0
setblock ~118 ~21 ~22 concrete 0
setblock ~118 ~21 ~41 stone 4
setblock ~119 ~21 ~22 white_glazed_terracotta 0
setblock ~119 ~21 ~42 sea_lantern 0
fill ~120 ~21 ~42 ~121 ~21 ~42 white_glazed_terracotta 0
setblock ~121 ~21 ~22 stone 4
fill ~122 ~21 ~42 ~123 ~21 ~42 sea_lantern 0
fill ~123 ~21 ~22 ~125 ~21 ~22 stone 4
fill ~124 ~21 ~42 ~127 ~21 ~42 white_glazed_terracotta 0
fill ~126 ~21 ~21 ~127 ~21 ~21 stone 3
setblock ~128 ~21 ~21 sea_lantern 0
setblock ~128 ~21 ~42 iron_block 0
setblock ~130 ~21 ~42 white_glazed_terracotta 0
setblock ~131 ~21 ~42 stone 4
fill ~133 ~21 ~42 ~133 ~24 ~42 stone 4
setblock ~134 ~21 ~42 concrete 0
setblock ~135 ~21 ~42 white_glazed_terracotta 0
setblock ~136 ~21 ~42 stone 4
setblock ~137 ~21 ~42 sea_lantern 0
fill ~12 ~22 ~21 ~12 ~23 ~21 stained_hardened_clay 7
setblock ~13 ~22 ~20 nether_brick 0
setblock ~13 ~22 ~23 soul_sand 0
fill ~13 ~22 ~24 ~13 ~23 ~24 stained_hardened_clay 7
fill ~14 ~22 ~25 ~14 ~22 ~26 soul_sand 0
setblock ~14 ~22 ~27 stained_hardened_clay 12
setblock ~15 ~22 ~20 nether_brick 0
setblock ~15 ~22 ~28 stained_hardened_clay 7
setblock ~15 ~22 ~29 soul_sand 0
setblock ~16 ~22 ~30 soul_sand 0
setblock ~16 ~22 ~31 stained_hardened_clay 12
fill ~16 ~22 ~32 ~16 ~23 ~32 soul_sand 0
setblock ~17 ~22 ~33 soul_sand 0
setblock ~17 ~22 ~34 stained_hardened_clay 7
fill ~18 ~22 ~20 ~18 ~24 ~20 soul_sand 0
fill ~18 ~22 ~36 ~18 ~22 ~37 soul_sand 0
setblock ~19 ~22 ~20 log2 1
setblock ~19 ~22 ~38 stained_hardened_clay 7
setblock ~19 ~22 ~39 soul_sand 0
setblock ~20 ~22 ~20 soul_sand 0
fill ~20 ~22 ~40 ~20 ~23 ~40 soul_sand 0
setblock ~21 ~22 ~40 nether_brick 0
setblock ~22 ~22 ~20 soul_sand 0
fill ~22 ~22 ~41 ~22 ~24 ~41 stained_hardened_clay 7
setblock ~23 ~22 ~20 nether_brick 0
setblock ~23 ~22 ~41 stained_hardened_clay 12
setblock ~24 ~22 ~20 soul_sand 0
fill ~24 ~22 ~41 ~24 ~24 ~41 stained_hardened_clay 7
setblock ~26 ~22 ~20 soul_sand 0
setblock ~26 ~22 ~40 soul_sand 0
fill ~27 ~22 ~21 ~28 ~22 ~21 stained_hardened_clay 12
fill ~27 ~22 ~40 ~27 ~23 ~40 stained_hardened_clay 7
setblock ~28 ~22 ~39 soul_sand 0
setblock ~29 ~22 ~23 stained_hardened_clay 12
setblock ~29 ~22 ~24 stained_hardened_clay 7
setblock ~29 ~22 ~25 soul_sand 0
setblock ~29 ~22 ~26 log2 1
setblock ~29 ~22 ~27 soul_sand 0
setblock ~29 ~22 ~28 nether_brick 0
setblock ~29 ~22 ~29 stained_hardened_clay 7
setblock ~29 ~22 ~30 nether_brick 0
setblock ~29 ~22 ~31 stained_hardened_clay 12
setblock ~29 ~22 ~32 nether_brick 0
setblock ~29 ~22 ~33 stained_hardened_clay 12
setblock ~29 ~22 ~34 log2 1
setblock ~29 ~22 ~35 soul_sand 0
setblock ~29 ~22 ~36 log2 1
setblock ~29 ~22 ~37 soul_sand 0
fill ~29 ~22 ~38 ~29 ~23 ~38 stained_hardened_clay 7
setblock ~80 ~22 ~28 white_glazed_terracotta 0
setblock ~82 ~22 ~28 white_glazed_terracotta 0
fill ~83 ~22 ~27 ~84 ~22 ~27 white_glazed_terracotta 0
setblock ~85 ~22 ~27 concrete 0
setblock ~88 ~22 ~26 concrete 0
setblock ~89 ~22 ~25 white_glazed_terracotta 0
setblock ~89 ~22 ~36 white_glazed_terracotta 0
setblock ~90 ~22 ~25 stone 4
setblock ~90 ~22 ~36 stone 4
setblock ~91 ~22 ~25 white_glazed_terracotta 0
setblock ~91 ~22 ~36 sea_lantern 0
setblock ~92 ~22 ~24 concrete 0
setblock ~92 ~22 ~36 concrete 0
fill ~93 ~22 ~24 ~95 ~22 ~24 sea_lantern 0
setblock ~93 ~22 ~37 iron_block 0
setblock ~94 ~22 ~37 stone 4
setblock ~95 ~22 ~37 concrete 0
fill ~96 ~22 ~24 ~97 ~22 ~24 white_glazed_terracotta 0
setblock ~96 ~22 ~37 white_glazed_terracotta 0
setblock ~98 ~22 ~24 concrete 0
setblock ~99 ~22 ~24 clay 0
setblock ~99 ~22 ~38 sea_lantern 0
setblock ~100 ~22 ~23 sea_lantern 0
setblock ~100 ~22 ~38 netherrack 0
setblock ~101 ~22 ~23 concrete 0
setblock ~101 ~22 ~39 concrete 0
setblock ~102 ~22 ~23 sea_lantern 0
setblock ~102 ~22 ~39 netherrack 0
setblock ~103 ~22 ~23 white_glazed_terracotta 0
setblock ~103 ~22 ~39 stone 3
setblock ~104 ~22 ~39 concrete 0
setblock ~105 ~22 ~23 iron_block 0
setblock ~105 ~22 ~39 white_glazed_terracotta 0
fill ~106 ~22 ~23 ~106 ~29 ~23 sea_lantern 0
setblock ~106 ~22 ~40 netherrack 0
fill ~107 ~22 ~23 ~111 ~22 ~23 white_glazed_terracotta 0
fill ~107 ~22 ~40 ~107 ~23 ~40 white_glazed_terracotta 0
setblock ~108 ~22 ~40 double_stone_slab 8
setblock ~109 ~22 ~40 red_nether_brick 0
setblock ~111 ~22 ~40 clay 0
setblock ~112 ~22 ~23 clay 0
setblock ~112 ~22 ~41 netherrack 0
setblock ~113 ~22 ~22 clay 0
fill ~113 ~22 ~41 ~114 ~22 ~41 white_glazed_terracotta 0
setblock ~115 ~22 ~22 stone 4
setblock ~115 ~22 ~41 stone 4
fill ~116 ~22 ~41 ~117 ~22 ~41 concrete 0
fill ~117 ~22 ~22 ~117 ~23 ~22 stone 4
fill ~118 ~22 ~22 ~118 ~23 ~22 white_glazed_terracotta 0
fill ~118 ~22 ~41 ~119 ~22 ~41 iron_block 0
fill ~119 ~22 ~22 ~120 ~22 ~22 concrete 0
fill ~120 ~22 ~42 ~120 ~21 ~42 white_glazed_terracotta 0
setblock ~121 ~22 ~22 sea_lantern 0
setblock ~121 ~22 ~42 clay 0
setblock ~122 ~22 ~42 concrete 0
setblock ~123 ~22 ~22 sea_lantern 0
fill ~123 ~22 ~42 ~123 ~23 ~42 sea_lantern 0
setblock ~124 ~22 ~22 white_glazed_terracotta 0
fill ~124 ~22 ~42 ~124 ~23 ~42 concrete 0
setblock ~125 ~22 ~22 stone 3
setblock ~125 ~22 ~42 stone 3
setblock ~126 ~22 ~22 concrete 0
setblock ~126 ~22 ~42 concrete 0
setblock ~127 ~22 ~21 concrete 0
setblock ~127 ~22 ~42 stone 3
setblock ~128 ~22 ~21 stone 4
fill ~128 ~22 ~42 ~129 ~22 ~42 concrete 0
setblock ~130 ~22 ~42 iron_block 0
setblock ~131 ~22 ~42 white_glazed_terracotta 0
setblock ~134 ~22 ~42 iron_block 0
setblock ~135 ~22 ~42 stone 3
setblock ~136 ~22 ~42 wool 0
setblock ~137 ~22 ~42 clay 0
setblock ~12 ~23 ~20 stained_hardened_clay 12
setblock ~12 ~23 ~22 soul_sand 0
setblock ~12 ~23 ~23 stained_hardened_clay 7
fill ~13 ~23 ~20 ~13 ~24 ~20 stained_hardened_clay 7
fill ~13 ~23 ~25 ~13 ~23 ~26 stained_hardened_clay 7
setblock ~14 ~23 ~27 stained_hardened_clay 7
setblock ~14 ~23 ~28 soul_sand 0
fill ~15 ~23 ~20 ~15 ~24 ~20 stained_hardened_clay 7
fill ~15 ~23 ~29 ~15 ~23 ~31 stained_hardened_clay 7
setblock ~16 ~23 ~33 stained_hardened_clay 7
setblock ~16 ~23 ~34 stained_hardened_clay 12
fill ~17 ~23 ~35 ~17 ~23 ~36 stained_hardened_clay 7
setblock ~18 ~23 ~37 stained_hardened_clay 7
setblock ~18 ~23 ~38 soul_sand 0
setblock ~18 ~23 ~39 stained_hardened_clay 7
fill ~19 ~23 ~20 ~20 ~23 ~20 stained_hardened_clay 12
fill ~19 ~23 ~40 ~19 ~25 ~40 stained_hardened_clay 7
setblock ~21 ~23 ~41 stained_hardened_clay 15
setblock ~22 ~23 ~20 log2 1
fill ~23 ~23 ~20 ~25 ~23 ~20 stained_hardened_clay 7
setblock ~23 ~23 ~41 stained_hardened_clay 15
setblock ~26 ~23 ~20 stained_hardened_clay 12
setblock ~26 ~23 ~40 stained_hardened_clay 7
fill ~27 ~23 ~20 ~27 ~24 ~20 stained_hardened_clay 7
fill ~28 ~23 ~21 ~28 ~25 ~21 stained_hardened_clay 7
setblock ~28 ~23 ~40 stained_hardened_clay 12
setblock ~29 ~23 ~22 soul_sand 0
setblock ~29 ~23 ~39 stained_hardened_clay 7
fill ~30 ~23 ~23 ~30 ~24 ~23 stained_hardened_clay 7
setblock ~30 ~23 ~24 stained_hardened_clay 12
fill ~30 ~23 ~25 ~30 ~23 ~26 stained_hardened_clay 7
setblock ~30 ~23 ~27 log2 1
fill ~30 ~23 ~28 ~30 ~23 ~29 stained_hardened_clay 7
setblock ~30 ~23 ~30 stained_hardened_clay 12
setblock ~30 ~23 ~31 stained_hardened_clay 15
setblock ~30 ~23 ~32 stained_hardened_clay 12
setblock ~30 ~23 ~33 stained_hardened_clay 7
setblock ~30 ~23 ~34 stained_hardened_clay 12
setblock ~30 ~23 ~35 stained_hardened_clay 7
setblock ~30 ~23 ~36 stained_hardened_clay 12
fill ~30 ~23 ~37 ~30 ~24 ~37 stained_hardened_clay 7
setblock ~80 ~23 ~29 sea_lantern 0
fill ~81 ~23 ~28 ~81 ~25 ~28 sea_lantern 0
setblock ~82 ~23 ~28 concrete 0
setblock ~83 ~23 ~28 white_glazed_terracotta 0
setblock ~84 ~23 ~27 stone 4
setblock ~85 ~23 ~27 sea_lantern 0
setblock ~86 ~23 ~26 iron_block 0
fill ~88 ~23 ~26 ~88 ~27 ~26 white_glazed_terracotta 0
setblock ~89 ~23 ~25 stone 4
setblock ~89 ~23 ~35 clay 0
setblock ~90 ~23 ~25 sea_lantern 0
fill ~90 ~23 ~36 ~91 ~23 ~36 white_glazed_terracotta 0
setblock ~91 ~23 ~25 clay 0
setblock ~92 ~23 ~24 white_glazed_terracotta 0
setblock ~92 ~23 ~36 stone 4
fill ~93 ~23 ~24 ~93 ~21 ~24 sea_lantern 0
setblock ~93 ~23 ~36 white_glazed_terracotta 0
fill ~94 ~23 ~24 ~94 ~24 ~24 concrete 0
fill ~94 ~23 ~37 ~94 ~27 ~37 sea_lantern 0
setblock ~95 ~23 ~24 sea_lantern 0
setblock ~95 ~23 ~37 clay 0
fill ~96 ~23 ~24 ~96 ~25 ~24 white_glazed_terracotta 0
fill ~96 ~23 ~37 ~96 ~27 ~37 sea_lantern 0
setblock ~97 ~23 ~24 sea_lantern 0
fill ~98 ~23 ~24 ~98 ~24 ~24 white_glazed_terracotta 0
fill ~98 ~23 ~38 ~99 ~23 ~38 white_glazed_terracotta 0
fill ~99 ~23 ~24 ~99 ~27 ~24 sea_lantern 0
setblock ~100 ~23 ~24 white_glazed_terracotta 0
setblock ~100 ~23 ~38 concrete 0
setblock ~101 ~23 ~23 clay 0
setblock ~101 ~23 ~39 black_glazed_terracotta 0
fill ~102 ~23 ~23 ~102 ~24 ~23 white_glazed_terracotta 0
fill ~102 ~23 ~39 ~102 ~24 ~39 sea_lantern 0
setblock ~103 ~23 ~23 clay 0
setblock ~103 ~23 ~39 clay 0
fill ~104 ~23 ~39 ~105 ~23 ~39 red_nether_brick 0
setblock ~105 ~23 ~23 clay 0
setblock ~106 ~23 ~40 concrete 0
fill ~107 ~23 ~23 ~108 ~23 ~23 sea_lantern 0
setblock ~108 ~23 ~40 concrete 0
setblock ~109 ~23 ~23 clay 0
setblock ~109 ~23 ~40 white_glazed_terracotta 0
fill ~110 ~23 ~23 ~112 ~23 ~23 sea_lantern 0
fill ~110 ~23 ~40 ~110 ~25 ~40 netherrack 0
setblock ~111 ~23 ~40 sea_lantern 0
fill ~112 ~23 ~41 ~112 ~24 ~41 clay 0
setblock ~113 ~23 ~23 double_stone_slab 8
setblock ~113 ~23 ~41 red_nether_brick 0
setblock ~114 ~23 ~22 sea_lantern 0
fill ~114 ~23 ~41 ~115 ~23 ~41 clay 0
setblock ~115 ~23 ~22 clay 0
setblock ~116 ~23 ~22 iron_block 0
setblock ~116 ~23 ~41 redstone_ore 0
setblock ~117 ~23 ~41 red_nether_brick 0
setblock ~118 ~23 ~41 clay 0
fill ~119 ~23 ~22 ~120 ~23 ~22 sea_lantern 0
setblock ~119 ~23 ~41 sea_lantern 0
setblock ~120 ~23 ~41 coal_ore 0
setblock ~121 ~23 ~22 concrete 0
setblock ~121 ~23 ~42 redstone_ore 0
setblock ~122 ~23 ~22 iron_block 0
setblock ~122 ~23 ~42 sea_lantern 0
setblock ~123 ~23 ~22 stone 4
fill ~124 ~23 ~22 ~124 ~26 ~22 concrete 0
setblock ~125 ~23 ~22 white_glazed_terracotta 0
fill ~125 ~23 ~42 ~126 ~23 ~42 white_glazed_terracotta 0
setblock ~126 ~23 ~22 iron_block 0
fill ~127 ~23 ~22 ~128 ~23 ~22 stone 4
setblock ~127 ~23 ~42 stone 4
fill ~128 ~23 ~42 ~128 ~25 ~42 concrete 0
fill ~129 ~23 ~42 ~129 ~24 ~42 stone 4
setblock ~130 ~23 ~42 concrete 0
setblock ~131 ~23 ~42 iron_block 0
setblock ~132 ~23 ~42 wool 0
setblock ~134 ~23 ~42 concrete 0
fill ~135 ~23 ~42 ~136 ~23 ~42 white_glazed_terracotta 0
fill ~137 ~23 ~42 ~137 ~24 ~42 sea_lantern 0
setblock ~11 ~24 ~21 soul_sand 0
setblock ~11 ~24 ~22 stained_hardened_clay 7
setblock ~11 ~24 ~23 soul_sand 0
setblock ~12 ~24 ~20 soul_sand 0
fill ~12 ~24 ~24 ~12 ~24 ~25 soul_sand 0
setblock ~13 ~24 ~26 stained_hardened_clay 7
setblock ~13 ~24 ~27 soul_sand 0
fill ~13 ~24 ~28 ~13 ~25 ~28 stained_hardened_clay 7
setblock ~14 ~24 ~20 soul_sand 0
setblock ~14 ~24 ~29 stained_hardened_clay 12
setblock ~14 ~24 ~30 soul_sand 0
setblock ~15 ~24 ~31 soul_sand 0
setblock ~15 ~24 ~32 stained_hardened_clay 7
setblock ~15 ~24 ~33 soul_sand 0
setblock ~16 ~24 ~34 soul_sand 0
setblock ~16 ~24 ~35 stained_hardened_clay 12
setblock ~17 ~24 ~20 stained_hardened_clay 15
setblock ~17 ~24 ~36 stained_hardened_clay 7
setblock ~17 ~24 ~37 soul_sand 0
fill ~17 ~24 ~38 ~17 ~25 ~38 stained_hardened_clay 7
setblock ~18 ~24 ~39 soul_sand 0
setblock ~19 ~24 ~20 log2 1
setblock ~20 ~24 ~20 soul_sand 0
fill ~20 ~24 ~41 ~25 ~24 ~41 stained_hardened_clay 7
setblock ~21 ~24 ~20 nether_brick 0
setblock ~22 ~24 ~20 stained_hardened_clay 12
setblock ~23 ~24 ~20 nether_brick 0
setblock ~24 ~24 ~20 soul_sand 0
setblock ~25 ~24 ~20 planks 5
setblock ~26 ~24 ~20 soul_sand 0
setblock ~26 ~24 ~40 soul_sand 0
setblock ~27 ~24 ~40 nether_brick 0
setblock ~28 ~24 ~40 soul_sand 0
setblock ~29 ~24 ~21 soul_sand 0
setblock ~29 ~24 ~39 soul_sand 0
setblock ~30 ~24 ~22 soul_sand 0
setblock ~30 ~24 ~24 soul_sand 0
setblock ~30 ~24 ~25 log2 1
setblock ~30 ~24 ~26 stained_hardened_clay 12
setblock ~30 ~24 ~27 stained_hardened_clay 7
setblock ~30 ~24 ~28 soul_sand 0
setblock ~30 ~24 ~29 stained_hardened_clay 7
setblock ~30 ~24 ~38 soul_sand 0
fill ~30 ~24 ~39 ~30 ~25 ~39 stained_hardened_clay 7
setblock ~31 ~24 ~30 stained_hardened_clay 15
fill ~31 ~24 ~31 ~31 ~24 ~32 stained_hardened_clay 7
setblock ~31 ~24 ~33 stained_hardened_clay 12
setblock ~31 ~24 ~34 nether_brick 0
setblock ~31 ~24 ~35 stained_hardened_clay 12
fill ~31 ~24 ~36 ~31 ~25 ~36 log2 1
fill ~82 ~24 ~28 ~82 ~25 ~28 white_glazed_terracotta 0
setblock ~83 ~24 ~28 clay 0
fill ~84 ~24 ~27 ~84 ~25 ~27 sea_lantern 0
setblock ~85 ~24 ~27 white_glazed_terracotta 0
setblock ~86 ~24 ~27 sea_lantern 0
setblock ~89 ~24 ~26 clay 0
setblock ~89 ~24 ~35 concrete 0
setblock ~90 ~24 ~25 white_glazed_terracotta 0
setblock ~90 ~24 ~36 concrete 0
setblock ~91 ~24 ~25 iron_block 0
fill ~91 ~24 ~36 ~91 ~27 ~36 sea_lantern 0
fill ~92 ~24 ~25 ~92 ~31 ~25 sea_lantern 0
setblock ~92 ~24 ~36 white_glazed_terracotta 0
setblock ~93 ~24 ~24 clay 0
setblock ~93 ~24 ~36 sea_lantern 0
fill ~95 ~24 ~24 ~95 ~26 ~24 clay 0
setblock ~95 ~24 ~37 iron_block 0
setblock ~97 ~24 ~24 clay 0
setblock ~97 ~24 ~37 concrete 0
fill ~98 ~24 ~38 ~98 ~23 ~38 white_glazed_terracotta 0
setblock ~99 ~24 ~38 red_nether_brick 0
setblock ~100 ~24 ~24 concrete 0
setblock ~100 ~24 ~38 iron_ore 0
setblock ~101 ~24 ~23 white_glazed_terracotta 0
setblock ~101 ~24 ~39 stone 4
setblock ~103 ~24 ~23 sea_lantern 0
setblock ~103 ~24 ~39 sea_lantern 0
setblock ~104 ~24 ~39 iron_block 0
setblock ~105 ~24 ~23 white_glazed_terracotta 0
setblock ~105 ~24 ~39 sea_lantern 0
setblock ~106 ~24 ~40 quartz_ore 0
setblock ~107 ~24 ~23 white_glazed_terracotta 0
fill ~107 ~24 ~40 ~107 ~25 ~40 sea_lantern 0
fill ~108 ~24 ~23 ~109 ~24 ~23 sea_lantern 0
setblock ~108 ~24 ~40 netherrack 0
fill ~109 ~24 ~40 ~109 ~25 ~40 clay 0
setblock ~110 ~24 ~23 concrete 0
setblock ~111 ~24 ~23 iron_block 0
setblock ~111 ~24 ~40 red_nether_brick 0
setblock ~112 ~24 ~23 concrete 0
fill ~113 ~24 ~23 ~114 ~24 ~23 sea_lantern 0
setblock ~113 ~24 ~41 netherrack 0
fill ~114 ~24 ~41 ~114 ~23 ~41 clay 0
setblock ~115 ~24 ~22 sea_lantern 0
setblock ~115 ~24 ~41 white_glazed_terracotta 0
setblock ~116 ~24 ~22 white_glazed_terracotta 0
setblock ~116 ~24 ~41 stone 4
fill ~117 ~24 ~22 ~117 ~25 ~22 sea_lantern 0
setblock ~117 ~24 ~41 netherrack 0
setblock ~118 ~24 ~22 concrete 0
fill ~118 ~24 ~41 ~118 ~27 ~41 sea_lantern 0
fill ~119 ~24 ~22 ~119 ~23 ~22 sea_lantern 0
fill ~119 ~24 ~41 ~120 ~24 ~41 white_glazed_terracotta 0
setblock ~120 ~24 ~22 iron_block 0
fill ~121 ~24 ~22 ~121 ~26 ~22 sea_lantern 0
setblock ~121 ~24 ~41 stone 4
setblock ~122 ~24 ~22 concrete 0
setblock ~122 ~24 ~42 white_glazed_terracotta 0
fill ~123 ~24 ~22 ~123 ~25 ~22 white_glazed_terracotta 0
setblock ~123 ~24 ~42 clay 0
fill ~124 ~24 ~42 ~125 ~24 ~42 white_glazed_terracotta 0
fill ~125 ~24 ~22 ~125 ~25 ~22 stone 4
setblock ~126 ~24 ~22 concrete 0
setblock ~126 ~24 ~42 iron_block 0
setblock ~127 ~24 ~22 sea_lantern 0
setblock ~127 ~24 ~42 stone 3
setblock ~128 ~24 ~22 iron_block 0
setblock ~130 ~24 ~42 wool 0
fill ~131 ~24 ~42 ~131 ~25 ~42 stone 4
setblock ~132 ~24 ~42 concrete 0
setblock ~134 ~24 ~42 iron_block 0
setblock ~135 ~24 ~42 stone 3
setblock ~136 ~24 ~42 concrete 0
setblock ~10 ~25 ~21 log2 1
fill ~10 ~25 ~22 ~10 ~26 ~22 soul_sand 0
fill ~11 ~25 ~20 ~12 ~25 ~20 stained_hardened_clay 7
fill ~11 ~25 ~23 ~11 ~25 ~24 stained_hardened_clay 7
setblock ~12 ~25 ~25 stained_hardened_clay 7
setblock ~12 ~25 ~26 soul_sand 0
setblock ~12 ~25 ~27 stained_hardened_clay 7
fill ~13 ~25 ~20 ~13 ~26 ~20 log2 1
setblock ~13 ~25 ~29 stained_hardened_clay 7
fill ~14 ~25 ~20 ~14 ~27 ~20 stained_hardened_clay 12
setblock ~14 ~25 ~30 stained_hardened_clay 12
setblock ~14 ~25 ~31 stained_hardened_clay 7
fill ~14 ~25 ~32 ~14 ~26 ~32 soul_sand 0
fill ~15 ~25 ~20 ~15 ~27 ~20 log2 1
fill ~15 ~25 ~33 ~15 ~25 ~35 stained_hardened_clay 7
fill ~16 ~25 ~20 ~17 ~25 ~20 stained_hardened_clay 7
setblock ~16 ~25 ~36 soul_sand 0
setblock ~16 ~25 ~37 stained_hardened_clay 7
setblock ~17 ~25 ~39 stained_hardened_clay 7
setblock ~18 ~25 ~20 log2 1
fill ~18 ~25 ~40 ~18 ~26 ~40 soul_sand 0
setblock ~19 ~25 ~20 stained_hardened_clay 7
setblock ~20 ~25 ~20 stained_hardened_clay 12
fill ~20 ~25 ~41 ~20 ~26 ~41 stained_hardened_clay 7
setblock ~21 ~25 ~20 log2 1
fill ~21 ~25 ~41 ~23 ~25 ~41 stained_hardened_clay 15
fill ~22 ~25 ~20 ~23 ~25 ~20 stained_hardened_clay 7
fill ~24 ~25 ~20 ~24 ~27 ~20 stained_hardened_clay 12
setblock ~24 ~25 ~41 nether_brick 0
setblock ~25 ~25 ~20 stained_hardened_clay 7
setblock ~25 ~25 ~41 stained_hardened_clay 15
setblock ~26 ~25 ~20 stained_hardened_clay 12
fill ~26 ~25 ~40 ~27 ~25 ~40 stained_hardened_clay 7
setblock ~27 ~25 ~20 log2 1
setblock ~28 ~25 ~40 stained_hardened_clay 12
setblock ~29 ~25 ~21 nether_brick 0
fill ~29 ~25 ~40 ~29 ~27 ~40 stained_hardened_clay 7
setblock ~30 ~25 ~21 stained_hardened_clay 7
fill ~31 ~25 ~22 ~31 ~26 ~22 stained_hardened_clay 7
setblock ~31 ~25 ~23 stained_hardened_clay 15
setblock ~31 ~25 ~24 stained_hardened_clay 12
setblock ~31 ~25 ~25 nether_brick 0
setblock ~31 ~25 ~26 stained_hardened_clay 7
setblock ~31 ~25 ~27 stained_hardened_clay 15
setblock ~31 ~25 ~28 stained_hardened_clay 7
setblock ~31 ~25 ~29 stained_hardened_clay 15
setblock ~31 ~25 ~30 nether_brick 0
setblock ~31 ~25 ~31 stained_hardened_clay 15
setblock ~31 ~25 ~32 stained_hardened_clay 7
setblock ~31 ~25 ~33 stained_hardened_clay 15
setblock ~31 ~25 ~34 stained_hardened_clay 7
setblock ~31 ~25 ~35 nether_brick 0
setblock ~31 ~25 ~37 nether_brick 0
setblock ~31 ~25 ~38 log2 1
setblock ~83 ~25 ~28 sea_lantern 0
setblock ~85 ~25 ~27 clay 0
setblock ~86 ~25 ~27 white_glazed_terracotta 0
setblock ~88 ~25 ~35 white_glazed_terracotta 0
fill ~89 ~25 ~26 ~89 ~29 ~26 sea_lantern 0
setblock ~89 ~25 ~35 clay 0
fill ~90 ~25 ~25 ~90 ~27 ~25 sea_lantern 0
setblock ~90 ~25 ~36 white_glazed_terracotta 0
setblock ~91 ~25 ~25 clay 0
setblock ~92 ~25 ~36 sea_lantern 0
fill ~93 ~25 ~24 ~94 ~25 ~24 sea_lantern 0
setblock ~93 ~25 ~36 stone 4
setblock ~95 ~25 ~37 clay 0
fill ~97 ~25 ~24 ~97 ~27 ~24 sea_lantern 0
setblock ~97 ~25 ~38 sea_lantern 0
setblock ~98 ~25 ~24 concrete 0
setblock ~98 ~25 ~38 concrete 0
setblock ~99 ~25 ~38 noteblock 0
fill ~100 ~25 ~24 ~101 ~25 ~24 white_glazed_terracotta 0
setblock ~100 ~25 ~38 sea_lantern 0
fill ~101 ~25 ~39 ~104 ~25 ~39 clay 0
fill ~102 ~25 ~23 ~103 ~25 ~23 clay 0
setblock ~105 ~25 ~23 clay 0
setblock ~105 ~25 ~39 red_nether_brick 0
setblock ~106 ~25 ~40 netherrack 0
setblock ~107 ~25 ~23 clay 0
fill ~108 ~25 ~23 ~108 ~23 ~23 sea_lantern 0
setblock ~108 ~25 ~40 concrete 0
setblock ~109 ~25 ~23 clay 0
setblock ~110 ~25 ~23 sea_lantern 0
setblock ~111 ~25 ~23 clay 0
setblock ~111 ~25 ~40 white_glazed_terracotta 0
setblock ~112 ~25 ~23 white_glazed_terracotta 0
fill ~112 ~25 ~40 ~112 ~26 ~40 netherrack 0
setblock ~113 ~25 ~23 clay 0
setblock ~113 ~25 ~41 clay 0
fill ~114 ~25 ~23 ~115 ~25 ~23 sea_lantern 0
setblock ~114 ~25 ~41 double_stone_slab 8
setblock ~115 ~25 ~41 sea_lantern 0
setblock ~116 ~25 ~23 concrete 0
fill ~116 ~25 ~41 ~117 ~25 ~41 red_nether_brick 0
fill ~118 ~25 ~22 ~120 ~25 ~22 white_glazed_terracotta 0
fill ~119 ~25 ~41 ~120 ~25 ~41 sea_lantern 0
setblock ~121 ~25 ~41 clay 0
fill ~122 ~25 ~22 ~122 ~27 ~22 white_glazed_terracotta 0
fill ~122 ~25 ~41 ~122 ~26 ~41 sea_lantern 0
setblock ~123 ~25 ~41 stone 4
fill ~124 ~25 ~41 ~125 ~25 ~41 stone 3
fill ~126 ~25 ~22 ~127 ~25 ~22 white_glazed_terracotta 0
setblock ~126 ~25 ~41 concrete 0
setblock ~127 ~25 ~42 concrete 0
setblock ~128 ~25 ~22 stone 4
setblock ~129 ~25 ~42 concrete 0
setblock ~130 ~25 ~42 iron_block 0
setblock ~132 ~25 ~42 iron_block 0
setblock ~133 ~25 ~42 concrete 0
setblock ~134 ~25 ~42 wool 0
setblock ~135 ~25 ~42 stone 4
fill ~136 ~25 ~42 ~137 ~25 ~42 white_glazed_terracotta 0
setblock ~9 ~26 ~21 soul_sand 0
setblock ~10 ~26 ~20 soul_sand 0
setblock ~10 ~26 ~23 stained_hardened_clay 12
fill ~10 ~26 ~24 ~10 ~27 ~24 soul_sand 0
setblock ~11 ~26 ~20 stained_hardened_clay 15
setblock ~11 ~26 ~25 soul_sand 0
fill ~11 ~26 ~26 ~11 ~27 ~26 stained_hardened_clay 7
setblock ~12 ~26 ~20 stained_hardened_clay 12
fill ~12 ~26 ~27 ~12 ~26 ~28 soul_sand 0
setblock ~12 ~26 ~29 stained_hardened_clay 12
setblock ~13 ~26 ~30 stained_hardened_clay 7
setblock ~13 ~26 ~31 soul_sand 0
setblock ~14 ~26 ~33 stained_hardened_clay 12
fill ~14 ~26 ~34 ~14 ~27 ~34 soul_sand 0
setblock ~15 ~26 ~35 soul_sand 0
setblock ~15 ~26 ~36 stained_hardened_clay 7
setblock ~16 ~26 ~20 soul_sand 0
setblock ~16 ~26 ~37 stained_hardened_clay 12
fill ~16 ~26 ~38 ~16 ~26 ~39 soul_sand 0
setblock ~17 ~26 ~20 nether_brick 0
setblock ~17 ~26 ~40 stained_hardened_clay 7
setblock ~18 ~26 ~20 soul_sand 0
setblock ~19 ~26 ~20 nether_brick 0
setblock ~19 ~26 ~41 stained_hardened_clay 12
setblock ~20 ~26 ~20 soul_sand 0
setblock ~21 ~26 ~20 nether_brick 0
setblock ~21 ~26 ~41 stained_hardened_clay 12
setblock ~22 ~26 ~20 soul_sand 0
setblock ~22 ~26 ~41 stained_hardened_clay 7
setblock ~23 ~26 ~20 log2 1
setblock ~23 ~26 ~41 stained_hardened_clay 12
setblock ~24 ~26 ~41 stained_hardened_clay 7
setblock ~25 ~26 ~20 nether_brick 0
setblock ~25 ~26 ~40 stained_hardened_clay 15
setblock ~26 ~26 ~20 soul_sand 0
setblock ~26 ~26 ~40 stained_hardened_clay 12
setblock ~27 ~26 ~20 nether_brick 0
setblock ~27 ~26 ~40 stained_hardened_clay 15
setblock ~28 ~26 ~20 soul_sand 0
setblock ~28 ~26 ~40 soul_sand 0
setblock ~29 ~26 ~21 soul_sand 0
setblock ~30 ~26 ~21 stained_hardened_clay 12
setblock ~30 ~26 ~40 soul_sand 0
setblock ~31 ~26 ~21 soul_sand 0
setblock ~31 ~26 ~39 stained_hardened_clay 12
setblock ~32 ~26 ~23 stained_hardened_clay 12
setblock ~32 ~26 ~24 soul_sand 0
setblock ~32 ~26 ~25 stained_hardened_clay 12
setblock ~32 ~26 ~26 soul_sand 0
setblock ~32 ~26 ~27 stained_hardened_clay 7
setblock ~32 ~26 ~28 soul_sand 0
setblock ~32 ~26 ~29 stained_hardened_clay 7
setblock ~32 ~26 ~30 soul_sand 0
setblock ~32 ~26 ~31 stained_hardened_clay 7
setblock ~32 ~26 ~32 soul_sand 0
setblock ~32 ~26 ~33 stained_hardened_clay 7
setblock ~32 ~26 ~34 soul_sand 0
setblock ~32 ~26 ~35 stained_hardened_clay 12
setblock ~32 ~26 ~36 soul_sand 0
setblock ~32 ~26 ~37 stained_hardened_clay 12
fill ~32 ~26 ~38 ~32 ~27 ~38 soul_sand 0
setblock ~81 ~26 ~28 clay 0
setblock ~82 ~26 ~28 iron_block 0
setblock ~83 ~26 ~28 clay 0
fill ~84 ~26 ~27 ~85 ~26 ~27 white_glazed_terracotta 0
fill ~86 ~26 ~27 ~86 ~29 ~27 sea_lantern 0
setblock ~87 ~26 ~26 clay 0
fill ~88 ~26 ~35 ~88 ~27 ~35 sea_lantern 0
setblock ~89 ~26 ~35 white_glazed_terracotta 0
setblock ~90 ~26 ~35 sea_lantern 0
setblock ~91 ~26 ~25 white_glazed_terracotta 0
fill ~92 ~26 ~36 ~92 ~27 ~36 white_glazed_terracotta 0
fill ~93 ~26 ~24 ~93 ~25 ~24 sea_lantern 0
setblock ~93 ~26 ~36 clay 0
setblock ~94 ~26 ~24 white_glazed_terracotta 0
setblock ~95 ~26 ~37 white_glazed_terracotta 0
setblock ~96 ~26 ~24 concrete 0
setblock ~97 ~26 ~37 white_glazed_terracotta 0
setblock ~98 ~26 ~24 white_glazed_terracotta 0
setblock ~98 ~26 ~38 white_glazed_terracotta 0
setblock ~99 ~26 ~38 netherrack 0
setblock ~100 ~26 ~24 sea_lantern 0
setblock ~100 ~26 ~38 mycelium 0
setblock ~101 ~26 ~24 white_glazed_terracotta 0
setblock ~101 ~26 ~39 netherrack 0
setblock ~102 ~26 ~24 iron_block 0
fill ~102 ~26 ~39 ~104 ~26 ~39 sea_lantern 0
setblock ~103 ~26 ~23 white_glazed_terracotta 0
setblock ~105 ~26 ~23 white_glazed_terracotta 0
setblock ~105 ~26 ~39 netherrack 0
fill ~106 ~26 ~39 ~106 ~28 ~39 sea_lantern 0
fill ~107 ~26 ~23 ~109 ~26 ~23 white_glazed_terracotta 0
setblock ~107 ~26 ~40 clay 0
setblock ~108 ~26 ~40 quartz_ore 0
setblock ~109 ~26 ~40 red_nether_brick 0
setblock ~110 ~26 ~23 concrete 0
setblock ~110 ~26 ~40 stone 3
fill ~111 ~26 ~23 ~112 ~26 ~23 sea_lantern 0
fill ~111 ~26 ~40 ~111 ~29 ~40 sea_lantern 0
setblock ~113 ~26 ~23 concrete 0
setblock ~113 ~26 ~41 sea_lantern 0
fill ~114 ~26 ~23 ~115 ~26 ~23 white_glazed_terracotta 0
fill ~114 ~26 ~41 ~115 ~26 ~41 netherrack 0
fill ~116 ~26 ~23 ~116 ~27 ~23 sea_lantern 0
setblock ~116 ~26 ~41 concrete 0
setblock ~117 ~26 ~23 white_glazed_terracotta 0
setblock ~117 ~26 ~41 netherrack 0
setblock ~118 ~26 ~22 iron_block 0
setblock ~119 ~26 ~22 clay 0
setblock ~119 ~26 ~41 white_glazed_terracotta 0
setblock ~120 ~26 ~22 iron_block 0
setblock ~120 ~26 ~41 stone 4
setblock ~121 ~26 ~41 stone 3
fill ~123 ~26 ~22 ~123 ~27 ~22 sea_lantern 0
setblock ~123 ~26 ~41 concrete 0
fill ~124 ~26 ~41 ~125 ~26 ~41 white_glazed_terracotta 0
setblock ~125 ~26 ~22 sea_lantern 0
setblock ~126 ~26 ~22 concrete 0
setblock ~126 ~26 ~41 stone 4
fill ~127 ~26 ~22 ~127 ~27 ~22 stone 3
setblock ~127 ~26 ~41 iron_block 0
setblock ~128 ~26 ~22 concrete 0
fill ~128 ~26 ~41 ~130 ~26 ~41 concrete 0
setblock ~131 ~26 ~41 iron_block 0
setblock ~132 ~26 ~41 wool 0
setblock ~133 ~26 ~42 stone 4
fill ~134 ~26 ~42 ~136 ~26 ~42 iron_block 0
setblock ~137 ~26 ~42 sea_lantern 0
fill ~9 ~27 ~20 ~10 ~27 ~20 stained_hardened_clay 12
setblock ~9 ~27 ~21 nether_brick 0
fill ~9 ~27 ~22 ~9 ~27 ~23 stained_hardened_clay 7
setblock ~10 ~27 ~25 stained_hardened_clay 7
fill ~11 ~27 ~20 ~12 ~27 ~20 log2 1
setblock ~11 ~27 ~27 stained_hardened_clay 7
setblock ~11 ~27 ~28 stained_hardened_clay 12
setblock ~12 ~27 ~29 stained_hardened_clay 7
setblock ~12 ~27 ~30 soul_sand 0
setblock ~13 ~27 ~20 stained_hardened_clay 7
fill ~13 ~27 ~31 ~13 ~27 ~33 stained_hardened_clay 7
setblock ~14 ~27 ~35 stained_hardened_clay 7
fill ~14 ~27 ~36 ~14 ~28 ~36 soul_sand 0
fill ~15 ~27 ~37 ~15 ~27 ~38 stained_hardened_clay 7
fill ~16 ~27 ~20 ~16 ~28 ~20 stained_hardened_clay 12
setblock ~16 ~27 ~39 stained_hardened_clay 7
fill ~16 ~27 ~40 ~16 ~29 ~40 soul_sand 0
setblock ~17 ~27 ~20 log2 1
setblock ~17 ~27 ~40 stained_hardened_clay 12
fill ~18 ~27 ~20 ~18 ~29 ~20 stained_hardened_clay 12
fill ~18 ~27 ~41 ~20 ~27 ~41 nether_brick 0
fill ~19 ~27 ~20 ~20 ~27 ~20 stained_hardened_clay 7
setblock ~21 ~27 ~20 log2 1
setblock ~21 ~27 ~41 stained_hardened_clay 15
fill ~22 ~27 ~20 ~22 ~29 ~20 stained_hardened_clay 12
fill ~22 ~27 ~41 ~22 ~28 ~41 nether_brick 0
setblock ~23 ~27 ~20 stained_hardened_clay 7
setblock ~23 ~27 ~41 stained_hardened_clay 15
fill ~24 ~27 ~41 ~24 ~28 ~41 nether_brick 0
fill ~25 ~27 ~20 ~27 ~27 ~20 stained_hardened_clay 7
fill ~25 ~27 ~40 ~31 ~27 ~40 stained_hardened_clay 7
setblock ~28 ~27 ~20 stained_hardened_clay 12
fill ~29 ~27 ~21 ~30 ~27 ~21 stained_hardened_clay 7
setblock ~31 ~27 ~21 nether_brick 0
setblock ~32 ~27 ~22 soul_sand 0
fill ~32 ~27 ~39 ~32 ~28 ~39 stained_hardened_clay 7
setblock ~33 ~27 ~23 nether_brick 0
setblock ~33 ~27 ~24 log2 1
fill ~33 ~27 ~25 ~33 ~27 ~28 stained_hardened_clay 7
setblock ~33 ~27 ~29 nether_brick 0
setblock ~33 ~27 ~30 stained_hardened_clay 7
setblock ~33 ~27 ~31 nether_brick 0
setblock ~33 ~27 ~32 stained_hardened_clay 7
setblock ~33 ~27 ~33 nether_brick 0
setblock ~33 ~27 ~34 stained_hardened_clay 7
setblock ~33 ~27 ~35 stained_hardened_clay 15
setblock ~33 ~27 ~36 stained_hardened_clay 12
setblock ~33 ~27 ~37 stained_hardened_clay 7
fill ~81 ~27 ~28 ~82 ~27 ~28 sea_lantern 0
setblock ~83 ~27 ~28 white_glazed_terracotta 0
fill ~84 ~27 ~27 ~84 ~26 ~27 white_glazed_terracotta 0
setblock ~85 ~27 ~27 clay 0
setblock ~87 ~27 ~26 white_glazed_terracotta 0
fill ~89 ~27 ~35 ~90 ~27 ~35 clay 0
setblock ~91 ~27 ~25 clay 0
setblock ~93 ~27 ~24 clay 0
fill ~93 ~27 ~36 ~93 ~30 ~36 sea_lantern 0
fill ~94 ~27 ~24 ~95 ~27 ~24 sea_lantern 0
setblock ~95 ~27 ~37 clay 0
fill ~96 ~27 ~24 ~96 ~28 ~24 white_glazed_terracotta 0
setblock ~97 ~27 ~37 clay 0
setblock ~98 ~27 ~24 concrete 0
setblock ~98 ~27 ~38 concrete 0
fill ~99 ~27 ~38 ~100 ~27 ~38 sea_lantern 0
fill ~100 ~27 ~24 ~100 ~28 ~24 white_glazed_terracotta 0
fill ~101 ~27 ~24 ~101 ~33 ~24 sea_lantern 0
setblock ~101 ~27 ~39 clay 0
fill ~102 ~27 ~24 ~102 ~28 ~24 white_glazed_terracotta 0
fill ~102 ~27 ~39 ~103 ~27 ~39 sea_lantern 0
fill ~103 ~27 ~24 ~103 ~29 ~24 sea_lantern 0
fill ~104 ~27 ~23 ~105 ~27 ~23 clay 0
fill ~104 ~27 ~39 ~105 ~27 ~39 clay 0
fill ~107 ~27 ~23 ~109 ~27 ~23 clay 0
fill ~107 ~27 ~40 ~108 ~27 ~40 sea_lantern 0
fill ~109 ~27 ~40 ~110 ~27 ~40 white_glazed_terracotta 0
fill ~110 ~27 ~23 ~110 ~28 ~23 white_glazed_terracotta 0
setblock ~111 ~27 ~23 clay 0
setblock ~112 ~27 ~23 sea_lantern 0
fill ~112 ~27 ~40 ~113 ~27 ~40 sea_lantern 0
setblock ~113 ~27 ~23 clay 0
fill ~114 ~27 ~23 ~114 ~32 ~23 sea_lantern 0
setblock ~114 ~27 ~41 sea_lantern 0
setblock ~115 ~27 ~23 double_stone_slab 8
setblock ~115 ~27 ~41 clay 0
fill ~116 ~27 ~41 ~116 ~28 ~41 sea_lantern 0
fill ~117 ~27 ~23 ~118 ~27 ~23 sea_lantern 0
setblock ~117 ~27 ~41 clay 0
setblock ~119 ~27 ~23 clay 0
fill ~119 ~27 ~41 ~121 ~27 ~41 sea_lantern 0
setblock ~120 ~27 ~22 stone 4
setblock ~121 ~27 ~22 concrete 0
setblock ~122 ~27 ~41 stone 4
setblock ~123 ~27 ~41 clay 0
setblock ~124 ~27 ~22 white_glazed_terracotta 0
fill ~124 ~27 ~41 ~124 ~28 ~41 sea_lantern 0
fill ~125 ~27 ~22 ~126 ~27 ~22 stone 4
fill ~125 ~27 ~41 ~125 ~28 ~41 white_glazed_terracotta 0
setblock ~126 ~27 ~41 stone 3
setblock ~127 ~27 ~41 stone 4
setblock ~128 ~27 ~22 white_glazed_terracotta 0
fill ~128 ~27 ~41 ~128 ~29 ~41 concrete 0
setblock ~129 ~27 ~41 stone 3
setblock ~130 ~27 ~41 white_glazed_terracotta 0
setblock ~131 ~27 ~41 stone 4
fill ~132 ~27 ~41 ~133 ~27 ~41 concrete 0
setblock ~134 ~27 ~41 stone 4
setblock ~135 ~27 ~41 stone 3
fill ~136 ~27 ~41 ~136 ~28 ~41 white_glazed_terracotta 0
setblock ~137 ~27 ~41 sea_lantern 0
setblock ~8 ~28 ~21 stained_hardened_clay 7
fill ~8 ~28 ~22 ~8 ~29 ~22 soul_sand 0
setblock ~9 ~28 ~20 stained_hardened_clay 15
setblock ~9 ~28 ~23 soul_sand 0
setblock ~9 ~28 ~24 stained_hardened_clay 7
setblock ~9 ~28 ~25 soul_sand 0
setblock ~10 ~28 ~20 stained_hardened_clay 12
setblock ~10 ~28 ~26 soul_sand 0
setblock ~10 ~28 ~27 stained_hardened_clay 12
setblock ~11 ~28 ~20 stained_hardened_clay 15
setblock ~11 ~28 ~28 stained_hardened_clay 7
setblock ~11 ~28 ~29 soul_sand 0
fill ~11 ~28 ~30 ~11 ~29 ~30 stained_hardened_clay 7
setblock ~12 ~28 ~20 stained_hardened_clay 12
setblock ~12 ~28 ~31 stained_hardened_clay 12
fill ~12 ~28 ~32 ~12 ~29 ~32 soul_sand 0
setblock ~13 ~28 ~20 stained_hardened_clay 15
setblock ~13 ~28 ~33 soul_sand 0
setblock ~13 ~28 ~34 stained_hardened_clay 7
setblock ~13 ~28 ~35 soul_sand 0
setblock ~14 ~28 ~20 stained_hardened_clay 7
fill ~14 ~28 ~37 ~14 ~29 ~37 stained_hardened_clay 7
setblock ~15 ~28 ~20 stained_hardened_clay 15
setblock ~15 ~28 ~38 stained_hardened_clay 7
setblock ~15 ~28 ~39 soul_sand 0
setblock ~17 ~28 ~20 stained_hardened_clay 15
setblock ~17 ~28 ~41 soul_sand 0
fill ~18 ~28 ~41 ~19 ~28 ~41 log2 1
setblock ~19 ~28 ~20 stained_hardened_clay 15
setblock ~20 ~28 ~20 soul_sand 0
fill ~20 ~28 ~41 ~21 ~28 ~41 stained_hardened_clay 7
setblock ~21 ~28 ~20 nether_brick 0
setblock ~23 ~28 ~20 nether_brick 0
setblock ~23 ~28 ~41 stained_hardened_clay 7
setblock ~24 ~28 ~20 soul_sand 0
fill ~25 ~28 ~20 ~25 ~29 ~20 log2 1
setblock ~25 ~28 ~40 nether_brick 0
setblock ~26 ~28 ~20 stained_hardened_clay 7
setblock ~26 ~28 ~40 stained_hardened_clay 12
setblock ~27 ~28 ~21 stained_hardened_clay 12
setblock ~27 ~28 ~40 stained_hardened_clay 15
setblock ~28 ~28 ~21 stained_hardened_clay 7
setblock ~28 ~28 ~40 stained_hardened_clay 12
setblock ~29 ~28 ~21 stained_hardened_clay 12
fill ~29 ~28 ~40 ~29 ~30 ~40 nether_brick 0
setblock ~30 ~28 ~21 stained_hardened_clay 7
setblock ~30 ~28 ~40 soul_sand 0
setblock ~31 ~28 ~21 soul_sand 0
fill ~31 ~28 ~40 ~31 ~31 ~40 stained_hardened_clay 7
fill ~32 ~28 ~21 ~32 ~29 ~21 stained_hardened_clay 7
setblock ~33 ~28 ~22 stained_hardened_clay 7
setblock ~33 ~28 ~23 soul_sand 0
setblock ~33 ~28 ~37 soul_sand 0
setblock ~33 ~28 ~38 stained_hardened_clay 7
setblock ~34 ~28 ~24 soul_sand 0
setblock ~34 ~28 ~25 stained_hardened_clay 7
setblock ~34 ~28 ~26 soul_sand 0
fill ~34 ~28 ~27 ~34 ~29 ~27 stained_hardened_clay 7
setblock ~34 ~28 ~28 soul_sand 0
setblock ~34 ~28 ~29 stained_hardened_clay 7
setblock ~34 ~28 ~30 stained_hardened_clay 12
setblock ~34 ~28 ~31 stained_hardened_clay 7
setblock ~34 ~28 ~32 stained_hardened_clay 12
fill ~34 ~28 ~33 ~34 ~29 ~33 stained_hardened_clay 7
setblock ~34 ~28 ~34 soul_sand 0
fill ~34 ~28 ~35 ~34 ~29 ~35 stained_hardened_clay 7
setblock ~34 ~28 ~36 soul_sand 0
setblock ~81 ~28 ~28 clay 0
setblock ~82 ~28 ~28 white_glazed_terracotta 0
fill ~83 ~28 ~28 ~83 ~30 ~28 clay 0
fill ~84 ~28 ~27 ~84 ~29 ~27 sea_lantern 0
setblock ~85 ~28 ~27 white_glazed_terracotta 0
setblock ~87 ~28 ~27 sea_lantern 0
setblock ~88 ~28 ~26 iron_block 0
setblock ~88 ~28 ~35 clay 0
setblock ~89 ~28 ~35 white_glazed_terracotta 0
setblock ~90 ~28 ~26 iron_block 0
fill ~90 ~28 ~35 ~90 ~31 ~35 sea_lantern 0
fill ~91 ~28 ~25 ~91 ~29 ~25 sea_lantern 0
setblock ~91 ~28 ~36 clay 0
setblock ~92 ~28 ~36 concrete 0
setblock ~93 ~28 ~25 concrete 0
setblock ~94 ~28 ~24 iron_block 0
fill ~94 ~28 ~36 ~94 ~29 ~36 white_glazed_terracotta 0
setblock ~95 ~28 ~24 clay 0
fill ~95 ~28 ~37 ~96 ~28 ~37 white_glazed_terracotta 0
setblock ~97 ~28 ~24 clay 0
setblock ~97 ~28 ~37 quartz_ore 0
setblock ~98 ~28 ~24 iron_block 0
setblock ~98 ~28 ~38 iron_ore 0
setblock ~99 ~28 ~24 clay 0
fill ~99 ~28 ~38 ~99 ~27 ~38 sea_lantern 0
fill ~100 ~28 ~38 ~100 ~29 ~38 netherrack 0
setblock ~101 ~28 ~39 white_glazed_terracotta 0
setblock ~102 ~28 ~39 brown_glazed_terracotta 0
setblock ~103 ~28 ~39 soul_sand 0
fill ~104 ~28 ~24 ~104 ~29 ~24 sea_lantern 0
fill ~104 ~28 ~39 ~105 ~28 ~39 stone 4
setblock ~105 ~28 ~23 white_glazed_terracotta 0
setblock ~107 ~28 ~23 sea_lantern 0
setblock ~107 ~28 ~40 clay 0
fill ~108 ~28 ~23 ~110 ~28 ~23 white_glazed_terracotta 0
fill ~108 ~28 ~40 ~108 ~29 ~40 white_glazed_terracotta 0
setblock ~109 ~28 ~40 clay 0
fill ~110 ~28 ~40 ~110 ~30 ~40 white_glazed_terracotta 0
setblock ~111 ~28 ~23 concrete 0
setblock ~112 ~28 ~23 white_glazed_terracotta 0
fill ~112 ~28 ~40 ~112 ~27 ~40 sea_lantern 0
setblock ~113 ~28 ~23 concrete 0
setblock ~113 ~28 ~40 clay 0
setblock ~114 ~28 ~40 white_glazed_terracotta 0
setblock ~115 ~28 ~23 white_glazed_terracotta 0
setblock ~115 ~28 ~41 stone 3
setblock ~116 ~28 ~23 concrete 0
setblock ~117 ~28 ~23 iron_block 0
fill ~117 ~28 ~41 ~121 ~28 ~41 white_glazed_terracotta 0
setblock ~118 ~28 ~23 concrete 0
fill ~119 ~28 ~23 ~120 ~28 ~23 white_glazed_terracotta 0
setblock ~121 ~28 ~22 stone 4
setblock ~122 ~28 ~22 concrete 0
setblock ~122 ~28 ~41 sea_lantern 0
fill ~123 ~28 ~22 ~123 ~29 ~22 white_glazed_terracotta 0
setblock ~123 ~28 ~41 white_glazed_terracotta 0
setblock ~124 ~28 ~22 concrete 0
setblock ~125 ~28 ~22 stone 3
setblock ~126 ~28 ~22 concrete 0
setblock ~126 ~28 ~41 stone 4
setblock ~127 ~28 ~22 sea_lantern 0
setblock ~127 ~28 ~41 iron_block 0
setblock ~128 ~28 ~22 iron_block 0
setblock ~129 ~28 ~22 stone 3
fill ~129 ~28 ~41 ~131 ~28 ~41 concrete 0
setblock ~132 ~28 ~41 white_glazed_terracotta 0
setblock ~133 ~28 ~41 wool 0
setblock ~134 ~28 ~41 iron_block 0
setblock ~135 ~28 ~41 white_glazed_terracotta 0
setblock ~137 ~28 ~41 concrete 0
setblock ~7 ~29 ~21 nether_brick 0
fill ~8 ~29 ~20 ~8 ~32 ~20 stained_hardened_clay 12
setblock ~8 ~29 ~23 stained_hardened_clay 7
fill ~8 ~29 ~24 ~8 ~30 ~24 soul_sand 0
setblock ~9 ~29 ~20 stained_hardened_clay 7
fill ~9 ~29 ~25 ~9 ~29 ~26 stained_hardened_clay 7
fill ~10 ~29 ~20 ~11 ~29 ~20 log2 1
setblock ~10 ~29 ~27 stained_hardened_clay 7
setblock ~10 ~29 ~28 soul_sand 0
setblock ~10 ~29 ~29 stained_hardened_clay 7
setblock ~11 ~29 ~31 stained_hardened_clay 7
setblock ~12 ~29 ~20 stained_hardened_clay 7
setblock ~12 ~29 ~33 stained_hardened_clay 7
fill ~12 ~29 ~34 ~12 ~30 ~34 soul_sand 0
fill ~13 ~29 ~20 ~14 ~29 ~20 log2 1
fill ~13 ~29 ~35 ~13 ~29 ~36 stained_hardened_clay 7
setblock ~14 ~29 ~38 soul_sand 0
setblock ~14 ~29 ~39 stained_hardened_clay 7
fill ~15 ~29 ~20 ~16 ~29 ~20 stained_hardened_clay 7
fill ~15 ~29 ~40 ~15 ~30 ~40 stained_hardened_clay 7
setblock ~17 ~29 ~20 nether_brick 0
setblock ~17 ~29 ~41 stained_hardened_clay 15
setblock ~18 ~29 ~41 nether_brick 0
fill ~19 ~29 ~20 ~19 ~30 ~20 nether_brick 0
setblock ~19 ~29 ~41 stained_hardened_clay 15
fill ~20 ~29 ~20 ~21 ~29 ~20 log2 1
setblock ~20 ~29 ~41 nether_brick 0
fill ~21 ~29 ~41 ~23 ~29 ~41 stained_hardened_clay 15
fill ~23 ~29 ~20 ~23 ~31 ~20 log2 1
setblock ~24 ~29 ~20 stained_hardened_clay 12
setblock ~24 ~29 ~40 stained_hardened_clay 7
setblock ~25 ~29 ~40 log2 1
setblock ~26 ~29 ~21 log2 1
setblock ~26 ~29 ~40 stained_hardened_clay 7
setblock ~27 ~29 ~21 stained_hardened_clay 15
setblock ~27 ~29 ~40 nether_brick 0
setblock ~28 ~29 ~21 log2 1
setblock ~28 ~29 ~40 stained_hardened_clay 7
setblock ~29 ~29 ~21 stained_hardened_clay 15
setblock ~30 ~29 ~21 log2 1
setblock ~30 ~29 ~40 stained_hardened_clay 7
setblock ~31 ~29 ~21 stained_hardened_clay 7
fill ~32 ~29 ~40 ~32 ~30 ~40 soul_sand 0
setblock ~33 ~29 ~21 stained_hardened_clay 7
setblock ~33 ~29 ~39 stained_hardened_clay 7
setblock ~34 ~29 ~22 stained_hardened_clay 12
fill ~34 ~29 ~23 ~34 ~29 ~24 stained_hardened_clay 7
setblock ~34 ~29 ~25 nether_brick 0
setblock ~34 ~29 ~26 stained_hardened_clay 12
setblock ~34 ~29 ~28 stained_hardened_clay 7
setblock ~34 ~29 ~29 nether_brick 0
setblock ~34 ~29 ~30 stained_hardened_clay 7
setblock ~34 ~29 ~31 log2 1
setblock ~34 ~29 ~32 stained_hardened_clay 7
setblock ~34 ~29 ~34 stained_hardened_clay 12
setblock ~34 ~29 ~36 stained_hardened_clay 12
setblock ~34 ~29 ~37 stained_hardened_clay 7
setblock ~34 ~29 ~38 stained_hardened_clay 12
fill ~81 ~29 ~28 ~82 ~29 ~28 sea_lantern 0
setblock ~85 ~29 ~27 sea_lantern 0
setblock ~87 ~29 ~27 clay 0
setblock ~88 ~29 ~26 sea_lantern 0
setblock ~88 ~29 ~35 sea_lantern 0
setblock ~89 ~29 ~35 clay 0
setblock ~90 ~29 ~26 white_glazed_terracotta 0
setblock ~91 ~29 ~35 clay 0
fill ~92 ~29 ~36 ~92 ~30 ~36 white_glazed_terracotta 0
setblock ~93 ~29 ~25 clay 0
fill ~94 ~29 ~25 ~94 ~30 ~25 sea_lantern 0
fill ~95 ~29 ~24 ~99 ~29 ~24 sea_lantern 0
fill ~95 ~29 ~37 ~95 ~30 ~37 white_glazed_terracotta 0
setblock ~96 ~29 ~37 clay 0
setblock ~97 ~29 ~37 sea_lantern 0
fill ~98 ~29 ~38 ~100 ~29 ~38 netherrack 0
fill ~100 ~29 ~24 ~100 ~30 ~24 concrete 0
setblock ~101 ~29 ~39 sea_lantern 0
setblock ~102 ~29 ~24 sea_lantern 0
setblock ~102 ~29 ~39 red_nether_brick 0
setblock ~103 ~29 ~39 sea_lantern 0
fill ~104 ~29 ~39 ~104 ~30 ~39 black_glazed_terracotta 0
setblock ~105 ~29 ~24 sea_lantern 0
fill ~105 ~29 ~39 ~107 ~29 ~39 clay 0
setblock ~107 ~29 ~23 clay 0
fill ~108 ~29 ~23 ~110 ~29 ~23 sea_lantern 0
setblock ~109 ~29 ~40 sea_lantern 0
setblock ~111 ~29 ~23 clay 0
fill ~112 ~29 ~23 ~114 ~29 ~23 sea_lantern 0
setblock ~112 ~29 ~40 soul_sand 0
fill ~113 ~29 ~40 ~114 ~29 ~40 netherrack 0
setblock ~115 ~29 ~23 clay 0
setblock ~115 ~29 ~40 sea_lantern 0
fill ~116 ~29 ~23 ~116 ~30 ~23 sea_lantern 0
fill ~116 ~29 ~40 ~116 ~30 ~40 netherrack 0
setblock ~117 ~29 ~23 clay 0
setblock ~117 ~29 ~41 red_nether_brick 0
fill ~118 ~29 ~23 ~119 ~29 ~23 sea_lantern 0
setblock ~118 ~29 ~41 stone 3
fill ~119 ~29 ~41 ~120 ~29 ~41 sea_lantern 0
setblock ~120 ~29 ~23 white_glazed_terracotta 0
fill ~121 ~29 ~23 ~122 ~29 ~23 sea_lantern 0
setblock ~121 ~29 ~41 clay 0
setblock ~122 ~29 ~41 stone 3
setblock ~123 ~29 ~41 wool 8
fill ~124 ~29 ~22 ~125 ~29 ~22 stone 4
setblock ~124 ~29 ~41 stone 4
setblock ~125 ~29 ~41 sea_lantern 0
setblock ~126 ~29 ~22 white_glazed_terracotta 0
fill ~126 ~29 ~41 ~127 ~29 ~41 stone 3
setblock ~127 ~29 ~22 concrete 0
setblock ~128 ~29 ~22 stone 4
setblock ~129 ~29 ~22 concrete 0
fill ~129 ~29 ~41 ~129 ~28 ~41 concrete 0
setblock ~130 ~29 ~41 stone 4
setblock ~131 ~29 ~41 stone 3
setblock ~132 ~29 ~41 stone 4
fill ~133 ~29 ~41 ~133 ~30 ~41 concrete 0
setblock ~134 ~29 ~41 stone 4
setblock ~135 ~29 ~41 stone 3
fill ~136 ~29 ~41 ~137 ~29 ~41 sea_lantern 0
fill ~7 ~30 ~20 ~7 ~31 ~20 stained_hardened_clay 7
setblock ~7 ~30 ~21 soul_sand 0
setblock ~7 ~30 ~22 stained_hardened_clay 7
setblock ~7 ~30 ~23 soul_sand 0
fill ~8 ~30 ~25 ~8 ~30 ~26 soul_sand 0
setblock ~9 ~30 ~20 planks 5
setblock ~9 ~30 ~27 soul_sand 0
fill ~9 ~30 ~28 ~9 ~31 ~28 stained_hardened_clay 7
setblock ~10 ~30 ~20 soul_sand 0
fill ~10 ~30 ~29 ~10 ~30 ~30 soul_sand 0
setblock ~10 ~30 ~31 stained_hardened_clay 12
setblock ~11 ~30 ~20 nether_brick 0
setblock ~11 ~30 ~32 stained_hardened_clay 7
setblock ~11 ~30 ~33 soul_sand 0
fill ~12 ~30 ~20 ~12 ~32 ~20 stained_hardened_clay 12
fill ~12 ~30 ~35 ~12 ~30 ~36 soul_sand 0
setblock ~13 ~30 ~20 stained_hardened_clay 15
setblock ~13 ~30 ~37 soul_sand 0
fill ~13 ~30 ~38 ~13 ~31 ~38 stained_hardened_clay 7
setblock ~14 ~30 ~20 stained_hardened_clay 12
setblock ~14 ~30 ~39 stained_hardened_clay 12
setblock ~15 ~30 ~20 stained_hardened_clay 15
setblock ~16 ~30 ~20 stained_hardened_clay 12
setblock ~16 ~30 ~41 log2 1
setblock ~17 ~30 ~20 stained_hardened_clay 15
setblock ~17 ~30 ~41 stained_hardened_clay 12
setblock ~18 ~30 ~20 soul_sand 0
fill ~18 ~30 ~41 ~19 ~30 ~41 log2 1
setblock ~20 ~30 ~20 stained_hardened_clay 12
fill ~20 ~30 ~41 ~21 ~30 ~41 stained_hardened_clay 7
setblock ~21 ~30 ~20 stained_hardened_clay 15
setblock ~22 ~30 ~20 soul_sand 0
setblock ~22 ~30 ~41 log2 1
setblock ~23 ~30 ~40 stained_hardened_clay 15
setblock ~24 ~30 ~20 soul_sand 0
setblock ~24 ~30 ~40 log2 1
setblock ~25 ~30 ~20 planks 5
setblock ~25 ~30 ~40 stained_hardened_clay 15
setblock ~26 ~30 ~21 stained_hardened_clay 7
setblock ~26 ~30 ~40 stained_hardened_clay 12
setblock ~27 ~30 ~21 soul_sand 0
setblock ~27 ~30 ~40 stained_hardened_clay 15
fill ~28 ~30 ~21 ~28 ~31 ~21 stained_hardened_clay 7
setblock ~28 ~30 ~40 soul_sand 0
setblock ~29 ~30 ~21 soul_sand 0
fill ~30 ~30 ~21 ~30 ~33 ~21 stained_hardened_clay 7
setblock ~30 ~30 ~40 soul_sand 0
setblock ~31 ~30 ~21 soul_sand 0
setblock ~32 ~30 ~21 stained_hardened_clay 12
setblock ~33 ~30 ~21 soul_sand 0
fill ~33 ~30 ~40 ~33 ~33 ~40 stained_hardened_clay 7
setblock ~34 ~30 ~22 soul_sand 0
fill ~34 ~30 ~39 ~34 ~31 ~39 stained_hardened_clay 7
setblock ~35 ~30 ~23 stained_hardened_clay 12
setblock ~35 ~30 ~24 nether_brick 0
setblock ~35 ~30 ~25 stained_hardened_clay 7
setblock ~35 ~30 ~26 nether_brick 0
setblock ~35 ~30 ~27 stained_hardened_clay 12
setblock ~35 ~30 ~28 stained_hardened_clay 15
setblock ~35 ~30 ~29 stained_hardened_clay 12
setblock ~35 ~30 ~30 stained_hardened_clay 15
setblock ~35 ~30 ~31 stained_hardened_clay 7
setblock ~35 ~30 ~32 nether_brick 0
setblock ~35 ~30 ~33 soul_sand 0
fill ~35 ~30 ~34 ~35 ~30 ~35 stained_hardened_clay 7
setblock ~35 ~30 ~36 log2 1
setblock ~35 ~30 ~37 soul_sand 0
setblock ~35 ~30 ~38 stained_hardened_clay 7
fill ~81 ~30 ~28 ~81 ~29 ~28 sea_lantern 0
setblock ~82 ~30 ~28 concrete 0
fill ~84 ~30 ~28 ~84 ~31 ~28 white_glazed_terracotta 0
setblock ~85 ~30 ~27 concrete 0
fill ~86 ~30 ~27 ~86 ~31 ~27 stone 4
fill ~87 ~30 ~27 ~87 ~31 ~27 white_glazed_terracotta 0
fill ~88 ~30 ~26 ~89 ~30 ~26 white_glazed_terracotta 0
setblock ~88 ~30 ~34 concrete 0
setblock ~89 ~30 ~35 white_glazed_terracotta 0
fill ~90 ~30 ~26 ~90 ~31 ~26 iron_block 0
setblock ~91 ~30 ~25 white_glazed_terracotta 0
setblock ~91 ~30 ~35 white_glazed_terracotta 0
setblock ~93 ~30 ~25 concrete 0
fill ~94 ~30 ~36 ~94 ~32 ~36 concrete 0
setblock ~95 ~30 ~25 white_glazed_terracotta 0
fill ~96 ~30 ~24 ~97 ~30 ~24 white_glazed_terracotta 0
fill ~96 ~30 ~37 ~96 ~32 ~37 sea_lantern 0
setblock ~97 ~30 ~37 white_glazed_terracotta 0
setblock ~98 ~30 ~24 stone 4
setblock ~98 ~30 ~38 iron_block 0
fill ~99 ~30 ~24 ~99 ~32 ~24 sea_lantern 0
setblock ~99 ~30 ~38 red_nether_brick 0
setblock ~100 ~30 ~38 white_glazed_terracotta 0
setblock ~101 ~30 ~38 clay 0
setblock ~102 ~30 ~24 white_glazed_terracotta 0
setblock ~102 ~30 ~39 clay 0
setblock ~103 ~30 ~24 concrete 0
setblock ~103 ~30 ~39 netherrack 0
setblock ~104 ~30 ~24 white_glazed_terracotta 0
setblock ~105 ~30 ~24 clay 0
fill ~105 ~30 ~39 ~107 ~30 ~39 white_glazed_terracotta 0
fill ~106 ~30 ~24 ~106 ~32 ~24 sea_lantern 0
fill ~107 ~30 ~24 ~107 ~31 ~24 concrete 0
setblock ~108 ~30 ~23 clay 0
setblock ~108 ~30 ~40 concrete 0
setblock ~109 ~30 ~23 iron_block 0
setblock ~109 ~30 ~40 double_stone_slab 8
setblock ~110 ~30 ~23 sea_lantern 0
setblock ~111 ~30 ~23 white_glazed_terracotta 0
setblock ~111 ~30 ~40 clay 0
fill ~112 ~30 ~23 ~114 ~30 ~23 sea_lantern 0
setblock ~112 ~30 ~40 double_stone_slab 8
setblock ~113 ~30 ~40 stone 5
setblock ~114 ~30 ~40 concrete 0
setblock ~115 ~30 ~23 concrete 0
setblock ~115 ~30 ~40 stained_hardened_clay 12
setblock ~117 ~30 ~23 white_glazed_terracotta 0
setblock ~117 ~30 ~40 stone 3
setblock ~118 ~30 ~23 stone 4
setblock ~118 ~30 ~41 redstone_ore 0
setblock ~119 ~30 ~23 white_glazed_terracotta 0
setblock ~119 ~30 ~41 concrete 0
setblock ~120 ~30 ~23 concrete 0
setblock ~120 ~30 ~41 soul_sand 0
setblock ~121 ~30 ~23 wool 0
setblock ~121 ~30 ~41 concrete 0
setblock ~122 ~30 ~23 stone 4
fill ~122 ~30 ~41 ~122 ~31 ~41 sea_lantern 0
setblock ~123 ~30 ~23 concrete 0
setblock ~123 ~30 ~41 concrete 0
setblock ~124 ~30 ~23 white_glazed_terracotta 0
setblock ~124 ~30 ~41 clay 0
setblock ~125 ~30 ~22 white_glazed_terracotta 0
setblock ~125 ~30 ~41 concrete 0
setblock ~126 ~30 ~22 iron_block 0
setblock ~126 ~30 ~41 stone 4
setblock ~127 ~30 ~22 white_glazed_terracotta 0
setblock ~127 ~30 ~41 iron_block 0
setblock ~128 ~30 ~22 concrete 0
setblock ~128 ~30 ~41 white_glazed_terracotta 0
setblock ~129 ~30 ~22 stone 3
setblock ~129 ~30 ~41 iron_block 0
setblock ~130 ~30 ~41 white_glazed_terracotta 0
setblock ~131 ~30 ~41 wool 0
setblock ~132 ~30 ~41 concrete 0
fill ~134 ~30 ~41 ~136 ~30 ~41 white_glazed_terracotta 0
setblock ~137 ~30 ~41 iron_block 0
setblock ~6 ~31 ~20 soul_sand 0
setblock ~6 ~31 ~21 stained_hardened_clay 12
setblock ~6 ~31 ~22 soul_sand 0
setblock ~6 ~31 ~23 stained_hardened_clay 7
setblock ~7 ~31 ~24 stained_hardened_clay 12
setblock ~7 ~31 ~25 stained_hardened_clay 7
setblock ~8 ~31 ~26 soul_sand 0
setblock ~8 ~31 ~27 stained_hardened_clay 7
setblock ~9 ~31 ~20 nether_brick 0
fill ~9 ~31 ~29 ~9 ~31 ~30 stained_hardened_clay 7
setblock ~10 ~31 ~20 stained_hardened_clay 7
setblock ~10 ~31 ~31 stained_hardened_clay 7
setblock ~10 ~31 ~32 soul_sand 0
setblock ~11 ~31 ~20 log2 1
fill ~11 ~31 ~33 ~11 ~31 ~35 stained_hardened_clay 7
setblock ~12 ~31 ~36 soul_sand 0
setblock ~12 ~31 ~37 stained_hardened_clay 7
fill ~13 ~31 ~20 ~13 ~32 ~20 nether_brick 0
setblock ~13 ~31 ~39 stained_hardened_clay 7
setblock ~14 ~31 ~20 log2 1
setblock ~14 ~31 ~40 stained_hardened_clay 12
setblock ~15 ~31 ~20 nether_brick 0
fill ~15 ~31 ~41 ~21 ~31 ~41 stained_hardened_clay 15
setblock ~16 ~31 ~20 log2 1
setblock ~17 ~31 ~20 nether_brick 0
fill ~18 ~31 ~20 ~18 ~32 ~20 stained_hardened_clay 7
setblock ~19 ~31 ~20 log2 1
fill ~20 ~31 ~20 ~21 ~31 ~20 stained_hardened_clay 7
setblock ~22 ~31 ~20 log2 1
setblock ~22 ~31 ~40 log2 1
setblock ~23 ~31 ~40 nether_brick 0
setblock ~24 ~31 ~20 log2 1
setblock ~24 ~31 ~40 stained_hardened_clay 7
setblock ~25 ~31 ~21 nether_brick 0
setblock ~25 ~31 ~40 planks 5
fill ~26 ~31 ~21 ~26 ~32 ~21 log2 1
setblock ~26 ~31 ~40 stained_hardened_clay 7
setblock ~27 ~31 ~21 nether_brick 0
setblock ~27 ~31 ~40 log2 1
setblock ~28 ~31 ~40 stained_hardened_clay 12
setblock ~29 ~31 ~21 nether_brick 0
fill ~29 ~31 ~40 ~31 ~31 ~40 stained_hardened_clay 7
setblock ~31 ~31 ~21 nether_brick 0
fill ~32 ~31 ~21 ~34 ~31 ~21 stained_hardened_clay 7
setblock ~32 ~31 ~40 stained_hardened_clay 12
setblock ~35 ~31 ~22 stained_hardened_clay 7
setblock ~35 ~31 ~38 stained_hardened_clay 12
setblock ~35 ~31 ~39 stained_hardened_clay 15
fill ~36 ~31 ~23 ~36 ~32 ~23 stained_hardened_clay 7
fill ~36 ~31 ~24 ~36 ~31 ~23 stained_hardened_clay 7
setblock ~36 ~31 ~25 stained_hardened_clay 15
fill ~36 ~31 ~26 ~36 ~31 ~27 stained_hardened_clay 7
setblock ~36 ~31 ~28 stained_hardened_clay 12
setblock ~36 ~31 ~29 log2 1
setblock ~36 ~31 ~30 stained_hardened_clay 7
setblock ~36 ~31 ~31 nether_brick 0
setblock ~36 ~31 ~32 stained_hardened_clay 7
setblock ~36 ~31 ~33 nether_brick 0
fill ~36 ~31 ~34 ~36 ~31 ~35 stained_hardened_clay 7
setblock ~36 ~31 ~36 stained_hardened_clay 12
setblock ~36 ~31 ~37 stained_hardened_clay 7
setblock ~81 ~31 ~29 sea_lantern 0
setblock ~82 ~31 ~28 stone 4
setblock ~83 ~31 ~28 concrete 0
setblock ~85 ~31 ~27 sea_lantern 0
fill ~88 ~31 ~26 ~88 ~30 ~26 white_glazed_terracotta 0
setblock ~88 ~31 ~34 sea_lantern 0
setblock ~89 ~31 ~26 sea_lantern 0
setblock ~89 ~31 ~35 clay 0
setblock ~91 ~31 ~25 sea_lantern 0
setblock ~91 ~31 ~35 sea_lantern 0
setblock ~92 ~31 ~36 stone 4
setblock ~93 ~31 ~25 clay 0
setblock ~93 ~31 ~36 white_glazed_terracotta 0
setblock ~94 ~31 ~25 white_glazed_terracotta 0
setblock ~95 ~31 ~25 clay 0
setblock ~95 ~31 ~37 sea_lantern 0
setblock ~96 ~31 ~25 white_glazed_terracotta 0
fill ~97 ~31 ~24 ~101 ~31 ~24 sea_lantern 0
setblock ~97 ~31 ~37 clay 0
fill ~98 ~31 ~37 ~98 ~32 ~37 stone 4
setblock ~99 ~31 ~38 sea_lantern 0
setblock ~100 ~31 ~38 stone 4
setblock ~101 ~31 ~38 sea_lantern 0
setblock ~102 ~31 ~24 concrete 0
setblock ~102 ~31 ~39 netherrack 0
fill ~103 ~31 ~24 ~106 ~31 ~24 sea_lantern 0
fill ~103 ~31 ~39 ~103 ~32 ~39 sea_lantern 0
setblock ~104 ~31 ~39 clay 0
setblock ~105 ~31 ~39 double_stone_slab 8
fill ~106 ~31 ~30 ~107 ~31 ~30 wool 7
fill ~106 ~31 ~31 ~108 ~31 ~31 concrete 7
fill ~106 ~31 ~39 ~108 ~31 ~39 sea_lantern 0
setblock ~108 ~31 ~24 white_glazed_terracotta 0
setblock ~108 ~31 ~30 bedrock 0
setblock ~109 ~31 ~24 sea_lantern 0
setblock ~109 ~31 ~40 sea_lantern 0
setblock ~110 ~31 ~23 stone 4
setblock ~110 ~31 ~40 concrete 0
setblock ~111 ~31 ~23 clay 0
setblock ~111 ~31 ~40 mycelium 0
setblock ~112 ~31 ~23 white_glazed_terracotta 0
fill ~112 ~31 ~40 ~113 ~31 ~40 clay 0
setblock ~113 ~31 ~23 sea_lantern 0
fill ~114 ~31 ~40 ~114 ~32 ~40 white_glazed_terracotta 0
setblock ~115 ~31 ~23 sea_lantern 0
setblock ~115 ~31 ~40 red_nether_brick 0
setblock ~116 ~31 ~23 clay 0
fill ~116 ~31 ~40 ~117 ~31 ~40 white_glazed_terracotta 0
setblock ~117 ~31 ~23 sea_lantern 0
setblock ~118 ~31 ~23 white_glazed_terracotta 0
setblock ~118 ~31 ~40 stone 3
setblock ~119 ~31 ~23 stone 4
setblock ~119 ~31 ~40 noteblock 0
fill ~120 ~31 ~23 ~121 ~31 ~23 sea_lantern 0
setblock ~120 ~31 ~40 stone 4
setblock ~121 ~31 ~41 soul_sand 0
fill ~122 ~31 ~23 ~122 ~32 ~23 concrete 0
setblock ~123 ~31 ~23 clay 0
setblock ~123 ~31 ~41 clay 0
setblock ~124 ~31 ~23 stone 3
setblock ~124 ~31 ~41 stone 6
setblock ~125 ~31 ~23 sea_lantern 0
setblock ~125 ~31 ~41 stone 4
fill ~126 ~31 ~22 ~127 ~31 ~22 concrete 0
setblock ~126 ~31 ~41 concrete 0
setblock ~127 ~31 ~41 white_glazed_terracotta 0
setblock ~128 ~31 ~22 white_glazed_terracotta 0
setblock ~128 ~31 ~41 stone 3
setblock ~129 ~31 ~22 stone 4
fill ~129 ~31 ~41 ~130 ~31 ~41 stone 4
setblock ~131 ~31 ~41 stone 3
fill ~132 ~31 ~41 ~134 ~31 ~41 stone 4
setblock ~135 ~31 ~41 clay 0
fill ~136 ~31 ~41 ~136 ~32 ~41 stone 4
setblock ~137 ~31 ~41 sea_lantern 0
setblock ~5 ~32 ~21 soul_sand 0
fill ~5 ~32 ~22 ~5 ~33 ~22 stained_hardened_clay 7
setblock ~6 ~32 ~20 stained_hardened_clay 12
setblock ~6 ~32 ~23 stained_hardened_clay 12
setblock ~6 ~32 ~24 soul_sand 0
setblock ~7 ~32 ~20 nether_brick 0
setblock ~7 ~32 ~25 soul_sand 0
setblock ~7 ~32 ~26 stained_hardened_clay 7
setblock ~7 ~32 ~27 soul_sand 0
setblock ~8 ~32 ~28 soul_sand 0
setblock ~8 ~32 ~29 stained_hardened_clay 12
setblock ~9 ~32 ~20 log2 1
setblock ~9 ~32 ~30 stained_hardened_clay 7
setblock ~9 ~32 ~31 soul_sand 0
setblock ~9 ~32 ~32 stained_hardened_clay 7
fill ~10 ~32 ~20 ~10 ~36 ~20 stained_hardened_clay 12
setblock ~10 ~32 ~33 stained_hardened_clay 7
fill ~10 ~32 ~34 ~10 ~33 ~34 soul_sand 0
setblock ~11 ~32 ~20 nether_brick 0
setblock ~11 ~32 ~35 soul_sand 0
setblock ~11 ~32 ~36 stained_hardened_clay 7
fill ~12 ~32 ~37 ~12 ~32 ~38 soul_sand 0
setblock ~12 ~32 ~39 stained_hardened_clay 12
fill ~13 ~32 ~40 ~13 ~33 ~40 stained_hardened_clay 7
setblock ~14 ~32 ~20 stained_hardened_clay 7
setblock ~14 ~32 ~40 soul_sand 0
setblock ~15 ~32 ~20 stained_hardened_clay 15
setblock ~15 ~32 ~41 stained_hardened_clay 12
setblock ~16 ~32 ~20 stained_hardened_clay 7
setblock ~16 ~32 ~41 log2 1
setblock ~17 ~32 ~20 stained_hardened_clay 15
setblock ~17 ~32 ~41 stained_hardened_clay 7
setblock ~18 ~32 ~41 log2 1
setblock ~19 ~32 ~20 stained_hardened_clay 15
fill ~19 ~32 ~41 ~20 ~32 ~41 stained_hardened_clay 7
fill ~20 ~32 ~20 ~21 ~32 ~20 log2 1
setblock ~21 ~32 ~41 log2 1
setblock ~22 ~32 ~20 stained_hardened_clay 12
setblock ~22 ~32 ~40 stained_hardened_clay 7
setblock ~23 ~32 ~20 nether_brick 0
setblock ~23 ~32 ~40 stained_hardened_clay 15
setblock ~24 ~32 ~20 soul_sand 0
setblock ~24 ~32 ~40 soul_sand 0
setblock ~25 ~32 ~21 stained_hardened_clay 12
fill ~25 ~32 ~40 ~25 ~34 ~40 nether_brick 0
setblock ~26 ~32 ~40 soul_sand 0
fill ~27 ~32 ~21 ~28 ~32 ~21 stained_hardened_clay 12
setblock ~27 ~32 ~40 nether_brick 0
setblock ~28 ~32 ~40 soul_sand 0
setblock ~29 ~32 ~21 soul_sand 0
setblock ~29 ~32 ~40 nether_brick 0
setblock ~30 ~32 ~40 soul_sand 0
setblock ~31 ~32 ~21 stained_hardened_clay 12
setblock ~31 ~32 ~40 nether_brick 0
fill ~32 ~32 ~21 ~32 ~31 ~21 stained_hardened_clay 7
setblock ~32 ~32 ~40 soul_sand 0
setblock ~33 ~32 ~21 soul_sand 0
setblock ~34 ~32 ~21 stained_hardened_clay 12
setblock ~34 ~32 ~40 soul_sand 0
setblock ~35 ~32 ~21 soul_sand 0
setblock ~35 ~32 ~39 soul_sand 0
setblock ~36 ~32 ~22 soul_sand 0
setblock ~36 ~32 ~38 soul_sand 0
fill ~37 ~32 ~24 ~37 ~33 ~24 nether_brick 0
fill ~37 ~32 ~25 ~37 ~32 ~26 stained_hardened_clay 7
setblock ~37 ~32 ~27 stained_hardened_clay 12
setblock ~37 ~32 ~28 nether_brick 0
setblock ~37 ~32 ~29 stained_hardened_clay 7
setblock ~37 ~32 ~30 stained_hardened_clay 15
setblock ~37 ~32 ~31 stained_hardened_clay 12
setblock ~37 ~32 ~32 nether_brick 0
setblock ~37 ~32 ~33 stained_hardened_clay 12
setblock ~37 ~32 ~34 nether_brick 0
setblock ~37 ~32 ~35 stained_hardened_clay 12
setblock ~37 ~32 ~36 stained_hardened_clay 7
setblock ~37 ~32 ~37 soul_sand 0
fill ~82 ~32 ~28 ~82 ~33 ~28 white_glazed_terracotta 0
setblock ~83 ~32 ~28 clay 0
setblock ~84 ~32 ~28 concrete 0
setblock ~85 ~32 ~27 concrete 0
setblock ~86 ~32 ~27 white_glazed_terracotta 0
setblock ~87 ~32 ~27 iron_block 0
setblock ~88 ~32 ~26 concrete 0
fill ~88 ~32 ~34 ~88 ~34 ~34 white_glazed_terracotta 0
setblock ~89 ~32 ~26 stone 3
setblock ~89 ~32 ~34 clay 0
setblock ~90 ~32 ~26 concrete 0
fill ~90 ~32 ~35 ~91 ~32 ~35 white_glazed_terracotta 0
setblock ~91 ~32 ~26 white_glazed_terracotta 0
fill ~92 ~32 ~25 ~93 ~32 ~25 white_glazed_terracotta 0
setblock ~92 ~32 ~35 iron_block 0
setblock ~93 ~32 ~36 stone 4
fill ~94 ~32 ~25 ~96 ~32 ~25 sea_lantern 0
setblock ~95 ~32 ~36 sea_lantern 0
setblock ~96 ~32 ~30 bedrock 0
setblock ~96 ~32 ~31 wool 7
setblock ~97 ~32 ~25 white_glazed_terracotta 0
setblock ~97 ~32 ~30 wool 7
setblock ~97 ~32 ~31 bedrock 0
setblock ~97 ~32 ~37 concrete 0
setblock ~98 ~32 ~24 concrete 0
setblock ~98 ~32 ~30 bedrock 0
fill ~98 ~32 ~31 ~100 ~32 ~31 wool 7
setblock ~99 ~32 ~30 concrete 7
setblock ~99 ~32 ~38 clay 0
setblock ~100 ~32 ~24 concrete 0
setblock ~100 ~32 ~29 stained_hardened_clay 9
setblock ~100 ~32 ~30 bedrock 0
setblock ~100 ~32 ~32 stonebrick 0
setblock ~100 ~32 ~38 white_glazed_terracotta 0
setblock ~101 ~32 ~29 stonebrick 0
setblock ~101 ~32 ~30 concrete 7
setblock ~101 ~32 ~31 bedrock 0
setblock ~101 ~32 ~32 coal_ore 0
setblock ~101 ~32 ~38 clay 0
fill ~102 ~32 ~24 ~102 ~33 ~24 white_glazed_terracotta 0
setblock ~102 ~32 ~29 coal_ore 0
setblock ~102 ~32 ~30 bedrock 0
setblock ~102 ~32 ~31 wool 7
setblock ~102 ~32 ~32 stone 6
setblock ~102 ~32 ~39 concrete 0
fill ~103 ~32 ~24 ~103 ~31 ~24 sea_lantern 0
setblock ~103 ~32 ~29 bedrock 0
setblock ~103 ~32 ~30 concrete 7
setblock ~103 ~32 ~31 bedrock 0
setblock ~103 ~32 ~32 concrete 7
fill ~104 ~32 ~24 ~104 ~35 ~24 white_glazed_terracotta 0
fill ~104 ~32 ~29 ~106 ~32 ~29 wool 7
setblock ~104 ~32 ~30 bedrock 0
setblock ~104 ~32 ~31 wool 7
setblock ~104 ~32 ~32 bedrock 0
fill ~104 ~32 ~39 ~105 ~32 ~39 sea_lantern 0
fill ~105 ~32 ~24 ~105 ~33 ~24 sea_lantern 0
setblock ~105 ~32 ~30 concrete 7
setblock ~105 ~32 ~31 cobblestone 0
fill ~105 ~32 ~32 ~105 ~34 ~32 concrete 7
fill ~106 ~32 ~32 ~106 ~34 ~32 bedrock 0
fill ~106 ~32 ~39 ~107 ~32 ~39 white_glazed_terracotta 0
setblock ~107 ~32 ~24 clay 0
setblock ~107 ~32 ~29 bedrock 0
setblock ~107 ~32 ~32 concrete 7
setblock ~108 ~32 ~24 concrete 0
fill ~108 ~32 ~29 ~110 ~32 ~29 wool 7
fill ~108 ~32 ~32 ~108 ~34 ~32 bedrock 0
setblock ~108 ~32 ~39 concrete 0
setblock ~109 ~32 ~24 clay 0
setblock ~109 ~32 ~30 concrete 7
setblock ~109 ~32 ~31 bedrock 0
setblock ~109 ~32 ~32 concrete 7
setblock ~109 ~32 ~39 stone 4
setblock ~110 ~32 ~24 concrete 0
setblock ~110 ~32 ~30 bedrock 0
fill ~110 ~32 ~31 ~112 ~32 ~31 wool 7
fill ~110 ~32 ~32 ~110 ~36 ~32 bedrock 0
setblock ~110 ~32 ~40 white_glazed_terracotta 0
setblock ~111 ~32 ~23 white_glazed_terracotta 0
setblock ~111 ~32 ~29 bedrock 0
setblock ~111 ~32 ~30 concrete 7
setblock ~111 ~32 ~32 coal_ore 0
setblock ~111 ~32 ~40 sea_lantern 0
setblock ~112 ~32 ~23 sea_lantern 0
setblock ~112 ~32 ~29 coal_ore 0
setblock ~112 ~32 ~30 bedrock 0
setblock ~112 ~32 ~32 stonebrick 3
setblock ~112 ~32 ~40 white_glazed_terracotta 0
setblock ~113 ~32 ~23 iron_block 0
setblock ~113 ~32 ~29 stonebrick 2
setblock ~113 ~32 ~30 concrete 7
setblock ~113 ~32 ~31 bedrock 0
setblock ~113 ~32 ~32 coal_ore 0
setblock ~113 ~32 ~40 clay 0
setblock ~114 ~32 ~29 coal_ore 0
setblock ~114 ~32 ~30 bedrock 0
setblock ~114 ~32 ~31 wool 7
setblock ~114 ~32 ~32 stonebrick 3
setblock ~115 ~32 ~23 concrete 0
setblock ~115 ~32 ~29 stonebrick 0
setblock ~115 ~32 ~30 concrete 7
setblock ~115 ~32 ~31 bedrock 0
fill ~115 ~32 ~32 ~115 ~33 ~32 wool 7
setblock ~115 ~32 ~40 sea_lantern 0
fill ~116 ~32 ~23 ~116 ~36 ~23 sea_lantern 0
setblock ~116 ~32 ~29 stained_hardened_clay 9
setblock ~116 ~32 ~30 bedrock 0
setblock ~116 ~32 ~31 wool 7
setblock ~116 ~32 ~32 stonebrick 2
fill ~116 ~32 ~40 ~116 ~31 ~40 white_glazed_terracotta 0
setblock ~117 ~32 ~23 white_glazed_terracotta 0
setblock ~117 ~32 ~30 concrete 7
setblock ~117 ~32 ~31 bedrock 0
setblock ~117 ~32 ~40 clay 0
fill ~118 ~32 ~23 ~118 ~33 ~23 sea_lantern 0
setblock ~118 ~32 ~30 bedrock 0
setblock ~118 ~32 ~31 wool 7
setblock ~118 ~32 ~40 white_glazed_terracotta 0
setblock ~119 ~32 ~23 white_glazed_terracotta 0
setblock ~119 ~32 ~30 concrete 7
setblock ~119 ~32 ~31 bedrock 0
setblock ~119 ~32 ~40 sea_lantern 0
fill ~120 ~32 ~23 ~120 ~38 ~23 sea_lantern 0
setblock ~120 ~32 ~40 white_glazed_terracotta 0
setblock ~121 ~32 ~23 concrete 0
setblock ~121 ~32 ~40 sea_lantern 0
setblock ~122 ~32 ~40 white_glazed_terracotta 0
setblock ~123 ~32 ~23 concrete 0
setblock ~123 ~32 ~40 clay 0
setblock ~124 ~32 ~23 stone 4
setblock ~124 ~32 ~40 iron_block 0
setblock ~125 ~32 ~23 concrete 0
fill ~125 ~32 ~40 ~125 ~33 ~40 sea_lantern 0
fill ~126 ~32 ~23 ~126 ~33 ~23 stone 4
setblock ~126 ~32 ~40 concrete 0
setblock ~127 ~32 ~23 concrete 0
setblock ~127 ~32 ~40 stone 3
setblock ~128 ~32 ~22 iron_block 0
setblock ~128 ~32 ~40 iron_block 0
setblock ~129 ~32 ~22 stone 3
fill ~129 ~32 ~40 ~129 ~33 ~40 stone 4
setblock ~130 ~32 ~41 white_glazed_terracotta 0
setblock ~131 ~32 ~41 concrete 0
setblock ~132 ~32 ~41 wool 0
setblock ~133 ~32 ~41 concrete 0
setblock ~134 ~32 ~41 iron_block 0
setblock ~135 ~32 ~41 concrete 0
setblock ~137 ~32 ~41 white_glazed_terracotta 0
setblock ~4 ~33 ~21 stained_hardened_clay 7
setblock ~5 ~33 ~20 stained_hardened_clay 7
fill ~5 ~33 ~23 ~5 ~33 ~24 stained_hardened_clay 7
fill ~6 ~33 ~20 ~7 ~33 ~20 log2 1
setblock ~6 ~33 ~25 stained_hardened_clay 7
fill ~6 ~33 ~26 ~6 ~34 ~26 soul_sand 0
fill ~7 ~33 ~27 ~7 ~33 ~28 stained_hardened_clay 7
fill ~8 ~33 ~20 ~9 ~33 ~20 stained_hardened_clay 7
setblock ~8 ~33 ~29 stained_hardened_clay 7
setblock ~8 ~33 ~30 soul_sand 0
setblock ~8 ~33 ~31 stained_hardened_clay 7
setblock ~9 ~33 ~32 stained_hardened_clay 12
setblock ~9 ~33 ~33 stained_hardened_clay 7
setblock ~10 ~33 ~35 stained_hardened_clay 7
fill ~10 ~33 ~36 ~10 ~34 ~36 soul_sand 0
setblock ~11 ~33 ~20 stained_hardened_clay 12
fill ~11 ~33 ~37 ~11 ~33 ~38 stained_hardened_clay 7
fill ~12 ~33 ~20 ~13 ~33 ~20 stained_hardened_clay 7
setblock ~12 ~33 ~39 stained_hardened_clay 7
setblock ~14 ~33 ~20 log2 1
fill ~14 ~33 ~41 ~15 ~33 ~41 stained_hardened_clay 15
fill ~15 ~33 ~20 ~15 ~34 ~20 nether_brick 0
setblock ~16 ~33 ~20 log2 1
fill ~16 ~33 ~41 ~16 ~36 ~41 nether_brick 0
fill ~17 ~33 ~20 ~19 ~33 ~20 nether_brick 0
fill ~17 ~33 ~41 ~21 ~33 ~41 stained_hardened_clay 15
fill ~20 ~33 ~20 ~20 ~35 ~20 stained_hardened_clay 7
setblock ~21 ~33 ~20 nether_brick 0
fill ~22 ~33 ~20 ~23 ~33 ~20 log2 1
fill ~22 ~33 ~40 ~24 ~33 ~40 log2 1
setblock ~24 ~33 ~21 stained_hardened_clay 7
fill ~25 ~33 ~21 ~26 ~33 ~21 nether_brick 0
setblock ~26 ~33 ~40 stained_hardened_clay 7
setblock ~27 ~33 ~21 stained_hardened_clay 15
setblock ~27 ~33 ~40 log2 1
setblock ~28 ~33 ~21 log2 1
setblock ~28 ~33 ~40 stained_hardened_clay 12
setblock ~29 ~33 ~21 nether_brick 0
fill ~29 ~33 ~40 ~30 ~33 ~40 stained_hardened_clay 7
setblock ~31 ~33 ~21 stained_hardened_clay 15
setblock ~31 ~33 ~40 log2 1
setblock ~32 ~33 ~21 log2 1
setblock ~32 ~33 ~40 stained_hardened_clay 7
setblock ~33 ~33 ~21 nether_brick 0
fill ~34 ~33 ~21 ~35 ~33 ~21 stained_hardened_clay 7
setblock ~34 ~33 ~40 stained_hardened_clay 12
setblock ~35 ~33 ~40 stained_hardened_clay 7
setblock ~36 ~33 ~22 stained_hardened_clay 12
setblock ~36 ~33 ~39 stained_hardened_clay 7
fill ~37 ~33 ~22 ~37 ~34 ~22 stained_hardened_clay 7
setblock ~37 ~33 ~23 nether_brick 0
setblock ~37 ~33 ~25 nether_brick 0
setblock ~37 ~33 ~36 stained_hardened_clay 12
fill ~37 ~33 ~37 ~37 ~33 ~38 stained_hardened_clay 7
fill ~38 ~33 ~26 ~38 ~33 ~28 stained_hardened_clay 7
setblock ~38 ~33 ~29 nether_brick 0
setblock ~38 ~33 ~30 stained_hardened_clay 7
setblock ~38 ~33 ~31 planks 5
fill ~38 ~33 ~32 ~38 ~34 ~32 stained_hardened_clay 12
setblock ~38 ~33 ~33 nether_brick 0
fill ~38 ~33 ~34 ~38 ~33 ~35 stained_hardened_clay 7
fill ~83 ~33 ~28 ~84 ~33 ~28 stone 4
setblock ~85 ~33 ~27 stone 3
fill ~86 ~33 ~27 ~86 ~34 ~27 stone 4
setblock ~87 ~33 ~27 sea_lantern 0
fill ~88 ~33 ~27 ~88 ~35 ~27 white_glazed_terracotta 0
setblock ~89 ~33 ~26 stone 4
setblock ~89 ~33 ~34 sea_lantern 0
setblock ~90 ~33 ~26 iron_block 0
setblock ~90 ~33 ~35 stone 4
fill ~91 ~33 ~26 ~91 ~34 ~26 sea_lantern 0
setblock ~91 ~33 ~35 clay 0
setblock ~92 ~33 ~25 sea_lantern 0
fill ~92 ~33 ~30 ~94 ~33 ~30 wool 7
fill ~92 ~33 ~31 ~92 ~33 ~30 wool 7
setblock ~92 ~33 ~35 sea_lantern 0
setblock ~93 ~33 ~25 clay 0
setblock ~93 ~33 ~31 stained_hardened_clay 7
setblock ~93 ~33 ~36 white_glazed_terracotta 0
fill ~94 ~33 ~25 ~94 ~32 ~25 sea_lantern 0
fill ~94 ~33 ~29 ~95 ~33 ~29 stained_hardened_clay 9
setblock ~94 ~33 ~31 wool 7
setblock ~94 ~33 ~32 cobblestone 0
setblock ~94 ~33 ~36 stone 4
setblock ~95 ~33 ~25 stone 4
setblock ~95 ~33 ~30 concrete 7
setblock ~95 ~33 ~31 stained_hardened_clay 7
fill ~95 ~33 ~32 ~96 ~33 ~32 coal_ore 0
setblock ~95 ~33 ~36 white_glazed_terracotta 0
setblock ~96 ~33 ~25 clay 0
fill ~96 ~33 ~29 ~98 ~33 ~29 concrete 7
fill ~96 ~33 ~37 ~97 ~33 ~37 clay 0
setblock ~97 ~33 ~25 sea_lantern 0
fill ~97 ~33 ~32 ~103 ~33 ~32 wool 7
setblock ~98 ~33 ~24 white_glazed_terracotta 0
setblock ~98 ~33 ~37 sea_lantern 0
setblock ~99 ~33 ~24 concrete 0
setblock ~99 ~33 ~29 wool 7
setblock ~99 ~33 ~38 sea_lantern 0
setblock ~100 ~33 ~24 white_glazed_terracotta 0
fill ~100 ~33 ~29 ~101 ~33 ~29 concrete 7
setblock ~100 ~33 ~38 iron_block 0
setblock ~101 ~33 ~38 stone 3
fill ~102 ~33 ~29 ~102 ~34 ~29 wool 7
setblock ~102 ~33 ~38 sea_lantern 0
setblock ~103 ~33 ~24 clay 0
