setblock ~10 ~-3 ~120 red_mushroom_block 0
setblock ~10 ~-3 ~121 redstone_block 0
setblock ~10 ~-3 ~122 red_mushroom_block 0
fill ~11 ~-3 ~118 ~15 ~-3 ~118 red_mushroom_block 0
setblock ~11 ~-3 ~119 redstone_block 0
fill ~11 ~-3 ~123 ~12 ~-3 ~123 redstone_block 0
setblock ~12 ~-3 ~115 redstone_block 0
fill ~12 ~-3 ~116 ~14 ~-3 ~116 red_mushroom_block 0
setblock ~12 ~-3 ~117 redstone_block 0
fill ~13 ~-3 ~113 ~13 ~-3 ~119 red_mushroom_block 0
setblock ~13 ~-3 ~123 red_mushroom_block 0
fill ~14 ~-3 ~110 ~15 ~-3 ~110 red_mushroom_block 0
setblock ~14 ~-3 ~111 redstone_block 0
setblock ~14 ~-3 ~112 red_mushroom_block 0
setblock ~14 ~-3 ~113 redstone_block 0
setblock ~14 ~-3 ~114 red_mushroom_block 0
setblock ~14 ~-3 ~115 redstone_block 0
setblock ~14 ~-3 ~117 redstone_block 0
fill ~14 ~-3 ~119 ~15 ~-3 ~119 redstone_block 0
setblock ~14 ~-3 ~123 redstone_block 0
setblock ~15 ~-3 ~109 red_mushroom_block 0
setblock ~15 ~-3 ~117 red_mushroom_block 0
fill ~15 ~-3 ~124 ~17 ~-3 ~124 red_mushroom_block 0
setblock ~16 ~-3 ~109 redstone_block 0
setblock ~17 ~-3 ~109 red_mushroom_block 0
setblock ~18 ~-3 ~109 redstone_block 0
setblock ~18 ~-3 ~125 redstone_block 0
setblock ~19 ~-3 ~109 red_mushroom_block 0
fill ~19 ~-3 ~125 ~19 ~-3 ~126 red_mushroom_block 0
setblock ~20 ~-3 ~109 redstone_block 0
setblock ~20 ~-3 ~125 redstone_block 0
fill ~20 ~-3 ~126 ~25 ~-3 ~126 red_mushroom_block 0
setblock ~20 ~-3 ~127 redstone_block 0
setblock ~21 ~-3 ~109 red_mushroom_block 0
setblock ~21 ~-3 ~125 red_mushroom_block 0
setblock ~21 ~-3 ~127 red_mushroom_block 0
setblock ~22 ~-3 ~109 redstone_block 0
setblock ~22 ~-3 ~125 redstone_block 0
fill ~22 ~-3 ~127 ~23 ~-3 ~127 redstone_block 0
setblock ~23 ~-3 ~109 red_mushroom_block 0
setblock ~23 ~-3 ~125 red_mushroom_block 0
setblock ~24 ~-3 ~109 redstone_block 0
fill ~24 ~-3 ~110 ~25 ~-3 ~110 red_mushroom_block 0
setblock ~24 ~-3 ~111 redstone_block 0
fill ~24 ~-3 ~112 ~25 ~-3 ~112 red_mushroom_block 0
setblock ~24 ~-3 ~113 redstone_block 0
setblock ~24 ~-3 ~125 redstone_block 0
setblock ~25 ~-3 ~111 red_mushroom_block 0
setblock ~25 ~-3 ~113 red_mushroom_block 0
setblock ~25 ~-3 ~125 red_mushroom_block 0
fill ~26 ~-3 ~114 ~27 ~-3 ~114 red_mushroom_block 0
fill ~26 ~-3 ~124 ~27 ~-3 ~124 red_mushroom_block 0
setblock ~26 ~-3 ~125 redstone_block 0
fill ~27 ~-3 ~123 ~28 ~-3 ~123 redstone_block 0
setblock ~28 ~-3 ~115 redstone_block 0
fill ~28 ~-3 ~122 ~29 ~-3 ~122 red_mushroom_block 0
fill ~29 ~-3 ~115 ~29 ~-3 ~116 red_mushroom_block 0
setblock ~29 ~-3 ~121 red_mushroom_block 0
setblock ~30 ~-3 ~116 red_mushroom_block 0
setblock ~30 ~-3 ~117 redstone_block 0
setblock ~30 ~-3 ~118 red_mushroom_block 0
setblock ~30 ~-3 ~119 redstone_block 0
setblock ~30 ~-3 ~120 red_mushroom_block 0
fill ~35 ~-3 ~76 ~35 ~-3 ~79 red_nether_brick 0
fill ~36 ~-3 ~73 ~36 ~-3 ~75 red_nether_brick 0
fill ~36 ~-3 ~80 ~36 ~2 ~80 red_nether_brick 0
fill ~36 ~-3 ~81 ~36 ~2 ~81 red_nether_brick 0
fill ~36 ~-3 ~82 ~36 ~1 ~82 red_nether_brick 0
fill ~36 ~-3 ~83 ~36 ~1 ~83 red_nether_brick 0
fill ~37 ~-3 ~71 ~37 ~-2 ~71 red_nether_brick 0
fill ~37 ~-3 ~72 ~37 ~-1 ~72 red_nether_brick 0
fill ~37 ~-3 ~84 ~37 ~-2 ~84 red_nether_brick 0
fill ~37 ~-3 ~85 ~37 ~1 ~85 red_nether_brick 0
fill ~37 ~-3 ~86 ~37 ~0 ~86 red_nether_brick 0
fill ~38 ~-3 ~70 ~38 ~-1 ~70 red_nether_brick 0
fill ~38 ~-3 ~87 ~38 ~0 ~87 red_nether_brick 0
fill ~39 ~-3 ~69 ~39 ~-1 ~69 red_nether_brick 0
fill ~39 ~-3 ~88 ~40 ~-3 ~88 red_nether_brick 0
fill ~40 ~-3 ~67 ~40 ~-2 ~67 red_nether_brick 0
fill ~40 ~-3 ~68 ~40 ~0 ~68 red_nether_brick 0
fill ~41 ~-3 ~66 ~41 ~0 ~66 red_nether_brick 0
fill ~41 ~-3 ~89 ~42 ~-3 ~89 red_nether_brick 0
fill ~42 ~-3 ~65 ~42 ~2 ~65 red_nether_brick 0
fill ~43 ~-3 ~63 ~43 ~3 ~63 red_nether_brick 0
fill ~43 ~-3 ~64 ~43 ~-3 ~63 red_nether_brick 0
fill ~43 ~-3 ~90 ~45 ~-3 ~90 red_nether_brick 0
fill ~44 ~-3 ~59 ~44 ~4 ~59 red_nether_brick 0
fill ~44 ~-3 ~60 ~44 ~5 ~60 red_nether_brick 0
fill ~44 ~-3 ~61 ~44 ~-3 ~62 red_nether_brick 0
fill ~45 ~-3 ~56 ~45 ~2 ~56 red_nether_brick 0
fill ~45 ~-3 ~57 ~45 ~-2 ~57 red_nether_brick 0
fill ~45 ~-3 ~58 ~45 ~-3 ~56 red_nether_brick 0
fill ~46 ~-3 ~55 ~46 ~-2 ~55 red_nether_brick 0
fill ~46 ~-3 ~91 ~47 ~-3 ~91 red_nether_brick 0
fill ~47 ~-3 ~54 ~48 ~-3 ~54 red_nether_brick 0
fill ~48 ~-3 ~90 ~49 ~-3 ~90 red_nether_brick 0
fill ~49 ~-3 ~53 ~50 ~-3 ~53 red_nether_brick 0
setblock ~50 ~-3 ~89 red_nether_brick 0
fill ~51 ~-3 ~52 ~52 ~-3 ~52 red_nether_brick 0
setblock ~51 ~-3 ~88 red_nether_brick 0
setblock ~52 ~-3 ~87 red_nether_brick 0
fill ~53 ~-3 ~53 ~57 ~-3 ~53 red_nether_brick 0
fill ~53 ~-3 ~85 ~53 ~-3 ~86 red_nether_brick 0
fill ~54 ~-3 ~82 ~54 ~-3 ~84 red_nether_brick 0
fill ~55 ~-3 ~78 ~55 ~-2 ~78 red_nether_brick 0
fill ~55 ~-3 ~79 ~55 ~2 ~79 red_nether_brick 0
fill ~55 ~-3 ~80 ~55 ~1 ~80 red_nether_brick 0
fill ~55 ~-3 ~81 ~55 ~1 ~81 red_nether_brick 0
fill ~56 ~-3 ~76 ~56 ~3 ~76 red_nether_brick 0
fill ~56 ~-3 ~77 ~56 ~2 ~77 red_nether_brick 0
fill ~57 ~-3 ~54 ~58 ~-3 ~54 red_nether_brick 0
fill ~57 ~-3 ~74 ~57 ~-1 ~74 red_nether_brick 0
fill ~57 ~-3 ~75 ~57 ~2 ~75 red_nether_brick 0
fill ~58 ~-3 ~72 ~58 ~-3 ~73 red_nether_brick 0
setblock ~59 ~-3 ~55 red_nether_brick 0
fill ~59 ~-3 ~69 ~59 ~-3 ~71 red_nether_brick 0
setblock ~60 ~-3 ~56 red_nether_brick 0
fill ~60 ~-3 ~67 ~60 ~-3 ~68 red_nether_brick 0
setblock ~61 ~-3 ~57 red_nether_brick 0
fill ~61 ~-3 ~65 ~61 ~-3 ~66 red_nether_brick 0
fill ~62 ~-3 ~58 ~62 ~-3 ~64 red_nether_brick 0
fill ~82 ~-3 ~59 ~82 ~-3 ~63 red_nether_brick 0
fill ~83 ~-3 ~57 ~83 ~-3 ~58 red_nether_brick 0
fill ~83 ~-3 ~64 ~83 ~-3 ~65 red_nether_brick 0
setblock ~84 ~-3 ~56 red_nether_brick 0
fill ~84 ~-3 ~66 ~84 ~-3 ~68 red_nether_brick 0
setblock ~85 ~-3 ~55 red_nether_brick 0
fill ~85 ~-3 ~69 ~85 ~-3 ~70 red_nether_brick 0
fill ~86 ~-3 ~54 ~87 ~-3 ~54 red_nether_brick 0
fill ~86 ~-3 ~71 ~86 ~-3 ~72 red_nether_brick 0
fill ~87 ~-3 ~73 ~87 ~-3 ~74 red_nether_brick 0
fill ~88 ~-3 ~53 ~91 ~-3 ~53 red_nether_brick 0
fill ~88 ~-3 ~75 ~88 ~-2 ~75 red_nether_brick 0
fill ~88 ~-3 ~76 ~88 ~2 ~76 red_nether_brick 0
fill ~89 ~-3 ~77 ~89 ~-3 ~77 red_nether_brick 0
fill ~89 ~-3 ~78 ~89 ~2 ~78 red_nether_brick 0
fill ~89 ~-3 ~79 ~89 ~1 ~79 red_nether_brick 0
fill ~90 ~-3 ~80 ~90 ~-3 ~80 red_nether_brick 0
fill ~90 ~-3 ~81 ~90 ~-3 ~83 red_nether_brick 0
fill ~91 ~-3 ~84 ~91 ~-3 ~85 red_nether_brick 0
fill ~92 ~-3 ~52 ~93 ~-3 ~52 red_nether_brick 0
fill ~92 ~-3 ~86 ~92 ~-3 ~87 red_nether_brick 0
fill ~93 ~-3 ~88 ~93 ~-2 ~88 red_nether_brick 0
fill ~94 ~-3 ~53 ~96 ~-3 ~53 red_nether_brick 0
setblock ~94 ~-3 ~89 red_nether_brick 0
fill ~95 ~-3 ~90 ~97 ~-3 ~90 red_nether_brick 0
setblock ~97 ~-3 ~54 red_nether_brick 0
setblock ~98 ~-3 ~55 red_nether_brick 0
fill ~98 ~-3 ~91 ~99 ~-3 ~91 red_nether_brick 0
fill ~99 ~-3 ~56 ~99 ~3 ~56 red_nether_brick 0
fill ~99 ~-3 ~57 ~99 ~-2 ~57 red_nether_brick 0
fill ~99 ~-3 ~58 ~99 ~-3 ~56 red_nether_brick 0
fill ~100 ~-3 ~59 ~100 ~5 ~59 red_nether_brick 0
fill ~100 ~-3 ~60 ~100 ~-1 ~60 red_nether_brick 0
fill ~100 ~-3 ~61 ~100 ~-3 ~62 red_nether_brick 0
fill ~100 ~-3 ~90 ~101 ~-3 ~90 red_nether_brick 0
fill ~101 ~-3 ~63 ~101 ~-2 ~63 red_nether_brick 0
fill ~102 ~-3 ~64 ~102 ~2 ~64 red_nether_brick 0
fill ~102 ~-3 ~65 ~102 ~3 ~65 red_nether_brick 0
fill ~102 ~-3 ~89 ~103 ~-3 ~89 red_nether_brick 0
fill ~103 ~-3 ~66 ~103 ~1 ~66 red_nether_brick 0
fill ~104 ~-3 ~67 ~104 ~0 ~67 red_nether_brick 0
fill ~104 ~-3 ~88 ~105 ~-3 ~88 red_nether_brick 0
fill ~105 ~-3 ~68 ~105 ~-2 ~68 red_nether_brick 0
fill ~106 ~-3 ~69 ~106 ~-3 ~70 red_nether_brick 0
setblock ~106 ~-3 ~87 red_nether_brick 0
fill ~107 ~-3 ~71 ~107 ~-1 ~71 red_nether_brick 0
fill ~107 ~-3 ~85 ~107 ~-2 ~85 red_nether_brick 0
fill ~107 ~-3 ~86 ~107 ~1 ~86 red_nether_brick 0
fill ~108 ~-3 ~72 ~108 ~-3 ~74 red_nether_brick 0
fill ~108 ~-3 ~82 ~108 ~-3 ~84 red_nether_brick 0
fill ~109 ~-3 ~75 ~109 ~-3 ~81 red_nether_brick 0
fill ~11 ~-2 ~120 ~11 ~-2 ~122 red_mushroom_block 0
setblock ~12 ~-2 ~119 red_mushroom_block 0
setblock ~12 ~-2 ~120 redstone_block 0
fill ~12 ~-2 ~121 ~28 ~-2 ~121 red_mushroom_block 0
setblock ~12 ~-2 ~122 redstone_block 0
setblock ~13 ~-2 ~120 red_mushroom_block 0
setblock ~13 ~-2 ~122 red_mushroom_block 0
setblock ~14 ~-2 ~120 redstone_block 0
setblock ~14 ~-2 ~122 redstone_block 0
fill ~14 ~-2 ~123 ~26 ~-2 ~123 red_mushroom_block 0
fill ~15 ~-2 ~111 ~23 ~-2 ~111 red_mushroom_block 0
fill ~15 ~-2 ~112 ~15 ~-2 ~116 red_mushroom_block 0
setblock ~15 ~-2 ~120 red_mushroom_block 0
setblock ~15 ~-2 ~122 red_mushroom_block 0
setblock ~16 ~-2 ~110 redstone_block 0
setblock ~16 ~-2 ~112 redstone_block 0
fill ~16 ~-2 ~113 ~23 ~-2 ~113 red_mushroom_block 0
setblock ~16 ~-2 ~114 redstone_block 0
fill ~16 ~-2 ~115 ~27 ~-2 ~115 red_mushroom_block 0
setblock ~16 ~-2 ~116 redstone_block 0
fill ~16 ~-2 ~117 ~29 ~-2 ~117 red_mushroom_block 0
setblock ~16 ~-2 ~118 redstone_block 0
fill ~16 ~-2 ~119 ~29 ~-2 ~119 red_mushroom_block 0
setblock ~16 ~-2 ~120 redstone_block 0
setblock ~16 ~-2 ~122 redstone_block 0
setblock ~17 ~-2 ~110 red_mushroom_block 0
setblock ~17 ~-2 ~112 red_mushroom_block 0
setblock ~17 ~-2 ~114 red_mushroom_block 0
setblock ~17 ~-2 ~116 red_mushroom_block 0
setblock ~17 ~-2 ~118 red_mushroom_block 0
setblock ~17 ~-2 ~120 red_mushroom_block 0
setblock ~17 ~-2 ~122 red_mushroom_block 0
setblock ~18 ~-2 ~110 redstone_block 0
setblock ~18 ~-2 ~112 redstone_block 0
setblock ~18 ~-2 ~114 redstone_block 0
setblock ~18 ~-2 ~116 redstone_block 0
setblock ~18 ~-2 ~118 redstone_block 0
setblock ~18 ~-2 ~120 redstone_block 0
setblock ~18 ~-2 ~122 redstone_block 0
setblock ~18 ~-2 ~124 redstone_block 0
setblock ~19 ~-2 ~110 red_mushroom_block 0
setblock ~19 ~-2 ~112 red_mushroom_block 0
setblock ~19 ~-2 ~114 red_mushroom_block 0
setblock ~19 ~-2 ~116 red_mushroom_block 0
setblock ~19 ~-2 ~118 red_mushroom_block 0
setblock ~19 ~-2 ~120 red_mushroom_block 0
setblock ~19 ~-2 ~122 red_mushroom_block 0
setblock ~19 ~-2 ~124 red_mushroom_block 0
setblock ~20 ~-2 ~110 redstone_block 0
setblock ~20 ~-2 ~112 redstone_block 0
setblock ~20 ~-2 ~114 redstone_block 0
setblock ~20 ~-2 ~116 redstone_block 0
setblock ~20 ~-2 ~118 redstone_block 0
setblock ~20 ~-2 ~120 redstone_block 0
setblock ~20 ~-2 ~122 redstone_block 0
setblock ~20 ~-2 ~124 redstone_block 0
setblock ~21 ~-2 ~110 red_mushroom_block 0
setblock ~21 ~-2 ~112 red_mushroom_block 0
setblock ~21 ~-2 ~114 red_mushroom_block 0
setblock ~21 ~-2 ~116 red_mushroom_block 0
setblock ~21 ~-2 ~118 red_mushroom_block 0
setblock ~21 ~-2 ~120 red_mushroom_block 0
setblock ~21 ~-2 ~122 red_mushroom_block 0
setblock ~21 ~-2 ~124 red_mushroom_block 0
setblock ~22 ~-2 ~110 redstone_block 0
setblock ~22 ~-2 ~112 redstone_block 0
setblock ~22 ~-2 ~114 redstone_block 0
setblock ~22 ~-2 ~116 redstone_block 0
setblock ~22 ~-2 ~118 redstone_block 0
setblock ~22 ~-2 ~120 redstone_block 0
setblock ~22 ~-2 ~122 redstone_block 0
setblock ~22 ~-2 ~124 redstone_block 0
setblock ~23 ~-2 ~110 red_mushroom_block 0
setblock ~23 ~-2 ~112 red_mushroom_block 0
setblock ~23 ~-2 ~114 red_mushroom_block 0
setblock ~23 ~-2 ~116 red_mushroom_block 0
setblock ~23 ~-2 ~118 red_mushroom_block 0
setblock ~23 ~-2 ~120 red_mushroom_block 0
setblock ~23 ~-2 ~122 red_mushroom_block 0
setblock ~23 ~-2 ~124 red_mushroom_block 0
setblock ~24 ~-2 ~114 redstone_block 0
setblock ~24 ~-2 ~116 redstone_block 0
setblock ~24 ~-2 ~118 redstone_block 0
setblock ~24 ~-2 ~120 redstone_block 0
setblock ~24 ~-2 ~122 redstone_block 0
setblock ~24 ~-2 ~124 redstone_block 0
setblock ~25 ~-2 ~114 red_mushroom_block 0
setblock ~25 ~-2 ~116 red_mushroom_block 0
setblock ~25 ~-2 ~118 red_mushroom_block 0
setblock ~25 ~-2 ~120 red_mushroom_block 0
setblock ~25 ~-2 ~122 red_mushroom_block 0
setblock ~25 ~-2 ~124 red_mushroom_block 0
setblock ~26 ~-2 ~116 redstone_block 0
setblock ~26 ~-2 ~118 redstone_block 0
setblock ~26 ~-2 ~120 redstone_block 0
setblock ~26 ~-2 ~122 redstone_block 0
setblock ~27 ~-2 ~116 red_mushroom_block 0
setblock ~27 ~-2 ~118 red_mushroom_block 0
setblock ~27 ~-2 ~120 red_mushroom_block 0
setblock ~27 ~-2 ~122 red_mushroom_block 0
setblock ~28 ~-2 ~116 redstone_block 0
setblock ~28 ~-2 ~118 redstone_block 0
setblock ~28 ~-2 ~120 redstone_block 0
setblock ~29 ~-2 ~118 red_mushroom_block 0
setblock ~29 ~-2 ~120 red_mushroom_block 0
setblock ~30 ~-2 ~118 redstone_block 0
fill ~35 ~-2 ~77 ~35 ~-2 ~79 red_nether_brick 0
fill ~36 ~-2 ~74 ~36 ~-1 ~74 red_nether_brick 0
fill ~36 ~-2 ~75 ~36 ~0 ~75 red_nether_brick 0
fill ~36 ~-2 ~76 ~36 ~1 ~76 red_nether_brick 0
fill ~37 ~-2 ~73 ~37 ~0 ~73 red_nether_brick 0
fill ~39 ~-2 ~88 ~39 ~0 ~88 red_nether_brick 0
fill ~40 ~-2 ~89 ~41 ~-2 ~89 red_nether_brick 0
fill ~42 ~-2 ~64 ~42 ~1 ~64 red_nether_brick 0
fill ~42 ~-2 ~90 ~44 ~-2 ~90 red_nether_brick 0
fill ~43 ~-2 ~61 ~43 ~2 ~61 red_nether_brick 0
fill ~43 ~-2 ~62 ~43 ~3 ~62 red_nether_brick 0
fill ~44 ~-2 ~58 ~44 ~2 ~58 red_nether_brick 0
fill ~45 ~-2 ~91 ~49 ~-2 ~91 red_nether_brick 0
fill ~47 ~-2 ~54 ~47 ~-3 ~54 red_nether_brick 0
fill ~48 ~-2 ~53 ~49 ~-2 ~53 red_nether_brick 0
fill ~50 ~-2 ~52 ~55 ~-2 ~52 red_nether_brick 0
fill ~50 ~-2 ~90 ~50 ~3 ~90 red_nether_brick 0
fill ~51 ~-2 ~89 ~51 ~3 ~89 red_nether_brick 0
fill ~52 ~-2 ~88 ~52 ~2 ~88 red_nether_brick 0
fill ~53 ~-2 ~86 ~53 ~-2 ~87 red_nether_brick 0
fill ~54 ~-2 ~83 ~54 ~-2 ~85 red_nether_brick 0
fill ~55 ~-2 ~82 ~55 ~0 ~82 red_nether_brick 0
fill ~56 ~-2 ~53 ~58 ~-2 ~53 red_nether_brick 0
fill ~58 ~-2 ~73 ~58 ~3 ~73 red_nether_brick 0
setblock ~59 ~-2 ~54 red_nether_brick 0
fill ~59 ~-2 ~70 ~59 ~-2 ~72 red_nether_brick 0
setblock ~60 ~-2 ~55 red_nether_brick 0
fill ~60 ~-2 ~68 ~60 ~-2 ~69 red_nether_brick 0
setblock ~61 ~-2 ~56 red_nether_brick 0
fill ~61 ~-2 ~67 ~61 ~-1 ~67 red_nether_brick 0
setblock ~62 ~-2 ~57 red_nether_brick 0
fill ~62 ~-2 ~62 ~62 ~-2 ~66 red_nether_brick 0
fill ~63 ~-2 ~58 ~63 ~5 ~58 red_nether_brick 0
fill ~63 ~-2 ~59 ~63 ~6 ~59 red_nether_brick 0
fill ~63 ~-2 ~60 ~63 ~7 ~60 red_nether_brick 0
fill ~63 ~-2 ~61 ~63 ~7 ~61 red_nether_brick 0
fill ~81 ~-2 ~59 ~81 ~6 ~59 red_nether_brick 0
fill ~81 ~-2 ~60 ~81 ~6 ~60 red_nether_brick 0
fill ~81 ~-2 ~61 ~81 ~6 ~61 red_nether_brick 0
fill ~82 ~-2 ~57 ~82 ~-1 ~57 red_nether_brick 0
fill ~82 ~-2 ~58 ~82 ~-2 ~57 red_nether_brick 0
fill ~82 ~-2 ~62 ~82 ~-2 ~65 red_nether_brick 0
fill ~83 ~-2 ~56 ~83 ~-1 ~56 red_nether_brick 0
fill ~83 ~-2 ~66 ~83 ~-2 ~67 red_nether_brick 0
setblock ~84 ~-2 ~55 red_nether_brick 0
fill ~84 ~-2 ~68 ~84 ~-2 ~69 red_nether_brick 0
setblock ~85 ~-2 ~54 red_nether_brick 0
fill ~85 ~-2 ~70 ~85 ~-1 ~70 red_nether_brick 0
fill ~85 ~-2 ~71 ~85 ~4 ~71 red_nether_brick 0
fill ~86 ~-2 ~53 ~89 ~-2 ~53 red_nether_brick 0
fill ~86 ~-2 ~72 ~86 ~0 ~72 red_nether_brick 0
fill ~86 ~-2 ~73 ~86 ~2 ~73 red_nether_brick 0
fill ~87 ~-2 ~74 ~87 ~3 ~74 red_nether_brick 0
fill ~88 ~-2 ~77 ~88 ~0 ~77 red_nether_brick 0
fill ~89 ~-2 ~80 ~89 ~0 ~80 red_nether_brick 0
fill ~89 ~-2 ~81 ~89 ~-1 ~81 red_nether_brick 0
fill ~90 ~-2 ~52 ~95 ~-2 ~52 red_nether_brick 0
fill ~90 ~-2 ~82 ~90 ~2 ~82 red_nether_brick 0
fill ~90 ~-2 ~83 ~90 ~2 ~83 red_nether_brick 0
fill ~90 ~-2 ~84 ~90 ~1 ~84 red_nether_brick 0
fill ~91 ~-2 ~85 ~91 ~-2 ~86 red_nether_brick 0
fill ~92 ~-2 ~87 ~92 ~-1 ~87 red_nether_brick 0
fill ~93 ~-2 ~89 ~93 ~2 ~89 red_nether_brick 0
fill ~94 ~-2 ~90 ~95 ~-2 ~90 red_nether_brick 0
fill ~96 ~-2 ~53 ~97 ~-2 ~53 red_nether_brick 0
fill ~96 ~-2 ~91 ~99 ~-2 ~91 red_nether_brick 0
fill ~98 ~-2 ~54 ~98 ~1 ~54 red_nether_brick 0
fill ~99 ~-2 ~55 ~99 ~0 ~55 red_nether_brick 0
fill ~100 ~-2 ~58 ~100 ~3 ~58 red_nether_brick 0
fill ~100 ~-2 ~90 ~102 ~-2 ~90 red_nether_brick 0
fill ~101 ~-2 ~61 ~101 ~3 ~61 red_nether_brick 0
fill ~101 ~-2 ~62 ~101 ~3 ~62 red_nether_brick 0
fill ~103 ~-2 ~89 ~104 ~-2 ~89 red_nether_brick 0
fill ~105 ~-2 ~69 ~105 ~0 ~69 red_nether_brick 0
fill ~105 ~-2 ~88 ~106 ~-2 ~88 red_nether_brick 0
fill ~106 ~-2 ~70 ~106 ~-1 ~70 red_nether_brick 0
fill ~107 ~-2 ~72 ~107 ~0 ~72 red_nether_brick 0
setblock ~107 ~-2 ~87 red_nether_brick 0
fill ~108 ~-2 ~73 ~108 ~-1 ~73 red_nether_brick 0
fill ~108 ~-2 ~74 ~108 ~0 ~74 red_nether_brick 0
fill ~108 ~-2 ~75 ~108 ~1 ~75 red_nether_brick 0
fill ~108 ~-2 ~83 ~108 ~2 ~83 red_nether_brick 0
fill ~108 ~-2 ~84 ~108 ~1 ~84 red_nether_brick 0
fill ~109 ~-2 ~76 ~109 ~-2 ~82 red_nether_brick 0
setblock ~35 ~-1 ~79 red_nether_brick 0
fill ~36 ~-1 ~77 ~36 ~1 ~77 red_nether_brick 0
fill ~36 ~-1 ~78 ~36 ~1 ~78 red_nether_brick 0
fill ~36 ~-1 ~84 ~36 ~0 ~84 red_nether_brick 0
fill ~38 ~-1 ~71 ~38 ~0 ~71 red_nether_brick 0
fill ~40 ~-1 ~89 ~41 ~-1 ~89 red_nether_brick 0
fill ~41 ~-1 ~67 ~41 ~1 ~67 red_nether_brick 0
fill ~42 ~-1 ~90 ~44 ~-1 ~90 red_nether_brick 0
fill ~44 ~-1 ~57 ~44 ~1 ~57 red_nether_brick 0
setblock ~45 ~-1 ~55 red_nether_brick 0
fill ~45 ~-1 ~91 ~49 ~-1 ~91 red_nether_brick 0
fill ~46 ~-1 ~54 ~46 ~1 ~54 red_nether_brick 0
fill ~47 ~-1 ~53 ~48 ~-1 ~53 red_nether_brick 0
fill ~49 ~-1 ~52 ~50 ~-1 ~52 red_nether_brick 0
fill ~51 ~-1 ~51 ~52 ~-1 ~51 red_nether_brick 0
fill ~51 ~-1 ~90 ~51 ~0 ~90 red_nether_brick 0
fill ~53 ~-1 ~52 ~57 ~-1 ~52 red_nether_brick 0
fill ~53 ~-1 ~87 ~53 ~1 ~87 red_nether_brick 0
fill ~54 ~-1 ~84 ~54 ~2 ~84 red_nether_brick 0
fill ~54 ~-1 ~85 ~54 ~1 ~85 red_nether_brick 0
fill ~54 ~-1 ~86 ~54 ~0 ~86 red_nether_brick 0
setblock ~55 ~-1 ~83 red_nether_brick 0
fill ~56 ~-1 ~78 ~56 ~0 ~78 red_nether_brick 0
fill ~58 ~-1 ~53 ~59 ~-1 ~53 red_nether_brick 0
fill ~59 ~-1 ~71 ~59 ~0 ~71 red_nether_brick 0
fill ~59 ~-1 ~72 ~59 ~2 ~72 red_nether_brick 0
fill ~60 ~-1 ~54 ~60 ~0 ~54 red_nether_brick 0
fill ~60 ~-1 ~69 ~60 ~0 ~69 red_nether_brick 0
fill ~60 ~-1 ~70 ~60 ~4 ~70 red_nether_brick 0
fill ~61 ~-1 ~55 ~61 ~1 ~55 red_nether_brick 0
fill ~61 ~-1 ~68 ~61 ~5 ~68 red_nether_brick 0
fill ~62 ~-1 ~56 ~62 ~5 ~56 red_nether_brick 0
fill ~62 ~-1 ~65 ~62 ~-1 ~66 red_nether_brick 0
fill ~63 ~-1 ~57 ~63 ~4 ~57 red_nether_brick 0
fill ~63 ~-1 ~62 ~63 ~6 ~62 red_nether_brick 0
fill ~63 ~-1 ~63 ~63 ~5 ~63 red_nether_brick 0
fill ~63 ~-1 ~64 ~63 ~4 ~64 red_nether_brick 0
fill ~81 ~-1 ~58 ~81 ~5 ~58 red_nether_brick 0
fill ~81 ~-1 ~62 ~81 ~5 ~62 red_nether_brick 0
fill ~82 ~-1 ~56 ~82 ~5 ~56 red_nether_brick 0
fill ~82 ~-1 ~63 ~82 ~-1 ~66 red_nether_brick 0
fill ~83 ~-1 ~55 ~83 ~5 ~55 red_nether_brick 0
fill ~83 ~-1 ~67 ~83 ~0 ~67 red_nether_brick 0
fill ~83 ~-1 ~68 ~83 ~4 ~68 red_nether_brick 0
fill ~84 ~-1 ~54 ~84 ~1 ~54 red_nether_brick 0
fill ~84 ~-1 ~69 ~84 ~1 ~69 red_nether_brick 0
fill ~85 ~-1 ~53 ~87 ~-1 ~53 red_nether_brick 0
fill ~87 ~-1 ~75 ~87 ~0 ~75 red_nether_brick 0
fill ~88 ~-1 ~52 ~91 ~-1 ~52 red_nether_brick 0
fill ~90 ~-1 ~85 ~90 ~0 ~85 red_nether_brick 0
fill ~91 ~-1 ~86 ~91 ~2 ~86 red_nether_brick 0
fill ~92 ~-1 ~51 ~93 ~-1 ~51 red_nether_brick 0
fill ~92 ~-1 ~88 ~92 ~2 ~88 red_nether_brick 0
fill ~94 ~-1 ~52 ~95 ~-1 ~52 red_nether_brick 0
fill ~94 ~-1 ~90 ~95 ~-1 ~90 red_nether_brick 0
fill ~96 ~-1 ~53 ~97 ~-1 ~53 red_nether_brick 0
fill ~96 ~-1 ~91 ~99 ~-1 ~91 red_nether_brick 0
fill ~100 ~-1 ~57 ~100 ~1 ~57 red_nether_brick 0
fill ~100 ~-1 ~90 ~102 ~-1 ~90 red_nether_brick 0
fill ~102 ~-1 ~63 ~102 ~0 ~63 red_nether_brick 0
fill ~103 ~-1 ~89 ~104 ~-1 ~89 red_nether_brick 0
fill ~104 ~-1 ~68 ~104 ~1 ~68 red_nether_brick 0
fill ~105 ~-1 ~88 ~105 ~1 ~88 red_nether_brick 0
fill ~106 ~-1 ~87 ~106 ~1 ~87 red_nether_brick 0
fill ~108 ~-1 ~76 ~108 ~1 ~76 red_nether_brick 0
fill ~108 ~-1 ~85 ~108 ~0 ~85 red_nether_brick 0
fill ~109 ~-1 ~77 ~109 ~-1 ~82 red_nether_brick 0
fill ~36 ~0 ~79 ~36 ~2 ~79 red_nether_brick 0
fill ~37 ~0 ~74 ~37 ~1 ~74 red_nether_brick 0
fill ~38 ~0 ~72 ~38 ~1 ~72 red_nether_brick 0
fill ~39 ~0 ~70 ~39 ~1 ~70 red_nether_brick 0
fill ~40 ~0 ~69 ~40 ~1 ~69 red_nether_brick 0
fill ~40 ~0 ~88 ~40 ~2 ~88 red_nether_brick 0
fill ~41 ~0 ~89 ~41 ~1 ~89 red_nether_brick 0
fill ~42 ~0 ~90 ~44 ~0 ~90 red_nether_brick 0
fill ~45 ~0 ~91 ~49 ~0 ~91 red_nether_brick 0
fill ~46 ~0 ~55 ~46 ~13 ~55 red_nether_brick 0
fill ~47 ~0 ~53 ~47 ~2 ~53 red_nether_brick 0
fill ~48 ~0 ~52 ~50 ~0 ~52 red_nether_brick 0
fill ~51 ~0 ~51 ~53 ~0 ~51 red_nether_brick 0
fill ~54 ~0 ~52 ~58 ~0 ~52 red_nether_brick 0
fill ~54 ~0 ~83 ~54 ~2 ~83 red_nether_brick 0
setblock ~58 ~0 ~74 red_nether_brick 0
fill ~59 ~0 ~53 ~59 ~5 ~53 red_nether_brick 0
fill ~62 ~0 ~66 ~62 ~5 ~66 red_nether_brick 0
fill ~62 ~0 ~67 ~62 ~3 ~67 red_nether_brick 0
fill ~63 ~0 ~65 ~63 ~3 ~65 red_nether_brick 0
fill ~81 ~0 ~57 ~81 ~4 ~57 red_nether_brick 0
fill ~81 ~0 ~63 ~81 ~4 ~63 red_nether_brick 0
fill ~81 ~0 ~64 ~81 ~3 ~64 red_nether_brick 0
fill ~82 ~0 ~65 ~82 ~0 ~66 red_nether_brick 0
fill ~84 ~0 ~70 ~84 ~4 ~70 red_nether_brick 0
fill ~85 ~0 ~53 ~86 ~0 ~53 red_nether_brick 0
fill ~87 ~0 ~52 ~90 ~0 ~52 red_nether_brick 0
fill ~90 ~0 ~81 ~90 ~3 ~81 red_nether_brick 0
fill ~91 ~0 ~51 ~93 ~0 ~51 red_nether_brick 0
setblock ~91 ~0 ~87 red_nether_brick 0
fill ~94 ~0 ~52 ~96 ~0 ~52 red_nether_brick 0
fill ~94 ~0 ~90 ~95 ~0 ~90 red_nether_brick 0
fill ~96 ~0 ~91 ~99 ~0 ~91 red_nether_brick 0
fill ~97 ~0 ~53 ~97 ~2 ~53 red_nether_brick 0
fill ~100 ~0 ~90 ~102 ~0 ~90 red_nether_brick 0
fill ~101 ~0 ~60 ~101 ~2 ~60 red_nether_brick 0
fill ~103 ~0 ~89 ~104 ~0 ~89 red_nether_brick 0
fill ~105 ~0 ~70 ~105 ~1 ~70 red_nether_brick 0
fill ~106 ~0 ~71 ~106 ~1 ~71 red_nether_brick 0
fill ~107 ~0 ~73 ~107 ~1 ~73 red_nether_brick 0
fill ~108 ~0 ~77 ~108 ~2 ~77 red_nether_brick 0
fill ~109 ~0 ~78 ~109 ~0 ~82 red_nether_brick 0
fill ~37 ~1 ~75 ~37 ~2 ~75 red_nether_brick 0
fill ~37 ~1 ~84 ~37 ~2 ~84 red_nether_brick 0
fill ~38 ~1 ~73 ~38 ~2 ~73 red_nether_brick 0
fill ~38 ~1 ~86 ~38 ~2 ~86 red_nether_brick 0
fill ~39 ~1 ~71 ~39 ~2 ~71 red_nether_brick 0
fill ~39 ~1 ~87 ~39 ~2 ~87 red_nether_brick 0
fill ~41 ~1 ~68 ~41 ~2 ~68 red_nether_brick 0
fill ~42 ~1 ~66 ~42 ~3 ~66 red_nether_brick 0
fill ~42 ~1 ~89 ~42 ~3 ~89 red_nether_brick 0
fill ~43 ~1 ~90 ~44 ~1 ~90 red_nether_brick 0
fill ~45 ~1 ~91 ~49 ~1 ~91 red_nether_brick 0
fill ~48 ~1 ~52 ~50 ~1 ~52 red_nether_brick 0
fill ~51 ~1 ~51 ~53 ~1 ~51 red_nether_brick 0
fill ~53 ~1 ~86 ~53 ~3 ~86 red_nether_brick 0
fill ~54 ~1 ~52 ~58 ~1 ~52 red_nether_brick 0
fill ~54 ~1 ~82 ~54 ~3 ~82 red_nether_brick 0
fill ~55 ~1 ~78 ~55 ~3 ~78 red_nether_brick 0
fill ~57 ~1 ~74 ~57 ~3 ~74 red_nether_brick 0
fill ~60 ~1 ~53 ~60 ~3 ~53 red_nether_brick 0
fill ~60 ~1 ~71 ~60 ~2 ~71 red_nether_brick 0
fill ~61 ~1 ~54 ~61 ~3 ~54 red_nether_brick 0
fill ~61 ~1 ~69 ~61 ~3 ~69 red_nether_brick 0
fill ~81 ~1 ~65 ~81 ~2 ~65 red_nether_brick 0
fill ~82 ~1 ~66 ~82 ~4 ~66 red_nether_brick 0
fill ~82 ~1 ~67 ~82 ~2 ~67 red_nether_brick 0
fill ~85 ~1 ~53 ~85 ~4 ~53 red_nether_brick 0
fill ~85 ~1 ~72 ~85 ~2 ~72 red_nether_brick 0
fill ~86 ~1 ~52 ~90 ~1 ~52 red_nether_brick 0
fill ~88 ~1 ~75 ~88 ~3 ~75 red_nether_brick 0
fill ~89 ~1 ~77 ~89 ~3 ~77 red_nether_brick 0
fill ~90 ~1 ~80 ~90 ~3 ~80 red_nether_brick 0
fill ~91 ~1 ~51 ~93 ~1 ~51 red_nether_brick 0
fill ~91 ~1 ~85 ~91 ~3 ~85 red_nether_brick 0
fill ~92 ~1 ~87 ~92 ~3 ~87 red_nether_brick 0
fill ~94 ~1 ~52 ~96 ~1 ~52 red_nether_brick 0
fill ~94 ~1 ~90 ~95 ~1 ~90 red_nether_brick 0
fill ~96 ~1 ~91 ~99 ~1 ~91 red_nether_brick 0
fill ~98 ~1 ~55 ~98 ~13 ~55 red_nether_brick 0
fill ~100 ~1 ~90 ~102 ~1 ~90 red_nether_brick 0
fill ~101 ~1 ~63 ~101 ~4 ~63 red_nether_brick 0
fill ~103 ~1 ~67 ~103 ~2 ~67 red_nether_brick 0
fill ~103 ~1 ~89 ~103 ~2 ~89 red_nether_brick 0
fill ~104 ~1 ~69 ~104 ~2 ~69 red_nether_brick 0
fill ~104 ~1 ~88 ~104 ~2 ~88 red_nether_brick 0
fill ~106 ~1 ~72 ~106 ~2 ~72 red_nether_brick 0
fill ~107 ~1 ~74 ~107 ~2 ~74 red_nether_brick 0
fill ~107 ~1 ~85 ~107 ~2 ~85 red_nether_brick 0
fill ~108 ~1 ~78 ~108 ~2 ~78 red_nether_brick 0
fill ~108 ~1 ~79 ~108 ~2 ~79 red_nether_brick 0
fill ~108 ~1 ~80 ~108 ~2 ~80 red_nether_brick 0
fill ~108 ~1 ~81 ~108 ~2 ~81 red_nether_brick 0
fill ~108 ~1 ~82 ~108 ~2 ~82 red_nether_brick 0
fill ~37 ~2 ~76 ~37 ~3 ~76 red_nether_brick 0
fill ~37 ~2 ~77 ~37 ~3 ~77 red_nether_brick 0
fill ~37 ~2 ~78 ~37 ~3 ~78 red_nether_brick 0
fill ~37 ~2 ~82 ~37 ~3 ~82 red_nether_brick 0
fill ~37 ~2 ~83 ~37 ~3 ~83 red_nether_brick 0
fill ~38 ~2 ~74 ~38 ~3 ~74 red_nether_brick 0
fill ~38 ~2 ~85 ~38 ~3 ~85 red_nether_brick 0
fill ~39 ~2 ~72 ~39 ~3 ~72 red_nether_brick 0
setblock ~40 ~2 ~70 red_nether_brick 0
fill ~41 ~2 ~69 ~41 ~3 ~69 red_nether_brick 0
fill ~41 ~2 ~88 ~41 ~3 ~88 red_nether_brick 0
fill ~42 ~2 ~67 ~42 ~3 ~67 red_nether_brick 0
fill ~43 ~2 ~64 ~43 ~4 ~64 red_nether_brick 0
fill ~43 ~2 ~90 ~45 ~2 ~90 red_nether_brick 0
fill ~45 ~2 ~57 ~45 ~13 ~57 red_nether_brick 0
fill ~46 ~2 ~91 ~48 ~2 ~91 red_nether_brick 0
fill ~47 ~2 ~54 ~47 ~12 ~54 red_nether_brick 0
fill ~48 ~2 ~53 ~48 ~12 ~53 red_nether_brick 0
fill ~49 ~2 ~52 ~51 ~2 ~52 red_nether_brick 0
fill ~49 ~2 ~90 ~49 ~3 ~90 red_nether_brick 0
fill ~52 ~2 ~51 ~53 ~2 ~51 red_nether_brick 0
fill ~52 ~2 ~87 ~52 ~4 ~87 red_nether_brick 0
fill ~53 ~2 ~85 ~53 ~3 ~85 red_nether_brick 0
fill ~54 ~2 ~52 ~58 ~2 ~52 red_nether_brick 0
fill ~54 ~2 ~80 ~54 ~3 ~80 red_nether_brick 0
fill ~54 ~2 ~81 ~54 ~3 ~81 red_nether_brick 0
setblock ~62 ~2 ~55 red_nether_brick 0
setblock ~83 ~2 ~54 red_nether_brick 0
fill ~83 ~2 ~69 ~83 ~3 ~69 red_nether_brick 0
setblock ~84 ~2 ~53 red_nether_brick 0
fill ~86 ~2 ~52 ~90 ~2 ~52 red_nether_brick 0
fill ~90 ~2 ~79 ~90 ~3 ~79 red_nether_brick 0
fill ~91 ~2 ~51 ~92 ~2 ~51 red_nether_brick 0
fill ~91 ~2 ~84 ~91 ~3 ~84 red_nether_brick 0
fill ~93 ~2 ~52 ~95 ~2 ~52 red_nether_brick 0
fill ~94 ~2 ~90 ~95 ~2 ~90 red_nether_brick 0
fill ~96 ~2 ~53 ~96 ~12 ~53 red_nether_brick 0
fill ~96 ~2 ~91 ~98 ~2 ~91 red_nether_brick 0
fill ~97 ~2 ~54 ~97 ~8 ~54 red_nether_brick 0
fill ~99 ~2 ~57 ~99 ~13 ~57 red_nether_brick 0
fill ~99 ~2 ~90 ~101 ~2 ~90 red_nether_brick 0
fill ~102 ~2 ~66 ~102 ~3 ~66 red_nether_brick 0
fill ~102 ~2 ~89 ~102 ~3 ~89 red_nether_brick 0
fill ~103 ~2 ~68 ~103 ~3 ~68 red_nether_brick 0
fill ~104 ~2 ~70 ~104 ~3 ~70 red_nether_brick 0
setblock ~105 ~2 ~71 red_nether_brick 0
setblock ~105 ~2 ~87 red_nether_brick 0
setblock ~106 ~2 ~73 red_nether_brick 0
setblock ~106 ~2 ~86 red_nether_brick 0
fill ~107 ~2 ~75 ~107 ~3 ~75 red_nether_brick 0
fill ~107 ~2 ~76 ~107 ~3 ~76 red_nether_brick 0
fill ~107 ~2 ~84 ~107 ~3 ~84 red_nether_brick 0
fill ~37 ~3 ~79 ~37 ~3 ~83 red_nether_brick 0
fill ~38 ~3 ~75 ~38 ~4 ~75 red_nether_brick 0
fill ~38 ~3 ~84 ~38 ~4 ~84 red_nether_brick 0
setblock ~39 ~3 ~73 red_nether_brick 0
setblock ~39 ~3 ~86 red_nether_brick 0
setblock ~40 ~3 ~71 red_nether_brick 0
setblock ~40 ~3 ~87 red_nether_brick 0
fill ~41 ~3 ~70 ~41 ~4 ~70 red_nether_brick 0
fill ~42 ~3 ~68 ~42 ~4 ~68 red_nether_brick 0
fill ~43 ~3 ~65 ~43 ~4 ~65 red_nether_brick 0
setblock ~43 ~3 ~89 red_nether_brick 0
fill ~44 ~3 ~61 ~44 ~5 ~61 red_nether_brick 0
fill ~44 ~3 ~90 ~50 ~3 ~90 red_nether_brick 0
fill ~45 ~3 ~58 ~45 ~13 ~58 red_nether_brick 0
fill ~46 ~3 ~56 ~46 ~9 ~56 red_nether_brick 0
fill ~49 ~3 ~52 ~52 ~3 ~52 red_nether_brick 0
fill ~51 ~3 ~88 ~51 ~4 ~88 red_nether_brick 0
setblock ~53 ~3 ~51 red_nether_brick 0
fill ~53 ~3 ~83 ~53 ~4 ~83 red_nether_brick 0
fill ~53 ~3 ~84 ~53 ~4 ~84 red_nether_brick 0
fill ~54 ~3 ~52 ~58 ~3 ~52 red_nether_brick 0
fill ~54 ~3 ~79 ~54 ~4 ~79 red_nether_brick 0
fill ~55 ~3 ~77 ~55 ~4 ~77 red_nether_brick 0
fill ~56 ~3 ~75 ~56 ~4 ~75 red_nether_brick 0
fill ~58 ~3 ~72 ~58 ~4 ~72 red_nether_brick 0
fill ~59 ~3 ~71 ~59 ~4 ~71 red_nether_brick 0
fill ~61 ~3 ~55 ~61 ~5 ~55 red_nether_brick 0
fill ~82 ~3 ~65 ~82 ~6 ~65 red_nether_brick 0
fill ~83 ~3 ~67 ~83 ~6 ~67 red_nether_brick 0
fill ~84 ~3 ~54 ~84 ~5 ~54 red_nether_brick 0
fill ~86 ~3 ~52 ~95 ~3 ~52 red_nether_brick 0
fill ~86 ~3 ~72 ~86 ~4 ~72 red_nether_brick 0
fill ~87 ~3 ~73 ~87 ~4 ~73 red_nether_brick 0
fill ~89 ~3 ~76 ~89 ~4 ~76 red_nether_brick 0
fill ~90 ~3 ~78 ~90 ~4 ~78 red_nether_brick 0
fill ~91 ~3 ~82 ~91 ~4 ~82 red_nether_brick 0
fill ~91 ~3 ~83 ~91 ~4 ~83 red_nether_brick 0
fill ~92 ~3 ~86 ~92 ~4 ~86 red_nether_brick 0
fill ~93 ~3 ~88 ~93 ~4 ~88 red_nether_brick 0
fill ~94 ~3 ~89 ~94 ~4 ~89 red_nether_brick 0
fill ~95 ~3 ~90 ~100 ~3 ~90 red_nether_brick 0
fill ~100 ~3 ~60 ~100 ~6 ~60 red_nether_brick 0
fill ~101 ~3 ~64 ~101 ~4 ~64 red_nether_brick 0
fill ~101 ~3 ~89 ~101 ~4 ~89 red_nether_brick 0
fill ~102 ~3 ~67 ~102 ~4 ~67 red_nether_brick 0
setblock ~103 ~3 ~69 red_nether_brick 0
setblock ~103 ~3 ~88 red_nether_brick 0
setblock ~104 ~3 ~71 red_nether_brick 0
fill ~104 ~3 ~87 ~104 ~4 ~87 red_nether_brick 0
fill ~105 ~3 ~72 ~105 ~3 ~73 red_nether_brick 0
fill ~105 ~3 ~86 ~105 ~4 ~86 red_nether_brick 0
setblock ~106 ~3 ~74 red_nether_brick 0
setblock ~106 ~3 ~85 red_nether_brick 0
fill ~107 ~3 ~77 ~107 ~3 ~84 red_nether_brick 0
fill ~38 ~4 ~76 ~38 ~4 ~84 red_nether_brick 0
setblock ~39 ~4 ~74 red_nether_brick 0
setblock ~39 ~4 ~85 red_nether_brick 0
fill ~40 ~4 ~72 ~40 ~4 ~73 red_nether_brick 0
setblock ~40 ~4 ~86 red_nether_brick 0
setblock ~41 ~4 ~71 red_nether_brick 0
setblock ~41 ~4 ~87 red_nether_brick 0
setblock ~42 ~4 ~69 red_nether_brick 0
fill ~42 ~4 ~88 ~43 ~4 ~88 red_nether_brick 0
fill ~43 ~4 ~66 ~43 ~4 ~67 red_nether_brick 0
fill ~44 ~4 ~62 ~44 ~6 ~62 red_nether_brick 0
fill ~44 ~4 ~63 ~44 ~5 ~63 red_nether_brick 0
fill ~44 ~4 ~89 ~45 ~4 ~89 red_nether_brick 0
fill ~46 ~4 ~90 ~48 ~4 ~90 red_nether_brick 0
fill ~49 ~4 ~52 ~57 ~4 ~52 red_nether_brick 0
fill ~49 ~4 ~89 ~50 ~4 ~89 red_nether_brick 0
fill ~52 ~4 ~85 ~52 ~5 ~85 red_nether_brick 0
fill ~52 ~4 ~86 ~52 ~4 ~85 red_nether_brick 0
fill ~53 ~4 ~80 ~53 ~5 ~80 red_nether_brick 0
fill ~53 ~4 ~81 ~53 ~5 ~81 red_nether_brick 0
fill ~53 ~4 ~82 ~53 ~4 ~80 red_nether_brick 0
setblock ~54 ~4 ~78 red_nether_brick 0
setblock ~55 ~4 ~76 red_nether_brick 0
fill ~56 ~4 ~74 ~56 ~5 ~74 red_nether_brick 0
setblock ~57 ~4 ~73 red_nether_brick 0
fill ~58 ~4 ~53 ~58 ~6 ~53 red_nether_brick 0
fill ~60 ~4 ~54 ~60 ~5 ~54 red_nether_brick 0
fill ~60 ~4 ~69 ~60 ~6 ~69 red_nether_brick 0
fill ~61 ~4 ~67 ~61 ~6 ~67 red_nether_brick 0
fill ~62 ~4 ~65 ~62 ~6 ~65 red_nether_brick 0
fill ~82 ~4 ~64 ~82 ~7 ~64 red_nether_brick 0
fill ~84 ~4 ~69 ~84 ~5 ~69 red_nether_brick 0
fill ~86 ~4 ~53 ~86 ~5 ~53 red_nether_brick 0
fill ~87 ~4 ~52 ~95 ~4 ~52 red_nether_brick 0
setblock ~88 ~4 ~74 red_nether_brick 0
fill ~89 ~4 ~75 ~89 ~5 ~75 red_nether_brick 0
fill ~90 ~4 ~77 ~90 ~5 ~77 red_nether_brick 0
fill ~91 ~4 ~79 ~91 ~5 ~79 red_nether_brick 0
fill ~91 ~4 ~80 ~91 ~4 ~83 red_nether_brick 0
fill ~92 ~4 ~84 ~92 ~5 ~84 red_nether_brick 0
fill ~92 ~4 ~85 ~92 ~4 ~84 red_nether_brick 0
fill ~93 ~4 ~87 ~93 ~5 ~87 red_nether_brick 0
fill ~95 ~4 ~89 ~96 ~4 ~89 red_nether_brick 0
fill ~97 ~4 ~90 ~99 ~4 ~90 red_nether_brick 0
fill ~98 ~4 ~56 ~98 ~8 ~56 red_nether_brick 0
fill ~99 ~4 ~58 ~99 ~13 ~58 red_nether_brick 0
fill ~100 ~4 ~61 ~100 ~6 ~61 red_nether_brick 0
fill ~100 ~4 ~62 ~100 ~6 ~62 red_nether_brick 0
setblock ~100 ~4 ~89 red_nether_brick 0
fill ~101 ~4 ~65 ~101 ~4 ~66 red_nether_brick 0
fill ~102 ~4 ~68 ~102 ~4 ~69 red_nether_brick 0
setblock ~102 ~4 ~88 red_nether_brick 0
fill ~103 ~4 ~70 ~103 ~4 ~71 red_nether_brick 0
setblock ~103 ~4 ~87 red_nether_brick 0
setblock ~104 ~4 ~72 red_nether_brick 0
fill ~105 ~4 ~73 ~105 ~4 ~74 red_nether_brick 0
fill ~105 ~4 ~85 ~105 ~5 ~85 red_nether_brick 0
fill ~106 ~4 ~75 ~106 ~4 ~78 red_nether_brick 0
fill ~106 ~4 ~83 ~106 ~5 ~83 red_nether_brick 0
fill ~106 ~4 ~84 ~106 ~4 ~83 red_nether_brick 0
fill ~107 ~4 ~79 ~107 ~4 ~82 red_nether_brick 0
fill ~38 ~5 ~80 ~38 ~5 ~82 red_nether_brick 0
fill ~39 ~5 ~75 ~39 ~5 ~79 red_nether_brick 0
fill ~39 ~5 ~82 ~39 ~5 ~84 red_nether_brick 0
setblock ~40 ~5 ~74 red_nether_brick 0
setblock ~40 ~5 ~85 red_nether_brick 0
fill ~41 ~5 ~72 ~41 ~5 ~73 red_nether_brick 0
setblock ~41 ~5 ~86 red_nether_brick 0
fill ~42 ~5 ~70 ~42 ~5 ~71 red_nether_brick 0
setblock ~42 ~5 ~87 red_nether_brick 0
fill ~43 ~5 ~67 ~43 ~5 ~69 red_nether_brick 0
fill ~43 ~5 ~88 ~44 ~5 ~88 red_nether_brick 0
fill ~44 ~5 ~64 ~44 ~5 ~66 red_nether_brick 0
fill ~45 ~5 ~59 ~45 ~14 ~59 red_nether_brick 0
fill ~45 ~5 ~89 ~48 ~5 ~89 red_nether_brick 0
fill ~49 ~5 ~52 ~56 ~5 ~52 red_nether_brick 0
fill ~49 ~5 ~88 ~50 ~5 ~88 red_nether_brick 0
fill ~51 ~5 ~86 ~51 ~5 ~87 red_nether_brick 0
fill ~52 ~5 ~82 ~52 ~5 ~85 red_nether_brick 0
fill ~53 ~5 ~78 ~53 ~5 ~81 red_nether_brick 0
fill ~54 ~5 ~76 ~54 ~5 ~77 red_nether_brick 0
setblock ~55 ~5 ~75 red_nether_brick 0
setblock ~56 ~5 ~73 red_nether_brick 0
fill ~57 ~5 ~53 ~57 ~13 ~53 red_nether_brick 0
setblock ~57 ~5 ~72 red_nether_brick 0
fill ~58 ~5 ~71 ~58 ~6 ~71 red_nether_brick 0
fill ~59 ~5 ~70 ~59 ~6 ~70 red_nether_brick 0
fill ~62 ~5 ~57 ~62 ~8 ~57 red_nether_brick 0
fill ~62 ~5 ~64 ~62 ~8 ~64 red_nether_brick 0
fill ~82 ~5 ~57 ~82 ~7 ~57 red_nether_brick 0
fill ~82 ~5 ~63 ~82 ~9 ~63 red_nether_brick 0
fill ~83 ~5 ~66 ~83 ~7 ~66 red_nether_brick 0
fill ~84 ~5 ~68 ~84 ~6 ~68 red_nether_brick 0
fill ~85 ~5 ~54 ~85 ~7 ~54 red_nether_brick 0
setblock ~85 ~5 ~70 red_nether_brick 0
setblock ~86 ~5 ~71 red_nether_brick 0
fill ~87 ~5 ~53 ~87 ~13 ~53 red_nether_brick 0
setblock ~87 ~5 ~72 red_nether_brick 0
fill ~88 ~5 ~52 ~95 ~5 ~52 red_nether_brick 0
setblock ~88 ~5 ~73 red_nether_brick 0
setblock ~89 ~5 ~74 red_nether_brick 0
setblock ~90 ~5 ~76 red_nether_brick 0
setblock ~91 ~5 ~78 red_nether_brick 0
fill ~92 ~5 ~80 ~92 ~5 ~84 red_nether_brick 0
fill ~93 ~5 ~85 ~93 ~5 ~87 red_nether_brick 0
fill ~94 ~5 ~88 ~95 ~5 ~88 red_nether_brick 0
fill ~96 ~5 ~89 ~99 ~5 ~89 red_nether_brick 0
fill ~100 ~5 ~63 ~100 ~6 ~63 red_nether_brick 0
fill ~100 ~5 ~64 ~100 ~6 ~64 red_nether_brick 0
fill ~100 ~5 ~65 ~100 ~6 ~65 red_nether_brick 0
fill ~100 ~5 ~88 ~101 ~5 ~88 red_nether_brick 0
fill ~101 ~5 ~66 ~101 ~5 ~68 red_nether_brick 0
fill ~102 ~5 ~69 ~102 ~5 ~71 red_nether_brick 0
setblock ~102 ~5 ~87 red_nether_brick 0
setblock ~103 ~5 ~72 red_nether_brick 0
fill ~103 ~5 ~86 ~104 ~5 ~86 red_nether_brick 0
fill ~104 ~5 ~73 ~104 ~5 ~74 red_nether_brick 0
setblock ~104 ~5 ~85 red_nether_brick 0
fill ~105 ~5 ~75 ~105 ~5 ~76 red_nether_brick 0
setblock ~105 ~5 ~84 red_nether_brick 0
fill ~106 ~5 ~77 ~106 ~5 ~83 red_nether_brick 0
fill ~39 ~6 ~78 ~40 ~6 ~78 red_nether_brick 0
fill ~39 ~6 ~80 ~39 ~6 ~81 red_nether_brick 0
fill ~40 ~6 ~75 ~40 ~6 ~79 red_nether_brick 0
fill ~40 ~6 ~81 ~40 ~6 ~84 red_nether_brick 0
setblock ~41 ~6 ~74 red_nether_brick 0
setblock ~41 ~6 ~85 red_nether_brick 0
fill ~42 ~6 ~72 ~43 ~6 ~72 red_nether_brick 0
fill ~42 ~6 ~73 ~42 ~6 ~72 red_nether_brick 0
fill ~42 ~6 ~86 ~43 ~6 ~86 red_nether_brick 0
fill ~43 ~6 ~70 ~44 ~6 ~70 red_nether_brick 0
fill ~43 ~6 ~71 ~43 ~6 ~70 red_nether_brick 0
fill ~43 ~6 ~87 ~45 ~6 ~87 red_nether_brick 0
fill ~44 ~6 ~65 ~44 ~6 ~70 red_nether_brick 0
fill ~45 ~6 ~60 ~45 ~14 ~60 red_nether_brick 0
fill ~45 ~6 ~61 ~45 ~14 ~61 red_nether_brick 0
fill ~45 ~6 ~63 ~45 ~9 ~63 red_nether_brick 0
fill ~45 ~6 ~64 ~45 ~8 ~64 red_nether_brick 0
fill ~45 ~6 ~88 ~48 ~6 ~88 red_nether_brick 0
fill ~49 ~6 ~52 ~55 ~6 ~52 red_nether_brick 0
fill ~49 ~6 ~87 ~50 ~6 ~87 red_nether_brick 0
setblock ~50 ~6 ~86 red_nether_brick 0
fill ~51 ~6 ~82 ~51 ~6 ~85 red_nether_brick 0
fill ~52 ~6 ~78 ~52 ~6 ~81 red_nether_brick 0
fill ~53 ~6 ~76 ~53 ~6 ~77 red_nether_brick 0
fill ~54 ~6 ~74 ~55 ~6 ~74 red_nether_brick 0
fill ~54 ~6 ~75 ~54 ~6 ~74 red_nether_brick 0
setblock ~55 ~6 ~73 red_nether_brick 0
fill ~56 ~6 ~53 ~56 ~13 ~53 red_nether_brick 0
setblock ~56 ~6 ~72 red_nether_brick 0
setblock ~57 ~6 ~71 red_nether_brick 0
fill ~59 ~6 ~54 ~59 ~13 ~54 red_nether_brick 0
fill ~60 ~6 ~55 ~60 ~14 ~55 red_nether_brick 0
fill ~60 ~6 ~68 ~60 ~7 ~68 red_nether_brick 0
fill ~61 ~6 ~56 ~61 ~14 ~56 red_nether_brick 0
fill ~61 ~6 ~66 ~61 ~8 ~66 red_nether_brick 0
fill ~62 ~6 ~58 ~62 ~13 ~58 red_nether_brick 0
fill ~62 ~6 ~63 ~62 ~10 ~63 red_nether_brick 0
fill ~82 ~6 ~58 ~82 ~10 ~58 red_nether_brick 0
fill ~82 ~6 ~62 ~82 ~10 ~62 red_nether_brick 0
fill ~83 ~6 ~56 ~83 ~8 ~56 red_nether_brick 0
fill ~84 ~6 ~55 ~84 ~13 ~55 red_nether_brick 0
setblock ~85 ~6 ~69 red_nether_brick 0
fill ~86 ~6 ~54 ~86 ~14 ~54 red_nether_brick 0
setblock ~86 ~6 ~70 red_nether_brick 0
setblock ~87 ~6 ~71 red_nether_brick 0
fill ~88 ~6 ~53 ~88 ~13 ~53 red_nether_brick 0
setblock ~88 ~6 ~72 red_nether_brick 0
fill ~89 ~6 ~52 ~95 ~6 ~52 red_nether_brick 0
setblock ~89 ~6 ~73 red_nether_brick 0
fill ~90 ~6 ~74 ~90 ~6 ~75 red_nether_brick 0
fill ~91 ~6 ~75 ~91 ~6 ~77 red_nether_brick 0
fill ~92 ~6 ~77 ~92 ~6 ~79 red_nether_brick 0
fill ~93 ~6 ~80 ~93 ~6 ~84 red_nether_brick 0
fill ~94 ~6 ~84 ~94 ~6 ~87 red_nether_brick 0
setblock ~95 ~6 ~87 red_nether_brick 0
fill ~96 ~6 ~88 ~99 ~6 ~88 red_nether_brick 0
fill ~99 ~6 ~59 ~99 ~11 ~59 red_nether_brick 0
fill ~99 ~6 ~87 ~101 ~6 ~87 red_nether_brick 0
fill ~100 ~6 ~66 ~100 ~6 ~69 red_nether_brick 0
fill ~101 ~6 ~69 ~101 ~6 ~71 red_nether_brick 0
fill ~102 ~6 ~72 ~102 ~6 ~73 red_nether_brick 0
setblock ~102 ~6 ~86 red_nether_brick 0
fill ~103 ~6 ~73 ~103 ~6 ~74 red_nether_brick 0
setblock ~103 ~6 ~85 red_nether_brick 0
setblock ~104 ~6 ~75 red_nether_brick 0
setblock ~104 ~6 ~84 red_nether_brick 0
fill ~105 ~6 ~76 ~105 ~6 ~83 red_nether_brick 0
fill ~40 ~7 ~79 ~41 ~7 ~79 red_nether_brick 0
fill ~40 ~7 ~80 ~41 ~7 ~80 red_nether_brick 0
fill ~41 ~7 ~75 ~42 ~7 ~75 red_nether_brick 0
fill ~41 ~7 ~76 ~42 ~7 ~76 red_nether_brick 0
fill ~41 ~7 ~77 ~41 ~7 ~84 red_nether_brick 0
fill ~42 ~7 ~74 ~43 ~7 ~74 red_nether_brick 0
fill ~42 ~7 ~84 ~42 ~7 ~85 red_nether_brick 0
fill ~43 ~7 ~73 ~44 ~7 ~73 red_nether_brick 0
setblock ~43 ~7 ~85 red_nether_brick 0
fill ~44 ~7 ~71 ~45 ~7 ~71 red_nether_brick 0
fill ~44 ~7 ~72 ~45 ~7 ~72 red_nether_brick 0
fill ~44 ~7 ~86 ~49 ~7 ~86 red_nether_brick 0
fill ~45 ~7 ~62 ~45 ~13 ~62 red_nether_brick 0
fill ~45 ~7 ~65 ~45 ~7 ~72 red_nether_brick 0
fill ~46 ~7 ~87 ~48 ~7 ~87 red_nether_brick 0
fill ~49 ~7 ~52 ~55 ~7 ~52 red_nether_brick 0
fill ~49 ~7 ~84 ~50 ~7 ~84 red_nether_brick 0
fill ~49 ~7 ~85 ~50 ~7 ~85 red_nether_brick 0
fill ~50 ~7 ~81 ~51 ~7 ~81 red_nether_brick 0
fill ~50 ~7 ~82 ~50 ~7 ~85 red_nether_brick 0
fill ~51 ~7 ~77 ~52 ~7 ~77 red_nether_brick 0
fill ~51 ~7 ~78 ~51 ~7 ~81 red_nether_brick 0
fill ~52 ~7 ~75 ~53 ~7 ~75 red_nether_brick 0
fill ~52 ~7 ~76 ~52 ~7 ~75 red_nether_brick 0
fill ~53 ~7 ~73 ~54 ~7 ~73 red_nether_brick 0
fill ~53 ~7 ~74 ~53 ~7 ~73 red_nether_brick 0
setblock ~55 ~7 ~72 red_nether_brick 0
setblock ~56 ~7 ~71 red_nether_brick 0
fill ~57 ~7 ~70 ~58 ~7 ~70 red_nether_brick 0
fill ~58 ~7 ~54 ~58 ~14 ~54 red_nether_brick 0
fill ~58 ~7 ~69 ~59 ~7 ~69 red_nether_brick 0
fill ~60 ~7 ~67 ~60 ~8 ~67 red_nether_brick 0
fill ~61 ~7 ~65 ~61 ~10 ~65 red_nether_brick 0
fill ~62 ~7 ~59 ~62 ~13 ~59 red_nether_brick 0
fill ~62 ~7 ~62 ~62 ~12 ~62 red_nether_brick 0
fill ~82 ~7 ~59 ~82 ~12 ~59 red_nether_brick 0
fill ~82 ~7 ~60 ~82 ~11 ~60 red_nether_brick 0
fill ~82 ~7 ~61 ~82 ~11 ~61 red_nether_brick 0
fill ~83 ~7 ~65 ~83 ~10 ~65 red_nether_brick 0
fill ~84 ~7 ~67 ~84 ~8 ~67 red_nether_brick 0
fill ~85 ~7 ~68 ~85 ~8 ~68 red_nether_brick 0
setblock ~86 ~7 ~69 red_nether_brick 0
setblock ~87 ~7 ~70 red_nether_brick 0
setblock ~88 ~7 ~71 red_nether_brick 0
fill ~89 ~7 ~53 ~89 ~13 ~53 red_nether_brick 0
fill ~89 ~7 ~72 ~90 ~7 ~72 red_nether_brick 0
fill ~90 ~7 ~52 ~95 ~7 ~52 red_nether_brick 0
fill ~90 ~7 ~73 ~91 ~7 ~73 red_nether_brick 0
fill ~91 ~7 ~74 ~92 ~7 ~74 red_nether_brick 0
fill ~92 ~7 ~75 ~92 ~7 ~76 red_nether_brick 0
fill ~93 ~7 ~76 ~93 ~7 ~79 red_nether_brick 0
fill ~94 ~7 ~80 ~94 ~7 ~83 red_nether_brick 0
fill ~95 ~7 ~83 ~95 ~7 ~86 red_nether_brick 0
fill ~96 ~7 ~85 ~96 ~7 ~87 red_nether_brick 0
fill ~97 ~7 ~86 ~101 ~7 ~86 red_nether_brick 0
fill ~97 ~7 ~87 ~98 ~7 ~87 red_nether_brick 0
fill ~99 ~7 ~60 ~99 ~14 ~60 red_nether_brick 0
fill ~99 ~7 ~61 ~99 ~14 ~61 red_nether_brick 0
fill ~99 ~7 ~62 ~99 ~14 ~62 red_nether_brick 0
fill ~99 ~7 ~63 ~99 ~9 ~63 red_nether_brick 0
fill ~99 ~7 ~64 ~99 ~8 ~64 red_nether_brick 0
fill ~99 ~7 ~65 ~99 ~7 ~71 red_nether_brick 0
fill ~100 ~7 ~70 ~100 ~7 ~73 red_nether_brick 0
fill ~101 ~7 ~72 ~101 ~7 ~74 red_nether_brick 0
fill ~101 ~7 ~85 ~102 ~7 ~85 red_nether_brick 0
fill ~102 ~7 ~74 ~102 ~7 ~75 red_nether_brick 0
fill ~103 ~7 ~75 ~103 ~7 ~77 red_nether_brick 0
fill ~103 ~7 ~82 ~104 ~7 ~82 red_nether_brick 0
fill ~103 ~7 ~83 ~104 ~7 ~83 red_nether_brick 0
fill ~103 ~7 ~84 ~103 ~7 ~82 red_nether_brick 0
fill ~104 ~7 ~76 ~104 ~7 ~83 red_nether_brick 0
fill ~42 ~8 ~77 ~43 ~8 ~77 red_nether_brick 0
fill ~42 ~8 ~78 ~42 ~8 ~83 red_nether_brick 0
fill ~43 ~8 ~75 ~51 ~8 ~75 red_nether_brick 0
fill ~43 ~8 ~76 ~44 ~8 ~76 red_nether_brick 0
fill ~43 ~8 ~82 ~43 ~8 ~84 red_nether_brick 0
fill ~44 ~8 ~74 ~52 ~8 ~74 red_nether_brick 0
fill ~44 ~8 ~84 ~48 ~8 ~84 red_nether_brick 0
fill ~44 ~8 ~85 ~48 ~8 ~85 red_nether_brick 0
fill ~45 ~8 ~73 ~52 ~8 ~73 red_nether_brick 0
fill ~46 ~8 ~65 ~46 ~9 ~65 red_nether_brick 0
fill ~46 ~8 ~66 ~46 ~8 ~75 red_nether_brick 0
fill ~47 ~8 ~68 ~47 ~8 ~75 red_nether_brick 0
fill ~47 ~8 ~83 ~49 ~8 ~83 red_nether_brick 0
fill ~48 ~8 ~70 ~48 ~8 ~76 red_nether_brick 0
fill ~48 ~8 ~81 ~49 ~8 ~81 red_nether_brick 0
fill ~48 ~8 ~82 ~49 ~8 ~82 red_nether_brick 0
fill ~49 ~8 ~52 ~54 ~8 ~52 red_nether_brick 0
fill ~49 ~8 ~72 ~54 ~8 ~72 red_nether_brick 0
fill ~49 ~8 ~76 ~51 ~8 ~76 red_nether_brick 0
fill ~49 ~8 ~77 ~50 ~8 ~77 red_nether_brick 0
fill ~49 ~8 ~78 ~50 ~8 ~78 red_nether_brick 0
fill ~49 ~8 ~79 ~50 ~8 ~79 red_nether_brick 0
fill ~49 ~8 ~80 ~50 ~8 ~80 red_nether_brick 0
fill ~53 ~8 ~71 ~55 ~8 ~71 red_nether_brick 0
fill ~55 ~8 ~53 ~55 ~11 ~53 red_nether_brick 0
fill ~55 ~8 ~70 ~56 ~8 ~70 red_nether_brick 0
setblock ~57 ~8 ~69 red_nether_brick 0
fill ~58 ~8 ~68 ~59 ~8 ~68 red_nether_brick 0
fill ~62 ~8 ~60 ~62 ~12 ~60 red_nether_brick 0
fill ~62 ~8 ~61 ~62 ~12 ~61 red_nether_brick 0
fill ~83 ~8 ~57 ~83 ~14 ~57 red_nether_brick 0
fill ~83 ~8 ~64 ~83 ~13 ~64 red_nether_brick 0
fill ~84 ~8 ~66 ~84 ~11 ~66 red_nether_brick 0
fill ~85 ~8 ~55 ~85 ~11 ~55 red_nether_brick 0
fill ~86 ~8 ~68 ~86 ~9 ~68 red_nether_brick 0
setblock ~87 ~8 ~69 red_nether_brick 0
fill ~88 ~8 ~70 ~89 ~8 ~70 red_nether_brick 0
fill ~89 ~8 ~71 ~91 ~8 ~71 red_nether_brick 0
fill ~90 ~8 ~52 ~95 ~8 ~52 red_nether_brick 0
fill ~91 ~8 ~72 ~99 ~8 ~72 red_nether_brick 0
fill ~92 ~8 ~73 ~99 ~8 ~73 red_nether_brick 0
fill ~93 ~8 ~74 ~100 ~8 ~74 red_nether_brick 0
fill ~93 ~8 ~75 ~101 ~8 ~75 red_nether_brick 0
fill ~94 ~8 ~76 ~96 ~8 ~76 red_nether_brick 0
fill ~94 ~8 ~77 ~96 ~8 ~77 red_nether_brick 0
fill ~94 ~8 ~78 ~95 ~8 ~78 red_nether_brick 0
fill ~94 ~8 ~79 ~96 ~8 ~79 red_nether_brick 0
fill ~95 ~8 ~80 ~96 ~8 ~80 red_nether_brick 0
fill ~95 ~8 ~81 ~96 ~8 ~81 red_nether_brick 0
fill ~95 ~8 ~82 ~97 ~8 ~82 red_nether_brick 0
fill ~96 ~8 ~71 ~98 ~8 ~71 red_nether_brick 0
fill ~96 ~8 ~83 ~98 ~8 ~83 red_nether_brick 0
fill ~96 ~8 ~84 ~102 ~8 ~84 red_nether_brick 0
fill ~97 ~8 ~53 ~97 ~11 ~53 red_nether_brick 0
fill ~97 ~8 ~68 ~98 ~8 ~68 red_nether_brick 0
fill ~97 ~8 ~69 ~98 ~8 ~69 red_nether_brick 0
fill ~97 ~8 ~70 ~98 ~8 ~70 red_nether_brick 0
fill ~97 ~8 ~85 ~100 ~8 ~85 red_nether_brick 0
fill ~98 ~8 ~65 ~98 ~9 ~65 red_nether_brick 0
fill ~98 ~8 ~66 ~98 ~8 ~75 red_nether_brick 0
fill ~100 ~8 ~76 ~102 ~8 ~76 red_nether_brick 0
fill ~101 ~8 ~77 ~102 ~8 ~77 red_nether_brick 0
fill ~101 ~8 ~83 ~102 ~8 ~83 red_nether_brick 0
fill ~102 ~8 ~78 ~103 ~8 ~78 red_nether_brick 0
fill ~102 ~8 ~79 ~103 ~8 ~79 red_nether_brick 0
fill ~102 ~8 ~80 ~103 ~8 ~80 red_nether_brick 0
fill ~102 ~8 ~81 ~103 ~8 ~81 red_nether_brick 0
fill ~102 ~8 ~82 ~102 ~8 ~76 red_nether_brick 0
fill ~43 ~9 ~78 ~48 ~9 ~78 red_nether_brick 0
fill ~43 ~9 ~79 ~48 ~9 ~79 red_nether_brick 0
fill ~43 ~9 ~80 ~48 ~9 ~80 red_nether_brick 0
fill ~43 ~9 ~81 ~47 ~9 ~81 red_nether_brick 0
fill ~44 ~9 ~77 ~48 ~9 ~77 red_nether_brick 0
fill ~44 ~9 ~82 ~47 ~9 ~82 red_nether_brick 0
fill ~44 ~9 ~83 ~46 ~9 ~83 red_nether_brick 0
fill ~45 ~9 ~76 ~47 ~9 ~76 red_nether_brick 0
fill ~46 ~9 ~64 ~46 ~10 ~64 red_nether_brick 0
fill ~47 ~9 ~53 ~47 ~10 ~53 red_nether_brick 0
fill ~47 ~9 ~66 ~47 ~9 ~67 red_nether_brick 0
fill ~48 ~9 ~67 ~48 ~9 ~69 red_nether_brick 0
fill ~49 ~9 ~52 ~54 ~9 ~52 red_nether_brick 0
fill ~49 ~9 ~68 ~49 ~9 ~71 red_nether_brick 0
fill ~50 ~9 ~69 ~50 ~9 ~71 red_nether_brick 0
fill ~51 ~9 ~70 ~54 ~9 ~70 red_nether_brick 0
fill ~51 ~9 ~71 ~52 ~9 ~71 red_nether_brick 0
fill ~55 ~9 ~69 ~56 ~9 ~69 red_nether_brick 0
fill ~57 ~9 ~68 ~58 ~9 ~68 red_nether_brick 0
fill ~59 ~9 ~67 ~59 ~10 ~67 red_nether_brick 0
fill ~60 ~9 ~66 ~60 ~11 ~66 red_nether_brick 0
fill ~61 ~9 ~57 ~61 ~14 ~57 red_nether_brick 0
fill ~61 ~9 ~64 ~61 ~14 ~64 red_nether_brick 0
fill ~84 ~9 ~56 ~84 ~15 ~56 red_nether_brick 0
fill ~85 ~9 ~67 ~85 ~10 ~67 red_nether_brick 0
fill ~87 ~9 ~68 ~87 ~10 ~68 red_nether_brick 0
fill ~88 ~9 ~69 ~89 ~9 ~69 red_nether_brick 0
fill ~90 ~9 ~52 ~95 ~9 ~52 red_nether_brick 0
fill ~90 ~9 ~70 ~96 ~9 ~70 red_nether_brick 0
fill ~92 ~9 ~71 ~95 ~9 ~71 red_nether_brick 0
fill ~94 ~9 ~69 ~96 ~9 ~69 red_nether_brick 0
setblock ~96 ~9 ~68 red_nether_brick 0
fill ~96 ~9 ~78 ~101 ~9 ~78 red_nether_brick 0
fill ~97 ~9 ~66 ~97 ~10 ~66 red_nether_brick 0
fill ~97 ~9 ~67 ~97 ~9 ~66 red_nether_brick 0
fill ~97 ~9 ~76 ~99 ~9 ~76 red_nether_brick 0
fill ~97 ~9 ~77 ~100 ~9 ~77 red_nether_brick 0
fill ~97 ~9 ~79 ~101 ~9 ~79 red_nether_brick 0
fill ~97 ~9 ~80 ~101 ~9 ~80 red_nether_brick 0
fill ~97 ~9 ~81 ~101 ~9 ~81 red_nether_brick 0
fill ~98 ~9 ~54 ~98 ~10 ~54 red_nether_brick 0
fill ~98 ~9 ~64 ~98 ~11 ~64 red_nether_brick 0
fill ~98 ~9 ~82 ~101 ~9 ~82 red_nether_brick 0
fill ~99 ~9 ~56 ~99 ~12 ~56 red_nether_brick 0
fill ~99 ~9 ~83 ~100 ~9 ~83 red_nether_brick 0
fill ~45 ~10 ~56 ~45 ~12 ~56 red_nether_brick 0
fill ~46 ~10 ~63 ~46 ~14 ~63 red_nether_brick 0
fill ~47 ~10 ~65 ~47 ~11 ~65 red_nether_brick 0
setblock ~48 ~10 ~66 red_nether_brick 0
fill ~49 ~10 ~52 ~54 ~10 ~52 red_nether_brick 0
setblock ~49 ~10 ~67 red_nether_brick 0
fill ~50 ~10 ~68 ~51 ~10 ~68 red_nether_brick 0
fill ~51 ~10 ~69 ~55 ~10 ~69 red_nether_brick 0
fill ~56 ~10 ~68 ~57 ~10 ~68 red_nether_brick 0
fill ~58 ~10 ~67 ~58 ~12 ~67 red_nether_brick 0
fill ~83 ~10 ~63 ~83 ~14 ~63 red_nether_brick 0
fill ~86 ~10 ~67 ~86 ~12 ~67 red_nether_brick 0
fill ~88 ~10 ~68 ~88 ~11 ~68 red_nether_brick 0
fill ~89 ~10 ~69 ~93 ~10 ~69 red_nether_brick 0
fill ~90 ~10 ~52 ~95 ~10 ~52 red_nether_brick 0
fill ~94 ~10 ~68 ~95 ~10 ~68 red_nether_brick 0
fill ~95 ~10 ~67 ~96 ~10 ~67 red_nether_brick 0
fill ~97 ~10 ~65 ~97 ~11 ~65 red_nether_brick 0
fill ~98 ~10 ~63 ~98 ~14 ~63 red_nether_brick 0
fill ~47 ~11 ~64 ~47 ~14 ~64 red_nether_brick 0
fill ~48 ~11 ~65 ~48 ~13 ~65 red_nether_brick 0
fill ~49 ~11 ~52 ~54 ~11 ~52 red_nether_brick 0
fill ~49 ~11 ~66 ~49 ~12 ~66 red_nether_brick 0
fill ~50 ~11 ~67 ~51 ~11 ~67 red_nether_brick 0
fill ~52 ~11 ~68 ~56 ~11 ~68 red_nether_brick 0
fill ~57 ~11 ~67 ~57 ~14 ~67 red_nether_brick 0
fill ~59 ~11 ~66 ~59 ~14 ~66 red_nether_brick 0
fill ~60 ~11 ~65 ~60 ~14 ~65 red_nether_brick 0
fill ~61 ~11 ~63 ~61 ~14 ~63 red_nether_brick 0
fill ~71 ~11 ~65 ~73 ~11 ~65 concrete 1
fill ~83 ~11 ~58 ~83 ~14 ~58 red_nether_brick 0
fill ~83 ~11 ~62 ~83 ~14 ~62 red_nether_brick 0
fill ~84 ~11 ~65 ~84 ~14 ~65 red_nether_brick 0
fill ~85 ~11 ~66 ~85 ~14 ~66 red_nether_brick 0
fill ~87 ~11 ~67 ~87 ~14 ~67 red_nether_brick 0
fill ~89 ~11 ~68 ~93 ~11 ~68 red_nether_brick 0
fill ~90 ~11 ~52 ~95 ~11 ~52 red_nether_brick 0
fill ~94 ~11 ~67 ~94 ~12 ~67 red_nether_brick 0
fill ~95 ~11 ~66 ~96 ~11 ~66 red_nether_brick 0
fill ~97 ~11 ~54 ~97 ~13 ~54 red_nether_brick 0
fill ~49 ~12 ~53 ~49 ~13 ~53 red_nether_brick 0
fill ~50 ~12 ~52 ~55 ~12 ~52 red_nether_brick 0
fill ~50 ~12 ~66 ~50 ~14 ~66 red_nether_brick 0
fill ~51 ~12 ~67 ~58 ~12 ~67 red_nether_brick 0
setblock ~61 ~12 ~65 red_nether_brick 0
fill ~64 ~12 ~70 ~64 ~13 ~70 concrete 1
fill ~64 ~12 ~71 ~65 ~12 ~71 wool 1
fill ~65 ~12 ~69 ~65 ~12 ~71 wool 1
fill ~70 ~12 ~65 ~71 ~12 ~65 wool 1
fill ~71 ~12 ~66 ~71 ~13 ~66 wool 1
fill ~72 ~12 ~64 ~72 ~14 ~64 concrete 1
setblock ~72 ~12 ~66 concrete 1
fill ~73 ~12 ~65 ~74 ~12 ~65 wool 1
fill ~73 ~12 ~66 ~73 ~13 ~66 wool 1
setblock ~78 ~12 ~68 red_sandstone 0
fill ~79 ~12 ~69 ~80 ~12 ~69 wool 1
fill ~79 ~12 ~70 ~79 ~12 ~69 wool 1
fill ~80 ~12 ~70 ~80 ~13 ~70 concrete 1
fill ~83 ~12 ~60 ~83 ~14 ~60 red_nether_brick 0
fill ~83 ~12 ~61 ~83 ~14 ~61 red_nether_brick 0
setblock ~85 ~12 ~54 red_nether_brick 0
fill ~88 ~12 ~67 ~88 ~14 ~67 red_nether_brick 0
fill ~89 ~12 ~68 ~89 ~11 ~68 red_nether_brick 0
fill ~90 ~12 ~52 ~94 ~12 ~52 red_nether_brick 0
fill ~90 ~12 ~67 ~94 ~12 ~67 red_nether_brick 0
fill ~95 ~12 ~53 ~95 ~13 ~53 red_nether_brick 0
fill ~95 ~12 ~66 ~95 ~11 ~66 red_nether_brick 0
fill ~96 ~12 ~65 ~96 ~13 ~65 red_nether_brick 0
fill ~97 ~12 ~64 ~97 ~14 ~64 red_nether_brick 0
setblock ~100 ~12 ~59 red_nether_brick 0
fill ~46 ~13 ~56 ~46 ~13 ~57 red_nether_brick 0
setblock ~47 ~13 ~55 red_nether_brick 0
fill ~48 ~13 ~54 ~49 ~13 ~54 red_nether_brick 0
fill ~49 ~13 ~65 ~49 ~15 ~65 red_nether_brick 0
fill ~50 ~13 ~53 ~57 ~13 ~53 red_nether_brick 0
fill ~51 ~13 ~66 ~51 ~14 ~66 red_nether_brick 0
fill ~52 ~13 ~67 ~57 ~13 ~67 red_nether_brick 0
fill ~58 ~13 ~66 ~58 ~15 ~66 red_nether_brick 0
fill ~61 ~13 ~60 ~61 ~14 ~60 red_nether_brick 0
fill ~61 ~13 ~61 ~61 ~14 ~61 red_nether_brick 0
fill ~61 ~13 ~62 ~61 ~14 ~62 red_nether_brick 0
setblock ~64 ~13 ~69 concrete 1
setblock ~64 ~13 ~71 red_mushroom_block 0
setblock ~64 ~13 ~72 concrete 1
fill ~65 ~13 ~68 ~65 ~14 ~68 wool 1
setblock ~65 ~13 ~72 wool 1
fill ~66 ~13 ~68 ~66 ~13 ~71 concrete 1
setblock ~67 ~13 ~68 wool 1
setblock ~68 ~13 ~79 red_mushroom_block 0
fill ~70 ~13 ~65 ~70 ~13 ~66 concrete 1
setblock ~71 ~13 ~64 wool 1
setblock ~72 ~13 ~67 red_mushroom_block 0
fill ~73 ~13 ~64 ~73 ~14 ~64 wool 1
fill ~74 ~13 ~65 ~74 ~13 ~66 concrete 1
setblock ~77 ~13 ~68 wool 1
setblock ~78 ~13 ~67 concrete 1
fill ~78 ~13 ~69 ~78 ~13 ~70 concrete 1
fill ~79 ~13 ~68 ~79 ~14 ~68 wool 1
setblock ~79 ~13 ~71 concrete 1
setblock ~80 ~13 ~69 concrete 1
setblock ~80 ~13 ~71 red_mushroom_block 0
fill ~83 ~13 ~59 ~83 ~14 ~59 red_nether_brick 0
fill ~85 ~13 ~55 ~85 ~14 ~55 red_nether_brick 0
fill ~86 ~13 ~66 ~86 ~15 ~66 red_nether_brick 0
fill ~89 ~13 ~67 ~92 ~13 ~67 red_nether_brick 0
fill ~90 ~13 ~53 ~95 ~13 ~53 red_nether_brick 0
fill ~93 ~13 ~66 ~94 ~13 ~66 red_nether_brick 0
fill ~95 ~13 ~54 ~97 ~13 ~54 red_nether_brick 0
fill ~95 ~13 ~65 ~95 ~15 ~65 red_nether_brick 0
setblock ~97 ~13 ~55 red_nether_brick 0
setblock ~98 ~13 ~56 red_nether_brick 0
fill ~99 ~13 ~59 ~99 ~14 ~59 red_nether_brick 0
fill ~46 ~14 ~58 ~50 ~14 ~58 red_nether_brick 0
fill ~46 ~14 ~59 ~46 ~14 ~58 red_nether_brick 0
fill ~46 ~14 ~62 ~46 ~15 ~62 red_nether_brick 0
fill ~47 ~14 ~56 ~54 ~14 ~56 red_nether_brick 0
fill ~47 ~14 ~57 ~52 ~14 ~57 red_nether_brick 0
fill ~48 ~14 ~55 ~57 ~14 ~55 red_nether_brick 0
fill ~48 ~14 ~64 ~48 ~15 ~64 red_nether_brick 0
fill ~50 ~14 ~54 ~58 ~14 ~54 red_nether_brick 0
fill ~52 ~14 ~66 ~52 ~15 ~66 red_nether_brick 0
fill ~53 ~14 ~67 ~57 ~14 ~67 red_nether_brick 0
setblock ~59 ~14 ~55 red_nether_brick 0
setblock ~60 ~14 ~64 red_nether_brick 0
fill ~61 ~14 ~58 ~61 ~14 ~64 red_nether_brick 0
setblock ~64 ~14 ~70 red_sandstone 0
setblock ~64 ~14 ~71 wool 1
setblock ~64 ~14 ~72 red_sandstone 0
setblock ~65 ~14 ~69 wool 1
fill ~65 ~14 ~73 ~66 ~14 ~73 wool 1
fill ~66 ~14 ~67 ~78 ~14 ~67 wool 1
setblock ~66 ~14 ~72 red_sandstone 0
fill ~67 ~14 ~69 ~68 ~14 ~69 wool 1
fill ~67 ~14 ~70 ~67 ~14 ~71 wool 1
fill ~67 ~14 ~76 ~67 ~16 ~76 wool 1
fill ~67 ~14 ~77 ~70 ~14 ~77 wool 1
fill ~67 ~14 ~78 ~67 ~15 ~78 wool 1
fill ~67 ~14 ~79 ~70 ~14 ~79 wool 1
setblock ~68 ~14 ~68 concrete 1
setblock ~68 ~14 ~70 red_sandstone 0
setblock ~68 ~14 ~76 red_sandstone 0
fill ~68 ~14 ~78 ~68 ~15 ~78 concrete 1
setblock ~69 ~14 ~66 wool 1
setblock ~69 ~14 ~78 wool 1
setblock ~69 ~14 ~80 wool 1
fill ~70 ~14 ~65 ~71 ~14 ~65 wool 1
setblock ~70 ~14 ~78 red_sandstone 0
setblock ~72 ~14 ~68 concrete 1
setblock ~74 ~14 ~65 wool 1
setblock ~75 ~14 ~66 wool 1
setblock ~76 ~14 ~68 concrete 1
fill ~76 ~14 ~69 ~77 ~14 ~69 wool 1
setblock ~76 ~14 ~70 red_sandstone 0
setblock ~76 ~14 ~76 red_sandstone 0
fill ~76 ~14 ~77 ~78 ~14 ~77 wool 1
fill ~76 ~14 ~78 ~76 ~15 ~78 concrete 1
setblock ~77 ~14 ~70 wool 1
fill ~77 ~14 ~75 ~77 ~14 ~78 wool 1
setblock ~78 ~14 ~71 wool 1
setblock ~78 ~14 ~72 red_sandstone 0
setblock ~78 ~14 ~76 red_sandstone 0
setblock ~79 ~14 ~69 wool 1
fill ~79 ~14 ~72 ~79 ~16 ~72 wool 1
setblock ~80 ~14 ~70 red_sandstone 0
setblock ~80 ~14 ~71 wool 1
setblock ~84 ~14 ~64 red_nether_brick 0
setblock ~86 ~14 ~55 red_nether_brick 0
fill ~87 ~14 ~54 ~94 ~14 ~54 red_nether_brick 0
fill ~88 ~14 ~55 ~96 ~14 ~55 red_nether_brick 0
fill ~89 ~14 ~67 ~91 ~14 ~67 red_nether_brick 0
fill ~90 ~14 ~56 ~97 ~14 ~56 red_nether_brick 0
fill ~92 ~14 ~57 ~98 ~14 ~57 red_nether_brick 0
fill ~92 ~14 ~66 ~94 ~14 ~66 red_nether_brick 0
fill ~94 ~14 ~58 ~98 ~14 ~58 red_nether_brick 0
fill ~96 ~14 ~64 ~96 ~15 ~64 red_nether_brick 0
setblock ~98 ~14 ~59 red_nether_brick 0
fill ~46 ~15 ~60 ~60 ~15 ~60 red_nether_brick 0
fill ~46 ~15 ~61 ~60 ~15 ~61 red_nether_brick 0
fill ~47 ~15 ~59 ~60 ~15 ~59 red_nether_brick 0
fill ~47 ~15 ~62 ~56 ~15 ~62 red_nether_brick 0
fill ~47 ~15 ~63 ~47 ~15 ~59 red_nether_brick 0
fill ~49 ~15 ~63 ~53 ~15 ~63 red_nether_brick 0
fill ~50 ~15 ~65 ~51 ~15 ~65 red_nether_brick 0
fill ~51 ~15 ~58 ~60 ~15 ~58 red_nether_brick 0
setblock ~51 ~15 ~64 red_nether_brick 0
fill ~53 ~15 ~57 ~60 ~15 ~57 red_nether_brick 0
fill ~53 ~15 ~66 ~58 ~15 ~66 red_nether_brick 0
setblock ~54 ~15 ~67 red_nether_brick 0
fill ~55 ~15 ~56 ~60 ~15 ~56 red_nether_brick 0
setblock ~58 ~15 ~55 red_nether_brick 0
fill ~58 ~15 ~65 ~59 ~15 ~65 red_nether_brick 0
fill ~59 ~15 ~62 ~60 ~15 ~62 red_nether_brick 0
fill ~59 ~15 ~63 ~60 ~15 ~63 red_nether_brick 0
fill ~59 ~15 ~64 ~59 ~15 ~56 red_nether_brick 0
setblock ~65 ~15 ~69 concrete 1
setblock ~65 ~15 ~70 wool 1
setblock ~65 ~15 ~71 concrete 1
fill ~65 ~15 ~72 ~65 ~16 ~72 wool 1
fill ~66 ~15 ~67 ~67 ~15 ~67 concrete 1
fill ~66 ~15 ~68 ~66 ~15 ~67 concrete 1
fill ~66 ~15 ~73 ~78 ~15 ~73 concrete 1
setblock ~67 ~15 ~72 wool 1
setblock ~67 ~15 ~74 wool 1
fill ~67 ~15 ~75 ~71 ~15 ~75 concrete 1
setblock ~67 ~15 ~77 concrete 1
fill ~68 ~15 ~66 ~68 ~16 ~66 concrete 1
fill ~68 ~15 ~71 ~77 ~15 ~71 concrete 1
fill ~68 ~15 ~72 ~68 ~15 ~71 concrete 1
setblock ~68 ~15 ~74 concrete 1
fill ~68 ~15 ~79 ~71 ~15 ~79 concrete 1
fill ~69 ~15 ~65 ~75 ~15 ~65 concrete 1
setblock ~69 ~15 ~68 wool 1
fill ~69 ~15 ~69 ~75 ~15 ~69 concrete 1
setblock ~69 ~15 ~70 wool 1
setblock ~69 ~15 ~72 wool 1
setblock ~69 ~15 ~74 wool 1
setblock ~69 ~15 ~76 wool 1
setblock ~70 ~15 ~68 concrete 1
setblock ~70 ~15 ~70 concrete 1
setblock ~70 ~15 ~72 concrete 1
setblock ~70 ~15 ~74 concrete 1
setblock ~70 ~15 ~76 concrete 1
setblock ~71 ~15 ~68 wool 1
setblock ~71 ~15 ~70 wool 1
setblock ~71 ~15 ~72 wool 1
setblock ~71 ~15 ~74 wool 1
setblock ~71 ~15 ~76 wool 1
fill ~71 ~15 ~77 ~75 ~15 ~77 concrete 1
fill ~71 ~15 ~78 ~71 ~17 ~78 wool 1
setblock ~72 ~15 ~70 concrete 1
setblock ~72 ~15 ~72 concrete 1
fill ~72 ~15 ~78 ~72 ~16 ~78 concrete 1
setblock ~73 ~15 ~68 wool 1
setblock ~73 ~15 ~70 wool 1
setblock ~73 ~15 ~72 wool 1
setblock ~74 ~15 ~68 concrete 1
setblock ~74 ~15 ~70 concrete 1
setblock ~74 ~15 ~72 concrete 1
setblock ~74 ~15 ~74 concrete 1
setblock ~74 ~15 ~76 concrete 1
setblock ~75 ~15 ~68 wool 1
setblock ~75 ~15 ~70 wool 1
setblock ~75 ~15 ~72 wool 1
setblock ~75 ~15 ~74 wool 1
fill ~75 ~15 ~75 ~76 ~15 ~75 concrete 1
setblock ~75 ~15 ~76 wool 1
fill ~76 ~15 ~66 ~76 ~16 ~66 concrete 1
setblock ~76 ~15 ~72 concrete 1
setblock ~76 ~15 ~74 concrete 1
setblock ~77 ~15 ~66 wool 1
setblock ~77 ~15 ~72 wool 1
setblock ~77 ~15 ~74 wool 1
fill ~77 ~15 ~77 ~78 ~15 ~77 concrete 1
fill ~78 ~15 ~67 ~78 ~15 ~68 concrete 1
fill ~78 ~15 ~74 ~78 ~15 ~77 concrete 1
setblock ~79 ~15 ~69 concrete 1
fill ~79 ~15 ~70 ~79 ~16 ~70 wool 1
setblock ~80 ~15 ~71 concrete 1
fill ~84 ~15 ~57 ~91 ~15 ~57 red_nether_brick 0
fill ~84 ~15 ~58 ~93 ~15 ~58 red_nether_brick 0
fill ~84 ~15 ~59 ~97 ~15 ~59 red_nether_brick 0
fill ~84 ~15 ~60 ~98 ~15 ~60 red_nether_brick 0
fill ~84 ~15 ~61 ~98 ~15 ~61 red_nether_brick 0
fill ~84 ~15 ~62 ~85 ~15 ~62 red_nether_brick 0
fill ~84 ~15 ~63 ~85 ~15 ~63 red_nether_brick 0
fill ~85 ~15 ~56 ~89 ~15 ~56 red_nether_brick 0
fill ~85 ~15 ~64 ~85 ~15 ~65 red_nether_brick 0
setblock ~86 ~15 ~65 red_nether_brick 0
setblock ~87 ~15 ~55 red_nether_brick 0
fill ~87 ~15 ~66 ~92 ~15 ~66 red_nether_brick 0
fill ~89 ~15 ~62 ~98 ~15 ~62 red_nether_brick 0
setblock ~90 ~15 ~67 red_nether_brick 0
fill ~91 ~15 ~63 ~97 ~15 ~63 red_nether_brick 0
fill ~93 ~15 ~64 ~93 ~15 ~65 red_nether_brick 0
setblock ~94 ~15 ~65 red_nether_brick 0
setblock ~48 ~16 ~63 red_nether_brick 0
fill ~49 ~16 ~64 ~50 ~16 ~64 red_nether_brick 0
fill ~52 ~16 ~64 ~58 ~16 ~64 red_nether_brick 0
fill ~52 ~16 ~65 ~57 ~16 ~65 red_nether_brick 0
fill ~54 ~16 ~63 ~58 ~16 ~63 red_nether_brick 0
fill ~57 ~16 ~62 ~58 ~16 ~62 red_nether_brick 0
setblock ~65 ~16 ~71 wool 1
setblock ~66 ~16 ~69 wool 1
setblock ~66 ~16 ~70 concrete 1
setblock ~66 ~16 ~73 wool 1
setblock ~66 ~16 ~74 red_sandstone 0
setblock ~67 ~16 ~67 concrete 1
setblock ~67 ~16 ~68 wool 1
fill ~67 ~16 ~75 ~67 ~15 ~75 concrete 1
setblock ~68 ~16 ~67 wool 1
setblock ~68 ~16 ~77 wool 1
setblock ~69 ~16 ~66 wool 1
setblock ~69 ~16 ~78 wool 1
fill ~70 ~16 ~65 ~74 ~16 ~65 wool 1
setblock ~70 ~16 ~78 red_sandstone 0
setblock ~72 ~16 ~74 concrete 1
setblock ~72 ~16 ~75 wool 1
setblock ~72 ~16 ~76 concrete 1
setblock ~73 ~16 ~74 wool 1
setblock ~73 ~16 ~75 concrete 1
fill ~73 ~16 ~76 ~73 ~16 ~77 wool 1
setblock ~74 ~16 ~75 wool 1
fill ~74 ~16 ~77 ~76 ~16 ~77 wool 1
setblock ~75 ~16 ~66 wool 1
setblock ~77 ~16 ~67 concrete 1
setblock ~77 ~16 ~68 wool 1
setblock ~77 ~16 ~76 wool 1
setblock ~78 ~16 ~68 red_sandstone 0
setblock ~78 ~16 ~69 wool 1
setblock ~78 ~16 ~73 wool 1
setblock ~78 ~16 ~74 red_sandstone 0
setblock ~78 ~16 ~75 wool 1
setblock ~79 ~16 ~71 wool 1
fill ~86 ~16 ~62 ~88 ~16 ~62 red_nether_brick 0
fill ~86 ~16 ~63 ~90 ~16 ~63 red_nether_brick 0
fill ~86 ~16 ~64 ~92 ~16 ~64 red_nether_brick 0
fill ~87 ~16 ~65 ~92 ~16 ~65 red_nether_brick 0
fill ~94 ~16 ~64 ~95 ~16 ~64 red_nether_brick 0
fill ~66 ~17 ~71 ~66 ~17 ~73 concrete 1
fill ~67 ~17 ~69 ~68 ~17 ~69 concrete 1
setblock ~67 ~17 ~70 wool 1
setblock ~67 ~17 ~71 red_sandstone 0
setblock ~67 ~17 ~72 wool 1
setblock ~67 ~17 ~73 concrete 1
setblock ~67 ~17 ~74 wool 1
setblock ~67 ~17 ~75 red_sandstone 0
setblock ~68 ~17 ~68 concrete 1
setblock ~68 ~17 ~75 red_mushroom_block 0
setblock ~68 ~17 ~76 concrete 1
fill ~69 ~17 ~67 ~70 ~17 ~67 concrete 1
fill ~69 ~17 ~68 ~69 ~18 ~68 wool 1
setblock ~69 ~17 ~76 wool 1
fill ~69 ~17 ~77 ~75 ~17 ~77 concrete 1
setblock ~70 ~17 ~66 concrete 1
fill ~71 ~17 ~66 ~71 ~18 ~66 wool 1
setblock ~71 ~17 ~67 red_sandstone 0
setblock ~72 ~17 ~66 concrete 1
fill ~73 ~17 ~66 ~73 ~18 ~66 wool 1
setblock ~73 ~17 ~67 red_sandstone 0
fill ~74 ~17 ~66 ~74 ~17 ~67 concrete 1
setblock ~75 ~17 ~67 concrete 1
setblock ~75 ~17 ~76 wool 1
setblock ~76 ~17 ~67 red_mushroom_block 0
fill ~76 ~17 ~68 ~76 ~17 ~69 concrete 1
setblock ~76 ~17 ~75 red_mushroom_block 0
setblock ~76 ~17 ~76 concrete 1
setblock ~77 ~17 ~69 concrete 1
setblock ~77 ~17 ~70 wool 1
setblock ~77 ~17 ~71 red_sandstone 0
setblock ~77 ~17 ~72 wool 1
fill ~77 ~17 ~73 ~78 ~17 ~73 concrete 1
setblock ~77 ~17 ~74 wool 1
setblock ~77 ~17 ~75 red_sandstone 0
fill ~78 ~17 ~70 ~78 ~17 ~73 concrete 1
fill ~68 ~18 ~69 ~69 ~18 ~69 wool 1
setblock ~68 ~18 ~70 red_sandstone 0
setblock ~68 ~18 ~71 wool 1
setblock ~68 ~18 ~72 red_sandstone 0
fill ~68 ~18 ~73 ~69 ~18 ~73 wool 1
fill ~68 ~18 ~74 ~68 ~19 ~74 concrete 1
fill ~69 ~18 ~67 ~75 ~18 ~67 wool 1
setblock ~69 ~18 ~70 wool 1
fill ~69 ~18 ~74 ~69 ~19 ~74 wool 1
fill ~69 ~18 ~75 ~75 ~18 ~75 wool 1
setblock ~70 ~18 ~68 red_sandstone 0
setblock ~70 ~18 ~74 red_sandstone 0
setblock ~70 ~18 ~76 red_sandstone 0
fill ~71 ~18 ~76 ~71 ~19 ~76 wool 1
setblock ~72 ~18 ~66 red_sandstone 0
setblock ~72 ~18 ~76 red_sandstone 0
fill ~73 ~18 ~76 ~73 ~19 ~76 wool 1
setblock ~74 ~18 ~68 red_sandstone 0
setblock ~74 ~18 ~74 red_sandstone 0
setblock ~74 ~18 ~76 red_sandstone 0
fill ~75 ~18 ~68 ~75 ~18 ~69 wool 1
fill ~75 ~18 ~73 ~76 ~18 ~73 wool 1
fill ~75 ~18 ~74 ~75 ~19 ~74 wool 1
setblock ~76 ~18 ~69 wool 1
setblock ~76 ~18 ~70 red_sandstone 0
setblock ~76 ~18 ~71 wool 1
setblock ~76 ~18 ~72 red_sandstone 0
fill ~76 ~18 ~74 ~76 ~19 ~74 concrete 1
fill ~66 ~19 ~69 ~67 ~19 ~69 concrete 1
fill ~66 ~19 ~70 ~66 ~19 ~72 concrete 1
fill ~67 ~19 ~67 ~68 ~19 ~67 concrete 1
setblock ~67 ~19 ~68 wool 1
setblock ~67 ~19 ~70 wool 1
setblock ~67 ~19 ~71 concrete 1
setblock ~67 ~19 ~72 wool 1
fill ~67 ~19 ~73 ~68 ~19 ~73 concrete 1
setblock ~67 ~19 ~74 wool 1
setblock ~68 ~19 ~66 concrete 1
setblock ~68 ~19 ~68 concrete 1
setblock ~68 ~19 ~72 concrete 1
fill ~68 ~19 ~75 ~76 ~19 ~75 concrete 1
fill ~69 ~19 ~65 ~75 ~19 ~65 concrete 1
setblock ~69 ~19 ~66 wool 1
setblock ~69 ~19 ~76 wool 1
setblock ~70 ~19 ~66 concrete 1
setblock ~70 ~19 ~76 concrete 1
setblock ~72 ~19 ~76 concrete 1
setblock ~74 ~19 ~66 concrete 1
setblock ~74 ~19 ~76 concrete 1
setblock ~75 ~19 ~66 wool 1
setblock ~75 ~19 ~76 wool 1
fill ~76 ~19 ~66 ~76 ~19 ~68 concrete 1
fill ~76 ~19 ~73 ~78 ~19 ~73 concrete 1
setblock ~77 ~19 ~67 concrete 1
setblock ~77 ~19 ~68 wool 1
fill ~77 ~19 ~69 ~78 ~19 ~69 concrete 1
setblock ~77 ~19 ~70 wool 1
fill ~77 ~19 ~71 ~78 ~19 ~71 concrete 1
setblock ~77 ~19 ~72 wool 1
setblock ~77 ~19 ~74 wool 1
setblock ~78 ~19 ~70 concrete 1
setblock ~78 ~19 ~72 concrete 1
fill ~65 ~20 ~68 ~65 ~20 ~74 wool 1
setblock ~66 ~20 ~66 concrete 1
setblock ~66 ~20 ~67 wool 1
setblock ~66 ~20 ~68 red_sandstone 0
setblock ~66 ~20 ~73 wool 1
setblock ~66 ~20 ~74 red_sandstone 0
setblock ~66 ~20 ~75 wool 1
fill ~67 ~20 ~65 ~68 ~20 ~65 wool 1
fill ~67 ~20 ~66 ~67 ~20 ~65 wool 1
setblock ~67 ~20 ~75 concrete 1
setblock ~67 ~20 ~76 wool 1
setblock ~68 ~20 ~64 concrete 1
setblock ~68 ~20 ~76 concrete 1
fill ~68 ~20 ~77 ~76 ~20 ~77 wool 1
setblock ~69 ~20 ~64 wool 1
setblock ~70 ~20 ~63 wool 1
setblock ~70 ~20 ~64 red_sandstone 0
setblock ~70 ~20 ~78 red_sandstone 0
setblock ~71 ~20 ~63 concrete 1
setblock ~71 ~20 ~64 wool 1
setblock ~71 ~20 ~78 wool 1
setblock ~72 ~20 ~63 wool 1
setblock ~72 ~20 ~64 concrete 1
setblock ~72 ~20 ~78 concrete 1
setblock ~73 ~20 ~63 concrete 1
setblock ~73 ~20 ~64 wool 1
setblock ~73 ~20 ~78 wool 1
setblock ~74 ~20 ~63 wool 1
setblock ~74 ~20 ~64 red_sandstone 0
setblock ~74 ~20 ~78 red_sandstone 0
setblock ~75 ~20 ~64 wool 1
setblock ~76 ~20 ~64 concrete 1
fill ~76 ~20 ~65 ~77 ~20 ~65 wool 1
setblock ~76 ~20 ~76 concrete 1
setblock ~77 ~20 ~66 wool 1
setblock ~77 ~20 ~75 concrete 1
setblock ~77 ~20 ~76 wool 1
setblock ~78 ~20 ~66 concrete 1
fill ~78 ~20 ~67 ~79 ~20 ~67 wool 1
setblock ~78 ~20 ~68 red_sandstone 0
setblock ~78 ~20 ~74 red_sandstone 0
setblock ~78 ~20 ~75 wool 1
fill ~79 ~20 ~68 ~79 ~20 ~74 wool 1
setblock ~80 ~20 ~70 concrete 1
setblock ~80 ~20 ~71 wool 1
fill ~63 ~21 ~69 ~64 ~21 ~69 concrete 1
setblock ~63 ~21 ~70 wool 1
setblock ~63 ~21 ~71 red_sandstone 0
setblock ~63 ~21 ~72 wool 1
fill ~63 ~21 ~73 ~64 ~21 ~73 concrete 1
setblock ~64 ~21 ~67 red_mushroom_block 0
setblock ~64 ~21 ~68 concrete 1
setblock ~64 ~21 ~70 concrete 1
setblock ~64 ~21 ~71 red_mushroom_block 0
setblock ~64 ~21 ~72 concrete 1
setblock ~64 ~21 ~74 concrete 1
setblock ~64 ~21 ~75 red_mushroom_block 0
fill ~65 ~21 ~65 ~66 ~21 ~65 concrete 1
setblock ~65 ~21 ~66 wool 1
setblock ~65 ~21 ~67 concrete 1
setblock ~65 ~21 ~75 concrete 1
setblock ~65 ~21 ~76 wool 1
setblock ~66 ~21 ~64 concrete 1
fill ~66 ~21 ~76 ~66 ~21 ~77 concrete 1
setblock ~67 ~21 ~63 red_sandstone 0
setblock ~67 ~21 ~64 wool 1
setblock ~67 ~21 ~77 concrete 1
fill ~67 ~21 ~78 ~67 ~22 ~78 wool 1
setblock ~68 ~21 ~63 red_mushroom_block 0
setblock ~68 ~21 ~78 concrete 1
setblock ~69 ~21 ~62 wool 1
setblock ~69 ~21 ~63 concrete 1
setblock ~69 ~21 ~78 wool 1
fill ~69 ~21 ~79 ~70 ~21 ~79 concrete 1
setblock ~70 ~21 ~62 concrete 1
setblock ~71 ~21 ~62 wool 1
setblock ~71 ~21 ~79 red_sandstone 0
setblock ~72 ~21 ~62 concrete 1
setblock ~72 ~21 ~79 red_mushroom_block 0
setblock ~73 ~21 ~62 wool 1
setblock ~73 ~21 ~79 red_sandstone 0
setblock ~74 ~21 ~62 concrete 1
fill ~74 ~21 ~79 ~75 ~21 ~79 concrete 1
setblock ~75 ~21 ~62 wool 1
setblock ~75 ~21 ~63 concrete 1
setblock ~75 ~21 ~78 wool 1
setblock ~76 ~21 ~63 red_mushroom_block 0
setblock ~76 ~21 ~78 concrete 1
setblock ~77 ~21 ~63 red_sandstone 0
setblock ~77 ~21 ~64 wool 1
fill ~77 ~21 ~77 ~78 ~21 ~77 concrete 1
fill ~77 ~21 ~78 ~77 ~22 ~78 wool 1
fill ~78 ~21 ~64 ~78 ~21 ~65 concrete 1
setblock ~78 ~21 ~76 concrete 1
setblock ~79 ~21 ~65 concrete 1
setblock ~79 ~21 ~66 wool 1
setblock ~79 ~21 ~75 concrete 1
setblock ~79 ~21 ~76 wool 1
setblock ~80 ~21 ~66 concrete 1
setblock ~80 ~21 ~67 red_mushroom_block 0
fill ~80 ~21 ~68 ~80 ~21 ~69 concrete 1
fill ~80 ~21 ~72 ~80 ~21 ~74 concrete 1
setblock ~80 ~21 ~75 red_mushroom_block 0
setblock ~81 ~21 ~68 wool 1
setblock ~81 ~21 ~69 concrete 1
setblock ~81 ~21 ~70 wool 1
setblock ~81 ~21 ~71 red_sandstone 0
setblock ~81 ~21 ~72 wool 1
setblock ~81 ~21 ~73 concrete 1
setblock ~62 ~22 ~68 red_sandstone 0
setblock ~62 ~22 ~69 wool 1
setblock ~62 ~22 ~70 red_sandstone 0
setblock ~62 ~22 ~71 wool 1
setblock ~62 ~22 ~72 red_sandstone 0
fill ~63 ~22 ~66 ~63 ~22 ~68 wool 1
fill ~63 ~22 ~73 ~63 ~22 ~74 wool 1
setblock ~64 ~22 ~64 concrete 1
setblock ~64 ~22 ~65 wool 1
setblock ~64 ~22 ~66 red_sandstone 0
setblock ~64 ~22 ~75 wool 1
setblock ~64 ~22 ~76 red_sandstone 0
fill ~65 ~22 ~63 ~66 ~22 ~63 wool 1
fill ~65 ~22 ~64 ~65 ~22 ~63 wool 1
setblock ~65 ~22 ~77 wool 1
setblock ~66 ~22 ~78 red_sandstone 0
setblock ~67 ~22 ~62 wool 1
fill ~68 ~22 ~61 ~76 ~22 ~61 wool 1
setblock ~68 ~22 ~62 red_sandstone 0
fill ~68 ~22 ~79 ~69 ~22 ~79 wool 1
setblock ~70 ~22 ~80 red_sandstone 0
fill ~71 ~22 ~80 ~71 ~23 ~80 wool 1
setblock ~72 ~22 ~80 red_sandstone 0
fill ~73 ~22 ~80 ~73 ~23 ~80 wool 1
setblock ~74 ~22 ~80 red_sandstone 0
fill ~75 ~22 ~79 ~76 ~22 ~79 wool 1
setblock ~76 ~22 ~62 red_sandstone 0
setblock ~77 ~22 ~62 wool 1
setblock ~78 ~22 ~62 red_sandstone 0
fill ~78 ~22 ~63 ~79 ~22 ~63 wool 1
setblock ~78 ~22 ~78 red_sandstone 0
setblock ~79 ~22 ~64 wool 1
setblock ~79 ~22 ~77 wool 1
setblock ~80 ~22 ~64 concrete 1
fill ~80 ~22 ~65 ~81 ~22 ~65 wool 1
setblock ~80 ~22 ~76 red_sandstone 0
fill ~81 ~22 ~66 ~81 ~22 ~67 wool 1
fill ~81 ~22 ~74 ~81 ~22 ~75 wool 1
setblock ~82 ~22 ~67 wool 1
setblock ~82 ~22 ~68 red_sandstone 0
setblock ~82 ~22 ~69 wool 1
setblock ~82 ~22 ~70 red_sandstone 0
setblock ~82 ~22 ~71 wool 1
setblock ~82 ~22 ~72 red_sandstone 0
setblock ~82 ~22 ~73 wool 1
setblock ~61 ~23 ~69 concrete 1
fill ~61 ~23 ~70 ~61 ~24 ~70 wool 1
setblock ~61 ~23 ~71 concrete 1
fill ~62 ~23 ~66 ~62 ~23 ~68 concrete 1
fill ~62 ~23 ~72 ~62 ~23 ~74 concrete 1
setblock ~63 ~23 ~64 wool 1
setblock ~63 ~23 ~65 concrete 1
setblock ~63 ~23 ~75 concrete 1
fill ~63 ~23 ~76 ~63 ~24 ~76 wool 1
setblock ~64 ~23 ~63 concrete 1
setblock ~64 ~23 ~77 concrete 1
setblock ~65 ~23 ~62 wool 1
setblock ~65 ~23 ~78 wool 1
fill ~66 ~23 ~61 ~67 ~23 ~61 concrete 1
fill ~66 ~23 ~62 ~66 ~23 ~61 concrete 1
fill ~66 ~23 ~79 ~67 ~23 ~79 concrete 1
setblock ~68 ~23 ~60 concrete 1
fill ~68 ~23 ~80 ~68 ~24 ~80 concrete 1
setblock ~69 ~23 ~60 wool 1
setblock ~69 ~23 ~80 wool 1
setblock ~70 ~23 ~60 concrete 1
setblock ~70 ~23 ~80 concrete 1
setblock ~71 ~23 ~60 wool 1
fill ~72 ~23 ~59 ~73 ~23 ~59 concrete 1
fill ~72 ~23 ~60 ~72 ~23 ~59 concrete 1
setblock ~72 ~23 ~80 concrete 1
setblock ~73 ~23 ~60 wool 1
setblock ~74 ~23 ~60 concrete 1
setblock ~74 ~23 ~80 concrete 1
setblock ~75 ~23 ~60 wool 1
setblock ~75 ~23 ~80 wool 1
setblock ~76 ~23 ~60 concrete 1
fill ~76 ~23 ~80 ~76 ~24 ~80 concrete 1
fill ~77 ~23 ~61 ~78 ~23 ~61 concrete 1
fill ~77 ~23 ~79 ~78 ~23 ~79 concrete 1
setblock ~79 ~23 ~62 wool 1
setblock ~79 ~23 ~78 wool 1
setblock ~80 ~23 ~63 concrete 1
setblock ~80 ~23 ~77 concrete 1
setblock ~81 ~23 ~64 wool 1
setblock ~81 ~23 ~75 concrete 1
setblock ~81 ~23 ~76 wool 1
fill ~82 ~23 ~65 ~82 ~23 ~67 concrete 1
fill ~82 ~23 ~73 ~82 ~23 ~74 concrete 1
fill ~83 ~23 ~68 ~83 ~24 ~68 wool 1
setblock ~83 ~23 ~69 concrete 1
fill ~83 ~23 ~70 ~83 ~24 ~70 wool 1
setblock ~83 ~23 ~71 concrete 1
fill ~83 ~23 ~72 ~83 ~24 ~72 wool 1
fill ~61 ~24 ~66 ~61 ~25 ~66 wool 1
fill ~61 ~24 ~67 ~61 ~24 ~73 wool 1
setblock ~62 ~24 ~64 red_sandstone 0
setblock ~62 ~24 ~65 wool 1
setblock ~62 ~24 ~74 red_sandstone 0
setblock ~62 ~24 ~75 wool 1
setblock ~63 ~24 ~63 concrete 1
setblock ~63 ~24 ~77 wool 1
setblock ~64 ~24 ~62 concrete 1
setblock ~64 ~24 ~78 concrete 1
setblock ~65 ~24 ~61 wool 1
fill ~65 ~24 ~79 ~66 ~24 ~79 wool 1
setblock ~66 ~24 ~60 red_sandstone 0
setblock ~67 ~24 ~60 wool 1
fill ~67 ~24 ~80 ~67 ~25 ~80 wool 1
fill ~68 ~24 ~59 ~70 ~24 ~59 wool 1
fill ~69 ~24 ~81 ~75 ~24 ~81 wool 1
setblock ~71 ~24 ~59 concrete 1
setblock ~72 ~24 ~59 wool 1
setblock ~73 ~24 ~59 concrete 1
fill ~74 ~24 ~59 ~76 ~24 ~59 wool 1
setblock ~77 ~24 ~60 wool 1
fill ~77 ~24 ~80 ~77 ~25 ~80 wool 1
setblock ~78 ~24 ~60 red_sandstone 0
fill ~78 ~24 ~79 ~79 ~24 ~79 wool 1
setblock ~79 ~24 ~61 wool 1
setblock ~80 ~24 ~62 concrete 1
setblock ~80 ~24 ~78 concrete 1
setblock ~81 ~24 ~63 concrete 1
setblock ~81 ~24 ~77 wool 1
setblock ~82 ~24 ~64 red_sandstone 0
setblock ~82 ~24 ~65 wool 1
setblock ~82 ~24 ~75 wool 1
fill ~82 ~24 ~76 ~82 ~25 ~76 concrete 1
fill ~83 ~24 ~66 ~83 ~25 ~66 wool 1
fill ~83 ~24 ~67 ~83 ~24 ~66 wool 1
setblock ~83 ~24 ~69 wool 1
setblock ~83 ~24 ~71 wool 1
fill ~83 ~24 ~73 ~83 ~24 ~74 wool 1
setblock ~60 ~25 ~67 red_mushroom_block 0
fill ~60 ~25 ~68 ~60 ~26 ~68 concrete 1
fill ~60 ~25 ~69 ~60 ~25 ~70 concrete 1
setblock ~60 ~25 ~71 red_mushroom_block 0
setblock ~60 ~25 ~72 concrete 1
setblock ~61 ~25 ~65 concrete 1
setblock ~61 ~25 ~73 concrete 1
setblock ~61 ~25 ~74 wool 1
setblock ~61 ~25 ~75 concrete 1
fill ~62 ~25 ~63 ~62 ~25 ~64 concrete 1
setblock ~62 ~25 ~76 concrete 1
setblock ~63 ~25 ~62 wool 1
setblock ~63 ~25 ~77 concrete 1
fill ~63 ~25 ~78 ~63 ~28 ~78 wool 1
setblock ~64 ~25 ~61 concrete 1
setblock ~64 ~25 ~79 red_mushroom_block 0
fill ~65 ~25 ~60 ~65 ~26 ~60 wool 1
setblock ~65 ~25 ~79 concrete 1
setblock ~66 ~25 ~60 concrete 1
setblock ~66 ~25 ~80 concrete 1
setblock ~67 ~25 ~59 red_sandstone 0
setblock ~68 ~25 ~59 red_mushroom_block 0
fill ~68 ~25 ~81 ~76 ~25 ~81 concrete 1
fill ~69 ~25 ~58 ~69 ~26 ~58 wool 1
setblock ~70 ~25 ~58 concrete 1
setblock ~71 ~25 ~58 wool 1
setblock ~72 ~25 ~58 concrete 1
setblock ~73 ~25 ~58 wool 1
setblock ~74 ~25 ~58 concrete 1
fill ~75 ~25 ~58 ~75 ~26 ~58 wool 1
setblock ~76 ~25 ~59 red_mushroom_block 0
setblock ~77 ~25 ~59 red_sandstone 0
setblock ~78 ~25 ~59 concrete 1
setblock ~78 ~25 ~80 concrete 1
setblock ~79 ~25 ~60 wool 1
setblock ~79 ~25 ~79 concrete 1
setblock ~80 ~25 ~61 concrete 1
setblock ~80 ~25 ~79 red_mushroom_block 0
setblock ~81 ~25 ~62 wool 1
fill ~81 ~25 ~78 ~81 ~27 ~78 wool 1
setblock ~82 ~25 ~63 concrete 1
setblock ~82 ~25 ~77 concrete 1
fill ~83 ~25 ~64 ~83 ~26 ~64 wool 1
setblock ~83 ~25 ~65 concrete 1
setblock ~83 ~25 ~74 wool 1
setblock ~83 ~25 ~75 concrete 1
setblock ~84 ~25 ~67 red_mushroom_block 0
fill ~84 ~25 ~68 ~84 ~25 ~70 concrete 1
setblock ~84 ~25 ~71 red_mushroom_block 0
fill ~84 ~25 ~72 ~84 ~25 ~73 concrete 1
fill ~59 ~26 ~69 ~59 ~26 ~70 wool 1
setblock ~60 ~26 ~65 wool 1
setblock ~60 ~26 ~66 red_sandstone 0
setblock ~60 ~26 ~67 wool 1
setblock ~60 ~26 ~71 wool 1
setblock ~60 ~26 ~72 red_sandstone 0
setblock ~60 ~26 ~73 wool 1
fill ~60 ~26 ~74 ~60 ~29 ~74 concrete 1
setblock ~61 ~26 ~64 wool 1
fill ~61 ~26 ~75 ~61 ~26 ~76 wool 1
setblock ~62 ~26 ~62 red_sandstone 0
setblock ~62 ~26 ~63 wool 1
setblock ~62 ~26 ~77 wool 1
setblock ~63 ~26 ~61 wool 1
fill ~64 ~26 ~60 ~64 ~27 ~60 concrete 1
setblock ~64 ~26 ~79 wool 1
fill ~65 ~26 ~80 ~65 ~30 ~80 wool 1
setblock ~66 ~26 ~59 wool 1
setblock ~66 ~26 ~80 red_sandstone 0
fill ~67 ~26 ~58 ~67 ~27 ~58 wool 1
fill ~67 ~26 ~81 ~69 ~26 ~81 wool 1
setblock ~68 ~26 ~58 red_sandstone 0
setblock ~70 ~26 ~58 red_sandstone 0
setblock ~70 ~26 ~82 red_sandstone 0
fill ~71 ~26 ~57 ~74 ~26 ~57 wool 1
fill ~71 ~26 ~82 ~71 ~31 ~82 wool 1
fill ~72 ~26 ~82 ~72 ~30 ~82 concrete 1
fill ~73 ~26 ~82 ~73 ~31 ~82 wool 1
fill ~74 ~26 ~81 ~77 ~26 ~81 wool 1
setblock ~76 ~26 ~58 red_sandstone 0
fill ~77 ~26 ~58 ~77 ~27 ~58 wool 1
fill ~78 ~26 ~59 ~79 ~26 ~59 wool 1
setblock ~78 ~26 ~80 red_sandstone 0
fill ~79 ~26 ~80 ~79 ~30 ~80 wool 1
setblock ~80 ~26 ~60 concrete 1
setblock ~80 ~26 ~79 wool 1
setblock ~81 ~26 ~61 wool 1
setblock ~82 ~26 ~62 red_sandstone 0
setblock ~82 ~26 ~77 wool 1
setblock ~83 ~26 ~63 wool 1
fill ~83 ~26 ~75 ~83 ~26 ~76 wool 1
setblock ~84 ~26 ~65 wool 1
setblock ~84 ~26 ~66 red_sandstone 0
setblock ~84 ~26 ~67 wool 1
setblock ~84 ~26 ~72 red_sandstone 0
setblock ~84 ~26 ~73 wool 1
fill ~84 ~26 ~74 ~84 ~29 ~74 concrete 1
fill ~85 ~26 ~68 ~85 ~29 ~68 wool 1
fill ~85 ~26 ~69 ~85 ~26 ~71 wool 1
fill ~59 ~27 ~67 ~59 ~28 ~67 concrete 1
fill ~59 ~27 ~68 ~59 ~29 ~68 wool 1
setblock ~59 ~27 ~69 concrete 1
fill ~59 ~27 ~70 ~59 ~29 ~70 wool 1
fill ~59 ~27 ~71 ~59 ~28 ~71 concrete 1
fill ~59 ~27 ~72 ~59 ~31 ~72 wool 1
fill ~60 ~27 ~64 ~60 ~29 ~64 concrete 1
fill ~60 ~27 ~65 ~60 ~27 ~66 concrete 1
setblock ~60 ~27 ~73 concrete 1
fill ~61 ~27 ~62 ~61 ~29 ~62 wool 1
setblock ~61 ~27 ~63 concrete 1
setblock ~61 ~27 ~75 concrete 1
fill ~61 ~27 ~76 ~61 ~29 ~76 wool 1
setblock ~62 ~27 ~61 concrete 1
setblock ~62 ~27 ~77 concrete 1
fill ~63 ~27 ~60 ~63 ~28 ~60 wool 1
setblock ~64 ~27 ~79 concrete 1
setblock ~65 ~27 ~59 concrete 1
fill ~66 ~27 ~58 ~66 ~28 ~58 concrete 1
setblock ~66 ~27 ~80 concrete 1
fill ~67 ~27 ~81 ~69 ~27 ~81 concrete 1
fill ~68 ~27 ~57 ~76 ~27 ~57 concrete 1
setblock ~70 ~27 ~82 concrete 1
setblock ~74 ~27 ~82 concrete 1
fill ~75 ~27 ~82 ~75 ~32 ~82 wool 1
fill ~76 ~27 ~81 ~77 ~27 ~81 concrete 1
setblock ~78 ~27 ~58 concrete 1
setblock ~78 ~27 ~80 concrete 1
fill ~79 ~27 ~59 ~80 ~27 ~59 concrete 1
setblock ~80 ~27 ~79 concrete 1
setblock ~81 ~27 ~60 wool 1
setblock ~82 ~27 ~61 concrete 1
setblock ~82 ~27 ~77 concrete 1
fill ~83 ~27 ~62 ~83 ~29 ~62 wool 1
setblock ~83 ~27 ~63 concrete 1
fill ~83 ~27 ~76 ~83 ~29 ~76 wool 1
fill ~84 ~27 ~64 ~84 ~29 ~64 concrete 1
fill ~84 ~27 ~65 ~84 ~27 ~64 concrete 1
setblock ~84 ~27 ~73 concrete 1
setblock ~84 ~27 ~75 concrete 1
fill ~85 ~27 ~66 ~85 ~30 ~66 wool 1
fill ~85 ~27 ~67 ~85 ~28 ~67 concrete 1
setblock ~85 ~27 ~69 concrete 1
fill ~85 ~27 ~70 ~85 ~29 ~70 wool 1
fill ~85 ~27 ~71 ~85 ~28 ~71 concrete 1
fill ~85 ~27 ~72 ~85 ~30 ~72 wool 1
fill ~59 ~28 ~66 ~59 ~30 ~66 wool 1
setblock ~59 ~28 ~69 wool 1
setblock ~60 ~28 ~63 wool 1
setblock ~60 ~28 ~65 wool 1
setblock ~60 ~28 ~73 wool 1
setblock ~60 ~28 ~75 wool 1
setblock ~62 ~28 ~61 wool 1
setblock ~62 ~28 ~77 wool 1
setblock ~64 ~28 ~59 wool 1
setblock ~64 ~28 ~79 wool 1
fill ~65 ~28 ~58 ~65 ~29 ~58 wool 1
fill ~66 ~28 ~81 ~68 ~28 ~81 wool 1
fill ~67 ~28 ~57 ~68 ~28 ~57 wool 1
fill ~69 ~28 ~56 ~69 ~31 ~56 wool 1
fill ~69 ~28 ~82 ~69 ~32 ~82 wool 1
setblock ~70 ~28 ~56 red_sandstone 0
setblock ~70 ~28 ~82 red_sandstone 0
fill ~71 ~28 ~56 ~71 ~30 ~56 wool 1
fill ~72 ~28 ~56 ~72 ~30 ~56 concrete 1
fill ~73 ~28 ~56 ~73 ~30 ~56 wool 1
setblock ~74 ~28 ~56 red_sandstone 0
setblock ~74 ~28 ~82 red_sandstone 0
fill ~75 ~28 ~56 ~75 ~31 ~56 wool 1
fill ~76 ~28 ~57 ~78 ~28 ~57 wool 1
fill ~76 ~28 ~81 ~78 ~28 ~81 wool 1
fill ~79 ~28 ~58 ~79 ~29 ~58 wool 1
setblock ~80 ~28 ~59 wool 1
setblock ~80 ~28 ~79 wool 1
setblock ~81 ~28 ~59 concrete 1
setblock ~81 ~28 ~79 concrete 1
setblock ~82 ~28 ~60 red_sandstone 0
setblock ~82 ~28 ~61 wool 1
setblock ~82 ~28 ~77 wool 1
setblock ~82 ~28 ~78 red_sandstone 0
setblock ~84 ~28 ~63 wool 1
setblock ~84 ~28 ~75 wool 1
setblock ~85 ~28 ~65 wool 1
setblock ~85 ~28 ~69 wool 1
setblock ~85 ~28 ~73 wool 1
setblock ~59 ~29 ~65 concrete 1
setblock ~59 ~29 ~67 red_sandstone 0
setblock ~59 ~29 ~69 concrete 1
setblock ~59 ~29 ~71 red_sandstone 0
setblock ~59 ~29 ~73 concrete 1
setblock ~60 ~29 ~63 red_mushroom_block 0
setblock ~60 ~29 ~75 red_mushroom_block 0
setblock ~61 ~29 ~61 concrete 1
setblock ~61 ~29 ~77 concrete 1
setblock ~62 ~29 ~60 concrete 1
setblock ~62 ~29 ~78 concrete 1
setblock ~63 ~29 ~59 red_sandstone 0
setblock ~63 ~29 ~79 red_sandstone 0
setblock ~64 ~29 ~58 concrete 1
setblock ~64 ~29 ~80 concrete 1
fill ~66 ~29 ~57 ~67 ~29 ~57 concrete 1
fill ~66 ~29 ~81 ~67 ~29 ~81 concrete 1
fill ~68 ~29 ~56 ~68 ~32 ~56 concrete 1
fill ~68 ~29 ~82 ~68 ~62 ~82 concrete 1
setblock ~70 ~29 ~56 concrete 1
setblock ~70 ~29 ~82 concrete 1
setblock ~74 ~29 ~56 concrete 1
setblock ~74 ~29 ~82 concrete 1
fill ~76 ~29 ~56 ~76 ~32 ~56 concrete 1
fill ~76 ~29 ~82 ~76 ~61 ~82 concrete 1
fill ~77 ~29 ~57 ~78 ~29 ~57 concrete 1
fill ~77 ~29 ~81 ~78 ~29 ~81 concrete 1
setblock ~80 ~29 ~58 concrete 1
setblock ~80 ~29 ~80 concrete 1
setblock ~81 ~29 ~59 red_sandstone 0
setblock ~81 ~29 ~79 red_sandstone 0
setblock ~82 ~29 ~60 concrete 1
setblock ~82 ~29 ~78 concrete 1
setblock ~83 ~29 ~61 concrete 1
setblock ~83 ~29 ~77 concrete 1
setblock ~84 ~29 ~63 red_mushroom_block 0
setblock ~84 ~29 ~75 red_mushroom_block 0
setblock ~85 ~29 ~65 concrete 1
setblock ~85 ~29 ~67 red_sandstone 0
setblock ~85 ~29 ~69 concrete 1
setblock ~85 ~29 ~71 red_sandstone 0
setblock ~85 ~29 ~73 concrete 1
setblock ~58 ~30 ~68 red_sandstone 0
setblock ~58 ~30 ~69 wool 1
setblock ~58 ~30 ~70 red_sandstone 0
fill ~59 ~30 ~64 ~59 ~33 ~64 wool 1
fill ~59 ~30 ~65 ~59 ~30 ~64 wool 1
setblock ~59 ~30 ~67 wool 1
setblock ~59 ~30 ~71 wool 1
fill ~59 ~30 ~73 ~59 ~30 ~74 wool 1
setblock ~60 ~30 ~62 red_sandstone 0
setblock ~60 ~30 ~63 wool 1
setblock ~60 ~30 ~75 wool 1
setblock ~60 ~30 ~76 red_sandstone 0
setblock ~61 ~30 ~61 wool 1
setblock ~61 ~30 ~77 wool 1
setblock ~62 ~30 ~60 red_sandstone 0
setblock ~62 ~30 ~78 red_sandstone 0
setblock ~63 ~30 ~59 wool 1
setblock ~63 ~30 ~79 wool 1
setblock ~64 ~30 ~58 red_sandstone 0
setblock ~64 ~30 ~80 red_sandstone 0
fill ~65 ~30 ~57 ~66 ~30 ~57 wool 1
fill ~66 ~30 ~81 ~67 ~30 ~81 wool 1
fill ~67 ~30 ~56 ~67 ~33 ~56 wool 1
setblock ~70 ~30 ~56 red_sandstone 0
setblock ~70 ~30 ~82 red_sandstone 0
setblock ~74 ~30 ~56 red_sandstone 0
setblock ~74 ~30 ~82 red_sandstone 0
fill ~77 ~30 ~56 ~77 ~32 ~56 wool 1
fill ~77 ~30 ~81 ~78 ~30 ~81 wool 1
fill ~78 ~30 ~57 ~79 ~30 ~57 wool 1
setblock ~80 ~30 ~58 red_sandstone 0
setblock ~80 ~30 ~80 red_sandstone 0
setblock ~81 ~30 ~59 wool 1
setblock ~81 ~30 ~79 wool 1
setblock ~82 ~30 ~60 red_sandstone 0
setblock ~82 ~30 ~78 red_sandstone 0
setblock ~83 ~30 ~61 wool 1
setblock ~83 ~30 ~77 wool 1
setblock ~84 ~30 ~62 red_sandstone 0
setblock ~84 ~30 ~63 wool 1
setblock ~84 ~30 ~75 wool 1
setblock ~84 ~30 ~76 red_sandstone 0
fill ~85 ~30 ~64 ~85 ~32 ~64 wool 1
fill ~85 ~30 ~65 ~85 ~30 ~64 wool 1
fill ~85 ~30 ~73 ~85 ~30 ~74 wool 1
setblock ~86 ~30 ~67 wool 1
setblock ~86 ~30 ~68 red_sandstone 0
setblock ~86 ~30 ~69 wool 1
setblock ~86 ~30 ~70 red_sandstone 0
setblock ~86 ~30 ~71 wool 1
fill ~21 ~31 ~113 ~21 ~31 ~115 red_mushroom_block 0
setblock ~22 ~31 ~113 redstone_block 0
fill ~22 ~31 ~114 ~23 ~31 ~114 red_mushroom_block 0
setblock ~22 ~31 ~115 redstone_block 0
fill ~58 ~31 ~66 ~58 ~33 ~66 concrete 1
fill ~58 ~31 ~67 ~58 ~31 ~71 concrete 1
setblock ~59 ~31 ~65 concrete 1
setblock ~59 ~31 ~73 concrete 1
fill ~59 ~31 ~74 ~59 ~33 ~74 wool 1
fill ~60 ~31 ~62 ~60 ~33 ~62 concrete 1
fill ~60 ~31 ~63 ~60 ~31 ~62 concrete 1
fill ~60 ~31 ~75 ~60 ~31 ~76 concrete 1
setblock ~61 ~31 ~61 concrete 1
setblock ~61 ~31 ~77 concrete 1
fill ~62 ~31 ~59 ~63 ~31 ~59 concrete 1
fill ~62 ~31 ~60 ~62 ~31 ~59 concrete 1
setblock ~62 ~31 ~78 concrete 1
fill ~63 ~31 ~79 ~63 ~32 ~79 concrete 1
setblock ~64 ~31 ~58 concrete 1
fill ~64 ~31 ~80 ~64 ~33 ~80 concrete 1
fill ~65 ~31 ~57 ~66 ~31 ~57 concrete 1
fill ~65 ~31 ~81 ~66 ~31 ~81 concrete 1
fill ~67 ~31 ~82 ~67 ~65 ~82 wool 1
fill ~70 ~31 ~55 ~74 ~31 ~55 concrete 1
setblock ~70 ~31 ~82 concrete 1
setblock ~72 ~31 ~83 concrete 1
setblock ~74 ~31 ~82 concrete 1
fill ~77 ~31 ~82 ~77 ~64 ~82 wool 1
fill ~78 ~31 ~57 ~79 ~31 ~57 concrete 1
fill ~78 ~31 ~81 ~79 ~31 ~81 concrete 1
setblock ~80 ~31 ~58 concrete 1
fill ~80 ~31 ~80 ~80 ~32 ~80 concrete 1
fill ~81 ~31 ~58 ~81 ~33 ~58 wool 1
setblock ~81 ~31 ~79 concrete 1
setblock ~82 ~31 ~59 concrete 1
setblock ~82 ~31 ~78 concrete 1
fill ~83 ~31 ~60 ~83 ~33 ~60 wool 1
setblock ~83 ~31 ~61 concrete 1
setblock ~83 ~31 ~77 concrete 1
fill ~84 ~31 ~62 ~84 ~32 ~62 concrete 1
fill ~84 ~31 ~75 ~84 ~31 ~76 concrete 1
fill ~85 ~31 ~63 ~85 ~32 ~63 concrete 1
setblock ~85 ~31 ~65 concrete 1
setblock ~85 ~31 ~73 concrete 1
fill ~85 ~31 ~74 ~85 ~33 ~74 wool 1
fill ~86 ~31 ~66 ~86 ~33 ~66 concrete 1
fill ~86 ~31 ~67 ~86 ~31 ~72 concrete 1
setblock ~20 ~32 ~113 red_mushroom_block 0
setblock ~20 ~32 ~114 redstone_block 0
fill ~21 ~32 ~112 ~21 ~34 ~112 red_mushroom_block 0
fill ~21 ~32 ~115 ~23 ~32 ~115 red_mushroom_block 0
setblock ~22 ~32 ~112 redstone_block 0
fill ~23 ~32 ~113 ~23 ~36 ~113 red_mushroom_block 0
setblock ~24 ~32 ~114 redstone_block 0
setblock ~58 ~32 ~67 wool 1
setblock ~58 ~32 ~68 red_sandstone 0
setblock ~58 ~32 ~69 wool 1
fill ~58 ~32 ~70 ~58 ~33 ~70 concrete 1
setblock ~58 ~32 ~71 wool 1
fill ~58 ~32 ~72 ~58 ~33 ~72 concrete 1
setblock ~59 ~32 ~63 concrete 1
setblock ~59 ~32 ~65 wool 1
setblock ~59 ~32 ~73 wool 1
setblock ~59 ~32 ~75 concrete 1
setblock ~60 ~32 ~61 wool 1
fill ~60 ~32 ~76 ~60 ~33 ~76 concrete 1
fill ~61 ~32 ~60 ~61 ~34 ~60 wool 1
setblock ~61 ~32 ~77 wool 1
setblock ~62 ~32 ~59 wool 1
setblock ~62 ~32 ~78 red_sandstone 0
setblock ~62 ~32 ~79 wool 1
fill ~63 ~32 ~58 ~63 ~34 ~58 wool 1
fill ~64 ~32 ~57 ~65 ~32 ~57 wool 1
fill ~65 ~32 ~81 ~66 ~32 ~81 wool 1
setblock ~66 ~32 ~56 red_sandstone 0
fill ~69 ~32 ~55 ~70 ~32 ~55 wool 1
setblock ~70 ~32 ~83 wool 1
setblock ~71 ~32 ~55 concrete 1
setblock ~71 ~32 ~83 concrete 1
setblock ~72 ~32 ~55 wool 1
setblock ~72 ~32 ~83 wool 1
setblock ~73 ~32 ~55 concrete 1
setblock ~73 ~32 ~83 concrete 1
fill ~74 ~32 ~55 ~75 ~32 ~55 wool 1
setblock ~74 ~32 ~83 wool 1
setblock ~78 ~32 ~56 red_sandstone 0
fill ~78 ~32 ~81 ~79 ~32 ~81 wool 1
fill ~79 ~32 ~57 ~80 ~32 ~57 wool 1
fill ~81 ~32 ~80 ~81 ~62 ~80 wool 1
setblock ~82 ~32 ~59 wool 1
setblock ~82 ~32 ~79 wool 1
fill ~83 ~32 ~77 ~83 ~32 ~78 wool 1
setblock ~84 ~32 ~61 wool 1
fill ~84 ~32 ~76 ~84 ~33 ~76 concrete 1
setblock ~85 ~32 ~75 concrete 1
setblock ~86 ~32 ~65 wool 1
setblock ~86 ~32 ~67 wool 1
setblock ~86 ~32 ~68 red_sandstone 0
setblock ~86 ~32 ~69 wool 1
fill ~86 ~32 ~70 ~86 ~33 ~70 concrete 1
setblock ~86 ~32 ~71 wool 1
fill ~86 ~32 ~72 ~86 ~33 ~72 concrete 1
setblock ~86 ~32 ~73 wool 1
setblock ~20 ~33 ~113 redstone_block 0
setblock ~20 ~33 ~114 red_mushroom_block 0
fill ~21 ~33 ~115 ~21 ~34 ~115 red_mushroom_block 0
setblock ~22 ~33 ~112 red_mushroom_block 0
fill ~22 ~33 ~115 ~23 ~33 ~115 redstone_block 0
setblock ~24 ~33 ~114 red_mushroom_block 0
setblock ~58 ~33 ~65 concrete 1
fill ~58 ~33 ~67 ~58 ~33 ~73 concrete 1
setblock ~59 ~33 ~63 red_sandstone 0
setblock ~59 ~33 ~75 red_sandstone 0
setblock ~60 ~33 ~61 concrete 1
setblock ~60 ~33 ~77 concrete 1
fill ~61 ~33 ~78 ~61 ~58 ~78 wool 1
setblock ~62 ~33 ~59 concrete 1
setblock ~62 ~33 ~79 concrete 1
fill ~63 ~33 ~80 ~63 ~63 ~80 wool 1
fill ~64 ~33 ~57 ~65 ~33 ~57 concrete 1
setblock ~65 ~33 ~81 concrete 1
setblock ~66 ~33 ~56 concrete 1
setblock ~66 ~33 ~82 concrete 1
setblock ~68 ~33 ~55 red_mushroom_block 0
fill ~69 ~33 ~55 ~70 ~33 ~55 concrete 1
fill ~69 ~33 ~83 ~70 ~33 ~83 concrete 1
setblock ~71 ~33 ~55 red_sandstone 0
setblock ~71 ~33 ~83 red_sandstone 0
setblock ~72 ~33 ~55 red_mushroom_block 0
setblock ~72 ~33 ~83 red_mushroom_block 0
setblock ~73 ~33 ~55 red_sandstone 0
setblock ~73 ~33 ~83 red_sandstone 0
fill ~74 ~33 ~55 ~75 ~33 ~55 concrete 1
fill ~74 ~33 ~83 ~75 ~33 ~83 concrete 1
setblock ~76 ~33 ~55 red_mushroom_block 0
setblock ~77 ~33 ~55 red_sandstone 0
setblock ~78 ~33 ~56 concrete 1
setblock ~78 ~33 ~82 concrete 1
fill ~79 ~33 ~56 ~79 ~35 ~56 wool 1
fill ~79 ~33 ~81 ~80 ~33 ~81 concrete 1
setblock ~80 ~33 ~57 concrete 1
setblock ~82 ~33 ~59 concrete 1
setblock ~82 ~33 ~79 concrete 1
fill ~83 ~33 ~78 ~83 ~57 ~78 wool 1
setblock ~84 ~33 ~61 concrete 1
setblock ~84 ~33 ~77 concrete 1
fill ~85 ~33 ~62 ~85 ~35 ~62 wool 1
setblock ~85 ~33 ~63 red_sandstone 0
setblock ~85 ~33 ~75 red_sandstone 0
fill ~86 ~33 ~64 ~86 ~33 ~73 concrete 1
fill ~21 ~34 ~113 ~21 ~36 ~113 red_mushroom_block 0
fill ~21 ~34 ~114 ~21 ~37 ~114 red_mushroom_block 0
setblock ~22 ~34 ~112 redstone_block 0
fill ~22 ~34 ~115 ~23 ~34 ~115 red_mushroom_block 0
fill ~23 ~34 ~114 ~23 ~38 ~114 red_mushroom_block 0
setblock ~57 ~34 ~69 wool 1
setblock ~58 ~34 ~64 red_sandstone 0
setblock ~58 ~34 ~65 wool 1
setblock ~58 ~34 ~66 red_sandstone 0
setblock ~58 ~34 ~67 wool 1
setblock ~58 ~34 ~68 red_sandstone 0
setblock ~58 ~34 ~70 red_sandstone 0
setblock ~58 ~34 ~71 wool 1
setblock ~58 ~34 ~72 red_sandstone 0
setblock ~58 ~34 ~73 wool 1
setblock ~58 ~34 ~74 red_sandstone 0
fill ~59 ~34 ~62 ~59 ~36 ~62 wool 1
fill ~59 ~34 ~63 ~59 ~34 ~62 wool 1
setblock ~59 ~34 ~75 wool 1
setblock ~60 ~34 ~61 wool 1
setblock ~60 ~34 ~76 red_sandstone 0
setblock ~60 ~34 ~77 wool 1
setblock ~61 ~34 ~59 wool 1
setblock ~62 ~34 ~58 red_sandstone 0
setblock ~62 ~34 ~79 wool 1
setblock ~64 ~34 ~57 wool 1
fill ~64 ~34 ~81 ~65 ~34 ~81 wool 1
fill ~65 ~34 ~56 ~65 ~36 ~56 wool 1
setblock ~66 ~34 ~56 red_sandstone 0
setblock ~66 ~34 ~82 red_sandstone 0
fill ~67 ~34 ~55 ~70 ~34 ~55 wool 1
fill ~69 ~34 ~83 ~75 ~34 ~83 wool 1
fill ~71 ~34 ~54 ~71 ~37 ~54 wool 1
setblock ~72 ~34 ~54 red_sandstone 0
fill ~73 ~34 ~54 ~73 ~37 ~54 wool 1
fill ~74 ~34 ~55 ~77 ~34 ~55 wool 1
setblock ~78 ~34 ~56 red_sandstone 0
setblock ~78 ~34 ~82 red_sandstone 0
fill ~79 ~34 ~81 ~80 ~34 ~81 wool 1
fill ~80 ~34 ~57 ~81 ~34 ~57 wool 1
setblock ~82 ~34 ~58 red_sandstone 0
setblock ~82 ~34 ~79 wool 1
setblock ~83 ~34 ~59 wool 1
fill ~84 ~34 ~60 ~84 ~36 ~60 concrete 1
setblock ~84 ~34 ~61 wool 1
setblock ~84 ~34 ~77 wool 1
setblock ~85 ~34 ~63 wool 1
fill ~85 ~34 ~75 ~85 ~34 ~76 wool 1
setblock ~86 ~34 ~64 red_sandstone 0
setblock ~86 ~34 ~65 wool 1
setblock ~86 ~34 ~66 red_sandstone 0
setblock ~86 ~34 ~72 red_sandstone 0
setblock ~86 ~34 ~73 wool 1
setblock ~86 ~34 ~74 red_sandstone 0
fill ~87 ~34 ~67 ~87 ~34 ~71 wool 1
setblock ~22 ~35 ~112 red_mushroom_block 0
setblock ~22 ~35 ~115 redstone_block 0
fill ~57 ~35 ~66 ~57 ~44 ~66 wool 1
setblock ~57 ~35 ~67 concrete 1
fill ~57 ~35 ~68 ~57 ~42 ~68 wool 1
setblock ~57 ~35 ~69 concrete 1
fill ~57 ~35 ~70 ~57 ~46 ~70 wool 1
setblock ~57 ~35 ~71 concrete 1
fill ~58 ~35 ~63 ~58 ~35 ~65 concrete 1
fill ~58 ~35 ~72 ~58 ~36 ~72 concrete 1
fill ~58 ~35 ~73 ~58 ~35 ~74 concrete 1
setblock ~59 ~35 ~61 concrete 1
fill ~59 ~35 ~75 ~59 ~36 ~75 concrete 1
fill ~59 ~35 ~76 ~59 ~60 ~76 wool 1
fill ~60 ~35 ~60 ~60 ~36 ~60 concrete 1
setblock ~60 ~35 ~77 concrete 1
setblock ~61 ~35 ~59 concrete 1
fill ~62 ~35 ~58 ~62 ~36 ~58 concrete 1
setblock ~62 ~35 ~79 concrete 1
setblock ~63 ~35 ~57 concrete 1
fill ~64 ~35 ~56 ~64 ~38 ~56 concrete 1
fill ~64 ~35 ~81 ~65 ~35 ~81 concrete 1
fill ~66 ~35 ~55 ~68 ~35 ~55 concrete 1
setblock ~66 ~35 ~82 concrete 1
fill ~69 ~35 ~54 ~69 ~38 ~54 wool 1
fill ~69 ~35 ~83 ~75 ~35 ~83 concrete 1
fill ~70 ~35 ~54 ~70 ~37 ~54 concrete 1
fill ~72 ~35 ~54 ~72 ~37 ~54 concrete 1
fill ~74 ~35 ~54 ~74 ~37 ~54 concrete 1
fill ~75 ~35 ~54 ~75 ~38 ~54 wool 1
fill ~76 ~35 ~55 ~78 ~35 ~55 concrete 1
setblock ~78 ~35 ~82 concrete 1
fill ~79 ~35 ~81 ~80 ~35 ~81 concrete 1
fill ~80 ~35 ~56 ~80 ~37 ~56 concrete 1
setblock ~81 ~35 ~57 concrete 1
setblock ~82 ~35 ~58 concrete 1
setblock ~82 ~35 ~79 concrete 1
setblock ~83 ~35 ~59 concrete 1
setblock ~84 ~35 ~77 concrete 1
setblock ~85 ~35 ~61 concrete 1
fill ~85 ~35 ~75 ~85 ~36 ~75 concrete 1
fill ~85 ~35 ~76 ~85 ~59 ~76 wool 1
fill ~86 ~35 ~63 ~86 ~35 ~65 concrete 1
fill ~86 ~35 ~72 ~86 ~35 ~74 concrete 1
fill ~87 ~35 ~66 ~87 ~42 ~66 wool 1
setblock ~87 ~35 ~67 concrete 1
fill ~87 ~35 ~68 ~87 ~41 ~68 wool 1
setblock ~87 ~35 ~69 concrete 1
fill ~87 ~35 ~70 ~87 ~43 ~70 wool 1
setblock ~87 ~35 ~71 concrete 1
setblock ~22 ~36 ~113 red_mushroom_block 0
setblock ~22 ~36 ~115 red_mushroom_block 0
setblock ~57 ~36 ~65 wool 1
setblock ~57 ~36 ~67 wool 1
setblock ~57 ~36 ~69 wool 1
setblock ~57 ~36 ~71 wool 1
setblock ~58 ~36 ~63 wool 1
setblock ~58 ~36 ~64 red_sandstone 0
setblock ~58 ~36 ~73 wool 1
setblock ~58 ~36 ~74 red_sandstone 0
setblock ~59 ~36 ~61 wool 1
setblock ~60 ~36 ~77 wool 1
setblock ~61 ~36 ~59 wool 1
setblock ~62 ~36 ~79 wool 1
setblock ~63 ~36 ~57 wool 1
fill ~64 ~36 ~81 ~65 ~36 ~81 wool 1
setblock ~66 ~36 ~55 wool 1
setblock ~66 ~36 ~82 red_sandstone 0
setblock ~67 ~36 ~55 concrete 1
fill ~68 ~36 ~54 ~68 ~37 ~54 concrete 1
fill ~69 ~36 ~83 ~70 ~36 ~83 wool 1
setblock ~71 ~36 ~83 concrete 1
setblock ~72 ~36 ~83 wool 1
setblock ~73 ~36 ~83 concrete 1
fill ~74 ~36 ~83 ~75 ~36 ~83 wool 1
fill ~76 ~36 ~54 ~76 ~37 ~54 concrete 1
setblock ~77 ~36 ~55 concrete 1
fill ~78 ~36 ~55 ~79 ~36 ~55 wool 1
setblock ~78 ~36 ~82 red_sandstone 0
fill ~79 ~36 ~81 ~80 ~36 ~81 wool 1
fill ~81 ~36 ~57 ~82 ~36 ~57 wool 1
setblock ~82 ~36 ~79 wool 1
fill ~83 ~36 ~58 ~83 ~39 ~58 wool 1
setblock ~84 ~36 ~59 wool 1
setblock ~84 ~36 ~77 wool 1
setblock ~85 ~36 ~61 wool 1
fill ~86 ~36 ~62 ~86 ~37 ~62 concrete 1
setblock ~86 ~36 ~63 wool 1
setblock ~86 ~36 ~64 red_sandstone 0
setblock ~86 ~36 ~73 wool 1
setblock ~86 ~36 ~74 red_sandstone 0
setblock ~87 ~36 ~65 wool 1
setblock ~87 ~36 ~67 wool 1
setblock ~87 ~36 ~69 wool 1
fill ~87 ~36 ~71 ~87 ~36 ~72 wool 1
setblock ~22 ~37 ~113 redstone_block 0
setblock ~22 ~37 ~114 red_mushroom_block 0
setblock ~57 ~37 ~65 concrete 1
setblock ~57 ~37 ~67 concrete 1
setblock ~57 ~37 ~69 concrete 1
setblock ~57 ~37 ~71 concrete 1
fill ~57 ~37 ~72 ~57 ~58 ~72 wool 1
fill ~58 ~37 ~62 ~58 ~37 ~64 concrete 1
fill ~58 ~37 ~73 ~58 ~37 ~74 concrete 1
fill ~59 ~37 ~60 ~59 ~43 ~60 wool 1
setblock ~59 ~37 ~61 concrete 1
setblock ~59 ~37 ~75 red_sandstone 0
setblock ~60 ~37 ~59 red_mushroom_block 0
setblock ~60 ~37 ~77 concrete 1
fill ~61 ~37 ~58 ~61 ~40 ~58 wool 1
setblock ~62 ~37 ~57 concrete 1
setblock ~62 ~37 ~79 concrete 1
fill ~63 ~37 ~56 ~63 ~41 ~56 wool 1
fill ~64 ~37 ~81 ~65 ~37 ~81 concrete 1
fill ~65 ~37 ~55 ~66 ~37 ~55 concrete 1
setblock ~66 ~37 ~82 concrete 1
fill ~67 ~37 ~54 ~67 ~41 ~54 wool 1
fill ~69 ~37 ~83 ~70 ~37 ~83 concrete 1
setblock ~71 ~37 ~83 red_sandstone 0
setblock ~72 ~37 ~83 red_mushroom_block 0
setblock ~73 ~37 ~83 red_sandstone 0
fill ~74 ~37 ~83 ~75 ~37 ~83 concrete 1
fill ~77 ~37 ~54 ~77 ~40 ~54 wool 1
fill ~78 ~37 ~55 ~79 ~37 ~55 concrete 1
setblock ~78 ~37 ~82 concrete 1
fill ~79 ~37 ~81 ~80 ~37 ~81 concrete 1
fill ~81 ~37 ~56 ~81 ~40 ~56 wool 1
setblock ~82 ~37 ~57 concrete 1
setblock ~82 ~37 ~79 concrete 1
setblock ~84 ~37 ~59 red_mushroom_block 0
setblock ~84 ~37 ~77 concrete 1
fill ~85 ~37 ~60 ~85 ~42 ~60 wool 1
setblock ~85 ~37 ~61 concrete 1
setblock ~85 ~37 ~75 red_sandstone 0
setblock ~86 ~37 ~63 concrete 1
fill ~86 ~37 ~73 ~86 ~37 ~74 concrete 1
fill ~87 ~37 ~64 ~87 ~45 ~64 wool 1
setblock ~87 ~37 ~65 concrete 1
setblock ~87 ~37 ~67 concrete 1
setblock ~87 ~37 ~69 concrete 1
setblock ~87 ~37 ~71 concrete 1
fill ~87 ~37 ~72 ~87 ~54 ~72 wool 1
setblock ~22 ~38 ~113 red_mushroom_block 0
setblock ~22 ~38 ~114 redstone_block 0
fill ~57 ~38 ~64 ~57 ~47 ~64 wool 1
fill ~57 ~38 ~65 ~57 ~38 ~64 wool 1
setblock ~57 ~38 ~67 wool 1
setblock ~57 ~38 ~69 wool 1
setblock ~57 ~38 ~71 wool 1
setblock ~58 ~38 ~62 red_sandstone 0
setblock ~58 ~38 ~63 wool 1
setblock ~58 ~38 ~73 wool 1
setblock ~58 ~38 ~74 red_sandstone 0
setblock ~59 ~38 ~61 wool 1
setblock ~59 ~38 ~75 wool 1
setblock ~60 ~38 ~59 wool 1
setblock ~60 ~38 ~77 wool 1
setblock ~62 ~38 ~57 wool 1
setblock ~62 ~38 ~79 wool 1
fill ~64 ~38 ~81 ~65 ~38 ~81 wool 1
setblock ~65 ~38 ~55 wool 1
setblock ~66 ~38 ~54 red_sandstone 0
setblock ~66 ~38 ~82 red_sandstone 0
setblock ~68 ~38 ~54 red_sandstone 0
fill ~69 ~38 ~83 ~75 ~38 ~83 wool 1
fill ~70 ~38 ~53 ~74 ~38 ~53 wool 1
setblock ~76 ~38 ~54 red_sandstone 0
setblock ~78 ~38 ~54 red_sandstone 0
setblock ~78 ~38 ~82 red_sandstone 0
fill ~79 ~38 ~55 ~80 ~38 ~55 wool 1
fill ~79 ~38 ~81 ~80 ~38 ~81 wool 1
setblock ~82 ~38 ~57 wool 1
setblock ~82 ~38 ~79 wool 1
setblock ~84 ~38 ~59 wool 1
setblock ~84 ~38 ~77 wool 1
setblock ~85 ~38 ~61 wool 1
setblock ~85 ~38 ~75 wool 1
setblock ~86 ~38 ~62 red_sandstone 0
setblock ~86 ~38 ~63 wool 1
setblock ~86 ~38 ~73 wool 1
setblock ~86 ~38 ~74 red_sandstone 0
setblock ~87 ~38 ~65 wool 1
setblock ~87 ~38 ~67 wool 1
setblock ~87 ~38 ~69 wool 1
setblock ~87 ~38 ~71 wool 1
setblock ~22 ~39 ~114 red_mushroom_block 0
setblock ~57 ~39 ~65 concrete 1
setblock ~57 ~39 ~67 concrete 1
setblock ~57 ~39 ~69 concrete 1
setblock ~57 ~39 ~71 concrete 1
fill ~58 ~39 ~62 ~58 ~41 ~62 concrete 1
fill ~58 ~39 ~63 ~58 ~39 ~62 concrete 1
fill ~58 ~39 ~73 ~58 ~39 ~74 concrete 1
setblock ~59 ~39 ~61 concrete 1
fill ~59 ~39 ~75 ~59 ~40 ~75 concrete 1
setblock ~60 ~39 ~59 concrete 1
setblock ~60 ~39 ~77 concrete 1
setblock ~62 ~39 ~57 concrete 1
setblock ~62 ~39 ~79 concrete 1
fill ~64 ~39 ~55 ~65 ~39 ~55 concrete 1
fill ~64 ~39 ~81 ~65 ~39 ~81 concrete 1
fill ~66 ~39 ~54 ~66 ~41 ~54 concrete 1
setblock ~66 ~39 ~82 concrete 1
setblock ~68 ~39 ~54 concrete 1
fill ~69 ~39 ~53 ~75 ~39 ~53 concrete 1
fill ~69 ~39 ~83 ~75 ~39 ~83 concrete 1
setblock ~76 ~39 ~54 concrete 1
fill ~78 ~39 ~54 ~78 ~41 ~54 concrete 1
setblock ~78 ~39 ~82 concrete 1
fill ~79 ~39 ~55 ~80 ~39 ~55 concrete 1
fill ~79 ~39 ~81 ~80 ~39 ~81 concrete 1
fill ~82 ~39 ~57 ~83 ~39 ~57 concrete 1
setblock ~82 ~39 ~79 concrete 1
setblock ~84 ~39 ~59 concrete 1
setblock ~84 ~39 ~77 concrete 1
setblock ~85 ~39 ~75 concrete 1
fill ~86 ~39 ~61 ~86 ~39 ~63 concrete 1
fill ~86 ~39 ~73 ~86 ~39 ~74 concrete 1
setblock ~87 ~39 ~65 concrete 1
setblock ~87 ~39 ~67 concrete 1
setblock ~87 ~39 ~69 concrete 1
setblock ~87 ~39 ~71 concrete 1
setblock ~22 ~40 ~114 redstone_block 0
setblock ~57 ~40 ~65 wool 1
setblock ~57 ~40 ~67 wool 1
setblock ~57 ~40 ~69 wool 1
setblock ~57 ~40 ~71 wool 1
setblock ~58 ~40 ~61 wool 1
setblock ~58 ~40 ~63 wool 1
setblock ~58 ~40 ~73 wool 1
setblock ~58 ~40 ~74 red_sandstone 0
setblock ~60 ~40 ~59 wool 1
setblock ~60 ~40 ~77 wool 1
fill ~61 ~40 ~57 ~62 ~40 ~57 wool 1
setblock ~62 ~40 ~79 wool 1
fill ~64 ~40 ~55 ~65 ~40 ~55 wool 1
fill ~64 ~40 ~81 ~65 ~40 ~81 wool 1
setblock ~66 ~40 ~82 red_sandstone 0
fill ~68 ~40 ~53 ~76 ~40 ~53 wool 1
fill ~69 ~40 ~83 ~70 ~40 ~83 wool 1
setblock ~71 ~40 ~83 concrete 1
setblock ~72 ~40 ~83 wool 1
setblock ~73 ~40 ~83 concrete 1
fill ~74 ~40 ~83 ~75 ~40 ~83 wool 1
setblock ~78 ~40 ~82 red_sandstone 0
fill ~79 ~40 ~55 ~80 ~40 ~55 wool 1
fill ~79 ~40 ~81 ~80 ~40 ~81 wool 1
setblock ~82 ~40 ~56 red_sandstone 0
setblock ~82 ~40 ~79 wool 1
setblock ~83 ~40 ~57 wool 1
fill ~84 ~40 ~58 ~84 ~41 ~58 concrete 1
setblock ~84 ~40 ~77 wool 1
setblock ~85 ~40 ~59 concrete 1
setblock ~86 ~40 ~61 wool 1
fill ~86 ~40 ~62 ~86 ~41 ~62 concrete 1
setblock ~86 ~40 ~74 red_sandstone 0
setblock ~86 ~40 ~75 wool 1
setblock ~87 ~40 ~63 wool 1
setblock ~87 ~40 ~65 wool 1
setblock ~87 ~40 ~67 wool 1
setblock ~87 ~40 ~69 wool 1
setblock ~87 ~40 ~71 wool 1
setblock ~87 ~40 ~73 wool 1
setblock ~22 ~41 ~114 red_mushroom_block 0
setblock ~57 ~41 ~63 concrete 1
setblock ~57 ~41 ~65 concrete 1
setblock ~57 ~41 ~67 concrete 1
setblock ~57 ~41 ~69 concrete 1
setblock ~57 ~41 ~71 concrete 1
setblock ~58 ~41 ~61 concrete 1
fill ~58 ~41 ~73 ~58 ~41 ~74 concrete 1
setblock ~59 ~41 ~75 red_sandstone 0
setblock ~60 ~41 ~58 concrete 1
setblock ~60 ~41 ~59 red_mushroom_block 0
setblock ~60 ~41 ~77 concrete 1
setblock ~61 ~41 ~57 concrete 1
setblock ~62 ~41 ~56 concrete 1
setblock ~62 ~41 ~79 concrete 1
setblock ~64 ~41 ~55 red_mushroom_block 0
fill ~64 ~41 ~81 ~65 ~41 ~81 concrete 1
fill ~65 ~41 ~54 ~65 ~45 ~54 wool 1
setblock ~66 ~41 ~82 concrete 1
fill ~68 ~41 ~53 ~77 ~41 ~53 concrete 1
fill ~69 ~41 ~82 ~69 ~59 ~82 wool 1
setblock ~70 ~41 ~83 concrete 1
setblock ~71 ~41 ~83 red_sandstone 0
setblock ~72 ~41 ~83 red_mushroom_block 0
setblock ~73 ~41 ~83 red_sandstone 0
fill ~74 ~41 ~83 ~75 ~41 ~83 concrete 1
setblock ~78 ~41 ~82 concrete 1
fill ~79 ~41 ~54 ~79 ~45 ~54 wool 1
fill ~79 ~41 ~81 ~80 ~41 ~81 concrete 1
setblock ~80 ~41 ~55 red_mushroom_block 0
setblock ~81 ~41 ~55 red_sandstone 0
setblock ~82 ~41 ~56 concrete 1
setblock ~82 ~41 ~79 concrete 1
setblock ~83 ~41 ~57 concrete 1
setblock ~84 ~41 ~77 concrete 1
setblock ~85 ~41 ~59 red_sandstone 0
setblock ~86 ~41 ~61 concrete 1
fill ~86 ~41 ~74 ~86 ~41 ~75 concrete 1
setblock ~87 ~41 ~63 concrete 1
setblock ~87 ~41 ~65 concrete 1
setblock ~87 ~41 ~69 concrete 1
setblock ~87 ~41 ~71 concrete 1
setblock ~87 ~41 ~73 concrete 1
setblock ~88 ~41 ~67 red_mushroom_block 0
fill ~91 ~41 ~46 ~91 ~41 ~47 planks 4
setblock ~22 ~42 ~114 redstone_block 0
setblock ~52 ~42 ~46 stained_hardened_clay 1
fill ~52 ~42 ~47 ~54 ~42 ~47 planks 4
setblock ~52 ~42 ~48 stained_hardened_clay 1
fill ~52 ~42 ~49 ~54 ~42 ~49 planks 4
setblock ~52 ~42 ~50 stained_hardened_clay 1
fill ~52 ~42 ~51 ~54 ~42 ~51 planks 4
setblock ~52 ~42 ~52 stained_hardened_clay 1
setblock ~53 ~42 ~46 planks 3
setblock ~53 ~42 ~48 planks 3
setblock ~53 ~42 ~50 planks 3
setblock ~53 ~42 ~52 planks 3
setblock ~53 ~42 ~53 planks 4
setblock ~54 ~42 ~48 stained_hardened_clay 1
setblock ~54 ~42 ~50 stained_hardened_clay 1
setblock ~57 ~42 ~63 wool 1
setblock ~57 ~42 ~65 wool 1
setblock ~57 ~42 ~67 wool 1
setblock ~57 ~42 ~69 wool 1
setblock ~57 ~42 ~71 wool 1
setblock ~58 ~42 ~61 wool 1
setblock ~58 ~42 ~62 red_sandstone 0
setblock ~58 ~42 ~73 wool 1
setblock ~58 ~42 ~74 red_sandstone 0
setblock ~59 ~42 ~59 wool 1
setblock ~59 ~42 ~75 wool 1
setblock ~60 ~42 ~58 red_sandstone 0
setblock ~60 ~42 ~77 wool 1
setblock ~61 ~42 ~57 wool 1
setblock ~62 ~42 ~56 red_sandstone 0
setblock ~62 ~42 ~79 wool 1
fill ~63 ~42 ~55 ~64 ~42 ~55 wool 1
fill ~64 ~42 ~81 ~65 ~42 ~81 wool 1
setblock ~66 ~42 ~54 red_sandstone 0
setblock ~66 ~42 ~82 red_sandstone 0
fill ~67 ~42 ~53 ~77 ~42 ~53 wool 1
fill ~70 ~42 ~83 ~74 ~42 ~83 wool 1
fill ~75 ~42 ~82 ~75 ~59 ~82 wool 1
setblock ~78 ~42 ~54 red_sandstone 0
setblock ~78 ~42 ~82 red_sandstone 0
fill ~79 ~42 ~81 ~80 ~42 ~81 wool 1
fill ~80 ~42 ~55 ~81 ~42 ~55 wool 1
setblock ~82 ~42 ~56 red_sandstone 0
setblock ~82 ~42 ~79 wool 1
setblock ~83 ~42 ~57 wool 1
setblock ~84 ~42 ~58 red_sandstone 0
setblock ~84 ~42 ~77 wool 1
setblock ~85 ~42 ~59 wool 1
setblock ~86 ~42 ~61 wool 1
setblock ~86 ~42 ~62 red_sandstone 0
setblock ~86 ~42 ~74 red_sandstone 0
setblock ~86 ~42 ~75 wool 1
setblock ~87 ~42 ~63 wool 1
setblock ~87 ~42 ~65 wool 1
setblock ~87 ~42 ~69 wool 1
setblock ~87 ~42 ~71 wool 1
setblock ~87 ~42 ~73 wool 1
setblock ~88 ~42 ~67 wool 1
fill ~88 ~42 ~68 ~88 ~55 ~68 concrete 1
setblock ~89 ~42 ~44 planks 3
fill ~89 ~42 ~45 ~91 ~42 ~45 planks 4
setblock ~89 ~42 ~46 planks 3
fill ~89 ~42 ~47 ~90 ~42 ~47 planks 4
setblock ~89 ~42 ~48 planks 3
setblock ~90 ~42 ~44 stained_hardened_clay 1
setblock ~90 ~42 ~46 stained_hardened_clay 1
setblock ~90 ~42 ~48 stained_hardened_clay 1
fill ~90 ~42 ~49 ~91 ~42 ~49 planks 4
setblock ~90 ~42 ~50 stained_hardened_clay 1
fill ~90 ~42 ~51 ~91 ~42 ~51 planks 4
setblock ~90 ~42 ~52 stained_hardened_clay 1
setblock ~91 ~42 ~44 planks 3
setblock ~91 ~42 ~48 planks 3
setblock ~91 ~42 ~50 planks 3
setblock ~91 ~42 ~52 planks 3
setblock ~91 ~42 ~53 planks 4
setblock ~92 ~42 ~46 stained_hardened_clay 1
setblock ~92 ~42 ~47 planks 4
setblock ~92 ~42 ~48 stained_hardened_clay 1
fill ~51 ~43 ~47 ~51 ~43 ~51 planks 4
setblock ~52 ~43 ~44 planks 4
setblock ~52 ~43 ~45 stained_hardened_clay 1
setblock ~52 ~43 ~46 planks 4
setblock ~52 ~43 ~52 planks 4
setblock ~52 ~43 ~53 stained_hardened_clay 1
fill ~52 ~43 ~54 ~55 ~43 ~54 planks 4
setblock ~52 ~43 ~55 stained_hardened_clay 1
fill ~52 ~43 ~56 ~53 ~43 ~56 planks 4
setblock ~52 ~43 ~57 stained_hardened_clay 1
setblock ~52 ~43 ~58 planks 4
setblock ~53 ~43 ~45 planks 4
