fill ~0~0~0 ~24~0~1 minecraft:grass
fill ~6~12~0 ~6~12~11 minecraft:wooden_slab 5
setblock ~7~12~0 minecraft:planks 5
setblock ~8~12~0 minecraft:wooden_slab 13
setblock ~8~13~0 minecraft:dark_oak_stairs 0
setblock ~9~13~0 minecraft:dark_oak_stairs 5
setblock ~9~14~0 minecraft:planks 5
setblock ~9~15~0 minecraft:dark_oak_stairs 0
setblock ~10~15~0 minecraft:dark_oak_stairs 5
setblock ~10~16~0 minecraft:planks 5
setblock ~10~17~0 minecraft:dark_oak_stairs 0
setblock ~11~17~0 minecraft:dark_oak_stairs 5
setblock ~11~18~0 minecraft:planks 5
setblock ~11~19~0 minecraft:dark_oak_stairs 0
setblock ~12~19~0 minecraft:dark_oak_stairs 6
setblock ~12~20~0 minecraft:planks 5
setblock ~12~21~0 minecraft:dark_oak_stairs 3
setblock ~13~17~0 minecraft:dark_oak_stairs 4
setblock ~13~18~0 minecraft:planks 5
setblock ~13~19~0 minecraft:dark_oak_stairs 1
setblock ~14~15~0 minecraft:dark_oak_stairs 4
setblock ~14~16~0 minecraft:planks 5
setblock ~14~17~0 minecraft:dark_oak_stairs 1
setblock ~15~13~0 minecraft:dark_oak_stairs 4
setblock ~15~14~0 minecraft:planks 5
setblock ~15~15~0 minecraft:dark_oak_stairs 1
setblock ~16~12~0 minecraft:wooden_slab 13
setblock ~16~13~0 minecraft:dark_oak_stairs 1
setblock ~17~12~0 minecraft:planks 5
fill ~18~12~0 ~18~12~4 minecraft:wooden_slab 5
fill ~25~0~0 ~26~0~0 minecraft:dark_prismarine_stairs 2
setblock ~27~0~0 minecraft:dirt 0
fill ~28~0~0 ~29~0~2 minecraft:grass_path
fill ~7~12~1 ~7~12~21 minecraft:warped_planks
setblock ~8~8~1 minecraft:spruce_stairs 6
fill ~8~9~1 ~8~12~1 minecraft:stripped_spruce_log 0
fill ~8~13~1 ~8~13~9 minecraft:warped_stairs 0
fill ~9~9~1 ~11~9~1 minecraft:wooden_slab 1
setblock ~9~12~1 minecraft:spruce_stairs 5
fill ~9~14~1 ~9~14~9 minecraft:warped_planks
fill ~9~15~1 ~9~15~9 minecraft:warped_stairs 0
setblock ~10~12~1 minecraft:spruce_trapdoor 3
fill ~10~16~1 ~10~16~21 minecraft:warped_planks
fill ~10~17~1 ~10~17~21 minecraft:warped_stairs 0
setblock ~11~12~1 minecraft:spruce_stairs 4
fill ~11~18~1 ~11~18~21 minecraft:warped_planks
fill ~11~19~1 ~11~19~21 minecraft:warped_stairs 0
setblock ~12~8~1 minecraft:spruce_stairs 6
fill ~12~9~1 ~12~16~1 minecraft:stripped_spruce_log 0
setblock ~12~17~1 minecraft:stripped_spruce_log 2
fill ~12~18~1 ~12~19~1 minecraft:stripped_spruce_log 0
fill ~12~20~1 ~12~20~21 minecraft:warped_planks
fill ~13~9~1 ~15~9~1 minecraft:wooden_slab 1
setblock ~13~12~1 minecraft:spruce_stairs 5
fill ~13~18~1 ~13~18~21 minecraft:warped_planks
fill ~13~19~1 ~13~19~6 minecraft:warped_stairs 1
setblock ~14~12~1 minecraft:spruce_trapdoor 1
fill ~14~16~1 ~14~16~21 minecraft:warped_planks
fill ~14~17~1 ~14~17~5 minecraft:warped_stairs 1
setblock ~15~12~1 minecraft:spruce_stairs 4
fill ~15~14~1 ~15~14~4 minecraft:warped_planks
fill ~15~15~1 ~15~15~4 minecraft:warped_stairs 1
setblock ~16~8~1 minecraft:spruce_stairs 6
fill ~16~9~1 ~16~12~1 minecraft:stripped_spruce_log 0
fill ~16~13~1 ~16~13~4 minecraft:warped_stairs 1
fill ~17~12~1 ~17~12~4 minecraft:warped_planks
fill ~25~0~1 ~27~0~2 minecraft:grass_path
fill ~0~0~2 ~3~0~2 minecraft:grass
fill ~3~8~2 ~3~8~10 minecraft:wooden_slab 5
setblock ~4~0~2 minecraft:dirt 0
setblock ~4~1~2 minecraft:spruce_stairs 2
setblock ~4~8~2 minecraft:double_wooden_slab 5
fill ~5~0~2 ~7~0~2 minecraft:grass
setblock ~5~8~2 minecraft:wooden_slab 13
setblock ~5~9~2 minecraft:wooden_slab 5
setblock ~6~9~2 minecraft:double_wooden_slab 5
setblock ~7~9~2 minecraft:wooden_slab 13
setblock ~7~10~2 minecraft:wooden_slab 5
setblock ~8~0~2 minecraft:dirt 0
setblock ~8~1~2 minecraft:spruce_stairs 2
setblock ~8~4~2 minecraft:spruce_stairs 6
fill ~8~5~2 ~8~8~2 minecraft:stripped_spruce_log 0
fill ~8~9~2 ~8~9~9 minecraft:wooden_slab 1
setblock ~8~10~2 minecraft:double_wooden_slab 5
setblock ~8~12~2 minecraft:spruce_stairs 7
fill ~9~0~2 ~11~0~3 minecraft:grass
fill ~9~5~2 ~11~6~2 minecraft:wooden_slab 1
setblock ~9~8~2 minecraft:spruce_stairs 5
fill ~9~9~2 ~11~9~3 minecraft:quartz_block 3
fill ~9~10~2 ~9~13~9 minecraft:quartz_block 3
setblock ~10~8~2 minecraft:spruce_trapdoor 3
fill ~10~10~2 ~10~11~2 minecraft:glass_pane
fill ~10~12~2 ~15~13~2 minecraft:quartz_block 3
fill ~10~14~2 ~14~15~2 minecraft:quartz_block 3
setblock ~11~8~2 minecraft:spruce_stairs 4
fill ~11~10~2 ~13~11~2 minecraft:quartz_block 3
fill ~11~16~2 ~13~17~2 minecraft:quartz_block 3
fill ~12~0~2 ~12~0~4 minecraft:dirt 0
setblock ~12~1~2 minecraft:spruce_stairs 2
setblock ~12~4~2 minecraft:spruce_stairs 6
fill ~12~5~2 ~12~8~2 minecraft:stripped_spruce_log 0
fill ~12~18~2 ~12~19~2 minecraft:quartz_block 3
fill ~13~0~2 ~15~0~3 minecraft:grass
fill ~13~5~2 ~15~6~2 minecraft:wooden_slab 1
setblock ~13~8~2 minecraft:spruce_stairs 5
fill ~13~9~2 ~15~9~3 minecraft:quartz_block 3
setblock ~14~8~2 minecraft:spruce_trapdoor 3
fill ~14~10~2 ~14~11~2 minecraft:glass_pane
setblock ~15~8~2 minecraft:spruce_stairs 4
fill ~15~10~2 ~15~11~5 minecraft:quartz_block 3
fill ~16~0~2 ~16~0~11 minecraft:dirt 0
setblock ~16~1~2 minecraft:spruce_stairs 2
setblock ~16~4~2 minecraft:spruce_stairs 6
fill ~16~5~2 ~16~8~2 minecraft:stripped_spruce_log 0
fill ~16~9~2 ~16~9~4 minecraft:wooden_slab 1
setblock ~16~12~2 minecraft:spruce_stairs 7
fill ~17~0~2 ~24~0~2 minecraft:grass
setblock ~24~1~2 minecraft:double_plant 2
fill ~0~0~3 ~2~0~29 minecraft:grass
setblock ~3~0~3 minecraft:dirt 0
setblock ~3~1~3 minecraft:spruce_stairs 0
fill ~4~0~3 ~4~7~3 minecraft:stripped_spruce_log 0
fill ~4~8~3 ~4~8~11 minecraft:warped_planks
setblock ~5~0~3 minecraft:stone_brick_stairs 3
fill ~5~4~3 ~7~4~3 minecraft:spruce_stairs 6
fill ~5~5~3 ~7~5~3 minecraft:lectern 0
fill ~5~6~3 ~7~6~3 minecraft:spruce_trapdoor 2
fill ~5~9~3 ~5~9~9 minecraft:warped_slab 0
setblock ~6~0~3 minecraft:normal_stone_stairs 3
fill ~6~9~3 ~6~9~11 minecraft:warped_slab 0
setblock ~7~0~3 minecraft:stone_brick_stairs 3
fill ~7~10~3 ~7~10~10 minecraft:warped_slab 0
fill ~8~0~3 ~8~4~3 minecraft:stripped_spruce_log 0
setblock ~8~8~3 minecraft:spruce_stairs 4
fill ~8~10~3 ~8~10~9 minecraft:warped_double_slab 0
setblock ~8~12~3 minecraft:wooden_slab 9
fill ~9~2~3 ~9~3~3 minecraft:spruce_trapdoor 3
setblock ~9~4~3 minecraft:spruce_stairs 5
fill ~9~5~3 ~15~8~3 minecraft:quartz_block 3
setblock ~10~4~3 minecraft:spruce_trapdoor 3
setblock ~11~4~3 minecraft:spruce_stairs 4
fill ~12~1~3 ~12~4~3 minecraft:stripped_spruce_log 0
setblock ~12~9~3 minecraft:quartz_block 3
setblock ~13~4~3 minecraft:spruce_stairs 5
setblock ~14~4~3 minecraft:spruce_trapdoor 3
setblock ~15~4~3 minecraft:spruce_stairs 4
fill ~15~12~3 ~15~13~5 minecraft:quartz_block 3
fill ~16~1~3 ~16~4~3 minecraft:stripped_spruce_log 0
fill ~16~5~3 ~16~5~11 minecraft:wooden_slab 1
fill ~16~7~3 ~16~7~4 minecraft:wooden_slab 13
setblock ~16~8~3 minecraft:spruce_stairs 5
setblock ~16~12~3 minecraft:spruce_trapdoor 3
fill ~17~0~3 ~19~0~3 minecraft:dirt 0
fill ~17~1~3 ~18~1~3 minecraft:spruce_stairs 2
fill ~17~7~3 ~17~7~11 minecraft:wooden_slab 5
fill ~18~6~3 ~18~6~11 minecraft:wooden_slab 13
setblock ~19~1~3 minecraft:stripped_spruce_log 0
fill ~19~2~3 ~19~5~3 minecraft:fence 1
fill ~19~6~3 ~19~6~10 minecraft:wooden_slab 5
fill ~20~0~3 ~29~0~11 minecraft:grass
fill ~20~5~3 ~20~5~10 minecraft:wooden_slab 13
fill ~3~0~4 ~3~0~6 minecraft:grass
setblock ~4~0~4 minecraft:stone_brick_stairs 1
fill ~4~4~4 ~4~4~6 minecraft:spruce_stairs 4
fill ~4~5~4 ~4~5~6 minecraft:lectern 3
fill ~4~6~4 ~4~6~6 minecraft:spruce_trapdoor 0
setblock ~5~0~4 minecraft:stone 0
fill ~5~4~4 ~8~4~9 minecraft:planks 1
setblock ~6~0~4 minecraft:stonebrick 0
setblock ~7~0~4 minecraft:stone 0
setblock ~8~0~4 minecraft:stonebrick 0
setblock ~8~8~4 minecraft:spruce_trapdoor 1
fill ~8~12~4 ~8~12~6 minecraft:spruce_trapdoor 1
fill ~9~0~4 ~11~0~4 minecraft:dirt 0
fill ~9~1~4 ~9~4~4 minecraft:stonebrick 0
fill ~9~5~4 ~9~5~6 minecraft:quartz_block 3
fill ~9~6~4 ~9~9~4 minecraft:quartz_block 3
fill ~10~1~4 ~11~1~4 minecraft:stone 0
fill ~10~2~4 ~10~3~4 minecraft:glass_pane
fill ~10~4~4 ~11~4~4 minecraft:stone 0
fill ~10~5~4 ~13~8~4 minecraft:chest 3
fill ~10~9~4 ~14~9~18 minecraft:wooden_slab 9
fill ~11~2~4 ~12~2~4 minecraft:stonebrick 0
setblock ~11~3~4 minecraft:stonebrick 0
setblock ~12~1~4 minecraft:stonebrick 0
fill ~12~3~4 ~14~3~4 minecraft:stone 0
fill ~12~4~4 ~14~4~4 minecraft:stonebrick 0
fill ~13~0~4 ~15~0~4 minecraft:dirt 0
fill ~13~1~4 ~13~2~4 minecraft:stone 0
fill ~14~1~4 ~15~1~4 minecraft:stonebrick 0
setblock ~14~2~4 minecraft:stonebrick 0
fill ~14~5~4 ~15~8~4 minecraft:quartz_block 3
setblock ~15~2~4 minecraft:stone 0
setblock ~15~3~4 minecraft:stonebrick 0
fill ~15~4~4 ~15~4~6 minecraft:stone 0
fill ~15~9~4 ~15~9~11 minecraft:quartz_block 3
fill ~16~1~4 ~18~1~6 minecraft:planks 1
setblock ~16~2~4 minecraft:spruce_trapdoor
setblock ~16~3~4 minecraft:spruce_trapdoor
setblock ~16~4~4 minecraft:spruce_stairs 7
setblock ~16~8~4 minecraft:spruce_trapdoor 3
setblock ~16~12~4 minecraft:spruce_stairs 6
fill ~16~14~4 ~18~14~4 minecraft:dark_oak_stairs 2
fill ~17~0~4 ~18~0~11 minecraft:dirt 0
fill ~19~0~4 ~19~0~6 minecraft:grass
fill ~19~1~4 ~19~1~6 minecraft:spruce_stairs 5
fill ~19~2~4 ~19~2~6 minecraft:spruce_fence_gate 3
setblock ~19~4~4 minecraft:spruce_fence_gate 1
fill ~19~5~4 ~19~5~6 minecraft:spruce_fence_gate 3
setblock ~4~0~5 minecraft:normal_stone_stairs 1
setblock ~5~0~5 minecraft:stonebrick 0
setblock ~6~0~5 minecraft:stone 0
setblock ~7~0~5 minecraft:stonebrick 0
setblock ~8~0~5 minecraft:stone 0
setblock ~8~8~5 minecraft:spruce_stairs 4
setblock ~9~0~5 minecraft:stonebrick 0
setblock ~9~1~5 minecraft:spruce_door 2
fill ~9~3~5 ~9~3~8 minecraft:stonebrick 0
setblock ~9~4~5 minecraft:stone 0
fill ~9~6~5 ~9~7~5 minecraft:glass_pane
fill ~9~8~5 ~9~9~9 minecraft:quartz_block 3
fill ~10~0~5 ~14~0~17 minecraft:planks 1
fill ~10~4~5 ~14~4~16 minecraft:wooden_slab 9
setblock ~10~8~5 minecraft:torch 1
fill ~14~5~5 ~14~8~10 minecraft:chest 4
fill ~15~0~5 ~15~0~11 minecraft:dirt 0
fill ~15~1~5 ~15~1~6 minecraft:stone 0
fill ~15~2~5 ~15~3~5 minecraft:glass_pane
fill ~15~5~5 ~15~8~11 minecraft:quartz_block 3
fill ~15~15~5 ~17~15~5 minecraft:warped_planks
fill ~15~16~5 ~17~16~5 minecraft:warped_stairs 2
setblock ~16~4~5 minecraft:spruce_trapdoor 2
setblock ~16~7~5 minecraft:wooden_slab 9
fill ~16~8~5 ~17~8~5 minecraft:spruce_stairs 5
fill ~16~9~5 ~16~10~9 minecraft:quartz_block 3
fill ~16~11~5 ~16~14~6 minecraft:quartz_block 3
fill ~17~9~5 ~17~14~5 minecraft:stripped_spruce_log 0
setblock ~18~14~5 minecraft:dark_oak_stairs 7
setblock ~18~15~5 minecraft:planks 5
setblock ~18~16~5 minecraft:dark_oak_stairs 2
fill ~19~4~5 ~19~4~6 minecraft:spruce_fence_gate 3
setblock ~4~0~6 minecraft:stone_brick_stairs 1
setblock ~5~0~6 minecraft:stone 0
setblock ~6~0~6 minecraft:stonebrick 0
setblock ~7~0~6 minecraft:stone 0
setblock ~8~0~6 minecraft:stonebrick 0
setblock ~8~8~6 minecraft:spruce_trapdoor 1
fill ~9~0~6 ~9~0~12 minecraft:dirt 0
fill ~9~1~6 ~9~2~6 minecraft:stone 0
setblock ~9~4~6 minecraft:stonebrick 0
fill ~9~6~6 ~9~7~6 minecraft:quartz_block 3
fill ~14~17~6 ~17~17~6 minecraft:warped_planks
fill ~14~18~6 ~17~18~6 minecraft:warped_stairs 2
fill ~15~2~6 ~15~2~7 minecraft:stonebrick 0
setblock ~15~3~6 minecraft:stonebrick 0
setblock ~15~15~6 minecraft:warped_stairs 3
setblock ~16~4~6 minecraft:spruce_stairs 6
fill ~16~7~6 ~16~7~8 minecraft:double_wooden_slab 5
setblock ~16~8~6 minecraft:spruce_trapdoor 3
fill ~16~15~6 ~16~16~8 minecraft:quartz_block 3
fill ~17~9~6 ~17~10~8 minecraft:wooden_slab 9
setblock ~18~16~6 minecraft:dark_oak_stairs 7
setblock ~18~17~6 minecraft:planks 5
setblock ~18~18~6 minecraft:dark_oak_stairs 2
setblock ~3~0~7 minecraft:dirt 0
setblock ~3~1~7 minecraft:spruce_stairs 0
setblock ~4~0~7 minecraft:normal_stone_stairs 1
fill ~4~1~7 ~4~5~7 minecraft:stripped_spruce_log 0
setblock ~4~6~7 minecraft:wooden_slab 1
setblock ~5~0~7 minecraft:stonebrick 0
setblock ~6~0~7 minecraft:stone 0
setblock ~7~0~7 minecraft:stonebrick 0
setblock ~8~0~7 minecraft:stone 0
setblock ~8~8~7 minecraft:spruce_stairs 4
setblock ~8~12~7 minecraft:spruce_trapdoor 3
fill ~9~1~7 ~9~1~8 minecraft:stonebrick 0
setblock ~9~2~7 minecraft:stonebrick 0
fill ~9~4~7 ~9~4~9 minecraft:stone 0
setblock ~9~5~7 minecraft:spruce_door 2
setblock ~9~7~7 minecraft:smooth_quartz_stairs 7
fill ~13~19~7 ~17~19~7 minecraft:warped_planks
setblock ~14~17~7 minecraft:warped_stairs 1
fill ~15~1~7 ~15~1~8 minecraft:stonebrick 0
setblock ~15~3~7 minecraft:stone 0
setblock ~15~4~7 minecraft:stonebrick 0
fill ~15~15~7 ~15~15~8 minecraft:warped_stairs 1
fill ~16~1~7 ~16~4~7 minecraft:stripped_spruce_log 0
setblock ~16~8~7 minecraft:spruce_stairs 5
fill ~16~11~7 ~16~14~7 minecraft:glass_pane
fill ~16~17~7 ~16~18~7 minecraft:quartz_block 3
fill ~17~1~7 ~18~1~10 minecraft:planks 1
setblock ~18~18~7 minecraft:dark_oak_stairs 5
setblock ~18~19~7 minecraft:planks 5
setblock ~18~20~7 minecraft:dark_oak_stairs 0
fill ~19~0~7 ~19~0~8 minecraft:dirt 0
setblock ~19~1~7 minecraft:stripped_spruce_log 0
fill ~19~2~7 ~19~5~7 minecraft:fence 1
setblock ~19~20~7 minecraft:dark_oak_stairs 5
fill ~3~0~8 ~3~0~10 minecraft:grass
setblock ~4~0~8 minecraft:stone_brick_stairs 1
fill ~4~4~8 ~4~4~10 minecraft:spruce_stairs 4
fill ~4~5~8 ~4~5~10 minecraft:lectern 3
fill ~4~6~8 ~4~6~10 minecraft:spruce_trapdoor 0
setblock ~5~0~8 minecraft:stone 0
setblock ~6~0~8 minecraft:stonebrick 0
setblock ~7~0~8 minecraft:stone 0
setblock ~8~0~8 minecraft:stonebrick 0
setblock ~8~8~8 minecraft:spruce_trapdoor 1
setblock ~8~12~8 minecraft:wooden_slab 9
setblock ~9~2~8 minecraft:stone 0
setblock ~9~5~8 minecraft:spruce_door 2
setblock ~9~7~8 minecraft:smooth_quartz_stairs 6
fill ~13~19~8 ~13~19~21 minecraft:warped_stairs 1
fill ~14~17~8 ~17~17~8 minecraft:warped_planks
fill ~14~18~8 ~17~18~8 minecraft:warped_stairs 3
setblock ~15~2~8 minecraft:stone 0
setblock ~15~3~8 minecraft:stonebrick 0
setblock ~15~4~8 minecraft:stone 0
fill ~16~1~8 ~16~1~10 minecraft:planks 1
setblock ~16~4~8 minecraft:spruce_stairs 7
setblock ~16~8~8 minecraft:spruce_trapdoor 3
fill ~16~11~8 ~16~12~9 minecraft:quartz_block 3
fill ~16~13~8 ~16~14~8 minecraft:quartz_block 3
setblock ~18~16~8 minecraft:dark_oak_stairs 6
setblock ~18~17~8 minecraft:planks 5
setblock ~18~18~8 minecraft:dark_oak_stairs 3
fill ~19~1~8 ~19~1~10 minecraft:spruce_stairs 5
setblock ~19~2~8 minecraft:spruce_fence_gate 3
fill ~19~4~8 ~19~4~10 minecraft:spruce_fence_gate 3
setblock ~19~5~8 minecraft:spruce_fence_gate 3
fill ~2~9~9 ~4~9~9 minecraft:wooden_slab 5
setblock ~4~0~9 minecraft:normal_stone_stairs 1
setblock ~5~0~9 minecraft:stonebrick 0
setblock ~6~0~9 minecraft:stone 0
setblock ~7~0~9 minecraft:stonebrick 0
setblock ~8~0~9 minecraft:stone 0
setblock ~8~8~9 minecraft:spruce_stairs 4
setblock ~8~12~9 minecraft:spruce_stairs 6
setblock ~9~1~9 minecraft:stone 0
fill ~9~2~9 ~9~2~12 minecraft:stonebrick 0
setblock ~9~3~9 minecraft:stone 0
fill ~9~5~9 ~9~7~9 minecraft:quartz_block 3
setblock ~14~1~9 minecraft:spruce_stairs 0
fill ~14~17~9 ~14~17~14 minecraft:warped_stairs 1
setblock ~15~1~9 minecraft:stone 0
setblock ~15~2~9 minecraft:spruce_door 0
setblock ~15~4~9 minecraft:stonebrick 0
fill ~15~10~9 ~15~11~11 minecraft:quartz_block 3
fill ~15~12~9 ~15~12~10 minecraft:quartz_block 3
setblock ~15~13~9 minecraft:quartz_block 3
fill ~15~15~9 ~17~15~9 minecraft:warped_planks
fill ~15~16~9 ~17~16~9 minecraft:warped_stairs 3
setblock ~16~4~9 minecraft:spruce_trapdoor 2
fill ~16~7~9 ~16~8~9 minecraft:spruce_stairs 5
setblock ~16~14~9 minecraft:quartz_block 3
setblock ~17~8~9 minecraft:spruce_stairs 5
fill ~17~9~9 ~17~14~9 minecraft:stripped_spruce_log 0
fill ~18~9~9 ~20~9~9 minecraft:wooden_slab 5
setblock ~18~14~9 minecraft:dark_oak_stairs 6
setblock ~18~15~9 minecraft:planks 5
setblock ~18~16~9 minecraft:dark_oak_stairs 3
fill ~19~0~9 ~19~0~10 minecraft:grass
setblock ~19~2~9 minecraft:spruce_fence_gate 3
setblock ~19~5~9 minecraft:fence 1
setblock ~29~1~9 minecraft:tallgrass 1
setblock ~0~1~10 minecraft:tallgrass 1
setblock ~2~9~10 minecraft:planks 5
fill ~3~9~10 ~5~9~10 minecraft:warped_planks
setblock ~4~0~10 minecraft:stone_brick_stairs 1
setblock ~5~0~10 minecraft:stone 0
fill ~5~4~10 ~7~4~11 minecraft:planks 1
setblock ~6~0~10 minecraft:stonebrick 0
setblock ~7~0~10 minecraft:stone 0
fill ~8~0~10 ~8~18~10 minecraft:stonebrick 0
setblock ~8~19~10 minecraft:stone_brick_stairs 0
fill ~8~20~10 ~9~21~12 minecraft:stonebrick 0
setblock ~8~22~10 minecraft:stone_brick_stairs 2
fill ~8~23~10 ~9~23~12 minecraft:stonebrick 0
fill ~9~1~10 ~9~1~11 minecraft:stonebrick 0
fill ~9~3~10 ~9~18~12 minecraft:stonebrick 0
setblock ~9~19~10 minecraft:stone_brick_stairs 2
fill ~9~22~10 ~9~22~11 minecraft:stone_brick_stairs 1
setblock ~15~1~10 minecraft:stonebrick 0
fill ~15~2~10 ~15~2~11 minecraft:stone 0
fill ~15~3~10 ~15~3~11 minecraft:stonebrick 0
setblock ~15~4~10 minecraft:stone 0
fill ~15~13~10 ~15~14~13 minecraft:warped_planks
fill ~15~15~10 ~15~15~13 minecraft:warped_stairs 1
setblock ~16~4~10 minecraft:spruce_stairs 6
fill ~16~7~10 ~16~7~11 minecraft:double_wooden_slab 5
setblock ~16~8~10 minecraft:spruce_trapdoor
fill ~16~9~10 ~19~9~10 minecraft:warped_planks
fill ~16~13~10 ~16~13~12 minecraft:warped_stairs 1
fill ~16~14~10 ~18~14~10 minecraft:dark_oak_stairs 3
fill ~17~12~10 ~17~12~12 minecraft:warped_planks
fill ~18~11~10 ~18~11~11 minecraft:wooden_slab 13
setblock ~19~2~10 minecraft:spruce_fence_gate 3
setblock ~19~5~10 minecraft:spruce_fence_gate 3
setblock ~20~9~10 minecraft:planks 5
setblock ~2~9~11 minecraft:wooden_slab 13
setblock ~2~10~11 minecraft:dark_oak_stairs 2
fill ~3~0~11 ~4~0~11 minecraft:dirt 0
setblock ~3~1~11 minecraft:spruce_stairs 0
setblock ~3~4~11 minecraft:spruce_stairs 4
fill ~3~5~11 ~4~5~11 minecraft:stripped_spruce_log 0
fill ~3~6~11 ~3~9~11 minecraft:stripped_spruce_log 0
fill ~3~10~11 ~7~10~11 minecraft:warped_stairs 2
fill ~4~1~11 ~4~4~11 minecraft:stripped_spruce_log 0
setblock ~4~6~11 minecraft:wooden_slab 1
setblock ~5~0~11 minecraft:stonebrick 0
setblock ~5~9~11 minecraft:warped_slab 0
setblock ~6~0~11 minecraft:stone 0
setblock ~7~0~11 minecraft:stonebrick 0
fill ~8~0~11 ~8~0~12 minecraft:dirt 0
fill ~8~1~11 ~8~15~12 minecraft:stonebrick 0
fill ~8~16~11 ~8~16~12 minecraft:stone_brick_stairs 0
fill ~8~17~11 ~8~19~12 minecraft:stonebrick 0
fill ~8~22~11 ~8~22~12 minecraft:stone_brick_stairs 0
fill ~9~19~11 ~9~19~12 minecraft:stonebrick 0
setblock ~14~8~11 minecraft:torch 2
setblock ~15~1~11 minecraft:stone 0
setblock ~15~4~11 minecraft:stonebrick 0
fill ~15~12~11 ~15~12~12 minecraft:warped_planks
fill ~16~1~11 ~16~4~11 minecraft:stripped_spruce_log 0
fill ~16~8~11 ~16~9~11 minecraft:spruce_stairs 5
fill ~16~10~11 ~19~10~11 minecraft:warped_stairs 2
setblock ~17~1~11 minecraft:planks 1
setblock ~17~4~11 minecraft:spruce_stairs 6
fill ~17~5~11 ~18~5~11 minecraft:wooden_slab 1
setblock ~17~9~11 minecraft:spruce_trapdoor 3
fill ~18~1~11 ~19~1~11 minecraft:stripped_spruce_log 0
fill ~18~2~11 ~18~4~11 minecraft:stripped_spruce_log 0
setblock ~18~9~11 minecraft:spruce_stairs 4
setblock ~19~0~11 minecraft:dirt 0
fill ~19~2~11 ~19~3~11 minecraft:fence 1
setblock ~19~4~11 minecraft:spruce_stairs 5
fill ~19~5~11 ~19~9~11 minecraft:stripped_spruce_log 0
setblock ~20~9~11 minecraft:wooden_slab 13
setblock ~20~10~11 minecraft:dark_oak_stairs 2
setblock ~2~10~12 minecraft:dark_oak_stairs 7
setblock ~2~11~12 minecraft:planks 5
setblock ~2~12~12 minecraft:dark_oak_stairs 2
fill ~3~0~12 ~4~0~14 minecraft:grass
fill ~3~5~12 ~3~6~14 minecraft:wooden_slab 1
setblock ~3~9~12 minecraft:spruce_stairs 7
fill ~3~11~12 ~7~11~12 minecraft:warped_planks
fill ~3~12~12 ~6~12~12 minecraft:warped_stairs 2
setblock ~4~4~12 minecraft:spruce_stairs 7
fill ~4~5~12 ~7~10~12 minecraft:quartz_block 3
fill ~5~0~12 ~7~0~12 minecraft:dirt 0
fill ~5~1~12 ~7~1~12 minecraft:stonebrick 0
fill ~5~2~12 ~6~2~12 minecraft:stone 0
fill ~5~3~12 ~7~3~12 minecraft:stonebrick 0
fill ~5~4~12 ~5~4~13 minecraft:stonebrick 0
fill ~6~4~12 ~6~4~17 minecraft:wooden_slab 9
setblock ~7~2~12 minecraft:stonebrick 0
setblock ~7~4~12 minecraft:stonebrick 0
setblock ~9~1~12 minecraft:stone 0
setblock ~9~22~12 minecraft:stone_brick_stairs 3
fill ~15~0~12 ~16~0~17 minecraft:planks 1
fill ~15~4~12 ~16~4~16 minecraft:wooden_slab 9
fill ~15~9~12 ~15~9~18 minecraft:wooden_slab 9
fill ~16~5~12 ~18~10~12 minecraft:quartz_block 3
fill ~16~11~12 ~19~11~12 minecraft:warped_planks
setblock ~16~12~12 minecraft:warped_stairs 2
fill ~17~0~12 ~17~0~18 minecraft:dirt 0
fill ~17~1~12 ~17~1~13 minecraft:stone 0
fill ~17~2~12 ~17~4~12 minecraft:stonebrick 0
fill ~18~0~12 ~27~0~14 minecraft:grass
fill ~18~2~12 ~18~3~12 minecraft:spruce_trapdoor
setblock ~18~4~12 minecraft:spruce_stairs 7
fill ~18~12~12 ~19~12~12 minecraft:warped_stairs 2
fill ~19~5~12 ~19~6~14 minecraft:wooden_slab 1
setblock ~19~7~12 minecraft:spruce_trapdoor
setblock ~19~8~12 minecraft:spruce_trapdoor
setblock ~19~9~12 minecraft:spruce_stairs 7
setblock ~20~10~12 minecraft:dark_oak_stairs 7
setblock ~20~11~12 minecraft:planks 5
setblock ~20~12~12 minecraft:dark_oak_stairs 2
fill ~28~0~12 ~29~0~29 minecraft:dirt 0
fill ~28~1~12 ~29~1~29 minecraft:grass
setblock ~2~12~13 minecraft:dark_oak_stairs 7
setblock ~2~13~13 minecraft:planks 5
setblock ~2~14~13 minecraft:dark_oak_stairs 2
setblock ~3~9~13 minecraft:spruce_trapdoor 1
fill ~3~13~13 ~7~13~13 minecraft:warped_planks
fill ~3~14~13 ~8~14~13 minecraft:warped_stairs 2
setblock ~4~4~13 minecraft:spruce_trapdoor 1
fill ~4~5~13 ~4~6~18 minecraft:quartz_block 3
fill ~4~7~13 ~4~8~13 minecraft:glass_pane
fill ~4~9~13 ~4~10~18 minecraft:quartz_block 3
fill ~4~11~13 ~4~12~17 minecraft:quartz_block 3
fill ~5~0~13 ~5~0~18 minecraft:dirt 0
setblock ~5~1~13 minecraft:stone 0
fill ~5~2~13 ~5~3~13 minecraft:glass_pane
fill ~5~5~13 ~8~7~13 minecraft:bookshelf
fill ~5~9~13 ~9~9~17 minecraft:wooden_slab 9
fill ~6~0~13 ~9~0~17 minecraft:planks 1
fill ~7~4~13 ~9~4~17 minecraft:wooden_slab 9
fill ~8~13~13 ~8~13~16 minecraft:warped_stairs 0
fill ~9~14~13 ~9~14~21 minecraft:warped_planks
setblock ~9~15~13 minecraft:warped_stairs 0
fill ~16~9~13 ~17~9~17 minecraft:wooden_slab 9
fill ~16~13~13 ~19~13~13 minecraft:warped_planks
fill ~16~14~13 ~19~14~13 minecraft:warped_stairs 2
fill ~17~2~13 ~17~3~13 minecraft:glass_pane
setblock ~17~4~13 minecraft:stone 0
setblock ~17~5~13 minecraft:smoker 4
setblock ~18~4~13 minecraft:spruce_trapdoor
fill ~18~5~13 ~18~6~18 minecraft:quartz_block 3
fill ~18~7~13 ~18~8~13 minecraft:glass_pane
fill ~18~9~13 ~18~11~18 minecraft:quartz_block 3
fill ~18~12~13 ~18~12~17 minecraft:quartz_block 3
setblock ~19~9~13 minecraft:spruce_trapdoor
setblock ~20~12~13 minecraft:dark_oak_stairs 7
setblock ~20~13~13 minecraft:planks 5
setblock ~20~14~13 minecraft:dark_oak_stairs 2
setblock ~2~14~14 minecraft:dark_oak_stairs 7
setblock ~2~15~14 minecraft:planks 5
setblock ~2~16~14 minecraft:dark_oak_stairs 2
setblock ~3~9~14 minecraft:spruce_stairs 6
fill ~3~15~14 ~9~15~14 minecraft:warped_planks
fill ~3~16~14 ~9~16~14 minecraft:warped_stairs 2
setblock ~4~4~14 minecraft:spruce_stairs 6
fill ~4~7~14 ~4~8~16 minecraft:quartz_block 3
fill ~4~13~14 ~4~14~16 minecraft:quartz_block 3
fill ~5~1~14 ~5~3~14 minecraft:stonebrick 0
setblock ~5~4~14 minecraft:stone 0
fill ~5~5~14 ~5~7~17 minecraft:bookshelf
fill ~6~1~14 ~8~1~14 minecraft:wooden_slab 1
fill ~15~14~14 ~15~14~21 minecraft:warped_planks
fill ~15~15~14 ~19~15~14 minecraft:warped_planks
fill ~15~16~14 ~19~16~14 minecraft:warped_stairs 2
fill ~17~1~14 ~17~1~15 minecraft:stonebrick 0
setblock ~17~2~14 minecraft:stonebrick 0
fill ~17~3~14 ~17~3~15 minecraft:stone 0
fill ~17~4~14 ~17~4~15 minecraft:stonebrick 0
setblock ~17~5~14 minecraft:blast_furnace 4
setblock ~18~4~14 minecraft:spruce_stairs 6
fill ~18~7~14 ~18~8~16 minecraft:quartz_block 3
fill ~18~13~14 ~18~14~16 minecraft:quartz_block 3
setblock ~19~9~14 minecraft:spruce_stairs 6
setblock ~20~14~14 minecraft:dark_oak_stairs 7
setblock ~20~15~14 minecraft:planks 5
setblock ~20~16~14 minecraft:dark_oak_stairs 2
setblock ~1~17~15 minecraft:dark_oak_stairs 4
setblock ~2~16~15 minecraft:dark_oak_stairs 4
setblock ~2~17~15 minecraft:dark_oak_stairs 1
fill ~3~0~15 ~4~0~15 minecraft:dirt 0
setblock ~3~1~15 minecraft:spruce_stairs 0
setblock ~3~4~15 minecraft:spruce_stairs 4
fill ~3~5~15 ~3~13~15 minecraft:stripped_spruce_log 0
setblock ~3~14~15 minecraft:stripped_spruce_log 1
setblock ~3~15~15 minecraft:stripped_spruce_log 0
fill ~3~16~15 ~9~16~15 minecraft:warped_planks
fill ~4~1~15 ~4~4~15 minecraft:stripped_spruce_log 0
setblock ~4~15~15 minecraft:quartz_block 3
fill ~5~1~15 ~5~1~16 minecraft:stone 0
fill ~5~2~15 ~5~2~16 minecraft:stonebrick 0
fill ~5~3~15 ~5~3~16 minecraft:stone 0
setblock ~5~4~15 minecraft:stonebrick 0
setblock ~5~8~15 minecraft:torch 1
setblock ~6~1~15 minecraft:bed 1
setblock ~6~7~15 minecraft:grindstone 3
setblock ~7~5~15 minecraft:enchanting_table
fill ~8~1~15 ~8~1~16 minecraft:wooden_slab 1
setblock ~9~15~15 minecraft:warped_stairs 0
fill ~14~17~15 ~19~17~15 minecraft:warped_planks
setblock ~15~15~15 minecraft:warped_stairs 1
setblock ~17~2~15 minecraft:stone 0
setblock ~17~5~15 minecraft:crafting_table
fill ~18~0~15 ~19~0~15 minecraft:dirt 0
fill ~18~1~15 ~18~4~15 minecraft:stripped_spruce_log 0
fill ~18~15~15 ~18~16~15 minecraft:quartz_block 3
setblock ~19~1~15 minecraft:spruce_stairs 1
setblock ~19~4~15 minecraft:spruce_stairs 5
fill ~19~5~15 ~19~13~15 minecraft:stripped_spruce_log 0
setblock ~19~14~15 minecraft:stripped_spruce_log 1
fill ~19~15~15 ~19~16~15 minecraft:stripped_spruce_log 0
fill ~20~0~15 ~27~0~22 minecraft:grass
setblock ~20~16~15 minecraft:dark_oak_stairs 5
setblock ~20~17~15 minecraft:planks 5
setblock ~20~18~15 minecraft:dark_oak_stairs 0
setblock ~21~18~15 minecraft:dark_oak_stairs 5
setblock ~24~1~15 minecraft:torch 5
setblock ~2~1~16 minecraft:tallgrass 1
setblock ~2~14~16 minecraft:dark_oak_stairs 6
setblock ~2~15~16 minecraft:planks 5
setblock ~2~16~16 minecraft:dark_oak_stairs 3
fill ~3~0~16 ~4~0~18 minecraft:grass
fill ~3~5~16 ~3~6~18 minecraft:wooden_slab 1
setblock ~3~9~16 minecraft:spruce_stairs 7
fill ~3~15~16 ~9~15~16 minecraft:warped_planks
fill ~3~16~16 ~9~16~16 minecraft:warped_stairs 3
setblock ~4~4~16 minecraft:spruce_stairs 7
fill ~5~4~16 ~5~4~17 minecraft:stone 0
fill ~6~1~16 ~7~1~16 minecraft:wooden_slab 1
fill ~14~17~16 ~14~17~21 minecraft:warped_stairs 1
fill ~15~15~16 ~19~15~16 minecraft:warped_planks
fill ~15~16~16 ~19~16~16 minecraft:warped_stairs 3
setblock ~17~1~16 minecraft:stone 0
fill ~17~2~16 ~17~3~16 minecraft:stonebrick 0
fill ~17~4~16 ~17~4~17 minecraft:stone 0
setblock ~17~5~16 minecraft:anvil 0
fill ~18~0~16 ~19~0~18 minecraft:grass
setblock ~18~2~16 minecraft:spruce_trapdoor
setblock ~18~3~16 minecraft:spruce_trapdoor
setblock ~18~4~16 minecraft:spruce_stairs 7
fill ~19~5~16 ~19~6~18 minecraft:wooden_slab 1
setblock ~19~7~16 minecraft:spruce_trapdoor
setblock ~19~8~16 minecraft:spruce_trapdoor
setblock ~19~9~16 minecraft:spruce_stairs 7
setblock ~20~14~16 minecraft:dark_oak_stairs 6
setblock ~20~15~16 minecraft:planks 5
setblock ~20~16~16 minecraft:dark_oak_stairs 3
setblock ~2~12~17 minecraft:dark_oak_stairs 6
setblock ~2~13~17 minecraft:planks 5
setblock ~2~14~17 minecraft:dark_oak_stairs 3
setblock ~3~9~17 minecraft:spruce_trapdoor 1
fill ~3~13~17 ~8~13~17 minecraft:warped_planks
fill ~3~14~17 ~8~14~17 minecraft:warped_stairs 3
fill ~4~7~17 ~4~8~17 minecraft:glass_pane
fill ~5~1~17 ~5~1~18 minecraft:stonebrick 0
fill ~5~2~17 ~5~3~17 minecraft:glass_pane
fill ~6~5~17 ~8~7~17 minecraft:bookshelf
fill ~9~15~17 ~9~15~21 minecraft:warped_stairs 0
setblock ~10~2~17 minecraft:torch 4
setblock ~10~4~17 minecraft:wooden_slab 9
fill ~11~1~17 ~14~1~17 minecraft:barrel 2
fill ~11~2~17 ~13~2~17 minecraft:barrel 2
fill ~11~3~17 ~12~3~17 minecraft:barrel 2
fill ~11~4~17 ~11~4~18 minecraft:stonebrick 0
setblock ~12~4~17 minecraft:stone_brick_stairs 1
setblock ~13~3~17 minecraft:stone_brick_stairs 1
setblock ~14~2~17 minecraft:stone_brick_stairs 1
setblock ~15~1~17 minecraft:stone_brick_stairs 1
fill ~15~15~17 ~15~15~21 minecraft:warped_stairs 1
setblock ~16~4~17 minecraft:wooden_slab 9
fill ~16~13~17 ~19~13~17 minecraft:warped_planks
fill ~16~14~17 ~19~14~17 minecraft:warped_stairs 3
setblock ~17~1~17 minecraft:stonebrick 0
fill ~17~2~17 ~17~3~17 minecraft:glass_pane
setblock ~17~5~17 minecraft:jukebox
setblock ~18~4~17 minecraft:spruce_trapdoor
fill ~18~7~17 ~18~8~17 minecraft:glass_pane
setblock ~19~9~17 minecraft:spruce_trapdoor 3
setblock ~20~12~17 minecraft:dark_oak_stairs 6
setblock ~20~13~17 minecraft:planks 5
setblock ~20~14~17 minecraft:dark_oak_stairs 3
setblock ~2~10~18 minecraft:dark_oak_stairs 6
setblock ~2~11~18 minecraft:planks 5
setblock ~2~12~18 minecraft:dark_oak_stairs 3
setblock ~3~9~18 minecraft:spruce_stairs 6
fill ~3~11~18 ~8~11~18 minecraft:warped_planks
fill ~3~12~18 ~6~12~18 minecraft:warped_stairs 3
setblock ~4~2~18 minecraft:spruce_trapdoor 1
setblock ~4~3~18 minecraft:spruce_trapdoor 1
setblock ~4~4~18 minecraft:spruce_stairs 6
fill ~4~7~18 ~8~8~18 minecraft:quartz_block 3
setblock ~5~2~18 minecraft:stonebrick 0
setblock ~5~3~18 minecraft:stone 0
fill ~5~4~18 ~7~4~18 minecraft:stonebrick 0
fill ~5~5~18 ~8~6~18 minecraft:quartz_block 3
fill ~5~9~18 ~8~10~18 minecraft:quartz_block 3
fill ~6~0~18 ~16~0~18 minecraft:dirt 0
fill ~6~1~18 ~7~1~18 minecraft:stone 0
fill ~6~2~18 ~6~3~18 minecraft:glass_pane
setblock ~7~2~18 minecraft:stone 0
setblock ~7~3~18 minecraft:stonebrick 0
fill ~8~1~18 ~8~2~18 minecraft:stonebrick 0
fill ~8~3~18 ~10~3~18 minecraft:stone 0
setblock ~8~4~18 minecraft:stone 0
fill ~8~13~18 ~8~13~21 minecraft:warped_stairs 0
fill ~9~1~18 ~9~2~18 minecraft:stone 0
setblock ~9~4~18 minecraft:stonebrick 0
setblock ~9~8~18 minecraft:torch 1
setblock ~9~9~18 minecraft:wooden_slab 9
fill ~9~10~18 ~9~13~20 minecraft:quartz_block 3
fill ~10~1~18 ~12~1~18 minecraft:stonebrick 0
setblock ~10~2~18 minecraft:stonebrick 0
setblock ~10~4~18 minecraft:stone 0
setblock ~11~2~18 minecraft:stone 0
setblock ~11~3~18 minecraft:stonebrick 0
fill ~12~2~18 ~15~2~18 minecraft:stonebrick 0
fill ~12~3~18 ~15~3~18 minecraft:stone 0
fill ~12~4~18 ~13~4~18 minecraft:stonebrick 0
fill ~13~1~18 ~14~1~18 minecraft:stone 0
fill ~14~4~18 ~15~4~18 minecraft:stone 0
fill ~15~1~18 ~16~1~18 minecraft:stonebrick 0
setblock ~15~8~18 minecraft:torch 2
fill ~15~10~18 ~17~10~18 minecraft:quartz_block 3
fill ~15~11~18 ~15~11~20 minecraft:quartz_block 3
fill ~15~12~18 ~15~13~18 minecraft:warped_planks
fill ~16~2~18 ~17~2~18 minecraft:stone 0
fill ~16~3~18 ~17~4~18 minecraft:stonebrick 0
fill ~16~5~18 ~17~9~18 minecraft:quartz_block 3
setblock ~16~12~18 minecraft:warped_stairs 3
fill ~16~13~18 ~16~13~21 minecraft:warped_stairs 1
setblock ~17~1~18 minecraft:stone 0
fill ~17~12~18 ~17~12~21 minecraft:warped_stairs 5
setblock ~18~4~18 minecraft:spruce_stairs 6
fill ~18~7~18 ~18~8~18 minecraft:quartz_block 3
fill ~18~12~18 ~19~12~18 minecraft:warped_stairs 3
setblock ~19~9~18 minecraft:spruce_stairs 6
setblock ~20~11~18 minecraft:wooden_slab 13
setblock ~20~12~18 minecraft:dark_oak_stairs 3
setblock ~29~2~18 minecraft:tallgrass 1
setblock ~2~9~19 minecraft:wooden_slab 13
setblock ~2~10~19 minecraft:dark_oak_stairs 3
fill ~3~0~19 ~4~0~19 minecraft:dirt 0
setblock ~3~1~19 minecraft:spruce_stairs 0
setblock ~3~4~19 minecraft:spruce_stairs 4
fill ~3~5~19 ~3~9~19 minecraft:stripped_spruce_log 0
fill ~3~10~19 ~8~10~19 minecraft:warped_stairs 3
fill ~4~1~19 ~4~4~19 minecraft:stripped_spruce_log 0
fill ~4~5~19 ~8~6~19 minecraft:wooden_slab 1
setblock ~4~9~19 minecraft:spruce_stairs 5
fill ~5~0~19 ~7~0~29 minecraft:grass
setblock ~5~4~19 minecraft:spruce_stairs 5
setblock ~5~9~19 minecraft:wooden_slab 9
setblock ~6~4~19 minecraft:spruce_trapdoor
setblock ~6~9~19 minecraft:spruce_trapdoor 2
fill ~6~12~19 ~6~12~22 minecraft:wooden_slab 5
setblock ~7~4~19 minecraft:spruce_stairs 4
setblock ~7~9~19 minecraft:wooden_slab 9
fill ~8~0~19 ~8~0~20 minecraft:dirt 0
fill ~8~1~19 ~8~4~19 minecraft:stripped_spruce_log 0
setblock ~8~9~19 minecraft:spruce_stairs 4
setblock ~8~12~19 minecraft:spruce_stairs 7
fill ~9~0~19 ~11~0~29 minecraft:grass
setblock ~9~4~19 minecraft:spruce_stairs 5
fill ~9~5~19 ~15~5~19 minecraft:quartz_block 3
fill ~9~6~19 ~9~9~19 minecraft:quartz_block 3
setblock ~10~4~19 minecraft:spruce_trapdoor 1
fill ~10~6~19 ~10~7~19 minecraft:glass_pane
fill ~10~8~19 ~15~9~19 minecraft:quartz_block 3
setblock ~11~4~19 minecraft:spruce_stairs 4
fill ~11~6~19 ~13~7~19 minecraft:quartz_block 3
fill ~12~0~19 ~12~0~20 minecraft:dirt 0
fill ~12~1~19 ~12~4~19 minecraft:stripped_spruce_log 0
fill ~13~0~19 ~15~0~29 minecraft:grass
setblock ~13~4~19 minecraft:spruce_stairs 5
setblock ~14~4~19 minecraft:spruce_trapdoor 2
fill ~14~6~19 ~14~7~19 minecraft:glass_pane
setblock ~15~4~19 minecraft:spruce_stairs 4
fill ~15~6~19 ~15~7~19 minecraft:quartz_block 3
fill ~15~10~19 ~15~10~20 minecraft:quartz_block 3
fill ~15~12~19 ~15~12~20 minecraft:quartz_block 3
fill ~15~13~19 ~15~13~20 minecraft:warped_planks
fill ~16~0~19 ~16~0~20 minecraft:dirt 0
fill ~16~1~19 ~16~4~19 minecraft:stripped_spruce_log 0
setblock ~16~8~19 minecraft:warped_stairs 7
fill ~16~9~19 ~16~10~19 minecraft:warped_stairs 3
fill ~16~11~19 ~19~11~19 minecraft:warped_planks
setblock ~16~12~19 minecraft:spruce_stairs 7
fill ~17~0~19 ~17~0~29 minecraft:grass
setblock ~17~4~19 minecraft:spruce_stairs 7
fill ~17~5~19 ~18~6~19 minecraft:wooden_slab 9
fill ~18~0~19 ~19~0~19 minecraft:dirt 0
fill ~18~1~19 ~18~4~19 minecraft:stripped_spruce_log 0
setblock ~18~10~19 minecraft:quartz_block 3
fill ~18~12~19 ~18~12~22 minecraft:wooden_slab 5
setblock ~19~1~19 minecraft:spruce_stairs 1
setblock ~19~4~19 minecraft:spruce_stairs 5
fill ~19~5~19 ~19~9~19 minecraft:stripped_spruce_log 0
setblock ~20~10~19 minecraft:dark_oak_stairs 6
setblock ~20~11~19 minecraft:planks 5
setblock ~24~1~19 minecraft:torch 5
setblock ~2~9~20 minecraft:double_wooden_slab 5
fill ~3~0~20 ~3~0~29 minecraft:grass
fill ~3~9~20 ~8~9~20 minecraft:warped_planks
setblock ~4~0~20 minecraft:dirt 0
setblock ~4~1~20 minecraft:spruce_stairs 3
setblock ~8~1~20 minecraft:spruce_stairs 3
setblock ~8~4~20 minecraft:spruce_stairs 7
fill ~8~5~20 ~8~8~20 minecraft:stripped_spruce_log 0
setblock ~8~12~20 minecraft:spruce_stairs 6
fill ~9~5~20 ~11~5~20 minecraft:wooden_slab 1
setblock ~9~8~20 minecraft:spruce_stairs 5
fill ~9~9~20 ~15~9~20 minecraft:quartz_block 3
setblock ~10~8~20 minecraft:spruce_trapdoor
fill ~10~10~20 ~14~15~20 minecraft:quartz_block 3
setblock ~11~8~20 minecraft:spruce_stairs 4
fill ~11~16~20 ~13~17~20 minecraft:quartz_block 3
setblock ~12~1~20 minecraft:spruce_stairs 3
setblock ~12~4~20 minecraft:spruce_stairs 7
fill ~12~5~20 ~12~8~20 minecraft:stripped_spruce_log 0
setblock ~12~18~20 minecraft:quartz_block 3
fill ~13~5~20 ~15~5~20 minecraft:wooden_slab 1
setblock ~13~8~20 minecraft:spruce_stairs 5
setblock ~14~8~20 minecraft:spruce_trapdoor
setblock ~15~6~20 minecraft:spruce_trapdoor 2
setblock ~15~7~20 minecraft:spruce_trapdoor 2
setblock ~15~8~20 minecraft:spruce_stairs 4
setblock ~16~1~20 minecraft:spruce_stairs 3
setblock ~16~4~20 minecraft:spruce_stairs 7
fill ~16~5~20 ~16~8~20 minecraft:stripped_spruce_log 0
fill ~16~10~20 ~19~10~20 minecraft:warped_stairs 3
setblock ~16~12~20 minecraft:spruce_stairs 6
fill ~17~9~20 ~19~9~20 minecraft:warped_planks
setblock ~18~0~20 minecraft:dirt 0
setblock ~18~1~20 minecraft:spruce_stairs 3
fill ~19~0~20 ~19~0~29 minecraft:grass
setblock ~20~9~20 minecraft:planks 5
setblock ~20~10~20 minecraft:dark_oak_stairs 3
setblock ~2~9~21 minecraft:wooden_slab 5
fill ~4~0~21 ~4~0~29 minecraft:grass
fill ~8~0~21 ~8~0~29 minecraft:grass
setblock ~8~8~21 minecraft:spruce_stairs 7
fill ~8~9~21 ~8~12~21 minecraft:stripped_spruce_log 0
fill ~9~9~21 ~11~9~21 minecraft:wooden_slab 1
setblock ~9~12~21 minecraft:spruce_stairs 5
setblock ~10~12~21 minecraft:spruce_trapdoor 1
setblock ~11~12~21 minecraft:spruce_stairs 4
fill ~12~0~21 ~12~0~29 minecraft:grass
setblock ~12~8~21 minecraft:spruce_stairs 7
fill ~12~9~21 ~12~16~21 minecraft:stripped_spruce_log 0
setblock ~12~17~21 minecraft:stripped_spruce_log 2
fill ~12~18~21 ~12~19~21 minecraft:stripped_spruce_log 0
fill ~13~9~21 ~15~9~21 minecraft:wooden_slab 1
setblock ~13~12~21 minecraft:spruce_stairs 5
setblock ~14~12~21 minecraft:spruce_trapdoor
setblock ~15~12~21 minecraft:spruce_stairs 4
fill ~16~0~21 ~16~0~29 minecraft:grass
setblock ~16~8~21 minecraft:spruce_stairs 7
fill ~16~9~21 ~16~12~21 minecraft:stripped_spruce_log 0
fill ~17~9~21 ~20~9~21 minecraft:wooden_slab 5
fill ~18~0~21 ~18~0~29 minecraft:grass
fill ~24~1~21 ~25~1~21 minecraft:torch 5
setblock ~0~1~22 minecraft:standing_sign 2
setblock ~7~12~22 minecraft:planks 5
setblock ~8~12~22 minecraft:wooden_slab 13
setblock ~8~13~22 minecraft:dark_oak_stairs 0
setblock ~9~13~22 minecraft:dark_oak_stairs 5
setblock ~9~14~22 minecraft:planks 5
setblock ~9~15~22 minecraft:dark_oak_stairs 0
setblock ~10~15~22 minecraft:dark_oak_stairs 5
setblock ~10~16~22 minecraft:planks 5
setblock ~10~17~22 minecraft:dark_oak_stairs 0
setblock ~11~17~22 minecraft:dark_oak_stairs 5
setblock ~11~18~22 minecraft:planks 5
setblock ~11~19~22 minecraft:dark_oak_stairs 0
setblock ~12~19~22 minecraft:dark_oak_stairs 7
setblock ~12~20~22 minecraft:planks 5
setblock ~12~21~22 minecraft:dark_oak_stairs 2
setblock ~13~17~22 minecraft:dark_oak_stairs 4
setblock ~13~18~22 minecraft:planks 5
setblock ~13~19~22 minecraft:dark_oak_stairs 1
setblock ~14~15~22 minecraft:dark_oak_stairs 4
setblock ~14~16~22 minecraft:planks 5
setblock ~14~17~22 minecraft:dark_oak_stairs 1
setblock ~15~13~22 minecraft:dark_oak_stairs 4
setblock ~15~14~22 minecraft:planks 5
setblock ~15~15~22 minecraft:dark_oak_stairs 1
setblock ~16~12~22 minecraft:wooden_slab 13
setblock ~16~13~22 minecraft:dark_oak_stairs 1
setblock ~17~12~22 minecraft:planks 5
setblock ~12~21~23 minecraft:dark_oak_stairs 7
fill ~20~0~23 ~26~0~23 minecraft:grass
fill ~27~0~23 ~27~0~29 minecraft:dirt 0
fill ~27~1~23 ~27~1~29 minecraft:grass
fill ~20~0~24 ~25~0~29 minecraft:grass
fill ~26~0~24 ~26~0~29 minecraft:dirt 0
fill ~26~1~24 ~26~1~29 minecraft:grass
