fill ~54 ~0 ~4 ~80 ~0 ~4 stained_glass 15
fill ~54 ~0 ~5 ~84 ~0 ~5 stained_glass 15
fill ~82 ~0 ~6 ~85 ~0 ~6 stained_glass 15
fill ~14 ~1 ~22 ~23 ~1 ~22 stained_glass 15
fill ~14 ~1 ~23 ~23 ~1 ~23 stained_glass 15
fill ~14 ~1 ~24 ~23 ~1 ~24 stained_glass 15
fill ~20 ~1 ~21 ~23 ~1 ~21 stained_glass 15
fill ~20 ~1 ~25 ~22 ~1 ~25 stained_glass 15
fill ~21 ~1 ~19 ~23 ~1 ~19 stained_glass 15
fill ~21 ~1 ~20 ~23 ~1 ~20 stained_glass 15
fill ~21 ~1 ~26 ~22 ~1 ~26 stained_glass 15
fill ~21 ~1 ~27 ~23 ~1 ~27 stained_glass 15
fill ~22 ~1 ~18 ~23 ~1 ~18 stained_glass 15
fill ~22 ~1 ~28 ~23 ~1 ~28 stained_glass 15
fill ~23 ~1 ~16 ~24 ~1 ~16 stained_glass 15
fill ~23 ~1 ~17 ~24 ~1 ~17 stained_glass 15
fill ~23 ~1 ~29 ~23 ~1 ~30 stained_glass 15
fill ~24 ~1 ~13 ~27 ~1 ~13 stained_glass 15
fill ~24 ~1 ~14 ~26 ~1 ~14 stained_glass 15
fill ~24 ~1 ~15 ~25 ~1 ~15 stained_glass 15
fill ~24 ~1 ~30 ~24 ~1 ~32 stained_glass 15
fill ~25 ~1 ~12 ~28 ~1 ~12 stained_glass 15
fill ~25 ~1 ~32 ~25 ~1 ~35 stained_glass 15
fill ~26 ~1 ~11 ~29 ~1 ~11 stained_glass 15
fill ~26 ~1 ~33 ~26 ~1 ~36 stained_glass 15
fill ~27 ~1 ~10 ~30 ~1 ~10 stained_glass 15
fill ~27 ~1 ~34 ~27 ~1 ~37 stained_glass 15
fill ~28 ~1 ~9 ~33 ~1 ~9 stained_glass 15
fill ~28 ~1 ~35 ~28 ~1 ~38 stained_glass 15
fill ~29 ~1 ~36 ~29 ~1 ~39 stained_glass 15
fill ~30 ~1 ~8 ~36 ~1 ~8 stained_glass 15
fill ~30 ~1 ~37 ~30 ~1 ~39 stained_glass 15
fill ~31 ~1 ~7 ~46 ~1 ~7 stained_glass 15
fill ~31 ~1 ~38 ~31 ~1 ~40 stained_glass 15
fill ~32 ~1 ~39 ~33 ~1 ~39 stained_glass 15
fill ~32 ~1 ~40 ~35 ~1 ~40 stained_glass 15
fill ~32 ~1 ~41 ~39 ~1 ~41 stained_glass 15
fill ~35 ~1 ~6 ~81 ~1 ~6 stained_glass 15
fill ~37 ~1 ~42 ~40 ~1 ~42 stained_glass 15
fill ~38 ~1 ~5 ~53 ~1 ~5 stained_glass 15
fill ~42 ~1 ~4 ~53 ~1 ~4 stained_glass 15
fill ~50 ~1 ~3 ~76 ~1 ~3 stained_glass 15
fill ~53 ~1 ~7 ~58 ~1 ~7 stained_glass 15
fill ~53 ~1 ~41 ~57 ~1 ~41 stained_glass 15
fill ~63 ~1 ~40 ~83 ~1 ~40 stained_glass 15
fill ~64 ~1 ~41 ~75 ~1 ~41 stained_glass 15
setblock ~67 ~1 ~39 stained_glass 15
fill ~69 ~1 ~7 ~98 ~1 ~7 stained_glass 15
fill ~74 ~1 ~39 ~84 ~1 ~39 stained_glass 15
fill ~77 ~1 ~4 ~84 ~1 ~4 stained_glass 15
fill ~85 ~1 ~5 ~86 ~1 ~5 stained_glass 15
fill ~85 ~1 ~8 ~100 ~1 ~8 stained_glass 15
fill ~86 ~1 ~6 ~90 ~1 ~6 stained_glass 15
fill ~89 ~1 ~9 ~108 ~1 ~9 stained_glass 15
setblock ~95 ~1 ~10 stained_glass 15
fill ~105 ~1 ~10 ~111 ~1 ~10 stained_glass 15
fill ~107 ~1 ~38 ~111 ~1 ~38 stained_glass 15
fill ~109 ~1 ~11 ~113 ~1 ~11 stained_glass 15
fill ~109 ~1 ~37 ~112 ~1 ~37 stained_glass 15
fill ~110 ~1 ~36 ~113 ~1 ~36 stained_glass 15
fill ~111 ~1 ~12 ~114 ~1 ~12 stained_glass 15
fill ~111 ~1 ~35 ~114 ~1 ~35 stained_glass 15
fill ~112 ~1 ~13 ~115 ~1 ~13 stained_glass 15
fill ~113 ~1 ~34 ~115 ~1 ~34 stained_glass 15
fill ~114 ~1 ~14 ~116 ~1 ~14 stained_glass 15
fill ~114 ~1 ~33 ~115 ~1 ~33 stained_glass 15
fill ~115 ~1 ~15 ~116 ~1 ~15 stained_glass 15
fill ~115 ~1 ~16 ~116 ~1 ~16 stained_glass 15
fill ~115 ~1 ~31 ~116 ~1 ~31 stained_glass 15
fill ~115 ~1 ~32 ~116 ~1 ~32 stained_glass 15
fill ~116 ~1 ~17 ~117 ~1 ~17 stained_glass 15
fill ~116 ~1 ~18 ~118 ~1 ~18 stained_glass 15
fill ~116 ~1 ~29 ~117 ~1 ~29 stained_glass 15
fill ~116 ~1 ~30 ~117 ~1 ~30 stained_glass 15
fill ~117 ~1 ~19 ~119 ~1 ~19 stained_glass 15
fill ~117 ~1 ~20 ~119 ~1 ~20 stained_glass 15
fill ~117 ~1 ~21 ~121 ~1 ~21 stained_glass 15
fill ~117 ~1 ~25 ~121 ~1 ~25 stained_glass 15
fill ~117 ~1 ~26 ~120 ~1 ~26 stained_glass 15
fill ~117 ~1 ~27 ~119 ~1 ~27 stained_glass 15
fill ~117 ~1 ~28 ~118 ~1 ~28 stained_glass 15
fill ~118 ~1 ~22 ~126 ~1 ~22 stained_glass 15
fill ~118 ~1 ~23 ~127 ~1 ~23 stained_glass 15
fill ~118 ~1 ~24 ~125 ~1 ~24 stained_glass 15
fill ~13 ~2 ~23 ~13 ~4 ~23 stained_glass 15
fill ~14 ~2 ~22 ~16 ~2 ~22 stained_glass 15
fill ~14 ~2 ~24 ~16 ~2 ~24 stained_glass 15
fill ~17 ~2 ~21 ~19 ~2 ~21 stained_glass 15
fill ~17 ~2 ~25 ~19 ~2 ~25 stained_glass 15
fill ~20 ~2 ~20 ~20 ~6 ~20 stained_glass 15
fill ~20 ~2 ~26 ~20 ~3 ~26 stained_glass 15
fill ~21 ~2 ~18 ~21 ~8 ~18 stained_glass 15
fill ~21 ~2 ~19 ~21 ~14 ~19 stained_glass 15
fill ~21 ~2 ~27 ~21 ~3 ~27 stained_glass 15
fill ~21 ~2 ~28 ~21 ~9 ~28 stained_glass 15
fill ~22 ~2 ~17 ~22 ~11 ~17 stained_glass 15
fill ~22 ~2 ~29 ~22 ~5 ~29 stained_glass 15
fill ~23 ~2 ~15 ~23 ~11 ~15 stained_glass 15
fill ~23 ~2 ~16 ~23 ~23 ~16 stained_glass 15
fill ~23 ~2 ~25 ~39 ~2 ~25 stained_glass 15
fill ~23 ~2 ~26 ~39 ~2 ~26 stained_glass 15
fill ~23 ~2 ~30 ~23 ~3 ~30 stained_glass 15
fill ~23 ~2 ~31 ~23 ~15 ~31 stained_glass 15
fill ~24 ~2 ~13 ~24 ~8 ~13 stained_glass 15
fill ~24 ~2 ~14 ~24 ~23 ~14 stained_glass 15
fill ~24 ~2 ~18 ~43 ~2 ~18 stained_glass 15
fill ~24 ~2 ~19 ~42 ~2 ~19 stained_glass 15
fill ~24 ~2 ~20 ~41 ~2 ~20 stained_glass 15
fill ~24 ~2 ~21 ~40 ~2 ~21 stained_glass 15
fill ~24 ~2 ~22 ~40 ~2 ~22 stained_glass 15
fill ~24 ~2 ~23 ~40 ~2 ~23 stained_glass 15
fill ~24 ~2 ~24 ~39 ~2 ~24 stained_glass 15
fill ~24 ~2 ~27 ~38 ~2 ~27 stained_glass 15
fill ~24 ~2 ~28 ~38 ~2 ~28 stained_glass 15
fill ~24 ~2 ~29 ~38 ~2 ~29 stained_glass 15
fill ~24 ~2 ~32 ~24 ~4 ~32 stained_glass 15
fill ~24 ~2 ~33 ~24 ~10 ~33 stained_glass 15
fill ~25 ~2 ~11 ~25 ~3 ~11 stained_glass 15
fill ~25 ~2 ~12 ~25 ~14 ~12 stained_glass 15
fill ~25 ~2 ~16 ~46 ~2 ~16 stained_glass 15
fill ~25 ~2 ~17 ~44 ~2 ~17 stained_glass 15
fill ~25 ~2 ~30 ~38 ~2 ~30 stained_glass 15
fill ~25 ~2 ~31 ~38 ~2 ~31 stained_glass 15
fill ~25 ~2 ~34 ~25 ~3 ~34 stained_glass 15
fill ~25 ~2 ~35 ~25 ~19 ~35 stained_glass 15
fill ~26 ~2 ~10 ~26 ~4 ~10 stained_glass 15
fill ~26 ~2 ~15 ~49 ~2 ~15 stained_glass 15
fill ~26 ~2 ~32 ~38 ~2 ~32 stained_glass 15
fill ~26 ~2 ~36 ~26 ~6 ~36 stained_glass 15
fill ~26 ~2 ~37 ~26 ~25 ~37 stained_glass 15
fill ~27 ~2 ~9 ~28 ~2 ~9 stained_glass 15
fill ~27 ~2 ~14 ~52 ~2 ~14 stained_glass 15
fill ~27 ~2 ~33 ~38 ~2 ~33 stained_glass 15
fill ~27 ~2 ~38 ~28 ~2 ~38 stained_glass 15
fill ~28 ~2 ~13 ~55 ~2 ~13 stained_glass 15
fill ~28 ~2 ~34 ~39 ~2 ~34 stained_glass 15
fill ~29 ~2 ~8 ~30 ~2 ~8 stained_glass 15
fill ~29 ~2 ~12 ~110 ~2 ~12 stained_glass 15
fill ~29 ~2 ~35 ~39 ~2 ~35 stained_glass 15
fill ~29 ~2 ~39 ~29 ~28 ~39 stained_glass 15
fill ~30 ~2 ~11 ~108 ~2 ~11 stained_glass 15
fill ~30 ~2 ~36 ~39 ~2 ~36 stained_glass 15
fill ~30 ~2 ~40 ~31 ~2 ~40 stained_glass 15
fill ~31 ~2 ~7 ~33 ~2 ~7 stained_glass 15
fill ~31 ~2 ~10 ~94 ~2 ~10 stained_glass 15
fill ~31 ~2 ~37 ~40 ~2 ~37 stained_glass 15
fill ~32 ~2 ~38 ~41 ~2 ~38 stained_glass 15
fill ~32 ~2 ~41 ~34 ~2 ~41 stained_glass 15
fill ~34 ~2 ~6 ~36 ~2 ~6 stained_glass 15
fill ~34 ~2 ~9 ~88 ~2 ~9 stained_glass 15
fill ~34 ~2 ~39 ~42 ~2 ~39 stained_glass 15
fill ~35 ~2 ~42 ~37 ~2 ~42 stained_glass 15
fill ~36 ~2 ~40 ~62 ~2 ~40 stained_glass 15
fill ~37 ~2 ~5 ~42 ~2 ~5 stained_glass 15
fill ~37 ~2 ~8 ~84 ~2 ~8 stained_glass 15
fill ~38 ~2 ~43 ~41 ~2 ~43 stained_glass 15
fill ~40 ~2 ~41 ~52 ~2 ~41 stained_glass 15
fill ~41 ~2 ~42 ~44 ~2 ~42 stained_glass 15
fill ~43 ~2 ~4 ~49 ~2 ~4 stained_glass 15
fill ~47 ~2 ~7 ~52 ~2 ~7 stained_glass 15
fill ~49 ~2 ~39 ~66 ~2 ~39 stained_glass 15
fill ~50 ~2 ~3 ~53 ~2 ~3 stained_glass 15
fill ~51 ~2 ~42 ~59 ~2 ~42 stained_glass 15
fill ~54 ~2 ~2 ~60 ~2 ~2 stained_glass 15
fill ~54 ~2 ~38 ~106 ~2 ~38 stained_glass 15
fill ~58 ~2 ~41 ~77 ~2 ~41 stained_glass 15
fill ~59 ~2 ~7 ~68 ~2 ~7 stained_glass 15
fill ~61 ~2 ~3 ~74 ~2 ~3 stained_glass 15
fill ~61 ~2 ~42 ~62 ~2 ~42 stained_glass 15
fill ~62 ~2 ~37 ~108 ~2 ~37 stained_glass 15
fill ~64 ~2 ~36 ~85 ~2 ~36 stained_glass 15
fill ~66 ~2 ~13 ~111 ~2 ~13 stained_glass 15
fill ~66 ~2 ~35 ~83 ~2 ~35 stained_glass 15
fill ~67 ~2 ~34 ~81 ~2 ~34 stained_glass 15
fill ~68 ~2 ~33 ~80 ~2 ~33 stained_glass 15
fill ~68 ~2 ~39 ~73 ~2 ~39 stained_glass 15
fill ~69 ~2 ~32 ~79 ~2 ~32 stained_glass 15
fill ~70 ~2 ~14 ~113 ~2 ~14 stained_glass 15
fill ~70 ~2 ~31 ~79 ~2 ~31 stained_glass 15
fill ~73 ~2 ~15 ~114 ~2 ~15 stained_glass 15
fill ~75 ~2 ~4 ~84 ~2 ~4 stained_glass 15
fill ~77 ~2 ~16 ~114 ~2 ~16 stained_glass 15
fill ~78 ~2 ~40 ~86 ~2 ~40 stained_glass 15
fill ~80 ~2 ~17 ~115 ~2 ~17 stained_glass 15
fill ~83 ~2 ~18 ~115 ~2 ~18 stained_glass 15
fill ~85 ~2 ~5 ~86 ~2 ~5 stained_glass 15
fill ~85 ~2 ~39 ~91 ~2 ~39 stained_glass 15
fill ~86 ~2 ~19 ~116 ~2 ~19 stained_glass 15
fill ~87 ~2 ~6 ~89 ~2 ~6 stained_glass 15
fill ~88 ~2 ~20 ~94 ~2 ~20 stained_glass 15
fill ~89 ~2 ~36 ~100 ~2 ~36 stained_glass 15
fill ~90 ~2 ~7 ~97 ~2 ~7 stained_glass 15
fill ~96 ~2 ~10 ~104 ~2 ~10 stained_glass 15
fill ~98 ~2 ~8 ~105 ~2 ~8 stained_glass 15
fill ~100 ~2 ~20 ~116 ~2 ~20 stained_glass 15
fill ~103 ~2 ~39 ~110 ~2 ~39 stained_glass 15
fill ~104 ~2 ~21 ~116 ~2 ~21 stained_glass 15
fill ~104 ~2 ~36 ~109 ~2 ~36 stained_glass 15
fill ~105 ~2 ~22 ~117 ~2 ~22 stained_glass 15
fill ~105 ~2 ~23 ~117 ~2 ~23 stained_glass 15
fill ~105 ~2 ~24 ~117 ~2 ~24 stained_glass 15
fill ~105 ~2 ~25 ~116 ~2 ~25 stained_glass 15
fill ~105 ~2 ~26 ~116 ~2 ~26 stained_glass 15
fill ~105 ~2 ~27 ~116 ~2 ~27 stained_glass 15
fill ~105 ~2 ~34 ~112 ~2 ~34 stained_glass 15
fill ~105 ~2 ~35 ~110 ~2 ~35 stained_glass 15
fill ~106 ~2 ~9 ~110 ~2 ~9 stained_glass 15
fill ~106 ~2 ~28 ~116 ~2 ~28 stained_glass 15
fill ~106 ~2 ~29 ~115 ~2 ~29 stained_glass 15
fill ~106 ~2 ~30 ~115 ~2 ~30 stained_glass 15
fill ~106 ~2 ~31 ~114 ~2 ~31 stained_glass 15
fill ~106 ~2 ~32 ~114 ~2 ~32 stained_glass 15
fill ~106 ~2 ~33 ~113 ~2 ~33 stained_glass 15
fill ~111 ~2 ~10 ~112 ~2 ~10 stained_glass 15
fill ~111 ~2 ~38 ~112 ~2 ~38 stained_glass 15
fill ~113 ~2 ~11 ~114 ~2 ~11 stained_glass 15
fill ~113 ~2 ~37 ~113 ~8 ~37 stained_glass 15
fill ~114 ~2 ~36 ~114 ~15 ~36 stained_glass 15
fill ~115 ~2 ~12 ~115 ~3 ~12 stained_glass 15
fill ~115 ~2 ~13 ~115 ~12 ~13 stained_glass 15
fill ~115 ~2 ~34 ~115 ~18 ~34 stained_glass 15
fill ~115 ~2 ~35 ~115 ~16 ~35 stained_glass 15
fill ~116 ~2 ~14 ~116 ~9 ~14 stained_glass 15
fill ~116 ~2 ~15 ~116 ~26 ~15 stained_glass 15
fill ~116 ~2 ~32 ~116 ~11 ~32 stained_glass 15
fill ~116 ~2 ~33 ~116 ~20 ~33 stained_glass 15
fill ~117 ~2 ~16 ~117 ~9 ~16 stained_glass 15
fill ~117 ~2 ~17 ~117 ~22 ~17 stained_glass 15
fill ~117 ~2 ~30 ~117 ~5 ~30 stained_glass 15
fill ~117 ~2 ~31 ~117 ~20 ~31 stained_glass 15
fill ~118 ~2 ~18 ~118 ~18 ~18 stained_glass 15
fill ~118 ~2 ~29 ~118 ~5 ~29 stained_glass 15
fill ~119 ~2 ~19 ~119 ~4 ~19 stained_glass 15
fill ~119 ~2 ~27 ~119 ~2 ~28 stained_glass 15
fill ~120 ~2 ~20 ~120 ~4 ~20 stained_glass 15
fill ~120 ~2 ~26 ~121 ~2 ~26 stained_glass 15
fill ~121 ~2 ~21 ~122 ~2 ~21 stained_glass 15
fill ~122 ~2 ~25 ~123 ~2 ~25 stained_glass 15
fill ~123 ~2 ~22 ~126 ~2 ~22 stained_glass 15
fill ~124 ~2 ~24 ~126 ~2 ~24 stained_glass 15
fill ~127 ~2 ~23 ~127 ~6 ~23 stained_glass 15
fill ~14 ~3 ~22 ~16 ~3 ~22 stained_glass 15
fill ~14 ~3 ~24 ~16 ~3 ~24 stained_glass 15
fill ~17 ~3 ~21 ~19 ~3 ~21 stained_glass 15
fill ~17 ~3 ~25 ~19 ~3 ~25 stained_glass 15
fill ~27 ~3 ~9 ~28 ~3 ~9 stained_glass 15
fill ~27 ~3 ~38 ~28 ~3 ~38 stained_glass 15
fill ~29 ~3 ~8 ~30 ~3 ~8 stained_glass 15
fill ~30 ~3 ~40 ~31 ~3 ~40 stained_glass 15
fill ~31 ~3 ~7 ~33 ~3 ~7 stained_glass 15
fill ~32 ~3 ~41 ~33 ~3 ~41 stained_glass 15
fill ~34 ~3 ~6 ~36 ~3 ~6 stained_glass 15
fill ~34 ~3 ~42 ~37 ~3 ~42 stained_glass 15
fill ~37 ~3 ~5 ~43 ~3 ~5 stained_glass 15
fill ~38 ~3 ~43 ~40 ~3 ~43 stained_glass 15
fill ~39 ~3 ~27 ~48 ~3 ~27 stained_glass 15
fill ~39 ~3 ~28 ~49 ~3 ~28 stained_glass 15
fill ~39 ~3 ~29 ~50 ~3 ~29 stained_glass 15
fill ~39 ~3 ~30 ~51 ~3 ~30 stained_glass 15
fill ~39 ~3 ~31 ~52 ~3 ~31 stained_glass 15
fill ~39 ~3 ~32 ~68 ~3 ~32 stained_glass 15
fill ~39 ~3 ~33 ~67 ~3 ~33 stained_glass 15
fill ~40 ~3 ~24 ~47 ~3 ~24 stained_glass 15
fill ~40 ~3 ~25 ~47 ~3 ~25 stained_glass 15
fill ~40 ~3 ~26 ~48 ~3 ~26 stained_glass 15
fill ~40 ~3 ~34 ~66 ~3 ~34 stained_glass 15
fill ~40 ~3 ~35 ~65 ~3 ~35 stained_glass 15
fill ~40 ~3 ~36 ~63 ~3 ~36 stained_glass 15
fill ~41 ~3 ~21 ~49 ~3 ~21 stained_glass 15
fill ~41 ~3 ~22 ~47 ~3 ~22 stained_glass 15
fill ~41 ~3 ~23 ~47 ~3 ~23 stained_glass 15
fill ~41 ~3 ~37 ~61 ~3 ~37 stained_glass 15
fill ~41 ~3 ~42 ~46 ~3 ~42 stained_glass 15
fill ~42 ~3 ~20 ~54 ~3 ~20 stained_glass 15
fill ~42 ~3 ~38 ~53 ~3 ~38 stained_glass 15
fill ~43 ~3 ~19 ~85 ~3 ~19 stained_glass 15
fill ~43 ~3 ~39 ~48 ~3 ~39 stained_glass 15
fill ~44 ~3 ~4 ~49 ~3 ~4 stained_glass 15
fill ~44 ~3 ~18 ~82 ~3 ~18 stained_glass 15
fill ~45 ~3 ~17 ~79 ~3 ~17 stained_glass 15
fill ~47 ~3 ~16 ~76 ~3 ~16 stained_glass 15
setblock ~47 ~3 ~41 stained_glass 15
fill ~48 ~3 ~42 ~51 ~3 ~42 stained_glass 15
fill ~50 ~3 ~3 ~51 ~3 ~3 stained_glass 15
fill ~50 ~3 ~15 ~72 ~3 ~15 stained_glass 15
fill ~52 ~3 ~2 ~61 ~3 ~2 stained_glass 15
fill ~52 ~3 ~43 ~56 ~3 ~43 stained_glass 15
fill ~53 ~3 ~14 ~69 ~3 ~14 stained_glass 15
fill ~54 ~3 ~31 ~69 ~3 ~31 stained_glass 15
fill ~55 ~3 ~30 ~105 ~3 ~30 stained_glass 15
fill ~56 ~3 ~13 ~65 ~3 ~13 stained_glass 15
fill ~57 ~3 ~29 ~105 ~3 ~29 stained_glass 15
fill ~57 ~3 ~42 ~60 ~3 ~42 stained_glass 15
fill ~58 ~3 ~28 ~105 ~3 ~28 stained_glass 15
fill ~59 ~3 ~27 ~104 ~3 ~27 stained_glass 15
fill ~61 ~3 ~20 ~87 ~3 ~20 stained_glass 15
fill ~61 ~3 ~26 ~104 ~3 ~26 stained_glass 15
fill ~61 ~3 ~41 ~67 ~3 ~41 stained_glass 15
fill ~62 ~3 ~3 ~74 ~3 ~3 stained_glass 15
fill ~62 ~3 ~25 ~104 ~3 ~25 stained_glass 15
fill ~63 ~3 ~24 ~104 ~3 ~24 stained_glass 15
fill ~65 ~3 ~21 ~103 ~3 ~21 stained_glass 15
fill ~65 ~3 ~22 ~104 ~3 ~22 stained_glass 15
fill ~65 ~3 ~23 ~104 ~3 ~23 stained_glass 15
fill ~68 ~3 ~40 ~70 ~3 ~40 stained_glass 15
fill ~71 ~3 ~41 ~73 ~3 ~41 stained_glass 15
fill ~74 ~3 ~40 ~84 ~3 ~40 stained_glass 15
fill ~75 ~3 ~4 ~84 ~3 ~4 stained_glass 15
fill ~80 ~3 ~31 ~105 ~3 ~31 stained_glass 15
fill ~80 ~3 ~32 ~105 ~3 ~32 stained_glass 15
fill ~81 ~3 ~33 ~105 ~3 ~33 stained_glass 15
fill ~82 ~3 ~34 ~104 ~3 ~34 stained_glass 15
fill ~84 ~3 ~35 ~104 ~3 ~35 stained_glass 15
fill ~85 ~3 ~5 ~86 ~3 ~5 stained_glass 15
fill ~85 ~3 ~39 ~89 ~3 ~39 stained_glass 15
fill ~86 ~3 ~36 ~88 ~3 ~36 stained_glass 15
fill ~87 ~3 ~6 ~88 ~3 ~6 stained_glass 15
fill ~89 ~3 ~7 ~95 ~3 ~7 stained_glass 15
fill ~90 ~3 ~38 ~98 ~3 ~38 stained_glass 15
fill ~95 ~3 ~20 ~99 ~3 ~20 stained_glass 15
fill ~96 ~3 ~8 ~104 ~3 ~8 stained_glass 15
fill ~99 ~3 ~39 ~110 ~3 ~39 stained_glass 15
fill ~101 ~3 ~36 ~103 ~3 ~36 stained_glass 15
fill ~105 ~3 ~9 ~110 ~3 ~9 stained_glass 15
fill ~111 ~3 ~10 ~112 ~3 ~10 stained_glass 15
fill ~111 ~3 ~38 ~112 ~3 ~38 stained_glass 15
fill ~113 ~3 ~11 ~114 ~3 ~11 stained_glass 15
fill ~119 ~3 ~28 ~119 ~5 ~28 stained_glass 15
fill ~120 ~3 ~27 ~120 ~5 ~27 stained_glass 15
fill ~121 ~3 ~20 ~121 ~14 ~20 stained_glass 15
fill ~121 ~3 ~26 ~121 ~5 ~26 stained_glass 15
fill ~122 ~3 ~21 ~123 ~3 ~21 stained_glass 15
fill ~122 ~3 ~25 ~123 ~3 ~25 stained_glass 15
fill ~124 ~3 ~22 ~126 ~3 ~22 stained_glass 15
fill ~124 ~3 ~24 ~126 ~3 ~24 stained_glass 15
fill ~14 ~4 ~22 ~16 ~4 ~22 stained_glass 15
fill ~14 ~4 ~24 ~15 ~4 ~24 stained_glass 15
fill ~16 ~4 ~25 ~18 ~4 ~25 stained_glass 15
fill ~17 ~4 ~21 ~19 ~4 ~21 stained_glass 15
fill ~19 ~4 ~26 ~19 ~7 ~26 stained_glass 15
fill ~20 ~4 ~27 ~20 ~7 ~27 stained_glass 15
fill ~22 ~4 ~30 ~22 ~15 ~30 stained_glass 15
fill ~24 ~4 ~34 ~24 ~21 ~34 stained_glass 15
fill ~26 ~4 ~11 ~26 ~26 ~11 stained_glass 15
fill ~27 ~4 ~10 ~27 ~28 ~10 stained_glass 15
fill ~27 ~4 ~38 ~28 ~4 ~38 stained_glass 15
fill ~28 ~4 ~9 ~28 ~43 ~9 stained_glass 15
fill ~29 ~4 ~8 ~30 ~4 ~8 stained_glass 15
fill ~30 ~4 ~40 ~31 ~4 ~40 stained_glass 15
fill ~31 ~4 ~7 ~32 ~4 ~7 stained_glass 15
fill ~32 ~4 ~41 ~33 ~4 ~41 stained_glass 15
fill ~33 ~4 ~6 ~36 ~4 ~6 stained_glass 15
fill ~34 ~4 ~42 ~36 ~4 ~42 stained_glass 15
fill ~37 ~4 ~5 ~45 ~4 ~5 stained_glass 15
fill ~37 ~4 ~43 ~41 ~4 ~43 stained_glass 15
fill ~42 ~4 ~42 ~51 ~4 ~42 stained_glass 15
fill ~46 ~4 ~4 ~49 ~4 ~4 stained_glass 15
fill ~48 ~4 ~22 ~64 ~4 ~22 stained_glass 15
fill ~48 ~4 ~23 ~64 ~4 ~23 stained_glass 15
fill ~48 ~4 ~24 ~62 ~4 ~24 stained_glass 15
fill ~48 ~4 ~25 ~61 ~4 ~25 stained_glass 15
fill ~49 ~4 ~26 ~60 ~4 ~26 stained_glass 15
fill ~49 ~4 ~27 ~58 ~4 ~27 stained_glass 15
fill ~50 ~4 ~3 ~51 ~4 ~3 stained_glass 15
fill ~50 ~4 ~21 ~64 ~4 ~21 stained_glass 15
fill ~50 ~4 ~28 ~57 ~4 ~28 stained_glass 15
fill ~51 ~4 ~29 ~56 ~4 ~29 stained_glass 15
fill ~52 ~4 ~2 ~61 ~4 ~2 stained_glass 15
fill ~52 ~4 ~30 ~54 ~4 ~30 stained_glass 15
fill ~52 ~4 ~43 ~56 ~4 ~43 stained_glass 15
setblock ~53 ~4 ~31 stained_glass 15
fill ~55 ~4 ~20 ~60 ~4 ~20 stained_glass 15
fill ~57 ~4 ~42 ~59 ~4 ~42 stained_glass 15
fill ~60 ~4 ~41 ~64 ~4 ~41 stained_glass 15
fill ~62 ~4 ~3 ~74 ~4 ~3 stained_glass 15
fill ~65 ~4 ~40 ~82 ~4 ~40 stained_glass 15
fill ~75 ~4 ~4 ~84 ~4 ~4 stained_glass 15
fill ~83 ~4 ~39 ~87 ~4 ~39 stained_glass 15
fill ~85 ~4 ~5 ~86 ~4 ~5 stained_glass 15
fill ~87 ~4 ~6 ~88 ~4 ~6 stained_glass 15
fill ~88 ~4 ~38 ~99 ~4 ~38 stained_glass 15
fill ~89 ~4 ~7 ~93 ~4 ~7 stained_glass 15
fill ~94 ~4 ~8 ~97 ~4 ~8 stained_glass 15
fill ~98 ~4 ~9 ~110 ~4 ~9 stained_glass 15
fill ~100 ~4 ~39 ~104 ~4 ~39 stained_glass 15
fill ~105 ~4 ~40 ~105 ~15 ~40 stained_glass 15
fill ~106 ~4 ~39 ~110 ~4 ~39 stained_glass 15
fill ~111 ~4 ~10 ~112 ~4 ~10 stained_glass 15
fill ~111 ~4 ~38 ~112 ~4 ~38 stained_glass 15
fill ~113 ~4 ~11 ~113 ~12 ~11 stained_glass 15
fill ~114 ~4 ~12 ~114 ~13 ~12 stained_glass 15
fill ~122 ~4 ~21 ~124 ~4 ~21 stained_glass 15
fill ~122 ~4 ~25 ~124 ~4 ~25 stained_glass 15
fill ~125 ~4 ~22 ~126 ~4 ~22 stained_glass 15
fill ~125 ~4 ~24 ~126 ~4 ~24 stained_glass 15
fill ~14 ~5 ~22 ~16 ~5 ~22 stained_glass 15
fill ~14 ~5 ~23 ~14 ~31 ~23 stained_glass 15
fill ~14 ~5 ~24 ~15 ~5 ~24 stained_glass 15
fill ~16 ~5 ~25 ~18 ~5 ~25 stained_glass 15
fill ~17 ~5 ~21 ~19 ~5 ~21 stained_glass 15
fill ~23 ~5 ~32 ~23 ~22 ~32 stained_glass 15
fill ~27 ~5 ~38 ~27 ~29 ~38 stained_glass 15
fill ~28 ~5 ~39 ~28 ~32 ~39 stained_glass 15
fill ~29 ~5 ~8 ~30 ~5 ~8 stained_glass 15
fill ~30 ~5 ~40 ~31 ~5 ~40 stained_glass 15
fill ~31 ~5 ~7 ~32 ~5 ~7 stained_glass 15
fill ~32 ~5 ~41 ~33 ~5 ~41 stained_glass 15
fill ~33 ~5 ~6 ~35 ~5 ~6 stained_glass 15
fill ~34 ~5 ~42 ~36 ~5 ~42 stained_glass 15
fill ~36 ~5 ~5 ~47 ~5 ~5 stained_glass 15
fill ~37 ~5 ~43 ~42 ~5 ~43 stained_glass 15
fill ~43 ~5 ~42 ~51 ~5 ~42 stained_glass 15
fill ~48 ~5 ~4 ~49 ~5 ~4 stained_glass 15
fill ~50 ~5 ~3 ~51 ~5 ~3 stained_glass 15
fill ~52 ~5 ~2 ~61 ~5 ~2 stained_glass 15
fill ~52 ~5 ~43 ~55 ~5 ~43 stained_glass 15
fill ~56 ~5 ~42 ~58 ~5 ~42 stained_glass 15
fill ~59 ~5 ~41 ~61 ~5 ~41 stained_glass 15
fill ~62 ~5 ~3 ~74 ~5 ~3 stained_glass 15
fill ~62 ~5 ~40 ~68 ~5 ~40 stained_glass 15
fill ~69 ~5 ~39 ~85 ~5 ~39 stained_glass 15
fill ~75 ~5 ~4 ~84 ~5 ~4 stained_glass 15
fill ~85 ~5 ~5 ~86 ~5 ~5 stained_glass 15
fill ~86 ~5 ~38 ~99 ~5 ~38 stained_glass 15
fill ~87 ~5 ~6 ~88 ~5 ~6 stained_glass 15
fill ~89 ~5 ~7 ~92 ~5 ~7 stained_glass 15
fill ~93 ~5 ~8 ~96 ~5 ~8 stained_glass 15
fill ~97 ~5 ~9 ~110 ~5 ~9 stained_glass 15
fill ~100 ~5 ~39 ~103 ~5 ~39 stained_glass 15
fill ~104 ~5 ~40 ~104 ~15 ~40 stained_glass 15
fill ~106 ~5 ~40 ~106 ~22 ~40 stained_glass 15
fill ~107 ~5 ~39 ~110 ~5 ~39 stained_glass 15
fill ~111 ~5 ~10 ~112 ~5 ~10 stained_glass 15
fill ~111 ~5 ~38 ~111 ~11 ~38 stained_glass 15
fill ~112 ~5 ~37 ~112 ~23 ~37 stained_glass 15
fill ~119 ~5 ~18 ~119 ~7 ~18 stained_glass 15
fill ~120 ~5 ~19 ~120 ~18 ~19 stained_glass 15
fill ~122 ~5 ~21 ~124 ~5 ~21 stained_glass 15
fill ~122 ~5 ~26 ~122 ~11 ~26 stained_glass 15
fill ~123 ~5 ~25 ~124 ~5 ~25 stained_glass 15
fill ~125 ~5 ~22 ~126 ~5 ~22 stained_glass 15
fill ~125 ~5 ~24 ~126 ~5 ~24 stained_glass 15
fill ~14 ~6 ~22 ~16 ~6 ~22 stained_glass 15
fill ~14 ~6 ~24 ~15 ~6 ~24 stained_glass 15
fill ~16 ~6 ~25 ~18 ~6 ~25 stained_glass 15
fill ~17 ~6 ~21 ~18 ~6 ~21 stained_glass 15
fill ~19 ~6 ~20 ~19 ~24 ~20 stained_glass 15
fill ~21 ~6 ~29 ~21 ~13 ~29 stained_glass 15
fill ~29 ~6 ~8 ~30 ~6 ~8 stained_glass 15
fill ~30 ~6 ~40 ~31 ~6 ~40 stained_glass 15
fill ~31 ~6 ~7 ~32 ~6 ~7 stained_glass 15
fill ~32 ~6 ~41 ~33 ~6 ~41 stained_glass 15
fill ~33 ~6 ~6 ~35 ~6 ~6 stained_glass 15
fill ~34 ~6 ~42 ~35 ~6 ~42 stained_glass 15
fill ~36 ~6 ~5 ~47 ~6 ~5 stained_glass 15
fill ~36 ~6 ~43 ~42 ~6 ~43 stained_glass 15
fill ~43 ~6 ~42 ~50 ~6 ~42 stained_glass 15
fill ~48 ~6 ~4 ~49 ~6 ~4 stained_glass 15
fill ~50 ~6 ~3 ~51 ~6 ~3 stained_glass 15
fill ~51 ~6 ~43 ~55 ~6 ~43 stained_glass 15
fill ~52 ~6 ~2 ~61 ~6 ~2 stained_glass 15
fill ~56 ~6 ~42 ~57 ~6 ~42 stained_glass 15
setblock ~58 ~6 ~23 wool 8
fill ~58 ~6 ~41 ~60 ~6 ~41 stained_glass 15
fill ~59 ~6 ~22 ~59 ~7 ~22 gold_ore 0
fill ~59 ~6 ~23 ~61 ~6 ~23 double_stone_slab 8
setblock ~59 ~6 ~24 stained_hardened_clay 0
setblock ~60 ~6 ~21 double_stone_slab 8
setblock ~60 ~6 ~22 stonebrick 1
setblock ~61 ~6 ~22 wool 8
fill ~61 ~6 ~40 ~64 ~6 ~40 stained_glass 15
fill ~62 ~6 ~3 ~75 ~6 ~3 stained_glass 15
setblock ~62 ~6 ~22 gold_ore 0
fill ~65 ~6 ~39 ~83 ~6 ~39 stained_glass 15
fill ~76 ~6 ~4 ~84 ~6 ~4 stained_glass 15
fill ~84 ~6 ~38 ~90 ~6 ~38 stained_glass 15
fill ~85 ~6 ~5 ~86 ~6 ~5 stained_glass 15
fill ~87 ~6 ~6 ~88 ~6 ~6 stained_glass 15
fill ~89 ~6 ~7 ~91 ~6 ~7 stained_glass 15
fill ~91 ~6 ~37 ~94 ~6 ~37 stained_glass 15
fill ~92 ~6 ~8 ~94 ~6 ~8 stained_glass 15
fill ~95 ~6 ~9 ~110 ~6 ~9 stained_glass 15
fill ~95 ~6 ~38 ~99 ~6 ~38 stained_glass 15
fill ~100 ~6 ~39 ~103 ~6 ~39 stained_glass 15
fill ~107 ~6 ~39 ~109 ~6 ~39 stained_glass 15
fill ~110 ~6 ~38 ~110 ~30 ~38 stained_glass 15
fill ~111 ~6 ~10 ~112 ~6 ~10 stained_glass 15
fill ~118 ~6 ~30 ~118 ~20 ~30 stained_glass 15
fill ~119 ~6 ~29 ~119 ~14 ~29 stained_glass 15
fill ~120 ~6 ~28 ~120 ~12 ~28 stained_glass 15
fill ~121 ~6 ~27 ~121 ~11 ~27 stained_glass 15
fill ~122 ~6 ~21 ~123 ~6 ~21 stained_glass 15
fill ~123 ~6 ~25 ~124 ~6 ~25 stained_glass 15
fill ~124 ~6 ~22 ~126 ~6 ~22 stained_glass 15
fill ~125 ~6 ~24 ~126 ~6 ~24 stained_glass 15
fill ~14 ~7 ~22 ~16 ~7 ~22 stained_glass 15
fill ~14 ~7 ~24 ~14 ~25 ~24 stained_glass 15
fill ~15 ~7 ~25 ~17 ~7 ~25 stained_glass 15
fill ~17 ~7 ~21 ~18 ~7 ~21 stained_glass 15
fill ~18 ~7 ~26 ~18 ~10 ~26 stained_glass 15
fill ~20 ~7 ~19 ~20 ~29 ~19 stained_glass 15
fill ~25 ~7 ~36 ~25 ~24 ~36 stained_glass 15
fill ~29 ~7 ~8 ~30 ~7 ~8 stained_glass 15
fill ~30 ~7 ~40 ~31 ~7 ~40 stained_glass 15
fill ~31 ~7 ~7 ~32 ~7 ~7 stained_glass 15
fill ~32 ~7 ~41 ~33 ~7 ~41 stained_glass 15
fill ~33 ~7 ~6 ~35 ~7 ~6 stained_glass 15
fill ~34 ~7 ~42 ~35 ~7 ~42 stained_glass 15
fill ~36 ~7 ~5 ~47 ~7 ~5 stained_glass 15
fill ~36 ~7 ~43 ~43 ~7 ~43 stained_glass 15
fill ~44 ~7 ~42 ~50 ~7 ~42 stained_glass 15
fill ~48 ~7 ~4 ~49 ~7 ~4 stained_glass 15
fill ~50 ~7 ~3 ~51 ~7 ~3 stained_glass 15
fill ~51 ~7 ~43 ~54 ~7 ~43 stained_glass 15
fill ~52 ~7 ~2 ~53 ~7 ~2 stained_glass 15
fill ~54 ~7 ~1 ~57 ~7 ~1 stained_glass 15
fill ~55 ~7 ~42 ~57 ~7 ~42 stained_glass 15
fill ~57 ~7 ~23 ~57 ~7 ~24 gold_ore 0
fill ~58 ~7 ~2 ~61 ~7 ~2 stained_glass 15
setblock ~58 ~7 ~22 gold_ore 0
fill ~58 ~7 ~24 ~58 ~8 ~24 gold_ore 0
fill ~58 ~7 ~41 ~59 ~7 ~41 stained_glass 15
setblock ~59 ~7 ~21 green_glazed_terracotta 0
fill ~59 ~7 ~24 ~60 ~7 ~24 double_stone_slab 8
setblock ~60 ~7 ~21 stained_hardened_clay 5
fill ~60 ~7 ~22 ~60 ~8 ~22 wool 8
fill ~60 ~7 ~40 ~62 ~7 ~40 stained_glass 15
fill ~61 ~7 ~20 ~62 ~7 ~20 green_glazed_terracotta 0
setblock ~61 ~7 ~21 wool 8
setblock ~61 ~7 ~22 planks 2
setblock ~61 ~7 ~23 double_stone_slab 8
fill ~62 ~7 ~3 ~76 ~7 ~3 stained_glass 15
setblock ~62 ~7 ~21 gold_ore 0
setblock ~62 ~7 ~22 double_stone_slab 8
setblock ~63 ~7 ~21 wool 8
fill ~63 ~7 ~39 ~70 ~7 ~39 stained_glass 15
fill ~71 ~7 ~38 ~78 ~7 ~38 stained_glass 15
fill ~77 ~7 ~4 ~84 ~7 ~4 stained_glass 15
fill ~79 ~7 ~39 ~82 ~7 ~39 stained_glass 15
fill ~83 ~7 ~38 ~88 ~7 ~38 stained_glass 15
fill ~85 ~7 ~5 ~86 ~7 ~5 stained_glass 15
fill ~87 ~7 ~6 ~88 ~7 ~6 stained_glass 15
fill ~89 ~7 ~7 ~90 ~7 ~7 stained_glass 15
fill ~89 ~7 ~37 ~95 ~7 ~37 stained_glass 15
fill ~91 ~7 ~8 ~93 ~7 ~8 stained_glass 15
fill ~94 ~7 ~9 ~110 ~7 ~9 stained_glass 15
fill ~96 ~7 ~38 ~98 ~7 ~38 stained_glass 15
fill ~99 ~7 ~39 ~102 ~7 ~39 stained_glass 15
fill ~103 ~7 ~40 ~103 ~13 ~40 stained_glass 15
fill ~107 ~7 ~40 ~107 ~8 ~40 stained_glass 15
fill ~108 ~7 ~39 ~109 ~7 ~39 stained_glass 15
fill ~111 ~7 ~10 ~112 ~7 ~10 stained_glass 15
fill ~122 ~7 ~20 ~122 ~17 ~20 stained_glass 15
fill ~123 ~7 ~21 ~123 ~12 ~21 stained_glass 15
fill ~123 ~7 ~25 ~124 ~7 ~25 stained_glass 15
fill ~124 ~7 ~22 ~126 ~7 ~22 stained_glass 15
fill ~125 ~7 ~24 ~126 ~7 ~24 stained_glass 15
fill ~126 ~7 ~23 ~126 ~12 ~23 stained_glass 15
fill ~14 ~8 ~22 ~16 ~8 ~22 stained_glass 15
fill ~15 ~8 ~25 ~17 ~8 ~25 stained_glass 15
fill ~17 ~8 ~21 ~18 ~8 ~21 stained_glass 15
fill ~19 ~8 ~27 ~19 ~11 ~27 stained_glass 15
fill ~20 ~8 ~28 ~20 ~12 ~28 stained_glass 15
fill ~29 ~8 ~8 ~30 ~8 ~8 stained_glass 15
fill ~30 ~8 ~40 ~31 ~8 ~40 stained_glass 15
fill ~31 ~8 ~7 ~32 ~8 ~7 stained_glass 15
fill ~32 ~8 ~41 ~33 ~8 ~41 stained_glass 15
fill ~33 ~8 ~6 ~35 ~8 ~6 stained_glass 15
fill ~34 ~8 ~42 ~36 ~8 ~42 stained_glass 15
fill ~36 ~8 ~5 ~47 ~8 ~5 stained_glass 15
fill ~37 ~8 ~43 ~43 ~8 ~43 stained_glass 15
fill ~44 ~8 ~42 ~50 ~8 ~42 stained_glass 15
fill ~48 ~8 ~4 ~49 ~8 ~4 stained_glass 15
fill ~50 ~8 ~3 ~51 ~8 ~3 stained_glass 15
fill ~51 ~8 ~43 ~54 ~8 ~43 stained_glass 15
fill ~52 ~8 ~2 ~52 ~15 ~2 stained_glass 15
fill ~53 ~8 ~1 ~57 ~8 ~1 stained_glass 15
fill ~55 ~8 ~42 ~57 ~8 ~42 stained_glass 15
setblock ~57 ~8 ~23 mossy_cobblestone 0
setblock ~57 ~8 ~24 orange_glazed_terracotta 0
fill ~58 ~8 ~2 ~61 ~8 ~2 stained_glass 15
setblock ~58 ~8 ~22 stained_hardened_clay 5
fill ~58 ~8 ~41 ~59 ~8 ~41 stained_glass 15
fill ~59 ~8 ~21 ~59 ~8 ~22 orange_glazed_terracotta 0
setblock ~59 ~8 ~24 planks 2
fill ~60 ~8 ~20 ~60 ~10 ~20 stained_hardened_clay 5
setblock ~60 ~8 ~24 wool 8
fill ~60 ~8 ~40 ~62 ~8 ~40 stained_glass 15
fill ~61 ~8 ~20 ~61 ~9 ~20 green_glazed_terracotta 0
setblock ~61 ~8 ~22 stained_hardened_clay 0
setblock ~61 ~8 ~23 planks 2
fill ~62 ~8 ~3 ~78 ~8 ~3 stained_glass 15
fill ~62 ~8 ~20 ~62 ~10 ~20 stained_hardened_clay 5
fill ~62 ~8 ~21 ~63 ~8 ~21 stained_hardened_clay 0
setblock ~63 ~8 ~20 orange_glazed_terracotta 0
fill ~63 ~8 ~39 ~68 ~8 ~39 stained_glass 15
fill ~69 ~8 ~38 ~87 ~8 ~38 stained_glass 15
fill ~79 ~8 ~4 ~84 ~8 ~4 stained_glass 15
fill ~85 ~8 ~5 ~86 ~8 ~5 stained_glass 15
fill ~87 ~8 ~6 ~88 ~8 ~6 stained_glass 15
fill ~88 ~8 ~37 ~95 ~8 ~37 stained_glass 15
fill ~89 ~8 ~7 ~90 ~8 ~7 stained_glass 15
fill ~91 ~8 ~8 ~93 ~8 ~8 stained_glass 15
fill ~94 ~8 ~9 ~110 ~8 ~9 stained_glass 15
fill ~96 ~8 ~38 ~98 ~8 ~38 stained_glass 15
fill ~99 ~8 ~39 ~101 ~8 ~39 stained_glass 15
fill ~102 ~8 ~40 ~102 ~13 ~40 stained_glass 15
fill ~108 ~8 ~39 ~109 ~8 ~39 stained_glass 15
fill ~111 ~8 ~10 ~111 ~35 ~10 stained_glass 15
fill ~112 ~8 ~11 ~112 ~22 ~11 stained_glass 15
fill ~119 ~8 ~19 ~119 ~28 ~19 stained_glass 15
fill ~123 ~8 ~25 ~124 ~8 ~25 stained_glass 15
fill ~124 ~8 ~22 ~126 ~8 ~22 stained_glass 15
fill ~125 ~8 ~24 ~126 ~8 ~24 stained_glass 15
fill ~14 ~9 ~22 ~16 ~9 ~22 stained_glass 15
fill ~15 ~9 ~25 ~17 ~9 ~25 stained_glass 15
fill ~17 ~9 ~21 ~18 ~9 ~21 stained_glass 15
fill ~22 ~9 ~18 ~22 ~22 ~18 stained_glass 15
fill ~25 ~9 ~13 ~25 ~21 ~13 stained_glass 15
fill ~29 ~9 ~8 ~30 ~9 ~8 stained_glass 15
fill ~30 ~9 ~40 ~31 ~9 ~40 stained_glass 15
fill ~31 ~9 ~7 ~32 ~9 ~7 stained_glass 15
fill ~32 ~9 ~41 ~33 ~9 ~41 stained_glass 15
fill ~33 ~9 ~6 ~34 ~9 ~6 stained_glass 15
fill ~34 ~9 ~42 ~36 ~9 ~42 stained_glass 15
fill ~35 ~9 ~5 ~47 ~9 ~5 stained_glass 15
fill ~37 ~9 ~43 ~45 ~9 ~43 stained_glass 15
fill ~46 ~9 ~42 ~49 ~9 ~42 stained_glass 15
fill ~48 ~9 ~4 ~49 ~9 ~4 stained_glass 15
fill ~50 ~9 ~3 ~51 ~9 ~3 stained_glass 15
fill ~50 ~9 ~43 ~55 ~9 ~43 stained_glass 15
fill ~53 ~9 ~1 ~57 ~9 ~1 stained_glass 15
fill ~56 ~9 ~23 ~57 ~9 ~23 stained_hardened_clay 5
setblock ~56 ~9 ~24 orange_glazed_terracotta 0
fill ~56 ~9 ~42 ~57 ~9 ~42 stained_glass 15
setblock ~57 ~9 ~24 gold_ore 0
fill ~58 ~9 ~2 ~61 ~9 ~2 stained_glass 15
setblock ~58 ~9 ~22 green_glazed_terracotta 0
fill ~58 ~9 ~24 ~59 ~9 ~24 wool 8
fill ~58 ~9 ~41 ~59 ~9 ~41 stained_glass 15
setblock ~59 ~9 ~20 bookshelf 0
setblock ~59 ~9 ~21 green_glazed_terracotta 0
setblock ~59 ~9 ~22 wool 8
setblock ~60 ~9 ~21 orange_glazed_terracotta 0
fill ~60 ~9 ~23 ~60 ~9 ~24 gold_ore 0
fill ~60 ~9 ~40 ~62 ~9 ~40 stained_glass 15
fill ~61 ~9 ~21 ~61 ~10 ~21 double_stone_slab 8
fill ~62 ~9 ~3 ~80 ~9 ~3 stained_glass 15
setblock ~62 ~9 ~21 wool 8
setblock ~63 ~9 ~20 green_glazed_terracotta 0
fill ~63 ~9 ~21 ~63 ~10 ~21 planks 2
fill ~63 ~9 ~39 ~67 ~9 ~39 stained_glass 15
fill ~68 ~9 ~38 ~87 ~9 ~38 stained_glass 15
fill ~81 ~9 ~4 ~84 ~9 ~4 stained_glass 15
fill ~85 ~9 ~5 ~86 ~9 ~5 stained_glass 15
fill ~87 ~9 ~6 ~88 ~9 ~6 stained_glass 15
fill ~88 ~9 ~37 ~94 ~9 ~37 stained_glass 15
fill ~89 ~9 ~7 ~90 ~9 ~7 stained_glass 15
fill ~91 ~9 ~8 ~92 ~9 ~8 stained_glass 15
fill ~93 ~9 ~9 ~104 ~9 ~9 stained_glass 15
fill ~95 ~9 ~38 ~97 ~9 ~38 stained_glass 15
fill ~98 ~9 ~39 ~101 ~9 ~39 stained_glass 15
fill ~105 ~9 ~8 ~105 ~23 ~8 stained_glass 15
fill ~106 ~9 ~9 ~110 ~9 ~9 stained_glass 15
fill ~107 ~9 ~39 ~109 ~9 ~39 stained_glass 15
fill ~113 ~9 ~36 ~113 ~17 ~36 stained_glass 15
fill ~123 ~9 ~25 ~124 ~9 ~25 stained_glass 15
fill ~124 ~9 ~21 ~124 ~16 ~21 stained_glass 15
fill ~125 ~9 ~22 ~126 ~9 ~22 stained_glass 15
fill ~125 ~9 ~24 ~125 ~11 ~24 stained_glass 15
fill ~14 ~10 ~22 ~16 ~10 ~22 stained_glass 15
fill ~15 ~10 ~25 ~16 ~10 ~25 stained_glass 15
fill ~17 ~10 ~21 ~18 ~10 ~21 stained_glass 15
fill ~17 ~10 ~26 ~17 ~12 ~26 stained_glass 15
fill ~29 ~10 ~8 ~30 ~10 ~8 stained_glass 15
fill ~30 ~10 ~40 ~31 ~10 ~40 stained_glass 15
fill ~31 ~10 ~7 ~32 ~10 ~7 stained_glass 15
fill ~32 ~10 ~41 ~33 ~10 ~41 stained_glass 15
fill ~33 ~10 ~6 ~34 ~10 ~6 stained_glass 15
fill ~34 ~10 ~42 ~36 ~10 ~42 stained_glass 15
fill ~35 ~10 ~5 ~47 ~10 ~5 stained_glass 15
fill ~37 ~10 ~43 ~56 ~10 ~43 stained_glass 15
fill ~48 ~10 ~4 ~49 ~10 ~4 stained_glass 15
fill ~50 ~10 ~3 ~51 ~10 ~3 stained_glass 15
fill ~53 ~10 ~1 ~57 ~10 ~1 stained_glass 15
setblock ~56 ~10 ~23 mossy_cobblestone 0
fill ~56 ~10 ~24 ~56 ~11 ~24 gold_ore 0
fill ~57 ~10 ~22 ~57 ~11 ~22 gold_ore 0
fill ~57 ~10 ~24 ~58 ~10 ~24 orange_glazed_terracotta 0
fill ~57 ~10 ~42 ~58 ~10 ~42 stained_glass 15
fill ~58 ~10 ~2 ~61 ~10 ~2 stained_glass 15
setblock ~58 ~10 ~21 orange_glazed_terracotta 0
setblock ~59 ~10 ~20 green_glazed_terracotta 0
setblock ~59 ~10 ~22 double_stone_slab 8
setblock ~59 ~10 ~24 wool 8
fill ~59 ~10 ~41 ~59 ~12 ~41 stained_glass 15
setblock ~60 ~10 ~21 double_stone_slab 8
setblock ~60 ~10 ~23 wool 8
fill ~60 ~10 ~40 ~62 ~10 ~40 stained_glass 15
setblock ~61 ~10 ~20 stained_hardened_clay 5
fill ~62 ~10 ~3 ~81 ~10 ~3 stained_glass 15
setblock ~62 ~10 ~21 planks 2
setblock ~63 ~10 ~20 orange_glazed_terracotta 0
fill ~63 ~10 ~39 ~68 ~10 ~39 stained_glass 15
fill ~69 ~10 ~38 ~80 ~10 ~38 stained_glass 15
fill ~81 ~10 ~39 ~82 ~10 ~39 stained_glass 15
fill ~82 ~10 ~4 ~84 ~10 ~4 stained_glass 15
fill ~83 ~10 ~38 ~87 ~10 ~38 stained_glass 15
fill ~85 ~10 ~5 ~86 ~10 ~5 stained_glass 15
fill ~87 ~10 ~6 ~88 ~10 ~6 stained_glass 15
fill ~88 ~10 ~37 ~92 ~10 ~37 stained_glass 15
fill ~89 ~10 ~7 ~90 ~10 ~7 stained_glass 15
fill ~91 ~10 ~8 ~92 ~10 ~8 stained_glass 15
fill ~93 ~10 ~9 ~104 ~10 ~9 stained_glass 15
fill ~93 ~10 ~38 ~96 ~10 ~38 stained_glass 15
fill ~97 ~10 ~39 ~100 ~10 ~39 stained_glass 15
fill ~101 ~10 ~40 ~101 ~13 ~40 stained_glass 15
fill ~106 ~10 ~8 ~107 ~10 ~8 stained_glass 15
fill ~107 ~10 ~40 ~107 ~20 ~40 stained_glass 15
fill ~108 ~10 ~9 ~110 ~10 ~9 stained_glass 15
fill ~108 ~10 ~39 ~109 ~10 ~39 stained_glass 15
fill ~115 ~10 ~14 ~115 ~24 ~14 stained_glass 15
fill ~116 ~10 ~16 ~116 ~19 ~16 stained_glass 15
fill ~123 ~10 ~25 ~124 ~10 ~25 stained_glass 15
fill ~125 ~10 ~22 ~126 ~10 ~22 stained_glass 15
fill ~126 ~10 ~24 ~126 ~24 ~24 stained_glass 15
fill ~14 ~11 ~22 ~15 ~11 ~22 stained_glass 15
fill ~15 ~11 ~25 ~16 ~11 ~25 stained_glass 15
fill ~16 ~11 ~21 ~17 ~11 ~21 stained_glass 15
fill ~18 ~11 ~20 ~18 ~18 ~20 stained_glass 15
fill ~18 ~11 ~27 ~18 ~13 ~27 stained_glass 15
fill ~23 ~11 ~33 ~23 ~24 ~33 stained_glass 15
fill ~29 ~11 ~8 ~30 ~11 ~8 stained_glass 15
fill ~30 ~11 ~40 ~31 ~11 ~40 stained_glass 15
fill ~31 ~11 ~7 ~31 ~27 ~7 stained_glass 15
fill ~32 ~11 ~6 ~34 ~11 ~6 stained_glass 15
fill ~32 ~11 ~41 ~33 ~11 ~41 stained_glass 15
fill ~34 ~11 ~42 ~36 ~11 ~42 stained_glass 15
fill ~35 ~11 ~5 ~47 ~11 ~5 stained_glass 15
fill ~37 ~11 ~43 ~56 ~11 ~43 stained_glass 15
fill ~48 ~11 ~4 ~49 ~11 ~4 stained_glass 15
fill ~50 ~11 ~3 ~50 ~15 ~3 stained_glass 15
fill ~51 ~11 ~2 ~51 ~20 ~2 stained_glass 15
setblock ~52 ~11 ~23 orange_glazed_terracotta 0
fill ~53 ~11 ~1 ~57 ~11 ~1 stained_glass 15
setblock ~53 ~11 ~23 gold_ore 0
setblock ~54 ~11 ~19 brown_glazed_terracotta 0
setblock ~54 ~11 ~23 bookshelf 0
setblock ~54 ~11 ~24 mossy_cobblestone 0
setblock ~55 ~11 ~23 gold_ore 0
fill ~55 ~11 ~24 ~55 ~12 ~24 planks 2
setblock ~56 ~11 ~22 orange_glazed_terracotta 0
setblock ~57 ~11 ~21 mycelium 0
fill ~57 ~11 ~24 ~58 ~11 ~24 orange_glazed_terracotta 0
fill ~57 ~11 ~42 ~58 ~11 ~42 stained_glass 15
fill ~58 ~11 ~2 ~60 ~11 ~2 stained_glass 15
setblock ~58 ~11 ~20 stained_hardened_clay 13
setblock ~58 ~11 ~21 bookshelf 0
setblock ~59 ~11 ~20 stained_hardened_clay 5
setblock ~59 ~11 ~21 wool 8
fill ~59 ~11 ~22 ~59 ~11 ~24 gold_ore 0
setblock ~60 ~11 ~19 stained_hardened_clay 13
setblock ~60 ~11 ~21 gold_ore 0
fill ~60 ~11 ~41 ~60 ~14 ~41 stained_glass 15
fill ~61 ~11 ~3 ~80 ~11 ~3 stained_glass 15
setblock ~61 ~11 ~20 concrete 13
setblock ~61 ~11 ~21 wool 8
fill ~61 ~11 ~40 ~62 ~11 ~40 stained_glass 15
fill ~62 ~11 ~20 ~63 ~11 ~20 green_glazed_terracotta 0
setblock ~62 ~11 ~21 gold_ore 0
fill ~63 ~11 ~21 ~63 ~14 ~21 orange_glazed_terracotta 0
fill ~63 ~11 ~39 ~68 ~11 ~39 stained_glass 15
fill ~69 ~11 ~38 ~79 ~11 ~38 stained_glass 15
fill ~80 ~11 ~39 ~83 ~11 ~39 stained_glass 15
fill ~81 ~11 ~4 ~84 ~11 ~4 stained_glass 15
fill ~84 ~11 ~38 ~95 ~11 ~38 stained_glass 15
fill ~85 ~11 ~5 ~86 ~11 ~5 stained_glass 15
fill ~87 ~11 ~6 ~88 ~11 ~6 stained_glass 15
fill ~89 ~11 ~7 ~90 ~11 ~7 stained_glass 15
fill ~91 ~11 ~8 ~92 ~11 ~8 stained_glass 15
fill ~93 ~11 ~9 ~102 ~11 ~9 stained_glass 15
fill ~96 ~11 ~39 ~99 ~11 ~39 stained_glass 15
fill ~100 ~11 ~40 ~100 ~14 ~40 stained_glass 15
fill ~103 ~11 ~8 ~107 ~11 ~8 stained_glass 15
fill ~108 ~11 ~9 ~110 ~11 ~9 stained_glass 15
fill ~108 ~11 ~39 ~109 ~11 ~39 stained_glass 15
fill ~123 ~11 ~26 ~123 ~14 ~26 stained_glass 15
fill ~124 ~11 ~25 ~124 ~13 ~25 stained_glass 15
fill ~125 ~11 ~22 ~126 ~11 ~22 stained_glass 15
fill ~15 ~12 ~22 ~15 ~34 ~22 stained_glass 15
fill ~15 ~12 ~25 ~15 ~19 ~25 stained_glass 15
fill ~16 ~12 ~21 ~17 ~12 ~21 stained_glass 15
fill ~16 ~12 ~26 ~16 ~20 ~26 stained_glass 15
fill ~19 ~12 ~28 ~19 ~14 ~28 stained_glass 15
fill ~23 ~12 ~17 ~23 ~21 ~17 stained_glass 15
fill ~24 ~12 ~15 ~24 ~20 ~15 stained_glass 15
fill ~29 ~12 ~8 ~30 ~12 ~8 stained_glass 15
fill ~30 ~12 ~40 ~31 ~12 ~40 stained_glass 15
fill ~32 ~12 ~7 ~32 ~34 ~7 stained_glass 15
fill ~32 ~12 ~41 ~33 ~12 ~41 stained_glass 15
fill ~33 ~12 ~6 ~34 ~12 ~6 stained_glass 15
fill ~34 ~12 ~42 ~36 ~12 ~42 stained_glass 15
fill ~35 ~12 ~5 ~46 ~12 ~5 stained_glass 15
fill ~37 ~12 ~43 ~52 ~12 ~43 stained_glass 15
fill ~47 ~12 ~4 ~49 ~12 ~4 stained_glass 15
setblock ~52 ~12 ~18 stained_hardened_clay 5
setblock ~52 ~12 ~19 orange_glazed_terracotta 0
fill ~53 ~12 ~1 ~57 ~12 ~1 stained_glass 15
setblock ~53 ~12 ~18 orange_glazed_terracotta 0
setblock ~53 ~12 ~19 bedrock 0
fill ~53 ~12 ~44 ~55 ~12 ~44 stained_glass 15
setblock ~54 ~12 ~18 mossy_cobblestone 0
setblock ~54 ~12 ~19 stonebrick 1
setblock ~54 ~12 ~23 gold_ore 0
setblock ~54 ~12 ~24 orange_glazed_terracotta 0
setblock ~55 ~12 ~19 stained_hardened_clay 9
setblock ~55 ~12 ~20 planks 2
setblock ~55 ~12 ~23 green_glazed_terracotta 0
setblock ~56 ~12 ~20 green_glazed_terracotta 0
setblock ~56 ~12 ~21 gold_ore 0
setblock ~56 ~12 ~22 sponge 1
setblock ~56 ~12 ~24 green_glazed_terracotta 0
fill ~56 ~12 ~43 ~57 ~12 ~43 stained_glass 15
setblock ~57 ~12 ~20 brown_mushroom_block 0
setblock ~57 ~12 ~25 planks 2
fill ~58 ~12 ~2 ~60 ~12 ~2 stained_glass 15
setblock ~58 ~12 ~20 stained_hardened_clay 5
setblock ~58 ~12 ~22 concrete 8
fill ~58 ~12 ~24 ~58 ~15 ~24 gold_ore 0
fill ~58 ~12 ~42 ~58 ~13 ~42 stained_glass 15
setblock ~59 ~12 ~19 concrete 13
setblock ~59 ~12 ~22 planks 2
fill ~59 ~12 ~23 ~59 ~14 ~23 gold_ore 0
setblock ~59 ~12 ~24 wool 8
setblock ~60 ~12 ~19 green_glazed_terracotta 0
setblock ~60 ~12 ~21 wool 8
fill ~61 ~12 ~3 ~79 ~12 ~3 stained_glass 15
setblock ~61 ~12 ~19 stained_hardened_clay 5
setblock ~61 ~12 ~21 planks 2
fill ~61 ~12 ~40 ~63 ~12 ~40 stained_glass 15
setblock ~62 ~12 ~19 orange_glazed_terracotta 0
setblock ~62 ~12 ~21 wool 8
setblock ~63 ~12 ~18 orange_glazed_terracotta 0
fill ~63 ~12 ~19 ~63 ~12 ~20 gold_ore 0
setblock ~64 ~12 ~17 mossy_cobblestone 0
fill ~64 ~12 ~18 ~64 ~13 ~18 gold_ore 0
setblock ~64 ~12 ~19 double_stone_slab 8
fill ~64 ~12 ~39 ~67 ~12 ~39 stained_glass 15
setblock ~65 ~12 ~18 double_stone_slab 8
fill ~68 ~12 ~38 ~77 ~12 ~38 stained_glass 15
fill ~78 ~12 ~39 ~84 ~12 ~39 stained_glass 15
fill ~80 ~12 ~4 ~84 ~12 ~4 stained_glass 15
fill ~85 ~12 ~5 ~86 ~12 ~5 stained_glass 15
fill ~85 ~12 ~38 ~94 ~12 ~38 stained_glass 15
fill ~87 ~12 ~6 ~87 ~16 ~6 stained_glass 15
fill ~88 ~12 ~7 ~89 ~12 ~7 stained_glass 15
fill ~90 ~12 ~8 ~92 ~12 ~8 stained_glass 15
fill ~93 ~12 ~9 ~101 ~12 ~9 stained_glass 15
fill ~95 ~12 ~39 ~98 ~12 ~39 stained_glass 15
fill ~99 ~12 ~40 ~99 ~14 ~40 stained_glass 15
fill ~102 ~12 ~8 ~108 ~12 ~8 stained_glass 15
fill ~108 ~12 ~39 ~109 ~12 ~39 stained_glass 15
fill ~109 ~12 ~9 ~110 ~12 ~9 stained_glass 15
fill ~111 ~12 ~37 ~111 ~14 ~37 stained_glass 15
setblock ~117 ~12 ~32 stained_glass 15
fill ~121 ~12 ~28 ~121 ~17 ~28 stained_glass 15
fill ~122 ~12 ~27 ~122 ~15 ~27 stained_glass 15
fill ~125 ~12 ~22 ~126 ~12 ~22 stained_glass 15
fill ~125 ~12 ~25 ~125 ~16 ~25 stained_glass 15
fill ~16 ~13 ~21 ~17 ~13 ~21 stained_glass 15
fill ~17 ~13 ~27 ~17 ~22 ~27 stained_glass 15
fill ~20 ~13 ~29 ~20 ~19 ~29 stained_glass 15
fill ~29 ~13 ~8 ~30 ~13 ~8 stained_glass 15
fill ~30 ~13 ~40 ~31 ~13 ~40 stained_glass 15
fill ~32 ~13 ~41 ~33 ~13 ~41 stained_glass 15
fill ~33 ~13 ~6 ~34 ~13 ~6 stained_glass 15
fill ~34 ~13 ~42 ~36 ~13 ~42 stained_glass 15
fill ~35 ~13 ~5 ~46 ~13 ~5 stained_glass 15
fill ~37 ~13 ~43 ~49 ~13 ~43 stained_glass 15
fill ~43 ~13 ~21 ~44 ~13 ~21 stained_hardened_clay 5
setblock ~44 ~13 ~20 bookshelf 0
fill ~45 ~13 ~21 ~46 ~13 ~21 stained_hardened_clay 13
fill ~47 ~13 ~4 ~48 ~13 ~4 stained_glass 15
setblock ~47 ~13 ~21 mossy_cobblestone 0
fill ~49 ~13 ~3 ~49 ~17 ~3 stained_glass 15
setblock ~49 ~13 ~19 orange_glazed_terracotta 0
setblock ~50 ~13 ~17 green_glazed_terracotta 0
setblock ~50 ~13 ~18 gold_ore 0
setblock ~50 ~13 ~19 green_glazed_terracotta 0
fill ~50 ~13 ~44 ~55 ~13 ~44 stained_glass 15
setblock ~51 ~13 ~17 stained_hardened_clay 5
setblock ~51 ~13 ~18 green_glazed_terracotta 0
setblock ~51 ~13 ~19 wool 7
setblock ~52 ~13 ~17 bedrock 0
fill ~52 ~13 ~20 ~52 ~14 ~20 stained_hardened_clay 5
fill ~53 ~13 ~1 ~57 ~13 ~1 stained_glass 15
setblock ~53 ~13 ~18 mossy_cobblestone 0
fill ~53 ~13 ~20 ~54 ~13 ~20 green_glazed_terracotta 0
setblock ~54 ~13 ~18 stained_hardened_clay 5
setblock ~55 ~13 ~18 green_glazed_terracotta 0
setblock ~55 ~13 ~20 orange_glazed_terracotta 0
setblock ~55 ~13 ~21 brown_glazed_terracotta 0
setblock ~55 ~13 ~22 stonebrick 1
setblock ~55 ~13 ~23 mossy_cobblestone 0
fill ~55 ~13 ~24 ~55 ~14 ~24 orange_glazed_terracotta 0
setblock ~56 ~13 ~19 log 3
setblock ~56 ~13 ~24 gold_ore 0
fill ~56 ~13 ~43 ~57 ~13 ~43 stained_glass 15
setblock ~57 ~13 ~19 concrete 13
setblock ~57 ~13 ~25 gold_ore 0
fill ~58 ~13 ~2 ~60 ~13 ~2 stained_glass 15
fill ~58 ~13 ~18 ~60 ~13 ~18 stained_hardened_clay 13
fill ~58 ~13 ~19 ~59 ~13 ~19 stained_hardened_clay 13
setblock ~59 ~13 ~22 wool 8
setblock ~59 ~13 ~24 gold_ore 0
fill ~59 ~13 ~42 ~59 ~15 ~42 stained_glass 15
setblock ~60 ~13 ~22 orange_glazed_terracotta 0
fill ~61 ~13 ~3 ~69 ~13 ~3 stained_glass 15
setblock ~61 ~13 ~18 concrete 13
setblock ~61 ~13 ~21 orange_glazed_terracotta 0
fill ~61 ~13 ~41 ~61 ~40 ~41 stained_glass 15
setblock ~62 ~13 ~18 log2 1
fill ~62 ~13 ~21 ~62 ~14 ~21 gold_ore 0
fill ~62 ~13 ~40 ~63 ~13 ~40 stained_glass 15
fill ~63 ~13 ~18 ~63 ~13 ~19 green_glazed_terracotta 0
setblock ~64 ~13 ~20 orange_glazed_terracotta 0
fill ~64 ~13 ~39 ~67 ~13 ~39 stained_glass 15
fill ~68 ~13 ~38 ~78 ~13 ~38 stained_glass 15
fill ~70 ~13 ~4 ~84 ~13 ~4 stained_glass 15
fill ~79 ~13 ~39 ~85 ~13 ~39 stained_glass 15
fill ~85 ~13 ~5 ~85 ~16 ~5 stained_glass 15
fill ~86 ~13 ~6 ~86 ~22 ~6 stained_glass 15
fill ~86 ~13 ~38 ~93 ~13 ~38 stained_glass 15
fill ~88 ~13 ~7 ~89 ~13 ~7 stained_glass 15
fill ~90 ~13 ~8 ~92 ~13 ~8 stained_glass 15
fill ~93 ~13 ~9 ~97 ~13 ~9 stained_glass 15
fill ~94 ~13 ~39 ~97 ~13 ~39 stained_glass 15
fill ~98 ~13 ~8 ~108 ~13 ~8 stained_glass 15
fill ~98 ~13 ~40 ~98 ~15 ~40 stained_glass 15
fill ~108 ~13 ~39 ~109 ~13 ~39 stained_glass 15
fill ~109 ~13 ~9 ~110 ~13 ~9 stained_glass 15
fill ~113 ~13 ~12 ~113 ~16 ~12 stained_glass 15
fill ~114 ~13 ~13 ~114 ~18 ~13 stained_glass 15
fill ~116 ~13 ~32 ~116 ~17 ~32 stained_glass 15
fill ~120 ~13 ~29 ~120 ~24 ~29 stained_glass 15
fill ~123 ~13 ~20 ~123 ~16 ~20 stained_glass 15
fill ~125 ~13 ~21 ~125 ~15 ~21 stained_glass 15
fill ~126 ~13 ~22 ~126 ~15 ~22 stained_glass 15
fill ~127 ~13 ~23 ~127 ~14 ~23 stained_glass 15
fill ~16 ~14 ~21 ~17 ~14 ~21 stained_glass 15
fill ~18 ~14 ~28 ~18 ~23 ~28 stained_glass 15
fill ~21 ~14 ~30 ~21 ~21 ~30 stained_glass 15
fill ~29 ~14 ~8 ~30 ~14 ~8 stained_glass 15
fill ~30 ~14 ~40 ~31 ~14 ~40 stained_glass 15
fill ~32 ~14 ~41 ~33 ~14 ~41 stained_glass 15
fill ~33 ~14 ~6 ~34 ~14 ~6 stained_glass 15
fill ~34 ~14 ~42 ~36 ~14 ~42 stained_glass 15
fill ~35 ~14 ~5 ~45 ~14 ~5 stained_glass 15
fill ~37 ~14 ~43 ~39 ~14 ~43 stained_glass 15
fill ~40 ~14 ~16 ~41 ~14 ~16 gold_ore 0
setblock ~40 ~14 ~17 sponge 1
fill ~40 ~14 ~44 ~43 ~14 ~44 stained_glass 15
setblock ~41 ~14 ~17 concrete 7
setblock ~41 ~14 ~21 stained_hardened_clay 13
setblock ~42 ~14 ~13 green_glazed_terracotta 0
fill ~42 ~14 ~17 ~43 ~14 ~17 gold_ore 0
setblock ~42 ~14 ~21 gold_ore 0
fill ~43 ~14 ~13 ~46 ~14 ~13 orange_glazed_terracotta 0
fill ~43 ~14 ~14 ~44 ~14 ~14 orange_glazed_terracotta 0
setblock ~43 ~14 ~15 concrete 13
setblock ~43 ~14 ~20 brown_glazed_terracotta 0
setblock ~43 ~14 ~22 stained_hardened_clay 9
fill ~44 ~14 ~15 ~44 ~14 ~16 gold_ore 0
setblock ~44 ~14 ~17 stained_hardened_clay 9
setblock ~44 ~14 ~18 gold_ore 0
fill ~44 ~14 ~19 ~45 ~14 ~19 orange_glazed_terracotta 0
setblock ~44 ~14 ~20 stained_hardened_clay 5
fill ~44 ~14 ~22 ~46 ~14 ~22 stained_hardened_clay 5
fill ~44 ~14 ~43 ~48 ~14 ~43 stained_glass 15
setblock ~45 ~14 ~14 planks 2
setblock ~45 ~14 ~15 stained_hardened_clay 9
setblock ~45 ~14 ~16 green_glazed_terracotta 0
setblock ~45 ~14 ~17 stained_hardened_clay 5
setblock ~45 ~14 ~18 orange_glazed_terracotta 0
setblock ~45 ~14 ~20 orange_glazed_terracotta 0
fill ~46 ~14 ~4 ~48 ~14 ~4 stained_glass 15
setblock ~46 ~14 ~14 brown_glazed_terracotta 0
setblock ~46 ~14 ~15 gold_ore 0
setblock ~46 ~14 ~16 stained_hardened_clay 5
fill ~46 ~14 ~17 ~47 ~14 ~17 green_glazed_terracotta 0
setblock ~46 ~14 ~18 stained_hardened_clay 5
fill ~46 ~14 ~19 ~46 ~14 ~20 green_glazed_terracotta 0
setblock ~47 ~14 ~13 gold_ore 0
setblock ~47 ~14 ~14 brown_mushroom_block 0
setblock ~47 ~14 ~15 bookshelf 0
setblock ~47 ~14 ~16 orange_glazed_terracotta 0
fill ~47 ~14 ~18 ~48 ~14 ~18 orange_glazed_terracotta 0
fill ~47 ~14 ~19 ~48 ~14 ~19 orange_glazed_terracotta 0
fill ~47 ~14 ~20 ~47 ~14 ~18 orange_glazed_terracotta 0
setblock ~47 ~14 ~22 orange_glazed_terracotta 0
setblock ~48 ~14 ~13 stained_hardened_clay 9
setblock ~48 ~14 ~14 stained_hardened_clay 13
fill ~48 ~14 ~15 ~48 ~14 ~16 stained_hardened_clay 5
fill ~48 ~14 ~17 ~49 ~14 ~17 orange_glazed_terracotta 0
setblock ~48 ~14 ~20 mossy_cobblestone 0
setblock ~48 ~14 ~21 stonebrick 1
setblock ~49 ~14 ~14 concrete 8
setblock ~49 ~14 ~15 wool 8
setblock ~49 ~14 ~16 orange_glazed_terracotta 0
setblock ~49 ~14 ~18 planks 2
setblock ~49 ~14 ~20 orange_glazed_terracotta 0
setblock ~49 ~14 ~21 green_glazed_terracotta 0
fill ~49 ~14 ~44 ~56 ~14 ~44 stained_glass 15
fill ~50 ~14 ~15 ~50 ~14 ~16 green_glazed_terracotta 0
setblock ~50 ~14 ~20 green_glazed_terracotta 0
setblock ~51 ~14 ~15 bookshelf 0
setblock ~51 ~14 ~16 green_glazed_terracotta 0
setblock ~51 ~14 ~20 orange_glazed_terracotta 0
setblock ~52 ~14 ~16 wool 7
fill ~53 ~14 ~1 ~56 ~14 ~1 stained_glass 15
fill ~53 ~14 ~17 ~54 ~14 ~17 green_glazed_terracotta 0
fill ~53 ~14 ~20 ~53 ~13 ~20 green_glazed_terracotta 0
setblock ~54 ~14 ~18 log 0
setblock ~54 ~14 ~21 wool 7
setblock ~54 ~14 ~22 stained_hardened_clay 12
setblock ~54 ~14 ~23 concrete 8
setblock ~55 ~14 ~18 stained_hardened_clay 5
setblock ~56 ~14 ~18 log 3
fill ~56 ~14 ~25 ~56 ~15 ~25 gold_ore 0
fill ~57 ~14 ~2 ~59 ~14 ~2 stained_glass 15
setblock ~57 ~14 ~17 stained_hardened_clay 13
setblock ~57 ~14 ~18 stained_hardened_clay 5
setblock ~57 ~14 ~25 wool 8
fill ~57 ~14 ~43 ~58 ~14 ~43 stained_glass 15
fill ~58 ~14 ~17 ~59 ~14 ~17 stained_hardened_clay 5
setblock ~59 ~14 ~22 orange_glazed_terracotta 0
fill ~60 ~14 ~3 ~65 ~14 ~3 stained_glass 15
setblock ~60 ~14 ~16 green_glazed_terracotta 0
setblock ~60 ~14 ~17 planks 2
setblock ~60 ~14 ~22 green_glazed_terracotta 0
fill ~61 ~14 ~17 ~63 ~14 ~17 green_glazed_terracotta 0
setblock ~61 ~14 ~22 planks 2
setblock ~62 ~14 ~16 bookshelf 0
fill ~62 ~14 ~40 ~64 ~14 ~40 stained_glass 15
setblock ~63 ~14 ~16 orange_glazed_terracotta 0
setblock ~63 ~14 ~18 wool 8
setblock ~63 ~14 ~19 log 3
fill ~64 ~14 ~15 ~65 ~14 ~15 orange_glazed_terracotta 0
setblock ~64 ~14 ~16 mossy_cobblestone 0
setblock ~64 ~14 ~19 stained_hardened_clay 5
setblock ~64 ~14 ~21 planks 2
setblock ~65 ~14 ~14 planks 2
setblock ~65 ~14 ~16 double_stone_slab 8
setblock ~65 ~14 ~20 orange_glazed_terracotta 0
fill ~65 ~14 ~39 ~67 ~14 ~39 stained_glass 15
fill ~66 ~14 ~4 ~83 ~14 ~4 stained_glass 15
setblock ~66 ~14 ~14 orange_glazed_terracotta 0
setblock ~66 ~14 ~15 planks 2
setblock ~66 ~14 ~16 iron_ore 0
setblock ~66 ~14 ~20 bookshelf 0
setblock ~67 ~14 ~14 planks 2
setblock ~67 ~14 ~15 orange_glazed_terracotta 0
setblock ~67 ~14 ~16 double_stone_slab 8
setblock ~68 ~14 ~14 green_glazed_terracotta 0
setblock ~68 ~14 ~15 sponge 1
fill ~68 ~14 ~16 ~68 ~15 ~16 gold_ore 0
fill ~68 ~14 ~38 ~78 ~14 ~38 stained_glass 15
setblock ~69 ~14 ~13 orange_glazed_terracotta 0
setblock ~69 ~14 ~14 planks 2
setblock ~69 ~14 ~15 gold_ore 0
setblock ~70 ~14 ~14 orange_glazed_terracotta 0
setblock ~71 ~14 ~14 planks 2
fill ~79 ~14 ~39 ~86 ~14 ~39 stained_glass 15
fill ~84 ~14 ~5 ~84 ~25 ~5 stained_glass 15
fill ~87 ~14 ~38 ~92 ~14 ~38 stained_glass 15
fill ~88 ~14 ~7 ~89 ~14 ~7 stained_glass 15
fill ~90 ~14 ~8 ~108 ~14 ~8 stained_glass 15
fill ~93 ~14 ~39 ~95 ~14 ~39 stained_glass 15
fill ~96 ~14 ~40 ~100 ~14 ~40 stained_glass 15
fill ~101 ~14 ~41 ~103 ~14 ~41 stained_glass 15
fill ~108 ~14 ~39 ~109 ~14 ~39 stained_glass 15
fill ~109 ~14 ~9 ~110 ~14 ~9 stained_glass 15
fill ~124 ~14 ~26 ~124 ~18 ~26 stained_glass 15
setblock ~127 ~14 ~24 stained_glass 15
fill ~16 ~15 ~21 ~17 ~15 ~21 stained_glass 15
fill ~19 ~15 ~29 ~19 ~17 ~29 stained_glass 15
fill ~21 ~15 ~18 ~21 ~16 ~18 stained_glass 15
fill ~26 ~15 ~12 ~26 ~18 ~12 stained_glass 15
fill ~29 ~15 ~8 ~30 ~15 ~8 stained_glass 15
fill ~30 ~15 ~40 ~31 ~15 ~40 stained_glass 15
fill ~32 ~15 ~41 ~33 ~15 ~41 stained_glass 15
fill ~33 ~15 ~6 ~34 ~15 ~6 stained_glass 15
fill ~34 ~15 ~42 ~36 ~15 ~42 stained_glass 15
fill ~35 ~15 ~5 ~42 ~15 ~5 stained_glass 15
fill ~37 ~15 ~43 ~39 ~15 ~43 stained_glass 15
setblock ~39 ~15 ~17 brown_glazed_terracotta 0
setblock ~40 ~15 ~16 mycelium 0
setblock ~40 ~15 ~17 stained_hardened_clay 13
setblock ~40 ~15 ~18 stained_hardened_clay 5
fill ~40 ~15 ~44 ~44 ~15 ~44 stained_glass 15
setblock ~41 ~15 ~13 mossy_cobblestone 0
setblock ~41 ~15 ~14 bookshelf 0
setblock ~41 ~15 ~16 bedrock 0
setblock ~41 ~15 ~18 log2 0
setblock ~42 ~15 ~12 planks 1
setblock ~42 ~15 ~14 stained_hardened_clay 5
setblock ~42 ~15 ~16 stained_hardened_clay 13
setblock ~42 ~15 ~18 gold_ore 0
setblock ~42 ~15 ~20 bedrock 0
setblock ~42 ~15 ~21 stained_hardened_clay 13
fill ~43 ~15 ~4 ~47 ~15 ~4 stained_glass 15
setblock ~43 ~15 ~12 concrete 7
setblock ~43 ~15 ~13 stained_hardened_clay 7
setblock ~43 ~15 ~15 stained_hardened_clay 5
setblock ~43 ~15 ~16 mycelium 0
setblock ~43 ~15 ~18 orange_glazed_terracotta 0
setblock ~43 ~15 ~19 brown_mushroom_block 0
setblock ~43 ~15 ~20 mossy_cobblestone 0
setblock ~43 ~15 ~22 bedrock 0
setblock ~44 ~15 ~12 stained_hardened_clay 13
fill ~44 ~15 ~22 ~45 ~15 ~22 green_glazed_terracotta 0
setblock ~45 ~15 ~12 gold_ore 0
fill ~45 ~15 ~43 ~47 ~15 ~43 stained_glass 15
setblock ~46 ~15 ~12 stained_hardened_clay 5
setblock ~46 ~15 ~22 orange_glazed_terracotta 0
setblock ~46 ~15 ~23 green_glazed_terracotta 0
setblock ~46 ~15 ~24 orange_glazed_terracotta 0
setblock ~47 ~15 ~12 bedrock 0
setblock ~47 ~15 ~23 orange_glazed_terracotta 0
fill ~48 ~15 ~3 ~48 ~21 ~3 stained_glass 15
setblock ~48 ~15 ~12 soul_sand 0
setblock ~48 ~15 ~22 green_glazed_terracotta 0
fill ~48 ~15 ~44 ~54 ~15 ~44 stained_glass 15
setblock ~49 ~15 ~13 stained_hardened_clay 12
setblock ~49 ~15 ~22 orange_glazed_terracotta 0
setblock ~50 ~15 ~14 bedrock 0
setblock ~50 ~15 ~21 stained_hardened_clay 5
setblock ~51 ~15 ~14 brown_glazed_terracotta 0
setblock ~51 ~15 ~15 log2 1
setblock ~51 ~15 ~20 green_glazed_terracotta 0
setblock ~51 ~15 ~21 soul_sand 0
setblock ~52 ~15 ~15 stained_hardened_clay 13
setblock ~52 ~15 ~20 stained_hardened_clay 13
setblock ~52 ~15 ~21 bedrock 0
fill ~53 ~15 ~1 ~56 ~15 ~1 stained_glass 15
setblock ~53 ~15 ~16 stained_hardened_clay 5
setblock ~53 ~15 ~21 wool 7
setblock ~53 ~15 ~22 coal_ore 0
fill ~53 ~15 ~23 ~54 ~15 ~23 bedrock 0
setblock ~54 ~15 ~16 bookshelf 0
setblock ~54 ~15 ~24 double_stone_slab 8
setblock ~55 ~15 ~17 log 0
setblock ~55 ~15 ~18 stained_hardened_clay 13
setblock ~55 ~15 ~24 gold_ore 0
fill ~55 ~15 ~45 ~55 ~22 ~45 stained_glass 15
fill ~56 ~15 ~17 ~57 ~15 ~17 log2 1
fill ~56 ~15 ~44 ~56 ~27 ~44 stained_glass 15
fill ~57 ~15 ~2 ~59 ~15 ~2 stained_glass 15
fill ~57 ~15 ~24 ~57 ~17 ~24 gold_ore 0
fill ~57 ~15 ~43 ~58 ~15 ~43 stained_glass 15
fill ~58 ~15 ~16 ~59 ~15 ~16 log2 1
fill ~58 ~15 ~23 ~59 ~15 ~23 mossy_cobblestone 0
fill ~60 ~15 ~3 ~63 ~15 ~3 stained_glass 15
setblock ~60 ~15 ~15 concrete 13
setblock ~60 ~15 ~22 mossy_cobblestone 0
fill ~60 ~15 ~42 ~60 ~23 ~42 stained_glass 15
setblock ~61 ~15 ~14 orange_glazed_terracotta 0
setblock ~61 ~15 ~15 stained_hardened_clay 5
setblock ~61 ~15 ~16 green_glazed_terracotta 0
setblock ~61 ~15 ~22 gold_ore 0
setblock ~62 ~15 ~14 stained_hardened_clay 5
setblock ~62 ~15 ~15 wool 13
setblock ~62 ~15 ~22 mossy_cobblestone 0
fill ~62 ~15 ~40 ~64 ~15 ~40 stained_glass 15
setblock ~63 ~15 ~15 green_glazed_terracotta 0
setblock ~63 ~15 ~18 stained_hardened_clay 5
setblock ~63 ~15 ~21 gold_ore 0
fill ~64 ~15 ~4 ~83 ~15 ~4 stained_glass 15
setblock ~64 ~15 ~14 stained_hardened_clay 13
setblock ~64 ~15 ~17 stonebrick 1
fill ~64 ~15 ~19 ~65 ~15 ~19 concrete 13
fill ~64 ~15 ~21 ~66 ~15 ~21 orange_glazed_terracotta 0
fill ~65 ~15 ~13 ~67 ~15 ~13 stained_hardened_clay 5
setblock ~65 ~15 ~17 clay 0
fill ~65 ~15 ~39 ~66 ~15 ~39 stained_glass 15
setblock ~66 ~15 ~17 stained_hardened_clay 9
setblock ~66 ~15 ~20 wool 13
setblock ~67 ~15 ~16 wool 8
setblock ~67 ~15 ~20 green_glazed_terracotta 0
fill ~67 ~15 ~38 ~77 ~15 ~38 stained_glass 15
setblock ~68 ~15 ~13 mossy_cobblestone 0
setblock ~69 ~15 ~13 concrete 13
setblock ~69 ~15 ~16 orange_glazed_terracotta 0
setblock ~70 ~15 ~13 green_glazed_terracotta 0
setblock ~70 ~15 ~15 concrete 8
setblock ~71 ~15 ~14 wool 8
fill ~78 ~15 ~39 ~94 ~15 ~39 stained_glass 15
fill ~88 ~15 ~7 ~89 ~15 ~7 stained_glass 15
fill ~90 ~15 ~8 ~108 ~15 ~8 stained_glass 15
fill ~95 ~15 ~40 ~98 ~15 ~40 stained_glass 15
fill ~99 ~15 ~41 ~103 ~15 ~41 stained_glass 15
fill ~108 ~15 ~39 ~109 ~15 ~39 stained_glass 15
fill ~109 ~15 ~9 ~110 ~15 ~9 stained_glass 15
fill ~111 ~15 ~38 ~111 ~30 ~38 stained_glass 15
fill ~119 ~15 ~30 ~119 ~29 ~30 stained_glass 15
fill ~121 ~15 ~19 ~121 ~16 ~19 stained_glass 15
fill ~123 ~15 ~27 ~123 ~19 ~27 stained_glass 15
fill ~126 ~15 ~23 ~126 ~34 ~23 stained_glass 15
fill ~126 ~15 ~25 ~126 ~25 ~25 stained_glass 15
fill ~16 ~16 ~21 ~17 ~16 ~21 stained_glass 15
fill ~22 ~16 ~31 ~22 ~22 ~31 stained_glass 15
fill ~29 ~16 ~9 ~29 ~21 ~9 stained_glass 15
fill ~30 ~16 ~8 ~30 ~49 ~8 stained_glass 15
fill ~30 ~16 ~40 ~31 ~16 ~40 stained_glass 15
fill ~32 ~16 ~41 ~33 ~16 ~41 stained_glass 15
fill ~33 ~16 ~6 ~34 ~16 ~6 stained_glass 15
fill ~34 ~16 ~42 ~36 ~16 ~42 stained_glass 15
fill ~35 ~16 ~5 ~39 ~16 ~5 stained_glass 15
setblock ~37 ~16 ~18 bedrock 0
fill ~37 ~16 ~43 ~40 ~16 ~43 stained_glass 15
setblock ~38 ~16 ~17 soul_sand 0
setblock ~38 ~16 ~18 stained_hardened_clay 13
setblock ~38 ~16 ~19 mycelium 0
setblock ~39 ~16 ~16 bedrock 0
setblock ~39 ~16 ~17 concrete 7
setblock ~39 ~16 ~18 mycelium 0
setblock ~39 ~16 ~19 stained_hardened_clay 13
fill ~40 ~16 ~4 ~47 ~16 ~4 stained_glass 15
fill ~40 ~16 ~16 ~41 ~16 ~16 stained_hardened_clay 13
setblock ~40 ~16 ~19 mycelium 0
setblock ~41 ~16 ~12 mossy_cobblestone 0
setblock ~41 ~16 ~13 gold_ore 0
setblock ~41 ~16 ~14 brown_glazed_terracotta 0
setblock ~41 ~16 ~15 bookshelf 0
setblock ~41 ~16 ~19 planks 1
fill ~41 ~16 ~44 ~45 ~16 ~44 stained_glass 15
setblock ~42 ~16 ~12 stained_hardened_clay 13
setblock ~42 ~16 ~15 green_glazed_terracotta 0
setblock ~42 ~16 ~19 orange_glazed_terracotta 0
setblock ~42 ~16 ~20 stained_hardened_clay 5
setblock ~42 ~16 ~21 stained_hardened_clay 9
setblock ~43 ~16 ~11 stained_hardened_clay 13
setblock ~43 ~16 ~20 orange_glazed_terracotta 0
setblock ~43 ~16 ~21 stained_hardened_clay 13
setblock ~43 ~16 ~22 mossy_cobblestone 0
setblock ~44 ~16 ~11 stained_hardened_clay 9
fill ~44 ~16 ~22 ~45 ~16 ~22 brown_glazed_terracotta 0
setblock ~45 ~16 ~11 bedrock 0
setblock ~45 ~16 ~25 stonebrick 1
setblock ~46 ~16 ~11 log 0
setblock ~46 ~16 ~22 stained_hardened_clay 13
setblock ~46 ~16 ~23 mossy_cobblestone 0
setblock ~46 ~16 ~24 stained_hardened_clay 5
fill ~46 ~16 ~25 ~46 ~17 ~25 gold_ore 0
fill ~46 ~16 ~43 ~47 ~16 ~43 stained_glass 15
setblock ~47 ~16 ~12 log 0
setblock ~47 ~16 ~22 brown_glazed_terracotta 0
setblock ~47 ~16 ~24 gold_ore 0
setblock ~48 ~16 ~12 log 1
setblock ~48 ~16 ~23 green_glazed_terracotta 0
fill ~48 ~16 ~44 ~53 ~16 ~44 stained_glass 15
setblock ~49 ~16 ~12 stained_hardened_clay 5
setblock ~49 ~16 ~13 log2 0
setblock ~49 ~16 ~22 green_glazed_terracotta 0
fill ~50 ~16 ~2 ~50 ~61 ~2 stained_glass 15
setblock ~50 ~16 ~13 stained_hardened_clay 13
setblock ~50 ~16 ~22 stained_hardened_clay 13
setblock ~51 ~16 ~14 bedrock 0
setblock ~51 ~16 ~22 bedrock 0
fill ~52 ~16 ~1 ~56 ~16 ~1 stained_glass 15
setblock ~52 ~16 ~14 stained_hardened_clay 13
setblock ~52 ~16 ~22 stained_hardened_clay 13
setblock ~53 ~16 ~15 stained_hardened_clay 13
fill ~53 ~16 ~23 ~53 ~15 ~23 bedrock 0
setblock ~53 ~16 ~24 gold_ore 0
setblock ~54 ~16 ~16 log2 1
fill ~54 ~16 ~24 ~54 ~17 ~24 mossy_cobblestone 0
fill ~54 ~16 ~45 ~54 ~30 ~45 stained_glass 15
setblock ~55 ~16 ~17 log2 1
setblock ~55 ~16 ~25 wool 8
setblock ~56 ~16 ~17 concrete 7
setblock ~56 ~16 ~25 planks 2
fill ~57 ~16 ~2 ~58 ~16 ~2 stained_glass 15
setblock ~57 ~16 ~16 stained_hardened_clay 13
fill ~57 ~16 ~44 ~57 ~22 ~44 stained_glass 15
setblock ~58 ~16 ~16 stained_hardened_clay 7
fill ~58 ~16 ~24 ~58 ~17 ~24 mossy_cobblestone 0
fill ~58 ~16 ~43 ~59 ~16 ~43 stained_glass 15
fill ~59 ~16 ~3 ~62 ~16 ~3 stained_glass 15
setblock ~59 ~16 ~15 stained_hardened_clay 13
fill ~59 ~16 ~23 ~59 ~17 ~23 mossy_cobblestone 0
setblock ~60 ~16 ~14 stained_hardened_clay 13
setblock ~60 ~16 ~23 wool 8
setblock ~61 ~16 ~14 stained_hardened_clay 5
setblock ~61 ~16 ~23 green_glazed_terracotta 0
setblock ~62 ~16 ~13 stained_hardened_clay 5
setblock ~62 ~16 ~22 mycelium 0
setblock ~62 ~16 ~23 orange_glazed_terracotta 0
fill ~62 ~16 ~41 ~62 ~21 ~41 stained_glass 15
fill ~63 ~16 ~4 ~69 ~16 ~4 stained_glass 15
setblock ~63 ~16 ~14 brown_glazed_terracotta 0
setblock ~63 ~16 ~21 brown_glazed_terracotta 0
fill ~63 ~16 ~40 ~64 ~16 ~40 stained_glass 15
fill ~64 ~16 ~13 ~65 ~16 ~13 stained_hardened_clay 13
setblock ~64 ~16 ~18 log 1
setblock ~64 ~16 ~21 wool 8
fill ~65 ~16 ~18 ~65 ~17 ~18 brown_glazed_terracotta 0
setblock ~65 ~16 ~19 stained_hardened_clay 13
setblock ~65 ~16 ~21 orange_glazed_terracotta 0
fill ~65 ~16 ~39 ~66 ~16 ~39 stained_glass 15
fill ~66 ~16 ~13 ~67 ~16 ~13 mossy_cobblestone 0
setblock ~66 ~16 ~17 mossy_cobblestone 0
setblock ~66 ~16 ~19 planks 1
setblock ~66 ~16 ~21 planks 2
setblock ~67 ~16 ~17 wool 8
setblock ~67 ~16 ~19 stained_hardened_clay 13
fill ~67 ~16 ~21 ~67 ~18 ~21 wool 8
fill ~67 ~16 ~38 ~72 ~16 ~38 stained_glass 15
setblock ~68 ~16 ~13 stonebrick 1
setblock ~68 ~16 ~16 green_glazed_terracotta 0
setblock ~68 ~16 ~20 green_glazed_terracotta 0
setblock ~68 ~16 ~21 planks 2
setblock ~69 ~16 ~13 concrete 8
setblock ~69 ~16 ~16 wool 8
setblock ~69 ~16 ~20 bookshelf 0
setblock ~69 ~16 ~21 stonebrick 1
fill ~70 ~16 ~5 ~76 ~16 ~5 stained_glass 15
setblock ~70 ~16 ~13 stained_hardened_clay 5
setblock ~70 ~16 ~16 mossy_cobblestone 0
setblock ~70 ~16 ~20 gold_ore 0
setblock ~71 ~16 ~14 gold_ore 0
setblock ~71 ~16 ~15 wool 8
fill ~73 ~16 ~37 ~73 ~18 ~37 stained_glass 15
fill ~74 ~16 ~38 ~77 ~16 ~38 stained_glass 15
fill ~77 ~16 ~4 ~82 ~16 ~4 stained_glass 15
fill ~78 ~16 ~39 ~82 ~16 ~39 stained_glass 15
fill ~83 ~16 ~5 ~83 ~25 ~5 stained_glass 15
fill ~83 ~16 ~40 ~83 ~32 ~40 stained_glass 15
fill ~84 ~16 ~39 ~92 ~16 ~39 stained_glass 15
fill ~88 ~16 ~7 ~89 ~16 ~7 stained_glass 15
setblock ~88 ~16 ~25 sandstone 0
fill ~88 ~16 ~26 ~89 ~16 ~26 orange_glazed_terracotta 0
setblock ~89 ~16 ~24 stone 3
setblock ~89 ~16 ~25 planks 2
fill ~90 ~16 ~8 ~95 ~16 ~8 stained_glass 15
setblock ~90 ~16 ~23 double_stone_slab 8
fill ~90 ~16 ~24 ~90 ~18 ~24 gold_ore 0
fill ~90 ~16 ~25 ~90 ~17 ~25 wool 8
setblock ~90 ~16 ~26 green_glazed_terracotta 0
setblock ~91 ~16 ~22 planks 2
setblock ~91 ~16 ~23 stone 3
setblock ~91 ~16 ~24 double_stone_slab 8
fill ~91 ~16 ~25 ~92 ~16 ~25 gold_ore 0
setblock ~92 ~16 ~22 wool 8
setblock ~92 ~16 ~23 double_stone_slab 8
fill ~92 ~16 ~24 ~92 ~17 ~24 mossy_cobblestone 0
fill ~93 ~16 ~40 ~97 ~16 ~40 stained_glass 15
fill ~96 ~16 ~7 ~103 ~16 ~7 stained_glass 15
fill ~98 ~16 ~41 ~105 ~16 ~41 stained_glass 15
setblock ~104 ~16 ~8 stained_glass 15
fill ~106 ~16 ~8 ~108 ~16 ~8 stained_glass 15
fill ~108 ~16 ~39 ~109 ~16 ~39 stained_glass 15
fill ~109 ~16 ~9 ~110 ~16 ~9 stained_glass 15
fill ~114 ~16 ~35 ~114 ~17 ~35 stained_glass 15
fill ~117 ~16 ~18 ~117 ~19 ~18 stained_glass 15
fill ~122 ~16 ~28 ~122 ~24 ~28 stained_glass 15
fill ~125 ~16 ~22 ~125 ~17 ~22 stained_glass 15
fill ~16 ~17 ~21 ~17 ~17 ~21 stained_glass 15
fill ~21 ~17 ~19 ~21 ~20 ~19 stained_glass 15
fill ~30 ~17 ~40 ~31 ~17 ~40 stained_glass 15
fill ~32 ~17 ~41 ~33 ~17 ~41 stained_glass 15
fill ~33 ~17 ~6 ~34 ~17 ~6 stained_glass 15
fill ~34 ~17 ~42 ~36 ~17 ~42 stained_glass 15
fill ~35 ~17 ~5 ~38 ~17 ~5 stained_glass 15
setblock ~36 ~17 ~18 mycelium 0
setblock ~36 ~17 ~19 bookshelf 0
setblock ~36 ~17 ~20 concrete 8
setblock ~36 ~17 ~21 mossy_cobblestone 0
fill ~37 ~17 ~17 ~37 ~18 ~17 soul_sand 0
setblock ~37 ~17 ~19 bedrock 0
setblock ~37 ~17 ~20 gold_ore 0
setblock ~37 ~17 ~21 brown_glazed_terracotta 0
fill ~37 ~17 ~43 ~41 ~17 ~43 stained_glass 15
setblock ~38 ~17 ~16 bedrock 0
setblock ~38 ~17 ~17 stained_hardened_clay 12
setblock ~38 ~17 ~20 stained_hardened_clay 13
setblock ~38 ~17 ~21 planks 1
fill ~39 ~17 ~4 ~46 ~17 ~4 stained_glass 15
setblock ~39 ~17 ~14 wool 8
setblock ~39 ~17 ~15 brown_mushroom_block 0
setblock ~39 ~17 ~16 brown_glazed_terracotta 0
setblock ~39 ~17 ~20 log 3
fill ~39 ~17 ~21 ~39 ~18 ~21 stained_hardened_clay 13
fill ~40 ~17 ~12 ~41 ~17 ~12 bookshelf 0
setblock ~40 ~17 ~13 stained_hardened_clay 13
setblock ~40 ~17 ~14 mossy_cobblestone 0
setblock ~40 ~17 ~15 stained_hardened_clay 13
fill ~40 ~17 ~20 ~40 ~17 ~21 log2 1
setblock ~41 ~17 ~14 stained_hardened_clay 12
setblock ~41 ~17 ~20 stained_hardened_clay 13
setblock ~41 ~17 ~21 log 1
setblock ~42 ~17 ~12 log 3
setblock ~42 ~17 ~21 stained_hardened_clay 13
fill ~42 ~17 ~44 ~45 ~17 ~44 stained_glass 15
setblock ~43 ~17 ~11 brown_glazed_terracotta 0
setblock ~43 ~17 ~21 stained_hardened_clay 5
fill ~44 ~17 ~11 ~44 ~18 ~11 bedrock 0
setblock ~44 ~17 ~21 stained_hardened_clay 13
fill ~44 ~17 ~25 ~45 ~17 ~25 mossy_cobblestone 0
setblock ~45 ~17 ~11 stained_hardened_clay 13
setblock ~45 ~17 ~22 bedrock 0
setblock ~46 ~17 ~10 redstone_ore 0
setblock ~46 ~17 ~12 mycelium 0
setblock ~46 ~17 ~22 concrete 7
fill ~46 ~17 ~24 ~47 ~17 ~24 mossy_cobblestone 0
fill ~46 ~17 ~43 ~46 ~10 ~43 stained_glass 15
fill ~47 ~17 ~3 ~47 ~27 ~3 stained_glass 15
setblock ~47 ~17 ~12 soul_sand 0
setblock ~47 ~17 ~23 stained_hardened_clay 13
fill ~47 ~17 ~25 ~47 ~18 ~25 mossy_cobblestone 0
fill ~47 ~17 ~44 ~53 ~17 ~44 stained_glass 15
setblock ~48 ~17 ~11 stained_hardened_clay 15
setblock ~48 ~17 ~12 stained_hardened_clay 12
fill ~48 ~17 ~24 ~48 ~18 ~24 brown_glazed_terracotta 0
setblock ~49 ~17 ~11 log2 1
setblock ~49 ~17 ~23 stained_hardened_clay 5
setblock ~50 ~17 ~11 stained_hardened_clay 7
fill ~50 ~17 ~12 ~51 ~17 ~12 stained_hardened_clay 13
setblock ~50 ~17 ~23 stained_hardened_clay 13
setblock ~51 ~17 ~11 log2 1
setblock ~51 ~17 ~13 brown_glazed_terracotta 0
fill ~51 ~17 ~14 ~52 ~17 ~14 log2 1
fill ~51 ~17 ~23 ~52 ~17 ~23 stained_hardened_clay 7
fill ~52 ~17 ~1 ~56 ~17 ~1 stained_glass 15
setblock ~52 ~17 ~12 stained_hardened_clay 12
setblock ~52 ~17 ~13 stained_hardened_clay 8
setblock ~53 ~17 ~13 bedrock 0
setblock ~53 ~17 ~14 mycelium 0
fill ~53 ~17 ~15 ~54 ~17 ~15 log2 1
setblock ~53 ~17 ~24 stonebrick 1
setblock ~55 ~17 ~16 log2 1
setblock ~55 ~17 ~25 green_glazed_terracotta 0
setblock ~56 ~17 ~17 nether_brick 0
fill ~56 ~17 ~25 ~56 ~18 ~25 wool 8
fill ~57 ~17 ~2 ~58 ~17 ~2 stained_glass 15
setblock ~57 ~17 ~16 stained_hardened_clay 7
setblock ~58 ~17 ~15 stained_hardened_clay 15
fill ~58 ~17 ~43 ~59 ~17 ~43 stained_glass 15
fill ~59 ~17 ~3 ~61 ~17 ~3 stained_glass 15
setblock ~59 ~17 ~14 stained_hardened_clay 13
fill ~60 ~17 ~13 ~61 ~17 ~13 stained_hardened_clay 13
setblock ~60 ~17 ~23 log2 0
setblock ~61 ~17 ~23 gold_ore 0
fill ~62 ~17 ~4 ~66 ~17 ~4 stained_glass 15
setblock ~62 ~17 ~13 log2 1
setblock ~62 ~17 ~22 brown_glazed_terracotta 0
setblock ~62 ~17 ~23 brown_mushroom_block 0
fill ~63 ~17 ~12 ~65 ~17 ~12 stained_hardened_clay 5
setblock ~63 ~17 ~13 stained_hardened_clay 13
fill ~63 ~17 ~21 ~66 ~17 ~21 gold_ore 0
fill ~63 ~17 ~40 ~64 ~17 ~40 stained_glass 15
fill ~65 ~17 ~39 ~66 ~17 ~39 stained_glass 15
fill ~66 ~17 ~13 ~66 ~17 ~14 mycelium 0
setblock ~66 ~17 ~18 stained_hardened_clay 13
fill ~67 ~17 ~5 ~84 ~17 ~5 stained_glass 15
setblock ~67 ~17 ~13 mossy_cobblestone 0
setblock ~67 ~17 ~14 log2 0
setblock ~67 ~17 ~17 green_glazed_terracotta 0
setblock ~67 ~17 ~18 soul_sand 0
fill ~67 ~17 ~19 ~68 ~17 ~19 log 1
fill ~67 ~17 ~38 ~70 ~17 ~38 stained_glass 15
setblock ~68 ~17 ~13 stained_hardened_clay 5
fill ~68 ~17 ~14 ~69 ~17 ~14 stained_hardened_clay 13
setblock ~68 ~17 ~17 stained_hardened_clay 13
setblock ~68 ~17 ~21 gold_ore 0
setblock ~69 ~17 ~16 stonebrick 1
setblock ~69 ~17 ~20 wool 13
setblock ~69 ~17 ~21 wool 8
setblock ~70 ~17 ~14 brown_glazed_terracotta 0
setblock ~70 ~17 ~16 gold_ore 0
setblock ~70 ~17 ~20 stained_hardened_clay 5
setblock ~70 ~17 ~21 gold_ore 0
setblock ~71 ~17 ~14 stonebrick 1
setblock ~71 ~17 ~15 gold_ore 0
setblock ~71 ~17 ~20 wool 8
fill ~71 ~17 ~37 ~73 ~17 ~37 stained_glass 15
fill ~74 ~17 ~38 ~77 ~17 ~38 stained_glass 15
fill ~78 ~17 ~39 ~82 ~17 ~39 stained_glass 15
fill ~84 ~17 ~39 ~90 ~17 ~39 stained_glass 15
fill ~85 ~17 ~6 ~85 ~22 ~6 stained_glass 15
fill ~87 ~17 ~7 ~104 ~17 ~7 stained_glass 15
fill ~87 ~17 ~26 ~88 ~17 ~26 planks 2
fill ~88 ~17 ~27 ~89 ~17 ~27 stained_hardened_clay 5
fill ~89 ~17 ~25 ~89 ~18 ~25 double_stone_slab 8
fill ~90 ~17 ~23 ~90 ~18 ~23 wool 8
fill ~90 ~17 ~26 ~90 ~18 ~26 stained_hardened_clay 5
setblock ~91 ~17 ~22 orange_glazed_terracotta 0
setblock ~91 ~17 ~24 gold_ore 0
fill ~91 ~17 ~26 ~91 ~18 ~26 green_glazed_terracotta 0
fill ~91 ~17 ~40 ~97 ~17 ~40 stained_glass 15
fill ~92 ~17 ~22 ~92 ~18 ~22 gold_ore 0
setblock ~92 ~17 ~25 stained_hardened_clay 5
setblock ~93 ~17 ~22 orange_glazed_terracotta 0
fill ~93 ~17 ~23 ~93 ~18 ~23 mossy_cobblestone 0
fill ~98 ~17 ~41 ~105 ~17 ~41 stained_glass 15
fill ~106 ~17 ~8 ~108 ~17 ~8 stained_glass 15
fill ~108 ~17 ~39 ~109 ~17 ~39 stained_glass 15
fill ~109 ~17 ~9 ~110 ~17 ~9 stained_glass 15
fill ~113 ~17 ~11 ~113 ~19 ~11 stained_glass 15
fill ~114 ~17 ~12 ~114 ~20 ~12 stained_glass 15
fill ~114 ~17 ~36 ~114 ~27 ~36 stained_glass 15
fill ~121 ~17 ~20 ~121 ~29 ~20 stained_glass 15
fill ~123 ~17 ~21 ~123 ~32 ~21 stained_glass 15
fill ~124 ~17 ~22 ~124 ~29 ~22 stained_glass 15
fill ~125 ~17 ~26 ~125 ~27 ~26 stained_glass 15
fill ~16 ~18 ~22 ~16 ~25 ~22 stained_glass 15
fill ~17 ~18 ~21 ~17 ~30 ~21 stained_glass 15
setblock ~19 ~18 ~28 stained_glass 15
fill ~30 ~18 ~40 ~31 ~18 ~40 stained_glass 15
fill ~32 ~18 ~41 ~33 ~18 ~41 stained_glass 15
fill ~33 ~18 ~6 ~34 ~18 ~6 stained_glass 15
fill ~34 ~18 ~42 ~36 ~18 ~42 stained_glass 15
fill ~35 ~18 ~5 ~38 ~18 ~5 stained_glass 15
setblock ~35 ~18 ~19 log2 0
setblock ~35 ~18 ~20 stonebrick 1
setblock ~36 ~18 ~17 gold_ore 0
setblock ~36 ~18 ~18 brown_glazed_terracotta 0
setblock ~36 ~18 ~21 brown_glazed_terracotta 0
setblock ~37 ~18 ~14 orange_glazed_terracotta 0
fill ~37 ~18 ~15 ~38 ~18 ~15 brown_mushroom_block 0
setblock ~37 ~18 ~21 stained_hardened_clay 9
fill ~37 ~18 ~43 ~41 ~18 ~43 stained_glass 15
setblock ~38 ~18 ~14 brown_glazed_terracotta 0
setblock ~38 ~18 ~16 stained_hardened_clay 13
setblock ~38 ~18 ~22 mycelium 0
fill ~39 ~18 ~4 ~45 ~18 ~4 stained_glass 15
setblock ~39 ~18 ~12 gold_ore 0
setblock ~39 ~18 ~13 mycelium 0
setblock ~39 ~18 ~14 gold_ore 0
fill ~40 ~18 ~12 ~40 ~17 ~12 bookshelf 0
setblock ~40 ~18 ~13 soul_sand 0
fill ~40 ~18 ~21 ~41 ~18 ~21 stained_hardened_clay 13
setblock ~41 ~18 ~12 bedrock 0
setblock ~42 ~18 ~11 brown_glazed_terracotta 0
setblock ~42 ~18 ~22 mycelium 0
fill ~42 ~18 ~44 ~52 ~18 ~44 stained_glass 15
setblock ~43 ~18 ~11 mycelium 0
setblock ~43 ~18 ~22 mossy_cobblestone 0
setblock ~43 ~18 ~23 brown_glazed_terracotta 0
setblock ~44 ~18 ~10 stained_hardened_clay 13
setblock ~44 ~18 ~22 soul_sand 0
setblock ~44 ~18 ~23 mossy_cobblestone 0
setblock ~44 ~18 ~25 stonebrick 1
setblock ~44 ~18 ~26 green_glazed_terracotta 0
setblock ~45 ~18 ~8 orange_glazed_terracotta 0
setblock ~45 ~18 ~9 stained_hardened_clay 5
setblock ~45 ~18 ~10 bedrock 0
setblock ~45 ~18 ~11 mycelium 0
setblock ~45 ~18 ~23 stained_hardened_clay 13
setblock ~45 ~18 ~25 bedrock 0
setblock ~45 ~18 ~26 double_stone_slab 8
fill ~46 ~18 ~3 ~46 ~63 ~3 stained_glass 15
setblock ~46 ~18 ~8 log 0
setblock ~46 ~18 ~9 brown_glazed_terracotta 0
setblock ~46 ~18 ~11 bedrock 0
fill ~46 ~18 ~23 ~46 ~18 ~24 bedrock 0
fill ~46 ~18 ~26 ~46 ~19 ~26 mossy_cobblestone 0
setblock ~47 ~18 ~8 planks 2
setblock ~47 ~18 ~9 planks 1
setblock ~47 ~18 ~10 stonebrick 2
setblock ~47 ~18 ~11 mossy_cobblestone 0
setblock ~48 ~18 ~8 bookshelf 0
setblock ~48 ~18 ~9 soul_sand 0
setblock ~48 ~18 ~10 log 1
fill ~49 ~18 ~2 ~49 ~59 ~2 stained_glass 15
setblock ~49 ~18 ~9 bedrock 0
setblock ~49 ~18 ~10 mycelium 0
setblock ~49 ~18 ~24 mossy_cobblestone 0
fill ~50 ~18 ~9 ~51 ~18 ~9 stained_hardened_clay 13
setblock ~50 ~18 ~10 log2 1
setblock ~50 ~18 ~23 gold_ore 0
setblock ~51 ~18 ~10 mycelium 0
setblock ~51 ~18 ~11 stained_hardened_clay 12
setblock ~51 ~18 ~23 mossy_cobblestone 0
fill ~52 ~18 ~1 ~56 ~18 ~1 stained_glass 15
setblock ~52 ~18 ~10 log 3
setblock ~52 ~18 ~11 stained_hardened_clay 13
fill ~52 ~18 ~24 ~52 ~19 ~24 stained_hardened_clay 13
setblock ~53 ~18 ~11 log 3
setblock ~53 ~18 ~12 log2 0
setblock ~53 ~18 ~24 concrete 8
fill ~53 ~18 ~45 ~53 ~23 ~45 stained_glass 15
setblock ~54 ~18 ~11 log 0
setblock ~54 ~18 ~12 stained_hardened_clay 12
setblock ~54 ~18 ~13 log 0
setblock ~54 ~18 ~14 log2 1
setblock ~54 ~18 ~15 bedrock 0
setblock ~54 ~18 ~25 wool 8
setblock ~55 ~18 ~11 brown_mushroom_block 0
setblock ~55 ~18 ~12 mycelium 0
setblock ~55 ~18 ~13 stained_hardened_clay 13
setblock ~55 ~18 ~14 mycelium 0
setblock ~55 ~18 ~15 concrete 7
setblock ~55 ~18 ~16 stained_hardened_clay 12
setblock ~55 ~18 ~25 planks 2
setblock ~56 ~18 ~15 log 1
setblock ~56 ~18 ~16 log2 1
fill ~57 ~18 ~2 ~58 ~18 ~2 stained_glass 15
setblock ~57 ~18 ~15 stained_hardened_clay 12
setblock ~57 ~18 ~24 wool 8
setblock ~58 ~18 ~14 stained_hardened_clay 15
fill ~58 ~18 ~24 ~58 ~19 ~24 brown_glazed_terracotta 0
setblock ~58 ~18 ~44 stained_glass 15
fill ~59 ~18 ~3 ~60 ~18 ~3 stained_glass 15
setblock ~59 ~18 ~13 stained_hardened_clay 7
setblock ~59 ~18 ~24 gold_ore 0
fill ~59 ~18 ~43 ~59 ~20 ~43 stained_glass 15
setblock ~60 ~18 ~13 soul_sand 0
setblock ~60 ~18 ~24 mycelium 0
fill ~61 ~18 ~4 ~64 ~18 ~4 stained_glass 15
setblock ~61 ~18 ~13 stained_hardened_clay 13
setblock ~61 ~18 ~23 wool 8
setblock ~62 ~18 ~12 stained_hardened_clay 13
setblock ~62 ~18 ~13 stained_hardened_clay 7
setblock ~62 ~18 ~23 planks 2
setblock ~63 ~18 ~11 stained_hardened_clay 13
fill ~63 ~18 ~22 ~64 ~18 ~22 gold_ore 0
setblock ~63 ~18 ~23 brown_glazed_terracotta 0
fill ~63 ~18 ~40 ~64 ~18 ~40 stained_glass 15
fill ~64 ~18 ~11 ~64 ~20 ~11 bookshelf 0
fill ~65 ~18 ~5 ~84 ~18 ~5 stained_glass 15
setblock ~65 ~18 ~12 bookshelf 0
setblock ~65 ~18 ~21 stonebrick 1
setblock ~65 ~18 ~22 wool 8
fill ~65 ~18 ~39 ~66 ~18 ~39 stained_glass 15
setblock ~66 ~18 ~12 planks 1
setblock ~66 ~18 ~21 orange_glazed_terracotta 0
setblock ~67 ~18 ~12 planks 2
setblock ~67 ~18 ~13 soul_sand 0
fill ~67 ~18 ~38 ~70 ~18 ~38 stained_glass 15
setblock ~68 ~18 ~13 log 3
fill ~68 ~18 ~14 ~68 ~17 ~14 stained_hardened_clay 13
fill ~68 ~18 ~15 ~69 ~18 ~15 stained_hardened_clay 13
setblock ~68 ~18 ~18 concrete 13
fill ~68 ~18 ~21 ~69 ~18 ~21 double_stone_slab 8
setblock ~69 ~18 ~17 brown_glazed_terracotta 0
setblock ~69 ~18 ~18 stained_hardened_clay 5
setblock ~69 ~18 ~19 planks 1
setblock ~70 ~18 ~15 gold_ore 0
setblock ~70 ~18 ~16 stained_hardened_clay 5
setblock ~70 ~18 ~17 mossy_cobblestone 0
setblock ~70 ~18 ~19 stained_hardened_clay 13
setblock ~70 ~18 ~21 planks 2
setblock ~71 ~18 ~17 gold_ore 0
setblock ~71 ~18 ~20 orange_glazed_terracotta 0
fill ~71 ~18 ~37 ~73 ~18 ~37 stained_glass 15
fill ~74 ~18 ~38 ~77 ~18 ~38 stained_glass 15
fill ~78 ~18 ~39 ~81 ~18 ~39 stained_glass 15
fill ~82 ~18 ~40 ~82 ~39 ~40 stained_glass 15
fill ~84 ~18 ~40 ~84 ~26 ~40 stained_glass 15
fill ~85 ~18 ~39 ~86 ~18 ~39 stained_glass 15
fill ~87 ~18 ~7 ~104 ~18 ~7 stained_glass 15
setblock ~87 ~18 ~26 stained_hardened_clay 0
fill ~87 ~18 ~40 ~96 ~18 ~40 stained_glass 15
fill ~88 ~18 ~26 ~88 ~19 ~26 planks 2
setblock ~88 ~18 ~27 green_glazed_terracotta 0
setblock ~89 ~18 ~27 stained_hardened_clay 5
setblock ~90 ~18 ~25 double_stone_slab 8
fill ~91 ~18 ~22 ~91 ~20 ~22 planks 2
fill ~91 ~18 ~25 ~91 ~20 ~25 wool 8
setblock ~92 ~18 ~24 stained_hardened_clay 5
setblock ~92 ~18 ~25 orange_glazed_terracotta 0
setblock ~93 ~18 ~22 wool 8
fill ~97 ~18 ~41 ~104 ~18 ~41 stained_glass 15
fill ~105 ~18 ~40 ~105 ~22 ~40 stained_glass 15
fill ~106 ~18 ~8 ~108 ~18 ~8 stained_glass 15
fill ~108 ~18 ~39 ~109 ~18 ~39 stained_glass 15
fill ~109 ~18 ~9 ~110 ~18 ~9 stained_glass 15
fill ~113 ~18 ~37 ~113 ~30 ~37 stained_glass 15
fill ~115 ~18 ~35 ~115 ~28 ~35 stained_glass 15
fill ~117 ~18 ~32 ~117 ~27 ~32 stained_glass 15
fill ~121 ~18 ~29 ~121 ~29 ~29 stained_glass 15
fill ~122 ~18 ~21 ~122 ~26 ~21 stained_glass 15
fill ~125 ~18 ~23 ~125 ~26 ~23 stained_glass 15
setblock ~18 ~19 ~21 stained_glass 15
fill ~19 ~19 ~29 ~19 ~24 ~29 stained_glass 15
fill ~25 ~19 ~12 ~25 ~28 ~12 stained_glass 15
fill ~30 ~19 ~40 ~31 ~19 ~40 stained_glass 15
fill ~32 ~19 ~41 ~33 ~19 ~41 stained_glass 15
fill ~33 ~19 ~6 ~34 ~19 ~6 stained_glass 15
setblock ~34 ~19 ~20 soul_sand 0
setblock ~34 ~19 ~21 wool 7
fill ~34 ~19 ~42 ~36 ~19 ~42 stained_glass 15
fill ~35 ~19 ~5 ~38 ~19 ~5 stained_glass 15
setblock ~35 ~19 ~19 brown_glazed_terracotta 0
fill ~35 ~19 ~21 ~37 ~19 ~21 stained_hardened_clay 7
fill ~36 ~19 ~13 ~37 ~19 ~13 stonebrick 1
setblock ~36 ~19 ~14 bedrock 0
setblock ~36 ~19 ~15 brown_glazed_terracotta 0
setblock ~36 ~19 ~16 soul_sand 0
setblock ~36 ~19 ~17 log2 1
setblock ~36 ~19 ~18 log 3
setblock ~37 ~19 ~16 bookshelf 0
fill ~37 ~19 ~43 ~41 ~19 ~43 stained_glass 15
setblock ~38 ~19 ~12 brown_glazed_terracotta 0
setblock ~38 ~19 ~13 stained_hardened_clay 13
setblock ~38 ~19 ~21 concrete 7
fill ~39 ~19 ~4 ~45 ~19 ~4 stained_glass 15
setblock ~39 ~19 ~12 stonebrick 1
setblock ~39 ~19 ~22 mycelium 0
setblock ~40 ~19 ~12 brown_glazed_terracotta 0
setblock ~40 ~19 ~22 stained_hardened_clay 13
setblock ~41 ~19 ~11 brown_glazed_terracotta 0
fill ~41 ~19 ~22 ~41 ~20 ~22 brown_glazed_terracotta 0
setblock ~42 ~19 ~11 stained_hardened_clay 13
setblock ~42 ~19 ~23 mycelium 0
fill ~42 ~19 ~44 ~52 ~19 ~44 stained_glass 15
setblock ~43 ~19 ~8 log2 0
setblock ~43 ~19 ~10 stained_hardened_clay 5
fill ~43 ~19 ~23 ~44 ~19 ~23 stained_hardened_clay 13
setblock ~44 ~19 ~8 bookshelf 0
setblock ~44 ~19 ~9 orange_glazed_terracotta 0
setblock ~44 ~19 ~25 bedrock 0
fill ~44 ~19 ~26 ~44 ~20 ~26 brown_glazed_terracotta 0
fill ~45 ~19 ~7 ~46 ~19 ~7 soul_sand 0
fill ~45 ~19 ~24 ~46 ~19 ~24 wool 7
fill ~45 ~19 ~25 ~45 ~19 ~24 wool 7
setblock ~45 ~19 ~26 gold_ore 0
setblock ~45 ~19 ~28 cobblestone 0
setblock ~47 ~19 ~8 bedrock 0
setblock ~47 ~19 ~25 gold_ore 0
setblock ~48 ~19 ~8 mycelium 0
setblock ~48 ~19 ~25 mycelium 0
fill ~49 ~19 ~8 ~49 ~20 ~8 stained_hardened_clay 13
setblock ~49 ~19 ~24 stonebrick 1
setblock ~50 ~19 ~8 stonebrick 1
setblock ~50 ~19 ~24 mossy_cobblestone 0
setblock ~51 ~19 ~8 gold_ore 0
setblock ~51 ~19 ~24 wool 7
fill ~52 ~19 ~1 ~56 ~19 ~1 stained_glass 15
setblock ~52 ~19 ~9 stained_hardened_clay 5
setblock ~53 ~19 ~9 stained_hardened_clay 13
setblock ~53 ~19 ~10 log 3
setblock ~53 ~19 ~24 gold_ore 0
setblock ~54 ~19 ~10 stained_hardened_clay 5
setblock ~54 ~19 ~25 mycelium 0
setblock ~55 ~19 ~11 planks 1
fill ~55 ~19 ~25 ~55 ~20 ~25 gold_ore 0
setblock ~56 ~19 ~12 stained_hardened_clay 5
fill ~56 ~19 ~13 ~57 ~19 ~13 stained_hardened_clay 13
fill ~56 ~19 ~14 ~56 ~19 ~13 stained_hardened_clay 13
setblock ~56 ~19 ~25 stonebrick 1
fill ~57 ~19 ~2 ~57 ~36 ~2 stained_glass 15
setblock ~57 ~19 ~14 stained_hardened_clay 8
setblock ~57 ~19 ~24 concrete 8
fill ~58 ~19 ~3 ~60 ~19 ~3 stained_glass 15
setblock ~58 ~19 ~13 coal_block 0
fill ~58 ~19 ~43 ~58 ~25 ~43 stained_glass 15
setblock ~59 ~19 ~13 stained_hardened_clay 15
setblock ~59 ~19 ~24 wool 8
setblock ~60 ~19 ~12 log2 1
setblock ~60 ~19 ~24 brown_glazed_terracotta 0
fill ~61 ~19 ~4 ~63 ~19 ~4 stained_glass 15
setblock ~61 ~19 ~12 stained_hardened_clay 12
setblock ~61 ~19 ~23 bedrock 0
setblock ~62 ~19 ~11 log2 1
fill ~62 ~19 ~23 ~62 ~20 ~23 brown_glazed_terracotta 0
setblock ~63 ~19 ~11 log 3
fill ~63 ~19 ~22 ~63 ~18 ~22 gold_ore 0
setblock ~63 ~19 ~23 stained_hardened_clay 13
fill ~63 ~19 ~40 ~64 ~19 ~40 stained_glass 15
fill ~64 ~19 ~5 ~70 ~19 ~5 stained_glass 15
setblock ~64 ~19 ~22 stonebrick 1
fill ~65 ~19 ~11 ~65 ~21 ~11 bookshelf 0
setblock ~65 ~19 ~23 gold_ore 0
fill ~65 ~19 ~39 ~66 ~19 ~39 stained_glass 15
setblock ~66 ~19 ~11 planks 0
setblock ~66 ~19 ~20 green_glazed_terracotta 0
setblock ~66 ~19 ~21 stained_hardened_clay 13
setblock ~66 ~19 ~22 brown_glazed_terracotta 0
setblock ~67 ~19 ~12 log 0
setblock ~67 ~19 ~20 wool 8
fill ~67 ~19 ~38 ~70 ~19 ~38 stained_glass 15
setblock ~68 ~19 ~12 bookshelf 0
setblock ~68 ~19 ~13 stained_hardened_clay 13
fill ~68 ~19 ~21 ~68 ~20 ~21 orange_glazed_terracotta 0
setblock ~69 ~19 ~13 log 0
setblock ~69 ~19 ~14 planks 1
setblock ~69 ~19 ~21 wool 8
setblock ~70 ~19 ~14 log 3
setblock ~70 ~19 ~15 log 1
fill ~70 ~19 ~18 ~71 ~19 ~18 stained_hardened_clay 5
fill ~70 ~19 ~21 ~71 ~19 ~21 gold_ore 0
fill ~71 ~19 ~6 ~72 ~19 ~6 stained_glass 15
setblock ~71 ~19 ~15 log2 1
setblock ~71 ~19 ~16 stained_hardened_clay 13
setblock ~71 ~19 ~19 stained_hardened_clay 13
fill ~71 ~19 ~37 ~72 ~19 ~37 stained_glass 15
fill ~72 ~19 ~16 ~72 ~19 ~17 stained_hardened_clay 5
setblock ~72 ~19 ~18 brown_glazed_terracotta 0
setblock ~72 ~19 ~20 stained_hardened_clay 5
fill ~73 ~19 ~5 ~84 ~19 ~5 stained_glass 15
setblock ~73 ~19 ~16 gold_ore 0
setblock ~73 ~19 ~17 brown_glazed_terracotta 0
setblock ~73 ~19 ~20 gold_ore 0
fill ~73 ~19 ~38 ~77 ~19 ~38 stained_glass 15
setblock ~74 ~19 ~16 mossy_cobblestone 0
fill ~78 ~19 ~39 ~80 ~19 ~39 stained_glass 15
fill ~81 ~19 ~40 ~81 ~38 ~40 stained_glass 15
fill ~85 ~19 ~40 ~93 ~19 ~40 stained_glass 15
fill ~87 ~19 ~7 ~89 ~19 ~7 stained_glass 15
fill ~88 ~19 ~27 ~88 ~20 ~27 stained_hardened_clay 5
fill ~89 ~19 ~25 ~91 ~19 ~25 wool 8
setblock ~89 ~19 ~27 wool 13
fill ~90 ~19 ~6 ~94 ~19 ~6 stained_glass 15
setblock ~90 ~19 ~23 gold_ore 0
setblock ~90 ~19 ~24 wool 8
setblock ~90 ~19 ~27 stained_hardened_clay 13
setblock ~91 ~19 ~24 double_stone_slab 8
setblock ~91 ~19 ~26 stained_hardened_clay 5
setblock ~92 ~19 ~22 orange_glazed_terracotta 0
fill ~92 ~19 ~24 ~92 ~19 ~25 green_glazed_terracotta 0
setblock ~93 ~19 ~22 gold_ore 0
setblock ~93 ~19 ~23 stained_hardened_clay 5
setblock ~93 ~19 ~24 orange_glazed_terracotta 0
fill ~94 ~19 ~41 ~103 ~19 ~41 stained_glass 15
fill ~95 ~19 ~7 ~103 ~19 ~7 stained_glass 15
fill ~104 ~19 ~8 ~104 ~25 ~8 stained_glass 15
fill ~104 ~19 ~40 ~104 ~23 ~40 stained_glass 15
fill ~106 ~19 ~8 ~108 ~19 ~8 stained_glass 15
fill ~108 ~19 ~39 ~109 ~19 ~39 stained_glass 15
fill ~109 ~19 ~9 ~110 ~19 ~9 stained_glass 15
setblock ~115 ~19 ~13 stained_glass 15
fill ~116 ~19 ~34 ~116 ~22 ~34 stained_glass 15
setblock ~118 ~19 ~19 stained_glass 15
fill ~120 ~19 ~20 ~120 ~24 ~20 stained_glass 15
fill ~124 ~19 ~27 ~124 ~28 ~27 stained_glass 15
fill ~14 ~20 ~25 ~14 ~29 ~25 stained_glass 15
fill ~15 ~20 ~26 ~15 ~33 ~26 stained_glass 15
fill ~18 ~20 ~20 ~18 ~31 ~20 stained_glass 15
fill ~20 ~20 ~30 ~20 ~28 ~30 stained_glass 15
fill ~24 ~20 ~35 ~24 ~26 ~35 stained_glass 15
fill ~30 ~20 ~40 ~31 ~20 ~40 stained_glass 15
fill ~32 ~20 ~41 ~33 ~20 ~41 stained_glass 15
fill ~33 ~20 ~6 ~35 ~20 ~6 stained_glass 15
setblock ~33 ~20 ~19 wool 7
setblock ~33 ~20 ~20 coal_ore 0
setblock ~33 ~20 ~21 bedrock 0
setblock ~34 ~20 ~18 stained_hardened_clay 13
setblock ~34 ~20 ~19 bedrock 0
setblock ~34 ~20 ~22 nether_brick 0
fill ~34 ~20 ~42 ~36 ~20 ~42 stained_glass 15
setblock ~35 ~20 ~14 stonebrick 1
setblock ~35 ~20 ~15 brown_mushroom_block 0
setblock ~35 ~20 ~16 gold_ore 0
setblock ~35 ~20 ~17 log 0
setblock ~35 ~20 ~18 bedrock 0
setblock ~35 ~20 ~21 stained_hardened_clay 12
fill ~36 ~20 ~5 ~38 ~20 ~5 stained_glass 15
setblock ~36 ~20 ~13 brown_glazed_terracotta 0
setblock ~36 ~20 ~21 wool 7
setblock ~37 ~20 ~13 planks 1
setblock ~37 ~20 ~14 gold_ore 0
setblock ~37 ~20 ~22 wool 7
fill ~37 ~20 ~43 ~41 ~20 ~43 stained_glass 15
setblock ~38 ~20 ~13 brown_glazed_terracotta 0
setblock ~38 ~20 ~22 stained_hardened_clay 12
fill ~39 ~20 ~4 ~41 ~20 ~4 stained_glass 15
setblock ~39 ~20 ~12 stained_hardened_clay 8
setblock ~39 ~20 ~22 concrete 7
setblock ~40 ~20 ~10 mossy_cobblestone 0
setblock ~40 ~20 ~11 gold_ore 0
setblock ~40 ~20 ~22 stained_hardened_clay 15
setblock ~41 ~20 ~10 wool 8
fill ~42 ~20 ~3 ~48 ~20 ~3 stained_glass 15
setblock ~42 ~20 ~8 brown_glazed_terracotta 0
setblock ~42 ~20 ~9 log2 0
setblock ~42 ~20 ~10 stained_hardened_clay 5
setblock ~42 ~20 ~23 stained_hardened_clay 13
fill ~42 ~20 ~44 ~52 ~20 ~44 stained_glass 15
setblock ~43 ~20 ~7 stained_hardened_clay 5
setblock ~43 ~20 ~9 brown_glazed_terracotta 0
setblock ~43 ~20 ~23 concrete 7
fill ~43 ~20 ~24 ~43 ~20 ~25 bedrock 0
setblock ~44 ~20 ~7 bedrock 0
setblock ~44 ~20 ~24 wool 7
setblock ~44 ~20 ~25 double_stone_slab 8
setblock ~44 ~20 ~27 stained_hardened_clay 9
setblock ~44 ~20 ~28 coal_ore 0
setblock ~45 ~20 ~7 mycelium 0
setblock ~45 ~20 ~24 bedrock 0
fill ~45 ~20 ~27 ~45 ~21 ~27 bedrock 0
setblock ~45 ~20 ~29 stonebrick 1
setblock ~46 ~20 ~7 bedrock 0
setblock ~46 ~20 ~26 stained_hardened_clay 13
setblock ~46 ~20 ~28 bedrock 0
setblock ~46 ~20 ~29 concrete 8
setblock ~47 ~20 ~7 stained_hardened_clay 12
setblock ~47 ~20 ~25 mossy_cobblestone 0
setblock ~48 ~20 ~7 soul_sand 0
setblock ~48 ~20 ~25 green_glazed_terracotta 0
setblock ~49 ~20 ~7 brown_glazed_terracotta 0
setblock ~49 ~20 ~25 gold_ore 0
setblock ~50 ~20 ~8 stained_hardened_clay 12
setblock ~50 ~20 ~24 planks 1
setblock ~51 ~20 ~8 brown_glazed_terracotta 0
fill ~51 ~20 ~24 ~52 ~20 ~24 mossy_cobblestone 0
fill ~52 ~20 ~1 ~55 ~20 ~1 stained_glass 15
setblock ~52 ~20 ~8 stained_hardened_clay 13
setblock ~53 ~20 ~9 stained_hardened_clay 5
fill ~53 ~20 ~25 ~53 ~21 ~25 stonebrick 1
setblock ~54 ~20 ~9 planks 1
setblock ~54 ~20 ~25 wool 8
setblock ~55 ~20 ~10 planks 1
fill ~56 ~20 ~2 ~56 ~34 ~2 stained_glass 15
setblock ~56 ~20 ~10 log 1
setblock ~56 ~20 ~11 stained_hardened_clay 5
setblock ~56 ~20 ~25 wool 8
setblock ~57 ~20 ~10 log 0
setblock ~57 ~20 ~11 log 3
setblock ~57 ~20 ~12 stained_hardened_clay 13
setblock ~57 ~20 ~25 stained_hardened_clay 9
fill ~58 ~20 ~3 ~59 ~20 ~3 stained_glass 15
setblock ~58 ~20 ~12 log2 1
fill ~58 ~20 ~25 ~59 ~20 ~25 wool 8
setblock ~59 ~20 ~12 stained_hardened_clay 7
fill ~60 ~20 ~4 ~63 ~20 ~4 stained_glass 15
setblock ~60 ~20 ~12 stained_hardened_clay 15
setblock ~60 ~20 ~24 mycelium 0
setblock ~61 ~20 ~12 log 3
setblock ~61 ~20 ~24 stained_hardened_clay 8
fill ~62 ~20 ~11 ~63 ~20 ~11 stained_hardened_clay 13
setblock ~63 ~20 ~23 stained_hardened_clay 8
fill ~63 ~20 ~40 ~64 ~20 ~40 stained_glass 15
fill ~64 ~20 ~5 ~68 ~20 ~5 stained_glass 15
setblock ~64 ~20 ~23 gold_ore 0
setblock ~65 ~20 ~23 wool 8
fill ~65 ~20 ~39 ~66 ~20 ~39 stained_glass 15
fill ~66 ~20 ~11 ~67 ~20 ~11 orange_glazed_terracotta 0
fill ~66 ~20 ~21 ~66 ~20 ~22 bedrock 0
setblock ~67 ~20 ~12 bookshelf 0
setblock ~67 ~20 ~21 brown_glazed_terracotta 0
fill ~67 ~20 ~38 ~70 ~20 ~38 stained_glass 15
setblock ~68 ~20 ~13 soul_sand 0
fill ~69 ~20 ~6 ~76 ~20 ~6 stained_glass 15
setblock ~69 ~20 ~13 stonebrick 1
fill ~69 ~20 ~21 ~69 ~21 ~21 gold_ore 0
setblock ~70 ~20 ~13 gold_ore 0
setblock ~70 ~20 ~14 brown_glazed_terracotta 0
setblock ~70 ~20 ~20 green_glazed_terracotta 0
setblock ~71 ~20 ~14 wool 8
setblock ~71 ~20 ~19 stained_hardened_clay 5
fill ~71 ~20 ~20 ~72 ~20 ~20 wool 8
fill ~71 ~20 ~37 ~71 ~17 ~37 stained_glass 15
setblock ~72 ~20 ~14 stained_hardened_clay 13
setblock ~72 ~20 ~15 mossy_cobblestone 0
setblock ~72 ~20 ~18 stained_hardened_clay 13
setblock ~72 ~20 ~19 brown_glazed_terracotta 0
fill ~72 ~20 ~38 ~77 ~20 ~38 stained_glass 15
setblock ~73 ~20 ~15 orange_glazed_terracotta 0
setblock ~73 ~20 ~16 mycelium 0
setblock ~73 ~20 ~18 stonebrick 1
setblock ~73 ~20 ~19 log 1
setblock ~73 ~20 ~20 double_stone_slab 8
setblock ~74 ~20 ~17 brown_glazed_terracotta 0
fill ~77 ~20 ~5 ~84 ~20 ~5 stained_glass 15
fill ~78 ~20 ~39 ~80 ~20 ~39 stained_glass 15
fill ~85 ~20 ~40 ~95 ~20 ~40 stained_glass 15
fill ~87 ~20 ~6 ~94 ~20 ~6 stained_glass 15
fill ~87 ~20 ~29 ~87 ~21 ~29 gold_ore 0
setblock ~88 ~20 ~26 wool 8
fill ~89 ~20 ~25 ~89 ~21 ~25 planks 2
fill ~89 ~20 ~27 ~90 ~20 ~27 stained_hardened_clay 5
setblock ~90 ~20 ~23 wool 8
setblock ~90 ~20 ~25 double_stone_slab 8
setblock ~91 ~20 ~24 orange_glazed_terracotta 0
setblock ~91 ~20 ~26 green_glazed_terracotta 0
setblock ~92 ~20 ~22 gold_ore 0
setblock ~92 ~20 ~25 orange_glazed_terracotta 0
setblock ~92 ~20 ~26 stained_hardened_clay 13
fill ~93 ~20 ~22 ~93 ~21 ~22 orange_glazed_terracotta 0
setblock ~93 ~20 ~24 gold_ore 0
fill ~94 ~20 ~22 ~94 ~20 ~23 gold_ore 0
fill ~95 ~20 ~7 ~103 ~20 ~7 stained_glass 15
fill ~96 ~20 ~41 ~102 ~20 ~41 stained_glass 15
fill ~103 ~20 ~40 ~103 ~24 ~40 stained_glass 15
fill ~106 ~20 ~8 ~107 ~20 ~8 stained_glass 15
fill ~108 ~20 ~9 ~110 ~20 ~9 stained_glass 15
fill ~108 ~20 ~39 ~109 ~20 ~39 stained_glass 15
fill ~113 ~20 ~12 ~113 ~21 ~12 stained_glass 15
fill ~114 ~20 ~13 ~114 ~23 ~13 stained_glass 15
fill ~117 ~20 ~16 ~117 ~28 ~16 stained_glass 15
fill ~118 ~20 ~18 ~118 ~28 ~18 stained_glass 15
fill ~123 ~20 ~28 ~123 ~30 ~28 stained_glass 15
fill ~16 ~21 ~27 ~16 ~35 ~27 stained_glass 15
fill ~21 ~21 ~18 ~21 ~30 ~18 stained_glass 15
fill ~23 ~21 ~15 ~23 ~29 ~15 stained_glass 15
fill ~30 ~21 ~40 ~31 ~21 ~40 stained_glass 15
setblock ~32 ~21 ~19 stained_hardened_clay 8
fill ~32 ~21 ~20 ~32 ~21 ~21 mycelium 0
setblock ~32 ~21 ~22 mossy_cobblestone 0
fill ~32 ~21 ~41 ~33 ~21 ~41 stained_glass 15
fill ~33 ~21 ~6 ~35 ~21 ~6 stained_glass 15
setblock ~33 ~21 ~18 brown_glazed_terracotta 0
setblock ~33 ~21 ~22 double_stone_slab 8
setblock ~33 ~21 ~23 bookshelf 0
setblock ~34 ~21 ~15 stained_hardened_clay 8
setblock ~34 ~21 ~16 gold_ore 0
setblock ~34 ~21 ~17 log 3
setblock ~34 ~21 ~22 planks 1
fill ~34 ~21 ~42 ~36 ~21 ~42 stained_glass 15
fill ~35 ~21 ~14 ~36 ~21 ~14 brown_glazed_terracotta 0
setblock ~35 ~21 ~22 stained_hardened_clay 13
fill ~36 ~21 ~5 ~38 ~21 ~5 stained_glass 15
setblock ~36 ~21 ~22 soul_sand 0
setblock ~37 ~21 ~14 concrete 8
setblock ~37 ~21 ~22 bedrock 0
fill ~37 ~21 ~43 ~42 ~21 ~43 stained_glass 15
setblock ~38 ~21 ~13 mycelium 0
setblock ~38 ~21 ~23 wool 7
fill ~39 ~21 ~4 ~41 ~21 ~4 stained_glass 15
setblock ~39 ~21 ~13 stained_hardened_clay 8
setblock ~39 ~21 ~23 concrete 7
fill ~40 ~21 ~11 ~40 ~21 ~12 bedrock 0
setblock ~40 ~21 ~23 stained_hardened_clay 7
setblock ~40 ~21 ~24 concrete 7
setblock ~41 ~21 ~8 stonebrick 1
setblock ~41 ~21 ~11 brown_glazed_terracotta 0
fill ~41 ~21 ~12 ~41 ~22 ~12 bedrock 0
setblock ~41 ~21 ~22 wool 15
setblock ~41 ~21 ~23 concrete 7
fill ~41 ~21 ~24 ~41 ~21 ~25 wool 7
fill ~42 ~21 ~3 ~48 ~21 ~3 stained_glass 15
setblock ~42 ~21 ~7 brown_glazed_terracotta 0
setblock ~42 ~21 ~9 brown_glazed_terracotta 0
setblock ~42 ~21 ~10 log 0
fill ~42 ~21 ~24 ~42 ~21 ~25 concrete 7
setblock ~42 ~21 ~26 coal_ore 0
setblock ~43 ~21 ~6 gold_ore 0
setblock ~43 ~21 ~7 log 3
setblock ~43 ~21 ~26 wool 7
setblock ~43 ~21 ~27 coal_ore 0
fill ~43 ~21 ~28 ~43 ~22 ~28 wool 8
fill ~43 ~21 ~44 ~46 ~21 ~44 stained_glass 15
setblock ~44 ~21 ~6 bedrock 0
setblock ~44 ~21 ~28 stonebrick 1
setblock ~45 ~21 ~6 mycelium 0
fill ~45 ~21 ~28 ~45 ~21 ~29 stained_hardened_clay 9
setblock ~46 ~21 ~5 stained_hardened_clay 5
fill ~46 ~21 ~6 ~48 ~21 ~6 stained_hardened_clay 13
setblock ~46 ~21 ~26 mossy_cobblestone 0
setblock ~47 ~21 ~5 mycelium 0
setblock ~47 ~21 ~26 stained_hardened_clay 5
fill ~47 ~21 ~43 ~47 ~25 ~43 stained_glass 15
setblock ~48 ~21 ~25 planks 1
fill ~48 ~21 ~44 ~52 ~21 ~44 stained_glass 15
setblock ~49 ~21 ~6 stained_hardened_clay 8
fill ~49 ~21 ~25 ~50 ~21 ~25 brown_glazed_terracotta 0
setblock ~50 ~21 ~6 bookshelf 0
setblock ~50 ~21 ~7 dirt 1
fill ~51 ~21 ~1 ~55 ~21 ~1 stained_glass 15
fill ~51 ~21 ~6 ~52 ~21 ~6 stained_hardened_clay 13
setblock ~51 ~21 ~7 log 0
setblock ~51 ~21 ~25 stained_hardened_clay 13
setblock ~52 ~21 ~7 log2 1
setblock ~52 ~21 ~25 brown_glazed_terracotta 0
setblock ~53 ~21 ~7 stained_hardened_clay 13
setblock ~53 ~21 ~8 log 3
setblock ~54 ~21 ~7 wool 13
setblock ~54 ~21 ~8 gold_ore 0
fill ~54 ~21 ~25 ~54 ~22 ~25 gold_ore 0
setblock ~55 ~21 ~8 orange_glazed_terracotta 0
setblock ~55 ~21 ~9 stained_hardened_clay 13
setblock ~55 ~21 ~25 mossy_cobblestone 0
setblock ~56 ~21 ~8 gold_ore 0
setblock ~56 ~21 ~9 brown_glazed_terracotta 0
setblock ~56 ~21 ~25 brown_glazed_terracotta 0
setblock ~57 ~21 ~9 log 1
setblock ~57 ~21 ~25 bedrock 0
fill ~58 ~21 ~3 ~59 ~21 ~3 stained_glass 15
setblock ~58 ~21 ~9 bookshelf 0
fill ~58 ~21 ~10 ~59 ~21 ~10 stained_hardened_clay 13
setblock ~58 ~21 ~11 log 1
setblock ~58 ~21 ~25 brown_glazed_terracotta 0
setblock ~59 ~21 ~9 brown_glazed_terracotta 0
setblock ~59 ~21 ~11 stained_hardened_clay 5
setblock ~59 ~21 ~25 double_stone_slab 8
fill ~59 ~21 ~42 ~59 ~40 ~42 stained_glass 15
fill ~60 ~21 ~4 ~62 ~21 ~4 stained_glass 15
setblock ~60 ~21 ~9 log 0
setblock ~60 ~21 ~10 brown_glazed_terracotta 0
setblock ~60 ~21 ~11 log 1
setblock ~60 ~21 ~12 stained_hardened_clay 13
setblock ~60 ~21 ~25 brown_glazed_terracotta 0
setblock ~61 ~21 ~12 stained_hardened_clay 12
fill ~61 ~21 ~24 ~63 ~21 ~24 gold_ore 0
setblock ~62 ~21 ~12 stained_hardened_clay 7
fill ~63 ~21 ~5 ~66 ~21 ~5 stained_glass 15
setblock ~63 ~21 ~11 log 1
fill ~63 ~21 ~40 ~64 ~21 ~40 stained_glass 15
fill ~64 ~21 ~11 ~64 ~22 ~11 soul_sand 0
setblock ~64 ~21 ~24 brown_glazed_terracotta 0
setblock ~65 ~21 ~12 brown_glazed_terracotta 0
fill ~65 ~21 ~22 ~66 ~21 ~22 stained_hardened_clay 9
setblock ~65 ~21 ~23 mycelium 0
fill ~65 ~21 ~39 ~66 ~21 ~39 stained_glass 15
setblock ~66 ~21 ~11 bookshelf 0
setblock ~66 ~21 ~12 mycelium 0
fill ~67 ~21 ~6 ~78 ~21 ~6 stained_glass 15
setblock ~67 ~21 ~12 brown_mushroom_block 0
fill ~67 ~21 ~22 ~67 ~22 ~22 brown_glazed_terracotta 0
fill ~67 ~21 ~38 ~77 ~21 ~38 stained_glass 15
setblock ~68 ~21 ~13 log 3
setblock ~68 ~21 ~21 log 3
fill ~69 ~21 ~13 ~69 ~22 ~13 stained_hardened_clay 13
setblock ~70 ~21 ~13 wool 8
fill ~70 ~21 ~21 ~71 ~21 ~21 gold_ore 0
setblock ~71 ~21 ~14 brown_glazed_terracotta 0
setblock ~71 ~21 ~20 mossy_cobblestone 0
setblock ~72 ~21 ~14 iron_ore 0
fill ~72 ~21 ~20 ~74 ~21 ~20 wool 8
setblock ~73 ~21 ~15 brown_glazed_terracotta 0
fill ~73 ~21 ~19 ~73 ~22 ~19 mycelium 0
fill ~74 ~21 ~16 ~74 ~22 ~16 concrete 8
setblock ~74 ~21 ~18 brown_glazed_terracotta 0
setblock ~74 ~21 ~19 concrete 13
setblock ~75 ~21 ~17 brown_glazed_terracotta 0
fill ~78 ~21 ~39 ~80 ~21 ~39 stained_glass 15
fill ~79 ~21 ~5 ~84 ~21 ~5 stained_glass 15
fill ~85 ~21 ~40 ~96 ~21 ~40 stained_glass 15
setblock ~86 ~21 ~27 green_glazed_terracotta 0
fill ~86 ~21 ~28 ~87 ~21 ~28 double_stone_slab 8
setblock ~86 ~21 ~29 gold_ore 0
fill ~87 ~21 ~6 ~94 ~21 ~6 stained_glass 15
fill ~87 ~21 ~26 ~87 ~22 ~26 planks 2
setblock ~87 ~21 ~27 stained_hardened_clay 5
setblock ~88 ~21 ~26 gold_ore 0
setblock ~88 ~21 ~27 green_glazed_terracotta 0
setblock ~88 ~21 ~28 orange_glazed_terracotta 0
fill ~89 ~21 ~27 ~90 ~21 ~27 stained_hardened_clay 5
setblock ~90 ~21 ~23 gold_ore 0
fill ~90 ~21 ~25 ~91 ~21 ~25 gold_ore 0
fill ~91 ~21 ~22 ~91 ~22 ~22 wool 8
setblock ~91 ~21 ~24 gold_ore 0
setblock ~91 ~21 ~27 concrete 13
setblock ~92 ~21 ~22 orange_glazed_terracotta 0
setblock ~92 ~21 ~26 stained_hardened_clay 5
setblock ~93 ~21 ~24 orange_glazed_terracotta 0
setblock ~93 ~21 ~25 bookshelf 0
setblock ~94 ~21 ~22 orange_glazed_terracotta 0
setblock ~94 ~21 ~23 stained_hardened_clay 5
fill ~95 ~21 ~7 ~102 ~21 ~7 stained_glass 15
fill ~95 ~21 ~22 ~96 ~21 ~22 gold_ore 0
fill ~95 ~21 ~23 ~95 ~21 ~22 gold_ore 0
fill ~97 ~21 ~41 ~100 ~21 ~41 stained_glass 15
fill ~101 ~21 ~40 ~106 ~21 ~40 stained_glass 15
fill ~103 ~21 ~8 ~103 ~26 ~8 stained_glass 15
fill ~106 ~21 ~8 ~107 ~21 ~8 stained_glass 15
fill ~107 ~21 ~39 ~109 ~21 ~39 stained_glass 15
fill ~108 ~21 ~9 ~110 ~21 ~9 stained_glass 15
setblock ~117 ~21 ~33 stained_glass 15
fill ~118 ~21 ~31 ~118 ~29 ~31 stained_glass 15
fill ~21 ~22 ~31 ~21 ~29 ~31 stained_glass 15
fill ~22 ~22 ~17 ~22 ~28 ~17 stained_glass 15
fill ~23 ~22 ~34 ~23 ~31 ~34 stained_glass 15
fill ~24 ~22 ~13 ~24 ~31 ~13 stained_glass 15
fill ~29 ~22 ~8 ~29 ~52 ~8 stained_glass 15
fill ~30 ~22 ~40 ~31 ~22 ~40 stained_glass 15
fill ~31 ~22 ~20 ~31 ~23 ~20 stonebrick 1
setblock ~31 ~22 ~21 coal_ore 0
setblock ~32 ~22 ~18 brown_glazed_terracotta 0
setblock ~32 ~22 ~19 gold_ore 0
setblock ~32 ~22 ~22 wool 8
fill ~32 ~22 ~41 ~33 ~22 ~41 stained_glass 15
fill ~33 ~22 ~6 ~35 ~22 ~6 stained_glass 15
fill ~33 ~22 ~16 ~33 ~23 ~16 gold_ore 0
fill ~33 ~22 ~17 ~33 ~23 ~17 brown_glazed_terracotta 0
setblock ~33 ~22 ~23 brown_glazed_terracotta 0
setblock ~34 ~22 ~15 gold_ore 0
setblock ~34 ~22 ~16 bedrock 0
setblock ~34 ~22 ~17 soul_sand 0
setblock ~34 ~22 ~23 log2 0
fill ~34 ~22 ~42 ~37 ~22 ~42 stained_glass 15
fill ~35 ~22 ~14 ~35 ~23 ~14 brown_glazed_terracotta 0
fill ~35 ~22 ~23 ~36 ~22 ~23 mycelium 0
fill ~36 ~22 ~5 ~38 ~22 ~5 stained_glass 15
setblock ~36 ~22 ~14 stained_hardened_clay 12
setblock ~37 ~22 ~14 bedrock 0
setblock ~37 ~22 ~23 gold_ore 0
setblock ~38 ~22 ~13 gold_ore 0
setblock ~38 ~22 ~14 soul_sand 0
setblock ~38 ~22 ~24 concrete 8
fill ~38 ~22 ~43 ~42 ~22 ~43 stained_glass 15
fill ~39 ~22 ~4 ~41 ~22 ~4 stained_glass 15
setblock ~39 ~22 ~13 brown_glazed_terracotta 0
setblock ~39 ~22 ~24 stonebrick 1
setblock ~39 ~22 ~25 double_stone_slab 8
setblock ~40 ~22 ~8 bedrock 0
setblock ~40 ~22 ~10 brown_mushroom_block 0
setblock ~40 ~22 ~12 bedrock 0
setblock ~40 ~22 ~25 wool 8
setblock ~41 ~22 ~6 brown_mushroom_block 0
setblock ~41 ~22 ~7 brown_glazed_terracotta 0
setblock ~41 ~22 ~9 mycelium 0
setblock ~41 ~22 ~10 bookshelf 0
setblock ~41 ~22 ~26 double_stone_slab 8
fill ~42 ~22 ~3 ~47 ~22 ~3 stained_glass 15
setblock ~42 ~22 ~5 brown_glazed_terracotta 0
setblock ~42 ~22 ~6 gold_ore 0
setblock ~42 ~22 ~11 bedrock 0
setblock ~42 ~22 ~12 stained_hardened_clay 7
setblock ~42 ~22 ~27 iron_ore 0
setblock ~43 ~22 ~5 stonebrick 1
fill ~43 ~22 ~44 ~46 ~22 ~44 stained_glass 15
setblock ~44 ~22 ~5 mossy_cobblestone 0
setblock ~44 ~22 ~28 stained_hardened_clay 9
setblock ~45 ~22 ~5 gold_ore 0
setblock ~45 ~22 ~27 brown_glazed_terracotta 0
setblock ~46 ~22 ~5 mossy_cobblestone 0
setblock ~46 ~22 ~26 stained_hardened_clay 13
setblock ~47 ~22 ~5 brown_glazed_terracotta 0
setblock ~47 ~22 ~26 gold_ore 0
fill ~48 ~22 ~2 ~48 ~23 ~2 stained_glass 15
setblock ~48 ~22 ~5 mossy_cobblestone 0
setblock ~48 ~22 ~26 log2 0
fill ~48 ~22 ~43 ~48 ~26 ~43 stained_glass 15
setblock ~49 ~22 ~5 bedrock 0
setblock ~49 ~22 ~26 wool 8
fill ~49 ~22 ~44 ~52 ~22 ~44 stained_glass 15
setblock ~50 ~22 ~5 concrete 8
setblock ~50 ~22 ~25 mossy_cobblestone 0
fill ~51 ~22 ~1 ~55 ~22 ~1 stained_glass 15
setblock ~51 ~22 ~5 gold_ore 0
setblock ~51 ~22 ~25 mycelium 0
setblock ~52 ~22 ~6 brown_glazed_terracotta 0
setblock ~52 ~22 ~25 mossy_cobblestone 0
setblock ~53 ~22 ~6 green_glazed_terracotta 0
setblock ~53 ~22 ~25 brown_glazed_terracotta 0
setblock ~54 ~22 ~6 planks 1
fill ~55 ~22 ~6 ~56 ~22 ~6 bookshelf 0
setblock ~55 ~22 ~7 brown_mushroom_block 0
setblock ~55 ~22 ~25 stonebrick 1
setblock ~56 ~22 ~7 orange_glazed_terracotta 0
setblock ~56 ~22 ~24 wool 7
setblock ~57 ~22 ~8 orange_glazed_terracotta 0
setblock ~57 ~22 ~24 stained_hardened_clay 13
fill ~58 ~22 ~3 ~59 ~22 ~3 stained_glass 15
setblock ~58 ~22 ~8 planks 1
setblock ~58 ~22 ~25 gold_ore 0
setblock ~59 ~22 ~9 noteblock 0
setblock ~59 ~22 ~25 wool 8
fill ~60 ~22 ~4 ~61 ~22 ~4 stained_glass 15
setblock ~60 ~22 ~9 brown_mushroom_block 0
setblock ~60 ~22 ~25 stonebrick 1
setblock ~61 ~22 ~9 log 0
setblock ~61 ~22 ~10 planks 0
setblock ~61 ~22 ~11 planks 1
setblock ~61 ~22 ~25 mossy_cobblestone 0
fill ~62 ~22 ~5 ~65 ~22 ~5 stained_glass 15
setblock ~62 ~22 ~10 stained_hardened_clay 5
setblock ~62 ~22 ~11 bookshelf 0
setblock ~62 ~22 ~25 gold_ore 0
fill ~62 ~22 ~40 ~64 ~22 ~40 stained_glass 15
setblock ~63 ~22 ~11 log 0
setblock ~63 ~22 ~24 gold_ore 0
setblock ~64 ~22 ~24 orange_glazed_terracotta 0
setblock ~65 ~22 ~11 planks 1
setblock ~65 ~22 ~12 gold_ore 0
fill ~65 ~22 ~23 ~65 ~23 ~23 stained_hardened_clay 13
fill ~65 ~22 ~39 ~66 ~22 ~39 stained_glass 15
fill ~66 ~22 ~6 ~78 ~22 ~6 stained_glass 15
fill ~66 ~22 ~12 ~66 ~22 ~13 brown_glazed_terracotta 0
setblock ~66 ~22 ~23 wool 8
setblock ~67 ~22 ~13 bedrock 0
fill ~67 ~22 ~38 ~77 ~22 ~38 stained_glass 15
setblock ~68 ~22 ~13 brown_glazed_terracotta 0
setblock ~68 ~22 ~14 log2 1
setblock ~68 ~22 ~22 mycelium 0
fill ~69 ~22 ~22 ~69 ~23 ~22 gold_ore 0
fill ~70 ~22 ~14 ~70 ~23 ~14 mossy_cobblestone 0
setblock ~70 ~22 ~22 stained_hardened_clay 8
fill ~71 ~22 ~14 ~71 ~24 ~14 gold_ore 0
setblock ~71 ~22 ~22 stained_hardened_clay 0
setblock ~72 ~22 ~15 brown_glazed_terracotta 0
setblock ~72 ~22 ~20 brown_glazed_terracotta 0
setblock ~72 ~22 ~21 gold_ore 0
fill ~73 ~22 ~15 ~73 ~23 ~15 mycelium 0
setblock ~73 ~22 ~20 planks 2
setblock ~74 ~22 ~15 concrete 8
setblock ~74 ~22 ~18 mossy_cobblestone 0
setblock ~75 ~22 ~17 mossy_cobblestone 0
fill ~78 ~22 ~39 ~80 ~22 ~39 stained_glass 15
fill ~79 ~22 ~5 ~84 ~22 ~5 stained_glass 15
setblock ~80 ~22 ~33 double_stone_slab 8
setblock ~80 ~22 ~34 concrete 8
setblock ~81 ~22 ~33 gold_ore 0
setblock ~81 ~22 ~34 planks 2
setblock ~82 ~22 ~32 iron_ore 0
setblock ~82 ~22 ~33 planks 2
setblock ~82 ~22 ~34 orange_glazed_terracotta 0
setblock ~83 ~22 ~32 planks 2
setblock ~83 ~22 ~33 orange_glazed_terracotta 0
setblock ~85 ~22 ~27 orange_glazed_terracotta 0
fill ~85 ~22 ~40 ~106 ~22 ~40 stained_glass 15
setblock ~86 ~22 ~26 green_glazed_terracotta 0
setblock ~86 ~22 ~27 stained_hardened_clay 5
setblock ~86 ~22 ~29 orange_glazed_terracotta 0
fill ~87 ~22 ~6 ~94 ~22 ~6 stained_glass 15
setblock ~87 ~22 ~28 gold_ore 0
setblock ~87 ~22 ~29 stained_hardened_clay 5
setblock ~88 ~22 ~26 orange_glazed_terracotta 0
setblock ~88 ~22 ~29 concrete 13
setblock ~89 ~22 ~25 orange_glazed_terracotta 0
setblock ~89 ~22 ~28 green_glazed_terracotta 0
setblock ~90 ~22 ~23 wool 8
fill ~90 ~22 ~25 ~90 ~21 ~25 gold_ore 0
setblock ~90 ~22 ~27 green_glazed_terracotta 0
setblock ~90 ~22 ~28 stained_hardened_clay 13
setblock ~91 ~22 ~24 wool 8
setblock ~91 ~22 ~27 stained_hardened_clay 13
setblock ~92 ~22 ~21 planks 2
setblock ~92 ~22 ~26 stained_hardened_clay 13
setblock ~93 ~22 ~22 planks 2
setblock ~93 ~22 ~26 bookshelf 0
fill ~94 ~22 ~22 ~94 ~23 ~22 gold_ore 0
fill ~94 ~22 ~23 ~94 ~22 ~25 orange_glazed_terracotta 0
setblock ~94 ~22 ~26 log 0
fill ~95 ~22 ~7 ~102 ~22 ~7 stained_glass 15
setblock ~95 ~22 ~22 planks 2
setblock ~95 ~22 ~23 wool 8
setblock ~95 ~22 ~26 double_stone_slab 8
setblock ~96 ~22 ~22 green_glazed_terracotta 0
setblock ~96 ~22 ~26 mossy_cobblestone 0
setblock ~97 ~22 ~22 orange_glazed_terracotta 0
fill ~97 ~22 ~26 ~97 ~22 ~27 orange_glazed_terracotta 0
fill ~106 ~22 ~8 ~106 ~10 ~8 stained_glass 15
fill ~107 ~22 ~9 ~110 ~22 ~9 stained_glass 15
fill ~107 ~22 ~39 ~109 ~22 ~39 stained_glass 15
fill ~113 ~22 ~11 ~113 ~30 ~11 stained_glass 15
fill ~114 ~22 ~12 ~114 ~25 ~12 stained_glass 15
fill ~116 ~22 ~33 ~116 ~26 ~33 stained_glass 15
fill ~17 ~23 ~28 ~17 ~36 ~28 stained_glass 15
fill ~22 ~23 ~32 ~22 ~28 ~32 stained_glass 15
fill ~30 ~23 ~40 ~31 ~23 ~40 stained_glass 15
setblock ~31 ~23 ~19 gold_ore 0
setblock ~31 ~23 ~21 concrete 8
setblock ~31 ~23 ~22 stonebrick 1
setblock ~32 ~23 ~18 gold_ore 0
setblock ~32 ~23 ~23 mossy_cobblestone 0
fill ~32 ~23 ~41 ~34 ~23 ~41 stained_glass 15
fill ~33 ~23 ~6 ~35 ~23 ~6 stained_glass 15
setblock ~33 ~23 ~15 mycelium 0
setblock ~33 ~23 ~23 stained_hardened_clay 13
setblock ~34 ~23 ~14 brown_glazed_terracotta 0
setblock ~34 ~23 ~22 bedrock 0
fill ~35 ~23 ~13 ~36 ~23 ~13 bedrock 0
fill ~35 ~23 ~23 ~36 ~23 ~23 mycelium 0
fill ~35 ~23 ~42 ~38 ~23 ~42 stained_glass 15
fill ~36 ~23 ~5 ~38 ~23 ~5 stained_glass 15
setblock ~36 ~23 ~14 bedrock 0
setblock ~37 ~23 ~12 concrete 8
setblock ~37 ~23 ~13 mossy_cobblestone 0
fill ~37 ~23 ~23 ~37 ~24 ~23 brown_glazed_terracotta 0
fill ~38 ~23 ~12 ~38 ~23 ~13 brown_glazed_terracotta 0
fill ~38 ~23 ~24 ~38 ~24 ~24 gold_ore 0
fill ~39 ~23 ~4 ~41 ~23 ~4 stained_glass 15
setblock ~39 ~23 ~12 bedrock 0
setblock ~39 ~23 ~25 gold_ore 0
fill ~39 ~23 ~43 ~43 ~23 ~43 stained_glass 15
fill ~40 ~23 ~7 ~40 ~24 ~7 mossy_cobblestone 0
setblock ~40 ~23 ~8 gold_ore 0
setblock ~40 ~23 ~9 brown_glazed_terracotta 0
setblock ~40 ~23 ~12 wool 7
setblock ~40 ~23 ~26 planks 2
setblock ~41 ~23 ~6 wool 8
setblock ~41 ~23 ~10 stained_hardened_clay 13
setblock ~41 ~23 ~12 concrete 7
fill ~41 ~23 ~27 ~42 ~23 ~27 gold_ore 0
fill ~42 ~23 ~3 ~47 ~23 ~3 stained_glass 15
setblock ~42 ~23 ~5 planks 1
setblock ~42 ~23 ~10 stained_hardened_clay 7
setblock ~42 ~23 ~11 stained_hardened_clay 12
