fill ~1 ~-3 ~0 ~196 ~-3 ~0 grass 0
fill ~1 ~-3 ~1 ~196 ~-3 ~1 grass 0
fill ~1 ~-3 ~2 ~196 ~-3 ~2 grass 0
fill ~1 ~-3 ~3 ~196 ~-3 ~3 grass 0
fill ~1 ~-3 ~4 ~196 ~-3 ~4 grass 0
fill ~1 ~-3 ~5 ~196 ~-3 ~5 grass 0
fill ~1 ~-3 ~6 ~196 ~-3 ~6 grass 0
fill ~1 ~-3 ~7 ~196 ~-3 ~7 grass 0
fill ~1 ~-3 ~8 ~46 ~-3 ~8 grass 0
fill ~1 ~-3 ~9 ~46 ~-3 ~9 grass 0
fill ~1 ~-3 ~10 ~46 ~-3 ~10 grass 0
fill ~1 ~-3 ~11 ~46 ~-3 ~11 grass 0
fill ~1 ~-3 ~12 ~46 ~-3 ~12 grass 0
fill ~1 ~-3 ~13 ~46 ~-3 ~13 grass 0
fill ~1 ~-3 ~14 ~160 ~-3 ~14 grass 0
fill ~1 ~-3 ~15 ~160 ~-3 ~15 grass 0
fill ~1 ~-3 ~16 ~160 ~-3 ~16 grass 0
fill ~1 ~-3 ~17 ~160 ~-3 ~17 grass 0
fill ~1 ~-3 ~18 ~196 ~-3 ~18 grass 0
fill ~1 ~-3 ~19 ~196 ~-3 ~19 grass 0
fill ~1 ~-3 ~20 ~196 ~-3 ~20 grass 0
fill ~1 ~-3 ~21 ~196 ~-3 ~21 grass 0
fill ~1 ~-3 ~22 ~196 ~-3 ~22 grass 0
fill ~1 ~-3 ~23 ~196 ~-3 ~23 grass 0
fill ~1 ~-3 ~24 ~196 ~-3 ~24 grass 0
fill ~1 ~-3 ~25 ~196 ~-3 ~25 grass 0
fill ~1 ~-3 ~26 ~196 ~-3 ~26 grass 0
fill ~1 ~-3 ~27 ~196 ~-3 ~27 grass 0
fill ~1 ~-3 ~28 ~196 ~-3 ~28 grass 0
fill ~1 ~-3 ~29 ~196 ~-3 ~29 grass 0
fill ~1 ~-3 ~30 ~196 ~-3 ~30 grass 0
fill ~1 ~-3 ~31 ~196 ~-3 ~31 grass 0
fill ~1 ~-3 ~32 ~196 ~-3 ~32 grass 0
fill ~1 ~-3 ~33 ~196 ~-3 ~33 grass 0
fill ~1 ~-3 ~34 ~196 ~-3 ~34 grass 0
fill ~1 ~-3 ~35 ~196 ~-3 ~35 grass 0
fill ~1 ~-3 ~36 ~196 ~-3 ~36 grass 0
fill ~1 ~-3 ~37 ~196 ~-3 ~37 grass 0
fill ~1 ~-3 ~38 ~196 ~-3 ~38 grass 0
fill ~1 ~-3 ~39 ~196 ~-3 ~39 grass 0
fill ~1 ~-3 ~40 ~196 ~-3 ~40 grass 0
fill ~1 ~-3 ~41 ~196 ~-3 ~41 grass 0
fill ~1 ~-3 ~42 ~196 ~-3 ~42 grass 0
fill ~1 ~-3 ~43 ~196 ~-3 ~43 grass 0
fill ~1 ~-3 ~44 ~196 ~-3 ~44 grass 0
fill ~1 ~-3 ~45 ~23 ~-3 ~45 grass 0
fill ~1 ~-3 ~46 ~196 ~-3 ~46 grass 0
fill ~1 ~-3 ~47 ~27 ~-3 ~47 grass 0
fill ~1 ~-3 ~48 ~196 ~-3 ~48 grass 0
fill ~1 ~-3 ~49 ~196 ~-3 ~49 grass 0
fill ~1 ~-3 ~50 ~196 ~-3 ~50 grass 0
fill ~1 ~-3 ~51 ~196 ~-3 ~51 grass 0
fill ~1 ~-3 ~52 ~22 ~-3 ~52 grass 0
fill ~1 ~-3 ~53 ~196 ~-3 ~53 grass 0
fill ~1 ~-3 ~54 ~196 ~-3 ~54 grass 0
fill ~1 ~-3 ~55 ~196 ~-3 ~55 grass 0
fill ~1 ~-3 ~56 ~196 ~-3 ~56 grass 0
fill ~1 ~-3 ~57 ~196 ~-3 ~57 grass 0
fill ~1 ~-3 ~58 ~31 ~-3 ~58 grass 0
fill ~1 ~-3 ~59 ~196 ~-3 ~59 grass 0
fill ~1 ~-3 ~60 ~196 ~-3 ~60 grass 0
fill ~1 ~-3 ~61 ~196 ~-3 ~61 grass 0
fill ~1 ~-3 ~62 ~196 ~-3 ~62 grass 0
fill ~1 ~-3 ~63 ~196 ~-3 ~63 grass 0
fill ~1 ~-3 ~64 ~196 ~-3 ~64 grass 0
fill ~1 ~-3 ~65 ~196 ~-3 ~65 grass 0
fill ~1 ~-3 ~66 ~196 ~-3 ~66 grass 0
fill ~1 ~-3 ~67 ~196 ~-3 ~67 grass 0
fill ~1 ~-3 ~68 ~31 ~-3 ~68 grass 0
fill ~1 ~-3 ~69 ~196 ~-3 ~69 grass 0
fill ~1 ~-3 ~70 ~196 ~-3 ~70 grass 0
fill ~1 ~-3 ~71 ~196 ~-3 ~71 grass 0
fill ~1 ~-3 ~72 ~196 ~-3 ~72 grass 0
fill ~1 ~-3 ~73 ~196 ~-3 ~73 grass 0
fill ~1 ~-3 ~74 ~196 ~-3 ~74 grass 0
fill ~1 ~-3 ~75 ~196 ~-3 ~75 grass 0
fill ~1 ~-3 ~76 ~160 ~-3 ~76 grass 0
fill ~1 ~-3 ~77 ~36 ~-3 ~77 grass 0
fill ~1 ~-3 ~78 ~47 ~-3 ~78 grass 0
fill ~1 ~-3 ~79 ~160 ~-3 ~79 grass 0
fill ~1 ~-3 ~80 ~46 ~-3 ~80 grass 0
fill ~1 ~-3 ~81 ~46 ~-3 ~81 grass 0
fill ~1 ~-3 ~82 ~46 ~-3 ~82 grass 0
fill ~1 ~-3 ~83 ~46 ~-3 ~83 grass 0
fill ~1 ~-3 ~84 ~46 ~-3 ~84 grass 0
fill ~1 ~-3 ~85 ~46 ~-3 ~85 grass 0
fill ~1 ~-3 ~86 ~196 ~-3 ~86 grass 0
fill ~1 ~-3 ~87 ~196 ~-3 ~87 grass 0
fill ~1 ~-3 ~88 ~196 ~-3 ~88 grass 0
fill ~1 ~-3 ~89 ~196 ~-3 ~89 grass 0
fill ~1 ~-3 ~90 ~196 ~-3 ~90 grass 0
fill ~1 ~-3 ~91 ~196 ~-3 ~91 grass 0
fill ~1 ~-3 ~92 ~196 ~-3 ~92 grass 0
fill ~1 ~-3 ~93 ~196 ~-3 ~93 grass 0
fill ~23 ~-3 ~52 ~23 ~-3 ~52 dirt 0
fill ~24 ~-3 ~45 ~24 ~-3 ~45 dirt 0
fill ~24 ~-3 ~52 ~196 ~-3 ~52 grass 0
fill ~25 ~-3 ~45 ~196 ~-3 ~45 grass 0
fill ~28 ~-3 ~47 ~28 ~-3 ~47 dirt 0
fill ~29 ~-3 ~47 ~196 ~-3 ~47 grass 0
fill ~32 ~-3 ~58 ~32 ~-3 ~58 dirt 0
fill ~32 ~-3 ~68 ~32 ~-3 ~68 dirt 0
fill ~33 ~-3 ~58 ~196 ~-3 ~58 grass 0
fill ~33 ~-3 ~68 ~196 ~-3 ~68 grass 0
fill ~37 ~-3 ~77 ~37 ~-3 ~77 dirt 0
fill ~38 ~-3 ~77 ~160 ~-3 ~77 grass 0
fill ~47 ~-3 ~8 ~53 ~-3 ~8 dirt 0
fill ~47 ~-3 ~9 ~53 ~-3 ~9 dirt 0
fill ~47 ~-3 ~10 ~53 ~-3 ~10 dirt 0
fill ~47 ~-3 ~11 ~53 ~-3 ~11 dirt 0
fill ~47 ~-3 ~12 ~53 ~-3 ~12 dirt 0
fill ~47 ~-3 ~13 ~53 ~-3 ~13 dirt 0
fill ~47 ~-3 ~80 ~53 ~-3 ~80 dirt 0
fill ~47 ~-3 ~81 ~53 ~-3 ~81 dirt 0
fill ~47 ~-3 ~82 ~53 ~-3 ~82 dirt 0
fill ~47 ~-3 ~83 ~53 ~-3 ~83 dirt 0
fill ~47 ~-3 ~84 ~53 ~-3 ~84 dirt 0
fill ~47 ~-3 ~85 ~53 ~-3 ~85 dirt 0
fill ~48 ~-3 ~78 ~48 ~-3 ~78 dirt 0
fill ~49 ~-3 ~78 ~160 ~-3 ~78 grass 0
fill ~54 ~-3 ~8 ~160 ~-3 ~8 grass 0
fill ~54 ~-3 ~9 ~160 ~-3 ~9 grass 0
fill ~54 ~-3 ~10 ~160 ~-3 ~10 grass 0
fill ~54 ~-3 ~11 ~160 ~-3 ~11 grass 0
fill ~54 ~-3 ~12 ~160 ~-3 ~12 grass 0
fill ~54 ~-3 ~13 ~160 ~-3 ~13 grass 0
fill ~54 ~-3 ~80 ~160 ~-3 ~80 grass 0
fill ~54 ~-3 ~81 ~160 ~-3 ~81 grass 0
fill ~54 ~-3 ~82 ~160 ~-3 ~82 grass 0
fill ~54 ~-3 ~83 ~160 ~-3 ~83 grass 0
fill ~54 ~-3 ~84 ~160 ~-3 ~84 grass 0
fill ~54 ~-3 ~85 ~160 ~-3 ~85 grass 0
fill ~161 ~-3 ~8 ~167 ~-3 ~8 dirt 0
fill ~161 ~-3 ~9 ~167 ~-3 ~9 dirt 0
fill ~161 ~-3 ~10 ~167 ~-3 ~10 dirt 0
fill ~161 ~-3 ~11 ~167 ~-3 ~11 dirt 0
fill ~161 ~-3 ~12 ~167 ~-3 ~12 dirt 0
fill ~161 ~-3 ~13 ~167 ~-3 ~13 dirt 0
fill ~161 ~-3 ~14 ~167 ~-3 ~14 dirt 0
fill ~161 ~-3 ~15 ~167 ~-3 ~15 dirt 0
fill ~161 ~-3 ~16 ~167 ~-3 ~16 dirt 0
fill ~161 ~-3 ~17 ~167 ~-3 ~17 dirt 0
fill ~161 ~-3 ~76 ~167 ~-3 ~76 dirt 0
fill ~161 ~-3 ~77 ~167 ~-3 ~77 dirt 0
fill ~161 ~-3 ~78 ~167 ~-3 ~78 dirt 0
fill ~161 ~-3 ~79 ~167 ~-3 ~79 dirt 0
fill ~161 ~-3 ~80 ~167 ~-3 ~80 dirt 0
fill ~161 ~-3 ~81 ~167 ~-3 ~81 dirt 0
fill ~161 ~-3 ~82 ~167 ~-3 ~82 dirt 0
fill ~161 ~-3 ~83 ~167 ~-3 ~83 dirt 0
fill ~161 ~-3 ~84 ~167 ~-3 ~84 dirt 0
fill ~161 ~-3 ~85 ~167 ~-3 ~85 dirt 0
fill ~168 ~-3 ~8 ~196 ~-3 ~8 grass 0
fill ~168 ~-3 ~9 ~196 ~-3 ~9 grass 0
fill ~168 ~-3 ~10 ~196 ~-3 ~10 grass 0
fill ~168 ~-3 ~11 ~196 ~-3 ~11 grass 0
fill ~168 ~-3 ~12 ~196 ~-3 ~12 grass 0
fill ~168 ~-3 ~13 ~196 ~-3 ~13 grass 0
fill ~168 ~-3 ~14 ~196 ~-3 ~14 grass 0
fill ~168 ~-3 ~15 ~196 ~-3 ~15 grass 0
fill ~168 ~-3 ~16 ~196 ~-3 ~16 grass 0
fill ~168 ~-3 ~17 ~196 ~-3 ~17 grass 0
fill ~168 ~-3 ~76 ~196 ~-3 ~76 grass 0
fill ~168 ~-3 ~77 ~196 ~-3 ~77 grass 0
fill ~168 ~-3 ~78 ~196 ~-3 ~78 grass 0
fill ~168 ~-3 ~79 ~196 ~-3 ~79 grass 0
fill ~168 ~-3 ~80 ~196 ~-3 ~80 grass 0
fill ~168 ~-3 ~81 ~196 ~-3 ~81 grass 0
fill ~168 ~-3 ~82 ~196 ~-3 ~82 grass 0
fill ~168 ~-3 ~83 ~196 ~-3 ~83 grass 0
fill ~168 ~-3 ~84 ~196 ~-3 ~84 grass 0
fill ~168 ~-3 ~85 ~196 ~-3 ~85 grass 0
fill ~47 ~-2 ~8 ~53 ~-2 ~8 wool 15
fill ~47 ~-2 ~9 ~53 ~-2 ~9 wool 15
fill ~47 ~-2 ~10 ~53 ~-2 ~10 wool 15
fill ~47 ~-2 ~11 ~53 ~-2 ~11 wool 15
fill ~47 ~-2 ~12 ~53 ~-2 ~12 wool 15
fill ~47 ~-2 ~13 ~53 ~-2 ~13 wool 15
fill ~47 ~-2 ~80 ~53 ~-2 ~80 wool 15
fill ~47 ~-2 ~81 ~53 ~-2 ~81 wool 15
fill ~47 ~-2 ~82 ~53 ~-2 ~82 wool 15
fill ~47 ~-2 ~83 ~53 ~-2 ~83 wool 15
fill ~47 ~-2 ~84 ~53 ~-2 ~84 wool 15
fill ~47 ~-2 ~85 ~53 ~-2 ~85 wool 15
fill ~161 ~-2 ~8 ~167 ~-2 ~8 wool 15
fill ~161 ~-2 ~9 ~167 ~-2 ~9 wool 15
fill ~161 ~-2 ~10 ~167 ~-2 ~10 wool 15
fill ~161 ~-2 ~11 ~167 ~-2 ~11 wool 15
fill ~161 ~-2 ~12 ~167 ~-2 ~12 wool 15
fill ~161 ~-2 ~13 ~167 ~-2 ~13 wool 15
fill ~161 ~-2 ~14 ~167 ~-2 ~14 wool 15
fill ~161 ~-2 ~15 ~167 ~-2 ~15 wool 15
fill ~161 ~-2 ~16 ~167 ~-2 ~16 wool 15
fill ~161 ~-2 ~17 ~167 ~-2 ~17 wool 15
fill ~161 ~-2 ~76 ~167 ~-2 ~76 wool 15
fill ~161 ~-2 ~77 ~167 ~-2 ~77 wool 15
fill ~161 ~-2 ~78 ~167 ~-2 ~78 wool 15
fill ~161 ~-2 ~79 ~167 ~-2 ~79 wool 15
fill ~161 ~-2 ~80 ~167 ~-2 ~80 wool 15
fill ~161 ~-2 ~81 ~167 ~-2 ~81 wool 15
fill ~161 ~-2 ~82 ~167 ~-2 ~82 wool 15
fill ~161 ~-2 ~83 ~167 ~-2 ~83 wool 15
fill ~161 ~-2 ~84 ~167 ~-2 ~84 wool 15
fill ~161 ~-2 ~85 ~167 ~-2 ~85 wool 15
fill ~44 ~-1 ~8 ~46 ~-1 ~8 wool 15
fill ~44 ~-1 ~9 ~46 ~-1 ~9 wool 15
fill ~44 ~-1 ~10 ~46 ~-1 ~10 wool 15
fill ~44 ~-1 ~11 ~46 ~-1 ~11 wool 15
fill ~44 ~-1 ~12 ~46 ~-1 ~12 wool 15
fill ~44 ~-1 ~13 ~46 ~-1 ~13 wool 15
fill ~44 ~-1 ~80 ~46 ~-1 ~80 wool 15
fill ~44 ~-1 ~81 ~46 ~-1 ~81 wool 15
fill ~44 ~-1 ~82 ~46 ~-1 ~82 wool 15
fill ~44 ~-1 ~83 ~46 ~-1 ~83 wool 15
fill ~44 ~-1 ~84 ~46 ~-1 ~84 wool 15
fill ~44 ~-1 ~85 ~46 ~-1 ~85 wool 15
fill ~47 ~-1 ~7 ~53 ~-1 ~7 wool 15
fill ~47 ~-1 ~14 ~53 ~-1 ~14 wool 15
fill ~47 ~-1 ~79 ~53 ~-1 ~79 wool 15
fill ~47 ~-1 ~86 ~53 ~-1 ~86 wool 15
fill ~54 ~-1 ~8 ~56 ~-1 ~8 wool 15
fill ~54 ~-1 ~9 ~56 ~-1 ~9 wool 15
fill ~54 ~-1 ~10 ~56 ~-1 ~10 wool 15
fill ~54 ~-1 ~11 ~56 ~-1 ~11 wool 15
fill ~54 ~-1 ~12 ~56 ~-1 ~12 wool 15
fill ~54 ~-1 ~13 ~56 ~-1 ~13 wool 15
fill ~54 ~-1 ~80 ~56 ~-1 ~80 wool 15
fill ~54 ~-1 ~81 ~56 ~-1 ~81 wool 15
fill ~54 ~-1 ~82 ~56 ~-1 ~82 wool 15
fill ~54 ~-1 ~83 ~56 ~-1 ~83 wool 15
fill ~54 ~-1 ~84 ~56 ~-1 ~84 wool 15
fill ~54 ~-1 ~85 ~56 ~-1 ~85 wool 15
fill ~158 ~-1 ~8 ~160 ~-1 ~8 wool 15
fill ~158 ~-1 ~9 ~160 ~-1 ~9 wool 15
fill ~158 ~-1 ~10 ~160 ~-1 ~10 wool 15
fill ~158 ~-1 ~11 ~160 ~-1 ~11 wool 15
fill ~158 ~-1 ~12 ~160 ~-1 ~12 wool 15
fill ~158 ~-1 ~13 ~160 ~-1 ~13 wool 15
fill ~158 ~-1 ~14 ~160 ~-1 ~14 wool 15
fill ~158 ~-1 ~15 ~160 ~-1 ~15 wool 15
fill ~158 ~-1 ~16 ~160 ~-1 ~16 wool 15
fill ~158 ~-1 ~17 ~160 ~-1 ~17 wool 15
fill ~158 ~-1 ~76 ~160 ~-1 ~76 wool 15
fill ~158 ~-1 ~77 ~160 ~-1 ~77 wool 15
fill ~158 ~-1 ~78 ~160 ~-1 ~78 wool 15
fill ~158 ~-1 ~79 ~160 ~-1 ~79 wool 15
fill ~158 ~-1 ~80 ~160 ~-1 ~80 wool 15
fill ~158 ~-1 ~81 ~160 ~-1 ~81 wool 15
fill ~158 ~-1 ~82 ~160 ~-1 ~82 wool 15
fill ~158 ~-1 ~83 ~160 ~-1 ~83 wool 15
fill ~158 ~-1 ~84 ~160 ~-1 ~84 wool 15
fill ~158 ~-1 ~85 ~160 ~-1 ~85 wool 15
fill ~161 ~-1 ~7 ~167 ~-1 ~7 wool 15
fill ~161 ~-1 ~18 ~167 ~-1 ~18 wool 15
fill ~161 ~-1 ~75 ~167 ~-1 ~75 wool 15
fill ~161 ~-1 ~86 ~167 ~-1 ~86 wool 15
fill ~168 ~-1 ~8 ~170 ~-1 ~8 wool 15
fill ~168 ~-1 ~9 ~170 ~-1 ~9 wool 15
fill ~168 ~-1 ~10 ~170 ~-1 ~10 wool 15
fill ~168 ~-1 ~11 ~170 ~-1 ~11 wool 15
fill ~168 ~-1 ~12 ~170 ~-1 ~12 wool 15
fill ~168 ~-1 ~13 ~170 ~-1 ~13 wool 15
fill ~168 ~-1 ~14 ~170 ~-1 ~14 wool 15
fill ~168 ~-1 ~15 ~170 ~-1 ~15 wool 15
fill ~168 ~-1 ~16 ~170 ~-1 ~16 wool 15
fill ~168 ~-1 ~17 ~170 ~-1 ~17 wool 15
fill ~168 ~-1 ~76 ~170 ~-1 ~76 wool 15
fill ~168 ~-1 ~77 ~170 ~-1 ~77 wool 15
fill ~168 ~-1 ~78 ~170 ~-1 ~78 wool 15
fill ~168 ~-1 ~79 ~170 ~-1 ~79 wool 15
fill ~168 ~-1 ~80 ~170 ~-1 ~80 wool 15
fill ~168 ~-1 ~81 ~170 ~-1 ~81 wool 15
fill ~168 ~-1 ~82 ~170 ~-1 ~82 wool 15
fill ~168 ~-1 ~83 ~170 ~-1 ~83 wool 15
fill ~168 ~-1 ~84 ~170 ~-1 ~84 wool 15
fill ~168 ~-1 ~85 ~170 ~-1 ~85 wool 15
fill ~42 ~0 ~8 ~43 ~0 ~8 wool 15
fill ~42 ~0 ~9 ~43 ~0 ~9 wool 15
fill ~42 ~0 ~10 ~43 ~0 ~10 wool 15
fill ~42 ~0 ~11 ~43 ~0 ~11 wool 15
fill ~42 ~0 ~12 ~43 ~0 ~12 wool 15
fill ~42 ~0 ~13 ~43 ~0 ~13 wool 15
fill ~42 ~0 ~80 ~43 ~0 ~80 wool 15
fill ~42 ~0 ~81 ~43 ~0 ~81 wool 15
fill ~42 ~0 ~82 ~43 ~0 ~82 wool 15
fill ~42 ~0 ~83 ~43 ~0 ~83 wool 15
fill ~42 ~0 ~84 ~43 ~0 ~84 wool 15
fill ~42 ~0 ~85 ~43 ~0 ~85 wool 15
fill ~44 ~0 ~7 ~46 ~0 ~7 wool 15
fill ~44 ~0 ~14 ~46 ~0 ~14 wool 15
fill ~44 ~0 ~79 ~46 ~0 ~79 wool 15
fill ~44 ~0 ~86 ~46 ~0 ~86 wool 15
fill ~47 ~0 ~7 ~53 ~0 ~7 stained_hardened_clay 9
fill ~47 ~0 ~8 ~53 ~0 ~8 stained_hardened_clay 9
fill ~47 ~0 ~9 ~53 ~0 ~9 wool 7
fill ~47 ~0 ~10 ~53 ~0 ~10 wool 7
fill ~47 ~0 ~11 ~53 ~0 ~11 wool 7
fill ~47 ~0 ~12 ~53 ~0 ~12 wool 7
fill ~47 ~0 ~13 ~53 ~0 ~13 wool 7
fill ~47 ~0 ~14 ~53 ~0 ~14 wool 7
fill ~47 ~0 ~79 ~53 ~0 ~79 wool 7
fill ~47 ~0 ~80 ~53 ~0 ~80 wool 7
fill ~47 ~0 ~81 ~53 ~0 ~81 wool 7
fill ~47 ~0 ~82 ~53 ~0 ~82 wool 7
fill ~47 ~0 ~83 ~53 ~0 ~83 wool 7
fill ~47 ~0 ~84 ~53 ~0 ~84 wool 7
fill ~47 ~0 ~85 ~53 ~0 ~85 stained_hardened_clay 9
fill ~47 ~0 ~86 ~53 ~0 ~86 stained_hardened_clay 9
fill ~54 ~0 ~7 ~56 ~0 ~7 wool 15
fill ~54 ~0 ~14 ~56 ~0 ~14 wool 15
fill ~54 ~0 ~79 ~56 ~0 ~79 wool 15
fill ~54 ~0 ~86 ~56 ~0 ~86 wool 15
fill ~57 ~0 ~8 ~58 ~0 ~8 wool 15
fill ~57 ~0 ~9 ~58 ~0 ~9 wool 15
fill ~57 ~0 ~10 ~58 ~0 ~10 wool 15
fill ~57 ~0 ~11 ~58 ~0 ~11 wool 15
fill ~57 ~0 ~12 ~58 ~0 ~12 wool 15
fill ~57 ~0 ~13 ~58 ~0 ~13 wool 15
fill ~57 ~0 ~80 ~58 ~0 ~80 wool 15
fill ~57 ~0 ~81 ~58 ~0 ~81 wool 15
fill ~57 ~0 ~82 ~58 ~0 ~82 wool 15
fill ~57 ~0 ~83 ~58 ~0 ~83 wool 15
fill ~57 ~0 ~84 ~58 ~0 ~84 wool 15
fill ~57 ~0 ~85 ~58 ~0 ~85 wool 15
fill ~156 ~0 ~8 ~157 ~0 ~8 wool 15
fill ~156 ~0 ~9 ~157 ~0 ~9 wool 15
fill ~156 ~0 ~10 ~157 ~0 ~10 wool 15
fill ~156 ~0 ~11 ~157 ~0 ~11 wool 15
fill ~156 ~0 ~12 ~157 ~0 ~12 wool 15
fill ~156 ~0 ~13 ~157 ~0 ~13 wool 15
fill ~156 ~0 ~14 ~157 ~0 ~14 wool 15
fill ~156 ~0 ~15 ~157 ~0 ~15 wool 15
fill ~156 ~0 ~16 ~157 ~0 ~16 wool 15
fill ~156 ~0 ~17 ~157 ~0 ~17 wool 15
fill ~156 ~0 ~76 ~157 ~0 ~76 wool 15
fill ~156 ~0 ~77 ~157 ~0 ~77 wool 15
fill ~156 ~0 ~78 ~157 ~0 ~78 wool 15
fill ~156 ~0 ~79 ~157 ~0 ~79 wool 15
fill ~156 ~0 ~80 ~157 ~0 ~80 wool 15
fill ~156 ~0 ~81 ~157 ~0 ~81 wool 15
fill ~156 ~0 ~82 ~157 ~0 ~82 wool 15
fill ~156 ~0 ~83 ~157 ~0 ~83 wool 15
fill ~156 ~0 ~84 ~157 ~0 ~84 wool 15
fill ~156 ~0 ~85 ~157 ~0 ~85 wool 15
fill ~158 ~0 ~7 ~170 ~0 ~7 wool 15
fill ~158 ~0 ~18 ~170 ~0 ~18 wool 15
fill ~158 ~0 ~75 ~170 ~0 ~75 wool 15
fill ~158 ~0 ~86 ~170 ~0 ~86 wool 15
fill ~171 ~0 ~8 ~172 ~0 ~8 wool 15
fill ~171 ~0 ~9 ~172 ~0 ~9 wool 15
fill ~171 ~0 ~10 ~172 ~0 ~10 wool 15
fill ~171 ~0 ~11 ~172 ~0 ~11 wool 15
fill ~171 ~0 ~12 ~172 ~0 ~12 wool 15
fill ~171 ~0 ~13 ~172 ~0 ~13 wool 15
fill ~171 ~0 ~14 ~172 ~0 ~14 wool 15
fill ~171 ~0 ~15 ~172 ~0 ~15 wool 15
fill ~171 ~0 ~16 ~172 ~0 ~16 wool 15
fill ~171 ~0 ~17 ~172 ~0 ~17 wool 15
fill ~171 ~0 ~76 ~172 ~0 ~76 wool 15
fill ~171 ~0 ~77 ~172 ~0 ~77 wool 15
fill ~171 ~0 ~78 ~172 ~0 ~78 wool 15
fill ~171 ~0 ~79 ~172 ~0 ~79 wool 15
fill ~171 ~0 ~80 ~172 ~0 ~80 wool 15
fill ~171 ~0 ~81 ~172 ~0 ~81 wool 15
fill ~171 ~0 ~82 ~172 ~0 ~82 wool 15
fill ~171 ~0 ~83 ~172 ~0 ~83 wool 15
fill ~171 ~0 ~84 ~172 ~0 ~84 wool 15
fill ~171 ~0 ~85 ~172 ~0 ~85 wool 15
fill ~41 ~1 ~8 ~41 ~1 ~13 wool 15
fill ~41 ~1 ~80 ~41 ~1 ~85 wool 15
fill ~42 ~1 ~7 ~44 ~1 ~7 wool 15
fill ~42 ~1 ~14 ~44 ~1 ~14 wool 15
fill ~42 ~1 ~79 ~44 ~1 ~79 wool 15
fill ~42 ~1 ~86 ~44 ~1 ~86 wool 15
fill ~45 ~1 ~7 ~46 ~1 ~7 stained_hardened_clay 9
fill ~45 ~1 ~8 ~46 ~1 ~8 stained_hardened_clay 9
fill ~45 ~1 ~9 ~46 ~1 ~9 wool 7
fill ~45 ~1 ~10 ~46 ~1 ~10 wool 7
fill ~45 ~1 ~11 ~46 ~1 ~11 wool 7
fill ~45 ~1 ~12 ~46 ~1 ~12 wool 7
fill ~45 ~1 ~13 ~46 ~1 ~13 wool 7
fill ~45 ~1 ~14 ~46 ~1 ~14 wool 7
fill ~45 ~1 ~79 ~46 ~1 ~79 wool 7
fill ~45 ~1 ~80 ~46 ~1 ~80 wool 7
fill ~45 ~1 ~81 ~46 ~1 ~81 wool 7
fill ~45 ~1 ~82 ~46 ~1 ~82 wool 7
fill ~45 ~1 ~83 ~46 ~1 ~83 wool 7
fill ~45 ~1 ~84 ~46 ~1 ~84 wool 7
fill ~45 ~1 ~85 ~46 ~1 ~85 stained_hardened_clay 9
fill ~45 ~1 ~86 ~46 ~1 ~86 stained_hardened_clay 9
fill ~47 ~1 ~9 ~53 ~1 ~9 stained_hardened_clay 9
fill ~47 ~1 ~84 ~53 ~1 ~84 stained_hardened_clay 9
fill ~54 ~1 ~7 ~55 ~1 ~7 stained_hardened_clay 9
fill ~54 ~1 ~8 ~55 ~1 ~8 stained_hardened_clay 9
fill ~54 ~1 ~9 ~55 ~1 ~9 wool 7
fill ~54 ~1 ~10 ~55 ~1 ~10 wool 7
fill ~54 ~1 ~11 ~55 ~1 ~11 wool 7
fill ~54 ~1 ~12 ~55 ~1 ~12 wool 7
fill ~54 ~1 ~13 ~55 ~1 ~13 wool 7
fill ~54 ~1 ~14 ~55 ~1 ~14 wool 7
fill ~54 ~1 ~79 ~55 ~1 ~79 wool 7
fill ~54 ~1 ~80 ~55 ~1 ~80 wool 7
fill ~54 ~1 ~81 ~55 ~1 ~81 wool 7
fill ~54 ~1 ~82 ~55 ~1 ~82 wool 7
fill ~54 ~1 ~83 ~55 ~1 ~83 wool 7
fill ~54 ~1 ~84 ~55 ~1 ~84 wool 7
fill ~54 ~1 ~85 ~55 ~1 ~85 stained_hardened_clay 9
fill ~54 ~1 ~86 ~55 ~1 ~86 stained_hardened_clay 9
fill ~56 ~1 ~7 ~58 ~1 ~7 wool 15
fill ~56 ~1 ~14 ~58 ~1 ~14 wool 15
fill ~56 ~1 ~79 ~58 ~1 ~79 wool 15
fill ~56 ~1 ~86 ~58 ~1 ~86 wool 15
fill ~59 ~1 ~8 ~59 ~1 ~13 wool 15
fill ~59 ~1 ~80 ~59 ~1 ~85 wool 15
fill ~155 ~1 ~8 ~155 ~1 ~17 wool 15
fill ~155 ~1 ~76 ~155 ~1 ~85 wool 15
fill ~156 ~1 ~7 ~160 ~1 ~7 wool 15
fill ~156 ~1 ~18 ~160 ~1 ~18 wool 15
fill ~156 ~1 ~75 ~160 ~1 ~75 wool 15
fill ~156 ~1 ~86 ~160 ~1 ~86 wool 15
fill ~161 ~1 ~7 ~167 ~1 ~7 stained_hardened_clay 9
fill ~161 ~1 ~8 ~167 ~1 ~8 stained_hardened_clay 9
fill ~161 ~1 ~9 ~167 ~1 ~9 wool 7
fill ~161 ~1 ~10 ~167 ~1 ~10 wool 7
fill ~161 ~1 ~11 ~167 ~1 ~11 wool 7
fill ~161 ~1 ~12 ~167 ~1 ~12 wool 7
fill ~161 ~1 ~13 ~167 ~1 ~13 wool 7
fill ~161 ~1 ~14 ~167 ~1 ~14 wool 7
fill ~161 ~1 ~15 ~167 ~1 ~15 wool 7
fill ~161 ~1 ~16 ~167 ~1 ~16 wool 7
fill ~161 ~1 ~17 ~167 ~1 ~17 wool 7
fill ~161 ~1 ~18 ~167 ~1 ~18 wool 7
fill ~161 ~1 ~75 ~167 ~1 ~75 wool 7
fill ~161 ~1 ~76 ~167 ~1 ~76 wool 7
fill ~161 ~1 ~77 ~167 ~1 ~77 wool 7
fill ~161 ~1 ~78 ~167 ~1 ~78 wool 7
fill ~161 ~1 ~79 ~167 ~1 ~79 wool 7
fill ~161 ~1 ~80 ~167 ~1 ~80 wool 7
fill ~161 ~1 ~81 ~167 ~1 ~81 wool 7
fill ~161 ~1 ~82 ~167 ~1 ~82 wool 7
fill ~161 ~1 ~83 ~167 ~1 ~83 wool 7
fill ~161 ~1 ~84 ~167 ~1 ~84 wool 7
fill ~161 ~1 ~85 ~167 ~1 ~85 stained_hardened_clay 9
fill ~161 ~1 ~86 ~167 ~1 ~86 stained_hardened_clay 9
fill ~168 ~1 ~7 ~172 ~1 ~7 wool 15
fill ~168 ~1 ~18 ~172 ~1 ~18 wool 15
fill ~168 ~1 ~75 ~172 ~1 ~75 wool 15
fill ~168 ~1 ~86 ~172 ~1 ~86 wool 15
fill ~173 ~1 ~8 ~173 ~1 ~17 wool 15
fill ~173 ~1 ~76 ~173 ~1 ~85 wool 15
fill ~40 ~2 ~8 ~40 ~2 ~13 wool 15
fill ~40 ~2 ~80 ~40 ~2 ~85 wool 15
fill ~41 ~2 ~7 ~42 ~2 ~7 wool 15
fill ~41 ~2 ~14 ~42 ~2 ~14 wool 15
fill ~41 ~2 ~79 ~42 ~2 ~79 wool 15
fill ~41 ~2 ~86 ~42 ~2 ~86 wool 15
fill ~43 ~2 ~7 ~44 ~2 ~7 stained_hardened_clay 9
fill ~43 ~2 ~8 ~44 ~2 ~8 stained_hardened_clay 9
fill ~43 ~2 ~9 ~44 ~2 ~9 wool 7
fill ~43 ~2 ~10 ~44 ~2 ~10 wool 7
fill ~43 ~2 ~11 ~44 ~2 ~11 wool 7
fill ~43 ~2 ~12 ~44 ~2 ~12 wool 7
fill ~43 ~2 ~13 ~44 ~2 ~13 wool 7
fill ~43 ~2 ~14 ~44 ~2 ~14 wool 7
fill ~43 ~2 ~79 ~44 ~2 ~79 wool 7
fill ~43 ~2 ~80 ~44 ~2 ~80 wool 7
fill ~43 ~2 ~81 ~44 ~2 ~81 wool 7
fill ~43 ~2 ~82 ~44 ~2 ~82 wool 7
fill ~43 ~2 ~83 ~44 ~2 ~83 wool 7
fill ~43 ~2 ~84 ~44 ~2 ~84 wool 7
fill ~43 ~2 ~85 ~44 ~2 ~85 stained_hardened_clay 9
fill ~43 ~2 ~86 ~44 ~2 ~86 stained_hardened_clay 9
fill ~45 ~2 ~9 ~46 ~2 ~9 stained_hardened_clay 9
fill ~45 ~2 ~84 ~46 ~2 ~84 stained_hardened_clay 9
fill ~54 ~2 ~9 ~55 ~2 ~9 stained_hardened_clay 9
fill ~54 ~2 ~84 ~55 ~2 ~84 stained_hardened_clay 9
fill ~56 ~2 ~7 ~57 ~2 ~7 stained_hardened_clay 9
fill ~56 ~2 ~8 ~57 ~2 ~8 stained_hardened_clay 9
fill ~56 ~2 ~9 ~57 ~2 ~9 wool 7
fill ~56 ~2 ~10 ~57 ~2 ~10 wool 7
fill ~56 ~2 ~11 ~57 ~2 ~11 wool 7
fill ~56 ~2 ~12 ~57 ~2 ~12 wool 7
fill ~56 ~2 ~13 ~57 ~2 ~13 wool 7
fill ~56 ~2 ~14 ~57 ~2 ~14 wool 7
fill ~56 ~2 ~79 ~57 ~2 ~79 wool 7
fill ~56 ~2 ~80 ~57 ~2 ~80 wool 7
fill ~56 ~2 ~81 ~57 ~2 ~81 wool 7
fill ~56 ~2 ~82 ~57 ~2 ~82 wool 7
fill ~56 ~2 ~83 ~57 ~2 ~83 wool 7
fill ~56 ~2 ~84 ~57 ~2 ~84 wool 7
fill ~56 ~2 ~85 ~57 ~2 ~85 stained_hardened_clay 9
fill ~56 ~2 ~86 ~57 ~2 ~86 stained_hardened_clay 9
fill ~58 ~2 ~7 ~59 ~2 ~7 wool 15
fill ~58 ~2 ~14 ~59 ~2 ~14 wool 15
fill ~58 ~2 ~79 ~59 ~2 ~79 wool 15
fill ~58 ~2 ~86 ~59 ~2 ~86 wool 15
fill ~60 ~2 ~8 ~60 ~2 ~13 wool 15
fill ~60 ~2 ~80 ~60 ~2 ~85 wool 15
fill ~154 ~2 ~8 ~154 ~2 ~17 wool 15
fill ~154 ~2 ~76 ~154 ~2 ~85 wool 15
fill ~155 ~2 ~7 ~158 ~2 ~7 wool 15
fill ~155 ~2 ~18 ~158 ~2 ~18 wool 15
fill ~155 ~2 ~75 ~158 ~2 ~75 wool 15
fill ~155 ~2 ~86 ~158 ~2 ~86 wool 15
fill ~159 ~2 ~7 ~160 ~2 ~7 stained_hardened_clay 9
fill ~159 ~2 ~8 ~160 ~2 ~8 stained_hardened_clay 9
fill ~159 ~2 ~9 ~160 ~2 ~9 wool 7
fill ~159 ~2 ~10 ~160 ~2 ~10 wool 7
fill ~159 ~2 ~11 ~160 ~2 ~11 wool 7
fill ~159 ~2 ~12 ~160 ~2 ~12 wool 7
fill ~159 ~2 ~13 ~160 ~2 ~13 wool 7
fill ~159 ~2 ~14 ~160 ~2 ~14 wool 7
fill ~159 ~2 ~15 ~160 ~2 ~15 wool 7
fill ~159 ~2 ~16 ~160 ~2 ~16 wool 7
fill ~159 ~2 ~17 ~160 ~2 ~17 wool 7
fill ~159 ~2 ~18 ~160 ~2 ~18 wool 7
fill ~159 ~2 ~75 ~160 ~2 ~75 wool 7
fill ~159 ~2 ~76 ~160 ~2 ~76 wool 7
fill ~159 ~2 ~77 ~160 ~2 ~77 wool 7
fill ~159 ~2 ~78 ~160 ~2 ~78 wool 7
fill ~159 ~2 ~79 ~160 ~2 ~79 wool 7
fill ~159 ~2 ~80 ~160 ~2 ~80 wool 7
fill ~159 ~2 ~81 ~160 ~2 ~81 wool 7
fill ~159 ~2 ~82 ~160 ~2 ~82 wool 7
fill ~159 ~2 ~83 ~160 ~2 ~83 wool 7
fill ~159 ~2 ~84 ~160 ~2 ~84 wool 7
fill ~159 ~2 ~85 ~160 ~2 ~85 stained_hardened_clay 9
fill ~159 ~2 ~86 ~160 ~2 ~86 stained_hardened_clay 9
fill ~161 ~2 ~9 ~167 ~2 ~9 stained_hardened_clay 9
fill ~161 ~2 ~84 ~167 ~2 ~84 stained_hardened_clay 9
fill ~168 ~2 ~7 ~169 ~2 ~7 stained_hardened_clay 9
fill ~168 ~2 ~8 ~169 ~2 ~8 stained_hardened_clay 9
fill ~168 ~2 ~9 ~169 ~2 ~9 wool 7
fill ~168 ~2 ~10 ~169 ~2 ~10 wool 7
fill ~168 ~2 ~11 ~169 ~2 ~11 wool 7
fill ~168 ~2 ~12 ~169 ~2 ~12 wool 7
fill ~168 ~2 ~13 ~169 ~2 ~13 wool 7
fill ~168 ~2 ~14 ~169 ~2 ~14 wool 7
fill ~168 ~2 ~15 ~169 ~2 ~15 wool 7
fill ~168 ~2 ~16 ~169 ~2 ~16 wool 7
fill ~168 ~2 ~17 ~169 ~2 ~17 wool 7
fill ~168 ~2 ~18 ~169 ~2 ~18 wool 7
fill ~168 ~2 ~75 ~169 ~2 ~75 wool 7
fill ~168 ~2 ~76 ~169 ~2 ~76 wool 7
fill ~168 ~2 ~77 ~169 ~2 ~77 wool 7
fill ~168 ~2 ~78 ~169 ~2 ~78 wool 7
fill ~168 ~2 ~79 ~169 ~2 ~79 wool 7
fill ~168 ~2 ~80 ~169 ~2 ~80 wool 7
fill ~168 ~2 ~81 ~169 ~2 ~81 wool 7
fill ~168 ~2 ~82 ~169 ~2 ~82 wool 7
fill ~168 ~2 ~83 ~169 ~2 ~83 wool 7
fill ~168 ~2 ~84 ~169 ~2 ~84 wool 7
fill ~168 ~2 ~85 ~169 ~2 ~85 stained_hardened_clay 9
fill ~168 ~2 ~86 ~169 ~2 ~86 stained_hardened_clay 9
fill ~170 ~2 ~7 ~173 ~2 ~7 wool 15
fill ~170 ~2 ~18 ~173 ~2 ~18 wool 15
fill ~170 ~2 ~75 ~173 ~2 ~75 wool 15
fill ~170 ~2 ~86 ~173 ~2 ~86 wool 15
fill ~174 ~2 ~8 ~174 ~2 ~17 wool 15
fill ~174 ~2 ~76 ~174 ~2 ~85 wool 15
fill ~39 ~3 ~8 ~39 ~3 ~13 wool 15
fill ~39 ~3 ~80 ~39 ~3 ~85 wool 15
fill ~40 ~3 ~7 ~41 ~3 ~7 wool 15
fill ~40 ~3 ~14 ~41 ~3 ~14 wool 15
fill ~40 ~3 ~79 ~41 ~3 ~79 wool 15
fill ~40 ~3 ~86 ~41 ~3 ~86 wool 15
fill ~42 ~3 ~7 ~42 ~3 ~8 stained_hardened_clay 9
fill ~42 ~3 ~9 ~42 ~3 ~14 wool 7
fill ~42 ~3 ~79 ~42 ~3 ~84 wool 7
fill ~42 ~3 ~85 ~42 ~3 ~86 stained_hardened_clay 9
fill ~43 ~3 ~9 ~44 ~3 ~9 stained_hardened_clay 9
fill ~43 ~3 ~84 ~44 ~3 ~84 stained_hardened_clay 9
fill ~45 ~3 ~7 ~45 ~4 ~7 stained_hardened_clay 9
fill ~45 ~3 ~86 ~45 ~4 ~86 stained_hardened_clay 9
fill ~55 ~3 ~7 ~55 ~4 ~7 stained_hardened_clay 9
fill ~55 ~3 ~86 ~55 ~4 ~86 stained_hardened_clay 9
fill ~56 ~3 ~9 ~57 ~3 ~9 stained_hardened_clay 9
fill ~56 ~3 ~84 ~57 ~3 ~84 stained_hardened_clay 9
fill ~58 ~3 ~7 ~58 ~3 ~8 stained_hardened_clay 9
fill ~58 ~3 ~9 ~58 ~3 ~14 wool 7
fill ~58 ~3 ~79 ~58 ~3 ~84 wool 7
fill ~58 ~3 ~85 ~58 ~3 ~86 stained_hardened_clay 9
fill ~59 ~3 ~7 ~60 ~3 ~7 wool 15
fill ~59 ~3 ~14 ~60 ~3 ~14 wool 15
fill ~59 ~3 ~79 ~60 ~3 ~79 wool 15
fill ~59 ~3 ~86 ~60 ~3 ~86 wool 15
fill ~61 ~3 ~8 ~61 ~3 ~13 wool 15
fill ~61 ~3 ~80 ~61 ~3 ~85 wool 15
fill ~153 ~3 ~8 ~153 ~3 ~17 wool 15
fill ~153 ~3 ~76 ~153 ~3 ~85 wool 15
fill ~154 ~3 ~7 ~156 ~3 ~7 wool 15
fill ~154 ~3 ~18 ~156 ~3 ~18 wool 15
fill ~154 ~3 ~75 ~156 ~3 ~75 wool 15
fill ~154 ~3 ~86 ~156 ~3 ~86 wool 15
fill ~157 ~3 ~7 ~158 ~3 ~7 stained_hardened_clay 9
fill ~157 ~3 ~8 ~158 ~3 ~8 stained_hardened_clay 9
fill ~157 ~3 ~9 ~158 ~3 ~9 wool 7
fill ~157 ~3 ~10 ~158 ~3 ~10 wool 7
fill ~157 ~3 ~11 ~158 ~3 ~11 wool 7
fill ~157 ~3 ~12 ~158 ~3 ~12 wool 7
fill ~157 ~3 ~13 ~158 ~3 ~13 wool 7
fill ~157 ~3 ~14 ~158 ~3 ~14 wool 7
fill ~157 ~3 ~15 ~158 ~3 ~15 wool 7
fill ~157 ~3 ~16 ~158 ~3 ~16 wool 7
fill ~157 ~3 ~17 ~158 ~3 ~17 wool 7
fill ~157 ~3 ~18 ~158 ~3 ~18 wool 7
fill ~157 ~3 ~75 ~158 ~3 ~75 wool 7
fill ~157 ~3 ~76 ~158 ~3 ~76 wool 7
fill ~157 ~3 ~77 ~158 ~3 ~77 wool 7
fill ~157 ~3 ~78 ~158 ~3 ~78 wool 7
fill ~157 ~3 ~79 ~158 ~3 ~79 wool 7
fill ~157 ~3 ~80 ~158 ~3 ~80 wool 7
fill ~157 ~3 ~81 ~158 ~3 ~81 wool 7
fill ~157 ~3 ~82 ~158 ~3 ~82 wool 7
fill ~157 ~3 ~83 ~158 ~3 ~83 wool 7
fill ~157 ~3 ~84 ~158 ~3 ~84 wool 7
fill ~157 ~3 ~85 ~158 ~3 ~85 stained_hardened_clay 9
fill ~157 ~3 ~86 ~158 ~3 ~86 stained_hardened_clay 9
fill ~159 ~3 ~9 ~160 ~3 ~9 stained_hardened_clay 9
fill ~159 ~3 ~84 ~160 ~3 ~84 stained_hardened_clay 9
fill ~168 ~3 ~9 ~169 ~3 ~9 stained_hardened_clay 9
fill ~168 ~3 ~84 ~169 ~3 ~84 stained_hardened_clay 9
fill ~170 ~3 ~7 ~171 ~3 ~7 stained_hardened_clay 9
fill ~170 ~3 ~8 ~171 ~3 ~8 stained_hardened_clay 9
fill ~170 ~3 ~9 ~171 ~3 ~9 wool 7
fill ~170 ~3 ~10 ~171 ~3 ~10 wool 7
fill ~170 ~3 ~11 ~171 ~3 ~11 wool 7
fill ~170 ~3 ~12 ~171 ~3 ~12 wool 7
fill ~170 ~3 ~13 ~171 ~3 ~13 wool 7
fill ~170 ~3 ~14 ~171 ~3 ~14 wool 7
fill ~170 ~3 ~15 ~171 ~3 ~15 wool 7
fill ~170 ~3 ~16 ~171 ~3 ~16 wool 7
fill ~170 ~3 ~17 ~171 ~3 ~17 wool 7
fill ~170 ~3 ~18 ~171 ~3 ~18 wool 7
fill ~170 ~3 ~75 ~171 ~3 ~75 wool 7
fill ~170 ~3 ~76 ~171 ~3 ~76 wool 7
fill ~170 ~3 ~77 ~171 ~3 ~77 wool 7
fill ~170 ~3 ~78 ~171 ~3 ~78 wool 7
fill ~170 ~3 ~79 ~171 ~3 ~79 wool 7
fill ~170 ~3 ~80 ~171 ~3 ~80 wool 7
fill ~170 ~3 ~81 ~171 ~3 ~81 wool 7
fill ~170 ~3 ~82 ~171 ~3 ~82 wool 7
fill ~170 ~3 ~83 ~171 ~3 ~83 wool 7
fill ~170 ~3 ~84 ~171 ~3 ~84 wool 7
fill ~170 ~3 ~85 ~171 ~3 ~85 stained_hardened_clay 9
fill ~170 ~3 ~86 ~171 ~3 ~86 stained_hardened_clay 9
fill ~172 ~3 ~7 ~174 ~3 ~7 wool 15
fill ~172 ~3 ~18 ~174 ~3 ~18 wool 15
fill ~172 ~3 ~75 ~174 ~3 ~75 wool 15
fill ~172 ~3 ~86 ~174 ~3 ~86 wool 15
fill ~175 ~3 ~8 ~175 ~3 ~17 wool 15
fill ~175 ~3 ~76 ~175 ~3 ~85 wool 15
fill ~26 ~4 ~8 ~27 ~4 ~8 stained_hardened_clay 14
fill ~26 ~4 ~9 ~33 ~4 ~9 wool 15
fill ~26 ~4 ~10 ~33 ~4 ~10 wool 15
fill ~26 ~4 ~11 ~33 ~4 ~11 wool 15
fill ~26 ~4 ~12 ~33 ~4 ~12 wool 15
fill ~26 ~4 ~13 ~33 ~4 ~13 wool 15
fill ~26 ~4 ~14 ~33 ~4 ~14 wool 15
fill ~26 ~4 ~15 ~33 ~4 ~15 wool 15
fill ~26 ~4 ~16 ~33 ~4 ~16 wool 15
fill ~26 ~4 ~17 ~33 ~4 ~17 wool 15
fill ~26 ~4 ~18 ~33 ~4 ~18 wool 15
fill ~26 ~4 ~19 ~33 ~4 ~19 wool 15
fill ~26 ~4 ~20 ~33 ~4 ~20 wool 15
fill ~26 ~4 ~21 ~33 ~4 ~21 wool 15
fill ~26 ~4 ~22 ~34 ~4 ~22 wool 15
fill ~26 ~4 ~23 ~34 ~4 ~23 wool 15
fill ~26 ~4 ~24 ~35 ~4 ~24 wool 15
fill ~26 ~4 ~25 ~37 ~4 ~25 wool 15
fill ~26 ~4 ~26 ~181 ~4 ~26 wool 15
fill ~26 ~4 ~27 ~172 ~4 ~27 wool 15
fill ~26 ~4 ~28 ~172 ~4 ~28 wool 15
fill ~26 ~4 ~29 ~172 ~4 ~29 wool 15
fill ~26 ~4 ~30 ~172 ~4 ~30 wool 15
fill ~26 ~4 ~31 ~183 ~4 ~31 wool 15
fill ~26 ~4 ~32 ~172 ~4 ~32 wool 15
fill ~26 ~4 ~33 ~172 ~4 ~33 wool 15
fill ~26 ~4 ~34 ~172 ~4 ~34 wool 15
fill ~26 ~4 ~35 ~172 ~4 ~35 wool 15
fill ~26 ~4 ~36 ~183 ~4 ~36 wool 15
fill ~26 ~4 ~37 ~172 ~4 ~37 wool 15
fill ~26 ~4 ~38 ~176 ~4 ~38 wool 15
fill ~26 ~4 ~39 ~178 ~4 ~39 wool 15
fill ~26 ~4 ~40 ~178 ~4 ~40 wool 15
fill ~26 ~4 ~41 ~178 ~4 ~41 wool 15
fill ~26 ~4 ~42 ~178 ~4 ~42 wool 15
fill ~26 ~4 ~43 ~178 ~4 ~43 wool 15
fill ~26 ~4 ~44 ~178 ~4 ~44 wool 15
fill ~26 ~4 ~45 ~178 ~4 ~45 wool 15
fill ~26 ~4 ~46 ~178 ~4 ~46 wool 15
fill ~26 ~4 ~47 ~178 ~4 ~47 wool 15
fill ~26 ~4 ~48 ~178 ~4 ~48 wool 15
fill ~26 ~4 ~49 ~178 ~4 ~49 wool 15
fill ~26 ~4 ~50 ~178 ~4 ~50 wool 15
fill ~26 ~4 ~51 ~178 ~4 ~51 wool 15
fill ~26 ~4 ~52 ~178 ~4 ~52 wool 15
fill ~26 ~4 ~53 ~178 ~4 ~53 wool 15
fill ~26 ~4 ~54 ~178 ~4 ~54 wool 15
fill ~26 ~4 ~55 ~176 ~4 ~55 wool 15
fill ~26 ~4 ~56 ~172 ~4 ~56 wool 15
fill ~26 ~4 ~57 ~183 ~4 ~57 wool 15
fill ~26 ~4 ~58 ~172 ~4 ~58 wool 15
fill ~26 ~4 ~59 ~172 ~4 ~59 wool 15
fill ~26 ~4 ~60 ~172 ~4 ~60 wool 15
fill ~26 ~4 ~61 ~172 ~4 ~61 wool 15
fill ~26 ~4 ~62 ~183 ~4 ~62 wool 15
fill ~26 ~4 ~63 ~172 ~4 ~63 wool 15
fill ~26 ~4 ~64 ~172 ~4 ~64 wool 15
fill ~26 ~4 ~65 ~172 ~4 ~65 wool 15
fill ~26 ~4 ~66 ~172 ~4 ~66 wool 15
fill ~26 ~4 ~67 ~181 ~4 ~67 wool 15
fill ~26 ~4 ~68 ~37 ~4 ~68 wool 15
fill ~26 ~4 ~69 ~35 ~4 ~69 wool 15
fill ~26 ~4 ~70 ~34 ~4 ~70 wool 15
fill ~26 ~4 ~71 ~34 ~4 ~71 wool 15
fill ~26 ~4 ~72 ~33 ~4 ~72 wool 15
fill ~26 ~4 ~73 ~33 ~4 ~73 wool 15
fill ~26 ~4 ~74 ~33 ~4 ~74 wool 15
fill ~26 ~4 ~75 ~33 ~4 ~75 wool 15
fill ~26 ~4 ~76 ~33 ~4 ~76 wool 15
fill ~26 ~4 ~77 ~33 ~4 ~77 wool 15
fill ~26 ~4 ~78 ~33 ~4 ~78 wool 15
fill ~26 ~4 ~79 ~33 ~4 ~79 wool 15
fill ~26 ~4 ~80 ~33 ~4 ~80 wool 15
fill ~26 ~4 ~81 ~33 ~4 ~81 wool 15
fill ~26 ~4 ~82 ~33 ~4 ~82 wool 15
fill ~26 ~4 ~83 ~33 ~4 ~83 wool 15
fill ~26 ~4 ~84 ~33 ~4 ~84 wool 15
fill ~26 ~4 ~85 ~27 ~4 ~85 stained_hardened_clay 14
fill ~28 ~4 ~7 ~34 ~4 ~7 stained_hardened_clay 14
fill ~28 ~4 ~8 ~33 ~4 ~8 wool 15
fill ~28 ~4 ~85 ~33 ~4 ~85 wool 15
fill ~28 ~4 ~86 ~34 ~4 ~86 stained_hardened_clay 14
fill ~38 ~4 ~8 ~38 ~5 ~8 wool 15
fill ~38 ~4 ~9 ~38 ~5 ~9 wool 15
fill ~38 ~4 ~10 ~38 ~5 ~10 wool 15
fill ~38 ~4 ~11 ~38 ~5 ~11 wool 15
fill ~38 ~4 ~12 ~38 ~5 ~12 wool 15
fill ~38 ~4 ~13 ~38 ~5 ~13 wool 15
fill ~38 ~4 ~80 ~38 ~5 ~80 wool 15
fill ~38 ~4 ~81 ~38 ~5 ~81 wool 15
fill ~38 ~4 ~82 ~38 ~5 ~82 wool 15
fill ~38 ~4 ~83 ~38 ~5 ~83 wool 15
fill ~38 ~4 ~84 ~38 ~5 ~84 wool 15
fill ~38 ~4 ~85 ~38 ~5 ~85 wool 15
fill ~39 ~4 ~7 ~40 ~4 ~7 wool 15
fill ~39 ~4 ~14 ~40 ~4 ~14 wool 15
fill ~39 ~4 ~79 ~40 ~4 ~79 wool 15
fill ~39 ~4 ~86 ~40 ~4 ~86 wool 15
fill ~41 ~4 ~7 ~41 ~5 ~7 stained_hardened_clay 9
fill ~41 ~4 ~8 ~41 ~4 ~7 stained_hardened_clay 9
fill ~41 ~4 ~9 ~41 ~4 ~14 wool 7
fill ~41 ~4 ~79 ~41 ~4 ~84 wool 7
fill ~41 ~4 ~85 ~41 ~4 ~86 stained_hardened_clay 9
setblock ~42 ~4 ~9 stained_hardened_clay 9
setblock ~42 ~4 ~84 stained_hardened_clay 9
fill ~45 ~4 ~25 ~55 ~4 ~25 wool 15
fill ~45 ~4 ~68 ~55 ~4 ~68 wool 15
fill ~46 ~4 ~24 ~54 ~4 ~24 wool 15
fill ~46 ~4 ~69 ~54 ~4 ~69 wool 15
fill ~47 ~4 ~21 ~53 ~4 ~21 wool 15
fill ~47 ~4 ~22 ~53 ~4 ~22 wool 15
fill ~47 ~4 ~23 ~53 ~4 ~23 wool 15
fill ~47 ~4 ~70 ~53 ~4 ~70 wool 15
fill ~47 ~4 ~71 ~53 ~4 ~71 wool 15
fill ~47 ~4 ~72 ~53 ~4 ~72 wool 15
fill ~48 ~4 ~19 ~52 ~4 ~19 wool 15
fill ~48 ~4 ~20 ~52 ~4 ~20 wool 15
fill ~48 ~4 ~73 ~52 ~4 ~73 wool 15
fill ~48 ~4 ~74 ~52 ~4 ~74 wool 15
fill ~49 ~4 ~18 ~51 ~4 ~18 wool 15
fill ~49 ~4 ~75 ~51 ~4 ~75 wool 15
setblock ~58 ~4 ~9 stained_hardened_clay 9
setblock ~58 ~4 ~84 stained_hardened_clay 9
fill ~59 ~4 ~7 ~59 ~5 ~7 stained_hardened_clay 9
fill ~59 ~4 ~8 ~59 ~4 ~7 stained_hardened_clay 9
fill ~59 ~4 ~9 ~59 ~4 ~14 wool 7
fill ~59 ~4 ~79 ~59 ~4 ~84 wool 7
fill ~59 ~4 ~85 ~59 ~4 ~86 stained_hardened_clay 9
fill ~60 ~4 ~7 ~61 ~4 ~7 wool 15
fill ~60 ~4 ~14 ~61 ~4 ~14 wool 15
fill ~60 ~4 ~79 ~61 ~4 ~79 wool 15
fill ~60 ~4 ~86 ~61 ~4 ~86 wool 15
fill ~62 ~4 ~8 ~62 ~5 ~8 wool 15
fill ~62 ~4 ~9 ~62 ~5 ~9 wool 15
fill ~62 ~4 ~10 ~62 ~5 ~10 wool 15
fill ~62 ~4 ~11 ~62 ~5 ~11 wool 15
fill ~62 ~4 ~12 ~62 ~5 ~12 wool 15
fill ~62 ~4 ~13 ~62 ~5 ~13 wool 15
fill ~62 ~4 ~80 ~62 ~5 ~80 wool 15
fill ~62 ~4 ~81 ~62 ~5 ~81 wool 15
fill ~62 ~4 ~82 ~62 ~5 ~82 wool 15
fill ~62 ~4 ~83 ~62 ~5 ~83 wool 15
fill ~62 ~4 ~84 ~62 ~5 ~84 wool 15
fill ~62 ~4 ~85 ~62 ~5 ~85 wool 15
fill ~63 ~4 ~25 ~172 ~4 ~25 wool 15
fill ~63 ~4 ~68 ~172 ~4 ~68 wool 15
fill ~65 ~4 ~24 ~177 ~4 ~24 wool 15
fill ~65 ~4 ~69 ~177 ~4 ~69 wool 15
fill ~66 ~4 ~7 ~147 ~4 ~7 stained_hardened_clay 14
fill ~66 ~4 ~22 ~149 ~4 ~22 wool 15
fill ~66 ~4 ~23 ~172 ~4 ~23 wool 15
fill ~66 ~4 ~70 ~172 ~4 ~70 wool 15
fill ~66 ~4 ~71 ~149 ~4 ~71 wool 15
fill ~66 ~4 ~86 ~147 ~4 ~86 stained_hardened_clay 14
fill ~67 ~4 ~8 ~147 ~4 ~8 wool 15
fill ~67 ~4 ~9 ~147 ~4 ~9 wool 15
fill ~67 ~4 ~10 ~147 ~4 ~10 wool 15
fill ~67 ~4 ~11 ~147 ~4 ~11 wool 15
fill ~67 ~4 ~12 ~147 ~4 ~12 wool 15
fill ~67 ~4 ~13 ~147 ~4 ~13 wool 15
fill ~67 ~4 ~14 ~147 ~4 ~14 wool 15
fill ~67 ~4 ~15 ~147 ~4 ~15 wool 15
fill ~67 ~4 ~16 ~147 ~4 ~16 wool 15
fill ~67 ~4 ~17 ~147 ~4 ~17 wool 15
fill ~67 ~4 ~18 ~147 ~4 ~18 wool 15
fill ~67 ~4 ~19 ~147 ~4 ~19 wool 15
fill ~67 ~4 ~20 ~147 ~4 ~20 wool 15
fill ~67 ~4 ~21 ~148 ~4 ~21 wool 15
fill ~67 ~4 ~72 ~148 ~4 ~72 wool 15
fill ~67 ~4 ~73 ~147 ~4 ~73 wool 15
fill ~67 ~4 ~74 ~147 ~4 ~74 wool 15
fill ~67 ~4 ~75 ~147 ~4 ~75 wool 15
fill ~67 ~4 ~76 ~147 ~4 ~76 wool 15
fill ~67 ~4 ~77 ~147 ~4 ~77 wool 15
fill ~67 ~4 ~78 ~147 ~4 ~78 wool 15
fill ~67 ~4 ~79 ~147 ~4 ~79 wool 15
fill ~67 ~4 ~80 ~147 ~4 ~80 wool 15
fill ~67 ~4 ~81 ~147 ~4 ~81 wool 15
fill ~67 ~4 ~82 ~147 ~4 ~82 wool 15
fill ~67 ~4 ~83 ~147 ~4 ~83 wool 15
fill ~67 ~4 ~84 ~147 ~4 ~84 wool 15
fill ~67 ~4 ~85 ~147 ~4 ~85 wool 15
fill ~152 ~4 ~8 ~152 ~4 ~17 wool 15
fill ~152 ~4 ~76 ~152 ~4 ~85 wool 15
fill ~153 ~4 ~7 ~155 ~4 ~7 wool 15
fill ~153 ~4 ~18 ~155 ~4 ~18 wool 15
fill ~153 ~4 ~75 ~155 ~4 ~75 wool 15
fill ~153 ~4 ~86 ~155 ~4 ~86 wool 15
fill ~156 ~4 ~7 ~156 ~4 ~8 stained_hardened_clay 9
fill ~156 ~4 ~9 ~156 ~4 ~18 wool 7
fill ~156 ~4 ~75 ~156 ~4 ~84 wool 7
fill ~156 ~4 ~85 ~156 ~4 ~86 stained_hardened_clay 9
fill ~157 ~4 ~9 ~158 ~4 ~9 stained_hardened_clay 9
fill ~157 ~4 ~84 ~158 ~4 ~84 stained_hardened_clay 9
fill ~159 ~4 ~7 ~159 ~5 ~7 stained_hardened_clay 9
fill ~159 ~4 ~86 ~159 ~5 ~86 stained_hardened_clay 9
fill ~169 ~4 ~7 ~169 ~5 ~7 stained_hardened_clay 9
fill ~169 ~4 ~86 ~169 ~5 ~86 stained_hardened_clay 9
fill ~170 ~4 ~9 ~171 ~4 ~9 stained_hardened_clay 9
fill ~170 ~4 ~84 ~171 ~4 ~84 stained_hardened_clay 9
fill ~172 ~4 ~7 ~172 ~4 ~8 stained_hardened_clay 9
fill ~172 ~4 ~9 ~172 ~4 ~18 wool 7
fill ~172 ~4 ~75 ~172 ~4 ~84 wool 7
fill ~172 ~4 ~85 ~172 ~4 ~86 stained_hardened_clay 9
fill ~173 ~4 ~7 ~175 ~4 ~7 wool 15
fill ~173 ~4 ~18 ~175 ~4 ~18 wool 15
fill ~173 ~4 ~75 ~175 ~4 ~75 wool 15
fill ~173 ~4 ~86 ~175 ~4 ~86 wool 15
fill ~176 ~4 ~8 ~176 ~4 ~17 wool 15
fill ~176 ~4 ~76 ~176 ~4 ~85 wool 15
fill ~178 ~4 ~23 ~180 ~4 ~23 wool 15
fill ~178 ~4 ~70 ~180 ~4 ~70 wool 15
fill ~181 ~4 ~22 ~182 ~4 ~22 wool 15
fill ~181 ~4 ~71 ~182 ~4 ~71 wool 15
fill ~183 ~4 ~21 ~183 ~6 ~21 wool 15
fill ~183 ~4 ~72 ~183 ~6 ~72 wool 15
fill ~184 ~4 ~20 ~184 ~6 ~20 wool 15
fill ~184 ~4 ~73 ~184 ~6 ~73 wool 15
fill ~18 ~5 ~9 ~21 ~5 ~9 stained_hardened_clay 14
fill ~18 ~5 ~10 ~25 ~5 ~10 wool 15
fill ~18 ~5 ~11 ~25 ~5 ~11 wool 15
fill ~18 ~5 ~12 ~25 ~5 ~12 wool 15
fill ~18 ~5 ~13 ~25 ~5 ~13 wool 15
fill ~18 ~5 ~14 ~25 ~5 ~14 wool 15
fill ~18 ~5 ~15 ~25 ~5 ~15 wool 15
fill ~18 ~5 ~16 ~25 ~5 ~16 wool 15
fill ~18 ~5 ~17 ~25 ~5 ~17 wool 15
fill ~18 ~5 ~18 ~25 ~5 ~18 wool 15
fill ~18 ~5 ~19 ~25 ~5 ~19 wool 15
fill ~18 ~5 ~20 ~25 ~5 ~20 wool 15
fill ~18 ~5 ~21 ~25 ~5 ~21 wool 15
fill ~18 ~5 ~22 ~25 ~5 ~22 wool 15
fill ~18 ~5 ~23 ~25 ~5 ~23 wool 15
fill ~18 ~5 ~24 ~25 ~5 ~24 wool 15
fill ~18 ~5 ~25 ~25 ~5 ~25 wool 15
fill ~18 ~5 ~26 ~25 ~5 ~26 wool 15
fill ~18 ~5 ~27 ~25 ~5 ~27 wool 15
fill ~18 ~5 ~28 ~25 ~5 ~28 wool 15
fill ~18 ~5 ~29 ~25 ~5 ~29 wool 15
fill ~18 ~5 ~30 ~25 ~5 ~30 wool 15
fill ~18 ~5 ~31 ~25 ~5 ~31 wool 15
fill ~18 ~5 ~32 ~25 ~5 ~32 wool 15
fill ~18 ~5 ~33 ~25 ~5 ~33 wool 15
fill ~18 ~5 ~34 ~25 ~5 ~34 wool 15
fill ~18 ~5 ~35 ~25 ~5 ~35 wool 15
fill ~18 ~5 ~36 ~25 ~5 ~36 wool 15
fill ~18 ~5 ~37 ~25 ~5 ~37 wool 15
fill ~18 ~5 ~56 ~25 ~5 ~56 wool 15
fill ~18 ~5 ~57 ~25 ~5 ~57 wool 15
fill ~18 ~5 ~58 ~25 ~5 ~58 wool 15
fill ~18 ~5 ~59 ~25 ~5 ~59 wool 15
fill ~18 ~5 ~60 ~25 ~5 ~60 wool 15
fill ~18 ~5 ~61 ~25 ~5 ~61 wool 15
fill ~18 ~5 ~62 ~25 ~5 ~62 wool 15
fill ~18 ~5 ~63 ~25 ~5 ~63 wool 15
fill ~18 ~5 ~64 ~25 ~5 ~64 wool 15
fill ~18 ~5 ~65 ~25 ~5 ~65 wool 15
fill ~18 ~5 ~66 ~25 ~5 ~66 wool 15
fill ~18 ~5 ~67 ~25 ~5 ~67 wool 15
fill ~18 ~5 ~68 ~25 ~5 ~68 wool 15
fill ~18 ~5 ~69 ~25 ~5 ~69 wool 15
fill ~18 ~5 ~70 ~25 ~5 ~70 wool 15
fill ~18 ~5 ~71 ~25 ~5 ~71 wool 15
fill ~18 ~5 ~72 ~25 ~5 ~72 wool 15
fill ~18 ~5 ~73 ~25 ~5 ~73 wool 15
fill ~18 ~5 ~74 ~25 ~5 ~74 wool 15
fill ~18 ~5 ~75 ~25 ~5 ~75 wool 15
fill ~18 ~5 ~76 ~25 ~5 ~76 wool 15
fill ~18 ~5 ~77 ~25 ~5 ~77 wool 15
fill ~18 ~5 ~78 ~25 ~5 ~78 wool 15
fill ~18 ~5 ~79 ~25 ~5 ~79 wool 15
fill ~18 ~5 ~80 ~25 ~5 ~80 wool 15
fill ~18 ~5 ~81 ~25 ~5 ~81 wool 15
fill ~18 ~5 ~82 ~25 ~5 ~82 wool 15
fill ~18 ~5 ~83 ~25 ~5 ~83 wool 15
fill ~18 ~5 ~84 ~21 ~5 ~84 stained_hardened_clay 14
fill ~21 ~5 ~38 ~25 ~5 ~38 wool 15
fill ~21 ~5 ~39 ~25 ~5 ~39 wool 15
fill ~21 ~5 ~40 ~25 ~5 ~40 wool 15
fill ~21 ~5 ~41 ~25 ~5 ~41 wool 15
fill ~21 ~5 ~42 ~25 ~5 ~42 wool 15
fill ~21 ~5 ~43 ~25 ~5 ~43 wool 15
fill ~21 ~5 ~44 ~25 ~5 ~44 wool 15
fill ~21 ~5 ~45 ~25 ~5 ~45 wool 15
fill ~21 ~5 ~46 ~25 ~5 ~46 wool 15
fill ~21 ~5 ~47 ~25 ~5 ~47 wool 15
fill ~21 ~5 ~48 ~25 ~5 ~48 wool 15
fill ~21 ~5 ~49 ~25 ~5 ~49 wool 15
fill ~21 ~5 ~50 ~25 ~5 ~50 wool 15
fill ~21 ~5 ~51 ~25 ~5 ~51 wool 15
fill ~21 ~5 ~52 ~25 ~5 ~52 wool 15
fill ~21 ~5 ~53 ~25 ~5 ~53 wool 15
fill ~21 ~5 ~54 ~25 ~5 ~54 wool 15
fill ~21 ~5 ~55 ~25 ~5 ~55 wool 15
fill ~22 ~5 ~8 ~27 ~5 ~8 stained_hardened_clay 14
fill ~22 ~5 ~9 ~25 ~5 ~9 wool 15
fill ~22 ~5 ~84 ~25 ~5 ~84 wool 15
fill ~22 ~5 ~85 ~27 ~5 ~85 stained_hardened_clay 14
fill ~28 ~5 ~7 ~34 ~5 ~7 stained_hardened_clay 14
fill ~28 ~5 ~86 ~34 ~5 ~86 stained_hardened_clay 14
fill ~33 ~5 ~8 ~33 ~14 ~8 wool 15
fill ~33 ~5 ~9 ~33 ~14 ~9 wool 15
fill ~33 ~5 ~10 ~33 ~14 ~10 wool 15
fill ~33 ~5 ~11 ~33 ~14 ~11 wool 15
fill ~33 ~5 ~12 ~33 ~14 ~12 wool 15
fill ~33 ~5 ~13 ~33 ~14 ~13 wool 15
fill ~33 ~5 ~14 ~33 ~14 ~14 wool 15
fill ~33 ~5 ~15 ~33 ~14 ~15 wool 15
fill ~33 ~5 ~16 ~33 ~14 ~16 wool 15
fill ~33 ~5 ~17 ~33 ~14 ~17 wool 15
fill ~33 ~5 ~18 ~33 ~14 ~18 wool 15
fill ~33 ~5 ~19 ~33 ~14 ~19 wool 15
fill ~33 ~5 ~20 ~33 ~14 ~20 wool 15
fill ~33 ~5 ~21 ~33 ~14 ~21 wool 15
fill ~33 ~5 ~72 ~33 ~14 ~72 wool 15
fill ~33 ~5 ~73 ~33 ~14 ~73 wool 15
fill ~33 ~5 ~74 ~33 ~14 ~74 wool 15
fill ~33 ~5 ~75 ~33 ~14 ~75 wool 15
fill ~33 ~5 ~76 ~33 ~14 ~76 wool 15
fill ~33 ~5 ~77 ~33 ~14 ~77 wool 15
fill ~33 ~5 ~78 ~33 ~14 ~78 wool 15
fill ~33 ~5 ~79 ~33 ~14 ~79 wool 15
fill ~33 ~5 ~80 ~33 ~14 ~80 wool 15
fill ~33 ~5 ~81 ~33 ~14 ~81 wool 15
fill ~33 ~5 ~82 ~33 ~14 ~82 wool 15
fill ~33 ~5 ~83 ~33 ~14 ~83 wool 15
fill ~33 ~5 ~84 ~33 ~14 ~84 wool 15
fill ~33 ~5 ~85 ~33 ~14 ~85 wool 15
fill ~34 ~5 ~22 ~34 ~14 ~22 wool 15
fill ~34 ~5 ~23 ~34 ~14 ~23 wool 15
fill ~34 ~5 ~70 ~34 ~14 ~70 wool 15
fill ~34 ~5 ~71 ~34 ~14 ~71 wool 15
fill ~35 ~5 ~24 ~35 ~14 ~24 wool 15
fill ~35 ~5 ~69 ~35 ~14 ~69 wool 15
fill ~36 ~5 ~25 ~37 ~5 ~25 wool 15
fill ~36 ~5 ~68 ~37 ~5 ~68 wool 15
fill ~38 ~5 ~26 ~62 ~5 ~26 wool 15
fill ~38 ~5 ~67 ~62 ~5 ~67 wool 15
fill ~39 ~5 ~7 ~39 ~6 ~7 wool 15
fill ~39 ~5 ~14 ~39 ~6 ~14 wool 15
fill ~39 ~5 ~79 ~39 ~6 ~79 wool 15
fill ~39 ~5 ~86 ~39 ~6 ~86 wool 15
fill ~40 ~5 ~7 ~40 ~6 ~7 stained_hardened_clay 9
fill ~40 ~5 ~8 ~40 ~6 ~8 stained_hardened_clay 9
fill ~40 ~5 ~9 ~40 ~6 ~9 wool 7
fill ~40 ~5 ~10 ~40 ~6 ~10 wool 7
fill ~40 ~5 ~11 ~40 ~6 ~11 wool 7
fill ~40 ~5 ~12 ~40 ~6 ~12 wool 7
fill ~40 ~5 ~13 ~40 ~6 ~13 wool 7
fill ~40 ~5 ~14 ~40 ~6 ~14 wool 7
fill ~40 ~5 ~79 ~40 ~6 ~79 wool 7
fill ~40 ~5 ~80 ~40 ~6 ~80 wool 7
fill ~40 ~5 ~81 ~40 ~6 ~81 wool 7
fill ~40 ~5 ~82 ~40 ~6 ~82 wool 7
fill ~40 ~5 ~83 ~40 ~6 ~83 wool 7
fill ~40 ~5 ~84 ~40 ~6 ~84 wool 7
fill ~40 ~5 ~85 ~40 ~6 ~85 stained_hardened_clay 9
fill ~40 ~5 ~86 ~41 ~5 ~86 stained_hardened_clay 9
fill ~41 ~5 ~9 ~41 ~6 ~9 stained_hardened_clay 9
fill ~41 ~5 ~84 ~41 ~6 ~84 stained_hardened_clay 9
setblock ~46 ~5 ~7 stained_hardened_clay 9
setblock ~46 ~5 ~86 stained_hardened_clay 9
fill ~47 ~5 ~12 ~51 ~5 ~12 wool 7
fill ~47 ~5 ~81 ~51 ~5 ~81 wool 7
fill ~49 ~5 ~19 ~49 ~11 ~19 wool 15
fill ~49 ~5 ~74 ~49 ~11 ~74 wool 15
fill ~50 ~5 ~18 ~50 ~10 ~18 wool 15
fill ~50 ~5 ~20 ~50 ~19 ~20 wool 15
fill ~50 ~5 ~73 ~50 ~19 ~73 wool 15
fill ~50 ~5 ~75 ~50 ~10 ~75 wool 15
fill ~51 ~5 ~19 ~51 ~11 ~19 wool 15
fill ~51 ~5 ~74 ~51 ~11 ~74 wool 15
setblock ~54 ~5 ~7 stained_hardened_clay 9
setblock ~54 ~5 ~86 stained_hardened_clay 9
fill ~55 ~5 ~27 ~116 ~5 ~27 stone 0
fill ~55 ~5 ~28 ~116 ~5 ~28 stone 0
fill ~55 ~5 ~29 ~116 ~5 ~29 stone 0
fill ~55 ~5 ~30 ~116 ~5 ~30 stone 0
fill ~55 ~5 ~31 ~116 ~5 ~31 stone 0
fill ~55 ~5 ~32 ~116 ~5 ~32 stone 0
fill ~55 ~5 ~33 ~116 ~5 ~33 stone 0
fill ~55 ~5 ~34 ~116 ~5 ~34 stone 0
fill ~55 ~5 ~35 ~116 ~5 ~35 stone 0
fill ~55 ~5 ~36 ~116 ~5 ~36 stone 0
fill ~55 ~5 ~37 ~116 ~5 ~37 stone 0
fill ~55 ~5 ~38 ~116 ~5 ~38 stone 0
fill ~55 ~5 ~39 ~116 ~5 ~39 stone 0
fill ~55 ~5 ~40 ~116 ~5 ~40 stone 0
fill ~55 ~5 ~41 ~116 ~5 ~41 stone 0
fill ~55 ~5 ~42 ~116 ~5 ~42 stone 0
fill ~55 ~5 ~43 ~116 ~5 ~43 stone 0
fill ~55 ~5 ~44 ~116 ~5 ~44 stone 0
fill ~55 ~5 ~45 ~116 ~5 ~45 stone 0
fill ~55 ~5 ~48 ~116 ~5 ~48 stone 0
fill ~55 ~5 ~49 ~116 ~5 ~49 stone 0
fill ~55 ~5 ~50 ~116 ~5 ~50 stone 0
fill ~55 ~5 ~51 ~116 ~5 ~51 stone 0
fill ~55 ~5 ~52 ~116 ~5 ~52 stone 0
fill ~55 ~5 ~53 ~116 ~5 ~53 stone 0
fill ~55 ~5 ~54 ~116 ~5 ~54 stone 0
fill ~55 ~5 ~55 ~116 ~5 ~55 stone 0
fill ~55 ~5 ~56 ~116 ~5 ~56 stone 0
fill ~55 ~5 ~57 ~116 ~5 ~57 stone 0
fill ~55 ~5 ~58 ~116 ~5 ~58 stone 0
fill ~55 ~5 ~59 ~116 ~5 ~59 stone 0
fill ~55 ~5 ~60 ~116 ~5 ~60 stone 0
fill ~55 ~5 ~61 ~116 ~5 ~61 stone 0
fill ~55 ~5 ~62 ~116 ~5 ~62 stone 0
fill ~55 ~5 ~63 ~116 ~5 ~63 stone 0
fill ~55 ~5 ~64 ~116 ~5 ~64 stone 0
fill ~55 ~5 ~65 ~116 ~5 ~65 stone 0
fill ~55 ~5 ~66 ~116 ~5 ~66 stone 0
fill ~59 ~5 ~9 ~59 ~6 ~9 stained_hardened_clay 9
fill ~59 ~5 ~84 ~59 ~6 ~84 stained_hardened_clay 9
fill ~59 ~5 ~86 ~60 ~5 ~86 stained_hardened_clay 9
fill ~60 ~5 ~7 ~60 ~6 ~7 stained_hardened_clay 9
fill ~60 ~5 ~8 ~60 ~6 ~8 stained_hardened_clay 9
fill ~60 ~5 ~9 ~60 ~6 ~9 wool 7
fill ~60 ~5 ~10 ~60 ~6 ~10 wool 7
fill ~60 ~5 ~11 ~60 ~6 ~11 wool 7
fill ~60 ~5 ~12 ~60 ~6 ~12 wool 7
fill ~60 ~5 ~13 ~60 ~6 ~13 wool 7
fill ~60 ~5 ~14 ~60 ~6 ~14 wool 7
fill ~60 ~5 ~79 ~60 ~6 ~79 wool 7
fill ~60 ~5 ~80 ~60 ~6 ~80 wool 7
fill ~60 ~5 ~81 ~60 ~6 ~81 wool 7
fill ~60 ~5 ~82 ~60 ~6 ~82 wool 7
fill ~60 ~5 ~83 ~60 ~6 ~83 wool 7
fill ~60 ~5 ~84 ~60 ~6 ~84 wool 7
fill ~60 ~5 ~85 ~60 ~6 ~85 stained_hardened_clay 9
fill ~61 ~5 ~7 ~61 ~6 ~7 wool 15
fill ~61 ~5 ~14 ~61 ~6 ~14 wool 15
fill ~61 ~5 ~79 ~61 ~6 ~79 wool 15
fill ~61 ~5 ~86 ~61 ~6 ~86 wool 15
fill ~63 ~5 ~25 ~64 ~5 ~25 wool 15
fill ~63 ~5 ~26 ~116 ~5 ~26 stone 0
fill ~63 ~5 ~67 ~116 ~5 ~67 stone 0
fill ~63 ~5 ~68 ~64 ~5 ~68 wool 15
fill ~65 ~5 ~24 ~65 ~14 ~24 wool 15
fill ~65 ~5 ~25 ~116 ~5 ~25 stone 0
fill ~65 ~5 ~68 ~116 ~5 ~68 stone 0
fill ~65 ~5 ~69 ~65 ~14 ~69 wool 15
fill ~66 ~5 ~7 ~147 ~5 ~7 stained_hardened_clay 14
fill ~66 ~5 ~22 ~66 ~14 ~22 wool 15
fill ~66 ~5 ~23 ~66 ~14 ~23 wool 15
fill ~66 ~5 ~24 ~116 ~5 ~24 stone 0
fill ~66 ~5 ~69 ~116 ~5 ~69 stone 0
fill ~66 ~5 ~70 ~66 ~14 ~70 wool 15
fill ~66 ~5 ~71 ~66 ~14 ~71 wool 15
fill ~66 ~5 ~86 ~147 ~5 ~86 stained_hardened_clay 14
fill ~67 ~5 ~8 ~67 ~14 ~8 wool 15
fill ~67 ~5 ~9 ~67 ~14 ~9 wool 15
fill ~67 ~5 ~10 ~67 ~14 ~10 wool 15
fill ~67 ~5 ~11 ~67 ~14 ~11 wool 15
fill ~67 ~5 ~12 ~67 ~14 ~12 wool 15
fill ~67 ~5 ~13 ~67 ~14 ~13 wool 15
fill ~67 ~5 ~14 ~67 ~14 ~14 wool 15
fill ~67 ~5 ~15 ~67 ~14 ~15 wool 15
fill ~67 ~5 ~16 ~67 ~14 ~16 wool 15
fill ~67 ~5 ~17 ~67 ~14 ~17 wool 15
fill ~67 ~5 ~18 ~67 ~14 ~18 wool 15
fill ~67 ~5 ~19 ~67 ~14 ~19 wool 15
fill ~67 ~5 ~20 ~67 ~14 ~20 wool 15
fill ~67 ~5 ~21 ~67 ~14 ~21 wool 15
fill ~67 ~5 ~22 ~116 ~5 ~22 stone 0
fill ~67 ~5 ~23 ~116 ~5 ~23 stone 0
fill ~67 ~5 ~70 ~116 ~5 ~70 stone 0
fill ~67 ~5 ~71 ~116 ~5 ~71 stone 0
fill ~67 ~5 ~72 ~67 ~14 ~72 wool 15
fill ~67 ~5 ~73 ~67 ~14 ~73 wool 15
fill ~67 ~5 ~74 ~67 ~14 ~74 wool 15
fill ~67 ~5 ~75 ~67 ~14 ~75 wool 15
fill ~67 ~5 ~76 ~67 ~14 ~76 wool 15
fill ~67 ~5 ~77 ~67 ~14 ~77 wool 15
fill ~67 ~5 ~78 ~67 ~14 ~78 wool 15
fill ~67 ~5 ~79 ~67 ~14 ~79 wool 15
fill ~67 ~5 ~80 ~67 ~14 ~80 wool 15
fill ~67 ~5 ~81 ~67 ~14 ~81 wool 15
fill ~67 ~5 ~82 ~67 ~14 ~82 wool 15
fill ~67 ~5 ~83 ~67 ~14 ~83 wool 15
fill ~67 ~5 ~84 ~67 ~14 ~84 wool 15
fill ~67 ~5 ~85 ~67 ~14 ~85 wool 15
fill ~68 ~5 ~21 ~116 ~5 ~21 stone 0
fill ~68 ~5 ~72 ~116 ~5 ~72 stone 0
fill ~107 ~5 ~19 ~116 ~5 ~19 stone 0
fill ~107 ~5 ~20 ~116 ~5 ~20 stone 0
fill ~107 ~5 ~73 ~116 ~5 ~73 stone 0
fill ~107 ~5 ~74 ~116 ~5 ~74 stone 0
fill ~115 ~5 ~11 ~115 ~8 ~11 stained_hardened_clay 14
fill ~115 ~5 ~82 ~115 ~8 ~82 stained_hardened_clay 14
fill ~117 ~5 ~19 ~117 ~8 ~19 stained_hardened_clay 9
fill ~117 ~5 ~74 ~117 ~8 ~74 stained_hardened_clay 9
fill ~147 ~5 ~8 ~147 ~17 ~8 wool 15
fill ~147 ~5 ~9 ~147 ~17 ~9 wool 15
fill ~147 ~5 ~10 ~147 ~17 ~10 wool 15
fill ~147 ~5 ~11 ~147 ~17 ~11 wool 15
fill ~147 ~5 ~12 ~147 ~17 ~12 wool 15
fill ~147 ~5 ~13 ~147 ~17 ~13 wool 15
fill ~147 ~5 ~14 ~147 ~17 ~14 wool 15
fill ~147 ~5 ~15 ~147 ~17 ~15 wool 15
fill ~147 ~5 ~16 ~147 ~17 ~16 wool 15
fill ~147 ~5 ~17 ~147 ~17 ~17 wool 15
fill ~147 ~5 ~18 ~147 ~17 ~18 wool 15
fill ~147 ~5 ~19 ~147 ~17 ~19 wool 15
fill ~147 ~5 ~20 ~147 ~17 ~20 wool 15
fill ~147 ~5 ~73 ~147 ~17 ~73 wool 15
fill ~147 ~5 ~74 ~147 ~17 ~74 wool 15
fill ~147 ~5 ~75 ~147 ~17 ~75 wool 15
fill ~147 ~5 ~76 ~147 ~17 ~76 wool 15
fill ~147 ~5 ~77 ~147 ~17 ~77 wool 15
fill ~147 ~5 ~78 ~147 ~17 ~78 wool 15
fill ~147 ~5 ~79 ~147 ~17 ~79 wool 15
fill ~147 ~5 ~80 ~147 ~17 ~80 wool 15
fill ~147 ~5 ~81 ~147 ~17 ~81 wool 15
fill ~147 ~5 ~82 ~147 ~17 ~82 wool 15
fill ~147 ~5 ~83 ~147 ~17 ~83 wool 15
fill ~147 ~5 ~84 ~147 ~17 ~84 wool 15
fill ~147 ~5 ~85 ~147 ~17 ~85 wool 15
fill ~148 ~5 ~21 ~148 ~17 ~21 wool 15
fill ~148 ~5 ~72 ~148 ~17 ~72 wool 15
fill ~149 ~5 ~22 ~149 ~17 ~22 wool 15
fill ~149 ~5 ~71 ~149 ~17 ~71 wool 15
fill ~150 ~5 ~23 ~180 ~5 ~23 wool 15
fill ~150 ~5 ~70 ~180 ~5 ~70 wool 15
fill ~151 ~5 ~8 ~151 ~6 ~8 wool 15
fill ~151 ~5 ~9 ~151 ~6 ~9 wool 15
fill ~151 ~5 ~10 ~151 ~6 ~10 wool 15
fill ~151 ~5 ~11 ~151 ~6 ~11 wool 15
fill ~151 ~5 ~12 ~151 ~6 ~12 wool 15
fill ~151 ~5 ~13 ~151 ~6 ~13 wool 15
fill ~151 ~5 ~14 ~151 ~6 ~14 wool 15
fill ~151 ~5 ~15 ~151 ~6 ~15 wool 15
fill ~151 ~5 ~16 ~151 ~6 ~16 wool 15
fill ~151 ~5 ~17 ~151 ~6 ~17 wool 15
fill ~151 ~5 ~76 ~151 ~6 ~76 wool 15
fill ~151 ~5 ~77 ~151 ~6 ~77 wool 15
fill ~151 ~5 ~78 ~151 ~6 ~78 wool 15
fill ~151 ~5 ~79 ~151 ~6 ~79 wool 15
fill ~151 ~5 ~80 ~151 ~6 ~80 wool 15
fill ~151 ~5 ~81 ~151 ~6 ~81 wool 15
fill ~151 ~5 ~82 ~151 ~6 ~82 wool 15
fill ~151 ~5 ~83 ~151 ~6 ~83 wool 15
fill ~151 ~5 ~84 ~151 ~6 ~84 wool 15
fill ~151 ~5 ~85 ~151 ~6 ~85 wool 15
fill ~152 ~5 ~7 ~154 ~5 ~7 wool 15
fill ~152 ~5 ~18 ~154 ~5 ~18 wool 15
fill ~152 ~5 ~75 ~154 ~5 ~75 wool 15
fill ~152 ~5 ~86 ~154 ~5 ~86 wool 15
fill ~155 ~5 ~7 ~155 ~6 ~7 stained_hardened_clay 9
fill ~155 ~5 ~8 ~155 ~5 ~7 stained_hardened_clay 9
fill ~155 ~5 ~9 ~155 ~5 ~18 wool 7
fill ~155 ~5 ~75 ~155 ~5 ~84 wool 7
fill ~155 ~5 ~85 ~155 ~5 ~86 stained_hardened_clay 9
setblock ~156 ~5 ~9 stained_hardened_clay 9
setblock ~156 ~5 ~84 stained_hardened_clay 9
fill ~162 ~5 ~12 ~166 ~5 ~12 wool 7
fill ~162 ~5 ~81 ~166 ~5 ~81 wool 7
setblock ~172 ~5 ~9 stained_hardened_clay 9
setblock ~172 ~5 ~84 stained_hardened_clay 9
fill ~173 ~5 ~7 ~173 ~6 ~7 stained_hardened_clay 9
fill ~173 ~5 ~8 ~173 ~5 ~7 stained_hardened_clay 9
fill ~173 ~5 ~9 ~173 ~5 ~18 wool 7
fill ~173 ~5 ~24 ~179 ~5 ~24 wool 15
fill ~173 ~5 ~25 ~176 ~5 ~25 wool 15
fill ~173 ~5 ~26 ~188 ~5 ~26 wool 15
fill ~173 ~5 ~27 ~176 ~5 ~27 wool 15
fill ~173 ~5 ~28 ~176 ~5 ~28 wool 15
fill ~173 ~5 ~29 ~176 ~5 ~29 wool 15
fill ~173 ~5 ~30 ~176 ~5 ~30 wool 15
fill ~173 ~5 ~31 ~189 ~5 ~31 wool 15
fill ~173 ~5 ~32 ~176 ~5 ~32 wool 15
fill ~173 ~5 ~33 ~176 ~5 ~33 wool 15
fill ~173 ~5 ~34 ~176 ~5 ~34 wool 15
fill ~173 ~5 ~35 ~176 ~5 ~35 wool 15
fill ~173 ~5 ~36 ~189 ~5 ~36 wool 15
fill ~173 ~5 ~37 ~176 ~5 ~37 wool 15
fill ~173 ~5 ~56 ~176 ~5 ~56 wool 15
fill ~173 ~5 ~57 ~189 ~5 ~57 wool 15
fill ~173 ~5 ~58 ~176 ~5 ~58 wool 15
fill ~173 ~5 ~59 ~176 ~5 ~59 wool 15
fill ~173 ~5 ~60 ~176 ~5 ~60 wool 15
fill ~173 ~5 ~61 ~176 ~5 ~61 wool 15
fill ~173 ~5 ~62 ~189 ~5 ~62 wool 15
fill ~173 ~5 ~63 ~176 ~5 ~63 wool 15
fill ~173 ~5 ~64 ~176 ~5 ~64 wool 15
fill ~173 ~5 ~65 ~176 ~5 ~65 wool 15
fill ~173 ~5 ~66 ~176 ~5 ~66 wool 15
fill ~173 ~5 ~67 ~188 ~5 ~67 wool 15
fill ~173 ~5 ~68 ~176 ~5 ~68 wool 15
fill ~173 ~5 ~69 ~179 ~5 ~69 wool 15
fill ~173 ~5 ~75 ~173 ~5 ~84 wool 7
fill ~173 ~5 ~85 ~173 ~5 ~86 stained_hardened_clay 9
fill ~174 ~5 ~7 ~176 ~5 ~7 wool 15
fill ~174 ~5 ~18 ~176 ~5 ~18 wool 15
fill ~174 ~5 ~75 ~176 ~5 ~75 wool 15
fill ~174 ~5 ~86 ~176 ~5 ~86 wool 15
fill ~177 ~5 ~8 ~177 ~6 ~8 wool 15
fill ~177 ~5 ~9 ~177 ~6 ~9 wool 15
fill ~177 ~5 ~10 ~177 ~6 ~10 wool 15
fill ~177 ~5 ~11 ~177 ~6 ~11 wool 15
fill ~177 ~5 ~12 ~177 ~6 ~12 wool 15
fill ~177 ~5 ~13 ~177 ~6 ~13 wool 15
fill ~177 ~5 ~14 ~177 ~6 ~14 wool 15
fill ~177 ~5 ~15 ~177 ~6 ~15 wool 15
fill ~177 ~5 ~16 ~177 ~6 ~16 wool 15
fill ~177 ~5 ~17 ~177 ~6 ~17 wool 15
fill ~177 ~5 ~38 ~178 ~5 ~38 wool 15
fill ~177 ~5 ~55 ~178 ~5 ~55 wool 15
fill ~177 ~5 ~76 ~177 ~6 ~76 wool 15
fill ~177 ~5 ~77 ~177 ~6 ~77 wool 15
fill ~177 ~5 ~78 ~177 ~6 ~78 wool 15
fill ~177 ~5 ~79 ~177 ~6 ~79 wool 15
fill ~177 ~5 ~80 ~177 ~6 ~80 wool 15
fill ~177 ~5 ~81 ~177 ~6 ~81 wool 15
fill ~177 ~5 ~82 ~177 ~6 ~82 wool 15
fill ~177 ~5 ~83 ~177 ~6 ~83 wool 15
fill ~177 ~5 ~84 ~177 ~6 ~84 wool 15
fill ~177 ~5 ~85 ~177 ~6 ~85 wool 15
fill ~179 ~5 ~39 ~179 ~5 ~54 wool 15
fill ~180 ~5 ~40 ~182 ~5 ~40 wool 15
fill ~180 ~5 ~41 ~184 ~5 ~41 wool 15
fill ~180 ~5 ~42 ~184 ~5 ~42 wool 15
fill ~180 ~5 ~43 ~184 ~5 ~43 wool 15
fill ~180 ~5 ~44 ~184 ~5 ~44 wool 15
fill ~180 ~5 ~45 ~184 ~5 ~45 wool 15
fill ~180 ~5 ~46 ~184 ~5 ~46 wool 15
fill ~180 ~5 ~47 ~184 ~5 ~47 wool 15
fill ~180 ~5 ~48 ~184 ~5 ~48 wool 15
fill ~180 ~5 ~49 ~184 ~5 ~49 wool 15
fill ~180 ~5 ~50 ~184 ~5 ~50 wool 15
fill ~180 ~5 ~51 ~184 ~5 ~51 wool 15
fill ~180 ~5 ~52 ~184 ~5 ~52 wool 15
fill ~180 ~5 ~53 ~182 ~5 ~53 wool 15
fill ~181 ~5 ~22 ~182 ~5 ~22 wool 15
fill ~181 ~5 ~71 ~182 ~5 ~71 wool 15
fill ~185 ~5 ~19 ~186 ~5 ~19 wool 15
fill ~185 ~5 ~74 ~186 ~5 ~74 wool 15
fill ~10 ~6 ~14 ~13 ~6 ~14 stained_hardened_clay 14
fill ~10 ~6 ~15 ~12 ~6 ~15 stained_hardened_clay 14
fill ~10 ~6 ~16 ~12 ~6 ~16 stained_hardened_clay 14
fill ~10 ~6 ~17 ~11 ~6 ~17 stained_hardened_clay 14
fill ~10 ~6 ~18 ~11 ~6 ~18 stained_hardened_clay 14
fill ~10 ~6 ~19 ~10 ~6 ~20 stained_hardened_clay 14
fill ~10 ~6 ~73 ~10 ~6 ~79 stained_hardened_clay 14
fill ~11 ~6 ~13 ~14 ~6 ~13 stained_hardened_clay 14
fill ~11 ~6 ~19 ~11 ~6 ~20 stone 0
fill ~11 ~6 ~21 ~17 ~6 ~21 wool 15
fill ~11 ~6 ~22 ~17 ~6 ~22 wool 15
fill ~11 ~6 ~23 ~17 ~6 ~23 wool 15
fill ~11 ~6 ~24 ~17 ~6 ~24 wool 15
fill ~11 ~6 ~25 ~17 ~6 ~25 wool 15
fill ~11 ~6 ~26 ~17 ~6 ~26 wool 15
fill ~11 ~6 ~27 ~17 ~6 ~27 wool 15
fill ~11 ~6 ~28 ~17 ~6 ~28 wool 15
fill ~11 ~6 ~29 ~17 ~6 ~29 wool 15
fill ~11 ~6 ~30 ~17 ~6 ~30 wool 15
fill ~11 ~6 ~31 ~17 ~6 ~31 wool 15
fill ~11 ~6 ~32 ~17 ~6 ~32 wool 15
fill ~11 ~6 ~33 ~17 ~6 ~33 wool 15
fill ~11 ~6 ~34 ~17 ~6 ~34 wool 15
fill ~11 ~6 ~35 ~17 ~6 ~35 wool 15
fill ~11 ~6 ~36 ~17 ~6 ~36 wool 15
fill ~11 ~6 ~37 ~19 ~6 ~37 wool 15
fill ~11 ~6 ~38 ~16 ~6 ~38 wool 15
fill ~11 ~6 ~39 ~16 ~6 ~39 wool 15
fill ~11 ~6 ~40 ~16 ~6 ~40 wool 15
fill ~11 ~6 ~41 ~16 ~6 ~41 wool 15
fill ~11 ~6 ~42 ~16 ~6 ~42 wool 15
fill ~11 ~6 ~43 ~16 ~6 ~43 wool 15
fill ~11 ~6 ~44 ~16 ~6 ~44 wool 15
fill ~11 ~6 ~45 ~16 ~6 ~45 wool 15
fill ~11 ~6 ~46 ~16 ~6 ~46 wool 15
fill ~11 ~6 ~47 ~16 ~6 ~47 wool 15
fill ~11 ~6 ~48 ~16 ~6 ~48 wool 15
fill ~11 ~6 ~49 ~16 ~6 ~49 wool 15
fill ~11 ~6 ~50 ~16 ~6 ~50 wool 15
fill ~11 ~6 ~51 ~16 ~6 ~51 wool 15
fill ~11 ~6 ~52 ~16 ~6 ~52 wool 15
fill ~11 ~6 ~53 ~16 ~6 ~53 wool 15
fill ~11 ~6 ~54 ~16 ~6 ~54 wool 15
fill ~11 ~6 ~55 ~16 ~6 ~55 wool 15
fill ~11 ~6 ~56 ~19 ~6 ~56 wool 15
fill ~11 ~6 ~57 ~17 ~6 ~57 wool 15
fill ~11 ~6 ~58 ~17 ~6 ~58 wool 15
fill ~11 ~6 ~59 ~17 ~6 ~59 wool 15
fill ~11 ~6 ~60 ~17 ~6 ~60 wool 15
fill ~11 ~6 ~61 ~17 ~6 ~61 wool 15
fill ~11 ~6 ~62 ~17 ~6 ~62 wool 15
fill ~11 ~6 ~63 ~17 ~6 ~63 wool 15
fill ~11 ~6 ~64 ~17 ~6 ~64 wool 15
fill ~11 ~6 ~65 ~17 ~6 ~65 wool 15
fill ~11 ~6 ~66 ~17 ~6 ~66 wool 15
fill ~11 ~6 ~67 ~17 ~6 ~67 wool 15
fill ~11 ~6 ~68 ~17 ~6 ~68 wool 15
fill ~11 ~6 ~69 ~17 ~6 ~69 wool 15
fill ~11 ~6 ~70 ~17 ~6 ~70 wool 15
fill ~11 ~6 ~71 ~17 ~6 ~71 wool 15
fill ~11 ~6 ~72 ~17 ~6 ~72 wool 15
fill ~11 ~6 ~73 ~11 ~6 ~74 stone 0
fill ~11 ~6 ~75 ~11 ~6 ~80 stained_hardened_clay 14
fill ~12 ~6 ~12 ~14 ~6 ~12 stained_hardened_clay 14
fill ~12 ~6 ~17 ~12 ~6 ~18 stone 0
fill ~12 ~6 ~19 ~17 ~6 ~19 wool 15
fill ~12 ~6 ~20 ~17 ~6 ~20 wool 15
fill ~12 ~6 ~73 ~17 ~6 ~73 wool 15
fill ~12 ~6 ~74 ~17 ~6 ~74 wool 15
fill ~12 ~6 ~75 ~12 ~6 ~76 stone 0
fill ~12 ~6 ~77 ~12 ~6 ~81 stained_hardened_clay 14
fill ~13 ~6 ~11 ~15 ~6 ~11 stained_hardened_clay 14
fill ~13 ~6 ~15 ~13 ~6 ~16 stone 0
fill ~13 ~6 ~17 ~17 ~6 ~17 wool 15
fill ~13 ~6 ~18 ~17 ~6 ~18 wool 15
fill ~13 ~6 ~75 ~17 ~6 ~75 wool 15
fill ~13 ~6 ~76 ~17 ~6 ~76 wool 15
fill ~13 ~6 ~77 ~13 ~6 ~78 stone 0
fill ~13 ~6 ~79 ~13 ~6 ~82 stained_hardened_clay 14
setblock ~14 ~6 ~14 stone 0
fill ~14 ~6 ~15 ~17 ~6 ~15 wool 15
fill ~14 ~6 ~16 ~17 ~6 ~16 wool 15
fill ~14 ~6 ~77 ~17 ~6 ~77 wool 15
fill ~14 ~6 ~78 ~17 ~6 ~78 wool 15
setblock ~14 ~6 ~79 stone 0
fill ~14 ~6 ~80 ~14 ~6 ~82 stained_hardened_clay 14
fill ~15 ~6 ~10 ~16 ~6 ~10 stained_hardened_clay 14
fill ~15 ~6 ~12 ~17 ~6 ~12 wool 15
setblock ~15 ~6 ~13 stone 0
fill ~15 ~6 ~14 ~17 ~6 ~14 wool 15
fill ~15 ~6 ~79 ~17 ~6 ~79 wool 15
setblock ~15 ~6 ~80 stone 0
fill ~15 ~6 ~81 ~17 ~6 ~81 wool 15
fill ~15 ~6 ~82 ~15 ~6 ~83 stained_hardened_clay 14
fill ~16 ~6 ~11 ~17 ~6 ~11 wool 15
fill ~16 ~6 ~13 ~17 ~6 ~13 wool 15
fill ~16 ~6 ~80 ~17 ~6 ~80 wool 15
fill ~16 ~6 ~82 ~17 ~6 ~82 wool 15
setblock ~16 ~6 ~83 stained_hardened_clay 14
fill ~17 ~6 ~9 ~26 ~6 ~9 stained_hardened_clay 14
setblock ~17 ~6 ~10 wool 15
setblock ~17 ~6 ~83 wool 15
fill ~17 ~6 ~84 ~26 ~6 ~84 stained_hardened_clay 14
fill ~20 ~6 ~38 ~20 ~6 ~55 wool 15
fill ~22 ~6 ~8 ~28 ~6 ~8 stained_hardened_clay 14
fill ~22 ~6 ~10 ~24 ~6 ~10 stained_hardened_clay 14
fill ~22 ~6 ~11 ~22 ~6 ~8 stained_hardened_clay 14
fill ~22 ~6 ~82 ~22 ~6 ~85 stained_hardened_clay 14
fill ~23 ~6 ~83 ~24 ~6 ~83 stained_hardened_clay 14
fill ~23 ~6 ~85 ~28 ~6 ~85 stained_hardened_clay 14
fill ~28 ~6 ~7 ~34 ~6 ~7 stained_hardened_clay 14
fill ~28 ~6 ~86 ~34 ~6 ~86 stained_hardened_clay 14
fill ~36 ~6 ~25 ~37 ~6 ~25 wool 15
fill ~36 ~6 ~68 ~37 ~6 ~68 wool 15
fill ~37 ~6 ~8 ~37 ~8 ~8 wool 15
fill ~37 ~6 ~9 ~37 ~8 ~9 wool 15
fill ~37 ~6 ~10 ~37 ~8 ~10 wool 15
fill ~37 ~6 ~11 ~37 ~8 ~11 wool 15
fill ~37 ~6 ~12 ~37 ~8 ~12 wool 15
fill ~37 ~6 ~13 ~37 ~8 ~13 wool 15
fill ~37 ~6 ~80 ~37 ~8 ~80 wool 15
fill ~37 ~6 ~81 ~37 ~8 ~81 wool 15
fill ~37 ~6 ~82 ~37 ~8 ~82 wool 15
fill ~37 ~6 ~83 ~37 ~8 ~83 wool 15
fill ~37 ~6 ~84 ~37 ~8 ~84 wool 15
fill ~37 ~6 ~85 ~37 ~8 ~85 wool 15
fill ~38 ~6 ~7 ~38 ~8 ~7 wool 15
fill ~38 ~6 ~14 ~38 ~8 ~14 wool 15
fill ~38 ~6 ~26 ~62 ~6 ~26 wool 15
fill ~38 ~6 ~67 ~62 ~6 ~67 wool 15
fill ~38 ~6 ~79 ~38 ~8 ~79 wool 15
fill ~38 ~6 ~86 ~38 ~8 ~86 wool 15
fill ~40 ~6 ~86 ~40 ~5 ~86 stained_hardened_clay 9
setblock ~42 ~6 ~7 stained_hardened_clay 9
setblock ~42 ~6 ~86 stained_hardened_clay 9
fill ~45 ~6 ~12 ~53 ~6 ~12 wool 7
fill ~45 ~6 ~81 ~53 ~6 ~81 wool 7
setblock ~47 ~6 ~7 stained_hardened_clay 9
setblock ~47 ~6 ~86 stained_hardened_clay 9
setblock ~53 ~6 ~7 stained_hardened_clay 9
setblock ~53 ~6 ~86 stained_hardened_clay 9
fill ~55 ~6 ~33 ~55 ~7 ~33 stained_hardened_clay 9
fill ~55 ~6 ~34 ~55 ~7 ~34 stained_hardened_clay 9
fill ~55 ~6 ~35 ~55 ~7 ~35 stained_hardened_clay 9
fill ~55 ~6 ~36 ~55 ~7 ~36 stained_hardened_clay 9
fill ~55 ~6 ~37 ~55 ~7 ~37 stained_hardened_clay 9
fill ~55 ~6 ~38 ~55 ~7 ~38 stained_hardened_clay 9
fill ~55 ~6 ~39 ~55 ~7 ~39 stained_hardened_clay 9
fill ~55 ~6 ~40 ~55 ~7 ~40 stained_hardened_clay 9
fill ~55 ~6 ~41 ~55 ~7 ~41 stained_hardened_clay 9
fill ~55 ~6 ~42 ~57 ~6 ~42 stained_hardened_clay 9
fill ~55 ~6 ~43 ~55 ~6 ~45 stained_hardened_clay 9
fill ~55 ~6 ~48 ~55 ~6 ~60 stained_hardened_clay 9
fill ~56 ~6 ~32 ~57 ~6 ~32 stained_hardened_clay 9
fill ~56 ~6 ~51 ~57 ~6 ~51 stained_hardened_clay 9
fill ~56 ~6 ~61 ~57 ~6 ~61 stained_hardened_clay 9
fill ~57 ~6 ~33 ~57 ~7 ~33 stained_hardened_clay 9
fill ~57 ~6 ~34 ~57 ~7 ~34 stained_hardened_clay 9
fill ~57 ~6 ~35 ~57 ~7 ~35 stained_hardened_clay 9
fill ~57 ~6 ~36 ~57 ~7 ~36 stained_hardened_clay 9
fill ~57 ~6 ~37 ~57 ~7 ~37 stained_hardened_clay 9
fill ~57 ~6 ~38 ~57 ~7 ~38 stained_hardened_clay 9
fill ~57 ~6 ~39 ~57 ~7 ~39 stained_hardened_clay 9
fill ~57 ~6 ~40 ~57 ~7 ~40 stained_hardened_clay 9
fill ~57 ~6 ~41 ~57 ~7 ~41 stained_hardened_clay 9
fill ~57 ~6 ~43 ~78 ~6 ~43 stained_hardened_clay 9
fill ~57 ~6 ~44 ~57 ~7 ~44 stained_hardened_clay 9
fill ~57 ~6 ~45 ~57 ~7 ~45 stained_hardened_clay 9
fill ~57 ~6 ~48 ~57 ~7 ~48 stained_hardened_clay 9
fill ~57 ~6 ~49 ~57 ~7 ~49 stained_hardened_clay 9
fill ~57 ~6 ~50 ~78 ~6 ~50 stained_hardened_clay 9
fill ~57 ~6 ~52 ~57 ~7 ~52 stained_hardened_clay 9
fill ~57 ~6 ~53 ~57 ~7 ~53 stained_hardened_clay 9
fill ~57 ~6 ~54 ~57 ~7 ~54 stained_hardened_clay 9
fill ~57 ~6 ~55 ~57 ~7 ~55 stained_hardened_clay 9
fill ~57 ~6 ~56 ~57 ~7 ~56 stained_hardened_clay 9
fill ~57 ~6 ~57 ~57 ~7 ~57 stained_hardened_clay 9
fill ~57 ~6 ~58 ~57 ~7 ~58 stained_hardened_clay 9
fill ~57 ~6 ~59 ~57 ~7 ~59 stained_hardened_clay 9
fill ~57 ~6 ~60 ~57 ~7 ~60 stained_hardened_clay 9
setblock ~58 ~6 ~7 stained_hardened_clay 9
fill ~58 ~6 ~31 ~59 ~6 ~31 stained_hardened_clay 9
fill ~58 ~6 ~62 ~59 ~6 ~62 stained_hardened_clay 9
setblock ~58 ~6 ~86 stained_hardened_clay 9
fill ~60 ~6 ~30 ~60 ~9 ~30 stained_hardened_clay 9
fill ~60 ~6 ~63 ~60 ~9 ~63 stained_hardened_clay 9
setblock ~60 ~6 ~86 stained_hardened_clay 9
fill ~61 ~6 ~29 ~61 ~14 ~29 stained_hardened_clay 9
fill ~61 ~6 ~64 ~61 ~13 ~64 stained_hardened_clay 9
fill ~62 ~6 ~7 ~62 ~8 ~7 wool 15
fill ~62 ~6 ~14 ~62 ~8 ~14 wool 15
fill ~62 ~6 ~28 ~62 ~14 ~28 stained_hardened_clay 9
fill ~62 ~6 ~54 ~62 ~8 ~54 iron_block 0
fill ~62 ~6 ~55 ~62 ~8 ~55 iron_block 0
fill ~62 ~6 ~65 ~62 ~13 ~65 stained_hardened_clay 9
fill ~62 ~6 ~79 ~62 ~8 ~79 wool 15
fill ~62 ~6 ~86 ~62 ~8 ~86 wool 15
fill ~63 ~6 ~8 ~63 ~8 ~8 wool 15
fill ~63 ~6 ~9 ~63 ~8 ~9 wool 15
fill ~63 ~6 ~10 ~63 ~8 ~10 wool 15
fill ~63 ~6 ~11 ~63 ~8 ~11 wool 15
fill ~63 ~6 ~12 ~63 ~8 ~12 wool 15
fill ~63 ~6 ~13 ~63 ~8 ~13 wool 15
fill ~63 ~6 ~25 ~64 ~6 ~25 wool 15
fill ~63 ~6 ~27 ~63 ~14 ~27 stained_hardened_clay 9
fill ~63 ~6 ~66 ~63 ~14 ~66 stained_hardened_clay 9
fill ~63 ~6 ~68 ~64 ~6 ~68 wool 15
fill ~63 ~6 ~80 ~63 ~8 ~80 wool 15
fill ~63 ~6 ~81 ~63 ~8 ~81 wool 15
fill ~63 ~6 ~82 ~63 ~8 ~82 wool 15
fill ~63 ~6 ~83 ~63 ~8 ~83 wool 15
fill ~63 ~6 ~84 ~63 ~8 ~84 wool 15
fill ~63 ~6 ~85 ~63 ~8 ~85 wool 15
fill ~64 ~6 ~26 ~64 ~15 ~26 stained_hardened_clay 9
fill ~64 ~6 ~67 ~64 ~15 ~67 stained_hardened_clay 9
fill ~65 ~6 ~25 ~65 ~15 ~25 stained_hardened_clay 9
fill ~65 ~6 ~68 ~65 ~15 ~68 stained_hardened_clay 9
fill ~66 ~6 ~7 ~147 ~6 ~7 stained_hardened_clay 14
fill ~66 ~6 ~24 ~66 ~15 ~24 stained_hardened_clay 9
fill ~66 ~6 ~69 ~66 ~15 ~69 stained_hardened_clay 9
fill ~66 ~6 ~86 ~147 ~6 ~86 stained_hardened_clay 14
fill ~67 ~6 ~22 ~67 ~14 ~22 stained_hardened_clay 9
fill ~67 ~6 ~23 ~67 ~14 ~23 stained_hardened_clay 9
fill ~67 ~6 ~70 ~67 ~16 ~70 stained_hardened_clay 9
fill ~67 ~6 ~71 ~67 ~16 ~71 stained_hardened_clay 9
fill ~68 ~6 ~21 ~116 ~6 ~21 wool 15
fill ~68 ~6 ~72 ~116 ~6 ~72 wool 15
fill ~79 ~6 ~42 ~117 ~6 ~42 stained_hardened_clay 9
fill ~79 ~6 ~51 ~117 ~6 ~51 stained_hardened_clay 9
fill ~86 ~6 ~26 ~108 ~6 ~26 wool 15
fill ~86 ~6 ~27 ~87 ~6 ~27 wool 15
fill ~86 ~6 ~35 ~88 ~6 ~35 wool 15
fill ~86 ~6 ~36 ~108 ~6 ~36 wool 15
fill ~86 ~6 ~57 ~108 ~6 ~57 wool 15
fill ~86 ~6 ~58 ~88 ~6 ~58 wool 15
fill ~86 ~6 ~66 ~87 ~6 ~66 wool 15
fill ~86 ~6 ~67 ~108 ~6 ~67 wool 15
fill ~87 ~6 ~28 ~87 ~7 ~28 wool 15
fill ~87 ~6 ~34 ~88 ~6 ~34 wool 15
fill ~87 ~6 ~59 ~88 ~6 ~59 wool 15
fill ~87 ~6 ~65 ~87 ~7 ~65 wool 15
fill ~88 ~6 ~29 ~88 ~7 ~29 wool 15
fill ~88 ~6 ~30 ~88 ~7 ~30 wool 15
fill ~88 ~6 ~31 ~88 ~7 ~31 wool 15
fill ~88 ~6 ~32 ~88 ~7 ~32 wool 15
fill ~88 ~6 ~33 ~88 ~7 ~33 wool 15
fill ~88 ~6 ~60 ~88 ~7 ~60 wool 15
fill ~88 ~6 ~61 ~88 ~7 ~61 wool 15
fill ~88 ~6 ~62 ~88 ~7 ~62 wool 15
fill ~88 ~6 ~63 ~88 ~7 ~63 wool 15
fill ~88 ~6 ~64 ~88 ~7 ~64 wool 15
fill ~92 ~6 ~8 ~142 ~6 ~8 stained_hardened_clay 14
fill ~92 ~6 ~85 ~142 ~6 ~85 stained_hardened_clay 14
fill ~98 ~6 ~25 ~108 ~6 ~25 wool 15
fill ~98 ~6 ~37 ~108 ~6 ~37 wool 15
fill ~98 ~6 ~56 ~108 ~6 ~56 wool 15
fill ~98 ~6 ~68 ~108 ~6 ~68 wool 15
setblock ~103 ~6 ~27 wool 15
setblock ~103 ~6 ~35 wool 15
setblock ~103 ~6 ~58 wool 15
setblock ~103 ~6 ~66 wool 15
fill ~108 ~6 ~27 ~108 ~7 ~27 wool 15
fill ~108 ~6 ~28 ~108 ~7 ~28 wool 15
fill ~108 ~6 ~29 ~108 ~7 ~29 wool 15
fill ~108 ~6 ~30 ~108 ~7 ~30 wool 15
fill ~108 ~6 ~31 ~108 ~7 ~31 wool 15
fill ~108 ~6 ~32 ~108 ~7 ~32 wool 15
fill ~108 ~6 ~33 ~108 ~7 ~33 wool 15
fill ~108 ~6 ~34 ~108 ~7 ~34 wool 15
fill ~108 ~6 ~35 ~108 ~7 ~35 wool 15
fill ~108 ~6 ~58 ~108 ~7 ~58 wool 15
fill ~108 ~6 ~59 ~108 ~7 ~59 wool 15
fill ~108 ~6 ~60 ~108 ~7 ~60 wool 15
fill ~108 ~6 ~61 ~108 ~7 ~61 wool 15
fill ~108 ~6 ~62 ~108 ~7 ~62 wool 15
fill ~108 ~6 ~63 ~108 ~7 ~63 wool 15
fill ~108 ~6 ~64 ~108 ~7 ~64 wool 15
fill ~108 ~6 ~65 ~108 ~7 ~65 wool 15
fill ~108 ~6 ~66 ~108 ~7 ~66 wool 15
fill ~116 ~6 ~9 ~142 ~6 ~9 stained_hardened_clay 14
fill ~116 ~6 ~84 ~142 ~6 ~84 stained_hardened_clay 14
fill ~117 ~6 ~20 ~117 ~8 ~20 stained_hardened_clay 9
fill ~117 ~6 ~21 ~117 ~8 ~21 stained_hardened_clay 9
fill ~117 ~6 ~22 ~117 ~8 ~22 stained_hardened_clay 9
fill ~117 ~6 ~23 ~117 ~8 ~23 stained_hardened_clay 9
fill ~117 ~6 ~24 ~117 ~8 ~24 stained_hardened_clay 9
fill ~117 ~6 ~25 ~117 ~8 ~25 stained_hardened_clay 9
fill ~117 ~6 ~26 ~117 ~8 ~26 stained_hardened_clay 9
fill ~117 ~6 ~27 ~117 ~8 ~27 stained_hardened_clay 9
fill ~117 ~6 ~28 ~117 ~8 ~28 stained_hardened_clay 9
fill ~117 ~6 ~29 ~117 ~8 ~29 stained_hardened_clay 9
fill ~117 ~6 ~30 ~117 ~8 ~30 stained_hardened_clay 9
fill ~117 ~6 ~31 ~117 ~8 ~31 stained_hardened_clay 9
fill ~117 ~6 ~32 ~117 ~8 ~32 stained_hardened_clay 9
fill ~117 ~6 ~33 ~117 ~8 ~33 stained_hardened_clay 9
fill ~117 ~6 ~34 ~117 ~8 ~34 stained_hardened_clay 9
fill ~117 ~6 ~35 ~117 ~8 ~35 stained_hardened_clay 9
fill ~117 ~6 ~36 ~117 ~8 ~36 stained_hardened_clay 9
fill ~117 ~6 ~37 ~117 ~8 ~37 stained_hardened_clay 9
fill ~117 ~6 ~38 ~117 ~8 ~38 stained_hardened_clay 9
fill ~117 ~6 ~39 ~117 ~8 ~39 stained_hardened_clay 9
fill ~117 ~6 ~40 ~117 ~8 ~40 stained_hardened_clay 9
fill ~117 ~6 ~41 ~117 ~8 ~41 stained_hardened_clay 9
fill ~117 ~6 ~43 ~117 ~13 ~43 stained_hardened_clay 9
fill ~117 ~6 ~44 ~117 ~8 ~44 stained_hardened_clay 9
fill ~117 ~6 ~45 ~117 ~8 ~45 stained_hardened_clay 9
fill ~117 ~6 ~46 ~117 ~8 ~46 stained_hardened_clay 9
fill ~117 ~6 ~47 ~117 ~8 ~47 stained_hardened_clay 9
fill ~117 ~6 ~48 ~117 ~8 ~48 stained_hardened_clay 9
fill ~117 ~6 ~49 ~117 ~8 ~49 stained_hardened_clay 9
fill ~117 ~6 ~50 ~117 ~13 ~50 stained_hardened_clay 9
fill ~117 ~6 ~52 ~117 ~8 ~52 stained_hardened_clay 9
fill ~117 ~6 ~53 ~117 ~8 ~53 stained_hardened_clay 9
fill ~117 ~6 ~54 ~117 ~8 ~54 stained_hardened_clay 9
fill ~117 ~6 ~55 ~117 ~8 ~55 stained_hardened_clay 9
fill ~117 ~6 ~56 ~117 ~8 ~56 stained_hardened_clay 9
fill ~117 ~6 ~57 ~117 ~8 ~57 stained_hardened_clay 9
fill ~117 ~6 ~58 ~117 ~8 ~58 stained_hardened_clay 9
fill ~117 ~6 ~59 ~117 ~8 ~59 stained_hardened_clay 9
fill ~117 ~6 ~60 ~117 ~8 ~60 stained_hardened_clay 9
fill ~117 ~6 ~61 ~117 ~8 ~61 stained_hardened_clay 9
fill ~117 ~6 ~62 ~117 ~8 ~62 stained_hardened_clay 9
fill ~117 ~6 ~63 ~117 ~8 ~63 stained_hardened_clay 9
fill ~117 ~6 ~64 ~117 ~8 ~64 stained_hardened_clay 9
fill ~117 ~6 ~65 ~117 ~8 ~65 stained_hardened_clay 9
fill ~117 ~6 ~66 ~117 ~8 ~66 stained_hardened_clay 9
fill ~117 ~6 ~67 ~117 ~8 ~67 stained_hardened_clay 9
fill ~117 ~6 ~68 ~117 ~8 ~68 stained_hardened_clay 9
fill ~117 ~6 ~69 ~117 ~8 ~69 stained_hardened_clay 9
fill ~117 ~6 ~70 ~117 ~8 ~70 stained_hardened_clay 9
fill ~117 ~6 ~71 ~117 ~8 ~71 stained_hardened_clay 9
fill ~117 ~6 ~72 ~117 ~8 ~72 stained_hardened_clay 9
fill ~117 ~6 ~73 ~117 ~8 ~73 stained_hardened_clay 9
fill ~150 ~6 ~23 ~182 ~6 ~23 wool 15
fill ~150 ~6 ~70 ~182 ~6 ~70 wool 15
fill ~152 ~6 ~7 ~153 ~6 ~7 wool 15
fill ~152 ~6 ~18 ~153 ~6 ~18 wool 15
fill ~152 ~6 ~75 ~153 ~6 ~75 wool 15
fill ~152 ~6 ~86 ~153 ~6 ~86 wool 15
fill ~154 ~6 ~7 ~154 ~7 ~7 stained_hardened_clay 9
fill ~154 ~6 ~8 ~154 ~7 ~8 stained_hardened_clay 9
fill ~154 ~6 ~9 ~154 ~7 ~9 wool 7
fill ~154 ~6 ~10 ~154 ~7 ~10 wool 7
fill ~154 ~6 ~11 ~154 ~7 ~11 wool 7
fill ~154 ~6 ~12 ~154 ~7 ~12 wool 7
fill ~154 ~6 ~13 ~154 ~7 ~13 wool 7
fill ~154 ~6 ~14 ~154 ~7 ~14 wool 7
fill ~154 ~6 ~15 ~154 ~7 ~15 wool 7
fill ~154 ~6 ~16 ~154 ~7 ~16 wool 7
fill ~154 ~6 ~17 ~154 ~7 ~17 wool 7
fill ~154 ~6 ~18 ~154 ~7 ~18 wool 7
fill ~154 ~6 ~75 ~154 ~7 ~75 wool 7
fill ~154 ~6 ~76 ~154 ~7 ~76 wool 7
fill ~154 ~6 ~77 ~154 ~7 ~77 wool 7
fill ~154 ~6 ~78 ~154 ~7 ~78 wool 7
fill ~154 ~6 ~79 ~154 ~7 ~79 wool 7
fill ~154 ~6 ~80 ~154 ~7 ~80 wool 7
fill ~154 ~6 ~81 ~154 ~7 ~81 wool 7
fill ~154 ~6 ~82 ~154 ~7 ~82 wool 7
fill ~154 ~6 ~83 ~154 ~7 ~83 wool 7
fill ~154 ~6 ~84 ~154 ~7 ~84 wool 7
fill ~154 ~6 ~85 ~154 ~7 ~85 stained_hardened_clay 9
fill ~154 ~6 ~86 ~155 ~6 ~86 stained_hardened_clay 9
fill ~155 ~6 ~9 ~155 ~7 ~9 stained_hardened_clay 9
fill ~155 ~6 ~84 ~155 ~7 ~84 stained_hardened_clay 9
setblock ~160 ~6 ~7 stained_hardened_clay 9
fill ~160 ~6 ~12 ~168 ~6 ~12 wool 7
fill ~160 ~6 ~81 ~168 ~6 ~81 wool 7
setblock ~160 ~6 ~86 stained_hardened_clay 9
setblock ~168 ~6 ~7 stained_hardened_clay 9
setblock ~168 ~6 ~86 stained_hardened_clay 9
fill ~173 ~6 ~9 ~173 ~7 ~9 stained_hardened_clay 9
fill ~173 ~6 ~84 ~173 ~7 ~84 stained_hardened_clay 9
fill ~173 ~6 ~86 ~174 ~6 ~86 stained_hardened_clay 9
fill ~174 ~6 ~7 ~174 ~7 ~7 stained_hardened_clay 9
fill ~174 ~6 ~8 ~174 ~7 ~8 stained_hardened_clay 9
fill ~174 ~6 ~9 ~174 ~7 ~9 wool 7
fill ~174 ~6 ~10 ~174 ~7 ~10 wool 7
fill ~174 ~6 ~11 ~174 ~7 ~11 wool 7
fill ~174 ~6 ~12 ~174 ~7 ~12 wool 7
fill ~174 ~6 ~13 ~174 ~7 ~13 wool 7
fill ~174 ~6 ~14 ~174 ~7 ~14 wool 7
fill ~174 ~6 ~15 ~174 ~7 ~15 wool 7
fill ~174 ~6 ~16 ~174 ~7 ~16 wool 7
fill ~174 ~6 ~17 ~174 ~7 ~17 wool 7
fill ~174 ~6 ~18 ~174 ~7 ~18 wool 7
fill ~174 ~6 ~75 ~174 ~7 ~75 wool 7
fill ~174 ~6 ~76 ~174 ~7 ~76 wool 7
fill ~174 ~6 ~77 ~174 ~7 ~77 wool 7
fill ~174 ~6 ~78 ~174 ~7 ~78 wool 7
fill ~174 ~6 ~79 ~174 ~7 ~79 wool 7
fill ~174 ~6 ~80 ~174 ~7 ~80 wool 7
fill ~174 ~6 ~81 ~174 ~7 ~81 wool 7
fill ~174 ~6 ~82 ~174 ~7 ~82 wool 7
fill ~174 ~6 ~83 ~174 ~7 ~83 wool 7
fill ~174 ~6 ~84 ~174 ~7 ~84 wool 7
fill ~174 ~6 ~85 ~174 ~7 ~85 stained_hardened_clay 9
fill ~175 ~6 ~7 ~176 ~6 ~7 wool 15
fill ~175 ~6 ~18 ~176 ~6 ~18 wool 15
fill ~175 ~6 ~75 ~176 ~6 ~75 wool 15
fill ~175 ~6 ~86 ~176 ~6 ~86 wool 15
fill ~177 ~6 ~25 ~179 ~6 ~25 wool 15
fill ~177 ~6 ~26 ~189 ~6 ~26 wool 15
fill ~177 ~6 ~27 ~179 ~6 ~27 wool 15
fill ~177 ~6 ~28 ~179 ~6 ~28 wool 15
fill ~177 ~6 ~29 ~179 ~6 ~29 wool 15
fill ~177 ~6 ~30 ~179 ~6 ~30 wool 15
fill ~177 ~6 ~31 ~190 ~6 ~31 wool 15
fill ~177 ~6 ~32 ~179 ~6 ~32 wool 15
fill ~177 ~6 ~33 ~179 ~6 ~33 wool 15
fill ~177 ~6 ~34 ~179 ~6 ~34 wool 15
fill ~177 ~6 ~35 ~179 ~6 ~35 wool 15
fill ~177 ~6 ~36 ~190 ~6 ~36 wool 15
fill ~177 ~6 ~37 ~179 ~6 ~37 wool 15
fill ~177 ~6 ~56 ~179 ~6 ~56 wool 15
fill ~177 ~6 ~57 ~190 ~6 ~57 wool 15
fill ~177 ~6 ~58 ~179 ~6 ~58 wool 15
fill ~177 ~6 ~59 ~179 ~6 ~59 wool 15
fill ~177 ~6 ~60 ~179 ~6 ~60 wool 15
fill ~177 ~6 ~61 ~179 ~6 ~61 wool 15
fill ~177 ~6 ~62 ~190 ~6 ~62 wool 15
fill ~177 ~6 ~63 ~179 ~6 ~63 wool 15
fill ~177 ~6 ~64 ~179 ~6 ~64 wool 15
fill ~177 ~6 ~65 ~179 ~6 ~65 wool 15
fill ~177 ~6 ~66 ~179 ~6 ~66 wool 15
fill ~177 ~6 ~67 ~189 ~6 ~67 wool 15
fill ~177 ~6 ~68 ~179 ~6 ~68 wool 15
fill ~179 ~6 ~22 ~183 ~6 ~22 wool 15
setblock ~179 ~6 ~38 wool 15
setblock ~179 ~6 ~55 wool 15
fill ~179 ~6 ~71 ~183 ~6 ~71 wool 15
fill ~180 ~6 ~21 ~184 ~6 ~21 wool 15
fill ~180 ~6 ~24 ~182 ~6 ~24 wool 15
fill ~180 ~6 ~39 ~182 ~6 ~39 wool 15
fill ~180 ~6 ~54 ~182 ~6 ~54 wool 15
fill ~180 ~6 ~69 ~182 ~6 ~69 wool 15
fill ~180 ~6 ~72 ~184 ~6 ~72 wool 15
fill ~181 ~6 ~7 ~183 ~6 ~7 stained_hardened_clay 14
fill ~181 ~6 ~8 ~183 ~6 ~8 wool 15
fill ~181 ~6 ~9 ~185 ~6 ~9 wool 15
fill ~181 ~6 ~10 ~186 ~6 ~10 wool 15
fill ~181 ~6 ~11 ~186 ~6 ~11 wool 15
fill ~181 ~6 ~12 ~186 ~6 ~12 wool 15
fill ~181 ~6 ~13 ~186 ~6 ~13 wool 15
fill ~181 ~6 ~14 ~186 ~6 ~14 wool 15
fill ~181 ~6 ~15 ~186 ~6 ~15 wool 15
fill ~181 ~6 ~16 ~186 ~6 ~16 wool 15
fill ~181 ~6 ~17 ~186 ~6 ~17 wool 15
fill ~181 ~6 ~18 ~186 ~6 ~18 wool 15
fill ~181 ~6 ~19 ~187 ~6 ~19 wool 15
fill ~181 ~6 ~20 ~184 ~6 ~20 wool 15
fill ~181 ~6 ~73 ~184 ~6 ~73 wool 15
fill ~181 ~6 ~74 ~187 ~6 ~74 wool 15
fill ~181 ~6 ~75 ~186 ~6 ~75 wool 15
fill ~181 ~6 ~76 ~186 ~6 ~76 wool 15
fill ~181 ~6 ~77 ~186 ~6 ~77 wool 15
fill ~181 ~6 ~78 ~186 ~6 ~78 wool 15
fill ~181 ~6 ~79 ~186 ~6 ~79 wool 15
fill ~181 ~6 ~80 ~186 ~6 ~80 wool 15
fill ~181 ~6 ~81 ~186 ~6 ~81 wool 15
fill ~181 ~6 ~82 ~186 ~6 ~82 wool 15
fill ~181 ~6 ~83 ~186 ~6 ~83 wool 15
fill ~181 ~6 ~84 ~185 ~6 ~84 wool 15
fill ~181 ~6 ~85 ~183 ~6 ~85 wool 15
fill ~181 ~6 ~86 ~183 ~6 ~86 stained_hardened_clay 14
fill ~183 ~6 ~40 ~184 ~6 ~40 wool 15
fill ~183 ~6 ~53 ~184 ~6 ~53 wool 15
fill ~184 ~6 ~8 ~185 ~6 ~8 stained_hardened_clay 14
fill ~184 ~6 ~85 ~185 ~6 ~85 stained_hardened_clay 14
fill ~185 ~6 ~41 ~185 ~6 ~52 wool 15
fill ~186 ~6 ~9 ~186 ~17 ~9 stained_hardened_clay 14
fill ~186 ~6 ~42 ~187 ~6 ~42 wool 15
fill ~186 ~6 ~43 ~189 ~6 ~43 wool 15
fill ~186 ~6 ~44 ~189 ~6 ~44 wool 15
fill ~186 ~6 ~45 ~189 ~6 ~45 wool 15
fill ~186 ~6 ~46 ~189 ~6 ~46 wool 15
fill ~186 ~6 ~47 ~189 ~6 ~47 wool 15
fill ~186 ~6 ~48 ~189 ~6 ~48 wool 15
fill ~186 ~6 ~49 ~189 ~6 ~49 wool 15
fill ~186 ~6 ~50 ~189 ~6 ~50 wool 15
fill ~186 ~6 ~51 ~187 ~6 ~51 wool 15
fill ~186 ~6 ~84 ~186 ~17 ~84 stained_hardened_clay 14
fill ~188 ~6 ~18 ~190 ~6 ~18 wool 15
fill ~188 ~6 ~75 ~190 ~6 ~75 wool 15
fill ~2 ~7 ~40 ~10 ~7 ~40 wool 15
fill ~2 ~7 ~41 ~10 ~7 ~41 wool 15
fill ~2 ~7 ~42 ~10 ~7 ~42 wool 15
fill ~2 ~7 ~43 ~10 ~7 ~43 wool 15
fill ~2 ~7 ~44 ~10 ~7 ~44 wool 15
fill ~2 ~7 ~45 ~10 ~7 ~45 wool 15
fill ~2 ~7 ~46 ~10 ~7 ~46 wool 15
fill ~2 ~7 ~47 ~10 ~7 ~47 wool 15
fill ~2 ~7 ~48 ~10 ~7 ~48 wool 15
fill ~2 ~7 ~49 ~10 ~7 ~49 wool 15
fill ~2 ~7 ~50 ~10 ~7 ~50 wool 15
fill ~2 ~7 ~51 ~10 ~7 ~51 wool 15
fill ~2 ~7 ~52 ~10 ~7 ~52 wool 15
fill ~2 ~7 ~53 ~10 ~7 ~53 wool 15
fill ~3 ~7 ~34 ~3 ~7 ~37 stained_hardened_clay 14
fill ~3 ~7 ~39 ~10 ~7 ~39 wool 15
fill ~3 ~7 ~54 ~10 ~7 ~54 wool 15
fill ~3 ~7 ~56 ~3 ~9 ~56 stained_hardened_clay 14
fill ~3 ~7 ~57 ~3 ~8 ~57 stained_hardened_clay 14
fill ~3 ~7 ~58 ~3 ~7 ~59 stained_hardened_clay 14
fill ~4 ~7 ~30 ~6 ~7 ~30 stained_hardened_clay 14
fill ~4 ~7 ~31 ~5 ~7 ~31 stained_hardened_clay 14
fill ~4 ~7 ~32 ~5 ~7 ~32 stained_hardened_clay 14
fill ~4 ~7 ~33 ~5 ~7 ~33 stained_hardened_clay 14
fill ~4 ~7 ~34 ~10 ~7 ~34 wool 15
fill ~4 ~7 ~35 ~10 ~7 ~35 wool 15
fill ~4 ~7 ~36 ~10 ~7 ~36 wool 15
fill ~4 ~7 ~37 ~17 ~7 ~37 wool 15
fill ~4 ~7 ~38 ~10 ~7 ~38 wool 15
fill ~4 ~7 ~55 ~10 ~7 ~55 wool 15
fill ~4 ~7 ~56 ~17 ~7 ~56 wool 15
fill ~4 ~7 ~57 ~10 ~7 ~57 wool 15
fill ~4 ~7 ~58 ~10 ~7 ~58 wool 15
fill ~4 ~7 ~59 ~10 ~7 ~59 wool 15
fill ~4 ~7 ~60 ~5 ~7 ~60 stained_hardened_clay 14
fill ~4 ~7 ~61 ~5 ~7 ~61 stained_hardened_clay 14
fill ~4 ~7 ~62 ~5 ~7 ~62 stained_hardened_clay 14
fill ~4 ~7 ~63 ~6 ~7 ~63 stained_hardened_clay 14
fill ~5 ~7 ~26 ~7 ~7 ~26 stained_hardened_clay 14
fill ~5 ~7 ~27 ~7 ~7 ~27 stained_hardened_clay 14
fill ~5 ~7 ~28 ~6 ~7 ~28 stained_hardened_clay 14
fill ~5 ~7 ~29 ~6 ~7 ~29 stained_hardened_clay 14
fill ~5 ~7 ~64 ~6 ~7 ~64 stained_hardened_clay 14
fill ~5 ~7 ~65 ~6 ~7 ~65 stained_hardened_clay 14
fill ~5 ~7 ~66 ~7 ~7 ~66 stained_hardened_clay 14
fill ~5 ~7 ~67 ~7 ~7 ~67 stained_hardened_clay 14
fill ~6 ~7 ~23 ~8 ~7 ~23 stained_hardened_clay 14
fill ~6 ~7 ~24 ~8 ~7 ~24 stained_hardened_clay 14
fill ~6 ~7 ~25 ~7 ~7 ~25 stained_hardened_clay 14
fill ~6 ~7 ~31 ~6 ~7 ~33 stone 0
fill ~6 ~7 ~60 ~6 ~7 ~62 stone 0
fill ~6 ~7 ~68 ~7 ~7 ~68 stained_hardened_clay 14
fill ~6 ~7 ~69 ~8 ~7 ~69 stained_hardened_clay 14
fill ~6 ~7 ~70 ~8 ~7 ~70 stained_hardened_clay 14
fill ~7 ~7 ~20 ~9 ~7 ~20 stained_hardened_clay 14
fill ~7 ~7 ~21 ~9 ~7 ~21 stained_hardened_clay 14
fill ~7 ~7 ~22 ~9 ~7 ~22 stained_hardened_clay 14
fill ~7 ~7 ~28 ~7 ~7 ~30 stone 0
fill ~7 ~7 ~31 ~10 ~7 ~31 wool 15
fill ~7 ~7 ~32 ~10 ~7 ~32 wool 15
fill ~7 ~7 ~33 ~10 ~7 ~33 wool 15
fill ~7 ~7 ~60 ~10 ~7 ~60 wool 15
fill ~7 ~7 ~61 ~10 ~7 ~61 wool 15
fill ~7 ~7 ~62 ~10 ~7 ~62 wool 15
fill ~7 ~7 ~63 ~7 ~7 ~65 stone 0
fill ~7 ~7 ~71 ~9 ~7 ~71 stained_hardened_clay 14
fill ~7 ~7 ~72 ~9 ~7 ~72 stained_hardened_clay 14
fill ~7 ~7 ~73 ~9 ~7 ~73 stained_hardened_clay 14
fill ~8 ~7 ~18 ~9 ~7 ~18 stained_hardened_clay 14
fill ~8 ~7 ~19 ~9 ~7 ~19 stained_hardened_clay 14
fill ~8 ~7 ~25 ~8 ~7 ~27 stone 0
fill ~8 ~7 ~28 ~11 ~7 ~28 wool 15
fill ~8 ~7 ~29 ~11 ~7 ~29 wool 15
fill ~8 ~7 ~30 ~10 ~7 ~30 wool 15
fill ~8 ~7 ~63 ~10 ~7 ~63 wool 15
fill ~8 ~7 ~64 ~11 ~7 ~64 wool 15
fill ~8 ~7 ~65 ~11 ~7 ~65 wool 15
fill ~8 ~7 ~66 ~8 ~7 ~68 stone 0
fill ~8 ~7 ~74 ~9 ~7 ~74 stained_hardened_clay 14
fill ~8 ~7 ~75 ~9 ~7 ~75 stained_hardened_clay 14
fill ~9 ~7 ~16 ~9 ~7 ~22 stained_hardened_clay 14
fill ~9 ~7 ~23 ~9 ~7 ~24 stone 0
fill ~9 ~7 ~25 ~10 ~7 ~25 wool 15
fill ~9 ~7 ~26 ~10 ~7 ~26 wool 15
fill ~9 ~7 ~27 ~10 ~7 ~27 wool 15
fill ~9 ~7 ~66 ~10 ~7 ~66 wool 15
fill ~9 ~7 ~67 ~10 ~7 ~67 wool 15
fill ~9 ~7 ~68 ~10 ~7 ~68 wool 15
fill ~9 ~7 ~69 ~9 ~7 ~70 stone 0
fill ~9 ~7 ~76 ~9 ~7 ~77 stained_hardened_clay 14
fill ~10 ~7 ~21 ~10 ~7 ~22 stone 0
fill ~10 ~7 ~23 ~10 ~7 ~70 wool 15
fill ~10 ~7 ~71 ~10 ~7 ~72 stone 0
fill ~11 ~7 ~19 ~11 ~10 ~19 stone_brick_stairs 6
fill ~11 ~7 ~20 ~11 ~11 ~20 stone_brick_stairs 6
fill ~11 ~7 ~73 ~11 ~11 ~73 stone_brick_stairs 7
fill ~11 ~7 ~74 ~11 ~10 ~74 stone_brick_stairs 7
fill ~12 ~7 ~17 ~12 ~10 ~17 stone_brick_stairs 6
fill ~12 ~7 ~18 ~12 ~11 ~18 stone_brick_stairs 6
setblock ~12 ~7 ~27 wool 15
setblock ~12 ~7 ~66 wool 15
fill ~12 ~7 ~75 ~12 ~11 ~75 stone_brick_stairs 7
fill ~12 ~7 ~76 ~12 ~10 ~76 stone_brick_stairs 7
fill ~13 ~7 ~15 ~13 ~9 ~15 stone_brick_stairs 6
fill ~13 ~7 ~16 ~13 ~10 ~16 stone_brick_stairs 6
setblock ~13 ~7 ~26 wool 15
setblock ~13 ~7 ~67 wool 15
fill ~13 ~7 ~77 ~13 ~10 ~77 stone_brick_stairs 7
fill ~13 ~7 ~78 ~13 ~9 ~78 stone_brick_stairs 7
fill ~14 ~7 ~14 ~14 ~9 ~14 stone_brick_stairs 6
setblock ~14 ~7 ~25 wool 15
setblock ~14 ~7 ~68 wool 15
fill ~14 ~7 ~79 ~14 ~9 ~79 stone_brick_stairs 7
fill ~15 ~7 ~12 ~15 ~18 ~12 stained_hardened_clay 14
fill ~15 ~7 ~13 ~15 ~9 ~13 stone_brick_stairs 6
setblock ~15 ~7 ~24 wool 15
setblock ~15 ~7 ~69 wool 15
fill ~15 ~7 ~80 ~15 ~9 ~80 stone_brick_stairs 7
fill ~15 ~7 ~81 ~15 ~18 ~81 stained_hardened_clay 14
fill ~16 ~7 ~11 ~16 ~18 ~11 stained_hardened_clay 14
fill ~16 ~7 ~12 ~16 ~9 ~12 wool 15
fill ~16 ~7 ~13 ~16 ~12 ~13 wool 15
fill ~16 ~7 ~14 ~16 ~14 ~14 wool 15
fill ~16 ~7 ~15 ~16 ~16 ~15 wool 15
fill ~16 ~7 ~16 ~16 ~16 ~16 wool 15
fill ~16 ~7 ~17 ~16 ~17 ~17 wool 15
fill ~16 ~7 ~18 ~16 ~16 ~18 wool 15
fill ~16 ~7 ~19 ~16 ~16 ~19 wool 15
fill ~16 ~7 ~20 ~16 ~15 ~20 wool 15
fill ~16 ~7 ~21 ~16 ~15 ~21 wool 15
fill ~16 ~7 ~22 ~16 ~14 ~22 wool 15
fill ~16 ~7 ~23 ~16 ~13 ~23 wool 15
fill ~16 ~7 ~70 ~16 ~13 ~70 wool 15
fill ~16 ~7 ~71 ~16 ~14 ~71 wool 15
fill ~16 ~7 ~72 ~16 ~15 ~72 wool 15
fill ~16 ~7 ~73 ~16 ~15 ~73 wool 15
fill ~16 ~7 ~74 ~16 ~16 ~74 wool 15
fill ~16 ~7 ~75 ~16 ~16 ~75 wool 15
fill ~16 ~7 ~76 ~16 ~17 ~76 wool 15
fill ~16 ~7 ~77 ~16 ~16 ~77 wool 15
fill ~16 ~7 ~78 ~16 ~16 ~78 wool 15
fill ~16 ~7 ~79 ~16 ~14 ~79 wool 15
fill ~16 ~7 ~80 ~16 ~12 ~80 wool 15
fill ~16 ~7 ~81 ~16 ~9 ~81 wool 15
fill ~16 ~7 ~82 ~16 ~18 ~82 stained_hardened_clay 14
fill ~17 ~7 ~10 ~21 ~7 ~10 stained_hardened_clay 14
fill ~17 ~7 ~83 ~21 ~7 ~83 stained_hardened_clay 14
fill ~18 ~7 ~38 ~19 ~7 ~38 wool 15
fill ~18 ~7 ~39 ~19 ~7 ~39 wool 15
fill ~18 ~7 ~40 ~19 ~7 ~40 wool 15
fill ~18 ~7 ~41 ~19 ~7 ~41 wool 15
fill ~18 ~7 ~42 ~19 ~7 ~42 wool 15
fill ~18 ~7 ~43 ~19 ~7 ~43 wool 15
fill ~18 ~7 ~44 ~19 ~7 ~44 wool 15
fill ~18 ~7 ~45 ~19 ~7 ~45 wool 15
fill ~18 ~7 ~46 ~19 ~7 ~46 wool 15
fill ~18 ~7 ~47 ~19 ~7 ~47 wool 15
fill ~18 ~7 ~48 ~19 ~7 ~48 wool 15
fill ~18 ~7 ~49 ~19 ~7 ~49 wool 15
fill ~18 ~7 ~50 ~19 ~7 ~50 wool 15
fill ~18 ~7 ~51 ~19 ~7 ~51 wool 15
fill ~18 ~7 ~52 ~19 ~7 ~52 wool 15
fill ~18 ~7 ~53 ~19 ~7 ~53 wool 15
fill ~18 ~7 ~54 ~19 ~7 ~54 wool 15
fill ~18 ~7 ~55 ~19 ~7 ~55 wool 15
fill ~21 ~7 ~11 ~21 ~8 ~11 wool 15
fill ~21 ~7 ~82 ~21 ~8 ~82 wool 15
fill ~22 ~7 ~12 ~22 ~8 ~12 wool 15
fill ~22 ~7 ~81 ~22 ~8 ~81 wool 15
fill ~23 ~7 ~11 ~24 ~7 ~11 stained_hardened_clay 14
fill ~23 ~7 ~82 ~24 ~7 ~82 stained_hardened_clay 14
fill ~25 ~7 ~10 ~26 ~7 ~10 stained_hardened_clay 14
fill ~25 ~7 ~83 ~26 ~7 ~83 stained_hardened_clay 14
fill ~27 ~7 ~9 ~28 ~7 ~9 stained_hardened_clay 14
fill ~27 ~7 ~84 ~28 ~7 ~84 stained_hardened_clay 14
fill ~29 ~7 ~8 ~31 ~7 ~8 stained_hardened_clay 14
fill ~29 ~7 ~85 ~31 ~7 ~85 stained_hardened_clay 14
fill ~32 ~7 ~7 ~33 ~7 ~7 stained_hardened_clay 14
fill ~32 ~7 ~86 ~33 ~7 ~86 stained_hardened_clay 14
fill ~36 ~7 ~25 ~37 ~7 ~25 wool 15
fill ~36 ~7 ~68 ~37 ~7 ~68 wool 15
fill ~38 ~7 ~26 ~62 ~7 ~26 wool 15
fill ~38 ~7 ~67 ~62 ~7 ~67 wool 15
fill ~39 ~7 ~7 ~39 ~8 ~7 stained_hardened_clay 9
fill ~39 ~7 ~8 ~39 ~8 ~8 stained_hardened_clay 9
fill ~39 ~7 ~9 ~39 ~8 ~9 wool 7
fill ~39 ~7 ~10 ~39 ~8 ~10 wool 7
fill ~39 ~7 ~11 ~39 ~8 ~11 wool 7
fill ~39 ~7 ~12 ~39 ~8 ~12 wool 7
fill ~39 ~7 ~13 ~39 ~8 ~13 wool 7
fill ~39 ~7 ~14 ~39 ~8 ~14 wool 7
fill ~39 ~7 ~79 ~39 ~8 ~79 wool 7
fill ~39 ~7 ~80 ~39 ~8 ~80 wool 7
fill ~39 ~7 ~81 ~39 ~8 ~81 wool 7
fill ~39 ~7 ~82 ~39 ~8 ~82 wool 7
fill ~39 ~7 ~83 ~39 ~8 ~83 wool 7
fill ~39 ~7 ~84 ~39 ~8 ~84 wool 7
fill ~39 ~7 ~85 ~39 ~8 ~85 stained_hardened_clay 9
fill ~39 ~7 ~86 ~39 ~8 ~86 stained_hardened_clay 9
fill ~40 ~7 ~9 ~40 ~8 ~9 stained_hardened_clay 9
fill ~40 ~7 ~84 ~40 ~8 ~84 stained_hardened_clay 9
setblock ~43 ~7 ~7 stained_hardened_clay 9
setblock ~43 ~7 ~86 stained_hardened_clay 9
fill ~44 ~7 ~12 ~54 ~7 ~12 wool 7
fill ~44 ~7 ~81 ~54 ~7 ~81 wool 7
setblock ~47 ~7 ~8 stained_hardened_clay 9
setblock ~47 ~7 ~85 stained_hardened_clay 9
setblock ~53 ~7 ~8 stained_hardened_clay 9
setblock ~53 ~7 ~85 stained_hardened_clay 9
setblock ~55 ~7 ~12 stained_hardened_clay 14
fill ~55 ~7 ~52 ~55 ~7 ~60 stained_hardened_clay 9
setblock ~55 ~7 ~81 stained_hardened_clay 14
fill ~56 ~7 ~32 ~57 ~7 ~32 stained_hardened_clay 9
fill ~56 ~7 ~61 ~57 ~7 ~61 stained_hardened_clay 9
setblock ~57 ~7 ~7 stained_hardened_clay 9
fill ~57 ~7 ~42 ~57 ~7 ~45 stained_hardened_clay 9
fill ~57 ~7 ~50 ~78 ~7 ~50 stained_hardened_clay 9
fill ~57 ~7 ~51 ~57 ~7 ~48 stained_hardened_clay 9
setblock ~57 ~7 ~86 stained_hardened_clay 9
fill ~58 ~7 ~31 ~59 ~7 ~31 stained_hardened_clay 9
fill ~58 ~7 ~43 ~78 ~7 ~43 stained_hardened_clay 9
fill ~58 ~7 ~62 ~59 ~7 ~62 stained_hardened_clay 9
fill ~60 ~7 ~9 ~60 ~8 ~9 stained_hardened_clay 9
fill ~60 ~7 ~84 ~60 ~8 ~84 stained_hardened_clay 9
fill ~61 ~7 ~7 ~61 ~8 ~7 stained_hardened_clay 9
fill ~61 ~7 ~8 ~61 ~8 ~8 stained_hardened_clay 9
fill ~61 ~7 ~9 ~61 ~8 ~9 wool 7
fill ~61 ~7 ~10 ~61 ~8 ~10 wool 7
fill ~61 ~7 ~11 ~61 ~8 ~11 wool 7
fill ~61 ~7 ~12 ~61 ~8 ~12 wool 7
fill ~61 ~7 ~13 ~61 ~8 ~13 wool 7
fill ~61 ~7 ~14 ~61 ~8 ~14 wool 7
fill ~61 ~7 ~79 ~61 ~8 ~79 wool 7
fill ~61 ~7 ~80 ~61 ~8 ~80 wool 7
fill ~61 ~7 ~81 ~61 ~8 ~81 wool 7
fill ~61 ~7 ~82 ~61 ~8 ~82 wool 7
fill ~61 ~7 ~83 ~61 ~8 ~83 wool 7
fill ~61 ~7 ~84 ~61 ~8 ~84 wool 7
fill ~61 ~7 ~85 ~61 ~8 ~85 stained_hardened_clay 9
fill ~61 ~7 ~86 ~61 ~8 ~86 stained_hardened_clay 9
fill ~63 ~7 ~25 ~64 ~7 ~25 wool 15
fill ~63 ~7 ~68 ~64 ~7 ~68 wool 15
fill ~67 ~7 ~7 ~75 ~7 ~7 stained_hardened_clay 14
fill ~67 ~7 ~86 ~75 ~7 ~86 stained_hardened_clay 14
fill ~68 ~7 ~19 ~73 ~7 ~19 wool 15
fill ~68 ~7 ~20 ~73 ~7 ~20 wool 15
fill ~68 ~7 ~21 ~68 ~14 ~21 stained_hardened_clay 9
fill ~68 ~7 ~72 ~68 ~16 ~72 stained_hardened_clay 9
fill ~68 ~7 ~73 ~73 ~7 ~73 wool 15
fill ~68 ~7 ~74 ~73 ~7 ~74 wool 15
fill ~73 ~7 ~8 ~91 ~7 ~8 stained_hardened_clay 14
fill ~73 ~7 ~85 ~91 ~7 ~85 stained_hardened_clay 14
fill ~74 ~7 ~19 ~93 ~7 ~19 iron_block 0
fill ~74 ~7 ~20 ~93 ~7 ~20 iron_block 0
fill ~74 ~7 ~73 ~93 ~7 ~73 iron_block 0
fill ~74 ~7 ~74 ~93 ~7 ~74 iron_block 0
fill ~78 ~7 ~9 ~115 ~7 ~9 stained_hardened_clay 14
fill ~78 ~7 ~84 ~115 ~7 ~84 stained_hardened_clay 14
fill ~79 ~7 ~42 ~117 ~7 ~42 stained_hardened_clay 9
fill ~79 ~7 ~51 ~117 ~7 ~51 stained_hardened_clay 9
fill ~84 ~7 ~10 ~113 ~7 ~10 stained_hardened_clay 14
fill ~84 ~7 ~83 ~113 ~7 ~83 stained_hardened_clay 14
fill ~86 ~7 ~26 ~109 ~7 ~26 wool 15
fill ~86 ~7 ~27 ~87 ~7 ~27 wool 15
fill ~86 ~7 ~35 ~87 ~7 ~35 wool 15
fill ~86 ~7 ~36 ~109 ~7 ~36 wool 15
fill ~86 ~7 ~57 ~109 ~7 ~57 wool 15
fill ~86 ~7 ~58 ~87 ~7 ~58 wool 15
fill ~86 ~7 ~66 ~87 ~7 ~66 wool 15
fill ~86 ~7 ~67 ~109 ~7 ~67 wool 15
fill ~87 ~7 ~34 ~88 ~7 ~34 wool 15
fill ~87 ~7 ~59 ~88 ~7 ~59 wool 15
fill ~94 ~7 ~11 ~115 ~7 ~11 stained_hardened_clay 14
fill ~94 ~7 ~19 ~116 ~7 ~19 wool 15
fill ~94 ~7 ~20 ~116 ~7 ~20 wool 15
fill ~94 ~7 ~73 ~116 ~7 ~73 wool 15
fill ~94 ~7 ~74 ~116 ~7 ~74 wool 15
fill ~94 ~7 ~82 ~115 ~7 ~82 stained_hardened_clay 14
fill ~100 ~7 ~25 ~109 ~7 ~25 wool 15
fill ~100 ~7 ~37 ~109 ~7 ~37 wool 15
fill ~100 ~7 ~56 ~109 ~7 ~56 wool 15
fill ~100 ~7 ~68 ~109 ~7 ~68 wool 15
fill ~105 ~7 ~24 ~109 ~7 ~24 wool 15
fill ~105 ~7 ~38 ~109 ~7 ~38 wool 15
fill ~105 ~7 ~55 ~109 ~7 ~55 wool 15
fill ~105 ~7 ~69 ~109 ~7 ~69 wool 15
fill ~109 ~7 ~27 ~109 ~7 ~34 wool 15
fill ~109 ~7 ~59 ~109 ~7 ~69 wool 15
fill ~114 ~7 ~12 ~114 ~7 ~20 wool 15
fill ~114 ~7 ~75 ~114 ~7 ~81 wool 15
fill ~115 ~7 ~10 ~142 ~7 ~10 stained_hardened_clay 14
fill ~115 ~7 ~83 ~142 ~7 ~83 stained_hardened_clay 14
fill ~126 ~7 ~46 ~126 ~11 ~46 wool 15
fill ~126 ~7 ~47 ~126 ~11 ~47 wool 15
fill ~138 ~7 ~11 ~141 ~7 ~11 stained_hardened_clay 14
fill ~138 ~7 ~82 ~141 ~7 ~82 stained_hardened_clay 14
fill ~143 ~7 ~7 ~147 ~7 ~7 stained_hardened_clay 14
fill ~143 ~7 ~8 ~143 ~7 ~9 wool 15
fill ~143 ~7 ~84 ~143 ~7 ~85 wool 15
fill ~143 ~7 ~86 ~147 ~7 ~86 stained_hardened_clay 14
fill ~150 ~7 ~8 ~150 ~9 ~8 wool 15
fill ~150 ~7 ~9 ~150 ~9 ~9 wool 15
fill ~150 ~7 ~10 ~150 ~9 ~10 wool 15
fill ~150 ~7 ~11 ~150 ~9 ~11 wool 15
fill ~150 ~7 ~12 ~150 ~9 ~12 wool 15
fill ~150 ~7 ~13 ~150 ~9 ~13 wool 15
fill ~150 ~7 ~14 ~150 ~9 ~14 wool 15
fill ~150 ~7 ~15 ~150 ~9 ~15 wool 15
fill ~150 ~7 ~16 ~150 ~9 ~16 wool 15
fill ~150 ~7 ~17 ~150 ~9 ~17 wool 15
fill ~150 ~7 ~23 ~178 ~7 ~23 wool 15
fill ~150 ~7 ~70 ~178 ~7 ~70 wool 15
fill ~150 ~7 ~76 ~150 ~9 ~76 wool 15
fill ~150 ~7 ~77 ~150 ~9 ~77 wool 15
fill ~150 ~7 ~78 ~150 ~9 ~78 wool 15
fill ~150 ~7 ~79 ~150 ~9 ~79 wool 15
fill ~150 ~7 ~80 ~150 ~9 ~80 wool 15
fill ~150 ~7 ~81 ~150 ~9 ~81 wool 15
fill ~150 ~7 ~82 ~150 ~9 ~82 wool 15
fill ~150 ~7 ~83 ~150 ~9 ~83 wool 15
fill ~150 ~7 ~84 ~150 ~9 ~84 wool 15
fill ~150 ~7 ~85 ~150 ~9 ~85 wool 15
fill ~151 ~7 ~7 ~153 ~7 ~7 wool 15
fill ~151 ~7 ~18 ~153 ~7 ~18 wool 15
fill ~151 ~7 ~75 ~153 ~7 ~75 wool 15
fill ~151 ~7 ~86 ~153 ~7 ~86 wool 15
fill ~154 ~7 ~86 ~154 ~6 ~86 stained_hardened_clay 9
setblock ~156 ~7 ~7 stained_hardened_clay 9
setblock ~156 ~7 ~86 stained_hardened_clay 9
fill ~159 ~7 ~12 ~169 ~7 ~12 wool 7
fill ~159 ~7 ~81 ~169 ~7 ~81 wool 7
setblock ~161 ~7 ~7 stained_hardened_clay 9
setblock ~161 ~7 ~86 stained_hardened_clay 9
setblock ~167 ~7 ~7 stained_hardened_clay 9
setblock ~167 ~7 ~86 stained_hardened_clay 9
setblock ~170 ~7 ~12 stained_hardened_clay 14
setblock ~170 ~7 ~81 stained_hardened_clay 14
setblock ~172 ~7 ~7 stained_hardened_clay 9
setblock ~172 ~7 ~86 stained_hardened_clay 9
setblock ~174 ~7 ~86 stained_hardened_clay 9
fill ~175 ~7 ~7 ~177 ~7 ~7 wool 15
fill ~175 ~7 ~18 ~177 ~7 ~18 wool 15
fill ~175 ~7 ~75 ~177 ~7 ~75 wool 15
fill ~175 ~7 ~86 ~177 ~7 ~86 wool 15
fill ~178 ~7 ~8 ~178 ~9 ~8 wool 15
fill ~178 ~7 ~9 ~178 ~9 ~9 wool 15
fill ~178 ~7 ~10 ~178 ~9 ~10 wool 15
fill ~178 ~7 ~11 ~178 ~9 ~11 wool 15
fill ~178 ~7 ~12 ~178 ~9 ~12 wool 15
fill ~178 ~7 ~13 ~178 ~9 ~13 wool 15
fill ~178 ~7 ~14 ~178 ~9 ~14 wool 15
fill ~178 ~7 ~15 ~178 ~9 ~15 wool 15
fill ~178 ~7 ~16 ~178 ~9 ~16 wool 15
fill ~178 ~7 ~17 ~178 ~9 ~17 wool 15
fill ~178 ~7 ~76 ~178 ~9 ~76 wool 15
fill ~178 ~7 ~77 ~178 ~9 ~77 wool 15
fill ~178 ~7 ~78 ~178 ~9 ~78 wool 15
fill ~178 ~7 ~79 ~178 ~9 ~79 wool 15
fill ~178 ~7 ~80 ~178 ~9 ~80 wool 15
fill ~178 ~7 ~81 ~178 ~9 ~81 wool 15
fill ~178 ~7 ~82 ~178 ~9 ~82 wool 15
fill ~178 ~7 ~83 ~178 ~9 ~83 wool 15
fill ~178 ~7 ~84 ~178 ~9 ~84 wool 15
fill ~178 ~7 ~85 ~178 ~9 ~85 wool 15
fill ~179 ~7 ~22 ~179 ~17 ~22 wool 15
fill ~179 ~7 ~71 ~179 ~17 ~71 wool 15
fill ~180 ~7 ~21 ~180 ~17 ~21 wool 15
fill ~180 ~7 ~25 ~182 ~7 ~25 wool 15
fill ~180 ~7 ~26 ~190 ~7 ~26 wool 15
fill ~180 ~7 ~27 ~181 ~7 ~27 wool 15
fill ~180 ~7 ~28 ~181 ~7 ~28 wool 15
fill ~180 ~7 ~29 ~181 ~7 ~29 wool 15
fill ~180 ~7 ~30 ~181 ~7 ~30 wool 15
fill ~180 ~7 ~31 ~191 ~7 ~31 wool 15
fill ~180 ~7 ~32 ~182 ~7 ~32 wool 15
fill ~180 ~7 ~33 ~182 ~7 ~33 wool 15
fill ~180 ~7 ~34 ~182 ~7 ~34 wool 15
fill ~180 ~7 ~35 ~182 ~7 ~35 wool 15
fill ~180 ~7 ~36 ~191 ~7 ~36 wool 15
fill ~180 ~7 ~37 ~182 ~7 ~37 wool 15
fill ~180 ~7 ~38 ~182 ~7 ~38 wool 15
fill ~180 ~7 ~55 ~182 ~7 ~55 wool 15
fill ~180 ~7 ~56 ~182 ~7 ~56 wool 15
fill ~180 ~7 ~57 ~191 ~7 ~57 wool 15
fill ~180 ~7 ~58 ~182 ~7 ~58 wool 15
fill ~180 ~7 ~59 ~182 ~7 ~59 wool 15
fill ~180 ~7 ~60 ~182 ~7 ~60 wool 15
fill ~180 ~7 ~61 ~182 ~7 ~61 wool 15
fill ~180 ~7 ~62 ~191 ~7 ~62 wool 15
fill ~180 ~7 ~63 ~181 ~7 ~63 wool 15
fill ~180 ~7 ~64 ~181 ~7 ~64 wool 15
fill ~180 ~7 ~65 ~181 ~7 ~65 wool 15
fill ~180 ~7 ~66 ~181 ~7 ~66 wool 15
fill ~180 ~7 ~67 ~190 ~7 ~67 wool 15
fill ~180 ~7 ~68 ~182 ~7 ~68 wool 15
fill ~180 ~7 ~72 ~180 ~17 ~72 wool 15
fill ~181 ~7 ~7 ~183 ~7 ~7 stained_hardened_clay 14
fill ~181 ~7 ~8 ~181 ~17 ~8 wool 15
fill ~181 ~7 ~9 ~181 ~17 ~9 wool 15
fill ~181 ~7 ~10 ~181 ~17 ~10 wool 15
fill ~181 ~7 ~11 ~181 ~17 ~11 wool 15
fill ~181 ~7 ~12 ~181 ~17 ~12 wool 15
fill ~181 ~7 ~13 ~181 ~17 ~13 wool 15
fill ~181 ~7 ~14 ~181 ~17 ~14 wool 15
fill ~181 ~7 ~15 ~181 ~17 ~15 wool 15
fill ~181 ~7 ~16 ~181 ~17 ~16 wool 15
fill ~181 ~7 ~17 ~181 ~17 ~17 wool 15
fill ~181 ~7 ~18 ~181 ~17 ~18 wool 15
fill ~181 ~7 ~19 ~181 ~17 ~19 wool 15
fill ~181 ~7 ~20 ~181 ~17 ~20 wool 15
fill ~181 ~7 ~73 ~181 ~17 ~73 wool 15
fill ~181 ~7 ~74 ~181 ~17 ~74 wool 15
fill ~181 ~7 ~75 ~181 ~17 ~75 wool 15
fill ~181 ~7 ~76 ~181 ~17 ~76 wool 15
fill ~181 ~7 ~77 ~181 ~17 ~77 wool 15
fill ~181 ~7 ~78 ~181 ~17 ~78 wool 15
fill ~181 ~7 ~79 ~181 ~17 ~79 wool 15
fill ~181 ~7 ~80 ~181 ~17 ~80 wool 15
fill ~181 ~7 ~81 ~181 ~17 ~81 wool 15
fill ~181 ~7 ~82 ~181 ~17 ~82 wool 15
fill ~181 ~7 ~83 ~181 ~17 ~83 wool 15
fill ~181 ~7 ~84 ~181 ~17 ~84 wool 15
fill ~181 ~7 ~85 ~181 ~17 ~85 wool 15
fill ~181 ~7 ~86 ~183 ~7 ~86 stained_hardened_clay 14
setblock ~182 ~7 ~39 wool 15
setblock ~182 ~7 ~54 wool 15
fill ~183 ~7 ~23 ~184 ~7 ~23 wool 15
fill ~183 ~7 ~24 ~184 ~7 ~24 wool 15
fill ~183 ~7 ~40 ~185 ~7 ~40 wool 15
fill ~183 ~7 ~53 ~185 ~7 ~53 wool 15
fill ~183 ~7 ~69 ~184 ~7 ~69 wool 15
fill ~183 ~7 ~70 ~184 ~7 ~70 wool 15
fill ~184 ~7 ~8 ~185 ~7 ~8 stained_hardened_clay 14
fill ~184 ~7 ~22 ~185 ~7 ~22 wool 15
fill ~184 ~7 ~71 ~185 ~7 ~71 wool 15
fill ~184 ~7 ~85 ~185 ~7 ~85 stained_hardened_clay 14
fill ~185 ~7 ~20 ~187 ~7 ~20 wool 15
fill ~185 ~7 ~21 ~186 ~7 ~21 wool 15
fill ~185 ~7 ~72 ~186 ~7 ~72 wool 15
fill ~185 ~7 ~73 ~187 ~7 ~73 wool 15
fill ~186 ~7 ~19 ~190 ~7 ~19 wool 15
fill ~186 ~7 ~41 ~187 ~7 ~41 wool 15
fill ~186 ~7 ~52 ~187 ~7 ~52 wool 15
fill ~186 ~7 ~74 ~190 ~7 ~74 wool 15
fill ~187 ~7 ~9 ~187 ~17 ~9 stained_hardened_clay 14
fill ~187 ~7 ~10 ~187 ~7 ~20 wool 15
fill ~187 ~7 ~75 ~191 ~7 ~75 wool 15
fill ~187 ~7 ~76 ~190 ~7 ~76 wool 15
fill ~187 ~7 ~77 ~190 ~7 ~77 wool 15
fill ~187 ~7 ~78 ~190 ~7 ~78 wool 15
fill ~187 ~7 ~79 ~190 ~7 ~79 wool 15
fill ~187 ~7 ~80 ~190 ~7 ~80 wool 15
fill ~187 ~7 ~81 ~189 ~7 ~81 wool 15
fill ~187 ~7 ~82 ~188 ~7 ~82 wool 15
fill ~187 ~7 ~83 ~187 ~7 ~73 wool 15
fill ~187 ~7 ~84 ~187 ~17 ~84 stained_hardened_clay 14
fill ~188 ~7 ~10 ~188 ~17 ~10 stained_hardened_clay 14
fill ~188 ~7 ~11 ~188 ~7 ~19 wool 15
fill ~188 ~7 ~42 ~189 ~7 ~42 wool 15
fill ~188 ~7 ~51 ~189 ~7 ~51 wool 15
fill ~188 ~7 ~83 ~188 ~17 ~83 stained_hardened_clay 14
fill ~189 ~7 ~11 ~189 ~17 ~11 stained_hardened_clay 14
fill ~189 ~7 ~12 ~189 ~7 ~19 wool 15
fill ~189 ~7 ~82 ~189 ~17 ~82 stained_hardened_clay 14
fill ~190 ~7 ~12 ~190 ~17 ~12 stained_hardened_clay 14
fill ~190 ~7 ~13 ~190 ~7 ~19 wool 15
fill ~190 ~7 ~43 ~191 ~7 ~43 wool 15
fill ~190 ~7 ~44 ~193 ~7 ~44 wool 15
fill ~190 ~7 ~45 ~193 ~7 ~45 wool 15
fill ~190 ~7 ~46 ~193 ~7 ~46 wool 15
fill ~190 ~7 ~47 ~193 ~7 ~47 wool 15
fill ~190 ~7 ~48 ~193 ~7 ~48 wool 15
fill ~190 ~7 ~49 ~193 ~7 ~49 wool 15
fill ~190 ~7 ~50 ~191 ~7 ~50 wool 15
fill ~190 ~7 ~81 ~190 ~17 ~81 stained_hardened_clay 14
fill ~191 ~7 ~18 ~191 ~18 ~18 wool 15
fill ~3 ~8 ~36 ~3 ~8 ~37 stained_hardened_clay 14
fill ~4 ~8 ~34 ~4 ~8 ~35 stained_hardened_clay 14
fill ~4 ~8 ~37 ~11 ~8 ~37 wool 15
fill ~4 ~8 ~56 ~11 ~8 ~56 wool 15
fill ~4 ~8 ~58 ~4 ~9 ~58 stained_hardened_clay 14
fill ~4 ~8 ~59 ~4 ~8 ~58 stained_hardened_clay 14
setblock ~5 ~8 ~34 stone 0
setblock ~5 ~8 ~59 stone 0
fill ~6 ~8 ~31 ~6 ~11 ~31 stone_brick_stairs 6
fill ~6 ~8 ~32 ~6 ~13 ~32 stone_brick_stairs 6
fill ~6 ~8 ~33 ~6 ~13 ~33 stone_brick_stairs 6
setblock ~6 ~8 ~34 wool 15
setblock ~6 ~8 ~59 wool 15
fill ~6 ~8 ~60 ~6 ~13 ~60 stone_brick_stairs 7
fill ~6 ~8 ~61 ~6 ~13 ~61 stone_brick_stairs 7
fill ~6 ~8 ~62 ~6 ~11 ~62 stone_brick_stairs 7
fill ~7 ~8 ~28 ~7 ~11 ~28 stone_brick_stairs 6
fill ~7 ~8 ~29 ~7 ~11 ~29 stone_brick_stairs 6
fill ~7 ~8 ~30 ~7 ~14 ~30 stone_brick_stairs 6
fill ~7 ~8 ~33 ~7 ~7 ~33 wool 15
fill ~7 ~8 ~60 ~7 ~7 ~60 wool 15
fill ~7 ~8 ~63 ~7 ~14 ~63 stone_brick_stairs 7
fill ~7 ~8 ~64 ~7 ~11 ~64 stone_brick_stairs 7
fill ~7 ~8 ~65 ~7 ~11 ~65 stone_brick_stairs 7
fill ~8 ~8 ~25 ~8 ~10 ~25 stone_brick_stairs 6
fill ~8 ~8 ~26 ~8 ~11 ~26 stone_brick_stairs 6
fill ~8 ~8 ~27 ~8 ~11 ~27 stone_brick_stairs 6
setblock ~8 ~8 ~32 wool 15
setblock ~8 ~8 ~61 wool 15
fill ~8 ~8 ~66 ~8 ~11 ~66 stone_brick_stairs 7
fill ~8 ~8 ~67 ~8 ~11 ~67 stone_brick_stairs 7
fill ~8 ~8 ~68 ~8 ~10 ~68 stone_brick_stairs 7
fill ~9 ~8 ~23 ~9 ~10 ~23 stone_brick_stairs 6
fill ~9 ~8 ~24 ~9 ~12 ~24 stone_brick_stairs 6
setblock ~9 ~8 ~31 wool 15
setblock ~9 ~8 ~62 wool 15
fill ~9 ~8 ~69 ~9 ~12 ~69 stone_brick_stairs 7
fill ~9 ~8 ~70 ~9 ~10 ~70 stone_brick_stairs 7
fill ~10 ~8 ~21 ~10 ~11 ~21 stone_brick_stairs 6
fill ~10 ~8 ~22 ~10 ~12 ~22 stone_brick_stairs 6
setblock ~10 ~8 ~30 wool 15
setblock ~10 ~8 ~63 wool 15
fill ~10 ~8 ~71 ~10 ~12 ~71 stone_brick_stairs 7
fill ~10 ~8 ~72 ~10 ~11 ~72 stone_brick_stairs 7
setblock ~11 ~8 ~29 wool 15
setblock ~11 ~8 ~64 wool 15
fill ~12 ~8 ~28 ~12 ~11 ~28 wool 15
fill ~12 ~8 ~38 ~17 ~8 ~38 wool 15
fill ~12 ~8 ~55 ~17 ~8 ~55 wool 15
fill ~12 ~8 ~65 ~12 ~11 ~65 wool 15
fill ~13 ~8 ~27 ~13 ~11 ~27 wool 15
fill ~13 ~8 ~66 ~13 ~11 ~66 wool 15
fill ~14 ~8 ~26 ~14 ~11 ~26 wool 15
fill ~14 ~8 ~67 ~14 ~11 ~67 wool 15
fill ~15 ~8 ~25 ~15 ~11 ~25 wool 15
fill ~15 ~8 ~68 ~15 ~11 ~68 wool 15
fill ~16 ~8 ~24 ~16 ~11 ~24 wool 15
fill ~16 ~8 ~39 ~17 ~8 ~39 wool 15
fill ~16 ~8 ~40 ~17 ~8 ~40 wool 15
fill ~16 ~8 ~41 ~17 ~8 ~41 wool 15
fill ~16 ~8 ~42 ~17 ~8 ~42 wool 15
fill ~16 ~8 ~43 ~17 ~8 ~43 wool 15
fill ~16 ~8 ~44 ~17 ~8 ~44 wool 15
fill ~16 ~8 ~45 ~17 ~8 ~45 wool 15
fill ~16 ~8 ~46 ~17 ~8 ~46 wool 15
fill ~16 ~8 ~47 ~17 ~8 ~47 wool 15
fill ~16 ~8 ~48 ~17 ~8 ~48 wool 15
fill ~16 ~8 ~49 ~17 ~8 ~49 wool 15
fill ~16 ~8 ~50 ~17 ~8 ~50 wool 15
fill ~16 ~8 ~51 ~17 ~8 ~51 wool 15
fill ~16 ~8 ~52 ~17 ~8 ~52 wool 15
fill ~16 ~8 ~53 ~17 ~8 ~53 wool 15
fill ~16 ~8 ~54 ~17 ~8 ~54 wool 15
fill ~16 ~8 ~69 ~16 ~11 ~69 wool 15
fill ~17 ~8 ~10 ~21 ~8 ~10 stained_hardened_clay 14
fill ~17 ~8 ~83 ~21 ~8 ~83 stained_hardened_clay 14
fill ~23 ~8 ~12 ~23 ~10 ~12 wool 15
fill ~23 ~8 ~81 ~23 ~10 ~81 wool 15
fill ~24 ~8 ~11 ~24 ~9 ~11 stained_hardened_clay 14
fill ~24 ~8 ~82 ~24 ~9 ~82 stained_hardened_clay 14
fill ~25 ~8 ~10 ~26 ~8 ~10 stained_hardened_clay 14
fill ~25 ~8 ~83 ~26 ~8 ~83 stained_hardened_clay 14
fill ~27 ~8 ~9 ~28 ~8 ~9 stained_hardened_clay 14
fill ~27 ~8 ~84 ~28 ~8 ~84 stained_hardened_clay 14
fill ~29 ~8 ~8 ~31 ~8 ~8 stained_hardened_clay 14
fill ~29 ~8 ~85 ~31 ~8 ~85 stained_hardened_clay 14
fill ~32 ~8 ~7 ~33 ~8 ~7 stained_hardened_clay 14
fill ~32 ~8 ~86 ~33 ~8 ~86 stained_hardened_clay 14
fill ~36 ~8 ~25 ~37 ~8 ~25 wool 15
fill ~36 ~8 ~68 ~37 ~8 ~68 wool 15
fill ~38 ~8 ~26 ~62 ~8 ~26 wool 15
fill ~38 ~8 ~67 ~62 ~8 ~67 wool 15
fill ~43 ~8 ~12 ~55 ~8 ~12 wool 7
fill ~43 ~8 ~81 ~55 ~8 ~81 wool 7
setblock ~44 ~8 ~7 stained_hardened_clay 9
setblock ~44 ~8 ~86 stained_hardened_clay 9
setblock ~45 ~8 ~8 stained_hardened_clay 9
setblock ~45 ~8 ~85 stained_hardened_clay 9
setblock ~48 ~8 ~8 stained_hardened_clay 9
setblock ~48 ~8 ~85 stained_hardened_clay 9
setblock ~52 ~8 ~8 stained_hardened_clay 9
setblock ~52 ~8 ~85 stained_hardened_clay 9
setblock ~55 ~8 ~8 stained_hardened_clay 9
fill ~55 ~8 ~11 ~55 ~12 ~11 stained_hardened_clay 14
fill ~55 ~8 ~13 ~55 ~12 ~13 stained_hardened_clay 14
fill ~55 ~8 ~80 ~55 ~12 ~80 stained_hardened_clay 14
fill ~55 ~8 ~82 ~55 ~12 ~82 stained_hardened_clay 14
setblock ~55 ~8 ~85 stained_hardened_clay 9
setblock ~56 ~8 ~7 stained_hardened_clay 9
setblock ~56 ~8 ~12 stained_hardened_clay 14
fill ~56 ~8 ~31 ~56 ~13 ~31 stained_hardened_clay 9
fill ~56 ~8 ~32 ~57 ~8 ~32 stained_hardened_clay 9
fill ~56 ~8 ~33 ~56 ~9 ~33 stained_hardened_clay 9
fill ~56 ~8 ~34 ~56 ~9 ~34 stained_hardened_clay 9
fill ~56 ~8 ~35 ~56 ~9 ~35 stained_hardened_clay 9
fill ~56 ~8 ~36 ~56 ~9 ~36 stained_hardened_clay 9
fill ~56 ~8 ~37 ~56 ~9 ~37 stained_hardened_clay 9
fill ~56 ~8 ~38 ~56 ~9 ~38 stained_hardened_clay 9
fill ~56 ~8 ~39 ~56 ~9 ~39 stained_hardened_clay 9
fill ~56 ~8 ~40 ~56 ~9 ~40 stained_hardened_clay 9
fill ~56 ~8 ~41 ~56 ~9 ~41 stained_hardened_clay 9
fill ~56 ~8 ~42 ~56 ~9 ~42 stained_hardened_clay 9
fill ~56 ~8 ~43 ~79 ~8 ~43 stained_hardened_clay 9
fill ~56 ~8 ~44 ~56 ~9 ~44 stained_hardened_clay 9
fill ~56 ~8 ~45 ~56 ~9 ~45 stained_hardened_clay 9
fill ~56 ~8 ~46 ~56 ~9 ~46 stained_hardened_clay 9
fill ~56 ~8 ~47 ~56 ~9 ~47 stained_hardened_clay 9
fill ~56 ~8 ~48 ~56 ~9 ~48 stained_hardened_clay 9
fill ~56 ~8 ~49 ~56 ~9 ~49 stained_hardened_clay 9
fill ~56 ~8 ~50 ~79 ~8 ~50 stained_hardened_clay 9
fill ~56 ~8 ~51 ~56 ~9 ~51 stained_hardened_clay 9
fill ~56 ~8 ~52 ~56 ~9 ~52 stained_hardened_clay 9
fill ~56 ~8 ~53 ~56 ~9 ~53 stained_hardened_clay 9
fill ~56 ~8 ~54 ~56 ~9 ~54 stained_hardened_clay 9
fill ~56 ~8 ~55 ~56 ~9 ~55 stained_hardened_clay 9
fill ~56 ~8 ~56 ~56 ~9 ~56 stained_hardened_clay 9
fill ~56 ~8 ~57 ~56 ~9 ~57 stained_hardened_clay 9
fill ~56 ~8 ~58 ~56 ~9 ~58 stained_hardened_clay 9
fill ~56 ~8 ~59 ~56 ~9 ~59 stained_hardened_clay 9
fill ~56 ~8 ~60 ~56 ~9 ~60 stained_hardened_clay 9
fill ~56 ~8 ~61 ~57 ~8 ~61 stained_hardened_clay 9
fill ~56 ~8 ~62 ~56 ~12 ~62 stained_hardened_clay 9
setblock ~56 ~8 ~81 stained_hardened_clay 14
setblock ~56 ~8 ~86 stained_hardened_clay 9
fill ~58 ~8 ~31 ~59 ~8 ~31 stained_hardened_clay 9
fill ~58 ~8 ~62 ~59 ~8 ~62 stained_hardened_clay 9
fill ~63 ~8 ~25 ~64 ~8 ~25 wool 15
fill ~63 ~8 ~68 ~64 ~8 ~68 wool 15
fill ~67 ~8 ~7 ~69 ~8 ~7 stained_hardened_clay 14
fill ~67 ~8 ~86 ~69 ~8 ~86 stained_hardened_clay 14
setblock ~68 ~8 ~18 wool 15
fill ~68 ~8 ~19 ~68 ~16 ~19 stained_hardened_clay 9
fill ~68 ~8 ~20 ~68 ~14 ~20 stained_hardened_clay 9
fill ~68 ~8 ~73 ~68 ~16 ~73 stained_hardened_clay 9
fill ~68 ~8 ~74 ~68 ~16 ~74 stained_hardened_clay 9
setblock ~68 ~8 ~75 wool 15
fill ~69 ~8 ~18 ~75 ~8 ~18 stained_hardened_clay 9
fill ~69 ~8 ~75 ~75 ~8 ~75 stained_hardened_clay 9
fill ~70 ~8 ~8 ~72 ~8 ~8 stained_hardened_clay 14
fill ~70 ~8 ~85 ~72 ~8 ~85 stained_hardened_clay 14
fill ~72 ~8 ~9 ~77 ~8 ~9 stained_hardened_clay 14
fill ~72 ~8 ~84 ~77 ~8 ~84 stained_hardened_clay 14
fill ~76 ~8 ~18 ~116 ~8 ~18 wool 7
fill ~76 ~8 ~75 ~116 ~8 ~75 wool 7
fill ~77 ~8 ~10 ~86 ~8 ~10 stained_hardened_clay 14
fill ~77 ~8 ~83 ~86 ~8 ~83 stained_hardened_clay 14
fill ~80 ~8 ~42 ~117 ~8 ~42 stained_hardened_clay 9
fill ~80 ~8 ~51 ~117 ~8 ~51 stained_hardened_clay 9
fill ~85 ~8 ~25 ~108 ~8 ~25 wool 7
fill ~85 ~8 ~26 ~85 ~10 ~26 wool 7
fill ~85 ~8 ~27 ~85 ~8 ~25 wool 7
fill ~85 ~8 ~35 ~85 ~8 ~37 wool 7
fill ~85 ~8 ~56 ~108 ~8 ~56 wool 7
fill ~85 ~8 ~57 ~85 ~8 ~58 wool 7
fill ~85 ~8 ~66 ~85 ~8 ~68 wool 7
fill ~86 ~8 ~11 ~93 ~8 ~11 stained_hardened_clay 14
fill ~86 ~8 ~28 ~87 ~8 ~28 wool 7
setblock ~86 ~8 ~34 wool 7
fill ~86 ~8 ~37 ~108 ~8 ~37 wool 7
setblock ~86 ~8 ~59 wool 7
fill ~86 ~8 ~65 ~87 ~8 ~65 wool 7
fill ~86 ~8 ~68 ~108 ~8 ~68 wool 7
fill ~86 ~8 ~82 ~93 ~8 ~82 stained_hardened_clay 14
fill ~87 ~8 ~29 ~87 ~8 ~33 wool 7
fill ~87 ~8 ~60 ~87 ~8 ~65 wool 7
fill ~93 ~8 ~12 ~116 ~8 ~12 stained_hardened_clay 14
fill ~93 ~8 ~81 ~116 ~8 ~81 stained_hardened_clay 14
fill ~95 ~8 ~26 ~97 ~8 ~26 wool 7
fill ~95 ~8 ~67 ~97 ~8 ~67 wool 7
fill ~96 ~8 ~36 ~100 ~8 ~36 wool 7
fill ~96 ~8 ~57 ~100 ~8 ~57 wool 7
fill ~102 ~8 ~24 ~110 ~8 ~24 wool 15
fill ~102 ~8 ~26 ~108 ~8 ~26 stained_hardened_clay 9
fill ~102 ~8 ~36 ~108 ~8 ~36 stained_hardened_clay 9
fill ~102 ~8 ~38 ~110 ~8 ~38 wool 15
fill ~102 ~8 ~55 ~110 ~8 ~55 wool 15
fill ~102 ~8 ~57 ~108 ~8 ~57 stained_hardened_clay 9
fill ~102 ~8 ~67 ~108 ~8 ~67 stained_hardened_clay 9
fill ~102 ~8 ~69 ~110 ~8 ~69 wool 15
fill ~104 ~8 ~31 ~109 ~8 ~31 wool 7
fill ~104 ~8 ~62 ~109 ~8 ~62 wool 7
fill ~105 ~8 ~27 ~108 ~8 ~27 stained_hardened_clay 9
fill ~105 ~8 ~28 ~109 ~8 ~28 wool 7
fill ~105 ~8 ~29 ~109 ~8 ~29 wool 7
fill ~105 ~8 ~30 ~109 ~8 ~30 wool 7
fill ~105 ~8 ~32 ~109 ~8 ~32 wool 7
fill ~105 ~8 ~33 ~109 ~8 ~33 wool 7
fill ~105 ~8 ~34 ~109 ~8 ~34 wool 7
fill ~105 ~8 ~35 ~108 ~8 ~35 stained_hardened_clay 9
fill ~105 ~8 ~58 ~108 ~8 ~58 stained_hardened_clay 9
fill ~105 ~8 ~59 ~109 ~8 ~59 wool 7
fill ~105 ~8 ~60 ~109 ~8 ~60 wool 7
fill ~105 ~8 ~61 ~109 ~8 ~61 wool 7
fill ~105 ~8 ~63 ~109 ~8 ~63 wool 7
fill ~105 ~8 ~64 ~109 ~8 ~64 wool 7
fill ~105 ~8 ~65 ~109 ~8 ~65 wool 7
fill ~105 ~8 ~66 ~108 ~8 ~66 stained_hardened_clay 9
fill ~106 ~8 ~23 ~107 ~8 ~23 wool 15
fill ~106 ~8 ~39 ~107 ~8 ~39 wool 15
fill ~106 ~8 ~54 ~107 ~8 ~54 wool 15
fill ~106 ~8 ~70 ~107 ~8 ~70 wool 15
fill ~109 ~8 ~25 ~110 ~8 ~25 wool 15
fill ~109 ~8 ~26 ~109 ~8 ~36 wool 7
fill ~109 ~8 ~37 ~110 ~8 ~37 wool 15
fill ~109 ~8 ~56 ~110 ~8 ~56 wool 15
fill ~109 ~8 ~57 ~109 ~8 ~67 wool 7
fill ~109 ~8 ~68 ~110 ~8 ~68 wool 15
fill ~110 ~8 ~26 ~110 ~8 ~38 wool 15
fill ~110 ~8 ~57 ~110 ~8 ~69 wool 15
fill ~114 ~8 ~10 ~115 ~8 ~10 stained_hardened_clay 14
fill ~114 ~8 ~11 ~114 ~8 ~10 stained_hardened_clay 14
fill ~114 ~8 ~82 ~114 ~8 ~83 stained_hardened_clay 14
fill ~115 ~8 ~83 ~115 ~7 ~83 stained_hardened_clay 14
fill ~116 ~8 ~11 ~141 ~8 ~11 stained_hardened_clay 14
fill ~116 ~8 ~82 ~141 ~8 ~82 stained_hardened_clay 14
setblock ~117 ~8 ~18 stained_hardened_clay 9
setblock ~117 ~8 ~75 stained_hardened_clay 9
fill ~118 ~8 ~19 ~118 ~11 ~19 stained_hardened_clay 9
fill ~118 ~8 ~46 ~118 ~11 ~46 stained_hardened_clay 9
fill ~118 ~8 ~47 ~118 ~11 ~47 stained_hardened_clay 9
fill ~118 ~8 ~74 ~118 ~11 ~74 stained_hardened_clay 9
fill ~142 ~8 ~7 ~147 ~8 ~7 stained_hardened_clay 14
fill ~142 ~8 ~8 ~142 ~8 ~10 wool 15
fill ~142 ~8 ~83 ~142 ~8 ~85 wool 15
fill ~142 ~8 ~86 ~147 ~8 ~86 stained_hardened_clay 14
fill ~150 ~8 ~23 ~178 ~8 ~23 wool 15
fill ~150 ~8 ~70 ~178 ~8 ~70 wool 15
fill ~151 ~8 ~7 ~152 ~8 ~7 wool 15
fill ~151 ~8 ~18 ~152 ~8 ~18 wool 15
fill ~151 ~8 ~75 ~152 ~8 ~75 wool 15
fill ~151 ~8 ~86 ~152 ~8 ~86 wool 15
fill ~153 ~8 ~7 ~153 ~9 ~7 stained_hardened_clay 9
fill ~153 ~8 ~8 ~153 ~9 ~8 stained_hardened_clay 9
fill ~153 ~8 ~9 ~153 ~9 ~9 wool 7
fill ~153 ~8 ~10 ~153 ~9 ~10 wool 7
fill ~153 ~8 ~11 ~153 ~9 ~11 wool 7
fill ~153 ~8 ~12 ~153 ~9 ~12 wool 7
fill ~153 ~8 ~13 ~153 ~9 ~13 wool 7
fill ~153 ~8 ~14 ~153 ~9 ~14 wool 7
fill ~153 ~8 ~15 ~153 ~9 ~15 wool 7
fill ~153 ~8 ~16 ~153 ~9 ~16 wool 7
fill ~153 ~8 ~17 ~153 ~9 ~17 wool 7
fill ~153 ~8 ~18 ~153 ~9 ~18 wool 7
fill ~153 ~8 ~75 ~153 ~9 ~75 wool 7
fill ~153 ~8 ~76 ~153 ~9 ~76 wool 7
fill ~153 ~8 ~77 ~153 ~9 ~77 wool 7
fill ~153 ~8 ~78 ~153 ~9 ~78 wool 7
fill ~153 ~8 ~79 ~153 ~9 ~79 wool 7
fill ~153 ~8 ~80 ~153 ~9 ~80 wool 7
fill ~153 ~8 ~81 ~153 ~9 ~81 wool 7
fill ~153 ~8 ~82 ~153 ~9 ~82 wool 7
fill ~153 ~8 ~83 ~153 ~9 ~83 wool 7
fill ~153 ~8 ~84 ~153 ~9 ~84 wool 7
fill ~153 ~8 ~85 ~153 ~9 ~85 stained_hardened_clay 9
fill ~153 ~8 ~86 ~153 ~9 ~86 stained_hardened_clay 9
fill ~154 ~8 ~9 ~154 ~9 ~9 stained_hardened_clay 9
fill ~154 ~8 ~84 ~154 ~9 ~84 stained_hardened_clay 9
setblock ~157 ~8 ~7 stained_hardened_clay 9
setblock ~157 ~8 ~86 stained_hardened_clay 9
fill ~158 ~8 ~12 ~170 ~8 ~12 wool 7
fill ~158 ~8 ~81 ~170 ~8 ~81 wool 7
setblock ~161 ~8 ~8 stained_hardened_clay 9
setblock ~161 ~8 ~85 stained_hardened_clay 9
setblock ~167 ~8 ~8 stained_hardened_clay 9
setblock ~167 ~8 ~85 stained_hardened_clay 9
fill ~170 ~8 ~11 ~170 ~12 ~11 stained_hardened_clay 14
fill ~170 ~8 ~13 ~170 ~12 ~13 stained_hardened_clay 14
fill ~170 ~8 ~80 ~170 ~12 ~80 stained_hardened_clay 14
fill ~170 ~8 ~82 ~170 ~12 ~82 stained_hardened_clay 14
setblock ~171 ~8 ~7 stained_hardened_clay 9
setblock ~171 ~8 ~12 stained_hardened_clay 14
setblock ~171 ~8 ~81 stained_hardened_clay 14
setblock ~171 ~8 ~86 stained_hardened_clay 9
