fill ~1 ~-3 ~5 ~1 ~-3 ~6 tallgrass 1
setblock ~1 ~-3 ~11 tallgrass 1
setblock ~1 ~-3 ~18 red_flower 0
fill ~1 ~-3 ~19 ~1 ~-3 ~20 tallgrass 1
fill ~1 ~-3 ~23 ~6 ~-3 ~23 tallgrass 1
fill ~2 ~-3 ~7 ~3 ~-3 ~7 tallgrass 1
fill ~2 ~-3 ~8 ~2 ~-3 ~7 tallgrass 1
setblock ~2 ~-3 ~10 tallgrass 1
setblock ~2 ~-3 ~15 red_flower 0
setblock ~2 ~-3 ~17 red_flower 0
fill ~2 ~-3 ~20 ~2 ~-3 ~21 red_flower 0
fill ~2 ~-3 ~22 ~3 ~-3 ~22 tallgrass 1
fill ~3 ~-3 ~6 ~6 ~-3 ~6 tallgrass 1
setblock ~3 ~-3 ~9 tallgrass 1
fill ~3 ~-3 ~11 ~4 ~-3 ~11 tallgrass 1
setblock ~3 ~-3 ~20 red_flower 3
setblock ~4 ~-3 ~10 tallgrass 1
fill ~4 ~-3 ~18 ~5 ~-3 ~18 red_flower 0
fill ~4 ~-3 ~19 ~5 ~-3 ~19 tallgrass 1
fill ~4 ~-3 ~20 ~7 ~-3 ~20 tallgrass 1
fill ~4 ~-3 ~21 ~6 ~-3 ~21 tallgrass 1
setblock ~4 ~-3 ~22 red_flower 0
setblock ~4 ~-3 ~24 yellow_flower 0
setblock ~4 ~-3 ~25 tallgrass 1
setblock ~5 ~-3 ~9 tallgrass 1
setblock ~5 ~-3 ~12 tallgrass 1
setblock ~5 ~-3 ~15 tallgrass 1
setblock ~5 ~-3 ~16 red_flower 0
setblock ~5 ~-3 ~17 tallgrass 1
fill ~5 ~-3 ~22 ~6 ~-3 ~22 tallgrass 1
setblock ~6 ~-3 ~5 tallgrass 1
fill ~6 ~-3 ~7 ~8 ~-3 ~7 tallgrass 1
fill ~6 ~-3 ~8 ~6 ~-3 ~5 tallgrass 1
fill ~6 ~-3 ~10 ~6 ~-3 ~11 tallgrass 1
setblock ~6 ~-3 ~24 tallgrass 1
setblock ~6 ~-3 ~26 tallgrass 1
fill ~7 ~-3 ~0 ~8 ~-3 ~0 air
fill ~7 ~-3 ~1 ~8 ~-3 ~1 air
fill ~7 ~-3 ~9 ~8 ~-3 ~9 tallgrass 1
setblock ~7 ~-3 ~11 tallgrass 1
setblock ~7 ~-3 ~14 tallgrass 1
setblock ~7 ~-3 ~25 tallgrass 1
fill ~8 ~-3 ~6 ~11 ~-3 ~6 tallgrass 1
fill ~8 ~-3 ~8 ~12 ~-3 ~8 tallgrass 1
setblock ~8 ~-3 ~12 tallgrass 1
fill ~9 ~-3 ~10 ~10 ~-3 ~10 tallgrass 1
setblock ~9 ~-3 ~14 tallgrass 1
setblock ~10 ~-3 ~13 tallgrass 1
setblock ~10 ~-3 ~47 tallgrass 1
fill ~10 ~-3 ~50 ~14 ~-3 ~50 tallgrass 1
setblock ~11 ~-3 ~7 tallgrass 1
fill ~11 ~-3 ~9 ~12 ~-3 ~9 tallgrass 1
fill ~11 ~-3 ~11 ~13 ~-3 ~11 tallgrass 1
setblock ~11 ~-3 ~49 yellow_flower 0
setblock ~12 ~-3 ~10 tallgrass 1
fill ~12 ~-3 ~12 ~12 ~-3 ~13 tallgrass 1
fill ~12 ~-3 ~48 ~15 ~-3 ~48 tallgrass 1
fill ~12 ~-3 ~49 ~14 ~-3 ~49 tallgrass 1
setblock ~12 ~-3 ~51 tallgrass 1
setblock ~12 ~-3 ~56 tallgrass 1
setblock ~13 ~-3 ~7 tallgrass 1
setblock ~13 ~-3 ~14 tallgrass 1
setblock ~13 ~-3 ~15 double_plant 2
setblock ~13 ~-3 ~47 tallgrass 1
setblock ~13 ~-3 ~53 tallgrass 1
fill ~14 ~-3 ~8 ~14 ~-3 ~9 tallgrass 1
setblock ~14 ~-3 ~11 double_plant 2
setblock ~14 ~-3 ~47 red_flower 0
fill ~14 ~-3 ~51 ~14 ~-3 ~52 tallgrass 1
fill ~14 ~-3 ~56 ~14 ~-3 ~59 tallgrass 1
setblock ~14 ~-3 ~61 tallgrass 1
fill ~15 ~-3 ~6 ~17 ~-3 ~6 tallgrass 1
setblock ~15 ~-3 ~9 double_plant 2
setblock ~15 ~-3 ~10 tallgrass 1
setblock ~15 ~-3 ~13 double_plant 2
fill ~15 ~-3 ~15 ~17 ~-3 ~15 tallgrass 1
fill ~15 ~-3 ~37 ~15 ~-2 ~37 stonebrick 0
setblock ~15 ~-3 ~47 tallgrass 1
fill ~15 ~-3 ~49 ~15 ~-3 ~50 red_flower 0
setblock ~15 ~-3 ~54 tallgrass 1
setblock ~15 ~-3 ~56 double_plant 2
fill ~15 ~-3 ~57 ~17 ~-3 ~57 tallgrass 1
fill ~15 ~-3 ~58 ~20 ~-3 ~58 tallgrass 1
fill ~15 ~-3 ~59 ~15 ~-3 ~57 tallgrass 1
fill ~16 ~-3 ~1 ~17 ~-3 ~1 air
fill ~16 ~-3 ~2 ~17 ~-3 ~2 air
setblock ~16 ~-3 ~7 double_plant 2
fill ~16 ~-3 ~14 ~18 ~-3 ~14 tallgrass 1
fill ~16 ~-3 ~20 ~17 ~-3 ~20 tallgrass 1
setblock ~16 ~-3 ~56 tallgrass 1
fill ~16 ~-3 ~61 ~16 ~-3 ~62 tallgrass 1
setblock ~17 ~-3 ~7 tallgrass 1
setblock ~17 ~-3 ~10 tallgrass 1
fill ~17 ~-3 ~12 ~18 ~-3 ~12 tallgrass 1
fill ~17 ~-3 ~13 ~17 ~-3 ~12 tallgrass 1
setblock ~17 ~-3 ~18 tallgrass 1
fill ~17 ~-3 ~21 ~17 ~-3 ~23 tallgrass 1
setblock ~17 ~-3 ~53 tallgrass 1
setblock ~17 ~-3 ~55 tallgrass 1
setblock ~17 ~-3 ~56 red_flower 0
setblock ~17 ~-3 ~60 double_plant 2
setblock ~17 ~-3 ~61 red_flower 8
fill ~17 ~-3 ~62 ~21 ~-3 ~62 tallgrass 1
fill ~17 ~-3 ~63 ~17 ~-3 ~64 tallgrass 1
setblock ~17 ~-3 ~66 yellow_flower 0
fill ~17 ~-3 ~67 ~20 ~-3 ~67 tallgrass 1
fill ~17 ~-3 ~70 ~17 ~-3 ~71 tallgrass 1
setblock ~18 ~-3 ~5 tallgrass 1
fill ~18 ~-3 ~8 ~18 ~-3 ~9 double_plant 2
setblock ~18 ~-3 ~11 double_plant 2
fill ~18 ~-3 ~16 ~18 ~-3 ~17 tallgrass 1
fill ~18 ~-3 ~22 ~20 ~-3 ~22 tallgrass 1
setblock ~18 ~-3 ~39 tallgrass 1
setblock ~18 ~-3 ~43 tallgrass 1
setblock ~18 ~-3 ~56 tallgrass 1
setblock ~18 ~-3 ~57 red_flower 0
fill ~18 ~-3 ~59 ~18 ~-3 ~62 tallgrass 1
setblock ~18 ~-3 ~64 red_flower 3
fill ~18 ~-3 ~65 ~20 ~-3 ~65 tallgrass 1
fill ~18 ~-3 ~66 ~19 ~-3 ~66 tallgrass 1
setblock ~18 ~-3 ~68 tallgrass 1
fill ~18 ~-3 ~71 ~19 ~-3 ~71 tallgrass 1
fill ~19 ~-3 ~1 ~21 ~-3 ~1 tallgrass 1
fill ~19 ~-3 ~2 ~20 ~-3 ~2 tallgrass 1
fill ~19 ~-3 ~3 ~23 ~-3 ~3 tallgrass 1
fill ~19 ~-3 ~4 ~20 ~-3 ~4 tallgrass 1
setblock ~19 ~-3 ~5 double_plant 2
fill ~19 ~-3 ~6 ~19 ~-3 ~9 tallgrass 1
fill ~19 ~-3 ~17 ~19 ~-3 ~18 tallgrass 1
fill ~19 ~-3 ~20 ~20 ~-3 ~20 tallgrass 1
fill ~19 ~-3 ~21 ~21 ~-3 ~21 tallgrass 1
fill ~19 ~-3 ~23 ~19 ~-3 ~24 tallgrass 1
setblock ~19 ~-3 ~44 yellow_flower 0
setblock ~19 ~-3 ~56 yellow_flower 0
fill ~19 ~-3 ~60 ~21 ~-3 ~60 tallgrass 1
fill ~19 ~-3 ~61 ~21 ~-3 ~61 tallgrass 1
setblock ~19 ~-3 ~63 tallgrass 1
setblock ~19 ~-3 ~64 double_plant 2
setblock ~19 ~-3 ~68 red_flower 3
fill ~19 ~-3 ~69 ~22 ~-3 ~69 tallgrass 1
fill ~20 ~-3 ~0 ~23 ~-3 ~0 tallgrass 1
fill ~20 ~-3 ~8 ~22 ~-3 ~8 tallgrass 1
setblock ~20 ~-3 ~9 double_plant 2
fill ~20 ~-3 ~13 ~20 ~-3 ~14 tallgrass 1
setblock ~20 ~-3 ~16 tallgrass 1
setblock ~20 ~-3 ~19 tallgrass 1
setblock ~20 ~-3 ~23 red_flower 3
fill ~20 ~-3 ~24 ~21 ~-3 ~24 tallgrass 1
fill ~20 ~-3 ~41 ~23 ~-3 ~41 tallgrass 1
fill ~20 ~-3 ~42 ~20 ~-3 ~43 tallgrass 1
setblock ~20 ~-3 ~56 red_flower 0
setblock ~20 ~-3 ~59 tallgrass 1
setblock ~20 ~-3 ~64 tallgrass 1
setblock ~20 ~-3 ~66 yellow_flower 0
setblock ~20 ~-3 ~68 tallgrass 1
fill ~20 ~-3 ~70 ~22 ~-3 ~70 tallgrass 1
fill ~21 ~-3 ~6 ~23 ~-3 ~6 tallgrass 1
fill ~21 ~-3 ~7 ~21 ~-3 ~6 tallgrass 1
fill ~21 ~-3 ~9 ~23 ~-3 ~9 tallgrass 1
fill ~21 ~-3 ~10 ~23 ~-3 ~10 tallgrass 1
setblock ~21 ~-3 ~12 tallgrass 1
fill ~21 ~-3 ~14 ~22 ~-3 ~14 tallgrass 1
setblock ~21 ~-3 ~17 tallgrass 1
fill ~21 ~-3 ~23 ~25 ~-3 ~23 tallgrass 1
fill ~21 ~-3 ~40 ~22 ~-3 ~40 tallgrass 1
fill ~21 ~-3 ~42 ~21 ~-3 ~43 yellow_flower 0
fill ~21 ~-3 ~45 ~22 ~-3 ~45 tallgrass 1
setblock ~21 ~-3 ~63 red_flower 0
setblock ~21 ~-3 ~66 tallgrass 1
setblock ~21 ~-3 ~68 double_plant 2
setblock ~21 ~-3 ~71 tallgrass 1
fill ~22 ~-3 ~2 ~24 ~-3 ~2 tallgrass 1
fill ~22 ~-3 ~4 ~26 ~-3 ~4 tallgrass 1
fill ~22 ~-3 ~20 ~27 ~-3 ~20 tallgrass 1
setblock ~22 ~-3 ~22 tallgrass 1
fill ~22 ~-3 ~42 ~23 ~-3 ~42 tallgrass 1
fill ~22 ~-3 ~43 ~23 ~-3 ~43 tallgrass 1
fill ~22 ~-3 ~44 ~22 ~-3 ~40 tallgrass 1
setblock ~22 ~-3 ~61 red_flower 0
fill ~22 ~-3 ~64 ~22 ~-3 ~65 tallgrass 1
fill ~22 ~-3 ~67 ~24 ~-3 ~67 tallgrass 1
fill ~22 ~-3 ~68 ~22 ~-3 ~67 tallgrass 1
setblock ~22 ~-3 ~72 tallgrass 1
setblock ~23 ~-3 ~1 tallgrass 1
fill ~23 ~-3 ~5 ~24 ~-3 ~5 tallgrass 1
setblock ~23 ~-3 ~7 tallgrass 1
fill ~23 ~-3 ~13 ~25 ~-3 ~13 tallgrass 1
fill ~23 ~-3 ~15 ~23 ~-3 ~16 tallgrass 1
fill ~23 ~-3 ~19 ~25 ~-3 ~19 tallgrass 1
setblock ~23 ~-3 ~21 tallgrass 1
setblock ~23 ~-3 ~22 yellow_flower 0
fill ~23 ~-3 ~24 ~26 ~-3 ~24 tallgrass 1
setblock ~23 ~-3 ~66 tallgrass 1
setblock ~23 ~-3 ~71 tallgrass 1
setblock ~24 ~-3 ~8 tallgrass 1
setblock ~24 ~-3 ~14 tallgrass 1
fill ~24 ~-3 ~25 ~25 ~-3 ~25 tallgrass 1
setblock ~24 ~-3 ~42 red_flower 3
setblock ~24 ~-3 ~44 yellow_flower 0
setblock ~24 ~-3 ~69 tallgrass 1
fill ~25 ~-3 ~0 ~26 ~-3 ~0 tallgrass 1
setblock ~25 ~-3 ~7 tallgrass 1
fill ~25 ~-3 ~9 ~27 ~-3 ~9 tallgrass 1
fill ~25 ~-3 ~10 ~26 ~-3 ~10 tallgrass 1
setblock ~25 ~-3 ~12 tallgrass 1
fill ~25 ~-3 ~16 ~26 ~-3 ~16 tallgrass 1
fill ~25 ~-3 ~21 ~28 ~-3 ~21 tallgrass 1
fill ~25 ~-3 ~22 ~25 ~-3 ~19 tallgrass 1
setblock ~25 ~-3 ~28 tallgrass 1
setblock ~25 ~-3 ~42 tallgrass 1
fill ~26 ~-3 ~1 ~27 ~-3 ~1 tallgrass 1
fill ~26 ~-3 ~2 ~26 ~-3 ~6 tallgrass 1
setblock ~26 ~-3 ~8 tallgrass 1
setblock ~26 ~-3 ~22 red_flower 3
setblock ~26 ~-3 ~23 yellow_flower 0
setblock ~27 ~-3 ~7 tallgrass 1
fill ~27 ~-3 ~12 ~28 ~-3 ~12 tallgrass 1
setblock ~27 ~-3 ~15 tallgrass 1
fill ~27 ~-3 ~17 ~28 ~-3 ~17 tallgrass 1
fill ~27 ~-3 ~18 ~28 ~-3 ~18 tallgrass 1
fill ~27 ~-3 ~19 ~27 ~-3 ~17 tallgrass 1
fill ~27 ~-3 ~23 ~29 ~-3 ~23 tallgrass 1
setblock ~27 ~-3 ~24 red_flower 8
setblock ~28 ~-3 ~0 tallgrass 1
setblock ~28 ~-3 ~3 tallgrass 1
fill ~28 ~-3 ~5 ~28 ~-3 ~6 tallgrass 1
fill ~28 ~-3 ~8 ~29 ~-3 ~8 tallgrass 1
fill ~28 ~-3 ~11 ~29 ~-3 ~11 tallgrass 1
setblock ~28 ~-3 ~13 tallgrass 1
setblock ~28 ~-3 ~16 tallgrass 1
fill ~28 ~-3 ~22 ~30 ~-3 ~22 tallgrass 1
setblock ~28 ~-3 ~25 tallgrass 1
fill ~28 ~-3 ~72 ~31 ~-3 ~72 tallgrass 1
setblock ~29 ~-3 ~6 tallgrass 1
fill ~29 ~-3 ~10 ~30 ~-3 ~10 tallgrass 1
fill ~29 ~-3 ~14 ~30 ~-3 ~14 tallgrass 1
setblock ~29 ~-3 ~19 tallgrass 1
fill ~29 ~-3 ~36 ~34 ~-3 ~36 tallgrass 1
setblock ~29 ~-3 ~38 tallgrass 1
setblock ~29 ~-3 ~73 tallgrass 1
setblock ~30 ~-3 ~2 tallgrass 1
fill ~30 ~-3 ~12 ~32 ~-3 ~12 tallgrass 1
setblock ~30 ~-3 ~20 double_plant 2
fill ~30 ~-3 ~21 ~32 ~-3 ~21 tallgrass 1
setblock ~30 ~-3 ~23 double_plant 2
fill ~30 ~-3 ~24 ~33 ~-3 ~24 tallgrass 1
fill ~30 ~-3 ~28 ~32 ~-3 ~28 tallgrass 1
fill ~30 ~-3 ~34 ~30 ~-3 ~37 tallgrass 1
setblock ~30 ~-3 ~38 yellow_flower 0
setblock ~30 ~-3 ~73 double_plant 2
fill ~31 ~-3 ~11 ~32 ~-3 ~11 tallgrass 1
setblock ~31 ~-3 ~15 tallgrass 1
fill ~31 ~-3 ~23 ~32 ~-3 ~23 tallgrass 1
fill ~31 ~-3 ~25 ~32 ~-3 ~25 tallgrass 1
setblock ~31 ~-3 ~29 tallgrass 1
fill ~31 ~-3 ~37 ~33 ~-3 ~37 tallgrass 1
setblock ~31 ~-3 ~38 red_flower 0
fill ~31 ~-3 ~73 ~32 ~-3 ~73 tallgrass 1
setblock ~32 ~-3 ~22 tallgrass 1
fill ~32 ~-3 ~26 ~34 ~-3 ~26 tallgrass 1
fill ~32 ~-3 ~38 ~34 ~-3 ~38 tallgrass 1
fill ~32 ~-3 ~39 ~33 ~-3 ~39 tallgrass 1
setblock ~32 ~-3 ~40 yellow_flower 0
setblock ~32 ~-3 ~42 tallgrass 1
setblock ~32 ~-3 ~72 yellow_flower 0
setblock ~33 ~-3 ~1 tallgrass 1
fill ~33 ~-3 ~4 ~33 ~-3 ~5 tallgrass 1
setblock ~33 ~-3 ~8 tallgrass 1
fill ~33 ~-3 ~9 ~33 ~-3 ~11 grass 0
setblock ~33 ~-3 ~27 yellow_flower 0
setblock ~33 ~-3 ~40 tallgrass 1
setblock ~33 ~-3 ~73 red_flower 8
setblock ~34 ~-3 ~10 grass 0
fill ~34 ~-3 ~11 ~37 ~-3 ~11 tallgrass 1
fill ~34 ~-3 ~23 ~35 ~-3 ~23 tallgrass 1
setblock ~34 ~-3 ~25 tallgrass 1
setblock ~34 ~-3 ~35 tallgrass 1
fill ~35 ~-3 ~3 ~35 ~-3 ~4 tallgrass 1
fill ~35 ~-3 ~9 ~37 ~-3 ~9 tallgrass 1
setblock ~35 ~-3 ~12 double_plant 2
fill ~35 ~-3 ~13 ~35 ~-3 ~14 tallgrass 1
fill ~35 ~-3 ~19 ~35 ~-3 ~20 tallgrass 1
fill ~35 ~-3 ~22 ~36 ~-3 ~22 tallgrass 1
setblock ~35 ~-3 ~24 tallgrass 1
setblock ~35 ~-3 ~69 tallgrass 1
setblock ~36 ~-3 ~4 tallgrass 1
setblock ~36 ~-3 ~6 tallgrass 1
setblock ~36 ~-3 ~16 tallgrass 1
setblock ~36 ~-3 ~20 tallgrass 1
fill ~36 ~-3 ~29 ~42 ~-3 ~29 tallgrass 1
fill ~36 ~-3 ~73 ~37 ~-3 ~73 tallgrass 1
setblock ~37 ~-3 ~5 tallgrass 1
setblock ~37 ~-3 ~10 tallgrass 1
setblock ~37 ~-3 ~13 tallgrass 1
fill ~37 ~-3 ~17 ~37 ~-3 ~18 tallgrass 1
fill ~37 ~-3 ~21 ~39 ~-3 ~21 tallgrass 1
fill ~37 ~-3 ~23 ~38 ~-3 ~23 tallgrass 1
setblock ~37 ~-3 ~28 tallgrass 1
setblock ~37 ~-3 ~32 tallgrass 1
setblock ~37 ~-3 ~72 tallgrass 1
setblock ~38 ~-3 ~6 tallgrass 1
fill ~38 ~-3 ~14 ~38 ~-3 ~15 tallgrass 1
setblock ~38 ~-3 ~18 tallgrass 1
fill ~38 ~-3 ~30 ~41 ~-3 ~30 tallgrass 1
fill ~39 ~-3 ~15 ~39 ~-3 ~17 tallgrass 1
fill ~39 ~-3 ~19 ~40 ~-3 ~19 tallgrass 1
setblock ~39 ~-3 ~20 double_plant 2
setblock ~39 ~-3 ~22 tallgrass 1
fill ~39 ~-3 ~28 ~41 ~-3 ~28 tallgrass 1
fill ~39 ~-3 ~31 ~40 ~-3 ~31 tallgrass 1
fill ~39 ~-3 ~32 ~41 ~-3 ~32 tallgrass 1
setblock ~40 ~-3 ~5 double_plant 2
fill ~40 ~-3 ~12 ~40 ~-3 ~13 tallgrass 1
fill ~40 ~-3 ~16 ~42 ~-3 ~16 tallgrass 1
fill ~40 ~-3 ~17 ~43 ~-3 ~17 tallgrass 1
setblock ~40 ~-3 ~20 tallgrass 1
fill ~41 ~-3 ~9 ~41 ~-3 ~11 tallgrass 1
fill ~41 ~-3 ~13 ~42 ~-3 ~13 tallgrass 1
fill ~41 ~-3 ~14 ~41 ~-3 ~17 tallgrass 1
setblock ~41 ~-3 ~22 tallgrass 1
fill ~42 ~-3 ~3 ~42 ~-3 ~5 tallgrass 1
setblock ~42 ~-3 ~10 stonebrick 0
fill ~42 ~-3 ~11 ~44 ~-3 ~11 tallgrass 1
fill ~42 ~-3 ~12 ~42 ~-3 ~11 tallgrass 1
setblock ~42 ~-3 ~15 tallgrass 1
fill ~42 ~-3 ~18 ~43 ~-3 ~18 tallgrass 1
fill ~42 ~-3 ~20 ~44 ~-3 ~20 tallgrass 1
fill ~42 ~-3 ~21 ~43 ~-3 ~21 tallgrass 1
setblock ~42 ~-3 ~31 tallgrass 1
setblock ~42 ~-3 ~43 red_flower 0
setblock ~42 ~-3 ~64 stonebrick 0
fill ~43 ~-3 ~4 ~43 ~-3 ~5 tallgrass 1
fill ~43 ~-3 ~7 ~44 ~-3 ~7 tallgrass 1
fill ~43 ~-3 ~9 ~44 ~-3 ~9 tallgrass 1
fill ~43 ~-3 ~14 ~44 ~-3 ~14 tallgrass 1
setblock ~43 ~-3 ~22 tallgrass 1
setblock ~43 ~-3 ~41 red_flower 3
fill ~43 ~-3 ~42 ~44 ~-3 ~42 tallgrass 1
setblock ~44 ~-3 ~6 tallgrass 1
setblock ~44 ~-3 ~8 tallgrass 1
setblock ~44 ~-3 ~13 tallgrass 1
fill ~44 ~-3 ~19 ~46 ~-3 ~19 tallgrass 1
fill ~44 ~-3 ~41 ~45 ~-3 ~41 tallgrass 1
fill ~44 ~-3 ~43 ~44 ~-3 ~45 tallgrass 1
setblock ~44 ~-3 ~46 red_flower 3
setblock ~45 ~-3 ~10 tallgrass 1
fill ~45 ~-3 ~15 ~45 ~-3 ~16 tallgrass 1
setblock ~45 ~-3 ~18 tallgrass 1
setblock ~45 ~-3 ~21 tallgrass 1
fill ~45 ~-3 ~23 ~47 ~-3 ~23 tallgrass 1
fill ~45 ~-3 ~28 ~47 ~-3 ~28 tallgrass 1
fill ~45 ~-3 ~29 ~48 ~-3 ~29 tallgrass 1
setblock ~45 ~-3 ~30 yellow_flower 0
setblock ~45 ~-3 ~40 tallgrass 1
setblock ~45 ~-3 ~42 red_flower 3
setblock ~45 ~-3 ~43 red_flower 8
fill ~45 ~-3 ~44 ~46 ~-3 ~44 tallgrass 1
fill ~45 ~-3 ~45 ~46 ~-3 ~45 tallgrass 1
fill ~45 ~-3 ~46 ~45 ~-3 ~44 tallgrass 1
fill ~46 ~-3 ~11 ~47 ~-3 ~11 tallgrass 1
fill ~46 ~-3 ~12 ~48 ~-3 ~12 tallgrass 1
setblock ~46 ~-3 ~20 tallgrass 1
setblock ~46 ~-3 ~22 tallgrass 1
fill ~46 ~-3 ~30 ~47 ~-3 ~30 tallgrass 1
setblock ~46 ~-3 ~41 red_flower 0
fill ~46 ~-3 ~42 ~48 ~-3 ~42 tallgrass 1
setblock ~46 ~-3 ~43 yellow_flower 0
setblock ~47 ~-3 ~8 double_plant 2
setblock ~47 ~-3 ~10 tallgrass 1
fill ~47 ~-3 ~17 ~47 ~-3 ~18 tallgrass 1
fill ~47 ~-3 ~27 ~48 ~-3 ~27 tallgrass 1
setblock ~47 ~-3 ~31 red_flower 0
setblock ~48 ~-3 ~6 tallgrass 1
fill ~48 ~-3 ~9 ~49 ~-3 ~9 tallgrass 1
fill ~48 ~-3 ~13 ~52 ~-3 ~13 tallgrass 1
fill ~48 ~-3 ~15 ~49 ~-3 ~15 tallgrass 1
fill ~48 ~-3 ~20 ~48 ~-3 ~21 tallgrass 1
setblock ~48 ~-3 ~30 red_flower 8
setblock ~48 ~-3 ~31 tallgrass 1
setblock ~48 ~-3 ~32 red_flower 8
setblock ~48 ~-3 ~45 tallgrass 1
setblock ~49 ~-3 ~5 tallgrass 1
fill ~49 ~-3 ~8 ~50 ~-3 ~8 tallgrass 1
fill ~49 ~-3 ~11 ~50 ~-3 ~11 tallgrass 1
fill ~49 ~-3 ~17 ~49 ~-3 ~19 tallgrass 1
fill ~49 ~-3 ~21 ~49 ~-3 ~23 tallgrass 1
fill ~50 ~-3 ~10 ~53 ~-3 ~10 tallgrass 1
setblock ~50 ~-3 ~18 tallgrass 1
setblock ~50 ~-3 ~20 tallgrass 1
fill ~50 ~-3 ~22 ~50 ~-3 ~23 tallgrass 1
setblock ~50 ~-3 ~29 red_flower 0
setblock ~50 ~-3 ~39 tallgrass 1
setblock ~50 ~-3 ~72 tallgrass 1
setblock ~51 ~-3 ~3 tallgrass 1
fill ~51 ~-3 ~5 ~54 ~-3 ~5 tallgrass 1
fill ~51 ~-3 ~6 ~52 ~-3 ~6 tallgrass 1
fill ~51 ~-3 ~9 ~52 ~-3 ~9 tallgrass 1
fill ~51 ~-3 ~16 ~51 ~-3 ~17 tallgrass 1
setblock ~51 ~-3 ~18 double_plant 2
fill ~51 ~-3 ~24 ~52 ~-3 ~24 tallgrass 1
fill ~51 ~-3 ~25 ~51 ~-3 ~26 tallgrass 1
fill ~52 ~-3 ~4 ~54 ~-3 ~4 tallgrass 1
fill ~52 ~-3 ~11 ~53 ~-3 ~11 tallgrass 1
fill ~52 ~-3 ~12 ~52 ~-3 ~9 tallgrass 1
setblock ~52 ~-3 ~15 tallgrass 1
setblock ~52 ~-3 ~16 double_plant 2
setblock ~52 ~-3 ~18 tallgrass 1
fill ~52 ~-3 ~22 ~54 ~-3 ~22 tallgrass 1
fill ~52 ~-3 ~23 ~52 ~-3 ~22 tallgrass 1
fill ~52 ~-3 ~26 ~52 ~-3 ~27 tallgrass 1
setblock ~52 ~-3 ~28 red_flower 3
setblock ~52 ~-3 ~49 tallgrass 1
setblock ~52 ~-3 ~50 red_flower 3
fill ~52 ~-3 ~51 ~55 ~-3 ~51 tallgrass 1
setblock ~52 ~-3 ~55 tallgrass 1
setblock ~52 ~-3 ~72 tallgrass 1
setblock ~53 ~-3 ~2 red_flower 8
setblock ~53 ~-3 ~3 tallgrass 1
setblock ~53 ~-3 ~6 double_plant 2
fill ~53 ~-3 ~7 ~53 ~-3 ~8 tallgrass 1
setblock ~53 ~-3 ~16 tallgrass 1
setblock ~53 ~-3 ~17 double_plant 2
fill ~53 ~-3 ~20 ~55 ~-3 ~20 tallgrass 1
fill ~53 ~-3 ~21 ~54 ~-3 ~21 tallgrass 1
fill ~53 ~-3 ~25 ~55 ~-3 ~25 tallgrass 1
setblock ~53 ~-3 ~26 red_flower 0
fill ~53 ~-3 ~27 ~55 ~-3 ~27 tallgrass 1
setblock ~53 ~-3 ~50 red_flower 0
setblock ~53 ~-3 ~54 tallgrass 1
setblock ~53 ~-3 ~73 tallgrass 1
setblock ~54 ~-3 ~0 tallgrass 1
setblock ~54 ~-3 ~6 tallgrass 1
fill ~54 ~-3 ~8 ~57 ~-3 ~8 tallgrass 1
setblock ~54 ~-3 ~9 red_flower 8
setblock ~54 ~-3 ~11 red_flower 8
setblock ~54 ~-3 ~12 double_plant 2
fill ~54 ~-3 ~14 ~55 ~-3 ~14 tallgrass 1
setblock ~54 ~-3 ~24 tallgrass 1
fill ~54 ~-3 ~28 ~54 ~-3 ~29 tallgrass 1
fill ~54 ~-3 ~48 ~54 ~-3 ~53 tallgrass 1
fill ~54 ~-3 ~72 ~59 ~-3 ~72 tallgrass 1
fill ~55 ~-3 ~3 ~58 ~-3 ~3 tallgrass 1
setblock ~55 ~-3 ~4 red_flower 8
fill ~55 ~-3 ~7 ~56 ~-3 ~7 tallgrass 1
fill ~55 ~-3 ~9 ~55 ~-3 ~11 tallgrass 1
fill ~55 ~-3 ~16 ~55 ~-3 ~17 double_plant 2
setblock ~55 ~-3 ~18 tallgrass 1
setblock ~55 ~-3 ~50 tallgrass 1
fill ~55 ~-3 ~52 ~57 ~-3 ~52 tallgrass 1
fill ~55 ~-3 ~73 ~59 ~-3 ~73 tallgrass 1
fill ~56 ~-3 ~1 ~57 ~-3 ~1 tallgrass 1
fill ~56 ~-3 ~2 ~57 ~-3 ~2 tallgrass 1
fill ~56 ~-3 ~4 ~57 ~-3 ~4 tallgrass 1
setblock ~56 ~-3 ~5 double_plant 2
fill ~56 ~-3 ~6 ~58 ~-3 ~6 tallgrass 1
fill ~56 ~-3 ~10 ~60 ~-3 ~10 tallgrass 1
setblock ~56 ~-3 ~11 red_flower 8
setblock ~56 ~-3 ~12 double_plant 2
setblock ~56 ~-3 ~13 tallgrass 1
setblock ~56 ~-3 ~14 double_plant 2
fill ~56 ~-3 ~15 ~56 ~-3 ~16 tallgrass 1
fill ~56 ~-3 ~23 ~57 ~-3 ~23 tallgrass 1
fill ~56 ~-3 ~26 ~63 ~-3 ~26 tallgrass 1
setblock ~56 ~-3 ~50 red_flower 8
setblock ~56 ~-3 ~51 red_flower 3
fill ~57 ~-3 ~5 ~58 ~-3 ~5 tallgrass 1
setblock ~57 ~-3 ~7 double_plant 2
setblock ~57 ~-3 ~9 double_plant 2
fill ~57 ~-3 ~13 ~58 ~-3 ~13 double_plant 2
setblock ~57 ~-3 ~15 double_plant 2
setblock ~57 ~-3 ~17 tallgrass 1
setblock ~57 ~-3 ~19 tallgrass 1
fill ~57 ~-3 ~21 ~58 ~-3 ~21 tallgrass 1
fill ~57 ~-3 ~22 ~57 ~-3 ~21 tallgrass 1
setblock ~57 ~-3 ~50 tallgrass 1
setblock ~57 ~-3 ~71 yellow_flower 0
setblock ~58 ~-3 ~0 tallgrass 1
fill ~58 ~-3 ~9 ~59 ~-3 ~9 tallgrass 1
fill ~58 ~-3 ~11 ~60 ~-3 ~11 tallgrass 1
fill ~58 ~-3 ~12 ~58 ~-3 ~9 tallgrass 1
setblock ~58 ~-3 ~14 double_plant 2
setblock ~58 ~-3 ~15 tallgrass 1
setblock ~58 ~-3 ~16 double_plant 2
fill ~58 ~-3 ~20 ~62 ~-3 ~20 tallgrass 1
fill ~58 ~-3 ~24 ~59 ~-3 ~24 red_flower 3
setblock ~58 ~-3 ~25 tallgrass 1
setblock ~58 ~-3 ~27 tallgrass 1
fill ~58 ~-3 ~30 ~59 ~-3 ~30 tallgrass 1
setblock ~58 ~-3 ~54 tallgrass 1
fill ~58 ~-3 ~70 ~58 ~-3 ~73 tallgrass 1
fill ~59 ~-3 ~7 ~62 ~-3 ~7 tallgrass 1
setblock ~59 ~-3 ~8 double_plant 2
setblock ~59 ~-3 ~12 double_plant 2
setblock ~59 ~-3 ~14 tallgrass 1
setblock ~59 ~-3 ~17 double_plant 2
setblock ~59 ~-3 ~19 tallgrass 1
setblock ~59 ~-3 ~25 red_flower 3
setblock ~59 ~-3 ~27 yellow_flower 0
fill ~59 ~-3 ~28 ~61 ~-3 ~28 tallgrass 1
setblock ~59 ~-3 ~52 tallgrass 1
fill ~60 ~-3 ~0 ~60 ~-3 ~3 tallgrass 1
setblock ~60 ~-3 ~5 red_flower 8
fill ~60 ~-3 ~8 ~63 ~-3 ~8 tallgrass 1
fill ~60 ~-3 ~12 ~61 ~-3 ~12 tallgrass 1
setblock ~60 ~-3 ~14 double_plant 2
setblock ~60 ~-3 ~17 tallgrass 1
fill ~60 ~-3 ~23 ~60 ~-3 ~24 tallgrass 1
fill ~60 ~-3 ~27 ~62 ~-3 ~27 tallgrass 1
setblock ~60 ~-3 ~31 tallgrass 1
setblock ~61 ~-3 ~0 red_flower 8
fill ~61 ~-3 ~1 ~61 ~-3 ~2 tallgrass 1
fill ~61 ~-3 ~4 ~62 ~-3 ~4 tallgrass 1
fill ~61 ~-3 ~6 ~63 ~-3 ~6 tallgrass 1
setblock ~61 ~-3 ~10 double_plant 2
setblock ~61 ~-3 ~11 red_flower 8
fill ~61 ~-3 ~13 ~62 ~-3 ~13 tallgrass 1
setblock ~61 ~-3 ~18 tallgrass 1
setblock ~61 ~-3 ~23 double_plant 2
fill ~61 ~-3 ~25 ~63 ~-3 ~25 tallgrass 1
setblock ~61 ~-3 ~30 tallgrass 1
setblock ~61 ~-3 ~72 tallgrass 1
setblock ~62 ~-3 ~5 tallgrass 1
fill ~62 ~-3 ~10 ~62 ~-3 ~11 tallgrass 1
setblock ~62 ~-3 ~15 tallgrass 1
fill ~62 ~-3 ~19 ~63 ~-3 ~19 tallgrass 1
fill ~62 ~-3 ~21 ~63 ~-3 ~21 tallgrass 1
setblock ~62 ~-3 ~24 tallgrass 1
setblock ~62 ~-3 ~69 tallgrass 1
setblock ~62 ~-3 ~71 tallgrass 1
setblock ~62 ~-3 ~72 yellow_flower 0
fill ~63 ~-3 ~1 ~63 ~-3 ~3 tallgrass 1
fill ~63 ~-3 ~12 ~64 ~-3 ~12 tallgrass 1
setblock ~63 ~-3 ~18 double_plant 2
setblock ~63 ~-3 ~71 yellow_flower 0
fill ~63 ~-3 ~72 ~64 ~-3 ~72 tallgrass 1
fill ~63 ~-3 ~73 ~63 ~-3 ~72 tallgrass 1
setblock ~64 ~-3 ~3 tallgrass 1
setblock ~64 ~-3 ~69 red_flower 3
fill ~64 ~-3 ~70 ~67 ~-3 ~70 tallgrass 1
setblock ~64 ~-3 ~71 red_flower 0
fill ~65 ~-3 ~0 ~66 ~-3 ~0 tallgrass 1
fill ~65 ~-3 ~11 ~67 ~-3 ~11 tallgrass 1
setblock ~65 ~-3 ~23 tallgrass 1
setblock ~65 ~-3 ~53 tallgrass 1
setblock ~65 ~-3 ~69 tallgrass 1
setblock ~65 ~-3 ~71 red_flower 8
setblock ~65 ~-3 ~73 tallgrass 1
setblock ~66 ~-3 ~2 tallgrass 1
setblock ~66 ~-3 ~54 tallgrass 1
fill ~66 ~-3 ~71 ~67 ~-3 ~71 tallgrass 1
setblock ~66 ~-3 ~73 yellow_flower 0
fill ~67 ~-3 ~52 ~70 ~-3 ~52 tallgrass 1
setblock ~67 ~-3 ~53 red_flower 8
fill ~67 ~-3 ~55 ~67 ~-3 ~56 tallgrass 1
setblock ~68 ~-3 ~0 tallgrass 1
setblock ~68 ~-3 ~51 tallgrass 1
fill ~68 ~-3 ~53 ~70 ~-3 ~53 tallgrass 1
fill ~68 ~-3 ~54 ~68 ~-3 ~51 tallgrass 1
setblock ~68 ~-3 ~55 red_flower 0
fill ~69 ~-3 ~17 ~77 ~-3 ~17 grass 0
fill ~69 ~-3 ~18 ~78 ~-3 ~18 grass 0
setblock ~69 ~-3 ~37 stonebrick 0
setblock ~69 ~-3 ~54 yellow_flower 0
fill ~69 ~-3 ~55 ~70 ~-3 ~55 tallgrass 1
setblock ~69 ~-3 ~57 tallgrass 1
setblock ~69 ~-3 ~72 tallgrass 1
fill ~70 ~-3 ~13 ~70 ~-3 ~20 grass 0
fill ~70 ~-3 ~54 ~71 ~-3 ~54 tallgrass 1
fill ~71 ~-3 ~0 ~78 ~-3 ~0 grass 0
fill ~71 ~-3 ~9 ~79 ~-3 ~9 grass 0
fill ~71 ~-3 ~11 ~77 ~-3 ~11 grass 0
fill ~71 ~-3 ~12 ~77 ~-3 ~12 grass 0
fill ~71 ~-3 ~13 ~72 ~-3 ~13 dirt 0
fill ~71 ~-3 ~14 ~72 ~-3 ~14 dirt 0
fill ~71 ~-3 ~15 ~79 ~-3 ~15 grass 0
fill ~71 ~-3 ~16 ~79 ~-3 ~16 grass 0
fill ~71 ~-3 ~19 ~79 ~-3 ~19 grass 0
fill ~71 ~-3 ~20 ~79 ~-3 ~20 grass 0
fill ~71 ~-3 ~21 ~79 ~-3 ~21 grass 0
fill ~71 ~-3 ~22 ~79 ~-3 ~22 grass 0
setblock ~71 ~-3 ~51 tallgrass 1
setblock ~71 ~-3 ~53 red_flower 0
setblock ~71 ~-3 ~66 tallgrass 1
setblock ~71 ~-3 ~68 tallgrass 1
fill ~72 ~-3 ~7 ~75 ~-3 ~7 grass 0
fill ~72 ~-3 ~8 ~79 ~-3 ~8 grass 0
fill ~72 ~-3 ~10 ~79 ~-3 ~10 grass 0
setblock ~72 ~-3 ~52 red_flower 8
setblock ~72 ~-3 ~56 tallgrass 1
fill ~73 ~-3 ~6 ~79 ~-3 ~6 grass 0
fill ~73 ~-3 ~13 ~79 ~-3 ~13 grass 0
fill ~73 ~-3 ~14 ~79 ~-3 ~14 grass 0
setblock ~73 ~-3 ~29 tallgrass 1
setblock ~73 ~-3 ~52 tallgrass 1
fill ~73 ~-3 ~63 ~75 ~-3 ~63 tallgrass 1
fill ~73 ~-3 ~64 ~74 ~-3 ~64 tallgrass 1
fill ~74 ~-3 ~27 ~74 ~-3 ~28 tallgrass 1
setblock ~74 ~-3 ~30 red_flower 3
setblock ~74 ~-3 ~36 tallgrass 1
setblock ~74 ~-3 ~41 tallgrass 1
fill ~74 ~-3 ~65 ~77 ~-3 ~65 tallgrass 1
fill ~74 ~-3 ~66 ~76 ~-3 ~66 tallgrass 1
setblock ~74 ~-3 ~67 yellow_flower 0
fill ~75 ~-3 ~1 ~79 ~-3 ~1 grass 0
fill ~75 ~-3 ~2 ~79 ~-3 ~2 grass 0
fill ~75 ~-3 ~4 ~77 ~-3 ~4 grass 0
fill ~75 ~-3 ~5 ~77 ~-3 ~5 grass 0
fill ~75 ~-3 ~23 ~79 ~-3 ~23 grass 0
fill ~75 ~-3 ~26 ~75 ~-3 ~27 yellow_flower 0
fill ~75 ~-3 ~28 ~77 ~-3 ~28 tallgrass 1
fill ~75 ~-3 ~29 ~75 ~-3 ~31 tallgrass 1
setblock ~75 ~-3 ~37 tallgrass 1
setblock ~75 ~-3 ~64 yellow_flower 0
fill ~76 ~-3 ~3 ~79 ~-3 ~3 grass 0
setblock ~76 ~-3 ~7 dirt 0
fill ~76 ~-3 ~27 ~78 ~-3 ~27 tallgrass 1
setblock ~76 ~-3 ~29 red_flower 8
fill ~76 ~-3 ~30 ~79 ~-3 ~30 tallgrass 1
setblock ~76 ~-3 ~37 yellow_flower 0
fill ~76 ~-3 ~38 ~78 ~-3 ~38 tallgrass 1
setblock ~76 ~-3 ~62 tallgrass 1
setblock ~76 ~-3 ~64 tallgrass 1
fill ~76 ~-3 ~68 ~77 ~-3 ~68 tallgrass 1
fill ~77 ~-3 ~7 ~79 ~-3 ~7 grass 0
setblock ~77 ~-3 ~29 tallgrass 1
setblock ~77 ~-3 ~33 tallgrass 1
setblock ~77 ~-3 ~35 red_flower 8
fill ~77 ~-3 ~36 ~77 ~-3 ~39 tallgrass 1
setblock ~77 ~-3 ~41 tallgrass 1
fill ~78 ~-3 ~4 ~79 ~-3 ~4 dirt 0
fill ~78 ~-3 ~5 ~79 ~-3 ~5 dirt 0
fill ~78 ~-3 ~11 ~79 ~-3 ~11 dirt 0
fill ~78 ~-3 ~12 ~79 ~-3 ~12 dirt 0
setblock ~78 ~-3 ~17 dirt 0
setblock ~78 ~-3 ~36 red_flower 0
fill ~78 ~-3 ~37 ~79 ~-3 ~37 tallgrass 1
setblock ~78 ~-3 ~40 red_flower 8
setblock ~79 ~-3 ~0 dirt 0
setblock ~79 ~-3 ~17 grass 0
setblock ~79 ~-3 ~18 dirt 0
fill ~79 ~-3 ~35 ~79 ~-3 ~37 tallgrass 1
fill ~79 ~-3 ~39 ~79 ~-3 ~40 tallgrass 1
setblock ~79 ~-3 ~41 yellow_flower 0
setblock ~79 ~-3 ~61 tallgrass 1
fill ~7 ~-2 ~0 ~8 ~-2 ~0 air
fill ~7 ~-2 ~1 ~9 ~-2 ~1 air
fill ~13 ~-2 ~37 ~17 ~-2 ~37 stonebrick 0
fill ~13 ~-2 ~38 ~17 ~-2 ~38 stonebrick 0
fill ~14 ~-2 ~35 ~15 ~-2 ~35 stonebrick 0
fill ~14 ~-2 ~36 ~15 ~-2 ~36 stonebrick 0
fill ~14 ~-2 ~39 ~15 ~-2 ~39 stonebrick 0
fill ~16 ~-2 ~1 ~17 ~-2 ~1 air
fill ~16 ~-2 ~2 ~17 ~-2 ~2 air
fill ~33 ~-2 ~10 ~33 ~-2 ~11 tallgrass 1
fill ~40 ~-2 ~10 ~41 ~-2 ~10 stonebrick 0
fill ~40 ~-2 ~11 ~44 ~-2 ~11 stonebrick 0
fill ~40 ~-2 ~64 ~41 ~-2 ~64 stonebrick 0
fill ~40 ~-2 ~65 ~44 ~-2 ~65 stonebrick 0
fill ~41 ~-2 ~8 ~42 ~-2 ~8 stonebrick 0
fill ~41 ~-2 ~9 ~42 ~-2 ~9 stonebrick 0
fill ~41 ~-2 ~12 ~42 ~-2 ~12 stonebrick 0
fill ~41 ~-2 ~62 ~42 ~-2 ~62 stonebrick 0
fill ~41 ~-2 ~63 ~42 ~-2 ~63 stonebrick 0
fill ~41 ~-2 ~66 ~42 ~-2 ~66 stonebrick 0
fill ~43 ~-2 ~10 ~44 ~-2 ~10 stonebrick 0
fill ~43 ~-2 ~64 ~44 ~-2 ~64 stonebrick 0
fill ~67 ~-2 ~37 ~68 ~-2 ~37 stonebrick 0
fill ~67 ~-2 ~38 ~71 ~-2 ~38 stonebrick 0
fill ~68 ~-2 ~35 ~69 ~-2 ~35 stonebrick 0
fill ~68 ~-2 ~36 ~69 ~-2 ~36 stonebrick 0
fill ~68 ~-2 ~39 ~69 ~-2 ~39 stonebrick 0
fill ~70 ~-2 ~37 ~71 ~-2 ~37 stonebrick 0
fill ~71 ~-2 ~13 ~72 ~-2 ~13 air
fill ~71 ~-2 ~14 ~72 ~-2 ~14 air
setblock ~76 ~-2 ~4 tallgrass 1
fill ~76 ~-2 ~7 ~76 ~1 ~7 log 0
fill ~78 ~-2 ~4 ~79 ~-2 ~4 air
fill ~78 ~-2 ~5 ~79 ~-2 ~5 air
fill ~78 ~-2 ~11 ~79 ~-2 ~11 air
fill ~78 ~-2 ~12 ~79 ~-2 ~12 air
fill ~78 ~-2 ~17 ~78 ~2 ~17 brown_mushroom_block 10
setblock ~79 ~-2 ~0 wool 3
setblock ~79 ~-2 ~18 grass 0
fill ~7 ~-1 ~0 ~9 ~-1 ~0 air
fill ~7 ~-1 ~1 ~9 ~-1 ~1 air
fill ~7 ~-1 ~2 ~7 ~1 ~2 air
fill ~9 ~-1 ~2 ~9 ~1 ~2 air
fill ~12 ~-1 ~36 ~13 ~-1 ~36 stonebrick 0
fill ~12 ~-1 ~37 ~12 ~-1 ~39 stonebrick 0
fill ~13 ~-1 ~34 ~16 ~-1 ~34 stonebrick 0
fill ~13 ~-1 ~35 ~13 ~-1 ~34 stonebrick 0
fill ~13 ~-1 ~39 ~13 ~-1 ~40 stonebrick 0
fill ~14 ~-1 ~40 ~16 ~-1 ~40 stonebrick 0
fill ~16 ~-1 ~1 ~17 ~-1 ~1 air
fill ~16 ~-1 ~2 ~17 ~-1 ~2 air
fill ~16 ~-1 ~35 ~16 ~-1 ~36 stonebrick 0
fill ~16 ~-1 ~39 ~17 ~-1 ~39 stonebrick 0
fill ~17 ~-1 ~36 ~18 ~-1 ~36 stonebrick 0
fill ~18 ~-1 ~37 ~18 ~-1 ~38 stonebrick 0
fill ~39 ~-1 ~9 ~40 ~-1 ~9 stonebrick 0
fill ~39 ~-1 ~10 ~39 ~-1 ~12 stonebrick 0
fill ~39 ~-1 ~63 ~40 ~-1 ~63 stonebrick 0
fill ~39 ~-1 ~64 ~39 ~-1 ~66 stonebrick 0
fill ~40 ~-1 ~7 ~43 ~-1 ~7 stonebrick 0
fill ~40 ~-1 ~8 ~40 ~-1 ~7 stonebrick 0
fill ~40 ~-1 ~12 ~40 ~-1 ~13 stonebrick 0
fill ~40 ~-1 ~61 ~43 ~-1 ~61 stonebrick 0
fill ~40 ~-1 ~62 ~40 ~-1 ~61 stonebrick 0
fill ~40 ~-1 ~66 ~40 ~-1 ~67 stonebrick 0
fill ~41 ~-1 ~13 ~43 ~-1 ~13 stonebrick 0
fill ~41 ~-1 ~67 ~43 ~-1 ~67 stonebrick 0
fill ~43 ~-1 ~8 ~43 ~-1 ~9 stonebrick 0
fill ~43 ~-1 ~12 ~44 ~-1 ~12 stonebrick 0
fill ~43 ~-1 ~62 ~43 ~-1 ~63 stonebrick 0
fill ~43 ~-1 ~66 ~44 ~-1 ~66 stonebrick 0
fill ~44 ~-1 ~9 ~45 ~-1 ~9 stonebrick 0
fill ~44 ~-1 ~63 ~45 ~-1 ~63 stonebrick 0
fill ~45 ~-1 ~10 ~45 ~-1 ~11 stonebrick 0
fill ~45 ~-1 ~64 ~45 ~-1 ~65 stonebrick 0
fill ~66 ~-1 ~36 ~67 ~-1 ~36 stonebrick 0
fill ~66 ~-1 ~37 ~66 ~-1 ~39 stonebrick 0
fill ~67 ~-1 ~34 ~70 ~-1 ~34 stonebrick 0
fill ~67 ~-1 ~35 ~67 ~-1 ~34 stonebrick 0
fill ~67 ~-1 ~39 ~67 ~-1 ~40 stonebrick 0
fill ~68 ~-1 ~40 ~70 ~-1 ~40 stonebrick 0
fill ~70 ~-1 ~35 ~70 ~-1 ~36 stonebrick 0
fill ~70 ~-1 ~39 ~71 ~-1 ~39 stonebrick 0
fill ~71 ~-1 ~13 ~72 ~-1 ~13 air
fill ~71 ~-1 ~14 ~72 ~-1 ~14 air
fill ~71 ~-1 ~36 ~72 ~-1 ~36 stonebrick 0
fill ~72 ~-1 ~37 ~72 ~-1 ~38 stonebrick 0
fill ~74 ~-1 ~5 ~77 ~-1 ~5 leaves 0
fill ~74 ~-1 ~6 ~78 ~-1 ~6 leaves 0
fill ~74 ~-1 ~7 ~75 ~-1 ~7 leaves 0
fill ~74 ~-1 ~8 ~78 ~-1 ~8 leaves 0
fill ~74 ~-1 ~9 ~77 ~-1 ~9 leaves 0
fill ~77 ~-1 ~7 ~78 ~-1 ~7 leaves 0
fill ~78 ~-1 ~4 ~79 ~-1 ~4 air
fill ~78 ~-1 ~5 ~79 ~-1 ~5 air
fill ~78 ~-1 ~11 ~79 ~-1 ~11 air
fill ~78 ~-1 ~12 ~79 ~-1 ~12 air
fill ~8 ~0 ~0 ~9 ~0 ~0 air
fill ~8 ~0 ~1 ~9 ~0 ~1 air
fill ~10 ~0 ~37 ~11 ~0 ~37 stonebrick 0
fill ~11 ~0 ~35 ~12 ~0 ~35 stonebrick 0
fill ~11 ~0 ~36 ~11 ~0 ~35 stonebrick 0
fill ~11 ~0 ~38 ~11 ~0 ~39 stonebrick 0
fill ~12 ~0 ~33 ~17 ~0 ~33 stonebrick 0
fill ~12 ~0 ~34 ~12 ~0 ~33 stonebrick 0
fill ~12 ~0 ~40 ~13 ~0 ~40 stonebrick 0
fill ~13 ~0 ~41 ~17 ~0 ~41 stonebrick 0
setblock ~15 ~0 ~32 stonebrick 0
setblock ~15 ~0 ~42 stonebrick 0
fill ~16 ~0 ~1 ~18 ~0 ~1 air
fill ~16 ~0 ~2 ~17 ~0 ~2 air
fill ~17 ~0 ~34 ~17 ~0 ~35 stonebrick 0
fill ~17 ~0 ~40 ~18 ~0 ~40 stonebrick 0
fill ~18 ~0 ~35 ~19 ~0 ~35 stonebrick 0
fill ~18 ~0 ~39 ~19 ~0 ~39 stonebrick 0
fill ~19 ~0 ~36 ~19 ~0 ~39 stonebrick 0
setblock ~20 ~0 ~37 stonebrick 0
fill ~37 ~0 ~10 ~38 ~0 ~10 stonebrick 0
fill ~37 ~0 ~64 ~38 ~0 ~64 stonebrick 0
fill ~38 ~0 ~8 ~39 ~0 ~8 stonebrick 0
fill ~38 ~0 ~9 ~38 ~0 ~8 stonebrick 0
fill ~38 ~0 ~11 ~38 ~0 ~12 stonebrick 0
fill ~38 ~0 ~62 ~39 ~0 ~62 stonebrick 0
fill ~38 ~0 ~63 ~38 ~0 ~62 stonebrick 0
fill ~38 ~0 ~65 ~38 ~0 ~66 stonebrick 0
fill ~39 ~0 ~6 ~44 ~0 ~6 stonebrick 0
fill ~39 ~0 ~7 ~39 ~0 ~6 stonebrick 0
fill ~39 ~0 ~13 ~40 ~0 ~13 stonebrick 0
fill ~39 ~0 ~60 ~44 ~0 ~60 stonebrick 0
fill ~39 ~0 ~61 ~39 ~0 ~60 stonebrick 0
fill ~39 ~0 ~67 ~40 ~0 ~67 stonebrick 0
fill ~40 ~0 ~14 ~44 ~0 ~14 stonebrick 0
fill ~40 ~0 ~68 ~44 ~0 ~68 stonebrick 0
setblock ~42 ~0 ~5 stonebrick 0
setblock ~42 ~0 ~15 stonebrick 0
setblock ~42 ~0 ~59 stonebrick 0
setblock ~42 ~0 ~69 stonebrick 0
fill ~44 ~0 ~7 ~44 ~0 ~8 stonebrick 0
fill ~44 ~0 ~13 ~45 ~0 ~13 stonebrick 0
fill ~44 ~0 ~61 ~44 ~0 ~62 stonebrick 0
fill ~44 ~0 ~67 ~45 ~0 ~67 stonebrick 0
fill ~45 ~0 ~8 ~46 ~0 ~8 stonebrick 0
fill ~45 ~0 ~12 ~46 ~0 ~12 stonebrick 0
fill ~45 ~0 ~62 ~46 ~0 ~62 stonebrick 0
fill ~45 ~0 ~66 ~46 ~0 ~66 stonebrick 0
fill ~46 ~0 ~9 ~46 ~0 ~12 stonebrick 0
fill ~46 ~0 ~63 ~46 ~0 ~66 stonebrick 0
setblock ~47 ~0 ~10 stonebrick 0
setblock ~47 ~0 ~64 stonebrick 0
fill ~64 ~0 ~37 ~65 ~0 ~37 stonebrick 0
fill ~65 ~0 ~35 ~66 ~0 ~35 stonebrick 0
fill ~65 ~0 ~36 ~65 ~0 ~35 stonebrick 0
fill ~65 ~0 ~38 ~65 ~0 ~39 stonebrick 0
fill ~66 ~0 ~33 ~71 ~0 ~33 stonebrick 0
fill ~66 ~0 ~34 ~66 ~0 ~33 stonebrick 0
fill ~66 ~0 ~40 ~67 ~0 ~40 stonebrick 0
fill ~67 ~0 ~41 ~71 ~0 ~41 stonebrick 0
setblock ~69 ~0 ~32 stonebrick 0
setblock ~69 ~0 ~42 stonebrick 0
fill ~71 ~0 ~13 ~72 ~0 ~13 air
fill ~71 ~0 ~14 ~72 ~0 ~14 air
fill ~71 ~0 ~34 ~71 ~0 ~35 stonebrick 0
fill ~71 ~0 ~40 ~72 ~0 ~40 stonebrick 0
fill ~72 ~0 ~35 ~73 ~0 ~35 stonebrick 0
fill ~72 ~0 ~39 ~73 ~0 ~39 stonebrick 0
fill ~73 ~0 ~12 ~73 ~3 ~12 air
fill ~73 ~0 ~36 ~73 ~0 ~39 stonebrick 0
fill ~74 ~0 ~6 ~78 ~0 ~6 leaves 0
fill ~74 ~0 ~7 ~75 ~0 ~7 leaves 0
fill ~74 ~0 ~8 ~78 ~0 ~8 leaves 0
fill ~74 ~0 ~9 ~77 ~0 ~9 leaves 0
setblock ~74 ~0 ~37 stonebrick 0
fill ~75 ~0 ~5 ~77 ~0 ~5 leaves 0
fill ~77 ~0 ~7 ~78 ~0 ~7 leaves 0
fill ~78 ~0 ~4 ~79 ~0 ~4 air
fill ~78 ~0 ~5 ~79 ~0 ~5 air
fill ~78 ~0 ~11 ~79 ~0 ~11 air
fill ~78 ~0 ~12 ~79 ~0 ~12 air
fill ~2 ~1 ~0 ~2 ~2 ~0 air
fill ~2 ~1 ~1 ~2 ~2 ~1 air
fill ~7 ~1 ~0 ~8 ~1 ~0 leaves2 1
fill ~7 ~1 ~1 ~8 ~1 ~1 leaves2 1
fill ~7 ~1 ~3 ~19 ~1 ~3 leaves2 1
fill ~8 ~1 ~2 ~8 ~3 ~2 leaves2 1
fill ~8 ~1 ~4 ~12 ~1 ~4 leaves2 1
fill ~9 ~1 ~0 ~10 ~1 ~0 air
fill ~9 ~1 ~1 ~10 ~1 ~1 air
fill ~9 ~1 ~36 ~10 ~1 ~36 stonebrick 0
fill ~9 ~1 ~37 ~9 ~1 ~38 stonebrick 0
fill ~10 ~1 ~2 ~15 ~1 ~2 leaves2 1
fill ~10 ~1 ~34 ~11 ~1 ~34 stonebrick 0
fill ~10 ~1 ~35 ~10 ~1 ~34 stonebrick 0
fill ~10 ~1 ~38 ~10 ~1 ~40 stonebrick 0
fill ~11 ~1 ~0 ~20 ~1 ~0 leaves2 1
fill ~11 ~1 ~1 ~15 ~1 ~1 leaves2 1
setblock ~11 ~1 ~33 stonebrick 0
fill ~11 ~1 ~39 ~11 ~1 ~41 stonebrick 0
fill ~12 ~1 ~32 ~14 ~1 ~32 stonebrick 0
fill ~12 ~1 ~41 ~12 ~1 ~42 stonebrick 0
fill ~13 ~1 ~42 ~14 ~1 ~42 stonebrick 0
fill ~14 ~1 ~4 ~19 ~1 ~4 leaves2 1
fill ~14 ~1 ~31 ~16 ~1 ~31 stonebrick 0
fill ~14 ~1 ~43 ~16 ~1 ~43 stonebrick 0
fill ~16 ~1 ~1 ~18 ~1 ~1 air
fill ~16 ~1 ~2 ~17 ~1 ~2 air
fill ~16 ~1 ~32 ~18 ~1 ~32 stonebrick 0
fill ~16 ~1 ~42 ~18 ~1 ~42 stonebrick 0
fill ~18 ~1 ~2 ~20 ~1 ~2 leaves2 1
fill ~18 ~1 ~33 ~19 ~1 ~33 stonebrick 0
fill ~18 ~1 ~34 ~20 ~1 ~34 stonebrick 0
fill ~18 ~1 ~41 ~19 ~1 ~41 stonebrick 0
fill ~19 ~1 ~1 ~20 ~1 ~1 leaves2 1
fill ~19 ~1 ~40 ~20 ~1 ~40 stonebrick 0
fill ~20 ~1 ~35 ~20 ~1 ~36 stonebrick 0
fill ~20 ~1 ~38 ~21 ~1 ~38 stonebrick 0
fill ~20 ~1 ~39 ~20 ~1 ~38 stonebrick 0
fill ~21 ~1 ~36 ~21 ~1 ~38 stonebrick 0
fill ~36 ~1 ~9 ~37 ~1 ~9 stonebrick 0
fill ~36 ~1 ~10 ~36 ~1 ~11 stonebrick 0
fill ~36 ~1 ~63 ~37 ~1 ~63 stonebrick 0
fill ~36 ~1 ~64 ~36 ~1 ~65 stonebrick 0
fill ~37 ~1 ~7 ~38 ~1 ~7 stonebrick 0
fill ~37 ~1 ~8 ~37 ~1 ~7 stonebrick 0
fill ~37 ~1 ~11 ~37 ~1 ~13 stonebrick 0
fill ~37 ~1 ~61 ~38 ~1 ~61 stonebrick 0
fill ~37 ~1 ~62 ~37 ~1 ~61 stonebrick 0
fill ~37 ~1 ~65 ~37 ~1 ~67 stonebrick 0
setblock ~38 ~1 ~6 stonebrick 0
fill ~38 ~1 ~12 ~38 ~1 ~14 stonebrick 0
setblock ~38 ~1 ~60 stonebrick 0
fill ~38 ~1 ~66 ~38 ~1 ~68 stonebrick 0
fill ~39 ~1 ~5 ~41 ~1 ~5 stonebrick 0
fill ~39 ~1 ~14 ~39 ~1 ~15 stonebrick 0
fill ~39 ~1 ~59 ~41 ~1 ~59 stonebrick 0
fill ~39 ~1 ~68 ~39 ~1 ~69 stonebrick 0
fill ~40 ~1 ~15 ~41 ~1 ~15 stonebrick 0
fill ~40 ~1 ~69 ~41 ~1 ~69 stonebrick 0
fill ~41 ~1 ~4 ~43 ~1 ~4 stonebrick 0
fill ~41 ~1 ~16 ~43 ~1 ~16 stonebrick 0
fill ~41 ~1 ~58 ~43 ~1 ~58 stonebrick 0
fill ~41 ~1 ~70 ~43 ~1 ~70 stonebrick 0
fill ~43 ~1 ~5 ~45 ~1 ~5 stonebrick 0
fill ~43 ~1 ~15 ~45 ~1 ~15 stonebrick 0
fill ~43 ~1 ~59 ~45 ~1 ~59 stonebrick 0
fill ~43 ~1 ~69 ~45 ~1 ~69 stonebrick 0
fill ~45 ~1 ~6 ~46 ~1 ~6 stonebrick 0
fill ~45 ~1 ~7 ~47 ~1 ~7 stonebrick 0
fill ~45 ~1 ~14 ~46 ~1 ~14 stonebrick 0
fill ~45 ~1 ~60 ~46 ~1 ~60 stonebrick 0
fill ~45 ~1 ~61 ~47 ~1 ~61 stonebrick 0
fill ~45 ~1 ~68 ~46 ~1 ~68 stonebrick 0
fill ~46 ~1 ~13 ~47 ~1 ~13 stonebrick 0
fill ~46 ~1 ~67 ~47 ~1 ~67 stonebrick 0
fill ~47 ~1 ~8 ~47 ~1 ~9 stonebrick 0
fill ~47 ~1 ~11 ~48 ~1 ~11 stonebrick 0
fill ~47 ~1 ~12 ~47 ~1 ~11 stonebrick 0
fill ~47 ~1 ~62 ~47 ~1 ~63 stonebrick 0
fill ~47 ~1 ~65 ~48 ~1 ~65 stonebrick 0
fill ~47 ~1 ~66 ~47 ~1 ~65 stonebrick 0
fill ~48 ~1 ~9 ~48 ~1 ~11 stonebrick 0
fill ~48 ~1 ~63 ~48 ~1 ~65 stonebrick 0
fill ~63 ~1 ~36 ~64 ~1 ~36 stonebrick 0
fill ~63 ~1 ~37 ~63 ~1 ~38 stonebrick 0
fill ~64 ~1 ~34 ~65 ~1 ~34 stonebrick 0
fill ~64 ~1 ~35 ~64 ~1 ~34 stonebrick 0
fill ~64 ~1 ~38 ~64 ~1 ~40 stonebrick 0
setblock ~65 ~1 ~33 stonebrick 0
fill ~65 ~1 ~39 ~65 ~1 ~41 stonebrick 0
fill ~66 ~1 ~32 ~68 ~1 ~32 stonebrick 0
fill ~66 ~1 ~41 ~66 ~1 ~42 stonebrick 0
fill ~67 ~1 ~42 ~68 ~1 ~42 stonebrick 0
fill ~68 ~1 ~31 ~70 ~1 ~31 stonebrick 0
fill ~68 ~1 ~43 ~70 ~1 ~43 stonebrick 0
fill ~70 ~1 ~32 ~72 ~1 ~32 stonebrick 0
fill ~70 ~1 ~42 ~72 ~1 ~42 stonebrick 0
fill ~71 ~1 ~13 ~72 ~1 ~13 air
fill ~71 ~1 ~14 ~72 ~1 ~14 air
fill ~72 ~1 ~12 ~72 ~3 ~12 air
fill ~72 ~1 ~33 ~73 ~1 ~33 stonebrick 0
fill ~72 ~1 ~34 ~74 ~1 ~34 stonebrick 0
fill ~72 ~1 ~41 ~73 ~1 ~41 stonebrick 0
fill ~73 ~1 ~40 ~74 ~1 ~40 stonebrick 0
fill ~74 ~1 ~35 ~74 ~1 ~36 stonebrick 0
fill ~74 ~1 ~38 ~75 ~1 ~38 stonebrick 0
fill ~74 ~1 ~39 ~74 ~1 ~38 stonebrick 0
fill ~75 ~1 ~7 ~75 ~2 ~7 leaves 0
fill ~75 ~1 ~8 ~76 ~1 ~8 leaves 0
fill ~75 ~1 ~36 ~75 ~1 ~38 stonebrick 0
fill ~76 ~1 ~6 ~76 ~2 ~6 leaves 0
fill ~77 ~1 ~7 ~77 ~2 ~7 leaves 0
fill ~78 ~1 ~4 ~79 ~1 ~4 air
fill ~78 ~1 ~5 ~79 ~1 ~5 air
fill ~78 ~1 ~11 ~79 ~1 ~11 air
fill ~78 ~1 ~12 ~79 ~1 ~12 air
fill ~1 ~2 ~2 ~4 ~2 ~2 leaves2 1
fill ~1 ~2 ~3 ~3 ~2 ~3 leaves2 1
fill ~1 ~2 ~4 ~1 ~3 ~4 leaves2 1
fill ~3 ~2 ~0 ~4 ~2 ~0 leaves2 1
fill ~3 ~2 ~1 ~4 ~2 ~1 leaves2 1
fill ~6 ~2 ~0 ~8 ~2 ~0 leaves2 1
fill ~6 ~2 ~1 ~8 ~2 ~1 leaves2 1
fill ~6 ~2 ~2 ~15 ~2 ~2 leaves2 1
fill ~7 ~2 ~3 ~20 ~2 ~3 leaves2 1
fill ~7 ~2 ~4 ~11 ~2 ~4 leaves2 1
fill ~8 ~2 ~35 ~9 ~2 ~35 stonebrick 0
fill ~8 ~2 ~36 ~8 ~2 ~39 stonebrick 0
fill ~9 ~2 ~0 ~10 ~2 ~0 air
fill ~9 ~2 ~1 ~10 ~2 ~1 air
fill ~9 ~2 ~33 ~10 ~2 ~33 stonebrick 0
fill ~9 ~2 ~34 ~10 ~2 ~34 stonebrick 0
fill ~9 ~2 ~39 ~9 ~2 ~41 stonebrick 0
fill ~10 ~2 ~32 ~11 ~2 ~32 stonebrick 0
fill ~10 ~2 ~41 ~10 ~2 ~42 stonebrick 0
fill ~11 ~2 ~0 ~20 ~2 ~0 leaves2 1
fill ~11 ~2 ~1 ~15 ~2 ~1 leaves2 1
fill ~11 ~2 ~31 ~13 ~2 ~31 stonebrick 0
fill ~11 ~2 ~42 ~11 ~2 ~43 stonebrick 0
fill ~12 ~2 ~43 ~13 ~2 ~43 stonebrick 0
fill ~13 ~2 ~30 ~17 ~2 ~30 stonebrick 0
fill ~13 ~2 ~44 ~17 ~2 ~44 stonebrick 0
fill ~14 ~2 ~4 ~18 ~2 ~4 leaves2 1
fill ~14 ~2 ~5 ~18 ~2 ~5 leaves2 1
fill ~16 ~2 ~1 ~17 ~2 ~1 air
fill ~16 ~2 ~2 ~17 ~2 ~2 air
fill ~17 ~2 ~31 ~19 ~2 ~31 stonebrick 0
fill ~17 ~2 ~43 ~19 ~2 ~43 stonebrick 0
fill ~18 ~2 ~1 ~20 ~2 ~1 leaves2 1
fill ~18 ~2 ~2 ~20 ~2 ~2 leaves2 1
fill ~19 ~2 ~32 ~20 ~2 ~32 stonebrick 0
fill ~19 ~2 ~42 ~20 ~2 ~42 stonebrick 0
fill ~20 ~2 ~33 ~21 ~2 ~33 stonebrick 0
fill ~20 ~2 ~41 ~21 ~2 ~41 stonebrick 0
fill ~21 ~2 ~34 ~21 ~2 ~35 stonebrick 0
fill ~21 ~2 ~39 ~22 ~2 ~39 stonebrick 0
fill ~21 ~2 ~40 ~21 ~2 ~39 stonebrick 0
fill ~22 ~2 ~35 ~22 ~2 ~39 stonebrick 0
fill ~35 ~2 ~8 ~36 ~2 ~8 stonebrick 0
fill ~35 ~2 ~9 ~35 ~2 ~12 stonebrick 0
fill ~35 ~2 ~62 ~36 ~2 ~62 stonebrick 0
fill ~35 ~2 ~63 ~35 ~2 ~66 stonebrick 0
fill ~36 ~2 ~6 ~37 ~2 ~6 stonebrick 0
fill ~36 ~2 ~7 ~37 ~2 ~7 stonebrick 0
fill ~36 ~2 ~12 ~36 ~2 ~14 stonebrick 0
fill ~36 ~2 ~60 ~37 ~2 ~60 stonebrick 0
fill ~36 ~2 ~61 ~37 ~2 ~61 stonebrick 0
fill ~36 ~2 ~66 ~36 ~2 ~68 stonebrick 0
fill ~37 ~2 ~5 ~38 ~2 ~5 stonebrick 0
fill ~37 ~2 ~14 ~37 ~2 ~15 stonebrick 0
fill ~37 ~2 ~59 ~38 ~2 ~59 stonebrick 0
fill ~37 ~2 ~68 ~37 ~2 ~69 stonebrick 0
fill ~38 ~2 ~4 ~40 ~2 ~4 stonebrick 0
fill ~38 ~2 ~15 ~38 ~2 ~16 stonebrick 0
fill ~38 ~2 ~58 ~40 ~2 ~58 stonebrick 0
fill ~38 ~2 ~69 ~38 ~2 ~70 stonebrick 0
fill ~39 ~2 ~16 ~40 ~2 ~16 stonebrick 0
fill ~39 ~2 ~70 ~40 ~2 ~70 stonebrick 0
fill ~40 ~2 ~3 ~44 ~2 ~3 stonebrick 0
fill ~40 ~2 ~17 ~44 ~2 ~17 stonebrick 0
fill ~40 ~2 ~57 ~44 ~2 ~57 stonebrick 0
fill ~40 ~2 ~71 ~44 ~2 ~71 stonebrick 0
fill ~44 ~2 ~4 ~46 ~2 ~4 stonebrick 0
fill ~44 ~2 ~16 ~46 ~2 ~16 stonebrick 0
fill ~44 ~2 ~58 ~46 ~2 ~58 stonebrick 0
fill ~44 ~2 ~70 ~46 ~2 ~70 stonebrick 0
fill ~46 ~2 ~5 ~47 ~2 ~5 stonebrick 0
fill ~46 ~2 ~15 ~47 ~2 ~15 stonebrick 0
fill ~46 ~2 ~59 ~47 ~2 ~59 stonebrick 0
fill ~46 ~2 ~69 ~47 ~2 ~69 stonebrick 0
fill ~47 ~2 ~6 ~48 ~2 ~6 stonebrick 0
fill ~47 ~2 ~14 ~48 ~2 ~14 stonebrick 0
fill ~47 ~2 ~60 ~48 ~2 ~60 stonebrick 0
fill ~47 ~2 ~68 ~48 ~2 ~68 stonebrick 0
fill ~48 ~2 ~7 ~48 ~2 ~8 stonebrick 0
fill ~48 ~2 ~12 ~49 ~2 ~12 stonebrick 0
fill ~48 ~2 ~13 ~48 ~2 ~12 stonebrick 0
fill ~48 ~2 ~61 ~48 ~2 ~62 stonebrick 0
fill ~48 ~2 ~66 ~49 ~2 ~66 stonebrick 0
fill ~48 ~2 ~67 ~48 ~2 ~66 stonebrick 0
fill ~49 ~2 ~8 ~49 ~2 ~12 stonebrick 0
fill ~49 ~2 ~62 ~49 ~2 ~66 stonebrick 0
fill ~62 ~2 ~35 ~63 ~2 ~35 stonebrick 0
fill ~62 ~2 ~36 ~62 ~2 ~39 stonebrick 0
fill ~63 ~2 ~33 ~64 ~2 ~33 stonebrick 0
fill ~63 ~2 ~34 ~64 ~2 ~34 stonebrick 0
fill ~63 ~2 ~39 ~63 ~2 ~41 stonebrick 0
fill ~64 ~2 ~32 ~65 ~2 ~32 stonebrick 0
fill ~64 ~2 ~41 ~64 ~2 ~42 stonebrick 0
fill ~65 ~2 ~31 ~67 ~2 ~31 stonebrick 0
fill ~65 ~2 ~42 ~65 ~2 ~43 stonebrick 0
fill ~66 ~2 ~43 ~67 ~2 ~43 stonebrick 0
fill ~67 ~2 ~30 ~71 ~2 ~30 stonebrick 0
fill ~67 ~2 ~44 ~71 ~2 ~44 stonebrick 0
fill ~71 ~2 ~13 ~72 ~2 ~13 air
fill ~71 ~2 ~14 ~72 ~2 ~14 air
fill ~71 ~2 ~31 ~73 ~2 ~31 stonebrick 0
fill ~71 ~2 ~43 ~73 ~2 ~43 stonebrick 0
fill ~73 ~2 ~32 ~74 ~2 ~32 stonebrick 0
fill ~73 ~2 ~42 ~74 ~2 ~42 stonebrick 0
fill ~74 ~2 ~33 ~75 ~2 ~33 stonebrick 0
fill ~74 ~2 ~41 ~75 ~2 ~41 stonebrick 0
fill ~75 ~2 ~34 ~75 ~2 ~35 stonebrick 0
fill ~75 ~2 ~39 ~76 ~2 ~39 stonebrick 0
fill ~75 ~2 ~40 ~75 ~2 ~39 stonebrick 0
fill ~76 ~2 ~7 ~76 ~2 ~8 leaves 0
fill ~76 ~2 ~35 ~76 ~2 ~39 stonebrick 0
fill ~77 ~2 ~4 ~79 ~2 ~4 air
fill ~77 ~2 ~6 ~77 ~3 ~6 air
fill ~78 ~2 ~3 ~79 ~2 ~3 air
fill ~78 ~2 ~11 ~79 ~2 ~11 air
fill ~78 ~2 ~12 ~79 ~2 ~12 air
fill ~78 ~2 ~13 ~78 ~4 ~13 air
fill ~1 ~3 ~2 ~4 ~3 ~2 leaves2 1
fill ~1 ~3 ~3 ~2 ~3 ~3 leaves2 1
fill ~2 ~3 ~0 ~4 ~3 ~0 leaves2 1
fill ~2 ~3 ~1 ~4 ~3 ~1 leaves2 1
setblock ~2 ~3 ~4 leaves2 1
fill ~7 ~3 ~0 ~12 ~3 ~0 leaves2 1
fill ~7 ~3 ~1 ~12 ~3 ~1 leaves2 1
fill ~8 ~3 ~32 ~9 ~3 ~32 stonebrick 0
fill ~8 ~3 ~33 ~8 ~3 ~34 stonebrick 0
fill ~8 ~3 ~40 ~8 ~3 ~42 stonebrick 0
fill ~9 ~3 ~2 ~11 ~3 ~2 leaves2 1
fill ~9 ~3 ~3 ~10 ~3 ~3 leaves2 1
fill ~9 ~3 ~31 ~10 ~3 ~31 stonebrick 0
fill ~9 ~3 ~42 ~9 ~3 ~43 stonebrick 0
fill ~10 ~3 ~30 ~12 ~3 ~30 stonebrick 0
fill ~10 ~3 ~43 ~10 ~3 ~44 stonebrick 0
fill ~11 ~3 ~44 ~12 ~3 ~44 stonebrick 0
fill ~12 ~3 ~29 ~18 ~3 ~29 stonebrick 0
fill ~12 ~3 ~45 ~18 ~3 ~45 stonebrick 0
fill ~13 ~3 ~31 ~13 ~4 ~31 stonebrick 0
fill ~14 ~3 ~1 ~19 ~3 ~1 leaves2 1
fill ~14 ~3 ~2 ~19 ~3 ~2 leaves2 1
fill ~15 ~3 ~0 ~18 ~3 ~0 leaves2 1
fill ~15 ~3 ~3 ~18 ~3 ~3 leaves2 1
fill ~16 ~3 ~4 ~17 ~3 ~4 leaves2 1
fill ~18 ~3 ~30 ~20 ~3 ~30 stonebrick 0
fill ~18 ~3 ~44 ~20 ~3 ~44 stonebrick 0
fill ~20 ~3 ~31 ~21 ~3 ~31 stonebrick 0
fill ~20 ~3 ~43 ~21 ~3 ~43 stonebrick 0
fill ~21 ~3 ~32 ~22 ~3 ~32 stonebrick 0
fill ~21 ~3 ~42 ~22 ~3 ~42 stonebrick 0
fill ~22 ~3 ~33 ~22 ~3 ~34 stonebrick 0
fill ~22 ~3 ~40 ~23 ~3 ~40 stonebrick 0
fill ~22 ~3 ~41 ~22 ~3 ~40 stonebrick 0
fill ~23 ~3 ~34 ~23 ~3 ~40 stonebrick 0
setblock ~29 ~3 ~24 stonebrick 0
setblock ~29 ~3 ~50 stonebrick 0
fill ~35 ~3 ~5 ~36 ~3 ~5 stonebrick 0
fill ~35 ~3 ~6 ~35 ~3 ~7 stonebrick 0
fill ~35 ~3 ~13 ~35 ~3 ~15 stonebrick 0
fill ~35 ~3 ~59 ~36 ~3 ~59 stonebrick 0
fill ~35 ~3 ~60 ~35 ~3 ~61 stonebrick 0
fill ~35 ~3 ~67 ~35 ~3 ~69 stonebrick 0
fill ~36 ~3 ~4 ~37 ~3 ~4 stonebrick 0
fill ~36 ~3 ~15 ~36 ~3 ~16 stonebrick 0
fill ~36 ~3 ~58 ~37 ~3 ~58 stonebrick 0
fill ~36 ~3 ~69 ~36 ~3 ~70 stonebrick 0
fill ~37 ~3 ~3 ~39 ~3 ~3 stonebrick 0
fill ~37 ~3 ~16 ~37 ~3 ~17 stonebrick 0
fill ~37 ~3 ~57 ~39 ~3 ~57 stonebrick 0
fill ~37 ~3 ~70 ~37 ~3 ~71 stonebrick 0
fill ~38 ~3 ~17 ~39 ~3 ~17 stonebrick 0
fill ~38 ~3 ~71 ~39 ~3 ~71 stonebrick 0
fill ~39 ~3 ~2 ~45 ~3 ~2 stonebrick 0
fill ~39 ~3 ~18 ~45 ~3 ~18 stonebrick 0
fill ~39 ~3 ~56 ~45 ~3 ~56 stonebrick 0
fill ~39 ~3 ~72 ~45 ~3 ~72 stonebrick 0
fill ~40 ~3 ~4 ~40 ~4 ~4 stonebrick 0
fill ~40 ~3 ~58 ~40 ~4 ~58 stonebrick 0
fill ~45 ~3 ~3 ~47 ~3 ~3 stonebrick 0
fill ~45 ~3 ~17 ~47 ~3 ~17 stonebrick 0
fill ~45 ~3 ~57 ~47 ~3 ~57 stonebrick 0
fill ~45 ~3 ~71 ~47 ~3 ~71 stonebrick 0
fill ~47 ~3 ~4 ~48 ~3 ~4 stonebrick 0
fill ~47 ~3 ~16 ~48 ~3 ~16 stonebrick 0
fill ~47 ~3 ~58 ~48 ~3 ~58 stonebrick 0
fill ~47 ~3 ~70 ~48 ~3 ~70 stonebrick 0
fill ~48 ~3 ~5 ~49 ~3 ~5 stonebrick 0
fill ~48 ~3 ~15 ~49 ~3 ~15 stonebrick 0
fill ~48 ~3 ~59 ~49 ~3 ~59 stonebrick 0
fill ~48 ~3 ~69 ~49 ~3 ~69 stonebrick 0
fill ~49 ~3 ~6 ~49 ~3 ~7 stonebrick 0
fill ~49 ~3 ~13 ~50 ~3 ~13 stonebrick 0
fill ~49 ~3 ~14 ~49 ~3 ~13 stonebrick 0
fill ~49 ~3 ~60 ~49 ~3 ~61 stonebrick 0
fill ~49 ~3 ~67 ~50 ~3 ~67 stonebrick 0
fill ~49 ~3 ~68 ~49 ~3 ~67 stonebrick 0
fill ~50 ~3 ~7 ~50 ~3 ~13 stonebrick 0
fill ~50 ~3 ~61 ~50 ~3 ~67 stonebrick 0
setblock ~55 ~3 ~24 stonebrick 0
setblock ~55 ~3 ~50 stonebrick 0
fill ~61 ~3 ~34 ~62 ~3 ~34 stonebrick 0
fill ~61 ~3 ~35 ~61 ~3 ~40 stonebrick 0
fill ~62 ~3 ~32 ~63 ~3 ~32 stonebrick 0
fill ~62 ~3 ~33 ~62 ~3 ~32 stonebrick 0
fill ~62 ~3 ~40 ~62 ~3 ~42 stonebrick 0
fill ~63 ~3 ~31 ~64 ~3 ~31 stonebrick 0
fill ~63 ~3 ~42 ~63 ~3 ~43 stonebrick 0
fill ~64 ~3 ~30 ~66 ~3 ~30 stonebrick 0
fill ~64 ~3 ~43 ~64 ~3 ~44 stonebrick 0
fill ~65 ~3 ~44 ~66 ~3 ~44 stonebrick 0
fill ~66 ~3 ~29 ~72 ~3 ~29 stonebrick 0
fill ~66 ~3 ~45 ~72 ~3 ~45 stonebrick 0
fill ~67 ~3 ~31 ~67 ~4 ~31 stonebrick 0
fill ~69 ~3 ~11 ~75 ~3 ~11 leaves2 1
fill ~69 ~3 ~12 ~71 ~3 ~12 leaves2 1
fill ~69 ~3 ~13 ~70 ~3 ~13 leaves2 1
fill ~69 ~3 ~14 ~70 ~3 ~14 leaves2 1
fill ~69 ~3 ~15 ~74 ~3 ~15 leaves2 1
fill ~69 ~3 ~16 ~74 ~3 ~16 leaves2 1
fill ~71 ~3 ~10 ~74 ~3 ~10 leaves2 1
fill ~71 ~3 ~13 ~72 ~3 ~13 air
fill ~71 ~3 ~14 ~72 ~3 ~14 air
fill ~72 ~3 ~30 ~74 ~3 ~30 stonebrick 0
fill ~72 ~3 ~44 ~74 ~3 ~44 stonebrick 0
fill ~73 ~3 ~13 ~75 ~3 ~13 leaves2 1
fill ~73 ~3 ~14 ~74 ~3 ~14 leaves2 1
fill ~74 ~3 ~12 ~75 ~3 ~12 leaves2 1
fill ~74 ~3 ~31 ~75 ~3 ~31 stonebrick 0
fill ~74 ~3 ~43 ~75 ~3 ~43 stonebrick 0
fill ~75 ~3 ~2 ~79 ~3 ~2 leaves2 1
fill ~75 ~3 ~3 ~77 ~3 ~3 leaves2 1
fill ~75 ~3 ~4 ~76 ~3 ~4 leaves2 1
fill ~75 ~3 ~5 ~79 ~3 ~5 leaves2 1
fill ~75 ~3 ~6 ~76 ~3 ~6 leaves2 1
setblock ~75 ~3 ~15 brown_mushroom_block 1
fill ~75 ~3 ~16 ~75 ~3 ~18 brown_mushroom_block 4
setblock ~75 ~3 ~19 brown_mushroom_block 7
fill ~75 ~3 ~32 ~76 ~3 ~32 stonebrick 0
fill ~75 ~3 ~42 ~76 ~3 ~42 stonebrick 0
fill ~76 ~3 ~1 ~79 ~3 ~1 leaves2 1
fill ~76 ~3 ~7 ~78 ~3 ~7 leaves2 1
setblock ~76 ~3 ~14 brown_mushroom_block 1
fill ~76 ~3 ~15 ~79 ~3 ~15 brown_mushroom_block 5
fill ~76 ~3 ~16 ~79 ~3 ~16 brown_mushroom_block 5
fill ~76 ~3 ~17 ~79 ~3 ~17 brown_mushroom_block 5
fill ~76 ~3 ~18 ~79 ~3 ~18 brown_mushroom_block 5
fill ~76 ~3 ~19 ~79 ~3 ~19 brown_mushroom_block 5
setblock ~76 ~3 ~20 brown_mushroom_block 7
fill ~76 ~3 ~33 ~76 ~3 ~34 stonebrick 0
fill ~76 ~3 ~40 ~77 ~3 ~40 stonebrick 0
fill ~76 ~3 ~41 ~76 ~3 ~40 stonebrick 0
fill ~77 ~3 ~4 ~79 ~3 ~4 air
fill ~77 ~3 ~12 ~79 ~3 ~12 air
fill ~77 ~3 ~14 ~79 ~3 ~14 brown_mushroom_block 2
fill ~77 ~3 ~20 ~79 ~3 ~20 brown_mushroom_block 8
fill ~77 ~3 ~34 ~77 ~3 ~40 stonebrick 0
fill ~78 ~3 ~3 ~79 ~3 ~3 air
fill ~78 ~3 ~6 ~79 ~3 ~6 leaves2 1
fill ~78 ~3 ~11 ~79 ~3 ~11 air
fill ~79 ~3 ~0 ~79 ~4 ~0 leaves2 1
fill ~1 ~4 ~0 ~3 ~4 ~0 leaves2 1
fill ~1 ~4 ~1 ~3 ~4 ~1 leaves2 1
fill ~1 ~4 ~2 ~2 ~4 ~2 leaves2 1
fill ~1 ~4 ~3 ~1 ~2 ~3 leaves2 1
fill ~6 ~4 ~33 ~7 ~4 ~33 stonebrick 0
fill ~6 ~4 ~34 ~6 ~4 ~41 stonebrick 0
fill ~7 ~4 ~31 ~8 ~4 ~31 stonebrick 0
fill ~7 ~4 ~32 ~7 ~4 ~31 stonebrick 0
fill ~7 ~4 ~34 ~7 ~4 ~40 stone_sts 1
fill ~7 ~4 ~41 ~7 ~4 ~43 stonebrick 0
fill ~8 ~4 ~30 ~9 ~4 ~30 stonebrick 0
fill ~8 ~4 ~32 ~8 ~4 ~33 stone_sts 1
setblock ~8 ~4 ~34 stone_sts 3
fill ~8 ~4 ~35 ~9 ~4 ~35 stonebrick 0
fill ~8 ~4 ~36 ~9 ~4 ~36 stonebrick 0
fill ~8 ~4 ~37 ~11 ~4 ~37 stone 5
fill ~8 ~4 ~38 ~9 ~4 ~38 stonebrick 0
fill ~8 ~4 ~39 ~9 ~4 ~39 stonebrick 0
setblock ~8 ~4 ~40 stone_sts 2
setblock ~8 ~4 ~41 stone_sts 1
setblock ~8 ~4 ~42 stone_sts 2
fill ~8 ~4 ~43 ~8 ~4 ~44 stonebrick 0
fill ~9 ~4 ~0 ~10 ~4 ~0 leaves2 1
fill ~9 ~4 ~1 ~10 ~4 ~1 leaves2 1
fill ~9 ~4 ~29 ~11 ~4 ~29 stonebrick 0
setblock ~9 ~4 ~31 stone_sts 1
setblock ~9 ~4 ~32 stone_sts 3
fill ~9 ~4 ~33 ~10 ~4 ~33 stonebrick 0
fill ~9 ~4 ~34 ~10 ~4 ~34 stonebrick 0
fill ~9 ~4 ~40 ~10 ~4 ~40 stonebrick 0
fill ~9 ~4 ~41 ~10 ~4 ~41 stonebrick 0
setblock ~9 ~4 ~42 stone_sts 1
setblock ~9 ~4 ~43 stone_sts 2
fill ~9 ~4 ~44 ~9 ~4 ~45 stonebrick 0
setblock ~10 ~4 ~30 stone_sts 1
setblock ~10 ~4 ~31 stone_sts 3
fill ~10 ~4 ~32 ~12 ~4 ~32 stonebrick 0
fill ~10 ~4 ~35 ~12 ~4 ~35 lapis_block 0
fill ~10 ~4 ~36 ~13 ~4 ~36 lapis_block 0
fill ~10 ~4 ~38 ~13 ~4 ~38 lapis_block 0
fill ~10 ~4 ~39 ~12 ~4 ~39 lapis_block 0
fill ~10 ~4 ~42 ~12 ~4 ~42 stonebrick 0
setblock ~10 ~4 ~43 stone_sts 1
fill ~10 ~4 ~44 ~11 ~4 ~44 stone_sts 2
fill ~10 ~4 ~45 ~11 ~4 ~45 stonebrick 0
fill ~11 ~4 ~28 ~19 ~4 ~28 stonebrick 0
setblock ~11 ~4 ~30 stone_sts 3
fill ~11 ~4 ~31 ~14 ~4 ~31 stonebrick 0
fill ~11 ~4 ~33 ~12 ~4 ~33 wool 3
fill ~11 ~4 ~34 ~12 ~4 ~34 wool 3
fill ~11 ~4 ~40 ~12 ~4 ~40 wool 3
fill ~11 ~4 ~41 ~12 ~4 ~41 wool 3
fill ~11 ~4 ~43 ~14 ~4 ~43 stonebrick 0
fill ~11 ~4 ~46 ~19 ~4 ~46 stonebrick 0
fill ~12 ~4 ~29 ~18 ~4 ~29 stone_sts 3
setblock ~12 ~4 ~30 stone_sts 1
setblock ~12 ~4 ~37 stone_sts 0
setblock ~12 ~4 ~44 stone_sts 1
fill ~12 ~4 ~45 ~18 ~4 ~45 stone_sts 2
fill ~13 ~4 ~30 ~14 ~4 ~30 stonebrick 0
fill ~13 ~4 ~32 ~14 ~4 ~32 lapis_block 0
fill ~13 ~4 ~33 ~14 ~4 ~33 lapis_block 0
fill ~13 ~4 ~34 ~14 ~4 ~34 lapis_block 0
setblock ~13 ~4 ~35 wool 3
setblock ~13 ~4 ~37 stonebrick 0
setblock ~13 ~4 ~39 wool 3
fill ~13 ~4 ~40 ~14 ~4 ~40 lapis_block 0
fill ~13 ~4 ~41 ~14 ~4 ~41 lapis_block 0
fill ~13 ~4 ~42 ~14 ~4 ~42 lapis_block 0
fill ~13 ~4 ~44 ~14 ~4 ~44 stonebrick 0
setblock ~14 ~4 ~35 lapis_block 0
setblock ~14 ~4 ~36 wool 3
setblock ~14 ~4 ~37 stone_sts 0
setblock ~14 ~4 ~38 wool 3
setblock ~14 ~4 ~39 lapis_block 0
fill ~15 ~4 ~30 ~15 ~4 ~33 stone 5
setblock ~15 ~4 ~34 stone_sts 2
setblock ~15 ~4 ~35 stonebrick 0
setblock ~15 ~4 ~36 stone_sts 2
setblock ~15 ~4 ~37 iron_trapdoor 11
setblock ~15 ~4 ~38 stone_sts 3
setblock ~15 ~4 ~39 stonebrick 0
setblock ~15 ~4 ~40 stone_sts 3
fill ~15 ~4 ~41 ~15 ~4 ~44 stone 5
fill ~16 ~4 ~1 ~17 ~4 ~1 leaves2 1
fill ~16 ~4 ~2 ~17 ~4 ~2 leaves2 1
fill ~16 ~4 ~30 ~17 ~4 ~30 stonebrick 0
fill ~16 ~4 ~31 ~19 ~4 ~31 stonebrick 0
fill ~16 ~4 ~32 ~17 ~4 ~32 lapis_block 0
fill ~16 ~4 ~33 ~17 ~4 ~33 lapis_block 0
fill ~16 ~4 ~34 ~17 ~4 ~34 lapis_block 0
fill ~16 ~4 ~35 ~16 ~4 ~32 lapis_block 0
setblock ~16 ~4 ~36 wool 3
setblock ~16 ~4 ~37 stone_sts 1
setblock ~16 ~4 ~38 wool 3
fill ~16 ~4 ~39 ~16 ~4 ~42 lapis_block 0
fill ~16 ~4 ~43 ~19 ~4 ~43 stonebrick 0
fill ~16 ~4 ~44 ~17 ~4 ~44 double_stone_slab 5
setblock ~17 ~4 ~35 wool 3
fill ~17 ~4 ~36 ~20 ~4 ~36 lapis_block 0
setblock ~17 ~4 ~37 stonebrick 0
fill ~17 ~4 ~38 ~20 ~4 ~38 lapis_block 0
setblock ~17 ~4 ~39 wool 3
fill ~17 ~4 ~40 ~17 ~4 ~42 lapis_block 0
setblock ~18 ~4 ~30 stone_sts 0
fill ~18 ~4 ~32 ~20 ~4 ~32 stonebrick 0
fill ~18 ~4 ~33 ~19 ~4 ~33 wool 3
fill ~18 ~4 ~34 ~19 ~4 ~34 wool 3
fill ~18 ~4 ~35 ~20 ~4 ~35 lapis_block 0
setblock ~18 ~4 ~37 stone_sts 1
fill ~18 ~4 ~39 ~20 ~4 ~39 lapis_block 0
fill ~18 ~4 ~40 ~19 ~4 ~40 wool 3
fill ~18 ~4 ~41 ~19 ~4 ~41 wool 3
fill ~18 ~4 ~42 ~20 ~4 ~42 stonebrick 0
setblock ~18 ~4 ~44 stone_sts 0
fill ~19 ~4 ~29 ~21 ~4 ~29 stonebrick 0
fill ~19 ~4 ~30 ~20 ~4 ~30 stone_sts 3
fill ~19 ~4 ~37 ~22 ~4 ~37 stone 5
setblock ~19 ~4 ~44 stone_sts 2
fill ~19 ~4 ~45 ~21 ~4 ~45 stonebrick 0
setblock ~20 ~4 ~31 stone_sts 0
fill ~20 ~4 ~33 ~21 ~4 ~33 stonebrick 0
fill ~20 ~4 ~34 ~21 ~4 ~34 stonebrick 0
fill ~20 ~4 ~40 ~21 ~4 ~40 stonebrick 0
fill ~20 ~4 ~41 ~21 ~4 ~41 stonebrick 0
setblock ~20 ~4 ~43 stone_sts 2
setblock ~20 ~4 ~44 stone_sts 0
fill ~21 ~4 ~30 ~22 ~4 ~30 stonebrick 0
setblock ~21 ~4 ~31 stone_sts 3
setblock ~21 ~4 ~32 stone_sts 0
fill ~21 ~4 ~35 ~22 ~4 ~35 stonebrick 0
fill ~21 ~4 ~36 ~22 ~4 ~36 stonebrick 0
fill ~21 ~4 ~38 ~22 ~4 ~38 stonebrick 0
fill ~21 ~4 ~39 ~22 ~4 ~39 stonebrick 0
setblock ~21 ~4 ~42 stone_sts 2
setblock ~21 ~4 ~43 stone_sts 0
fill ~21 ~4 ~44 ~22 ~4 ~44 stonebrick 0
fill ~22 ~4 ~31 ~23 ~4 ~31 stonebrick 0
setblock ~22 ~4 ~32 stone_sts 3
setblock ~22 ~4 ~33 stone_sts 0
setblock ~22 ~4 ~34 stone_sts 3
setblock ~22 ~4 ~40 stone_sts 2
fill ~22 ~4 ~41 ~22 ~4 ~42 stone_sts 0
fill ~22 ~4 ~43 ~23 ~4 ~43 stonebrick 0
fill ~23 ~4 ~32 ~25 ~4 ~32 stonebrick 0
fill ~23 ~4 ~33 ~24 ~4 ~33 stonebrick 0
fill ~23 ~4 ~34 ~23 ~4 ~40 stone_sts 0
fill ~23 ~4 ~41 ~24 ~4 ~41 stonebrick 0
fill ~23 ~4 ~42 ~25 ~4 ~42 stonebrick 0
fill ~24 ~4 ~34 ~24 ~4 ~42 stonebrick 0
fill ~25 ~4 ~28 ~26 ~4 ~28 stonebrick 0
fill ~25 ~4 ~29 ~26 ~4 ~29 stonebrick 0
fill ~25 ~4 ~30 ~25 ~4 ~32 stonebrick 0
setblock ~25 ~4 ~33 glowstone 0
fill ~25 ~4 ~34 ~25 ~4 ~40 cobblestone 0
setblock ~25 ~4 ~41 glowstone 0
fill ~25 ~4 ~43 ~25 ~4 ~46 stonebrick 0
fill ~26 ~4 ~22 ~32 ~4 ~22 stonebrick 0
fill ~26 ~4 ~23 ~31 ~4 ~23 stonebrick 0
fill ~26 ~4 ~24 ~28 ~4 ~24 stonebrick 0
fill ~26 ~4 ~25 ~29 ~4 ~25 stonebrick 0
fill ~26 ~4 ~26 ~28 ~4 ~26 stonebrick 0
fill ~26 ~4 ~27 ~27 ~4 ~27 stonebrick 0
fill ~26 ~4 ~30 ~27 ~4 ~30 cobblestone 0
fill ~26 ~4 ~31 ~26 ~4 ~33 cobblestone 0
fill ~26 ~4 ~34 ~27 ~4 ~34 bedrock 0
fill ~26 ~4 ~35 ~27 ~4 ~35 bedrock 0
fill ~26 ~4 ~36 ~27 ~4 ~36 bedrock 0
fill ~26 ~4 ~37 ~30 ~4 ~37 stone 5
fill ~26 ~4 ~38 ~27 ~4 ~38 bedrock 0
fill ~26 ~4 ~39 ~27 ~4 ~39 bedrock 0
fill ~26 ~4 ~40 ~27 ~4 ~40 bedrock 0
fill ~26 ~4 ~41 ~26 ~4 ~44 cobblestone 0
fill ~26 ~4 ~45 ~26 ~4 ~52 stonebrick 0
fill ~27 ~4 ~21 ~34 ~4 ~21 stonebrick 0
fill ~27 ~4 ~28 ~28 ~4 ~28 cobblestone 0
fill ~27 ~4 ~29 ~27 ~4 ~28 cobblestone 0
fill ~27 ~4 ~31 ~28 ~4 ~31 bedrock 0
fill ~27 ~4 ~32 ~28 ~4 ~32 bedrock 0
fill ~27 ~4 ~33 ~28 ~4 ~33 bedrock 0
fill ~27 ~4 ~41 ~28 ~4 ~41 bedrock 0
fill ~27 ~4 ~42 ~28 ~4 ~42 bedrock 0
fill ~27 ~4 ~43 ~28 ~4 ~43 bedrock 0
fill ~27 ~4 ~44 ~27 ~4 ~46 cobblestone 0
fill ~27 ~4 ~47 ~27 ~4 ~53 stonebrick 0
fill ~28 ~4 ~27 ~29 ~4 ~27 cobblestone 0
fill ~28 ~4 ~29 ~29 ~4 ~29 bedrock 0
fill ~28 ~4 ~30 ~29 ~4 ~30 bedrock 0
fill ~28 ~4 ~34 ~28 ~4 ~36 cobblestone 0
fill ~28 ~4 ~38 ~28 ~4 ~40 cobblestone 0
fill ~28 ~4 ~44 ~29 ~4 ~44 bedrock 0
fill ~28 ~4 ~46 ~28 ~4 ~47 cobblestone 0
fill ~28 ~4 ~48 ~28 ~4 ~53 stonebrick 0
fill ~29 ~4 ~24 ~29 ~13 ~24 water 0
fill ~29 ~4 ~26 ~30 ~4 ~26 cobblestone 0
fill ~29 ~4 ~28 ~30 ~4 ~28 bedrock 0
fill ~29 ~4 ~31 ~29 ~4 ~33 cobblestone 0
fill ~29 ~4 ~34 ~30 ~4 ~34 stonebrick 0
fill ~29 ~4 ~35 ~30 ~4 ~35 stonebrick 0
fill ~29 ~4 ~36 ~30 ~4 ~36 stonebrick 0
fill ~29 ~4 ~38 ~30 ~4 ~38 stonebrick 0
fill ~29 ~4 ~39 ~30 ~4 ~39 stonebrick 0
fill ~29 ~4 ~40 ~30 ~4 ~40 stonebrick 0
fill ~29 ~4 ~41 ~29 ~4 ~43 cobblestone 0
fill ~29 ~4 ~45 ~29 ~4 ~46 bedrock 0
fill ~29 ~4 ~47 ~29 ~4 ~48 cobblestone 0
setblock ~29 ~4 ~49 stonebrick 0
fill ~29 ~4 ~50 ~29 ~12 ~50 water 8
fill ~29 ~4 ~51 ~31 ~4 ~51 stonebrick 0
fill ~29 ~4 ~52 ~32 ~4 ~52 stonebrick 0
fill ~29 ~4 ~53 ~34 ~4 ~53 stonebrick 0
setblock ~30 ~4 ~24 stonebrick 0
fill ~30 ~4 ~25 ~31 ~4 ~25 cobblestone 0
fill ~30 ~4 ~27 ~31 ~4 ~27 bedrock 0
fill ~30 ~4 ~29 ~31 ~4 ~29 cobblestone 0
fill ~30 ~4 ~30 ~30 ~4 ~29 cobblestone 0
fill ~30 ~4 ~31 ~31 ~4 ~31 stonebrick 0
fill ~30 ~4 ~32 ~31 ~4 ~32 stonebrick 0
fill ~30 ~4 ~33 ~30 ~4 ~31 stonebrick 0
fill ~30 ~4 ~41 ~30 ~4 ~43 stonebrick 0
fill ~30 ~4 ~44 ~30 ~4 ~45 cobblestone 0
fill ~30 ~4 ~46 ~30 ~4 ~47 bedrock 0
fill ~30 ~4 ~48 ~30 ~4 ~49 cobblestone 0
setblock ~30 ~4 ~50 stonebrick 0
fill ~31 ~4 ~24 ~32 ~4 ~24 cobblestone 0
fill ~31 ~4 ~26 ~32 ~4 ~26 bedrock 0
setblock ~31 ~4 ~28 cobblestone 0
fill ~31 ~4 ~30 ~32 ~4 ~30 stonebrick 0
fill ~31 ~4 ~33 ~31 ~4 ~40 stone_sts 0
setblock ~31 ~4 ~41 stone_sts 3
fill ~31 ~4 ~42 ~31 ~4 ~44 stonebrick 0
fill ~31 ~4 ~45 ~31 ~4 ~46 cobblestone 0
fill ~31 ~4 ~47 ~31 ~4 ~48 bedrock 0
fill ~31 ~4 ~49 ~31 ~4 ~50 cobblestone 0
fill ~32 ~4 ~23 ~33 ~4 ~23 cobblestone 0
fill ~32 ~4 ~25 ~33 ~4 ~25 bedrock 0
setblock ~32 ~4 ~27 cobblestone 0
fill ~32 ~4 ~28 ~34 ~4 ~28 stonebrick 0
fill ~32 ~4 ~29 ~33 ~4 ~29 stonebrick 0
fill ~32 ~4 ~31 ~32 ~4 ~32 stone_sts 0
setblock ~32 ~4 ~33 stone_sts 2
fill ~32 ~4 ~34 ~33 ~4 ~34 stonebrick 0
fill ~32 ~4 ~35 ~33 ~4 ~35 stonebrick 0
fill ~32 ~4 ~36 ~33 ~4 ~36 stonebrick 0
fill ~32 ~4 ~37 ~33 ~4 ~37 stone 5
fill ~32 ~4 ~38 ~33 ~4 ~38 stonebrick 0
fill ~32 ~4 ~39 ~33 ~4 ~39 stonebrick 0
fill ~32 ~4 ~40 ~33 ~4 ~40 stonebrick 0
fill ~32 ~4 ~41 ~32 ~4 ~42 stone_sts 0
setblock ~32 ~4 ~43 stone_sts 3
fill ~32 ~4 ~44 ~32 ~4 ~46 stonebrick 0
setblock ~32 ~4 ~47 cobblestone 0
fill ~32 ~4 ~48 ~32 ~4 ~49 bedrock 0
fill ~32 ~4 ~50 ~32 ~4 ~51 cobblestone 0
fill ~33 ~4 ~6 ~34 ~4 ~6 stonebrick 0
fill ~33 ~4 ~7 ~33 ~4 ~14 stonebrick 0
fill ~33 ~4 ~20 ~37 ~4 ~20 stonebrick 0
fill ~33 ~4 ~22 ~35 ~4 ~22 cobblestone 0
fill ~33 ~4 ~24 ~35 ~4 ~24 bedrock 0
fill ~33 ~4 ~26 ~34 ~4 ~26 cobblestone 0
fill ~33 ~4 ~27 ~35 ~4 ~27 stonebrick 0
setblock ~33 ~4 ~30 stone_sts 0
setblock ~33 ~4 ~31 stone_sts 2
fill ~33 ~4 ~32 ~34 ~4 ~32 stonebrick 0
fill ~33 ~4 ~33 ~34 ~4 ~33 stonebrick 0
fill ~33 ~4 ~41 ~34 ~4 ~41 stonebrick 0
fill ~33 ~4 ~42 ~34 ~4 ~42 stonebrick 0
setblock ~33 ~4 ~43 stone_sts 0
setblock ~33 ~4 ~44 stone_sts 3
fill ~33 ~4 ~45 ~33 ~4 ~47 stonebrick 0
fill ~33 ~4 ~48 ~34 ~4 ~48 cobblestone 0
fill ~33 ~4 ~49 ~33 ~4 ~50 bedrock 0
fill ~33 ~4 ~51 ~33 ~4 ~52 cobblestone 0
fill ~33 ~4 ~54 ~37 ~4 ~54 stonebrick 0
fill ~33 ~4 ~60 ~34 ~4 ~60 stonebrick 0
fill ~33 ~4 ~61 ~33 ~4 ~68 stonebrick 0
fill ~34 ~4 ~4 ~35 ~4 ~4 stonebrick 0
fill ~34 ~4 ~5 ~34 ~4 ~4 stonebrick 0
fill ~34 ~4 ~7 ~34 ~4 ~13 stone_sts 1
fill ~34 ~4 ~14 ~34 ~4 ~16 stonebrick 0
fill ~34 ~4 ~23 ~38 ~4 ~23 bedrock 0
fill ~34 ~4 ~25 ~35 ~4 ~25 cobblestone 0
setblock ~34 ~4 ~29 stone_sts 0
setblock ~34 ~4 ~30 stone_sts 2
fill ~34 ~4 ~31 ~35 ~4 ~31 stonebrick 0
fill ~34 ~4 ~34 ~34 ~4 ~40 stone_sts 1
fill ~34 ~4 ~43 ~35 ~4 ~43 stonebrick 0
setblock ~34 ~4 ~44 stone_sts 0
setblock ~34 ~4 ~45 stone_sts 3
fill ~34 ~4 ~46 ~34 ~4 ~47 stonebrick 0
fill ~34 ~4 ~49 ~35 ~4 ~49 cobblestone 0
fill ~34 ~4 ~50 ~35 ~4 ~50 bedrock 0
fill ~34 ~4 ~51 ~38 ~4 ~51 bedrock 0
fill ~34 ~4 ~52 ~35 ~4 ~52 cobblestone 0
fill ~34 ~4 ~58 ~35 ~4 ~58 stonebrick 0
fill ~34 ~4 ~59 ~34 ~4 ~58 stonebrick 0
fill ~34 ~4 ~61 ~34 ~4 ~67 stone_sts 1
fill ~34 ~4 ~68 ~34 ~4 ~70 stonebrick 0
fill ~35 ~4 ~3 ~36 ~4 ~3 stonebrick 0
fill ~35 ~4 ~5 ~35 ~4 ~6 stone_sts 1
setblock ~35 ~4 ~7 stone_sts 3
fill ~35 ~4 ~8 ~36 ~4 ~8 stonebrick 0
fill ~35 ~4 ~9 ~36 ~4 ~9 stonebrick 0
fill ~35 ~4 ~10 ~38 ~4 ~10 stone 5
fill ~35 ~4 ~11 ~36 ~4 ~11 stonebrick 0
fill ~35 ~4 ~12 ~36 ~4 ~12 stonebrick 0
setblock ~35 ~4 ~13 stone_sts 2
setblock ~35 ~4 ~14 stone_sts 1
setblock ~35 ~4 ~15 stone_sts 2
fill ~35 ~4 ~16 ~35 ~4 ~17 stonebrick 0
fill ~35 ~4 ~21 ~38 ~4 ~21 cobblestone 0
fill ~35 ~4 ~26 ~37 ~4 ~26 stonebrick 0
setblock ~35 ~4 ~28 stone_sts 0
setblock ~35 ~4 ~29 stone_sts 2
fill ~35 ~4 ~30 ~36 ~4 ~30 stonebrick 0
fill ~35 ~4 ~32 ~35 ~4 ~33 stone_sts 1
setblock ~35 ~4 ~34 stone_sts 3
fill ~35 ~4 ~35 ~35 ~4 ~36 stonebrick 0
fill ~35 ~4 ~37 ~38 ~4 ~37 stone 5
fill ~35 ~4 ~38 ~35 ~4 ~39 stonebrick 0
setblock ~35 ~4 ~40 stone_sts 2
setblock ~35 ~4 ~41 stone_sts 1
setblock ~35 ~4 ~42 stone_sts 2
fill ~35 ~4 ~44 ~36 ~4 ~44 stonebrick 0
setblock ~35 ~4 ~45 stone_sts 0
setblock ~35 ~4 ~46 stone_sts 3
fill ~35 ~4 ~47 ~35 ~4 ~48 stonebrick 0
fill ~35 ~4 ~53 ~38 ~4 ~53 cobblestone 0
fill ~35 ~4 ~57 ~36 ~4 ~57 stonebrick 0
fill ~35 ~4 ~59 ~35 ~4 ~60 stone_sts 1
setblock ~35 ~4 ~61 stone_sts 3
fill ~35 ~4 ~62 ~36 ~4 ~62 stonebrick 0
fill ~35 ~4 ~63 ~36 ~4 ~63 stonebrick 0
fill ~35 ~4 ~64 ~38 ~4 ~64 stone 5
fill ~35 ~4 ~65 ~36 ~4 ~65 stonebrick 0
fill ~35 ~4 ~66 ~36 ~4 ~66 stonebrick 0
setblock ~35 ~4 ~67 stone_sts 2
setblock ~35 ~4 ~68 stone_sts 1
setblock ~35 ~4 ~69 stone_sts 2
fill ~35 ~4 ~70 ~35 ~4 ~71 stonebrick 0
fill ~36 ~4 ~2 ~38 ~4 ~2 stonebrick 0
setblock ~36 ~4 ~4 stone_sts 1
setblock ~36 ~4 ~5 stone_sts 3
fill ~36 ~4 ~6 ~37 ~4 ~6 stonebrick 0
fill ~36 ~4 ~7 ~37 ~4 ~7 stonebrick 0
fill ~36 ~4 ~13 ~37 ~4 ~13 stonebrick 0
fill ~36 ~4 ~14 ~37 ~4 ~14 stonebrick 0
setblock ~36 ~4 ~15 stone_sts 1
setblock ~36 ~4 ~16 stone_sts 2
fill ~36 ~4 ~17 ~36 ~4 ~18 stonebrick 0
fill ~36 ~4 ~22 ~41 ~4 ~22 bedrock 0
fill ~36 ~4 ~24 ~38 ~4 ~24 cobblestone 0
fill ~36 ~4 ~25 ~41 ~4 ~25 stonebrick 0
setblock ~36 ~4 ~27 stone_sts 0
setblock ~36 ~4 ~28 stone_sts 2
fill ~36 ~4 ~29 ~38 ~4 ~29 stonebrick 0
setblock ~36 ~4 ~31 stone_sts 1
setblock ~36 ~4 ~32 stone_sts 3
fill ~36 ~4 ~33 ~36 ~4 ~34 stonebrick 0
fill ~36 ~4 ~35 ~36 ~4 ~36 diamond_ore 0
fill ~36 ~4 ~38 ~36 ~4 ~39 diamond_ore 0
fill ~36 ~4 ~40 ~36 ~4 ~41 stonebrick 0
setblock ~36 ~4 ~42 stone_sts 1
setblock ~36 ~4 ~43 stone_sts 2
fill ~36 ~4 ~45 ~38 ~4 ~45 stonebrick 0
setblock ~36 ~4 ~46 stone_sts 0
fill ~36 ~4 ~47 ~37 ~4 ~47 stone_sts 3
fill ~36 ~4 ~48 ~37 ~4 ~48 stonebrick 0
fill ~36 ~4 ~49 ~41 ~4 ~49 stonebrick 0
fill ~36 ~4 ~50 ~38 ~4 ~50 cobblestone 0
fill ~36 ~4 ~52 ~41 ~4 ~52 bedrock 0
fill ~36 ~4 ~56 ~38 ~4 ~56 stonebrick 0
setblock ~36 ~4 ~58 stone_sts 1
setblock ~36 ~4 ~59 stone_sts 3
fill ~36 ~4 ~60 ~37 ~4 ~60 stonebrick 0
fill ~36 ~4 ~61 ~37 ~4 ~61 stonebrick 0
fill ~36 ~4 ~67 ~37 ~4 ~67 stonebrick 0
fill ~36 ~4 ~68 ~37 ~4 ~68 stonebrick 0
setblock ~36 ~4 ~70 stone_sts 2
fill ~36 ~4 ~71 ~36 ~4 ~72 stonebrick 0
setblock ~37 ~4 ~3 stone_sts 1
setblock ~37 ~4 ~4 stone_sts 3
fill ~37 ~4 ~5 ~39 ~4 ~5 stonebrick 0
fill ~37 ~4 ~8 ~39 ~4 ~8 lapis_block 0
fill ~37 ~4 ~9 ~40 ~4 ~9 lapis_block 0
fill ~37 ~4 ~11 ~40 ~4 ~11 lapis_block 0
fill ~37 ~4 ~12 ~39 ~4 ~12 lapis_block 0
fill ~37 ~4 ~15 ~39 ~4 ~15 stonebrick 0
setblock ~37 ~4 ~16 stone_sts 1
fill ~37 ~4 ~17 ~38 ~4 ~17 stone_sts 2
fill ~37 ~4 ~18 ~38 ~4 ~18 stonebrick 0
fill ~37 ~4 ~19 ~37 ~4 ~18 stonebrick 0
fill ~37 ~4 ~27 ~38 ~4 ~27 stone_sts 2
fill ~37 ~4 ~28 ~41 ~4 ~28 stonebrick 0
setblock ~37 ~4 ~30 stone_sts 1
setblock ~37 ~4 ~31 stone_sts 3
setblock ~37 ~4 ~32 sea_lantern 0
fill ~37 ~4 ~33 ~37 ~4 ~34 diamond_ore 0
fill ~37 ~4 ~35 ~39 ~4 ~35 lapis_block 0
fill ~37 ~4 ~36 ~40 ~4 ~36 lapis_block 0
fill ~37 ~4 ~38 ~40 ~4 ~38 lapis_block 0
fill ~37 ~4 ~39 ~39 ~4 ~39 lapis_block 0
fill ~37 ~4 ~40 ~37 ~4 ~41 diamond_ore 0
setblock ~37 ~4 ~42 sea_lantern 0
setblock ~37 ~4 ~43 stone_sts 1
fill ~37 ~4 ~44 ~38 ~4 ~44 stone_sts 2
fill ~37 ~4 ~46 ~41 ~4 ~46 stonebrick 0
fill ~37 ~4 ~55 ~47 ~4 ~55 stonebrick 0
setblock ~37 ~4 ~57 stone_sts 1
setblock ~37 ~4 ~58 stone_sts 3
fill ~37 ~4 ~59 ~39 ~4 ~59 stonebrick 0
fill ~37 ~4 ~62 ~39 ~4 ~62 lapis_block 0
fill ~37 ~4 ~63 ~40 ~4 ~63 lapis_block 0
fill ~37 ~4 ~65 ~40 ~4 ~65 lapis_block 0
fill ~37 ~4 ~66 ~39 ~4 ~66 lapis_block 0
fill ~37 ~4 ~69 ~39 ~4 ~69 stonebrick 0
setblock ~37 ~4 ~70 stone_sts 1
fill ~37 ~4 ~71 ~38 ~4 ~71 stone_sts 2
fill ~37 ~4 ~72 ~38 ~4 ~72 stonebrick 0
fill ~38 ~4 ~1 ~46 ~4 ~1 stonebrick 0
setblock ~38 ~4 ~3 stone_sts 3
fill ~38 ~4 ~4 ~41 ~4 ~4 stonebrick 0
fill ~38 ~4 ~6 ~39 ~4 ~6 wool 3
fill ~38 ~4 ~7 ~39 ~4 ~7 wool 3
fill ~38 ~4 ~13 ~39 ~4 ~13 wool 3
fill ~38 ~4 ~14 ~39 ~4 ~14 wool 3
fill ~38 ~4 ~16 ~41 ~4 ~16 stonebrick 0
setblock ~38 ~4 ~19 glowstone 0
fill ~38 ~4 ~20 ~46 ~4 ~20 cobblestone 0
setblock ~38 ~4 ~26 stone_sts 0
setblock ~38 ~4 ~30 stone_sts 3
fill ~38 ~4 ~31 ~39 ~4 ~31 stonebrick 0
fill ~38 ~4 ~32 ~39 ~4 ~32 diamond_ore 0
fill ~38 ~4 ~33 ~39 ~4 ~33 wool 3
fill ~38 ~4 ~34 ~39 ~4 ~34 wool 3
fill ~38 ~4 ~40 ~39 ~4 ~40 wool 3
fill ~38 ~4 ~41 ~39 ~4 ~41 wool 3
fill ~38 ~4 ~42 ~39 ~4 ~42 diamond_ore 0
fill ~38 ~4 ~43 ~39 ~4 ~43 stonebrick 0
setblock ~38 ~4 ~47 stone_sts 0
fill ~38 ~4 ~48 ~45 ~4 ~48 stone_sts 3
setblock ~38 ~4 ~54 glowstone 0
fill ~38 ~4 ~58 ~41 ~4 ~58 stonebrick 0
fill ~38 ~4 ~60 ~39 ~4 ~60 wool 3
fill ~38 ~4 ~61 ~39 ~4 ~61 wool 3
fill ~38 ~4 ~67 ~39 ~4 ~67 wool 3
fill ~38 ~4 ~68 ~39 ~4 ~68 wool 3
fill ~38 ~4 ~70 ~41 ~4 ~70 stonebrick 0
fill ~38 ~4 ~73 ~46 ~4 ~73 stonebrick 0
fill ~39 ~4 ~2 ~45 ~4 ~2 stone_sts 3
setblock ~39 ~4 ~3 stone_sts 1
setblock ~39 ~4 ~10 stone_sts 0
setblock ~39 ~4 ~17 stone_sts 1
fill ~39 ~4 ~18 ~45 ~4 ~18 stone_sts 2
fill ~39 ~4 ~19 ~45 ~4 ~19 stonebrick 0
fill ~39 ~4 ~21 ~41 ~4 ~21 bedrock 0
fill ~39 ~4 ~23 ~41 ~4 ~23 cobblestone 0
fill ~39 ~4 ~24 ~41 ~4 ~24 stonebrick 0
fill ~39 ~4 ~26 ~46 ~4 ~26 stone_sts 2
fill ~39 ~4 ~27 ~41 ~4 ~27 stonebrick 0
fill ~39 ~4 ~29 ~45 ~4 ~29 stone_sts 3
setblock ~39 ~4 ~30 stone_sts 1
setblock ~39 ~4 ~37 stone_sts 0
setblock ~39 ~4 ~44 stone_sts 1
fill ~39 ~4 ~45 ~45 ~4 ~45 stone_sts 2
fill ~39 ~4 ~47 ~41 ~4 ~47 stonebrick 0
fill ~39 ~4 ~50 ~41 ~4 ~50 stonebrick 0
fill ~39 ~4 ~51 ~41 ~4 ~51 cobblestone 0
fill ~39 ~4 ~53 ~41 ~4 ~53 bedrock 0
fill ~39 ~4 ~54 ~45 ~4 ~54 cobblestone 0
fill ~39 ~4 ~56 ~45 ~4 ~56 stone_sts 3
setblock ~39 ~4 ~57 stone_sts 1
setblock ~39 ~4 ~64 stone_sts 0
setblock ~39 ~4 ~71 stone_sts 1
fill ~39 ~4 ~72 ~45 ~4 ~72 stone_sts 2
fill ~40 ~4 ~3 ~41 ~4 ~3 stonebrick 0
fill ~40 ~4 ~5 ~41 ~4 ~5 lapis_block 0
fill ~40 ~4 ~6 ~41 ~4 ~6 lapis_block 0
fill ~40 ~4 ~7 ~41 ~4 ~7 lapis_block 0
setblock ~40 ~4 ~8 wool 3
setblock ~40 ~4 ~10 stonebrick 0
setblock ~40 ~4 ~12 wool 3
fill ~40 ~4 ~13 ~41 ~4 ~13 lapis_block 0
fill ~40 ~4 ~14 ~41 ~4 ~14 lapis_block 0
fill ~40 ~4 ~15 ~41 ~4 ~15 lapis_block 0
fill ~40 ~4 ~17 ~41 ~4 ~17 stonebrick 0
fill ~40 ~4 ~30 ~41 ~4 ~30 stonebrick 0
fill ~40 ~4 ~31 ~41 ~4 ~31 diamond_ore 0
fill ~40 ~4 ~32 ~41 ~4 ~32 lapis_block 0
fill ~40 ~4 ~33 ~41 ~4 ~33 lapis_block 0
fill ~40 ~4 ~34 ~41 ~4 ~34 lapis_block 0
setblock ~40 ~4 ~35 wool 3
setblock ~40 ~4 ~37 stonebrick 0
setblock ~40 ~4 ~39 wool 3
fill ~40 ~4 ~40 ~41 ~4 ~40 lapis_block 0
fill ~40 ~4 ~41 ~41 ~4 ~41 lapis_block 0
fill ~40 ~4 ~42 ~41 ~4 ~42 lapis_block 0
fill ~40 ~4 ~43 ~41 ~4 ~43 diamond_ore 0
fill ~40 ~4 ~44 ~41 ~4 ~44 stonebrick 0
fill ~40 ~4 ~57 ~41 ~4 ~57 stonebrick 0
fill ~40 ~4 ~59 ~41 ~4 ~59 lapis_block 0
fill ~40 ~4 ~60 ~41 ~4 ~60 lapis_block 0
fill ~40 ~4 ~61 ~41 ~4 ~61 lapis_block 0
setblock ~40 ~4 ~62 wool 3
setblock ~40 ~4 ~64 stonebrick 0
setblock ~40 ~4 ~66 wool 3
fill ~40 ~4 ~67 ~41 ~4 ~67 lapis_block 0
fill ~40 ~4 ~68 ~41 ~4 ~68 lapis_block 0
fill ~40 ~4 ~69 ~41 ~4 ~69 lapis_block 0
fill ~40 ~4 ~71 ~41 ~4 ~71 stonebrick 0
setblock ~41 ~4 ~8 lapis_block 0
setblock ~41 ~4 ~9 wool 3
setblock ~41 ~4 ~10 stone_sts 0
setblock ~41 ~4 ~11 wool 3
setblock ~41 ~4 ~12 lapis_block 0
setblock ~41 ~4 ~35 lapis_block 0
setblock ~41 ~4 ~36 wool 3
setblock ~41 ~4 ~37 stone_sts 1
setblock ~41 ~4 ~38 wool 3
setblock ~41 ~4 ~39 lapis_block 0
setblock ~41 ~4 ~62 lapis_block 0
setblock ~41 ~4 ~63 wool 3
setblock ~41 ~4 ~64 stone_sts 0
setblock ~41 ~4 ~65 wool 3
setblock ~41 ~4 ~66 lapis_block 0
fill ~42 ~4 ~3 ~42 ~4 ~6 stone 5
setblock ~42 ~4 ~7 stone_sts 2
setblock ~42 ~4 ~8 stonebrick 0
setblock ~42 ~4 ~9 stone_sts 2
setblock ~42 ~4 ~10 iron_trapdoor 9
setblock ~42 ~4 ~11 stone_sts 3
setblock ~42 ~4 ~12 stonebrick 0
setblock ~42 ~4 ~13 stone_sts 3
fill ~42 ~4 ~14 ~42 ~4 ~17 stone 5
fill ~42 ~4 ~21 ~42 ~4 ~25 stone 5
fill ~42 ~4 ~27 ~42 ~4 ~28 stone 5
fill ~42 ~4 ~30 ~42 ~4 ~33 stone 5
setblock ~42 ~4 ~34 stone_sts 2
setblock ~42 ~4 ~35 stonebrick 0
setblock ~42 ~4 ~36 stone_sts 3
setblock ~42 ~4 ~37 sea_lantern 0
setblock ~42 ~4 ~38 stone_sts 2
setblock ~42 ~4 ~39 stonebrick 0
setblock ~42 ~4 ~40 stone_sts 3
fill ~42 ~4 ~41 ~42 ~4 ~44 stone 5
fill ~42 ~4 ~46 ~42 ~4 ~47 stone 5
fill ~42 ~4 ~49 ~42 ~4 ~53 stone 5
fill ~42 ~4 ~57 ~42 ~4 ~60 stone 5
setblock ~42 ~4 ~61 stone_sts 2
setblock ~42 ~4 ~62 stonebrick 0
setblock ~42 ~4 ~63 stone_sts 2
setblock ~42 ~4 ~64 iron_trapdoor 8
setblock ~42 ~4 ~65 stone_sts 3
setblock ~42 ~4 ~66 stonebrick 0
setblock ~42 ~4 ~67 stone_sts 3
fill ~42 ~4 ~68 ~42 ~4 ~71 stone 5
fill ~43 ~4 ~3 ~44 ~4 ~3 stonebrick 0
fill ~43 ~4 ~4 ~46 ~4 ~4 stonebrick 0
fill ~43 ~4 ~5 ~44 ~4 ~5 lapis_block 0
fill ~43 ~4 ~6 ~44 ~4 ~6 lapis_block 0
fill ~43 ~4 ~7 ~44 ~4 ~7 lapis_block 0
fill ~43 ~4 ~8 ~43 ~4 ~5 lapis_block 0
setblock ~43 ~4 ~9 wool 3
setblock ~43 ~4 ~10 stone_sts 1
setblock ~43 ~4 ~11 wool 3
fill ~43 ~4 ~12 ~43 ~4 ~15 lapis_block 0
fill ~43 ~4 ~16 ~46 ~4 ~16 stonebrick 0
fill ~43 ~4 ~17 ~44 ~4 ~17 stonebrick 0
fill ~43 ~4 ~21 ~45 ~4 ~21 bedrock 0
fill ~43 ~4 ~22 ~48 ~4 ~22 bedrock 0
fill ~43 ~4 ~23 ~45 ~4 ~23 cobblestone 0
fill ~43 ~4 ~24 ~45 ~4 ~24 stonebrick 0
fill ~43 ~4 ~25 ~48 ~4 ~25 stonebrick 0
fill ~43 ~4 ~27 ~45 ~4 ~27 stonebrick 0
fill ~43 ~4 ~28 ~47 ~4 ~28 stonebrick 0
fill ~43 ~4 ~30 ~44 ~4 ~30 stonebrick 0
fill ~43 ~4 ~31 ~44 ~4 ~31 diamond_ore 0
fill ~43 ~4 ~32 ~44 ~4 ~32 lapis_block 0
fill ~43 ~4 ~33 ~44 ~4 ~33 lapis_block 0
fill ~43 ~4 ~34 ~44 ~4 ~34 lapis_block 0
fill ~43 ~4 ~35 ~43 ~4 ~32 lapis_block 0
setblock ~43 ~4 ~36 wool 3
setblock ~43 ~4 ~37 stone_sts 0
setblock ~43 ~4 ~38 wool 3
fill ~43 ~4 ~39 ~43 ~4 ~42 lapis_block 0
fill ~43 ~4 ~43 ~44 ~4 ~43 diamond_ore 0
fill ~43 ~4 ~44 ~44 ~4 ~44 stonebrick 0
fill ~43 ~4 ~46 ~47 ~4 ~46 stonebrick 0
fill ~43 ~4 ~47 ~45 ~4 ~47 stonebrick 0
fill ~43 ~4 ~49 ~48 ~4 ~49 stonebrick 0
fill ~43 ~4 ~50 ~45 ~4 ~50 stonebrick 0
fill ~43 ~4 ~51 ~45 ~4 ~51 cobblestone 0
fill ~43 ~4 ~52 ~48 ~4 ~52 bedrock 0
fill ~43 ~4 ~53 ~45 ~4 ~53 bedrock 0
fill ~43 ~4 ~57 ~44 ~4 ~57 stonebrick 0
fill ~43 ~4 ~58 ~46 ~4 ~58 stonebrick 0
fill ~43 ~4 ~59 ~44 ~4 ~59 lapis_block 0
fill ~43 ~4 ~60 ~44 ~4 ~60 lapis_block 0
fill ~43 ~4 ~61 ~44 ~4 ~61 lapis_block 0
fill ~43 ~4 ~62 ~43 ~4 ~59 lapis_block 0
setblock ~43 ~4 ~63 wool 3
setblock ~43 ~4 ~64 stone_sts 1
setblock ~43 ~4 ~65 wool 3
fill ~43 ~4 ~66 ~43 ~4 ~69 lapis_block 0
fill ~43 ~4 ~70 ~46 ~4 ~70 stonebrick 0
fill ~43 ~4 ~71 ~44 ~4 ~71 stonebrick 0
setblock ~44 ~4 ~8 wool 3
fill ~44 ~4 ~9 ~47 ~4 ~9 lapis_block 0
setblock ~44 ~4 ~10 stonebrick 0
fill ~44 ~4 ~11 ~47 ~4 ~11 lapis_block 0
setblock ~44 ~4 ~12 wool 3
fill ~44 ~4 ~13 ~44 ~4 ~15 lapis_block 0
setblock ~44 ~4 ~35 wool 3
fill ~44 ~4 ~36 ~47 ~4 ~36 lapis_block 0
setblock ~44 ~4 ~37 stonebrick 0
fill ~44 ~4 ~38 ~47 ~4 ~38 lapis_block 0
setblock ~44 ~4 ~39 wool 3
fill ~44 ~4 ~40 ~44 ~4 ~42 lapis_block 0
setblock ~44 ~4 ~62 wool 3
fill ~44 ~4 ~63 ~47 ~4 ~63 lapis_block 0
setblock ~44 ~4 ~64 stonebrick 0
fill ~44 ~4 ~65 ~47 ~4 ~65 lapis_block 0
setblock ~44 ~4 ~66 wool 3
fill ~44 ~4 ~67 ~44 ~4 ~69 lapis_block 0
setblock ~45 ~4 ~3 stone_sts 0
fill ~45 ~4 ~5 ~47 ~4 ~5 stonebrick 0
fill ~45 ~4 ~6 ~46 ~4 ~6 wool 3
fill ~45 ~4 ~7 ~46 ~4 ~7 wool 3
fill ~45 ~4 ~8 ~47 ~4 ~8 lapis_block 0
setblock ~45 ~4 ~10 stone_sts 1
fill ~45 ~4 ~12 ~47 ~4 ~12 lapis_block 0
fill ~45 ~4 ~13 ~46 ~4 ~13 wool 3
fill ~45 ~4 ~14 ~46 ~4 ~14 wool 3
fill ~45 ~4 ~15 ~47 ~4 ~15 stonebrick 0
setblock ~45 ~4 ~17 stone_sts 0
setblock ~45 ~4 ~30 stone_sts 0
fill ~45 ~4 ~31 ~46 ~4 ~31 stonebrick 0
fill ~45 ~4 ~32 ~46 ~4 ~32 diamond_ore 0
fill ~45 ~4 ~33 ~46 ~4 ~33 wool 3
fill ~45 ~4 ~34 ~46 ~4 ~34 wool 3
fill ~45 ~4 ~35 ~47 ~4 ~35 lapis_block 0
setblock ~45 ~4 ~37 stone_sts 1
fill ~45 ~4 ~39 ~47 ~4 ~39 lapis_block 0
fill ~45 ~4 ~40 ~46 ~4 ~40 wool 3
fill ~45 ~4 ~41 ~46 ~4 ~41 wool 3
fill ~45 ~4 ~42 ~46 ~4 ~42 diamond_ore 0
fill ~45 ~4 ~43 ~46 ~4 ~43 stonebrick 0
setblock ~45 ~4 ~44 stone_sts 0
setblock ~45 ~4 ~57 stone_sts 0
fill ~45 ~4 ~59 ~47 ~4 ~59 stonebrick 0
fill ~45 ~4 ~60 ~46 ~4 ~60 wool 3
fill ~45 ~4 ~61 ~46 ~4 ~61 wool 3
fill ~45 ~4 ~62 ~47 ~4 ~62 lapis_block 0
setblock ~45 ~4 ~64 stone_sts 1
fill ~45 ~4 ~66 ~47 ~4 ~66 lapis_block 0
fill ~45 ~4 ~67 ~46 ~4 ~67 wool 3
fill ~45 ~4 ~68 ~46 ~4 ~68 wool 3
fill ~45 ~4 ~69 ~47 ~4 ~69 stonebrick 0
fill ~46 ~4 ~2 ~48 ~4 ~2 stonebrick 0
fill ~46 ~4 ~3 ~47 ~4 ~3 stone_sts 3
fill ~46 ~4 ~10 ~49 ~4 ~10 stone 5
setblock ~46 ~4 ~17 stone_sts 2
fill ~46 ~4 ~18 ~48 ~4 ~18 stonebrick 0
setblock ~46 ~4 ~19 glowstone 0
setblock ~46 ~4 ~21 cobblestone 0
fill ~46 ~4 ~23 ~50 ~4 ~23 bedrock 0
fill ~46 ~4 ~24 ~48 ~4 ~24 cobblestone 0
setblock ~46 ~4 ~27 stone_sts 1
fill ~46 ~4 ~29 ~48 ~4 ~29 stonebrick 0
fill ~46 ~4 ~30 ~47 ~4 ~30 stone_sts 3
fill ~46 ~4 ~37 ~49 ~4 ~37 stone 5
setblock ~46 ~4 ~44 stone_sts 2
fill ~46 ~4 ~45 ~48 ~4 ~45 stonebrick 0
fill ~46 ~4 ~47 ~47 ~4 ~47 stone_sts 3
setblock ~46 ~4 ~48 stone_sts 1
fill ~46 ~4 ~50 ~48 ~4 ~50 cobblestone 0
fill ~46 ~4 ~51 ~50 ~4 ~51 bedrock 0
fill ~46 ~4 ~53 ~49 ~4 ~53 cobblestone 0
setblock ~46 ~4 ~54 glowstone 0
fill ~46 ~4 ~56 ~48 ~4 ~56 stonebrick 0
fill ~46 ~4 ~57 ~47 ~4 ~57 stone_sts 3
fill ~46 ~4 ~64 ~49 ~4 ~64 stone 5
setblock ~46 ~4 ~71 stone_sts 2
fill ~46 ~4 ~72 ~48 ~4 ~72 stonebrick 0
setblock ~47 ~4 ~4 stone_sts 0
fill ~47 ~4 ~6 ~48 ~4 ~6 stonebrick 0
fill ~47 ~4 ~7 ~48 ~4 ~7 stonebrick 0
fill ~47 ~4 ~13 ~48 ~4 ~13 stonebrick 0
fill ~47 ~4 ~14 ~48 ~4 ~14 stonebrick 0
setblock ~47 ~4 ~16 stone_sts 2
setblock ~47 ~4 ~17 stone_sts 0
fill ~47 ~4 ~19 ~47 ~4 ~20 stonebrick 0
fill ~47 ~4 ~26 ~49 ~4 ~26 stonebrick 0
fill ~47 ~4 ~27 ~48 ~4 ~27 stone_sts 2
setblock ~47 ~4 ~31 stone_sts 0
setblock ~47 ~4 ~32 sea_lantern 0
fill ~47 ~4 ~33 ~47 ~4 ~34 diamond_ore 0
fill ~47 ~4 ~40 ~47 ~4 ~41 diamond_ore 0
setblock ~47 ~4 ~42 sea_lantern 0
setblock ~47 ~4 ~43 stone_sts 2
setblock ~47 ~4 ~44 stone_sts 0
fill ~47 ~4 ~48 ~49 ~4 ~48 stonebrick 0
fill ~47 ~4 ~54 ~51 ~4 ~54 stonebrick 0
setblock ~47 ~4 ~58 stone_sts 0
fill ~47 ~4 ~60 ~48 ~4 ~60 stonebrick 0
fill ~47 ~4 ~61 ~48 ~4 ~61 stonebrick 0
fill ~47 ~4 ~67 ~48 ~4 ~67 stonebrick 0
fill ~47 ~4 ~68 ~48 ~4 ~68 stonebrick 0
setblock ~47 ~4 ~70 stone_sts 2
setblock ~47 ~4 ~71 stone_sts 0
fill ~48 ~4 ~3 ~49 ~4 ~3 stonebrick 0
setblock ~48 ~4 ~4 stone_sts 3
setblock ~48 ~4 ~5 stone_sts 0
fill ~48 ~4 ~8 ~49 ~4 ~8 stonebrick 0
fill ~48 ~4 ~9 ~49 ~4 ~9 stonebrick 0
fill ~48 ~4 ~11 ~49 ~4 ~11 stonebrick 0
fill ~48 ~4 ~12 ~49 ~4 ~12 stonebrick 0
setblock ~48 ~4 ~15 stone_sts 2
setblock ~48 ~4 ~16 stone_sts 0
fill ~48 ~4 ~17 ~49 ~4 ~17 stonebrick 0
fill ~48 ~4 ~20 ~51 ~4 ~20 stonebrick 0
fill ~48 ~4 ~21 ~49 ~4 ~21 cobblestone 0
setblock ~48 ~4 ~28 stone_sts 1
fill ~48 ~4 ~30 ~49 ~4 ~30 stonebrick 0
setblock ~48 ~4 ~31 stone_sts 3
setblock ~48 ~4 ~32 stone_sts 0
fill ~48 ~4 ~33 ~48 ~4 ~34 stonebrick 0
fill ~48 ~4 ~35 ~48 ~4 ~36 diamond_ore 0
fill ~48 ~4 ~38 ~48 ~4 ~39 diamond_ore 0
fill ~48 ~4 ~40 ~48 ~4 ~41 stonebrick 0
setblock ~48 ~4 ~42 stone_sts 2
setblock ~48 ~4 ~43 stone_sts 0
fill ~48 ~4 ~44 ~49 ~4 ~44 stonebrick 0
setblock ~48 ~4 ~46 stone_sts 3
setblock ~48 ~4 ~47 stone_sts 1
fill ~48 ~4 ~57 ~49 ~4 ~57 stonebrick 0
setblock ~48 ~4 ~58 stone_sts 3
setblock ~48 ~4 ~59 stone_sts 0
fill ~48 ~4 ~62 ~49 ~4 ~62 stonebrick 0
fill ~48 ~4 ~63 ~49 ~4 ~63 stonebrick 0
fill ~48 ~4 ~65 ~49 ~4 ~65 stonebrick 0
fill ~48 ~4 ~66 ~49 ~4 ~66 stonebrick 0
setblock ~48 ~4 ~69 stone_sts 2
setblock ~48 ~4 ~70 stone_sts 0
fill ~48 ~4 ~71 ~49 ~4 ~71 stonebrick 0
fill ~49 ~4 ~4 ~50 ~4 ~4 stonebrick 0
setblock ~49 ~4 ~5 stone_sts 3
setblock ~49 ~4 ~6 stone_sts 0
setblock ~49 ~4 ~7 stone_sts 3
setblock ~49 ~4 ~13 stone_sts 2
fill ~49 ~4 ~14 ~49 ~4 ~15 stone_sts 0
fill ~49 ~4 ~16 ~50 ~4 ~16 stonebrick 0
fill ~49 ~4 ~22 ~51 ~4 ~22 cobblestone 0
fill ~49 ~4 ~24 ~51 ~4 ~24 bedrock 0
fill ~49 ~4 ~25 ~50 ~4 ~25 cobblestone 0
fill ~49 ~4 ~27 ~51 ~4 ~27 stonebrick 0
setblock ~49 ~4 ~28 stone_sts 2
setblock ~49 ~4 ~29 stone_sts 1
fill ~49 ~4 ~31 ~50 ~4 ~31 stonebrick 0
setblock ~49 ~4 ~32 stone_sts 3
setblock ~49 ~4 ~33 stone_sts 0
setblock ~49 ~4 ~34 stone_sts 3
fill ~49 ~4 ~35 ~49 ~4 ~36 stonebrick 0
fill ~49 ~4 ~38 ~49 ~4 ~39 stonebrick 0
setblock ~49 ~4 ~40 stone_sts 2
fill ~49 ~4 ~41 ~49 ~4 ~42 stone_sts 0
fill ~49 ~4 ~43 ~50 ~4 ~43 stonebrick 0
setblock ~49 ~4 ~45 stone_sts 3
setblock ~49 ~4 ~46 stone_sts 1
fill ~49 ~4 ~47 ~51 ~4 ~47 stonebrick 0
fill ~49 ~4 ~49 ~50 ~4 ~49 cobblestone 0
fill ~49 ~4 ~50 ~51 ~4 ~50 bedrock 0
fill ~49 ~4 ~52 ~51 ~4 ~52 cobblestone 0
fill ~49 ~4 ~58 ~50 ~4 ~58 stonebrick 0
setblock ~49 ~4 ~59 stone_sts 3
setblock ~49 ~4 ~60 stone_sts 0
setblock ~49 ~4 ~61 stone_sts 3
setblock ~49 ~4 ~67 stone_sts 2
fill ~49 ~4 ~68 ~49 ~4 ~69 stone_sts 0
fill ~49 ~4 ~70 ~50 ~4 ~70 stonebrick 0
fill ~50 ~4 ~5 ~50 ~4 ~6 stonebrick 0
fill ~50 ~4 ~7 ~50 ~4 ~13 stone_sts 0
fill ~50 ~4 ~14 ~51 ~4 ~14 stonebrick 0
fill ~50 ~4 ~15 ~50 ~4 ~14 stonebrick 0
fill ~50 ~4 ~21 ~57 ~4 ~21 stonebrick 0
fill ~50 ~4 ~26 ~51 ~4 ~26 cobblestone 0
fill ~50 ~4 ~28 ~52 ~4 ~28 stonebrick 0
setblock ~50 ~4 ~29 stone_sts 2
setblock ~50 ~4 ~30 stone_sts 1
fill ~50 ~4 ~32 ~51 ~4 ~32 stonebrick 0
fill ~50 ~4 ~33 ~51 ~4 ~33 stonebrick 0
fill ~50 ~4 ~34 ~50 ~4 ~40 stone_sts 0
fill ~50 ~4 ~41 ~51 ~4 ~41 stonebrick 0
fill ~50 ~4 ~42 ~51 ~4 ~42 stonebrick 0
setblock ~50 ~4 ~44 stone_sts 3
setblock ~50 ~4 ~45 stone_sts 1
fill ~50 ~4 ~46 ~52 ~4 ~46 stonebrick 0
fill ~50 ~4 ~48 ~51 ~4 ~48 cobblestone 0
fill ~50 ~4 ~53 ~57 ~4 ~53 stonebrick 0
fill ~50 ~4 ~59 ~50 ~4 ~60 stonebrick 0
fill ~50 ~4 ~61 ~50 ~4 ~67 stone_sts 0
fill ~50 ~4 ~68 ~51 ~4 ~68 stonebrick 0
fill ~50 ~4 ~69 ~50 ~4 ~68 stonebrick 0
fill ~51 ~4 ~6 ~51 ~4 ~14 stonebrick 0
fill ~51 ~4 ~23 ~52 ~4 ~23 cobblestone 0
fill ~51 ~4 ~25 ~52 ~4 ~25 bedrock 0
fill ~51 ~4 ~29 ~52 ~4 ~29 stonebrick 0
setblock ~51 ~4 ~30 stone_sts 2
setblock ~51 ~4 ~31 stone_sts 1
fill ~51 ~4 ~34 ~52 ~4 ~34 stonebrick 0
fill ~51 ~4 ~35 ~52 ~4 ~35 stonebrick 0
fill ~51 ~4 ~36 ~52 ~4 ~36 stonebrick 0
fill ~51 ~4 ~37 ~52 ~4 ~37 stone 5
fill ~51 ~4 ~38 ~52 ~4 ~38 stonebrick 0
fill ~51 ~4 ~39 ~52 ~4 ~39 stonebrick 0
fill ~51 ~4 ~40 ~52 ~4 ~40 stonebrick 0
setblock ~51 ~4 ~43 stone_sts 3
setblock ~51 ~4 ~44 stone_sts 1
fill ~51 ~4 ~45 ~52 ~4 ~45 stonebrick 0
fill ~51 ~4 ~49 ~52 ~4 ~49 bedrock 0
fill ~51 ~4 ~51 ~52 ~4 ~51 cobblestone 0
fill ~51 ~4 ~60 ~51 ~4 ~68 stonebrick 0
fill ~52 ~4 ~22 ~58 ~4 ~22 stonebrick 0
fill ~52 ~4 ~24 ~53 ~4 ~24 cobblestone 0
fill ~52 ~4 ~26 ~53 ~4 ~26 bedrock 0
setblock ~52 ~4 ~27 cobblestone 0
fill ~52 ~4 ~30 ~53 ~4 ~30 stonebrick 0
setblock ~52 ~4 ~31 stone_sts 2
fill ~52 ~4 ~32 ~52 ~4 ~33 stone_sts 1
setblock ~52 ~4 ~41 stone_sts 3
fill ~52 ~4 ~42 ~52 ~4 ~43 stone_sts 1
fill ~52 ~4 ~44 ~53 ~4 ~44 stonebrick 0
setblock ~52 ~4 ~47 cobblestone 0
fill ~52 ~4 ~48 ~53 ~4 ~48 bedrock 0
fill ~52 ~4 ~50 ~53 ~4 ~50 cobblestone 0
fill ~52 ~4 ~52 ~58 ~4 ~52 stonebrick 0
fill ~53 ~4 ~23 ~58 ~4 ~23 stonebrick 0
fill ~53 ~4 ~25 ~54 ~4 ~25 cobblestone 0
fill ~53 ~4 ~27 ~54 ~4 ~27 bedrock 0
fill ~53 ~4 ~28 ~53 ~4 ~29 cobblestone 0
fill ~53 ~4 ~31 ~54 ~4 ~31 stonebrick 0
fill ~53 ~4 ~32 ~54 ~4 ~32 stonebrick 0
setblock ~53 ~4 ~33 stone_sts 2
fill ~53 ~4 ~34 ~53 ~4 ~41 stone_sts 1
fill ~53 ~4 ~42 ~54 ~4 ~42 stonebrick 0
fill ~53 ~4 ~43 ~54 ~4 ~43 stonebrick 0
fill ~53 ~4 ~45 ~54 ~4 ~45 cobblestone 0
fill ~53 ~4 ~46 ~53 ~4 ~45 cobblestone 0
fill ~53 ~4 ~47 ~54 ~4 ~47 bedrock 0
fill ~53 ~4 ~49 ~54 ~4 ~49 cobblestone 0
fill ~53 ~4 ~51 ~58 ~4 ~51 stonebrick 0
setblock ~54 ~4 ~24 stonebrick 0
fill ~54 ~4 ~26 ~55 ~4 ~26 cobblestone 0
fill ~54 ~4 ~28 ~55 ~4 ~28 bedrock 0
fill ~54 ~4 ~29 ~54 ~4 ~30 cobblestone 0
fill ~54 ~4 ~33 ~54 ~4 ~36 stonebrick 0
fill ~54 ~4 ~37 ~58 ~4 ~37 stone 5
fill ~54 ~4 ~38 ~55 ~4 ~38 stonebrick 0
fill ~54 ~4 ~39 ~55 ~4 ~39 stonebrick 0
fill ~54 ~4 ~40 ~55 ~4 ~40 stonebrick 0
fill ~54 ~4 ~41 ~54 ~4 ~38 stonebrick 0
setblock ~54 ~4 ~44 cobblestone 0
fill ~54 ~4 ~46 ~55 ~4 ~46 bedrock 0
fill ~54 ~4 ~48 ~55 ~4 ~48 cobblestone 0
setblock ~54 ~4 ~50 stonebrick 0
fill ~55 ~4 ~24 ~55 ~12 ~24 water 8
fill ~55 ~4 ~25 ~58 ~4 ~25 stonebrick 0
fill ~55 ~4 ~27 ~56 ~4 ~27 cobblestone 0
fill ~55 ~4 ~29 ~56 ~4 ~29 bedrock 0
fill ~55 ~4 ~30 ~56 ~4 ~30 bedrock 0
fill ~55 ~4 ~31 ~55 ~4 ~33 cobblestone 0
fill ~55 ~4 ~34 ~55 ~4 ~36 stonebrick 0
fill ~55 ~4 ~41 ~55 ~4 ~43 cobblestone 0
fill ~55 ~4 ~44 ~56 ~4 ~44 bedrock 0
fill ~55 ~4 ~45 ~56 ~4 ~45 bedrock 0
fill ~55 ~4 ~47 ~56 ~4 ~47 cobblestone 0
fill ~55 ~4 ~49 ~58 ~4 ~49 stonebrick 0
fill ~55 ~4 ~50 ~55 ~12 ~50 water 8
fill ~56 ~4 ~24 ~58 ~4 ~24 stonebrick 0
fill ~56 ~4 ~26 ~58 ~4 ~26 stonebrick 0
fill ~56 ~4 ~28 ~57 ~4 ~28 cobblestone 0
fill ~56 ~4 ~31 ~57 ~4 ~31 bedrock 0
fill ~56 ~4 ~32 ~57 ~4 ~32 bedrock 0
fill ~56 ~4 ~33 ~57 ~4 ~33 bedrock 0
fill ~56 ~4 ~34 ~56 ~4 ~36 cobblestone 0
fill ~56 ~4 ~38 ~56 ~4 ~40 cobblestone 0
fill ~56 ~4 ~41 ~57 ~4 ~41 bedrock 0
fill ~56 ~4 ~42 ~57 ~4 ~42 bedrock 0
fill ~56 ~4 ~43 ~57 ~4 ~43 bedrock 0
fill ~56 ~4 ~46 ~57 ~4 ~46 cobblestone 0
fill ~56 ~4 ~48 ~58 ~4 ~48 stonebrick 0
fill ~56 ~4 ~50 ~58 ~4 ~50 stonebrick 0
fill ~57 ~4 ~27 ~58 ~4 ~27 stonebrick 0
fill ~57 ~4 ~29 ~57 ~4 ~30 cobblestone 0
fill ~57 ~4 ~34 ~58 ~4 ~34 bedrock 0
fill ~57 ~4 ~35 ~58 ~4 ~35 bedrock 0
fill ~57 ~4 ~36 ~58 ~4 ~36 bedrock 0
fill ~57 ~4 ~38 ~58 ~4 ~38 bedrock 0
fill ~57 ~4 ~39 ~58 ~4 ~39 bedrock 0
fill ~57 ~4 ~40 ~58 ~4 ~40 bedrock 0
fill ~57 ~4 ~44 ~58 ~4 ~44 cobblestone 0
fill ~57 ~4 ~45 ~57 ~4 ~44 cobblestone 0
fill ~57 ~4 ~47 ~58 ~4 ~47 stonebrick 0
fill ~58 ~4 ~28 ~59 ~4 ~28 stonebrick 0
fill ~58 ~4 ~29 ~59 ~4 ~29 stonebrick 0
fill ~58 ~4 ~30 ~58 ~4 ~33 cobblestone 0
fill ~58 ~4 ~41 ~59 ~4 ~41 cobblestone 0
fill ~58 ~4 ~42 ~58 ~4 ~44 cobblestone 0
fill ~58 ~4 ~45 ~59 ~4 ~45 stonebrick 0
fill ~58 ~4 ~46 ~59 ~4 ~46 stonebrick 0
fill ~59 ~4 ~30 ~59 ~4 ~32 stonebrick 0
fill ~59 ~4 ~33 ~59 ~4 ~41 cobblestone 0
fill ~59 ~4 ~42 ~61 ~4 ~42 stonebrick 0
fill ~59 ~4 ~43 ~59 ~4 ~46 stonebrick 0
fill ~60 ~4 ~32 ~61 ~4 ~32 stonebrick 0
setblock ~60 ~4 ~33 glowstone 0
fill ~60 ~4 ~34 ~60 ~4 ~40 stonebrick 0
setblock ~60 ~4 ~41 glowstone 0
fill ~61 ~4 ~31 ~62 ~4 ~31 stonebrick 0
setblock ~61 ~4 ~33 stonebrick 0
fill ~61 ~4 ~34 ~61 ~4 ~40 stone_sts 1
setblock ~61 ~4 ~41 stonebrick 0
fill ~61 ~4 ~43 ~62 ~4 ~43 stonebrick 0
fill ~62 ~4 ~30 ~63 ~4 ~30 stonebrick 0
fill ~62 ~4 ~32 ~62 ~4 ~33 stone_sts 1
setblock ~62 ~4 ~34 stone_sts 3
fill ~62 ~4 ~35 ~63 ~4 ~35 stonebrick 0
fill ~62 ~4 ~36 ~63 ~4 ~36 stonebrick 0
fill ~62 ~4 ~37 ~65 ~4 ~37 stone 5
fill ~62 ~4 ~38 ~63 ~4 ~38 stonebrick 0
fill ~62 ~4 ~39 ~63 ~4 ~39 stonebrick 0
setblock ~62 ~4 ~40 stone_sts 2
setblock ~62 ~4 ~41 stone_sts 1
setblock ~62 ~4 ~42 stone_sts 2
fill ~62 ~4 ~44 ~63 ~4 ~44 stonebrick 0
fill ~63 ~4 ~29 ~65 ~4 ~29 stonebrick 0
setblock ~63 ~4 ~31 stone_sts 1
setblock ~63 ~4 ~32 stone_sts 3
fill ~63 ~4 ~33 ~64 ~4 ~33 stonebrick 0
fill ~63 ~4 ~34 ~64 ~4 ~34 stonebrick 0
fill ~63 ~4 ~40 ~64 ~4 ~40 stonebrick 0
fill ~63 ~4 ~41 ~64 ~4 ~41 stonebrick 0
setblock ~63 ~4 ~42 stone_sts 1
setblock ~63 ~4 ~43 stone_sts 2
fill ~63 ~4 ~45 ~65 ~4 ~45 stonebrick 0
setblock ~64 ~4 ~30 stone_sts 1
setblock ~64 ~4 ~31 stone_sts 3
fill ~64 ~4 ~32 ~66 ~4 ~32 stonebrick 0
fill ~64 ~4 ~35 ~66 ~4 ~35 lapis_block 0
fill ~64 ~4 ~36 ~67 ~4 ~36 lapis_block 0
fill ~64 ~4 ~38 ~67 ~4 ~38 lapis_block 0
fill ~64 ~4 ~39 ~66 ~4 ~39 lapis_block 0
fill ~64 ~4 ~42 ~66 ~4 ~42 stonebrick 0
setblock ~64 ~4 ~43 stone_sts 1
fill ~64 ~4 ~44 ~65 ~4 ~44 stone_sts 2
fill ~65 ~4 ~28 ~73 ~4 ~28 stonebrick 0
setblock ~65 ~4 ~30 stone_sts 3
fill ~65 ~4 ~31 ~68 ~4 ~31 stonebrick 0
fill ~65 ~4 ~33 ~66 ~4 ~33 wool 3
fill ~65 ~4 ~34 ~66 ~4 ~34 wool 3
fill ~65 ~4 ~40 ~66 ~4 ~40 wool 3
fill ~65 ~4 ~41 ~66 ~4 ~41 wool 3
fill ~65 ~4 ~43 ~68 ~4 ~43 stonebrick 0
fill ~65 ~4 ~46 ~73 ~4 ~46 stonebrick 0
fill ~66 ~4 ~29 ~72 ~4 ~29 stone_sts 3
setblock ~66 ~4 ~30 stone_sts 1
setblock ~66 ~4 ~37 stone_sts 0
setblock ~66 ~4 ~44 stone_sts 1
fill ~66 ~4 ~45 ~72 ~4 ~45 stone_sts 2
setblock ~67 ~4 ~30 stonebrick 0
fill ~67 ~4 ~32 ~68 ~4 ~32 lapis_block 0
fill ~67 ~4 ~33 ~68 ~4 ~33 lapis_block 0
fill ~67 ~4 ~34 ~68 ~4 ~34 lapis_block 0
setblock ~67 ~4 ~35 wool 3
setblock ~67 ~4 ~37 stonebrick 0
setblock ~67 ~4 ~39 wool 3
fill ~67 ~4 ~40 ~68 ~4 ~40 lapis_block 0
fill ~67 ~4 ~41 ~68 ~4 ~41 lapis_block 0
fill ~67 ~4 ~42 ~68 ~4 ~42 lapis_block 0
setblock ~67 ~4 ~44 stonebrick 0
fill ~68 ~4 ~11 ~77 ~4 ~11 leaves2 1
fill ~68 ~4 ~12 ~76 ~4 ~12 leaves2 1
fill ~68 ~4 ~13 ~70 ~4 ~13 leaves2 1
fill ~68 ~4 ~14 ~70 ~4 ~14 leaves2 1
fill ~68 ~4 ~15 ~75 ~4 ~15 leaves2 1
fill ~68 ~4 ~30 ~69 ~4 ~30 glowstone 0
setblock ~68 ~4 ~35 lapis_block 0
setblock ~68 ~4 ~36 wool 3
setblock ~68 ~4 ~37 stone_sts 0
setblock ~68 ~4 ~38 wool 3
setblock ~68 ~4 ~39 lapis_block 0
fill ~68 ~4 ~44 ~69 ~4 ~44 glowstone 0
fill ~69 ~4 ~10 ~73 ~4 ~10 leaves2 1
fill ~69 ~4 ~16 ~73 ~4 ~16 leaves2 1
fill ~69 ~4 ~17 ~73 ~4 ~17 leaves2 1
fill ~69 ~4 ~31 ~69 ~4 ~33 stone 5
setblock ~69 ~4 ~34 stone_sts 2
setblock ~69 ~4 ~35 stonebrick 0
setblock ~69 ~4 ~36 stone_sts 2
setblock ~69 ~4 ~37 iron_trapdoor 10
setblock ~69 ~4 ~38 stone_sts 3
setblock ~69 ~4 ~39 stonebrick 0
setblock ~69 ~4 ~40 stone_sts 3
fill ~69 ~4 ~41 ~69 ~4 ~43 stone 5
fill ~70 ~4 ~30 ~71 ~4 ~30 stonebrick 0
fill ~70 ~4 ~31 ~73 ~4 ~31 stonebrick 0
fill ~70 ~4 ~32 ~71 ~4 ~32 lapis_block 0
fill ~70 ~4 ~33 ~71 ~4 ~33 lapis_block 0
fill ~70 ~4 ~34 ~71 ~4 ~34 lapis_block 0
fill ~70 ~4 ~35 ~70 ~4 ~32 lapis_block 0
setblock ~70 ~4 ~36 wool 3
setblock ~70 ~4 ~37 stone_sts 1
setblock ~70 ~4 ~38 wool 3
fill ~70 ~4 ~39 ~70 ~4 ~42 lapis_block 0
fill ~70 ~4 ~43 ~73 ~4 ~43 stonebrick 0
fill ~70 ~4 ~44 ~71 ~4 ~44 stonebrick 0
fill ~71 ~4 ~13 ~72 ~4 ~13 air
fill ~71 ~4 ~14 ~72 ~4 ~14 air
setblock ~71 ~4 ~35 wool 3
fill ~71 ~4 ~36 ~74 ~4 ~36 lapis_block 0
setblock ~71 ~4 ~37 stonebrick 0
fill ~71 ~4 ~38 ~74 ~4 ~38 lapis_block 0
setblock ~71 ~4 ~39 wool 3
fill ~71 ~4 ~40 ~71 ~4 ~42 lapis_block 0
setblock ~72 ~4 ~30 stone_sts 0
fill ~72 ~4 ~32 ~74 ~4 ~32 stonebrick 0
fill ~72 ~4 ~33 ~73 ~4 ~33 wool 3
fill ~72 ~4 ~34 ~73 ~4 ~34 wool 3
fill ~72 ~4 ~35 ~74 ~4 ~35 lapis_block 0
setblock ~72 ~4 ~37 stone_sts 1
fill ~72 ~4 ~39 ~74 ~4 ~39 lapis_block 0
fill ~72 ~4 ~40 ~73 ~4 ~40 wool 3
fill ~72 ~4 ~41 ~73 ~4 ~41 wool 3
fill ~72 ~4 ~42 ~74 ~4 ~42 stonebrick 0
setblock ~72 ~4 ~44 stone_sts 0
fill ~73 ~4 ~13 ~77 ~4 ~13 leaves2 1
fill ~73 ~4 ~14 ~79 ~4 ~14 leaves2 1
fill ~73 ~4 ~29 ~75 ~4 ~29 stonebrick 0
fill ~73 ~4 ~30 ~74 ~4 ~30 stone_sts 3
fill ~73 ~4 ~37 ~76 ~4 ~37 stone 5
setblock ~73 ~4 ~44 stone_sts 2
fill ~73 ~4 ~45 ~75 ~4 ~45 stonebrick 0
setblock ~74 ~4 ~31 stone_sts 0
fill ~74 ~4 ~33 ~75 ~4 ~33 stonebrick 0
fill ~74 ~4 ~34 ~75 ~4 ~34 stonebrick 0
fill ~74 ~4 ~40 ~75 ~4 ~40 stonebrick 0
fill ~74 ~4 ~41 ~75 ~4 ~41 stonebrick 0
setblock ~74 ~4 ~43 stone_sts 2
setblock ~74 ~4 ~44 stone_sts 0
fill ~75 ~4 ~1 ~79 ~4 ~1 leaves2 1
fill ~75 ~4 ~2 ~79 ~4 ~2 leaves2 1
fill ~75 ~4 ~3 ~77 ~4 ~3 leaves2 1
fill ~75 ~4 ~4 ~77 ~4 ~4 leaves2 1
fill ~75 ~4 ~5 ~79 ~4 ~5 leaves2 1
fill ~75 ~4 ~30 ~76 ~4 ~30 stonebrick 0
setblock ~75 ~4 ~31 stone_sts 3
setblock ~75 ~4 ~32 stone_sts 0
fill ~75 ~4 ~35 ~76 ~4 ~35 stonebrick 0
fill ~75 ~4 ~36 ~76 ~4 ~36 stonebrick 0
fill ~75 ~4 ~38 ~76 ~4 ~38 stonebrick 0
fill ~75 ~4 ~39 ~76 ~4 ~39 stonebrick 0
setblock ~75 ~4 ~42 stone_sts 2
setblock ~75 ~4 ~43 stone_sts 0
fill ~75 ~4 ~44 ~76 ~4 ~44 stonebrick 0
fill ~76 ~4 ~0 ~77 ~4 ~0 leaves2 1
fill ~76 ~4 ~6 ~79 ~4 ~6 leaves2 1
fill ~76 ~4 ~7 ~79 ~4 ~7 leaves2 1
fill ~76 ~4 ~9 ~79 ~4 ~9 leaves2 1
fill ~76 ~4 ~10 ~79 ~4 ~10 leaves2 1
fill ~76 ~4 ~31 ~77 ~4 ~31 stonebrick 0
setblock ~76 ~4 ~32 stone_sts 3
setblock ~76 ~4 ~33 stone_sts 0
setblock ~76 ~4 ~34 stone_sts 3
setblock ~76 ~4 ~40 stone_sts 2
fill ~76 ~4 ~41 ~76 ~4 ~42 stone_sts 0
fill ~76 ~4 ~43 ~77 ~4 ~43 stonebrick 0
fill ~77 ~4 ~12 ~79 ~4 ~12 air
fill ~77 ~4 ~15 ~79 ~4 ~15 leaves2 1
fill ~77 ~4 ~32 ~77 ~4 ~33 stonebrick 0
fill ~77 ~4 ~34 ~77 ~4 ~40 stone_sts 0
fill ~77 ~4 ~41 ~78 ~4 ~41 stonebrick 0
fill ~77 ~4 ~42 ~77 ~4 ~41 stonebrick 0
fill ~78 ~4 ~3 ~79 ~4 ~3 air
fill ~78 ~4 ~4 ~79 ~4 ~4 air
fill ~78 ~4 ~11 ~79 ~4 ~11 air
fill ~78 ~4 ~33 ~78 ~4 ~41 stonebrick 0
fill ~79 ~4 ~13 ~79 ~6 ~13 leaves2 1
fill ~1 ~5 ~0 ~1 ~4 ~0 leaves2 1
fill ~1 ~5 ~1 ~1 ~4 ~1 leaves2 1
fill ~6 ~5 ~33 ~6 ~5 ~40 stone_brick_sts 1
setblock ~6 ~5 ~41 stone_brick_sts 2
fill ~7 ~5 ~31 ~7 ~5 ~32 stone_brick_sts 1
setblock ~7 ~5 ~33 stone_brick_sts 3
fill ~7 ~5 ~41 ~7 ~5 ~42 stone_brick_sts 1
setblock ~7 ~5 ~43 stone_brick_sts 2
setblock ~8 ~5 ~30 stone_brick_sts 1
setblock ~8 ~5 ~31 stone_brick_sts 3
setblock ~8 ~5 ~43 stone_brick_sts 1
setblock ~8 ~5 ~44 stone_brick_sts 2
setblock ~9 ~5 ~29 stone_brick_sts 1
setblock ~9 ~5 ~30 stone_brick_sts 3
setblock ~9 ~5 ~33 lapis_block 0
setblock ~9 ~5 ~35 lapis_block 0
setblock ~9 ~5 ~37 lapis_block 0
setblock ~9 ~5 ~39 lapis_block 0
setblock ~9 ~5 ~41 lapis_block 0
setblock ~9 ~5 ~44 stone_brick_sts 1
fill ~9 ~5 ~45 ~10 ~5 ~45 stone_brick_sts 2
fill ~10 ~5 ~29 ~11 ~5 ~29 stone_brick_sts 3
setblock ~11 ~5 ~28 stone_brick_sts 1
setblock ~11 ~5 ~45 stone_brick_sts 1
fill ~11 ~5 ~46 ~18 ~5 ~46 stone_brick_sts 2
fill ~12 ~5 ~28 ~19 ~5 ~28 stone_brick_sts 3
setblock ~13 ~5 ~31 lapis_block 0
setblock ~13 ~5 ~43 lapis_block 0
setblock ~15 ~5 ~31 lapis_block 0
setblock ~15 ~5 ~43 lapis_block 0
setblock ~17 ~5 ~31 lapis_block 0
setblock ~17 ~5 ~43 lapis_block 0
setblock ~19 ~5 ~29 stone_brick_sts 0
fill ~19 ~5 ~45 ~20 ~5 ~45 stone_brick_sts 2
setblock ~19 ~5 ~46 stone_brick_sts 0
fill ~20 ~5 ~29 ~21 ~5 ~29 stone_brick_sts 3
setblock ~21 ~5 ~30 stone_brick_sts 0
setblock ~21 ~5 ~44 stone_brick_sts 2
setblock ~21 ~5 ~45 stone_brick_sts 0
setblock ~22 ~5 ~30 stone_brick_sts 3
setblock ~22 ~5 ~31 stone_brick_sts 0
setblock ~22 ~5 ~43 stone_brick_sts 2
setblock ~22 ~5 ~44 stone_brick_sts 0
setblock ~23 ~5 ~31 stone_brick_sts 3
setblock ~23 ~5 ~32 stone_brick_sts 0
fill ~23 ~5 ~42 ~24 ~5 ~42 stone_brick_sts 2
setblock ~23 ~5 ~43 stone_brick_sts 0
fill ~24 ~5 ~32 ~25 ~5 ~32 stone_brick_sts 3
setblock ~25 ~5 ~23 stone_sts 0
fill ~25 ~5 ~28 ~25 ~5 ~31 stone_brick_sts 1
fill ~25 ~5 ~42 ~25 ~5 ~45 stone_brick_sts 1
setblock ~25 ~5 ~46 stone_brick_sts 2
setblock ~25 ~5 ~51 stone_sts 0
fill ~26 ~5 ~22 ~26 ~13 ~22 cobblestone_wall 0
fill ~26 ~5 ~23 ~27 ~5 ~23 stonebrick 0
fill ~26 ~5 ~24 ~26 ~13 ~24 cobblestone_wall 0
setblock ~26 ~5 ~25 stone_brick_sts 3
fill ~26 ~5 ~26 ~26 ~5 ~27 stone_brick_sts 1
setblock ~26 ~5 ~28 stone_brick_sts 3
fill ~26 ~5 ~46 ~26 ~5 ~48 stone_brick_sts 1
setblock ~26 ~5 ~49 stone_brick_sts 2
fill ~26 ~5 ~50 ~26 ~13 ~50 cobblestone_wall 0
fill ~26 ~5 ~51 ~30 ~5 ~51 stonebrick 0
fill ~26 ~5 ~52 ~26 ~13 ~52 cobblestone_wall 0
fill ~27 ~5 ~21 ~27 ~13 ~21 cobblestone_wall 0
fill ~27 ~5 ~22 ~27 ~16 ~22 stonebrick 0
fill ~27 ~5 ~24 ~28 ~5 ~24 stonebrick 0
fill ~27 ~5 ~25 ~27 ~13 ~25 cobblestone_wall 0
fill ~27 ~5 ~49 ~27 ~13 ~49 cobblestone_wall 0
fill ~27 ~5 ~50 ~28 ~5 ~50 stonebrick 0
fill ~27 ~5 ~52 ~29 ~5 ~52 stonebrick 0
fill ~27 ~5 ~53 ~27 ~9 ~53 cobblestone_wall 0
setblock ~28 ~5 ~20 stone_sts 2
fill ~28 ~5 ~21 ~28 ~14 ~21 stonebrick 0
fill ~28 ~5 ~25 ~28 ~7 ~25 stonebrick 0
setblock ~28 ~5 ~26 stone_sts 3
setblock ~28 ~5 ~48 stone_sts 2
fill ~28 ~5 ~49 ~28 ~16 ~49 stonebrick 0
fill ~28 ~5 ~53 ~28 ~16 ~53 stonebrick 0
setblock ~28 ~5 ~54 stone_sts 3
fill ~29 ~5 ~21 ~29 ~13 ~21 cobblestone_wall 0
fill ~29 ~5 ~22 ~29 ~16 ~22 stonebrick 0
fill ~29 ~5 ~23 ~30 ~5 ~23 stonebrick 0
fill ~29 ~5 ~25 ~29 ~13 ~25 cobblestone_wall 0
fill ~29 ~5 ~49 ~29 ~13 ~49 cobblestone_wall 0
fill ~29 ~5 ~53 ~29 ~13 ~53 cobblestone_wall 0
setblock ~30 ~5 ~21 stone_brick_sts 1
fill ~30 ~5 ~22 ~30 ~13 ~22 cobblestone_wall 0
fill ~30 ~5 ~24 ~30 ~13 ~24 cobblestone_wall 0
fill ~30 ~5 ~27 ~30 ~8 ~27 cobblestone_wall 0
fill ~30 ~5 ~47 ~30 ~8 ~47 cobblestone_wall 0
fill ~30 ~5 ~50 ~30 ~13 ~50 cobblestone_wall 0
fill ~30 ~5 ~52 ~30 ~13 ~52 cobblestone_wall 0
setblock ~30 ~5 ~53 stone_brick_sts 1
fill ~31 ~5 ~21 ~32 ~5 ~21 stone_brick_sts 3
setblock ~31 ~5 ~23 stone_sts 1
setblock ~31 ~5 ~51 stone_sts 1
fill ~31 ~5 ~53 ~33 ~5 ~53 stone_brick_sts 2
fill ~32 ~5 ~25 ~32 ~8 ~25 cobblestone_wall 0
fill ~32 ~5 ~49 ~32 ~8 ~49 cobblestone_wall 0
setblock ~33 ~5 ~6 stone_brick_sts 3
fill ~33 ~5 ~7 ~33 ~5 ~14 stone_brick_sts 1
fill ~33 ~5 ~20 ~36 ~5 ~20 stone_brick_sts 3
setblock ~33 ~5 ~21 stone_brick_sts 1
setblock ~33 ~5 ~54 stone_brick_sts 1
setblock ~33 ~5 ~60 stone_brick_sts 3
fill ~33 ~5 ~61 ~33 ~5 ~68 stone_brick_sts 1
setblock ~34 ~5 ~4 stone_brick_sts 3
fill ~34 ~5 ~5 ~34 ~5 ~6 stone_brick_sts 1
setblock ~34 ~5 ~14 stone_brick_sts 2
fill ~34 ~5 ~15 ~34 ~5 ~16 stone_brick_sts 1
fill ~34 ~5 ~54 ~37 ~5 ~54 stone_brick_sts 2
setblock ~34 ~5 ~58 stone_brick_sts 3
fill ~34 ~5 ~59 ~34 ~5 ~60 stone_brick_sts 1
setblock ~34 ~5 ~68 stone_brick_sts 2
fill ~34 ~5 ~69 ~34 ~5 ~70 stone_brick_sts 1
setblock ~35 ~5 ~3 stone_brick_sts 3
setblock ~35 ~5 ~4 stone_brick_sts 1
setblock ~35 ~5 ~10 glowstone 0
setblock ~35 ~5 ~16 stone_brick_sts 2
setblock ~35 ~5 ~17 stone_brick_sts 1
setblock ~35 ~5 ~57 stone_brick_sts 3
setblock ~35 ~5 ~58 stone_brick_sts 1
setblock ~35 ~5 ~70 stone_brick_sts 2
setblock ~35 ~5 ~71 stone_brick_sts 1
fill ~36 ~5 ~2 ~37 ~5 ~2 stone_brick_sts 3
setblock ~36 ~5 ~3 stone_brick_sts 1
setblock ~36 ~5 ~17 stone_brick_sts 2
setblock ~36 ~5 ~18 stone_brick_sts 1
setblock ~36 ~5 ~56 stone_brick_sts 3
setblock ~36 ~5 ~57 stone_brick_sts 1
setblock ~36 ~5 ~71 stone_brick_sts 2
setblock ~36 ~5 ~72 stone_brick_sts 1
setblock ~37 ~5 ~18 stone_brick_sts 2
fill ~37 ~5 ~19 ~37 ~5 ~20 stone_brick_sts 1
setblock ~37 ~5 ~33 ender_chest 3
setblock ~37 ~5 ~41 ender_chest 2
fill ~37 ~5 ~55 ~37 ~5 ~56 stone_brick_sts 1
fill ~37 ~5 ~72 ~38 ~5 ~72 stone_brick_sts 2
fill ~38 ~5 ~1 ~45 ~5 ~1 stone_brick_sts 3
setblock ~38 ~5 ~2 stone_brick_sts 1
setblock ~38 ~5 ~5 stonebrick 3
setblock ~38 ~5 ~32 ender_chest 5
setblock ~38 ~5 ~42 ender_chest 5
setblock ~38 ~5 ~73 stone_brick_sts 1
fill ~39 ~5 ~73 ~46 ~5 ~73 stone_brick_sts 2
fill ~41 ~5 ~64 ~41 ~6 ~64 cobblestone_wall 0
setblock ~42 ~5 ~5 glowstone 0
fill ~42 ~5 ~65 ~42 ~6 ~65 cobblestone_wall 0
fill ~43 ~5 ~64 ~43 ~6 ~64 cobblestone_wall 0
setblock ~46 ~5 ~1 stone_brick_sts 0
fill ~46 ~5 ~2 ~47 ~5 ~2 stone_brick_sts 3
setblock ~46 ~5 ~5 stonebrick 3
setblock ~46 ~5 ~32 ender_chest 4
setblock ~46 ~5 ~42 ender_chest 4
setblock ~46 ~5 ~72 stone_brick_sts 0
setblock ~47 ~5 ~5 stone_brick_sts 1
fill ~47 ~5 ~18 ~47 ~5 ~19 stone_brick_sts 0
fill ~47 ~5 ~20 ~50 ~5 ~20 stone_brick_sts 3
setblock ~47 ~5 ~33 ender_chest 3
setblock ~47 ~5 ~41 ender_chest 2
fill ~47 ~5 ~54 ~47 ~5 ~55 stone_brick_sts 0
setblock ~47 ~5 ~56 stone_brick_sts 3
fill ~47 ~5 ~72 ~48 ~5 ~72 stone_brick_sts 2
setblock ~48 ~5 ~2 stone_brick_sts 0
setblock ~48 ~5 ~3 stone_brick_sts 3
setblock ~48 ~5 ~17 stone_brick_sts 0
setblock ~48 ~5 ~18 stone_brick_sts 2
fill ~48 ~5 ~54 ~51 ~5 ~54 stone_brick_sts 2
setblock ~48 ~5 ~56 stone_brick_sts 0
setblock ~48 ~5 ~57 stone_brick_sts 3
setblock ~48 ~5 ~71 stone_brick_sts 0
setblock ~49 ~5 ~3 stone_brick_sts 0
setblock ~49 ~5 ~4 stone_brick_sts 3
setblock ~49 ~5 ~10 glowstone 0
setblock ~49 ~5 ~16 stone_brick_sts 0
setblock ~49 ~5 ~17 stone_brick_sts 2
setblock ~49 ~5 ~57 stone_brick_sts 0
setblock ~49 ~5 ~58 stone_brick_sts 3
setblock ~49 ~5 ~70 stone_brick_sts 0
setblock ~49 ~5 ~71 stone_brick_sts 2
fill ~50 ~5 ~4 ~50 ~5 ~5 stone_brick_sts 0
setblock ~50 ~5 ~6 stone_brick_sts 3
fill ~50 ~5 ~14 ~51 ~5 ~14 stone_brick_sts 2
setblock ~50 ~5 ~15 stone_brick_sts 0
setblock ~50 ~5 ~16 stone_brick_sts 2
fill ~50 ~5 ~58 ~50 ~5 ~59 stone_brick_sts 0
setblock ~50 ~5 ~60 stone_brick_sts 3
fill ~50 ~5 ~68 ~50 ~5 ~69 stone_brick_sts 0
setblock ~50 ~5 ~70 stone_brick_sts 2
fill ~51 ~5 ~6 ~51 ~5 ~13 stone_brick_sts 0
setblock ~51 ~5 ~20 stone_brick_sts 0
fill ~51 ~5 ~21 ~53 ~5 ~21 stone_brick_sts 3
setblock ~51 ~5 ~53 stone_brick_sts 0
fill ~51 ~5 ~60 ~51 ~5 ~67 stone_brick_sts 0
setblock ~51 ~5 ~68 stone_brick_sts 2
fill ~52 ~5 ~25 ~52 ~8 ~25 cobblestone_wall 0
fill ~52 ~5 ~49 ~52 ~8 ~49 cobblestone_wall 0
fill ~52 ~5 ~53 ~53 ~5 ~53 stone_brick_sts 2
setblock ~53 ~5 ~23 stone_sts 0
setblock ~53 ~5 ~51 stone_sts 0
setblock ~54 ~5 ~21 stone_brick_sts 0
fill ~54 ~5 ~22 ~54 ~13 ~22 cobblestone_wall 0
fill ~54 ~5 ~23 ~58 ~5 ~23 stonebrick 0
fill ~54 ~5 ~24 ~54 ~13 ~24 cobblestone_wall 0
fill ~54 ~5 ~27 ~54 ~8 ~27 cobblestone_wall 0
fill ~54 ~5 ~47 ~54 ~8 ~47 cobblestone_wall 0
fill ~54 ~5 ~50 ~54 ~13 ~50 cobblestone_wall 0
fill ~54 ~5 ~51 ~58 ~5 ~51 stonebrick 0
fill ~54 ~5 ~52 ~54 ~13 ~52 cobblestone_wall 0
setblock ~54 ~5 ~53 stone_brick_sts 0
fill ~55 ~5 ~21 ~55 ~13 ~21 cobblestone_wall 0
fill ~55 ~5 ~22 ~57 ~5 ~22 stonebrick 0
fill ~55 ~5 ~25 ~55 ~13 ~25 cobblestone_wall 0
fill ~55 ~5 ~49 ~55 ~13 ~49 cobblestone_wall 0
fill ~55 ~5 ~52 ~57 ~5 ~52 stonebrick 0
fill ~55 ~5 ~53 ~55 ~13 ~53 cobblestone_wall 0
setblock ~56 ~5 ~20 stone_sts 2
fill ~56 ~5 ~21 ~56 ~16 ~21 stonebrick 0
fill ~56 ~5 ~24 ~57 ~5 ~24 stonebrick 0
fill ~56 ~5 ~25 ~56 ~16 ~25 stonebrick 0
setblock ~56 ~5 ~26 stone_sts 3
setblock ~56 ~5 ~48 stone_sts 2
fill ~56 ~5 ~49 ~56 ~16 ~49 stonebrick 0
fill ~56 ~5 ~50 ~57 ~5 ~50 stonebrick 0
fill ~56 ~5 ~53 ~56 ~16 ~53 stonebrick 0
setblock ~56 ~5 ~54 stone_sts 3
fill ~57 ~5 ~21 ~57 ~13 ~21 cobblestone_wall 0
fill ~57 ~5 ~25 ~57 ~13 ~25 cobblestone_wall 0
fill ~57 ~5 ~49 ~57 ~13 ~49 cobblestone_wall 0
fill ~57 ~5 ~53 ~57 ~13 ~53 cobblestone_wall 0
fill ~58 ~5 ~22 ~58 ~13 ~22 cobblestone_wall 0
fill ~58 ~5 ~24 ~58 ~13 ~24 cobblestone_wall 0
setblock ~58 ~5 ~25 stone_brick_sts 3
fill ~58 ~5 ~26 ~58 ~5 ~28 stone_brick_sts 0
setblock ~58 ~5 ~46 stone_brick_sts 2
fill ~58 ~5 ~47 ~58 ~5 ~48 stone_brick_sts 0
setblock ~58 ~5 ~49 stone_brick_sts 2
fill ~58 ~5 ~50 ~58 ~13 ~50 cobblestone_wall 0
fill ~58 ~5 ~52 ~58 ~13 ~52 cobblestone_wall 0
setblock ~59 ~5 ~23 stone_sts 1
setblock ~59 ~5 ~28 stone_brick_sts 3
fill ~59 ~5 ~29 ~59 ~5 ~32 stone_brick_sts 0
fill ~59 ~5 ~42 ~60 ~5 ~42 stone_brick_sts 2
fill ~59 ~5 ~43 ~59 ~5 ~46 stone_brick_sts 0
setblock ~59 ~5 ~51 stone_sts 1
fill ~60 ~5 ~32 ~61 ~5 ~32 stone_brick_sts 3
setblock ~61 ~5 ~31 stone_brick_sts 1
setblock ~61 ~5 ~42 stone_brick_sts 1
setblock ~61 ~5 ~43 stone_brick_sts 2
setblock ~62 ~5 ~30 stone_brick_sts 1
setblock ~62 ~5 ~31 stone_brick_sts 3
setblock ~62 ~5 ~43 stone_brick_sts 1
setblock ~62 ~5 ~44 stone_brick_sts 2
setblock ~63 ~5 ~29 stone_brick_sts 1
setblock ~63 ~5 ~30 stone_brick_sts 3
setblock ~63 ~5 ~44 stone_brick_sts 1
fill ~63 ~5 ~45 ~64 ~5 ~45 stone_brick_sts 2
fill ~64 ~5 ~29 ~65 ~5 ~29 stone_brick_sts 3
setblock ~65 ~5 ~28 stone_brick_sts 1
setblock ~65 ~5 ~45 stone_brick_sts 1
fill ~65 ~5 ~46 ~72 ~5 ~46 stone_brick_sts 2
fill ~66 ~5 ~28 ~73 ~5 ~28 stone_brick_sts 3
fill ~69 ~5 ~13 ~79 ~5 ~13 leaves2 1
fill ~69 ~5 ~14 ~74 ~5 ~14 leaves2 1
fill ~70 ~5 ~12 ~73 ~5 ~12 leaves2 1
fill ~70 ~5 ~15 ~73 ~5 ~15 leaves2 1
fill ~71 ~5 ~11 ~72 ~5 ~11 leaves2 1
fill ~71 ~5 ~16 ~72 ~5 ~16 leaves2 1
setblock ~73 ~5 ~29 stone_brick_sts 0
fill ~73 ~5 ~45 ~74 ~5 ~45 stone_brick_sts 2
setblock ~73 ~5 ~46 stone_brick_sts 0
fill ~74 ~5 ~29 ~75 ~5 ~29 stone_brick_sts 3
setblock ~74 ~5 ~34 glowstone 0
fill ~74 ~5 ~35 ~74 ~8 ~35 lapis_block 0
setblock ~74 ~5 ~36 glowstone 0
fill ~74 ~5 ~37 ~74 ~8 ~37 lapis_block 0
setblock ~74 ~5 ~38 glowstone 0
fill ~74 ~5 ~39 ~74 ~8 ~39 lapis_block 0
setblock ~74 ~5 ~40 glowstone 0
fill ~75 ~5 ~9 ~79 ~5 ~9 leaves2 1
fill ~75 ~5 ~10 ~79 ~5 ~10 leaves2 1
fill ~75 ~5 ~11 ~77 ~5 ~11 leaves2 1
fill ~75 ~5 ~12 ~77 ~5 ~12 leaves2 1
setblock ~75 ~5 ~30 stone_brick_sts 0
setblock ~75 ~5 ~44 stone_brick_sts 2
setblock ~75 ~5 ~45 stone_brick_sts 0
fill ~76 ~5 ~3 ~79 ~5 ~3 leaves2 1
fill ~76 ~5 ~4 ~79 ~5 ~4 leaves2 1
fill ~76 ~5 ~8 ~79 ~5 ~8 leaves2 1
fill ~76 ~5 ~14 ~79 ~5 ~14 leaves2 1
fill ~76 ~5 ~15 ~79 ~5 ~15 leaves2 1
setblock ~76 ~5 ~30 stone_brick_sts 3
setblock ~76 ~5 ~31 stone_brick_sts 0
setblock ~76 ~5 ~43 stone_brick_sts 2
setblock ~76 ~5 ~44 stone_brick_sts 0
fill ~77 ~5 ~2 ~79 ~5 ~2 leaves2 1
fill ~77 ~5 ~5 ~79 ~5 ~5 leaves2 1
setblock ~77 ~5 ~31 stone_brick_sts 3
fill ~77 ~5 ~32 ~77 ~5 ~33 stone_brick_sts 0
setblock ~77 ~5 ~41 stone_brick_sts 2
fill ~77 ~5 ~42 ~77 ~5 ~43 stone_brick_sts 0
fill ~78 ~5 ~1 ~79 ~5 ~1 leaves2 1
fill ~78 ~5 ~6 ~79 ~5 ~6 leaves2 1
fill ~78 ~5 ~11 ~79 ~5 ~11 air
fill ~78 ~5 ~12 ~79 ~5 ~12 air
setblock ~78 ~5 ~33 stone_brick_sts 3
fill ~78 ~5 ~34 ~78 ~5 ~41 stone_brick_sts 0
setblock ~25 ~6 ~23 cobblestone_wall 0
setblock ~25 ~6 ~51 cobblestone_wall 0
fill ~26 ~6 ~23 ~27 ~6 ~23 stonebrick 0
fill ~26 ~6 ~51 ~27 ~6 ~51 stonebrick 0
fill ~27 ~6 ~24 ~28 ~6 ~24 stonebrick 0
fill ~27 ~6 ~50 ~28 ~6 ~50 stonebrick 0
fill ~27 ~6 ~52 ~29 ~6 ~52 stonebrick 0
setblock ~28 ~6 ~20 cobblestone_wall 0
setblock ~28 ~6 ~26 cobblestone_wall 0
setblock ~28 ~6 ~48 cobblestone_wall 0
setblock ~28 ~6 ~54 cobblestone_wall 0
fill ~29 ~6 ~23 ~30 ~6 ~23 stonebrick 0
fill ~29 ~6 ~51 ~30 ~6 ~51 stonebrick 0
setblock ~31 ~6 ~23 cobblestone_wall 0
setblock ~31 ~6 ~51 cobblestone_wall 0
fill ~38 ~6 ~5 ~46 ~6 ~5 stonebrick 0
setblock ~53 ~6 ~23 cobblestone_wall 0
setblock ~53 ~6 ~51 cobblestone_wall 0
fill ~54 ~6 ~23 ~55 ~6 ~23 stonebrick 0
fill ~54 ~6 ~51 ~55 ~6 ~51 stonebrick 0
fill ~55 ~6 ~22 ~57 ~6 ~22 stonebrick 0
fill ~55 ~6 ~52 ~57 ~6 ~52 stonebrick 0
setblock ~56 ~6 ~20 cobblestone_wall 0
fill ~56 ~6 ~24 ~57 ~6 ~24 stonebrick 0
setblock ~56 ~6 ~26 cobblestone_wall 0
setblock ~56 ~6 ~48 cobblestone_wall 0
fill ~56 ~6 ~50 ~57 ~6 ~50 stonebrick 0
setblock ~56 ~6 ~54 cobblestone_wall 0
fill ~57 ~6 ~23 ~58 ~6 ~23 stonebrick 0
fill ~57 ~6 ~51 ~58 ~6 ~51 stonebrick 0
setblock ~59 ~6 ~23 cobblestone_wall 0
setblock ~59 ~6 ~51 cobblestone_wall 0
fill ~71 ~6 ~13 ~72 ~6 ~13 leaves2 1
fill ~71 ~6 ~14 ~72 ~6 ~14 leaves2 1
fill ~74 ~6 ~34 ~74 ~8 ~34 lapis_block 0
fill ~74 ~6 ~36 ~74 ~8 ~36 lapis_block 0
fill ~74 ~6 ~38 ~74 ~8 ~38 lapis_block 0
fill ~74 ~6 ~40 ~74 ~8 ~40 lapis_block 0
fill ~76 ~6 ~11 ~79 ~6 ~11 leaves2 1
fill ~76 ~6 ~12 ~79 ~6 ~12 leaves2 1
fill ~77 ~6 ~10 ~79 ~6 ~10 leaves2 1
fill ~77 ~6 ~13 ~79 ~6 ~13 leaves2 1
fill ~78 ~6 ~3 ~79 ~6 ~3 leaves2 1
fill ~78 ~6 ~4 ~79 ~6 ~4 leaves2 1
fill ~78 ~6 ~9 ~79 ~6 ~9 leaves2 1
fill ~78 ~6 ~14 ~79 ~6 ~14 leaves2 1
setblock ~25 ~7 ~23 stone_sts 4
setblock ~25 ~7 ~51 stone_sts 4
fill ~26 ~7 ~23 ~27 ~7 ~23 stonebrick 0
fill ~26 ~7 ~51 ~27 ~7 ~51 stonebrick 0
fill ~27 ~7 ~24 ~28 ~7 ~24 stonebrick 0
fill ~27 ~7 ~50 ~28 ~7 ~50 stonebrick 0
fill ~27 ~7 ~52 ~27 ~16 ~52 stonebrick 0
setblock ~28 ~7 ~20 stone_sts 6
setblock ~28 ~7 ~26 stone_sts 7
setblock ~28 ~7 ~48 stone_sts 6
setblock ~28 ~7 ~54 stone_sts 7
fill ~29 ~7 ~23 ~30 ~7 ~23 stonebrick 0
fill ~29 ~7 ~51 ~30 ~7 ~51 stonebrick 0
fill ~29 ~7 ~52 ~29 ~16 ~52 stonebrick 0
setblock ~31 ~7 ~23 stone_sts 5
setblock ~31 ~7 ~51 stone_sts 5
fill ~38 ~7 ~5 ~46 ~7 ~5 stonebrick 0
setblock ~53 ~7 ~23 stone_sts 4
setblock ~53 ~7 ~51 stone_sts 4
fill ~54 ~7 ~23 ~55 ~7 ~23 stonebrick 0
fill ~54 ~7 ~51 ~55 ~7 ~51 stonebrick 0
fill ~55 ~7 ~22 ~57 ~7 ~22 stonebrick 0
fill ~55 ~7 ~52 ~57 ~7 ~52 stonebrick 0
setblock ~56 ~7 ~20 stone_sts 6
fill ~56 ~7 ~24 ~57 ~7 ~24 stonebrick 0
setblock ~56 ~7 ~26 stone_sts 7
setblock ~56 ~7 ~48 stone_sts 6
fill ~56 ~7 ~50 ~56 ~4 ~50 stonebrick 0
setblock ~56 ~7 ~54 stone_sts 7
fill ~57 ~7 ~23 ~58 ~7 ~23 stonebrick 0
fill ~58 ~7 ~51 ~58 ~16 ~51 stonebrick 0
setblock ~59 ~7 ~23 stone_sts 5
setblock ~59 ~7 ~51 stone_sts 5
fill ~78 ~7 ~11 ~79 ~7 ~11 leaves2 1
fill ~78 ~7 ~12 ~79 ~7 ~12 leaves2 1
fill ~26 ~8 ~23 ~27 ~8 ~23 stonebrick 0
