setblock ~4 ~-3 ~14 iron_block 0
setblock ~4 ~-3 ~36 iron_block 0
fill ~5 ~-3 ~15 ~5 ~-2 ~15 iron_block 0
fill ~5 ~-3 ~35 ~5 ~-2 ~35 iron_block 0
fill ~6 ~-3 ~16 ~6 ~0 ~16 iron_block 0
fill ~6 ~-3 ~19 ~6 ~0 ~19 wool 15
fill ~6 ~-3 ~20 ~6 ~0 ~20 wool 15
fill ~6 ~-3 ~21 ~6 ~0 ~21 wool 15
fill ~6 ~-3 ~22 ~6 ~0 ~22 wool 15
fill ~6 ~-3 ~23 ~6 ~0 ~23 wool 15
fill ~6 ~-3 ~25 ~7 ~-3 ~25 torch 5
fill ~6 ~-3 ~27 ~6 ~0 ~27 wool 15
fill ~6 ~-3 ~28 ~6 ~0 ~28 wool 15
fill ~6 ~-3 ~29 ~6 ~0 ~29 wool 15
fill ~6 ~-3 ~30 ~6 ~0 ~30 wool 15
fill ~6 ~-3 ~31 ~6 ~0 ~31 wool 15
fill ~6 ~-3 ~34 ~6 ~0 ~34 iron_block 0
fill ~7 ~-3 ~17 ~7 ~2 ~17 iron_block 0
fill ~7 ~-3 ~18 ~7 ~0 ~18 wool 15
fill ~7 ~-3 ~19 ~7 ~11 ~19 iron_block 0
fill ~7 ~-3 ~20 ~23 ~-3 ~20 iron_block 0
fill ~7 ~-3 ~21 ~10 ~-3 ~21 iron_block 0
fill ~7 ~-3 ~22 ~23 ~-3 ~22 iron_block 0
fill ~7 ~-3 ~23 ~13 ~-3 ~23 iron_block 0
fill ~7 ~-3 ~24 ~7 ~0 ~24 wool 15
fill ~7 ~-3 ~26 ~7 ~0 ~26 wool 15
fill ~7 ~-3 ~27 ~7 ~11 ~27 iron_block 0
fill ~7 ~-3 ~28 ~23 ~-3 ~28 iron_block 0
fill ~7 ~-3 ~29 ~10 ~-3 ~29 iron_block 0
fill ~7 ~-3 ~30 ~23 ~-3 ~30 iron_block 0
fill ~7 ~-3 ~31 ~7 ~11 ~31 iron_block 0
fill ~7 ~-3 ~32 ~7 ~0 ~32 wool 15
fill ~7 ~-3 ~33 ~7 ~2 ~33 iron_block 0
fill ~8 ~-3 ~17 ~8 ~0 ~17 wool 15
fill ~8 ~-3 ~18 ~8 ~11 ~18 iron_block 0
fill ~8 ~-3 ~24 ~12 ~-3 ~24 iron_block 0
fill ~8 ~-3 ~25 ~8 ~0 ~25 wool 15
fill ~8 ~-3 ~26 ~12 ~-3 ~26 iron_block 0
fill ~8 ~-3 ~32 ~8 ~11 ~32 iron_block 0
fill ~8 ~-3 ~33 ~8 ~0 ~33 wool 15
fill ~9 ~-3 ~16 ~13 ~-3 ~16 wool 15
fill ~9 ~-3 ~17 ~13 ~-3 ~17 iron_block 0
fill ~9 ~-3 ~19 ~13 ~-3 ~19 iron_block 0
fill ~9 ~-3 ~25 ~13 ~-3 ~25 iron_block 0
fill ~9 ~-3 ~27 ~13 ~-3 ~27 iron_block 0
fill ~9 ~-3 ~31 ~21 ~-3 ~31 iron_block 0
fill ~9 ~-3 ~33 ~13 ~-3 ~33 iron_block 0
fill ~9 ~-3 ~34 ~13 ~-3 ~34 wool 15
fill ~10 ~-3 ~18 ~12 ~-3 ~18 iron_block 0
fill ~10 ~-3 ~32 ~14 ~-3 ~32 iron_block 0
fill ~12 ~-3 ~21 ~18 ~-3 ~21 iron_block 0
fill ~12 ~-3 ~29 ~18 ~-3 ~29 iron_block 0
fill ~14 ~-3 ~17 ~14 ~0 ~17 wool 15
fill ~14 ~-3 ~18 ~14 ~11 ~18 iron_block 0
fill ~14 ~-3 ~24 ~14 ~11 ~24 iron_block 0
setblock ~14 ~-3 ~25 torch 5
fill ~14 ~-3 ~26 ~14 ~11 ~26 iron_block 0
fill ~14 ~-3 ~33 ~14 ~0 ~33 wool 15
setblock ~15 ~-3 ~17 torch 5
fill ~15 ~-3 ~18 ~15 ~0 ~18 wool 15
fill ~15 ~-3 ~19 ~21 ~-3 ~19 iron_block 0
fill ~15 ~-3 ~23 ~15 ~11 ~23 iron_block 0
setblock ~15 ~-3 ~24 torch 5
setblock ~15 ~-3 ~25 iron_block 0
setblock ~15 ~-3 ~26 torch 5
fill ~15 ~-3 ~27 ~15 ~11 ~27 iron_block 0
fill ~15 ~-3 ~32 ~15 ~0 ~32 wool 15
fill ~15 ~-3 ~33 ~15 ~-3 ~34 torch 5
fill ~16 ~-3 ~17 ~16 ~0 ~17 wool 15
fill ~16 ~-3 ~18 ~20 ~-3 ~18 iron_block 0
fill ~16 ~-3 ~24 ~16 ~11 ~24 iron_block 0
setblock ~16 ~-3 ~25 torch 5
fill ~16 ~-3 ~26 ~16 ~11 ~26 iron_block 0
fill ~16 ~-3 ~32 ~20 ~-3 ~32 iron_block 0
fill ~16 ~-3 ~33 ~16 ~0 ~33 wool 15
fill ~17 ~-3 ~16 ~21 ~-3 ~16 wool 15
fill ~17 ~-3 ~17 ~21 ~-3 ~17 iron_block 0
fill ~17 ~-3 ~23 ~23 ~-3 ~23 iron_block 0
fill ~17 ~-3 ~25 ~20 ~-3 ~25 iron_block 0
fill ~17 ~-3 ~27 ~23 ~-3 ~27 iron_block 0
fill ~17 ~-3 ~33 ~21 ~-3 ~33 iron_block 0
fill ~17 ~-3 ~34 ~21 ~-3 ~34 wool 15
fill ~18 ~-3 ~24 ~22 ~-3 ~24 iron_block 0
fill ~18 ~-3 ~26 ~22 ~-3 ~26 iron_block 0
fill ~20 ~-3 ~21 ~23 ~-3 ~21 iron_block 0
fill ~20 ~-3 ~29 ~23 ~-3 ~29 iron_block 0
fill ~22 ~-3 ~17 ~23 ~-3 ~17 wool 15
fill ~22 ~-3 ~18 ~22 ~11 ~18 iron_block 0
fill ~22 ~-3 ~25 ~22 ~0 ~25 wool 15
fill ~22 ~-3 ~32 ~22 ~11 ~32 iron_block 0
fill ~22 ~-3 ~33 ~23 ~-3 ~33 wool 15
fill ~23 ~-3 ~18 ~23 ~0 ~18 wool 15
fill ~23 ~-3 ~19 ~23 ~11 ~19 iron_block 0
fill ~23 ~-3 ~24 ~23 ~0 ~24 wool 15
setblock ~23 ~-3 ~25 torch 5
fill ~23 ~-3 ~26 ~23 ~0 ~26 wool 15
fill ~23 ~-3 ~31 ~23 ~11 ~31 iron_block 0
fill ~23 ~-3 ~32 ~23 ~0 ~32 wool 15
fill ~24 ~-3 ~16 ~24 ~0 ~16 iron_block 0
fill ~24 ~-3 ~18 ~24 ~0 ~18 iron_bars 0
fill ~24 ~-3 ~19 ~24 ~0 ~19 wool 15
fill ~24 ~-3 ~20 ~24 ~0 ~20 wool 15
fill ~24 ~-3 ~21 ~24 ~0 ~21 wool 15
fill ~24 ~-3 ~22 ~24 ~0 ~22 wool 15
fill ~24 ~-3 ~23 ~24 ~0 ~23 wool 15
fill ~24 ~-3 ~24 ~24 ~0 ~24 iron_bars 0
fill ~24 ~-3 ~27 ~24 ~0 ~27 wool 15
fill ~24 ~-3 ~28 ~24 ~0 ~28 wool 15
fill ~24 ~-3 ~29 ~24 ~0 ~29 wool 15
fill ~24 ~-3 ~30 ~24 ~0 ~30 wool 15
fill ~24 ~-3 ~31 ~24 ~0 ~31 wool 15
fill ~24 ~-3 ~34 ~24 ~0 ~34 iron_block 0
fill ~25 ~-3 ~15 ~25 ~-2 ~15 iron_block 0
fill ~25 ~-3 ~20 ~25 ~0 ~20 iron_bars 0
fill ~25 ~-3 ~22 ~25 ~0 ~22 iron_bars 0
fill ~25 ~-3 ~35 ~25 ~-2 ~35 iron_block 0
setblock ~26 ~-3 ~14 iron_block 0
setblock ~26 ~-3 ~36 iron_block 0
fill ~7 ~-2 ~20 ~23 ~-2 ~20 iron_block 0
fill ~7 ~-2 ~21 ~10 ~-2 ~21 iron_block 0
fill ~7 ~-2 ~22 ~23 ~-2 ~22 iron_block 0
fill ~7 ~-2 ~23 ~7 ~11 ~23 iron_block 0
fill ~7 ~-2 ~28 ~23 ~-2 ~28 iron_block 0
fill ~7 ~-2 ~29 ~10 ~-2 ~29 iron_block 0
fill ~7 ~-2 ~30 ~23 ~-2 ~30 iron_block 0
fill ~8 ~-2 ~24 ~12 ~-2 ~24 iron_block 0
fill ~8 ~-2 ~26 ~12 ~-2 ~26 iron_block 0
fill ~9 ~-2 ~16 ~13 ~-2 ~16 wool 15
fill ~9 ~-2 ~17 ~13 ~-2 ~17 iron_block 0
fill ~9 ~-2 ~19 ~13 ~-2 ~19 iron_block 0
fill ~9 ~-2 ~23 ~13 ~-2 ~23 iron_block 0
fill ~9 ~-2 ~25 ~13 ~-2 ~25 iron_block 0
fill ~9 ~-2 ~27 ~13 ~-2 ~27 iron_block 0
fill ~9 ~-2 ~31 ~21 ~-2 ~31 iron_block 0
fill ~9 ~-2 ~33 ~13 ~-2 ~33 iron_block 0
fill ~9 ~-2 ~34 ~13 ~-2 ~34 wool 15
fill ~10 ~-2 ~18 ~12 ~-2 ~18 iron_block 0
fill ~10 ~-2 ~32 ~12 ~-2 ~32 iron_block 0
fill ~12 ~-2 ~21 ~18 ~-2 ~21 iron_block 0
fill ~12 ~-2 ~29 ~18 ~-2 ~29 iron_block 0
fill ~14 ~-2 ~32 ~14 ~11 ~32 iron_block 0
fill ~15 ~-2 ~19 ~21 ~-2 ~19 iron_block 0
fill ~16 ~-2 ~18 ~16 ~11 ~18 iron_block 0
fill ~16 ~-2 ~32 ~16 ~11 ~32 iron_block 0
fill ~17 ~-2 ~16 ~21 ~-2 ~16 wool 15
fill ~17 ~-2 ~17 ~21 ~-2 ~17 iron_block 0
fill ~17 ~-2 ~23 ~21 ~-2 ~23 iron_block 0
fill ~17 ~-2 ~25 ~20 ~-2 ~25 iron_block 0
fill ~17 ~-2 ~27 ~21 ~-2 ~27 iron_block 0
fill ~17 ~-2 ~33 ~21 ~-2 ~33 iron_block 0
fill ~17 ~-2 ~34 ~21 ~-2 ~34 wool 15
fill ~18 ~-2 ~18 ~20 ~-2 ~18 iron_block 0
fill ~18 ~-2 ~24 ~22 ~-2 ~24 iron_block 0
fill ~18 ~-2 ~26 ~22 ~-2 ~26 iron_block 0
fill ~18 ~-2 ~32 ~20 ~-2 ~32 iron_block 0
fill ~20 ~-2 ~21 ~23 ~-2 ~21 iron_block 0
fill ~20 ~-2 ~29 ~23 ~-2 ~29 iron_block 0
fill ~22 ~-2 ~17 ~23 ~-2 ~17 wool 15
fill ~22 ~-2 ~33 ~23 ~-2 ~33 wool 15
fill ~23 ~-2 ~23 ~23 ~11 ~23 iron_block 0
fill ~23 ~-2 ~27 ~23 ~11 ~27 iron_block 0
fill ~7 ~-1 ~20 ~23 ~-1 ~20 iron_block 0
fill ~7 ~-1 ~21 ~10 ~-1 ~21 iron_block 0
fill ~7 ~-1 ~22 ~23 ~-1 ~22 iron_block 0
fill ~7 ~-1 ~28 ~23 ~-1 ~28 iron_block 0
fill ~7 ~-1 ~29 ~10 ~-1 ~29 iron_block 0
fill ~7 ~-1 ~30 ~23 ~-1 ~30 iron_block 0
fill ~8 ~-1 ~24 ~12 ~-1 ~24 iron_block 0
fill ~8 ~-1 ~26 ~12 ~-1 ~26 iron_block 0
fill ~9 ~-1 ~16 ~13 ~-1 ~16 wool 15
fill ~9 ~-1 ~17 ~13 ~-1 ~17 iron_block 0
fill ~9 ~-1 ~19 ~13 ~-1 ~19 iron_block 0
fill ~9 ~-1 ~23 ~13 ~-1 ~23 iron_block 0
fill ~9 ~-1 ~25 ~13 ~-1 ~25 iron_block 0
fill ~9 ~-1 ~27 ~13 ~-1 ~27 iron_block 0
fill ~9 ~-1 ~31 ~21 ~-1 ~31 iron_block 0
fill ~9 ~-1 ~33 ~13 ~-1 ~33 iron_block 0
fill ~9 ~-1 ~34 ~13 ~-1 ~34 wool 15
fill ~10 ~-1 ~18 ~12 ~-1 ~18 iron_block 0
fill ~10 ~-1 ~32 ~12 ~-1 ~32 iron_block 0
fill ~12 ~-1 ~21 ~18 ~-1 ~21 iron_block 0
fill ~12 ~-1 ~29 ~18 ~-1 ~29 iron_block 0
fill ~15 ~-1 ~19 ~21 ~-1 ~19 iron_block 0
fill ~17 ~-1 ~16 ~21 ~-1 ~16 wool 15
fill ~17 ~-1 ~17 ~21 ~-1 ~17 iron_block 0
fill ~17 ~-1 ~23 ~21 ~-1 ~23 iron_block 0
fill ~17 ~-1 ~25 ~20 ~-1 ~25 iron_block 0
fill ~17 ~-1 ~27 ~21 ~-1 ~27 iron_block 0
fill ~17 ~-1 ~33 ~21 ~-1 ~33 iron_block 0
fill ~17 ~-1 ~34 ~21 ~-1 ~34 wool 15
fill ~18 ~-1 ~18 ~20 ~-1 ~18 iron_block 0
fill ~18 ~-1 ~24 ~22 ~-1 ~24 iron_block 0
fill ~18 ~-1 ~26 ~22 ~-1 ~26 iron_block 0
fill ~18 ~-1 ~32 ~20 ~-1 ~32 iron_block 0
fill ~20 ~-1 ~21 ~23 ~-1 ~21 iron_block 0
fill ~20 ~-1 ~29 ~23 ~-1 ~29 iron_block 0
fill ~22 ~-1 ~17 ~23 ~-1 ~17 wool 15
fill ~22 ~-1 ~33 ~23 ~-1 ~33 wool 15
fill ~7 ~0 ~20 ~23 ~0 ~20 iron_block 0
fill ~7 ~0 ~21 ~10 ~0 ~21 iron_block 0
fill ~7 ~0 ~22 ~23 ~0 ~22 iron_block 0
fill ~7 ~0 ~28 ~23 ~0 ~28 iron_block 0
fill ~7 ~0 ~29 ~10 ~0 ~29 iron_block 0
fill ~7 ~0 ~30 ~23 ~0 ~30 iron_block 0
fill ~8 ~0 ~24 ~12 ~0 ~24 iron_block 0
fill ~8 ~0 ~26 ~12 ~0 ~26 iron_block 0
fill ~9 ~0 ~16 ~13 ~0 ~16 wool 15
fill ~9 ~0 ~17 ~13 ~0 ~17 iron_block 0
fill ~9 ~0 ~19 ~13 ~0 ~19 iron_block 0
fill ~9 ~0 ~23 ~13 ~0 ~23 iron_block 0
fill ~9 ~0 ~25 ~13 ~0 ~25 iron_block 0
fill ~9 ~0 ~27 ~13 ~0 ~27 iron_block 0
fill ~9 ~0 ~31 ~21 ~0 ~31 iron_block 0
fill ~9 ~0 ~33 ~13 ~0 ~33 iron_block 0
fill ~9 ~0 ~34 ~13 ~0 ~34 wool 15
fill ~10 ~0 ~18 ~12 ~0 ~18 iron_block 0
fill ~10 ~0 ~32 ~12 ~0 ~32 iron_block 0
fill ~12 ~0 ~21 ~18 ~0 ~21 iron_block 0
fill ~12 ~0 ~29 ~18 ~0 ~29 iron_block 0
fill ~15 ~0 ~19 ~21 ~0 ~19 iron_block 0
fill ~17 ~0 ~16 ~21 ~0 ~16 wool 15
fill ~17 ~0 ~17 ~21 ~0 ~17 iron_block 0
fill ~17 ~0 ~23 ~21 ~0 ~23 iron_block 0
fill ~17 ~0 ~25 ~20 ~0 ~25 iron_block 0
fill ~17 ~0 ~27 ~21 ~0 ~27 iron_block 0
fill ~17 ~0 ~33 ~21 ~0 ~33 iron_block 0
fill ~17 ~0 ~34 ~21 ~0 ~34 wool 15
fill ~18 ~0 ~18 ~20 ~0 ~18 iron_block 0
fill ~18 ~0 ~24 ~22 ~0 ~24 iron_block 0
fill ~18 ~0 ~26 ~22 ~0 ~26 iron_block 0
fill ~18 ~0 ~32 ~20 ~0 ~32 iron_block 0
fill ~20 ~0 ~21 ~23 ~0 ~21 iron_block 0
fill ~20 ~0 ~29 ~23 ~0 ~29 iron_block 0
fill ~22 ~0 ~17 ~23 ~0 ~17 wool 15
fill ~22 ~0 ~33 ~23 ~0 ~33 wool 15
fill ~6 ~1 ~19 ~6 ~3 ~19 iron_block 0
fill ~6 ~1 ~20 ~24 ~1 ~20 iron_block 0
fill ~6 ~1 ~21 ~10 ~1 ~21 iron_block 0
fill ~6 ~1 ~22 ~24 ~1 ~22 iron_block 0
fill ~6 ~1 ~23 ~6 ~3 ~23 iron_block 0
fill ~6 ~1 ~27 ~6 ~3 ~27 iron_block 0
fill ~6 ~1 ~28 ~24 ~1 ~28 iron_block 0
fill ~6 ~1 ~29 ~10 ~1 ~29 iron_block 0
fill ~6 ~1 ~30 ~24 ~1 ~30 iron_block 0
fill ~6 ~1 ~31 ~6 ~3 ~31 iron_block 0
fill ~7 ~1 ~18 ~7 ~3 ~18 iron_block 0
fill ~7 ~1 ~24 ~12 ~1 ~24 iron_block 0
fill ~7 ~1 ~26 ~12 ~1 ~26 iron_block 0
fill ~7 ~1 ~32 ~7 ~3 ~32 iron_block 0
fill ~8 ~1 ~17 ~14 ~1 ~17 iron_block 0
fill ~8 ~1 ~25 ~13 ~1 ~25 iron_block 0
fill ~8 ~1 ~33 ~14 ~1 ~33 iron_block 0
fill ~9 ~1 ~16 ~13 ~1 ~16 iron_block 0
fill ~9 ~1 ~19 ~13 ~1 ~19 iron_block 0
fill ~9 ~1 ~23 ~13 ~1 ~23 iron_block 0
fill ~9 ~1 ~27 ~13 ~1 ~27 iron_block 0
fill ~9 ~1 ~31 ~21 ~1 ~31 iron_block 0
fill ~9 ~1 ~34 ~13 ~1 ~34 iron_block 0
fill ~10 ~1 ~18 ~12 ~1 ~18 iron_block 0
fill ~10 ~1 ~32 ~12 ~1 ~32 iron_block 0
fill ~12 ~1 ~21 ~18 ~1 ~21 iron_block 0
fill ~12 ~1 ~29 ~18 ~1 ~29 iron_block 0
fill ~15 ~1 ~18 ~15 ~3 ~18 iron_block 0
fill ~15 ~1 ~19 ~21 ~1 ~19 iron_block 0
fill ~15 ~1 ~32 ~15 ~3 ~32 iron_block 0
fill ~16 ~1 ~17 ~23 ~1 ~17 iron_block 0
fill ~16 ~1 ~33 ~23 ~1 ~33 iron_block 0
fill ~17 ~1 ~16 ~21 ~1 ~16 iron_block 0
fill ~17 ~1 ~23 ~21 ~1 ~23 iron_block 0
fill ~17 ~1 ~25 ~20 ~1 ~25 iron_block 0
fill ~17 ~1 ~27 ~21 ~1 ~27 iron_block 0
fill ~17 ~1 ~34 ~21 ~1 ~34 iron_block 0
fill ~18 ~1 ~18 ~20 ~1 ~18 iron_block 0
fill ~18 ~1 ~24 ~23 ~1 ~24 iron_block 0
fill ~18 ~1 ~26 ~23 ~1 ~26 iron_block 0
fill ~18 ~1 ~32 ~20 ~1 ~32 iron_block 0
fill ~20 ~1 ~21 ~24 ~1 ~21 iron_block 0
fill ~20 ~1 ~29 ~24 ~1 ~29 iron_block 0
fill ~22 ~1 ~25 ~22 ~3 ~25 iron_block 0
fill ~23 ~1 ~18 ~23 ~3 ~18 iron_block 0
fill ~23 ~1 ~32 ~23 ~3 ~32 iron_block 0
fill ~24 ~1 ~19 ~24 ~3 ~19 iron_block 0
fill ~24 ~1 ~23 ~24 ~3 ~23 iron_block 0
fill ~24 ~1 ~27 ~24 ~3 ~27 iron_block 0
fill ~24 ~1 ~31 ~24 ~3 ~31 iron_block 0
fill ~6 ~2 ~20 ~24 ~2 ~20 iron_block 0
fill ~6 ~2 ~21 ~10 ~2 ~21 iron_block 0
fill ~6 ~2 ~22 ~24 ~2 ~22 iron_block 0
fill ~6 ~2 ~28 ~24 ~2 ~28 iron_block 0
fill ~6 ~2 ~29 ~10 ~2 ~29 iron_block 0
fill ~6 ~2 ~30 ~24 ~2 ~30 iron_block 0
fill ~7 ~2 ~24 ~12 ~2 ~24 iron_block 0
fill ~7 ~2 ~26 ~12 ~2 ~26 iron_block 0
fill ~8 ~2 ~17 ~14 ~2 ~17 iron_block 0
fill ~8 ~2 ~25 ~13 ~2 ~25 iron_block 0
fill ~8 ~2 ~33 ~14 ~2 ~33 iron_block 0
fill ~9 ~2 ~16 ~13 ~2 ~16 iron_block 0
fill ~9 ~2 ~19 ~13 ~2 ~19 iron_block 0
fill ~9 ~2 ~23 ~13 ~2 ~23 iron_block 0
fill ~9 ~2 ~27 ~13 ~2 ~27 iron_block 0
fill ~9 ~2 ~31 ~21 ~2 ~31 iron_block 0
fill ~9 ~2 ~34 ~13 ~2 ~34 iron_block 0
fill ~10 ~2 ~18 ~12 ~2 ~18 iron_block 0
fill ~10 ~2 ~32 ~12 ~2 ~32 iron_block 0
fill ~12 ~2 ~21 ~18 ~2 ~21 iron_block 0
fill ~12 ~2 ~29 ~18 ~2 ~29 iron_block 0
fill ~15 ~2 ~19 ~21 ~2 ~19 iron_block 0
fill ~16 ~2 ~17 ~23 ~2 ~17 iron_block 0
fill ~16 ~2 ~33 ~23 ~2 ~33 iron_block 0
fill ~17 ~2 ~16 ~21 ~2 ~16 iron_block 0
fill ~17 ~2 ~23 ~21 ~2 ~23 iron_block 0
fill ~17 ~2 ~25 ~20 ~2 ~25 iron_block 0
fill ~17 ~2 ~27 ~21 ~2 ~27 iron_block 0
fill ~17 ~2 ~34 ~21 ~2 ~34 iron_block 0
fill ~18 ~2 ~18 ~20 ~2 ~18 iron_block 0
fill ~18 ~2 ~24 ~23 ~2 ~24 iron_block 0
fill ~18 ~2 ~26 ~23 ~2 ~26 iron_block 0
fill ~18 ~2 ~32 ~20 ~2 ~32 iron_block 0
fill ~20 ~2 ~21 ~24 ~2 ~21 iron_block 0
fill ~20 ~2 ~29 ~24 ~2 ~29 iron_block 0
fill ~6 ~3 ~20 ~24 ~3 ~20 iron_block 0
fill ~6 ~3 ~21 ~10 ~3 ~21 iron_block 0
fill ~6 ~3 ~22 ~24 ~3 ~22 iron_block 0
fill ~6 ~3 ~28 ~24 ~3 ~28 iron_block 0
fill ~6 ~3 ~29 ~10 ~3 ~29 iron_block 0
fill ~6 ~3 ~30 ~24 ~3 ~30 iron_block 0
fill ~7 ~3 ~24 ~12 ~3 ~24 iron_block 0
fill ~7 ~3 ~26 ~12 ~3 ~26 iron_block 0
fill ~8 ~3 ~17 ~14 ~3 ~17 iron_block 0
fill ~8 ~3 ~25 ~13 ~3 ~25 iron_block 0
fill ~8 ~3 ~33 ~14 ~3 ~33 iron_block 0
fill ~9 ~3 ~16 ~13 ~3 ~16 iron_block 0
fill ~9 ~3 ~19 ~13 ~3 ~19 iron_block 0
fill ~9 ~3 ~23 ~13 ~3 ~23 iron_block 0
fill ~9 ~3 ~27 ~13 ~3 ~27 iron_block 0
fill ~9 ~3 ~31 ~21 ~3 ~31 iron_block 0
fill ~9 ~3 ~34 ~13 ~3 ~34 iron_block 0
fill ~10 ~3 ~18 ~12 ~3 ~18 iron_block 0
fill ~10 ~3 ~32 ~12 ~3 ~32 iron_block 0
fill ~12 ~3 ~21 ~18 ~3 ~21 iron_block 0
fill ~12 ~3 ~29 ~18 ~3 ~29 iron_block 0
fill ~15 ~3 ~19 ~21 ~3 ~19 iron_block 0
fill ~16 ~3 ~17 ~22 ~3 ~17 iron_block 0
fill ~16 ~3 ~33 ~22 ~3 ~33 iron_block 0
fill ~17 ~3 ~16 ~21 ~3 ~16 iron_block 0
fill ~17 ~3 ~23 ~21 ~3 ~23 iron_block 0
fill ~17 ~3 ~25 ~22 ~3 ~25 iron_block 0
fill ~17 ~3 ~27 ~21 ~3 ~27 iron_block 0
fill ~17 ~3 ~34 ~21 ~3 ~34 iron_block 0
fill ~18 ~3 ~18 ~20 ~3 ~18 iron_block 0
fill ~18 ~3 ~24 ~23 ~3 ~24 iron_block 0
fill ~18 ~3 ~26 ~23 ~3 ~26 iron_block 0
fill ~18 ~3 ~32 ~20 ~3 ~32 iron_block 0
fill ~20 ~3 ~21 ~24 ~3 ~21 iron_block 0
fill ~20 ~3 ~29 ~24 ~3 ~29 iron_block 0
fill ~7 ~4 ~20 ~23 ~4 ~20 iron_block 0
fill ~7 ~4 ~21 ~10 ~4 ~21 iron_block 0
fill ~7 ~4 ~22 ~23 ~4 ~22 iron_block 0
fill ~7 ~4 ~28 ~23 ~4 ~28 iron_block 0
fill ~7 ~4 ~29 ~10 ~4 ~29 iron_block 0
fill ~7 ~4 ~30 ~23 ~4 ~30 iron_block 0
fill ~8 ~4 ~24 ~12 ~4 ~24 iron_block 0
fill ~8 ~4 ~26 ~12 ~4 ~26 iron_block 0
fill ~9 ~4 ~17 ~13 ~4 ~17 iron_block 0
fill ~9 ~4 ~19 ~13 ~4 ~19 iron_block 0
fill ~9 ~4 ~23 ~13 ~4 ~23 iron_block 0
fill ~9 ~4 ~25 ~13 ~4 ~25 iron_block 0
fill ~9 ~4 ~27 ~13 ~4 ~27 iron_block 0
fill ~9 ~4 ~31 ~21 ~4 ~31 iron_block 0
fill ~9 ~4 ~33 ~13 ~4 ~33 iron_block 0
fill ~10 ~4 ~18 ~12 ~4 ~18 iron_block 0
fill ~10 ~4 ~32 ~12 ~4 ~32 iron_block 0
fill ~12 ~4 ~21 ~18 ~4 ~21 iron_block 0
fill ~12 ~4 ~29 ~18 ~4 ~29 iron_block 0
fill ~15 ~4 ~19 ~21 ~4 ~19 iron_block 0
fill ~17 ~4 ~17 ~21 ~4 ~17 iron_block 0
fill ~17 ~4 ~23 ~21 ~4 ~23 iron_block 0
fill ~17 ~4 ~25 ~20 ~4 ~25 iron_block 0
fill ~17 ~4 ~27 ~21 ~4 ~27 iron_block 0
fill ~17 ~4 ~33 ~21 ~4 ~33 iron_block 0
fill ~18 ~4 ~18 ~20 ~4 ~18 iron_block 0
fill ~18 ~4 ~24 ~22 ~4 ~24 iron_block 0
fill ~18 ~4 ~26 ~22 ~4 ~26 iron_block 0
fill ~18 ~4 ~32 ~20 ~4 ~32 iron_block 0
fill ~20 ~4 ~21 ~23 ~4 ~21 iron_block 0
fill ~20 ~4 ~29 ~23 ~4 ~29 iron_block 0
fill ~6 ~5 ~20 ~6 ~10 ~20 iron_bars 0
fill ~6 ~5 ~22 ~6 ~10 ~22 iron_bars 0
fill ~6 ~5 ~28 ~6 ~10 ~28 iron_bars 0
fill ~6 ~5 ~30 ~6 ~10 ~30 iron_bars 0
fill ~7 ~5 ~20 ~7 ~10 ~20 wool 15
fill ~7 ~5 ~21 ~7 ~10 ~21 wool 15
fill ~7 ~5 ~22 ~7 ~10 ~22 wool 15
fill ~7 ~5 ~28 ~7 ~10 ~28 wool 15
fill ~7 ~5 ~29 ~7 ~10 ~29 wool 15
fill ~7 ~5 ~30 ~7 ~10 ~30 wool 15
fill ~8 ~5 ~20 ~22 ~5 ~20 iron_block 0
fill ~8 ~5 ~21 ~10 ~5 ~21 iron_block 0
fill ~8 ~5 ~22 ~22 ~5 ~22 iron_block 0
fill ~8 ~5 ~24 ~12 ~5 ~24 iron_block 0
fill ~8 ~5 ~26 ~12 ~5 ~26 iron_block 0
fill ~8 ~5 ~28 ~22 ~5 ~28 iron_block 0
fill ~8 ~5 ~29 ~10 ~5 ~29 iron_block 0
fill ~8 ~5 ~30 ~22 ~5 ~30 iron_block 0
fill ~9 ~5 ~17 ~9 ~11 ~17 iron_block 0
fill ~9 ~5 ~19 ~13 ~5 ~19 iron_block 0
fill ~9 ~5 ~23 ~13 ~5 ~23 iron_block 0
fill ~9 ~5 ~25 ~13 ~5 ~25 iron_block 0
fill ~9 ~5 ~27 ~13 ~5 ~27 iron_block 0
fill ~9 ~5 ~31 ~21 ~5 ~31 iron_block 0
fill ~9 ~5 ~33 ~9 ~11 ~33 iron_block 0
fill ~10 ~5 ~16 ~10 ~10 ~16 iron_bars 0
fill ~10 ~5 ~17 ~12 ~5 ~17 wool 15
fill ~10 ~5 ~18 ~12 ~5 ~18 iron_block 0
fill ~10 ~5 ~32 ~12 ~5 ~32 iron_block 0
fill ~10 ~5 ~33 ~12 ~5 ~33 wool 15
fill ~10 ~5 ~34 ~10 ~10 ~34 iron_bars 0
fill ~12 ~5 ~16 ~12 ~10 ~16 iron_bars 0
fill ~12 ~5 ~21 ~18 ~5 ~21 iron_block 0
fill ~12 ~5 ~29 ~18 ~5 ~29 iron_block 0
fill ~12 ~5 ~34 ~12 ~10 ~34 iron_bars 0
fill ~13 ~5 ~17 ~13 ~11 ~17 iron_block 0
fill ~13 ~5 ~33 ~13 ~11 ~33 iron_block 0
fill ~15 ~5 ~19 ~21 ~5 ~19 iron_block 0
fill ~17 ~5 ~17 ~17 ~11 ~17 iron_block 0
fill ~17 ~5 ~23 ~21 ~5 ~23 iron_block 0
fill ~17 ~5 ~25 ~20 ~5 ~25 iron_block 0
fill ~17 ~5 ~27 ~21 ~5 ~27 iron_block 0
fill ~17 ~5 ~33 ~17 ~11 ~33 iron_block 0
fill ~18 ~5 ~16 ~18 ~10 ~16 iron_bars 0
fill ~18 ~5 ~17 ~20 ~5 ~17 wool 15
fill ~18 ~5 ~18 ~20 ~5 ~18 iron_block 0
fill ~18 ~5 ~24 ~22 ~5 ~24 iron_block 0
fill ~18 ~5 ~26 ~22 ~5 ~26 iron_block 0
fill ~18 ~5 ~32 ~20 ~5 ~32 iron_block 0
fill ~18 ~5 ~33 ~20 ~5 ~33 wool 15
fill ~18 ~5 ~34 ~18 ~10 ~34 iron_bars 0
fill ~20 ~5 ~16 ~20 ~10 ~16 iron_bars 0
fill ~20 ~5 ~21 ~22 ~5 ~21 iron_block 0
fill ~20 ~5 ~29 ~22 ~5 ~29 iron_block 0
fill ~20 ~5 ~34 ~20 ~10 ~34 iron_bars 0
fill ~21 ~5 ~17 ~21 ~11 ~17 iron_block 0
fill ~21 ~5 ~33 ~21 ~11 ~33 iron_block 0
fill ~23 ~5 ~20 ~23 ~10 ~20 wool 15
fill ~23 ~5 ~21 ~23 ~10 ~21 wool 15
fill ~23 ~5 ~22 ~23 ~10 ~22 wool 15
fill ~23 ~5 ~28 ~23 ~10 ~28 wool 15
fill ~23 ~5 ~29 ~23 ~10 ~29 wool 15
fill ~23 ~5 ~30 ~23 ~10 ~30 wool 15
fill ~24 ~5 ~20 ~24 ~10 ~20 iron_bars 0
fill ~24 ~5 ~22 ~24 ~10 ~22 iron_bars 0
fill ~24 ~5 ~28 ~24 ~10 ~28 iron_bars 0
fill ~24 ~5 ~30 ~24 ~10 ~30 iron_bars 0
fill ~8 ~6 ~20 ~22 ~6 ~20 iron_block 0
fill ~8 ~6 ~21 ~10 ~6 ~21 iron_block 0
fill ~8 ~6 ~22 ~22 ~6 ~22 iron_block 0
fill ~8 ~6 ~24 ~12 ~6 ~24 iron_block 0
fill ~8 ~6 ~26 ~12 ~6 ~26 iron_block 0
fill ~8 ~6 ~28 ~22 ~6 ~28 iron_block 0
fill ~8 ~6 ~29 ~10 ~6 ~29 iron_block 0
fill ~8 ~6 ~30 ~22 ~6 ~30 iron_block 0
fill ~9 ~6 ~19 ~13 ~6 ~19 iron_block 0
fill ~9 ~6 ~23 ~13 ~6 ~23 iron_block 0
fill ~9 ~6 ~25 ~13 ~6 ~25 iron_block 0
fill ~9 ~6 ~27 ~13 ~6 ~27 iron_block 0
fill ~9 ~6 ~31 ~21 ~6 ~31 iron_block 0
fill ~10 ~6 ~17 ~12 ~6 ~17 wool 15
fill ~10 ~6 ~18 ~12 ~6 ~18 iron_block 0
fill ~10 ~6 ~32 ~12 ~6 ~32 iron_block 0
fill ~10 ~6 ~33 ~12 ~6 ~33 wool 15
fill ~12 ~6 ~21 ~18 ~6 ~21 iron_block 0
fill ~12 ~6 ~29 ~18 ~6 ~29 iron_block 0
fill ~15 ~6 ~19 ~21 ~6 ~19 iron_block 0
fill ~17 ~6 ~23 ~21 ~6 ~23 iron_block 0
fill ~17 ~6 ~25 ~20 ~6 ~25 iron_block 0
fill ~17 ~6 ~27 ~21 ~6 ~27 iron_block 0
fill ~18 ~6 ~17 ~20 ~6 ~17 wool 15
fill ~18 ~6 ~18 ~20 ~6 ~18 iron_block 0
fill ~18 ~6 ~24 ~22 ~6 ~24 iron_block 0
fill ~18 ~6 ~26 ~22 ~6 ~26 iron_block 0
fill ~18 ~6 ~32 ~20 ~6 ~32 iron_block 0
fill ~18 ~6 ~33 ~20 ~6 ~33 wool 15
fill ~20 ~6 ~21 ~22 ~6 ~21 iron_block 0
fill ~20 ~6 ~29 ~22 ~6 ~29 iron_block 0
fill ~8 ~7 ~20 ~22 ~7 ~20 iron_block 0
fill ~8 ~7 ~21 ~10 ~7 ~21 iron_block 0
fill ~8 ~7 ~22 ~22 ~7 ~22 iron_block 0
fill ~8 ~7 ~24 ~12 ~7 ~24 iron_block 0
fill ~8 ~7 ~26 ~12 ~7 ~26 iron_block 0
fill ~8 ~7 ~28 ~22 ~7 ~28 iron_block 0
fill ~8 ~7 ~29 ~10 ~7 ~29 iron_block 0
fill ~8 ~7 ~30 ~22 ~7 ~30 iron_block 0
fill ~9 ~7 ~19 ~13 ~7 ~19 iron_block 0
fill ~9 ~7 ~23 ~13 ~7 ~23 iron_block 0
fill ~9 ~7 ~25 ~13 ~7 ~25 iron_block 0
fill ~9 ~7 ~27 ~13 ~7 ~27 iron_block 0
fill ~9 ~7 ~31 ~21 ~7 ~31 iron_block 0
fill ~10 ~7 ~17 ~12 ~7 ~17 wool 15
fill ~10 ~7 ~18 ~11 ~7 ~18 iron_block 0
fill ~10 ~7 ~32 ~12 ~7 ~32 iron_block 0
fill ~10 ~7 ~33 ~12 ~7 ~33 wool 15
fill ~12 ~7 ~21 ~18 ~7 ~21 iron_block 0
fill ~12 ~7 ~29 ~18 ~7 ~29 iron_block 0
fill ~15 ~7 ~19 ~21 ~7 ~19 iron_block 0
fill ~17 ~7 ~23 ~21 ~7 ~23 iron_block 0
fill ~17 ~7 ~25 ~20 ~7 ~25 iron_block 0
fill ~17 ~7 ~27 ~21 ~7 ~27 iron_block 0
fill ~18 ~7 ~17 ~20 ~7 ~17 wool 15
fill ~18 ~7 ~18 ~20 ~7 ~18 iron_block 0
fill ~18 ~7 ~24 ~22 ~7 ~24 iron_block 0
fill ~18 ~7 ~26 ~22 ~7 ~26 iron_block 0
fill ~18 ~7 ~32 ~20 ~7 ~32 iron_block 0
fill ~18 ~7 ~33 ~20 ~7 ~33 wool 15
fill ~20 ~7 ~21 ~22 ~7 ~21 iron_block 0
fill ~20 ~7 ~29 ~22 ~7 ~29 iron_block 0
fill ~8 ~8 ~20 ~22 ~8 ~20 iron_block 0
fill ~8 ~8 ~21 ~10 ~8 ~21 iron_block 0
fill ~8 ~8 ~22 ~22 ~8 ~22 iron_block 0
fill ~8 ~8 ~24 ~12 ~8 ~24 iron_block 0
fill ~8 ~8 ~26 ~12 ~8 ~26 iron_block 0
fill ~8 ~8 ~28 ~22 ~8 ~28 iron_block 0
fill ~8 ~8 ~29 ~10 ~8 ~29 iron_block 0
fill ~8 ~8 ~30 ~22 ~8 ~30 iron_block 0
fill ~9 ~8 ~19 ~13 ~8 ~19 iron_block 0
fill ~9 ~8 ~23 ~13 ~8 ~23 iron_block 0
fill ~9 ~8 ~25 ~13 ~8 ~25 iron_block 0
fill ~9 ~8 ~27 ~13 ~8 ~27 iron_block 0
fill ~9 ~8 ~31 ~21 ~8 ~31 iron_block 0
fill ~10 ~8 ~17 ~12 ~8 ~17 wool 15
fill ~10 ~8 ~18 ~12 ~8 ~18 iron_block 0
fill ~10 ~8 ~32 ~12 ~8 ~32 iron_block 0
fill ~10 ~8 ~33 ~12 ~8 ~33 wool 15
fill ~12 ~8 ~21 ~18 ~8 ~21 iron_block 0
fill ~12 ~8 ~29 ~18 ~8 ~29 iron_block 0
fill ~15 ~8 ~19 ~21 ~8 ~19 iron_block 0
fill ~17 ~8 ~23 ~21 ~8 ~23 iron_block 0
fill ~17 ~8 ~25 ~20 ~8 ~25 iron_block 0
fill ~17 ~8 ~27 ~21 ~8 ~27 iron_block 0
fill ~18 ~8 ~17 ~20 ~8 ~17 wool 15
fill ~18 ~8 ~18 ~20 ~8 ~18 iron_block 0
fill ~18 ~8 ~24 ~22 ~8 ~24 iron_block 0
fill ~18 ~8 ~26 ~22 ~8 ~26 iron_block 0
fill ~18 ~8 ~32 ~20 ~8 ~32 iron_block 0
fill ~18 ~8 ~33 ~20 ~8 ~33 wool 15
fill ~20 ~8 ~21 ~22 ~8 ~21 iron_block 0
fill ~20 ~8 ~29 ~22 ~8 ~29 iron_block 0
fill ~8 ~9 ~20 ~22 ~9 ~20 iron_block 0
fill ~8 ~9 ~21 ~10 ~9 ~21 iron_block 0
fill ~8 ~9 ~22 ~22 ~9 ~22 iron_block 0
fill ~8 ~9 ~24 ~12 ~9 ~24 iron_block 0
fill ~8 ~9 ~26 ~12 ~9 ~26 iron_block 0
fill ~8 ~9 ~28 ~22 ~9 ~28 iron_block 0
fill ~8 ~9 ~29 ~10 ~9 ~29 iron_block 0
fill ~8 ~9 ~30 ~22 ~9 ~30 iron_block 0
fill ~9 ~9 ~19 ~13 ~9 ~19 iron_block 0
fill ~9 ~9 ~23 ~13 ~9 ~23 iron_block 0
fill ~9 ~9 ~25 ~13 ~9 ~25 iron_block 0
fill ~9 ~9 ~27 ~13 ~9 ~27 iron_block 0
fill ~9 ~9 ~31 ~21 ~9 ~31 iron_block 0
fill ~10 ~9 ~17 ~12 ~9 ~17 wool 15
fill ~10 ~9 ~18 ~12 ~9 ~18 iron_block 0
fill ~10 ~9 ~32 ~12 ~9 ~32 iron_block 0
fill ~10 ~9 ~33 ~12 ~9 ~33 wool 15
fill ~12 ~9 ~21 ~18 ~9 ~21 iron_block 0
fill ~12 ~9 ~29 ~18 ~9 ~29 iron_block 0
fill ~15 ~9 ~19 ~21 ~9 ~19 iron_block 0
fill ~17 ~9 ~23 ~21 ~9 ~23 iron_block 0
fill ~17 ~9 ~25 ~20 ~9 ~25 iron_block 0
fill ~17 ~9 ~27 ~21 ~9 ~27 iron_block 0
fill ~18 ~9 ~17 ~20 ~9 ~17 wool 15
fill ~18 ~9 ~18 ~20 ~9 ~18 iron_block 0
fill ~18 ~9 ~24 ~22 ~9 ~24 iron_block 0
fill ~18 ~9 ~26 ~22 ~9 ~26 iron_block 0
fill ~18 ~9 ~32 ~20 ~9 ~32 iron_block 0
fill ~18 ~9 ~33 ~20 ~9 ~33 wool 15
fill ~20 ~9 ~21 ~22 ~9 ~21 iron_block 0
fill ~20 ~9 ~29 ~22 ~9 ~29 iron_block 0
fill ~8 ~10 ~20 ~22 ~10 ~20 iron_block 0
fill ~8 ~10 ~21 ~10 ~10 ~21 iron_block 0
fill ~8 ~10 ~22 ~22 ~10 ~22 iron_block 0
fill ~8 ~10 ~24 ~12 ~10 ~24 iron_block 0
fill ~8 ~10 ~26 ~12 ~10 ~26 iron_block 0
fill ~8 ~10 ~28 ~22 ~10 ~28 iron_block 0
fill ~8 ~10 ~29 ~10 ~10 ~29 iron_block 0
fill ~8 ~10 ~30 ~22 ~10 ~30 iron_block 0
fill ~9 ~10 ~19 ~13 ~10 ~19 iron_block 0
fill ~9 ~10 ~23 ~13 ~10 ~23 iron_block 0
fill ~9 ~10 ~25 ~13 ~10 ~25 iron_block 0
fill ~9 ~10 ~27 ~13 ~10 ~27 iron_block 0
fill ~9 ~10 ~31 ~21 ~10 ~31 iron_block 0
fill ~10 ~10 ~17 ~12 ~10 ~17 wool 15
fill ~10 ~10 ~18 ~12 ~10 ~18 iron_block 0
fill ~10 ~10 ~32 ~12 ~10 ~32 iron_block 0
fill ~10 ~10 ~33 ~12 ~10 ~33 wool 15
fill ~12 ~10 ~21 ~18 ~10 ~21 iron_block 0
fill ~12 ~10 ~29 ~18 ~10 ~29 iron_block 0
fill ~15 ~10 ~19 ~21 ~10 ~19 iron_block 0
fill ~17 ~10 ~23 ~21 ~10 ~23 iron_block 0
fill ~17 ~10 ~25 ~20 ~10 ~25 iron_block 0
fill ~17 ~10 ~27 ~21 ~10 ~27 iron_block 0
fill ~18 ~10 ~17 ~20 ~10 ~17 wool 15
fill ~18 ~10 ~18 ~20 ~10 ~18 iron_block 0
fill ~18 ~10 ~24 ~22 ~10 ~24 iron_block 0
fill ~18 ~10 ~26 ~22 ~10 ~26 iron_block 0
fill ~18 ~10 ~32 ~20 ~10 ~32 iron_block 0
fill ~18 ~10 ~33 ~20 ~10 ~33 wool 15
fill ~20 ~10 ~21 ~22 ~10 ~21 iron_block 0
fill ~20 ~10 ~29 ~22 ~10 ~29 iron_block 0
fill ~7 ~11 ~20 ~23 ~11 ~20 iron_block 0
fill ~7 ~11 ~21 ~10 ~11 ~21 iron_block 0
fill ~7 ~11 ~22 ~23 ~11 ~22 iron_block 0
fill ~7 ~11 ~28 ~23 ~11 ~28 iron_block 0
fill ~7 ~11 ~29 ~10 ~11 ~29 iron_block 0
fill ~7 ~11 ~30 ~23 ~11 ~30 iron_block 0
fill ~8 ~11 ~19 ~23 ~11 ~19 iron_block 0
fill ~8 ~11 ~23 ~13 ~11 ~23 iron_block 0
fill ~8 ~11 ~24 ~12 ~11 ~24 iron_block 0
fill ~8 ~11 ~26 ~12 ~11 ~26 iron_block 0
fill ~8 ~11 ~27 ~13 ~11 ~27 iron_block 0
fill ~8 ~11 ~31 ~23 ~11 ~31 iron_block 0
fill ~9 ~11 ~18 ~14 ~11 ~18 iron_block 0
fill ~9 ~11 ~25 ~13 ~11 ~25 iron_block 0
fill ~9 ~11 ~32 ~14 ~11 ~32 iron_block 0
fill ~10 ~11 ~17 ~13 ~11 ~17 iron_block 0
fill ~10 ~11 ~33 ~13 ~11 ~33 iron_block 0
fill ~12 ~11 ~21 ~18 ~11 ~21 iron_block 0
fill ~12 ~11 ~29 ~18 ~11 ~29 iron_block 0
fill ~17 ~11 ~18 ~22 ~11 ~18 iron_block 0
fill ~17 ~11 ~23 ~23 ~11 ~23 iron_block 0
fill ~17 ~11 ~25 ~20 ~11 ~25 iron_block 0
fill ~17 ~11 ~27 ~23 ~11 ~27 iron_block 0
fill ~17 ~11 ~32 ~22 ~11 ~32 iron_block 0
fill ~18 ~11 ~17 ~21 ~11 ~17 iron_block 0
fill ~18 ~11 ~24 ~22 ~11 ~24 iron_block 0
fill ~18 ~11 ~26 ~22 ~11 ~26 iron_block 0
fill ~18 ~11 ~33 ~21 ~11 ~33 iron_block 0
fill ~20 ~11 ~21 ~23 ~11 ~21 iron_block 0
fill ~20 ~11 ~29 ~23 ~11 ~29 iron_block 0
fill ~8 ~12 ~20 ~22 ~12 ~20 iron_block 0
fill ~8 ~12 ~21 ~10 ~12 ~21 iron_block 0
fill ~8 ~12 ~22 ~14 ~12 ~22 iron_block 0
fill ~8 ~12 ~28 ~14 ~12 ~28 iron_block 0
fill ~8 ~12 ~29 ~10 ~12 ~29 iron_block 0
fill ~8 ~12 ~30 ~22 ~12 ~30 iron_block 0
fill ~9 ~12 ~19 ~13 ~12 ~19 iron_block 0
fill ~9 ~12 ~23 ~13 ~12 ~23 iron_block 0
fill ~9 ~12 ~27 ~13 ~12 ~27 iron_block 0
fill ~9 ~12 ~31 ~13 ~12 ~31 iron_block 0
fill ~10 ~12 ~18 ~12 ~12 ~18 iron_block 0
fill ~10 ~12 ~24 ~12 ~12 ~24 iron_block 0
fill ~10 ~12 ~25 ~10 ~57 ~25 iron_block 0
fill ~10 ~12 ~26 ~12 ~12 ~26 iron_block 0
fill ~10 ~12 ~32 ~12 ~12 ~32 iron_block 0
fill ~12 ~12 ~21 ~14 ~12 ~21 iron_block 0
fill ~12 ~12 ~29 ~14 ~12 ~29 iron_block 0
fill ~16 ~12 ~21 ~18 ~12 ~21 iron_block 0
fill ~16 ~12 ~22 ~22 ~12 ~22 iron_block 0
fill ~16 ~12 ~28 ~22 ~12 ~28 iron_block 0
fill ~16 ~12 ~29 ~18 ~12 ~29 iron_block 0
fill ~17 ~12 ~19 ~21 ~12 ~19 iron_block 0
fill ~17 ~12 ~23 ~21 ~12 ~23 iron_block 0
fill ~17 ~12 ~27 ~21 ~12 ~27 iron_block 0
fill ~17 ~12 ~31 ~21 ~12 ~31 iron_block 0
fill ~18 ~12 ~18 ~20 ~12 ~18 iron_block 0
fill ~18 ~12 ~24 ~20 ~12 ~24 iron_block 0
fill ~18 ~12 ~26 ~20 ~12 ~26 iron_block 0
fill ~18 ~12 ~32 ~20 ~12 ~32 iron_block 0
fill ~20 ~12 ~21 ~22 ~12 ~21 iron_block 0
fill ~20 ~12 ~25 ~20 ~46 ~25 iron_block 0
fill ~20 ~12 ~29 ~22 ~12 ~29 iron_block 0
fill ~8 ~13 ~20 ~22 ~13 ~20 iron_block 0
fill ~8 ~13 ~21 ~10 ~13 ~21 iron_block 0
fill ~8 ~13 ~22 ~14 ~13 ~22 iron_block 0
fill ~8 ~13 ~28 ~14 ~13 ~28 iron_block 0
fill ~8 ~13 ~29 ~10 ~13 ~29 iron_block 0
fill ~8 ~13 ~30 ~22 ~13 ~30 iron_block 0
fill ~9 ~13 ~19 ~13 ~13 ~19 iron_block 0
fill ~9 ~13 ~23 ~13 ~13 ~23 iron_block 0
fill ~9 ~13 ~27 ~13 ~13 ~27 iron_block 0
fill ~9 ~13 ~31 ~13 ~13 ~31 iron_block 0
fill ~10 ~13 ~18 ~12 ~13 ~18 iron_block 0
fill ~10 ~13 ~24 ~12 ~13 ~24 iron_block 0
fill ~10 ~13 ~26 ~12 ~13 ~26 iron_block 0
fill ~10 ~13 ~32 ~12 ~13 ~32 iron_block 0
fill ~12 ~13 ~21 ~14 ~13 ~21 iron_block 0
fill ~12 ~13 ~29 ~14 ~13 ~29 iron_block 0
fill ~16 ~13 ~21 ~18 ~13 ~21 iron_block 0
fill ~16 ~13 ~22 ~22 ~13 ~22 iron_block 0
fill ~16 ~13 ~28 ~22 ~13 ~28 iron_block 0
fill ~16 ~13 ~29 ~18 ~13 ~29 iron_block 0
fill ~17 ~13 ~19 ~21 ~13 ~19 iron_block 0
fill ~17 ~13 ~23 ~21 ~13 ~23 iron_block 0
fill ~17 ~13 ~27 ~21 ~13 ~27 iron_block 0
fill ~17 ~13 ~31 ~21 ~13 ~31 iron_block 0
fill ~18 ~13 ~18 ~20 ~13 ~18 iron_block 0
fill ~18 ~13 ~24 ~20 ~13 ~24 iron_block 0
fill ~18 ~13 ~26 ~20 ~13 ~26 iron_block 0
fill ~18 ~13 ~32 ~20 ~13 ~32 iron_block 0
fill ~20 ~13 ~21 ~22 ~13 ~21 iron_block 0
fill ~20 ~13 ~29 ~22 ~13 ~29 iron_block 0
fill ~8 ~14 ~20 ~22 ~14 ~20 iron_block 0
fill ~8 ~14 ~21 ~10 ~14 ~21 iron_block 0
fill ~8 ~14 ~22 ~14 ~14 ~22 iron_block 0
fill ~8 ~14 ~28 ~14 ~14 ~28 iron_block 0
fill ~8 ~14 ~29 ~10 ~14 ~29 iron_block 0
fill ~8 ~14 ~30 ~22 ~14 ~30 iron_block 0
fill ~9 ~14 ~19 ~13 ~14 ~19 iron_block 0
fill ~9 ~14 ~23 ~13 ~14 ~23 iron_block 0
fill ~9 ~14 ~27 ~13 ~14 ~27 iron_block 0
fill ~9 ~14 ~31 ~13 ~14 ~31 iron_block 0
fill ~10 ~14 ~18 ~12 ~14 ~18 iron_block 0
fill ~10 ~14 ~24 ~12 ~14 ~24 iron_block 0
fill ~10 ~14 ~26 ~12 ~14 ~26 iron_block 0
fill ~10 ~14 ~32 ~12 ~14 ~32 iron_block 0
fill ~12 ~14 ~21 ~14 ~14 ~21 iron_block 0
fill ~12 ~14 ~29 ~14 ~14 ~29 iron_block 0
fill ~16 ~14 ~21 ~18 ~14 ~21 iron_block 0
fill ~16 ~14 ~22 ~22 ~14 ~22 iron_block 0
fill ~16 ~14 ~28 ~22 ~14 ~28 iron_block 0
fill ~16 ~14 ~29 ~18 ~14 ~29 iron_block 0
fill ~17 ~14 ~19 ~21 ~14 ~19 iron_block 0
fill ~17 ~14 ~23 ~21 ~14 ~23 iron_block 0
fill ~17 ~14 ~27 ~21 ~14 ~27 iron_block 0
fill ~17 ~14 ~31 ~21 ~14 ~31 iron_block 0
fill ~18 ~14 ~18 ~20 ~14 ~18 iron_block 0
fill ~18 ~14 ~24 ~20 ~14 ~24 iron_block 0
fill ~18 ~14 ~26 ~20 ~14 ~26 iron_block 0
fill ~18 ~14 ~32 ~20 ~14 ~32 iron_block 0
fill ~20 ~14 ~21 ~22 ~14 ~21 iron_block 0
fill ~20 ~14 ~29 ~22 ~14 ~29 iron_block 0
fill ~8 ~15 ~20 ~22 ~15 ~20 iron_block 0
fill ~8 ~15 ~21 ~10 ~15 ~21 iron_block 0
fill ~8 ~15 ~22 ~14 ~15 ~22 iron_block 0
fill ~8 ~15 ~28 ~14 ~15 ~28 iron_block 0
fill ~8 ~15 ~29 ~10 ~15 ~29 iron_block 0
fill ~8 ~15 ~30 ~22 ~15 ~30 iron_block 0
fill ~9 ~15 ~19 ~13 ~15 ~19 iron_block 0
fill ~9 ~15 ~23 ~13 ~15 ~23 iron_block 0
fill ~9 ~15 ~27 ~13 ~15 ~27 iron_block 0
fill ~9 ~15 ~31 ~13 ~15 ~31 iron_block 0
fill ~10 ~15 ~18 ~12 ~15 ~18 iron_block 0
fill ~10 ~15 ~24 ~12 ~15 ~24 iron_block 0
fill ~10 ~15 ~26 ~12 ~15 ~26 iron_block 0
fill ~10 ~15 ~32 ~12 ~15 ~32 iron_block 0
fill ~12 ~15 ~21 ~14 ~15 ~21 iron_block 0
fill ~12 ~15 ~29 ~14 ~15 ~29 iron_block 0
fill ~16 ~15 ~21 ~18 ~15 ~21 iron_block 0
fill ~16 ~15 ~22 ~22 ~15 ~22 iron_block 0
fill ~16 ~15 ~28 ~22 ~15 ~28 iron_block 0
fill ~16 ~15 ~29 ~18 ~15 ~29 iron_block 0
fill ~17 ~15 ~19 ~21 ~15 ~19 iron_block 0
fill ~17 ~15 ~23 ~21 ~15 ~23 iron_block 0
fill ~17 ~15 ~27 ~21 ~15 ~27 iron_block 0
fill ~17 ~15 ~31 ~21 ~15 ~31 iron_block 0
fill ~18 ~15 ~18 ~20 ~15 ~18 iron_block 0
fill ~18 ~15 ~24 ~20 ~15 ~24 iron_block 0
fill ~18 ~15 ~26 ~20 ~15 ~26 iron_block 0
fill ~18 ~15 ~32 ~20 ~15 ~32 iron_block 0
fill ~20 ~15 ~21 ~22 ~15 ~21 iron_block 0
fill ~20 ~15 ~29 ~22 ~15 ~29 iron_block 0
fill ~8 ~16 ~20 ~22 ~16 ~20 iron_block 0
fill ~8 ~16 ~21 ~10 ~16 ~21 iron_block 0
fill ~8 ~16 ~22 ~14 ~16 ~22 iron_block 0
fill ~8 ~16 ~28 ~14 ~16 ~28 iron_block 0
fill ~8 ~16 ~29 ~10 ~16 ~29 iron_block 0
fill ~8 ~16 ~30 ~22 ~16 ~30 iron_block 0
fill ~9 ~16 ~19 ~13 ~16 ~19 iron_block 0
fill ~9 ~16 ~23 ~13 ~16 ~23 iron_block 0
fill ~9 ~16 ~27 ~13 ~16 ~27 iron_block 0
fill ~9 ~16 ~31 ~13 ~16 ~31 iron_block 0
fill ~10 ~16 ~18 ~12 ~16 ~18 iron_block 0
fill ~10 ~16 ~24 ~12 ~16 ~24 iron_block 0
fill ~10 ~16 ~26 ~12 ~16 ~26 iron_block 0
fill ~10 ~16 ~32 ~12 ~16 ~32 iron_block 0
fill ~12 ~16 ~21 ~14 ~16 ~21 iron_block 0
fill ~12 ~16 ~29 ~14 ~16 ~29 iron_block 0
fill ~16 ~16 ~21 ~18 ~16 ~21 iron_block 0
fill ~16 ~16 ~22 ~22 ~16 ~22 iron_block 0
fill ~16 ~16 ~28 ~22 ~16 ~28 iron_block 0
fill ~16 ~16 ~29 ~18 ~16 ~29 iron_block 0
fill ~17 ~16 ~19 ~21 ~16 ~19 iron_block 0
fill ~17 ~16 ~23 ~21 ~16 ~23 iron_block 0
fill ~17 ~16 ~27 ~21 ~16 ~27 iron_block 0
fill ~17 ~16 ~31 ~21 ~16 ~31 iron_block 0
fill ~18 ~16 ~18 ~20 ~16 ~18 iron_block 0
fill ~18 ~16 ~24 ~20 ~16 ~24 iron_block 0
fill ~18 ~16 ~26 ~20 ~16 ~26 iron_block 0
fill ~18 ~16 ~32 ~20 ~16 ~32 iron_block 0
fill ~20 ~16 ~21 ~22 ~16 ~21 iron_block 0
fill ~20 ~16 ~29 ~22 ~16 ~29 iron_block 0
fill ~8 ~17 ~20 ~22 ~17 ~20 iron_block 0
fill ~8 ~17 ~21 ~10 ~17 ~21 iron_block 0
fill ~8 ~17 ~22 ~14 ~17 ~22 iron_block 0
fill ~8 ~17 ~28 ~14 ~17 ~28 iron_block 0
fill ~8 ~17 ~29 ~10 ~17 ~29 iron_block 0
fill ~8 ~17 ~30 ~22 ~17 ~30 iron_block 0
fill ~9 ~17 ~19 ~13 ~17 ~19 iron_block 0
fill ~9 ~17 ~23 ~13 ~17 ~23 iron_block 0
fill ~9 ~17 ~27 ~13 ~17 ~27 iron_block 0
fill ~9 ~17 ~31 ~13 ~17 ~31 iron_block 0
fill ~10 ~17 ~18 ~12 ~17 ~18 iron_block 0
fill ~10 ~17 ~24 ~12 ~17 ~24 iron_block 0
fill ~10 ~17 ~26 ~12 ~17 ~26 iron_block 0
fill ~10 ~17 ~32 ~12 ~17 ~32 iron_block 0
fill ~12 ~17 ~21 ~14 ~17 ~21 iron_block 0
fill ~12 ~17 ~29 ~14 ~17 ~29 iron_block 0
fill ~16 ~17 ~21 ~18 ~17 ~21 iron_block 0
fill ~16 ~17 ~22 ~22 ~17 ~22 iron_block 0
fill ~16 ~17 ~28 ~22 ~17 ~28 iron_block 0
fill ~16 ~17 ~29 ~18 ~17 ~29 iron_block 0
fill ~17 ~17 ~19 ~21 ~17 ~19 iron_block 0
fill ~17 ~17 ~23 ~21 ~17 ~23 iron_block 0
fill ~17 ~17 ~27 ~21 ~17 ~27 iron_block 0
fill ~17 ~17 ~31 ~21 ~17 ~31 iron_block 0
fill ~18 ~17 ~18 ~20 ~17 ~18 iron_block 0
fill ~18 ~17 ~24 ~20 ~17 ~24 iron_block 0
fill ~18 ~17 ~26 ~20 ~17 ~26 iron_block 0
fill ~18 ~17 ~32 ~20 ~17 ~32 iron_block 0
fill ~20 ~17 ~21 ~22 ~17 ~21 iron_block 0
fill ~20 ~17 ~29 ~22 ~17 ~29 iron_block 0
fill ~8 ~18 ~20 ~22 ~18 ~20 iron_block 0
fill ~8 ~18 ~21 ~10 ~18 ~21 iron_block 0
fill ~8 ~18 ~22 ~14 ~18 ~22 iron_block 0
fill ~8 ~18 ~28 ~14 ~18 ~28 iron_block 0
fill ~8 ~18 ~29 ~10 ~18 ~29 iron_block 0
fill ~8 ~18 ~30 ~22 ~18 ~30 iron_block 0
fill ~9 ~18 ~19 ~13 ~18 ~19 iron_block 0
fill ~9 ~18 ~23 ~13 ~18 ~23 iron_block 0
fill ~9 ~18 ~27 ~13 ~18 ~27 iron_block 0
fill ~9 ~18 ~31 ~13 ~18 ~31 iron_block 0
fill ~10 ~18 ~18 ~12 ~18 ~18 iron_block 0
fill ~10 ~18 ~24 ~12 ~18 ~24 iron_block 0
fill ~10 ~18 ~26 ~12 ~18 ~26 iron_block 0
fill ~10 ~18 ~32 ~12 ~18 ~32 iron_block 0
fill ~12 ~18 ~21 ~14 ~18 ~21 iron_block 0
fill ~12 ~18 ~29 ~14 ~18 ~29 iron_block 0
fill ~16 ~18 ~21 ~18 ~18 ~21 iron_block 0
fill ~16 ~18 ~22 ~22 ~18 ~22 iron_block 0
fill ~16 ~18 ~28 ~22 ~18 ~28 iron_block 0
fill ~16 ~18 ~29 ~18 ~18 ~29 iron_block 0
fill ~17 ~18 ~19 ~21 ~18 ~19 iron_block 0
fill ~17 ~18 ~23 ~21 ~18 ~23 iron_block 0
fill ~17 ~18 ~27 ~21 ~18 ~27 iron_block 0
fill ~17 ~18 ~31 ~21 ~18 ~31 iron_block 0
fill ~18 ~18 ~18 ~20 ~18 ~18 iron_block 0
fill ~18 ~18 ~24 ~20 ~18 ~24 iron_block 0
fill ~18 ~18 ~26 ~20 ~18 ~26 iron_block 0
fill ~18 ~18 ~32 ~20 ~18 ~32 iron_block 0
fill ~20 ~18 ~21 ~22 ~18 ~21 iron_block 0
fill ~20 ~18 ~29 ~22 ~18 ~29 iron_block 0
fill ~8 ~19 ~20 ~22 ~19 ~20 iron_block 0
fill ~8 ~19 ~21 ~10 ~19 ~21 iron_block 0
fill ~8 ~19 ~22 ~14 ~19 ~22 iron_block 0
fill ~8 ~19 ~28 ~14 ~19 ~28 iron_block 0
fill ~8 ~19 ~29 ~10 ~19 ~29 iron_block 0
fill ~8 ~19 ~30 ~22 ~19 ~30 iron_block 0
fill ~9 ~19 ~19 ~13 ~19 ~19 iron_block 0
fill ~9 ~19 ~23 ~13 ~19 ~23 iron_block 0
fill ~9 ~19 ~27 ~13 ~19 ~27 iron_block 0
fill ~9 ~19 ~31 ~13 ~19 ~31 iron_block 0
fill ~10 ~19 ~18 ~12 ~19 ~18 iron_block 0
fill ~10 ~19 ~24 ~12 ~19 ~24 iron_block 0
fill ~10 ~19 ~26 ~12 ~19 ~26 iron_block 0
fill ~10 ~19 ~32 ~12 ~19 ~32 iron_block 0
fill ~12 ~19 ~21 ~14 ~19 ~21 iron_block 0
fill ~12 ~19 ~29 ~14 ~19 ~29 iron_block 0
fill ~16 ~19 ~21 ~18 ~19 ~21 iron_block 0
fill ~16 ~19 ~22 ~22 ~19 ~22 iron_block 0
fill ~16 ~19 ~28 ~22 ~19 ~28 iron_block 0
fill ~16 ~19 ~29 ~18 ~19 ~29 iron_block 0
fill ~17 ~19 ~19 ~21 ~19 ~19 iron_block 0
fill ~17 ~19 ~23 ~21 ~19 ~23 iron_block 0
fill ~17 ~19 ~27 ~21 ~19 ~27 iron_block 0
fill ~17 ~19 ~31 ~21 ~19 ~31 iron_block 0
fill ~18 ~19 ~18 ~20 ~19 ~18 iron_block 0
fill ~18 ~19 ~24 ~20 ~19 ~24 iron_block 0
fill ~18 ~19 ~26 ~20 ~19 ~26 iron_block 0
fill ~18 ~19 ~32 ~20 ~19 ~32 iron_block 0
fill ~20 ~19 ~21 ~22 ~19 ~21 iron_block 0
fill ~20 ~19 ~29 ~22 ~19 ~29 iron_block 0
fill ~8 ~20 ~20 ~8 ~21 ~20 wool 15
fill ~8 ~20 ~21 ~8 ~21 ~21 wool 15
fill ~8 ~20 ~22 ~8 ~21 ~22 wool 15
fill ~8 ~20 ~28 ~8 ~21 ~28 wool 15
fill ~8 ~20 ~29 ~8 ~21 ~29 wool 15
fill ~8 ~20 ~30 ~8 ~21 ~30 wool 15
fill ~9 ~20 ~19 ~9 ~21 ~19 wool 15
fill ~9 ~20 ~20 ~21 ~20 ~20 iron_block 0
fill ~9 ~20 ~21 ~10 ~20 ~21 iron_block 0
fill ~9 ~20 ~22 ~14 ~20 ~22 iron_block 0
fill ~9 ~20 ~23 ~9 ~21 ~23 wool 15
fill ~9 ~20 ~27 ~9 ~21 ~27 wool 15
fill ~9 ~20 ~28 ~14 ~20 ~28 iron_block 0
fill ~9 ~20 ~29 ~10 ~20 ~29 iron_block 0
fill ~9 ~20 ~30 ~21 ~20 ~30 iron_block 0
fill ~9 ~20 ~31 ~9 ~21 ~31 wool 15
fill ~10 ~20 ~18 ~12 ~20 ~18 wool 15
fill ~10 ~20 ~19 ~12 ~20 ~19 iron_block 0
fill ~10 ~20 ~23 ~13 ~20 ~23 iron_block 0
fill ~10 ~20 ~24 ~12 ~20 ~24 iron_block 0
fill ~10 ~20 ~26 ~12 ~20 ~26 iron_block 0
fill ~10 ~20 ~27 ~13 ~20 ~27 iron_block 0
fill ~10 ~20 ~31 ~12 ~20 ~31 iron_block 0
fill ~10 ~20 ~32 ~12 ~20 ~32 wool 15
fill ~12 ~20 ~21 ~14 ~20 ~21 iron_block 0
fill ~12 ~20 ~29 ~14 ~20 ~29 iron_block 0
fill ~13 ~20 ~19 ~13 ~21 ~19 wool 15
fill ~13 ~20 ~31 ~13 ~21 ~31 wool 15
fill ~16 ~20 ~21 ~18 ~20 ~21 iron_block 0
fill ~16 ~20 ~22 ~21 ~20 ~22 iron_block 0
fill ~16 ~20 ~28 ~21 ~20 ~28 iron_block 0
fill ~16 ~20 ~29 ~18 ~20 ~29 iron_block 0
fill ~17 ~20 ~19 ~17 ~21 ~19 wool 15
fill ~17 ~20 ~23 ~20 ~20 ~23 iron_block 0
fill ~17 ~20 ~27 ~20 ~20 ~27 iron_block 0
fill ~17 ~20 ~31 ~17 ~21 ~31 wool 15
fill ~18 ~20 ~18 ~20 ~20 ~18 wool 15
fill ~18 ~20 ~19 ~20 ~20 ~19 iron_block 0
fill ~18 ~20 ~24 ~20 ~20 ~24 iron_block 0
fill ~18 ~20 ~26 ~20 ~20 ~26 iron_block 0
fill ~18 ~20 ~31 ~20 ~20 ~31 iron_block 0
fill ~18 ~20 ~32 ~20 ~20 ~32 wool 15
fill ~20 ~20 ~21 ~21 ~20 ~21 iron_block 0
fill ~20 ~20 ~29 ~21 ~20 ~29 iron_block 0
fill ~21 ~20 ~19 ~21 ~21 ~19 wool 15
fill ~21 ~20 ~23 ~21 ~21 ~23 wool 15
fill ~21 ~20 ~27 ~21 ~21 ~27 wool 15
fill ~21 ~20 ~31 ~21 ~21 ~31 wool 15
fill ~22 ~20 ~20 ~22 ~21 ~20 wool 15
fill ~22 ~20 ~21 ~22 ~21 ~21 wool 15
fill ~22 ~20 ~22 ~22 ~21 ~22 wool 15
fill ~22 ~20 ~28 ~22 ~21 ~28 wool 15
fill ~22 ~20 ~29 ~22 ~21 ~29 wool 15
fill ~22 ~20 ~30 ~22 ~21 ~30 wool 15
fill ~9 ~21 ~20 ~21 ~21 ~20 iron_block 0
fill ~9 ~21 ~21 ~10 ~21 ~21 iron_block 0
fill ~9 ~21 ~22 ~14 ~21 ~22 iron_block 0
fill ~9 ~21 ~28 ~14 ~21 ~28 iron_block 0
fill ~9 ~21 ~29 ~10 ~21 ~29 iron_block 0
fill ~9 ~21 ~30 ~21 ~21 ~30 iron_block 0
fill ~10 ~21 ~18 ~12 ~21 ~18 wool 15
fill ~10 ~21 ~19 ~12 ~21 ~19 iron_block 0
fill ~10 ~21 ~23 ~13 ~21 ~23 iron_block 0
fill ~10 ~21 ~24 ~12 ~21 ~24 iron_block 0
fill ~10 ~21 ~26 ~12 ~21 ~26 iron_block 0
fill ~10 ~21 ~27 ~13 ~21 ~27 iron_block 0
fill ~10 ~21 ~31 ~12 ~21 ~31 iron_block 0
fill ~10 ~21 ~32 ~12 ~21 ~32 wool 15
fill ~12 ~21 ~21 ~14 ~21 ~21 iron_block 0
fill ~12 ~21 ~29 ~14 ~21 ~29 iron_block 0
fill ~16 ~21 ~21 ~18 ~21 ~21 iron_block 0
fill ~16 ~21 ~22 ~21 ~21 ~22 iron_block 0
fill ~16 ~21 ~28 ~21 ~21 ~28 iron_block 0
fill ~16 ~21 ~29 ~18 ~21 ~29 iron_block 0
fill ~17 ~21 ~23 ~20 ~21 ~23 iron_block 0
fill ~17 ~21 ~27 ~20 ~21 ~27 iron_block 0
fill ~18 ~21 ~18 ~20 ~21 ~18 wool 15
fill ~18 ~21 ~19 ~20 ~21 ~19 iron_block 0
fill ~18 ~21 ~24 ~20 ~21 ~24 iron_block 0
fill ~18 ~21 ~26 ~20 ~21 ~26 iron_block 0
fill ~18 ~21 ~31 ~20 ~21 ~31 iron_block 0
fill ~18 ~21 ~32 ~20 ~21 ~32 wool 15
fill ~20 ~21 ~21 ~21 ~21 ~21 iron_block 0
fill ~20 ~21 ~29 ~21 ~21 ~29 iron_block 0
fill ~9 ~22 ~20 ~9 ~31 ~20 wool 14
fill ~9 ~22 ~21 ~9 ~31 ~21 wool 14
fill ~9 ~22 ~22 ~9 ~31 ~22 wool 14
fill ~9 ~22 ~28 ~9 ~31 ~28 wool 14
fill ~9 ~22 ~29 ~9 ~31 ~29 wool 14
fill ~9 ~22 ~30 ~9 ~31 ~30 wool 14
fill ~10 ~22 ~19 ~12 ~22 ~19 wool 14
fill ~10 ~22 ~20 ~12 ~22 ~20 iron_block 0
fill ~10 ~22 ~21 ~10 ~31 ~21 iron_block 0
fill ~10 ~22 ~22 ~13 ~22 ~22 iron_block 0
fill ~10 ~22 ~23 ~10 ~31 ~23 wool 14
fill ~10 ~22 ~24 ~10 ~57 ~24 iron_block 0
fill ~10 ~22 ~26 ~10 ~57 ~26 iron_block 0
fill ~10 ~22 ~27 ~10 ~31 ~27 wool 14
fill ~10 ~22 ~28 ~13 ~22 ~28 iron_block 0
fill ~10 ~22 ~29 ~10 ~31 ~29 iron_block 0
fill ~10 ~22 ~30 ~12 ~22 ~30 iron_block 0
fill ~10 ~22 ~31 ~12 ~22 ~31 wool 14
fill ~11 ~22 ~23 ~12 ~22 ~23 iron_block 0
fill ~11 ~22 ~27 ~12 ~22 ~27 iron_block 0
fill ~12 ~22 ~21 ~13 ~22 ~21 iron_block 0
fill ~12 ~22 ~29 ~13 ~22 ~29 iron_block 0
fill ~13 ~22 ~20 ~13 ~31 ~20 wool 14
fill ~13 ~22 ~30 ~13 ~31 ~30 wool 14
fill ~14 ~22 ~20 ~16 ~22 ~20 iron_block 0
fill ~14 ~22 ~30 ~20 ~22 ~30 iron_block 0
fill ~17 ~22 ~20 ~17 ~31 ~20 wool 14
fill ~17 ~22 ~21 ~18 ~22 ~21 iron_block 0
fill ~17 ~22 ~22 ~20 ~22 ~22 iron_block 0
fill ~17 ~22 ~28 ~20 ~22 ~28 iron_block 0
fill ~17 ~22 ~29 ~18 ~22 ~29 iron_block 0
fill ~18 ~22 ~19 ~20 ~22 ~19 wool 14
fill ~18 ~22 ~20 ~20 ~22 ~20 iron_block 0
fill ~18 ~22 ~23 ~19 ~22 ~23 iron_block 0
fill ~18 ~22 ~27 ~19 ~22 ~27 iron_block 0
fill ~18 ~22 ~31 ~20 ~22 ~31 wool 14
fill ~20 ~22 ~21 ~20 ~31 ~21 iron_block 0
fill ~20 ~22 ~23 ~20 ~31 ~23 wool 14
fill ~20 ~22 ~24 ~20 ~46 ~24 iron_block 0
fill ~20 ~22 ~26 ~20 ~46 ~26 iron_block 0
fill ~20 ~22 ~27 ~20 ~31 ~27 wool 14
fill ~20 ~22 ~29 ~20 ~31 ~29 iron_block 0
fill ~21 ~22 ~20 ~21 ~31 ~20 wool 14
fill ~21 ~22 ~21 ~21 ~31 ~21 wool 14
fill ~21 ~22 ~22 ~21 ~31 ~22 wool 14
fill ~21 ~22 ~28 ~21 ~31 ~28 wool 14
fill ~21 ~22 ~29 ~21 ~31 ~29 wool 14
fill ~21 ~22 ~30 ~21 ~31 ~30 wool 14
fill ~10 ~23 ~19 ~12 ~23 ~19 wool 14
fill ~10 ~23 ~20 ~12 ~23 ~20 iron_block 0
fill ~10 ~23 ~22 ~13 ~23 ~22 iron_block 0
fill ~10 ~23 ~28 ~13 ~23 ~28 iron_block 0
fill ~10 ~23 ~30 ~12 ~23 ~30 iron_block 0
fill ~10 ~23 ~31 ~12 ~23 ~31 wool 14
fill ~11 ~23 ~23 ~12 ~23 ~23 iron_block 0
fill ~11 ~23 ~27 ~12 ~23 ~27 iron_block 0
fill ~12 ~23 ~21 ~13 ~23 ~21 iron_block 0
fill ~12 ~23 ~29 ~13 ~23 ~29 iron_block 0
fill ~14 ~23 ~20 ~16 ~23 ~20 iron_block 0
fill ~14 ~23 ~30 ~20 ~23 ~30 iron_block 0
fill ~17 ~23 ~21 ~18 ~23 ~21 iron_block 0
fill ~17 ~23 ~22 ~20 ~23 ~22 iron_block 0
fill ~17 ~23 ~28 ~20 ~23 ~28 iron_block 0
fill ~17 ~23 ~29 ~18 ~23 ~29 iron_block 0
fill ~18 ~23 ~19 ~20 ~23 ~19 wool 14
fill ~18 ~23 ~20 ~20 ~23 ~20 iron_block 0
fill ~18 ~23 ~23 ~19 ~23 ~23 iron_block 0
fill ~18 ~23 ~27 ~19 ~23 ~27 iron_block 0
fill ~18 ~23 ~31 ~20 ~23 ~31 wool 14
fill ~10 ~24 ~19 ~12 ~24 ~19 wool 14
fill ~10 ~24 ~20 ~12 ~24 ~20 iron_block 0
fill ~10 ~24 ~22 ~13 ~24 ~22 iron_block 0
fill ~10 ~24 ~28 ~13 ~24 ~28 iron_block 0
fill ~10 ~24 ~30 ~12 ~24 ~30 iron_block 0
fill ~10 ~24 ~31 ~12 ~24 ~31 wool 14
fill ~11 ~24 ~23 ~12 ~24 ~23 iron_block 0
fill ~11 ~24 ~27 ~12 ~24 ~27 iron_block 0
fill ~12 ~24 ~21 ~13 ~24 ~21 iron_block 0
fill ~12 ~24 ~29 ~13 ~24 ~29 iron_block 0
fill ~14 ~24 ~20 ~16 ~24 ~20 iron_block 0
fill ~14 ~24 ~30 ~20 ~24 ~30 iron_block 0
fill ~17 ~24 ~21 ~18 ~24 ~21 iron_block 0
fill ~17 ~24 ~22 ~20 ~24 ~22 iron_block 0
fill ~17 ~24 ~28 ~20 ~24 ~28 iron_block 0
fill ~17 ~24 ~29 ~18 ~24 ~29 iron_block 0
fill ~18 ~24 ~19 ~20 ~24 ~19 wool 14
fill ~18 ~24 ~20 ~20 ~24 ~20 iron_block 0
fill ~18 ~24 ~23 ~19 ~24 ~23 iron_block 0
fill ~18 ~24 ~27 ~19 ~24 ~27 iron_block 0
fill ~18 ~24 ~31 ~20 ~24 ~31 wool 14
fill ~10 ~25 ~19 ~12 ~25 ~19 wool 14
fill ~10 ~25 ~20 ~12 ~25 ~20 iron_block 0
fill ~10 ~25 ~22 ~13 ~25 ~22 iron_block 0
fill ~10 ~25 ~28 ~13 ~25 ~28 iron_block 0
fill ~10 ~25 ~30 ~12 ~25 ~30 iron_block 0
fill ~10 ~25 ~31 ~12 ~25 ~31 wool 14
fill ~11 ~25 ~23 ~12 ~25 ~23 iron_block 0
fill ~11 ~25 ~27 ~12 ~25 ~27 iron_block 0
fill ~12 ~25 ~21 ~13 ~25 ~21 iron_block 0
fill ~12 ~25 ~29 ~13 ~25 ~29 iron_block 0
fill ~14 ~25 ~20 ~16 ~25 ~20 iron_block 0
fill ~14 ~25 ~30 ~17 ~25 ~30 iron_block 0
fill ~17 ~25 ~21 ~18 ~25 ~21 iron_block 0
fill ~17 ~25 ~22 ~20 ~25 ~22 iron_block 0
fill ~17 ~25 ~28 ~20 ~25 ~28 iron_block 0
fill ~17 ~25 ~29 ~18 ~25 ~29 iron_block 0
fill ~18 ~25 ~19 ~20 ~25 ~19 wool 14
fill ~18 ~25 ~20 ~20 ~25 ~20 iron_block 0
fill ~18 ~25 ~23 ~19 ~25 ~23 iron_block 0
fill ~18 ~25 ~27 ~19 ~25 ~27 iron_block 0
fill ~18 ~25 ~30 ~18 ~25 ~31 wool 14
fill ~19 ~25 ~30 ~20 ~25 ~30 iron_block 0
fill ~19 ~25 ~31 ~20 ~25 ~31 wool 14
fill ~10 ~26 ~19 ~12 ~26 ~19 wool 14
fill ~10 ~26 ~20 ~12 ~26 ~20 iron_block 0
fill ~10 ~26 ~22 ~13 ~26 ~22 iron_block 0
fill ~10 ~26 ~28 ~13 ~26 ~28 iron_block 0
fill ~10 ~26 ~30 ~12 ~26 ~30 iron_block 0
fill ~10 ~26 ~31 ~12 ~26 ~31 wool 14
fill ~11 ~26 ~23 ~12 ~26 ~23 iron_block 0
fill ~11 ~26 ~27 ~12 ~26 ~27 iron_block 0
fill ~12 ~26 ~21 ~13 ~26 ~21 iron_block 0
fill ~12 ~26 ~29 ~13 ~26 ~29 iron_block 0
fill ~14 ~26 ~20 ~16 ~26 ~20 iron_block 0
fill ~14 ~26 ~30 ~20 ~26 ~30 iron_block 0
fill ~17 ~26 ~21 ~18 ~26 ~21 iron_block 0
fill ~17 ~26 ~22 ~20 ~26 ~22 iron_block 0
fill ~17 ~26 ~28 ~20 ~26 ~28 iron_block 0
fill ~17 ~26 ~29 ~18 ~26 ~29 iron_block 0
fill ~18 ~26 ~19 ~20 ~26 ~19 wool 14
fill ~18 ~26 ~20 ~20 ~26 ~20 iron_block 0
fill ~18 ~26 ~23 ~19 ~26 ~23 iron_block 0
fill ~18 ~26 ~27 ~19 ~26 ~27 iron_block 0
fill ~18 ~26 ~31 ~20 ~26 ~31 wool 14
fill ~10 ~27 ~19 ~12 ~27 ~19 wool 14
fill ~10 ~27 ~20 ~12 ~27 ~20 iron_block 0
fill ~10 ~27 ~22 ~13 ~27 ~22 iron_block 0
fill ~10 ~27 ~28 ~13 ~27 ~28 iron_block 0
fill ~10 ~27 ~30 ~12 ~27 ~30 iron_block 0
fill ~10 ~27 ~31 ~12 ~27 ~31 wool 14
fill ~11 ~27 ~23 ~12 ~27 ~23 iron_block 0
fill ~11 ~27 ~27 ~12 ~27 ~27 iron_block 0
fill ~12 ~27 ~21 ~13 ~27 ~21 iron_block 0
fill ~12 ~27 ~29 ~13 ~27 ~29 iron_block 0
fill ~14 ~27 ~20 ~16 ~27 ~20 iron_block 0
fill ~14 ~27 ~30 ~20 ~27 ~30 iron_block 0
fill ~17 ~27 ~21 ~18 ~27 ~21 iron_block 0
fill ~17 ~27 ~22 ~20 ~27 ~22 iron_block 0
fill ~17 ~27 ~28 ~20 ~27 ~28 iron_block 0
fill ~17 ~27 ~29 ~18 ~27 ~29 iron_block 0
fill ~18 ~27 ~19 ~20 ~27 ~19 wool 14
fill ~18 ~27 ~20 ~20 ~27 ~20 iron_block 0
fill ~18 ~27 ~23 ~19 ~27 ~23 iron_block 0
fill ~18 ~27 ~27 ~19 ~27 ~27 iron_block 0
fill ~18 ~27 ~31 ~20 ~27 ~31 wool 14
fill ~10 ~28 ~19 ~12 ~28 ~19 wool 14
fill ~10 ~28 ~20 ~12 ~28 ~20 iron_block 0
fill ~10 ~28 ~22 ~13 ~28 ~22 iron_block 0
fill ~10 ~28 ~28 ~13 ~28 ~28 iron_block 0
fill ~10 ~28 ~30 ~12 ~28 ~30 iron_block 0
fill ~10 ~28 ~31 ~12 ~28 ~31 wool 14
fill ~11 ~28 ~23 ~12 ~28 ~23 iron_block 0
fill ~11 ~28 ~27 ~12 ~28 ~27 iron_block 0
fill ~12 ~28 ~21 ~13 ~28 ~21 iron_block 0
fill ~12 ~28 ~29 ~13 ~28 ~29 iron_block 0
fill ~14 ~28 ~20 ~16 ~28 ~20 iron_block 0
fill ~14 ~28 ~30 ~20 ~28 ~30 iron_block 0
fill ~17 ~28 ~21 ~18 ~28 ~21 iron_block 0
fill ~17 ~28 ~22 ~20 ~28 ~22 iron_block 0
fill ~17 ~28 ~28 ~20 ~28 ~28 iron_block 0
fill ~17 ~28 ~29 ~18 ~28 ~29 iron_block 0
fill ~18 ~28 ~19 ~20 ~28 ~19 wool 14
fill ~18 ~28 ~20 ~20 ~28 ~20 iron_block 0
fill ~18 ~28 ~23 ~19 ~28 ~23 iron_block 0
fill ~18 ~28 ~27 ~19 ~28 ~27 iron_block 0
fill ~18 ~28 ~31 ~20 ~28 ~31 wool 14
fill ~10 ~29 ~19 ~12 ~29 ~19 wool 14
fill ~10 ~29 ~20 ~12 ~29 ~20 iron_block 0
fill ~10 ~29 ~22 ~13 ~29 ~22 iron_block 0
fill ~10 ~29 ~28 ~13 ~29 ~28 iron_block 0
fill ~10 ~29 ~30 ~12 ~29 ~30 iron_block 0
fill ~10 ~29 ~31 ~12 ~29 ~31 wool 14
fill ~11 ~29 ~23 ~12 ~29 ~23 iron_block 0
fill ~11 ~29 ~27 ~12 ~29 ~27 iron_block 0
fill ~12 ~29 ~21 ~13 ~29 ~21 iron_block 0
fill ~12 ~29 ~29 ~13 ~29 ~29 iron_block 0
fill ~14 ~29 ~20 ~16 ~29 ~20 iron_block 0
fill ~14 ~29 ~30 ~20 ~29 ~30 iron_block 0
fill ~17 ~29 ~21 ~18 ~29 ~21 iron_block 0
fill ~17 ~29 ~22 ~20 ~29 ~22 iron_block 0
fill ~17 ~29 ~28 ~20 ~29 ~28 iron_block 0
fill ~17 ~29 ~29 ~18 ~29 ~29 iron_block 0
fill ~18 ~29 ~19 ~20 ~29 ~19 wool 14
fill ~18 ~29 ~20 ~20 ~29 ~20 iron_block 0
fill ~18 ~29 ~23 ~19 ~29 ~23 iron_block 0
fill ~18 ~29 ~27 ~19 ~29 ~27 iron_block 0
fill ~18 ~29 ~31 ~20 ~29 ~31 wool 14
fill ~10 ~30 ~19 ~12 ~30 ~19 wool 14
fill ~10 ~30 ~20 ~12 ~30 ~20 iron_block 0
fill ~10 ~30 ~22 ~13 ~30 ~22 iron_block 0
fill ~10 ~30 ~28 ~13 ~30 ~28 iron_block 0
fill ~10 ~30 ~30 ~12 ~30 ~30 iron_block 0
fill ~10 ~30 ~31 ~12 ~30 ~31 wool 14
fill ~11 ~30 ~23 ~12 ~30 ~23 iron_block 0
fill ~11 ~30 ~27 ~12 ~30 ~27 iron_block 0
fill ~12 ~30 ~21 ~13 ~30 ~21 iron_block 0
fill ~12 ~30 ~29 ~13 ~30 ~29 iron_block 0
fill ~14 ~30 ~20 ~16 ~30 ~20 iron_block 0
fill ~14 ~30 ~30 ~20 ~30 ~30 iron_block 0
fill ~17 ~30 ~21 ~18 ~30 ~21 iron_block 0
fill ~17 ~30 ~22 ~20 ~30 ~22 iron_block 0
fill ~17 ~30 ~28 ~20 ~30 ~28 iron_block 0
fill ~17 ~30 ~29 ~18 ~30 ~29 iron_block 0
fill ~18 ~30 ~19 ~20 ~30 ~19 wool 14
fill ~18 ~30 ~20 ~20 ~30 ~20 iron_block 0
fill ~18 ~30 ~23 ~19 ~30 ~23 iron_block 0
fill ~18 ~30 ~27 ~19 ~30 ~27 iron_block 0
fill ~18 ~30 ~31 ~20 ~30 ~31 wool 14
fill ~10 ~31 ~19 ~12 ~31 ~19 wool 14
fill ~10 ~31 ~20 ~10 ~31 ~19 wool 14
setblock ~10 ~31 ~22 wool 14
setblock ~10 ~31 ~28 wool 14
fill ~10 ~31 ~30 ~10 ~31 ~31 wool 14
setblock ~11 ~31 ~20 iron_block 0
fill ~11 ~31 ~22 ~13 ~31 ~22 iron_block 0
fill ~11 ~31 ~23 ~12 ~31 ~23 iron_block 0
fill ~11 ~31 ~27 ~12 ~31 ~27 iron_block 0
fill ~11 ~31 ~28 ~13 ~31 ~28 iron_block 0
setblock ~11 ~31 ~30 iron_block 0
fill ~11 ~31 ~31 ~12 ~31 ~31 wool 14
setblock ~12 ~31 ~20 wool 14
fill ~12 ~31 ~29 ~13 ~31 ~29 iron_block 0
setblock ~12 ~31 ~30 wool 14
fill ~13 ~31 ~21 ~13 ~57 ~21 iron_block 0
fill ~14 ~31 ~20 ~16 ~31 ~20 iron_block 0
fill ~14 ~31 ~30 ~17 ~31 ~30 iron_block 0
fill ~17 ~31 ~21 ~18 ~31 ~21 iron_block 0
fill ~17 ~31 ~22 ~19 ~31 ~22 iron_block 0
fill ~17 ~31 ~28 ~19 ~31 ~28 iron_block 0
fill ~17 ~31 ~29 ~18 ~31 ~29 iron_block 0
fill ~18 ~31 ~19 ~20 ~31 ~19 wool 14
fill ~18 ~31 ~20 ~18 ~31 ~19 wool 14
fill ~18 ~31 ~23 ~19 ~31 ~23 iron_block 0
fill ~18 ~31 ~27 ~19 ~31 ~27 iron_block 0
fill ~18 ~31 ~30 ~18 ~31 ~31 wool 14
setblock ~19 ~31 ~20 iron_block 0
setblock ~19 ~31 ~30 iron_block 0
fill ~19 ~31 ~31 ~20 ~31 ~31 wool 14
setblock ~20 ~31 ~20 wool 14
setblock ~20 ~31 ~22 wool 14
setblock ~20 ~31 ~28 wool 14
setblock ~20 ~31 ~30 wool 14
fill ~10 ~32 ~21 ~10 ~37 ~21 wool 14
fill ~10 ~32 ~27 ~10 ~41 ~27 iron_block 0
fill ~10 ~32 ~29 ~10 ~37 ~29 wool 14
fill ~11 ~32 ~20 ~11 ~37 ~20 wool 14
fill ~11 ~32 ~22 ~11 ~37 ~22 wool 14
fill ~11 ~32 ~23 ~11 ~57 ~23 iron_block 0
fill ~11 ~32 ~28 ~11 ~37 ~28 wool 14
fill ~11 ~32 ~30 ~11 ~37 ~30 wool 14
fill ~12 ~32 ~21 ~12 ~37 ~21 wool 14
fill ~12 ~32 ~22 ~12 ~41 ~22 iron_block 0
fill ~12 ~32 ~28 ~12 ~41 ~28 iron_block 0
fill ~12 ~32 ~29 ~12 ~57 ~29 iron_block 0
fill ~13 ~32 ~30 ~17 ~32 ~30 iron_block 0
fill ~14 ~32 ~20 ~16 ~32 ~20 iron_block 0
fill ~17 ~32 ~21 ~17 ~48 ~21 iron_block 0
fill ~18 ~32 ~21 ~18 ~37 ~21 wool 14
fill ~18 ~32 ~22 ~18 ~41 ~22 iron_block 0
fill ~18 ~32 ~28 ~18 ~41 ~28 iron_block 0
fill ~18 ~32 ~29 ~18 ~37 ~29 wool 14
fill ~19 ~32 ~20 ~19 ~37 ~20 wool 14
fill ~19 ~32 ~22 ~19 ~37 ~22 wool 14
fill ~19 ~32 ~28 ~19 ~37 ~28 wool 14
fill ~19 ~32 ~30 ~19 ~37 ~30 wool 14
fill ~20 ~32 ~21 ~20 ~37 ~21 wool 14
fill ~20 ~32 ~23 ~20 ~41 ~23 iron_block 0
fill ~20 ~32 ~27 ~20 ~41 ~27 iron_block 0
fill ~20 ~32 ~29 ~20 ~37 ~29 wool 14
fill ~13 ~33 ~30 ~17 ~33 ~30 iron_block 0
fill ~14 ~33 ~20 ~16 ~33 ~20 iron_block 0
fill ~13 ~34 ~30 ~17 ~34 ~30 iron_block 0
fill ~14 ~34 ~20 ~16 ~34 ~20 iron_block 0
fill ~19 ~34 ~21 ~19 ~37 ~21 wool 14
fill ~19 ~34 ~29 ~19 ~37 ~29 wool 14
fill ~13 ~35 ~30 ~17 ~35 ~30 iron_block 0
fill ~14 ~35 ~20 ~16 ~35 ~20 iron_block 0
fill ~13 ~36 ~30 ~17 ~36 ~30 iron_block 0
fill ~14 ~36 ~20 ~16 ~36 ~20 iron_block 0
fill ~13 ~37 ~30 ~17 ~37 ~30 iron_block 0
fill ~14 ~37 ~20 ~16 ~37 ~20 iron_block 0
fill ~10 ~38 ~21 ~10 ~41 ~21 iron_block 0
fill ~10 ~38 ~29 ~10 ~41 ~29 iron_block 0
fill ~11 ~38 ~20 ~11 ~41 ~20 iron_block 0
fill ~11 ~38 ~22 ~11 ~57 ~22 iron_block 0
fill ~11 ~38 ~28 ~11 ~57 ~28 iron_block 0
fill ~11 ~38 ~30 ~11 ~41 ~30 iron_block 0
fill ~12 ~38 ~21 ~12 ~57 ~21 iron_block 0
fill ~13 ~38 ~30 ~17 ~38 ~30 iron_block 0
fill ~14 ~38 ~20 ~16 ~38 ~20 iron_block 0
fill ~18 ~38 ~21 ~18 ~47 ~21 iron_block 0
fill ~18 ~38 ~29 ~18 ~47 ~29 iron_block 0
fill ~19 ~38 ~20 ~19 ~41 ~20 iron_block 0
fill ~19 ~38 ~22 ~19 ~46 ~22 iron_block 0
fill ~19 ~38 ~28 ~19 ~46 ~28 iron_block 0
fill ~19 ~38 ~30 ~19 ~41 ~30 iron_block 0
fill ~20 ~38 ~21 ~20 ~41 ~21 iron_block 0
fill ~20 ~38 ~29 ~20 ~41 ~29 iron_block 0
fill ~13 ~39 ~30 ~17 ~39 ~30 iron_block 0
fill ~14 ~39 ~20 ~16 ~39 ~20 iron_block 0
fill ~13 ~40 ~30 ~17 ~40 ~30 iron_block 0
fill ~14 ~40 ~20 ~16 ~40 ~20 iron_block 0
fill ~11 ~41 ~25 ~20 ~41 ~25 iron_block 0
fill ~13 ~41 ~30 ~17 ~41 ~30 iron_block 0
fill ~14 ~41 ~20 ~16 ~41 ~20 iron_block 0
fill ~11 ~42 ~27 ~11 ~57 ~27 iron_block 0
fill ~13 ~42 ~29 ~13 ~57 ~29 iron_block 0
fill ~14 ~42 ~20 ~16 ~42 ~20 iron_block 0
fill ~14 ~42 ~30 ~16 ~42 ~30 iron_block 0
fill ~17 ~42 ~29 ~17 ~48 ~29 iron_block 0
fill ~19 ~42 ~23 ~19 ~46 ~23 iron_block 0
fill ~19 ~42 ~27 ~19 ~46 ~27 iron_block 0
fill ~14 ~43 ~20 ~16 ~43 ~20 iron_block 0
fill ~14 ~43 ~30 ~16 ~43 ~30 iron_block 0
fill ~14 ~44 ~20 ~16 ~44 ~20 iron_block 0
fill ~14 ~44 ~30 ~16 ~44 ~30 iron_block 0
fill ~14 ~45 ~20 ~16 ~45 ~20 iron_block 0
fill ~14 ~45 ~30 ~16 ~45 ~30 iron_block 0
fill ~14 ~46 ~20 ~16 ~46 ~20 iron_block 0
fill ~14 ~46 ~30 ~16 ~46 ~30 iron_block 0
fill ~14 ~47 ~20 ~16 ~47 ~20 iron_block 0
fill ~14 ~47 ~30 ~16 ~47 ~30 iron_block 0
fill ~19 ~47 ~22 ~19 ~47 ~23 obsidian 0
fill ~19 ~47 ~27 ~19 ~47 ~28 obsidian 0
fill ~20 ~47 ~24 ~20 ~48 ~24 obsidian 0
fill ~20 ~47 ~25 ~20 ~49 ~25 obsidian 0
fill ~20 ~47 ~26 ~20 ~48 ~26 obsidian 0
fill ~14 ~48 ~20 ~16 ~48 ~20 iron_block 0
fill ~14 ~48 ~30 ~16 ~48 ~30 iron_block 0
setblock ~18 ~48 ~21 obsidian 0
setblock ~18 ~48 ~29 obsidian 0
fill ~19 ~48 ~22 ~19 ~50 ~22 gold_block 0
fill ~19 ~48 ~23 ~19 ~50 ~23 gold_block 0
fill ~19 ~48 ~27 ~19 ~50 ~27 gold_block 0
fill ~19 ~48 ~28 ~19 ~50 ~28 gold_block 0
fill ~14 ~49 ~20 ~15 ~49 ~20 iron_block 0
fill ~14 ~49 ~30 ~15 ~49 ~30 iron_block 0
fill ~16 ~49 ~20 ~16 ~51 ~20 obsidian 0
fill ~16 ~49 ~30 ~16 ~51 ~30 obsidian 0
fill ~17 ~49 ~21 ~17 ~51 ~21 obsidian 0
fill ~17 ~49 ~29 ~17 ~51 ~29 obsidian 0
fill ~18 ~49 ~21 ~18 ~50 ~21 gold_block 0
fill ~18 ~49 ~29 ~18 ~50 ~29 gold_block 0
setblock ~20 ~49 ~24 gold_block 0
setblock ~20 ~49 ~26 gold_block 0
fill ~14 ~50 ~20 ~15 ~50 ~20 iron_block 0
fill ~14 ~50 ~30 ~15 ~50 ~30 iron_block 0
setblock ~20 ~50 ~24 obsidian 0
setblock ~20 ~50 ~25 gold_block 0
setblock ~20 ~50 ~26 obsidian 0
fill ~14 ~51 ~20 ~15 ~51 ~20 iron_block 0
fill ~14 ~51 ~30 ~15 ~51 ~30 iron_block 0
fill ~18 ~51 ~21 ~18 ~52 ~21 obsidian 0
fill ~18 ~51 ~29 ~18 ~52 ~29 obsidian 0
fill ~19 ~51 ~22 ~19 ~53 ~22 obsidian 0
fill ~19 ~51 ~23 ~19 ~51 ~22 obsidian 0
setblock ~19 ~51 ~27 wool 15
fill ~19 ~51 ~28 ~19 ~54 ~28 obsidian 0
fill ~20 ~51 ~24 ~20 ~53 ~24 gold_block 0
setblock ~20 ~51 ~25 obsidian 0
fill ~20 ~51 ~26 ~20 ~53 ~26 gold_block 0
fill ~14 ~52 ~20 ~16 ~52 ~20 iron_block 0
fill ~14 ~52 ~30 ~16 ~52 ~30 iron_block 0
fill ~17 ~52 ~21 ~17 ~57 ~21 iron_block 0
fill ~17 ~52 ~29 ~17 ~56 ~29 iron_block 0
fill ~19 ~52 ~23 ~19 ~53 ~23 gold_block 0
fill ~19 ~52 ~27 ~19 ~53 ~27 gold_block 0
fill ~20 ~52 ~25 ~20 ~53 ~25 gold_block 0
fill ~14 ~53 ~20 ~16 ~53 ~20 iron_block 0
fill ~14 ~53 ~30 ~16 ~53 ~30 iron_block 0
fill ~18 ~53 ~21 ~18 ~57 ~21 iron_block 0
fill ~18 ~53 ~29 ~18 ~57 ~29 iron_block 0
fill ~14 ~54 ~20 ~16 ~54 ~20 iron_block 0
fill ~14 ~54 ~30 ~16 ~54 ~30 iron_block 0
fill ~19 ~54 ~22 ~19 ~57 ~22 iron_block 0
setblock ~19 ~54 ~23 obsidian 0
setblock ~19 ~54 ~27 obsidian 0
fill ~20 ~54 ~24 ~20 ~54 ~26 obsidian 0
fill ~14 ~55 ~20 ~16 ~55 ~20 iron_block 0
fill ~14 ~55 ~30 ~16 ~55 ~30 iron_block 0
fill ~19 ~55 ~23 ~19 ~56 ~23 iron_block 0
fill ~19 ~55 ~27 ~19 ~56 ~27 iron_block 0
fill ~19 ~55 ~28 ~19 ~57 ~28 iron_block 0
fill ~20 ~55 ~24 ~20 ~57 ~24 iron_block 0
fill ~20 ~55 ~25 ~20 ~57 ~25 iron_block 0
fill ~20 ~55 ~26 ~20 ~57 ~26 iron_block 0
fill ~4 ~56 ~25 ~9 ~56 ~25 wool 14
fill ~11 ~56 ~25 ~19 ~56 ~25 wool 14
fill ~14 ~56 ~20 ~16 ~56 ~20 iron_block 0
fill ~14 ~56 ~30 ~16 ~56 ~30 iron_block 0
fill ~11 ~57 ~24 ~11 ~61 ~24 obsidian 0
fill ~11 ~57 ~25 ~11 ~61 ~25 obsidian 0
fill ~11 ~57 ~26 ~11 ~61 ~26 obsidian 0
fill ~12 ~57 ~22 ~12 ~61 ~22 obsidian 0
fill ~12 ~57 ~25 ~14 ~57 ~25 redstone_torch 5
fill ~12 ~57 ~28 ~12 ~61 ~28 obsidian 0
fill ~14 ~57 ~20 ~16 ~57 ~20 iron_block 0
fill ~14 ~57 ~21 ~16 ~57 ~21 obsidian 0
fill ~14 ~57 ~29 ~17 ~57 ~29 obsidian 0
fill ~14 ~57 ~30 ~16 ~57 ~30 iron_block 0
fill ~16 ~57 ~25 ~18 ~57 ~25 redstone_torch 5
fill ~18 ~57 ~22 ~18 ~61 ~22 obsidian 0
fill ~18 ~57 ~28 ~18 ~61 ~28 obsidian 0
fill ~19 ~57 ~23 ~19 ~61 ~23 obsidian 0
fill ~19 ~57 ~24 ~19 ~61 ~24 obsidian 0
fill ~19 ~57 ~25 ~19 ~61 ~25 obsidian 0
fill ~19 ~57 ~26 ~19 ~61 ~26 obsidian 0
fill ~19 ~57 ~27 ~19 ~61 ~27 obsidian 0
fill ~11 ~58 ~23 ~11 ~61 ~23 obsidian 0
fill ~11 ~58 ~27 ~11 ~61 ~27 obsidian 0
fill ~13 ~58 ~21 ~17 ~58 ~21 obsidian 0
fill ~13 ~58 ~29 ~17 ~58 ~29 obsidian 0
fill ~13 ~59 ~21 ~17 ~59 ~21 obsidian 0
fill ~13 ~59 ~29 ~17 ~59 ~29 obsidian 0
fill ~13 ~60 ~21 ~17 ~60 ~21 obsidian 0
fill ~13 ~60 ~29 ~17 ~60 ~29 obsidian 0
fill ~10 ~61 ~23 ~10 ~63 ~23 wool 14
fill ~10 ~61 ~24 ~10 ~63 ~24 wool 14
fill ~10 ~61 ~25 ~10 ~63 ~25 wool 14
fill ~10 ~61 ~26 ~10 ~63 ~26 wool 14
fill ~10 ~61 ~27 ~10 ~63 ~27 wool 14
fill ~11 ~61 ~22 ~11 ~63 ~22 wool 14
fill ~11 ~61 ~28 ~11 ~63 ~28 wool 14
fill ~12 ~61 ~21 ~12 ~63 ~21 wool 14
fill ~12 ~61 ~25 ~18 ~61 ~25 wool 14
fill ~12 ~61 ~29 ~12 ~63 ~29 wool 14
fill ~13 ~61 ~20 ~17 ~61 ~20 wool 14
fill ~13 ~61 ~21 ~17 ~61 ~21 obsidian 0
fill ~13 ~61 ~29 ~17 ~61 ~29 obsidian 0
fill ~13 ~61 ~30 ~17 ~61 ~30 wool 14
fill ~18 ~61 ~21 ~18 ~63 ~21 wool 14
fill ~18 ~61 ~29 ~18 ~63 ~29 wool 14
fill ~19 ~61 ~22 ~19 ~63 ~22 wool 14
fill ~19 ~61 ~28 ~19 ~63 ~28 wool 14
fill ~20 ~61 ~23 ~20 ~63 ~23 wool 14
fill ~20 ~61 ~24 ~20 ~63 ~24 wool 14
fill ~20 ~61 ~25 ~20 ~63 ~25 wool 14
fill ~20 ~61 ~26 ~20 ~63 ~26 wool 14
fill ~20 ~61 ~27 ~20 ~63 ~27 wool 14
fill ~13 ~62 ~20 ~17 ~62 ~20 wool 14
fill ~13 ~62 ~30 ~17 ~62 ~30 wool 14
fill ~11 ~63 ~23 ~11 ~63 ~28 wool 14
setblock ~12 ~63 ~22 wool 14
setblock ~12 ~63 ~28 wool 14
fill ~13 ~63 ~20 ~17 ~63 ~20 wool 14
fill ~13 ~63 ~21 ~18 ~63 ~21 wool 14
fill ~13 ~63 ~29 ~18 ~63 ~29 wool 14
fill ~13 ~63 ~30 ~17 ~63 ~30 wool 14
setblock ~18 ~63 ~22 wool 14
setblock ~18 ~63 ~28 wool 14
fill ~19 ~63 ~23 ~19 ~63 ~28 wool 14
fill ~10 ~64 ~24 ~10 ~64 ~26 iron_block 0
fill ~11 ~64 ~23 ~11 ~65 ~23 iron_block 0
fill ~11 ~64 ~24 ~11 ~64 ~26 wool 14
fill ~11 ~64 ~27 ~11 ~65 ~27 iron_block 0
fill ~12 ~64 ~22 ~12 ~65 ~22 iron_block 0
fill ~12 ~64 ~28 ~12 ~65 ~28 iron_block 0
fill ~13 ~64 ~21 ~13 ~65 ~21 iron_block 0
fill ~13 ~64 ~29 ~13 ~65 ~29 iron_block 0
fill ~14 ~64 ~20 ~16 ~64 ~20 iron_block 0
fill ~14 ~64 ~21 ~15 ~64 ~21 wool 14
fill ~14 ~64 ~29 ~15 ~64 ~29 wool 14
fill ~14 ~64 ~30 ~16 ~64 ~30 iron_block 0
fill ~16 ~64 ~21 ~17 ~64 ~21 iron_block 0
fill ~16 ~64 ~29 ~17 ~64 ~29 iron_block 0
fill ~18 ~64 ~22 ~18 ~65 ~22 iron_block 0
fill ~18 ~64 ~28 ~18 ~65 ~28 iron_block 0
fill ~19 ~64 ~23 ~19 ~65 ~23 iron_block 0
fill ~19 ~64 ~24 ~19 ~64 ~26 wool 14
fill ~19 ~64 ~27 ~19 ~65 ~27 iron_block 0
fill ~20 ~64 ~24 ~20 ~64 ~26 iron_block 0
fill ~11 ~65 ~24 ~12 ~65 ~24 iron_block 0
fill ~11 ~65 ~25 ~12 ~65 ~25 iron_block 0
fill ~11 ~65 ~26 ~12 ~65 ~26 iron_block 0
fill ~12 ~65 ~23 ~12 ~68 ~23 iron_block 0
fill ~12 ~65 ~27 ~12 ~68 ~27 iron_block 0
fill ~13 ~65 ~22 ~18 ~65 ~22 iron_block 0
fill ~13 ~65 ~28 ~18 ~65 ~28 iron_block 0
fill ~14 ~65 ~21 ~17 ~65 ~21 iron_block 0
fill ~14 ~65 ~29 ~17 ~65 ~29 iron_block 0
fill ~17 ~65 ~23 ~19 ~65 ~23 iron_block 0
fill ~17 ~65 ~27 ~19 ~65 ~27 iron_block 0
fill ~18 ~65 ~24 ~19 ~65 ~24 iron_block 0
fill ~18 ~65 ~25 ~19 ~65 ~25 iron_block 0
fill ~18 ~65 ~26 ~19 ~65 ~26 iron_block 0
fill ~11 ~66 ~24 ~12 ~66 ~24 iron_block 0
fill ~11 ~66 ~25 ~12 ~66 ~25 iron_block 0
fill ~11 ~66 ~26 ~12 ~66 ~26 iron_block 0
fill ~13 ~66 ~22 ~17 ~66 ~22 iron_block 0
fill ~13 ~66 ~23 ~13 ~70 ~23 iron_block 0
fill ~13 ~66 ~27 ~13 ~70 ~27 iron_block 0
fill ~13 ~66 ~28 ~17 ~66 ~28 iron_block 0
fill ~14 ~66 ~21 ~16 ~66 ~21 iron_block 0
fill ~14 ~66 ~29 ~16 ~66 ~29 iron_block 0
fill ~16 ~66 ~27 ~18 ~66 ~27 iron_block 0
fill ~17 ~66 ~23 ~18 ~66 ~23 iron_block 0
fill ~17 ~66 ~24 ~19 ~66 ~24 iron_block 0
fill ~17 ~66 ~25 ~19 ~66 ~25 iron_block 0
fill ~17 ~66 ~26 ~19 ~66 ~26 iron_block 0
fill ~11 ~67 ~25 ~13 ~67 ~25 iron_block 0
fill ~12 ~67 ~24 ~13 ~67 ~24 iron_block 0
fill ~12 ~67 ~26 ~13 ~67 ~26 iron_block 0
fill ~13 ~67 ~22 ~17 ~67 ~22 iron_block 0
fill ~13 ~67 ~28 ~17 ~67 ~28 iron_block 0
fill ~14 ~67 ~23 ~18 ~67 ~23 iron_block 0
fill ~14 ~67 ~27 ~18 ~67 ~27 iron_block 0
fill ~15 ~67 ~21 ~15 ~68 ~21 iron_block 0
fill ~15 ~67 ~29 ~15 ~68 ~29 iron_block 0
fill ~16 ~67 ~25 ~19 ~67 ~25 iron_block 0
fill ~16 ~67 ~26 ~18 ~67 ~26 iron_block 0
fill ~17 ~67 ~24 ~18 ~67 ~24 iron_block 0
fill ~11 ~68 ~25 ~14 ~68 ~25 iron_block 0
fill ~12 ~68 ~24 ~18 ~68 ~24 iron_block 0
fill ~12 ~68 ~26 ~18 ~68 ~26 iron_block 0
fill ~13 ~68 ~22 ~17 ~68 ~22 iron_block 0
fill ~13 ~68 ~28 ~17 ~68 ~28 iron_block 0
fill ~14 ~68 ~23 ~18 ~68 ~23 iron_block 0
fill ~14 ~68 ~27 ~18 ~68 ~27 iron_block 0
fill ~16 ~68 ~25 ~19 ~68 ~25 iron_block 0
fill ~12 ~69 ~25 ~18 ~69 ~25 iron_block 0
fill ~13 ~69 ~24 ~17 ~69 ~24 iron_block 0
fill ~13 ~69 ~26 ~17 ~69 ~26 iron_block 0
fill ~14 ~69 ~23 ~17 ~69 ~23 iron_block 0
fill ~14 ~69 ~27 ~17 ~69 ~27 iron_block 0
fill ~15 ~69 ~22 ~15 ~70 ~22 iron_block 0
fill ~15 ~69 ~28 ~15 ~70 ~28 iron_block 0
fill ~12 ~70 ~25 ~18 ~70 ~25 iron_block 0
fill ~13 ~70 ~24 ~17 ~70 ~24 iron_block 0
fill ~13 ~70 ~26 ~17 ~70 ~26 iron_block 0
fill ~14 ~70 ~23 ~17 ~70 ~23 iron_block 0
fill ~14 ~70 ~27 ~17 ~70 ~27 iron_block 0
fill ~13 ~71 ~25 ~17 ~71 ~25 iron_block 0
fill ~14 ~71 ~24 ~16 ~71 ~24 iron_block 0
fill ~14 ~71 ~26 ~16 ~71 ~26 iron_block 0
fill ~15 ~71 ~23 ~15 ~72 ~23 iron_block 0
fill ~15 ~71 ~27 ~15 ~72 ~27 iron_block 0
fill ~13 ~72 ~25 ~17 ~72 ~25 iron_block 0
fill ~14 ~72 ~24 ~16 ~72 ~24 iron_block 0
fill ~14 ~72 ~26 ~16 ~72 ~26 iron_block 0
fill ~14 ~73 ~25 ~16 ~73 ~25 iron_block 0
fill ~15 ~73 ~24 ~15 ~74 ~24 iron_block 0
fill ~15 ~73 ~26 ~15 ~74 ~26 iron_block 0
fill ~14 ~74 ~25 ~16 ~74 ~25 iron_block 0
fill ~15 ~75 ~25 ~15 ~76 ~25 iron_block 0