setblock ~1 ~-3 ~0 grass 0
fill ~5 ~-3 ~35 ~5 ~3 ~35 fence 0
fill ~6 ~-3 ~30 ~6 ~-3 ~32 stone_slab 3
fill ~6 ~-3 ~33 ~6 ~-3 ~40 grass 0
fill ~7 ~-3 ~22 ~20 ~-3 ~22 grass 0
fill ~7 ~-3 ~23 ~16 ~-3 ~23 grass 0
fill ~7 ~-3 ~24 ~14 ~-3 ~24 grass 0
fill ~7 ~-3 ~25 ~13 ~-3 ~25 grass 0
fill ~7 ~-3 ~26 ~8 ~-3 ~26 grass 0
fill ~7 ~-3 ~27 ~7 ~-3 ~29 stone_slab 3
fill ~7 ~-3 ~30 ~8 ~-3 ~30 wool 11
setblock ~7 ~-3 ~31 stained_glass 3
setblock ~7 ~-3 ~32 lapis_ore 0
fill ~7 ~-3 ~33 ~8 ~-3 ~33 stained_glass 9
fill ~7 ~-3 ~34 ~8 ~-3 ~34 grass 0
fill ~7 ~-3 ~35 ~10 ~-3 ~35 grass 0
fill ~7 ~-3 ~36 ~12 ~-3 ~36 grass 0
fill ~7 ~-3 ~37 ~16 ~-3 ~37 grass 0
fill ~7 ~-3 ~38 ~12 ~-3 ~38 grass 0
fill ~7 ~-3 ~39 ~18 ~-3 ~39 grass 0
fill ~7 ~-3 ~40 ~18 ~-3 ~40 grass 0
fill ~7 ~-3 ~41 ~18 ~-3 ~41 grass 0
fill ~7 ~-3 ~42 ~17 ~-3 ~42 grass 0
fill ~8 ~-3 ~19 ~21 ~-3 ~19 grass 0
fill ~8 ~-3 ~20 ~21 ~-3 ~20 grass 0
fill ~8 ~-3 ~21 ~21 ~-3 ~21 grass 0
setblock ~8 ~-3 ~27 wool 11
fill ~8 ~-3 ~28 ~8 ~-3 ~29 lapis_ore 0
fill ~8 ~-3 ~31 ~8 ~-3 ~32 cobblestone 0
fill ~8 ~-3 ~43 ~17 ~-3 ~43 grass 0
fill ~8 ~-3 ~44 ~16 ~-3 ~44 grass 0
fill ~8 ~-3 ~45 ~16 ~-3 ~45 grass 0
fill ~9 ~-3 ~17 ~21 ~-3 ~17 grass 0
fill ~9 ~-3 ~18 ~21 ~-3 ~18 grass 0
setblock ~9 ~-3 ~26 lapis_ore 0
fill ~9 ~-3 ~27 ~11 ~-3 ~27 stone 0
fill ~9 ~-3 ~28 ~9 ~-3 ~29 stained_glass 9
setblock ~9 ~-3 ~30 lapis_ore 0
setblock ~9 ~-3 ~31 stained_glass 9
fill ~9 ~-3 ~32 ~9 ~-3 ~33 lapis_ore 0
setblock ~9 ~-3 ~34 stone 0
fill ~9 ~-3 ~46 ~16 ~-3 ~46 grass 0
fill ~9 ~-3 ~47 ~16 ~-3 ~47 grass 0
fill ~9 ~-3 ~48 ~16 ~-3 ~48 grass 0
fill ~10 ~-3 ~14 ~21 ~-3 ~14 grass 0
fill ~10 ~-3 ~15 ~21 ~-3 ~15 grass 0
fill ~10 ~-3 ~16 ~21 ~-3 ~16 grass 0
fill ~10 ~-3 ~26 ~13 ~-3 ~26 grass 0
setblock ~10 ~-3 ~28 wool 11
fill ~10 ~-3 ~29 ~11 ~-3 ~29 stained_glass 9
setblock ~10 ~-3 ~30 stone 0
fill ~10 ~-3 ~31 ~10 ~-3 ~32 cobblestone 0
setblock ~10 ~-3 ~33 stone 0
setblock ~10 ~-3 ~34 wool 11
fill ~10 ~-3 ~49 ~17 ~-3 ~49 grass 0
fill ~10 ~-3 ~50 ~18 ~-3 ~50 grass 0
fill ~10 ~-3 ~51 ~19 ~-3 ~51 grass 0
fill ~11 ~-3 ~12 ~22 ~-3 ~12 grass 0
fill ~11 ~-3 ~13 ~21 ~-3 ~13 grass 0
fill ~11 ~-3 ~28 ~12 ~-3 ~28 cobblestone 0
setblock ~11 ~-3 ~30 cobblestone 0
setblock ~11 ~-3 ~31 stone 0
fill ~11 ~-3 ~32 ~11 ~-3 ~33 stained_glass 9
setblock ~11 ~-3 ~34 cobblestone 0
setblock ~11 ~-3 ~35 wool 11
fill ~11 ~-3 ~52 ~13 ~-3 ~52 grass 0
fill ~11 ~-3 ~53 ~20 ~-3 ~53 grass 0
fill ~12 ~-3 ~11 ~22 ~-3 ~11 grass 0
fill ~12 ~-3 ~29 ~12 ~-3 ~30 stained_glass 3
setblock ~12 ~-3 ~31 wool 11
setblock ~12 ~-3 ~32 cobblestone 0
setblock ~12 ~-3 ~33 wool 11
setblock ~12 ~-3 ~34 lapis_ore 0
setblock ~12 ~-3 ~35 wool 3
fill ~12 ~-3 ~54 ~20 ~-3 ~54 grass 0
fill ~12 ~-3 ~55 ~21 ~-3 ~55 grass 0
fill ~12 ~-3 ~56 ~21 ~-3 ~56 grass 0
fill ~13 ~-3 ~9 ~22 ~-3 ~9 grass 0
fill ~13 ~-3 ~10 ~22 ~-3 ~10 grass 0
fill ~13 ~-3 ~27 ~14 ~-3 ~27 wool 11
setblock ~13 ~-3 ~28 lapis_ore 0
setblock ~13 ~-3 ~29 wool 11
setblock ~13 ~-3 ~30 stained_glass 3
setblock ~13 ~-3 ~31 stone 0
setblock ~13 ~-3 ~32 stained_glass 9
setblock ~13 ~-3 ~33 lapis_ore 0
setblock ~13 ~-3 ~34 cobblestone 0
setblock ~13 ~-3 ~35 wool 11
setblock ~13 ~-3 ~36 wool 3
fill ~13 ~-3 ~57 ~22 ~-3 ~57 grass 0
fill ~13 ~-3 ~58 ~22 ~-3 ~58 grass 0
fill ~13 ~-3 ~59 ~23 ~-3 ~59 grass 0
fill ~14 ~-3 ~7 ~23 ~-3 ~7 grass 0
fill ~14 ~-3 ~8 ~23 ~-3 ~8 grass 0
fill ~14 ~-3 ~25 ~14 ~-3 ~26 lapis_ore 0
setblock ~14 ~-3 ~28 cobblestone 0
setblock ~14 ~-3 ~29 stained_glass 3
setblock ~14 ~-3 ~30 lapis_ore 0
setblock ~14 ~-3 ~31 stained_glass 9
setblock ~14 ~-3 ~32 wool 11
setblock ~14 ~-3 ~33 stained_glass 9
setblock ~14 ~-3 ~34 stone 0
setblock ~14 ~-3 ~35 stained_glass 9
setblock ~14 ~-3 ~36 lapis_ore 0
fill ~14 ~-3 ~38 ~17 ~-3 ~38 grass 0
fill ~14 ~-3 ~60 ~23 ~-3 ~60 grass 0
fill ~15 ~-3 ~5 ~24 ~-3 ~5 grass 0
fill ~15 ~-3 ~6 ~24 ~-3 ~6 grass 0
setblock ~15 ~-3 ~24 cobblestone 0
setblock ~15 ~-3 ~25 wool 11
setblock ~15 ~-3 ~26 lapis_ore 0
setblock ~15 ~-3 ~27 stained_glass 9
setblock ~15 ~-3 ~28 stone 0
fill ~15 ~-3 ~29 ~15 ~-3 ~30 stained_glass 9
setblock ~15 ~-3 ~31 wool 11
setblock ~15 ~-3 ~32 lapis_ore 0
setblock ~15 ~-3 ~33 wool 11
setblock ~15 ~-3 ~34 stained_glass 9
setblock ~15 ~-3 ~35 lapis_ore 0
setblock ~15 ~-3 ~36 grass 0
fill ~15 ~-3 ~52 ~19 ~-3 ~52 grass 0
fill ~15 ~-3 ~61 ~24 ~-3 ~61 grass 0
fill ~16 ~-3 ~3 ~22 ~-3 ~3 grass 0
fill ~16 ~-3 ~4 ~25 ~-3 ~4 grass 0
fill ~16 ~-3 ~24 ~17 ~-3 ~24 lapis_ore 0
setblock ~16 ~-3 ~25 cobblestone 0
fill ~16 ~-3 ~26 ~16 ~-3 ~27 stone 0
fill ~16 ~-3 ~28 ~17 ~-3 ~28 wool 11
setblock ~16 ~-3 ~29 stained_glass 3
setblock ~16 ~-3 ~30 stone 0
setblock ~16 ~-3 ~31 cobblestone 0
setblock ~16 ~-3 ~32 stone 0
setblock ~16 ~-3 ~33 stained_glass 9
setblock ~16 ~-3 ~34 lapis_ore 0
setblock ~16 ~-3 ~35 wool 3
setblock ~16 ~-3 ~36 lapis_ore 0
fill ~16 ~-3 ~62 ~25 ~-3 ~62 grass 0
fill ~16 ~-3 ~63 ~17 ~-3 ~63 grass 0
fill ~17 ~-3 ~2 ~27 ~-3 ~2 grass 0
setblock ~17 ~-3 ~23 wool 11
fill ~17 ~-3 ~25 ~18 ~-3 ~25 stained_glass 9
fill ~17 ~-3 ~26 ~17 ~-3 ~27 stained_glass 9
setblock ~17 ~-3 ~29 stone 0
setblock ~17 ~-3 ~30 stained_glass 9
setblock ~17 ~-3 ~31 stone 0
fill ~17 ~-3 ~64 ~26 ~-3 ~64 grass 0
fill ~17 ~-3 ~65 ~27 ~-3 ~65 grass 0
fill ~18 ~-3 ~1 ~28 ~-3 ~1 grass 0
fill ~18 ~-3 ~23 ~18 ~-3 ~24 wool 3
setblock ~18 ~-3 ~26 lapis_ore 0
fill ~18 ~-3 ~66 ~29 ~-3 ~66 grass 0
setblock ~19 ~-3 ~23 grass 0
setblock ~19 ~-3 ~24 lapis_ore 0
fill ~19 ~-3 ~63 ~25 ~-3 ~63 grass 0
fill ~19 ~-3 ~67 ~31 ~-3 ~67 grass 0
fill ~20 ~-3 ~0 ~29 ~-3 ~0 grass 0
fill ~20 ~-3 ~68 ~30 ~-3 ~68 grass 0
fill ~21 ~-3 ~69 ~33 ~-3 ~69 grass 0
fill ~22 ~-3 ~70 ~34 ~-3 ~70 grass 0
fill ~24 ~-3 ~3 ~26 ~-3 ~3 grass 0
setblock ~32 ~-3 ~68 grass 0
setblock ~37 ~-3 ~31 glowstone 0
fill ~39 ~-3 ~44 ~39 ~-3 ~45 stained_hardened_clay 2
setblock ~40 ~-3 ~45 stained_hardened_clay 2
setblock ~49 ~-3 ~15 glowstone 0
setblock ~54 ~-3 ~16 stained_hardened_clay 14
setblock ~55 ~-3 ~15 stained_hardened_clay 14
fill ~55 ~-3 ~17 ~55 ~-2 ~17 stained_hardened_clay 14
setblock ~56 ~-3 ~16 stained_hardened_clay 14
setblock ~57 ~-3 ~45 glowstone 0
fill ~57 ~-3 ~70 ~80 ~-3 ~70 grass 0
fill ~59 ~-3 ~69 ~82 ~-3 ~69 grass 0
fill ~61 ~-3 ~68 ~85 ~-3 ~68 grass 0
fill ~63 ~-3 ~67 ~88 ~-3 ~67 grass 0
fill ~65 ~-3 ~66 ~70 ~-3 ~66 grass 0
fill ~67 ~-3 ~65 ~69 ~-3 ~65 grass 0
fill ~76 ~-3 ~66 ~90 ~-3 ~66 grass 0
fill ~78 ~-3 ~65 ~91 ~-3 ~65 grass 0
fill ~82 ~-3 ~64 ~92 ~-3 ~64 grass 0
fill ~84 ~-3 ~63 ~93 ~-3 ~63 grass 0
fill ~85 ~-3 ~62 ~93 ~-3 ~62 grass 0
fill ~86 ~-3 ~61 ~94 ~-3 ~61 grass 0
fill ~87 ~-3 ~60 ~94 ~-3 ~60 grass 0
fill ~88 ~-3 ~0 ~96 ~-3 ~0 grass 0
fill ~88 ~-3 ~58 ~94 ~-3 ~58 grass 0
fill ~88 ~-3 ~59 ~90 ~-3 ~59 grass 0
fill ~89 ~-3 ~1 ~96 ~-3 ~1 grass 0
fill ~89 ~-3 ~2 ~96 ~-3 ~2 grass 0
fill ~89 ~-3 ~55 ~95 ~-3 ~55 grass 0
fill ~89 ~-3 ~56 ~95 ~-3 ~56 grass 0
fill ~89 ~-3 ~57 ~95 ~-3 ~57 grass 0
fill ~90 ~-3 ~3 ~91 ~-3 ~3 grass 0
fill ~90 ~-3 ~53 ~96 ~-3 ~53 grass 0
fill ~90 ~-3 ~54 ~95 ~-3 ~54 grass 0
fill ~91 ~-3 ~4 ~97 ~-3 ~4 grass 0
fill ~91 ~-3 ~5 ~97 ~-3 ~5 grass 0
fill ~91 ~-3 ~52 ~96 ~-3 ~52 grass 0
fill ~92 ~-3 ~6 ~97 ~-3 ~6 grass 0
fill ~92 ~-3 ~7 ~97 ~-3 ~7 grass 0
fill ~92 ~-3 ~51 ~96 ~-3 ~51 grass 0
fill ~92 ~-3 ~59 ~94 ~-3 ~59 grass 0
fill ~93 ~-3 ~3 ~97 ~-3 ~3 grass 0
fill ~93 ~-3 ~8 ~97 ~-3 ~8 grass 0
fill ~93 ~-3 ~9 ~97 ~-3 ~9 grass 0
fill ~93 ~-3 ~49 ~97 ~-3 ~49 grass 0
fill ~93 ~-3 ~50 ~97 ~-3 ~50 grass 0
fill ~94 ~-3 ~10 ~97 ~-3 ~10 grass 0
fill ~94 ~-3 ~11 ~97 ~-3 ~11 grass 0
fill ~94 ~-3 ~47 ~97 ~-3 ~47 grass 0
fill ~94 ~-3 ~48 ~97 ~-3 ~48 grass 0
fill ~95 ~-3 ~12 ~97 ~-3 ~12 grass 0
fill ~95 ~-3 ~13 ~97 ~-3 ~13 grass 0
fill ~95 ~-3 ~14 ~97 ~-3 ~14 grass 0
fill ~95 ~-3 ~33 ~97 ~-3 ~33 grass 0
fill ~95 ~-3 ~34 ~97 ~-3 ~34 grass 0
fill ~95 ~-3 ~35 ~97 ~-3 ~35 grass 0
fill ~95 ~-3 ~36 ~97 ~-3 ~36 grass 0
fill ~95 ~-3 ~44 ~97 ~-3 ~44 grass 0
fill ~95 ~-3 ~45 ~97 ~-3 ~45 grass 0
fill ~95 ~-3 ~46 ~97 ~-3 ~46 grass 0
fill ~96 ~-3 ~15 ~97 ~-3 ~15 grass 0
fill ~96 ~-3 ~16 ~97 ~-3 ~16 grass 0
fill ~96 ~-3 ~17 ~97 ~-3 ~17 grass 0
fill ~96 ~-3 ~31 ~97 ~-3 ~31 grass 0
fill ~96 ~-3 ~32 ~97 ~-3 ~32 grass 0
fill ~96 ~-3 ~37 ~97 ~-3 ~37 grass 0
fill ~96 ~-3 ~38 ~97 ~-3 ~38 grass 0
fill ~96 ~-3 ~39 ~97 ~-3 ~39 grass 0
fill ~96 ~-3 ~40 ~97 ~-3 ~40 grass 0
fill ~96 ~-3 ~41 ~97 ~-3 ~41 grass 0
fill ~96 ~-3 ~42 ~97 ~-3 ~42 grass 0
fill ~96 ~-3 ~43 ~97 ~-3 ~43 grass 0
fill ~97 ~-3 ~18 ~97 ~-3 ~20 grass 0
fill ~6 ~-2 ~35 ~7 ~-2 ~35 tallgrass 1
setblock ~6 ~-2 ~38 tallgrass 1
setblock ~7 ~-2 ~25 tallgrass 1
fill ~7 ~-2 ~34 ~8 ~-2 ~34 tallgrass 1
fill ~7 ~-2 ~37 ~8 ~-2 ~37 tallgrass 1
fill ~7 ~-2 ~39 ~8 ~-2 ~39 tallgrass 1
fill ~7 ~-2 ~40 ~9 ~-2 ~40 tallgrass 1
fill ~7 ~-2 ~41 ~7 ~-2 ~39 tallgrass 1
fill ~8 ~-2 ~24 ~9 ~-2 ~24 tallgrass 1
setblock ~8 ~-2 ~26 tallgrass 1
fill ~8 ~-2 ~36 ~11 ~-2 ~36 tallgrass 1
fill ~8 ~-2 ~38 ~9 ~-2 ~38 tallgrass 1
fill ~9 ~-2 ~22 ~11 ~-2 ~22 tallgrass 1
fill ~9 ~-2 ~23 ~9 ~-2 ~22 tallgrass 1
fill ~9 ~-2 ~25 ~11 ~-2 ~25 tallgrass 1
setblock ~9 ~-2 ~35 tallgrass 1
fill ~9 ~-2 ~41 ~10 ~-2 ~41 tallgrass 1
fill ~9 ~-2 ~46 ~15 ~-2 ~46 tallgrass 1
fill ~9 ~-2 ~47 ~13 ~-2 ~47 tallgrass 1
fill ~9 ~-2 ~48 ~12 ~-2 ~48 tallgrass 1
fill ~10 ~-2 ~26 ~11 ~-2 ~26 tallgrass 1
setblock ~10 ~-2 ~35 red_flower 7
setblock ~10 ~-2 ~37 tallgrass 1
setblock ~10 ~-2 ~39 tallgrass 1
fill ~10 ~-2 ~42 ~10 ~-2 ~44 tallgrass 1
fill ~10 ~-2 ~50 ~13 ~-2 ~50 tallgrass 1
setblock ~11 ~-2 ~14 double_plant 5
fill ~11 ~-2 ~16 ~15 ~-2 ~16 tallgrass 1
fill ~11 ~-2 ~21 ~15 ~-2 ~21 tallgrass 1
fill ~11 ~-2 ~24 ~13 ~-2 ~24 tallgrass 1
fill ~11 ~-2 ~38 ~12 ~-2 ~38 tallgrass 1
fill ~11 ~-2 ~40 ~13 ~-2 ~40 tallgrass 1
fill ~11 ~-2 ~43 ~15 ~-2 ~43 tallgrass 1
fill ~11 ~-2 ~44 ~11 ~-2 ~51 tallgrass 1
setblock ~11 ~-2 ~53 tallgrass 1
fill ~12 ~-2 ~17 ~16 ~-2 ~17 tallgrass 1
fill ~12 ~-2 ~20 ~13 ~-2 ~20 tallgrass 1
fill ~12 ~-2 ~23 ~14 ~-2 ~23 tallgrass 1
setblock ~12 ~-2 ~27 fence 0
setblock ~12 ~-2 ~39 tallgrass 1
setblock ~12 ~-2 ~41 tallgrass 1
fill ~12 ~-2 ~45 ~13 ~-2 ~45 tallgrass 1
fill ~12 ~-2 ~49 ~15 ~-2 ~49 tallgrass 1
fill ~12 ~-2 ~51 ~13 ~-2 ~51 tallgrass 1
fill ~12 ~-2 ~52 ~13 ~-2 ~52 tallgrass 1
setblock ~12 ~-2 ~56 tallgrass 1
setblock ~13 ~-2 ~10 tallgrass 1
fill ~13 ~-2 ~14 ~15 ~-2 ~14 tallgrass 1
fill ~13 ~-2 ~22 ~15 ~-2 ~22 tallgrass 1
fill ~13 ~-2 ~38 ~13 ~4 ~38 fence 0
fill ~13 ~-2 ~42 ~14 ~-2 ~42 tallgrass 1
fill ~13 ~-2 ~44 ~14 ~-2 ~44 tallgrass 1
setblock ~13 ~-2 ~54 tallgrass 1
setblock ~13 ~-2 ~57 double_plant 3
fill ~13 ~-2 ~58 ~13 ~-2 ~59 tallgrass 1
fill ~14 ~-2 ~12 ~19 ~-2 ~12 tallgrass 1
fill ~14 ~-2 ~15 ~17 ~-2 ~15 tallgrass 1
setblock ~14 ~-2 ~41 tallgrass 1
setblock ~14 ~-2 ~52 log 0
fill ~14 ~-2 ~53 ~17 ~-2 ~53 tallgrass 1
fill ~14 ~-2 ~57 ~17 ~-2 ~57 tallgrass 1
fill ~14 ~-2 ~59 ~15 ~-2 ~59 tallgrass 1
fill ~14 ~-2 ~60 ~14 ~-2 ~59 tallgrass 1
fill ~15 ~-2 ~5 ~16 ~-2 ~5 tallgrass 1
fill ~15 ~-2 ~10 ~17 ~-2 ~10 tallgrass 1
fill ~15 ~-2 ~11 ~17 ~-2 ~11 tallgrass 1
setblock ~15 ~-2 ~38 double_plant 5
fill ~15 ~-2 ~39 ~15 ~-2 ~40 tallgrass 1
setblock ~15 ~-2 ~45 tallgrass 1
fill ~15 ~-2 ~51 ~15 ~-2 ~53 tallgrass 1
fill ~16 ~-2 ~3 ~16 ~-2 ~6 tallgrass 1
fill ~16 ~-2 ~20 ~17 ~-2 ~20 tallgrass 1
setblock ~16 ~-2 ~23 tallgrass 1
setblock ~16 ~-2 ~42 tallgrass 1
setblock ~16 ~-2 ~46 red_flower 7
fill ~16 ~-2 ~50 ~18 ~-2 ~50 tallgrass 1
fill ~16 ~-2 ~52 ~17 ~-2 ~52 tallgrass 1
setblock ~16 ~-2 ~60 tallgrass 1
fill ~17 ~-2 ~4 ~23 ~-2 ~4 tallgrass 1
fill ~17 ~-2 ~13 ~18 ~-2 ~13 tallgrass 1
setblock ~17 ~-2 ~19 tallgrass 1
fill ~17 ~-2 ~32 ~17 ~-2 ~37 stone_slab 3
fill ~17 ~-2 ~44 ~23 ~-2 ~44 grass 0
fill ~17 ~-2 ~45 ~23 ~-2 ~45 grass 0
fill ~17 ~-2 ~46 ~24 ~-2 ~46 grass 0
fill ~17 ~-2 ~47 ~24 ~-2 ~47 grass 0
fill ~17 ~-2 ~48 ~18 ~-2 ~48 grass 0
fill ~17 ~-2 ~51 ~19 ~-2 ~51 tallgrass 1
fill ~17 ~-2 ~55 ~17 ~-2 ~59 tallgrass 1
fill ~18 ~-2 ~3 ~20 ~-2 ~3 tallgrass 1
fill ~18 ~-2 ~5 ~19 ~-2 ~5 tallgrass 1
setblock ~18 ~-2 ~7 tallgrass 1
fill ~18 ~-2 ~9 ~21 ~-2 ~9 tallgrass 1
setblock ~18 ~-2 ~16 tallgrass 1
fill ~18 ~-2 ~27 ~18 ~-2 ~31 stone_slab 3
setblock ~18 ~-2 ~32 lapis_ore 0
setblock ~18 ~-2 ~33 stained_glass 9
setblock ~18 ~-2 ~34 wool 11
fill ~18 ~-2 ~35 ~18 ~-2 ~36 cobblestone 0
setblock ~18 ~-2 ~37 stained_glass 9
setblock ~18 ~-2 ~38 stone_slab 3
fill ~18 ~-2 ~42 ~23 ~-2 ~42 grass 0
fill ~18 ~-2 ~43 ~23 ~-2 ~43 grass 0
fill ~18 ~-2 ~49 ~25 ~-2 ~49 grass 0
fill ~18 ~-2 ~56 ~19 ~-2 ~56 tallgrass 1
fill ~18 ~-2 ~58 ~19 ~-2 ~58 tallgrass 1
fill ~18 ~-2 ~59 ~19 ~-2 ~59 tallgrass 1
fill ~18 ~-2 ~63 ~18 ~0 ~63 log 0
setblock ~19 ~-2 ~2 tallgrass 1
setblock ~19 ~-2 ~6 tallgrass 1
fill ~19 ~-2 ~11 ~21 ~-2 ~11 tallgrass 1
fill ~19 ~-2 ~14 ~19 ~-2 ~15 tallgrass 1
fill ~19 ~-2 ~18 ~20 ~-2 ~18 tallgrass 1
fill ~19 ~-2 ~25 ~19 ~-2 ~26 stone_slab 3
fill ~19 ~-2 ~27 ~19 ~-2 ~28 wool 11
setblock ~19 ~-2 ~29 cobblestone 0
setblock ~19 ~-2 ~30 double_stone_slab 3
setblock ~19 ~-2 ~31 lapis_ore 0
fill ~19 ~-2 ~32 ~19 ~-2 ~33 wool 3
fill ~19 ~-2 ~34 ~19 ~-2 ~35 stained_glass 9
setblock ~19 ~-2 ~36 stained_glass 3
fill ~19 ~-2 ~37 ~20 ~-2 ~37 wool 11
setblock ~19 ~-2 ~38 lapis_ore 0
fill ~19 ~-2 ~39 ~19 ~-2 ~47 grass 0
fill ~19 ~-2 ~50 ~25 ~-2 ~50 grass 0
fill ~19 ~-2 ~57 ~21 ~-2 ~57 tallgrass 1
setblock ~20 ~-2 ~0 tallgrass 1
setblock ~20 ~-2 ~8 tallgrass 1
fill ~20 ~-2 ~15 ~20 ~-2 ~16 tallgrass 1
fill ~20 ~-2 ~23 ~20 ~-2 ~24 stone_slab 3
fill ~20 ~-2 ~25 ~20 ~-2 ~26 lapis_ore 0
fill ~20 ~-2 ~27 ~20 ~-2 ~28 cobblestone 0
setblock ~20 ~-2 ~34 lapis_ore 0
setblock ~20 ~-2 ~35 wool 3
setblock ~20 ~-2 ~36 cobblestone 0
setblock ~20 ~-2 ~38 wool 3
setblock ~20 ~-2 ~39 lapis_ore 0
fill ~20 ~-2 ~40 ~24 ~-2 ~40 grass 0
fill ~20 ~-2 ~41 ~23 ~-2 ~41 grass 0
fill ~20 ~-2 ~48 ~24 ~-2 ~48 grass 0
fill ~20 ~-2 ~51 ~26 ~-2 ~51 grass 0
fill ~20 ~-2 ~52 ~26 ~-2 ~52 grass 0
fill ~20 ~-2 ~60 ~21 ~-2 ~60 tallgrass 1
fill ~20 ~-2 ~63 ~20 ~-2 ~66 tallgrass 1
fill ~21 ~-2 ~1 ~26 ~-2 ~1 tallgrass 1
fill ~21 ~-2 ~2 ~22 ~-2 ~2 tallgrass 1
setblock ~21 ~-2 ~7 tallgrass 1
fill ~21 ~-2 ~10 ~22 ~-2 ~10 tallgrass 1
fill ~21 ~-2 ~12 ~22 ~-2 ~12 tallgrass 1
setblock ~21 ~-2 ~14 tallgrass 1
setblock ~21 ~-2 ~19 tallgrass 1
setblock ~21 ~-2 ~21 tallgrass 1
fill ~21 ~-2 ~22 ~25 ~-2 ~22 grass 0
fill ~21 ~-2 ~23 ~21 ~-2 ~24 lapis_ore 0
fill ~21 ~-2 ~25 ~22 ~-2 ~25 stained_glass 9
setblock ~21 ~-2 ~26 cobblestone 0
setblock ~21 ~-2 ~36 wool 11
setblock ~21 ~-2 ~37 stained_glass 9
setblock ~21 ~-2 ~38 stained_glass 3
fill ~21 ~-2 ~39 ~24 ~-2 ~39 grass 0
fill ~21 ~-2 ~53 ~27 ~-2 ~53 grass 0
fill ~21 ~-2 ~54 ~27 ~-2 ~54 grass 0
setblock ~21 ~-2 ~56 tallgrass 1
fill ~21 ~-2 ~58 ~22 ~-2 ~58 tallgrass 1
fill ~21 ~-2 ~59 ~22 ~-2 ~59 tallgrass 1
fill ~21 ~-2 ~61 ~23 ~-2 ~61 tallgrass 1
fill ~21 ~-2 ~62 ~25 ~-2 ~62 tallgrass 1
fill ~21 ~-2 ~66 ~24 ~-2 ~66 tallgrass 1
fill ~21 ~-2 ~67 ~22 ~-2 ~67 tallgrass 1
fill ~21 ~-2 ~68 ~24 ~-2 ~68 tallgrass 1
fill ~21 ~-2 ~69 ~22 ~-2 ~69 tallgrass 1
setblock ~22 ~-2 ~0 tallgrass 1
setblock ~22 ~-2 ~3 tallgrass 1
fill ~22 ~-2 ~5 ~22 ~-2 ~6 tallgrass 1
fill ~22 ~-2 ~8 ~23 ~-2 ~8 tallgrass 1
fill ~22 ~-2 ~13 ~22 ~-2 ~23 grass 0
fill ~22 ~-2 ~24 ~23 ~-2 ~24 lapis_ore 0
setblock ~22 ~-2 ~37 stained_glass 3
setblock ~22 ~-2 ~38 wool 11
fill ~22 ~-2 ~55 ~28 ~-2 ~55 grass 0
fill ~22 ~-2 ~56 ~28 ~-2 ~56 grass 0
fill ~22 ~-2 ~64 ~22 ~-2 ~69 tallgrass 1
setblock ~23 ~-2 ~3 log 0
setblock ~23 ~-2 ~7 tallgrass 1
fill ~23 ~-2 ~9 ~26 ~-2 ~9 grass 0
fill ~23 ~-2 ~10 ~26 ~-2 ~10 grass 0
fill ~23 ~-2 ~11 ~25 ~-2 ~11 grass 0
fill ~23 ~-2 ~12 ~25 ~-2 ~12 grass 0
fill ~23 ~-2 ~14 ~25 ~-2 ~14 grass 0
fill ~23 ~-2 ~15 ~25 ~-2 ~15 grass 0
fill ~23 ~-2 ~16 ~25 ~-2 ~16 grass 0
fill ~23 ~-2 ~17 ~25 ~-2 ~17 grass 0
fill ~23 ~-2 ~18 ~25 ~-2 ~18 grass 0
fill ~23 ~-2 ~19 ~25 ~-2 ~19 grass 0
fill ~23 ~-2 ~20 ~25 ~-2 ~20 grass 0
fill ~23 ~-2 ~21 ~25 ~-2 ~21 grass 0
fill ~23 ~-2 ~23 ~26 ~-2 ~23 grass 0
setblock ~23 ~-2 ~25 cobblestone 0
setblock ~23 ~-2 ~37 wool 11
fill ~23 ~-2 ~57 ~29 ~-2 ~57 grass 0
fill ~23 ~-2 ~58 ~29 ~-2 ~58 grass 0
setblock ~23 ~-2 ~60 tallgrass 1
setblock ~23 ~-2 ~63 tallgrass 1
fill ~23 ~-2 ~65 ~24 ~-2 ~65 tallgrass 1
setblock ~23 ~-2 ~70 tallgrass 1
setblock ~24 ~-2 ~0 tallgrass 1
fill ~24 ~-2 ~2 ~24 ~-2 ~3 tallgrass 1
fill ~24 ~-2 ~7 ~26 ~-2 ~7 grass 0
fill ~24 ~-2 ~8 ~26 ~-2 ~8 grass 0
fill ~24 ~-2 ~13 ~25 ~-2 ~13 grass 0
fill ~24 ~-2 ~24 ~25 ~-2 ~24 grass 0
fill ~24 ~-2 ~38 ~25 ~-2 ~38 grass 0
fill ~24 ~-2 ~59 ~29 ~-2 ~59 grass 0
fill ~24 ~-2 ~60 ~30 ~-2 ~60 grass 0
setblock ~24 ~-2 ~64 tallgrass 1
setblock ~24 ~-2 ~67 tallgrass 1
fill ~25 ~-2 ~5 ~28 ~-2 ~5 grass 0
fill ~25 ~-2 ~6 ~27 ~-2 ~6 grass 0
fill ~25 ~-2 ~61 ~31 ~-2 ~61 grass 0
setblock ~26 ~-2 ~3 tallgrass 1
fill ~26 ~-2 ~4 ~29 ~-2 ~4 grass 0
fill ~26 ~-2 ~62 ~33 ~-2 ~62 grass 0
fill ~26 ~-2 ~63 ~35 ~-2 ~63 grass 0
setblock ~26 ~-2 ~64 tallgrass 1
fill ~26 ~-2 ~69 ~27 ~-2 ~69 tallgrass 1
fill ~27 ~-2 ~3 ~30 ~-2 ~3 grass 0
fill ~27 ~-2 ~64 ~39 ~-2 ~64 grass 0
fill ~27 ~-2 ~65 ~27 ~-2 ~69 tallgrass 1
fill ~28 ~-2 ~0 ~29 ~-2 ~0 tallgrass 1
fill ~28 ~-2 ~1 ~28 ~-2 ~0 tallgrass 1
fill ~28 ~-2 ~2 ~32 ~-2 ~2 grass 0
fill ~28 ~-2 ~65 ~44 ~-2 ~65 grass 0
fill ~28 ~-2 ~66 ~28 ~-2 ~67 tallgrass 1
fill ~29 ~-2 ~1 ~34 ~-2 ~1 grass 0
setblock ~29 ~-2 ~69 tallgrass 1
fill ~30 ~-2 ~0 ~35 ~-2 ~0 grass 0
fill ~30 ~-2 ~66 ~64 ~-2 ~66 grass 0
fill ~30 ~-2 ~70 ~31 ~-2 ~70 tallgrass 1
setblock ~31 ~-2 ~67 tallgrass 1
setblock ~31 ~-2 ~68 dirt 0
setblock ~31 ~-2 ~69 tallgrass 1
fill ~32 ~-2 ~67 ~49 ~-2 ~67 grass 0
fill ~33 ~-2 ~68 ~60 ~-2 ~68 grass 0
fill ~34 ~-2 ~69 ~58 ~-2 ~69 grass 0
fill ~35 ~-2 ~31 ~36 ~-2 ~31 stained_hardened_clay 6
fill ~35 ~-2 ~70 ~56 ~-2 ~70 grass 0
fill ~37 ~-2 ~30 ~69 ~-2 ~30 stained_hardened_clay 14
setblock ~37 ~-2 ~31 carpet 14
fill ~37 ~-2 ~32 ~70 ~-2 ~32 stained_hardened_clay 14
fill ~38 ~-2 ~29 ~69 ~-2 ~29 stained_hardened_clay 14
fill ~38 ~-2 ~31 ~55 ~-2 ~31 stained_hardened_clay 14
fill ~38 ~-2 ~33 ~71 ~-2 ~33 stained_hardened_clay 14
setblock ~38 ~-2 ~44 stained_hardened_clay 14
setblock ~38 ~-2 ~45 stained_hardened_clay 2
fill ~39 ~-2 ~28 ~68 ~-2 ~28 stained_hardened_clay 14
fill ~39 ~-2 ~34 ~71 ~-2 ~34 stained_hardened_clay 14
setblock ~39 ~-2 ~43 dirt 0
fill ~39 ~-2 ~46 ~40 ~-2 ~46 stained_hardened_clay 14
setblock ~40 ~-2 ~20 glowstone 0
fill ~40 ~-2 ~27 ~69 ~-2 ~27 stained_hardened_clay 14
fill ~40 ~-2 ~35 ~71 ~-2 ~35 stained_hardened_clay 14
setblock ~40 ~-2 ~44 glowstone 0
fill ~41 ~-2 ~19 ~69 ~-2 ~19 stained_hardened_clay 14
fill ~41 ~-2 ~20 ~70 ~-2 ~20 stained_hardened_clay 14
fill ~41 ~-2 ~21 ~69 ~-2 ~21 stained_hardened_clay 14
fill ~41 ~-2 ~22 ~69 ~-2 ~22 stained_hardened_clay 14
fill ~41 ~-2 ~23 ~69 ~-2 ~23 stained_hardened_clay 14
fill ~41 ~-2 ~24 ~69 ~-2 ~24 stained_hardened_clay 14
fill ~41 ~-2 ~25 ~69 ~-2 ~25 stained_hardened_clay 14
fill ~41 ~-2 ~26 ~68 ~-2 ~26 stained_hardened_clay 14
fill ~41 ~-2 ~36 ~71 ~-2 ~36 stained_hardened_clay 14
fill ~41 ~-2 ~37 ~70 ~-2 ~37 stained_hardened_clay 14
fill ~41 ~-2 ~38 ~71 ~-2 ~38 stained_hardened_clay 14
fill ~41 ~-2 ~39 ~70 ~-2 ~39 stained_hardened_clay 14
fill ~41 ~-2 ~40 ~71 ~-2 ~40 stained_hardened_clay 14
fill ~41 ~-2 ~41 ~71 ~-2 ~41 stained_hardened_clay 14
fill ~41 ~-2 ~42 ~70 ~-2 ~42 stained_hardened_clay 14
fill ~41 ~-2 ~43 ~71 ~-2 ~43 stained_hardened_clay 14
fill ~41 ~-2 ~44 ~71 ~-2 ~44 stained_hardened_clay 14
fill ~41 ~-2 ~45 ~56 ~-2 ~45 stained_hardened_clay 14
fill ~42 ~-2 ~17 ~57 ~-2 ~17 stained_hardened_clay 14
fill ~42 ~-2 ~18 ~69 ~-2 ~18 stained_hardened_clay 14
fill ~43 ~-2 ~16 ~44 ~-2 ~16 stained_hardened_clay 14
fill ~44 ~-2 ~46 ~45 ~-2 ~46 stained_hardened_clay 14
fill ~46 ~-2 ~16 ~52 ~-2 ~16 stained_hardened_clay 14
setblock ~48 ~-2 ~15 dirt 0
setblock ~49 ~-2 ~14 dirt 0
setblock ~49 ~-2 ~15 carpet 14
setblock ~50 ~-2 ~15 stained_hardened_clay 14
fill ~51 ~-2 ~67 ~62 ~-2 ~67 grass 0
setblock ~55 ~-2 ~16 dirt 0
setblock ~56 ~-2 ~31 glowstone 0
fill ~57 ~-2 ~31 ~71 ~-2 ~31 stained_hardened_clay 14
setblock ~57 ~-2 ~45 carpet 14
fill ~57 ~-2 ~46 ~57 ~6 ~46 stained_hardened_clay 14
setblock ~57 ~-2 ~70 tallgrass 1
setblock ~58 ~-2 ~17 glowstone 0
fill ~58 ~-2 ~45 ~58 ~2 ~45 stained_hardened_clay 14
fill ~59 ~-2 ~17 ~68 ~-2 ~17 stained_hardened_clay 14
fill ~59 ~-2 ~70 ~60 ~-2 ~70 tallgrass 1
setblock ~60 ~-2 ~69 tallgrass 1
fill ~61 ~-2 ~65 ~66 ~-2 ~65 grass 0
setblock ~62 ~-2 ~68 tallgrass 1
fill ~63 ~-2 ~64 ~81 ~-2 ~64 grass 0
fill ~63 ~-2 ~69 ~76 ~-2 ~69 tallgrass 1
fill ~63 ~-2 ~70 ~65 ~-2 ~70 tallgrass 1
setblock ~64 ~-2 ~68 tallgrass 1
fill ~66 ~-2 ~63 ~80 ~-2 ~63 grass 0
setblock ~67 ~-2 ~67 tallgrass 1
fill ~67 ~-2 ~70 ~70 ~-2 ~70 tallgrass 1
fill ~68 ~-2 ~62 ~74 ~-2 ~62 grass 0
fill ~68 ~-2 ~68 ~70 ~-2 ~68 tallgrass 1
setblock ~69 ~-2 ~61 grass 0
setblock ~69 ~-2 ~65 tallgrass 1
setblock ~69 ~-2 ~67 tallgrass 1
fill ~70 ~-2 ~65 ~77 ~-2 ~65 grass 0
setblock ~70 ~-2 ~66 tallgrass 1
fill ~71 ~-2 ~66 ~75 ~-2 ~66 grass 0
setblock ~72 ~-2 ~61 grass 0
setblock ~72 ~-2 ~67 tallgrass 1
fill ~72 ~-2 ~70 ~74 ~-2 ~70 tallgrass 1
fill ~74 ~-2 ~67 ~75 ~-2 ~67 tallgrass 1
fill ~74 ~-2 ~68 ~75 ~-2 ~68 tallgrass 1
fill ~76 ~-2 ~70 ~78 ~-2 ~70 tallgrass 1
fill ~77 ~-2 ~0 ~87 ~-2 ~0 grass 0
fill ~77 ~-2 ~67 ~77 ~-2 ~68 tallgrass 1
fill ~78 ~-2 ~62 ~84 ~-2 ~62 grass 0
fill ~78 ~-2 ~66 ~80 ~-2 ~66 tallgrass 1
setblock ~78 ~-2 ~69 tallgrass 1
setblock ~79 ~-2 ~65 tallgrass 1
fill ~80 ~-2 ~61 ~85 ~-2 ~61 grass 0
fill ~80 ~-2 ~68 ~80 ~-2 ~69 tallgrass 1
fill ~81 ~-2 ~1 ~88 ~-2 ~1 grass 0
fill ~81 ~-2 ~59 ~87 ~-2 ~59 grass 0
fill ~81 ~-2 ~60 ~86 ~-2 ~60 grass 0
fill ~81 ~-2 ~65 ~82 ~-2 ~65 tallgrass 1
setblock ~81 ~-2 ~67 tallgrass 1
setblock ~81 ~-2 ~69 tallgrass 1
fill ~82 ~-2 ~58 ~87 ~-2 ~58 grass 0
fill ~82 ~-2 ~63 ~83 ~-2 ~63 grass 0
fill ~82 ~-2 ~66 ~85 ~-2 ~66 tallgrass 1
setblock ~82 ~-2 ~68 tallgrass 1
fill ~83 ~-2 ~2 ~88 ~-2 ~2 grass 0
fill ~83 ~-2 ~57 ~88 ~-2 ~57 grass 0
fill ~84 ~-2 ~64 ~86 ~-2 ~64 tallgrass 1
fill ~84 ~-2 ~65 ~84 ~-2 ~64 tallgrass 1
fill ~85 ~-2 ~3 ~89 ~-2 ~3 grass 0
fill ~85 ~-2 ~4 ~90 ~-2 ~4 grass 0
fill ~85 ~-2 ~56 ~88 ~-2 ~56 grass 0
setblock ~85 ~-2 ~62 tallgrass 1
setblock ~85 ~-2 ~67 tallgrass 1
fill ~86 ~-2 ~5 ~90 ~-2 ~5 grass 0
fill ~86 ~-2 ~55 ~88 ~-2 ~55 grass 0
fill ~86 ~-2 ~61 ~90 ~-2 ~61 tallgrass 1
setblock ~86 ~-2 ~65 tallgrass 1
fill ~87 ~-2 ~6 ~91 ~-2 ~6 grass 0
fill ~87 ~-2 ~7 ~91 ~-2 ~7 grass 0
fill ~87 ~-2 ~8 ~92 ~-2 ~8 grass 0
fill ~87 ~-2 ~54 ~89 ~-2 ~54 grass 0
fill ~87 ~-2 ~60 ~91 ~-2 ~60 tallgrass 1
fill ~87 ~-2 ~63 ~89 ~-2 ~63 tallgrass 1
setblock ~87 ~-2 ~67 tallgrass 1
fill ~88 ~-2 ~9 ~92 ~-2 ~9 grass 0
fill ~88 ~-2 ~10 ~88 ~-2 ~1 grass 0
fill ~88 ~-2 ~52 ~90 ~-2 ~52 grass 0
fill ~88 ~-2 ~53 ~89 ~-2 ~53 grass 0
setblock ~88 ~-2 ~58 tallgrass 1
fill ~88 ~-2 ~62 ~89 ~-2 ~62 tallgrass 1
fill ~88 ~-2 ~64 ~89 ~-2 ~64 tallgrass 1
setblock ~88 ~-2 ~66 tallgrass 1
fill ~89 ~-2 ~11 ~93 ~-2 ~11 grass 0
fill ~89 ~-2 ~12 ~94 ~-2 ~12 grass 0
fill ~89 ~-2 ~50 ~92 ~-2 ~50 grass 0
fill ~89 ~-2 ~51 ~91 ~-2 ~51 grass 0
fill ~89 ~-2 ~59 ~90 ~-2 ~59 tallgrass 1
fill ~90 ~-2 ~0 ~90 ~-2 ~2 tallgrass 1
setblock ~90 ~-2 ~3 red_flower 7
fill ~90 ~-2 ~10 ~93 ~-2 ~10 grass 0
fill ~90 ~-2 ~13 ~94 ~-2 ~13 grass 0
fill ~90 ~-2 ~14 ~94 ~-2 ~14 grass 0
fill ~90 ~-2 ~45 ~94 ~-2 ~45 grass 0
fill ~90 ~-2 ~46 ~94 ~-2 ~46 grass 0
fill ~90 ~-2 ~47 ~93 ~-2 ~47 grass 0
fill ~90 ~-2 ~48 ~93 ~-2 ~48 grass 0
fill ~90 ~-2 ~49 ~92 ~-2 ~49 grass 0
fill ~90 ~-2 ~53 ~91 ~-2 ~53 tallgrass 1
fill ~90 ~-2 ~54 ~95 ~-2 ~54 tallgrass 1
fill ~90 ~-2 ~56 ~91 ~-2 ~56 tallgrass 1
fill ~90 ~-2 ~57 ~92 ~-2 ~57 tallgrass 1
setblock ~90 ~-2 ~65 tallgrass 1
setblock ~91 ~-2 ~2 tallgrass 1
setblock ~91 ~-2 ~5 tallgrass 1
fill ~91 ~-2 ~15 ~95 ~-2 ~15 grass 0
fill ~91 ~-2 ~43 ~95 ~-2 ~43 grass 0
fill ~91 ~-2 ~44 ~94 ~-2 ~44 grass 0
fill ~91 ~-2 ~52 ~95 ~-2 ~52 tallgrass 1
setblock ~91 ~-2 ~55 tallgrass 1
fill ~91 ~-2 ~58 ~94 ~-2 ~58 tallgrass 1
fill ~91 ~-2 ~59 ~91 ~4 ~59 fence 0
fill ~91 ~-2 ~63 ~91 ~-2 ~64 tallgrass 1
fill ~92 ~-2 ~1 ~96 ~-2 ~1 tallgrass 1
fill ~92 ~-2 ~3 ~92 ~5 ~3 fence 0
fill ~92 ~-2 ~16 ~95 ~-2 ~16 grass 0
fill ~92 ~-2 ~17 ~95 ~-2 ~17 grass 0
fill ~92 ~-2 ~40 ~95 ~-2 ~40 grass 0
fill ~92 ~-2 ~41 ~95 ~-2 ~41 grass 0
fill ~92 ~-2 ~42 ~95 ~-2 ~42 grass 0
setblock ~93 ~-2 ~0 tallgrass 1
fill ~93 ~-2 ~2 ~93 ~-2 ~3 tallgrass 1
fill ~93 ~-2 ~18 ~93 ~-2 ~19 grass 0
fill ~93 ~-2 ~37 ~95 ~-2 ~37 grass 0
fill ~93 ~-2 ~38 ~95 ~-2 ~38 grass 0
fill ~93 ~-2 ~39 ~95 ~-2 ~39 grass 0
fill ~93 ~-2 ~50 ~96 ~-2 ~50 tallgrass 1
fill ~93 ~-2 ~53 ~94 ~-2 ~53 tallgrass 1
fill ~93 ~-2 ~56 ~95 ~-2 ~56 tallgrass 1
setblock ~93 ~-2 ~59 tallgrass 1
setblock ~93 ~-2 ~61 double_plant 3
fill ~94 ~-2 ~6 ~97 ~-2 ~6 tallgrass 1
fill ~94 ~-2 ~7 ~96 ~-2 ~7 tallgrass 1
fill ~94 ~-2 ~19 ~96 ~-2 ~19 grass 0
fill ~94 ~-2 ~20 ~96 ~-2 ~20 grass 0
fill ~94 ~-2 ~21 ~97 ~-2 ~21 grass 0
fill ~94 ~-2 ~22 ~97 ~-2 ~22 grass 0
fill ~94 ~-2 ~23 ~97 ~-2 ~23 grass 0
fill ~94 ~-2 ~30 ~97 ~-2 ~30 grass 0
fill ~94 ~-2 ~31 ~95 ~-2 ~31 grass 0
fill ~94 ~-2 ~32 ~95 ~-2 ~32 grass 0
fill ~94 ~-2 ~33 ~94 ~-2 ~46 grass 0
fill ~94 ~-2 ~48 ~97 ~-2 ~48 tallgrass 1
fill ~94 ~-2 ~49 ~94 ~-2 ~48 tallgrass 1
setblock ~94 ~-2 ~51 tallgrass 1
setblock ~94 ~-2 ~57 tallgrass 1
setblock ~95 ~-2 ~2 red_flower 7
fill ~95 ~-2 ~3 ~95 ~-2 ~7 tallgrass 1
setblock ~95 ~-2 ~10 tallgrass 1
setblock ~95 ~-2 ~13 tallgrass 1
fill ~95 ~-2 ~18 ~96 ~-2 ~18 grass 0
fill ~95 ~-2 ~24 ~96 ~-2 ~24 grass 0
fill ~95 ~-2 ~25 ~97 ~-2 ~25 grass 0
fill ~95 ~-2 ~26 ~97 ~-2 ~26 grass 0
fill ~95 ~-2 ~27 ~96 ~-2 ~27 grass 0
fill ~95 ~-2 ~28 ~96 ~-2 ~28 grass 0
fill ~95 ~-2 ~29 ~97 ~-2 ~29 grass 0
setblock ~95 ~-2 ~33 tallgrass 1
fill ~95 ~-2 ~47 ~97 ~-2 ~47 tallgrass 1
setblock ~95 ~-2 ~55 tallgrass 1
fill ~96 ~-2 ~5 ~97 ~-2 ~5 tallgrass 1
fill ~96 ~-2 ~8 ~97 ~-2 ~8 tallgrass 1
fill ~96 ~-2 ~9 ~97 ~-2 ~9 red_flower 7
fill ~96 ~-2 ~12 ~97 ~-2 ~12 tallgrass 1
fill ~96 ~-2 ~14 ~96 ~-2 ~15 tallgrass 1
fill ~96 ~-2 ~31 ~97 ~-2 ~31 tallgrass 1
setblock ~96 ~-2 ~40 tallgrass 1
setblock ~96 ~-2 ~44 tallgrass 1
fill ~96 ~-2 ~49 ~97 ~-2 ~49 tallgrass 1
setblock ~97 ~-2 ~3 tallgrass 1
setblock ~97 ~-2 ~7 red_flower 7
setblock ~97 ~-2 ~13 tallgrass 1
fill ~97 ~-2 ~19 ~97 ~-2 ~20 tallgrass 1
setblock ~97 ~-2 ~28 log 0
setblock ~12 ~-1 ~27 torch 5
fill ~14 ~-1 ~48 ~14 ~2 ~48 leaves 15
fill ~14 ~-1 ~51 ~14 ~0 ~51 log 0
fill ~17 ~-1 ~45 ~18 ~-1 ~45 tallgrass 1
fill ~17 ~-1 ~46 ~20 ~-1 ~46 tallgrass 1
setblock ~17 ~-1 ~48 tallgrass 1
fill ~17 ~-1 ~62 ~17 ~1 ~62 leaves 7
fill ~18 ~-1 ~42 ~19 ~-1 ~42 tallgrass 1
fill ~18 ~-1 ~43 ~21 ~-1 ~43 tallgrass 1
fill ~18 ~-1 ~44 ~19 ~-1 ~44 tallgrass 1
fill ~19 ~-1 ~3 ~19 ~2 ~3 leaves 15
fill ~19 ~-1 ~40 ~20 ~-1 ~40 tallgrass 1
fill ~19 ~-1 ~41 ~23 ~-1 ~41 tallgrass 1
setblock ~19 ~-1 ~45 red_flower 7
setblock ~19 ~-1 ~48 log 0
fill ~20 ~-1 ~29 ~22 ~-1 ~29 stained_hardened_clay 14
fill ~20 ~-1 ~30 ~22 ~-1 ~30 stained_hardened_clay 14
fill ~20 ~-1 ~31 ~20 ~-1 ~33 stained_hardened_clay 14
fill ~20 ~-1 ~45 ~21 ~-1 ~45 tallgrass 1
fill ~21 ~-1 ~27 ~24 ~-1 ~27 stained_hardened_clay 14
fill ~21 ~-1 ~28 ~23 ~-1 ~28 stained_hardened_clay 14
fill ~21 ~-1 ~31 ~22 ~-1 ~31 stained_hardened_clay 6
fill ~21 ~-1 ~32 ~22 ~-1 ~32 stained_hardened_clay 14
fill ~21 ~-1 ~33 ~22 ~-1 ~33 stained_hardened_clay 14
fill ~21 ~-1 ~34 ~23 ~-1 ~34 stained_hardened_clay 14
fill ~21 ~-1 ~35 ~24 ~-1 ~35 stained_hardened_clay 14
setblock ~21 ~-1 ~42 tallgrass 1
fill ~21 ~-1 ~44 ~22 ~-1 ~44 tallgrass 1
setblock ~21 ~-1 ~47 red_flower 7
setblock ~21 ~-1 ~50 double_plant 3
fill ~21 ~-1 ~52 ~24 ~-1 ~52 tallgrass 1
fill ~21 ~-1 ~53 ~21 ~-1 ~52 tallgrass 1
fill ~22 ~-1 ~3 ~22 ~0 ~3 log 0
fill ~22 ~-1 ~13 ~22 ~-1 ~14 tallgrass 1
fill ~22 ~-1 ~16 ~22 ~-1 ~20 tallgrass 1
setblock ~22 ~-1 ~23 double_plant 2
fill ~22 ~-1 ~26 ~26 ~-1 ~26 stained_hardened_clay 14
fill ~22 ~-1 ~36 ~26 ~-1 ~36 stained_hardened_clay 14
setblock ~22 ~-1 ~40 tallgrass 1
fill ~22 ~-1 ~50 ~23 ~-1 ~50 tallgrass 1
fill ~22 ~-1 ~54 ~23 ~-1 ~54 tallgrass 1
fill ~23 ~-1 ~10 ~25 ~-1 ~10 tallgrass 1
fill ~23 ~-1 ~11 ~23 ~-1 ~10 tallgrass 1
fill ~23 ~-1 ~13 ~23 ~4 ~13 fence 0
fill ~23 ~-1 ~15 ~25 ~-1 ~15 tallgrass 1
fill ~23 ~-1 ~18 ~25 ~-1 ~18 tallgrass 1
fill ~23 ~-1 ~19 ~25 ~-1 ~19 tallgrass 1
fill ~23 ~-1 ~20 ~24 ~-1 ~20 tallgrass 1
setblock ~23 ~-1 ~22 tallgrass 1
setblock ~23 ~-1 ~38 fence 0
setblock ~23 ~-1 ~39 tallgrass 1
fill ~23 ~-1 ~42 ~23 ~-1 ~43 tallgrass 1
fill ~23 ~-1 ~45 ~23 ~-1 ~46 tallgrass 1
setblock ~23 ~-1 ~51 tallgrass 1
setblock ~23 ~-1 ~55 tallgrass 1
setblock ~24 ~-1 ~7 tallgrass 1
fill ~24 ~-1 ~9 ~26 ~-1 ~9 tallgrass 1
fill ~24 ~-1 ~12 ~25 ~-1 ~12 tallgrass 1
fill ~24 ~-1 ~13 ~25 ~-1 ~13 tallgrass 1
fill ~24 ~-1 ~14 ~25 ~-1 ~14 tallgrass 1
fill ~24 ~-1 ~17 ~25 ~-1 ~17 tallgrass 1
fill ~24 ~-1 ~21 ~25 ~-1 ~21 tallgrass 1
fill ~24 ~-1 ~24 ~25 ~-1 ~24 tallgrass 1
fill ~24 ~-1 ~25 ~28 ~-1 ~25 stained_hardened_clay 14
fill ~24 ~-1 ~37 ~28 ~-1 ~37 stained_hardened_clay 14
fill ~24 ~-1 ~41 ~26 ~-1 ~41 grass 0
fill ~24 ~-1 ~42 ~25 ~-1 ~42 grass 0
fill ~24 ~-1 ~43 ~25 ~-1 ~43 grass 0
fill ~24 ~-1 ~44 ~25 ~-1 ~44 grass 0
fill ~24 ~-1 ~45 ~25 ~-1 ~45 grass 0
fill ~24 ~-1 ~59 ~26 ~-1 ~59 tallgrass 1
fill ~25 ~-1 ~5 ~25 ~-1 ~6 tallgrass 1
setblock ~25 ~-1 ~16 tallgrass 1
fill ~25 ~-1 ~22 ~25 ~-1 ~24 tallgrass 1
fill ~25 ~-1 ~39 ~27 ~-1 ~39 grass 0
fill ~25 ~-1 ~40 ~26 ~-1 ~40 grass 0
fill ~25 ~-1 ~46 ~26 ~-1 ~46 grass 0
fill ~25 ~-1 ~47 ~26 ~-1 ~47 grass 0
fill ~25 ~-1 ~48 ~27 ~-1 ~48 grass 0
fill ~25 ~-1 ~51 ~26 ~-1 ~51 tallgrass 1
fill ~25 ~-1 ~53 ~26 ~-1 ~53 tallgrass 1
fill ~25 ~-1 ~55 ~25 ~-1 ~57 tallgrass 1
setblock ~26 ~-1 ~8 tallgrass 1
fill ~26 ~-1 ~11 ~27 ~-1 ~11 grass 0
fill ~26 ~-1 ~12 ~27 ~-1 ~12 grass 0
fill ~26 ~-1 ~13 ~27 ~-1 ~13 grass 0
fill ~26 ~-1 ~14 ~27 ~-1 ~14 grass 0
fill ~26 ~-1 ~15 ~27 ~-1 ~15 grass 0
fill ~26 ~-1 ~16 ~27 ~-1 ~16 grass 0
fill ~26 ~-1 ~17 ~26 ~-1 ~22 grass 0
setblock ~26 ~-1 ~24 grass 0
fill ~26 ~-1 ~38 ~28 ~-1 ~38 grass 0
fill ~26 ~-1 ~49 ~27 ~-1 ~49 grass 0
fill ~26 ~-1 ~50 ~28 ~-1 ~50 grass 0
setblock ~26 ~-1 ~52 tallgrass 1
setblock ~26 ~-1 ~54 tallgrass 1
setblock ~26 ~-1 ~56 tallgrass 1
fill ~26 ~-1 ~58 ~27 ~-1 ~58 tallgrass 1
fill ~27 ~-1 ~5 ~28 ~-1 ~5 tallgrass 1
fill ~27 ~-1 ~6 ~27 ~-1 ~5 tallgrass 1
fill ~27 ~-1 ~7 ~29 ~-1 ~7 grass 0
fill ~27 ~-1 ~8 ~28 ~-1 ~8 grass 0
fill ~27 ~-1 ~9 ~28 ~-1 ~9 grass 0
fill ~27 ~-1 ~10 ~28 ~-1 ~10 grass 0
setblock ~27 ~-1 ~23 grass 0
fill ~27 ~-1 ~51 ~28 ~-1 ~51 grass 0
fill ~27 ~-1 ~52 ~29 ~-1 ~52 grass 0
setblock ~27 ~-1 ~60 tallgrass 1
fill ~27 ~-1 ~63 ~28 ~-1 ~63 tallgrass 1
fill ~28 ~-1 ~3 ~30 ~-1 ~3 tallgrass 1
fill ~28 ~-1 ~4 ~29 ~-1 ~4 tallgrass 1
fill ~28 ~-1 ~6 ~30 ~-1 ~6 grass 0
setblock ~28 ~-1 ~24 grass 0
fill ~28 ~-1 ~53 ~30 ~-1 ~53 grass 0
fill ~28 ~-1 ~54 ~30 ~-1 ~54 grass 0
setblock ~28 ~-1 ~61 double_plant 3
fill ~28 ~-1 ~62 ~29 ~-1 ~62 tallgrass 1
setblock ~28 ~-1 ~65 tallgrass 1
fill ~29 ~-1 ~5 ~32 ~-1 ~5 grass 0
fill ~29 ~-1 ~55 ~31 ~-1 ~55 grass 0
fill ~29 ~-1 ~56 ~31 ~-1 ~56 grass 0
fill ~29 ~-1 ~60 ~30 ~-1 ~60 tallgrass 1
fill ~29 ~-1 ~61 ~30 ~-1 ~61 tallgrass 1
fill ~29 ~-1 ~64 ~30 ~-1 ~64 tallgrass 1
fill ~30 ~-1 ~2 ~32 ~-1 ~2 tallgrass 1
fill ~30 ~-1 ~4 ~33 ~-1 ~4 grass 0
fill ~30 ~-1 ~57 ~32 ~-1 ~57 grass 0
fill ~30 ~-1 ~58 ~33 ~-1 ~58 grass 0
fill ~30 ~-1 ~59 ~30 ~-1 ~53 grass 0
fill ~30 ~-1 ~63 ~31 ~-1 ~63 tallgrass 1
fill ~31 ~-1 ~0 ~35 ~-1 ~0 tallgrass 1
fill ~31 ~-1 ~1 ~33 ~-1 ~1 tallgrass 1
fill ~31 ~-1 ~3 ~34 ~-1 ~3 grass 0
fill ~31 ~-1 ~31 ~32 ~-1 ~31 stained_hardened_clay 6
fill ~31 ~-1 ~60 ~34 ~-1 ~60 grass 0
setblock ~31 ~-1 ~62 tallgrass 1
setblock ~31 ~-1 ~68 log 0
fill ~32 ~-1 ~30 ~34 ~-1 ~30 stained_hardened_clay 14
fill ~32 ~-1 ~32 ~34 ~-1 ~32 stained_hardened_clay 14
fill ~32 ~-1 ~59 ~33 ~-1 ~59 grass 0
fill ~32 ~-1 ~61 ~35 ~-1 ~61 grass 0
fill ~33 ~-1 ~2 ~35 ~-1 ~2 grass 0
fill ~33 ~-1 ~31 ~34 ~-1 ~31 stone_slab 4
setblock ~33 ~-1 ~64 tallgrass 1
fill ~33 ~-1 ~67 ~34 ~-1 ~67 tallgrass 1
fill ~34 ~-1 ~62 ~42 ~-1 ~62 grass 0
fill ~35 ~-1 ~1 ~36 ~-1 ~1 grass 0
fill ~35 ~-1 ~29 ~36 ~-1 ~29 stained_hardened_clay 14
fill ~35 ~-1 ~30 ~36 ~-1 ~30 stone_slab 4
fill ~35 ~-1 ~32 ~36 ~-1 ~32 stone_slab 4
fill ~35 ~-1 ~33 ~36 ~-1 ~33 stained_hardened_clay 14
setblock ~35 ~-1 ~63 double_plant 2
fill ~35 ~-1 ~65 ~37 ~-1 ~65 tallgrass 1
fill ~35 ~-1 ~66 ~38 ~-1 ~66 tallgrass 1
setblock ~35 ~-1 ~68 tallgrass 1
fill ~36 ~-1 ~0 ~39 ~-1 ~0 grass 0
fill ~36 ~-1 ~63 ~48 ~-1 ~63 grass 0
fill ~36 ~-1 ~67 ~37 ~-1 ~67 tallgrass 1
setblock ~36 ~-1 ~69 tallgrass 1
setblock ~37 ~-1 ~28 stained_hardened_clay 14
setblock ~37 ~-1 ~29 stone_slab 4
setblock ~37 ~-1 ~33 stone_slab 4
setblock ~37 ~-1 ~34 stained_hardened_clay 14
setblock ~37 ~-1 ~68 tallgrass 1
fill ~37 ~-1 ~70 ~44 ~-1 ~70 tallgrass 1
setblock ~38 ~-1 ~27 stained_hardened_clay 14
setblock ~38 ~-1 ~28 stone_slab 4
setblock ~38 ~-1 ~34 stone_slab 4
setblock ~38 ~-1 ~35 stained_hardened_clay 14
fill ~38 ~-1 ~45 ~38 ~1 ~45 stained_hardened_clay 14
setblock ~38 ~-1 ~64 tallgrass 1
fill ~38 ~-1 ~69 ~42 ~-1 ~69 tallgrass 1
setblock ~39 ~-1 ~20 stained_hardened_clay 14
fill ~39 ~-1 ~25 ~39 ~-1 ~26 stained_hardened_clay 14
setblock ~39 ~-1 ~27 stone_slab 4
setblock ~39 ~-1 ~35 stone_slab 4
fill ~39 ~-1 ~36 ~39 ~-1 ~37 stained_hardened_clay 14
fill ~39 ~-1 ~44 ~39 ~2 ~44 stained_hardened_clay 14
fill ~39 ~-1 ~46 ~39 ~1 ~46 stained_hardened_clay 14
fill ~40 ~-1 ~19 ~40 ~0 ~19 stained_hardened_clay 14
setblock ~40 ~-1 ~20 carpet 14
fill ~40 ~-1 ~21 ~40 ~-1 ~24 stained_hardened_clay 14
fill ~40 ~-1 ~25 ~40 ~-1 ~26 stone_slab 4
fill ~40 ~-1 ~36 ~40 ~-1 ~37 stone_slab 4
fill ~40 ~-1 ~38 ~40 ~-1 ~43 stained_hardened_clay 14
setblock ~40 ~-1 ~44 carpet 14
fill ~40 ~-1 ~45 ~41 ~-1 ~45 stained_hardened_clay 14
fill ~40 ~-1 ~64 ~51 ~-1 ~64 grass 0
fill ~40 ~-1 ~67 ~40 ~-1 ~70 tallgrass 1
fill ~41 ~-1 ~17 ~41 ~-1 ~18 stained_hardened_clay 14
fill ~41 ~-1 ~46 ~43 ~-1 ~46 stained_hardened_clay 14
fill ~41 ~-1 ~65 ~41 ~-1 ~66 tallgrass 1
fill ~41 ~-1 ~68 ~49 ~-1 ~68 tallgrass 1
setblock ~42 ~-1 ~16 stained_hardened_clay 14
fill ~42 ~-1 ~66 ~49 ~-1 ~66 tallgrass 1
fill ~43 ~-1 ~15 ~44 ~-1 ~15 stained_hardened_clay 14
setblock ~43 ~-1 ~65 tallgrass 1
fill ~44 ~-1 ~47 ~45 ~-1 ~47 stained_hardened_clay 14
setblock ~44 ~-1 ~67 tallgrass 1
setblock ~45 ~-1 ~16 stained_hardened_clay 14
fill ~45 ~-1 ~65 ~60 ~-1 ~65 grass 0
setblock ~45 ~-1 ~69 tallgrass 1
fill ~46 ~-1 ~15 ~48 ~-1 ~15 stained_hardened_clay 14
fill ~46 ~-1 ~46 ~57 ~-1 ~46 stained_hardened_clay 14
fill ~46 ~-1 ~70 ~48 ~-1 ~70 tallgrass 1
setblock ~47 ~-1 ~67 tallgrass 1
fill ~47 ~-1 ~69 ~49 ~-1 ~69 tallgrass 1
fill ~49 ~-1 ~14 ~50 ~-1 ~14 stained_hardened_clay 14
setblock ~49 ~-1 ~67 tallgrass 1
fill ~50 ~-1 ~67 ~50 ~5 ~67 fence 0
fill ~51 ~-1 ~15 ~52 ~-1 ~15 stained_hardened_clay 14
fill ~52 ~-1 ~68 ~57 ~-1 ~68 tallgrass 1
fill ~52 ~-1 ~69 ~52 ~-1 ~68 tallgrass 1
fill ~53 ~-1 ~16 ~68 ~-1 ~16 stained_hardened_clay 14
fill ~53 ~-1 ~66 ~54 ~-1 ~66 tallgrass 1
fill ~53 ~-1 ~70 ~54 ~-1 ~70 tallgrass 1
fill ~54 ~-1 ~69 ~55 ~-1 ~69 tallgrass 1
fill ~55 ~-1 ~64 ~62 ~-1 ~64 grass 0
setblock ~55 ~-1 ~67 tallgrass 1
setblock ~56 ~-1 ~31 carpet 14
fill ~56 ~-1 ~66 ~63 ~-1 ~66 tallgrass 1
fill ~57 ~-1 ~63 ~65 ~-1 ~63 grass 0
fill ~59 ~-1 ~45 ~71 ~-1 ~45 stained_hardened_clay 14
fill ~60 ~-1 ~62 ~67 ~-1 ~62 grass 0
fill ~61 ~-1 ~67 ~62 ~-1 ~67 tallgrass 1
fill ~62 ~-1 ~65 ~66 ~-1 ~65 tallgrass 1
fill ~63 ~-1 ~61 ~68 ~-1 ~61 grass 0
fill ~64 ~-1 ~64 ~67 ~-1 ~64 tallgrass 1
fill ~65 ~-1 ~0 ~76 ~-1 ~0 grass 0
setblock ~66 ~-1 ~63 tallgrass 1
fill ~68 ~-1 ~60 ~69 ~-1 ~60 grass 0
fill ~68 ~-1 ~62 ~71 ~-1 ~62 tallgrass 1
setblock ~69 ~-1 ~17 stained_hardened_clay 14
setblock ~69 ~-1 ~26 stained_hardened_clay 14
setblock ~69 ~-1 ~28 stained_hardened_clay 14
setblock ~69 ~-1 ~61 tallgrass 1
fill ~69 ~-1 ~63 ~72 ~-1 ~63 tallgrass 1
fill ~69 ~-1 ~64 ~70 ~-1 ~64 tallgrass 1
fill ~70 ~-1 ~18 ~70 ~-1 ~19 stained_hardened_clay 14
fill ~70 ~-1 ~21 ~70 ~-1 ~25 stained_hardened_clay 14
fill ~70 ~-1 ~27 ~70 ~0 ~27 stained_hardened_clay 14
fill ~70 ~-1 ~29 ~71 ~-1 ~29 stained_hardened_clay 14
fill ~70 ~-1 ~30 ~71 ~-1 ~30 stained_hardened_clay 14
fill ~70 ~-1 ~61 ~71 ~-1 ~61 grass 0
fill ~70 ~-1 ~65 ~72 ~-1 ~65 tallgrass 1
setblock ~71 ~-1 ~20 stained_hardened_clay 14
fill ~71 ~-1 ~32 ~72 ~-1 ~32 stained_hardened_clay 14
setblock ~71 ~-1 ~37 stained_hardened_clay 14
setblock ~71 ~-1 ~39 stained_hardened_clay 14
fill ~71 ~-1 ~42 ~73 ~-1 ~42 stained_hardened_clay 14
fill ~71 ~-1 ~66 ~74 ~-1 ~66 tallgrass 1
fill ~72 ~-1 ~1 ~80 ~-1 ~1 grass 0
fill ~72 ~-1 ~31 ~72 ~1 ~31 stained_hardened_clay 14
fill ~72 ~-1 ~33 ~72 ~-1 ~34 stained_hardened_clay 14
setblock ~72 ~-1 ~35 stained_hardened_clay 2
fill ~72 ~-1 ~36 ~72 ~0 ~36 stained_hardened_clay 14
fill ~72 ~-1 ~38 ~72 ~0 ~38 stained_hardened_clay 14
fill ~72 ~-1 ~40 ~72 ~0 ~40 stained_hardened_clay 14
fill ~72 ~-1 ~41 ~72 ~0 ~41 stained_hardened_clay 14
fill ~72 ~-1 ~43 ~73 ~-1 ~43 stained_hardened_clay 14
fill ~72 ~-1 ~44 ~72 ~0 ~44 stained_hardened_clay 14
fill ~72 ~-1 ~60 ~80 ~-1 ~60 grass 0
fill ~73 ~-1 ~61 ~79 ~-1 ~61 grass 0
fill ~73 ~-1 ~64 ~74 ~-1 ~64 tallgrass 1
setblock ~74 ~-1 ~62 tallgrass 1
fill ~74 ~-1 ~65 ~77 ~-1 ~65 tallgrass 1
fill ~75 ~-1 ~2 ~82 ~-1 ~2 grass 0
fill ~75 ~-1 ~62 ~77 ~-1 ~62 grass 0
setblock ~77 ~-1 ~0 tallgrass 1
fill ~77 ~-1 ~3 ~84 ~-1 ~3 grass 0
fill ~77 ~-1 ~63 ~77 ~-1 ~65 tallgrass 1
fill ~78 ~-1 ~59 ~80 ~-1 ~59 grass 0
setblock ~78 ~-1 ~62 tallgrass 1
fill ~78 ~-1 ~64 ~79 ~-1 ~64 tallgrass 1
fill ~79 ~-1 ~58 ~81 ~-1 ~58 grass 0
fill ~79 ~-1 ~63 ~80 ~-1 ~63 tallgrass 1
fill ~80 ~-1 ~61 ~82 ~-1 ~61 tallgrass 1
fill ~80 ~-1 ~62 ~83 ~-1 ~62 tallgrass 1
fill ~81 ~-1 ~0 ~81 ~-1 ~1 tallgrass 1
fill ~81 ~-1 ~4 ~84 ~-1 ~4 grass 0
fill ~81 ~-1 ~57 ~82 ~-1 ~57 grass 0
fill ~81 ~-1 ~59 ~84 ~-1 ~59 tallgrass 1
fill ~81 ~-1 ~60 ~85 ~-1 ~60 tallgrass 1
fill ~81 ~-1 ~63 ~81 ~1 ~63 log 0
fill ~82 ~-1 ~1 ~83 ~-1 ~1 tallgrass 1
fill ~82 ~-1 ~5 ~85 ~-1 ~5 grass 0
fill ~82 ~-1 ~56 ~84 ~-1 ~56 grass 0
setblock ~82 ~-1 ~63 tallgrass 1
fill ~83 ~-1 ~0 ~84 ~-1 ~0 tallgrass 1
setblock ~83 ~-1 ~2 tallgrass 1
setblock ~83 ~-1 ~58 tallgrass 1
fill ~84 ~-1 ~6 ~86 ~-1 ~6 grass 0
fill ~84 ~-1 ~55 ~85 ~-1 ~55 grass 0
fill ~84 ~-1 ~57 ~88 ~-1 ~57 tallgrass 1
fill ~85 ~-1 ~1 ~88 ~-1 ~1 tallgrass 1
fill ~85 ~-1 ~3 ~86 ~-1 ~3 tallgrass 1
fill ~85 ~-1 ~7 ~86 ~-1 ~7 grass 0
fill ~85 ~-1 ~53 ~87 ~-1 ~53 grass 0
fill ~85 ~-1 ~54 ~86 ~-1 ~54 grass 0
setblock ~85 ~-1 ~56 double_plant 2
setblock ~85 ~-1 ~58 tallgrass 1
setblock ~85 ~-1 ~61 tallgrass 1
setblock ~86 ~-1 ~0 tallgrass 1
fill ~86 ~-1 ~4 ~88 ~-1 ~4 tallgrass 1
fill ~86 ~-1 ~8 ~86 ~-1 ~9 grass 0
fill ~86 ~-1 ~51 ~88 ~-1 ~51 grass 0
fill ~86 ~-1 ~52 ~87 ~-1 ~52 grass 0
fill ~86 ~-1 ~55 ~87 ~-1 ~55 tallgrass 1
fill ~86 ~-1 ~56 ~86 ~-1 ~55 tallgrass 1
fill ~86 ~-1 ~59 ~87 ~-1 ~59 tallgrass 1
fill ~87 ~-1 ~5 ~87 ~-1 ~8 tallgrass 1
fill ~87 ~-1 ~9 ~87 ~-1 ~12 grass 0
fill ~87 ~-1 ~48 ~89 ~-1 ~48 grass 0
fill ~87 ~-1 ~49 ~89 ~-1 ~49 grass 0
fill ~87 ~-1 ~50 ~88 ~-1 ~50 grass 0
fill ~87 ~-1 ~54 ~88 ~-1 ~54 tallgrass 1
setblock ~87 ~-1 ~58 tallgrass 1
fill ~88 ~-1 ~3 ~89 ~-1 ~3 tallgrass 1
fill ~88 ~-1 ~6 ~90 ~-1 ~6 tallgrass 1
fill ~88 ~-1 ~7 ~91 ~-1 ~7 tallgrass 1
fill ~88 ~-1 ~8 ~90 ~-1 ~8 tallgrass 1
fill ~88 ~-1 ~9 ~92 ~-1 ~9 tallgrass 1
fill ~88 ~-1 ~11 ~88 ~-1 ~14 grass 0
fill ~88 ~-1 ~46 ~89 ~-1 ~46 grass 0
fill ~88 ~-1 ~47 ~89 ~-1 ~47 grass 0
fill ~88 ~-1 ~53 ~89 ~-1 ~53 tallgrass 1
setblock ~88 ~-1 ~56 tallgrass 1
setblock ~89 ~-1 ~10 log 0
fill ~89 ~-1 ~11 ~93 ~-1 ~11 tallgrass 1
fill ~89 ~-1 ~12 ~90 ~-1 ~12 tallgrass 1
fill ~89 ~-1 ~13 ~89 ~-1 ~16 grass 0
fill ~89 ~-1 ~42 ~91 ~-1 ~42 grass 0
fill ~89 ~-1 ~43 ~90 ~-1 ~43 grass 0
fill ~89 ~-1 ~44 ~90 ~-1 ~44 grass 0
fill ~89 ~-1 ~45 ~89 ~-1 ~42 grass 0
fill ~89 ~-1 ~50 ~89 ~-1 ~53 tallgrass 1
setblock ~90 ~-1 ~4 tallgrass 1
fill ~90 ~-1 ~13 ~91 ~-1 ~13 tallgrass 1
fill ~90 ~-1 ~14 ~90 ~-1 ~11 tallgrass 1
fill ~90 ~-1 ~15 ~90 ~-1 ~18 grass 0
fill ~90 ~-1 ~39 ~92 ~-1 ~39 grass 0
fill ~90 ~-1 ~40 ~91 ~-1 ~40 grass 0
fill ~90 ~-1 ~41 ~91 ~-1 ~41 grass 0
fill ~90 ~-1 ~46 ~91 ~-1 ~46 tallgrass 1
setblock ~90 ~-1 ~51 tallgrass 1
setblock ~91 ~-1 ~10 tallgrass 1
fill ~91 ~-1 ~15 ~92 ~-1 ~15 tallgrass 1
fill ~91 ~-1 ~16 ~91 ~-1 ~21 grass 0
fill ~91 ~-1 ~38 ~92 ~-1 ~38 grass 0
setblock ~91 ~-1 ~43 tallgrass 1
fill ~91 ~-1 ~47 ~93 ~-1 ~47 tallgrass 1
fill ~91 ~-1 ~48 ~92 ~-1 ~48 tallgrass 1
setblock ~92 ~-1 ~8 tallgrass 1
fill ~92 ~-1 ~12 ~94 ~-1 ~12 tallgrass 1
setblock ~92 ~-1 ~14 tallgrass 1
fill ~92 ~-1 ~16 ~95 ~-1 ~16 tallgrass 1
fill ~92 ~-1 ~17 ~95 ~-1 ~17 tallgrass 1
fill ~92 ~-1 ~18 ~92 ~-1 ~23 grass 0
fill ~92 ~-1 ~30 ~93 ~-1 ~30 grass 0
fill ~92 ~-1 ~31 ~93 ~-1 ~31 grass 0
fill ~92 ~-1 ~32 ~93 ~-1 ~32 grass 0
fill ~92 ~-1 ~33 ~93 ~-1 ~33 grass 0
fill ~92 ~-1 ~34 ~93 ~-1 ~34 grass 0
fill ~92 ~-1 ~35 ~93 ~-1 ~35 grass 0
fill ~92 ~-1 ~36 ~93 ~-1 ~36 grass 0
fill ~92 ~-1 ~37 ~92 ~-1 ~30 grass 0
fill ~92 ~-1 ~40 ~93 ~-1 ~40 tallgrass 1
setblock ~92 ~-1 ~42 tallgrass 1
fill ~92 ~-1 ~45 ~93 ~-1 ~45 tallgrass 1
fill ~92 ~-1 ~49 ~92 ~-1 ~50 tallgrass 1
setblock ~93 ~-1 ~10 tallgrass 1
setblock ~93 ~-1 ~18 tallgrass 1
fill ~93 ~-1 ~20 ~93 ~-1 ~36 grass 0
setblock ~93 ~-1 ~39 double_plant 2
setblock ~93 ~-1 ~41 tallgrass 1
setblock ~93 ~-1 ~44 tallgrass 1
setblock ~93 ~-1 ~46 tallgrass 1
fill ~94 ~-1 ~13 ~94 ~-1 ~17 tallgrass 1
fill ~94 ~-1 ~18 ~94 ~1 ~18 log 0
fill ~94 ~-1 ~19 ~95 ~-1 ~19 tallgrass 1
fill ~94 ~-1 ~20 ~94 ~-1 ~23 tallgrass 1
fill ~94 ~-1 ~24 ~94 ~-1 ~29 grass 0
fill ~94 ~-1 ~30 ~94 ~-1 ~31 tallgrass 1
setblock ~94 ~-1 ~33 tallgrass 1
setblock ~94 ~-1 ~38 double_plant 2
fill ~94 ~-1 ~39 ~95 ~-1 ~39 tallgrass 1
fill ~94 ~-1 ~42 ~95 ~-1 ~42 tallgrass 1
fill ~94 ~-1 ~43 ~95 ~-1 ~43 tallgrass 1
fill ~94 ~-1 ~46 ~94 ~2 ~46 leaves 15
fill ~95 ~-1 ~18 ~96 ~-1 ~18 tallgrass 1
fill ~95 ~-1 ~21 ~96 ~-1 ~21 tallgrass 1
fill ~95 ~-1 ~22 ~96 ~-1 ~22 tallgrass 1
fill ~95 ~-1 ~23 ~95 ~-1 ~29 tallgrass 1
fill ~95 ~-1 ~31 ~95 ~-1 ~32 tallgrass 1
fill ~95 ~-1 ~40 ~95 ~-1 ~43 tallgrass 1
setblock ~96 ~-1 ~24 tallgrass 1
fill ~96 ~-1 ~28 ~96 ~-1 ~29 tallgrass 1
setblock ~97 ~-1 ~23 tallgrass 1
fill ~97 ~-1 ~24 ~97 ~2 ~24 leaves 15
fill ~97 ~-1 ~25 ~97 ~-1 ~26 tallgrass 1
fill ~97 ~-1 ~27 ~97 ~0 ~27 log 0
fill ~97 ~-1 ~29 ~97 ~-1 ~30 tallgrass 1
fill ~97 ~-1 ~46 ~97 ~0 ~46 log 0
fill ~3 ~0 ~35 ~3 ~3 ~35 leaves 7
fill ~12 ~0 ~50 ~12 ~2 ~50 leaves 15
fill ~15 ~0 ~48 ~15 ~3 ~48 leaves 15
fill ~16 ~0 ~50 ~16 ~2 ~50 leaves 15
setblock ~17 ~0 ~66 leaves 15
fill ~18 ~0 ~48 ~18 ~1 ~48 log 0
fill ~19 ~0 ~64 ~19 ~1 ~64 leaves 7
fill ~21 ~0 ~1 ~21 ~2 ~1 leaves 15
fill ~21 ~0 ~5 ~21 ~2 ~5 leaves 15
fill ~23 ~0 ~29 ~31 ~0 ~29 stained_hardened_clay 14
fill ~23 ~0 ~30 ~30 ~0 ~30 stained_hardened_clay 14
fill ~23 ~0 ~31 ~29 ~0 ~31 stained_hardened_clay 6
fill ~23 ~0 ~32 ~30 ~0 ~32 stained_hardened_clay 14
fill ~23 ~0 ~33 ~31 ~0 ~33 stained_hardened_clay 14
setblock ~23 ~0 ~38 torch 5
fill ~24 ~0 ~28 ~34 ~0 ~28 stained_hardened_clay 14
fill ~24 ~0 ~34 ~34 ~0 ~34 stained_hardened_clay 14
fill ~24 ~0 ~44 ~24 ~0 ~45 tallgrass 1
fill ~25 ~0 ~27 ~36 ~0 ~27 stained_hardened_clay 14
fill ~25 ~0 ~35 ~36 ~0 ~35 stained_hardened_clay 14
setblock ~25 ~0 ~42 double_plant 2
setblock ~25 ~0 ~43 tallgrass 1
fill ~25 ~0 ~46 ~26 ~0 ~46 tallgrass 1
fill ~25 ~0 ~47 ~25 ~0 ~48 tallgrass 1
setblock ~26 ~0 ~11 tallgrass 1
setblock ~26 ~0 ~15 tallgrass 1
fill ~26 ~0 ~17 ~26 ~0 ~18 tallgrass 1
fill ~26 ~0 ~20 ~26 ~0 ~22 tallgrass 1
setblock ~26 ~0 ~24 tallgrass 1
fill ~26 ~0 ~38 ~28 ~0 ~38 tallgrass 1
fill ~26 ~0 ~39 ~27 ~0 ~39 tallgrass 1
fill ~26 ~0 ~40 ~26 ~0 ~38 tallgrass 1
fill ~26 ~0 ~42 ~27 ~0 ~42 grass 0
fill ~26 ~0 ~43 ~26 ~0 ~45 grass 0
fill ~26 ~0 ~48 ~27 ~0 ~48 tallgrass 1
fill ~26 ~0 ~49 ~27 ~0 ~49 tallgrass 1
fill ~26 ~0 ~50 ~26 ~0 ~48 tallgrass 1
fill ~27 ~0 ~7 ~27 ~0 ~10 tallgrass 1
fill ~27 ~0 ~12 ~27 ~0 ~14 tallgrass 1
setblock ~27 ~0 ~16 tallgrass 1
fill ~27 ~0 ~17 ~28 ~0 ~17 grass 0
fill ~27 ~0 ~18 ~27 ~0 ~22 grass 0
setblock ~27 ~0 ~23 tallgrass 1
setblock ~27 ~0 ~24 fence 0
fill ~27 ~0 ~26 ~37 ~0 ~26 stained_hardened_clay 14
fill ~27 ~0 ~36 ~37 ~0 ~36 stained_hardened_clay 14
fill ~27 ~0 ~40 ~28 ~0 ~40 grass 0
fill ~27 ~0 ~41 ~27 ~0 ~40 grass 0
fill ~27 ~0 ~45 ~27 ~0 ~47 grass 0
setblock ~27 ~0 ~51 tallgrass 1
fill ~27 ~0 ~68 ~27 ~3 ~68 leaves 15
fill ~28 ~0 ~6 ~30 ~0 ~6 tallgrass 1
setblock ~28 ~0 ~8 tallgrass 1
fill ~28 ~0 ~11 ~28 ~0 ~17 grass 0
setblock ~28 ~0 ~23 grass 0
setblock ~28 ~0 ~39 grass 0
fill ~28 ~0 ~47 ~28 ~0 ~49 grass 0
setblock ~28 ~0 ~50 tallgrass 1
setblock ~29 ~0 ~7 tallgrass 1
fill ~29 ~0 ~8 ~30 ~0 ~8 grass 0
fill ~29 ~0 ~9 ~29 ~0 ~10 grass 0
fill ~29 ~0 ~24 ~30 ~0 ~24 stained_hardened_clay 2
fill ~29 ~0 ~25 ~37 ~0 ~25 stained_hardened_clay 14
fill ~29 ~0 ~37 ~31 ~0 ~37 stained_hardened_clay 14
setblock ~29 ~0 ~38 stained_hardened_clay 2
fill ~29 ~0 ~50 ~29 ~0 ~51 grass 0
fill ~29 ~0 ~52 ~29 ~0 ~54 tallgrass 1
setblock ~29 ~0 ~56 tallgrass 1
fill ~30 ~0 ~4 ~33 ~0 ~4 tallgrass 1
fill ~30 ~0 ~5 ~32 ~0 ~5 tallgrass 1
setblock ~30 ~0 ~7 grass 0
setblock ~30 ~0 ~31 stone_slab 4
fill ~30 ~0 ~51 ~30 ~0 ~52 grass 0
fill ~30 ~0 ~53 ~30 ~0 ~55 tallgrass 1
setblock ~30 ~0 ~57 tallgrass 1
setblock ~30 ~0 ~59 tallgrass 1
fill ~30 ~0 ~68 ~30 ~1 ~68 log 0
fill ~31 ~0 ~3 ~33 ~0 ~3 tallgrass 1
fill ~31 ~0 ~6 ~33 ~0 ~6 grass 0
setblock ~31 ~0 ~30 stone_slab 4
setblock ~31 ~0 ~32 stone_slab 4
fill ~31 ~0 ~53 ~31 ~0 ~54 grass 0
setblock ~31 ~0 ~55 tallgrass 1
fill ~31 ~0 ~58 ~33 ~0 ~58 tallgrass 1
fill ~31 ~0 ~59 ~31 ~2 ~59 log 0
setblock ~32 ~0 ~7 grass 0
fill ~32 ~0 ~29 ~34 ~0 ~29 stone_slab 4
fill ~32 ~0 ~33 ~34 ~0 ~33 stone_slab 4
fill ~32 ~0 ~54 ~32 ~0 ~56 grass 0
setblock ~32 ~0 ~57 tallgrass 1
fill ~32 ~0 ~59 ~33 ~0 ~59 tallgrass 1
fill ~32 ~0 ~60 ~32 ~0 ~57 tallgrass 1
setblock ~33 ~0 ~2 tallgrass 1
setblock ~33 ~0 ~5 grass 0
fill ~33 ~0 ~56 ~34 ~0 ~56 grass 0
fill ~33 ~0 ~57 ~34 ~0 ~57 grass 0
setblock ~33 ~0 ~61 tallgrass 1
setblock ~34 ~0 ~4 grass 0
fill ~34 ~0 ~58 ~35 ~0 ~58 grass 0
fill ~34 ~0 ~59 ~36 ~0 ~59 grass 0
setblock ~35 ~0 ~2 tallgrass 1
fill ~35 ~0 ~3 ~36 ~0 ~3 grass 0
fill ~35 ~0 ~28 ~36 ~0 ~28 stone_slab 4
fill ~35 ~0 ~34 ~36 ~0 ~34 stone_slab 4
fill ~35 ~0 ~60 ~41 ~0 ~60 grass 0
setblock ~35 ~0 ~61 tallgrass 1
fill ~36 ~0 ~0 ~39 ~0 ~0 tallgrass 1
fill ~36 ~0 ~2 ~37 ~0 ~2 grass 0
fill ~36 ~0 ~37 ~37 ~0 ~37 stained_hardened_clay 14
fill ~36 ~0 ~61 ~51 ~0 ~61 grass 0
fill ~36 ~0 ~62 ~36 ~0 ~63 tallgrass 1
fill ~37 ~0 ~1 ~41 ~0 ~1 grass 0
setblock ~37 ~0 ~27 stone_slab 4
setblock ~37 ~0 ~35 stone_slab 4
setblock ~37 ~0 ~63 tallgrass 1
setblock ~38 ~0 ~24 stained_hardened_clay 14
fill ~38 ~0 ~25 ~38 ~0 ~26 stone_slab 4
fill ~38 ~0 ~36 ~38 ~0 ~37 stone_slab 4
setblock ~38 ~0 ~38 stained_hardened_clay 14
setblock ~38 ~0 ~62 tallgrass 1
fill ~39 ~0 ~21 ~39 ~0 ~23 stained_hardened_clay 14
setblock ~39 ~0 ~24 stone_slab 4
setblock ~39 ~0 ~38 stone_slab 4
fill ~39 ~0 ~39 ~39 ~0 ~40 stained_hardened_clay 14
setblock ~39 ~0 ~41 stained_hardened_clay 10
fill ~39 ~0 ~42 ~39 ~0 ~44 stained_hardened_clay 14
fill ~39 ~0 ~63 ~46 ~0 ~63 tallgrass 1
fill ~40 ~0 ~0 ~51 ~0 ~0 grass 0
fill ~40 ~0 ~17 ~40 ~7 ~17 stained_hardened_clay 14
fill ~40 ~0 ~18 ~40 ~0 ~17 stained_hardened_clay 14
setblock ~40 ~0 ~20 stained_hardened_clay 14
fill ~40 ~0 ~44 ~40 ~0 ~46 stained_hardened_clay 14
fill ~40 ~0 ~62 ~42 ~0 ~62 tallgrass 1
setblock ~41 ~0 ~16 stained_hardened_clay 14
fill ~41 ~0 ~47 ~45 ~0 ~47 stained_hardened_clay 14
fill ~41 ~0 ~64 ~42 ~0 ~64 tallgrass 1
fill ~42 ~0 ~15 ~47 ~0 ~15 stained_hardened_clay 14
fill ~43 ~0 ~62 ~53 ~0 ~62 grass 0
setblock ~43 ~0 ~64 red_flower 7
setblock ~44 ~0 ~64 tallgrass 1
fill ~45 ~0 ~65 ~47 ~0 ~65 tallgrass 1
fill ~46 ~0 ~46 ~46 ~1 ~46 stained_hardened_clay 14
fill ~46 ~0 ~64 ~48 ~0 ~64 tallgrass 1
setblock ~47 ~0 ~46 stained_hardened_clay 10
fill ~48 ~0 ~1 ~50 ~0 ~1 grass 0
fill ~48 ~0 ~14 ~50 ~0 ~14 stained_hardened_clay 14
fill ~48 ~0 ~46 ~57 ~0 ~46 stained_hardened_clay 14
fill ~49 ~0 ~63 ~56 ~0 ~63 grass 0
fill ~50 ~0 ~65 ~54 ~0 ~65 tallgrass 1
fill ~51 ~0 ~15 ~52 ~0 ~15 stained_hardened_clay 14
fill ~52 ~0 ~64 ~54 ~0 ~64 grass 0
fill ~53 ~0 ~0 ~64 ~0 ~0 grass 0
fill ~53 ~0 ~16 ~65 ~0 ~16 stained_hardened_clay 14
fill ~55 ~0 ~62 ~59 ~0 ~62 grass 0
setblock ~55 ~0 ~64 tallgrass 1
fill ~56 ~0 ~65 ~57 ~0 ~65 tallgrass 1
fill ~57 ~0 ~63 ~59 ~0 ~63 tallgrass 1
fill ~57 ~0 ~64 ~59 ~0 ~64 tallgrass 1
fill ~59 ~0 ~45 ~69 ~0 ~45 stained_hardened_clay 14
fill ~59 ~0 ~65 ~60 ~0 ~65 tallgrass 1
fill ~60 ~0 ~61 ~62 ~0 ~61 grass 0
setblock ~60 ~0 ~62 tallgrass 1
fill ~61 ~0 ~1 ~71 ~0 ~1 grass 0
setblock ~61 ~0 ~60 grass 0
fill ~61 ~0 ~63 ~61 ~0 ~64 tallgrass 1
setblock ~62 ~0 ~62 tallgrass 1
fill ~63 ~0 ~60 ~66 ~0 ~60 grass 0
fill ~63 ~0 ~61 ~64 ~0 ~61 tallgrass 1
setblock ~63 ~0 ~63 tallgrass 1
setblock ~64 ~0 ~2 grass 0
fill ~65 ~0 ~0 ~66 ~0 ~0 tallgrass 1
fill ~66 ~0 ~15 ~66 ~9 ~15 stained_hardened_clay 14
fill ~66 ~0 ~61 ~68 ~0 ~61 tallgrass 1
fill ~67 ~0 ~16 ~69 ~0 ~16 stained_hardened_clay 14
fill ~67 ~0 ~59 ~69 ~0 ~59 grass 0
setblock ~67 ~0 ~60 leaves 12
setblock ~67 ~0 ~62 tallgrass 1
fill ~68 ~0 ~0 ~70 ~0 ~0 tallgrass 1
setblock ~68 ~0 ~2 grass 0
fill ~68 ~0 ~60 ~69 ~0 ~60 tallgrass 1
setblock ~70 ~0 ~17 stained_hardened_clay 14
fill ~70 ~0 ~24 ~70 ~0 ~28 stained_hardened_clay 14
fill ~70 ~0 ~45 ~71 ~0 ~45 stained_hardened_clay 10
fill ~70 ~0 ~60 ~71 ~0 ~60 grass 0
fill ~71 ~0 ~2 ~74 ~0 ~2 grass 0
fill ~71 ~0 ~18 ~71 ~1 ~18 stained_hardened_clay 14
fill ~71 ~0 ~19 ~71 ~1 ~19 stained_hardened_clay 14
fill ~71 ~0 ~21 ~71 ~0 ~22 stained_hardened_clay 14
fill ~71 ~0 ~23 ~71 ~1 ~23 piston_extension 4
fill ~71 ~0 ~28 ~71 ~1 ~28 stained_hardened_clay 14
fill ~72 ~0 ~0 ~72 ~0 ~1 tallgrass 1
setblock ~72 ~0 ~3 grass 0
fill ~72 ~0 ~20 ~72 ~1 ~20 stained_hardened_clay 14
fill ~72 ~0 ~29 ~72 ~1 ~29 stained_hardened_clay 14
fill ~72 ~0 ~30 ~72 ~1 ~30 stained_hardened_clay 14
setblock ~72 ~0 ~37 stained_hardened_clay 14
fill ~72 ~0 ~39 ~74 ~0 ~39 stained_hardened_clay 14
fill ~72 ~0 ~59 ~77 ~0 ~59 grass 0
fill ~72 ~0 ~60 ~77 ~0 ~60 tallgrass 1
setblock ~73 ~0 ~1 tallgrass 1
fill ~73 ~0 ~32 ~73 ~1 ~32 stained_hardened_clay 2
fill ~73 ~0 ~33 ~73 ~1 ~33 stained_hardened_clay 2
fill ~73 ~0 ~34 ~73 ~0 ~35 stained_hardened_clay 2
setblock ~73 ~0 ~36 stained_hardened_clay 14
fill ~73 ~0 ~40 ~73 ~0 ~41 stained_hardened_clay 14
setblock ~73 ~0 ~44 stained_hardened_clay 14
fill ~73 ~0 ~61 ~78 ~0 ~61 tallgrass 1
fill ~74 ~0 ~42 ~74 ~5 ~42 stained_hardened_clay 14
fill ~74 ~0 ~43 ~74 ~3 ~43 stained_hardened_clay 14
fill ~75 ~0 ~0 ~76 ~0 ~0 tallgrass 1
fill ~75 ~0 ~2 ~77 ~0 ~2 tallgrass 1
fill ~75 ~0 ~3 ~76 ~0 ~3 grass 0
fill ~75 ~0 ~62 ~76 ~0 ~62 tallgrass 1
fill ~76 ~0 ~1 ~80 ~0 ~1 tallgrass 1
setblock ~77 ~0 ~3 tallgrass 1
setblock ~77 ~0 ~4 dirt 0
fill ~78 ~0 ~4 ~80 ~0 ~4 grass 0
setblock ~78 ~0 ~58 grass 0
setblock ~78 ~0 ~59 tallgrass 1
fill ~79 ~0 ~3 ~83 ~0 ~3 tallgrass 1
fill ~79 ~0 ~5 ~81 ~0 ~5 grass 0
fill ~79 ~0 ~57 ~80 ~0 ~57 grass 0
fill ~79 ~0 ~58 ~81 ~0 ~58 tallgrass 1
setblock ~79 ~0 ~60 tallgrass 1
setblock ~80 ~0 ~2 tallgrass 1
fill ~80 ~0 ~56 ~81 ~0 ~56 grass 0
fill ~80 ~0 ~62 ~80 ~2 ~62 leaves 7
fill ~81 ~0 ~6 ~83 ~0 ~6 grass 0
fill ~81 ~0 ~55 ~83 ~0 ~55 grass 0
fill ~81 ~0 ~57 ~82 ~0 ~57 tallgrass 1
setblock ~82 ~0 ~2 tallgrass 1
fill ~82 ~0 ~4 ~84 ~0 ~4 tallgrass 1
fill ~82 ~0 ~5 ~84 ~0 ~5 tallgrass 1
fill ~82 ~0 ~53 ~84 ~0 ~53 grass 0
fill ~82 ~0 ~54 ~84 ~0 ~54 grass 0
setblock ~82 ~0 ~56 tallgrass 1
fill ~83 ~0 ~7 ~84 ~0 ~7 grass 0
fill ~83 ~0 ~51 ~85 ~0 ~51 grass 0
fill ~83 ~0 ~52 ~85 ~0 ~52 grass 0
fill ~84 ~0 ~3 ~84 ~6 ~3 fence 0
fill ~84 ~0 ~6 ~86 ~0 ~6 tallgrass 1
fill ~84 ~0 ~8 ~85 ~0 ~8 grass 0
fill ~84 ~0 ~49 ~86 ~0 ~49 grass 0
fill ~84 ~0 ~50 ~86 ~0 ~50 grass 0
setblock ~84 ~0 ~55 tallgrass 1
fill ~85 ~0 ~9 ~85 ~0 ~10 grass 0
fill ~85 ~0 ~48 ~86 ~0 ~48 grass 0
setblock ~85 ~0 ~54 tallgrass 1
setblock ~86 ~0 ~7 tallgrass 1
fill ~86 ~0 ~10 ~86 ~0 ~14 grass 0
fill ~86 ~0 ~46 ~87 ~0 ~46 grass 0
fill ~86 ~0 ~47 ~87 ~0 ~47 grass 0
fill ~86 ~0 ~51 ~86 ~0 ~53 tallgrass 1
setblock ~87 ~0 ~11 tallgrass 1
fill ~87 ~0 ~13 ~87 ~0 ~16 grass 0
fill ~87 ~0 ~45 ~88 ~0 ~45 grass 0
fill ~87 ~0 ~48 ~89 ~0 ~48 tallgrass 1
fill ~87 ~0 ~49 ~88 ~0 ~49 tallgrass 1
fill ~88 ~0 ~15 ~88 ~0 ~18 grass 0
fill ~88 ~0 ~33 ~91 ~0 ~33 grass 0
fill ~88 ~0 ~34 ~91 ~0 ~34 grass 0
fill ~88 ~0 ~35 ~91 ~0 ~35 grass 0
fill ~88 ~0 ~39 ~89 ~0 ~39 grass 0
fill ~88 ~0 ~40 ~89 ~0 ~40 grass 0
fill ~88 ~0 ~41 ~89 ~0 ~41 grass 0
fill ~88 ~0 ~42 ~88 ~0 ~45 grass 0
fill ~88 ~0 ~46 ~89 ~0 ~46 tallgrass 1
fill ~88 ~0 ~47 ~88 ~0 ~46 tallgrass 1
setblock ~88 ~0 ~50 tallgrass 1
setblock ~89 ~0 ~6 leaves 15
fill ~89 ~0 ~9 ~89 ~1 ~9 log 0
setblock ~89 ~0 ~13 tallgrass 1
fill ~89 ~0 ~15 ~90 ~0 ~15 tallgrass 1
fill ~89 ~0 ~16 ~90 ~0 ~16 tallgrass 1
fill ~89 ~0 ~17 ~89 ~0 ~20 grass 0
fill ~89 ~0 ~31 ~89 ~0 ~41 grass 0
fill ~89 ~0 ~42 ~90 ~0 ~42 tallgrass 1
fill ~89 ~0 ~43 ~90 ~0 ~43 tallgrass 1
fill ~89 ~0 ~44 ~90 ~0 ~44 tallgrass 1
fill ~89 ~0 ~45 ~89 ~0 ~42 tallgrass 1
fill ~90 ~0 ~18 ~92 ~0 ~18 tallgrass 1
fill ~90 ~0 ~19 ~90 ~0 ~22 grass 0
fill ~90 ~0 ~28 ~92 ~0 ~28 grass 0
fill ~90 ~0 ~29 ~92 ~0 ~29 grass 0
fill ~90 ~0 ~32 ~91 ~0 ~32 grass 0
fill ~90 ~0 ~36 ~91 ~0 ~36 grass 0
setblock ~90 ~0 ~38 grass 0
fill ~90 ~0 ~41 ~91 ~0 ~41 tallgrass 1
setblock ~91 ~0 ~17 tallgrass 1
setblock ~91 ~0 ~21 tallgrass 1
fill ~91 ~0 ~22 ~91 ~0 ~37 grass 0
fill ~91 ~0 ~38 ~92 ~0 ~38 tallgrass 1
fill ~91 ~0 ~39 ~91 ~0 ~41 tallgrass 1
setblock ~92 ~0 ~19 tallgrass 1
fill ~92 ~0 ~22 ~92 ~0 ~23 tallgrass 1
fill ~92 ~0 ~24 ~92 ~0 ~29 grass 0
fill ~92 ~0 ~31 ~93 ~0 ~31 tallgrass 1
fill ~92 ~0 ~32 ~92 ~0 ~33 tallgrass 1
fill ~92 ~0 ~36 ~93 ~0 ~36 tallgrass 1
fill ~92 ~0 ~37 ~92 ~0 ~36 tallgrass 1
fill ~93 ~0 ~17 ~93 ~2 ~17 leaves 7
setblock ~93 ~0 ~21 tallgrass 1
setblock ~93 ~0 ~24 double_plant 2
fill ~93 ~0 ~26 ~94 ~0 ~26 tallgrass 1
fill ~93 ~0 ~27 ~94 ~0 ~27 tallgrass 1
fill ~93 ~0 ~28 ~93 ~0 ~31 tallgrass 1
setblock ~93 ~0 ~34 tallgrass 1
fill ~94 ~0 ~24 ~94 ~0 ~27 tallgrass 1
setblock ~94 ~0 ~29 tallgrass 1
fill ~95 ~0 ~26 ~95 ~2 ~26 leaves 15
fill ~96 ~0 ~44 ~96 ~1 ~44 leaves 15
fill ~96 ~0 ~48 ~96 ~2 ~48 leaves 15
setblock ~5 ~1 ~37 leaves 7
fill ~11 ~1 ~38 ~11 ~4 ~38 leaves 7
fill ~14 ~1 ~50 ~14 ~2 ~50 log 0
fill ~14 ~1 ~52 ~14 ~2 ~52 leaves 15
fill ~15 ~1 ~64 ~15 ~2 ~64 leaves 15
fill ~17 ~1 ~46 ~17 ~3 ~46 leaves 15
fill ~17 ~1 ~50 ~17 ~3 ~50 leaves 15
fill ~17 ~1 ~64 ~17 ~2 ~64 log 0
setblock ~17 ~1 ~66 leaves 7
fill ~21 ~1 ~3 ~21 ~2 ~3 log 0
fill ~21 ~1 ~13 ~21 ~3 ~13 leaves 7
fill ~23 ~1 ~3 ~23 ~2 ~3 leaves 15
fill ~26 ~1 ~42 ~26 ~1 ~45 tallgrass 1
fill ~27 ~1 ~17 ~28 ~1 ~17 tallgrass 1
fill ~27 ~1 ~18 ~27 ~1 ~17 tallgrass 1
setblock ~27 ~1 ~20 tallgrass 1
setblock ~27 ~1 ~22 tallgrass 1
setblock ~27 ~1 ~24 torch 5
fill ~27 ~1 ~40 ~28 ~1 ~40 tallgrass 1
fill ~27 ~1 ~43 ~27 ~1 ~44 stained_hardened_clay 2
setblock ~27 ~1 ~45 tallgrass 1
fill ~27 ~1 ~47 ~28 ~1 ~47 tallgrass 1
fill ~28 ~1 ~12 ~28 ~1 ~13 tallgrass 1
setblock ~28 ~1 ~16 tallgrass 1
fill ~28 ~1 ~18 ~28 ~1 ~22 stained_hardened_clay 2
setblock ~28 ~1 ~23 tallgrass 1
fill ~28 ~1 ~41 ~28 ~1 ~42 stained_hardened_clay 2
fill ~28 ~1 ~45 ~28 ~2 ~45 stained_hardened_clay 2
fill ~28 ~1 ~46 ~28 ~1 ~45 stained_hardened_clay 2
fill ~28 ~1 ~48 ~28 ~1 ~49 tallgrass 1
fill ~29 ~1 ~8 ~30 ~1 ~8 tallgrass 1
setblock ~29 ~1 ~10 tallgrass 1
fill ~29 ~1 ~11 ~29 ~1 ~17 stained_hardened_clay 2
fill ~29 ~1 ~20 ~29 ~1 ~23 stained_hardened_clay 2
fill ~29 ~1 ~39 ~30 ~1 ~39 stained_hardened_clay 2
fill ~29 ~1 ~40 ~29 ~1 ~39 stained_hardened_clay 2
fill ~29 ~1 ~47 ~29 ~2 ~47 stained_hardened_clay 2
fill ~29 ~1 ~48 ~29 ~1 ~49 stained_hardened_clay 2
fill ~29 ~1 ~51 ~30 ~1 ~51 tallgrass 1
fill ~29 ~1 ~66 ~29 ~3 ~66 leaves 15
fill ~29 ~1 ~70 ~29 ~2 ~70 leaves 15
setblock ~30 ~1 ~7 tallgrass 1
setblock ~30 ~1 ~9 leaves 3
setblock ~30 ~1 ~10 stained_hardened_clay 2
fill ~30 ~1 ~22 ~30 ~1 ~23 stained_hardened_clay 2
fill ~30 ~1 ~38 ~31 ~1 ~38 stained_hardened_clay 2
fill ~30 ~1 ~49 ~30 ~1 ~50 stained_hardened_clay 2
fill ~30 ~1 ~58 ~30 ~3 ~58 leaves 7
setblock ~31 ~1 ~7 leaves 0
fill ~31 ~1 ~8 ~34 ~1 ~8 stained_hardened_clay 2
fill ~31 ~1 ~9 ~32 ~1 ~9 stained_hardened_clay 2
fill ~31 ~1 ~23 ~33 ~1 ~23 stained_hardened_clay 2
fill ~31 ~1 ~24 ~37 ~1 ~24 stained_hardened_clay 2
fill ~31 ~1 ~51 ~31 ~1 ~52 stained_hardened_clay 2
fill ~31 ~1 ~53 ~31 ~1 ~54 tallgrass 1
fill ~32 ~1 ~37 ~34 ~1 ~37 stained_hardened_clay 2
setblock ~32 ~1 ~52 stained_hardened_clay 2
setblock ~32 ~1 ~53 stained_hardened_clay 10
setblock ~32 ~1 ~54 tallgrass 1
fill ~32 ~1 ~56 ~34 ~1 ~56 tallgrass 1
fill ~33 ~1 ~5 ~33 ~1 ~6 tallgrass 1
fill ~33 ~1 ~7 ~35 ~1 ~7 stained_hardened_clay 2
fill ~33 ~1 ~54 ~34 ~1 ~54 stained_hardened_clay 2
setblock ~33 ~1 ~55 stained_hardened_clay 10
fill ~33 ~1 ~57 ~34 ~1 ~57 tallgrass 1
setblock ~34 ~1 ~4 tallgrass 1
fill ~34 ~1 ~5 ~36 ~1 ~5 stained_hardened_clay 2
fill ~34 ~1 ~6 ~35 ~1 ~6 stained_hardened_clay 2
fill ~34 ~1 ~55 ~35 ~1 ~55 stained_hardened_clay 2
fill ~34 ~1 ~58 ~35 ~1 ~58 tallgrass 1
fill ~35 ~1 ~4 ~37 ~1 ~4 stained_hardened_clay 2
setblock ~35 ~1 ~37 stained_hardened_clay 6
fill ~35 ~1 ~56 ~36 ~1 ~56 stained_hardened_clay 2
fill ~35 ~1 ~57 ~36 ~1 ~57 stained_hardened_clay 2
setblock ~35 ~1 ~60 tallgrass 1
fill ~36 ~1 ~2 ~37 ~1 ~2 tallgrass 1
fill ~36 ~1 ~3 ~36 ~1 ~2 tallgrass 1
fill ~36 ~1 ~38 ~37 ~1 ~38 stained_hardened_clay 14
setblock ~36 ~1 ~58 stained_hardened_clay 6
fill ~36 ~1 ~61 ~49 ~1 ~61 tallgrass 1
fill ~37 ~1 ~1 ~41 ~1 ~1 tallgrass 1
fill ~37 ~1 ~3 ~39 ~1 ~3 stained_hardened_clay 2
setblock ~37 ~1 ~57 stained_hardened_clay 6
fill ~37 ~1 ~58 ~38 ~1 ~58 stained_hardened_clay 2
fill ~37 ~1 ~59 ~38 ~1 ~59 stained_hardened_clay 2
setblock ~37 ~1 ~60 tallgrass 1
fill ~38 ~1 ~2 ~42 ~1 ~2 stained_hardened_clay 2
fill ~38 ~1 ~21 ~38 ~1 ~23 stained_hardened_clay 2
fill ~38 ~1 ~39 ~38 ~1 ~43 stained_hardened_clay 14
fill ~39 ~1 ~18 ~39 ~7 ~18 stained_hardened_clay 14
fill ~39 ~1 ~19 ~39 ~2 ~19 stained_hardened_clay 14
fill ~39 ~1 ~20 ~39 ~1 ~18 stained_hardened_clay 14
setblock ~39 ~1 ~59 stained_hardened_clay 10
fill ~39 ~1 ~60 ~41 ~1 ~60 tallgrass 1
setblock ~40 ~1 ~0 tallgrass 1
fill ~40 ~1 ~16 ~40 ~6 ~16 stained_hardened_clay 14
fill ~40 ~1 ~46 ~40 ~5 ~46 stained_hardened_clay 14
fill ~40 ~1 ~59 ~42 ~1 ~59 stained_hardened_clay 2
fill ~41 ~1 ~15 ~47 ~1 ~15 stained_hardened_clay 14
fill ~41 ~1 ~47 ~45 ~1 ~47 stained_hardened_clay 14
fill ~42 ~1 ~0 ~44 ~1 ~0 tallgrass 1
fill ~42 ~1 ~1 ~46 ~1 ~1 stained_hardened_clay 2
fill ~42 ~1 ~60 ~43 ~1 ~60 stained_hardened_clay 2
fill ~43 ~1 ~62 ~50 ~1 ~62 tallgrass 1
setblock ~44 ~1 ~60 stained_hardened_clay 10
fill ~45 ~1 ~60 ~51 ~1 ~60 stained_hardened_clay 2
fill ~46 ~1 ~0 ~47 ~1 ~0 tallgrass 1
setblock ~47 ~1 ~1 stained_hardened_clay 6
fill ~47 ~1 ~2 ~50 ~1 ~2 stained_hardened_clay 2
fill ~47 ~1 ~46 ~55 ~1 ~46 stained_hardened_clay 14
fill ~48 ~1 ~14 ~50 ~1 ~14 stained_hardened_clay 14
setblock ~48 ~1 ~59 dirt 0
setblock ~49 ~1 ~0 tallgrass 1
fill ~49 ~1 ~63 ~50 ~1 ~63 tallgrass 1
fill ~50 ~1 ~61 ~51 ~1 ~61 red_flower 7
setblock ~51 ~1 ~0 tallgrass 1
setblock ~51 ~1 ~1 stained_hardened_clay 2
fill ~51 ~1 ~15 ~52 ~1 ~15 stained_hardened_clay 14
setblock ~52 ~1 ~0 leaves 8
fill ~52 ~1 ~61 ~59 ~1 ~61 stained_hardened_clay 2
fill ~52 ~1 ~63 ~55 ~1 ~63 tallgrass 1
fill ~53 ~1 ~0 ~61 ~1 ~0 tallgrass 1
fill ~53 ~1 ~1 ~58 ~1 ~1 stained_hardened_clay 2
fill ~53 ~1 ~16 ~65 ~1 ~16 stained_hardened_clay 14
fill ~53 ~1 ~60 ~60 ~1 ~60 stained_hardened_clay 2
setblock ~53 ~1 ~62 tallgrass 1
setblock ~53 ~1 ~64 tallgrass 1
setblock ~54 ~1 ~62 stained_hardened_clay 2
setblock ~56 ~1 ~46 stained_hardened_clay 10
fill ~57 ~1 ~59 ~66 ~1 ~59 stained_hardened_clay 2
fill ~57 ~1 ~62 ~59 ~1 ~62 tallgrass 1
setblock ~59 ~1 ~1 stained_hardened_clay 6
fill ~59 ~1 ~45 ~72 ~1 ~45 stained_hardened_clay 14
setblock ~60 ~1 ~1 stained_hardened_clay 2
setblock ~60 ~1 ~61 tallgrass 1
setblock ~61 ~1 ~1 tallgrass 1
fill ~61 ~1 ~2 ~63 ~1 ~2 stained_hardened_clay 2
setblock ~61 ~1 ~60 tallgrass 1
setblock ~62 ~1 ~60 stained_hardened_clay 2
setblock ~62 ~1 ~61 tallgrass 1
fill ~64 ~1 ~0 ~64 ~1 ~2 tallgrass 1
fill ~64 ~1 ~3 ~65 ~1 ~3 stained_hardened_clay 2
fill ~65 ~1 ~2 ~67 ~1 ~2 stained_hardened_clay 2
fill ~66 ~1 ~1 ~68 ~1 ~1 tallgrass 1
fill ~66 ~1 ~58 ~69 ~1 ~58 stained_hardened_clay 2
fill ~67 ~1 ~16 ~70 ~1 ~16 stained_hardened_clay 14
setblock ~67 ~1 ~59 tallgrass 1
setblock ~68 ~1 ~2 tallgrass 1
fill ~68 ~1 ~3 ~68 ~2 ~3 stained_hardened_clay 2
fill ~69 ~1 ~2 ~70 ~1 ~2 stained_hardened_clay 2
fill ~70 ~1 ~1 ~71 ~1 ~1 tallgrass 1
fill ~70 ~1 ~3 ~71 ~1 ~3 stained_hardened_clay 2
fill ~70 ~1 ~59 ~71 ~1 ~59 stained_hardened_clay 2
fill ~71 ~1 ~2 ~74 ~1 ~2 tallgrass 1
fill ~71 ~1 ~17 ~71 ~6 ~17 stained_hardened_clay 14
setblock ~71 ~1 ~24 piston_extension 4
fill ~71 ~1 ~25 ~71 ~1 ~28 stained_hardened_clay 14
setblock ~72 ~1 ~3 tallgrass 1
fill ~72 ~1 ~4 ~72 ~3 ~4 stained_hardened_clay 2
setblock ~72 ~1 ~19 stained_hardened_clay 14
fill ~72 ~1 ~21 ~72 ~1 ~22 stained_hardened_clay 14
setblock ~72 ~1 ~27 stained_hardened_clay 14
fill ~72 ~1 ~58 ~76 ~1 ~58 stained_hardened_clay 2
fill ~73 ~1 ~3 ~74 ~1 ~3 stained_hardened_clay 2
setblock ~73 ~1 ~20 stained_hardened_clay 14
fill ~73 ~1 ~30 ~73 ~1 ~31 stained_hardened_clay 14
fill ~73 ~1 ~35 ~74 ~1 ~35 stained_hardened_clay 14
fill ~73 ~1 ~37 ~77 ~1 ~37 stained_hardened_clay 14
fill ~73 ~1 ~38 ~76 ~1 ~38 stained_hardened_clay 14
fill ~73 ~1 ~44 ~73 ~2 ~44 stained_hardened_clay 10
setblock ~74 ~1 ~34 stained_hardened_clay 2
setblock ~74 ~1 ~36 stained_hardened_clay 14
fill ~74 ~1 ~40 ~76 ~1 ~40 stained_hardened_clay 14
fill ~74 ~1 ~41 ~75 ~1 ~41 stained_hardened_clay 14
setblock ~74 ~1 ~59 tallgrass 1
setblock ~75 ~1 ~3 tallgrass 1
fill ~75 ~1 ~4 ~77 ~1 ~4 stained_hardened_clay 2
fill ~75 ~1 ~39 ~76 ~1 ~39 stained_hardened_clay 14
fill ~76 ~1 ~59 ~77 ~1 ~59 tallgrass 1
fill ~77 ~1 ~5 ~78 ~1 ~5 stained_hardened_clay 2
setblock ~77 ~1 ~58 stained_hardened_clay 6
setblock ~78 ~1 ~4 tallgrass 1
fill ~78 ~1 ~6 ~80 ~1 ~6 stained_hardened_clay 2
setblock ~78 ~1 ~57 stained_hardened_clay 2
setblock ~78 ~1 ~58 tallgrass 1
setblock ~79 ~1 ~5 tallgrass 1
fill ~79 ~1 ~55 ~80 ~1 ~55 stained_hardened_clay 2
fill ~79 ~1 ~56 ~79 ~1 ~55 stained_hardened_clay 2
fill ~79 ~1 ~57 ~80 ~1 ~57 tallgrass 1
setblock ~80 ~1 ~4 tallgrass 1
fill ~80 ~1 ~7 ~82 ~1 ~7 stained_hardened_clay 2
fill ~80 ~1 ~54 ~81 ~1 ~54 stained_hardened_clay 2
fill ~80 ~1 ~56 ~81 ~1 ~56 tallgrass 1
setblock ~80 ~1 ~66 leaves 15
setblock ~81 ~1 ~5 tallgrass 1
setblock ~81 ~1 ~53 grass 0
setblock ~81 ~1 ~55 tallgrass 1
fill ~82 ~1 ~8 ~83 ~1 ~8 stained_hardened_clay 2
fill ~82 ~1 ~51 ~82 ~3 ~51 stained_hardened_clay 2
fill ~82 ~1 ~52 ~82 ~1 ~51 stained_hardened_clay 2
fill ~82 ~1 ~54 ~84 ~1 ~54 tallgrass 1
setblock ~82 ~1 ~64 leaves 7
setblock ~83 ~1 ~6 tallgrass 1
fill ~83 ~1 ~9 ~84 ~1 ~9 stained_hardened_clay 2
fill ~83 ~1 ~49 ~83 ~3 ~49 stained_hardened_clay 2
fill ~83 ~1 ~50 ~83 ~2 ~50 stained_hardened_clay 2
fill ~83 ~1 ~51 ~85 ~1 ~51 tallgrass 1
fill ~83 ~1 ~52 ~84 ~1 ~52 tallgrass 1
fill ~83 ~1 ~53 ~83 ~1 ~51 tallgrass 1
setblock ~83 ~1 ~55 tallgrass 1
fill ~84 ~1 ~10 ~84 ~1 ~11 stained_hardened_clay 2
fill ~84 ~1 ~48 ~84 ~2 ~48 stained_hardened_clay 2
fill ~84 ~1 ~49 ~85 ~1 ~49 tallgrass 1
setblock ~85 ~1 ~9 double_plant 2
setblock ~85 ~1 ~10 tallgrass 1
fill ~85 ~1 ~11 ~85 ~1 ~14 stained_hardened_clay 2
fill ~85 ~1 ~46 ~85 ~2 ~46 stained_hardened_clay 2
fill ~85 ~1 ~47 ~85 ~1 ~46 stained_hardened_clay 2
fill ~85 ~1 ~48 ~86 ~1 ~48 tallgrass 1
setblock ~85 ~1 ~50 tallgrass 1
fill ~86 ~1 ~12 ~86 ~1 ~14 tallgrass 1
fill ~86 ~1 ~15 ~86 ~1 ~16 stained_hardened_clay 2
setblock ~86 ~1 ~45 stained_hardened_clay 2
fill ~86 ~1 ~46 ~87 ~1 ~46 tallgrass 1
fill ~86 ~1 ~47 ~87 ~1 ~47 tallgrass 1
fill ~87 ~1 ~8 ~87 ~3 ~8 leaves 15
setblock ~87 ~1 ~13 tallgrass 1
fill ~87 ~1 ~15 ~88 ~1 ~15 tallgrass 1
fill ~87 ~1 ~16 ~88 ~1 ~16 tallgrass 1
fill ~87 ~1 ~17 ~87 ~1 ~18 stained_hardened_clay 2
setblock ~87 ~1 ~33 stained_hardened_clay 6
fill ~87 ~1 ~34 ~87 ~1 ~35 stained_hardened_clay 2
fill ~87 ~1 ~39 ~87 ~3 ~39 stained_hardened_clay 2
fill ~87 ~1 ~40 ~87 ~1 ~44 stained_hardened_clay 2
fill ~87 ~1 ~45 ~88 ~1 ~45 tallgrass 1
setblock ~88 ~1 ~18 tallgrass 1
fill ~88 ~1 ~19 ~88 ~1 ~20 stained_hardened_clay 2
fill ~88 ~1 ~31 ~88 ~2 ~31 stained_hardened_clay 2
fill ~88 ~1 ~32 ~88 ~1 ~31 stained_hardened_clay 2
fill ~88 ~1 ~33 ~89 ~1 ~33 tallgrass 1
fill ~88 ~1 ~36 ~88 ~1 ~38 stained_hardened_clay 2
fill ~88 ~1 ~39 ~89 ~1 ~39 tallgrass 1
fill ~88 ~1 ~40 ~89 ~1 ~40 tallgrass 1
fill ~88 ~1 ~41 ~89 ~1 ~41 tallgrass 1
fill ~88 ~1 ~43 ~88 ~1 ~45 tallgrass 1
setblock ~89 ~1 ~6 leaves 12
setblock ~89 ~1 ~17 tallgrass 1
fill ~89 ~1 ~19 ~90 ~1 ~19 tallgrass 1
fill ~89 ~1 ~20 ~90 ~1 ~20 tallgrass 1
fill ~89 ~1 ~21 ~89 ~1 ~22 stained_hardened_clay 2
fill ~89 ~1 ~28 ~89 ~2 ~28 stained_hardened_clay 2
fill ~89 ~1 ~29 ~89 ~1 ~30 stained_hardened_clay 2
fill ~89 ~1 ~35 ~90 ~1 ~35 tallgrass 1
fill ~89 ~1 ~36 ~91 ~1 ~36 tallgrass 1
fill ~89 ~1 ~37 ~89 ~1 ~35 tallgrass 1
fill ~89 ~1 ~59 ~89 ~4 ~59 leaves 7
fill ~90 ~1 ~23 ~90 ~1 ~27 stained_hardened_clay 2
fill ~90 ~1 ~28 ~90 ~1 ~29 tallgrass 1
fill ~90 ~1 ~30 ~90 ~1 ~31 stained_hardened_clay 2
fill ~90 ~1 ~34 ~91 ~1 ~34 tallgrass 1
fill ~90 ~1 ~37 ~90 ~3 ~37 log 0
fill ~91 ~1 ~8 ~91 ~3 ~8 leaves 15
fill ~91 ~1 ~22 ~91 ~1 ~23 tallgrass 1
fill ~91 ~1 ~25 ~91 ~1 ~27 tallgrass 1
fill ~91 ~1 ~29 ~91 ~1 ~31 tallgrass 1
setblock ~91 ~1 ~37 tallgrass 1
setblock ~93 ~1 ~21 leaves 15
fill ~95 ~1 ~19 ~95 ~2 ~19 leaves 7
fill ~96 ~1 ~46 ~96 ~2 ~46 log 0
fill ~97 ~1 ~26 ~97 ~2 ~26 log 0
fill ~97 ~1 ~28 ~97 ~2 ~28 leaves 15
fill ~97 ~1 ~40 ~97 ~2 ~40 leaves 15
setblock ~5 ~2 ~33 leaves 7
fill ~5 ~2 ~37 ~5 ~4 ~37 leaves 15
fill ~7 ~2 ~35 ~7 ~3 ~35 leaves 7
fill ~12 ~2 ~48 ~12 ~3 ~48 leaves 15
setblock ~13 ~2 ~40 leaves 7
fill ~17 ~2 ~48 ~17 ~3 ~48 log 0
setblock ~17 ~2 ~62 leaves 15
setblock ~17 ~2 ~66 leaves 15
fill ~19 ~2 ~5 ~19 ~3 ~5 leaves 15
fill ~19 ~2 ~48 ~19 ~3 ~48 leaves 15
setblock ~19 ~2 ~64 leaves 15
setblock ~23 ~2 ~15 leaves 7
fill ~28 ~2 ~42 ~28 ~2 ~45 stained_hardened_clay 2
fill ~29 ~2 ~16 ~29 ~2 ~19 stained_hardened_clay 2
setblock ~29 ~2 ~41 stained_hardened_clay 2
fill ~29 ~2 ~46 ~29 ~3 ~46 stained_hardened_clay 2
fill ~29 ~2 ~68 ~29 ~3 ~68 log 0
fill ~30 ~2 ~11 ~31 ~2 ~11 stained_hardened_clay 2
fill ~30 ~2 ~12 ~30 ~2 ~15 stained_hardened_clay 2
fill ~30 ~2 ~20 ~30 ~2 ~21 stained_hardened_clay 2
setblock ~30 ~2 ~40 stained_hardened_clay 2
fill ~30 ~2 ~47 ~30 ~2 ~48 stained_hardened_clay 2
setblock ~30 ~2 ~62 leaves 15
setblock ~31 ~2 ~7 leaves 12
setblock ~31 ~2 ~8 leaves 3
fill ~31 ~2 ~10 ~32 ~2 ~10 stained_hardened_clay 2
fill ~31 ~2 ~21 ~31 ~2 ~22 stained_hardened_clay 2
fill ~31 ~2 ~39 ~31 ~3 ~39 stained_hardened_clay 2
fill ~31 ~2 ~49 ~31 ~3 ~49 stained_hardened_clay 2
fill ~31 ~2 ~50 ~31 ~2 ~49 stained_hardened_clay 2
fill ~31 ~2 ~68 ~31 ~3 ~68 leaves 15
fill ~32 ~2 ~22 ~33 ~2 ~22 stained_hardened_clay 2
fill ~32 ~2 ~38 ~32 ~3 ~38 stained_hardened_clay 2
setblock ~32 ~2 ~51 stained_hardened_clay 2
fill ~32 ~2 ~60 ~32 ~3 ~60 leaves 7
setblock ~33 ~2 ~6 leaves 12
fill ~33 ~2 ~9 ~34 ~2 ~9 stained_hardened_clay 2
fill ~33 ~2 ~37 ~34 ~2 ~37 stained_hardened_clay 2
fill ~33 ~2 ~52 ~33 ~2 ~53 stained_hardened_clay 2
fill ~34 ~2 ~23 ~35 ~2 ~23 stained_hardened_clay 2
setblock ~34 ~2 ~53 stained_hardened_clay 2
setblock ~35 ~2 ~8 stained_hardened_clay 2
fill ~35 ~2 ~38 ~35 ~4 ~38 stained_hardened_clay 14
fill ~35 ~2 ~54 ~36 ~2 ~54 stained_hardened_clay 2
fill ~36 ~2 ~6 ~36 ~2 ~7 stained_hardened_clay 2
fill ~36 ~2 ~23 ~37 ~2 ~23 stained_hardened_clay 14
fill ~36 ~2 ~39 ~37 ~2 ~39 stained_hardened_clay 14
setblock ~36 ~2 ~55 stained_hardened_clay 2
setblock ~37 ~2 ~5 stained_hardened_clay 2
fill ~37 ~2 ~22 ~37 ~6 ~22 stained_hardened_clay 14
fill ~37 ~2 ~40 ~37 ~5 ~40 stained_hardened_clay 14
fill ~37 ~2 ~41 ~37 ~5 ~41 stained_hardened_clay 14
fill ~37 ~2 ~42 ~37 ~4 ~42 stained_hardened_clay 14
fill ~37 ~2 ~43 ~37 ~3 ~43 stained_hardened_clay 14
setblock ~37 ~2 ~56 stained_hardened_clay 2
fill ~38 ~2 ~4 ~39 ~2 ~4 stained_hardened_clay 2
fill ~38 ~2 ~20 ~38 ~7 ~20 stained_hardened_clay 14
fill ~38 ~2 ~21 ~38 ~2 ~20 stained_hardened_clay 14
fill ~38 ~2 ~44 ~38 ~5 ~44 stained_hardened_clay 14
setblock ~38 ~2 ~57 stained_hardened_clay 2
fill ~39 ~2 ~45 ~39 ~5 ~45 stained_hardened_clay 14
fill ~39 ~2 ~58 ~42 ~2 ~58 stained_hardened_clay 2
fill ~40 ~2 ~3 ~41 ~2 ~3 stained_hardened_clay 2
fill ~41 ~2 ~15 ~47 ~2 ~15 stained_hardened_clay 14
fill ~41 ~2 ~47 ~45 ~2 ~47 stained_hardened_clay 14
setblock ~42 ~2 ~3 stained_hardened_clay 6
fill ~43 ~2 ~2 ~46 ~2 ~2 stained_hardened_clay 2
fill ~43 ~2 ~59 ~47 ~2 ~59 stained_hardened_clay 2
fill ~45 ~2 ~60 ~45 ~1 ~60 stained_hardened_clay 2
setblock ~46 ~2 ~46 stained_hardened_clay 10
fill ~47 ~2 ~3 ~51 ~2 ~3 stained_hardened_clay 2
fill ~47 ~2 ~46 ~57 ~2 ~46 stained_hardened_clay 14
fill ~48 ~2 ~14 ~50 ~2 ~14 stained_hardened_clay 14
setblock ~48 ~2 ~58 stained_hardened_clay 6
fill ~48 ~2 ~67 ~48 ~5 ~67 leaves 7
setblock ~49 ~2 ~59 stained_hardened_clay 6
setblock ~49 ~2 ~60 stained_hardened_clay 2
fill ~50 ~2 ~59 ~51 ~2 ~59 stained_hardened_clay 2
fill ~51 ~2 ~15 ~52 ~2 ~15 stained_hardened_clay 14
setblock ~52 ~2 ~1 leaves 8
fill ~52 ~2 ~2 ~57 ~2 ~2 stained_hardened_clay 2
setblock ~52 ~2 ~60 stained_hardened_clay 2
fill ~53 ~2 ~16 ~64 ~2 ~16 stained_hardened_clay 14
fill ~53 ~2 ~59 ~56 ~2 ~59 stained_hardened_clay 2
fill ~55 ~2 ~58 ~65 ~2 ~58 stained_hardened_clay 2
fill ~58 ~2 ~1 ~59 ~2 ~1 stained_hardened_clay 2
fill ~59 ~2 ~45 ~71 ~2 ~45 stained_hardened_clay 14
fill ~60 ~2 ~2 ~62 ~2 ~2 stained_hardened_clay 2
fill ~63 ~2 ~3 ~64 ~2 ~3 stained_hardened_clay 2
fill ~65 ~2 ~4 ~65 ~4 ~4 stained_hardened_clay 2
fill ~65 ~2 ~15 ~65 ~5 ~15 stained_hardened_clay 14
fill ~66 ~2 ~3 ~69 ~2 ~3 stained_hardened_clay 2
fill ~66 ~2 ~57 ~69 ~2 ~57 stained_hardened_clay 2
fill ~67 ~2 ~16 ~70 ~2 ~16 stained_hardened_clay 14
setblock ~67 ~2 ~56 stained_hardened_clay 2
fill ~70 ~2 ~4 ~75 ~2 ~4 stained_hardened_clay 2
fill ~70 ~2 ~58 ~71 ~2 ~58 stained_hardened_clay 2
fill ~72 ~2 ~18 ~72 ~6 ~18 stained_hardened_clay 14
fill ~72 ~2 ~22 ~73 ~2 ~22 stained_hardened_clay 14
setblock ~72 ~2 ~23 piston_extension 4
fill ~72 ~2 ~24 ~72 ~2 ~26 stained_hardened_clay 14
setblock ~72 ~2 ~28 stained_hardened_clay 14
fill ~72 ~2 ~44 ~72 ~5 ~44 stained_hardened_clay 14
fill ~72 ~2 ~57 ~77 ~2 ~57 stained_hardened_clay 2
fill ~73 ~2 ~19 ~73 ~6 ~19 stained_hardened_clay 14
setblock ~73 ~2 ~21 stained_hardened_clay 14
setblock ~73 ~2 ~23 stained_hardened_clay 14
setblock ~73 ~2 ~27 stained_hardened_clay 14
setblock ~73 ~2 ~29 stained_hardened_clay 14
fill ~74 ~2 ~20 ~74 ~6 ~20 stained_hardened_clay 14
fill ~74 ~2 ~30 ~74 ~4 ~30 stained_hardened_clay 14
fill ~74 ~2 ~31 ~74 ~2 ~33 stained_hardened_clay 2
setblock ~75 ~2 ~34 stained_hardened_clay 2
fill ~75 ~2 ~35 ~75 ~7 ~35 stained_hardened_clay 14
fill ~75 ~2 ~36 ~76 ~2 ~36 stained_hardened_clay 14
setblock ~75 ~2 ~42 stained_hardened_clay 14
setblock ~76 ~2 ~5 stained_hardened_clay 2
setblock ~76 ~2 ~41 stained_hardened_clay 14
setblock ~76 ~2 ~56 stained_hardened_clay 2
setblock ~77 ~2 ~6 stained_hardened_clay 2
setblock ~77 ~2 ~36 glowstone 0
fill ~77 ~2 ~38 ~77 ~4 ~38 stained_hardened_clay 14
fill ~77 ~2 ~39 ~77 ~2 ~40 stained_hardened_clay 14
setblock ~77 ~2 ~56 stained_hardened_clay 6
fill ~78 ~2 ~7 ~79 ~2 ~7 stained_hardened_clay 2
setblock ~78 ~2 ~37 stained_hardened_clay 2
fill ~78 ~2 ~55 ~78 ~2 ~56 stained_hardened_clay 2
setblock ~78 ~2 ~64 leaves 4
setblock ~79 ~2 ~54 stained_hardened_clay 2
fill ~80 ~2 ~8 ~81 ~2 ~8 stained_hardened_clay 2
setblock ~80 ~2 ~53 stained_hardened_clay 2
fill ~80 ~2 ~64 ~80 ~3 ~64 log 0
setblock ~80 ~2 ~66 leaves 7
fill ~81 ~2 ~52 ~81 ~3 ~52 stained_hardened_clay 2
fill ~82 ~2 ~9 ~82 ~2 ~10 stained_hardened_clay 2
setblock ~82 ~2 ~64 leaves 15
fill ~83 ~2 ~10 ~83 ~2 ~13 stained_hardened_clay 2
fill ~84 ~2 ~12 ~84 ~2 ~14 stained_hardened_clay 2
fill ~84 ~2 ~47 ~84 ~3 ~47 stained_hardened_clay 2
fill ~85 ~2 ~15 ~85 ~2 ~16 stained_hardened_clay 2
fill ~85 ~2 ~43 ~86 ~2 ~43 stained_hardened_clay 2
fill ~85 ~2 ~45 ~85 ~3 ~45 stained_hardened_clay 2
fill ~86 ~2 ~17 ~86 ~2 ~19 stained_hardened_clay 2
fill ~86 ~2 ~33 ~86 ~4 ~33 stained_hardened_clay 2
fill ~86 ~2 ~34 ~86 ~5 ~34 stained_hardened_clay 2
fill ~86 ~2 ~35 ~86 ~5 ~35 stained_hardened_clay 2
fill ~86 ~2 ~40 ~86 ~3 ~40 stained_hardened_clay 2
fill ~86 ~2 ~41 ~86 ~3 ~41 stained_hardened_clay 2
fill ~86 ~2 ~42 ~86 ~2 ~40 stained_hardened_clay 2
setblock ~86 ~2 ~44 stained_hardened_clay 2
fill ~87 ~2 ~19 ~87 ~2 ~21 stained_hardened_clay 2
setblock ~87 ~2 ~32 stained_hardened_clay 2
fill ~87 ~2 ~36 ~87 ~2 ~39 stained_hardened_clay 2
fill ~88 ~2 ~21 ~88 ~2 ~22 stained_hardened_clay 2
fill ~88 ~2 ~24 ~89 ~2 ~24 stained_hardened_clay 2
fill ~88 ~2 ~25 ~89 ~2 ~25 stained_hardened_clay 2
fill ~88 ~2 ~29 ~88 ~2 ~31 stained_hardened_clay 2
fill ~89 ~2 ~6 ~89 ~3 ~6 leaves 15
fill ~89 ~2 ~8 ~89 ~3 ~8 log 0
fill ~89 ~2 ~10 ~89 ~3 ~10 leaves 15
setblock ~89 ~2 ~23 stained_hardened_clay 2
fill ~89 ~2 ~26 ~89 ~2 ~28 stained_hardened_clay 2
fill ~89 ~2 ~36 ~89 ~4 ~36 leaves 7
fill ~90 ~2 ~3 ~90 ~5 ~3 leaves 7
fill ~91 ~2 ~19 ~91 ~3 ~19 leaves 15
setblock ~91 ~2 ~61 leaves 7
fill ~93 ~2 ~19 ~93 ~3 ~19 log 0
setblock ~93 ~2 ~21 leaves 7
fill ~94 ~2 ~48 ~94 ~3 ~48 leaves 15
fill ~95 ~2 ~24 ~95 ~3 ~24 leaves 15
setblock ~96 ~2 ~44 leaves 12
fill ~5 ~3 ~33 ~5 ~4 ~33 leaves 15
setblock ~10 ~3 ~50 leaves 15
setblock ~12 ~3 ~52 leaves 15
setblock ~13 ~3 ~36 leaves 7
fill ~13 ~3 ~40 ~13 ~5 ~40 leaves 15
setblock ~13 ~3 ~50 leaves 15
setblock ~14 ~3 ~49 leaves 12
setblock ~14 ~3 ~51 leaves 15
fill ~15 ~3 ~38 ~15 ~4 ~38 leaves 7
setblock ~15 ~3 ~50 leaves 15
fill ~16 ~3 ~64 ~18 ~3 ~64 leaves 15
setblock ~17 ~3 ~63 leaves 15
setblock ~17 ~3 ~65 leaves 15
setblock ~20 ~3 ~3 leaves 12
setblock ~21 ~3 ~0 leaves 15
setblock ~21 ~3 ~2 leaves 15
setblock ~21 ~3 ~4 leaves 15
setblock ~21 ~3 ~7 leaves 12
setblock ~22 ~3 ~3 leaves 15
setblock ~23 ~3 ~5 leaves 15
fill ~23 ~3 ~11 ~23 ~5 ~11 leaves 15
fill ~23 ~3 ~15 ~23 ~5 ~15 leaves 15
fill ~25 ~3 ~13 ~25 ~4 ~13 leaves 7
fill ~27 ~3 ~70 ~27 ~4 ~70 leaves 15
fill ~28 ~3 ~43 ~28 ~3 ~44 stained_hardened_clay 2
fill ~28 ~3 ~60 ~28 ~4 ~60 leaves 15
setblock ~29 ~3 ~42 stained_hardened_clay 2
setblock ~29 ~3 ~45 stained_hardened_clay 2
setblock ~29 ~3 ~70 leaves 12
fill ~30 ~3 ~15 ~30 ~3 ~19 stained_hardened_clay 2
setblock ~30 ~3 ~41 stained_hardened_clay 2
setblock ~30 ~3 ~46 stained_hardened_clay 2
fill ~30 ~3 ~60 ~30 ~4 ~60 log 0
setblock ~30 ~3 ~62 leaves 7
setblock ~31 ~3 ~7 leaves 0
fill ~31 ~3 ~12 ~31 ~3 ~14 stained_hardened_clay 2
setblock ~31 ~3 ~20 stained_hardened_clay 2
fill ~31 ~3 ~40 ~31 ~4 ~40 stained_hardened_clay 2
fill ~31 ~3 ~47 ~31 ~4 ~47 stained_hardened_clay 2
fill ~31 ~3 ~48 ~31 ~4 ~48 stained_hardened_clay 2
setblock ~32 ~3 ~10 leaves 0
setblock ~32 ~3 ~11 stained_hardened_clay 2
setblock ~32 ~3 ~21 stained_hardened_clay 2
setblock ~32 ~3 ~50 stained_hardened_clay 2
fill ~33 ~3 ~10 ~34 ~3 ~10 stained_hardened_clay 2
fill ~33 ~3 ~22 ~34 ~3 ~22 stained_hardened_clay 2
fill ~33 ~3 ~38 ~33 ~4 ~38 stained_hardened_clay 2
setblock ~33 ~3 ~51 stained_hardened_clay 2
setblock ~34 ~3 ~37 stained_hardened_clay 2
setblock ~34 ~3 ~52 stained_hardened_clay 6
setblock ~35 ~3 ~9 stained_hardened_clay 2
fill ~35 ~3 ~23 ~36 ~3 ~23 stained_hardened_clay 14
fill ~35 ~3 ~53 ~36 ~3 ~53 stained_hardened_clay 2
setblock ~36 ~3 ~8 stained_hardened_clay 2
fill ~36 ~3 ~39 ~36 ~4 ~39 stained_hardened_clay 14
fill ~37 ~3 ~6 ~37 ~3 ~7 stained_hardened_clay 2
fill ~37 ~3 ~21 ~37 ~5 ~21 stained_hardened_clay 14
fill ~37 ~3 ~54 ~37 ~4 ~54 stained_hardened_clay 2
setblock ~37 ~3 ~55 stained_hardened_clay 10
setblock ~38 ~3 ~5 stained_hardened_clay 2
fill ~38 ~3 ~19 ~38 ~7 ~19 stained_hardened_clay 14
setblock ~38 ~3 ~56 stained_hardened_clay 10
fill ~39 ~3 ~4 ~42 ~3 ~4 stained_hardened_clay 2
fill ~39 ~3 ~57 ~40 ~3 ~57 stained_hardened_clay 2
fill ~41 ~3 ~15 ~47 ~3 ~15 stained_hardened_clay 14
fill ~41 ~3 ~47 ~45 ~3 ~47 stained_hardened_clay 14
fill ~41 ~3 ~58 ~48 ~3 ~58 stained_hardened_clay 2
fill ~43 ~3 ~3 ~46 ~3 ~3 stained_hardened_clay 2
fill ~46 ~3 ~46 ~58 ~3 ~46 stained_hardened_clay 14
setblock ~47 ~3 ~4 stained_hardened_clay 2
setblock ~48 ~3 ~3 leaves 0
fill ~48 ~3 ~14 ~50 ~3 ~14 stained_hardened_clay 14
fill ~49 ~3 ~2 ~50 ~3 ~2 leaves 8
fill ~49 ~3 ~4 ~51 ~3 ~4 stained_hardened_clay 2
fill ~49 ~3 ~59 ~52 ~3 ~59 stained_hardened_clay 2
setblock ~50 ~3 ~69 leaves 7
fill ~51 ~3 ~15 ~52 ~3 ~15 stained_hardened_clay 14
setblock ~52 ~3 ~3 stained_hardened_clay 2
setblock ~53 ~3 ~3 stained_hardened_clay 6
fill ~53 ~3 ~16 ~63 ~3 ~16 stained_hardened_clay 14
fill ~53 ~3 ~58 ~54 ~3 ~58 stained_hardened_clay 2
fill ~54 ~3 ~3 ~56 ~3 ~3 stained_hardened_clay 2
fill ~55 ~3 ~57 ~55 ~8 ~57 stained_hardened_clay 2
fill ~56 ~3 ~31 ~56 ~5 ~31 stained_hardened_clay 14
setblock ~56 ~3 ~57 stained_hardened_clay 10
fill ~57 ~3 ~2 ~60 ~3 ~2 stained_hardened_clay 2
fill ~57 ~3 ~57 ~61 ~3 ~57 stained_hardened_clay 2
fill ~59 ~3 ~45 ~59 ~6 ~45 stained_hardened_clay 14
setblock ~60 ~3 ~45 stained_hardened_clay 10
fill ~61 ~3 ~3 ~61 ~4 ~3 stained_hardened_clay 2
fill ~61 ~3 ~45 ~71 ~3 ~45 stained_hardened_clay 14
setblock ~62 ~3 ~3 stained_hardened_clay 6
setblock ~62 ~3 ~58 stained_hardened_clay 2
fill ~63 ~3 ~3 ~64 ~3 ~3 stained_hardened_clay 2
fill ~63 ~3 ~57 ~65 ~3 ~57 stained_hardened_clay 2
fill ~64 ~3 ~15 ~64 ~4 ~15 stained_hardened_clay 14
fill ~66 ~3 ~4 ~68 ~3 ~4 stained_hardened_clay 2
setblock ~66 ~3 ~56 stained_hardened_clay 10
fill ~67 ~3 ~15 ~67 ~6 ~15 stained_hardened_clay 14
setblock ~67 ~3 ~55 stained_hardened_clay 2
setblock ~67 ~3 ~69 leaves 7
fill ~68 ~3 ~16 ~70 ~3 ~16 stained_hardened_clay 14
setblock ~68 ~3 ~56 stained_hardened_clay 2
setblock ~69 ~3 ~4 stained_hardened_clay 6
setblock ~69 ~3 ~56 stained_hardened_clay 6
fill ~70 ~3 ~4 ~73 ~3 ~4 stained_hardened_clay 2
setblock ~70 ~3 ~57 stained_hardened_clay 2
setblock ~71 ~3 ~57 stained_hardened_clay 6
setblock ~72 ~3 ~56 stained_hardened_clay 6
fill ~73 ~3 ~24 ~73 ~3 ~26 stained_hardened_clay 14
setblock ~73 ~3 ~28 stained_hardened_clay 14
setblock ~73 ~3 ~44 stained_hardened_clay 14
setblock ~73 ~3 ~56 stained_hardened_clay 2
setblock ~74 ~3 ~4 stained_hardened_clay 6
fill ~74 ~3 ~21 ~74 ~7 ~21 stained_hardened_clay 14
fill ~74 ~3 ~22 ~74 ~8 ~22 stained_hardened_clay 14
fill ~74 ~3 ~23 ~74 ~8 ~23 stained_hardened_clay 14
fill ~74 ~3 ~27 ~74 ~8 ~27 stained_hardened_clay 14
fill ~74 ~3 ~29 ~74 ~9 ~29 stained_hardened_clay 14
setblock ~74 ~3 ~31 stained_hardened_clay 6
fill ~74 ~3 ~32 ~74 ~3 ~33 stained_hardened_clay 2
setblock ~74 ~3 ~55 stained_hardened_clay 2
setblock ~74 ~3 ~56 stained_hardened_clay 10
setblock ~75 ~3 ~5 stained_hardened_clay 6
fill ~75 ~3 ~34 ~75 ~6 ~34 stained_hardened_clay 14
fill ~75 ~3 ~41 ~75 ~5 ~41 stained_hardened_clay 14
setblock ~75 ~3 ~55 stained_hardened_clay 6
setblock ~75 ~3 ~56 stained_hardened_clay 2
setblock ~76 ~3 ~6 stained_hardened_clay 2
fill ~76 ~3 ~36 ~76 ~4 ~36 stained_hardened_clay 14
fill ~76 ~3 ~39 ~76 ~5 ~39 stained_hardened_clay 14
fill ~76 ~3 ~40 ~76 ~3 ~39 stained_hardened_clay 14
fill ~76 ~3 ~54 ~76 ~3 ~55 stained_hardened_clay 2
fill ~77 ~3 ~7 ~77 ~4 ~7 stained_hardened_clay 2
setblock ~77 ~3 ~37 stained_hardened_clay 14
setblock ~77 ~3 ~55 stained_hardened_clay 2
fill ~78 ~3 ~8 ~79 ~3 ~8 stained_hardened_clay 2
setblock ~78 ~3 ~54 stained_hardened_clay 2
setblock ~78 ~3 ~64 leaves 15
setblock ~79 ~3 ~53 stained_hardened_clay 6
fill ~80 ~3 ~9 ~81 ~3 ~9 stained_hardened_clay 2
setblock ~80 ~3 ~52 stained_hardened_clay 2
setblock ~80 ~3 ~62 leaves 15
setblock ~80 ~3 ~66 leaves 15
fill ~81 ~3 ~10 ~81 ~4 ~10 stained_hardened_clay 2
fill ~82 ~3 ~3 ~82 ~6 ~3 leaves 7
fill ~82 ~3 ~11 ~82 ~4 ~11 stained_hardened_clay 2
fill ~82 ~3 ~12 ~82 ~5 ~12 stained_hardened_clay 2
fill ~82 ~3 ~13 ~82 ~5 ~13 stained_hardened_clay 2
setblock ~82 ~3 ~64 leaves 4
fill ~83 ~3 ~14 ~83 ~4 ~14 stained_hardened_clay 2
fill ~83 ~3 ~15 ~84 ~3 ~15 stained_hardened_clay 2
setblock ~83 ~3 ~48 stained_hardened_clay 6
fill ~83 ~3 ~50 ~83 ~4 ~50 leaves 12
fill ~84 ~3 ~16 ~84 ~4 ~16 stained_hardened_clay 2
setblock ~84 ~3 ~43 stained_hardened_clay 2
setblock ~84 ~3 ~46 stained_hardened_clay 2
fill ~85 ~3 ~17 ~85 ~3 ~19 stained_hardened_clay 2
fill ~85 ~3 ~22 ~86 ~3 ~22 stained_hardened_clay 2
setblock ~85 ~3 ~42 stained_hardened_clay 2
setblock ~85 ~3 ~44 stained_hardened_clay 2
fill ~86 ~3 ~20 ~86 ~3 ~23 stained_hardened_clay 2
setblock ~86 ~3 ~32 stained_hardened_clay 2
fill ~86 ~3 ~36 ~86 ~5 ~36 stained_hardened_clay 2
fill ~86 ~3 ~37 ~86 ~6 ~37 stained_hardened_clay 2
fill ~87 ~3 ~6 ~87 ~4 ~6 leaves 15
fill ~87 ~3 ~22 ~87 ~4 ~22 leaves 12
fill ~87 ~3 ~24 ~87 ~3 ~26 stained_hardened_clay 2
setblock ~87 ~3 ~31 stained_hardened_clay 2
setblock ~87 ~3 ~38 stained_hardened_clay 2
setblock ~88 ~3 ~23 leaves 12
fill ~88 ~3 ~26 ~88 ~3 ~28 stained_hardened_clay 2
fill ~88 ~3 ~29 ~88 ~5 ~29 leaves 12
setblock ~88 ~3 ~30 stained_hardened_clay 2
setblock ~89 ~3 ~26 leaves 12
setblock ~89 ~3 ~40 leaves 15
fill ~91 ~3 ~38 ~91 ~4 ~38 leaves 7
setblock ~91 ~3 ~57 leaves 7
fill ~91 ~3 ~61 ~91 ~5 ~61 leaves 15
fill ~92 ~3 ~5 ~92 ~4 ~5 leaves 15
setblock ~93 ~3 ~17 leaves 15
setblock ~93 ~3 ~21 leaves 15
setblock ~93 ~3 ~26 leaves 15
fill ~93 ~3 ~59 ~93 ~4 ~59 leaves 7
setblock ~95 ~3 ~19 leaves 15
setblock ~95 ~3 ~28 leaves 15
setblock ~95 ~3 ~46 leaves 15
setblock ~96 ~3 ~26 leaves 15
setblock ~96 ~3 ~43 leaves 15
setblock ~96 ~3 ~45 leaves 15
setblock ~96 ~3 ~47 leaves 15
setblock ~96 ~3 ~50 leaves 15
setblock ~97 ~3 ~25 leaves 15
setblock ~97 ~3 ~27 leaves 15
setblock ~97 ~3 ~46 leaves 15
setblock ~3 ~4 ~35 leaves 15
setblock ~5 ~4 ~34 cocoa 8
setblock ~5 ~4 ~35 log 3
setblock ~5 ~4 ~36 cocoa 10
setblock ~6 ~4 ~35 cocoa 9
setblock ~7 ~4 ~35 leaves 15
fill ~11 ~4 ~50 ~12 ~4 ~50 leaves 15
fill ~13 ~4 ~36 ~13 ~5 ~36 leaves 15
setblock ~13 ~4 ~49 leaves 15
setblock ~13 ~4 ~51 leaves 15
setblock ~14 ~4 ~48 leaves 15
fill ~14 ~4 ~52 ~14 ~4 ~53 leaves 15
setblock ~15 ~4 ~47 leaves 15
setblock ~15 ~4 ~49 leaves 15
setblock ~15 ~4 ~51 leaves 15
setblock ~16 ~4 ~48 leaves 15
setblock ~16 ~4 ~50 leaves 15
setblock ~17 ~4 ~45 leaves 15
setblock ~17 ~4 ~47 leaves 15
setblock ~17 ~4 ~49 leaves 15
setblock ~17 ~4 ~52 leaves 15
setblock ~18 ~4 ~48 leaves 15
setblock ~19 ~4 ~3 leaves 12
setblock ~19 ~4 ~50 leaves 15
setblock ~20 ~4 ~2 leaves 15
setblock ~20 ~4 ~4 leaves 15
setblock ~21 ~4 ~1 leaves 15
fill ~21 ~4 ~5 ~21 ~4 ~6 leaves 15
setblock ~21 ~4 ~13 leaves 15
setblock ~22 ~4 ~2 leaves 15
setblock ~22 ~4 ~4 leaves 15
fill ~23 ~4 ~3 ~24 ~4 ~3 leaves 15
setblock ~28 ~4 ~68 leaves 15
fill ~29 ~4 ~43 ~29 ~4 ~44 stained_hardened_clay 2
setblock ~29 ~4 ~65 leaves 12
setblock ~29 ~4 ~67 leaves 15
setblock ~29 ~4 ~69 leaves 15
fill ~30 ~4 ~17 ~30 ~4 ~18 stained_hardened_clay 2
setblock ~30 ~4 ~42 stained_hardened_clay 2
setblock ~30 ~4 ~45 stained_hardened_clay 2
setblock ~30 ~4 ~58 leaves 15
setblock ~30 ~4 ~62 leaves 15
setblock ~30 ~4 ~68 leaves 15
fill ~31 ~4 ~15 ~31 ~4 ~16 stained_hardened_clay 2
fill ~31 ~4 ~19 ~31 ~8 ~19 stained_hardened_clay 2
fill ~31 ~4 ~41 ~31 ~6 ~41 stained_hardened_clay 2
fill ~31 ~4 ~46 ~31 ~5 ~46 stained_hardened_clay 2
setblock ~31 ~4 ~70 leaves 15
fill ~32 ~4 ~12 ~33 ~4 ~12 stained_hardened_clay 2
fill ~32 ~4 ~13 ~32 ~4 ~14 stained_hardened_clay 2
fill ~32 ~4 ~20 ~32 ~5 ~20 stained_hardened_clay 2
setblock ~32 ~4 ~39 stained_hardened_clay 2
setblock ~32 ~4 ~49 stained_hardened_clay 2
setblock ~32 ~4 ~60 leaves 15
setblock ~33 ~4 ~11 stained_hardened_clay 2
fill ~33 ~4 ~21 ~33 ~6 ~21 stained_hardened_clay 2
setblock ~33 ~4 ~50 stained_hardened_clay 2
fill ~34 ~4 ~10 ~35 ~4 ~10 stained_hardened_clay 2
setblock ~34 ~4 ~11 stained_hardened_clay 6
fill ~34 ~4 ~22 ~34 ~6 ~22 stained_hardened_clay 2
fill ~34 ~4 ~38 ~34 ~6 ~38 stained_hardened_clay 2
setblock ~34 ~4 ~51 stained_hardened_clay 2
fill ~35 ~4 ~22 ~35 ~5 ~22 stained_hardened_clay 14
setblock ~35 ~4 ~52 stained_hardened_clay 2
fill ~36 ~4 ~9 ~36 ~5 ~9 stained_hardened_clay 2
fill ~36 ~4 ~23 ~36 ~7 ~23 stained_hardened_clay 14
setblock ~36 ~4 ~52 stained_hardened_clay 10
setblock ~37 ~4 ~8 stained_hardened_clay 2
setblock ~37 ~4 ~53 stained_hardened_clay 2
fill ~38 ~4 ~6 ~38 ~4 ~7 stained_hardened_clay 2
fill ~38 ~4 ~43 ~38 ~6 ~43 stained_hardened_clay 14
setblock ~38 ~4 ~55 stained_hardened_clay 2
fill ~39 ~4 ~5 ~41 ~4 ~5 stained_hardened_clay 2
fill ~39 ~4 ~56 ~40 ~4 ~56 stained_hardened_clay 2
fill ~41 ~4 ~15 ~48 ~4 ~15 stained_hardened_clay 14
fill ~41 ~4 ~46 ~41 ~5 ~46 stained_hardened_clay 14
fill ~41 ~4 ~57 ~44 ~4 ~57 stained_hardened_clay 2
fill ~42 ~4 ~4 ~46 ~4 ~4 stained_hardened_clay 2
fill ~42 ~4 ~47 ~44 ~4 ~47 stained_hardened_clay 14
fill ~45 ~4 ~46 ~58 ~4 ~46 stained_hardened_clay 14
setblock ~45 ~4 ~57 stained_hardened_clay 10
fill ~46 ~4 ~57 ~47 ~4 ~57 stained_hardened_clay 2
setblock ~47 ~4 ~3 leaves 0
fill ~48 ~4 ~4 ~54 ~4 ~4 stained_hardened_clay 2
fill ~48 ~4 ~58 ~53 ~4 ~58 stained_hardened_clay 2
setblock ~49 ~4 ~14 stained_hardened_clay 14
fill ~50 ~4 ~15 ~52 ~4 ~15 stained_hardened_clay 14
setblock ~50 ~4 ~65 leaves 7
fill ~50 ~4 ~69 ~50 ~6 ~69 leaves 15
fill ~52 ~4 ~67 ~52 ~5 ~67 leaves 7
fill ~53 ~4 ~16 ~63 ~4 ~16 stained_hardened_clay 14
fill ~54 ~4 ~57 ~54 ~7 ~57 stained_hardened_clay 2
fill ~55 ~4 ~3 ~62 ~4 ~3 stained_hardened_clay 2
fill ~56 ~4 ~57 ~64 ~4 ~57 stained_hardened_clay 2
fill ~60 ~4 ~45 ~71 ~4 ~45 stained_hardened_clay 14
fill ~63 ~4 ~4 ~69 ~4 ~4 stained_hardened_clay 2
fill ~64 ~4 ~56 ~65 ~4 ~56 stained_hardened_clay 2
setblock ~66 ~4 ~55 stained_hardened_clay 2
fill ~67 ~4 ~54 ~67 ~11 ~54 stained_hardened_clay 2
fill ~67 ~4 ~69 ~67 ~5 ~69 leaves 15
fill ~68 ~4 ~16 ~70 ~4 ~16 stained_hardened_clay 14
setblock ~68 ~4 ~55 stained_hardened_clay 6
setblock ~69 ~4 ~55 stained_hardened_clay 10
fill ~70 ~4 ~5 ~74 ~4 ~5 stained_hardened_clay 2
fill ~70 ~4 ~56 ~71 ~4 ~56 stained_hardened_clay 2
setblock ~72 ~4 ~55 stained_hardened_clay 2
fill ~73 ~4 ~43 ~73 ~5 ~43 stained_hardened_clay 14
setblock ~73 ~4 ~55 stained_hardened_clay 6
fill ~74 ~4 ~24 ~74 ~8 ~24 stained_hardened_clay 14
fill ~74 ~4 ~25 ~74 ~8 ~25 stained_hardened_clay 14
fill ~74 ~4 ~26 ~74 ~8 ~26 stained_hardened_clay 14
fill ~74 ~4 ~28 ~74 ~11 ~28 stained_hardened_clay 14
fill ~74 ~4 ~31 ~74 ~5 ~31 stained_hardened_clay 2
setblock ~74 ~4 ~32 stained_hardened_clay 6
setblock ~74 ~4 ~33 stained_hardened_clay 2
fill ~74 ~4 ~54 ~75 ~4 ~54 stained_hardened_clay 2
setblock ~75 ~4 ~6 stained_hardened_clay 2
fill ~75 ~4 ~40 ~75 ~7 ~40 stained_hardened_clay 14
fill ~76 ~4 ~7 ~76 ~6 ~7 stained_hardened_clay 2
fill ~76 ~4 ~37 ~76 ~5 ~37 stained_hardened_clay 14
fill ~76 ~4 ~53 ~78 ~4 ~53 stained_hardened_clay 2
setblock ~77 ~4 ~54 stained_hardened_clay 2
fill ~78 ~4 ~8 ~78 ~5 ~8 stained_hardened_clay 2
fill ~79 ~4 ~9 ~79 ~5 ~9 stained_hardened_clay 2
setblock ~79 ~4 ~52 stained_hardened_clay 2
fill ~79 ~4 ~64 ~81 ~4 ~64 leaves 15
fill ~80 ~4 ~10 ~80 ~5 ~10 stained_hardened_clay 2
fill ~80 ~4 ~51 ~81 ~4 ~51 stained_hardened_clay 2
setblock ~80 ~4 ~52 stained_hardened_clay 10
setblock ~80 ~4 ~63 leaves 15
setblock ~80 ~4 ~65 leaves 15
fill ~81 ~4 ~50 ~82 ~4 ~50 stained_hardened_clay 2
fill ~82 ~4 ~15 ~82 ~8 ~15 stained_hardened_clay 2
setblock ~82 ~4 ~49 stained_hardened_clay 6
fill ~83 ~4 ~16 ~83 ~6 ~16 stained_hardened_clay 2
fill ~83 ~4 ~46 ~83 ~5 ~46 stained_hardened_clay 2
fill ~83 ~4 ~47 ~83 ~4 ~48 stained_hardened_clay 2
setblock ~83 ~4 ~51 leaves 2
setblock ~84 ~4 ~5 leaves 7
setblock ~84 ~4 ~17 stained_hardened_clay 2
fill ~84 ~4 ~22 ~84 ~5 ~22 stained_hardened_clay 2
setblock ~84 ~4 ~42 stained_hardened_clay 2
fill ~84 ~4 ~43 ~84 ~4 ~44 stained_hardened_clay 6
setblock ~84 ~4 ~45 stained_hardened_clay 2
setblock ~85 ~4 ~8 leaves 15
fill ~85 ~4 ~18 ~85 ~4 ~21 stained_hardened_clay 2
fill ~85 ~4 ~23 ~85 ~4 ~24 stained_hardened_clay 2
fill ~85 ~4 ~40 ~85 ~5 ~40 stained_hardened_clay 2
fill ~85 ~4 ~41 ~85 ~4 ~40 stained_hardened_clay 2
fill ~86 ~4 ~24 ~86 ~4 ~29 stained_hardened_clay 2
setblock ~86 ~4 ~30 stained_hardened_clay 6
setblock ~86 ~4 ~31 stained_hardened_clay 2
setblock ~86 ~4 ~32 stained_hardened_clay 6
setblock ~86 ~4 ~39 stained_hardened_clay 2
setblock ~87 ~4 ~10 leaves 15
setblock ~87 ~4 ~23 leaves 0
fill ~87 ~4 ~27 ~87 ~4 ~30 stained_hardened_clay 2
fill ~87 ~4 ~38 ~87 ~5 ~38 leaves 15
setblock ~88 ~4 ~8 leaves 15
setblock ~88 ~4 ~23 leaves 4
fill ~88 ~4 ~27 ~88 ~4 ~29 leaves 12
setblock ~89 ~4 ~7 leaves 15
setblock ~89 ~4 ~9 leaves 15
fill ~89 ~4 ~38 ~89 ~5 ~38 log 0
setblock ~89 ~4 ~40 leaves 7
setblock ~90 ~4 ~8 leaves 15
fill ~91 ~4 ~57 ~91 ~5 ~57 leaves 15
setblock ~92 ~4 ~1 leaves 7
setblock ~92 ~4 ~8 leaves 15
fill ~92 ~4 ~19 ~94 ~4 ~19 leaves 15
setblock ~93 ~4 ~18 leaves 4
setblock ~93 ~4 ~20 leaves 15
setblock ~93 ~4 ~45 leaves 12
fill ~94 ~4 ~3 ~94 ~5 ~3 leaves 7
fill ~94 ~4 ~26 ~95 ~4 ~26 leaves 15
setblock ~94 ~4 ~46 leaves 15
setblock ~95 ~4 ~45 leaves 15
setblock ~95 ~4 ~47 leaves 15
setblock ~96 ~4 ~25 leaves 15
setblock ~96 ~4 ~27 leaves 15
setblock ~96 ~4 ~44 leaves 15
fill ~96 ~4 ~48 ~96 ~4 ~49 leaves 15
setblock ~97 ~4 ~24 leaves 15
fill ~97 ~4 ~28 ~97 ~4 ~29 leaves 15
setblock ~97 ~4 ~45 leaves 15
setblock ~97 ~4 ~47 leaves 15
setblock ~4 ~5 ~35 leaves 15
fill ~5 ~5 ~34 ~5 ~5 ~35 leaves 12
setblock ~5 ~5 ~36 leaves 4
setblock ~6 ~5 ~35 leaves 15
setblock ~11 ~5 ~38 leaves 15
setblock ~12 ~5 ~52 leaves 15
setblock ~13 ~5 ~37 cocoa 8
setblock ~13 ~5 ~38 log 3
setblock ~13 ~5 ~39 cocoa 10
setblock ~13 ~5 ~50 leaves 15
setblock ~14 ~5 ~38 cocoa 9
setblock ~14 ~5 ~47 leaves 15
setblock ~14 ~5 ~49 leaves 12
setblock ~14 ~5 ~51 leaves 15
setblock ~15 ~5 ~38 leaves 15
setblock ~15 ~5 ~48 leaves 15
setblock ~15 ~5 ~50 leaves 15
setblock ~16 ~5 ~47 leaves 15
setblock ~16 ~5 ~49 leaves 15
setblock ~17 ~5 ~46 leaves 15
fill ~17 ~5 ~50 ~17 ~5 ~51 leaves 15
setblock ~18 ~5 ~47 leaves 15
setblock ~18 ~5 ~49 leaves 15
fill ~19 ~5 ~48 ~20 ~5 ~48 leaves 15
setblock ~20 ~5 ~3 leaves 15
setblock ~21 ~5 ~2 leaves 15
setblock ~21 ~5 ~4 leaves 12
setblock ~21 ~5 ~13 leaves 4
setblock ~22 ~5 ~3 leaves 15
setblock ~23 ~5 ~5 leaves 15
setblock ~23 ~5 ~12 cocoa 8
setblock ~23 ~5 ~13 log 3
setblock ~23 ~5 ~14 cocoa 10
setblock ~24 ~5 ~13 cocoa 9
setblock ~25 ~5 ~13 leaves 15
setblock ~26 ~5 ~67 leaves 15
setblock ~27 ~5 ~68 leaves 15
setblock ~28 ~5 ~67 leaves 15
setblock ~28 ~5 ~69 leaves 15
fill ~29 ~5 ~60 ~31 ~5 ~60 leaves 15
setblock ~29 ~5 ~66 leaves 15
setblock ~29 ~5 ~70 leaves 15
fill ~30 ~5 ~43 ~30 ~5 ~44 stained_hardened_clay 2
setblock ~30 ~5 ~59 leaves 15
setblock ~30 ~5 ~61 leaves 15
setblock ~30 ~5 ~67 leaves 15
setblock ~30 ~5 ~69 leaves 15
fill ~31 ~5 ~16 ~31 ~5 ~19 stained_hardened_clay 2
fill ~31 ~5 ~42 ~31 ~7 ~42 stained_hardened_clay 2
fill ~31 ~5 ~45 ~31 ~6 ~45 stained_hardened_clay 2
fill ~31 ~5 ~68 ~32 ~5 ~68 leaves 15
setblock ~32 ~5 ~15 stained_hardened_clay 2
fill ~32 ~5 ~40 ~32 ~14 ~40 stained_hardened_clay 2
fill ~32 ~5 ~47 ~32 ~6 ~47 stained_hardened_clay 2
fill ~32 ~5 ~48 ~32 ~5 ~47 stained_hardened_clay 2
fill ~33 ~5 ~13 ~33 ~5 ~14 stained_hardened_clay 2
fill ~33 ~5 ~39 ~33 ~7 ~39 stained_hardened_clay 2
setblock ~33 ~5 ~49 stained_hardened_clay 2
setblock ~34 ~5 ~12 stained_hardened_clay 2
setblock ~34 ~5 ~50 stained_hardened_clay 2
setblock ~35 ~5 ~11 stained_hardened_clay 2
setblock ~35 ~5 ~38 stained_hardened_clay 2
fill ~35 ~5 ~51 ~36 ~5 ~51 stained_hardened_clay 2
setblock ~36 ~5 ~10 stained_hardened_clay 6
setblock ~36 ~5 ~38 stained_hardened_clay 10
setblock ~37 ~5 ~9 stained_hardened_clay 2
setblock ~37 ~5 ~39 stained_hardened_clay 14
setblock ~37 ~5 ~52 stained_hardened_clay 2
fill ~38 ~5 ~7 ~38 ~5 ~8 stained_hardened_clay 2
fill ~38 ~5 ~42 ~38 ~7 ~42 stained_hardened_clay 14
fill ~38 ~5 ~53 ~38 ~6 ~53 stained_hardened_clay 2
fill ~38 ~5 ~54 ~38 ~5 ~53 stained_hardened_clay 2
fill ~39 ~5 ~6 ~40 ~5 ~6 stained_hardened_clay 2
fill ~39 ~5 ~55 ~41 ~5 ~55 stained_hardened_clay 2
fill ~41 ~5 ~5 ~42 ~5 ~5 stained_hardened_clay 2
fill ~41 ~5 ~15 ~52 ~5 ~15 stained_hardened_clay 14
fill ~41 ~5 ~56 ~47 ~5 ~56 stained_hardened_clay 2
fill ~42 ~5 ~46 ~58 ~5 ~46 stained_hardened_clay 14
fill ~43 ~5 ~4 ~55 ~5 ~4 stained_hardened_clay 2
setblock ~47 ~5 ~3 leaves 12
fill ~48 ~5 ~57 ~62 ~5 ~57 stained_hardened_clay 2
fill ~50 ~5 ~65 ~50 ~6 ~65 leaves 15
fill ~53 ~5 ~16 ~64 ~5 ~16 stained_hardened_clay 14
fill ~56 ~5 ~3 ~58 ~5 ~3 stained_hardened_clay 2
fill ~59 ~5 ~4 ~64 ~5 ~4 stained_hardened_clay 2
fill ~60 ~5 ~45 ~71 ~5 ~45 stained_hardened_clay 14
setblock ~63 ~5 ~56 stained_hardened_clay 6
fill ~64 ~5 ~55 ~65 ~5 ~55 stained_hardened_clay 6
fill ~65 ~5 ~5 ~72 ~5 ~5 stained_hardened_clay 2
fill ~66 ~5 ~54 ~66 ~7 ~54 stained_hardened_clay 2
setblock ~67 ~5 ~70 cocoa 8
fill ~68 ~5 ~16 ~70 ~5 ~16 stained_hardened_clay 14
fill ~68 ~5 ~54 ~69 ~5 ~54 stained_hardened_clay 2
fill ~70 ~5 ~55 ~71 ~5 ~55 stained_hardened_clay 2
fill ~72 ~5 ~54 ~73 ~5 ~54 stained_hardened_clay 2
fill ~73 ~5 ~6 ~74 ~5 ~6 stained_hardened_clay 2
setblock ~74 ~5 ~30 stained_hardened_clay 2
setblock ~74 ~5 ~32 stained_hardened_clay 2
setblock ~74 ~5 ~33 stained_hardened_clay 14
fill ~74 ~5 ~53 ~76 ~5 ~53 stained_hardened_clay 2
fill ~75 ~5 ~7 ~75 ~7 ~7 stained_hardened_clay 2
fill ~75 ~5 ~36 ~75 ~7 ~36 stained_hardened_clay 14
setblock ~76 ~5 ~38 stained_hardened_clay 14
fill ~77 ~5 ~8 ~77 ~7 ~8 stained_hardened_clay 2
fill ~77 ~5 ~52 ~78 ~5 ~52 stained_hardened_clay 2
fill ~79 ~5 ~50 ~80 ~5 ~50 stained_hardened_clay 2
fill ~79 ~5 ~51 ~79 ~5 ~50 stained_hardened_clay 2
setblock ~81 ~5 ~11 stained_hardened_clay 2
setblock ~81 ~5 ~49 stained_hardened_clay 2
fill ~82 ~5 ~14 ~82 ~6 ~14 stained_hardened_clay 2
fill ~82 ~5 ~47 ~82 ~5 ~48 stained_hardened_clay 2
fill ~83 ~5 ~17 ~83 ~6 ~17 stained_hardened_clay 2
setblock ~83 ~5 ~42 stained_hardened_clay 10
fill ~83 ~5 ~43 ~83 ~7 ~43 stained_hardened_clay 2
setblock ~83 ~5 ~45 stained_hardened_clay 2
setblock ~83 ~5 ~50 leaves 4
setblock ~84 ~5 ~1 leaves 7
fill ~84 ~5 ~5 ~84 ~7 ~5 leaves 15
fill ~84 ~5 ~18 ~84 ~5 ~24 stained_hardened_clay 2
fill ~84 ~5 ~41 ~84 ~6 ~41 stained_hardened_clay 2
setblock ~84 ~5 ~44 stained_hardened_clay 2
fill ~85 ~5 ~25 ~85 ~5 ~31 stained_hardened_clay 2
fill ~85 ~5 ~33 ~85 ~6 ~33 stained_hardened_clay 2
fill ~85 ~5 ~39 ~85 ~6 ~39 stained_hardened_clay 2
fill ~86 ~5 ~3 ~86 ~6 ~3 leaves 7
setblock ~86 ~5 ~8 leaves 15
setblock ~86 ~5 ~32 stained_hardened_clay 2
setblock ~86 ~5 ~38 stained_hardened_clay 2
setblock ~87 ~5 ~8 leaves 12
setblock ~88 ~5 ~7 leaves 15
setblock ~88 ~5 ~9 leaves 15
setblock ~88 ~5 ~30 leaves 12
setblock ~89 ~5 ~6 leaves 15
fill ~89 ~5 ~10 ~89 ~5 ~11 leaves 15
setblock ~89 ~5 ~36 leaves 15
setblock ~89 ~5 ~40 leaves 15
setblock ~89 ~5 ~59 leaves 15
setblock ~90 ~5 ~5 leaves 15
setblock ~90 ~5 ~7 leaves 15
setblock ~90 ~5 ~9 leaves 15
setblock ~91 ~5 ~8 leaves 15
setblock ~91 ~5 ~38 leaves 15
setblock ~91 ~5 ~58 cocoa 8
setblock ~91 ~5 ~59 log 3
setblock ~91 ~5 ~60 cocoa 10
fill ~92 ~5 ~1 ~92 ~6 ~1 leaves 15
setblock ~92 ~5 ~5 leaves 12
setblock ~92 ~5 ~59 cocoa 9
setblock ~93 ~5 ~59 leaves 15
setblock ~95 ~5 ~28 leaves 15
setblock ~95 ~5 ~46 leaves 15
setblock ~96 ~5 ~26 leaves 15
setblock ~96 ~5 ~45 leaves 15
setblock ~96 ~5 ~47 leaves 15
setblock ~97 ~5 ~25 leaves 15
setblock ~97 ~5 ~27 leaves 15
setblock ~97 ~5 ~46 leaves 15
fill ~11 ~6 ~50 ~12 ~6 ~50 leaves 15
fill ~12 ~6 ~38 ~14 ~6 ~38 leaves 15
setblock ~13 ~6 ~37 leaves 15
setblock ~13 ~6 ~39 leaves 15
setblock ~14 ~6 ~48 leaves 15
fill ~14 ~6 ~50 ~14 ~7 ~50 leaves 15
fill ~14 ~6 ~52 ~14 ~6 ~53 leaves 15
setblock ~16 ~6 ~48 leaves 15
setblock ~16 ~6 ~50 leaves 15
setblock ~17 ~6 ~47 leaves 15
setblock ~17 ~6 ~49 leaves 15
setblock ~18 ~6 ~48 leaves 15
fill ~19 ~6 ~3 ~19 ~7 ~3 leaves 15
setblock ~19 ~6 ~50 leaves 15
setblock ~21 ~6 ~1 leaves 15
fill ~21 ~6 ~3 ~21 ~7 ~3 leaves 15
fill ~21 ~6 ~5 ~21 ~6 ~6 leaves 15
fill ~22 ~6 ~13 ~24 ~6 ~13 leaves 15
fill ~23 ~6 ~3 ~24 ~6 ~3 leaves 15
setblock ~23 ~6 ~12 leaves 15
setblock ~23 ~6 ~14 leaves 15
setblock ~28 ~6 ~68 leaves 15
setblock ~29 ~6 ~67 leaves 15
setblock ~29 ~6 ~69 leaves 15
setblock ~30 ~6 ~68 leaves 15
fill ~31 ~6 ~17 ~31 ~6 ~20 stained_hardened_clay 2
fill ~31 ~6 ~43 ~31 ~7 ~43 stained_hardened_clay 2
fill ~31 ~6 ~44 ~31 ~7 ~44 stained_hardened_clay 2
setblock ~31 ~6 ~70 leaves 15
setblock ~32 ~6 ~16 stained_hardened_clay 2
fill ~32 ~6 ~21 ~32 ~7 ~21 stained_hardened_clay 2
fill ~32 ~6 ~46 ~32 ~7 ~46 stained_hardened_clay 2
setblock ~33 ~6 ~15 stained_hardened_clay 2
setblock ~33 ~6 ~48 stained_hardened_clay 2
fill ~34 ~6 ~13 ~34 ~6 ~14 stained_hardened_clay 2
setblock ~34 ~6 ~49 stained_hardened_clay 2
setblock ~35 ~6 ~12 stained_hardened_clay 2
fill ~35 ~6 ~23 ~35 ~7 ~23 stained_hardened_clay 2
fill ~35 ~6 ~37 ~36 ~6 ~37 stained_hardened_clay 2
setblock ~35 ~6 ~50 stained_hardened_clay 2
setblock ~36 ~6 ~11 stained_hardened_clay 2
setblock ~36 ~6 ~51 stained_hardened_clay 2
setblock ~37 ~6 ~10 stained_hardened_clay 2
setblock ~37 ~6 ~38 stained_hardened_clay 10
setblock ~37 ~6 ~51 stained_hardened_clay 10
fill ~38 ~6 ~8 ~38 ~6 ~9 stained_hardened_clay 6
setblock ~38 ~6 ~21 stained_hardened_clay 14
fill ~38 ~6 ~39 ~38 ~7 ~39 stained_hardened_clay 14
fill ~38 ~6 ~40 ~38 ~7 ~40 stained_hardened_clay 14
fill ~38 ~6 ~41 ~38 ~7 ~41 stained_hardened_clay 14
fill ~38 ~6 ~52 ~38 ~7 ~52 stained_hardened_clay 2
fill ~39 ~6 ~7 ~40 ~6 ~7 stained_hardened_clay 2
setblock ~39 ~6 ~44 stained_hardened_clay 14
fill ~39 ~6 ~54 ~41 ~6 ~54 stained_hardened_clay 2
fill ~40 ~6 ~45 ~43 ~6 ~45 stained_hardened_clay 14
setblock ~41 ~6 ~6 stained_hardened_clay 2
fill ~41 ~6 ~15 ~51 ~6 ~15 stained_hardened_clay 14
fill ~42 ~6 ~5 ~48 ~6 ~5 stained_hardened_clay 2
setblock ~42 ~6 ~55 stained_hardened_clay 10
fill ~43 ~6 ~55 ~43 ~8 ~55 stained_hardened_clay 2
fill ~44 ~6 ~46 ~57 ~6 ~46 stained_hardened_clay 14
fill ~44 ~6 ~56 ~48 ~6 ~56 stained_hardened_clay 2
setblock ~48 ~6 ~67 leaves 15
fill ~49 ~6 ~4 ~58 ~6 ~4 stained_hardened_clay 2
setblock ~49 ~6 ~57 stained_hardened_clay 10
fill ~50 ~6 ~57 ~52 ~6 ~57 stained_hardened_clay 2
setblock ~50 ~6 ~66 cocoa 8
setblock ~50 ~6 ~67 log 3
setblock ~50 ~6 ~68 cocoa 10
setblock ~51 ~6 ~67 cocoa 9
fill ~52 ~6 ~16 ~57 ~6 ~16 stained_hardened_clay 14
setblock ~52 ~6 ~67 leaves 15
setblock ~53 ~6 ~57 stained_hardened_clay 6
fill ~55 ~6 ~31 ~55 ~8 ~31 stained_hardened_clay 14
fill ~56 ~6 ~30 ~56 ~8 ~30 stained_hardened_clay 14
fill ~56 ~6 ~32 ~56 ~7 ~32 stained_hardened_clay 14
fill ~56 ~6 ~57 ~56 ~8 ~57 stained_hardened_clay 2
fill ~57 ~6 ~31 ~57 ~7 ~31 stained_hardened_clay 14
setblock ~57 ~6 ~57 stained_hardened_clay 10
setblock ~58 ~6 ~17 stained_hardened_clay 14
fill ~58 ~6 ~45 ~58 ~7 ~45 stained_hardened_clay 14
fill ~58 ~6 ~57 ~61 ~6 ~57 stained_hardened_clay 2
fill ~59 ~6 ~5 ~59 ~9 ~5 stained_hardened_clay 2
fill ~59 ~6 ~16 ~65 ~6 ~16 stained_hardened_clay 14
fill ~60 ~6 ~4 ~64 ~6 ~4 stained_hardened_clay 2
fill ~60 ~6 ~45 ~61 ~6 ~45 stained_hardened_clay 14
fill ~62 ~6 ~44 ~63 ~6 ~44 stained_hardened_clay 14
fill ~62 ~6 ~56 ~63 ~6 ~56 stained_hardened_clay 2
fill ~64 ~6 ~45 ~70 ~6 ~45 stained_hardened_clay 14
fill ~64 ~6 ~55 ~64 ~7 ~55 stained_hardened_clay 2
fill ~65 ~6 ~5 ~71 ~6 ~5 stained_hardened_clay 2
fill ~65 ~6 ~54 ~65 ~14 ~54 stained_hardened_clay 2
setblock ~67 ~6 ~70 leaves 15
fill ~68 ~6 ~16 ~70 ~6 ~16 stained_hardened_clay 14
fill ~68 ~6 ~54 ~69 ~6 ~54 stained_hardened_clay 2
fill ~70 ~6 ~54 ~70 ~7 ~54 stained_hardened_clay 6
fill ~71 ~6 ~44 ~71 ~7 ~44 stained_hardened_clay 14
fill ~71 ~6 ~54 ~72 ~6 ~54 stained_hardened_clay 2
fill ~72 ~6 ~6 ~73 ~6 ~6 stained_hardened_clay 2
fill ~72 ~6 ~19 ~72 ~7 ~19 stained_hardened_clay 14
fill ~72 ~6 ~43 ~72 ~7 ~43 stained_hardened_clay 14
fill ~73 ~6 ~42 ~73 ~7 ~42 stained_hardened_clay 14
fill ~73 ~6 ~53 ~74 ~6 ~53 stained_hardened_clay 2
fill ~74 ~6 ~7 ~74 ~8 ~7 stained_hardened_clay 2
fill ~74 ~6 ~30 ~74 ~8 ~30 stained_hardened_clay 14
fill ~74 ~6 ~31 ~74 ~8 ~31 stained_hardened_clay 14
fill ~74 ~6 ~32 ~74 ~8 ~32 stained_hardened_clay 14
setblock ~74 ~6 ~33 stained_hardened_clay 10
fill ~74 ~6 ~41 ~74 ~7 ~41 stained_hardened_clay 14
fill ~75 ~6 ~37 ~75 ~8 ~37 stained_hardened_clay 14
