fill ~74 ~0 ~84 ~80 ~0 ~84 concrete 15
fill ~74 ~0 ~85 ~76 ~0 ~85 concrete 15
fill ~81 ~0 ~83 ~82 ~0 ~83 concrete 15
fill ~63 ~1 ~74 ~87 ~1 ~74 concrete 15
fill ~63 ~1 ~75 ~87 ~1 ~75 concrete 15
fill ~63 ~1 ~76 ~87 ~1 ~76 concrete 15
fill ~64 ~1 ~77 ~87 ~1 ~77 concrete 15
fill ~64 ~1 ~78 ~87 ~1 ~78 concrete 15
fill ~64 ~1 ~79 ~86 ~1 ~79 concrete 15
fill ~65 ~1 ~80 ~86 ~1 ~80 concrete 15
fill ~65 ~1 ~81 ~85 ~1 ~81 concrete 15
fill ~66 ~1 ~82 ~84 ~1 ~82 concrete 15
fill ~68 ~1 ~83 ~80 ~1 ~83 concrete 15
fill ~69 ~1 ~84 ~73 ~1 ~84 concrete 15
fill ~72 ~1 ~85 ~79 ~1 ~85 concrete 15
fill ~80 ~1 ~84 ~81 ~1 ~84 concrete 15
fill ~82 ~1 ~83 ~83 ~1 ~83 concrete 15
fill ~83 ~1 ~73 ~88 ~1 ~73 concrete 15
fill ~36 ~2 ~84 ~48 ~2 ~84 concrete 15
fill ~37 ~2 ~82 ~50 ~2 ~82 concrete 15
fill ~37 ~2 ~83 ~49 ~2 ~83 concrete 15
fill ~38 ~2 ~80 ~52 ~2 ~80 concrete 15
fill ~38 ~2 ~81 ~51 ~2 ~81 concrete 15
fill ~39 ~2 ~77 ~54 ~2 ~77 concrete 15
fill ~39 ~2 ~78 ~53 ~2 ~78 concrete 15
fill ~39 ~2 ~79 ~53 ~2 ~79 concrete 15
fill ~39 ~2 ~85 ~46 ~2 ~85 concrete 15
fill ~40 ~2 ~75 ~54 ~2 ~75 concrete 15
fill ~40 ~2 ~76 ~54 ~2 ~76 concrete 15
fill ~41 ~2 ~72 ~55 ~2 ~72 concrete 15
fill ~41 ~2 ~73 ~55 ~2 ~73 concrete 15
fill ~41 ~2 ~74 ~54 ~2 ~74 concrete 15
fill ~42 ~2 ~69 ~55 ~2 ~69 concrete 15
fill ~42 ~2 ~70 ~55 ~2 ~70 concrete 15
fill ~42 ~2 ~71 ~55 ~2 ~71 concrete 15
fill ~43 ~2 ~66 ~56 ~2 ~66 concrete 15
fill ~43 ~2 ~67 ~55 ~2 ~67 concrete 15
fill ~43 ~2 ~68 ~55 ~2 ~68 concrete 15
fill ~44 ~2 ~63 ~56 ~2 ~63 concrete 15
fill ~44 ~2 ~64 ~56 ~2 ~64 concrete 15
fill ~44 ~2 ~65 ~56 ~2 ~65 concrete 15
fill ~45 ~2 ~59 ~56 ~2 ~59 concrete 15
fill ~45 ~2 ~60 ~56 ~2 ~60 concrete 15
fill ~45 ~2 ~61 ~56 ~2 ~61 concrete 15
fill ~45 ~2 ~62 ~56 ~2 ~62 concrete 15
fill ~46 ~2 ~54 ~55 ~2 ~54 concrete 15
fill ~46 ~2 ~55 ~55 ~2 ~55 concrete 15
fill ~46 ~2 ~56 ~56 ~2 ~56 concrete 15
fill ~46 ~2 ~57 ~56 ~2 ~57 concrete 15
fill ~46 ~2 ~58 ~56 ~2 ~58 concrete 15
fill ~47 ~2 ~49 ~48 ~2 ~49 concrete 15
fill ~47 ~2 ~50 ~55 ~2 ~50 concrete 15
fill ~47 ~2 ~51 ~55 ~2 ~51 concrete 15
fill ~47 ~2 ~52 ~55 ~2 ~52 concrete 15
fill ~47 ~2 ~53 ~55 ~2 ~53 concrete 15
fill ~49 ~2 ~43 ~55 ~2 ~43 concrete 15
fill ~49 ~2 ~44 ~55 ~2 ~44 concrete 15
fill ~49 ~2 ~45 ~55 ~2 ~45 concrete 15
fill ~50 ~2 ~41 ~54 ~2 ~41 concrete 15
fill ~50 ~2 ~42 ~55 ~2 ~42 concrete 15
fill ~51 ~2 ~39 ~54 ~2 ~39 concrete 15
fill ~51 ~2 ~40 ~54 ~2 ~40 concrete 15
fill ~52 ~2 ~37 ~54 ~2 ~37 concrete 15
fill ~52 ~2 ~38 ~54 ~2 ~38 concrete 15
fill ~52 ~2 ~46 ~55 ~2 ~46 concrete 15
fill ~53 ~2 ~36 ~54 ~2 ~36 concrete 15
fill ~61 ~2 ~60 ~62 ~2 ~60 concrete 15
fill ~61 ~2 ~61 ~66 ~2 ~61 concrete 15
fill ~61 ~2 ~62 ~71 ~2 ~62 concrete 15
fill ~61 ~2 ~63 ~78 ~2 ~63 concrete 15
fill ~61 ~2 ~64 ~88 ~2 ~64 concrete 15
fill ~61 ~2 ~65 ~88 ~2 ~65 concrete 15
fill ~61 ~2 ~66 ~88 ~2 ~66 concrete 15
fill ~61 ~2 ~67 ~88 ~2 ~67 concrete 15
fill ~61 ~2 ~68 ~88 ~2 ~68 concrete 15
fill ~61 ~2 ~69 ~88 ~2 ~69 concrete 15
fill ~61 ~2 ~70 ~88 ~2 ~70 concrete 15
fill ~61 ~2 ~71 ~88 ~2 ~71 concrete 15
fill ~62 ~2 ~72 ~88 ~2 ~72 concrete 15
fill ~62 ~2 ~73 ~82 ~2 ~73 concrete 15
fill ~62 ~2 ~74 ~62 ~11 ~74 concrete 15
fill ~62 ~2 ~75 ~62 ~10 ~75 concrete 15
fill ~63 ~2 ~76 ~63 ~13 ~76 concrete 15
fill ~63 ~2 ~77 ~63 ~12 ~77 concrete 15
fill ~63 ~2 ~78 ~63 ~11 ~78 concrete 15
fill ~64 ~2 ~79 ~64 ~13 ~79 concrete 15
fill ~65 ~2 ~80 ~65 ~3 ~80 concrete 15
fill ~65 ~2 ~81 ~65 ~11 ~81 concrete 15
fill ~66 ~2 ~82 ~66 ~12 ~82 concrete 15
fill ~67 ~2 ~83 ~68 ~2 ~83 concrete 15
fill ~69 ~2 ~84 ~70 ~2 ~84 concrete 15
fill ~71 ~2 ~85 ~79 ~2 ~85 concrete 15
fill ~80 ~2 ~84 ~81 ~2 ~84 concrete 15
fill ~82 ~2 ~83 ~83 ~2 ~83 concrete 15
fill ~84 ~2 ~82 ~84 ~5 ~82 concrete 15
fill ~85 ~2 ~81 ~85 ~5 ~81 concrete 15
fill ~86 ~2 ~79 ~86 ~3 ~79 concrete 15
fill ~86 ~2 ~80 ~86 ~7 ~80 concrete 15
fill ~87 ~2 ~77 ~87 ~4 ~77 concrete 15
fill ~87 ~2 ~78 ~87 ~6 ~78 concrete 15
fill ~88 ~2 ~73 ~88 ~5 ~73 concrete 15
fill ~88 ~2 ~74 ~88 ~6 ~74 concrete 15
fill ~88 ~2 ~75 ~88 ~14 ~75 concrete 15
fill ~88 ~2 ~76 ~88 ~14 ~76 concrete 15
fill ~29 ~3 ~68 ~42 ~3 ~68 concrete 15
fill ~29 ~3 ~69 ~41 ~3 ~69 concrete 15
fill ~29 ~3 ~70 ~41 ~3 ~70 concrete 15
fill ~29 ~3 ~71 ~41 ~3 ~71 concrete 15
fill ~29 ~3 ~72 ~40 ~3 ~72 concrete 15
fill ~29 ~3 ~73 ~40 ~3 ~73 concrete 15
fill ~29 ~3 ~74 ~40 ~3 ~74 concrete 15
fill ~29 ~3 ~75 ~39 ~3 ~75 concrete 15
fill ~30 ~3 ~66 ~42 ~3 ~66 concrete 15
fill ~30 ~3 ~67 ~42 ~3 ~67 concrete 15
fill ~30 ~3 ~76 ~39 ~3 ~76 concrete 15
fill ~30 ~3 ~77 ~38 ~3 ~77 concrete 15
fill ~30 ~3 ~78 ~38 ~3 ~78 concrete 15
fill ~30 ~3 ~79 ~38 ~3 ~79 concrete 15
fill ~31 ~3 ~64 ~43 ~3 ~64 concrete 15
fill ~31 ~3 ~65 ~43 ~3 ~65 concrete 15
fill ~31 ~3 ~80 ~37 ~3 ~80 concrete 15
fill ~32 ~3 ~62 ~44 ~3 ~62 concrete 15
fill ~32 ~3 ~63 ~43 ~3 ~63 concrete 15
fill ~32 ~3 ~81 ~37 ~3 ~81 concrete 15
fill ~33 ~3 ~60 ~44 ~3 ~60 concrete 15
fill ~33 ~3 ~61 ~44 ~3 ~61 concrete 15
fill ~33 ~3 ~82 ~36 ~3 ~82 concrete 15
fill ~34 ~3 ~58 ~45 ~3 ~58 concrete 15
fill ~34 ~3 ~59 ~44 ~3 ~59 concrete 15
fill ~34 ~3 ~83 ~36 ~3 ~83 concrete 15
fill ~35 ~3 ~56 ~45 ~3 ~56 concrete 15
fill ~35 ~3 ~57 ~45 ~3 ~57 concrete 15
fill ~35 ~3 ~84 ~36 ~3 ~84 concrete 15
fill ~36 ~3 ~54 ~45 ~3 ~54 concrete 15
fill ~36 ~3 ~55 ~45 ~3 ~55 concrete 15
fill ~37 ~3 ~51 ~46 ~3 ~51 concrete 15
fill ~37 ~3 ~52 ~46 ~3 ~52 concrete 15
fill ~37 ~3 ~53 ~46 ~3 ~53 concrete 15
fill ~37 ~3 ~85 ~46 ~3 ~85 concrete 15
fill ~38 ~3 ~43 ~48 ~3 ~43 concrete 15
fill ~38 ~3 ~48 ~46 ~3 ~48 concrete 15
fill ~38 ~3 ~49 ~55 ~3 ~49 concrete 15
fill ~38 ~3 ~50 ~46 ~3 ~50 concrete 15
fill ~39 ~3 ~31 ~52 ~3 ~31 concrete 15
fill ~39 ~3 ~32 ~53 ~3 ~32 concrete 15
fill ~39 ~3 ~33 ~53 ~3 ~33 concrete 15
fill ~39 ~3 ~34 ~53 ~3 ~34 concrete 15
fill ~39 ~3 ~35 ~54 ~3 ~35 concrete 15
fill ~39 ~3 ~36 ~52 ~3 ~36 concrete 15
fill ~39 ~3 ~37 ~51 ~3 ~37 concrete 15
fill ~39 ~3 ~38 ~51 ~3 ~38 concrete 15
fill ~39 ~3 ~39 ~50 ~3 ~39 concrete 15
fill ~39 ~3 ~40 ~50 ~3 ~40 concrete 15
fill ~39 ~3 ~41 ~49 ~3 ~41 concrete 15
fill ~39 ~3 ~42 ~49 ~3 ~42 concrete 15
fill ~39 ~3 ~44 ~48 ~3 ~44 concrete 15
fill ~40 ~3 ~27 ~46 ~3 ~27 concrete 15
fill ~40 ~3 ~28 ~49 ~3 ~28 concrete 15
fill ~40 ~3 ~29 ~50 ~3 ~29 concrete 15
fill ~40 ~3 ~30 ~51 ~3 ~30 concrete 15
fill ~44 ~3 ~45 ~48 ~3 ~45 concrete 15
fill ~47 ~3 ~84 ~48 ~3 ~84 concrete 15
fill ~48 ~3 ~46 ~52 ~3 ~46 concrete 15
fill ~49 ~3 ~83 ~49 ~13 ~83 concrete 15
fill ~50 ~3 ~82 ~50 ~14 ~82 concrete 15
fill ~51 ~3 ~81 ~51 ~4 ~81 concrete 15
fill ~52 ~3 ~80 ~52 ~14 ~80 concrete 15
fill ~53 ~3 ~47 ~55 ~3 ~47 concrete 15
fill ~53 ~3 ~78 ~53 ~6 ~78 concrete 15
fill ~53 ~3 ~79 ~53 ~13 ~79 concrete 15
fill ~54 ~3 ~36 ~54 ~15 ~36 concrete 15
fill ~54 ~3 ~37 ~54 ~4 ~37 concrete 15
fill ~54 ~3 ~75 ~54 ~5 ~75 concrete 15
fill ~54 ~3 ~76 ~54 ~14 ~76 concrete 15
fill ~54 ~3 ~77 ~54 ~13 ~77 concrete 15
fill ~55 ~3 ~38 ~55 ~13 ~38 concrete 15
fill ~55 ~3 ~39 ~55 ~15 ~39 concrete 15
fill ~55 ~3 ~40 ~55 ~16 ~40 concrete 15
fill ~55 ~3 ~41 ~55 ~16 ~41 concrete 15
fill ~55 ~3 ~42 ~55 ~16 ~42 concrete 15
fill ~55 ~3 ~43 ~55 ~16 ~43 concrete 15
fill ~55 ~3 ~44 ~55 ~16 ~44 concrete 15
fill ~55 ~3 ~45 ~55 ~16 ~45 concrete 15
fill ~55 ~3 ~46 ~55 ~16 ~46 concrete 15
fill ~55 ~3 ~50 ~55 ~16 ~50 concrete 15
fill ~55 ~3 ~51 ~55 ~15 ~51 concrete 15
fill ~55 ~3 ~52 ~55 ~15 ~52 concrete 15
fill ~55 ~3 ~53 ~55 ~14 ~53 concrete 15
fill ~55 ~3 ~54 ~55 ~14 ~54 concrete 15
fill ~55 ~3 ~55 ~55 ~13 ~55 concrete 15
fill ~55 ~3 ~56 ~55 ~13 ~56 concrete 15
fill ~55 ~3 ~67 ~55 ~3 ~74 concrete 15
fill ~56 ~3 ~57 ~56 ~4 ~57 concrete 15
fill ~56 ~3 ~58 ~56 ~5 ~58 concrete 15
fill ~56 ~3 ~59 ~56 ~6 ~59 concrete 15
fill ~56 ~3 ~60 ~56 ~7 ~60 concrete 15
fill ~56 ~3 ~61 ~56 ~7 ~61 concrete 15
fill ~56 ~3 ~62 ~56 ~7 ~62 concrete 15
fill ~56 ~3 ~63 ~56 ~8 ~63 concrete 15
fill ~56 ~3 ~64 ~56 ~8 ~64 concrete 15
fill ~56 ~3 ~65 ~56 ~8 ~65 concrete 15
fill ~56 ~3 ~66 ~56 ~8 ~66 concrete 15
fill ~61 ~3 ~52 ~74 ~3 ~52 concrete 15
fill ~61 ~3 ~53 ~77 ~3 ~53 concrete 15
fill ~61 ~3 ~54 ~81 ~3 ~54 concrete 15
fill ~61 ~3 ~55 ~86 ~3 ~55 concrete 15
fill ~61 ~3 ~56 ~87 ~3 ~56 concrete 15
fill ~61 ~3 ~57 ~87 ~3 ~57 concrete 15
fill ~61 ~3 ~58 ~87 ~3 ~58 concrete 15
fill ~61 ~3 ~59 ~88 ~3 ~59 concrete 15
fill ~61 ~3 ~60 ~61 ~9 ~60 concrete 15
fill ~61 ~3 ~61 ~61 ~9 ~61 concrete 15
fill ~61 ~3 ~62 ~61 ~9 ~62 concrete 15
fill ~61 ~3 ~63 ~61 ~9 ~63 concrete 15
fill ~61 ~3 ~64 ~61 ~9 ~64 concrete 15
fill ~61 ~3 ~65 ~61 ~9 ~65 concrete 15
fill ~61 ~3 ~66 ~61 ~9 ~66 concrete 15
fill ~61 ~3 ~67 ~61 ~9 ~67 concrete 15
fill ~61 ~3 ~68 ~61 ~9 ~68 concrete 15
fill ~61 ~3 ~69 ~61 ~9 ~69 concrete 15
fill ~61 ~3 ~70 ~61 ~8 ~70 concrete 15
fill ~61 ~3 ~71 ~61 ~7 ~71 concrete 15
fill ~62 ~3 ~50 ~69 ~3 ~50 concrete 15
fill ~62 ~3 ~51 ~71 ~3 ~51 concrete 15
fill ~62 ~3 ~72 ~62 ~12 ~72 concrete 15
fill ~62 ~3 ~73 ~62 ~12 ~73 concrete 15
fill ~63 ~3 ~60 ~88 ~3 ~60 concrete 15
fill ~67 ~3 ~61 ~88 ~3 ~61 concrete 15
fill ~67 ~3 ~83 ~68 ~3 ~83 concrete 15
fill ~69 ~3 ~84 ~70 ~3 ~84 concrete 15
fill ~71 ~3 ~85 ~79 ~3 ~85 concrete 15
fill ~72 ~3 ~62 ~88 ~3 ~62 concrete 15
fill ~79 ~3 ~63 ~88 ~3 ~63 concrete 15
fill ~80 ~3 ~84 ~81 ~3 ~84 concrete 15
fill ~82 ~3 ~83 ~83 ~3 ~83 concrete 15
setblock ~88 ~3 ~64 concrete 15
fill ~88 ~3 ~71 ~88 ~3 ~76 concrete 15
fill ~89 ~3 ~65 ~89 ~11 ~65 concrete 15
fill ~89 ~3 ~66 ~89 ~11 ~66 concrete 15
fill ~89 ~3 ~67 ~89 ~12 ~67 concrete 15
fill ~89 ~3 ~68 ~89 ~12 ~68 concrete 15
fill ~89 ~3 ~69 ~89 ~12 ~69 concrete 15
fill ~89 ~3 ~70 ~89 ~12 ~70 concrete 15
fill ~28 ~4 ~59 ~33 ~4 ~59 concrete 15
fill ~28 ~4 ~60 ~32 ~4 ~60 concrete 15
fill ~28 ~4 ~61 ~32 ~4 ~61 concrete 15
fill ~28 ~4 ~62 ~31 ~4 ~62 concrete 15
fill ~28 ~4 ~63 ~31 ~4 ~63 concrete 15
fill ~28 ~4 ~64 ~30 ~4 ~64 concrete 15
fill ~28 ~4 ~65 ~30 ~4 ~65 concrete 15
fill ~28 ~4 ~66 ~29 ~4 ~66 concrete 15
fill ~28 ~4 ~67 ~29 ~4 ~67 concrete 15
fill ~28 ~4 ~68 ~28 ~13 ~68 concrete 15
fill ~28 ~4 ~69 ~28 ~13 ~69 concrete 15
fill ~28 ~4 ~70 ~28 ~13 ~70 concrete 15
fill ~28 ~4 ~71 ~28 ~13 ~71 concrete 15
fill ~28 ~4 ~72 ~28 ~13 ~72 concrete 15
fill ~28 ~4 ~73 ~28 ~12 ~73 concrete 15
fill ~29 ~4 ~54 ~35 ~4 ~54 concrete 15
fill ~29 ~4 ~55 ~35 ~4 ~55 concrete 15
fill ~29 ~4 ~56 ~34 ~4 ~56 concrete 15
fill ~29 ~4 ~57 ~34 ~4 ~57 concrete 15
fill ~29 ~4 ~58 ~33 ~4 ~58 concrete 15
fill ~29 ~4 ~74 ~29 ~5 ~74 concrete 15
fill ~29 ~4 ~75 ~29 ~15 ~75 concrete 15
fill ~29 ~4 ~76 ~29 ~14 ~76 concrete 15
fill ~29 ~4 ~77 ~29 ~13 ~77 concrete 15
fill ~30 ~4 ~47 ~42 ~4 ~47 concrete 15
fill ~30 ~4 ~48 ~37 ~4 ~48 concrete 15
fill ~30 ~4 ~49 ~37 ~4 ~49 concrete 15
fill ~30 ~4 ~50 ~37 ~4 ~50 concrete 15
fill ~30 ~4 ~51 ~36 ~4 ~51 concrete 15
fill ~30 ~4 ~52 ~36 ~4 ~52 concrete 15
fill ~30 ~4 ~53 ~36 ~4 ~53 concrete 15
fill ~30 ~4 ~78 ~30 ~7 ~78 concrete 15
fill ~30 ~4 ~79 ~30 ~14 ~79 concrete 15
fill ~31 ~4 ~80 ~31 ~14 ~80 concrete 15
fill ~32 ~4 ~33 ~38 ~4 ~33 concrete 15
fill ~32 ~4 ~34 ~38 ~4 ~34 concrete 15
fill ~32 ~4 ~35 ~38 ~4 ~35 concrete 15
fill ~32 ~4 ~36 ~38 ~4 ~36 concrete 15
fill ~32 ~4 ~37 ~38 ~4 ~37 concrete 15
fill ~32 ~4 ~38 ~38 ~4 ~38 concrete 15
fill ~32 ~4 ~39 ~38 ~4 ~39 concrete 15
fill ~32 ~4 ~40 ~38 ~4 ~40 concrete 15
fill ~32 ~4 ~41 ~38 ~4 ~41 concrete 15
fill ~32 ~4 ~42 ~38 ~4 ~42 concrete 15
fill ~32 ~4 ~43 ~37 ~4 ~43 concrete 15
fill ~32 ~4 ~81 ~32 ~6 ~81 concrete 15
fill ~33 ~4 ~31 ~38 ~4 ~31 concrete 15
fill ~33 ~4 ~32 ~38 ~4 ~32 concrete 15
fill ~33 ~4 ~82 ~33 ~5 ~82 concrete 15
fill ~34 ~4 ~29 ~39 ~4 ~29 concrete 15
fill ~34 ~4 ~30 ~39 ~4 ~30 concrete 15
fill ~34 ~4 ~83 ~34 ~13 ~83 concrete 15
fill ~35 ~4 ~28 ~39 ~4 ~28 concrete 15
fill ~35 ~4 ~44 ~40 ~4 ~44 concrete 15
fill ~35 ~4 ~84 ~36 ~4 ~84 concrete 15
fill ~37 ~4 ~27 ~39 ~4 ~27 concrete 15
fill ~37 ~4 ~85 ~46 ~4 ~85 concrete 15
fill ~40 ~4 ~26 ~44 ~4 ~26 concrete 15
fill ~41 ~4 ~45 ~45 ~4 ~45 concrete 15
fill ~43 ~4 ~48 ~55 ~4 ~48 concrete 15
fill ~45 ~4 ~27 ~47 ~4 ~27 concrete 15
fill ~46 ~4 ~46 ~49 ~4 ~46 concrete 15
fill ~47 ~4 ~84 ~48 ~4 ~84 concrete 15
fill ~48 ~4 ~28 ~49 ~4 ~28 concrete 15
fill ~50 ~4 ~29 ~50 ~11 ~29 concrete 15
fill ~50 ~4 ~47 ~53 ~4 ~47 concrete 15
fill ~51 ~4 ~30 ~51 ~11 ~30 concrete 15
fill ~52 ~4 ~31 ~52 ~11 ~31 concrete 15
fill ~53 ~4 ~32 ~53 ~10 ~32 concrete 15
fill ~53 ~4 ~33 ~53 ~13 ~33 concrete 15
fill ~54 ~4 ~34 ~54 ~10 ~34 concrete 15
fill ~54 ~4 ~35 ~54 ~13 ~35 concrete 15
fill ~54 ~4 ~49 ~55 ~4 ~49 concrete 15
fill ~55 ~4 ~47 ~55 ~16 ~47 concrete 15
fill ~55 ~4 ~68 ~55 ~4 ~74 concrete 15
fill ~56 ~4 ~67 ~56 ~8 ~67 concrete 15
fill ~61 ~4 ~44 ~77 ~4 ~44 concrete 15
fill ~61 ~4 ~45 ~71 ~4 ~45 concrete 15
fill ~61 ~4 ~46 ~67 ~4 ~46 concrete 15
fill ~61 ~4 ~47 ~61 ~13 ~47 concrete 15
fill ~61 ~4 ~50 ~62 ~4 ~50 concrete 15
fill ~61 ~4 ~51 ~61 ~11 ~51 concrete 15
fill ~61 ~4 ~52 ~61 ~10 ~52 concrete 15
fill ~61 ~4 ~53 ~61 ~9 ~53 concrete 15
fill ~61 ~4 ~54 ~61 ~9 ~54 concrete 15
fill ~61 ~4 ~55 ~61 ~9 ~55 concrete 15
fill ~61 ~4 ~56 ~61 ~8 ~56 concrete 15
fill ~61 ~4 ~57 ~61 ~8 ~57 concrete 15
fill ~61 ~4 ~58 ~61 ~9 ~58 concrete 15
fill ~61 ~4 ~59 ~61 ~9 ~59 concrete 15
fill ~62 ~4 ~40 ~69 ~4 ~40 concrete 15
fill ~62 ~4 ~41 ~75 ~4 ~41 concrete 15
fill ~62 ~4 ~42 ~78 ~4 ~42 concrete 15
fill ~62 ~4 ~43 ~81 ~4 ~43 concrete 15
fill ~63 ~4 ~49 ~86 ~4 ~49 concrete 15
fill ~64 ~4 ~80 ~64 ~11 ~80 concrete 15
fill ~67 ~4 ~83 ~68 ~4 ~83 concrete 15
fill ~69 ~4 ~84 ~70 ~4 ~84 concrete 15
fill ~70 ~4 ~50 ~87 ~4 ~50 concrete 15
fill ~71 ~4 ~48 ~86 ~4 ~48 concrete 15
fill ~71 ~4 ~85 ~79 ~4 ~85 concrete 15
fill ~72 ~4 ~51 ~87 ~4 ~51 concrete 15
fill ~75 ~4 ~52 ~87 ~4 ~52 concrete 15
fill ~78 ~4 ~53 ~87 ~4 ~53 concrete 15
fill ~80 ~4 ~84 ~82 ~4 ~84 concrete 15
fill ~81 ~4 ~47 ~86 ~4 ~47 concrete 15
fill ~82 ~4 ~54 ~88 ~4 ~54 concrete 15
fill ~83 ~4 ~83 ~83 ~14 ~83 concrete 15
fill ~87 ~4 ~55 ~88 ~4 ~55 concrete 15
fill ~87 ~4 ~79 ~87 ~13 ~79 concrete 15
fill ~88 ~4 ~56 ~88 ~9 ~56 concrete 15
fill ~88 ~4 ~57 ~88 ~10 ~57 concrete 15
fill ~88 ~4 ~58 ~88 ~10 ~58 concrete 15
fill ~88 ~4 ~59 ~88 ~11 ~59 concrete 15
fill ~88 ~4 ~60 ~88 ~12 ~60 concrete 15
fill ~88 ~4 ~61 ~88 ~12 ~61 concrete 15
fill ~88 ~4 ~62 ~88 ~13 ~62 concrete 15
fill ~88 ~4 ~63 ~88 ~4 ~54 concrete 15
setblock ~88 ~4 ~72 concrete 15
fill ~89 ~4 ~64 ~89 ~10 ~64 concrete 15
fill ~89 ~4 ~71 ~89 ~12 ~71 concrete 15
fill ~28 ~5 ~59 ~28 ~6 ~59 concrete 15
fill ~28 ~5 ~60 ~28 ~8 ~60 concrete 15
fill ~28 ~5 ~61 ~28 ~9 ~61 concrete 15
fill ~28 ~5 ~62 ~28 ~10 ~62 concrete 15
fill ~28 ~5 ~63 ~28 ~10 ~63 concrete 15
fill ~28 ~5 ~64 ~28 ~11 ~64 concrete 15
fill ~28 ~5 ~65 ~28 ~12 ~65 concrete 15
fill ~28 ~5 ~66 ~28 ~12 ~66 concrete 15
fill ~28 ~5 ~67 ~28 ~12 ~67 concrete 15
fill ~29 ~5 ~51 ~29 ~5 ~58 concrete 15
fill ~30 ~5 ~47 ~30 ~4 ~47 concrete 15
fill ~30 ~5 ~48 ~30 ~6 ~48 concrete 15
fill ~30 ~5 ~49 ~30 ~7 ~49 concrete 15
fill ~30 ~5 ~50 ~30 ~8 ~50 concrete 15
fill ~31 ~5 ~46 ~39 ~5 ~46 concrete 15
fill ~32 ~5 ~33 ~32 ~4 ~33 concrete 15
fill ~32 ~5 ~34 ~32 ~6 ~34 concrete 15
fill ~32 ~5 ~35 ~32 ~7 ~35 concrete 15
fill ~32 ~5 ~36 ~32 ~7 ~36 concrete 15
fill ~32 ~5 ~37 ~32 ~8 ~37 concrete 15
fill ~32 ~5 ~38 ~32 ~8 ~38 concrete 15
fill ~32 ~5 ~39 ~32 ~7 ~39 concrete 15
fill ~32 ~5 ~40 ~32 ~7 ~40 concrete 15
fill ~32 ~5 ~41 ~32 ~6 ~41 concrete 15
fill ~32 ~5 ~42 ~32 ~6 ~42 concrete 15
fill ~32 ~5 ~43 ~33 ~5 ~43 concrete 15
fill ~32 ~5 ~82 ~32 ~10 ~82 concrete 15
fill ~33 ~5 ~31 ~33 ~8 ~31 concrete 15
fill ~33 ~5 ~32 ~33 ~10 ~32 concrete 15
fill ~34 ~5 ~29 ~34 ~4 ~29 concrete 15
fill ~34 ~5 ~30 ~34 ~11 ~30 concrete 15
fill ~34 ~5 ~44 ~38 ~5 ~44 concrete 15
fill ~35 ~5 ~28 ~36 ~5 ~28 concrete 15
fill ~35 ~5 ~84 ~36 ~5 ~84 concrete 15
fill ~37 ~5 ~27 ~39 ~5 ~27 concrete 15
fill ~37 ~5 ~85 ~45 ~5 ~85 concrete 15
fill ~39 ~5 ~45 ~42 ~5 ~45 concrete 15
fill ~40 ~5 ~26 ~44 ~5 ~26 concrete 15
fill ~40 ~5 ~47 ~51 ~5 ~47 concrete 15
fill ~43 ~5 ~46 ~47 ~5 ~46 concrete 15
fill ~45 ~5 ~27 ~47 ~5 ~27 concrete 15
fill ~46 ~5 ~84 ~48 ~5 ~84 concrete 15
fill ~48 ~5 ~28 ~49 ~5 ~28 concrete 15
fill ~50 ~5 ~48 ~55 ~5 ~48 concrete 15
fill ~51 ~5 ~82 ~51 ~11 ~82 concrete 15
fill ~52 ~5 ~81 ~52 ~11 ~81 concrete 15
fill ~55 ~5 ~37 ~55 ~11 ~37 concrete 15
fill ~55 ~5 ~49 ~55 ~16 ~49 concrete 15
fill ~55 ~5 ~57 ~55 ~13 ~57 concrete 15
fill ~55 ~5 ~69 ~55 ~14 ~69 concrete 15
fill ~55 ~5 ~70 ~55 ~14 ~70 concrete 15
fill ~55 ~5 ~71 ~55 ~14 ~71 concrete 15
fill ~55 ~5 ~72 ~55 ~13 ~72 concrete 15
fill ~55 ~5 ~73 ~55 ~13 ~73 concrete 15
fill ~55 ~5 ~74 ~55 ~12 ~74 concrete 15
fill ~56 ~5 ~68 ~56 ~8 ~68 concrete 15
fill ~61 ~5 ~41 ~61 ~10 ~41 concrete 15
fill ~61 ~5 ~42 ~61 ~11 ~42 concrete 15
fill ~61 ~5 ~43 ~61 ~12 ~43 concrete 15
fill ~61 ~5 ~44 ~61 ~12 ~44 concrete 15
fill ~61 ~5 ~45 ~61 ~13 ~45 concrete 15
fill ~61 ~5 ~46 ~61 ~13 ~46 concrete 15
fill ~61 ~5 ~50 ~61 ~11 ~50 concrete 15
fill ~62 ~5 ~36 ~85 ~5 ~36 concrete 15
fill ~62 ~5 ~37 ~85 ~5 ~37 concrete 15
fill ~62 ~5 ~38 ~85 ~5 ~38 concrete 15
fill ~62 ~5 ~39 ~85 ~5 ~39 concrete 15
fill ~62 ~5 ~40 ~62 ~6 ~40 concrete 15
fill ~62 ~5 ~47 ~65 ~5 ~47 concrete 15
fill ~62 ~5 ~49 ~66 ~5 ~49 concrete 15
fill ~63 ~5 ~34 ~84 ~5 ~34 concrete 15
fill ~63 ~5 ~35 ~84 ~5 ~35 concrete 15
fill ~64 ~5 ~32 ~83 ~5 ~32 concrete 15
fill ~64 ~5 ~33 ~84 ~5 ~33 concrete 15
fill ~65 ~5 ~31 ~83 ~5 ~31 concrete 15
fill ~66 ~5 ~46 ~70 ~5 ~46 concrete 15
fill ~67 ~5 ~48 ~73 ~5 ~48 concrete 15
fill ~67 ~5 ~83 ~68 ~5 ~83 concrete 15
fill ~68 ~5 ~30 ~82 ~5 ~30 concrete 15
fill ~69 ~5 ~84 ~70 ~5 ~84 concrete 15
fill ~70 ~5 ~40 ~85 ~5 ~40 concrete 15
fill ~71 ~5 ~45 ~76 ~5 ~45 concrete 15
fill ~71 ~5 ~85 ~79 ~5 ~85 concrete 15
fill ~74 ~5 ~47 ~81 ~5 ~47 concrete 15
fill ~75 ~5 ~29 ~81 ~5 ~29 concrete 15
fill ~76 ~5 ~41 ~85 ~5 ~41 concrete 15
fill ~77 ~5 ~44 ~81 ~5 ~44 concrete 15
fill ~79 ~5 ~42 ~85 ~5 ~42 concrete 15
fill ~80 ~5 ~28 ~80 ~14 ~28 concrete 15
fill ~80 ~5 ~84 ~82 ~5 ~84 concrete 15
fill ~82 ~5 ~43 ~85 ~5 ~43 concrete 15
fill ~82 ~5 ~46 ~86 ~5 ~46 concrete 15
fill ~86 ~5 ~47 ~86 ~6 ~47 concrete 15
fill ~87 ~5 ~48 ~87 ~5 ~53 concrete 15
fill ~88 ~5 ~54 ~88 ~5 ~62 concrete 15
fill ~88 ~5 ~77 ~88 ~13 ~77 concrete 15
fill ~89 ~5 ~63 ~89 ~9 ~63 concrete 15
fill ~89 ~5 ~72 ~89 ~12 ~72 concrete 15
fill ~28 ~6 ~74 ~28 ~11 ~74 concrete 15
fill ~29 ~6 ~52 ~29 ~6 ~58 concrete 15
fill ~30 ~6 ~51 ~30 ~9 ~51 concrete 15
fill ~31 ~6 ~46 ~31 ~5 ~46 concrete 15
fill ~31 ~6 ~47 ~31 ~7 ~47 concrete 15
fill ~32 ~6 ~43 ~32 ~4 ~43 concrete 15
fill ~32 ~6 ~45 ~41 ~6 ~45 concrete 15
fill ~33 ~6 ~33 ~33 ~13 ~33 concrete 15
fill ~33 ~6 ~44 ~36 ~6 ~44 concrete 15
fill ~33 ~6 ~83 ~33 ~9 ~83 concrete 15
fill ~35 ~6 ~29 ~35 ~12 ~29 concrete 15
fill ~35 ~6 ~84 ~37 ~6 ~84 concrete 15
fill ~36 ~6 ~28 ~36 ~12 ~28 concrete 15
fill ~37 ~6 ~27 ~39 ~6 ~27 concrete 15
fill ~37 ~6 ~46 ~44 ~6 ~46 concrete 15
fill ~38 ~6 ~85 ~45 ~6 ~85 concrete 15
fill ~40 ~6 ~26 ~44 ~6 ~26 concrete 15
fill ~45 ~6 ~27 ~47 ~6 ~27 concrete 15
fill ~46 ~6 ~84 ~48 ~6 ~84 concrete 15
fill ~48 ~6 ~28 ~49 ~6 ~28 concrete 15
fill ~55 ~6 ~48 ~55 ~16 ~48 concrete 15
fill ~55 ~6 ~58 ~55 ~13 ~58 concrete 15
fill ~55 ~6 ~75 ~55 ~11 ~75 concrete 15
fill ~61 ~6 ~48 ~69 ~6 ~48 concrete 15
fill ~61 ~6 ~49 ~62 ~6 ~49 concrete 15
fill ~62 ~6 ~36 ~62 ~11 ~36 concrete 15
fill ~62 ~6 ~37 ~62 ~13 ~37 concrete 15
fill ~62 ~6 ~38 ~62 ~14 ~38 concrete 15
fill ~62 ~6 ~39 ~62 ~15 ~39 concrete 15
fill ~63 ~6 ~33 ~63 ~10 ~33 concrete 15
fill ~63 ~6 ~34 ~63 ~12 ~34 concrete 15
fill ~63 ~6 ~35 ~63 ~5 ~35 concrete 15
fill ~64 ~6 ~31 ~64 ~8 ~31 concrete 15
fill ~64 ~6 ~32 ~64 ~12 ~32 concrete 15
fill ~65 ~6 ~30 ~67 ~6 ~30 concrete 15
fill ~65 ~6 ~47 ~68 ~6 ~47 concrete 15
fill ~66 ~6 ~29 ~74 ~6 ~29 concrete 15
fill ~67 ~6 ~28 ~81 ~6 ~28 concrete 15
fill ~67 ~6 ~83 ~68 ~6 ~83 concrete 15
fill ~69 ~6 ~27 ~79 ~6 ~27 concrete 15
fill ~69 ~6 ~46 ~73 ~6 ~46 concrete 15
fill ~69 ~6 ~84 ~70 ~6 ~84 concrete 15
fill ~70 ~6 ~47 ~76 ~6 ~47 concrete 15
fill ~71 ~6 ~85 ~80 ~6 ~85 concrete 15
fill ~73 ~6 ~26 ~76 ~6 ~26 concrete 15
fill ~74 ~6 ~45 ~78 ~6 ~45 concrete 15
fill ~77 ~6 ~46 ~83 ~6 ~46 concrete 15
fill ~79 ~6 ~44 ~84 ~6 ~44 concrete 15
fill ~81 ~6 ~84 ~82 ~6 ~84 concrete 15
fill ~82 ~6 ~29 ~82 ~10 ~29 concrete 15
fill ~83 ~6 ~30 ~83 ~8 ~30 concrete 15
fill ~83 ~6 ~31 ~83 ~13 ~31 concrete 15
fill ~84 ~6 ~32 ~84 ~7 ~32 concrete 15
fill ~84 ~6 ~33 ~84 ~11 ~33 concrete 15
fill ~84 ~6 ~34 ~84 ~15 ~34 concrete 15
fill ~84 ~6 ~35 ~84 ~17 ~35 concrete 15
fill ~84 ~6 ~36 ~84 ~18 ~36 concrete 15
fill ~84 ~6 ~42 ~84 ~13 ~42 concrete 15
fill ~84 ~6 ~43 ~84 ~12 ~43 concrete 15
fill ~84 ~6 ~45 ~85 ~6 ~45 concrete 15
fill ~84 ~6 ~83 ~84 ~12 ~83 concrete 15
fill ~85 ~6 ~37 ~85 ~6 ~41 concrete 15
fill ~85 ~6 ~46 ~85 ~8 ~46 concrete 15
fill ~85 ~6 ~82 ~85 ~13 ~82 concrete 15
fill ~86 ~6 ~48 ~86 ~8 ~48 concrete 15
fill ~86 ~6 ~81 ~86 ~12 ~81 concrete 15
fill ~87 ~6 ~49 ~87 ~6 ~54 concrete 15
fill ~88 ~6 ~55 ~88 ~7 ~55 concrete 15
fill ~89 ~6 ~73 ~89 ~12 ~73 concrete 15
fill ~29 ~7 ~53 ~29 ~7 ~59 concrete 15
fill ~30 ~7 ~52 ~30 ~10 ~52 concrete 15
fill ~31 ~7 ~48 ~31 ~8 ~48 concrete 15
fill ~31 ~7 ~81 ~31 ~12 ~81 concrete 15
fill ~32 ~7 ~45 ~32 ~6 ~45 concrete 15
fill ~32 ~7 ~46 ~32 ~15 ~46 concrete 15
fill ~33 ~7 ~34 ~33 ~15 ~34 concrete 15
fill ~33 ~7 ~41 ~33 ~12 ~41 concrete 15
fill ~33 ~7 ~42 ~33 ~11 ~42 concrete 15
fill ~33 ~7 ~43 ~33 ~11 ~43 concrete 15
fill ~33 ~7 ~44 ~35 ~7 ~44 concrete 15
fill ~35 ~7 ~84 ~37 ~7 ~84 concrete 15
fill ~37 ~7 ~27 ~39 ~7 ~27 concrete 15
fill ~37 ~7 ~45 ~38 ~7 ~45 concrete 15
fill ~38 ~7 ~85 ~45 ~7 ~85 concrete 15
fill ~40 ~7 ~26 ~43 ~7 ~26 concrete 15
fill ~44 ~7 ~27 ~47 ~7 ~27 concrete 15
fill ~46 ~7 ~84 ~48 ~7 ~84 concrete 15
fill ~48 ~7 ~28 ~49 ~7 ~28 concrete 15
fill ~54 ~7 ~78 ~54 ~10 ~78 concrete 15
fill ~55 ~7 ~59 ~55 ~13 ~59 concrete 15
setblock ~61 ~7 ~40 concrete 15
fill ~61 ~7 ~48 ~61 ~12 ~48 concrete 15
fill ~61 ~7 ~49 ~61 ~12 ~49 concrete 15
setblock ~62 ~7 ~35 concrete 15
setblock ~64 ~7 ~48 concrete 15
fill ~65 ~7 ~30 ~65 ~9 ~30 concrete 15
fill ~66 ~7 ~29 ~67 ~7 ~29 concrete 15
fill ~67 ~7 ~83 ~68 ~7 ~83 concrete 15
fill ~68 ~7 ~28 ~68 ~10 ~28 concrete 15
fill ~69 ~7 ~27 ~72 ~7 ~27 concrete 15
fill ~69 ~7 ~47 ~72 ~7 ~47 concrete 15
fill ~69 ~7 ~84 ~70 ~7 ~84 concrete 15
fill ~71 ~7 ~85 ~80 ~7 ~85 concrete 15
fill ~72 ~7 ~46 ~78 ~7 ~46 concrete 15
fill ~73 ~7 ~26 ~76 ~7 ~26 concrete 15
fill ~77 ~7 ~27 ~79 ~7 ~27 concrete 15
fill ~77 ~7 ~45 ~84 ~7 ~45 concrete 15
fill ~81 ~7 ~28 ~81 ~10 ~28 concrete 15
fill ~81 ~7 ~44 ~83 ~7 ~44 concrete 15
fill ~81 ~7 ~84 ~82 ~7 ~84 concrete 15
fill ~84 ~7 ~37 ~84 ~19 ~37 concrete 15
fill ~84 ~7 ~38 ~84 ~19 ~38 concrete 15
fill ~84 ~7 ~39 ~84 ~19 ~39 concrete 15
fill ~84 ~7 ~40 ~84 ~19 ~40 concrete 15
fill ~84 ~7 ~41 ~84 ~14 ~41 concrete 15
fill ~85 ~7 ~47 ~85 ~16 ~47 concrete 15
fill ~86 ~7 ~49 ~86 ~9 ~49 concrete 15
fill ~87 ~7 ~50 ~87 ~7 ~54 concrete 15
fill ~88 ~7 ~78 ~88 ~12 ~78 concrete 15
fill ~89 ~7 ~74 ~89 ~11 ~74 concrete 15
fill ~29 ~8 ~54 ~29 ~8 ~59 concrete 15
setblock ~29 ~8 ~78 concrete 15
fill ~30 ~8 ~53 ~30 ~11 ~53 concrete 15
fill ~31 ~8 ~49 ~31 ~10 ~49 concrete 15
fill ~32 ~8 ~47 ~32 ~15 ~47 concrete 15
fill ~33 ~8 ~35 ~33 ~16 ~35 concrete 15
fill ~33 ~8 ~36 ~33 ~17 ~36 concrete 15
fill ~33 ~8 ~39 ~33 ~18 ~39 concrete 15
fill ~33 ~8 ~40 ~33 ~18 ~40 concrete 15
fill ~33 ~8 ~44 ~33 ~10 ~44 concrete 15
fill ~33 ~8 ~45 ~33 ~9 ~45 concrete 15
fill ~35 ~8 ~84 ~37 ~8 ~84 concrete 15
fill ~37 ~8 ~27 ~40 ~8 ~27 concrete 15
fill ~38 ~8 ~85 ~45 ~8 ~85 concrete 15
fill ~41 ~8 ~26 ~43 ~8 ~26 concrete 15
fill ~44 ~8 ~27 ~47 ~8 ~27 concrete 15
fill ~46 ~8 ~84 ~48 ~8 ~84 concrete 15
fill ~48 ~8 ~28 ~49 ~8 ~28 concrete 15
fill ~55 ~8 ~60 ~55 ~13 ~60 concrete 15
fill ~55 ~8 ~61 ~55 ~13 ~61 concrete 15
fill ~55 ~8 ~62 ~55 ~13 ~62 concrete 15
fill ~62 ~8 ~40 ~62 ~16 ~40 concrete 15
fill ~62 ~8 ~71 ~62 ~13 ~71 concrete 15
fill ~63 ~8 ~35 ~63 ~14 ~35 concrete 15
fill ~66 ~8 ~29 ~67 ~8 ~29 concrete 15
fill ~67 ~8 ~83 ~68 ~8 ~83 concrete 15
fill ~69 ~8 ~28 ~69 ~12 ~28 concrete 15
fill ~69 ~8 ~84 ~70 ~8 ~84 concrete 15
fill ~70 ~8 ~27 ~74 ~8 ~27 concrete 15
fill ~71 ~8 ~85 ~80 ~8 ~85 concrete 15
setblock ~75 ~8 ~26 concrete 15
fill ~76 ~8 ~27 ~79 ~8 ~27 concrete 15
fill ~81 ~8 ~84 ~82 ~8 ~84 concrete 15
fill ~83 ~8 ~32 ~83 ~17 ~32 concrete 15
fill ~84 ~8 ~44 ~84 ~12 ~44 concrete 15
fill ~84 ~8 ~45 ~84 ~11 ~45 concrete 15
fill ~86 ~8 ~50 ~86 ~10 ~50 concrete 15
fill ~87 ~8 ~51 ~87 ~8 ~55 concrete 15
fill ~87 ~8 ~80 ~87 ~12 ~80 concrete 15
fill ~29 ~9 ~55 ~29 ~9 ~60 concrete 15
fill ~30 ~9 ~54 ~30 ~11 ~54 concrete 15
fill ~30 ~9 ~78 ~30 ~15 ~78 concrete 15
fill ~31 ~9 ~50 ~31 ~11 ~50 concrete 15
fill ~32 ~9 ~48 ~32 ~15 ~48 concrete 15
fill ~33 ~9 ~37 ~33 ~17 ~37 concrete 15
fill ~33 ~9 ~38 ~33 ~18 ~38 concrete 15
fill ~34 ~9 ~31 ~34 ~14 ~31 concrete 15
fill ~35 ~9 ~84 ~37 ~9 ~84 concrete 15
fill ~37 ~9 ~27 ~40 ~9 ~27 concrete 15
fill ~38 ~9 ~85 ~45 ~9 ~85 concrete 15
fill ~41 ~9 ~26 ~42 ~9 ~26 concrete 15
fill ~43 ~9 ~27 ~47 ~9 ~27 concrete 15
fill ~46 ~9 ~84 ~48 ~9 ~84 concrete 15
fill ~48 ~9 ~28 ~49 ~9 ~28 concrete 15
fill ~55 ~9 ~63 ~55 ~13 ~63 concrete 15
fill ~55 ~9 ~64 ~55 ~13 ~64 concrete 15
fill ~55 ~9 ~65 ~55 ~13 ~65 concrete 15
fill ~55 ~9 ~66 ~55 ~13 ~66 concrete 15
fill ~55 ~9 ~67 ~55 ~14 ~67 concrete 15
fill ~55 ~9 ~68 ~55 ~14 ~68 concrete 15
fill ~62 ~9 ~56 ~62 ~14 ~56 concrete 15
fill ~62 ~9 ~57 ~62 ~13 ~57 concrete 15
fill ~62 ~9 ~70 ~62 ~13 ~70 concrete 15
fill ~65 ~9 ~31 ~65 ~12 ~31 concrete 15
fill ~66 ~9 ~30 ~66 ~12 ~30 concrete 15
fill ~67 ~9 ~29 ~67 ~12 ~29 concrete 15
fill ~67 ~9 ~83 ~68 ~9 ~83 concrete 15
fill ~69 ~9 ~84 ~70 ~9 ~84 concrete 15
fill ~70 ~9 ~27 ~79 ~9 ~27 concrete 15
fill ~71 ~9 ~85 ~80 ~9 ~85 concrete 15
fill ~81 ~9 ~84 ~82 ~9 ~84 concrete 15
fill ~82 ~9 ~30 ~82 ~15 ~30 concrete 15
fill ~84 ~9 ~46 ~84 ~10 ~46 concrete 15
fill ~85 ~9 ~48 ~85 ~16 ~48 concrete 15
fill ~86 ~9 ~51 ~86 ~11 ~51 concrete 15
fill ~87 ~9 ~52 ~87 ~9 ~55 concrete 15
fill ~29 ~10 ~56 ~29 ~10 ~61 concrete 15
fill ~30 ~10 ~55 ~30 ~12 ~55 concrete 15
fill ~31 ~10 ~51 ~31 ~12 ~51 concrete 15
fill ~32 ~10 ~45 ~32 ~15 ~45 concrete 15
fill ~33 ~10 ~82 ~33 ~14 ~82 concrete 15
fill ~35 ~10 ~84 ~37 ~10 ~84 concrete 15
fill ~37 ~10 ~28 ~37 ~15 ~28 concrete 15
fill ~38 ~10 ~27 ~46 ~10 ~27 concrete 15
fill ~38 ~10 ~85 ~44 ~10 ~85 concrete 15
fill ~45 ~10 ~84 ~47 ~10 ~84 concrete 15
fill ~47 ~10 ~28 ~48 ~10 ~28 concrete 15
fill ~48 ~10 ~83 ~48 ~15 ~83 concrete 15
fill ~49 ~10 ~29 ~49 ~13 ~29 concrete 15
fill ~62 ~10 ~53 ~62 ~15 ~53 concrete 15
fill ~62 ~10 ~54 ~62 ~15 ~54 concrete 15
fill ~62 ~10 ~55 ~62 ~14 ~55 concrete 15
fill ~62 ~10 ~58 ~62 ~13 ~58 concrete 15
fill ~62 ~10 ~59 ~62 ~13 ~59 concrete 15
fill ~62 ~10 ~60 ~62 ~13 ~60 concrete 15
fill ~62 ~10 ~61 ~62 ~13 ~61 concrete 15
fill ~62 ~10 ~62 ~62 ~13 ~62 concrete 15
fill ~62 ~10 ~63 ~62 ~13 ~63 concrete 15
fill ~62 ~10 ~64 ~62 ~13 ~64 concrete 15
fill ~62 ~10 ~65 ~62 ~13 ~65 concrete 15
fill ~62 ~10 ~66 ~62 ~13 ~66 concrete 15
fill ~62 ~10 ~67 ~62 ~13 ~67 concrete 15
fill ~62 ~10 ~68 ~62 ~13 ~68 concrete 15
fill ~62 ~10 ~69 ~62 ~13 ~69 concrete 15
fill ~67 ~10 ~83 ~68 ~10 ~83 concrete 15
fill ~69 ~10 ~84 ~70 ~10 ~84 concrete 15
fill ~70 ~10 ~28 ~70 ~14 ~28 concrete 15
fill ~71 ~10 ~27 ~79 ~10 ~27 concrete 15
fill ~71 ~10 ~85 ~80 ~10 ~85 concrete 15
fill ~81 ~10 ~84 ~82 ~10 ~84 concrete 15
fill ~85 ~10 ~49 ~85 ~16 ~49 concrete 15
fill ~86 ~10 ~52 ~86 ~12 ~52 concrete 15
fill ~87 ~10 ~53 ~87 ~10 ~56 concrete 15
fill ~88 ~10 ~63 ~88 ~13 ~63 concrete 15
fill ~29 ~11 ~57 ~29 ~11 ~63 concrete 15
fill ~30 ~11 ~56 ~30 ~13 ~56 concrete 15
fill ~31 ~11 ~52 ~31 ~13 ~52 concrete 15
fill ~32 ~11 ~44 ~32 ~15 ~44 concrete 15
fill ~32 ~11 ~49 ~32 ~15 ~49 concrete 15
fill ~32 ~11 ~81 ~32 ~15 ~81 concrete 15
fill ~34 ~11 ~32 ~34 ~16 ~32 concrete 15
fill ~35 ~11 ~83 ~35 ~15 ~83 concrete 15
fill ~36 ~11 ~84 ~38 ~11 ~84 concrete 15
fill ~38 ~11 ~27 ~46 ~11 ~27 concrete 15
fill ~39 ~11 ~85 ~44 ~11 ~85 concrete 15
fill ~43 ~11 ~43 ~48 ~11 ~43 concrete 15
fill ~43 ~11 ~44 ~48 ~11 ~44 concrete 15
fill ~44 ~11 ~42 ~47 ~11 ~42 concrete 15
fill ~44 ~11 ~45 ~47 ~11 ~45 concrete 15
fill ~44 ~11 ~46 ~47 ~11 ~46 concrete 15
fill ~45 ~11 ~41 ~46 ~11 ~41 concrete 15
fill ~45 ~11 ~84 ~47 ~11 ~84 concrete 15
fill ~47 ~11 ~28 ~48 ~11 ~28 concrete 15
fill ~52 ~11 ~32 ~52 ~14 ~32 concrete 15
fill ~53 ~11 ~34 ~53 ~15 ~34 concrete 15
fill ~53 ~11 ~78 ~53 ~15 ~78 concrete 15
fill ~62 ~11 ~41 ~62 ~17 ~41 concrete 15
fill ~62 ~11 ~52 ~62 ~16 ~52 concrete 15
fill ~63 ~11 ~75 ~63 ~14 ~75 concrete 15
fill ~64 ~11 ~33 ~64 ~14 ~33 concrete 15
fill ~67 ~11 ~83 ~68 ~11 ~83 concrete 15
fill ~68 ~11 ~29 ~68 ~14 ~29 concrete 15
fill ~69 ~11 ~84 ~71 ~11 ~84 concrete 15
fill ~71 ~11 ~27 ~78 ~11 ~27 concrete 15
fill ~72 ~11 ~85 ~79 ~11 ~85 concrete 15
fill ~79 ~11 ~28 ~79 ~16 ~28 concrete 15
fill ~80 ~11 ~84 ~82 ~11 ~84 concrete 15
fill ~81 ~11 ~29 ~81 ~15 ~29 concrete 15
fill ~85 ~11 ~46 ~85 ~16 ~46 concrete 15
fill ~85 ~11 ~50 ~85 ~16 ~50 concrete 15
fill ~86 ~11 ~53 ~86 ~13 ~53 concrete 15
fill ~87 ~11 ~54 ~87 ~11 ~58 concrete 15
fill ~88 ~11 ~64 ~88 ~13 ~64 concrete 15
fill ~29 ~12 ~59 ~29 ~12 ~64 concrete 15
fill ~29 ~12 ~74 ~29 ~15 ~74 concrete 15
fill ~30 ~12 ~57 ~30 ~13 ~57 concrete 15
fill ~30 ~12 ~58 ~30 ~14 ~58 concrete 15
fill ~31 ~12 ~53 ~31 ~13 ~53 concrete 15
fill ~31 ~12 ~54 ~31 ~14 ~54 concrete 15
fill ~32 ~12 ~42 ~32 ~14 ~42 concrete 15
fill ~32 ~12 ~43 ~32 ~14 ~43 concrete 15
fill ~32 ~12 ~50 ~32 ~15 ~50 concrete 15
fill ~35 ~12 ~30 ~35 ~16 ~30 concrete 15
fill ~36 ~12 ~84 ~39 ~12 ~84 concrete 15
fill ~38 ~12 ~27 ~45 ~12 ~27 concrete 15
fill ~40 ~12 ~85 ~43 ~12 ~85 concrete 15
fill ~41 ~12 ~41 ~44 ~12 ~41 concrete 15
fill ~41 ~12 ~42 ~43 ~12 ~42 concrete 15
fill ~41 ~12 ~43 ~42 ~12 ~43 concrete 15
fill ~41 ~12 ~44 ~42 ~12 ~44 concrete 15
fill ~41 ~12 ~45 ~43 ~12 ~45 concrete 15
fill ~41 ~12 ~46 ~43 ~12 ~46 concrete 15
fill ~42 ~12 ~40 ~48 ~12 ~40 concrete 15
fill ~42 ~12 ~47 ~49 ~12 ~47 concrete 15
fill ~42 ~12 ~48 ~49 ~12 ~48 concrete 15
fill ~43 ~12 ~39 ~47 ~12 ~39 concrete 15
fill ~44 ~12 ~49 ~47 ~12 ~49 concrete 15
fill ~44 ~12 ~84 ~47 ~12 ~84 concrete 15
fill ~46 ~12 ~28 ~48 ~12 ~28 concrete 15
fill ~47 ~12 ~41 ~49 ~12 ~41 concrete 15
fill ~48 ~12 ~42 ~49 ~12 ~42 concrete 15
fill ~48 ~12 ~45 ~50 ~12 ~45 concrete 15
fill ~48 ~12 ~46 ~50 ~12 ~46 concrete 15
fill ~49 ~12 ~43 ~50 ~12 ~43 concrete 15
fill ~49 ~12 ~44 ~50 ~12 ~44 concrete 15
fill ~50 ~12 ~30 ~50 ~14 ~30 concrete 15
fill ~51 ~12 ~31 ~51 ~14 ~31 concrete 15
fill ~51 ~12 ~81 ~51 ~14 ~81 concrete 15
fill ~54 ~12 ~37 ~54 ~16 ~37 concrete 15
fill ~54 ~12 ~75 ~54 ~15 ~75 concrete 15
fill ~62 ~12 ~42 ~62 ~17 ~42 concrete 15
fill ~62 ~12 ~50 ~62 ~16 ~50 concrete 15
fill ~62 ~12 ~51 ~62 ~16 ~51 concrete 15
fill ~63 ~12 ~36 ~63 ~16 ~36 concrete 15
fill ~63 ~12 ~74 ~63 ~14 ~74 concrete 15
fill ~64 ~12 ~78 ~64 ~14 ~78 concrete 15
fill ~65 ~12 ~80 ~65 ~14 ~80 concrete 15
fill ~66 ~12 ~81 ~66 ~14 ~81 concrete 15
fill ~67 ~12 ~82 ~67 ~14 ~82 concrete 15
fill ~68 ~12 ~83 ~68 ~13 ~83 concrete 15
fill ~69 ~12 ~84 ~72 ~12 ~84 concrete 15
fill ~71 ~12 ~28 ~71 ~15 ~28 concrete 15
fill ~72 ~12 ~27 ~78 ~12 ~27 concrete 15
fill ~72 ~12 ~44 ~72 ~12 ~46 concrete 15
fill ~73 ~12 ~45 ~73 ~12 ~46 concrete 15
fill ~73 ~12 ~85 ~79 ~12 ~85 concrete 15
fill ~80 ~12 ~84 ~82 ~12 ~84 concrete 15
fill ~83 ~12 ~33 ~83 ~19 ~33 concrete 15
fill ~85 ~12 ~45 ~85 ~16 ~45 concrete 15
fill ~85 ~12 ~51 ~85 ~16 ~51 concrete 15
fill ~86 ~12 ~54 ~86 ~14 ~54 concrete 15
fill ~87 ~12 ~55 ~87 ~12 ~59 concrete 15
fill ~88 ~12 ~65 ~88 ~14 ~65 concrete 15
fill ~88 ~12 ~66 ~88 ~14 ~66 concrete 15
fill ~88 ~12 ~74 ~88 ~14 ~74 concrete 15
fill ~29 ~13 ~60 ~29 ~13 ~67 concrete 15
fill ~29 ~13 ~73 ~29 ~15 ~73 concrete 15
fill ~30 ~13 ~59 ~30 ~14 ~59 concrete 15
fill ~31 ~13 ~55 ~31 ~14 ~55 concrete 15
setblock ~32 ~13 ~41 concrete 15
fill ~32 ~13 ~51 ~32 ~15 ~51 concrete 15
fill ~36 ~13 ~29 ~36 ~16 ~29 concrete 15
fill ~36 ~13 ~84 ~46 ~13 ~84 concrete 15
fill ~38 ~13 ~28 ~38 ~17 ~28 concrete 15
fill ~39 ~13 ~27 ~44 ~13 ~27 concrete 15
fill ~39 ~13 ~43 ~40 ~13 ~43 concrete 15
fill ~39 ~13 ~44 ~40 ~13 ~44 concrete 15
fill ~39 ~13 ~45 ~40 ~13 ~45 concrete 15
fill ~40 ~13 ~40 ~41 ~13 ~40 concrete 15
fill ~40 ~13 ~41 ~40 ~13 ~48 concrete 15
fill ~41 ~13 ~38 ~48 ~13 ~38 concrete 15
fill ~41 ~13 ~39 ~42 ~13 ~39 concrete 15
fill ~41 ~13 ~47 ~41 ~13 ~49 concrete 15
fill ~42 ~13 ~49 ~43 ~13 ~49 concrete 15
fill ~42 ~13 ~50 ~49 ~13 ~50 concrete 15
fill ~43 ~13 ~37 ~46 ~13 ~37 concrete 15
fill ~44 ~13 ~51 ~47 ~13 ~51 concrete 15
fill ~45 ~13 ~28 ~47 ~13 ~28 concrete 15
fill ~47 ~13 ~83 ~47 ~16 ~83 concrete 15
fill ~48 ~13 ~29 ~48 ~15 ~29 concrete 15
fill ~48 ~13 ~39 ~49 ~13 ~39 concrete 15
fill ~48 ~13 ~49 ~50 ~13 ~49 concrete 15
fill ~49 ~13 ~40 ~50 ~13 ~40 concrete 15
fill ~50 ~13 ~41 ~50 ~13 ~42 concrete 15
fill ~50 ~13 ~47 ~51 ~13 ~47 concrete 15
fill ~50 ~13 ~48 ~50 ~13 ~47 concrete 15
fill ~51 ~13 ~42 ~51 ~13 ~47 concrete 15
fill ~54 ~13 ~74 ~54 ~15 ~74 concrete 15
fill ~62 ~13 ~43 ~62 ~17 ~43 concrete 15
fill ~62 ~13 ~44 ~62 ~17 ~44 concrete 15
fill ~62 ~13 ~48 ~62 ~17 ~48 concrete 15
fill ~62 ~13 ~49 ~62 ~17 ~49 concrete 15
fill ~63 ~13 ~72 ~63 ~15 ~72 concrete 15
fill ~63 ~13 ~73 ~63 ~15 ~73 concrete 15
fill ~64 ~13 ~34 ~64 ~16 ~34 concrete 15
fill ~64 ~13 ~77 ~64 ~15 ~77 concrete 15
fill ~65 ~13 ~32 ~65 ~15 ~32 concrete 15
fill ~66 ~13 ~31 ~66 ~15 ~31 concrete 15
fill ~67 ~13 ~30 ~67 ~14 ~30 concrete 15
fill ~68 ~13 ~44 ~71 ~13 ~44 concrete 15
fill ~68 ~13 ~45 ~71 ~13 ~45 concrete 15
fill ~68 ~13 ~46 ~71 ~13 ~46 concrete 15
fill ~68 ~13 ~47 ~76 ~13 ~47 concrete 15
fill ~69 ~13 ~29 ~69 ~15 ~29 concrete 15
fill ~69 ~13 ~42 ~75 ~13 ~42 concrete 15
fill ~69 ~13 ~43 ~76 ~13 ~43 concrete 15
fill ~69 ~13 ~48 ~76 ~13 ~48 concrete 15
fill ~69 ~13 ~49 ~75 ~13 ~49 concrete 15
fill ~69 ~13 ~83 ~69 ~15 ~83 concrete 15
fill ~70 ~13 ~41 ~75 ~13 ~41 concrete 15
fill ~70 ~13 ~84 ~73 ~13 ~84 concrete 15
fill ~71 ~13 ~50 ~74 ~13 ~50 concrete 15
fill ~72 ~13 ~28 ~72 ~16 ~28 concrete 15
fill ~72 ~13 ~40 ~73 ~13 ~40 concrete 15
fill ~73 ~13 ~27 ~77 ~13 ~27 concrete 15
fill ~73 ~13 ~44 ~76 ~13 ~44 concrete 15
fill ~74 ~13 ~45 ~76 ~13 ~45 concrete 15
fill ~74 ~13 ~46 ~76 ~13 ~46 concrete 15
fill ~74 ~13 ~85 ~78 ~13 ~85 concrete 15
fill ~78 ~13 ~28 ~78 ~17 ~28 concrete 15
fill ~79 ~13 ~84 ~81 ~13 ~84 concrete 15
fill ~82 ~13 ~83 ~82 ~15 ~83 concrete 15
fill ~84 ~13 ~82 ~84 ~14 ~82 concrete 15
fill ~85 ~13 ~43 ~85 ~16 ~43 concrete 15
fill ~85 ~13 ~44 ~85 ~16 ~44 concrete 15
fill ~85 ~13 ~52 ~85 ~16 ~52 concrete 15
fill ~85 ~13 ~81 ~85 ~14 ~81 concrete 15
fill ~86 ~13 ~55 ~86 ~14 ~55 concrete 15
fill ~86 ~13 ~56 ~86 ~14 ~56 concrete 15
fill ~86 ~13 ~80 ~86 ~14 ~80 concrete 15
fill ~87 ~13 ~57 ~87 ~13 ~61 concrete 15
fill ~87 ~13 ~78 ~87 ~14 ~78 concrete 15
fill ~88 ~13 ~67 ~88 ~14 ~67 concrete 15
fill ~88 ~13 ~68 ~88 ~14 ~68 concrete 15
fill ~88 ~13 ~69 ~88 ~15 ~69 concrete 15
fill ~88 ~13 ~70 ~88 ~15 ~70 concrete 15
fill ~88 ~13 ~71 ~88 ~15 ~71 concrete 15
fill ~88 ~13 ~72 ~88 ~15 ~72 concrete 15
fill ~88 ~13 ~73 ~88 ~15 ~73 concrete 15
fill ~29 ~14 ~63 ~29 ~14 ~76 concrete 15
fill ~30 ~14 ~60 ~30 ~15 ~60 concrete 15
fill ~30 ~14 ~61 ~30 ~15 ~61 concrete 15
fill ~30 ~14 ~62 ~30 ~15 ~62 concrete 15
fill ~30 ~14 ~77 ~30 ~16 ~77 concrete 15
fill ~31 ~14 ~56 ~31 ~15 ~56 concrete 15
fill ~31 ~14 ~57 ~31 ~15 ~57 concrete 15
fill ~32 ~14 ~52 ~32 ~15 ~52 concrete 15
fill ~32 ~14 ~53 ~32 ~15 ~53 concrete 15
fill ~33 ~14 ~41 ~33 ~18 ~41 concrete 15
fill ~34 ~14 ~33 ~34 ~18 ~33 concrete 15
fill ~34 ~14 ~82 ~34 ~16 ~82 concrete 15
fill ~36 ~14 ~83 ~36 ~16 ~83 concrete 15
fill ~37 ~14 ~84 ~46 ~14 ~84 concrete 15
fill ~38 ~14 ~42 ~39 ~14 ~42 concrete 15
fill ~38 ~14 ~43 ~38 ~14 ~45 concrete 15
fill ~39 ~14 ~27 ~44 ~14 ~27 concrete 15
fill ~39 ~14 ~39 ~40 ~14 ~39 concrete 15
fill ~39 ~14 ~40 ~39 ~14 ~42 concrete 15
fill ~39 ~14 ~46 ~39 ~14 ~48 concrete 15
setblock ~40 ~14 ~38 concrete 15
fill ~40 ~14 ~49 ~40 ~14 ~50 concrete 15
fill ~41 ~14 ~37 ~42 ~14 ~37 concrete 15
fill ~41 ~14 ~50 ~41 ~14 ~51 concrete 15
fill ~42 ~14 ~36 ~46 ~14 ~36 concrete 15
fill ~42 ~14 ~51 ~43 ~14 ~51 concrete 15
fill ~43 ~14 ~52 ~48 ~14 ~52 concrete 15
fill ~45 ~14 ~28 ~46 ~14 ~28 concrete 15
fill ~47 ~14 ~29 ~47 ~16 ~29 concrete 15
fill ~47 ~14 ~37 ~48 ~14 ~37 concrete 15
fill ~48 ~14 ~51 ~50 ~14 ~51 concrete 15
fill ~49 ~14 ~30 ~49 ~16 ~30 concrete 15
setblock ~49 ~14 ~38 concrete 15
fill ~49 ~14 ~82 ~49 ~16 ~82 concrete 15
setblock ~50 ~14 ~39 concrete 15
setblock ~50 ~14 ~50 concrete 15
fill ~51 ~14 ~40 ~51 ~15 ~40 concrete 15
fill ~51 ~14 ~41 ~51 ~14 ~40 concrete 15
fill ~51 ~14 ~48 ~51 ~14 ~49 concrete 15
fill ~52 ~14 ~33 ~52 ~16 ~33 concrete 15
fill ~52 ~14 ~42 ~52 ~15 ~42 concrete 15
fill ~52 ~14 ~43 ~52 ~14 ~47 concrete 15
fill ~52 ~14 ~79 ~52 ~16 ~79 concrete 15
fill ~53 ~14 ~35 ~53 ~17 ~35 concrete 15
fill ~53 ~14 ~77 ~53 ~16 ~77 concrete 15
fill ~54 ~14 ~38 ~54 ~17 ~38 concrete 15
fill ~54 ~14 ~55 ~54 ~16 ~55 concrete 15
fill ~54 ~14 ~56 ~54 ~15 ~56 concrete 15
fill ~54 ~14 ~57 ~54 ~15 ~57 concrete 15
fill ~54 ~14 ~58 ~54 ~15 ~58 concrete 15
fill ~54 ~14 ~59 ~54 ~15 ~59 concrete 15
fill ~54 ~14 ~60 ~54 ~15 ~60 concrete 15
fill ~54 ~14 ~61 ~54 ~15 ~61 concrete 15
fill ~54 ~14 ~62 ~54 ~15 ~62 concrete 15
fill ~54 ~14 ~63 ~54 ~15 ~63 concrete 15
fill ~54 ~14 ~64 ~54 ~15 ~64 concrete 15
fill ~54 ~14 ~65 ~54 ~15 ~65 concrete 15
fill ~54 ~14 ~66 ~54 ~15 ~66 concrete 15
fill ~54 ~14 ~72 ~54 ~16 ~72 concrete 15
fill ~54 ~14 ~73 ~54 ~16 ~73 concrete 15
fill ~62 ~14 ~45 ~62 ~17 ~45 concrete 15
fill ~62 ~14 ~46 ~62 ~17 ~46 concrete 15
fill ~62 ~14 ~47 ~62 ~17 ~47 concrete 15
fill ~63 ~14 ~37 ~63 ~17 ~37 concrete 15
fill ~63 ~14 ~57 ~63 ~16 ~57 concrete 15
fill ~63 ~14 ~58 ~63 ~16 ~58 concrete 15
fill ~63 ~14 ~59 ~63 ~15 ~59 concrete 15
fill ~63 ~14 ~60 ~63 ~15 ~60 concrete 15
fill ~63 ~14 ~61 ~63 ~15 ~61 concrete 15
fill ~63 ~14 ~62 ~63 ~15 ~62 concrete 15
fill ~63 ~14 ~63 ~63 ~15 ~63 concrete 15
fill ~63 ~14 ~64 ~63 ~15 ~64 concrete 15
fill ~63 ~14 ~65 ~63 ~15 ~65 concrete 15
fill ~63 ~14 ~66 ~63 ~15 ~66 concrete 15
fill ~63 ~14 ~67 ~63 ~15 ~67 concrete 15
fill ~63 ~14 ~68 ~63 ~15 ~68 concrete 15
fill ~63 ~14 ~69 ~63 ~15 ~69 concrete 15
fill ~63 ~14 ~70 ~63 ~15 ~70 concrete 15
fill ~63 ~14 ~71 ~63 ~15 ~71 concrete 15
fill ~64 ~14 ~76 ~64 ~15 ~76 concrete 15
fill ~65 ~14 ~79 ~65 ~15 ~79 concrete 15
fill ~67 ~14 ~43 ~68 ~14 ~43 concrete 15
fill ~67 ~14 ~44 ~67 ~14 ~49 concrete 15
fill ~68 ~14 ~41 ~69 ~14 ~41 concrete 15
fill ~68 ~14 ~42 ~68 ~14 ~41 concrete 15
fill ~68 ~14 ~48 ~68 ~14 ~50 concrete 15
fill ~68 ~14 ~82 ~68 ~15 ~82 concrete 15
fill ~69 ~14 ~40 ~71 ~14 ~40 concrete 15
fill ~69 ~14 ~50 ~70 ~14 ~50 concrete 15
fill ~69 ~14 ~51 ~76 ~14 ~51 concrete 15
fill ~70 ~14 ~83 ~70 ~16 ~83 concrete 15
fill ~71 ~14 ~39 ~75 ~14 ~39 concrete 15
fill ~71 ~14 ~52 ~74 ~14 ~52 concrete 15
fill ~71 ~14 ~84 ~81 ~14 ~84 concrete 15
fill ~73 ~14 ~28 ~73 ~17 ~28 concrete 15
fill ~74 ~14 ~27 ~76 ~14 ~27 concrete 15
fill ~74 ~14 ~40 ~76 ~14 ~40 concrete 15
fill ~75 ~14 ~50 ~76 ~14 ~50 concrete 15
fill ~76 ~14 ~41 ~77 ~14 ~41 concrete 15
fill ~76 ~14 ~42 ~77 ~14 ~42 concrete 15
fill ~76 ~14 ~49 ~77 ~14 ~49 concrete 15
fill ~77 ~14 ~28 ~77 ~17 ~28 concrete 15
fill ~77 ~14 ~43 ~78 ~14 ~43 concrete 15
fill ~77 ~14 ~44 ~78 ~14 ~44 concrete 15
fill ~77 ~14 ~45 ~78 ~14 ~45 concrete 15
fill ~77 ~14 ~46 ~78 ~14 ~46 concrete 15
fill ~77 ~14 ~47 ~78 ~14 ~47 concrete 15
fill ~77 ~14 ~48 ~78 ~14 ~48 concrete 15
fill ~82 ~14 ~31 ~82 ~18 ~31 concrete 15
fill ~85 ~14 ~42 ~85 ~16 ~42 concrete 15
fill ~85 ~14 ~53 ~85 ~16 ~53 concrete 15
fill ~86 ~14 ~57 ~86 ~15 ~57 concrete 15
fill ~86 ~14 ~58 ~86 ~15 ~58 concrete 15
fill ~86 ~14 ~79 ~86 ~15 ~79 concrete 15
fill ~87 ~14 ~59 ~87 ~14 ~64 concrete 15
fill ~87 ~14 ~77 ~87 ~15 ~77 concrete 15
fill ~29 ~15 ~65 ~29 ~15 ~75 concrete 15
fill ~30 ~15 ~63 ~30 ~16 ~63 concrete 15
fill ~30 ~15 ~64 ~30 ~16 ~64 concrete 15
fill ~30 ~15 ~76 ~30 ~16 ~76 concrete 15
fill ~31 ~15 ~58 ~31 ~15 ~59 concrete 15
fill ~31 ~15 ~79 ~31 ~16 ~79 concrete 15
fill ~32 ~15 ~54 ~32 ~16 ~54 concrete 15
fill ~32 ~15 ~55 ~32 ~16 ~55 concrete 15
fill ~32 ~15 ~80 ~32 ~16 ~80 concrete 15
fill ~33 ~15 ~42 ~33 ~18 ~42 concrete 15
fill ~33 ~15 ~43 ~33 ~18 ~43 concrete 15
fill ~33 ~15 ~81 ~33 ~16 ~81 concrete 15
fill ~35 ~15 ~31 ~35 ~18 ~31 concrete 15
fill ~37 ~15 ~42 ~37 ~16 ~42 concrete 15
fill ~37 ~15 ~43 ~37 ~16 ~43 concrete 15
fill ~37 ~15 ~44 ~37 ~16 ~44 concrete 15
fill ~37 ~15 ~45 ~37 ~16 ~45 concrete 15
fill ~37 ~15 ~83 ~37 ~17 ~83 concrete 15
fill ~38 ~15 ~39 ~38 ~15 ~41 concrete 15
fill ~38 ~15 ~46 ~38 ~15 ~49 concrete 15
fill ~38 ~15 ~84 ~45 ~15 ~84 concrete 15
fill ~39 ~15 ~28 ~39 ~17 ~28 concrete 15
fill ~39 ~15 ~37 ~40 ~15 ~37 concrete 15
fill ~39 ~15 ~38 ~39 ~15 ~37 concrete 15
fill ~39 ~15 ~49 ~39 ~15 ~51 concrete 15
fill ~40 ~15 ~27 ~42 ~15 ~27 concrete 15
fill ~40 ~15 ~36 ~41 ~15 ~36 concrete 15
fill ~40 ~15 ~51 ~40 ~15 ~52 concrete 15
fill ~41 ~15 ~52 ~42 ~15 ~52 concrete 15
fill ~42 ~15 ~35 ~46 ~15 ~35 concrete 15
fill ~42 ~15 ~53 ~49 ~15 ~53 concrete 15
fill ~43 ~15 ~28 ~46 ~15 ~28 concrete 15
fill ~46 ~15 ~83 ~46 ~17 ~83 concrete 15
fill ~47 ~15 ~36 ~48 ~15 ~36 concrete 15
setblock ~49 ~15 ~37 concrete 15
fill ~49 ~15 ~52 ~50 ~15 ~52 concrete 15
fill ~50 ~15 ~31 ~50 ~16 ~31 concrete 15
setblock ~50 ~15 ~38 concrete 15
fill ~50 ~15 ~81 ~50 ~16 ~81 concrete 15
fill ~51 ~15 ~32 ~51 ~16 ~32 concrete 15
setblock ~51 ~15 ~39 concrete 15
fill ~51 ~15 ~50 ~52 ~15 ~50 concrete 15
fill ~51 ~15 ~51 ~51 ~15 ~50 concrete 15
fill ~51 ~15 ~80 ~51 ~16 ~80 concrete 15
setblock ~52 ~15 ~41 concrete 15
fill ~52 ~15 ~48 ~52 ~15 ~50 concrete 15
fill ~53 ~15 ~43 ~53 ~16 ~43 concrete 15
fill ~53 ~15 ~44 ~53 ~16 ~44 concrete 15
fill ~53 ~15 ~45 ~53 ~16 ~45 concrete 15
fill ~53 ~15 ~46 ~53 ~16 ~46 concrete 15
fill ~53 ~15 ~47 ~53 ~16 ~47 concrete 15
fill ~53 ~15 ~76 ~53 ~16 ~76 concrete 15
fill ~54 ~15 ~53 ~54 ~16 ~53 concrete 15
fill ~54 ~15 ~54 ~54 ~16 ~54 concrete 15
fill ~54 ~15 ~67 ~54 ~16 ~67 concrete 15
fill ~54 ~15 ~68 ~54 ~16 ~68 concrete 15
fill ~54 ~15 ~69 ~54 ~16 ~69 concrete 15
fill ~54 ~15 ~70 ~54 ~16 ~70 concrete 15
fill ~54 ~15 ~71 ~54 ~16 ~71 concrete 15
fill ~63 ~15 ~38 ~63 ~18 ~38 concrete 15
fill ~63 ~15 ~55 ~63 ~16 ~55 concrete 15
fill ~63 ~15 ~56 ~63 ~16 ~56 concrete 15
fill ~64 ~15 ~35 ~64 ~17 ~35 concrete 15
fill ~64 ~15 ~74 ~64 ~16 ~74 concrete 15
fill ~64 ~15 ~75 ~64 ~16 ~75 concrete 15
fill ~65 ~15 ~33 ~65 ~16 ~33 concrete 15
fill ~65 ~15 ~78 ~65 ~16 ~78 concrete 15
fill ~66 ~15 ~43 ~66 ~15 ~49 concrete 15
fill ~66 ~15 ~80 ~66 ~16 ~80 concrete 15
fill ~67 ~15 ~31 ~67 ~16 ~31 concrete 15
fill ~67 ~15 ~41 ~67 ~15 ~42 concrete 15
fill ~67 ~15 ~50 ~67 ~15 ~51 concrete 15
fill ~67 ~15 ~81 ~67 ~16 ~81 concrete 15
fill ~68 ~15 ~30 ~68 ~16 ~30 concrete 15
setblock ~68 ~15 ~40 concrete 15
fill ~68 ~15 ~51 ~68 ~15 ~52 concrete 15
fill ~69 ~15 ~39 ~70 ~15 ~39 concrete 15
fill ~69 ~15 ~52 ~70 ~15 ~52 concrete 15
fill ~69 ~15 ~53 ~76 ~15 ~53 concrete 15
fill ~70 ~15 ~29 ~70 ~16 ~29 concrete 15
fill ~70 ~15 ~38 ~76 ~15 ~38 concrete 15
fill ~71 ~15 ~83 ~71 ~16 ~83 concrete 15
fill ~72 ~15 ~84 ~79 ~15 ~84 concrete 15
fill ~74 ~15 ~28 ~79 ~15 ~28 concrete 15
fill ~75 ~15 ~52 ~77 ~15 ~52 concrete 15
fill ~76 ~15 ~39 ~77 ~15 ~39 concrete 15
fill ~77 ~15 ~40 ~78 ~15 ~40 concrete 15
fill ~77 ~15 ~50 ~78 ~15 ~50 concrete 15
fill ~77 ~15 ~51 ~78 ~15 ~51 concrete 15
fill ~78 ~15 ~41 ~78 ~15 ~42 concrete 15
fill ~78 ~15 ~49 ~79 ~15 ~49 concrete 15
fill ~79 ~15 ~42 ~79 ~15 ~49 concrete 15
fill ~80 ~15 ~29 ~80 ~18 ~29 concrete 15
fill ~80 ~15 ~83 ~82 ~15 ~83 concrete 15
setblock ~83 ~15 ~82 concrete 15
fill ~84 ~15 ~81 ~84 ~16 ~81 concrete 15
fill ~85 ~15 ~41 ~85 ~16 ~41 concrete 15
fill ~85 ~15 ~54 ~85 ~16 ~54 concrete 15
fill ~85 ~15 ~55 ~85 ~16 ~55 concrete 15
fill ~85 ~15 ~56 ~85 ~16 ~56 concrete 15
fill ~85 ~15 ~80 ~85 ~16 ~80 concrete 15
fill ~86 ~15 ~59 ~86 ~15 ~61 concrete 15
fill ~86 ~15 ~78 ~86 ~16 ~78 concrete 15
fill ~87 ~15 ~62 ~87 ~15 ~68 concrete 15
fill ~87 ~15 ~74 ~87 ~16 ~74 concrete 15
fill ~87 ~15 ~75 ~87 ~16 ~75 concrete 15
fill ~87 ~15 ~76 ~87 ~15 ~74 concrete 15
fill ~29 ~16 ~70 ~29 ~16 ~72 concrete 15
fill ~30 ~16 ~65 ~30 ~16 ~69 concrete 15
fill ~30 ~16 ~73 ~30 ~17 ~73 concrete 15
fill ~30 ~16 ~74 ~30 ~17 ~74 concrete 15
fill ~30 ~16 ~75 ~30 ~17 ~75 concrete 15
fill ~31 ~16 ~59 ~31 ~16 ~62 concrete 15
fill ~31 ~16 ~78 ~31 ~17 ~78 concrete 15
fill ~32 ~16 ~56 ~32 ~16 ~58 concrete 15
fill ~33 ~16 ~44 ~33 ~18 ~44 concrete 15
fill ~33 ~16 ~45 ~33 ~17 ~45 concrete 15
fill ~33 ~16 ~46 ~33 ~17 ~46 concrete 15
fill ~33 ~16 ~47 ~33 ~17 ~47 concrete 15
fill ~33 ~16 ~48 ~33 ~17 ~48 concrete 15
fill ~33 ~16 ~49 ~33 ~17 ~49 concrete 15
fill ~33 ~16 ~50 ~33 ~17 ~50 concrete 15
fill ~33 ~16 ~51 ~33 ~17 ~51 concrete 15
fill ~33 ~16 ~52 ~33 ~17 ~52 concrete 15
fill ~33 ~16 ~53 ~33 ~17 ~53 concrete 15
fill ~34 ~16 ~34 ~34 ~18 ~34 concrete 15
fill ~35 ~16 ~82 ~35 ~17 ~82 concrete 15
fill ~37 ~16 ~29 ~37 ~18 ~29 concrete 15
fill ~37 ~16 ~39 ~37 ~16 ~49 concrete 15
fill ~38 ~16 ~37 ~38 ~16 ~38 concrete 15
fill ~38 ~16 ~50 ~38 ~16 ~51 concrete 15
fill ~38 ~16 ~83 ~39 ~16 ~83 concrete 15
setblock ~39 ~16 ~36 concrete 15
setblock ~39 ~16 ~52 concrete 15
fill ~40 ~16 ~28 ~45 ~16 ~28 concrete 15
fill ~40 ~16 ~35 ~41 ~16 ~35 concrete 15
fill ~40 ~16 ~53 ~41 ~16 ~53 concrete 15
fill ~40 ~16 ~84 ~43 ~16 ~84 concrete 15
fill ~41 ~16 ~54 ~50 ~16 ~54 concrete 15
fill ~42 ~16 ~34 ~45 ~16 ~34 concrete 15
fill ~44 ~16 ~55 ~47 ~16 ~55 concrete 15
fill ~44 ~16 ~83 ~47 ~16 ~83 concrete 15
fill ~46 ~16 ~29 ~46 ~18 ~29 concrete 15
fill ~46 ~16 ~35 ~47 ~16 ~35 concrete 15
fill ~48 ~16 ~30 ~48 ~17 ~30 concrete 15
fill ~48 ~16 ~36 ~49 ~16 ~36 concrete 15
fill ~48 ~16 ~82 ~48 ~17 ~82 concrete 15
setblock ~50 ~16 ~37 concrete 15
fill ~50 ~16 ~53 ~52 ~16 ~53 concrete 15
fill ~51 ~16 ~38 ~51 ~17 ~38 concrete 15
fill ~51 ~16 ~52 ~52 ~16 ~52 concrete 15
fill ~52 ~16 ~34 ~52 ~17 ~34 concrete 15
fill ~52 ~16 ~39 ~52 ~17 ~39 concrete 15
fill ~52 ~16 ~40 ~52 ~16 ~39 concrete 15
fill ~52 ~16 ~51 ~54 ~16 ~51 concrete 15
fill ~52 ~16 ~78 ~52 ~17 ~78 concrete 15
fill ~53 ~16 ~36 ~53 ~17 ~36 concrete 15
fill ~53 ~16 ~41 ~53 ~17 ~41 concrete 15
fill ~53 ~16 ~42 ~53 ~17 ~42 concrete 15
fill ~53 ~16 ~48 ~53 ~16 ~51 concrete 15
fill ~53 ~16 ~55 ~53 ~16 ~66 concrete 15
fill ~53 ~16 ~74 ~53 ~17 ~74 concrete 15
fill ~53 ~16 ~75 ~53 ~17 ~75 concrete 15
fill ~54 ~16 ~39 ~54 ~17 ~39 concrete 15
setblock ~54 ~16 ~52 concrete 15
fill ~55 ~16 ~51 ~55 ~16 ~53 planks 2
setblock ~55 ~16 ~54 orange_glazed_terracotta 0
setblock ~55 ~16 ~55 planks 2
setblock ~56 ~16 ~49 orange_glazed_terracotta 0
fill ~56 ~16 ~50 ~58 ~16 ~50 planks 2
setblock ~56 ~16 ~51 orange_glazed_terracotta 0
fill ~56 ~16 ~52 ~57 ~16 ~52 planks 2
setblock ~56 ~16 ~53 orange_glazed_terracotta 0
setblock ~56 ~16 ~54 planks 2
fill ~56 ~16 ~55 ~56 ~21 ~55 orange_glazed_terracotta 0
fill ~57 ~16 ~46 ~58 ~16 ~46 planks 2
fill ~57 ~16 ~47 ~57 ~16 ~53 planks 2
setblock ~58 ~16 ~43 orange_glazed_terracotta 0
setblock ~58 ~16 ~44 planks 2
setblock ~58 ~16 ~45 orange_glazed_terracotta 0
setblock ~58 ~16 ~47 orange_glazed_terracotta 0
setblock ~58 ~16 ~48 planks 2
fill ~58 ~16 ~49 ~58 ~24 ~49 orange_glazed_terracotta 0
fill ~58 ~16 ~51 ~58 ~42 ~51 orange_glazed_terracotta 0
fill ~63 ~16 ~39 ~63 ~18 ~39 concrete 15
fill ~63 ~16 ~53 ~63 ~16 ~58 concrete 15
fill ~64 ~16 ~59 ~64 ~16 ~75 concrete 15
fill ~65 ~16 ~43 ~65 ~17 ~43 concrete 15
fill ~65 ~16 ~44 ~65 ~17 ~44 concrete 15
fill ~65 ~16 ~45 ~65 ~16 ~49 concrete 15
fill ~65 ~16 ~76 ~65 ~17 ~76 concrete 15
fill ~65 ~16 ~77 ~65 ~16 ~76 concrete 15
setblock ~66 ~16 ~32 concrete 15
fill ~66 ~16 ~41 ~66 ~17 ~41 concrete 15
fill ~66 ~16 ~42 ~66 ~16 ~41 concrete 15
fill ~66 ~16 ~50 ~66 ~16 ~52 concrete 15
setblock ~66 ~16 ~79 concrete 15
setblock ~67 ~16 ~40 concrete 15
fill ~67 ~16 ~52 ~67 ~16 ~53 concrete 15
setblock ~68 ~16 ~39 concrete 15
fill ~68 ~16 ~53 ~68 ~16 ~54 concrete 15
fill ~68 ~16 ~81 ~68 ~17 ~81 concrete 15
fill ~69 ~16 ~30 ~69 ~17 ~30 concrete 15
setblock ~69 ~16 ~38 concrete 15
fill ~69 ~16 ~54 ~77 ~16 ~54 concrete 15
setblock ~69 ~16 ~82 concrete 15
fill ~70 ~16 ~37 ~76 ~16 ~37 concrete 15
fill ~71 ~16 ~29 ~71 ~18 ~29 concrete 15
fill ~71 ~16 ~55 ~75 ~16 ~55 concrete 15
fill ~72 ~16 ~83 ~73 ~16 ~83 concrete 15
fill ~74 ~16 ~28 ~79 ~16 ~28 concrete 15
fill ~74 ~16 ~84 ~77 ~16 ~84 concrete 15
fill ~77 ~16 ~38 ~78 ~16 ~38 concrete 15
fill ~77 ~16 ~53 ~78 ~16 ~53 concrete 15
setblock ~78 ~16 ~39 concrete 15
fill ~78 ~16 ~52 ~79 ~16 ~52 concrete 15
fill ~78 ~16 ~83 ~81 ~16 ~83 concrete 15
fill ~79 ~16 ~40 ~79 ~16 ~41 concrete 15
fill ~79 ~16 ~50 ~80 ~16 ~50 concrete 15
fill ~79 ~16 ~51 ~79 ~16 ~50 concrete 15
fill ~80 ~16 ~42 ~80 ~16 ~50 concrete 15
fill ~81 ~16 ~30 ~81 ~18 ~30 concrete 15
setblock ~82 ~16 ~82 concrete 15
fill ~83 ~16 ~34 ~83 ~20 ~34 concrete 15
setblock ~83 ~16 ~81 concrete 15
setblock ~84 ~16 ~80 concrete 15
fill ~85 ~16 ~57 ~85 ~16 ~60 concrete 15
setblock ~85 ~16 ~79 concrete 15
fill ~86 ~16 ~61 ~86 ~16 ~65 concrete 15
fill ~86 ~16 ~76 ~86 ~17 ~76 concrete 15
fill ~86 ~16 ~77 ~86 ~16 ~76 concrete 15
fill ~87 ~16 ~48 ~87 ~16 ~49 planks 2
fill ~87 ~16 ~66 ~87 ~16 ~75 concrete 15
fill ~30 ~17 ~67 ~30 ~17 ~75 concrete 15
fill ~31 ~17 ~63 ~31 ~17 ~66 concrete 15
fill ~31 ~17 ~76 ~31 ~18 ~76 concrete 15
fill ~31 ~17 ~77 ~31 ~17 ~76 concrete 15
fill ~32 ~17 ~59 ~32 ~17 ~62 concrete 15
setblock ~32 ~17 ~79 concrete 15
fill ~33 ~17 ~54 ~34 ~17 ~54 concrete 15
fill ~33 ~17 ~55 ~33 ~17 ~58 concrete 15
setblock ~33 ~17 ~80 concrete 15
fill ~34 ~17 ~35 ~34 ~19 ~35 concrete 15
setblock ~34 ~17 ~52 concrete 15
setblock ~34 ~17 ~81 concrete 15
fill ~35 ~17 ~32 ~35 ~19 ~32 concrete 15
fill ~36 ~17 ~30 ~36 ~18 ~30 concrete 15
fill ~36 ~17 ~39 ~36 ~18 ~39 concrete 15
fill ~36 ~17 ~40 ~36 ~17 ~51 concrete 15
setblock ~36 ~17 ~82 concrete 15
fill ~37 ~17 ~37 ~37 ~17 ~38 concrete 15
fill ~37 ~17 ~50 ~37 ~17 ~53 concrete 15
setblock ~38 ~17 ~36 concrete 15
fill ~38 ~17 ~52 ~38 ~17 ~54 concrete 15
fill ~38 ~17 ~83 ~46 ~17 ~83 concrete 15
setblock ~39 ~17 ~35 concrete 15
fill ~39 ~17 ~53 ~39 ~17 ~54 concrete 15
fill ~40 ~17 ~28 ~44 ~17 ~28 concrete 15
fill ~40 ~17 ~34 ~42 ~17 ~34 concrete 15
fill ~40 ~17 ~54 ~40 ~17 ~55 concrete 15
fill ~41 ~17 ~55 ~43 ~17 ~55 concrete 15
fill ~42 ~17 ~56 ~47 ~17 ~56 concrete 15
fill ~43 ~17 ~33 ~43 ~18 ~33 concrete 15
fill ~44 ~17 ~34 ~47 ~17 ~34 concrete 15
fill ~45 ~17 ~29 ~45 ~18 ~29 concrete 15
fill ~47 ~17 ~30 ~47 ~18 ~30 concrete 15
setblock ~47 ~17 ~53 planks 2
fill ~47 ~17 ~54 ~50 ~17 ~54 orange_glazed_terracotta 0
setblock ~47 ~17 ~55 planks 2
setblock ~47 ~17 ~82 concrete 15
setblock ~48 ~17 ~35 concrete 15
fill ~48 ~17 ~52 ~52 ~17 ~52 orange_glazed_terracotta 0
fill ~48 ~17 ~53 ~48 ~17 ~52 orange_glazed_terracotta 0
setblock ~48 ~17 ~55 stained_hardened_clay 13
setblock ~48 ~17 ~56 stained_hardened_clay 15
fill ~49 ~17 ~31 ~49 ~18 ~31 concrete 15
fill ~49 ~17 ~36 ~50 ~17 ~36 concrete 15
fill ~49 ~17 ~50 ~53 ~17 ~50 orange_glazed_terracotta 0
setblock ~49 ~17 ~51 planks 2
setblock ~49 ~17 ~53 planks 2
setblock ~49 ~17 ~55 bedrock 0
setblock ~49 ~17 ~56 stained_hardened_clay 7
setblock ~49 ~17 ~57 planks 2
setblock ~49 ~17 ~81 concrete 15
fill ~50 ~17 ~32 ~50 ~18 ~32 concrete 15
setblock ~50 ~17 ~49 orange_glazed_terracotta 0
setblock ~50 ~17 ~51 orange_glazed_terracotta 0
setblock ~50 ~17 ~53 orange_glazed_terracotta 0
setblock ~50 ~17 ~55 stained_hardened_clay 7
fill ~50 ~17 ~56 ~52 ~17 ~56 stained_hardened_clay 13
setblock ~50 ~17 ~57 orange_glazed_terracotta 0
setblock ~50 ~17 ~80 concrete 15
fill ~51 ~17 ~33 ~51 ~18 ~33 concrete 15
fill ~51 ~17 ~37 ~51 ~18 ~37 concrete 15
fill ~51 ~17 ~48 ~53 ~17 ~48 orange_glazed_terracotta 0
setblock ~51 ~17 ~49 planks 2
setblock ~51 ~17 ~51 planks 2
setblock ~51 ~17 ~53 planks 2
setblock ~51 ~17 ~54 stained_hardened_clay 5
fill ~51 ~17 ~55 ~52 ~17 ~55 stained_hardened_clay 13
setblock ~51 ~17 ~57 bedrock 0
setblock ~51 ~17 ~58 orange_glazed_terracotta 0
setblock ~51 ~17 ~79 concrete 15
setblock ~52 ~17 ~47 orange_glazed_terracotta 0
setblock ~52 ~17 ~49 orange_glazed_terracotta 0
setblock ~52 ~17 ~51 orange_glazed_terracotta 0
setblock ~52 ~17 ~53 orange_glazed_terracotta 0
fill ~52 ~17 ~54 ~53 ~17 ~54 stained_hardened_clay 13
setblock ~52 ~17 ~57 stained_hardened_clay 7
setblock ~52 ~17 ~58 stained_hardened_clay 15
setblock ~52 ~17 ~59 stained_hardened_clay 7
fill ~52 ~17 ~60 ~52 ~17 ~64 concrete 15
fill ~52 ~17 ~76 ~52 ~18 ~76 concrete 15
fill ~52 ~17 ~77 ~52 ~17 ~76 concrete 15
setblock ~53 ~17 ~37 concrete 15
fill ~53 ~17 ~40 ~54 ~17 ~40 concrete 15
setblock ~53 ~17 ~45 planks 2
setblock ~53 ~17 ~46 orange_glazed_terracotta 0
setblock ~53 ~17 ~47 planks 2
setblock ~53 ~17 ~49 planks 2
setblock ~53 ~17 ~51 planks 2
setblock ~53 ~17 ~52 stained_hardened_clay 13
setblock ~53 ~17 ~53 bedrock 0
setblock ~53 ~17 ~55 planks 2
fill ~53 ~17 ~56 ~55 ~17 ~56 orange_glazed_terracotta 0
setblock ~53 ~17 ~57 planks 2
fill ~53 ~17 ~58 ~54 ~17 ~58 orange_glazed_terracotta 0
fill ~53 ~17 ~64 ~53 ~17 ~75 concrete 15
setblock ~54 ~17 ~43 stained_hardened_clay 7
setblock ~54 ~17 ~44 wool 15
setblock ~54 ~17 ~45 stained_hardened_clay 7
setblock ~54 ~17 ~46 stained_hardened_clay 15
setblock ~54 ~17 ~47 green_glazed_terracotta 0
fill ~54 ~17 ~48 ~54 ~17 ~50 stained_hardened_clay 13
fill ~54 ~17 ~51 ~54 ~17 ~58 orange_glazed_terracotta 0
fill ~55 ~17 ~41 ~55 ~17 ~42 stained_hardened_clay 13
setblock ~55 ~17 ~43 bedrock 0
setblock ~55 ~17 ~44 stained_hardened_clay 13
setblock ~55 ~17 ~45 green_glazed_terracotta 0
setblock ~55 ~17 ~46 stained_hardened_clay 5
setblock ~55 ~17 ~47 planks 2
fill ~55 ~17 ~48 ~56 ~17 ~48 orange_glazed_terracotta 0
setblock ~55 ~17 ~49 planks 2
setblock ~55 ~17 ~50 orange_glazed_terracotta 0
fill ~55 ~17 ~57 ~55 ~27 ~57 planks 2
setblock ~56 ~17 ~32 orange_glazed_terracotta 0
fill ~56 ~17 ~36 ~58 ~17 ~36 orange_glazed_terracotta 0
fill ~56 ~17 ~37 ~56 ~17 ~48 orange_glazed_terracotta 0
setblock ~57 ~17 ~34 orange_glazed_terracotta 0
setblock ~57 ~17 ~35 planks 2
setblock ~57 ~17 ~37 planks 2
fill ~57 ~17 ~38 ~59 ~17 ~38 orange_glazed_terracotta 0
setblock ~57 ~17 ~39 planks 2
fill ~57 ~17 ~40 ~59 ~17 ~40 orange_glazed_terracotta 0
setblock ~57 ~17 ~41 planks 2
fill ~57 ~17 ~42 ~59 ~17 ~42 orange_glazed_terracotta 0
setblock ~57 ~17 ~43 planks 2
setblock ~57 ~17 ~44 orange_glazed_terracotta 0
setblock ~57 ~17 ~45 planks 2
setblock ~57 ~17 ~52 orange_glazed_terracotta 0
fill ~57 ~17 ~53 ~57 ~23 ~53 planks 2
setblock ~57 ~17 ~54 orange_glazed_terracotta 0
fill ~58 ~17 ~37 ~58 ~30 ~37 orange_glazed_terracotta 0
setblock ~58 ~17 ~39 orange_glazed_terracotta 0
setblock ~58 ~17 ~41 orange_glazed_terracotta 0
setblock ~58 ~17 ~48 orange_glazed_terracotta 0
setblock ~58 ~17 ~50 orange_glazed_terracotta 0
fill ~59 ~17 ~39 ~59 ~38 ~39 planks 2
fill ~59 ~17 ~41 ~59 ~42 ~41 planks 2
fill ~59 ~17 ~43 ~59 ~56 ~43 planks 2
fill ~59 ~17 ~44 ~60 ~17 ~44 orange_glazed_terracotta 0
fill ~59 ~17 ~45 ~59 ~56 ~45 planks 2
fill ~59 ~17 ~46 ~60 ~17 ~46 orange_glazed_terracotta 0
fill ~59 ~17 ~47 ~59 ~56 ~47 planks 2
setblock ~60 ~17 ~45 orange_glazed_terracotta 0
fill ~60 ~17 ~47 ~60 ~17 ~52 orange_glazed_terracotta 0
setblock ~61 ~17 ~47 planks 2
setblock ~61 ~17 ~48 orange_glazed_terracotta 0
setblock ~61 ~17 ~49 planks 2
setblock ~61 ~17 ~50 orange_glazed_terracotta 0
setblock ~61 ~17 ~51 planks 2
fill ~61 ~17 ~52 ~62 ~17 ~52 orange_glazed_terracotta 0
fill ~61 ~17 ~53 ~61 ~18 ~53 planks 2
fill ~61 ~17 ~54 ~62 ~17 ~54 orange_glazed_terracotta 0
fill ~61 ~17 ~55 ~61 ~56 ~55 planks 2
setblock ~62 ~17 ~50 stained_hardened_clay 13
setblock ~62 ~17 ~51 orange_glazed_terracotta 0
setblock ~62 ~17 ~53 orange_glazed_terracotta 0
fill ~62 ~17 ~55 ~62 ~17 ~57 orange_glazed_terracotta 0
fill ~63 ~17 ~40 ~63 ~18 ~40 concrete 15
setblock ~63 ~17 ~51 concrete 15
fill ~63 ~17 ~52 ~63 ~17 ~53 stained_hardened_clay 7
setblock ~63 ~17 ~54 stained_hardened_clay 13
setblock ~63 ~17 ~55 planks 2
setblock ~63 ~17 ~56 orange_glazed_terracotta 0
setblock ~63 ~17 ~57 planks 2
setblock ~63 ~17 ~58 orange_glazed_terracotta 0
fill ~63 ~17 ~59 ~63 ~33 ~59 planks 2
fill ~64 ~17 ~36 ~64 ~18 ~36 concrete 15
fill ~64 ~17 ~45 ~64 ~18 ~45 concrete 15
fill ~64 ~17 ~46 ~64 ~18 ~46 concrete 15
fill ~64 ~17 ~47 ~64 ~18 ~47 concrete 15
fill ~64 ~17 ~48 ~64 ~17 ~49 concrete 15
setblock ~64 ~17 ~55 stained_hardened_clay 7
fill ~64 ~17 ~56 ~64 ~17 ~58 stained_hardened_clay 15
setblock ~64 ~17 ~59 stained_hardened_clay 13
setblock ~64 ~17 ~60 concrete 15
fill ~65 ~17 ~34 ~65 ~18 ~34 concrete 15
fill ~65 ~17 ~42 ~65 ~18 ~42 concrete 15
fill ~65 ~17 ~50 ~65 ~17 ~52 concrete 15
setblock ~65 ~17 ~57 planks 2
setblock ~65 ~17 ~58 orange_glazed_terracotta 0
setblock ~65 ~17 ~59 planks 2
setblock ~65 ~17 ~60 stained_hardened_clay 13
fill ~65 ~17 ~61 ~65 ~17 ~76 concrete 15
fill ~66 ~17 ~33 ~66 ~18 ~33 concrete 15
fill ~66 ~17 ~40 ~66 ~18 ~40 concrete 15
fill ~66 ~17 ~53 ~66 ~17 ~54 concrete 15
fill ~66 ~17 ~77 ~66 ~17 ~78 concrete 15
fill ~67 ~17 ~32 ~67 ~18 ~32 concrete 15
setblock ~67 ~17 ~39 concrete 15
fill ~67 ~17 ~54 ~67 ~17 ~55 concrete 15
fill ~67 ~17 ~79 ~67 ~17 ~80 concrete 15
fill ~68 ~17 ~31 ~68 ~18 ~31 concrete 15
setblock ~68 ~17 ~38 concrete 15
fill ~68 ~17 ~55 ~70 ~17 ~55 concrete 15
setblock ~68 ~17 ~80 concrete 15
fill ~69 ~17 ~37 ~70 ~17 ~37 concrete 15
fill ~69 ~17 ~56 ~77 ~17 ~56 concrete 15
setblock ~69 ~17 ~81 concrete 15
fill ~70 ~17 ~30 ~70 ~19 ~30 concrete 15
fill ~70 ~17 ~82 ~71 ~17 ~82 concrete 15
fill ~71 ~17 ~36 ~77 ~17 ~36 concrete 15
fill ~72 ~17 ~29 ~72 ~18 ~29 concrete 15
fill ~72 ~17 ~83 ~79 ~17 ~83 concrete 15
fill ~74 ~17 ~28 ~78 ~17 ~28 concrete 15
fill ~76 ~17 ~55 ~79 ~17 ~55 concrete 15
fill ~77 ~17 ~37 ~78 ~17 ~37 concrete 15
fill ~78 ~17 ~54 ~80 ~17 ~54 concrete 15
fill ~79 ~17 ~29 ~79 ~19 ~29 concrete 15
fill ~79 ~17 ~38 ~79 ~17 ~39 concrete 15
fill ~79 ~17 ~53 ~80 ~17 ~53 concrete 15
fill ~79 ~17 ~82 ~81 ~17 ~82 concrete 15
fill ~80 ~17 ~40 ~80 ~17 ~41 concrete 15
fill ~80 ~17 ~51 ~81 ~17 ~51 concrete 15
fill ~80 ~17 ~52 ~81 ~17 ~52 concrete 15
fill ~81 ~17 ~42 ~81 ~18 ~42 concrete 15
fill ~81 ~17 ~43 ~81 ~17 ~52 concrete 15
setblock ~82 ~17 ~81 concrete 15
setblock ~83 ~17 ~80 concrete 15
fill ~84 ~17 ~41 ~84 ~19 ~41 concrete 15
fill ~84 ~17 ~42 ~84 ~19 ~42 concrete 15
fill ~84 ~17 ~43 ~84 ~19 ~43 concrete 15
fill ~84 ~17 ~44 ~84 ~19 ~44 concrete 15
fill ~84 ~17 ~45 ~84 ~18 ~45 concrete 15
fill ~84 ~17 ~46 ~84 ~18 ~46 concrete 15
fill ~84 ~17 ~47 ~84 ~18 ~47 concrete 15
fill ~84 ~17 ~48 ~84 ~18 ~48 concrete 15
fill ~84 ~17 ~49 ~84 ~18 ~49 concrete 15
fill ~84 ~17 ~50 ~84 ~17 ~55 concrete 15
setblock ~84 ~17 ~56 stained_hardened_clay 15
fill ~84 ~17 ~57 ~84 ~17 ~61 concrete 15
fill ~84 ~17 ~78 ~85 ~17 ~78 concrete 15
fill ~84 ~17 ~79 ~84 ~17 ~78 concrete 15
fill ~85 ~17 ~52 ~87 ~17 ~52 orange_glazed_terracotta 0
setblock ~85 ~17 ~53 planks 2
fill ~85 ~17 ~54 ~86 ~17 ~54 orange_glazed_terracotta 0
setblock ~85 ~17 ~55 planks 2
setblock ~85 ~17 ~56 orange_glazed_terracotta 0
fill ~85 ~17 ~61 ~85 ~17 ~66 concrete 15
fill ~85 ~17 ~76 ~85 ~17 ~78 concrete 15
fill ~86 ~17 ~48 ~87 ~17 ~48 orange_glazed_terracotta 0
fill ~86 ~17 ~49 ~86 ~17 ~55 orange_glazed_terracotta 0
fill ~86 ~17 ~66 ~86 ~17 ~76 concrete 15
setblock ~87 ~17 ~36 orange_glazed_terracotta 0
fill ~87 ~17 ~37 ~87 ~30 ~37 planks 2
setblock ~87 ~17 ~38 orange_glazed_terracotta 0
fill ~87 ~17 ~39 ~87 ~18 ~39 planks 2
setblock ~87 ~17 ~40 orange_glazed_terracotta 0
setblock ~87 ~17 ~41 planks 2
fill ~87 ~17 ~42 ~88 ~17 ~42 orange_glazed_terracotta 0
setblock ~87 ~17 ~43 planks 2
fill ~87 ~17 ~44 ~88 ~17 ~44 orange_glazed_terracotta 0
setblock ~87 ~17 ~45 planks 2
setblock ~87 ~17 ~46 orange_glazed_terracotta 0
fill ~87 ~17 ~47 ~87 ~18 ~47 planks 2
fill ~87 ~17 ~49 ~87 ~20 ~49 planks 2
setblock ~87 ~17 ~50 orange_glazed_terracotta 0
fill ~87 ~17 ~51 ~87 ~31 ~51 planks 2
fill ~88 ~17 ~41 ~88 ~48 ~41 orange_glazed_terracotta 0
fill ~88 ~17 ~43 ~88 ~51 ~43 orange_glazed_terracotta 0
fill ~88 ~17 ~45 ~88 ~53 ~45 orange_glazed_terracotta 0
fill ~30 ~18 ~45 ~30 ~56 ~45 orange_glazed_terracotta 0
fill ~30 ~18 ~46 ~33 ~18 ~46 planks 2
fill ~30 ~18 ~47 ~30 ~59 ~47 orange_glazed_terracotta 0
fill ~30 ~18 ~48 ~33 ~18 ~48 planks 2
fill ~30 ~18 ~49 ~30 ~50 ~49 orange_glazed_terracotta 0
fill ~30 ~18 ~50 ~33 ~18 ~50 planks 2
fill ~30 ~18 ~51 ~30 ~29 ~51 orange_glazed_terracotta 0
fill ~30 ~18 ~52 ~34 ~18 ~52 planks 2
setblock ~31 ~18 ~47 planks 2
setblock ~31 ~18 ~49 planks 2
setblock ~31 ~18 ~51 planks 2
fill ~31 ~18 ~53 ~31 ~31 ~53 planks 2
fill ~31 ~18 ~54 ~34 ~18 ~54 planks 2
fill ~31 ~18 ~67 ~32 ~18 ~67 concrete 15
fill ~31 ~18 ~68 ~31 ~18 ~76 concrete 15
setblock ~32 ~18 ~47 orange_glazed_terracotta 0
setblock ~32 ~18 ~49 orange_glazed_terracotta 0
setblock ~32 ~18 ~51 orange_glazed_terracotta 0
setblock ~32 ~18 ~53 orange_glazed_terracotta 0
fill ~32 ~18 ~55 ~32 ~29 ~55 orange_glazed_terracotta 0
fill ~32 ~18 ~56 ~33 ~18 ~56 planks 2
fill ~32 ~18 ~63 ~33 ~18 ~63 concrete 15
fill ~32 ~18 ~64 ~32 ~18 ~67 concrete 15
fill ~32 ~18 ~76 ~32 ~18 ~78 concrete 15
setblock ~33 ~18 ~47 planks 2
setblock ~33 ~18 ~49 planks 2
setblock ~33 ~18 ~51 planks 2
setblock ~33 ~18 ~53 planks 2
setblock ~33 ~18 ~55 planks 2
fill ~33 ~18 ~57 ~33 ~24 ~57 planks 2
fill ~33 ~18 ~59 ~35 ~18 ~59 concrete 15
fill ~33 ~18 ~60 ~34 ~18 ~60 concrete 15
fill ~33 ~18 ~61 ~33 ~18 ~63 concrete 15
setblock ~33 ~18 ~79 concrete 15
fill ~34 ~18 ~36 ~34 ~19 ~36 concrete 15
fill ~34 ~18 ~37 ~34 ~19 ~37 concrete 15
fill ~34 ~18 ~43 ~35 ~18 ~43 concrete 15
fill ~34 ~18 ~44 ~35 ~18 ~44 concrete 15
fill ~34 ~18 ~45 ~35 ~18 ~45 concrete 15
setblock ~34 ~18 ~46 concrete 7
setblock ~34 ~18 ~47 wool 15
fill ~34 ~18 ~48 ~35 ~18 ~48 stained_hardened_clay 13
fill ~34 ~18 ~49 ~35 ~18 ~49 stained_hardened_clay 5
fill ~34 ~18 ~50 ~34 ~18 ~49 stained_hardened_clay 5
setblock ~34 ~18 ~51 stained_hardened_clay 13
setblock ~34 ~18 ~53 stained_hardened_clay 13
fill ~34 ~18 ~55 ~35 ~18 ~55 stained_hardened_clay 13
setblock ~34 ~18 ~56 mossy_cobblestone 0
setblock ~34 ~18 ~57 stained_hardened_clay 7
fill ~34 ~18 ~58 ~35 ~18 ~58 concrete 15
setblock ~34 ~18 ~80 concrete 15
fill ~35 ~18 ~40 ~35 ~18 ~46 concrete 15
setblock ~35 ~18 ~47 bedrock 0
setblock ~35 ~18 ~50 mossy_cobblestone 0
setblock ~35 ~18 ~51 bedrock 0
setblock ~35 ~18 ~52 stained_hardened_clay 13
setblock ~35 ~18 ~53 stained_hardened_clay 5
setblock ~35 ~18 ~54 stained_hardened_clay 13
setblock ~35 ~18 ~56 stained_hardened_clay 13
setblock ~35 ~18 ~57 stained_hardened_clay 5
fill ~35 ~18 ~81 ~36 ~18 ~81 concrete 15
fill ~36 ~18 ~37 ~36 ~18 ~39 concrete 15
setblock ~36 ~18 ~47 orange_glazed_terracotta 0
fill ~36 ~18 ~48 ~50 ~18 ~48 planks 2
setblock ~36 ~18 ~49 orange_glazed_terracotta 0
fill ~36 ~18 ~50 ~48 ~18 ~50 planks 2
setblock ~36 ~18 ~51 orange_glazed_terracotta 0
setblock ~36 ~18 ~52 bedrock 0
setblock ~36 ~18 ~53 stained_hardened_clay 13
setblock ~36 ~18 ~54 stained_hardened_clay 5
setblock ~36 ~18 ~55 stained_hardened_clay 7
setblock ~36 ~18 ~56 bedrock 0
setblock ~36 ~18 ~57 stained_hardened_clay 13
fill ~37 ~18 ~35 ~38 ~18 ~35 concrete 15
fill ~37 ~18 ~36 ~37 ~18 ~35 concrete 15
setblock ~37 ~18 ~47 planks 2
setblock ~37 ~18 ~49 planks 2
fill ~37 ~18 ~51 ~37 ~18 ~53 planks 2
fill ~37 ~18 ~54 ~37 ~18 ~56 stained_hardened_clay 13
setblock ~37 ~18 ~57 bedrock 0
fill ~37 ~18 ~82 ~40 ~18 ~82 concrete 15
fill ~38 ~18 ~29 ~39 ~18 ~29 concrete 15
fill ~38 ~18 ~34 ~39 ~18 ~34 concrete 15
setblock ~38 ~18 ~47 orange_glazed_terracotta 0
setblock ~38 ~18 ~49 orange_glazed_terracotta 0
setblock ~38 ~18 ~51 orange_glazed_terracotta 0
fill ~38 ~18 ~52 ~47 ~18 ~52 planks 2
setblock ~38 ~18 ~53 orange_glazed_terracotta 0
fill ~38 ~18 ~54 ~46 ~18 ~54 planks 2
setblock ~38 ~18 ~55 stained_hardened_clay 13
setblock ~38 ~18 ~56 stained_hardened_clay 5
setblock ~38 ~18 ~57 stained_hardened_clay 13
setblock ~39 ~18 ~49 planks 2
setblock ~39 ~18 ~51 planks 2
setblock ~39 ~18 ~53 planks 2
setblock ~39 ~18 ~55 mossy_cobblestone 0
setblock ~39 ~18 ~56 nether_brick 0
setblock ~39 ~18 ~57 stained_hardened_clay 5
fill ~40 ~18 ~28 ~42 ~18 ~28 concrete 15
fill ~40 ~18 ~33 ~46 ~18 ~33 concrete 15
setblock ~40 ~18 ~49 orange_glazed_terracotta 0
setblock ~40 ~18 ~51 orange_glazed_terracotta 0
setblock ~40 ~18 ~53 orange_glazed_terracotta 0
setblock ~40 ~18 ~55 orange_glazed_terracotta 0
setblock ~40 ~18 ~56 concrete 7
fill ~40 ~18 ~57 ~41 ~18 ~57 stained_hardened_clay 13
setblock ~41 ~18 ~49 planks 2
setblock ~41 ~18 ~51 planks 2
setblock ~41 ~18 ~53 planks 2
setblock ~41 ~18 ~55 planks 2
setblock ~41 ~18 ~56 stained_hardened_clay 13
fill ~41 ~18 ~83 ~42 ~18 ~83 concrete 15
setblock ~42 ~18 ~49 orange_glazed_terracotta 0
setblock ~42 ~18 ~51 orange_glazed_terracotta 0
setblock ~42 ~18 ~53 orange_glazed_terracotta 0
setblock ~42 ~18 ~55 orange_glazed_terracotta 0
fill ~42 ~18 ~56 ~47 ~18 ~56 planks 2
setblock ~42 ~18 ~57 wool 15
setblock ~42 ~18 ~58 stained_hardened_clay 5
fill ~43 ~18 ~29 ~46 ~18 ~29 concrete 15
setblock ~43 ~18 ~49 planks 2
setblock ~43 ~18 ~51 planks 2
setblock ~43 ~18 ~53 planks 2
setblock ~43 ~18 ~55 planks 2
fill ~43 ~18 ~57 ~44 ~18 ~57 stained_hardened_clay 13
fill ~43 ~18 ~58 ~43 ~18 ~57 stained_hardened_clay 13
fill ~43 ~18 ~82 ~46 ~18 ~82 concrete 15
setblock ~44 ~18 ~47 orange_glazed_terracotta 0
setblock ~44 ~18 ~49 orange_glazed_terracotta 0
setblock ~44 ~18 ~51 orange_glazed_terracotta 0
setblock ~44 ~18 ~53 orange_glazed_terracotta 0
setblock ~44 ~18 ~55 orange_glazed_terracotta 0
setblock ~44 ~18 ~58 stained_hardened_clay 5
setblock ~45 ~18 ~47 planks 2
setblock ~45 ~18 ~49 planks 2
setblock ~45 ~18 ~51 planks 2
setblock ~45 ~18 ~53 planks 2
setblock ~45 ~18 ~55 planks 2
setblock ~45 ~18 ~57 gold_ore 0
setblock ~45 ~18 ~58 concrete 7
setblock ~45 ~18 ~59 planks 2
fill ~46 ~18 ~46 ~52 ~18 ~46 planks 2
setblock ~46 ~18 ~47 orange_glazed_terracotta 0
setblock ~46 ~18 ~49 orange_glazed_terracotta 0
setblock ~46 ~18 ~51 orange_glazed_terracotta 0
setblock ~46 ~18 ~53 orange_glazed_terracotta 0
setblock ~46 ~18 ~55 orange_glazed_terracotta 0
setblock ~46 ~18 ~57 stained_hardened_clay 13
fill ~46 ~18 ~58 ~47 ~18 ~58 stained_hardened_clay 5
setblock ~46 ~18 ~59 orange_glazed_terracotta 0
fill ~47 ~18 ~34 ~48 ~18 ~34 concrete 15
setblock ~47 ~18 ~45 planks 2
setblock ~47 ~18 ~47 planks 2
setblock ~47 ~18 ~49 planks 2
setblock ~47 ~18 ~51 planks 2
setblock ~47 ~18 ~57 stained_hardened_clay 5
setblock ~47 ~18 ~59 bedrock 0
fill ~47 ~18 ~81 ~48 ~18 ~81 concrete 15
setblock ~48 ~18 ~31 concrete 15
fill ~48 ~18 ~44 ~53 ~18 ~44 planks 2
setblock ~48 ~18 ~45 orange_glazed_terracotta 0
setblock ~48 ~18 ~47 orange_glazed_terracotta 0
setblock ~48 ~18 ~49 orange_glazed_terracotta 0
setblock ~48 ~18 ~51 orange_glazed_terracotta 0
fill ~48 ~18 ~57 ~48 ~18 ~58 stained_hardened_clay 13
setblock ~48 ~18 ~59 stained_hardened_clay 5
setblock ~48 ~18 ~60 planks 2
setblock ~49 ~18 ~35 concrete 15
setblock ~49 ~18 ~43 planks 2
setblock ~49 ~18 ~45 planks 2
setblock ~49 ~18 ~47 planks 2
setblock ~49 ~18 ~49 planks 2
fill ~49 ~18 ~57 ~50 ~18 ~57 concrete 15
setblock ~49 ~18 ~58 stained_hardened_clay 7
setblock ~49 ~18 ~59 gold_ore 0
setblock ~49 ~18 ~60 stained_hardened_clay 13
setblock ~49 ~18 ~80 concrete 15
setblock ~50 ~18 ~28 planks 2
setblock ~50 ~18 ~36 concrete 15
fill ~50 ~18 ~42 ~53 ~18 ~42 planks 2
setblock ~50 ~18 ~43 orange_glazed_terracotta 0
setblock ~50 ~18 ~45 orange_glazed_terracotta 0
setblock ~50 ~18 ~47 orange_glazed_terracotta 0
setblock ~50 ~18 ~58 stained_hardened_clay 5
setblock ~50 ~18 ~59 wool 15
setblock ~50 ~18 ~60 stained_hardened_clay 5
fill ~50 ~18 ~61 ~51 ~18 ~61 concrete 15
fill ~50 ~18 ~62 ~51 ~18 ~62 concrete 15
setblock ~50 ~18 ~79 concrete 15
fill ~51 ~18 ~29 ~51 ~18 ~30 planks 2
setblock ~51 ~18 ~34 concrete 15
fill ~51 ~18 ~40 ~52 ~18 ~40 planks 2
fill ~51 ~18 ~41 ~51 ~18 ~40 planks 2
setblock ~51 ~18 ~43 planks 2
setblock ~51 ~18 ~45 planks 2
setblock ~51 ~18 ~47 planks 2
setblock ~51 ~18 ~58 concrete 15
setblock ~51 ~18 ~59 bedrock 0
setblock ~51 ~18 ~60 stained_hardened_clay 13
fill ~51 ~18 ~63 ~51 ~18 ~65 concrete 15
fill ~51 ~18 ~77 ~51 ~18 ~78 concrete 15
fill ~52 ~18 ~29 ~52 ~27 ~29 orange_glazed_terracotta 0
fill ~52 ~18 ~30 ~54 ~18 ~30 planks 2
setblock ~52 ~18 ~31 orange_glazed_terracotta 0
fill ~52 ~18 ~32 ~56 ~18 ~32 planks 2
setblock ~52 ~18 ~35 concrete 15
setblock ~52 ~18 ~37 orange_glazed_terracotta 0
setblock ~52 ~18 ~38 stained_hardened_clay 7
setblock ~52 ~18 ~39 orange_glazed_terracotta 0
setblock ~52 ~18 ~41 orange_glazed_terracotta 0
setblock ~52 ~18 ~43 orange_glazed_terracotta 0
setblock ~52 ~18 ~45 orange_glazed_terracotta 0
fill ~52 ~18 ~59 ~52 ~40 ~59 orange_glazed_terracotta 0
fill ~52 ~18 ~65 ~52 ~18 ~76 concrete 15
fill ~53 ~18 ~29 ~53 ~20 ~29 planks 2
setblock ~53 ~18 ~31 planks 2
fill ~53 ~18 ~33 ~53 ~18 ~35 planks 2
setblock ~53 ~18 ~36 stained_hardened_clay 13
setblock ~53 ~18 ~37 stained_hardened_clay 7
setblock ~53 ~18 ~38 concrete 7
fill ~53 ~18 ~39 ~54 ~18 ~39 stained_hardened_clay 13
setblock ~53 ~18 ~40 green_glazed_terracotta 0
setblock ~53 ~18 ~41 planks 2
setblock ~53 ~18 ~43 planks 2
fill ~53 ~18 ~59 ~53 ~43 ~59 planks 2
setblock ~54 ~18 ~31 orange_glazed_terracotta 0
setblock ~54 ~18 ~33 orange_glazed_terracotta 0
fill ~54 ~18 ~34 ~57 ~18 ~34 planks 2
setblock ~54 ~18 ~35 orange_glazed_terracotta 0
fill ~54 ~18 ~36 ~55 ~18 ~36 planks 2
setblock ~54 ~18 ~37 orange_glazed_terracotta 0
fill ~54 ~18 ~38 ~55 ~18 ~38 planks 2
fill ~54 ~18 ~40 ~54 ~18 ~41 stained_hardened_clay 13
setblock ~54 ~18 ~42 stained_hardened_clay 5
setblock ~54 ~18 ~58 planks 2
fill ~55 ~18 ~31 ~55 ~22 ~31 planks 2
setblock ~55 ~18 ~33 planks 2
setblock ~55 ~18 ~35 planks 2
setblock ~55 ~18 ~37 planks 2
fill ~55 ~18 ~39 ~55 ~18 ~40 planks 2
setblock ~56 ~18 ~33 orange_glazed_terracotta 0
setblock ~56 ~18 ~35 orange_glazed_terracotta 0
setblock ~56 ~18 ~56 planks 2
fill ~57 ~18 ~33 ~57 ~19 ~33 planks 2
setblock ~57 ~18 ~54 planks 2
fill ~58 ~18 ~35 ~58 ~19 ~35 orange_glazed_terracotta 0
fill ~58 ~18 ~36 ~61 ~18 ~36 planks 2
fill ~58 ~18 ~38 ~61 ~18 ~38 planks 2
setblock ~58 ~18 ~50 planks 2
setblock ~58 ~18 ~52 planks 2
fill ~59 ~18 ~37 ~59 ~33 ~37 planks 2
fill ~59 ~18 ~40 ~61 ~18 ~40 planks 2
fill ~59 ~18 ~42 ~61 ~18 ~42 planks 2
setblock ~59 ~18 ~44 planks 2
setblock ~59 ~18 ~46 planks 2
setblock ~59 ~18 ~48 planks 2
fill ~60 ~18 ~33 ~60 ~28 ~33 orange_glazed_terracotta 0
fill ~60 ~18 ~34 ~61 ~18 ~34 planks 2
fill ~60 ~18 ~35 ~60 ~37 ~35 orange_glazed_terracotta 0
setblock ~60 ~18 ~37 orange_glazed_terracotta 0
setblock ~60 ~18 ~39 orange_glazed_terracotta 0
setblock ~60 ~18 ~41 orange_glazed_terracotta 0
setblock ~60 ~18 ~43 orange_glazed_terracotta 0
fill ~60 ~18 ~49 ~60 ~19 ~49 orange_glazed_terracotta 0
setblock ~60 ~18 ~50 planks 2
fill ~60 ~18 ~51 ~60 ~25 ~51 orange_glazed_terracotta 0
setblock ~60 ~18 ~52 planks 2
fill ~61 ~18 ~32 ~61 ~18 ~46 planks 2
setblock ~61 ~18 ~54 planks 2
setblock ~62 ~18 ~30 planks 2
setblock ~62 ~18 ~42 stained_hardened_clay 5
setblock ~62 ~18 ~43 stained_hardened_clay 13
fill ~62 ~18 ~44 ~62 ~18 ~45 stained_hardened_clay 5
setblock ~62 ~18 ~46 gold_ore 0
fill ~62 ~18 ~47 ~62 ~18 ~48 stained_hardened_clay 5
setblock ~62 ~18 ~49 orange_glazed_terracotta 0
setblock ~62 ~18 ~56 planks 2
fill ~62 ~18 ~57 ~62 ~53 ~57 orange_glazed_terracotta 0
setblock ~63 ~18 ~41 concrete 15
fill ~63 ~18 ~45 ~63 ~18 ~48 planks 2
setblock ~63 ~18 ~49 bedrock 0
setblock ~63 ~18 ~50 concrete 7
setblock ~63 ~18 ~51 stained_hardened_clay 7
setblock ~63 ~18 ~52 concrete 15
setblock ~63 ~18 ~58 planks 2
fill ~64 ~18 ~37 ~64 ~19 ~37 concrete 15
fill ~64 ~18 ~43 ~64 ~18 ~47 concrete 15
setblock ~64 ~18 ~48 bedrock 0
setblock ~64 ~18 ~49 stained_hardened_clay 7
setblock ~64 ~18 ~50 mossy_cobblestone 0
setblock ~64 ~18 ~51 stained_hardened_clay 13
setblock ~64 ~18 ~52 concrete 7
setblock ~64 ~18 ~53 stained_hardened_clay 13
setblock ~64 ~18 ~54 stained_hardened_clay 5
setblock ~64 ~18 ~60 planks 2
fill ~65 ~18 ~35 ~65 ~19 ~35 concrete 15
fill ~65 ~18 ~41 ~65 ~19 ~41 concrete 15
fill ~65 ~18 ~49 ~65 ~18 ~52 planks 2
setblock ~65 ~18 ~53 mossy_cobblestone 0
setblock ~65 ~18 ~54 stained_hardened_clay 13
setblock ~65 ~18 ~55 bedrock 0
setblock ~65 ~18 ~56 stained_hardened_clay 13
fill ~65 ~18 ~57 ~65 ~18 ~59 concrete 15
fill ~65 ~18 ~61 ~65 ~29 ~61 planks 2
fill ~65 ~18 ~67 ~66 ~18 ~67 concrete 15
fill ~65 ~18 ~68 ~66 ~18 ~68 concrete 15
fill ~65 ~18 ~69 ~66 ~18 ~69 concrete 15
fill ~65 ~18 ~70 ~66 ~18 ~70 concrete 15
fill ~65 ~18 ~71 ~66 ~18 ~71 concrete 15
fill ~66 ~18 ~39 ~66 ~19 ~39 concrete 15
setblock ~66 ~18 ~51 orange_glazed_terracotta 0
fill ~66 ~18 ~52 ~67 ~18 ~52 planks 2
setblock ~66 ~18 ~53 orange_glazed_terracotta 0
fill ~66 ~18 ~54 ~68 ~18 ~54 planks 2
setblock ~66 ~18 ~55 stained_hardened_clay 13
setblock ~66 ~18 ~56 stained_hardened_clay 5
fill ~66 ~18 ~57 ~67 ~18 ~57 stained_hardened_clay 7
fill ~66 ~18 ~58 ~66 ~18 ~59 stained_hardened_clay 7
fill ~66 ~18 ~60 ~67 ~18 ~60 stained_hardened_clay 13
setblock ~66 ~18 ~61 stained_hardened_clay 7
setblock ~66 ~18 ~62 concrete 7
fill ~66 ~18 ~63 ~66 ~18 ~76 concrete 15
fill ~67 ~18 ~38 ~67 ~19 ~38 concrete 15
setblock ~67 ~18 ~53 planks 2
setblock ~67 ~18 ~55 planks 2
setblock ~67 ~18 ~56 green_glazed_terracotta 0
setblock ~67 ~18 ~58 stained_hardened_clay 13
setblock ~67 ~18 ~59 bedrock 0
setblock ~67 ~18 ~61 mossy_cobblestone 0
fill ~67 ~18 ~62 ~68 ~18 ~62 planks 2
fill ~67 ~18 ~77 ~67 ~18 ~78 concrete 15
fill ~68 ~18 ~37 ~69 ~18 ~37 concrete 15
setblock ~68 ~18 ~55 orange_glazed_terracotta 0
setblock ~68 ~18 ~56 bedrock 0
fill ~68 ~18 ~57 ~70 ~18 ~57 stained_hardened_clay 13
setblock ~68 ~18 ~58 mossy_cobblestone 0
setblock ~68 ~18 ~59 stained_hardened_clay 5
fill ~68 ~18 ~60 ~70 ~18 ~60 planks 2
setblock ~68 ~18 ~61 orange_glazed_terracotta 0
fill ~68 ~18 ~78 ~68 ~18 ~79 concrete 15
fill ~69 ~18 ~31 ~69 ~19 ~31 concrete 15
fill ~69 ~18 ~55 ~69 ~18 ~56 planks 2
setblock ~69 ~18 ~58 stained_hardened_clay 13
setblock ~69 ~18 ~59 planks 2
setblock ~69 ~18 ~61 planks 2
fill ~69 ~18 ~80 ~70 ~18 ~80 concrete 15
fill ~70 ~18 ~36 ~71 ~18 ~36 concrete 15
setblock ~70 ~18 ~58 concrete 7
setblock ~70 ~18 ~59 orange_glazed_terracotta 0
fill ~70 ~18 ~81 ~72 ~18 ~81 concrete 15
fill ~71 ~18 ~57 ~80 ~18 ~57 concrete 15
fill ~71 ~18 ~58 ~81 ~18 ~58 concrete 15
fill ~72 ~18 ~35 ~77 ~18 ~35 concrete 15
fill ~72 ~18 ~82 ~78 ~18 ~82 concrete 15
fill ~73 ~18 ~29 ~75 ~18 ~29 concrete 15
setblock ~76 ~18 ~28 concrete 15
fill ~77 ~18 ~29 ~80 ~18 ~29 concrete 15
setblock ~78 ~18 ~36 concrete 15
fill ~78 ~18 ~56 ~80 ~18 ~56 concrete 15
fill ~78 ~18 ~81 ~81 ~18 ~81 concrete 15
setblock ~79 ~18 ~37 concrete 15
fill ~80 ~18 ~38 ~80 ~18 ~39 concrete 15
setblock ~80 ~18 ~55 concrete 15
fill ~81 ~18 ~40 ~81 ~18 ~42 concrete 15
fill ~81 ~18 ~53 ~82 ~18 ~53 concrete 15
fill ~81 ~18 ~54 ~81 ~18 ~53 concrete 15
setblock ~81 ~18 ~55 bedrock 0
setblock ~81 ~18 ~56 stained_hardened_clay 7
setblock ~81 ~18 ~57 stained_hardened_clay 5
fill ~81 ~18 ~59 ~83 ~18 ~59 concrete 15
fill ~81 ~18 ~80 ~82 ~18 ~80 concrete 15
fill ~82 ~18 ~32 ~82 ~20 ~32 concrete 15
fill ~82 ~18 ~43 ~82 ~18 ~53 concrete 15
setblock ~82 ~18 ~54 stained_hardened_clay 5
setblock ~82 ~18 ~55 stained_hardened_clay 13
setblock ~82 ~18 ~56 stained_hardened_clay 5
setblock ~82 ~18 ~57 wool 15
setblock ~82 ~18 ~58 concrete 7
fill ~82 ~18 ~60 ~83 ~18 ~60 concrete 15
fill ~82 ~18 ~61 ~83 ~18 ~61 concrete 15
fill ~82 ~18 ~62 ~84 ~18 ~62 concrete 15
fill ~82 ~18 ~79 ~83 ~18 ~79 concrete 15
fill ~83 ~18 ~35 ~83 ~20 ~35 concrete 15
fill ~83 ~18 ~47 ~83 ~18 ~51 concrete 15
setblock ~83 ~18 ~52 stained_hardened_clay 13
setblock ~83 ~18 ~53 mossy_cobblestone 0
setblock ~83 ~18 ~54 green_glazed_terracotta 0
fill ~83 ~18 ~55 ~83 ~18 ~57 mossy_cobblestone 0
setblock ~83 ~18 ~58 green_glazed_terracotta 0
fill ~83 ~18 ~63 ~84 ~18 ~63 concrete 15
fill ~83 ~18 ~64 ~84 ~18 ~64 concrete 15
fill ~83 ~18 ~65 ~84 ~18 ~65 concrete 15
fill ~83 ~18 ~77 ~84 ~18 ~77 concrete 15
fill ~83 ~18 ~78 ~83 ~18 ~77 concrete 15
setblock ~84 ~18 ~28 planks 2
fill ~84 ~18 ~50 ~85 ~18 ~50 planks 2
setblock ~84 ~18 ~51 orange_glazed_terracotta 0
setblock ~84 ~18 ~52 planks 2
setblock ~84 ~18 ~53 orange_glazed_terracotta 0
setblock ~84 ~18 ~54 planks 2
setblock ~84 ~18 ~55 orange_glazed_terracotta 0
setblock ~84 ~18 ~57 orange_glazed_terracotta 0
setblock ~84 ~18 ~58 planks 2
fill ~84 ~18 ~66 ~84 ~18 ~77 concrete 15
fill ~85 ~18 ~29 ~85 ~22 ~29 planks 2
fill ~85 ~18 ~30 ~85 ~18 ~29 planks 2
fill ~85 ~18 ~47 ~85 ~18 ~51 planks 2
fill ~85 ~18 ~56 ~85 ~18 ~57 planks 2
fill ~85 ~18 ~67 ~85 ~18 ~75 concrete 15
fill ~86 ~18 ~31 ~86 ~23 ~31 orange_glazed_terracotta 0
setblock ~86 ~18 ~32 planks 2
fill ~86 ~18 ~33 ~86 ~43 ~33 orange_glazed_terracotta 0
fill ~86 ~18 ~34 ~87 ~18 ~34 planks 2
fill ~86 ~18 ~35 ~86 ~19 ~35 orange_glazed_terracotta 0
fill ~86 ~18 ~36 ~87 ~18 ~36 planks 2
fill ~86 ~18 ~37 ~86 ~19 ~37 orange_glazed_terracotta 0
fill ~86 ~18 ~41 ~86 ~19 ~41 orange_glazed_terracotta 0
setblock ~86 ~18 ~42 planks 2
setblock ~86 ~18 ~43 orange_glazed_terracotta 0
setblock ~86 ~18 ~44 planks 2
setblock ~86 ~18 ~45 orange_glazed_terracotta 0
setblock ~86 ~18 ~46 planks 2
setblock ~86 ~18 ~47 orange_glazed_terracotta 0
setblock ~86 ~18 ~53 orange_glazed_terracotta 0
setblock ~86 ~18 ~54 planks 2
fill ~86 ~18 ~55 ~86 ~26 ~55 orange_glazed_terracotta 0
setblock ~87 ~18 ~33 planks 2
fill ~87 ~18 ~35 ~87 ~48 ~35 planks 2
setblock ~87 ~18 ~38 planks 2
fill ~87 ~18 ~40 ~88 ~18 ~40 planks 2
setblock ~87 ~18 ~48 planks 2
setblock ~87 ~18 ~50 planks 2
setblock ~87 ~18 ~52 planks 2
setblock ~88 ~18 ~42 planks 2
setblock ~88 ~18 ~44 planks 2
setblock ~88 ~18 ~46 planks 2
fill ~30 ~19 ~40 ~33 ~19 ~40 orange_glazed_terracotta 0
fill ~30 ~19 ~41 ~30 ~50 ~41 orange_glazed_terracotta 0
fill ~30 ~19 ~42 ~33 ~19 ~42 orange_glazed_terracotta 0
fill ~30 ~19 ~43 ~30 ~45 ~43 orange_glazed_terracotta 0
fill ~30 ~19 ~44 ~47 ~19 ~44 orange_glazed_terracotta 0
setblock ~30 ~19 ~46 orange_glazed_terracotta 0
setblock ~30 ~19 ~48 orange_glazed_terracotta 0
setblock ~30 ~19 ~50 orange_glazed_terracotta 0
setblock ~30 ~19 ~52 orange_glazed_terracotta 0
setblock ~31 ~19 ~39 planks 2
setblock ~31 ~19 ~41 planks 2
setblock ~31 ~19 ~43 planks 2
setblock ~31 ~19 ~45 planks 2
fill ~31 ~19 ~54 ~31 ~21 ~54 orange_glazed_terracotta 0
setblock ~32 ~19 ~41 orange_glazed_terracotta 0
setblock ~32 ~19 ~43 orange_glazed_terracotta 0
setblock ~32 ~19 ~45 orange_glazed_terracotta 0
setblock ~32 ~19 ~56 orange_glazed_terracotta 0
fill ~32 ~19 ~68 ~33 ~19 ~68 concrete 15
fill ~32 ~19 ~69 ~33 ~19 ~69 concrete 15
fill ~32 ~19 ~70 ~33 ~19 ~70 concrete 15
fill ~32 ~19 ~71 ~33 ~19 ~71 concrete 15
fill ~32 ~19 ~72 ~32 ~19 ~75 concrete 15
setblock ~33 ~19 ~41 planks 2
setblock ~33 ~19 ~43 planks 2
setblock ~33 ~19 ~45 planks 2
fill ~33 ~19 ~64 ~35 ~19 ~64 concrete 15
fill ~33 ~19 ~65 ~34 ~19 ~65 concrete 15
fill ~33 ~19 ~66 ~34 ~19 ~66 concrete 15
fill ~33 ~19 ~67 ~33 ~19 ~64 concrete 15
fill ~33 ~19 ~74 ~33 ~19 ~78 concrete 15
fill ~34 ~19 ~38 ~35 ~19 ~38 concrete 15
fill ~34 ~19 ~39 ~35 ~19 ~39 concrete 15
fill ~34 ~19 ~40 ~34 ~19 ~35 concrete 15
fill ~34 ~19 ~41 ~34 ~19 ~42 stained_hardened_clay 13
setblock ~34 ~19 ~43 orange_glazed_terracotta 0
setblock ~34 ~19 ~45 orange_glazed_terracotta 0
fill ~34 ~19 ~58 ~35 ~19 ~58 orange_glazed_terracotta 0
fill ~34 ~19 ~61 ~38 ~19 ~61 concrete 15
fill ~34 ~19 ~62 ~36 ~19 ~62 concrete 15
fill ~34 ~19 ~63 ~35 ~19 ~63 concrete 15
fill ~34 ~19 ~78 ~34 ~19 ~79 concrete 15
fill ~35 ~19 ~33 ~35 ~19 ~34 concrete 15
fill ~35 ~19 ~36 ~36 ~19 ~36 concrete 15
fill ~35 ~19 ~37 ~35 ~19 ~36 concrete 15
setblock ~35 ~19 ~41 planks 2
fill ~35 ~19 ~42 ~49 ~19 ~42 orange_glazed_terracotta 0
setblock ~35 ~19 ~43 planks 2
setblock ~35 ~19 ~45 planks 2
fill ~35 ~19 ~46 ~45 ~19 ~46 orange_glazed_terracotta 0
fill ~35 ~19 ~59 ~35 ~21 ~59 planks 2
fill ~35 ~19 ~60 ~37 ~19 ~60 concrete 15
fill ~35 ~19 ~79 ~35 ~19 ~80 concrete 15
setblock ~36 ~19 ~31 concrete 15
setblock ~36 ~19 ~35 concrete 15
setblock ~36 ~19 ~41 orange_glazed_terracotta 0
setblock ~36 ~19 ~43 orange_glazed_terracotta 0
setblock ~36 ~19 ~45 orange_glazed_terracotta 0
fill ~36 ~19 ~58 ~41 ~19 ~58 stained_hardened_clay 13
setblock ~36 ~19 ~59 green_glazed_terracotta 0
setblock ~36 ~19 ~80 concrete 15
setblock ~37 ~19 ~30 concrete 15
setblock ~37 ~19 ~34 concrete 15
setblock ~37 ~19 ~41 planks 2
setblock ~37 ~19 ~43 planks 2
setblock ~37 ~19 ~45 planks 2
setblock ~37 ~19 ~59 stained_hardened_clay 5
fill ~37 ~19 ~81 ~40 ~19 ~81 concrete 15
fill ~38 ~19 ~29 ~43 ~19 ~29 concrete 15
fill ~38 ~19 ~33 ~39 ~19 ~33 concrete 15
setblock ~38 ~19 ~41 orange_glazed_terracotta 0
setblock ~38 ~19 ~43 orange_glazed_terracotta 0
setblock ~38 ~19 ~45 orange_glazed_terracotta 0
fill ~38 ~19 ~59 ~38 ~19 ~60 stained_hardened_clay 13
setblock ~39 ~19 ~41 planks 2
setblock ~39 ~19 ~43 planks 2
setblock ~39 ~19 ~45 planks 2
setblock ~39 ~19 ~47 planks 2
setblock ~39 ~19 ~59 bedrock 0
fill ~39 ~19 ~60 ~41 ~19 ~60 stained_hardened_clay 13
fill ~40 ~19 ~32 ~45 ~19 ~32 concrete 15
setblock ~40 ~19 ~41 orange_glazed_terracotta 0
setblock ~40 ~19 ~43 orange_glazed_terracotta 0
setblock ~40 ~19 ~45 orange_glazed_terracotta 0
setblock ~40 ~19 ~47 orange_glazed_terracotta 0
setblock ~40 ~19 ~59 stained_hardened_clay 13
fill ~40 ~19 ~82 ~43 ~19 ~82 concrete 15
fill ~41 ~19 ~27 ~41 ~37 ~27 planks 2
setblock ~41 ~19 ~41 planks 2
setblock ~41 ~19 ~43 planks 2
setblock ~41 ~19 ~45 planks 2
setblock ~41 ~19 ~47 planks 2
setblock ~41 ~19 ~59 bedrock 0
fill ~42 ~19 ~27 ~42 ~36 ~27 orange_glazed_terracotta 0
fill ~42 ~19 ~28 ~51 ~19 ~28 orange_glazed_terracotta 0
setblock ~42 ~19 ~41 orange_glazed_terracotta 0
setblock ~42 ~19 ~43 orange_glazed_terracotta 0
setblock ~42 ~19 ~45 orange_glazed_terracotta 0
setblock ~42 ~19 ~47 orange_glazed_terracotta 0
setblock ~42 ~19 ~59 stained_hardened_clay 7
setblock ~42 ~19 ~60 stained_hardened_clay 5
fill ~43 ~19 ~27 ~43 ~36 ~27 planks 2
setblock ~43 ~19 ~41 planks 2
setblock ~43 ~19 ~43 planks 2
setblock ~43 ~19 ~45 planks 2
setblock ~43 ~19 ~47 planks 2
setblock ~43 ~19 ~59 bedrock 0
setblock ~43 ~19 ~60 stained_hardened_clay 13
fill ~43 ~19 ~61 ~44 ~19 ~61 concrete 15
fill ~43 ~19 ~81 ~46 ~19 ~81 concrete 15
fill ~44 ~19 ~27 ~44 ~37 ~27 orange_glazed_terracotta 0
setblock ~44 ~19 ~29 stained_hardened_clay 7
fill ~44 ~19 ~40 ~50 ~19 ~40 orange_glazed_terracotta 0
fill ~44 ~19 ~41 ~44 ~19 ~40 orange_glazed_terracotta 0
setblock ~44 ~19 ~43 orange_glazed_terracotta 0
setblock ~44 ~19 ~45 orange_glazed_terracotta 0
setblock ~44 ~19 ~59 stained_hardened_clay 13
setblock ~44 ~19 ~60 concrete 13
fill ~45 ~19 ~27 ~45 ~39 ~27 planks 2
setblock ~45 ~19 ~29 planks 2
setblock ~45 ~19 ~30 stained_hardened_clay 13
setblock ~45 ~19 ~39 planks 2
setblock ~45 ~19 ~41 planks 2
setblock ~45 ~19 ~43 planks 2
setblock ~45 ~19 ~45 planks 2
fill ~45 ~19 ~59 ~46 ~19 ~59 concrete 15
fill ~45 ~19 ~60 ~46 ~19 ~60 stained_hardened_clay 7
setblock ~45 ~19 ~61 bedrock 0
fill ~46 ~19 ~27 ~46 ~41 ~27 orange_glazed_terracotta 0
setblock ~46 ~19 ~29 orange_glazed_terracotta 0
setblock ~46 ~19 ~30 stained_hardened_clay 15
setblock ~46 ~19 ~31 orange_glazed_terracotta 0
fill ~46 ~19 ~33 ~47 ~19 ~33 concrete 15
fill ~46 ~19 ~38 ~51 ~19 ~38 orange_glazed_terracotta 0
fill ~46 ~19 ~39 ~46 ~19 ~38 orange_glazed_terracotta 0
setblock ~46 ~19 ~41 orange_glazed_terracotta 0
setblock ~46 ~19 ~43 orange_glazed_terracotta 0
setblock ~46 ~19 ~45 orange_glazed_terracotta 0
setblock ~46 ~19 ~61 stained_hardened_clay 5
fill ~46 ~19 ~62 ~49 ~19 ~62 concrete 15
fill ~47 ~19 ~27 ~47 ~44 ~27 planks 2
setblock ~47 ~19 ~29 planks 2
fill ~47 ~19 ~30 ~50 ~19 ~30 orange_glazed_terracotta 0
setblock ~47 ~19 ~31 stained_hardened_clay 7
fill ~47 ~19 ~32 ~48 ~19 ~32 orange_glazed_terracotta 0
fill ~47 ~19 ~36 ~50 ~19 ~36 orange_glazed_terracotta 0
setblock ~47 ~19 ~37 planks 2
setblock ~47 ~19 ~39 planks 2
setblock ~47 ~19 ~41 planks 2
setblock ~47 ~19 ~43 planks 2
setblock ~47 ~19 ~60 stained_hardened_clay 13
fill ~47 ~19 ~61 ~48 ~19 ~61 stained_hardened_clay 7
fill ~47 ~19 ~80 ~48 ~19 ~80 concrete 15
fill ~48 ~19 ~27 ~48 ~24 ~27 orange_glazed_terracotta 0
setblock ~48 ~19 ~29 orange_glazed_terracotta 0
setblock ~48 ~19 ~31 stained_hardened_clay 15
setblock ~48 ~19 ~33 orange_glazed_terracotta 0
setblock ~48 ~19 ~34 stained_hardened_clay 13
setblock ~48 ~19 ~35 orange_glazed_terracotta 0
setblock ~48 ~19 ~37 orange_glazed_terracotta 0
setblock ~48 ~19 ~39 orange_glazed_terracotta 0
setblock ~48 ~19 ~41 orange_glazed_terracotta 0
setblock ~48 ~19 ~43 orange_glazed_terracotta 0
setblock ~48 ~19 ~60 concrete 15
fill ~48 ~19 ~63 ~50 ~19 ~63 concrete 15
fill ~48 ~19 ~64 ~50 ~19 ~64 concrete 15
fill ~48 ~19 ~79 ~49 ~19 ~79 concrete 15
setblock ~49 ~19 ~29 planks 2
setblock ~49 ~19 ~31 planks 2
setblock ~49 ~19 ~32 stained_hardened_clay 15
setblock ~49 ~19 ~33 planks 2
setblock ~49 ~19 ~34 stained_hardened_clay 15
setblock ~49 ~19 ~35 planks 2
setblock ~49 ~19 ~37 planks 2
setblock ~49 ~19 ~39 planks 2
setblock ~49 ~19 ~41 planks 2
fill ~49 ~19 ~60 ~51 ~19 ~60 orange_glazed_terracotta 0
setblock ~49 ~19 ~61 concrete 15
fill ~49 ~19 ~65 ~50 ~19 ~65 concrete 15
fill ~49 ~19 ~66 ~51 ~19 ~66 concrete 15
fill ~49 ~19 ~78 ~50 ~19 ~78 concrete 15
setblock ~50 ~19 ~29 orange_glazed_terracotta 0
fill ~50 ~19 ~31 ~50 ~19 ~32 orange_glazed_terracotta 0
setblock ~50 ~19 ~33 stained_hardened_clay 13
setblock ~50 ~19 ~34 green_glazed_terracotta 0
setblock ~50 ~19 ~35 stained_hardened_clay 13
setblock ~50 ~19 ~37 orange_glazed_terracotta 0
setblock ~50 ~19 ~39 orange_glazed_terracotta 0
setblock ~50 ~19 ~41 orange_glazed_terracotta 0
fill ~50 ~19 ~67 ~51 ~19 ~67 concrete 15
fill ~50 ~19 ~68 ~51 ~19 ~68 concrete 15
fill ~50 ~19 ~69 ~51 ~19 ~69 concrete 15
fill ~50 ~19 ~70 ~51 ~19 ~70 concrete 15
fill ~50 ~19 ~74 ~51 ~19 ~74 concrete 15
fill ~50 ~19 ~75 ~51 ~19 ~75 concrete 15
fill ~50 ~19 ~76 ~51 ~19 ~76 concrete 15
fill ~50 ~19 ~77 ~50 ~19 ~74 concrete 15
setblock ~51 ~19 ~31 planks 2
setblock ~51 ~19 ~32 orange_glazed_terracotta 0
setblock ~51 ~19 ~33 planks 2
fill ~51 ~19 ~34 ~51 ~19 ~36 stained_hardened_clay 7
setblock ~51 ~19 ~37 planks 2
setblock ~51 ~19 ~39 planks 2
fill ~51 ~19 ~71 ~51 ~19 ~76 concrete 15
fill ~52 ~19 ~33 ~52 ~19 ~35 orange_glazed_terracotta 0
setblock ~52 ~19 ~36 stained_hardened_clay 13
setblock ~52 ~19 ~37 concrete 15
setblock ~54 ~19 ~30 orange_glazed_terracotta 0
setblock ~54 ~19 ~58 orange_glazed_terracotta 0
setblock ~56 ~19 ~32 orange_glazed_terracotta 0
setblock ~56 ~19 ~56 orange_glazed_terracotta 0
setblock ~57 ~19 ~34 orange_glazed_terracotta 0
setblock ~57 ~19 ~54 orange_glazed_terracotta 0
fill ~58 ~19 ~36 ~59 ~19 ~36 orange_glazed_terracotta 0
fill ~58 ~19 ~38 ~59 ~19 ~38 orange_glazed_terracotta 0
setblock ~58 ~19 ~50 orange_glazed_terracotta 0
setblock ~58 ~19 ~52 orange_glazed_terracotta 0
setblock ~59 ~19 ~40 orange_glazed_terracotta 0
fill ~59 ~19 ~42 ~59 ~21 ~42 orange_glazed_terracotta 0
setblock ~59 ~19 ~44 orange_glazed_terracotta 0
fill ~59 ~19 ~46 ~59 ~21 ~46 orange_glazed_terracotta 0
setblock ~59 ~19 ~48 orange_glazed_terracotta 0
setblock ~60 ~19 ~34 orange_glazed_terracotta 0
setblock ~60 ~19 ~50 orange_glazed_terracotta 0
fill ~60 ~19 ~52 ~60 ~19 ~53 orange_glazed_terracotta 0
fill ~61 ~19 ~31 ~61 ~28 ~31 planks 2
fill ~61 ~19 ~32 ~63 ~19 ~32 orange_glazed_terracotta 0
fill ~61 ~19 ~54 ~61 ~21 ~54 orange_glazed_terracotta 0
fill ~62 ~19 ~29 ~62 ~20 ~29 orange_glazed_terracotta 0
fill ~62 ~19 ~30 ~64 ~19 ~30 orange_glazed_terracotta 0
fill ~62 ~19 ~31 ~62 ~19 ~29 orange_glazed_terracotta 0
fill ~62 ~19 ~33 ~62 ~19 ~41 orange_glazed_terracotta 0
setblock ~62 ~19 ~56 orange_glazed_terracotta 0
setblock ~62 ~19 ~58 orange_glazed_terracotta 0
fill ~63 ~19 ~28 ~65 ~19 ~28 orange_glazed_terracotta 0
setblock ~63 ~19 ~29 planks 2
setblock ~63 ~19 ~31 planks 2
setblock ~63 ~19 ~33 planks 2
setblock ~63 ~19 ~34 orange_glazed_terracotta 0
setblock ~63 ~19 ~35 planks 2
setblock ~63 ~19 ~36 orange_glazed_terracotta 0
setblock ~63 ~19 ~37 planks 2
setblock ~63 ~19 ~38 orange_glazed_terracotta 0
setblock ~63 ~19 ~39 bedrock 0
setblock ~63 ~19 ~40 stained_hardened_clay 13
setblock ~63 ~19 ~41 bedrock 0
setblock ~63 ~19 ~42 stained_hardened_clay 5
setblock ~63 ~19 ~43 bedrock 0
setblock ~63 ~19 ~44 stained_hardened_clay 7
fill ~63 ~19 ~45 ~63 ~19 ~48 concrete 15
fill ~64 ~19 ~27 ~64 ~22 ~27 orange_glazed_terracotta 0
setblock ~64 ~19 ~29 orange_glazed_terracotta 0
setblock ~64 ~19 ~38 concrete 15
setblock ~64 ~19 ~41 orange_glazed_terracotta 0
setblock ~64 ~19 ~42 stained_hardened_clay 7
setblock ~64 ~19 ~43 stained_hardened_clay 13
setblock ~64 ~19 ~44 stained_hardened_clay 5
fill ~64 ~19 ~45 ~64 ~19 ~47 orange_glazed_terracotta 0
setblock ~64 ~19 ~60 orange_glazed_terracotta 0
fill ~65 ~19 ~27 ~65 ~32 ~27 planks 2
setblock ~65 ~19 ~36 concrete 15
setblock ~65 ~19 ~40 concrete 15
setblock ~65 ~19 ~43 planks 2
setblock ~65 ~19 ~44 orange_glazed_terracotta 0
setblock ~65 ~19 ~45 planks 2
fill ~65 ~19 ~46 ~66 ~19 ~46 orange_glazed_terracotta 0
setblock ~65 ~19 ~47 planks 2
fill ~65 ~19 ~48 ~68 ~19 ~48 orange_glazed_terracotta 0
fill ~66 ~19 ~26 ~67 ~19 ~26 orange_glazed_terracotta 0
fill ~66 ~19 ~27 ~66 ~19 ~26 orange_glazed_terracotta 0
fill ~66 ~19 ~34 ~66 ~20 ~34 concrete 15
setblock ~66 ~19 ~45 orange_glazed_terracotta 0
setblock ~66 ~19 ~47 orange_glazed_terracotta 0
fill ~66 ~19 ~49 ~66 ~19 ~50 orange_glazed_terracotta 0
setblock ~66 ~19 ~62 orange_glazed_terracotta 0
fill ~67 ~19 ~25 ~67 ~25 ~25 planks 2
fill ~67 ~19 ~33 ~67 ~20 ~33 concrete 15
setblock ~67 ~19 ~47 planks 2
setblock ~67 ~19 ~49 planks 2
fill ~67 ~19 ~50 ~70 ~19 ~50 orange_glazed_terracotta 0
setblock ~67 ~19 ~51 planks 2
setblock ~67 ~19 ~62 green_glazed_terracotta 0
fill ~67 ~19 ~63 ~71 ~19 ~63 concrete 15
fill ~67 ~19 ~64 ~69 ~19 ~64 concrete 15
fill ~67 ~19 ~65 ~69 ~19 ~65 concrete 15
fill ~67 ~19 ~66 ~69 ~19 ~66 concrete 15
fill ~67 ~19 ~67 ~68 ~19 ~67 concrete 15
fill ~67 ~19 ~68 ~68 ~19 ~68 concrete 15
fill ~67 ~19 ~69 ~68 ~19 ~69 concrete 15
fill ~67 ~19 ~70 ~68 ~19 ~70 concrete 15
fill ~67 ~19 ~71 ~68 ~19 ~71 concrete 15
fill ~67 ~19 ~72 ~68 ~19 ~72 concrete 15
fill ~67 ~19 ~73 ~68 ~19 ~73 concrete 15
fill ~67 ~19 ~74 ~68 ~19 ~74 concrete 15
fill ~67 ~19 ~75 ~68 ~19 ~75 concrete 15
fill ~67 ~19 ~76 ~69 ~19 ~76 concrete 15
fill ~68 ~19 ~25 ~68 ~33 ~25 orange_glazed_terracotta 0
fill ~68 ~19 ~32 ~68 ~20 ~32 concrete 15
fill ~68 ~19 ~37 ~68 ~18 ~37 concrete 15
setblock ~68 ~19 ~49 orange_glazed_terracotta 0
fill ~68 ~19 ~51 ~68 ~19 ~53 orange_glazed_terracotta 0
fill ~68 ~19 ~60 ~70 ~19 ~60 concrete 15
fill ~68 ~19 ~61 ~69 ~19 ~61 concrete 15
fill ~68 ~19 ~62 ~69 ~19 ~62 stained_hardened_clay 13
fill ~68 ~19 ~77 ~69 ~19 ~77 concrete 15
setblock ~69 ~19 ~25 planks 2
fill ~69 ~19 ~36 ~70 ~19 ~36 concrete 15
setblock ~69 ~19 ~49 planks 2
setblock ~69 ~19 ~51 planks 2
fill ~69 ~19 ~52 ~73 ~19 ~52 orange_glazed_terracotta 0
setblock ~69 ~19 ~53 planks 2
fill ~69 ~19 ~54 ~81 ~19 ~54 orange_glazed_terracotta 0
fill ~69 ~19 ~59 ~70 ~19 ~59 concrete 15
fill ~69 ~19 ~78 ~70 ~19 ~78 concrete 15
fill ~69 ~19 ~79 ~72 ~19 ~79 concrete 15
setblock ~70 ~19 ~51 orange_glazed_terracotta 0
setblock ~70 ~19 ~53 orange_glazed_terracotta 0
fill ~70 ~19 ~55 ~70 ~19 ~56 orange_glazed_terracotta 0
setblock ~70 ~19 ~61 stained_hardened_clay 15
setblock ~70 ~19 ~62 green_glazed_terracotta 0
fill ~71 ~19 ~24 ~73 ~19 ~24 orange_glazed_terracotta 0
fill ~71 ~19 ~30 ~72 ~19 ~30 concrete 15
fill ~71 ~19 ~35 ~72 ~19 ~35 concrete 15
setblock ~71 ~19 ~51 planks 2
setblock ~71 ~19 ~53 planks 2
setblock ~71 ~19 ~55 planks 2
fill ~71 ~19 ~56 ~80 ~19 ~56 orange_glazed_terracotta 0
setblock ~71 ~19 ~57 planks 2
fill ~71 ~19 ~58 ~81 ~19 ~58 orange_glazed_terracotta 0
setblock ~71 ~19 ~59 bedrock 0
setblock ~71 ~19 ~60 stained_hardened_clay 13
setblock ~71 ~19 ~61 bedrock 0
setblock ~71 ~19 ~62 stained_hardened_clay 13
fill ~71 ~19 ~80 ~80 ~19 ~80 concrete 15
setblock ~72 ~19 ~53 orange_glazed_terracotta 0
setblock ~72 ~19 ~55 orange_glazed_terracotta 0
setblock ~72 ~19 ~57 orange_glazed_terracotta 0
setblock ~72 ~19 ~59 stained_hardened_clay 13
setblock ~72 ~19 ~60 stained_hardened_clay 15
setblock ~72 ~19 ~61 green_glazed_terracotta 0
fill ~72 ~19 ~62 ~81 ~19 ~62 concrete 15
fill ~73 ~19 ~29 ~79 ~19 ~29 concrete 15
fill ~73 ~19 ~34 ~76 ~19 ~34 concrete 15
setblock ~73 ~19 ~53 planks 2
setblock ~73 ~19 ~55 planks 2
setblock ~73 ~19 ~57 planks 2
setblock ~73 ~19 ~59 bedrock 0
setblock ~73 ~19 ~60 stained_hardened_clay 5
setblock ~73 ~19 ~61 stained_hardened_clay 13
fill ~73 ~19 ~81 ~77 ~19 ~81 concrete 15
setblock ~74 ~19 ~53 orange_glazed_terracotta 0
setblock ~74 ~19 ~55 orange_glazed_terracotta 0
setblock ~74 ~19 ~57 orange_glazed_terracotta 0
setblock ~74 ~19 ~59 green_glazed_terracotta 0
fill ~74 ~19 ~60 ~75 ~19 ~60 stained_hardened_clay 7
fill ~74 ~19 ~61 ~81 ~19 ~61 concrete 15
setblock ~75 ~19 ~53 planks 2
setblock ~75 ~19 ~55 planks 2
setblock ~75 ~19 ~57 planks 2
setblock ~75 ~19 ~59 bedrock 0
setblock ~76 ~19 ~53 orange_glazed_terracotta 0
setblock ~76 ~19 ~55 orange_glazed_terracotta 0
setblock ~76 ~19 ~57 orange_glazed_terracotta 0
setblock ~76 ~19 ~59 stained_hardened_clay 13
setblock ~76 ~19 ~60 stained_hardened_clay 15
fill ~77 ~19 ~24 ~78 ~19 ~24 orange_glazed_terracotta 0
fill ~77 ~19 ~35 ~78 ~19 ~35 concrete 15
setblock ~77 ~19 ~53 planks 2
setblock ~77 ~19 ~55 planks 2
setblock ~77 ~19 ~57 planks 2
setblock ~77 ~19 ~59 bedrock 0
fill ~77 ~19 ~60 ~81 ~19 ~60 concrete 15
setblock ~78 ~19 ~53 orange_glazed_terracotta 0
setblock ~78 ~19 ~55 orange_glazed_terracotta 0
setblock ~78 ~19 ~57 orange_glazed_terracotta 0
setblock ~78 ~19 ~59 stained_hardened_clay 13
fill ~78 ~19 ~63 ~82 ~19 ~63 concrete 15
fill ~78 ~19 ~79 ~81 ~19 ~79 concrete 15
setblock ~79 ~19 ~36 concrete 15
fill ~79 ~19 ~52 ~82 ~19 ~52 orange_glazed_terracotta 0
setblock ~79 ~19 ~53 planks 2
setblock ~79 ~19 ~55 planks 2
setblock ~79 ~19 ~57 planks 2
setblock ~79 ~19 ~59 mossy_cobblestone 0
fill ~79 ~19 ~64 ~82 ~19 ~64 concrete 15
fill ~80 ~19 ~24 ~80 ~19 ~25 orange_glazed_terracotta 0
fill ~80 ~19 ~30 ~80 ~20 ~30 concrete 15
setblock ~80 ~19 ~37 concrete 15
setblock ~80 ~19 ~51 orange_glazed_terracotta 0
setblock ~80 ~19 ~53 orange_glazed_terracotta 0
setblock ~80 ~19 ~55 orange_glazed_terracotta 0
setblock ~80 ~19 ~57 orange_glazed_terracotta 0
setblock ~80 ~19 ~59 green_glazed_terracotta 0
fill ~80 ~19 ~65 ~82 ~19 ~65 concrete 15
fill ~80 ~19 ~77 ~82 ~19 ~77 concrete 15
fill ~80 ~19 ~78 ~82 ~19 ~78 concrete 15
fill ~81 ~19 ~25 ~81 ~25 ~25 planks 2
fill ~81 ~19 ~31 ~81 ~20 ~31 concrete 15
fill ~81 ~19 ~38 ~81 ~19 ~39 concrete 15
fill ~81 ~19 ~50 ~83 ~19 ~50 orange_glazed_terracotta 0
setblock ~81 ~19 ~51 planks 2
setblock ~81 ~19 ~53 planks 2
setblock ~81 ~19 ~59 planks 2
fill ~81 ~19 ~66 ~83 ~19 ~66 concrete 15
fill ~81 ~19 ~67 ~83 ~19 ~67 concrete 15
fill ~81 ~19 ~68 ~83 ~19 ~68 concrete 15
fill ~81 ~19 ~76 ~83 ~19 ~76 concrete 15
fill ~82 ~19 ~26 ~83 ~19 ~26 orange_glazed_terracotta 0
fill ~82 ~19 ~40 ~82 ~19 ~42 concrete 15
setblock ~82 ~19 ~49 orange_glazed_terracotta 0
setblock ~82 ~19 ~51 orange_glazed_terracotta 0
setblock ~82 ~19 ~53 orange_glazed_terracotta 0
fill ~82 ~19 ~59 ~82 ~26 ~59 orange_glazed_terracotta 0
fill ~82 ~19 ~69 ~83 ~19 ~69 concrete 15
fill ~82 ~19 ~70 ~83 ~19 ~70 concrete 15
fill ~82 ~19 ~71 ~83 ~19 ~71 concrete 15
fill ~82 ~19 ~72 ~83 ~19 ~72 concrete 15
fill ~82 ~19 ~73 ~83 ~19 ~73 concrete 15
fill ~82 ~19 ~74 ~83 ~19 ~74 concrete 15
fill ~82 ~19 ~75 ~83 ~19 ~75 concrete 15
fill ~83 ~19 ~27 ~83 ~28 ~27 planks 2
fill ~83 ~19 ~28 ~84 ~19 ~28 orange_glazed_terracotta 0
fill ~83 ~19 ~36 ~83 ~20 ~36 concrete 15
fill ~83 ~19 ~42 ~83 ~19 ~46 concrete 15
fill ~83 ~19 ~48 ~84 ~19 ~48 orange_glazed_terracotta 0
setblock ~83 ~19 ~49 planks 2
setblock ~83 ~19 ~51 planks 2
fill ~83 ~19 ~59 ~83 ~20 ~59 planks 2
fill ~84 ~19 ~29 ~84 ~19 ~30 orange_glazed_terracotta 0
fill ~84 ~19 ~46 ~85 ~19 ~46 orange_glazed_terracotta 0
fill ~84 ~19 ~47 ~84 ~19 ~46 orange_glazed_terracotta 0
setblock ~84 ~19 ~49 orange_glazed_terracotta 0
setblock ~84 ~19 ~58 orange_glazed_terracotta 0
fill ~85 ~19 ~30 ~85 ~21 ~30 orange_glazed_terracotta 0
setblock ~85 ~19 ~31 planks 2
fill ~85 ~19 ~32 ~86 ~19 ~32 orange_glazed_terracotta 0
setblock ~85 ~19 ~33 planks 2
fill ~85 ~19 ~42 ~86 ~19 ~42 orange_glazed_terracotta 0
setblock ~85 ~19 ~43 planks 2
setblock ~85 ~19 ~44 orange_glazed_terracotta 0
setblock ~85 ~19 ~45 planks 2
setblock ~85 ~19 ~56 orange_glazed_terracotta 0
fill ~85 ~19 ~57 ~85 ~22 ~57 planks 2
fill ~86 ~19 ~34 ~87 ~19 ~34 orange_glazed_terracotta 0
fill ~86 ~19 ~36 ~87 ~19 ~36 orange_glazed_terracotta 0
fill ~86 ~19 ~38 ~87 ~19 ~38 orange_glazed_terracotta 0
fill ~86 ~19 ~39 ~86 ~19 ~42 orange_glazed_terracotta 0
setblock ~86 ~19 ~54 orange_glazed_terracotta 0
setblock ~87 ~19 ~48 orange_glazed_terracotta 0
setblock ~87 ~19 ~50 orange_glazed_terracotta 0
setblock ~87 ~19 ~52 orange_glazed_terracotta 0
fill ~87 ~19 ~53 ~87 ~26 ~53 planks 2
fill ~88 ~19 ~39 ~88 ~50 ~39 orange_glazed_terracotta 0
fill ~88 ~19 ~40 ~88 ~19 ~39 orange_glazed_terracotta 0
setblock ~88 ~19 ~42 orange_glazed_terracotta 0
setblock ~88 ~19 ~44 orange_glazed_terracotta 0
fill ~88 ~19 ~46 ~88 ~19 ~47 orange_glazed_terracotta 0
setblock ~30 ~20 ~38 planks 2
fill ~30 ~20 ~39 ~30 ~55 ~39 orange_glazed_terracotta 0
setblock ~30 ~20 ~40 planks 2
setblock ~30 ~20 ~42 planks 2
setblock ~30 ~20 ~44 planks 2
setblock ~30 ~20 ~46 planks 2
setblock ~30 ~20 ~48 planks 2
setblock ~30 ~20 ~50 planks 2
setblock ~30 ~20 ~52 planks 2
fill ~31 ~20 ~35 ~31 ~31 ~35 planks 2
fill ~31 ~20 ~36 ~46 ~20 ~36 planks 2
fill ~31 ~20 ~37 ~31 ~48 ~37 planks 2
setblock ~31 ~20 ~38 orange_glazed_terracotta 0
fill ~32 ~20 ~33 ~32 ~33 ~33 orange_glazed_terracotta 0
fill ~32 ~20 ~34 ~34 ~20 ~34 planks 2
setblock ~32 ~20 ~35 orange_glazed_terracotta 0
setblock ~32 ~20 ~37 orange_glazed_terracotta 0
fill ~32 ~20 ~38 ~34 ~20 ~38 planks 2
setblock ~32 ~20 ~39 orange_glazed_terracotta 0
setblock ~32 ~20 ~56 planks 2
fill ~33 ~20 ~32 ~35 ~20 ~32 planks 2
fill ~33 ~20 ~33 ~33 ~20 ~32 planks 2
setblock ~33 ~20 ~35 planks 2
setblock ~33 ~20 ~37 planks 2
setblock ~33 ~20 ~39 planks 2
fill ~33 ~20 ~72 ~35 ~20 ~72 concrete 15
fill ~33 ~20 ~73 ~35 ~20 ~73 concrete 15
setblock ~34 ~20 ~30 planks 2
setblock ~34 ~20 ~31 orange_glazed_terracotta 0
setblock ~34 ~20 ~33 orange_glazed_terracotta 0
setblock ~34 ~20 ~35 orange_glazed_terracotta 0
setblock ~34 ~20 ~37 orange_glazed_terracotta 0
setblock ~34 ~20 ~39 orange_glazed_terracotta 0
fill ~34 ~20 ~40 ~43 ~20 ~40 planks 2
setblock ~34 ~20 ~58 planks 2
fill ~34 ~20 ~67 ~37 ~20 ~67 concrete 15
fill ~34 ~20 ~68 ~36 ~20 ~68 concrete 15
fill ~34 ~20 ~69 ~36 ~20 ~69 concrete 15
fill ~34 ~20 ~70 ~35 ~20 ~70 concrete 15
fill ~34 ~20 ~71 ~35 ~20 ~71 concrete 15
fill ~34 ~20 ~74 ~35 ~20 ~74 concrete 15
fill ~34 ~20 ~75 ~35 ~20 ~75 concrete 15
fill ~34 ~20 ~76 ~36 ~20 ~76 concrete 15
fill ~34 ~20 ~77 ~36 ~20 ~77 concrete 15
setblock ~35 ~20 ~30 orange_glazed_terracotta 0
setblock ~35 ~20 ~31 planks 2
setblock ~35 ~20 ~33 planks 2
setblock ~35 ~20 ~34 stained_hardened_clay 13
setblock ~35 ~20 ~35 bedrock 0
setblock ~35 ~20 ~37 planks 2
setblock ~35 ~20 ~38 orange_glazed_terracotta 0
setblock ~35 ~20 ~39 planks 2
fill ~35 ~20 ~65 ~41 ~20 ~65 concrete 15
fill ~35 ~20 ~66 ~38 ~20 ~66 concrete 15
fill ~35 ~20 ~78 ~37 ~20 ~78 concrete 15
setblock ~36 ~20 ~29 orange_glazed_terracotta 0
fill ~36 ~20 ~30 ~37 ~20 ~30 planks 2
setblock ~36 ~20 ~31 orange_glazed_terracotta 0
fill ~36 ~20 ~32 ~37 ~20 ~32 concrete 7
setblock ~36 ~20 ~33 stained_hardened_clay 13
setblock ~36 ~20 ~34 bedrock 0
setblock ~36 ~20 ~35 orange_glazed_terracotta 0
setblock ~36 ~20 ~37 orange_glazed_terracotta 0
fill ~36 ~20 ~38 ~38 ~20 ~38 planks 2
setblock ~36 ~20 ~39 orange_glazed_terracotta 0
fill ~36 ~20 ~59 ~36 ~25 ~59 orange_glazed_terracotta 0
fill ~36 ~20 ~63 ~47 ~20 ~63 concrete 15
fill ~36 ~20 ~64 ~47 ~20 ~64 concrete 15
fill ~36 ~20 ~79 ~39 ~20 ~79 concrete 15
fill ~37 ~20 ~28 ~41 ~20 ~28 planks 2
