setblock ~92 ~-3 ~44 redstone_block 0
setblock ~91 ~-2 ~44 redstone_block 0
setblock ~92 ~-2 ~43 redstone_block 0
setblock ~92 ~-2 ~44 red_mushroom_block 0
fill ~92 ~-2 ~45 ~92 ~-1 ~45 redstone_block 0
setblock ~93 ~-2 ~44 redstone_block 0
setblock ~90 ~-1 ~44 redstone_block 0
setblock ~92 ~-1 ~42 redstone_block 0
setblock ~92 ~-1 ~46 redstone_block 0
setblock ~94 ~-1 ~44 redstone_block 0
setblock ~41 ~0 ~33 stone 2
fill ~42 ~0 ~33 ~43 ~0 ~33 stained_hardened_clay 6
setblock ~43 ~0 ~25 stone 2
fill ~43 ~0 ~26 ~46 ~0 ~26 brick_block 0
setblock ~43 ~0 ~27 stone 2
setblock ~43 ~0 ~28 brick_block 0
setblock ~43 ~0 ~29 stone 1
fill ~43 ~0 ~34 ~45 ~0 ~34 stained_hardened_clay 6
setblock ~44 ~0 ~25 stained_hardened_clay 10
setblock ~44 ~0 ~27 stained_hardened_clay 10
setblock ~44 ~0 ~28 stone 2
setblock ~44 ~0 ~29 dirt 0
fill ~44 ~0 ~30 ~45 ~0 ~30 brick_block 0
setblock ~44 ~0 ~31 quartz_ore 0
setblock ~44 ~0 ~33 quartz_ore 0
setblock ~44 ~0 ~35 stained_hardened_clay 6
fill ~45 ~0 ~24 ~46 ~0 ~24 brick_block 0
setblock ~45 ~0 ~25 stone 2
setblock ~45 ~0 ~27 stone 1
fill ~45 ~0 ~28 ~46 ~0 ~28 brick_block 0
setblock ~45 ~0 ~29 stone 2
setblock ~45 ~0 ~31 brick_block 0
setblock ~45 ~0 ~35 stone 2
fill ~45 ~0 ~36 ~48 ~0 ~36 stained_hardened_clay 6
setblock ~46 ~0 ~22 brick_block 0
setblock ~46 ~0 ~23 quartz_ore 0
setblock ~46 ~0 ~25 quartz_ore 0
setblock ~46 ~0 ~27 quartz_ore 0
setblock ~46 ~0 ~29 quartz_ore 0
setblock ~46 ~0 ~30 stone 1
setblock ~46 ~0 ~31 quartz_ore 0
setblock ~46 ~0 ~32 brick_block 0
setblock ~46 ~0 ~35 quartz_ore 0
setblock ~47 ~0 ~20 stained_hardened_clay 10
setblock ~47 ~0 ~21 brick_block 0
setblock ~47 ~0 ~22 quartz_ore 0
setblock ~47 ~0 ~23 stone 1
setblock ~47 ~0 ~24 stained_hardened_clay 10
setblock ~47 ~0 ~25 stone 1
setblock ~47 ~0 ~26 log2 0
setblock ~47 ~0 ~27 stone 1
setblock ~47 ~0 ~28 stained_hardened_clay 10
setblock ~47 ~0 ~29 stone 1
fill ~47 ~0 ~30 ~48 ~0 ~30 brick_block 0
setblock ~47 ~0 ~31 stone 2
setblock ~47 ~0 ~32 dirt 0
setblock ~47 ~0 ~33 brick_block 0
setblock ~47 ~0 ~35 stone 2
setblock ~47 ~0 ~37 stone 2
setblock ~48 ~0 ~20 dirt 0
setblock ~48 ~0 ~21 quartz_ore 0
setblock ~48 ~0 ~22 stained_hardened_clay 10
setblock ~48 ~0 ~23 quartz_ore 0
setblock ~48 ~0 ~24 brick_block 0
setblock ~48 ~0 ~25 quartz_ore 0
setblock ~48 ~0 ~26 brick_block 0
setblock ~48 ~0 ~27 stained_hardened_clay 10
setblock ~48 ~0 ~28 brick_block 0
setblock ~48 ~0 ~29 quartz_ore 0
setblock ~48 ~0 ~31 stained_hardened_clay 10
fill ~48 ~0 ~32 ~54 ~0 ~32 brick_block 0
setblock ~48 ~0 ~33 stained_hardened_clay 6
setblock ~48 ~0 ~34 brick_block 0
setblock ~48 ~0 ~37 quartz_ore 0
setblock ~48 ~0 ~38 log2 0
setblock ~49 ~0 ~21 log2 0
setblock ~49 ~0 ~22 quartz_ore 0
setblock ~49 ~0 ~23 brick_block 0
setblock ~49 ~0 ~24 dirt 0
setblock ~49 ~0 ~25 brick_block 0
setblock ~49 ~0 ~26 log2 0
setblock ~49 ~0 ~27 stained_hardened_clay 2
setblock ~49 ~0 ~28 dirt 0
setblock ~49 ~0 ~29 stone 1
setblock ~49 ~0 ~30 log2 0
setblock ~49 ~0 ~31 stone 2
setblock ~49 ~0 ~33 brick_block 0
setblock ~49 ~0 ~34 quartz_ore 0
setblock ~49 ~0 ~37 stone 2
setblock ~49 ~0 ~38 stained_hardened_clay 6
setblock ~50 ~0 ~21 quartz_ore 0
setblock ~50 ~0 ~22 stained_hardened_clay 10
setblock ~50 ~0 ~23 quartz_ore 0
setblock ~50 ~0 ~24 brick_block 0
setblock ~50 ~0 ~25 quartz_ore 0
setblock ~50 ~0 ~26 brick_block 0
setblock ~50 ~0 ~27 stained_hardened_clay 10
setblock ~50 ~0 ~28 brick_block 0
setblock ~50 ~0 ~29 quartz_ore 0
setblock ~50 ~0 ~30 brick_block 0
setblock ~50 ~0 ~31 quartz_ore 0
setblock ~50 ~0 ~33 quartz_ore 0
setblock ~50 ~0 ~34 brick_block 0
setblock ~50 ~0 ~38 stone 2
setblock ~50 ~0 ~39 stained_hardened_clay 6
setblock ~51 ~0 ~22 quartz_ore 0
setblock ~51 ~0 ~23 log2 0
fill ~51 ~0 ~24 ~53 ~0 ~24 stained_hardened_clay 10
setblock ~51 ~0 ~25 brick_block 0
setblock ~51 ~0 ~26 stained_hardened_clay 10
setblock ~51 ~0 ~27 stained_hardened_clay 2
setblock ~51 ~0 ~28 stained_hardened_clay 10
setblock ~51 ~0 ~29 brick_block 0
setblock ~51 ~0 ~30 stained_hardened_clay 10
setblock ~51 ~0 ~31 brick_block 0
setblock ~51 ~0 ~33 brick_block 0
setblock ~51 ~0 ~34 stained_hardened_clay 6
setblock ~51 ~0 ~35 brick_block 0
setblock ~51 ~0 ~39 stone 2
setblock ~52 ~0 ~22 stained_hardened_clay 10
setblock ~52 ~0 ~23 quartz_ore 0
setblock ~52 ~0 ~25 quartz_ore 0
setblock ~52 ~0 ~26 brick_block 0
setblock ~52 ~0 ~27 quartz_ore 0
fill ~52 ~0 ~28 ~56 ~0 ~28 brick_block 0
setblock ~52 ~0 ~29 quartz_ore 0
fill ~52 ~0 ~30 ~55 ~0 ~30 brick_block 0
setblock ~52 ~0 ~31 quartz_ore 0
setblock ~52 ~0 ~33 quartz_ore 0
fill ~52 ~0 ~34 ~53 ~0 ~34 brick_block 0
setblock ~52 ~0 ~35 quartz_ore 0
setblock ~53 ~0 ~23 brick_block 0
setblock ~53 ~0 ~25 brick_block 0
setblock ~53 ~0 ~26 stained_hardened_clay 10
setblock ~53 ~0 ~27 stone 1
setblock ~53 ~0 ~29 stone 1
setblock ~53 ~0 ~31 stone 1
setblock ~53 ~0 ~33 stone 2
setblock ~53 ~0 ~35 stone 2
setblock ~54 ~0 ~24 brick_block 0
setblock ~54 ~0 ~25 quartz_ore 0
setblock ~54 ~0 ~26 brick_block 0
setblock ~54 ~0 ~27 stained_hardened_clay 10
setblock ~54 ~0 ~29 stained_hardened_clay 10
setblock ~54 ~0 ~31 stained_hardened_clay 10
setblock ~54 ~0 ~33 stained_hardened_clay 10
setblock ~55 ~0 ~25 brick_block 0
setblock ~55 ~0 ~26 stained_hardened_clay 10
setblock ~55 ~0 ~27 stone 1
setblock ~55 ~0 ~29 stone 1
setblock ~56 ~0 ~25 quartz_ore 0
setblock ~56 ~0 ~26 brick_block 0
setblock ~56 ~0 ~27 quartz_ore 0
setblock ~89 ~0 ~44 red_mushroom_block 0
fill ~92 ~0 ~41 ~92 ~1 ~41 redstone_block 0
setblock ~92 ~0 ~46 red_mushroom_block 0
fill ~92 ~0 ~47 ~92 ~1 ~47 redstone_block 0
setblock ~95 ~0 ~44 red_mushroom_block 0
setblock ~128 ~0 ~25 quartz_ore 0
setblock ~128 ~0 ~26 brick_block 0
setblock ~128 ~0 ~27 quartz_ore 0
fill ~128 ~0 ~28 ~132 ~0 ~28 brick_block 0
setblock ~129 ~0 ~25 brick_block 0
setblock ~129 ~0 ~26 stained_hardened_clay 10
setblock ~129 ~0 ~27 stone 1
setblock ~129 ~0 ~29 stone 1
fill ~129 ~0 ~30 ~132 ~0 ~30 brick_block 0
setblock ~130 ~0 ~24 brick_block 0
setblock ~130 ~0 ~25 quartz_ore 0
setblock ~130 ~0 ~26 brick_block 0
setblock ~130 ~0 ~27 stained_hardened_clay 10
setblock ~130 ~0 ~29 stained_hardened_clay 10
setblock ~130 ~0 ~31 stained_hardened_clay 10
fill ~130 ~0 ~32 ~136 ~0 ~32 brick_block 0
setblock ~130 ~0 ~33 stained_hardened_clay 10
setblock ~131 ~0 ~23 brick_block 0
setblock ~131 ~0 ~24 stained_hardened_clay 10
setblock ~131 ~0 ~25 brick_block 0
setblock ~131 ~0 ~26 dirt 0
setblock ~131 ~0 ~27 stone 1
setblock ~131 ~0 ~29 stone 1
setblock ~131 ~0 ~31 stone 2
setblock ~131 ~0 ~33 stone 2
fill ~131 ~0 ~34 ~132 ~0 ~34 brick_block 0
setblock ~131 ~0 ~35 stone 2
setblock ~132 ~0 ~22 stained_hardened_clay 10
setblock ~132 ~0 ~23 quartz_ore 0
setblock ~132 ~0 ~24 log2 0
setblock ~132 ~0 ~25 quartz_ore 0
setblock ~132 ~0 ~26 brick_block 0
setblock ~132 ~0 ~27 quartz_ore 0
setblock ~132 ~0 ~29 quartz_ore 0
setblock ~132 ~0 ~31 quartz_ore 0
setblock ~132 ~0 ~33 quartz_ore 0
setblock ~132 ~0 ~35 quartz_ore 0
setblock ~133 ~0 ~22 quartz_ore 0
setblock ~133 ~0 ~23 log2 0
setblock ~133 ~0 ~24 stained_hardened_clay 10
setblock ~133 ~0 ~25 brick_block 0
setblock ~133 ~0 ~26 stained_hardened_clay 10
setblock ~133 ~0 ~27 stained_hardened_clay 2
setblock ~133 ~0 ~28 stained_hardened_clay 10
setblock ~133 ~0 ~29 brick_block 0
setblock ~133 ~0 ~30 stained_hardened_clay 10
setblock ~133 ~0 ~31 brick_block 0
setblock ~133 ~0 ~33 brick_block 0
setblock ~133 ~0 ~34 stained_hardened_clay 6
setblock ~133 ~0 ~35 stone 2
setblock ~133 ~0 ~39 stone 2
setblock ~134 ~0 ~21 quartz_ore 0
setblock ~134 ~0 ~22 stained_hardened_clay 10
setblock ~134 ~0 ~23 quartz_ore 0
setblock ~134 ~0 ~24 brick_block 0
setblock ~134 ~0 ~25 quartz_ore 0
setblock ~134 ~0 ~26 brick_block 0
setblock ~134 ~0 ~27 stained_hardened_clay 10
setblock ~134 ~0 ~28 brick_block 0
setblock ~134 ~0 ~29 quartz_ore 0
setblock ~134 ~0 ~30 brick_block 0
setblock ~134 ~0 ~31 stained_hardened_clay 10
setblock ~134 ~0 ~33 quartz_ore 0
setblock ~134 ~0 ~34 brick_block 0
setblock ~134 ~0 ~38 stone 2
setblock ~134 ~0 ~39 stained_hardened_clay 6
setblock ~135 ~0 ~21 stained_hardened_clay 10
setblock ~135 ~0 ~22 quartz_ore 0
setblock ~135 ~0 ~23 brick_block 0
setblock ~135 ~0 ~24 stained_hardened_clay 10
setblock ~135 ~0 ~25 brick_block 0
setblock ~135 ~0 ~26 log2 0
setblock ~135 ~0 ~27 stained_hardened_clay 2
setblock ~135 ~0 ~28 stained_hardened_clay 10
setblock ~135 ~0 ~29 brick_block 0
setblock ~135 ~0 ~30 log2 0
setblock ~135 ~0 ~31 stone 2
setblock ~135 ~0 ~33 brick_block 0
setblock ~135 ~0 ~34 quartz_ore 0
setblock ~135 ~0 ~37 brick_block 0
setblock ~135 ~0 ~38 stained_hardened_clay 6
fill ~136 ~0 ~20 ~137 ~0 ~20 stained_hardened_clay 10
setblock ~136 ~0 ~21 quartz_ore 0
setblock ~136 ~0 ~22 stained_hardened_clay 10
setblock ~136 ~0 ~23 quartz_ore 0
setblock ~136 ~0 ~24 brick_block 0
setblock ~136 ~0 ~25 quartz_ore 0
setblock ~136 ~0 ~26 brick_block 0
setblock ~136 ~0 ~27 stained_hardened_clay 10
setblock ~136 ~0 ~28 brick_block 0
setblock ~136 ~0 ~29 quartz_ore 0
fill ~136 ~0 ~30 ~137 ~0 ~30 brick_block 0
setblock ~136 ~0 ~31 stained_hardened_clay 10
setblock ~136 ~0 ~33 stained_hardened_clay 6
setblock ~136 ~0 ~34 brick_block 0
fill ~136 ~0 ~36 ~139 ~0 ~36 stained_hardened_clay 6
setblock ~136 ~0 ~37 quartz_ore 0
setblock ~136 ~0 ~38 log2 0
setblock ~137 ~0 ~21 brick_block 0
setblock ~137 ~0 ~22 quartz_ore 0
setblock ~137 ~0 ~23 brick_block 0
setblock ~137 ~0 ~24 stained_hardened_clay 10
setblock ~137 ~0 ~25 stone 1
setblock ~137 ~0 ~26 log2 0
setblock ~137 ~0 ~27 stone 1
setblock ~137 ~0 ~28 stained_hardened_clay 10
setblock ~137 ~0 ~29 stone 1
setblock ~137 ~0 ~31 stone 2
setblock ~137 ~0 ~32 dirt 0
setblock ~137 ~0 ~33 brick_block 0
setblock ~137 ~0 ~35 stone 2
setblock ~137 ~0 ~37 stone 2
setblock ~138 ~0 ~22 brick_block 0
setblock ~138 ~0 ~23 quartz_ore 0
fill ~138 ~0 ~24 ~139 ~0 ~24 brick_block 0
setblock ~138 ~0 ~25 quartz_ore 0
fill ~138 ~0 ~26 ~141 ~0 ~26 brick_block 0
setblock ~138 ~0 ~27 quartz_ore 0
fill ~138 ~0 ~28 ~141 ~0 ~28 brick_block 0
setblock ~138 ~0 ~29 quartz_ore 0
setblock ~138 ~0 ~30 stone 1
setblock ~138 ~0 ~31 quartz_ore 0
setblock ~138 ~0 ~32 brick_block 0
setblock ~138 ~0 ~35 quartz_ore 0
setblock ~139 ~0 ~25 stone 2
setblock ~139 ~0 ~27 stone 1
setblock ~139 ~0 ~29 stone 2
fill ~139 ~0 ~30 ~140 ~0 ~30 brick_block 0
fill ~139 ~0 ~31 ~139 ~0 ~30 brick_block 0
fill ~139 ~0 ~34 ~141 ~0 ~34 stained_hardened_clay 6
setblock ~139 ~0 ~35 stone 2
setblock ~140 ~0 ~25 stained_hardened_clay 10
setblock ~140 ~0 ~27 stained_hardened_clay 10
setblock ~140 ~0 ~29 stained_hardened_clay 10
setblock ~140 ~0 ~31 quartz_ore 0
setblock ~140 ~0 ~33 quartz_ore 0
setblock ~140 ~0 ~35 stained_hardened_clay 6
setblock ~141 ~0 ~25 stone 2
setblock ~141 ~0 ~27 stone 2
setblock ~141 ~0 ~29 stone 1
fill ~141 ~0 ~33 ~142 ~0 ~33 stained_hardened_clay 6
setblock ~143 ~0 ~33 stone 2
fill ~2 ~1 ~127 ~3 ~1 ~127 red_nether_brick 0
fill ~2 ~1 ~128 ~3 ~1 ~128 red_nether_brick 0
setblock ~2 ~1 ~129 quartz_ore 0
setblock ~4 ~1 ~126 netherrack 0
setblock ~4 ~1 ~127 quartz_ore 0
setblock ~5 ~1 ~126 stained_hardened_clay 6
fill ~5 ~1 ~131 ~5 ~1 ~132 netherrack 0
setblock ~6 ~1 ~125 netherrack 0
setblock ~6 ~1 ~130 netherrack 0
fill ~6 ~1 ~131 ~7 ~1 ~131 quartz_ore 0
setblock ~6 ~1 ~132 netherrack 0
fill ~7 ~1 ~129 ~9 ~1 ~129 quartz_ore 0
fill ~7 ~1 ~130 ~7 ~1 ~129 quartz_ore 0
setblock ~8 ~1 ~128 quartz_ore 0
setblock ~8 ~1 ~130 netherrack 0
setblock ~8 ~1 ~134 black_glazed_terracotta 0
setblock ~8 ~1 ~135 red_nether_brick 0
fill ~8 ~1 ~136 ~9 ~1 ~136 netherrack 0
fill ~9 ~1 ~127 ~9 ~1 ~128 netherrack 0
fill ~9 ~1 ~132 ~9 ~1 ~133 quartz_ore 0
fill ~9 ~1 ~134 ~10 ~1 ~134 netherrack 0
fill ~9 ~1 ~135 ~10 ~1 ~135 quartz_ore 0
setblock ~10 ~1 ~128 netherrack 0
fill ~10 ~1 ~130 ~13 ~1 ~130 quartz_ore 0
setblock ~10 ~1 ~131 red_nether_brick 0
fill ~10 ~1 ~132 ~11 ~1 ~132 netherrack 0
fill ~10 ~1 ~133 ~10 ~1 ~132 netherrack 0
setblock ~10 ~1 ~136 stained_hardened_clay 12
setblock ~11 ~1 ~129 stained_hardened_clay 6
setblock ~11 ~1 ~131 netherrack 0
fill ~11 ~1 ~133 ~11 ~1 ~134 red_nether_brick 0
fill ~12 ~1 ~129 ~13 ~1 ~129 quartz_ore 0
setblock ~12 ~1 ~131 black_glazed_terracotta 0
setblock ~12 ~1 ~132 red_nether_brick 0
setblock ~13 ~1 ~134 netherrack 0
setblock ~13 ~1 ~135 quartz_ore 0
fill ~13 ~1 ~136 ~14 ~1 ~136 netherrack 0
setblock ~13 ~1 ~137 quartz_ore 0
setblock ~14 ~1 ~132 red_nether_brick 0
fill ~14 ~1 ~133 ~16 ~1 ~133 netherrack 0
fill ~14 ~1 ~134 ~15 ~1 ~134 red_nether_brick 0
fill ~14 ~1 ~135 ~15 ~1 ~135 netherrack 0
fill ~14 ~1 ~137 ~14 ~2 ~137 netherrack 0
fill ~15 ~1 ~130 ~16 ~1 ~130 red_nether_brick 0
fill ~15 ~1 ~131 ~15 ~1 ~132 quartz_ore 0
fill ~16 ~1 ~131 ~16 ~1 ~133 netherrack 0
fill ~40 ~1 ~31 ~40 ~1 ~33 stained_hardened_clay 6
setblock ~41 ~1 ~30 stained_hardened_clay 6
setblock ~41 ~1 ~31 stone 2
setblock ~41 ~1 ~32 stained_hardened_clay 6
fill ~41 ~1 ~34 ~42 ~1 ~34 stained_hardened_clay 6
setblock ~42 ~1 ~25 brick_block 0
setblock ~42 ~1 ~26 stained_hardened_clay 10
setblock ~42 ~1 ~27 brick_block 0
fill ~42 ~1 ~28 ~42 ~1 ~29 stained_hardened_clay 6
fill ~42 ~1 ~30 ~42 ~1 ~32 quartz_ore 0
fill ~42 ~1 ~35 ~43 ~1 ~35 stained_hardened_clay 6
setblock ~43 ~1 ~21 brick_block 0
setblock ~43 ~1 ~22 stained_hardened_clay 10
fill ~43 ~1 ~23 ~45 ~1 ~23 brick_block 0
fill ~43 ~1 ~24 ~43 ~1 ~23 brick_block 0
setblock ~43 ~1 ~30 stained_hardened_clay 10
setblock ~43 ~1 ~31 brick_block 0
setblock ~43 ~1 ~32 stained_hardened_clay 6
fill ~43 ~1 ~36 ~44 ~1 ~36 stained_hardened_clay 6
fill ~44 ~1 ~20 ~46 ~1 ~20 quartz_ore 0
setblock ~44 ~1 ~21 stained_hardened_clay 10
fill ~44 ~1 ~22 ~45 ~1 ~22 quartz_ore 0
setblock ~44 ~1 ~24 quartz_ore 0
setblock ~44 ~1 ~32 quartz_ore 0
setblock ~45 ~1 ~21 brick_block 0
fill ~45 ~1 ~32 ~45 ~1 ~33 stained_hardened_clay 6
fill ~45 ~1 ~37 ~46 ~1 ~37 stained_hardened_clay 6
fill ~46 ~1 ~19 ~47 ~1 ~19 stained_hardened_clay 10
setblock ~46 ~1 ~21 quartz_ore 0
fill ~46 ~1 ~33 ~46 ~1 ~34 quartz_ore 0
fill ~46 ~1 ~38 ~47 ~1 ~38 stained_hardened_clay 6
setblock ~47 ~1 ~34 quartz_ore 0
setblock ~48 ~1 ~19 quartz_ore 0
setblock ~48 ~1 ~35 stained_hardened_clay 6
fill ~48 ~1 ~39 ~49 ~1 ~39 stained_hardened_clay 6
fill ~49 ~1 ~20 ~51 ~1 ~20 quartz_ore 0
fill ~49 ~1 ~35 ~50 ~1 ~35 stained_hardened_clay 10
fill ~49 ~1 ~36 ~50 ~1 ~36 quartz_ore 0
fill ~49 ~1 ~40 ~49 ~2 ~40 stained_hardened_clay 6
fill ~50 ~1 ~37 ~52 ~1 ~37 stained_hardened_clay 6
setblock ~50 ~1 ~40 stained_hardened_clay 14
fill ~51 ~1 ~21 ~52 ~1 ~21 quartz_ore 0
setblock ~51 ~1 ~36 stained_hardened_clay 6
setblock ~51 ~1 ~38 stained_hardened_clay 6
fill ~51 ~1 ~40 ~51 ~2 ~40 stained_hardened_clay 6
setblock ~52 ~1 ~36 quartz_ore 0
setblock ~52 ~1 ~38 quartz_ore 0
setblock ~52 ~1 ~39 stained_hardened_clay 6
setblock ~53 ~1 ~22 quartz_ore 0
setblock ~53 ~1 ~36 stained_hardened_clay 6
setblock ~54 ~1 ~23 quartz_ore 0
setblock ~54 ~1 ~34 quartz_ore 0
setblock ~54 ~1 ~35 brick_block 0
setblock ~55 ~1 ~23 stained_hardened_clay 10
fill ~55 ~1 ~24 ~56 ~1 ~24 quartz_ore 0
setblock ~55 ~1 ~31 brick_block 0
setblock ~55 ~1 ~32 stained_hardened_clay 10
fill ~55 ~1 ~33 ~55 ~3 ~33 brick_block 0
setblock ~56 ~1 ~29 stained_hardened_clay 10
setblock ~56 ~1 ~30 quartz_ore 0
setblock ~56 ~1 ~31 stained_hardened_clay 10
setblock ~57 ~1 ~25 stained_hardened_clay 10
setblock ~57 ~1 ~26 quartz_ore 0
setblock ~57 ~1 ~27 brick_block 0
setblock ~57 ~1 ~28 quartz_ore 0
setblock ~89 ~1 ~43 red_mushroom_block 0
setblock ~89 ~1 ~44 redstone_block 0
setblock ~89 ~1 ~45 red_mushroom_block 0
fill ~90 ~1 ~42 ~91 ~1 ~42 redstone_block 0
fill ~90 ~1 ~43 ~90 ~1 ~42 redstone_block 0
fill ~90 ~1 ~45 ~90 ~1 ~46 redstone_block 0
setblock ~91 ~1 ~41 red_mushroom_block 0
setblock ~91 ~1 ~46 redstone_block 0
setblock ~91 ~1 ~47 red_mushroom_block 0
setblock ~93 ~1 ~41 red_mushroom_block 0
fill ~93 ~1 ~42 ~94 ~1 ~42 redstone_block 0
fill ~93 ~1 ~46 ~94 ~1 ~46 redstone_block 0
setblock ~93 ~1 ~47 red_mushroom_block 0
setblock ~94 ~1 ~43 redstone_block 0
setblock ~94 ~1 ~45 redstone_block 0
setblock ~95 ~1 ~43 red_mushroom_block 0
setblock ~95 ~1 ~44 redstone_block 0
setblock ~95 ~1 ~45 red_mushroom_block 0
setblock ~127 ~1 ~25 stained_hardened_clay 10
setblock ~127 ~1 ~26 quartz_ore 0
setblock ~127 ~1 ~27 brick_block 0
setblock ~127 ~1 ~28 quartz_ore 0
fill ~128 ~1 ~24 ~129 ~1 ~24 quartz_ore 0
setblock ~128 ~1 ~29 stained_hardened_clay 10
setblock ~128 ~1 ~30 quartz_ore 0
setblock ~128 ~1 ~31 stained_hardened_clay 10
setblock ~129 ~1 ~23 stained_hardened_clay 10
setblock ~129 ~1 ~31 brick_block 0
setblock ~129 ~1 ~32 dirt 0
setblock ~129 ~1 ~33 brick_block 0
setblock ~130 ~1 ~23 quartz_ore 0
setblock ~130 ~1 ~34 quartz_ore 0
setblock ~130 ~1 ~35 brick_block 0
setblock ~131 ~1 ~22 quartz_ore 0
setblock ~131 ~1 ~36 stained_hardened_clay 6
fill ~132 ~1 ~21 ~133 ~1 ~21 quartz_ore 0
setblock ~132 ~1 ~36 quartz_ore 0
fill ~132 ~1 ~37 ~134 ~1 ~37 stained_hardened_clay 6
setblock ~132 ~1 ~38 quartz_ore 0
setblock ~132 ~1 ~39 stained_hardened_clay 6
fill ~133 ~1 ~20 ~135 ~1 ~20 quartz_ore 0
setblock ~133 ~1 ~36 stained_hardened_clay 6
setblock ~133 ~1 ~38 stained_hardened_clay 6
fill ~133 ~1 ~40 ~133 ~2 ~40 stained_hardened_clay 6
setblock ~134 ~1 ~35 dirt 0
fill ~134 ~1 ~36 ~135 ~1 ~36 quartz_ore 0
setblock ~134 ~1 ~40 stained_hardened_clay 14
setblock ~135 ~1 ~35 stained_hardened_clay 10
fill ~135 ~1 ~39 ~136 ~1 ~39 stained_hardened_clay 6
fill ~135 ~1 ~40 ~135 ~2 ~40 stained_hardened_clay 6
setblock ~136 ~1 ~19 quartz_ore 0
setblock ~136 ~1 ~35 quartz_ore 0
setblock ~137 ~1 ~19 dirt 0
fill ~137 ~1 ~34 ~138 ~1 ~34 quartz_ore 0
fill ~137 ~1 ~38 ~138 ~1 ~38 stained_hardened_clay 6
fill ~138 ~1 ~19 ~138 ~3 ~19 quartz_ore 0
fill ~138 ~1 ~20 ~140 ~1 ~20 quartz_ore 0
fill ~138 ~1 ~21 ~138 ~1 ~19 quartz_ore 0
setblock ~138 ~1 ~33 quartz_ore 0
setblock ~138 ~1 ~37 stained_hardened_clay 6
setblock ~139 ~1 ~21 brick_block 0
fill ~139 ~1 ~22 ~140 ~1 ~22 quartz_ore 0
fill ~139 ~1 ~23 ~141 ~1 ~23 brick_block 0
fill ~139 ~1 ~32 ~139 ~1 ~33 stained_hardened_clay 6
setblock ~139 ~1 ~37 quartz_ore 0
setblock ~140 ~1 ~21 stained_hardened_clay 10
setblock ~140 ~1 ~24 quartz_ore 0
setblock ~140 ~1 ~32 quartz_ore 0
fill ~140 ~1 ~36 ~141 ~1 ~36 stained_hardened_clay 6
setblock ~141 ~1 ~21 brick_block 0
setblock ~141 ~1 ~22 stained_hardened_clay 10
setblock ~141 ~1 ~24 brick_block 0
setblock ~141 ~1 ~30 stained_hardened_clay 10
setblock ~141 ~1 ~31 brick_block 0
setblock ~141 ~1 ~32 stained_hardened_clay 6
fill ~141 ~1 ~35 ~142 ~1 ~35 stained_hardened_clay 6
setblock ~142 ~1 ~25 brick_block 0
setblock ~142 ~1 ~26 stained_hardened_clay 10
setblock ~142 ~1 ~27 brick_block 0
setblock ~142 ~1 ~28 stained_hardened_clay 6
setblock ~142 ~1 ~29 brick_block 0
fill ~142 ~1 ~30 ~142 ~1 ~32 quartz_ore 0
fill ~142 ~1 ~34 ~143 ~1 ~34 stained_hardened_clay 6
setblock ~143 ~1 ~30 stained_hardened_clay 6
setblock ~143 ~1 ~31 stone 2
fill ~143 ~1 ~32 ~144 ~1 ~32 stained_hardened_clay 6
setblock ~144 ~1 ~31 stained_hardened_clay 6
setblock ~144 ~1 ~33 stained_hardened_clay 6
fill ~168 ~1 ~130 ~169 ~1 ~130 netherrack 0
setblock ~168 ~1 ~131 quartz_ore 0
fill ~168 ~1 ~132 ~168 ~1 ~133 red_nether_brick 0
setblock ~169 ~1 ~131 stained_hardened_clay 6
fill ~169 ~1 ~132 ~170 ~1 ~132 netherrack 0
fill ~169 ~1 ~133 ~169 ~1 ~132 netherrack 0
fill ~169 ~1 ~134 ~170 ~1 ~134 red_nether_brick 0
fill ~169 ~1 ~135 ~171 ~1 ~135 red_nether_brick 0
setblock ~170 ~1 ~133 red_nether_brick 0
fill ~170 ~1 ~136 ~171 ~1 ~136 red_nether_brick 0
fill ~170 ~1 ~137 ~171 ~1 ~137 red_nether_brick 0
setblock ~171 ~1 ~129 stained_hardened_clay 6
fill ~171 ~1 ~130 ~173 ~1 ~130 netherrack 0
fill ~171 ~1 ~134 ~171 ~2 ~134 netherrack 0
setblock ~172 ~1 ~129 quartz_ore 0
fill ~172 ~1 ~131 ~172 ~1 ~132 red_nether_brick 0
fill ~173 ~1 ~129 ~173 ~2 ~129 netherrack 0
fill ~173 ~1 ~131 ~173 ~1 ~132 netherrack 0
fill ~173 ~1 ~133 ~173 ~1 ~134 red_nether_brick 0
fill ~174 ~1 ~128 ~175 ~1 ~128 quartz_ore 0
fill ~174 ~1 ~130 ~174 ~4 ~130 red_nether_brick 0
fill ~174 ~1 ~131 ~174 ~1 ~132 red_nether_brick 0
setblock ~174 ~1 ~133 netherrack 0
fill ~174 ~1 ~134 ~176 ~1 ~134 red_nether_brick 0
fill ~174 ~1 ~135 ~176 ~1 ~135 red_nether_brick 0
fill ~174 ~1 ~136 ~176 ~1 ~136 red_nether_brick 0
fill ~175 ~1 ~127 ~175 ~2 ~127 quartz_ore 0
setblock ~175 ~1 ~129 red_nether_brick 0
fill ~175 ~1 ~132 ~175 ~3 ~132 red_nether_brick 0
fill ~175 ~1 ~133 ~175 ~1 ~132 red_nether_brick 0
setblock ~176 ~1 ~128 netherrack 0
setblock ~176 ~1 ~129 quartz_ore 0
fill ~176 ~1 ~130 ~177 ~1 ~130 netherrack 0
setblock ~177 ~1 ~129 netherrack 0
fill ~177 ~1 ~131 ~179 ~1 ~131 red_nether_brick 0
setblock ~178 ~1 ~125 stained_hardened_clay 6
setblock ~178 ~1 ~130 red_nether_brick 0
fill ~178 ~1 ~132 ~179 ~1 ~132 red_nether_brick 0
setblock ~179 ~1 ~126 quartz_ore 0
setblock ~180 ~1 ~126 red_nether_brick 0
fill ~180 ~1 ~127 ~181 ~1 ~127 quartz_ore 0
setblock ~181 ~1 ~128 red_nether_brick 0
setblock ~182 ~1 ~127 red_nether_brick 0
setblock ~182 ~1 ~128 quartz_ore 0
fill ~182 ~1 ~129 ~182 ~2 ~129 netherrack 0
setblock ~1 ~2 ~127 nether_wart_block 0
setblock ~1 ~2 ~128 red_nether_brick 0
setblock ~1 ~2 ~129 quartz_ore 0
setblock ~2 ~2 ~126 nether_wart_block 0
setblock ~2 ~2 ~129 red_nether_brick 0
setblock ~3 ~2 ~125 netherrack 0
setblock ~3 ~2 ~126 red_nether_brick 0
setblock ~3 ~2 ~129 brick_block 0
setblock ~4 ~2 ~125 red_nether_brick 0
setblock ~4 ~2 ~128 dirt 0
setblock ~4 ~2 ~129 quartz_ore 0
fill ~4 ~2 ~131 ~4 ~2 ~132 red_nether_brick 0
fill ~4 ~2 ~133 ~5 ~2 ~133 quartz_ore 0
setblock ~5 ~2 ~124 dirt 0
setblock ~5 ~2 ~125 stone 2
fill ~5 ~2 ~127 ~5 ~2 ~128 quartz_ore 0
fill ~5 ~2 ~130 ~5 ~3 ~130 netherrack 0
setblock ~6 ~2 ~123 netherrack 0
fill ~6 ~2 ~124 ~7 ~2 ~124 stained_hardened_clay 6
fill ~6 ~2 ~126 ~7 ~2 ~126 quartz_ore 0
setblock ~6 ~2 ~127 black_glazed_terracotta 0
fill ~6 ~2 ~129 ~6 ~3 ~129 netherrack 0
setblock ~6 ~2 ~133 netherrack 0
setblock ~7 ~2 ~125 stained_hardened_clay 6
setblock ~7 ~2 ~128 netherrack 0
setblock ~7 ~2 ~132 black_glazed_terracotta 0
setblock ~7 ~2 ~135 quartz_ore 0
setblock ~8 ~2 ~127 netherrack 0
setblock ~8 ~2 ~131 netherrack 0
setblock ~8 ~2 ~133 red_nether_brick 0
setblock ~8 ~2 ~134 netherrack 0
setblock ~8 ~2 ~136 quartz_ore 0
fill ~8 ~2 ~137 ~8 ~4 ~137 black_glazed_terracotta 0
setblock ~9 ~2 ~127 quartz_ore 0
fill ~9 ~2 ~130 ~10 ~2 ~130 netherrack 0
setblock ~9 ~2 ~131 stained_hardened_clay 12
fill ~9 ~2 ~132 ~9 ~3 ~132 red_nether_brick 0
setblock ~9 ~2 ~137 quartz_ore 0
setblock ~10 ~2 ~127 netherrack 0
fill ~10 ~2 ~128 ~10 ~2 ~129 quartz_ore 0
setblock ~10 ~2 ~136 quartz_ore 0
setblock ~11 ~2 ~128 black_glazed_terracotta 0
setblock ~11 ~2 ~129 stained_hardened_clay 10
fill ~11 ~2 ~134 ~11 ~2 ~135 noteblock 0
setblock ~12 ~2 ~128 stained_hardened_clay 6
setblock ~12 ~2 ~132 quartz_ore 0
setblock ~12 ~2 ~133 netherrack 0
fill ~12 ~2 ~135 ~12 ~3 ~135 black_glazed_terracotta 0
setblock ~12 ~2 ~136 stained_hardened_clay 12
fill ~12 ~2 ~137 ~12 ~4 ~137 black_glazed_terracotta 0
setblock ~13 ~2 ~129 red_nether_brick 0
setblock ~13 ~2 ~130 quartz_ore 0
setblock ~13 ~2 ~131 noteblock 0
setblock ~13 ~2 ~133 nether_wart_block 0
setblock ~13 ~2 ~134 black_glazed_terracotta 0
fill ~13 ~2 ~138 ~13 ~3 ~138 netherrack 0
fill ~14 ~2 ~130 ~14 ~2 ~132 netherrack 0
setblock ~15 ~2 ~130 stained_hardened_clay 14
fill ~15 ~2 ~136 ~15 ~2 ~137 quartz_ore 0
setblock ~16 ~2 ~130 stained_hardened_clay 6
setblock ~16 ~2 ~133 black_glazed_terracotta 0
fill ~16 ~2 ~134 ~16 ~2 ~135 netherrack 0
setblock ~17 ~2 ~131 quartz_ore 0
setblock ~17 ~2 ~132 red_nether_brick 0
fill ~22 ~2 ~130 ~23 ~2 ~130 stained_hardened_clay 6
setblock ~22 ~2 ~131 red_nether_brick 0
fill ~23 ~2 ~129 ~24 ~2 ~129 stained_hardened_clay 6
setblock ~23 ~2 ~131 brick_block 0
setblock ~24 ~2 ~130 nether_wart_block 0
setblock ~24 ~2 ~131 netherrack 0
fill ~25 ~2 ~130 ~25 ~2 ~131 stained_hardened_clay 6
setblock ~39 ~2 ~31 stone 2
fill ~39 ~2 ~32 ~39 ~3 ~32 stained_hardened_clay 6
setblock ~39 ~2 ~33 planks 2
setblock ~40 ~2 ~29 stained_hardened_clay 6
setblock ~40 ~2 ~30 stone 2
setblock ~40 ~2 ~33 gold_ore 0
setblock ~41 ~2 ~25 stone 2
setblock ~41 ~2 ~26 brick_block 0
fill ~41 ~2 ~27 ~41 ~4 ~27 stone 2
setblock ~41 ~2 ~28 brick_block 0
setblock ~41 ~2 ~29 stone 2
setblock ~41 ~2 ~34 gold_ore 0
setblock ~42 ~2 ~22 stone 2
setblock ~42 ~2 ~23 dirt 0
setblock ~42 ~2 ~24 stone 2
setblock ~42 ~2 ~35 gold_ore 0
setblock ~43 ~2 ~20 dirt 0
setblock ~43 ~2 ~21 stone 2
fill ~43 ~2 ~35 ~43 ~3 ~35 stained_hardened_clay 6
setblock ~44 ~2 ~20 brick_block 0
setblock ~44 ~2 ~36 planks 2
fill ~45 ~2 ~19 ~45 ~4 ~19 brick_block 0
setblock ~45 ~2 ~36 glowstone 0
fill ~46 ~2 ~19 ~46 ~3 ~19 quartz_ore 0
setblock ~46 ~2 ~37 redstone_ore 0
fill ~46 ~2 ~38 ~46 ~1 ~38 stained_hardened_clay 6
setblock ~47 ~2 ~19 brick_block 0
fill ~47 ~2 ~39 ~48 ~2 ~39 quartz_ore 0
setblock ~48 ~2 ~18 stained_hardened_clay 10
setblock ~49 ~2 ~19 stained_hardened_clay 10
setblock ~50 ~2 ~19 quartz_ore 0
setblock ~50 ~2 ~40 stained_hardened_clay 6
setblock ~51 ~2 ~19 stained_hardened_clay 10
setblock ~52 ~2 ~20 stained_hardened_clay 10
setblock ~52 ~2 ~39 quartz_ore 0
setblock ~52 ~2 ~40 stained_hardened_clay 6
setblock ~53 ~2 ~21 stained_hardened_clay 10
setblock ~53 ~2 ~37 stone 2
setblock ~53 ~2 ~38 stained_hardened_clay 6
setblock ~54 ~2 ~21 quartz_ore 0
fill ~54 ~2 ~22 ~55 ~2 ~22 stained_hardened_clay 10
setblock ~54 ~2 ~35 quartz_ore 0
setblock ~54 ~2 ~36 brick_block 0
setblock ~54 ~2 ~37 quartz_ore 0
setblock ~55 ~2 ~34 brick_block 0
fill ~56 ~2 ~23 ~56 ~3 ~23 quartz_ore 0
setblock ~56 ~2 ~24 stained_hardened_clay 10
setblock ~56 ~2 ~32 brick_block 0
setblock ~57 ~2 ~25 brick_block 0
setblock ~57 ~2 ~26 stained_hardened_clay 10
fill ~57 ~2 ~29 ~57 ~4 ~29 brick_block 0
setblock ~57 ~2 ~30 dirt 0
setblock ~57 ~2 ~31 brick_block 0
setblock ~58 ~2 ~27 quartz_ore 0
setblock ~58 ~2 ~28 brick_block 0
setblock ~58 ~2 ~29 quartz_ore 0
setblock ~90 ~2 ~44 red_mushroom_block 0
setblock ~92 ~2 ~42 red_mushroom_block 0
setblock ~92 ~2 ~46 red_mushroom_block 0
setblock ~94 ~2 ~44 red_mushroom_block 0
setblock ~126 ~2 ~27 quartz_ore 0
setblock ~126 ~2 ~28 brick_block 0
setblock ~126 ~2 ~29 quartz_ore 0
setblock ~127 ~2 ~25 brick_block 0
setblock ~127 ~2 ~26 stained_hardened_clay 10
fill ~127 ~2 ~29 ~127 ~2 ~31 brick_block 0
fill ~128 ~2 ~23 ~128 ~3 ~23 quartz_ore 0
setblock ~128 ~2 ~24 stained_hardened_clay 10
setblock ~128 ~2 ~32 brick_block 0
fill ~129 ~2 ~22 ~130 ~2 ~22 stained_hardened_clay 10
setblock ~129 ~2 ~33 stone 2
setblock ~129 ~2 ~34 brick_block 0
setblock ~130 ~2 ~21 quartz_ore 0
setblock ~130 ~2 ~35 quartz_ore 0
setblock ~130 ~2 ~36 brick_block 0
setblock ~130 ~2 ~37 quartz_ore 0
setblock ~131 ~2 ~21 stained_hardened_clay 10
setblock ~131 ~2 ~37 stone 2
setblock ~131 ~2 ~38 stained_hardened_clay 6
setblock ~132 ~2 ~20 stained_hardened_clay 10
setblock ~132 ~2 ~39 quartz_ore 0
setblock ~132 ~2 ~40 stained_hardened_clay 6
setblock ~133 ~2 ~19 mycelium 0
setblock ~134 ~2 ~19 quartz_ore 0
setblock ~134 ~2 ~40 stained_hardened_clay 6
setblock ~135 ~2 ~19 stained_hardened_clay 10
setblock ~136 ~2 ~18 stained_hardened_clay 10
setblock ~136 ~2 ~39 stained_hardened_clay 14
setblock ~137 ~2 ~19 brick_block 0
setblock ~137 ~2 ~39 stained_hardened_clay 10
fill ~138 ~2 ~37 ~138 ~3 ~37 gold_ore 0
setblock ~138 ~2 ~38 brick_block 0
fill ~139 ~2 ~19 ~139 ~4 ~19 brick_block 0
setblock ~139 ~2 ~36 stained_hardened_clay 6
fill ~140 ~2 ~20 ~141 ~2 ~20 brick_block 0
setblock ~140 ~2 ~36 planks 2
setblock ~141 ~2 ~21 stone 2
setblock ~141 ~2 ~35 glowstone 0
setblock ~142 ~2 ~22 stone 2
setblock ~142 ~2 ~23 dirt 0
setblock ~142 ~2 ~24 stone 2
setblock ~142 ~2 ~35 gold_ore 0
setblock ~143 ~2 ~25 stone 2
setblock ~143 ~2 ~26 brick_block 0
setblock ~143 ~2 ~27 stone 2
setblock ~143 ~2 ~28 brick_block 0
setblock ~143 ~2 ~29 stone 2
setblock ~143 ~2 ~34 planks 2
setblock ~144 ~2 ~29 stained_hardened_clay 6
setblock ~144 ~2 ~30 stone 2
setblock ~144 ~2 ~33 gold_ore 0
setblock ~145 ~2 ~31 stone 2
fill ~145 ~2 ~32 ~145 ~3 ~32 stained_hardened_clay 6
setblock ~145 ~2 ~33 stained_hardened_clay 0
setblock ~159 ~2 ~130 netherrack 0
setblock ~159 ~2 ~131 stained_hardened_clay 14
setblock ~160 ~2 ~129 stained_hardened_clay 14
setblock ~160 ~2 ~130 stone 2
setblock ~160 ~2 ~131 red_nether_brick 0
setblock ~161 ~2 ~129 stained_hardened_clay 6
fill ~161 ~2 ~130 ~161 ~2 ~131 netherrack 0
setblock ~162 ~2 ~130 dirt 0
setblock ~162 ~2 ~131 red_nether_brick 0
setblock ~167 ~2 ~131 nether_wart_block 0
fill ~167 ~2 ~132 ~167 ~7 ~132 red_nether_brick 0
setblock ~168 ~2 ~130 quartz_ore 0
fill ~168 ~2 ~133 ~168 ~4 ~133 red_nether_brick 0
fill ~168 ~2 ~134 ~168 ~3 ~134 red_nether_brick 0
fill ~168 ~2 ~135 ~168 ~3 ~135 red_nether_brick 0
fill ~169 ~2 ~130 ~169 ~3 ~130 netherrack 0
fill ~169 ~2 ~136 ~169 ~4 ~136 red_nether_brick 0
setblock ~169 ~2 ~137 nether_wart_block 0
setblock ~170 ~2 ~130 quartz_ore 0
setblock ~170 ~2 ~131 black_glazed_terracotta 0
setblock ~170 ~2 ~132 netherrack 0
fill ~170 ~2 ~137 ~170 ~1 ~137 red_nether_brick 0
setblock ~171 ~2 ~129 quartz_ore 0
setblock ~171 ~2 ~130 red_nether_brick 0
setblock ~171 ~2 ~131 quartz_ore 0
setblock ~171 ~2 ~133 brick_block 0
fill ~171 ~2 ~138 ~171 ~4 ~138 red_nether_brick 0
setblock ~172 ~2 ~128 hardened_clay 0
setblock ~172 ~2 ~132 black_glazed_terracotta 0
fill ~172 ~2 ~133 ~172 ~3 ~133 red_nether_brick 0
fill ~172 ~2 ~135 ~173 ~2 ~135 red_nether_brick 0
fill ~172 ~2 ~136 ~172 ~4 ~136 red_nether_brick 0
fill ~172 ~2 ~137 ~172 ~5 ~137 red_nether_brick 0
setblock ~173 ~2 ~128 netherrack 0
setblock ~173 ~2 ~134 red_nether_brick 0
setblock ~174 ~2 ~127 red_nether_brick 0
setblock ~174 ~2 ~128 stained_hardened_clay 6
fill ~174 ~2 ~129 ~174 ~3 ~129 black_glazed_terracotta 0
fill ~174 ~2 ~136 ~174 ~1 ~136 red_nether_brick 0
setblock ~175 ~2 ~130 netherrack 0
fill ~175 ~2 ~131 ~176 ~2 ~131 red_nether_brick 0
setblock ~175 ~2 ~137 netherrack 0
setblock ~176 ~2 ~127 netherrack 0
fill ~176 ~2 ~133 ~176 ~2 ~134 red_nether_brick 0
setblock ~176 ~2 ~136 nether_wart_block 0
fill ~176 ~2 ~137 ~176 ~4 ~137 red_nether_brick 0
fill ~177 ~2 ~124 ~177 ~4 ~124 quartz_ore 0
fill ~177 ~2 ~125 ~177 ~2 ~126 stained_hardened_clay 6
setblock ~177 ~2 ~128 netherrack 0
setblock ~177 ~2 ~132 red_nether_brick 0
fill ~177 ~2 ~135 ~177 ~4 ~135 netherrack 0
fill ~178 ~2 ~123 ~178 ~3 ~123 quartz_ore 0
setblock ~178 ~2 ~124 stained_hardened_clay 6
setblock ~178 ~2 ~126 stained_hardened_clay 6
setblock ~178 ~2 ~127 quartz_ore 0
setblock ~178 ~2 ~129 black_glazed_terracotta 0
setblock ~178 ~2 ~133 red_nether_brick 0
fill ~179 ~2 ~124 ~179 ~3 ~124 quartz_ore 0
setblock ~179 ~2 ~125 stone 2
setblock ~179 ~2 ~127 netherrack 0
fill ~179 ~2 ~128 ~180 ~2 ~128 quartz_ore 0
fill ~179 ~2 ~130 ~179 ~3 ~130 red_nether_brick 0
setblock ~179 ~2 ~133 nether_wart_block 0
setblock ~180 ~2 ~125 quartz_ore 0
fill ~180 ~2 ~129 ~183 ~2 ~129 netherrack 0
fill ~180 ~2 ~131 ~180 ~3 ~131 red_nether_brick 0
setblock ~180 ~2 ~132 netherrack 0
fill ~180 ~2 ~133 ~180 ~6 ~133 red_nether_brick 0
fill ~181 ~2 ~125 ~181 ~3 ~125 brick_block 0
setblock ~181 ~2 ~126 netherrack 0
fill ~182 ~2 ~126 ~182 ~3 ~126 quartz_ore 0
setblock ~183 ~2 ~127 netherrack 0
fill ~183 ~2 ~128 ~183 ~5 ~128 red_nether_brick 0
setblock ~1 ~3 ~127 red_nether_brick 0
setblock ~1 ~3 ~128 quartz_ore 0
setblock ~1 ~3 ~129 nether_wart_block 0
setblock ~2 ~3 ~126 red_nether_brick 0
setblock ~2 ~3 ~130 quartz_ore 0
fill ~3 ~3 ~125 ~3 ~4 ~125 quartz_ore 0
fill ~3 ~3 ~130 ~5 ~3 ~130 netherrack 0
setblock ~4 ~3 ~124 netherrack 0
fill ~4 ~3 ~131 ~4 ~6 ~131 black_glazed_terracotta 0
setblock ~4 ~3 ~132 red_nether_brick 0
fill ~4 ~3 ~133 ~4 ~4 ~133 netherrack 0
fill ~4 ~3 ~134 ~5 ~3 ~134 netherrack 0
setblock ~5 ~3 ~124 stained_hardened_clay 6
fill ~5 ~3 ~129 ~5 ~4 ~129 quartz_ore 0
setblock ~6 ~3 ~123 quartz_ore 0
setblock ~6 ~3 ~128 black_glazed_terracotta 0
setblock ~6 ~3 ~134 red_nether_brick 0
fill ~7 ~3 ~124 ~7 ~4 ~124 quartz_ore 0
fill ~7 ~3 ~127 ~7 ~4 ~127 netherrack 0
setblock ~7 ~3 ~133 noteblock 0
setblock ~7 ~3 ~135 noteblock 0
setblock ~7 ~3 ~136 red_nether_brick 0
setblock ~8 ~3 ~125 quartz_ore 0
fill ~8 ~3 ~126 ~8 ~4 ~126 netherrack 0
fill ~8 ~3 ~131 ~8 ~3 ~133 black_glazed_terracotta 0
setblock ~8 ~3 ~134 red_nether_brick 0
setblock ~9 ~3 ~126 red_nether_brick 0
setblock ~9 ~3 ~130 nether_brick 0
setblock ~9 ~3 ~137 noteblock 0
setblock ~10 ~3 ~127 quartz_ore 0
setblock ~10 ~3 ~128 netherrack 0
fill ~10 ~3 ~129 ~11 ~3 ~129 black_glazed_terracotta 0
fill ~10 ~3 ~130 ~10 ~4 ~130 black_glazed_terracotta 0
fill ~10 ~3 ~131 ~10 ~3 ~129 black_glazed_terracotta 0
setblock ~10 ~3 ~137 stained_hardened_clay 12
setblock ~11 ~3 ~128 red_nether_brick 0
setblock ~11 ~3 ~135 stained_hardened_clay 12
setblock ~11 ~3 ~136 nether_brick 0
setblock ~12 ~3 ~128 black_glazed_terracotta 0
fill ~12 ~3 ~133 ~12 ~3 ~134 red_nether_brick 0
fill ~12 ~3 ~136 ~12 ~4 ~136 black_glazed_terracotta 0
fill ~13 ~3 ~129 ~13 ~4 ~129 quartz_ore 0
fill ~13 ~3 ~131 ~14 ~3 ~131 black_glazed_terracotta 0
fill ~13 ~3 ~132 ~13 ~3 ~131 black_glazed_terracotta 0
setblock ~13 ~3 ~133 stained_hardened_clay 12
setblock ~13 ~3 ~134 stained_hardened_clay 15
setblock ~14 ~3 ~130 red_nether_brick 0
setblock ~14 ~3 ~132 red_nether_brick 0
setblock ~14 ~3 ~138 red_nether_brick 0
setblock ~15 ~3 ~130 black_glazed_terracotta 0
setblock ~15 ~3 ~136 red_nether_brick 0
setblock ~15 ~3 ~137 quartz_ore 0
setblock ~16 ~3 ~130 netherrack 0
setblock ~16 ~3 ~133 netherrack 0
setblock ~16 ~3 ~134 black_glazed_terracotta 0
setblock ~16 ~3 ~135 netherrack 0
fill ~17 ~3 ~131 ~17 ~3 ~132 netherrack 0
fill ~21 ~3 ~131 ~21 ~3 ~132 quartz_ore 0
fill ~22 ~3 ~129 ~22 ~3 ~130 quartz_ore 0
setblock ~22 ~3 ~132 red_nether_brick 0
setblock ~23 ~3 ~128 stained_hardened_clay 6
setblock ~23 ~3 ~132 netherrack 0
setblock ~24 ~3 ~128 stained_hardened_clay 14
setblock ~24 ~3 ~132 stained_hardened_clay 14
setblock ~25 ~3 ~129 stained_hardened_clay 14
setblock ~25 ~3 ~132 quartz_ore 0
setblock ~26 ~3 ~130 stained_hardened_clay 14
setblock ~26 ~3 ~131 netherrack 0
setblock ~39 ~3 ~31 stained_hardened_clay 6
setblock ~40 ~3 ~28 quartz_ore 0
setblock ~40 ~3 ~29 stained_hardened_clay 10
setblock ~40 ~3 ~30 stained_hardened_clay 14
setblock ~40 ~3 ~32 stained_hardened_clay 6
fill ~41 ~3 ~24 ~41 ~4 ~24 brick_block 0
fill ~41 ~3 ~25 ~41 ~3 ~24 brick_block 0
setblock ~41 ~3 ~26 dirt 0
setblock ~41 ~3 ~33 stained_hardened_clay 6
setblock ~42 ~3 ~21 brick_block 0
setblock ~42 ~3 ~22 quartz_ore 0
setblock ~42 ~3 ~23 brick_block 0
setblock ~42 ~3 ~34 stained_hardened_clay 14
setblock ~43 ~3 ~20 stained_hardened_clay 10
setblock ~43 ~3 ~34 quartz_ore 0
setblock ~44 ~3 ~20 quartz_ore 0
fill ~44 ~3 ~35 ~45 ~3 ~35 stained_hardened_clay 6
setblock ~45 ~3 ~36 quartz_ore 0
setblock ~46 ~3 ~37 gold_ore 0
fill ~47 ~3 ~18 ~49 ~3 ~18 quartz_ore 0
setblock ~47 ~3 ~38 stained_hardened_clay 8
setblock ~48 ~3 ~39 quartz_ore 0
setblock ~49 ~3 ~39 wool 8
setblock ~50 ~3 ~18 noteblock 0
setblock ~50 ~3 ~39 gold_ore 0
setblock ~50 ~3 ~40 stone 2
setblock ~51 ~3 ~18 quartz_ore 0
setblock ~51 ~3 ~39 wool 8
setblock ~52 ~3 ~19 quartz_ore 0
fill ~52 ~3 ~37 ~53 ~3 ~37 stained_hardened_clay 6
setblock ~52 ~3 ~38 stained_hardened_clay 14
setblock ~52 ~3 ~39 stained_hardened_clay 6
setblock ~53 ~3 ~20 quartz_ore 0
setblock ~53 ~3 ~36 quartz_ore 0
setblock ~54 ~3 ~20 noteblock 0
setblock ~54 ~3 ~34 quartz_ore 0
setblock ~54 ~3 ~35 stained_hardened_clay 10
setblock ~55 ~3 ~21 stained_hardened_clay 10
setblock ~55 ~3 ~32 quartz_ore 0
setblock ~56 ~3 ~22 quartz_ore 0
setblock ~56 ~3 ~31 stained_hardened_clay 10
fill ~57 ~3 ~24 ~57 ~4 ~24 quartz_ore 0
setblock ~57 ~3 ~25 stained_hardened_clay 10
fill ~57 ~3 ~30 ~57 ~4 ~30 quartz_ore 0
setblock ~58 ~3 ~26 quartz_ore 0
setblock ~58 ~3 ~27 stained_hardened_clay 10
setblock ~58 ~3 ~28 quartz_ore 0
setblock ~91 ~3 ~44 redstone_block 0
setblock ~92 ~3 ~43 redstone_block 0
setblock ~92 ~3 ~45 redstone_block 0
setblock ~93 ~3 ~44 redstone_block 0
setblock ~126 ~3 ~26 quartz_ore 0
setblock ~126 ~3 ~27 stained_hardened_clay 10
setblock ~126 ~3 ~28 quartz_ore 0
fill ~127 ~3 ~24 ~127 ~4 ~24 quartz_ore 0
setblock ~127 ~3 ~25 stained_hardened_clay 10
setblock ~127 ~3 ~29 dirt 0
fill ~127 ~3 ~30 ~127 ~4 ~30 quartz_ore 0
setblock ~128 ~3 ~22 quartz_ore 0
setblock ~128 ~3 ~31 stained_hardened_clay 10
setblock ~129 ~3 ~21 stained_hardened_clay 10
fill ~129 ~3 ~32 ~129 ~4 ~32 stained_hardened_clay 10
setblock ~129 ~3 ~33 brick_block 0
setblock ~130 ~3 ~20 noteblock 0
setblock ~130 ~3 ~34 quartz_ore 0
setblock ~130 ~3 ~35 stained_hardened_clay 10
setblock ~131 ~3 ~20 quartz_ore 0
setblock ~131 ~3 ~36 quartz_ore 0
fill ~131 ~3 ~37 ~132 ~3 ~37 stained_hardened_clay 6
setblock ~132 ~3 ~19 quartz_ore 0
setblock ~132 ~3 ~38 quartz_ore 0
setblock ~132 ~3 ~39 stained_hardened_clay 6
setblock ~133 ~3 ~18 quartz_ore 0
fill ~133 ~3 ~39 ~134 ~3 ~39 gold_ore 0
setblock ~134 ~3 ~18 noteblock 0
setblock ~134 ~3 ~40 gold_ore 0
fill ~135 ~3 ~18 ~137 ~3 ~18 quartz_ore 0
setblock ~135 ~3 ~39 wool 8
setblock ~136 ~3 ~39 quartz_ore 0
setblock ~137 ~3 ~38 quartz_ore 0
fill ~139 ~3 ~35 ~141 ~3 ~35 stained_hardened_clay 6
setblock ~139 ~3 ~36 quartz_ore 0
setblock ~140 ~3 ~20 quartz_ore 0
setblock ~141 ~3 ~20 stained_hardened_clay 10
setblock ~141 ~3 ~34 quartz_ore 0
setblock ~142 ~3 ~21 brick_block 0
setblock ~142 ~3 ~22 quartz_ore 0
setblock ~142 ~3 ~23 brick_block 0
setblock ~142 ~3 ~34 stained_hardened_clay 14
fill ~143 ~3 ~24 ~143 ~4 ~24 brick_block 0
fill ~143 ~3 ~25 ~143 ~3 ~24 brick_block 0
setblock ~143 ~3 ~26 dirt 0
setblock ~143 ~3 ~27 stone 1
setblock ~143 ~3 ~33 stained_hardened_clay 6
setblock ~144 ~3 ~28 quartz_ore 0
setblock ~144 ~3 ~29 stained_hardened_clay 10
setblock ~144 ~3 ~30 stained_hardened_clay 14
setblock ~144 ~3 ~32 hardened_clay 0
setblock ~145 ~3 ~31 stained_hardened_clay 6
setblock ~158 ~3 ~130 stained_hardened_clay 14
setblock ~158 ~3 ~131 stained_hardened_clay 6
setblock ~159 ~3 ~129 stained_hardened_clay 14
setblock ~159 ~3 ~132 quartz_ore 0
setblock ~160 ~3 ~128 stained_hardened_clay 14
fill ~160 ~3 ~132 ~160 ~4 ~132 netherrack 0
setblock ~161 ~3 ~128 quartz_ore 0
fill ~161 ~3 ~132 ~163 ~3 ~132 red_nether_brick 0
setblock ~162 ~3 ~129 stained_hardened_clay 6
setblock ~162 ~3 ~130 quartz_ore 0
setblock ~163 ~3 ~131 netherrack 0
setblock ~167 ~3 ~131 netherrack 0
fill ~168 ~3 ~130 ~168 ~4 ~130 netherrack 0
setblock ~169 ~3 ~137 red_nether_brick 0
fill ~170 ~3 ~130 ~170 ~3 ~132 red_nether_brick 0
setblock ~170 ~3 ~138 red_nether_brick 0
fill ~171 ~3 ~129 ~171 ~4 ~129 red_nether_brick 0
fill ~171 ~3 ~131 ~171 ~8 ~131 red_nether_brick 0
fill ~171 ~3 ~132 ~171 ~3 ~131 red_nether_brick 0
setblock ~171 ~3 ~133 black_glazed_terracotta 0
fill ~171 ~3 ~134 ~172 ~3 ~134 red_nether_brick 0
setblock ~172 ~3 ~128 netherrack 0
setblock ~172 ~3 ~135 stained_hardened_clay 15
fill ~173 ~3 ~128 ~173 ~3 ~129 red_nether_brick 0
fill ~173 ~3 ~135 ~173 ~4 ~135 red_nether_brick 0
fill ~173 ~3 ~136 ~173 ~6 ~136 red_nether_brick 0
fill ~174 ~3 ~127 ~174 ~4 ~127 netherrack 0
fill ~174 ~3 ~128 ~174 ~4 ~128 black_glazed_terracotta 0
setblock ~174 ~3 ~131 red_nether_brick 0
fill ~174 ~3 ~137 ~176 ~3 ~137 red_nether_brick 0
fill ~175 ~3 ~126 ~176 ~3 ~126 netherrack 0
setblock ~175 ~3 ~130 red_nether_brick 0
fill ~176 ~3 ~125 ~176 ~5 ~125 quartz_ore 0
fill ~176 ~3 ~131 ~176 ~3 ~132 red_nether_brick 0
setblock ~176 ~3 ~133 black_glazed_terracotta 0
setblock ~176 ~3 ~134 red_nether_brick 0
setblock ~177 ~3 ~127 netherrack 0
fill ~177 ~3 ~133 ~177 ~5 ~133 red_nether_brick 0
fill ~177 ~3 ~136 ~177 ~5 ~136 red_nether_brick 0
fill ~178 ~3 ~128 ~178 ~3 ~129 red_nether_brick 0
fill ~178 ~3 ~134 ~180 ~3 ~134 red_nether_brick 0
setblock ~179 ~3 ~129 netherrack 0
setblock ~180 ~3 ~124 quartz_ore 0
setblock ~180 ~3 ~130 netherrack 0
fill ~180 ~3 ~132 ~180 ~4 ~132 red_nether_brick 0
fill ~181 ~3 ~130 ~181 ~4 ~130 red_nether_brick 0
setblock ~182 ~3 ~130 netherrack 0
setblock ~183 ~3 ~127 nether_wart_block 0
fill ~183 ~3 ~129 ~183 ~4 ~129 nether_wart_block 0
setblock ~1 ~4 ~127 quartz_ore 0
setblock ~1 ~4 ~128 red_nether_brick 0
setblock ~1 ~4 ~129 quartz_ore 0
fill ~1 ~4 ~130 ~1 ~5 ~130 red_nether_brick 0
setblock ~2 ~4 ~126 netherrack 0
setblock ~2 ~4 ~130 netherrack 0
setblock ~3 ~4 ~130 stained_hardened_clay 12
fill ~4 ~4 ~125 ~4 ~5 ~125 netherrack 0
setblock ~4 ~4 ~130 noteblock 0
setblock ~4 ~4 ~132 quartz_ore 0
setblock ~4 ~4 ~134 quartz_ore 0
setblock ~5 ~4 ~124 netherrack 0
setblock ~5 ~4 ~130 stained_hardened_clay 12
fill ~5 ~4 ~135 ~5 ~5 ~135 noteblock 0
fill ~6 ~4 ~123 ~6 ~5 ~123 netherrack 0
setblock ~6 ~4 ~128 stained_hardened_clay 12
fill ~6 ~4 ~129 ~7 ~4 ~129 red_nether_brick 0
setblock ~6 ~4 ~130 black_glazed_terracotta 0
setblock ~6 ~4 ~134 noteblock 0
setblock ~7 ~4 ~128 red_nether_brick 0
setblock ~7 ~4 ~131 black_glazed_terracotta 0
setblock ~7 ~4 ~132 nether_brick 0
setblock ~7 ~4 ~133 stained_hardened_clay 12
fill ~7 ~4 ~135 ~7 ~5 ~135 red_nether_brick 0
setblock ~7 ~4 ~136 netherrack 0
setblock ~7 ~4 ~137 noteblock 0
fill ~8 ~4 ~125 ~8 ~5 ~125 netherrack 0
setblock ~8 ~4 ~129 coal_block 0
fill ~8 ~4 ~130 ~9 ~4 ~130 stained_hardened_clay 15
fill ~8 ~4 ~131 ~8 ~4 ~130 stained_hardened_clay 15
fill ~8 ~4 ~133 ~8 ~5 ~133 red_nether_brick 0
setblock ~8 ~4 ~134 black_glazed_terracotta 0
setblock ~9 ~4 ~126 quartz_ore 0
setblock ~9 ~4 ~129 nether_brick 0
fill ~9 ~4 ~132 ~9 ~4 ~133 black_glazed_terracotta 0
setblock ~9 ~4 ~138 red_nether_brick 0
setblock ~10 ~4 ~127 black_glazed_terracotta 0
setblock ~10 ~4 ~128 noteblock 0
fill ~10 ~4 ~129 ~11 ~4 ~129 black_glazed_terracotta 0
setblock ~10 ~4 ~131 stained_hardened_clay 15
setblock ~10 ~4 ~132 nether_brick 0
fill ~10 ~4 ~137 ~10 ~5 ~137 black_glazed_terracotta 0
setblock ~11 ~4 ~128 netherrack 0
setblock ~11 ~4 ~132 red_nether_brick 0
setblock ~11 ~4 ~133 black_glazed_terracotta 0
setblock ~11 ~4 ~134 nether_brick 0
fill ~11 ~4 ~135 ~11 ~4 ~136 black_glazed_terracotta 0
setblock ~12 ~4 ~128 noteblock 0
setblock ~12 ~4 ~132 black_glazed_terracotta 0
setblock ~12 ~4 ~133 stained_hardened_clay 15
setblock ~13 ~4 ~131 stained_hardened_clay 12
fill ~13 ~4 ~134 ~15 ~4 ~134 black_glazed_terracotta 0
setblock ~13 ~4 ~135 nether_brick 0
setblock ~13 ~4 ~138 stained_hardened_clay 12
setblock ~14 ~4 ~130 noteblock 0
fill ~14 ~4 ~131 ~14 ~5 ~131 black_glazed_terracotta 0
fill ~14 ~4 ~132 ~14 ~4 ~131 black_glazed_terracotta 0
setblock ~14 ~4 ~133 nether_brick 0
setblock ~14 ~4 ~138 nether_wart_block 0
setblock ~15 ~4 ~129 red_nether_brick 0
setblock ~15 ~4 ~133 black_glazed_terracotta 0
setblock ~15 ~4 ~135 netherrack 0
setblock ~15 ~4 ~136 black_glazed_terracotta 0
fill ~15 ~4 ~137 ~15 ~5 ~137 netherrack 0
setblock ~15 ~4 ~138 noteblock 0
setblock ~16 ~4 ~130 quartz_ore 0
setblock ~16 ~4 ~133 red_nether_brick 0
fill ~17 ~4 ~131 ~17 ~4 ~132 quartz_ore 0
fill ~20 ~4 ~130 ~21 ~4 ~130 quartz_ore 0
fill ~20 ~4 ~131 ~20 ~4 ~132 quartz_ore 0
fill ~21 ~4 ~133 ~21 ~6 ~133 quartz_ore 0
setblock ~22 ~4 ~129 red_nether_brick 0
fill ~22 ~4 ~133 ~22 ~8 ~133 netherrack 0
setblock ~23 ~4 ~129 glowstone 0
setblock ~23 ~4 ~133 quartz_ore 0
setblock ~24 ~4 ~128 stained_hardened_clay 6
setblock ~24 ~4 ~132 quartz_ore 0
setblock ~25 ~4 ~129 dirt 0
setblock ~25 ~4 ~130 quartz_ore 0
setblock ~25 ~4 ~131 brick_block 0
setblock ~40 ~4 ~28 brick_block 0
setblock ~40 ~4 ~29 quartz_ore 0
setblock ~40 ~4 ~30 stained_hardened_clay 6
setblock ~40 ~4 ~31 stained_hardened_clay 14
setblock ~41 ~4 ~25 stone 2
setblock ~41 ~4 ~26 brick_block 0
setblock ~41 ~4 ~31 brick_block 0
setblock ~41 ~4 ~32 stained_hardened_clay 10
setblock ~42 ~4 ~22 brick_block 0
setblock ~42 ~4 ~23 stained_hardened_clay 10
setblock ~42 ~4 ~24 brick_block 0
setblock ~42 ~4 ~25 quartz_ore 0
setblock ~42 ~4 ~30 brick_block 0
setblock ~42 ~4 ~31 quartz_ore 0
setblock ~42 ~4 ~32 brick_block 0
setblock ~42 ~4 ~33 stained_hardened_clay 14
setblock ~43 ~4 ~21 stone 2
setblock ~43 ~4 ~30 stained_hardened_clay 10
setblock ~43 ~4 ~31 brick_block 0
fill ~43 ~4 ~32 ~44 ~4 ~32 stained_hardened_clay 6
setblock ~43 ~4 ~33 brick_block 0
setblock ~44 ~4 ~20 brick_block 0
setblock ~44 ~4 ~31 quartz_ore 0
setblock ~44 ~4 ~33 quartz_ore 0
setblock ~44 ~4 ~34 brick_block 0
setblock ~45 ~4 ~32 stained_hardened_clay 10
setblock ~45 ~4 ~33 brick_block 0
setblock ~45 ~4 ~34 stained_hardened_clay 6
setblock ~46 ~4 ~18 brick_block 0
setblock ~46 ~4 ~33 quartz_ore 0
setblock ~46 ~4 ~34 brick_block 0
setblock ~46 ~4 ~35 quartz_ore 0
setblock ~46 ~4 ~36 stone 2
fill ~47 ~4 ~18 ~47 ~3 ~18 quartz_ore 0
setblock ~47 ~4 ~33 brick_block 0
setblock ~47 ~4 ~34 stained_hardened_clay 6
setblock ~47 ~4 ~35 brick_block 0
fill ~47 ~4 ~36 ~47 ~4 ~37 stained_hardened_clay 6
fill ~48 ~4 ~17 ~48 ~10 ~17 quartz_ore 0
setblock ~48 ~4 ~34 stained_hardened_clay 10
setblock ~48 ~4 ~35 quartz_ore 0
setblock ~48 ~4 ~37 netherrack 0
setblock ~48 ~4 ~38 dirt 0
setblock ~49 ~4 ~17 stained_hardened_clay 10
setblock ~49 ~4 ~37 brick_block 0
setblock ~49 ~4 ~38 stained_hardened_clay 6
fill ~50 ~4 ~17 ~50 ~6 ~17 quartz_ore 0
setblock ~50 ~4 ~37 quartz_ore 0
fill ~50 ~4 ~38 ~51 ~4 ~38 gold_ore 0
setblock ~51 ~4 ~17 stained_hardened_clay 10
fill ~51 ~4 ~36 ~51 ~4 ~37 stained_hardened_clay 6
setblock ~52 ~4 ~18 stained_hardened_clay 10
setblock ~52 ~4 ~36 brick_block 0
setblock ~52 ~4 ~37 quartz_ore 0
setblock ~53 ~4 ~19 stained_hardened_clay 10
setblock ~53 ~4 ~35 brick_block 0
setblock ~54 ~4 ~20 stained_hardened_clay 10
fill ~54 ~4 ~33 ~54 ~5 ~33 quartz_ore 0
setblock ~54 ~4 ~34 brick_block 0
fill ~55 ~4 ~20 ~55 ~5 ~20 quartz_ore 0
setblock ~55 ~4 ~32 stained_hardened_clay 10
fill ~56 ~4 ~21 ~56 ~5 ~21 quartz_ore 0
setblock ~56 ~4 ~22 stained_hardened_clay 10
setblock ~56 ~4 ~31 quartz_ore 0
fill ~57 ~4 ~23 ~57 ~5 ~23 stained_hardened_clay 10
fill ~58 ~4 ~25 ~58 ~5 ~25 quartz_ore 0
setblock ~58 ~4 ~26 brick_block 0
setblock ~58 ~4 ~27 quartz_ore 0
setblock ~58 ~4 ~28 brick_block 0
setblock ~92 ~4 ~44 red_mushroom_block 0
fill ~126 ~4 ~25 ~126 ~5 ~25 quartz_ore 0
setblock ~126 ~4 ~26 brick_block 0
setblock ~126 ~4 ~27 quartz_ore 0
setblock ~126 ~4 ~28 brick_block 0
fill ~127 ~4 ~23 ~127 ~5 ~23 stained_hardened_clay 10
setblock ~127 ~4 ~29 brick_block 0
fill ~128 ~4 ~21 ~128 ~5 ~21 quartz_ore 0
setblock ~128 ~4 ~22 stained_hardened_clay 10
setblock ~128 ~4 ~31 quartz_ore 0
fill ~129 ~4 ~20 ~129 ~5 ~20 quartz_ore 0
setblock ~130 ~4 ~20 stained_hardened_clay 10
fill ~130 ~4 ~33 ~130 ~5 ~33 quartz_ore 0
setblock ~130 ~4 ~34 brick_block 0
setblock ~131 ~4 ~19 stained_hardened_clay 10
setblock ~131 ~4 ~35 brick_block 0
setblock ~132 ~4 ~18 stained_hardened_clay 10
setblock ~132 ~4 ~36 brick_block 0
setblock ~132 ~4 ~37 quartz_ore 0
setblock ~133 ~4 ~17 stained_hardened_clay 10
setblock ~133 ~4 ~36 stained_hardened_clay 6
setblock ~133 ~4 ~37 brick_block 0
setblock ~133 ~4 ~38 gold_ore 0
fill ~134 ~4 ~17 ~134 ~6 ~17 quartz_ore 0
setblock ~134 ~4 ~37 quartz_ore 0
setblock ~134 ~4 ~38 wool 8
setblock ~135 ~4 ~17 stained_hardened_clay 10
setblock ~135 ~4 ~37 brick_block 0
fill ~135 ~4 ~38 ~136 ~4 ~38 stained_hardened_clay 6
fill ~136 ~4 ~17 ~136 ~10 ~17 quartz_ore 0
setblock ~136 ~4 ~34 stained_hardened_clay 10
setblock ~136 ~4 ~35 quartz_ore 0
setblock ~136 ~4 ~37 netherrack 0
setblock ~137 ~4 ~18 quartz_ore 0
setblock ~137 ~4 ~33 brick_block 0
setblock ~137 ~4 ~34 stained_hardened_clay 6
setblock ~137 ~4 ~35 brick_block 0
fill ~137 ~4 ~36 ~137 ~4 ~37 stained_hardened_clay 6
setblock ~138 ~4 ~18 brick_block 0
setblock ~138 ~4 ~33 quartz_ore 0
setblock ~138 ~4 ~34 brick_block 0
setblock ~138 ~4 ~35 quartz_ore 0
setblock ~138 ~4 ~36 stone 2
setblock ~139 ~4 ~32 dirt 0
setblock ~139 ~4 ~33 brick_block 0
setblock ~139 ~4 ~34 stained_hardened_clay 6
setblock ~140 ~4 ~20 brick_block 0
setblock ~140 ~4 ~31 quartz_ore 0
fill ~140 ~4 ~32 ~141 ~4 ~32 stained_hardened_clay 6
setblock ~140 ~4 ~33 quartz_ore 0
setblock ~140 ~4 ~34 brick_block 0
setblock ~141 ~4 ~21 stone 2
setblock ~141 ~4 ~30 stained_hardened_clay 10
setblock ~141 ~4 ~31 brick_block 0
setblock ~141 ~4 ~33 brick_block 0
setblock ~142 ~4 ~22 brick_block 0
setblock ~142 ~4 ~23 quartz_ore 0
setblock ~142 ~4 ~24 brick_block 0
setblock ~142 ~4 ~25 quartz_ore 0
setblock ~142 ~4 ~30 brick_block 0
setblock ~142 ~4 ~31 quartz_ore 0
setblock ~142 ~4 ~32 brick_block 0
setblock ~142 ~4 ~33 stained_hardened_clay 6
setblock ~143 ~4 ~25 stone 1
setblock ~143 ~4 ~26 brick_block 0
setblock ~143 ~4 ~27 stone 2
setblock ~143 ~4 ~31 brick_block 0
setblock ~143 ~4 ~32 stained_hardened_clay 10
setblock ~144 ~4 ~28 brick_block 0
setblock ~144 ~4 ~29 quartz_ore 0
setblock ~144 ~4 ~30 stained_hardened_clay 6
setblock ~144 ~4 ~31 stained_hardened_clay 14
setblock ~159 ~4 ~129 dirt 0
setblock ~159 ~4 ~130 quartz_ore 0
setblock ~159 ~4 ~131 stained_hardened_clay 6
setblock ~160 ~4 ~128 concrete_powder 8
setblock ~161 ~4 ~129 stone 2
setblock ~161 ~4 ~133 netherrack 0
setblock ~162 ~4 ~129 netherrack 0
fill ~162 ~4 ~133 ~162 ~6 ~133 red_nether_brick 0
fill ~163 ~4 ~130 ~164 ~4 ~130 quartz_ore 0
setblock ~163 ~4 ~133 netherrack 0
setblock ~164 ~4 ~131 netherrack 0
fill ~164 ~4 ~132 ~164 ~5 ~132 red_nether_brick 0
fill ~167 ~4 ~131 ~167 ~8 ~131 red_nether_brick 0
fill ~169 ~4 ~129 ~169 ~5 ~129 quartz_ore 0
setblock ~169 ~4 ~133 red_nether_brick 0
fill ~169 ~4 ~134 ~171 ~4 ~134 black_glazed_terracotta 0
setblock ~169 ~4 ~135 netherrack 0
setblock ~169 ~4 ~137 nether_wart_block 0
fill ~169 ~4 ~138 ~169 ~12 ~138 red_nether_brick 0
setblock ~170 ~4 ~130 netherrack 0
fill ~170 ~4 ~131 ~170 ~6 ~131 red_nether_brick 0
fill ~170 ~4 ~132 ~170 ~4 ~133 stained_hardened_clay 15
setblock ~170 ~4 ~138 nether_wart_block 0
setblock ~171 ~4 ~135 black_glazed_terracotta 0
setblock ~172 ~4 ~128 quartz_ore 0
fill ~172 ~4 ~132 ~174 ~4 ~132 red_nether_brick 0
setblock ~172 ~4 ~133 coal_block 0
fill ~173 ~4 ~128 ~173 ~5 ~128 netherrack 0
setblock ~173 ~4 ~129 black_glazed_terracotta 0
setblock ~173 ~4 ~133 red_nether_brick 0
fill ~173 ~4 ~134 ~173 ~5 ~134 stained_hardened_clay 15
fill ~174 ~4 ~129 ~174 ~5 ~129 red_nether_brick 0
setblock ~174 ~4 ~131 coal_block 0
fill ~174 ~4 ~137 ~174 ~5 ~137 red_nether_brick 0
fill ~175 ~4 ~126 ~176 ~4 ~126 quartz_ore 0
setblock ~175 ~4 ~129 nether_brick 0
fill ~175 ~4 ~130 ~176 ~4 ~130 stained_hardened_clay 15
setblock ~175 ~4 ~132 stained_hardened_clay 15
setblock ~175 ~4 ~133 black_glazed_terracotta 0
fill ~175 ~4 ~138 ~175 ~6 ~138 red_nether_brick 0
setblock ~176 ~4 ~129 concrete 15
setblock ~176 ~4 ~131 concrete 15
fill ~176 ~4 ~133 ~176 ~5 ~133 nether_brick 0
setblock ~176 ~4 ~134 black_glazed_terracotta 0
setblock ~177 ~4 ~127 stained_hardened_clay 12
fill ~177 ~4 ~128 ~177 ~4 ~129 red_nether_brick 0
setblock ~177 ~4 ~131 black_glazed_terracotta 0
setblock ~177 ~4 ~132 stained_hardened_clay 15
setblock ~177 ~4 ~137 nether_wart_block 0
setblock ~178 ~4 ~123 netherrack 0
setblock ~178 ~4 ~128 stained_hardened_clay 12
setblock ~178 ~4 ~129 black_glazed_terracotta 0
setblock ~178 ~4 ~130 noteblock 0
fill ~178 ~4 ~134 ~178 ~3 ~134 red_nether_brick 0
fill ~179 ~4 ~124 ~179 ~6 ~124 netherrack 0
setblock ~179 ~4 ~129 noteblock 0
fill ~179 ~4 ~130 ~180 ~4 ~130 black_glazed_terracotta 0
fill ~179 ~4 ~135 ~179 ~5 ~135 red_nether_brick 0
fill ~180 ~4 ~125 ~181 ~4 ~125 netherrack 0
fill ~180 ~4 ~131 ~180 ~5 ~131 black_glazed_terracotta 0
fill ~180 ~4 ~134 ~180 ~5 ~134 red_nether_brick 0
setblock ~182 ~4 ~126 nether_wart_block 0
fill ~182 ~4 ~130 ~183 ~4 ~130 red_nether_brick 0
setblock ~183 ~4 ~127 quartz_ore 0
fill ~1 ~5 ~128 ~1 ~6 ~128 netherrack 0
setblock ~1 ~5 ~129 nether_wart_block 0
setblock ~2 ~5 ~127 quartz_ore 0
setblock ~2 ~5 ~131 red_nether_brick 0
fill ~3 ~5 ~126 ~3 ~5 ~127 netherrack 0
setblock ~3 ~5 ~131 netherrack 0
setblock ~4 ~5 ~126 red_nether_brick 0
fill ~4 ~5 ~128 ~4 ~5 ~131 black_glazed_terracotta 0
setblock ~4 ~5 ~132 nether_brick 0
fill ~4 ~5 ~133 ~4 ~6 ~133 red_nether_brick 0
setblock ~4 ~5 ~134 netherrack 0
fill ~5 ~5 ~124 ~5 ~7 ~124 red_nether_brick 0
fill ~5 ~5 ~127 ~5 ~5 ~128 red_nether_brick 0
fill ~5 ~5 ~131 ~5 ~6 ~131 black_glazed_terracotta 0
fill ~6 ~5 ~127 ~6 ~6 ~127 stained_hardened_clay 15
fill ~6 ~5 ~131 ~7 ~5 ~131 red_nether_brick 0
setblock ~6 ~5 ~135 black_glazed_terracotta 0
setblock ~7 ~5 ~124 netherrack 0
fill ~7 ~5 ~127 ~7 ~6 ~127 red_nether_brick 0
setblock ~7 ~5 ~130 nether_brick 0
setblock ~7 ~5 ~132 stained_hardened_clay 15
fill ~7 ~5 ~133 ~7 ~5 ~134 nether_brick 0
fill ~7 ~5 ~136 ~7 ~5 ~137 black_glazed_terracotta 0
setblock ~8 ~5 ~126 noteblock 0
setblock ~8 ~5 ~128 stained_hardened_clay 15
setblock ~8 ~5 ~129 red_nether_brick 0
setblock ~8 ~5 ~134 concrete 15
setblock ~8 ~5 ~138 red_nether_brick 0
fill ~9 ~5 ~126 ~9 ~6 ~126 netherrack 0
setblock ~9 ~5 ~129 stained_hardened_clay 15
setblock ~9 ~5 ~133 red_nether_brick 0
setblock ~9 ~5 ~138 black_glazed_terracotta 0
setblock ~10 ~5 ~127 netherrack 0
fill ~10 ~5 ~128 ~11 ~5 ~128 red_nether_brick 0
setblock ~10 ~5 ~129 nether_brick 0
setblock ~10 ~5 ~130 concrete 15
setblock ~10 ~5 ~133 black_glazed_terracotta 0
fill ~10 ~5 ~134 ~11 ~5 ~134 stained_hardened_clay 15
setblock ~10 ~5 ~138 red_nether_brick 0
setblock ~11 ~5 ~129 red_nether_brick 0
fill ~11 ~5 ~131 ~11 ~5 ~132 stained_hardened_clay 15
setblock ~11 ~5 ~135 nether_brick 0
setblock ~11 ~5 ~136 stained_hardened_clay 15
setblock ~12 ~5 ~128 black_glazed_terracotta 0
setblock ~12 ~5 ~132 concrete 15
setblock ~12 ~5 ~136 coal_block 0
setblock ~12 ~5 ~137 red_nether_brick 0
setblock ~12 ~5 ~138 black_glazed_terracotta 0
setblock ~13 ~5 ~129 netherrack 0
fill ~13 ~5 ~131 ~13 ~7 ~131 black_glazed_terracotta 0
fill ~13 ~5 ~135 ~13 ~6 ~135 black_glazed_terracotta 0
fill ~13 ~5 ~139 ~14 ~5 ~139 red_nether_brick 0
setblock ~14 ~5 ~130 red_nether_brick 0
setblock ~14 ~5 ~132 coal_block 0
fill ~14 ~5 ~135 ~15 ~5 ~135 red_nether_brick 0
fill ~15 ~5 ~129 ~15 ~6 ~129 quartz_ore 0
fill ~15 ~5 ~132 ~17 ~5 ~132 red_nether_brick 0
setblock ~15 ~5 ~138 black_glazed_terracotta 0
setblock ~16 ~5 ~129 netherrack 0
setblock ~16 ~5 ~136 black_glazed_terracotta 0
setblock ~17 ~5 ~130 quartz_ore 0
setblock ~17 ~5 ~131 netherrack 0
fill ~20 ~5 ~130 ~20 ~5 ~133 netherrack 0
fill ~21 ~5 ~130 ~21 ~6 ~130 quartz_ore 0
setblock ~22 ~5 ~129 quartz_ore 0
setblock ~23 ~5 ~130 netherrack 0
fill ~23 ~5 ~132 ~24 ~5 ~132 netherrack 0
fill ~24 ~5 ~129 ~24 ~5 ~130 gold_ore 0
setblock ~24 ~5 ~131 netherrack 0
setblock ~41 ~5 ~27 brick_block 0
fill ~41 ~5 ~28 ~41 ~5 ~29 stained_hardened_clay 10
setblock ~41 ~5 ~30 quartz_ore 0
setblock ~42 ~5 ~26 quartz_ore 0
setblock ~42 ~5 ~27 dirt 0
setblock ~42 ~5 ~29 stained_hardened_clay 10
setblock ~43 ~5 ~22 stained_hardened_clay 10
fill ~43 ~5 ~23 ~43 ~6 ~23 brick_block 0
setblock ~43 ~5 ~24 stained_hardened_clay 10
setblock ~43 ~5 ~25 brick_block 0
setblock ~43 ~5 ~26 stained_hardened_clay 10
setblock ~43 ~5 ~29 brick_block 0
setblock ~44 ~5 ~20 quartz_ore 0
setblock ~44 ~5 ~21 stained_hardened_clay 10
setblock ~44 ~5 ~26 quartz_ore 0
setblock ~44 ~5 ~28 quartz_ore 0
setblock ~44 ~5 ~29 stained_hardened_clay 10
setblock ~44 ~5 ~30 quartz_ore 0
setblock ~45 ~5 ~19 stained_hardened_clay 10
setblock ~45 ~5 ~29 brick_block 0
setblock ~45 ~5 ~30 stained_hardened_clay 10
setblock ~45 ~5 ~31 log2 0
setblock ~46 ~5 ~18 quartz_ore 0
setblock ~46 ~5 ~30 quartz_ore 0
setblock ~46 ~5 ~31 stained_hardened_clay 10
fill ~46 ~5 ~32 ~54 ~5 ~32 quartz_ore 0
setblock ~47 ~5 ~17 stained_hardened_clay 10
setblock ~47 ~5 ~31 log2 0
setblock ~48 ~5 ~31 stained_hardened_clay 10
setblock ~48 ~5 ~33 quartz_ore 0
fill ~48 ~5 ~36 ~50 ~5 ~36 quartz_ore 0
setblock ~49 ~5 ~17 quartz_ore 0
setblock ~49 ~5 ~33 stained_hardened_clay 10
fill ~49 ~5 ~34 ~53 ~5 ~34 quartz_ore 0
fill ~49 ~5 ~35 ~50 ~5 ~35 quartz_ore 0
setblock ~50 ~5 ~33 quartz_ore 0
fill ~51 ~5 ~17 ~52 ~5 ~17 quartz_ore 0
setblock ~51 ~5 ~33 stained_hardened_clay 10
setblock ~51 ~5 ~35 stained_hardened_clay 6
setblock ~52 ~5 ~33 quartz_ore 0
setblock ~52 ~5 ~35 quartz_ore 0
fill ~53 ~5 ~18 ~53 ~6 ~18 quartz_ore 0
setblock ~53 ~5 ~33 stained_hardened_clay 10
setblock ~54 ~5 ~19 quartz_ore 0
fill ~54 ~5 ~31 ~54 ~6 ~31 quartz_ore 0
setblock ~55 ~5 ~31 stained_hardened_clay 10
setblock ~56 ~5 ~30 netherrack 0
fill ~57 ~5 ~22 ~57 ~6 ~22 quartz_ore 0
setblock ~57 ~5 ~27 stained_hardened_clay 10
setblock ~57 ~5 ~28 quartz_ore 0
setblock ~57 ~5 ~29 stained_hardened_clay 10
setblock ~58 ~5 ~24 quartz_ore 0
setblock ~58 ~5 ~26 quartz_ore 0
setblock ~126 ~5 ~24 quartz_ore 0
setblock ~126 ~5 ~26 quartz_ore 0
fill ~127 ~5 ~22 ~127 ~6 ~22 quartz_ore 0
setblock ~127 ~5 ~27 stained_hardened_clay 10
setblock ~127 ~5 ~28 quartz_ore 0
setblock ~127 ~5 ~29 stained_hardened_clay 10
setblock ~128 ~5 ~30 netherrack 0
fill ~129 ~5 ~31 ~130 ~5 ~31 stained_hardened_clay 10
setblock ~130 ~5 ~19 quartz_ore 0
fill ~130 ~5 ~32 ~138 ~5 ~32 quartz_ore 0
fill ~131 ~5 ~18 ~131 ~6 ~18 quartz_ore 0
setblock ~131 ~5 ~33 brick_block 0
fill ~131 ~5 ~34 ~135 ~5 ~34 quartz_ore 0
fill ~132 ~5 ~17 ~136 ~5 ~17 quartz_ore 0
setblock ~132 ~5 ~33 quartz_ore 0
setblock ~132 ~5 ~35 stained_hardened_clay 10
setblock ~133 ~5 ~33 stained_hardened_clay 10
setblock ~133 ~5 ~35 brick_block 0
setblock ~134 ~5 ~33 quartz_ore 0
fill ~134 ~5 ~35 ~135 ~5 ~35 quartz_ore 0
fill ~134 ~5 ~36 ~135 ~5 ~36 quartz_ore 0
setblock ~135 ~5 ~33 stained_hardened_clay 10
setblock ~136 ~5 ~31 stained_hardened_clay 10
setblock ~136 ~5 ~33 quartz_ore 0
setblock ~136 ~5 ~36 netherrack 0
setblock ~137 ~5 ~17 stained_hardened_clay 10
setblock ~137 ~5 ~31 log2 0
setblock ~138 ~5 ~18 quartz_ore 0
setblock ~138 ~5 ~30 quartz_ore 0
setblock ~138 ~5 ~31 stained_hardened_clay 10
setblock ~139 ~5 ~19 stained_hardened_clay 10
setblock ~139 ~5 ~29 brick_block 0
setblock ~139 ~5 ~30 stained_hardened_clay 10
setblock ~139 ~5 ~31 log2 0
setblock ~140 ~5 ~20 quartz_ore 0
setblock ~140 ~5 ~21 stained_hardened_clay 10
setblock ~140 ~5 ~26 quartz_ore 0
setblock ~140 ~5 ~28 quartz_ore 0
setblock ~140 ~5 ~29 stained_hardened_clay 10
setblock ~140 ~5 ~30 quartz_ore 0
setblock ~141 ~5 ~22 stained_hardened_clay 10
setblock ~141 ~5 ~23 brick_block 0
setblock ~141 ~5 ~24 stained_hardened_clay 10
setblock ~141 ~5 ~25 brick_block 0
setblock ~141 ~5 ~26 stained_hardened_clay 10
setblock ~141 ~5 ~29 brick_block 0
setblock ~142 ~5 ~26 quartz_ore 0
setblock ~142 ~5 ~27 stained_hardened_clay 10
fill ~142 ~5 ~29 ~143 ~5 ~29 stained_hardened_clay 10
setblock ~143 ~5 ~27 brick_block 0
setblock ~143 ~5 ~28 stained_hardened_clay 10
setblock ~143 ~5 ~30 quartz_ore 0
setblock ~160 ~5 ~129 gold_ore 0
setblock ~160 ~5 ~130 stained_hardened_clay 8
fill ~160 ~5 ~131 ~160 ~5 ~132 red_nether_brick 0
setblock ~161 ~5 ~130 quartz_ore 0
fill ~161 ~5 ~132 ~161 ~7 ~132 netherrack 0
setblock ~162 ~5 ~129 quartz_ore 0
fill ~163 ~5 ~130 ~163 ~4 ~130 quartz_ore 0
fill ~163 ~5 ~133 ~164 ~5 ~133 red_nether_brick 0
setblock ~164 ~5 ~130 netherrack 0
setblock ~164 ~5 ~131 black_glazed_terracotta 0
setblock ~167 ~5 ~130 red_nether_brick 0
setblock ~168 ~5 ~129 netherrack 0
fill ~168 ~5 ~132 ~169 ~5 ~132 red_nether_brick 0
fill ~168 ~5 ~136 ~168 ~7 ~136 red_nether_brick 0
fill ~169 ~5 ~135 ~169 ~6 ~135 stained_hardened_clay 12
setblock ~169 ~5 ~137 red_nether_brick 0
fill ~170 ~5 ~130 ~170 ~7 ~130 red_nether_brick 0
setblock ~170 ~5 ~132 concrete 15
fill ~170 ~5 ~135 ~170 ~6 ~135 black_glazed_terracotta 0
fill ~170 ~5 ~139 ~171 ~5 ~139 red_nether_brick 0
setblock ~171 ~5 ~129 netherrack 0
setblock ~171 ~5 ~135 nether_brick 0
setblock ~172 ~5 ~128 netherrack 0
setblock ~172 ~5 ~132 concrete 15
setblock ~172 ~5 ~136 stained_hardened_clay 15
setblock ~172 ~5 ~138 red_nether_brick 0
fill ~173 ~5 ~129 ~173 ~6 ~129 red_nether_brick 0
setblock ~173 ~5 ~131 stained_hardened_clay 15
setblock ~173 ~5 ~132 coal_block 0
setblock ~173 ~5 ~135 stained_hardened_clay 15
fill ~174 ~5 ~127 ~174 ~5 ~129 red_nether_brick 0
setblock ~174 ~5 ~130 concrete 15
setblock ~174 ~5 ~133 red_nether_brick 0
setblock ~174 ~5 ~134 stained_hardened_clay 15
fill ~174 ~5 ~138 ~174 ~7 ~138 red_nether_brick 0
setblock ~175 ~5 ~126 netherrack 0
setblock ~175 ~5 ~129 stained_hardened_clay 15
setblock ~175 ~5 ~133 nether_brick 0
fill ~176 ~5 ~126 ~176 ~6 ~126 noteblock 0
fill ~176 ~5 ~128 ~176 ~8 ~128 red_nether_brick 0
fill ~176 ~5 ~129 ~176 ~6 ~129 red_nether_brick 0
setblock ~176 ~5 ~134 stained_hardened_clay 15
setblock ~176 ~5 ~138 red_nether_brick 0
setblock ~177 ~5 ~124 netherrack 0
setblock ~177 ~5 ~127 red_nether_brick 0
setblock ~177 ~5 ~130 black_glazed_terracotta 0
setblock ~177 ~5 ~131 stained_hardened_clay 12
setblock ~177 ~5 ~132 coal_block 0
fill ~177 ~5 ~134 ~177 ~5 ~137 red_nether_brick 0
setblock ~178 ~5 ~123 quartz_ore 0
setblock ~178 ~5 ~127 stained_hardened_clay 15
fill ~178 ~5 ~131 ~178 ~6 ~131 black_glazed_terracotta 0
fill ~178 ~5 ~135 ~178 ~6 ~135 red_nether_brick 0
setblock ~179 ~5 ~127 red_nether_brick 0
setblock ~179 ~5 ~128 black_glazed_terracotta 0
setblock ~179 ~5 ~131 stained_hardened_clay 12
fill ~180 ~5 ~125 ~180 ~4 ~125 netherrack 0
fill ~180 ~5 ~126 ~181 ~5 ~126 netherrack 0
setblock ~180 ~5 ~128 red_nether_brick 0
setblock ~180 ~5 ~129 black_glazed_terracotta 0
setblock ~180 ~5 ~130 red_nether_brick 0
setblock ~180 ~5 ~132 black_glazed_terracotta 0
setblock ~181 ~5 ~127 quartz_ore 0
fill ~181 ~5 ~131 ~182 ~5 ~131 red_nether_brick 0
setblock ~182 ~5 ~127 netherrack 0
setblock ~183 ~5 ~129 netherrack 0
setblock ~183 ~5 ~130 red_nether_brick 0
setblock ~1 ~6 ~129 quartz_ore 0
fill ~1 ~6 ~130 ~1 ~8 ~130 netherrack 0
setblock ~2 ~6 ~128 quartz_ore 0
setblock ~2 ~6 ~131 netherrack 0
fill ~3 ~6 ~128 ~4 ~6 ~128 noteblock 0
setblock ~3 ~6 ~131 quartz_ore 0
setblock ~3 ~6 ~132 black_glazed_terracotta 0
setblock ~4 ~6 ~127 quartz_ore 0
setblock ~4 ~6 ~129 nether_brick 0
setblock ~4 ~6 ~130 stained_hardened_clay 12
setblock ~4 ~6 ~132 stained_hardened_clay 7
setblock ~4 ~6 ~134 quartz_ore 0
setblock ~4 ~6 ~135 red_nether_brick 0
setblock ~5 ~6 ~125 nether_wart_block 0
setblock ~5 ~6 ~126 red_nether_brick 0
fill ~5 ~6 ~136 ~6 ~6 ~136 black_glazed_terracotta 0
fill ~6 ~6 ~124 ~6 ~7 ~124 netherrack 0
setblock ~6 ~6 ~131 stained_hardened_clay 15
setblock ~6 ~6 ~135 red_nether_brick 0
setblock ~6 ~6 ~137 red_nether_brick 0
setblock ~7 ~6 ~124 dirt 1
setblock ~7 ~6 ~132 red_nether_brick 0
setblock ~7 ~6 ~133 black_glazed_terracotta 0
fill ~7 ~6 ~134 ~7 ~7 ~134 red_nether_brick 0
setblock ~7 ~6 ~135 stained_hardened_clay 12
fill ~7 ~6 ~138 ~7 ~7 ~138 netherrack 0
setblock ~8 ~6 ~125 red_nether_brick 0
setblock ~8 ~6 ~126 log2 0
fill ~8 ~6 ~128 ~8 ~7 ~128 red_nether_brick 0
setblock ~8 ~6 ~129 nether_brick 0
setblock ~8 ~6 ~133 stained_hardened_clay 15
setblock ~8 ~6 ~138 nether_wart_block 0
fill ~9 ~6 ~129 ~9 ~7 ~129 black_glazed_terracotta 0
fill ~9 ~6 ~133 ~9 ~8 ~133 stained_hardened_clay 12
setblock ~9 ~6 ~138 stained_hardened_clay 12
setblock ~10 ~6 ~127 soul_sand 0
setblock ~10 ~6 ~128 netherrack 0
setblock ~10 ~6 ~129 coal_block 0
fill ~10 ~6 ~130 ~10 ~7 ~130 red_nether_brick 0
setblock ~10 ~6 ~133 nether_brick 0
setblock ~10 ~6 ~138 soul_sand 0
fill ~11 ~6 ~128 ~11 ~6 ~129 black_glazed_terracotta 0
fill ~11 ~6 ~131 ~12 ~6 ~131 red_nether_brick 0
setblock ~11 ~6 ~132 stained_hardened_clay 15
setblock ~11 ~6 ~134 nether_brick 0
setblock ~11 ~6 ~135 red_nether_brick 0
setblock ~11 ~6 ~136 nether_brick 0
fill ~11 ~6 ~137 ~11 ~6 ~138 black_glazed_terracotta 0
setblock ~12 ~6 ~128 wool 12
setblock ~12 ~6 ~135 stained_hardened_clay 15
setblock ~12 ~6 ~136 stained_hardened_clay 7
setblock ~12 ~6 ~139 black_glazed_terracotta 0
setblock ~13 ~6 ~128 black_glazed_terracotta 0
setblock ~13 ~6 ~139 quartz_ore 0
setblock ~14 ~6 ~129 red_nether_brick 0
setblock ~14 ~6 ~130 black_glazed_terracotta 0
setblock ~14 ~6 ~131 nether_brick 0
fill ~14 ~6 ~135 ~14 ~5 ~135 red_nether_brick 0
setblock ~14 ~6 ~139 red_nether_brick 0
fill ~15 ~6 ~132 ~15 ~5 ~132 red_nether_brick 0
fill ~15 ~6 ~135 ~15 ~7 ~135 stained_hardened_clay 12
fill ~15 ~6 ~138 ~15 ~7 ~138 netherrack 0
setblock ~16 ~6 ~129 noteblock 0
setblock ~16 ~6 ~132 black_glazed_terracotta 0
setblock ~16 ~6 ~136 netherrack 0
setblock ~16 ~6 ~137 black_glazed_terracotta 0
setblock ~17 ~6 ~130 brown_glazed_terracotta 0
setblock ~17 ~6 ~131 noteblock 0
setblock ~17 ~6 ~132 netherrack 0
setblock ~19 ~6 ~131 quartz_ore 0
setblock ~19 ~6 ~132 netherrack 0
setblock ~20 ~6 ~130 quartz_ore 0
setblock ~20 ~6 ~133 black_glazed_terracotta 0
setblock ~22 ~6 ~130 quartz_ore 0
setblock ~23 ~6 ~131 quartz_ore 0
fill ~23 ~6 ~132 ~23 ~9 ~132 netherrack 0
setblock ~42 ~6 ~28 stone 2
setblock ~43 ~6 ~27 stone 1
setblock ~43 ~6 ~28 brick_block 0
setblock ~44 ~6 ~22 brick_block 0
setblock ~44 ~6 ~24 brick_block 0
setblock ~44 ~6 ~25 quartz_ore 0
setblock ~44 ~6 ~26 brick_block 0
setblock ~44 ~6 ~27 quartz_ore 0
setblock ~45 ~6 ~19 brick_block 0
setblock ~45 ~6 ~20 stained_hardened_clay 10
setblock ~45 ~6 ~21 brick_block 0
setblock ~45 ~6 ~27 stained_hardened_clay 8
setblock ~45 ~6 ~28 log2 0
setblock ~46 ~6 ~18 dirt 0
setblock ~46 ~6 ~28 brick_block 0
setblock ~46 ~6 ~29 quartz_ore 0
setblock ~47 ~6 ~17 brick_block 0
setblock ~47 ~6 ~29 stained_hardened_clay 8
setblock ~47 ~6 ~30 stained_hardened_clay 10
setblock ~48 ~6 ~30 brick_block 0
setblock ~49 ~6 ~17 log2 0
setblock ~49 ~6 ~31 brick_block 0
setblock ~50 ~6 ~31 quartz_ore 0
setblock ~51 ~6 ~17 log2 0
setblock ~51 ~6 ~31 stained_hardened_clay 10
fill ~52 ~6 ~17 ~52 ~7 ~17 quartz_ore 0
setblock ~52 ~6 ~31 quartz_ore 0
setblock ~53 ~6 ~31 brick_block 0
setblock ~54 ~6 ~18 stained_hardened_clay 10
setblock ~54 ~6 ~30 stained_hardened_clay 10
fill ~55 ~6 ~19 ~55 ~7 ~19 stained_hardened_clay 10
setblock ~55 ~6 ~29 mycelium 0
setblock ~55 ~6 ~30 quartz_ore 0
setblock ~56 ~6 ~20 stained_hardened_clay 10
fill ~56 ~6 ~27 ~56 ~9 ~27 quartz_ore 0
setblock ~56 ~6 ~28 stained_hardened_clay 10
setblock ~56 ~6 ~29 quartz_ore 0
setblock ~57 ~6 ~21 log2 0
setblock ~57 ~6 ~25 log2 0
setblock ~57 ~6 ~26 stained_hardened_clay 10
fill ~58 ~6 ~23 ~58 ~9 ~23 quartz_ore 0
setblock ~58 ~6 ~24 log2 0
fill ~126 ~6 ~23 ~126 ~9 ~23 quartz_ore 0
setblock ~126 ~6 ~24 brick_block 0
setblock ~127 ~6 ~21 log2 0
setblock ~127 ~6 ~25 log2 0
setblock ~127 ~6 ~26 stained_hardened_clay 10
setblock ~128 ~6 ~20 stained_hardened_clay 10
fill ~128 ~6 ~27 ~128 ~9 ~27 quartz_ore 0
setblock ~128 ~6 ~28 stained_hardened_clay 10
setblock ~128 ~6 ~29 quartz_ore 0
fill ~129 ~6 ~19 ~129 ~7 ~19 stained_hardened_clay 10
setblock ~129 ~6 ~29 log2 0
setblock ~129 ~6 ~30 quartz_ore 0
setblock ~130 ~6 ~18 stained_hardened_clay 10
setblock ~130 ~6 ~30 stained_hardened_clay 10
setblock ~130 ~6 ~31 quartz_ore 0
setblock ~131 ~6 ~31 brick_block 0
fill ~132 ~6 ~17 ~132 ~7 ~17 quartz_ore 0
setblock ~132 ~6 ~31 quartz_ore 0
setblock ~133 ~6 ~17 mycelium 0
setblock ~133 ~6 ~31 stained_hardened_clay 10
setblock ~134 ~6 ~31 quartz_ore 0
setblock ~135 ~6 ~17 log2 0
setblock ~135 ~6 ~31 brick_block 0
setblock ~136 ~6 ~30 log2 0
setblock ~137 ~6 ~17 brick_block 0
setblock ~137 ~6 ~29 stained_hardened_clay 8
setblock ~137 ~6 ~30 stained_hardened_clay 10
setblock ~138 ~6 ~18 brick_block 0
setblock ~138 ~6 ~28 stained_hardened_clay 8
setblock ~138 ~6 ~29 quartz_ore 0
setblock ~139 ~6 ~19 brick_block 0
setblock ~139 ~6 ~20 stained_hardened_clay 10
setblock ~139 ~6 ~21 brick_block 0
setblock ~139 ~6 ~27 stained_hardened_clay 8
setblock ~139 ~6 ~28 log2 0
setblock ~140 ~6 ~22 brick_block 0
setblock ~140 ~6 ~24 brick_block 0
setblock ~140 ~6 ~25 quartz_ore 0
setblock ~140 ~6 ~26 brick_block 0
setblock ~140 ~6 ~27 quartz_ore 0
setblock ~141 ~6 ~23 stone 1
setblock ~141 ~6 ~27 stone 1
setblock ~141 ~6 ~28 brick_block 0
setblock ~142 ~6 ~28 stone 2
setblock ~161 ~6 ~131 brick_block 0
setblock ~162 ~6 ~130 quartz_ore 0
setblock ~163 ~6 ~130 noteblock 0
setblock ~163 ~6 ~133 nether_wart_block 0
setblock ~164 ~6 ~130 stained_hardened_clay 6
fill ~164 ~6 ~133 ~164 ~7 ~133 red_nether_brick 0
setblock ~165 ~6 ~131 netherrack 0
setblock ~165 ~6 ~132 black_glazed_terracotta 0
setblock ~167 ~6 ~130 redstone_ore 0
fill ~168 ~6 ~129 ~168 ~7 ~129 stained_hardened_clay 8
fill ~168 ~6 ~132 ~169 ~6 ~132 red_nether_brick 0
fill ~168 ~6 ~137 ~168 ~11 ~137 red_nether_brick 0
fill ~169 ~6 ~129 ~169 ~7 ~129 mycelium 0
fill ~170 ~6 ~129 ~170 ~8 ~129 red_nether_brick 0
fill ~170 ~6 ~139 ~170 ~17 ~139 red_nether_brick 0
setblock ~171 ~6 ~128 wool 12
setblock ~171 ~6 ~135 stained_hardened_clay 12
setblock ~171 ~6 ~139 nether_wart_block 0
setblock ~172 ~6 ~128 quartz_ore 0
fill ~172 ~6 ~131 ~173 ~6 ~131 red_nether_brick 0
setblock ~172 ~6 ~135 stained_hardened_clay 15
setblock ~172 ~6 ~136 red_nether_brick 0
fill ~172 ~6 ~139 ~172 ~7 ~139 red_nether_brick 0
fill ~173 ~6 ~128 ~173 ~7 ~128 black_glazed_terracotta 0
setblock ~173 ~6 ~132 stained_hardened_clay 15
fill ~173 ~6 ~134 ~173 ~7 ~134 red_nether_brick 0
setblock ~173 ~6 ~135 black_glazed_terracotta 0
fill ~173 ~6 ~137 ~173 ~7 ~137 red_nether_brick 0
fill ~173 ~6 ~138 ~173 ~7 ~138 red_nether_brick 0
setblock ~174 ~6 ~127 log2 0
fill ~174 ~6 ~128 ~174 ~8 ~128 red_nether_brick 0
setblock ~174 ~6 ~129 coal_block 0
fill ~174 ~6 ~130 ~174 ~7 ~130 red_nether_brick 0
setblock ~174 ~6 ~133 stained_hardened_clay 15
setblock ~175 ~6 ~126 brown_glazed_terracotta 0
setblock ~175 ~6 ~129 nether_brick 0
setblock ~175 ~6 ~133 noteblock 0
setblock ~176 ~6 ~125 netherrack 0
setblock ~176 ~6 ~133 stained_hardened_clay 15
setblock ~176 ~6 ~138 nether_wart_block 0
setblock ~177 ~6 ~124 dirt 0
setblock ~177 ~6 ~127 black_glazed_terracotta 0
setblock ~177 ~6 ~132 red_nether_brick 0
fill ~177 ~6 ~133 ~177 ~6 ~134 nether_brick 0
setblock ~177 ~6 ~135 red_nether_brick 0
fill ~177 ~6 ~138 ~177 ~14 ~138 red_nether_brick 0
setblock ~178 ~6 ~124 quartz_ore 0
setblock ~178 ~6 ~127 coal_block 0
fill ~178 ~6 ~136 ~179 ~6 ~136 red_nether_brick 0
fill ~178 ~6 ~137 ~178 ~9 ~137 red_nether_brick 0
setblock ~179 ~6 ~125 quartz_ore 0
fill ~179 ~6 ~126 ~179 ~7 ~126 red_nether_brick 0
setblock ~179 ~6 ~131 noteblock 0
setblock ~180 ~6 ~127 netherrack 0
setblock ~180 ~6 ~128 noteblock 0
setblock ~180 ~6 ~129 stained_hardened_clay 15
setblock ~180 ~6 ~130 noteblock 0
setblock ~180 ~6 ~131 nether_brick 0
fill ~180 ~6 ~132 ~181 ~6 ~132 red_nether_brick 0
setblock ~180 ~6 ~134 nether_wart_block 0
fill ~180 ~6 ~135 ~180 ~9 ~135 red_nether_brick 0
fill ~181 ~6 ~128 ~181 ~7 ~128 netherrack 0
fill ~181 ~6 ~131 ~182 ~6 ~131 red_nether_brick 0
fill ~182 ~6 ~128 ~182 ~10 ~128 quartz_ore 0
setblock ~183 ~6 ~128 netherrack 0
setblock ~183 ~6 ~129 nether_wart_block 0
setblock ~183 ~6 ~130 netherrack 0
setblock ~1 ~7 ~129 netherrack 0
setblock ~1 ~7 ~131 netherrack 0
setblock ~2 ~7 ~128 black_glazed_terracotta 0
setblock ~2 ~7 ~131 red_nether_brick 0
setblock ~2 ~7 ~132 black_glazed_terracotta 0
setblock ~3 ~7 ~128 red_nether_brick 0
setblock ~3 ~7 ~132 stained_hardened_clay 12
fill ~3 ~7 ~133 ~3 ~8 ~133 quartz_ore 0
setblock ~4 ~7 ~129 black_glazed_terracotta 0
setblock ~4 ~7 ~130 stained_hardened_clay 15
setblock ~4 ~7 ~131 red_nether_brick 0
setblock ~4 ~7 ~134 red_nether_brick 0
setblock ~4 ~7 ~135 noteblock 0
setblock ~5 ~7 ~125 red_nether_brick 0
setblock ~5 ~7 ~126 black_glazed_terracotta 0
fill ~5 ~7 ~130 ~5 ~9 ~130 black_glazed_terracotta 0
fill ~5 ~7 ~136 ~5 ~9 ~136 red_nether_brick 0
fill ~6 ~7 ~127 ~7 ~7 ~127 black_glazed_terracotta 0
setblock ~6 ~7 ~131 nether_brick 0
setblock ~6 ~7 ~137 netherrack 0
setblock ~7 ~7 ~124 stained_hardened_clay 8
setblock ~7 ~7 ~131 black_glazed_terracotta 0
setblock ~8 ~7 ~124 soul_sand 0
setblock ~8 ~7 ~125 netherrack 0
setblock ~8 ~7 ~126 black_glazed_terracotta 0
setblock ~8 ~7 ~132 stained_hardened_clay 15
fill ~8 ~7 ~133 ~8 ~8 ~133 nether_brick 0
fill ~8 ~7 ~139 ~8 ~8 ~139 black_glazed_terracotta 0
setblock ~9 ~7 ~126 mycelium 0
setblock ~9 ~7 ~139 noteblock 0
setblock ~10 ~7 ~127 quartz_ore 0
fill ~10 ~7 ~128 ~11 ~7 ~128 red_nether_brick 0
fill ~10 ~7 ~129 ~11 ~7 ~129 red_nether_brick 0
setblock ~10 ~7 ~133 black_glazed_terracotta 0
setblock ~10 ~7 ~138 red_nether_brick 0
fill ~10 ~7 ~139 ~11 ~7 ~139 stained_hardened_clay 12
setblock ~11 ~7 ~131 nether_brick 0
fill ~11 ~7 ~134 ~12 ~7 ~134 stained_hardened_clay 15
setblock ~11 ~7 ~137 stained_hardened_clay 12
setblock ~11 ~7 ~138 noteblock 0
setblock ~12 ~7 ~128 log2 0
fill ~12 ~7 ~131 ~12 ~8 ~131 stained_hardened_clay 15
setblock ~12 ~7 ~135 red_nether_brick 0
setblock ~12 ~7 ~139 red_nether_brick 0
setblock ~13 ~7 ~128 netherrack 0
fill ~13 ~7 ~134 ~14 ~7 ~134 red_nether_brick 0
setblock ~13 ~7 ~139 netherrack 0
setblock ~14 ~7 ~129 noteblock 0
setblock ~14 ~7 ~130 red_nether_brick 0
setblock ~14 ~7 ~139 black_glazed_terracotta 0
setblock ~15 ~7 ~129 red_nether_brick 0
setblock ~15 ~7 ~131 red_nether_brick 0
fill ~16 ~7 ~129 ~16 ~8 ~129 mycelium 0
fill ~16 ~7 ~132 ~17 ~7 ~132 red_nether_brick 0
setblock ~16 ~7 ~136 red_nether_brick 0
setblock ~16 ~7 ~137 noteblock 0
setblock ~17 ~7 ~129 netherrack 0
setblock ~17 ~7 ~130 black_glazed_terracotta 0
setblock ~17 ~7 ~131 red_nether_brick 0
setblock ~19 ~7 ~131 noteblock 0
setblock ~19 ~7 ~132 black_glazed_terracotta 0
fill ~20 ~7 ~130 ~21 ~7 ~130 red_nether_brick 0
setblock ~20 ~7 ~133 netherrack 0
setblock ~21 ~7 ~133 noteblock 0
setblock ~22 ~7 ~130 black_glazed_terracotta 0
setblock ~23 ~7 ~131 noteblock 0
setblock ~44 ~7 ~23 stained_hardened_clay 10
setblock ~44 ~7 ~24 quartz_ore 0
setblock ~44 ~7 ~25 stained_hardened_clay 10
setblock ~45 ~7 ~20 quartz_ore 0
setblock ~45 ~7 ~21 log2 0
fill ~45 ~7 ~22 ~45 ~9 ~22 stained_hardened_clay 10
fill ~45 ~7 ~26 ~45 ~8 ~26 stained_hardened_clay 10
setblock ~45 ~7 ~27 brick_block 0
setblock ~46 ~7 ~18 quartz_ore 0
setblock ~46 ~7 ~19 stained_hardened_clay 10
setblock ~46 ~7 ~27 stained_hardened_clay 10
setblock ~47 ~7 ~17 dirt 0
setblock ~47 ~7 ~28 quartz_ore 0
fill ~48 ~7 ~29 ~49 ~7 ~29 stained_hardened_clay 10
setblock ~49 ~7 ~17 stained_hardened_clay 10
setblock ~49 ~7 ~30 quartz_ore 0
setblock ~50 ~7 ~16 quartz_ore 0
setblock ~50 ~7 ~30 noteblock 0
setblock ~51 ~7 ~17 stained_hardened_clay 10
setblock ~51 ~7 ~30 quartz_ore 0
setblock ~52 ~7 ~30 noteblock 0
setblock ~53 ~7 ~17 stained_hardened_clay 10
setblock ~53 ~7 ~30 quartz_ore 0
setblock ~54 ~7 ~18 noteblock 0
setblock ~54 ~7 ~29 quartz_ore 0
fill ~55 ~7 ~27 ~55 ~8 ~27 stained_hardened_clay 10
setblock ~55 ~7 ~28 quartz_ore 0
setblock ~56 ~7 ~20 quartz_ore 0
setblock ~56 ~7 ~26 quartz_ore 0
setblock ~57 ~7 ~21 stained_hardened_clay 10
setblock ~57 ~7 ~25 stained_hardened_clay 10
setblock ~58 ~7 ~22 noteblock 0
setblock ~58 ~7 ~24 noteblock 0
setblock ~126 ~7 ~22 netherrack 0
setblock ~126 ~7 ~24 noteblock 0
setblock ~127 ~7 ~21 stained_hardened_clay 10
setblock ~127 ~7 ~25 stained_hardened_clay 10
setblock ~128 ~7 ~20 noteblock 0
setblock ~128 ~7 ~26 quartz_ore 0
fill ~129 ~7 ~27 ~129 ~8 ~27 stained_hardened_clay 10
setblock ~129 ~7 ~28 quartz_ore 0
setblock ~130 ~7 ~18 noteblock 0
setblock ~130 ~7 ~29 quartz_ore 0
setblock ~131 ~7 ~17 stained_hardened_clay 10
setblock ~131 ~7 ~30 quartz_ore 0
setblock ~132 ~7 ~30 noteblock 0
setblock ~133 ~7 ~17 stained_hardened_clay 10
setblock ~133 ~7 ~30 quartz_ore 0
setblock ~134 ~7 ~16 quartz_ore 0
setblock ~134 ~7 ~30 noteblock 0
setblock ~135 ~7 ~17 stained_hardened_clay 10
fill ~135 ~7 ~29 ~136 ~7 ~29 stained_hardened_clay 10
setblock ~135 ~7 ~30 quartz_ore 0
setblock ~137 ~7 ~17 log2 0
setblock ~137 ~7 ~28 quartz_ore 0
setblock ~138 ~7 ~18 quartz_ore 0
setblock ~138 ~7 ~19 stained_hardened_clay 10
setblock ~138 ~7 ~27 stained_hardened_clay 10
setblock ~139 ~7 ~20 quartz_ore 0
setblock ~139 ~7 ~21 log2 0
setblock ~139 ~7 ~22 stained_hardened_clay 10
setblock ~139 ~7 ~26 quartz_ore 0
setblock ~139 ~7 ~27 brick_block 0
setblock ~140 ~7 ~23 stained_hardened_clay 10
setblock ~140 ~7 ~24 quartz_ore 0
setblock ~140 ~7 ~25 stained_hardened_clay 10
setblock ~161 ~7 ~131 quartz_ore 0
setblock ~162 ~7 ~130 netherrack 0
fill ~162 ~7 ~133 ~163 ~7 ~133 netherrack 0
fill ~163 ~7 ~130 ~164 ~7 ~130 quartz_ore 0
fill ~165 ~7 ~131 ~165 ~8 ~131 quartz_ore 0
fill ~165 ~7 ~132 ~165 ~8 ~132 red_nether_brick 0
setblock ~167 ~7 ~129 log2 0
setblock ~167 ~7 ~130 red_nether_brick 0
fill ~168 ~7 ~132 ~168 ~5 ~132 red_nether_brick 0
setblock ~169 ~7 ~131 red_nether_brick 0
fill ~169 ~7 ~135 ~169 ~8 ~135 black_glazed_terracotta 0
fill ~170 ~7 ~134 ~171 ~7 ~134 nether_brick 0
setblock ~171 ~7 ~128 stained_hardened_clay 8
setblock ~171 ~7 ~139 red_nether_brick 0
fill ~172 ~7 ~128 ~172 ~8 ~128 mycelium 0
setblock ~172 ~7 ~131 stained_hardened_clay 15
setblock ~172 ~7 ~134 stained_hardened_clay 15
setblock ~172 ~7 ~135 nether_brick 0
setblock ~173 ~7 ~129 black_glazed_terracotta 0
fill ~173 ~7 ~131 ~173 ~8 ~131 red_nether_brick 0
fill ~173 ~7 ~139 ~176 ~7 ~139 red_nether_brick 0
setblock ~174 ~7 ~127 netherrack 0
fill ~174 ~7 ~129 ~175 ~7 ~129 stained_hardened_clay 15
setblock ~174 ~7 ~133 nether_brick 0
setblock ~175 ~7 ~126 gold_ore 0
setblock ~175 ~7 ~133 black_glazed_terracotta 0
setblock ~176 ~7 ~124 soul_sand 0
fill ~176 ~7 ~125 ~176 ~7 ~126 red_nether_brick 0
setblock ~176 ~7 ~132 coal_block 0
fill ~176 ~7 ~133 ~176 ~8 ~133 nether_brick 0
setblock ~177 ~7 ~124 gold_ore 0
fill ~177 ~7 ~127 ~178 ~7 ~127 red_nether_brick 0
setblock ~177 ~7 ~131 black_glazed_terracotta 0
setblock ~177 ~7 ~134 stained_hardened_clay 15
setblock ~178 ~7 ~124 netherrack 0
setblock ~178 ~7 ~131 stained_hardened_clay 12
setblock ~179 ~7 ~124 quartz_ore 0
setblock ~179 ~7 ~125 red_nether_brick 0
setblock ~179 ~7 ~130 netherrack 0
fill ~179 ~7 ~136 ~179 ~9 ~136 red_nether_brick 0
setblock ~180 ~7 ~129 black_glazed_terracotta 0
setblock ~180 ~7 ~130 stained_hardened_clay 15
setblock ~180 ~7 ~131 black_glazed_terracotta 0
setblock ~180 ~7 ~134 red_nether_brick 0
fill ~181 ~7 ~132 ~182 ~7 ~132 red_nether_brick 0
fill ~181 ~7 ~133 ~181 ~8 ~133 red_nether_brick 0
fill ~182 ~7 ~131 ~183 ~7 ~131 red_nether_brick 0
setblock ~183 ~7 ~129 netherrack 0
setblock ~183 ~7 ~130 red_nether_brick 0
setblock ~1 ~8 ~129 quartz_ore 0
setblock ~1 ~8 ~131 red_nether_brick 0
setblock ~2 ~8 ~128 red_nether_brick 0
fill ~2 ~8 ~132 ~2 ~9 ~132 red_nether_brick 0
fill ~3 ~8 ~128 ~4 ~8 ~128 quartz_ore 0
setblock ~4 ~8 ~130 black_glazed_terracotta 0
setblock ~4 ~8 ~131 stained_hardened_clay 15
setblock ~4 ~8 ~134 quartz_ore 0
fill ~4 ~8 ~135 ~4 ~9 ~135 black_glazed_terracotta 0
setblock ~5 ~8 ~129 red_nether_brick 0
setblock ~6 ~8 ~124 quartz_ore 0
fill ~6 ~8 ~125 ~7 ~8 ~125 netherrack 0
setblock ~6 ~8 ~126 black_glazed_terracotta 0
setblock ~6 ~8 ~130 black_glazed_terracotta 0
fill ~6 ~8 ~137 ~6 ~9 ~137 red_nether_brick 0
setblock ~7 ~8 ~124 netherrack 0
setblock ~7 ~8 ~126 red_nether_brick 0
setblock ~7 ~8 ~131 stained_hardened_clay 12
fill ~7 ~8 ~138 ~7 ~9 ~138 red_nether_brick 0
setblock ~8 ~8 ~126 quartz_ore 0
setblock ~8 ~8 ~127 red_nether_brick 0
setblock ~8 ~8 ~128 netherrack 0
setblock ~8 ~8 ~132 stained_hardened_clay 7
fill ~9 ~8 ~126 ~9 ~8 ~127 netherrack 0
setblock ~9 ~8 ~128 black_glazed_terracotta 0
setblock ~9 ~8 ~129 stained_hardened_clay 12
setblock ~9 ~8 ~139 nether_wart_block 0
setblock ~10 ~8 ~127 red_nether_brick 0
setblock ~10 ~8 ~128 netherrack 0
fill ~10 ~8 ~129 ~11 ~8 ~129 black_glazed_terracotta 0
fill ~10 ~8 ~133 ~11 ~8 ~133 red_nether_brick 0
fill ~10 ~8 ~139 ~10 ~18 ~139 red_nether_brick 0
setblock ~11 ~8 ~128 black_glazed_terracotta 0
fill ~11 ~8 ~130 ~11 ~8 ~131 red_nether_brick 0
setblock ~11 ~8 ~139 noteblock 0
setblock ~12 ~8 ~128 netherrack 0
fill ~12 ~8 ~134 ~13 ~8 ~134 black_glazed_terracotta 0
fill ~12 ~8 ~140 ~13 ~8 ~140 red_nether_brick 0
setblock ~13 ~8 ~128 noteblock 0
fill ~13 ~8 ~129 ~13 ~8 ~130 netherrack 0
setblock ~13 ~8 ~131 stained_hardened_clay 12
setblock ~14 ~8 ~129 red_nether_brick 0
setblock ~14 ~8 ~134 red_nether_brick 0
fill ~14 ~8 ~139 ~14 ~9 ~139 red_nether_brick 0
setblock ~15 ~8 ~130 red_nether_brick 0
setblock ~15 ~8 ~135 netherrack 0
setblock ~15 ~8 ~138 quartz_ore 0
setblock ~16 ~8 ~130 netherrack 0
setblock ~16 ~8 ~131 black_glazed_terracotta 0
fill ~16 ~8 ~135 ~16 ~10 ~135 black_glazed_terracotta 0
setblock ~16 ~8 ~136 quartz_ore 0
setblock ~16 ~8 ~137 black_glazed_terracotta 0
setblock ~17 ~8 ~130 red_nether_brick 0
setblock ~17 ~8 ~131 stained_hardened_clay 12
setblock ~19 ~8 ~131 netherrack 0
fill ~19 ~8 ~132 ~19 ~9 ~132 red_nether_brick 0
fill ~19 ~8 ~133 ~19 ~8 ~132 red_nether_brick 0
setblock ~20 ~8 ~130 netherrack 0
setblock ~20 ~8 ~134 quartz_ore 0
fill ~21 ~8 ~130 ~22 ~8 ~130 quartz_ore 0
fill ~21 ~8 ~134 ~21 ~11 ~134 red_nether_brick 0
setblock ~23 ~8 ~131 quartz_ore 0
setblock ~45 ~8 ~20 stained_hardened_clay 10
setblock ~45 ~8 ~21 brick_block 0
setblock ~45 ~8 ~23 stone 1
setblock ~45 ~8 ~24 log2 0
setblock ~45 ~8 ~25 stained_hardened_clay 8
setblock ~46 ~8 ~19 quartz_ore 0
setblock ~46 ~8 ~27 quartz_ore 0
setblock ~47 ~8 ~17 brick_block 0
setblock ~47 ~8 ~18 stained_hardened_clay 10
fill ~47 ~8 ~28 ~48 ~8 ~28 stained_hardened_clay 10
setblock ~49 ~8 ~17 log2 0
setblock ~49 ~8 ~29 log2 0
setblock ~50 ~8 ~16 mycelium 0
setblock ~50 ~8 ~29 noteblock 0
fill ~51 ~8 ~16 ~51 ~10 ~16 quartz_ore 0
setblock ~51 ~8 ~29 stained_hardened_clay 10
setblock ~52 ~8 ~16 stained_hardened_clay 10
setblock ~52 ~8 ~29 noteblock 0
setblock ~53 ~8 ~17 mycelium 0
setblock ~53 ~8 ~29 stained_hardened_clay 10
setblock ~54 ~8 ~17 soul_sand 0
setblock ~54 ~8 ~28 stained_hardened_clay 10
fill ~55 ~8 ~18 ~55 ~9 ~18 quartz_ore 0
fill ~56 ~8 ~19 ~56 ~9 ~19 quartz_ore 0
setblock ~57 ~8 ~20 quartz_ore 0
setblock ~57 ~8 ~25 log2 0
fill ~57 ~8 ~26 ~57 ~10 ~26 quartz_ore 0
fill ~58 ~8 ~21 ~58 ~9 ~21 quartz_ore 0
setblock ~58 ~8 ~22 stained_hardened_clay 10
setblock ~58 ~8 ~24 stained_hardened_clay 10
fill ~126 ~8 ~21 ~126 ~9 ~21 quartz_ore 0
setblock ~126 ~8 ~22 stained_hardened_clay 10
setblock ~126 ~8 ~24 stained_hardened_clay 10
setblock ~127 ~8 ~20 quartz_ore 0
setblock ~127 ~8 ~25 log2 0
fill ~127 ~8 ~26 ~127 ~10 ~26 quartz_ore 0
fill ~128 ~8 ~19 ~128 ~9 ~19 quartz_ore 0
fill ~129 ~8 ~18 ~129 ~9 ~18 quartz_ore 0
fill ~130 ~8 ~17 ~130 ~9 ~17 quartz_ore 0
setblock ~130 ~8 ~28 stained_hardened_clay 10
setblock ~131 ~8 ~17 mycelium 0
setblock ~131 ~8 ~29 stained_hardened_clay 10
setblock ~132 ~8 ~16 stained_hardened_clay 10
setblock ~132 ~8 ~29 noteblock 0
fill ~133 ~8 ~16 ~133 ~10 ~16 quartz_ore 0
setblock ~133 ~8 ~29 stained_hardened_clay 10
setblock ~134 ~8 ~16 mycelium 0
setblock ~134 ~8 ~29 noteblock 0
setblock ~135 ~8 ~17 log2 0
setblock ~135 ~8 ~29 mycelium 0
fill ~136 ~8 ~28 ~137 ~8 ~28 stained_hardened_clay 10
setblock ~137 ~8 ~17 brick_block 0
setblock ~137 ~8 ~18 stained_hardened_clay 10
setblock ~138 ~8 ~19 quartz_ore 0
fill ~138 ~8 ~27 ~138 ~9 ~27 quartz_ore 0
setblock ~139 ~8 ~20 stained_hardened_clay 10
setblock ~139 ~8 ~21 brick_block 0
setblock ~139 ~8 ~22 log2 0
setblock ~139 ~8 ~23 stained_hardened_clay 2
setblock ~139 ~8 ~24 log2 0
setblock ~139 ~8 ~25 stone 1
setblock ~139 ~8 ~26 stained_hardened_clay 10
setblock ~161 ~8 ~131 dirt 0
setblock ~161 ~8 ~132 quartz_ore 0
fill ~162 ~8 ~130 ~164 ~8 ~130 quartz_ore 0
fill ~162 ~8 ~133 ~162 ~7 ~133 netherrack 0
setblock ~163 ~8 ~134 black_glazed_terracotta 0
fill ~164 ~8 ~134 ~164 ~9 ~134 red_nether_brick 0
fill ~165 ~8 ~133 ~165 ~9 ~133 black_glazed_terracotta 0
setblock ~167 ~8 ~130 black_glazed_terracotta 0
setblock ~168 ~8 ~129 bedrock 0
setblock ~168 ~8 ~130 netherrack 0
setblock ~168 ~8 ~131 red_nether_brick 0
fill ~168 ~8 ~135 ~168 ~9 ~135 black_glazed_terracotta 0
setblock ~168 ~8 ~136 netherrack 0
setblock ~169 ~8 ~130 red_nether_brick 0
setblock ~170 ~8 ~134 soul_sand 0
setblock ~171 ~8 ~128 brown_glazed_terracotta 0
fill ~171 ~8 ~129 ~171 ~8 ~131 red_nether_brick 0
fill ~171 ~8 ~134 ~172 ~8 ~134 black_glazed_terracotta 0
fill ~171 ~8 ~140 ~172 ~8 ~140 red_nether_brick 0
setblock ~172 ~8 ~131 concrete 15
setblock ~173 ~8 ~128 netherrack 0
fill ~173 ~8 ~129 ~173 ~8 ~131 red_nether_brick 0
setblock ~173 ~8 ~133 stained_hardened_clay 12
fill ~173 ~8 ~139 ~174 ~8 ~139 red_nether_brick 0
setblock ~174 ~8 ~127 red_nether_brick 0
setblock ~174 ~8 ~129 coal_block 0
setblock ~174 ~8 ~133 black_glazed_terracotta 0
fill ~175 ~8 ~126 ~176 ~8 ~126 quartz_ore 0
setblock ~175 ~8 ~127 stained_hardened_clay 12
fill ~175 ~8 ~128 ~175 ~8 ~129 red_nether_brick 0
setblock ~175 ~8 ~133 stained_hardened_clay 7
setblock ~175 ~8 ~139 nether_wart_block 0
setblock ~176 ~8 ~127 black_glazed_terracotta 0
setblock ~176 ~8 ~132 stained_hardened_clay 12
fill ~176 ~8 ~139 ~176 ~19 ~139 red_nether_brick 0
setblock ~177 ~8 ~124 quartz_ore 0
setblock ~177 ~8 ~125 dirt 0
setblock ~177 ~8 ~126 red_nether_brick 0
setblock ~177 ~8 ~131 stained_hardened_clay 12
setblock ~178 ~8 ~124 stained_hardened_clay 6
setblock ~178 ~8 ~125 red_nether_brick 0
setblock ~178 ~8 ~126 quartz_ore 0
fill ~178 ~8 ~130 ~179 ~8 ~130 stained_hardened_clay 12
setblock ~179 ~8 ~129 black_glazed_terracotta 0
fill ~180 ~8 ~128 ~182 ~8 ~128 quartz_ore 0
setblock ~180 ~8 ~130 black_glazed_terracotta 0
setblock ~180 ~8 ~131 stained_hardened_clay 15
setblock ~180 ~8 ~134 netherrack 0
setblock ~182 ~8 ~132 netherrack 0
setblock ~183 ~8 ~129 quartz_ore 0
setblock ~183 ~8 ~130 netherrack 0
setblock ~183 ~8 ~131 noteblock 0
setblock ~1 ~9 ~129 netherrack 0
fill ~1 ~9 ~130 ~1 ~12 ~130 red_nether_brick 0
setblock ~1 ~9 ~131 netherrack 0
fill ~2 ~9 ~128 ~3 ~9 ~128 netherrack 0
setblock ~3 ~9 ~133 netherrack 0
setblock ~3 ~9 ~134 black_glazed_terracotta 0
setblock ~4 ~9 ~129 stained_hardened_clay 12
setblock ~4 ~9 ~130 stained_hardened_clay 15
setblock ~4 ~9 ~136 black_glazed_terracotta 0
setblock ~5 ~9 ~129 noteblock 0
setblock ~6 ~9 ~130 nether_brick 0
setblock ~7 ~9 ~131 black_glazed_terracotta 0
fill ~8 ~9 ~132 ~9 ~9 ~132 nether_brick 0
fill ~8 ~9 ~139 ~11 ~9 ~139 red_nether_brick 0
fill ~10 ~9 ~133 ~12 ~9 ~133 red_nether_brick 0
setblock ~12 ~9 ~129 netherrack 0
setblock ~12 ~9 ~130 red_nether_brick 0
fill ~12 ~9 ~140 ~13 ~9 ~140 black_glazed_terracotta 0
fill ~13 ~9 ~133 ~14 ~9 ~133 black_glazed_terracotta 0
fill ~14 ~9 ~134 ~15 ~9 ~134 black_glazed_terracotta 0
fill ~15 ~9 ~138 ~15 ~9 ~139 noteblock 0
setblock ~16 ~9 ~136 stained_hardened_clay 12
setblock ~16 ~9 ~137 noteblock 0
setblock ~19 ~9 ~131 black_glazed_terracotta 0
setblock ~19 ~9 ~133 stained_hardened_clay 12
setblock ~19 ~9 ~134 red_nether_brick 0
setblock ~20 ~9 ~130 black_glazed_terracotta 0
fill ~20 ~9 ~134 ~20 ~10 ~134 netherrack 0
fill ~21 ~9 ~130 ~21 ~8 ~130 quartz_ore 0
setblock ~22 ~9 ~130 netherrack 0
setblock ~22 ~9 ~133 noteblock 0
setblock ~23 ~9 ~131 netherrack 0
setblock ~45 ~9 ~23 brick_block 0
fill ~45 ~9 ~24 ~45 ~9 ~25 stained_hardened_clay 10
setblock ~46 ~9 ~19 stained_hardened_clay 10
setblock ~46 ~9 ~20 quartz_ore 0
setblock ~46 ~9 ~21 stained_hardened_clay 10
setblock ~46 ~9 ~26 quartz_ore 0
setblock ~46 ~9 ~27 stained_hardened_clay 10
setblock ~47 ~9 ~18 quartz_ore 0
setblock ~47 ~9 ~28 quartz_ore 0
setblock ~48 ~9 ~28 noteblock 0
setblock ~49 ~9 ~17 stained_hardened_clay 10
fill ~49 ~9 ~28 ~49 ~11 ~28 quartz_ore 0
setblock ~50 ~9 ~16 quartz_ore 0
fill ~50 ~9 ~29 ~52 ~9 ~29 quartz_ore 0
setblock ~52 ~9 ~16 noteblock 0
fill ~53 ~9 ~16 ~53 ~11 ~16 quartz_ore 0
fill ~53 ~9 ~28 ~54 ~9 ~28 noteblock 0
setblock ~54 ~9 ~17 quartz_ore 0
fill ~55 ~9 ~28 ~55 ~16 ~28 quartz_ore 0
setblock ~57 ~9 ~19 stained_hardened_clay 10
setblock ~57 ~9 ~25 quartz_ore 0
setblock ~58 ~9 ~20 noteblock 0
setblock ~58 ~9 ~22 noteblock 0
setblock ~58 ~9 ~24 noteblock 0
setblock ~126 ~9 ~20 noteblock 0
setblock ~126 ~9 ~22 noteblock 0
setblock ~126 ~9 ~24 noteblock 0
setblock ~127 ~9 ~19 stained_hardened_clay 10
setblock ~127 ~9 ~25 quartz_ore 0
fill ~129 ~9 ~28 ~129 ~16 ~28 quartz_ore 0
setblock ~130 ~9 ~28 noteblock 0
fill ~131 ~9 ~16 ~131 ~11 ~16 quartz_ore 0
fill ~131 ~9 ~28 ~131 ~13 ~28 quartz_ore 0
setblock ~132 ~9 ~16 noteblock 0
setblock ~132 ~9 ~29 soul_sand 0
fill ~133 ~9 ~29 ~134 ~9 ~29 quartz_ore 0
setblock ~134 ~9 ~16 quartz_ore 0
setblock ~135 ~9 ~17 stained_hardened_clay 10
fill ~135 ~9 ~28 ~135 ~11 ~28 quartz_ore 0
setblock ~136 ~9 ~28 noteblock 0
setblock ~137 ~9 ~18 quartz_ore 0
setblock ~137 ~9 ~28 quartz_ore 0
setblock ~138 ~9 ~19 stained_hardened_clay 10
setblock ~138 ~9 ~20 quartz_ore 0
setblock ~138 ~9 ~21 stained_hardened_clay 10
setblock ~138 ~9 ~26 quartz_ore 0
setblock ~139 ~9 ~22 stained_hardened_clay 10
setblock ~139 ~9 ~23 brick_block 0
setblock ~139 ~9 ~24 quartz_ore 0
setblock ~139 ~9 ~25 log2 0
setblock ~161 ~9 ~131 quartz_ore 0
setblock ~161 ~9 ~132 netherrack 0
setblock ~162 ~9 ~130 netherrack 0
setblock ~162 ~9 ~133 quartz_ore 0
fill ~163 ~9 ~130 ~163 ~11 ~130 quartz_ore 0
fill ~163 ~9 ~134 ~163 ~10 ~134 netherrack 0
setblock ~164 ~9 ~130 netherrack 0
setblock ~165 ~9 ~131 noteblock 0
setblock ~165 ~9 ~132 black_glazed_terracotta 0
setblock ~165 ~9 ~134 red_nether_brick 0
fill ~168 ~9 ~136 ~168 ~11 ~136 red_nether_brick 0
setblock ~169 ~9 ~134 black_glazed_terracotta 0
setblock ~169 ~9 ~139 red_nether_brick 0
setblock ~170 ~9 ~133 black_glazed_terracotta 0
setblock ~170 ~9 ~134 stained_hardened_clay 15
setblock ~171 ~9 ~133 stained_hardened_clay 12
fill ~171 ~9 ~140 ~172 ~9 ~140 red_nether_brick 0
setblock ~172 ~9 ~129 netherrack 0
setblock ~172 ~9 ~130 red_nether_brick 0
setblock ~172 ~9 ~133 nether_brick 0
setblock ~173 ~9 ~133 stained_hardened_clay 7
fill ~173 ~9 ~139 ~176 ~9 ~139 red_nether_brick 0
setblock ~174 ~9 ~133 nether_brick 0
setblock ~175 ~9 ~132 black_glazed_terracotta 0
setblock ~176 ~9 ~132 nether_brick 0
setblock ~177 ~9 ~131 black_glazed_terracotta 0
setblock ~178 ~9 ~130 nether_brick 0
setblock ~179 ~9 ~129 stained_hardened_clay 12
setblock ~179 ~9 ~130 black_glazed_terracotta 0
fill ~180 ~9 ~129 ~180 ~10 ~129 netherrack 0
setblock ~180 ~9 ~130 stained_hardened_clay 15
fill ~180 ~9 ~136 ~180 ~13 ~136 red_nether_brick 0
setblock ~181 ~9 ~128 noteblock 0
setblock ~181 ~9 ~133 black_glazed_terracotta 0
fill ~181 ~9 ~134 ~181 ~12 ~134 red_nether_brick 0
setblock ~182 ~9 ~132 red_nether_brick 0
fill ~183 ~9 ~129 ~183 ~9 ~131 red_nether_brick 0
setblock ~1 ~10 ~129 nether_wart_block 0
fill ~1 ~10 ~131 ~1 ~11 ~131 quartz_ore 0
setblock ~2 ~10 ~128 brick_block 0
setblock ~2 ~10 ~132 quartz_ore 0
setblock ~2 ~10 ~133 red_nether_brick 0
setblock ~3 ~10 ~128 quartz_ore 0
setblock ~3 ~10 ~134 soul_sand 0
setblock ~3 ~10 ~135 netherrack 0
setblock ~4 ~10 ~129 black_glazed_terracotta 0
setblock ~4 ~10 ~136 noteblock 0
setblock ~5 ~10 ~129 quartz_ore 0
fill ~5 ~10 ~137 ~5 ~11 ~137 noteblock 0
setblock ~6 ~10 ~130 black_glazed_terracotta 0
setblock ~6 ~10 ~138 soul_sand 0
setblock ~7 ~10 ~130 stained_hardened_clay 7
setblock ~7 ~10 ~138 netherrack 0
fill ~8 ~10 ~131 ~8 ~11 ~131 red_nether_brick 0
setblock ~8 ~10 ~139 netherrack 0
fill ~9 ~10 ~132 ~11 ~10 ~132 black_glazed_terracotta 0
setblock ~9 ~10 ~139 nether_wart_block 0
setblock ~11 ~10 ~139 stained_hardened_clay 12
fill ~12 ~10 ~132 ~13 ~10 ~132 stained_hardened_clay 12
setblock ~12 ~10 ~140 netherrack 0
setblock ~13 ~10 ~139 netherrack 0
setblock ~14 ~10 ~132 netherrack 0
setblock ~14 ~10 ~139 black_glazed_terracotta 0
setblock ~15 ~10 ~132 stained_hardened_clay 12
setblock ~15 ~10 ~133 soul_sand 0
setblock ~15 ~10 ~138 stained_hardened_clay 12
setblock ~16 ~10 ~133 black_glazed_terracotta 0
setblock ~16 ~10 ~134 stained_hardened_clay 12
setblock ~16 ~10 ~136 soul_sand 0
setblock ~16 ~10 ~137 black_glazed_terracotta 0
setblock ~16 ~10 ~138 quartz_ore 0
setblock ~18 ~10 ~130 noteblock 0
setblock ~18 ~10 ~131 red_nether_brick 0
setblock ~18 ~10 ~132 noteblock 0
setblock ~18 ~10 ~133 black_glazed_terracotta 0
setblock ~18 ~10 ~134 netherrack 0
setblock ~19 ~10 ~130 netherrack 0
setblock ~19 ~10 ~134 black_glazed_terracotta 0
setblock ~20 ~10 ~130 quartz_ore 0
setblock ~21 ~10 ~130 noteblock 0
fill ~22 ~10 ~131 ~22 ~11 ~131 black_glazed_terracotta 0
fill ~22 ~10 ~132 ~22 ~10 ~133 netherrack 0
setblock ~45 ~10 ~23 stone 1
setblock ~46 ~10 ~19 quartz_ore 0
setblock ~46 ~10 ~20 brick_block 0
setblock ~46 ~10 ~21 quartz_ore 0
setblock ~46 ~10 ~22 brick_block 0
setblock ~46 ~10 ~24 brick_block 0
setblock ~46 ~10 ~25 quartz_ore 0
setblock ~46 ~10 ~26 log2 0
setblock ~47 ~10 ~18 mycelium 0
setblock ~47 ~10 ~27 log2 0
setblock ~48 ~10 ~28 stained_hardened_clay 10
setblock ~49 ~10 ~17 brick_block 0
setblock ~50 ~10 ~16 log2 0
setblock ~50 ~10 ~28 stained_hardened_clay 10
fill ~51 ~10 ~28 ~53 ~10 ~28 quartz_ore 0
setblock ~52 ~10 ~16 stained_hardened_clay 10
setblock ~54 ~10 ~16 mycelium 0
setblock ~54 ~10 ~28 stained_hardened_clay 10
setblock ~55 ~10 ~17 mycelium 0
setblock ~56 ~10 ~18 mycelium 0
setblock ~56 ~10 ~27 noteblock 0
setblock ~57 ~10 ~19 log2 0
fill ~57 ~10 ~27 ~57 ~11 ~27 stained_hardened_clay 10
setblock ~58 ~10 ~20 mycelium 0
setblock ~58 ~10 ~23 soul_sand 0
setblock ~58 ~10 ~24 mycelium 0
setblock ~58 ~10 ~25 noteblock 0
setblock ~59 ~10 ~21 log2 0
fill ~59 ~10 ~22 ~59 ~11 ~22 quartz_ore 0
setblock ~125 ~10 ~21 log2 0
fill ~125 ~10 ~22 ~125 ~11 ~22 quartz_ore 0
setblock ~126 ~10 ~20 mycelium 0
setblock ~126 ~10 ~23 soul_sand 0
setblock ~126 ~10 ~24 stained_hardened_clay 10
fill ~126 ~10 ~25 ~126 ~11 ~25 quartz_ore 0
setblock ~127 ~10 ~19 log2 0
setblock ~127 ~10 ~27 mycelium 0
setblock ~128 ~10 ~18 mycelium 0
setblock ~128 ~10 ~27 noteblock 0
setblock ~129 ~10 ~17 mycelium 0
setblock ~130 ~10 ~16 mycelium 0
setblock ~130 ~10 ~28 stained_hardened_clay 10
setblock ~132 ~10 ~16 stained_hardened_clay 10
fill ~132 ~10 ~28 ~133 ~10 ~28 quartz_ore 0
setblock ~134 ~10 ~16 log2 0
setblock ~134 ~10 ~28 stained_hardened_clay 10
setblock ~135 ~10 ~17 brick_block 0
setblock ~136 ~10 ~28 stained_hardened_clay 10
setblock ~137 ~10 ~18 stained_hardened_clay 10
setblock ~137 ~10 ~27 log2 0
setblock ~138 ~10 ~19 quartz_ore 0
setblock ~138 ~10 ~20 brick_block 0
setblock ~138 ~10 ~21 quartz_ore 0
setblock ~138 ~10 ~22 brick_block 0
setblock ~138 ~10 ~24 brick_block 0
setblock ~138 ~10 ~25 quartz_ore 0
setblock ~138 ~10 ~26 log2 0
setblock ~139 ~10 ~23 stone 1
setblock ~162 ~10 ~131 black_glazed_terracotta 0
setblock ~162 ~10 ~132 quartz_ore 0
fill ~162 ~10 ~133 ~162 ~11 ~133 netherrack 0
fill ~164 ~10 ~130 ~165 ~10 ~130 quartz_ore 0
setblock ~164 ~10 ~134 netherrack 0
setblock ~165 ~10 ~134 black_glazed_terracotta 0
setblock ~166 ~10 ~130 stained_hardened_clay 10
setblock ~166 ~10 ~131 stained_hardened_clay 12
setblock ~166 ~10 ~132 netherrack 0
fill ~166 ~10 ~133 ~166 ~10 ~134 red_nether_brick 0
fill ~168 ~10 ~133 ~168 ~10 ~134 black_glazed_terracotta 0
setblock ~168 ~10 ~135 red_nether_brick 0
fill ~168 ~10 ~138 ~168 ~13 ~138 red_nether_brick 0
setblock ~169 ~10 ~132 stained_hardened_clay 12
setblock ~169 ~10 ~133 soul_sand 0
setblock ~170 ~10 ~132 soul_sand 0
setblock ~171 ~10 ~132 stained_hardened_clay 7
setblock ~171 ~10 ~139 nether_wart_block 0
setblock ~172 ~10 ~132 stained_hardened_clay 12
fill ~172 ~10 ~140 ~172 ~11 ~140 red_nether_brick 0
setblock ~173 ~10 ~132 black_glazed_terracotta 0
setblock ~173 ~10 ~139 nether_wart_block 0
setblock ~174 ~10 ~132 stained_hardened_clay 7
fill ~174 ~10 ~139 ~174 ~18 ~139 red_nether_brick 0
setblock ~175 ~10 ~132 stained_hardened_clay 12
setblock ~175 ~10 ~139 nether_wart_block 0
setblock ~176 ~10 ~131 nether_brick 0
fill ~177 ~10 ~130 ~177 ~11 ~130 stained_hardened_clay 12
setblock ~178 ~10 ~130 soul_sand 0
setblock ~178 ~10 ~138 nether_wart_block 0
fill ~179 ~10 ~129 ~179 ~11 ~129 soul_sand 0
setblock ~179 ~10 ~137 nether_wart_block 0
fill ~181 ~10 ~128 ~181 ~11 ~128 stained_hardened_clay 12
setblock ~181 ~10 ~135 nether_wart_block 0
setblock ~182 ~10 ~132 netherrack 0
setblock ~182 ~10 ~133 red_nether_brick 0
setblock ~183 ~10 ~129 nether_wart_block 0
setblock ~183 ~10 ~130 noteblock 0
setblock ~183 ~10 ~131 nether_wart_block 0
setblock ~1 ~11 ~129 red_nether_brick 0
fill ~2 ~11 ~128 ~4 ~11 ~128 noteblock 0
setblock ~2 ~11 ~132 red_nether_brick 0
setblock ~2 ~11 ~133 black_glazed_terracotta 0
fill ~3 ~11 ~134 ~3 ~12 ~134 red_nether_brick 0
setblock ~3 ~11 ~135 quartz_ore 0
setblock ~4 ~11 ~136 black_glazed_terracotta 0
setblock ~5 ~11 ~129 netherrack 0
fill ~6 ~11 ~130 ~7 ~11 ~130 red_nether_brick 0
setblock ~6 ~11 ~138 black_glazed_terracotta 0
fill ~7 ~11 ~138 ~7 ~14 ~138 red_nether_brick 0
fill ~8 ~11 ~139 ~10 ~11 ~139 red_nether_brick 0
setblock ~9 ~11 ~131 red_nether_brick 0
setblock ~10 ~11 ~131 stained_hardened_clay 7
setblock ~11 ~11 ~131 stained_hardened_clay 12
fill ~11 ~11 ~140 ~12 ~11 ~140 red_nether_brick 0
setblock ~12 ~11 ~131 black_glazed_terracotta 0
setblock ~13 ~11 ~131 soul_sand 0
setblock ~13 ~11 ~139 soul_sand 0
setblock ~14 ~11 ~131 black_glazed_terracotta 0
setblock ~14 ~11 ~139 red_nether_brick 0
setblock ~15 ~11 ~131 stained_hardened_clay 12
setblock ~15 ~11 ~138 noteblock 0
fill ~16 ~11 ~131 ~17 ~11 ~131 black_glazed_terracotta 0
fill ~16 ~11 ~132 ~17 ~11 ~132 black_glazed_terracotta 0
fill ~16 ~11 ~136 ~17 ~11 ~136 black_glazed_terracotta 0
setblock ~16 ~11 ~137 stained_hardened_clay 12
setblock ~16 ~11 ~138 black_glazed_terracotta 0
setblock ~17 ~11 ~130 black_glazed_terracotta 0
fill ~17 ~11 ~133 ~17 ~11 ~134 black_glazed_terracotta 0
setblock ~17 ~11 ~135 netherrack 0
setblock ~18 ~11 ~130 red_nether_brick 0
setblock ~18 ~11 ~135 red_nether_brick 0
setblock ~19 ~11 ~130 noteblock 0
setblock ~19 ~11 ~135 netherrack 0
fill ~20 ~11 ~130 ~21 ~11 ~130 netherrack 0
setblock ~20 ~11 ~134 black_glazed_terracotta 0
setblock ~22 ~11 ~132 black_glazed_terracotta 0
setblock ~22 ~11 ~133 netherrack 0
setblock ~46 ~11 ~19 stained_hardened_clay 10
setblock ~46 ~11 ~20 quartz_ore 0
fill ~46 ~11 ~21 ~46 ~12 ~21 stained_hardened_clay 10
setblock ~46 ~11 ~22 quartz_ore 0
setblock ~46 ~11 ~23 stained_hardened_clay 10
setblock ~46 ~11 ~24 quartz_ore 0
setblock ~46 ~11 ~25 stained_hardened_clay 10
setblock ~47 ~11 ~18 quartz_ore 0
setblock ~47 ~11 ~26 quartz_ore 0
setblock ~48 ~11 ~17 stained_hardened_clay 10
fill ~48 ~11 ~27 ~48 ~12 ~27 quartz_ore 0
setblock ~49 ~11 ~17 mycelium 0
setblock ~50 ~11 ~16 quartz_ore 0
setblock ~50 ~11 ~28 noteblock 0
setblock ~51 ~11 ~15 stained_hardened_clay 10
fill ~51 ~11 ~28 ~51 ~12 ~28 quartz_ore 0
fill ~52 ~11 ~15 ~52 ~13 ~15 quartz_ore 0
setblock ~52 ~11 ~28 noteblock 0
fill ~53 ~11 ~28 ~53 ~13 ~28 quartz_ore 0
setblock ~54 ~11 ~16 noteblock 0
setblock ~54 ~11 ~28 noteblock 0
fill ~55 ~11 ~16 ~55 ~12 ~16 quartz_ore 0
setblock ~56 ~11 ~17 quartz_ore 0
setblock ~56 ~11 ~27 quartz_ore 0
setblock ~57 ~11 ~18 quartz_ore 0
fill ~58 ~11 ~19 ~59 ~11 ~19 quartz_ore 0
fill ~58 ~11 ~24 ~58 ~11 ~26 quartz_ore 0
setblock ~59 ~11 ~20 quartz_ore 0
setblock ~59 ~11 ~21 stained_hardened_clay 10
setblock ~59 ~11 ~23 stained_hardened_clay 10
fill ~125 ~11 ~19 ~126 ~11 ~19 quartz_ore 0
fill ~125 ~11 ~20 ~125 ~11 ~19 quartz_ore 0
setblock ~125 ~11 ~21 stained_hardened_clay 10
setblock ~125 ~11 ~23 quartz_ore 0
setblock ~126 ~11 ~24 noteblock 0
setblock ~126 ~11 ~26 quartz_ore 0
setblock ~127 ~11 ~18 quartz_ore 0
setblock ~127 ~11 ~27 stained_hardened_clay 10
setblock ~128 ~11 ~17 quartz_ore 0
setblock ~128 ~11 ~27 quartz_ore 0
fill ~129 ~11 ~16 ~129 ~12 ~16 quartz_ore 0
setblock ~130 ~11 ~16 noteblock 0
setblock ~130 ~11 ~28 noteblock 0
fill ~132 ~11 ~15 ~132 ~13 ~15 quartz_ore 0
setblock ~132 ~11 ~28 noteblock 0
setblock ~133 ~11 ~15 stained_hardened_clay 10
fill ~133 ~11 ~28 ~133 ~12 ~28 quartz_ore 0
setblock ~134 ~11 ~16 quartz_ore 0
setblock ~134 ~11 ~28 noteblock 0
setblock ~135 ~11 ~17 mycelium 0
setblock ~136 ~11 ~17 stained_hardened_clay 10
fill ~136 ~11 ~27 ~136 ~12 ~27 quartz_ore 0
setblock ~137 ~11 ~18 quartz_ore 0
setblock ~137 ~11 ~26 quartz_ore 0
setblock ~138 ~11 ~19 stained_hardened_clay 10
setblock ~138 ~11 ~20 quartz_ore 0
setblock ~138 ~11 ~21 stained_hardened_clay 10
setblock ~138 ~11 ~22 quartz_ore 0
setblock ~138 ~11 ~23 stained_hardened_clay 10
setblock ~138 ~11 ~24 quartz_ore 0
setblock ~138 ~11 ~25 stained_hardened_clay 10
fill ~162 ~11 ~131 ~162 ~11 ~133 netherrack 0
setblock ~163 ~11 ~134 quartz_ore 0
fill ~164 ~11 ~130 ~165 ~11 ~130 quartz_ore 0
setblock ~164 ~11 ~134 red_nether_brick 0
setblock ~165 ~11 ~135 netherrack 0
setblock ~166 ~11 ~130 black_glazed_terracotta 0
fill ~166 ~11 ~135 ~167 ~11 ~135 red_nether_brick 0
fill ~167 ~11 ~130 ~167 ~11 ~131 stained_hardened_clay 12
fill ~167 ~11 ~132 ~167 ~11 ~133 black_glazed_terracotta 0
setblock ~167 ~11 ~134 red_nether_brick 0
fill ~167 ~11 ~136 ~167 ~13 ~136 red_nether_brick 0
