setblock ~42 ~0 ~32 planks 2
setblock ~40 ~1 ~30 sandstone
setblock ~40 ~1 ~31 planks 2
setblock ~41 ~1 ~31 end_stone
fill ~41 ~1 ~32 ~43 ~1 ~32 sandstone
setblock ~41 ~1 ~33 end_stone
setblock ~42 ~1 ~33 planks 2
setblock ~43 ~1 ~33 end_stone
setblock ~44 ~1 ~33 planks 2
setblock ~39 ~2 ~29 sandstone
fill ~39 ~2 ~30 ~41 ~2 ~30 planks 2
setblock ~39 ~2 ~31 sandstone
fill ~39 ~2 ~32 ~40 ~2 ~32 planks 2
setblock ~40 ~2 ~33 sandstone
fill ~41 ~2 ~34 ~43 ~2 ~34 planks 2
setblock ~42 ~2 ~31 sandstone
fill ~43 ~2 ~32 ~44 ~2 ~32 planks 2
setblock ~44 ~2 ~33 sandstone
fill ~38 ~3 ~28 ~39 ~3 ~28 sandstone
setblock ~38 ~3 ~29 planks 2
setblock ~38 ~3 ~30 sandstone
setblock ~38 ~3 ~31 planks 2
setblock ~39 ~3 ~32 sandstone
setblock ~40 ~3 ~29 planks 2
setblock ~40 ~3 ~33 planks 2
fill ~41 ~3 ~30 ~42 ~3 ~30 sandstone
fill ~41 ~3 ~34 ~43 ~3 ~34 sandstone
setblock ~43 ~3 ~31 end_stone
fill ~44 ~3 ~32 ~45 ~3 ~32 sandstone
setblock ~44 ~3 ~33 planks 2
setblock ~45 ~3 ~33 end_stone
fill ~38 ~4 ~28 ~40 ~4 ~28 planks 2
setblock ~38 ~4 ~29 sandstone
setblock ~38 ~4 ~30 planks 2
setblock ~39 ~4 ~31 sandstone
fill ~39 ~4 ~32 ~40 ~4 ~32 planks 2
setblock ~41 ~4 ~29 sandstone
setblock ~41 ~4 ~33 sandstone
fill ~42 ~4 ~30 ~43 ~4 ~30 planks 2
fill ~42 ~4 ~34 ~44 ~4 ~34 planks 2
setblock ~44 ~4 ~31 planks 2
fill ~45 ~4 ~32 ~46 ~4 ~32 planks 2
setblock ~45 ~4 ~33 sandstone
setblock ~38 ~5 ~28 sandstone
setblock ~38 ~5 ~29 planks 2
setblock ~39 ~5 ~27 end_stone
setblock ~39 ~5 ~30 sandstone
setblock ~39 ~5 ~31 end_stone
fill ~40 ~5 ~28 ~41 ~5 ~28 sandstone
setblock ~40 ~5 ~32 sandstone
setblock ~41 ~5 ~33 end_stone
setblock ~42 ~5 ~29 planks 2
setblock ~42 ~5 ~34 end_stone
fill ~43 ~5 ~30 ~44 ~5 ~30 sandstone
fill ~43 ~5 ~34 ~44 ~5 ~34 sandstone
setblock ~45 ~5 ~31 end_stone
setblock ~45 ~5 ~33 end_stone
setblock ~46 ~5 ~32 sandstone
setblock ~46 ~5 ~33 planks 2
setblock ~38 ~6 ~27 sandstone
setblock ~38 ~6 ~28 planks 2
setblock ~38 ~6 ~29 sandstone
setblock ~39 ~6 ~26 planks 2
setblock ~39 ~6 ~30 planks 2
setblock ~39 ~6 ~31 sandstone
setblock ~40 ~6 ~27 sandstone
setblock ~40 ~6 ~32 planks 2
fill ~41 ~6 ~28 ~42 ~6 ~28 planks 2
setblock ~41 ~6 ~33 sandstone
fill ~42 ~6 ~34 ~45 ~6 ~34 planks 2
setblock ~43 ~6 ~29 sandstone
fill ~44 ~6 ~30 ~45 ~6 ~30 planks 2
setblock ~45 ~6 ~33 sandstone
setblock ~46 ~6 ~31 sandstone
fill ~46 ~6 ~32 ~47 ~6 ~32 planks 2
setblock ~38 ~7 ~28 sandstone
setblock ~39 ~7 ~26 sandstone
setblock ~39 ~7 ~27 end_stone
setblock ~39 ~7 ~29 end_stone
setblock ~39 ~7 ~30 sandstone
setblock ~39 ~7 ~31 end_stone
setblock ~40 ~7 ~27 planks 2
setblock ~40 ~7 ~32 sandstone
setblock ~41 ~7 ~27 end_stone
setblock ~41 ~7 ~33 end_stone
fill ~42 ~7 ~28 ~43 ~7 ~28 sandstone
fill ~42 ~7 ~34 ~45 ~7 ~34 sandstone
setblock ~44 ~7 ~29 planks 2
fill ~45 ~7 ~30 ~46 ~7 ~30 sandstone
setblock ~45 ~7 ~33 end_stone
fill ~46 ~7 ~32 ~47 ~7 ~32 sandstone
setblock ~47 ~7 ~31 end_stone
setblock ~38 ~8 ~28 planks 2
fill ~39 ~8 ~26 ~40 ~8 ~26 planks 2
setblock ~39 ~8 ~27 sandstone
setblock ~39 ~8 ~29 sandstone
setblock ~39 ~8 ~30 planks 2
setblock ~39 ~8 ~31 sandstone
setblock ~40 ~8 ~32 planks 2
fill ~41 ~8 ~27 ~42 ~8 ~27 sandstone
setblock ~41 ~8 ~33 sandstone
fill ~42 ~8 ~34 ~45 ~8 ~34 planks 2
setblock ~43 ~8 ~28 planks 2
fill ~44 ~8 ~29 ~45 ~8 ~29 sandstone
setblock ~46 ~8 ~30 planks 2
fill ~46 ~8 ~32 ~47 ~8 ~32 planks 2
setblock ~46 ~8 ~33 sandstone
setblock ~47 ~8 ~31 sandstone
fill ~39 ~9 ~26 ~41 ~9 ~26 sandstone
setblock ~39 ~9 ~27 end_stone
setblock ~39 ~9 ~28 sandstone
setblock ~39 ~9 ~29 end_stone
setblock ~39 ~9 ~30 sandstone
setblock ~39 ~9 ~31 end_stone
setblock ~40 ~9 ~32 sandstone
setblock ~41 ~9 ~33 end_stone
setblock ~42 ~9 ~27 planks 2
setblock ~42 ~9 ~34 end_stone
setblock ~43 ~9 ~27 end_stone
fill ~43 ~9 ~34 ~45 ~9 ~34 sandstone
setblock ~44 ~9 ~28 sandstone
setblock ~45 ~9 ~29 end_stone
setblock ~46 ~9 ~29 planks 2
setblock ~46 ~9 ~32 sandstone
setblock ~46 ~9 ~33 planks 2
setblock ~47 ~9 ~30 sandstone
setblock ~47 ~9 ~31 end_stone
setblock ~39 ~10 ~26 planks 2
setblock ~39 ~10 ~27 sandstone
setblock ~39 ~10 ~28 planks 2
setblock ~39 ~10 ~29 sandstone
setblock ~39 ~10 ~30 planks 2
setblock ~39 ~10 ~31 sandstone
setblock ~40 ~10 ~25 sandstone
setblock ~40 ~10 ~32 planks 2
fill ~41 ~10 ~26 ~42 ~10 ~26 planks 2
setblock ~41 ~10 ~33 sandstone
fill ~42 ~10 ~34 ~43 ~10 ~34 planks 2
setblock ~43 ~10 ~27 sandstone
fill ~44 ~10 ~28 ~45 ~10 ~28 planks 2
setblock ~44 ~10 ~35 sandstone
setblock ~45 ~10 ~33 sandstone
setblock ~45 ~10 ~34 planks 2
setblock ~46 ~10 ~29 sandstone
setblock ~46 ~10 ~32 planks 2
setblock ~47 ~10 ~30 planks 2
setblock ~47 ~10 ~31 sandstone
setblock ~39 ~11 ~27 end_stone
setblock ~39 ~11 ~28 sandstone
setblock ~39 ~11 ~29 end_stone
setblock ~39 ~11 ~30 sandstone
setblock ~39 ~11 ~31 end_stone
setblock ~39 ~11 ~32 sandstone
setblock ~40 ~11 ~25 planks 2
setblock ~40 ~11 ~26 sandstone
setblock ~40 ~11 ~33 planks 2
setblock ~41 ~11 ~25 end_stone
setblock ~41 ~11 ~34 sandstone
setblock ~42 ~11 ~26 sandstone
setblock ~42 ~11 ~35 planks 2
setblock ~43 ~11 ~27 end_stone
setblock ~43 ~11 ~35 end_stone
fill ~44 ~11 ~28 ~45 ~11 ~28 sandstone
fill ~44 ~11 ~35 ~44 ~13 ~35 planks 2
setblock ~45 ~11 ~33 end_stone
setblock ~45 ~11 ~34 sandstone
setblock ~46 ~11 ~29 planks 2
setblock ~46 ~11 ~32 sandstone
setblock ~47 ~11 ~30 sandstone
setblock ~47 ~11 ~31 end_stone
setblock ~39 ~12 ~27 sandstone
setblock ~39 ~12 ~28 planks 2
setblock ~39 ~12 ~29 sandstone
setblock ~39 ~12 ~30 planks 2
setblock ~39 ~12 ~31 sandstone
setblock ~39 ~12 ~32 planks 2
fill ~40 ~12 ~25 ~41 ~12 ~25 sandstone
setblock ~40 ~12 ~26 planks 2
setblock ~40 ~12 ~33 sandstone
setblock ~41 ~12 ~34 planks 2
setblock ~42 ~12 ~26 planks 2
fill ~42 ~12 ~35 ~43 ~12 ~35 sandstone
setblock ~43 ~12 ~27 sandstone
fill ~44 ~12 ~27 ~44 ~13 ~27 planks 2
setblock ~45 ~12 ~28 planks 2
setblock ~45 ~12 ~33 sandstone
setblock ~45 ~12 ~34 planks 2
setblock ~46 ~12 ~29 sandstone
setblock ~46 ~12 ~31 sandstone
setblock ~46 ~12 ~32 planks 2
setblock ~47 ~12 ~30 planks 2
setblock ~39 ~13 ~28 sandstone
setblock ~39 ~13 ~29 end_stone
setblock ~39 ~13 ~30 sandstone
setblock ~39 ~13 ~31 end_stone
setblock ~39 ~13 ~32 sandstone
setblock ~40 ~13 ~26 sandstone
setblock ~40 ~13 ~27 planks 2
setblock ~40 ~13 ~33 planks 2
setblock ~41 ~13 ~25 end_stone
setblock ~41 ~13 ~34 sandstone
setblock ~42 ~13 ~26 end_stone
setblock ~42 ~13 ~35 planks 2
setblock ~43 ~13 ~26 sandstone
setblock ~43 ~13 ~35 end_stone
setblock ~45 ~13 ~28 sandstone
setblock ~45 ~13 ~32 sandstone
setblock ~45 ~13 ~33 end_stone
setblock ~45 ~13 ~34 sandstone
setblock ~46 ~13 ~29 planks 2
setblock ~46 ~13 ~31 planks 2
setblock ~47 ~13 ~30 sandstone
setblock ~39 ~14 ~28 planks 2
setblock ~39 ~14 ~29 sandstone
setblock ~39 ~14 ~30 planks 2
setblock ~39 ~14 ~31 sandstone
setblock ~39 ~14 ~32 planks 2
setblock ~39 ~14 ~33 sandstone
setblock ~40 ~14 ~27 sandstone
setblock ~40 ~14 ~34 planks 2
fill ~41 ~14 ~25 ~42 ~14 ~25 sandstone
setblock ~41 ~14 ~26 planks 2
setblock ~41 ~14 ~35 sandstone
setblock ~42 ~14 ~36 planks 2
setblock ~43 ~14 ~26 planks 2
fill ~43 ~14 ~35 ~44 ~14 ~35 sandstone
setblock ~44 ~14 ~27 sandstone
fill ~45 ~14 ~28 ~46 ~14 ~28 planks 2
setblock ~45 ~14 ~32 planks 2
setblock ~45 ~14 ~33 sandstone
setblock ~45 ~14 ~34 planks 2
setblock ~46 ~14 ~31 sandstone
setblock ~47 ~14 ~29 sandstone
setblock ~47 ~14 ~30 planks 2
setblock ~39 ~15 ~29 end_stone
setblock ~39 ~15 ~30 sandstone
setblock ~39 ~15 ~31 end_stone
setblock ~39 ~15 ~32 sandstone
setblock ~39 ~15 ~33 end_stone
setblock ~40 ~15 ~27 planks 2
setblock ~40 ~15 ~28 sandstone
setblock ~40 ~15 ~34 sandstone
setblock ~41 ~15 ~26 sandstone
setblock ~41 ~15 ~35 end_stone
setblock ~42 ~15 ~24 sandstone
setblock ~42 ~15 ~25 planks 2
setblock ~42 ~15 ~36 sandstone
setblock ~43 ~15 ~25 end_stone
setblock ~43 ~15 ~35 end_stone
setblock ~44 ~15 ~26 sandstone
fill ~44 ~15 ~35 ~44 ~17 ~35 planks 2
setblock ~45 ~15 ~27 end_stone
setblock ~45 ~15 ~33 end_stone
setblock ~45 ~15 ~34 sandstone
setblock ~46 ~15 ~27 planks 2
setblock ~46 ~15 ~31 planks 2
setblock ~46 ~15 ~32 sandstone
setblock ~47 ~15 ~28 sandstone
setblock ~47 ~15 ~30 sandstone
setblock ~48 ~15 ~29 planks 2
setblock ~39 ~16 ~32 planks 2
setblock ~39 ~16 ~33 sandstone
setblock ~40 ~16 ~28 planks 2
setblock ~40 ~16 ~29 sandstone
fill ~40 ~16 ~30 ~40 ~16 ~31 planks 2
setblock ~40 ~16 ~34 planks 2
setblock ~41 ~16 ~26 planks 2
setblock ~41 ~16 ~27 sandstone
setblock ~41 ~16 ~35 sandstone
setblock ~42 ~16 ~25 sandstone
fill ~42 ~16 ~36 ~43 ~16 ~36 planks 2
setblock ~43 ~16 ~24 planks 2
fill ~44 ~16 ~25 ~45 ~16 ~25 sandstone
fill ~45 ~16 ~26 ~46 ~16 ~26 planks 2
setblock ~45 ~16 ~34 planks 2
setblock ~46 ~16 ~31 sandstone
setblock ~46 ~16 ~32 planks 2
setblock ~46 ~16 ~33 sandstone
setblock ~47 ~16 ~27 sandstone
setblock ~47 ~16 ~30 planks 2
fill ~48 ~16 ~27 ~48 ~16 ~28 planks 2
setblock ~48 ~16 ~29 sandstone
setblock ~39 ~17 ~33 end_stone
setblock ~40 ~17 ~29 planks 2
setblock ~40 ~17 ~30 sandstone
setblock ~40 ~17 ~31 planks 2
setblock ~40 ~17 ~32 sandstone
setblock ~40 ~17 ~34 sandstone
setblock ~41 ~17 ~27 end_stone
setblock ~41 ~17 ~28 sandstone
setblock ~41 ~17 ~35 end_stone
setblock ~42 ~17 ~26 end_stone
fill ~42 ~17 ~36 ~43 ~17 ~36 sandstone
setblock ~43 ~17 ~25 end_stone
setblock ~44 ~17 ~25 planks 2
setblock ~45 ~17 ~24 sandstone
setblock ~45 ~17 ~34 sandstone
setblock ~45 ~17 ~35 end_stone
setblock ~46 ~17 ~25 planks 2
setblock ~46 ~17 ~32 sandstone
setblock ~46 ~17 ~33 planks 2
setblock ~47 ~17 ~25 end_stone
fill ~47 ~17 ~26 ~48 ~17 ~26 sandstone
setblock ~47 ~17 ~29 end_stone
setblock ~47 ~17 ~30 sandstone
setblock ~47 ~17 ~31 end_stone
setblock ~48 ~17 ~28 sandstone
setblock ~49 ~17 ~27 end_stone
setblock ~40 ~18 ~30 planks 2
setblock ~40 ~18 ~31 sandstone
setblock ~40 ~18 ~32 planks 2
setblock ~40 ~18 ~33 sandstone
setblock ~40 ~18 ~34 planks 2
setblock ~41 ~18 ~29 sandstone
setblock ~41 ~18 ~35 sandstone
setblock ~42 ~18 ~27 sandstone
setblock ~42 ~18 ~28 planks 2
fill ~42 ~18 ~36 ~44 ~18 ~36 planks 2
setblock ~43 ~18 ~26 planks 2
fill ~44 ~18 ~25 ~46 ~18 ~25 sandstone
setblock ~45 ~18 ~34 planks 2
setblock ~45 ~18 ~35 sandstone
setblock ~46 ~18 ~32 planks 2
setblock ~46 ~18 ~33 sandstone
setblock ~47 ~18 ~26 planks 2
setblock ~47 ~18 ~29 sandstone
setblock ~47 ~18 ~30 planks 2
setblock ~47 ~18 ~31 sandstone
setblock ~48 ~18 ~27 sandstone
setblock ~48 ~18 ~28 planks 2
setblock ~40 ~19 ~30 sandstone
fill ~40 ~19 ~31 ~40 ~20 ~31 planks 2
setblock ~40 ~19 ~32 sandstone
setblock ~40 ~19 ~33 planks 2
setblock ~40 ~19 ~34 sandstone
setblock ~41 ~19 ~29 end_stone
setblock ~41 ~19 ~35 end_stone
fill ~42 ~19 ~28 ~43 ~19 ~28 sandstone
setblock ~42 ~19 ~29 planks 2
fill ~42 ~19 ~36 ~44 ~19 ~36 sandstone
setblock ~43 ~19 ~27 end_stone
fill ~44 ~19 ~26 ~46 ~19 ~26 sandstone
setblock ~45 ~19 ~34 sandstone
setblock ~45 ~19 ~35 end_stone
setblock ~46 ~19 ~27 planks 2
setblock ~46 ~19 ~33 planks 2
setblock ~47 ~19 ~27 end_stone
setblock ~47 ~19 ~29 end_stone
setblock ~47 ~19 ~30 sandstone
setblock ~47 ~19 ~31 end_stone
setblock ~47 ~19 ~32 sandstone
setblock ~48 ~19 ~28 sandstone
setblock ~40 ~20 ~32 planks 2
setblock ~40 ~20 ~33 sandstone
setblock ~40 ~20 ~34 planks 2
setblock ~41 ~20 ~30 planks 2
setblock ~41 ~20 ~35 sandstone
fill ~42 ~20 ~29 ~43 ~20 ~29 sandstone
fill ~42 ~20 ~36 ~45 ~20 ~36 planks 2
fill ~44 ~20 ~27 ~44 ~20 ~28 planks 2
setblock ~45 ~20 ~27 sandstone
setblock ~45 ~20 ~35 sandstone
fill ~46 ~20 ~28 ~47 ~20 ~28 planks 2
setblock ~46 ~20 ~33 sandstone
setblock ~46 ~20 ~34 planks 2
setblock ~47 ~20 ~29 sandstone
setblock ~47 ~20 ~30 planks 2
setblock ~47 ~20 ~31 sandstone
setblock ~47 ~20 ~32 planks 2
setblock ~40 ~21 ~32 sandstone
setblock ~40 ~21 ~33 planks 2
setblock ~40 ~21 ~34 sandstone
setblock ~41 ~21 ~31 end_stone
setblock ~41 ~21 ~35 end_stone
setblock ~42 ~21 ~30 end_stone
fill ~42 ~21 ~36 ~45 ~21 ~36 sandstone
setblock ~43 ~21 ~29 end_stone
setblock ~44 ~21 ~29 planks 2
fill ~45 ~21 ~28 ~46 ~21 ~28 sandstone
setblock ~45 ~21 ~35 end_stone
setblock ~46 ~21 ~33 planks 2
setblock ~46 ~21 ~34 end_stone
setblock ~47 ~21 ~29 end_stone
setblock ~47 ~21 ~30 sandstone
setblock ~47 ~21 ~31 end_stone
setblock ~47 ~21 ~32 sandstone
setblock ~40 ~22 ~32 planks 2
setblock ~40 ~22 ~33 sandstone
setblock ~40 ~22 ~34 planks 2
setblock ~41 ~22 ~31 sandstone
setblock ~41 ~22 ~35 sandstone
setblock ~42 ~22 ~30 planks 2
fill ~42 ~22 ~36 ~45 ~22 ~36 planks 2
fill ~43 ~22 ~29 ~46 ~22 ~29 sandstone
setblock ~45 ~22 ~35 sandstone
setblock ~46 ~22 ~34 planks 2
setblock ~47 ~22 ~30 planks 2
setblock ~47 ~22 ~31 sandstone
setblock ~47 ~22 ~32 planks 2
setblock ~47 ~22 ~33 sandstone
setblock ~40 ~23 ~33 planks 2
setblock ~40 ~23 ~34 sandstone
setblock ~41 ~23 ~31 end_stone
setblock ~41 ~23 ~32 sandstone
setblock ~41 ~23 ~35 end_stone
fill ~42 ~23 ~30 ~43 ~23 ~30 sandstone
fill ~42 ~23 ~36 ~44 ~23 ~36 sandstone
setblock ~44 ~23 ~29 planks 2
setblock ~45 ~23 ~29 end_stone
setblock ~45 ~23 ~35 end_stone
setblock ~46 ~23 ~29 planks 2
setblock ~46 ~23 ~34 sandstone
setblock ~47 ~23 ~30 sandstone
setblock ~47 ~23 ~31 end_stone
setblock ~47 ~23 ~32 sandstone
setblock ~47 ~23 ~33 end_stone
setblock ~40 ~24 ~33 sandstone
setblock ~40 ~24 ~34 planks 2
setblock ~41 ~24 ~31 sandstone
setblock ~41 ~24 ~32 planks 2
setblock ~41 ~24 ~35 sandstone
fill ~42 ~24 ~30 ~43 ~24 ~30 planks 2
fill ~42 ~24 ~36 ~44 ~24 ~36 planks 2
fill ~44 ~24 ~29 ~46 ~24 ~29 sandstone
setblock ~45 ~24 ~35 sandstone
setblock ~46 ~24 ~34 planks 2
setblock ~47 ~24 ~30 planks 2
setblock ~47 ~24 ~31 sandstone
setblock ~47 ~24 ~32 planks 2
setblock ~47 ~24 ~33 sandstone
setblock ~67 ~24 ~26 planks 2
setblock ~40 ~25 ~34 sandstone
setblock ~41 ~25 ~31 end_stone
setblock ~41 ~25 ~32 sandstone
setblock ~41 ~25 ~33 end_stone
setblock ~41 ~25 ~35 end_stone
setblock ~42 ~25 ~31 planks 2
fill ~42 ~25 ~36 ~44 ~25 ~36 sandstone
setblock ~43 ~25 ~30 sandstone
setblock ~44 ~25 ~29 planks 2
setblock ~45 ~25 ~29 end_stone
setblock ~45 ~25 ~35 end_stone
setblock ~46 ~25 ~29 planks 2
setblock ~46 ~25 ~34 end_stone
setblock ~47 ~25 ~30 sandstone
setblock ~47 ~25 ~31 end_stone
setblock ~47 ~25 ~32 sandstone
setblock ~47 ~25 ~33 end_stone
setblock ~65 ~25 ~26 sandstone
setblock ~66 ~25 ~26 end_stone
setblock ~66 ~25 ~27 planks 2
fill ~66 ~25 ~28 ~68 ~25 ~28 sandstone
fill ~67 ~25 ~26 ~69 ~25 ~26 sandstone
setblock ~67 ~25 ~27 end_stone
setblock ~68 ~25 ~25 planks 2
setblock ~68 ~25 ~27 planks 2
setblock ~69 ~25 ~25 end_stone
setblock ~69 ~25 ~27 end_stone
setblock ~70 ~25 ~25 planks 2
setblock ~40 ~26 ~34 planks 2
setblock ~41 ~26 ~32 planks 2
setblock ~41 ~26 ~33 sandstone
setblock ~41 ~26 ~35 sandstone
setblock ~42 ~26 ~31 sandstone
fill ~42 ~26 ~36 ~45 ~26 ~36 planks 2
setblock ~43 ~26 ~30 planks 2
fill ~44 ~26 ~29 ~46 ~26 ~29 sandstone
setblock ~46 ~26 ~35 sandstone
setblock ~47 ~26 ~30 planks 2
setblock ~47 ~26 ~31 sandstone
setblock ~47 ~26 ~32 planks 2
setblock ~47 ~26 ~33 sandstone
setblock ~47 ~26 ~34 planks 2
fill ~65 ~26 ~26 ~66 ~26 ~26 planks 2
setblock ~65 ~26 ~27 sandstone
setblock ~65 ~26 ~28 planks 2
setblock ~66 ~26 ~29 sandstone
fill ~67 ~26 ~25 ~71 ~26 ~25 sandstone
fill ~67 ~26 ~28 ~69 ~26 ~28 planks 2
fill ~70 ~26 ~26 ~71 ~26 ~26 planks 2
setblock ~70 ~26 ~27 sandstone
setblock ~40 ~27 ~34 sandstone
setblock ~41 ~27 ~32 sandstone
setblock ~41 ~27 ~33 end_stone
setblock ~41 ~27 ~35 end_stone
setblock ~41 ~27 ~36 sandstone
setblock ~42 ~27 ~31 planks 2
setblock ~42 ~27 ~37 planks 2
setblock ~43 ~27 ~30 sandstone
setblock ~43 ~27 ~37 end_stone
setblock ~44 ~27 ~29 planks 2
setblock ~44 ~27 ~37 planks 2
setblock ~45 ~27 ~29 end_stone
setblock ~45 ~27 ~36 sandstone
setblock ~46 ~27 ~29 planks 2
setblock ~46 ~27 ~35 planks 2
setblock ~47 ~27 ~30 sandstone
setblock ~47 ~27 ~33 end_stone
setblock ~47 ~27 ~34 sandstone
fill ~48 ~27 ~31 ~48 ~29 ~31 planks 2
setblock ~48 ~27 ~32 sandstone
fill ~64 ~27 ~26 ~66 ~27 ~26 sandstone
setblock ~65 ~27 ~27 end_stone
setblock ~65 ~27 ~28 sandstone
setblock ~66 ~27 ~29 planks 2
setblock ~67 ~27 ~25 end_stone
setblock ~67 ~27 ~29 end_stone
setblock ~68 ~27 ~25 planks 2
fill ~68 ~27 ~28 ~69 ~27 ~28 sandstone
setblock ~69 ~27 ~25 end_stone
setblock ~70 ~27 ~25 planks 2
setblock ~70 ~27 ~27 planks 2
setblock ~71 ~27 ~24 sandstone
setblock ~71 ~27 ~25 end_stone
setblock ~71 ~27 ~27 end_stone
setblock ~72 ~27 ~26 sandstone
setblock ~41 ~28 ~32 planks 2
setblock ~41 ~28 ~33 sandstone
setblock ~41 ~28 ~34 planks 2
setblock ~41 ~28 ~35 sandstone
setblock ~41 ~28 ~36 planks 2
setblock ~42 ~28 ~31 sandstone
fill ~42 ~28 ~37 ~45 ~28 ~37 sandstone
fill ~43 ~28 ~30 ~44 ~28 ~30 planks 2
fill ~45 ~28 ~29 ~46 ~28 ~29 sandstone
setblock ~46 ~28 ~36 planks 2
setblock ~47 ~28 ~30 planks 2
setblock ~47 ~28 ~35 sandstone
setblock ~48 ~28 ~32 planks 2
setblock ~48 ~28 ~33 sandstone
setblock ~48 ~28 ~34 planks 2
fill ~64 ~28 ~26 ~65 ~28 ~26 planks 2
fill ~64 ~28 ~27 ~64 ~29 ~27 planks 2
setblock ~65 ~28 ~28 planks 2
fill ~65 ~28 ~29 ~67 ~28 ~29 sandstone
fill ~66 ~28 ~25 ~69 ~28 ~25 sandstone
fill ~68 ~28 ~28 ~70 ~28 ~28 planks 2
fill ~70 ~28 ~24 ~72 ~28 ~24 planks 2
setblock ~71 ~28 ~27 sandstone
setblock ~72 ~28 ~25 sandstone
setblock ~72 ~28 ~26 planks 2
setblock ~40 ~29 ~35 planks 2
setblock ~41 ~29 ~32 sandstone
setblock ~41 ~29 ~33 end_stone
setblock ~41 ~29 ~34 sandstone
setblock ~41 ~29 ~36 sandstone
setblock ~42 ~29 ~31 planks 2
setblock ~42 ~29 ~37 planks 2
fill ~43 ~29 ~30 ~45 ~29 ~30 sandstone
setblock ~43 ~29 ~37 end_stone
setblock ~44 ~29 ~38 sandstone
setblock ~45 ~29 ~37 end_stone
setblock ~46 ~29 ~29 planks 2
setblock ~46 ~29 ~36 sandstone
setblock ~47 ~29 ~30 sandstone
setblock ~47 ~29 ~35 end_stone
setblock ~48 ~29 ~32 sandstone
setblock ~48 ~29 ~33 planks 2
setblock ~48 ~29 ~34 sandstone
fill ~63 ~29 ~26 ~65 ~29 ~26 sandstone
setblock ~64 ~29 ~28 sandstone
setblock ~65 ~29 ~29 end_stone
setblock ~66 ~29 ~25 planks 2
setblock ~66 ~29 ~29 planks 2
setblock ~67 ~29 ~25 end_stone
setblock ~67 ~29 ~29 end_stone
setblock ~68 ~29 ~25 planks 2
fill ~68 ~29 ~28 ~70 ~29 ~28 sandstone
setblock ~69 ~29 ~25 end_stone
fill ~70 ~29 ~24 ~72 ~29 ~24 sandstone
setblock ~71 ~29 ~27 end_stone
setblock ~72 ~29 ~25 planks 2
setblock ~72 ~29 ~26 sandstone
setblock ~40 ~30 ~35 sandstone
setblock ~41 ~30 ~32 planks 2
setblock ~41 ~30 ~33 sandstone
setblock ~41 ~30 ~34 planks 2
setblock ~41 ~30 ~36 planks 2
setblock ~42 ~30 ~31 sandstone
setblock ~42 ~30 ~37 sandstone
fill ~42 ~30 ~38 ~45 ~30 ~38 planks 2
fill ~43 ~30 ~30 ~47 ~30 ~30 planks 2
setblock ~46 ~30 ~37 sandstone
setblock ~47 ~30 ~36 planks 2
setblock ~48 ~30 ~31 sandstone
setblock ~48 ~30 ~32 planks 2
setblock ~48 ~30 ~33 sandstone
setblock ~48 ~30 ~34 planks 2
setblock ~48 ~30 ~35 sandstone
fill ~63 ~30 ~26 ~64 ~30 ~26 planks 2
setblock ~63 ~30 ~27 sandstone
setblock ~64 ~30 ~28 planks 2
fill ~64 ~30 ~29 ~68 ~30 ~29 sandstone
fill ~65 ~30 ~25 ~68 ~30 ~25 sandstone
fill ~69 ~30 ~24 ~72 ~30 ~24 planks 2
fill ~69 ~30 ~28 ~70 ~30 ~28 planks 2
setblock ~71 ~30 ~27 sandstone
setblock ~72 ~30 ~25 sandstone
setblock ~72 ~30 ~26 planks 2
fill ~40 ~31 ~35 ~40 ~33 ~35 planks 2
setblock ~41 ~31 ~32 sandstone
setblock ~41 ~31 ~33 end_stone
setblock ~41 ~31 ~34 sandstone
setblock ~41 ~31 ~36 sandstone
setblock ~41 ~31 ~37 end_stone
setblock ~42 ~31 ~31 planks 2
fill ~42 ~31 ~38 ~45 ~31 ~38 sandstone
fill ~43 ~31 ~30 ~46 ~31 ~30 sandstone
setblock ~46 ~31 ~37 planks 2
setblock ~47 ~31 ~31 end_stone
setblock ~47 ~31 ~37 end_stone
setblock ~48 ~31 ~31 planks 2
setblock ~48 ~31 ~32 sandstone
setblock ~48 ~31 ~33 planks 2
setblock ~48 ~31 ~34 sandstone
fill ~48 ~31 ~35 ~48 ~32 ~35 planks 2
setblock ~48 ~31 ~36 sandstone
fill ~63 ~31 ~26 ~64 ~31 ~26 sandstone
setblock ~63 ~31 ~27 end_stone
setblock ~64 ~31 ~28 sandstone
setblock ~64 ~31 ~29 planks 2
setblock ~65 ~31 ~25 end_stone
fill ~65 ~31 ~30 ~67 ~31 ~30 sandstone
setblock ~66 ~31 ~25 planks 2
setblock ~67 ~31 ~25 end_stone
setblock ~68 ~31 ~25 planks 2
setblock ~68 ~31 ~29 planks 2
fill ~69 ~31 ~24 ~72 ~31 ~24 sandstone
setblock ~69 ~31 ~29 end_stone
setblock ~70 ~31 ~28 sandstone
setblock ~71 ~31 ~27 end_stone
fill ~72 ~31 ~23 ~72 ~33 ~23 planks 2
setblock ~72 ~31 ~25 planks 2
setblock ~72 ~31 ~26 sandstone
setblock ~40 ~32 ~36 planks 2
setblock ~41 ~32 ~32 planks 2
setblock ~41 ~32 ~33 sandstone
setblock ~41 ~32 ~34 planks 2
setblock ~41 ~32 ~37 sandstone
setblock ~42 ~32 ~31 sandstone
setblock ~42 ~32 ~38 planks 2
fill ~43 ~32 ~30 ~46 ~32 ~30 planks 2
setblock ~43 ~32 ~39 sandstone
setblock ~44 ~32 ~39 planks 2
setblock ~45 ~32 ~39 sandstone
setblock ~46 ~32 ~38 planks 2
setblock ~47 ~32 ~31 sandstone
setblock ~47 ~32 ~37 sandstone
setblock ~48 ~32 ~32 planks 2
setblock ~48 ~32 ~34 planks 2
setblock ~48 ~32 ~36 planks 2
setblock ~49 ~32 ~33 sandstone
setblock ~63 ~32 ~26 planks 2
setblock ~63 ~32 ~27 sandstone
fill ~64 ~32 ~25 ~67 ~32 ~25 sandstone
setblock ~64 ~32 ~28 planks 2
setblock ~64 ~32 ~29 sandstone
fill ~64 ~32 ~30 ~65 ~32 ~30 planks 2
setblock ~66 ~32 ~31 sandstone
fill ~67 ~32 ~30 ~68 ~32 ~30 planks 2
fill ~68 ~32 ~24 ~72 ~32 ~24 planks 2
fill ~69 ~32 ~29 ~70 ~32 ~29 sandstone
setblock ~71 ~32 ~28 planks 2
setblock ~72 ~32 ~25 sandstone
fill ~72 ~32 ~26 ~72 ~32 ~27 planks 2
setblock ~40 ~33 ~34 sandstone
setblock ~40 ~33 ~36 sandstone
setblock ~40 ~33 ~37 planks 2
setblock ~41 ~33 ~32 sandstone
setblock ~41 ~33 ~33 end_stone
setblock ~41 ~33 ~38 sandstone
setblock ~41 ~33 ~39 end_stone
setblock ~42 ~33 ~31 planks 2
setblock ~42 ~33 ~39 planks 2
fill ~43 ~33 ~30 ~45 ~33 ~30 sandstone
fill ~43 ~33 ~40 ~45 ~33 ~40 sandstone
setblock ~46 ~33 ~30 end_stone
setblock ~46 ~33 ~39 planks 2
setblock ~47 ~33 ~31 end_stone
setblock ~47 ~33 ~38 sandstone
setblock ~48 ~33 ~32 sandstone
setblock ~48 ~33 ~37 planks 2
setblock ~49 ~33 ~33 end_stone
setblock ~49 ~33 ~34 sandstone
setblock ~49 ~33 ~35 end_stone
setblock ~49 ~33 ~36 sandstone
setblock ~63 ~33 ~25 end_stone
setblock ~63 ~33 ~26 sandstone
setblock ~63 ~33 ~27 end_stone
setblock ~64 ~33 ~25 planks 2
setblock ~64 ~33 ~28 sandstone
setblock ~64 ~33 ~29 planks 2
setblock ~64 ~33 ~30 sandstone
setblock ~65 ~33 ~25 end_stone
setblock ~65 ~33 ~31 end_stone
setblock ~66 ~33 ~25 planks 2
setblock ~66 ~33 ~31 planks 2
setblock ~67 ~33 ~25 end_stone
setblock ~67 ~33 ~31 end_stone
fill ~68 ~33 ~24 ~70 ~33 ~24 sandstone
fill ~68 ~33 ~30 ~69 ~33 ~30 sandstone
setblock ~70 ~33 ~29 planks 2
setblock ~71 ~33 ~23 end_stone
setblock ~71 ~33 ~28 sandstone
setblock ~72 ~33 ~24 sandstone
setblock ~72 ~33 ~25 planks 2
setblock ~72 ~33 ~26 sandstone
setblock ~72 ~33 ~27 planks 2
setblock ~40 ~34 ~33 sandstone
setblock ~40 ~34 ~34 planks 2
setblock ~40 ~34 ~35 sandstone
setblock ~40 ~34 ~36 planks 2
setblock ~40 ~34 ~37 sandstone
setblock ~40 ~34 ~38 planks 2
setblock ~41 ~34 ~32 planks 2
setblock ~41 ~34 ~39 sandstone
fill ~41 ~34 ~40 ~42 ~34 ~40 planks 2
setblock ~42 ~34 ~31 sandstone
fill ~43 ~34 ~30 ~46 ~34 ~30 planks 2
fill ~43 ~34 ~41 ~44 ~34 ~41 sandstone
fill ~45 ~34 ~40 ~46 ~34 ~40 planks 2
setblock ~47 ~34 ~31 sandstone
setblock ~47 ~34 ~39 sandstone
setblock ~48 ~34 ~32 planks 2
setblock ~48 ~34 ~38 planks 2
setblock ~49 ~34 ~33 sandstone
setblock ~49 ~34 ~34 planks 2
setblock ~49 ~34 ~35 sandstone
setblock ~49 ~34 ~36 planks 2
setblock ~49 ~34 ~37 sandstone
setblock ~63 ~34 ~26 planks 2
setblock ~63 ~34 ~27 sandstone
fill ~64 ~34 ~25 ~66 ~34 ~25 sandstone
setblock ~64 ~34 ~28 planks 2
setblock ~64 ~34 ~29 sandstone
setblock ~64 ~34 ~30 planks 2
fill ~65 ~34 ~31 ~66 ~34 ~31 sandstone
fill ~67 ~34 ~24 ~70 ~34 ~24 planks 2
setblock ~67 ~34 ~32 planks 2
fill ~68 ~34 ~31 ~69 ~34 ~31 sandstone
setblock ~70 ~34 ~29 sandstone
setblock ~70 ~34 ~30 planks 2
fill ~71 ~34 ~23 ~72 ~34 ~23 sandstone
setblock ~71 ~34 ~28 planks 2
setblock ~72 ~34 ~24 planks 2
setblock ~72 ~34 ~25 sandstone
setblock ~72 ~34 ~26 planks 2
setblock ~72 ~34 ~27 sandstone
setblock ~39 ~35 ~35 end_stone
setblock ~39 ~35 ~36 sandstone
setblock ~39 ~35 ~37 end_stone
setblock ~39 ~35 ~38 sandstone
setblock ~40 ~35 ~33 planks 2
setblock ~40 ~35 ~34 sandstone
fill ~40 ~35 ~39 ~40 ~36 ~39 planks 2
setblock ~40 ~35 ~40 sandstone
setblock ~41 ~35 ~32 sandstone
setblock ~41 ~35 ~41 end_stone
setblock ~42 ~35 ~31 planks 2
setblock ~42 ~35 ~41 planks 2
fill ~43 ~35 ~30 ~46 ~35 ~30 sandstone
setblock ~43 ~35 ~41 end_stone
setblock ~44 ~35 ~41 planks 2
setblock ~45 ~35 ~41 end_stone
setblock ~46 ~35 ~40 sandstone
setblock ~46 ~35 ~41 planks 2
setblock ~47 ~35 ~31 end_stone
setblock ~47 ~35 ~39 end_stone
setblock ~48 ~35 ~32 sandstone
setblock ~48 ~35 ~38 sandstone
setblock ~49 ~35 ~33 end_stone
setblock ~49 ~35 ~34 sandstone
setblock ~49 ~35 ~35 end_stone
setblock ~49 ~35 ~36 sandstone
setblock ~49 ~35 ~37 end_stone
setblock ~50 ~35 ~33 planks 2
fill ~63 ~35 ~26 ~64 ~35 ~26 sandstone
setblock ~63 ~35 ~27 end_stone
setblock ~64 ~35 ~28 sandstone
setblock ~64 ~35 ~29 planks 2
setblock ~64 ~35 ~30 sandstone
fill ~64 ~35 ~31 ~64 ~37 ~31 planks 2
setblock ~65 ~35 ~25 end_stone
setblock ~65 ~35 ~31 end_stone
setblock ~66 ~35 ~25 planks 2
setblock ~66 ~35 ~32 sandstone
setblock ~67 ~35 ~25 end_stone
setblock ~67 ~35 ~33 end_stone
fill ~68 ~35 ~24 ~70 ~35 ~24 sandstone
setblock ~68 ~35 ~32 sandstone
setblock ~69 ~35 ~31 end_stone
setblock ~70 ~35 ~29 planks 2
setblock ~70 ~35 ~30 sandstone
setblock ~70 ~35 ~31 planks 2
setblock ~71 ~35 ~23 end_stone
setblock ~71 ~35 ~28 sandstone
setblock ~72 ~35 ~23 planks 2
setblock ~72 ~35 ~24 sandstone
setblock ~72 ~35 ~25 planks 2
setblock ~72 ~35 ~26 sandstone
fill ~72 ~35 ~27 ~72 ~37 ~27 planks 2
setblock ~39 ~36 ~34 planks 2
setblock ~39 ~36 ~35 sandstone
setblock ~39 ~36 ~36 planks 2
setblock ~39 ~36 ~37 sandstone
setblock ~39 ~36 ~38 planks 2
setblock ~40 ~36 ~33 sandstone
setblock ~40 ~36 ~40 planks 2
setblock ~41 ~36 ~32 planks 2
setblock ~41 ~36 ~41 sandstone
setblock ~42 ~36 ~31 sandstone
fill ~42 ~36 ~42 ~45 ~36 ~42 planks 2
fill ~43 ~36 ~30 ~46 ~36 ~30 planks 2
setblock ~46 ~36 ~41 sandstone
setblock ~47 ~36 ~31 sandstone
setblock ~47 ~36 ~40 planks 2
fill ~48 ~36 ~32 ~49 ~36 ~32 planks 2
setblock ~48 ~36 ~39 planks 2
setblock ~49 ~36 ~38 planks 2
setblock ~50 ~36 ~33 sandstone
setblock ~50 ~36 ~34 planks 2
setblock ~50 ~36 ~35 sandstone
setblock ~50 ~36 ~36 planks 2
setblock ~50 ~36 ~37 sandstone
fill ~64 ~36 ~26 ~64 ~36 ~28 planks 2
setblock ~64 ~36 ~29 sandstone
setblock ~64 ~36 ~30 planks 2
fill ~65 ~36 ~25 ~67 ~36 ~25 sandstone
fill ~65 ~36 ~32 ~66 ~36 ~32 planks 2
fill ~67 ~36 ~33 ~68 ~36 ~33 sandstone
fill ~68 ~36 ~24 ~70 ~36 ~24 planks 2
fill ~69 ~36 ~32 ~70 ~36 ~32 planks 2
setblock ~70 ~36 ~30 planks 2
setblock ~70 ~36 ~31 sandstone
setblock ~71 ~36 ~23 sandstone
setblock ~71 ~36 ~28 planks 2
setblock ~71 ~36 ~29 sandstone
setblock ~72 ~36 ~24 planks 2
setblock ~72 ~36 ~25 sandstone
setblock ~72 ~36 ~26 planks 2
setblock ~38 ~37 ~37 planks 2
setblock ~39 ~37 ~34 sandstone
setblock ~39 ~37 ~35 end_stone
setblock ~39 ~37 ~36 sandstone
setblock ~39 ~37 ~38 sandstone
setblock ~40 ~37 ~33 planks 2
fill ~40 ~37 ~39 ~40 ~37 ~40 concrete 6
setblock ~41 ~37 ~32 sandstone
setblock ~41 ~37 ~41 wool 6
setblock ~42 ~37 ~31 planks 2
fill ~42 ~37 ~42 ~44 ~37 ~42 concrete 6
fill ~43 ~37 ~30 ~45 ~37 ~30 sandstone
setblock ~45 ~37 ~42 sandstone
setblock ~46 ~37 ~30 end_stone
setblock ~46 ~37 ~42 end_stone
setblock ~47 ~37 ~31 end_stone
setblock ~47 ~37 ~41 end_stone
fill ~48 ~37 ~32 ~49 ~37 ~32 sandstone
setblock ~48 ~37 ~40 sandstone
setblock ~49 ~37 ~39 end_stone
setblock ~50 ~37 ~33 planks 2
setblock ~50 ~37 ~34 end_stone
setblock ~50 ~37 ~35 planks 2
setblock ~50 ~37 ~36 sandstone
setblock ~50 ~37 ~37 planks 2
setblock ~50 ~37 ~38 end_stone
fill ~64 ~37 ~26 ~65 ~37 ~26 sandstone
setblock ~64 ~37 ~27 planks 2
setblock ~64 ~37 ~28 sandstone
setblock ~64 ~37 ~29 planks 2
setblock ~64 ~37 ~30 sandstone
setblock ~65 ~37 ~32 sandstone
setblock ~66 ~37 ~25 planks 2
setblock ~66 ~37 ~33 planks 2
setblock ~67 ~37 ~25 end_stone
fill ~67 ~37 ~34 ~68 ~37 ~34 sandstone
setblock ~68 ~37 ~25 planks 2
fill ~69 ~37 ~24 ~70 ~37 ~24 sandstone
setblock ~69 ~37 ~33 end_stone
setblock ~70 ~37 ~32 sandstone
setblock ~71 ~37 ~23 end_stone
setblock ~71 ~37 ~25 end_stone
setblock ~71 ~37 ~26 sandstone
setblock ~71 ~37 ~28 sandstone
setblock ~71 ~37 ~29 end_stone
setblock ~71 ~37 ~30 sandstone
setblock ~71 ~37 ~31 end_stone
setblock ~72 ~37 ~24 sandstone
setblock ~38 ~38 ~35 sandstone
setblock ~38 ~38 ~36 planks 2
setblock ~39 ~38 ~34 planks 2
setblock ~39 ~38 ~37 sandstone
fill ~39 ~38 ~38 ~39 ~48 ~38 concrete 6
fill ~39 ~38 ~39 ~39 ~49 ~39 concrete 6
setblock ~40 ~38 ~33 sandstone
fill ~40 ~38 ~40 ~40 ~39 ~40 concrete 6
setblock ~41 ~38 ~32 planks 2
setblock ~41 ~38 ~41 concrete 6
setblock ~42 ~38 ~31 sandstone
fill ~42 ~38 ~42 ~45 ~38 ~42 concrete 6
fill ~43 ~38 ~30 ~46 ~38 ~30 planks 2
setblock ~46 ~38 ~42 planks 2
setblock ~47 ~38 ~31 sandstone
fill ~47 ~38 ~41 ~48 ~38 ~41 sandstone
fill ~48 ~38 ~32 ~49 ~38 ~32 planks 2
setblock ~49 ~38 ~40 planks 2
setblock ~50 ~38 ~33 sandstone
setblock ~50 ~38 ~38 planks 2
setblock ~50 ~38 ~39 sandstone
setblock ~51 ~38 ~34 planks 2
setblock ~51 ~38 ~35 sandstone
setblock ~51 ~38 ~36 planks 2
setblock ~51 ~38 ~37 sandstone
setblock ~64 ~38 ~27 sandstone
setblock ~65 ~38 ~26 planks 2
setblock ~65 ~38 ~28 planks 2
setblock ~65 ~38 ~29 sandstone
setblock ~65 ~38 ~30 planks 2
setblock ~65 ~38 ~31 sandstone
setblock ~65 ~38 ~32 planks 2
setblock ~65 ~38 ~33 sandstone
fill ~66 ~38 ~25 ~68 ~38 ~25 sandstone
setblock ~66 ~38 ~34 planks 2
fill ~67 ~38 ~35 ~68 ~38 ~35 sandstone
fill ~69 ~38 ~24 ~71 ~38 ~24 planks 2
setblock ~69 ~38 ~34 planks 2
setblock ~70 ~38 ~32 planks 2
setblock ~70 ~38 ~33 sandstone
setblock ~71 ~38 ~23 sandstone
setblock ~71 ~38 ~25 sandstone
setblock ~71 ~38 ~26 planks 2
setblock ~71 ~38 ~27 sandstone
setblock ~71 ~38 ~28 planks 2
setblock ~71 ~38 ~29 sandstone
setblock ~71 ~38 ~30 planks 2
setblock ~71 ~38 ~31 sandstone
setblock ~38 ~39 ~35 planks 2
setblock ~39 ~39 ~34 sandstone
fill ~39 ~39 ~36 ~39 ~45 ~36 concrete 6
fill ~39 ~39 ~37 ~39 ~46 ~37 concrete 6
setblock ~40 ~39 ~33 planks 2
fill ~40 ~39 ~41 ~40 ~41 ~41 concrete 6
setblock ~41 ~39 ~32 sandstone
fill ~41 ~39 ~42 ~41 ~40 ~42 concrete 6
setblock ~42 ~39 ~31 planks 2
fill ~42 ~39 ~43 ~42 ~42 ~43 concrete 6
fill ~43 ~39 ~30 ~46 ~39 ~30 sandstone
fill ~43 ~39 ~42 ~46 ~39 ~42 concrete 6
setblock ~47 ~39 ~31 end_stone
fill ~47 ~39 ~41 ~47 ~41 ~41 concrete 6
fill ~48 ~39 ~32 ~49 ~39 ~32 sandstone
fill ~48 ~39 ~40 ~49 ~39 ~40 concrete 6
setblock ~50 ~39 ~33 planks 2
setblock ~50 ~39 ~38 sandstone
fill ~50 ~39 ~39 ~50 ~49 ~39 concrete 6
setblock ~51 ~39 ~34 sandstone
setblock ~51 ~39 ~35 end_stone
setblock ~51 ~39 ~36 sandstone
setblock ~51 ~39 ~37 end_stone
fill ~64 ~39 ~26 ~65 ~39 ~26 sandstone
fill ~64 ~39 ~27 ~64 ~41 ~27 planks 2
setblock ~64 ~39 ~28 sandstone
setblock ~64 ~39 ~29 planks 2
setblock ~64 ~39 ~30 sandstone
fill ~64 ~39 ~31 ~64 ~41 ~31 planks 2
setblock ~64 ~39 ~32 sandstone
setblock ~65 ~39 ~33 end_stone
fill ~65 ~39 ~34 ~66 ~39 ~34 sandstone
setblock ~66 ~39 ~25 planks 2
setblock ~67 ~39 ~25 end_stone
setblock ~67 ~39 ~35 end_stone
setblock ~68 ~39 ~25 planks 2
setblock ~68 ~39 ~35 planks 2
fill ~69 ~39 ~24 ~71 ~39 ~24 sandstone
setblock ~69 ~39 ~35 end_stone
setblock ~70 ~39 ~32 sandstone
setblock ~70 ~39 ~33 planks 2
setblock ~70 ~39 ~34 sandstone
setblock ~71 ~39 ~23 end_stone
setblock ~71 ~39 ~25 end_stone
setblock ~71 ~39 ~26 sandstone
setblock ~71 ~39 ~27 end_stone
setblock ~71 ~39 ~28 sandstone
setblock ~71 ~39 ~29 end_stone
setblock ~71 ~39 ~30 sandstone
setblock ~71 ~39 ~31 end_stone
setblock ~39 ~40 ~34 planks 2
setblock ~39 ~40 ~35 sandstone
fill ~39 ~40 ~40 ~39 ~50 ~40 concrete 6
setblock ~40 ~40 ~33 sandstone
setblock ~41 ~40 ~32 planks 2
setblock ~42 ~40 ~31 sandstone
fill ~43 ~40 ~30 ~46 ~40 ~30 planks 2
fill ~43 ~40 ~43 ~45 ~40 ~43 concrete 6
fill ~46 ~40 ~42 ~46 ~42 ~42 concrete 6
setblock ~47 ~40 ~31 sandstone
fill ~48 ~40 ~32 ~49 ~40 ~32 planks 2
fill ~48 ~40 ~40 ~49 ~40 ~40 concrete 6
setblock ~50 ~40 ~33 sandstone
fill ~50 ~40 ~38 ~50 ~41 ~38 concrete 6
setblock ~51 ~40 ~34 planks 2
setblock ~51 ~40 ~36 planks 2
setblock ~51 ~40 ~37 sandstone
fill ~52 ~40 ~35 ~52 ~41 ~35 planks 2
fill ~64 ~40 ~25 ~66 ~40 ~25 sandstone
setblock ~64 ~40 ~26 planks 2
setblock ~64 ~40 ~28 planks 2
setblock ~64 ~40 ~29 sandstone
setblock ~64 ~40 ~30 planks 2
setblock ~64 ~40 ~32 planks 2
setblock ~64 ~40 ~33 sandstone
setblock ~65 ~40 ~34 planks 2
fill ~65 ~40 ~35 ~66 ~40 ~35 sandstone
fill ~66 ~40 ~36 ~68 ~40 ~36 planks 2
fill ~67 ~40 ~24 ~71 ~40 ~24 planks 2
fill ~69 ~40 ~35 ~70 ~40 ~35 sandstone
setblock ~70 ~40 ~32 planks 2
setblock ~70 ~40 ~33 sandstone
setblock ~70 ~40 ~34 planks 2
setblock ~71 ~40 ~25 sandstone
setblock ~71 ~40 ~26 planks 2
setblock ~71 ~40 ~27 sandstone
setblock ~71 ~40 ~28 planks 2
setblock ~71 ~40 ~29 sandstone
setblock ~71 ~40 ~30 planks 2
setblock ~71 ~40 ~31 sandstone
setblock ~39 ~41 ~34 sandstone
setblock ~39 ~41 ~35 stained_hardened_clay
setblock ~40 ~41 ~33 planks 2
fill ~40 ~41 ~42 ~40 ~44 ~42 concrete 6
setblock ~41 ~41 ~32 sandstone
fill ~41 ~41 ~43 ~41 ~42 ~43 concrete 6
setblock ~42 ~41 ~31 planks 2
setblock ~43 ~41 ~31 end_stone
fill ~43 ~41 ~43 ~45 ~41 ~43 concrete 6
fill ~44 ~41 ~30 ~45 ~41 ~30 sandstone
setblock ~46 ~41 ~30 end_stone
setblock ~47 ~41 ~31 end_stone
setblock ~48 ~41 ~31 planks 2
fill ~48 ~41 ~41 ~48 ~42 ~41 concrete 6
setblock ~49 ~41 ~32 sandstone
fill ~49 ~41 ~40 ~50 ~41 ~40 concrete 6
setblock ~50 ~41 ~33 planks 2
fill ~51 ~41 ~34 ~52 ~41 ~34 sandstone
fill ~51 ~41 ~36 ~51 ~45 ~36 concrete 6
fill ~51 ~41 ~37 ~51 ~46 ~37 concrete 6
setblock ~63 ~41 ~26 sandstone
setblock ~64 ~41 ~25 planks 2
setblock ~64 ~41 ~28 sandstone
setblock ~64 ~41 ~29 planks 2
setblock ~64 ~41 ~30 sandstone
setblock ~64 ~41 ~32 sandstone
setblock ~64 ~41 ~33 planks 2
setblock ~65 ~41 ~25 end_stone
setblock ~65 ~41 ~34 sandstone
setblock ~65 ~41 ~35 end_stone
setblock ~65 ~41 ~36 sandstone
fill ~66 ~41 ~24 ~70 ~41 ~24 sandstone
setblock ~66 ~41 ~37 planks 2
setblock ~67 ~41 ~37 end_stone
setblock ~68 ~41 ~37 planks 2
setblock ~69 ~41 ~36 sandstone
setblock ~70 ~41 ~23 planks 2
setblock ~70 ~41 ~25 planks 2
setblock ~70 ~41 ~26 end_stone
setblock ~70 ~41 ~32 sandstone
setblock ~70 ~41 ~33 planks 2
setblock ~70 ~41 ~34 end_stone
setblock ~70 ~41 ~35 planks 2
setblock ~71 ~41 ~27 end_stone
setblock ~71 ~41 ~28 sandstone
setblock ~71 ~41 ~29 end_stone
setblock ~71 ~41 ~30 sandstone
setblock ~71 ~41 ~31 end_stone
fill ~39 ~42 ~35 ~39 ~43 ~35 concrete 6
fill ~39 ~42 ~41 ~39 ~51 ~41 concrete 6
fill ~40 ~42 ~34 ~40 ~43 ~34 concrete 6
fill ~41 ~42 ~32 ~42 ~42 ~32 planks 2
fill ~41 ~42 ~33 ~41 ~43 ~33 concrete 6
fill ~42 ~42 ~31 ~45 ~42 ~31 sandstone
fill ~43 ~42 ~43 ~45 ~42 ~43 concrete 6
setblock ~46 ~42 ~30 planks 2
fill ~47 ~42 ~31 ~48 ~42 ~31 sandstone
fill ~47 ~42 ~42 ~47 ~43 ~42 concrete 6
fill ~48 ~42 ~32 ~49 ~42 ~32 planks 2
fill ~49 ~42 ~33 ~50 ~42 ~33 sandstone
fill ~49 ~42 ~41 ~49 ~44 ~41 concrete 6
fill ~50 ~42 ~34 ~50 ~43 ~34 concrete 6
fill ~50 ~42 ~40 ~50 ~50 ~40 concrete 6
fill ~51 ~42 ~35 ~51 ~43 ~35 concrete 6
fill ~51 ~42 ~38 ~51 ~47 ~38 concrete 6
fill ~63 ~42 ~25 ~65 ~42 ~25 sandstone
setblock ~63 ~42 ~26 planks 2
setblock ~63 ~42 ~27 sandstone
setblock ~64 ~42 ~28 planks 2
setblock ~64 ~42 ~29 sandstone
setblock ~64 ~42 ~30 planks 2
setblock ~64 ~42 ~31 sandstone
setblock ~64 ~42 ~32 planks 2
setblock ~64 ~42 ~33 sandstone
setblock ~65 ~42 ~34 planks 2
setblock ~65 ~42 ~35 sandstone
setblock ~65 ~42 ~36 planks 2
setblock ~65 ~42 ~37 sandstone
fill ~66 ~42 ~24 ~68 ~42 ~24 planks 2
fill ~66 ~42 ~38 ~68 ~42 ~38 planks 2
setblock ~69 ~42 ~23 sandstone
fill ~69 ~42 ~37 ~70 ~42 ~37 sandstone
setblock ~70 ~42 ~24 planks 2
setblock ~70 ~42 ~25 sandstone
setblock ~70 ~42 ~26 planks 2
setblock ~70 ~42 ~27 sandstone
setblock ~70 ~42 ~28 planks 2
setblock ~70 ~42 ~29 sandstone
setblock ~70 ~42 ~30 planks 2
setblock ~70 ~42 ~32 planks 2
setblock ~70 ~42 ~33 sandstone
setblock ~70 ~42 ~34 planks 2
setblock ~70 ~42 ~35 sandstone
setblock ~70 ~42 ~36 planks 2
setblock ~71 ~42 ~31 sandstone
fill ~40 ~43 ~43 ~40 ~47 ~43 concrete 6
fill ~41 ~43 ~44 ~43 ~43 ~44 concrete 6
fill ~42 ~43 ~32 ~45 ~43 ~32 concrete 6
fill ~44 ~43 ~43 ~46 ~43 ~43 concrete 6
setblock ~46 ~43 ~31 planks 2
setblock ~47 ~43 ~31 end_stone
fill ~47 ~43 ~32 ~47 ~44 ~32 concrete 6
fill ~48 ~43 ~33 ~49 ~43 ~33 concrete 6
fill ~48 ~43 ~42 ~48 ~45 ~42 concrete 6
setblock ~63 ~43 ~25 end_stone
setblock ~63 ~43 ~26 sandstone
setblock ~64 ~43 ~25 planks 2
fill ~64 ~43 ~27 ~64 ~45 ~27 planks 2
setblock ~64 ~43 ~28 sandstone
setblock ~64 ~43 ~29 planks 2
setblock ~64 ~43 ~30 sandstone
fill ~64 ~43 ~31 ~64 ~45 ~31 planks 2
setblock ~64 ~43 ~32 sandstone
setblock ~64 ~43 ~33 planks 2
setblock ~64 ~43 ~34 sandstone
fill ~65 ~43 ~24 ~69 ~43 ~24 sandstone
setblock ~65 ~43 ~35 end_stone
setblock ~65 ~43 ~36 sandstone
setblock ~65 ~43 ~37 end_stone
setblock ~66 ~43 ~38 sandstone
setblock ~67 ~43 ~39 end_stone
setblock ~68 ~43 ~39 planks 2
fill ~68 ~43 ~40 ~69 ~43 ~40 sandstone
setblock ~69 ~43 ~23 end_stone
setblock ~69 ~43 ~25 end_stone
setblock ~69 ~43 ~26 sandstone
setblock ~69 ~43 ~27 end_stone
setblock ~69 ~43 ~28 sandstone
setblock ~69 ~43 ~29 end_stone
fill ~69 ~43 ~38 ~70 ~43 ~38 sandstone
setblock ~69 ~43 ~39 end_stone
setblock ~70 ~43 ~30 sandstone
setblock ~70 ~43 ~31 planks 2
setblock ~70 ~43 ~32 sandstone
setblock ~70 ~43 ~33 planks 2
setblock ~70 ~43 ~34 sandstone
setblock ~70 ~43 ~35 planks 2
setblock ~71 ~43 ~36 sandstone
setblock ~71 ~43 ~37 end_stone
fill ~40 ~44 ~35 ~40 ~45 ~35 concrete 6
fill ~41 ~44 ~34 ~41 ~45 ~34 concrete 6
fill ~41 ~44 ~44 ~45 ~44 ~44 concrete 6
fill ~42 ~44 ~33 ~42 ~45 ~33 concrete 6
fill ~43 ~44 ~32 ~47 ~44 ~32 concrete 6
fill ~46 ~44 ~43 ~47 ~44 ~43 concrete 6
fill ~48 ~44 ~33 ~48 ~43 ~33 concrete 6
fill ~49 ~44 ~34 ~49 ~45 ~34 concrete 6
fill ~50 ~44 ~35 ~50 ~45 ~35 concrete 6
fill ~50 ~44 ~41 ~50 ~49 ~41 concrete 6
setblock ~63 ~44 ~25 sandstone
setblock ~63 ~44 ~26 planks 2
fill ~64 ~44 ~24 ~68 ~44 ~24 planks 2
setblock ~64 ~44 ~28 planks 2
setblock ~64 ~44 ~29 sandstone
setblock ~64 ~44 ~30 planks 2
setblock ~64 ~44 ~32 planks 2
setblock ~64 ~44 ~33 sandstone
fill ~64 ~44 ~34 ~64 ~44 ~35 planks 2
setblock ~65 ~44 ~36 planks 2
setblock ~65 ~44 ~37 sandstone
setblock ~66 ~44 ~38 planks 2
setblock ~66 ~44 ~39 sandstone
fill ~66 ~44 ~40 ~67 ~44 ~40 planks 2
fill ~67 ~44 ~41 ~69 ~44 ~41 sandstone
setblock ~68 ~44 ~23 planks 2
setblock ~68 ~44 ~25 sandstone
fill ~68 ~44 ~42 ~69 ~44 ~42 planks 2
setblock ~69 ~44 ~26 planks 2
setblock ~69 ~44 ~27 sandstone
setblock ~69 ~44 ~28 planks 2
setblock ~69 ~44 ~29 sandstone
setblock ~69 ~44 ~30 planks 2
setblock ~69 ~44 ~31 sandstone
setblock ~69 ~44 ~32 planks 2
setblock ~70 ~44 ~33 sandstone
setblock ~70 ~44 ~34 planks 2
setblock ~70 ~44 ~35 sandstone
setblock ~70 ~44 ~39 sandstone
setblock ~70 ~44 ~40 planks 2
setblock ~71 ~44 ~36 planks 2
setblock ~71 ~44 ~37 sandstone
setblock ~71 ~44 ~38 planks 2
fill ~39 ~45 ~42 ~39 ~52 ~42 concrete 6
fill ~41 ~45 ~44 ~46 ~45 ~44 concrete 6
fill ~43 ~45 ~33 ~44 ~45 ~33 concrete 6
fill ~45 ~45 ~32 ~46 ~45 ~32 concrete 6
fill ~47 ~45 ~33 ~47 ~46 ~33 concrete 6
fill ~47 ~45 ~43 ~47 ~46 ~43 concrete 6
fill ~48 ~45 ~34 ~48 ~46 ~34 concrete 6
fill ~49 ~45 ~42 ~49 ~56 ~42 concrete 6
setblock ~63 ~45 ~25 end_stone
fill ~63 ~45 ~26 ~65 ~45 ~26 sandstone
fill ~64 ~45 ~24 ~67 ~45 ~24 sandstone
setblock ~64 ~45 ~25 planks 2
setblock ~64 ~45 ~28 sandstone
setblock ~64 ~45 ~29 planks 2
setblock ~64 ~45 ~30 sandstone
setblock ~64 ~45 ~32 sandstone
setblock ~64 ~45 ~33 planks 2
setblock ~64 ~45 ~34 sandstone
setblock ~64 ~45 ~35 planks 2
setblock ~64 ~45 ~36 sandstone
setblock ~65 ~45 ~25 end_stone
setblock ~65 ~45 ~37 end_stone
setblock ~65 ~45 ~38 sandstone
setblock ~66 ~45 ~39 planks 2
setblock ~66 ~45 ~40 sandstone
setblock ~66 ~45 ~41 planks 2
setblock ~66 ~45 ~42 end_stone
setblock ~67 ~45 ~23 end_stone
setblock ~67 ~45 ~42 sandstone
setblock ~67 ~45 ~43 end_stone
setblock ~68 ~45 ~25 planks 2
setblock ~68 ~45 ~26 sandstone
setblock ~68 ~45 ~27 planks 2
setblock ~68 ~45 ~28 sandstone
setblock ~68 ~45 ~29 planks 2
setblock ~68 ~45 ~30 sandstone
setblock ~68 ~45 ~31 planks 2
setblock ~68 ~45 ~43 planks 2
fill ~68 ~45 ~44 ~69 ~45 ~44 sandstone
setblock ~69 ~45 ~32 sandstone
setblock ~69 ~45 ~33 end_stone
setblock ~69 ~45 ~43 end_stone
setblock ~70 ~45 ~34 end_stone
setblock ~70 ~45 ~35 planks 2
setblock ~70 ~45 ~41 planks 2
setblock ~70 ~45 ~42 end_stone
setblock ~71 ~45 ~36 sandstone
setblock ~71 ~45 ~37 end_stone
setblock ~71 ~45 ~38 sandstone
setblock ~71 ~45 ~39 end_stone
setblock ~71 ~45 ~40 sandstone
setblock ~71 ~45 ~41 end_stone
setblock ~40 ~46 ~36 concrete 6
setblock ~41 ~46 ~35 concrete 6
fill ~41 ~46 ~44 ~41 ~43 ~44 concrete 6
setblock ~42 ~46 ~34 concrete 6
fill ~42 ~46 ~45 ~45 ~46 ~45 concrete 6
fill ~43 ~46 ~33 ~47 ~46 ~33 concrete 6
fill ~46 ~46 ~44 ~46 ~49 ~44 concrete 6
fill ~48 ~46 ~43 ~48 ~48 ~43 concrete 6
setblock ~49 ~46 ~35 concrete 6
setblock ~50 ~46 ~36 concrete 6
fill ~64 ~46 ~29 ~66 ~46 ~29 sandstone
fill ~64 ~46 ~30 ~66 ~46 ~30 planks 2
fill ~64 ~46 ~31 ~67 ~46 ~31 sandstone
fill ~64 ~46 ~32 ~65 ~46 ~32 planks 2
setblock ~64 ~46 ~33 sandstone
setblock ~64 ~46 ~34 planks 2
setblock ~64 ~46 ~35 sandstone
setblock ~64 ~46 ~36 planks 2
fill ~65 ~46 ~27 ~68 ~46 ~27 sandstone
fill ~65 ~46 ~28 ~68 ~46 ~28 planks 2
setblock ~65 ~46 ~37 sandstone
setblock ~65 ~46 ~38 planks 2
setblock ~65 ~46 ~39 sandstone
setblock ~65 ~46 ~40 planks 2
fill ~66 ~46 ~24 ~67 ~46 ~24 planks 2
fill ~66 ~46 ~25 ~67 ~46 ~25 sandstone
fill ~66 ~46 ~26 ~67 ~46 ~26 planks 2
setblock ~66 ~46 ~41 sandstone
setblock ~66 ~46 ~42 planks 2
setblock ~66 ~46 ~43 sandstone
fill ~66 ~46 ~44 ~67 ~46 ~44 planks 2
fill ~67 ~46 ~45 ~70 ~46 ~45 sandstone
fill ~67 ~46 ~46 ~70 ~46 ~46 planks 2
fill ~67 ~46 ~47 ~70 ~46 ~47 sandstone
setblock ~68 ~46 ~29 sandstone
setblock ~68 ~46 ~30 planks 2
setblock ~68 ~46 ~32 planks 2
fill ~68 ~46 ~48 ~70 ~46 ~48 planks 2
fill ~68 ~46 ~49 ~70 ~46 ~49 sandstone
setblock ~69 ~46 ~33 sandstone
setblock ~69 ~46 ~50 planks 2
setblock ~70 ~46 ~34 planks 2
setblock ~70 ~46 ~35 sandstone
fill ~70 ~46 ~43 ~71 ~46 ~43 sandstone
setblock ~70 ~46 ~44 planks 2
setblock ~71 ~46 ~36 planks 2
setblock ~71 ~46 ~37 sandstone
setblock ~71 ~46 ~38 planks 2
setblock ~71 ~46 ~39 sandstone
setblock ~71 ~46 ~40 planks 2
setblock ~71 ~46 ~41 sandstone
setblock ~71 ~46 ~42 planks 2
fill ~40 ~47 ~37 ~40 ~48 ~37 concrete 6
fill ~40 ~47 ~44 ~40 ~49 ~44 concrete 6
fill ~41 ~47 ~36 ~41 ~48 ~36 concrete 6
fill ~41 ~47 ~45 ~45 ~47 ~45 concrete 6
fill ~42 ~47 ~35 ~42 ~48 ~35 concrete 6
fill ~43 ~47 ~34 ~45 ~47 ~34 concrete 6
setblock ~46 ~47 ~33 concrete 6
setblock ~47 ~47 ~34 concrete 6
fill ~47 ~47 ~44 ~47 ~49 ~44 concrete 6
setblock ~48 ~47 ~35 concrete 6
setblock ~49 ~47 ~36 concrete 6
setblock ~50 ~47 ~37 concrete 6
setblock ~64 ~47 ~38 sandstone
setblock ~65 ~47 ~33 end_stone
setblock ~65 ~47 ~34 sandstone
setblock ~65 ~47 ~35 end_stone
setblock ~65 ~47 ~36 sandstone
setblock ~65 ~47 ~37 end_stone
setblock ~65 ~47 ~39 end_stone
setblock ~65 ~47 ~40 sandstone
setblock ~65 ~47 ~41 end_stone
setblock ~65 ~47 ~42 sandstone
setblock ~65 ~47 ~43 end_stone
fill ~66 ~47 ~32 ~67 ~47 ~32 sandstone
setblock ~66 ~47 ~44 sandstone
setblock ~66 ~47 ~45 planks 2
setblock ~66 ~47 ~46 sandstone
setblock ~66 ~47 ~47 planks 2
fill ~66 ~47 ~48 ~67 ~47 ~48 sandstone
setblock ~67 ~47 ~29 end_stone
setblock ~67 ~47 ~30 sandstone
setblock ~67 ~47 ~49 end_stone
fill ~67 ~47 ~50 ~68 ~47 ~50 sandstone
setblock ~67 ~47 ~51 end_stone
setblock ~68 ~47 ~33 planks 2
setblock ~68 ~47 ~51 planks 2
setblock ~69 ~47 ~34 sandstone
setblock ~69 ~47 ~51 end_stone
setblock ~70 ~47 ~35 planks 2
setblock ~70 ~47 ~36 sandstone
setblock ~70 ~47 ~50 sandstone
setblock ~70 ~47 ~51 concrete 6
setblock ~71 ~47 ~37 end_stone
setblock ~71 ~47 ~38 sandstone
setblock ~71 ~47 ~39 end_stone
setblock ~71 ~47 ~40 sandstone
setblock ~71 ~47 ~41 end_stone
setblock ~71 ~47 ~44 sandstone
setblock ~71 ~47 ~45 end_stone
fill ~71 ~47 ~46 ~72 ~47 ~46 sandstone
setblock ~71 ~47 ~47 end_stone
fill ~71 ~47 ~48 ~72 ~47 ~48 sandstone
setblock ~71 ~47 ~49 end_stone
setblock ~72 ~47 ~42 sandstone
fill ~72 ~47 ~43 ~72 ~49 ~43 planks 2
setblock ~72 ~47 ~47 planks 2
setblock ~72 ~47 ~49 planks 2
fill ~39 ~48 ~43 ~39 ~55 ~43 concrete 6
fill ~41 ~48 ~45 ~42 ~48 ~45 concrete 6
fill ~43 ~48 ~35 ~43 ~49 ~35 concrete 6
fill ~43 ~48 ~46 ~44 ~48 ~46 concrete 6
fill ~44 ~48 ~34 ~46 ~48 ~34 concrete 6
setblock ~45 ~48 ~45 concrete 6
fill ~47 ~48 ~35 ~47 ~49 ~35 concrete 6
fill ~48 ~48 ~36 ~48 ~49 ~36 concrete 6
setblock ~49 ~48 ~37 concrete 6
fill ~49 ~48 ~43 ~49 ~50 ~43 concrete 6
setblock ~50 ~48 ~38 concrete 6
fill ~64 ~48 ~39 ~64 ~48 ~40 planks 2
setblock ~64 ~48 ~41 sandstone
fill ~65 ~48 ~34 ~66 ~48 ~34 planks 2
setblock ~65 ~48 ~35 sandstone
setblock ~65 ~48 ~36 planks 2
setblock ~65 ~48 ~37 sandstone
setblock ~65 ~48 ~38 planks 2
setblock ~65 ~48 ~42 planks 2
setblock ~65 ~48 ~43 sandstone
setblock ~65 ~48 ~44 planks 2
setblock ~65 ~48 ~45 sandstone
setblock ~65 ~48 ~46 planks 2
setblock ~65 ~48 ~47 sandstone
setblock ~65 ~48 ~48 planks 2
fill ~66 ~48 ~33 ~67 ~48 ~33 sandstone
setblock ~66 ~48 ~49 sandstone
setblock ~66 ~48 ~50 planks 2
fill ~66 ~48 ~51 ~67 ~48 ~51 sandstone
setblock ~68 ~48 ~34 planks 2
fill ~68 ~48 ~52 ~71 ~48 ~52 concrete 6
setblock ~69 ~48 ~35 sandstone
fill ~69 ~48 ~53 ~70 ~48 ~53 concrete 6
setblock ~70 ~48 ~36 planks 2
setblock ~70 ~48 ~37 sandstone
setblock ~71 ~48 ~38 planks 2
setblock ~71 ~48 ~39 sandstone
setblock ~71 ~48 ~40 planks 2
fill ~71 ~48 ~50 ~72 ~48 ~50 concrete 6
fill ~71 ~48 ~51 ~71 ~48 ~50 concrete 6
setblock ~72 ~48 ~41 sandstone
setblock ~72 ~48 ~42 planks 2
setblock ~72 ~48 ~44 planks 2
setblock ~72 ~48 ~45 sandstone
fill ~72 ~48 ~49 ~73 ~48 ~49 sandstone
setblock ~73 ~48 ~46 planks 2
setblock ~73 ~48 ~47 sandstone
setblock ~73 ~48 ~48 planks 2
setblock ~40 ~49 ~38 concrete 6
fill ~40 ~49 ~45 ~40 ~51 ~45 concrete 6
setblock ~41 ~49 ~37 wool 6
fill ~41 ~49 ~46 ~44 ~49 ~46 concrete 6
setblock ~42 ~49 ~36 concrete 6
fill ~44 ~49 ~35 ~47 ~49 ~35 concrete 6
setblock ~45 ~49 ~45 wool 6
fill ~48 ~49 ~37 ~48 ~50 ~37 concrete 6
fill ~48 ~49 ~44 ~48 ~52 ~44 concrete 6
setblock ~49 ~49 ~38 concrete 6
setblock ~64 ~49 ~41 planks 2
setblock ~64 ~49 ~42 sandstone
setblock ~64 ~49 ~43 planks 2
setblock ~64 ~49 ~44 sandstone
setblock ~65 ~49 ~36 sandstone
setblock ~65 ~49 ~37 end_stone
setblock ~65 ~49 ~38 sandstone
setblock ~65 ~49 ~39 end_stone
setblock ~65 ~49 ~40 sandstone
setblock ~65 ~49 ~45 end_stone
setblock ~65 ~49 ~46 sandstone
setblock ~65 ~49 ~47 end_stone
setblock ~65 ~49 ~48 sandstone
setblock ~65 ~49 ~49 end_stone
setblock ~65 ~49 ~50 sandstone
setblock ~66 ~49 ~35 planks 2
setblock ~66 ~49 ~51 planks 2
setblock ~66 ~49 ~52 sandstone
setblock ~67 ~49 ~34 sandstone
fill ~67 ~49 ~52 ~67 ~49 ~53 concrete 6
setblock ~68 ~49 ~35 planks 2
fill ~68 ~49 ~53 ~68 ~49 ~54 concrete 6
setblock ~69 ~49 ~36 sandstone
fill ~69 ~49 ~54 ~71 ~49 ~54 concrete 6
setblock ~70 ~49 ~37 planks 2
setblock ~70 ~49 ~55 concrete 6
setblock ~71 ~49 ~38 sandstone
setblock ~71 ~49 ~39 end_stone
fill ~71 ~49 ~53 ~72 ~49 ~53 concrete 6
setblock ~71 ~49 ~55 wool 6
setblock ~71 ~49 ~56 concrete 6
setblock ~72 ~49 ~40 sandstone
setblock ~72 ~49 ~41 planks 2
setblock ~72 ~49 ~42 sandstone
setblock ~72 ~49 ~44 sandstone
fill ~72 ~49 ~51 ~73 ~49 ~51 concrete 6
fill ~72 ~49 ~52 ~72 ~49 ~51 concrete 6
setblock ~73 ~49 ~45 end_stone
setblock ~73 ~49 ~46 sandstone
setblock ~73 ~49 ~47 end_stone
setblock ~73 ~49 ~50 concrete 6
setblock ~74 ~49 ~48 sandstone
setblock ~74 ~49 ~49 planks 2
fill ~39 ~50 ~44 ~39 ~59 ~44 concrete 6
setblock ~40 ~50 ~39 concrete 6
fill ~40 ~50 ~46 ~44 ~50 ~46 concrete 6
setblock ~41 ~50 ~38 concrete 6
setblock ~42 ~50 ~37 concrete 6
fill ~43 ~50 ~36 ~47 ~50 ~36 concrete 6
fill ~45 ~50 ~45 ~47 ~50 ~45 concrete 6
fill ~48 ~50 ~38 ~48 ~51 ~38 concrete 6
setblock ~49 ~50 ~39 concrete 6
fill ~49 ~50 ~41 ~49 ~52 ~41 concrete 6
setblock ~64 ~50 ~41 sandstone
setblock ~64 ~50 ~42 planks 2
setblock ~64 ~50 ~43 sandstone
setblock ~64 ~50 ~44 planks 2
setblock ~64 ~50 ~45 sandstone
setblock ~64 ~50 ~46 planks 2
setblock ~64 ~50 ~47 sandstone
setblock ~64 ~50 ~48 planks 2
fill ~65 ~50 ~37 ~66 ~50 ~37 sandstone
setblock ~65 ~50 ~38 planks 2
setblock ~65 ~50 ~39 sandstone
setblock ~65 ~50 ~40 planks 2
setblock ~65 ~50 ~49 sandstone
setblock ~65 ~50 ~50 planks 2
setblock ~65 ~50 ~51 sandstone
setblock ~65 ~50 ~52 planks 2
fill ~66 ~50 ~36 ~69 ~50 ~36 planks 2
setblock ~66 ~50 ~53 concrete 6
setblock ~67 ~50 ~35 sandstone
setblock ~67 ~50 ~54 concrete 6
fill ~68 ~50 ~55 ~69 ~50 ~55 concrete 6
fill ~69 ~50 ~56 ~70 ~50 ~56 concrete 6
setblock ~70 ~50 ~37 sandstone
setblock ~70 ~50 ~38 planks 2
fill ~70 ~50 ~57 ~71 ~50 ~57 concrete 6
setblock ~71 ~50 ~39 sandstone
setblock ~71 ~50 ~40 planks 2
setblock ~72 ~50 ~41 sandstone
setblock ~72 ~50 ~42 planks 2
setblock ~72 ~50 ~43 sandstone
fill ~72 ~50 ~54 ~73 ~50 ~54 concrete 6
fill ~72 ~50 ~55 ~72 ~50 ~56 concrete 6
setblock ~73 ~50 ~44 planks 2
setblock ~73 ~50 ~45 sandstone
fill ~73 ~50 ~52 ~73 ~50 ~54 concrete 6
setblock ~74 ~50 ~46 planks 2
setblock ~74 ~50 ~47 sandstone
setblock ~74 ~50 ~48 planks 2
setblock ~74 ~50 ~49 sandstone
fill ~74 ~50 ~50 ~74 ~52 ~50 concrete 6
fill ~74 ~50 ~51 ~74 ~52 ~51 concrete 6
fill ~40 ~51 ~40 ~40 ~52 ~40 concrete 6
fill ~40 ~51 ~46 ~41 ~51 ~46 concrete 6
fill ~41 ~51 ~39 ~41 ~52 ~39 concrete 6
fill ~42 ~51 ~38 ~42 ~52 ~38 concrete 6
fill ~42 ~51 ~47 ~43 ~51 ~47 concrete 6
fill ~43 ~51 ~37 ~43 ~52 ~37 concrete 6
setblock ~44 ~51 ~36 concrete 6
fill ~44 ~51 ~46 ~46 ~51 ~46 concrete 6
fill ~45 ~51 ~37 ~47 ~51 ~37 concrete 6
setblock ~47 ~51 ~45 concrete 6
fill ~48 ~51 ~39 ~48 ~52 ~39 concrete 6
fill ~48 ~51 ~43 ~48 ~52 ~43 concrete 6
setblock ~49 ~51 ~40 concrete 6
setblock ~64 ~51 ~41 planks 2
setblock ~64 ~51 ~42 sandstone
fill ~64 ~51 ~43 ~64 ~53 ~43 planks 2
setblock ~64 ~51 ~44 sandstone
setblock ~64 ~51 ~45 planks 2
setblock ~64 ~51 ~46 sandstone
setblock ~64 ~51 ~47 planks 2
setblock ~64 ~51 ~48 sandstone
setblock ~64 ~51 ~49 planks 2
setblock ~64 ~51 ~50 sandstone
setblock ~64 ~51 ~51 planks 2
setblock ~65 ~51 ~39 end_stone
setblock ~65 ~51 ~40 sandstone
fill ~65 ~51 ~52 ~65 ~51 ~53 concrete 6
setblock ~66 ~51 ~38 sandstone
setblock ~66 ~51 ~54 concrete 6
setblock ~67 ~51 ~37 end_stone
fill ~67 ~51 ~55 ~67 ~51 ~56 concrete 6
setblock ~68 ~51 ~37 planks 2
fill ~68 ~51 ~56 ~68 ~51 ~57 concrete 6
setblock ~69 ~51 ~37 end_stone
fill ~69 ~51 ~57 ~69 ~51 ~58 concrete 6
setblock ~70 ~51 ~38 sandstone
fill ~70 ~51 ~58 ~72 ~51 ~58 concrete 6
fill ~70 ~51 ~59 ~71 ~51 ~59 concrete 6
setblock ~71 ~51 ~39 end_stone
setblock ~71 ~51 ~40 sandstone
setblock ~72 ~51 ~41 planks 2
setblock ~72 ~51 ~42 sandstone
fill ~72 ~51 ~57 ~73 ~51 ~57 concrete 6
setblock ~73 ~51 ~43 end_stone
setblock ~73 ~51 ~44 sandstone
fill ~73 ~51 ~55 ~74 ~51 ~55 concrete 6
fill ~73 ~51 ~56 ~73 ~51 ~55 concrete 6
setblock ~74 ~51 ~45 planks 2
setblock ~74 ~51 ~46 sandstone
setblock ~74 ~51 ~47 planks 2
fill ~74 ~51 ~49 ~74 ~52 ~49 concrete 6
fill ~74 ~51 ~52 ~74 ~52 ~52 concrete 6
fill ~74 ~51 ~53 ~74 ~52 ~53 concrete 6
fill ~74 ~51 ~54 ~74 ~53 ~54 concrete 6
setblock ~75 ~51 ~48 sandstone
fill ~39 ~52 ~45 ~39 ~59 ~45 concrete 6
fill ~40 ~52 ~41 ~40 ~57 ~41 concrete 6
fill ~40 ~52 ~46 ~40 ~58 ~46 concrete 6
fill ~41 ~52 ~47 ~44 ~52 ~47 concrete 6
fill ~44 ~52 ~37 ~46 ~52 ~37 concrete 6
fill ~45 ~52 ~46 ~47 ~52 ~46 concrete 6
fill ~47 ~52 ~38 ~47 ~53 ~38 concrete 6
fill ~48 ~52 ~40 ~48 ~53 ~40 concrete 6
setblock ~48 ~52 ~45 concrete 6
setblock ~63 ~52 ~46 planks 2
setblock ~63 ~52 ~47 sandstone
setblock ~63 ~52 ~48 planks 2
setblock ~63 ~52 ~49 sandstone
setblock ~63 ~52 ~50 planks 2
setblock ~64 ~52 ~42 planks 2
setblock ~64 ~52 ~44 planks 2
setblock ~64 ~52 ~45 sandstone
fill ~64 ~52 ~51 ~64 ~52 ~52 concrete 6
fill ~65 ~52 ~40 ~66 ~52 ~40 planks 2
setblock ~65 ~52 ~41 sandstone
fill ~65 ~52 ~53 ~65 ~52 ~54 concrete 6
fill ~66 ~52 ~39 ~67 ~52 ~39 sandstone
fill ~66 ~52 ~55 ~66 ~52 ~56 concrete 6
fill ~67 ~52 ~38 ~69 ~52 ~38 planks 2
fill ~67 ~52 ~57 ~67 ~52 ~58 concrete 6
fill ~68 ~52 ~58 ~68 ~52 ~59 concrete 6
fill ~69 ~52 ~39 ~70 ~52 ~39 sandstone
fill ~69 ~52 ~59 ~69 ~52 ~60 concrete 6
fill ~70 ~52 ~60 ~72 ~52 ~60 concrete 6
fill ~70 ~52 ~61 ~72 ~52 ~61 concrete 6
setblock ~71 ~52 ~40 planks 2
setblock ~71 ~52 ~41 sandstone
setblock ~72 ~52 ~42 planks 2
fill ~72 ~52 ~59 ~73 ~52 ~59 concrete 6
setblock ~72 ~52 ~62 concrete 6
setblock ~73 ~52 ~43 sandstone
setblock ~73 ~52 ~44 planks 2
setblock ~73 ~52 ~58 concrete 6
setblock ~74 ~52 ~45 sandstone
setblock ~74 ~52 ~46 planks 2
fill ~74 ~52 ~55 ~74 ~53 ~55 concrete 6
fill ~74 ~52 ~56 ~74 ~53 ~56 concrete 6
fill ~74 ~52 ~57 ~74 ~53 ~57 concrete 6
setblock ~75 ~52 ~47 sandstone
setblock ~75 ~52 ~48 planks 2
fill ~40 ~53 ~42 ~40 ~56 ~42 concrete 6
fill ~41 ~53 ~40 ~41 ~59 ~40 concrete 6
fill ~41 ~53 ~47 ~45 ~53 ~47 concrete 6
fill ~42 ~53 ~39 ~42 ~66 ~39 concrete 6
fill ~43 ~53 ~38 ~47 ~53 ~38 concrete 6
fill ~46 ~53 ~46 ~48 ~53 ~46 concrete 6
fill ~47 ~53 ~39 ~47 ~54 ~39 concrete 6
setblock ~49 ~53 ~41 wool 6
fill ~49 ~53 ~43 ~49 ~56 ~43 concrete 6
fill ~49 ~53 ~44 ~49 ~55 ~44 concrete 6
setblock ~49 ~53 ~45 wool 6
setblock ~63 ~53 ~46 sandstone
setblock ~63 ~53 ~47 end_stone
setblock ~63 ~53 ~48 sandstone
setblock ~63 ~53 ~49 end_stone
setblock ~63 ~53 ~50 sandstone
fill ~63 ~53 ~51 ~63 ~58 ~51 concrete 6
setblock ~64 ~53 ~44 sandstone
setblock ~64 ~53 ~45 planks 2
fill ~64 ~53 ~52 ~64 ~53 ~53 concrete 6
setblock ~65 ~53 ~42 sandstone
fill ~65 ~53 ~54 ~65 ~53 ~55 concrete 6
setblock ~66 ~53 ~41 planks 2
fill ~66 ~53 ~56 ~66 ~53 ~57 concrete 6
fill ~67 ~53 ~40 ~71 ~53 ~40 sandstone
setblock ~67 ~53 ~58 concrete 6
setblock ~67 ~53 ~59 wool 6
setblock ~68 ~53 ~39 planks 2
fill ~68 ~53 ~60 ~68 ~53 ~61 concrete 6
fill ~69 ~53 ~61 ~69 ~53 ~62 concrete 6
fill ~70 ~53 ~62 ~71 ~53 ~62 concrete 6
fill ~70 ~53 ~63 ~70 ~53 ~62 concrete 6
setblock ~71 ~53 ~41 end_stone
setblock ~71 ~53 ~63 wool 6
setblock ~72 ~53 ~42 sandstone
setblock ~72 ~53 ~43 planks 2
setblock ~72 ~53 ~63 concrete 6
setblock ~73 ~53 ~44 sandstone
fill ~73 ~53 ~60 ~74 ~53 ~60 concrete 6
fill ~73 ~53 ~61 ~73 ~53 ~62 concrete 6
setblock ~74 ~53 ~45 planks 2
setblock ~74 ~53 ~46 end_stone
fill ~74 ~53 ~58 ~74 ~54 ~58 concrete 6
fill ~74 ~53 ~59 ~74 ~54 ~59 concrete 6
setblock ~75 ~53 ~47 end_stone
setblock ~75 ~53 ~48 sandstone
setblock ~75 ~53 ~49 end_stone
fill ~75 ~53 ~50 ~75 ~54 ~50 concrete 6
fill ~75 ~53 ~51 ~75 ~55 ~51 concrete 6
fill ~75 ~53 ~52 ~75 ~56 ~52 concrete 6
fill ~75 ~53 ~53 ~75 ~56 ~53 concrete 6
fill ~41 ~54 ~47 ~46 ~54 ~47 concrete 6
fill ~43 ~54 ~39 ~43 ~64 ~39 concrete 6
fill ~44 ~54 ~38 ~46 ~54 ~38 concrete 6
fill ~47 ~54 ~40 ~47 ~61 ~40 concrete 6
fill ~47 ~54 ~46 ~49 ~54 ~46 concrete 6
fill ~48 ~54 ~41 ~49 ~54 ~41 concrete 6
fill ~49 ~54 ~45 ~49 ~55 ~45 concrete 6
setblock ~63 ~54 ~46 planks 2
setblock ~63 ~54 ~47 sandstone
setblock ~63 ~54 ~48 planks 2
setblock ~63 ~54 ~49 sandstone
setblock ~63 ~54 ~50 planks 2
fill ~63 ~54 ~52 ~63 ~59 ~52 concrete 6
fill ~63 ~54 ~53 ~63 ~59 ~53 concrete 6
setblock ~64 ~54 ~44 planks 2
setblock ~64 ~54 ~45 sandstone
fill ~64 ~54 ~54 ~64 ~54 ~55 concrete 6
setblock ~65 ~54 ~43 sandstone
fill ~65 ~54 ~56 ~65 ~54 ~57 concrete 6
setblock ~66 ~54 ~42 planks 2
fill ~66 ~54 ~58 ~66 ~54 ~59 concrete 6
fill ~67 ~54 ~41 ~71 ~54 ~41 sandstone
setblock ~67 ~54 ~60 concrete 6
fill ~68 ~54 ~61 ~68 ~54 ~62 concrete 6
setblock ~69 ~54 ~63 concrete 6
fill ~70 ~54 ~64 ~72 ~54 ~64 concrete 6
fill ~71 ~54 ~42 ~72 ~54 ~42 planks 2
setblock ~72 ~54 ~43 sandstone
setblock ~73 ~54 ~44 planks 2
setblock ~73 ~54 ~45 sandstone
setblock ~73 ~54 ~63 concrete 6
setblock ~74 ~54 ~46 planks 2
setblock ~74 ~54 ~47 sandstone
fill ~74 ~54 ~60 ~74 ~54 ~62 concrete 6
setblock ~75 ~54 ~48 planks 2
setblock ~75 ~54 ~49 sandstone
fill ~75 ~54 ~54 ~75 ~56 ~54 concrete 6
fill ~75 ~54 ~55 ~75 ~56 ~55 concrete 6
fill ~75 ~54 ~56 ~75 ~57 ~56 concrete 6
fill ~75 ~54 ~57 ~75 ~57 ~57 concrete 6
setblock ~32 ~55 ~8 sandstone
fill ~41 ~55 ~47 ~42 ~55 ~47 concrete 6
fill ~43 ~55 ~48 ~45 ~55 ~48 concrete 6
fill ~44 ~55 ~38 ~45 ~55 ~38 concrete 6
fill ~46 ~55 ~39 ~46 ~63 ~39 concrete 6
fill ~46 ~55 ~47 ~47 ~55 ~47 concrete 6
fill ~48 ~55 ~41 ~49 ~55 ~41 concrete 6
fill ~48 ~55 ~46 ~49 ~55 ~46 concrete 6
setblock ~63 ~55 ~46 sandstone
setblock ~63 ~55 ~47 end_stone
setblock ~63 ~55 ~48 sandstone
setblock ~63 ~55 ~49 end_stone
setblock ~63 ~55 ~50 stained_hardened_clay
fill ~63 ~55 ~54 ~63 ~57 ~54 concrete 6
setblock ~64 ~55 ~45 planks 2
fill ~64 ~55 ~55 ~64 ~59 ~55 concrete 6
fill ~64 ~55 ~56 ~64 ~59 ~56 concrete 6
setblock ~65 ~55 ~44 sandstone
fill ~65 ~55 ~57 ~65 ~55 ~58 concrete 6
setblock ~66 ~55 ~43 planks 2
fill ~66 ~55 ~59 ~66 ~55 ~60 concrete 6
fill ~67 ~55 ~42 ~70 ~55 ~42 sandstone
setblock ~67 ~55 ~43 end_stone
fill ~67 ~55 ~61 ~67 ~55 ~62 concrete 6
fill ~68 ~55 ~62 ~68 ~55 ~63 concrete 6
fill ~69 ~55 ~64 ~69 ~55 ~65 concrete 6
setblock ~70 ~55 ~43 planks 2
fill ~70 ~55 ~65 ~73 ~55 ~65 concrete 6
setblock ~71 ~55 ~43 end_stone
setblock ~72 ~55 ~43 planks 2
setblock ~72 ~55 ~44 sandstone
setblock ~73 ~55 ~45 end_stone
setblock ~73 ~55 ~46 sandstone
setblock ~73 ~55 ~64 concrete 6
setblock ~74 ~55 ~47 planks 2
setblock ~74 ~55 ~48 sandstone
setblock ~74 ~55 ~49 planks 2
fill ~74 ~55 ~50 ~74 ~56 ~50 concrete 6
fill ~74 ~55 ~61 ~74 ~55 ~63 concrete 6
fill ~75 ~55 ~58 ~75 ~57 ~58 concrete 6
fill ~75 ~55 ~59 ~75 ~56 ~59 concrete 6
fill ~75 ~55 ~60 ~75 ~57 ~60 concrete 6
setblock ~80 ~55 ~10 sandstone
setblock ~32 ~56 ~8 planks 2
setblock ~33 ~56 ~6 planks 2
setblock ~33 ~56 ~7 sandstone
setblock ~40 ~56 ~43 concrete 6
fill ~41 ~56 ~47 ~41 ~57 ~47 concrete 6
fill ~42 ~56 ~48 ~46 ~56 ~48 concrete 6
fill ~44 ~56 ~39 ~46 ~56 ~39 concrete 6
fill ~47 ~56 ~47 ~49 ~56 ~47 concrete 6
fill ~48 ~56 ~41 ~49 ~56 ~41 concrete 6
fill ~50 ~56 ~44 ~50 ~59 ~44 concrete 6
fill ~50 ~56 ~45 ~50 ~58 ~45 concrete 6
fill ~50 ~56 ~46 ~50 ~57 ~46 concrete 6
setblock ~62 ~56 ~49 sandstone
fill ~63 ~56 ~46 ~64 ~56 ~46 planks 2
setblock ~63 ~56 ~47 sandstone
setblock ~63 ~56 ~48 planks 2
setblock ~63 ~56 ~50 planks 2
fill ~64 ~56 ~57 ~64 ~59 ~57 concrete 6
fill ~64 ~56 ~58 ~64 ~58 ~58 concrete 6
setblock ~65 ~56 ~45 sandstone
fill ~65 ~56 ~59 ~65 ~61 ~59 concrete 6
fill ~65 ~56 ~60 ~65 ~59 ~60 concrete 6
fill ~66 ~56 ~44 ~67 ~56 ~44 planks 2
fill ~66 ~56 ~61 ~66 ~56 ~62 concrete 6
setblock ~67 ~56 ~63 concrete 6
setblock ~68 ~56 ~43 planks 2
fill ~68 ~56 ~64 ~68 ~56 ~65 concrete 6
setblock ~69 ~56 ~43 sandstone
fill ~69 ~56 ~66 ~73 ~56 ~66 concrete 6
fill ~70 ~56 ~44 ~72 ~56 ~44 planks 2
setblock ~73 ~56 ~45 sandstone
setblock ~73 ~56 ~46 planks 2
setblock ~74 ~56 ~47 sandstone
setblock ~74 ~56 ~48 planks 2
setblock ~74 ~56 ~49 concrete 6
fill ~74 ~56 ~51 ~74 ~57 ~51 concrete 6
fill ~74 ~56 ~64 ~75 ~56 ~64 concrete 6
fill ~74 ~56 ~65 ~74 ~56 ~64 concrete 6
fill ~75 ~56 ~61 ~75 ~58 ~61 concrete 6
fill ~75 ~56 ~62 ~75 ~58 ~62 concrete 6
fill ~75 ~56 ~63 ~75 ~56 ~52 concrete 6
setblock ~80 ~56 ~8 planks 2
setblock ~80 ~56 ~9 sandstone
setblock ~80 ~56 ~10 planks 2
setblock ~81 ~56 ~11 sandstone
setblock ~32 ~57 ~8 sandstone
setblock ~32 ~57 ~9 planks 2
setblock ~33 ~57 ~5 end_stone
setblock ~33 ~57 ~6 sandstone
setblock ~33 ~57 ~7 end_stone
setblock ~34 ~57 ~4 sandstone
fill ~39 ~57 ~42 ~39 ~58 ~42 concrete 6
fill ~39 ~57 ~43 ~39 ~59 ~43 concrete 6
fill ~41 ~57 ~48 ~44 ~57 ~48 concrete 6
fill ~44 ~57 ~39 ~46 ~57 ~39 concrete 6
setblock ~44 ~57 ~49 concrete 6
setblock ~45 ~57 ~49 wool 6
fill ~46 ~57 ~49 ~47 ~57 ~49 concrete 6
fill ~47 ~57 ~48 ~48 ~57 ~48 concrete 6
fill ~48 ~57 ~41 ~48 ~60 ~41 concrete 6
setblock ~49 ~57 ~41 wool 6
setblock ~49 ~57 ~47 concrete 6
fill ~50 ~57 ~42 ~50 ~61 ~42 concrete 6
fill ~50 ~57 ~43 ~50 ~60 ~43 concrete 6
setblock ~63 ~57 ~47 end_stone
setblock ~63 ~57 ~48 sandstone
setblock ~63 ~57 ~49 end_stone
fill ~63 ~57 ~50 ~63 ~58 ~50 concrete 6
setblock ~64 ~57 ~47 planks 2
setblock ~65 ~57 ~46 sandstone
fill ~65 ~57 ~61 ~65 ~58 ~61 concrete 6
setblock ~66 ~57 ~45 planks 2
setblock ~66 ~57 ~46 end_stone
fill ~66 ~57 ~62 ~66 ~59 ~62 concrete 6
fill ~66 ~57 ~63 ~66 ~57 ~62 concrete 6
setblock ~67 ~57 ~45 end_stone
setblock ~67 ~57 ~64 concrete 6
fill ~68 ~57 ~44 ~69 ~57 ~44 sandstone
setblock ~68 ~57 ~65 concrete 6
fill ~69 ~57 ~66 ~69 ~58 ~66 concrete 6
setblock ~70 ~57 ~45 planks 2
fill ~70 ~57 ~67 ~70 ~69 ~67 concrete 6
setblock ~71 ~57 ~45 end_stone
setblock ~71 ~57 ~67 wool 6
setblock ~72 ~57 ~45 planks 2
fill ~72 ~57 ~46 ~73 ~57 ~46 sandstone
fill ~72 ~57 ~67 ~72 ~62 ~67 concrete 6
setblock ~73 ~57 ~47 end_stone
setblock ~73 ~57 ~48 sandstone
fill ~73 ~57 ~49 ~73 ~58 ~49 concrete 6
fill ~73 ~57 ~50 ~73 ~58 ~50 concrete 6
fill ~73 ~57 ~66 ~74 ~57 ~66 concrete 6
fill ~74 ~57 ~52 ~74 ~58 ~52 concrete 6
fill ~74 ~57 ~53 ~74 ~58 ~53 concrete 6
fill ~74 ~57 ~54 ~74 ~58 ~54 concrete 6
fill ~74 ~57 ~55 ~74 ~58 ~55 concrete 6
setblock ~75 ~57 ~59 wool 6
setblock ~75 ~57 ~63 wool 6
fill ~75 ~57 ~64 ~75 ~68 ~64 concrete 6
fill ~75 ~57 ~65 ~75 ~58 ~65 concrete 6
setblock ~79 ~57 ~6 sandstone
setblock ~79 ~57 ~7 end_stone
setblock ~80 ~57 ~8 sandstone
setblock ~80 ~57 ~9 planks 2
setblock ~80 ~57 ~10 sandstone
setblock ~81 ~57 ~11 end_stone
setblock ~32 ~58 ~8 concrete
fill ~32 ~58 ~9 ~32 ~61 ~9 iron_block
setblock ~33 ~58 ~5 sandstone
setblock ~33 ~58 ~6 planks 2
setblock ~33 ~58 ~7 sandstone
setblock ~34 ~58 ~3 sandstone
setblock ~34 ~58 ~4 planks 2
setblock ~35 ~58 ~2 planks 2
fill ~39 ~58 ~41 ~39 ~66 ~41 concrete 6
setblock ~40 ~58 ~40 concrete 6
fill ~40 ~58 ~47 ~40 ~58 ~48 concrete 6
fill ~41 ~58 ~49 ~43 ~58 ~49 concrete 6
fill ~43 ~58 ~50 ~46 ~58 ~50 concrete 6
fill ~44 ~58 ~39 ~46 ~58 ~39 concrete 6
fill ~47 ~58 ~49 ~48 ~58 ~49 concrete 6
fill ~49 ~58 ~41 ~49 ~60 ~41 concrete 6
fill ~49 ~58 ~48 ~49 ~59 ~48 concrete 6
fill ~50 ~58 ~47 ~50 ~59 ~47 concrete 6
fill ~51 ~58 ~46 ~51 ~61 ~46 concrete 6
fill ~63 ~58 ~48 ~64 ~58 ~48 planks 2
fill ~63 ~58 ~49 ~64 ~58 ~49 sandstone
fill ~64 ~58 ~54 ~64 ~59 ~54 concrete 6
fill ~65 ~58 ~47 ~66 ~58 ~47 sandstone
fill ~65 ~58 ~63 ~65 ~60 ~63 concrete 6
setblock ~66 ~58 ~64 concrete 6
setblock ~67 ~58 ~46 planks 2
fill ~67 ~58 ~65 ~67 ~60 ~65 concrete 6
fill ~68 ~58 ~45 ~70 ~58 ~45 sandstone
fill ~68 ~58 ~66 ~68 ~63 ~66 concrete 6
fill ~70 ~58 ~46 ~71 ~58 ~46 planks 2
fill ~71 ~58 ~67 ~71 ~60 ~67 concrete 6
fill ~72 ~58 ~47 ~73 ~58 ~47 sandstone
setblock ~72 ~58 ~48 concrete 6
fill ~73 ~58 ~51 ~73 ~59 ~51 concrete 6
fill ~73 ~58 ~66 ~74 ~58 ~66 concrete 6
fill ~74 ~58 ~56 ~74 ~58 ~60 concrete 6
fill ~75 ~58 ~63 ~75 ~60 ~63 concrete 6
setblock ~78 ~58 ~4 planks 2
setblock ~79 ~58 ~5 sandstone
setblock ~79 ~58 ~6 planks 2
setblock ~79 ~58 ~7 sandstone
setblock ~80 ~58 ~8 planks 2
setblock ~80 ~58 ~9 sandstone
setblock ~80 ~58 ~10 concrete
setblock ~81 ~58 ~11 wool
setblock ~81 ~58 ~12 iron_block
setblock ~32 ~59 ~8 wool
setblock ~32 ~59 ~10 wool
setblock ~33 ~59 ~5 end_stone
fill ~33 ~59 ~6 ~33 ~59 ~7 wool
setblock ~34 ~59 ~3 planks 2
setblock ~34 ~59 ~4 sandstone
fill ~35 ~59 ~2 ~36 ~59 ~2 sandstone
fill ~38 ~59 ~42 ~38 ~65 ~42 concrete 6
fill ~39 ~59 ~46 ~39 ~59 ~47 concrete 6
setblock ~40 ~59 ~41 concrete 6
fill ~40 ~59 ~48 ~40 ~59 ~49 concrete 6
fill ~41 ~59 ~50 ~42 ~59 ~50 concrete 6
fill ~42 ~59 ~51 ~46 ~59 ~51 concrete 6
fill ~44 ~59 ~39 ~46 ~59 ~39 concrete 6
setblock ~47 ~59 ~50 concrete 6
setblock ~48 ~59 ~9 planks 2
setblock ~48 ~59 ~49 concrete 6
setblock ~51 ~59 ~12 sandstone
setblock ~51 ~59 ~13 end_stone
fill ~51 ~59 ~45 ~51 ~63 ~45 concrete 6
setblock ~52 ~59 ~14 sandstone
setblock ~53 ~59 ~13 end_stone
setblock ~54 ~59 ~13 planks 2
setblock ~55 ~59 ~12 sandstone
setblock ~57 ~59 ~12 sandstone
setblock ~58 ~59 ~13 planks 2
setblock ~59 ~59 ~13 end_stone
setblock ~60 ~59 ~13 planks 2
setblock ~60 ~59 ~14 sandstone
setblock ~61 ~59 ~12 sandstone
fill ~64 ~59 ~50 ~66 ~59 ~50 concrete 6
fill ~64 ~59 ~51 ~65 ~59 ~51 concrete 6
fill ~64 ~59 ~52 ~64 ~59 ~57 concrete 6
fill ~65 ~59 ~48 ~68 ~59 ~48 sandstone
fill ~65 ~59 ~49 ~67 ~59 ~49 concrete 6
fill ~65 ~59 ~58 ~65 ~60 ~58 concrete 6
fill ~65 ~59 ~64 ~65 ~62 ~64 concrete 6
setblock ~66 ~59 ~61 concrete 6
fill ~66 ~59 ~65 ~66 ~62 ~65 concrete 6
setblock ~67 ~59 ~47 end_stone
fill ~68 ~59 ~46 ~69 ~59 ~46 sandstone
setblock ~69 ~59 ~67 concrete 6
setblock ~70 ~59 ~47 planks 2
fill ~70 ~59 ~48 ~71 ~59 ~48 concrete 6
setblock ~71 ~59 ~47 end_stone
fill ~71 ~59 ~49 ~72 ~59 ~49 concrete 6
fill ~71 ~59 ~50 ~72 ~59 ~50 concrete 6
setblock ~72 ~59 ~51 concrete 6
fill ~73 ~59 ~52 ~73 ~59 ~58 concrete 6
fill ~73 ~59 ~66 ~74 ~59 ~66 concrete 6
fill ~74 ~59 ~59 ~74 ~59 ~62 concrete 6
fill ~74 ~59 ~65 ~74 ~69 ~65 concrete 6
setblock ~76 ~59 ~3 planks 2
setblock ~77 ~59 ~4 sandstone
setblock ~78 ~59 ~5 planks 2
setblock ~79 ~59 ~5 end_stone
setblock ~79 ~59 ~6 sandstone
setblock ~79 ~59 ~7 end_stone
setblock ~80 ~59 ~8 wool
fill ~80 ~59 ~9 ~80 ~61 ~9 iron_block
setblock ~80 ~59 ~10 wool
fill ~80 ~59 ~11 ~80 ~61 ~11 iron_block
setblock ~81 ~59 ~12 wool
setblock ~31 ~60 ~11 wool
setblock ~32 ~60 ~10 concrete
setblock ~33 ~60 ~6 iron_block
fill ~33 ~60 ~7 ~33 ~62 ~7 wool
setblock ~33 ~60 ~8 iron_block
setblock ~34 ~60 ~4 log 2
setblock ~34 ~60 ~5 quartz_block
setblock ~35 ~60 ~3 sandstone
fill ~36 ~60 ~2 ~37 ~60 ~2 planks 2
fill ~38 ~60 ~1 ~39 ~60 ~1 sandstone
fill ~38 ~60 ~43 ~38 ~62 ~43 concrete 6
fill ~38 ~60 ~44 ~38 ~62 ~44 concrete 6
fill ~38 ~60 ~45 ~38 ~62 ~45 concrete 6
fill ~38 ~60 ~46 ~38 ~72 ~46 concrete 6
fill ~38 ~60 ~47 ~38 ~71 ~47 concrete 6
fill ~39 ~60 ~48 ~39 ~60 ~49 concrete 6
fill ~40 ~60 ~40 ~40 ~68 ~40 concrete 6
fill ~40 ~60 ~50 ~40 ~63 ~50 concrete 6
fill ~41 ~60 ~39 ~41 ~71 ~39 concrete 6
fill ~41 ~60 ~51 ~47 ~60 ~51 concrete 6
setblock ~42 ~60 ~3 sandstone
setblock ~43 ~60 ~4 planks 2
fill ~44 ~60 ~39 ~46 ~60 ~39 concrete 6
setblock ~46 ~60 ~6 planks 2
setblock ~46 ~60 ~7 sandstone
setblock ~46 ~60 ~8 planks 2
fill ~46 ~60 ~9 ~47 ~60 ~9 sandstone
fill ~48 ~60 ~10 ~50 ~60 ~10 planks 2
fill ~48 ~60 ~50 ~48 ~61 ~50 concrete 6
setblock ~49 ~60 ~49 concrete 6
setblock ~50 ~60 ~11 sandstone
setblock ~50 ~60 ~12 planks 2
fill ~50 ~60 ~48 ~50 ~61 ~48 concrete 6
setblock ~51 ~60 ~13 sandstone
fill ~51 ~60 ~14 ~54 ~60 ~14 planks 2
fill ~51 ~60 ~44 ~51 ~64 ~44 concrete 6
fill ~51 ~60 ~47 ~51 ~61 ~47 concrete 6
fill ~55 ~60 ~13 ~57 ~60 ~13 sandstone
setblock ~56 ~60 ~12 planks 2
fill ~58 ~60 ~14 ~61 ~60 ~14 planks 2
setblock ~61 ~60 ~12 planks 2
setblock ~61 ~60 ~13 sandstone
fill ~62 ~60 ~10 ~66 ~60 ~10 planks 2
setblock ~62 ~60 ~11 sandstone
fill ~64 ~60 ~64 ~64 ~61 ~64 concrete 6
fill ~65 ~60 ~52 ~67 ~60 ~52 concrete 6
fill ~65 ~60 ~53 ~67 ~60 ~53 concrete 6
fill ~65 ~60 ~54 ~67 ~60 ~54 concrete 6
fill ~65 ~60 ~55 ~67 ~60 ~55 concrete 6
fill ~65 ~60 ~56 ~67 ~60 ~56 concrete 6
fill ~65 ~60 ~57 ~67 ~60 ~57 concrete 6
fill ~65 ~60 ~61 ~65 ~61 ~61 concrete 6
fill ~65 ~60 ~62 ~65 ~60 ~61 concrete 6
setblock ~66 ~60 ~8 planks 2
setblock ~66 ~60 ~9 sandstone
fill ~66 ~60 ~51 ~68 ~60 ~51 concrete 6
fill ~66 ~60 ~58 ~67 ~60 ~58 concrete 6
fill ~66 ~60 ~59 ~67 ~60 ~59 concrete 6
fill ~66 ~60 ~60 ~68 ~60 ~60 concrete 6
setblock ~67 ~60 ~6 planks 2
setblock ~67 ~60 ~7 sandstone
fill ~67 ~60 ~50 ~70 ~60 ~50 concrete 6
setblock ~67 ~60 ~61 concrete 6
setblock ~68 ~60 ~47 planks 2
fill ~68 ~60 ~49 ~70 ~60 ~49 concrete 6
setblock ~69 ~60 ~47 sandstone
setblock ~69 ~60 ~48 concrete 6
fill ~69 ~60 ~66 ~69 ~63 ~66 concrete 6
fill ~70 ~60 ~5 ~71 ~60 ~5 sandstone
fill ~70 ~60 ~51 ~71 ~60 ~51 concrete 6
setblock ~71 ~60 ~4 planks 2
fill ~71 ~60 ~52 ~72 ~60 ~52 concrete 6
fill ~71 ~60 ~53 ~72 ~60 ~53 concrete 6
fill ~71 ~60 ~54 ~72 ~60 ~54 concrete 6
fill ~71 ~60 ~55 ~73 ~60 ~55 concrete 6
fill ~72 ~60 ~56 ~73 ~60 ~56 concrete 6
fill ~73 ~60 ~57 ~73 ~60 ~61 concrete 6
fill ~73 ~60 ~66 ~74 ~60 ~66 concrete 6
fill ~74 ~60 ~3 ~75 ~60 ~3 sandstone
fill ~74 ~60 ~61 ~74 ~61 ~61 concrete 6
fill ~74 ~60 ~62 ~75 ~60 ~62 concrete 6
setblock ~76 ~60 ~4 planks 2
fill ~77 ~60 ~5 ~78 ~60 ~5 sandstone
setblock ~79 ~60 ~6 iron_block
fill ~79 ~60 ~7 ~79 ~61 ~7 wool
setblock ~79 ~60 ~8 iron_block
setblock ~80 ~60 ~10 concrete
setblock ~81 ~60 ~12 iron_block
fill ~81 ~60 ~13 ~81 ~62 ~13 wool
setblock ~31 ~61 ~12 wool
setblock ~32 ~61 ~10 wool
setblock ~32 ~61 ~11 iron_block
setblock ~33 ~61 ~6 wool
setblock ~33 ~61 ~8 wool
fill ~34 ~61 ~4 ~35 ~61 ~4 wool
setblock ~34 ~61 ~5 iron_block
setblock ~36 ~61 ~3 planks 2
setblock ~37 ~61 ~3 end_stone
setblock ~38 ~61 ~2 end_stone
fill ~38 ~61 ~48 ~38 ~71 ~48 concrete 6
setblock ~39 ~61 ~2 sandstone
fill ~39 ~61 ~49 ~39 ~63 ~49 concrete 6
setblock ~40 ~61 ~1 planks 2
setblock ~41 ~61 ~1 end_stone
setblock ~41 ~61 ~2 sandstone
setblock ~41 ~61 ~3 end_stone
fill ~41 ~61 ~51 ~42 ~61 ~51 concrete 6
setblock ~42 ~61 ~4 sandstone
setblock ~43 ~61 ~5 end_stone
fill ~43 ~61 ~52 ~46 ~61 ~52 concrete 6
setblock ~44 ~61 ~5 planks 2
fill ~44 ~61 ~39 ~46 ~61 ~39 concrete 6
setblock ~45 ~61 ~5 end_stone
setblock ~45 ~61 ~6 sandstone
setblock ~46 ~61 ~7 planks 2
setblock ~46 ~61 ~8 sandstone
setblock ~46 ~61 ~9 planks 2
setblock ~46 ~61 ~10 quartz_block 1
setblock ~47 ~61 ~10 sandstone
setblock ~47 ~61 ~51 concrete 6
setblock ~48 ~61 ~11 log 2
fill ~48 ~61 ~40 ~48 ~64 ~40 concrete 6
setblock ~49 ~61 ~11 end_stone
setblock ~49 ~61 ~41 wool 6
setblock ~49 ~61 ~49 wool 6
setblock ~50 ~61 ~11 planks 2
setblock ~50 ~61 ~12 sandstone
setblock ~50 ~61 ~13 iron_block
fill ~51 ~61 ~14 ~51 ~61 ~15 wool
fill ~51 ~61 ~42 ~51 ~66 ~42 concrete 6
fill ~51 ~61 ~43 ~51 ~65 ~43 concrete 6
setblock ~52 ~61 ~15 iron_block
setblock ~53 ~61 ~15 wool
fill ~54 ~61 ~14 ~55 ~61 ~14 wool
fill ~56 ~61 ~14 ~57 ~61 ~14 bone_block
setblock ~58 ~61 ~14 wool
setblock ~58 ~61 ~15 iron_block
setblock ~59 ~61 ~15 wool
setblock ~60 ~61 ~15 iron_block
fill ~61 ~61 ~14 ~61 ~61 ~15 wool
setblock ~62 ~61 ~12 sandstone
setblock ~62 ~61 ~13 iron_block
setblock ~63 ~61 ~11 end_stone
setblock ~64 ~61 ~11 planks 2
fill ~64 ~61 ~62 ~64 ~61 ~64 concrete 6
setblock ~65 ~61 ~11 bone_block
setblock ~65 ~61 ~60 concrete 6
setblock ~66 ~61 ~10 end_stone
setblock ~66 ~61 ~11 iron_block
fill ~66 ~61 ~59 ~66 ~60 ~59 concrete 6
setblock ~67 ~61 ~7 end_stone
setblock ~67 ~61 ~8 sandstone
setblock ~67 ~61 ~9 end_stone
setblock ~67 ~61 ~59 wool 6
fill ~67 ~61 ~66 ~67 ~64 ~66 concrete 6
fill ~68 ~61 ~6 ~69 ~61 ~6 sandstone
fill ~68 ~61 ~52 ~70 ~61 ~52 concrete 6
fill ~68 ~61 ~53 ~70 ~61 ~53 concrete 6
fill ~68 ~61 ~54 ~70 ~61 ~54 concrete 6
fill ~68 ~61 ~55 ~70 ~61 ~55 concrete 6
fill ~68 ~61 ~56 ~71 ~61 ~56 concrete 6
fill ~68 ~61 ~57 ~72 ~61 ~57 concrete 6
fill ~68 ~61 ~58 ~72 ~61 ~58 concrete 6
fill ~68 ~61 ~59 ~70 ~61 ~59 concrete 6
fill ~68 ~61 ~60 ~74 ~61 ~60 concrete 6
setblock ~69 ~61 ~51 concrete 6
setblock ~70 ~61 ~6 end_stone
setblock ~71 ~61 ~5 end_stone
setblock ~71 ~61 ~6 sandstone
setblock ~71 ~61 ~59 wool 6
setblock ~71 ~61 ~67 wool 6
setblock ~72 ~61 ~3 planks 2
setblock ~72 ~61 ~4 sandstone
setblock ~72 ~61 ~59 concrete 6
fill ~72 ~61 ~61 ~74 ~61 ~61 concrete 6
setblock ~73 ~61 ~3 end_stone
fill ~73 ~61 ~66 ~74 ~61 ~66 concrete 6
setblock ~74 ~61 ~3 planks 2
setblock ~75 ~61 ~4 sandstone
fill ~75 ~61 ~62 ~75 ~62 ~62 concrete 6
setblock ~75 ~61 ~63 wool 6
setblock ~76 ~61 ~5 planks 2
setblock ~77 ~61 ~5 quartz_block 1
setblock ~78 ~61 ~6 wool
setblock ~79 ~61 ~8 wool
setblock ~80 ~61 ~10 wool
setblock ~80 ~61 ~12 wool
setblock ~31 ~62 ~12 iron_block
setblock ~32 ~62 ~10 concrete
setblock ~32 ~62 ~11 quartz_block
setblock ~33 ~62 ~8 iron_block
fill ~33 ~62 ~9 ~33 ~64 ~9 wool
fill ~34 ~62 ~5 ~35 ~62 ~5 wool
setblock ~34 ~62 ~6 iron_block
setblock ~36 ~62 ~4 concrete
setblock ~37 ~62 ~4 iron_block
setblock ~38 ~62 ~3 bone_block
fill ~39 ~62 ~2 ~40 ~62 ~2 planks 2
setblock ~41 ~62 ~3 sandstone
setblock ~41 ~62 ~4 planks 2
setblock ~41 ~62 ~5 end_bricks
fill ~41 ~62 ~51 ~41 ~63 ~51 concrete 6
setblock ~42 ~62 ~5 sandstone
setblock ~42 ~62 ~6 log 2
fill ~42 ~62 ~52 ~47 ~62 ~52 concrete 6
fill ~43 ~62 ~6 ~44 ~62 ~6 planks 2
setblock ~44 ~62 ~7 quartz_block
fill ~44 ~62 ~39 ~47 ~62 ~39 concrete 6
setblock ~45 ~62 ~7 sandstone
setblock ~45 ~62 ~8 iron_block
fill ~45 ~62 ~9 ~45 ~63 ~9 wool
fill ~46 ~62 ~10 ~46 ~62 ~11 iron_block
setblock ~46 ~62 ~12 concrete
setblock ~47 ~62 ~11 wool
setblock ~47 ~62 ~12 iron_block
setblock ~48 ~62 ~12 concrete
fill ~48 ~62 ~51 ~48 ~63 ~51 concrete 6
setblock ~49 ~62 ~12 iron_block
fill ~49 ~62 ~41 ~50 ~62 ~41 concrete 6
fill ~49 ~62 ~50 ~49 ~63 ~50 concrete 6
setblock ~50 ~62 ~13 wool
fill ~50 ~62 ~14 ~50 ~62 ~15 iron_block
fill ~50 ~62 ~49 ~50 ~63 ~49 concrete 6
setblock ~51 ~62 ~16 iron_block
fill ~51 ~62 ~48 ~51 ~64 ~48 concrete 6
setblock ~52 ~62 ~16 concrete
fill ~52 ~62 ~46 ~52 ~68 ~46 concrete 6
fill ~52 ~62 ~47 ~52 ~68 ~47 concrete 6
setblock ~53 ~62 ~16 iron_block
setblock ~54 ~62 ~15 iron_block
setblock ~54 ~62 ~16 concrete
setblock ~55 ~62 ~15 wool
setblock ~56 ~62 ~15 quartz_block
setblock ~57 ~62 ~15 wool
setblock ~58 ~62 ~16 concrete
setblock ~59 ~62 ~16 iron_block
setblock ~60 ~62 ~16 concrete
setblock ~61 ~62 ~15 wool
setblock ~61 ~62 ~16 iron_block
setblock ~62 ~62 ~13 wool
setblock ~62 ~62 ~14 iron_block
setblock ~63 ~62 ~12 iron_block
fill ~63 ~62 ~62 ~63 ~66 ~62 concrete 6
setblock ~64 ~62 ~12 concrete
fill ~64 ~62 ~59 ~64 ~63 ~59 concrete 6
fill ~64 ~62 ~60 ~64 ~62 ~61 concrete 6
setblock ~64 ~62 ~63 concrete 6
setblock ~65 ~62 ~12 iron_block
fill ~65 ~62 ~58 ~68 ~62 ~58 concrete 6
setblock ~66 ~62 ~12 concrete
fill ~66 ~62 ~57 ~71 ~62 ~57 concrete 6
setblock ~67 ~62 ~9 wool
setblock ~67 ~62 ~10 iron_block
fill ~67 ~62 ~11 ~67 ~63 ~11 wool
setblock ~68 ~62 ~7 log 2
setblock ~68 ~62 ~8 concrete
setblock ~69 ~62 ~7 bone_block
setblock ~70 ~62 ~7 iron_block
setblock ~71 ~62 ~7 wool
fill ~71 ~62 ~58 ~72 ~62 ~58 concrete 6
fill ~71 ~62 ~67 ~71 ~64 ~67 concrete 6
setblock ~72 ~62 ~5 sandstone
setblock ~72 ~62 ~6 concrete
setblock ~73 ~62 ~3 sandstone
fill ~73 ~62 ~4 ~74 ~62 ~4 planks 2
fill ~73 ~62 ~59 ~74 ~62 ~59 concrete 6
fill ~73 ~62 ~66 ~73 ~63 ~66 concrete 6
setblock ~74 ~62 ~60 concrete 6
fill ~75 ~62 ~5 ~75 ~63 ~5 wool
fill ~75 ~62 ~61 ~75 ~63 ~61 concrete 6
fill ~75 ~62 ~63 ~75 ~64 ~63 concrete 6
setblock ~76 ~62 ~5 iron_block
setblock ~77 ~62 ~6 iron_block
setblock ~78 ~62 ~7 iron_block
setblock ~79 ~62 ~8 iron_block
fill ~79 ~62 ~9 ~79 ~64 ~9 wool
setblock ~80 ~62 ~10 concrete
setblock ~80 ~62 ~11 quartz_block
setblock ~80 ~62 ~12 concrete
setblock ~81 ~62 ~14 iron_block
setblock ~31 ~63 ~13 wool
setblock ~32 ~63 ~10 wool
fill ~32 ~63 ~11 ~32 ~64 ~11 iron_block
setblock ~32 ~63 ~12 wool
setblock ~33 ~63 ~8 wool
fill ~34 ~63 ~6 ~35 ~63 ~6 wool
fill ~34 ~63 ~7 ~34 ~64 ~7 iron_block
setblock ~36 ~63 ~5 iron_block
setblock ~37 ~63 ~5 wool
fill ~37 ~63 ~43 ~37 ~63 ~45 concrete 6
setblock ~38 ~63 ~4 wool
setblock ~39 ~63 ~3 wool
fill ~39 ~63 ~50 ~39 ~75 ~50 concrete 6
setblock ~40 ~63 ~3 log 2
setblock ~40 ~63 ~4 wool
fill ~40 ~63 ~5 ~40 ~64 ~5 iron_block
fill ~41 ~63 ~6 ~41 ~63 ~7 wool
setblock ~42 ~63 ~7 iron_block
fill ~42 ~63 ~52 ~47 ~63 ~52 concrete 6
fill ~43 ~63 ~7 ~43 ~63 ~8 wool
fill ~44 ~63 ~8 ~45 ~63 ~8 wool
fill ~44 ~63 ~38 ~45 ~63 ~38 concrete 6
fill ~45 ~63 ~10 ~45 ~63 ~11 wool
setblock ~46 ~63 ~12 wool
setblock ~46 ~63 ~13 iron_block
setblock ~47 ~63 ~13 wool
fill ~47 ~63 ~39 ~47 ~65 ~39 concrete 6
setblock ~48 ~63 ~13 iron_block
fill ~49 ~63 ~13 ~49 ~63 ~14 wool
fill ~49 ~63 ~40 ~49 ~67 ~40 concrete 6
setblock ~50 ~63 ~15 iron_block
setblock ~50 ~63 ~16 wool
fill ~50 ~63 ~41 ~50 ~66 ~41 concrete 6
setblock ~51 ~63 ~17 wool
setblock ~52 ~63 ~17 iron_block
setblock ~53 ~63 ~17 wool
setblock ~54 ~63 ~17 iron_block
fill ~55 ~63 ~16 ~57 ~63 ~16 wool
setblock ~57 ~63 ~17 wool
setblock ~58 ~63 ~17 iron_block
setblock ~59 ~63 ~17 wool
setblock ~60 ~63 ~17 iron_block
fill ~61 ~63 ~16 ~61 ~63 ~17 wool
setblock ~62 ~63 ~14 wool
setblock ~62 ~63 ~15 iron_block
setblock ~63 ~63 ~13 wool
fill ~63 ~63 ~60 ~63 ~63 ~63 concrete 6
setblock ~64 ~63 ~13 iron_block
fill ~64 ~63 ~57 ~65 ~63 ~57 concrete 6
fill ~64 ~63 ~58 ~64 ~63 ~57 concrete 6
fill ~64 ~63 ~64 ~64 ~67 ~64 concrete 6
setblock ~65 ~63 ~13 wool
fill ~65 ~63 ~56 ~71 ~63 ~56 concrete 6
fill ~65 ~63 ~65 ~65 ~65 ~65 concrete 6
setblock ~66 ~63 ~13 iron_block
fill ~66 ~63 ~66 ~66 ~65 ~66 concrete 6
setblock ~67 ~63 ~12 wool
setblock ~68 ~63 ~9 iron_block
setblock ~68 ~63 ~10 wool
fill ~69 ~63 ~8 ~71 ~63 ~8 wool
setblock ~72 ~63 ~7 iron_block
setblock ~72 ~63 ~57 concrete 6
fill ~72 ~63 ~66 ~72 ~69 ~66 concrete 6
fill ~73 ~63 ~5 ~73 ~63 ~6 wool
fill ~73 ~63 ~58 ~74 ~63 ~58 concrete 6
setblock ~74 ~63 ~5 iron_block
fill ~75 ~63 ~59 ~75 ~64 ~59 concrete 6
fill ~75 ~63 ~60 ~75 ~64 ~60 concrete 6
setblock ~76 ~63 ~6 wool
fill ~76 ~63 ~62 ~76 ~67 ~62 concrete 6
setblock ~77 ~63 ~7 wool
setblock ~78 ~63 ~8 wool
setblock ~80 ~63 ~10 wool
fill ~80 ~63 ~11 ~80 ~64 ~11 iron_block
setblock ~80 ~63 ~12 wool
fill ~80 ~63 ~13 ~80 ~67 ~13 iron_block
setblock ~81 ~63 ~14 wool
setblock ~31 ~64 ~14 iron_block
setblock ~32 ~64 ~12 concrete
fill ~32 ~64 ~13 ~32 ~67 ~13 iron_block
setblock ~33 ~64 ~8 iron_block
setblock ~33 ~64 ~10 iron_block
setblock ~35 ~64 ~7 wool
setblock ~36 ~64 ~6 concrete
setblock ~37 ~64 ~6 iron_block
fill ~37 ~64 ~44 ~37 ~67 ~44 concrete 6
fill ~37 ~64 ~45 ~37 ~64 ~44 concrete 6
setblock ~38 ~64 ~5 quartz_block
fill ~38 ~64 ~43 ~38 ~70 ~43 concrete 6
fill ~38 ~64 ~49 ~38 ~71 ~49 concrete 6
setblock ~39 ~64 ~4 iron_block
setblock ~40 ~64 ~6 concrete
fill ~40 ~64 ~51 ~40 ~70 ~51 concrete 6
setblock ~41 ~64 ~7 wool
setblock ~41 ~64 ~8 iron_block
fill ~41 ~64 ~52 ~41 ~70 ~52 concrete 6
setblock ~42 ~64 ~8 concrete
setblock ~42 ~64 ~9 quartz_block
fill ~42 ~64 ~53 ~47 ~64 ~53 concrete 6
setblock ~43 ~64 ~9 wool
setblock ~44 ~64 ~9 iron_block
fill ~44 ~64 ~38 ~46 ~64 ~38 concrete 6
setblock ~45 ~64 ~10 iron_block
setblock ~45 ~64 ~11 wool
setblock ~45 ~64 ~12 iron_block
setblock ~45 ~64 ~13 wool
setblock ~46 ~64 ~14 concrete
setblock ~47 ~64 ~14 iron_block
setblock ~48 ~64 ~14 concrete
fill ~48 ~64 ~52 ~48 ~66 ~52 concrete 6
setblock ~49 ~64 ~14 iron_block
setblock ~49 ~64 ~15 wool
fill ~49 ~64 ~51 ~49 ~66 ~51 concrete 6
setblock ~50 ~64 ~16 concrete
setblock ~50 ~64 ~17 quartz_block
fill ~50 ~64 ~50 ~50 ~67 ~50 concrete 6
setblock ~51 ~64 ~18 iron_block
fill ~51 ~64 ~49 ~51 ~67 ~49 concrete 6
setblock ~52 ~64 ~18 concrete
fill ~52 ~64 ~45 ~52 ~69 ~45 concrete 6
setblock ~53 ~64 ~18 iron_block
setblock ~54 ~64 ~18 concrete
setblock ~55 ~64 ~17 wool
setblock ~55 ~64 ~18 iron_block
setblock ~56 ~64 ~17 iron_block
setblock ~57 ~64 ~18 iron_block
setblock ~58 ~64 ~18 concrete
setblock ~59 ~64 ~18 iron_block
setblock ~60 ~64 ~18 concrete
setblock ~61 ~64 ~17 wool
setblock ~62 ~64 ~16 concrete
setblock ~62 ~64 ~17 quartz_block
fill ~62 ~64 ~60 ~62 ~71 ~60 concrete 6
fill ~62 ~64 ~61 ~62 ~75 ~61 concrete 6
setblock ~63 ~64 ~14 iron_block
setblock ~63 ~64 ~15 wool
fill ~63 ~64 ~58 ~63 ~64 ~59 concrete 6
setblock ~63 ~64 ~63 concrete 6
setblock ~64 ~64 ~14 concrete
setblock ~64 ~64 ~15 iron_block
fill ~64 ~64 ~56 ~64 ~64 ~57 concrete 6
setblock ~65 ~64 ~14 iron_block
setblock ~65 ~64 ~15 wool
fill ~65 ~64 ~55 ~71 ~64 ~55 concrete 6
setblock ~66 ~64 ~14 concrete
setblock ~66 ~64 ~15 iron_block
setblock ~67 ~64 ~12 iron_block
setblock ~67 ~64 ~13 wool
setblock ~67 ~64 ~14 iron_block
setblock ~68 ~64 ~10 concrete
fill ~68 ~64 ~11 ~68 ~65 ~11 iron_block
fill ~68 ~64 ~67 ~71 ~64 ~67 concrete 6
setblock ~69 ~64 ~9 wool
fill ~69 ~64 ~54 ~70 ~64 ~54 concrete 6
setblock ~70 ~64 ~9 quartz_block
setblock ~71 ~64 ~9 wool
setblock ~72 ~64 ~8 concrete
setblock ~72 ~64 ~56 concrete 6
setblock ~73 ~64 ~6 iron_block
fill ~73 ~64 ~7 ~73 ~65 ~7 wool
fill ~73 ~64 ~57 ~74 ~64 ~57 concrete 6
fill ~73 ~64 ~65 ~73 ~65 ~65 concrete 6
setblock ~74 ~64 ~6 concrete
setblock ~75 ~64 ~6 iron_block
fill ~75 ~64 ~58 ~75 ~74 ~58 concrete 6
setblock ~76 ~64 ~7 iron_block
fill ~76 ~64 ~61 ~76 ~69 ~61 concrete 6
setblock ~77 ~64 ~8 iron_block
setblock ~78 ~64 ~9 quartz_block
setblock ~79 ~64 ~10 iron_block
setblock ~80 ~64 ~12 concrete
setblock ~81 ~64 ~14 iron_block
fill ~81 ~64 ~15 ~81 ~67 ~15 wool
fill ~31 ~65 ~14 ~31 ~65 ~15 wool
setblock ~32 ~65 ~12 wool
setblock ~33 ~65 ~9 snow
fill ~33 ~65 ~10 ~33 ~65 ~11 wool
fill ~34 ~65 ~8 ~35 ~65 ~8 wool
setblock ~36 ~65 ~7 iron_block
setblock ~37 ~65 ~7 wool
setblock ~37 ~65 ~45 wool 6
setblock ~38 ~65 ~6 wool
setblock ~39 ~65 ~5 wool
setblock ~40 ~65 ~6 wool
setblock ~40 ~65 ~7 iron_block
setblock ~40 ~65 ~8 wool
setblock ~41 ~65 ~9 snow
fill ~42 ~65 ~10 ~44 ~65 ~10 wool
fill ~42 ~65 ~53 ~47 ~65 ~53 concrete 6
fill ~43 ~65 ~38 ~46 ~65 ~38 concrete 6
setblock ~44 ~65 ~11 iron_block
setblock ~45 ~65 ~12 wool
setblock ~45 ~65 ~13 snow
fill ~45 ~65 ~14 ~45 ~65 ~15 wool
setblock ~46 ~65 ~15 iron_block
setblock ~47 ~65 ~15 wool
setblock ~48 ~65 ~15 iron_block
fill ~48 ~65 ~16 ~49 ~65 ~16 wool
fill ~48 ~65 ~39 ~48 ~68 ~39 concrete 6
setblock ~50 ~65 ~17 iron_block
fill ~50 ~65 ~18 ~51 ~65 ~18 wool
fill ~51 ~65 ~41 ~51 ~69 ~41 concrete 6
setblock ~52 ~65 ~19 iron_block
fill ~52 ~65 ~44 ~52 ~69 ~44 concrete 6
fill ~52 ~65 ~48 ~52 ~68 ~48 concrete 6
setblock ~53 ~65 ~19 wool
setblock ~54 ~65 ~19 iron_block
setblock ~55 ~65 ~19 wool
setblock ~56 ~65 ~18 wool
setblock ~57 ~65 ~19 wool
setblock ~58 ~65 ~19 iron_block
setblock ~59 ~65 ~19 wool
setblock ~60 ~65 ~19 iron_block
fill ~61 ~65 ~18 ~62 ~65 ~18 wool
setblock ~62 ~65 ~17 iron_block
fill ~62 ~65 ~58 ~62 ~66 ~58 concrete 6
fill ~62 ~65 ~59 ~62 ~65 ~58 concrete 6
fill ~63 ~65 ~16 ~66 ~65 ~16 wool
fill ~63 ~65 ~56 ~63 ~66 ~56 concrete 6
fill ~63 ~65 ~57 ~63 ~65 ~56 concrete 6
setblock ~63 ~65 ~63 wool 6
setblock ~64 ~65 ~55 concrete 6
fill ~65 ~65 ~54 ~68 ~65 ~54 concrete 6
fill ~65 ~65 ~66 ~65 ~70 ~66 concrete 6
fill ~67 ~65 ~14 ~67 ~65 ~15 wool
setblock ~67 ~65 ~67 wool 6
setblock ~68 ~65 ~12 wool
fill ~68 ~65 ~13 ~68 ~66 ~13 iron_block
fill ~68 ~65 ~67 ~70 ~65 ~67 concrete 6
fill ~69 ~65 ~10 ~72 ~65 ~10 wool
fill ~69 ~65 ~11 ~69 ~65 ~10 wool
fill ~69 ~65 ~53 ~70 ~65 ~53 concrete 6
setblock ~71 ~65 ~54 concrete 6
setblock ~71 ~65 ~67 wool 6
setblock ~72 ~65 ~9 iron_block
setblock ~72 ~65 ~55 concrete 6
setblock ~73 ~65 ~8 wool
fill ~73 ~65 ~56 ~74 ~65 ~56 concrete 6
setblock ~74 ~65 ~7 iron_block
setblock ~75 ~65 ~7 wool
fill ~75 ~65 ~57 ~75 ~74 ~57 concrete 6
setblock ~75 ~65 ~59 wool 6
setblock ~75 ~65 ~63 wool 6
setblock ~76 ~65 ~8 wool
fill ~76 ~65 ~60 ~76 ~71 ~60 concrete 6
fill ~77 ~65 ~9 ~77 ~66 ~9 wool
setblock ~78 ~65 ~9 iron_block
fill ~79 ~65 ~10 ~79 ~65 ~11 wool
setblock ~80 ~65 ~12 wool
setblock ~80 ~65 ~14 wool
fill ~31 ~66 ~15 ~31 ~67 ~15 wool
setblock ~32 ~66 ~12 concrete
setblock ~32 ~66 ~14 concrete
setblock ~33 ~66 ~10 iron_block
fill ~33 ~66 ~11 ~33 ~67 ~11 wool
fill ~34 ~66 ~9 ~35 ~66 ~9 wool
setblock ~36 ~66 ~8 concrete
setblock ~37 ~66 ~8 iron_block
setblock ~37 ~66 ~45 concrete 6
setblock ~38 ~66 ~7 iron_block
setblock ~39 ~66 ~6 iron_block
setblock ~39 ~66 ~7 wool
fill ~39 ~66 ~42 ~39 ~71 ~42 concrete 6
setblock ~40 ~66 ~8 concrete
setblock ~40 ~66 ~9 iron_block
setblock ~40 ~66 ~10 concrete
setblock ~41 ~66 ~10 iron_block
setblock ~41 ~66 ~11 wool
setblock ~42 ~66 ~11 iron_block
fill ~42 ~66 ~53 ~47 ~66 ~53 concrete 6
setblock ~43 ~66 ~11 wool
setblock ~43 ~66 ~12 iron_block
fill ~43 ~66 ~38 ~47 ~66 ~38 concrete 6
setblock ~44 ~66 ~12 concrete
setblock ~44 ~66 ~13 iron_block
setblock ~45 ~66 ~14 iron_block
setblock ~45 ~66 ~15 wool
setblock ~45 ~66 ~16 iron_block
setblock ~46 ~66 ~16 concrete
fill ~46 ~66 ~17 ~47 ~66 ~17 wool
setblock ~47 ~66 ~16 iron_block
setblock ~48 ~66 ~17 iron_block
setblock ~49 ~66 ~17 wool
setblock ~49 ~66 ~18 iron_block
setblock ~50 ~66 ~19 iron_block
setblock ~51 ~66 ~19 wool
setblock ~52 ~66 ~19 quartz_block
fill ~52 ~66 ~43 ~52 ~70 ~43 concrete 6
setblock ~53 ~66 ~20 iron_block
setblock ~54 ~66 ~20 concrete
setblock ~55 ~66 ~20 iron_block
setblock ~56 ~66 ~19 quartz_block
setblock ~56 ~66 ~20 concrete
setblock ~57 ~66 ~20 iron_block
setblock ~58 ~66 ~20 concrete
setblock ~59 ~66 ~20 iron_block
setblock ~60 ~66 ~19 quartz_block
setblock ~61 ~66 ~19 wool
fill ~61 ~66 ~59 ~61 ~76 ~59 concrete 6
fill ~62 ~66 ~18 ~62 ~66 ~19 iron_block
fill ~62 ~66 ~57 ~62 ~67 ~57 concrete 6
setblock ~63 ~66 ~17 wool
fill ~63 ~66 ~55 ~63 ~67 ~55 concrete 6
fill ~63 ~66 ~63 ~63 ~68 ~63 concrete 6
setblock ~64 ~66 ~17 iron_block
setblock ~64 ~66 ~54 concrete 6
fill ~64 ~66 ~65 ~64 ~71 ~65 concrete 6
fill ~65 ~66 ~17 ~66 ~66 ~17 wool
fill ~65 ~66 ~53 ~68 ~66 ~53 concrete 6
fill ~66 ~66 ~67 ~71 ~66 ~67 concrete 6
setblock ~67 ~66 ~15 wool
setblock ~67 ~66 ~16 iron_block
setblock ~68 ~66 ~14 concrete
setblock ~69 ~66 ~12 iron_block
fill ~69 ~66 ~52 ~70 ~66 ~52 concrete 6
setblock ~70 ~66 ~11 iron_block
setblock ~71 ~66 ~11 wool
setblock ~71 ~66 ~53 concrete 6
setblock ~72 ~66 ~10 concrete
setblock ~72 ~66 ~11 quartz_block
setblock ~72 ~66 ~54 concrete 6
setblock ~73 ~66 ~9 wool
fill ~73 ~66 ~55 ~74 ~66 ~55 concrete 6
fill ~73 ~66 ~66 ~73 ~68 ~66 concrete 6
setblock ~74 ~66 ~8 concrete
fill ~74 ~66 ~56 ~75 ~66 ~56 concrete 6
setblock ~75 ~66 ~8 iron_block
fill ~75 ~66 ~59 ~75 ~68 ~59 concrete 6
fill ~75 ~66 ~63 ~75 ~68 ~63 concrete 6
setblock ~76 ~66 ~9 iron_block
setblock ~78 ~66 ~10 iron_block
setblock ~79 ~66 ~11 wool
setblock ~79 ~66 ~12 iron_block
setblock ~80 ~66 ~14 concrete
setblock ~81 ~66 ~16 iron_block
setblock ~31 ~67 ~16 wool
setblock ~32 ~67 ~14 wool
setblock ~33 ~67 ~12 wool
fill ~34 ~67 ~10 ~35 ~67 ~10 wool
setblock ~36 ~67 ~9 iron_block
setblock ~37 ~67 ~9 wool
fill ~38 ~67 ~8 ~39 ~67 ~8 wool
fill ~38 ~67 ~45 ~38 ~72 ~45 concrete 6
setblock ~39 ~67 ~9 wool
setblock ~40 ~67 ~10 wool
setblock ~40 ~67 ~11 iron_block
fill ~40 ~67 ~41 ~40 ~73 ~41 concrete 6
fill ~41 ~67 ~12 ~42 ~67 ~12 wool
setblock ~42 ~67 ~13 iron_block
fill ~42 ~67 ~38 ~47 ~67 ~38 concrete 6
fill ~42 ~67 ~53 ~48 ~67 ~53 concrete 6
setblock ~43 ~67 ~13 wool
setblock ~44 ~67 ~14 wool
fill ~44 ~67 ~15 ~44 ~68 ~15 iron_block
fill ~45 ~67 ~16 ~45 ~67 ~18 wool
fill ~46 ~67 ~18 ~49 ~67 ~18 wool
setblock ~49 ~67 ~19 wool
fill ~49 ~67 ~52 ~49 ~69 ~52 concrete 6
fill ~50 ~67 ~20 ~52 ~67 ~20 wool
fill ~50 ~67 ~40 ~50 ~70 ~40 concrete 6
fill ~50 ~67 ~51 ~50 ~69 ~51 concrete 6
fill ~52 ~67 ~42 ~52 ~70 ~42 concrete 6
fill ~53 ~67 ~21 ~53 ~68 ~21 wool
setblock ~54 ~67 ~21 iron_block
setblock ~55 ~67 ~21 wool
setblock ~56 ~67 ~21 iron_block
setblock ~57 ~67 ~21 wool
setblock ~58 ~67 ~21 iron_block
fill ~59 ~67 ~20 ~62 ~67 ~20 wool
fill ~61 ~67 ~58 ~61 ~75 ~58 concrete 6
setblock ~62 ~67 ~19 iron_block
fill ~62 ~67 ~56 ~62 ~68 ~56 concrete 6
fill ~62 ~67 ~62 ~62 ~76 ~62 concrete 6
fill ~63 ~67 ~18 ~67 ~67 ~18 wool
fill ~63 ~67 ~53 ~64 ~67 ~53 concrete 6
fill ~63 ~67 ~54 ~63 ~67 ~53 concrete 6
fill ~65 ~67 ~52 ~68 ~67 ~52 concrete 6
fill ~66 ~67 ~66 ~66 ~71 ~66 concrete 6
setblock ~67 ~67 ~17 wool
fill ~67 ~67 ~67 ~71 ~67 ~67 concrete 6
setblock ~68 ~67 ~14 wool
setblock ~68 ~67 ~15 iron_block
setblock ~68 ~67 ~16 wool
setblock ~69 ~67 ~13 wool
fill ~69 ~67 ~51 ~70 ~67 ~51 concrete 6
fill ~70 ~67 ~12 ~72 ~67 ~12 wool
setblock ~70 ~67 ~13 iron_block
setblock ~71 ~67 ~52 concrete 6
setblock ~72 ~67 ~53 concrete 6
fill ~73 ~67 ~10 ~73 ~67 ~11 wool
setblock ~73 ~67 ~54 concrete 6
setblock ~74 ~67 ~9 iron_block
fill ~74 ~67 ~55 ~74 ~70 ~55 concrete 6
setblock ~75 ~67 ~9 wool
fill ~75 ~67 ~56 ~75 ~75 ~56 concrete 6
fill ~76 ~67 ~10 ~77 ~67 ~10 wool
setblock ~78 ~67 ~11 iron_block
setblock ~79 ~67 ~12 wool
setblock ~80 ~67 ~14 wool
fill ~81 ~67 ~16 ~81 ~67 ~17 wool
setblock ~31 ~68 ~16 iron_block
setblock ~32 ~68 ~14 concrete
fill ~32 ~68 ~15 ~32 ~69 ~15 iron_block
setblock ~33 ~68 ~12 iron_block
setblock ~33 ~68 ~13 wool
setblock ~34 ~68 ~11 iron_block
setblock ~35 ~68 ~11 wool
setblock ~36 ~68 ~10 concrete
setblock ~37 ~68 ~10 iron_block
setblock ~38 ~68 ~9 quartz_block
fill ~38 ~68 ~44 ~38 ~73 ~44 concrete 6
setblock ~39 ~68 ~10 iron_block
setblock ~39 ~68 ~11 wool
setblock ~40 ~68 ~12 concrete
setblock ~40 ~68 ~13 iron_block
setblock ~41 ~68 ~13 wool
setblock ~42 ~68 ~14 concrete
fill ~42 ~68 ~38 ~47 ~68 ~38 concrete 6
fill ~42 ~68 ~53 ~42 ~79 ~53 concrete 6
setblock ~43 ~68 ~14 iron_block
setblock ~43 ~68 ~15 wool
fill ~43 ~68 ~54 ~47 ~68 ~54 concrete 6
setblock ~44 ~68 ~16 concrete
fill ~44 ~68 ~17 ~44 ~69 ~17 iron_block
setblock ~45 ~68 ~18 iron_block
setblock ~45 ~68 ~19 wool
setblock ~46 ~68 ~19 iron_block
setblock ~47 ~68 ~19 wool
setblock ~48 ~68 ~19 iron_block
setblock ~48 ~68 ~53 concrete 6
setblock ~49 ~68 ~20 iron_block
fill ~49 ~68 ~39 ~49 ~71 ~39 concrete 6
setblock ~50 ~68 ~21 quartz_block
setblock ~51 ~68 ~21 wool
fill ~51 ~68 ~50 ~51 ~69 ~50 concrete 6
setblock ~52 ~68 ~21 iron_block
fill ~52 ~68 ~49 ~52 ~71 ~49 concrete 6
setblock ~54 ~68 ~22 concrete
setblock ~55 ~68 ~22 iron_block
setblock ~56 ~68 ~22 concrete
setblock ~57 ~68 ~22 iron_block
setblock ~58 ~68 ~22 concrete
setblock ~59 ~68 ~21 wool
setblock ~60 ~68 ~21 iron_block
setblock ~61 ~68 ~21 wool
fill ~61 ~68 ~57 ~61 ~69 ~57 concrete 6
setblock ~62 ~68 ~20 concrete
fill ~62 ~68 ~54 ~62 ~69 ~54 concrete 6
fill ~62 ~68 ~55 ~62 ~68 ~54 concrete 6
setblock ~63 ~68 ~19 wool
setblock ~63 ~68 ~20 iron_block
fill ~63 ~68 ~52 ~64 ~68 ~52 concrete 6
fill ~63 ~68 ~53 ~63 ~68 ~52 concrete 6
fill ~63 ~68 ~64 ~63 ~72 ~64 concrete 6
setblock ~64 ~68 ~19 iron_block
setblock ~64 ~68 ~20 concrete
setblock ~65 ~68 ~19 wool
setblock ~65 ~68 ~20 iron_block
fill ~65 ~68 ~51 ~68 ~68 ~51 concrete 6
setblock ~66 ~68 ~19 iron_block
setblock ~67 ~68 ~18 iron_block
fill ~67 ~68 ~19 ~67 ~69 ~19 wool
fill ~67 ~68 ~67 ~71 ~68 ~67 concrete 6
setblock ~68 ~68 ~16 concrete
fill ~68 ~68 ~17 ~68 ~69 ~17 iron_block
setblock ~69 ~68 ~14 iron_block
setblock ~69 ~68 ~15 wool
setblock ~69 ~68 ~50 concrete 6
setblock ~70 ~68 ~14 concrete
fill ~70 ~68 ~51 ~71 ~68 ~51 concrete 6
setblock ~71 ~68 ~13 wool
setblock ~72 ~68 ~13 iron_block
fill ~72 ~68 ~52 ~72 ~69 ~52 concrete 6
setblock ~73 ~68 ~11 wool
setblock ~73 ~68 ~12 iron_block
setblock ~73 ~68 ~53 concrete 6
setblock ~74 ~68 ~10 concrete
fill ~74 ~68 ~54 ~74 ~78 ~54 concrete 6
setblock ~75 ~68 ~10 iron_block
fill ~75 ~68 ~62 ~75 ~70 ~62 concrete 6
setblock ~76 ~68 ~11 iron_block
setblock ~77 ~68 ~11 wool
setblock ~78 ~68 ~12 concrete
setblock ~79 ~68 ~13 wool
setblock ~80 ~68 ~14 concrete
fill ~80 ~68 ~15 ~80 ~69 ~15 iron_block
setblock ~81 ~68 ~16 iron_block
fill ~81 ~68 ~17 ~81 ~69 ~17 wool
fill ~31 ~69 ~16 ~31 ~69 ~17 wool
setblock ~32 ~69 ~14 wool
setblock ~33 ~69 ~13 snow
fill ~34 ~69 ~12 ~35 ~69 ~12 wool
setblock ~36 ~69 ~11 iron_block
setblock ~37 ~69 ~11 wool
setblock ~38 ~69 ~10 wool
fill ~38 ~69 ~11 ~38 ~70 ~11 iron_block
setblock ~38 ~69 ~50 concrete 6
fill ~39 ~69 ~12 ~39 ~69 ~13 wool
fill ~40 ~69 ~14 ~41 ~69 ~14 wool
setblock ~41 ~69 ~15 wool
fill ~41 ~69 ~40 ~41 ~74 ~40 concrete 6
setblock ~42 ~69 ~15 iron_block
fill ~42 ~69 ~38 ~48 ~69 ~38 concrete 6
setblock ~43 ~69 ~16 wool
fill ~43 ~69 ~54 ~48 ~69 ~54 concrete 6
setblock ~44 ~69 ~18 wool
setblock ~44 ~69 ~19 iron_block
fill ~45 ~69 ~20 ~48 ~69 ~20 wool
setblock ~47 ~69 ~21 wool
setblock ~48 ~69 ~21 iron_block
setblock ~49 ~69 ~21 snow
fill ~49 ~69 ~53 ~49 ~70 ~53 concrete 6
setblock ~50 ~69 ~21 iron_block
fill ~51 ~69 ~22 ~53 ~69 ~22 wool
fill ~53 ~69 ~46 ~53 ~72 ~46 concrete 6
fill ~53 ~69 ~47 ~53 ~72 ~47 concrete 6
fill ~53 ~69 ~48 ~53 ~73 ~48 concrete 6
fill ~54 ~69 ~23 ~54 ~71 ~23 iron_block
fill ~55 ~69 ~23 ~55 ~70 ~23 wool
setblock ~56 ~69 ~23 iron_block
fill ~57 ~69 ~23 ~57 ~70 ~23 wool
fill ~58 ~69 ~22 ~61 ~69 ~22 wool
fill ~61 ~69 ~55 ~61 ~70 ~55 concrete 6
fill ~61 ~69 ~56 ~61 ~70 ~56 concrete 6
setblock ~62 ~69 ~21 iron_block
fill ~62 ~69 ~53 ~62 ~70 ~53 concrete 6
setblock ~63 ~69 ~21 snow
fill ~63 ~69 ~51 ~64 ~69 ~51 concrete 6
fill ~63 ~69 ~52 ~63 ~69 ~51 concrete 6
setblock ~63 ~69 ~63 wool 6
setblock ~64 ~69 ~21 iron_block
setblock ~65 ~69 ~21 wool
fill ~65 ~69 ~50 ~68 ~69 ~50 concrete 6
fill ~66 ~69 ~20 ~67 ~69 ~20 wool
setblock ~66 ~69 ~21 iron_block
fill ~67 ~69 ~66 ~67 ~73 ~66 concrete 6
setblock ~68 ~69 ~18 wool
fill ~68 ~69 ~67 ~70 ~69 ~67 concrete 6
setblock ~69 ~69 ~16 wool
setblock ~69 ~69 ~49 concrete 6
setblock ~70 ~69 ~15 iron_block
setblock ~70 ~69 ~50 concrete 6
fill ~71 ~69 ~14 ~72 ~69 ~14 wool
fill ~71 ~69 ~15 ~71 ~69 ~14 wool
setblock ~71 ~69 ~51 concrete 6
fill ~71 ~69 ~66 ~71 ~70 ~66 concrete 6
setblock ~73 ~69 ~13 wool
fill ~73 ~69 ~52 ~73 ~70 ~52 concrete 6
fill ~73 ~69 ~65 ~73 ~71 ~65 concrete 6
setblock ~74 ~69 ~11 iron_block
setblock ~74 ~69 ~12 wool
fill ~74 ~69 ~53 ~74 ~78 ~53 concrete 6
fill ~74 ~69 ~63 ~74 ~71 ~63 concrete 6
fill ~74 ~69 ~64 ~74 ~70 ~64 concrete 6
setblock ~75 ~69 ~11 wool
setblock ~75 ~69 ~59 wool 6
fill ~76 ~69 ~12 ~77 ~69 ~12 wool
setblock ~78 ~69 ~13 iron_block
setblock ~79 ~69 ~13 snow
setblock ~79 ~69 ~14 wool
setblock ~80 ~69 ~16 wool
setblock ~81 ~69 ~18 wool
setblock ~31 ~70 ~17 wool
setblock ~31 ~70 ~18 iron_block
setblock ~32 ~70 ~15 quartz_block
setblock ~32 ~70 ~16 concrete
setblock ~33 ~70 ~14 iron_block
fill ~34 ~70 ~13 ~35 ~70 ~13 wool
setblock ~36 ~70 ~12 concrete
setblock ~37 ~70 ~12 iron_block
setblock ~38 ~70 ~12 concrete
setblock ~39 ~70 ~13 wool
setblock ~39 ~70 ~14 iron_block
fill ~39 ~70 ~51 ~39 ~74 ~51 concrete 6
setblock ~40 ~70 ~15 quartz_block
setblock ~41 ~70 ~16 iron_block
setblock ~42 ~70 ~16 concrete
fill ~42 ~70 ~17 ~43 ~70 ~17 wool
fill ~42 ~70 ~38 ~48 ~70 ~38 concrete 6
setblock ~43 ~70 ~18 iron_block
fill ~43 ~70 ~54 ~48 ~70 ~54 concrete 6
setblock ~44 ~70 ~19 quartz_block
setblock ~44 ~70 ~20 concrete
fill ~44 ~70 ~21 ~44 ~79 ~21 iron_block
fill ~45 ~70 ~21 ~46 ~70 ~21 wool
fill ~46 ~70 ~22 ~47 ~70 ~22 iron_block
setblock ~48 ~70 ~22 concrete
fill ~49 ~70 ~22 ~51 ~70 ~22 iron_block
fill ~50 ~70 ~52 ~50 ~71 ~52 concrete 6
fill ~51 ~70 ~40 ~51 ~72 ~40 concrete 6
fill ~51 ~70 ~51 ~51 ~71 ~51 concrete 6
setblock ~52 ~70 ~23 quartz_block
fill ~52 ~70 ~41 ~52 ~72 ~41 concrete 6
fill ~52 ~70 ~50 ~52 ~74 ~50 concrete 6
fill ~53 ~70 ~23 ~53 ~72 ~23 wool
fill ~53 ~70 ~44 ~53 ~73 ~44 concrete 6
fill ~53 ~70 ~45 ~53 ~72 ~45 concrete 6
setblock ~56 ~70 ~24 concrete
fill ~58 ~70 ~23 ~58 ~71 ~23 iron_block
fill ~59 ~70 ~23 ~59 ~72 ~23 wool
setblock ~60 ~70 ~22 concrete
fill ~60 ~70 ~57 ~60 ~78 ~57 concrete 6
fill ~61 ~70 ~22 ~63 ~70 ~22 iron_block
fill ~61 ~70 ~54 ~61 ~71 ~54 concrete 6
fill ~62 ~70 ~51 ~62 ~71 ~51 concrete 6
fill ~62 ~70 ~52 ~62 ~70 ~51 concrete 6
fill ~63 ~70 ~50 ~64 ~70 ~50 concrete 6
fill ~63 ~70 ~63 ~63 ~72 ~63 concrete 6
setblock ~64 ~70 ~22 concrete
fill ~65 ~70 ~22 ~66 ~70 ~22 iron_block
fill ~65 ~70 ~49 ~68 ~70 ~49 concrete 6
fill ~67 ~70 ~21 ~67 ~72 ~21 wool
setblock ~68 ~70 ~19 quartz_block
setblock ~68 ~70 ~20 concrete
fill ~68 ~70 ~67 ~69 ~70 ~67 concrete 6
fill ~69 ~70 ~17 ~70 ~70 ~17 wool
setblock ~69 ~70 ~18 iron_block
fill ~69 ~70 ~48 ~69 ~71 ~48 concrete 6
setblock ~70 ~70 ~16 concrete
setblock ~70 ~70 ~49 concrete 6
fill ~70 ~70 ~66 ~70 ~71 ~66 concrete 6
setblock ~71 ~70 ~16 iron_block
setblock ~71 ~70 ~50 concrete 6
setblock ~72 ~70 ~15 quartz_block
setblock ~72 ~70 ~51 concrete 6
fill ~72 ~70 ~65 ~72 ~72 ~65 concrete 6
setblock ~73 ~70 ~14 iron_block
setblock ~74 ~70 ~12 concrete
setblock ~74 ~70 ~13 wool
setblock ~75 ~70 ~12 iron_block
fill ~75 ~70 ~61 ~75 ~72 ~61 concrete 6
setblock ~76 ~70 ~13 iron_block
fill ~76 ~70 ~59 ~76 ~71 ~59 concrete 6
setblock ~77 ~70 ~13 wool
fill ~78 ~70 ~14 ~79 ~70 ~14 iron_block
fill ~79 ~70 ~15 ~79 ~71 ~15 wool
setblock ~80 ~70 ~16 concrete
fill ~80 ~70 ~17 ~80 ~72 ~17 iron_block
setblock ~81 ~70 ~18 iron_block
setblock ~31 ~71 ~18 wool
setblock ~32 ~71 ~16 wool
fill ~32 ~71 ~17 ~32 ~73 ~17 iron_block
setblock ~33 ~71 ~15 wool
fill ~34 ~71 ~14 ~35 ~71 ~14 wool
setblock ~36 ~71 ~13 iron_block
setblock ~37 ~71 ~13 wool
setblock ~38 ~71 ~13 iron_block
setblock ~38 ~71 ~14 wool
fill ~39 ~71 ~15 ~39 ~71 ~16 wool
fill ~39 ~71 ~43 ~39 ~75 ~43 concrete 6
setblock ~40 ~71 ~16 wool
fill ~40 ~71 ~17 ~40 ~72 ~17 iron_block
fill ~40 ~71 ~52 ~40 ~73 ~52 concrete 6
setblock ~41 ~71 ~17 wool
fill ~41 ~71 ~53 ~41 ~72 ~53 concrete 6
setblock ~42 ~71 ~18 wool
fill ~42 ~71 ~38 ~46 ~71 ~38 concrete 6
fill ~43 ~71 ~19 ~43 ~74 ~19 wool
fill ~43 ~71 ~54 ~49 ~71 ~54 concrete 6
setblock ~44 ~71 ~20 wool
fill ~45 ~71 ~22 ~50 ~71 ~22 wool
fill ~47 ~71 ~37 ~47 ~73 ~37 concrete 6
fill ~48 ~71 ~38 ~48 ~72 ~38 concrete 6
fill ~50 ~71 ~39 ~50 ~73 ~39 concrete 6
fill ~50 ~71 ~53 ~50 ~72 ~53 concrete 6
fill ~51 ~71 ~23 ~51 ~74 ~23 wool
fill ~52 ~71 ~23 ~52 ~73 ~23 iron_block
fill ~53 ~71 ~42 ~53 ~74 ~42 concrete 6
fill ~53 ~71 ~43 ~53 ~73 ~43 concrete 6
fill ~55 ~71 ~24 ~57 ~71 ~24 wool
fill ~60 ~71 ~23 ~60 ~72 ~23 iron_block
fill ~60 ~71 ~55 ~60 ~76 ~55 concrete 6
fill ~60 ~71 ~56 ~60 ~77 ~56 concrete 6
fill ~61 ~71 ~23 ~61 ~73 ~23 wool
fill ~61 ~71 ~52 ~61 ~72 ~52 concrete 6
fill ~61 ~71 ~53 ~61 ~71 ~52 concrete 6
fill ~62 ~71 ~22 ~66 ~71 ~22 wool
fill ~62 ~71 ~49 ~64 ~71 ~49 concrete 6
fill ~62 ~71 ~50 ~62 ~71 ~49 concrete 6
fill ~64 ~71 ~48 ~70 ~71 ~48 concrete 6
fill ~65 ~71 ~65 ~65 ~72 ~65 concrete 6
fill ~67 ~71 ~47 ~68 ~71 ~47 concrete 6
fill ~68 ~71 ~19 ~68 ~72 ~19 iron_block
setblock ~68 ~71 ~20 wool
fill ~68 ~71 ~66 ~70 ~71 ~66 concrete 6
fill ~69 ~71 ~18 ~70 ~71 ~18 wool
fill ~71 ~71 ~17 ~71 ~72 ~17 wool
fill ~71 ~71 ~49 ~71 ~72 ~49 concrete 6
fill ~71 ~71 ~65 ~71 ~73 ~65 concrete 6
fill ~72 ~71 ~16 ~73 ~71 ~16 wool
setblock ~72 ~71 ~50 concrete 6
setblock ~73 ~71 ~15 wool
fill ~73 ~71 ~51 ~73 ~81 ~51 concrete 6
fill ~73 ~71 ~64 ~73 ~72 ~64 concrete 6
setblock ~74 ~71 ~14 wool
fill ~74 ~71 ~52 ~74 ~75 ~52 concrete 6
fill ~74 ~71 ~62 ~74 ~72 ~62 concrete 6
setblock ~75 ~71 ~13 wool
fill ~75 ~71 ~55 ~75 ~72 ~55 concrete 6
fill ~76 ~71 ~14 ~77 ~71 ~14 wool
fill ~78 ~71 ~15 ~78 ~72 ~15 iron_block
setblock ~79 ~71 ~16 wool
setblock ~81 ~71 ~18 wool
setblock ~31 ~72 ~18 iron_block
fill ~31 ~72 ~19 ~31 ~73 ~19 wool
setblock ~32 ~72 ~16 concrete
setblock ~33 ~72 ~16 iron_block
setblock ~34 ~72 ~15 iron_block
setblock ~35 ~72 ~15 wool
setblock ~36 ~72 ~14 concrete
setblock ~37 ~72 ~14 iron_block
setblock ~38 ~72 ~15 iron_block
setblock ~38 ~72 ~16 concrete
fill ~39 ~72 ~17 ~39 ~74 ~17 wool
fill ~39 ~72 ~47 ~39 ~76 ~47 concrete 6
fill ~39 ~72 ~48 ~39 ~75 ~48 concrete 6
fill ~39 ~72 ~49 ~39 ~75 ~49 concrete 6
fill ~40 ~72 ~42 ~40 ~76 ~42 concrete 6
setblock ~41 ~72 ~18 iron_block
setblock ~42 ~72 ~18 concrete
fill ~42 ~72 ~38 ~46 ~72 ~38 concrete 6
fill ~42 ~72 ~39 ~42 ~75 ~39 concrete 6
fill ~43 ~72 ~54 ~49 ~72 ~54 concrete 6
setblock ~44 ~72 ~20 concrete
setblock ~45 ~72 ~22 iron_block
setblock ~46 ~72 ~22 concrete
setblock ~47 ~72 ~22 iron_block
setblock ~48 ~72 ~22 concrete
setblock ~49 ~72 ~22 iron_block
fill ~49 ~72 ~38 ~49 ~74 ~38 concrete 6
fill ~50 ~72 ~23 ~50 ~75 ~23 iron_block
fill ~51 ~72 ~52 ~51 ~74 ~52 concrete 6
fill ~52 ~72 ~51 ~52 ~75 ~51 concrete 6
setblock ~53 ~72 ~49 concrete 6
setblock ~54 ~72 ~24 concrete
setblock ~55 ~72 ~24 iron_block
setblock ~56 ~72 ~24 concrete
setblock ~57 ~72 ~24 iron_block
setblock ~58 ~72 ~24 concrete
fill ~60 ~72 ~53 ~60 ~73 ~53 concrete 6
fill ~60 ~72 ~54 ~60 ~72 ~53 concrete 6
fill ~61 ~72 ~50 ~61 ~73 ~50 concrete 6
fill ~61 ~72 ~51 ~61 ~72 ~50 concrete 6
fill ~61 ~72 ~60 ~61 ~78 ~60 concrete 6
fill ~62 ~72 ~23 ~62 ~75 ~23 iron_block
fill ~62 ~72 ~48 ~63 ~72 ~48 concrete 6
fill ~62 ~72 ~49 ~62 ~72 ~48 concrete 6
setblock ~63 ~72 ~22 iron_block
fill ~63 ~72 ~47 ~66 ~72 ~47 concrete 6
setblock ~64 ~72 ~22 concrete
fill ~64 ~72 ~64 ~64 ~74 ~64 concrete 6
setblock ~65 ~72 ~22 iron_block
setblock ~66 ~72 ~22 concrete
fill ~66 ~72 ~46 ~68 ~72 ~46 concrete 6
fill ~66 ~72 ~65 ~66 ~74 ~65 concrete 6
setblock ~68 ~72 ~20 concrete
fill ~68 ~72 ~66 ~69 ~72 ~66 concrete 6
fill ~69 ~72 ~19 ~69 ~75 ~19 wool
setblock ~69 ~72 ~47 concrete 6
setblock ~70 ~72 ~18 concrete
setblock ~70 ~72 ~48 concrete 6
fill ~70 ~72 ~65 ~70 ~73 ~65 concrete 6
fill ~72 ~72 ~17 ~72 ~76 ~17 iron_block
fill ~72 ~72 ~49 ~72 ~73 ~49 concrete 6
setblock ~73 ~72 ~16 iron_block
fill ~73 ~72 ~50 ~73 ~78 ~50 concrete 6
fill ~73 ~72 ~63 ~73 ~74 ~63 concrete 6
