fill ~137 ~0 ~34 ~137 ~0 ~35 wool 12
setblock ~137 ~0 ~36 stained_hardened_clay 12
fill ~137 ~0 ~37 ~139 ~0 ~37 noteblock 0
fill ~137 ~0 ~38 ~137 ~0 ~37 noteblock 0
setblock ~137 ~0 ~39 dirt 1
fill ~137 ~0 ~40 ~154 ~0 ~40 noteblock 0
setblock ~137 ~0 ~41 wool 12
setblock ~137 ~0 ~42 noteblock 0
setblock ~137 ~0 ~43 wool 12
setblock ~138 ~0 ~29 noteblock 0
setblock ~138 ~0 ~30 redstone_lamp 0
setblock ~138 ~0 ~31 noteblock 0
setblock ~138 ~0 ~32 log 1
setblock ~138 ~0 ~33 wool 12
fill ~138 ~0 ~34 ~138 ~0 ~35 noteblock 0
setblock ~138 ~0 ~36 planks 5
setblock ~138 ~0 ~38 stained_hardened_clay 12
setblock ~138 ~0 ~39 quartz_ore 0
setblock ~138 ~0 ~41 noteblock 0
setblock ~138 ~0 ~42 redstone_lamp 0
setblock ~138 ~0 ~43 noteblock 0
setblock ~138 ~0 ~44 redstone_lamp 0
setblock ~138 ~0 ~45 concrete 12
setblock ~138 ~0 ~46 log 1
setblock ~138 ~0 ~47 noteblock 0
setblock ~139 ~0 ~15 noteblock 0
setblock ~139 ~0 ~16 stained_hardened_clay 12
setblock ~139 ~0 ~17 noteblock 0
setblock ~139 ~0 ~18 stained_hardened_clay 12
fill ~139 ~0 ~19 ~142 ~0 ~19 noteblock 0
fill ~139 ~0 ~20 ~139 ~0 ~19 noteblock 0
fill ~139 ~0 ~21 ~139 ~1 ~21 quartz_ore 0
fill ~139 ~0 ~22 ~143 ~0 ~22 noteblock 0
fill ~139 ~0 ~23 ~139 ~1 ~23 quartz_ore 0
setblock ~139 ~0 ~24 noteblock 0
setblock ~139 ~0 ~25 quartz_ore 0
fill ~139 ~0 ~26 ~139 ~1 ~26 noteblock 0
setblock ~139 ~0 ~27 wool 12
setblock ~139 ~0 ~28 noteblock 0
setblock ~139 ~0 ~29 quartz_ore 0
setblock ~139 ~0 ~30 noteblock 0
setblock ~139 ~0 ~31 wool 12
setblock ~139 ~0 ~32 redstone_lamp 0
setblock ~139 ~0 ~33 quartz_ore 0
fill ~139 ~0 ~34 ~139 ~0 ~35 wool 12
setblock ~139 ~0 ~36 stained_hardened_clay 12
setblock ~139 ~0 ~38 noteblock 0
setblock ~139 ~0 ~39 dirt 1
setblock ~139 ~0 ~41 wool 12
setblock ~139 ~0 ~42 noteblock 0
setblock ~139 ~0 ~43 quartz_ore 0
setblock ~139 ~0 ~44 noteblock 0
setblock ~139 ~0 ~45 wool 12
setblock ~139 ~0 ~46 redstone_lamp 0
setblock ~139 ~0 ~47 wool 12
setblock ~140 ~0 ~14 planks 5
setblock ~140 ~0 ~15 stained_hardened_clay 12
setblock ~140 ~0 ~16 log 1
setblock ~140 ~0 ~17 stained_hardened_clay 12
setblock ~140 ~0 ~18 planks 5
setblock ~140 ~0 ~20 stained_hardened_clay 12
setblock ~140 ~0 ~21 noteblock 0
setblock ~140 ~0 ~23 noteblock 0
setblock ~140 ~0 ~24 redstone_lamp 0
setblock ~140 ~0 ~25 noteblock 0
setblock ~140 ~0 ~26 redstone_lamp 0
setblock ~140 ~0 ~27 noteblock 0
setblock ~140 ~0 ~28 stained_hardened_clay 12
setblock ~140 ~0 ~29 noteblock 0
setblock ~140 ~0 ~30 redstone_lamp 0
setblock ~140 ~0 ~31 noteblock 0
setblock ~140 ~0 ~32 log 1
setblock ~140 ~0 ~33 noteblock 0
setblock ~140 ~0 ~34 redstone_lamp 0
setblock ~140 ~0 ~35 noteblock 0
setblock ~140 ~0 ~36 planks 5
setblock ~140 ~0 ~37 redstone_lamp 0
setblock ~140 ~0 ~38 stained_hardened_clay 12
setblock ~140 ~0 ~39 quartz_ore 0
setblock ~140 ~0 ~41 noteblock 0
setblock ~140 ~0 ~42 redstone_lamp 0
setblock ~140 ~0 ~43 noteblock 0
setblock ~140 ~0 ~44 redstone_lamp 0
setblock ~140 ~0 ~45 noteblock 0
setblock ~140 ~0 ~46 log 1
setblock ~140 ~0 ~47 noteblock 0
setblock ~140 ~0 ~48 planks 5
fill ~141 ~0 ~12 ~141 ~1 ~12 black_glazed_terracotta 0
setblock ~141 ~0 ~13 noteblock 0
setblock ~141 ~0 ~14 stained_hardened_clay 12
setblock ~141 ~0 ~15 noteblock 0
setblock ~141 ~0 ~16 stained_hardened_clay 12
setblock ~141 ~0 ~17 soul_sand 0
setblock ~141 ~0 ~18 stained_hardened_clay 12
setblock ~141 ~0 ~20 noteblock 0
setblock ~141 ~0 ~21 soul_sand 0
setblock ~141 ~0 ~23 quartz_ore 0
setblock ~141 ~0 ~24 noteblock 0
setblock ~141 ~0 ~25 wool 12
setblock ~141 ~0 ~26 noteblock 0
setblock ~141 ~0 ~27 wool 12
setblock ~141 ~0 ~28 noteblock 0
setblock ~141 ~0 ~29 quartz_ore 0
setblock ~141 ~0 ~30 noteblock 0
setblock ~141 ~0 ~31 wool 12
setblock ~141 ~0 ~32 redstone_lamp 0
setblock ~141 ~0 ~33 quartz_ore 0
setblock ~141 ~0 ~34 concrete 12
setblock ~141 ~0 ~35 wool 12
setblock ~141 ~0 ~36 stained_hardened_clay 12
fill ~141 ~0 ~37 ~151 ~0 ~37 noteblock 0
fill ~141 ~0 ~38 ~141 ~0 ~37 noteblock 0
setblock ~141 ~0 ~39 dirt 1
setblock ~141 ~0 ~41 wool 12
setblock ~141 ~0 ~42 noteblock 0
setblock ~141 ~0 ~43 wool 12
setblock ~141 ~0 ~44 noteblock 0
setblock ~141 ~0 ~45 wool 12
setblock ~141 ~0 ~46 redstone_lamp 0
setblock ~141 ~0 ~47 wool 12
fill ~141 ~0 ~48 ~142 ~0 ~48 log 1
fill ~141 ~0 ~49 ~141 ~1 ~49 noteblock 0
setblock ~142 ~0 ~11 log 1
setblock ~142 ~0 ~12 planks 5
setblock ~142 ~0 ~13 stained_hardened_clay 12
setblock ~142 ~0 ~14 planks 5
setblock ~142 ~0 ~15 stained_hardened_clay 12
setblock ~142 ~0 ~16 log 1
setblock ~142 ~0 ~17 noteblock 0
setblock ~142 ~0 ~18 planks 5
setblock ~142 ~0 ~20 stained_hardened_clay 12
setblock ~142 ~0 ~21 noteblock 0
setblock ~142 ~0 ~23 noteblock 0
setblock ~142 ~0 ~24 redstone_lamp 0
setblock ~142 ~0 ~25 noteblock 0
setblock ~142 ~0 ~26 redstone_lamp 0
setblock ~142 ~0 ~27 noteblock 0
setblock ~142 ~0 ~28 stained_hardened_clay 12
setblock ~142 ~0 ~29 noteblock 0
setblock ~142 ~0 ~30 redstone_lamp 0
setblock ~142 ~0 ~31 noteblock 0
setblock ~142 ~0 ~32 log 1
setblock ~142 ~0 ~33 wool 12
fill ~142 ~0 ~34 ~142 ~0 ~35 noteblock 0
setblock ~142 ~0 ~36 planks 5
setblock ~142 ~0 ~38 stained_hardened_clay 12
setblock ~142 ~0 ~39 quartz_ore 0
setblock ~142 ~0 ~41 noteblock 0
setblock ~142 ~0 ~42 redstone_lamp 0
setblock ~142 ~0 ~43 noteblock 0
setblock ~142 ~0 ~44 redstone_lamp 0
setblock ~142 ~0 ~45 concrete 12
setblock ~142 ~0 ~46 log 1
setblock ~142 ~0 ~47 noteblock 0
setblock ~142 ~0 ~49 redstone_lamp 0
fill ~142 ~0 ~50 ~146 ~0 ~50 planks 5
fill ~143 ~0 ~10 ~144 ~0 ~10 planks 5
setblock ~143 ~0 ~11 stained_hardened_clay 12
setblock ~143 ~0 ~12 black_glazed_terracotta 0
setblock ~143 ~0 ~13 soul_sand 0
setblock ~143 ~0 ~14 stained_hardened_clay 12
setblock ~143 ~0 ~15 soul_sand 0
setblock ~143 ~0 ~16 stained_hardened_clay 12
setblock ~143 ~0 ~17 soul_sand 0
setblock ~143 ~0 ~18 stained_hardened_clay 12
fill ~143 ~0 ~19 ~143 ~0 ~20 soul_sand 0
setblock ~143 ~0 ~21 quartz_ore 0
setblock ~143 ~0 ~23 planks 1
setblock ~143 ~0 ~24 noteblock 0
setblock ~143 ~0 ~25 quartz_ore 0
setblock ~143 ~0 ~26 noteblock 0
setblock ~143 ~0 ~27 wool 12
setblock ~143 ~0 ~28 noteblock 0
setblock ~143 ~0 ~29 quartz_ore 0
setblock ~143 ~0 ~30 noteblock 0
setblock ~143 ~0 ~31 wool 12
setblock ~143 ~0 ~32 redstone_lamp 0
setblock ~143 ~0 ~33 quartz_ore 0
fill ~143 ~0 ~34 ~143 ~0 ~35 wool 12
setblock ~143 ~0 ~36 stained_hardened_clay 12
fill ~143 ~0 ~38 ~143 ~0 ~40 noteblock 0
setblock ~143 ~0 ~41 wool 12
setblock ~143 ~0 ~42 noteblock 0
setblock ~143 ~0 ~43 quartz_ore 0
setblock ~143 ~0 ~44 noteblock 0
setblock ~143 ~0 ~45 wool 12
setblock ~143 ~0 ~46 redstone_lamp 0
setblock ~143 ~0 ~47 wool 12
setblock ~143 ~0 ~48 redstone_lamp 0
setblock ~143 ~0 ~49 noteblock 0
setblock ~144 ~0 ~11 log 1
setblock ~144 ~0 ~12 planks 5
setblock ~144 ~0 ~13 stained_hardened_clay 12
setblock ~144 ~0 ~14 planks 5
setblock ~144 ~0 ~15 stained_hardened_clay 12
setblock ~144 ~0 ~16 log 1
setblock ~144 ~0 ~17 stained_hardened_clay 12
setblock ~144 ~0 ~18 black_glazed_terracotta 0
setblock ~144 ~0 ~19 noteblock 0
setblock ~144 ~0 ~20 stained_hardened_clay 12
setblock ~144 ~0 ~21 noteblock 0
setblock ~144 ~0 ~22 stained_hardened_clay 12
setblock ~144 ~0 ~23 noteblock 0
setblock ~144 ~0 ~24 stained_hardened_clay 12
setblock ~144 ~0 ~25 noteblock 0
setblock ~144 ~0 ~26 redstone_lamp 0
setblock ~144 ~0 ~27 noteblock 0
setblock ~144 ~0 ~28 stained_hardened_clay 12
setblock ~144 ~0 ~29 noteblock 0
setblock ~144 ~0 ~30 stained_hardened_clay 12
setblock ~144 ~0 ~31 noteblock 0
setblock ~144 ~0 ~32 log 1
setblock ~144 ~0 ~33 noteblock 0
setblock ~144 ~0 ~34 redstone_lamp 0
setblock ~144 ~0 ~35 noteblock 0
setblock ~144 ~0 ~36 planks 5
setblock ~144 ~0 ~38 stained_hardened_clay 12
setblock ~144 ~0 ~39 noteblock 0
setblock ~144 ~0 ~41 noteblock 0
setblock ~144 ~0 ~42 redstone_lamp 0
setblock ~144 ~0 ~43 noteblock 0
setblock ~144 ~0 ~44 redstone_lamp 0
setblock ~144 ~0 ~45 noteblock 0
setblock ~144 ~0 ~46 log 1
setblock ~144 ~0 ~47 noteblock 0
setblock ~144 ~0 ~48 planks 5
setblock ~144 ~0 ~49 redstone_lamp 0
fill ~145 ~0 ~11 ~145 ~1 ~11 stained_hardened_clay 12
setblock ~145 ~0 ~12 black_glazed_terracotta 0
setblock ~145 ~0 ~13 soul_sand 0
setblock ~145 ~0 ~14 stained_hardened_clay 12
setblock ~145 ~0 ~15 soul_sand 0
setblock ~145 ~0 ~16 stained_hardened_clay 12
setblock ~145 ~0 ~17 soul_sand 0
fill ~145 ~0 ~18 ~146 ~0 ~18 stained_hardened_clay 12
setblock ~145 ~0 ~19 quartz_ore 0
setblock ~145 ~0 ~20 noteblock 0
setblock ~145 ~0 ~21 quartz_ore 0
setblock ~145 ~0 ~22 soul_sand 0
setblock ~145 ~0 ~23 quartz_ore 0
setblock ~145 ~0 ~24 noteblock 0
setblock ~145 ~0 ~25 wool 12
setblock ~145 ~0 ~26 noteblock 0
setblock ~145 ~0 ~27 wool 12
setblock ~145 ~0 ~28 noteblock 0
setblock ~145 ~0 ~29 quartz_ore 0
setblock ~145 ~0 ~30 noteblock 0
setblock ~145 ~0 ~31 wool 12
setblock ~145 ~0 ~32 redstone_lamp 0
setblock ~145 ~0 ~33 quartz_ore 0
setblock ~145 ~0 ~34 concrete 12
setblock ~145 ~0 ~35 wool 12
setblock ~145 ~0 ~36 stained_hardened_clay 12
setblock ~145 ~0 ~38 noteblock 0
setblock ~145 ~0 ~39 quartz_ore 0
setblock ~145 ~0 ~41 wool 12
setblock ~145 ~0 ~42 noteblock 0
setblock ~145 ~0 ~43 wool 12
setblock ~145 ~0 ~44 noteblock 0
setblock ~145 ~0 ~45 wool 12
setblock ~145 ~0 ~46 redstone_lamp 0
setblock ~145 ~0 ~47 wool 12
fill ~145 ~0 ~48 ~146 ~0 ~48 log 1
setblock ~145 ~0 ~49 noteblock 0
setblock ~146 ~0 ~12 planks 5
setblock ~146 ~0 ~13 stained_hardened_clay 12
setblock ~146 ~0 ~14 planks 5
setblock ~146 ~0 ~15 stained_hardened_clay 12
setblock ~146 ~0 ~16 log 1
setblock ~146 ~0 ~17 stained_hardened_clay 12
setblock ~146 ~0 ~19 noteblock 0
setblock ~146 ~0 ~20 stained_hardened_clay 12
fill ~146 ~0 ~21 ~146 ~0 ~23 noteblock 0
setblock ~146 ~0 ~24 redstone_lamp 0
setblock ~146 ~0 ~25 noteblock 0
setblock ~146 ~0 ~26 redstone_lamp 0
setblock ~146 ~0 ~27 noteblock 0
setblock ~146 ~0 ~28 stained_hardened_clay 12
setblock ~146 ~0 ~29 noteblock 0
setblock ~146 ~0 ~30 redstone_lamp 0
setblock ~146 ~0 ~31 noteblock 0
setblock ~146 ~0 ~32 log 1
setblock ~146 ~0 ~33 wool 12
fill ~146 ~0 ~34 ~146 ~0 ~35 noteblock 0
setblock ~146 ~0 ~36 planks 5
setblock ~146 ~0 ~38 stained_hardened_clay 12
setblock ~146 ~0 ~39 noteblock 0
setblock ~146 ~0 ~41 noteblock 0
setblock ~146 ~0 ~42 redstone_lamp 0
setblock ~146 ~0 ~43 noteblock 0
setblock ~146 ~0 ~44 redstone_lamp 0
setblock ~146 ~0 ~45 noteblock 0
setblock ~146 ~0 ~46 log 1
setblock ~146 ~0 ~47 noteblock 0
setblock ~146 ~0 ~49 redstone_lamp 0
fill ~147 ~0 ~12 ~147 ~1 ~12 log 1
setblock ~147 ~0 ~13 soul_sand 0
setblock ~147 ~0 ~14 stained_hardened_clay 12
setblock ~147 ~0 ~15 soul_sand 0
setblock ~147 ~0 ~16 stained_hardened_clay 12
setblock ~147 ~0 ~17 soul_sand 0
setblock ~147 ~0 ~18 noteblock 0
setblock ~147 ~0 ~19 quartz_ore 0
setblock ~147 ~0 ~20 noteblock 0
setblock ~147 ~0 ~21 quartz_ore 0
setblock ~147 ~0 ~22 noteblock 0
setblock ~147 ~0 ~23 planks 1
setblock ~147 ~0 ~24 noteblock 0
setblock ~147 ~0 ~25 quartz_ore 0
setblock ~147 ~0 ~26 noteblock 0
setblock ~147 ~0 ~27 wool 12
setblock ~147 ~0 ~28 noteblock 0
setblock ~147 ~0 ~29 quartz_ore 0
setblock ~147 ~0 ~30 noteblock 0
setblock ~147 ~0 ~31 wool 12
setblock ~147 ~0 ~32 redstone_lamp 0
setblock ~147 ~0 ~33 quartz_ore 0
setblock ~147 ~0 ~34 concrete 12
setblock ~147 ~0 ~35 wool 12
setblock ~147 ~0 ~36 stained_hardened_clay 12
setblock ~147 ~0 ~38 noteblock 0
setblock ~147 ~0 ~39 planks 1
setblock ~147 ~0 ~41 wool 12
setblock ~147 ~0 ~42 noteblock 0
setblock ~147 ~0 ~43 quartz_ore 0
setblock ~147 ~0 ~44 noteblock 0
setblock ~147 ~0 ~45 wool 12
setblock ~147 ~0 ~46 redstone_lamp 0
setblock ~147 ~0 ~47 wool 12
setblock ~147 ~0 ~48 redstone_lamp 0
setblock ~147 ~0 ~49 noteblock 0
setblock ~148 ~0 ~13 stained_hardened_clay 12
setblock ~148 ~0 ~14 planks 5
setblock ~148 ~0 ~15 stained_hardened_clay 12
setblock ~148 ~0 ~16 log 1
setblock ~148 ~0 ~17 stained_hardened_clay 12
setblock ~148 ~0 ~18 log 1
fill ~148 ~0 ~19 ~149 ~0 ~19 soul_sand 0
setblock ~148 ~0 ~20 stained_hardened_clay 12
setblock ~148 ~0 ~21 noteblock 0
setblock ~148 ~0 ~22 stained_hardened_clay 12
setblock ~148 ~0 ~23 noteblock 0
setblock ~148 ~0 ~24 stained_hardened_clay 12
setblock ~148 ~0 ~25 noteblock 0
setblock ~148 ~0 ~26 redstone_lamp 0
setblock ~148 ~0 ~27 noteblock 0
setblock ~148 ~0 ~28 stained_hardened_clay 12
setblock ~148 ~0 ~29 noteblock 0
setblock ~148 ~0 ~30 stained_hardened_clay 12
setblock ~148 ~0 ~31 noteblock 0
setblock ~148 ~0 ~32 log 1
setblock ~148 ~0 ~33 noteblock 0
setblock ~148 ~0 ~34 redstone_lamp 0
setblock ~148 ~0 ~35 noteblock 0
setblock ~148 ~0 ~36 planks 5
setblock ~148 ~0 ~38 stained_hardened_clay 12
setblock ~148 ~0 ~39 noteblock 0
setblock ~148 ~0 ~41 noteblock 0
setblock ~148 ~0 ~42 redstone_lamp 0
setblock ~148 ~0 ~43 noteblock 0
setblock ~148 ~0 ~44 redstone_lamp 0
setblock ~148 ~0 ~45 noteblock 0
setblock ~148 ~0 ~46 log 1
setblock ~148 ~0 ~47 noteblock 0
setblock ~148 ~0 ~48 planks 5
setblock ~148 ~0 ~49 redstone_lamp 0
setblock ~149 ~0 ~14 stained_hardened_clay 12
setblock ~149 ~0 ~15 soul_sand 0
setblock ~149 ~0 ~16 stained_hardened_clay 12
setblock ~149 ~0 ~17 soul_sand 0
fill ~149 ~0 ~18 ~150 ~0 ~18 stained_hardened_clay 12
setblock ~149 ~0 ~20 noteblock 0
setblock ~149 ~0 ~21 quartz_ore 0
setblock ~149 ~0 ~22 soul_sand 0
setblock ~149 ~0 ~23 quartz_ore 0
setblock ~149 ~0 ~24 noteblock 0
setblock ~149 ~0 ~25 wool 12
setblock ~149 ~0 ~26 noteblock 0
setblock ~149 ~0 ~27 wool 12
setblock ~149 ~0 ~28 noteblock 0
setblock ~149 ~0 ~29 quartz_ore 0
setblock ~149 ~0 ~30 noteblock 0
setblock ~149 ~0 ~31 wool 12
setblock ~149 ~0 ~32 redstone_lamp 0
setblock ~149 ~0 ~33 quartz_ore 0
setblock ~149 ~0 ~34 concrete 12
setblock ~149 ~0 ~35 wool 12
setblock ~149 ~0 ~36 stained_hardened_clay 12
setblock ~149 ~0 ~38 noteblock 0
setblock ~149 ~0 ~39 planks 1
setblock ~149 ~0 ~41 quartz_ore 0
setblock ~149 ~0 ~42 noteblock 0
setblock ~149 ~0 ~43 wool 12
setblock ~149 ~0 ~44 noteblock 0
setblock ~149 ~0 ~45 wool 12
setblock ~149 ~0 ~46 redstone_lamp 0
setblock ~149 ~0 ~47 wool 12
setblock ~149 ~0 ~48 log 1
setblock ~150 ~0 ~15 stained_hardened_clay 12
setblock ~150 ~0 ~16 log 1
setblock ~150 ~0 ~17 stained_hardened_clay 12
setblock ~150 ~0 ~19 noteblock 0
setblock ~150 ~0 ~20 stained_hardened_clay 12
fill ~150 ~0 ~21 ~150 ~0 ~23 noteblock 0
setblock ~150 ~0 ~24 redstone_lamp 0
setblock ~150 ~0 ~25 noteblock 0
setblock ~150 ~0 ~26 redstone_lamp 0
setblock ~150 ~0 ~27 noteblock 0
setblock ~150 ~0 ~28 stained_hardened_clay 12
setblock ~150 ~0 ~29 noteblock 0
setblock ~150 ~0 ~30 redstone_lamp 0
setblock ~150 ~0 ~31 noteblock 0
setblock ~150 ~0 ~32 log 1
setblock ~150 ~0 ~33 wool 12
fill ~150 ~0 ~34 ~150 ~0 ~35 noteblock 0
setblock ~150 ~0 ~36 planks 5
setblock ~150 ~0 ~38 stained_hardened_clay 12
setblock ~150 ~0 ~39 wool 12
setblock ~150 ~0 ~41 noteblock 0
setblock ~150 ~0 ~42 redstone_lamp 0
setblock ~150 ~0 ~43 noteblock 0
setblock ~150 ~0 ~44 redstone_lamp 0
setblock ~150 ~0 ~45 noteblock 0
setblock ~150 ~0 ~46 log 1
setblock ~150 ~0 ~47 noteblock 0
setblock ~151 ~0 ~18 noteblock 0
setblock ~151 ~0 ~19 quartz_ore 0
setblock ~151 ~0 ~20 noteblock 0
setblock ~151 ~0 ~21 quartz_ore 0
setblock ~151 ~0 ~22 noteblock 0
setblock ~151 ~0 ~23 planks 1
setblock ~151 ~0 ~24 noteblock 0
setblock ~151 ~0 ~25 quartz_ore 0
setblock ~151 ~0 ~26 noteblock 0
setblock ~151 ~0 ~27 wool 12
setblock ~151 ~0 ~28 noteblock 0
setblock ~151 ~0 ~29 quartz_ore 0
setblock ~151 ~0 ~30 noteblock 0
setblock ~151 ~0 ~31 wool 12
setblock ~151 ~0 ~32 redstone_lamp 0
setblock ~151 ~0 ~33 quartz_ore 0
fill ~151 ~0 ~34 ~151 ~0 ~35 wool 12
setblock ~151 ~0 ~36 stained_hardened_clay 12
setblock ~151 ~0 ~38 noteblock 0
setblock ~151 ~0 ~39 planks 1
setblock ~151 ~0 ~41 quartz_ore 0
setblock ~151 ~0 ~42 noteblock 0
setblock ~151 ~0 ~43 quartz_ore 0
setblock ~151 ~0 ~44 noteblock 0
setblock ~151 ~0 ~45 wool 12
setblock ~151 ~0 ~46 redstone_lamp 0
setblock ~152 ~0 ~20 stained_hardened_clay 12
setblock ~152 ~0 ~21 noteblock 0
setblock ~152 ~0 ~22 stained_hardened_clay 12
setblock ~152 ~0 ~23 noteblock 0
setblock ~152 ~0 ~24 stained_hardened_clay 12
setblock ~152 ~0 ~25 noteblock 0
setblock ~152 ~0 ~26 redstone_lamp 0
setblock ~152 ~0 ~27 noteblock 0
setblock ~152 ~0 ~28 stained_hardened_clay 12
setblock ~152 ~0 ~29 noteblock 0
setblock ~152 ~0 ~30 stained_hardened_clay 12
setblock ~152 ~0 ~31 noteblock 0
setblock ~152 ~0 ~32 log 1
setblock ~152 ~0 ~33 noteblock 0
setblock ~152 ~0 ~34 redstone_lamp 0
setblock ~152 ~0 ~35 noteblock 0
setblock ~152 ~0 ~36 planks 5
setblock ~152 ~0 ~37 redstone_lamp 0
setblock ~152 ~0 ~38 stained_hardened_clay 12
setblock ~152 ~0 ~39 noteblock 0
setblock ~152 ~0 ~41 noteblock 0
setblock ~152 ~0 ~42 stained_hardened_clay 12
setblock ~152 ~0 ~43 noteblock 0
setblock ~152 ~0 ~44 redstone_lamp 0
setblock ~152 ~0 ~45 noteblock 0
setblock ~153 ~0 ~23 quartz_ore 0
setblock ~153 ~0 ~24 noteblock 0
setblock ~153 ~0 ~25 wool 12
setblock ~153 ~0 ~26 noteblock 0
setblock ~153 ~0 ~27 wool 12
setblock ~153 ~0 ~28 noteblock 0
setblock ~153 ~0 ~29 quartz_ore 0
setblock ~153 ~0 ~30 noteblock 0
setblock ~153 ~0 ~31 wool 12
setblock ~153 ~0 ~32 redstone_lamp 0
setblock ~153 ~0 ~33 quartz_ore 0
setblock ~153 ~0 ~34 concrete 12
setblock ~153 ~0 ~35 wool 12
setblock ~153 ~0 ~36 stained_hardened_clay 12
fill ~153 ~0 ~37 ~154 ~0 ~37 noteblock 0
fill ~153 ~0 ~38 ~153 ~0 ~37 noteblock 0
setblock ~153 ~0 ~39 quartz_ore 0
setblock ~153 ~0 ~41 quartz_ore 0
setblock ~153 ~0 ~42 noteblock 0
setblock ~153 ~0 ~43 wool 12
setblock ~153 ~0 ~44 noteblock 0
setblock ~154 ~0 ~25 noteblock 0
setblock ~154 ~0 ~26 redstone_lamp 0
setblock ~154 ~0 ~27 noteblock 0
setblock ~154 ~0 ~28 stained_hardened_clay 12
setblock ~154 ~0 ~29 noteblock 0
setblock ~154 ~0 ~30 redstone_lamp 0
setblock ~154 ~0 ~31 noteblock 0
setblock ~154 ~0 ~32 log 1
setblock ~154 ~0 ~33 wool 12
fill ~154 ~0 ~34 ~154 ~0 ~35 noteblock 0
setblock ~154 ~0 ~36 planks 5
setblock ~154 ~0 ~38 stained_hardened_clay 12
setblock ~154 ~0 ~39 noteblock 0
setblock ~154 ~0 ~41 noteblock 0
setblock ~154 ~0 ~42 stained_hardened_clay 12
setblock ~154 ~0 ~43 noteblock 0
setblock ~93 ~1 ~25 dirt 1
setblock ~93 ~1 ~26 noteblock 0
fill ~93 ~1 ~27 ~93 ~2 ~27 soul_sand 0
setblock ~93 ~1 ~28 noteblock 0
setblock ~93 ~1 ~29 quartz_ore 0
setblock ~93 ~1 ~30 noteblock 0
setblock ~93 ~1 ~31 planks 1
setblock ~93 ~1 ~32 wool 12
setblock ~93 ~1 ~33 dirt 1
setblock ~93 ~1 ~34 noteblock 0
setblock ~93 ~1 ~35 quartz_ore 0
setblock ~93 ~1 ~36 noteblock 0
setblock ~93 ~1 ~37 quartz_ore 0
fill ~93 ~1 ~38 ~93 ~1 ~39 dirt 1
setblock ~93 ~1 ~40 wool 12
setblock ~93 ~1 ~41 dirt 1
setblock ~94 ~1 ~22 soul_sand 0
setblock ~94 ~1 ~23 redstone_lamp 0
setblock ~94 ~1 ~24 quartz_ore 0
setblock ~94 ~1 ~25 noteblock 0
setblock ~94 ~1 ~26 planks 1
setblock ~94 ~1 ~27 noteblock 0
setblock ~94 ~1 ~28 quartz_ore 0
setblock ~94 ~1 ~29 noteblock 0
setblock ~94 ~1 ~30 planks 1
setblock ~94 ~1 ~31 redstone_lamp 0
setblock ~94 ~1 ~32 planks 1
setblock ~94 ~1 ~33 noteblock 0
setblock ~94 ~1 ~34 quartz_ore 0
setblock ~94 ~1 ~35 log 1
setblock ~94 ~1 ~36 quartz_ore 0
setblock ~94 ~1 ~37 stained_hardened_clay 12
setblock ~94 ~1 ~38 mycelium 0
setblock ~94 ~1 ~39 noteblock 0
setblock ~94 ~1 ~40 quartz_ore 0
setblock ~94 ~1 ~41 redstone_lamp 0
setblock ~94 ~1 ~42 quartz_ore 0
setblock ~95 ~1 ~20 noteblock 0
setblock ~95 ~1 ~21 dirt 1
setblock ~95 ~1 ~22 quartz_ore 0
setblock ~95 ~1 ~23 dirt 1
setblock ~95 ~1 ~24 wool 12
setblock ~95 ~1 ~25 planks 1
setblock ~95 ~1 ~26 noteblock 0
setblock ~95 ~1 ~27 dirt 1
setblock ~95 ~1 ~28 wool 12
setblock ~95 ~1 ~29 dirt 1
setblock ~95 ~1 ~30 noteblock 0
setblock ~95 ~1 ~31 dirt 1
setblock ~95 ~1 ~32 wool 12
setblock ~95 ~1 ~33 dirt 1
setblock ~95 ~1 ~34 noteblock 0
setblock ~95 ~1 ~35 quartz_ore 0
setblock ~95 ~1 ~36 noteblock 0
setblock ~95 ~1 ~37 quartz_ore 0
setblock ~95 ~1 ~38 planks 1
setblock ~95 ~1 ~39 dirt 1
setblock ~95 ~1 ~40 noteblock 0
setblock ~95 ~1 ~41 dirt 1
setblock ~95 ~1 ~42 wool 12
setblock ~95 ~1 ~43 quartz_ore 0
fill ~96 ~1 ~17 ~96 ~2 ~17 stained_hardened_clay 12
setblock ~96 ~1 ~18 soul_sand 0
fill ~96 ~1 ~19 ~96 ~2 ~19 stained_hardened_clay 12
setblock ~96 ~1 ~20 dirt 1
setblock ~96 ~1 ~21 noteblock 0
setblock ~96 ~1 ~22 dirt 1
setblock ~96 ~1 ~23 noteblock 0
setblock ~96 ~1 ~24 planks 1
setblock ~96 ~1 ~25 redstone_lamp 0
setblock ~96 ~1 ~26 quartz_ore 0
setblock ~96 ~1 ~27 noteblock 0
setblock ~96 ~1 ~28 quartz_ore 0
setblock ~96 ~1 ~29 noteblock 0
setblock ~96 ~1 ~30 quartz_ore 0
setblock ~96 ~1 ~31 redstone_lamp 0
setblock ~96 ~1 ~32 planks 1
setblock ~96 ~1 ~33 noteblock 0
setblock ~96 ~1 ~34 wool 12
setblock ~96 ~1 ~35 stained_hardened_clay 12
setblock ~96 ~1 ~36 quartz_ore 0
setblock ~96 ~1 ~37 stained_hardened_clay 12
fill ~96 ~1 ~38 ~97 ~1 ~38 dirt 1
setblock ~96 ~1 ~39 noteblock 0
setblock ~96 ~1 ~40 quartz_ore 0
setblock ~96 ~1 ~41 noteblock 0
setblock ~96 ~1 ~42 planks 1
setblock ~96 ~1 ~43 redstone_lamp 0
setblock ~96 ~1 ~44 quartz_ore 0
fill ~97 ~1 ~15 ~97 ~2 ~15 soul_sand 0
fill ~97 ~1 ~16 ~103 ~1 ~16 noteblock 0
setblock ~97 ~1 ~17 dirt 1
setblock ~97 ~1 ~18 quartz_ore 0
setblock ~97 ~1 ~19 dirt 1
setblock ~97 ~1 ~20 quartz_ore 0
setblock ~97 ~1 ~21 dirt 1
setblock ~97 ~1 ~22 quartz_ore 0
setblock ~97 ~1 ~23 dirt 1
setblock ~97 ~1 ~24 wool 12
setblock ~97 ~1 ~25 dirt 1
setblock ~97 ~1 ~26 wool 12
setblock ~97 ~1 ~27 dirt 1
setblock ~97 ~1 ~28 noteblock 0
setblock ~97 ~1 ~29 dirt 1
setblock ~97 ~1 ~30 wool 12
setblock ~97 ~1 ~31 planks 1
setblock ~97 ~1 ~32 wool 12
setblock ~97 ~1 ~33 dirt 1
setblock ~97 ~1 ~34 noteblock 0
setblock ~97 ~1 ~35 wool 12
setblock ~97 ~1 ~36 noteblock 0
setblock ~97 ~1 ~37 quartz_ore 0
setblock ~97 ~1 ~39 dirt 1
setblock ~97 ~1 ~40 noteblock 0
setblock ~97 ~1 ~41 dirt 1
setblock ~97 ~1 ~42 wool 12
setblock ~97 ~1 ~43 dirt 1
setblock ~97 ~1 ~44 wool 12
setblock ~97 ~1 ~45 quartz_ore 0
fill ~98 ~1 ~13 ~98 ~2 ~13 stained_hardened_clay 12
fill ~98 ~1 ~14 ~106 ~1 ~14 soul_sand 0
setblock ~98 ~1 ~15 log 1
setblock ~98 ~1 ~17 stained_hardened_clay 12
setblock ~98 ~1 ~18 dirt 1
setblock ~98 ~1 ~19 noteblock 0
setblock ~98 ~1 ~20 dirt 1
setblock ~98 ~1 ~21 noteblock 0
setblock ~98 ~1 ~22 dirt 1
setblock ~98 ~1 ~23 noteblock 0
setblock ~98 ~1 ~24 planks 1
setblock ~98 ~1 ~25 noteblock 0
setblock ~98 ~1 ~26 planks 1
setblock ~98 ~1 ~27 noteblock 0
setblock ~98 ~1 ~28 quartz_ore 0
setblock ~98 ~1 ~29 noteblock 0
setblock ~98 ~1 ~30 planks 1
setblock ~98 ~1 ~31 redstone_lamp 0
setblock ~98 ~1 ~32 planks 1
setblock ~98 ~1 ~33 noteblock 0
setblock ~98 ~1 ~34 quartz_ore 0
setblock ~98 ~1 ~35 log 1
setblock ~98 ~1 ~36 quartz_ore 0
setblock ~98 ~1 ~37 stained_hardened_clay 12
setblock ~98 ~1 ~38 mycelium 0
setblock ~98 ~1 ~39 noteblock 0
setblock ~98 ~1 ~40 quartz_ore 0
setblock ~98 ~1 ~41 redstone_lamp 0
setblock ~98 ~1 ~42 planks 1
setblock ~98 ~1 ~43 noteblock 0
setblock ~98 ~1 ~44 quartz_ore 0
setblock ~98 ~1 ~45 stained_hardened_clay 12
fill ~98 ~1 ~46 ~99 ~1 ~46 noteblock 0
setblock ~99 ~1 ~12 stained_hardened_clay 12
setblock ~99 ~1 ~13 soul_sand 0
setblock ~99 ~1 ~15 quartz_ore 0
setblock ~99 ~1 ~17 quartz_ore 0
setblock ~99 ~1 ~18 noteblock 0
setblock ~99 ~1 ~19 dirt 1
setblock ~99 ~1 ~20 quartz_ore 0
setblock ~99 ~1 ~21 dirt 1
setblock ~99 ~1 ~22 quartz_ore 0
setblock ~99 ~1 ~23 dirt 1
setblock ~99 ~1 ~24 wool 12
setblock ~99 ~1 ~25 planks 1
setblock ~99 ~1 ~26 noteblock 0
setblock ~99 ~1 ~27 dirt 1
setblock ~99 ~1 ~28 wool 12
setblock ~99 ~1 ~29 dirt 1
setblock ~99 ~1 ~30 noteblock 0
setblock ~99 ~1 ~31 dirt 1
setblock ~99 ~1 ~32 wool 12
setblock ~99 ~1 ~33 dirt 1
setblock ~99 ~1 ~34 noteblock 0
setblock ~99 ~1 ~35 quartz_ore 0
setblock ~99 ~1 ~36 noteblock 0
fill ~99 ~1 ~37 ~99 ~1 ~38 quartz_ore 0
setblock ~99 ~1 ~39 dirt 1
setblock ~99 ~1 ~40 noteblock 0
setblock ~99 ~1 ~41 dirt 1
setblock ~99 ~1 ~42 wool 12
setblock ~99 ~1 ~43 planks 1
setblock ~99 ~1 ~44 wool 12
setblock ~99 ~1 ~45 quartz_ore 0
setblock ~99 ~1 ~47 noteblock 0
setblock ~100 ~1 ~11 stained_hardened_clay 7
setblock ~100 ~1 ~12 soul_sand 0
setblock ~100 ~1 ~13 black_glazed_terracotta 0
setblock ~100 ~1 ~15 stained_hardened_clay 12
setblock ~100 ~1 ~17 stained_hardened_clay 12
setblock ~100 ~1 ~18 quartz_ore 0
setblock ~100 ~1 ~19 noteblock 0
setblock ~100 ~1 ~20 dirt 1
setblock ~100 ~1 ~21 noteblock 0
setblock ~100 ~1 ~22 dirt 1
setblock ~100 ~1 ~23 noteblock 0
setblock ~100 ~1 ~24 planks 1
setblock ~100 ~1 ~25 redstone_lamp 0
setblock ~100 ~1 ~26 quartz_ore 0
setblock ~100 ~1 ~27 noteblock 0
setblock ~100 ~1 ~28 quartz_ore 0
setblock ~100 ~1 ~29 noteblock 0
setblock ~100 ~1 ~30 quartz_ore 0
setblock ~100 ~1 ~31 redstone_lamp 0
setblock ~100 ~1 ~32 planks 1
setblock ~100 ~1 ~33 noteblock 0
setblock ~100 ~1 ~34 wool 12
setblock ~100 ~1 ~35 stained_hardened_clay 12
setblock ~100 ~1 ~36 quartz_ore 0
setblock ~100 ~1 ~37 stained_hardened_clay 12
fill ~100 ~1 ~38 ~101 ~1 ~38 dirt 1
setblock ~100 ~1 ~39 noteblock 0
setblock ~100 ~1 ~40 quartz_ore 0
setblock ~100 ~1 ~41 noteblock 0
setblock ~100 ~1 ~42 planks 1
setblock ~100 ~1 ~43 redstone_lamp 0
setblock ~100 ~1 ~44 quartz_ore 0
setblock ~100 ~1 ~45 stained_hardened_clay 12
setblock ~100 ~1 ~46 wool 12
setblock ~100 ~1 ~47 log 1
setblock ~100 ~1 ~48 noteblock 0
setblock ~101 ~1 ~11 soul_sand 0
setblock ~101 ~1 ~12 noteblock 0
setblock ~101 ~1 ~13 soul_sand 0
setblock ~101 ~1 ~15 quartz_ore 0
setblock ~101 ~1 ~17 dirt 1
setblock ~101 ~1 ~18 soul_sand 0
setblock ~101 ~1 ~19 dirt 1
setblock ~101 ~1 ~20 quartz_ore 0
setblock ~101 ~1 ~21 dirt 1
setblock ~101 ~1 ~22 quartz_ore 0
setblock ~101 ~1 ~23 dirt 1
setblock ~101 ~1 ~24 wool 12
setblock ~101 ~1 ~25 dirt 1
setblock ~101 ~1 ~26 wool 12
setblock ~101 ~1 ~27 dirt 1
setblock ~101 ~1 ~28 noteblock 0
setblock ~101 ~1 ~29 dirt 1
setblock ~101 ~1 ~30 wool 12
setblock ~101 ~1 ~31 planks 1
setblock ~101 ~1 ~32 wool 12
setblock ~101 ~1 ~33 dirt 1
setblock ~101 ~1 ~34 noteblock 0
setblock ~101 ~1 ~35 wool 12
setblock ~101 ~1 ~36 noteblock 0
setblock ~101 ~1 ~37 quartz_ore 0
setblock ~101 ~1 ~39 dirt 1
setblock ~101 ~1 ~40 noteblock 0
setblock ~101 ~1 ~41 dirt 1
setblock ~101 ~1 ~42 wool 12
setblock ~101 ~1 ~43 dirt 1
setblock ~101 ~1 ~44 concrete 12
setblock ~101 ~1 ~45 quartz_ore 0
setblock ~101 ~1 ~46 noteblock 0
setblock ~101 ~1 ~47 wool 12
setblock ~101 ~1 ~48 redstone_lamp 0
setblock ~101 ~1 ~49 noteblock 0
setblock ~102 ~1 ~10 soul_sand 0
setblock ~102 ~1 ~11 black_glazed_terracotta 0
setblock ~102 ~1 ~12 soul_sand 0
setblock ~102 ~1 ~13 log 1
setblock ~102 ~1 ~15 stained_hardened_clay 12
setblock ~102 ~1 ~17 stained_hardened_clay 12
setblock ~102 ~1 ~18 dirt 1
setblock ~102 ~1 ~19 noteblock 0
setblock ~102 ~1 ~20 dirt 1
setblock ~102 ~1 ~21 noteblock 0
setblock ~102 ~1 ~22 dirt 1
setblock ~102 ~1 ~23 noteblock 0
setblock ~102 ~1 ~24 planks 1
setblock ~102 ~1 ~25 noteblock 0
setblock ~102 ~1 ~26 planks 1
setblock ~102 ~1 ~27 noteblock 0
setblock ~102 ~1 ~28 quartz_ore 0
setblock ~102 ~1 ~29 noteblock 0
setblock ~102 ~1 ~30 planks 1
setblock ~102 ~1 ~31 redstone_lamp 0
setblock ~102 ~1 ~32 planks 1
setblock ~102 ~1 ~33 noteblock 0
setblock ~102 ~1 ~34 wool 12
setblock ~102 ~1 ~35 log 1
setblock ~102 ~1 ~36 quartz_ore 0
setblock ~102 ~1 ~37 stained_hardened_clay 12
setblock ~102 ~1 ~38 mycelium 0
setblock ~102 ~1 ~39 noteblock 0
setblock ~102 ~1 ~40 quartz_ore 0
setblock ~102 ~1 ~41 redstone_lamp 0
setblock ~102 ~1 ~42 planks 1
setblock ~102 ~1 ~43 noteblock 0
fill ~102 ~1 ~44 ~103 ~1 ~44 wool 12
setblock ~102 ~1 ~45 stained_hardened_clay 12
setblock ~102 ~1 ~46 wool 12
setblock ~102 ~1 ~47 log 1
setblock ~102 ~1 ~48 noteblock 0
setblock ~102 ~1 ~49 planks 5
setblock ~102 ~1 ~50 stained_hardened_clay 12
fill ~103 ~1 ~9 ~103 ~1 ~10 stained_hardened_clay 12
setblock ~103 ~1 ~11 soul_sand 0
setblock ~103 ~1 ~12 noteblock 0
setblock ~103 ~1 ~13 soul_sand 0
setblock ~103 ~1 ~15 quartz_ore 0
setblock ~103 ~1 ~17 quartz_ore 0
setblock ~103 ~1 ~18 noteblock 0
setblock ~103 ~1 ~19 dirt 1
setblock ~103 ~1 ~20 quartz_ore 0
setblock ~103 ~1 ~21 dirt 1
setblock ~103 ~1 ~22 quartz_ore 0
setblock ~103 ~1 ~23 dirt 1
setblock ~103 ~1 ~24 wool 12
setblock ~103 ~1 ~25 planks 1
setblock ~103 ~1 ~26 noteblock 0
setblock ~103 ~1 ~27 dirt 1
setblock ~103 ~1 ~28 wool 12
setblock ~103 ~1 ~29 dirt 1
setblock ~103 ~1 ~30 noteblock 0
setblock ~103 ~1 ~31 dirt 1
setblock ~103 ~1 ~32 wool 12
setblock ~103 ~1 ~33 dirt 1
setblock ~103 ~1 ~34 noteblock 0
setblock ~103 ~1 ~35 quartz_ore 0
setblock ~103 ~1 ~36 noteblock 0
setblock ~103 ~1 ~37 quartz_ore 0
setblock ~103 ~1 ~38 planks 1
setblock ~103 ~1 ~39 dirt 1
setblock ~103 ~1 ~40 noteblock 0
setblock ~103 ~1 ~41 dirt 1
setblock ~103 ~1 ~42 wool 12
setblock ~103 ~1 ~43 planks 1
setblock ~103 ~1 ~45 quartz_ore 0
setblock ~103 ~1 ~46 noteblock 0
setblock ~103 ~1 ~47 wool 12
setblock ~103 ~1 ~48 redstone_lamp 0
setblock ~103 ~1 ~49 noteblock 0
setblock ~103 ~1 ~50 planks 5
fill ~103 ~1 ~51 ~103 ~2 ~51 stained_hardened_clay 12
setblock ~104 ~1 ~8 log 1
setblock ~104 ~1 ~9 planks 5
setblock ~104 ~1 ~10 soul_sand 0
setblock ~104 ~1 ~11 black_glazed_terracotta 0
setblock ~104 ~1 ~12 soul_sand 0
setblock ~104 ~1 ~13 black_glazed_terracotta 0
setblock ~104 ~1 ~15 stained_hardened_clay 12
fill ~104 ~1 ~16 ~108 ~1 ~16 soul_sand 0
setblock ~104 ~1 ~17 stained_hardened_clay 12
setblock ~104 ~1 ~18 quartz_ore 0
setblock ~104 ~1 ~19 noteblock 0
setblock ~104 ~1 ~20 dirt 1
setblock ~104 ~1 ~21 noteblock 0
setblock ~104 ~1 ~22 dirt 1
setblock ~104 ~1 ~23 noteblock 0
setblock ~104 ~1 ~24 planks 1
setblock ~104 ~1 ~25 redstone_lamp 0
setblock ~104 ~1 ~26 quartz_ore 0
setblock ~104 ~1 ~27 noteblock 0
setblock ~104 ~1 ~28 quartz_ore 0
setblock ~104 ~1 ~29 noteblock 0
setblock ~104 ~1 ~30 quartz_ore 0
setblock ~104 ~1 ~31 noteblock 0
setblock ~104 ~1 ~32 planks 1
setblock ~104 ~1 ~33 noteblock 0
setblock ~104 ~1 ~34 wool 12
setblock ~104 ~1 ~35 stained_hardened_clay 12
setblock ~104 ~1 ~36 quartz_ore 0
setblock ~104 ~1 ~37 stained_hardened_clay 12
setblock ~104 ~1 ~38 dirt 1
setblock ~104 ~1 ~39 noteblock 0
setblock ~104 ~1 ~40 quartz_ore 0
setblock ~104 ~1 ~41 noteblock 0
setblock ~104 ~1 ~42 planks 1
setblock ~104 ~1 ~43 redstone_lamp 0
setblock ~104 ~1 ~44 quartz_ore 0
setblock ~104 ~1 ~45 stained_hardened_clay 12
setblock ~104 ~1 ~46 wool 12
setblock ~104 ~1 ~47 log 1
setblock ~104 ~1 ~48 noteblock 0
setblock ~104 ~1 ~49 planks 5
setblock ~104 ~1 ~50 log 1
setblock ~105 ~1 ~8 black_glazed_terracotta 0
setblock ~105 ~1 ~9 soul_sand 0
fill ~105 ~1 ~10 ~106 ~1 ~10 stained_hardened_clay 12
setblock ~105 ~1 ~11 soul_sand 0
setblock ~105 ~1 ~12 noteblock 0
setblock ~105 ~1 ~13 soul_sand 0
setblock ~105 ~1 ~15 quartz_ore 0
setblock ~105 ~1 ~17 quartz_ore 0
setblock ~105 ~1 ~18 soul_sand 0
setblock ~105 ~1 ~19 dirt 1
setblock ~105 ~1 ~20 quartz_ore 0
setblock ~105 ~1 ~21 dirt 1
setblock ~105 ~1 ~22 quartz_ore 0
setblock ~105 ~1 ~23 dirt 1
setblock ~105 ~1 ~24 wool 12 KittysCommands:
setblock ~105 ~1 ~25 dirt 1
setblock ~105 ~1 ~26 wool 12
setblock ~105 ~1 ~27 dirt 1
setblock ~105 ~1 ~28 noteblock 0
setblock ~105 ~1 ~29 dirt 1
setblock ~105 ~1 ~30 wool 12
setblock ~105 ~1 ~31 planks 1
setblock ~105 ~1 ~32 wool 12
setblock ~105 ~1 ~33 dirt 1
setblock ~105 ~1 ~34 noteblock 0
setblock ~105 ~1 ~35 wool 12
setblock ~105 ~1 ~36 noteblock 0
setblock ~105 ~1 ~37 quartz_ore 0
setblock ~105 ~1 ~38 planks 1
setblock ~105 ~1 ~39 dirt 1
setblock ~105 ~1 ~40 noteblock 0
setblock ~105 ~1 ~41 dirt 1
setblock ~105 ~1 ~42 wool 12
setblock ~105 ~1 ~43 dirt 1
setblock ~105 ~1 ~44 wool 12
setblock ~105 ~1 ~45 quartz_ore 0
setblock ~105 ~1 ~46 noteblock 0
setblock ~105 ~1 ~47 wool 12
setblock ~105 ~1 ~48 redstone_lamp 0
setblock ~105 ~1 ~49 noteblock 0
setblock ~106 ~1 ~9 planks 5
setblock ~106 ~1 ~11 planks 5
setblock ~106 ~1 ~12 soul_sand 0
setblock ~106 ~1 ~13 log 1
setblock ~106 ~1 ~15 stained_hardened_clay 12
setblock ~106 ~1 ~17 stained_hardened_clay 12
setblock ~106 ~1 ~18 quartz_ore 0
setblock ~106 ~1 ~19 noteblock 0
setblock ~106 ~1 ~20 dirt 1
setblock ~106 ~1 ~21 noteblock 0
setblock ~106 ~1 ~22 dirt 1
setblock ~106 ~1 ~23 noteblock 0
setblock ~106 ~1 ~24 planks 1
setblock ~106 ~1 ~25 noteblock 0
setblock ~106 ~1 ~26 planks 1
setblock ~106 ~1 ~27 noteblock 0
setblock ~106 ~1 ~28 quartz_ore 0
setblock ~106 ~1 ~29 noteblock 0
setblock ~106 ~1 ~30 quartz_ore 0
setblock ~106 ~1 ~31 redstone_lamp 0
setblock ~106 ~1 ~32 planks 1
setblock ~106 ~1 ~33 noteblock 0
setblock ~106 ~1 ~34 wool 12
setblock ~106 ~1 ~35 log 1
setblock ~106 ~1 ~36 quartz_ore 0
setblock ~106 ~1 ~37 stained_hardened_clay 12
setblock ~106 ~1 ~38 dirt 1
setblock ~106 ~1 ~39 noteblock 0
setblock ~106 ~1 ~40 quartz_ore 0
setblock ~106 ~1 ~41 redstone_lamp 0
setblock ~106 ~1 ~42 planks 1
setblock ~106 ~1 ~43 noteblock 0
setblock ~106 ~1 ~44 quartz_ore 0
setblock ~106 ~1 ~45 stained_hardened_clay 12
setblock ~106 ~1 ~46 wool 12
setblock ~106 ~1 ~47 log 1
setblock ~106 ~1 ~48 noteblock 0
setblock ~106 ~1 ~49 planks 5
setblock ~107 ~1 ~11 soul_sand 0
fill ~107 ~1 ~12 ~108 ~1 ~12 noteblock 0
setblock ~107 ~1 ~13 soul_sand 0
fill ~107 ~1 ~14 ~109 ~1 ~14 noteblock 0
setblock ~107 ~1 ~15 dirt 1
setblock ~107 ~1 ~17 soul_sand 0
setblock ~107 ~1 ~18 noteblock 0
setblock ~107 ~1 ~19 dirt 1
setblock ~107 ~1 ~20 soul_sand 0
setblock ~107 ~1 ~21 dirt 1
setblock ~107 ~1 ~22 quartz_ore 0
setblock ~107 ~1 ~23 dirt 1
setblock ~107 ~1 ~24 wool 12
setblock ~107 ~1 ~25 planks 1
setblock ~107 ~1 ~26 noteblock 0
setblock ~107 ~1 ~27 dirt 1
setblock ~107 ~1 ~28 wool 12
setblock ~107 ~1 ~29 dirt 1
setblock ~107 ~1 ~30 noteblock 0
setblock ~107 ~1 ~31 dirt 1
setblock ~107 ~1 ~32 wool 12
setblock ~107 ~1 ~33 dirt 1
setblock ~107 ~1 ~34 noteblock 0
setblock ~107 ~1 ~35 quartz_ore 0
setblock ~107 ~1 ~36 noteblock 0
setblock ~107 ~1 ~37 dirt 1
setblock ~107 ~1 ~38 quartz_ore 0
setblock ~107 ~1 ~39 dirt 1
setblock ~107 ~1 ~40 noteblock 0
setblock ~107 ~1 ~41 dirt 1
setblock ~107 ~1 ~42 wool 12
setblock ~107 ~1 ~43 planks 1
setblock ~107 ~1 ~44 wool 12
setblock ~107 ~1 ~45 quartz_ore 0
setblock ~107 ~1 ~46 noteblock 0
setblock ~107 ~1 ~47 wool 12
setblock ~107 ~1 ~48 stained_hardened_clay 12
setblock ~108 ~1 ~13 black_glazed_terracotta 0
setblock ~108 ~1 ~15 stained_hardened_clay 12
setblock ~108 ~1 ~17 log 1
setblock ~108 ~1 ~18 quartz_ore 0
setblock ~108 ~1 ~19 noteblock 0
setblock ~108 ~1 ~20 dirt 1
setblock ~108 ~1 ~21 noteblock 0
setblock ~108 ~1 ~22 dirt 1
setblock ~108 ~1 ~23 noteblock 0
setblock ~108 ~1 ~24 planks 1
setblock ~108 ~1 ~25 redstone_lamp 0
setblock ~108 ~1 ~26 quartz_ore 0
setblock ~108 ~1 ~27 noteblock 0
setblock ~108 ~1 ~28 quartz_ore 0
setblock ~108 ~1 ~29 noteblock 0
setblock ~108 ~1 ~30 quartz_ore 0
setblock ~108 ~1 ~31 noteblock 0
setblock ~108 ~1 ~32 planks 1
setblock ~108 ~1 ~33 noteblock 0
setblock ~108 ~1 ~34 wool 12
setblock ~108 ~1 ~35 stained_hardened_clay 12
setblock ~108 ~1 ~36 quartz_ore 0
setblock ~108 ~1 ~37 redstone_lamp 0
fill ~108 ~1 ~38 ~109 ~1 ~38 dirt 1
setblock ~108 ~1 ~39 noteblock 0
setblock ~108 ~1 ~40 quartz_ore 0
setblock ~108 ~1 ~41 noteblock 0
setblock ~108 ~1 ~42 planks 1
setblock ~108 ~1 ~43 redstone_lamp 0
setblock ~108 ~1 ~44 quartz_ore 0
setblock ~108 ~1 ~45 stained_hardened_clay 12
setblock ~108 ~1 ~46 wool 12
fill ~108 ~1 ~47 ~108 ~2 ~47 log 1
setblock ~109 ~1 ~13 noteblock 0
setblock ~109 ~1 ~15 soul_sand 0
setblock ~109 ~1 ~16 noteblock 0
setblock ~109 ~1 ~17 quartz_ore 0
setblock ~109 ~1 ~18 noteblock 0
setblock ~109 ~1 ~19 quartz_ore 0
setblock ~109 ~1 ~20 noteblock 0
setblock ~109 ~1 ~21 dirt 1
setblock ~109 ~1 ~22 quartz_ore 0
setblock ~109 ~1 ~23 dirt 1
setblock ~109 ~1 ~24 noteblock 0
setblock ~109 ~1 ~25 dirt 1
setblock ~109 ~1 ~26 wool 12
setblock ~109 ~1 ~27 dirt 1
setblock ~109 ~1 ~28 noteblock 0
setblock ~109 ~1 ~29 dirt 1
setblock ~109 ~1 ~30 wool 12
setblock ~109 ~1 ~31 planks 1
setblock ~109 ~1 ~32 wool 12
setblock ~109 ~1 ~33 dirt 1
setblock ~109 ~1 ~34 noteblock 0
setblock ~109 ~1 ~35 wool 12
setblock ~109 ~1 ~36 noteblock 0
setblock ~109 ~1 ~37 quartz_ore 0
setblock ~109 ~1 ~39 dirt 1
setblock ~109 ~1 ~40 noteblock 0
setblock ~109 ~1 ~41 dirt 1
setblock ~109 ~1 ~42 wool 12
setblock ~109 ~1 ~43 dirt 1
setblock ~109 ~1 ~44 wool 12
setblock ~109 ~1 ~45 quartz_ore 0
setblock ~109 ~1 ~46 noteblock 0
setblock ~110 ~1 ~26 quartz_ore 0
fill ~110 ~1 ~27 ~110 ~2 ~27 stained_hardened_clay 12
setblock ~110 ~1 ~28 quartz_ore 0
setblock ~110 ~1 ~29 noteblock 0
setblock ~110 ~1 ~30 quartz_ore 0
setblock ~110 ~1 ~31 redstone_lamp 0
setblock ~110 ~1 ~32 planks 1
setblock ~110 ~1 ~33 noteblock 0
setblock ~110 ~1 ~34 wool 12
setblock ~110 ~1 ~35 log 1
setblock ~110 ~1 ~36 quartz_ore 0
setblock ~110 ~1 ~37 stained_hardened_clay 12
setblock ~110 ~1 ~38 mycelium 0
setblock ~110 ~1 ~39 noteblock 0
setblock ~110 ~1 ~40 quartz_ore 0
setblock ~110 ~1 ~41 redstone_lamp 0
setblock ~110 ~1 ~42 planks 1
setblock ~110 ~1 ~43 noteblock 0
setblock ~110 ~1 ~44 quartz_ore 0
fill ~110 ~1 ~45 ~110 ~2 ~45 stained_hardened_clay 12
setblock ~110 ~1 ~46 wool 12
setblock ~111 ~1 ~30 noteblock 0
setblock ~111 ~1 ~31 planks 1
setblock ~111 ~1 ~32 wool 12
setblock ~111 ~1 ~33 planks 1
setblock ~111 ~1 ~34 noteblock 0
setblock ~111 ~1 ~35 quartz_ore 0
setblock ~111 ~1 ~36 noteblock 0
fill ~111 ~1 ~37 ~111 ~1 ~38 quartz_ore 0
setblock ~111 ~1 ~39 dirt 1
setblock ~111 ~1 ~40 wool 12
setblock ~111 ~1 ~41 dirt 1
setblock ~111 ~1 ~42 noteblock 0
setblock ~111 ~1 ~43 planks 1
setblock ~111 ~1 ~44 wool 12
setblock ~112 ~1 ~35 stained_hardened_clay 12
setblock ~112 ~1 ~36 quartz_ore 0
fill ~136 ~1 ~35 ~136 ~2 ~35 stained_hardened_clay 12
setblock ~136 ~1 ~36 quartz_ore 0
setblock ~136 ~1 ~37 stained_hardened_clay 12
setblock ~136 ~1 ~38 quartz_ore 0
fill ~137 ~1 ~31 ~137 ~3 ~31 soul_sand 0
setblock ~137 ~1 ~32 noteblock 0
setblock ~137 ~1 ~33 soul_sand 0
setblock ~137 ~1 ~34 noteblock 0
fill ~137 ~1 ~39 ~137 ~1 ~40 quartz_ore 0
setblock ~137 ~1 ~41 dirt 1
setblock ~137 ~1 ~42 quartz_ore 0
setblock ~137 ~1 ~43 dirt 1
setblock ~137 ~1 ~44 wool 12
setblock ~137 ~1 ~45 dirt 1
setblock ~137 ~1 ~46 noteblock 0
setblock ~138 ~1 ~16 soul_sand 0
setblock ~138 ~1 ~17 stained_hardened_clay 12
setblock ~138 ~1 ~18 noteblock 0
setblock ~138 ~1 ~19 stained_hardened_clay 12
setblock ~138 ~1 ~20 soul_sand 0
setblock ~138 ~1 ~27 redstone_lamp 0
setblock ~138 ~1 ~28 soul_sand 0
setblock ~138 ~1 ~29 black_glazed_terracotta 0
setblock ~138 ~1 ~30 soul_sand 0
setblock ~138 ~1 ~47 stained_hardened_clay 12
fill ~139 ~1 ~14 ~139 ~1 ~15 soul_sand 0
fill ~139 ~1 ~22 ~139 ~0 ~22 noteblock 0
setblock ~139 ~1 ~24 stained_hardened_clay 12
setblock ~139 ~1 ~25 noteblock 0
setblock ~139 ~1 ~48 redstone_lamp 0
setblock ~140 ~1 ~13 black_glazed_terracotta 0
setblock ~140 ~1 ~48 soul_sand 0
fill ~142 ~1 ~11 ~142 ~3 ~11 stained_hardened_clay 15
setblock ~142 ~1 ~50 stained_hardened_clay 12
setblock ~143 ~1 ~9 stained_hardened_clay 7
fill ~143 ~1 ~10 ~144 ~1 ~10 black_glazed_terracotta 0
setblock ~143 ~1 ~51 noteblock 0
setblock ~144 ~1 ~51 nether_brick 0
setblock ~144 ~1 ~52 stained_hardened_clay 12
setblock ~145 ~1 ~51 stained_hardened_clay 12
fill ~145 ~1 ~52 ~145 ~4 ~52 black_glazed_terracotta 0
setblock ~146 ~1 ~11 planks 5
setblock ~146 ~1 ~51 planks 5
setblock ~147 ~1 ~50 stained_hardened_clay 12
setblock ~148 ~1 ~12 soul_sand 0
fill ~148 ~1 ~49 ~148 ~2 ~49 planks 5
setblock ~149 ~1 ~13 soul_sand 0
setblock ~149 ~1 ~48 noteblock 0
setblock ~150 ~1 ~14 noteblock 0
fill ~150 ~1 ~15 ~150 ~2 ~15 log 1
setblock ~150 ~1 ~47 stained_hardened_clay 12
setblock ~151 ~1 ~16 noteblock 0
fill ~151 ~1 ~17 ~151 ~1 ~18 soul_sand 0
setblock ~151 ~1 ~46 noteblock 0
fill ~152 ~1 ~19 ~152 ~2 ~19 stained_hardened_clay 12
setblock ~152 ~1 ~20 soul_sand 0
fill ~152 ~1 ~45 ~152 ~2 ~45 stained_hardened_clay 12
setblock ~153 ~1 ~21 soul_sand 0
setblock ~153 ~1 ~22 noteblock 0
setblock ~153 ~1 ~23 dirt 1
setblock ~153 ~1 ~45 quartz_ore 0
setblock ~154 ~1 ~24 noteblock 0
setblock ~154 ~1 ~25 log 1
setblock ~154 ~1 ~26 planks 1
setblock ~154 ~1 ~44 quartz_ore 0
setblock ~155 ~1 ~27 dirt 1
setblock ~155 ~1 ~28 noteblock 0
setblock ~155 ~1 ~29 quartz_ore 0
setblock ~155 ~1 ~30 noteblock 0
setblock ~155 ~1 ~31 soul_sand 0
setblock ~155 ~1 ~32 noteblock 0
setblock ~155 ~1 ~33 quartz_ore 0
fill ~155 ~1 ~34 ~155 ~1 ~35 soul_sand 0
setblock ~155 ~1 ~36 noteblock 0
setblock ~155 ~1 ~37 quartz_ore 0
setblock ~155 ~1 ~38 noteblock 0
setblock ~155 ~1 ~39 dirt 1
setblock ~155 ~1 ~40 noteblock 0
setblock ~155 ~1 ~41 dirt 1
setblock ~155 ~1 ~42 noteblock 0
setblock ~155 ~1 ~43 planks 1
setblock ~93 ~2 ~25 noteblock 0
setblock ~93 ~2 ~26 stained_hardened_clay 12
setblock ~93 ~2 ~28 stained_hardened_clay 12
setblock ~93 ~2 ~29 soul_sand 0
setblock ~93 ~2 ~30 stained_hardened_clay 12
setblock ~93 ~2 ~31 soul_sand 0
setblock ~93 ~2 ~32 log 1
setblock ~93 ~2 ~33 soul_sand 0
fill ~93 ~2 ~34 ~93 ~2 ~36 stained_hardened_clay 12
fill ~93 ~2 ~37 ~93 ~2 ~38 noteblock 0
setblock ~93 ~2 ~39 quartz_ore 0
setblock ~93 ~2 ~40 noteblock 0
fill ~94 ~2 ~22 ~94 ~3 ~22 stained_hardened_clay 12
setblock ~94 ~2 ~23 stained_hardened_clay 7
setblock ~94 ~2 ~24 stained_hardened_clay 15
setblock ~94 ~2 ~41 noteblock 0
setblock ~94 ~2 ~42 stained_hardened_clay 12
fill ~95 ~2 ~20 ~95 ~3 ~20 stained_hardened_clay 12
fill ~95 ~2 ~21 ~95 ~6 ~21 soul_sand 0
setblock ~95 ~2 ~43 noteblock 0
setblock ~96 ~2 ~18 black_glazed_terracotta 0
setblock ~96 ~2 ~44 planks 5
setblock ~97 ~2 ~16 black_glazed_terracotta 0
setblock ~97 ~2 ~45 noteblock 0
setblock ~98 ~2 ~14 planks 5
setblock ~98 ~2 ~46 planks 5
fill ~99 ~2 ~12 ~99 ~3 ~12 black_glazed_terracotta 0
setblock ~99 ~2 ~47 stained_hardened_clay 12
setblock ~100 ~2 ~11 black_glazed_terracotta 0
setblock ~100 ~2 ~48 stained_hardened_clay 15
fill ~101 ~2 ~11 ~101 ~3 ~11 stained_hardened_clay 7
setblock ~101 ~2 ~49 log 1
fill ~102 ~2 ~10 ~102 ~4 ~10 stained_hardened_clay 15
setblock ~102 ~2 ~50 stained_hardened_clay 15
setblock ~103 ~2 ~9 planks 5
fill ~104 ~2 ~8 ~105 ~2 ~8 stained_hardened_clay 15
setblock ~104 ~2 ~50 stained_hardened_clay 15
setblock ~105 ~2 ~49 log 1
fill ~106 ~2 ~9 ~106 ~6 ~9 stained_hardened_clay 15
fill ~106 ~2 ~10 ~106 ~4 ~10 stained_hardened_clay 15
setblock ~106 ~2 ~48 planks 5
setblock ~107 ~2 ~11 planks 5
setblock ~107 ~2 ~47 stained_hardened_clay 12
setblock ~108 ~2 ~12 stained_hardened_clay 15
setblock ~109 ~2 ~13 stained_hardened_clay 12
fill ~109 ~2 ~14 ~109 ~3 ~14 stained_hardened_clay 15
setblock ~109 ~2 ~21 quartz_ore 0
setblock ~109 ~2 ~22 stained_hardened_clay 12
setblock ~109 ~2 ~23 noteblock 0
setblock ~109 ~2 ~24 planks 5
setblock ~109 ~2 ~46 stained_hardened_clay 12
fill ~110 ~2 ~15 ~110 ~2 ~16 black_glazed_terracotta 0
setblock ~110 ~2 ~17 stained_hardened_clay 12
setblock ~110 ~2 ~18 black_glazed_terracotta 0
setblock ~110 ~2 ~19 stained_hardened_clay 12
setblock ~110 ~2 ~20 planks 5
setblock ~110 ~2 ~25 stained_hardened_clay 12
setblock ~110 ~2 ~26 log 1
setblock ~110 ~2 ~28 planks 5
setblock ~110 ~2 ~29 stained_hardened_clay 12
setblock ~111 ~2 ~30 log 1
fill ~111 ~2 ~31 ~111 ~3 ~31 soul_sand 0
fill ~111 ~2 ~32 ~111 ~3 ~32 stained_hardened_clay 12
setblock ~111 ~2 ~33 noteblock 0
setblock ~111 ~2 ~34 log 1
setblock ~111 ~2 ~37 wool 12
fill ~111 ~2 ~38 ~111 ~3 ~38 noteblock 0
setblock ~111 ~2 ~39 planks 1
fill ~111 ~2 ~40 ~111 ~3 ~40 noteblock 0
fill ~111 ~2 ~41 ~111 ~2 ~40 noteblock 0
setblock ~111 ~2 ~42 stained_hardened_clay 12
fill ~111 ~2 ~43 ~111 ~3 ~43 noteblock 0
setblock ~111 ~2 ~44 stained_hardened_clay 12
setblock ~112 ~2 ~35 noteblock 0
setblock ~112 ~2 ~36 stained_hardened_clay 12
setblock ~136 ~2 ~36 black_glazed_terracotta 0
setblock ~136 ~2 ~37 noteblock 0
setblock ~136 ~2 ~38 planks 5
setblock ~137 ~2 ~30 log 1
fill ~137 ~2 ~32 ~137 ~3 ~32 stained_hardened_clay 12
setblock ~137 ~2 ~33 noteblock 0
setblock ~137 ~2 ~34 log 1
fill ~137 ~2 ~39 ~137 ~2 ~40 noteblock 0
setblock ~137 ~2 ~41 wool 12
setblock ~137 ~2 ~42 stained_hardened_clay 12
setblock ~137 ~2 ~43 noteblock 0
setblock ~137 ~2 ~44 stained_hardened_clay 12
fill ~137 ~2 ~45 ~137 ~3 ~45 noteblock 0
setblock ~138 ~2 ~16 black_glazed_terracotta 0
setblock ~138 ~2 ~17 log 1
setblock ~138 ~2 ~18 stained_hardened_clay 15
setblock ~138 ~2 ~19 stained_hardened_clay 7
setblock ~138 ~2 ~20 black_glazed_terracotta 0
setblock ~138 ~2 ~21 stained_hardened_clay 12
setblock ~138 ~2 ~22 black_glazed_terracotta 0
setblock ~138 ~2 ~23 noteblock 0
setblock ~138 ~2 ~24 log 1
setblock ~138 ~2 ~25 planks 5
setblock ~138 ~2 ~26 black_glazed_terracotta 0
setblock ~138 ~2 ~27 noteblock 0
setblock ~138 ~2 ~28 planks 5
setblock ~138 ~2 ~29 stained_hardened_clay 12
setblock ~138 ~2 ~46 black_glazed_terracotta 0
fill ~138 ~2 ~47 ~139 ~2 ~47 noteblock 0
fill ~139 ~2 ~15 ~139 ~3 ~15 stained_hardened_clay 7
fill ~140 ~2 ~13 ~140 ~5 ~13 stained_hardened_clay 15
fill ~140 ~2 ~14 ~140 ~2 ~13 stained_hardened_clay 15
setblock ~140 ~2 ~48 planks 5
fill ~141 ~2 ~12 ~141 ~3 ~12 stained_hardened_clay 15
setblock ~141 ~2 ~49 stained_hardened_clay 12
setblock ~142 ~2 ~50 black_glazed_terracotta 0
setblock ~143 ~2 ~9 nether_brick 0
fill ~143 ~2 ~10 ~144 ~2 ~10 stained_hardened_clay 15
setblock ~143 ~2 ~50 planks 5
setblock ~144 ~2 ~51 black_glazed_terracotta 0
fill ~145 ~2 ~11 ~145 ~4 ~11 black_glazed_terracotta 0
fill ~146 ~2 ~11 ~146 ~5 ~11 stained_hardened_clay 15
setblock ~146 ~2 ~51 black_glazed_terracotta 0
fill ~147 ~2 ~12 ~147 ~4 ~12 stained_hardened_clay 15
setblock ~147 ~2 ~50 stained_hardened_clay 15
setblock ~148 ~2 ~13 planks 5
setblock ~149 ~2 ~13 stained_hardened_clay 7
fill ~149 ~2 ~48 ~149 ~3 ~48 black_glazed_terracotta 0
setblock ~150 ~2 ~14 black_glazed_terracotta 0
setblock ~150 ~2 ~47 noteblock 0
setblock ~151 ~2 ~16 planks 5
setblock ~151 ~2 ~17 stained_hardened_clay 12
setblock ~151 ~2 ~18 black_glazed_terracotta 0
fill ~151 ~2 ~46 ~151 ~3 ~46 stained_hardened_clay 12
setblock ~152 ~2 ~20 black_glazed_terracotta 0
fill ~153 ~2 ~21 ~153 ~3 ~21 stained_hardened_clay 12
setblock ~153 ~2 ~22 log 1
setblock ~153 ~2 ~23 noteblock 0
fill ~153 ~2 ~44 ~153 ~3 ~44 stained_hardened_clay 12
setblock ~154 ~2 ~24 planks 5
setblock ~154 ~2 ~25 log2 1
setblock ~154 ~2 ~26 planks 5
setblock ~154 ~2 ~27 stained_hardened_clay 12
setblock ~154 ~2 ~28 planks 5
setblock ~154 ~2 ~29 stained_hardened_clay 12
setblock ~154 ~2 ~30 black_glazed_terracotta 0
setblock ~154 ~2 ~31 stained_hardened_clay 12
setblock ~154 ~2 ~37 stained_hardened_clay 7
setblock ~154 ~2 ~38 planks 5
setblock ~154 ~2 ~39 noteblock 0
setblock ~154 ~2 ~40 black_glazed_terracotta 0
setblock ~154 ~2 ~41 noteblock 0
setblock ~154 ~2 ~42 stained_hardened_clay 12
setblock ~154 ~2 ~43 noteblock 0
setblock ~155 ~2 ~32 log 1
setblock ~155 ~2 ~33 noteblock 0
setblock ~155 ~2 ~34 log 1
setblock ~155 ~2 ~35 soul_sand 0
setblock ~155 ~2 ~36 stained_hardened_clay 12
setblock ~93 ~3 ~29 stained_hardened_clay 12
setblock ~94 ~3 ~23 stained_hardened_clay 15
fill ~94 ~3 ~24 ~94 ~3 ~25 stained_hardened_clay 7
setblock ~94 ~3 ~26 soul_sand 0
setblock ~94 ~3 ~27 stained_hardened_clay 7
setblock ~94 ~3 ~28 soul_sand 0
setblock ~94 ~3 ~30 stained_hardened_clay 12
setblock ~94 ~3 ~31 black_glazed_terracotta 0
fill ~94 ~3 ~32 ~94 ~4 ~32 stained_hardened_clay 12
setblock ~94 ~3 ~33 black_glazed_terracotta 0
setblock ~94 ~3 ~34 soul_sand 0
setblock ~94 ~3 ~35 planks 5
setblock ~94 ~3 ~36 stained_hardened_clay 12
fill ~94 ~3 ~37 ~94 ~4 ~37 black_glazed_terracotta 0
setblock ~94 ~3 ~38 noteblock 0
setblock ~94 ~3 ~39 planks 5
setblock ~94 ~3 ~40 noteblock 0
setblock ~94 ~3 ~41 planks 5
setblock ~95 ~3 ~19 soul_sand 0
setblock ~95 ~3 ~42 stained_hardened_clay 12
setblock ~96 ~3 ~17 black_glazed_terracotta 0
setblock ~96 ~3 ~18 stained_hardened_clay 12
setblock ~96 ~3 ~43 log 1
fill ~97 ~3 ~15 ~97 ~4 ~15 stained_hardened_clay 12
fill ~97 ~3 ~16 ~97 ~4 ~16 stained_hardened_clay 7
fill ~97 ~3 ~44 ~97 ~4 ~44 stained_hardened_clay 12
setblock ~98 ~3 ~13 stained_hardened_clay 15
setblock ~98 ~3 ~14 stained_hardened_clay 12
setblock ~98 ~3 ~45 planks 5
setblock ~99 ~3 ~46 stained_hardened_clay 12
fill ~100 ~3 ~11 ~100 ~5 ~11 stained_hardened_clay 15
setblock ~100 ~3 ~47 stained_hardened_clay 15
setblock ~101 ~3 ~48 black_glazed_terracotta 0
setblock ~102 ~3 ~49 stained_hardened_clay 15
setblock ~103 ~3 ~9 black_glazed_terracotta 0
fill ~103 ~3 ~50 ~104 ~3 ~50 black_glazed_terracotta 0
setblock ~104 ~3 ~8 planks 5
setblock ~105 ~3 ~8 black_glazed_terracotta 0
fill ~105 ~3 ~49 ~105 ~4 ~49 stained_hardened_clay 7
setblock ~106 ~3 ~48 stained_hardened_clay 12
fill ~107 ~3 ~11 ~107 ~4 ~11 black_glazed_terracotta 0
setblock ~107 ~3 ~47 soul_sand 0
setblock ~108 ~3 ~12 black_glazed_terracotta 0
fill ~108 ~3 ~46 ~109 ~3 ~46 noteblock 0
setblock ~109 ~3 ~13 stained_hardened_clay 7
setblock ~110 ~3 ~15 stained_hardened_clay 15
setblock ~110 ~3 ~16 stained_hardened_clay 12
setblock ~110 ~3 ~17 black_glazed_terracotta 0
setblock ~110 ~3 ~18 noteblock 0
fill ~110 ~3 ~19 ~110 ~4 ~19 black_glazed_terracotta 0
setblock ~110 ~3 ~20 soul_sand 0
setblock ~110 ~3 ~21 black_glazed_terracotta 0
setblock ~110 ~3 ~22 soul_sand 0
setblock ~110 ~3 ~23 stained_hardened_clay 15
setblock ~110 ~3 ~24 log2 1
setblock ~110 ~3 ~25 log 1
setblock ~110 ~3 ~26 soul_sand 0
fill ~110 ~3 ~27 ~110 ~4 ~27 stained_hardened_clay 7
setblock ~110 ~3 ~28 stained_hardened_clay 12
setblock ~110 ~3 ~44 noteblock 0
setblock ~110 ~3 ~45 planks 5
setblock ~111 ~3 ~29 stained_hardened_clay 12
fill ~111 ~3 ~30 ~111 ~5 ~30 black_glazed_terracotta 0
setblock ~111 ~3 ~33 soul_sand 0
setblock ~111 ~3 ~37 noteblock 0
setblock ~111 ~3 ~39 quartz_ore 0
setblock ~111 ~3 ~41 quartz_ore 0
setblock ~111 ~3 ~42 noteblock 0
setblock ~112 ~3 ~34 noteblock 0
fill ~112 ~3 ~35 ~112 ~4 ~35 log 1
setblock ~112 ~3 ~36 noteblock 0
setblock ~136 ~3 ~35 black_glazed_terracotta 0
setblock ~136 ~3 ~36 soul_sand 0
setblock ~136 ~3 ~37 black_glazed_terracotta 0
setblock ~136 ~3 ~38 stained_hardened_clay 12
setblock ~137 ~3 ~30 black_glazed_terracotta 0
setblock ~137 ~3 ~33 soul_sand 0
setblock ~137 ~3 ~34 stained_hardened_clay 12
setblock ~137 ~3 ~39 soul_sand 0
setblock ~137 ~3 ~40 noteblock 0
setblock ~137 ~3 ~41 quartz_ore 0
setblock ~137 ~3 ~42 noteblock 0
setblock ~137 ~3 ~43 quartz_ore 0
setblock ~137 ~3 ~44 noteblock 0
setblock ~138 ~3 ~16 stained_hardened_clay 7
setblock ~138 ~3 ~17 black_glazed_terracotta 0
setblock ~138 ~3 ~18 soul_sand 0
setblock ~138 ~3 ~19 black_glazed_terracotta 0
setblock ~138 ~3 ~20 soul_sand 0
fill ~138 ~3 ~21 ~138 ~4 ~21 black_glazed_terracotta 0
setblock ~138 ~3 ~22 soul_sand 0
setblock ~138 ~3 ~23 black_glazed_terracotta 0
setblock ~138 ~3 ~24 soul_sand 0
setblock ~138 ~3 ~25 stained_hardened_clay 15
setblock ~138 ~3 ~26 noteblock 0
setblock ~138 ~3 ~27 planks 5
setblock ~138 ~3 ~28 noteblock 0
setblock ~138 ~3 ~29 stained_hardened_clay 7
setblock ~138 ~3 ~46 noteblock 0
setblock ~139 ~3 ~47 quartz_ore 0
setblock ~140 ~3 ~14 stained_hardened_clay 7
setblock ~140 ~3 ~48 noteblock 0
setblock ~141 ~3 ~49 noteblock 0
setblock ~142 ~3 ~10 stained_hardened_clay 7
setblock ~142 ~3 ~49 stained_hardened_clay 15
fill ~143 ~3 ~9 ~143 ~4 ~9 black_glazed_terracotta 0
fill ~143 ~3 ~50 ~143 ~4 ~50 stained_hardened_clay 7
setblock ~144 ~3 ~10 planks 5
setblock ~144 ~3 ~51 stained_hardened_clay 15
setblock ~146 ~3 ~51 stained_hardened_clay 15
setblock ~147 ~3 ~50 black_glazed_terracotta 0
fill ~148 ~3 ~13 ~148 ~5 ~13 stained_hardened_clay 15
setblock ~148 ~3 ~49 stained_hardened_clay 15
setblock ~149 ~3 ~13 black_glazed_terracotta 0
setblock ~150 ~3 ~14 stained_hardened_clay 7
setblock ~150 ~3 ~15 stained_hardened_clay 15
setblock ~150 ~3 ~47 stained_hardened_clay 7
setblock ~151 ~3 ~16 black_glazed_terracotta 0
setblock ~151 ~3 ~17 soul_sand 0
setblock ~151 ~3 ~18 stained_hardened_clay 12
setblock ~152 ~3 ~19 black_glazed_terracotta 0
setblock ~152 ~3 ~20 stained_hardened_clay 12
setblock ~152 ~3 ~45 black_glazed_terracotta 0
setblock ~153 ~3 ~22 stained_hardened_clay 12
setblock ~153 ~3 ~23 soul_sand 0
setblock ~154 ~3 ~24 log2 1
setblock ~154 ~3 ~25 nether_brick 0
setblock ~154 ~3 ~26 stained_hardened_clay 12
setblock ~154 ~3 ~27 stained_hardened_clay 15
fill ~154 ~3 ~28 ~154 ~4 ~28 stained_hardened_clay 7
setblock ~154 ~3 ~29 stained_hardened_clay 15
setblock ~154 ~3 ~30 log2 1
setblock ~154 ~3 ~31 stained_hardened_clay 15
setblock ~154 ~3 ~32 soul_sand 0
setblock ~154 ~3 ~33 black_glazed_terracotta 0
fill ~154 ~3 ~34 ~154 ~4 ~34 stained_hardened_clay 12
setblock ~154 ~3 ~35 black_glazed_terracotta 0
setblock ~154 ~3 ~36 soul_sand 0
fill ~154 ~3 ~37 ~154 ~4 ~37 black_glazed_terracotta 0
setblock ~154 ~3 ~38 stained_hardened_clay 12
setblock ~154 ~3 ~39 planks 5
setblock ~154 ~3 ~40 stained_hardened_clay 12
setblock ~154 ~3 ~41 black_glazed_terracotta 0
setblock ~154 ~3 ~42 noteblock 0
setblock ~154 ~3 ~43 black_glazed_terracotta 0
fill ~94 ~4 ~23 ~94 ~5 ~23 stained_hardened_clay 7
setblock ~94 ~4 ~24 stained_hardened_clay 15
setblock ~94 ~4 ~25 log2 1
setblock ~94 ~4 ~26 black_glazed_terracotta 0
setblock ~94 ~4 ~27 log2 1
setblock ~94 ~4 ~28 nether_brick 0
setblock ~94 ~4 ~29 stained_hardened_clay 7
setblock ~94 ~4 ~30 black_glazed_terracotta 0
setblock ~94 ~4 ~31 stained_hardened_clay 12
setblock ~94 ~4 ~33 soul_sand 0
setblock ~94 ~4 ~34 stained_hardened_clay 7
setblock ~94 ~4 ~35 stained_hardened_clay 12
setblock ~94 ~4 ~36 black_glazed_terracotta 0
setblock ~94 ~4 ~38 black_glazed_terracotta 0
setblock ~94 ~4 ~39 soul_sand 0
setblock ~94 ~4 ~40 stained_hardened_clay 12
setblock ~95 ~4 ~20 stained_hardened_clay 7
setblock ~95 ~4 ~22 stained_hardened_clay 7
setblock ~95 ~4 ~41 brown_glazed_terracotta 0
setblock ~95 ~4 ~42 noteblock 0
fill ~96 ~4 ~17 ~96 ~5 ~17 stained_hardened_clay 12
setblock ~96 ~4 ~18 nether_brick 0
fill ~96 ~4 ~19 ~96 ~5 ~19 stained_hardened_clay 7
setblock ~96 ~4 ~41 quartz_ore 0
fill ~96 ~4 ~42 ~97 ~4 ~42 soul_sand 0
fill ~96 ~4 ~43 ~96 ~4 ~42 soul_sand 0
fill ~97 ~4 ~14 ~97 ~5 ~14 stained_hardened_clay 7
setblock ~97 ~4 ~43 mycelium 0
setblock ~98 ~4 ~13 black_glazed_terracotta 0
fill ~98 ~4 ~45 ~98 ~5 ~45 soul_sand 0
fill ~99 ~4 ~12 ~99 ~5 ~12 stained_hardened_clay 15
setblock ~99 ~4 ~46 stained_hardened_clay 7
fill ~100 ~4 ~47 ~100 ~5 ~47 stained_hardened_clay 12
setblock ~101 ~4 ~11 stained_hardened_clay 15
setblock ~101 ~4 ~48 stained_hardened_clay 7
fill ~102 ~4 ~49 ~102 ~5 ~49 black_glazed_terracotta 0
fill ~103 ~4 ~9 ~103 ~5 ~9 stained_hardened_clay 7
setblock ~103 ~4 ~50 planks 5
fill ~104 ~4 ~8 ~105 ~4 ~8 stained_hardened_clay 15
fill ~104 ~4 ~49 ~104 ~5 ~49 black_glazed_terracotta 0
setblock ~106 ~4 ~48 stained_hardened_clay 15
setblock ~107 ~4 ~47 stained_hardened_clay 12
fill ~108 ~4 ~12 ~108 ~4 ~13 stained_hardened_clay 15
setblock ~108 ~4 ~46 planks 5
fill ~109 ~4 ~14 ~109 ~6 ~14 black_glazed_terracotta 0
setblock ~109 ~4 ~45 stained_hardened_clay 12
setblock ~110 ~4 ~15 stained_hardened_clay 7
setblock ~110 ~4 ~16 stained_hardened_clay 15
fill ~110 ~4 ~17 ~110 ~4 ~18 stained_hardened_clay 7
setblock ~110 ~4 ~20 stained_hardened_clay 15
setblock ~110 ~4 ~21 stained_hardened_clay 12
fill ~110 ~4 ~22 ~110 ~4 ~23 black_glazed_terracotta 0
setblock ~110 ~4 ~24 stained_hardened_clay 15
setblock ~110 ~4 ~25 stained_hardened_clay 7
setblock ~110 ~4 ~26 stained_hardened_clay 15
setblock ~110 ~4 ~43 log 1
setblock ~110 ~4 ~44 planks 5
setblock ~111 ~4 ~28 stained_hardened_clay 15
fill ~111 ~4 ~29 ~111 ~5 ~29 stained_hardened_clay 7
fill ~111 ~4 ~31 ~111 ~4 ~32 stained_hardened_clay 7
setblock ~111 ~4 ~33 log 1
setblock ~111 ~4 ~36 black_glazed_terracotta 0
setblock ~111 ~4 ~37 stained_hardened_clay 12
setblock ~111 ~4 ~38 black_glazed_terracotta 0
setblock ~111 ~4 ~39 stained_hardened_clay 12
setblock ~111 ~4 ~40 log 1
setblock ~111 ~4 ~41 noteblock 0
setblock ~111 ~4 ~42 black_glazed_terracotta 0
setblock ~112 ~4 ~34 black_glazed_terracotta 0
setblock ~136 ~4 ~35 planks 5
setblock ~136 ~4 ~36 black_glazed_terracotta 0
setblock ~136 ~4 ~37 planks 5
fill ~137 ~4 ~29 ~137 ~4 ~30 stained_hardened_clay 15
setblock ~137 ~4 ~31 stained_hardened_clay 7
setblock ~137 ~4 ~32 planks 5
setblock ~137 ~4 ~33 log2 1
setblock ~137 ~4 ~34 black_glazed_terracotta 0
setblock ~137 ~4 ~38 planks 5
fill ~137 ~4 ~39 ~137 ~5 ~39 stained_hardened_clay 12
setblock ~137 ~4 ~40 black_glazed_terracotta 0
setblock ~137 ~4 ~41 stained_hardened_clay 12
setblock ~137 ~4 ~42 black_glazed_terracotta 0
setblock ~137 ~4 ~43 soul_sand 0
setblock ~137 ~4 ~44 log 1
setblock ~138 ~4 ~16 stained_hardened_clay 15
setblock ~138 ~4 ~17 stained_hardened_clay 12
setblock ~138 ~4 ~18 nether_brick 0
setblock ~138 ~4 ~19 stained_hardened_clay 7
setblock ~138 ~4 ~20 black_glazed_terracotta 0
fill ~138 ~4 ~22 ~138 ~4 ~23 stained_hardened_clay 7
setblock ~138 ~4 ~24 stained_hardened_clay 15
fill ~138 ~4 ~25 ~138 ~5 ~25 black_glazed_terracotta 0
setblock ~138 ~4 ~26 stained_hardened_clay 15
setblock ~138 ~4 ~27 black_glazed_terracotta 0
setblock ~138 ~4 ~28 stained_hardened_clay 15
setblock ~138 ~4 ~45 log 1
setblock ~138 ~4 ~46 planks 5
setblock ~139 ~4 ~15 black_glazed_terracotta 0
setblock ~139 ~4 ~47 soul_sand 0
setblock ~140 ~4 ~14 stained_hardened_clay 15
setblock ~140 ~4 ~47 stained_hardened_clay 12
setblock ~141 ~4 ~12 planks 5
setblock ~141 ~4 ~48 stained_hardened_clay 7
setblock ~142 ~4 ~10 stained_hardened_clay 15
setblock ~142 ~4 ~11 log2 1
fill ~142 ~4 ~49 ~142 ~5 ~49 stained_hardened_clay 7
setblock ~144 ~4 ~10 stained_hardened_clay 15
fill ~144 ~4 ~51 ~144 ~5 ~51 black_glazed_terracotta 0
setblock ~146 ~4 ~51 stained_hardened_clay 7
setblock ~147 ~4 ~50 stained_hardened_clay 7
setblock ~148 ~4 ~49 black_glazed_terracotta 0
setblock ~149 ~4 ~13 stained_hardened_clay 7
setblock ~149 ~4 ~48 stained_hardened_clay 7
setblock ~150 ~4 ~14 nether_brick 0
setblock ~150 ~4 ~15 stained_hardened_clay 7
setblock ~150 ~4 ~43 soul_sand 0
setblock ~150 ~4 ~44 stained_hardened_clay 12
setblock ~150 ~4 ~45 mycelium 0
fill ~150 ~4 ~46 ~150 ~4 ~47 stained_hardened_clay 12
fill ~151 ~4 ~16 ~151 ~5 ~16 stained_hardened_clay 7
setblock ~151 ~4 ~17 stained_hardened_clay 12
setblock ~151 ~4 ~43 mycelium 0
setblock ~151 ~4 ~44 quartz_ore 0
fill ~151 ~4 ~45 ~151 ~4 ~46 soul_sand 0
setblock ~152 ~4 ~18 black_glazed_terracotta 0
fill ~152 ~4 ~19 ~152 ~5 ~19 stained_hardened_clay 12
setblock ~152 ~4 ~20 black_glazed_terracotta 0
setblock ~152 ~4 ~42 noteblock 0
setblock ~152 ~4 ~43 dirt 1
setblock ~152 ~4 ~44 soul_sand 0
setblock ~153 ~4 ~21 soul_sand 0
fill ~153 ~4 ~22 ~153 ~5 ~22 stained_hardened_clay 7
fill ~153 ~4 ~23 ~153 ~4 ~22 stained_hardened_clay 7
fill ~153 ~4 ~41 ~153 ~5 ~41 soul_sand 0
fill ~153 ~4 ~42 ~153 ~4 ~43 mycelium 0
setblock ~154 ~4 ~24 black_glazed_terracotta 0
fill ~154 ~4 ~25 ~154 ~4 ~26 stained_hardened_clay 7
setblock ~154 ~4 ~27 soul_sand 0
setblock ~154 ~4 ~29 stained_hardened_clay 7
setblock ~154 ~4 ~30 stained_hardened_clay 15
setblock ~154 ~4 ~31 nether_brick 0
setblock ~154 ~4 ~32 stained_hardened_clay 15
setblock ~154 ~4 ~33 stained_hardened_clay 12
setblock ~154 ~4 ~35 soul_sand 0
setblock ~154 ~4 ~36 stained_hardened_clay 7
setblock ~154 ~4 ~38 stained_hardened_clay 15
fill ~154 ~4 ~39 ~154 ~4 ~40 black_glazed_terracotta 0
setblock ~94 ~5 ~24 soul_sand 0
setblock ~94 ~5 ~25 stained_hardened_clay 12
setblock ~94 ~5 ~26 soul_sand 0
setblock ~94 ~5 ~27 stained_hardened_clay 7
setblock ~94 ~5 ~28 soul_sand 0
setblock ~94 ~5 ~29 stained_hardened_clay 12
setblock ~94 ~5 ~30 soul_sand 0
setblock ~94 ~5 ~31 log 1
setblock ~95 ~5 ~20 soul_sand 0
setblock ~95 ~5 ~22 stained_hardened_clay 12
setblock ~95 ~5 ~32 stained_hardened_clay 12
setblock ~95 ~5 ~33 soul_sand 0
setblock ~95 ~5 ~34 noteblock 0
fill ~95 ~5 ~35 ~95 ~6 ~35 soul_sand 0
fill ~95 ~5 ~36 ~95 ~6 ~36 stained_hardened_clay 12
fill ~95 ~5 ~37 ~95 ~6 ~37 soul_sand 0
fill ~95 ~5 ~38 ~95 ~5 ~39 soul_sand 0
setblock ~95 ~5 ~40 stained_hardened_clay 12
setblock ~96 ~5 ~18 soul_sand 0
setblock ~96 ~5 ~39 stained_hardened_clay 12
setblock ~96 ~5 ~40 mycelium 0
fill ~97 ~5 ~15 ~97 ~7 ~15 soul_sand 0
fill ~97 ~5 ~16 ~97 ~5 ~15 soul_sand 0
setblock ~97 ~5 ~40 noteblock 0
setblock ~97 ~5 ~41 mycelium 0
setblock ~98 ~5 ~13 stained_hardened_clay 7
setblock ~98 ~5 ~41 stained_hardened_clay 7
fill ~98 ~5 ~42 ~99 ~5 ~42 soul_sand 0
fill ~98 ~5 ~43 ~99 ~5 ~43 soul_sand 0
fill ~98 ~5 ~44 ~99 ~5 ~44 mycelium 0
setblock ~99 ~5 ~41 soul_sand 0
setblock ~99 ~5 ~45 mycelium 0
setblock ~99 ~5 ~46 soul_sand 0
fill ~100 ~5 ~42 ~101 ~5 ~42 stained_hardened_clay 12
setblock ~100 ~5 ~43 stained_hardened_clay 7
fill ~100 ~5 ~44 ~102 ~5 ~44 soul_sand 0
fill ~100 ~5 ~45 ~101 ~5 ~45 soul_sand 0
setblock ~100 ~5 ~46 mycelium 0
fill ~101 ~5 ~10 ~102 ~5 ~10 stained_hardened_clay 7
setblock ~101 ~5 ~43 soul_sand 0
fill ~101 ~5 ~46 ~102 ~5 ~46 soul_sand 0
setblock ~101 ~5 ~47 mycelium 0
setblock ~101 ~5 ~48 soul_sand 0
setblock ~102 ~5 ~43 stained_hardened_clay 7
setblock ~102 ~5 ~45 stained_hardened_clay 7
setblock ~102 ~5 ~47 soul_sand 0
setblock ~102 ~5 ~48 mycelium 0
setblock ~103 ~5 ~43 soul_sand 0
setblock ~103 ~5 ~50 stained_hardened_clay 7
setblock ~104 ~5 ~8 stained_hardened_clay 7
setblock ~104 ~5 ~43 stained_hardened_clay 7
setblock ~105 ~5 ~8 nether_brick 0
setblock ~105 ~5 ~48 stained_hardened_clay 12
setblock ~106 ~5 ~10 stained_hardened_clay 7
setblock ~106 ~5 ~44 soul_sand 0
setblock ~106 ~5 ~47 stained_hardened_clay 7
fill ~107 ~5 ~11 ~107 ~6 ~11 stained_hardened_clay 7
fill ~107 ~5 ~44 ~108 ~5 ~44 mycelium 0
setblock ~107 ~5 ~47 soul_sand 0
setblock ~108 ~5 ~12 stained_hardened_clay 12
setblock ~108 ~5 ~13 stained_hardened_clay 15
setblock ~108 ~5 ~46 soul_sand 0
setblock ~109 ~5 ~44 dirt 1
setblock ~109 ~5 ~45 soul_sand 0
setblock ~110 ~5 ~15 nether_brick 0
setblock ~110 ~5 ~16 stained_hardened_clay 7
setblock ~110 ~5 ~17 stained_hardened_clay 15
setblock ~110 ~5 ~18 soul_sand 0
setblock ~110 ~5 ~19 stained_hardened_clay 7
setblock ~110 ~5 ~20 soul_sand 0
fill ~110 ~5 ~21 ~110 ~7 ~21 stained_hardened_clay 7
setblock ~110 ~5 ~22 stained_hardened_clay 12
setblock ~110 ~5 ~23 black_glazed_terracotta 0
setblock ~110 ~5 ~24 stained_hardened_clay 12
setblock ~110 ~5 ~25 stained_hardened_clay 15
setblock ~110 ~5 ~26 soul_sand 0
setblock ~110 ~5 ~27 stained_hardened_clay 15
setblock ~110 ~5 ~28 stained_hardened_clay 7
setblock ~110 ~5 ~42 dirt 1
setblock ~110 ~5 ~43 stained_hardened_clay 12
setblock ~110 ~5 ~44 noteblock 0
setblock ~111 ~5 ~31 soul_sand 0
setblock ~111 ~5 ~32 stained_hardened_clay 12
fill ~111 ~5 ~33 ~111 ~6 ~33 soul_sand 0
fill ~111 ~5 ~34 ~111 ~6 ~34 soul_sand 0
fill ~111 ~5 ~35 ~111 ~6 ~35 soul_sand 0
setblock ~111 ~5 ~36 stained_hardened_clay 12
setblock ~111 ~5 ~37 soul_sand 0
setblock ~111 ~5 ~38 stained_hardened_clay 12
setblock ~111 ~5 ~39 noteblock 0
setblock ~111 ~5 ~40 stained_hardened_clay 12
setblock ~111 ~5 ~41 quartz_ore 0
setblock ~137 ~5 ~30 planks 5
setblock ~137 ~5 ~31 stained_hardened_clay 12
setblock ~137 ~5 ~32 stained_hardened_clay 7
setblock ~137 ~5 ~33 soul_sand 0
setblock ~137 ~5 ~34 stained_hardened_clay 12
fill ~137 ~5 ~35 ~137 ~6 ~35 soul_sand 0
fill ~137 ~5 ~36 ~137 ~6 ~36 soul_sand 0
fill ~137 ~5 ~37 ~137 ~6 ~37 soul_sand 0
setblock ~137 ~5 ~38 log 1
setblock ~137 ~5 ~40 stained_hardened_clay 12
setblock ~137 ~5 ~41 noteblock 0
setblock ~137 ~5 ~42 stained_hardened_clay 12
setblock ~137 ~5 ~43 quartz_ore 0
setblock ~138 ~5 ~16 soul_sand 0
setblock ~138 ~5 ~17 black_glazed_terracotta 0
setblock ~138 ~5 ~18 stained_hardened_clay 7
setblock ~138 ~5 ~19 stained_hardened_clay 12
setblock ~138 ~5 ~20 soul_sand 0
setblock ~138 ~5 ~21 stained_hardened_clay 7
setblock ~138 ~5 ~22 soul_sand 0
setblock ~138 ~5 ~23 stained_hardened_clay 7
setblock ~138 ~5 ~24 stained_hardened_clay 12
setblock ~138 ~5 ~26 stained_hardened_clay 7
setblock ~138 ~5 ~27 stained_hardened_clay 15
setblock ~138 ~5 ~28 soul_sand 0
setblock ~138 ~5 ~29 stained_hardened_clay 15
setblock ~138 ~5 ~44 soul_sand 0
setblock ~138 ~5 ~45 stained_hardened_clay 12
setblock ~138 ~5 ~46 noteblock 0
setblock ~139 ~5 ~15 soul_sand 0
setblock ~139 ~5 ~45 mycelium 0
setblock ~139 ~5 ~46 soul_sand 0
setblock ~140 ~5 ~14 stained_hardened_clay 7
setblock ~140 ~5 ~45 soul_sand 0
fill ~140 ~5 ~46 ~141 ~5 ~46 mycelium 0
setblock ~140 ~5 ~47 stained_hardened_clay 7
fill ~141 ~5 ~12 ~141 ~6 ~12 nether_brick 0
setblock ~141 ~5 ~45 dirt 1
setblock ~141 ~5 ~47 mycelium 0
fill ~141 ~5 ~48 ~143 ~5 ~48 soul_sand 0
setblock ~142 ~5 ~10 stained_hardened_clay 7
fill ~142 ~5 ~11 ~142 ~6 ~11 stained_hardened_clay 15
fill ~142 ~5 ~45 ~142 ~5 ~48 soul_sand 0
fill ~143 ~5 ~9 ~143 ~7 ~9 stained_hardened_clay 12
setblock ~143 ~5 ~45 mycelium 0
fill ~143 ~5 ~46 ~144 ~5 ~46 soul_sand 0
setblock ~143 ~5 ~47 mycelium 0
setblock ~143 ~5 ~49 mycelium 0
fill ~143 ~5 ~50 ~146 ~5 ~50 soul_sand 0
setblock ~144 ~5 ~10 black_glazed_terracotta 0
setblock ~144 ~5 ~44 noteblock 0
setblock ~144 ~5 ~45 stained_hardened_clay 7
setblock ~144 ~5 ~47 stained_hardened_clay 7
setblock ~144 ~5 ~48 mycelium 0
fill ~144 ~5 ~49 ~146 ~5 ~49 soul_sand 0
setblock ~145 ~5 ~11 stained_hardened_clay 12
fill ~145 ~5 ~44 ~147 ~5 ~44 stained_hardened_clay 12
setblock ~145 ~5 ~45 soul_sand 0
setblock ~145 ~5 ~46 stained_hardened_clay 12
fill ~145 ~5 ~47 ~145 ~5 ~50 soul_sand 0
setblock ~145 ~5 ~51 stained_hardened_clay 12
setblock ~146 ~5 ~45 stained_hardened_clay 7
setblock ~146 ~5 ~46 soul_sand 0
setblock ~146 ~5 ~47 stained_hardened_clay 7
setblock ~146 ~5 ~48 soul_sand 0
setblock ~147 ~5 ~12 log 1
setblock ~147 ~5 ~43 soul_sand 0
setblock ~147 ~5 ~45 soul_sand 0
setblock ~147 ~5 ~46 stained_hardened_clay 12
setblock ~147 ~5 ~47 brown_glazed_terracotta 0
fill ~147 ~5 ~48 ~147 ~5 ~49 mycelium 0
setblock ~148 ~5 ~43 stained_hardened_clay 15
setblock ~148 ~5 ~44 soul_sand 0
setblock ~148 ~5 ~45 stained_hardened_clay 12
fill ~148 ~5 ~46 ~149 ~5 ~46 soul_sand 0
fill ~148 ~5 ~47 ~148 ~5 ~46 soul_sand 0
setblock ~148 ~5 ~48 dirt 1
setblock ~149 ~5 ~13 black_glazed_terracotta 0
fill ~149 ~5 ~42 ~150 ~5 ~42 soul_sand 0
fill ~149 ~5 ~43 ~149 ~5 ~44 stained_hardened_clay 12
setblock ~149 ~5 ~45 mycelium 0
setblock ~149 ~5 ~47 mycelium 0
setblock ~150 ~5 ~14 stained_hardened_clay 12
setblock ~150 ~5 ~15 nether_brick 0
fill ~151 ~5 ~17 ~151 ~5 ~18 soul_sand 0
fill ~151 ~5 ~41 ~151 ~5 ~42 dirt 1
setblock ~152 ~5 ~20 soul_sand 0
setblock ~152 ~5 ~21 stained_hardened_clay 7
setblock ~152 ~5 ~40 quartz_ore 0
setblock ~152 ~5 ~41 soul_sand 0
fill ~153 ~5 ~23 ~153 ~6 ~23 soul_sand 0
fill ~153 ~5 ~24 ~153 ~6 ~24 stained_hardened_clay 7
fill ~153 ~5 ~25 ~153 ~6 ~25 soul_sand 0
fill ~153 ~5 ~28 ~153 ~5 ~30 soul_sand 0
setblock ~153 ~5 ~31 quartz_ore 0
fill ~153 ~5 ~32 ~153 ~5 ~33 soul_sand 0
setblock ~153 ~5 ~34 stained_hardened_clay 12
fill ~153 ~5 ~35 ~153 ~5 ~39 soul_sand 0
setblock ~153 ~5 ~40 noteblock 0
setblock ~154 ~5 ~26 soul_sand 0
setblock ~154 ~5 ~27 stained_hardened_clay 7
fill ~95 ~6 ~22 ~95 ~6 ~23 stained_hardened_clay 7
fill ~95 ~6 ~24 ~95 ~7 ~24 stained_hardened_clay 12
fill ~95 ~6 ~25 ~95 ~7 ~25 soul_sand 0
fill ~95 ~6 ~26 ~95 ~6 ~27 soul_sand 0
setblock ~95 ~6 ~28 stained_hardened_clay 12
fill ~95 ~6 ~29 ~95 ~7 ~29 soul_sand 0
setblock ~95 ~6 ~30 black_glazed_terracotta 0
setblock ~95 ~6 ~31 soul_sand 0
setblock ~95 ~6 ~32 black_glazed_terracotta 0
setblock ~95 ~6 ~33 stained_hardened_clay 12
setblock ~95 ~6 ~34 black_glazed_terracotta 0
setblock ~96 ~6 ~18 stained_hardened_clay 7
setblock ~96 ~6 ~19 soul_sand 0
setblock ~96 ~6 ~20 planks 5
setblock ~96 ~6 ~37 soul_sand 0
setblock ~96 ~6 ~38 stained_hardened_clay 12
setblock ~97 ~6 ~16 stained_hardened_clay 12
setblock ~97 ~6 ~17 dirt 1
fill ~97 ~6 ~38 ~97 ~6 ~39 soul_sand 0
setblock ~98 ~6 ~13 black_glazed_terracotta 0
setblock ~98 ~6 ~14 stained_hardened_clay 15
setblock ~98 ~6 ~39 stained_hardened_clay 12
setblock ~98 ~6 ~40 stained_hardened_clay 7
setblock ~99 ~6 ~12 black_glazed_terracotta 0
setblock ~99 ~6 ~39 noteblock 0
setblock ~99 ~6 ~40 stained_hardened_clay 12
setblock ~100 ~6 ~11 stained_hardened_clay 7
setblock ~100 ~6 ~40 black_glazed_terracotta 0
setblock ~100 ~6 ~41 stained_hardened_clay 7
fill ~101 ~6 ~10 ~102 ~6 ~10 stained_hardened_clay 15
setblock ~101 ~6 ~40 stained_hardened_clay 12
setblock ~101 ~6 ~41 noteblock 0
setblock ~102 ~6 ~41 log 1
fill ~102 ~6 ~42 ~104 ~6 ~42 black_glazed_terracotta 0
setblock ~103 ~6 ~9 nether_brick 0
setblock ~103 ~6 ~41 noteblock 0
setblock ~103 ~6 ~44 stained_hardened_clay 12
fill ~103 ~6 ~45 ~106 ~6 ~45 soul_sand 0
setblock ~103 ~6 ~46 stained_hardened_clay 7
fill ~103 ~6 ~47 ~104 ~6 ~47 soul_sand 0
fill ~103 ~6 ~48 ~105 ~6 ~48 soul_sand 0
fill ~103 ~6 ~49 ~104 ~6 ~49 soul_sand 0
fill ~104 ~6 ~8 ~105 ~6 ~8 stained_hardened_clay 15
setblock ~104 ~6 ~44 black_glazed_terracotta 0
fill ~104 ~6 ~46 ~107 ~6 ~46 soul_sand 0
setblock ~105 ~6 ~42 stained_hardened_clay 7
fill ~105 ~6 ~43 ~105 ~6 ~44 stained_hardened_clay 12
setblock ~105 ~6 ~47 mycelium 0
setblock ~106 ~6 ~10 stained_hardened_clay 15
setblock ~106 ~6 ~42 planks 5
setblock ~106 ~6 ~43 noteblock 0
setblock ~106 ~6 ~47 soul_sand 0
setblock ~107 ~6 ~42 soul_sand 0
setblock ~107 ~6 ~43 quartz_ore 0
setblock ~107 ~6 ~45 mycelium 0
setblock ~108 ~6 ~12 stained_hardened_clay 15
setblock ~108 ~6 ~13 stained_hardened_clay 7
setblock ~108 ~6 ~42 stained_hardened_clay 12
setblock ~108 ~6 ~43 soul_sand 0
setblock ~108 ~6 ~45 bedrock 0
setblock ~109 ~6 ~15 stained_hardened_clay 12
fill ~109 ~6 ~42 ~110 ~6 ~42 soul_sand 0
setblock ~109 ~6 ~43 mycelium 0
setblock ~110 ~6 ~16 black_glazed_terracotta 0
setblock ~110 ~6 ~17 log 1
fill ~110 ~6 ~18 ~110 ~6 ~19 stained_hardened_clay 12
setblock ~110 ~6 ~20 planks 5
fill ~110 ~6 ~22 ~110 ~6 ~23 stained_hardened_clay 7
setblock ~110 ~6 ~24 nether_brick 0
setblock ~110 ~6 ~25 stained_hardened_clay 7
setblock ~110 ~6 ~26 stained_hardened_clay 15
setblock ~110 ~6 ~27 stained_hardened_clay 7
setblock ~110 ~6 ~28 stained_hardened_clay 15
setblock ~110 ~6 ~29 planks 5
setblock ~110 ~6 ~38 black_glazed_terracotta 0
setblock ~110 ~6 ~39 stained_hardened_clay 7
fill ~110 ~6 ~40 ~110 ~6 ~41 black_glazed_terracotta 0
setblock ~110 ~6 ~43 dirt 1
setblock ~111 ~6 ~30 stained_hardened_clay 15
fill ~111 ~6 ~31 ~111 ~6 ~32 stained_hardened_clay 7
setblock ~111 ~6 ~36 stained_hardened_clay 7
setblock ~111 ~6 ~37 stained_hardened_clay 12
setblock ~137 ~6 ~31 black_glazed_terracotta 0
setblock ~137 ~6 ~32 nether_brick 0
fill ~137 ~6 ~33 ~137 ~6 ~34 stained_hardened_clay 7
setblock ~137 ~6 ~38 stained_hardened_clay 7
setblock ~138 ~6 ~17 stained_hardened_clay 7
setblock ~138 ~6 ~18 planks 5
setblock ~138 ~6 ~19 stained_hardened_clay 7
setblock ~138 ~6 ~20 stained_hardened_clay 12
setblock ~138 ~6 ~21 soul_sand 0
setblock ~138 ~6 ~22 black_glazed_terracotta 0
setblock ~138 ~6 ~23 stained_hardened_clay 12
fill ~138 ~6 ~24 ~138 ~6 ~25 stained_hardened_clay 7
setblock ~138 ~6 ~26 black_glazed_terracotta 0
setblock ~138 ~6 ~27 nether_brick 0
setblock ~138 ~6 ~28 stained_hardened_clay 15
setblock ~138 ~6 ~29 log2 1
setblock ~138 ~6 ~30 stained_hardened_clay 15
setblock ~138 ~6 ~39 stained_hardened_clay 7
setblock ~138 ~6 ~40 nether_brick 0
setblock ~138 ~6 ~41 stained_hardened_clay 7
setblock ~138 ~6 ~42 black_glazed_terracotta 0
setblock ~138 ~6 ~43 soul_sand 0
setblock ~138 ~6 ~44 noteblock 0
setblock ~139 ~6 ~15 stained_hardened_clay 12
setblock ~139 ~6 ~16 nether_brick 0
fill ~139 ~6 ~43 ~139 ~6 ~44 dirt 1
setblock ~140 ~6 ~13 black_glazed_terracotta 0
setblock ~140 ~6 ~14 stained_hardened_clay 15
fill ~140 ~6 ~43 ~142 ~6 ~43 soul_sand 0
fill ~140 ~6 ~44 ~141 ~6 ~44 noteblock 0
setblock ~142 ~6 ~10 stained_hardened_clay 15
fill ~142 ~6 ~44 ~143 ~6 ~44 black_glazed_terracotta 0
setblock ~143 ~6 ~43 noteblock 0
fill ~144 ~6 ~10 ~145 ~6 ~10 stained_hardened_clay 15
setblock ~144 ~6 ~43 log 1
setblock ~145 ~6 ~42 stained_hardened_clay 7
setblock ~145 ~6 ~43 soul_sand 0
setblock ~145 ~6 ~51 soul_sand 0
setblock ~146 ~6 ~11 black_glazed_terracotta 0
setblock ~146 ~6 ~42 planks 5
setblock ~146 ~6 ~43 black_glazed_terracotta 0
setblock ~147 ~6 ~12 black_glazed_terracotta 0
setblock ~147 ~6 ~41 soul_sand 0
setblock ~147 ~6 ~42 stained_hardened_clay 12
setblock ~148 ~6 ~13 log2 1
setblock ~148 ~6 ~41 stained_hardened_clay 12
setblock ~148 ~6 ~42 planks 5
setblock ~149 ~6 ~14 black_glazed_terracotta 0
setblock ~149 ~6 ~40 stained_hardened_clay 12
setblock ~149 ~6 ~41 soul_sand 0
setblock ~150 ~6 ~14 stained_hardened_clay 15
fill ~150 ~6 ~15 ~150 ~7 ~15 stained_hardened_clay 7
fill ~150 ~6 ~16 ~150 ~6 ~15 stained_hardened_clay 7
setblock ~150 ~6 ~40 stained_hardened_clay 7
setblock ~150 ~6 ~41 stained_hardened_clay 12
setblock ~151 ~6 ~17 stained_hardened_clay 12
fill ~151 ~6 ~18 ~151 ~7 ~18 stained_hardened_clay 7
fill ~151 ~6 ~19 ~151 ~9 ~19 soul_sand 0
setblock ~151 ~6 ~39 soul_sand 0
setblock ~151 ~6 ~40 stained_hardened_clay 12
setblock ~152 ~6 ~20 stained_hardened_clay 7
setblock ~152 ~6 ~21 soul_sand 0
setblock ~152 ~6 ~22 stained_hardened_clay 7
setblock ~152 ~6 ~38 black_glazed_terracotta 0
setblock ~152 ~6 ~39 noteblock 0
setblock ~153 ~6 ~26 stained_hardened_clay 12
fill ~153 ~6 ~27 ~153 ~7 ~27 soul_sand 0
fill ~153 ~6 ~28 ~153 ~6 ~29 stained_hardened_clay 12
setblock ~153 ~6 ~30 stained_hardened_clay 7
setblock ~153 ~6 ~31 stained_hardened_clay 12
fill ~153 ~6 ~32 ~153 ~6 ~34 black_glazed_terracotta 0
setblock ~153 ~6 ~35 noteblock 0
setblock ~153 ~6 ~36 log 1
setblock ~153 ~6 ~37 noteblock 0
setblock ~153 ~6 ~38 stained_hardened_clay 12
setblock ~95 ~7 ~22 stained_hardened_clay 12
setblock ~95 ~7 ~23 soul_sand 0
setblock ~95 ~7 ~26 stained_hardened_clay 12
setblock ~95 ~7 ~27 soul_sand 0
setblock ~95 ~7 ~28 stained_hardened_clay 7
setblock ~95 ~7 ~30 stained_hardened_clay 12
setblock ~95 ~7 ~31 noteblock 0
setblock ~96 ~7 ~19 black_glazed_terracotta 0
setblock ~96 ~7 ~20 soul_sand 0
setblock ~96 ~7 ~21 stained_hardened_clay 15
setblock ~96 ~7 ~32 stained_hardened_clay 12
setblock ~96 ~7 ~33 black_glazed_terracotta 0
setblock ~96 ~7 ~34 stained_hardened_clay 12
setblock ~96 ~7 ~35 black_glazed_terracotta 0
setblock ~96 ~7 ~36 stained_hardened_clay 12
setblock ~97 ~7 ~16 stained_hardened_clay 7
setblock ~97 ~7 ~17 soul_sand 0
fill ~97 ~7 ~18 ~97 ~9 ~18 stained_hardened_clay 12
setblock ~97 ~7 ~36 log 1
setblock ~97 ~7 ~37 soul_sand 0
fill ~98 ~7 ~13 ~98 ~8 ~13 stained_hardened_clay 7
setblock ~98 ~7 ~14 soul_sand 0
setblock ~98 ~7 ~37 black_glazed_terracotta 0
fill ~98 ~7 ~38 ~99 ~7 ~38 stained_hardened_clay 12
fill ~99 ~7 ~13 ~99 ~10 ~13 soul_sand 0
setblock ~99 ~7 ~37 soul_sand 0
setblock ~100 ~7 ~12 soul_sand 0
setblock ~100 ~7 ~38 soul_sand 0
setblock ~100 ~7 ~39 black_glazed_terracotta 0
setblock ~101 ~7 ~11 soul_sand 0
setblock ~101 ~7 ~39 noteblock 0
setblock ~102 ~7 ~10 stained_hardened_clay 12
setblock ~102 ~7 ~39 black_glazed_terracotta 0
fill ~102 ~7 ~40 ~103 ~7 ~40 stained_hardened_clay 12
setblock ~103 ~7 ~9 stained_hardened_clay 12
setblock ~103 ~7 ~39 soul_sand 0
fill ~104 ~7 ~8 ~105 ~7 ~8 stained_hardened_clay 7
fill ~104 ~7 ~40 ~105 ~7 ~40 noteblock 0
setblock ~104 ~7 ~41 stained_hardened_clay 12
setblock ~105 ~7 ~41 soul_sand 0
fill ~106 ~7 ~9 ~106 ~8 ~9 black_glazed_terracotta 0
setblock ~106 ~7 ~10 soul_sand 0
setblock ~106 ~7 ~40 soul_sand 0
setblock ~106 ~7 ~41 log 1
setblock ~107 ~7 ~11 stained_hardened_clay 12
setblock ~107 ~7 ~40 stained_hardened_clay 12
setblock ~107 ~7 ~41 soul_sand 0
setblock ~108 ~7 ~12 stained_hardened_clay 12
setblock ~108 ~7 ~13 log2 1
fill ~108 ~7 ~40 ~110 ~7 ~40 soul_sand 0
setblock ~108 ~7 ~41 stained_hardened_clay 12
fill ~109 ~7 ~14 ~109 ~8 ~14 stained_hardened_clay 12
setblock ~109 ~7 ~15 soul_sand 0
setblock ~109 ~7 ~16 stained_hardened_clay 7
setblock ~109 ~7 ~17 soul_sand 0
setblock ~109 ~7 ~18 stained_hardened_clay 7
setblock ~109 ~7 ~19 soul_sand 0
setblock ~109 ~7 ~41 dirt 1
setblock ~110 ~7 ~20 soul_sand 0
setblock ~110 ~7 ~22 soul_sand 0
fill ~110 ~7 ~23 ~110 ~8 ~23 stained_hardened_clay 7
setblock ~110 ~7 ~24 stained_hardened_clay 12
setblock ~110 ~7 ~25 black_glazed_terracotta 0
setblock ~110 ~7 ~26 stained_hardened_clay 12
fill ~110 ~7 ~27 ~110 ~8 ~27 stained_hardened_clay 15
setblock ~110 ~7 ~28 soul_sand 0
setblock ~110 ~7 ~29 stained_hardened_clay 15
setblock ~110 ~7 ~30 stained_hardened_clay 7
setblock ~110 ~7 ~32 stained_hardened_clay 7
setblock ~110 ~7 ~33 black_glazed_terracotta 0
setblock ~110 ~7 ~34 soul_sand 0
fill ~110 ~7 ~35 ~110 ~8 ~35 stained_hardened_clay 12
setblock ~110 ~7 ~36 soul_sand 0
setblock ~110 ~7 ~37 stained_hardened_clay 7
setblock ~110 ~7 ~38 soul_sand 0
setblock ~110 ~7 ~39 log 1
setblock ~111 ~7 ~31 stained_hardened_clay 12
setblock ~137 ~7 ~32 black_glazed_terracotta 0
setblock ~137 ~7 ~33 stained_hardened_clay 12
setblock ~138 ~7 ~21 stained_hardened_clay 7
setblock ~138 ~7 ~22 soul_sand 0
setblock ~138 ~7 ~23 stained_hardened_clay 7
setblock ~138 ~7 ~24 soul_sand 0
fill ~138 ~7 ~25 ~138 ~8 ~25 stained_hardened_clay 7
setblock ~138 ~7 ~26 stained_hardened_clay 12
setblock ~138 ~7 ~27 black_glazed_terracotta 0
setblock ~138 ~7 ~28 stained_hardened_clay 7
fill ~138 ~7 ~29 ~138 ~8 ~29 nether_brick 0
setblock ~138 ~7 ~30 stained_hardened_clay 12
setblock ~138 ~7 ~31 stained_hardened_clay 15
setblock ~138 ~7 ~34 stained_hardened_clay 12
setblock ~138 ~7 ~35 black_glazed_terracotta 0
setblock ~138 ~7 ~36 soul_sand 0
setblock ~138 ~7 ~37 stained_hardened_clay 12
setblock ~138 ~7 ~38 soul_sand 0
setblock ~138 ~7 ~39 black_glazed_terracotta 0
setblock ~138 ~7 ~40 soul_sand 0
setblock ~138 ~7 ~41 log 1
fill ~139 ~7 ~15 ~139 ~8 ~15 soul_sand 0
setblock ~139 ~7 ~16 stained_hardened_clay 12
setblock ~139 ~7 ~17 soul_sand 0
fill ~139 ~7 ~18 ~139 ~8 ~18 stained_hardened_clay 7
fill ~139 ~7 ~19 ~139 ~7 ~20 stained_hardened_clay 7
setblock ~139 ~7 ~41 dirt 1
setblock ~139 ~7 ~42 soul_sand 0
setblock ~140 ~7 ~14 soul_sand 0
setblock ~140 ~7 ~41 log 1
setblock ~140 ~7 ~42 dirt 1
setblock ~141 ~7 ~12 stained_hardened_clay 12
setblock ~141 ~7 ~13 soul_sand 0
fill ~141 ~7 ~41 ~141 ~7 ~42 soul_sand 0
setblock ~142 ~7 ~10 soul_sand 0
setblock ~142 ~7 ~11 stained_hardened_clay 7
setblock ~142 ~7 ~41 black_glazed_terracotta 0
setblock ~142 ~7 ~42 soul_sand 0
fill ~143 ~7 ~41 ~143 ~7 ~42 noteblock 0
setblock ~144 ~7 ~10 soul_sand 0
setblock ~144 ~7 ~41 planks 5
setblock ~144 ~7 ~42 soul_sand 0
setblock ~145 ~7 ~11 soul_sand 0
setblock ~145 ~7 ~40 stained_hardened_clay 12
setblock ~145 ~7 ~41 quartz_ore 0
setblock ~146 ~7 ~12 soul_sand 0
setblock ~146 ~7 ~40 noteblock 0
setblock ~146 ~7 ~41 stained_hardened_clay 12
fill ~147 ~7 ~13 ~147 ~8 ~13 soul_sand 0
setblock ~147 ~7 ~39 soul_sand 0
fill ~147 ~7 ~40 ~148 ~7 ~40 stained_hardened_clay 12
setblock ~148 ~7 ~13 stained_hardened_clay 7
setblock ~148 ~7 ~39 black_glazed_terracotta 0
setblock ~149 ~7 ~14 stained_hardened_clay 12
fill ~149 ~7 ~38 ~151 ~7 ~38 stained_hardened_clay 12
setblock ~149 ~7 ~39 soul_sand 0
setblock ~150 ~7 ~16 stained_hardened_clay 12
setblock ~150 ~7 ~39 planks 5
setblock ~151 ~7 ~17 stained_hardened_clay 7
fill ~151 ~7 ~20 ~151 ~8 ~20 stained_hardened_clay 12
setblock ~151 ~7 ~37 stained_hardened_clay 12
setblock ~152 ~7 ~21 stained_hardened_clay 7
setblock ~152 ~7 ~22 stained_hardened_clay 12
setblock ~152 ~7 ~23 black_glazed_terracotta 0
setblock ~152 ~7 ~24 soul_sand 0
setblock ~152 ~7 ~25 stained_hardened_clay 7
setblock ~152 ~7 ~28 stained_hardened_clay 12
setblock ~152 ~7 ~29 black_glazed_terracotta 0
setblock ~152 ~7 ~30 soul_sand 0
setblock ~152 ~7 ~31 stained_hardened_clay 7
setblock ~152 ~7 ~32 soul_sand 0
fill ~152 ~7 ~33 ~152 ~8 ~33 black_glazed_terracotta 0
setblock ~152 ~7 ~34 stained_hardened_clay 12
setblock ~152 ~7 ~35 black_glazed_terracotta 0
setblock ~152 ~7 ~36 stained_hardened_clay 12
setblock ~152 ~7 ~37 black_glazed_terracotta 0
setblock ~153 ~7 ~26 soul_sand 0
setblock ~96 ~8 ~19 stained_hardened_clay 12
setblock ~96 ~8 ~20 planks 5
setblock ~96 ~8 ~21 stained_hardened_clay 7
setblock ~96 ~8 ~22 black_glazed_terracotta 0
setblock ~96 ~8 ~23 stained_hardened_clay 12
setblock ~96 ~8 ~24 stained_hardened_clay 7
setblock ~96 ~8 ~25 soul_sand 0
fill ~96 ~8 ~26 ~96 ~8 ~27 black_glazed_terracotta 0
setblock ~96 ~8 ~28 nether_brick 0
fill ~96 ~8 ~29 ~96 ~9 ~29 black_glazed_terracotta 0
setblock ~96 ~8 ~30 nether_brick 0
fill ~96 ~8 ~31 ~96 ~9 ~31 black_glazed_terracotta 0
setblock ~96 ~8 ~32 stained_hardened_clay 15
setblock ~96 ~8 ~33 stained_hardened_clay 7
fill ~96 ~8 ~34 ~97 ~8 ~34 planks 5
setblock ~97 ~8 ~16 black_glazed_terracotta 0
setblock ~97 ~8 ~17 stained_hardened_clay 12
setblock ~97 ~8 ~35 nether_brick 0
setblock ~98 ~8 ~14 nether_brick 0
setblock ~98 ~8 ~15 stained_hardened_clay 7
setblock ~98 ~8 ~35 stained_hardened_clay 7
setblock ~98 ~8 ~36 stained_hardened_clay 15
setblock ~99 ~8 ~35 stained_hardened_clay 12
setblock ~99 ~8 ~36 stained_hardened_clay 7
setblock ~100 ~8 ~12 black_glazed_terracotta 0
setblock ~100 ~8 ~36 nether_brick 0
setblock ~100 ~8 ~37 stained_hardened_clay 7
fill ~101 ~8 ~12 ~101 ~9 ~12 stained_hardened_clay 12
fill ~101 ~8 ~37 ~101 ~8 ~38 black_glazed_terracotta 0
fill ~102 ~8 ~11 ~102 ~9 ~11 stained_hardened_clay 12
setblock ~102 ~8 ~37 stained_hardened_clay 12
fill ~102 ~8 ~38 ~105 ~8 ~38 planks 5
setblock ~103 ~8 ~10 stained_hardened_clay 12
fill ~104 ~8 ~9 ~105 ~8 ~9 stained_hardened_clay 12
setblock ~104 ~8 ~39 black_glazed_terracotta 0
fill ~105 ~8 ~39 ~108 ~8 ~39 stained_hardened_clay 12
setblock ~106 ~8 ~10 black_glazed_terracotta 0
fill ~106 ~8 ~38 ~108 ~8 ~38 black_glazed_terracotta 0
setblock ~107 ~8 ~11 noteblock 0
setblock ~108 ~8 ~12 stained_hardened_clay 7
setblock ~108 ~8 ~13 stained_hardened_clay 12
setblock ~109 ~8 ~15 stained_hardened_clay 12
setblock ~109 ~8 ~16 black_glazed_terracotta 0
setblock ~109 ~8 ~17 noteblock 0
fill ~109 ~8 ~18 ~109 ~9 ~18 stained_hardened_clay 12
fill ~109 ~8 ~19 ~109 ~8 ~18 stained_hardened_clay 12
setblock ~109 ~8 ~20 stained_hardened_clay 7
fill ~109 ~8 ~21 ~109 ~9 ~21 soul_sand 0
fill ~109 ~8 ~22 ~109 ~8 ~21 soul_sand 0
setblock ~109 ~8 ~37 stained_hardened_clay 12
setblock ~109 ~8 ~38 log 1
setblock ~109 ~8 ~39 noteblock 0
fill ~110 ~8 ~24 ~110 ~8 ~25 stained_hardened_clay 7
setblock ~110 ~8 ~26 stained_hardened_clay 15
setblock ~110 ~8 ~28 stained_hardened_clay 15
setblock ~110 ~8 ~29 stained_hardened_clay 7
fill ~110 ~8 ~30 ~110 ~8 ~32 stained_hardened_clay 15
setblock ~110 ~8 ~33 stained_hardened_clay 12
setblock ~110 ~8 ~34 log 1
setblock ~110 ~8 ~36 black_glazed_terracotta 0
setblock ~138 ~8 ~24 nether_brick 0
fill ~138 ~8 ~26 ~138 ~8 ~27 stained_hardened_clay 7
setblock ~138 ~8 ~28 stained_hardened_clay 15
setblock ~138 ~8 ~30 stained_hardened_clay 15
setblock ~138 ~8 ~31 log2 1
setblock ~138 ~8 ~32 stained_hardened_clay 15
setblock ~138 ~8 ~33 black_glazed_terracotta 0
setblock ~138 ~8 ~34 planks 5
setblock ~138 ~8 ~35 stained_hardened_clay 12
setblock ~138 ~8 ~36 black_glazed_terracotta 0
setblock ~138 ~8 ~37 log 1
setblock ~138 ~8 ~38 black_glazed_terracotta 0
setblock ~139 ~8 ~16 stained_hardened_clay 7
setblock ~139 ~8 ~17 black_glazed_terracotta 0
fill ~139 ~8 ~19 ~139 ~8 ~20 stained_hardened_clay 12
fill ~139 ~8 ~21 ~139 ~10 ~21 soul_sand 0
setblock ~139 ~8 ~22 stained_hardened_clay 12
fill ~139 ~8 ~23 ~139 ~9 ~23 soul_sand 0
setblock ~139 ~8 ~38 stained_hardened_clay 7
setblock ~139 ~8 ~39 stained_hardened_clay 12
setblock ~139 ~8 ~40 log 1
setblock ~140 ~8 ~14 black_glazed_terracotta 0
fill ~140 ~8 ~39 ~140 ~8 ~40 black_glazed_terracotta 0
setblock ~141 ~8 ~12 stained_hardened_clay 7
setblock ~141 ~8 ~13 quartz_ore 0
fill ~141 ~8 ~39 ~143 ~8 ~39 stained_hardened_clay 12
setblock ~141 ~8 ~40 stained_hardened_clay 7
setblock ~142 ~8 ~11 black_glazed_terracotta 0
setblock ~142 ~8 ~40 log 1
setblock ~143 ~8 ~10 black_glazed_terracotta 0
setblock ~143 ~8 ~40 stained_hardened_clay 7
setblock ~144 ~8 ~11 noteblock 0
setblock ~144 ~8 ~39 planks 5
setblock ~144 ~8 ~40 black_glazed_terracotta 0
setblock ~145 ~8 ~12 noteblock 0
setblock ~145 ~8 ~39 noteblock 0
setblock ~146 ~8 ~12 planks 5
fill ~146 ~8 ~38 ~148 ~8 ~38 black_glazed_terracotta 0
setblock ~146 ~8 ~39 stained_hardened_clay 12
setblock ~148 ~8 ~14 planks 5
setblock ~148 ~8 ~37 stained_hardened_clay 7
setblock ~149 ~8 ~14 stained_hardened_clay 7
fill ~149 ~8 ~36 ~149 ~8 ~37 stained_hardened_clay 12
setblock ~150 ~8 ~15 black_glazed_terracotta 0
setblock ~150 ~8 ~16 stained_hardened_clay 15
setblock ~150 ~8 ~17 black_glazed_terracotta 0
fill ~150 ~8 ~35 ~151 ~8 ~35 stained_hardened_clay 12
setblock ~150 ~8 ~36 stained_hardened_clay 15
setblock ~150 ~8 ~37 stained_hardened_clay 7
setblock ~151 ~8 ~18 stained_hardened_clay 12
setblock ~151 ~8 ~36 coal_block 0
setblock ~152 ~8 ~21 log 1
setblock ~152 ~8 ~22 stained_hardened_clay 15
setblock ~152 ~8 ~23 stained_hardened_clay 12
setblock ~152 ~8 ~24 log2 1
setblock ~152 ~8 ~25 stained_hardened_clay 12
setblock ~152 ~8 ~26 soul_sand 0
fill ~152 ~8 ~27 ~152 ~9 ~27 stained_hardened_clay 12
setblock ~152 ~8 ~28 stained_hardened_clay 15
setblock ~152 ~8 ~29 stained_hardened_clay 7
setblock ~152 ~8 ~30 nether_brick 0
setblock ~152 ~8 ~31 black_glazed_terracotta 0
setblock ~152 ~8 ~32 stained_hardened_clay 15
setblock ~152 ~8 ~34 stained_hardened_clay 15
setblock ~96 ~9 ~22 stained_hardened_clay 12
setblock ~96 ~9 ~23 mycelium 0
setblock ~96 ~9 ~24 stained_hardened_clay 8
setblock ~96 ~9 ~25 stained_hardened_clay 12
setblock ~96 ~9 ~26 soul_sand 0
setblock ~96 ~9 ~27 nether_brick 0
setblock ~96 ~9 ~28 stained_hardened_clay 12
setblock ~96 ~9 ~30 noteblock 0
setblock ~97 ~9 ~17 soul_sand 0
fill ~97 ~9 ~19 ~97 ~9 ~20 soul_sand 0
fill ~97 ~9 ~21 ~97 ~10 ~21 stained_hardened_clay 7
setblock ~97 ~9 ~31 soul_sand 0
setblock ~97 ~9 ~32 black_glazed_terracotta 0
setblock ~97 ~9 ~33 noteblock 0
setblock ~97 ~9 ~34 coal_block 0
setblock ~98 ~9 ~14 stained_hardened_clay 12
setblock ~98 ~9 ~15 black_glazed_terracotta 0
setblock ~98 ~9 ~16 soul_sand 0
setblock ~98 ~9 ~32 stained_hardened_clay 12
setblock ~98 ~9 ~33 stained_hardened_clay 15
setblock ~98 ~9 ~34 nether_brick 0
setblock ~99 ~9 ~33 stained_hardened_clay 12
fill ~99 ~9 ~34 ~100 ~9 ~34 stained_hardened_clay 7
setblock ~100 ~9 ~13 stained_hardened_clay 15
setblock ~100 ~9 ~35 stained_hardened_clay 7
setblock ~101 ~9 ~35 stained_hardened_clay 12
setblock ~101 ~9 ~36 log 1
setblock ~102 ~9 ~35 black_glazed_terracotta 0
setblock ~102 ~9 ~36 stained_hardened_clay 12
fill ~103 ~9 ~11 ~103 ~10 ~11 soul_sand 0
setblock ~103 ~9 ~36 black_glazed_terracotta 0
setblock ~103 ~9 ~37 soul_sand 0
setblock ~104 ~9 ~10 soul_sand 0
setblock ~104 ~9 ~36 stained_hardened_clay 12
setblock ~104 ~9 ~37 planks 5
setblock ~105 ~9 ~9 soul_sand 0
setblock ~105 ~9 ~36 soul_sand 0
setblock ~105 ~9 ~37 noteblock 0
setblock ~106 ~9 ~10 soul_sand 0
setblock ~106 ~9 ~36 noteblock 0
setblock ~106 ~9 ~37 black_glazed_terracotta 0
fill ~107 ~9 ~11 ~107 ~10 ~11 soul_sand 0
fill ~107 ~9 ~12 ~107 ~9 ~11 soul_sand 0
setblock ~107 ~9 ~36 stained_hardened_clay 12
setblock ~107 ~9 ~37 soul_sand 0
setblock ~108 ~9 ~13 black_glazed_terracotta 0
setblock ~108 ~9 ~35 black_glazed_terracotta 0
setblock ~108 ~9 ~36 soul_sand 0
setblock ~108 ~9 ~37 black_glazed_terracotta 0
setblock ~109 ~9 ~14 log 1
fill ~109 ~9 ~15 ~109 ~10 ~15 soul_sand 0
setblock ~109 ~9 ~16 stained_hardened_clay 7
setblock ~109 ~9 ~17 soul_sand 0
fill ~109 ~9 ~19 ~109 ~9 ~21 soul_sand 0
fill ~109 ~9 ~22 ~109 ~10 ~22 stained_hardened_clay 12
setblock ~109 ~9 ~23 soul_sand 0
fill ~109 ~9 ~24 ~109 ~9 ~25 stained_hardened_clay 12
setblock ~109 ~9 ~31 soul_sand 0
setblock ~109 ~9 ~32 stained_hardened_clay 12
setblock ~109 ~9 ~33 soul_sand 0
setblock ~109 ~9 ~34 log 1
setblock ~109 ~9 ~35 stained_hardened_clay 12
setblock ~109 ~9 ~36 stained_hardened_clay 7
setblock ~110 ~9 ~26 soul_sand 0
setblock ~110 ~9 ~27 log2 1
fill ~110 ~9 ~28 ~110 ~9 ~30 soul_sand 0
setblock ~138 ~9 ~27 nether_brick 0
setblock ~138 ~9 ~28 soul_sand 0
setblock ~138 ~9 ~29 stained_hardened_clay 7
setblock ~138 ~9 ~30 soul_sand 0
setblock ~138 ~9 ~31 black_glazed_terracotta 0
setblock ~138 ~9 ~32 stained_hardened_clay 12
setblock ~139 ~9 ~16 stained_hardened_clay 12
setblock ~139 ~9 ~17 soul_sand 0
setblock ~139 ~9 ~18 stained_hardened_clay 12
fill ~139 ~9 ~19 ~139 ~9 ~23 soul_sand 0
setblock ~139 ~9 ~24 stained_hardened_clay 12
fill ~139 ~9 ~25 ~139 ~11 ~25 soul_sand 0
fill ~139 ~9 ~26 ~139 ~10 ~26 stained_hardened_clay 12
setblock ~139 ~9 ~33 soul_sand 0
setblock ~139 ~9 ~34 stained_hardened_clay 12
setblock ~139 ~9 ~35 noteblock 0
setblock ~139 ~9 ~36 black_glazed_terracotta 0
setblock ~139 ~9 ~37 soul_sand 0
setblock ~140 ~9 ~14 stained_hardened_clay 12
setblock ~140 ~9 ~15 planks 5
setblock ~140 ~9 ~36 noteblock 0
setblock ~140 ~9 ~37 black_glazed_terracotta 0
setblock ~140 ~9 ~38 stained_hardened_clay 12
setblock ~141 ~9 ~12 stained_hardened_clay 12
fill ~141 ~9 ~13 ~141 ~10 ~13 soul_sand 0
setblock ~141 ~9 ~37 soul_sand 0
setblock ~141 ~9 ~38 black_glazed_terracotta 0
setblock ~142 ~9 ~11 stained_hardened_clay 7
setblock ~142 ~9 ~37 stained_hardened_clay 7
setblock ~142 ~9 ~38 noteblock 0
setblock ~143 ~9 ~11 soul_sand 0
setblock ~143 ~9 ~37 stained_hardened_clay 12
setblock ~143 ~9 ~38 soul_sand 0
setblock ~144 ~9 ~11 stained_hardened_clay 7
setblock ~144 ~9 ~37 stained_hardened_clay 15
setblock ~144 ~9 ~38 stained_hardened_clay 12
setblock ~145 ~9 ~12 stained_hardened_clay 12
setblock ~145 ~9 ~37 soul_sand 0
setblock ~145 ~9 ~38 black_glazed_terracotta 0
setblock ~146 ~9 ~13 log 1
setblock ~146 ~9 ~36 stained_hardened_clay 12
setblock ~146 ~9 ~37 black_glazed_terracotta 0
fill ~147 ~9 ~14 ~147 ~11 ~14 stained_hardened_clay 7
setblock ~147 ~9 ~36 black_glazed_terracotta 0
setblock ~147 ~9 ~37 soul_sand 0
setblock ~148 ~9 ~14 log2 1
setblock ~148 ~9 ~35 black_glazed_terracotta 0
setblock ~148 ~9 ~36 stained_hardened_clay 12
fill ~149 ~9 ~14 ~149 ~9 ~15 stained_hardened_clay 12
setblock ~149 ~9 ~34 black_glazed_terracotta 0
setblock ~149 ~9 ~35 soul_sand 0
setblock ~150 ~9 ~16 stained_hardened_clay 12
setblock ~150 ~9 ~17 stained_hardened_clay 7
setblock ~150 ~9 ~18 soul_sand 0
setblock ~150 ~9 ~33 black_glazed_terracotta 0
setblock ~150 ~9 ~34 noteblock 0
setblock ~150 ~9 ~35 concrete 15
fill ~151 ~9 ~20 ~151 ~9 ~21 soul_sand 0
fill ~151 ~9 ~22 ~151 ~10 ~22 stained_hardened_clay 7
fill ~151 ~9 ~23 ~151 ~9 ~24 soul_sand 0
fill ~151 ~9 ~28 ~151 ~9 ~29 stained_hardened_clay 12
setblock ~151 ~9 ~30 stained_hardened_clay 7
setblock ~151 ~9 ~31 stained_hardened_clay 12
setblock ~151 ~9 ~32 black_glazed_terracotta 0
setblock ~151 ~9 ~33 stained_hardened_clay 12
setblock ~151 ~9 ~34 black_glazed_terracotta 0
setblock ~152 ~9 ~25 quartz_ore 0
setblock ~152 ~9 ~26 mycelium 0
setblock ~97 ~10 ~18 log2 1
setblock ~97 ~10 ~19 stained_hardened_clay 12
setblock ~97 ~10 ~20 stained_hardened_clay 7
setblock ~97 ~10 ~22 stained_hardened_clay 7
setblock ~97 ~10 ~23 soul_sand 0
fill ~97 ~10 ~24 ~97 ~11 ~24 nether_brick 0
setblock ~97 ~10 ~25 stained_hardened_clay 12
setblock ~97 ~10 ~26 black_glazed_terracotta 0
setblock ~97 ~10 ~27 stained_hardened_clay 12
setblock ~97 ~10 ~28 black_glazed_terracotta 0
setblock ~97 ~10 ~29 stained_hardened_clay 12
setblock ~97 ~10 ~30 black_glazed_terracotta 0
setblock ~98 ~10 ~15 nether_brick 0
setblock ~98 ~10 ~16 planks 5
fill ~98 ~10 ~17 ~98 ~11 ~17 black_glazed_terracotta 0
setblock ~98 ~10 ~30 nether_brick 0
setblock ~98 ~10 ~31 black_glazed_terracotta 0
fill ~99 ~10 ~14 ~99 ~11 ~14 stained_hardened_clay 7
setblock ~99 ~10 ~31 stained_hardened_clay 12
setblock ~99 ~10 ~32 stained_hardened_clay 15
setblock ~99 ~10 ~33 concrete 15
setblock ~100 ~10 ~13 stained_hardened_clay 7
fill ~100 ~10 ~32 ~100 ~10 ~33 black_glazed_terracotta 0
setblock ~101 ~10 ~13 stained_hardened_clay 12
setblock ~101 ~10 ~33 soul_sand 0
setblock ~101 ~10 ~34 black_glazed_terracotta 0
setblock ~102 ~10 ~12 black_glazed_terracotta 0
setblock ~102 ~10 ~33 stained_hardened_clay 7
setblock ~102 ~10 ~34 stained_hardened_clay 15
setblock ~103 ~10 ~34 planks 5
setblock ~103 ~10 ~35 stained_hardened_clay 12
fill ~104 ~10 ~10 ~105 ~10 ~10 black_glazed_terracotta 0
setblock ~104 ~10 ~34 black_glazed_terracotta 0
setblock ~104 ~10 ~35 stained_hardened_clay 7
setblock ~105 ~10 ~34 nether_brick 0
fill ~105 ~10 ~35 ~106 ~10 ~35 stained_hardened_clay 12
setblock ~106 ~10 ~11 stained_hardened_clay 12
setblock ~106 ~10 ~34 stained_hardened_clay 15
setblock ~107 ~10 ~12 log 1
fill ~107 ~10 ~33 ~108 ~10 ~33 black_glazed_terracotta 0
fill ~107 ~10 ~34 ~107 ~10 ~33 black_glazed_terracotta 0
setblock ~107 ~10 ~35 stained_hardened_clay 7
setblock ~108 ~10 ~13 stained_hardened_clay 7
setblock ~108 ~10 ~34 nether_brick 0
setblock ~109 ~10 ~14 stained_hardened_clay 7
setblock ~109 ~10 ~16 black_glazed_terracotta 0
setblock ~109 ~10 ~17 stained_hardened_clay 12
setblock ~109 ~10 ~18 black_glazed_terracotta 0
fill ~109 ~10 ~19 ~109 ~11 ~19 stained_hardened_clay 12
fill ~109 ~10 ~20 ~109 ~11 ~20 stained_hardened_clay 7
setblock ~109 ~10 ~21 stained_hardened_clay 12
setblock ~109 ~10 ~23 stained_hardened_clay 12
setblock ~109 ~10 ~24 log 1
setblock ~109 ~10 ~25 soul_sand 0
setblock ~109 ~10 ~26 stained_hardened_clay 12
setblock ~109 ~10 ~27 soul_sand 0
fill ~109 ~10 ~28 ~109 ~10 ~29 stained_hardened_clay 12
setblock ~109 ~10 ~30 stained_hardened_clay 7
setblock ~109 ~10 ~31 stained_hardened_clay 12
fill ~109 ~10 ~32 ~109 ~10 ~33 log 1
setblock ~109 ~10 ~34 planks 5
setblock ~139 ~10 ~16 black_glazed_terracotta 0
fill ~139 ~10 ~17 ~139 ~11 ~17 stained_hardened_clay 7
setblock ~139 ~10 ~18 nether_brick 0
setblock ~139 ~10 ~19 log2 1
setblock ~139 ~10 ~20 stained_hardened_clay 7
fill ~139 ~10 ~22 ~139 ~10 ~23 stained_hardened_clay 7
setblock ~139 ~10 ~24 stained_hardened_clay 15
setblock ~139 ~10 ~27 soul_sand 0
setblock ~139 ~10 ~28 stained_hardened_clay 12
fill ~139 ~10 ~29 ~139 ~11 ~29 soul_sand 0
setblock ~139 ~10 ~30 black_glazed_terracotta 0
fill ~139 ~10 ~31 ~139 ~11 ~31 stained_hardened_clay 12
setblock ~139 ~10 ~32 black_glazed_terracotta 0
setblock ~139 ~10 ~33 noteblock 0
setblock ~139 ~10 ~34 planks 5
setblock ~139 ~10 ~35 log 1
setblock ~140 ~10 ~14 black_glazed_terracotta 0
setblock ~140 ~10 ~15 stained_hardened_clay 12
setblock ~140 ~10 ~34 nether_brick 0
fill ~140 ~10 ~35 ~142 ~10 ~35 black_glazed_terracotta 0
setblock ~141 ~10 ~34 planks 5
fill ~141 ~10 ~36 ~142 ~10 ~36 stained_hardened_clay 15
fill ~142 ~10 ~12 ~144 ~10 ~12 stained_hardened_clay 7
setblock ~143 ~10 ~35 stained_hardened_clay 12
setblock ~143 ~10 ~36 nether_brick 0
setblock ~144 ~10 ~35 nether_brick 0
setblock ~144 ~10 ~36 stained_hardened_clay 15
setblock ~145 ~10 ~13 soul_sand 0
fill ~145 ~10 ~35 ~147 ~10 ~35 planks 5
setblock ~145 ~10 ~36 stained_hardened_clay 7
fill ~146 ~10 ~14 ~146 ~11 ~14 stained_hardened_clay 12
setblock ~146 ~10 ~34 black_glazed_terracotta 0
setblock ~147 ~10 ~34 stained_hardened_clay 12
setblock ~148 ~10 ~14 stained_hardened_clay 15
setblock ~148 ~10 ~33 black_glazed_terracotta 0
setblock ~148 ~10 ~34 stained_hardened_clay 15
setblock ~149 ~10 ~15 stained_hardened_clay 7
setblock ~149 ~10 ~16 black_glazed_terracotta 0
setblock ~149 ~10 ~32 planks 5
setblock ~149 ~10 ~33 stained_hardened_clay 15
setblock ~149 ~10 ~34 concrete 15
setblock ~150 ~10 ~17 log2 1
setblock ~150 ~10 ~18 stained_hardened_clay 15
setblock ~150 ~10 ~19 stained_hardened_clay 7
setblock ~150 ~10 ~20 stained_hardened_clay 15
setblock ~150 ~10 ~31 planks 5
setblock ~150 ~10 ~32 nether_brick 0
setblock ~151 ~10 ~21 soul_sand 0
setblock ~151 ~10 ~23 stained_hardened_clay 12
fill ~151 ~10 ~24 ~151 ~10 ~25 stained_hardened_clay 7
setblock ~151 ~10 ~26 black_glazed_terracotta 0
setblock ~151 ~10 ~27 noteblock 0
fill ~151 ~10 ~28 ~151 ~10 ~30 black_glazed_terracotta 0
setblock ~151 ~10 ~31 log 1
setblock ~97 ~11 ~22 soul_sand 0
setblock ~97 ~11 ~23 stained_hardened_clay 7
setblock ~97 ~11 ~25 noteblock 0
setblock ~97 ~11 ~26 log 1
fill ~97 ~11 ~27 ~97 ~11 ~28 stained_hardened_clay 7
setblock ~98 ~11 ~16 soul_sand 0
setblock ~98 ~11 ~18 soul_sand 0
fill ~98 ~11 ~19 ~98 ~12 ~19 stained_hardened_clay 15
setblock ~98 ~11 ~20 stained_hardened_clay 7
setblock ~98 ~11 ~21 nether_brick 0
setblock ~98 ~11 ~28 stained_hardened_clay 12
setblock ~98 ~11 ~29 nether_brick 0
setblock ~99 ~11 ~13 stained_hardened_clay 7
setblock ~99 ~11 ~15 soul_sand 0
setblock ~99 ~11 ~29 soul_sand 0
setblock ~99 ~11 ~30 planks 5
setblock ~100 ~11 ~13 stained_hardened_clay 15
setblock ~100 ~11 ~30 stained_hardened_clay 12
setblock ~100 ~11 ~31 concrete 15
setblock ~100 ~11 ~32 coal_block 0
fill ~101 ~11 ~13 ~101 ~13 ~13 stained_hardened_clay 7
setblock ~101 ~11 ~31 soul_sand 0
setblock ~101 ~11 ~32 stained_hardened_clay 12
setblock ~102 ~11 ~12 stained_hardened_clay 12
setblock ~102 ~11 ~31 stained_hardened_clay 12
setblock ~102 ~11 ~32 soul_sand 0
setblock ~103 ~11 ~12 stained_hardened_clay 7
setblock ~103 ~11 ~32 black_glazed_terracotta 0
setblock ~103 ~11 ~33 soul_sand 0
setblock ~104 ~11 ~11 black_glazed_terracotta 0
setblock ~104 ~11 ~32 noteblock 0
setblock ~104 ~11 ~33 stained_hardened_clay 7
setblock ~105 ~11 ~11 soul_sand 0
setblock ~105 ~11 ~32 black_glazed_terracotta 0
setblock ~105 ~11 ~33 stained_hardened_clay 12
setblock ~105 ~11 ~34 concrete 15
setblock ~106 ~11 ~11 nether_brick 0
setblock ~106 ~11 ~31 nether_brick 0
setblock ~106 ~11 ~32 stained_hardened_clay 12
setblock ~106 ~11 ~33 stained_hardened_clay 15
setblock ~106 ~11 ~34 coal_block 0
setblock ~106 ~11 ~35 concrete 15
setblock ~107 ~11 ~12 nether_brick 0
setblock ~107 ~11 ~31 stained_hardened_clay 12
setblock ~107 ~11 ~32 stained_hardened_clay 7
setblock ~108 ~11 ~13 stained_hardened_clay 15
setblock ~108 ~11 ~14 stained_hardened_clay 7
setblock ~108 ~11 ~30 stained_hardened_clay 12
setblock ~108 ~11 ~31 black_glazed_terracotta 0
setblock ~108 ~11 ~32 stained_hardened_clay 12
setblock ~109 ~11 ~15 stained_hardened_clay 7
setblock ~109 ~11 ~16 stained_hardened_clay 12
fill ~109 ~11 ~17 ~109 ~12 ~17 soul_sand 0
setblock ~109 ~11 ~18 log2 1
setblock ~109 ~11 ~21 soul_sand 0
setblock ~109 ~11 ~22 black_glazed_terracotta 0
setblock ~109 ~11 ~23 soul_sand 0
setblock ~109 ~11 ~24 stained_hardened_clay 12
setblock ~109 ~11 ~25 brown_glazed_terracotta 0
setblock ~109 ~11 ~26 soul_sand 0
setblock ~109 ~11 ~27 mycelium 0
setblock ~109 ~11 ~28 noteblock 0
setblock ~109 ~11 ~29 soul_sand 0
setblock ~109 ~11 ~30 black_glazed_terracotta 0
setblock ~139 ~11 ~16 nether_brick 0
fill ~139 ~11 ~18 ~139 ~11 ~19 soul_sand 0
setblock ~139 ~11 ~20 black_glazed_terracotta 0
setblock ~139 ~11 ~21 stained_hardened_clay 7
setblock ~139 ~11 ~22 black_glazed_terracotta 0
setblock ~139 ~11 ~23 stained_hardened_clay 7
setblock ~139 ~11 ~24 stained_hardened_clay 12
setblock ~139 ~11 ~26 soul_sand 0
setblock ~139 ~11 ~27 brown_glazed_terracotta 0
setblock ~139 ~11 ~28 dirt 1
setblock ~139 ~11 ~30 nether_brick 0
setblock ~140 ~11 ~14 stained_hardened_clay 7
fill ~140 ~11 ~15 ~140 ~12 ~15 nether_brick 0
setblock ~140 ~11 ~31 black_glazed_terracotta 0
setblock ~140 ~11 ~32 stained_hardened_clay 12
setblock ~140 ~11 ~33 nether_brick 0
setblock ~141 ~11 ~13 stained_hardened_clay 7
setblock ~141 ~11 ~32 black_glazed_terracotta 0
setblock ~141 ~11 ~33 noteblock 0
setblock ~142 ~11 ~13 nether_brick 0
setblock ~142 ~11 ~32 stained_hardened_clay 12
fill ~142 ~11 ~33 ~142 ~11 ~34 nether_brick 0
setblock ~142 ~11 ~35 concrete 15
setblock ~142 ~11 ~36 coal_block 0
setblock ~143 ~11 ~12 stained_hardened_clay 7
setblock ~143 ~11 ~33 noteblock 0
setblock ~143 ~11 ~34 stained_hardened_clay 7
fill ~144 ~11 ~13 ~144 ~12 ~13 stained_hardened_clay 15
setblock ~144 ~11 ~33 stained_hardened_clay 12
fill ~144 ~11 ~34 ~145 ~11 ~34 soul_sand 0
setblock ~145 ~11 ~13 stained_hardened_clay 7
fill ~145 ~11 ~33 ~147 ~11 ~33 soul_sand 0
setblock ~146 ~11 ~32 soul_sand 0
setblock ~147 ~11 ~31 soul_sand 0
setblock ~147 ~11 ~32 black_glazed_terracotta 0
setblock ~148 ~11 ~14 stained_hardened_clay 12
setblock ~148 ~11 ~31 nether_brick 0
setblock ~148 ~11 ~32 stained_hardened_clay 15
setblock ~148 ~11 ~33 concrete 15
fill ~149 ~11 ~15 ~149 ~12 ~15 nether_brick 0
fill ~149 ~11 ~16 ~149 ~11 ~15 nether_brick 0
setblock ~149 ~11 ~17 soul_sand 0
setblock ~149 ~11 ~30 planks 5
setblock ~149 ~11 ~31 stained_hardened_clay 12
setblock ~150 ~11 ~18 soul_sand 0
setblock ~150 ~11 ~19 stained_hardened_clay 15
setblock ~150 ~11 ~20 stained_hardened_clay 7
