fill ~4 ~-3 ~46 ~8 ~-3 ~46 stone 0
fill ~4 ~-3 ~47 ~7 ~-3 ~47 stone 0
fill ~4 ~-3 ~48 ~7 ~-3 ~48 stone 0
fill ~4 ~-3 ~49 ~7 ~-3 ~49 stone 0
fill ~4 ~-3 ~50 ~7 ~-3 ~50 stone 0
fill ~4 ~-3 ~51 ~7 ~-3 ~51 stone 0
fill ~4 ~-3 ~52 ~7 ~-3 ~52 stone 0
fill ~4 ~-3 ~53 ~7 ~-3 ~53 stone 0
fill ~4 ~-3 ~54 ~7 ~-3 ~54 stone 0
fill ~4 ~-3 ~55 ~7 ~-3 ~55 stone 0
fill ~4 ~-3 ~56 ~7 ~-3 ~56 stone 0
fill ~4 ~-3 ~57 ~7 ~-3 ~57 stone 0
fill ~4 ~-3 ~58 ~8 ~-3 ~58 stone 0
fill ~4 ~-3 ~59 ~8 ~-3 ~59 stone 0
fill ~5 ~-3 ~43 ~9 ~-3 ~43 stone 0
fill ~5 ~-3 ~44 ~8 ~-3 ~44 stone 0
fill ~5 ~-3 ~45 ~8 ~-3 ~45 stone 0
fill ~5 ~-3 ~60 ~8 ~-3 ~60 stone 0
fill ~5 ~-3 ~61 ~8 ~-3 ~61 stone 0
fill ~5 ~-3 ~62 ~9 ~-3 ~62 stone 0
fill ~6 ~-3 ~40 ~11 ~-3 ~40 stone 0
fill ~6 ~-3 ~41 ~10 ~-3 ~41 stone 0
fill ~6 ~-3 ~42 ~9 ~-3 ~42 stone 0
fill ~6 ~-3 ~63 ~9 ~-3 ~63 stone 0
fill ~6 ~-3 ~64 ~10 ~-3 ~64 stone 0
fill ~6 ~-3 ~65 ~10 ~-3 ~65 stone 0
fill ~7 ~-3 ~38 ~12 ~-3 ~38 stone 0
fill ~7 ~-3 ~39 ~11 ~-3 ~39 stone 0
fill ~7 ~-3 ~66 ~11 ~-3 ~66 stone 0
fill ~7 ~-3 ~67 ~12 ~-3 ~67 stone 0
fill ~8 ~-3 ~37 ~14 ~-3 ~37 stone 0
fill ~8 ~-3 ~47 ~24 ~-3 ~47 wool 8
fill ~8 ~-3 ~48 ~22 ~-3 ~48 wool 8
fill ~8 ~-3 ~49 ~23 ~-3 ~49 wool 8
fill ~8 ~-3 ~50 ~24 ~-3 ~50 wool 8
fill ~8 ~-3 ~51 ~25 ~-3 ~51 wool 8
fill ~8 ~-3 ~52 ~25 ~-3 ~52 wool 8
fill ~8 ~-3 ~53 ~27 ~-3 ~53 wool 8
fill ~8 ~-3 ~54 ~29 ~-3 ~54 wool 8
fill ~8 ~-3 ~55 ~31 ~-3 ~55 wool 8
fill ~8 ~-3 ~56 ~30 ~-3 ~56 wool 8
fill ~8 ~-3 ~57 ~33 ~-3 ~57 wool 8
fill ~8 ~-3 ~68 ~13 ~-3 ~68 stone 0
fill ~9 ~-3 ~35 ~18 ~-3 ~35 stone 0
fill ~9 ~-3 ~36 ~15 ~-3 ~36 stone 0
fill ~9 ~-3 ~44 ~21 ~-3 ~44 wool 8
fill ~9 ~-3 ~45 ~22 ~-3 ~45 wool 8
fill ~9 ~-3 ~46 ~23 ~-3 ~46 wool 8
fill ~9 ~-3 ~58 ~48 ~-3 ~58 wool 8
fill ~9 ~-3 ~59 ~47 ~-3 ~59 wool 8
fill ~9 ~-3 ~60 ~48 ~-3 ~60 wool 8
fill ~9 ~-3 ~61 ~49 ~-3 ~61 wool 8
fill ~9 ~-3 ~69 ~14 ~-3 ~69 stone 0
fill ~9 ~-3 ~70 ~15 ~-3 ~70 stone 0
fill ~10 ~-3 ~34 ~22 ~-3 ~34 stone 0
fill ~10 ~-3 ~42 ~21 ~-3 ~42 wool 8
fill ~10 ~-3 ~43 ~20 ~-3 ~43 wool 8
fill ~10 ~-3 ~62 ~47 ~-3 ~62 wool 8
fill ~10 ~-3 ~63 ~45 ~-3 ~63 wool 8
fill ~10 ~-3 ~71 ~17 ~-3 ~71 stone 0
fill ~11 ~-3 ~33 ~56 ~-3 ~33 stone 0
fill ~11 ~-3 ~41 ~22 ~-3 ~41 wool 8
fill ~11 ~-3 ~64 ~47 ~-3 ~64 wool 8
fill ~11 ~-3 ~65 ~49 ~-3 ~65 wool 8
fill ~11 ~-3 ~72 ~19 ~-3 ~72 stone 0
fill ~12 ~-3 ~32 ~55 ~-3 ~32 stone 0
fill ~12 ~-3 ~39 ~24 ~-3 ~39 wool 8
fill ~12 ~-3 ~40 ~23 ~-3 ~40 wool 8
fill ~12 ~-3 ~66 ~45 ~-3 ~66 wool 8
fill ~12 ~-3 ~73 ~55 ~-3 ~73 stone 0
fill ~13 ~-3 ~31 ~54 ~-3 ~31 stone 0
fill ~13 ~-3 ~38 ~45 ~-3 ~38 wool 8
fill ~13 ~-3 ~67 ~46 ~-3 ~67 wool 8
fill ~13 ~-3 ~74 ~54 ~-3 ~74 stone 0
fill ~14 ~-3 ~30 ~53 ~-3 ~30 stone 0
fill ~14 ~-3 ~68 ~40 ~-3 ~68 wool 8
fill ~14 ~-3 ~75 ~53 ~-3 ~75 stone 0
fill ~15 ~-3 ~29 ~52 ~-3 ~29 stone 0
fill ~15 ~-3 ~37 ~34 ~-3 ~37 wool 8
fill ~15 ~-3 ~69 ~38 ~-3 ~69 wool 8
fill ~15 ~-3 ~76 ~52 ~-3 ~76 stone 0
fill ~16 ~-3 ~28 ~51 ~-3 ~28 stone 0
fill ~16 ~-3 ~36 ~32 ~-3 ~36 wool 8
fill ~16 ~-3 ~70 ~35 ~-3 ~70 wool 8
fill ~16 ~-3 ~77 ~51 ~-3 ~77 stone 0
fill ~18 ~-3 ~27 ~49 ~-3 ~27 stone 0
fill ~18 ~-3 ~71 ~33 ~-3 ~71 wool 8
fill ~18 ~-3 ~78 ~49 ~-3 ~78 stone 0
fill ~19 ~-3 ~26 ~48 ~-3 ~26 stone 0
fill ~19 ~-3 ~35 ~30 ~-3 ~35 wool 8
fill ~19 ~-3 ~79 ~48 ~-3 ~79 stone 0
fill ~20 ~-3 ~72 ~30 ~-3 ~72 wool 8
fill ~21 ~-3 ~25 ~46 ~-3 ~25 stone 0
fill ~21 ~-3 ~43 ~25 ~-3 ~43 stained_hardened_clay 0
fill ~21 ~-3 ~80 ~46 ~-3 ~80 stone 0
fill ~22 ~-3 ~42 ~25 ~-3 ~42 stained_hardened_clay 0
fill ~22 ~-3 ~44 ~39 ~-3 ~44 stained_hardened_clay 0
fill ~23 ~-3 ~34 ~25 ~-3 ~34 wool 8
fill ~23 ~-3 ~41 ~36 ~-3 ~41 stained_hardened_clay 0
fill ~23 ~-3 ~45 ~40 ~-3 ~45 stained_hardened_clay 0
fill ~23 ~-3 ~48 ~30 ~-3 ~48 stained_hardened_clay 0
fill ~24 ~-3 ~24 ~43 ~-3 ~24 stone 0
fill ~24 ~-3 ~40 ~35 ~-3 ~40 stained_hardened_clay 0
fill ~24 ~-3 ~46 ~30 ~-3 ~46 stained_hardened_clay 0
fill ~24 ~-3 ~49 ~41 ~-3 ~49 stained_hardened_clay 0
fill ~24 ~-3 ~81 ~43 ~-3 ~81 stone 0
fill ~25 ~-3 ~39 ~32 ~-3 ~39 stained_hardened_clay 0
fill ~25 ~-3 ~47 ~30 ~-3 ~47 stained_hardened_clay 0
fill ~25 ~-3 ~50 ~42 ~-3 ~50 stained_hardened_clay 0
fill ~26 ~-3 ~34 ~57 ~-3 ~34 stone 0
fill ~26 ~-3 ~42 ~28 ~-3 ~42 wool 15
fill ~26 ~-3 ~43 ~28 ~-3 ~43 wool 15
fill ~26 ~-3 ~51 ~28 ~-3 ~51 wool 15
fill ~26 ~-3 ~52 ~28 ~-3 ~52 wool 15
fill ~27 ~-3 ~23 ~40 ~-3 ~23 stone 0
fill ~27 ~-3 ~82 ~40 ~-3 ~82 stone 0
fill ~28 ~-3 ~53 ~46 ~-3 ~53 stained_hardened_clay 0
fill ~29 ~-3 ~42 ~38 ~-3 ~42 stained_hardened_clay 0
fill ~29 ~-3 ~43 ~38 ~-3 ~43 stained_hardened_clay 0
fill ~29 ~-3 ~51 ~51 ~-3 ~51 stained_hardened_clay 0
fill ~29 ~-3 ~52 ~47 ~-3 ~52 stained_hardened_clay 0
fill ~30 ~-3 ~54 ~45 ~-3 ~54 stained_hardened_clay 0
fill ~31 ~-3 ~35 ~58 ~-3 ~35 stone 0
fill ~31 ~-3 ~46 ~31 ~-3 ~48 stained_hardened_clay 14
fill ~31 ~-3 ~56 ~42 ~-3 ~56 stained_hardened_clay 0
fill ~31 ~-3 ~72 ~56 ~-3 ~72 stone 0
fill ~32 ~-3 ~46 ~40 ~-3 ~46 stained_hardened_clay 0
fill ~32 ~-3 ~47 ~40 ~-3 ~47 stained_hardened_clay 0
fill ~32 ~-3 ~48 ~41 ~-3 ~48 stained_hardened_clay 0
fill ~32 ~-3 ~55 ~44 ~-3 ~55 stained_hardened_clay 0
fill ~33 ~-3 ~36 ~45 ~-3 ~36 stone 0
fill ~33 ~-3 ~39 ~44 ~-3 ~39 wool 8
fill ~34 ~-3 ~57 ~39 ~-3 ~57 stained_hardened_clay 0
fill ~34 ~-3 ~71 ~57 ~-3 ~71 stone 0
fill ~35 ~-3 ~37 ~43 ~-3 ~37 stone 0
fill ~36 ~-3 ~40 ~43 ~-3 ~40 wool 8
fill ~36 ~-3 ~70 ~58 ~-3 ~70 stone 0
fill ~37 ~-3 ~41 ~46 ~-3 ~41 wool 8
fill ~39 ~-3 ~42 ~45 ~-3 ~42 wool 8
fill ~39 ~-3 ~43 ~43 ~-3 ~43 wool 8
fill ~39 ~-3 ~69 ~46 ~-3 ~69 stone 0
fill ~40 ~-3 ~44 ~45 ~-3 ~44 wool 8
fill ~40 ~-3 ~57 ~49 ~-3 ~57 wool 8
fill ~41 ~-3 ~45 ~45 ~-3 ~45 wool 8
fill ~41 ~-3 ~46 ~44 ~-3 ~46 wool 8
fill ~41 ~-3 ~47 ~44 ~-3 ~47 wool 8
fill ~41 ~-3 ~68 ~43 ~-3 ~68 stone 0
fill ~42 ~-3 ~48 ~44 ~-3 ~48 wool 8
fill ~42 ~-3 ~49 ~46 ~-3 ~49 wool 8
fill ~43 ~-3 ~50 ~46 ~-3 ~50 wool 8
fill ~43 ~-3 ~56 ~47 ~-3 ~56 wool 8
fill ~44 ~-3 ~37 ~46 ~-3 ~37 wool 8
fill ~44 ~-3 ~40 ~61 ~-3 ~40 stone 0
fill ~44 ~-3 ~43 ~50 ~-3 ~43 stone 0
fill ~44 ~-3 ~68 ~47 ~-3 ~68 wool 8
fill ~45 ~-3 ~39 ~60 ~-3 ~39 stone 0
fill ~45 ~-3 ~46 ~48 ~-3 ~46 stone 0
fill ~45 ~-3 ~47 ~47 ~-3 ~47 stone 0
fill ~45 ~-3 ~48 ~47 ~-3 ~48 stone 0
fill ~45 ~-3 ~55 ~47 ~-3 ~55 wool 8
setblock ~46 ~-3 ~36 wool 8
fill ~46 ~-3 ~38 ~60 ~-3 ~38 stone 0
fill ~46 ~-3 ~42 ~51 ~-3 ~42 stone 0
fill ~46 ~-3 ~44 ~49 ~-3 ~44 stone 0
fill ~46 ~-3 ~45 ~48 ~-3 ~45 stone 0
fill ~46 ~-3 ~54 ~48 ~-3 ~54 wool 8
fill ~46 ~-3 ~63 ~50 ~-3 ~63 stone 0
fill ~46 ~-3 ~66 ~60 ~-3 ~66 stone 0
fill ~47 ~-3 ~36 ~58 ~-3 ~36 stone 0
fill ~47 ~-3 ~37 ~59 ~-3 ~37 stone 0
fill ~47 ~-3 ~41 ~55 ~-3 ~41 stone 0
fill ~47 ~-3 ~49 ~47 ~-1 ~49 stone 0
fill ~47 ~-3 ~50 ~51 ~-3 ~50 stained_hardened_clay 0
fill ~47 ~-3 ~53 ~48 ~-3 ~53 wool 8
fill ~47 ~-3 ~67 ~60 ~-3 ~67 stone 0
fill ~47 ~-3 ~69 ~48 ~-3 ~69 wool 8
fill ~48 ~-3 ~47 ~51 ~-3 ~47 wool 11
fill ~48 ~-3 ~48 ~52 ~-3 ~48 wool 11
fill ~48 ~-3 ~49 ~49 ~-3 ~49 stained_hardened_clay 0
setblock ~48 ~-3 ~52 wool 8
fill ~48 ~-3 ~55 ~50 ~-3 ~55 stained_hardened_clay 0
fill ~48 ~-3 ~56 ~49 ~-3 ~56 stained_hardened_clay 0
fill ~48 ~-3 ~59 ~48 ~-1 ~59 stone 0
fill ~48 ~-3 ~62 ~49 ~-3 ~62 stone 0
fill ~48 ~-3 ~64 ~51 ~-3 ~64 stone 0
fill ~48 ~-3 ~68 ~59 ~-3 ~68 stone 0
fill ~49 ~-3 ~45 ~49 ~-3 ~48 wool 11
fill ~49 ~-3 ~52 ~51 ~-3 ~52 stained_hardened_clay 0
fill ~49 ~-3 ~53 ~51 ~-3 ~53 stained_hardened_clay 0
fill ~49 ~-3 ~54 ~51 ~-3 ~54 stained_hardened_clay 0
fill ~49 ~-3 ~58 ~51 ~-3 ~58 wool 11
fill ~49 ~-3 ~59 ~50 ~-3 ~59 wool 11
fill ~49 ~-3 ~60 ~49 ~-3 ~58 wool 11
fill ~49 ~-3 ~69 ~58 ~-3 ~69 stone 0
fill ~50 ~-3 ~44 ~61 ~-3 ~44 snow 0
fill ~50 ~-3 ~45 ~61 ~-3 ~45 snow 0
setblock ~50 ~-3 ~46 wool 11
fill ~50 ~-3 ~49 ~52 ~-3 ~49 wool 11
fill ~50 ~-3 ~56 ~52 ~-3 ~56 wool 11
fill ~50 ~-3 ~57 ~51 ~-3 ~57 wool 11
fill ~50 ~-3 ~60 ~61 ~-3 ~60 snow 0
fill ~50 ~-3 ~61 ~61 ~-3 ~61 snow 0
fill ~50 ~-3 ~62 ~61 ~-3 ~62 snow 0
fill ~50 ~-3 ~65 ~55 ~-3 ~65 stone 0
fill ~51 ~-3 ~43 ~61 ~-3 ~43 snow 0
fill ~51 ~-3 ~46 ~62 ~-3 ~46 snow 0
fill ~51 ~-3 ~55 ~52 ~-3 ~55 wool 11
fill ~51 ~-3 ~59 ~62 ~-3 ~59 snow 0
fill ~51 ~-3 ~63 ~60 ~-3 ~63 snow 0
fill ~52 ~-3 ~42 ~60 ~-3 ~42 snow 0
fill ~52 ~-3 ~47 ~62 ~-3 ~47 snow 0
fill ~52 ~-3 ~50 ~53 ~-3 ~50 wool 11
fill ~52 ~-3 ~51 ~52 ~-3 ~52 snow 0
fill ~52 ~-3 ~53 ~53 ~-3 ~53 wool 11
fill ~52 ~-3 ~54 ~53 ~-3 ~54 wool 11
fill ~52 ~-3 ~57 ~62 ~-3 ~57 snow 0
fill ~52 ~-3 ~58 ~62 ~-3 ~58 snow 0
fill ~52 ~-3 ~64 ~60 ~-3 ~64 snow 0
fill ~53 ~-3 ~48 ~62 ~-3 ~48 snow 0
fill ~53 ~-3 ~49 ~57 ~-3 ~49 snow 0
fill ~53 ~-3 ~51 ~53 ~-3 ~54 wool 11
fill ~53 ~-3 ~55 ~62 ~-3 ~55 snow 0
fill ~53 ~-3 ~56 ~62 ~-3 ~56 snow 0
fill ~54 ~-3 ~50 ~55 ~-3 ~50 snow 0
fill ~54 ~-3 ~51 ~54 ~-3 ~52 stained_hardened_clay 14
fill ~54 ~-3 ~53 ~62 ~-3 ~53 snow 0
fill ~54 ~-3 ~54 ~62 ~-3 ~54 snow 0
fill ~55 ~-3 ~51 ~62 ~-3 ~51 wool 14
setblock ~55 ~-3 ~52 stained_hardened_clay 14
fill ~56 ~-3 ~41 ~60 ~-3 ~41 snow 0
fill ~56 ~-3 ~50 ~62 ~-3 ~50 wool 14
fill ~56 ~-3 ~52 ~60 ~-3 ~52 snow 0
fill ~56 ~-3 ~65 ~60 ~-3 ~65 snow 0
fill ~58 ~-3 ~49 ~60 ~-3 ~49 wool 14
fill ~61 ~-3 ~41 ~61 ~0 ~41 stone 0
fill ~61 ~-3 ~42 ~61 ~0 ~42 stone 0
fill ~61 ~-3 ~49 ~62 ~-3 ~49 snow 0
fill ~61 ~-3 ~52 ~62 ~-3 ~52 wool 14
fill ~61 ~-3 ~63 ~61 ~0 ~63 stone 0
fill ~61 ~-3 ~64 ~61 ~0 ~64 stone 0
fill ~61 ~-3 ~65 ~61 ~0 ~65 stone 0
fill ~62 ~-3 ~43 ~62 ~0 ~43 stone 0
fill ~62 ~-3 ~44 ~62 ~0 ~44 stone 0
fill ~62 ~-3 ~45 ~62 ~0 ~45 stone 0
fill ~62 ~-3 ~60 ~62 ~0 ~60 stone 0
fill ~62 ~-3 ~61 ~62 ~0 ~61 stone 0
fill ~62 ~-3 ~62 ~62 ~0 ~62 stone 0
fill ~63 ~-3 ~46 ~63 ~0 ~46 stone 0
fill ~63 ~-3 ~47 ~63 ~0 ~47 stone 0
fill ~63 ~-3 ~48 ~63 ~0 ~48 stone 0
fill ~63 ~-3 ~49 ~63 ~0 ~49 stone 0
fill ~63 ~-3 ~50 ~63 ~0 ~50 stone 0
fill ~63 ~-3 ~51 ~63 ~0 ~51 stone 0
fill ~63 ~-3 ~52 ~63 ~0 ~52 stone 0
fill ~63 ~-3 ~53 ~63 ~0 ~53 stone 0
fill ~63 ~-3 ~54 ~63 ~0 ~54 stone 0
fill ~63 ~-3 ~55 ~63 ~0 ~55 stone 0
fill ~63 ~-3 ~56 ~63 ~0 ~56 stone 0
fill ~63 ~-3 ~57 ~63 ~0 ~57 stone 0
fill ~63 ~-3 ~58 ~63 ~0 ~58 stone 0
fill ~63 ~-3 ~59 ~63 ~0 ~59 stone 0
setblock ~3 ~-2 ~46 stone_slab 14
fill ~3 ~-2 ~48 ~3 ~-1 ~48 double_stone_slab 6
fill ~3 ~-2 ~49 ~3 ~0 ~49 stone_slab 6
fill ~3 ~-2 ~50 ~3 ~0 ~50 stone_slab 6
fill ~3 ~-2 ~55 ~3 ~-1 ~55 double_stone_slab 6
setblock ~3 ~-2 ~57 double_stone_slab 6
setblock ~4 ~-2 ~44 stone_slab 14
setblock ~4 ~-2 ~45 stone_slab 6
fill ~4 ~-2 ~46 ~63 ~-2 ~46 stone 0
fill ~4 ~-2 ~47 ~63 ~-2 ~47 stone 0
fill ~4 ~-2 ~48 ~63 ~-2 ~48 stone 0
fill ~4 ~-2 ~49 ~63 ~-2 ~49 stone 0
fill ~4 ~-2 ~50 ~63 ~-2 ~50 stone 0
fill ~4 ~-2 ~51 ~63 ~-2 ~51 stone 0
fill ~4 ~-2 ~52 ~63 ~-2 ~52 stone 0
fill ~4 ~-2 ~53 ~63 ~-2 ~53 stone 0
fill ~4 ~-2 ~54 ~63 ~-2 ~54 stone 0
fill ~4 ~-2 ~55 ~63 ~-2 ~55 stone 0
fill ~4 ~-2 ~56 ~63 ~-2 ~56 stone 0
fill ~4 ~-2 ~57 ~63 ~-2 ~57 stone 0
fill ~4 ~-2 ~58 ~63 ~-2 ~58 stone 0
fill ~4 ~-2 ~59 ~63 ~-2 ~59 stone 0
setblock ~4 ~-2 ~60 double_stone_slab 6
setblock ~5 ~-2 ~40 double_stone_slab 6
fill ~5 ~-2 ~41 ~5 ~0 ~41 stone_slab 6
fill ~5 ~-2 ~42 ~5 ~-2 ~41 stone_slab 6
fill ~5 ~-2 ~43 ~62 ~-2 ~43 stone 0
fill ~5 ~-2 ~44 ~62 ~-2 ~44 stone 0
fill ~5 ~-2 ~45 ~62 ~-2 ~45 stone 0
fill ~5 ~-2 ~60 ~62 ~-2 ~60 stone 0
fill ~5 ~-2 ~61 ~62 ~-2 ~61 stone 0
fill ~5 ~-2 ~62 ~62 ~-2 ~62 stone 0
setblock ~5 ~-2 ~63 stone_slab 14
setblock ~5 ~-2 ~64 stone_slab 6
setblock ~5 ~-2 ~65 stone_slab 14
fill ~6 ~-2 ~38 ~6 ~-1 ~38 double_stone_slab 6
fill ~6 ~-2 ~40 ~61 ~-2 ~40 stone 0
fill ~6 ~-2 ~41 ~61 ~-2 ~41 stone 0
fill ~6 ~-2 ~42 ~61 ~-2 ~42 stone 0
fill ~6 ~-2 ~63 ~61 ~-2 ~63 stone 0
fill ~6 ~-2 ~64 ~61 ~-2 ~64 stone 0
fill ~6 ~-2 ~65 ~61 ~-2 ~65 stone 0
setblock ~6 ~-2 ~67 stone_slab 6
setblock ~7 ~-2 ~37 stone_slab 14
fill ~7 ~-2 ~38 ~60 ~-2 ~38 stone 0
fill ~7 ~-2 ~39 ~60 ~-2 ~39 stone 0
fill ~7 ~-2 ~66 ~60 ~-2 ~66 stone 0
fill ~7 ~-2 ~67 ~60 ~-2 ~67 stone 0
fill ~7 ~-2 ~68 ~7 ~0 ~68 stone_slab 6
fill ~8 ~-2 ~36 ~8 ~-1 ~36 double_stone_slab 6
fill ~8 ~-2 ~37 ~59 ~-2 ~37 stone 0
fill ~8 ~-2 ~68 ~59 ~-2 ~68 stone 0
setblock ~8 ~-2 ~69 stone_slab 14
setblock ~9 ~-2 ~34 stone_slab 14
fill ~9 ~-2 ~35 ~58 ~-2 ~35 stone 0
fill ~9 ~-2 ~36 ~58 ~-2 ~36 stone 0
fill ~9 ~-2 ~69 ~58 ~-2 ~69 stone 0
fill ~9 ~-2 ~70 ~58 ~-2 ~70 stone 0
setblock ~9 ~-2 ~71 stone_slab 14
setblock ~10 ~-2 ~33 stone_slab 6
fill ~10 ~-2 ~34 ~57 ~-2 ~34 stone 0
fill ~10 ~-2 ~71 ~57 ~-2 ~71 stone 0
setblock ~10 ~-2 ~72 stone_slab 6
setblock ~11 ~-2 ~32 stone_slab 14
fill ~11 ~-2 ~33 ~56 ~-2 ~33 stone 0
fill ~11 ~-2 ~72 ~56 ~-2 ~72 stone 0
setblock ~11 ~-2 ~73 stone_slab 14
setblock ~12 ~-2 ~31 stone_slab 6
fill ~12 ~-2 ~32 ~55 ~-2 ~32 stone 0
fill ~12 ~-2 ~73 ~55 ~-2 ~73 stone 0
setblock ~13 ~-2 ~30 stone_slab 14
fill ~13 ~-2 ~31 ~54 ~-2 ~31 stone 0
fill ~13 ~-2 ~74 ~54 ~-2 ~74 stone 0
fill ~13 ~-2 ~75 ~13 ~-1 ~75 double_stone_slab 6
fill ~14 ~-2 ~30 ~53 ~-2 ~30 stone 0
fill ~14 ~-2 ~75 ~53 ~-2 ~75 stone 0
fill ~15 ~-2 ~28 ~15 ~-1 ~28 double_stone_slab 6
fill ~15 ~-2 ~29 ~52 ~-2 ~29 stone 0
fill ~15 ~-2 ~76 ~52 ~-2 ~76 stone 0
setblock ~15 ~-2 ~77 double_stone_slab 6
setblock ~16 ~-2 ~27 stone_slab 14
fill ~16 ~-2 ~28 ~51 ~-2 ~28 stone 0
fill ~16 ~-2 ~77 ~51 ~-2 ~77 stone 0
fill ~17 ~-2 ~27 ~17 ~-1 ~27 double_stone_slab 6
fill ~17 ~-2 ~78 ~17 ~-1 ~78 double_stone_slab 6
fill ~18 ~-2 ~27 ~49 ~-2 ~27 stone 0
fill ~18 ~-2 ~78 ~49 ~-2 ~78 stone 0
fill ~18 ~-2 ~79 ~18 ~0 ~79 stone_slab 6
setblock ~19 ~-2 ~25 double_stone_slab 6
fill ~19 ~-2 ~26 ~48 ~-2 ~26 stone 0
fill ~19 ~-2 ~79 ~48 ~-2 ~79 stone 0
fill ~19 ~-2 ~80 ~19 ~0 ~80 stone_slab 6
fill ~21 ~-2 ~24 ~21 ~-1 ~24 double_stone_slab 6
fill ~21 ~-2 ~25 ~46 ~-2 ~25 stone 0
fill ~21 ~-2 ~80 ~46 ~-2 ~80 stone 0
fill ~24 ~-2 ~24 ~43 ~-2 ~24 stone 0
fill ~24 ~-2 ~81 ~43 ~-2 ~81 stone 0
fill ~27 ~-2 ~23 ~40 ~-2 ~23 stone 0
fill ~27 ~-2 ~82 ~40 ~-2 ~82 stone 0
fill ~46 ~-2 ~81 ~46 ~-1 ~81 double_stone_slab 6
fill ~48 ~-2 ~25 ~48 ~0 ~25 stone_slab 6
setblock ~48 ~-2 ~80 double_stone_slab 6
fill ~49 ~-2 ~26 ~49 ~0 ~26 stone_slab 6
fill ~50 ~-2 ~27 ~50 ~-1 ~27 double_stone_slab 6
fill ~50 ~-2 ~78 ~50 ~-1 ~78 double_stone_slab 6
setblock ~51 ~-2 ~78 stone_slab 14
setblock ~52 ~-2 ~28 double_stone_slab 6
fill ~52 ~-2 ~77 ~52 ~-1 ~77 double_stone_slab 6
fill ~54 ~-2 ~30 ~54 ~-1 ~30 double_stone_slab 6
setblock ~54 ~-2 ~75 stone_slab 14
setblock ~55 ~-2 ~74 stone_slab 6
setblock ~56 ~-2 ~32 stone_slab 14
setblock ~56 ~-2 ~73 stone_slab 14
setblock ~57 ~-2 ~33 stone_slab 6
setblock ~57 ~-2 ~72 stone_slab 6
setblock ~58 ~-2 ~34 stone_slab 14
setblock ~58 ~-2 ~71 stone_slab 14
setblock ~59 ~-2 ~36 stone_slab 14
fill ~59 ~-2 ~69 ~59 ~-1 ~69 double_stone_slab 6
fill ~60 ~-2 ~37 ~60 ~0 ~37 stone_slab 6
setblock ~60 ~-2 ~68 stone_slab 14
setblock ~61 ~-2 ~38 stone_slab 6
fill ~61 ~-2 ~67 ~61 ~-1 ~67 double_stone_slab 6
setblock ~62 ~-2 ~40 stone_slab 14
setblock ~62 ~-2 ~41 stone_slab 6
setblock ~62 ~-2 ~42 stone_slab 14
fill ~62 ~-2 ~63 ~62 ~-2 ~64 stone_slab 6
setblock ~62 ~-2 ~65 double_stone_slab 6
setblock ~63 ~-2 ~45 double_stone_slab 6
setblock ~63 ~-2 ~60 stone_slab 6
setblock ~63 ~-2 ~61 stone_slab 14
setblock ~64 ~-2 ~48 double_stone_slab 6
fill ~64 ~-2 ~50 ~64 ~-1 ~50 double_stone_slab 6
fill ~64 ~-2 ~55 ~64 ~0 ~55 stone_slab 6
fill ~64 ~-2 ~56 ~64 ~0 ~56 stone_slab 6
fill ~64 ~-2 ~57 ~64 ~-1 ~57 double_stone_slab 6
setblock ~64 ~-2 ~59 stone_slab 14
setblock ~3 ~-1 ~46 double_stone_slab 6
setblock ~3 ~-1 ~56 stone_slab 6
setblock ~3 ~-1 ~57 stone_slab 14
setblock ~3 ~-1 ~59 double_stone_slab 6
setblock ~4 ~-1 ~44 double_stone_slab 6
fill ~4 ~-1 ~46 ~63 ~-1 ~46 stone 0
fill ~4 ~-1 ~47 ~63 ~-1 ~47 stone 0
fill ~4 ~-1 ~48 ~63 ~-1 ~48 stone 0
fill ~4 ~-1 ~49 ~63 ~-1 ~49 stone 0
fill ~4 ~-1 ~50 ~63 ~-1 ~50 stone 0
fill ~4 ~-1 ~51 ~63 ~-1 ~51 stone 0
fill ~4 ~-1 ~52 ~63 ~-1 ~52 stone 0
fill ~4 ~-1 ~53 ~63 ~-1 ~53 stone 0
fill ~4 ~-1 ~54 ~63 ~-1 ~54 stone 0
fill ~4 ~-1 ~55 ~63 ~-1 ~55 stone 0
fill ~4 ~-1 ~56 ~63 ~-1 ~56 stone 0
fill ~4 ~-1 ~57 ~63 ~-1 ~57 stone 0
fill ~4 ~-1 ~58 ~63 ~-1 ~58 stone 0
fill ~4 ~-1 ~59 ~63 ~-1 ~59 stone 0
setblock ~4 ~-1 ~60 stone_slab 6
setblock ~4 ~-1 ~61 double_stone_slab 6
setblock ~5 ~-1 ~42 stone_slab 14
fill ~5 ~-1 ~43 ~62 ~-1 ~43 stone 0
fill ~5 ~-1 ~44 ~62 ~-1 ~44 stone 0
fill ~5 ~-1 ~45 ~62 ~-1 ~45 stone 0
fill ~5 ~-1 ~60 ~62 ~-1 ~60 stone 0
fill ~5 ~-1 ~61 ~62 ~-1 ~61 stone 0
fill ~5 ~-1 ~62 ~62 ~-1 ~62 stone 0
setblock ~5 ~-1 ~63 double_stone_slab 6
setblock ~5 ~-1 ~65 double_stone_slab 6
fill ~6 ~-1 ~40 ~61 ~-1 ~40 stone 0
fill ~6 ~-1 ~41 ~61 ~-1 ~41 stone 0
fill ~6 ~-1 ~42 ~61 ~-1 ~42 stone 0
fill ~6 ~-1 ~63 ~61 ~-1 ~63 stone 0
fill ~6 ~-1 ~64 ~61 ~-1 ~64 stone 0
fill ~6 ~-1 ~65 ~61 ~-1 ~65 stone 0
setblock ~6 ~-1 ~67 stone_slab 14
fill ~7 ~-1 ~38 ~60 ~-1 ~38 stone 0
fill ~7 ~-1 ~39 ~60 ~-1 ~39 stone 0
fill ~7 ~-1 ~66 ~60 ~-1 ~66 stone 0
fill ~7 ~-1 ~67 ~60 ~-1 ~67 stone 0
fill ~8 ~-1 ~37 ~59 ~-1 ~37 stone 0
fill ~8 ~-1 ~68 ~59 ~-1 ~68 stone 0
setblock ~9 ~-1 ~34 double_stone_slab 6
fill ~9 ~-1 ~35 ~58 ~-1 ~35 stone 0
fill ~9 ~-1 ~36 ~58 ~-1 ~36 stone 0
fill ~9 ~-1 ~69 ~58 ~-1 ~69 stone 0
fill ~9 ~-1 ~70 ~58 ~-1 ~70 stone 0
setblock ~9 ~-1 ~71 double_stone_slab 6
fill ~10 ~-1 ~34 ~57 ~-1 ~34 stone 0
fill ~10 ~-1 ~71 ~57 ~-1 ~71 stone 0
setblock ~11 ~-1 ~32 double_stone_slab 6
fill ~11 ~-1 ~33 ~56 ~-1 ~33 stone 0
fill ~11 ~-1 ~72 ~56 ~-1 ~72 stone 0
setblock ~11 ~-1 ~73 double_stone_slab 6
fill ~12 ~-1 ~32 ~55 ~-1 ~32 stone 0
fill ~12 ~-1 ~73 ~55 ~-1 ~73 stone 0
setblock ~13 ~-1 ~30 double_stone_slab 6
fill ~13 ~-1 ~31 ~54 ~-1 ~31 stone 0
fill ~13 ~-1 ~74 ~54 ~-1 ~74 stone 0
fill ~14 ~-1 ~30 ~53 ~-1 ~30 stone 0
fill ~14 ~-1 ~75 ~53 ~-1 ~75 stone 0
setblock ~14 ~-1 ~76 stone_slab 6
fill ~15 ~-1 ~29 ~52 ~-1 ~29 stone 0
fill ~15 ~-1 ~76 ~52 ~-1 ~76 stone 0
setblock ~15 ~-1 ~77 stone_slab 14
fill ~16 ~-1 ~28 ~51 ~-1 ~28 stone 0
fill ~16 ~-1 ~77 ~51 ~-1 ~77 stone 0
fill ~18 ~-1 ~27 ~49 ~-1 ~27 stone 0
fill ~18 ~-1 ~78 ~49 ~-1 ~78 stone 0
setblock ~19 ~-1 ~25 stone_slab 14
fill ~19 ~-1 ~26 ~48 ~-1 ~26 stone 0
fill ~19 ~-1 ~79 ~48 ~-1 ~79 stone 0
setblock ~20 ~-1 ~25 stone_slab 6
fill ~21 ~-1 ~25 ~46 ~-1 ~25 stone 0
fill ~21 ~-1 ~80 ~46 ~-1 ~80 stone 0
fill ~24 ~-1 ~24 ~43 ~-1 ~24 stone 0
fill ~24 ~-1 ~81 ~43 ~-1 ~81 stone 0
fill ~27 ~-1 ~23 ~40 ~-1 ~23 stone 0
fill ~27 ~-1 ~82 ~40 ~-1 ~82 stone 0
setblock ~47 ~-1 ~80 stone_slab 6
setblock ~48 ~-1 ~80 stone_slab 14
setblock ~52 ~-1 ~28 stone_slab 14
setblock ~53 ~-1 ~29 stone_slab 6
setblock ~54 ~-1 ~75 double_stone_slab 6
setblock ~56 ~-1 ~32 double_stone_slab 6
setblock ~56 ~-1 ~73 double_stone_slab 6
setblock ~58 ~-1 ~34 double_stone_slab 6
setblock ~58 ~-1 ~71 double_stone_slab 6
setblock ~61 ~-1 ~38 stone_slab 14
setblock ~62 ~-1 ~40 double_stone_slab 6
setblock ~62 ~-1 ~42 double_stone_slab 6
setblock ~62 ~-1 ~63 stone_slab 14
fill ~62 ~-1 ~64 ~62 ~0 ~64 stone_slab 6
setblock ~63 ~-1 ~44 double_stone_slab 6
setblock ~63 ~-1 ~45 stone_slab 6
setblock ~63 ~-1 ~61 double_stone_slab 6
setblock ~64 ~-1 ~46 double_stone_slab 6
setblock ~64 ~-1 ~48 stone_slab 14
setblock ~64 ~-1 ~49 stone_slab 6
setblock ~64 ~-1 ~59 double_stone_slab 6
setblock ~3 ~0 ~48 stone_slab 6
setblock ~3 ~0 ~55 stone_slab 6
setblock ~3 ~0 ~57 stone_slab 6
setblock ~3 ~0 ~59 stone_slab 6
setblock ~4 ~0 ~45 stone_slab 6
fill ~4 ~0 ~46 ~5 ~0 ~46 stone 0
fill ~4 ~0 ~47 ~5 ~0 ~47 stone 0
fill ~4 ~0 ~48 ~5 ~0 ~48 stone 0
fill ~4 ~0 ~49 ~5 ~0 ~49 stone 0
fill ~4 ~0 ~50 ~5 ~0 ~50 stone 0
fill ~4 ~0 ~51 ~4 ~-3 ~51 stone 0
fill ~4 ~0 ~52 ~4 ~-3 ~52 stone 0
fill ~4 ~0 ~53 ~4 ~-3 ~53 stone 0
fill ~4 ~0 ~54 ~4 ~-3 ~54 stone 0
fill ~4 ~0 ~55 ~5 ~0 ~55 stone 0
fill ~4 ~0 ~56 ~5 ~0 ~56 stone 0
fill ~4 ~0 ~57 ~5 ~0 ~57 stone 0
fill ~4 ~0 ~58 ~5 ~0 ~58 stone 0
fill ~4 ~0 ~59 ~5 ~0 ~59 stone 0
setblock ~4 ~0 ~61 stone_slab 6
setblock ~5 ~0 ~40 stone_slab 6
setblock ~5 ~0 ~42 stone_slab 6
fill ~5 ~0 ~43 ~6 ~0 ~43 stone 0
fill ~5 ~0 ~44 ~6 ~0 ~44 stone 0
fill ~5 ~0 ~45 ~5 ~-3 ~45 stone 0
fill ~5 ~0 ~51 ~62 ~0 ~51 dirt 0
fill ~5 ~0 ~52 ~62 ~0 ~52 dirt 0
fill ~5 ~0 ~53 ~62 ~0 ~53 dirt 0
fill ~5 ~0 ~54 ~62 ~0 ~54 dirt 0
fill ~5 ~0 ~60 ~5 ~-3 ~60 stone 0
fill ~5 ~0 ~61 ~6 ~0 ~61 stone 0
fill ~5 ~0 ~62 ~6 ~0 ~62 stone 0
setblock ~5 ~0 ~64 stone_slab 6
fill ~6 ~0 ~40 ~7 ~0 ~40 stone 0
fill ~6 ~0 ~41 ~7 ~0 ~41 stone 0
fill ~6 ~0 ~42 ~6 ~-3 ~42 stone 0
fill ~6 ~0 ~45 ~61 ~0 ~45 dirt 0
fill ~6 ~0 ~46 ~61 ~0 ~46 dirt 0
fill ~6 ~0 ~47 ~61 ~0 ~47 dirt 0
fill ~6 ~0 ~48 ~61 ~0 ~48 dirt 0
fill ~6 ~0 ~49 ~61 ~0 ~49 dirt 0
fill ~6 ~0 ~50 ~61 ~0 ~50 dirt 0
fill ~6 ~0 ~55 ~61 ~0 ~55 dirt 0
fill ~6 ~0 ~56 ~61 ~0 ~56 dirt 0
fill ~6 ~0 ~57 ~61 ~0 ~57 dirt 0
fill ~6 ~0 ~58 ~61 ~0 ~58 dirt 0
fill ~6 ~0 ~59 ~61 ~0 ~59 dirt 0
fill ~6 ~0 ~60 ~61 ~0 ~60 dirt 0
fill ~6 ~0 ~63 ~6 ~-3 ~63 stone 0
fill ~6 ~0 ~64 ~7 ~0 ~64 stone 0
fill ~6 ~0 ~65 ~7 ~0 ~65 stone 0
setblock ~7 ~0 ~37 stone_slab 6
fill ~7 ~0 ~38 ~8 ~0 ~38 stone 0
fill ~7 ~0 ~39 ~8 ~0 ~39 stone 0
fill ~7 ~0 ~42 ~60 ~0 ~42 dirt 0
fill ~7 ~0 ~43 ~60 ~0 ~43 dirt 0
fill ~7 ~0 ~44 ~60 ~0 ~44 dirt 0
fill ~7 ~0 ~61 ~60 ~0 ~61 dirt 0
fill ~7 ~0 ~62 ~60 ~0 ~62 dirt 0
fill ~7 ~0 ~63 ~60 ~0 ~63 dirt 0
fill ~7 ~0 ~66 ~8 ~0 ~66 stone 0
fill ~7 ~0 ~67 ~8 ~0 ~67 stone 0
fill ~8 ~0 ~37 ~9 ~0 ~37 stone 0
fill ~8 ~0 ~40 ~59 ~0 ~40 dirt 0
fill ~8 ~0 ~41 ~59 ~0 ~41 dirt 0
fill ~8 ~0 ~64 ~59 ~0 ~64 dirt 0
fill ~8 ~0 ~65 ~59 ~0 ~65 dirt 0
fill ~8 ~0 ~68 ~9 ~0 ~68 stone 0
setblock ~8 ~0 ~69 stone_slab 6
setblock ~9 ~0 ~34 stone_slab 6
fill ~9 ~0 ~35 ~10 ~0 ~35 stone 0
fill ~9 ~0 ~36 ~10 ~0 ~36 stone 0
fill ~9 ~0 ~38 ~58 ~0 ~38 dirt 0
fill ~9 ~0 ~39 ~58 ~0 ~39 dirt 0
fill ~9 ~0 ~66 ~58 ~0 ~66 dirt 0
fill ~9 ~0 ~67 ~58 ~0 ~67 dirt 0
fill ~9 ~0 ~69 ~10 ~0 ~69 stone 0
fill ~9 ~0 ~70 ~10 ~0 ~70 stone 0
setblock ~9 ~0 ~71 stone_slab 6
fill ~10 ~0 ~34 ~11 ~0 ~34 stone 0
fill ~10 ~0 ~37 ~57 ~0 ~37 dirt 0
fill ~10 ~0 ~68 ~57 ~0 ~68 dirt 0
fill ~10 ~0 ~71 ~11 ~0 ~71 stone 0
fill ~11 ~0 ~33 ~12 ~0 ~33 stone 0
fill ~11 ~0 ~35 ~56 ~0 ~35 dirt 0
fill ~11 ~0 ~36 ~56 ~0 ~36 dirt 0
fill ~11 ~0 ~69 ~56 ~0 ~69 dirt 0
fill ~11 ~0 ~70 ~56 ~0 ~70 dirt 0
fill ~11 ~0 ~72 ~12 ~0 ~72 stone 0
setblock ~11 ~0 ~73 stone_slab 6
fill ~12 ~0 ~32 ~13 ~0 ~32 stone 0
fill ~12 ~0 ~34 ~55 ~0 ~34 dirt 0
fill ~12 ~0 ~71 ~55 ~0 ~71 dirt 0
fill ~12 ~0 ~73 ~13 ~0 ~73 stone 0
setblock ~13 ~0 ~30 stone_slab 6
fill ~13 ~0 ~31 ~14 ~0 ~31 stone 0
fill ~13 ~0 ~33 ~54 ~0 ~33 dirt 0
fill ~13 ~0 ~72 ~54 ~0 ~72 dirt 0
fill ~13 ~0 ~74 ~14 ~0 ~74 stone 0
setblock ~13 ~0 ~75 stone_slab 6
fill ~14 ~0 ~30 ~15 ~0 ~30 stone 0
fill ~14 ~0 ~32 ~53 ~0 ~32 dirt 0
fill ~14 ~0 ~73 ~53 ~0 ~73 dirt 0
fill ~14 ~0 ~75 ~15 ~0 ~75 stone 0
fill ~15 ~0 ~29 ~17 ~0 ~29 stone 0
fill ~15 ~0 ~31 ~52 ~0 ~31 dirt 0
fill ~15 ~0 ~74 ~52 ~0 ~74 dirt 0
fill ~15 ~0 ~76 ~17 ~0 ~76 stone 0
setblock ~15 ~0 ~77 stone_slab 6
setblock ~16 ~0 ~27 stone_slab 6
fill ~16 ~0 ~28 ~18 ~0 ~28 stone 0
fill ~16 ~0 ~30 ~51 ~0 ~30 dirt 0
fill ~16 ~0 ~75 ~51 ~0 ~75 dirt 0
fill ~16 ~0 ~77 ~18 ~0 ~77 stone 0
setblock ~17 ~0 ~78 stone_slab 6
fill ~18 ~0 ~27 ~20 ~0 ~27 stone 0
fill ~18 ~0 ~29 ~49 ~0 ~29 dirt 0
fill ~18 ~0 ~76 ~49 ~0 ~76 dirt 0
fill ~18 ~0 ~78 ~20 ~0 ~78 stone 0
setblock ~19 ~0 ~25 stone_slab 6
fill ~19 ~0 ~26 ~22 ~0 ~26 stone 0
fill ~19 ~0 ~28 ~48 ~0 ~28 dirt 0
fill ~19 ~0 ~77 ~48 ~0 ~77 dirt 0
fill ~19 ~0 ~79 ~22 ~0 ~79 stone 0
setblock ~21 ~0 ~24 stone_slab 6
fill ~21 ~0 ~25 ~25 ~0 ~25 stone 0
fill ~21 ~0 ~27 ~46 ~0 ~27 dirt 0
fill ~21 ~0 ~78 ~46 ~0 ~78 dirt 0
fill ~21 ~0 ~80 ~25 ~0 ~80 stone 0
fill ~23 ~0 ~26 ~44 ~0 ~26 dirt 0
fill ~23 ~0 ~79 ~44 ~0 ~79 dirt 0
fill ~24 ~0 ~24 ~31 ~0 ~24 stone 0
fill ~24 ~0 ~81 ~31 ~0 ~81 stone 0
fill ~26 ~0 ~25 ~41 ~0 ~25 dirt 0
fill ~26 ~0 ~80 ~41 ~0 ~80 dirt 0
fill ~27 ~0 ~23 ~40 ~0 ~23 stone 0
fill ~27 ~0 ~82 ~40 ~0 ~82 stone 0
fill ~32 ~0 ~24 ~35 ~0 ~24 dirt 0
fill ~32 ~0 ~81 ~35 ~0 ~81 dirt 0
fill ~36 ~0 ~24 ~43 ~0 ~24 stone 0
fill ~36 ~0 ~81 ~43 ~0 ~81 stone 0
fill ~42 ~0 ~25 ~46 ~0 ~25 stone 0
fill ~42 ~0 ~80 ~46 ~0 ~80 stone 0
fill ~45 ~0 ~26 ~48 ~0 ~26 stone 0
fill ~45 ~0 ~79 ~48 ~0 ~79 stone 0
setblock ~46 ~0 ~81 stone_slab 6
fill ~47 ~0 ~27 ~49 ~0 ~27 stone 0
fill ~47 ~0 ~78 ~49 ~0 ~78 stone 0
setblock ~48 ~0 ~80 stone_slab 6
fill ~49 ~0 ~28 ~51 ~0 ~28 stone 0
fill ~49 ~0 ~77 ~51 ~0 ~77 stone 0
setblock ~50 ~0 ~27 stone_slab 6
fill ~50 ~0 ~29 ~52 ~0 ~29 stone 0
fill ~50 ~0 ~76 ~52 ~0 ~76 stone 0
setblock ~51 ~0 ~78 stone_slab 6
setblock ~52 ~0 ~28 stone_slab 6
fill ~52 ~0 ~30 ~53 ~0 ~30 stone 0
fill ~52 ~0 ~75 ~53 ~0 ~75 stone 0
fill ~53 ~0 ~31 ~54 ~0 ~31 stone 0
fill ~53 ~0 ~74 ~54 ~0 ~74 stone 0
setblock ~54 ~0 ~30 stone_slab 6
fill ~54 ~0 ~32 ~55 ~0 ~32 stone 0
fill ~54 ~0 ~73 ~55 ~0 ~73 stone 0
setblock ~54 ~0 ~75 stone_slab 6
fill ~55 ~0 ~33 ~56 ~0 ~33 stone 0
fill ~55 ~0 ~72 ~56 ~0 ~72 stone 0
setblock ~56 ~0 ~32 stone_slab 6
fill ~56 ~0 ~34 ~57 ~0 ~34 stone 0
fill ~56 ~0 ~71 ~57 ~0 ~71 stone 0
fill ~57 ~0 ~35 ~58 ~0 ~35 stone 0
fill ~57 ~0 ~36 ~58 ~0 ~36 stone 0
fill ~57 ~0 ~69 ~58 ~0 ~69 stone 0
fill ~57 ~0 ~70 ~58 ~0 ~70 stone 0
setblock ~58 ~0 ~34 stone_slab 6
fill ~58 ~0 ~37 ~59 ~0 ~37 stone 0
fill ~58 ~0 ~68 ~59 ~0 ~68 stone 0
setblock ~58 ~0 ~71 stone_slab 6
setblock ~59 ~0 ~36 stone_slab 6
fill ~59 ~0 ~38 ~60 ~0 ~38 stone 0
fill ~59 ~0 ~39 ~60 ~0 ~39 stone 0
fill ~59 ~0 ~66 ~60 ~0 ~66 stone 0
fill ~59 ~0 ~67 ~60 ~0 ~67 stone 0
fill ~60 ~0 ~40 ~61 ~0 ~40 stone 0
fill ~60 ~0 ~41 ~60 ~0 ~38 stone 0
fill ~60 ~0 ~64 ~60 ~0 ~67 stone 0
setblock ~60 ~0 ~68 stone_slab 6
fill ~61 ~0 ~43 ~61 ~0 ~44 stone 0
fill ~61 ~0 ~61 ~61 ~0 ~65 stone 0
setblock ~62 ~0 ~41 stone_slab 6
fill ~62 ~0 ~46 ~62 ~0 ~50 stone 0
fill ~62 ~0 ~55 ~62 ~0 ~62 stone 0
setblock ~62 ~0 ~63 stone_slab 6
setblock ~62 ~0 ~65 stone_slab 6
setblock ~63 ~0 ~44 stone_slab 6
setblock ~63 ~0 ~60 stone_slab 6
setblock ~64 ~0 ~46 stone_slab 6
setblock ~64 ~0 ~48 stone_slab 6
setblock ~64 ~0 ~50 stone_slab 6
setblock ~64 ~0 ~57 stone_slab 6
fill ~4 ~1 ~46 ~5 ~1 ~46 stone_slab 0
fill ~4 ~1 ~47 ~5 ~1 ~47 stone_slab 0
fill ~4 ~1 ~48 ~5 ~1 ~48 stone_slab 0
fill ~4 ~1 ~49 ~5 ~1 ~49 stone_slab 0
fill ~4 ~1 ~50 ~5 ~1 ~50 stone_slab 0
fill ~4 ~1 ~51 ~4 ~1 ~59 stone_slab 0
fill ~5 ~1 ~43 ~6 ~1 ~43 stone_slab 0
fill ~5 ~1 ~44 ~6 ~1 ~44 stone_slab 0
fill ~5 ~1 ~45 ~5 ~1 ~43 stone_slab 0
fill ~5 ~1 ~51 ~62 ~1 ~51 grass 0
fill ~5 ~1 ~52 ~62 ~1 ~52 grass 0
fill ~5 ~1 ~53 ~62 ~1 ~53 grass 0
fill ~5 ~1 ~54 ~62 ~1 ~54 grass 0
fill ~5 ~1 ~55 ~5 ~1 ~62 stone_slab 0
fill ~6 ~1 ~40 ~7 ~1 ~40 stone_slab 0
fill ~6 ~1 ~41 ~7 ~1 ~41 stone_slab 0
fill ~6 ~1 ~42 ~6 ~1 ~40 stone_slab 0
fill ~6 ~1 ~45 ~61 ~1 ~45 grass 0
fill ~6 ~1 ~46 ~61 ~1 ~46 grass 0
fill ~6 ~1 ~47 ~61 ~1 ~47 grass 0
fill ~6 ~1 ~48 ~61 ~1 ~48 grass 0
fill ~6 ~1 ~49 ~61 ~1 ~49 grass 0
fill ~6 ~1 ~50 ~61 ~1 ~50 grass 0
fill ~6 ~1 ~55 ~61 ~1 ~55 grass 0
fill ~6 ~1 ~56 ~61 ~1 ~56 grass 0
fill ~6 ~1 ~57 ~61 ~1 ~57 grass 0
fill ~6 ~1 ~58 ~22 ~1 ~58 grass 0
fill ~6 ~1 ~59 ~19 ~1 ~59 grass 0
fill ~6 ~1 ~60 ~18 ~1 ~60 grass 0
fill ~6 ~1 ~61 ~6 ~1 ~65 stone_slab 0
fill ~7 ~1 ~38 ~8 ~1 ~38 stone_slab 0
fill ~7 ~1 ~39 ~8 ~1 ~39 stone_slab 0
fill ~7 ~1 ~42 ~60 ~1 ~42 grass 0
fill ~7 ~1 ~43 ~60 ~1 ~43 grass 0
fill ~7 ~1 ~44 ~60 ~1 ~44 grass 0
fill ~7 ~1 ~61 ~18 ~1 ~61 grass 0
fill ~7 ~1 ~62 ~18 ~1 ~62 grass 0
fill ~7 ~1 ~63 ~19 ~1 ~63 grass 0
fill ~7 ~1 ~64 ~7 ~1 ~67 stone_slab 0
fill ~8 ~1 ~37 ~9 ~1 ~37 stone_slab 0
fill ~8 ~1 ~40 ~59 ~1 ~40 grass 0
fill ~8 ~1 ~41 ~59 ~1 ~41 grass 0
fill ~8 ~1 ~64 ~20 ~1 ~64 grass 0
fill ~8 ~1 ~65 ~23 ~1 ~65 grass 0
fill ~8 ~1 ~66 ~8 ~1 ~68 stone_slab 0
fill ~9 ~1 ~35 ~10 ~1 ~35 stone_slab 0
fill ~9 ~1 ~36 ~10 ~1 ~36 stone_slab 0
fill ~9 ~1 ~38 ~58 ~1 ~38 grass 0
fill ~9 ~1 ~39 ~58 ~1 ~39 grass 0
fill ~9 ~1 ~66 ~58 ~1 ~66 grass 0
fill ~9 ~1 ~67 ~58 ~1 ~67 grass 0
fill ~9 ~1 ~68 ~9 ~1 ~70 stone_slab 0
fill ~10 ~1 ~34 ~11 ~1 ~34 stone_slab 0
fill ~10 ~1 ~37 ~57 ~1 ~37 grass 0
fill ~10 ~1 ~68 ~57 ~1 ~68 grass 0
fill ~10 ~1 ~69 ~10 ~1 ~71 stone_slab 0
fill ~11 ~1 ~33 ~12 ~1 ~33 stone_slab 0
fill ~11 ~1 ~35 ~56 ~1 ~35 grass 0
fill ~11 ~1 ~36 ~56 ~1 ~36 grass 0
fill ~11 ~1 ~69 ~56 ~1 ~69 grass 0
fill ~11 ~1 ~70 ~56 ~1 ~70 grass 0
fill ~11 ~1 ~71 ~11 ~1 ~72 stone_slab 0
fill ~12 ~1 ~32 ~13 ~1 ~32 stone_slab 0
fill ~12 ~1 ~34 ~55 ~1 ~34 grass 0
fill ~12 ~1 ~71 ~55 ~1 ~71 grass 0
fill ~12 ~1 ~72 ~12 ~1 ~73 stone_slab 0
fill ~13 ~1 ~31 ~14 ~1 ~31 stone_slab 0
fill ~13 ~1 ~33 ~54 ~1 ~33 grass 0
fill ~13 ~1 ~72 ~54 ~1 ~72 grass 0
fill ~13 ~1 ~73 ~13 ~1 ~74 stone_slab 0
fill ~14 ~1 ~30 ~15 ~1 ~30 stone_slab 0
fill ~14 ~1 ~32 ~53 ~1 ~32 grass 0
fill ~14 ~1 ~73 ~53 ~1 ~73 grass 0
fill ~14 ~1 ~74 ~14 ~1 ~75 stone_slab 0
fill ~15 ~1 ~29 ~17 ~1 ~29 stone_slab 0
fill ~15 ~1 ~31 ~52 ~1 ~31 grass 0
fill ~15 ~1 ~74 ~52 ~1 ~74 grass 0
fill ~15 ~1 ~75 ~15 ~1 ~76 stone_slab 0
fill ~16 ~1 ~28 ~18 ~1 ~28 stone_slab 0
fill ~16 ~1 ~30 ~51 ~1 ~30 grass 0
fill ~16 ~1 ~75 ~51 ~1 ~75 grass 0
fill ~16 ~1 ~76 ~17 ~1 ~76 stone_slab 0
fill ~16 ~1 ~77 ~18 ~1 ~77 stone_slab 0
fill ~18 ~1 ~27 ~20 ~1 ~27 stone_slab 0
fill ~18 ~1 ~29 ~49 ~1 ~29 grass 0
fill ~18 ~1 ~76 ~49 ~1 ~76 grass 0
fill ~18 ~1 ~78 ~20 ~1 ~78 stone_slab 0
fill ~19 ~1 ~26 ~22 ~1 ~26 stone_slab 0
fill ~19 ~1 ~28 ~48 ~1 ~28 grass 0
fill ~19 ~1 ~60 ~20 ~1 ~60 dirt 0
fill ~19 ~1 ~61 ~20 ~1 ~61 dirt 0
fill ~19 ~1 ~62 ~20 ~1 ~62 dirt 0
fill ~19 ~1 ~77 ~48 ~1 ~77 grass 0
fill ~19 ~1 ~79 ~22 ~1 ~79 stone_slab 0
fill ~20 ~1 ~59 ~24 ~1 ~59 dirt 0
fill ~20 ~1 ~63 ~21 ~1 ~63 dirt 0
fill ~21 ~1 ~25 ~25 ~1 ~25 stone_slab 0
fill ~21 ~1 ~27 ~46 ~1 ~27 grass 0
fill ~21 ~1 ~60 ~37 ~1 ~60 grass 0
fill ~21 ~1 ~61 ~37 ~1 ~61 grass 0
fill ~21 ~1 ~62 ~37 ~1 ~62 grass 0
fill ~21 ~1 ~64 ~25 ~1 ~64 dirt 0
fill ~21 ~1 ~78 ~46 ~1 ~78 grass 0
fill ~21 ~1 ~80 ~25 ~1 ~80 stone_slab 0
fill ~22 ~1 ~63 ~36 ~1 ~63 grass 0
fill ~23 ~1 ~26 ~44 ~1 ~26 grass 0
fill ~23 ~1 ~58 ~31 ~1 ~58 dirt 0
fill ~23 ~1 ~79 ~44 ~1 ~79 grass 0
fill ~24 ~1 ~24 ~31 ~1 ~24 stone_slab 0
fill ~24 ~1 ~65 ~30 ~1 ~65 dirt 0
fill ~24 ~1 ~81 ~31 ~1 ~81 stone_slab 0
fill ~25 ~1 ~59 ~28 ~1 ~59 grass 0
fill ~26 ~1 ~25 ~41 ~1 ~25 grass 0
fill ~26 ~1 ~64 ~27 ~1 ~64 grass 0
fill ~26 ~1 ~80 ~41 ~1 ~80 grass 0
fill ~27 ~1 ~23 ~40 ~1 ~23 stone_slab 0
fill ~27 ~1 ~82 ~40 ~1 ~82 stone_slab 0
fill ~28 ~1 ~64 ~39 ~1 ~64 dirt 0
fill ~29 ~1 ~59 ~34 ~1 ~59 dirt 0
fill ~31 ~1 ~65 ~59 ~1 ~65 grass 0
fill ~32 ~1 ~24 ~35 ~1 ~24 grass 0
fill ~32 ~1 ~58 ~33 ~1 ~58 grass 0
fill ~32 ~1 ~81 ~35 ~1 ~81 grass 0
fill ~34 ~1 ~58 ~38 ~1 ~58 dirt 0
fill ~35 ~1 ~59 ~36 ~1 ~59 grass 0
fill ~36 ~1 ~24 ~43 ~1 ~24 stone_slab 0
fill ~36 ~1 ~81 ~43 ~1 ~81 stone_slab 0
fill ~37 ~1 ~59 ~39 ~1 ~59 dirt 0
fill ~37 ~1 ~63 ~40 ~1 ~63 dirt 0
fill ~38 ~1 ~60 ~40 ~1 ~60 dirt 0
fill ~38 ~1 ~61 ~40 ~1 ~61 dirt 0
fill ~38 ~1 ~62 ~40 ~1 ~62 dirt 0
fill ~39 ~1 ~58 ~61 ~1 ~58 grass 0
fill ~40 ~1 ~59 ~61 ~1 ~59 grass 0
fill ~40 ~1 ~64 ~59 ~1 ~64 grass 0
fill ~41 ~1 ~60 ~61 ~1 ~60 grass 0
fill ~41 ~1 ~61 ~60 ~1 ~61 grass 0
fill ~41 ~1 ~62 ~60 ~1 ~62 grass 0
fill ~41 ~1 ~63 ~60 ~1 ~63 grass 0
fill ~42 ~1 ~25 ~46 ~1 ~25 stone_slab 0
fill ~42 ~1 ~80 ~46 ~1 ~80 stone_slab 0
fill ~45 ~1 ~26 ~48 ~1 ~26 stone_slab 0
fill ~45 ~1 ~79 ~48 ~1 ~79 stone_slab 0
fill ~47 ~1 ~27 ~49 ~1 ~27 stone_slab 0
fill ~47 ~1 ~78 ~49 ~1 ~78 stone_slab 0
fill ~49 ~1 ~28 ~51 ~1 ~28 stone_slab 0
fill ~49 ~1 ~77 ~51 ~1 ~77 stone_slab 0
fill ~50 ~1 ~29 ~52 ~1 ~29 stone_slab 0
fill ~50 ~1 ~76 ~52 ~1 ~76 stone_slab 0
fill ~52 ~1 ~30 ~53 ~1 ~30 stone_slab 0
fill ~52 ~1 ~75 ~53 ~1 ~75 stone_slab 0
fill ~53 ~1 ~31 ~54 ~1 ~31 stone_slab 0
fill ~53 ~1 ~74 ~54 ~1 ~74 stone_slab 0
fill ~54 ~1 ~32 ~55 ~1 ~32 stone_slab 0
fill ~54 ~1 ~73 ~55 ~1 ~73 stone_slab 0
fill ~55 ~1 ~33 ~56 ~1 ~33 stone_slab 0
fill ~55 ~1 ~72 ~56 ~1 ~72 stone_slab 0
fill ~56 ~1 ~34 ~57 ~1 ~34 stone_slab 0
fill ~56 ~1 ~71 ~57 ~1 ~71 stone_slab 0
fill ~57 ~1 ~35 ~58 ~1 ~35 stone_slab 0
fill ~57 ~1 ~36 ~58 ~1 ~36 stone_slab 0
fill ~57 ~1 ~69 ~58 ~1 ~69 stone_slab 0
fill ~57 ~1 ~70 ~58 ~1 ~70 stone_slab 0
fill ~58 ~1 ~37 ~59 ~1 ~37 stone_slab 0
fill ~58 ~1 ~68 ~59 ~1 ~68 stone_slab 0
fill ~59 ~1 ~38 ~60 ~1 ~38 stone_slab 0
fill ~59 ~1 ~39 ~60 ~1 ~39 stone_slab 0
fill ~59 ~1 ~66 ~60 ~1 ~66 stone_slab 0
fill ~59 ~1 ~67 ~60 ~1 ~67 stone_slab 0
fill ~60 ~1 ~40 ~61 ~1 ~40 stone_slab 0
fill ~60 ~1 ~41 ~61 ~1 ~41 stone_slab 0
fill ~60 ~1 ~64 ~61 ~1 ~64 stone_slab 0
fill ~60 ~1 ~65 ~61 ~1 ~65 stone_slab 0
fill ~61 ~1 ~42 ~61 ~1 ~44 stone_slab 0
fill ~61 ~1 ~61 ~62 ~1 ~61 stone_slab 0
fill ~61 ~1 ~62 ~62 ~1 ~62 stone_slab 0
fill ~61 ~1 ~63 ~61 ~1 ~61 stone_slab 0
fill ~62 ~1 ~43 ~62 ~1 ~50 stone_slab 0
fill ~62 ~1 ~55 ~63 ~1 ~55 stone_slab 0
fill ~62 ~1 ~56 ~63 ~1 ~56 stone_slab 0
fill ~62 ~1 ~57 ~63 ~1 ~57 stone_slab 0
fill ~62 ~1 ~58 ~63 ~1 ~58 stone_slab 0
fill ~62 ~1 ~59 ~63 ~1 ~59 stone_slab 0
fill ~62 ~1 ~60 ~62 ~1 ~55 stone_slab 0
fill ~63 ~1 ~46 ~63 ~1 ~59 stone_slab 0
fill ~19 ~2 ~60 ~20 ~2 ~60 wool 9
fill ~19 ~2 ~61 ~20 ~2 ~61 wool 9
fill ~19 ~2 ~62 ~20 ~2 ~62 wool 9
fill ~20 ~2 ~59 ~24 ~2 ~59 wool 9
fill ~20 ~2 ~63 ~21 ~2 ~63 wool 9
fill ~21 ~2 ~64 ~25 ~2 ~64 wool 9
fill ~23 ~2 ~58 ~31 ~2 ~58 wool 9
fill ~24 ~2 ~65 ~30 ~2 ~65 wool 9
fill ~28 ~2 ~64 ~39 ~2 ~64 wool 9
fill ~29 ~2 ~59 ~34 ~2 ~59 wool 9
fill ~34 ~2 ~58 ~38 ~2 ~58 wool 9
fill ~37 ~2 ~59 ~39 ~2 ~59 wool 9
fill ~37 ~2 ~63 ~40 ~2 ~63 wool 9
fill ~38 ~2 ~60 ~40 ~2 ~60 wool 9
fill ~38 ~2 ~61 ~40 ~2 ~61 wool 9
fill ~38 ~2 ~62 ~40 ~2 ~62 wool 9
fill ~19 ~3 ~60 ~20 ~3 ~60 wool 9
fill ~19 ~3 ~61 ~19 ~4 ~61 wool 9
fill ~19 ~3 ~62 ~20 ~3 ~62 wool 9
fill ~20 ~3 ~59 ~22 ~3 ~59 wool 9
fill ~20 ~3 ~63 ~21 ~3 ~63 wool 9
fill ~21 ~3 ~64 ~23 ~3 ~64 wool 9
fill ~23 ~3 ~58 ~38 ~3 ~58 wool 9
fill ~24 ~3 ~60 ~30 ~3 ~60 coal_block 0
fill ~24 ~3 ~61 ~31 ~3 ~61 coal_block 0
fill ~24 ~3 ~62 ~38 ~3 ~62 coal_block 0
fill ~24 ~3 ~63 ~37 ~3 ~63 coal_block 0
fill ~24 ~3 ~65 ~31 ~3 ~65 wool 9
fill ~25 ~3 ~59 ~29 ~3 ~59 coal_block 0
fill ~25 ~3 ~64 ~31 ~3 ~64 coal_block 0
fill ~31 ~3 ~59 ~34 ~3 ~59 wool 9
fill ~32 ~3 ~64 ~39 ~3 ~64 wool 9
fill ~35 ~3 ~61 ~38 ~3 ~61 coal_block 0
setblock ~37 ~3 ~60 coal_block 0
fill ~38 ~3 ~59 ~39 ~3 ~59 wool 9
fill ~38 ~3 ~60 ~40 ~3 ~60 wool 9
fill ~38 ~3 ~63 ~40 ~3 ~63 wool 9
fill ~39 ~3 ~61 ~40 ~3 ~61 wool 9
fill ~39 ~3 ~62 ~40 ~3 ~62 wool 9
fill ~19 ~4 ~60 ~20 ~4 ~60 wool 9
fill ~19 ~4 ~62 ~20 ~4 ~62 wool 9
fill ~20 ~4 ~59 ~22 ~4 ~59 wool 9
fill ~20 ~4 ~63 ~21 ~4 ~63 wool 9
fill ~21 ~4 ~60 ~23 ~4 ~60 coal_block 0
fill ~21 ~4 ~61 ~23 ~4 ~61 coal_block 0
fill ~21 ~4 ~62 ~23 ~4 ~62 coal_block 0
fill ~21 ~4 ~64 ~23 ~4 ~64 wool 9
fill ~22 ~4 ~63 ~23 ~4 ~63 coal_block 0
fill ~23 ~4 ~58 ~38 ~4 ~58 wool 9
fill ~23 ~4 ~59 ~24 ~4 ~59 coal_block 0
setblock ~24 ~4 ~64 coal_block 0
fill ~24 ~4 ~65 ~32 ~4 ~65 wool 9
fill ~30 ~4 ~59 ~31 ~4 ~59 coal_block 0
fill ~31 ~4 ~60 ~36 ~4 ~60 coal_block 0
setblock ~31 ~4 ~64 wool 9
fill ~32 ~4 ~61 ~34 ~4 ~61 coal_block 0
fill ~32 ~4 ~64 ~32 ~6 ~64 coal_block 0
fill ~33 ~4 ~59 ~34 ~4 ~59 wool 9
fill ~33 ~4 ~64 ~39 ~4 ~64 wool 9
fill ~36 ~4 ~59 ~37 ~4 ~59 coal_block 0
fill ~38 ~4 ~59 ~39 ~4 ~59 wool 9
setblock ~38 ~4 ~63 coal_block 0
fill ~39 ~4 ~60 ~39 ~8 ~60 coal_block 0
fill ~39 ~4 ~61 ~39 ~5 ~61 coal_block 0
fill ~39 ~4 ~62 ~39 ~5 ~62 coal_block 0
fill ~39 ~4 ~63 ~40 ~4 ~63 wool 9
fill ~40 ~4 ~60 ~40 ~9 ~60 wool 9
fill ~40 ~4 ~61 ~40 ~9 ~61 wool 9
fill ~40 ~4 ~62 ~40 ~9 ~62 wool 9
fill ~20 ~5 ~60 ~20 ~5 ~62 wool 9
fill ~21 ~5 ~59 ~23 ~5 ~59 wool 9
fill ~21 ~5 ~62 ~21 ~4 ~62 coal_block 0
setblock ~21 ~5 ~63 wool 9
fill ~22 ~5 ~63 ~23 ~5 ~63 coal_block 0
fill ~22 ~5 ~64 ~25 ~5 ~64 wool 9
fill ~24 ~5 ~58 ~38 ~5 ~58 wool 9
setblock ~24 ~5 ~59 coal_block 0
setblock ~26 ~5 ~64 coal_block 0
fill ~26 ~5 ~65 ~32 ~5 ~65 wool 9
fill ~32 ~5 ~59 ~38 ~5 ~59 coal_block 0
fill ~33 ~5 ~64 ~39 ~5 ~64 wool 9
fill ~39 ~5 ~59 ~39 ~9 ~59 wool 9
fill ~39 ~5 ~63 ~39 ~7 ~63 coal_block 0
fill ~40 ~5 ~63 ~40 ~9 ~63 wool 9
fill ~21 ~6 ~60 ~26 ~6 ~60 wool 9
fill ~21 ~6 ~61 ~25 ~6 ~61 wool 9
fill ~21 ~6 ~62 ~25 ~6 ~62 wool 9
fill ~22 ~6 ~59 ~28 ~6 ~59 wool 9
fill ~22 ~6 ~63 ~27 ~6 ~63 wool 9
fill ~25 ~6 ~64 ~29 ~6 ~64 wool 9
fill ~26 ~6 ~61 ~26 ~6 ~62 coal_block 0
setblock ~27 ~6 ~60 coal_block 0
fill ~28 ~6 ~58 ~38 ~6 ~58 wool 9
fill ~29 ~6 ~59 ~38 ~6 ~59 coal_block 0
fill ~30 ~6 ~64 ~32 ~6 ~64 coal_block 0
fill ~30 ~6 ~65 ~32 ~6 ~65 wool 9
fill ~33 ~6 ~64 ~39 ~6 ~64 wool 9
fill ~26 ~7 ~61 ~28 ~7 ~61 wool 9
fill ~26 ~7 ~62 ~28 ~7 ~62 wool 9
fill ~27 ~7 ~60 ~29 ~7 ~60 wool 9
fill ~28 ~7 ~63 ~29 ~7 ~63 wool 9
fill ~29 ~7 ~59 ~31 ~7 ~59 wool 9
fill ~29 ~7 ~61 ~29 ~7 ~62 coal_block 0
setblock ~30 ~7 ~60 coal_block 0
setblock ~30 ~7 ~63 coal_block 0
fill ~30 ~7 ~64 ~39 ~7 ~64 wool 9
fill ~32 ~7 ~58 ~38 ~7 ~58 wool 9
fill ~32 ~7 ~59 ~38 ~7 ~59 coal_block 0
setblock ~32 ~7 ~63 wool 9
fill ~30 ~8 ~61 ~31 ~8 ~61 coal_block 0
fill ~30 ~8 ~62 ~31 ~8 ~62 coal_block 0
fill ~31 ~8 ~60 ~32 ~8 ~60 coal_block 0
fill ~31 ~8 ~63 ~36 ~8 ~63 coal_block 0
fill ~32 ~8 ~59 ~34 ~8 ~59 coal_block 0
fill ~35 ~8 ~58 ~38 ~8 ~58 wool 9
fill ~35 ~8 ~59 ~36 ~8 ~59 wool 9
setblock ~37 ~8 ~59 coal_block 0
fill ~37 ~8 ~64 ~39 ~8 ~64 wool 9
setblock ~38 ~8 ~59 wool 9
fill ~38 ~8 ~61 ~38 ~8 ~62 wool 9
fill ~39 ~8 ~61 ~39 ~8 ~62 coal_block 0
fill ~39 ~8 ~63 ~39 ~9 ~63 wool 9
fill ~31 ~9 ~61 ~32 ~9 ~61 coal_block 0
fill ~32 ~9 ~60 ~34 ~9 ~60 coal_block 0
setblock ~32 ~9 ~62 coal_block 0
fill ~33 ~9 ~59 ~34 ~9 ~59 coal_block 0
fill ~33 ~9 ~63 ~35 ~9 ~63 coal_block 0
fill ~35 ~9 ~59 ~37 ~9 ~59 wool 9
fill ~36 ~9 ~63 ~40 ~9 ~63 wool 9
setblock ~38 ~9 ~59 coal_block 0
fill ~38 ~9 ~60 ~40 ~9 ~60 wool 9
fill ~38 ~9 ~62 ~40 ~9 ~62 wool 9
setblock ~39 ~9 ~61 wool 9
setblock ~39 ~9 ~64 wool 9
fill ~32 ~10 ~61 ~33 ~10 ~61 coal_block 0
setblock ~33 ~10 ~60 coal_block 0
fill ~33 ~10 ~62 ~33 ~11 ~62 coal_block 0
fill ~34 ~10 ~60 ~35 ~10 ~60 wool 9
fill ~34 ~10 ~63 ~34 ~11 ~63 coal_block 0
fill ~35 ~10 ~63 ~37 ~10 ~63 wool 9
setblock ~36 ~10 ~59 wool 9
fill ~37 ~10 ~59 ~37 ~16 ~59 coal_block 0
fill ~38 ~10 ~60 ~39 ~10 ~60 coal_block 0
fill ~38 ~10 ~62 ~40 ~10 ~62 coal_block 0
fill ~38 ~10 ~63 ~39 ~10 ~63 coal_block 0
fill ~39 ~10 ~61 ~40 ~10 ~61 coal_block 0
setblock ~33 ~11 ~61 coal_block 0
fill ~34 ~11 ~60 ~36 ~11 ~60 wool 9
fill ~34 ~11 ~61 ~34 ~16 ~61 wool 9
fill ~34 ~11 ~62 ~34 ~11 ~60 wool 9
fill ~35 ~11 ~63 ~36 ~11 ~63 wool 9
fill ~37 ~11 ~63 ~39 ~11 ~63 coal_block 0
fill ~38 ~11 ~60 ~39 ~11 ~60 coal_block 0
fill ~38 ~11 ~62 ~40 ~11 ~62 coal_block 0
fill ~39 ~11 ~61 ~40 ~11 ~61 coal_block 0
setblock ~34 ~12 ~62 coal_block 0
setblock ~35 ~12 ~60 wool 9
fill ~35 ~12 ~62 ~35 ~17 ~62 wool 9
fill ~35 ~12 ~63 ~35 ~13 ~63 wool 9
fill ~36 ~12 ~60 ~36 ~15 ~60 coal_block 0
fill ~36 ~12 ~63 ~39 ~12 ~63 coal_block 0
fill ~38 ~12 ~59 ~38 ~16 ~59 coal_block 0
fill ~38 ~12 ~60 ~39 ~12 ~60 coal_block 0
fill ~38 ~12 ~62 ~40 ~12 ~62 coal_block 0
fill ~39 ~12 ~61 ~40 ~12 ~61 coal_block 0
fill ~34 ~13 ~62 ~34 ~14 ~62 wool 9
fill ~35 ~13 ~60 ~35 ~14 ~60 coal_block 0
fill ~35 ~13 ~61 ~35 ~14 ~61 coal_block 0
fill ~36 ~13 ~63 ~39 ~13 ~63 coal_block 0
fill ~38 ~13 ~62 ~40 ~13 ~62 coal_block 0
fill ~39 ~13 ~60 ~39 ~17 ~60 coal_block 0
fill ~39 ~13 ~61 ~40 ~13 ~61 coal_block 0
fill ~35 ~14 ~63 ~39 ~14 ~63 coal_block 0
fill ~38 ~14 ~62 ~40 ~14 ~62 coal_block 0
fill ~39 ~14 ~61 ~39 ~15 ~61 coal_block 0
fill ~40 ~14 ~60 ~40 ~19 ~60 coal_block 0
fill ~35 ~15 ~60 ~35 ~17 ~60 wool 9
fill ~36 ~15 ~63 ~39 ~15 ~63 coal_block 0
fill ~38 ~15 ~62 ~40 ~15 ~62 coal_block 0
fill ~39 ~15 ~59 ~39 ~17 ~59 coal_block 0
fill ~36 ~16 ~60 ~36 ~17 ~60 wool 9
fill ~36 ~16 ~62 ~36 ~18 ~62 wool 9
fill ~36 ~16 ~63 ~36 ~17 ~63 wool 9
fill ~37 ~16 ~63 ~40 ~16 ~63 coal_block 0
fill ~38 ~16 ~62 ~39 ~16 ~62 coal_block 0
fill ~40 ~16 ~61 ~40 ~19 ~61 coal_block 0
fill ~35 ~17 ~61 ~35 ~19 ~61 coal_block 0
fill ~37 ~17 ~59 ~38 ~17 ~59 wool 9
fill ~37 ~17 ~63 ~37 ~18 ~63 wool 9
fill ~38 ~17 ~62 ~38 ~136 ~62 coal_block 0
fill ~38 ~17 ~64 ~38 ~18 ~64 wool 9
fill ~39 ~17 ~63 ~40 ~17 ~63 coal_block 0
fill ~40 ~17 ~62 ~40 ~18 ~62 coal_block 0
fill ~35 ~18 ~60 ~36 ~18 ~60 coal_block 0
fill ~35 ~18 ~62 ~35 ~19 ~62 coal_block 0
fill ~36 ~18 ~63 ~36 ~19 ~63 coal_block 0
fill ~37 ~18 ~59 ~39 ~18 ~59 wool 9
fill ~39 ~18 ~63 ~39 ~19 ~63 wool 9
fill ~39 ~18 ~64 ~39 ~21 ~64 wool 9
setblock ~40 ~18 ~63 coal_block 0
fill ~35 ~19 ~60 ~36 ~19 ~60 coal_block 0
setblock ~36 ~19 ~62 coal_block 0
setblock ~37 ~19 ~59 coal_block 0
setblock ~37 ~19 ~63 coal_block 0
fill ~38 ~19 ~59 ~40 ~19 ~59 wool 9
setblock ~38 ~19 ~64 coal_block 0
fill ~40 ~19 ~62 ~40 ~21 ~62 wool 9
fill ~40 ~19 ~63 ~40 ~21 ~63 wool 9
fill ~41 ~19 ~60 ~41 ~19 ~62 coal_block 0
fill ~35 ~20 ~60 ~36 ~20 ~60 wool 9
fill ~35 ~20 ~61 ~35 ~21 ~61 wool 9
fill ~35 ~20 ~62 ~36 ~20 ~62 wool 9
fill ~36 ~20 ~63 ~37 ~20 ~63 wool 9
fill ~37 ~20 ~59 ~40 ~20 ~59 wool 9
fill ~38 ~20 ~64 ~38 ~21 ~64 wool 9
fill ~40 ~20 ~60 ~41 ~20 ~60 wool 9
fill ~40 ~20 ~61 ~41 ~20 ~61 wool 9
fill ~41 ~20 ~62 ~41 ~21 ~62 wool 9
fill ~35 ~21 ~62 ~36 ~21 ~62 wool 9
setblock ~36 ~21 ~60 wool 9
fill ~36 ~21 ~61 ~36 ~22 ~61 coal_block 0
fill ~36 ~21 ~63 ~37 ~21 ~63 wool 9
fill ~37 ~21 ~59 ~40 ~21 ~59 wool 9
fill ~40 ~21 ~60 ~41 ~21 ~60 wool 9
setblock ~40 ~21 ~64 wool 9
setblock ~41 ~21 ~61 wool 9
setblock ~41 ~21 ~63 wool 9
fill ~35 ~22 ~61 ~35 ~26 ~61 coal_block 0
fill ~35 ~22 ~62 ~35 ~23 ~62 coal_block 0
fill ~36 ~22 ~60 ~36 ~41 ~60 coal_block 0
fill ~36 ~22 ~63 ~37 ~22 ~63 coal_block 0
fill ~37 ~22 ~59 ~41 ~22 ~59 coal_block 0
fill ~38 ~22 ~64 ~40 ~22 ~64 coal_block 0
fill ~40 ~22 ~63 ~41 ~22 ~63 coal_block 0
fill ~41 ~22 ~60 ~41 ~25 ~60 coal_block 0
fill ~41 ~22 ~61 ~41 ~24 ~61 coal_block 0
fill ~41 ~22 ~62 ~41 ~24 ~62 coal_block 0
fill ~36 ~23 ~63 ~37 ~23 ~63 coal_block 0
fill ~37 ~23 ~59 ~41 ~23 ~59 coal_block 0
fill ~37 ~23 ~60 ~37 ~36 ~60 coal_block 0
fill ~38 ~23 ~64 ~40 ~23 ~64 coal_block 0
fill ~40 ~23 ~63 ~41 ~23 ~63 coal_block 0
setblock ~42 ~23 ~61 coal_block 0
fill ~36 ~24 ~62 ~36 ~42 ~62 coal_block 0
fill ~36 ~24 ~63 ~37 ~24 ~63 coal_block 0
fill ~37 ~24 ~59 ~41 ~24 ~59 coal_block 0
fill ~38 ~24 ~64 ~41 ~24 ~64 coal_block 0
fill ~41 ~24 ~63 ~41 ~28 ~63 coal_block 0
fill ~42 ~24 ~60 ~42 ~28 ~60 coal_block 0
fill ~42 ~24 ~62 ~42 ~28 ~62 coal_block 0
fill ~36 ~25 ~63 ~37 ~25 ~63 coal_block 0
fill ~37 ~25 ~59 ~41 ~25 ~59 coal_block 0
fill ~38 ~25 ~64 ~41 ~25 ~64 coal_block 0
fill ~40 ~25 ~58 ~40 ~34 ~58 coal_block 0
fill ~42 ~25 ~61 ~42 ~27 ~61 coal_block 0
fill ~42 ~25 ~63 ~42 ~30 ~63 coal_block 0
fill ~36 ~26 ~63 ~37 ~26 ~63 coal_block 0
fill ~37 ~26 ~59 ~39 ~26 ~59 coal_block 0
fill ~38 ~26 ~64 ~41 ~26 ~64 coal_block 0
fill ~41 ~26 ~59 ~42 ~26 ~59 coal_block 0
setblock ~41 ~26 ~62 coal_block 0
fill ~36 ~27 ~61 ~36 ~43 ~61 coal_block 0
fill ~36 ~27 ~63 ~37 ~27 ~63 coal_block 0
fill ~37 ~27 ~59 ~38 ~27 ~59 coal_block 0
fill ~37 ~27 ~64 ~42 ~27 ~64 coal_block 0
fill ~39 ~27 ~58 ~39 ~39 ~58 coal_block 0
setblock ~40 ~27 ~63 coal_block 0
fill ~41 ~27 ~59 ~42 ~27 ~59 coal_block 0
fill ~43 ~27 ~60 ~43 ~32 ~60 coal_block 0
fill ~43 ~27 ~61 ~43 ~32 ~61 coal_block 0
fill ~43 ~27 ~62 ~43 ~27 ~60 coal_block 0
fill ~36 ~28 ~63 ~37 ~28 ~63 coal_block 0
fill ~37 ~28 ~59 ~38 ~28 ~59 coal_block 0
fill ~37 ~28 ~64 ~39 ~28 ~64 coal_block 0
fill ~40 ~28 ~65 ~40 ~37 ~65 coal_block 0
fill ~41 ~28 ~58 ~41 ~33 ~58 coal_block 0
fill ~41 ~28 ~59 ~42 ~28 ~59 coal_block 0
fill ~41 ~28 ~64 ~42 ~28 ~64 coal_block 0
fill ~43 ~28 ~63 ~43 ~29 ~63 coal_block 0
fill ~36 ~29 ~63 ~37 ~29 ~63 coal_block 0
fill ~37 ~29 ~59 ~38 ~29 ~59 coal_block 0
fill ~37 ~29 ~64 ~39 ~29 ~64 coal_block 0
setblock ~39 ~29 ~63 coal_block 0
fill ~41 ~29 ~64 ~42 ~29 ~64 coal_block 0
fill ~41 ~29 ~65 ~41 ~35 ~65 coal_block 0
fill ~42 ~29 ~59 ~43 ~29 ~59 coal_block 0
fill ~43 ~29 ~62 ~43 ~33 ~62 coal_block 0
fill ~36 ~30 ~63 ~37 ~30 ~63 coal_block 0
fill ~37 ~30 ~59 ~38 ~30 ~59 coal_block 0
fill ~37 ~30 ~64 ~38 ~30 ~64 coal_block 0
fill ~39 ~30 ~65 ~39 ~56 ~65 coal_block 0
fill ~42 ~30 ~58 ~42 ~34 ~58 coal_block 0
fill ~42 ~30 ~59 ~43 ~30 ~59 coal_block 0
fill ~42 ~30 ~64 ~43 ~30 ~64 coal_block 0
setblock ~44 ~30 ~61 coal_block 0
fill ~60 ~30 ~46 ~63 ~30 ~46 wool 9
fill ~60 ~30 ~47 ~63 ~30 ~47 wool 9
fill ~60 ~30 ~48 ~63 ~30 ~48 wool 9
fill ~61 ~30 ~45 ~63 ~30 ~45 wool 9
fill ~36 ~31 ~63 ~36 ~33 ~63 coal_block 0
fill ~37 ~31 ~59 ~38 ~31 ~59 coal_block 0
fill ~37 ~31 ~62 ~37 ~35 ~62 coal_block 0
fill ~37 ~31 ~64 ~38 ~31 ~64 coal_block 0
fill ~42 ~31 ~59 ~43 ~31 ~59 coal_block 0
fill ~42 ~31 ~64 ~43 ~31 ~64 coal_block 0
fill ~42 ~31 ~65 ~42 ~35 ~65 coal_block 0
fill ~43 ~31 ~63 ~43 ~33 ~63 coal_block 0
setblock ~44 ~31 ~60 coal_block 0
setblock ~44 ~31 ~62 coal_block 0
fill ~59 ~31 ~47 ~59 ~37 ~47 wool 9
fill ~59 ~31 ~48 ~59 ~38 ~48 wool 9
fill ~60 ~31 ~45 ~61 ~31 ~45 wool 9
fill ~60 ~31 ~46 ~60 ~30 ~46 wool 9
fill ~60 ~31 ~49 ~63 ~31 ~49 wool 9
fill ~61 ~31 ~47 ~61 ~34 ~47 coal_block 0
fill ~61 ~31 ~48 ~61 ~34 ~48 coal_block 0
fill ~62 ~31 ~44 ~63 ~31 ~44 wool 9
fill ~63 ~31 ~45 ~63 ~43 ~45 wool 9
fill ~63 ~31 ~46 ~63 ~43 ~46 wool 9
fill ~63 ~31 ~47 ~63 ~42 ~47 wool 9
fill ~63 ~31 ~48 ~63 ~42 ~48 wool 9
fill ~37 ~32 ~59 ~38 ~32 ~59 coal_block 0
fill ~37 ~32 ~64 ~38 ~32 ~64 coal_block 0
fill ~38 ~32 ~58 ~38 ~63 ~58 coal_block 0
fill ~41 ~32 ~64 ~43 ~32 ~64 coal_block 0
setblock ~42 ~32 ~63 coal_block 0
fill ~43 ~32 ~58 ~43 ~37 ~58 coal_block 0
fill ~43 ~32 ~59 ~44 ~32 ~59 coal_block 0
fill ~44 ~32 ~61 ~44 ~35 ~61 coal_block 0
fill ~44 ~32 ~63 ~44 ~37 ~63 coal_block 0
fill ~59 ~32 ~46 ~59 ~37 ~46 wool 9
fill ~59 ~32 ~49 ~63 ~32 ~49 wool 9
fill ~60 ~32 ~45 ~60 ~35 ~45 wool 9
fill ~60 ~32 ~46 ~61 ~32 ~46 coal_block 0
fill ~60 ~32 ~47 ~60 ~32 ~48 coal_block 0
fill ~61 ~32 ~44 ~63 ~32 ~44 wool 9
fill ~61 ~32 ~45 ~61 ~33 ~45 coal_block 0
fill ~37 ~33 ~59 ~38 ~33 ~59 coal_block 0
fill ~37 ~33 ~64 ~40 ~33 ~64 coal_block 0
fill ~41 ~33 ~57 ~41 ~40 ~57 coal_block 0
fill ~43 ~33 ~59 ~44 ~33 ~59 coal_block 0
fill ~43 ~33 ~64 ~43 ~36 ~64 coal_block 0
fill ~43 ~33 ~65 ~43 ~38 ~65 coal_block 0
fill ~44 ~33 ~60 ~44 ~36 ~60 coal_block 0
fill ~44 ~33 ~62 ~44 ~37 ~62 coal_block 0
fill ~59 ~33 ~49 ~60 ~33 ~49 wool 9
fill ~60 ~33 ~44 ~61 ~33 ~44 wool 9
fill ~60 ~33 ~46 ~62 ~33 ~46 coal_block 0
fill ~60 ~33 ~48 ~60 ~34 ~48 coal_block 0
fill ~61 ~33 ~49 ~61 ~34 ~49 coal_block 0
fill ~61 ~33 ~50 ~63 ~33 ~50 wool 9
fill ~62 ~33 ~43 ~63 ~33 ~43 wool 9
fill ~62 ~33 ~44 ~62 ~33 ~48 coal_block 0
fill ~63 ~33 ~44 ~63 ~43 ~44 wool 9
fill ~63 ~33 ~49 ~63 ~42 ~49 wool 9
fill ~37 ~34 ~59 ~38 ~34 ~59 coal_block 0
fill ~37 ~34 ~63 ~37 ~73 ~63 coal_block 0
fill ~37 ~34 ~64 ~39 ~34 ~64 coal_block 0
fill ~40 ~34 ~57 ~40 ~45 ~57 coal_block 0
fill ~43 ~34 ~59 ~44 ~34 ~59 coal_block 0
fill ~44 ~34 ~64 ~44 ~39 ~64 coal_block 0
setblock ~45 ~34 ~61 coal_block 0
fill ~59 ~34 ~45 ~59 ~39 ~45 wool 9
fill ~59 ~34 ~49 ~60 ~34 ~49 wool 9
fill ~60 ~34 ~44 ~61 ~34 ~44 wool 9
setblock ~61 ~34 ~46 coal_block 0
fill ~61 ~34 ~50 ~63 ~34 ~50 wool 9
fill ~62 ~34 ~43 ~63 ~34 ~43 wool 9
fill ~62 ~34 ~45 ~62 ~37 ~45 coal_block 0
fill ~62 ~34 ~49 ~62 ~42 ~49 coal_block 0
fill ~37 ~35 ~59 ~38 ~35 ~59 coal_block 0
fill ~37 ~35 ~61 ~37 ~36 ~61 coal_block 0
fill ~37 ~35 ~64 ~38 ~35 ~64 coal_block 0
setblock ~38 ~35 ~63 coal_block 0
fill ~38 ~35 ~65 ~38 ~50 ~65 coal_block 0
fill ~41 ~35 ~66 ~41 ~55 ~66 coal_block 0
fill ~42 ~35 ~57 ~42 ~40 ~57 coal_block 0
setblock ~42 ~35 ~64 coal_block 0
fill ~44 ~35 ~58 ~44 ~40 ~58 coal_block 0
fill ~44 ~35 ~59 ~44 ~37 ~59 coal_block 0
setblock ~45 ~35 ~60 coal_block 0
setblock ~45 ~35 ~62 coal_block 0
fill ~59 ~35 ~49 ~59 ~45 ~49 wool 9
fill ~60 ~35 ~44 ~60 ~50 ~44 wool 9
fill ~60 ~35 ~49 ~60 ~36 ~49 coal_block 0
fill ~60 ~35 ~50 ~63 ~35 ~50 wool 9
fill ~61 ~35 ~43 ~63 ~35 ~43 wool 9
fill ~61 ~35 ~44 ~62 ~35 ~44 coal_block 0
fill ~62 ~35 ~46 ~62 ~38 ~46 coal_block 0
fill ~62 ~35 ~47 ~62 ~42 ~47 coal_block 0
fill ~62 ~35 ~48 ~62 ~42 ~48 coal_block 0
fill ~37 ~36 ~59 ~38 ~36 ~59 coal_block 0
fill ~37 ~36 ~64 ~39 ~36 ~64 coal_block 0
fill ~42 ~36 ~66 ~42 ~56 ~66 coal_block 0
fill ~44 ~36 ~65 ~44 ~41 ~65 coal_block 0
fill ~45 ~36 ~59 ~45 ~40 ~59 coal_block 0
fill ~45 ~36 ~61 ~45 ~39 ~61 coal_block 0
fill ~45 ~36 ~63 ~45 ~40 ~63 coal_block 0
fill ~59 ~36 ~44 ~59 ~50 ~44 wool 9
fill ~60 ~36 ~45 ~60 ~38 ~45 coal_block 0
fill ~60 ~36 ~50 ~63 ~36 ~50 wool 9
fill ~61 ~36 ~43 ~63 ~36 ~43 wool 9
fill ~61 ~36 ~44 ~62 ~36 ~44 coal_block 0
fill ~37 ~37 ~59 ~37 ~59 ~59 coal_block 0
fill ~37 ~37 ~64 ~38 ~37 ~64 coal_block 0
setblock ~38 ~37 ~63 coal_block 0
setblock ~40 ~37 ~64 coal_block 0
fill ~43 ~37 ~57 ~43 ~42 ~57 coal_block 0
fill ~45 ~37 ~60 ~45 ~39 ~60 coal_block 0
fill ~45 ~37 ~62 ~45 ~39 ~62 coal_block 0
fill ~60 ~37 ~49 ~60 ~37 ~50 wool 9
fill ~61 ~37 ~43 ~63 ~37 ~43 wool 9
fill ~61 ~37 ~44 ~62 ~37 ~44 coal_block 0
fill ~61 ~37 ~50 ~63 ~37 ~50 wool 9
fill ~37 ~38 ~64 ~38 ~38 ~64 coal_block 0
fill ~38 ~38 ~61 ~38 ~41 ~61 coal_block 0
fill ~39 ~38 ~57 ~39 ~68 ~57 coal_block 0
fill ~40 ~38 ~66 ~40 ~51 ~66 coal_block 0
fill ~43 ~38 ~66 ~43 ~56 ~66 coal_block 0
fill ~45 ~38 ~58 ~45 ~43 ~58 coal_block 0
fill ~45 ~38 ~64 ~45 ~41 ~64 coal_block 0
fill ~46 ~38 ~60 ~46 ~41 ~60 coal_block 0
fill ~46 ~38 ~61 ~46 ~38 ~60 coal_block 0
fill ~58 ~38 ~46 ~58 ~38 ~47 wool 9
setblock ~59 ~38 ~46 coal_block 0
fill ~60 ~38 ~49 ~60 ~46 ~49 coal_block 0
fill ~60 ~38 ~50 ~63 ~38 ~50 wool 9
fill ~61 ~38 ~43 ~63 ~38 ~43 wool 9
fill ~61 ~38 ~44 ~61 ~42 ~44 coal_block 0
fill ~37 ~39 ~64 ~38 ~39 ~64 coal_block 0
fill ~44 ~39 ~57 ~44 ~44 ~57 coal_block 0
fill ~46 ~39 ~62 ~46 ~41 ~62 coal_block 0
fill ~46 ~39 ~63 ~46 ~39 ~62 coal_block 0
fill ~58 ~39 ~46 ~58 ~41 ~46 coal_block 0
fill ~58 ~39 ~47 ~58 ~42 ~47 coal_block 0
fill ~58 ~39 ~48 ~58 ~40 ~48 wool 9
setblock ~59 ~39 ~48 coal_block 0
fill ~60 ~39 ~45 ~60 ~40 ~45 wool 9
fill ~60 ~39 ~46 ~60 ~39 ~48 wool 9
fill ~60 ~39 ~50 ~63 ~39 ~50 wool 9
fill ~61 ~39 ~43 ~63 ~39 ~43 wool 9
fill ~37 ~40 ~64 ~38 ~40 ~64 coal_block 0
fill ~38 ~40 ~57 ~38 ~45 ~57 coal_block 0
fill ~42 ~40 ~56 ~42 ~62 ~56 coal_block 0
fill ~44 ~40 ~66 ~44 ~55 ~66 coal_block 0
fill ~45 ~40 ~65 ~45 ~44 ~65 coal_block 0
fill ~46 ~40 ~59 ~46 ~43 ~59 coal_block 0
fill ~46 ~40 ~61 ~47 ~40 ~61 coal_block 0
fill ~46 ~40 ~64 ~46 ~44 ~64 coal_block 0
fill ~59 ~40 ~45 ~59 ~43 ~45 coal_block 0
fill ~59 ~40 ~46 ~59 ~40 ~47 coal_block 0
fill ~59 ~40 ~48 ~60 ~40 ~48 wool 9
fill ~60 ~40 ~50 ~63 ~40 ~50 wool 9
fill ~61 ~40 ~43 ~63 ~40 ~43 wool 9
fill ~37 ~41 ~64 ~38 ~41 ~64 coal_block 0
fill ~41 ~41 ~56 ~41 ~79 ~56 coal_block 0
fill ~43 ~41 ~56 ~43 ~60 ~56 coal_block 0
fill ~46 ~41 ~58 ~46 ~46 ~58 coal_block 0
fill ~46 ~41 ~61 ~46 ~40 ~61 coal_block 0
fill ~46 ~41 ~63 ~46 ~42 ~63 coal_block 0
fill ~47 ~41 ~60 ~47 ~46 ~60 coal_block 0
fill ~47 ~41 ~62 ~47 ~45 ~62 coal_block 0
fill ~58 ~41 ~45 ~58 ~45 ~45 coal_block 0
fill ~58 ~41 ~48 ~59 ~41 ~48 coal_block 0
fill ~58 ~41 ~49 ~58 ~49 ~49 wool 9
fill ~60 ~41 ~50 ~63 ~41 ~50 wool 9
fill ~61 ~41 ~43 ~63 ~41 ~43 wool 9
fill ~62 ~41 ~44 ~62 ~42 ~44 coal_block 0
fill ~37 ~42 ~60 ~37 ~61 ~60 coal_block 0
fill ~37 ~42 ~64 ~38 ~42 ~64 coal_block 0
fill ~38 ~42 ~59 ~38 ~58 ~59 coal_block 0
setblock ~39 ~42 ~56 coal_block 0
fill ~45 ~42 ~57 ~45 ~47 ~57 coal_block 0
fill ~46 ~42 ~65 ~46 ~56 ~65 coal_block 0
fill ~47 ~42 ~59 ~47 ~59 ~59 coal_block 0
fill ~47 ~42 ~61 ~47 ~45 ~61 coal_block 0
fill ~47 ~42 ~63 ~47 ~47 ~63 coal_block 0
fill ~57 ~42 ~46 ~57 ~44 ~46 coal_block 0
fill ~57 ~42 ~47 ~57 ~44 ~47 coal_block 0
fill ~58 ~42 ~48 ~59 ~42 ~48 coal_block 0
setblock ~60 ~42 ~45 wool 9
fill ~60 ~42 ~50 ~63 ~42 ~50 wool 9
fill ~61 ~42 ~43 ~62 ~42 ~43 wool 9
fill ~61 ~42 ~49 ~61 ~47 ~49 coal_block 0
fill ~37 ~43 ~61 ~38 ~43 ~61 coal_block 0
fill ~37 ~43 ~62 ~37 ~60 ~62 coal_block 0
fill ~37 ~43 ~64 ~38 ~43 ~64 coal_block 0
fill ~45 ~43 ~66 ~45 ~53 ~66 coal_block 0
fill ~47 ~43 ~64 ~47 ~55 ~64 coal_block 0
fill ~48 ~43 ~61 ~48 ~56 ~61 coal_block 0
fill ~57 ~43 ~48 ~58 ~43 ~48 coal_block 0
fill ~58 ~43 ~44 ~58 ~49 ~44 wool 9
setblock ~58 ~43 ~46 coal_block 0
fill ~60 ~43 ~50 ~62 ~43 ~50 wool 9
fill ~61 ~43 ~44 ~63 ~43 ~44 wool 9
fill ~62 ~43 ~47 ~62 ~45 ~47 wool 9
fill ~62 ~43 ~48 ~62 ~44 ~48 wool 9
fill ~62 ~43 ~49 ~62 ~44 ~49 wool 9
fill ~37 ~44 ~61 ~37 ~58 ~61 coal_block 0
fill ~37 ~44 ~64 ~37 ~46 ~64 coal_block 0
fill ~38 ~44 ~63 ~38 ~70 ~63 coal_block 0
fill ~39 ~44 ~61 ~42 ~44 ~61 coal_block 0
fill ~39 ~44 ~62 ~48 ~44 ~62 coal_block 0
fill ~40 ~44 ~56 ~40 ~51 ~56 coal_block 0
fill ~42 ~44 ~57 ~42 ~44 ~66 coal_block 0
fill ~44 ~44 ~56 ~44 ~58 ~56 coal_block 0
fill ~46 ~44 ~57 ~46 ~58 ~57 coal_block 0
fill ~47 ~44 ~58 ~47 ~58 ~58 coal_block 0
fill ~48 ~44 ~60 ~48 ~56 ~60 coal_block 0
fill ~56 ~44 ~46 ~56 ~45 ~46 coal_block 0
fill ~56 ~44 ~47 ~56 ~45 ~47 coal_block 0
fill ~57 ~44 ~45 ~57 ~50 ~45 coal_block 0
fill ~57 ~44 ~48 ~58 ~44 ~48 coal_block 0
fill ~57 ~44 ~49 ~57 ~48 ~49 wool 9
fill ~60 ~44 ~50 ~62 ~44 ~50 wool 9
fill ~61 ~44 ~44 ~62 ~44 ~44 wool 9
fill ~62 ~44 ~45 ~62 ~45 ~45 wool 9
fill ~62 ~44 ~46 ~62 ~45 ~46 wool 9
fill ~42 ~45 ~59 ~43 ~45 ~59 coal_block 0
fill ~42 ~45 ~60 ~43 ~45 ~60 coal_block 0
fill ~47 ~45 ~65 ~47 ~52 ~65 coal_block 0
fill ~48 ~45 ~59 ~48 ~55 ~59 coal_block 0
fill ~48 ~45 ~62 ~48 ~55 ~62 coal_block 0
fill ~48 ~45 ~63 ~48 ~54 ~63 coal_block 0
fill ~55 ~45 ~46 ~55 ~46 ~46 coal_block 0
fill ~55 ~45 ~47 ~55 ~46 ~47 coal_block 0
setblock ~56 ~45 ~45 coal_block 0
fill ~56 ~45 ~48 ~57 ~45 ~48 coal_block 0
fill ~60 ~45 ~47 ~61 ~45 ~47 coal_block 0
fill ~60 ~45 ~50 ~63 ~45 ~50 wool 9
fill ~61 ~45 ~44 ~62 ~45 ~44 wool 9
fill ~62 ~45 ~48 ~62 ~45 ~49 coal_block 0
fill ~63 ~45 ~48 ~63 ~50 ~48 wool 9
fill ~63 ~45 ~49 ~63 ~50 ~49 wool 9
fill ~43 ~46 ~60 ~43 ~67 ~60 coal_block 0
fill ~45 ~46 ~56 ~45 ~55 ~56 coal_block 0
fill ~46 ~46 ~66 ~46 ~51 ~66 coal_block 0
setblock ~55 ~46 ~45 coal_block 0
setblock ~55 ~46 ~48 coal_block 0
fill ~56 ~46 ~45 ~56 ~48 ~45 wool 9
fill ~56 ~46 ~48 ~57 ~46 ~48 wool 9
fill ~57 ~46 ~44 ~57 ~48 ~44 wool 9
fill ~58 ~46 ~47 ~60 ~46 ~47 coal_block 0
setblock ~59 ~46 ~49 coal_block 0
fill ~59 ~46 ~50 ~63 ~46 ~50 wool 9
fill ~61 ~46 ~44 ~63 ~46 ~44 wool 9
fill ~62 ~46 ~49 ~62 ~49 ~49 coal_block 0
fill ~63 ~46 ~45 ~63 ~50 ~45 wool 9
fill ~63 ~46 ~46 ~63 ~50 ~46 wool 9
fill ~63 ~46 ~47 ~63 ~50 ~47 wool 9
fill ~38 ~47 ~64 ~38 ~60 ~64 coal_block 0
fill ~40 ~47 ~57 ~40 ~64 ~57 coal_block 0
fill ~48 ~47 ~64 ~48 ~51 ~64 coal_block 0
fill ~53 ~47 ~46 ~54 ~47 ~46 wool 9
fill ~53 ~47 ~47 ~54 ~47 ~47 coal_block 0
fill ~54 ~47 ~48 ~56 ~47 ~48 wool 9
fill ~55 ~47 ~45 ~55 ~48 ~45 wool 9
fill ~57 ~47 ~47 ~58 ~47 ~47 coal_block 0
fill ~59 ~47 ~49 ~60 ~47 ~49 wool 9
fill ~59 ~47 ~50 ~63 ~47 ~50 wool 9
setblock ~60 ~47 ~47 coal_block 0
fill ~61 ~47 ~44 ~63 ~47 ~44 wool 9
fill ~47 ~48 ~57 ~47 ~54 ~57 coal_block 0
fill ~51 ~48 ~47 ~52 ~48 ~47 wool 9
setblock ~52 ~48 ~46 wool 9
fill ~53 ~48 ~45 ~56 ~48 ~45 wool 9
setblock ~53 ~48 ~46 coal_block 0
fill ~53 ~48 ~48 ~56 ~48 ~48 wool 9
fill ~55 ~48 ~47 ~56 ~48 ~47 wool 9
fill ~57 ~48 ~47 ~58 ~48 ~47 coal_block 0
fill ~57 ~48 ~48 ~57 ~50 ~48 coal_block 0
fill ~59 ~48 ~48 ~59 ~50 ~48 wool 9
fill ~59 ~48 ~49 ~61 ~48 ~49 wool 9
fill ~60 ~48 ~50 ~63 ~48 ~50 wool 9
fill ~61 ~48 ~44 ~63 ~48 ~44 wool 9
fill ~39 ~49 ~58 ~39 ~54 ~58 coal_block 0
fill ~48 ~49 ~58 ~48 ~51 ~58 coal_block 0
fill ~50 ~49 ~47 ~51 ~49 ~47 coal_block 0
setblock ~51 ~49 ~46 wool 9
setblock ~52 ~49 ~45 wool 9
setblock ~52 ~49 ~46 coal_block 0
fill ~52 ~49 ~48 ~54 ~49 ~48 wool 9
fill ~53 ~49 ~45 ~57 ~49 ~45 coal_block 0
fill ~53 ~49 ~47 ~54 ~49 ~47 wool 9
fill ~55 ~49 ~47 ~56 ~49 ~47 coal_block 0
fill ~55 ~49 ~49 ~56 ~49 ~49 coal_block 0
fill ~58 ~49 ~45 ~59 ~49 ~45 wool 9
fill ~58 ~49 ~48 ~58 ~50 ~48 wool 9
fill ~59 ~49 ~49 ~61 ~49 ~49 wool 9
fill ~61 ~49 ~44 ~63 ~49 ~44 wool 9
fill ~61 ~49 ~50 ~62 ~49 ~50 wool 9
fill ~49 ~50 ~46 ~49 ~51 ~46 coal_block 0
fill ~49 ~50 ~47 ~49 ~51 ~47 coal_block 0
fill ~50 ~50 ~46 ~50 ~50 ~47 wool 9
fill ~50 ~50 ~48 ~51 ~50 ~48 coal_block 0
fill ~51 ~50 ~45 ~51 ~51 ~45 wool 9
fill ~52 ~50 ~45 ~57 ~50 ~45 coal_block 0
fill ~52 ~50 ~47 ~52 ~50 ~48 wool 9
fill ~53 ~50 ~47 ~54 ~50 ~47 coal_block 0
fill ~53 ~50 ~49 ~53 ~51 ~49 wool 9
fill ~54 ~50 ~49 ~55 ~50 ~49 coal_block 0
fill ~56 ~50 ~48 ~56 ~51 ~48 coal_block 0
fill ~58 ~50 ~45 ~58 ~49 ~45 wool 9
fill ~58 ~50 ~46 ~59 ~50 ~46 wool 9
fill ~58 ~50 ~47 ~59 ~50 ~47 wool 9
fill ~59 ~50 ~45 ~61 ~50 ~45 coal_block 0
fill ~60 ~50 ~48 ~62 ~50 ~48 coal_block 0
fill ~60 ~50 ~49 ~63 ~50 ~49 wool 9
fill ~61 ~50 ~44 ~61 ~43 ~44 wool 9
setblock ~62 ~50 ~45 wool 9
fill ~62 ~50 ~46 ~62 ~50 ~48 coal_block 0
fill ~40 ~51 ~65 ~40 ~59 ~65 coal_block 0
fill ~48 ~51 ~46 ~48 ~52 ~46 coal_block 0
fill ~48 ~51 ~47 ~48 ~51 ~46 coal_block 0
fill ~49 ~51 ~45 ~49 ~52 ~45 coal_block 0
fill ~49 ~51 ~48 ~50 ~51 ~48 coal_block 0
fill ~50 ~51 ~45 ~50 ~52 ~45 wool 9
fill ~51 ~51 ~49 ~53 ~51 ~49 wool 9
fill ~52 ~51 ~45 ~56 ~51 ~45 coal_block 0
fill ~52 ~51 ~47 ~53 ~51 ~47 coal_block 0
fill ~54 ~51 ~49 ~54 ~50 ~49 coal_block 0
fill ~55 ~51 ~48 ~55 ~52 ~48 coal_block 0
fill ~56 ~51 ~46 ~57 ~51 ~46 coal_block 0
setblock ~57 ~51 ~47 coal_block 0
fill ~58 ~51 ~46 ~62 ~51 ~46 wool 9
fill ~58 ~51 ~47 ~62 ~51 ~47 wool 9
fill ~59 ~51 ~45 ~61 ~51 ~45 wool 9
fill ~60 ~51 ~48 ~62 ~51 ~48 wool 9
fill ~39 ~52 ~64 ~39 ~73 ~64 coal_block 0
fill ~46 ~52 ~46 ~47 ~52 ~46 wool 9
fill ~46 ~52 ~47 ~47 ~52 ~47 wool 9
fill ~47 ~52 ~48 ~47 ~53 ~48 wool 9
fill ~47 ~52 ~63 ~47 ~57 ~63 coal_block 0
fill ~48 ~52 ~45 ~48 ~53 ~45 coal_block 0
fill ~48 ~52 ~48 ~49 ~52 ~48 coal_block 0
setblock ~50 ~52 ~49 coal_block 0
setblock ~51 ~52 ~44 wool 9
fill ~51 ~52 ~47 ~52 ~52 ~47 coal_block 0
fill ~51 ~52 ~49 ~52 ~52 ~49 wool 9
setblock ~52 ~52 ~44 coal_block 0
fill ~53 ~52 ~45 ~55 ~52 ~45 coal_block 0
setblock ~53 ~52 ~49 coal_block 0
fill ~54 ~52 ~48 ~54 ~53 ~48 coal_block 0
fill ~55 ~52 ~46 ~56 ~52 ~46 coal_block 0
fill ~55 ~52 ~47 ~56 ~52 ~47 coal_block 0
fill ~45 ~53 ~46 ~46 ~53 ~46 coal_block 0
fill ~45 ~53 ~47 ~45 ~57 ~47 coal_block 0
fill ~45 ~53 ~48 ~45 ~54 ~48 coal_block 0
fill ~46 ~53 ~45 ~47 ~53 ~45 wool 9
fill ~46 ~53 ~47 ~46 ~52 ~47 wool 9
fill ~46 ~53 ~48 ~46 ~53 ~47 wool 9
fill ~48 ~53 ~47 ~51 ~53 ~47 coal_block 0
fill ~48 ~53 ~49 ~48 ~56 ~49 wool 9
fill ~49 ~53 ~44 ~50 ~53 ~44 wool 9
setblock ~49 ~53 ~49 coal_block 0
fill ~50 ~53 ~49 ~51 ~53 ~49 wool 9
setblock ~51 ~53 ~44 coal_block 0
fill ~52 ~53 ~45 ~53 ~53 ~45 coal_block 0
setblock ~52 ~53 ~49 coal_block 0
fill ~53 ~53 ~46 ~54 ~53 ~46 coal_block 0
fill ~53 ~53 ~47 ~54 ~53 ~47 coal_block 0
fill ~53 ~53 ~48 ~53 ~53 ~45 coal_block 0
fill ~43 ~54 ~46 ~45 ~54 ~46 coal_block 0
fill ~43 ~54 ~47 ~45 ~54 ~47 coal_block 0
fill ~44 ~54 ~48 ~44 ~55 ~48 coal_block 0
fill ~45 ~54 ~45 ~45 ~55 ~45 coal_block 0
fill ~45 ~54 ~57 ~45 ~61 ~57 coal_block 0
fill ~45 ~54 ~65 ~45 ~58 ~65 coal_block 0
fill ~46 ~54 ~45 ~46 ~53 ~45 wool 9
fill ~46 ~54 ~49 ~46 ~59 ~49 coal_block 0
fill ~46 ~54 ~64 ~46 ~58 ~64 coal_block 0
fill ~47 ~54 ~44 ~50 ~54 ~44 wool 9
fill ~47 ~54 ~47 ~48 ~54 ~47 coal_block 0
setblock ~47 ~54 ~49 wool 9
fill ~47 ~54 ~62 ~47 ~59 ~62 coal_block 0
fill ~49 ~54 ~49 ~51 ~54 ~49 wool 9
setblock ~50 ~54 ~47 wool 9
fill ~51 ~54 ~45 ~52 ~54 ~45 coal_block 0
fill ~52 ~54 ~46 ~53 ~54 ~46 coal_block 0
fill ~52 ~54 ~47 ~53 ~54 ~47 coal_block 0
fill ~52 ~54 ~48 ~52 ~54 ~45 coal_block 0
fill ~42 ~55 ~46 ~43 ~55 ~46 coal_block 0
fill ~42 ~55 ~47 ~48 ~55 ~47 coal_block 0
fill ~42 ~55 ~48 ~44 ~55 ~48 coal_block 0
fill ~43 ~55 ~45 ~45 ~55 ~45 coal_block 0
fill ~45 ~55 ~49 ~45 ~60 ~49 coal_block 0
fill ~46 ~55 ~44 ~46 ~59 ~44 coal_block 0
fill ~46 ~55 ~58 ~46 ~61 ~58 coal_block 0
fill ~47 ~55 ~44 ~49 ~55 ~44 wool 9
fill ~47 ~55 ~45 ~47 ~56 ~45 coal_block 0
fill ~47 ~55 ~46 ~47 ~56 ~46 coal_block 0
setblock ~47 ~55 ~48 wool 9
fill ~47 ~55 ~49 ~47 ~58 ~49 coal_block 0
fill ~47 ~55 ~60 ~47 ~60 ~60 coal_block 0
fill ~47 ~55 ~61 ~47 ~60 ~61 coal_block 0
fill ~49 ~55 ~49 ~50 ~55 ~49 wool 9
fill ~50 ~55 ~45 ~50 ~56 ~45 wool 9
fill ~50 ~55 ~48 ~51 ~55 ~48 wool 9
fill ~51 ~55 ~45 ~51 ~54 ~45 coal_block 0
fill ~51 ~55 ~46 ~52 ~55 ~46 coal_block 0
setblock ~51 ~55 ~47 wool 9
setblock ~52 ~55 ~47 coal_block 0
fill ~38 ~56 ~60 ~48 ~56 ~60 coal_block 0
fill ~40 ~56 ~46 ~41 ~56 ~46 coal_block 0
fill ~40 ~56 ~47 ~41 ~56 ~47 coal_block 0
setblock ~40 ~56 ~59 coal_block 0
fill ~41 ~56 ~45 ~43 ~56 ~45 coal_block 0
fill ~41 ~56 ~48 ~42 ~56 ~48 coal_block 0
fill ~41 ~56 ~65 ~41 ~61 ~65 coal_block 0
fill ~42 ~56 ~59 ~43 ~56 ~59 coal_block 0
fill ~43 ~56 ~49 ~47 ~56 ~49 coal_block 0
fill ~43 ~56 ~57 ~43 ~56 ~64 coal_block 0
fill ~44 ~56 ~44 ~47 ~56 ~44 coal_block 0
fill ~44 ~56 ~47 ~44 ~58 ~47 coal_block 0
fill ~44 ~56 ~65 ~44 ~59 ~65 coal_block 0
fill ~46 ~56 ~63 ~46 ~60 ~63 coal_block 0
setblock ~47 ~56 ~47 coal_block 0
setblock ~48 ~56 ~44 wool 9
fill ~49 ~56 ~45 ~49 ~57 ~45 wool 9
fill ~49 ~56 ~48 ~50 ~56 ~48 wool 9
fill ~49 ~56 ~49 ~49 ~54 ~49 wool 9
fill ~50 ~56 ~46 ~50 ~56 ~48 wool 9
fill ~51 ~56 ~46 ~51 ~55 ~46 coal_block 0
fill ~51 ~56 ~47 ~51 ~56 ~46 coal_block 0
fill ~38 ~57 ~60 ~39 ~57 ~60 coal_block 0
fill ~38 ~57 ~61 ~38 ~57 ~58 coal_block 0
fill ~39 ~57 ~46 ~40 ~57 ~46 coal_block 0
fill ~39 ~57 ~47 ~40 ~57 ~47 coal_block 0
fill ~39 ~57 ~48 ~40 ~57 ~48 coal_block 0
fill ~40 ~57 ~45 ~41 ~57 ~45 coal_block 0
fill ~41 ~57 ~49 ~48 ~57 ~49 coal_block 0
fill ~42 ~57 ~44 ~47 ~57 ~44 coal_block 0
fill ~42 ~57 ~64 ~42 ~57 ~65 coal_block 0
setblock ~43 ~57 ~62 coal_block 0
fill ~43 ~57 ~65 ~43 ~60 ~65 coal_block 0
fill ~45 ~57 ~64 ~45 ~60 ~64 coal_block 0
fill ~47 ~57 ~47 ~47 ~58 ~47 wool 9
setblock ~48 ~57 ~45 wool 9
fill ~48 ~57 ~48 ~49 ~57 ~48 wool 9
fill ~49 ~57 ~46 ~49 ~57 ~48 wool 9
setblock ~50 ~57 ~47 wool 9
fill ~37 ~58 ~46 ~38 ~58 ~46 coal_block 0
fill ~37 ~58 ~47 ~38 ~58 ~47 coal_block 0
fill ~37 ~58 ~48 ~39 ~58 ~48 coal_block 0
fill ~37 ~58 ~58 ~37 ~68 ~58 coal_block 0
fill ~38 ~58 ~45 ~39 ~58 ~45 coal_block 0
fill ~39 ~58 ~49 ~42 ~58 ~49 coal_block 0
fill ~40 ~58 ~44 ~43 ~58 ~44 coal_block 0
fill ~42 ~58 ~47 ~44 ~58 ~47 coal_block 0
fill ~42 ~58 ~65 ~42 ~61 ~65 coal_block 0
fill ~43 ~58 ~43 ~44 ~58 ~43 coal_block 0
fill ~43 ~58 ~50 ~44 ~58 ~50 coal_block 0
setblock ~43 ~58 ~64 coal_block 0
fill ~45 ~58 ~44 ~45 ~60 ~44 coal_block 0
fill ~46 ~58 ~45 ~48 ~58 ~45 coal_block 0
fill ~46 ~58 ~59 ~46 ~62 ~59 coal_block 0
fill ~46 ~58 ~62 ~46 ~61 ~62 coal_block 0
fill ~47 ~58 ~46 ~48 ~58 ~46 coal_block 0
setblock ~47 ~58 ~48 wool 9
fill ~48 ~58 ~47 ~48 ~58 ~48 coal_block 0
setblock ~49 ~58 ~47 wool 9
fill ~35 ~59 ~47 ~36 ~59 ~47 coal_block 0
fill ~36 ~59 ~45 ~37 ~59 ~45 coal_block 0
fill ~36 ~59 ~46 ~37 ~59 ~46 coal_block 0
fill ~36 ~59 ~48 ~37 ~59 ~48 coal_block 0
fill ~36 ~59 ~60 ~36 ~70 ~60 coal_block 0
fill ~36 ~59 ~61 ~36 ~72 ~61 coal_block 0
fill ~37 ~59 ~49 ~39 ~59 ~49 coal_block 0
fill ~38 ~59 ~44 ~39 ~59 ~44 coal_block 0
fill ~38 ~59 ~61 ~38 ~61 ~61 coal_block 0
fill ~40 ~59 ~43 ~44 ~59 ~43 coal_block 0
fill ~40 ~59 ~47 ~43 ~59 ~47 coal_block 0
fill ~40 ~59 ~50 ~43 ~59 ~50 coal_block 0
fill ~41 ~59 ~44 ~46 ~59 ~44 coal_block 0
fill ~44 ~59 ~49 ~44 ~61 ~49 coal_block 0
fill ~44 ~59 ~57 ~44 ~92 ~57 coal_block 0
fill ~44 ~59 ~63 ~46 ~59 ~63 coal_block 0
fill ~44 ~59 ~64 ~44 ~62 ~64 coal_block 0
fill ~45 ~59 ~46 ~47 ~59 ~46 coal_block 0
setblock ~45 ~59 ~62 coal_block 0
fill ~46 ~59 ~45 ~47 ~59 ~45 coal_block 0
fill ~46 ~59 ~48 ~47 ~59 ~48 coal_block 0
fill ~46 ~59 ~60 ~46 ~62 ~60 coal_block 0
fill ~46 ~59 ~61 ~46 ~62 ~61 coal_block 0
setblock ~47 ~59 ~47 coal_block 0
fill ~34 ~60 ~46 ~35 ~60 ~46 coal_block 0
fill ~34 ~60 ~47 ~35 ~60 ~47 coal_block 0
fill ~34 ~60 ~48 ~35 ~60 ~48 coal_block 0
fill ~35 ~60 ~45 ~36 ~60 ~45 coal_block 0
fill ~35 ~60 ~49 ~37 ~60 ~49 coal_block 0
fill ~36 ~60 ~44 ~37 ~60 ~44 coal_block 0
fill ~36 ~60 ~59 ~36 ~68 ~59 coal_block 0
fill ~38 ~60 ~43 ~43 ~60 ~43 coal_block 0
fill ~38 ~60 ~50 ~43 ~60 ~50 coal_block 0
fill ~38 ~60 ~57 ~38 ~71 ~57 coal_block 0
fill ~39 ~60 ~47 ~41 ~60 ~47 coal_block 0
fill ~40 ~60 ~64 ~40 ~73 ~64 coal_block 0
fill ~44 ~60 ~44 ~44 ~61 ~44 coal_block 0
fill ~45 ~60 ~45 ~46 ~60 ~45 coal_block 0
fill ~45 ~60 ~46 ~46 ~60 ~46 coal_block 0
fill ~45 ~60 ~48 ~46 ~60 ~48 coal_block 0
fill ~45 ~60 ~58 ~45 ~68 ~58 coal_block 0
fill ~45 ~60 ~63 ~45 ~62 ~63 coal_block 0
setblock ~46 ~60 ~47 coal_block 0
fill ~32 ~61 ~46 ~33 ~61 ~46 coal_block 0
fill ~32 ~61 ~47 ~33 ~61 ~47 coal_block 0
fill ~32 ~61 ~48 ~34 ~61 ~48 coal_block 0
fill ~33 ~61 ~45 ~34 ~61 ~45 coal_block 0
fill ~33 ~61 ~49 ~35 ~61 ~49 coal_block 0
fill ~34 ~61 ~44 ~35 ~61 ~44 coal_block 0
setblock ~35 ~61 ~46 coal_block 0
fill ~36 ~61 ~43 ~42 ~61 ~43 coal_block 0
fill ~36 ~61 ~47 ~39 ~61 ~47 coal_block 0
fill ~36 ~61 ~50 ~42 ~61 ~50 coal_block 0
fill ~36 ~61 ~62 ~36 ~70 ~62 coal_block 0
fill ~37 ~61 ~59 ~37 ~65 ~59 coal_block 0
setblock ~37 ~61 ~61 coal_block 0
setblock ~39 ~61 ~63 coal_block 0
setblock ~41 ~61 ~47 coal_block 0
fill ~43 ~61 ~44 ~43 ~62 ~44 coal_block 0
fill ~43 ~61 ~49 ~43 ~62 ~49 coal_block 0
fill ~43 ~61 ~57 ~43 ~85 ~57 coal_block 0
fill ~43 ~61 ~59 ~43 ~63 ~59 coal_block 0
fill ~43 ~61 ~64 ~43 ~68 ~64 coal_block 0
fill ~44 ~61 ~45 ~45 ~61 ~45 coal_block 0
fill ~44 ~61 ~46 ~45 ~61 ~46 coal_block 0
fill ~44 ~61 ~48 ~45 ~61 ~48 coal_block 0
fill ~44 ~61 ~63 ~44 ~66 ~63 coal_block 0
fill ~45 ~61 ~47 ~45 ~62 ~47 coal_block 0
fill ~45 ~61 ~62 ~45 ~63 ~62 coal_block 0
fill ~31 ~62 ~45 ~32 ~62 ~45 coal_block 0
fill ~31 ~62 ~46 ~32 ~62 ~46 coal_block 0
fill ~31 ~62 ~47 ~32 ~62 ~47 coal_block 0
fill ~31 ~62 ~48 ~32 ~62 ~48 coal_block 0
fill ~32 ~62 ~44 ~34 ~62 ~44 coal_block 0
fill ~32 ~62 ~49 ~33 ~62 ~49 coal_block 0
fill ~34 ~62 ~43 ~42 ~62 ~43 coal_block 0
fill ~34 ~62 ~50 ~41 ~62 ~50 coal_block 0
fill ~35 ~62 ~47 ~37 ~62 ~47 coal_block 0
fill ~37 ~62 ~62 ~37 ~69 ~62 coal_block 0
fill ~40 ~62 ~63 ~45 ~62 ~63 coal_block 0
fill ~41 ~62 ~64 ~44 ~62 ~64 coal_block 0
fill ~42 ~62 ~44 ~42 ~63 ~44 coal_block 0
fill ~42 ~62 ~49 ~42 ~63 ~49 coal_block 0
fill ~43 ~62 ~45 ~44 ~62 ~45 coal_block 0
fill ~43 ~62 ~46 ~44 ~62 ~46 coal_block 0
fill ~43 ~62 ~48 ~44 ~62 ~48 coal_block 0
setblock ~44 ~62 ~47 coal_block 0
fill ~44 ~62 ~62 ~44 ~65 ~62 coal_block 0
fill ~45 ~62 ~59 ~45 ~70 ~59 coal_block 0
fill ~45 ~62 ~60 ~45 ~70 ~60 coal_block 0
fill ~45 ~62 ~61 ~45 ~67 ~61 coal_block 0
fill ~29 ~63 ~46 ~30 ~63 ~46 coal_block 0
fill ~29 ~63 ~47 ~30 ~63 ~47 coal_block 0
fill ~29 ~63 ~48 ~30 ~63 ~48 coal_block 0
fill ~30 ~63 ~45 ~32 ~63 ~45 coal_block 0
fill ~30 ~63 ~49 ~31 ~63 ~49 coal_block 0
fill ~31 ~63 ~44 ~32 ~63 ~44 coal_block 0
fill ~32 ~63 ~43 ~34 ~63 ~43 coal_block 0
fill ~32 ~63 ~50 ~34 ~63 ~50 coal_block 0
fill ~33 ~63 ~47 ~36 ~63 ~47 coal_block 0
fill ~35 ~63 ~42 ~38 ~63 ~42 coal_block 0
fill ~35 ~63 ~51 ~37 ~63 ~51 coal_block 0
fill ~36 ~63 ~43 ~37 ~63 ~43 coal_block 0
fill ~38 ~63 ~50 ~41 ~63 ~50 coal_block 0
fill ~39 ~63 ~43 ~41 ~63 ~43 coal_block 0
fill ~41 ~63 ~44 ~41 ~64 ~44 coal_block 0
fill ~41 ~63 ~49 ~41 ~64 ~49 coal_block 0
fill ~41 ~63 ~64 ~43 ~63 ~64 coal_block 0
fill ~42 ~63 ~45 ~43 ~63 ~45 coal_block 0
fill ~42 ~63 ~46 ~43 ~63 ~46 coal_block 0
fill ~42 ~63 ~48 ~43 ~63 ~48 coal_block 0
setblock ~42 ~63 ~57 coal_block 0
setblock ~43 ~63 ~47 coal_block 0
fill ~43 ~63 ~63 ~43 ~81 ~63 coal_block 0
fill ~44 ~63 ~58 ~44 ~87 ~58 coal_block 0
fill ~27 ~64 ~46 ~29 ~64 ~46 coal_block 0
fill ~27 ~64 ~47 ~28 ~64 ~47 coal_block 0
fill ~28 ~64 ~45 ~29 ~64 ~45 coal_block 0
fill ~28 ~64 ~48 ~29 ~64 ~48 coal_block 0
fill ~28 ~64 ~49 ~29 ~64 ~49 coal_block 0
fill ~29 ~64 ~44 ~31 ~64 ~44 coal_block 0
fill ~30 ~64 ~50 ~31 ~64 ~50 coal_block 0
fill ~31 ~64 ~43 ~32 ~64 ~43 coal_block 0
setblock ~31 ~64 ~45 coal_block 0
fill ~32 ~64 ~51 ~37 ~64 ~51 coal_block 0
fill ~33 ~64 ~42 ~38 ~64 ~42 coal_block 0
fill ~33 ~64 ~46 ~33 ~67 ~46 coal_block 0
fill ~33 ~64 ~47 ~33 ~70 ~47 coal_block 0
fill ~36 ~64 ~58 ~36 ~72 ~58 coal_block 0
fill ~37 ~64 ~61 ~37 ~66 ~61 coal_block 0
fill ~38 ~64 ~50 ~40 ~64 ~50 coal_block 0
fill ~39 ~64 ~43 ~40 ~64 ~43 coal_block 0
fill ~39 ~64 ~63 ~39 ~68 ~63 coal_block 0
fill ~40 ~64 ~44 ~40 ~65 ~44 coal_block 0
fill ~40 ~64 ~49 ~40 ~65 ~49 coal_block 0
fill ~41 ~64 ~45 ~42 ~64 ~45 coal_block 0
fill ~41 ~64 ~46 ~42 ~64 ~46 coal_block 0
fill ~41 ~64 ~47 ~42 ~64 ~47 coal_block 0
fill ~41 ~64 ~48 ~42 ~64 ~48 coal_block 0
fill ~41 ~64 ~64 ~43 ~64 ~64 coal_block 0
fill ~42 ~64 ~56 ~42 ~86 ~56 coal_block 0
fill ~44 ~64 ~61 ~44 ~83 ~61 coal_block 0
fill ~26 ~65 ~45 ~28 ~65 ~45 coal_block 0
fill ~26 ~65 ~46 ~27 ~65 ~46 coal_block 0
fill ~26 ~65 ~47 ~27 ~65 ~47 coal_block 0
fill ~26 ~65 ~48 ~27 ~65 ~48 coal_block 0
fill ~27 ~65 ~44 ~28 ~65 ~44 coal_block 0
fill ~27 ~65 ~49 ~28 ~65 ~49 coal_block 0
fill ~28 ~65 ~50 ~29 ~65 ~50 coal_block 0
fill ~29 ~65 ~43 ~30 ~65 ~43 coal_block 0
setblock ~30 ~65 ~44 coal_block 0
fill ~30 ~65 ~51 ~37 ~65 ~51 coal_block 0
fill ~31 ~65 ~42 ~37 ~65 ~42 coal_block 0
fill ~31 ~65 ~47 ~33 ~65 ~47 coal_block 0
fill ~32 ~65 ~43 ~32 ~67 ~43 coal_block 0
fill ~32 ~65 ~44 ~32 ~65 ~45 coal_block 0
fill ~33 ~65 ~45 ~33 ~66 ~45 coal_block 0
fill ~33 ~65 ~48 ~33 ~66 ~48 coal_block 0
fill ~33 ~65 ~49 ~33 ~68 ~49 coal_block 0
fill ~33 ~65 ~50 ~33 ~66 ~50 coal_block 0
fill ~38 ~65 ~43 ~39 ~65 ~43 coal_block 0
fill ~38 ~65 ~50 ~39 ~65 ~50 coal_block 0
fill ~39 ~65 ~44 ~39 ~66 ~44 coal_block 0
fill ~39 ~65 ~49 ~39 ~66 ~49 coal_block 0
fill ~40 ~65 ~45 ~41 ~65 ~45 coal_block 0
fill ~40 ~65 ~46 ~41 ~65 ~46 coal_block 0
fill ~40 ~65 ~47 ~41 ~65 ~47 coal_block 0
fill ~40 ~65 ~48 ~41 ~65 ~48 coal_block 0
fill ~40 ~65 ~56 ~40 ~75 ~56 coal_block 0
fill ~41 ~65 ~64 ~43 ~65 ~64 coal_block 0
fill ~44 ~65 ~59 ~44 ~84 ~59 coal_block 0
fill ~44 ~65 ~60 ~44 ~83 ~60 coal_block 0
fill ~24 ~66 ~46 ~25 ~66 ~46 coal_block 0
fill ~24 ~66 ~47 ~26 ~66 ~47 coal_block 0
fill ~24 ~66 ~48 ~26 ~66 ~48 coal_block 0
fill ~25 ~66 ~45 ~27 ~66 ~45 coal_block 0
fill ~25 ~66 ~49 ~26 ~66 ~49 coal_block 0
fill ~26 ~66 ~44 ~27 ~66 ~44 coal_block 0
fill ~26 ~66 ~50 ~27 ~66 ~50 coal_block 0
fill ~27 ~66 ~43 ~29 ~66 ~43 coal_block 0
fill ~28 ~66 ~47 ~33 ~66 ~47 coal_block 0
fill ~28 ~66 ~51 ~36 ~66 ~51 coal_block 0
fill ~29 ~66 ~42 ~36 ~66 ~42 coal_block 0
fill ~29 ~66 ~50 ~29 ~67 ~50 coal_block 0
fill ~32 ~66 ~45 ~32 ~67 ~45 coal_block 0
fill ~32 ~66 ~46 ~32 ~67 ~46 coal_block 0
fill ~37 ~66 ~43 ~38 ~66 ~43 coal_block 0
fill ~37 ~66 ~50 ~38 ~66 ~50 coal_block 0
fill ~38 ~66 ~44 ~38 ~67 ~44 coal_block 0
fill ~38 ~66 ~49 ~38 ~67 ~49 coal_block 0
fill ~39 ~66 ~45 ~40 ~66 ~45 coal_block 0
fill ~39 ~66 ~46 ~40 ~66 ~46 coal_block 0
fill ~39 ~66 ~47 ~40 ~66 ~47 coal_block 0
fill ~39 ~66 ~48 ~40 ~66 ~48 coal_block 0
fill ~41 ~66 ~64 ~43 ~66 ~64 coal_block 0
fill ~43 ~66 ~62 ~43 ~80 ~62 coal_block 0
fill ~23 ~67 ~45 ~24 ~67 ~45 coal_block 0
fill ~23 ~67 ~46 ~24 ~67 ~46 coal_block 0
fill ~23 ~67 ~47 ~24 ~67 ~47 coal_block 0
fill ~23 ~67 ~48 ~24 ~67 ~48 coal_block 0
fill ~24 ~67 ~44 ~25 ~67 ~44 coal_block 0
fill ~24 ~67 ~49 ~25 ~67 ~49 coal_block 0
fill ~25 ~67 ~43 ~27 ~67 ~43 coal_block 0
fill ~25 ~67 ~50 ~26 ~67 ~50 coal_block 0
fill ~26 ~67 ~51 ~29 ~67 ~51 coal_block 0
setblock ~27 ~67 ~44 coal_block 0
fill ~27 ~67 ~47 ~29 ~67 ~47 coal_block 0
fill ~28 ~67 ~42 ~35 ~67 ~42 coal_block 0
fill ~29 ~67 ~52 ~32 ~67 ~52 coal_block 0
setblock ~31 ~67 ~45 coal_block 0
fill ~31 ~67 ~47 ~33 ~67 ~47 coal_block 0
fill ~32 ~67 ~51 ~35 ~67 ~51 coal_block 0
fill ~36 ~67 ~43 ~37 ~67 ~43 coal_block 0
fill ~36 ~67 ~50 ~37 ~67 ~50 coal_block 0
fill ~37 ~67 ~44 ~37 ~68 ~44 coal_block 0
fill ~37 ~67 ~49 ~37 ~68 ~49 coal_block 0
fill ~37 ~67 ~57 ~37 ~74 ~57 coal_block 0
fill ~38 ~67 ~45 ~39 ~67 ~45 coal_block 0
fill ~38 ~67 ~46 ~39 ~67 ~46 coal_block 0
fill ~38 ~67 ~47 ~39 ~67 ~47 coal_block 0
fill ~38 ~67 ~48 ~39 ~67 ~48 coal_block 0
fill ~39 ~67 ~60 ~45 ~67 ~60 coal_block 0
fill ~41 ~67 ~64 ~43 ~67 ~64 coal_block 0
fill ~44 ~67 ~62 ~44 ~84 ~62 coal_block 0
fill ~21 ~68 ~45 ~23 ~68 ~45 coal_block 0
fill ~21 ~68 ~46 ~22 ~68 ~46 coal_block 0
fill ~21 ~68 ~47 ~22 ~68 ~47 coal_block 0
fill ~21 ~68 ~48 ~22 ~68 ~48 coal_block 0
fill ~22 ~68 ~44 ~23 ~68 ~44 coal_block 0
fill ~22 ~68 ~49 ~23 ~68 ~49 coal_block 0
fill ~23 ~68 ~50 ~24 ~68 ~50 coal_block 0
fill ~24 ~68 ~43 ~25 ~68 ~43 coal_block 0
fill ~25 ~68 ~47 ~29 ~68 ~47 coal_block 0
fill ~25 ~68 ~51 ~27 ~68 ~51 coal_block 0
fill ~26 ~68 ~42 ~28 ~68 ~42 coal_block 0
fill ~28 ~68 ~52 ~31 ~68 ~52 coal_block 0
fill ~29 ~68 ~41 ~31 ~68 ~41 coal_block 0
fill ~31 ~68 ~42 ~35 ~68 ~42 coal_block 0
fill ~32 ~68 ~51 ~35 ~68 ~51 coal_block 0
fill ~35 ~68 ~43 ~36 ~68 ~43 coal_block 0
fill ~35 ~68 ~50 ~36 ~68 ~50 coal_block 0
fill ~35 ~68 ~60 ~35 ~71 ~60 coal_block 0
fill ~36 ~68 ~44 ~36 ~69 ~44 coal_block 0
fill ~36 ~68 ~49 ~36 ~69 ~49 coal_block 0
fill ~37 ~68 ~45 ~37 ~68 ~49 coal_block 0
fill ~38 ~68 ~46 ~38 ~67 ~46 coal_block 0
fill ~38 ~68 ~47 ~38 ~67 ~47 coal_block 0
fill ~38 ~68 ~48 ~38 ~67 ~48 coal_block 0
fill ~39 ~68 ~60 ~40 ~68 ~60 coal_block 0
fill ~41 ~68 ~64 ~43 ~68 ~64 coal_block 0
fill ~43 ~68 ~56 ~43 ~93 ~56 coal_block 0
fill ~19 ~69 ~46 ~20 ~69 ~46 coal_block 0
fill ~19 ~69 ~47 ~20 ~69 ~47 coal_block 0
fill ~19 ~69 ~48 ~20 ~69 ~48 coal_block 0
fill ~20 ~69 ~45 ~21 ~69 ~45 coal_block 0
fill ~20 ~69 ~49 ~21 ~69 ~49 coal_block 0
fill ~21 ~69 ~44 ~22 ~69 ~44 coal_block 0
fill ~21 ~69 ~50 ~23 ~69 ~50 coal_block 0
fill ~22 ~69 ~43 ~23 ~69 ~43 coal_block 0
fill ~23 ~69 ~51 ~25 ~69 ~51 coal_block 0
fill ~24 ~69 ~42 ~27 ~69 ~42 coal_block 0
fill ~25 ~69 ~47 ~27 ~69 ~47 coal_block 0
fill ~26 ~69 ~52 ~31 ~69 ~52 coal_block 0
fill ~28 ~69 ~41 ~30 ~69 ~41 coal_block 0
fill ~31 ~69 ~42 ~34 ~69 ~42 coal_block 0
fill ~32 ~69 ~51 ~34 ~69 ~51 coal_block 0
fill ~34 ~69 ~43 ~35 ~69 ~43 coal_block 0
fill ~34 ~69 ~50 ~35 ~69 ~50 coal_block 0
fill ~35 ~69 ~44 ~35 ~70 ~44 coal_block 0
fill ~35 ~69 ~49 ~35 ~71 ~49 coal_block 0
fill ~35 ~69 ~59 ~35 ~72 ~59 coal_block 0
fill ~35 ~69 ~61 ~35 ~72 ~61 coal_block 0
fill ~36 ~69 ~45 ~36 ~70 ~45 coal_block 0
fill ~36 ~69 ~46 ~37 ~69 ~46 coal_block 0
fill ~36 ~69 ~47 ~37 ~69 ~47 coal_block 0
fill ~36 ~69 ~48 ~37 ~69 ~48 coal_block 0
fill ~38 ~69 ~58 ~38 ~70 ~58 coal_block 0
fill ~38 ~69 ~59 ~38 ~70 ~59 coal_block 0
fill ~38 ~69 ~60 ~45 ~69 ~60 coal_block 0
fill ~38 ~69 ~61 ~38 ~69 ~57 coal_block 0
fill ~39 ~69 ~56 ~39 ~75 ~56 coal_block 0
fill ~41 ~69 ~64 ~42 ~69 ~64 coal_block 0
fill ~17 ~70 ~46 ~18 ~70 ~46 coal_block 0
fill ~17 ~70 ~47 ~18 ~70 ~47 coal_block 0
fill ~17 ~70 ~48 ~18 ~70 ~48 coal_block 0
fill ~18 ~70 ~45 ~19 ~70 ~45 coal_block 0
fill ~18 ~70 ~49 ~19 ~70 ~49 coal_block 0
fill ~19 ~70 ~44 ~20 ~70 ~44 coal_block 0
fill ~19 ~70 ~50 ~21 ~70 ~50 coal_block 0
fill ~21 ~70 ~43 ~22 ~70 ~43 coal_block 0
fill ~22 ~70 ~51 ~23 ~70 ~51 coal_block 0
fill ~23 ~70 ~42 ~25 ~70 ~42 coal_block 0
fill ~23 ~70 ~47 ~26 ~70 ~47 coal_block 0
fill ~24 ~70 ~52 ~30 ~70 ~52 coal_block 0
fill ~26 ~70 ~41 ~30 ~70 ~41 coal_block 0
fill ~31 ~70 ~42 ~33 ~70 ~42 coal_block 0
fill ~31 ~70 ~51 ~33 ~70 ~51 coal_block 0
fill ~33 ~70 ~43 ~34 ~70 ~43 coal_block 0
fill ~33 ~70 ~50 ~34 ~70 ~50 coal_block 0
fill ~34 ~70 ~44 ~34 ~71 ~44 coal_block 0
fill ~35 ~70 ~45 ~35 ~71 ~45 coal_block 0
fill ~35 ~70 ~46 ~36 ~70 ~46 coal_block 0
fill ~35 ~70 ~47 ~36 ~70 ~47 coal_block 0
fill ~35 ~70 ~48 ~36 ~70 ~48 coal_block 0
fill ~36 ~70 ~57 ~36 ~75 ~57 coal_block 0
fill ~36 ~70 ~59 ~36 ~71 ~59 coal_block 0
fill ~38 ~70 ~60 ~41 ~70 ~60 coal_block 0
fill ~41 ~70 ~64 ~42 ~70 ~64 coal_block 0
fill ~15 ~71 ~46 ~17 ~71 ~46 coal_block 0
fill ~15 ~71 ~47 ~16 ~71 ~47 coal_block 0
fill ~15 ~71 ~48 ~16 ~71 ~48 coal_block 0
fill ~16 ~71 ~45 ~17 ~71 ~45 coal_block 0
fill ~16 ~71 ~49 ~17 ~71 ~49 coal_block 0
fill ~17 ~71 ~44 ~19 ~71 ~44 coal_block 0
fill ~18 ~71 ~50 ~19 ~71 ~50 coal_block 0
fill ~19 ~71 ~43 ~21 ~71 ~43 coal_block 0
fill ~20 ~71 ~51 ~22 ~71 ~51 coal_block 0
fill ~22 ~71 ~42 ~24 ~71 ~42 coal_block 0
fill ~23 ~71 ~47 ~25 ~71 ~47 coal_block 0
fill ~23 ~71 ~52 ~29 ~71 ~52 coal_block 0
fill ~25 ~71 ~41 ~29 ~71 ~41 coal_block 0
fill ~30 ~71 ~42 ~32 ~71 ~42 coal_block 0
fill ~30 ~71 ~51 ~32 ~71 ~51 coal_block 0
fill ~32 ~71 ~43 ~33 ~71 ~43 coal_block 0
fill ~32 ~71 ~50 ~34 ~71 ~50 coal_block 0
fill ~33 ~71 ~44 ~33 ~72 ~44 coal_block 0
fill ~34 ~71 ~45 ~34 ~72 ~45 coal_block 0
fill ~34 ~71 ~48 ~35 ~71 ~48 coal_block 0
fill ~34 ~71 ~49 ~34 ~72 ~49 coal_block 0
fill ~35 ~71 ~46 ~35 ~72 ~46 coal_block 0
fill ~35 ~71 ~47 ~35 ~72 ~47 coal_block 0
fill ~35 ~71 ~58 ~35 ~76 ~58 coal_block 0
fill ~35 ~71 ~62 ~35 ~73 ~62 coal_block 0
fill ~36 ~71 ~63 ~36 ~75 ~63 coal_block 0
fill ~38 ~71 ~56 ~38 ~77 ~56 coal_block 0
fill ~38 ~71 ~64 ~38 ~75 ~64 coal_block 0
fill ~41 ~71 ~60 ~41 ~160 ~60 coal_block 0
fill ~41 ~71 ~64 ~42 ~71 ~64 coal_block 0
fill ~12 ~72 ~47 ~14 ~72 ~47 coal_block 0
fill ~12 ~72 ~48 ~14 ~72 ~48 coal_block 0
fill ~13 ~72 ~46 ~14 ~72 ~46 coal_block 0
fill ~13 ~72 ~49 ~15 ~72 ~49 coal_block 0
fill ~14 ~72 ~45 ~16 ~72 ~45 coal_block 0
fill ~16 ~72 ~44 ~17 ~72 ~44 coal_block 0
fill ~16 ~72 ~50 ~17 ~72 ~50 coal_block 0
fill ~18 ~72 ~43 ~19 ~72 ~43 coal_block 0
fill ~18 ~72 ~51 ~20 ~72 ~51 coal_block 0
fill ~20 ~72 ~42 ~24 ~72 ~42 coal_block 0
fill ~21 ~72 ~47 ~23 ~72 ~47 coal_block 0
fill ~21 ~72 ~52 ~29 ~72 ~52 coal_block 0
fill ~25 ~72 ~41 ~27 ~72 ~41 coal_block 0
fill ~28 ~72 ~42 ~31 ~72 ~42 coal_block 0
fill ~30 ~72 ~51 ~31 ~72 ~51 coal_block 0
fill ~31 ~72 ~43 ~32 ~72 ~43 coal_block 0
fill ~32 ~72 ~50 ~33 ~72 ~50 coal_block 0
fill ~33 ~72 ~45 ~33 ~73 ~45 coal_block 0
fill ~33 ~72 ~49 ~33 ~73 ~49 coal_block 0
fill ~34 ~72 ~46 ~34 ~73 ~46 coal_block 0
fill ~34 ~72 ~47 ~34 ~73 ~47 coal_block 0
fill ~34 ~72 ~48 ~34 ~71 ~48 coal_block 0
fill ~34 ~72 ~60 ~34 ~75 ~60 coal_block 0
fill ~36 ~72 ~62 ~36 ~73 ~62 coal_block 0
fill ~41 ~72 ~64 ~42 ~72 ~64 coal_block 0
fill ~10 ~73 ~47 ~11 ~73 ~47 coal_block 0
fill ~10 ~73 ~48 ~11 ~73 ~48 coal_block 0
fill ~11 ~73 ~46 ~12 ~73 ~46 coal_block 0
fill ~11 ~73 ~49 ~12 ~73 ~49 coal_block 0
fill ~12 ~73 ~45 ~14 ~73 ~45 coal_block 0
fill ~13 ~73 ~50 ~15 ~73 ~50 coal_block 0
fill ~14 ~73 ~44 ~16 ~73 ~44 coal_block 0
fill ~16 ~73 ~51 ~19 ~73 ~51 coal_block 0
fill ~17 ~73 ~43 ~18 ~73 ~43 coal_block 0
fill ~19 ~73 ~42 ~25 ~73 ~42 coal_block 0
fill ~20 ~73 ~47 ~21 ~73 ~47 coal_block 0
fill ~20 ~73 ~52 ~27 ~73 ~52 coal_block 0
fill ~21 ~73 ~44 ~21 ~74 ~44 coal_block 0
fill ~21 ~73 ~45 ~21 ~74 ~45 coal_block 0
fill ~21 ~73 ~46 ~21 ~73 ~44 coal_block 0
fill ~21 ~73 ~48 ~21 ~74 ~48 coal_block 0
fill ~21 ~73 ~49 ~21 ~73 ~52 coal_block 0
setblock ~26 ~73 ~41 coal_block 0
fill ~27 ~73 ~42 ~30 ~73 ~42 coal_block 0
fill ~28 ~73 ~51 ~30 ~73 ~51 coal_block 0
fill ~31 ~73 ~43 ~31 ~72 ~43 coal_block 0
fill ~31 ~73 ~50 ~32 ~73 ~50 coal_block 0
fill ~32 ~73 ~44 ~32 ~73 ~45 coal_block 0
fill ~32 ~73 ~49 ~32 ~74 ~49 coal_block 0
fill ~33 ~73 ~46 ~33 ~74 ~46 coal_block 0
fill ~33 ~73 ~47 ~33 ~74 ~47 coal_block 0
fill ~33 ~73 ~48 ~33 ~73 ~45 coal_block 0
fill ~34 ~73 ~59 ~34 ~76 ~59 coal_block 0
fill ~34 ~73 ~61 ~34 ~75 ~61 coal_block 0
setblock ~35 ~73 ~60 coal_block 0
fill ~37 ~73 ~64 ~37 ~76 ~64 coal_block 0
fill ~41 ~73 ~64 ~42 ~73 ~64 coal_block 0
fill ~9 ~74 ~47 ~10 ~74 ~47 coal_block 0
fill ~9 ~74 ~48 ~9 ~76 ~48 coal_block 0
setblock ~10 ~74 ~46 coal_block 0
setblock ~10 ~74 ~49 coal_block 0
fill ~11 ~74 ~45 ~12 ~74 ~45 coal_block 0
fill ~11 ~74 ~50 ~13 ~74 ~50 coal_block 0
fill ~13 ~74 ~44 ~14 ~74 ~44 coal_block 0
fill ~14 ~74 ~45 ~15 ~74 ~45 coal_block 0
fill ~14 ~74 ~51 ~18 ~74 ~51 coal_block 0
fill ~15 ~74 ~43 ~17 ~74 ~43 coal_block 0
fill ~15 ~74 ~46 ~16 ~74 ~46 coal_block 0
fill ~15 ~74 ~50 ~16 ~74 ~50 coal_block 0
fill ~16 ~74 ~47 ~16 ~75 ~47 coal_block 0
fill ~16 ~74 ~48 ~17 ~74 ~48 coal_block 0
fill ~16 ~74 ~49 ~16 ~75 ~49 coal_block 0
fill ~18 ~74 ~42 ~29 ~74 ~42 coal_block 0
fill ~18 ~74 ~47 ~20 ~74 ~47 coal_block 0
fill ~19 ~74 ~52 ~26 ~74 ~52 coal_block 0
fill ~20 ~74 ~46 ~20 ~75 ~46 coal_block 0
fill ~27 ~74 ~51 ~29 ~74 ~51 coal_block 0
fill ~29 ~74 ~43 ~30 ~74 ~43 coal_block 0
fill ~29 ~74 ~50 ~30 ~74 ~50 coal_block 0
fill ~30 ~74 ~44 ~31 ~74 ~44 coal_block 0
fill ~31 ~74 ~45 ~32 ~74 ~45 coal_block 0
fill ~31 ~74 ~48 ~32 ~74 ~48 coal_block 0
fill ~31 ~74 ~49 ~31 ~74 ~48 coal_block 0
fill ~32 ~74 ~46 ~32 ~74 ~49 coal_block 0
fill ~34 ~74 ~62 ~34 ~76 ~62 coal_block 0
fill ~35 ~74 ~57 ~35 ~80 ~57 coal_block 0
setblock ~35 ~74 ~59 coal_block 0
fill ~35 ~74 ~61 ~35 ~75 ~61 coal_block 0
fill ~35 ~74 ~63 ~35 ~77 ~63 coal_block 0
fill ~36 ~74 ~64 ~36 ~77 ~64 coal_block 0
fill ~37 ~74 ~56 ~37 ~80 ~56 coal_block 0
fill ~39 ~74 ~65 ~41 ~74 ~65 coal_block 0
fill ~42 ~74 ~64 ~43 ~74 ~64 coal_block 0
fill ~8 ~75 ~48 ~8 ~78 ~48 coal_block 0
fill ~9 ~75 ~46 ~9 ~79 ~46 coal_block 0
fill ~9 ~75 ~47 ~10 ~75 ~47 coal_block 0
fill ~9 ~75 ~49 ~9 ~77 ~49 coal_block 0
fill ~10 ~75 ~45 ~11 ~75 ~45 coal_block 0
fill ~10 ~75 ~50 ~11 ~75 ~50 coal_block 0
fill ~12 ~75 ~44 ~15 ~75 ~44 coal_block 0
fill ~12 ~75 ~51 ~17 ~75 ~51 coal_block 0
fill ~14 ~75 ~43 ~17 ~75 ~43 coal_block 0
fill ~15 ~75 ~45 ~16 ~75 ~45 coal_block 0
fill ~16 ~75 ~46 ~16 ~76 ~46 coal_block 0
fill ~16 ~75 ~48 ~16 ~74 ~48 coal_block 0
fill ~16 ~75 ~50 ~16 ~76 ~50 coal_block 0
fill ~17 ~75 ~47 ~17 ~77 ~47 coal_block 0
fill ~17 ~75 ~49 ~17 ~77 ~49 coal_block 0
fill ~18 ~75 ~42 ~28 ~75 ~42 coal_block 0
fill ~18 ~75 ~52 ~24 ~75 ~52 coal_block 0
fill ~21 ~75 ~43 ~21 ~77 ~43 coal_block 0
fill ~25 ~75 ~51 ~28 ~75 ~51 coal_block 0
fill ~28 ~75 ~43 ~29 ~75 ~43 coal_block 0
fill ~28 ~75 ~50 ~29 ~75 ~50 coal_block 0
fill ~29 ~75 ~44 ~30 ~75 ~44 coal_block 0
fill ~29 ~75 ~49 ~30 ~75 ~49 coal_block 0
fill ~30 ~75 ~45 ~31 ~75 ~45 coal_block 0
fill ~30 ~75 ~46 ~31 ~75 ~46 coal_block 0
fill ~30 ~75 ~48 ~31 ~75 ~48 coal_block 0
setblock ~31 ~75 ~47 coal_block 0
fill ~34 ~75 ~58 ~34 ~77 ~58 coal_block 0
setblock ~35 ~75 ~62 coal_block 0
fill ~36 ~75 ~56 ~36 ~86 ~56 coal_block 0
fill ~38 ~75 ~65 ~41 ~75 ~65 coal_block 0
fill ~42 ~75 ~64 ~43 ~75 ~64 coal_block 0
fill ~8 ~76 ~47 ~9 ~76 ~47 coal_block 0
fill ~8 ~76 ~49 ~8 ~77 ~49 coal_block 0
fill ~9 ~76 ~45 ~10 ~76 ~45 coal_block 0
fill ~9 ~76 ~50 ~10 ~76 ~50 coal_block 0
fill ~11 ~76 ~44 ~15 ~76 ~44 coal_block 0
fill ~11 ~76 ~51 ~19 ~76 ~51 coal_block 0
fill ~14 ~76 ~43 ~18 ~76 ~43 coal_block 0
fill ~15 ~76 ~45 ~16 ~76 ~45 coal_block 0
fill ~17 ~76 ~46 ~17 ~78 ~46 coal_block 0
fill ~17 ~76 ~48 ~18 ~76 ~48 coal_block 0
fill ~17 ~76 ~50 ~17 ~77 ~50 coal_block 0
setblock ~18 ~76 ~49 coal_block 0
fill ~18 ~76 ~52 ~21 ~76 ~52 coal_block 0
fill ~19 ~76 ~42 ~24 ~76 ~42 coal_block 0
fill ~20 ~76 ~50 ~21 ~76 ~50 coal_block 0
fill ~21 ~76 ~51 ~26 ~76 ~51 coal_block 0
setblock ~23 ~76 ~50 coal_block 0
fill ~25 ~76 ~43 ~28 ~76 ~43 coal_block 0
fill ~27 ~76 ~50 ~28 ~76 ~50 coal_block 0
fill ~28 ~76 ~44 ~29 ~76 ~44 coal_block 0
fill ~28 ~76 ~49 ~29 ~76 ~49 coal_block 0
fill ~29 ~76 ~45 ~30 ~76 ~45 coal_block 0
fill ~29 ~76 ~46 ~30 ~76 ~46 coal_block 0
fill ~29 ~76 ~47 ~30 ~76 ~47 coal_block 0
fill ~29 ~76 ~48 ~30 ~76 ~48 coal_block 0
fill ~33 ~76 ~60 ~33 ~81 ~60 coal_block 0
fill ~33 ~76 ~61 ~33 ~80 ~61 coal_block 0
fill ~34 ~76 ~63 ~34 ~80 ~63 coal_block 0
fill ~35 ~76 ~64 ~35 ~80 ~64 coal_block 0
fill ~37 ~76 ~65 ~42 ~76 ~65 coal_block 0
fill ~39 ~76 ~55 ~40 ~76 ~55 coal_block 0
fill ~42 ~76 ~64 ~43 ~76 ~64 coal_block 0
fill ~8 ~77 ~47 ~8 ~76 ~47 coal_block 0
fill ~9 ~77 ~45 ~10 ~77 ~45 coal_block 0
fill ~9 ~77 ~50 ~10 ~77 ~50 coal_block 0
fill ~11 ~77 ~44 ~16 ~77 ~44 coal_block 0
fill ~11 ~77 ~51 ~24 ~77 ~51 coal_block 0
fill ~13 ~77 ~43 ~25 ~77 ~43 coal_block 0
fill ~16 ~77 ~45 ~17 ~77 ~45 coal_block 0
fill ~18 ~77 ~47 ~18 ~80 ~47 coal_block 0
fill ~18 ~77 ~48 ~18 ~78 ~48 coal_block 0
fill ~18 ~77 ~50 ~18 ~79 ~50 coal_block 0
fill ~21 ~77 ~44 ~21 ~78 ~44 coal_block 0
fill ~21 ~77 ~45 ~21 ~79 ~45 coal_block 0
fill ~25 ~77 ~44 ~27 ~77 ~44 coal_block 0
fill ~25 ~77 ~50 ~26 ~77 ~50 coal_block 0
fill ~26 ~77 ~49 ~28 ~77 ~49 coal_block 0
fill ~27 ~77 ~45 ~28 ~77 ~45 coal_block 0
fill ~27 ~77 ~48 ~28 ~77 ~48 coal_block 0
fill ~28 ~77 ~46 ~29 ~77 ~46 coal_block 0
fill ~28 ~77 ~47 ~29 ~77 ~47 coal_block 0
fill ~33 ~77 ~59 ~33 ~81 ~59 coal_block 0
fill ~33 ~77 ~62 ~33 ~80 ~62 coal_block 0
fill ~34 ~77 ~57 ~34 ~112 ~57 coal_block 0
fill ~34 ~77 ~60 ~34 ~78 ~60 coal_block 0
fill ~34 ~77 ~61 ~34 ~77 ~60 coal_block 0
fill ~35 ~77 ~56 ~35 ~103 ~56 coal_block 0
fill ~36 ~77 ~65 ~38 ~77 ~65 coal_block 0
fill ~38 ~77 ~55 ~40 ~77 ~55 coal_block 0
fill ~39 ~77 ~66 ~40 ~77 ~66 coal_block 0
fill ~41 ~77 ~65 ~42 ~77 ~65 coal_block 0
fill ~42 ~77 ~64 ~43 ~77 ~64 coal_block 0
fill ~43 ~77 ~58 ~43 ~79 ~58 coal_block 0
fill ~9 ~78 ~47 ~9 ~80 ~47 coal_block 0
fill ~9 ~78 ~48 ~9 ~81 ~48 coal_block 0
fill ~9 ~78 ~50 ~10 ~78 ~50 coal_block 0
fill ~10 ~78 ~45 ~11 ~78 ~45 coal_block 0
fill ~11 ~78 ~44 ~17 ~78 ~44 coal_block 0
fill ~11 ~78 ~51 ~21 ~78 ~51 coal_block 0
fill ~13 ~78 ~43 ~20 ~78 ~43 coal_block 0
fill ~17 ~78 ~45 ~17 ~80 ~45 coal_block 0
fill ~18 ~78 ~46 ~18 ~80 ~46 coal_block 0
fill ~18 ~78 ~49 ~19 ~78 ~49 coal_block 0
fill ~19 ~78 ~47 ~19 ~78 ~49 coal_block 0
fill ~21 ~78 ~49 ~22 ~78 ~49 coal_block 0
fill ~22 ~78 ~44 ~24 ~78 ~44 coal_block 0
fill ~22 ~78 ~45 ~22 ~79 ~45 coal_block 0
fill ~22 ~78 ~46 ~22 ~79 ~46 coal_block 0
fill ~22 ~78 ~50 ~24 ~78 ~50 coal_block 0
fill ~24 ~78 ~45 ~26 ~78 ~45 coal_block 0
fill ~24 ~78 ~49 ~26 ~78 ~49 coal_block 0
fill ~25 ~78 ~46 ~27 ~78 ~46 coal_block 0
fill ~25 ~78 ~48 ~27 ~78 ~48 coal_block 0
fill ~26 ~78 ~47 ~27 ~78 ~47 coal_block 0
fill ~33 ~78 ~58 ~33 ~86 ~58 coal_block 0
fill ~34 ~78 ~59 ~34 ~79 ~59 coal_block 0
setblock ~34 ~78 ~62 coal_block 0
fill ~34 ~78 ~64 ~34 ~83 ~64 coal_block 0
fill ~36 ~78 ~65 ~37 ~78 ~65 coal_block 0
fill ~38 ~78 ~55 ~41 ~78 ~55 coal_block 0
fill ~38 ~78 ~66 ~41 ~78 ~66 coal_block 0
fill ~41 ~78 ~65 ~42 ~78 ~65 coal_block 0
fill ~42 ~78 ~64 ~43 ~78 ~64 coal_block 0
fill ~44 ~78 ~63 ~44 ~87 ~63 coal_block 0
fill ~9 ~79 ~49 ~9 ~80 ~49 coal_block 0
fill ~9 ~79 ~50 ~10 ~79 ~50 coal_block 0
fill ~10 ~79 ~45 ~11 ~79 ~45 coal_block 0
fill ~10 ~79 ~46 ~10 ~83 ~46 coal_block 0
fill ~11 ~79 ~44 ~20 ~79 ~44 coal_block 0
fill ~11 ~79 ~51 ~18 ~79 ~51 coal_block 0
fill ~13 ~79 ~43 ~17 ~79 ~43 coal_block 0
fill ~17 ~79 ~50 ~17 ~80 ~50 coal_block 0
fill ~18 ~79 ~45 ~23 ~79 ~45 coal_block 0
fill ~19 ~79 ~46 ~19 ~81 ~46 coal_block 0
fill ~19 ~79 ~48 ~19 ~80 ~48 coal_block 0
fill ~19 ~79 ~49 ~19 ~80 ~49 coal_block 0
fill ~19 ~79 ~50 ~21 ~79 ~50 coal_block 0
fill ~21 ~79 ~49 ~23 ~79 ~49 coal_block 0
fill ~22 ~79 ~47 ~25 ~79 ~47 coal_block 0
fill ~22 ~79 ~48 ~24 ~79 ~48 coal_block 0
fill ~23 ~79 ~46 ~24 ~79 ~46 coal_block 0
fill ~33 ~79 ~63 ~33 ~82 ~63 coal_block 0
fill ~34 ~79 ~58 ~34 ~82 ~58 coal_block 0
fill ~35 ~79 ~65 ~37 ~79 ~65 coal_block 0
fill ~38 ~79 ~55 ~41 ~79 ~55 coal_block 0
fill ~38 ~79 ~66 ~41 ~79 ~66 coal_block 0
fill ~41 ~79 ~65 ~42 ~79 ~65 coal_block 0
fill ~42 ~79 ~64 ~43 ~79 ~64 coal_block 0
fill ~10 ~80 ~45 ~19 ~80 ~45 coal_block 0
fill ~10 ~80 ~47 ~10 ~84 ~47 coal_block 0
fill ~10 ~80 ~48 ~11 ~80 ~48 coal_block 0
fill ~10 ~80 ~49 ~10 ~83 ~49 coal_block 0
fill ~10 ~80 ~50 ~11 ~80 ~50 coal_block 0
fill ~11 ~80 ~44 ~18 ~80 ~44 coal_block 0
fill ~11 ~80 ~51 ~14 ~80 ~51 coal_block 0
fill ~13 ~80 ~43 ~15 ~80 ~43 coal_block 0
fill ~14 ~80 ~46 ~21 ~80 ~46 coal_block 0
fill ~14 ~80 ~50 ~17 ~80 ~50 coal_block 0
fill ~15 ~80 ~52 ~16 ~80 ~52 coal_block 0
fill ~17 ~80 ~49 ~20 ~80 ~49 coal_block 0
fill ~17 ~80 ~51 ~19 ~80 ~51 coal_block 0
fill ~18 ~80 ~48 ~18 ~81 ~48 coal_block 0
fill ~19 ~80 ~47 ~22 ~80 ~47 coal_block 0
fill ~19 ~80 ~50 ~19 ~81 ~50 coal_block 0
fill ~20 ~80 ~48 ~22 ~80 ~48 coal_block 0
fill ~35 ~80 ~65 ~36 ~80 ~65 coal_block 0
fill ~37 ~80 ~55 ~41 ~80 ~55 coal_block 0
fill ~37 ~80 ~66 ~41 ~80 ~66 coal_block 0
fill ~42 ~80 ~65 ~43 ~80 ~65 coal_block 0
fill ~43 ~80 ~64 ~43 ~83 ~64 coal_block 0
fill ~10 ~81 ~50 ~13 ~81 ~50 coal_block 0
fill ~11 ~81 ~45 ~12 ~81 ~45 coal_block 0
fill ~11 ~81 ~46 ~13 ~81 ~46 coal_block 0
fill ~11 ~81 ~47 ~11 ~81 ~45 coal_block 0
fill ~12 ~81 ~44 ~14 ~81 ~44 coal_block 0
fill ~12 ~81 ~51 ~14 ~81 ~51 coal_block 0
fill ~13 ~81 ~43 ~17 ~81 ~43 coal_block 0
fill ~13 ~81 ~47 ~17 ~81 ~47 coal_block 0
fill ~13 ~81 ~49 ~17 ~81 ~49 coal_block 0
fill ~14 ~81 ~48 ~18 ~81 ~48 coal_block 0
fill ~15 ~81 ~52 ~17 ~81 ~52 coal_block 0
fill ~18 ~81 ~44 ~19 ~81 ~44 coal_block 0
fill ~18 ~81 ~51 ~19 ~81 ~51 coal_block 0
fill ~19 ~81 ~45 ~19 ~82 ~45 coal_block 0
fill ~20 ~81 ~46 ~20 ~82 ~46 coal_block 0
fill ~20 ~81 ~47 ~20 ~82 ~47 coal_block 0
fill ~20 ~81 ~48 ~21 ~81 ~48 coal_block 0
fill ~20 ~81 ~49 ~20 ~82 ~49 coal_block 0
fill ~20 ~81 ~50 ~20 ~83 ~50 coal_block 0
fill ~32 ~81 ~60 ~32 ~88 ~60 coal_block 0
fill ~32 ~81 ~61 ~32 ~86 ~61 coal_block 0
fill ~32 ~81 ~62 ~32 ~87 ~62 coal_block 0
fill ~33 ~81 ~64 ~33 ~87 ~64 coal_block 0
fill ~34 ~81 ~65 ~36 ~81 ~65 coal_block 0
fill ~36 ~81 ~66 ~38 ~81 ~66 coal_block 0
fill ~37 ~81 ~55 ~41 ~81 ~55 coal_block 0
fill ~39 ~81 ~67 ~40 ~81 ~67 coal_block 0
fill ~41 ~81 ~66 ~42 ~81 ~66 coal_block 0
fill ~42 ~81 ~65 ~43 ~81 ~65 coal_block 0
fill ~45 ~81 ~60 ~45 ~89 ~60 coal_block 0
fill ~45 ~81 ~61 ~45 ~90 ~61 coal_block 0
fill ~10 ~82 ~48 ~10 ~84 ~48 coal_block 0
fill ~11 ~82 ~45 ~12 ~82 ~45 coal_block 0
fill ~11 ~82 ~46 ~12 ~82 ~46 coal_block 0
fill ~11 ~82 ~49 ~12 ~82 ~49 coal_block 0
fill ~11 ~82 ~50 ~11 ~84 ~50 coal_block 0
fill ~12 ~82 ~44 ~14 ~82 ~44 coal_block 0
fill ~12 ~82 ~51 ~13 ~82 ~51 coal_block 0
setblock ~13 ~82 ~48 coal_block 0
fill ~14 ~82 ~43 ~18 ~82 ~43 coal_block 0
fill ~14 ~82 ~52 ~18 ~82 ~52 coal_block 0
fill ~16 ~82 ~48 ~16 ~83 ~48 coal_block 0
fill ~18 ~82 ~44 ~19 ~82 ~44 coal_block 0
fill ~19 ~82 ~51 ~20 ~82 ~51 coal_block 0
fill ~20 ~82 ~45 ~20 ~83 ~45 coal_block 0
fill ~21 ~82 ~46 ~21 ~84 ~46 coal_block 0
fill ~21 ~82 ~47 ~21 ~83 ~47 coal_block 0
fill ~21 ~82 ~48 ~21 ~83 ~48 coal_block 0
fill ~21 ~82 ~49 ~21 ~83 ~49 coal_block 0
fill ~21 ~82 ~50 ~21 ~84 ~50 coal_block 0
fill ~32 ~82 ~59 ~32 ~104 ~59 coal_block 0
fill ~33 ~82 ~61 ~33 ~82 ~64 coal_block 0
fill ~34 ~82 ~65 ~35 ~82 ~65 coal_block 0
fill ~36 ~82 ~66 ~37 ~82 ~66 coal_block 0
fill ~37 ~82 ~55 ~41 ~82 ~55 coal_block 0
fill ~38 ~82 ~67 ~40 ~82 ~67 coal_block 0
fill ~41 ~82 ~66 ~42 ~82 ~66 coal_block 0
fill ~42 ~82 ~65 ~43 ~82 ~65 coal_block 0
fill ~44 ~82 ~64 ~44 ~88 ~64 coal_block 0
fill ~45 ~82 ~59 ~45 ~90 ~59 coal_block 0
fill ~45 ~82 ~62 ~45 ~89 ~62 coal_block 0
fill ~11 ~83 ~45 ~13 ~83 ~45 coal_block 0
fill ~11 ~83 ~46 ~11 ~86 ~46 coal_block 0
fill ~11 ~83 ~47 ~11 ~86 ~47 coal_block 0
fill ~11 ~83 ~48 ~12 ~83 ~48 coal_block 0
fill ~12 ~83 ~44 ~14 ~83 ~44 coal_block 0
fill ~12 ~83 ~50 ~13 ~83 ~50 coal_block 0
fill ~12 ~83 ~51 ~13 ~83 ~51 coal_block 0
fill ~14 ~83 ~43 ~19 ~83 ~43 coal_block 0
fill ~14 ~83 ~52 ~19 ~83 ~52 coal_block 0
fill ~17 ~83 ~48 ~17 ~84 ~48 coal_block 0
fill ~19 ~83 ~44 ~20 ~83 ~44 coal_block 0
fill ~19 ~83 ~51 ~20 ~83 ~51 coal_block 0
fill ~21 ~83 ~45 ~21 ~84 ~45 coal_block 0
fill ~22 ~83 ~47 ~22 ~84 ~47 coal_block 0
fill ~22 ~83 ~48 ~22 ~84 ~48 coal_block 0
fill ~22 ~83 ~49 ~22 ~85 ~49 coal_block 0
fill ~32 ~83 ~63 ~32 ~87 ~63 coal_block 0
fill ~33 ~83 ~57 ~33 ~98 ~57 coal_block 0
setblock ~33 ~83 ~60 coal_block 0
fill ~33 ~83 ~62 ~33 ~84 ~62 coal_block 0
fill ~34 ~83 ~56 ~34 ~96 ~56 coal_block 0
fill ~34 ~83 ~65 ~35 ~83 ~65 coal_block 0
fill ~35 ~83 ~66 ~37 ~83 ~66 coal_block 0
fill ~37 ~83 ~55 ~42 ~83 ~55 coal_block 0
fill ~38 ~83 ~67 ~41 ~83 ~67 coal_block 0
fill ~42 ~83 ~66 ~42 ~85 ~66 coal_block 0
fill ~43 ~83 ~65 ~43 ~86 ~65 coal_block 0
fill ~11 ~84 ~48 ~11 ~86 ~48 coal_block 0
fill ~11 ~84 ~49 ~11 ~86 ~49 coal_block 0
fill ~12 ~84 ~45 ~12 ~88 ~45 coal_block 0
fill ~12 ~84 ~46 ~13 ~84 ~46 coal_block 0
fill ~12 ~84 ~47 ~12 ~84 ~45 coal_block 0
fill ~12 ~84 ~50 ~12 ~87 ~50 coal_block 0
fill ~12 ~84 ~51 ~13 ~84 ~51 coal_block 0
fill ~13 ~84 ~44 ~14 ~84 ~44 coal_block 0
fill ~14 ~84 ~43 ~20 ~84 ~43 coal_block 0
fill ~14 ~84 ~52 ~20 ~84 ~52 coal_block 0
fill ~18 ~84 ~48 ~18 ~85 ~48 coal_block 0
fill ~20 ~84 ~44 ~21 ~84 ~44 coal_block 0
fill ~20 ~84 ~51 ~21 ~84 ~51 coal_block 0
fill ~22 ~84 ~45 ~22 ~85 ~45 coal_block 0
fill ~22 ~84 ~46 ~22 ~85 ~46 coal_block 0
fill ~22 ~84 ~50 ~22 ~85 ~50 coal_block 0
fill ~23 ~84 ~48 ~23 ~86 ~48 coal_block 0
fill ~33 ~84 ~59 ~33 ~88 ~59 coal_block 0
setblock ~33 ~84 ~63 coal_block 0
fill ~33 ~84 ~65 ~35 ~84 ~65 coal_block 0
fill ~34 ~84 ~62 ~45 ~84 ~62 coal_block 0
fill ~35 ~84 ~66 ~36 ~84 ~66 coal_block 0
fill ~37 ~84 ~55 ~42 ~84 ~55 coal_block 0
fill ~37 ~84 ~67 ~42 ~84 ~67 coal_block 0
fill ~38 ~84 ~57 ~38 ~85 ~57 coal_block 0
fill ~38 ~84 ~58 ~38 ~85 ~58 coal_block 0
fill ~38 ~84 ~59 ~38 ~85 ~59 coal_block 0
fill ~38 ~84 ~60 ~38 ~85 ~60 coal_block 0
fill ~38 ~84 ~61 ~38 ~84 ~57 coal_block 0
fill ~38 ~84 ~63 ~38 ~84 ~67 coal_block 0
fill ~43 ~84 ~66 ~43 ~90 ~66 coal_block 0
fill ~44 ~84 ~65 ~44 ~90 ~65 coal_block 0
fill ~45 ~84 ~58 ~45 ~94 ~58 coal_block 0
fill ~45 ~84 ~63 ~45 ~90 ~63 coal_block 0
fill ~12 ~85 ~46 ~13 ~85 ~46 coal_block 0
fill ~12 ~85 ~49 ~13 ~85 ~49 coal_block 0
fill ~12 ~85 ~51 ~14 ~85 ~51 coal_block 0
fill ~13 ~85 ~44 ~15 ~85 ~44 coal_block 0
fill ~13 ~85 ~45 ~13 ~87 ~45 coal_block 0
fill ~14 ~85 ~43 ~16 ~85 ~43 coal_block 0
fill ~14 ~85 ~52 ~20 ~85 ~52 coal_block 0
fill ~17 ~85 ~42 ~19 ~85 ~42 coal_block 0
fill ~19 ~85 ~48 ~19 ~86 ~48 coal_block 0
fill ~20 ~85 ~43 ~21 ~85 ~43 coal_block 0
fill ~21 ~85 ~44 ~22 ~85 ~44 coal_block 0
fill ~21 ~85 ~51 ~22 ~85 ~51 coal_block 0
fill ~23 ~85 ~45 ~23 ~86 ~45 coal_block 0
fill ~23 ~85 ~46 ~23 ~86 ~46 coal_block 0
fill ~23 ~85 ~47 ~23 ~86 ~47 coal_block 0
fill ~23 ~85 ~49 ~23 ~86 ~49 coal_block 0
fill ~23 ~85 ~50 ~23 ~87 ~50 coal_block 0
fill ~32 ~85 ~64 ~32 ~90 ~64 coal_block 0
fill ~33 ~85 ~65 ~34 ~85 ~65 coal_block 0
fill ~34 ~85 ~66 ~36 ~85 ~66 coal_block 0
fill ~36 ~85 ~67 ~42 ~85 ~67 coal_block 0
fill ~37 ~85 ~55 ~42 ~85 ~55 coal_block 0
fill ~40 ~85 ~62 ~43 ~85 ~62 coal_block 0
fill ~12 ~86 ~47 ~12 ~89 ~47 coal_block 0
fill ~12 ~86 ~48 ~12 ~89 ~48 coal_block 0
fill ~13 ~86 ~44 ~14 ~86 ~44 coal_block 0
fill ~13 ~86 ~50 ~14 ~86 ~50 coal_block 0
fill ~13 ~86 ~51 ~15 ~86 ~51 coal_block 0
fill ~14 ~86 ~43 ~15 ~86 ~43 coal_block 0
setblock ~14 ~86 ~45 coal_block 0
fill ~14 ~86 ~52 ~21 ~86 ~52 coal_block 0
fill ~16 ~86 ~42 ~20 ~86 ~42 coal_block 0
fill ~20 ~86 ~48 ~21 ~86 ~48 coal_block 0
fill ~21 ~86 ~43 ~22 ~86 ~43 coal_block 0
fill ~21 ~86 ~51 ~22 ~86 ~51 coal_block 0
fill ~22 ~86 ~44 ~23 ~86 ~44 coal_block 0
fill ~24 ~86 ~45 ~24 ~87 ~45 coal_block 0
fill ~24 ~86 ~46 ~24 ~87 ~46 coal_block 0
fill ~24 ~86 ~47 ~24 ~87 ~47 coal_block 0
fill ~24 ~86 ~48 ~24 ~87 ~48 coal_block 0
fill ~24 ~86 ~49 ~24 ~87 ~49 coal_block 0
fill ~33 ~86 ~65 ~34 ~86 ~65 coal_block 0
fill ~34 ~86 ~66 ~35 ~86 ~66 coal_block 0
fill ~36 ~86 ~55 ~42 ~86 ~55 coal_block 0
fill ~36 ~86 ~67 ~39 ~86 ~67 coal_block 0
fill ~39 ~86 ~68 ~40 ~86 ~68 coal_block 0
fill ~41 ~86 ~67 ~42 ~86 ~67 coal_block 0
fill ~45 ~86 ~64 ~45 ~92 ~64 coal_block 0
fill ~12 ~87 ~46 ~12 ~89 ~46 coal_block 0
fill ~12 ~87 ~49 ~12 ~89 ~49 coal_block 0
fill ~13 ~87 ~44 ~14 ~87 ~44 coal_block 0
fill ~13 ~87 ~50 ~13 ~90 ~50 coal_block 0
fill ~13 ~87 ~51 ~14 ~87 ~51 coal_block 0
fill ~14 ~87 ~43 ~15 ~87 ~43 coal_block 0
fill ~14 ~87 ~52 ~17 ~87 ~52 coal_block 0
fill ~16 ~87 ~42 ~22 ~87 ~42 coal_block 0
fill ~18 ~87 ~53 ~19 ~87 ~53 coal_block 0
fill ~20 ~87 ~48 ~22 ~87 ~48 coal_block 0
fill ~20 ~87 ~52 ~22 ~87 ~52 coal_block 0
fill ~22 ~87 ~43 ~23 ~87 ~43 coal_block 0
fill ~22 ~87 ~51 ~23 ~87 ~51 coal_block 0
fill ~23 ~87 ~44 ~24 ~87 ~44 coal_block 0
fill ~24 ~87 ~50 ~24 ~88 ~50 coal_block 0
fill ~25 ~87 ~45 ~25 ~88 ~45 coal_block 0
fill ~25 ~87 ~46 ~25 ~88 ~46 coal_block 0
fill ~25 ~87 ~47 ~25 ~88 ~47 coal_block 0
fill ~25 ~87 ~48 ~25 ~88 ~48 coal_block 0
fill ~25 ~87 ~49 ~25 ~88 ~49 coal_block 0
fill ~31 ~87 ~61 ~31 ~99 ~61 coal_block 0
fill ~31 ~87 ~62 ~31 ~100 ~62 coal_block 0
fill ~32 ~87 ~58 ~32 ~96 ~58 coal_block 0
fill ~33 ~87 ~65 ~34 ~87 ~65 coal_block 0
fill ~34 ~87 ~66 ~35 ~87 ~66 coal_block 0
fill ~35 ~87 ~67 ~37 ~87 ~67 coal_block 0
fill ~36 ~87 ~55 ~42 ~87 ~55 coal_block 0
fill ~38 ~87 ~68 ~41 ~87 ~68 coal_block 0
fill ~41 ~87 ~67 ~43 ~87 ~67 coal_block 0
fill ~44 ~87 ~56 ~44 ~98 ~56 coal_block 0
fill ~44 ~87 ~66 ~44 ~92 ~66 coal_block 0
fill ~46 ~87 ~60 ~46 ~94 ~60 coal_block 0
fill ~46 ~87 ~61 ~46 ~95 ~61 coal_block 0
fill ~13 ~88 ~44 ~14 ~88 ~44 coal_block 0
setblock ~13 ~88 ~46 coal_block 0
setblock ~13 ~88 ~49 coal_block 0
fill ~13 ~88 ~51 ~14 ~88 ~51 coal_block 0
fill ~14 ~88 ~43 ~15 ~88 ~43 coal_block 0
fill ~15 ~88 ~52 ~17 ~88 ~52 coal_block 0
fill ~16 ~88 ~42 ~17 ~88 ~42 coal_block 0
fill ~18 ~88 ~41 ~21 ~88 ~41 coal_block 0
fill ~18 ~88 ~53 ~20 ~88 ~53 coal_block 0
fill ~21 ~88 ~48 ~22 ~88 ~48 coal_block 0
fill ~21 ~88 ~52 ~23 ~88 ~52 coal_block 0
fill ~22 ~88 ~42 ~23 ~88 ~42 coal_block 0
fill ~23 ~88 ~43 ~24 ~88 ~43 coal_block 0
fill ~23 ~88 ~51 ~24 ~88 ~51 coal_block 0
fill ~24 ~88 ~44 ~25 ~88 ~44 coal_block 0
fill ~25 ~88 ~50 ~25 ~89 ~50 coal_block 0
fill ~26 ~88 ~45 ~26 ~89 ~45 coal_block 0
fill ~26 ~88 ~46 ~26 ~89 ~46 coal_block 0
fill ~26 ~88 ~47 ~26 ~89 ~47 coal_block 0
fill ~26 ~88 ~48 ~26 ~89 ~48 coal_block 0
fill ~26 ~88 ~49 ~26 ~89 ~49 coal_block 0
fill ~31 ~88 ~63 ~31 ~100 ~63 coal_block 0
fill ~32 ~88 ~65 ~33 ~88 ~65 coal_block 0
fill ~33 ~88 ~58 ~33 ~114 ~58 coal_block 0
fill ~33 ~88 ~66 ~35 ~88 ~66 coal_block 0
fill ~35 ~88 ~67 ~37 ~88 ~67 coal_block 0
fill ~36 ~88 ~55 ~42 ~88 ~55 coal_block 0
fill ~37 ~88 ~68 ~42 ~88 ~68 coal_block 0
fill ~42 ~88 ~67 ~43 ~88 ~67 coal_block 0
fill ~45 ~88 ~57 ~45 ~98 ~57 coal_block 0
fill ~45 ~88 ~65 ~45 ~95 ~65 coal_block 0
fill ~46 ~88 ~59 ~46 ~97 ~59 coal_block 0
fill ~46 ~88 ~62 ~46 ~95 ~62 coal_block 0
fill ~13 ~89 ~44 ~14 ~89 ~44 coal_block 0
fill ~13 ~89 ~45 ~13 ~91 ~45 coal_block 0
fill ~13 ~89 ~47 ~13 ~92 ~47 coal_block 0
fill ~13 ~89 ~48 ~13 ~92 ~48 coal_block 0
fill ~14 ~89 ~43 ~15 ~89 ~43 coal_block 0
fill ~14 ~89 ~50 ~14 ~92 ~50 coal_block 0
fill ~14 ~89 ~51 ~16 ~89 ~51 coal_block 0
fill ~15 ~89 ~52 ~17 ~89 ~52 coal_block 0
fill ~16 ~89 ~42 ~18 ~89 ~42 coal_block 0
fill ~18 ~89 ~41 ~22 ~89 ~41 coal_block 0
fill ~18 ~89 ~53 ~21 ~89 ~53 coal_block 0
fill ~22 ~89 ~48 ~24 ~89 ~48 coal_block 0
fill ~22 ~89 ~52 ~23 ~89 ~52 coal_block 0
fill ~23 ~89 ~42 ~24 ~89 ~42 coal_block 0
fill ~24 ~89 ~43 ~25 ~89 ~43 coal_block 0
fill ~24 ~89 ~51 ~25 ~89 ~51 coal_block 0
fill ~25 ~89 ~44 ~26 ~89 ~44 coal_block 0
fill ~26 ~89 ~50 ~26 ~90 ~50 coal_block 0
fill ~27 ~89 ~45 ~27 ~90 ~45 coal_block 0
fill ~27 ~89 ~46 ~27 ~90 ~46 coal_block 0
fill ~27 ~89 ~47 ~27 ~90 ~47 coal_block 0
fill ~27 ~89 ~48 ~27 ~90 ~48 coal_block 0
fill ~27 ~89 ~49 ~27 ~91 ~49 coal_block 0
fill ~31 ~89 ~60 ~31 ~95 ~60 coal_block 0
fill ~32 ~89 ~65 ~33 ~89 ~65 coal_block 0
fill ~33 ~89 ~66 ~34 ~89 ~66 coal_block 0
fill ~35 ~89 ~67 ~36 ~89 ~67 coal_block 0
fill ~36 ~89 ~55 ~42 ~89 ~55 coal_block 0
fill ~37 ~89 ~68 ~42 ~89 ~68 coal_block 0
fill ~42 ~89 ~67 ~43 ~89 ~67 coal_block 0
fill ~46 ~89 ~63 ~46 ~95 ~63 coal_block 0
fill ~13 ~90 ~46 ~13 ~92 ~46 coal_block 0
fill ~13 ~90 ~49 ~13 ~91 ~49 coal_block 0
fill ~14 ~90 ~44 ~14 ~93 ~44 coal_block 0
fill ~14 ~90 ~45 ~14 ~90 ~44 coal_block 0
fill ~14 ~90 ~51 ~15 ~90 ~51 coal_block 0
fill ~15 ~90 ~43 ~16 ~90 ~43 coal_block 0
fill ~16 ~90 ~42 ~17 ~90 ~42 coal_block 0
fill ~16 ~90 ~52 ~17 ~90 ~52 coal_block 0
fill ~18 ~90 ~41 ~24 ~90 ~41 coal_block 0
fill ~18 ~90 ~53 ~22 ~90 ~53 coal_block 0
fill ~22 ~90 ~48 ~23 ~90 ~48 coal_block 0
fill ~23 ~90 ~52 ~24 ~90 ~52 coal_block 0
fill ~24 ~90 ~42 ~25 ~90 ~42 coal_block 0
fill ~25 ~90 ~43 ~26 ~90 ~43 coal_block 0
fill ~25 ~90 ~51 ~26 ~90 ~51 coal_block 0
fill ~26 ~90 ~44 ~27 ~90 ~44 coal_block 0
fill ~27 ~90 ~50 ~27 ~91 ~50 coal_block 0
fill ~28 ~90 ~45 ~28 ~91 ~45 coal_block 0
fill ~28 ~90 ~46 ~28 ~91 ~46 coal_block 0
fill ~28 ~90 ~47 ~28 ~91 ~47 coal_block 0
fill ~28 ~90 ~48 ~28 ~91 ~48 coal_block 0
fill ~32 ~90 ~61 ~32 ~96 ~61 coal_block 0
fill ~32 ~90 ~62 ~32 ~90 ~61 coal_block 0
fill ~32 ~90 ~65 ~33 ~90 ~65 coal_block 0
fill ~33 ~90 ~66 ~34 ~90 ~66 coal_block 0
fill ~34 ~90 ~67 ~36 ~90 ~67 coal_block 0
fill ~36 ~90 ~55 ~42 ~90 ~55 coal_block 0
fill ~36 ~90 ~68 ~42 ~90 ~68 coal_block 0
fill ~43 ~90 ~67 ~44 ~90 ~67 coal_block 0
fill ~46 ~90 ~58 ~46 ~99 ~58 coal_block 0
fill ~46 ~90 ~64 ~46 ~96 ~64 coal_block 0
fill ~14 ~91 ~46 ~14 ~91 ~50 coal_block 0
fill ~15 ~91 ~43 ~16 ~91 ~43 coal_block 0
fill ~15 ~91 ~44 ~15 ~92 ~44 coal_block 0
fill ~15 ~91 ~50 ~15 ~94 ~50 coal_block 0
fill ~15 ~91 ~51 ~16 ~91 ~51 coal_block 0
fill ~16 ~91 ~42 ~17 ~91 ~42 coal_block 0
fill ~16 ~91 ~52 ~18 ~91 ~52 coal_block 0
fill ~18 ~91 ~41 ~20 ~91 ~41 coal_block 0
fill ~19 ~91 ~53 ~23 ~91 ~53 coal_block 0
fill ~21 ~91 ~40 ~22 ~91 ~40 coal_block 0
fill ~23 ~91 ~41 ~25 ~91 ~41 coal_block 0
fill ~23 ~91 ~48 ~24 ~91 ~48 coal_block 0
