fill ~63~49~8 ~70~49~8
fill ~71~49~8 ~71~49~10
fill ~3 ~-3 ~2 ~53 ~-3 ~2 dirt 0
fill ~3 ~-3 ~3 ~61 ~-3 ~3 dirt 0
fill ~3 ~-3 ~4 ~66 ~-3 ~4 dirt 0
fill ~3 ~-3 ~5 ~69 ~-3 ~5 dirt 0
fill ~3 ~-3 ~6 ~70 ~-3 ~6 dirt 0
fill ~3 ~-3 ~7 ~72 ~-3 ~7 dirt 0
fill ~3 ~-3 ~8 ~73 ~-3 ~8 dirt 0
fill ~3 ~-3 ~9 ~74 ~-3 ~9 dirt 0
fill ~3 ~-3 ~10 ~74 ~-3 ~10 dirt 0
fill ~3 ~-3 ~11 ~75 ~-3 ~11 dirt 0
fill ~3 ~-3 ~12 ~75 ~-3 ~12 dirt 0
fill ~3 ~-3 ~13 ~75 ~-3 ~13 dirt 0
fill ~3 ~-3 ~14 ~75 ~-3 ~14 dirt 0
fill ~3 ~-3 ~15 ~76 ~-3 ~15 dirt 0
fill ~3 ~-3 ~16 ~76 ~-3 ~16 dirt 0
fill ~3 ~-3 ~17 ~76 ~-3 ~17 dirt 0
fill ~3 ~-3 ~18 ~76 ~-3 ~18 dirt 0
fill ~3 ~-3 ~19 ~76 ~-3 ~19 dirt 0
fill ~3 ~-3 ~20 ~76 ~-3 ~20 dirt 0
fill ~3 ~-3 ~21 ~76 ~-3 ~21 dirt 0
fill ~3 ~-3 ~22 ~76 ~-3 ~22 dirt 0
fill ~3 ~-3 ~23 ~76 ~-3 ~23 dirt 0
fill ~3 ~-3 ~24 ~76 ~-3 ~24 dirt 0
fill ~3 ~-3 ~25 ~76 ~-3 ~25 dirt 0
fill ~3 ~-3 ~26 ~76 ~-3 ~26 dirt 0
fill ~3 ~-3 ~27 ~76 ~-3 ~27 dirt 0
fill ~3 ~-3 ~28 ~76 ~-3 ~28 dirt 0
fill ~3 ~-3 ~29 ~76 ~-3 ~29 dirt 0
fill ~3 ~-3 ~30 ~76 ~-3 ~30 dirt 0
fill ~3 ~-3 ~31 ~76 ~-3 ~31 dirt 0
fill ~3 ~-3 ~32 ~76 ~-3 ~32 dirt 0
fill ~3 ~-3 ~33 ~76 ~-3 ~33 dirt 0
fill ~3 ~-3 ~34 ~76 ~-3 ~34 dirt 0
fill ~3 ~-3 ~35 ~76 ~-3 ~35 dirt 0
fill ~3 ~-3 ~36 ~76 ~-3 ~36 dirt 0
fill ~3 ~-3 ~37 ~76 ~-3 ~37 dirt 0
fill ~3 ~-3 ~38 ~76 ~-3 ~38 dirt 0
fill ~3 ~-3 ~39 ~76 ~-3 ~39 dirt 0
fill ~3 ~-3 ~40 ~76 ~-3 ~40 dirt 0
fill ~3 ~-3 ~41 ~76 ~-3 ~41 dirt 0
fill ~3 ~-3 ~42 ~76 ~-3 ~42 dirt 0
fill ~3 ~-3 ~43 ~76 ~-3 ~43 dirt 0
fill ~3 ~-3 ~44 ~76 ~-3 ~44 dirt 0
fill ~3 ~-3 ~45 ~76 ~-3 ~45 dirt 0
fill ~3 ~-3 ~46 ~76 ~-3 ~46 dirt 0
fill ~3 ~-3 ~47 ~76 ~-3 ~47 dirt 0
fill ~3 ~-3 ~48 ~76 ~-3 ~48 dirt 0
fill ~3 ~-3 ~49 ~76 ~-3 ~49 dirt 0
fill ~3 ~-3 ~50 ~76 ~-3 ~50 dirt 0
fill ~3 ~-3 ~51 ~76 ~-3 ~51 dirt 0
fill ~3 ~-3 ~52 ~76 ~-3 ~52 dirt 0
fill ~3 ~-3 ~53 ~76 ~-3 ~53 dirt 0
fill ~3 ~-3 ~54 ~76 ~-3 ~54 dirt 0
fill ~3 ~-3 ~55 ~76 ~-3 ~55 dirt 0
fill ~3 ~-3 ~56 ~76 ~-3 ~56 dirt 0
fill ~3 ~-3 ~57 ~76 ~-3 ~57 dirt 0
fill ~3 ~-3 ~58 ~76 ~-3 ~58 dirt 0
fill ~3 ~-3 ~59 ~3 ~-3 ~86 grass 0
fill ~4 ~-3 ~59 ~76 ~-3 ~59 dirt 0
fill ~4 ~-3 ~60 ~76 ~-3 ~60 dirt 0
fill ~4 ~-3 ~61 ~76 ~-3 ~61 dirt 0
fill ~4 ~-3 ~62 ~76 ~-3 ~62 dirt 0
fill ~4 ~-3 ~63 ~76 ~-3 ~63 dirt 0
fill ~4 ~-3 ~64 ~76 ~-3 ~64 dirt 0
fill ~4 ~-3 ~65 ~76 ~-3 ~65 dirt 0
fill ~4 ~-3 ~66 ~76 ~-3 ~66 dirt 0
fill ~4 ~-3 ~67 ~76 ~-3 ~67 dirt 0
fill ~4 ~-3 ~68 ~76 ~-3 ~68 dirt 0
fill ~4 ~-3 ~69 ~76 ~-3 ~69 dirt 0
fill ~4 ~-3 ~70 ~76 ~-3 ~70 dirt 0
fill ~4 ~-3 ~71 ~76 ~-3 ~71 dirt 0
fill ~4 ~-3 ~72 ~76 ~-3 ~72 dirt 0
fill ~4 ~-3 ~73 ~76 ~-3 ~73 dirt 0
fill ~4 ~-3 ~74 ~76 ~-3 ~74 dirt 0
fill ~4 ~-3 ~75 ~76 ~-3 ~75 dirt 0
fill ~4 ~-3 ~76 ~76 ~-3 ~76 dirt 0
fill ~4 ~-3 ~77 ~76 ~-3 ~77 dirt 0
fill ~4 ~-3 ~78 ~76 ~-3 ~78 dirt 0
fill ~4 ~-3 ~79 ~76 ~-3 ~79 dirt 0
fill ~4 ~-3 ~80 ~76 ~-3 ~80 dirt 0
fill ~4 ~-3 ~81 ~4 ~-3 ~88 grass 0
fill ~5 ~-3 ~81 ~75 ~-3 ~81 dirt 0
fill ~5 ~-3 ~82 ~75 ~-3 ~82 dirt 0
fill ~5 ~-3 ~83 ~75 ~-3 ~83 dirt 0
fill ~5 ~-3 ~84 ~75 ~-3 ~84 dirt 0
fill ~5 ~-3 ~85 ~74 ~-3 ~85 dirt 0
fill ~5 ~-3 ~86 ~74 ~-3 ~86 dirt 0
fill ~5 ~-3 ~87 ~5 ~-3 ~89 grass 0
fill ~6 ~-3 ~87 ~73 ~-3 ~87 dirt 0
fill ~6 ~-3 ~88 ~73 ~-3 ~88 dirt 0
fill ~6 ~-3 ~89 ~6 ~-3 ~91 grass 0
fill ~7 ~-3 ~89 ~72 ~-3 ~89 dirt 0
fill ~7 ~-3 ~90 ~71 ~-3 ~90 dirt 0
fill ~7 ~-3 ~91 ~7 ~-3 ~92 grass 0
fill ~8 ~-3 ~91 ~70 ~-3 ~91 dirt 0
fill ~8 ~-3 ~92 ~9 ~-3 ~92 grass 0
fill ~9 ~-3 ~93 ~12 ~-3 ~93 grass 0
fill ~10 ~-3 ~92 ~66 ~-3 ~92 dirt 0
fill ~10 ~-3 ~94 ~65 ~-3 ~94 grass 0
fill ~13 ~-3 ~93 ~60 ~-3 ~93 dirt 0
fill ~54 ~-3 ~2 ~63 ~-3 ~2 grass 0
fill ~61 ~-3 ~93 ~67 ~-3 ~93 grass 0
fill ~62 ~-3 ~3 ~68 ~-3 ~3 grass 0
fill ~67 ~-3 ~4 ~70 ~-3 ~4 grass 0
fill ~67 ~-3 ~92 ~71 ~-3 ~92 grass 0
fill ~70 ~-3 ~5 ~72 ~-3 ~5 grass 0
fill ~71 ~-3 ~6 ~73 ~-3 ~6 grass 0
fill ~71 ~-3 ~91 ~72 ~-3 ~91 grass 0
fill ~72 ~-3 ~90 ~73 ~-3 ~90 grass 0
fill ~73 ~-3 ~7 ~74 ~-3 ~7 grass 0
fill ~73 ~-3 ~89 ~74 ~-3 ~89 grass 0
fill ~74 ~-3 ~8 ~75 ~-3 ~8 grass 0
fill ~74 ~-3 ~87 ~75 ~-3 ~87 grass 0
fill ~74 ~-3 ~88 ~74 ~-3 ~87 grass 0
fill ~75 ~-3 ~9 ~75 ~-3 ~10 grass 0
fill ~75 ~-3 ~85 ~75 ~-3 ~87 grass 0
fill ~76 ~-3 ~10 ~76 ~-3 ~14 grass 0
fill ~76 ~-3 ~81 ~77 ~-3 ~81 grass 0
fill ~76 ~-3 ~82 ~77 ~-3 ~82 grass 0
fill ~76 ~-3 ~83 ~76 ~-3 ~84 grass 0
fill ~77 ~-3 ~13 ~77 ~-3 ~82 grass 0
fill ~3 ~-2 ~2 ~53 ~-2 ~2 grass 0
fill ~3 ~-2 ~3 ~3 ~-2 ~58 grass 0
fill ~4 ~-2 ~3 ~28 ~-2 ~3 dirt 0
fill ~4 ~-2 ~4 ~28 ~-2 ~4 dirt 0
fill ~4 ~-2 ~5 ~28 ~-2 ~5 dirt 0
fill ~4 ~-2 ~6 ~28 ~-2 ~6 dirt 0
fill ~4 ~-2 ~7 ~28 ~-2 ~7 dirt 0
fill ~4 ~-2 ~8 ~28 ~-2 ~8 dirt 0
fill ~4 ~-2 ~9 ~28 ~-2 ~9 dirt 0
fill ~4 ~-2 ~10 ~55 ~-2 ~10 dirt 0
fill ~4 ~-2 ~11 ~55 ~-2 ~11 dirt 0
fill ~4 ~-2 ~12 ~55 ~-2 ~12 dirt 0
fill ~4 ~-2 ~13 ~55 ~-2 ~13 dirt 0
fill ~4 ~-2 ~14 ~55 ~-2 ~14 dirt 0
fill ~4 ~-2 ~15 ~65 ~-2 ~15 dirt 0
fill ~4 ~-2 ~16 ~65 ~-2 ~16 dirt 0
fill ~4 ~-2 ~17 ~65 ~-2 ~17 dirt 0
fill ~4 ~-2 ~18 ~65 ~-2 ~18 dirt 0
fill ~4 ~-2 ~19 ~65 ~-2 ~19 dirt 0
fill ~4 ~-2 ~20 ~65 ~-2 ~20 dirt 0
fill ~4 ~-2 ~21 ~65 ~-2 ~21 dirt 0
fill ~4 ~-2 ~22 ~65 ~-2 ~22 dirt 0
fill ~4 ~-2 ~23 ~65 ~-2 ~23 dirt 0
fill ~4 ~-2 ~24 ~55 ~-2 ~24 dirt 0
fill ~4 ~-2 ~25 ~55 ~-2 ~25 dirt 0
fill ~4 ~-2 ~26 ~55 ~-2 ~26 dirt 0
fill ~4 ~-2 ~27 ~55 ~-2 ~27 dirt 0
fill ~4 ~-2 ~28 ~55 ~-2 ~28 dirt 0
fill ~4 ~-2 ~29 ~55 ~-2 ~29 dirt 0
fill ~4 ~-2 ~30 ~55 ~-2 ~30 dirt 0
fill ~4 ~-2 ~31 ~55 ~-2 ~31 dirt 0
fill ~4 ~-2 ~32 ~55 ~-2 ~32 dirt 0
fill ~4 ~-2 ~33 ~55 ~-2 ~33 dirt 0
fill ~4 ~-2 ~34 ~55 ~-2 ~34 dirt 0
fill ~4 ~-2 ~35 ~7 ~-2 ~35 dirt 0
fill ~4 ~-2 ~36 ~19 ~-2 ~36 dirt 0
fill ~4 ~-2 ~37 ~55 ~-2 ~37 dirt 0
fill ~4 ~-2 ~38 ~55 ~-2 ~38 dirt 0
fill ~4 ~-2 ~39 ~37 ~-2 ~39 dirt 0
fill ~4 ~-2 ~40 ~55 ~-2 ~40 dirt 0
fill ~4 ~-2 ~41 ~55 ~-2 ~41 dirt 0
fill ~4 ~-2 ~42 ~55 ~-2 ~42 dirt 0
fill ~4 ~-2 ~43 ~72 ~-2 ~43 dirt 0
fill ~4 ~-2 ~44 ~72 ~-2 ~44 dirt 0
fill ~4 ~-2 ~45 ~72 ~-2 ~45 dirt 0
fill ~4 ~-2 ~46 ~72 ~-2 ~46 dirt 0
fill ~4 ~-2 ~47 ~7 ~-2 ~47 dirt 0
fill ~4 ~-2 ~48 ~68 ~-2 ~48 dirt 0
fill ~4 ~-2 ~49 ~68 ~-2 ~49 dirt 0
fill ~4 ~-2 ~50 ~67 ~-2 ~50 dirt 0
fill ~4 ~-2 ~51 ~66 ~-2 ~51 dirt 0
fill ~4 ~-2 ~52 ~17 ~-2 ~52 grass 0
fill ~4 ~-2 ~53 ~17 ~-2 ~53 grass 0
fill ~4 ~-2 ~54 ~17 ~-2 ~54 grass 0
fill ~4 ~-2 ~55 ~17 ~-2 ~55 grass 0
fill ~4 ~-2 ~56 ~17 ~-2 ~56 grass 0
fill ~4 ~-2 ~57 ~17 ~-2 ~57 grass 0
fill ~4 ~-2 ~58 ~17 ~-2 ~58 grass 0
fill ~4 ~-2 ~59 ~17 ~-2 ~59 grass 0
fill ~4 ~-2 ~60 ~17 ~-2 ~60 grass 0
fill ~4 ~-2 ~61 ~17 ~-2 ~61 grass 0
fill ~4 ~-2 ~62 ~13 ~-2 ~62 grass 0
fill ~4 ~-2 ~63 ~12 ~-2 ~63 grass 0
fill ~4 ~-2 ~64 ~11 ~-2 ~64 grass 0
fill ~4 ~-2 ~65 ~10 ~-2 ~65 grass 0
fill ~4 ~-2 ~66 ~9 ~-2 ~66 grass 0
fill ~4 ~-2 ~67 ~9 ~-2 ~67 grass 0
fill ~4 ~-2 ~68 ~9 ~-2 ~68 grass 0
fill ~4 ~-2 ~69 ~9 ~-2 ~69 grass 0
fill ~4 ~-2 ~70 ~9 ~-2 ~70 grass 0
fill ~4 ~-2 ~71 ~9 ~-2 ~71 grass 0
fill ~4 ~-2 ~72 ~9 ~-2 ~72 grass 0
fill ~4 ~-2 ~73 ~9 ~-2 ~73 grass 0
fill ~4 ~-2 ~74 ~9 ~-2 ~74 grass 0
fill ~4 ~-2 ~75 ~10 ~-2 ~75 grass 0
fill ~4 ~-2 ~76 ~10 ~-2 ~76 grass 0
fill ~4 ~-2 ~77 ~11 ~-2 ~77 grass 0
fill ~4 ~-2 ~78 ~12 ~-2 ~78 grass 0
fill ~4 ~-2 ~79 ~13 ~-2 ~79 grass 0
fill ~4 ~-2 ~80 ~29 ~-2 ~80 grass 0
fill ~5 ~-2 ~81 ~29 ~-2 ~81 grass 0
fill ~5 ~-2 ~82 ~29 ~-2 ~82 grass 0
fill ~5 ~-2 ~83 ~29 ~-2 ~83 grass 0
fill ~5 ~-2 ~84 ~29 ~-2 ~84 grass 0
fill ~5 ~-2 ~85 ~40 ~-2 ~85 grass 0
fill ~5 ~-2 ~86 ~40 ~-2 ~86 grass 0
fill ~6 ~-2 ~87 ~40 ~-2 ~87 grass 0
fill ~6 ~-2 ~88 ~40 ~-2 ~88 grass 0
fill ~7 ~-2 ~89 ~40 ~-2 ~89 grass 0
fill ~7 ~-2 ~90 ~40 ~-2 ~90 grass 0
setblock ~8 ~-2 ~35 mob_spawner 0
setblock ~8 ~-2 ~47 mob_spawner 0
fill ~8 ~-2 ~91 ~70 ~-2 ~91 grass 0
fill ~9 ~-2 ~35 ~55 ~-2 ~35 dirt 0
fill ~9 ~-2 ~47 ~15 ~-2 ~47 dirt 0
fill ~10 ~-2 ~66 ~67 ~-2 ~66 dirt 0
fill ~10 ~-2 ~67 ~15 ~-2 ~67 dirt 0
fill ~10 ~-2 ~68 ~67 ~-2 ~68 dirt 0
fill ~10 ~-2 ~69 ~67 ~-2 ~69 dirt 0
fill ~10 ~-2 ~70 ~67 ~-2 ~70 dirt 0
fill ~10 ~-2 ~71 ~63 ~-2 ~71 dirt 0
fill ~10 ~-2 ~72 ~63 ~-2 ~72 dirt 0
fill ~10 ~-2 ~73 ~63 ~-2 ~73 dirt 0
fill ~10 ~-2 ~74 ~63 ~-2 ~74 dirt 0
fill ~10 ~-2 ~92 ~66 ~-2 ~92 grass 0
fill ~11 ~-2 ~65 ~67 ~-2 ~65 dirt 0
fill ~11 ~-2 ~75 ~63 ~-2 ~75 dirt 0
fill ~11 ~-2 ~76 ~26 ~-2 ~76 dirt 0
fill ~12 ~-2 ~64 ~67 ~-2 ~64 dirt 0
fill ~12 ~-2 ~77 ~25 ~-2 ~77 dirt 0
fill ~13 ~-2 ~63 ~67 ~-2 ~63 dirt 0
fill ~13 ~-2 ~78 ~24 ~-2 ~78 dirt 0
fill ~13 ~-2 ~93 ~60 ~-2 ~93 grass 0
fill ~14 ~-2 ~62 ~67 ~-2 ~62 dirt 0
fill ~14 ~-2 ~79 ~23 ~-2 ~79 dirt 0
setblock ~16 ~-2 ~47 mob_spawner 0
setblock ~16 ~-2 ~67 mob_spawner 0
fill ~17 ~-2 ~47 ~69 ~-2 ~47 dirt 0
fill ~17 ~-2 ~67 ~67 ~-2 ~67 dirt 0
fill ~18 ~-2 ~52 ~66 ~-2 ~52 dirt 0
fill ~18 ~-2 ~53 ~65 ~-2 ~53 dirt 0
fill ~18 ~-2 ~54 ~65 ~-2 ~54 dirt 0
fill ~18 ~-2 ~55 ~64 ~-2 ~55 dirt 0
fill ~18 ~-2 ~56 ~63 ~-2 ~56 dirt 0
fill ~18 ~-2 ~57 ~72 ~-2 ~57 dirt 0
fill ~18 ~-2 ~58 ~72 ~-2 ~58 dirt 0
fill ~18 ~-2 ~59 ~43 ~-2 ~59 dirt 0
fill ~18 ~-2 ~60 ~62 ~-2 ~60 dirt 0
fill ~18 ~-2 ~61 ~62 ~-2 ~61 dirt 0
setblock ~20 ~-2 ~36 mob_spawner 0
fill ~21 ~-2 ~36 ~55 ~-2 ~36 dirt 0
fill ~24 ~-2 ~79 ~29 ~-2 ~79 grass 0
fill ~25 ~-2 ~78 ~29 ~-2 ~78 grass 0
fill ~26 ~-2 ~77 ~29 ~-2 ~77 grass 0
fill ~27 ~-2 ~76 ~29 ~-2 ~76 grass 0
fill ~29 ~-2 ~3 ~61 ~-2 ~3 grass 0
fill ~29 ~-2 ~4 ~66 ~-2 ~4 grass 0
fill ~29 ~-2 ~5 ~69 ~-2 ~5 grass 0
fill ~29 ~-2 ~6 ~34 ~-2 ~6 grass 0
fill ~29 ~-2 ~7 ~34 ~-2 ~7 grass 0
fill ~29 ~-2 ~8 ~34 ~-2 ~8 grass 0
fill ~29 ~-2 ~9 ~34 ~-2 ~9 grass 0
fill ~30 ~-2 ~76 ~63 ~-2 ~76 dirt 0
fill ~30 ~-2 ~77 ~63 ~-2 ~77 dirt 0
fill ~30 ~-2 ~78 ~49 ~-2 ~78 dirt 0
fill ~30 ~-2 ~79 ~49 ~-2 ~79 dirt 0
fill ~30 ~-2 ~80 ~49 ~-2 ~80 dirt 0
fill ~30 ~-2 ~81 ~49 ~-2 ~81 dirt 0
fill ~30 ~-2 ~82 ~49 ~-2 ~82 dirt 0
fill ~30 ~-2 ~83 ~49 ~-2 ~83 dirt 0
fill ~30 ~-2 ~84 ~49 ~-2 ~84 dirt 0
fill ~35 ~-2 ~6 ~42 ~-2 ~6 dirt 0
fill ~35 ~-2 ~7 ~42 ~-2 ~7 dirt 0
fill ~35 ~-2 ~8 ~42 ~-2 ~8 dirt 0
fill ~35 ~-2 ~9 ~55 ~-2 ~9 dirt 0
setblock ~38 ~-2 ~39 mob_spawner 0
fill ~39 ~-2 ~39 ~55 ~-2 ~39 dirt 0
fill ~41 ~-2 ~85 ~49 ~-2 ~85 dirt 0
fill ~41 ~-2 ~86 ~49 ~-2 ~86 dirt 0
fill ~41 ~-2 ~87 ~49 ~-2 ~87 dirt 0
fill ~41 ~-2 ~88 ~49 ~-2 ~88 dirt 0
fill ~41 ~-2 ~89 ~49 ~-2 ~89 dirt 0
fill ~41 ~-2 ~90 ~49 ~-2 ~90 dirt 0
setblock ~41 ~-2 ~94 tallgrass 1
fill ~43 ~-2 ~6 ~70 ~-2 ~6 grass 0
fill ~43 ~-2 ~7 ~72 ~-2 ~7 grass 0
fill ~43 ~-2 ~8 ~73 ~-2 ~8 grass 0
setblock ~44 ~-2 ~59 mob_spawner 0
fill ~45 ~-2 ~59 ~63 ~-2 ~59 dirt 0
fill ~50 ~-2 ~78 ~76 ~-2 ~78 grass 0
fill ~50 ~-2 ~79 ~76 ~-2 ~79 grass 0
fill ~50 ~-2 ~80 ~76 ~-2 ~80 grass 0
fill ~50 ~-2 ~81 ~75 ~-2 ~81 grass 0
fill ~50 ~-2 ~82 ~75 ~-2 ~82 grass 0
fill ~50 ~-2 ~83 ~75 ~-2 ~83 grass 0
fill ~50 ~-2 ~84 ~75 ~-2 ~84 grass 0
fill ~50 ~-2 ~85 ~74 ~-2 ~85 grass 0
fill ~50 ~-2 ~86 ~74 ~-2 ~86 grass 0
fill ~50 ~-2 ~87 ~73 ~-2 ~87 grass 0
fill ~50 ~-2 ~88 ~73 ~-2 ~88 grass 0
fill ~50 ~-2 ~89 ~72 ~-2 ~89 grass 0
fill ~50 ~-2 ~90 ~71 ~-2 ~90 grass 0
fill ~56 ~-2 ~9 ~74 ~-2 ~9 grass 0
fill ~56 ~-2 ~10 ~74 ~-2 ~10 grass 0
fill ~56 ~-2 ~11 ~75 ~-2 ~11 grass 0
fill ~56 ~-2 ~12 ~75 ~-2 ~12 grass 0
fill ~56 ~-2 ~13 ~75 ~-2 ~13 grass 0
fill ~56 ~-2 ~14 ~75 ~-2 ~14 grass 0
fill ~56 ~-2 ~24 ~76 ~-2 ~24 grass 0
fill ~56 ~-2 ~25 ~76 ~-2 ~25 grass 0
fill ~56 ~-2 ~26 ~76 ~-2 ~26 grass 0
fill ~56 ~-2 ~27 ~76 ~-2 ~27 grass 0
fill ~56 ~-2 ~28 ~76 ~-2 ~28 grass 0
fill ~56 ~-2 ~29 ~76 ~-2 ~29 grass 0
fill ~56 ~-2 ~30 ~62 ~-2 ~30 grass 0
fill ~56 ~-2 ~31 ~61 ~-2 ~31 grass 0
fill ~56 ~-2 ~32 ~60 ~-2 ~32 grass 0
fill ~56 ~-2 ~33 ~60 ~-2 ~33 grass 0
fill ~56 ~-2 ~34 ~60 ~-2 ~34 grass 0
fill ~56 ~-2 ~35 ~61 ~-2 ~35 grass 0
fill ~56 ~-2 ~36 ~62 ~-2 ~36 grass 0
fill ~56 ~-2 ~37 ~76 ~-2 ~37 grass 0
fill ~56 ~-2 ~38 ~76 ~-2 ~38 grass 0
fill ~56 ~-2 ~39 ~76 ~-2 ~39 grass 0
fill ~56 ~-2 ~40 ~76 ~-2 ~40 grass 0
fill ~56 ~-2 ~41 ~76 ~-2 ~41 grass 0
fill ~56 ~-2 ~42 ~76 ~-2 ~42 grass 0
fill ~61 ~-2 ~32 ~67 ~-2 ~32 dirt 0
fill ~61 ~-2 ~33 ~67 ~-2 ~33 dirt 0
fill ~61 ~-2 ~34 ~67 ~-2 ~34 dirt 0
fill ~62 ~-2 ~31 ~66 ~-2 ~31 dirt 0
fill ~62 ~-2 ~35 ~66 ~-2 ~35 dirt 0
fill ~62 ~-2 ~94 ~63 ~-2 ~94 tallgrass 1
fill ~63 ~-2 ~30 ~65 ~-2 ~30 dirt 0
fill ~63 ~-2 ~36 ~65 ~-2 ~36 dirt 0
fill ~63 ~-2 ~60 ~76 ~-2 ~60 grass 0
fill ~63 ~-2 ~61 ~76 ~-2 ~61 grass 0
fill ~64 ~-2 ~56 ~65 ~-2 ~56 grass 0
fill ~64 ~-2 ~59 ~76 ~-2 ~59 grass 0
fill ~64 ~-2 ~71 ~76 ~-2 ~71 grass 0
fill ~64 ~-2 ~72 ~76 ~-2 ~72 grass 0
fill ~64 ~-2 ~73 ~76 ~-2 ~73 grass 0
fill ~64 ~-2 ~74 ~76 ~-2 ~74 grass 0
fill ~64 ~-2 ~75 ~76 ~-2 ~75 grass 0
fill ~64 ~-2 ~76 ~76 ~-2 ~76 grass 0
fill ~64 ~-2 ~77 ~76 ~-2 ~77 grass 0
setblock ~64 ~-2 ~93 tallgrass 1
fill ~65 ~-2 ~55 ~66 ~-2 ~55 grass 0
fill ~66 ~-2 ~15 ~76 ~-2 ~15 grass 0
fill ~66 ~-2 ~16 ~76 ~-2 ~16 grass 0
fill ~66 ~-2 ~17 ~76 ~-2 ~17 grass 0
fill ~66 ~-2 ~18 ~76 ~-2 ~18 grass 0
fill ~66 ~-2 ~19 ~76 ~-2 ~19 grass 0
fill ~66 ~-2 ~20 ~76 ~-2 ~20 grass 0
fill ~66 ~-2 ~21 ~76 ~-2 ~21 grass 0
fill ~66 ~-2 ~22 ~76 ~-2 ~22 grass 0
fill ~66 ~-2 ~23 ~76 ~-2 ~23 grass 0
fill ~66 ~-2 ~30 ~76 ~-2 ~30 grass 0
fill ~66 ~-2 ~36 ~76 ~-2 ~36 grass 0
fill ~66 ~-2 ~53 ~70 ~-2 ~53 grass 0
fill ~66 ~-2 ~54 ~67 ~-2 ~54 grass 0
fill ~67 ~-2 ~31 ~76 ~-2 ~31 grass 0
fill ~67 ~-2 ~35 ~76 ~-2 ~35 grass 0
fill ~67 ~-2 ~51 ~70 ~-2 ~51 grass 0
fill ~67 ~-2 ~52 ~67 ~-2 ~51 grass 0
fill ~68 ~-2 ~32 ~76 ~-2 ~32 grass 0
fill ~68 ~-2 ~33 ~76 ~-2 ~33 grass 0
fill ~68 ~-2 ~34 ~76 ~-2 ~34 grass 0
fill ~68 ~-2 ~50 ~69 ~-2 ~50 mycelium 0
setblock ~68 ~-2 ~52 dirt 0
fill ~68 ~-2 ~56 ~70 ~-2 ~56 grass 0
fill ~68 ~-2 ~62 ~76 ~-2 ~62 grass 0
fill ~68 ~-2 ~63 ~76 ~-2 ~63 grass 0
fill ~68 ~-2 ~64 ~76 ~-2 ~64 grass 0
fill ~68 ~-2 ~65 ~76 ~-2 ~65 grass 0
fill ~68 ~-2 ~66 ~76 ~-2 ~66 grass 0
fill ~68 ~-2 ~67 ~76 ~-2 ~67 grass 0
fill ~68 ~-2 ~68 ~76 ~-2 ~68 grass 0
fill ~68 ~-2 ~69 ~76 ~-2 ~69 grass 0
fill ~68 ~-2 ~70 ~76 ~-2 ~70 grass 0
fill ~69 ~-2 ~48 ~70 ~-2 ~48 mycelium 0
fill ~69 ~-2 ~49 ~70 ~-2 ~49 mycelium 0
fill ~69 ~-2 ~52 ~70 ~-2 ~52 grass 0
setblock ~70 ~-2 ~47 mycelium 0
setblock ~70 ~-2 ~50 grass 0
fill ~70 ~-2 ~54 ~70 ~-2 ~56 grass 0
fill ~71 ~-2 ~47 ~72 ~-2 ~47 dirt 0
fill ~71 ~-2 ~48 ~72 ~-2 ~48 dirt 0
fill ~71 ~-2 ~49 ~72 ~-2 ~49 dirt 0
fill ~71 ~-2 ~50 ~72 ~-2 ~50 dirt 0
fill ~71 ~-2 ~51 ~72 ~-2 ~51 dirt 0
fill ~71 ~-2 ~52 ~72 ~-2 ~52 dirt 0
fill ~71 ~-2 ~53 ~72 ~-2 ~53 dirt 0
fill ~71 ~-2 ~54 ~72 ~-2 ~54 dirt 0
fill ~71 ~-2 ~55 ~72 ~-2 ~55 dirt 0
fill ~71 ~-2 ~56 ~72 ~-2 ~56 dirt 0
fill ~73 ~-2 ~43 ~76 ~-2 ~43 grass 0
fill ~73 ~-2 ~44 ~76 ~-2 ~44 grass 0
fill ~73 ~-2 ~45 ~76 ~-2 ~45 grass 0
fill ~73 ~-2 ~46 ~76 ~-2 ~46 grass 0
fill ~73 ~-2 ~47 ~76 ~-2 ~47 grass 0
fill ~73 ~-2 ~48 ~76 ~-2 ~48 grass 0
fill ~73 ~-2 ~49 ~76 ~-2 ~49 grass 0
fill ~73 ~-2 ~50 ~76 ~-2 ~50 grass 0
fill ~73 ~-2 ~51 ~76 ~-2 ~51 grass 0
fill ~73 ~-2 ~52 ~76 ~-2 ~52 grass 0
fill ~73 ~-2 ~53 ~76 ~-2 ~53 grass 0
fill ~73 ~-2 ~54 ~76 ~-2 ~54 grass 0
fill ~73 ~-2 ~55 ~76 ~-2 ~55 grass 0
fill ~73 ~-2 ~56 ~76 ~-2 ~56 grass 0
fill ~73 ~-2 ~57 ~76 ~-2 ~57 grass 0
fill ~73 ~-2 ~58 ~76 ~-2 ~58 grass 0
setblock ~73 ~-2 ~90 tallgrass 1
fill ~74 ~-2 ~88 ~74 ~-2 ~89 tallgrass 1
fill ~76 ~-2 ~81 ~76 ~-2 ~83 tallgrass 1
setblock ~77 ~-2 ~59 tallgrass 1
setblock ~77 ~-2 ~81 yellow_flower 0
setblock ~77 ~-2 ~82 tallgrass 1
fill ~3 ~-1 ~5 ~3 ~-1 ~7 tallgrass 1
fill ~3 ~-1 ~12 ~3 ~-1 ~14 tallgrass 1
fill ~3 ~-1 ~19 ~3 ~-1 ~21 tallgrass 1
setblock ~3 ~-1 ~24 tallgrass 1
setblock ~3 ~-1 ~25 yellow_flower 0
fill ~3 ~-1 ~26 ~3 ~-1 ~27 tallgrass 1
setblock ~3 ~-1 ~29 yellow_flower 0
fill ~3 ~-1 ~30 ~3 ~-1 ~32 tallgrass 1
setblock ~3 ~-1 ~39 tallgrass 1
setblock ~3 ~-1 ~40 red_flower 0
setblock ~3 ~-1 ~41 tallgrass 1
setblock ~3 ~-1 ~52 tallgrass 1
fill ~4 ~-1 ~3 ~28 ~-1 ~3 stonebrick 0
fill ~4 ~-1 ~4 ~4 ~-1 ~3 stonebrick 0
fill ~4 ~-1 ~5 ~28 ~-1 ~5 stonebrick 2
fill ~4 ~-1 ~6 ~28 ~-1 ~6 stonebrick 2
fill ~4 ~-1 ~7 ~28 ~-1 ~7 stonebrick 2
fill ~4 ~-1 ~8 ~28 ~-1 ~8 stonebrick 2
fill ~4 ~-1 ~9 ~28 ~-1 ~9 stonebrick 2
fill ~4 ~-1 ~10 ~34 ~-1 ~10 stonebrick 2
fill ~4 ~-1 ~11 ~54 ~-1 ~11 stonebrick 2
fill ~4 ~-1 ~12 ~54 ~-1 ~12 stonebrick 2
fill ~4 ~-1 ~13 ~54 ~-1 ~13 stonebrick 2
fill ~4 ~-1 ~14 ~54 ~-1 ~14 stonebrick 2
fill ~4 ~-1 ~15 ~54 ~-1 ~15 stonebrick 2
fill ~4 ~-1 ~16 ~64 ~-1 ~16 stonebrick 2
fill ~4 ~-1 ~17 ~64 ~-1 ~17 stonebrick 2
fill ~4 ~-1 ~18 ~64 ~-1 ~18 stonebrick 2
fill ~4 ~-1 ~19 ~64 ~-1 ~19 stonebrick 2
fill ~4 ~-1 ~20 ~64 ~-1 ~20 stonebrick 2
fill ~4 ~-1 ~21 ~64 ~-1 ~21 stonebrick 2
fill ~4 ~-1 ~22 ~64 ~-1 ~22 stonebrick 2
fill ~4 ~-1 ~23 ~54 ~-1 ~23 stonebrick 2
fill ~4 ~-1 ~24 ~54 ~-1 ~24 stonebrick 2
fill ~4 ~-1 ~25 ~54 ~-1 ~25 stonebrick 2
fill ~4 ~-1 ~26 ~54 ~-1 ~26 stonebrick 2
fill ~4 ~-1 ~27 ~54 ~-1 ~27 stonebrick 2
fill ~4 ~-1 ~28 ~54 ~-1 ~28 stonebrick 2
fill ~4 ~-1 ~29 ~54 ~-1 ~29 stonebrick 2
fill ~4 ~-1 ~30 ~54 ~-1 ~30 stonebrick 2
fill ~4 ~-1 ~31 ~4 ~-1 ~36 stonebrick 1
fill ~4 ~-1 ~37 ~37 ~-1 ~37 stonebrick 2
fill ~4 ~-1 ~38 ~38 ~-1 ~38 stonebrick 2
fill ~4 ~-1 ~39 ~37 ~-1 ~39 stonebrick 2
fill ~4 ~-1 ~40 ~54 ~-1 ~40 stonebrick 2
fill ~4 ~-1 ~41 ~54 ~-1 ~41 stonebrick 2
fill ~4 ~-1 ~42 ~54 ~-1 ~42 stonebrick 2
fill ~4 ~-1 ~43 ~45 ~-1 ~43 stonebrick 2
fill ~4 ~-1 ~44 ~69 ~-1 ~44 stonebrick 2
fill ~4 ~-1 ~45 ~70 ~-1 ~45 stonebrick 2
fill ~4 ~-1 ~46 ~70 ~-1 ~46 stonebrick 2
fill ~4 ~-1 ~47 ~7 ~-1 ~47 stonebrick 2
fill ~4 ~-1 ~48 ~68 ~-1 ~48 stonebrick 2
fill ~4 ~-1 ~49 ~48 ~-1 ~49 stonebrick 2
fill ~4 ~-1 ~50 ~67 ~-1 ~50 stonebrick 2
fill ~4 ~-1 ~51 ~66 ~-1 ~51 stonebrick 2
fill ~4 ~-1 ~54 ~4 ~-1 ~55 tallgrass 1
fill ~4 ~-1 ~65 ~8 ~-1 ~65 tallgrass 1
setblock ~4 ~-1 ~67 tallgrass 1
fill ~5 ~-1 ~2 ~6 ~-1 ~2 tallgrass 1
fill ~5 ~-1 ~4 ~28 ~-1 ~4 stonebrick 2
fill ~5 ~-1 ~31 ~39 ~-1 ~31 stonebrick 2
fill ~5 ~-1 ~32 ~54 ~-1 ~32 stonebrick 2
fill ~5 ~-1 ~33 ~5 ~0 ~33 stonebrick 1
fill ~5 ~-1 ~34 ~35 ~-1 ~34 stonebrick 2
fill ~5 ~-1 ~35 ~7 ~-1 ~35 stonebrick 2
fill ~5 ~-1 ~36 ~19 ~-1 ~36 stonebrick 2
fill ~5 ~-1 ~53 ~9 ~-1 ~53 tallgrass 1
setblock ~5 ~-1 ~54 red_flower 0
fill ~5 ~-1 ~55 ~8 ~-1 ~55 tallgrass 1
setblock ~5 ~-1 ~58 tallgrass 1
setblock ~5 ~-1 ~64 yellow_flower 0
fill ~5 ~-1 ~66 ~8 ~-1 ~66 tallgrass 1
fill ~5 ~-1 ~71 ~8 ~-1 ~71 tallgrass 1
setblock ~5 ~-1 ~74 yellow_flower 0
fill ~6 ~-1 ~33 ~54 ~-1 ~33 stonebrick 2
fill ~6 ~-1 ~52 ~7 ~-1 ~52 tallgrass 1
fill ~6 ~-1 ~54 ~9 ~-1 ~54 tallgrass 1
fill ~6 ~-1 ~56 ~6 ~-1 ~57 tallgrass 1
setblock ~6 ~-1 ~64 tallgrass 1
fill ~6 ~-1 ~67 ~9 ~-1 ~67 tallgrass 1
fill ~6 ~-1 ~69 ~6 ~-1 ~73 tallgrass 1
fill ~6 ~-1 ~82 ~9 ~-1 ~82 tallgrass 1
setblock ~7 ~-1 ~2 red_flower 0
setblock ~7 ~-1 ~56 yellow_flower 0
setblock ~7 ~-1 ~62 red_flower 0
setblock ~7 ~-1 ~63 tallgrass 1
setblock ~7 ~-1 ~64 yellow_flower 0
setblock ~7 ~-1 ~68 tallgrass 1
setblock ~7 ~-1 ~70 tallgrass 1
fill ~7 ~-1 ~72 ~9 ~-1 ~72 tallgrass 1
fill ~7 ~-1 ~84 ~15 ~-1 ~84 tallgrass 1
fill ~7 ~-1 ~85 ~7 ~-1 ~84 tallgrass 1
fill ~8 ~-1 ~2 ~10 ~-1 ~2 tallgrass 1
setblock ~8 ~-1 ~35 stonebrick 1
setblock ~8 ~-1 ~47 stonebrick 1
setblock ~8 ~-1 ~58 yellow_flower 0
fill ~8 ~-1 ~59 ~12 ~-1 ~59 tallgrass 1
setblock ~8 ~-1 ~64 tallgrass 1
setblock ~8 ~-1 ~70 red_flower 0
setblock ~8 ~-1 ~73 tallgrass 1
setblock ~8 ~-1 ~81 tallgrass 1
fill ~8 ~-1 ~83 ~10 ~-1 ~83 tallgrass 1
fill ~8 ~-1 ~85 ~9 ~-1 ~85 yellow_flower 0
fill ~9 ~-1 ~35 ~35 ~-1 ~35 stonebrick 2
fill ~9 ~-1 ~47 ~15 ~-1 ~47 stonebrick 2
setblock ~9 ~-1 ~56 tallgrass 1
setblock ~9 ~-1 ~57 red_flower 0
fill ~9 ~-1 ~58 ~12 ~-1 ~58 tallgrass 1
setblock ~9 ~-1 ~63 tallgrass 1
setblock ~9 ~-1 ~65 red_flower 0
setblock ~9 ~-1 ~70 tallgrass 1
setblock ~9 ~-1 ~73 yellow_flower 0
setblock ~9 ~-1 ~74 tallgrass 1
setblock ~9 ~-1 ~81 yellow_flower 0
fill ~10 ~-1 ~55 ~12 ~-1 ~55 tallgrass 1
fill ~10 ~-1 ~57 ~12 ~-1 ~57 tallgrass 1
setblock ~10 ~-1 ~60 red_flower 0
fill ~10 ~-1 ~61 ~11 ~-1 ~61 tallgrass 1
fill ~10 ~-1 ~64 ~10 ~-1 ~65 tallgrass 1
fill ~10 ~-1 ~66 ~11 ~-1 ~66 stonebrick 0
fill ~10 ~-1 ~67 ~11 ~-1 ~67 stonebrick 0
fill ~10 ~-1 ~68 ~10 ~-1 ~74 stonebrick 0
fill ~10 ~-1 ~76 ~10 ~21 ~76 vine 12
fill ~10 ~-1 ~85 ~10 ~-1 ~86 tallgrass 1
setblock ~11 ~-1 ~52 tallgrass 1
setblock ~11 ~-1 ~60 tallgrass 1
fill ~11 ~-1 ~64 ~11 ~22 ~64 vine 9
fill ~11 ~-1 ~65 ~12 ~-1 ~65 stonebrick 0
fill ~11 ~-1 ~68 ~13 ~-1 ~68 stonebrick 2
fill ~11 ~-1 ~69 ~12 ~-1 ~69 stonebrick 2
fill ~11 ~-1 ~70 ~62 ~-1 ~70 stonebrick 2
fill ~11 ~-1 ~71 ~62 ~-1 ~71 stonebrick 2
fill ~11 ~-1 ~72 ~62 ~-1 ~72 stonebrick 2
fill ~11 ~-1 ~73 ~62 ~-1 ~73 stonebrick 2
fill ~11 ~-1 ~74 ~11 ~-1 ~76 stonebrick 0
fill ~11 ~-1 ~77 ~11 ~17 ~77 vine 4
fill ~11 ~-1 ~78 ~11 ~19 ~78 vine 12
setblock ~11 ~-1 ~89 tallgrass 1
fill ~12 ~-1 ~53 ~17 ~-1 ~53 tallgrass 1
fill ~12 ~-1 ~54 ~14 ~-1 ~54 tallgrass 1
fill ~12 ~-1 ~63 ~12 ~21 ~63 vine 9
fill ~12 ~-1 ~64 ~13 ~-1 ~64 stonebrick 0
fill ~12 ~-1 ~66 ~16 ~-1 ~66 stonebrick 2
fill ~12 ~-1 ~67 ~14 ~-1 ~67 stonebrick 2
fill ~12 ~-1 ~74 ~62 ~-1 ~74 stonebrick 2
fill ~12 ~-1 ~75 ~26 ~-1 ~75 stonebrick 2
fill ~12 ~-1 ~76 ~12 ~-1 ~77 stonebrick 0
setblock ~12 ~-1 ~82 tallgrass 1
fill ~12 ~-1 ~85 ~16 ~-1 ~85 tallgrass 1
setblock ~12 ~-1 ~86 yellow_flower 0
fill ~13 ~-1 ~2 ~15 ~-1 ~2 tallgrass 1
fill ~13 ~-1 ~52 ~14 ~-1 ~52 tallgrass 1
setblock ~13 ~-1 ~55 yellow_flower 0
fill ~13 ~-1 ~56 ~14 ~-1 ~56 tallgrass 1
setblock ~13 ~-1 ~59 yellow_flower 0
fill ~13 ~-1 ~62 ~13 ~21 ~62 vine 9
fill ~13 ~-1 ~63 ~14 ~-1 ~63 stonebrick 1
fill ~13 ~-1 ~65 ~62 ~-1 ~65 stonebrick 2
fill ~13 ~-1 ~69 ~14 ~-1 ~69 stonebrick 1
fill ~13 ~-1 ~76 ~25 ~-1 ~76 stonebrick 2
fill ~13 ~-1 ~77 ~13 ~-1 ~78 stonebrick 0
setblock ~13 ~-1 ~83 tallgrass 1
fill ~13 ~-1 ~86 ~15 ~-1 ~86 tallgrass 1
fill ~13 ~-1 ~87 ~14 ~-1 ~87 tallgrass 1
fill ~14 ~-1 ~55 ~15 ~-1 ~55 tallgrass 1
fill ~14 ~-1 ~57 ~15 ~-1 ~57 tallgrass 1
setblock ~14 ~-1 ~59 tallgrass 1
fill ~14 ~-1 ~61 ~14 ~22 ~61 vine 1
fill ~14 ~-1 ~62 ~18 ~-1 ~62 stonebrick 0
fill ~14 ~-1 ~64 ~47 ~-1 ~64 stonebrick 2
fill ~14 ~-1 ~68 ~15 ~-1 ~68 stonebrick 1
fill ~14 ~-1 ~77 ~24 ~-1 ~77 stonebrick 2
fill ~14 ~-1 ~78 ~14 ~-1 ~79 stonebrick 0
fill ~15 ~-1 ~63 ~50 ~-1 ~63 stonebrick 2
fill ~15 ~-1 ~67 ~17 ~-1 ~67 stonebrick 1
fill ~15 ~-1 ~69 ~62 ~-1 ~69 stonebrick 2
fill ~15 ~-1 ~78 ~23 ~-1 ~78 stonebrick 2
fill ~15 ~-1 ~79 ~23 ~-1 ~79 stonebrick 0
fill ~15 ~-1 ~83 ~16 ~-1 ~83 tallgrass 1
setblock ~15 ~-1 ~87 yellow_flower 0
setblock ~16 ~-1 ~47 monster_egg 4
setblock ~16 ~-1 ~54 tallgrass 1
fill ~16 ~-1 ~68 ~62 ~-1 ~68 stonebrick 2
fill ~17 ~-1 ~47 ~69 ~-1 ~47 stonebrick 2
fill ~17 ~-1 ~66 ~19 ~-1 ~66 stonebrick 1
setblock ~17 ~-1 ~81 tallgrass 1
setblock ~17 ~-1 ~87 tallgrass 1
fill ~18 ~-1 ~52 ~18 ~-1 ~62 stonebrick 0
fill ~18 ~-1 ~67 ~62 ~-1 ~67 stonebrick 2
fill ~18 ~-1 ~83 ~21 ~-1 ~83 tallgrass 1
fill ~18 ~-1 ~85 ~21 ~-1 ~85 tallgrass 1
fill ~18 ~-1 ~86 ~19 ~-1 ~86 tallgrass 1
fill ~19 ~-1 ~52 ~66 ~-1 ~52 stonebrick 2
fill ~19 ~-1 ~53 ~44 ~-1 ~53 stonebrick 2
fill ~19 ~-1 ~54 ~65 ~-1 ~54 stonebrick 2
fill ~19 ~-1 ~55 ~64 ~-1 ~55 stonebrick 2
fill ~19 ~-1 ~56 ~63 ~-1 ~56 stonebrick 2
fill ~19 ~-1 ~57 ~65 ~-1 ~57 stonebrick 2
fill ~19 ~-1 ~58 ~41 ~-1 ~58 stonebrick 2
fill ~19 ~-1 ~59 ~40 ~-1 ~59 stonebrick 2
fill ~19 ~-1 ~60 ~62 ~-1 ~60 stonebrick 2
fill ~19 ~-1 ~61 ~48 ~-1 ~61 stonebrick 2
fill ~19 ~-1 ~62 ~62 ~-1 ~62 stonebrick 2
setblock ~19 ~-1 ~84 yellow_flower 0
setblock ~20 ~-1 ~36 stonebrick 1
fill ~20 ~-1 ~66 ~62 ~-1 ~66 stonebrick 2
fill ~20 ~-1 ~82 ~22 ~-1 ~82 tallgrass 1
fill ~20 ~-1 ~84 ~21 ~-1 ~84 tallgrass 1
fill ~21 ~-1 ~36 ~36 ~-1 ~36 stonebrick 2
setblock ~21 ~-1 ~86 tallgrass 1
setblock ~22 ~-1 ~87 tallgrass 1
setblock ~23 ~-1 ~84 red_flower 0
setblock ~24 ~-1 ~78 stonebrick 0
setblock ~24 ~-1 ~87 tallgrass 1
setblock ~25 ~-1 ~77 stonebrick 0
setblock ~25 ~-1 ~80 yellow_flower 0
fill ~25 ~-1 ~81 ~25 ~-1 ~82 tallgrass 1
setblock ~25 ~-1 ~85 tallgrass 1
setblock ~26 ~-1 ~76 stonebrick 0
fill ~26 ~-1 ~78 ~26 ~-1 ~80 tallgrass 1
setblock ~26 ~-1 ~81 yellow_flower 0
fill ~26 ~-1 ~82 ~29 ~-1 ~82 tallgrass 1
setblock ~26 ~-1 ~84 tallgrass 1
fill ~26 ~-1 ~88 ~32 ~-1 ~88 tallgrass 1
fill ~26 ~-1 ~89 ~28 ~-1 ~89 tallgrass 1
fill ~27 ~-1 ~2 ~28 ~-1 ~2 tallgrass 1
fill ~27 ~-1 ~75 ~31 ~-1 ~75 stonebrick 0
fill ~27 ~-1 ~79 ~29 ~-1 ~79 tallgrass 1
fill ~27 ~-1 ~80 ~29 ~-1 ~80 tallgrass 1
fill ~27 ~-1 ~81 ~29 ~-1 ~81 tallgrass 1
setblock ~27 ~-1 ~85 tallgrass 1
setblock ~27 ~-1 ~86 yellow_flower 0
fill ~27 ~-1 ~87 ~31 ~-1 ~87 tallgrass 1
setblock ~27 ~-1 ~90 tallgrass 1
setblock ~28 ~-1 ~83 tallgrass 1
setblock ~28 ~-1 ~86 tallgrass 1
fill ~29 ~-1 ~3 ~29 ~-1 ~8 tallgrass 1
setblock ~29 ~-1 ~9 vine 11
fill ~29 ~-1 ~83 ~29 ~21 ~83 vine 8
fill ~29 ~-1 ~84 ~29 ~23 ~84 vine 8
setblock ~29 ~-1 ~89 yellow_flower 0
setblock ~29 ~-1 ~90 tallgrass 1
fill ~30 ~-1 ~4 ~32 ~-1 ~4 tallgrass 1
fill ~30 ~-1 ~5 ~33 ~-1 ~5 tallgrass 1
fill ~30 ~-1 ~6 ~30 ~-1 ~7 tallgrass 1
fill ~30 ~-1 ~76 ~31 ~-1 ~76 stonebrick 0
fill ~30 ~-1 ~77 ~31 ~-1 ~77 stonebrick 0
fill ~30 ~-1 ~78 ~31 ~-1 ~78 stonebrick 0
fill ~30 ~-1 ~79 ~31 ~-1 ~79 stonebrick 0
fill ~30 ~-1 ~80 ~31 ~-1 ~80 stonebrick 0
fill ~30 ~-1 ~81 ~31 ~-1 ~81 stonebrick 0
fill ~30 ~-1 ~82 ~31 ~-1 ~82 stonebrick 0
fill ~30 ~-1 ~83 ~31 ~-1 ~83 stonebrick 0
fill ~30 ~-1 ~84 ~41 ~-1 ~84 stonebrick 0
fill ~30 ~-1 ~89 ~31 ~-1 ~89 tallgrass 1
fill ~30 ~-1 ~92 ~31 ~-1 ~92 tallgrass 1
fill ~31 ~-1 ~7 ~32 ~-1 ~7 yellow_flower 0
setblock ~31 ~-1 ~86 tallgrass 1
setblock ~32 ~-1 ~2 yellow_flower 0
setblock ~32 ~-1 ~3 tallgrass 1
setblock ~32 ~-1 ~6 tallgrass 1
fill ~32 ~-1 ~9 ~34 ~-1 ~9 tallgrass 1
fill ~32 ~-1 ~75 ~62 ~-1 ~75 stonebrick 2
fill ~32 ~-1 ~76 ~62 ~-1 ~76 stonebrick 2
fill ~32 ~-1 ~77 ~51 ~-1 ~77 stonebrick 2
fill ~32 ~-1 ~78 ~48 ~-1 ~78 stonebrick 2
fill ~32 ~-1 ~79 ~48 ~-1 ~79 stonebrick 2
fill ~32 ~-1 ~80 ~48 ~-1 ~80 stonebrick 2
fill ~32 ~-1 ~81 ~48 ~-1 ~81 stonebrick 2
fill ~32 ~-1 ~82 ~48 ~-1 ~82 stonebrick 2
fill ~32 ~-1 ~83 ~48 ~-1 ~83 stonebrick 2
fill ~32 ~-1 ~85 ~32 ~21 ~85 vine 4
fill ~33 ~-1 ~7 ~34 ~-1 ~7 tallgrass 1
fill ~33 ~-1 ~8 ~34 ~-1 ~8 tallgrass 1
fill ~33 ~-1 ~87 ~38 ~-1 ~87 tallgrass 1
setblock ~33 ~-1 ~90 tallgrass 1
fill ~34 ~-1 ~86 ~35 ~-1 ~86 tallgrass 1
fill ~34 ~-1 ~88 ~34 ~-1 ~89 tallgrass 1
setblock ~34 ~-1 ~91 yellow_flower 0
fill ~35 ~-1 ~3 ~38 ~-1 ~3 tallgrass 1
fill ~35 ~-1 ~4 ~39 ~-1 ~4 tallgrass 1
fill ~35 ~-1 ~6 ~42 ~-1 ~6 brick_block 0
fill ~35 ~-1 ~7 ~35 ~17 ~7 brick_block 0
fill ~35 ~-1 ~8 ~35 ~15 ~8 brick_block 0
fill ~35 ~-1 ~9 ~35 ~15 ~9 brick_block 0
fill ~35 ~-1 ~10 ~41 ~-1 ~10 double_stone_slab 4
setblock ~35 ~-1 ~88 red_flower 0
fill ~36 ~-1 ~2 ~39 ~-1 ~2 tallgrass 1
fill ~36 ~-1 ~7 ~41 ~-1 ~7 netherrack 0
fill ~36 ~-1 ~8 ~41 ~-1 ~8 netherrack 0
fill ~36 ~-1 ~9 ~41 ~-1 ~9 netherrack 0
fill ~36 ~-1 ~34 ~36 ~-1 ~35 stonebrick 0
setblock ~36 ~-1 ~85 tallgrass 1
setblock ~36 ~-1 ~86 red_flower 0
fill ~36 ~-1 ~88 ~38 ~-1 ~88 tallgrass 1
fill ~36 ~-1 ~89 ~38 ~-1 ~89 tallgrass 1
fill ~36 ~-1 ~90 ~39 ~-1 ~90 tallgrass 1
fill ~36 ~-1 ~91 ~37 ~-1 ~91 tallgrass 1
fill ~37 ~-1 ~34 ~54 ~-1 ~34 stonebrick 2
fill ~37 ~-1 ~35 ~54 ~-1 ~35 stonebrick 2
setblock ~37 ~-1 ~36 stonebrick 0
fill ~37 ~-1 ~92 ~39 ~-1 ~92 tallgrass 1
fill ~38 ~-1 ~36 ~54 ~-1 ~36 stonebrick 2
setblock ~38 ~-1 ~37 stonebrick 0
setblock ~38 ~-1 ~39 stonebrick 1
fill ~38 ~-1 ~85 ~38 ~-1 ~90 tallgrass 1
setblock ~38 ~-1 ~91 yellow_flower 0
setblock ~39 ~-1 ~5 tallgrass 1
fill ~39 ~-1 ~37 ~54 ~-1 ~37 stonebrick 2
setblock ~39 ~-1 ~38 stonebrick 0
fill ~39 ~-1 ~39 ~54 ~-1 ~39 stonebrick 2
fill ~39 ~-1 ~85 ~39 ~11 ~85 vine 14
fill ~39 ~-1 ~86 ~39 ~12 ~86 vine 8
fill ~39 ~-1 ~87 ~39 ~12 ~87 vine 8
fill ~39 ~-1 ~88 ~39 ~12 ~88 vine 8
fill ~39 ~-1 ~91 ~40 ~-1 ~91 tallgrass 1
setblock ~39 ~-1 ~93 tallgrass 1
setblock ~40 ~-1 ~2 yellow_flower 0
fill ~40 ~-1 ~3 ~41 ~-1 ~3 tallgrass 1
setblock ~40 ~-1 ~31 monster_egg 4
fill ~40 ~-1 ~38 ~54 ~-1 ~38 stonebrick 2
fill ~40 ~-1 ~85 ~40 ~7 ~85 vine 12
fill ~40 ~-1 ~88 ~40 ~-1 ~89 tallgrass 1
fill ~41 ~-1 ~31 ~54 ~-1 ~31 stonebrick 2
setblock ~41 ~-1 ~59 stonebrick 0
fill ~41 ~-1 ~85 ~41 ~-1 ~90 stonebrick 0
setblock ~41 ~-1 ~91 yellow_flower 0
fill ~41 ~-1 ~93 ~43 ~-1 ~93 tallgrass 1
fill ~42 ~-1 ~5 ~44 ~-1 ~5 tallgrass 1
fill ~42 ~-1 ~7 ~42 ~14 ~7 brick_block 0
fill ~42 ~-1 ~8 ~42 ~14 ~8 brick_block 0
fill ~42 ~-1 ~9 ~42 ~14 ~9 brick_block 0
fill ~42 ~-1 ~10 ~54 ~-1 ~10 stonebrick 2
fill ~42 ~-1 ~58 ~43 ~-1 ~58 stonebrick 0
fill ~42 ~-1 ~59 ~43 ~-1 ~59 stonebrick 2
fill ~42 ~-1 ~84 ~48 ~-1 ~84 stonebrick 2
fill ~42 ~-1 ~85 ~48 ~-1 ~85 stonebrick 2
fill ~42 ~-1 ~86 ~48 ~-1 ~86 stonebrick 2
fill ~42 ~-1 ~87 ~48 ~-1 ~87 stonebrick 2
fill ~42 ~-1 ~88 ~49 ~-1 ~88 stonebrick 0
fill ~42 ~-1 ~89 ~49 ~-1 ~89 stonebrick 0
fill ~42 ~-1 ~90 ~49 ~-1 ~90 stonebrick 0
fill ~42 ~-1 ~91 ~43 ~-1 ~91 tallgrass 1
fill ~42 ~-1 ~92 ~44 ~-1 ~92 tallgrass 1
setblock ~43 ~-1 ~3 yellow_flower 0
setblock ~43 ~-1 ~4 tallgrass 1
fill ~43 ~-1 ~6 ~44 ~-1 ~6 tallgrass 1
fill ~43 ~-1 ~7 ~46 ~-1 ~7 tallgrass 1
setblock ~43 ~-1 ~8 vine 3
fill ~43 ~-1 ~9 ~55 ~-1 ~9 stonebrick 1
setblock ~44 ~-1 ~8 vine 1
setblock ~44 ~-1 ~58 stonebrick 2
setblock ~44 ~-1 ~59 stonebrick 0
setblock ~44 ~-1 ~93 yellow_flower 0
fill ~45 ~-1 ~2 ~45 ~-1 ~4 tallgrass 1
setblock ~45 ~-1 ~5 yellow_flower 0
setblock ~45 ~-1 ~6 red_flower 0
setblock ~45 ~-1 ~53 stonebrick 0
setblock ~45 ~-1 ~58 stonebrick 0
setblock ~45 ~-1 ~59 stonebrick 2
setblock ~45 ~-1 ~91 tallgrass 1
fill ~46 ~-1 ~3 ~47 ~-1 ~3 tallgrass 1
fill ~46 ~-1 ~4 ~47 ~-1 ~4 tallgrass 1
fill ~46 ~-1 ~5 ~46 ~-1 ~3 tallgrass 1
setblock ~46 ~-1 ~43 stonebrick 0
fill ~46 ~-1 ~53 ~65 ~-1 ~53 stonebrick 2
fill ~46 ~-1 ~58 ~62 ~-1 ~58 stonebrick 2
setblock ~46 ~-1 ~59 stonebrick 0
setblock ~47 ~-1 ~2 tallgrass 1
setblock ~47 ~-1 ~8 tallgrass 1
fill ~47 ~-1 ~43 ~69 ~-1 ~43 stonebrick 2
fill ~47 ~-1 ~59 ~62 ~-1 ~59 stonebrick 2
setblock ~47 ~-1 ~92 tallgrass 1
setblock ~48 ~-1 ~5 yellow_flower 0
setblock ~48 ~-1 ~64 stonebrick 0
setblock ~49 ~-1 ~8 tallgrass 1
setblock ~49 ~-1 ~49 stonebrick 0
setblock ~49 ~-1 ~61 stonebrick 0
fill ~49 ~-1 ~64 ~62 ~-1 ~64 stonebrick 2
fill ~49 ~-1 ~78 ~49 ~-1 ~90 stonebrick 0
setblock ~50 ~-1 ~4 tallgrass 1
setblock ~50 ~-1 ~6 tallgrass 1
fill ~50 ~-1 ~49 ~67 ~-1 ~49 stonebrick 2
fill ~50 ~-1 ~61 ~62 ~-1 ~61 stonebrick 2
setblock ~50 ~-1 ~80 tallgrass 1
setblock ~50 ~-1 ~87 tallgrass 1
setblock ~50 ~-1 ~88 yellow_flower 0
fill ~50 ~-1 ~89 ~53 ~-1 ~89 tallgrass 1
setblock ~50 ~-1 ~92 yellow_flower 0
setblock ~51 ~-1 ~3 yellow_flower 0
fill ~51 ~-1 ~5 ~54 ~-1 ~5 tallgrass 1
setblock ~51 ~-1 ~63 stonebrick 0
fill ~51 ~-1 ~79 ~56 ~-1 ~79 tallgrass 1
setblock ~51 ~-1 ~84 tallgrass 1
fill ~51 ~-1 ~86 ~52 ~-1 ~86 tallgrass 1
fill ~51 ~-1 ~88 ~52 ~-1 ~88 tallgrass 1
setblock ~51 ~-1 ~90 yellow_flower 0
fill ~52 ~-1 ~6 ~55 ~-1 ~6 tallgrass 1
fill ~52 ~-1 ~7 ~55 ~-1 ~7 tallgrass 1
fill ~52 ~-1 ~8 ~52 ~-1 ~5 tallgrass 1
fill ~52 ~-1 ~63 ~62 ~-1 ~63 stonebrick 2
fill ~52 ~-1 ~77 ~63 ~-1 ~77 stonebrick 0
fill ~52 ~-1 ~78 ~54 ~-1 ~78 tallgrass 1
fill ~52 ~-1 ~82 ~55 ~-1 ~82 tallgrass 1
fill ~52 ~-1 ~83 ~55 ~-1 ~83 tallgrass 1
setblock ~52 ~-1 ~87 tallgrass 1
fill ~52 ~-1 ~90 ~53 ~-1 ~90 tallgrass 1
fill ~53 ~-1 ~80 ~56 ~-1 ~80 tallgrass 1
setblock ~53 ~-1 ~81 yellow_flower 0
setblock ~54 ~-1 ~8 tallgrass 1
fill ~54 ~-1 ~81 ~57 ~-1 ~81 tallgrass 1
setblock ~54 ~-1 ~86 tallgrass 1
setblock ~54 ~-1 ~88 tallgrass 1
fill ~54 ~-1 ~91 ~55 ~-1 ~91 tallgrass 1
setblock ~55 ~-1 ~4 tallgrass 1
fill ~55 ~-1 ~10 ~55 ~-1 ~15 stonebrick 0
fill ~55 ~-1 ~23 ~65 ~-1 ~23 stonebrick 1 
fill ~55 ~-1 ~24 ~55 ~-1 ~42 stonebrick 1
setblock ~55 ~-1 ~89 tallgrass 1
fill ~55 ~-1 ~92 ~58 ~-1 ~92 tallgrass 1
setblock ~56 ~-1 ~5 tallgrass 1
fill ~56 ~-1 ~8 ~57 ~-1 ~8 tallgrass 1
fill ~56 ~-1 ~10 ~65 ~-1 ~10 tallgrass 1
fill ~56 ~-1 ~11 ~56 ~5 ~11 vine 2
fill ~56 ~-1 ~12 ~57 ~-1 ~12 tallgrass 1
fill ~56 ~-1 ~13 ~56 ~-1 ~12 tallgrass 1
fill ~56 ~-1 ~15 ~62 ~-1 ~15 stonebrick 0
fill ~56 ~-1 ~25 ~56 ~25 ~25 vine 7
fill ~56 ~-1 ~26 ~57 ~-1 ~26 vine 3
setblock ~56 ~-1 ~27 tallgrass 1
fill ~56 ~-1 ~31 ~56 ~-1 ~33 vine 2
fill ~56 ~-1 ~34 ~56 ~25 ~34 vine 3
setblock ~56 ~-1 ~35 tallgrass 1
fill ~56 ~-1 ~37 ~59 ~-1 ~37 tallgrass 1
fill ~56 ~-1 ~38 ~56 ~-1 ~39 tallgrass 1
fill ~56 ~-1 ~41 ~56 ~19 ~41 vine 3
fill ~56 ~-1 ~42 ~58 ~-1 ~42 vine 3
fill ~56 ~-1 ~87 ~56 ~-1 ~88 tallgrass 1
setblock ~56 ~-1 ~89 red_flower 0
fill ~56 ~-1 ~90 ~59 ~-1 ~90 tallgrass 1
setblock ~56 ~-1 ~91 yellow_flower 0
fill ~57 ~-1 ~6 ~57 ~-1 ~12 tallgrass 1
setblock ~57 ~-1 ~25 tallgrass 1
fill ~57 ~-1 ~30 ~61 ~-1 ~30 tallgrass 1
fill ~57 ~-1 ~33 ~57 ~29 ~33 vine 6
fill ~57 ~-1 ~35 ~57 ~13 ~35 vine 2
setblock ~57 ~-1 ~36 tallgrass 1
setblock ~57 ~-1 ~38 red_flower 0
fill ~57 ~-1 ~39 ~59 ~-1 ~39 tallgrass 1
fill ~57 ~-1 ~40 ~57 ~-1 ~39 tallgrass 1
fill ~57 ~-1 ~88 ~58 ~-1 ~88 tallgrass 1
fill ~57 ~-1 ~89 ~58 ~-1 ~89 tallgrass 1
setblock ~57 ~-1 ~91 red_flower 0
setblock ~58 ~-1 ~9 yellow_flower 0
fill ~58 ~-1 ~11 ~61 ~-1 ~11 tallgrass 1
setblock ~58 ~-1 ~12 yellow_flower 0
setblock ~58 ~-1 ~24 tallgrass 1
fill ~58 ~-1 ~26 ~61 ~-1 ~26 tallgrass 1
fill ~58 ~-1 ~28 ~60 ~-1 ~28 tallgrass 1
fill ~58 ~-1 ~31 ~58 ~-1 ~33 tallgrass 1
setblock ~58 ~-1 ~35 tallgrass 1
fill ~58 ~-1 ~38 ~59 ~-1 ~38 tallgrass 1
fill ~58 ~-1 ~91 ~60 ~-1 ~91 tallgrass 1
fill ~59 ~-1 ~9 ~61 ~-1 ~9 tallgrass 1
setblock ~59 ~-1 ~12 tallgrass 1
setblock ~59 ~-1 ~25 tallgrass 1
fill ~59 ~-1 ~27 ~61 ~-1 ~27 tallgrass 1
setblock ~59 ~-1 ~29 yellow_flower 0
setblock ~59 ~-1 ~31 yellow_flower 0
fill ~59 ~-1 ~32 ~60 ~-1 ~32 tallgrass 1
setblock ~59 ~-1 ~34 tallgrass 1
fill ~59 ~-1 ~40 ~61 ~-1 ~40 tallgrass 1
fill ~59 ~-1 ~42 ~60 ~-1 ~42 vine 1
setblock ~59 ~-1 ~86 yellow_flower 0
fill ~60 ~-1 ~24 ~61 ~-1 ~24 tallgrass 1
setblock ~60 ~-1 ~25 red_flower 0
fill ~60 ~-1 ~29 ~62 ~-1 ~29 tallgrass 1
setblock ~60 ~-1 ~31 tallgrass 1
setblock ~60 ~-1 ~33 tallgrass 1
setblock ~60 ~-1 ~36 tallgrass 1
setblock ~60 ~-1 ~41 tallgrass 1
setblock ~60 ~-1 ~82 tallgrass 1
setblock ~60 ~-1 ~86 tallgrass 1
setblock ~60 ~-1 ~89 tallgrass 1
setblock ~60 ~-1 ~93 tallgrass 1
fill ~61 ~-1 ~7 ~64 ~-1 ~7 tallgrass 1
fill ~61 ~-1 ~8 ~64 ~-1 ~8 tallgrass 1
fill ~61 ~-1 ~25 ~62 ~-1 ~25 tallgrass 1
setblock ~61 ~-1 ~31 stone_slab 0
fill ~61 ~-1 ~32 ~61 ~0 ~32 stonebrick 1
fill ~61 ~-1 ~33 ~61 ~0 ~33 stonebrick 1
fill ~61 ~-1 ~34 ~61 ~0 ~34 stonebrick 1
setblock ~61 ~-1 ~35 stone_slab 0
fill ~61 ~-1 ~37 ~65 ~-1 ~37 tallgrass 1
setblock ~61 ~-1 ~38 red_flower 0
fill ~61 ~-1 ~39 ~63 ~-1 ~39 tallgrass 1
fill ~61 ~-1 ~78 ~61 ~15 ~78 vine 4
fill ~61 ~-1 ~84 ~63 ~-1 ~84 tallgrass 1
fill ~61 ~-1 ~85 ~64 ~-1 ~85 tallgrass 1
setblock ~62 ~-1 ~5 yellow_flower 0
setblock ~62 ~-1 ~6 tallgrass 1
setblock ~62 ~-1 ~9 yellow_flower 0
setblock ~62 ~-1 ~11 yellow_flower 0
setblock ~62 ~-1 ~13 yellow_flower 0
setblock ~62 ~-1 ~30 stone_slab 0
fill ~62 ~-1 ~31 ~62 ~0 ~31 stonebrick 1
fill ~62 ~-1 ~32 ~66 ~-1 ~32 stone_slab 0
fill ~62 ~-1 ~33 ~63 ~-1 ~33 stone_slab 0
fill ~62 ~-1 ~34 ~66 ~-1 ~34 stone_slab 0
fill ~62 ~-1 ~35 ~62 ~0 ~35 stonebrick 1
setblock ~62 ~-1 ~36 stone_slab 0
fill ~62 ~-1 ~38 ~66 ~-1 ~38 tallgrass 1
fill ~62 ~-1 ~78 ~62 ~17 ~78 vine 12
setblock ~62 ~-1 ~83 tallgrass 1
fill ~62 ~-1 ~86 ~66 ~-1 ~86 tallgrass 1
fill ~62 ~-1 ~91 ~65 ~-1 ~91 tallgrass 1
setblock ~63 ~-1 ~9 tallgrass 1
fill ~63 ~-1 ~11 ~63 ~-1 ~12 tallgrass 1
fill ~63 ~-1 ~15 ~65 ~-1 ~15 stonebrick 1
fill ~63 ~-1 ~26 ~65 ~-1 ~26 tallgrass 1
fill ~63 ~-1 ~30 ~65 ~-1 ~30 stonebrick 1
fill ~63 ~-1 ~31 ~65 ~-1 ~31 stone_slab 0
fill ~63 ~-1 ~35 ~65 ~-1 ~35 stone_slab 0
fill ~63 ~-1 ~36 ~65 ~-1 ~36 stonebrick 1
fill ~63 ~-1 ~40 ~64 ~-1 ~40 tallgrass 1
fill ~63 ~-1 ~58 ~63 ~1 ~58 stonebrick 0
fill ~63 ~-1 ~59 ~63 ~1 ~59 stonebrick 0
fill ~63 ~-1 ~62 ~67 ~-1 ~62 brick_block 0
fill ~63 ~-1 ~63 ~67 ~-1 ~63 brick_block 0
fill ~63 ~-1 ~64 ~67 ~-1 ~64 brick_block 0
fill ~63 ~-1 ~65 ~67 ~-1 ~65 brick_block 0
fill ~63 ~-1 ~66 ~67 ~-1 ~66 brick_block 0
fill ~63 ~-1 ~67 ~67 ~-1 ~67 brick_block 0
fill ~63 ~-1 ~68 ~67 ~-1 ~68 brick_block 0
fill ~63 ~-1 ~69 ~67 ~-1 ~69 brick_block 0
fill ~63 ~-1 ~70 ~67 ~-1 ~70 brick_block 0
fill ~63 ~-1 ~71 ~63 ~-1 ~77 stonebrick 0
setblock ~63 ~-1 ~78 tallgrass 1
fill ~63 ~-1 ~79 ~63 ~3 ~79 vine 4
setblock ~63 ~-1 ~81 tallgrass 1
setblock ~63 ~-1 ~83 red_flower 0
fill ~63 ~-1 ~87 ~64 ~-1 ~87 tallgrass 1
setblock ~63 ~-1 ~89 yellow_flower 0
fill ~63 ~-1 ~92 ~65 ~-1 ~92 tallgrass 1
setblock ~64 ~-1 ~6 tallgrass 1
setblock ~64 ~-1 ~9 yellow_flower 0
fill ~64 ~-1 ~33 ~64 ~1 ~33 stonebrick 1
fill ~64 ~-1 ~58 ~72 ~-1 ~58 stonebrick 1
fill ~64 ~-1 ~60 ~64 ~20 ~60 vine 6
fill ~64 ~-1 ~61 ~64 ~21 ~61 vine 2
fill ~64 ~-1 ~71 ~64 ~19 ~71 vine 2
fill ~64 ~-1 ~77 ~64 ~20 ~77 vine 7
fill ~64 ~-1 ~78 ~64 ~29 ~78 vine 2
setblock ~64 ~-1 ~83 tallgrass 1
setblock ~64 ~-1 ~84 yellow_flower 0
fill ~64 ~-1 ~89 ~65 ~-1 ~89 tallgrass 1
setblock ~65 ~-1 ~11 tallgrass 1
setblock ~65 ~-1 ~13 tallgrass 1
fill ~65 ~-1 ~16 ~65 ~-1 ~23 stonebrick 1
fill ~65 ~-1 ~27 ~69 ~-1 ~27 tallgrass 1
fill ~65 ~-1 ~33 ~66 ~-1 ~33 stone_slab 0
setblock ~65 ~-1 ~56 tallgrass 1
fill ~65 ~-1 ~60 ~66 ~-1 ~60 vine 4
setblock ~65 ~-1 ~78 tallgrass 1
fill ~65 ~-1 ~80 ~65 ~-1 ~82 tallgrass 1
setblock ~65 ~-1 ~85 yellow_flower 0
setblock ~66 ~-1 ~15 tallgrass 1
fill ~66 ~-1 ~17 ~66 ~8 ~17 vine 2
fill ~66 ~-1 ~23 ~68 ~-1 ~23 tallgrass 1
setblock ~66 ~-1 ~30 stone_slab 0
fill ~66 ~-1 ~31 ~66 ~0 ~31 stonebrick 1
fill ~66 ~-1 ~35 ~66 ~0 ~35 stonebrick 1
setblock ~66 ~-1 ~36 stone_slab 0
setblock ~66 ~-1 ~40 tallgrass 1
setblock ~66 ~-1 ~53 red_mushroom 0
fill ~66 ~-1 ~54 ~67 ~-1 ~54 tallgrass 1
fill ~66 ~-1 ~55 ~66 ~-1 ~54 tallgrass 1
fill ~66 ~-1 ~57 ~67 ~-1 ~57 stonebrick 1
fill ~66 ~-1 ~81 ~69 ~-1 ~81 tallgrass 1
setblock ~66 ~-1 ~82 yellow_flower 0
setblock ~66 ~-1 ~83 tallgrass 1
setblock ~66 ~-1 ~84 yellow_flower 0
fill ~67 ~-1 ~8 ~68 ~-1 ~8 tallgrass 1
fill ~67 ~-1 ~11 ~68 ~-1 ~11 tallgrass 1
fill ~67 ~-1 ~12 ~69 ~-1 ~12 tallgrass 1
setblock ~67 ~-1 ~14 tallgrass 1
fill ~67 ~-1 ~24 ~69 ~-1 ~24 tallgrass 1
fill ~67 ~-1 ~25 ~70 ~-1 ~25 tallgrass 1
fill ~67 ~-1 ~26 ~70 ~-1 ~26 tallgrass 1
setblock ~67 ~-1 ~31 stone_slab 0
fill ~67 ~-1 ~32 ~67 ~0 ~32 stonebrick 1
fill ~67 ~-1 ~33 ~67 ~0 ~33 stonebrick 1
fill ~67 ~-1 ~34 ~67 ~0 ~34 stonebrick 1
setblock ~67 ~-1 ~35 stone_slab 0
fill ~67 ~-1 ~37 ~71 ~-1 ~37 tallgrass 1
fill ~67 ~-1 ~52 ~67 ~-1 ~54 tallgrass 1
fill ~67 ~-1 ~59 ~67 ~9 ~59 vine 14
setblock ~67 ~-1 ~71 tallgrass 1
fill ~67 ~-1 ~78 ~68 ~-1 ~78 tallgrass 1
fill ~67 ~-1 ~79 ~67 ~-1 ~82 tallgrass 1
setblock ~67 ~-1 ~83 yellow_flower 0
setblock ~67 ~-1 ~88 tallgrass 1
fill ~68 ~-1 ~9 ~70 ~-1 ~9 tallgrass 1
fill ~68 ~-1 ~10 ~70 ~-1 ~10 tallgrass 1
setblock ~68 ~-1 ~13 tallgrass 1
fill ~68 ~-1 ~16 ~72 ~-1 ~16 tallgrass 1
fill ~68 ~-1 ~17 ~68 ~-1 ~19 tallgrass 1
fill ~68 ~-1 ~28 ~69 ~-1 ~28 tallgrass 1
setblock ~68 ~-1 ~29 yellow_flower 0
fill ~68 ~-1 ~30 ~69 ~-1 ~30 tallgrass 1
fill ~68 ~-1 ~31 ~68 ~-1 ~34 tallgrass 1
setblock ~68 ~-1 ~35 red_flower 0
setblock ~68 ~-1 ~38 red_flower 0
setblock ~68 ~-1 ~39 tallgrass 1
setblock ~68 ~-1 ~40 yellow_flower 0
setblock ~68 ~-1 ~49 stonebrick 0
fill ~68 ~-1 ~50 ~69 ~-1 ~50 red_mushroom 0
setblock ~68 ~-1 ~51 tallgrass 1
fill ~68 ~-1 ~52 ~68 ~3 ~52 log 0
fill ~68 ~-1 ~56 ~69 ~-1 ~56 tallgrass 1
fill ~68 ~-1 ~57 ~71 ~-1 ~57 stonebrick 2
fill ~68 ~-1 ~59 ~68 ~10 ~59 vine 4
fill ~68 ~-1 ~60 ~68 ~18 ~60 vine 4
fill ~68 ~-1 ~75 ~69 ~-1 ~75 tallgrass 1
setblock ~68 ~-1 ~80 tallgrass 1
fill ~68 ~-1 ~82 ~69 ~-1 ~82 tallgrass 1
setblock ~69 ~-1 ~11 red_flower 0
fill ~69 ~-1 ~14 ~69 ~-1 ~16 tallgrass 1
setblock ~69 ~-1 ~17 red_flower 0
fill ~69 ~-1 ~18 ~71 ~-1 ~18 tallgrass 1
setblock ~69 ~-1 ~23 yellow_flower 0
setblock ~69 ~-1 ~31 yellow_flower 0
fill ~69 ~-1 ~32 ~70 ~-1 ~32 tallgrass 1
fill ~69 ~-1 ~33 ~70 ~-1 ~33 tallgrass 1
fill ~69 ~-1 ~35 ~71 ~-1 ~35 tallgrass 1
setblock ~69 ~-1 ~36 red_flower 0
fill ~69 ~-1 ~38 ~70 ~-1 ~38 tallgrass 1
setblock ~69 ~-1 ~39 red_flower 0
fill ~69 ~-1 ~40 ~71 ~-1 ~40 tallgrass 1
fill ~69 ~-1 ~41 ~69 ~21 ~41 vine 1
fill ~69 ~-1 ~48 ~70 ~-1 ~48 red_mushroom 0
setblock ~69 ~-1 ~51 red_mushroom 0
fill ~69 ~-1 ~52 ~70 ~-1 ~52 tallgrass 1
fill ~69 ~-1 ~53 ~69 ~-1 ~52 tallgrass 1
fill ~69 ~-1 ~59 ~70 ~-1 ~59 vine 12
setblock ~69 ~-1 ~65 tallgrass 1
fill ~69 ~-1 ~72 ~71 ~-1 ~72 tallgrass 1
fill ~69 ~-1 ~73 ~72 ~-1 ~73 tallgrass 1
fill ~69 ~-1 ~74 ~72 ~-1 ~74 tallgrass 1
setblock ~69 ~-1 ~80 red_flower 0
setblock ~70 ~-1 ~8 tallgrass 1
setblock ~70 ~-1 ~14 yellow_flower 0
fill ~70 ~-1 ~15 ~71 ~-1 ~15 tallgrass 1
fill ~70 ~-1 ~17 ~71 ~-1 ~17 tallgrass 1
fill ~70 ~-1 ~19 ~70 ~-1 ~23 tallgrass 1
setblock ~70 ~-1 ~36 tallgrass 1
setblock ~70 ~-1 ~39 yellow_flower 0
setblock ~70 ~-1 ~41 tallgrass 1
fill ~70 ~-1 ~42 ~70 ~17 ~42 vine 9
fill ~70 ~-1 ~43 ~72 ~-1 ~43 stonebrick 1
fill ~70 ~-1 ~44 ~72 ~-1 ~44 stonebrick 1
setblock ~70 ~-1 ~51 tallgrass 1
setblock ~70 ~-1 ~53 red_mushroom 0
fill ~70 ~-1 ~54 ~70 ~-1 ~55 tallgrass 1
setblock ~70 ~-1 ~56 red_mushroom 0
setblock ~70 ~-1 ~61 tallgrass 1
fill ~70 ~-1 ~63 ~74 ~-1 ~63 tallgrass 1
fill ~70 ~-1 ~66 ~71 ~-1 ~66 red_flower 0
fill ~70 ~-1 ~69 ~73 ~-1 ~69 tallgrass 1
setblock ~70 ~-1 ~76 tallgrass 1
setblock ~70 ~-1 ~80 yellow_flower 0
fill ~71 ~-1 ~14 ~72 ~-1 ~14 tallgrass 1
fill ~71 ~-1 ~20 ~73 ~-1 ~20 tallgrass 1
fill ~71 ~-1 ~21 ~72 ~-1 ~21 tallgrass 1
fill ~71 ~-1 ~22 ~72 ~-1 ~22 tallgrass 1
fill ~71 ~-1 ~23 ~72 ~-1 ~23 yellow_flower 0
setblock ~71 ~-1 ~33 red_flower 0
setblock ~71 ~-1 ~39 tallgrass 1
fill ~71 ~-1 ~41 ~71 ~21 ~41 vine 1
fill ~71 ~-1 ~45 ~72 ~-1 ~45 stonebrick 1
fill ~71 ~-1 ~46 ~72 ~-1 ~46 stonebrick 1
fill ~71 ~-1 ~47 ~72 ~-1 ~47 stonebrick 1
fill ~71 ~-1 ~48 ~71 ~11 ~48 stonebrick 2
fill ~71 ~-1 ~49 ~71 ~23 ~49 stonebrick 2
fill ~71 ~-1 ~50 ~71 ~23 ~50 stonebrick 2
fill ~71 ~-1 ~51 ~71 ~23 ~51 stonebrick 2
fill ~71 ~-1 ~52 ~71 ~23 ~52 stonebrick 2
fill ~71 ~-1 ~53 ~71 ~11 ~53 stonebrick 2
fill ~71 ~-1 ~54 ~72 ~-1 ~54 stonebrick 1
fill ~71 ~-1 ~55 ~72 ~-1 ~55 stonebrick 1
fill ~71 ~-1 ~56 ~71 ~11 ~56 stonebrick 2
setblock ~71 ~-1 ~60 tallgrass 1
fill ~71 ~-1 ~62 ~74 ~-1 ~62 tallgrass 1
setblock ~71 ~-1 ~65 yellow_flower 0
fill ~71 ~-1 ~67 ~73 ~-1 ~67 tallgrass 1
fill ~71 ~-1 ~68 ~74 ~-1 ~68 tallgrass 1
fill ~71 ~-1 ~70 ~72 ~-1 ~70 tallgrass 1
fill ~71 ~-1 ~71 ~71 ~-1 ~67 tallgrass 1
setblock ~71 ~-1 ~75 tallgrass 1
setblock ~72 ~-1 ~9 tallgrass 1
fill ~72 ~-1 ~17 ~72 ~-1 ~18 yellow_flower 0
fill ~72 ~-1 ~19 ~73 ~-1 ~19 tallgrass 1
setblock ~72 ~-1 ~27 tallgrass 1
setblock ~72 ~-1 ~34 tallgrass 1
fill ~72 ~-1 ~41 ~74 ~-1 ~41 tallgrass 1
fill ~72 ~-1 ~42 ~72 ~22 ~42 vine 2
fill ~72 ~-1 ~48 ~72 ~-1 ~58 stonebrick 1
fill ~72 ~-1 ~59 ~72 ~22 ~59 vine 2
setblock ~72 ~-1 ~64 yellow_flower 0
setblock ~72 ~-1 ~72 yellow_flower 0
setblock ~72 ~-1 ~80 tallgrass 1
fill ~72 ~-1 ~88 ~73 ~-1 ~88 tallgrass 1
setblock ~73 ~-1 ~24 tallgrass 1
fill ~73 ~-1 ~36 ~74 ~-1 ~36 tallgrass 1
fill ~73 ~-1 ~37 ~73 ~-1 ~41 tallgrass 1
fill ~73 ~-1 ~44 ~73 ~-1 ~48 tallgrass 1
setblock ~73 ~-1 ~51 tallgrass 1
setblock ~73 ~-1 ~56 yellow_flower 0
fill ~73 ~-1 ~57 ~76 ~-1 ~57 tallgrass 1
fill ~73 ~-1 ~60 ~73 ~-1 ~69 tallgrass 1
setblock ~74 ~-1 ~21 tallgrass 1
setblock ~74 ~-1 ~38 yellow_flower 0
fill ~74 ~-1 ~39 ~75 ~-1 ~39 tallgrass 1
fill ~74 ~-1 ~40 ~74 ~-1 ~39 tallgrass 1
setblock ~74 ~-1 ~43 red_flower 0
fill ~74 ~-1 ~45 ~75 ~-1 ~45 tallgrass 1
fill ~74 ~-1 ~46 ~75 ~-1 ~46 tallgrass 1
fill ~74 ~-1 ~47 ~76 ~-1 ~47 tallgrass 1
setblock ~74 ~-1 ~49 tallgrass 1
fill ~74 ~-1 ~53 ~74 ~-1 ~57 tallgrass 1
fill ~74 ~-1 ~61 ~75 ~-1 ~61 tallgrass 1
fill ~74 ~-1 ~64 ~75 ~-1 ~64 tallgrass 1
fill ~74 ~-1 ~65 ~74 ~-1 ~66 tallgrass 1
fill ~74 ~-1 ~79 ~76 ~-1 ~79 tallgrass 1
fill ~74 ~-1 ~80 ~74 ~-1 ~82 tallgrass 1
fill ~75 ~-1 ~37 ~76 ~-1 ~37 tallgrass 1
fill ~75 ~-1 ~38 ~76 ~-1 ~38 tallgrass 1
setblock ~75 ~-1 ~40 yellow_flower 0
fill ~75 ~-1 ~44 ~76 ~-1 ~44 tallgrass 1
setblock ~75 ~-1 ~48 tallgrass 1
fill ~75 ~-1 ~54 ~76 ~-1 ~54 tallgrass 1
fill ~75 ~-1 ~55 ~75 ~-1 ~58 tallgrass 1
setblock ~75 ~-1 ~62 yellow_flower 0
setblock ~75 ~-1 ~80 yellow_flower 0
setblock ~75 ~-1 ~81 red_flower 0
fill ~75 ~-1 ~82 ~75 ~-1 ~84 tallgrass 1
setblock ~76 ~-1 ~40 tallgrass 1
setblock ~76 ~-1 ~42 tallgrass 1
setblock ~76 ~-1 ~55 yellow_flower 0
setblock ~76 ~-1 ~56 tallgrass 1
setblock ~76 ~-1 ~58 tallgrass 1
setblock ~76 ~-1 ~63 tallgrass 1
setblock ~76 ~-1 ~66 tallgrass 1
setblock ~76 ~-1 ~69 yellow_flower 0
setblock ~76 ~-1 ~70 tallgrass 1
setblock ~76 ~-1 ~80 tallgrass 1
fill ~5 ~0 ~4 ~27 ~0 ~4 stonebrick 2
fill ~5 ~0 ~5 ~5 ~0 ~31 stonebrick 2
setblock ~5 ~0 ~32 stonebrick 1
fill ~5 ~0 ~34 ~5 ~0 ~35 stonebrick 1
fill ~5 ~0 ~36 ~6 ~0 ~36 stonebrick 2
fill ~5 ~0 ~37 ~6 ~0 ~37 stonebrick 2
fill ~5 ~0 ~38 ~6 ~0 ~38 stonebrick 2
fill ~5 ~0 ~39 ~6 ~0 ~39 stonebrick 2
fill ~5 ~0 ~40 ~6 ~0 ~40 stonebrick 2
fill ~5 ~0 ~41 ~6 ~0 ~41 stonebrick 2
fill ~5 ~0 ~42 ~6 ~0 ~42 stonebrick 2
fill ~5 ~0 ~43 ~5 ~0 ~50 stonebrick 2
fill ~6 ~0 ~6 ~6 ~11 ~6 stonebrick 2
fill ~6 ~0 ~7 ~6 ~1 ~7 stonebrick 2
fill ~6 ~0 ~8 ~6 ~1 ~8 stonebrick 2
fill ~6 ~0 ~9 ~6 ~1 ~9 stonebrick 2
fill ~6 ~0 ~10 ~6 ~1 ~10 stonebrick 2
fill ~6 ~0 ~11 ~6 ~1 ~11 stonebrick 2
fill ~6 ~0 ~12 ~6 ~1 ~12 stonebrick 2
fill ~6 ~0 ~13 ~6 ~11 ~13 stonebrick 2
fill ~6 ~0 ~14 ~6 ~11 ~14 stonebrick 2
fill ~6 ~0 ~15 ~6 ~1 ~15 stonebrick 2
fill ~6 ~0 ~16 ~6 ~1 ~16 stonebrick 2
fill ~6 ~0 ~17 ~6 ~1 ~17 stonebrick 2
fill ~6 ~0 ~18 ~6 ~1 ~18 stonebrick 2
fill ~6 ~0 ~19 ~6 ~1 ~19 stonebrick 2
fill ~6 ~0 ~20 ~6 ~1 ~20 stonebrick 2
fill ~6 ~0 ~21 ~6 ~1 ~21 stonebrick 2
fill ~6 ~0 ~23 ~6 ~11 ~23 stonebrick 2
fill ~6 ~0 ~24 ~6 ~11 ~24 stonebrick 2
fill ~6 ~0 ~25 ~6 ~1 ~25 stonebrick 2
fill ~6 ~0 ~26 ~6 ~1 ~26 stonebrick 2
fill ~6 ~0 ~27 ~6 ~1 ~27 stonebrick 2
fill ~6 ~0 ~28 ~6 ~1 ~28 stonebrick 2
fill ~6 ~0 ~29 ~6 ~1 ~29 stonebrick 2
fill ~6 ~0 ~30 ~6 ~1 ~30 stonebrick 2
fill ~6 ~0 ~31 ~6 ~1 ~31 stonebrick 2
fill ~6 ~0 ~32 ~6 ~4 ~32 stonebrick 2
fill ~6 ~0 ~33 ~23 ~0 ~33 stonebrick 2
fill ~6 ~0 ~34 ~6 ~0 ~42 stonebrick 2
fill ~6 ~0 ~43 ~6 ~1 ~43 stonebrick 1
fill ~6 ~0 ~44 ~6 ~6 ~44 stonebrick 2
fill ~6 ~0 ~45 ~6 ~6 ~45 stonebrick 2
fill ~6 ~0 ~46 ~6 ~6 ~46 stonebrick 2
fill ~6 ~0 ~47 ~6 ~6 ~47 stonebrick 2
fill ~6 ~0 ~48 ~6 ~6 ~48 stonebrick 2
fill ~6 ~0 ~49 ~6 ~6 ~49 stonebrick 2
fill ~6 ~0 ~50 ~22 ~0 ~50 stonebrick 2
fill ~7 ~0 ~5 ~15 ~0 ~5 stonebrick 2
fill ~7 ~0 ~22 ~7 ~1 ~22 stonebrick 2
fill ~9 ~0 ~35 ~9 ~2 ~35 crafting_table 0
fill ~9 ~0 ~36 ~9 ~2 ~36 crafting_table 0
fill ~9 ~0 ~37 ~11 ~0 ~37 crafting_table 0
fill ~9 ~0 ~74 ~9 ~22 ~74 vine 8
fill ~9 ~0 ~75 ~9 ~22 ~75 vine 8
setblock ~10 ~0 ~35 wooden_door 1
setblock ~10 ~0 ~40 carpet 0
setblock ~10 ~0 ~41 carpet 14
setblock ~10 ~0 ~42 carpet 0
setblock ~10 ~0 ~43 carpet 14
setblock ~10 ~0 ~44 carpet 0
setblock ~10 ~0 ~45 carpet 14
setblock ~10 ~0 ~46 carpet 0
setblock ~10 ~0 ~47 carpet 14
fill ~11 ~0 ~35 ~11 ~2 ~35 crafting_table 0
fill ~11 ~0 ~36 ~11 ~2 ~36 crafting_table 0
setblock ~11 ~0 ~40 carpet 14
setblock ~11 ~0 ~41 carpet 0
setblock ~11 ~0 ~42 carpet 14
setblock ~11 ~0 ~43 carpet 0
setblock ~11 ~0 ~44 carpet 14
setblock ~11 ~0 ~45 carpet 0
setblock ~11 ~0 ~46 carpet 14
setblock ~11 ~0 ~47 carpet 0
fill ~11 ~0 ~65 ~11 ~17 ~65 vine 8
fill ~11 ~0 ~66 ~11 ~4 ~66 vine 8
setblock ~11 ~0 ~67 stonebrick 0
fill ~11 ~0 ~68 ~12 ~0 ~68 stonebrick 2
fill ~11 ~0 ~69 ~12 ~0 ~69 stonebrick 2
fill ~11 ~0 ~70 ~11 ~-1 ~70 stonebrick 2
fill ~11 ~0 ~71 ~11 ~-1 ~71 stonebrick 2
setblock ~11 ~0 ~72 stonebrick 0
setblock ~12 ~0 ~40 carpet 0
setblock ~12 ~0 ~41 carpet 14
setblock ~12 ~0 ~42 carpet 0
setblock ~12 ~0 ~43 carpet 14
setblock ~12 ~0 ~44 carpet 0
setblock ~12 ~0 ~45 carpet 14
setblock ~12 ~0 ~46 carpet 0
setblock ~12 ~0 ~47 carpet 14
fill ~12 ~0 ~64 ~12 ~2 ~64 vine 9
fill ~12 ~0 ~65 ~14 ~0 ~65 stonebrick 2
fill ~12 ~0 ~66 ~13 ~0 ~66 stonebrick 2
fill ~12 ~0 ~67 ~12 ~17 ~67 stonebrick 2
fill ~12 ~0 ~70 ~12 ~1 ~70 stonebrick 0
fill ~12 ~0 ~71 ~12 ~1 ~71 stonebrick 0
fill ~12 ~0 ~72 ~12 ~1 ~72 stonebrick 2
fill ~12 ~0 ~73 ~12 ~15 ~73 stonebrick 2
fill ~12 ~0 ~74 ~12 ~16 ~74 stonebrick 2
fill ~12 ~0 ~75 ~13 ~0 ~75 stonebrick 2
fill ~12 ~0 ~77 ~12 ~16 ~77 vine 1
setblock ~13 ~0 ~40 carpet 14
setblock ~13 ~0 ~41 carpet 0
setblock ~13 ~0 ~42 carpet 14
setblock ~13 ~0 ~43 carpet 0
setblock ~13 ~0 ~44 carpet 14
setblock ~13 ~0 ~45 carpet 0
setblock ~13 ~0 ~46 carpet 14
setblock ~13 ~0 ~47 carpet 0
fill ~13 ~0 ~64 ~13 ~1 ~64 stonebrick 1
fill ~13 ~0 ~74 ~13 ~1 ~74 stonebrick 1
fill ~13 ~0 ~76 ~14 ~0 ~76 stonebrick 2
fill ~13 ~0 ~78 ~13 ~16 ~78 vine 6
fill ~14 ~0 ~35 ~14 ~1 ~35 furnace 2
setblock ~14 ~0 ~36 furnace 5
fill ~14 ~0 ~37 ~16 ~0 ~37 furnace 3
setblock ~14 ~0 ~40 carpet 0
setblock ~14 ~0 ~41 carpet 14
setblock ~14 ~0 ~42 carpet 0
setblock ~14 ~0 ~43 carpet 14
setblock ~14 ~0 ~44 carpet 0
setblock ~14 ~0 ~45 carpet 14
setblock ~14 ~0 ~46 carpet 0
setblock ~14 ~0 ~47 carpet 14
fill ~14 ~0 ~64 ~16 ~0 ~64 stonebrick 2
fill ~14 ~0 ~77 ~16 ~0 ~77 stonebrick 2
fill ~14 ~0 ~78 ~14 ~7 ~78 vine 12
setblock ~15 ~0 ~35 wooden_door 1
setblock ~15 ~0 ~36 torch 5
setblock ~15 ~0 ~40 carpet 14
setblock ~15 ~0 ~41 carpet 0
setblock ~15 ~0 ~42 carpet 14
setblock ~15 ~0 ~43 carpet 0
setblock ~15 ~0 ~44 carpet 14
setblock ~15 ~0 ~45 carpet 0
setblock ~15 ~0 ~46 carpet 14
setblock ~15 ~0 ~47 carpet 0
fill ~15 ~0 ~62 ~15 ~17 ~62 vine 2
fill ~15 ~0 ~63 ~15 ~1 ~63 stonebrick 1
fill ~15 ~0 ~78 ~23 ~0 ~78 stonebrick 2
fill ~16 ~0 ~35 ~16 ~0 ~36 furnace 4
setblock ~16 ~0 ~40 carpet 0
setblock ~16 ~0 ~41 carpet 14
setblock ~16 ~0 ~42 carpet 0
setblock ~16 ~0 ~43 carpet 14
setblock ~16 ~0 ~44 carpet 0
setblock ~16 ~0 ~45 carpet 14
setblock ~16 ~0 ~46 carpet 0
setblock ~16 ~0 ~47 carpet 14
fill ~16 ~0 ~63 ~21 ~0 ~63 stonebrick 2
fill ~17 ~0 ~5 ~27 ~0 ~5 stonebrick 2
setblock ~17 ~0 ~40 carpet 14
setblock ~17 ~0 ~41 carpet 0
setblock ~17 ~0 ~42 carpet 14
setblock ~17 ~0 ~43 carpet 0
setblock ~17 ~0 ~44 carpet 14
setblock ~17 ~0 ~45 carpet 0
setblock ~17 ~0 ~46 carpet 14
setblock ~17 ~0 ~47 carpet 0
setblock ~18 ~0 ~40 carpet 0
setblock ~18 ~0 ~41 carpet 14
setblock ~18 ~0 ~42 carpet 0
setblock ~18 ~0 ~43 carpet 14
setblock ~18 ~0 ~44 carpet 0
setblock ~18 ~0 ~45 carpet 14
setblock ~18 ~0 ~46 carpet 0
setblock ~18 ~0 ~47 carpet 14
fill ~19 ~0 ~35 ~19 ~2 ~35 chest 4
fill ~19 ~0 ~36 ~21 ~0 ~36 noteblock 0
fill ~19 ~0 ~37 ~19 ~2 ~37 chest 4
setblock ~19 ~0 ~40 carpet 14
setblock ~19 ~0 ~41 carpet 0
setblock ~19 ~0 ~42 carpet 14
setblock ~19 ~0 ~43 carpet 0
setblock ~19 ~0 ~44 carpet 14
setblock ~19 ~0 ~45 carpet 0
setblock ~19 ~0 ~46 carpet 14
setblock ~19 ~0 ~47 carpet 0
fill ~19 ~0 ~51 ~19 ~4 ~51 stonebrick 2
fill ~19 ~0 ~52 ~19 ~1 ~52 stonebrick 2
fill ~19 ~0 ~53 ~19 ~1 ~53 stonebrick 2
fill ~19 ~0 ~54 ~19 ~11 ~54 stonebrick 2
fill ~19 ~0 ~55 ~19 ~1 ~55 stonebrick 2
fill ~19 ~0 ~56 ~19 ~1 ~56 stonebrick 2
fill ~19 ~0 ~57 ~19 ~11 ~57 stonebrick 2
fill ~19 ~0 ~58 ~19 ~1 ~58 stonebrick 2
fill ~19 ~0 ~59 ~19 ~1 ~59 stonebrick 2
fill ~19 ~0 ~60 ~19 ~11 ~60 stonebrick 2
fill ~19 ~0 ~61 ~19 ~1 ~61 stonebrick 2
fill ~19 ~0 ~62 ~19 ~1 ~62 stonebrick 2
fill ~20 ~0 ~35 ~20 ~2 ~35 noteblock 0
fill ~20 ~0 ~37 ~20 ~2 ~37 noteblock 0
setblock ~20 ~0 ~51 glowstone 0
fill ~20 ~0 ~52 ~20 ~1 ~52 stonebrick 0
fill ~20 ~0 ~53 ~20 ~1 ~53 stonebrick 0
fill ~20 ~0 ~54 ~20 ~1 ~54 stonebrick 0
fill ~20 ~0 ~55 ~20 ~1 ~55 stonebrick 0
fill ~20 ~0 ~56 ~20 ~1 ~56 stonebrick 0
fill ~20 ~0 ~57 ~20 ~1 ~57 stonebrick 0
fill ~20 ~0 ~58 ~20 ~1 ~58 stonebrick 0
fill ~20 ~0 ~59 ~20 ~1 ~59 stonebrick 0
fill ~20 ~0 ~60 ~20 ~1 ~60 stonebrick 0
fill ~20 ~0 ~61 ~20 ~1 ~61 stonebrick 0
fill ~20 ~0 ~62 ~21 ~0 ~62 glowstone 0
fill ~21 ~0 ~35 ~21 ~2 ~35 chest 5
fill ~21 ~0 ~37 ~21 ~2 ~37 chest 5
fill ~21 ~0 ~51 ~22 ~0 ~51 stonebrick 0
fill ~21 ~0 ~52 ~21 ~0 ~62 glowstone 0
setblock ~22 ~0 ~52 stone_brick_stairs 3
setblock ~22 ~0 ~53 stone_slab 5
setblock ~22 ~0 ~61 stone_slab 5
setblock ~22 ~0 ~62 stone_brick_stairs 2
fill ~22 ~0 ~63 ~22 ~1 ~63 stonebrick 0
fill ~22 ~0 ~64 ~22 ~4 ~64 stonebrick 0
fill ~22 ~0 ~77 ~24 ~0 ~77 stonebrick 2
fill ~23 ~0 ~10 ~31 ~0 ~10 stonebrick 2
fill ~23 ~0 ~11 ~23 ~0 ~40 stonebrick 2
fill ~23 ~0 ~41 ~23 ~5 ~41 planks 5
setblock ~23 ~0 ~42 dark_oak_door 2
fill ~23 ~0 ~43 ~23 ~5 ~43 planks 5
fill ~23 ~0 ~44 ~23 ~7 ~44 stonebrick 2
fill ~23 ~0 ~45 ~23 ~7 ~45 stonebrick 2
fill ~23 ~0 ~46 ~23 ~7 ~46 stonebrick 2
fill ~23 ~0 ~47 ~23 ~7 ~47 stonebrick 2
fill ~23 ~0 ~48 ~23 ~7 ~48 stonebrick 2
fill ~23 ~0 ~49 ~23 ~7 ~49 stonebrick 2
fill ~23 ~0 ~50 ~23 ~1 ~50 stonebrick 0
fill ~23 ~0 ~63 ~23 ~6 ~63 stonebrick 1
fill ~23 ~0 ~64 ~23 ~6 ~64 stonebrick 1
fill ~23 ~0 ~65 ~23 ~6 ~65 stonebrick 0
fill ~23 ~0 ~66 ~26 ~0 ~66 stonebrick 0
fill ~24 ~0 ~67 ~26 ~0 ~67 stonebrick 2
fill ~24 ~0 ~76 ~25 ~0 ~76 stonebrick 2
fill ~25 ~0 ~75 ~26 ~0 ~75 stonebrick 2
fill ~26 ~0 ~68 ~26 ~11 ~68 stonebrick 2
fill ~26 ~0 ~69 ~26 ~3 ~69 stonebrick 2
fill ~26 ~0 ~70 ~26 ~5 ~70 planks 5
setblock ~26 ~0 ~71 dark_oak_door 2
fill ~26 ~0 ~72 ~26 ~5 ~72 planks 5
fill ~26 ~0 ~73 ~26 ~8 ~73 stonebrick 2
fill ~26 ~0 ~74 ~31 ~0 ~74 stonebrick 2
fill ~27 ~0 ~6 ~27 ~0 ~10 stonebrick 2
fill ~27 ~0 ~66 ~27 ~4 ~66 stonebrick 2
fill ~28 ~0 ~8 ~28 ~13 ~8 vine 2
fill ~28 ~0 ~9 ~28 ~13 ~9 vine 3
fill ~28 ~0 ~66 ~28 ~5 ~66 planks 5
fill ~29 ~0 ~9 ~29 ~12 ~9 vine 9
setblock ~29 ~0 ~36 dark_oak_fence 0
setblock ~29 ~0 ~38 dark_oak_fence 0
setblock ~29 ~0 ~41 dark_oak_fence 0
setblock ~29 ~0 ~43 dark_oak_fence 0
setblock ~29 ~0 ~66 dark_oak_door 1
fill ~29 ~0 ~82 ~29 ~27 ~82 vine 8
fill ~30 ~0 ~66 ~30 ~5 ~66 planks 5
fill ~30 ~0 ~81 ~30 ~13 ~81 vine 8
fill ~30 ~0 ~82 ~30 ~12 ~82 vine 9
fill ~31 ~0 ~11 ~34 ~0 ~11 log 8
fill ~31 ~0 ~12 ~34 ~0 ~12 log 8
fill ~31 ~0 ~13 ~31 ~0 ~18 carpet 14
fill ~31 ~0 ~19 ~32 ~0 ~19 dark_oak_fence 0
fill ~31 ~0 ~20 ~32 ~0 ~20 dark_oak_fence 0
setblock ~31 ~0 ~36 dark_oak_fence 0
setblock ~31 ~0 ~38 dark_oak_fence 0
setblock ~31 ~0 ~41 dark_oak_fence 0
setblock ~31 ~0 ~43 dark_oak_fence 0
fill ~31 ~0 ~66 ~32 ~0 ~66 stonebrick 0
fill ~31 ~0 ~67 ~31 ~16 ~67 stonebrick 0
fill ~31 ~0 ~68 ~31 ~4 ~68 stonebrick 0
fill ~31 ~0 ~69 ~31 ~1 ~69 stonebrick 0
fill ~31 ~0 ~70 ~31 ~1 ~70 stonebrick 0
fill ~31 ~0 ~71 ~31 ~0 ~74 stonebrick 2
fill ~31 ~0 ~75 ~31 ~0 ~77 stonebrick 0
fill ~31 ~0 ~78 ~31 ~16 ~78 stonebrick 2
fill ~31 ~0 ~79 ~31 ~16 ~79 stonebrick 2
fill ~31 ~0 ~80 ~31 ~16 ~80 stonebrick 2
fill ~31 ~0 ~81 ~31 ~16 ~81 stonebrick 2
fill ~31 ~0 ~82 ~31 ~16 ~82 stonebrick 2
fill ~31 ~0 ~83 ~41 ~0 ~83 stonebrick 2
fill ~32 ~0 ~10 ~32 ~2 ~10 stonebrick 1
fill ~32 ~0 ~13 ~45 ~0 ~13 carpet 12
fill ~32 ~0 ~14 ~45 ~0 ~14 carpet 12
fill ~32 ~0 ~15 ~45 ~0 ~15 carpet 12
fill ~32 ~0 ~16 ~45 ~0 ~16 carpet 12
fill ~32 ~0 ~17 ~45 ~0 ~17 carpet 12
fill ~32 ~0 ~18 ~34 ~0 ~18 carpet 14
fill ~32 ~0 ~53 ~44 ~0 ~53 carpet 14
fill ~32 ~0 ~54 ~39 ~0 ~54 carpet 14
fill ~32 ~0 ~55 ~33 ~0 ~55 carpet 14
fill ~32 ~0 ~56 ~34 ~0 ~56 carpet 14
fill ~32 ~0 ~57 ~34 ~0 ~57 carpet 14
fill ~32 ~0 ~58 ~33 ~0 ~58 carpet 14
fill ~32 ~0 ~59 ~39 ~0 ~59 carpet 14
fill ~32 ~0 ~60 ~44 ~0 ~60 carpet 14
fill ~33 ~0 ~7 ~33 ~4 ~7 vine 1
fill ~33 ~0 ~8 ~33 ~31 ~8 vine 9
fill ~33 ~0 ~10 ~34 ~0 ~10 stonebrick 2
fill ~33 ~0 ~34 ~33 ~1 ~34 dark_oak_fence 0
fill ~33 ~0 ~45 ~33 ~1 ~45 dark_oak_fence 0
fill ~33 ~0 ~66 ~34 ~0 ~66 stonebrick 2
fill ~33 ~0 ~84 ~33 ~8 ~84 vine 6
setblock ~34 ~0 ~20 log 1
setblock ~34 ~0 ~23 log 1
setblock ~34 ~0 ~55 carpet 0
setblock ~34 ~0 ~58 carpet 0
fill ~34 ~0 ~84 ~35 ~0 ~84 vine 4
fill ~35 ~0 ~6 ~42 ~0 ~6 brick_block 0
fill ~35 ~0 ~10 ~35 ~17 ~10 stonebrick 0
fill ~35 ~0 ~12 ~42 ~0 ~12 carpet 14
fill ~35 ~0 ~18 ~36 ~0 ~18 double_stone_slab2 0
fill ~35 ~0 ~19 ~36 ~0 ~19 double_stone_slab2 0
setblock ~35 ~0 ~30 dark_oak_fence 0
setblock ~35 ~0 ~32 dark_oak_fence 0
setblock ~35 ~0 ~47 dark_oak_fence 0
setblock ~35 ~0 ~49 dark_oak_fence 0
fill ~35 ~0 ~55 ~36 ~0 ~55 carpet 4
fill ~35 ~0 ~56 ~37 ~0 ~56 carpet 4
fill ~35 ~0 ~57 ~37 ~0 ~57 carpet 4
fill ~35 ~0 ~58 ~36 ~0 ~58 carpet 4
fill ~35 ~0 ~66 ~35 ~5 ~66 planks 5
fill ~36 ~0 ~7 ~41 ~0 ~7 fire 15
fill ~36 ~0 ~8 ~41 ~0 ~8 fire 15
fill ~36 ~0 ~9 ~41 ~0 ~9 fire 15
fill ~36 ~0 ~10 ~36 ~18 ~10 double_stone_slab 4
fill ~36 ~0 ~11 ~36 ~4 ~11 stonebrick 0
setblock ~36 ~0 ~66 dark_oak_door 1
fill ~37 ~0 ~10 ~40 ~0 ~10 stonebrick 0
fill ~37 ~0 ~18 ~40 ~0 ~18 carpet 14
setblock ~37 ~0 ~20 log 1
setblock ~37 ~0 ~23 log 1
setblock ~37 ~0 ~30 dark_oak_fence 0
setblock ~37 ~0 ~32 dark_oak_fence 0
setblock ~37 ~0 ~47 dark_oak_fence 0
setblock ~37 ~0 ~49 dark_oak_fence 0
setblock ~37 ~0 ~55 carpet 0
setblock ~37 ~0 ~58 carpet 0
fill ~37 ~0 ~66 ~37 ~5 ~66 planks 5
fill ~38 ~0 ~55 ~39 ~0 ~55 carpet 14
fill ~38 ~0 ~56 ~38 ~0 ~57 carpet 0
fill ~38 ~0 ~58 ~39 ~0 ~58 carpet 14
fill ~38 ~0 ~66 ~54 ~0 ~66 stonebrick 2
fill ~38 ~0 ~86 ~38 ~29 ~86 vine 4
fill ~39 ~0 ~56 ~44 ~0 ~56 carpet 14
fill ~39 ~0 ~57 ~44 ~0 ~57 carpet 14
fill ~39 ~0 ~62 ~39 ~1 ~62 dark_oak_fence 0
fill ~39 ~0 ~64 ~39 ~1 ~64 dark_oak_fence 0
fill ~39 ~0 ~67 ~39 ~0 ~75 stonebrick 0
fill ~39 ~0 ~84 ~39 ~10 ~84 vine 12
setblock ~40 ~0 ~20 log 1
setblock ~40 ~0 ~23 log 1
setblock ~40 ~0 ~30 dark_oak_fence 0
setblock ~40 ~0 ~32 dark_oak_fence 0
fill ~40 ~0 ~47 ~40 ~1 ~47 planks 5
setblock ~40 ~0 ~49 dark_oak_fence 0
fill ~40 ~0 ~54 ~41 ~0 ~54 carpet 0
setblock ~40 ~0 ~55 carpet 4
setblock ~40 ~0 ~58 carpet 4
fill ~40 ~0 ~59 ~41 ~0 ~59 carpet 0
fill ~40 ~0 ~67 ~42 ~0 ~67 stonebrick 1
fill ~40 ~0 ~68 ~42 ~0 ~68 stonebrick 1
fill ~40 ~0 ~69 ~42 ~0 ~69 stonebrick 1
fill ~40 ~0 ~70 ~42 ~0 ~70 stonebrick 1
fill ~40 ~0 ~71 ~42 ~0 ~71 stonebrick 1
fill ~40 ~0 ~72 ~42 ~0 ~72 stonebrick 1
fill ~40 ~0 ~73 ~42 ~0 ~73 stonebrick 1
fill ~40 ~0 ~74 ~43 ~0 ~74 stonebrick 0
fill ~40 ~0 ~75 ~43 ~0 ~75 stonebrick 0
fill ~40 ~0 ~84 ~40 ~4 ~84 vine 4
fill ~41 ~0 ~10 ~41 ~37 ~10 double_stone_slab 4
fill ~41 ~0 ~11 ~41 ~4 ~11 stonebrick 0
fill ~41 ~0 ~18 ~42 ~0 ~18 double_stone_slab2 0
fill ~41 ~0 ~19 ~42 ~0 ~19 double_stone_slab2 0
setblock ~41 ~0 ~55 carpet 0
setblock ~41 ~0 ~58 carpet 0
fill ~41 ~0 ~62 ~41 ~1 ~62 dark_oak_fence 0
fill ~41 ~0 ~64 ~41 ~1 ~64 dark_oak_fence 0
fill ~41 ~0 ~85 ~41 ~2 ~85 vine 12
fill ~41 ~0 ~86 ~41 ~4 ~86 vine 9
fill ~42 ~0 ~10 ~42 ~14 ~10 stonebrick 0
setblock ~42 ~0 ~30 dark_oak_fence 0
setblock ~42 ~0 ~32 dark_oak_fence 0
setblock ~42 ~0 ~47 dark_oak_fence 0
setblock ~42 ~0 ~49 dark_oak_fence 0
fill ~42 ~0 ~54 ~44 ~0 ~54 carpet 14
fill ~42 ~0 ~55 ~44 ~0 ~55 carpet 14
fill ~42 ~0 ~58 ~44 ~0 ~58 carpet 14
fill ~42 ~0 ~59 ~44 ~0 ~59 carpet 14
fill ~42 ~0 ~84 ~42 ~1 ~84 stonebrick 2
fill ~42 ~0 ~85 ~42 ~3 ~85 stonebrick 2
fill ~42 ~0 ~86 ~42 ~4 ~86 stonebrick 2
fill ~42 ~0 ~87 ~47 ~0 ~87 stonebrick 2
fill ~43 ~0 ~7 ~43 ~14 ~7 vine 2
fill ~43 ~0 ~8 ~43 ~14 ~8 vine 2
fill ~43 ~0 ~9 ~43 ~8 ~9 vine 11
fill ~43 ~0 ~10 ~46 ~0 ~10 stonebrick 2
fill ~43 ~0 ~11 ~45 ~0 ~11 log 8
fill ~43 ~0 ~12 ~45 ~0 ~12 log 8
fill ~43 ~0 ~18 ~46 ~0 ~18 carpet 14
setblock ~43 ~0 ~20 log 1
setblock ~43 ~0 ~23 log 1
fill ~43 ~0 ~67 ~44 ~0 ~67 web 0
fill ~43 ~0 ~68 ~43 ~0 ~67 web 0
fill ~43 ~0 ~84 ~47 ~0 ~84 planks 5
fill ~43 ~0 ~85 ~47 ~0 ~85 planks 5
fill ~43 ~0 ~86 ~47 ~0 ~86 planks 5
fill ~43 ~0 ~88 ~47 ~0 ~88 stonebrick 0
fill ~43 ~0 ~89 ~47 ~0 ~89 stonebrick 0
fill ~44 ~0 ~34 ~44 ~1 ~34 dark_oak_fence 0
fill ~44 ~0 ~45 ~44 ~1 ~45 dark_oak_fence 0
fill ~44 ~0 ~74 ~44 ~4 ~74 planks 5
fill ~45 ~0 ~19 ~46 ~0 ~19 dark_oak_fence 0
fill ~45 ~0 ~20 ~46 ~0 ~20 dark_oak_fence 0
fill ~45 ~0 ~62 ~45 ~6 ~62 planks 5
fill ~45 ~0 ~63 ~45 ~6 ~63 planks 5
fill ~45 ~0 ~64 ~45 ~6 ~64 planks 5
fill ~45 ~0 ~65 ~45 ~6 ~65 planks 5
setblock ~45 ~0 ~74 dark_oak_door 3
fill ~46 ~0 ~12 ~46 ~0 ~18 carpet 14
setblock ~46 ~0 ~36 dark_oak_fence 0
fill ~46 ~0 ~38 ~46 ~1 ~38 planks 5
setblock ~46 ~0 ~41 dark_oak_fence 0
setblock ~46 ~0 ~43 dark_oak_fence 0
fill ~46 ~0 ~62 ~51 ~0 ~62 planks 1
fill ~46 ~0 ~74 ~46 ~4 ~74 planks 5
fill ~47 ~0 ~8 ~47 ~13 ~8 vine 1
fill ~47 ~0 ~10 ~48 ~0 ~10 stonebrick 1
fill ~47 ~0 ~74 ~47 ~8 ~74 stonebrick 0
fill ~47 ~0 ~75 ~47 ~2 ~75 stonebrick 0
fill ~48 ~0 ~9 ~48 ~13 ~9 vine 3
setblock ~48 ~0 ~36 dark_oak_fence 0
fill ~48 ~0 ~38 ~48 ~2 ~38 planks 5
setblock ~48 ~0 ~41 dark_oak_fence 0
setblock ~48 ~0 ~43 dark_oak_fence 0
fill ~48 ~0 ~74 ~48 ~0 ~75 web 0
fill ~48 ~0 ~76 ~62 ~0 ~76 stonebrick 2
fill ~48 ~0 ~77 ~48 ~1 ~77 stonebrick 2
fill ~48 ~0 ~78 ~48 ~3 ~78 stonebrick 2
fill ~48 ~0 ~79 ~48 ~4 ~79 stonebrick 2
fill ~48 ~0 ~80 ~48 ~3 ~80 stonebrick 2
fill ~48 ~0 ~81 ~48 ~3 ~81 stonebrick 2
fill ~48 ~0 ~82 ~48 ~3 ~82 stonebrick 2
fill ~48 ~0 ~83 ~48 ~3 ~83 stonebrick 2
fill ~48 ~0 ~84 ~48 ~3 ~84 stonebrick 2
fill ~48 ~0 ~85 ~48 ~3 ~85 stonebrick 2
fill ~48 ~0 ~86 ~48 ~3 ~86 stonebrick 2
fill ~48 ~0 ~87 ~48 ~6 ~87 stonebrick 1
fill ~49 ~0 ~9 ~49 ~20 ~9 vine 1
fill ~49 ~0 ~10 ~50 ~0 ~10 stonebrick 2
setblock ~49 ~0 ~75 web 0
fill ~51 ~0 ~10 ~51 ~2 ~10 stonebrick 1
fill ~52 ~0 ~10 ~53 ~0 ~10 stonebrick 2
fill ~52 ~0 ~62 ~52 ~6 ~62 planks 5
fill ~52 ~0 ~63 ~52 ~6 ~63 planks 5
fill ~52 ~0 ~64 ~52 ~6 ~64 planks 5
setblock ~52 ~0 ~65 dark_oak_door 2
fill ~54 ~0 ~9 ~55 ~0 ~9 vine 1
fill ~54 ~0 ~10 ~54 ~4 ~10 stonebrick 1
fill ~54 ~0 ~11 ~54 ~0 ~12 stonebrick 2
setblock ~54 ~0 ~13 stonebrick 0
fill ~54 ~0 ~14 ~54 ~4 ~14 stonebrick 2
fill ~54 ~0 ~15 ~54 ~0 ~14 stonebrick 2
fill ~54 ~0 ~16 ~54 ~5 ~16 stonebrick 0
fill ~54 ~0 ~17 ~54 ~5 ~17 stonebrick 2
fill ~54 ~0 ~18 ~54 ~5 ~18 planks 5
setblock ~54 ~0 ~19 dark_oak_door 0
fill ~54 ~0 ~20 ~54 ~5 ~20 planks 5
fill ~54 ~0 ~21 ~54 ~5 ~21 stonebrick 2
fill ~54 ~0 ~22 ~54 ~5 ~22 stonebrick 0
fill ~54 ~0 ~23 ~54 ~4 ~23 stonebrick 2
fill ~54 ~0 ~24 ~54 ~4 ~24 stonebrick 2
fill ~54 ~0 ~25 ~54 ~3 ~25 stonebrick 2
fill ~54 ~0 ~26 ~54 ~2 ~26 stonebrick 2
fill ~54 ~0 ~27 ~54 ~0 ~36 stonebrick 2
fill ~54 ~0 ~37 ~54 ~2 ~37 stonebrick 1
fill ~54 ~0 ~38 ~54 ~2 ~38 stonebrick 2
fill ~54 ~0 ~39 ~54 ~5 ~39 stonebrick 2
fill ~54 ~0 ~40 ~54 ~5 ~40 stonebrick 2
fill ~54 ~0 ~41 ~54 ~5 ~41 stonebrick 2
fill ~54 ~0 ~42 ~54 ~2 ~42 stonebrick 2
fill ~54 ~0 ~43 ~54 ~0 ~38 stonebrick 2
fill ~54 ~0 ~44 ~54 ~2 ~44 stonebrick 0
fill ~54 ~0 ~45 ~54 ~0 ~44 stonebrick 0
fill ~54 ~0 ~46 ~54 ~5 ~46 stonebrick 2
fill ~54 ~0 ~47 ~54 ~5 ~47 stonebrick 2
fill ~54 ~0 ~48 ~54 ~5 ~48 stonebrick 2
fill ~54 ~0 ~49 ~54 ~5 ~49 stonebrick 2
fill ~54 ~0 ~50 ~54 ~5 ~50 planks 5
setblock ~54 ~0 ~51 dark_oak_door 0
fill ~54 ~0 ~52 ~54 ~5 ~52 planks 5
fill ~54 ~0 ~53 ~54 ~5 ~53 stonebrick 2
fill ~54 ~0 ~54 ~54 ~5 ~54 stonebrick 2
fill ~54 ~0 ~55 ~54 ~6 ~55 stonebrick 0
fill ~54 ~0 ~56 ~54 ~2 ~56 stonebrick 2
fill ~54 ~0 ~57 ~54 ~2 ~57 stonebrick 0
fill ~54 ~0 ~58 ~54 ~2 ~58 stonebrick 2
fill ~54 ~0 ~59 ~54 ~2 ~59 stonebrick 2
fill ~54 ~0 ~60 ~54 ~4 ~60 stonebrick 2
fill ~54 ~0 ~61 ~54 ~4 ~61 stonebrick 2
setblock ~54 ~0 ~62 wooden_door 2
fill ~54 ~0 ~63 ~54 ~4 ~63 stonebrick 2
fill ~54 ~0 ~64 ~54 ~4 ~64 stonebrick 2
fill ~54 ~0 ~65 ~54 ~4 ~65 stonebrick 2
fill ~55 ~0 ~16 ~64 ~0 ~16 stonebrick 2
fill ~55 ~0 ~22 ~63 ~0 ~22 stonebrick 2
fill ~55 ~0 ~23 ~55 ~4 ~23 vine 2
fill ~55 ~0 ~24 ~55 ~5 ~24 vine 2
fill ~55 ~0 ~27 ~55 ~4 ~27 vine 2
fill ~55 ~0 ~41 ~55 ~4 ~41 vine 1
fill ~55 ~0 ~43 ~55 ~3 ~43 stonebrick 1
fill ~55 ~0 ~44 ~69 ~0 ~44 stonebrick 2
fill ~55 ~0 ~45 ~70 ~0 ~45 stonebrick 2
fill ~55 ~0 ~57 ~61 ~0 ~57 stonebrick 2
fill ~56 ~0 ~10 ~56 ~14 ~10 vine 2
fill ~56 ~0 ~12 ~56 ~19 ~12 vine 2
fill ~56 ~0 ~13 ~56 ~11 ~13 vine 3
fill ~56 ~0 ~26 ~56 ~22 ~26 vine 3
fill ~56 ~0 ~27 ~56 ~13 ~27 vine 3
fill ~56 ~0 ~32 ~56 ~9 ~32 vine 2
fill ~56 ~0 ~33 ~56 ~23 ~33 vine 2
fill ~56 ~0 ~39 ~56 ~23 ~39 vine 7
fill ~56 ~0 ~42 ~58 ~0 ~42 vine 3
fill ~57 ~0 ~25 ~57 ~27 ~25 vine 2
fill ~57 ~0 ~26 ~57 ~29 ~26 vine 7
fill ~57 ~0 ~43 ~57 ~10 ~43 vine 3
fill ~58 ~0 ~23 ~58 ~4 ~23 vine 4
fill ~58 ~0 ~32 ~58 ~30 ~32 vine 2
fill ~59 ~0 ~42 ~60 ~0 ~42 vine 1
fill ~59 ~0 ~58 ~61 ~0 ~58 web 0
fill ~60 ~0 ~75 ~60 ~8 ~75 ladder 2
fill ~61 ~0 ~15 ~64 ~0 ~15 vine 1
fill ~61 ~0 ~23 ~64 ~0 ~23 vine 4
fill ~61 ~0 ~59 ~61 ~3 ~59 web 0
fill ~61 ~0 ~60 ~61 ~0 ~61 web 0
fill ~61 ~0 ~63 ~61 ~5 ~63 stonebrick 2
fill ~61 ~0 ~69 ~61 ~5 ~69 stonebrick 2
setblock ~61 ~0 ~75 web 0
fill ~61 ~0 ~77 ~61 ~5 ~77 vine 8
fill ~62 ~0 ~59 ~62 ~11 ~59 stonebrick 2
fill ~62 ~0 ~60 ~62 ~11 ~60 stonebrick 2
fill ~62 ~0 ~61 ~62 ~8 ~61 stonebrick 2
fill ~62 ~0 ~62 ~62 ~11 ~62 stonebrick 2
fill ~62 ~0 ~64 ~62 ~1 ~64 stonebrick 2
fill ~62 ~0 ~65 ~62 ~0 ~67 stonebrick 0
fill ~62 ~0 ~68 ~62 ~19 ~68 stonebrick 2
fill ~62 ~0 ~70 ~62 ~5 ~70 stonebrick 2
fill ~62 ~0 ~71 ~62 ~8 ~71 stonebrick 2
fill ~62 ~0 ~72 ~62 ~8 ~72 stonebrick 2
fill ~62 ~0 ~73 ~62 ~8 ~73 stonebrick 2
fill ~62 ~0 ~74 ~62 ~9 ~74 stonebrick 2
fill ~62 ~0 ~75 ~62 ~9 ~75 stonebrick 2
fill ~63 ~0 ~30 ~65 ~0 ~30 stonebrick 1
fill ~63 ~0 ~36 ~65 ~0 ~36 stonebrick 1
fill ~63 ~0 ~57 ~65 ~0 ~57 stonebrick 2
fill ~63 ~0 ~63 ~66 ~0 ~63 brick_block 0
fill ~63 ~0 ~64 ~65 ~0 ~64 netherrack 0
fill ~63 ~0 ~65 ~65 ~0 ~65 netherrack 0
fill ~63 ~0 ~66 ~65 ~0 ~66 netherrack 0
fill ~63 ~0 ~67 ~65 ~0 ~67 netherrack 0
fill ~63 ~0 ~68 ~65 ~0 ~68 netherrack 0
fill ~63 ~0 ~69 ~66 ~0 ~69 brick_block 0
fill ~63 ~0 ~70 ~64 ~0 ~70 vine 6
fill ~63 ~0 ~71 ~63 ~4 ~71 vine 2
fill ~63 ~0 ~76 ~63 ~5 ~76 vine 2
fill ~63 ~0 ~77 ~63 ~5 ~77 vine 2
fill ~64 ~0 ~17 ~64 ~1 ~17 stonebrick 2
fill ~64 ~0 ~18 ~64 ~1 ~18 stonebrick 2
fill ~64 ~0 ~19 ~64 ~1 ~19 stonebrick 2
fill ~64 ~0 ~20 ~64 ~1 ~20 stonebrick 2
fill ~64 ~0 ~21 ~64 ~1 ~21 stonebrick 2
fill ~64 ~0 ~22 ~64 ~6 ~22 stonebrick 1
fill ~64 ~0 ~62 ~64 ~21 ~62 vine 3
fill ~65 ~0 ~15 ~65 ~7 ~15 vine 7
fill ~65 ~0 ~16 ~65 ~4 ~16 vine 3
fill ~65 ~0 ~17 ~65 ~3 ~17 vine 2
fill ~65 ~0 ~18 ~65 ~7 ~18 vine 4
fill ~65 ~0 ~60 ~66 ~0 ~60 vine 4
fill ~65 ~0 ~70 ~67 ~0 ~70 vine 4
fill ~66 ~0 ~57 ~66 ~1 ~57 stonebrick 1
fill ~66 ~0 ~64 ~66 ~8 ~64 brick_block 0
fill ~66 ~0 ~65 ~66 ~5 ~65 brick_block 0
fill ~66 ~0 ~66 ~66 ~8 ~66 brick_block 0
fill ~66 ~0 ~67 ~66 ~5 ~67 brick_block 0
fill ~66 ~0 ~68 ~66 ~8 ~68 brick_block 0
fill ~67 ~0 ~57 ~71 ~0 ~57 stonebrick 2
fill ~69 ~0 ~59 ~70 ~0 ~59 vine 12
fill ~70 ~0 ~41 ~70 ~21 ~41 vine 1
fill ~70 ~0 ~44 ~70 ~3 ~44 stonebrick 1
fill ~71 ~0 ~45 ~71 ~2 ~45 stonebrick 1
fill ~71 ~0 ~46 ~71 ~-1 ~46 stonebrick 1
fill ~71 ~0 ~47 ~71 ~11 ~47 stonebrick 2
fill ~71 ~0 ~54 ~71 ~11 ~54 stonebrick 2
fill ~71 ~0 ~55 ~71 ~-1 ~55 stonebrick 1
fill ~71 ~0 ~60 ~71 ~12 ~60 vine 4
fill ~72 ~0 ~43 ~72 ~16 ~43 vine 2
fill ~72 ~0 ~44 ~72 ~6 ~44 vine 2
fill ~72 ~0 ~45 ~72 ~10 ~45 vine 2
fill ~72 ~0 ~46 ~72 ~10 ~46 vine 2
fill ~72 ~0 ~47 ~72 ~10 ~47 vine 2
fill ~72 ~0 ~51 ~72 ~23 ~51 vine 2
fill ~72 ~0 ~52 ~72 ~14 ~52 vine 3
fill ~72 ~0 ~53 ~72 ~10 ~53 vine 2
fill ~72 ~0 ~54 ~72 ~10 ~54 vine 2
fill ~72 ~0 ~55 ~72 ~10 ~55 vine 2
fill ~72 ~0 ~57 ~72 ~17 ~57 vine 6
fill ~72 ~0 ~58 ~72 ~24 ~58 vine 3
fill ~5 ~1 ~5 ~5 ~10 ~5 vine 8
fill ~5 ~1 ~13 ~5 ~10 ~13 vine 8
fill ~5 ~1 ~14 ~5 ~10 ~14 vine 8
fill ~5 ~1 ~23 ~5 ~10 ~23 vine 8
fill ~5 ~1 ~24 ~5 ~10 ~24 vine 8
fill ~6 ~1 ~4 ~9 ~1 ~4 vine 1
fill ~6 ~1 ~5 ~26 ~1 ~5 stonebrick 2
setblock ~6 ~1 ~22 stonebrick 2
fill ~6 ~1 ~33 ~22 ~1 ~33 stonebrick 2
fill ~6 ~1 ~34 ~6 ~6 ~34 stonebrick 1
fill ~6 ~1 ~35 ~6 ~1 ~34 stonebrick 1
fill ~6 ~1 ~36 ~6 ~6 ~36 stonebrick 2
fill ~6 ~1 ~37 ~6 ~6 ~37 stonebrick 2
fill ~6 ~1 ~38 ~6 ~6 ~38 stonebrick 2
fill ~6 ~1 ~39 ~6 ~6 ~39 stonebrick 2
fill ~6 ~1 ~40 ~6 ~6 ~40 stonebrick 2
fill ~6 ~1 ~41 ~6 ~2 ~41 stonebrick 2
fill ~6 ~1 ~42 ~6 ~1 ~36 stonebrick 2
fill ~6 ~1 ~50 ~22 ~1 ~50 stonebrick 2
setblock ~6 ~1 ~51 slime 0
fill ~7 ~1 ~6 ~26 ~1 ~6 stonebrick 2
fill ~7 ~1 ~7 ~26 ~1 ~7 stonebrick 2
fill ~7 ~1 ~8 ~26 ~1 ~8 stonebrick 2
fill ~7 ~1 ~9 ~26 ~1 ~9 stonebrick 2
fill ~7 ~1 ~10 ~22 ~1 ~10 stonebrick 2
fill ~7 ~1 ~11 ~13 ~1 ~11 stonebrick 2
fill ~7 ~1 ~12 ~11 ~1 ~12 stonebrick 2
fill ~7 ~1 ~13 ~10 ~1 ~13 stonebrick 2
fill ~7 ~1 ~14 ~22 ~1 ~14 stonebrick 2
fill ~7 ~1 ~15 ~22 ~1 ~15 stonebrick 2
fill ~7 ~1 ~16 ~13 ~1 ~16 stonebrick 2
fill ~7 ~1 ~17 ~11 ~1 ~17 stonebrick 2
fill ~7 ~1 ~18 ~9 ~1 ~18 stonebrick 2
fill ~7 ~1 ~19 ~8 ~1 ~19 stonebrick 2
fill ~7 ~1 ~20 ~18 ~1 ~20 stonebrick 2
fill ~7 ~1 ~21 ~19 ~1 ~21 stonebrick 2
fill ~7 ~1 ~23 ~17 ~1 ~23 stonebrick 2
fill ~7 ~1 ~24 ~22 ~1 ~24 stonebrick 2
fill ~7 ~1 ~25 ~22 ~1 ~25 stonebrick 2
fill ~7 ~1 ~26 ~22 ~1 ~26 stonebrick 2
fill ~7 ~1 ~27 ~22 ~1 ~27 stonebrick 2
fill ~7 ~1 ~28 ~22 ~1 ~28 stonebrick 2
fill ~7 ~1 ~29 ~22 ~1 ~29 stonebrick 2
fill ~7 ~1 ~30 ~22 ~1 ~30 stonebrick 2
fill ~7 ~1 ~31 ~22 ~1 ~31 stonebrick 2
fill ~7 ~1 ~32 ~22 ~1 ~32 stonebrick 2
fill ~8 ~1 ~22 ~18 ~1 ~22 stonebrick 2
setblock ~9 ~1 ~19 stonebrick 0
fill ~9 ~1 ~37 ~11 ~1 ~37 crafting_table 0
fill ~10 ~1 ~18 ~12 ~1 ~18 stonebrick 0
fill ~10 ~1 ~19 ~22 ~1 ~19 stonebrick 2
setblock ~10 ~1 ~35 wooden_door 9
setblock ~11 ~1 ~13 stonebrick 0
fill ~12 ~1 ~12 ~13 ~1 ~12 stonebrick 0
fill ~12 ~1 ~13 ~22 ~1 ~13 stonebrick 2
fill ~12 ~1 ~17 ~14 ~1 ~17 stonebrick 0
fill ~12 ~1 ~65 ~12 ~2 ~65 stonebrick 2
fill ~12 ~1 ~66 ~13 ~1 ~66 stonebrick 2
fill ~12 ~1 ~68 ~12 ~16 ~68 stonebrick 2
setblock ~12 ~1 ~69 stonebrick 0
fill ~12 ~1 ~75 ~13 ~1 ~75 stonebrick 2
fill ~13 ~1 ~18 ~22 ~1 ~18 stonebrick 2
fill ~13 ~1 ~76 ~14 ~1 ~76 stonebrick 2
fill ~14 ~1 ~11 ~16 ~1 ~11 stonebrick 0
fill ~14 ~1 ~12 ~22 ~1 ~12 stonebrick 2
setblock ~14 ~1 ~16 stonebrick 0
fill ~14 ~1 ~36 ~14 ~2 ~36 furnace 4
fill ~14 ~1 ~37 ~14 ~1 ~36 furnace 4
fill ~14 ~1 ~64 ~14 ~3 ~64 stonebrick 1
fill ~14 ~1 ~65 ~14 ~5 ~65 stonebrick 2
fill ~14 ~1 ~77 ~16 ~1 ~77 stonebrick 2
fill ~15 ~1 ~16 ~22 ~1 ~16 stonebrick 2
fill ~15 ~1 ~17 ~22 ~1 ~17 stonebrick 2
setblock ~15 ~1 ~35 wooden_door 9
fill ~15 ~1 ~37 ~15 ~2 ~37 furnace 3
fill ~15 ~1 ~64 ~16 ~1 ~64 stonebrick 2
fill ~15 ~1 ~78 ~23 ~1 ~78 stonebrick 2
fill ~16 ~1 ~4 ~18 ~1 ~4 vine 1
setblock ~16 ~1 ~35 furnace 2
fill ~16 ~1 ~36 ~16 ~2 ~36 furnace 4
fill ~16 ~1 ~37 ~16 ~1 ~36 furnace 4
fill ~16 ~1 ~63 ~16 ~4 ~63 stonebrick 1
fill ~17 ~1 ~11 ~22 ~1 ~11 stonebrick 2
fill ~17 ~1 ~63 ~21 ~1 ~63 stonebrick 2
setblock ~18 ~1 ~23 stonebrick 0
setblock ~19 ~1 ~20 stonebrick 0
setblock ~19 ~1 ~22 stonebrick 0
fill ~19 ~1 ~23 ~22 ~1 ~23 stonebrick 2
fill ~19 ~1 ~36 ~21 ~1 ~36 noteblock 0
fill ~20 ~1 ~20 ~22 ~1 ~20 stonebrick 2
setblock ~20 ~1 ~21 stonebrick 0
setblock ~20 ~1 ~22 stonebrick 2
setblock ~20 ~1 ~51 stonebrick 0
setblock ~20 ~1 ~62 stonebrick 0
fill ~21 ~1 ~21 ~22 ~1 ~21 stonebrick 2
setblock ~21 ~1 ~22 stonebrick 0
fill ~21 ~1 ~51 ~21 ~12 ~51 stonebrick 2
fill ~21 ~1 ~52 ~21 ~1 ~53 stonebrick 0
fill ~21 ~1 ~54 ~21 ~1 ~63 stonebrick 2
setblock ~22 ~1 ~22 stonebrick 2
setblock ~22 ~1 ~51 stonebrick 0
fill ~22 ~1 ~77 ~24 ~1 ~77 stonebrick 2
fill ~23 ~1 ~10 ~26 ~1 ~10 stonebrick 0
fill ~23 ~1 ~12 ~23 ~1 ~18 glowstone 0
fill ~23 ~1 ~25 ~23 ~1 ~31 glowstone 0
fill ~23 ~1 ~33 ~23 ~7 ~33 stonebrick 1
fill ~23 ~1 ~34 ~23 ~7 ~34 stonebrick 2
fill ~23 ~1 ~35 ~23 ~7 ~35 stonebrick 2
fill ~23 ~1 ~36 ~23 ~7 ~36 stonebrick 2
fill ~23 ~1 ~37 ~23 ~7 ~37 stonebrick 2
fill ~23 ~1 ~38 ~23 ~7 ~38 stonebrick 2
fill ~23 ~1 ~39 ~23 ~7 ~39 stonebrick 2
fill ~23 ~1 ~40 ~23 ~7 ~40 stonebrick 2
setblock ~23 ~1 ~42 dark_oak_door 9
fill ~23 ~1 ~66 ~26 ~1 ~66 stonebrick 0
fill ~24 ~1 ~67 ~26 ~1 ~67 stonebrick 2
fill ~24 ~1 ~76 ~25 ~1 ~76 stonebrick 2
fill ~25 ~1 ~75 ~26 ~1 ~75 stonebrick 2
setblock ~26 ~1 ~71 dark_oak_door 9
fill ~26 ~1 ~74 ~27 ~1 ~74 stonebrick 2
fill ~27 ~1 ~9 ~27 ~11 ~9 vine 1
fill ~27 ~1 ~10 ~29 ~1 ~10 stonebrick 2
setblock ~28 ~1 ~37 trapdoor 14
setblock ~28 ~1 ~42 trapdoor 14
fill ~28 ~1 ~74 ~29 ~1 ~74 stonebrick 0
fill ~29 ~1 ~36 ~31 ~1 ~36 planks 5
fill ~29 ~1 ~37 ~29 ~1 ~38 planks 5
fill ~29 ~1 ~41 ~31 ~1 ~41 planks 5
fill ~29 ~1 ~42 ~29 ~1 ~43 planks 5
setblock ~29 ~1 ~66 dark_oak_door 9
fill ~30 ~1 ~10 ~32 ~1 ~10 stonebrick 1
setblock ~30 ~1 ~37 wool 14
fill ~30 ~1 ~38 ~31 ~1 ~38 planks 5
setblock ~30 ~1 ~42 wool 14
fill ~30 ~1 ~43 ~31 ~1 ~43 planks 5
fill ~30 ~1 ~74 ~31 ~1 ~74 stonebrick 2
fill ~31 ~1 ~19 ~32 ~1 ~19 wooden_slab 5
fill ~31 ~1 ~20 ~32 ~1 ~20 wooden_slab 5
setblock ~31 ~1 ~37 planks 5
setblock ~31 ~1 ~42 planks 5
fill ~31 ~1 ~66 ~32 ~1 ~66 stonebrick 0
setblock ~31 ~1 ~71 stonebrick 0
fill ~31 ~1 ~72 ~31 ~11 ~72 stonebrick 2
fill ~31 ~1 ~73 ~31 ~10 ~73 stonebrick 2
fill ~31 ~1 ~75 ~31 ~10 ~75 stonebrick 2
fill ~31 ~1 ~76 ~31 ~16 ~76 stonebrick 2
fill ~31 ~1 ~77 ~31 ~16 ~77 stonebrick 2
fill ~31 ~1 ~83 ~40 ~1 ~83 stonebrick 2
fill ~32 ~1 ~11 ~33 ~1 ~11 log 8
fill ~32 ~1 ~12 ~33 ~1 ~12 log 8
fill ~33 ~1 ~10 ~34 ~1 ~10 stonebrick 2
fill ~33 ~1 ~66 ~34 ~1 ~66 stonebrick 2
fill ~34 ~1 ~20 ~37 ~1 ~20 planks 5
fill ~34 ~1 ~21 ~37 ~1 ~21 planks 5
fill ~34 ~1 ~22 ~37 ~1 ~22 planks 5
fill ~34 ~1 ~23 ~37 ~1 ~23 planks 5
fill ~34 ~1 ~84 ~35 ~1 ~84 vine 4
fill ~35 ~1 ~6 ~42 ~1 ~6 brick_block 0
fill ~35 ~1 ~19 ~36 ~1 ~19 ladder 2
fill ~35 ~1 ~30 ~37 ~1 ~30 planks 5
fill ~35 ~1 ~31 ~35 ~1 ~32 planks 5
fill ~35 ~1 ~47 ~37 ~1 ~47 planks 5
fill ~35 ~1 ~48 ~35 ~1 ~49 planks 5
setblock ~36 ~1 ~29 trapdoor 12
setblock ~36 ~1 ~31 wool 14
fill ~36 ~1 ~32 ~37 ~1 ~32 planks 5
setblock ~36 ~1 ~48 wool 14
fill ~36 ~1 ~49 ~37 ~1 ~49 planks 5
setblock ~36 ~1 ~50 trapdoor 13
setblock ~36 ~1 ~66 dark_oak_door 9
setblock ~37 ~1 ~31 planks 5
setblock ~37 ~1 ~48 planks 5
fill ~38 ~1 ~66 ~46 ~1 ~66 stonebrick 2
fill ~40 ~1 ~20 ~43 ~1 ~20 planks 5
fill ~40 ~1 ~21 ~43 ~1 ~21 planks 5
fill ~40 ~1 ~22 ~43 ~1 ~22 planks 5
fill ~40 ~1 ~23 ~43 ~1 ~23 planks 5
fill ~40 ~1 ~30 ~42 ~1 ~30 planks 5
fill ~40 ~1 ~31 ~40 ~1 ~32 planks 5
fill ~40 ~1 ~48 ~40 ~1 ~49 planks 5
fill ~40 ~1 ~67 ~40 ~1 ~75 stonebrick 0
fill ~41 ~1 ~19 ~42 ~1 ~19 ladder 2
setblock ~41 ~1 ~29 trapdoor 12
setblock ~41 ~1 ~31 wool 14
fill ~41 ~1 ~32 ~42 ~1 ~32 planks 5
fill ~41 ~1 ~47 ~42 ~1 ~47 planks 5
setblock ~41 ~1 ~48 wool 14
fill ~41 ~1 ~49 ~42 ~1 ~49 planks 5
setblock ~41 ~1 ~50 trapdoor 13
fill ~41 ~1 ~67 ~42 ~1 ~67 stonebrick 1
fill ~41 ~1 ~68 ~42 ~1 ~68 stonebrick 1
fill ~41 ~1 ~69 ~42 ~1 ~69 stonebrick 1
fill ~41 ~1 ~70 ~41 ~1 ~71 stonebrick 1
setblock ~41 ~1 ~72 mob_spawner 0
fill ~41 ~1 ~73 ~42 ~1 ~73 stonebrick 1
fill ~41 ~1 ~74 ~43 ~1 ~74 stonebrick 0
fill ~41 ~1 ~75 ~43 ~1 ~75 stonebrick 0
setblock ~41 ~1 ~83 stonebrick 0
setblock ~41 ~1 ~84 slime 0
setblock ~42 ~1 ~31 planks 5
setblock ~42 ~1 ~48 planks 5
fill ~42 ~1 ~70 ~42 ~3 ~70 stonebrick 0
setblock ~42 ~1 ~71 stonebrick 2
setblock ~42 ~1 ~72 stonebrick 1
fill ~42 ~1 ~87 ~47 ~1 ~87 stonebrick 2
fill ~43 ~1 ~10 ~46 ~1 ~10 stonebrick 2
setblock ~43 ~1 ~67 web 0
fill ~43 ~1 ~86 ~47 ~1 ~86 planks 5
fill ~44 ~1 ~11 ~44 ~1 ~12 log 8
fill ~44 ~1 ~88 ~46 ~1 ~88 stonebrick 0
fill ~45 ~1 ~19 ~46 ~1 ~19 wooden_slab 5
fill ~45 ~1 ~20 ~46 ~1 ~20 wooden_slab 5
setblock ~45 ~1 ~74 dark_oak_door 8
fill ~46 ~1 ~36 ~48 ~1 ~36 planks 5
fill ~46 ~1 ~37 ~46 ~1 ~36 planks 5
fill ~46 ~1 ~41 ~48 ~1 ~41 planks 5
fill ~46 ~1 ~42 ~46 ~1 ~43 planks 5
fill ~46 ~1 ~62 ~51 ~1 ~62 planks 1
fill ~47 ~1 ~10 ~48 ~1 ~10 stonebrick 1
setblock ~47 ~1 ~37 wool 14
setblock ~47 ~1 ~38 planks 5
setblock ~47 ~1 ~42 wool 14
fill ~47 ~1 ~43 ~48 ~1 ~43 planks 5
setblock ~47 ~1 ~66 stonebrick 1
setblock ~48 ~1 ~37 planks 5
setblock ~48 ~1 ~42 planks 5
fill ~48 ~1 ~66 ~54 ~1 ~66 stonebrick 2
fill ~48 ~1 ~75 ~48 ~2 ~75 web 0
fill ~48 ~1 ~76 ~62 ~1 ~76 stonebrick 2
fill ~49 ~1 ~10 ~50 ~1 ~10 stonebrick 2
setblock ~49 ~1 ~37 trapdoor 15
setblock ~49 ~1 ~42 trapdoor 15
setblock ~49 ~1 ~77 slime 0
fill ~49 ~1 ~87 ~49 ~2 ~87 slime 0
fill ~52 ~1 ~10 ~53 ~1 ~10 stonebrick 2
setblock ~52 ~1 ~65 dark_oak_door 9
fill ~54 ~1 ~9 ~55 ~1 ~9 vine 1
setblock ~54 ~1 ~11 stonebrick 0
fill ~54 ~1 ~12 ~54 ~2 ~12 stonebrick 2
setblock ~54 ~1 ~13 stonebrick 1
fill ~54 ~1 ~15 ~54 ~5 ~15 stonebrick 0
setblock ~54 ~1 ~19 dark_oak_door 8
fill ~54 ~1 ~27 ~54 ~6 ~27 stonebrick 1
fill ~54 ~1 ~28 ~54 ~2 ~28 stonebrick 2
fill ~54 ~1 ~29 ~54 ~2 ~29 stonebrick 2
fill ~54 ~1 ~30 ~54 ~2 ~30 stonebrick 2
fill ~54 ~1 ~31 ~54 ~2 ~31 stonebrick 2
fill ~54 ~1 ~32 ~54 ~3 ~32 stonebrick 2
fill ~54 ~1 ~33 ~54 ~4 ~33 stonebrick 2
fill ~54 ~1 ~34 ~54 ~1 ~36 stonebrick 2
fill ~54 ~1 ~43 ~54 ~2 ~43 stonebrick 0
fill ~54 ~1 ~45 ~54 ~2 ~45 stonebrick 2
setblock ~54 ~1 ~51 dark_oak_door 8
setblock ~54 ~1 ~62 wooden_door 8
fill ~55 ~1 ~15 ~55 ~19 ~15 stonebrick 2
fill ~55 ~1 ~16 ~64 ~1 ~16 stonebrick 2
fill ~55 ~1 ~22 ~63 ~1 ~22 stonebrick 2
fill ~55 ~1 ~44 ~69 ~1 ~44 stonebrick 2
fill ~55 ~1 ~45 ~69 ~1 ~45 stonebrick 1
fill ~55 ~1 ~57 ~61 ~1 ~57 stonebrick 2
fill ~56 ~1 ~15 ~59 ~1 ~15 stonebrick 0
fill ~56 ~1 ~42 ~58 ~1 ~42 vine 3
setblock ~57 ~1 ~32 vine 2
fill ~59 ~1 ~42 ~60 ~1 ~42 vine 1
setblock ~60 ~1 ~15 slime 0
fill ~61 ~1 ~15 ~64 ~1 ~15 vine 1
fill ~61 ~1 ~23 ~64 ~1 ~23 vine 4
fill ~61 ~1 ~58 ~61 ~2 ~58 web 0
fill ~63 ~1 ~57 ~64 ~1 ~57 stonebrick 2
fill ~63 ~1 ~63 ~66 ~1 ~63 brick_block 0
fill ~63 ~1 ~64 ~65 ~1 ~64 fire 15
fill ~63 ~1 ~65 ~65 ~1 ~65 fire 15
fill ~63 ~1 ~66 ~65 ~1 ~66 fire 15
fill ~63 ~1 ~67 ~65 ~1 ~67 fire 15
fill ~63 ~1 ~68 ~65 ~1 ~68 fire 15
fill ~63 ~1 ~69 ~66 ~1 ~69 brick_block 0
fill ~63 ~1 ~70 ~64 ~1 ~70 vine 6
fill ~64 ~1 ~58 ~69 ~1 ~58 slime 0
fill ~65 ~1 ~57 ~65 ~2 ~57 stonebrick 1
fill ~65 ~1 ~60 ~66 ~1 ~60 vine 4
fill ~65 ~1 ~70 ~67 ~1 ~70 vine 4
fill ~67 ~1 ~51 ~70 ~1 ~51 leaves 0
fill ~67 ~1 ~52 ~67 ~3 ~52 leaves 0
fill ~67 ~1 ~53 ~70 ~1 ~53 leaves 0
fill ~67 ~1 ~54 ~69 ~1 ~54 leaves 0
fill ~67 ~1 ~57 ~71 ~1 ~57 stonebrick 2
setblock ~69 ~1 ~52 leaves 4
fill ~69 ~1 ~59 ~70 ~1 ~59 vine 12
fill ~70 ~1 ~45 ~70 ~2 ~45 stonebrick 2
fill ~70 ~1 ~52 ~70 ~2 ~52 leaves 0
fill ~70 ~1 ~58 ~71 ~1 ~58 stonebrick 2
fill ~71 ~1 ~46 ~71 ~11 ~46 stonebrick 2
fill ~71 ~1 ~55 ~71 ~11 ~55 stonebrick 2
fill ~73 ~1 ~58 ~73 ~24 ~58 vine 1
fill ~6 ~2 ~4 ~7 ~2 ~4 vine 1
fill ~6 ~2 ~5 ~7 ~2 ~5 stonebrick 2
fill ~6 ~2 ~12 ~6 ~10 ~12 vine 9
fill ~6 ~2 ~25 ~6 ~10 ~25 vine 12
fill ~6 ~2 ~33 ~6 ~4 ~33 stonebrick 1
fill ~6 ~2 ~35 ~6 ~3 ~35 stonebrick 2
fill ~6 ~2 ~42 ~6 ~3 ~42 stonebrick 1
fill ~6 ~2 ~43 ~6 ~14 ~43 stonebrick 2
fill ~6 ~2 ~50 ~6 ~6 ~50 stonebrick 2
fill ~6 ~2 ~51 ~7 ~2 ~51 stonebrick 0
fill ~7 ~2 ~6 ~7 ~10 ~6 stonebrick 2
fill ~7 ~2 ~12 ~7 ~8 ~12 vine 1
fill ~7 ~2 ~13 ~7 ~11 ~13 stonebrick 2
fill ~7 ~2 ~14 ~7 ~11 ~14 stonebrick 2
fill ~7 ~2 ~23 ~7 ~11 ~23 stonebrick 2
fill ~7 ~2 ~24 ~7 ~11 ~24 stonebrick 2
fill ~7 ~2 ~25 ~7 ~8 ~25 vine 4
fill ~7 ~2 ~32 ~7 ~11 ~32 stonebrick 2
fill ~7 ~2 ~33 ~22 ~2 ~33 stonebrick 2
fill ~8 ~2 ~5 ~8 ~9 ~5 vine 2
fill ~8 ~2 ~51 ~22 ~2 ~51 stonebrick 2
fill ~9 ~2 ~37 ~11 ~2 ~37 crafting_table 0
fill ~10 ~2 ~35 ~10 ~2 ~37 crafting_table 0
fill ~11 ~2 ~69 ~12 ~2 ~69 planks 5
fill ~11 ~2 ~70 ~12 ~2 ~70 planks 5
fill ~11 ~2 ~71 ~12 ~2 ~71 planks 5
fill ~11 ~2 ~72 ~12 ~2 ~72 planks 5
fill ~12 ~2 ~66 ~13 ~2 ~66 stonebrick 2
fill ~12 ~2 ~75 ~13 ~2 ~75 stonebrick 2
setblock ~13 ~2 ~64 mossy_cobblestone 0
setblock ~13 ~2 ~65 stonebrick 2
fill ~13 ~2 ~67 ~13 ~15 ~67 stonebrick 2
fill ~13 ~2 ~74 ~13 ~14 ~74 stonebrick 2
fill ~13 ~2 ~76 ~14 ~2 ~76 stonebrick 2
setblock ~14 ~2 ~35 furnace 4
setblock ~14 ~2 ~37 furnace 3
fill ~14 ~2 ~77 ~16 ~2 ~77 stonebrick 2
fill ~15 ~2 ~35 ~15 ~2 ~36 furnace 2
fill ~15 ~2 ~63 ~15 ~3 ~63 mossy_cobblestone 0
fill ~15 ~2 ~64 ~16 ~2 ~64 stonebrick 2
fill ~15 ~2 ~78 ~16 ~2 ~78 stonebrick 2
fill ~16 ~2 ~4 ~18 ~2 ~4 vine 1
fill ~16 ~2 ~5 ~17 ~2 ~5 stonebrick 2
fill ~16 ~2 ~6 ~17 ~2 ~6 stonebrick 2
setblock ~16 ~2 ~35 furnace 4
setblock ~16 ~2 ~37 furnace 3
fill ~17 ~2 ~7 ~17 ~6 ~7 vine 4
fill ~17 ~2 ~63 ~22 ~2 ~63 stonebrick 2
fill ~17 ~2 ~78 ~21 ~2 ~78 planks 5
fill ~17 ~2 ~79 ~21 ~2 ~79 planks 5
fill ~18 ~2 ~5 ~18 ~9 ~5 vine 2
fill ~18 ~2 ~6 ~18 ~7 ~6 vine 2
fill ~19 ~2 ~36 ~21 ~2 ~36 noteblock 0
fill ~20 ~2 ~54 ~20 ~11 ~54 stonebrick 2
fill ~20 ~2 ~57 ~20 ~11 ~57 stonebrick 2
fill ~20 ~2 ~60 ~20 ~11 ~60 stonebrick 2
fill ~21 ~2 ~19 ~22 ~2 ~19 planks 5
fill ~21 ~2 ~24 ~22 ~2 ~24 planks 5
fill ~21 ~2 ~52 ~21 ~3 ~52 stained_glass 11
fill ~21 ~2 ~53 ~21 ~3 ~53 stained_glass 11
fill ~21 ~2 ~54 ~21 ~3 ~54 stained_glass 11
fill ~21 ~2 ~55 ~21 ~3 ~55 stained_glass 11
fill ~21 ~2 ~56 ~21 ~10 ~56 stained_glass 14
fill ~21 ~2 ~57 ~21 ~10 ~57 stained_glass 14
fill ~21 ~2 ~58 ~21 ~10 ~58 stained_glass 14
fill ~21 ~2 ~59 ~21 ~3 ~59 stained_glass 11
fill ~21 ~2 ~60 ~21 ~3 ~60 stained_glass 11
fill ~21 ~2 ~61 ~21 ~3 ~61 stained_glass 11
fill ~21 ~2 ~62 ~21 ~3 ~62 stained_glass 11
fill ~22 ~2 ~10 ~29 ~2 ~10 stonebrick 2
fill ~22 ~2 ~11 ~22 ~30 ~11 stonebrick 2
fill ~22 ~2 ~12 ~23 ~2 ~12 stonebrick 2
fill ~22 ~2 ~13 ~23 ~2 ~13 stonebrick 2
fill ~22 ~2 ~14 ~23 ~2 ~14 stonebrick 2
fill ~22 ~2 ~15 ~23 ~2 ~15 stonebrick 2
fill ~22 ~2 ~16 ~23 ~2 ~16 stonebrick 2
fill ~22 ~2 ~17 ~22 ~7 ~17 stonebrick 0
fill ~22 ~2 ~18 ~22 ~7 ~18 stonebrick 0
fill ~22 ~2 ~20 ~22 ~6 ~20 planks 0
fill ~22 ~2 ~21 ~22 ~2 ~22 wooden_door 0
fill ~22 ~2 ~23 ~22 ~6 ~23 planks 0
fill ~22 ~2 ~25 ~22 ~7 ~25 stonebrick 0
fill ~22 ~2 ~26 ~22 ~4 ~26 stonebrick 0
fill ~22 ~2 ~27 ~23 ~2 ~27 stonebrick 2
fill ~22 ~2 ~28 ~23 ~2 ~28 stonebrick 2
fill ~22 ~2 ~29 ~23 ~2 ~29 stonebrick 2
fill ~22 ~2 ~30 ~23 ~2 ~30 stonebrick 2
fill ~22 ~2 ~31 ~23 ~2 ~31 stonebrick 2
fill ~22 ~2 ~32 ~22 ~30 ~32 stonebrick 2
fill ~22 ~2 ~77 ~24 ~2 ~77 stonebrick 2
fill ~22 ~2 ~78 ~23 ~2 ~78 stonebrick 2
fill ~23 ~2 ~17 ~23 ~2 ~18 stonebrick 2
fill ~23 ~2 ~25 ~23 ~2 ~31 stonebrick 2
fill ~23 ~2 ~42 ~23 ~5 ~42 planks 5
fill ~23 ~2 ~50 ~23 ~4 ~50 stonebrick 2
fill ~23 ~2 ~66 ~26 ~2 ~66 stonebrick 0
fill ~24 ~2 ~67 ~26 ~2 ~67 stonebrick 2
fill ~24 ~2 ~76 ~25 ~2 ~76 stonebrick 2
fill ~25 ~2 ~5 ~26 ~2 ~5 stonebrick 2
fill ~25 ~2 ~6 ~26 ~2 ~6 stonebrick 2
fill ~25 ~2 ~75 ~26 ~2 ~75 stonebrick 2
fill ~26 ~2 ~9 ~26 ~9 ~9 vine 1
fill ~26 ~2 ~71 ~26 ~5 ~71 planks 5
fill ~26 ~2 ~74 ~27 ~2 ~74 stonebrick 2
fill ~28 ~2 ~37 ~28 ~3 ~37 trapdoor 6
fill ~28 ~2 ~42 ~28 ~3 ~42 trapdoor 6
fill ~28 ~2 ~74 ~29 ~2 ~74 stonebrick 0
fill ~29 ~2 ~36 ~29 ~1 ~36 planks 5
setblock ~29 ~2 ~37 beacon 0
setblock ~29 ~2 ~38 planks 5
fill ~29 ~2 ~41 ~29 ~1 ~41 planks 5
setblock ~29 ~2 ~42 beacon 0
setblock ~29 ~2 ~43 planks 5
fill ~29 ~2 ~66 ~29 ~5 ~66 planks 5
fill ~30 ~2 ~10 ~34 ~2 ~10 stonebrick 1
fill ~30 ~2 ~36 ~31 ~2 ~36 dark_oak_stairs 3
fill ~30 ~2 ~38 ~31 ~2 ~38 dark_oak_stairs 2
fill ~30 ~2 ~41 ~31 ~2 ~41 dark_oak_stairs 3
fill ~30 ~2 ~43 ~31 ~2 ~43 dark_oak_stairs 2
fill ~30 ~2 ~74 ~31 ~2 ~74 stonebrick 2
setblock ~31 ~2 ~37 carpet 14
setblock ~31 ~2 ~42 carpet 14
fill ~31 ~2 ~66 ~32 ~2 ~66 stonebrick 0
fill ~31 ~2 ~69 ~31 ~16 ~69 stonebrick 2
fill ~31 ~2 ~70 ~31 ~16 ~70 stonebrick 2
fill ~31 ~2 ~71 ~31 ~13 ~71 stonebrick 2
fill ~31 ~2 ~83 ~40 ~2 ~83 stonebrick 2
fill ~33 ~2 ~34 ~44 ~2 ~34 planks 5
fill ~33 ~2 ~35 ~44 ~2 ~35 planks 5
fill ~33 ~2 ~36 ~44 ~2 ~36 planks 5
fill ~33 ~2 ~37 ~44 ~2 ~37 planks 5
fill ~33 ~2 ~38 ~44 ~2 ~38 planks 5
fill ~33 ~2 ~39 ~44 ~2 ~39 planks 5
fill ~33 ~2 ~40 ~44 ~2 ~40 planks 5
fill ~33 ~2 ~41 ~44 ~2 ~41 planks 5
fill ~33 ~2 ~42 ~44 ~2 ~42 planks 5
fill ~33 ~2 ~43 ~44 ~2 ~43 planks 5
fill ~33 ~2 ~44 ~44 ~2 ~44 planks 5
fill ~33 ~2 ~45 ~44 ~2 ~45 planks 5
fill ~33 ~2 ~66 ~34 ~2 ~66 stonebrick 2
setblock ~34 ~2 ~20 dark_oak_stairs 6
fill ~34 ~2 ~21 ~34 ~1 ~21 planks 5
fill ~34 ~2 ~22 ~34 ~1 ~22 planks 5
setblock ~34 ~2 ~23 double_wooden_slab 5
fill ~34 ~2 ~84 ~35 ~2 ~84 vine 4
fill ~35 ~2 ~6 ~42 ~2 ~6 brick_block 0
fill ~35 ~2 ~20 ~36 ~2 ~20 carpet 14
fill ~35 ~2 ~21 ~36 ~2 ~21 carpet 14
fill ~35 ~2 ~22 ~36 ~2 ~22 carpet 14
fill ~35 ~2 ~23 ~37 ~2 ~23 planks 5
fill ~35 ~2 ~30 ~35 ~1 ~30 planks 5
fill ~35 ~2 ~31 ~35 ~2 ~32 dark_oak_stairs 1
fill ~35 ~2 ~47 ~35 ~2 ~48 dark_oak_stairs 1
setblock ~35 ~2 ~49 planks 5
fill ~36 ~2 ~29 ~36 ~3 ~29 trapdoor 4
setblock ~36 ~2 ~30 beacon 0
setblock ~36 ~2 ~32 carpet 14
setblock ~36 ~2 ~47 carpet 14
setblock ~36 ~2 ~49 beacon 0
setblock ~36 ~2 ~50 trapdoor 5
fill ~36 ~2 ~66 ~36 ~5 ~66 planks 5
setblock ~37 ~2 ~20 dark_oak_stairs 6
fill ~37 ~2 ~21 ~37 ~2 ~23 planks 5
setblock ~37 ~2 ~30 planks 5
fill ~37 ~2 ~31 ~37 ~2 ~32 dark_oak_stairs 0
fill ~37 ~2 ~47 ~37 ~2 ~48 dark_oak_stairs 0
setblock ~37 ~2 ~49 planks 5
fill ~38 ~2 ~66 ~47 ~2 ~66 stonebrick 2
setblock ~39 ~2 ~62 planks 5
setblock ~39 ~2 ~63 dark_oak_stairs 4
setblock ~39 ~2 ~64 planks 5
setblock ~40 ~2 ~20 dark_oak_stairs 6
fill ~40 ~2 ~21 ~40 ~1 ~21 planks 5
fill ~40 ~2 ~22 ~40 ~1 ~22 planks 5
fill ~40 ~2 ~23 ~43 ~2 ~23 planks 5
fill ~40 ~2 ~30 ~40 ~1 ~30 planks 5
fill ~40 ~2 ~31 ~40 ~2 ~32 dark_oak_stairs 1
fill ~40 ~2 ~47 ~40 ~2 ~48 dark_oak_stairs 1
setblock ~40 ~2 ~49 planks 5
setblock ~40 ~2 ~62 dark_oak_stairs 6
setblock ~40 ~2 ~63 lever 12
setblock ~40 ~2 ~64 dark_oak_stairs 7
fill ~41 ~2 ~20 ~42 ~2 ~20 carpet 14
fill ~41 ~2 ~21 ~42 ~2 ~21 carpet 14
fill ~41 ~2 ~22 ~42 ~2 ~22 carpet 14
fill ~41 ~2 ~29 ~41 ~3 ~29 trapdoor 4
setblock ~41 ~2 ~30 beacon 0
setblock ~41 ~2 ~32 carpet 14
setblock ~41 ~2 ~47 carpet 14
setblock ~41 ~2 ~49 beacon 0
fill ~41 ~2 ~50 ~41 ~3 ~50 trapdoor 5
setblock ~41 ~2 ~62 planks 5
setblock ~41 ~2 ~63 dark_oak_stairs 5
setblock ~41 ~2 ~64 planks 5
fill ~41 ~2 ~67 ~42 ~2 ~67 stonebrick 0
fill ~41 ~2 ~68 ~42 ~2 ~68 stonebrick 0
fill ~41 ~2 ~69 ~42 ~2 ~69 stonebrick 0
fill ~41 ~2 ~70 ~41 ~2 ~75 stonebrick 0
fill ~41 ~2 ~84 ~41 ~6 ~84 stonebrick 2
setblock ~42 ~2 ~30 planks 5
fill ~42 ~2 ~31 ~42 ~2 ~32 dark_oak_stairs 0
fill ~42 ~2 ~47 ~42 ~2 ~48 dark_oak_stairs 0
setblock ~42 ~2 ~49 planks 5
fill ~42 ~2 ~71 ~42 ~3 ~71 stonebrick 0
setblock ~42 ~2 ~72 stonebrick 2
setblock ~42 ~2 ~73 stonebrick 1
fill ~42 ~2 ~74 ~43 ~2 ~74 stonebrick 0
fill ~42 ~2 ~75 ~43 ~2 ~75 stonebrick 0
fill ~42 ~2 ~87 ~42 ~10 ~87 stonebrick 2
fill ~43 ~2 ~10 ~46 ~2 ~10 stonebrick 2
setblock ~43 ~2 ~20 dark_oak_stairs 6
fill ~43 ~2 ~21 ~43 ~2 ~23 planks 5
fill ~43 ~2 ~87 ~43 ~9 ~87 planks 5
fill ~44 ~2 ~87 ~44 ~7 ~87 planks 0
fill ~45 ~2 ~74 ~45 ~4 ~74 planks 5
setblock ~45 ~2 ~87 wooden_door 3
fill ~46 ~2 ~36 ~47 ~2 ~36 dark_oak_stairs 3
setblock ~46 ~2 ~37 carpet 14
fill ~46 ~2 ~38 ~47 ~2 ~38 dark_oak_stairs 2
fill ~46 ~2 ~41 ~47 ~2 ~41 dark_oak_stairs 3
setblock ~46 ~2 ~42 carpet 14
fill ~46 ~2 ~43 ~47 ~2 ~43 dark_oak_stairs 2
fill ~46 ~2 ~62 ~51 ~2 ~62 planks 1
fill ~46 ~2 ~87 ~46 ~7 ~87 planks 0
fill ~47 ~2 ~10 ~48 ~2 ~10 stonebrick 1
fill ~47 ~2 ~87 ~47 ~9 ~87 planks 5
setblock ~48 ~2 ~36 planks 5
setblock ~48 ~2 ~37 beacon 0
setblock ~48 ~2 ~41 planks 5
setblock ~48 ~2 ~42 beacon 0
setblock ~48 ~2 ~43 planks 5
fill ~48 ~2 ~66 ~50 ~2 ~66 stonebrick 1
fill ~48 ~2 ~76 ~62 ~2 ~76 stonebrick 2
fill ~48 ~2 ~77 ~48 ~3 ~77 stonebrick 1
fill ~49 ~2 ~10 ~50 ~2 ~10 stonebrick 2
fill ~49 ~2 ~37 ~49 ~3 ~37 trapdoor 7
setblock ~49 ~2 ~42 trapdoor 7
fill ~49 ~2 ~77 ~49 ~3 ~77 mossy_cobblestone 0
setblock ~49 ~2 ~86 slime 0
fill ~51 ~2 ~66 ~54 ~2 ~66 stonebrick 2
fill ~52 ~2 ~10 ~53 ~2 ~10 stonebrick 2
fill ~52 ~2 ~65 ~52 ~6 ~65 planks 5
fill ~54 ~2 ~9 ~55 ~2 ~9 vine 1
fill ~54 ~2 ~11 ~54 ~3 ~11 stonebrick 1
setblock ~54 ~2 ~13 stonebrick 0
fill ~54 ~2 ~19 ~54 ~5 ~19 planks 5
fill ~54 ~2 ~34 ~54 ~5 ~34 stonebrick 1
fill ~54 ~2 ~35 ~54 ~2 ~36 stonebrick 2
fill ~54 ~2 ~51 ~54 ~5 ~51 planks 5
setblock ~54 ~2 ~62 stonebrick 0
setblock ~55 ~2 ~10 slime 0
fill ~55 ~2 ~16 ~58 ~2 ~16 stonebrick 2
fill ~55 ~2 ~22 ~62 ~2 ~22 stonebrick 2
fill ~55 ~2 ~44 ~64 ~2 ~44 stonebrick 2
fill ~55 ~2 ~45 ~69 ~2 ~45 stonebrick 1
fill ~55 ~2 ~57 ~61 ~2 ~57 stonebrick 2
fill ~56 ~2 ~15 ~56 ~9 ~15 stonebrick 2
fill ~56 ~2 ~42 ~58 ~2 ~42 vine 3
fill ~57 ~2 ~15 ~63 ~2 ~15 stonebrick 0
fill ~57 ~2 ~32 ~57 ~28 ~32 vine 6
fill ~58 ~2 ~31 ~58 ~30 ~31 vine 2
fill ~59 ~2 ~16 ~60 ~2 ~16 stonebrick 0
fill ~59 ~2 ~42 ~60 ~2 ~42 vine 1
fill ~61 ~2 ~16 ~64 ~2 ~16 stonebrick 2
fill ~61 ~2 ~23 ~63 ~2 ~23 vine 4
fill ~62 ~2 ~57 ~62 ~3 ~57 stonebrick 0
fill ~62 ~2 ~58 ~63 ~2 ~58 stonebrick 2
setblock ~62 ~2 ~64 stonebrick 0
fill ~63 ~2 ~22 ~63 ~3 ~22 stonebrick 1
fill ~63 ~2 ~57 ~64 ~2 ~57 stonebrick 2
fill ~63 ~2 ~59 ~63 ~10 ~59 stonebrick 2
fill ~63 ~2 ~63 ~66 ~2 ~63 brick_block 0
fill ~63 ~2 ~69 ~66 ~2 ~69 brick_block 0
fill ~63 ~2 ~70 ~64 ~2 ~70 vine 6
fill ~64 ~2 ~15 ~64 ~9 ~15 stonebrick 2
fill ~64 ~2 ~17 ~64 ~8 ~17 planks 5
fill ~64 ~2 ~18 ~64 ~2 ~21 planks 5
setblock ~64 ~2 ~23 slime 0
setblock ~64 ~2 ~58 stonebrick 0
setblock ~65 ~2 ~44 stonebrick 1
fill ~65 ~2 ~58 ~71 ~2 ~58 stonebrick 2
fill ~65 ~2 ~60 ~66 ~2 ~60 vine 4
fill ~65 ~2 ~70 ~67 ~2 ~70 vine 4
fill ~66 ~2 ~44 ~69 ~2 ~44 stonebrick 2
fill ~66 ~2 ~51 ~70 ~2 ~51 leaves 0
fill ~66 ~2 ~52 ~66 ~2 ~53 leaves 0
fill ~66 ~2 ~57 ~71 ~2 ~57 stonebrick 2
fill ~67 ~2 ~50 ~70 ~2 ~50 leaves 0
fill ~67 ~2 ~53 ~70 ~2 ~53 leaves 0
fill ~67 ~2 ~54 ~70 ~2 ~54 leaves 0
setblock ~69 ~2 ~52 mob_spawner 0
fill ~69 ~2 ~59 ~70 ~2 ~59 vine 12
setblock ~71 ~2 ~44 slime 0
fill ~6 ~3 ~4 ~7 ~3 ~4 vine 1
fill ~6 ~3 ~5 ~7 ~3 ~5 stonebrick 2
setblock ~6 ~3 ~41 stonebrick 1
fill ~6 ~3 ~51 ~22 ~3 ~51 stonebrick 2
fill ~7 ~3 ~33 ~22 ~3 ~33 stonebrick 2
fill ~11 ~3 ~69 ~12 ~3 ~69 planks 5
fill ~11 ~3 ~72 ~12 ~3 ~72 planks 5
setblock ~12 ~3 ~64 vine 8
setblock ~12 ~3 ~65 mossy_cobblestone 0
fill ~12 ~3 ~66 ~13 ~3 ~66 stonebrick 2
setblock ~12 ~3 ~70 stained_glass 14
fill ~12 ~3 ~71 ~12 ~7 ~71 stained_glass 11
setblock ~13 ~3 ~64 slime 0
fill ~13 ~3 ~65 ~13 ~5 ~65 stonebrick 1
fill ~13 ~3 ~75 ~13 ~13 ~75 stonebrick 2
fill ~13 ~3 ~76 ~14 ~3 ~76 stonebrick 2
fill ~14 ~3 ~77 ~16 ~3 ~77 stonebrick 2
fill ~15 ~3 ~64 ~16 ~3 ~64 stonebrick 2
fill ~15 ~3 ~78 ~16 ~3 ~78 stonebrick 2
fill ~16 ~3 ~4 ~18 ~3 ~4 vine 1
fill ~16 ~3 ~5 ~17 ~3 ~5 stonebrick 2
fill ~16 ~3 ~6 ~17 ~3 ~6 stonebrick 2
fill ~16 ~3 ~65 ~16 ~10 ~65 ladder 3
fill ~17 ~3 ~63 ~22 ~3 ~63 stonebrick 2
fill ~17 ~3 ~78 ~17 ~9 ~78 planks 5
fill ~17 ~3 ~79 ~17 ~9 ~79 planks 5
setblock ~18 ~3 ~78 stained_glass 14
fill ~19 ~3 ~78 ~19 ~8 ~78 stained_glass 11
setblock ~20 ~3 ~78 stained_glass 14
fill ~21 ~3 ~13 ~22 ~3 ~13 planks 5
fill ~21 ~3 ~14 ~22 ~3 ~14 planks 5
fill ~21 ~3 ~15 ~22 ~3 ~15 planks 5
fill ~21 ~3 ~16 ~22 ~3 ~16 planks 5
fill ~21 ~3 ~19 ~22 ~3 ~19 planks 5
fill ~21 ~3 ~24 ~22 ~3 ~24 planks 5
fill ~21 ~3 ~28 ~22 ~3 ~28 planks 5
fill ~21 ~3 ~29 ~22 ~3 ~29 planks 5
fill ~21 ~3 ~30 ~22 ~3 ~30 planks 5
fill ~21 ~3 ~31 ~22 ~3 ~31 planks 5
fill ~21 ~3 ~78 ~21 ~9 ~78 planks 5
fill ~21 ~3 ~79 ~21 ~9 ~79 planks 5
fill ~22 ~3 ~10 ~28 ~3 ~10 stonebrick 2
fill ~22 ~3 ~12 ~22 ~7 ~12 stonebrick 0
setblock ~22 ~3 ~21 wooden_door 8
setblock ~22 ~3 ~22 wooden_door 9
fill ~22 ~3 ~27 ~22 ~20 ~27 stonebrick 2
setblock ~22 ~3 ~37 end_rod 0
setblock ~22 ~3 ~47 end_rod 0
fill ~22 ~3 ~52 ~22 ~3 ~53 wall_banner 5
fill ~22 ~3 ~61 ~22 ~3 ~62 wall_banner 5
fill ~22 ~3 ~77 ~24 ~3 ~77 stonebrick 2
fill ~22 ~3 ~78 ~23 ~3 ~78 stonebrick 2
fill ~23 ~3 ~66 ~26 ~3 ~66 stonebrick 0
setblock ~24 ~3 ~36 end_rod 0
setblock ~24 ~3 ~48 end_rod 0
fill ~24 ~3 ~67 ~26 ~3 ~67 stonebrick 2
fill ~24 ~3 ~76 ~25 ~3 ~76 stonebrick 2
fill ~25 ~3 ~5 ~26 ~3 ~5 stonebrick 2
fill ~25 ~3 ~6 ~26 ~3 ~6 stonebrick 2
fill ~25 ~3 ~75 ~26 ~3 ~75 stonebrick 2
fill ~26 ~3 ~74 ~27 ~3 ~74 stonebrick 2
fill ~28 ~3 ~74 ~29 ~3 ~74 stonebrick 0
fill ~29 ~3 ~10 ~29 ~9 ~10 stonebrick 1
setblock ~29 ~3 ~36 dark_oak_stairs 2
setblock ~29 ~3 ~37 wool 14
setblock ~29 ~3 ~38 dark_oak_stairs 3
setblock ~29 ~3 ~41 dark_oak_stairs 2
setblock ~29 ~3 ~42 wool 14
setblock ~29 ~3 ~43 dark_oak_stairs 3
fill ~30 ~3 ~9 ~33 ~3 ~9 planks 5
setblock ~30 ~3 ~10 dark_oak_stairs 1
fill ~30 ~3 ~74 ~31 ~3 ~74 stonebrick 2
fill ~31 ~3 ~10 ~32 ~3 ~10 wooden_slab 5
fill ~31 ~3 ~66 ~32 ~3 ~66 stonebrick 0
fill ~31 ~3 ~83 ~40 ~3 ~83 stonebrick 2
setblock ~33 ~3 ~10 dark_oak_stairs 0
fill ~33 ~3 ~36 ~34 ~3 ~36 carpet 8
fill ~33 ~3 ~37 ~34 ~3 ~37 carpet 8
fill ~33 ~3 ~38 ~34 ~3 ~38 carpet 8
fill ~33 ~3 ~41 ~34 ~3 ~41 carpet 8
fill ~33 ~3 ~42 ~34 ~3 ~42 carpet 8
fill ~33 ~3 ~43 ~34 ~3 ~43 carpet 8
fill ~33 ~3 ~66 ~34 ~3 ~66 stonebrick 2
fill ~34 ~3 ~10 ~34 ~4 ~10 stonebrick 1
setblock ~34 ~3 ~22 dark_oak_stairs 2
fill ~34 ~3 ~23 ~37 ~3 ~23 planks 5
setblock ~34 ~3 ~35 skull 1
setblock ~34 ~3 ~44 skull 1
fill ~34 ~3 ~84 ~35 ~3 ~84 vine 4
fill ~35 ~3 ~6 ~42 ~3 ~6 brick_block 0
fill ~35 ~3 ~22 ~36 ~3 ~22 ladder 2
setblock ~35 ~3 ~30 dark_oak_stairs 0
fill ~35 ~3 ~34 ~37 ~3 ~34 carpet 8
fill ~35 ~3 ~35 ~37 ~3 ~35 carpet 8
setblock ~35 ~3 ~39 skull 1
fill ~35 ~3 ~44 ~37 ~3 ~44 carpet 8
fill ~35 ~3 ~45 ~37 ~3 ~45 carpet 8
setblock ~35 ~3 ~49 dark_oak_stairs 0
setblock ~36 ~3 ~30 wool 14
setblock ~36 ~3 ~49 wool 14
setblock ~36 ~3 ~50 trapdoor 13
setblock ~37 ~3 ~22 dark_oak_stairs 2
setblock ~37 ~3 ~30 dark_oak_stairs 1
fill ~37 ~3 ~39 ~37 ~3 ~40 BLOCKNOTFOUND:216 0
setblock ~37 ~3 ~49 dark_oak_stairs 1
fill ~38 ~3 ~38 ~39 ~3 ~38 BLOCKNOTFOUND:216 0
setblock ~38 ~3 ~39 lit_pumpkin 3
setblock ~38 ~3 ~40 BLOCKNOTFOUND:219 1
fill ~38 ~3 ~41 ~39 ~3 ~41 BLOCKNOTFOUND:216 0
setblock ~38 ~3 ~44 skull 1
fill ~38 ~3 ~66 ~49 ~3 ~66 stonebrick 2
setblock ~39 ~3 ~39 BLOCKNOTFOUND:219 1
setblock ~39 ~3 ~40 lit_pumpkin 2
setblock ~39 ~3 ~63 trapdoor 6
setblock ~40 ~3 ~22 dark_oak_stairs 2
fill ~40 ~3 ~23 ~43 ~3 ~23 planks 5
setblock ~40 ~3 ~30 dark_oak_stairs 0
fill ~40 ~3 ~34 ~42 ~3 ~34 carpet 8
fill ~40 ~3 ~35 ~42 ~3 ~35 carpet 8
setblock ~40 ~3 ~36 skull 1
fill ~40 ~3 ~39 ~40 ~3 ~40 BLOCKNOTFOUND:216 0
fill ~40 ~3 ~44 ~42 ~3 ~44 carpet 8
fill ~40 ~3 ~45 ~42 ~3 ~45 carpet 8
setblock ~40 ~3 ~49 dark_oak_stairs 0
setblock ~40 ~3 ~62 trapdoor 4
setblock ~40 ~3 ~63 sticky_piston 9
setblock ~40 ~3 ~64 trapdoor 5
fill ~41 ~3 ~22 ~42 ~3 ~22 ladder 2
setblock ~41 ~3 ~30 wool 14
setblock ~41 ~3 ~49 wool 14
setblock ~41 ~3 ~63 trapdoor 7
setblock ~41 ~3 ~85 vine 4
fill ~41 ~3 ~87 ~41 ~4 ~87 slime 0
setblock ~42 ~3 ~30 dark_oak_stairs 1
setblock ~42 ~3 ~49 dark_oak_stairs 1
setblock ~42 ~3 ~65 end_rod 0
fill ~42 ~3 ~67 ~42 ~3 ~75 stonebrick 0
fill ~43 ~3 ~10 ~43 ~30 ~10 stonebrick 2
setblock ~43 ~3 ~22 dark_oak_stairs 2
setblock ~43 ~3 ~35 skull 1
fill ~43 ~3 ~36 ~44 ~3 ~36 carpet 8
fill ~43 ~3 ~37 ~44 ~3 ~37 carpet 8
fill ~43 ~3 ~38 ~44 ~3 ~38 carpet 8
setblock ~43 ~3 ~40 skull 1
fill ~43 ~3 ~41 ~44 ~3 ~41 carpet 8
fill ~43 ~3 ~42 ~44 ~3 ~42 carpet 8
fill ~43 ~3 ~43 ~44 ~3 ~43 carpet 8
setblock ~43 ~3 ~44 skull 1
setblock ~43 ~3 ~73 web 0
fill ~43 ~3 ~74 ~43 ~4 ~74 stonebrick 0
fill ~43 ~3 ~75 ~43 ~4 ~75 stonebrick 0
fill ~44 ~3 ~9 ~47 ~3 ~9 planks 5
setblock ~44 ~3 ~10 dark_oak_stairs 1
fill ~45 ~3 ~10 ~46 ~3 ~10 wooden_slab 5
setblock ~45 ~3 ~87 wooden_door 9
fill ~46 ~3 ~62 ~51 ~3 ~62 planks 1
setblock ~47 ~3 ~10 dark_oak_stairs 0
fill ~47 ~3 ~75 ~47 ~7 ~75 stonebrick 2
fill ~48 ~3 ~10 ~48 ~12 ~10 stonebrick 1
setblock ~48 ~3 ~36 dark_oak_stairs 2
setblock ~48 ~3 ~37 wool 14
setblock ~48 ~3 ~38 dark_oak_stairs 3
setblock ~48 ~3 ~41 dark_oak_stairs 2
setblock ~48 ~3 ~42 wool 14
setblock ~48 ~3 ~43 dark_oak_stairs 3
fill ~48 ~3 ~76 ~62 ~3 ~76 stonebrick 2
fill ~49 ~3 ~10 ~49 ~11 ~10 stonebrick 2
setblock ~49 ~3 ~42 trapdoor 15
setblock ~49 ~3 ~84 slime 0
fill ~49 ~3 ~85 ~49 ~4 ~85 mossy_cobblestone 0
fill ~49 ~3 ~86 ~49 ~4 ~86 mossy_cobblestone 0
fill ~49 ~3 ~87 ~49 ~4 ~87 mossy_cobblestone 0
fill ~50 ~3 ~9 ~53 ~3 ~9 planks 5
setblock ~50 ~3 ~10 dark_oak_stairs 1
fill ~50 ~3 ~66 ~51 ~3 ~66 stonebrick 1
setblock ~50 ~3 ~77 slime 0
fill ~51 ~3 ~10 ~52 ~3 ~10 wooden_slab 5
setblock ~51 ~3 ~63 torch 3
fill ~52 ~3 ~66 ~54 ~3 ~66 stonebrick 2
setblock ~53 ~3 ~10 dark_oak_stairs 0
setblock ~53 ~3 ~14 end_rod 0
setblock ~53 ~3 ~45 end_rod 0
setblock ~53 ~3 ~57 end_rod 0
fill ~54 ~3 ~9 ~55 ~3 ~9 vine 1
fill ~54 ~3 ~12 ~54 ~4 ~12 stonebrick 1
setblock ~54 ~3 ~13 stonebrick 2
fill ~54 ~3 ~26 ~54 ~5 ~26 stonebrick 1
fill ~54 ~3 ~28 ~54 ~3 ~31 glowstone 0
fill ~54 ~3 ~35 ~54 ~3 ~38 glowstone 0
setblock ~54 ~3 ~42 stonebrick 0
fill ~54 ~3 ~43 ~54 ~3 ~45 stonebrick 1
fill ~54 ~3 ~56 ~54 ~4 ~56 stonebrick 1
fill ~54 ~3 ~57 ~54 ~3 ~58 stonebrick 1
setblock ~54 ~3 ~59 stonebrick 0
fill ~54 ~3 ~62 ~54 ~4 ~62 stonebrick 2
fill ~55 ~3 ~10 ~55 ~5 ~10 mossy_cobblestone 0
setblock ~55 ~3 ~11 slime 0
fill ~55 ~3 ~16 ~55 ~19 ~16 stonebrick 2
fill ~55 ~3 ~22 ~58 ~3 ~22 stonebrick 2
fill ~55 ~3 ~28 ~56 ~3 ~28 planks 5
fill ~55 ~3 ~29 ~56 ~3 ~29 planks 5
fill ~55 ~3 ~30 ~56 ~3 ~30 planks 5
fill ~55 ~3 ~31 ~56 ~3 ~31 planks 5
fill ~55 ~3 ~35 ~56 ~3 ~35 planks 5
fill ~55 ~3 ~36 ~56 ~3 ~36 planks 5
fill ~55 ~3 ~37 ~56 ~3 ~37 planks 5
fill ~55 ~3 ~38 ~56 ~3 ~38 planks 5
fill ~55 ~3 ~44 ~69 ~3 ~44 stonebrick 2
fill ~55 ~3 ~45 ~69 ~3 ~45 stonebrick 1
fill ~55 ~3 ~57 ~61 ~3 ~57 stonebrick 2
fill ~55 ~3 ~58 ~61 ~3 ~58 stonebrick 2
fill ~56 ~3 ~42 ~58 ~3 ~42 vine 3
fill ~57 ~3 ~15 ~60 ~3 ~15 stonebrick 2
fill ~59 ~3 ~22 ~64 ~3 ~22 stonebrick 1
fill ~59 ~3 ~42 ~60 ~3 ~42 vine 1
fill ~61 ~3 ~15 ~61 ~4 ~15 stonebrick 0
fill ~61 ~3 ~23 ~62 ~3 ~23 vine 4
fill ~62 ~3 ~15 ~64 ~3 ~15 stonebrick 2
fill ~62 ~3 ~58 ~63 ~3 ~58 stonebrick 0
fill ~62 ~3 ~64 ~62 ~19 ~64 stonebrick 2
fill ~62 ~3 ~77 ~62 ~5 ~77 slime 0
setblock ~63 ~3 ~23 slime 0
fill ~63 ~3 ~57 ~63 ~-1 ~57 stonebrick 2
fill ~63 ~3 ~63 ~66 ~3 ~63 brick_block 0
fill ~63 ~3 ~69 ~66 ~3 ~69 brick_block 0
fill ~63 ~3 ~70 ~65 ~3 ~70 vine 6
fill ~64 ~3 ~16 ~64 ~10 ~16 stonebrick 2
setblock ~64 ~3 ~18 stained_glass 14
fill ~64 ~3 ~19 ~64 ~7 ~19 stained_glass 11
setblock ~64 ~3 ~20 stained_glass 14
fill ~64 ~3 ~21 ~64 ~8 ~21 planks 5
fill ~64 ~3 ~23 ~64 ~8 ~23 mossy_cobblestone 0
setblock ~64 ~3 ~57 stonebrick 1
fill ~64 ~3 ~58 ~71 ~3 ~58 stonebrick 2
setblock ~65 ~3 ~57 stonebrick 2
fill ~65 ~3 ~60 ~66 ~3 ~60 vine 4
fill ~66 ~3 ~57 ~69 ~3 ~57 stonebrick 1
fill ~66 ~3 ~70 ~67 ~3 ~70 vine 4
fill ~68 ~3 ~51 ~68 ~4 ~51 leaves 0
fill ~68 ~3 ~53 ~69 ~3 ~53 leaves 0
fill ~69 ~3 ~52 ~69 ~4 ~52 leaves 0
fill ~69 ~3 ~59 ~70 ~3 ~59 vine 12
setblock ~70 ~3 ~45 glowstone 0
fill ~70 ~3 ~57 ~71 ~3 ~57 stonebrick 2
fill ~71 ~3 ~44 ~71 ~7 ~44 stonebrick 1
fill ~71 ~3 ~45 ~71 ~11 ~45 stonebrick 2
fill ~5 ~4 ~37 ~5 ~7 ~37 planks 5
fill ~5 ~4 ~38 ~5 ~7 ~38 planks 5
fill ~5 ~4 ~39 ~5 ~7 ~39 planks 5
fill ~5 ~4 ~46 ~5 ~7 ~46 planks 5
fill ~5 ~4 ~47 ~5 ~7 ~47 planks 5
fill ~5 ~4 ~48 ~5 ~7 ~48 planks 5
fill ~6 ~4 ~4 ~7 ~4 ~4 vine 1
fill ~6 ~4 ~5 ~7 ~4 ~5 stonebrick 2
setblock ~6 ~4 ~35 stonebrick 1
fill ~6 ~4 ~41 ~6 ~6 ~41 stonebrick 2
fill ~6 ~4 ~42 ~6 ~14 ~42 stonebrick 2
fill ~6 ~4 ~51 ~22 ~4 ~51 stonebrick 2
fill ~7 ~4 ~33 ~22 ~4 ~33 stonebrick 2
setblock ~8 ~4 ~50 dark_oak_stairs 4
fill ~9 ~4 ~50 ~11 ~4 ~50 wooden_slab 13
fill ~11 ~4 ~69 ~12 ~4 ~69 planks 5
fill ~11 ~4 ~72 ~12 ~4 ~72 planks 5
setblock ~12 ~4 ~50 dark_oak_stairs 5
setblock ~12 ~4 ~66 mossy_cobblestone 0
setblock ~12 ~4 ~70 stained_glass 11
fill ~13 ~4 ~66 ~13 ~14 ~66 stonebrick 2
fill ~13 ~4 ~76 ~14 ~4 ~76 stonebrick 2
fill ~14 ~4 ~64 ~14 ~6 ~64 mossy_cobblestone 0
fill ~14 ~4 ~77 ~16 ~4 ~77 stonebrick 2
setblock ~15 ~4 ~63 slime 0
fill ~15 ~4 ~64 ~16 ~4 ~64 stonebrick 2
fill ~15 ~4 ~78 ~16 ~4 ~78 stonebrick 2
fill ~16 ~4 ~4 ~18 ~4 ~4 vine 1
fill ~16 ~4 ~5 ~17 ~4 ~5 stonebrick 2
fill ~16 ~4 ~6 ~17 ~4 ~6 stonebrick 2
setblock ~16 ~4 ~50 dark_oak_stairs 4
fill ~17 ~4 ~50 ~19 ~4 ~50 wooden_slab 13
fill ~17 ~4 ~63 ~17 ~5 ~63 stonebrick 1
fill ~18 ~4 ~63 ~22 ~4 ~63 stonebrick 2
setblock ~18 ~4 ~78 stained_glass 11
setblock ~19 ~4 ~64 end_rod 0
setblock ~20 ~4 ~50 dark_oak_stairs 5
setblock ~20 ~4 ~78 stained_glass 11
fill ~21 ~4 ~13 ~21 ~13 ~13 planks 5
fill ~21 ~4 ~14 ~21 ~5 ~14 stained_glass 14
fill ~21 ~4 ~15 ~21 ~12 ~15 stained_glass 11
fill ~21 ~4 ~16 ~21 ~13 ~16 planks 5
fill ~21 ~4 ~19 ~22 ~4 ~19 planks 5
fill ~21 ~4 ~24 ~22 ~4 ~24 planks 5
fill ~21 ~4 ~28 ~21 ~13 ~28 planks 5
fill ~21 ~4 ~29 ~21 ~12 ~29 stained_glass 11
fill ~21 ~4 ~30 ~21 ~5 ~30 stained_glass 14
fill ~21 ~4 ~31 ~21 ~13 ~31 planks 5
fill ~21 ~4 ~52 ~21 ~6 ~52 stained_glass 14
fill ~21 ~4 ~53 ~21 ~6 ~53 stained_glass 14
fill ~21 ~4 ~54 ~21 ~6 ~54 stained_glass 14
fill ~21 ~4 ~55 ~21 ~6 ~55 stained_glass 14
fill ~21 ~4 ~59 ~21 ~6 ~59 stained_glass 14
fill ~21 ~4 ~60 ~21 ~6 ~60 stained_glass 14
fill ~21 ~4 ~61 ~21 ~6 ~61 stained_glass 14
fill ~21 ~4 ~62 ~21 ~6 ~62 stained_glass 14
fill ~22 ~4 ~10 ~28 ~4 ~10 stonebrick 2
setblock ~22 ~4 ~13 dark_oak_stairs 3
setblock ~22 ~4 ~16 dark_oak_stairs 2
fill ~22 ~4 ~21 ~22 ~6 ~21 planks 0
fill ~22 ~4 ~22 ~22 ~6 ~22 planks 0
setblock ~22 ~4 ~28 dark_oak_stairs 3
setblock ~22 ~4 ~31 dark_oak_stairs 2
setblock ~22 ~4 ~37 cobblestone_wall 0
setblock ~22 ~4 ~47 cobblestone_wall 0
fill ~22 ~4 ~77 ~24 ~4 ~77 stonebrick 2
fill ~22 ~4 ~78 ~23 ~4 ~78 stonebrick 2
fill ~23 ~4 ~66 ~26 ~4 ~66 stonebrick 0
setblock ~24 ~4 ~36 cobblestone_wall 0
setblock ~24 ~4 ~48 cobblestone_wall 0
fill ~24 ~4 ~67 ~26 ~4 ~67 stonebrick 2
fill ~24 ~4 ~76 ~25 ~4 ~76 stonebrick 2
fill ~25 ~4 ~5 ~26 ~4 ~5 stonebrick 2
fill ~25 ~4 ~6 ~26 ~4 ~6 stonebrick 2
fill ~25 ~4 ~74 ~27 ~4 ~74 stonebrick 2
fill ~25 ~4 ~75 ~26 ~4 ~75 stonebrick 2
setblock ~26 ~4 ~69 stonebrick 1
fill ~28 ~4 ~74 ~29 ~4 ~74 stonebrick 0
setblock ~29 ~4 ~37 wooden_slab 5
setblock ~29 ~4 ~42 wooden_slab 5
fill ~30 ~4 ~9 ~30 ~14 ~9 planks 5
