fill ~1 ~-3 ~31 ~3 ~-3 ~31 planks 2
fill ~1 ~-3 ~32 ~1 ~-1 ~32 planks 2
fill ~1 ~-3 ~33 ~1 ~-3 ~33 planks 2
fill ~1 ~-3 ~34 ~3 ~-3 ~34 planks 2
fill ~1 ~-3 ~35 ~4 ~-3 ~35 planks 2
fill ~1 ~-3 ~51 ~4 ~-3 ~51 planks 2
fill ~1 ~-3 ~52 ~2 ~-3 ~52 planks 2
fill ~1 ~-3 ~67 ~2 ~-3 ~67 sand 1
fill ~1 ~-3 ~68 ~1 ~-3 ~68 sand 0
fill ~1 ~-3 ~69 ~4 ~-3 ~69 sand 0
fill ~1 ~-3 ~70 ~8 ~-3 ~70 sand 0
fill ~1 ~-3 ~71 ~7 ~-3 ~71 sand 0
fill ~1 ~-3 ~72 ~10 ~-3 ~72 sand 0
fill ~1 ~-3 ~73 ~9 ~-3 ~73 sand 0
fill ~1 ~-3 ~74 ~10 ~-3 ~74 sand 0
fill ~1 ~-3 ~75 ~10 ~-3 ~75 sand 0
fill ~1 ~-3 ~76 ~11 ~-3 ~76 sand 0
fill ~1 ~-3 ~77 ~12 ~-3 ~77 sand 0
fill ~1 ~-3 ~78 ~13 ~-3 ~78 sand 0
fill ~1 ~-3 ~79 ~13 ~-3 ~79 sand 0
fill ~1 ~-3 ~80 ~13 ~-3 ~80 sand 0
fill ~1 ~-3 ~81 ~14 ~-3 ~81 sand 0
fill ~1 ~-3 ~82 ~14 ~-3 ~82 sand 0
fill ~1 ~-3 ~83 ~15 ~-3 ~83 sand 0
fill ~1 ~-3 ~84 ~15 ~-3 ~84 sand 0
fill ~1 ~-3 ~85 ~16 ~-3 ~85 sand 0
fill ~1 ~-3 ~86 ~18 ~-3 ~86 sand 0
fill ~1 ~-3 ~87 ~20 ~-3 ~87 sand 0
fill ~1 ~-3 ~88 ~24 ~-3 ~88 sand 0
fill ~1 ~-3 ~89 ~25 ~-3 ~89 sand 0
fill ~1 ~-3 ~90 ~26 ~-3 ~90 sand 0
fill ~1 ~-3 ~91 ~28 ~-3 ~91 sand 0
fill ~1 ~-3 ~92 ~28 ~-3 ~92 sand 0
fill ~1 ~-3 ~93 ~28 ~-3 ~93 sand 0
fill ~1 ~-3 ~105 ~1 ~0 ~105 planks 2
fill ~2 ~-3 ~29 ~3 ~-3 ~29 planks 2
fill ~2 ~-3 ~30 ~2 ~-2 ~30 wool 15
fill ~2 ~-3 ~32 ~2 ~-3 ~33 sandstone 0
setblock ~2 ~-3 ~36 planks 2
setblock ~2 ~-3 ~37 sandstone 0
fill ~2 ~-3 ~50 ~5 ~-3 ~50 planks 2
fill ~2 ~-3 ~53 ~2 ~-1 ~53 planks 2
fill ~2 ~-3 ~54 ~4 ~-3 ~54 planks 2
fill ~2 ~-3 ~66 ~7 ~-3 ~66 sand 1
fill ~2 ~-3 ~68 ~4 ~-3 ~68 sand 1
fill ~2 ~-3 ~94 ~28 ~-3 ~94 sand 0
fill ~3 ~-3 ~28 ~3 ~-2 ~28 wool 15
fill ~3 ~-3 ~30 ~4 ~-3 ~30 planks 2
fill ~3 ~-3 ~32 ~4 ~-3 ~32 planks 2
fill ~3 ~-3 ~33 ~3 ~1 ~33 planks 2
fill ~3 ~-3 ~36 ~4 ~-3 ~36 sandstone 0
fill ~3 ~-3 ~37 ~8 ~-3 ~37 planks 2
fill ~3 ~-3 ~38 ~9 ~-3 ~38 planks 2
setblock ~3 ~-3 ~48 sandstone 0
setblock ~3 ~-3 ~49 planks 2
fill ~3 ~-3 ~52 ~3 ~-3 ~53 sandstone 0
fill ~3 ~-3 ~55 ~3 ~-2 ~55 wool 15
fill ~3 ~-3 ~56 ~4 ~-3 ~56 planks 2
fill ~3 ~-3 ~65 ~10 ~-3 ~65 sand 1
fill ~3 ~-3 ~67 ~3 ~-3 ~67 sand 0
fill ~4 ~-3 ~27 ~6 ~-3 ~27 end_stone 0
fill ~4 ~-3 ~28 ~4 ~-1 ~28 sandstone 0
fill ~4 ~-3 ~31 ~7 ~-3 ~31 sandstone 0
fill ~4 ~-3 ~33 ~13 ~-3 ~33 sandstone 0
fill ~4 ~-3 ~34 ~4 ~-1 ~34 sandstone 0
fill ~4 ~-3 ~39 ~8 ~-3 ~39 planks 2
fill ~4 ~-3 ~47 ~10 ~-3 ~47 planks 2
fill ~4 ~-3 ~48 ~9 ~-3 ~48 planks 2
fill ~4 ~-3 ~49 ~5 ~-3 ~49 sandstone 0
fill ~4 ~-3 ~52 ~4 ~1 ~52 planks 2
fill ~4 ~-3 ~53 ~5 ~-3 ~53 planks 2
fill ~4 ~-3 ~55 ~5 ~-3 ~55 planks 2
fill ~4 ~-3 ~57 ~4 ~-2 ~57 wool 15
fill ~4 ~-3 ~64 ~8 ~-3 ~64 sand 1
fill ~4 ~-3 ~67 ~4 ~-2 ~67 sand 1
fill ~4 ~-3 ~95 ~26 ~-3 ~95 sand 0
fill ~5 ~-3 ~19 ~7 ~-3 ~19 planks 0
fill ~5 ~-3 ~28 ~5 ~-2 ~28 end_stone 0
fill ~5 ~-3 ~29 ~6 ~-3 ~29 end_stone 0
fill ~5 ~-3 ~30 ~6 ~-3 ~30 sandstone 0
fill ~5 ~-3 ~32 ~9 ~-3 ~32 sandstone 0
fill ~5 ~-3 ~34 ~5 ~-3 ~34 planks 2
fill ~5 ~-3 ~35 ~12 ~-3 ~35 sandstone 0
fill ~5 ~-3 ~36 ~6 ~-3 ~36 planks 2
fill ~5 ~-3 ~40 ~7 ~-3 ~40 planks 2
fill ~5 ~-3 ~46 ~9 ~-3 ~46 planks 2
fill ~5 ~-3 ~51 ~5 ~-1 ~51 sandstone 0
fill ~5 ~-3 ~52 ~14 ~-3 ~52 sandstone 0
fill ~5 ~-3 ~54 ~8 ~-3 ~54 sandstone 0
fill ~5 ~-3 ~57 ~5 ~-1 ~57 sandstone 0
fill ~5 ~-3 ~58 ~7 ~-3 ~58 end_stone 0
fill ~5 ~-3 ~67 ~5 ~-3 ~67 sand 0
fill ~5 ~-3 ~68 ~6 ~-3 ~68 sand 0
setblock ~5 ~-3 ~69 sand 1
fill ~6 ~-3 ~16 ~6 ~-1 ~16 planks 2
fill ~6 ~-3 ~18 ~6 ~8 ~18 planks 2
fill ~6 ~-3 ~28 ~6 ~-3 ~28 brick_block 0
fill ~6 ~-3 ~34 ~13 ~-3 ~34 sandstone 0
fill ~6 ~-3 ~45 ~8 ~-3 ~45 planks 2
fill ~6 ~-3 ~49 ~7 ~-3 ~49 planks 2
fill ~6 ~-3 ~50 ~13 ~-3 ~50 sandstone 0
fill ~6 ~-3 ~51 ~6 ~-3 ~51 planks 2
fill ~6 ~-3 ~53 ~10 ~-3 ~53 sandstone 0
fill ~6 ~-3 ~55 ~7 ~-3 ~55 sandstone 0
fill ~6 ~-3 ~56 ~7 ~-3 ~56 end_stone 0
fill ~6 ~-3 ~57 ~6 ~-2 ~57 end_stone 0
fill ~6 ~-3 ~63 ~6 ~-3 ~63 sand 1
fill ~6 ~-3 ~67 ~7 ~-3 ~67 sand 1
fill ~6 ~-3 ~69 ~7 ~-3 ~69 sand 0
fill ~6 ~-3 ~96 ~24 ~-3 ~96 sand 0
fill ~7 ~-3 ~27 ~8 ~-3 ~27 brick_block 0
setblock ~7 ~-3 ~28 end_stone 0
fill ~7 ~-3 ~29 ~10 ~-3 ~29 brick_block 0
setblock ~7 ~-3 ~30 end_stone 0
fill ~7 ~-3 ~36 ~11 ~-3 ~36 sandstone 0
fill ~7 ~-3 ~51 ~14 ~-3 ~51 sandstone 0
fill ~7 ~-3 ~57 ~7 ~-3 ~57 brick_block 0
fill ~7 ~-3 ~68 ~15 ~-3 ~68 sand 1
fill ~7 ~-3 ~97 ~23 ~-3 ~97 sand 0
fill ~8 ~-3 ~17 ~8 ~4 ~17 planks 0
fill ~8 ~-3 ~20 ~8 ~3 ~20 planks 0
fill ~8 ~-3 ~28 ~10 ~-3 ~28 brick_block 0
fill ~8 ~-3 ~30 ~10 ~-3 ~30 quartz_block 0
fill ~8 ~-3 ~31 ~12 ~-3 ~31 end_stone 0
fill ~8 ~-3 ~49 ~12 ~-3 ~49 sandstone 0
setblock ~8 ~-3 ~55 end_stone 0
fill ~8 ~-3 ~56 ~11 ~-3 ~56 brick_block 0
setblock ~8 ~-3 ~57 end_stone 0
fill ~8 ~-3 ~58 ~9 ~-3 ~58 brick_block 0
fill ~8 ~-3 ~66 ~8 ~-3 ~67 sand 0
fill ~8 ~-3 ~69 ~8 ~-2 ~69 sand 1
fill ~8 ~-3 ~71 ~9 ~-3 ~71 sand 1
fill ~9 ~-3 ~18 ~9 ~0 ~18 planks 2
fill ~9 ~-3 ~37 ~12 ~-3 ~37 sandstone 0
fill ~9 ~-3 ~54 ~13 ~-3 ~54 end_stone 0
fill ~9 ~-3 ~55 ~11 ~-3 ~55 quartz_block 0
fill ~9 ~-3 ~57 ~11 ~-3 ~57 brick_block 0
fill ~9 ~-3 ~66 ~12 ~-3 ~66 sand 1
fill ~9 ~-3 ~67 ~14 ~-3 ~67 sand 1
setblock ~9 ~-3 ~69 sand 0
setblock ~9 ~-3 ~70 sand 1
fill ~9 ~-3 ~98 ~22 ~-3 ~98 sand 0
fill ~10 ~-3 ~32 ~12 ~-3 ~32 end_stone 0
fill ~10 ~-3 ~38 ~11 ~-3 ~38 sandstone 0
fill ~10 ~-3 ~48 ~13 ~-3 ~48 sandstone 0
fill ~10 ~-3 ~69 ~16 ~-3 ~69 sand 1
fill ~10 ~-3 ~70 ~10 ~-2 ~70 sand 0
fill ~10 ~-3 ~71 ~10 ~-1 ~71 sand 0
fill ~10 ~-3 ~73 ~15 ~-3 ~73 sand 1
fill ~10 ~-3 ~99 ~22 ~-3 ~99 sand 0
fill ~11 ~-3 ~4 ~11 ~-1 ~4 planks 3
fill ~11 ~-3 ~29 ~11 ~-3 ~32 end_stone 0
fill ~11 ~-3 ~47 ~12 ~-3 ~47 sandstone 0
fill ~11 ~-3 ~53 ~13 ~-3 ~53 end_stone 0
fill ~11 ~-3 ~70 ~16 ~-3 ~70 sand 1
fill ~11 ~-3 ~71 ~15 ~-3 ~71 sand 1
fill ~11 ~-3 ~72 ~16 ~-3 ~72 sand 1
fill ~11 ~-3 ~74 ~16 ~-3 ~74 sand 1
fill ~11 ~-3 ~75 ~16 ~-3 ~75 sand 1
fill ~11 ~-3 ~100 ~21 ~-3 ~100 sand 0
fill ~12 ~-3 ~2 ~12 ~1 ~2 planks 2
fill ~12 ~-3 ~3 ~12 ~-3 ~3 planks 3
fill ~12 ~-3 ~30 ~12 ~0 ~30 end_stone 0
fill ~12 ~-3 ~36 ~30 ~-3 ~36 sand 0
fill ~12 ~-3 ~38 ~33 ~-3 ~38 sand 0
fill ~12 ~-3 ~39 ~35 ~-3 ~39 sand 0
fill ~12 ~-3 ~40 ~36 ~-3 ~40 sand 0
fill ~12 ~-3 ~41 ~37 ~-3 ~41 sand 0
fill ~12 ~-3 ~55 ~13 ~-3 ~55 end_stone 0
fill ~12 ~-3 ~56 ~12 ~-3 ~53 end_stone 0
fill ~12 ~-3 ~57 ~12 ~-3 ~57 sand 0
fill ~12 ~-3 ~76 ~16 ~-3 ~76 sand 1
fill ~13 ~-3 ~0 ~14 ~-3 ~0 planks 0
fill ~13 ~-3 ~31 ~13 ~-3 ~34 sandstone 0
fill ~13 ~-3 ~35 ~29 ~-3 ~35 sand 0
fill ~13 ~-3 ~37 ~31 ~-3 ~37 sand 0
fill ~13 ~-3 ~42 ~38 ~-3 ~42 sand 0
fill ~13 ~-3 ~43 ~38 ~-3 ~43 sand 0
fill ~13 ~-3 ~77 ~16 ~-3 ~77 sand 1
fill ~13 ~-3 ~101 ~20 ~-3 ~101 sand 0
fill ~14 ~-3 ~1 ~14 ~18 ~1 planks 3
fill ~14 ~-3 ~4 ~14 ~-3 ~4 planks 0
fill ~14 ~-3 ~5 ~14 ~-2 ~5 planks 0
fill ~14 ~-3 ~33 ~26 ~-3 ~33 sand 0
fill ~14 ~-3 ~34 ~27 ~-3 ~34 sand 0
fill ~14 ~-3 ~44 ~39 ~-3 ~44 sand 0
fill ~14 ~-3 ~45 ~39 ~-3 ~45 sand 0
fill ~14 ~-3 ~46 ~40 ~-3 ~46 sand 0
fill ~14 ~-3 ~49 ~14 ~-3 ~50 sand 0
fill ~14 ~-3 ~53 ~14 ~-2 ~53 sandstone 0
fill ~14 ~-3 ~54 ~14 ~-3 ~51 sandstone 0
fill ~14 ~-3 ~55 ~14 ~-3 ~55 sand 0
fill ~14 ~-3 ~78 ~15 ~-3 ~78 sand 1
fill ~14 ~-3 ~79 ~15 ~-3 ~79 sand 1
fill ~14 ~-3 ~80 ~15 ~-3 ~80 sand 1
fill ~14 ~-3 ~102 ~19 ~-3 ~102 sand 0
fill ~15 ~-3 ~0 ~15 ~0 ~0 planks 3
fill ~15 ~-3 ~9 ~15 ~1 ~9 planks 2
fill ~15 ~-3 ~31 ~22 ~-3 ~31 sand 0
fill ~15 ~-3 ~32 ~24 ~-3 ~32 sand 0
fill ~15 ~-3 ~47 ~41 ~-3 ~47 sand 0
fill ~15 ~-3 ~50 ~15 ~-2 ~50 sand 0
fill ~15 ~-3 ~51 ~16 ~-3 ~51 sand 0
fill ~15 ~-3 ~52 ~15 ~-3 ~52 sand 0
fill ~15 ~-3 ~67 ~22 ~-3 ~67 hardened_clay 0
fill ~15 ~-3 ~81 ~15 ~-3 ~81 sand 1
fill ~15 ~-3 ~82 ~16 ~-3 ~82 sand 1
fill ~16 ~-3 ~2 ~16 ~-3 ~2 planks 2
fill ~16 ~-3 ~7 ~16 ~6 ~7 planks 0
fill ~16 ~-3 ~8 ~16 ~-2 ~8 planks 2
fill ~16 ~-3 ~29 ~19 ~-3 ~29 sand 0
fill ~16 ~-3 ~30 ~20 ~-3 ~30 sand 0
fill ~16 ~-3 ~48 ~42 ~-3 ~48 sand 0
fill ~16 ~-3 ~68 ~22 ~-3 ~68 hardened_clay 0
fill ~16 ~-3 ~71 ~17 ~-3 ~71 hardened_clay 0
setblock ~16 ~-3 ~73 hardened_clay 0
fill ~16 ~-3 ~83 ~17 ~-3 ~83 sand 1
fill ~16 ~-3 ~84 ~18 ~-3 ~84 sand 1
fill ~16 ~-3 ~103 ~17 ~-3 ~103 sand 0
fill ~17 ~-3 ~3 ~17 ~0 ~3 planks 2
fill ~17 ~-3 ~6 ~17 ~2 ~6 planks 2
fill ~17 ~-3 ~7 ~17 ~-2 ~7 planks 2
fill ~17 ~-3 ~9 ~17 ~-2 ~9 planks 0
fill ~17 ~-3 ~28 ~17 ~-3 ~28 sand 0
fill ~17 ~-3 ~49 ~42 ~-3 ~49 sand 0
fill ~17 ~-3 ~66 ~22 ~-3 ~66 hardened_clay 0
fill ~17 ~-3 ~69 ~18 ~-3 ~69 hardened_clay 0
fill ~17 ~-3 ~70 ~18 ~-3 ~70 hardened_clay 0
setblock ~17 ~-3 ~72 hardened_clay 0
fill ~17 ~-3 ~85 ~19 ~-3 ~85 sand 1
fill ~18 ~-3 ~8 ~18 ~1 ~8 planks 0
fill ~18 ~-3 ~50 ~18 ~-3 ~51 sand 1
fill ~19 ~-3 ~50 ~41 ~-3 ~50 sand 0
fill ~19 ~-3 ~51 ~19 ~-3 ~29 sand 0
fill ~19 ~-3 ~65 ~22 ~-3 ~65 hardened_clay 0
fill ~19 ~-3 ~86 ~21 ~-3 ~86 sand 1
fill ~20 ~-3 ~51 ~21 ~-3 ~51 sand 1
fill ~20 ~-3 ~52 ~21 ~-3 ~52 sand 1
fill ~20 ~-3 ~53 ~21 ~-3 ~53 sand 1
fill ~20 ~-3 ~64 ~21 ~-3 ~64 hardened_clay 0
fill ~21 ~-3 ~54 ~26 ~-3 ~54 sand 1
fill ~21 ~-3 ~63 ~27 ~-3 ~63 sand 1
fill ~21 ~-3 ~87 ~23 ~-3 ~87 sand 1
fill ~22 ~-3 ~51 ~40 ~-3 ~51 sand 0
fill ~22 ~-3 ~52 ~22 ~-3 ~53 sand 0
fill ~22 ~-3 ~62 ~26 ~-3 ~62 sand 1
fill ~22 ~-3 ~64 ~28 ~-3 ~64 sand 1
fill ~23 ~-3 ~52 ~24 ~-3 ~52 sand 1
fill ~23 ~-3 ~53 ~23 ~-2 ~53 sand 0
fill ~23 ~-3 ~55 ~24 ~-3 ~55 sand 1
fill ~23 ~-3 ~56 ~23 ~-3 ~56 sand 0
setblock ~23 ~-3 ~57 sand 0
fill ~23 ~-3 ~58 ~26 ~-3 ~58 sand 1
fill ~23 ~-3 ~59 ~26 ~-3 ~59 sand 1
fill ~23 ~-3 ~60 ~25 ~-3 ~60 sand 1
fill ~23 ~-3 ~61 ~25 ~-3 ~61 sand 1
fill ~23 ~-3 ~65 ~29 ~-3 ~65 sand 1
fill ~23 ~-3 ~66 ~34 ~-3 ~66 sand 1
fill ~23 ~-3 ~67 ~30 ~-3 ~67 sand 1
fill ~24 ~-3 ~53 ~24 ~-2 ~53 sand 1
fill ~24 ~-3 ~56 ~24 ~-2 ~56 sand 1
fill ~24 ~-3 ~57 ~25 ~-3 ~57 sand 1
fill ~24 ~-3 ~68 ~26 ~-3 ~68 sand 1
fill ~25 ~-3 ~52 ~40 ~-3 ~52 sand 0
fill ~25 ~-3 ~53 ~39 ~-3 ~53 sand 0
fill ~25 ~-3 ~55 ~25 ~-3 ~56 sand 0
fill ~26 ~-3 ~55 ~26 ~-3 ~55 sand 1
fill ~26 ~-3 ~56 ~26 ~-2 ~56 sand 1
fill ~26 ~-3 ~57 ~39 ~-3 ~57 sand 0
fill ~26 ~-3 ~60 ~39 ~-3 ~60 sand 0
fill ~26 ~-3 ~61 ~26 ~-3 ~60 sand 0
fill ~27 ~-3 ~54 ~39 ~-3 ~54 sand 0
fill ~27 ~-3 ~55 ~39 ~-3 ~55 sand 0
fill ~27 ~-3 ~56 ~39 ~-3 ~56 sand 0
fill ~27 ~-3 ~58 ~39 ~-3 ~58 sand 0
fill ~27 ~-3 ~59 ~39 ~-3 ~59 sand 0
fill ~27 ~-3 ~61 ~27 ~-3 ~61 sand 1
fill ~27 ~-3 ~62 ~38 ~-3 ~62 sand 0
fill ~28 ~-3 ~61 ~39 ~-3 ~61 sand 0
fill ~28 ~-3 ~63 ~32 ~-3 ~63 sand 0
fill ~29 ~-3 ~64 ~30 ~-3 ~64 sand 0
fill ~29 ~-3 ~92 ~29 ~-3 ~92 sand 1
fill ~29 ~-3 ~93 ~29 ~-3 ~93 sand 1
fill ~30 ~-3 ~65 ~31 ~-3 ~65 sand 0
fill ~31 ~-3 ~64 ~32 ~-3 ~64 sand 1
fill ~31 ~-3 ~67 ~31 ~-3 ~67 sand 0
fill ~32 ~-3 ~65 ~33 ~-3 ~65 sand 1
fill ~32 ~-3 ~67 ~34 ~-3 ~67 sand 1
fill ~33 ~-3 ~63 ~34 ~-3 ~63 sand 1
fill ~33 ~-3 ~64 ~33 ~-2 ~64 sand 0
fill ~34 ~-3 ~64 ~37 ~-3 ~64 sand 1
fill ~34 ~-3 ~65 ~34 ~-3 ~65 sand 0
fill ~34 ~-3 ~68 ~34 ~-3 ~68 sand 1
setblock ~35 ~-3 ~63 sand 0
setblock ~35 ~-3 ~65 sand 1
fill ~35 ~-3 ~66 ~37 ~-3 ~66 sand 0
fill ~35 ~-3 ~67 ~36 ~-3 ~67 sand 0
setblock ~36 ~-3 ~63 sand 1
fill ~36 ~-3 ~65 ~37 ~-3 ~65 sand 0
fill ~37 ~-3 ~63 ~38 ~-3 ~63 sand 0
fill ~39 ~-3 ~0 ~46 ~-3 ~0 sand 1
fill ~40 ~-3 ~53 ~43 ~-3 ~53 sand 1
fill ~40 ~-3 ~54 ~43 ~-3 ~54 sand 1
fill ~40 ~-3 ~55 ~42 ~-3 ~55 sand 1
fill ~40 ~-3 ~56 ~41 ~-3 ~56 sand 1
fill ~40 ~-3 ~57 ~41 ~-3 ~57 sand 1
fill ~40 ~-3 ~58 ~40 ~-3 ~58 sand 1
fill ~41 ~-3 ~1 ~42 ~-3 ~1 sand 1
fill ~41 ~-3 ~51 ~44 ~-3 ~51 sand 1
fill ~41 ~-3 ~52 ~43 ~-3 ~52 sand 1
fill ~42 ~-3 ~50 ~43 ~-3 ~50 sand 1
fill ~43 ~-3 ~49 ~43 ~-3 ~49 sand 1
fill ~45 ~-3 ~75 ~51 ~-3 ~75 sand 1
fill ~46 ~-3 ~74 ~46 ~-3 ~74 hardened_clay 0
fill ~46 ~-3 ~76 ~51 ~-3 ~76 sand 1
fill ~46 ~-3 ~77 ~48 ~-3 ~77 sand 1
fill ~46 ~-3 ~78 ~48 ~-3 ~78 sand 1
fill ~47 ~-3 ~74 ~49 ~-3 ~74 sand 1
fill ~47 ~-3 ~79 ~53 ~-3 ~79 sand 1
fill ~47 ~-3 ~80 ~48 ~-3 ~80 sand 1
fill ~48 ~-3 ~73 ~49 ~-3 ~73 sand 1
setblock ~48 ~-3 ~81 sand 0
fill ~49 ~-3 ~77 ~50 ~-3 ~77 sand 0
fill ~49 ~-3 ~78 ~50 ~-3 ~78 sand 0
fill ~49 ~-3 ~80 ~50 ~-3 ~80 sand 0
setblock ~49 ~-3 ~81 sand 1
setblock ~49 ~-3 ~82 sand 0
fill ~49 ~-3 ~83 ~51 ~-3 ~83 sand 1
fill ~50 ~-3 ~73 ~55 ~-3 ~73 sand 0
fill ~50 ~-3 ~74 ~51 ~-3 ~74 sand 0
fill ~50 ~-3 ~81 ~50 ~-3 ~81 sand 0
setblock ~50 ~-3 ~82 sand 1
fill ~50 ~-3 ~84 ~52 ~-3 ~84 sand 1
fill ~51 ~-3 ~77 ~53 ~-3 ~77 sand 1
fill ~51 ~-3 ~78 ~54 ~-3 ~78 sand 1
fill ~51 ~-3 ~80 ~51 ~-2 ~80 sand 1
fill ~51 ~-3 ~81 ~52 ~-3 ~81 sand 1
fill ~51 ~-3 ~82 ~75 ~-3 ~82 sand 0
fill ~51 ~-3 ~85 ~53 ~-3 ~85 sand 1
fill ~51 ~-3 ~112 ~51 ~-2 ~112 planks 2
fill ~51 ~-3 ~113 ~52 ~-3 ~113 planks 0
fill ~51 ~-3 ~114 ~51 ~2 ~114 planks 2
fill ~51 ~-3 ~115 ~51 ~0 ~115 planks 3
fill ~52 ~-3 ~27 ~53 ~-3 ~27 stone 0
fill ~52 ~-3 ~28 ~56 ~-3 ~28 stone 0
fill ~52 ~-3 ~29 ~59 ~-3 ~29 stone 0
fill ~52 ~-3 ~30 ~73 ~-3 ~30 stone 0
fill ~52 ~-3 ~31 ~73 ~-3 ~31 stone 0
fill ~52 ~-3 ~72 ~52 ~-3 ~72 sand 0
setblock ~52 ~-3 ~74 sand 1
fill ~52 ~-3 ~75 ~75 ~-3 ~75 sand 0
fill ~52 ~-3 ~76 ~75 ~-3 ~76 sand 0
fill ~52 ~-3 ~80 ~52 ~-3 ~80 sand 0
fill ~52 ~-3 ~83 ~75 ~-3 ~83 sand 0
fill ~52 ~-3 ~86 ~53 ~-3 ~86 sand 1
fill ~52 ~-3 ~114 ~52 ~13 ~114 planks 3
fill ~52 ~-3 ~115 ~52 ~-2 ~115 planks 0
fill ~53 ~-3 ~26 ~55 ~-3 ~26 stone 6
fill ~53 ~-3 ~32 ~73 ~-3 ~32 stone 0
fill ~53 ~-3 ~33 ~72 ~-3 ~33 stone 0
fill ~53 ~-3 ~71 ~57 ~-3 ~71 sand 0
setblock ~53 ~-3 ~72 sand 1
fill ~53 ~-3 ~74 ~75 ~-3 ~74 sand 0
fill ~53 ~-3 ~80 ~53 ~-2 ~80 sand 1
fill ~53 ~-3 ~81 ~75 ~-3 ~81 sand 0
fill ~53 ~-3 ~84 ~75 ~-3 ~84 sand 0
setblock ~53 ~-3 ~87 sand 1
fill ~53 ~-3 ~113 ~53 ~6 ~113 planks 3
fill ~53 ~-3 ~114 ~53 ~-1 ~114 planks 2
fill ~54 ~-3 ~4 ~58 ~-3 ~4 stone 5
fill ~54 ~-3 ~5 ~62 ~-3 ~5 stone 5
fill ~54 ~-3 ~6 ~60 ~-3 ~6 stone 5
fill ~54 ~-3 ~7 ~60 ~-3 ~7 stone 5
fill ~54 ~-3 ~25 ~54 ~-3 ~25 stone 6
fill ~54 ~-3 ~27 ~55 ~-3 ~27 stone 6
fill ~54 ~-3 ~34 ~72 ~-3 ~34 stone 0
fill ~54 ~-3 ~35 ~71 ~-3 ~35 stone 0
fill ~54 ~-3 ~70 ~57 ~-3 ~70 sand 0
fill ~54 ~-3 ~72 ~56 ~-3 ~72 sand 0
fill ~54 ~-3 ~77 ~75 ~-3 ~77 sand 0
fill ~54 ~-3 ~79 ~75 ~-3 ~79 sand 0
fill ~54 ~-3 ~80 ~75 ~-3 ~80 sand 0
fill ~54 ~-3 ~85 ~75 ~-3 ~85 sand 0
fill ~54 ~-3 ~86 ~75 ~-3 ~86 sand 0
fill ~54 ~-3 ~87 ~75 ~-3 ~87 sand 0
fill ~54 ~-3 ~88 ~75 ~-3 ~88 sand 0
fill ~55 ~-3 ~0 ~55 ~-3 ~0 stone 5
fill ~55 ~-3 ~1 ~57 ~-3 ~1 stone 5
fill ~55 ~-3 ~2 ~56 ~-3 ~2 stone 5
fill ~55 ~-3 ~3 ~57 ~-3 ~3 stone 5
fill ~55 ~-3 ~8 ~62 ~-3 ~8 stone 5
fill ~55 ~-3 ~9 ~60 ~-3 ~9 stone 5
fill ~55 ~-3 ~24 ~55 ~-3 ~25 stone 0
fill ~55 ~-3 ~36 ~71 ~-3 ~36 stone 0
fill ~55 ~-3 ~37 ~70 ~-3 ~37 stone 0
fill ~55 ~-3 ~63 ~57 ~-3 ~63 sand 1
fill ~55 ~-3 ~64 ~55 ~-3 ~64 sand 1
fill ~55 ~-3 ~65 ~55 ~-2 ~65 sand 1
fill ~55 ~-3 ~66 ~56 ~-3 ~66 sand 1
fill ~55 ~-3 ~67 ~58 ~-3 ~67 sand 1
fill ~55 ~-3 ~68 ~59 ~-3 ~68 sand 1
fill ~55 ~-3 ~69 ~59 ~-3 ~69 sand 1
fill ~55 ~-3 ~78 ~75 ~-3 ~78 sand 0
fill ~55 ~-3 ~89 ~75 ~-3 ~89 sand 0
fill ~55 ~-3 ~90 ~75 ~-3 ~90 sand 0
fill ~55 ~-3 ~91 ~75 ~-3 ~91 sand 0
fill ~55 ~-3 ~92 ~75 ~-3 ~92 sand 0
fill ~55 ~-3 ~93 ~75 ~-3 ~93 sand 0
fill ~55 ~-3 ~94 ~75 ~-3 ~94 sand 0
fill ~56 ~-3 ~0 ~66 ~-3 ~0 stone 6
fill ~56 ~-3 ~10 ~60 ~-3 ~10 stone 5
fill ~56 ~-3 ~23 ~65 ~-3 ~23 stone 6
fill ~56 ~-3 ~24 ~66 ~-3 ~24 stone 6
fill ~56 ~-3 ~25 ~58 ~-3 ~25 stone 0
fill ~56 ~-3 ~26 ~57 ~-3 ~26 stone 0
fill ~56 ~-3 ~27 ~59 ~-3 ~27 stone 0
fill ~56 ~-3 ~38 ~69 ~-3 ~38 stone 0
fill ~56 ~-3 ~61 ~56 ~-3 ~61 sand 1
setblock ~56 ~-3 ~62 sand 0
fill ~56 ~-3 ~64 ~75 ~-3 ~64 sand 0
fill ~56 ~-3 ~65 ~57 ~-3 ~65 sand 0
setblock ~56 ~-3 ~73 sand 1
fill ~56 ~-3 ~95 ~75 ~-3 ~95 sand 0
fill ~56 ~-3 ~96 ~75 ~-3 ~96 sand 0
fill ~57 ~-3 ~2 ~58 ~-3 ~2 stone 6
fill ~57 ~-3 ~11 ~63 ~-3 ~11 stone 5
fill ~57 ~-3 ~28 ~57 ~-3 ~28 stone 6
fill ~57 ~-3 ~59 ~58 ~-3 ~59 sand 1
fill ~57 ~-3 ~60 ~57 ~-3 ~60 sand 1
fill ~57 ~-3 ~61 ~75 ~-3 ~61 sand 0
fill ~57 ~-3 ~62 ~57 ~-2 ~62 sand 1
fill ~57 ~-3 ~66 ~57 ~-1 ~66 sand 0
fill ~57 ~-3 ~72 ~57 ~-2 ~72 sand 1
fill ~57 ~-3 ~73 ~75 ~-3 ~73 sand 0
fill ~57 ~-3 ~97 ~74 ~-3 ~97 sand 0
fill ~57 ~-3 ~98 ~71 ~-3 ~98 sand 0
fill ~58 ~-3 ~1 ~65 ~-3 ~1 stone 6
fill ~58 ~-3 ~3 ~58 ~-1 ~3 stone 6
fill ~58 ~-3 ~22 ~65 ~-3 ~22 stone 6
fill ~58 ~-3 ~26 ~58 ~-2 ~26 stone 6
fill ~58 ~-3 ~28 ~59 ~-3 ~28 stone 0
fill ~58 ~-3 ~39 ~67 ~-3 ~39 stone 0
fill ~58 ~-3 ~45 ~58 ~-3 ~45 sand 1
fill ~58 ~-3 ~46 ~58 ~-3 ~46 sand 1
fill ~58 ~-3 ~47 ~74 ~-3 ~47 sand 0
fill ~58 ~-3 ~48 ~74 ~-3 ~48 sand 0
fill ~58 ~-3 ~49 ~58 ~-3 ~49 sand 1
fill ~58 ~-3 ~50 ~58 ~-3 ~50 sand 0
fill ~58 ~-3 ~51 ~59 ~-3 ~51 sand 1
fill ~58 ~-3 ~58 ~58 ~-3 ~58 sand 1
fill ~58 ~-3 ~60 ~75 ~-3 ~60 sand 0
fill ~58 ~-3 ~62 ~75 ~-3 ~62 sand 0
fill ~58 ~-3 ~63 ~75 ~-3 ~63 sand 0
fill ~58 ~-3 ~65 ~59 ~-3 ~65 sand 1
fill ~58 ~-3 ~66 ~59 ~-3 ~66 sand 1
fill ~58 ~-3 ~70 ~58 ~-2 ~70 sand 1
fill ~58 ~-3 ~71 ~58 ~-3 ~65 sand 1
fill ~58 ~-3 ~72 ~75 ~-3 ~72 sand 0
fill ~58 ~-3 ~99 ~61 ~-3 ~99 sand 0
fill ~59 ~-3 ~2 ~59 ~-3 ~3 stone 5
fill ~59 ~-3 ~4 ~59 ~-3 ~4 stone 6
fill ~59 ~-3 ~12 ~61 ~-3 ~12 stone 5
fill ~59 ~-3 ~25 ~65 ~-3 ~25 stone 6
setblock ~59 ~-3 ~26 stone 0
fill ~59 ~-3 ~43 ~60 ~-3 ~43 sand 1
fill ~59 ~-3 ~44 ~59 ~-3 ~44 sand 0
fill ~59 ~-3 ~45 ~60 ~-3 ~45 sand 0
fill ~59 ~-3 ~46 ~74 ~-3 ~46 sand 0
fill ~59 ~-3 ~49 ~75 ~-3 ~49 sand 0
setblock ~59 ~-3 ~50 sand 1
fill ~59 ~-3 ~52 ~72 ~-3 ~52 sand 0
fill ~59 ~-3 ~57 ~73 ~-3 ~57 sand 0
fill ~59 ~-3 ~58 ~74 ~-3 ~58 sand 0
fill ~59 ~-3 ~59 ~75 ~-3 ~59 sand 0
fill ~59 ~-3 ~67 ~75 ~-3 ~67 sand 0
fill ~59 ~-3 ~70 ~75 ~-3 ~70 sand 0
fill ~59 ~-3 ~71 ~75 ~-3 ~71 sand 0
fill ~59 ~-3 ~100 ~59 ~-3 ~100 sand 0
fill ~60 ~-3 ~2 ~65 ~-3 ~2 stone 6
fill ~60 ~-3 ~3 ~65 ~-3 ~3 stone 6
fill ~60 ~-3 ~4 ~60 ~1 ~4 stone 5
fill ~60 ~-3 ~21 ~65 ~-3 ~21 stone 6
fill ~60 ~-3 ~26 ~66 ~-3 ~26 stone 6
fill ~60 ~-3 ~27 ~73 ~-3 ~27 stone 6
fill ~60 ~-3 ~28 ~65 ~-3 ~28 stone 6
fill ~60 ~-3 ~29 ~62 ~-3 ~29 stone 6
fill ~60 ~-3 ~41 ~72 ~-3 ~41 sand 0
fill ~60 ~-3 ~42 ~60 ~-3 ~42 sand 1
setblock ~60 ~-3 ~44 sand 1
fill ~60 ~-3 ~50 ~75 ~-3 ~50 sand 0
fill ~60 ~-3 ~51 ~73 ~-3 ~51 sand 0
fill ~60 ~-3 ~53 ~74 ~-3 ~53 sand 0
fill ~60 ~-3 ~54 ~72 ~-3 ~54 sand 0
fill ~60 ~-3 ~55 ~72 ~-3 ~55 sand 0
fill ~60 ~-3 ~56 ~72 ~-3 ~56 sand 0
fill ~60 ~-3 ~65 ~75 ~-3 ~65 sand 0
fill ~60 ~-3 ~66 ~75 ~-3 ~66 sand 0
fill ~60 ~-3 ~68 ~75 ~-3 ~68 sand 0
fill ~60 ~-3 ~69 ~75 ~-3 ~69 sand 0
fill ~61 ~-3 ~4 ~65 ~-3 ~4 stone 6
fill ~61 ~-3 ~6 ~65 ~-3 ~6 stone 6
fill ~61 ~-3 ~7 ~65 ~-3 ~7 stone 6
fill ~61 ~-3 ~9 ~61 ~-3 ~10 stone 6
fill ~61 ~-3 ~40 ~63 ~-3 ~40 stone 0
fill ~61 ~-3 ~42 ~71 ~-3 ~42 sand 0
fill ~61 ~-3 ~43 ~71 ~-3 ~43 sand 0
fill ~61 ~-3 ~44 ~72 ~-3 ~44 sand 0
setblock ~61 ~-3 ~45 sand 1
fill ~62 ~-3 ~9 ~62 ~-2 ~9 stone 5
fill ~62 ~-3 ~10 ~62 ~-3 ~8 stone 5
fill ~62 ~-3 ~12 ~62 ~-3 ~12 stone 6
fill ~62 ~-3 ~45 ~74 ~-3 ~45 sand 0
fill ~63 ~-3 ~5 ~65 ~-3 ~5 stone 6
fill ~63 ~-3 ~8 ~63 ~-1 ~8 stone 6
fill ~63 ~-3 ~9 ~65 ~-3 ~9 stone 6
fill ~63 ~-3 ~10 ~64 ~-3 ~10 stone 6
fill ~63 ~-3 ~29 ~71 ~-3 ~29 stone 0
setblock ~64 ~-3 ~8 stone 0
setblock ~64 ~-3 ~11 stone 6
fill ~64 ~-3 ~20 ~64 ~-3 ~20 stone 6
fill ~64 ~-3 ~40 ~69 ~-3 ~40 sand 0
fill ~65 ~-3 ~8 ~65 ~0 ~8 stone 6
fill ~65 ~-3 ~10 ~66 ~-3 ~10 stone 0
setblock ~65 ~-3 ~20 stone 5
fill ~66 ~-3 ~1 ~75 ~-3 ~1 stone 0
fill ~66 ~-3 ~2 ~75 ~-3 ~2 stone 0
fill ~66 ~-3 ~3 ~75 ~-3 ~3 stone 0
fill ~66 ~-3 ~4 ~74 ~-3 ~4 stone 0
fill ~66 ~-3 ~5 ~74 ~-3 ~5 stone 0
fill ~66 ~-3 ~6 ~73 ~-3 ~6 stone 0
fill ~66 ~-3 ~7 ~72 ~-3 ~7 stone 0
fill ~66 ~-3 ~8 ~70 ~-3 ~8 stone 0
fill ~66 ~-3 ~9 ~68 ~-3 ~9 stone 0
fill ~66 ~-3 ~20 ~67 ~-3 ~20 stone 6
fill ~66 ~-3 ~21 ~66 ~-3 ~23 stone 5
fill ~66 ~-3 ~25 ~67 ~-3 ~25 stone 5
fill ~66 ~-3 ~28 ~66 ~1 ~28 stone 0
fill ~67 ~-3 ~0 ~75 ~-3 ~0 stone 0
fill ~67 ~-3 ~21 ~67 ~-3 ~21 stone 6
fill ~67 ~-3 ~22 ~67 ~-2 ~22 stone 5
fill ~67 ~-3 ~23 ~68 ~-3 ~23 stone 5
fill ~67 ~-3 ~24 ~68 ~-3 ~24 stone 5
setblock ~67 ~-3 ~26 stone 5
fill ~67 ~-3 ~28 ~74 ~-3 ~28 stone 6
fill ~68 ~-3 ~20 ~71 ~-3 ~20 stone 5
fill ~68 ~-3 ~21 ~73 ~-3 ~21 stone 5
fill ~68 ~-3 ~22 ~69 ~-3 ~22 stone 6
fill ~68 ~-3 ~25 ~68 ~-3 ~25 stone 6
fill ~68 ~-3 ~26 ~69 ~-3 ~26 stone 6
fill ~68 ~-3 ~39 ~74 ~-3 ~39 sand 1
fill ~68 ~-3 ~107 ~68 ~9 ~107 planks 0
fill ~68 ~-3 ~108 ~69 ~-3 ~108 planks 2
fill ~69 ~-3 ~23 ~69 ~-3 ~23 stone 6
fill ~69 ~-3 ~24 ~70 ~-3 ~24 stone 6
fill ~69 ~-3 ~25 ~69 ~0 ~25 stone 5
fill ~69 ~-3 ~107 ~70 ~-3 ~107 planks 2
fill ~69 ~-3 ~109 ~69 ~1 ~109 planks 0
fill ~70 ~-3 ~22 ~74 ~-3 ~22 stone 5
fill ~70 ~-3 ~23 ~75 ~-3 ~23 stone 5
fill ~70 ~-3 ~25 ~70 ~-3 ~25 stone 6
fill ~70 ~-3 ~26 ~71 ~-3 ~26 stone 5
fill ~70 ~-3 ~38 ~74 ~-3 ~38 sand 1
fill ~70 ~-3 ~40 ~75 ~-3 ~40 sand 1
fill ~70 ~-3 ~108 ~70 ~4 ~108 planks 0
fill ~71 ~-3 ~24 ~73 ~-3 ~24 stone 5
fill ~71 ~-3 ~25 ~72 ~-3 ~25 stone 5
fill ~71 ~-3 ~37 ~75 ~-3 ~37 sand 1
fill ~72 ~-3 ~26 ~72 ~-3 ~26 stone 6
setblock ~72 ~-3 ~29 stone 6
fill ~72 ~-3 ~35 ~73 ~-3 ~35 sand 1
fill ~72 ~-3 ~36 ~74 ~-3 ~36 sand 1
fill ~72 ~-3 ~42 ~74 ~-3 ~42 sand 1
fill ~72 ~-3 ~43 ~73 ~-3 ~43 sand 1
fill ~73 ~-3 ~25 ~75 ~-3 ~25 stone 6
fill ~73 ~-3 ~26 ~73 ~-1 ~26 stone 5
fill ~73 ~-3 ~29 ~73 ~-2 ~29 stone 0
fill ~73 ~-3 ~33 ~75 ~-3 ~33 hardened_clay 0
fill ~73 ~-3 ~34 ~75 ~-3 ~34 hardened_clay 0
fill ~73 ~-3 ~41 ~73 ~-2 ~41 sand 1
fill ~73 ~-3 ~44 ~74 ~-3 ~44 sand 1
setblock ~73 ~-3 ~52 sand 1
fill ~73 ~-3 ~54 ~74 ~-3 ~54 sand 1
fill ~73 ~-3 ~55 ~74 ~-3 ~55 sand 1
fill ~73 ~-3 ~56 ~73 ~-3 ~56 sand 1
setblock ~74 ~-3 ~24 stone 6
fill ~74 ~-3 ~26 ~75 ~-3 ~26 stone 6
fill ~74 ~-3 ~27 ~74 ~-2 ~27 stone 5
fill ~74 ~-3 ~30 ~75 ~-3 ~30 hardened_clay 0
fill ~74 ~-3 ~31 ~75 ~-3 ~31 hardened_clay 0
fill ~74 ~-3 ~32 ~75 ~-3 ~32 hardened_clay 0
fill ~74 ~-3 ~35 ~75 ~-3 ~35 hardened_clay 0
setblock ~74 ~-3 ~41 hardened_clay 0
setblock ~74 ~-3 ~43 sand 0
setblock ~74 ~-3 ~51 sand 1
fill ~74 ~-3 ~52 ~74 ~-3 ~52 sand 0
fill ~74 ~-3 ~57 ~74 ~-3 ~57 sand 1
fill ~75 ~-3 ~24 ~75 ~-3 ~24 stone 5
fill ~75 ~-3 ~36 ~75 ~-3 ~36 hardened_clay 0
fill ~75 ~-3 ~38 ~75 ~-3 ~38 hardened_clay 0
fill ~75 ~-3 ~39 ~75 ~-2 ~39 hardened_clay 0
setblock ~75 ~-3 ~41 sand 1
fill ~75 ~-3 ~42 ~75 ~-2 ~42 hardened_clay 0
fill ~75 ~-3 ~43 ~75 ~-2 ~43 hardened_clay 0
fill ~75 ~-3 ~44 ~75 ~-3 ~44 hardened_clay 0
fill ~75 ~-3 ~45 ~75 ~-3 ~45 sand 1
setblock ~75 ~-3 ~46 end_stone 0
fill ~75 ~-3 ~47 ~75 ~2 ~47 sandstone 0
setblock ~75 ~-3 ~48 end_stone 0
fill ~75 ~-3 ~51 ~75 ~-2 ~51 sand 0
fill ~75 ~-3 ~52 ~75 ~-3 ~52 sand 1
fill ~75 ~-3 ~53 ~75 ~-3 ~53 sand 1
fill ~75 ~-3 ~58 ~75 ~-3 ~58 sand 1
fill ~1 ~-2 ~31 ~4 ~-2 ~31 planks 2
fill ~1 ~-2 ~33 ~4 ~-2 ~33 planks 2
fill ~1 ~-2 ~34 ~2 ~-2 ~34 planks 2
fill ~1 ~-2 ~35 ~1 ~-3 ~35 planks 2
fill ~1 ~-2 ~36 ~3 ~-2 ~36 planks 0
fill ~1 ~-2 ~37 ~1 ~-2 ~38 planks 0
fill ~1 ~-2 ~50 ~1 ~-1 ~50 planks 0
fill ~1 ~-2 ~51 ~3 ~-2 ~51 planks 2
fill ~1 ~-2 ~52 ~5 ~-2 ~52 planks 2
fill ~1 ~-2 ~53 ~1 ~-2 ~53 planks 2
fill ~1 ~-2 ~54 ~5 ~-2 ~54 planks 2
fill ~1 ~-2 ~69 ~3 ~-2 ~69 sand 0
fill ~1 ~-2 ~70 ~10 ~-2 ~70 sand 0
fill ~1 ~-2 ~71 ~7 ~-2 ~71 sand 0
fill ~1 ~-2 ~72 ~10 ~-2 ~72 sand 0
fill ~1 ~-2 ~73 ~10 ~-2 ~73 sand 0
fill ~1 ~-2 ~74 ~10 ~-2 ~74 sand 0
fill ~1 ~-2 ~75 ~10 ~-2 ~75 sand 0
fill ~1 ~-2 ~76 ~11 ~-2 ~76 sand 0
fill ~1 ~-2 ~77 ~12 ~-2 ~77 sand 0
fill ~1 ~-2 ~78 ~13 ~-2 ~78 sand 0
fill ~1 ~-2 ~79 ~13 ~-2 ~79 sand 0
fill ~1 ~-2 ~80 ~13 ~-2 ~80 sand 0
fill ~1 ~-2 ~81 ~12 ~-2 ~81 sand 0
fill ~1 ~-2 ~82 ~11 ~-2 ~82 sand 0
fill ~1 ~-2 ~83 ~11 ~-2 ~83 sand 0
fill ~1 ~-2 ~84 ~11 ~-2 ~84 sand 0
fill ~1 ~-2 ~85 ~12 ~-2 ~85 sand 0
fill ~1 ~-2 ~86 ~13 ~-2 ~86 sand 0
fill ~1 ~-2 ~87 ~16 ~-2 ~87 sand 0
fill ~1 ~-2 ~88 ~18 ~-2 ~88 sand 0
fill ~1 ~-2 ~89 ~21 ~-2 ~89 sand 0
fill ~1 ~-2 ~90 ~22 ~-2 ~90 sand 0
fill ~2 ~-2 ~29 ~3 ~-2 ~29 planks 2
fill ~2 ~-2 ~32 ~3 ~-2 ~32 planks 2
setblock ~2 ~-2 ~35 planks 0
fill ~2 ~-2 ~37 ~9 ~-2 ~37 planks 2
fill ~2 ~-2 ~38 ~2 ~3 ~38 planks 0
fill ~2 ~-2 ~39 ~2 ~2 ~39 planks 0
fill ~2 ~-2 ~47 ~3 ~-2 ~47 planks 0
fill ~2 ~-2 ~48 ~2 ~-2 ~49 planks 0
fill ~2 ~-2 ~50 ~2 ~-3 ~50 planks 2
setblock ~2 ~-2 ~68 sand 0
fill ~2 ~-2 ~91 ~23 ~-2 ~91 sand 0
fill ~2 ~-2 ~92 ~24 ~-2 ~92 sand 0
fill ~3 ~-2 ~30 ~3 ~-1 ~30 planks 2
setblock ~3 ~-2 ~34 sandstone 0
fill ~3 ~-2 ~35 ~3 ~0 ~35 planks 2
fill ~3 ~-2 ~38 ~9 ~-2 ~38 planks 2
fill ~3 ~-2 ~39 ~10 ~-2 ~39 planks 2
fill ~3 ~-2 ~46 ~3 ~2 ~46 planks 0
fill ~3 ~-2 ~48 ~10 ~-2 ~48 planks 2
fill ~3 ~-2 ~49 ~4 ~-2 ~49 planks 0
fill ~3 ~-2 ~50 ~3 ~-2 ~49 planks 0
fill ~3 ~-2 ~53 ~4 ~-2 ~53 planks 2
fill ~3 ~-2 ~56 ~4 ~-2 ~56 planks 2
fill ~3 ~-2 ~67 ~3 ~-2 ~68 sand 1
fill ~4 ~-2 ~27 ~7 ~-2 ~27 end_stone 0
fill ~4 ~-2 ~29 ~6 ~-2 ~29 end_stone 0
fill ~4 ~-2 ~30 ~7 ~-2 ~30 sandstone 0
fill ~4 ~-2 ~32 ~9 ~-2 ~32 sandstone 0
fill ~4 ~-2 ~35 ~13 ~-2 ~35 sandstone 0
fill ~4 ~-2 ~36 ~7 ~-2 ~36 planks 2
fill ~4 ~-2 ~46 ~11 ~-2 ~46 planks 2
fill ~4 ~-2 ~47 ~10 ~-2 ~47 planks 2
fill ~4 ~-2 ~50 ~4 ~0 ~50 planks 2
setblock ~4 ~-2 ~51 sandstone 0
fill ~4 ~-2 ~55 ~4 ~-1 ~55 planks 2
setblock ~4 ~-2 ~66 sand 0
fill ~4 ~-2 ~68 ~8 ~-2 ~68 sand 1
fill ~4 ~-2 ~69 ~4 ~-1 ~69 sand 1
fill ~4 ~-2 ~93 ~25 ~-2 ~93 sand 0
setblock ~5 ~-2 ~16 planks 2
fill ~5 ~-2 ~19 ~5 ~1 ~19 planks 0
fill ~5 ~-2 ~26 ~5 ~-1 ~26 end_stone 0
fill ~5 ~-2 ~31 ~9 ~-2 ~31 sandstone 0
fill ~5 ~-2 ~33 ~14 ~-2 ~33 sandstone 0
fill ~5 ~-2 ~34 ~13 ~-2 ~34 sandstone 0
fill ~5 ~-2 ~40 ~7 ~-2 ~40 planks 2
fill ~5 ~-2 ~49 ~8 ~-2 ~49 planks 2
fill ~5 ~-2 ~50 ~14 ~-2 ~50 sandstone 0
fill ~5 ~-2 ~53 ~10 ~-2 ~53 sandstone 0
fill ~5 ~-2 ~55 ~8 ~-2 ~55 sandstone 0
fill ~5 ~-2 ~56 ~7 ~-2 ~56 end_stone 0
fill ~5 ~-2 ~58 ~8 ~-2 ~58 end_stone 0
fill ~5 ~-2 ~66 ~5 ~-2 ~68 sand 1
fill ~5 ~-2 ~69 ~6 ~-2 ~69 sand 0
fill ~5 ~-2 ~94 ~24 ~-2 ~94 sand 0
setblock ~6 ~-2 ~28 end_stone 0
fill ~6 ~-2 ~45 ~8 ~-2 ~45 planks 2
fill ~6 ~-2 ~51 ~14 ~-2 ~51 sandstone 0
fill ~6 ~-2 ~52 ~15 ~-2 ~52 sandstone 0
fill ~6 ~-2 ~54 ~10 ~-2 ~54 sandstone 0
fill ~6 ~-2 ~59 ~6 ~-1 ~59 end_stone 0
setblock ~6 ~-2 ~65 sand 1
setblock ~6 ~-2 ~66 sand 0
fill ~6 ~-2 ~67 ~7 ~-2 ~67 sand 1
fill ~7 ~-2 ~19 ~8 ~-2 ~19 planks 0
fill ~7 ~-2 ~26 ~8 ~-2 ~26 end_stone 0
fill ~7 ~-2 ~28 ~7 ~-2 ~29 brick_block 0
setblock ~7 ~-2 ~57 end_stone 0
fill ~7 ~-2 ~66 ~8 ~-2 ~66 sand 1
setblock ~7 ~-2 ~69 sand 1
fill ~7 ~-2 ~95 ~24 ~-2 ~95 sand 0
fill ~8 ~-2 ~27 ~9 ~-2 ~27 brick_block 0
fill ~8 ~-2 ~28 ~9 ~-2 ~28 end_stone 0
fill ~8 ~-2 ~29 ~12 ~-2 ~29 brick_block 0
fill ~8 ~-2 ~30 ~8 ~0 ~30 end_stone 0
fill ~8 ~-2 ~36 ~13 ~-2 ~36 sandstone 0
fill ~8 ~-2 ~56 ~13 ~-2 ~56 brick_block 0
fill ~8 ~-2 ~57 ~8 ~-2 ~56 brick_block 0
fill ~8 ~-2 ~59 ~9 ~-2 ~59 end_stone 0
fill ~8 ~-2 ~67 ~9 ~-2 ~67 sand 0
fill ~8 ~-2 ~71 ~8 ~-3 ~71 sand 1
fill ~8 ~-2 ~96 ~22 ~-2 ~96 sand 0
setblock ~9 ~-2 ~30 quartz_block 0
fill ~9 ~-2 ~40 ~9 ~3 ~40 planks 2
fill ~9 ~-2 ~49 ~14 ~-2 ~49 sandstone 0
fill ~9 ~-2 ~55 ~9 ~0 ~55 end_stone 0
fill ~9 ~-2 ~57 ~10 ~-2 ~57 end_stone 0
fill ~9 ~-2 ~58 ~10 ~-2 ~58 brick_block 0
setblock ~9 ~-2 ~68 sand 0
fill ~9 ~-2 ~69 ~13 ~-2 ~69 sand 1
fill ~9 ~-2 ~71 ~9 ~-1 ~71 sand 0
fill ~9 ~-2 ~97 ~22 ~-2 ~97 sand 0
setblock ~10 ~-2 ~28 brick_block 0
fill ~10 ~-2 ~30 ~10 ~2 ~30 end_stone 0
fill ~10 ~-2 ~31 ~10 ~-1 ~31 end_stone 0
fill ~10 ~-2 ~32 ~11 ~-2 ~32 end_stone 0
fill ~10 ~-2 ~37 ~12 ~-2 ~37 sandstone 0
fill ~10 ~-2 ~38 ~12 ~-2 ~38 sandstone 0
fill ~10 ~-2 ~45 ~10 ~3 ~45 planks 2
setblock ~10 ~-2 ~55 quartz_block 0
fill ~10 ~-2 ~67 ~10 ~-2 ~69 sand 1
setblock ~11 ~-2 ~30 quartz_block 0
fill ~11 ~-2 ~31 ~11 ~0 ~31 sandstone 0
fill ~11 ~-2 ~47 ~13 ~-2 ~47 sandstone 0
fill ~11 ~-2 ~48 ~13 ~-2 ~48 sandstone 0
fill ~11 ~-2 ~53 ~12 ~-2 ~53 end_stone 0
fill ~11 ~-2 ~54 ~11 ~-1 ~54 end_stone 0
fill ~11 ~-2 ~55 ~11 ~2 ~55 end_stone 0
setblock ~11 ~-2 ~57 brick_block 0
fill ~11 ~-2 ~68 ~12 ~-2 ~68 sand 1
fill ~11 ~-2 ~70 ~15 ~-2 ~70 sand 1
setblock ~11 ~-2 ~71 sand 0
fill ~11 ~-2 ~72 ~14 ~-2 ~72 sand 1
fill ~11 ~-2 ~73 ~15 ~-2 ~73 sand 1
fill ~11 ~-2 ~74 ~15 ~-2 ~74 sand 1
fill ~11 ~-2 ~75 ~15 ~-2 ~75 sand 1
fill ~11 ~-2 ~98 ~21 ~-2 ~98 sand 0
fill ~12 ~-2 ~31 ~13 ~-2 ~31 end_stone 0
fill ~12 ~-2 ~32 ~14 ~-2 ~32 sandstone 0
fill ~12 ~-2 ~54 ~12 ~0 ~54 sandstone 0
setblock ~12 ~-2 ~55 quartz_block 0
fill ~12 ~-2 ~71 ~16 ~-2 ~71 sand 1
fill ~12 ~-2 ~76 ~14 ~-2 ~76 sand 1
fill ~12 ~-2 ~99 ~20 ~-2 ~99 sand 0
fill ~13 ~-2 ~0 ~13 ~7 ~0 planks 0
fill ~13 ~-2 ~53 ~13 ~-1 ~53 sandstone 0
fill ~13 ~-2 ~54 ~14 ~-2 ~54 end_stone 0
fill ~13 ~-2 ~55 ~13 ~0 ~55 end_stone 0
fill ~13 ~-2 ~77 ~14 ~-2 ~77 sand 1
fill ~14 ~-2 ~6 ~14 ~-1 ~6 planks 0
setblock ~14 ~-2 ~69 hardened_clay 0
fill ~14 ~-2 ~78 ~14 ~-3 ~78 sand 1
fill ~14 ~-2 ~100 ~19 ~-2 ~100 sand 0
setblock ~15 ~-2 ~8 planks 2
fill ~15 ~-2 ~53 ~15 ~-1 ~53 sandstone 0
setblock ~15 ~-2 ~72 hardened_clay 0
fill ~16 ~-2 ~101 ~18 ~-2 ~101 sand 0
setblock ~17 ~-2 ~10 planks 0
fill ~17 ~-2 ~43 ~36 ~-2 ~43 sand 0
fill ~18 ~-2 ~41 ~34 ~-2 ~41 sand 0
fill ~18 ~-2 ~42 ~35 ~-2 ~42 sand 0
fill ~18 ~-2 ~44 ~37 ~-2 ~44 sand 0
fill ~18 ~-2 ~45 ~37 ~-2 ~45 sand 0
fill ~19 ~-2 ~39 ~31 ~-2 ~39 sand 0
fill ~19 ~-2 ~40 ~32 ~-2 ~40 sand 0
fill ~19 ~-2 ~46 ~38 ~-2 ~46 sand 0
fill ~19 ~-2 ~47 ~38 ~-2 ~47 sand 0
fill ~20 ~-2 ~38 ~29 ~-2 ~38 sand 0
fill ~20 ~-2 ~48 ~39 ~-2 ~48 sand 0
fill ~20 ~-2 ~49 ~39 ~-2 ~49 sand 0
fill ~21 ~-2 ~37 ~27 ~-2 ~37 sand 0
fill ~21 ~-2 ~50 ~40 ~-2 ~50 sand 0
fill ~21 ~-2 ~51 ~22 ~-2 ~51 sand 1
fill ~22 ~-2 ~36 ~26 ~-2 ~36 sand 0
setblock ~22 ~-2 ~52 sand 1
fill ~23 ~-2 ~51 ~40 ~-2 ~51 sand 0
fill ~23 ~-2 ~52 ~40 ~-2 ~52 sand 0
setblock ~23 ~-2 ~54 sand 0
setblock ~24 ~-2 ~35 sand 0
fill ~24 ~-2 ~54 ~25 ~-2 ~54 sand 1
fill ~24 ~-2 ~55 ~25 ~-2 ~55 sand 1
fill ~24 ~-2 ~57 ~25 ~-2 ~57 sand 1
fill ~24 ~-2 ~58 ~25 ~-2 ~58 sand 1
fill ~24 ~-2 ~59 ~27 ~-2 ~59 sand 1
fill ~24 ~-2 ~60 ~25 ~-2 ~60 sand 1
fill ~24 ~-2 ~61 ~26 ~-2 ~61 sand 1
fill ~24 ~-2 ~62 ~26 ~-2 ~62 sand 1
fill ~24 ~-2 ~63 ~27 ~-2 ~63 sand 1
fill ~24 ~-2 ~64 ~28 ~-2 ~64 sand 1
fill ~24 ~-2 ~65 ~29 ~-2 ~65 sand 1
setblock ~25 ~-2 ~53 sand 1
fill ~25 ~-2 ~56 ~25 ~-1 ~56 sand 1
fill ~25 ~-2 ~66 ~29 ~-2 ~66 sand 1
fill ~26 ~-2 ~53 ~40 ~-2 ~53 sand 0
fill ~26 ~-2 ~54 ~39 ~-2 ~54 sand 0
fill ~26 ~-2 ~55 ~39 ~-2 ~55 sand 0
fill ~26 ~-2 ~57 ~39 ~-2 ~57 sand 0
fill ~26 ~-2 ~58 ~38 ~-2 ~58 sand 0
setblock ~26 ~-2 ~60 sand 0
fill ~27 ~-2 ~56 ~39 ~-2 ~56 sand 0
setblock ~27 ~-2 ~60 sand 1
fill ~27 ~-2 ~61 ~37 ~-2 ~61 sand 0
fill ~27 ~-2 ~62 ~36 ~-2 ~62 sand 0
fill ~28 ~-2 ~59 ~38 ~-2 ~59 sand 0
fill ~28 ~-2 ~60 ~37 ~-2 ~60 sand 0
fill ~28 ~-2 ~63 ~31 ~-2 ~63 sand 0
fill ~29 ~-2 ~21 ~29 ~-1 ~21 web 0
fill ~29 ~-2 ~22 ~29 ~-1 ~22 web 0
fill ~29 ~-2 ~23 ~29 ~-1 ~23 web 0
fill ~29 ~-2 ~24 ~29 ~-1 ~24 web 0
fill ~29 ~-2 ~25 ~30 ~-2 ~25 web 0
fill ~29 ~-2 ~26 ~30 ~-2 ~26 web 0
fill ~29 ~-2 ~27 ~31 ~-2 ~27 web 0
fill ~29 ~-2 ~64 ~33 ~-2 ~64 sand 0
fill ~30 ~-2 ~28 ~31 ~-2 ~28 web 0
fill ~30 ~-2 ~29 ~32 ~-2 ~29 web 0
fill ~30 ~-2 ~65 ~31 ~-2 ~65 sand 0
fill ~30 ~-2 ~66 ~30 ~-2 ~39 sand 0
fill ~31 ~-2 ~30 ~32 ~-2 ~30 web 0
fill ~31 ~-2 ~31 ~32 ~-2 ~31 web 0
fill ~32 ~-2 ~32 ~32 ~0 ~32 web 0
setblock ~32 ~-2 ~63 sand 1
fill ~32 ~-2 ~65 ~32 ~-3 ~65 sand 1
fill ~32 ~-2 ~66 ~32 ~-2 ~65 sand 1
fill ~33 ~-2 ~63 ~34 ~-2 ~63 sand 0
setblock ~33 ~-2 ~65 sand 0
fill ~34 ~-2 ~64 ~34 ~-3 ~64 sand 1
setblock ~35 ~-2 ~63 sand 1
fill ~40 ~-2 ~54 ~41 ~-2 ~54 sand 1
fill ~40 ~-2 ~55 ~40 ~-3 ~55 sand 1
fill ~40 ~-2 ~56 ~40 ~-3 ~56 sand 1
fill ~41 ~-2 ~52 ~41 ~-3 ~52 sand 1
fill ~41 ~-2 ~53 ~41 ~-2 ~52 sand 1
fill ~48 ~-2 ~77 ~49 ~-2 ~77 sand 1
fill ~48 ~-2 ~78 ~49 ~-2 ~78 sand 1
fill ~48 ~-2 ~79 ~52 ~-2 ~79 sand 1
fill ~49 ~-2 ~80 ~53 ~-2 ~80 sand 1
fill ~50 ~-2 ~76 ~51 ~-2 ~76 sand 1
fill ~50 ~-2 ~77 ~51 ~-2 ~77 sand 0
fill ~50 ~-2 ~78 ~50 ~-2 ~77 sand 0
fill ~50 ~-2 ~81 ~51 ~-2 ~81 sand 1
fill ~50 ~-2 ~82 ~55 ~-2 ~82 sand 0
fill ~50 ~-2 ~111 ~50 ~1 ~111 planks 2
fill ~51 ~-2 ~78 ~51 ~-3 ~78 sand 1
fill ~51 ~-2 ~113 ~52 ~-2 ~113 planks 0
fill ~52 ~-2 ~30 ~71 ~-2 ~30 stone 0
setblock ~52 ~-2 ~75 sand 1
fill ~52 ~-2 ~76 ~56 ~-2 ~76 sand 0
fill ~52 ~-2 ~77 ~54 ~-2 ~77 sand 1
setblock ~52 ~-2 ~78 sand 0
fill ~52 ~-2 ~81 ~56 ~-2 ~81 sand 0
fill ~52 ~-2 ~116 ~52 ~1 ~116 planks 0
fill ~53 ~-2 ~28 ~57 ~-2 ~28 stone 0
fill ~53 ~-2 ~29 ~68 ~-2 ~29 stone 0
fill ~53 ~-2 ~31 ~73 ~-2 ~31 stone 0
fill ~53 ~-2 ~32 ~73 ~-2 ~32 stone 0
fill ~53 ~-2 ~33 ~72 ~-2 ~33 stone 0
fill ~53 ~-2 ~74 ~75 ~-2 ~74 sand 0
fill ~53 ~-2 ~75 ~58 ~-2 ~75 sand 0
fill ~53 ~-2 ~78 ~54 ~-2 ~78 sand 1
fill ~53 ~-2 ~79 ~54 ~-2 ~79 sand 0
setblock ~54 ~-2 ~26 stone 6
fill ~54 ~-2 ~27 ~59 ~-2 ~27 stone 0
fill ~54 ~-2 ~34 ~72 ~-2 ~34 stone 0
setblock ~54 ~-2 ~73 sand 0
fill ~54 ~-2 ~80 ~55 ~-2 ~80 sand 0
fill ~55 ~-2 ~6 ~56 ~-2 ~6 stone 5
fill ~55 ~-2 ~7 ~60 ~-2 ~7 stone 5
fill ~55 ~-2 ~25 ~56 ~-2 ~25 stone 0
fill ~55 ~-2 ~26 ~57 ~-2 ~26 stone 0
fill ~55 ~-2 ~35 ~71 ~-2 ~35 stone 0
fill ~55 ~-2 ~36 ~71 ~-2 ~36 stone 0
fill ~55 ~-2 ~72 ~56 ~-2 ~72 sand 0
setblock ~55 ~-2 ~73 sand 1
fill ~55 ~-2 ~77 ~55 ~-2 ~78 sand 0
fill ~56 ~-2 ~0 ~65 ~-2 ~0 stone 6
fill ~56 ~-2 ~1 ~65 ~-2 ~1 stone 6
fill ~56 ~-2 ~2 ~57 ~-2 ~2 stone 5
fill ~56 ~-2 ~3 ~56 ~-2 ~9 stone 5
fill ~56 ~-2 ~37 ~70 ~-2 ~37 stone 0
fill ~56 ~-2 ~38 ~70 ~-2 ~38 stone 0
fill ~56 ~-2 ~64 ~56 ~-2 ~70 sand 1
fill ~56 ~-2 ~71 ~75 ~-2 ~71 sand 0
fill ~56 ~-2 ~73 ~75 ~-2 ~73 sand 0
fill ~57 ~-2 ~3 ~57 ~-1 ~3 stone 6
fill ~57 ~-2 ~4 ~61 ~-2 ~4 stone 5
fill ~57 ~-2 ~5 ~59 ~-2 ~5 stone 5
setblock ~57 ~-2 ~6 stone 6
fill ~57 ~-2 ~8 ~61 ~-2 ~8 stone 5
fill ~57 ~-2 ~9 ~62 ~-2 ~9 stone 5
fill ~57 ~-2 ~10 ~61 ~-2 ~10 stone 5
fill ~57 ~-2 ~24 ~57 ~-2 ~25 stone 6
fill ~57 ~-2 ~63 ~75 ~-2 ~63 sand 0
fill ~57 ~-2 ~64 ~75 ~-2 ~64 sand 0
fill ~57 ~-2 ~65 ~58 ~-2 ~65 sand 1
fill ~57 ~-2 ~67 ~57 ~-2 ~70 sand 1
fill ~58 ~-2 ~2 ~60 ~-2 ~2 stone 6
fill ~58 ~-2 ~6 ~58 ~-1 ~6 stone 5
setblock ~58 ~-2 ~11 stone 5
fill ~58 ~-2 ~23 ~65 ~-2 ~23 stone 6
fill ~58 ~-2 ~24 ~59 ~-2 ~24 stone 0
fill ~58 ~-2 ~25 ~60 ~-2 ~25 stone 0
setblock ~58 ~-2 ~28 stone 6
fill ~58 ~-2 ~39 ~69 ~-2 ~39 stone 0
fill ~58 ~-2 ~60 ~75 ~-2 ~60 sand 0
fill ~58 ~-2 ~61 ~75 ~-2 ~61 sand 0
fill ~58 ~-2 ~62 ~75 ~-2 ~62 sand 0
fill ~58 ~-2 ~66 ~58 ~0 ~66 sand 0
fill ~58 ~-2 ~67 ~58 ~-2 ~66 sand 0
fill ~58 ~-2 ~68 ~59 ~-2 ~68 sand 1
fill ~58 ~-2 ~69 ~58 ~-1 ~69 sand 1
fill ~58 ~-2 ~72 ~75 ~-2 ~72 sand 0
setblock ~59 ~-2 ~3 stone 6
setblock ~59 ~-2 ~6 stone 6
fill ~59 ~-2 ~11 ~60 ~-2 ~11 stone 6
setblock ~59 ~-2 ~26 stone 6
fill ~59 ~-2 ~28 ~62 ~-2 ~28 stone 0
setblock ~59 ~-2 ~47 sand 0
setblock ~59 ~-2 ~48 sand 1
fill ~59 ~-2 ~49 ~60 ~-2 ~49 sand 0
fill ~59 ~-2 ~50 ~74 ~-2 ~50 sand 0
fill ~59 ~-2 ~59 ~72 ~-2 ~59 sand 0
fill ~59 ~-2 ~65 ~75 ~-2 ~65 sand 0
fill ~59 ~-2 ~66 ~59 ~-2 ~68 sand 1
fill ~59 ~-2 ~69 ~75 ~-2 ~69 sand 0
fill ~59 ~-2 ~70 ~75 ~-2 ~70 sand 0
fill ~60 ~-2 ~3 ~62 ~-2 ~3 stone 5
fill ~60 ~-2 ~5 ~65 ~-2 ~5 stone 6
fill ~60 ~-2 ~6 ~60 ~-1 ~6 stone 5
setblock ~60 ~-2 ~12 stone 6
fill ~60 ~-2 ~22 ~64 ~-2 ~22 stone 6
fill ~60 ~-2 ~24 ~66 ~-2 ~24 stone 6
setblock ~60 ~-2 ~26 stone 0
fill ~60 ~-2 ~27 ~67 ~-2 ~27 stone 6
fill ~60 ~-2 ~45 ~74 ~-2 ~45 sand 0
fill ~60 ~-2 ~46 ~74 ~-2 ~46 sand 0
fill ~60 ~-2 ~47 ~61 ~-2 ~47 sand 1
fill ~60 ~-2 ~48 ~74 ~-2 ~48 sand 0
fill ~60 ~-2 ~51 ~75 ~-2 ~51 sand 0
fill ~60 ~-2 ~58 ~71 ~-2 ~58 sand 0
fill ~60 ~-2 ~66 ~75 ~-2 ~66 sand 0
fill ~60 ~-2 ~67 ~75 ~-2 ~67 sand 0
fill ~60 ~-2 ~68 ~75 ~-2 ~68 sand 0
setblock ~61 ~-2 ~2 stone 5
fill ~61 ~-2 ~6 ~65 ~-2 ~6 stone 6
fill ~61 ~-2 ~7 ~61 ~-3 ~7 stone 6
fill ~61 ~-2 ~11 ~63 ~-2 ~11 stone 5
fill ~61 ~-2 ~12 ~61 ~-2 ~8 stone 5
fill ~61 ~-2 ~25 ~65 ~-2 ~25 stone 6
fill ~61 ~-2 ~26 ~65 ~-2 ~26 stone 6
fill ~61 ~-2 ~40 ~65 ~-2 ~40 stone 0
fill ~61 ~-2 ~42 ~71 ~-2 ~42 sand 0
fill ~61 ~-2 ~43 ~72 ~-2 ~43 sand 0
fill ~61 ~-2 ~44 ~72 ~-2 ~44 sand 0
setblock ~61 ~-2 ~49 sand 1
fill ~61 ~-2 ~57 ~70 ~-2 ~57 sand 0
fill ~61 ~-2 ~91 ~61 ~2 ~91 planks 2
fill ~62 ~-2 ~2 ~65 ~-2 ~2 stone 6
fill ~62 ~-2 ~4 ~62 ~-1 ~4 stone 6
fill ~62 ~-2 ~7 ~62 ~1 ~7 stone 5
setblock ~62 ~-2 ~8 stone 6
fill ~62 ~-2 ~10 ~63 ~-2 ~10 stone 6
fill ~62 ~-2 ~41 ~70 ~-2 ~41 sand 0
fill ~62 ~-2 ~47 ~74 ~-2 ~47 sand 0
fill ~62 ~-2 ~49 ~75 ~-2 ~49 sand 0
fill ~62 ~-2 ~52 ~73 ~-2 ~52 sand 0
fill ~62 ~-2 ~55 ~70 ~-2 ~55 sand 0
fill ~62 ~-2 ~56 ~69 ~-2 ~56 sand 0
fill ~62 ~-2 ~89 ~62 ~10 ~89 planks 3
fill ~62 ~-2 ~90 ~62 ~7 ~90 planks 0
fill ~62 ~-2 ~91 ~62 ~17 ~91 planks 0
fill ~63 ~-2 ~3 ~65 ~-2 ~3 stone 6
setblock ~63 ~-2 ~4 stone 5
fill ~63 ~-2 ~7 ~65 ~-2 ~7 stone 6
fill ~63 ~-2 ~9 ~65 ~-2 ~9 stone 6
fill ~63 ~-2 ~28 ~64 ~-2 ~28 stone 6
fill ~63 ~-2 ~53 ~72 ~-2 ~53 sand 0
fill ~63 ~-2 ~54 ~70 ~-2 ~54 sand 0
fill ~63 ~-2 ~75 ~75 ~-2 ~75 sand 0
fill ~63 ~-2 ~89 ~63 ~3 ~89 planks 2
fill ~63 ~-2 ~90 ~63 ~17 ~90 planks 3
fill ~63 ~-2 ~91 ~63 ~6 ~91 planks 2
fill ~64 ~-2 ~4 ~65 ~-2 ~4 stone 6
fill ~64 ~-2 ~8 ~64 ~2 ~8 stone 6
fill ~64 ~-2 ~10 ~64 ~0 ~10 stone 5
fill ~64 ~-2 ~76 ~75 ~-2 ~76 sand 0
fill ~64 ~-2 ~90 ~64 ~2 ~90 planks 0
fill ~65 ~-2 ~10 ~65 ~-3 ~10 stone 0
fill ~65 ~-2 ~22 ~72 ~-2 ~22 stone 5
fill ~65 ~-2 ~28 ~65 ~1 ~28 stone 0
fill ~65 ~-2 ~77 ~75 ~-2 ~77 sand 0
fill ~66 ~-2 ~0 ~75 ~-2 ~0 stone 0
fill ~66 ~-2 ~1 ~75 ~-2 ~1 stone 0
fill ~66 ~-2 ~2 ~75 ~-2 ~2 stone 0
fill ~66 ~-2 ~3 ~75 ~-2 ~3 stone 0
fill ~66 ~-2 ~4 ~75 ~-2 ~4 stone 0
fill ~66 ~-2 ~5 ~75 ~-2 ~5 stone 0
fill ~66 ~-2 ~6 ~74 ~-2 ~6 stone 0
fill ~66 ~-2 ~7 ~72 ~-2 ~7 stone 0
fill ~66 ~-2 ~8 ~70 ~-2 ~8 stone 0
fill ~66 ~-2 ~9 ~69 ~-2 ~9 stone 0
fill ~66 ~-2 ~23 ~66 ~-1 ~23 stone 5
fill ~66 ~-2 ~25 ~71 ~-2 ~25 stone 5
fill ~66 ~-2 ~26 ~66 ~0 ~26 stone 5
fill ~66 ~-2 ~40 ~69 ~-2 ~40 sand 0
fill ~66 ~-2 ~78 ~75 ~-2 ~78 sand 0
setblock ~67 ~-2 ~23 stone 6
fill ~67 ~-2 ~24 ~67 ~-3 ~24 stone 5
fill ~67 ~-2 ~26 ~70 ~-2 ~26 stone 6
fill ~67 ~-2 ~28 ~67 ~-1 ~28 stone 0
fill ~68 ~-2 ~23 ~69 ~-2 ~23 stone 5
setblock ~68 ~-2 ~24 stone 6
fill ~68 ~-2 ~27 ~68 ~-1 ~27 stone 5
fill ~68 ~-2 ~28 ~73 ~-2 ~28 stone 6
fill ~68 ~-2 ~108 ~69 ~-2 ~108 planks 2
fill ~69 ~-2 ~24 ~71 ~-2 ~24 stone 5
fill ~69 ~-2 ~27 ~73 ~-2 ~27 stone 6
setblock ~69 ~-2 ~29 stone 6
fill ~69 ~-2 ~79 ~75 ~-2 ~79 sand 0
fill ~69 ~-2 ~107 ~69 ~1 ~107 planks 2
fill ~70 ~-2 ~23 ~71 ~-2 ~23 stone 6
fill ~70 ~-2 ~29 ~73 ~-2 ~29 stone 0
fill ~70 ~-2 ~39 ~74 ~-2 ~39 sand 1
fill ~70 ~-2 ~40 ~74 ~-2 ~40 sand 1
fill ~71 ~-2 ~26 ~73 ~-2 ~26 stone 5
fill ~71 ~-2 ~41 ~71 ~-1 ~41 sand 1
fill ~72 ~-2 ~23 ~74 ~-2 ~23 stone 5
fill ~72 ~-2 ~24 ~72 ~-1 ~24 stone 6
fill ~72 ~-2 ~25 ~74 ~-2 ~25 stone 6
fill ~72 ~-2 ~30 ~72 ~-1 ~30 stone 6
fill ~72 ~-2 ~37 ~73 ~-2 ~37 sand 1
fill ~72 ~-2 ~38 ~75 ~-2 ~38 sand 1
setblock ~72 ~-2 ~41 sand 0
fill ~72 ~-2 ~42 ~73 ~-2 ~42 sand 1
fill ~72 ~-2 ~80 ~75 ~-2 ~80 sand 0
fill ~73 ~-2 ~24 ~74 ~-2 ~24 stone 5
fill ~73 ~-2 ~30 ~73 ~-1 ~30 stone 0
fill ~73 ~-2 ~35 ~74 ~-2 ~35 sand 1
fill ~73 ~-2 ~36 ~74 ~-2 ~36 sand 1
fill ~73 ~-2 ~43 ~74 ~-2 ~43 sand 1
fill ~73 ~-2 ~44 ~74 ~-2 ~44 sand 1
fill ~74 ~-2 ~26 ~74 ~-3 ~26 stone 6
fill ~74 ~-2 ~34 ~75 ~-2 ~34 hardened_clay 0
fill ~74 ~-2 ~37 ~75 ~-2 ~37 hardened_clay 0
setblock ~74 ~-2 ~41 sand 1
setblock ~74 ~-2 ~42 hardened_clay 0
setblock ~74 ~-2 ~52 sand 1
fill ~74 ~-2 ~81 ~75 ~-2 ~81 sand 0
fill ~75 ~-2 ~33 ~75 ~-2 ~33 hardened_clay 0
fill ~75 ~-2 ~35 ~75 ~-2 ~35 hardened_clay 0
fill ~75 ~-2 ~36 ~75 ~-2 ~36 hardened_clay 0
fill ~75 ~-2 ~40 ~75 ~-2 ~44 hardened_clay 0
fill ~75 ~-2 ~45 ~75 ~-2 ~45 sand 1
setblock ~75 ~-2 ~46 sandstone 0
fill ~75 ~-2 ~48 ~75 ~-2 ~48 planks 2
setblock ~75 ~-2 ~50 sand 1
fill ~75 ~-2 ~82 ~75 ~-1 ~82 planks 2
fill ~75 ~-2 ~83 ~75 ~-2 ~83 planks 2
fill ~75 ~-2 ~84 ~75 ~11 ~84 planks 0
fill ~1 ~-1 ~29 ~2 ~-1 ~29 planks 2
fill ~1 ~-1 ~30 ~3 ~-1 ~30 planks 2
fill ~1 ~-1 ~31 ~2 ~-1 ~31 planks 2
fill ~1 ~-1 ~33 ~3 ~-1 ~33 planks 2
fill ~1 ~-1 ~34 ~3 ~-1 ~34 planks 2
fill ~1 ~-1 ~35 ~1 ~-1 ~35 planks 0
fill ~1 ~-1 ~36 ~3 ~-1 ~36 planks 0
setblock ~1 ~-1 ~37 planks 2
fill ~1 ~-1 ~38 ~1 ~2 ~38 planks 0
fill ~1 ~-1 ~49 ~4 ~-1 ~49 planks 0
fill ~1 ~-1 ~51 ~4 ~-1 ~51 planks 2
fill ~1 ~-1 ~52 ~4 ~-1 ~52 planks 2
fill ~1 ~-1 ~53 ~1 ~-1 ~53 planks 2
fill ~1 ~-1 ~54 ~3 ~-1 ~54 planks 2
fill ~1 ~-1 ~55 ~4 ~-1 ~55 planks 2
fill ~1 ~-1 ~73 ~10 ~-1 ~73 sand 0
fill ~1 ~-1 ~74 ~10 ~-1 ~74 sand 0
fill ~1 ~-1 ~75 ~11 ~-1 ~75 sand 0
fill ~1 ~-1 ~76 ~11 ~-1 ~76 sand 0
fill ~1 ~-1 ~77 ~5 ~-1 ~77 sand 0
fill ~1 ~-1 ~78 ~4 ~-1 ~78 sand 0
fill ~2 ~-1 ~28 ~4 ~-1 ~28 sandstone 0
fill ~2 ~-1 ~32 ~3 ~-1 ~32 planks 2
fill ~2 ~-1 ~35 ~2 ~3 ~35 planks 2
fill ~2 ~-1 ~37 ~3 ~-1 ~37 planks 0
fill ~2 ~-1 ~47 ~4 ~-1 ~47 planks 0
setblock ~2 ~-1 ~48 planks 2
fill ~2 ~-1 ~50 ~2 ~1 ~50 planks 0
fill ~2 ~-1 ~56 ~3 ~-1 ~56 planks 2
fill ~2 ~-1 ~71 ~10 ~-1 ~71 sand 0
fill ~2 ~-1 ~72 ~10 ~-1 ~72 sand 0
fill ~2 ~-1 ~79 ~5 ~-1 ~79 sand 0
fill ~2 ~-1 ~80 ~10 ~-1 ~80 sand 0
fill ~2 ~-1 ~81 ~9 ~-1 ~81 sand 0
fill ~2 ~-1 ~82 ~8 ~-1 ~82 sand 0
fill ~2 ~-1 ~83 ~7 ~-1 ~83 sand 0
fill ~2 ~-1 ~84 ~7 ~-1 ~84 sand 0
fill ~2 ~-1 ~85 ~7 ~-1 ~85 sand 0
fill ~3 ~-1 ~29 ~5 ~-1 ~29 sandstone 0
fill ~3 ~-1 ~31 ~8 ~-1 ~31 sandstone 0
fill ~3 ~-1 ~38 ~3 ~4 ~38 planks 0
fill ~3 ~-1 ~39 ~3 ~2 ~39 planks 0
fill ~3 ~-1 ~40 ~3 ~2 ~40 planks 0
fill ~3 ~-1 ~48 ~4 ~-1 ~48 planks 0
fill ~3 ~-1 ~50 ~3 ~3 ~50 planks 2
fill ~3 ~-1 ~53 ~4 ~-1 ~53 planks 2
fill ~3 ~-1 ~57 ~5 ~-1 ~57 sandstone 0
fill ~3 ~-1 ~70 ~8 ~-1 ~70 sand 0
fill ~3 ~-1 ~86 ~7 ~-1 ~86 sand 0
fill ~3 ~-1 ~87 ~8 ~-1 ~87 sand 0
fill ~3 ~-1 ~88 ~9 ~-1 ~88 sand 0
fill ~3 ~-1 ~89 ~10 ~-1 ~89 sand 0
fill ~4 ~-1 ~27 ~8 ~-1 ~27 end_stone 0
fill ~4 ~-1 ~30 ~7 ~-1 ~30 sandstone 0
fill ~4 ~-1 ~32 ~12 ~-1 ~32 sandstone 0
fill ~4 ~-1 ~33 ~14 ~-1 ~33 sandstone 0
fill ~4 ~-1 ~35 ~14 ~-1 ~35 sandstone 0
fill ~4 ~-1 ~36 ~4 ~6 ~36 planks 2
fill ~4 ~-1 ~37 ~4 ~1 ~37 planks 2
fill ~4 ~-1 ~38 ~7 ~-1 ~38 planks 2
fill ~4 ~-1 ~39 ~11 ~-1 ~39 planks 2
fill ~4 ~-1 ~45 ~4 ~2 ~45 planks 0
fill ~4 ~-1 ~46 ~4 ~2 ~46 planks 0
fill ~4 ~-1 ~54 ~9 ~-1 ~54 sandstone 0
fill ~4 ~-1 ~56 ~6 ~-1 ~56 sandstone 0
fill ~4 ~-1 ~90 ~11 ~-1 ~90 sand 0
fill ~4 ~-1 ~91 ~18 ~-1 ~91 sand 0
fill ~5 ~-1 ~15 ~6 ~-1 ~15 planks 2
fill ~5 ~-1 ~28 ~6 ~-1 ~28 wool 15
fill ~5 ~-1 ~34 ~13 ~-1 ~34 sandstone 0
fill ~5 ~-1 ~36 ~5 ~-1 ~37 sandstone 0
fill ~5 ~-1 ~40 ~9 ~-1 ~40 planks 2
fill ~5 ~-1 ~46 ~12 ~-1 ~46 planks 2
fill ~5 ~-1 ~47 ~8 ~-1 ~47 planks 2
fill ~5 ~-1 ~48 ~5 ~1 ~48 planks 2
fill ~5 ~-1 ~49 ~5 ~6 ~49 planks 2
fill ~5 ~-1 ~50 ~15 ~-1 ~50 sandstone 0
fill ~5 ~-1 ~52 ~15 ~-1 ~52 sandstone 0
fill ~5 ~-1 ~53 ~13 ~-1 ~53 sandstone 0
fill ~5 ~-1 ~55 ~8 ~-1 ~55 sandstone 0
fill ~5 ~-1 ~58 ~9 ~-1 ~58 end_stone 0
setblock ~5 ~-1 ~68 sand 1
fill ~5 ~-1 ~69 ~8 ~-1 ~69 sand 0
fill ~5 ~-1 ~78 ~5 ~3 ~78 planks 0
fill ~5 ~-1 ~92 ~21 ~-1 ~92 sand 0
fill ~6 ~-1 ~26 ~8 ~-1 ~26 end_stone 0
fill ~6 ~-1 ~29 ~6 ~2 ~29 wool 15
fill ~6 ~-1 ~36 ~7 ~-1 ~36 planks 2
fill ~6 ~-1 ~37 ~9 ~-1 ~37 planks 2
fill ~6 ~-1 ~41 ~8 ~-1 ~41 planks 2
fill ~6 ~-1 ~45 ~10 ~-1 ~45 planks 2
fill ~6 ~-1 ~48 ~6 ~-1 ~56 sandstone 0
fill ~6 ~-1 ~57 ~7 ~-1 ~57 wool 15
fill ~6 ~-1 ~68 ~7 ~-1 ~68 sand 0
fill ~6 ~-1 ~77 ~6 ~7 ~77 planks 2
fill ~6 ~-1 ~78 ~6 ~17 ~78 planks 3
fill ~6 ~-1 ~79 ~6 ~4 ~79 planks 2
fill ~7 ~-1 ~19 ~7 ~-3 ~19 planks 0
fill ~7 ~-1 ~20 ~7 ~-1 ~19 planks 0
fill ~7 ~-1 ~28 ~7 ~-1 ~29 end_stone 0
fill ~7 ~-1 ~44 ~9 ~-1 ~44 planks 2
fill ~7 ~-1 ~48 ~10 ~-1 ~48 planks 2
fill ~7 ~-1 ~49 ~8 ~-1 ~49 planks 2
fill ~7 ~-1 ~51 ~14 ~-1 ~51 sandstone 0
fill ~7 ~-1 ~56 ~7 ~2 ~56 wool 15
fill ~7 ~-1 ~59 ~9 ~-1 ~59 end_stone 0
fill ~7 ~-1 ~77 ~7 ~18 ~77 planks 0
fill ~7 ~-1 ~78 ~7 ~8 ~78 planks 0
fill ~7 ~-1 ~79 ~7 ~11 ~79 planks 3
fill ~7 ~-1 ~93 ~22 ~-1 ~93 sand 0
fill ~8 ~-1 ~28 ~9 ~-1 ~28 brick_block 0
setblock ~8 ~-1 ~29 sandstone 0
fill ~8 ~-1 ~36 ~13 ~-1 ~36 sandstone 0
setblock ~8 ~-1 ~38 sandstone 0
fill ~8 ~-1 ~56 ~8 ~-1 ~59 end_stone 0
setblock ~8 ~-1 ~68 sand 1
fill ~8 ~-1 ~77 ~8 ~3 ~77 planks 2
fill ~8 ~-1 ~78 ~11 ~-1 ~78 sand 0
fill ~8 ~-1 ~79 ~10 ~-1 ~79 sand 0
fill ~8 ~-1 ~94 ~22 ~-1 ~94 sand 0
fill ~9 ~-1 ~27 ~10 ~-1 ~27 brick_block 0
fill ~9 ~-1 ~29 ~10 ~-1 ~29 brick_block 0
setblock ~9 ~-1 ~30 sandstone 0
setblock ~9 ~-1 ~31 end_stone 0
fill ~9 ~-1 ~38 ~10 ~-1 ~38 planks 2
setblock ~9 ~-1 ~47 sandstone 0
fill ~9 ~-1 ~49 ~14 ~-1 ~49 sandstone 0
setblock ~9 ~-1 ~56 sandstone 0
fill ~9 ~-1 ~57 ~10 ~-1 ~57 brick_block 0
setblock ~9 ~-1 ~70 sand 1
fill ~9 ~-1 ~77 ~11 ~-1 ~77 sand 0
fill ~9 ~-1 ~95 ~22 ~-1 ~95 sand 0
fill ~10 ~-1 ~5 ~10 ~0 ~5 planks 3
fill ~10 ~-1 ~28 ~10 ~1 ~28 end_stone 0
fill ~10 ~-1 ~37 ~12 ~-1 ~37 sandstone 0
fill ~10 ~-1 ~47 ~11 ~-1 ~47 planks 2
setblock ~10 ~-1 ~54 end_stone 0
setblock ~10 ~-1 ~55 sandstone 0
fill ~10 ~-1 ~56 ~11 ~-1 ~56 brick_block 0
fill ~10 ~-1 ~58 ~11 ~-1 ~58 brick_block 0
setblock ~11 ~-1 ~28 brick_block 0
fill ~11 ~-1 ~29 ~12 ~-1 ~29 end_stone 0
fill ~11 ~-1 ~30 ~11 ~1 ~30 end_stone 0
fill ~11 ~-1 ~38 ~12 ~-1 ~38 sandstone 0
fill ~11 ~-1 ~48 ~13 ~-1 ~48 sandstone 0
fill ~11 ~-1 ~57 ~11 ~1 ~57 end_stone 0
fill ~11 ~-1 ~72 ~11 ~-3 ~72 sand 1
fill ~11 ~-1 ~73 ~11 ~-3 ~73 sand 1
fill ~11 ~-1 ~74 ~11 ~-3 ~74 sand 1
fill ~11 ~-1 ~96 ~20 ~-1 ~96 sand 0
setblock ~12 ~-1 ~31 sandstone 0
fill ~12 ~-1 ~47 ~13 ~-1 ~47 sandstone 0
fill ~12 ~-1 ~55 ~12 ~1 ~55 end_stone 0
fill ~12 ~-1 ~56 ~13 ~-1 ~56 end_stone 0
setblock ~12 ~-1 ~57 brick_block 0
fill ~12 ~-1 ~76 ~12 ~-3 ~76 sand 1
fill ~13 ~-1 ~30 ~13 ~-1 ~32 end_stone 0
setblock ~13 ~-1 ~54 sandstone 0
fill ~13 ~-1 ~97 ~19 ~-1 ~97 sand 0
setblock ~14 ~-1 ~32 sandstone 0
fill ~14 ~-1 ~53 ~14 ~0 ~53 end_stone 0
fill ~14 ~-1 ~54 ~14 ~1 ~54 end_stone 0
fill ~14 ~-1 ~55 ~14 ~-1 ~53 end_stone 0
fill ~14 ~-1 ~98 ~19 ~-1 ~98 sand 0
fill ~16 ~-1 ~99 ~18 ~-1 ~99 sand 0
fill ~17 ~-1 ~9 ~17 ~10 ~9 planks 2
fill ~18 ~-1 ~9 ~18 ~-1 ~10 planks 0
fill ~19 ~-1 ~7 ~19 ~5 ~7 planks 0
fill ~20 ~-1 ~45 ~35 ~-1 ~45 sand 0
fill ~21 ~-1 ~43 ~33 ~-1 ~43 sand 0
fill ~21 ~-1 ~44 ~35 ~-1 ~44 sand 0
fill ~21 ~-1 ~46 ~36 ~-1 ~46 sand 0
fill ~21 ~-1 ~47 ~36 ~-1 ~47 sand 0
fill ~22 ~-1 ~41 ~30 ~-1 ~41 sand 0
fill ~22 ~-1 ~42 ~32 ~-1 ~42 sand 0
fill ~22 ~-1 ~48 ~37 ~-1 ~48 sand 0
fill ~22 ~-1 ~49 ~37 ~-1 ~49 sand 0
fill ~23 ~-1 ~39 ~27 ~-1 ~39 sand 0
fill ~23 ~-1 ~40 ~29 ~-1 ~40 sand 0
fill ~23 ~-1 ~50 ~38 ~-1 ~50 sand 0
fill ~23 ~-1 ~51 ~38 ~-1 ~51 sand 0
fill ~24 ~-1 ~38 ~25 ~-1 ~38 sand 0
fill ~24 ~-1 ~52 ~39 ~-1 ~52 sand 0
fill ~25 ~-1 ~53 ~39 ~-1 ~53 sand 0
fill ~25 ~-1 ~54 ~39 ~-1 ~54 sand 0
fill ~26 ~-1 ~55 ~38 ~-1 ~55 sand 0
fill ~26 ~-1 ~56 ~38 ~-1 ~56 sand 0
fill ~26 ~-1 ~57 ~26 ~-1 ~60 sand 1
fill ~27 ~-1 ~57 ~37 ~-1 ~57 sand 0
fill ~27 ~-1 ~58 ~37 ~-1 ~58 sand 0
fill ~27 ~-1 ~59 ~36 ~-1 ~59 sand 0
fill ~27 ~-1 ~60 ~35 ~-1 ~60 sand 0
fill ~27 ~-1 ~61 ~33 ~-1 ~61 sand 0
fill ~27 ~-1 ~62 ~31 ~-1 ~62 sand 0
setblock ~27 ~-1 ~63 sand 1
fill ~28 ~-1 ~19 ~28 ~0 ~19 web 0
fill ~28 ~-1 ~20 ~28 ~0 ~20 web 0
fill ~28 ~-1 ~21 ~28 ~0 ~21 web 0
fill ~28 ~-1 ~22 ~28 ~0 ~22 web 0
fill ~28 ~-1 ~23 ~28 ~0 ~23 web 0
fill ~28 ~-1 ~24 ~28 ~0 ~24 web 0
fill ~28 ~-1 ~25 ~30 ~-1 ~25 web 0
fill ~28 ~-1 ~26 ~30 ~-1 ~26 web 0
fill ~28 ~-1 ~27 ~31 ~-1 ~27 web 0
fill ~28 ~-1 ~28 ~31 ~-1 ~28 web 0
fill ~28 ~-1 ~63 ~30 ~-1 ~63 sand 0
setblock ~28 ~-1 ~64 sand 1
fill ~29 ~-1 ~29 ~32 ~-1 ~29 web 0
fill ~29 ~-1 ~30 ~32 ~-1 ~30 web 0
fill ~30 ~-1 ~31 ~32 ~-1 ~31 web 0
fill ~30 ~-1 ~32 ~32 ~-1 ~32 web 0
fill ~32 ~-1 ~33 ~32 ~0 ~33 web 0
fill ~51 ~-1 ~113 ~52 ~-1 ~113 planks 0
fill ~52 ~-1 ~23 ~52 ~0 ~23 web 0
fill ~52 ~-1 ~24 ~52 ~0 ~24 web 0
fill ~53 ~-1 ~30 ~68 ~-1 ~30 stone 0
fill ~53 ~-1 ~31 ~73 ~-1 ~31 stone 0
fill ~54 ~-1 ~28 ~61 ~-1 ~28 stone 0
fill ~54 ~-1 ~29 ~67 ~-1 ~29 stone 0
fill ~54 ~-1 ~32 ~72 ~-1 ~32 stone 0
fill ~54 ~-1 ~33 ~72 ~-1 ~33 stone 0
fill ~54 ~-1 ~34 ~71 ~-1 ~34 stone 0
fill ~54 ~-1 ~115 ~54 ~3 ~115 planks 2
fill ~55 ~-1 ~27 ~60 ~-1 ~27 stone 0
fill ~55 ~-1 ~35 ~71 ~-1 ~35 stone 0
fill ~55 ~-1 ~36 ~71 ~-1 ~36 stone 0
fill ~56 ~-1 ~37 ~70 ~-1 ~37 stone 0
fill ~57 ~-1 ~0 ~65 ~-1 ~0 stone 6
setblock ~57 ~-1 ~1 stone 5
setblock ~57 ~-1 ~2 stone 6
fill ~57 ~-1 ~4 ~58 ~-1 ~4 stone 5
fill ~57 ~-1 ~5 ~58 ~-1 ~5 stone 5
fill ~57 ~-1 ~6 ~57 ~-1 ~7 stone 5
fill ~57 ~-1 ~26 ~59 ~-1 ~26 stone 0
fill ~57 ~-1 ~38 ~70 ~-1 ~38 stone 0
fill ~57 ~-1 ~64 ~75 ~-1 ~64 sand 0
fill ~57 ~-1 ~65 ~75 ~-1 ~65 sand 0
setblock ~57 ~-1 ~67 sand 0
setblock ~57 ~-1 ~68 sand 1
fill ~58 ~-1 ~1 ~65 ~-1 ~1 stone 6
fill ~58 ~-1 ~2 ~60 ~-1 ~2 stone 5
fill ~58 ~-1 ~7 ~63 ~-1 ~7 stone 5
fill ~58 ~-1 ~8 ~62 ~-1 ~8 stone 5
fill ~58 ~-1 ~9 ~61 ~-1 ~9 stone 5
fill ~58 ~-1 ~25 ~66 ~-1 ~25 stone 6
fill ~58 ~-1 ~63 ~75 ~-1 ~63 sand 0
setblock ~58 ~-1 ~67 sand 1
fill ~58 ~-1 ~68 ~75 ~-1 ~68 sand 0
fill ~59 ~-1 ~3 ~63 ~-1 ~3 stone 5
fill ~59 ~-1 ~4 ~59 ~-1 ~5 stone 6
fill ~59 ~-1 ~6 ~59 ~0 ~6 stone 5
fill ~59 ~-1 ~10 ~60 ~-1 ~10 stone 5
fill ~59 ~-1 ~39 ~69 ~-1 ~39 stone 0
fill ~59 ~-1 ~61 ~69 ~-1 ~61 sand 0
fill ~59 ~-1 ~62 ~75 ~-1 ~62 sand 0
fill ~59 ~-1 ~66 ~75 ~-1 ~66 sand 0
fill ~59 ~-1 ~67 ~75 ~-1 ~67 sand 0
fill ~59 ~-1 ~69 ~75 ~-1 ~69 sand 0
fill ~59 ~-1 ~70 ~75 ~-1 ~70 sand 0
fill ~60 ~-1 ~5 ~61 ~-1 ~5 stone 6
fill ~60 ~-1 ~11 ~61 ~-1 ~11 stone 5
fill ~60 ~-1 ~24 ~64 ~-1 ~24 stone 6
fill ~60 ~-1 ~26 ~65 ~-1 ~26 stone 6
fill ~60 ~-1 ~60 ~67 ~-1 ~60 sand 0
fill ~60 ~-1 ~71 ~75 ~-1 ~71 sand 0
fill ~61 ~-1 ~2 ~61 ~0 ~2 stone 6
setblock ~61 ~-1 ~4 stone 5
fill ~61 ~-1 ~6 ~62 ~-1 ~6 stone 6
fill ~61 ~-1 ~10 ~63 ~-1 ~10 stone 6
setblock ~61 ~-1 ~27 stone 6
fill ~61 ~-1 ~46 ~73 ~-1 ~46 sand 0
fill ~61 ~-1 ~47 ~73 ~-1 ~47 sand 0
fill ~61 ~-1 ~48 ~74 ~-1 ~48 sand 0
fill ~61 ~-1 ~72 ~75 ~-1 ~72 sand 0
fill ~62 ~-1 ~2 ~62 ~0 ~2 stone 5
fill ~62 ~-1 ~5 ~62 ~2 ~5 stone 5
fill ~62 ~-1 ~9 ~62 ~1 ~9 stone 6
fill ~62 ~-1 ~11 ~63 ~-1 ~11 stone 6
fill ~62 ~-1 ~27 ~63 ~-1 ~27 stone 0
setblock ~62 ~-1 ~28 stone 6
fill ~62 ~-1 ~45 ~74 ~-1 ~45 sand 0
fill ~62 ~-1 ~49 ~74 ~-1 ~49 sand 0
fill ~62 ~-1 ~59 ~65 ~-1 ~59 sand 0
fill ~62 ~-1 ~73 ~75 ~-1 ~73 sand 0
fill ~63 ~-1 ~2 ~64 ~-1 ~2 stone 6
fill ~63 ~-1 ~4 ~65 ~-1 ~4 stone 6
fill ~63 ~-1 ~5 ~65 ~-1 ~5 stone 6
setblock ~63 ~-1 ~6 stone 5
fill ~63 ~-1 ~9 ~63 ~1 ~9 stone 5
fill ~63 ~-1 ~23 ~65 ~-1 ~23 stone 6
fill ~63 ~-1 ~28 ~68 ~-1 ~28 stone 0
fill ~63 ~-1 ~40 ~67 ~-1 ~40 stone 0
fill ~63 ~-1 ~43 ~71 ~-1 ~43 sand 0
fill ~63 ~-1 ~44 ~74 ~-1 ~44 sand 0
fill ~63 ~-1 ~50 ~72 ~-1 ~50 sand 0
fill ~63 ~-1 ~74 ~75 ~-1 ~74 sand 0
fill ~64 ~-1 ~3 ~65 ~-1 ~3 stone 6
fill ~64 ~-1 ~6 ~65 ~-1 ~6 stone 6
fill ~64 ~-1 ~7 ~65 ~-1 ~7 stone 6
fill ~64 ~-1 ~9 ~65 ~-1 ~9 stone 6
fill ~64 ~-1 ~27 ~67 ~-1 ~27 stone 6
fill ~64 ~-1 ~42 ~72 ~-1 ~42 sand 0
fill ~65 ~-1 ~2 ~75 ~-1 ~2 stone 0
setblock ~65 ~-1 ~10 stone 6
fill ~65 ~-1 ~24 ~66 ~-1 ~24 stone 5
fill ~65 ~-1 ~41 ~70 ~-1 ~41 sand 0
fill ~65 ~-1 ~75 ~75 ~-1 ~75 sand 0
fill ~66 ~-1 ~0 ~75 ~-1 ~0 stone 0
fill ~66 ~-1 ~1 ~75 ~-1 ~1 stone 0
fill ~66 ~-1 ~3 ~75 ~-1 ~3 stone 0
fill ~66 ~-1 ~4 ~75 ~-1 ~4 stone 0
fill ~66 ~-1 ~5 ~75 ~-1 ~5 stone 0
fill ~66 ~-1 ~6 ~74 ~-1 ~6 stone 0
fill ~66 ~-1 ~7 ~73 ~-1 ~7 stone 0
setblock ~66 ~-1 ~8 stone 6
fill ~66 ~-1 ~9 ~69 ~-1 ~9 stone 0
fill ~66 ~-1 ~51 ~70 ~-1 ~51 sand 0
fill ~66 ~-1 ~76 ~75 ~-1 ~76 sand 0
fill ~67 ~-1 ~8 ~71 ~-1 ~8 stone 0
fill ~67 ~-1 ~23 ~68 ~-1 ~23 stone 5
fill ~67 ~-1 ~24 ~67 ~0 ~24 stone 6
fill ~67 ~-1 ~25 ~72 ~-1 ~25 stone 5
fill ~67 ~-1 ~26 ~67 ~1 ~26 stone 5
setblock ~68 ~-1 ~24 stone 5
fill ~68 ~-1 ~26 ~70 ~-1 ~26 stone 6
setblock ~68 ~-1 ~29 stone 6
fill ~68 ~-1 ~77 ~75 ~-1 ~77 sand 0
fill ~68 ~-1 ~108 ~68 ~1 ~108 planks 2
fill ~68 ~-1 ~109 ~68 ~-1 ~108 planks 2
fill ~69 ~-1 ~23 ~69 ~-1 ~24 stone 6
fill ~69 ~-1 ~27 ~69 ~-3 ~27 stone 6
fill ~69 ~-1 ~28 ~71 ~-1 ~28 stone 6
fill ~69 ~-1 ~29 ~69 ~0 ~29 stone 0
setblock ~69 ~-1 ~30 stone 6
fill ~70 ~-1 ~23 ~70 ~-1 ~25 stone 5
fill ~70 ~-1 ~27 ~70 ~0 ~27 stone 5
fill ~70 ~-1 ~29 ~71 ~-1 ~29 stone 6
setblock ~70 ~-1 ~30 stone 0
setblock ~71 ~-1 ~24 stone 5
fill ~71 ~-1 ~26 ~73 ~-1 ~26 stone 5
fill ~71 ~-1 ~27 ~72 ~-1 ~27 stone 6
fill ~71 ~-1 ~30 ~71 ~1 ~30 stone 6
fill ~71 ~-1 ~78 ~75 ~-1 ~78 sand 0
fill ~72 ~-1 ~28 ~72 ~-1 ~29 stone 0
setblock ~72 ~-1 ~43 sand 1
setblock ~73 ~-1 ~25 stone 6
setblock ~73 ~-1 ~27 stone 5
fill ~73 ~-1 ~28 ~73 ~-1 ~29 stone 6
setblock ~73 ~-1 ~43 sand 0
fill ~73 ~-1 ~79 ~75 ~-1 ~79 sand 0
setblock ~74 ~-1 ~46 sandstone 0
fill ~74 ~-1 ~47 ~74 ~2 ~47 end_stone 0
setblock ~75 ~-1 ~42 end_stone 0
fill ~75 ~-1 ~44 ~75 ~-1 ~45 brick_block 0
fill ~75 ~-1 ~46 ~75 ~1 ~46 end_stone 0
fill ~75 ~-1 ~48 ~75 ~1 ~48 wool 15
fill ~75 ~-1 ~49 ~75 ~-1 ~49 planks 2
fill ~75 ~-1 ~80 ~75 ~-1 ~80 sand 0
fill ~75 ~-1 ~83 ~75 ~-1 ~83 planks 2
fill ~1 ~0 ~20 ~1 ~0 ~20 planks 2
setblock ~1 ~0 ~32 wool 15
fill ~1 ~0 ~33 ~1 ~0 ~33 planks 2
fill ~1 ~0 ~34 ~4 ~0 ~34 planks 2
fill ~1 ~0 ~35 ~1 ~1 ~35 planks 0
fill ~1 ~0 ~36 ~2 ~0 ~36 planks 0
fill ~1 ~0 ~37 ~2 ~0 ~37 planks 0
fill ~1 ~0 ~48 ~3 ~0 ~48 planks 0
fill ~1 ~0 ~49 ~3 ~0 ~49 planks 0
fill ~1 ~0 ~50 ~1 ~0 ~53 planks 2
fill ~2 ~0 ~28 ~3 ~0 ~28 sandstone 0
fill ~2 ~0 ~29 ~3 ~0 ~29 sandstone 0
setblock ~2 ~0 ~30 planks 2
setblock ~2 ~0 ~31 wool 15
fill ~2 ~0 ~32 ~3 ~0 ~32 planks 2
setblock ~2 ~0 ~33 wool 15
fill ~2 ~0 ~47 ~5 ~0 ~47 planks 0
fill ~2 ~0 ~51 ~5 ~0 ~51 planks 2
fill ~2 ~0 ~52 ~2 ~0 ~51 planks 2
setblock ~2 ~0 ~53 wool 15
fill ~2 ~0 ~106 ~2 ~3 ~106 planks 2
fill ~3 ~0 ~30 ~7 ~0 ~30 sandstone 0
setblock ~3 ~0 ~31 planks 2
fill ~3 ~0 ~36 ~3 ~1 ~36 planks 2
fill ~3 ~0 ~37 ~3 ~0 ~31 planks 2
setblock ~3 ~0 ~52 wool 15
fill ~3 ~0 ~53 ~4 ~0 ~53 planks 2
setblock ~3 ~0 ~54 wool 15
setblock ~3 ~0 ~55 planks 2
fill ~3 ~0 ~56 ~4 ~0 ~56 sandstone 0
fill ~3 ~0 ~57 ~4 ~0 ~57 sandstone 0
setblock ~4 ~0 ~19 planks 0
fill ~4 ~0 ~29 ~7 ~0 ~29 wool 15
fill ~4 ~0 ~31 ~11 ~0 ~31 sandstone 0
fill ~4 ~0 ~32 ~11 ~0 ~32 sandstone 0
fill ~4 ~0 ~33 ~12 ~0 ~33 sandstone 0
fill ~4 ~0 ~35 ~4 ~6 ~35 planks 2
fill ~4 ~0 ~38 ~4 ~5 ~38 planks 0
fill ~4 ~0 ~39 ~4 ~4 ~39 planks 0
fill ~4 ~0 ~40 ~10 ~0 ~40 planks 2
setblock ~4 ~0 ~41 planks 0
fill ~4 ~0 ~48 ~4 ~0 ~54 planks 2
fill ~4 ~0 ~55 ~8 ~0 ~55 sandstone 0
fill ~4 ~0 ~74 ~7 ~0 ~74 sand 0
fill ~4 ~0 ~75 ~6 ~0 ~75 sand 0
fill ~5 ~0 ~15 ~5 ~3 ~15 planks 2
setblock ~5 ~0 ~26 sandstone 0
fill ~5 ~0 ~34 ~13 ~0 ~34 sandstone 0
fill ~5 ~0 ~35 ~14 ~0 ~35 sandstone 0
fill ~5 ~0 ~36 ~6 ~0 ~36 planks 2
fill ~5 ~0 ~37 ~10 ~0 ~37 planks 2
fill ~5 ~0 ~38 ~11 ~0 ~38 planks 2
fill ~5 ~0 ~39 ~11 ~0 ~39 planks 2
fill ~5 ~0 ~41 ~8 ~0 ~41 planks 2
setblock ~5 ~0 ~44 planks 0
fill ~5 ~0 ~45 ~11 ~0 ~45 planks 2
fill ~5 ~0 ~46 ~5 ~4 ~46 planks 0
fill ~5 ~0 ~50 ~5 ~6 ~50 planks 2
fill ~5 ~0 ~52 ~13 ~0 ~52 sandstone 0
fill ~5 ~0 ~53 ~12 ~0 ~53 sandstone 0
fill ~5 ~0 ~54 ~12 ~0 ~54 sandstone 0
fill ~5 ~0 ~56 ~8 ~0 ~56 wool 15
fill ~5 ~0 ~72 ~6 ~0 ~72 sand 0
fill ~5 ~0 ~73 ~7 ~0 ~73 sand 0
setblock ~5 ~0 ~76 sand 0
fill ~6 ~0 ~26 ~8 ~0 ~26 end_stone 0
fill ~6 ~0 ~44 ~9 ~0 ~44 planks 2
fill ~6 ~0 ~46 ~12 ~0 ~46 planks 2
fill ~6 ~0 ~47 ~12 ~0 ~47 planks 2
fill ~6 ~0 ~48 ~11 ~0 ~48 planks 2
fill ~6 ~0 ~49 ~7 ~0 ~49 planks 2
fill ~6 ~0 ~50 ~15 ~0 ~50 sandstone 0
fill ~6 ~0 ~51 ~14 ~0 ~51 sandstone 0
setblock ~6 ~0 ~59 sandstone 0
setblock ~7 ~0 ~27 sandstone 0
setblock ~7 ~0 ~28 wool 15
fill ~7 ~0 ~36 ~13 ~0 ~36 sandstone 0
fill ~7 ~0 ~59 ~9 ~0 ~59 end_stone 0
fill ~8 ~0 ~27 ~10 ~0 ~27 end_stone 0
fill ~8 ~0 ~28 ~10 ~0 ~28 end_stone 0
fill ~8 ~0 ~29 ~8 ~0 ~26 end_stone 0
fill ~8 ~0 ~49 ~14 ~0 ~49 sandstone 0
setblock ~8 ~0 ~57 wool 15
setblock ~8 ~0 ~58 sandstone 0
fill ~9 ~0 ~29 ~9 ~5 ~29 sandstone 0
setblock ~9 ~0 ~30 end_stone 0
fill ~9 ~0 ~56 ~9 ~0 ~59 end_stone 0
fill ~10 ~0 ~18 ~10 ~5 ~18 planks 2
fill ~10 ~0 ~29 ~12 ~0 ~29 end_stone 0
setblock ~10 ~0 ~55 end_stone 0
fill ~10 ~0 ~56 ~10 ~5 ~56 sandstone 0
fill ~10 ~0 ~57 ~10 ~0 ~58 end_stone 0
setblock ~11 ~0 ~28 sandstone 0
fill ~11 ~0 ~37 ~13 ~0 ~37 sandstone 0
fill ~11 ~0 ~56 ~13 ~0 ~56 end_stone 0
setblock ~11 ~0 ~58 end_stone 0
fill ~12 ~0 ~31 ~13 ~0 ~31 end_stone 0
fill ~12 ~0 ~32 ~14 ~0 ~32 end_stone 0
fill ~12 ~0 ~38 ~12 ~1 ~38 sandstone 0
fill ~12 ~0 ~48 ~14 ~0 ~48 sandstone 0
setblock ~12 ~0 ~57 sandstone 0
setblock ~13 ~0 ~30 sandstone 0
fill ~13 ~0 ~33 ~14 ~0 ~33 end_stone 0
fill ~13 ~0 ~47 ~13 ~1 ~47 sandstone 0
fill ~13 ~0 ~53 ~13 ~0 ~56 end_stone 0
setblock ~14 ~0 ~7 planks 0
setblock ~14 ~0 ~31 sandstone 0
fill ~14 ~0 ~52 ~15 ~0 ~52 end_stone 0
setblock ~14 ~0 ~55 sandstone 0
setblock ~15 ~0 ~10 planks 2
setblock ~15 ~0 ~53 end_stone 0
setblock ~15 ~0 ~54 sandstone 0
fill ~16 ~0 ~0 ~16 ~4 ~0 planks 3
fill ~18 ~0 ~4 ~18 ~2 ~4 planks 2
setblock ~18 ~0 ~7 planks 0
fill ~18 ~0 ~10 ~18 ~3 ~10 planks 0
fill ~23 ~0 ~44 ~31 ~0 ~44 sand 0
fill ~23 ~0 ~45 ~33 ~0 ~45 sand 0
fill ~23 ~0 ~46 ~33 ~0 ~46 sand 0
fill ~23 ~0 ~47 ~34 ~0 ~47 sand 0
fill ~24 ~0 ~42 ~28 ~0 ~42 sand 0
fill ~24 ~0 ~43 ~30 ~0 ~43 sand 0
fill ~24 ~0 ~48 ~34 ~0 ~48 sand 0
fill ~24 ~0 ~49 ~35 ~0 ~49 sand 0
fill ~25 ~0 ~41 ~26 ~0 ~41 sand 0
fill ~25 ~0 ~50 ~35 ~0 ~50 sand 0
fill ~25 ~0 ~51 ~36 ~0 ~51 sand 0
fill ~27 ~0 ~18 ~27 ~2 ~18 web 0
fill ~27 ~0 ~19 ~27 ~1 ~19 web 0
fill ~27 ~0 ~20 ~27 ~1 ~20 web 0
fill ~27 ~0 ~21 ~27 ~1 ~21 web 0
fill ~27 ~0 ~22 ~27 ~1 ~22 web 0
fill ~27 ~0 ~23 ~27 ~1 ~23 web 0
fill ~27 ~0 ~24 ~27 ~1 ~24 web 0
fill ~27 ~0 ~25 ~28 ~0 ~25 web 0
fill ~27 ~0 ~26 ~28 ~0 ~26 web 0
fill ~27 ~0 ~27 ~29 ~0 ~27 web 0
fill ~27 ~0 ~28 ~29 ~0 ~28 web 0
fill ~27 ~0 ~29 ~30 ~0 ~29 web 0
fill ~27 ~0 ~52 ~36 ~0 ~52 sand 0
fill ~27 ~0 ~53 ~37 ~0 ~53 sand 0
fill ~28 ~0 ~30 ~30 ~0 ~30 web 0
fill ~28 ~0 ~54 ~36 ~0 ~54 sand 0
fill ~28 ~0 ~55 ~36 ~0 ~55 sand 0
fill ~29 ~0 ~31 ~31 ~0 ~31 web 0
fill ~29 ~0 ~56 ~35 ~0 ~56 sand 0
fill ~29 ~0 ~57 ~33 ~0 ~57 sand 0
fill ~30 ~0 ~32 ~32 ~0 ~32 web 0
fill ~30 ~0 ~58 ~31 ~0 ~58 sand 0
fill ~50 ~0 ~116 ~50 ~3 ~116 planks 3
fill ~51 ~0 ~113 ~52 ~0 ~113 planks 0
fill ~53 ~0 ~22 ~53 ~1 ~22 web 0
fill ~53 ~0 ~23 ~53 ~1 ~23 web 0
fill ~53 ~0 ~24 ~53 ~1 ~24 web 0
fill ~53 ~0 ~25 ~53 ~1 ~25 web 0
fill ~53 ~0 ~26 ~53 ~1 ~26 web 0
fill ~53 ~0 ~27 ~53 ~1 ~27 web 0
fill ~53 ~0 ~28 ~53 ~1 ~28 web 0
fill ~53 ~0 ~29 ~53 ~2 ~29 web 0
fill ~54 ~0 ~31 ~69 ~0 ~31 stone 0
fill ~55 ~0 ~29 ~65 ~0 ~29 stone 0
fill ~55 ~0 ~30 ~66 ~0 ~30 stone 0
fill ~55 ~0 ~32 ~72 ~0 ~32 stone 0
fill ~55 ~0 ~33 ~72 ~0 ~33 stone 0
fill ~55 ~0 ~34 ~71 ~0 ~34 stone 0
fill ~55 ~0 ~35 ~71 ~0 ~35 stone 0
fill ~56 ~0 ~28 ~66 ~0 ~28 stone 0
fill ~56 ~0 ~36 ~71 ~0 ~36 stone 0
fill ~56 ~0 ~37 ~70 ~0 ~37 stone 0
fill ~57 ~0 ~38 ~70 ~0 ~38 stone 0
fill ~58 ~0 ~65 ~74 ~0 ~65 sand 0
fill ~59 ~0 ~0 ~65 ~0 ~0 stone 6
fill ~59 ~0 ~1 ~59 ~0 ~8 stone 5
fill ~59 ~0 ~63 ~70 ~0 ~63 sand 0
fill ~59 ~0 ~64 ~72 ~0 ~64 sand 0
fill ~59 ~0 ~66 ~75 ~0 ~66 sand 0
fill ~59 ~0 ~67 ~75 ~0 ~67 sand 0
fill ~59 ~0 ~68 ~75 ~0 ~68 sand 0
fill ~60 ~0 ~1 ~64 ~0 ~1 stone 6
fill ~60 ~0 ~2 ~60 ~1 ~2 stone 5
setblock ~60 ~0 ~3 stone 6
fill ~60 ~0 ~5 ~62 ~0 ~5 stone 5
fill ~60 ~0 ~6 ~60 ~0 ~7 stone 6
fill ~60 ~0 ~8 ~60 ~0 ~10 stone 5
fill ~60 ~0 ~62 ~67 ~0 ~62 sand 0
fill ~60 ~0 ~69 ~75 ~0 ~69 sand 0
fill ~61 ~0 ~3 ~62 ~0 ~3 stone 5
setblock ~61 ~0 ~4 stone 6
fill ~61 ~0 ~6 ~62 ~0 ~6 stone 5
fill ~61 ~0 ~7 ~61 ~1 ~7 stone 5
fill ~61 ~0 ~8 ~62 ~0 ~8 stone 6
fill ~61 ~0 ~9 ~61 ~0 ~10 stone 5
fill ~61 ~0 ~27 ~63 ~0 ~27 stone 0
fill ~61 ~0 ~39 ~69 ~0 ~39 stone 0
fill ~61 ~0 ~70 ~75 ~0 ~70 sand 0
fill ~62 ~0 ~4 ~62 ~2 ~4 stone 5
fill ~62 ~0 ~10 ~63 ~0 ~10 stone 6
fill ~62 ~0 ~61 ~65 ~0 ~61 sand 0
fill ~62 ~0 ~71 ~75 ~0 ~71 sand 0
fill ~63 ~0 ~2 ~63 ~2 ~2 stone 5
fill ~63 ~0 ~3 ~64 ~0 ~3 stone 6
fill ~63 ~0 ~4 ~63 ~1 ~4 stone 6
fill ~63 ~0 ~5 ~66 ~0 ~5 stone 6
fill ~63 ~0 ~6 ~65 ~0 ~6 stone 6
fill ~63 ~0 ~7 ~63 ~2 ~7 stone 5
fill ~63 ~0 ~8 ~63 ~2 ~8 stone 5
fill ~63 ~0 ~26 ~65 ~0 ~26 stone 6
fill ~63 ~0 ~72 ~75 ~0 ~72 sand 0
fill ~64 ~0 ~2 ~64 ~2 ~2 stone 6
fill ~64 ~0 ~4 ~64 ~1 ~4 stone 5
fill ~64 ~0 ~7 ~65 ~0 ~7 stone 6
fill ~64 ~0 ~9 ~65 ~0 ~9 stone 6
fill ~64 ~0 ~25 ~65 ~0 ~25 stone 6
fill ~64 ~0 ~27 ~64 ~-3 ~27 stone 6
fill ~64 ~0 ~40 ~68 ~0 ~40 stone 0
fill ~64 ~0 ~73 ~75 ~0 ~73 sand 0
fill ~65 ~0 ~1 ~75 ~0 ~1 stone 0
fill ~65 ~0 ~2 ~75 ~0 ~2 stone 0
fill ~65 ~0 ~3 ~75 ~0 ~3 stone 0
setblock ~65 ~0 ~4 stone 6
fill ~65 ~0 ~27 ~65 ~1 ~27 stone 0
fill ~65 ~0 ~74 ~74 ~0 ~74 sand 0
fill ~66 ~0 ~0 ~75 ~0 ~0 stone 0
fill ~66 ~0 ~4 ~75 ~0 ~4 stone 0
fill ~66 ~0 ~6 ~75 ~0 ~6 stone 0
fill ~66 ~0 ~7 ~73 ~0 ~7 stone 0
fill ~66 ~0 ~8 ~66 ~1 ~8 stone 0
fill ~66 ~0 ~9 ~69 ~0 ~9 stone 0
fill ~66 ~0 ~24 ~66 ~0 ~26 stone 5
setblock ~66 ~0 ~27 stone 6
setblock ~66 ~0 ~29 stone 6
fill ~67 ~0 ~5 ~75 ~0 ~5 stone 0
fill ~67 ~0 ~8 ~67 ~1 ~8 stone 6
setblock ~67 ~0 ~25 stone 6
fill ~67 ~0 ~27 ~67 ~1 ~27 stone 0
setblock ~67 ~0 ~28 stone 6
fill ~67 ~0 ~29 ~69 ~0 ~29 stone 0
fill ~67 ~0 ~30 ~68 ~0 ~30 stone 6
fill ~67 ~0 ~109 ~67 ~4 ~109 planks 2
fill ~68 ~0 ~8 ~71 ~0 ~8 stone 0
setblock ~68 ~0 ~24 stone 6
fill ~68 ~0 ~25 ~68 ~0 ~26 stone 5
fill ~68 ~0 ~27 ~68 ~1 ~27 stone 6
fill ~68 ~0 ~28 ~69 ~0 ~28 stone 0
fill ~69 ~0 ~26 ~70 ~0 ~26 stone 6
setblock ~69 ~0 ~27 stone 5
fill ~69 ~0 ~30 ~69 ~2 ~30 stone 0
fill ~69 ~0 ~106 ~69 ~5 ~106 planks 2
setblock ~70 ~0 ~25 stone 5
fill ~70 ~0 ~28 ~72 ~0 ~28 stone 6
fill ~70 ~0 ~29 ~72 ~0 ~29 stone 6
fill ~70 ~0 ~30 ~70 ~1 ~30 stone 6
fill ~70 ~0 ~31 ~70 ~1 ~31 stone 6
fill ~70 ~0 ~75 ~72 ~0 ~75 sand 0
fill ~71 ~0 ~26 ~72 ~0 ~26 stone 5
fill ~71 ~0 ~27 ~73 ~0 ~27 stone 6
fill ~71 ~0 ~31 ~71 ~1 ~31 stone 0
setblock ~72 ~0 ~30 stone 0
setblock ~72 ~0 ~31 stone 6
fill ~73 ~0 ~28 ~73 ~0 ~29 stone 0
fill ~74 ~0 ~43 ~75 ~0 ~43 brick_block 0
fill ~74 ~0 ~44 ~74 ~0 ~43 brick_block 0
fill ~74 ~0 ~45 ~74 ~2 ~45 end_stone 0
fill ~74 ~0 ~46 ~74 ~2 ~46 end_stone 0
fill ~75 ~0 ~41 ~75 ~0 ~41 brick_block 0
fill ~75 ~0 ~42 ~75 ~0 ~42 brick_block 0
setblock ~75 ~0 ~44 end_stone 0
setblock ~75 ~0 ~45 brick_block 0
fill ~75 ~0 ~83 ~75 ~0 ~83 planks 2
fill ~1 ~1 ~20 ~1 ~5 ~20 planks 2
fill ~1 ~1 ~33 ~1 ~2 ~33 wool 15
fill ~1 ~1 ~34 ~1 ~2 ~34 wool 15
fill ~1 ~1 ~36 ~2 ~1 ~36 planks 0
fill ~1 ~1 ~37 ~3 ~1 ~37 planks 0
fill ~1 ~1 ~48 ~4 ~1 ~48 planks 0
fill ~1 ~1 ~49 ~3 ~1 ~49 planks 0
fill ~1 ~1 ~50 ~1 ~1 ~48 planks 0
setblock ~1 ~1 ~51 planks 2
fill ~2 ~1 ~29 ~3 ~1 ~29 sandstone 0
fill ~2 ~1 ~32 ~3 ~1 ~32 wool 15
fill ~2 ~1 ~34 ~4 ~1 ~34 planks 2
fill ~2 ~1 ~47 ~5 ~1 ~47 planks 0
fill ~2 ~1 ~51 ~2 ~2 ~51 wool 15
fill ~2 ~1 ~52 ~2 ~2 ~52 wool 15
fill ~3 ~1 ~30 ~9 ~1 ~30 sandstone 0
fill ~3 ~1 ~31 ~3 ~2 ~31 wool 15
setblock ~3 ~1 ~35 planks 0
fill ~3 ~1 ~51 ~5 ~1 ~51 planks 2
fill ~3 ~1 ~53 ~4 ~1 ~53 wool 15
fill ~3 ~1 ~56 ~4 ~1 ~56 sandstone 0
fill ~4 ~1 ~20 ~5 ~1 ~20 planks 0
fill ~4 ~1 ~29 ~7 ~1 ~29 wool 15
fill ~4 ~1 ~31 ~10 ~1 ~31 sandstone 0
fill ~4 ~1 ~32 ~10 ~1 ~32 sandstone 0
fill ~4 ~1 ~33 ~11 ~1 ~33 sandstone 0
setblock ~4 ~1 ~40 planks 0
setblock ~4 ~1 ~49 planks 2
setblock ~4 ~1 ~50 planks 0
fill ~4 ~1 ~54 ~4 ~2 ~54 wool 15
fill ~4 ~1 ~55 ~10 ~1 ~55 sandstone 0
fill ~5 ~1 ~34 ~13 ~1 ~34 sandstone 0
fill ~5 ~1 ~35 ~5 ~7 ~35 planks 2
fill ~5 ~1 ~36 ~5 ~0 ~36 planks 2
fill ~5 ~1 ~37 ~9 ~1 ~37 planks 2
fill ~5 ~1 ~38 ~11 ~1 ~38 planks 2
fill ~5 ~1 ~39 ~5 ~3 ~39 planks 0
fill ~5 ~1 ~40 ~10 ~1 ~40 planks 2
fill ~5 ~1 ~41 ~8 ~1 ~41 planks 2
setblock ~5 ~1 ~45 planks 0
fill ~5 ~1 ~52 ~12 ~1 ~52 sandstone 0
fill ~5 ~1 ~53 ~11 ~1 ~53 sandstone 0
fill ~5 ~1 ~54 ~11 ~1 ~54 sandstone 0
fill ~5 ~1 ~56 ~8 ~1 ~56 wool 15
fill ~6 ~1 ~35 ~14 ~1 ~35 sandstone 0
fill ~6 ~1 ~36 ~7 ~1 ~36 sandstone 0
fill ~6 ~1 ~39 ~11 ~1 ~39 planks 2
fill ~6 ~1 ~44 ~9 ~1 ~44 planks 2
fill ~6 ~1 ~45 ~11 ~1 ~45 planks 2
fill ~6 ~1 ~46 ~6 ~3 ~46 planks 0
fill ~6 ~1 ~47 ~12 ~1 ~47 planks 2
fill ~6 ~1 ~48 ~10 ~1 ~48 planks 2
fill ~6 ~1 ~49 ~6 ~0 ~49 planks 2
fill ~6 ~1 ~50 ~6 ~7 ~50 planks 2
fill ~6 ~1 ~51 ~14 ~1 ~51 sandstone 0
fill ~7 ~1 ~26 ~7 ~1 ~27 end_stone 0
fill ~7 ~1 ~46 ~12 ~1 ~46 planks 2
fill ~7 ~1 ~49 ~8 ~1 ~49 sandstone 0
fill ~7 ~1 ~50 ~15 ~1 ~50 sandstone 0
setblock ~8 ~1 ~26 sandstone 0
fill ~8 ~1 ~27 ~9 ~1 ~27 end_stone 0
fill ~8 ~1 ~28 ~9 ~1 ~28 sandstone 0
fill ~8 ~1 ~29 ~8 ~5 ~29 sandstone 0
fill ~8 ~1 ~36 ~8 ~6 ~36 planks 2
fill ~8 ~1 ~58 ~10 ~1 ~58 end_stone 0
fill ~8 ~1 ~59 ~8 ~1 ~58 end_stone 0
fill ~9 ~1 ~36 ~13 ~1 ~36 sandstone 0
fill ~9 ~1 ~49 ~9 ~6 ~49 planks 2
fill ~9 ~1 ~56 ~9 ~5 ~56 sandstone 0
fill ~9 ~1 ~57 ~10 ~1 ~57 sandstone 0
setblock ~9 ~1 ~59 sandstone 0
setblock ~10 ~1 ~27 sandstone 0
fill ~10 ~1 ~29 ~12 ~1 ~29 end_stone 0
setblock ~10 ~1 ~37 sandstone 0
fill ~10 ~1 ~49 ~14 ~1 ~49 sandstone 0
fill ~11 ~1 ~3 ~11 ~5 ~3 planks 2
fill ~11 ~1 ~28 ~11 ~2 ~28 end_stone 0
fill ~11 ~1 ~31 ~11 ~1 ~32 end_stone 0
fill ~11 ~1 ~37 ~11 ~4 ~37 planks 2
setblock ~11 ~1 ~48 sandstone 0
fill ~11 ~1 ~56 ~13 ~1 ~56 end_stone 0
setblock ~11 ~1 ~58 sandstone 0
fill ~12 ~1 ~30 ~12 ~1 ~32 sandstone 0
fill ~12 ~1 ~33 ~14 ~1 ~33 end_stone 0
fill ~12 ~1 ~37 ~13 ~1 ~37 sandstone 0
fill ~12 ~1 ~48 ~12 ~4 ~48 planks 2
fill ~12 ~1 ~53 ~12 ~3 ~53 end_stone 0
fill ~12 ~1 ~54 ~12 ~1 ~53 end_stone 0
fill ~12 ~1 ~57 ~12 ~2 ~57 end_stone 0
fill ~13 ~1 ~30 ~13 ~1 ~31 end_stone 0
fill ~13 ~1 ~32 ~14 ~1 ~32 sandstone 0
fill ~13 ~1 ~48 ~14 ~1 ~48 sandstone 0
fill ~13 ~1 ~52 ~15 ~1 ~52 end_stone 0
fill ~13 ~1 ~53 ~15 ~1 ~53 sandstone 0
fill ~13 ~1 ~54 ~13 ~1 ~55 sandstone 0
fill ~14 ~1 ~9 ~14 ~1 ~10 planks 2
setblock ~14 ~1 ~55 end_stone 0
setblock ~19 ~1 ~8 planks 0
fill ~26 ~1 ~18 ~26 ~3 ~18 web 0
fill ~26 ~1 ~19 ~26 ~2 ~19 web 0
fill ~26 ~1 ~20 ~26 ~2 ~20 web 0
fill ~26 ~1 ~21 ~26 ~2 ~21 web 0
fill ~26 ~1 ~22 ~26 ~2 ~22 web 0
fill ~26 ~1 ~23 ~26 ~2 ~23 web 0
fill ~26 ~1 ~24 ~26 ~2 ~24 web 0
fill ~26 ~1 ~25 ~27 ~1 ~25 web 0
fill ~26 ~1 ~26 ~27 ~1 ~26 web 0
fill ~26 ~1 ~27 ~27 ~1 ~27 web 0
fill ~26 ~1 ~28 ~28 ~1 ~28 web 0
fill ~26 ~1 ~29 ~28 ~1 ~29 web 0
fill ~27 ~1 ~16 ~27 ~3 ~16 web 0
fill ~27 ~1 ~17 ~27 ~2 ~17 web 0
fill ~27 ~1 ~30 ~29 ~1 ~30 web 0
fill ~29 ~1 ~31 ~29 ~0 ~31 web 0
fill ~49 ~1 ~110 ~49 ~3 ~110 planks 2
fill ~51 ~1 ~113 ~52 ~1 ~113 planks 0
fill ~52 ~1 ~31 ~53 ~1 ~31 web 0
fill ~52 ~1 ~32 ~52 ~3 ~32 web 0
fill ~52 ~1 ~117 ~52 ~3 ~117 planks 0
fill ~53 ~1 ~30 ~53 ~2 ~30 web 0
fill ~54 ~1 ~23 ~54 ~2 ~23 web 0
fill ~54 ~1 ~24 ~54 ~2 ~24 web 0
fill ~54 ~1 ~25 ~54 ~2 ~25 web 0
fill ~54 ~1 ~26 ~54 ~2 ~26 web 0
fill ~54 ~1 ~27 ~54 ~2 ~27 web 0
fill ~54 ~1 ~28 ~54 ~2 ~28 web 0
fill ~54 ~1 ~29 ~54 ~3 ~29 web 0
fill ~56 ~1 ~31 ~67 ~1 ~31 stone 0
fill ~56 ~1 ~32 ~71 ~1 ~32 stone 0
fill ~56 ~1 ~33 ~71 ~1 ~33 stone 0
fill ~56 ~1 ~34 ~71 ~1 ~34 stone 0
fill ~56 ~1 ~35 ~71 ~1 ~35 stone 0
fill ~57 ~1 ~29 ~68 ~1 ~29 stone 0
fill ~57 ~1 ~30 ~66 ~1 ~30 stone 0
fill ~57 ~1 ~36 ~70 ~1 ~36 stone 0
fill ~58 ~1 ~37 ~70 ~1 ~37 stone 0
fill ~59 ~1 ~38 ~69 ~1 ~38 stone 0
fill ~60 ~1 ~0 ~64 ~1 ~0 stone 6
fill ~60 ~1 ~1 ~60 ~-3 ~1 stone 6
setblock ~60 ~1 ~3 stone 5
fill ~60 ~1 ~5 ~61 ~1 ~5 stone 6
fill ~60 ~1 ~6 ~62 ~1 ~6 stone 5
fill ~60 ~1 ~65 ~69 ~1 ~65 sand 0
fill ~60 ~1 ~66 ~70 ~1 ~66 sand 0
fill ~61 ~1 ~1 ~61 ~1 ~2 stone 5
fill ~61 ~1 ~3 ~61 ~2 ~3 stone 6
setblock ~61 ~1 ~4 stone 5
fill ~61 ~1 ~8 ~61 ~0 ~8 stone 6
fill ~61 ~1 ~64 ~67 ~1 ~64 sand 0
fill ~61 ~1 ~67 ~71 ~1 ~67 sand 0
fill ~61 ~1 ~68 ~71 ~1 ~68 sand 0
fill ~62 ~1 ~1 ~64 ~1 ~1 stone 6
fill ~62 ~1 ~2 ~62 ~1 ~0 stone 6
fill ~62 ~1 ~3 ~63 ~1 ~3 stone 5
setblock ~62 ~1 ~8 stone 5
fill ~62 ~1 ~28 ~67 ~1 ~28 stone 0
fill ~62 ~1 ~63 ~65 ~1 ~63 sand 0
fill ~63 ~1 ~5 ~65 ~1 ~5 stone 6
fill ~63 ~1 ~6 ~63 ~2 ~6 stone 6
fill ~63 ~1 ~69 ~72 ~1 ~69 sand 0
setblock ~64 ~1 ~3 stone 6
fill ~64 ~1 ~6 ~64 ~2 ~6 stone 5
fill ~64 ~1 ~7 ~67 ~1 ~7 stone 6
setblock ~64 ~1 ~9 stone 5
setblock ~64 ~1 ~27 stone 0
fill ~64 ~1 ~39 ~69 ~1 ~39 stone 0
fill ~64 ~1 ~91 ~64 ~4 ~91 planks 3
fill ~65 ~1 ~0 ~75 ~1 ~0 stone 0
fill ~65 ~1 ~1 ~75 ~1 ~1 stone 0
fill ~65 ~1 ~2 ~75 ~1 ~2 stone 0
fill ~65 ~1 ~3 ~75 ~1 ~3 stone 0
fill ~65 ~1 ~4 ~65 ~2 ~4 stone 0
fill ~65 ~1 ~6 ~66 ~1 ~6 stone 6
setblock ~65 ~1 ~8 stone 0
fill ~65 ~1 ~9 ~66 ~1 ~9 stone 6
fill ~65 ~1 ~70 ~71 ~1 ~70 sand 0
setblock ~66 ~1 ~4 stone 6
fill ~66 ~1 ~5 ~66 ~2 ~5 stone 0
fill ~66 ~1 ~26 ~66 ~1 ~40 stone 0
fill ~67 ~1 ~4 ~75 ~1 ~4 stone 0
setblock ~67 ~1 ~5 stone 6
fill ~67 ~1 ~6 ~75 ~1 ~6 stone 0
fill ~67 ~1 ~9 ~68 ~1 ~9 stone 0
fill ~67 ~1 ~30 ~68 ~1 ~30 stone 6
setblock ~67 ~1 ~40 stone 0
fill ~67 ~1 ~71 ~70 ~1 ~71 sand 0
setblock ~67 ~1 ~108 planks 2
fill ~68 ~1 ~5 ~75 ~1 ~5 stone 0
fill ~68 ~1 ~7 ~73 ~1 ~7 stone 0
fill ~68 ~1 ~8 ~70 ~1 ~8 stone 0
setblock ~68 ~1 ~26 stone 5
fill ~68 ~1 ~28 ~70 ~1 ~28 stone 6
setblock ~68 ~1 ~31 stone 6
fill ~69 ~1 ~27 ~70 ~1 ~27 stone 6
fill ~69 ~1 ~29 ~70 ~1 ~29 stone 6
fill ~69 ~1 ~31 ~69 ~2 ~31 stone 0
setblock ~69 ~1 ~110 planks 0
fill ~71 ~1 ~28 ~71 ~1 ~29 stone 0
setblock ~72 ~1 ~29 stone 6
fill ~73 ~1 ~43 ~73 ~3 ~43 end_stone 0
fill ~73 ~1 ~44 ~74 ~1 ~44 end_stone 0
fill ~73 ~1 ~46 ~73 ~2 ~46 end_stone 0
fill ~74 ~1 ~42 ~74 ~2 ~42 brick_block 0
fill ~74 ~1 ~43 ~74 ~1 ~42 brick_block 0
fill ~75 ~1 ~41 ~75 ~1 ~41 brick_block 0
fill ~75 ~1 ~42 ~75 ~1 ~43 end_stone 0
fill ~75 ~1 ~44 ~75 ~1 ~44 brick_block 0
fill ~75 ~1 ~45 ~75 ~1 ~45 end_stone 0
fill ~75 ~1 ~83 ~75 ~3 ~83 planks 2
fill ~1 ~2 ~35 ~1 ~2 ~35 planks 2
fill ~1 ~2 ~36 ~3 ~2 ~36 planks 0
fill ~1 ~2 ~37 ~4 ~2 ~37 planks 0
fill ~1 ~2 ~50 ~6 ~2 ~50 planks 2
fill ~1 ~2 ~51 ~1 ~3 ~51 planks 0
fill ~1 ~2 ~52 ~1 ~4 ~52 planks 2
fill ~2 ~2 ~29 ~3 ~2 ~29 sandstone 0
fill ~2 ~2 ~30 ~9 ~2 ~30 sandstone 0
fill ~2 ~2 ~33 ~3 ~2 ~33 wool 15
fill ~2 ~2 ~34 ~5 ~2 ~34 planks 2
fill ~2 ~2 ~47 ~5 ~2 ~47 planks 0
fill ~2 ~2 ~48 ~5 ~2 ~48 planks 0
fill ~2 ~2 ~49 ~4 ~2 ~49 planks 0
fill ~3 ~2 ~28 ~3 ~3 ~28 sandstone 0
fill ~3 ~2 ~32 ~3 ~3 ~32 wool 15
fill ~3 ~2 ~35 ~3 ~6 ~35 planks 2
fill ~3 ~2 ~51 ~6 ~2 ~51 planks 2
fill ~3 ~2 ~52 ~4 ~2 ~52 wool 15
fill ~3 ~2 ~55 ~10 ~2 ~55 sandstone 0
fill ~3 ~2 ~56 ~4 ~2 ~56 sandstone 0
setblock ~4 ~2 ~15 planks 2
fill ~4 ~2 ~20 ~4 ~4 ~20 planks 0
fill ~4 ~2 ~29 ~6 ~2 ~29 wool 15
fill ~4 ~2 ~31 ~9 ~2 ~31 sandstone 0
fill ~4 ~2 ~32 ~10 ~2 ~32 sandstone 0
fill ~4 ~2 ~33 ~4 ~5 ~33 planks 2
fill ~4 ~2 ~53 ~4 ~3 ~53 wool 15
fill ~4 ~2 ~57 ~4 ~3 ~57 sandstone 0
fill ~5 ~2 ~33 ~11 ~2 ~33 sandstone 0
setblock ~5 ~2 ~36 sandstone 0
fill ~5 ~2 ~37 ~11 ~2 ~37 planks 2
fill ~5 ~2 ~38 ~12 ~2 ~38 planks 2
fill ~5 ~2 ~40 ~5 ~3 ~40 planks 0
fill ~5 ~2 ~52 ~5 ~5 ~52 planks 2
fill ~5 ~2 ~53 ~11 ~2 ~53 sandstone 0
fill ~5 ~2 ~54 ~10 ~2 ~54 sandstone 0
fill ~5 ~2 ~56 ~7 ~2 ~56 wool 15
fill ~5 ~2 ~77 ~5 ~5 ~77 planks 3
fill ~6 ~2 ~27 ~9 ~2 ~27 sandstone 0
setblock ~6 ~2 ~28 wool 15
fill ~6 ~2 ~34 ~13 ~2 ~34 sandstone 0
fill ~6 ~2 ~35 ~14 ~2 ~35 sandstone 0
fill ~6 ~2 ~36 ~10 ~2 ~36 planks 2
fill ~6 ~2 ~39 ~10 ~2 ~39 planks 2
fill ~6 ~2 ~40 ~9 ~2 ~40 planks 2
fill ~6 ~2 ~41 ~7 ~2 ~41 planks 2
fill ~6 ~2 ~45 ~6 ~3 ~45 planks 0
fill ~6 ~2 ~47 ~13 ~2 ~47 planks 2
fill ~6 ~2 ~48 ~12 ~2 ~48 planks 2
setblock ~6 ~2 ~49 sandstone 0
fill ~6 ~2 ~52 ~12 ~2 ~52 sandstone 0
setblock ~7 ~2 ~26 sandstone 0
fill ~7 ~2 ~28 ~10 ~2 ~28 sandstone 0
fill ~7 ~2 ~29 ~7 ~5 ~29 sandstone 0
fill ~7 ~2 ~44 ~8 ~2 ~44 planks 2
fill ~7 ~2 ~45 ~10 ~2 ~45 planks 2
fill ~7 ~2 ~46 ~11 ~2 ~46 planks 2
fill ~7 ~2 ~49 ~11 ~2 ~49 planks 2
fill ~7 ~2 ~50 ~15 ~2 ~50 sandstone 0
fill ~7 ~2 ~51 ~14 ~2 ~51 sandstone 0
setblock ~7 ~2 ~57 wool 15
fill ~7 ~2 ~58 ~10 ~2 ~58 sandstone 0
fill ~8 ~2 ~56 ~8 ~5 ~56 sandstone 0
fill ~8 ~2 ~57 ~11 ~2 ~57 sandstone 0
setblock ~8 ~2 ~59 sandstone 0
setblock ~9 ~2 ~20 planks 0
fill ~10 ~2 ~29 ~12 ~2 ~29 sandstone 0
setblock ~10 ~2 ~31 end_stone 0
fill ~11 ~2 ~30 ~11 ~2 ~31 sandstone 0
fill ~11 ~2 ~32 ~14 ~2 ~32 end_stone 0
fill ~11 ~2 ~36 ~13 ~2 ~36 sandstone 0
setblock ~11 ~2 ~39 sandstone 0
setblock ~11 ~2 ~54 end_stone 0
fill ~11 ~2 ~56 ~13 ~2 ~56 sandstone 0
fill ~12 ~2 ~30 ~12 ~2 ~33 end_stone 0
fill ~12 ~2 ~37 ~12 ~3 ~37 sandstone 0
setblock ~12 ~2 ~46 sandstone 0
fill ~12 ~2 ~49 ~14 ~2 ~49 sandstone 0
fill ~12 ~2 ~54 ~12 ~5 ~54 sandstone 0
fill ~12 ~2 ~55 ~12 ~2 ~54 sandstone 0
fill ~13 ~2 ~30 ~13 ~2 ~31 sandstone 0
fill ~13 ~2 ~33 ~14 ~2 ~33 end_stone 0
fill ~13 ~2 ~48 ~13 ~3 ~48 sandstone 0
fill ~13 ~2 ~52 ~15 ~2 ~52 end_stone 0
fill ~13 ~2 ~53 ~15 ~2 ~53 end_stone 0
fill ~13 ~2 ~54 ~13 ~2 ~55 end_stone 0
fill ~14 ~2 ~10 ~14 ~5 ~10 planks 2
fill ~14 ~2 ~54 ~14 ~2 ~55 sandstone 0
fill ~17 ~2 ~5 ~17 ~7 ~5 planks 2
setblock ~18 ~2 ~11 planks 0
fill ~19 ~2 ~5 ~19 ~3 ~5 planks 2
fill ~25 ~2 ~18 ~25 ~4 ~18 web 0
fill ~25 ~2 ~19 ~25 ~4 ~19 web 0
fill ~25 ~2 ~20 ~25 ~3 ~20 web 0
fill ~25 ~2 ~21 ~25 ~3 ~21 web 0
fill ~25 ~2 ~22 ~25 ~3 ~22 web 0
fill ~25 ~2 ~23 ~25 ~3 ~23 web 0
fill ~25 ~2 ~24 ~25 ~3 ~24 web 0
fill ~25 ~2 ~25 ~26 ~2 ~25 web 0
fill ~25 ~2 ~26 ~26 ~2 ~26 web 0
fill ~25 ~2 ~27 ~26 ~2 ~27 web 0
fill ~25 ~2 ~28 ~26 ~2 ~28 web 0
fill ~25 ~2 ~29 ~27 ~2 ~29 web 0
fill ~26 ~2 ~16 ~26 ~4 ~16 web 0
fill ~26 ~2 ~17 ~26 ~3 ~17 web 0
fill ~27 ~2 ~15 ~27 ~4 ~15 web 0
fill ~27 ~2 ~30 ~27 ~1 ~30 web 0
fill ~50 ~2 ~115 ~50 ~7 ~115 planks 2
fill ~51 ~2 ~113 ~52 ~2 ~113 planks 0
fill ~52 ~2 ~31 ~54 ~2 ~31 web 0
fill ~52 ~2 ~33 ~53 ~2 ~33 web 0
fill ~52 ~2 ~34 ~52 ~4 ~34 web 0
fill ~53 ~2 ~32 ~53 ~4 ~32 web 0
fill ~54 ~2 ~30 ~54 ~3 ~30 web 0
fill ~55 ~2 ~24 ~55 ~3 ~24 web 0
fill ~55 ~2 ~25 ~55 ~3 ~25 web 0
fill ~55 ~2 ~26 ~55 ~3 ~26 web 0
fill ~55 ~2 ~27 ~55 ~3 ~27 web 0
fill ~55 ~2 ~28 ~55 ~4 ~28 web 0
fill ~55 ~2 ~29 ~55 ~4 ~29 web 0
fill ~57 ~2 ~33 ~70 ~2 ~33 stone 0
fill ~57 ~2 ~34 ~70 ~2 ~34 stone 0
fill ~58 ~2 ~31 ~69 ~2 ~31 stone 0
fill ~58 ~2 ~32 ~70 ~2 ~32 stone 0
fill ~58 ~2 ~35 ~70 ~2 ~35 stone 0
fill ~58 ~2 ~36 ~70 ~2 ~36 stone 0
fill ~59 ~2 ~30 ~66 ~2 ~30 stone 0
fill ~59 ~2 ~37 ~69 ~2 ~37 stone 0
fill ~60 ~2 ~92 ~60 ~5 ~92 planks 2
fill ~61 ~2 ~2 ~63 ~2 ~2 stone 5
setblock ~61 ~2 ~4 stone 6
fill ~62 ~2 ~0 ~64 ~2 ~0 stone 6
fill ~62 ~2 ~1 ~63 ~2 ~1 stone 6
setblock ~62 ~2 ~3 stone 6
setblock ~62 ~2 ~6 stone 5
fill ~63 ~2 ~3 ~63 ~3 ~3 stone 5
fill ~63 ~2 ~4 ~63 ~3 ~4 stone 5
fill ~63 ~2 ~5 ~63 ~-3 ~5 stone 6
fill ~64 ~2 ~1 ~75 ~2 ~1 stone 0
fill ~64 ~2 ~3 ~64 ~3 ~3 stone 0
fill ~64 ~2 ~4 ~64 ~3 ~4 stone 6
setblock ~64 ~2 ~5 stone 5
fill ~64 ~2 ~7 ~67 ~2 ~7 stone 6
setblock ~64 ~2 ~9 stone 6
fill ~64 ~2 ~29 ~68 ~2 ~29 stone 0
fill ~64 ~2 ~38 ~69 ~2 ~38 stone 0
fill ~65 ~2 ~0 ~75 ~2 ~0 stone 0
fill ~65 ~2 ~2 ~65 ~3 ~2 stone 0
setblock ~65 ~2 ~3 stone 6
setblock ~65 ~2 ~5 stone 0
fill ~65 ~2 ~6 ~68 ~2 ~6 stone 6
fill ~65 ~2 ~8 ~66 ~2 ~8 stone 6
fill ~65 ~2 ~9 ~66 ~2 ~9 stone 0
fill ~65 ~2 ~39 ~68 ~2 ~39 stone 0
fill ~65 ~2 ~90 ~65 ~5 ~90 planks 0
setblock ~66 ~2 ~2 stone 6
fill ~66 ~2 ~3 ~66 ~4 ~3 stone 0
fill ~66 ~2 ~4 ~66 ~4 ~4 stone 0
fill ~67 ~2 ~2 ~75 ~2 ~2 stone 0
fill ~67 ~2 ~3 ~67 ~4 ~3 stone 6
fill ~67 ~2 ~4 ~67 ~3 ~4 stone 6
fill ~67 ~2 ~5 ~75 ~2 ~5 stone 0
setblock ~67 ~2 ~8 stone 0
setblock ~67 ~2 ~28 stone 0
fill ~67 ~2 ~30 ~67 ~0 ~30 stone 6
fill ~68 ~2 ~3 ~75 ~2 ~3 stone 0
fill ~68 ~2 ~4 ~75 ~2 ~4 stone 0
fill ~68 ~2 ~7 ~73 ~2 ~7 stone 0
setblock ~68 ~2 ~8 stone 6
setblock ~68 ~2 ~30 stone 0
fill ~69 ~2 ~6 ~75 ~2 ~6 stone 0
fill ~69 ~2 ~8 ~70 ~2 ~8 stone 0
fill ~69 ~2 ~109 ~69 ~13 ~109 planks 2
fill ~70 ~2 ~109 ~70 ~2 ~110 planks 0
fill ~71 ~2 ~107 ~71 ~8 ~107 planks 0
fill ~73 ~2 ~44 ~75 ~2 ~44 end_stone 0
fill ~73 ~2 ~45 ~73 ~3 ~45 end_stone 0
setblock ~74 ~2 ~41 brick_block 0
fill ~74 ~2 ~43 ~74 ~4 ~43 end_stone 0
fill ~74 ~2 ~83 ~74 ~7 ~83 planks 2
setblock ~75 ~2 ~40 brick_block 0
fill ~75 ~2 ~41 ~75 ~4 ~41 end_stone 0
fill ~75 ~2 ~42 ~75 ~2 ~42 brick_block 0
setblock ~75 ~2 ~43 brick_block 0
fill ~75 ~2 ~45 ~75 ~2 ~45 wool 15
setblock ~75 ~2 ~46 wool 15
fill ~75 ~2 ~48 ~75 ~2 ~48 sandstone 0
fill ~75 ~2 ~49 ~75 ~3 ~49 sandstone 0
fill ~1 ~3 ~30 ~3 ~3 ~30 sandstone 0
fill ~1 ~3 ~31 ~1 ~3 ~30 sandstone 0
fill ~1 ~3 ~32 ~1 ~5 ~32 planks 2
fill ~1 ~3 ~33 ~6 ~3 ~33 planks 2
fill ~1 ~3 ~34 ~6 ~3 ~34 planks 2
fill ~1 ~3 ~35 ~1 ~3 ~36 planks 0
fill ~1 ~3 ~103 ~1 ~3 ~103 planks 3
fill ~2 ~3 ~29 ~4 ~3 ~29 sandstone 0
fill ~2 ~3 ~31 ~4 ~3 ~31 planks 2
setblock ~2 ~3 ~32 wool 15
fill ~2 ~3 ~36 ~3 ~3 ~36 planks 0
fill ~2 ~3 ~37 ~5 ~3 ~37 planks 0
fill ~2 ~3 ~49 ~4 ~3 ~49 planks 0
fill ~2 ~3 ~50 ~2 ~3 ~49 planks 0
fill ~2 ~3 ~51 ~7 ~3 ~51 planks 2
fill ~2 ~3 ~52 ~7 ~3 ~52 planks 2
fill ~2 ~3 ~53 ~2 ~5 ~53 planks 2
fill ~2 ~3 ~54 ~2 ~3 ~55 sandstone 0
fill ~3 ~3 ~47 ~5 ~3 ~47 planks 0
fill ~3 ~3 ~48 ~6 ~3 ~48 planks 0
setblock ~3 ~3 ~53 wool 15
fill ~3 ~3 ~54 ~5 ~3 ~54 planks 2
fill ~3 ~3 ~55 ~4 ~3 ~55 sandstone 0
fill ~3 ~3 ~56 ~5 ~3 ~56 sandstone 0
fill ~3 ~3 ~107 ~3 ~5 ~107 planks 2
fill ~4 ~3 ~14 ~5 ~3 ~14 planks 2
setblock ~4 ~3 ~21 planks 0
fill ~4 ~3 ~28 ~10 ~3 ~28 sandstone 0
fill ~4 ~3 ~30 ~4 ~5 ~30 planks 2
fill ~4 ~3 ~32 ~7 ~3 ~32 planks 2
fill ~4 ~3 ~50 ~4 ~6 ~50 planks 2
fill ~4 ~3 ~78 ~4 ~6 ~78 planks 0
fill ~5 ~3 ~29 ~5 ~5 ~29 planks 2
fill ~5 ~3 ~30 ~5 ~4 ~30 sandstone 0
fill ~5 ~3 ~31 ~5 ~3 ~30 sandstone 0
fill ~5 ~3 ~36 ~11 ~3 ~36 planks 2
fill ~5 ~3 ~38 ~5 ~4 ~38 planks 2
fill ~5 ~3 ~53 ~8 ~3 ~53 planks 2
fill ~5 ~3 ~55 ~5 ~5 ~55 planks 2
fill ~5 ~3 ~57 ~11 ~3 ~57 sandstone 0
fill ~6 ~3 ~27 ~9 ~3 ~27 sandstone 0
setblock ~6 ~3 ~29 sandstone 0
fill ~6 ~3 ~30 ~6 ~3 ~37 planks 2
fill ~6 ~3 ~38 ~6 ~3 ~39 planks 0
fill ~6 ~3 ~40 ~7 ~3 ~40 planks 2
fill ~6 ~3 ~47 ~6 ~4 ~47 planks 2
fill ~6 ~3 ~49 ~12 ~3 ~49 planks 2
fill ~6 ~3 ~54 ~6 ~3 ~55 sandstone 0
fill ~6 ~3 ~56 ~6 ~5 ~56 planks 2
fill ~7 ~3 ~30 ~10 ~3 ~30 sandstone 0
fill ~7 ~3 ~31 ~12 ~3 ~31 sandstone 0
fill ~7 ~3 ~33 ~14 ~3 ~33 sandstone 0
fill ~7 ~3 ~34 ~8 ~3 ~34 sandstone 0
fill ~7 ~3 ~35 ~7 ~3 ~33 sandstone 0
fill ~7 ~3 ~37 ~11 ~3 ~37 planks 2
fill ~7 ~3 ~38 ~11 ~3 ~38 planks 2
fill ~7 ~3 ~39 ~10 ~3 ~39 planks 2
fill ~7 ~3 ~45 ~8 ~3 ~45 planks 2
fill ~7 ~3 ~46 ~7 ~4 ~46 planks 0
fill ~7 ~3 ~47 ~7 ~3 ~46 planks 0
fill ~7 ~3 ~48 ~12 ~3 ~48 planks 2
fill ~7 ~3 ~50 ~7 ~7 ~50 planks 2
fill ~7 ~3 ~54 ~7 ~6 ~54 planks 2
fill ~7 ~3 ~55 ~7 ~3 ~48 planks 2
setblock ~7 ~3 ~56 sandstone 0
fill ~7 ~3 ~58 ~10 ~3 ~58 sandstone 0
fill ~8 ~3 ~21 ~9 ~3 ~21 planks 0
fill ~8 ~3 ~32 ~10 ~3 ~32 sandstone 0
fill ~8 ~3 ~35 ~8 ~7 ~35 planks 2
fill ~8 ~3 ~46 ~11 ~3 ~46 planks 2
fill ~8 ~3 ~47 ~12 ~3 ~47 planks 2
fill ~8 ~3 ~50 ~8 ~3 ~52 sandstone 0
fill ~8 ~3 ~54 ~13 ~3 ~54 sandstone 0
fill ~8 ~3 ~55 ~11 ~3 ~55 sandstone 0
setblock ~9 ~3 ~17 planks 0
fill ~9 ~3 ~34 ~9 ~4 ~34 planks 2
fill ~9 ~3 ~35 ~13 ~3 ~35 sandstone 0
fill ~9 ~3 ~50 ~9 ~7 ~50 planks 2
fill ~9 ~3 ~51 ~9 ~3 ~58 sandstone 0
fill ~9 ~3 ~76 ~9 ~6 ~76 planks 2
fill ~10 ~3 ~29 ~11 ~3 ~29 sandstone 0
fill ~10 ~3 ~34 ~13 ~3 ~34 sandstone 0
fill ~10 ~3 ~50 ~14 ~3 ~50 sandstone 0
fill ~10 ~3 ~51 ~10 ~4 ~51 planks 2
fill ~10 ~3 ~52 ~15 ~3 ~52 sandstone 0
fill ~10 ~3 ~53 ~11 ~3 ~53 sandstone 0
setblock ~11 ~3 ~30 end_stone 0
fill ~11 ~3 ~32 ~11 ~1 ~32 end_stone 0
fill ~11 ~3 ~51 ~14 ~3 ~51 sandstone 0
fill ~11 ~3 ~56 ~12 ~3 ~56 sandstone 0
setblock ~12 ~3 ~29 end_stone 0
fill ~12 ~3 ~30 ~12 ~4 ~30 sandstone 0
fill ~12 ~3 ~32 ~13 ~3 ~32 sandstone 0
fill ~12 ~3 ~36 ~13 ~3 ~36 sandstone 0
setblock ~12 ~3 ~38 sandstone 0
setblock ~12 ~3 ~55 end_stone 0
setblock ~13 ~3 ~31 end_stone 0
setblock ~13 ~3 ~47 sandstone 0
fill ~13 ~3 ~49 ~14 ~3 ~49 sandstone 0
fill ~13 ~3 ~53 ~14 ~3 ~53 sandstone 0
fill ~13 ~3 ~55 ~13 ~4 ~55 sandstone 0
setblock ~13 ~3 ~56 end_stone 0
setblock ~14 ~3 ~54 end_stone 0
fill ~19 ~3 ~10 ~19 ~3 ~11 planks 0
fill ~20 ~3 ~6 ~20 ~4 ~6 planks 2
fill ~24 ~3 ~19 ~24 ~5 ~19 web 0
fill ~24 ~3 ~20 ~24 ~5 ~20 web 0
fill ~24 ~3 ~21 ~24 ~4 ~21 web 0
fill ~24 ~3 ~22 ~24 ~4 ~22 web 0
fill ~24 ~3 ~23 ~24 ~4 ~23 web 0
fill ~24 ~3 ~24 ~24 ~4 ~24 web 0
fill ~24 ~3 ~25 ~25 ~3 ~25 web 0
fill ~24 ~3 ~26 ~25 ~3 ~26 web 0
fill ~24 ~3 ~27 ~25 ~3 ~27 web 0
fill ~24 ~3 ~28 ~25 ~3 ~28 web 0
fill ~25 ~3 ~16 ~25 ~5 ~16 web 0
fill ~25 ~3 ~17 ~25 ~5 ~17 web 0
fill ~25 ~3 ~29 ~25 ~4 ~29 web 0
fill ~26 ~3 ~15 ~26 ~5 ~15 web 0
fill ~27 ~3 ~14 ~27 ~4 ~14 web 0
fill ~48 ~3 ~109 ~48 ~4 ~109 planks 2
fill ~49 ~3 ~117 ~49 ~5 ~117 planks 3
fill ~51 ~3 ~113 ~52 ~3 ~113 planks 0
fill ~52 ~3 ~33 ~53 ~3 ~33 web 0
fill ~52 ~3 ~35 ~52 ~4 ~35 web 0
fill ~52 ~3 ~118 ~52 ~4 ~118 planks 0
fill ~53 ~3 ~31 ~55 ~3 ~31 web 0
fill ~53 ~3 ~34 ~53 ~5 ~34 web 0
fill ~53 ~3 ~112 ~53 ~8 ~112 planks 0
fill ~54 ~3 ~32 ~54 ~5 ~32 web 0
fill ~55 ~3 ~30 ~55 ~5 ~30 web 0
fill ~55 ~3 ~116 ~55 ~6 ~116 planks 2
fill ~56 ~3 ~24 ~56 ~4 ~24 web 0
fill ~56 ~3 ~25 ~56 ~4 ~25 web 0
fill ~56 ~3 ~26 ~56 ~4 ~26 web 0
fill ~56 ~3 ~27 ~56 ~5 ~27 web 0
fill ~56 ~3 ~28 ~56 ~5 ~28 web 0
fill ~60 ~3 ~35 ~68 ~3 ~35 stone 0
fill ~61 ~3 ~33 ~67 ~3 ~33 stone 0
fill ~61 ~3 ~34 ~67 ~3 ~34 stone 0
fill ~61 ~3 ~36 ~68 ~3 ~36 stone 0
fill ~62 ~3 ~32 ~67 ~3 ~32 stone 0
fill ~63 ~3 ~2 ~75 ~3 ~2 stone 0
fill ~64 ~3 ~0 ~75 ~3 ~0 stone 0
fill ~64 ~3 ~1 ~75 ~3 ~1 stone 0
fill ~64 ~3 ~5 ~66 ~3 ~5 stone 6
fill ~64 ~3 ~6 ~68 ~3 ~6 stone 6
fill ~64 ~3 ~31 ~66 ~3 ~31 stone 0
fill ~64 ~3 ~37 ~68 ~3 ~37 stone 0
fill ~64 ~3 ~88 ~64 ~7 ~88 planks 2
fill ~65 ~3 ~3 ~65 ~4 ~3 stone 0
setblock ~65 ~3 ~4 stone 6
fill ~65 ~3 ~7 ~66 ~3 ~7 stone 0
setblock ~66 ~3 ~8 stone 6
fill ~66 ~3 ~38 ~67 ~3 ~38 stone 0
fill ~67 ~3 ~5 ~75 ~3 ~5 stone 0
setblock ~67 ~3 ~7 stone 6
setblock ~67 ~3 ~110 planks 2
fill ~68 ~3 ~3 ~75 ~3 ~3 stone 0
setblock ~68 ~3 ~4 stone 6
fill ~68 ~3 ~7 ~72 ~3 ~7 stone 0
fill ~69 ~3 ~4 ~75 ~3 ~4 stone 0
fill ~69 ~3 ~6 ~74 ~3 ~6 stone 0
setblock ~70 ~3 ~107 planks 0
fill ~70 ~3 ~110 ~70 ~6 ~110 planks 0
fill ~73 ~3 ~44 ~73 ~4 ~44 end_stone 0
setblock ~73 ~3 ~46 sandstone 0
fill ~74 ~3 ~41 ~74 ~3 ~43 end_stone 0
setblock ~74 ~3 ~44 sandstone 0
setblock ~75 ~3 ~40 sandstone 0
fill ~75 ~3 ~42 ~75 ~3 ~43 end_stone 0
fill ~75 ~3 ~44 ~75 ~3 ~44 wool 15
fill ~75 ~3 ~48 ~75 ~3 ~48 sandstone 0
fill ~1 ~4 ~31 ~7 ~4 ~31 planks 2
fill ~1 ~4 ~33 ~10 ~4 ~33 planks 2
fill ~1 ~4 ~34 ~1 ~5 ~34 planks 2
fill ~1 ~4 ~35 ~1 ~4 ~31 planks 2
fill ~1 ~4 ~103 ~1 ~7 ~103 planks 3
setblock ~2 ~4 ~20 planks 2
fill ~2 ~4 ~29 ~2 ~0 ~29 sandstone 0
fill ~2 ~4 ~30 ~2 ~4 ~29 sandstone 0
fill ~2 ~4 ~32 ~6 ~4 ~32 planks 2
fill ~2 ~4 ~35 ~2 ~4 ~37 planks 0
fill ~2 ~4 ~50 ~2 ~4 ~54 planks 2
fill ~3 ~4 ~20 ~3 ~4 ~21 planks 0
fill ~3 ~4 ~29 ~6 ~4 ~29 planks 2
fill ~3 ~4 ~30 ~3 ~5 ~30 planks 2
fill ~3 ~4 ~34 ~11 ~4 ~34 planks 2
fill ~3 ~4 ~36 ~3 ~4 ~38 planks 0
fill ~3 ~4 ~48 ~5 ~4 ~48 planks 0
fill ~3 ~4 ~49 ~4 ~4 ~49 planks 0
fill ~3 ~4 ~50 ~3 ~4 ~48 planks 0
fill ~3 ~4 ~52 ~11 ~4 ~52 planks 2
fill ~3 ~4 ~53 ~7 ~4 ~53 planks 2
fill ~3 ~4 ~54 ~8 ~4 ~54 planks 2
fill ~3 ~4 ~55 ~3 ~2 ~55 sandstone 0
fill ~3 ~4 ~56 ~3 ~0 ~56 sandstone 0
fill ~4 ~4 ~14 ~4 ~9 ~14 planks 2
fill ~4 ~4 ~37 ~4 ~5 ~37 planks 0
fill ~4 ~4 ~47 ~5 ~4 ~47 planks 0
fill ~4 ~4 ~51 ~12 ~4 ~51 planks 2
fill ~4 ~4 ~55 ~4 ~5 ~55 planks 2
fill ~4 ~4 ~56 ~7 ~4 ~56 planks 2
fill ~5 ~4 ~28 ~6 ~4 ~28 planks 2
fill ~5 ~4 ~36 ~12 ~4 ~36 planks 2
fill ~5 ~4 ~37 ~12 ~4 ~37 planks 2
fill ~5 ~4 ~39 ~5 ~5 ~39 planks 2
fill ~5 ~4 ~80 ~5 ~8 ~80 planks 2
fill ~6 ~4 ~27 ~8 ~4 ~27 sandstone 0
setblock ~6 ~4 ~30 sandstone 0
fill ~6 ~4 ~35 ~9 ~4 ~35 planks 2
fill ~6 ~4 ~38 ~11 ~4 ~38 planks 2
fill ~6 ~4 ~39 ~6 ~4 ~40 planks 0
fill ~6 ~4 ~46 ~6 ~5 ~46 planks 2
fill ~6 ~4 ~48 ~13 ~4 ~48 planks 2
fill ~6 ~4 ~49 ~13 ~4 ~49 planks 2
fill ~6 ~4 ~55 ~7 ~4 ~55 sandstone 0
fill ~6 ~4 ~57 ~7 ~4 ~57 planks 2
fill ~7 ~4 ~28 ~10 ~4 ~28 sandstone 0
fill ~7 ~4 ~30 ~8 ~4 ~30 planks 2
fill ~7 ~4 ~32 ~7 ~5 ~32 sandstone 0
setblock ~7 ~4 ~39 sandstone 0
setblock ~7 ~4 ~40 planks 2
setblock ~7 ~4 ~45 planks 0
fill ~7 ~4 ~47 ~12 ~4 ~47 planks 2
fill ~7 ~4 ~58 ~9 ~4 ~58 sandstone 0
fill ~8 ~4 ~16 ~9 ~4 ~16 planks 0
fill ~8 ~4 ~31 ~12 ~4 ~31 sandstone 0
fill ~8 ~4 ~32 ~8 ~7 ~32 planks 2
fill ~8 ~4 ~39 ~10 ~4 ~39 planks 2
setblock ~8 ~4 ~45 planks 2
setblock ~8 ~4 ~46 sandstone 0
fill ~8 ~4 ~50 ~8 ~7 ~50 planks 2
fill ~8 ~4 ~53 ~8 ~5 ~53 sandstone 0
fill ~8 ~4 ~55 ~9 ~4 ~55 planks 2
fill ~8 ~4 ~57 ~11 ~4 ~57 sandstone 0
fill ~9 ~4 ~21 ~9 ~6 ~21 planks 0
fill ~9 ~4 ~30 ~12 ~4 ~30 sandstone 0
fill ~9 ~4 ~32 ~13 ~4 ~32 sandstone 0
fill ~9 ~4 ~46 ~11 ~4 ~46 planks 2
fill ~9 ~4 ~53 ~9 ~7 ~53 planks 2
fill ~9 ~4 ~54 ~13 ~4 ~54 sandstone 0
fill ~10 ~4 ~29 ~11 ~4 ~29 sandstone 0
setblock ~10 ~4 ~35 sandstone 0
fill ~10 ~4 ~50 ~10 ~7 ~50 planks 2
fill ~10 ~4 ~53 ~14 ~4 ~53 sandstone 0
fill ~10 ~4 ~55 ~13 ~4 ~55 sandstone 0
setblock ~11 ~4 ~18 planks 2
fill ~11 ~4 ~33 ~13 ~4 ~33 sandstone 0
fill ~11 ~4 ~35 ~12 ~4 ~35 planks 2
setblock ~11 ~4 ~50 sandstone 0
fill ~11 ~4 ~56 ~12 ~4 ~56 sandstone 0
fill ~12 ~4 ~34 ~13 ~4 ~34 sandstone 0
fill ~12 ~4 ~50 ~13 ~4 ~50 planks 2
fill ~12 ~4 ~52 ~14 ~4 ~52 sandstone 0
fill ~13 ~4 ~51 ~14 ~4 ~51 sandstone 0
setblock ~14 ~4 ~11 planks 2
setblock ~19 ~4 ~6 planks 0
fill ~19 ~4 ~11 ~19 ~6 ~11 planks 0
fill ~23 ~4 ~20 ~23 ~7 ~20 web 0
fill ~23 ~4 ~21 ~23 ~6 ~21 web 0
fill ~23 ~4 ~22 ~23 ~6 ~22 web 0
fill ~23 ~4 ~23 ~23 ~6 ~23 web 0
fill ~23 ~4 ~24 ~23 ~6 ~24 web 0
fill ~23 ~4 ~25 ~24 ~4 ~25 web 0
fill ~23 ~4 ~26 ~24 ~4 ~26 web 0
fill ~23 ~4 ~27 ~24 ~4 ~27 web 0
fill ~24 ~4 ~17 ~24 ~6 ~17 web 0
fill ~24 ~4 ~18 ~24 ~6 ~18 web 0
fill ~24 ~4 ~28 ~25 ~4 ~28 web 0
fill ~25 ~4 ~15 ~25 ~6 ~15 web 0
fill ~26 ~4 ~13 ~26 ~7 ~13 web 0
fill ~26 ~4 ~14 ~26 ~6 ~14 web 0
fill ~51 ~4 ~113 ~51 ~13 ~113 planks 0
fill ~52 ~4 ~119 ~52 ~5 ~119 planks 0
fill ~53 ~4 ~33 ~54 ~4 ~33 web 0
fill ~53 ~4 ~35 ~53 ~7 ~35 web 0
fill ~54 ~4 ~31 ~55 ~4 ~31 web 0
fill ~54 ~4 ~34 ~54 ~7 ~34 web 0
fill ~55 ~4 ~32 ~55 ~6 ~32 web 0
fill ~56 ~4 ~29 ~56 ~6 ~29 web 0
fill ~56 ~4 ~30 ~56 ~6 ~30 web 0
fill ~57 ~4 ~25 ~57 ~6 ~25 web 0
fill ~57 ~4 ~26 ~57 ~6 ~26 web 0
fill ~57 ~4 ~27 ~57 ~7 ~27 web 0
fill ~65 ~4 ~92 ~65 ~7 ~92 planks 3
fill ~66 ~4 ~0 ~75 ~4 ~0 stone 0
fill ~66 ~4 ~1 ~75 ~4 ~1 stone 0
fill ~66 ~4 ~2 ~75 ~4 ~2 stone 0
fill ~66 ~4 ~109 ~66 ~4 ~110 planks 2
fill ~67 ~4 ~4 ~75 ~4 ~4 stone 0
fill ~67 ~4 ~5 ~75 ~4 ~5 stone 0
fill ~68 ~4 ~3 ~75 ~4 ~3 stone 0
fill ~69 ~4 ~6 ~73 ~4 ~6 stone 0
setblock ~71 ~4 ~108 planks 0
setblock ~73 ~4 ~43 sandstone 0
setblock ~74 ~4 ~41 sandstone 0
setblock ~74 ~4 ~42 end_stone 0
setblock ~74 ~4 ~44 end_stone 0
fill ~75 ~4 ~40 ~75 ~4 ~40 end_stone 0
fill ~75 ~4 ~42 ~75 ~4 ~42 sandstone 0
fill ~75 ~4 ~43 ~75 ~4 ~43 sandstone 0
fill ~75 ~4 ~81 ~75 ~10 ~81 planks 0
fill ~1 ~5 ~21 ~2 ~5 ~21 planks 2
fill ~1 ~5 ~23 ~1 ~5 ~23 planks 0
fill ~1 ~5 ~33 ~5 ~5 ~33 planks 2
fill ~1 ~5 ~101 ~1 ~9 ~101 planks 0
fill ~2 ~5 ~31 ~9 ~5 ~31 planks 2
fill ~2 ~5 ~32 ~6 ~5 ~32 planks 2
fill ~2 ~5 ~34 ~8 ~5 ~34 planks 2
fill ~2 ~5 ~35 ~2 ~6 ~35 planks 2
fill ~2 ~5 ~36 ~11 ~5 ~36 planks 2
fill ~2 ~5 ~51 ~9 ~5 ~51 planks 2
fill ~2 ~5 ~52 ~6 ~5 ~52 planks 2
fill ~3 ~5 ~21 ~3 ~6 ~21 planks 0
setblock ~3 ~5 ~37 planks 0
fill ~3 ~5 ~49 ~12 ~5 ~49 planks 2
fill ~3 ~5 ~50 ~3 ~6 ~50 planks 2
fill ~3 ~5 ~53 ~7 ~5 ~53 planks 2
fill ~3 ~5 ~54 ~10 ~5 ~54 planks 2
setblock ~4 ~5 ~29 sandstone 0
fill ~4 ~5 ~48 ~6 ~5 ~48 planks 0
fill ~4 ~5 ~76 ~4 ~8 ~76 planks 3
fill ~4 ~5 ~108 ~4 ~6 ~108 planks 2
fill ~5 ~5 ~30 ~8 ~5 ~30 planks 2
fill ~5 ~5 ~37 ~5 ~5 ~38 planks 0
fill ~5 ~5 ~47 ~7 ~5 ~47 planks 0
setblock ~5 ~5 ~56 sandstone 0
fill ~6 ~5 ~28 ~7 ~5 ~28 sandstone 0
setblock ~6 ~5 ~29 planks 2
setblock ~6 ~5 ~33 sandstone 0
fill ~6 ~5 ~35 ~10 ~5 ~35 planks 2
fill ~6 ~5 ~37 ~10 ~5 ~37 planks 2
setblock ~6 ~5 ~38 planks 0
fill ~6 ~5 ~39 ~8 ~5 ~39 planks 2
fill ~6 ~5 ~55 ~9 ~5 ~55 planks 2
fill ~7 ~5 ~33 ~11 ~5 ~33 planks 2
fill ~7 ~5 ~38 ~9 ~5 ~38 planks 2
fill ~7 ~5 ~46 ~9 ~5 ~46 planks 2
fill ~7 ~5 ~48 ~11 ~5 ~48 planks 2
setblock ~7 ~5 ~52 sandstone 0
setblock ~7 ~5 ~56 planks 2
fill ~7 ~5 ~57 ~8 ~5 ~57 sandstone 0
fill ~8 ~5 ~47 ~10 ~5 ~47 planks 2
fill ~8 ~5 ~52 ~12 ~5 ~52 planks 2
fill ~9 ~5 ~16 ~9 ~10 ~16 planks 0
setblock ~9 ~5 ~28 sandstone 0
fill ~9 ~5 ~30 ~11 ~5 ~30 sandstone 0
fill ~9 ~5 ~32 ~9 ~6 ~32 planks 2
setblock ~9 ~5 ~34 sandstone 0
fill ~10 ~5 ~4 ~10 ~8 ~4 planks 2
fill ~10 ~5 ~19 ~11 ~5 ~19 planks 2
setblock ~10 ~5 ~21 planks 0
fill ~10 ~5 ~29 ~10 ~2 ~29 sandstone 0
fill ~10 ~5 ~31 ~12 ~5 ~31 sandstone 0
fill ~10 ~5 ~32 ~13 ~5 ~32 sandstone 0
setblock ~10 ~5 ~34 planks 2
setblock ~10 ~5 ~51 sandstone 0
fill ~10 ~5 ~53 ~10 ~6 ~53 planks 2
fill ~10 ~5 ~55 ~12 ~5 ~55 sandstone 0
setblock ~10 ~5 ~57 sandstone 0
fill ~11 ~5 ~34 ~11 ~5 ~35 sandstone 0
fill ~11 ~5 ~50 ~11 ~6 ~50 planks 2
fill ~11 ~5 ~51 ~11 ~5 ~48 planks 2
fill ~11 ~5 ~53 ~14 ~5 ~53 sandstone 0
fill ~11 ~5 ~54 ~11 ~6 ~54 sandstone 0
fill ~11 ~5 ~56 ~11 ~2 ~56 sandstone 0
setblock ~12 ~5 ~33 sandstone 0
fill ~12 ~5 ~34 ~12 ~5 ~35 planks 2
fill ~12 ~5 ~50 ~12 ~5 ~51 sandstone 0
fill ~13 ~5 ~10 ~13 ~5 ~11 planks 2
fill ~13 ~5 ~50 ~13 ~5 ~51 planks 2
setblock ~13 ~5 ~52 sandstone 0
setblock ~13 ~5 ~54 sandstone 0
setblock ~16 ~5 ~6 planks 0
fill ~20 ~5 ~6 ~20 ~8 ~6 planks 0
fill ~20 ~5 ~7 ~20 ~5 ~6 planks 0
setblock ~20 ~5 ~11 planks 0
fill ~23 ~5 ~18 ~23 ~8 ~18 web 0
fill ~23 ~5 ~19 ~23 ~7 ~19 web 0
fill ~23 ~5 ~25 ~23 ~6 ~25 web 0
fill ~23 ~5 ~26 ~23 ~4 ~26 web 0
fill ~23 ~5 ~27 ~24 ~5 ~27 web 0
fill ~24 ~5 ~15 ~24 ~8 ~15 web 0
fill ~24 ~5 ~16 ~24 ~7 ~16 web 0
fill ~24 ~5 ~28 ~24 ~3 ~28 web 0
fill ~25 ~5 ~14 ~25 ~7 ~14 web 0
fill ~26 ~5 ~12 ~26 ~8 ~12 web 0
fill ~38 ~5 ~0 ~41 ~5 ~0 web 0
fill ~38 ~5 ~1 ~40 ~5 ~1 web 0
fill ~39 ~5 ~2 ~39 ~14 ~2 web 0
setblock ~47 ~5 ~108 planks 2
fill ~48 ~5 ~118 ~48 ~6 ~118 planks 3
fill ~54 ~5 ~33 ~55 ~5 ~33 web 0
fill ~54 ~5 ~35 ~54 ~8 ~35 web 0
fill ~55 ~5 ~31 ~56 ~5 ~31 web 0
fill ~56 ~5 ~32 ~56 ~8 ~32 web 0
fill ~57 ~5 ~28 ~57 ~7 ~28 web 0
fill ~57 ~5 ~29 ~57 ~8 ~29 web 0
fill ~59 ~5 ~93 ~59 ~7 ~93 planks 2
fill ~66 ~5 ~90 ~66 ~7 ~90 planks 0
fill ~66 ~5 ~110 ~66 ~8 ~110 planks 2
fill ~68 ~5 ~0 ~74 ~5 ~0 stone 0
fill ~68 ~5 ~1 ~74 ~5 ~1 stone 0
fill ~68 ~5 ~2 ~75 ~5 ~2 stone 0
fill ~69 ~5 ~3 ~75 ~5 ~3 stone 0
fill ~69 ~5 ~105 ~69 ~10 ~105 planks 2
setblock ~70 ~5 ~111 planks 0
fill ~72 ~5 ~4 ~74 ~5 ~4 stone 0
fill ~73 ~5 ~44 ~75 ~5 ~44 sandstone 0
fill ~74 ~5 ~42 ~75 ~5 ~42 sandstone 0
fill ~74 ~5 ~43 ~75 ~5 ~43 sandstone 0
fill ~74 ~5 ~45 ~74 ~7 ~45 sandstone 0
setblock ~75 ~5 ~40 end_stone 0
fill ~75 ~5 ~41 ~75 ~5 ~41 sandstone 0
fill ~75 ~5 ~45 ~75 ~5 ~45 wool 15
fill ~75 ~5 ~48 ~75 ~5 ~48 sandstone 0
fill ~75 ~5 ~82 ~75 ~5 ~82 planks 0
fill ~1 ~6 ~24 ~1 ~6 ~24 planks 0
fill ~2 ~6 ~21 ~2 ~9 ~21 planks 2
fill ~2 ~6 ~22 ~3 ~6 ~22 planks 0
fill ~2 ~6 ~34 ~9 ~6 ~34 planks 2
fill ~3 ~6 ~31 ~6 ~6 ~31 planks 2
fill ~3 ~6 ~32 ~10 ~6 ~32 planks 2
fill ~3 ~6 ~33 ~3 ~6 ~31 planks 2
setblock ~3 ~6 ~36 planks 2
fill ~3 ~6 ~51 ~10 ~6 ~51 planks 2
fill ~3 ~6 ~78 ~3 ~8 ~78 planks 0
setblock ~4 ~6 ~30 sandstone 0
setblock ~4 ~6 ~33 sandstone 0
fill ~4 ~6 ~37 ~9 ~6 ~37 planks 2
setblock ~4 ~6 ~49 planks 2
fill ~4 ~6 ~52 ~4 ~6 ~54 planks 2
fill ~5 ~6 ~30 ~9 ~6 ~30 planks 2
fill ~5 ~6 ~33 ~6 ~6 ~33 planks 2
fill ~5 ~6 ~36 ~10 ~6 ~36 planks 2
setblock ~5 ~6 ~38 planks 0
fill ~5 ~6 ~48 ~10 ~6 ~48 planks 2
setblock ~5 ~6 ~52 sandstone 0
fill ~5 ~6 ~53 ~11 ~6 ~53 planks 2
fill ~5 ~6 ~54 ~7 ~6 ~54 planks 2
setblock ~5 ~6 ~55 sandstone 0
fill ~5 ~6 ~109 ~5 ~7 ~109 planks 2
fill ~6 ~6 ~35 ~11 ~6 ~35 planks 2
setblock ~6 ~6 ~47 planks 0
fill ~6 ~6 ~49 ~11 ~6 ~49 planks 2
fill ~6 ~6 ~52 ~7 ~6 ~52 planks 2
fill ~6 ~6 ~55 ~10 ~6 ~55 planks 2
setblock ~7 ~6 ~29 planks 2
setblock ~7 ~6 ~31 sandstone 0
setblock ~7 ~6 ~33 sandstone 0
fill ~7 ~6 ~38 ~8 ~6 ~38 planks 2
fill ~8 ~6 ~31 ~9 ~6 ~31 planks 2
fill ~8 ~6 ~33 ~8 ~7 ~33 planks 2
fill ~8 ~6 ~47 ~9 ~6 ~47 planks 2
setblock ~8 ~6 ~52 sandstone 0
setblock ~8 ~6 ~54 sandstone 0
setblock ~8 ~6 ~56 planks 2
fill ~9 ~6 ~22 ~10 ~6 ~22 planks 0
fill ~9 ~6 ~33 ~9 ~7 ~33 sandstone 0
fill ~9 ~6 ~52 ~9 ~7 ~52 planks 2
fill ~9 ~6 ~54 ~10 ~6 ~54 planks 2
fill ~10 ~6 ~31 ~10 ~3 ~31 sandstone 0
setblock ~10 ~6 ~33 planks 2
setblock ~10 ~6 ~34 sandstone 0
fill ~10 ~6 ~52 ~10 ~7 ~52 sandstone 0
fill ~10 ~6 ~75 ~10 ~8 ~75 planks 2
fill ~11 ~6 ~19 ~11 ~9 ~19 planks 2
fill ~11 ~6 ~32 ~11 ~6 ~33 sandstone 0
setblock ~11 ~6 ~34 planks 2
setblock ~11 ~6 ~51 sandstone 0
setblock ~11 ~6 ~52 planks 2
fill ~12 ~6 ~50 ~12 ~6 ~51 planks 2
fill ~12 ~6 ~52 ~12 ~6 ~53 sandstone 0
fill ~13 ~6 ~11 ~13 ~11 ~11 planks 2
fill ~15 ~6 ~6 ~15 ~12 ~6 planks 0
fill ~15 ~6 ~7 ~15 ~6 ~6 planks 0
setblock ~17 ~6 ~4 planks 2
fill ~19 ~6 ~12 ~20 ~6 ~12 planks 0
fill ~22 ~6 ~20 ~22 ~9 ~20 web 0
fill ~22 ~6 ~21 ~22 ~8 ~21 web 0
fill ~22 ~6 ~22 ~22 ~8 ~22 web 0
fill ~22 ~6 ~23 ~22 ~8 ~23 web 0
fill ~22 ~6 ~24 ~22 ~8 ~24 web 0
fill ~23 ~6 ~16 ~23 ~10 ~16 web 0
fill ~23 ~6 ~17 ~23 ~9 ~17 web 0
fill ~24 ~6 ~14 ~24 ~10 ~14 web 0
fill ~25 ~6 ~13 ~25 ~9 ~13 web 0
fill ~37 ~6 ~2 ~42 ~6 ~2 web 0
fill ~38 ~6 ~0 ~42 ~6 ~0 web 0
fill ~38 ~6 ~1 ~42 ~6 ~1 web 0
fill ~38 ~6 ~3 ~43 ~6 ~3 web 0
fill ~40 ~6 ~4 ~42 ~6 ~4 web 0
fill ~41 ~6 ~5 ~41 ~13 ~5 web 0
setblock ~52 ~6 ~120 planks 0
fill ~53 ~6 ~36 ~53 ~7 ~36 web 0
fill ~54 ~6 ~33 ~56 ~6 ~33 web 0
fill ~54 ~6 ~113 ~54 ~10 ~113 planks 3
fill ~55 ~6 ~34 ~55 ~9 ~34 web 0
fill ~56 ~6 ~31 ~57 ~6 ~31 web 0
fill ~56 ~6 ~117 ~56 ~8 ~117 planks 2
fill ~57 ~6 ~30 ~57 ~9 ~30 web 0
fill ~58 ~6 ~25 ~58 ~8 ~25 web 0
fill ~58 ~6 ~26 ~58 ~8 ~26 web 0
fill ~58 ~6 ~27 ~58 ~9 ~27 web 0
fill ~64 ~6 ~92 ~64 ~11 ~92 planks 2
fill ~71 ~6 ~110 ~71 ~6 ~111 planks 0
fill ~74 ~6 ~42 ~75 ~6 ~42 sandstone 0
fill ~74 ~6 ~43 ~75 ~6 ~43 sandstone 0
fill ~74 ~6 ~44 ~75 ~6 ~44 sandstone 0
fill ~75 ~6 ~41 ~75 ~6 ~41 sandstone 0
fill ~75 ~6 ~45 ~75 ~6 ~45 sandstone 0
fill ~75 ~6 ~46 ~75 ~6 ~48 sandstone 0
fill ~1 ~7 ~22 ~2 ~7 ~22 planks 0
fill ~1 ~7 ~24 ~2 ~7 ~24 planks 0
fill ~2 ~7 ~102 ~2 ~10 ~102 planks 3
fill ~3 ~7 ~13 ~3 ~14 ~13 planks 2
fill ~4 ~7 ~34 ~9 ~7 ~34 planks 2
setblock ~5 ~7 ~18 planks 2
fill ~5 ~7 ~31 ~5 ~7 ~35 planks 2
fill ~5 ~7 ~51 ~10 ~7 ~51 planks 2
fill ~5 ~7 ~76 ~5 ~12 ~76 planks 2
setblock ~6 ~7 ~31 sandstone 0
fill ~6 ~7 ~32 ~8 ~7 ~32 planks 2
fill ~6 ~7 ~33 ~8 ~7 ~33 planks 2
fill ~6 ~7 ~35 ~9 ~7 ~35 planks 2
fill ~6 ~7 ~36 ~6 ~7 ~32 planks 2
fill ~6 ~7 ~52 ~9 ~7 ~52 planks 2
fill ~6 ~7 ~53 ~9 ~7 ~53 planks 2
fill ~6 ~7 ~54 ~6 ~7 ~50 planks 2
setblock ~7 ~7 ~31 planks 2
setblock ~7 ~7 ~49 planks 2
setblock ~7 ~7 ~54 sandstone 0
setblock ~8 ~7 ~54 planks 2
setblock ~9 ~7 ~31 planks 2
setblock ~9 ~7 ~36 planks 2
fill ~10 ~7 ~22 ~11 ~7 ~22 planks 0
setblock ~10 ~7 ~49 planks 2
setblock ~10 ~7 ~54 planks 2
fill ~18 ~7 ~4 ~18 ~11 ~4 planks 2
fill ~18 ~7 ~5 ~18 ~7 ~4 planks 2
setblock ~20 ~7 ~5 planks 0
fill ~20 ~7 ~12 ~20 ~8 ~12 planks 0
fill ~20 ~7 ~13 ~20 ~7 ~12 planks 0
fill ~22 ~7 ~18 ~22 ~10 ~18 web 0
fill ~22 ~7 ~19 ~22 ~10 ~19 web 0
fill ~23 ~7 ~15 ~23 ~10 ~15 web 0
fill ~24 ~7 ~13 ~24 ~11 ~13 web 0
fill ~25 ~7 ~12 ~25 ~11 ~12 web 0
fill ~26 ~7 ~11 ~26 ~10 ~11 web 0
fill ~36 ~7 ~2 ~44 ~7 ~2 web 0
fill ~37 ~7 ~1 ~43 ~7 ~1 web 0
fill ~37 ~7 ~3 ~44 ~7 ~3 web 0
fill ~38 ~7 ~0 ~43 ~7 ~0 web 0
fill ~38 ~7 ~4 ~44 ~7 ~4 web 0
fill ~39 ~7 ~5 ~43 ~7 ~5 web 0
fill ~40 ~7 ~6 ~42 ~7 ~6 web 0
fill ~49 ~7 ~116 ~49 ~11 ~116 planks 2
fill ~54 ~7 ~36 ~54 ~10 ~36 web 0
fill ~55 ~7 ~33 ~56 ~7 ~33 web 0
fill ~55 ~7 ~35 ~55 ~11 ~35 web 0
fill ~56 ~7 ~31 ~57 ~7 ~31 web 0
fill ~56 ~7 ~34 ~56 ~12 ~34 web 0
fill ~57 ~7 ~32 ~57 ~12 ~32 web 0
fill ~58 ~7 ~28 ~58 ~10 ~28 web 0
fill ~58 ~7 ~29 ~58 ~11 ~29 web 0
fill ~58 ~7 ~94 ~58 ~8 ~94 planks 2
fill ~61 ~7 ~89 ~61 ~12 ~89 planks 0
fill ~65 ~7 ~87 ~65 ~10 ~87 planks 2
fill ~66 ~7 ~93 ~66 ~9 ~93 planks 3
setblock ~66 ~7 ~111 planks 2
fill ~67 ~7 ~90 ~67 ~8 ~90 planks 0
setblock ~71 ~7 ~106 planks 0
fill ~71 ~7 ~111 ~71 ~9 ~111 planks 0
fill ~73 ~7 ~83 ~73 ~12 ~83 planks 2
fill ~74 ~7 ~43 ~75 ~7 ~43 sandstone 0
fill ~74 ~7 ~44 ~75 ~7 ~44 sandstone 0
fill ~75 ~7 ~41 ~75 ~7 ~41 sandstone 0
fill ~75 ~7 ~42 ~75 ~7 ~42 sandstone 0
fill ~75 ~7 ~45 ~75 ~7 ~45 planks 2
fill ~75 ~7 ~46 ~75 ~7 ~46 planks 2
fill ~1 ~8 ~23 ~2 ~8 ~23 planks 0
fill ~1 ~8 ~24 ~1 ~9 ~24 planks 0
fill ~1 ~8 ~25 ~2 ~8 ~25 planks 0
setblock ~2 ~8 ~22 planks 0
fill ~2 ~8 ~78 ~2 ~9 ~78 planks 0
fill ~3 ~8 ~75 ~3 ~10 ~75 planks 3
setblock ~4 ~8 ~13 planks 2
fill ~4 ~8 ~81 ~4 ~11 ~81 planks 2
fill ~5 ~8 ~19 ~6 ~8 ~19 planks 2
fill ~8 ~8 ~79 ~8 ~13 ~79 planks 0
fill ~9 ~8 ~5 ~9 ~10 ~5 planks 2
fill ~10 ~8 ~22 ~10 ~6 ~22 planks 0
fill ~10 ~8 ~23 ~11 ~8 ~23 planks 0
fill ~11 ~8 ~74 ~11 ~9 ~74 planks 2
fill ~21 ~8 ~5 ~21 ~10 ~5 planks 0
fill ~21 ~8 ~6 ~21 ~8 ~5 planks 0
fill ~21 ~8 ~12 ~21 ~8 ~13 planks 0
fill ~21 ~8 ~20 ~21 ~9 ~20 web 0
fill ~21 ~8 ~21 ~21 ~9 ~21 web 0
fill ~21 ~8 ~22 ~21 ~9 ~22 web 0
fill ~22 ~8 ~17 ~22 ~10 ~17 web 0
fill ~23 ~8 ~14 ~23 ~10 ~14 web 0
fill ~25 ~8 ~11 ~25 ~11 ~11 web 0
fill ~26 ~8 ~10 ~26 ~11 ~10 web 0
fill ~35 ~8 ~0 ~42 ~8 ~0 web 0
fill ~35 ~8 ~1 ~43 ~8 ~1 web 0
fill ~36 ~8 ~2 ~44 ~8 ~2 web 0
fill ~36 ~8 ~3 ~45 ~8 ~3 web 0
fill ~38 ~8 ~4 ~44 ~8 ~4 web 0
fill ~38 ~8 ~5 ~44 ~8 ~5 web 0
fill ~38 ~8 ~6 ~43 ~8 ~6 web 0
fill ~38 ~8 ~7 ~42 ~8 ~7 web 0
fill ~38 ~8 ~8 ~42 ~8 ~8 web 0
fill ~39 ~8 ~9 ~41 ~8 ~9 web 0
fill ~54 ~8 ~111 ~54 ~12 ~111 planks 0
fill ~55 ~8 ~36 ~55 ~16 ~36 web 0
fill ~56 ~8 ~33 ~57 ~8 ~33 web 0
fill ~57 ~8 ~31 ~57 ~10 ~31 web 0
fill ~57 ~8 ~118 ~57 ~9 ~118 planks 2
fill ~58 ~8 ~30 ~58 ~11 ~30 web 0
fill ~59 ~8 ~26 ~59 ~9 ~26 web 0
fill ~59 ~8 ~27 ~59 ~10 ~27 web 0
fill ~65 ~8 ~110 ~65 ~8 ~111 planks 2
fill ~68 ~8 ~90 ~68 ~9 ~90 planks 0
setblock ~68 ~8 ~106 planks 0
fill ~72 ~8 ~106 ~72 ~11 ~106 planks 0
fill ~72 ~8 ~107 ~72 ~8 ~106 planks 0
setblock ~72 ~8 ~111 planks 0
fill ~75 ~8 ~42 ~75 ~8 ~42 sandstone 0
fill ~75 ~8 ~44 ~75 ~8 ~44 sandstone 0
setblock ~75 ~8 ~45 sandstone 0
fill ~1 ~9 ~23 ~1 ~8 ~23 planks 0
fill ~1 ~9 ~78 ~1 ~10 ~78 planks 0
fill ~2 ~9 ~25 ~2 ~10 ~25 planks 0
fill ~2 ~9 ~100 ~2 ~12 ~100 planks 0
setblock ~3 ~9 ~14 planks 2
fill ~3 ~9 ~21 ~3 ~12 ~21 planks 2
fill ~5 ~9 ~19 ~5 ~12 ~19 planks 2
setblock ~9 ~9 ~15 planks 0
fill ~11 ~9 ~23 ~11 ~10 ~23 planks 0
fill ~12 ~9 ~12 ~12 ~16 ~12 planks 2
fill ~12 ~9 ~19 ~12 ~12 ~19 planks 2
setblock ~17 ~9 ~10 planks 2
setblock ~21 ~9 ~4 planks 0
fill ~21 ~9 ~13 ~21 ~10 ~13 planks 0
fill ~21 ~9 ~14 ~21 ~9 ~13 planks 0
fill ~22 ~9 ~16 ~22 ~10 ~16 web 0
fill ~24 ~9 ~12 ~24 ~11 ~12 web 0
fill ~27 ~9 ~9 ~27 ~12 ~9 web 0
fill ~27 ~9 ~10 ~27 ~10 ~10 web 0
fill ~35 ~9 ~0 ~42 ~9 ~0 web 0
fill ~35 ~9 ~1 ~42 ~9 ~1 web 0
fill ~35 ~9 ~2 ~44 ~9 ~2 web 0
fill ~36 ~9 ~3 ~44 ~9 ~3 web 0
fill ~37 ~9 ~4 ~41 ~9 ~4 web 0
fill ~37 ~9 ~5 ~44 ~9 ~5 web 0
fill ~37 ~9 ~6 ~44 ~9 ~6 web 0
fill ~37 ~9 ~7 ~43 ~9 ~7 web 0
fill ~37 ~9 ~8 ~43 ~9 ~8 web 0
fill ~37 ~9 ~9 ~43 ~9 ~9 web 0
fill ~38 ~9 ~10 ~42 ~9 ~10 web 0
fill ~43 ~9 ~4 ~45 ~9 ~4 web 0
fill ~54 ~9 ~37 ~54 ~10 ~37 web 0
fill ~56 ~9 ~33 ~57 ~9 ~33 web 0
fill ~56 ~9 ~35 ~56 ~17 ~35 web 0
setblock ~57 ~9 ~95 planks 2
fill ~58 ~9 ~31 ~58 ~12 ~31 web 0
fill ~58 ~9 ~119 ~58 ~10 ~119 planks 2
fill ~59 ~9 ~28 ~59 ~10 ~28 web 0
fill ~65 ~9 ~111 ~65 ~14 ~111 planks 2
fill ~67 ~9 ~94 ~67 ~10 ~94 planks 3
fill ~67 ~9 ~106 ~67 ~15 ~106 planks 0
fill ~67 ~9 ~107 ~67 ~9 ~106 planks 0
setblock ~69 ~9 ~104 planks 2
fill ~71 ~9 ~112 ~72 ~9 ~112 planks 0
setblock ~74 ~9 ~81 planks 0
fill ~1 ~10 ~17 ~1 ~14 ~17 planks 0
fill ~1 ~10 ~18 ~1 ~10 ~18 planks 0
fill ~2 ~10 ~26 ~3 ~10 ~26 planks 0
fill ~2 ~10 ~74 ~2 ~11 ~74 planks 3
fill ~3 ~10 ~102 ~3 ~12 ~102 planks 3
fill ~8 ~10 ~6 ~8 ~12 ~6 planks 2
fill ~10 ~10 ~15 ~10 ~14 ~15 planks 0
fill ~10 ~10 ~16 ~10 ~10 ~15 planks 0
fill ~11 ~10 ~24 ~12 ~10 ~24 planks 0
setblock ~12 ~10 ~11 planks 2
setblock ~12 ~10 ~73 planks 2
fill ~18 ~10 ~9 ~18 ~10 ~10 planks 2
fill ~22 ~10 ~4 ~22 ~12 ~4 planks 0
fill ~22 ~10 ~5 ~22 ~10 ~4 planks 0
fill ~22 ~10 ~13 ~22 ~10 ~14 planks 0
fill ~25 ~10 ~10 ~25 ~11 ~10 web 0
fill ~26 ~10 ~9 ~26 ~11 ~9 web 0
fill ~27 ~10 ~8 ~27 ~12 ~8 web 0
fill ~33 ~10 ~41 ~35 ~10 ~41 web 0
fill ~33 ~10 ~42 ~34 ~10 ~42 web 0
fill ~34 ~10 ~40 ~35 ~10 ~40 web 0
fill ~35 ~10 ~0 ~41 ~10 ~0 web 0
fill ~35 ~10 ~1 ~41 ~10 ~1 web 0
fill ~36 ~10 ~2 ~43 ~10 ~2 web 0
fill ~36 ~10 ~3 ~45 ~10 ~3 web 0
fill ~36 ~10 ~5 ~39 ~10 ~5 web 0
fill ~36 ~10 ~6 ~44 ~10 ~6 web 0
fill ~36 ~10 ~7 ~44 ~10 ~7 web 0
fill ~36 ~10 ~8 ~44 ~10 ~8 web 0
fill ~36 ~10 ~9 ~44 ~10 ~9 web 0
fill ~37 ~10 ~4 ~44 ~10 ~4 web 0
fill ~37 ~10 ~10 ~43 ~10 ~10 web 0
fill ~37 ~10 ~20 ~39 ~10 ~20 web 0
fill ~37 ~10 ~21 ~41 ~10 ~21 web 0
fill ~37 ~10 ~22 ~40 ~10 ~22 web 0
fill ~38 ~10 ~11 ~42 ~10 ~11 web 0
fill ~38 ~10 ~19 ~39 ~10 ~19 web 0
fill ~38 ~10 ~23 ~40 ~10 ~23 web 0
fill ~39 ~10 ~26 ~43 ~10 ~26 web 0
fill ~39 ~10 ~27 ~42 ~10 ~27 web 0
fill ~39 ~10 ~28 ~43 ~10 ~28 web 0
fill ~40 ~10 ~25 ~42 ~10 ~25 web 0
fill ~40 ~10 ~29 ~41 ~10 ~29 web 0
fill ~42 ~10 ~5 ~45 ~10 ~5 web 0
setblock ~45 ~10 ~2 web 0
fill ~51 ~10 ~69 ~53 ~10 ~69 web 0
fill ~51 ~10 ~70 ~52 ~10 ~70 web 0
fill ~52 ~10 ~68 ~53 ~10 ~68 web 0
fill ~55 ~10 ~37 ~55 ~16 ~37 web 0
fill ~55 ~10 ~112 ~55 ~13 ~112 planks 3
fill ~56 ~10 ~33 ~57 ~10 ~33 web 0
fill ~57 ~10 ~34 ~57 ~16 ~34 web 0
fill ~58 ~10 ~32 ~58 ~12 ~32 web 0
fill ~62 ~10 ~88 ~62 ~14 ~88 planks 3
fill ~66 ~10 ~86 ~66 ~12 ~86 planks 2
setblock ~69 ~10 ~90 planks 0
fill ~70 ~10 ~104 ~70 ~14 ~104 planks 2
fill ~70 ~10 ~105 ~70 ~10 ~104 planks 2
setblock ~72 ~10 ~105 planks 0
fill ~72 ~10 ~112 ~72 ~11 ~112 planks 0
fill ~72 ~10 ~113 ~72 ~10 ~112 planks 0
fill ~74 ~10 ~80 ~75 ~10 ~80 planks 0
setblock ~74 ~10 ~84 planks 0
setblock ~3 ~11 ~22 planks 2
fill ~3 ~11 ~26 ~3 ~11 ~27 planks 0
fill ~3 ~11 ~82 ~3 ~13 ~82 planks 2
fill ~4 ~11 ~27 ~4 ~12 ~27 planks 0
