fill ~1 ~-3 ~0 ~130 ~-3 ~0 air 0
fill ~1 ~-3 ~1 ~130 ~-3 ~1 air 0
fill ~1 ~-3 ~2 ~130 ~-3 ~2 air 0
fill ~1 ~-3 ~3 ~130 ~-3 ~3 air 0
fill ~1 ~-3 ~4 ~130 ~-3 ~4 air 0
fill ~1 ~-3 ~5 ~130 ~-3 ~5 air 0
fill ~1 ~-3 ~6 ~130 ~-3 ~6 air 0
fill ~1 ~-3 ~7 ~130 ~-3 ~7 air 0
fill ~1 ~-3 ~8 ~130 ~-3 ~8 air 0
fill ~1 ~-3 ~9 ~130 ~-3 ~9 air 0
fill ~1 ~-3 ~10 ~130 ~-3 ~10 air 0
fill ~1 ~-3 ~11 ~130 ~-3 ~11 air 0
fill ~1 ~-3 ~12 ~130 ~-3 ~12 air 0
fill ~1 ~-3 ~13 ~130 ~-3 ~13 air 0
fill ~1 ~-3 ~14 ~130 ~-3 ~14 air 0
fill ~1 ~-3 ~15 ~130 ~-3 ~15 air 0
fill ~1 ~-3 ~16 ~130 ~-3 ~16 air 0
fill ~1 ~-3 ~17 ~130 ~-3 ~17 air 0
fill ~1 ~-3 ~18 ~130 ~-3 ~18 air 0
fill ~1 ~-3 ~19 ~130 ~-3 ~19 air 0
fill ~1 ~-3 ~20 ~130 ~-3 ~20 air 0
fill ~1 ~-3 ~21 ~130 ~-3 ~21 air 0
fill ~1 ~-3 ~22 ~130 ~-3 ~22 air 0
fill ~1 ~-3 ~23 ~130 ~-3 ~23 air 0
fill ~1 ~-3 ~24 ~130 ~-3 ~24 air 0
fill ~1 ~-3 ~25 ~130 ~-3 ~25 air 0
fill ~1 ~-3 ~26 ~130 ~-3 ~26 air 0
fill ~1 ~-3 ~27 ~130 ~-3 ~27 air 0
fill ~1 ~-3 ~28 ~130 ~-3 ~28 air 0
fill ~1 ~-3 ~29 ~130 ~-3 ~29 air 0
fill ~1 ~-3 ~30 ~130 ~-3 ~30 air 0
fill ~1 ~-3 ~31 ~130 ~-3 ~31 air 0
fill ~1 ~-3 ~32 ~130 ~-3 ~32 air 0
fill ~1 ~-3 ~33 ~130 ~-3 ~33 air 0
fill ~1 ~-3 ~34 ~130 ~-3 ~34 air 0
fill ~1 ~-3 ~35 ~130 ~-3 ~35 air 0
fill ~1 ~-3 ~36 ~130 ~-3 ~36 air 0
fill ~1 ~-3 ~37 ~130 ~-3 ~37 air 0
fill ~1 ~-3 ~38 ~130 ~-3 ~38 air 0
fill ~1 ~-3 ~39 ~130 ~-3 ~39 air 0
fill ~1 ~-3 ~40 ~130 ~-3 ~40 air 0
fill ~1 ~-3 ~41 ~130 ~-3 ~41 air 0
fill ~1 ~-3 ~42 ~130 ~-3 ~42 air 0
fill ~1 ~-3 ~43 ~130 ~-3 ~43 air 0
fill ~1 ~-3 ~44 ~130 ~-3 ~44 air 0
fill ~1 ~-3 ~45 ~130 ~-3 ~45 air 0
fill ~1 ~-3 ~46 ~130 ~-3 ~46 air 0
fill ~1 ~-3 ~47 ~130 ~-3 ~47 air 0
fill ~1 ~-3 ~48 ~130 ~-3 ~48 air 0
fill ~1 ~-3 ~49 ~130 ~-3 ~49 air 0
fill ~1 ~-3 ~50 ~130 ~-3 ~50 air 0
fill ~1 ~-3 ~51 ~130 ~-3 ~51 air 0
fill ~1 ~-3 ~52 ~130 ~-3 ~52 air 0
fill ~1 ~-3 ~53 ~130 ~-3 ~53 air 0
fill ~1 ~-3 ~54 ~130 ~-3 ~54 air 0
fill ~1 ~-3 ~55 ~130 ~-3 ~55 air 0
fill ~1 ~-3 ~56 ~130 ~-3 ~56 air 0
fill ~1 ~-3 ~57 ~130 ~-3 ~57 air 0
fill ~1 ~-3 ~58 ~130 ~-3 ~58 air 0
fill ~1 ~-3 ~59 ~130 ~-3 ~59 air 0
fill ~1 ~-3 ~60 ~130 ~-3 ~60 air 0
fill ~1 ~-3 ~61 ~130 ~-3 ~61 air 0
fill ~1 ~-3 ~62 ~130 ~-3 ~62 air 0
fill ~1 ~-3 ~63 ~130 ~-3 ~63 air 0
fill ~1 ~-3 ~64 ~130 ~-3 ~64 air 0
fill ~1 ~-3 ~65 ~130 ~-3 ~65 air 0
fill ~1 ~-3 ~66 ~130 ~-3 ~66 air 0
fill ~1 ~-3 ~67 ~130 ~-3 ~67 air 0
fill ~1 ~-3 ~68 ~130 ~-3 ~68 air 0
fill ~1 ~-3 ~69 ~130 ~-3 ~69 air 0
fill ~1 ~-3 ~70 ~130 ~-3 ~70 air 0
fill ~1 ~-3 ~71 ~130 ~-3 ~71 air 0
fill ~1 ~-3 ~72 ~130 ~-3 ~72 air 0
fill ~1 ~-3 ~73 ~130 ~-3 ~73 air 0
fill ~1 ~-3 ~74 ~130 ~-3 ~74 air 0
fill ~1 ~-3 ~75 ~130 ~-3 ~75 air 0
fill ~1 ~-3 ~76 ~130 ~-3 ~76 air 0
fill ~1 ~-3 ~77 ~130 ~-3 ~77 air 0
fill ~1 ~-3 ~78 ~130 ~-3 ~78 air 0
fill ~1 ~-3 ~79 ~130 ~-3 ~79 air 0
fill ~1 ~-3 ~80 ~130 ~-3 ~80 air 0
fill ~1 ~-3 ~81 ~130 ~-3 ~81 air 0
fill ~1 ~-3 ~82 ~130 ~-3 ~82 air 0
fill ~1 ~-3 ~83 ~130 ~-3 ~83 air 0
fill ~1 ~-3 ~84 ~130 ~-3 ~84 air 0
fill ~61 ~46 ~49 ~65 ~46 ~49 log 12
fill ~59 ~47 ~49 ~60 ~47 ~49 log 12
setblock ~60 ~47 ~48 wooden_slab 8
fill ~61 ~47 ~48 ~65 ~47 ~48 planks 0
fill ~61 ~47 ~50 ~65 ~47 ~50 planks 5
fill ~62 ~47 ~47 ~64 ~47 ~47 wooden_slab 10
setblock ~66 ~47 ~48 wooden_slab 8
fill ~66 ~47 ~49 ~67 ~47 ~49 log 12
setblock ~58 ~48 ~48 log 12
fill ~59 ~48 ~47 ~60 ~48 ~47 planks 0
setblock ~59 ~48 ~48 wooden_slab 0
fill ~59 ~48 ~49 ~60 ~48 ~49 planks 5
fill ~60 ~48 ~46 ~61 ~48 ~46 planks 2
fill ~60 ~48 ~50 ~66 ~48 ~50 planks 5
fill ~61 ~48 ~47 ~65 ~48 ~47 iron_block 0
setblock ~61 ~48 ~51 wooden_slab 13
setblock ~62 ~48 ~46 wooden_slab 2
fill ~62 ~48 ~51 ~64 ~48 ~51 double_wooden_slab 5
setblock ~63 ~48 ~46 coal_block 0
setblock ~64 ~48 ~46 wooden_slab 2
fill ~65 ~48 ~46 ~66 ~48 ~46 planks 2
setblock ~65 ~48 ~51 wooden_slab 13
fill ~66 ~48 ~47 ~67 ~48 ~47 planks 0
fill ~66 ~48 ~49 ~67 ~48 ~49 planks 5
setblock ~67 ~48 ~48 wooden_slab 0
setblock ~68 ~48 ~48 log 12
setblock ~57 ~49 ~48 log 12
setblock ~58 ~49 ~47 planks 0
setblock ~58 ~49 ~49 planks 5
setblock ~59 ~49 ~46 planks 2
fill ~59 ~49 ~47 ~60 ~49 ~47 iron_block 0
fill ~59 ~49 ~50 ~60 ~49 ~50 planks 5
setblock ~60 ~49 ~46 coal_block 0
setblock ~60 ~49 ~51 double_wooden_slab 5
fill ~61 ~49 ~46 ~65 ~49 ~46 stained_glass 0
fill ~61 ~49 ~47 ~65 ~49 ~47 prismarine 0
fill ~61 ~49 ~50 ~65 ~49 ~50 glowstone 0
fill ~61 ~49 ~51 ~65 ~49 ~51 planks 5
setblock ~66 ~49 ~46 coal_block 0
fill ~66 ~49 ~47 ~67 ~49 ~47 iron_block 0
fill ~66 ~49 ~50 ~67 ~49 ~50 planks 5
setblock ~66 ~49 ~51 double_wooden_slab 5
setblock ~67 ~49 ~46 planks 2
setblock ~68 ~49 ~47 planks 0
setblock ~68 ~49 ~49 planks 5
setblock ~69 ~49 ~48 log 12
setblock ~56 ~50 ~48 log 12
setblock ~57 ~50 ~47 planks 0
fill ~57 ~50 ~49 ~57 ~52 ~49 planks 5
setblock ~58 ~50 ~46 planks 2
setblock ~58 ~50 ~47 iron_block 0
setblock ~58 ~50 ~50 planks 5
fill ~59 ~50 ~46 ~60 ~50 ~46 stained_glass 0
fill ~59 ~50 ~47 ~60 ~50 ~47 prismarine 0
fill ~59 ~50 ~50 ~60 ~50 ~50 glowstone 0
fill ~59 ~50 ~51 ~67 ~50 ~51 planks 5
fill ~61 ~50 ~46 ~65 ~50 ~46 iron_block 0
fill ~61 ~50 ~47 ~65 ~50 ~47 iron_block 0
setblock ~62 ~50 ~45 ice 0
fill ~62 ~50 ~48 ~64 ~50 ~48 coal_block 0
fill ~66 ~50 ~46 ~67 ~50 ~46 stained_glass 0
fill ~66 ~50 ~47 ~67 ~50 ~47 prismarine 0
fill ~66 ~50 ~50 ~67 ~50 ~50 glowstone 0
setblock ~68 ~50 ~46 planks 2
setblock ~68 ~50 ~47 iron_block 0
setblock ~68 ~50 ~50 planks 5
setblock ~69 ~50 ~47 planks 0
fill ~69 ~50 ~49 ~69 ~52 ~49 planks 5
setblock ~70 ~50 ~48 log 12
fill ~78 ~50 ~42 ~81 ~50 ~42 iron_block 0
setblock ~56 ~51 ~47 log 12
fill ~57 ~51 ~45 ~57 ~52 ~45 planks 2
setblock ~57 ~51 ~46 planks 0
setblock ~57 ~51 ~48 planks 5
setblock ~58 ~51 ~45 coal_block 0
setblock ~58 ~51 ~46 iron_block 0
setblock ~58 ~51 ~49 planks 5
setblock ~58 ~51 ~50 wooden_slab 13
setblock ~59 ~51 ~45 stained_glass 0
setblock ~59 ~51 ~46 prismarine 0
setblock ~59 ~51 ~49 glowstone 0
fill ~59 ~51 ~50 ~60 ~51 ~50 planks 5
fill ~59 ~51 ~51 ~60 ~51 ~51 double_wooden_slab 5
fill ~60 ~51 ~45 ~60 ~51 ~46 iron_block 0
setblock ~61 ~51 ~45 stone 6
fill ~61 ~51 ~46 ~61 ~50 ~46 iron_block 0
setblock ~61 ~51 ~47 coal_block 0
fill ~61 ~51 ~51 ~65 ~51 ~51 planks 5
setblock ~62 ~51 ~44 ice 0
fill ~62 ~51 ~45 ~64 ~51 ~45 stained_glass 0
fill ~62 ~51 ~48 ~64 ~51 ~48 coal_block 0
setblock ~65 ~51 ~45 stone 6
fill ~65 ~51 ~46 ~66 ~51 ~46 iron_block 0
setblock ~65 ~51 ~47 coal_block 0
setblock ~66 ~51 ~45 iron_block 0
fill ~66 ~51 ~50 ~67 ~51 ~50 planks 5
fill ~66 ~51 ~51 ~67 ~51 ~51 double_wooden_slab 5
setblock ~67 ~51 ~45 stained_glass 0
setblock ~67 ~51 ~46 prismarine 0
setblock ~67 ~51 ~49 glowstone 0
setblock ~68 ~51 ~45 coal_block 0
setblock ~68 ~51 ~46 iron_block 0
setblock ~68 ~51 ~49 planks 5
setblock ~68 ~51 ~50 double_wooden_slab 5
fill ~69 ~51 ~45 ~69 ~52 ~45 planks 2
setblock ~69 ~51 ~46 planks 0
setblock ~69 ~51 ~48 planks 5
setblock ~70 ~51 ~47 log 12
fill ~76 ~51 ~42 ~77 ~51 ~42 iron_block 0
fill ~82 ~51 ~43 ~83 ~51 ~43 iron_block 0
setblock ~55 ~52 ~47 log 12
setblock ~56 ~52 ~46 planks 0
setblock ~56 ~52 ~48 planks 5
setblock ~57 ~52 ~46 iron_block 0
setblock ~58 ~52 ~45 stained_glass 0
setblock ~58 ~52 ~46 prismarine 0
setblock ~58 ~52 ~49 glowstone 0
fill ~58 ~52 ~50 ~59 ~52 ~50 planks 5
fill ~59 ~52 ~45 ~59 ~55 ~45 iron_block 0
fill ~59 ~52 ~46 ~60 ~52 ~46 iron_block 0
setblock ~60 ~52 ~45 stone 6
fill ~60 ~52 ~47 ~60 ~55 ~47 coal_block 0
fill ~60 ~52 ~51 ~66 ~52 ~51 planks 5
setblock ~61 ~52 ~45 stained_glass 0
setblock ~61 ~52 ~48 coal_block 0
fill ~62 ~52 ~45 ~64 ~52 ~45 prismarine 2
fill ~62 ~52 ~46 ~64 ~52 ~46 coal_block 0
setblock ~63 ~52 ~44 ice 0
setblock ~65 ~52 ~45 stained_glass 0
setblock ~65 ~52 ~48 coal_block 0
setblock ~66 ~52 ~45 stone 6
fill ~66 ~52 ~46 ~67 ~52 ~46 iron_block 0
fill ~66 ~52 ~47 ~66 ~55 ~47 coal_block 0
fill ~67 ~52 ~45 ~67 ~55 ~45 iron_block 0
fill ~67 ~52 ~50 ~68 ~52 ~50 planks 5
setblock ~68 ~52 ~45 stained_glass 0
setblock ~68 ~52 ~46 prismarine 0
setblock ~68 ~52 ~49 glowstone 0
setblock ~69 ~52 ~46 iron_block 0
setblock ~70 ~52 ~46 planks 0
setblock ~70 ~52 ~48 planks 5
setblock ~71 ~52 ~47 log 12
setblock ~75 ~52 ~42 iron_block 0
setblock ~84 ~52 ~43 iron_block 0
fill ~55 ~53 ~46 ~55 ~55 ~46 log 12
fill ~56 ~53 ~45 ~56 ~55 ~45 planks 0
fill ~56 ~53 ~47 ~56 ~55 ~47 planks 5
setblock ~57 ~53 ~44 planks 2
fill ~57 ~53 ~45 ~57 ~55 ~45 iron_block 0
fill ~57 ~53 ~48 ~57 ~54 ~48 planks 5
setblock ~57 ~53 ~49 wooden_slab 5
fill ~58 ~53 ~44 ~58 ~55 ~44 stained_glass 0
fill ~58 ~53 ~45 ~58 ~55 ~45 prismarine 0
fill ~58 ~53 ~48 ~58 ~55 ~48 glowstone 0
fill ~58 ~53 ~49 ~59 ~53 ~49 planks 5
fill ~59 ~53 ~44 ~59 ~56 ~44 iron_block 0
fill ~59 ~53 ~46 ~59 ~55 ~46 coal_block 0
setblock ~59 ~53 ~50 double_wooden_slab 5
fill ~60 ~53 ~44 ~60 ~55 ~44 stained_glass 0
fill ~60 ~53 ~50 ~66 ~53 ~50 planks 5
fill ~61 ~53 ~44 ~61 ~55 ~44 prismarine 2
fill ~61 ~53 ~45 ~62 ~53 ~45 coal_block 0
setblock ~61 ~53 ~51 wooden_slab 5
setblock ~62 ~53 ~44 prismarine 1
fill ~62 ~53 ~51 ~64 ~53 ~51 double_wooden_slab 5
setblock ~63 ~53 ~43 ice 0
setblock ~63 ~53 ~44 prismarine 0
setblock ~63 ~53 ~45 iron_block 0
fill ~63 ~53 ~46 ~63 ~55 ~46 glowstone 0
setblock ~64 ~53 ~44 prismarine 1
fill ~64 ~53 ~45 ~65 ~53 ~45 coal_block 0
fill ~65 ~53 ~44 ~65 ~55 ~44 prismarine 2
setblock ~65 ~53 ~51 wooden_slab 5
fill ~66 ~53 ~44 ~66 ~55 ~44 stained_glass 0
fill ~67 ~53 ~44 ~67 ~56 ~44 iron_block 0
fill ~67 ~53 ~46 ~67 ~55 ~46 coal_block 0
fill ~67 ~53 ~49 ~68 ~53 ~49 planks 5
setblock ~67 ~53 ~50 double_wooden_slab 5
fill ~68 ~53 ~44 ~68 ~55 ~44 stained_glass 0
fill ~68 ~53 ~45 ~68 ~55 ~45 prismarine 0
fill ~68 ~53 ~48 ~68 ~55 ~48 glowstone 0
setblock ~69 ~53 ~44 planks 2
fill ~69 ~53 ~45 ~69 ~55 ~45 iron_block 0
fill ~69 ~53 ~48 ~69 ~55 ~48 planks 5
setblock ~69 ~53 ~49 wooden_slab 5
fill ~70 ~53 ~45 ~70 ~55 ~45 planks 0
fill ~70 ~53 ~47 ~70 ~55 ~47 planks 5
fill ~71 ~53 ~46 ~71 ~55 ~46 log 12
fill ~74 ~53 ~41 ~74 ~54 ~41 iron_block 0
fill ~85 ~53 ~44 ~85 ~54 ~44 iron_block 0
setblock ~57 ~54 ~44 coal_block 0
fill ~58 ~54 ~49 ~59 ~54 ~49 planks 5
fill ~60 ~54 ~50 ~66 ~54 ~50 planks 5
fill ~61 ~54 ~45 ~61 ~55 ~45 coal_block 0
setblock ~62 ~54 ~44 prismarine 0
setblock ~62 ~54 ~45 iron_block 0
setblock ~62 ~54 ~46 glowstone 0
setblock ~63 ~54 ~43 stained_glass 15
setblock ~63 ~54 ~45 coal_block 0
setblock ~64 ~54 ~44 prismarine 0
setblock ~64 ~54 ~45 iron_block 0
setblock ~64 ~54 ~46 glowstone 0
fill ~65 ~54 ~45 ~65 ~55 ~45 coal_block 0
setblock ~66 ~54 ~45 iron_block 0
fill ~67 ~54 ~49 ~68 ~54 ~49 planks 5
setblock ~69 ~54 ~44 coal_block 0
setblock ~57 ~55 ~44 planks 2
setblock ~57 ~55 ~48 double_wooden_slab 5
setblock ~58 ~55 ~49 double_wooden_slab 5
setblock ~59 ~55 ~49 planks 5
setblock ~60 ~55 ~49 double_wooden_slab 5
fill ~61 ~55 ~50 ~65 ~55 ~50 planks 5
setblock ~62 ~55 ~44 prismarine 1
setblock ~62 ~55 ~45 coal_block 0
setblock ~63 ~55 ~44 prismarine 0
setblock ~63 ~55 ~45 iron_block 0
setblock ~64 ~55 ~43 packed_ice 0
setblock ~64 ~55 ~44 prismarine 1
setblock ~64 ~55 ~45 coal_block 0
setblock ~66 ~55 ~49 double_wooden_slab 5
fill ~67 ~55 ~49 ~68 ~55 ~49 planks 5
setblock ~69 ~55 ~44 planks 2
fill ~73 ~55 ~40 ~73 ~56 ~40 iron_block 0
fill ~85 ~55 ~45 ~85 ~56 ~45 iron_block 0
setblock ~55 ~56 ~45 log 12
setblock ~56 ~56 ~44 planks 0
setblock ~56 ~56 ~46 planks 5
fill ~57 ~56 ~43 ~57 ~57 ~43 planks 2
setblock ~57 ~56 ~44 iron_block 0
setblock ~57 ~56 ~47 planks 5
setblock ~58 ~56 ~43 stained_glass 0
setblock ~58 ~56 ~44 prismarine 0
setblock ~58 ~56 ~47 glowstone 0
fill ~58 ~56 ~48 ~59 ~56 ~48 planks 5
setblock ~59 ~56 ~43 iron_block 0
setblock ~60 ~56 ~43 stone 6
fill ~60 ~56 ~44 ~60 ~57 ~44 iron_block 0
setblock ~60 ~56 ~45 coal_block 0
fill ~60 ~56 ~49 ~66 ~56 ~49 planks 5
setblock ~61 ~56 ~43 stained_glass 0
setblock ~61 ~56 ~46 coal_block 0
fill ~62 ~56 ~43 ~64 ~56 ~43 prismarine 2
fill ~62 ~56 ~44 ~64 ~56 ~44 coal_block 0
setblock ~65 ~56 ~42 packed_ice 0
setblock ~65 ~56 ~43 stained_glass 0
setblock ~65 ~56 ~46 coal_block 0
setblock ~66 ~56 ~43 stone 6
fill ~66 ~56 ~44 ~66 ~57 ~44 iron_block 0
setblock ~66 ~56 ~45 coal_block 0
setblock ~67 ~56 ~43 iron_block 0
fill ~67 ~56 ~48 ~68 ~56 ~48 planks 5
setblock ~68 ~56 ~43 stained_glass 0
setblock ~68 ~56 ~44 prismarine 0
setblock ~68 ~56 ~47 glowstone 0
fill ~69 ~56 ~43 ~69 ~57 ~43 planks 2
setblock ~69 ~56 ~44 iron_block 0
setblock ~69 ~56 ~47 planks 5
setblock ~70 ~56 ~44 planks 0
setblock ~70 ~56 ~46 planks 5
setblock ~71 ~56 ~45 log 12
setblock ~56 ~57 ~45 log 12
setblock ~57 ~57 ~44 planks 0
setblock ~57 ~57 ~46 planks 5
setblock ~58 ~57 ~43 coal_block 0
setblock ~58 ~57 ~44 iron_block 0
setblock ~58 ~57 ~47 planks 5
setblock ~59 ~57 ~43 stained_glass 0
setblock ~59 ~57 ~44 prismarine 0
setblock ~59 ~57 ~47 glowstone 0
fill ~59 ~57 ~48 ~60 ~57 ~48 planks 5
setblock ~60 ~57 ~43 iron_block 0
setblock ~61 ~57 ~43 stone 6
setblock ~61 ~57 ~44 iron_block 0
setblock ~61 ~57 ~45 coal_block 0
fill ~61 ~57 ~49 ~65 ~57 ~49 planks 5
fill ~62 ~57 ~43 ~64 ~57 ~43 stained_glass 0
fill ~62 ~57 ~46 ~64 ~57 ~46 coal_block 0
setblock ~65 ~57 ~43 stone 6
setblock ~65 ~57 ~44 iron_block 0
setblock ~65 ~57 ~45 coal_block 0
setblock ~66 ~57 ~42 packed_ice 0
setblock ~66 ~57 ~43 iron_block 0
fill ~66 ~57 ~48 ~67 ~57 ~48 planks 5
setblock ~67 ~57 ~43 stained_glass 0
setblock ~67 ~57 ~44 prismarine 0
setblock ~67 ~57 ~47 glowstone 0
setblock ~68 ~57 ~43 coal_block 0
setblock ~68 ~57 ~44 iron_block 0
setblock ~68 ~57 ~47 planks 5
setblock ~69 ~57 ~44 planks 0
setblock ~69 ~57 ~46 planks 5
setblock ~70 ~57 ~45 log 12
setblock ~73 ~57 ~39 iron_block 0
setblock ~84 ~57 ~46 iron_block 0
setblock ~56 ~58 ~44 log 12
setblock ~57 ~58 ~43 planks 0
setblock ~57 ~58 ~45 planks 5
setblock ~58 ~58 ~42 planks 2
setblock ~58 ~58 ~43 iron_block 0
setblock ~58 ~58 ~46 planks 5
fill ~59 ~58 ~42 ~60 ~58 ~42 stained_glass 0
fill ~59 ~58 ~43 ~60 ~58 ~43 prismarine 0
fill ~59 ~58 ~46 ~60 ~58 ~46 glowstone 0
fill ~59 ~58 ~47 ~67 ~58 ~47 planks 5
fill ~61 ~58 ~42 ~65 ~58 ~42 iron_block 0
fill ~61 ~58 ~43 ~65 ~58 ~43 iron_block 0
fill ~61 ~58 ~48 ~65 ~58 ~48 double_wooden_slab 5
fill ~62 ~58 ~44 ~64 ~58 ~44 coal_block 0
fill ~66 ~58 ~42 ~67 ~58 ~42 stained_glass 0
fill ~66 ~58 ~43 ~67 ~58 ~43 prismarine 0
fill ~66 ~58 ~46 ~67 ~58 ~46 glowstone 0
setblock ~67 ~58 ~41 packed_ice 0
setblock ~68 ~58 ~42 planks 2
setblock ~68 ~58 ~43 iron_block 0
setblock ~68 ~58 ~46 planks 5
setblock ~69 ~58 ~43 planks 0
setblock ~69 ~58 ~45 planks 5
setblock ~70 ~58 ~44 log 12
setblock ~73 ~58 ~38 iron_block 0
setblock ~83 ~58 ~47 iron_block 0
setblock ~57 ~59 ~44 log 12
setblock ~58 ~59 ~43 planks 0
setblock ~58 ~59 ~45 planks 5
setblock ~59 ~59 ~42 planks 2
fill ~59 ~59 ~43 ~60 ~59 ~43 iron_block 0
fill ~59 ~59 ~46 ~60 ~59 ~46 planks 5
setblock ~60 ~59 ~42 coal_block 0
setblock ~60 ~59 ~47 wooden_slab 5
fill ~61 ~59 ~42 ~65 ~59 ~42 stained_glass 0
fill ~61 ~59 ~43 ~65 ~59 ~43 prismarine 0
fill ~61 ~59 ~46 ~65 ~59 ~46 glowstone 0
fill ~61 ~59 ~47 ~65 ~59 ~47 planks 5
setblock ~66 ~59 ~42 coal_block 0
fill ~66 ~59 ~43 ~67 ~59 ~43 iron_block 0
fill ~66 ~59 ~46 ~67 ~59 ~46 planks 5
setblock ~66 ~59 ~47 wooden_slab 5
setblock ~67 ~59 ~42 planks 2
setblock ~68 ~59 ~43 planks 0
setblock ~68 ~59 ~45 planks 5
setblock ~69 ~59 ~44 log 12
setblock ~73 ~59 ~37 iron_block 0
setblock ~58 ~60 ~43 iron_block 0
setblock ~58 ~60 ~44 log 12
fill ~59 ~60 ~43 ~60 ~60 ~43 planks 0
fill ~59 ~60 ~45 ~60 ~60 ~45 planks 5
fill ~60 ~60 ~42 ~61 ~60 ~42 planks 2
fill ~60 ~60 ~46 ~66 ~60 ~46 planks 5
fill ~61 ~60 ~43 ~65 ~60 ~43 iron_block 0
setblock ~62 ~60 ~42 wooden_slab 10
setblock ~63 ~60 ~42 coal_block 0
setblock ~64 ~60 ~42 wooden_slab 10
fill ~65 ~60 ~42 ~66 ~60 ~42 planks 2
fill ~66 ~60 ~43 ~67 ~60 ~43 planks 0
fill ~66 ~60 ~45 ~67 ~60 ~45 planks 5
setblock ~68 ~60 ~44 log 12
setblock ~74 ~60 ~37 iron_block 0
setblock ~57 ~61 ~42 iron_block 0
fill ~59 ~61 ~43 ~60 ~61 ~43 log 12
fill ~59 ~61 ~44 ~60 ~61 ~44 wooden_slab 5
setblock ~60 ~61 ~42 wooden_slab 0
fill ~61 ~61 ~42 ~65 ~61 ~42 planks 0
fill ~61 ~61 ~44 ~65 ~61 ~44 planks 5
fill ~61 ~61 ~45 ~65 ~61 ~45 wooden_slab 5
fill ~62 ~61 ~41 ~64 ~61 ~41 wooden_slab 2
setblock ~66 ~61 ~42 wooden_slab 0
fill ~66 ~61 ~43 ~67 ~61 ~43 log 12
fill ~66 ~61 ~44 ~67 ~61 ~44 wooden_slab 5
setblock ~74 ~61 ~36 iron_block 0
fill ~56 ~62 ~41 ~56 ~63 ~41 iron_block 0
fill ~61 ~62 ~43 ~65 ~62 ~43 log 12
setblock ~75 ~62 ~36 iron_block 0
setblock ~76 ~63 ~35 iron_block 0
fill ~55 ~64 ~40 ~55 ~65 ~40 iron_block 0
fill ~77 ~64 ~35 ~77 ~65 ~35 iron_block 0
fill ~55 ~66 ~39 ~55 ~68 ~39 iron_block 0
fill ~78 ~66 ~34 ~78 ~68 ~34 iron_block 0
fill ~56 ~69 ~38 ~56 ~70 ~38 iron_block 0
setblock ~59 ~69 ~35 stone_brick_stairs 6
setblock ~59 ~69 ~36 stone_brick_stairs 7
fill ~78 ~69 ~33 ~78 ~70 ~33 iron_block 0
setblock ~58 ~70 ~35 stone_brick_stairs 6
setblock ~58 ~70 ~36 stonebrick 2
setblock ~58 ~70 ~37 stone_brick_stairs 7
setblock ~59 ~70 ~34 stone_stairs 6
setblock ~59 ~70 ~35 stone_slab 5
setblock ~60 ~70 ~36 stone_stairs 6
setblock ~60 ~70 ~37 stone_brick_stairs 7
setblock ~57 ~71 ~37 iron_block 0
setblock ~58 ~71 ~34 stone_stairs 6
setblock ~58 ~71 ~35 stone_slab 5
setblock ~58 ~71 ~37 stone_stairs 2
setblock ~59 ~71 ~34 birch_stairs 6
setblock ~59 ~71 ~35 wooden_slab 10
setblock ~59 ~71 ~36 birch_stairs 7
setblock ~60 ~71 ~35 stone_stairs 6
setblock ~60 ~71 ~36 stone_slab 5
fill ~77 ~71 ~33 ~77 ~72 ~33 iron_block 0
fill ~58 ~72 ~34 ~58 ~73 ~34 birch_stairs 4
setblock ~58 ~72 ~35 birch_stairs 2
setblock ~58 ~72 ~36 birch_stairs 7
fill ~58 ~72 ~37 ~59 ~72 ~37 iron_block 0
fill ~59 ~72 ~34 ~59 ~74 ~34 planks 2
fill ~59 ~72 ~35 ~60 ~72 ~35 planks 2
fill ~59 ~72 ~36 ~59 ~73 ~36 birch_stairs 3
setblock ~59 ~72 ~38 stone_stairs 2
setblock ~59 ~72 ~39 stone_brick_stairs 7
fill ~60 ~72 ~34 ~60 ~73 ~34 birch_stairs 5
fill ~60 ~72 ~36 ~61 ~72 ~36 iron_block 0
setblock ~62 ~72 ~35 iron_block 0
setblock ~69 ~72 ~29 stone_brick_stairs 6
setblock ~69 ~72 ~30 stone_brick_stairs 7
setblock ~58 ~73 ~35 birch_stairs 0
setblock ~58 ~73 ~36 planks 2
fill ~59 ~73 ~35 ~59 ~74 ~35 planks 1
setblock ~59 ~73 ~39 stone_stairs 3
fill ~60 ~73 ~35 ~60 ~74 ~35 planks 2
setblock ~60 ~73 ~36 birch_stairs 7
setblock ~60 ~73 ~37 birch_stairs 3
setblock ~60 ~73 ~38 stone_brick_stairs 6
fill ~63 ~73 ~34 ~64 ~73 ~34 iron_block 0
setblock ~65 ~73 ~33 iron_block 0
setblock ~68 ~73 ~30 stone_stairs 6
setblock ~68 ~73 ~31 stone_brick_stairs 7
setblock ~69 ~73 ~28 stone_stairs 6
setblock ~69 ~73 ~29 stone_slab 5
setblock ~70 ~73 ~29 stone_brick_stairs 6
setblock ~70 ~73 ~30 stonebrick 2
setblock ~70 ~73 ~31 stone_brick_stairs 7
setblock ~76 ~73 ~32 iron_block 0
setblock ~58 ~74 ~34 oak_stairs 0
setblock ~58 ~74 ~35 planks 2
setblock ~58 ~74 ~36 birch_stairs 4
setblock ~59 ~74 ~36 birch_stairs 7
setblock ~59 ~74 ~37 birch_stairs 6
setblock ~59 ~74 ~38 birch_stairs 3
setblock ~60 ~74 ~34 birch_stairs 1
fill ~60 ~74 ~36 ~60 ~75 ~36 planks 2
setblock ~60 ~74 ~37 stonebrick 0
setblock ~60 ~74 ~38 stone_brick_stairs 3
fill ~66 ~74 ~32 ~67 ~74 ~32 iron_block 0
setblock ~68 ~74 ~29 stone_stairs 6
setblock ~68 ~74 ~30 stone_slab 5
setblock ~68 ~74 ~31 iron_block 0
setblock ~69 ~74 ~28 birch_stairs 6
setblock ~69 ~74 ~29 wooden_slab 10
setblock ~69 ~74 ~30 birch_stairs 7
setblock ~70 ~74 ~28 stone_stairs 6
setblock ~70 ~74 ~29 stone_slab 5
setblock ~70 ~74 ~31 stone_stairs 2
fill ~74 ~74 ~32 ~75 ~74 ~32 iron_block 0
setblock ~58 ~75 ~35 birch_stairs 2
setblock ~58 ~75 ~36 wooden_slab 8
setblock ~58 ~75 ~37 wooden_slab 2
setblock ~59 ~75 ~35 planks 2
setblock ~59 ~75 ~36 planks 1
setblock ~59 ~75 ~37 planks 2
setblock ~59 ~75 ~38 birch_stairs 7
setblock ~60 ~75 ~35 oak_stairs 1
setblock ~60 ~75 ~37 planks 0
setblock ~60 ~75 ~38 wooden_slab 2
fill ~68 ~75 ~28 ~68 ~76 ~28 birch_stairs 4
fill ~68 ~75 ~29 ~69 ~75 ~29 planks 2
fill ~69 ~75 ~28 ~69 ~77 ~28 planks 2
fill ~69 ~75 ~30 ~69 ~76 ~30 birch_stairs 3
fill ~69 ~75 ~31 ~73 ~75 ~31 iron_block 0
setblock ~69 ~75 ~32 stone_stairs 2
setblock ~69 ~75 ~33 stone_brick_stairs 7
fill ~70 ~75 ~28 ~70 ~76 ~28 birch_stairs 5
setblock ~70 ~75 ~29 birch_stairs 2
setblock ~70 ~75 ~30 birch_stairs 7
setblock ~58 ~76 ~36 wooden_slab 0
setblock ~58 ~76 ~37 birch_stairs 4
setblock ~59 ~76 ~35 oak_stairs 2
fill ~59 ~76 ~36 ~60 ~76 ~36 planks 0
fill ~59 ~76 ~37 ~59 ~81 ~37 planks 1
setblock ~59 ~76 ~38 planks 0
setblock ~60 ~76 ~37 planks 2
setblock ~60 ~76 ~38 birch_stairs 7
setblock ~61 ~76 ~37 birch_stairs 5
fill ~68 ~76 ~29 ~68 ~77 ~29 planks 2
setblock ~68 ~76 ~30 birch_stairs 7
setblock ~68 ~76 ~31 birch_stairs 3
setblock ~68 ~76 ~32 stone_brick_stairs 6
fill ~69 ~76 ~29 ~69 ~77 ~29 planks 1
setblock ~69 ~76 ~33 stone_stairs 3
setblock ~70 ~76 ~29 birch_stairs 1
setblock ~70 ~76 ~30 planks 2
setblock ~58 ~77 ~36 oak_stairs 6
setblock ~58 ~77 ~37 planks 0
setblock ~58 ~77 ~38 birch_stairs 7
fill ~59 ~77 ~36 ~60 ~77 ~36 planks 0
fill ~59 ~77 ~38 ~59 ~78 ~38 planks 2
fill ~60 ~77 ~37 ~60 ~80 ~37 planks 1
setblock ~60 ~77 ~38 planks 0
setblock ~61 ~77 ~36 oak_stairs 5
fill ~61 ~77 ~37 ~61 ~79 ~37 planks 0
setblock ~61 ~77 ~38 birch_stairs 5
setblock ~68 ~77 ~28 birch_stairs 0
fill ~68 ~77 ~30 ~68 ~78 ~30 planks 2
setblock ~68 ~77 ~31 stonebrick 0
setblock ~68 ~77 ~32 stone_brick_stairs 3
setblock ~69 ~77 ~30 birch_stairs 7
setblock ~69 ~77 ~31 birch_stairs 6
setblock ~69 ~77 ~32 birch_stairs 3
setblock ~70 ~77 ~28 oak_stairs 1
setblock ~70 ~77 ~29 planks 2
setblock ~70 ~77 ~30 birch_stairs 5
setblock ~58 ~78 ~36 planks 0
setblock ~58 ~78 ~37 oak_stairs 3
setblock ~58 ~78 ~38 oak_stairs 6
setblock ~59 ~78 ~35 spruce_stairs 6
fill ~59 ~78 ~36 ~59 ~84 ~36 planks 1
setblock ~59 ~78 ~39 oak_stairs 4
setblock ~60 ~78 ~36 planks 0
setblock ~60 ~78 ~38 planks 2
setblock ~60 ~78 ~39 oak_stairs 5
setblock ~61 ~78 ~36 oak_stairs 2
fill ~61 ~78 ~38 ~61 ~79 ~38 planks 0
setblock ~68 ~78 ~29 oak_stairs 0
setblock ~68 ~78 ~31 planks 0
setblock ~68 ~78 ~32 wooden_slab 2
fill ~68 ~78 ~33 ~69 ~78 ~33 planks 0
setblock ~68 ~78 ~34 wooden_slab 8
setblock ~69 ~78 ~28 wooden_slab 0
setblock ~69 ~78 ~29 planks 2
setblock ~69 ~78 ~30 planks 1
setblock ~69 ~78 ~31 planks 2
setblock ~69 ~78 ~32 birch_stairs 7
setblock ~69 ~78 ~34 planks 0
setblock ~69 ~78 ~35 wooden_slab 8
setblock ~70 ~78 ~29 birch_stairs 2
setblock ~70 ~78 ~30 wooden_slab 8
setblock ~70 ~78 ~31 wooden_slab 2
fill ~70 ~78 ~32 ~70 ~79 ~32 oak_stairs 1
setblock ~70 ~78 ~33 oak_stairs 5
fill ~58 ~79 ~35 ~58 ~79 ~36 planks 1
setblock ~58 ~79 ~37 oak_stairs 2
setblock ~58 ~79 ~38 oak_stairs 3
setblock ~59 ~79 ~35 planks 0
fill ~59 ~79 ~38 ~60 ~79 ~38 planks 1
fill ~59 ~79 ~39 ~60 ~79 ~39 planks 0
setblock ~60 ~79 ~35 spruce_stairs 5
fill ~60 ~79 ~36 ~60 ~83 ~36 planks 1
setblock ~68 ~79 ~30 oak_stairs 0
setblock ~68 ~79 ~31 planks 2
setblock ~68 ~79 ~32 birch_stairs 7
fill ~68 ~79 ~33 ~68 ~78 ~33 planks 0
fill ~68 ~79 ~34 ~68 ~80 ~34 planks 0
setblock ~68 ~79 ~35 spruce_stairs 4
fill ~68 ~79 ~36 ~69 ~79 ~36 planks 0
setblock ~69 ~79 ~29 oak_stairs 2
setblock ~69 ~79 ~30 double_wooden_slab 0
setblock ~69 ~79 ~31 planks 1
setblock ~69 ~79 ~32 planks 0
fill ~69 ~79 ~33 ~69 ~80 ~33 planks 1
fill ~69 ~79 ~34 ~69 ~80 ~34 planks 1
setblock ~69 ~79 ~35 planks 0
setblock ~69 ~79 ~37 oak_stairs 7
setblock ~70 ~79 ~30 oak_stairs 1
setblock ~70 ~79 ~31 birch_stairs 5
fill ~70 ~79 ~33 ~70 ~80 ~33 planks 0
fill ~70 ~79 ~34 ~70 ~80 ~34 planks 0
setblock ~70 ~79 ~35 spruce_stairs 5
setblock ~70 ~79 ~36 oak_stairs 7
fill ~71 ~79 ~33 ~71 ~79 ~34 wooden_slab 8
setblock ~57 ~80 ~35 spruce_stairs 6
setblock ~57 ~80 ~36 planks 0
setblock ~57 ~80 ~37 spruce_stairs 7
fill ~58 ~80 ~34 ~59 ~80 ~34 planks 1
setblock ~58 ~80 ~35 planks 0
fill ~58 ~80 ~36 ~58 ~81 ~36 planks 1
fill ~58 ~80 ~37 ~58 ~80 ~38 planks 1
fill ~59 ~80 ~35 ~60 ~80 ~35 planks 1
fill ~59 ~80 ~38 ~60 ~80 ~38 planks 1
setblock ~59 ~80 ~39 oak_stairs 0
setblock ~60 ~80 ~39 oak_stairs 1
setblock ~61 ~80 ~36 planks 0
setblock ~61 ~80 ~37 planks 1
setblock ~61 ~80 ~38 oak_stairs 1
setblock ~67 ~80 ~36 spruce_stairs 4
fill ~68 ~80 ~32 ~68 ~80 ~33 oak_stairs 0
fill ~68 ~80 ~35 ~68 ~80 ~36 planks 0
setblock ~68 ~80 ~37 planks 1
setblock ~69 ~80 ~30 wooden_slab 0
setblock ~69 ~80 ~31 oak_stairs 2
setblock ~69 ~80 ~32 planks 2
fill ~69 ~80 ~35 ~69 ~87 ~35 planks 1
fill ~69 ~80 ~36 ~69 ~84 ~36 planks 1
setblock ~69 ~80 ~37 planks 0
setblock ~69 ~80 ~38 oak_stairs 7
setblock ~70 ~80 ~32 wooden_slab 0
fill ~70 ~80 ~35 ~71 ~80 ~35 planks 0
fill ~70 ~80 ~36 ~70 ~80 ~33 planks 0
setblock ~70 ~80 ~37 spruce_stairs 5
setblock ~71 ~80 ~34 spruce_stairs 1
setblock ~71 ~80 ~36 oak_stairs 5
setblock ~57 ~81 ~34 planks 5
fill ~57 ~81 ~35 ~61 ~81 ~35 planks 1
fill ~57 ~81 ~36 ~57 ~81 ~35 planks 1
setblock ~57 ~81 ~37 spruce_stairs 0
setblock ~58 ~81 ~33 planks 5
fill ~58 ~81 ~34 ~58 ~80 ~34 planks 1
setblock ~58 ~81 ~37 planks 0
setblock ~59 ~81 ~34 planks 5
fill ~59 ~81 ~38 ~59 ~79 ~38 planks 1
setblock ~60 ~81 ~34 dark_oak_stairs 5
fill ~60 ~81 ~37 ~61 ~81 ~37 planks 0
setblock ~60 ~81 ~38 spruce_stairs 1
fill ~61 ~81 ~36 ~61 ~83 ~36 planks 1
setblock ~64 ~81 ~56 dark_oak_stairs 3
fill ~67 ~81 ~35 ~70 ~81 ~35 planks 1
fill ~67 ~81 ~36 ~71 ~81 ~36 planks 1
setblock ~67 ~81 ~37 spruce_stairs 7
setblock ~68 ~81 ~34 dark_oak_stairs 4
setblock ~68 ~81 ~37 planks 0
setblock ~68 ~81 ~38 oak_stairs 0
setblock ~69 ~81 ~33 wooden_slab 0
setblock ~69 ~81 ~34 planks 5
fill ~69 ~81 ~37 ~69 ~81 ~38 planks 1
setblock ~70 ~81 ~33 planks 5
setblock ~70 ~81 ~34 planks 1
setblock ~70 ~81 ~37 planks 0
setblock ~70 ~81 ~38 oak_stairs 1
setblock ~71 ~81 ~34 planks 5
setblock ~71 ~81 ~35 planks 0
setblock ~71 ~81 ~37 spruce_stairs 1
setblock ~56 ~82 ~53 wooden_slab 13
setblock ~56 ~82 ~54 wooden_slab 5
fill ~57 ~82 ~33 ~59 ~82 ~33 planks 1
setblock ~57 ~82 ~34 dark_oak_stairs 6
setblock ~57 ~82 ~35 planks 1
setblock ~57 ~82 ~36 planks 5
setblock ~57 ~82 ~53 planks 5
setblock ~58 ~82 ~32 dark_oak_stairs 6
setblock ~58 ~82 ~37 planks 1
fill ~59 ~82 ~34 ~61 ~82 ~34 planks 1
fill ~59 ~82 ~35 ~61 ~82 ~35 planks 1
setblock ~59 ~82 ~37 planks 0
setblock ~60 ~82 ~32 wooden_slab 8
setblock ~60 ~82 ~37 planks 1
setblock ~61 ~82 ~31 wooden_slab 8
setblock ~61 ~82 ~33 oak_stairs 4
setblock ~62 ~82 ~32 oak_stairs 4
fill ~62 ~82 ~33 ~66 ~82 ~33 planks 0
setblock ~62 ~82 ~34 wooden_slab 8
fill ~63 ~82 ~30 ~65 ~82 ~30 wooden_slab 8
fill ~63 ~82 ~31 ~65 ~82 ~31 planks 0
fill ~63 ~82 ~32 ~65 ~82 ~32 planks 0
fill ~63 ~82 ~34 ~65 ~82 ~34 planks 0
setblock ~63 ~82 ~35 wooden_slab 8
setblock ~63 ~82 ~54 dark_oak_stairs 0
setblock ~63 ~82 ~55 dark_oak_stairs 3
setblock ~64 ~82 ~35 oak_stairs 7
setblock ~64 ~82 ~55 planks 5
setblock ~64 ~82 ~56 wooden_slab 5
setblock ~65 ~82 ~35 wooden_slab 8
setblock ~65 ~82 ~54 dark_oak_stairs 1
setblock ~65 ~82 ~55 dark_oak_stairs 3
setblock ~66 ~82 ~32 oak_stairs 5
setblock ~66 ~82 ~34 wooden_slab 8
setblock ~67 ~82 ~31 wooden_slab 8
setblock ~67 ~82 ~33 oak_stairs 5
fill ~67 ~82 ~34 ~69 ~82 ~34 planks 1
fill ~67 ~82 ~35 ~69 ~82 ~35 planks 1
fill ~67 ~82 ~36 ~69 ~82 ~36 planks 1
setblock ~68 ~82 ~32 wooden_slab 8
setblock ~68 ~82 ~33 planks 0
setblock ~68 ~82 ~37 planks 1
fill ~69 ~82 ~33 ~71 ~82 ~33 planks 1
setblock ~69 ~82 ~37 planks 0
setblock ~69 ~82 ~38 oak_stairs 3
setblock ~70 ~82 ~32 dark_oak_stairs 6
setblock ~70 ~82 ~37 planks 1
setblock ~71 ~82 ~34 dark_oak_stairs 6
setblock ~71 ~82 ~35 planks 1
setblock ~71 ~82 ~36 planks 5
setblock ~71 ~82 ~53 planks 5
setblock ~72 ~82 ~53 wooden_slab 13
setblock ~72 ~82 ~54 wooden_slab 5
setblock ~50 ~83 ~45 planks 5
setblock ~52 ~83 ~51 planks 5
fill ~56 ~83 ~50 ~56 ~83 ~51 planks 5
setblock ~57 ~83 ~32 spruce_stairs 6
setblock ~57 ~83 ~33 spruce_stairs 7
setblock ~57 ~83 ~34 planks 1
fill ~57 ~83 ~35 ~57 ~85 ~35 planks 5
setblock ~57 ~83 ~36 spruce_stairs 0
fill ~57 ~83 ~51 ~57 ~83 ~52 planks 5
setblock ~57 ~83 ~53 wooden_slab 5
setblock ~58 ~83 ~32 planks 5
fill ~58 ~83 ~33 ~58 ~84 ~33 planks 1
setblock ~58 ~83 ~36 planks 1
setblock ~58 ~83 ~53 planks 5
setblock ~59 ~83 ~32 dark_oak_stairs 5
setblock ~59 ~83 ~33 planks 5
fill ~59 ~83 ~34 ~61 ~83 ~34 planks 1
fill ~59 ~83 ~35 ~61 ~83 ~35 planks 1
setblock ~59 ~83 ~37 planks 1
setblock ~60 ~83 ~30 wooden_slab 8
fill ~60 ~83 ~31 ~62 ~83 ~31 planks 0
fill ~60 ~83 ~32 ~60 ~83 ~31 planks 0
setblock ~60 ~83 ~33 planks 1
setblock ~61 ~83 ~29 wooden_slab 8
fill ~61 ~83 ~30 ~67 ~83 ~30 planks 0
setblock ~61 ~83 ~32 oak_stairs 4
setblock ~61 ~83 ~33 oak_stairs 6
fill ~62 ~83 ~29 ~66 ~83 ~29 planks 0
fill ~62 ~83 ~32 ~62 ~84 ~32 planks 0
fill ~62 ~83 ~33 ~62 ~84 ~33 planks 0
fill ~62 ~83 ~34 ~62 ~83 ~35 planks 0
setblock ~62 ~83 ~36 wooden_slab 8
setblock ~62 ~83 ~52 spruce_stairs 4
setblock ~63 ~83 ~28 wooden_slab 8
fill ~63 ~83 ~35 ~66 ~83 ~35 planks 0
fill ~63 ~83 ~36 ~65 ~83 ~36 planks 0
setblock ~63 ~83 ~53 planks 5
setblock ~63 ~83 ~54 wooden_slab 5
setblock ~64 ~83 ~28 oak_stairs 6
setblock ~64 ~83 ~37 wooden_slab 8
setblock ~64 ~83 ~54 dark_oak_stairs 3
setblock ~65 ~83 ~28 wooden_slab 8
setblock ~65 ~83 ~53 planks 5
setblock ~65 ~83 ~54 wooden_slab 5
fill ~66 ~83 ~31 ~68 ~83 ~31 planks 0
fill ~66 ~83 ~32 ~66 ~84 ~32 planks 0
fill ~66 ~83 ~33 ~66 ~84 ~33 planks 0
fill ~66 ~83 ~34 ~66 ~83 ~29 planks 0
setblock ~66 ~83 ~36 wooden_slab 8
setblock ~66 ~83 ~52 spruce_stairs 5
setblock ~67 ~83 ~29 wooden_slab 8
setblock ~67 ~83 ~32 oak_stairs 5
setblock ~67 ~83 ~33 oak_stairs 6
fill ~67 ~83 ~34 ~69 ~83 ~34 planks 1
fill ~67 ~83 ~35 ~69 ~83 ~35 planks 1
fill ~67 ~83 ~36 ~70 ~83 ~36 planks 1
setblock ~68 ~83 ~30 wooden_slab 8
setblock ~68 ~83 ~32 planks 0
setblock ~68 ~83 ~33 planks 1
setblock ~69 ~83 ~32 dark_oak_stairs 4
setblock ~69 ~83 ~33 planks 5
setblock ~69 ~83 ~37 planks 1
setblock ~70 ~83 ~32 planks 5
fill ~70 ~83 ~33 ~70 ~84 ~33 planks 1
setblock ~70 ~83 ~53 planks 5
setblock ~71 ~83 ~32 spruce_stairs 6
setblock ~71 ~83 ~33 spruce_stairs 7
setblock ~71 ~83 ~34 planks 1
fill ~71 ~83 ~35 ~71 ~85 ~35 planks 5
setblock ~71 ~83 ~36 spruce_stairs 1
fill ~71 ~83 ~51 ~72 ~83 ~51 planks 5
fill ~71 ~83 ~52 ~71 ~83 ~51 planks 5
setblock ~71 ~83 ~53 wooden_slab 5
setblock ~72 ~83 ~50 planks 5
setblock ~76 ~83 ~51 planks 5
setblock ~78 ~83 ~45 planks 5
setblock ~50 ~84 ~44 wooden_slab 5
fill ~51 ~84 ~43 ~51 ~85 ~43 wooden_slab 13
setblock ~51 ~84 ~44 planks 5
setblock ~51 ~84 ~45 double_wooden_slab 5
setblock ~52 ~84 ~50 wooden_slab 5
fill ~53 ~84 ~49 ~53 ~84 ~50 planks 5
setblock ~53 ~84 ~51 wooden_slab 5
setblock ~54 ~84 ~50 planks 5
setblock ~56 ~84 ~49 double_wooden_slab 1
setblock ~56 ~84 ~50 wooden_slab 5
setblock ~57 ~84 ~31 spruce_stairs 4
fill ~57 ~84 ~32 ~60 ~84 ~32 planks 1
setblock ~57 ~84 ~33 spruce_stairs 0
setblock ~57 ~84 ~34 dark_oak_stairs 6
setblock ~57 ~84 ~49 planks 5
setblock ~57 ~84 ~50 planks 1
setblock ~57 ~84 ~51 wooden_slab 5
setblock ~58 ~84 ~31 planks 5
fill ~58 ~84 ~34 ~58 ~86 ~34 planks 1
fill ~58 ~84 ~35 ~61 ~84 ~35 planks 1
setblock ~58 ~84 ~36 planks 5
fill ~58 ~84 ~50 ~58 ~84 ~51 planks 5
fill ~58 ~84 ~52 ~59 ~84 ~52 wooden_slab 5
fill ~59 ~84 ~31 ~60 ~84 ~31 planks 0
setblock ~59 ~84 ~51 planks 1
fill ~60 ~84 ~29 ~62 ~84 ~29 planks 0
fill ~60 ~84 ~30 ~62 ~84 ~30 planks 0
fill ~60 ~84 ~33 ~60 ~85 ~33 planks 0
fill ~60 ~84 ~34 ~61 ~84 ~34 planks 1
setblock ~60 ~84 ~36 planks 5
setblock ~60 ~84 ~50 planks 5
fill ~61 ~84 ~28 ~63 ~84 ~28 planks 0
setblock ~61 ~84 ~32 oak_stairs 6
fill ~61 ~84 ~33 ~61 ~87 ~33 planks 1
fill ~61 ~84 ~36 ~62 ~84 ~36 planks 0
setblock ~61 ~84 ~37 wooden_slab 8
setblock ~62 ~84 ~27 wooden_slab 8
setblock ~62 ~84 ~35 planks 0
fill ~62 ~84 ~37 ~66 ~84 ~37 planks 0
setblock ~62 ~84 ~38 wooden_slab 8
setblock ~62 ~84 ~50 planks 1
setblock ~62 ~84 ~51 dark_oak_stairs 0
setblock ~63 ~84 ~26 wooden_slab 8
fill ~63 ~84 ~27 ~65 ~84 ~27 planks 0
fill ~63 ~84 ~38 ~65 ~84 ~38 planks 0
fill ~63 ~84 ~39 ~63 ~85 ~39 wooden_slab 8
setblock ~63 ~84 ~51 planks 5
setblock ~63 ~84 ~52 spruce_stairs 0
setblock ~64 ~84 ~26 oak_stairs 6
setblock ~64 ~84 ~52 planks 5
setblock ~64 ~84 ~53 dark_oak_stairs 3
setblock ~65 ~84 ~26 wooden_slab 8
fill ~65 ~84 ~28 ~67 ~84 ~28 planks 0
fill ~65 ~84 ~39 ~65 ~85 ~39 wooden_slab 8
setblock ~65 ~84 ~51 planks 5
setblock ~65 ~84 ~52 spruce_stairs 1
setblock ~66 ~84 ~27 wooden_slab 8
fill ~66 ~84 ~29 ~68 ~84 ~29 planks 0
fill ~66 ~84 ~30 ~68 ~84 ~30 planks 0
fill ~66 ~84 ~35 ~66 ~84 ~37 planks 0
setblock ~66 ~84 ~38 wooden_slab 8
setblock ~66 ~84 ~50 planks 1
setblock ~66 ~84 ~51 dark_oak_stairs 1
setblock ~67 ~84 ~32 oak_stairs 6
fill ~67 ~84 ~33 ~67 ~87 ~33 planks 1
fill ~67 ~84 ~34 ~68 ~84 ~34 planks 1
fill ~67 ~84 ~35 ~70 ~84 ~35 planks 1
fill ~67 ~84 ~36 ~67 ~86 ~36 planks 0
setblock ~67 ~84 ~37 wooden_slab 8
fill ~68 ~84 ~31 ~69 ~84 ~31 planks 0
fill ~68 ~84 ~32 ~71 ~84 ~32 planks 1
fill ~68 ~84 ~33 ~68 ~85 ~33 planks 0
setblock ~68 ~84 ~36 planks 5
setblock ~68 ~84 ~50 planks 5
setblock ~69 ~84 ~51 planks 1
fill ~69 ~84 ~52 ~70 ~84 ~52 wooden_slab 5
setblock ~70 ~84 ~31 planks 5
fill ~70 ~84 ~34 ~70 ~86 ~34 planks 1
setblock ~70 ~84 ~36 planks 5
fill ~70 ~84 ~50 ~70 ~84 ~51 planks 5
setblock ~71 ~84 ~31 spruce_stairs 5
setblock ~71 ~84 ~33 spruce_stairs 1
setblock ~71 ~84 ~34 dark_oak_stairs 6
setblock ~71 ~84 ~49 planks 5
setblock ~71 ~84 ~50 planks 1
setblock ~71 ~84 ~51 wooden_slab 5
setblock ~72 ~84 ~49 double_wooden_slab 1
setblock ~72 ~84 ~50 wooden_slab 5
fill ~74 ~84 ~50 ~75 ~84 ~50 planks 5
setblock ~75 ~84 ~49 planks 5
setblock ~75 ~84 ~51 wooden_slab 5
setblock ~76 ~84 ~50 wooden_slab 5
fill ~77 ~84 ~43 ~77 ~85 ~43 wooden_slab 13
setblock ~77 ~84 ~44 planks 5
setblock ~77 ~84 ~45 double_wooden_slab 5
setblock ~78 ~84 ~44 wooden_slab 5
setblock ~51 ~85 ~44 wooden_slab 5
setblock ~52 ~85 ~41 wooden_slab 9
fill ~52 ~85 ~42 ~52 ~85 ~43 planks 5
setblock ~52 ~85 ~44 double_wooden_slab 5
setblock ~52 ~85 ~45 wooden_slab 5
setblock ~54 ~85 ~48 planks 1
setblock ~54 ~85 ~49 planks 5
setblock ~55 ~85 ~49 planks 1
setblock ~57 ~85 ~30 dark_oak_stairs 4
setblock ~57 ~85 ~31 spruce_stairs 3
fill ~57 ~85 ~32 ~61 ~85 ~32 planks 1
setblock ~57 ~85 ~33 dark_oak_stairs 2
fill ~57 ~85 ~34 ~57 ~86 ~34 planks 5
fill ~57 ~85 ~47 ~57 ~85 ~48 planks 1
setblock ~57 ~85 ~49 wooden_slab 5
fill ~58 ~85 ~30 ~58 ~86 ~30 dark_oak_stairs 5
fill ~58 ~85 ~31 ~58 ~86 ~31 double_wooden_slab 5
fill ~58 ~85 ~33 ~58 ~87 ~33 planks 5
fill ~58 ~85 ~35 ~61 ~85 ~35 planks 1
fill ~58 ~85 ~36 ~58 ~85 ~34 planks 1
setblock ~58 ~85 ~49 planks 5
setblock ~58 ~85 ~50 wooden_slab 1
setblock ~59 ~85 ~29 wooden_slab 8
fill ~59 ~85 ~30 ~59 ~90 ~30 planks 0
fill ~59 ~85 ~31 ~59 ~88 ~31 planks 1
fill ~59 ~85 ~34 ~61 ~85 ~34 planks 1
setblock ~59 ~85 ~36 planks 5
setblock ~59 ~85 ~50 planks 5
fill ~60 ~85 ~28 ~62 ~85 ~28 planks 0
fill ~60 ~85 ~29 ~60 ~89 ~29 planks 0
setblock ~60 ~85 ~36 planks 1
fill ~60 ~85 ~37 ~62 ~85 ~37 planks 0
setblock ~60 ~85 ~38 wooden_slab 8
setblock ~60 ~85 ~49 planks 1
fill ~61 ~85 ~27 ~63 ~85 ~27 planks 0
fill ~61 ~85 ~36 ~62 ~85 ~36 planks 0
fill ~61 ~85 ~38 ~63 ~85 ~38 planks 0
setblock ~61 ~85 ~48 planks 1
setblock ~62 ~85 ~26 wooden_slab 8
setblock ~62 ~85 ~39 wooden_slab 0
setblock ~62 ~85 ~49 planks 1
setblock ~62 ~85 ~50 spruce_stairs 0
setblock ~63 ~85 ~25 oak_stairs 4
fill ~63 ~85 ~26 ~63 ~86 ~26 planks 0
setblock ~63 ~85 ~50 planks 1
setblock ~63 ~85 ~51 wooden_slab 5
setblock ~64 ~85 ~25 dark_oak_stairs 6
setblock ~64 ~85 ~39 planks 0
setblock ~64 ~85 ~51 planks 1
setblock ~64 ~85 ~52 wooden_slab 5
setblock ~65 ~85 ~25 oak_stairs 5
fill ~65 ~85 ~26 ~65 ~86 ~26 planks 0
fill ~65 ~85 ~27 ~67 ~85 ~27 planks 0
fill ~65 ~85 ~38 ~67 ~85 ~38 planks 0
setblock ~65 ~85 ~50 planks 1
setblock ~65 ~85 ~51 wooden_slab 5
setblock ~66 ~85 ~26 wooden_slab 8
fill ~66 ~85 ~28 ~68 ~85 ~28 planks 0
fill ~66 ~85 ~36 ~66 ~85 ~38 planks 0
setblock ~66 ~85 ~39 wooden_slab 0
setblock ~66 ~85 ~49 planks 1
setblock ~66 ~85 ~50 spruce_stairs 1
fill ~67 ~85 ~32 ~71 ~85 ~32 planks 1
fill ~67 ~85 ~34 ~70 ~85 ~34 planks 1
fill ~67 ~85 ~35 ~70 ~85 ~35 planks 1
fill ~67 ~85 ~37 ~68 ~85 ~37 planks 0
setblock ~67 ~85 ~48 planks 1
fill ~68 ~85 ~29 ~68 ~89 ~29 planks 0
setblock ~68 ~85 ~36 planks 1
setblock ~68 ~85 ~38 wooden_slab 8
setblock ~68 ~85 ~49 planks 1
setblock ~69 ~85 ~29 wooden_slab 8
fill ~69 ~85 ~30 ~69 ~90 ~30 planks 0
fill ~69 ~85 ~31 ~69 ~88 ~31 planks 1
setblock ~69 ~85 ~36 planks 5
setblock ~69 ~85 ~50 planks 5
fill ~70 ~85 ~30 ~70 ~86 ~30 dark_oak_stairs 4
fill ~70 ~85 ~31 ~70 ~86 ~31 double_wooden_slab 5
fill ~70 ~85 ~33 ~70 ~87 ~33 planks 5
setblock ~70 ~85 ~36 planks 1
setblock ~70 ~85 ~49 planks 5
setblock ~70 ~85 ~50 wooden_slab 1
setblock ~71 ~85 ~30 dark_oak_stairs 5
setblock ~71 ~85 ~31 spruce_stairs 3
setblock ~71 ~85 ~33 dark_oak_stairs 2
fill ~71 ~85 ~34 ~71 ~86 ~34 planks 5
fill ~71 ~85 ~47 ~71 ~85 ~48 planks 1
setblock ~71 ~85 ~49 wooden_slab 5
setblock ~73 ~85 ~49 planks 1
setblock ~74 ~85 ~48 planks 1
setblock ~74 ~85 ~49 planks 5
setblock ~76 ~85 ~41 wooden_slab 9
fill ~76 ~85 ~42 ~76 ~85 ~43 planks 5
setblock ~76 ~85 ~44 double_wooden_slab 5
setblock ~76 ~85 ~45 wooden_slab 5
setblock ~77 ~85 ~44 wooden_slab 5
fill ~50 ~86 ~36 ~50 ~88 ~36 planks 5
setblock ~52 ~86 ~42 wooden_slab 13
setblock ~52 ~86 ~43 wooden_slab 1
setblock ~53 ~86 ~40 wooden_slab 9
setblock ~53 ~86 ~41 double_wooden_slab 1
fill ~53 ~86 ~42 ~53 ~86 ~43 planks 5
setblock ~53 ~86 ~44 wooden_slab 1
setblock ~54 ~86 ~47 planks 5
setblock ~55 ~86 ~48 planks 5
setblock ~56 ~86 ~48 planks 1
setblock ~57 ~86 ~30 planks 5
setblock ~57 ~86 ~31 spruce_stairs 2
setblock ~57 ~86 ~32 planks 5
setblock ~57 ~86 ~33 dark_oak_stairs 6
setblock ~57 ~86 ~35 dark_oak_stairs 3
setblock ~57 ~86 ~47 spruce_stairs 0
fill ~58 ~86 ~28 ~58 ~87 ~28 wooden_slab 8
setblock ~58 ~86 ~29 oak_stairs 0
fill ~58 ~86 ~32 ~61 ~86 ~32 planks 1
fill ~58 ~86 ~35 ~58 ~88 ~35 planks 5
setblock ~58 ~86 ~36 dark_oak_stairs 0
setblock ~58 ~86 ~45 oak_stairs 6
setblock ~58 ~86 ~46 planks 0
setblock ~58 ~86 ~47 wooden_slab 9
setblock ~58 ~86 ~48 wooden_slab 1
fill ~59 ~86 ~28 ~61 ~86 ~28 planks 0
fill ~59 ~86 ~29 ~59 ~89 ~29 planks 0
fill ~59 ~86 ~33 ~61 ~86 ~33 planks 1
fill ~59 ~86 ~34 ~59 ~87 ~34 planks 0
fill ~59 ~86 ~35 ~60 ~86 ~35 planks 1
fill ~59 ~86 ~36 ~59 ~86 ~35 planks 1
setblock ~59 ~86 ~37 oak_stairs 4
setblock ~59 ~86 ~48 wooden_slab 9
setblock ~59 ~86 ~49 wooden_slab 1
fill ~60 ~86 ~27 ~62 ~86 ~27 planks 0
fill ~60 ~86 ~31 ~60 ~87 ~31 planks 1
fill ~60 ~86 ~34 ~61 ~86 ~34 planks 1
setblock ~60 ~86 ~36 dark_oak_stairs 1
fill ~60 ~86 ~37 ~62 ~86 ~37 planks 0
setblock ~60 ~86 ~38 oak_stairs 4
setblock ~60 ~86 ~48 spruce_stairs 3
fill ~61 ~86 ~24 ~61 ~87 ~24 planks 5
fill ~61 ~86 ~26 ~63 ~86 ~26 planks 0
fill ~61 ~86 ~36 ~61 ~84 ~36 planks 0
fill ~61 ~86 ~38 ~63 ~86 ~38 planks 0
setblock ~61 ~86 ~39 wooden_slab 0
setblock ~61 ~86 ~47 planks 1
setblock ~62 ~86 ~23 dark_oak_stairs 5
setblock ~62 ~86 ~24 dark_oak_stairs 7
setblock ~62 ~86 ~25 planks 5
fill ~62 ~86 ~39 ~63 ~86 ~39 planks 0
setblock ~62 ~86 ~40 wooden_slab 0
setblock ~62 ~86 ~47 planks 0
setblock ~62 ~86 ~48 spruce_stairs 0
setblock ~63 ~86 ~24 dark_oak_stairs 4
setblock ~63 ~86 ~25 planks 0
setblock ~63 ~86 ~40 wooden_slab 8
fill ~63 ~86 ~48 ~63 ~86 ~49 planks 1
fill ~64 ~86 ~22 ~64 ~86 ~23 spruce_stairs 6
setblock ~64 ~86 ~24 dark_oak_stairs 7
setblock ~64 ~86 ~25 planks 5
setblock ~64 ~86 ~26 wooden_slab 13
fill ~64 ~86 ~40 ~64 ~90 ~40 planks 0
setblock ~64 ~86 ~41 wooden_slab 8
fill ~64 ~86 ~49 ~65 ~86 ~49 planks 1
setblock ~64 ~86 ~50 dark_oak_stairs 3
setblock ~65 ~86 ~24 dark_oak_stairs 5
setblock ~65 ~86 ~25 planks 0
fill ~65 ~86 ~38 ~67 ~86 ~38 planks 0
fill ~65 ~86 ~39 ~66 ~86 ~39 planks 0
setblock ~65 ~86 ~40 wooden_slab 8
setblock ~65 ~86 ~48 planks 1
setblock ~66 ~86 ~23 dark_oak_stairs 4
setblock ~66 ~86 ~24 dark_oak_stairs 7
setblock ~66 ~86 ~25 planks 5
fill ~66 ~86 ~26 ~67 ~86 ~26 planks 0
fill ~66 ~86 ~27 ~68 ~86 ~27 planks 0
fill ~66 ~86 ~37 ~68 ~86 ~37 planks 0
setblock ~66 ~86 ~40 wooden_slab 0
setblock ~66 ~86 ~47 planks 0
setblock ~66 ~86 ~48 spruce_stairs 1
fill ~67 ~86 ~24 ~67 ~87 ~24 planks 5
fill ~67 ~86 ~28 ~69 ~86 ~28 planks 0
fill ~67 ~86 ~32 ~70 ~86 ~32 planks 1
fill ~67 ~86 ~34 ~68 ~86 ~34 planks 1
setblock ~67 ~86 ~39 wooden_slab 0
setblock ~67 ~86 ~47 planks 1
fill ~68 ~86 ~31 ~68 ~87 ~31 planks 1
fill ~68 ~86 ~33 ~69 ~86 ~33 planks 1
fill ~68 ~86 ~35 ~68 ~87 ~35 planks 1
setblock ~68 ~86 ~36 dark_oak_stairs 0
setblock ~68 ~86 ~38 oak_stairs 5
setblock ~68 ~86 ~48 spruce_stairs 3
fill ~69 ~86 ~29 ~69 ~89 ~29 planks 0
fill ~69 ~86 ~34 ~69 ~87 ~34 planks 0
setblock ~69 ~86 ~36 planks 1
setblock ~69 ~86 ~37 oak_stairs 5
setblock ~69 ~86 ~48 wooden_slab 9
setblock ~69 ~86 ~49 wooden_slab 1
fill ~70 ~86 ~28 ~70 ~87 ~28 wooden_slab 8
setblock ~70 ~86 ~29 oak_stairs 1
fill ~70 ~86 ~35 ~70 ~88 ~35 planks 5
setblock ~70 ~86 ~36 dark_oak_stairs 1
setblock ~70 ~86 ~45 oak_stairs 6
setblock ~70 ~86 ~46 planks 0
setblock ~70 ~86 ~47 wooden_slab 9
setblock ~70 ~86 ~48 wooden_slab 1
setblock ~71 ~86 ~30 planks 5
setblock ~71 ~86 ~31 spruce_stairs 2
setblock ~71 ~86 ~32 planks 5
setblock ~71 ~86 ~33 dark_oak_stairs 6
setblock ~71 ~86 ~35 dark_oak_stairs 3
setblock ~71 ~86 ~47 spruce_stairs 1
setblock ~72 ~86 ~48 planks 1
setblock ~73 ~86 ~48 planks 5
setblock ~74 ~86 ~47 planks 5
setblock ~75 ~86 ~40 wooden_slab 9
setblock ~75 ~86 ~41 double_wooden_slab 1
fill ~75 ~86 ~42 ~75 ~86 ~43 planks 5
setblock ~75 ~86 ~44 wooden_slab 1
setblock ~76 ~86 ~42 wooden_slab 13
setblock ~76 ~86 ~43 wooden_slab 1
fill ~78 ~86 ~36 ~78 ~88 ~36 planks 5
setblock ~51 ~87 ~36 planks 5
setblock ~53 ~87 ~41 wooden_slab 9
setblock ~53 ~87 ~42 wooden_slab 1
setblock ~54 ~87 ~39 wooden_slab 8
fill ~54 ~87 ~40 ~54 ~87 ~42 double_wooden_slab 1
setblock ~54 ~87 ~43 wooden_slab 1
setblock ~55 ~87 ~45 double_wooden_slab 1
setblock ~55 ~87 ~46 planks 1
setblock ~55 ~87 ~47 wooden_slab 1
setblock ~56 ~87 ~47 wooden_slab 9
setblock ~56 ~87 ~48 wooden_slab 5
setblock ~57 ~87 ~30 double_stone_slab 5
setblock ~57 ~87 ~31 dark_oak_stairs 6
setblock ~57 ~87 ~32 spruce_stairs 2
setblock ~57 ~87 ~33 dark_oak_stairs 3
setblock ~57 ~87 ~34 dark_oak_stairs 6
setblock ~57 ~87 ~35 dark_oak_stairs 0
setblock ~57 ~87 ~47 double_wooden_slab 1
setblock ~58 ~87 ~29 wooden_slab 0
setblock ~58 ~87 ~30 dark_oak_stairs 2
fill ~58 ~87 ~31 ~58 ~88 ~31 wooden_slab 5
setblock ~58 ~87 ~32 double_wooden_slab 5
setblock ~58 ~87 ~34 planks 5
setblock ~58 ~87 ~36 wooden_slab 8
setblock ~58 ~87 ~37 double_wooden_slab 0
setblock ~58 ~87 ~45 spruce_stairs 0
setblock ~58 ~87 ~46 wooden_slab 0
setblock ~59 ~87 ~27 oak_stairs 2
fill ~59 ~87 ~28 ~61 ~87 ~28 planks 0
fill ~59 ~87 ~32 ~60 ~87 ~32 planks 1
fill ~59 ~87 ~33 ~61 ~87 ~33 planks 1
fill ~59 ~87 ~35 ~60 ~87 ~35 planks 1
setblock ~59 ~87 ~36 dark_oak_stairs 3
fill ~59 ~87 ~37 ~60 ~87 ~37 planks 0
setblock ~59 ~87 ~38 oak_stairs 7
setblock ~59 ~87 ~44 planks 0
setblock ~59 ~87 ~46 double_wooden_slab 1
setblock ~59 ~87 ~47 wooden_slab 0
setblock ~60 ~87 ~22 dark_oak_stairs 4
setblock ~60 ~87 ~24 wooden_slab 9
fill ~60 ~87 ~25 ~61 ~87 ~25 planks 5
fill ~60 ~87 ~27 ~62 ~87 ~27 planks 0
fill ~60 ~87 ~34 ~60 ~88 ~34 planks 1
setblock ~60 ~87 ~36 planks 0
fill ~60 ~87 ~38 ~61 ~87 ~38 planks 0
setblock ~60 ~87 ~39 wooden_slab 0
setblock ~60 ~87 ~47 oak_stairs 3
setblock ~61 ~87 ~22 dark_oak_stairs 6
setblock ~61 ~87 ~23 planks 5
setblock ~61 ~87 ~26 planks 5
fill ~61 ~87 ~39 ~62 ~87 ~39 planks 0
setblock ~61 ~87 ~40 wooden_slab 8
setblock ~61 ~87 ~46 planks 0
setblock ~62 ~87 ~20 spruce_stairs 5
fill ~62 ~87 ~21 ~62 ~87 ~22 wooden_slab 8
fill ~62 ~87 ~23 ~63 ~87 ~23 planks 0
fill ~62 ~87 ~24 ~62 ~87 ~23 planks 0
fill ~62 ~87 ~40 ~66 ~87 ~40 planks 0
setblock ~62 ~87 ~41 wooden_slab 8
fill ~62 ~87 ~45 ~63 ~87 ~45 wooden_slab 8
fill ~62 ~87 ~46 ~63 ~87 ~46 planks 1
setblock ~62 ~87 ~47 wooden_slab 0
setblock ~63 ~87 ~19 wooden_slab 9
setblock ~63 ~87 ~21 spruce_stairs 6
fill ~63 ~87 ~22 ~65 ~87 ~22 planks 0
fill ~63 ~87 ~41 ~65 ~87 ~41 planks 0
setblock ~63 ~87 ~42 wooden_slab 8
fill ~63 ~87 ~47 ~65 ~87 ~47 planks 0
setblock ~63 ~87 ~48 wooden_slab 1
setblock ~64 ~87 ~20 wooden_slab 8
setblock ~64 ~87 ~21 planks 0
fill ~64 ~87 ~42 ~64 ~89 ~42 planks 0
setblock ~64 ~87 ~43 oak_stairs 7
setblock ~64 ~87 ~46 wooden_slab 9
setblock ~64 ~87 ~48 planks 1
setblock ~64 ~87 ~49 wooden_slab 1
setblock ~65 ~87 ~19 wooden_slab 9
setblock ~65 ~87 ~21 spruce_stairs 6
fill ~65 ~87 ~23 ~66 ~87 ~23 planks 0
setblock ~65 ~87 ~42 wooden_slab 8
fill ~65 ~87 ~45 ~66 ~87 ~45 wooden_slab 8
fill ~65 ~87 ~46 ~66 ~87 ~46 planks 1
setblock ~65 ~87 ~48 wooden_slab 1
setblock ~66 ~87 ~20 spruce_stairs 4
fill ~66 ~87 ~21 ~66 ~87 ~22 wooden_slab 8
setblock ~66 ~87 ~24 planks 0
fill ~66 ~87 ~27 ~68 ~87 ~27 planks 0
fill ~66 ~87 ~39 ~67 ~87 ~39 planks 0
setblock ~66 ~87 ~41 wooden_slab 8
setblock ~66 ~87 ~47 wooden_slab 0
setblock ~67 ~87 ~22 dark_oak_stairs 6
setblock ~67 ~87 ~23 planks 5
fill ~67 ~87 ~25 ~68 ~87 ~25 planks 5
fill ~67 ~87 ~26 ~67 ~87 ~23 planks 5
fill ~67 ~87 ~28 ~69 ~87 ~28 planks 0
fill ~67 ~87 ~38 ~68 ~87 ~38 planks 0
setblock ~67 ~87 ~40 wooden_slab 8
setblock ~67 ~87 ~46 planks 0
setblock ~68 ~87 ~22 dark_oak_stairs 5
setblock ~68 ~87 ~24 wooden_slab 9
fill ~68 ~87 ~32 ~69 ~87 ~32 planks 1
fill ~68 ~87 ~33 ~69 ~87 ~33 planks 1
fill ~68 ~87 ~34 ~68 ~88 ~34 planks 1
fill ~68 ~87 ~36 ~68 ~87 ~38 planks 0
setblock ~68 ~87 ~39 wooden_slab 0
setblock ~68 ~87 ~47 oak_stairs 3
setblock ~69 ~87 ~27 oak_stairs 2
setblock ~69 ~87 ~36 dark_oak_stairs 3
fill ~69 ~87 ~37 ~69 ~91 ~37 planks 0
setblock ~69 ~87 ~38 oak_stairs 7
setblock ~69 ~87 ~44 planks 0
setblock ~69 ~87 ~46 double_wooden_slab 1
setblock ~69 ~87 ~47 wooden_slab 0
setblock ~70 ~87 ~29 wooden_slab 0
setblock ~70 ~87 ~30 dark_oak_stairs 2
fill ~70 ~87 ~31 ~70 ~88 ~31 wooden_slab 5
setblock ~70 ~87 ~32 double_wooden_slab 5
setblock ~70 ~87 ~34 planks 5
setblock ~70 ~87 ~36 wooden_slab 8
setblock ~70 ~87 ~37 double_wooden_slab 0
setblock ~70 ~87 ~45 spruce_stairs 1
setblock ~70 ~87 ~46 wooden_slab 0
setblock ~71 ~87 ~30 double_stone_slab 5
setblock ~71 ~87 ~31 dark_oak_stairs 6
setblock ~71 ~87 ~32 spruce_stairs 2
setblock ~71 ~87 ~33 dark_oak_stairs 3
setblock ~71 ~87 ~34 dark_oak_stairs 6
setblock ~71 ~87 ~35 dark_oak_stairs 1
setblock ~71 ~87 ~47 double_wooden_slab 1
setblock ~72 ~87 ~47 wooden_slab 9
setblock ~72 ~87 ~48 wooden_slab 5
setblock ~73 ~87 ~45 double_wooden_slab 1
setblock ~73 ~87 ~46 planks 1
setblock ~73 ~87 ~47 wooden_slab 1
setblock ~74 ~87 ~39 wooden_slab 8
fill ~74 ~87 ~40 ~74 ~87 ~42 double_wooden_slab 1
setblock ~74 ~87 ~43 wooden_slab 1
setblock ~75 ~87 ~41 wooden_slab 9
setblock ~75 ~87 ~42 wooden_slab 1
setblock ~77 ~87 ~36 planks 5
setblock ~51 ~88 ~35 planks 5
setblock ~54 ~88 ~40 wooden_slab 0
setblock ~54 ~88 ~41 wooden_slab 1
setblock ~55 ~88 ~33 stone 6
setblock ~55 ~88 ~37 wooden_slab 10
setblock ~55 ~88 ~38 planks 0
setblock ~55 ~88 ~39 double_wooden_slab 1
setblock ~55 ~88 ~40 wooden_slab 9
setblock ~55 ~88 ~41 wooden_slab 8
setblock ~55 ~88 ~42 wooden_slab 1
setblock ~56 ~88 ~30 cobblestone 0
setblock ~56 ~88 ~31 stone_stairs 7
setblock ~56 ~88 ~42 planks 0
setblock ~56 ~88 ~43 double_wooden_slab 1
setblock ~56 ~88 ~44 planks 0
fill ~56 ~88 ~45 ~56 ~88 ~46 wooden_slab 1
setblock ~57 ~88 ~27 stone 6
setblock ~57 ~88 ~29 stone_stairs 6
setblock ~57 ~88 ~30 dark_oak_stairs 2
setblock ~57 ~88 ~31 dark_oak_stairs 7
setblock ~57 ~88 ~32 dark_oak_stairs 6
fill ~57 ~88 ~33 ~57 ~88 ~34 planks 5
fill ~57 ~88 ~35 ~57 ~89 ~35 wooden_slab 8
setblock ~57 ~88 ~36 wooden_slab 0
setblock ~57 ~88 ~45 planks 0
setblock ~57 ~88 ~46 double_wooden_slab 1
setblock ~58 ~88 ~29 oak_stairs 6
fill ~58 ~88 ~30 ~58 ~89 ~30 planks 0
setblock ~58 ~88 ~32 wooden_slab 5
fill ~58 ~88 ~33 ~60 ~88 ~33 planks 1
fill ~58 ~88 ~34 ~60 ~88 ~34 planks 1
fill ~58 ~88 ~36 ~59 ~88 ~36 planks 0
fill ~58 ~88 ~37 ~58 ~88 ~38 wooden_slab 8
setblock ~58 ~88 ~45 double_wooden_slab 0
setblock ~58 ~88 ~46 wooden_slab 1
fill ~59 ~88 ~22 ~59 ~88 ~23 wooden_slab 13
setblock ~59 ~88 ~24 wooden_slab 9
fill ~59 ~88 ~28 ~61 ~88 ~28 planks 0
fill ~59 ~88 ~32 ~60 ~88 ~32 planks 1
fill ~59 ~88 ~35 ~59 ~89 ~35 planks 0
fill ~59 ~88 ~37 ~60 ~88 ~37 planks 0
fill ~59 ~88 ~38 ~61 ~88 ~38 planks 0
setblock ~59 ~88 ~39 wooden_slab 0
setblock ~59 ~88 ~44 oak_stairs 0
setblock ~59 ~88 ~45 wooden_slab 0
setblock ~60 ~88 ~19 dark_oak_stairs 6
setblock ~60 ~88 ~20 dark_oak_stairs 4
setblock ~60 ~88 ~21 dark_oak_stairs 7
setblock ~60 ~88 ~22 wooden_slab 5
setblock ~60 ~88 ~23 planks 5
fill ~60 ~88 ~24 ~61 ~88 ~24 planks 1
fill ~60 ~88 ~26 ~60 ~89 ~26 planks 5
fill ~60 ~88 ~27 ~60 ~90 ~27 planks 5
fill ~60 ~88 ~39 ~62 ~88 ~39 planks 0
setblock ~60 ~88 ~40 wooden_slab 0
setblock ~60 ~88 ~41 birch_stairs 6
setblock ~60 ~88 ~42 planks 0
setblock ~60 ~88 ~43 double_wooden_slab 2
fill ~60 ~88 ~44 ~61 ~88 ~44 planks 0
fill ~60 ~88 ~45 ~60 ~88 ~44 planks 0
setblock ~60 ~88 ~46 wooden_slab 1
setblock ~61 ~88 ~20 spruce_stairs 5
fill ~61 ~88 ~21 ~63 ~88 ~21 planks 0
setblock ~61 ~88 ~25 planks 5
setblock ~61 ~88 ~27 planks 0
fill ~61 ~88 ~29 ~61 ~89 ~29 planks 0
fill ~61 ~88 ~40 ~67 ~88 ~40 planks 0
setblock ~61 ~88 ~41 wooden_slab 0
setblock ~61 ~88 ~45 wooden_slab 0
setblock ~62 ~88 ~17 dark_oak_stairs 5
fill ~62 ~88 ~19 ~62 ~88 ~20 wooden_slab 8
setblock ~62 ~88 ~22 planks 0
fill ~62 ~88 ~41 ~66 ~88 ~41 planks 0
fill ~62 ~88 ~42 ~62 ~89 ~42 wooden_slab 0
setblock ~62 ~88 ~43 double_wooden_slab 2
setblock ~62 ~88 ~44 wooden_slab 1
setblock ~63 ~88 ~18 sandstone_stairs 6
fill ~63 ~88 ~19 ~65 ~88 ~19 double_stone_slab 9
setblock ~63 ~88 ~20 planks 0
setblock ~63 ~88 ~42 planks 0
setblock ~63 ~88 ~43 double_wooden_slab 0
setblock ~63 ~88 ~44 oak_stairs 6
setblock ~63 ~88 ~45 oak_stairs 0
setblock ~63 ~88 ~46 wooden_slab 1
fill ~64 ~88 ~17 ~64 ~88 ~18 spruce_stairs 7
setblock ~64 ~88 ~43 planks 0
setblock ~64 ~88 ~44 double_wooden_slab 2
setblock ~64 ~88 ~45 planks 0
setblock ~64 ~88 ~46 planks 1
setblock ~64 ~88 ~47 wooden_slab 0
setblock ~65 ~88 ~18 sandstone_stairs 6
fill ~65 ~88 ~20 ~65 ~88 ~21 planks 0
setblock ~65 ~88 ~42 planks 0
setblock ~65 ~88 ~43 double_wooden_slab 0
setblock ~65 ~88 ~44 oak_stairs 6
setblock ~65 ~88 ~45 oak_stairs 1
setblock ~65 ~88 ~46 wooden_slab 1
setblock ~66 ~88 ~17 dark_oak_stairs 4
fill ~66 ~88 ~19 ~66 ~88 ~20 wooden_slab 8
fill ~66 ~88 ~21 ~67 ~88 ~21 planks 0
fill ~66 ~88 ~22 ~66 ~88 ~21 planks 0
fill ~66 ~88 ~39 ~68 ~88 ~39 planks 0
fill ~66 ~88 ~42 ~66 ~89 ~42 wooden_slab 0
setblock ~66 ~88 ~43 double_wooden_slab 2
setblock ~66 ~88 ~44 wooden_slab 1
setblock ~67 ~88 ~20 spruce_stairs 4
fill ~67 ~88 ~24 ~68 ~88 ~24 planks 1
setblock ~67 ~88 ~25 planks 5
fill ~67 ~88 ~27 ~67 ~88 ~29 planks 0
fill ~67 ~88 ~38 ~69 ~88 ~38 planks 0
setblock ~67 ~88 ~41 wooden_slab 0
fill ~67 ~88 ~44 ~68 ~88 ~44 planks 0
setblock ~67 ~88 ~45 wooden_slab 0
setblock ~68 ~88 ~19 dark_oak_stairs 6
setblock ~68 ~88 ~20 dark_oak_stairs 5
setblock ~68 ~88 ~21 dark_oak_stairs 7
setblock ~68 ~88 ~22 wooden_slab 5
setblock ~68 ~88 ~23 planks 5
fill ~68 ~88 ~26 ~68 ~89 ~26 planks 5
fill ~68 ~88 ~27 ~68 ~90 ~27 planks 5
fill ~68 ~88 ~28 ~69 ~88 ~28 planks 0
fill ~68 ~88 ~32 ~69 ~88 ~32 planks 1
fill ~68 ~88 ~33 ~70 ~88 ~33 planks 1
fill ~68 ~88 ~37 ~68 ~89 ~37 planks 0
setblock ~68 ~88 ~40 wooden_slab 0
setblock ~68 ~88 ~41 birch_stairs 6
setblock ~68 ~88 ~42 planks 0
setblock ~68 ~88 ~43 double_wooden_slab 2
setblock ~68 ~88 ~45 planks 0
setblock ~68 ~88 ~46 wooden_slab 1
fill ~69 ~88 ~22 ~69 ~88 ~23 wooden_slab 13
setblock ~69 ~88 ~24 wooden_slab 9
fill ~69 ~88 ~34 ~70 ~88 ~34 planks 1
fill ~69 ~88 ~35 ~69 ~89 ~35 planks 0
fill ~69 ~88 ~36 ~70 ~88 ~36 planks 0
setblock ~69 ~88 ~39 wooden_slab 0
setblock ~69 ~88 ~44 oak_stairs 1
setblock ~69 ~88 ~45 wooden_slab 0
setblock ~70 ~88 ~29 oak_stairs 6
fill ~70 ~88 ~30 ~70 ~89 ~30 planks 0
setblock ~70 ~88 ~32 wooden_slab 5
fill ~70 ~88 ~37 ~70 ~88 ~38 wooden_slab 8
setblock ~70 ~88 ~45 double_wooden_slab 0
setblock ~70 ~88 ~46 wooden_slab 1
setblock ~71 ~88 ~27 stone 6
setblock ~71 ~88 ~29 stone_stairs 6
setblock ~71 ~88 ~30 dark_oak_stairs 2
setblock ~71 ~88 ~31 dark_oak_stairs 7
setblock ~71 ~88 ~32 dark_oak_stairs 6
fill ~71 ~88 ~33 ~71 ~88 ~34 planks 5
fill ~71 ~88 ~35 ~71 ~89 ~35 wooden_slab 8
setblock ~71 ~88 ~36 wooden_slab 0
setblock ~71 ~88 ~45 planks 0
setblock ~71 ~88 ~46 double_wooden_slab 1
setblock ~72 ~88 ~30 cobblestone 0
setblock ~72 ~88 ~31 stone_stairs 7
setblock ~72 ~88 ~42 planks 0
setblock ~72 ~88 ~43 double_wooden_slab 1
setblock ~72 ~88 ~44 planks 0
fill ~72 ~88 ~45 ~72 ~88 ~46 wooden_slab 1
setblock ~73 ~88 ~33 stone 6
setblock ~73 ~88 ~37 wooden_slab 10
setblock ~73 ~88 ~38 planks 0
setblock ~73 ~88 ~39 double_wooden_slab 1
setblock ~73 ~88 ~40 wooden_slab 9
setblock ~73 ~88 ~41 wooden_slab 8
setblock ~73 ~88 ~42 wooden_slab 1
setblock ~74 ~88 ~40 wooden_slab 0
setblock ~74 ~88 ~41 wooden_slab 1
setblock ~77 ~88 ~35 planks 5
fill ~44 ~89 ~39 ~44 ~90 ~39 planks 5
setblock ~50 ~89 ~35 planks 5
fill ~51 ~89 ~35 ~52 ~89 ~35 planks 1
setblock ~55 ~89 ~32 double_stone_slab 3
setblock ~55 ~89 ~38 wooden_slab 0
setblock ~55 ~89 ~40 wooden_slab 1
setblock ~56 ~89 ~30 stone_brick_stairs 7
fill ~56 ~89 ~36 ~56 ~90 ~36 wooden_slab 2
setblock ~56 ~89 ~37 planks 0
setblock ~56 ~89 ~38 double_wooden_slab 2
fill ~56 ~89 ~39 ~56 ~89 ~40 planks 0
setblock ~56 ~89 ~41 wooden_slab 1
setblock ~57 ~89 ~28 cobblestone 0
fill ~57 ~89 ~31 ~57 ~89 ~33 wooden_slab 5
setblock ~57 ~89 ~34 wooden_slab 0
setblock ~57 ~89 ~36 wooden_slab 10
fill ~57 ~89 ~38 ~57 ~89 ~39 wooden_slab 8
setblock ~57 ~89 ~40 wooden_slab 2
fill ~57 ~89 ~41 ~57 ~89 ~42 double_wooden_slab 0
setblock ~57 ~89 ~43 wooden_slab 0
setblock ~57 ~89 ~44 wooden_slab 1
setblock ~58 ~89 ~20 wooden_slab 13
setblock ~58 ~89 ~29 oak_stairs 2
fill ~58 ~89 ~31 ~58 ~89 ~33 wooden_slab 13
setblock ~58 ~89 ~34 double_wooden_slab 5
setblock ~58 ~89 ~35 wooden_slab 0
fill ~58 ~89 ~36 ~58 ~90 ~36 planks 0
fill ~58 ~89 ~37 ~60 ~89 ~37 planks 0
setblock ~58 ~89 ~38 wooden_slab 10
setblock ~58 ~89 ~39 planks 2
setblock ~58 ~89 ~40 double_wooden_slab 0
fill ~58 ~89 ~42 ~59 ~89 ~42 wooden_slab 8
fill ~58 ~89 ~43 ~58 ~89 ~42 wooden_slab 8
setblock ~58 ~89 ~44 double_wooden_slab 0
setblock ~58 ~89 ~45 wooden_slab 1
setblock ~59 ~89 ~19 wooden_slab 9
setblock ~59 ~89 ~20 planks 5
fill ~59 ~89 ~21 ~59 ~90 ~21 double_stone_slab 9
fill ~59 ~89 ~22 ~59 ~89 ~21 double_stone_slab 9
setblock ~59 ~89 ~23 wooden_slab 5
setblock ~59 ~89 ~24 planks 5
fill ~59 ~89 ~25 ~60 ~89 ~25 planks 1
setblock ~59 ~89 ~27 planks 5
fill ~59 ~89 ~32 ~59 ~84 ~32 planks 1
fill ~59 ~89 ~33 ~59 ~89 ~32 planks 1
fill ~59 ~89 ~38 ~60 ~89 ~38 double_wooden_slab 2
setblock ~59 ~89 ~39 wooden_slab 10
setblock ~59 ~89 ~40 planks 0
setblock ~59 ~89 ~41 wooden_slab 10
setblock ~59 ~89 ~43 wooden_slab 0
setblock ~60 ~89 ~18 dark_oak_stairs 4
setblock ~60 ~89 ~19 planks 1
fill ~60 ~89 ~22 ~60 ~90 ~22 planks 1
setblock ~60 ~89 ~23 double_stone_slab 9
fill ~60 ~89 ~24 ~60 ~88 ~24 planks 1
setblock ~60 ~89 ~28 planks 5
setblock ~60 ~89 ~39 planks 2
setblock ~60 ~89 ~40 wooden_slab 2
setblock ~60 ~89 ~41 birch_stairs 0
setblock ~60 ~89 ~42 wooden_slab 0
setblock ~61 ~89 ~16 wooden_slab 13
setblock ~61 ~89 ~17 planks 5
setblock ~61 ~89 ~18 dark_oak_stairs 7
fill ~61 ~89 ~19 ~62 ~89 ~19 planks 0
fill ~61 ~89 ~20 ~62 ~89 ~20 planks 0
fill ~61 ~89 ~38 ~62 ~89 ~38 wooden_slab 8
setblock ~61 ~89 ~39 birch_stairs 6
fill ~61 ~89 ~40 ~61 ~89 ~41 planks 2
setblock ~61 ~89 ~42 planks 0
setblock ~61 ~89 ~43 wooden_slab 2
setblock ~62 ~89 ~16 dark_oak_stairs 6
fill ~62 ~89 ~17 ~62 ~89 ~20 planks 0
fill ~62 ~89 ~39 ~62 ~89 ~40 planks 0
setblock ~62 ~89 ~41 wooden_slab 10
setblock ~63 ~89 ~16 dark_oak_stairs 4
setblock ~63 ~89 ~17 double_stone_slab 9
fill ~63 ~89 ~40 ~63 ~89 ~41 planks 0
setblock ~63 ~89 ~42 planks 2
setblock ~63 ~89 ~43 wooden_slab 0
setblock ~64 ~89 ~15 wooden_slab 13
setblock ~64 ~89 ~16 dark_oak_stairs 6
setblock ~64 ~89 ~17 planks 0
setblock ~64 ~89 ~18 double_stone_slab 9
setblock ~64 ~89 ~41 planks 2
setblock ~64 ~89 ~43 planks 2
setblock ~64 ~89 ~44 wooden_slab 0
setblock ~65 ~89 ~16 dark_oak_stairs 5
setblock ~65 ~89 ~17 double_stone_slab 9
fill ~65 ~89 ~40 ~66 ~89 ~40 planks 0
fill ~65 ~89 ~41 ~65 ~89 ~40 planks 0
setblock ~65 ~89 ~42 planks 2
setblock ~65 ~89 ~43 wooden_slab 0
setblock ~66 ~89 ~16 dark_oak_stairs 6
fill ~66 ~89 ~17 ~66 ~89 ~20 planks 0
fill ~66 ~89 ~38 ~67 ~89 ~38 wooden_slab 8
fill ~66 ~89 ~39 ~66 ~86 ~39 planks 0
setblock ~66 ~89 ~41 wooden_slab 10
setblock ~67 ~89 ~16 wooden_slab 13
setblock ~67 ~89 ~17 planks 5
setblock ~67 ~89 ~18 dark_oak_stairs 7
fill ~67 ~89 ~19 ~67 ~89 ~20 planks 0
setblock ~67 ~89 ~29 planks 0
setblock ~67 ~89 ~39 birch_stairs 6
fill ~67 ~89 ~40 ~67 ~89 ~41 planks 2
setblock ~67 ~89 ~42 planks 0
setblock ~67 ~89 ~43 wooden_slab 2
setblock ~68 ~89 ~18 dark_oak_stairs 5
setblock ~68 ~89 ~19 planks 1
fill ~68 ~89 ~22 ~68 ~90 ~22 planks 1
setblock ~68 ~89 ~23 double_stone_slab 9
fill ~68 ~89 ~24 ~68 ~89 ~25 planks 1
setblock ~68 ~89 ~28 planks 5
fill ~68 ~89 ~38 ~69 ~89 ~38 double_wooden_slab 2
setblock ~68 ~89 ~39 planks 2
setblock ~68 ~89 ~40 wooden_slab 2
setblock ~68 ~89 ~41 birch_stairs 1
setblock ~68 ~89 ~42 wooden_slab 0
setblock ~69 ~89 ~19 wooden_slab 9
setblock ~69 ~89 ~20 planks 5
fill ~69 ~89 ~21 ~69 ~90 ~21 double_stone_slab 9
fill ~69 ~89 ~22 ~69 ~89 ~21 double_stone_slab 9
setblock ~69 ~89 ~23 wooden_slab 5
setblock ~69 ~89 ~24 planks 5
fill ~69 ~89 ~25 ~69 ~93 ~25 planks 1
setblock ~69 ~89 ~27 planks 5
fill ~69 ~89 ~32 ~69 ~89 ~33 planks 1
setblock ~69 ~89 ~39 wooden_slab 10
setblock ~69 ~89 ~40 planks 0
setblock ~69 ~89 ~41 wooden_slab 10
fill ~69 ~89 ~42 ~70 ~89 ~42 wooden_slab 8
setblock ~69 ~89 ~43 wooden_slab 0
setblock ~70 ~89 ~20 wooden_slab 13
setblock ~70 ~89 ~29 oak_stairs 2
fill ~70 ~89 ~31 ~70 ~89 ~33 wooden_slab 13
setblock ~70 ~89 ~34 double_wooden_slab 5
setblock ~70 ~89 ~35 wooden_slab 0
fill ~70 ~89 ~36 ~70 ~90 ~36 planks 0
fill ~70 ~89 ~37 ~70 ~89 ~36 planks 0
setblock ~70 ~89 ~38 wooden_slab 10
setblock ~70 ~89 ~39 planks 2
setblock ~70 ~89 ~40 double_wooden_slab 0
setblock ~70 ~89 ~43 wooden_slab 8
setblock ~70 ~89 ~44 double_wooden_slab 0
setblock ~70 ~89 ~45 wooden_slab 1
setblock ~71 ~89 ~28 cobblestone 0
fill ~71 ~89 ~31 ~71 ~89 ~33 wooden_slab 5
setblock ~71 ~89 ~34 wooden_slab 0
setblock ~71 ~89 ~36 wooden_slab 10
fill ~71 ~89 ~38 ~71 ~89 ~39 wooden_slab 8
setblock ~71 ~89 ~40 wooden_slab 2
fill ~71 ~89 ~41 ~71 ~89 ~42 double_wooden_slab 0
setblock ~71 ~89 ~43 wooden_slab 0
setblock ~71 ~89 ~44 wooden_slab 1
setblock ~72 ~89 ~30 stone_brick_stairs 7
fill ~72 ~89 ~36 ~72 ~90 ~36 wooden_slab 2
setblock ~72 ~89 ~37 planks 0
setblock ~72 ~89 ~38 double_wooden_slab 2
fill ~72 ~89 ~39 ~72 ~89 ~40 planks 0
setblock ~72 ~89 ~41 wooden_slab 1
setblock ~73 ~89 ~32 double_stone_slab 3
setblock ~73 ~89 ~38 wooden_slab 0
setblock ~73 ~89 ~40 wooden_slab 1
fill ~76 ~89 ~35 ~77 ~89 ~35 planks 1
setblock ~78 ~89 ~35 planks 5
fill ~84 ~89 ~39 ~84 ~90 ~39 planks 5
fill ~45 ~90 ~39 ~45 ~91 ~39 planks 5
setblock ~50 ~90 ~35 planks 1
setblock ~51 ~90 ~35 planks 5
fill ~52 ~90 ~35 ~52 ~91 ~35 planks 1
setblock ~55 ~90 ~33 stone_stairs 7
setblock ~56 ~90 ~29 stone_brick_stairs 6
setblock ~56 ~90 ~30 stone_brick_stairs 3
setblock ~56 ~90 ~31 stone_brick_stairs 7
setblock ~56 ~90 ~35 wooden_slab 2
setblock ~57 ~90 ~27 stone_stairs 6
setblock ~57 ~90 ~34 birch_stairs 2
fill ~57 ~90 ~35 ~57 ~90 ~36 double_wooden_slab 2
setblock ~57 ~90 ~37 planks 0
setblock ~57 ~90 ~39 wooden_slab 0
setblock ~58 ~90 ~18 stone_slab 9
setblock ~58 ~90 ~19 spruce_stairs 4
setblock ~58 ~90 ~21 stone_slab 9
fill ~58 ~90 ~22 ~58 ~91 ~22 double_stone_slab 9
fill ~58 ~90 ~23 ~59 ~90 ~23 double_stone_slab 9
setblock ~58 ~90 ~24 planks 5
setblock ~58 ~90 ~25 wooden_slab 9
setblock ~58 ~90 ~30 wooden_slab 0
setblock ~58 ~90 ~31 wooden_slab 8
fill ~58 ~90 ~32 ~58 ~90 ~33 wooden_slab 5
fill ~58 ~90 ~34 ~58 ~93 ~34 planks 0
fill ~58 ~90 ~35 ~58 ~94 ~35 planks 0
setblock ~58 ~90 ~37 double_wooden_slab 0
setblock ~58 ~90 ~38 wooden_slab 2
setblock ~58 ~90 ~41 wooden_slab 2
setblock ~59 ~90 ~18 wooden_slab 2
setblock ~59 ~90 ~19 planks 0
setblock ~59 ~90 ~20 double_stone_slab 9
fill ~59 ~90 ~22 ~59 ~93 ~22 planks 1
fill ~59 ~90 ~24 ~59 ~93 ~24 planks 1
fill ~59 ~90 ~25 ~60 ~90 ~25 planks 1
fill ~59 ~90 ~26 ~60 ~90 ~26 planks 1
fill ~59 ~90 ~28 ~59 ~91 ~28 planks 5
fill ~59 ~90 ~29 ~59 ~92 ~29 planks 5
fill ~59 ~90 ~31 ~59 ~92 ~31 planks 0
fill ~59 ~90 ~32 ~59 ~90 ~33 planks 0
fill ~59 ~90 ~37 ~59 ~91 ~37 planks 0
fill ~59 ~90 ~38 ~61 ~90 ~38 wooden_slab 8
setblock ~59 ~90 ~39 wooden_slab 2
setblock ~59 ~90 ~40 wooden_slab 0
fill ~60 ~90 ~16 ~61 ~90 ~16 wooden_slab 5
setblock ~60 ~90 ~17 sandstone_stairs 4
fill ~60 ~90 ~18 ~60 ~91 ~18 planks 0
fill ~60 ~90 ~21 ~60 ~91 ~21 planks 1
fill ~60 ~90 ~23 ~60 ~92 ~23 planks 1
fill ~60 ~90 ~37 ~61 ~90 ~37 double_wooden_slab 0
fill ~61 ~90 ~17 ~62 ~90 ~17 double_stone_slab 9
fill ~61 ~90 ~39 ~62 ~90 ~39 wooden_slab 2
setblock ~61 ~90 ~41 wooden_slab 2
setblock ~62 ~90 ~16 sandstone_stairs 4
setblock ~62 ~90 ~37 wooden_slab 0
fill ~62 ~90 ~38 ~62 ~91 ~38 birch_stairs 6
setblock ~62 ~90 ~40 wooden_slab 2
setblock ~63 ~90 ~15 wooden_slab 5
fill ~63 ~90 ~16 ~63 ~91 ~16 double_stone_slab 9
setblock ~63 ~90 ~38 wooden_slab 0
setblock ~63 ~90 ~39 birch_stairs 6
setblock ~63 ~90 ~40 planks 2
fill ~63 ~90 ~41 ~63 ~91 ~41 wooden_slab 0
setblock ~64 ~90 ~15 planks 5
fill ~64 ~90 ~16 ~64 ~91 ~16 planks 0
setblock ~64 ~90 ~42 wooden_slab 8
setblock ~65 ~90 ~15 wooden_slab 5
fill ~65 ~90 ~16 ~65 ~91 ~16 double_stone_slab 9
setblock ~65 ~90 ~38 wooden_slab 0
setblock ~65 ~90 ~39 birch_stairs 6
setblock ~65 ~90 ~40 planks 2
fill ~65 ~90 ~41 ~65 ~91 ~41 wooden_slab 0
setblock ~66 ~90 ~16 sandstone_stairs 5
fill ~66 ~90 ~17 ~67 ~90 ~17 double_stone_slab 9
setblock ~66 ~90 ~37 wooden_slab 0
fill ~66 ~90 ~38 ~66 ~91 ~38 birch_stairs 6
fill ~66 ~90 ~39 ~67 ~90 ~39 wooden_slab 2
fill ~66 ~90 ~40 ~66 ~90 ~39 wooden_slab 2
fill ~67 ~90 ~16 ~68 ~90 ~16 wooden_slab 5
fill ~67 ~90 ~37 ~68 ~90 ~37 double_wooden_slab 0
fill ~67 ~90 ~38 ~69 ~90 ~38 wooden_slab 8
setblock ~67 ~90 ~41 wooden_slab 2
setblock ~68 ~90 ~17 sandstone_stairs 5
fill ~68 ~90 ~18 ~68 ~91 ~18 planks 0
fill ~68 ~90 ~21 ~68 ~91 ~21 planks 1
fill ~68 ~90 ~23 ~68 ~92 ~23 planks 1
fill ~68 ~90 ~25 ~68 ~92 ~25 planks 1
fill ~68 ~90 ~26 ~69 ~90 ~26 planks 1
setblock ~69 ~90 ~18 wooden_slab 2
setblock ~69 ~90 ~19 planks 0
setblock ~69 ~90 ~20 double_stone_slab 9
fill ~69 ~90 ~22 ~69 ~93 ~22 planks 1
fill ~69 ~90 ~23 ~70 ~90 ~23 double_stone_slab 9
fill ~69 ~90 ~24 ~69 ~93 ~24 planks 1
fill ~69 ~90 ~28 ~69 ~91 ~28 planks 5
fill ~69 ~90 ~29 ~69 ~92 ~29 planks 5
fill ~69 ~90 ~31 ~69 ~92 ~31 planks 0
fill ~69 ~90 ~32 ~69 ~90 ~33 planks 0
setblock ~69 ~90 ~39 wooden_slab 2
setblock ~69 ~90 ~40 wooden_slab 0
setblock ~70 ~90 ~18 stone_slab 9
setblock ~70 ~90 ~19 spruce_stairs 5
setblock ~70 ~90 ~21 stone_slab 9
fill ~70 ~90 ~22 ~70 ~91 ~22 double_stone_slab 9
setblock ~70 ~90 ~24 planks 5
setblock ~70 ~90 ~25 wooden_slab 9
setblock ~70 ~90 ~30 wooden_slab 0
setblock ~70 ~90 ~31 wooden_slab 8
fill ~70 ~90 ~32 ~70 ~90 ~33 wooden_slab 5
fill ~70 ~90 ~34 ~70 ~93 ~34 planks 0
fill ~70 ~90 ~35 ~70 ~94 ~35 planks 0
setblock ~70 ~90 ~37 double_wooden_slab 0
setblock ~70 ~90 ~38 wooden_slab 2
setblock ~70 ~90 ~41 wooden_slab 2
setblock ~71 ~90 ~18 sandstone_stairs 1
setblock ~71 ~90 ~27 stone_stairs 6
setblock ~71 ~90 ~34 birch_stairs 2
fill ~71 ~90 ~35 ~71 ~90 ~36 double_wooden_slab 2
setblock ~71 ~90 ~37 planks 0
setblock ~71 ~90 ~39 wooden_slab 0
setblock ~72 ~90 ~29 stone_brick_stairs 6
setblock ~72 ~90 ~30 stone_brick_stairs 3
setblock ~72 ~90 ~31 stone_brick_stairs 7
setblock ~72 ~90 ~35 wooden_slab 2
setblock ~73 ~90 ~33 stone_stairs 7
fill ~76 ~90 ~35 ~76 ~91 ~35 planks 1
setblock ~77 ~90 ~35 planks 5
setblock ~78 ~90 ~35 planks 1
fill ~83 ~90 ~39 ~83 ~91 ~39 planks 5
setblock ~46 ~91 ~38 planks 1
fill ~51 ~91 ~35 ~51 ~92 ~35 planks 1
fill ~53 ~91 ~34 ~53 ~92 ~34 planks 1
setblock ~55 ~91 ~32 stone_brick_stairs 3
setblock ~55 ~91 ~33 double_stone_slab 3
setblock ~55 ~91 ~34 double_stone_slab 5
setblock ~56 ~91 ~28 stone_brick_stairs 6
setblock ~56 ~91 ~29 stone_brick_stairs 7
setblock ~56 ~91 ~31 stone_brick_stairs 2
setblock ~56 ~91 ~35 oak_stairs 4
setblock ~56 ~91 ~36 wooden_slab 0
fill ~57 ~91 ~22 ~57 ~91 ~24 stone_slab 9
setblock ~57 ~91 ~26 double_stone_slab 5
setblock ~57 ~91 ~27 cobblestone 0
setblock ~57 ~91 ~30 stone 6
setblock ~57 ~91 ~33 wooden_slab 8
fill ~57 ~91 ~34 ~57 ~92 ~34 planks 0
fill ~57 ~91 ~35 ~57 ~91 ~36 planks 0
setblock ~58 ~91 ~18 stone_slab 1
setblock ~58 ~91 ~19 sandstone_stairs 7
setblock ~58 ~91 ~20 planks 2
setblock ~58 ~91 ~21 double_stone_slab 9
fill ~58 ~91 ~23 ~58 ~90 ~23 double_stone_slab 9
fill ~58 ~91 ~24 ~58 ~91 ~21 double_stone_slab 9
setblock ~58 ~91 ~25 planks 5
fill ~58 ~91 ~26 ~59 ~91 ~26 planks 1
setblock ~58 ~91 ~29 planks 5
setblock ~58 ~91 ~30 glowstone 0
fill ~58 ~91 ~32 ~58 ~91 ~35 planks 0
setblock ~58 ~91 ~36 planks 2
setblock ~58 ~91 ~37 wooden_slab 2
setblock ~59 ~91 ~17 birch_stairs 0
setblock ~59 ~91 ~18 sandstone_stairs 5
setblock ~59 ~91 ~19 planks 1
setblock ~59 ~91 ~21 planks 1
fill ~59 ~91 ~23 ~59 ~93 ~23 planks 1
fill ~59 ~91 ~25 ~60 ~91 ~25 planks 1
fill ~59 ~91 ~27 ~59 ~92 ~27 planks 1
fill ~59 ~91 ~30 ~59 ~92 ~30 planks 5
setblock ~59 ~91 ~38 wooden_slab 0
fill ~60 ~91 ~17 ~60 ~92 ~17 planks 2
fill ~60 ~91 ~24 ~60 ~92 ~24 planks 1
setblock ~60 ~91 ~38 double_wooden_slab 2
setblock ~61 ~91 ~15 stone_slab 9
fill ~61 ~91 ~16 ~63 ~91 ~16 double_stone_slab 9
fill ~61 ~91 ~17 ~61 ~90 ~17 double_stone_slab 9
fill ~61 ~91 ~38 ~61 ~92 ~38 planks 0
setblock ~61 ~91 ~39 oak_stairs 0
fill ~62 ~91 ~39 ~63 ~91 ~39 wooden_slab 10
setblock ~62 ~91 ~40 wooden_slab 0
setblock ~63 ~91 ~15 sandstone_stairs 4
setblock ~63 ~91 ~38 birch_stairs 6
setblock ~63 ~91 ~40 wooden_slab 10
setblock ~64 ~91 ~14 wooden_slab 5
setblock ~64 ~91 ~15 double_stone_slab 9
fill ~64 ~91 ~39 ~64 ~92 ~39 planks 0
setblock ~64 ~91 ~41 double_wooden_slab 2
setblock ~64 ~91 ~42 wooden_slab 2
setblock ~65 ~91 ~15 sandstone_stairs 5
setblock ~65 ~91 ~38 birch_stairs 6
fill ~65 ~91 ~39 ~66 ~91 ~39 wooden_slab 10
fill ~65 ~91 ~40 ~65 ~91 ~39 wooden_slab 10
fill ~66 ~91 ~16 ~67 ~91 ~16 double_stone_slab 9
setblock ~66 ~91 ~40 wooden_slab 0
setblock ~67 ~91 ~15 stone_slab 9
setblock ~67 ~91 ~17 double_stone_slab 9
fill ~67 ~91 ~38 ~67 ~92 ~38 planks 0
setblock ~67 ~91 ~39 oak_stairs 1
fill ~68 ~91 ~17 ~68 ~92 ~17 planks 2
fill ~68 ~91 ~24 ~68 ~92 ~24 planks 1
setblock ~68 ~91 ~38 double_wooden_slab 2
setblock ~69 ~91 ~17 birch_stairs 1
setblock ~69 ~91 ~18 sandstone_stairs 4
setblock ~69 ~91 ~19 planks 1
setblock ~69 ~91 ~21 planks 1
fill ~69 ~91 ~23 ~69 ~93 ~23 planks 1
fill ~69 ~91 ~26 ~70 ~91 ~26 planks 1
fill ~69 ~91 ~27 ~69 ~92 ~27 planks 1
fill ~69 ~91 ~30 ~69 ~92 ~30 planks 5
setblock ~69 ~91 ~38 wooden_slab 0
setblock ~70 ~91 ~18 stone_slab 1
setblock ~70 ~91 ~19 sandstone_stairs 7
setblock ~70 ~91 ~20 planks 2
setblock ~70 ~91 ~21 double_stone_slab 9
fill ~70 ~91 ~23 ~70 ~91 ~24 double_stone_slab 9
setblock ~70 ~91 ~25 planks 5
setblock ~70 ~91 ~29 planks 5
setblock ~70 ~91 ~30 glowstone 0
fill ~70 ~91 ~32 ~70 ~91 ~35 planks 0
setblock ~70 ~91 ~36 planks 2
setblock ~70 ~91 ~37 wooden_slab 2
fill ~71 ~91 ~22 ~71 ~91 ~24 stone_slab 9
setblock ~71 ~91 ~26 double_stone_slab 5
setblock ~71 ~91 ~27 cobblestone 0
setblock ~71 ~91 ~30 stone 6
setblock ~71 ~91 ~33 wooden_slab 8
fill ~71 ~91 ~34 ~71 ~92 ~34 planks 0
fill ~71 ~91 ~35 ~71 ~91 ~36 planks 0
setblock ~72 ~91 ~28 stone_brick_stairs 6
setblock ~72 ~91 ~29 stone_brick_stairs 7
setblock ~72 ~91 ~31 stone_brick_stairs 2
setblock ~72 ~91 ~35 oak_stairs 5
setblock ~72 ~91 ~36 wooden_slab 0
setblock ~73 ~91 ~32 stone_brick_stairs 3
setblock ~73 ~91 ~33 double_stone_slab 3
setblock ~73 ~91 ~34 double_stone_slab 5
fill ~75 ~91 ~34 ~75 ~92 ~34 planks 1
fill ~77 ~91 ~35 ~77 ~92 ~35 planks 1
setblock ~82 ~91 ~38 planks 1
setblock ~38 ~92 ~41 planks 5
setblock ~45 ~92 ~39 planks 1
setblock ~46 ~92 ~39 planks 5
fill ~47 ~92 ~38 ~47 ~94 ~38 planks 1
fill ~52 ~92 ~34 ~52 ~93 ~34 planks 1
setblock ~55 ~92 ~33 stone_stairs 3
setblock ~56 ~92 ~23 stone_slab 9
setblock ~56 ~92 ~29 stone_brick_stairs 2
setblock ~56 ~92 ~30 stone_brick_stairs 6
setblock ~56 ~92 ~31 stone_brick_stairs 3
fill ~56 ~92 ~34 ~56 ~92 ~35 planks 0
setblock ~57 ~92 ~20 stone_slab 9
fill ~57 ~92 ~21 ~57 ~92 ~24 double_stone_slab 9
fill ~57 ~92 ~25 ~57 ~93 ~25 planks 5
setblock ~57 ~92 ~27 stone_stairs 2
fill ~57 ~92 ~33 ~58 ~92 ~33 planks 0
setblock ~57 ~92 ~35 planks 2
setblock ~57 ~92 ~36 wooden_slab 10
setblock ~58 ~92 ~18 sandstone_stairs 6
setblock ~58 ~92 ~19 planks 2
setblock ~58 ~92 ~20 double_stone_slab 9
fill ~58 ~92 ~21 ~58 ~94 ~21 planks 1
fill ~58 ~92 ~22 ~58 ~94 ~22 planks 1
fill ~58 ~92 ~23 ~58 ~94 ~23 planks 1
fill ~58 ~92 ~24 ~58 ~94 ~24 planks 1
fill ~58 ~92 ~25 ~60 ~92 ~25 planks 1
fill ~58 ~92 ~26 ~60 ~92 ~26 planks 1
fill ~58 ~92 ~27 ~58 ~93 ~27 planks 1
fill ~58 ~92 ~28 ~59 ~92 ~28 planks 1
setblock ~58 ~92 ~30 dark_oak_stairs 0
fill ~58 ~92 ~32 ~58 ~93 ~32 wooden_slab 8
fill ~58 ~92 ~36 ~59 ~92 ~36 planks 0
setblock ~59 ~92 ~17 birch_stairs 6
fill ~59 ~92 ~18 ~59 ~94 ~18 double_stone_slab 9
fill ~59 ~92 ~32 ~59 ~94 ~32 planks 0
setblock ~59 ~92 ~37 wooden_slab 0
setblock ~60 ~92 ~16 birch_stairs 4
setblock ~60 ~92 ~22 planks 1
fill ~60 ~92 ~37 ~61 ~92 ~37 planks 0
fill ~61 ~92 ~16 ~62 ~92 ~16 double_stone_slab 9
setblock ~62 ~92 ~12 spruce_stairs 4
setblock ~62 ~92 ~15 sandstone_stairs 6
fill ~62 ~92 ~38 ~63 ~92 ~38 planks 0
setblock ~62 ~92 ~39 wooden_slab 0
fill ~63 ~92 ~15 ~63 ~94 ~15 double_stone_slab 9
setblock ~63 ~92 ~39 planks 0
setblock ~64 ~92 ~14 sandstone_stairs 6
setblock ~64 ~92 ~15 planks 0
setblock ~64 ~92 ~40 planks 0
fill ~65 ~92 ~15 ~65 ~94 ~15 double_stone_slab 9
fill ~65 ~92 ~38 ~67 ~92 ~38 planks 0
fill ~65 ~92 ~39 ~65 ~92 ~38 planks 0
setblock ~66 ~92 ~12 spruce_stairs 5
setblock ~66 ~92 ~15 sandstone_stairs 6
fill ~66 ~92 ~16 ~67 ~92 ~16 double_stone_slab 9
setblock ~66 ~92 ~39 wooden_slab 0
fill ~67 ~92 ~37 ~68 ~92 ~37 planks 0
setblock ~68 ~92 ~16 birch_stairs 5
setblock ~68 ~92 ~22 planks 1
fill ~68 ~92 ~26 ~70 ~92 ~26 planks 1
setblock ~69 ~92 ~17 birch_stairs 6
fill ~69 ~92 ~18 ~69 ~94 ~18 double_stone_slab 9
fill ~69 ~92 ~28 ~70 ~92 ~28 planks 1
fill ~69 ~92 ~32 ~69 ~94 ~32 planks 0
fill ~69 ~92 ~36 ~70 ~92 ~36 planks 0
setblock ~69 ~92 ~37 wooden_slab 0
setblock ~70 ~92 ~18 sandstone_stairs 6
setblock ~70 ~92 ~19 planks 2
setblock ~70 ~92 ~20 double_stone_slab 9
fill ~70 ~92 ~21 ~70 ~94 ~21 planks 1
fill ~70 ~92 ~22 ~70 ~94 ~22 planks 1
fill ~70 ~92 ~23 ~70 ~94 ~23 planks 1
fill ~70 ~92 ~24 ~70 ~94 ~24 planks 1
fill ~70 ~92 ~25 ~70 ~94 ~25 planks 1
fill ~70 ~92 ~27 ~70 ~93 ~27 planks 1
setblock ~70 ~92 ~30 dark_oak_stairs 1
fill ~70 ~92 ~32 ~70 ~93 ~32 wooden_slab 8
fill ~70 ~92 ~33 ~71 ~92 ~33 planks 0
setblock ~71 ~92 ~20 stone_slab 9
fill ~71 ~92 ~21 ~71 ~92 ~24 double_stone_slab 9
fill ~71 ~92 ~25 ~71 ~93 ~25 planks 5
setblock ~71 ~92 ~27 stone_stairs 2
setblock ~71 ~92 ~35 planks 2
setblock ~71 ~92 ~36 wooden_slab 10
setblock ~72 ~92 ~23 stone_slab 9
setblock ~72 ~92 ~29 stone_brick_stairs 2
setblock ~72 ~92 ~30 stone_brick_stairs 6
setblock ~72 ~92 ~31 stone_brick_stairs 3
fill ~72 ~92 ~34 ~72 ~92 ~35 planks 0
setblock ~73 ~92 ~33 stone_stairs 3
fill ~76 ~92 ~34 ~76 ~93 ~34 planks 1
fill ~81 ~92 ~38 ~81 ~94 ~38 planks 1
setblock ~82 ~92 ~39 planks 5
setblock ~83 ~92 ~39 planks 1
setblock ~90 ~92 ~41 planks 5
fill ~39 ~93 ~41 ~39 ~94 ~41 planks 5
setblock ~46 ~93 ~39 planks 1
setblock ~48 ~93 ~38 planks 1
setblock ~51 ~93 ~34 planks 1
setblock ~53 ~93 ~34 planks 0
setblock ~54 ~93 ~34 oak_stairs 5
setblock ~55 ~93 ~32 cobblestone 0
setblock ~55 ~93 ~33 planks 0
setblock ~55 ~93 ~34 oak_stairs 4
setblock ~56 ~93 ~22 stone_slab 1
fill ~56 ~93 ~23 ~56 ~93 ~24 double_stone_slab 9
setblock ~56 ~93 ~25 wooden_slab 13
setblock ~56 ~93 ~26 wooden_slab 9
setblock ~56 ~93 ~30 stone_brick_stairs 2
setblock ~56 ~93 ~34 planks 2
setblock ~57 ~93 ~19 sandstone_stairs 0
setblock ~57 ~93 ~20 double_stone_slab 9
setblock ~57 ~93 ~21 planks 5
fill ~57 ~93 ~22 ~57 ~94 ~22 double_stone_slab 9
fill ~57 ~93 ~23 ~57 ~93 ~24 planks 1
setblock ~57 ~93 ~26 double_wooden_slab 1
setblock ~57 ~93 ~27 planks 1
setblock ~57 ~93 ~28 cobblestone 0
setblock ~57 ~93 ~34 wooden_slab 0
setblock ~57 ~93 ~35 planks 0
setblock ~58 ~93 ~12 spruce_stairs 5
fill ~58 ~93 ~18 ~58 ~95 ~18 planks 2
fill ~58 ~93 ~19 ~58 ~95 ~19 double_stone_slab 9
setblock ~58 ~93 ~20 planks 1
fill ~58 ~93 ~25 ~59 ~93 ~25 planks 1
fill ~58 ~93 ~26 ~60 ~93 ~26 planks 1
fill ~58 ~93 ~28 ~58 ~94 ~28 planks 1
fill ~58 ~93 ~29 ~58 ~94 ~29 planks 5
fill ~58 ~93 ~30 ~58 ~94 ~30 planks 5
fill ~58 ~93 ~31 ~59 ~93 ~31 planks 5
setblock ~58 ~93 ~33 planks 0
setblock ~59 ~93 ~17 planks 2
fill ~59 ~93 ~36 ~61 ~93 ~36 planks 0
setblock ~60 ~93 ~15 stone_slab 1
setblock ~60 ~93 ~16 planks 2
setblock ~60 ~93 ~17 double_stone_slab 9
setblock ~60 ~93 ~37 wooden_slab 0
setblock ~61 ~93 ~13 wooden_slab 9
setblock ~61 ~93 ~15 sandstone_stairs 4
fill ~61 ~93 ~16 ~61 ~96 ~16 double_stone_slab 9
setblock ~61 ~93 ~37 double_wooden_slab 0
setblock ~62 ~93 ~12 spruce_stairs 2
fill ~62 ~93 ~14 ~62 ~94 ~14 stone_slab 1
fill ~62 ~93 ~15 ~62 ~94 ~15 double_stone_slab 9
setblock ~62 ~93 ~37 planks 0
setblock ~62 ~93 ~38 wooden_slab 0
setblock ~63 ~93 ~13 spruce_stairs 5
setblock ~63 ~93 ~14 sandstone_stairs 4
fill ~63 ~93 ~38 ~65 ~93 ~38 planks 0
setblock ~64 ~93 ~12 dark_oak_stairs 4
fill ~64 ~93 ~14 ~64 ~93 ~15 double_stone_slab 9
setblock ~64 ~93 ~39 wooden_slab 0
setblock ~65 ~93 ~13 spruce_stairs 4
setblock ~65 ~93 ~14 sandstone_stairs 5
setblock ~66 ~93 ~12 spruce_stairs 2
fill ~66 ~93 ~14 ~66 ~94 ~14 stone_slab 1
fill ~66 ~93 ~15 ~66 ~94 ~15 double_stone_slab 9
setblock ~66 ~93 ~37 planks 0
setblock ~66 ~93 ~38 wooden_slab 0
setblock ~67 ~93 ~13 wooden_slab 9
setblock ~67 ~93 ~15 sandstone_stairs 5
fill ~67 ~93 ~16 ~67 ~96 ~16 double_stone_slab 9
fill ~67 ~93 ~36 ~69 ~93 ~36 planks 0
setblock ~67 ~93 ~37 double_wooden_slab 0
setblock ~68 ~93 ~15 stone_slab 1
setblock ~68 ~93 ~16 planks 2
setblock ~68 ~93 ~17 double_stone_slab 9
fill ~68 ~93 ~26 ~70 ~93 ~26 planks 1
setblock ~68 ~93 ~37 wooden_slab 0
setblock ~69 ~93 ~17 planks 2
fill ~69 ~93 ~31 ~70 ~93 ~31 planks 5
setblock ~70 ~93 ~12 spruce_stairs 4
fill ~70 ~93 ~18 ~70 ~95 ~18 planks 2
fill ~70 ~93 ~19 ~70 ~95 ~19 double_stone_slab 9
setblock ~70 ~93 ~20 planks 1
fill ~70 ~93 ~28 ~70 ~94 ~28 planks 1
fill ~70 ~93 ~29 ~70 ~94 ~29 planks 5
fill ~70 ~93 ~30 ~70 ~94 ~30 planks 5
fill ~70 ~93 ~33 ~70 ~91 ~33 planks 0
setblock ~71 ~93 ~19 sandstone_stairs 1
setblock ~71 ~93 ~20 double_stone_slab 9
setblock ~71 ~93 ~21 planks 5
fill ~71 ~93 ~22 ~71 ~94 ~22 double_stone_slab 9
fill ~71 ~93 ~23 ~71 ~93 ~24 planks 1
setblock ~71 ~93 ~26 double_wooden_slab 1
setblock ~71 ~93 ~27 planks 1
setblock ~71 ~93 ~28 cobblestone 0
setblock ~71 ~93 ~34 wooden_slab 0
setblock ~71 ~93 ~35 planks 0
setblock ~72 ~93 ~22 stone_slab 1
fill ~72 ~93 ~23 ~72 ~93 ~24 double_stone_slab 9
setblock ~72 ~93 ~25 wooden_slab 13
setblock ~72 ~93 ~26 wooden_slab 9
setblock ~72 ~93 ~30 stone_brick_stairs 2
setblock ~72 ~93 ~34 planks 2
setblock ~73 ~93 ~21 stone_slab 9
setblock ~73 ~93 ~32 cobblestone 0
setblock ~73 ~93 ~33 planks 0
setblock ~73 ~93 ~34 oak_stairs 5
setblock ~74 ~93 ~34 oak_stairs 4
setblock ~75 ~93 ~34 planks 0
setblock ~77 ~93 ~34 planks 1
setblock ~80 ~93 ~38 planks 1
setblock ~82 ~93 ~39 planks 1
fill ~89 ~93 ~41 ~89 ~94 ~41 planks 5
setblock ~40 ~94 ~41 planks 5
setblock ~41 ~94 ~40 planks 1
setblock ~46 ~94 ~38 planks 1
setblock ~48 ~94 ~38 planks 0
fill ~51 ~94 ~34 ~52 ~94 ~34 planks 0
setblock ~53 ~94 ~33 planks 1
setblock ~53 ~94 ~34 wooden_slab 0
setblock ~54 ~94 ~33 planks 2
setblock ~55 ~94 ~25 wooden_slab 8
fill ~55 ~94 ~32 ~55 ~96 ~32 planks 0
setblock ~55 ~94 ~33 stone 6
setblock ~55 ~94 ~34 oak_stairs 3
setblock ~56 ~94 ~21 sandstone_stairs 0
setblock ~56 ~94 ~23 stone_slab 9
setblock ~56 ~94 ~24 planks 5
setblock ~56 ~94 ~25 planks 0
setblock ~56 ~94 ~26 planks 5
fill ~56 ~94 ~27 ~56 ~98 ~27 planks 1
fill ~56 ~94 ~30 ~57 ~94 ~30 cobblestone 0
setblock ~56 ~94 ~31 stone_stairs 3
fill ~56 ~94 ~33 ~56 ~95 ~33 planks 0
fill ~56 ~94 ~34 ~57 ~94 ~34 planks 0
fill ~57 ~94 ~18 ~57 ~95 ~18 wooden_slab 10
fill ~57 ~94 ~20 ~57 ~95 ~20 planks 5
setblock ~57 ~94 ~21 planks 1
fill ~57 ~94 ~23 ~57 ~95 ~23 double_stone_slab 9
fill ~57 ~94 ~24 ~57 ~94 ~26 planks 1
setblock ~57 ~94 ~27 stone 6
fill ~57 ~94 ~28 ~57 ~95 ~28 planks 1
setblock ~57 ~94 ~29 stone_stairs 2
fill ~57 ~94 ~31 ~58 ~94 ~31 planks 5
fill ~57 ~94 ~32 ~58 ~94 ~32 planks 5
fill ~57 ~94 ~33 ~57 ~94 ~31 planks 5
setblock ~57 ~94 ~35 wooden_slab 8
setblock ~58 ~94 ~12 spruce_stairs 0
setblock ~58 ~94 ~15 sandstone_stairs 0
setblock ~58 ~94 ~17 planks 2
fill ~58 ~94 ~20 ~58 ~95 ~20 double_stone_slab 9
fill ~58 ~94 ~25 ~58 ~92 ~25 planks 1
fill ~58 ~94 ~26 ~59 ~94 ~26 planks 1
setblock ~59 ~94 ~13 spruce_stairs 5
setblock ~59 ~94 ~16 planks 2
fill ~59 ~94 ~17 ~59 ~95 ~17 double_stone_slab 9
fill ~59 ~94 ~35 ~60 ~94 ~35 planks 0
setblock ~60 ~94 ~12 dark_oak_stairs 5
setblock ~60 ~94 ~13 wooden_slab 9
fill ~60 ~94 ~15 ~63 ~94 ~15 double_stone_slab 9
fill ~60 ~94 ~16 ~60 ~96 ~16 double_stone_slab 9
setblock ~60 ~94 ~36 wooden_slab 0
setblock ~61 ~94 ~13 spruce_stairs 2
setblock ~61 ~94 ~14 sandstone_stairs 6
fill ~61 ~94 ~36 ~62 ~94 ~36 planks 0
setblock ~62 ~94 ~13 planks 1
setblock ~62 ~94 ~37 wooden_slab 0
setblock ~63 ~94 ~12 dark_oak_stairs 6
setblock ~63 ~94 ~13 wooden_slab 13
fill ~63 ~94 ~14 ~65 ~94 ~14 planks 1
fill ~63 ~94 ~37 ~65 ~94 ~37 planks 0
setblock ~64 ~94 ~12 planks 5
setblock ~64 ~94 ~38 wooden_slab 0
setblock ~65 ~94 ~12 dark_oak_stairs 6
setblock ~65 ~94 ~13 wooden_slab 13
setblock ~66 ~94 ~13 planks 1
fill ~66 ~94 ~36 ~67 ~94 ~36 planks 0
setblock ~66 ~94 ~37 wooden_slab 0
setblock ~67 ~94 ~13 spruce_stairs 2
setblock ~67 ~94 ~14 sandstone_stairs 6
fill ~67 ~94 ~15 ~68 ~94 ~15 double_stone_slab 9
setblock ~68 ~94 ~12 dark_oak_stairs 4
setblock ~68 ~94 ~13 wooden_slab 9
fill ~68 ~94 ~16 ~68 ~96 ~16 double_stone_slab 9
fill ~68 ~94 ~35 ~70 ~94 ~35 planks 0
setblock ~68 ~94 ~36 wooden_slab 0
setblock ~69 ~94 ~13 spruce_stairs 4
setblock ~69 ~94 ~16 planks 2
fill ~69 ~94 ~17 ~69 ~95 ~17 double_stone_slab 9
fill ~69 ~94 ~26 ~71 ~94 ~26 planks 1
setblock ~70 ~94 ~12 spruce_stairs 1
setblock ~70 ~94 ~15 sandstone_stairs 1
setblock ~70 ~94 ~17 planks 2
fill ~70 ~94 ~20 ~70 ~95 ~20 double_stone_slab 9
fill ~70 ~94 ~31 ~71 ~94 ~31 planks 5
fill ~70 ~94 ~32 ~71 ~94 ~32 planks 5
fill ~71 ~94 ~18 ~71 ~95 ~18 wooden_slab 10
fill ~71 ~94 ~20 ~71 ~95 ~20 planks 5
setblock ~71 ~94 ~21 planks 1
fill ~71 ~94 ~23 ~71 ~95 ~23 double_stone_slab 9
fill ~71 ~94 ~24 ~71 ~94 ~26 planks 1
setblock ~71 ~94 ~27 stone 6
fill ~71 ~94 ~28 ~71 ~95 ~28 planks 1
setblock ~71 ~94 ~29 stone_stairs 2
fill ~71 ~94 ~30 ~72 ~94 ~30 cobblestone 0
setblock ~71 ~94 ~33 planks 5
fill ~71 ~94 ~34 ~72 ~94 ~34 planks 0
setblock ~71 ~94 ~35 wooden_slab 8
setblock ~72 ~94 ~21 sandstone_stairs 1
setblock ~72 ~94 ~23 stone_slab 9
setblock ~72 ~94 ~24 planks 5
setblock ~72 ~94 ~25 planks 0
setblock ~72 ~94 ~26 planks 5
fill ~72 ~94 ~27 ~72 ~98 ~27 planks 1
setblock ~72 ~94 ~31 stone_stairs 3
fill ~72 ~94 ~33 ~72 ~95 ~33 planks 0
setblock ~73 ~94 ~25 wooden_slab 8
fill ~73 ~94 ~32 ~73 ~96 ~32 planks 0
setblock ~73 ~94 ~33 stone 6
setblock ~73 ~94 ~34 oak_stairs 3
setblock ~74 ~94 ~33 planks 2
setblock ~75 ~94 ~33 planks 1
setblock ~75 ~94 ~34 wooden_slab 0
fill ~76 ~94 ~34 ~77 ~94 ~34 planks 0
setblock ~80 ~94 ~38 planks 0
setblock ~82 ~94 ~38 planks 1
setblock ~87 ~94 ~40 planks 1
setblock ~88 ~94 ~41 planks 5
setblock ~40 ~95 ~40 planks 1
setblock ~41 ~95 ~40 planks 5
fill ~42 ~95 ~40 ~42 ~96 ~40 planks 1
setblock ~47 ~95 ~38 planks 0
setblock ~48 ~95 ~37 planks 1
fill ~49 ~95 ~37 ~49 ~96 ~37 planks 0
setblock ~52 ~95 ~34 planks 1
setblock ~53 ~95 ~33 planks 0
fill ~54 ~95 ~32 ~54 ~96 ~32 planks 0
fill ~54 ~95 ~33 ~54 ~96 ~33 wooden_slab 0
setblock ~55 ~95 ~25 wooden_slab 0
setblock ~55 ~95 ~26 planks 5
setblock ~55 ~95 ~33 planks 0
setblock ~55 ~95 ~34 wooden_slab 0
setblock ~56 ~95 ~22 sandstone_stairs 0
setblock ~56 ~95 ~24 wooden_slab 5
setblock ~56 ~95 ~25 wooden_slab 8
fill ~56 ~95 ~26 ~57 ~95 ~26 planks 1
fill ~56 ~95 ~28 ~56 ~97 ~28 planks 1
fill ~56 ~95 ~30 ~57 ~95 ~30 double_stone_slab 5
fill ~56 ~95 ~32 ~56 ~96 ~32 planks 0
setblock ~56 ~95 ~34 wooden_slab 8
setblock ~57 ~95 ~19 double_wooden_slab 2
setblock ~57 ~95 ~21 double_stone_slab 9
setblock ~57 ~95 ~22 planks 1
setblock ~57 ~95 ~24 planks 5
setblock ~57 ~95 ~25 planks 1
setblock ~57 ~95 ~27 planks 1
fill ~57 ~95 ~29 ~57 ~96 ~29 planks 5
fill ~57 ~95 ~31 ~58 ~95 ~31 planks 5
fill ~57 ~95 ~32 ~58 ~95 ~32 planks 5
fill ~57 ~95 ~33 ~57 ~96 ~33 planks 0
fill ~57 ~95 ~34 ~60 ~95 ~34 planks 0
setblock ~57 ~95 ~36 wooden_slab 9
setblock ~58 ~95 ~13 wooden_slab 1
setblock ~58 ~95 ~14 wooden_slab 9
setblock ~58 ~95 ~17 wooden_slab 2
setblock ~58 ~95 ~21 spruce_stairs 0
setblock ~58 ~95 ~23 planks 0
setblock ~59 ~95 ~13 spruce_stairs 1
fill ~59 ~95 ~14 ~59 ~96 ~14 planks 0
fill ~59 ~95 ~15 ~61 ~95 ~15 double_stone_slab 9
setblock ~59 ~95 ~16 sandstone_stairs 4
setblock ~59 ~95 ~18 planks 2
setblock ~59 ~95 ~35 wooden_slab 0
setblock ~60 ~95 ~12 dark_oak_stairs 0
setblock ~60 ~95 ~13 planks 1
setblock ~60 ~95 ~33 planks 0
fill ~60 ~95 ~35 ~61 ~95 ~35 planks 0
setblock ~61 ~95 ~12 planks 5
fill ~61 ~95 ~13 ~62 ~95 ~13 planks 0
fill ~61 ~95 ~14 ~63 ~95 ~14 double_stone_slab 9
fill ~62 ~95 ~12 ~63 ~95 ~12 wooden_slab 5
fill ~62 ~95 ~36 ~66 ~95 ~36 planks 0
setblock ~62 ~95 ~37 wooden_slab 9
setblock ~63 ~95 ~13 planks 5
setblock ~63 ~95 ~37 spruce_stairs 4
setblock ~64 ~95 ~13 wooden_slab 5
fill ~64 ~95 ~14 ~64 ~96 ~14 planks 0
setblock ~64 ~95 ~37 double_wooden_slab 1
setblock ~64 ~95 ~38 wooden_slab 1
fill ~65 ~95 ~12 ~66 ~95 ~12 wooden_slab 5
setblock ~65 ~95 ~13 planks 5
fill ~65 ~95 ~14 ~67 ~95 ~14 double_stone_slab 9
setblock ~65 ~95 ~37 spruce_stairs 5
fill ~66 ~95 ~13 ~67 ~95 ~13 planks 0
setblock ~66 ~95 ~37 wooden_slab 9
setblock ~67 ~95 ~12 planks 5
fill ~67 ~95 ~15 ~69 ~95 ~15 double_stone_slab 9
fill ~67 ~95 ~35 ~68 ~95 ~35 planks 0
setblock ~68 ~95 ~12 dark_oak_stairs 1
setblock ~68 ~95 ~13 planks 1
fill ~68 ~95 ~33 ~68 ~95 ~35 planks 0
setblock ~69 ~95 ~13 spruce_stairs 0
fill ~69 ~95 ~14 ~69 ~96 ~14 planks 0
setblock ~69 ~95 ~16 sandstone_stairs 5
setblock ~69 ~95 ~18 planks 2
fill ~69 ~95 ~34 ~71 ~95 ~34 planks 0
setblock ~69 ~95 ~35 wooden_slab 0
setblock ~70 ~95 ~13 wooden_slab 1
setblock ~70 ~95 ~14 wooden_slab 9
setblock ~70 ~95 ~17 wooden_slab 2
setblock ~70 ~95 ~21 spruce_stairs 1
setblock ~70 ~95 ~23 planks 0
fill ~70 ~95 ~31 ~71 ~95 ~31 planks 5
fill ~70 ~95 ~32 ~71 ~95 ~32 planks 5
setblock ~71 ~95 ~19 double_wooden_slab 2
setblock ~71 ~95 ~21 double_stone_slab 9
setblock ~71 ~95 ~22 planks 1
setblock ~71 ~95 ~24 planks 5
fill ~71 ~95 ~25 ~71 ~95 ~28 planks 1
fill ~71 ~95 ~29 ~71 ~96 ~29 planks 5
fill ~71 ~95 ~30 ~72 ~95 ~30 double_stone_slab 5
fill ~71 ~95 ~33 ~71 ~96 ~33 planks 0
setblock ~71 ~95 ~36 wooden_slab 9
setblock ~72 ~95 ~22 sandstone_stairs 1
setblock ~72 ~95 ~24 wooden_slab 5
setblock ~72 ~95 ~25 wooden_slab 8
setblock ~72 ~95 ~26 planks 1
fill ~72 ~95 ~28 ~72 ~97 ~28 planks 1
fill ~72 ~95 ~32 ~72 ~96 ~32 planks 0
setblock ~72 ~95 ~34 wooden_slab 8
setblock ~73 ~95 ~25 wooden_slab 0
setblock ~73 ~95 ~26 planks 5
setblock ~73 ~95 ~33 planks 0
setblock ~73 ~95 ~34 wooden_slab 0
fill ~74 ~95 ~32 ~74 ~96 ~32 planks 0
fill ~74 ~95 ~33 ~74 ~96 ~33 wooden_slab 0
setblock ~75 ~95 ~33 planks 0
setblock ~76 ~95 ~34 planks 1
fill ~79 ~95 ~37 ~79 ~96 ~37 planks 0
setblock ~80 ~95 ~37 planks 1
setblock ~81 ~95 ~38 planks 0
fill ~86 ~95 ~40 ~86 ~96 ~40 planks 1
setblock ~87 ~95 ~40 planks 5
setblock ~88 ~95 ~40 planks 1
setblock ~32 ~96 ~41 planks 5
setblock ~41 ~96 ~40 planks 1
fill ~43 ~96 ~39 ~43 ~97 ~39 planks 1
setblock ~47 ~96 ~38 planks 1
fill ~48 ~96 ~37 ~48 ~97 ~37 planks 0
setblock ~50 ~96 ~36 planks 2
setblock ~52 ~96 ~16 planks 0
setblock ~52 ~96 ~33 planks 0
setblock ~53 ~96 ~14 wooden_slab 1
setblock ~53 ~96 ~33 double_stone_slab 9
setblock ~54 ~96 ~14 wooden_slab 9
setblock ~55 ~96 ~26 dark_oak_stairs 2
setblock ~55 ~96 ~27 planks 1
setblock ~55 ~96 ~28 wooden_slab 9
fill ~55 ~96 ~33 ~56 ~96 ~33 wooden_slab 9
setblock ~55 ~96 ~34 wooden_slab 1
setblock ~56 ~96 ~12 wooden_slab 5
setblock ~56 ~96 ~14 spruce_stairs 5
setblock ~56 ~96 ~19 birch_stairs 6
setblock ~56 ~96 ~20 planks 2
setblock ~56 ~96 ~21 wooden_slab 13
setblock ~56 ~96 ~24 wooden_slab 0
setblock ~56 ~96 ~25 oak_stairs 2
setblock ~56 ~96 ~26 planks 5
fill ~56 ~96 ~29 ~56 ~97 ~29 planks 5
setblock ~56 ~96 ~31 planks 5
setblock ~56 ~96 ~34 wooden_slab 9
setblock ~57 ~96 ~12 wooden_slab 13
setblock ~57 ~96 ~14 spruce_stairs 4
setblock ~57 ~96 ~17 sandstone_stairs 6
fill ~57 ~96 ~18 ~58 ~96 ~18 double_stone_slab 9
setblock ~57 ~96 ~19 planks 2
setblock ~57 ~96 ~20 double_stone_slab 9
fill ~57 ~96 ~21 ~57 ~96 ~22 planks 5
setblock ~57 ~96 ~23 dark_oak_stairs 4
setblock ~57 ~96 ~24 double_wooden_slab 0
setblock ~57 ~96 ~25 wooden_slab 8
setblock ~57 ~96 ~26 planks 1
setblock ~57 ~96 ~30 planks 5
fill ~57 ~96 ~31 ~57 ~99 ~31 planks 1
fill ~57 ~96 ~32 ~57 ~94 ~32 planks 5
setblock ~58 ~96 ~13 dark_oak_stairs 5
fill ~58 ~96 ~14 ~58 ~97 ~14 planks 0
fill ~58 ~96 ~15 ~58 ~96 ~14 planks 0
setblock ~58 ~96 ~16 sandstone_stairs 4
fill ~58 ~96 ~17 ~58 ~97 ~17 double_stone_slab 9
fill ~58 ~96 ~32 ~58 ~99 ~32 planks 1
setblock ~58 ~96 ~33 spruce_stairs 4
setblock ~58 ~96 ~34 wooden_slab 9
setblock ~58 ~96 ~35 wooden_slab 1
setblock ~59 ~96 ~11 wooden_slab 9
setblock ~59 ~96 ~13 wooden_slab 0
setblock ~59 ~96 ~16 double_stone_slab 9
fill ~59 ~96 ~33 ~60 ~96 ~33 planks 1
setblock ~59 ~96 ~35 planks 1
setblock ~60 ~96 ~13 dark_oak_stairs 4
fill ~60 ~96 ~14 ~60 ~97 ~14 planks 0
fill ~60 ~96 ~34 ~61 ~96 ~34 planks 1
setblock ~60 ~96 ~35 wooden_slab 9
setblock ~61 ~96 ~12 wooden_slab 9
setblock ~61 ~96 ~13 planks 5
setblock ~61 ~96 ~35 spruce_stairs 4
setblock ~62 ~96 ~12 planks 1
fill ~62 ~96 ~15 ~63 ~96 ~15 planks 0
setblock ~62 ~96 ~35 planks 0
setblock ~62 ~96 ~36 wooden_slab 1
setblock ~63 ~96 ~12 wooden_slab 8
setblock ~63 ~96 ~13 planks 1
setblock ~63 ~96 ~36 wooden_slab 8
setblock ~63 ~96 ~37 wooden_slab 1
setblock ~64 ~96 ~12 planks 1
fill ~64 ~96 ~13 ~64 ~97 ~13 planks 0
setblock ~64 ~96 ~36 planks 0
setblock ~64 ~96 ~37 planks 1
setblock ~64 ~96 ~38 wooden_slab 0
setblock ~65 ~96 ~12 wooden_slab 8
setblock ~65 ~96 ~13 planks 1
fill ~65 ~96 ~15 ~66 ~96 ~15 planks 0
setblock ~65 ~96 ~36 wooden_slab 8
setblock ~65 ~96 ~37 wooden_slab 1
setblock ~66 ~96 ~12 planks 1
setblock ~66 ~96 ~35 planks 0
setblock ~66 ~96 ~36 wooden_slab 1
setblock ~67 ~96 ~12 wooden_slab 9
setblock ~67 ~96 ~13 planks 5
fill ~67 ~96 ~34 ~68 ~96 ~34 planks 1
setblock ~67 ~96 ~35 spruce_stairs 5
setblock ~68 ~96 ~13 dark_oak_stairs 5
fill ~68 ~96 ~14 ~68 ~97 ~14 planks 0
fill ~68 ~96 ~33 ~69 ~96 ~33 planks 1
setblock ~68 ~96 ~35 wooden_slab 9
setblock ~69 ~96 ~11 wooden_slab 9
setblock ~69 ~96 ~13 wooden_slab 0
setblock ~69 ~96 ~16 double_stone_slab 9
setblock ~69 ~96 ~35 planks 1
setblock ~70 ~96 ~13 dark_oak_stairs 4
fill ~70 ~96 ~14 ~70 ~97 ~14 planks 0
fill ~70 ~96 ~15 ~70 ~96 ~14 planks 0
setblock ~70 ~96 ~16 sandstone_stairs 5
fill ~70 ~96 ~17 ~70 ~97 ~17 double_stone_slab 9
fill ~70 ~96 ~18 ~71 ~96 ~18 double_stone_slab 9
fill ~70 ~96 ~32 ~70 ~99 ~32 planks 1
setblock ~70 ~96 ~33 spruce_stairs 5
setblock ~70 ~96 ~34 wooden_slab 9
setblock ~70 ~96 ~35 wooden_slab 1
setblock ~71 ~96 ~12 wooden_slab 13
setblock ~71 ~96 ~14 spruce_stairs 5
setblock ~71 ~96 ~17 sandstone_stairs 6
setblock ~71 ~96 ~19 planks 2
setblock ~71 ~96 ~20 double_stone_slab 9
fill ~71 ~96 ~21 ~71 ~96 ~22 planks 5
setblock ~71 ~96 ~23 dark_oak_stairs 5
setblock ~71 ~96 ~24 double_wooden_slab 0
setblock ~71 ~96 ~25 wooden_slab 8
setblock ~71 ~96 ~26 planks 1
setblock ~71 ~96 ~30 planks 5
fill ~71 ~96 ~31 ~71 ~99 ~31 planks 1
setblock ~71 ~96 ~32 planks 5
setblock ~72 ~96 ~12 wooden_slab 5
setblock ~72 ~96 ~14 spruce_stairs 4
setblock ~72 ~96 ~19 birch_stairs 6
setblock ~72 ~96 ~20 planks 2
setblock ~72 ~96 ~21 wooden_slab 13
setblock ~72 ~96 ~24 wooden_slab 0
setblock ~72 ~96 ~25 oak_stairs 2
setblock ~72 ~96 ~26 planks 5
fill ~72 ~96 ~29 ~72 ~97 ~29 planks 5
setblock ~72 ~96 ~31 planks 5
fill ~72 ~96 ~33 ~73 ~96 ~33 wooden_slab 9
fill ~72 ~96 ~34 ~72 ~96 ~33 wooden_slab 9
setblock ~73 ~96 ~26 dark_oak_stairs 2
setblock ~73 ~96 ~27 planks 1
setblock ~73 ~96 ~28 wooden_slab 9
setblock ~73 ~96 ~34 wooden_slab 1
setblock ~74 ~96 ~14 wooden_slab 9
setblock ~75 ~96 ~14 wooden_slab 1
setblock ~75 ~96 ~33 double_stone_slab 9
setblock ~76 ~96 ~16 planks 0
setblock ~76 ~96 ~33 planks 0
setblock ~78 ~96 ~36 planks 2
fill ~80 ~96 ~37 ~80 ~97 ~37 planks 0
setblock ~81 ~96 ~38 planks 1
fill ~85 ~96 ~39 ~85 ~97 ~39 planks 1
setblock ~87 ~96 ~40 planks 1
setblock ~96 ~96 ~41 planks 5
fill ~33 ~97 ~41 ~33 ~98 ~41 planks 5
fill ~41 ~97 ~39 ~43 ~97 ~39 planks 1
fill ~42 ~97 ~37 ~42 ~98 ~37 stone_slab 8
setblock ~44 ~97 ~36 stone_brick_stairs 5
setblock ~44 ~97 ~38 planks 0
fill ~46 ~97 ~35 ~46 ~98 ~35 stone_slab 8
fill ~49 ~97 ~36 ~50 ~97 ~36 planks 0
setblock ~51 ~97 ~35 planks 2
fill ~52 ~97 ~33 ~52 ~98 ~33 planks 2
setblock ~53 ~97 ~16 planks 0
setblock ~53 ~97 ~32 planks 2
setblock ~54 ~97 ~14 spruce_stairs 0
setblock ~54 ~97 ~27 wooden_slab 13
setblock ~54 ~97 ~31 planks 2
setblock ~55 ~97 ~14 planks 1
fill ~55 ~97 ~16 ~55 ~98 ~16 planks 0
fill ~55 ~97 ~19 ~56 ~97 ~19 double_stone_slab 9
setblock ~55 ~97 ~20 stone_slab 9
fill ~55 ~97 ~25 ~55 ~97 ~26 wooden_slab 8
setblock ~55 ~97 ~27 wooden_slab 5
fill ~55 ~97 ~28 ~55 ~98 ~28 planks 1
fill ~55 ~97 ~29 ~55 ~98 ~29 planks 1
setblock ~55 ~97 ~31 wooden_slab 10
setblock ~55 ~97 ~32 wooden_slab 1
fill ~56 ~97 ~14 ~57 ~97 ~14 wooden_slab 1
fill ~56 ~97 ~15 ~57 ~97 ~15 planks 0
setblock ~56 ~97 ~17 sandstone_stairs 6
fill ~56 ~97 ~18 ~57 ~97 ~18 double_stone_slab 9
fill ~56 ~97 ~20 ~56 ~98 ~20 double_stone_slab 9
setblock ~56 ~97 ~21 planks 2
setblock ~56 ~97 ~22 dark_oak_stairs 7
setblock ~56 ~97 ~23 wooden_slab 0
setblock ~56 ~97 ~24 wooden_slab 8
fill ~56 ~97 ~25 ~56 ~97 ~26 wooden_slab 0
fill ~56 ~97 ~30 ~56 ~100 ~30 planks 1
setblock ~56 ~97 ~31 wooden_slab 1
setblock ~56 ~97 ~32 wooden_slab 8
setblock ~56 ~97 ~33 wooden_slab 0
setblock ~57 ~97 ~12 wooden_slab 5
fill ~57 ~97 ~13 ~58 ~97 ~13 dark_oak_stairs 0
setblock ~57 ~97 ~16 sandstone_stairs 4
fill ~57 ~97 ~17 ~57 ~98 ~17 double_stone_slab 9
setblock ~57 ~97 ~22 planks 5
setblock ~57 ~97 ~23 planks 0
setblock ~57 ~97 ~24 wooden_slab 0
setblock ~57 ~97 ~32 planks 1
setblock ~57 ~97 ~33 wooden_slab 8
setblock ~57 ~97 ~34 wooden_slab 1
setblock ~58 ~97 ~12 planks 5
setblock ~58 ~97 ~16 double_stone_slab 9
setblock ~58 ~97 ~33 oak_stairs 0
setblock ~59 ~97 ~12 wooden_slab 5
setblock ~59 ~97 ~13 planks 5
fill ~59 ~97 ~33 ~59 ~96 ~33 planks 1
setblock ~59 ~97 ~34 planks 0
fill ~60 ~97 ~12 ~61 ~97 ~12 planks 1
fill ~60 ~97 ~34 ~61 ~97 ~34 planks 1
setblock ~60 ~97 ~35 wooden_slab 8
setblock ~61 ~97 ~11 oak_stairs 4
setblock ~61 ~97 ~14 planks 0
setblock ~61 ~97 ~35 oak_stairs 1
fill ~62 ~97 ~11 ~62 ~97 ~12 planks 0
setblock ~62 ~97 ~35 wooden_slab 9
setblock ~62 ~97 ~36 spruce_stairs 0
setblock ~63 ~97 ~11 wooden_slab 8
setblock ~63 ~97 ~12 planks 0
fill ~63 ~97 ~35 ~63 ~98 ~35 planks 1
fill ~63 ~97 ~36 ~63 ~97 ~35 planks 1
setblock ~64 ~97 ~12 oak_stairs 6
setblock ~64 ~97 ~15 planks 0
setblock ~64 ~97 ~35 planks 0
setblock ~64 ~97 ~36 spruce_stairs 3
setblock ~64 ~97 ~37 wooden_slab 0
setblock ~65 ~97 ~11 wooden_slab 8
fill ~65 ~97 ~12 ~66 ~97 ~12 planks 0
fill ~65 ~97 ~35 ~65 ~98 ~35 planks 1
fill ~65 ~97 ~36 ~65 ~97 ~35 planks 1
setblock ~66 ~97 ~11 planks 0
setblock ~66 ~97 ~35 wooden_slab 9
setblock ~66 ~97 ~36 spruce_stairs 1
setblock ~67 ~97 ~11 oak_stairs 5
fill ~67 ~97 ~12 ~68 ~97 ~12 planks 1
setblock ~67 ~97 ~14 planks 0
fill ~67 ~97 ~34 ~68 ~97 ~34 planks 1
setblock ~67 ~97 ~35 oak_stairs 0
setblock ~68 ~97 ~35 wooden_slab 8
setblock ~69 ~97 ~12 wooden_slab 5
setblock ~69 ~97 ~13 planks 5
setblock ~69 ~97 ~33 planks 1
setblock ~69 ~97 ~34 planks 0
setblock ~70 ~97 ~12 planks 5
fill ~70 ~97 ~13 ~71 ~97 ~13 dark_oak_stairs 1
setblock ~70 ~97 ~16 double_stone_slab 9
setblock ~70 ~97 ~33 oak_stairs 1
setblock ~71 ~97 ~12 wooden_slab 5
fill ~71 ~97 ~14 ~72 ~97 ~14 wooden_slab 1
fill ~71 ~97 ~15 ~72 ~97 ~15 planks 0
setblock ~71 ~97 ~16 sandstone_stairs 5
fill ~71 ~97 ~17 ~71 ~98 ~17 double_stone_slab 9
fill ~71 ~97 ~18 ~72 ~97 ~18 double_stone_slab 9
setblock ~71 ~97 ~22 planks 5
setblock ~71 ~97 ~23 planks 0
setblock ~71 ~97 ~24 wooden_slab 0
setblock ~71 ~97 ~32 planks 1
setblock ~71 ~97 ~33 wooden_slab 8
setblock ~71 ~97 ~34 wooden_slab 1
setblock ~72 ~97 ~17 sandstone_stairs 6
fill ~72 ~97 ~19 ~73 ~97 ~19 double_stone_slab 9
fill ~72 ~97 ~20 ~72 ~98 ~20 double_stone_slab 9
setblock ~72 ~97 ~21 planks 2
setblock ~72 ~97 ~22 dark_oak_stairs 7
setblock ~72 ~97 ~23 wooden_slab 0
setblock ~72 ~97 ~24 wooden_slab 8
fill ~72 ~97 ~25 ~72 ~97 ~26 wooden_slab 0
fill ~72 ~97 ~30 ~72 ~100 ~30 planks 1
setblock ~72 ~97 ~31 wooden_slab 1
setblock ~72 ~97 ~32 wooden_slab 8
setblock ~72 ~97 ~33 wooden_slab 0
setblock ~73 ~97 ~14 planks 1
fill ~73 ~97 ~16 ~73 ~98 ~16 planks 0
setblock ~73 ~97 ~20 stone_slab 9
fill ~73 ~97 ~25 ~73 ~97 ~26 wooden_slab 8
setblock ~73 ~97 ~27 wooden_slab 5
fill ~73 ~97 ~28 ~73 ~98 ~28 planks 1
fill ~73 ~97 ~29 ~73 ~98 ~29 planks 1
setblock ~73 ~97 ~31 wooden_slab 10
setblock ~73 ~97 ~32 wooden_slab 1
setblock ~74 ~97 ~14 spruce_stairs 1
setblock ~74 ~97 ~27 wooden_slab 13
setblock ~74 ~97 ~31 planks 2
setblock ~75 ~97 ~16 planks 0
setblock ~75 ~97 ~32 planks 2
fill ~76 ~97 ~33 ~76 ~98 ~33 planks 2
setblock ~77 ~97 ~35 planks 2
fill ~78 ~97 ~36 ~79 ~97 ~36 planks 0
fill ~82 ~97 ~35 ~82 ~98 ~35 stone_slab 8
setblock ~84 ~97 ~36 stone_brick_stairs 4
setblock ~84 ~97 ~38 planks 0
fill ~86 ~97 ~37 ~86 ~98 ~37 stone_slab 8
fill ~86 ~97 ~39 ~87 ~97 ~39 planks 1
fill ~95 ~97 ~41 ~95 ~98 ~41 planks 5
setblock ~34 ~98 ~41 planks 5
setblock ~35 ~98 ~41 planks 1
setblock ~40 ~98 ~38 stone_brick_stairs 4
fill ~42 ~98 ~38 ~43 ~98 ~38 planks 0
setblock ~42 ~98 ~39 wooden_slab 1
setblock ~43 ~98 ~37 stonebrick 0
setblock ~44 ~98 ~36 stone_slab 5
setblock ~44 ~98 ~37 double_stone_slab 8
setblock ~44 ~98 ~38 planks 1
setblock ~45 ~98 ~36 stonebrick 0
fill ~45 ~98 ~37 ~45 ~99 ~37 planks 0
setblock ~48 ~98 ~34 stone_brick_stairs 5
setblock ~49 ~98 ~36 planks 2
setblock ~50 ~98 ~35 double_stone_slab 9
setblock ~51 ~98 ~34 planks 2
setblock ~52 ~98 ~32 planks 2
setblock ~53 ~98 ~17 planks 0
setblock ~53 ~98 ~31 double_stone_slab 9
setblock ~54 ~98 ~16 planks 0
setblock ~54 ~98 ~19 stone_slab 1
setblock ~54 ~98 ~27 wooden_slab 5
setblock ~54 ~98 ~28 planks 1
setblock ~54 ~98 ~30 planks 0
setblock ~54 ~98 ~31 wooden_slab 8
setblock ~55 ~98 ~15 spruce_stairs 0
setblock ~55 ~98 ~17 stone_slab 9
setblock ~55 ~98 ~18 sandstone_stairs 6
fill ~55 ~98 ~19 ~56 ~98 ~19 double_stone_slab 9
setblock ~55 ~98 ~20 sandstone_stairs 7
setblock ~55 ~98 ~21 wooden_slab 5
setblock ~55 ~98 ~26 planks 0
setblock ~55 ~98 ~27 planks 5
setblock ~55 ~98 ~30 double_wooden_slab 0
setblock ~55 ~98 ~31 wooden_slab 2
setblock ~56 ~98 ~14 oak_stairs 4
fill ~56 ~98 ~15 ~56 ~100 ~15 planks 1
setblock ~56 ~98 ~16 planks 0
fill ~56 ~98 ~17 ~56 ~99 ~17 double_stone_slab 9
fill ~56 ~98 ~18 ~56 ~99 ~18 double_stone_slab 9
setblock ~56 ~98 ~21 planks 5
fill ~56 ~98 ~22 ~56 ~100 ~22 planks 0
setblock ~56 ~98 ~23 oak_stairs 4
setblock ~56 ~98 ~24 wooden_slab 0
setblock ~56 ~98 ~25 planks 0
setblock ~56 ~98 ~26 planks 1
fill ~56 ~98 ~29 ~56 ~99 ~29 planks 1
setblock ~56 ~98 ~31 planks 0
setblock ~57 ~98 ~13 wooden_slab 0
fill ~57 ~98 ~14 ~57 ~100 ~14 planks 0
fill ~57 ~98 ~15 ~57 ~98 ~14 planks 0
setblock ~57 ~98 ~16 double_stone_slab 9
fill ~57 ~98 ~23 ~57 ~99 ~23 double_stone_slab 9
fill ~57 ~98 ~24 ~57 ~99 ~24 planks 0
fill ~57 ~98 ~30 ~57 ~101 ~30 planks 1
setblock ~57 ~98 ~32 wooden_slab 0
setblock ~58 ~98 ~11 wooden_slab 9
fill ~58 ~98 ~13 ~58 ~99 ~13 planks 5
fill ~58 ~98 ~31 ~58 ~100 ~31 planks 1
setblock ~58 ~98 ~33 wooden_slab 9
fill ~59 ~98 ~12 ~59 ~99 ~12 planks 1
fill ~59 ~98 ~13 ~59 ~99 ~13 planks 0
fill ~59 ~98 ~32 ~59 ~99 ~32 planks 1
setblock ~59 ~98 ~33 spruce_stairs 0
fill ~60 ~98 ~11 ~61 ~98 ~11 planks 0
fill ~60 ~98 ~12 ~61 ~98 ~12 planks 0
fill ~60 ~98 ~34 ~62 ~98 ~34 planks 1
setblock ~61 ~98 ~10 wooden_slab 8
setblock ~61 ~98 ~35 wooden_slab 9
setblock ~62 ~98 ~10 wooden_slab 2
setblock ~62 ~98 ~11 double_stone_slab 9
fill ~62 ~98 ~12 ~66 ~98 ~12 planks 2
setblock ~62 ~98 ~35 spruce_stairs 0
setblock ~63 ~98 ~10 wooden_slab 10
setblock ~63 ~98 ~11 planks 2
setblock ~64 ~98 ~9 stone_stairs 6
setblock ~64 ~98 ~10 stone_stairs 7
setblock ~64 ~98 ~11 birch_stairs 6
setblock ~64 ~98 ~35 planks 1
setblock ~64 ~98 ~36 wooden_slab 1
setblock ~65 ~98 ~10 wooden_slab 10
setblock ~65 ~98 ~11 planks 2
setblock ~66 ~98 ~10 wooden_slab 2
setblock ~66 ~98 ~11 double_stone_slab 9
fill ~66 ~98 ~34 ~68 ~98 ~34 planks 1
setblock ~66 ~98 ~35 spruce_stairs 1
setblock ~67 ~98 ~10 wooden_slab 8
fill ~67 ~98 ~11 ~68 ~98 ~11 planks 0
fill ~67 ~98 ~12 ~68 ~98 ~12 planks 0
setblock ~67 ~98 ~35 wooden_slab 9
fill ~69 ~98 ~12 ~69 ~99 ~12 planks 1
fill ~69 ~98 ~13 ~69 ~99 ~13 planks 0
fill ~69 ~98 ~32 ~69 ~99 ~32 planks 1
setblock ~69 ~98 ~33 spruce_stairs 1
setblock ~70 ~98 ~11 wooden_slab 9
fill ~70 ~98 ~13 ~70 ~99 ~13 planks 5
fill ~70 ~98 ~31 ~70 ~100 ~31 planks 1
setblock ~70 ~98 ~33 wooden_slab 9
setblock ~71 ~98 ~13 wooden_slab 0
fill ~71 ~98 ~14 ~71 ~100 ~14 planks 0
fill ~71 ~98 ~15 ~71 ~97 ~15 planks 0
setblock ~71 ~98 ~16 double_stone_slab 9
fill ~71 ~98 ~23 ~71 ~99 ~23 double_stone_slab 9
fill ~71 ~98 ~24 ~71 ~99 ~24 planks 0
fill ~71 ~98 ~30 ~71 ~101 ~30 planks 1
setblock ~71 ~98 ~32 wooden_slab 0
setblock ~72 ~98 ~14 oak_stairs 5
fill ~72 ~98 ~15 ~72 ~100 ~15 planks 1
setblock ~72 ~98 ~16 planks 0
fill ~72 ~98 ~17 ~72 ~99 ~17 double_stone_slab 9
fill ~72 ~98 ~18 ~72 ~99 ~18 double_stone_slab 9
fill ~72 ~98 ~19 ~73 ~98 ~19 double_stone_slab 9
setblock ~72 ~98 ~21 planks 5
fill ~72 ~98 ~22 ~72 ~100 ~22 planks 0
setblock ~72 ~98 ~23 oak_stairs 5
setblock ~72 ~98 ~24 wooden_slab 0
setblock ~72 ~98 ~25 planks 0
setblock ~72 ~98 ~26 planks 1
fill ~72 ~98 ~29 ~72 ~99 ~29 planks 1
setblock ~72 ~98 ~31 planks 0
setblock ~73 ~98 ~15 spruce_stairs 1
setblock ~73 ~98 ~17 stone_slab 9
setblock ~73 ~98 ~18 sandstone_stairs 6
setblock ~73 ~98 ~20 sandstone_stairs 7
setblock ~73 ~98 ~21 wooden_slab 5
setblock ~73 ~98 ~26 planks 0
setblock ~73 ~98 ~27 planks 5
setblock ~73 ~98 ~30 double_wooden_slab 0
setblock ~73 ~98 ~31 wooden_slab 2
setblock ~74 ~98 ~16 planks 0
setblock ~74 ~98 ~19 stone_slab 1
setblock ~74 ~98 ~27 wooden_slab 5
setblock ~74 ~98 ~28 planks 1
setblock ~74 ~98 ~30 planks 0
setblock ~74 ~98 ~31 wooden_slab 8
setblock ~75 ~98 ~17 planks 0
setblock ~75 ~98 ~31 double_stone_slab 9
setblock ~76 ~98 ~32 planks 2
setblock ~77 ~98 ~34 planks 2
setblock ~78 ~98 ~35 double_stone_slab 9
setblock ~79 ~98 ~36 planks 2
setblock ~80 ~98 ~34 stone_brick_stairs 4
setblock ~83 ~98 ~36 stonebrick 0
fill ~83 ~98 ~37 ~83 ~99 ~37 planks 0
setblock ~84 ~98 ~36 stone_slab 5
setblock ~84 ~98 ~37 double_stone_slab 8
setblock ~84 ~98 ~38 planks 1
setblock ~85 ~98 ~37 stonebrick 0
fill ~85 ~98 ~38 ~86 ~98 ~38 planks 0
setblock ~86 ~98 ~39 wooden_slab 1
setblock ~88 ~98 ~38 stone_brick_stairs 5
setblock ~93 ~98 ~41 planks 1
setblock ~94 ~98 ~41 planks 5
setblock ~34 ~99 ~41 planks 1
setblock ~35 ~99 ~41 planks 5
fill ~36 ~99 ~41 ~36 ~101 ~41 planks 1
setblock ~37 ~99 ~41 wooden_slab 9
setblock ~41 ~99 ~37 stone_brick_stairs 4
setblock ~42 ~99 ~36 stone_brick_stairs 1
setblock ~42 ~99 ~37 double_stone_slab 8
fill ~43 ~99 ~37 ~45 ~99 ~37 planks 0
setblock ~43 ~99 ~38 wooden_slab 0
setblock ~44 ~99 ~36 double_stone_slab 8
setblock ~46 ~99 ~34 stone_brick_stairs 0
