fill ~1 ~-3 ~0 ~47 ~-3 ~0 grass 0
fill ~1 ~-3 ~1 ~47 ~-3 ~1 grass 0
fill ~1 ~-3 ~2 ~30 ~-3 ~2 grass 0
fill ~1 ~-3 ~3 ~47 ~-3 ~3 grass 0
fill ~1 ~-3 ~4 ~47 ~-3 ~4 grass 0
fill ~1 ~-3 ~5 ~47 ~-3 ~5 grass 0
fill ~1 ~-3 ~6 ~20 ~-3 ~6 grass 0
fill ~1 ~-3 ~7 ~18 ~-3 ~7 grass 0
fill ~1 ~-3 ~8 ~16 ~-3 ~8 grass 0
fill ~1 ~-3 ~9 ~14 ~-3 ~9 grass 0
fill ~1 ~-3 ~10 ~13 ~-3 ~10 grass 0
fill ~1 ~-3 ~11 ~12 ~-3 ~11 grass 0
fill ~1 ~-3 ~12 ~11 ~-3 ~12 grass 0
fill ~1 ~-3 ~13 ~11 ~-3 ~13 grass 0
fill ~1 ~-3 ~14 ~10 ~-3 ~14 grass 0
fill ~1 ~-3 ~15 ~10 ~-3 ~15 grass 0
fill ~1 ~-3 ~16 ~9 ~-3 ~16 grass 0
fill ~1 ~-3 ~17 ~9 ~-3 ~17 grass 0
fill ~1 ~-3 ~18 ~8 ~-3 ~18 grass 0
fill ~1 ~-3 ~19 ~8 ~-3 ~19 grass 0
fill ~1 ~-3 ~20 ~8 ~-3 ~20 grass 0
fill ~1 ~-3 ~21 ~8 ~-3 ~21 grass 0
fill ~1 ~-3 ~22 ~8 ~-3 ~22 grass 0
fill ~1 ~-3 ~23 ~8 ~-3 ~23 grass 0
fill ~1 ~-3 ~24 ~8 ~-3 ~24 grass 0
fill ~1 ~-3 ~25 ~8 ~-3 ~25 grass 0
fill ~1 ~-3 ~26 ~8 ~-3 ~26 grass 0
fill ~1 ~-3 ~27 ~9 ~-3 ~27 grass 0
fill ~1 ~-3 ~28 ~9 ~-3 ~28 grass 0
fill ~1 ~-3 ~29 ~10 ~-3 ~29 grass 0
fill ~1 ~-3 ~30 ~10 ~-3 ~30 grass 0
fill ~1 ~-3 ~31 ~11 ~-3 ~31 grass 0
fill ~1 ~-3 ~32 ~11 ~-3 ~32 grass 0
fill ~1 ~-3 ~33 ~12 ~-3 ~33 grass 0
fill ~1 ~-3 ~34 ~13 ~-3 ~34 grass 0
fill ~1 ~-3 ~35 ~14 ~-3 ~35 grass 0
fill ~1 ~-3 ~36 ~16 ~-3 ~36 grass 0
fill ~1 ~-3 ~37 ~18 ~-3 ~37 grass 0
fill ~1 ~-3 ~38 ~20 ~-3 ~38 grass 0
fill ~1 ~-3 ~39 ~47 ~-3 ~39 grass 0
fill ~1 ~-3 ~40 ~47 ~-3 ~40 grass 0
fill ~1 ~-3 ~41 ~47 ~-3 ~41 grass 0
fill ~1 ~-3 ~42 ~47 ~-3 ~42 grass 0
fill ~1 ~-3 ~43 ~3 ~-3 ~43 grass 0
fill ~1 ~-3 ~44 ~3 ~-3 ~44 grass 0
fill ~4 ~-3 ~43 ~4 ~-3 ~43 dirt 0
fill ~4 ~-3 ~44 ~4 ~-3 ~44 dirt 0
fill ~5 ~-3 ~43 ~47 ~-3 ~43 grass 0
fill ~5 ~-3 ~44 ~47 ~-3 ~44 grass 0
fill ~9 ~-3 ~18 ~16 ~-3 ~18 iron_block 0
fill ~9 ~-3 ~19 ~15 ~-3 ~19 iron_block 0
fill ~9 ~-3 ~20 ~16 ~-3 ~20 iron_block 0
fill ~9 ~-3 ~21 ~16 ~-3 ~21 iron_block 0
fill ~9 ~-3 ~22 ~16 ~-3 ~22 iron_block 0
fill ~9 ~-3 ~23 ~16 ~-3 ~23 iron_block 0
fill ~9 ~-3 ~24 ~16 ~-3 ~24 iron_block 0
fill ~9 ~-3 ~25 ~16 ~-3 ~25 iron_block 0
fill ~9 ~-3 ~26 ~16 ~-3 ~26 iron_block 0
fill ~10 ~-3 ~16 ~16 ~-3 ~16 iron_block 0
fill ~10 ~-3 ~17 ~16 ~-3 ~17 iron_block 0
fill ~10 ~-3 ~27 ~16 ~-3 ~27 iron_block 0
fill ~10 ~-3 ~28 ~16 ~-3 ~28 iron_block 0
fill ~11 ~-3 ~14 ~14 ~-3 ~14 iron_block 0
fill ~11 ~-3 ~15 ~15 ~-3 ~15 iron_block 0
fill ~11 ~-3 ~29 ~15 ~-3 ~29 iron_block 0
fill ~11 ~-3 ~30 ~14 ~-3 ~30 iron_block 0
fill ~12 ~-3 ~12 ~16 ~-3 ~12 iron_block 0
fill ~12 ~-3 ~13 ~15 ~-3 ~13 iron_block 0
fill ~12 ~-3 ~31 ~15 ~-3 ~31 iron_block 0
fill ~12 ~-3 ~32 ~16 ~-3 ~32 iron_block 0
fill ~13 ~-3 ~11 ~37 ~-3 ~11 iron_block 0
fill ~13 ~-3 ~33 ~37 ~-3 ~33 iron_block 0
fill ~14 ~-3 ~10 ~36 ~-3 ~10 iron_block 0
fill ~14 ~-3 ~34 ~36 ~-3 ~34 iron_block 0
fill ~15 ~-3 ~9 ~35 ~-3 ~9 iron_block 0
fill ~15 ~-3 ~14 ~19 ~-3 ~14 dirt 0
fill ~15 ~-3 ~30 ~35 ~-3 ~30 dirt 0
fill ~15 ~-3 ~35 ~35 ~-3 ~35 iron_block 0
fill ~16 ~-3 ~13 ~18 ~-3 ~13 dirt 0
fill ~16 ~-3 ~15 ~17 ~-3 ~15 dirt 0
fill ~16 ~-3 ~19 ~17 ~-3 ~19 dirt 0
fill ~16 ~-3 ~29 ~17 ~-3 ~29 dirt 0
fill ~16 ~-3 ~31 ~18 ~-3 ~31 dirt 0
fill ~17 ~-3 ~8 ~33 ~-3 ~8 iron_block 0
fill ~17 ~-3 ~12 ~17 ~-3 ~12 dirt 0
fill ~17 ~-3 ~16 ~17 ~-3 ~16 dirt 0
fill ~17 ~-3 ~17 ~17 ~-3 ~17 dirt 0
fill ~17 ~-3 ~18 ~17 ~-3 ~18 dirt 0
fill ~17 ~-3 ~20 ~17 ~-3 ~20 dirt 0
fill ~17 ~-3 ~21 ~17 ~-3 ~21 dirt 0
fill ~17 ~-3 ~22 ~17 ~-3 ~22 dirt 0
fill ~17 ~-3 ~23 ~17 ~-3 ~23 dirt 0
fill ~17 ~-3 ~24 ~17 ~-3 ~24 dirt 0
fill ~17 ~-3 ~25 ~17 ~-3 ~25 dirt 0
fill ~17 ~-3 ~26 ~17 ~-3 ~26 dirt 0
fill ~17 ~-3 ~27 ~17 ~-3 ~27 dirt 0
fill ~17 ~-3 ~28 ~17 ~-3 ~28 dirt 0
fill ~17 ~-3 ~32 ~17 ~-3 ~32 dirt 0
fill ~17 ~-3 ~36 ~33 ~-3 ~36 iron_block 0
fill ~18 ~-3 ~12 ~32 ~-3 ~12 iron_block 0
setblock ~18 ~-3 ~15 wool 7
setblock ~18 ~-3 ~16 wool 15
fill ~18 ~-3 ~17 ~18 ~-3 ~18 wool 7
setblock ~18 ~-3 ~19 wool 15
setblock ~18 ~-3 ~20 wool 7
setblock ~18 ~-3 ~21 wool 8
setblock ~18 ~-3 ~22 wool 15
setblock ~18 ~-3 ~23 stone 0
setblock ~18 ~-3 ~24 wool 8
setblock ~18 ~-3 ~25 wool 15
setblock ~18 ~-3 ~26 stone 0
fill ~18 ~-3 ~27 ~19 ~-3 ~27 wool 0
setblock ~18 ~-3 ~28 wool 7
setblock ~18 ~-3 ~29 wool 0
fill ~18 ~-3 ~32 ~32 ~-3 ~32 iron_block 0
fill ~19 ~-3 ~7 ~31 ~-3 ~7 iron_block 0
setblock ~19 ~-3 ~13 iron_block 0
fill ~19 ~-3 ~15 ~19 ~-3 ~16 stone 0
setblock ~19 ~-3 ~17 wool 8
fill ~19 ~-3 ~18 ~19 ~-3 ~19 stone 0
setblock ~19 ~-3 ~20 wool 8
setblock ~19 ~-3 ~21 wool 7
setblock ~19 ~-3 ~22 wool 0
setblock ~19 ~-3 ~23 wool 15
setblock ~19 ~-3 ~24 wool 7
setblock ~19 ~-3 ~25 wool 8
setblock ~19 ~-3 ~26 wool 7
setblock ~19 ~-3 ~28 wool 0
setblock ~19 ~-3 ~29 wool 7
fill ~19 ~-3 ~31 ~31 ~-3 ~31 iron_block 0
fill ~19 ~-3 ~37 ~31 ~-3 ~37 iron_block 0
fill ~20 ~-3 ~13 ~21 ~-3 ~13 dirt 0
fill ~20 ~-3 ~14 ~20 ~-3 ~15 iron_block 0
fill ~20 ~-3 ~16 ~20 ~-3 ~17 wool 0
fill ~20 ~-3 ~18 ~20 ~-3 ~20 wool 7
fill ~20 ~-3 ~21 ~20 ~-3 ~22 stone 0
setblock ~20 ~-3 ~23 wool 0
setblock ~20 ~-3 ~24 wool 15
setblock ~20 ~-3 ~25 wool 0
setblock ~20 ~-3 ~26 wool 8
fill ~20 ~-3 ~27 ~20 ~-3 ~28 wool 7
setblock ~20 ~-3 ~29 wool 8
fill ~21 ~-3 ~6 ~29 ~-3 ~6 iron_block 0
fill ~21 ~-3 ~14 ~21 ~-3 ~14 dirt 0
fill ~21 ~-3 ~15 ~24 ~-3 ~15 wool 15
setblock ~21 ~-3 ~16 wool 7
setblock ~21 ~-3 ~17 wool 8
setblock ~21 ~-3 ~18 wool 15
setblock ~21 ~-3 ~19 wool 0
setblock ~21 ~-3 ~20 wool 7
setblock ~21 ~-3 ~21 wool 15
fill ~21 ~-3 ~22 ~22 ~-3 ~22 wool 8
fill ~21 ~-3 ~23 ~21 ~-3 ~22 wool 8
setblock ~21 ~-3 ~24 wool 0
setblock ~21 ~-3 ~25 wool 8
setblock ~21 ~-3 ~26 stone 0
setblock ~21 ~-3 ~27 wool 0
fill ~21 ~-3 ~28 ~21 ~-3 ~29 stone 0
fill ~21 ~-3 ~38 ~29 ~-3 ~38 iron_block 0
setblock ~22 ~-3 ~13 wool 15
setblock ~22 ~-3 ~14 wool 0
setblock ~22 ~-3 ~16 wool 8
fill ~22 ~-3 ~17 ~23 ~-3 ~17 wool 0
fill ~22 ~-3 ~18 ~22 ~-3 ~19 wool 7
setblock ~22 ~-3 ~20 wool 8
fill ~22 ~-3 ~21 ~23 ~-3 ~21 stone 0
setblock ~22 ~-3 ~23 wool 15
setblock ~22 ~-3 ~24 wool 8
setblock ~22 ~-3 ~25 wool 0
setblock ~22 ~-3 ~26 wool 15
setblock ~22 ~-3 ~27 stone 0
setblock ~22 ~-3 ~28 wool 7
setblock ~22 ~-3 ~29 wool 0
fill ~23 ~-3 ~13 ~23 ~-3 ~14 wool 7
setblock ~23 ~-3 ~16 wool 0
setblock ~23 ~-3 ~18 wool 0
fill ~23 ~-3 ~19 ~24 ~-3 ~19 wool 7
setblock ~23 ~-3 ~20 wool 0
fill ~23 ~-3 ~22 ~24 ~-3 ~22 wool 15
fill ~23 ~-3 ~23 ~23 ~-3 ~24 wool 0
setblock ~23 ~-3 ~25 wool 8
setblock ~23 ~-3 ~26 wool 7
setblock ~23 ~-3 ~27 wool 0
fill ~23 ~-3 ~28 ~24 ~-3 ~28 wool 8
fill ~23 ~-3 ~29 ~23 ~-3 ~28 wool 8
setblock ~24 ~-3 ~13 stone 0
setblock ~24 ~-3 ~14 wool 15
setblock ~24 ~-3 ~16 wool 15
fill ~24 ~-3 ~17 ~26 ~-3 ~17 wool 8
setblock ~24 ~-3 ~18 stone 0
fill ~24 ~-3 ~20 ~24 ~-3 ~21 wool 7
fill ~24 ~-3 ~23 ~24 ~-3 ~24 wool 8
fill ~24 ~-3 ~25 ~24 ~-3 ~26 wool 0
setblock ~24 ~-3 ~27 stone 0
fill ~24 ~-3 ~29 ~25 ~-3 ~29 stone 0
setblock ~25 ~-3 ~13 wool 7
fill ~25 ~-3 ~14 ~25 ~-3 ~15 stone 0
setblock ~25 ~-3 ~16 wool 8
setblock ~25 ~-3 ~18 wool 0
setblock ~25 ~-3 ~19 stone 0
fill ~25 ~-3 ~20 ~26 ~-3 ~20 wool 15
fill ~25 ~-3 ~21 ~26 ~-3 ~21 wool 8
setblock ~25 ~-3 ~22 stone 0
setblock ~25 ~-3 ~23 wool 0
setblock ~25 ~-3 ~24 wool 8
setblock ~25 ~-3 ~25 stone 0
setblock ~25 ~-3 ~26 wool 8
setblock ~25 ~-3 ~27 wool 15
setblock ~25 ~-3 ~28 stone 0
fill ~26 ~-3 ~13 ~26 ~-3 ~14 wool 8
setblock ~26 ~-3 ~15 wool 7
fill ~26 ~-3 ~16 ~27 ~-3 ~16 stone 0
setblock ~26 ~-3 ~18 wool 8
setblock ~26 ~-3 ~19 wool 7
fill ~26 ~-3 ~22 ~26 ~-3 ~23 wool 8
setblock ~26 ~-3 ~24 wool 7
setblock ~26 ~-3 ~25 wool 0
setblock ~26 ~-3 ~26 stone 0
setblock ~26 ~-3 ~27 wool 0
fill ~26 ~-3 ~28 ~27 ~-3 ~28 wool 8
setblock ~26 ~-3 ~29 wool 7
setblock ~27 ~-3 ~13 wool 7
fill ~27 ~-3 ~14 ~27 ~-3 ~15 wool 0
fill ~27 ~-3 ~17 ~27 ~-3 ~18 wool 15
setblock ~27 ~-3 ~19 wool 8
fill ~27 ~-3 ~20 ~29 ~-3 ~20 stone 0
setblock ~27 ~-3 ~21 wool 7
fill ~27 ~-3 ~22 ~28 ~-3 ~22 wool 0
setblock ~27 ~-3 ~23 wool 7
setblock ~27 ~-3 ~24 stone 0
setblock ~27 ~-3 ~25 wool 8
setblock ~27 ~-3 ~26 wool 7
fill ~27 ~-3 ~27 ~28 ~-3 ~27 wool 15
setblock ~27 ~-3 ~29 wool 8
setblock ~28 ~-3 ~13 wool 0
setblock ~28 ~-3 ~14 stone 0
setblock ~28 ~-3 ~15 wool 7
setblock ~28 ~-3 ~16 wool 15
setblock ~28 ~-3 ~17 wool 7
fill ~28 ~-3 ~18 ~30 ~-3 ~18 wool 15
fill ~28 ~-3 ~19 ~28 ~-3 ~18 wool 15
fill ~28 ~-3 ~21 ~29 ~-3 ~21 wool 0
fill ~28 ~-3 ~23 ~29 ~-3 ~23 wool 0
fill ~28 ~-3 ~24 ~28 ~-3 ~25 wool 7
setblock ~28 ~-3 ~26 wool 0
setblock ~28 ~-3 ~28 wool 0
setblock ~28 ~-3 ~29 wool 15
fill ~29 ~-3 ~13 ~30 ~-3 ~13 dirt 0
fill ~29 ~-3 ~14 ~29 ~-3 ~14 dirt 0
setblock ~29 ~-3 ~15 wool 15
fill ~29 ~-3 ~16 ~29 ~-3 ~17 stone 0
fill ~29 ~-3 ~19 ~30 ~-3 ~19 wool 0
setblock ~29 ~-3 ~22 wool 8
setblock ~29 ~-3 ~24 wool 15
setblock ~29 ~-3 ~25 wool 0
setblock ~29 ~-3 ~26 wool 8
fill ~29 ~-3 ~27 ~29 ~-3 ~28 wool 7
setblock ~29 ~-3 ~29 wool 0
fill ~30 ~-3 ~6 ~47 ~-3 ~6 grass 0
fill ~30 ~-3 ~14 ~30 ~-3 ~15 iron_block 0
fill ~30 ~-3 ~16 ~31 ~-3 ~16 wool 15
setblock ~30 ~-3 ~17 wool 0
fill ~30 ~-3 ~20 ~31 ~-3 ~20 wool 15
fill ~30 ~-3 ~21 ~30 ~-3 ~20 wool 15
fill ~30 ~-3 ~22 ~31 ~-3 ~22 wool 7
setblock ~30 ~-3 ~23 wool 15
fill ~30 ~-3 ~24 ~30 ~-3 ~25 wool 7
fill ~30 ~-3 ~26 ~30 ~-3 ~27 stone 0
setblock ~30 ~-3 ~28 wool 0
setblock ~30 ~-3 ~29 wool 8
fill ~30 ~-3 ~38 ~47 ~-3 ~38 grass 0
setblock ~31 ~-3 ~13 iron_block 0
fill ~31 ~-3 ~14 ~35 ~-3 ~14 dirt 0
setblock ~31 ~-3 ~15 wool 7
setblock ~31 ~-3 ~17 wool 8
setblock ~31 ~-3 ~18 wool 0
setblock ~31 ~-3 ~19 wool 7
fill ~31 ~-3 ~21 ~32 ~-3 ~21 wool 8
setblock ~31 ~-3 ~23 stone 0
fill ~31 ~-3 ~24 ~32 ~-3 ~24 wool 0
fill ~31 ~-3 ~25 ~32 ~-3 ~25 wool 0
fill ~31 ~-3 ~26 ~32 ~-3 ~26 wool 15
fill ~31 ~-3 ~27 ~31 ~-3 ~28 stone 0
setblock ~31 ~-3 ~29 wool 7
fill ~32 ~-3 ~2 ~47 ~-3 ~2 grass 0
fill ~32 ~-3 ~7 ~47 ~-3 ~7 grass 0
fill ~32 ~-3 ~13 ~34 ~-3 ~13 dirt 0
setblock ~32 ~-3 ~15 stone 0
setblock ~32 ~-3 ~16 wool 8
setblock ~32 ~-3 ~17 wool 7
fill ~32 ~-3 ~18 ~32 ~-3 ~21 wool 8
setblock ~32 ~-3 ~22 stone 0
setblock ~32 ~-3 ~23 wool 7
setblock ~32 ~-3 ~27 wool 15
setblock ~32 ~-3 ~28 wool 8
setblock ~32 ~-3 ~29 wool 15
fill ~32 ~-3 ~31 ~34 ~-3 ~31 dirt 0
fill ~32 ~-3 ~37 ~47 ~-3 ~37 grass 0
fill ~33 ~-3 ~12 ~33 ~-3 ~12 dirt 0
fill ~33 ~-3 ~15 ~34 ~-3 ~15 dirt 0
fill ~33 ~-3 ~16 ~33 ~-3 ~16 dirt 0
fill ~33 ~-3 ~17 ~33 ~-3 ~17 dirt 0
fill ~33 ~-3 ~18 ~33 ~-3 ~18 dirt 0
fill ~33 ~-3 ~19 ~33 ~-3 ~19 dirt 0
fill ~33 ~-3 ~20 ~33 ~-3 ~20 dirt 0
fill ~33 ~-3 ~21 ~33 ~-3 ~21 dirt 0
fill ~33 ~-3 ~22 ~33 ~-3 ~22 dirt 0
fill ~33 ~-3 ~23 ~33 ~-3 ~23 dirt 0
fill ~33 ~-3 ~24 ~33 ~-3 ~24 dirt 0
fill ~33 ~-3 ~25 ~33 ~-3 ~25 dirt 0
fill ~33 ~-3 ~26 ~33 ~-3 ~26 dirt 0
fill ~33 ~-3 ~27 ~33 ~-3 ~27 dirt 0
fill ~33 ~-3 ~28 ~33 ~-3 ~28 dirt 0
fill ~33 ~-3 ~29 ~34 ~-3 ~29 dirt 0
fill ~33 ~-3 ~32 ~33 ~-3 ~32 dirt 0
fill ~34 ~-3 ~8 ~47 ~-3 ~8 grass 0
fill ~34 ~-3 ~12 ~38 ~-3 ~12 iron_block 0
fill ~34 ~-3 ~16 ~40 ~-3 ~16 iron_block 0
fill ~34 ~-3 ~17 ~40 ~-3 ~17 iron_block 0
fill ~34 ~-3 ~18 ~41 ~-3 ~18 iron_block 0
fill ~34 ~-3 ~19 ~41 ~-3 ~19 iron_block 0
fill ~34 ~-3 ~20 ~41 ~-3 ~20 iron_block 0
fill ~34 ~-3 ~21 ~41 ~-3 ~21 iron_block 0
fill ~34 ~-3 ~22 ~41 ~-3 ~22 iron_block 0
fill ~34 ~-3 ~23 ~41 ~-3 ~23 iron_block 0
fill ~34 ~-3 ~24 ~41 ~-3 ~24 iron_block 0
fill ~34 ~-3 ~25 ~41 ~-3 ~25 iron_block 0
fill ~34 ~-3 ~26 ~41 ~-3 ~26 iron_block 0
fill ~34 ~-3 ~27 ~40 ~-3 ~27 iron_block 0
fill ~34 ~-3 ~28 ~40 ~-3 ~28 iron_block 0
fill ~34 ~-3 ~32 ~38 ~-3 ~32 iron_block 0
fill ~34 ~-3 ~36 ~47 ~-3 ~36 grass 0
fill ~35 ~-3 ~13 ~38 ~-3 ~13 iron_block 0
fill ~35 ~-3 ~15 ~39 ~-3 ~15 iron_block 0
fill ~35 ~-3 ~29 ~39 ~-3 ~29 iron_block 0
fill ~35 ~-3 ~31 ~38 ~-3 ~31 iron_block 0
fill ~36 ~-3 ~9 ~47 ~-3 ~9 grass 0
fill ~36 ~-3 ~14 ~39 ~-3 ~14 iron_block 0
fill ~36 ~-3 ~30 ~39 ~-3 ~30 iron_block 0
fill ~36 ~-3 ~35 ~47 ~-3 ~35 grass 0
fill ~37 ~-3 ~10 ~47 ~-3 ~10 grass 0
fill ~37 ~-3 ~34 ~47 ~-3 ~34 grass 0
fill ~38 ~-3 ~11 ~47 ~-3 ~11 grass 0
fill ~38 ~-3 ~33 ~47 ~-3 ~33 grass 0
fill ~39 ~-3 ~12 ~47 ~-3 ~12 grass 0
fill ~39 ~-3 ~13 ~47 ~-3 ~13 grass 0
fill ~39 ~-3 ~31 ~47 ~-3 ~31 grass 0
fill ~39 ~-3 ~32 ~47 ~-3 ~32 grass 0
fill ~40 ~-3 ~14 ~47 ~-3 ~14 grass 0
fill ~40 ~-3 ~15 ~47 ~-3 ~15 grass 0
fill ~40 ~-3 ~29 ~47 ~-3 ~29 grass 0
fill ~40 ~-3 ~30 ~47 ~-3 ~30 grass 0
fill ~41 ~-3 ~16 ~47 ~-3 ~16 grass 0
fill ~41 ~-3 ~17 ~47 ~-3 ~17 grass 0
fill ~41 ~-3 ~27 ~47 ~-3 ~27 grass 0
fill ~41 ~-3 ~28 ~47 ~-3 ~28 grass 0
fill ~42 ~-3 ~18 ~47 ~-3 ~18 grass 0
fill ~42 ~-3 ~19 ~47 ~-3 ~19 grass 0
fill ~42 ~-3 ~20 ~47 ~-3 ~20 grass 0
fill ~42 ~-3 ~21 ~47 ~-3 ~21 grass 0
fill ~42 ~-3 ~22 ~47 ~-3 ~22 grass 0
fill ~42 ~-3 ~23 ~47 ~-3 ~23 grass 0
fill ~42 ~-3 ~24 ~47 ~-3 ~24 grass 0
fill ~42 ~-3 ~25 ~47 ~-3 ~25 grass 0
fill ~42 ~-3 ~26 ~47 ~-3 ~26 grass 0
fill ~10 ~-2 ~16 ~10 ~19 ~16 fence 0
fill ~10 ~-2 ~28 ~10 ~19 ~28 fence 0
fill ~11 ~-2 ~14 ~11 ~19 ~14 fence 0
fill ~11 ~-2 ~30 ~11 ~19 ~30 fence 0
fill ~12 ~-2 ~12 ~12 ~19 ~12 fence 0
fill ~12 ~-2 ~32 ~12 ~19 ~32 fence 0
fill ~15 ~-2 ~9 ~15 ~19 ~9 fence 0
fill ~15 ~-2 ~14 ~16 ~-2 ~14 stone 0
fill ~15 ~-2 ~30 ~16 ~-2 ~30 stone 0
fill ~15 ~-2 ~35 ~15 ~19 ~35 fence 0
fill ~16 ~-2 ~13 ~18 ~-2 ~13 stone 0
fill ~16 ~-2 ~15 ~16 ~2 ~15 stone 0
fill ~16 ~-2 ~29 ~16 ~2 ~29 stone 0
fill ~16 ~-2 ~31 ~18 ~-2 ~31 stone 0
fill ~17 ~-2 ~8 ~17 ~20 ~8 fence 0
fill ~17 ~-2 ~12 ~17 ~-1 ~12 stone 0
fill ~17 ~-2 ~14 ~19 ~-2 ~14 planks 0
fill ~17 ~-2 ~15 ~20 ~-2 ~15 planks 0
fill ~17 ~-2 ~16 ~19 ~-2 ~16 planks 0
fill ~17 ~-2 ~28 ~19 ~-2 ~28 planks 0
fill ~17 ~-2 ~29 ~33 ~-2 ~29 planks 0
fill ~17 ~-2 ~30 ~19 ~-2 ~30 planks 0
fill ~17 ~-2 ~32 ~17 ~-1 ~32 stone 0
fill ~17 ~-2 ~36 ~17 ~19 ~36 fence 0
fill ~18 ~-2 ~17 ~18 ~21 ~17 planks 0
fill ~18 ~-2 ~18 ~18 ~21 ~18 planks 0
fill ~18 ~-2 ~19 ~18 ~21 ~19 planks 0
fill ~18 ~-2 ~20 ~18 ~21 ~20 planks 0
fill ~18 ~-2 ~21 ~18 ~21 ~21 planks 0
fill ~18 ~-2 ~22 ~18 ~21 ~22 planks 0
fill ~18 ~-2 ~23 ~18 ~21 ~23 planks 0
fill ~18 ~-2 ~24 ~18 ~21 ~24 planks 0
fill ~18 ~-2 ~25 ~18 ~21 ~25 planks 0
fill ~18 ~-2 ~26 ~18 ~21 ~26 planks 0
fill ~18 ~-2 ~27 ~18 ~21 ~27 planks 0
fill ~19 ~-2 ~7 ~19 ~19 ~7 fence 0
fill ~19 ~-2 ~37 ~19 ~19 ~37 fence 0
fill ~20 ~-2 ~13 ~21 ~-2 ~13 planks 0
fill ~21 ~-2 ~14 ~21 ~22 ~14 planks 0
fill ~24 ~-2 ~26 ~26 ~-2 ~26 iron_block 0
fill ~24 ~-2 ~27 ~26 ~-2 ~27 iron_block 0
fill ~24 ~-2 ~28 ~26 ~-2 ~28 iron_block 0
fill ~29 ~-2 ~13 ~30 ~-2 ~13 planks 0
fill ~29 ~-2 ~14 ~33 ~-2 ~14 planks 0
fill ~30 ~-2 ~15 ~33 ~-2 ~15 planks 0
fill ~31 ~-2 ~7 ~31 ~19 ~7 fence 0
fill ~31 ~-2 ~16 ~33 ~-2 ~16 planks 0
fill ~31 ~-2 ~28 ~33 ~-2 ~28 planks 0
fill ~31 ~-2 ~30 ~33 ~-2 ~30 planks 0
fill ~31 ~-2 ~37 ~31 ~19 ~37 fence 0
fill ~32 ~-2 ~13 ~34 ~-2 ~13 stone 0
fill ~32 ~-2 ~17 ~32 ~21 ~17 planks 0
fill ~32 ~-2 ~18 ~32 ~21 ~18 planks 0
fill ~32 ~-2 ~19 ~32 ~21 ~19 planks 0
fill ~32 ~-2 ~20 ~32 ~21 ~20 planks 0
fill ~32 ~-2 ~21 ~32 ~21 ~21 planks 0
fill ~32 ~-2 ~22 ~32 ~21 ~22 planks 0
fill ~32 ~-2 ~23 ~32 ~21 ~23 planks 0
fill ~32 ~-2 ~24 ~32 ~21 ~24 planks 0
fill ~32 ~-2 ~25 ~32 ~21 ~25 planks 0
fill ~32 ~-2 ~26 ~32 ~21 ~26 planks 0
fill ~32 ~-2 ~27 ~32 ~21 ~27 planks 0
fill ~32 ~-2 ~31 ~34 ~-2 ~31 stone 0
fill ~33 ~-2 ~8 ~33 ~19 ~8 fence 0
fill ~33 ~-2 ~12 ~33 ~-1 ~12 stone 0
fill ~33 ~-2 ~32 ~33 ~-1 ~32 stone 0
fill ~33 ~-2 ~36 ~33 ~19 ~36 fence 0
fill ~34 ~-2 ~14 ~35 ~-2 ~14 stone 0
fill ~34 ~-2 ~15 ~34 ~2 ~15 stone 0
fill ~34 ~-2 ~29 ~34 ~2 ~29 stone 0
fill ~34 ~-2 ~30 ~35 ~-2 ~30 stone 0
fill ~35 ~-2 ~9 ~35 ~19 ~9 fence 0
fill ~35 ~-2 ~35 ~35 ~19 ~35 fence 0
fill ~38 ~-2 ~12 ~38 ~19 ~12 fence 0
fill ~38 ~-2 ~32 ~38 ~19 ~32 fence 0
fill ~39 ~-2 ~14 ~39 ~19 ~14 fence 0
fill ~39 ~-2 ~30 ~39 ~19 ~30 fence 0
fill ~40 ~-2 ~16 ~40 ~19 ~16 fence 0
fill ~40 ~-2 ~28 ~40 ~19 ~28 fence 0
fill ~15 ~-1 ~14 ~16 ~-1 ~14 stone 0
fill ~15 ~-1 ~30 ~16 ~-1 ~30 stone 0
fill ~16 ~-1 ~13 ~18 ~-1 ~13 stone 0
fill ~16 ~-1 ~31 ~18 ~-1 ~31 stone 0
fill ~17 ~-1 ~14 ~19 ~-1 ~14 planks 0
fill ~17 ~-1 ~15 ~20 ~-1 ~15 planks 0
fill ~17 ~-1 ~16 ~19 ~-1 ~16 planks 0
fill ~17 ~-1 ~28 ~19 ~-1 ~28 planks 0
fill ~17 ~-1 ~29 ~33 ~-1 ~29 planks 0
fill ~17 ~-1 ~30 ~19 ~-1 ~30 planks 0
setblock ~19 ~-1 ~17 torch 3
setblock ~19 ~-1 ~27 torch 4
fill ~20 ~-1 ~13 ~21 ~-1 ~13 planks 0
fill ~22 ~-1 ~26 ~24 ~-1 ~26 gold_block 0
fill ~22 ~-1 ~27 ~24 ~-1 ~27 gold_block 0
fill ~22 ~-1 ~28 ~24 ~-1 ~28 gold_block 0
fill ~25 ~-1 ~27 ~25 ~20 ~27 fence 0
fill ~29 ~-1 ~13 ~30 ~-1 ~13 planks 0
fill ~29 ~-1 ~14 ~33 ~-1 ~14 planks 0
fill ~30 ~-1 ~15 ~33 ~-1 ~15 planks 0
fill ~31 ~-1 ~16 ~33 ~-1 ~16 planks 0
setblock ~31 ~-1 ~17 torch 3
setblock ~31 ~-1 ~27 torch 4
fill ~31 ~-1 ~28 ~33 ~-1 ~28 planks 0
fill ~31 ~-1 ~30 ~33 ~-1 ~30 planks 0
setblock ~32 ~-1 ~8 gold_block 0
fill ~32 ~-1 ~13 ~34 ~-1 ~13 stone 0
fill ~32 ~-1 ~31 ~34 ~-1 ~31 stone 0
setblock ~32 ~-1 ~36 gold_block 0
setblock ~33 ~-1 ~7 gold_block 0
setblock ~33 ~-1 ~9 gold_block 0
setblock ~33 ~-1 ~35 gold_block 0
setblock ~33 ~-1 ~37 gold_block 0
setblock ~34 ~-1 ~8 gold_block 0
fill ~34 ~-1 ~14 ~35 ~-1 ~14 stone 0
fill ~34 ~-1 ~30 ~35 ~-1 ~30 stone 0
setblock ~34 ~-1 ~36 gold_block 0
fill ~16 ~0 ~13 ~16 ~2 ~13 stone 0
fill ~16 ~0 ~31 ~16 ~2 ~31 stone 0
fill ~17 ~0 ~14 ~19 ~0 ~14 planks 0
fill ~17 ~0 ~15 ~20 ~0 ~15 planks 0
fill ~17 ~0 ~16 ~19 ~0 ~16 planks 0
fill ~17 ~0 ~28 ~19 ~0 ~28 planks 0
fill ~17 ~0 ~29 ~33 ~0 ~29 planks 0
fill ~17 ~0 ~30 ~19 ~0 ~30 planks 0
fill ~18 ~0 ~13 ~18 ~2 ~13 stone 0
fill ~18 ~0 ~31 ~18 ~2 ~31 stone 0
setblock ~18 ~0 ~37 iron_block 0
setblock ~19 ~0 ~36 iron_block 0
setblock ~19 ~0 ~38 iron_block 0
fill ~20 ~0 ~13 ~21 ~0 ~13 planks 0
fill ~20 ~0 ~25 ~22 ~0 ~25 iron_block 0
fill ~20 ~0 ~26 ~22 ~0 ~26 iron_block 0
fill ~20 ~0 ~27 ~22 ~0 ~27 iron_block 0
setblock ~20 ~0 ~37 iron_block 0
fill ~23 ~0 ~27 ~23 ~20 ~27 fence 0
fill ~29 ~0 ~13 ~30 ~0 ~13 planks 0
fill ~29 ~0 ~14 ~33 ~0 ~14 planks 0
fill ~30 ~0 ~15 ~33 ~0 ~15 planks 0
fill ~31 ~0 ~16 ~33 ~0 ~16 planks 0
fill ~31 ~0 ~28 ~33 ~0 ~28 planks 0
fill ~31 ~0 ~30 ~33 ~0 ~30 planks 0
fill ~32 ~0 ~13 ~32 ~2 ~13 stone 0
fill ~32 ~0 ~31 ~32 ~2 ~31 stone 0
fill ~34 ~0 ~13 ~34 ~2 ~13 stone 0
fill ~34 ~0 ~31 ~34 ~2 ~31 stone 0
setblock ~37 ~0 ~12 iron_block 0
setblock ~38 ~0 ~11 iron_block 0
setblock ~38 ~0 ~13 iron_block 0
setblock ~38 ~0 ~30 iron_block 0
setblock ~39 ~0 ~12 iron_block 0
setblock ~39 ~0 ~29 iron_block 0
setblock ~39 ~0 ~31 iron_block 0
setblock ~40 ~0 ~30 iron_block 0
setblock ~10 ~1 ~14 iron_block 0
setblock ~11 ~1 ~13 iron_block 0
setblock ~11 ~1 ~15 iron_block 0
setblock ~12 ~1 ~14 iron_block 0
fill ~15 ~1 ~14 ~17 ~1 ~14 stone 0
fill ~15 ~1 ~30 ~17 ~1 ~30 stone 0
setblock ~16 ~1 ~8 iron_block 0
setblock ~17 ~1 ~7 iron_block 0
setblock ~17 ~1 ~9 iron_block 0
fill ~17 ~1 ~12 ~17 ~5 ~12 stone 0
fill ~17 ~1 ~13 ~17 ~2 ~13 stone 0
fill ~17 ~1 ~15 ~20 ~1 ~15 planks 0
fill ~17 ~1 ~16 ~19 ~1 ~16 planks 0
fill ~17 ~1 ~28 ~19 ~1 ~28 planks 0
fill ~17 ~1 ~29 ~33 ~1 ~29 planks 0
fill ~17 ~1 ~31 ~17 ~2 ~31 stone 0
fill ~17 ~1 ~32 ~17 ~5 ~32 stone 0
setblock ~18 ~1 ~8 iron_block 0
fill ~18 ~1 ~14 ~19 ~1 ~14 planks 0
fill ~18 ~1 ~30 ~19 ~1 ~30 planks 0
fill ~19 ~1 ~23 ~21 ~1 ~23 gold_block 0
fill ~19 ~1 ~24 ~21 ~1 ~24 gold_block 0
fill ~19 ~1 ~25 ~21 ~1 ~25 gold_block 0
fill ~20 ~1 ~13 ~21 ~1 ~13 planks 0
fill ~21 ~1 ~26 ~21 ~20 ~26 fence 0
fill ~29 ~1 ~13 ~30 ~1 ~13 planks 0
fill ~29 ~1 ~14 ~32 ~1 ~14 planks 0
fill ~30 ~1 ~15 ~33 ~1 ~15 planks 0
fill ~31 ~1 ~16 ~33 ~1 ~16 planks 0
fill ~31 ~1 ~28 ~33 ~1 ~28 planks 0
fill ~31 ~1 ~30 ~32 ~1 ~30 planks 0
fill ~33 ~1 ~12 ~33 ~5 ~12 stone 0
fill ~33 ~1 ~13 ~33 ~2 ~13 stone 0
fill ~33 ~1 ~14 ~35 ~1 ~14 stone 0
fill ~33 ~1 ~30 ~35 ~1 ~30 stone 0
fill ~33 ~1 ~31 ~33 ~2 ~31 stone 0
fill ~33 ~1 ~32 ~33 ~5 ~32 stone 0
setblock ~10 ~2 ~30 iron_block 0
setblock ~11 ~2 ~29 iron_block 0
setblock ~11 ~2 ~31 iron_block 0
setblock ~12 ~2 ~30 iron_block 0
setblock ~14 ~2 ~35 gold_block 0
fill ~15 ~2 ~14 ~17 ~2 ~14 stone 0
fill ~15 ~2 ~30 ~17 ~2 ~30 stone 0
setblock ~15 ~2 ~34 gold_block 0
setblock ~15 ~2 ~36 gold_block 0
setblock ~16 ~2 ~35 gold_block 0
fill ~17 ~2 ~15 ~20 ~2 ~15 planks 0
fill ~17 ~2 ~16 ~19 ~2 ~16 planks 0
fill ~17 ~2 ~28 ~19 ~2 ~28 planks 0
fill ~17 ~2 ~29 ~33 ~2 ~29 planks 0
fill ~18 ~2 ~14 ~19 ~2 ~14 planks 0
fill ~18 ~2 ~30 ~19 ~2 ~30 planks 0
fill ~19 ~2 ~21 ~21 ~2 ~21 iron_block 0
fill ~19 ~2 ~22 ~21 ~2 ~22 iron_block 0
fill ~19 ~2 ~23 ~21 ~2 ~23 iron_block 0
fill ~20 ~2 ~13 ~21 ~2 ~13 planks 0
fill ~20 ~2 ~24 ~20 ~20 ~24 fence 0
fill ~29 ~2 ~13 ~30 ~2 ~13 planks 0
fill ~29 ~2 ~14 ~32 ~2 ~14 planks 0
fill ~30 ~2 ~15 ~33 ~2 ~15 planks 0
fill ~31 ~2 ~16 ~33 ~2 ~16 planks 0
fill ~31 ~2 ~28 ~33 ~2 ~28 planks 0
fill ~31 ~2 ~30 ~32 ~2 ~30 planks 0
fill ~33 ~2 ~14 ~35 ~2 ~14 stone 0
fill ~33 ~2 ~30 ~35 ~2 ~30 stone 0
setblock ~11 ~3 ~12 gold_block 0
setblock ~12 ~3 ~11 gold_block 0
setblock ~12 ~3 ~13 gold_block 0
setblock ~13 ~3 ~12 gold_block 0
fill ~15 ~3 ~14 ~15 ~5 ~14 stone 0
fill ~15 ~3 ~30 ~15 ~5 ~30 stone 0
setblock ~17 ~3 ~14 stone 0
fill ~17 ~3 ~15 ~20 ~3 ~15 planks 0
fill ~17 ~3 ~16 ~19 ~3 ~16 planks 0
fill ~17 ~3 ~28 ~19 ~3 ~28 planks 0
fill ~17 ~3 ~29 ~33 ~3 ~29 planks 0
setblock ~17 ~3 ~30 stone 0
fill ~18 ~3 ~14 ~19 ~3 ~14 planks 0
fill ~18 ~3 ~30 ~19 ~3 ~30 planks 0
fill ~19 ~3 ~19 ~21 ~3 ~19 gold_block 0
fill ~19 ~3 ~20 ~21 ~3 ~20 gold_block 0
fill ~19 ~3 ~21 ~21 ~3 ~21 gold_block 0
fill ~20 ~3 ~13 ~21 ~3 ~13 planks 0
fill ~20 ~3 ~22 ~20 ~20 ~22 fence 0
fill ~29 ~3 ~13 ~30 ~3 ~13 planks 0
fill ~29 ~3 ~14 ~32 ~3 ~14 planks 0
fill ~30 ~3 ~15 ~33 ~3 ~15 planks 0
fill ~31 ~3 ~16 ~33 ~3 ~16 planks 0
fill ~31 ~3 ~28 ~33 ~3 ~28 planks 0
fill ~31 ~3 ~30 ~32 ~3 ~30 planks 0
fill ~33 ~3 ~14 ~33 ~1 ~14 stone 0
fill ~33 ~3 ~30 ~33 ~1 ~30 stone 0
setblock ~34 ~3 ~9 gold_block 0
setblock ~34 ~3 ~35 iron_block 0
setblock ~35 ~3 ~8 gold_block 0
setblock ~35 ~3 ~10 gold_block 0
fill ~35 ~3 ~14 ~35 ~5 ~14 stone 0
fill ~35 ~3 ~30 ~35 ~5 ~30 stone 0
setblock ~35 ~3 ~34 iron_block 0
setblock ~35 ~3 ~36 iron_block 0
setblock ~36 ~3 ~9 gold_block 0
setblock ~36 ~3 ~35 iron_block 0
setblock ~38 ~3 ~14 gold_block 0
setblock ~39 ~3 ~13 gold_block 0
setblock ~39 ~3 ~15 gold_block 0
setblock ~40 ~3 ~14 gold_block 0
fill ~16 ~4 ~13 ~18 ~4 ~13 stone 0
fill ~16 ~4 ~14 ~16 ~5 ~14 stone 0
fill ~16 ~4 ~15 ~16 ~8 ~15 stone 0
fill ~16 ~4 ~29 ~16 ~8 ~29 stone 0
fill ~16 ~4 ~30 ~16 ~5 ~30 stone 0
fill ~16 ~4 ~31 ~18 ~4 ~31 stone 0
setblock ~16 ~4 ~36 iron_block 0
fill ~17 ~4 ~14 ~19 ~4 ~14 planks 0
fill ~17 ~4 ~15 ~20 ~4 ~15 planks 0
fill ~17 ~4 ~16 ~19 ~4 ~16 planks 0
fill ~17 ~4 ~28 ~19 ~4 ~28 planks 0
fill ~17 ~4 ~29 ~33 ~4 ~29 planks 0
fill ~17 ~4 ~30 ~19 ~4 ~30 planks 0
setblock ~17 ~4 ~35 iron_block 0
setblock ~17 ~4 ~37 iron_block 0
setblock ~18 ~4 ~36 iron_block 0
setblock ~19 ~4 ~27 torch 4
fill ~20 ~4 ~13 ~21 ~4 ~13 planks 0
fill ~20 ~4 ~17 ~22 ~4 ~17 iron_block 0
fill ~20 ~4 ~18 ~22 ~4 ~18 iron_block 0
fill ~20 ~4 ~19 ~22 ~4 ~19 iron_block 0
fill ~20 ~4 ~20 ~20 ~20 ~20 fence 0
fill ~29 ~4 ~13 ~30 ~4 ~13 planks 0
fill ~29 ~4 ~14 ~33 ~4 ~14 planks 0
fill ~30 ~4 ~15 ~33 ~4 ~15 planks 0
fill ~31 ~4 ~16 ~33 ~4 ~16 planks 0
setblock ~31 ~4 ~17 torch 3
setblock ~31 ~4 ~27 torch 4
fill ~31 ~4 ~28 ~33 ~4 ~28 planks 0
fill ~31 ~4 ~30 ~33 ~4 ~30 planks 0
fill ~32 ~4 ~13 ~34 ~4 ~13 stone 0
fill ~32 ~4 ~31 ~34 ~4 ~31 stone 0
fill ~34 ~4 ~14 ~34 ~5 ~14 stone 0
fill ~34 ~4 ~15 ~34 ~8 ~15 stone 0
fill ~34 ~4 ~29 ~34 ~8 ~29 stone 0
fill ~34 ~4 ~30 ~34 ~5 ~30 stone 0
setblock ~37 ~4 ~32 gold_block 0
setblock ~38 ~4 ~31 gold_block 0
setblock ~38 ~4 ~33 gold_block 0
setblock ~39 ~4 ~32 gold_block 0
fill ~16 ~5 ~13 ~18 ~5 ~13 stone 0
fill ~16 ~5 ~31 ~18 ~5 ~31 stone 0
fill ~17 ~5 ~14 ~19 ~5 ~14 planks 0
fill ~17 ~5 ~15 ~20 ~5 ~15 planks 0
fill ~17 ~5 ~16 ~19 ~5 ~16 planks 0
fill ~17 ~5 ~28 ~19 ~5 ~28 planks 0
fill ~17 ~5 ~29 ~33 ~5 ~29 planks 0
fill ~17 ~5 ~30 ~19 ~5 ~30 planks 0
fill ~20 ~5 ~13 ~21 ~5 ~13 planks 0
fill ~21 ~5 ~18 ~21 ~20 ~18 fence 0
fill ~22 ~5 ~16 ~24 ~5 ~16 gold_block 0
fill ~22 ~5 ~17 ~24 ~5 ~17 gold_block 0
fill ~22 ~5 ~18 ~24 ~5 ~18 gold_block 0
fill ~29 ~5 ~13 ~30 ~5 ~13 planks 0
fill ~29 ~5 ~14 ~33 ~5 ~14 planks 0
fill ~30 ~5 ~15 ~33 ~5 ~15 planks 0
fill ~31 ~5 ~16 ~33 ~5 ~16 planks 0
fill ~31 ~5 ~28 ~33 ~5 ~28 planks 0
fill ~31 ~5 ~30 ~33 ~5 ~30 planks 0
fill ~32 ~5 ~13 ~34 ~5 ~13 stone 0
fill ~32 ~5 ~31 ~34 ~5 ~31 stone 0
setblock ~9 ~6 ~16 gold_block 0
setblock ~10 ~6 ~15 gold_block 0
setblock ~10 ~6 ~17 gold_block 0
setblock ~11 ~6 ~16 gold_block 0
setblock ~14 ~6 ~9 iron_block 0
setblock ~15 ~6 ~8 iron_block 0
setblock ~15 ~6 ~10 iron_block 0
setblock ~16 ~6 ~9 iron_block 0
fill ~16 ~6 ~13 ~16 ~8 ~13 stone 0
fill ~16 ~6 ~31 ~16 ~8 ~31 stone 0
fill ~17 ~6 ~14 ~19 ~6 ~14 planks 0
fill ~17 ~6 ~15 ~20 ~6 ~15 planks 0
fill ~17 ~6 ~16 ~19 ~6 ~16 planks 0
fill ~17 ~6 ~28 ~19 ~6 ~28 planks 0
fill ~17 ~6 ~29 ~33 ~6 ~29 planks 0
fill ~17 ~6 ~30 ~19 ~6 ~30 planks 0
fill ~18 ~6 ~13 ~18 ~8 ~13 stone 0
fill ~18 ~6 ~31 ~18 ~8 ~31 stone 0
fill ~20 ~6 ~13 ~21 ~6 ~13 planks 0
fill ~23 ~6 ~17 ~23 ~20 ~17 fence 0
fill ~24 ~6 ~16 ~26 ~6 ~16 iron_block 0
fill ~24 ~6 ~17 ~26 ~6 ~17 iron_block 0
fill ~24 ~6 ~18 ~26 ~6 ~18 iron_block 0
fill ~29 ~6 ~13 ~30 ~6 ~13 planks 0
fill ~29 ~6 ~14 ~33 ~6 ~14 planks 0
setblock ~30 ~6 ~7 iron_block 0
fill ~30 ~6 ~15 ~33 ~6 ~15 planks 0
setblock ~31 ~6 ~6 iron_block 0
setblock ~31 ~6 ~8 iron_block 0
fill ~31 ~6 ~16 ~33 ~6 ~16 planks 0
fill ~31 ~6 ~28 ~33 ~6 ~28 planks 0
fill ~31 ~6 ~30 ~33 ~6 ~30 planks 0
setblock ~32 ~6 ~7 iron_block 0
fill ~32 ~6 ~13 ~32 ~8 ~13 stone 0
fill ~32 ~6 ~31 ~32 ~8 ~31 stone 0
fill ~34 ~6 ~13 ~34 ~8 ~13 stone 0
fill ~34 ~6 ~31 ~34 ~8 ~31 stone 0
setblock ~10 ~7 ~30 gold_block 0
setblock ~11 ~7 ~29 gold_block 0
setblock ~11 ~7 ~31 gold_block 0
setblock ~12 ~7 ~30 gold_block 0
fill ~15 ~7 ~14 ~17 ~7 ~14 stone 0
fill ~15 ~7 ~30 ~17 ~7 ~30 stone 0
fill ~17 ~7 ~12 ~17 ~11 ~12 stone 0
fill ~17 ~7 ~13 ~17 ~8 ~13 stone 0
fill ~17 ~7 ~15 ~20 ~7 ~15 planks 0
fill ~17 ~7 ~16 ~19 ~7 ~16 planks 0
fill ~17 ~7 ~28 ~19 ~7 ~28 planks 0
fill ~17 ~7 ~29 ~33 ~7 ~29 planks 0
fill ~17 ~7 ~31 ~17 ~8 ~31 stone 0
fill ~17 ~7 ~32 ~17 ~11 ~32 stone 0
setblock ~18 ~7 ~7 gold_block 0
fill ~18 ~7 ~14 ~19 ~7 ~14 planks 0
fill ~18 ~7 ~30 ~19 ~7 ~30 planks 0
setblock ~19 ~7 ~6 gold_block 0
setblock ~19 ~7 ~8 gold_block 0
setblock ~20 ~7 ~7 gold_block 0
fill ~20 ~7 ~13 ~21 ~7 ~13 planks 0
fill ~25 ~7 ~17 ~25 ~20 ~17 fence 0
fill ~26 ~7 ~16 ~28 ~7 ~16 gold_block 0
fill ~26 ~7 ~17 ~28 ~7 ~17 gold_block 0
fill ~26 ~7 ~18 ~28 ~7 ~18 gold_block 0
fill ~29 ~7 ~13 ~30 ~7 ~13 planks 0
fill ~29 ~7 ~14 ~32 ~7 ~14 planks 0
fill ~30 ~7 ~15 ~33 ~7 ~15 planks 0
setblock ~30 ~7 ~37 gold_block 0
fill ~31 ~7 ~16 ~33 ~7 ~16 planks 0
fill ~31 ~7 ~28 ~33 ~7 ~28 planks 0
fill ~31 ~7 ~30 ~32 ~7 ~30 planks 0
setblock ~31 ~7 ~36 gold_block 0
setblock ~31 ~7 ~38 gold_block 0
setblock ~32 ~7 ~37 gold_block 0
fill ~33 ~7 ~12 ~33 ~11 ~12 stone 0
fill ~33 ~7 ~13 ~33 ~8 ~13 stone 0
fill ~33 ~7 ~14 ~35 ~7 ~14 stone 0
fill ~33 ~7 ~30 ~35 ~7 ~30 stone 0
fill ~33 ~7 ~31 ~33 ~8 ~31 stone 0
fill ~33 ~7 ~32 ~33 ~11 ~32 stone 0
setblock ~38 ~7 ~14 iron_block 0
setblock ~39 ~7 ~13 iron_block 0
setblock ~39 ~7 ~15 iron_block 0
setblock ~39 ~7 ~28 iron_block 0
setblock ~40 ~7 ~14 iron_block 0
setblock ~40 ~7 ~27 iron_block 0
setblock ~40 ~7 ~29 iron_block 0
setblock ~41 ~7 ~28 iron_block 0
fill ~15 ~8 ~14 ~17 ~8 ~14 stone 0
fill ~15 ~8 ~30 ~17 ~8 ~30 stone 0
fill ~17 ~8 ~15 ~20 ~8 ~15 planks 0
fill ~17 ~8 ~16 ~19 ~8 ~16 planks 0
fill ~17 ~8 ~28 ~19 ~8 ~28 planks 0
fill ~17 ~8 ~29 ~33 ~8 ~29 planks 0
fill ~18 ~8 ~14 ~19 ~8 ~14 planks 0
fill ~18 ~8 ~30 ~19 ~8 ~30 planks 0
fill ~20 ~8 ~13 ~22 ~8 ~13 planks 0
fill ~22 ~8 ~14 ~22 ~12 ~14 planks 0
fill ~27 ~8 ~17 ~27 ~20 ~17 fence 0
fill ~28 ~8 ~13 ~30 ~8 ~13 planks 0
fill ~28 ~8 ~14 ~32 ~8 ~14 planks 0
fill ~28 ~8 ~17 ~30 ~8 ~17 iron_block 0
fill ~28 ~8 ~18 ~30 ~8 ~18 iron_block 0
fill ~28 ~8 ~19 ~30 ~8 ~19 iron_block 0
fill ~30 ~8 ~15 ~33 ~8 ~15 planks 0
fill ~31 ~8 ~16 ~33 ~8 ~16 planks 0
fill ~31 ~8 ~28 ~33 ~8 ~28 planks 0
fill ~31 ~8 ~30 ~32 ~8 ~30 planks 0
fill ~33 ~8 ~14 ~35 ~8 ~14 stone 0
fill ~33 ~8 ~30 ~35 ~8 ~30 stone 0
setblock ~11 ~9 ~12 iron_block 0
setblock ~11 ~9 ~32 iron_block 0
setblock ~12 ~9 ~11 iron_block 0
setblock ~12 ~9 ~13 iron_block 0
setblock ~12 ~9 ~31 iron_block 0
setblock ~12 ~9 ~33 iron_block 0
setblock ~13 ~9 ~12 iron_block 0
setblock ~13 ~9 ~32 iron_block 0
fill ~15 ~9 ~14 ~15 ~11 ~14 stone 0
fill ~15 ~9 ~30 ~15 ~11 ~30 stone 0
setblock ~16 ~9 ~36 gold_block 0
setblock ~17 ~9 ~14 stone 0
fill ~17 ~9 ~15 ~20 ~9 ~15 planks 0
fill ~17 ~9 ~16 ~19 ~9 ~16 planks 0
fill ~17 ~9 ~28 ~19 ~9 ~28 planks 0
fill ~17 ~9 ~29 ~33 ~9 ~29 planks 0
setblock ~17 ~9 ~30 stone 0
setblock ~17 ~9 ~35 gold_block 0
setblock ~17 ~9 ~37 gold_block 0
fill ~18 ~9 ~14 ~19 ~9 ~14 planks 0
fill ~18 ~9 ~30 ~19 ~9 ~30 planks 0
setblock ~18 ~9 ~36 gold_block 0
fill ~20 ~9 ~13 ~30 ~9 ~13 planks 0
fill ~23 ~9 ~14 ~32 ~9 ~14 planks 0
fill ~29 ~9 ~18 ~29 ~20 ~18 fence 0
fill ~29 ~9 ~19 ~31 ~9 ~19 gold_block 0
fill ~29 ~9 ~20 ~31 ~9 ~20 gold_block 0
fill ~29 ~9 ~21 ~31 ~9 ~21 gold_block 0
fill ~30 ~9 ~15 ~33 ~9 ~15 planks 0
fill ~31 ~9 ~16 ~33 ~9 ~16 planks 0
fill ~31 ~9 ~28 ~33 ~9 ~28 planks 0
fill ~31 ~9 ~30 ~32 ~9 ~30 planks 0
setblock ~32 ~9 ~36 iron_block 0
fill ~33 ~9 ~14 ~33 ~7 ~14 stone 0
fill ~33 ~9 ~30 ~33 ~7 ~30 stone 0
setblock ~33 ~9 ~35 iron_block 0
setblock ~33 ~9 ~37 iron_block 0
setblock ~34 ~9 ~36 iron_block 0
fill ~35 ~9 ~14 ~35 ~11 ~14 stone 0
fill ~35 ~9 ~30 ~35 ~11 ~30 stone 0
fill ~16 ~10 ~13 ~18 ~10 ~13 stone 0
fill ~16 ~10 ~14 ~16 ~11 ~14 stone 0
fill ~16 ~10 ~15 ~16 ~14 ~15 stone 0
fill ~16 ~10 ~29 ~16 ~14 ~29 stone 0
fill ~16 ~10 ~30 ~16 ~11 ~30 stone 0
fill ~16 ~10 ~31 ~18 ~10 ~31 stone 0
fill ~17 ~10 ~14 ~19 ~10 ~14 planks 0
fill ~17 ~10 ~15 ~20 ~10 ~15 planks 0
fill ~17 ~10 ~16 ~19 ~10 ~16 planks 0
fill ~17 ~10 ~28 ~19 ~10 ~28 planks 0
fill ~17 ~10 ~29 ~33 ~10 ~29 planks 0
fill ~17 ~10 ~30 ~19 ~10 ~30 planks 0
setblock ~19 ~10 ~17 torch 3
setblock ~19 ~10 ~27 torch 4
fill ~20 ~10 ~13 ~20 ~17 ~13 planks 0
fill ~22 ~10 ~13 ~28 ~10 ~13 planks 0
fill ~23 ~10 ~14 ~33 ~10 ~14 planks 0
fill ~29 ~10 ~21 ~31 ~10 ~21 iron_block 0
fill ~29 ~10 ~22 ~31 ~10 ~22 iron_block 0
fill ~29 ~10 ~23 ~31 ~10 ~23 iron_block 0
fill ~30 ~10 ~13 ~30 ~17 ~13 planks 0
fill ~30 ~10 ~15 ~33 ~10 ~15 planks 0
fill ~30 ~10 ~20 ~30 ~20 ~20 fence 0
fill ~31 ~10 ~16 ~33 ~10 ~16 planks 0
setblock ~31 ~10 ~17 torch 3
setblock ~31 ~10 ~27 torch 4
fill ~31 ~10 ~28 ~33 ~10 ~28 planks 0
fill ~31 ~10 ~30 ~33 ~10 ~30 planks 0
fill ~32 ~10 ~13 ~34 ~10 ~13 stone 0
fill ~32 ~10 ~31 ~34 ~10 ~31 stone 0
setblock ~34 ~10 ~9 iron_block 0
fill ~34 ~10 ~14 ~34 ~11 ~14 stone 0
fill ~34 ~10 ~15 ~34 ~14 ~15 stone 0
fill ~34 ~10 ~29 ~34 ~14 ~29 stone 0
fill ~34 ~10 ~30 ~34 ~11 ~30 stone 0
setblock ~35 ~10 ~8 iron_block 0
setblock ~35 ~10 ~10 iron_block 0
setblock ~36 ~10 ~9 iron_block 0
setblock ~38 ~10 ~30 gold_block 0
setblock ~39 ~10 ~16 gold_block 0
setblock ~39 ~10 ~29 gold_block 0
setblock ~39 ~10 ~31 gold_block 0
setblock ~40 ~10 ~15 gold_block 0
setblock ~40 ~10 ~17 gold_block 0
setblock ~40 ~10 ~30 gold_block 0
setblock ~41 ~10 ~16 gold_block 0
setblock ~9 ~11 ~28 gold_block 0
setblock ~10 ~11 ~27 gold_block 0
setblock ~10 ~11 ~29 gold_block 0
setblock ~11 ~11 ~28 gold_block 0
fill ~16 ~11 ~13 ~18 ~11 ~13 stone 0
fill ~16 ~11 ~31 ~18 ~11 ~31 stone 0
fill ~17 ~11 ~14 ~19 ~11 ~14 planks 0
fill ~17 ~11 ~15 ~20 ~11 ~15 planks 0
fill ~17 ~11 ~16 ~19 ~11 ~16 planks 0
fill ~17 ~11 ~28 ~19 ~11 ~28 planks 0
fill ~17 ~11 ~29 ~33 ~11 ~29 planks 0
fill ~17 ~11 ~30 ~19 ~11 ~30 planks 0
fill ~23 ~11 ~14 ~33 ~11 ~14 planks 0
fill ~29 ~11 ~23 ~31 ~11 ~23 gold_block 0
fill ~29 ~11 ~24 ~31 ~11 ~24 gold_block 0
fill ~29 ~11 ~25 ~31 ~11 ~25 gold_block 0
fill ~30 ~11 ~15 ~33 ~11 ~15 planks 0
fill ~30 ~11 ~22 ~30 ~20 ~22 fence 0
fill ~31 ~11 ~16 ~33 ~11 ~16 planks 0
fill ~31 ~11 ~28 ~33 ~11 ~28 planks 0
fill ~31 ~11 ~30 ~33 ~11 ~30 planks 0
fill ~32 ~11 ~13 ~34 ~11 ~13 stone 0
fill ~32 ~11 ~31 ~34 ~11 ~31 stone 0
fill ~16 ~12 ~13 ~16 ~14 ~13 stone 0
fill ~16 ~12 ~31 ~16 ~14 ~31 stone 0
fill ~17 ~12 ~14 ~19 ~12 ~14 planks 0
fill ~17 ~12 ~15 ~20 ~12 ~15 planks 0
fill ~17 ~12 ~16 ~19 ~12 ~16 planks 0
fill ~17 ~12 ~28 ~19 ~12 ~28 planks 0
fill ~17 ~12 ~29 ~33 ~12 ~29 planks 0
fill ~17 ~12 ~30 ~19 ~12 ~30 planks 0
fill ~18 ~12 ~13 ~18 ~14 ~13 stone 0
fill ~18 ~12 ~31 ~18 ~14 ~31 stone 0
fill ~23 ~12 ~14 ~33 ~12 ~14 planks 0
fill ~28 ~12 ~25 ~30 ~12 ~25 iron_block 0
fill ~28 ~12 ~26 ~30 ~12 ~26 iron_block 0
fill ~28 ~12 ~27 ~30 ~12 ~27 iron_block 0
fill ~30 ~12 ~15 ~33 ~12 ~15 planks 0
fill ~30 ~12 ~24 ~30 ~20 ~24 fence 0
fill ~31 ~12 ~16 ~33 ~12 ~16 planks 0
fill ~31 ~12 ~28 ~33 ~12 ~28 planks 0
fill ~31 ~12 ~30 ~33 ~12 ~30 planks 0
fill ~32 ~12 ~13 ~32 ~14 ~13 stone 0
fill ~32 ~12 ~31 ~32 ~14 ~31 stone 0
fill ~34 ~12 ~13 ~34 ~14 ~13 stone 0
fill ~34 ~12 ~31 ~34 ~14 ~31 stone 0
setblock ~37 ~12 ~32 iron_block 0
setblock ~38 ~12 ~31 iron_block 0
setblock ~38 ~12 ~33 iron_block 0
setblock ~39 ~12 ~32 iron_block 0
setblock ~10 ~13 ~14 gold_block 0
setblock ~11 ~13 ~13 gold_block 0
setblock ~11 ~13 ~15 gold_block 0
setblock ~12 ~13 ~14 gold_block 0
setblock ~14 ~13 ~35 iron_block 0
fill ~15 ~13 ~14 ~17 ~13 ~14 stone 0
fill ~15 ~13 ~30 ~17 ~13 ~30 stone 0
setblock ~15 ~13 ~34 iron_block 0
setblock ~15 ~13 ~36 iron_block 0
setblock ~16 ~13 ~35 iron_block 0
fill ~17 ~13 ~12 ~17 ~17 ~12 stone 0
fill ~17 ~13 ~13 ~17 ~14 ~13 stone 0
fill ~17 ~13 ~15 ~20 ~13 ~15 planks 0
fill ~17 ~13 ~16 ~19 ~13 ~16 planks 0
fill ~17 ~13 ~28 ~19 ~13 ~28 planks 0
fill ~17 ~13 ~29 ~33 ~13 ~29 planks 0
fill ~17 ~13 ~31 ~17 ~14 ~31 stone 0
fill ~17 ~13 ~32 ~17 ~17 ~32 stone 0
fill ~18 ~13 ~14 ~19 ~13 ~14 planks 0
fill ~18 ~13 ~30 ~19 ~13 ~30 planks 0
fill ~22 ~13 ~14 ~28 ~13 ~14 glass 0
fill ~26 ~13 ~26 ~28 ~13 ~26 gold_block 0
fill ~26 ~13 ~27 ~28 ~13 ~27 gold_block 0
fill ~26 ~13 ~28 ~28 ~13 ~28 gold_block 0
fill ~29 ~13 ~14 ~32 ~13 ~14 planks 0
fill ~29 ~13 ~26 ~29 ~20 ~26 fence 0
fill ~30 ~13 ~15 ~33 ~13 ~15 planks 0
fill ~31 ~13 ~16 ~33 ~13 ~16 planks 0
fill ~31 ~13 ~28 ~33 ~13 ~28 planks 0
fill ~31 ~13 ~30 ~32 ~13 ~30 planks 0
fill ~33 ~13 ~12 ~33 ~17 ~12 stone 0
fill ~33 ~13 ~13 ~33 ~14 ~13 stone 0
fill ~33 ~13 ~14 ~35 ~13 ~14 stone 0
fill ~33 ~13 ~30 ~35 ~13 ~30 stone 0
fill ~33 ~13 ~31 ~33 ~14 ~31 stone 0
fill ~33 ~13 ~32 ~33 ~17 ~32 stone 0
setblock ~37 ~13 ~12 gold_block 0
setblock ~38 ~13 ~11 gold_block 0
setblock ~38 ~13 ~13 gold_block 0
setblock ~39 ~13 ~12 gold_block 0
fill ~15 ~14 ~14 ~17 ~14 ~14 stone 0
fill ~15 ~14 ~30 ~17 ~14 ~30 stone 0
fill ~17 ~14 ~15 ~20 ~14 ~15 planks 0
fill ~17 ~14 ~16 ~19 ~14 ~16 planks 0
fill ~17 ~14 ~28 ~19 ~14 ~28 planks 0
fill ~17 ~14 ~29 ~33 ~14 ~29 planks 0
fill ~18 ~14 ~14 ~19 ~14 ~14 planks 0
fill ~18 ~14 ~30 ~19 ~14 ~30 planks 0
fill ~22 ~14 ~14 ~28 ~14 ~14 glass 0
fill ~24 ~14 ~26 ~26 ~14 ~26 iron_block 0
fill ~24 ~14 ~27 ~24 ~14 ~28 iron_block 0
fill ~25 ~14 ~28 ~26 ~14 ~28 iron_block 0
setblock ~26 ~14 ~27 iron_block 0
fill ~27 ~14 ~27 ~27 ~20 ~27 fence 0
fill ~29 ~14 ~14 ~32 ~14 ~14 planks 0
setblock ~30 ~14 ~7 gold_block 0
fill ~30 ~14 ~15 ~33 ~14 ~15 planks 0
setblock ~31 ~14 ~6 gold_block 0
setblock ~31 ~14 ~8 gold_block 0
fill ~31 ~14 ~16 ~33 ~14 ~16 planks 0
fill ~31 ~14 ~28 ~33 ~14 ~28 planks 0
fill ~31 ~14 ~30 ~32 ~14 ~30 planks 0
setblock ~32 ~14 ~7 gold_block 0
fill ~33 ~14 ~14 ~35 ~14 ~14 stone 0
fill ~33 ~14 ~30 ~35 ~14 ~30 stone 0
setblock ~34 ~14 ~35 gold_block 0
setblock ~35 ~14 ~34 gold_block 0
setblock ~35 ~14 ~36 gold_block 0
setblock ~36 ~14 ~35 gold_block 0
setblock ~9 ~15 ~16 iron_block 0
setblock ~10 ~15 ~15 iron_block 0
setblock ~10 ~15 ~17 iron_block 0
setblock ~11 ~15 ~16 iron_block 0
setblock ~11 ~15 ~32 gold_block 0
setblock ~12 ~15 ~31 gold_block 0
setblock ~12 ~15 ~33 gold_block 0
setblock ~13 ~15 ~32 gold_block 0
fill ~15 ~15 ~14 ~15 ~17 ~14 stone 0
fill ~15 ~15 ~30 ~15 ~17 ~30 stone 0
setblock ~17 ~15 ~14 stone 0
fill ~17 ~15 ~15 ~20 ~15 ~15 planks 0
fill ~17 ~15 ~16 ~19 ~15 ~16 planks 0
fill ~17 ~15 ~28 ~19 ~15 ~28 planks 0
fill ~17 ~15 ~29 ~33 ~15 ~29 planks 0
setblock ~17 ~15 ~30 stone 0
setblock ~18 ~15 ~7 iron_block 0
fill ~18 ~15 ~14 ~19 ~15 ~14 planks 0
fill ~18 ~15 ~30 ~19 ~15 ~30 planks 0
setblock ~19 ~15 ~6 iron_block 0
setblock ~19 ~15 ~8 iron_block 0
setblock ~20 ~15 ~7 iron_block 0
fill ~22 ~15 ~14 ~28 ~15 ~14 glass 0
fill ~22 ~15 ~26 ~24 ~15 ~26 gold_block 0
fill ~22 ~15 ~27 ~22 ~15 ~28 gold_block 0
fill ~23 ~15 ~28 ~24 ~15 ~28 gold_block 0
setblock ~24 ~15 ~27 gold_block 0
fill ~29 ~15 ~14 ~32 ~15 ~14 planks 0
fill ~30 ~15 ~15 ~33 ~15 ~15 planks 0
fill ~31 ~15 ~16 ~33 ~15 ~16 planks 0
fill ~31 ~15 ~28 ~33 ~15 ~28 planks 0
fill ~31 ~15 ~30 ~32 ~15 ~30 planks 0
fill ~33 ~15 ~14 ~33 ~13 ~14 stone 0
fill ~33 ~15 ~30 ~33 ~13 ~30 stone 0
fill ~35 ~15 ~14 ~35 ~17 ~14 stone 0
fill ~35 ~15 ~30 ~35 ~17 ~30 stone 0
setblock ~39 ~15 ~28 gold_block 0
setblock ~40 ~15 ~27 gold_block 0
setblock ~40 ~15 ~29 gold_block 0
setblock ~41 ~15 ~28 gold_block 0
fill ~16 ~16 ~13 ~18 ~16 ~13 stone 0
fill ~16 ~16 ~14 ~16 ~17 ~14 stone 0
fill ~16 ~16 ~15 ~16 ~20 ~15 stone 0
fill ~16 ~16 ~29 ~16 ~20 ~29 stone 0
fill ~16 ~16 ~30 ~16 ~17 ~30 stone 0
fill ~16 ~16 ~31 ~18 ~16 ~31 stone 0
fill ~17 ~16 ~14 ~19 ~16 ~14 planks 0
fill ~17 ~16 ~15 ~20 ~16 ~15 planks 0
fill ~17 ~16 ~16 ~19 ~16 ~16 planks 0
fill ~17 ~16 ~28 ~19 ~16 ~28 planks 0
fill ~17 ~16 ~29 ~33 ~16 ~29 planks 0
fill ~17 ~16 ~30 ~19 ~16 ~30 planks 0
setblock ~18 ~16 ~37 gold_block 0
setblock ~19 ~16 ~36 gold_block 0
setblock ~19 ~16 ~38 gold_block 0
fill ~20 ~16 ~25 ~22 ~16 ~25 iron_block 0
fill ~20 ~16 ~26 ~20 ~16 ~27 iron_block 0
setblock ~20 ~16 ~37 gold_block 0
fill ~21 ~16 ~27 ~22 ~16 ~27 iron_block 0
fill ~22 ~16 ~14 ~22 ~22 ~14 planks 0
setblock ~22 ~16 ~26 iron_block 0
fill ~23 ~16 ~14 ~27 ~16 ~14 glass 0
fill ~28 ~16 ~14 ~33 ~16 ~14 planks 0
fill ~30 ~16 ~15 ~33 ~16 ~15 planks 0
fill ~31 ~16 ~16 ~33 ~16 ~16 planks 0
fill ~31 ~16 ~28 ~33 ~16 ~28 planks 0
fill ~31 ~16 ~30 ~33 ~16 ~30 planks 0
fill ~32 ~16 ~13 ~34 ~16 ~13 stone 0
fill ~32 ~16 ~31 ~34 ~16 ~31 stone 0
fill ~34 ~16 ~14 ~34 ~17 ~14 stone 0
fill ~34 ~16 ~15 ~34 ~20 ~15 stone 0
fill ~34 ~16 ~29 ~34 ~20 ~29 stone 0
fill ~34 ~16 ~30 ~34 ~17 ~30 stone 0
setblock ~39 ~16 ~16 iron_block 0
setblock ~40 ~16 ~15 iron_block 0
setblock ~40 ~16 ~17 iron_block 0
setblock ~41 ~16 ~16 iron_block 0
setblock ~9 ~17 ~28 iron_block 0
setblock ~10 ~17 ~27 iron_block 0
setblock ~10 ~17 ~29 iron_block 0
setblock ~11 ~17 ~28 iron_block 0
setblock ~14 ~17 ~9 gold_block 0
setblock ~15 ~17 ~8 gold_block 0
setblock ~15 ~17 ~10 gold_block 0
setblock ~16 ~17 ~9 gold_block 0
fill ~16 ~17 ~13 ~18 ~17 ~13 stone 0
fill ~16 ~17 ~31 ~18 ~17 ~31 stone 0
fill ~17 ~17 ~14 ~19 ~17 ~14 planks 0
fill ~17 ~17 ~15 ~20 ~17 ~15 planks 0
fill ~17 ~17 ~16 ~19 ~17 ~16 planks 0
fill ~17 ~17 ~28 ~19 ~17 ~28 planks 0
fill ~17 ~17 ~29 ~33 ~17 ~29 planks 0
fill ~17 ~17 ~30 ~19 ~17 ~30 planks 0
fill ~19 ~17 ~23 ~21 ~17 ~23 gold_block 0
fill ~19 ~17 ~24 ~19 ~17 ~25 gold_block 0
fill ~20 ~17 ~25 ~21 ~17 ~25 gold_block 0
fill ~21 ~17 ~13 ~21 ~18 ~13 planks 0
setblock ~21 ~17 ~24 gold_block 0
fill ~23 ~17 ~14 ~23 ~22 ~14 planks 0
fill ~24 ~17 ~14 ~26 ~17 ~14 glass 0
fill ~27 ~17 ~14 ~33 ~17 ~14 planks 0
fill ~29 ~17 ~13 ~29 ~18 ~13 planks 0
fill ~30 ~17 ~15 ~33 ~17 ~15 planks 0
setblock ~30 ~17 ~37 iron_block 0
fill ~31 ~17 ~16 ~33 ~17 ~16 planks 0
fill ~31 ~17 ~28 ~33 ~17 ~28 planks 0
fill ~31 ~17 ~30 ~33 ~17 ~30 planks 0
setblock ~31 ~17 ~36 iron_block 0
setblock ~31 ~17 ~38 iron_block 0
fill ~32 ~17 ~13 ~34 ~17 ~13 stone 0
fill ~32 ~17 ~31 ~34 ~17 ~31 stone 0
setblock ~32 ~17 ~37 iron_block 0
fill ~16 ~18 ~13 ~16 ~20 ~13 stone 0
fill ~16 ~18 ~31 ~16 ~20 ~31 stone 0
fill ~17 ~18 ~14 ~33 ~18 ~14 planks 0
fill ~17 ~18 ~15 ~20 ~18 ~15 planks 0
fill ~17 ~18 ~16 ~19 ~18 ~16 planks 0
fill ~17 ~18 ~28 ~19 ~18 ~28 planks 0
fill ~17 ~18 ~29 ~33 ~18 ~29 planks 0
fill ~17 ~18 ~30 ~19 ~18 ~30 planks 0
fill ~18 ~18 ~13 ~18 ~20 ~13 stone 0
fill ~18 ~18 ~31 ~18 ~20 ~31 stone 0
fill ~19 ~18 ~21 ~21 ~18 ~21 iron_block 0
fill ~19 ~18 ~22 ~19 ~18 ~23 iron_block 0
fill ~20 ~18 ~23 ~21 ~18 ~23 iron_block 0
setblock ~21 ~18 ~22 iron_block 0
fill ~22 ~18 ~13 ~22 ~19 ~13 planks 0
fill ~28 ~18 ~13 ~28 ~19 ~13 planks 0
fill ~30 ~18 ~15 ~33 ~18 ~15 planks 0
fill ~31 ~18 ~16 ~33 ~18 ~16 planks 0
fill ~31 ~18 ~28 ~33 ~18 ~28 planks 0
fill ~31 ~18 ~30 ~33 ~18 ~30 planks 0
setblock ~32 ~18 ~8 iron_block 0
fill ~32 ~18 ~13 ~32 ~20 ~13 stone 0
fill ~32 ~18 ~31 ~32 ~20 ~31 stone 0
setblock ~33 ~18 ~7 iron_block 0
setblock ~33 ~18 ~9 iron_block 0
setblock ~34 ~18 ~8 iron_block 0
fill ~34 ~18 ~13 ~34 ~20 ~13 stone 0
fill ~34 ~18 ~31 ~34 ~20 ~31 stone 0
fill ~15 ~19 ~14 ~17 ~19 ~14 stone 0
fill ~15 ~19 ~30 ~17 ~19 ~30 stone 0
fill ~17 ~19 ~12 ~17 ~20 ~12 stone 0
fill ~17 ~19 ~13 ~17 ~20 ~13 stone 0
fill ~17 ~19 ~15 ~33 ~19 ~15 planks 0
fill ~17 ~19 ~16 ~19 ~19 ~16 planks 0
fill ~17 ~19 ~28 ~19 ~19 ~28 planks 0
fill ~17 ~19 ~29 ~33 ~19 ~29 planks 0
fill ~17 ~19 ~31 ~17 ~20 ~31 stone 0
fill ~17 ~19 ~32 ~17 ~20 ~32 stone 0
fill ~18 ~19 ~14 ~32 ~19 ~14 planks 0
fill ~18 ~19 ~30 ~19 ~19 ~30 planks 0
fill ~19 ~19 ~19 ~21 ~19 ~19 gold_block 0
fill ~19 ~19 ~20 ~19 ~19 ~21 gold_block 0
fill ~20 ~19 ~21 ~21 ~19 ~21 gold_block 0
setblock ~21 ~19 ~20 gold_block 0
fill ~23 ~19 ~13 ~28 ~19 ~13 planks 0
fill ~31 ~19 ~16 ~33 ~19 ~16 planks 0
fill ~31 ~19 ~28 ~33 ~19 ~28 planks 0
fill ~31 ~19 ~30 ~32 ~19 ~30 planks 0
fill ~33 ~19 ~12 ~33 ~20 ~12 stone 0
fill ~33 ~19 ~13 ~33 ~20 ~13 stone 0
fill ~33 ~19 ~14 ~35 ~19 ~14 stone 0
fill ~33 ~19 ~30 ~35 ~19 ~30 stone 0
fill ~33 ~19 ~31 ~33 ~20 ~31 stone 0
fill ~33 ~19 ~32 ~33 ~20 ~32 stone 0
fill ~3 ~20 ~21 ~8 ~20 ~21 gold_block 0
fill ~4 ~20 ~22 ~8 ~20 ~22 gold_block 0
fill ~5 ~20 ~12 ~5 ~20 ~15 gold_block 0
fill ~5 ~20 ~23 ~8 ~20 ~23 gold_block 0
fill ~5 ~20 ~27 ~9 ~20 ~27 gold_block 0
fill ~6 ~20 ~13 ~6 ~20 ~17 gold_block 0
fill ~6 ~20 ~24 ~8 ~20 ~24 gold_block 0
fill ~6 ~20 ~28 ~9 ~20 ~28 gold_block 0
fill ~7 ~20 ~14 ~10 ~20 ~14 gold_block 0
fill ~7 ~20 ~15 ~10 ~20 ~15 gold_block 0
fill ~7 ~20 ~16 ~9 ~20 ~16 gold_block 0
fill ~7 ~20 ~17 ~9 ~20 ~17 gold_block 0
fill ~7 ~20 ~18 ~8 ~20 ~18 gold_block 0
fill ~7 ~20 ~19 ~8 ~20 ~19 gold_block 0
fill ~7 ~20 ~20 ~8 ~20 ~20 gold_block 0
fill ~7 ~20 ~25 ~8 ~20 ~25 gold_block 0
fill ~7 ~20 ~26 ~8 ~20 ~26 gold_block 0
fill ~7 ~20 ~29 ~10 ~20 ~29 gold_block 0
fill ~8 ~20 ~30 ~10 ~20 ~30 gold_block 0
fill ~8 ~20 ~36 ~16 ~20 ~36 gold_block 0
fill ~9 ~20 ~12 ~11 ~20 ~12 gold_block 0
fill ~9 ~20 ~13 ~11 ~20 ~13 gold_block 0
fill ~9 ~20 ~31 ~11 ~20 ~31 gold_block 0
fill ~9 ~20 ~35 ~14 ~20 ~35 gold_block 0
fill ~10 ~20 ~10 ~13 ~20 ~10 gold_block 0
fill ~10 ~20 ~11 ~12 ~20 ~11 gold_block 0
fill ~10 ~20 ~32 ~11 ~20 ~32 gold_block 0
fill ~10 ~20 ~33 ~12 ~20 ~33 gold_block 0
fill ~10 ~20 ~34 ~13 ~20 ~34 gold_block 0
fill ~11 ~20 ~5 ~11 ~20 ~13 gold_block 0
fill ~12 ~20 ~6 ~12 ~20 ~11 gold_block 0
fill ~13 ~20 ~7 ~18 ~20 ~7 gold_block 0
fill ~13 ~20 ~8 ~16 ~20 ~8 gold_block 0
fill ~13 ~20 ~9 ~14 ~20 ~9 gold_block 0
fill ~13 ~20 ~37 ~18 ~20 ~37 gold_block 0
fill ~15 ~20 ~14 ~17 ~20 ~14 stone 0
fill ~15 ~20 ~30 ~17 ~20 ~30 stone 0
fill ~15 ~20 ~38 ~20 ~20 ~38 gold_block 0
fill ~15 ~20 ~42 ~18 ~20 ~42 gold_block 0
fill ~16 ~20 ~6 ~20 ~20 ~6 gold_block 0
fill ~16 ~20 ~41 ~20 ~20 ~41 gold_block 0
fill ~17 ~20 ~5 ~33 ~20 ~5 gold_block 0
fill ~17 ~20 ~15 ~33 ~20 ~15 planks 0
fill ~17 ~20 ~16 ~33 ~20 ~16 planks 0
fill ~17 ~20 ~17 ~17 ~76 ~17 planks 0
fill ~17 ~20 ~18 ~17 ~76 ~18 planks 0
fill ~17 ~20 ~19 ~17 ~76 ~19 planks 0
fill ~17 ~20 ~20 ~17 ~76 ~20 planks 0
fill ~17 ~20 ~21 ~17 ~26 ~21 planks 0
fill ~17 ~20 ~22 ~17 ~26 ~22 planks 0
fill ~17 ~20 ~23 ~17 ~26 ~23 planks 0
fill ~17 ~20 ~24 ~17 ~76 ~24 planks 0
fill ~17 ~20 ~25 ~17 ~76 ~25 planks 0
fill ~17 ~20 ~26 ~17 ~22 ~26 planks 0
fill ~17 ~20 ~27 ~17 ~22 ~27 planks 0
fill ~17 ~20 ~28 ~33 ~20 ~28 planks 0
fill ~17 ~20 ~29 ~33 ~20 ~29 planks 0
fill ~17 ~20 ~39 ~33 ~20 ~39 gold_block 0
fill ~17 ~20 ~40 ~32 ~20 ~40 gold_block 0
fill ~18 ~20 ~4 ~33 ~20 ~4 gold_block 0
fill ~18 ~20 ~14 ~32 ~20 ~14 planks 0
fill ~18 ~20 ~30 ~32 ~20 ~30 planks 0
fill ~19 ~20 ~3 ~20 ~20 ~3 gold_block 0
fill ~19 ~20 ~17 ~19 ~21 ~17 planks 0
fill ~19 ~20 ~18 ~19 ~21 ~18 planks 0
fill ~19 ~20 ~19 ~19 ~21 ~19 planks 0
fill ~19 ~20 ~20 ~19 ~21 ~20 planks 0
fill ~19 ~20 ~21 ~19 ~21 ~21 planks 0
fill ~19 ~20 ~22 ~19 ~21 ~22 planks 0
fill ~19 ~20 ~23 ~19 ~21 ~23 planks 0
fill ~19 ~20 ~24 ~19 ~21 ~24 planks 0
fill ~19 ~20 ~25 ~19 ~21 ~25 planks 0
fill ~19 ~20 ~26 ~19 ~21 ~26 planks 0
fill ~19 ~20 ~27 ~19 ~21 ~27 planks 0
setblock ~20 ~20 ~2 gold_block 0
fill ~20 ~20 ~17 ~22 ~20 ~17 iron_block 0
fill ~20 ~20 ~18 ~20 ~20 ~19 iron_block 0
fill ~21 ~20 ~19 ~22 ~20 ~19 iron_block 0
setblock ~22 ~20 ~18 iron_block 0
fill ~23 ~20 ~3 ~26 ~20 ~3 gold_block 0
fill ~24 ~20 ~2 ~26 ~20 ~2 gold_block 0
fill ~24 ~20 ~41 ~27 ~20 ~41 gold_block 0
fill ~24 ~20 ~42 ~26 ~20 ~42 gold_block 0
fill ~24 ~20 ~43 ~25 ~20 ~43 gold_block 0
fill ~24 ~20 ~44 ~24 ~20 ~39 gold_block 0
fill ~25 ~20 ~1 ~26 ~20 ~1 gold_block 0
setblock ~26 ~20 ~0 gold_block 0
fill ~30 ~20 ~3 ~34 ~20 ~3 gold_block 0
fill ~30 ~20 ~6 ~35 ~20 ~6 gold_block 0
fill ~30 ~20 ~38 ~34 ~20 ~38 gold_block 0
fill ~30 ~20 ~41 ~31 ~20 ~41 gold_block 0
fill ~30 ~20 ~42 ~30 ~20 ~38 gold_block 0
fill ~31 ~20 ~17 ~31 ~21 ~17 planks 0
fill ~31 ~20 ~18 ~31 ~21 ~18 planks 0
fill ~31 ~20 ~19 ~31 ~21 ~19 planks 0
fill ~31 ~20 ~20 ~31 ~21 ~20 planks 0
fill ~31 ~20 ~21 ~31 ~21 ~21 planks 0
fill ~31 ~20 ~22 ~31 ~21 ~22 planks 0
fill ~31 ~20 ~23 ~31 ~21 ~23 planks 0
fill ~31 ~20 ~24 ~31 ~21 ~24 planks 0
fill ~31 ~20 ~25 ~31 ~21 ~25 planks 0
fill ~31 ~20 ~26 ~31 ~21 ~26 planks 0
fill ~31 ~20 ~27 ~31 ~21 ~27 planks 0
fill ~32 ~20 ~2 ~35 ~20 ~2 gold_block 0
fill ~32 ~20 ~7 ~37 ~20 ~7 gold_block 0
fill ~32 ~20 ~37 ~39 ~20 ~37 gold_block 0
fill ~33 ~20 ~14 ~35 ~20 ~14 stone 0
fill ~33 ~20 ~17 ~33 ~52 ~17 planks 0
fill ~33 ~20 ~18 ~33 ~52 ~18 planks 0
fill ~33 ~20 ~19 ~33 ~76 ~19 planks 0
fill ~33 ~20 ~20 ~33 ~76 ~20 planks 0
fill ~33 ~20 ~21 ~33 ~28 ~21 planks 0
fill ~33 ~20 ~22 ~33 ~28 ~22 planks 0
fill ~33 ~20 ~23 ~33 ~28 ~23 planks 0
fill ~33 ~20 ~24 ~33 ~76 ~24 planks 0
fill ~33 ~20 ~25 ~33 ~76 ~25 planks 0
fill ~33 ~20 ~26 ~33 ~76 ~26 planks 0
fill ~33 ~20 ~27 ~33 ~76 ~27 planks 0
fill ~33 ~20 ~30 ~35 ~20 ~30 stone 0
fill ~34 ~20 ~8 ~42 ~20 ~8 gold_block 0
fill ~34 ~20 ~36 ~39 ~20 ~36 gold_block 0
fill ~36 ~20 ~9 ~41 ~20 ~9 gold_block 0
fill ~36 ~20 ~35 ~39 ~20 ~35 gold_block 0
fill ~37 ~20 ~10 ~40 ~20 ~10 gold_block 0
fill ~37 ~20 ~34 ~40 ~20 ~34 gold_block 0
fill ~38 ~20 ~11 ~40 ~20 ~11 gold_block 0
fill ~38 ~20 ~33 ~40 ~20 ~33 gold_block 0
fill ~38 ~20 ~38 ~39 ~20 ~38 gold_block 0
fill ~39 ~20 ~12 ~40 ~20 ~12 gold_block 0
fill ~39 ~20 ~13 ~41 ~20 ~13 gold_block 0
fill ~39 ~20 ~31 ~41 ~20 ~31 gold_block 0
fill ~39 ~20 ~32 ~41 ~20 ~32 gold_block 0
setblock ~39 ~20 ~39 gold_block 0
fill ~40 ~20 ~14 ~42 ~20 ~14 gold_block 0
fill ~40 ~20 ~15 ~43 ~20 ~15 gold_block 0
fill ~40 ~20 ~29 ~45 ~20 ~29 gold_block 0
fill ~40 ~20 ~30 ~45 ~20 ~30 gold_block 0
fill ~41 ~20 ~16 ~44 ~20 ~16 gold_block 0
fill ~41 ~20 ~17 ~45 ~20 ~17 gold_block 0
fill ~41 ~20 ~27 ~44 ~20 ~27 gold_block 0
fill ~41 ~20 ~28 ~44 ~20 ~28 gold_block 0
fill ~42 ~20 ~18 ~43 ~20 ~18 gold_block 0
fill ~42 ~20 ~19 ~43 ~20 ~19 gold_block 0
fill ~42 ~20 ~20 ~44 ~20 ~20 gold_block 0
fill ~42 ~20 ~21 ~45 ~20 ~21 gold_block 0
fill ~42 ~20 ~22 ~46 ~20 ~22 gold_block 0
fill ~42 ~20 ~23 ~47 ~20 ~23 gold_block 0
fill ~42 ~20 ~24 ~43 ~20 ~24 gold_block 0
fill ~42 ~20 ~25 ~43 ~20 ~25 gold_block 0
fill ~42 ~20 ~26 ~43 ~20 ~26 gold_block 0
fill ~44 ~20 ~31 ~45 ~20 ~31 gold_block 0
setblock ~45 ~20 ~32 gold_block 0
fill ~3 ~21 ~21 ~8 ~21 ~21 iron_block 0
fill ~4 ~21 ~22 ~8 ~21 ~22 iron_block 0
fill ~5 ~21 ~12 ~5 ~21 ~15 iron_block 0
fill ~5 ~21 ~23 ~8 ~21 ~23 iron_block 0
fill ~5 ~21 ~27 ~9 ~21 ~27 iron_block 0
fill ~6 ~21 ~13 ~6 ~21 ~17 iron_block 0
fill ~6 ~21 ~24 ~8 ~21 ~24 iron_block 0
fill ~6 ~21 ~28 ~9 ~21 ~28 iron_block 0
fill ~7 ~21 ~14 ~10 ~21 ~14 iron_block 0
fill ~7 ~21 ~15 ~10 ~21 ~15 iron_block 0
fill ~7 ~21 ~16 ~9 ~21 ~16 iron_block 0
fill ~7 ~21 ~17 ~9 ~21 ~17 iron_block 0
fill ~7 ~21 ~18 ~8 ~21 ~18 iron_block 0
fill ~7 ~21 ~19 ~8 ~21 ~19 iron_block 0
fill ~7 ~21 ~20 ~8 ~21 ~20 iron_block 0
fill ~7 ~21 ~25 ~8 ~21 ~25 iron_block 0
fill ~7 ~21 ~26 ~8 ~21 ~26 iron_block 0
fill ~7 ~21 ~29 ~10 ~21 ~29 iron_block 0
fill ~8 ~21 ~30 ~10 ~21 ~30 iron_block 0
fill ~8 ~21 ~36 ~16 ~21 ~36 iron_block 0
fill ~9 ~21 ~12 ~11 ~21 ~12 iron_block 0
fill ~9 ~21 ~13 ~11 ~21 ~13 iron_block 0
fill ~9 ~21 ~18 ~21 ~21 ~18 planks 0
fill ~9 ~21 ~19 ~20 ~21 ~19 planks 0
fill ~9 ~21 ~20 ~20 ~21 ~20 planks 0
fill ~9 ~21 ~21 ~20 ~21 ~21 planks 0
fill ~9 ~21 ~22 ~20 ~21 ~22 planks 0
fill ~9 ~21 ~23 ~20 ~21 ~23 planks 0
fill ~9 ~21 ~24 ~20 ~21 ~24 planks 0
fill ~9 ~21 ~25 ~21 ~21 ~25 planks 0
fill ~9 ~21 ~26 ~22 ~21 ~26 planks 0
fill ~9 ~21 ~31 ~11 ~21 ~31 iron_block 0
fill ~9 ~21 ~35 ~14 ~21 ~35 iron_block 0
fill ~10 ~21 ~10 ~13 ~21 ~10 iron_block 0
fill ~10 ~21 ~11 ~12 ~21 ~11 iron_block 0
fill ~10 ~21 ~16 ~40 ~21 ~16 planks 0
fill ~10 ~21 ~17 ~21 ~21 ~17 planks 0
fill ~10 ~21 ~27 ~40 ~21 ~27 planks 0
fill ~10 ~21 ~28 ~40 ~21 ~28 planks 0
fill ~10 ~21 ~32 ~11 ~21 ~32 iron_block 0
fill ~10 ~21 ~33 ~12 ~21 ~33 iron_block 0
fill ~10 ~21 ~34 ~13 ~21 ~34 iron_block 0
fill ~11 ~21 ~5 ~11 ~21 ~13 iron_block 0
fill ~11 ~21 ~14 ~39 ~21 ~14 planks 0
fill ~11 ~21 ~15 ~39 ~21 ~15 planks 0
fill ~11 ~21 ~29 ~39 ~21 ~29 planks 0
fill ~11 ~21 ~30 ~39 ~21 ~30 planks 0
fill ~12 ~21 ~6 ~12 ~21 ~11 iron_block 0
fill ~12 ~21 ~12 ~38 ~21 ~12 planks 0
fill ~12 ~21 ~13 ~38 ~21 ~13 planks 0
fill ~12 ~21 ~31 ~38 ~21 ~31 planks 0
fill ~12 ~21 ~32 ~38 ~21 ~32 planks 0
fill ~13 ~21 ~7 ~18 ~21 ~7 iron_block 0
fill ~13 ~21 ~8 ~16 ~21 ~8 iron_block 0
fill ~13 ~21 ~9 ~13 ~21 ~7 iron_block 0
fill ~13 ~21 ~11 ~37 ~21 ~11 planks 0
fill ~13 ~21 ~33 ~37 ~21 ~33 planks 0
fill ~13 ~21 ~37 ~18 ~21 ~37 iron_block 0
fill ~14 ~21 ~9 ~35 ~21 ~9 planks 0
fill ~14 ~21 ~10 ~36 ~21 ~10 planks 0
fill ~14 ~21 ~34 ~37 ~21 ~34 planks 0
fill ~15 ~21 ~35 ~37 ~21 ~35 planks 0
fill ~15 ~21 ~38 ~20 ~21 ~38 iron_block 0
fill ~15 ~21 ~42 ~18 ~21 ~42 iron_block 0
fill ~16 ~21 ~6 ~20 ~21 ~6 iron_block 0
fill ~16 ~21 ~41 ~20 ~21 ~41 iron_block 0
fill ~17 ~21 ~5 ~33 ~21 ~5 iron_block 0
fill ~17 ~21 ~8 ~33 ~21 ~8 planks 0
fill ~17 ~21 ~36 ~33 ~21 ~36 planks 0
fill ~17 ~21 ~39 ~33 ~21 ~39 iron_block 0
fill ~17 ~21 ~40 ~32 ~21 ~40 iron_block 0
fill ~18 ~21 ~4 ~33 ~21 ~4 iron_block 0
fill ~19 ~21 ~3 ~20 ~21 ~3 iron_block 0
fill ~19 ~21 ~7 ~31 ~21 ~7 planks 0
fill ~19 ~21 ~37 ~31 ~21 ~37 planks 0
setblock ~20 ~21 ~2 iron_block 0
fill ~21 ~21 ~6 ~29 ~21 ~6 planks 0
fill ~21 ~21 ~38 ~29 ~21 ~38 planks 0
setblock ~22 ~21 ~17 oak_stairs 3
fill ~23 ~21 ~3 ~26 ~21 ~3 iron_block 0
fill ~23 ~21 ~17 ~40 ~21 ~17 planks 0
fill ~24 ~21 ~2 ~26 ~21 ~2 iron_block 0
fill ~24 ~21 ~41 ~27 ~21 ~41 iron_block 0
fill ~24 ~21 ~42 ~26 ~21 ~42 iron_block 0
fill ~24 ~21 ~43 ~25 ~21 ~43 iron_block 0
fill ~24 ~21 ~44 ~24 ~21 ~39 iron_block 0
fill ~25 ~21 ~1 ~26 ~21 ~1 iron_block 0
setblock ~26 ~21 ~0 iron_block 0
fill ~28 ~21 ~18 ~41 ~21 ~18 planks 0
fill ~28 ~21 ~26 ~41 ~21 ~26 planks 0
fill ~29 ~21 ~19 ~41 ~21 ~19 planks 0
fill ~29 ~21 ~25 ~41 ~21 ~25 planks 0
fill ~30 ~21 ~3 ~34 ~21 ~3 iron_block 0
fill ~30 ~21 ~6 ~35 ~21 ~6 iron_block 0
fill ~30 ~21 ~20 ~30 ~21 ~37 planks 0
fill ~30 ~21 ~38 ~34 ~21 ~38 iron_block 0
fill ~30 ~21 ~41 ~31 ~21 ~41 iron_block 0
fill ~30 ~21 ~42 ~30 ~21 ~38 iron_block 0
fill ~32 ~21 ~2 ~35 ~21 ~2 iron_block 0
fill ~32 ~21 ~7 ~37 ~21 ~7 iron_block 0
fill ~32 ~21 ~37 ~39 ~21 ~37 iron_block 0
fill ~34 ~21 ~8 ~42 ~21 ~8 iron_block 0
fill ~34 ~21 ~20 ~41 ~21 ~20 planks 0
fill ~34 ~21 ~21 ~41 ~21 ~21 planks 0
fill ~34 ~21 ~22 ~41 ~21 ~22 planks 0
fill ~34 ~21 ~23 ~41 ~21 ~23 planks 0
fill ~34 ~21 ~24 ~41 ~21 ~24 planks 0
fill ~34 ~21 ~36 ~39 ~21 ~36 iron_block 0
fill ~36 ~21 ~9 ~41 ~21 ~9 iron_block 0
fill ~37 ~21 ~10 ~40 ~21 ~10 iron_block 0
fill ~38 ~21 ~11 ~40 ~21 ~11 iron_block 0
fill ~38 ~21 ~33 ~40 ~21 ~33 iron_block 0
fill ~38 ~21 ~34 ~40 ~21 ~34 iron_block 0
fill ~38 ~21 ~35 ~39 ~21 ~35 iron_block 0
fill ~38 ~21 ~38 ~39 ~21 ~38 iron_block 0
fill ~39 ~21 ~12 ~40 ~21 ~12 iron_block 0
fill ~39 ~21 ~13 ~41 ~21 ~13 iron_block 0
fill ~39 ~21 ~31 ~41 ~21 ~31 iron_block 0
fill ~39 ~21 ~32 ~41 ~21 ~32 iron_block 0
setblock ~39 ~21 ~39 iron_block 0
fill ~40 ~21 ~14 ~42 ~21 ~14 iron_block 0
fill ~40 ~21 ~15 ~43 ~21 ~15 iron_block 0
fill ~40 ~21 ~29 ~45 ~21 ~29 iron_block 0
fill ~40 ~21 ~30 ~45 ~21 ~30 iron_block 0
fill ~41 ~21 ~16 ~44 ~21 ~16 iron_block 0
fill ~41 ~21 ~17 ~45 ~21 ~17 iron_block 0
fill ~41 ~21 ~27 ~44 ~21 ~27 iron_block 0
fill ~41 ~21 ~28 ~44 ~21 ~28 iron_block 0
fill ~42 ~21 ~18 ~43 ~21 ~18 iron_block 0
fill ~42 ~21 ~19 ~43 ~21 ~19 iron_block 0
fill ~42 ~21 ~20 ~44 ~21 ~20 iron_block 0
fill ~42 ~21 ~21 ~45 ~21 ~21 iron_block 0
fill ~42 ~21 ~22 ~46 ~21 ~22 iron_block 0
fill ~42 ~21 ~23 ~47 ~21 ~23 iron_block 0
fill ~42 ~21 ~24 ~43 ~21 ~24 iron_block 0
fill ~42 ~21 ~25 ~43 ~21 ~25 iron_block 0
fill ~42 ~21 ~26 ~43 ~21 ~26 iron_block 0
fill ~44 ~21 ~31 ~45 ~21 ~31 iron_block 0
setblock ~45 ~21 ~32 iron_block 0
fill ~3 ~22 ~21 ~8 ~22 ~21 gold_block 0
fill ~4 ~22 ~22 ~8 ~22 ~22 gold_block 0
fill ~5 ~22 ~12 ~5 ~22 ~15 gold_block 0
fill ~5 ~22 ~23 ~8 ~22 ~23 gold_block 0
fill ~5 ~22 ~27 ~9 ~22 ~27 gold_block 0
fill ~6 ~22 ~13 ~6 ~22 ~17 gold_block 0
fill ~6 ~22 ~24 ~8 ~22 ~24 gold_block 0
fill ~6 ~22 ~28 ~9 ~22 ~28 gold_block 0
fill ~7 ~22 ~14 ~10 ~22 ~14 gold_block 0
fill ~7 ~22 ~15 ~10 ~22 ~15 gold_block 0
fill ~7 ~22 ~16 ~9 ~22 ~16 gold_block 0
fill ~7 ~22 ~17 ~9 ~22 ~17 gold_block 0
fill ~7 ~22 ~18 ~8 ~22 ~18 gold_block 0
fill ~7 ~22 ~19 ~8 ~22 ~19 gold_block 0
fill ~7 ~22 ~20 ~8 ~22 ~20 gold_block 0
fill ~7 ~22 ~25 ~8 ~22 ~25 gold_block 0
fill ~7 ~22 ~26 ~8 ~22 ~26 gold_block 0
fill ~7 ~22 ~29 ~10 ~22 ~29 gold_block 0
fill ~8 ~22 ~30 ~10 ~22 ~30 gold_block 0
fill ~8 ~22 ~36 ~16 ~22 ~36 gold_block 0
fill ~9 ~22 ~12 ~11 ~22 ~12 gold_block 0
fill ~9 ~22 ~13 ~11 ~22 ~13 gold_block 0
fill ~9 ~22 ~31 ~11 ~22 ~31 gold_block 0
fill ~9 ~22 ~35 ~14 ~22 ~35 gold_block 0
fill ~10 ~22 ~10 ~13 ~22 ~10 gold_block 0
fill ~10 ~22 ~11 ~12 ~22 ~11 gold_block 0
fill ~10 ~22 ~32 ~11 ~22 ~32 gold_block 0
fill ~10 ~22 ~33 ~12 ~22 ~33 gold_block 0
fill ~10 ~22 ~34 ~13 ~22 ~34 gold_block 0
fill ~11 ~22 ~5 ~11 ~22 ~13 gold_block 0
fill ~12 ~22 ~6 ~12 ~22 ~11 gold_block 0
fill ~13 ~22 ~7 ~18 ~22 ~7 gold_block 0
fill ~13 ~22 ~8 ~16 ~22 ~8 gold_block 0
fill ~13 ~22 ~9 ~14 ~22 ~9 gold_block 0
fill ~13 ~22 ~37 ~18 ~22 ~37 gold_block 0
fill ~15 ~22 ~14 ~16 ~22 ~14 stone 0
fill ~15 ~22 ~30 ~16 ~22 ~30 stone 0
fill ~15 ~22 ~38 ~20 ~22 ~38 gold_block 0
fill ~15 ~22 ~42 ~18 ~22 ~42 gold_block 0
fill ~16 ~22 ~6 ~20 ~22 ~6 gold_block 0
fill ~16 ~22 ~13 ~18 ~22 ~13 stone 0
fill ~16 ~22 ~15 ~16 ~26 ~15 stone 0
fill ~16 ~22 ~29 ~16 ~26 ~29 stone 0
fill ~16 ~22 ~31 ~18 ~22 ~31 stone 0
fill ~16 ~22 ~41 ~20 ~22 ~41 gold_block 0
fill ~17 ~22 ~5 ~33 ~22 ~5 gold_block 0
fill ~17 ~22 ~12 ~17 ~23 ~12 stone 0
fill ~17 ~22 ~14 ~18 ~22 ~14 planks 0
fill ~17 ~22 ~15 ~17 ~76 ~15 planks 0
fill ~17 ~22 ~16 ~17 ~76 ~16 planks 0
fill ~17 ~22 ~28 ~17 ~22 ~30 planks 0
fill ~17 ~22 ~32 ~17 ~23 ~32 stone 0
fill ~17 ~22 ~39 ~33 ~22 ~39 gold_block 0
fill ~17 ~22 ~40 ~32 ~22 ~40 gold_block 0
fill ~18 ~22 ~4 ~33 ~22 ~4 gold_block 0
fill ~18 ~22 ~29 ~18 ~74 ~29 ladder 2
fill ~18 ~22 ~30 ~19 ~22 ~30 planks 0
fill ~19 ~22 ~3 ~20 ~22 ~3 gold_block 0
setblock ~19 ~22 ~11 rail 6
fill ~19 ~22 ~12 ~19 ~22 ~13 rail 0
setblock ~19 ~22 ~14 wooden_door 0
fill ~19 ~22 ~15 ~19 ~22 ~26 rail 0
setblock ~19 ~22 ~27 rail 9
setblock ~20 ~22 ~2 gold_block 0
setblock ~20 ~22 ~10 rail 6
setblock ~20 ~22 ~11 rail 8
fill ~20 ~22 ~14 ~20 ~22 ~15 planks 0
fill ~20 ~22 ~18 ~21 ~22 ~18 fence 0
fill ~20 ~22 ~19 ~20 ~22 ~25 fence 0
setblock ~20 ~22 ~27 rail 1
fill ~20 ~22 ~29 ~30 ~22 ~29 planks 0
fill ~21 ~22 ~10 ~22 ~22 ~10 rail 1
fill ~21 ~22 ~15 ~30 ~22 ~15 planks 0
setblock ~21 ~22 ~17 fence 0
fill ~21 ~22 ~25 ~21 ~22 ~26 fence 0
setblock ~21 ~22 ~27 rail 7
setblock ~21 ~22 ~28 rail 9
fill ~22 ~22 ~26 ~22 ~22 ~27 fence 0
fill ~22 ~22 ~28 ~28 ~22 ~28 rail 1
fill ~23 ~22 ~3 ~26 ~22 ~3 gold_block 0
setblock ~23 ~22 ~9 rail 6
setblock ~23 ~22 ~10 rail 8
fill ~23 ~22 ~17 ~28 ~22 ~17 fence 0
fill ~23 ~22 ~27 ~28 ~22 ~27 fence 0
fill ~24 ~22 ~2 ~26 ~22 ~2 gold_block 0
fill ~24 ~22 ~9 ~26 ~22 ~9 rail 1
fill ~24 ~22 ~14 ~30 ~22 ~14 planks 0
fill ~24 ~22 ~41 ~27 ~22 ~41 gold_block 0
fill ~24 ~22 ~42 ~26 ~22 ~42 gold_block 0
fill ~24 ~22 ~43 ~25 ~22 ~43 gold_block 0
fill ~24 ~22 ~44 ~24 ~22 ~39 gold_block 0
fill ~25 ~22 ~1 ~26 ~22 ~1 gold_block 0
setblock ~26 ~22 ~0 gold_block 0
setblock ~27 ~22 ~9 rail 7
setblock ~27 ~22 ~10 rail 9
fill ~28 ~22 ~10 ~29 ~22 ~10 rail 1
fill ~28 ~22 ~18 ~29 ~22 ~18 fence 0
fill ~28 ~22 ~26 ~29 ~22 ~26 fence 0
fill ~29 ~22 ~19 ~30 ~22 ~19 fence 0
fill ~29 ~22 ~25 ~30 ~22 ~25 fence 0
setblock ~29 ~22 ~27 rail 6
setblock ~29 ~22 ~28 rail 8
fill ~30 ~22 ~3 ~34 ~22 ~3 gold_block 0
fill ~30 ~22 ~6 ~35 ~22 ~6 gold_block 0
setblock ~30 ~22 ~10 rail 7
setblock ~30 ~22 ~11 rail 9
fill ~30 ~22 ~20 ~30 ~22 ~25 fence 0
setblock ~30 ~22 ~27 rail 1
fill ~30 ~22 ~38 ~34 ~22 ~38 gold_block 0
fill ~30 ~22 ~41 ~31 ~22 ~41 gold_block 0
fill ~30 ~22 ~42 ~30 ~22 ~38 gold_block 0
setblock ~31 ~22 ~11 rail 7
fill ~31 ~22 ~12 ~31 ~22 ~13 rail 0
setblock ~31 ~22 ~14 wooden_door 5
fill ~31 ~22 ~15 ~31 ~22 ~26 rail 0
setblock ~31 ~22 ~27 rail 8
fill ~31 ~22 ~30 ~33 ~22 ~30 planks 0
fill ~32 ~22 ~2 ~35 ~22 ~2 gold_block 0
fill ~32 ~22 ~7 ~37 ~22 ~7 gold_block 0
fill ~32 ~22 ~13 ~34 ~22 ~13 stone 0
fill ~32 ~22 ~14 ~33 ~22 ~14 planks 0
fill ~32 ~22 ~31 ~34 ~22 ~31 stone 0
fill ~32 ~22 ~37 ~39 ~22 ~37 gold_block 0
fill ~33 ~22 ~12 ~33 ~23 ~12 stone 0
fill ~33 ~22 ~15 ~33 ~76 ~15 planks 0
fill ~33 ~22 ~16 ~33 ~52 ~16 planks 0
fill ~33 ~22 ~28 ~33 ~76 ~28 planks 0
fill ~33 ~22 ~29 ~33 ~76 ~29 planks 0
fill ~33 ~22 ~32 ~33 ~23 ~32 stone 0
fill ~34 ~22 ~8 ~42 ~22 ~8 gold_block 0
fill ~34 ~22 ~14 ~35 ~22 ~14 stone 0
fill ~34 ~22 ~15 ~34 ~26 ~15 stone 0
fill ~34 ~22 ~29 ~34 ~26 ~29 stone 0
fill ~34 ~22 ~30 ~35 ~22 ~30 stone 0
fill ~34 ~22 ~36 ~39 ~22 ~36 gold_block 0
fill ~36 ~22 ~9 ~41 ~22 ~9 gold_block 0
fill ~36 ~22 ~35 ~39 ~22 ~35 gold_block 0
fill ~37 ~22 ~10 ~40 ~22 ~10 gold_block 0
fill ~37 ~22 ~34 ~40 ~22 ~34 gold_block 0
fill ~38 ~22 ~11 ~40 ~22 ~11 gold_block 0
fill ~38 ~22 ~33 ~40 ~22 ~33 gold_block 0
fill ~38 ~22 ~38 ~39 ~22 ~38 gold_block 0
fill ~39 ~22 ~12 ~40 ~22 ~12 gold_block 0
fill ~39 ~22 ~13 ~41 ~22 ~13 gold_block 0
fill ~39 ~22 ~31 ~41 ~22 ~31 gold_block 0
fill ~39 ~22 ~32 ~41 ~22 ~32 gold_block 0
setblock ~39 ~22 ~39 gold_block 0
fill ~40 ~22 ~14 ~42 ~22 ~14 gold_block 0
fill ~40 ~22 ~15 ~43 ~22 ~15 gold_block 0
fill ~40 ~22 ~29 ~45 ~22 ~29 gold_block 0
fill ~40 ~22 ~30 ~45 ~22 ~30 gold_block 0
fill ~41 ~22 ~16 ~44 ~22 ~16 gold_block 0
fill ~41 ~22 ~17 ~45 ~22 ~17 gold_block 0
fill ~41 ~22 ~27 ~44 ~22 ~27 gold_block 0
fill ~41 ~22 ~28 ~44 ~22 ~28 gold_block 0
fill ~42 ~22 ~18 ~43 ~22 ~18 gold_block 0
fill ~42 ~22 ~19 ~43 ~22 ~19 gold_block 0
fill ~42 ~22 ~20 ~44 ~22 ~20 gold_block 0
fill ~42 ~22 ~21 ~45 ~22 ~21 gold_block 0
fill ~42 ~22 ~22 ~46 ~22 ~22 gold_block 0
fill ~42 ~22 ~23 ~47 ~22 ~23 gold_block 0
fill ~42 ~22 ~24 ~43 ~22 ~24 gold_block 0
fill ~42 ~22 ~25 ~43 ~22 ~25 gold_block 0
fill ~42 ~22 ~26 ~43 ~22 ~26 gold_block 0
fill ~44 ~22 ~31 ~45 ~22 ~31 gold_block 0
setblock ~45 ~22 ~32 gold_block 0
fill ~15 ~23 ~14 ~16 ~23 ~14 stone 0
fill ~15 ~23 ~26 ~15 ~26 ~26 iron_block 0
fill ~15 ~23 ~27 ~15 ~26 ~27 gold_block 0
fill ~15 ~23 ~28 ~15 ~26 ~28 iron_block 0
fill ~15 ~23 ~30 ~16 ~23 ~30 stone 0
fill ~16 ~23 ~13 ~18 ~23 ~13 stone 0
fill ~16 ~23 ~31 ~18 ~23 ~31 stone 0
fill ~17 ~23 ~14 ~18 ~23 ~14 planks 0
fill ~17 ~23 ~29 ~17 ~76 ~29 planks 0
fill ~17 ~23 ~30 ~19 ~23 ~30 planks 0
setblock ~19 ~23 ~14 wooden_door 8
fill ~20 ~23 ~14 ~30 ~23 ~14 glass 0
fill ~20 ~23 ~15 ~30 ~23 ~15 planks 0
fill ~20 ~23 ~29 ~30 ~23 ~29 planks 0
setblock ~31 ~23 ~14 wooden_door 13
fill ~31 ~23 ~30 ~33 ~23 ~30 planks 0
fill ~32 ~23 ~13 ~34 ~23 ~13 stone 0
fill ~32 ~23 ~14 ~33 ~23 ~14 planks 0
fill ~32 ~23 ~31 ~34 ~23 ~31 stone 0
fill ~34 ~23 ~14 ~35 ~23 ~14 stone 0
fill ~34 ~23 ~30 ~35 ~23 ~30 stone 0
fill ~14 ~24 ~26 ~14 ~26 ~26 iron_block 0
fill ~14 ~24 ~27 ~14 ~32 ~27 gold_block 0
fill ~14 ~24 ~28 ~14 ~26 ~28 iron_block 0
fill ~16 ~24 ~13 ~16 ~26 ~13 stone 0
fill ~16 ~24 ~31 ~16 ~26 ~31 stone 0
setblock ~17 ~24 ~13 torch 4
fill ~17 ~24 ~14 ~19 ~24 ~14 planks 0
fill ~17 ~24 ~30 ~19 ~24 ~30 planks 0
fill ~18 ~24 ~13 ~18 ~26 ~13 stone 0
fill ~18 ~24 ~31 ~18 ~26 ~31 stone 0
fill ~20 ~24 ~14 ~30 ~24 ~14 glass 0
fill ~20 ~24 ~15 ~20 ~53 ~15 planks 0
fill ~20 ~24 ~29 ~30 ~24 ~29 planks 0
fill ~30 ~24 ~15 ~30 ~53 ~15 planks 0
fill ~31 ~24 ~14 ~33 ~24 ~14 planks 0
fill ~31 ~24 ~30 ~33 ~24 ~30 planks 0
fill ~32 ~24 ~13 ~32 ~26 ~13 stone 0
fill ~32 ~24 ~31 ~32 ~26 ~31 stone 0
setblock ~33 ~24 ~13 torch 4
fill ~34 ~24 ~13 ~34 ~26 ~13 stone 0
fill ~34 ~24 ~31 ~34 ~26 ~31 stone 0
fill ~10 ~25 ~26 ~10 ~28 ~26 iron_block 0
fill ~10 ~25 ~27 ~10 ~28 ~27 gold_block 0
fill ~10 ~25 ~28 ~10 ~28 ~28 iron_block 0
fill ~15 ~25 ~14 ~17 ~25 ~14 stone 0
fill ~15 ~25 ~30 ~17 ~25 ~30 stone 0
fill ~16 ~25 ~26 ~16 ~26 ~26 iron_block 0
fill ~16 ~25 ~27 ~16 ~32 ~27 gold_block 0
fill ~16 ~25 ~28 ~16 ~26 ~28 iron_block 0
fill ~17 ~25 ~12 ~17 ~29 ~12 stone 0
fill ~17 ~25 ~13 ~17 ~26 ~13 stone 0
fill ~17 ~25 ~31 ~17 ~26 ~31 stone 0
fill ~17 ~25 ~32 ~17 ~29 ~32 stone 0
fill ~18 ~25 ~14 ~19 ~25 ~14 planks 0
fill ~18 ~25 ~30 ~19 ~25 ~30 planks 0
fill ~20 ~25 ~14 ~30 ~25 ~14 glass 0
fill ~20 ~25 ~29 ~30 ~25 ~29 planks 0
fill ~31 ~25 ~14 ~32 ~25 ~14 planks 0
fill ~31 ~25 ~30 ~32 ~25 ~30 planks 0
fill ~33 ~25 ~12 ~33 ~29 ~12 stone 0
fill ~33 ~25 ~13 ~33 ~26 ~13 stone 0
fill ~33 ~25 ~14 ~35 ~25 ~14 stone 0
fill ~33 ~25 ~30 ~35 ~25 ~30 stone 0
fill ~33 ~25 ~31 ~33 ~26 ~31 stone 0
fill ~33 ~25 ~32 ~33 ~29 ~32 stone 0
fill ~9 ~26 ~26 ~9 ~30 ~26 iron_block 0
fill ~9 ~26 ~27 ~9 ~30 ~27 gold_block 0
fill ~9 ~26 ~28 ~9 ~30 ~28 iron_block 0
fill ~12 ~26 ~26 ~21 ~26 ~26 iron_block 0
fill ~12 ~26 ~27 ~21 ~26 ~27 gold_block 0
fill ~12 ~26 ~28 ~21 ~26 ~28 iron_block 0
fill ~15 ~26 ~14 ~17 ~26 ~14 stone 0
fill ~15 ~26 ~30 ~17 ~26 ~30 stone 0
fill ~18 ~26 ~14 ~19 ~26 ~14 planks 0
setblock ~18 ~26 ~15 torch 3
fill ~18 ~26 ~30 ~19 ~26 ~30 planks 0
setblock ~19 ~26 ~29 torch 4
fill ~20 ~26 ~14 ~30 ~26 ~14 glass 0
fill ~20 ~26 ~29 ~30 ~26 ~29 planks 0
fill ~22 ~26 ~21 ~22 ~31 ~21 gold_block 0
fill ~22 ~26 ~22 ~22 ~46 ~22 iron_block 0
fill ~22 ~26 ~23 ~22 ~31 ~23 gold_block 0
fill ~31 ~26 ~14 ~32 ~26 ~14 planks 0
fill ~31 ~26 ~30 ~32 ~26 ~30 planks 0
setblock ~32 ~26 ~15 torch 3
setblock ~32 ~26 ~29 torch 4
fill ~33 ~26 ~14 ~35 ~26 ~14 stone 0
fill ~33 ~26 ~30 ~35 ~26 ~30 stone 0
fill ~8 ~27 ~26 ~8 ~36 ~26 iron_block 0
fill ~8 ~27 ~27 ~8 ~36 ~27 gold_block 0
fill ~8 ~27 ~28 ~8 ~36 ~28 iron_block 0
fill ~11 ~27 ~26 ~12 ~27 ~26 iron_block 0
fill ~11 ~27 ~27 ~12 ~27 ~27 gold_block 0
fill ~11 ~27 ~28 ~12 ~27 ~28 iron_block 0
fill ~15 ~27 ~14 ~15 ~29 ~14 stone 0
fill ~15 ~27 ~27 ~15 ~32 ~27 iron_block 0
fill ~15 ~27 ~30 ~15 ~29 ~30 stone 0
setblock ~17 ~27 ~14 stone 0
setblock ~17 ~27 ~30 stone 0
fill ~18 ~27 ~14 ~19 ~27 ~14 planks 0
fill ~18 ~27 ~26 ~22 ~27 ~26 iron_block 0
fill ~18 ~27 ~27 ~22 ~27 ~27 gold_block 0
fill ~18 ~27 ~28 ~22 ~27 ~28 iron_block 0
fill ~18 ~27 ~30 ~19 ~27 ~30 planks 0
fill ~20 ~27 ~14 ~30 ~27 ~14 glass 0
fill ~20 ~27 ~29 ~30 ~27 ~29 planks 0
fill ~23 ~27 ~21 ~23 ~31 ~21 gold_block 0
fill ~23 ~27 ~22 ~23 ~31 ~22 iron_block 0
fill ~23 ~27 ~23 ~23 ~31 ~23 gold_block 0
fill ~31 ~27 ~14 ~32 ~27 ~14 planks 0
fill ~31 ~27 ~30 ~32 ~27 ~30 planks 0
fill ~33 ~27 ~14 ~33 ~25 ~14 stone 0
fill ~33 ~27 ~30 ~33 ~25 ~30 stone 0
fill ~35 ~27 ~14 ~35 ~29 ~14 stone 0
fill ~35 ~27 ~30 ~35 ~29 ~30 stone 0
fill ~13 ~28 ~21 ~16 ~28 ~21 gold_block 0
fill ~13 ~28 ~22 ~16 ~28 ~22 iron_block 0
fill ~13 ~28 ~23 ~16 ~28 ~23 gold_block 0
fill ~16 ~28 ~13 ~18 ~28 ~13 stone 0
fill ~16 ~28 ~14 ~16 ~29 ~14 stone 0
fill ~16 ~28 ~15 ~16 ~32 ~15 stone 0
fill ~16 ~28 ~29 ~16 ~38 ~29 stone 0
fill ~16 ~28 ~30 ~16 ~29 ~30 stone 0
fill ~16 ~28 ~31 ~18 ~28 ~31 stone 0
fill ~17 ~28 ~14 ~19 ~28 ~14 planks 0
fill ~17 ~28 ~30 ~19 ~28 ~30 planks 0
fill ~20 ~28 ~14 ~30 ~28 ~14 glass 0
fill ~20 ~28 ~26 ~23 ~28 ~26 iron_block 0
fill ~20 ~28 ~27 ~23 ~28 ~27 gold_block 0
fill ~20 ~28 ~28 ~23 ~28 ~28 iron_block 0
fill ~20 ~28 ~29 ~30 ~28 ~29 planks 0
fill ~24 ~28 ~21 ~24 ~31 ~21 gold_block 0
fill ~24 ~28 ~22 ~24 ~46 ~22 iron_block 0
fill ~24 ~28 ~23 ~24 ~31 ~23 gold_block 0
fill ~28 ~28 ~21 ~28 ~32 ~21 gold_block 0
fill ~28 ~28 ~22 ~28 ~32 ~22 iron_block 0
fill ~28 ~28 ~23 ~28 ~32 ~23 gold_block 0
fill ~31 ~28 ~14 ~33 ~28 ~14 planks 0
fill ~31 ~28 ~30 ~33 ~28 ~30 planks 0
fill ~32 ~28 ~13 ~34 ~28 ~13 stone 0
fill ~32 ~28 ~31 ~34 ~28 ~31 stone 0
fill ~34 ~28 ~14 ~34 ~29 ~14 stone 0
fill ~34 ~28 ~15 ~34 ~32 ~15 stone 0
fill ~34 ~28 ~29 ~34 ~32 ~29 stone 0
fill ~34 ~28 ~30 ~34 ~29 ~30 stone 0
fill ~14 ~29 ~21 ~18 ~29 ~21 gold_block 0
fill ~14 ~29 ~22 ~18 ~29 ~22 iron_block 0
fill ~14 ~29 ~23 ~18 ~29 ~23 gold_block 0
fill ~16 ~29 ~13 ~18 ~29 ~13 stone 0
fill ~16 ~29 ~31 ~18 ~29 ~31 stone 0
fill ~17 ~29 ~14 ~19 ~29 ~14 planks 0
fill ~17 ~29 ~30 ~19 ~29 ~30 planks 0
fill ~20 ~29 ~14 ~30 ~29 ~14 glass 0
fill ~20 ~29 ~29 ~30 ~29 ~29 planks 0
fill ~21 ~29 ~26 ~21 ~30 ~26 iron_block 0
fill ~21 ~29 ~27 ~21 ~30 ~27 gold_block 0
fill ~21 ~29 ~28 ~21 ~30 ~28 iron_block 0
fill ~25 ~29 ~21 ~25 ~31 ~21 gold_block 0
fill ~25 ~29 ~22 ~25 ~31 ~22 iron_block 0
fill ~25 ~29 ~23 ~25 ~31 ~23 gold_block 0
fill ~27 ~29 ~15 ~27 ~33 ~15 wool 12
fill ~29 ~29 ~21 ~29 ~32 ~21 gold_block 0
fill ~29 ~29 ~22 ~29 ~32 ~22 iron_block 0
fill ~29 ~29 ~23 ~29 ~32 ~23 gold_block 0
fill ~31 ~29 ~14 ~33 ~29 ~14 planks 0
fill ~31 ~29 ~30 ~33 ~29 ~30 planks 0
fill ~32 ~29 ~13 ~34 ~29 ~13 stone 0
fill ~32 ~29 ~31 ~34 ~29 ~31 stone 0
fill ~15 ~30 ~21 ~30 ~30 ~21 gold_block 0
fill ~15 ~30 ~22 ~30 ~30 ~22 iron_block 0
fill ~15 ~30 ~23 ~30 ~30 ~23 gold_block 0
fill ~16 ~30 ~13 ~16 ~32 ~13 stone 0
fill ~16 ~30 ~31 ~16 ~32 ~31 stone 0
setblock ~17 ~30 ~13 torch 4
fill ~17 ~30 ~14 ~19 ~30 ~14 planks 0
fill ~17 ~30 ~30 ~19 ~30 ~30 planks 0
fill ~18 ~30 ~13 ~18 ~32 ~13 stone 0
fill ~18 ~30 ~31 ~18 ~32 ~31 stone 0
fill ~20 ~30 ~14 ~30 ~30 ~14 glass 0
fill ~20 ~30 ~29 ~30 ~30 ~29 planks 0
fill ~22 ~30 ~26 ~22 ~39 ~26 iron_block 0
fill ~22 ~30 ~27 ~22 ~39 ~27 gold_block 0
fill ~22 ~30 ~28 ~22 ~39 ~28 iron_block 0
fill ~26 ~30 ~15 ~26 ~31 ~15 wool 12
fill ~28 ~30 ~15 ~28 ~31 ~15 wool 12
fill ~31 ~30 ~14 ~33 ~30 ~14 planks 0
fill ~31 ~30 ~30 ~33 ~30 ~30 planks 0
fill ~32 ~30 ~13 ~32 ~32 ~13 stone 0
fill ~32 ~30 ~31 ~32 ~32 ~31 stone 0
setblock ~33 ~30 ~13 torch 4
fill ~34 ~30 ~13 ~34 ~32 ~13 stone 0
fill ~34 ~30 ~31 ~34 ~32 ~31 stone 0
fill ~15 ~31 ~14 ~17 ~31 ~14 stone 0
fill ~15 ~31 ~21 ~31 ~31 ~21 gold_block 0
fill ~15 ~31 ~22 ~31 ~31 ~22 iron_block 0
fill ~15 ~31 ~23 ~31 ~31 ~23 gold_block 0
fill ~15 ~31 ~30 ~17 ~31 ~30 stone 0
fill ~17 ~31 ~12 ~17 ~35 ~12 stone 0
fill ~17 ~31 ~13 ~17 ~32 ~13 stone 0
fill ~17 ~31 ~31 ~17 ~32 ~31 stone 0
fill ~17 ~31 ~32 ~17 ~35 ~32 stone 0
fill ~18 ~31 ~14 ~19 ~31 ~14 planks 0
fill ~18 ~31 ~30 ~19 ~31 ~30 planks 0
fill ~20 ~31 ~14 ~30 ~31 ~14 glass 0
fill ~20 ~31 ~29 ~30 ~31 ~29 planks 0
fill ~31 ~31 ~14 ~32 ~31 ~14 planks 0
fill ~31 ~31 ~30 ~32 ~31 ~30 planks 0
fill ~33 ~31 ~12 ~33 ~35 ~12 stone 0
fill ~33 ~31 ~13 ~33 ~32 ~13 stone 0
fill ~33 ~31 ~14 ~35 ~31 ~14 stone 0
fill ~33 ~31 ~30 ~35 ~31 ~30 stone 0
fill ~33 ~31 ~31 ~33 ~32 ~31 stone 0
fill ~33 ~31 ~32 ~33 ~35 ~32 stone 0
fill ~37 ~31 ~21 ~37 ~39 ~21 gold_block 0
fill ~37 ~31 ~22 ~37 ~39 ~22 iron_block 0
fill ~37 ~31 ~23 ~37 ~39 ~23 gold_block 0
fill ~7 ~32 ~26 ~7 ~34 ~26 iron_block 0
fill ~7 ~32 ~27 ~7 ~34 ~27 gold_block 0
fill ~7 ~32 ~28 ~7 ~34 ~28 iron_block 0
fill ~9 ~32 ~27 ~14 ~32 ~27 gold_block 0
fill ~13 ~32 ~21 ~18 ~32 ~21 gold_block 0
fill ~13 ~32 ~22 ~18 ~32 ~22 iron_block 0
fill ~13 ~32 ~23 ~18 ~32 ~23 gold_block 0
fill ~15 ~32 ~14 ~17 ~32 ~14 stone 0
fill ~15 ~32 ~30 ~17 ~32 ~30 stone 0
fill ~17 ~32 ~27 ~24 ~32 ~27 gold_block 0
fill ~18 ~32 ~14 ~19 ~32 ~14 planks 0
fill ~18 ~32 ~30 ~19 ~32 ~30 planks 0
fill ~20 ~32 ~14 ~30 ~32 ~14 glass 0
fill ~20 ~32 ~29 ~30 ~32 ~29 planks 0
fill ~23 ~32 ~22 ~23 ~46 ~22 gold_block 0
fill ~23 ~32 ~26 ~24 ~32 ~26 iron_block 0
fill ~23 ~32 ~28 ~24 ~32 ~28 iron_block 0
fill ~30 ~32 ~21 ~32 ~32 ~21 gold_block 0
fill ~30 ~32 ~22 ~32 ~32 ~22 iron_block 0
fill ~30 ~32 ~23 ~32 ~32 ~23 gold_block 0
fill ~31 ~32 ~14 ~32 ~32 ~14 planks 0
fill ~31 ~32 ~30 ~32 ~32 ~30 planks 0
fill ~33 ~32 ~14 ~35 ~32 ~14 stone 0
fill ~33 ~32 ~30 ~35 ~32 ~30 stone 0
fill ~36 ~32 ~21 ~36 ~37 ~21 gold_block 0
fill ~36 ~32 ~22 ~36 ~37 ~22 iron_block 0
fill ~36 ~32 ~23 ~36 ~37 ~23 gold_block 0
fill ~5 ~33 ~26 ~8 ~33 ~26 iron_block 0
fill ~5 ~33 ~27 ~8 ~33 ~27 gold_block 0
fill ~5 ~33 ~28 ~8 ~33 ~28 iron_block 0
fill ~9 ~33 ~27 ~14 ~33 ~27 iron_block 0
fill ~11 ~33 ~21 ~16 ~33 ~21 gold_block 0
fill ~11 ~33 ~22 ~16 ~33 ~22 iron_block 0
fill ~11 ~33 ~23 ~16 ~33 ~23 gold_block 0
fill ~15 ~33 ~14 ~15 ~35 ~14 stone 0
fill ~15 ~33 ~25 ~16 ~33 ~25 stone 0
fill ~15 ~33 ~26 ~15 ~33 ~30 stone 0
fill ~16 ~33 ~27 ~21 ~33 ~27 iron_block 0
setblock ~17 ~33 ~14 stone 0
setblock ~17 ~33 ~30 stone 0
fill ~18 ~33 ~14 ~19 ~33 ~14 planks 0
fill ~18 ~33 ~30 ~19 ~33 ~30 planks 0
fill ~20 ~33 ~14 ~30 ~33 ~14 glass 0
fill ~20 ~33 ~29 ~30 ~33 ~29 planks 0
fill ~23 ~33 ~26 ~25 ~33 ~26 iron_block 0
fill ~23 ~33 ~27 ~25 ~33 ~27 gold_block 0
fill ~23 ~33 ~28 ~25 ~33 ~28 iron_block 0
fill ~30 ~33 ~21 ~33 ~33 ~21 gold_block 0
fill ~30 ~33 ~22 ~32 ~33 ~22 iron_block 0
fill ~30 ~33 ~23 ~32 ~33 ~23 gold_block 0
fill ~31 ~33 ~14 ~32 ~33 ~14 planks 0
fill ~31 ~33 ~30 ~32 ~33 ~30 planks 0
fill ~33 ~33 ~14 ~33 ~31 ~14 stone 0
fill ~33 ~33 ~30 ~33 ~31 ~30 stone 0
fill ~35 ~33 ~14 ~35 ~35 ~14 stone 0
fill ~35 ~33 ~21 ~35 ~36 ~21 gold_block 0
fill ~35 ~33 ~22 ~35 ~38 ~22 iron_block 0
fill ~35 ~33 ~23 ~35 ~36 ~23 gold_block 0
fill ~35 ~33 ~30 ~35 ~35 ~30 stone 0
fill ~6 ~34 ~21 ~14 ~34 ~21 gold_block 0
fill ~6 ~34 ~22 ~14 ~34 ~22 iron_block 0
fill ~6 ~34 ~23 ~14 ~34 ~23 gold_block 0
setblock ~6 ~34 ~26 iron_block 0
setblock ~6 ~34 ~27 gold_block 0
setblock ~6 ~34 ~28 iron_block 0
fill ~9 ~34 ~27 ~14 ~34 ~27 gold_block 0
fill ~15 ~34 ~27 ~15 ~39 ~27 iron_block 0
fill ~15 ~34 ~30 ~16 ~34 ~30 stone 0
fill ~16 ~34 ~13 ~18 ~34 ~13 stone 0
fill ~16 ~34 ~14 ~16 ~35 ~14 stone 0
fill ~16 ~34 ~15 ~16 ~38 ~15 stone 0
fill ~16 ~34 ~27 ~23 ~34 ~27 gold_block 0
fill ~16 ~34 ~31 ~18 ~34 ~31 stone 0
fill ~17 ~34 ~14 ~19 ~34 ~14 planks 0
fill ~17 ~34 ~30 ~19 ~34 ~30 planks 0
fill ~20 ~34 ~14 ~30 ~34 ~14 glass 0
fill ~20 ~34 ~29 ~30 ~34 ~29 planks 0
fill ~23 ~34 ~26 ~23 ~32 ~26 iron_block 0
fill ~23 ~34 ~28 ~23 ~32 ~28 iron_block 0
fill ~27 ~34 ~15 ~27 ~55 ~15 fence 0
fill ~31 ~34 ~14 ~33 ~34 ~14 planks 0
fill ~31 ~34 ~30 ~33 ~34 ~30 planks 0
fill ~32 ~34 ~13 ~34 ~34 ~13 stone 0
fill ~32 ~34 ~21 ~37 ~34 ~21 gold_block 0
fill ~32 ~34 ~22 ~37 ~34 ~22 iron_block 0
fill ~32 ~34 ~23 ~37 ~34 ~23 gold_block 0
fill ~32 ~34 ~31 ~34 ~34 ~31 stone 0
fill ~34 ~34 ~14 ~34 ~35 ~14 stone 0
fill ~34 ~34 ~15 ~34 ~38 ~15 stone 0
fill ~34 ~34 ~29 ~34 ~38 ~29 stone 0
fill ~34 ~34 ~30 ~34 ~35 ~30 stone 0
fill ~7 ~35 ~21 ~12 ~35 ~21 gold_block 0
fill ~7 ~35 ~22 ~12 ~35 ~22 iron_block 0
fill ~7 ~35 ~23 ~12 ~35 ~23 gold_block 0
fill ~14 ~35 ~27 ~14 ~41 ~27 gold_block 0
fill ~15 ~35 ~30 ~16 ~35 ~30 stone 0
fill ~16 ~35 ~13 ~18 ~35 ~13 stone 0
fill ~16 ~35 ~27 ~16 ~42 ~27 gold_block 0
fill ~16 ~35 ~31 ~18 ~35 ~31 stone 0
fill ~17 ~35 ~14 ~19 ~35 ~14 planks 0
fill ~17 ~35 ~30 ~19 ~35 ~30 planks 0
fill ~20 ~35 ~14 ~30 ~35 ~14 glass 0
fill ~20 ~35 ~29 ~30 ~35 ~29 planks 0
fill ~31 ~35 ~14 ~33 ~35 ~14 planks 0
fill ~31 ~35 ~30 ~33 ~35 ~30 planks 0
fill ~32 ~35 ~13 ~34 ~35 ~13 stone 0
fill ~32 ~35 ~31 ~34 ~35 ~31 stone 0
setblock ~34 ~35 ~21 gold_block 0
fill ~34 ~35 ~22 ~34 ~36 ~22 iron_block 0
setblock ~34 ~35 ~23 gold_block 0
fill ~8 ~36 ~21 ~11 ~36 ~21 gold_block 0
fill ~8 ~36 ~22 ~13 ~36 ~22 iron_block 0
fill ~8 ~36 ~23 ~11 ~36 ~23 gold_block 0
fill ~9 ~36 ~26 ~9 ~40 ~26 iron_block 0
fill ~9 ~36 ~27 ~9 ~40 ~27 gold_block 0
fill ~9 ~36 ~28 ~9 ~40 ~28 iron_block 0
fill ~16 ~36 ~13 ~16 ~38 ~13 stone 0
fill ~16 ~36 ~31 ~16 ~38 ~31 stone 0
setblock ~17 ~36 ~13 torch 4
fill ~17 ~36 ~14 ~19 ~36 ~14 planks 0
fill ~17 ~36 ~30 ~19 ~36 ~30 planks 0
fill ~18 ~36 ~13 ~18 ~38 ~13 stone 0
fill ~18 ~36 ~31 ~18 ~38 ~31 stone 0
fill ~20 ~36 ~14 ~30 ~36 ~14 glass 0
fill ~20 ~36 ~29 ~30 ~36 ~29 planks 0
fill ~21 ~36 ~26 ~21 ~40 ~26 iron_block 0
fill ~21 ~36 ~27 ~21 ~40 ~27 gold_block 0
fill ~21 ~36 ~28 ~21 ~40 ~28 iron_block 0
fill ~31 ~36 ~14 ~33 ~36 ~14 planks 0
fill ~31 ~36 ~30 ~33 ~36 ~30 planks 0
fill ~32 ~36 ~13 ~32 ~38 ~13 stone 0
fill ~32 ~36 ~31 ~32 ~38 ~31 stone 0
setblock ~33 ~36 ~13 torch 4
fill ~33 ~36 ~22 ~33 ~37 ~22 iron_block 0
fill ~34 ~36 ~13 ~34 ~38 ~13 stone 0
fill ~34 ~36 ~31 ~34 ~38 ~31 stone 0
fill ~38 ~36 ~21 ~38 ~41 ~21 gold_block 0
fill ~38 ~36 ~22 ~38 ~41 ~22 iron_block 0
fill ~38 ~36 ~23 ~38 ~41 ~23 gold_block 0
fill ~8 ~37 ~21 ~10 ~37 ~21 gold_block 0
fill ~9 ~37 ~22 ~11 ~37 ~22 iron_block 0
fill ~9 ~37 ~23 ~10 ~37 ~23 gold_block 0
setblock ~12 ~37 ~22 gold_block 0
fill ~13 ~37 ~22 ~14 ~37 ~22 iron_block 0
fill ~15 ~37 ~14 ~17 ~37 ~14 stone 0
fill ~15 ~37 ~30 ~17 ~37 ~30 stone 0
fill ~17 ~37 ~12 ~17 ~41 ~12 stone 0
fill ~17 ~37 ~13 ~17 ~38 ~13 stone 0
fill ~17 ~37 ~31 ~17 ~38 ~31 stone 0
fill ~17 ~37 ~32 ~17 ~41 ~32 stone 0
fill ~18 ~37 ~14 ~19 ~37 ~14 planks 0
fill ~18 ~37 ~30 ~19 ~37 ~30 planks 0
fill ~20 ~37 ~14 ~30 ~37 ~14 glass 0
fill ~20 ~37 ~29 ~30 ~37 ~29 planks 0
fill ~23 ~37 ~15 ~23 ~41 ~15 wool 12
fill ~31 ~37 ~14 ~32 ~37 ~14 planks 0
fill ~31 ~37 ~30 ~32 ~37 ~30 planks 0
fill ~32 ~37 ~22 ~32 ~38 ~22 iron_block 0
fill ~33 ~37 ~12 ~33 ~41 ~12 stone 0
fill ~33 ~37 ~13 ~33 ~38 ~13 stone 0
fill ~33 ~37 ~14 ~35 ~37 ~14 stone 0
fill ~33 ~37 ~30 ~35 ~37 ~30 stone 0
fill ~33 ~37 ~31 ~33 ~38 ~31 stone 0
fill ~33 ~37 ~32 ~33 ~41 ~32 stone 0
setblock ~34 ~37 ~22 gold_block 0
fill ~7 ~38 ~26 ~10 ~38 ~26 iron_block 0
fill ~7 ~38 ~27 ~10 ~38 ~27 gold_block 0
fill ~7 ~38 ~28 ~10 ~38 ~28 iron_block 0
fill ~8 ~38 ~21 ~9 ~38 ~21 gold_block 0
fill ~8 ~38 ~22 ~9 ~38 ~22 iron_block 0
fill ~8 ~38 ~23 ~9 ~38 ~23 gold_block 0
fill ~11 ~38 ~22 ~12 ~38 ~22 iron_block 0
setblock ~13 ~38 ~22 gold_block 0
fill ~14 ~38 ~22 ~15 ~38 ~22 iron_block 0
fill ~15 ~38 ~14 ~17 ~38 ~14 stone 0
fill ~15 ~38 ~30 ~17 ~38 ~30 stone 0
fill ~18 ~38 ~14 ~19 ~38 ~14 planks 0
fill ~18 ~38 ~30 ~19 ~38 ~30 planks 0
fill ~20 ~38 ~14 ~30 ~38 ~14 glass 0
fill ~20 ~38 ~26 ~20 ~41 ~26 iron_block 0
fill ~20 ~38 ~27 ~20 ~41 ~27 gold_block 0
fill ~20 ~38 ~28 ~20 ~41 ~28 iron_block 0
fill ~20 ~38 ~29 ~30 ~38 ~29 planks 0
fill ~22 ~38 ~15 ~22 ~39 ~15 wool 12
fill ~24 ~38 ~15 ~24 ~39 ~15 wool 12
fill ~31 ~38 ~14 ~32 ~38 ~14 planks 0
fill ~31 ~38 ~22 ~31 ~39 ~22 iron_block 0
fill ~31 ~38 ~30 ~32 ~38 ~30 planks 0
fill ~33 ~38 ~14 ~35 ~38 ~14 stone 0
setblock ~33 ~38 ~22 gold_block 0
fill ~33 ~38 ~30 ~35 ~38 ~30 stone 0
fill ~34 ~38 ~22 ~34 ~39 ~22 iron_block 0
fill ~39 ~38 ~21 ~39 ~43 ~21 gold_block 0
fill ~39 ~38 ~22 ~39 ~43 ~22 iron_block 0
fill ~39 ~38 ~23 ~39 ~43 ~23 gold_block 0
fill ~43 ~38 ~21 ~43 ~41 ~21 gold_block 0
fill ~43 ~38 ~22 ~43 ~41 ~22 iron_block 0
fill ~43 ~38 ~23 ~43 ~41 ~23 gold_block 0
fill ~7 ~39 ~21 ~9 ~39 ~21 gold_block 0
fill ~7 ~39 ~22 ~9 ~39 ~22 iron_block 0
fill ~7 ~39 ~23 ~9 ~39 ~23 gold_block 0
setblock ~8 ~39 ~26 iron_block 0
setblock ~8 ~39 ~27 gold_block 0
setblock ~8 ~39 ~28 iron_block 0
fill ~10 ~39 ~26 ~12 ~39 ~26 iron_block 0
fill ~10 ~39 ~27 ~12 ~39 ~27 gold_block 0
fill ~10 ~39 ~28 ~12 ~39 ~28 iron_block 0
fill ~12 ~39 ~22 ~13 ~39 ~22 iron_block 0
setblock ~14 ~39 ~22 gold_block 0
fill ~15 ~39 ~14 ~15 ~41 ~14 stone 0
fill ~15 ~39 ~22 ~16 ~39 ~22 iron_block 0
fill ~15 ~39 ~30 ~15 ~41 ~30 stone 0
setblock ~17 ~39 ~14 stone 0
setblock ~17 ~39 ~30 stone 0
fill ~18 ~39 ~14 ~19 ~39 ~14 planks 0
fill ~18 ~39 ~26 ~22 ~39 ~26 iron_block 0
fill ~18 ~39 ~27 ~22 ~39 ~27 gold_block 0
fill ~18 ~39 ~28 ~22 ~39 ~28 iron_block 0
fill ~18 ~39 ~30 ~19 ~39 ~30 planks 0
fill ~20 ~39 ~14 ~30 ~39 ~14 glass 0
fill ~20 ~39 ~29 ~30 ~39 ~29 planks 0
fill ~30 ~39 ~22 ~30 ~40 ~22 iron_block 0
fill ~31 ~39 ~14 ~32 ~39 ~14 planks 0
fill ~31 ~39 ~30 ~32 ~39 ~30 planks 0
setblock ~32 ~39 ~22 gold_block 0
fill ~33 ~39 ~14 ~33 ~37 ~14 stone 0
fill ~33 ~39 ~22 ~33 ~40 ~22 iron_block 0
fill ~33 ~39 ~30 ~33 ~37 ~30 stone 0
fill ~35 ~39 ~14 ~35 ~41 ~14 stone 0
fill ~35 ~39 ~30 ~35 ~41 ~30 stone 0
fill ~42 ~39 ~21 ~42 ~43 ~21 gold_block 0
fill ~42 ~39 ~22 ~42 ~43 ~22 iron_block 0
fill ~42 ~39 ~23 ~42 ~43 ~23 gold_block 0
fill ~6 ~40 ~21 ~8 ~40 ~21 gold_block 0
fill ~6 ~40 ~22 ~8 ~40 ~22 iron_block 0
fill ~6 ~40 ~23 ~8 ~40 ~23 gold_block 0
fill ~10 ~40 ~26 ~18 ~40 ~26 iron_block 0
fill ~10 ~40 ~27 ~18 ~40 ~27 gold_block 0
fill ~10 ~40 ~28 ~18 ~40 ~28 iron_block 0
fill ~13 ~40 ~22 ~14 ~40 ~22 iron_block 0
setblock ~15 ~40 ~22 gold_block 0
fill ~16 ~40 ~13 ~18 ~40 ~13 stone 0
fill ~16 ~40 ~14 ~16 ~41 ~14 stone 0
fill ~16 ~40 ~15 ~16 ~44 ~15 stone 0
fill ~16 ~40 ~22 ~17 ~40 ~22 iron_block 0
fill ~16 ~40 ~29 ~16 ~44 ~29 stone 0
fill ~16 ~40 ~30 ~16 ~41 ~30 stone 0
fill ~16 ~40 ~31 ~18 ~40 ~31 stone 0
fill ~17 ~40 ~14 ~19 ~40 ~14 planks 0
fill ~17 ~40 ~30 ~19 ~40 ~30 planks 0
fill ~20 ~40 ~14 ~30 ~40 ~14 glass 0
fill ~20 ~40 ~29 ~30 ~40 ~29 planks 0
fill ~29 ~40 ~22 ~29 ~41 ~22 iron_block 0
fill ~31 ~40 ~14 ~33 ~40 ~14 planks 0
setblock ~31 ~40 ~22 gold_block 0
fill ~31 ~40 ~30 ~33 ~40 ~30 planks 0
fill ~32 ~40 ~13 ~34 ~40 ~13 stone 0
fill ~32 ~40 ~22 ~32 ~41 ~22 iron_block 0
fill ~32 ~40 ~31 ~34 ~40 ~31 stone 0
fill ~34 ~40 ~14 ~34 ~41 ~14 stone 0
fill ~34 ~40 ~15 ~34 ~44 ~15 stone 0
fill ~34 ~40 ~29 ~34 ~44 ~29 stone 0
fill ~34 ~40 ~30 ~34 ~41 ~30 stone 0
fill ~40 ~40 ~21 ~43 ~40 ~21 gold_block 0
fill ~40 ~40 ~22 ~43 ~40 ~22 iron_block 0
fill ~40 ~40 ~23 ~43 ~40 ~23 gold_block 0
fill ~5 ~41 ~21 ~8 ~41 ~21 gold_block 0
fill ~5 ~41 ~22 ~8 ~41 ~22 iron_block 0
fill ~5 ~41 ~23 ~8 ~41 ~23 gold_block 0
fill ~14 ~41 ~22 ~15 ~41 ~22 iron_block 0
fill ~14 ~41 ~26 ~16 ~41 ~26 iron_block 0
fill ~14 ~41 ~28 ~16 ~41 ~28 iron_block 0
fill ~15 ~41 ~27 ~15 ~43 ~27 gold_block 0
fill ~16 ~41 ~13 ~18 ~41 ~13 stone 0
setblock ~16 ~41 ~22 gold_block 0
fill ~16 ~41 ~31 ~18 ~41 ~31 stone 0
fill ~17 ~41 ~14 ~19 ~41 ~14 planks 0
fill ~17 ~41 ~22 ~18 ~41 ~22 iron_block 0
fill ~17 ~41 ~30 ~19 ~41 ~30 planks 0
fill ~20 ~41 ~14 ~30 ~41 ~14 glass 0
fill ~20 ~41 ~29 ~30 ~41 ~29 planks 0
fill ~28 ~41 ~22 ~28 ~42 ~22 iron_block 0
setblock ~30 ~41 ~22 gold_block 0
fill ~31 ~41 ~14 ~33 ~41 ~14 planks 0
fill ~31 ~41 ~22 ~31 ~42 ~22 iron_block 0
fill ~31 ~41 ~30 ~33 ~41 ~30 planks 0
fill ~32 ~41 ~13 ~34 ~41 ~13 stone 0
fill ~32 ~41 ~31 ~34 ~41 ~31 stone 0
fill ~40 ~41 ~21 ~43 ~41 ~21 gold_block 0
fill ~40 ~41 ~22 ~43 ~41 ~22 iron_block 0
fill ~40 ~41 ~23 ~43 ~41 ~23 gold_block 0
fill ~4 ~42 ~21 ~7 ~42 ~21 gold_block 0
fill ~4 ~42 ~22 ~7 ~42 ~22 iron_block 0
fill ~4 ~42 ~23 ~7 ~42 ~23 gold_block 0
fill ~15 ~42 ~22 ~16 ~42 ~22 iron_block 0
fill ~15 ~42 ~26 ~16 ~42 ~26 iron_block 0
fill ~15 ~42 ~28 ~16 ~42 ~28 iron_block 0
fill ~16 ~42 ~13 ~16 ~44 ~13 stone 0
fill ~16 ~42 ~31 ~16 ~44 ~31 stone 0
setblock ~17 ~42 ~13 torch 4
fill ~17 ~42 ~14 ~19 ~42 ~14 planks 0
setblock ~17 ~42 ~22 gold_block 0
fill ~17 ~42 ~30 ~19 ~42 ~30 planks 0
fill ~18 ~42 ~13 ~18 ~44 ~13 stone 0
fill ~18 ~42 ~22 ~19 ~42 ~22 iron_block 0
fill ~18 ~42 ~31 ~18 ~44 ~31 stone 0
fill ~20 ~42 ~14 ~30 ~42 ~14 glass 0
fill ~20 ~42 ~29 ~30 ~42 ~29 planks 0
fill ~23 ~42 ~15 ~23 ~55 ~15 fence 0
fill ~27 ~42 ~22 ~27 ~43 ~22 iron_block 0
setblock ~29 ~42 ~22 gold_block 0
fill ~30 ~42 ~22 ~30 ~43 ~22 iron_block 0
fill ~31 ~42 ~14 ~33 ~42 ~14 planks 0
fill ~31 ~42 ~30 ~33 ~42 ~30 planks 0
fill ~32 ~42 ~13 ~32 ~44 ~13 stone 0
fill ~32 ~42 ~31 ~32 ~44 ~31 stone 0
setblock ~33 ~42 ~13 torch 4
fill ~34 ~42 ~13 ~34 ~44 ~13 stone 0
fill ~34 ~42 ~31 ~34 ~44 ~31 stone 0
fill ~40 ~42 ~21 ~42 ~42 ~21 gold_block 0
fill ~40 ~42 ~22 ~42 ~42 ~22 iron_block 0
fill ~40 ~42 ~23 ~42 ~42 ~23 gold_block 0
fill ~3 ~43 ~21 ~7 ~43 ~21 gold_block 0
fill ~3 ~43 ~22 ~7 ~43 ~22 iron_block 0
fill ~3 ~43 ~23 ~7 ~43 ~23 gold_block 0
fill ~15 ~43 ~14 ~17 ~43 ~14 stone 0
fill ~15 ~43 ~26 ~15 ~40 ~26 iron_block 0
fill ~15 ~43 ~28 ~15 ~40 ~28 iron_block 0
fill ~15 ~43 ~30 ~17 ~43 ~30 stone 0
fill ~16 ~43 ~22 ~17 ~43 ~22 iron_block 0
fill ~17 ~43 ~12 ~17 ~47 ~12 stone 0
fill ~17 ~43 ~13 ~17 ~44 ~13 stone 0
fill ~17 ~43 ~31 ~17 ~44 ~31 stone 0
fill ~17 ~43 ~32 ~17 ~47 ~32 stone 0
fill ~18 ~43 ~14 ~19 ~43 ~14 planks 0
setblock ~18 ~43 ~22 gold_block 0
fill ~18 ~43 ~30 ~19 ~43 ~30 planks 0
fill ~19 ~43 ~22 ~20 ~43 ~22 iron_block 0
fill ~20 ~43 ~14 ~30 ~43 ~14 glass 0
fill ~20 ~43 ~29 ~30 ~43 ~29 planks 0
fill ~26 ~43 ~22 ~26 ~44 ~22 iron_block 0
setblock ~28 ~43 ~22 gold_block 0
fill ~29 ~43 ~22 ~29 ~44 ~22 iron_block 0
fill ~31 ~43 ~14 ~32 ~43 ~14 planks 0
fill ~31 ~43 ~30 ~32 ~43 ~30 planks 0
fill ~33 ~43 ~12 ~33 ~47 ~12 stone 0
fill ~33 ~43 ~13 ~33 ~44 ~13 stone 0
fill ~33 ~43 ~14 ~35 ~43 ~14 stone 0
fill ~33 ~43 ~30 ~35 ~43 ~30 stone 0
fill ~33 ~43 ~31 ~33 ~44 ~31 stone 0
fill ~33 ~43 ~32 ~33 ~47 ~32 stone 0
fill ~40 ~43 ~21 ~42 ~43 ~21 gold_block 0
fill ~40 ~43 ~22 ~42 ~43 ~22 iron_block 0
fill ~40 ~43 ~23 ~42 ~43 ~23 gold_block 0
fill ~5 ~44 ~21 ~6 ~44 ~21 gold_block 0
fill ~5 ~44 ~22 ~6 ~44 ~22 iron_block 0
fill ~5 ~44 ~23 ~6 ~44 ~23 gold_block 0
fill ~15 ~44 ~14 ~17 ~44 ~14 stone 0
fill ~15 ~44 ~30 ~17 ~44 ~30 stone 0
fill ~17 ~44 ~22 ~18 ~44 ~22 iron_block 0
fill ~18 ~44 ~14 ~19 ~44 ~14 planks 0
fill ~18 ~44 ~30 ~19 ~44 ~30 planks 0
setblock ~19 ~44 ~22 gold_block 0
fill ~20 ~44 ~14 ~30 ~44 ~14 glass 0
fill ~20 ~44 ~22 ~22 ~44 ~22 iron_block 0
fill ~20 ~44 ~29 ~30 ~44 ~29 planks 0
fill ~25 ~44 ~22 ~25 ~45 ~22 iron_block 0
setblock ~27 ~44 ~22 gold_block 0
fill ~28 ~44 ~22 ~28 ~45 ~22 iron_block 0
fill ~31 ~44 ~14 ~32 ~44 ~14 planks 0
fill ~31 ~44 ~30 ~32 ~44 ~30 planks 0
fill ~33 ~44 ~14 ~35 ~44 ~14 stone 0
fill ~33 ~44 ~30 ~35 ~44 ~30 stone 0
fill ~40 ~44 ~21 ~41 ~44 ~21 gold_block 0
fill ~40 ~44 ~22 ~41 ~44 ~22 iron_block 0
fill ~40 ~44 ~23 ~41 ~44 ~23 gold_block 0
fill ~5 ~45 ~21 ~6 ~45 ~21 gold_block 0
fill ~5 ~45 ~22 ~6 ~45 ~22 iron_block 0
fill ~5 ~45 ~23 ~6 ~45 ~23 gold_block 0
fill ~15 ~45 ~14 ~15 ~47 ~14 stone 0
fill ~15 ~45 ~30 ~15 ~47 ~30 stone 0
setblock ~17 ~45 ~14 stone 0
fill ~17 ~45 ~26 ~17 ~76 ~26 planks 0
fill ~17 ~45 ~27 ~17 ~76 ~27 planks 0
fill ~17 ~45 ~28 ~17 ~76 ~28 planks 0
setblock ~17 ~45 ~30 stone 0
fill ~18 ~45 ~14 ~19 ~45 ~14 planks 0
fill ~18 ~45 ~22 ~19 ~45 ~22 iron_block 0
fill ~18 ~45 ~30 ~19 ~45 ~30 planks 0
fill ~20 ~45 ~14 ~30 ~45 ~14 glass 0
setblock ~20 ~45 ~22 gold_block 0
fill ~20 ~45 ~29 ~30 ~45 ~29 planks 0
setblock ~21 ~45 ~22 iron_block 0
setblock ~26 ~45 ~22 gold_block 0
fill ~27 ~45 ~22 ~27 ~47 ~22 iron_block 0
fill ~31 ~45 ~14 ~32 ~45 ~14 planks 0
fill ~31 ~45 ~30 ~32 ~45 ~30 planks 0
fill ~33 ~45 ~14 ~33 ~43 ~14 stone 0
fill ~33 ~45 ~30 ~33 ~43 ~30 stone 0
fill ~35 ~45 ~14 ~35 ~47 ~14 stone 0
fill ~35 ~45 ~30 ~35 ~47 ~30 stone 0
fill ~40 ~45 ~21 ~41 ~45 ~21 gold_block 0
fill ~40 ~45 ~22 ~41 ~45 ~22 iron_block 0
fill ~40 ~45 ~23 ~41 ~45 ~23 gold_block 0
fill ~4 ~46 ~21 ~6 ~46 ~21 gold_block 0
fill ~4 ~46 ~22 ~6 ~46 ~22 iron_block 0
fill ~4 ~46 ~23 ~6 ~46 ~23 gold_block 0
fill ~16 ~46 ~13 ~18 ~46 ~13 stone 0
fill ~16 ~46 ~14 ~16 ~47 ~14 stone 0
fill ~16 ~46 ~15 ~16 ~50 ~15 stone 0
fill ~16 ~46 ~29 ~16 ~50 ~29 stone 0
fill ~16 ~46 ~30 ~16 ~47 ~30 stone 0
fill ~16 ~46 ~31 ~18 ~46 ~31 stone 0
fill ~17 ~46 ~14 ~19 ~46 ~14 planks 0
fill ~17 ~46 ~30 ~19 ~46 ~30 planks 0
fill ~19 ~46 ~22 ~20 ~46 ~22 iron_block 0
fill ~20 ~46 ~14 ~30 ~46 ~14 glass 0
fill ~20 ~46 ~29 ~30 ~46 ~29 planks 0
setblock ~21 ~46 ~22 gold_block 0
setblock ~25 ~46 ~22 gold_block 0
fill ~26 ~46 ~22 ~26 ~47 ~22 iron_block 0
fill ~31 ~46 ~14 ~33 ~46 ~14 planks 0
fill ~31 ~46 ~30 ~33 ~46 ~30 planks 0
fill ~32 ~46 ~13 ~34 ~46 ~13 stone 0
fill ~32 ~46 ~31 ~34 ~46 ~31 stone 0
fill ~34 ~46 ~14 ~34 ~47 ~14 stone 0
fill ~34 ~46 ~15 ~34 ~50 ~15 stone 0
fill ~34 ~46 ~29 ~34 ~50 ~29 stone 0
fill ~34 ~46 ~30 ~34 ~47 ~30 stone 0
fill ~40 ~46 ~21 ~41 ~46 ~21 gold_block 0
fill ~40 ~46 ~22 ~41 ~46 ~22 iron_block 0
fill ~40 ~46 ~23 ~41 ~46 ~23 gold_block 0
fill ~3 ~47 ~21 ~6 ~47 ~21 gold_block 0
fill ~3 ~47 ~22 ~21 ~47 ~22 iron_block 0
fill ~3 ~47 ~23 ~6 ~47 ~23 gold_block 0
fill ~16 ~47 ~13 ~18 ~47 ~13 stone 0
fill ~16 ~47 ~31 ~18 ~47 ~31 stone 0
fill ~17 ~47 ~14 ~19 ~47 ~14 planks 0
fill ~17 ~47 ~30 ~19 ~47 ~30 planks 0
fill ~20 ~47 ~14 ~30 ~47 ~14 glass 0
fill ~20 ~47 ~29 ~30 ~47 ~29 planks 0
setblock ~22 ~47 ~22 gold_block 0
fill ~23 ~47 ~21 ~23 ~49 ~21 planks 0
fill ~23 ~47 ~22 ~23 ~49 ~22 planks 0
fill ~23 ~47 ~23 ~23 ~49 ~23 planks 0
fill ~23 ~47 ~24 ~23 ~49 ~24 planks 0
setblock ~24 ~47 ~22 gold_block 0
setblock ~25 ~47 ~22 iron_block 0
fill ~28 ~47 ~22 ~45 ~47 ~22 iron_block 0
fill ~31 ~47 ~14 ~33 ~47 ~14 planks 0
fill ~31 ~47 ~30 ~33 ~47 ~30 planks 0
fill ~32 ~47 ~13 ~34 ~47 ~13 stone 0
fill ~32 ~47 ~31 ~34 ~47 ~31 stone 0
fill ~40 ~47 ~21 ~45 ~47 ~21 gold_block 0
fill ~40 ~47 ~23 ~45 ~47 ~23 gold_block 0
fill ~2 ~48 ~21 ~6 ~48 ~21 gold_block 0
fill ~2 ~48 ~22 ~6 ~48 ~22 iron_block 0
fill ~2 ~48 ~23 ~6 ~48 ~23 gold_block 0
fill ~7 ~48 ~22 ~21 ~48 ~22 gold_block 0
fill ~16 ~48 ~13 ~16 ~50 ~13 stone 0
fill ~16 ~48 ~31 ~16 ~50 ~31 stone 0
setblock ~17 ~48 ~13 torch 4
fill ~17 ~48 ~14 ~19 ~48 ~14 planks 0
fill ~17 ~48 ~30 ~19 ~48 ~30 planks 0
fill ~18 ~48 ~13 ~18 ~50 ~13 stone 0
fill ~18 ~48 ~31 ~18 ~50 ~31 stone 0
fill ~20 ~48 ~14 ~30 ~48 ~14 glass 0
fill ~20 ~48 ~29 ~30 ~48 ~29 planks 0
fill ~22 ~48 ~21 ~22 ~48 ~24 planks 0
fill ~24 ~48 ~21 ~24 ~48 ~24 planks 0
fill ~25 ~48 ~22 ~39 ~48 ~22 gold_block 0
fill ~31 ~48 ~14 ~33 ~48 ~14 planks 0
fill ~31 ~48 ~30 ~33 ~48 ~30 planks 0
fill ~32 ~48 ~13 ~32 ~50 ~13 stone 0
fill ~32 ~48 ~31 ~32 ~50 ~31 stone 0
setblock ~33 ~48 ~13 torch 4
fill ~34 ~48 ~13 ~34 ~50 ~13 stone 0
fill ~34 ~48 ~31 ~34 ~50 ~31 stone 0
fill ~40 ~48 ~21 ~44 ~48 ~21 gold_block 0
fill ~40 ~48 ~22 ~44 ~48 ~22 iron_block 0
fill ~40 ~48 ~23 ~44 ~48 ~23 gold_block 0
fill ~1 ~49 ~21 ~6 ~49 ~21 gold_block 0
fill ~1 ~49 ~22 ~21 ~49 ~22 iron_block 0
fill ~1 ~49 ~23 ~6 ~49 ~23 gold_block 0
fill ~15 ~49 ~14 ~17 ~49 ~14 stone 0
fill ~15 ~49 ~30 ~17 ~49 ~30 stone 0
fill ~17 ~49 ~12 ~17 ~53 ~12 stone 0
fill ~17 ~49 ~13 ~17 ~50 ~13 stone 0
fill ~17 ~49 ~31 ~17 ~50 ~31 stone 0
fill ~17 ~49 ~32 ~17 ~53 ~32 stone 0
fill ~18 ~49 ~14 ~19 ~49 ~14 planks 0
fill ~18 ~49 ~30 ~19 ~49 ~30 planks 0
fill ~20 ~49 ~14 ~30 ~49 ~14 glass 0
fill ~20 ~49 ~29 ~30 ~49 ~29 planks 0
setblock ~22 ~49 ~22 gold_block 0
setblock ~24 ~49 ~22 gold_block 0
fill ~25 ~49 ~22 ~43 ~49 ~22 iron_block 0
fill ~31 ~49 ~14 ~32 ~49 ~14 planks 0
fill ~31 ~49 ~30 ~32 ~49 ~30 planks 0
fill ~33 ~49 ~12 ~33 ~53 ~12 stone 0
fill ~33 ~49 ~13 ~33 ~50 ~13 stone 0
fill ~33 ~49 ~14 ~35 ~49 ~14 stone 0
fill ~33 ~49 ~30 ~35 ~49 ~30 stone 0
fill ~33 ~49 ~31 ~33 ~50 ~31 stone 0
fill ~33 ~49 ~32 ~33 ~53 ~32 stone 0
fill ~40 ~49 ~21 ~43 ~49 ~21 gold_block 0
fill ~40 ~49 ~23 ~43 ~49 ~23 gold_block 0
fill ~5 ~50 ~21 ~6 ~50 ~21 gold_block 0
fill ~5 ~50 ~22 ~6 ~50 ~22 iron_block 0
fill ~5 ~50 ~23 ~6 ~50 ~23 gold_block 0
fill ~15 ~50 ~14 ~17 ~50 ~14 stone 0
fill ~15 ~50 ~30 ~17 ~50 ~30 stone 0
fill ~18 ~50 ~14 ~19 ~50 ~14 planks 0
fill ~18 ~50 ~30 ~19 ~50 ~30 planks 0
fill ~19 ~50 ~22 ~20 ~50 ~22 iron_block 0
fill ~20 ~50 ~14 ~30 ~50 ~14 glass 0
fill ~20 ~50 ~29 ~30 ~50 ~29 planks 0
setblock ~21 ~50 ~22 gold_block 0
fill ~22 ~50 ~22 ~22 ~68 ~22 iron_block 0
fill ~23 ~50 ~22 ~23 ~64 ~22 gold_block 0
fill ~24 ~50 ~22 ~24 ~70 ~22 iron_block 0
setblock ~25 ~50 ~22 gold_block 0
fill ~26 ~50 ~22 ~27 ~50 ~22 iron_block 0
fill ~31 ~50 ~14 ~32 ~50 ~14 planks 0
fill ~31 ~50 ~30 ~32 ~50 ~30 planks 0
fill ~33 ~50 ~14 ~35 ~50 ~14 stone 0
fill ~33 ~50 ~30 ~35 ~50 ~30 stone 0
fill ~40 ~50 ~21 ~42 ~50 ~21 gold_block 0
fill ~40 ~50 ~22 ~42 ~50 ~22 iron_block 0
fill ~40 ~50 ~23 ~42 ~50 ~23 gold_block 0
fill ~5 ~51 ~21 ~6 ~51 ~21 gold_block 0
fill ~5 ~51 ~22 ~6 ~51 ~22 iron_block 0
fill ~5 ~51 ~23 ~6 ~51 ~23 gold_block 0
fill ~15 ~51 ~14 ~15 ~53 ~14 stone 0
fill ~15 ~51 ~30 ~15 ~53 ~30 stone 0
setblock ~17 ~51 ~14 stone 0
setblock ~17 ~51 ~30 stone 0
fill ~18 ~51 ~14 ~19 ~51 ~14 planks 0
fill ~18 ~51 ~22 ~19 ~51 ~22 iron_block 0
fill ~18 ~51 ~30 ~19 ~51 ~30 planks 0
fill ~20 ~51 ~14 ~30 ~51 ~14 glass 0
setblock ~20 ~51 ~22 gold_block 0
fill ~20 ~51 ~29 ~30 ~51 ~29 planks 0
fill ~21 ~51 ~22 ~21 ~52 ~22 iron_block 0
fill ~25 ~51 ~22 ~25 ~52 ~22 iron_block 0
setblock ~26 ~51 ~22 gold_block 0
fill ~27 ~51 ~22 ~28 ~51 ~22 iron_block 0
fill ~31 ~51 ~14 ~32 ~51 ~14 planks 0
fill ~31 ~51 ~30 ~32 ~51 ~30 planks 0
fill ~33 ~51 ~14 ~33 ~49 ~14 stone 0
fill ~33 ~51 ~30 ~33 ~49 ~30 stone 0
fill ~35 ~51 ~14 ~35 ~53 ~14 stone 0
fill ~35 ~51 ~30 ~35 ~53 ~30 stone 0
fill ~40 ~51 ~21 ~41 ~51 ~21 gold_block 0
fill ~40 ~51 ~22 ~41 ~51 ~22 iron_block 0
fill ~40 ~51 ~23 ~41 ~51 ~23 gold_block 0
fill ~5 ~52 ~21 ~6 ~52 ~21 gold_block 0
fill ~5 ~52 ~22 ~6 ~52 ~22 iron_block 0
fill ~5 ~52 ~23 ~6 ~52 ~23 gold_block 0
fill ~16 ~52 ~13 ~18 ~52 ~13 stone 0
fill ~16 ~52 ~14 ~16 ~53 ~14 stone 0
fill ~16 ~52 ~15 ~16 ~56 ~15 stone 0
fill ~16 ~52 ~29 ~16 ~56 ~29 stone 0
fill ~16 ~52 ~30 ~16 ~53 ~30 stone 0
fill ~16 ~52 ~31 ~18 ~52 ~31 stone 0
fill ~17 ~52 ~14 ~19 ~52 ~14 planks 0
fill ~17 ~52 ~22 ~18 ~52 ~22 iron_block 0
fill ~17 ~52 ~30 ~19 ~52 ~30 planks 0
setblock ~19 ~52 ~22 gold_block 0
fill ~20 ~52 ~14 ~30 ~52 ~14 glass 0
fill ~20 ~52 ~22 ~20 ~53 ~22 iron_block 0
fill ~20 ~52 ~29 ~30 ~52 ~29 planks 0
fill ~26 ~52 ~22 ~26 ~53 ~22 iron_block 0
setblock ~27 ~52 ~22 gold_block 0
fill ~28 ~52 ~22 ~29 ~52 ~22 iron_block 0
fill ~31 ~52 ~14 ~33 ~52 ~14 planks 0
fill ~31 ~52 ~30 ~33 ~52 ~30 planks 0
fill ~32 ~52 ~13 ~34 ~52 ~13 stone 0
fill ~32 ~52 ~31 ~34 ~52 ~31 stone 0
fill ~34 ~52 ~14 ~34 ~53 ~14 stone 0
fill ~34 ~52 ~15 ~34 ~56 ~15 stone 0
fill ~34 ~52 ~29 ~34 ~56 ~29 stone 0
fill ~34 ~52 ~30 ~34 ~53 ~30 stone 0
fill ~40 ~52 ~21 ~41 ~52 ~21 gold_block 0
fill ~40 ~52 ~22 ~41 ~52 ~22 iron_block 0
fill ~40 ~52 ~23 ~41 ~52 ~23 gold_block 0
fill ~4 ~53 ~21 ~7 ~53 ~21 gold_block 0
fill ~4 ~53 ~22 ~7 ~53 ~22 iron_block 0
fill ~4 ~53 ~23 ~7 ~53 ~23 gold_block 0
fill ~16 ~53 ~13 ~18 ~53 ~13 stone 0
fill ~16 ~53 ~22 ~17 ~53 ~22 iron_block 0
fill ~16 ~53 ~31 ~18 ~53 ~31 stone 0
fill ~17 ~53 ~14 ~19 ~53 ~14 planks 0
fill ~17 ~53 ~30 ~19 ~53 ~30 planks 0
setblock ~18 ~53 ~22 gold_block 0
fill ~19 ~53 ~22 ~19 ~54 ~22 iron_block 0
fill ~20 ~53 ~14 ~30 ~53 ~14 glass 0
fill ~20 ~53 ~29 ~30 ~53 ~29 planks 0
fill ~21 ~53 ~15 ~21 ~55 ~15 planks 0
fill ~27 ~53 ~22 ~27 ~54 ~22 iron_block 0
setblock ~28 ~53 ~22 gold_block 0
fill ~29 ~53 ~15 ~29 ~55 ~15 planks 0
fill ~29 ~53 ~22 ~30 ~53 ~22 iron_block 0
fill ~31 ~53 ~14 ~33 ~53 ~14 planks 0
fill ~31 ~53 ~30 ~33 ~53 ~30 planks 0
fill ~32 ~53 ~13 ~34 ~53 ~13 stone 0
fill ~32 ~53 ~31 ~34 ~53 ~31 stone 0
fill ~39 ~53 ~21 ~43 ~53 ~21 gold_block 0
fill ~39 ~53 ~22 ~43 ~53 ~22 iron_block 0
fill ~39 ~53 ~23 ~43 ~53 ~23 gold_block 0
fill ~4 ~54 ~21 ~7 ~54 ~21 gold_block 0
fill ~4 ~54 ~22 ~7 ~54 ~22 iron_block 0
fill ~4 ~54 ~23 ~7 ~54 ~23 gold_block 0
fill ~15 ~54 ~22 ~16 ~54 ~22 iron_block 0
fill ~16 ~54 ~13 ~16 ~56 ~13 stone 0
fill ~16 ~54 ~31 ~16 ~56 ~31 stone 0
setblock ~17 ~54 ~13 torch 4
fill ~17 ~54 ~14 ~20 ~54 ~14 planks 0
setblock ~17 ~54 ~22 gold_block 0
fill ~17 ~54 ~30 ~19 ~54 ~30 planks 0
fill ~18 ~54 ~13 ~18 ~56 ~13 stone 0
fill ~18 ~54 ~22 ~18 ~55 ~22 iron_block 0
fill ~18 ~54 ~31 ~18 ~56 ~31 stone 0
fill ~20 ~54 ~29 ~30 ~54 ~29 planks 0
fill ~21 ~54 ~14 ~29 ~54 ~14 glass 0
fill ~28 ~54 ~22 ~28 ~55 ~22 iron_block 0
setblock ~29 ~54 ~22 gold_block 0
fill ~30 ~54 ~14 ~33 ~54 ~14 planks 0
fill ~30 ~54 ~22 ~31 ~54 ~22 iron_block 0
fill ~31 ~54 ~30 ~33 ~54 ~30 planks 0
fill ~32 ~54 ~13 ~32 ~56 ~13 stone 0
fill ~32 ~54 ~31 ~32 ~56 ~31 stone 0
setblock ~33 ~54 ~13 torch 4
fill ~34 ~54 ~13 ~34 ~56 ~13 stone 0
fill ~34 ~54 ~31 ~34 ~56 ~31 stone 0
fill ~39 ~54 ~21 ~42 ~54 ~21 gold_block 0
fill ~39 ~54 ~22 ~42 ~54 ~22 iron_block 0
fill ~39 ~54 ~23 ~42 ~54 ~23 gold_block 0
fill ~3 ~55 ~21 ~8 ~55 ~21 gold_block 0
fill ~3 ~55 ~22 ~8 ~55 ~22 iron_block 0
fill ~3 ~55 ~23 ~8 ~55 ~23 gold_block 0
fill ~14 ~55 ~22 ~15 ~55 ~22 iron_block 0
fill ~15 ~55 ~14 ~17 ~55 ~14 stone 0
fill ~15 ~55 ~30 ~17 ~55 ~30 stone 0
setblock ~16 ~55 ~22 gold_block 0
fill ~17 ~55 ~12 ~17 ~59 ~12 stone 0
fill ~17 ~55 ~13 ~17 ~56 ~13 stone 0
fill ~17 ~55 ~22 ~17 ~56 ~22 iron_block 0
fill ~17 ~55 ~31 ~17 ~56 ~31 stone 0
fill ~17 ~55 ~32 ~17 ~59 ~32 stone 0
fill ~18 ~55 ~14 ~20 ~55 ~14 planks 0
fill ~18 ~55 ~30 ~19 ~55 ~30 planks 0
fill ~19 ~55 ~13 ~19 ~63 ~13 wool 12
fill ~20 ~55 ~29 ~30 ~55 ~29 planks 0
fill ~21 ~55 ~14 ~29 ~55 ~14 glass 0
fill ~22 ~55 ~15 ~22 ~56 ~15 planks 0
fill ~28 ~55 ~15 ~28 ~56 ~15 planks 0
fill ~29 ~55 ~22 ~29 ~56 ~22 iron_block 0
fill ~30 ~55 ~14 ~32 ~55 ~14 planks 0
setblock ~30 ~55 ~22 gold_block 0
fill ~31 ~55 ~13 ~31 ~63 ~13 wool 12
fill ~31 ~55 ~22 ~32 ~55 ~22 iron_block 0
fill ~31 ~55 ~30 ~32 ~55 ~30 planks 0
fill ~32 ~55 ~16 ~32 ~57 ~16 iron_block 0
fill ~32 ~55 ~17 ~32 ~63 ~17 gold_block 0
fill ~32 ~55 ~18 ~32 ~57 ~18 iron_block 0
fill ~33 ~55 ~12 ~33 ~59 ~12 stone 0
fill ~33 ~55 ~13 ~33 ~56 ~13 stone 0
fill ~33 ~55 ~14 ~35 ~55 ~14 stone 0
fill ~33 ~55 ~30 ~35 ~55 ~30 stone 0
fill ~33 ~55 ~31 ~33 ~56 ~31 stone 0
fill ~33 ~55 ~32 ~33 ~59 ~32 stone 0
fill ~38 ~55 ~21 ~41 ~55 ~21 gold_block 0
fill ~38 ~55 ~22 ~41 ~55 ~22 iron_block 0
fill ~38 ~55 ~23 ~41 ~55 ~23 gold_block 0
fill ~3 ~56 ~21 ~8 ~56 ~21 gold_block 0
fill ~3 ~56 ~22 ~8 ~56 ~22 iron_block 0
fill ~3 ~56 ~23 ~8 ~56 ~23 gold_block 0
fill ~13 ~56 ~22 ~14 ~56 ~22 iron_block 0
fill ~15 ~56 ~14 ~17 ~56 ~14 stone 0
setblock ~15 ~56 ~22 gold_block 0
fill ~15 ~56 ~30 ~17 ~56 ~30 stone 0
fill ~16 ~56 ~22 ~16 ~57 ~22 iron_block 0
fill ~18 ~56 ~14 ~21 ~56 ~14 planks 0
fill ~18 ~56 ~30 ~19 ~56 ~30 planks 0
fill ~20 ~56 ~29 ~30 ~56 ~29 planks 0
fill ~22 ~56 ~14 ~28 ~56 ~14 glass 0
fill ~23 ~56 ~15 ~24 ~56 ~15 planks 0
fill ~26 ~56 ~15 ~28 ~56 ~15 planks 0
fill ~28 ~56 ~16 ~28 ~59 ~16 iron_block 0
fill ~28 ~56 ~17 ~28 ~59 ~17 gold_block 0
fill ~28 ~56 ~18 ~28 ~59 ~18 iron_block 0
fill ~29 ~56 ~14 ~32 ~56 ~14 planks 0
fill ~30 ~56 ~22 ~30 ~57 ~22 iron_block 0
setblock ~31 ~56 ~22 gold_block 0
fill ~31 ~56 ~30 ~32 ~56 ~30 planks 0
fill ~32 ~56 ~22 ~33 ~56 ~22 iron_block 0
fill ~33 ~56 ~14 ~35 ~56 ~14 stone 0
fill ~33 ~56 ~16 ~34 ~56 ~16 iron_block 0
fill ~33 ~56 ~17 ~34 ~56 ~17 gold_block 0
fill ~33 ~56 ~18 ~34 ~56 ~18 iron_block 0
fill ~33 ~56 ~30 ~35 ~56 ~30 stone 0
fill ~38 ~56 ~21 ~40 ~56 ~21 gold_block 0
fill ~38 ~56 ~22 ~40 ~56 ~22 iron_block 0
fill ~38 ~56 ~23 ~40 ~56 ~23 gold_block 0
fill ~3 ~57 ~21 ~4 ~57 ~21 gold_block 0
fill ~3 ~57 ~22 ~4 ~57 ~22 iron_block 0
fill ~3 ~57 ~23 ~4 ~57 ~23 gold_block 0
fill ~7 ~57 ~21 ~9 ~57 ~21 gold_block 0
fill ~7 ~57 ~22 ~9 ~57 ~22 iron_block 0
fill ~7 ~57 ~23 ~9 ~57 ~23 gold_block 0
fill ~12 ~57 ~22 ~13 ~57 ~22 iron_block 0
setblock ~14 ~57 ~22 gold_block 0
fill ~15 ~57 ~14 ~15 ~59 ~14 stone 0
fill ~15 ~57 ~22 ~15 ~58 ~22 iron_block 0
fill ~15 ~57 ~30 ~15 ~59 ~30 stone 0
setblock ~17 ~57 ~14 stone 0
setblock ~17 ~57 ~30 stone 0
setblock ~18 ~57 ~13 wool 12
fill ~18 ~57 ~14 ~23 ~57 ~14 planks 0
fill ~18 ~57 ~30 ~19 ~57 ~30 planks 0
fill ~20 ~57 ~13 ~20 ~61 ~13 wool 12
fill ~20 ~57 ~29 ~30 ~57 ~29 planks 0
fill ~24 ~57 ~14 ~26 ~57 ~14 glass 0
fill ~24 ~57 ~15 ~26 ~57 ~15 planks 0
fill ~27 ~57 ~14 ~32 ~57 ~14 planks 0
fill ~27 ~57 ~16 ~27 ~61 ~16 iron_block 0
fill ~27 ~57 ~17 ~27 ~61 ~17 gold_block 0
fill ~27 ~57 ~18 ~27 ~61 ~18 iron_block 0
fill ~30 ~57 ~13 ~30 ~61 ~13 wool 12
fill ~30 ~57 ~16 ~39 ~57 ~16 iron_block 0
fill ~30 ~57 ~17 ~39 ~57 ~17 gold_block 0
fill ~30 ~57 ~18 ~39 ~57 ~18 iron_block 0
fill ~31 ~57 ~22 ~31 ~58 ~22 iron_block 0
fill ~31 ~57 ~30 ~32 ~57 ~30 planks 0
setblock ~32 ~57 ~13 wool 12
setblock ~32 ~57 ~22 gold_block 0
fill ~33 ~57 ~14 ~33 ~55 ~14 stone 0
fill ~33 ~57 ~22 ~34 ~57 ~22 iron_block 0
fill ~33 ~57 ~30 ~33 ~55 ~30 stone 0
fill ~35 ~57 ~14 ~35 ~59 ~14 stone 0
fill ~35 ~57 ~30 ~35 ~59 ~30 stone 0
fill ~37 ~57 ~21 ~39 ~57 ~21 gold_block 0
fill ~37 ~57 ~22 ~39 ~57 ~22 iron_block 0
fill ~37 ~57 ~23 ~39 ~57 ~23 gold_block 0
fill ~3 ~58 ~21 ~3 ~55 ~21 gold_block 0
fill ~3 ~58 ~22 ~3 ~55 ~22 iron_block 0
fill ~3 ~58 ~23 ~3 ~55 ~23 gold_block 0
fill ~7 ~58 ~21 ~9 ~58 ~21 gold_block 0
fill ~7 ~58 ~22 ~9 ~58 ~22 iron_block 0
fill ~7 ~58 ~23 ~9 ~58 ~23 gold_block 0
fill ~11 ~58 ~22 ~12 ~58 ~22 iron_block 0
setblock ~13 ~58 ~22 gold_block 0
fill ~14 ~58 ~22 ~14 ~59 ~22 iron_block 0
fill ~16 ~58 ~13 ~18 ~58 ~13 stone 0
fill ~16 ~58 ~14 ~16 ~59 ~14 stone 0
fill ~16 ~58 ~15 ~16 ~62 ~15 stone 0
fill ~16 ~58 ~29 ~16 ~62 ~29 stone 0
fill ~16 ~58 ~30 ~16 ~59 ~30 stone 0
fill ~16 ~58 ~31 ~18 ~58 ~31 stone 0
fill ~17 ~58 ~14 ~33 ~58 ~14 planks 0
fill ~17 ~58 ~30 ~19 ~58 ~30 planks 0
fill ~20 ~58 ~29 ~30 ~58 ~29 planks 0
fill ~21 ~58 ~13 ~22 ~58 ~13 wool 12
fill ~26 ~58 ~16 ~26 ~67 ~16 iron_block 0
fill ~26 ~58 ~17 ~26 ~67 ~17 gold_block 0
fill ~26 ~58 ~18 ~26 ~67 ~18 iron_block 0
fill ~28 ~58 ~13 ~31 ~58 ~13 wool 12
fill ~29 ~58 ~16 ~30 ~58 ~16 iron_block 0
fill ~29 ~58 ~17 ~30 ~58 ~17 gold_block 0
fill ~29 ~58 ~18 ~30 ~58 ~18 iron_block 0
fill ~31 ~58 ~30 ~33 ~58 ~30 planks 0
fill ~32 ~58 ~13 ~34 ~58 ~13 stone 0
fill ~32 ~58 ~22 ~32 ~59 ~22 iron_block 0
fill ~32 ~58 ~31 ~34 ~58 ~31 stone 0
fill ~33 ~58 ~17 ~33 ~63 ~17 iron_block 0
setblock ~33 ~58 ~22 gold_block 0
fill ~34 ~58 ~14 ~34 ~59 ~14 stone 0
fill ~34 ~58 ~15 ~34 ~62 ~15 stone 0
fill ~34 ~58 ~17 ~34 ~63 ~17 gold_block 0
fill ~34 ~58 ~22 ~35 ~58 ~22 iron_block 0
fill ~34 ~58 ~29 ~34 ~62 ~29 stone 0
fill ~34 ~58 ~30 ~34 ~59 ~30 stone 0
fill ~36 ~58 ~16 ~40 ~58 ~16 iron_block 0
fill ~36 ~58 ~17 ~40 ~58 ~17 gold_block 0
fill ~36 ~58 ~18 ~40 ~58 ~18 iron_block 0
fill ~37 ~58 ~21 ~38 ~58 ~21 gold_block 0
fill ~37 ~58 ~22 ~38 ~58 ~22 iron_block 0
fill ~37 ~58 ~23 ~38 ~58 ~23 gold_block 0
fill ~8 ~59 ~21 ~10 ~59 ~21 gold_block 0
fill ~8 ~59 ~22 ~11 ~59 ~22 iron_block 0
fill ~8 ~59 ~23 ~10 ~59 ~23 gold_block 0
setblock ~12 ~59 ~22 gold_block 0
fill ~13 ~59 ~22 ~13 ~60 ~22 iron_block 0
fill ~16 ~59 ~13 ~18 ~59 ~13 stone 0
fill ~16 ~59 ~31 ~18 ~59 ~31 stone 0
fill ~17 ~59 ~14 ~33 ~59 ~14 planks 0
fill ~17 ~59 ~30 ~19 ~59 ~30 planks 0
fill ~18 ~59 ~15 ~33 ~59 ~15 planks 0
fill ~20 ~59 ~29 ~30 ~59 ~29 planks 0
fill ~21 ~59 ~13 ~31 ~59 ~13 wool 12
fill ~31 ~59 ~30 ~33 ~59 ~30 planks 0
fill ~32 ~59 ~13 ~34 ~59 ~13 stone 0
fill ~32 ~59 ~31 ~34 ~59 ~31 stone 0
fill ~33 ~59 ~22 ~33 ~64 ~22 iron_block 0
setblock ~34 ~59 ~22 gold_block 0
fill ~35 ~59 ~22 ~37 ~59 ~22 iron_block 0
fill ~36 ~59 ~21 ~37 ~59 ~21 gold_block 0
fill ~36 ~59 ~23 ~37 ~59 ~23 gold_block 0
fill ~38 ~59 ~16 ~41 ~59 ~16 iron_block 0
fill ~38 ~59 ~17 ~41 ~59 ~17 gold_block 0
fill ~38 ~59 ~18 ~41 ~59 ~18 iron_block 0
fill ~8 ~60 ~21 ~11 ~60 ~21 gold_block 0
fill ~8 ~60 ~22 ~13 ~60 ~22 iron_block 0
fill ~8 ~60 ~23 ~11 ~60 ~23 gold_block 0
fill ~16 ~60 ~13 ~16 ~62 ~13 stone 0
fill ~16 ~60 ~31 ~16 ~62 ~31 stone 0
setblock ~17 ~60 ~13 torch 4
fill ~17 ~60 ~14 ~22 ~60 ~14 planks 0
fill ~17 ~60 ~30 ~19 ~60 ~30 planks 0
fill ~18 ~60 ~13 ~18 ~62 ~13 stone 0
fill ~18 ~60 ~15 ~33 ~60 ~15 planks 0
fill ~18 ~60 ~31 ~18 ~62 ~31 stone 0
fill ~20 ~60 ~29 ~30 ~60 ~29 planks 0
fill ~21 ~60 ~13 ~22 ~60 ~13 wool 12
fill ~23 ~60 ~14 ~27 ~60 ~14 iron_block 0
fill ~28 ~60 ~13 ~31 ~60 ~13 wool 12
fill ~28 ~60 ~14 ~33 ~60 ~14 planks 0
fill ~31 ~60 ~30 ~33 ~60 ~30 planks 0
fill ~32 ~60 ~13 ~32 ~62 ~13 stone 0
fill ~32 ~60 ~31 ~32 ~62 ~31 stone 0
setblock ~33 ~60 ~13 torch 4
fill ~34 ~60 ~13 ~34 ~62 ~13 stone 0
fill ~34 ~60 ~22 ~38 ~60 ~22 iron_block 0
fill ~34 ~60 ~31 ~34 ~62 ~31 stone 0
fill ~35 ~60 ~21 ~38 ~60 ~21 gold_block 0
