fill ~1 ~-3 ~1 ~69 ~-3 ~1 grass 0
fill ~1 ~-3 ~2 ~69 ~-3 ~2 grass 0
fill ~1 ~-3 ~3 ~69 ~-3 ~3 grass 0
fill ~1 ~-3 ~4 ~69 ~-3 ~4 grass 0
fill ~1 ~-3 ~5 ~69 ~-3 ~5 grass 0
fill ~1 ~-3 ~6 ~69 ~-3 ~6 grass 0
fill ~1 ~-3 ~7 ~69 ~-3 ~7 grass 0
fill ~1 ~-3 ~8 ~69 ~-3 ~8 grass 0
fill ~1 ~-3 ~9 ~69 ~-3 ~9 grass 0
fill ~1 ~-3 ~10 ~69 ~-3 ~10 grass 0
fill ~1 ~-3 ~11 ~69 ~-3 ~11 grass 0
fill ~1 ~-3 ~12 ~69 ~-3 ~12 grass 0
fill ~1 ~-3 ~13 ~69 ~-3 ~13 grass 0
fill ~1 ~-3 ~14 ~69 ~-3 ~14 grass 0
fill ~1 ~-3 ~15 ~69 ~-3 ~15 grass 0
fill ~1 ~-3 ~16 ~69 ~-3 ~16 grass 0
fill ~1 ~-3 ~17 ~69 ~-3 ~17 grass 0
fill ~1 ~-3 ~18 ~44 ~-3 ~18 grass 0
fill ~1 ~-3 ~19 ~40 ~-3 ~19 grass 0
fill ~1 ~-3 ~20 ~37 ~-3 ~20 grass 0
fill ~1 ~-3 ~21 ~36 ~-3 ~21 grass 0
fill ~1 ~-3 ~22 ~35 ~-3 ~22 grass 0
fill ~1 ~-3 ~23 ~34 ~-3 ~23 grass 0
fill ~1 ~-3 ~24 ~34 ~-3 ~24 grass 0
fill ~1 ~-3 ~25 ~36 ~-3 ~25 grass 0
fill ~1 ~-3 ~26 ~32 ~-3 ~26 grass 0
fill ~1 ~-3 ~27 ~32 ~-3 ~27 grass 0
fill ~1 ~-3 ~28 ~32 ~-3 ~28 grass 0
fill ~1 ~-3 ~29 ~32 ~-3 ~29 grass 0
fill ~1 ~-3 ~30 ~32 ~-3 ~30 grass 0
fill ~1 ~-3 ~31 ~32 ~-3 ~31 grass 0
fill ~1 ~-3 ~32 ~33 ~-3 ~32 grass 0
fill ~1 ~-3 ~33 ~33 ~-3 ~33 grass 0
fill ~1 ~-3 ~34 ~33 ~-3 ~34 grass 0
fill ~1 ~-3 ~35 ~34 ~-3 ~35 grass 0
fill ~1 ~-3 ~36 ~35 ~-3 ~36 grass 0
fill ~1 ~-3 ~37 ~36 ~-3 ~37 grass 0
fill ~1 ~-3 ~38 ~39 ~-3 ~38 grass 0
fill ~1 ~-3 ~39 ~35 ~-3 ~39 grass 0
fill ~1 ~-3 ~40 ~36 ~-3 ~40 grass 0
fill ~1 ~-3 ~41 ~35 ~-3 ~41 grass 0
fill ~1 ~-3 ~42 ~29 ~-3 ~42 grass 0
fill ~1 ~-3 ~43 ~29 ~-3 ~43 grass 0
fill ~1 ~-3 ~44 ~29 ~-3 ~44 grass 0
fill ~1 ~-3 ~45 ~29 ~-3 ~45 grass 0
fill ~1 ~-3 ~46 ~29 ~-3 ~46 grass 0
fill ~1 ~-3 ~47 ~29 ~-3 ~47 grass 0
fill ~1 ~-3 ~48 ~30 ~-3 ~48 grass 0
fill ~1 ~-3 ~49 ~43 ~-3 ~49 grass 0
fill ~1 ~-3 ~50 ~46 ~-3 ~50 grass 0
fill ~1 ~-3 ~51 ~69 ~-3 ~51 grass 0
fill ~1 ~-3 ~52 ~69 ~-3 ~52 grass 0
fill ~1 ~-3 ~53 ~69 ~-3 ~53 grass 0
fill ~1 ~-3 ~54 ~69 ~-3 ~54 grass 0
fill ~1 ~-3 ~55 ~69 ~-3 ~55 grass 0
fill ~1 ~-3 ~56 ~69 ~-3 ~56 grass 0
fill ~1 ~-3 ~57 ~69 ~-3 ~57 grass 0
fill ~1 ~-3 ~58 ~69 ~-3 ~58 grass 0
fill ~1 ~-3 ~59 ~69 ~-3 ~59 grass 0
fill ~1 ~-3 ~60 ~69 ~-3 ~60 grass 0
fill ~1 ~-3 ~61 ~69 ~-3 ~61 grass 0
fill ~1 ~-3 ~62 ~69 ~-3 ~62 grass 0
fill ~1 ~-3 ~63 ~69 ~-3 ~63 grass 0
fill ~1 ~-3 ~64 ~69 ~-3 ~64 grass 0
fill ~1 ~-3 ~65 ~69 ~-3 ~65 grass 0
fill ~1 ~-3 ~66 ~69 ~-3 ~66 grass 0
fill ~1 ~-3 ~67 ~69 ~-3 ~67 grass 0
fill ~1 ~-3 ~68 ~69 ~-3 ~68 grass 0
fill ~1 ~-3 ~69 ~69 ~-3 ~69 grass 0
fill ~1 ~-3 ~70 ~69 ~-3 ~70 grass 0
fill ~1 ~-3 ~71 ~69 ~-3 ~71 grass 0
fill ~1 ~-3 ~72 ~69 ~-3 ~72 grass 0
fill ~1 ~-3 ~73 ~69 ~-3 ~73 grass 0
fill ~1 ~-3 ~74 ~69 ~-3 ~74 grass 0
fill ~1 ~-3 ~75 ~69 ~-3 ~75 grass 0
fill ~1 ~-3 ~76 ~69 ~-3 ~76 grass 0
fill ~1 ~-3 ~77 ~69 ~-3 ~77 grass 0
fill ~1 ~-3 ~78 ~69 ~-3 ~78 grass 0
fill ~1 ~-3 ~79 ~69 ~-3 ~79 grass 0
fill ~1 ~-3 ~80 ~69 ~-3 ~80 grass 0
fill ~1 ~-3 ~81 ~69 ~-3 ~81 grass 0
fill ~1 ~-3 ~82 ~69 ~-3 ~82 grass 0
fill ~1 ~-3 ~83 ~69 ~-3 ~83 grass 0
fill ~1 ~-3 ~84 ~69 ~-3 ~84 grass 0
fill ~1 ~-3 ~85 ~69 ~-3 ~85 grass 0
fill ~1 ~-3 ~86 ~69 ~-3 ~86 grass 0
fill ~1 ~-3 ~87 ~69 ~-3 ~87 grass 0
fill ~30 ~-3 ~42 ~30 ~-3 ~42 dirt 0
fill ~30 ~-3 ~43 ~31 ~-3 ~43 dirt 0
fill ~30 ~-3 ~44 ~31 ~-3 ~44 dirt 0
fill ~30 ~-3 ~45 ~33 ~-3 ~45 dirt 0
fill ~30 ~-3 ~46 ~33 ~-3 ~46 dirt 0
fill ~30 ~-3 ~47 ~33 ~-3 ~47 dirt 0
setblock ~31 ~-3 ~42 grass 0
fill ~31 ~-3 ~48 ~32 ~-3 ~48 dirt 0
fill ~32 ~-3 ~42 ~33 ~-3 ~42 dirt 0
fill ~32 ~-3 ~43 ~34 ~-3 ~43 grass 0
fill ~32 ~-3 ~44 ~32 ~-3 ~43 grass 0
fill ~33 ~-3 ~26 ~33 ~-2 ~26 dirt 0
fill ~33 ~-3 ~27 ~36 ~-3 ~27 dirt 0
fill ~33 ~-3 ~28 ~34 ~-3 ~28 dirt 0
fill ~33 ~-3 ~29 ~35 ~-3 ~29 dirt 0
fill ~33 ~-3 ~30 ~34 ~-3 ~30 dirt 0
fill ~33 ~-3 ~31 ~33 ~-3 ~31 dirt 0
fill ~33 ~-3 ~44 ~37 ~-3 ~44 dirt 0
fill ~33 ~-3 ~48 ~34 ~-3 ~48 grass 0
fill ~34 ~-3 ~26 ~36 ~-3 ~26 grass 0
setblock ~34 ~-3 ~31 grass 0
fill ~34 ~-3 ~32 ~34 ~-3 ~32 dirt 0
fill ~34 ~-3 ~33 ~35 ~-3 ~33 dirt 0
fill ~34 ~-3 ~34 ~34 ~-3 ~34 dirt 0
setblock ~34 ~-3 ~42 grass 0
fill ~34 ~-3 ~45 ~36 ~-3 ~45 grass 0
fill ~34 ~-3 ~46 ~34 ~-3 ~87 grass 0
fill ~35 ~-3 ~23 ~35 ~-3 ~23 dirt 0
fill ~35 ~-3 ~24 ~35 ~-3 ~24 dirt 0
fill ~35 ~-3 ~28 ~36 ~-3 ~28 grass 0
setblock ~35 ~-3 ~30 grass 0
fill ~35 ~-3 ~31 ~35 ~-3 ~31 dirt 0
fill ~35 ~-3 ~32 ~36 ~-3 ~32 grass 0
setblock ~35 ~-3 ~34 grass 0
fill ~35 ~-3 ~35 ~37 ~-3 ~35 dirt 0
fill ~35 ~-3 ~42 ~35 ~-3 ~42 dirt 0
fill ~35 ~-3 ~43 ~35 ~-3 ~43 dirt 0
fill ~35 ~-3 ~46 ~36 ~-3 ~46 dirt 0
setblock ~35 ~-3 ~47 grass 0
fill ~35 ~-3 ~48 ~35 ~-3 ~48 dirt 0
fill ~36 ~-3 ~22 ~36 ~-3 ~22 dirt 0
fill ~36 ~-3 ~23 ~36 ~-3 ~26 grass 0
setblock ~36 ~-3 ~29 grass 0
fill ~36 ~-3 ~30 ~36 ~-3 ~30 dirt 0
fill ~36 ~-3 ~31 ~37 ~-3 ~31 grass 0
setblock ~36 ~-3 ~33 grass 0
fill ~36 ~-3 ~34 ~37 ~-3 ~34 dirt 0
fill ~36 ~-3 ~36 ~38 ~-3 ~36 dirt 0
fill ~36 ~-3 ~39 ~37 ~-3 ~39 dirt 0
fill ~36 ~-3 ~41 ~36 ~-3 ~41 dirt 0
fill ~36 ~-3 ~42 ~36 ~-3 ~43 grass 0
fill ~36 ~-3 ~47 ~36 ~-3 ~47 dirt 0
setblock ~36 ~-3 ~48 grass 0
fill ~37 ~-3 ~21 ~37 ~-3 ~21 dirt 0
fill ~37 ~-3 ~22 ~41 ~-3 ~22 grass 0
fill ~37 ~-3 ~23 ~37 ~-3 ~23 dirt 0
setblock ~37 ~-3 ~24 grass 0
fill ~37 ~-3 ~25 ~37 ~-3 ~25 dirt 0
fill ~37 ~-3 ~26 ~37 ~-3 ~26 dirt 0
fill ~37 ~-3 ~27 ~38 ~-3 ~27 grass 0
fill ~37 ~-3 ~28 ~38 ~-3 ~28 dirt 0
fill ~37 ~-3 ~29 ~40 ~-3 ~29 dirt 0
fill ~37 ~-3 ~30 ~38 ~-3 ~30 grass 0
fill ~37 ~-3 ~32 ~39 ~-3 ~32 dirt 0
fill ~37 ~-3 ~33 ~37 ~-3 ~33 dirt 0
fill ~37 ~-3 ~37 ~39 ~-3 ~37 dirt 0
fill ~37 ~-3 ~40 ~37 ~-3 ~40 dirt 0
setblock ~37 ~-3 ~41 grass 0
fill ~37 ~-3 ~42 ~37 ~-3 ~42 dirt 0
fill ~37 ~-3 ~43 ~40 ~-3 ~43 grass 0
fill ~37 ~-3 ~45 ~37 ~-3 ~45 dirt 0
fill ~37 ~-3 ~46 ~38 ~-3 ~46 grass 0
fill ~37 ~-3 ~47 ~40 ~-3 ~47 grass 0
fill ~37 ~-3 ~48 ~37 ~-3 ~48 dirt 0
fill ~38 ~-3 ~20 ~42 ~-3 ~20 dirt 0
fill ~38 ~-3 ~21 ~40 ~-3 ~21 grass 0
setblock ~38 ~-3 ~23 grass 0
fill ~38 ~-3 ~24 ~38 ~-3 ~24 dirt 0
fill ~38 ~-3 ~25 ~39 ~-3 ~25 grass 0
fill ~38 ~-3 ~26 ~39 ~-3 ~26 grass 0
fill ~38 ~-3 ~31 ~39 ~-3 ~31 dirt 0
fill ~38 ~-3 ~33 ~39 ~-3 ~33 grass 0
fill ~38 ~-3 ~34 ~40 ~-3 ~34 grass 0
fill ~38 ~-3 ~35 ~38 ~-3 ~33 grass 0
fill ~38 ~-3 ~39 ~38 ~-3 ~40 grass 0
fill ~38 ~-3 ~41 ~38 ~-3 ~41 dirt 0
fill ~38 ~-3 ~42 ~39 ~-3 ~42 grass 0
fill ~38 ~-3 ~44 ~39 ~-3 ~44 grass 0
fill ~38 ~-3 ~45 ~39 ~-3 ~45 grass 0
fill ~38 ~-3 ~48 ~42 ~-3 ~48 grass 0
fill ~39 ~-3 ~23 ~39 ~-3 ~23 dirt 0
fill ~39 ~-3 ~24 ~40 ~-3 ~24 grass 0
fill ~39 ~-3 ~27 ~39 ~-3 ~27 dirt 0
setblock ~39 ~-3 ~28 grass 0
fill ~39 ~-3 ~30 ~39 ~-3 ~30 dirt 0
fill ~39 ~-3 ~35 ~39 ~-3 ~35 dirt 0
fill ~39 ~-3 ~36 ~40 ~-3 ~36 grass 0
fill ~39 ~-3 ~39 ~40 ~-3 ~39 dirt 0
fill ~39 ~-3 ~40 ~43 ~-3 ~40 dirt 0
setblock ~39 ~-3 ~41 grass 0
fill ~39 ~-3 ~46 ~39 ~-3 ~46 dirt 0
setblock ~40 ~-3 ~23 grass 0
fill ~40 ~-3 ~25 ~40 ~-3 ~25 dirt 0
fill ~40 ~-3 ~26 ~41 ~-3 ~26 dirt 0
fill ~40 ~-3 ~27 ~42 ~-3 ~27 grass 0
fill ~40 ~-3 ~28 ~40 ~-3 ~28 dirt 0
fill ~40 ~-3 ~30 ~40 ~-3 ~32 grass 0
fill ~40 ~-3 ~33 ~40 ~-3 ~33 dirt 0
fill ~40 ~-3 ~35 ~41 ~-3 ~35 grass 0
fill ~40 ~-3 ~37 ~41 ~-3 ~37 grass 0
fill ~40 ~-3 ~38 ~44 ~-3 ~38 dirt 0
fill ~40 ~-3 ~41 ~40 ~-3 ~41 dirt 0
fill ~40 ~-3 ~42 ~40 ~-3 ~42 dirt 0
fill ~40 ~-3 ~44 ~42 ~-3 ~44 dirt 0
fill ~40 ~-3 ~45 ~42 ~-3 ~45 dirt 0
fill ~40 ~-3 ~46 ~41 ~-3 ~46 grass 0
fill ~41 ~-3 ~19 ~41 ~-3 ~19 dirt 0
fill ~41 ~-3 ~21 ~41 ~-3 ~21 dirt 0
fill ~41 ~-3 ~23 ~41 ~-3 ~23 dirt 0
fill ~41 ~-3 ~24 ~41 ~-3 ~24 dirt 0
fill ~41 ~-3 ~25 ~42 ~-3 ~25 grass 0
fill ~41 ~-3 ~28 ~43 ~-3 ~28 grass 0
fill ~41 ~-3 ~29 ~43 ~-3 ~29 grass 0
fill ~41 ~-3 ~30 ~43 ~-3 ~30 dirt 0
fill ~41 ~-3 ~31 ~41 ~-3 ~31 dirt 0
fill ~41 ~-3 ~32 ~42 ~-3 ~32 dirt 0
setblock ~41 ~-3 ~33 grass 0
fill ~41 ~-3 ~34 ~44 ~-3 ~34 dirt 0
fill ~41 ~-3 ~36 ~42 ~-3 ~36 dirt 0
setblock ~41 ~-3 ~39 grass 0
fill ~41 ~-3 ~41 ~43 ~-3 ~41 grass 0
fill ~41 ~-3 ~42 ~42 ~-3 ~42 grass 0
fill ~41 ~-3 ~43 ~43 ~-3 ~43 dirt 0
fill ~41 ~-3 ~47 ~42 ~-3 ~47 dirt 0
fill ~42 ~-3 ~19 ~46 ~-3 ~19 grass 0
fill ~42 ~-3 ~21 ~45 ~-3 ~21 grass 0
fill ~42 ~-3 ~22 ~43 ~-3 ~22 dirt 0
fill ~42 ~-3 ~23 ~43 ~-3 ~23 grass 0
fill ~42 ~-3 ~24 ~43 ~-3 ~24 grass 0
fill ~42 ~-3 ~26 ~43 ~-3 ~26 grass 0
fill ~42 ~-3 ~31 ~43 ~-3 ~31 grass 0
fill ~42 ~-3 ~33 ~42 ~-3 ~33 dirt 0
fill ~42 ~-3 ~35 ~45 ~-3 ~35 dirt 0
fill ~42 ~-3 ~37 ~42 ~-3 ~37 dirt 0
fill ~42 ~-3 ~39 ~43 ~-3 ~39 dirt 0
fill ~42 ~-3 ~46 ~43 ~-3 ~46 dirt 0
fill ~43 ~-3 ~20 ~44 ~-3 ~20 grass 0
fill ~43 ~-3 ~25 ~43 ~-3 ~25 dirt 0
fill ~43 ~-3 ~27 ~43 ~-3 ~27 dirt 0
fill ~43 ~-3 ~32 ~43 ~-3 ~33 grass 0
fill ~43 ~-3 ~36 ~44 ~-3 ~36 grass 0
fill ~43 ~-3 ~37 ~44 ~-3 ~37 grass 0
fill ~43 ~-3 ~42 ~44 ~-3 ~42 dirt 0
fill ~43 ~-3 ~44 ~44 ~-3 ~44 grass 0
fill ~43 ~-3 ~45 ~45 ~-3 ~45 grass 0
fill ~43 ~-3 ~47 ~44 ~-3 ~47 grass 0
fill ~43 ~-3 ~48 ~44 ~-3 ~48 dirt 0
setblock ~44 ~-3 ~22 grass 0
fill ~44 ~-3 ~23 ~46 ~-3 ~23 dirt 0
fill ~44 ~-3 ~24 ~44 ~-3 ~24 dirt 0
setblock ~44 ~-3 ~25 grass 0
fill ~44 ~-3 ~26 ~45 ~-3 ~26 dirt 0
fill ~44 ~-3 ~27 ~45 ~-3 ~27 grass 0
fill ~44 ~-3 ~28 ~45 ~-3 ~28 dirt 0
fill ~44 ~-3 ~29 ~44 ~-3 ~29 dirt 0
setblock ~44 ~-3 ~30 grass 0
fill ~44 ~-3 ~31 ~51 ~-3 ~31 dirt 0
fill ~44 ~-3 ~32 ~45 ~-3 ~32 dirt 0
fill ~44 ~-3 ~33 ~46 ~-3 ~33 dirt 0
fill ~44 ~-3 ~39 ~44 ~-3 ~40 grass 0
fill ~44 ~-3 ~41 ~47 ~-3 ~41 dirt 0
setblock ~44 ~-3 ~43 grass 0
fill ~44 ~-3 ~46 ~45 ~-3 ~46 grass 0
fill ~44 ~-3 ~49 ~44 ~-3 ~49 dirt 0
fill ~45 ~-3 ~18 ~48 ~-3 ~18 dirt 0
fill ~45 ~-3 ~20 ~45 ~-3 ~20 dirt 0
fill ~45 ~-3 ~22 ~49 ~-3 ~22 dirt 0
setblock ~45 ~-3 ~24 grass 0
fill ~45 ~-3 ~25 ~45 ~-3 ~25 dirt 0
setblock ~45 ~-3 ~29 grass 0
fill ~45 ~-3 ~30 ~45 ~-3 ~30 dirt 0
setblock ~45 ~-3 ~34 grass 0
fill ~45 ~-3 ~36 ~45 ~-3 ~36 dirt 0
fill ~45 ~-3 ~37 ~47 ~-3 ~37 dirt 0
setblock ~45 ~-3 ~38 grass 0
fill ~45 ~-3 ~39 ~45 ~-3 ~39 dirt 0
fill ~45 ~-3 ~40 ~46 ~-3 ~40 grass 0
setblock ~45 ~-3 ~42 grass 0
fill ~45 ~-3 ~43 ~46 ~-3 ~43 dirt 0
fill ~45 ~-3 ~44 ~45 ~-3 ~44 dirt 0
fill ~45 ~-3 ~47 ~45 ~-3 ~47 dirt 0
fill ~45 ~-3 ~48 ~46 ~-3 ~48 grass 0
fill ~45 ~-3 ~49 ~47 ~-3 ~49 grass 0
setblock ~46 ~-3 ~20 grass 0
fill ~46 ~-3 ~21 ~49 ~-3 ~21 dirt 0
fill ~46 ~-3 ~24 ~52 ~-3 ~24 dirt 0
fill ~46 ~-3 ~25 ~46 ~-3 ~26 grass 0
fill ~46 ~-3 ~27 ~46 ~-3 ~27 dirt 0
fill ~46 ~-3 ~28 ~47 ~-3 ~28 grass 0
fill ~46 ~-3 ~29 ~51 ~-3 ~29 dirt 0
setblock ~46 ~-3 ~30 grass 0
fill ~46 ~-3 ~32 ~50 ~-3 ~32 grass 0
fill ~46 ~-3 ~34 ~49 ~-3 ~34 dirt 0
fill ~46 ~-3 ~35 ~48 ~-3 ~35 grass 0
fill ~46 ~-3 ~36 ~49 ~-3 ~36 grass 0
fill ~46 ~-3 ~38 ~47 ~-3 ~38 dirt 0
fill ~46 ~-3 ~39 ~48 ~-3 ~39 grass 0
fill ~46 ~-3 ~42 ~48 ~-3 ~42 dirt 0
setblock ~46 ~-3 ~44 grass 0
fill ~46 ~-3 ~45 ~46 ~-3 ~45 dirt 0
fill ~46 ~-3 ~46 ~47 ~-3 ~46 dirt 0
setblock ~46 ~-3 ~47 grass 0
fill ~47 ~-3 ~19 ~50 ~-3 ~19 dirt 0
fill ~47 ~-3 ~20 ~49 ~-3 ~20 dirt 0
setblock ~47 ~-3 ~23 grass 0
fill ~47 ~-3 ~25 ~47 ~-3 ~25 dirt 0
fill ~47 ~-3 ~26 ~48 ~-3 ~26 dirt 0
setblock ~47 ~-3 ~27 grass 0
fill ~47 ~-3 ~30 ~47 ~-3 ~30 dirt 0
setblock ~47 ~-3 ~33 grass 0
fill ~47 ~-3 ~40 ~47 ~-3 ~40 dirt 0
fill ~47 ~-3 ~43 ~48 ~-3 ~43 grass 0
fill ~47 ~-3 ~44 ~47 ~-3 ~44 dirt 0
setblock ~47 ~-3 ~45 grass 0
fill ~47 ~-3 ~47 ~47 ~-3 ~47 dirt 0
fill ~47 ~-3 ~48 ~49 ~-3 ~48 dirt 0
fill ~47 ~-3 ~50 ~48 ~-3 ~50 dirt 0
fill ~48 ~-3 ~23 ~51 ~-3 ~23 dirt 0
fill ~48 ~-3 ~25 ~50 ~-3 ~25 grass 0
fill ~48 ~-3 ~27 ~48 ~-3 ~27 dirt 0
fill ~48 ~-3 ~28 ~50 ~-3 ~28 dirt 0
setblock ~48 ~-3 ~30 grass 0
fill ~48 ~-3 ~33 ~48 ~-3 ~33 dirt 0
fill ~48 ~-3 ~37 ~57 ~-3 ~37 grass 0
fill ~48 ~-3 ~38 ~48 ~-3 ~35 grass 0
fill ~48 ~-3 ~40 ~48 ~-3 ~41 grass 0
fill ~48 ~-3 ~44 ~51 ~-3 ~44 grass 0
fill ~48 ~-3 ~45 ~48 ~-3 ~45 dirt 0
fill ~48 ~-3 ~46 ~48 ~-3 ~47 grass 0
fill ~48 ~-3 ~49 ~49 ~-3 ~49 dirt 0
fill ~49 ~-3 ~18 ~51 ~-3 ~18 grass 0
fill ~49 ~-3 ~26 ~49 ~-3 ~27 grass 0
fill ~49 ~-3 ~30 ~50 ~-3 ~30 dirt 0
setblock ~49 ~-3 ~33 grass 0
fill ~49 ~-3 ~35 ~49 ~-3 ~35 dirt 0
fill ~49 ~-3 ~38 ~49 ~-3 ~38 dirt 0
fill ~49 ~-3 ~39 ~53 ~-3 ~39 dirt 0
fill ~49 ~-3 ~40 ~49 ~-3 ~40 dirt 0
fill ~49 ~-3 ~41 ~52 ~-3 ~41 dirt 0
setblock ~49 ~-3 ~42 grass 0
fill ~49 ~-3 ~43 ~49 ~-3 ~43 dirt 0
fill ~49 ~-3 ~45 ~52 ~-3 ~45 grass 0
fill ~49 ~-3 ~46 ~52 ~-3 ~46 dirt 0
fill ~49 ~-3 ~47 ~55 ~-3 ~47 dirt 0
setblock ~49 ~-3 ~50 grass 0
fill ~50 ~-3 ~20 ~50 ~-3 ~22 grass 0
fill ~50 ~-3 ~26 ~54 ~-3 ~26 dirt 0
fill ~50 ~-3 ~27 ~52 ~-3 ~27 grass 0
fill ~50 ~-3 ~33 ~51 ~-3 ~33 dirt 0
fill ~50 ~-3 ~34 ~51 ~-3 ~34 grass 0
fill ~50 ~-3 ~35 ~50 ~-3 ~34 grass 0
fill ~50 ~-3 ~36 ~51 ~-3 ~36 dirt 0
setblock ~50 ~-3 ~38 grass 0
fill ~50 ~-3 ~40 ~53 ~-3 ~40 grass 0
fill ~50 ~-3 ~42 ~50 ~-3 ~42 dirt 0
fill ~50 ~-3 ~43 ~51 ~-3 ~43 grass 0
fill ~50 ~-3 ~48 ~51 ~-3 ~48 grass 0
fill ~50 ~-3 ~49 ~50 ~-3 ~48 grass 0
fill ~50 ~-3 ~50 ~56 ~-3 ~50 dirt 0
fill ~51 ~-3 ~19 ~52 ~-3 ~19 grass 0
fill ~51 ~-3 ~20 ~54 ~-3 ~20 dirt 0
fill ~51 ~-3 ~21 ~55 ~-3 ~21 grass 0
fill ~51 ~-3 ~22 ~52 ~-3 ~22 dirt 0
fill ~51 ~-3 ~25 ~51 ~-3 ~25 dirt 0
setblock ~51 ~-3 ~28 grass 0
setblock ~51 ~-3 ~30 grass 0
fill ~51 ~-3 ~32 ~52 ~-3 ~32 dirt 0
fill ~51 ~-3 ~35 ~54 ~-3 ~35 dirt 0
fill ~51 ~-3 ~38 ~53 ~-3 ~38 dirt 0
setblock ~51 ~-3 ~42 grass 0
fill ~51 ~-3 ~49 ~51 ~-2 ~49 dirt 0
fill ~52 ~-3 ~18 ~54 ~-3 ~18 dirt 0
fill ~52 ~-3 ~23 ~54 ~-3 ~23 grass 0
fill ~52 ~-3 ~25 ~53 ~-3 ~25 grass 0
fill ~52 ~-3 ~28 ~52 ~-3 ~28 dirt 0
fill ~52 ~-3 ~29 ~59 ~-3 ~29 grass 0
fill ~52 ~-3 ~30 ~53 ~-3 ~30 dirt 0
fill ~52 ~-3 ~31 ~53 ~-3 ~31 grass 0
fill ~52 ~-3 ~33 ~53 ~-3 ~33 grass 0
fill ~52 ~-3 ~34 ~56 ~-3 ~34 dirt 0
fill ~52 ~-3 ~36 ~53 ~-3 ~36 grass 0
fill ~52 ~-3 ~42 ~53 ~-3 ~42 dirt 0
fill ~52 ~-3 ~43 ~53 ~-3 ~43 dirt 0
fill ~52 ~-3 ~44 ~54 ~-3 ~44 dirt 0
fill ~52 ~-3 ~48 ~53 ~-3 ~48 dirt 0
fill ~52 ~-3 ~49 ~53 ~-3 ~49 grass 0
fill ~53 ~-3 ~19 ~53 ~-3 ~19 dirt 0
fill ~53 ~-3 ~22 ~56 ~-3 ~22 grass 0
setblock ~53 ~-3 ~24 grass 0
fill ~53 ~-3 ~27 ~55 ~-3 ~27 dirt 0
fill ~53 ~-3 ~28 ~56 ~-3 ~28 grass 0
fill ~53 ~-3 ~32 ~54 ~-3 ~32 grass 0
setblock ~53 ~-3 ~41 grass 0
fill ~53 ~-3 ~45 ~58 ~-3 ~45 dirt 0
setblock ~53 ~-3 ~46 grass 0
fill ~54 ~-3 ~19 ~55 ~-3 ~19 grass 0
fill ~54 ~-3 ~24 ~54 ~-3 ~24 dirt 0
fill ~54 ~-3 ~25 ~54 ~-3 ~25 dirt 0
fill ~54 ~-3 ~30 ~56 ~-3 ~30 grass 0
fill ~54 ~-3 ~31 ~55 ~-3 ~31 dirt 0
fill ~54 ~-3 ~33 ~54 ~-3 ~33 dirt 0
fill ~54 ~-3 ~36 ~54 ~-3 ~36 dirt 0
fill ~54 ~-3 ~38 ~56 ~-3 ~38 grass 0
fill ~54 ~-3 ~39 ~55 ~-3 ~39 grass 0
fill ~54 ~-3 ~40 ~54 ~-3 ~40 dirt 0
fill ~54 ~-3 ~41 ~54 ~-3 ~41 dirt 0
fill ~54 ~-3 ~42 ~54 ~-3 ~43 grass 0
fill ~54 ~-3 ~46 ~55 ~-3 ~46 dirt 0
fill ~54 ~-3 ~48 ~60 ~-3 ~48 grass 0
fill ~54 ~-3 ~49 ~58 ~-3 ~49 dirt 0
fill ~55 ~-3 ~18 ~69 ~-3 ~18 grass 0
setblock ~55 ~-3 ~20 grass 0
fill ~55 ~-3 ~23 ~55 ~-3 ~23 dirt 0
fill ~55 ~-3 ~24 ~55 ~-3 ~26 grass 0
fill ~55 ~-3 ~32 ~58 ~-3 ~32 dirt 0
fill ~55 ~-3 ~33 ~57 ~-3 ~33 grass 0
fill ~55 ~-3 ~35 ~55 ~-3 ~41 grass 0
fill ~55 ~-3 ~42 ~55 ~-3 ~42 dirt 0
fill ~55 ~-3 ~43 ~56 ~-3 ~43 dirt 0
setblock ~55 ~-3 ~44 grass 0
fill ~56 ~-3 ~19 ~56 ~-3 ~19 dirt 0
fill ~56 ~-3 ~20 ~56 ~-3 ~20 dirt 0
fill ~56 ~-3 ~21 ~61 ~-3 ~21 dirt 0
setblock ~56 ~-3 ~23 grass 0
fill ~56 ~-3 ~24 ~56 ~-3 ~24 dirt 0
fill ~56 ~-3 ~25 ~56 ~-3 ~25 dirt 0
fill ~56 ~-3 ~26 ~61 ~-3 ~26 dirt 0
fill ~56 ~-3 ~27 ~58 ~-3 ~27 grass 0
fill ~56 ~-3 ~31 ~58 ~-3 ~31 grass 0
fill ~56 ~-3 ~35 ~57 ~-3 ~35 dirt 0
fill ~56 ~-3 ~36 ~57 ~-3 ~36 grass 0
fill ~56 ~-3 ~39 ~56 ~-3 ~39 dirt 0
fill ~56 ~-3 ~40 ~58 ~-3 ~40 grass 0
fill ~56 ~-3 ~41 ~58 ~-3 ~41 dirt 0
fill ~56 ~-3 ~42 ~57 ~-3 ~42 grass 0
fill ~56 ~-3 ~44 ~56 ~-3 ~44 dirt 0
fill ~56 ~-3 ~46 ~58 ~-3 ~46 grass 0
fill ~56 ~-3 ~47 ~57 ~-3 ~47 grass 0
fill ~57 ~-3 ~19 ~57 ~-3 ~20 grass 0
fill ~57 ~-3 ~22 ~57 ~-3 ~22 dirt 0
fill ~57 ~-3 ~23 ~57 ~-3 ~23 dirt 0
fill ~57 ~-3 ~24 ~58 ~-3 ~24 grass 0
fill ~57 ~-3 ~25 ~59 ~-3 ~25 grass 0
fill ~57 ~-3 ~28 ~60 ~-3 ~28 dirt 0
fill ~57 ~-3 ~30 ~57 ~-3 ~30 dirt 0
fill ~57 ~-3 ~34 ~59 ~-3 ~34 grass 0
fill ~57 ~-3 ~38 ~60 ~-3 ~38 dirt 0
setblock ~57 ~-3 ~39 grass 0
fill ~57 ~-3 ~43 ~58 ~-3 ~43 grass 0
fill ~57 ~-3 ~44 ~57 ~-3 ~42 grass 0
fill ~57 ~-3 ~50 ~58 ~-3 ~50 grass 0
fill ~58 ~-3 ~19 ~58 ~-3 ~19 dirt 0
fill ~58 ~-3 ~20 ~69 ~-3 ~20 grass 0
fill ~58 ~-3 ~22 ~58 ~-3 ~25 grass 0
fill ~58 ~-3 ~30 ~64 ~-3 ~30 grass 0
fill ~58 ~-3 ~33 ~63 ~-3 ~33 dirt 0
fill ~58 ~-3 ~35 ~59 ~-3 ~35 grass 0
fill ~58 ~-3 ~36 ~64 ~-3 ~36 dirt 0
fill ~58 ~-3 ~37 ~62 ~-3 ~37 dirt 0
fill ~58 ~-3 ~39 ~60 ~-3 ~39 dirt 0
fill ~58 ~-3 ~42 ~58 ~-3 ~42 dirt 0
fill ~58 ~-3 ~44 ~58 ~-3 ~44 dirt 0
fill ~58 ~-3 ~47 ~58 ~-3 ~47 dirt 0
fill ~59 ~-3 ~19 ~69 ~-3 ~19 grass 0
fill ~59 ~-3 ~22 ~59 ~-3 ~22 dirt 0
setblock ~59 ~-3 ~23 grass 0
fill ~59 ~-3 ~24 ~59 ~-3 ~24 dirt 0
fill ~59 ~-3 ~27 ~59 ~-3 ~27 dirt 0
fill ~59 ~-3 ~31 ~61 ~-3 ~31 dirt 0
setblock ~59 ~-3 ~32 grass 0
fill ~59 ~-3 ~40 ~60 ~-3 ~40 dirt 0
fill ~59 ~-3 ~41 ~59 ~-3 ~42 grass 0
fill ~59 ~-3 ~43 ~60 ~-3 ~43 dirt 0
fill ~59 ~-3 ~44 ~61 ~-3 ~44 grass 0
fill ~59 ~-3 ~45 ~60 ~-3 ~45 grass 0
fill ~59 ~-3 ~46 ~60 ~-3 ~46 dirt 0
fill ~59 ~-3 ~47 ~61 ~-3 ~47 grass 0
fill ~59 ~-3 ~49 ~60 ~-3 ~49 grass 0
fill ~59 ~-3 ~50 ~60 ~-3 ~50 dirt 0
setblock ~60 ~-3 ~22 grass 0
fill ~60 ~-3 ~23 ~63 ~-3 ~23 dirt 0
fill ~60 ~-3 ~24 ~61 ~-3 ~24 grass 0
fill ~60 ~-3 ~25 ~62 ~-3 ~25 dirt 0
setblock ~60 ~-3 ~27 grass 0
fill ~60 ~-3 ~29 ~61 ~-3 ~29 dirt 0
fill ~60 ~-3 ~32 ~63 ~-3 ~32 dirt 0
fill ~60 ~-3 ~34 ~62 ~-3 ~34 dirt 0
fill ~60 ~-3 ~35 ~60 ~-3 ~35 dirt 0
fill ~60 ~-3 ~41 ~61 ~-3 ~41 dirt 0
fill ~60 ~-3 ~42 ~61 ~-3 ~42 grass 0
fill ~61 ~-3 ~22 ~61 ~-3 ~22 dirt 0
fill ~61 ~-3 ~27 ~65 ~-3 ~27 dirt 0
setblock ~61 ~-3 ~28 grass 0
setblock ~61 ~-3 ~35 grass 0
fill ~61 ~-3 ~38 ~62 ~-3 ~38 grass 0
fill ~61 ~-3 ~39 ~63 ~-3 ~39 grass 0
fill ~61 ~-3 ~40 ~61 ~-3 ~38 grass 0
setblock ~61 ~-3 ~43 grass 0
fill ~61 ~-3 ~45 ~61 ~-3 ~45 dirt 0
setblock ~61 ~-3 ~46 grass 0
fill ~61 ~-3 ~48 ~62 ~-3 ~48 dirt 0
fill ~61 ~-3 ~49 ~61 ~-3 ~49 dirt 0
fill ~61 ~-3 ~50 ~69 ~-3 ~50 grass 0
fill ~62 ~-3 ~21 ~69 ~-3 ~21 grass 0
fill ~62 ~-3 ~22 ~69 ~-3 ~22 grass 0
fill ~62 ~-3 ~24 ~62 ~-3 ~24 dirt 0
fill ~62 ~-3 ~26 ~69 ~-3 ~26 grass 0
fill ~62 ~-3 ~28 ~63 ~-3 ~28 dirt 0
fill ~62 ~-3 ~29 ~63 ~-3 ~29 grass 0
setblock ~62 ~-3 ~31 grass 0
fill ~62 ~-3 ~35 ~63 ~-3 ~35 dirt 0
fill ~62 ~-3 ~40 ~67 ~-3 ~40 dirt 0
setblock ~62 ~-3 ~41 grass 0
fill ~62 ~-3 ~42 ~67 ~-3 ~42 dirt 0
fill ~62 ~-3 ~43 ~62 ~-3 ~43 dirt 0
fill ~62 ~-3 ~44 ~62 ~-3 ~44 dirt 0
fill ~62 ~-3 ~45 ~63 ~-3 ~45 grass 0
fill ~62 ~-3 ~46 ~66 ~-3 ~46 dirt 0
fill ~62 ~-3 ~47 ~65 ~-3 ~47 dirt 0
fill ~62 ~-3 ~49 ~69 ~-3 ~49 grass 0
fill ~63 ~-3 ~24 ~69 ~-3 ~24 grass 0
fill ~63 ~-3 ~25 ~63 ~-3 ~24 grass 0
fill ~63 ~-3 ~31 ~66 ~-3 ~31 dirt 0
setblock ~63 ~-3 ~34 grass 0
setblock ~63 ~-3 ~37 grass 0
fill ~63 ~-3 ~38 ~64 ~-3 ~38 dirt 0
fill ~63 ~-3 ~41 ~67 ~-3 ~41 dirt 0
fill ~63 ~-3 ~43 ~63 ~-3 ~45 grass 0
fill ~63 ~-3 ~48 ~69 ~-3 ~48 grass 0
fill ~64 ~-3 ~23 ~69 ~-3 ~23 grass 0
fill ~64 ~-3 ~25 ~65 ~-3 ~25 dirt 0
setblock ~64 ~-3 ~28 grass 0
fill ~64 ~-3 ~29 ~64 ~-3 ~29 dirt 0
fill ~64 ~-3 ~32 ~65 ~-3 ~32 grass 0
fill ~64 ~-3 ~33 ~64 ~-3 ~32 grass 0
fill ~64 ~-3 ~34 ~65 ~-3 ~34 dirt 0
setblock ~64 ~-3 ~35 grass 0
fill ~64 ~-3 ~37 ~64 ~-3 ~37 dirt 0
fill ~64 ~-3 ~39 ~67 ~-3 ~39 dirt 0
fill ~64 ~-3 ~43 ~66 ~-3 ~43 dirt 0
setblock ~64 ~-3 ~44 grass 0
fill ~64 ~-3 ~45 ~66 ~-3 ~45 dirt 0
fill ~65 ~-3 ~28 ~66 ~-3 ~28 dirt 0
setblock ~65 ~-3 ~29 grass 0
fill ~65 ~-3 ~30 ~65 ~-3 ~30 dirt 0
fill ~65 ~-3 ~33 ~65 ~-3 ~33 dirt 0
fill ~65 ~-3 ~35 ~67 ~-3 ~35 dirt 0
fill ~65 ~-3 ~36 ~65 ~-3 ~38 grass 0
fill ~65 ~-3 ~44 ~66 ~-3 ~44 dirt 0
fill ~66 ~-3 ~25 ~69 ~-3 ~25 grass 0
fill ~66 ~-3 ~27 ~67 ~-3 ~27 grass 0
fill ~66 ~-3 ~29 ~66 ~-3 ~29 dirt 0
fill ~66 ~-3 ~30 ~69 ~-3 ~30 grass 0
fill ~66 ~-3 ~32 ~66 ~-3 ~32 dirt 0
fill ~66 ~-3 ~33 ~69 ~-3 ~33 grass 0
fill ~66 ~-3 ~34 ~66 ~-3 ~33 grass 0
fill ~66 ~-3 ~36 ~67 ~-3 ~36 dirt 0
fill ~66 ~-3 ~37 ~66 ~-3 ~38 grass 0
fill ~66 ~-3 ~47 ~69 ~-3 ~47 grass 0
fill ~67 ~-3 ~28 ~69 ~-3 ~28 grass 0
fill ~67 ~-3 ~29 ~67 ~-3 ~0 grass 0
fill ~67 ~-3 ~31 ~67 ~-3 ~33 grass 0
fill ~67 ~-3 ~34 ~67 ~-3 ~34 dirt 0
fill ~67 ~-3 ~37 ~67 ~-3 ~37 dirt 0
fill ~67 ~-3 ~38 ~67 ~-3 ~38 dirt 0
fill ~67 ~-3 ~43 ~69 ~-3 ~43 grass 0
fill ~67 ~-3 ~44 ~69 ~-3 ~44 grass 0
fill ~67 ~-3 ~45 ~69 ~-3 ~45 grass 0
fill ~67 ~-3 ~46 ~69 ~-3 ~46 grass 0
fill ~68 ~-3 ~27 ~68 ~-3 ~27 dirt 0
fill ~68 ~-3 ~29 ~68 ~-3 ~29 dirt 0
fill ~68 ~-3 ~31 ~68 ~-3 ~31 dirt 0
fill ~68 ~-3 ~32 ~68 ~-3 ~32 dirt 0
fill ~68 ~-3 ~34 ~69 ~-3 ~34 grass 0
fill ~68 ~-3 ~35 ~69 ~-3 ~35 grass 0
fill ~68 ~-3 ~36 ~69 ~-3 ~36 grass 0
fill ~68 ~-3 ~37 ~69 ~-3 ~37 grass 0
fill ~68 ~-3 ~38 ~69 ~-3 ~38 grass 0
fill ~68 ~-3 ~39 ~69 ~-3 ~39 grass 0
fill ~68 ~-3 ~40 ~69 ~-3 ~40 grass 0
fill ~68 ~-3 ~41 ~69 ~-3 ~41 grass 0
fill ~68 ~-3 ~42 ~69 ~-3 ~42 grass 0
setblock ~69 ~-3 ~0 gold_block 0
setblock ~69 ~-3 ~27 grass 0
setblock ~69 ~-3 ~29 grass 0
fill ~69 ~-3 ~31 ~69 ~-3 ~87 grass 0
setblock ~1 ~-2 ~0 tallgrass 1
setblock ~1 ~-2 ~2 tallgrass 1
setblock ~1 ~-2 ~4 tallgrass 1
fill ~1 ~-2 ~23 ~1 ~-2 ~25 tallgrass 1
setblock ~1 ~-2 ~27 tallgrass 1
fill ~1 ~-2 ~30 ~5 ~-2 ~30 tallgrass 1
fill ~1 ~-2 ~31 ~2 ~-2 ~31 tallgrass 1
fill ~1 ~-2 ~32 ~3 ~-2 ~32 tallgrass 1
fill ~1 ~-2 ~33 ~1 ~-2 ~34 tallgrass 1
setblock ~1 ~-2 ~63 tallgrass 1
setblock ~1 ~-2 ~65 tallgrass 1
fill ~1 ~-2 ~67 ~4 ~-2 ~67 tallgrass 1
fill ~1 ~-2 ~68 ~3 ~-2 ~68 tallgrass 1
fill ~1 ~-2 ~69 ~2 ~-2 ~69 tallgrass 1
setblock ~1 ~-2 ~71 tallgrass 1
fill ~1 ~-2 ~74 ~6 ~-2 ~74 tallgrass 1
fill ~1 ~-2 ~75 ~1 ~-2 ~74 tallgrass 1
fill ~1 ~-2 ~79 ~1 ~-2 ~80 tallgrass 1
fill ~1 ~-2 ~82 ~5 ~-2 ~82 tallgrass 1
fill ~1 ~-2 ~83 ~3 ~-2 ~83 tallgrass 1
fill ~2 ~-2 ~1 ~4 ~-2 ~1 tallgrass 1
fill ~2 ~-2 ~9 ~3 ~-2 ~9 tallgrass 1
fill ~2 ~-2 ~26 ~3 ~-2 ~26 tallgrass 1
fill ~2 ~-2 ~29 ~3 ~-2 ~29 tallgrass 1
setblock ~2 ~-2 ~57 tallgrass 1
setblock ~2 ~-2 ~66 tallgrass 1
setblock ~2 ~-2 ~70 tallgrass 1
setblock ~2 ~-2 ~73 tallgrass 1
fill ~2 ~-2 ~76 ~2 ~-2 ~78 tallgrass 1
fill ~2 ~-2 ~81 ~5 ~-2 ~81 tallgrass 1
fill ~2 ~-2 ~84 ~2 ~-2 ~85 tallgrass 1
fill ~3 ~-2 ~20 ~5 ~-2 ~20 tallgrass 1
fill ~3 ~-2 ~23 ~7 ~-2 ~23 tallgrass 1
setblock ~3 ~-2 ~28 tallgrass 1
fill ~3 ~-2 ~33 ~4 ~-2 ~33 tallgrass 1
setblock ~3 ~-2 ~52 tallgrass 1
setblock ~3 ~-2 ~63 tallgrass 1
setblock ~3 ~-2 ~65 tallgrass 1
fill ~3 ~-2 ~75 ~4 ~-2 ~75 tallgrass 1
setblock ~3 ~-2 ~77 tallgrass 1
setblock ~3 ~-2 ~80 tallgrass 1
fill ~3 ~-2 ~86 ~6 ~-2 ~86 tallgrass 1
fill ~3 ~-2 ~87 ~3 ~-2 ~86 tallgrass 1
fill ~4 ~-2 ~5 ~5 ~-2 ~5 tallgrass 1
fill ~4 ~-2 ~6 ~4 ~-2 ~5 tallgrass 1
fill ~4 ~-2 ~21 ~6 ~-2 ~21 tallgrass 1
setblock ~4 ~-2 ~27 tallgrass 1
setblock ~4 ~-2 ~31 tallgrass 1
setblock ~4 ~-2 ~60 tallgrass 1
fill ~4 ~-2 ~64 ~5 ~-2 ~64 tallgrass 1
setblock ~4 ~-2 ~72 tallgrass 1
setblock ~4 ~-2 ~78 tallgrass 1
fill ~5 ~-2 ~7 ~7 ~-2 ~7 tallgrass 1
fill ~5 ~-2 ~8 ~6 ~-2 ~8 tallgrass 1
fill ~5 ~-2 ~24 ~6 ~-2 ~24 tallgrass 1
fill ~5 ~-2 ~26 ~6 ~-2 ~26 tallgrass 1
setblock ~5 ~-2 ~29 tallgrass 1
setblock ~5 ~-2 ~55 tallgrass 1
setblock ~5 ~-2 ~63 tallgrass 1
fill ~5 ~-2 ~65 ~6 ~-2 ~65 tallgrass 1
setblock ~5 ~-2 ~69 tallgrass 1
fill ~5 ~-2 ~79 ~6 ~-2 ~79 tallgrass 1
setblock ~5 ~-2 ~83 tallgrass 1
fill ~5 ~-2 ~85 ~6 ~-2 ~85 tallgrass 1
setblock ~6 ~-2 ~1 tallgrass 1
setblock ~6 ~-2 ~4 tallgrass 1
setblock ~6 ~-2 ~6 tallgrass 1
setblock ~6 ~-2 ~9 tallgrass 1
setblock ~6 ~-2 ~11 tallgrass 1
setblock ~6 ~-2 ~19 tallgrass 1
fill ~6 ~-2 ~25 ~8 ~-2 ~25 tallgrass 1
fill ~6 ~-2 ~28 ~7 ~-2 ~28 tallgrass 1
fill ~6 ~-2 ~31 ~7 ~-2 ~31 tallgrass 1
fill ~6 ~-2 ~32 ~6 ~-2 ~33 tallgrass 1
fill ~6 ~-2 ~35 ~7 ~-2 ~35 tallgrass 1
setblock ~6 ~-2 ~45 tallgrass 1
setblock ~6 ~-2 ~59 tallgrass 1
setblock ~6 ~-2 ~62 tallgrass 1
setblock ~6 ~-2 ~70 tallgrass 1
fill ~6 ~-2 ~72 ~7 ~-2 ~72 tallgrass 1
fill ~6 ~-2 ~78 ~7 ~-2 ~78 tallgrass 1
fill ~6 ~-2 ~80 ~8 ~-2 ~80 tallgrass 1
setblock ~6 ~-2 ~87 tallgrass 1
fill ~7 ~-2 ~3 ~8 ~-2 ~3 tallgrass 1
setblock ~7 ~-2 ~5 tallgrass 1
fill ~7 ~-2 ~14 ~7 ~-2 ~15 tallgrass 1
setblock ~7 ~-2 ~20 tallgrass 1
setblock ~7 ~-2 ~30 tallgrass 1
fill ~7 ~-2 ~34 ~8 ~-2 ~34 tallgrass 1
setblock ~7 ~-2 ~44 tallgrass 1
setblock ~7 ~-2 ~48 tallgrass 1
setblock ~7 ~-2 ~50 tallgrass 1
setblock ~7 ~-2 ~56 tallgrass 1
fill ~7 ~-2 ~64 ~8 ~-2 ~64 tallgrass 1
setblock ~7 ~-2 ~67 tallgrass 1
setblock ~7 ~-2 ~69 tallgrass 1
fill ~7 ~-2 ~71 ~9 ~-2 ~71 tallgrass 1
setblock ~7 ~-2 ~73 tallgrass 1
fill ~7 ~-2 ~77 ~9 ~-2 ~77 tallgrass 1
fill ~7 ~-2 ~81 ~7 ~-2 ~83 tallgrass 1
fill ~8 ~-2 ~9 ~9 ~-2 ~9 tallgrass 1
fill ~8 ~-2 ~11 ~10 ~-2 ~11 tallgrass 1
fill ~8 ~-2 ~12 ~10 ~-2 ~12 tallgrass 1
fill ~8 ~-2 ~15 ~8 ~-2 ~16 tallgrass 1
fill ~8 ~-2 ~18 ~9 ~-2 ~18 tallgrass 1
fill ~8 ~-2 ~19 ~8 ~-2 ~18 tallgrass 1
setblock ~8 ~-2 ~24 tallgrass 1
setblock ~8 ~-2 ~45 tallgrass 1
fill ~8 ~-2 ~49 ~9 ~-2 ~49 tallgrass 1
setblock ~8 ~-2 ~51 tallgrass 1
fill ~8 ~-2 ~59 ~11 ~-2 ~59 tallgrass 1
setblock ~8 ~-2 ~65 tallgrass 1
setblock ~8 ~-2 ~70 tallgrass 1
fill ~8 ~-2 ~75 ~9 ~-2 ~75 tallgrass 1
fill ~8 ~-2 ~76 ~9 ~-2 ~76 tallgrass 1
setblock ~8 ~-2 ~79 tallgrass 1
setblock ~8 ~-2 ~82 tallgrass 1
setblock ~8 ~-2 ~85 tallgrass 1
setblock ~8 ~-2 ~87 tallgrass 1
setblock ~9 ~-2 ~13 tallgrass 1
fill ~9 ~-2 ~23 ~10 ~-2 ~23 tallgrass 1
setblock ~9 ~-2 ~28 tallgrass 1
fill ~9 ~-2 ~31 ~9 ~-2 ~33 tallgrass 1
setblock ~9 ~-2 ~36 tallgrass 1
setblock ~9 ~-2 ~52 tallgrass 1
setblock ~9 ~-2 ~55 tallgrass 1
fill ~9 ~-2 ~57 ~11 ~-2 ~57 tallgrass 1
setblock ~9 ~-2 ~61 tallgrass 1
setblock ~9 ~-2 ~68 tallgrass 1
setblock ~9 ~-2 ~84 tallgrass 1
fill ~10 ~-2 ~0 ~12 ~-2 ~0 tallgrass 1
fill ~10 ~-2 ~2 ~10 ~-2 ~8 tallgrass 1
setblock ~10 ~-2 ~25 tallgrass 1
fill ~10 ~-2 ~32 ~11 ~-2 ~32 tallgrass 1
fill ~10 ~-2 ~34 ~12 ~-2 ~34 tallgrass 1
setblock ~10 ~-2 ~47 tallgrass 1
setblock ~10 ~-2 ~51 tallgrass 1
setblock ~10 ~-2 ~54 tallgrass 1
setblock ~10 ~-2 ~73 tallgrass 1
fill ~10 ~-2 ~82 ~10 ~-2 ~83 tallgrass 1
fill ~10 ~-2 ~85 ~12 ~-2 ~85 tallgrass 1
fill ~10 ~-2 ~87 ~13 ~-2 ~87 tallgrass 1
setblock ~11 ~-2 ~3 tallgrass 1
fill ~11 ~-2 ~5 ~11 ~-2 ~6 tallgrass 1
fill ~11 ~-2 ~8 ~13 ~-2 ~8 tallgrass 1
setblock ~11 ~-2 ~15 tallgrass 1
setblock ~11 ~-2 ~22 tallgrass 1
setblock ~11 ~-2 ~33 tallgrass 1
fill ~11 ~-2 ~36 ~11 ~-2 ~37 tallgrass 1
fill ~11 ~-2 ~60 ~12 ~-2 ~60 tallgrass 1
fill ~11 ~-2 ~61 ~12 ~-2 ~61 tallgrass 1
fill ~11 ~-2 ~63 ~13 ~-2 ~63 tallgrass 1
fill ~11 ~-2 ~67 ~11 ~-2 ~69 tallgrass 1
setblock ~11 ~-2 ~71 tallgrass 1
setblock ~11 ~-2 ~74 tallgrass 1
fill ~11 ~-2 ~76 ~12 ~-2 ~76 tallgrass 1
fill ~11 ~-2 ~77 ~11 ~-2 ~78 tallgrass 1
setblock ~11 ~-2 ~80 tallgrass 1
setblock ~11 ~-2 ~84 tallgrass 1
fill ~12 ~-2 ~2 ~18 ~-2 ~2 tallgrass 1
fill ~12 ~-2 ~10 ~15 ~-2 ~10 tallgrass 1
fill ~12 ~-2 ~11 ~12 ~-2 ~10 tallgrass 1
fill ~12 ~-2 ~16 ~14 ~-2 ~16 tallgrass 1
setblock ~12 ~-2 ~19 tallgrass 1
fill ~12 ~-2 ~27 ~14 ~-2 ~27 tallgrass 1
setblock ~12 ~-2 ~35 tallgrass 1
fill ~12 ~-2 ~65 ~13 ~-2 ~65 tallgrass 1
fill ~12 ~-2 ~69 ~12 ~-2 ~70 tallgrass 1
setblock ~12 ~-2 ~73 tallgrass 1
fill ~12 ~-2 ~75 ~14 ~-2 ~75 tallgrass 1
fill ~12 ~-2 ~78 ~13 ~-2 ~78 tallgrass 1
fill ~12 ~-2 ~81 ~12 ~-2 ~82 tallgrass 1
fill ~12 ~-2 ~86 ~15 ~-2 ~86 tallgrass 1
setblock ~13 ~-2 ~1 tallgrass 1
fill ~13 ~-2 ~3 ~14 ~-2 ~3 tallgrass 1
fill ~13 ~-2 ~5 ~15 ~-2 ~5 tallgrass 1
fill ~13 ~-2 ~6 ~13 ~-2 ~10 tallgrass 1
fill ~13 ~-2 ~13 ~13 ~-2 ~14 tallgrass 1
fill ~13 ~-2 ~20 ~13 ~-2 ~21 tallgrass 1
fill ~13 ~-2 ~26 ~14 ~-2 ~26 tallgrass 1
setblock ~13 ~-2 ~30 tallgrass 1
fill ~13 ~-2 ~32 ~13 ~-2 ~33 tallgrass 1
setblock ~13 ~-2 ~37 tallgrass 1
setblock ~13 ~-2 ~62 tallgrass 1
fill ~13 ~-2 ~66 ~13 ~-2 ~67 tallgrass 1
fill ~13 ~-2 ~70 ~13 ~-2 ~72 tallgrass 1
fill ~13 ~-2 ~74 ~15 ~-2 ~74 tallgrass 1
setblock ~13 ~-2 ~82 tallgrass 1
setblock ~13 ~-2 ~84 tallgrass 1
setblock ~14 ~-2 ~9 tallgrass 1
setblock ~14 ~-2 ~11 tallgrass 1
fill ~14 ~-2 ~17 ~15 ~-2 ~17 tallgrass 1
fill ~14 ~-2 ~19 ~17 ~-2 ~19 tallgrass 1
fill ~14 ~-2 ~21 ~15 ~-2 ~21 tallgrass 1
fill ~14 ~-2 ~23 ~14 ~-2 ~24 tallgrass 1
fill ~14 ~-2 ~28 ~14 ~-2 ~29 tallgrass 1
setblock ~14 ~-2 ~35 tallgrass 1
setblock ~14 ~-2 ~71 tallgrass 1
setblock ~14 ~-2 ~77 tallgrass 1
fill ~14 ~-2 ~81 ~15 ~-2 ~81 tallgrass 1
setblock ~15 ~-2 ~14 tallgrass 1
setblock ~15 ~-2 ~18 tallgrass 1
setblock ~15 ~-2 ~25 tallgrass 1
setblock ~15 ~-2 ~29 tallgrass 1
setblock ~15 ~-2 ~31 tallgrass 1
setblock ~15 ~-2 ~73 tallgrass 1
fill ~15 ~-2 ~76 ~16 ~-2 ~76 tallgrass 1
fill ~16 ~-2 ~7 ~18 ~-2 ~7 tallgrass 1
fill ~16 ~-2 ~8 ~16 ~-2 ~9 tallgrass 1
setblock ~16 ~-2 ~13 tallgrass 1
setblock ~16 ~-2 ~16 tallgrass 1
fill ~16 ~-2 ~26 ~17 ~-2 ~26 tallgrass 1
setblock ~16 ~-2 ~79 tallgrass 1
setblock ~16 ~-2 ~84 tallgrass 1
fill ~17 ~-2 ~0 ~18 ~-2 ~0 tallgrass 1
fill ~17 ~-2 ~1 ~17 ~-2 ~0 tallgrass 1
setblock ~17 ~-2 ~4 tallgrass 1
fill ~17 ~-2 ~11 ~17 ~-2 ~12 tallgrass 1
setblock ~17 ~-2 ~20 tallgrass 1
fill ~17 ~-2 ~22 ~18 ~-2 ~22 tallgrass 1
setblock ~17 ~-2 ~25 tallgrass 1
setblock ~17 ~-2 ~83 tallgrass 1
setblock ~18 ~-2 ~6 tallgrass 1
setblock ~18 ~-2 ~8 tallgrass 1
setblock ~18 ~-2 ~13 tallgrass 1
setblock ~18 ~-2 ~78 tallgrass 1
fill ~18 ~-2 ~87 ~20 ~-2 ~87 tallgrass 1
fill ~19 ~-2 ~3 ~19 ~-2 ~5 tallgrass 1
setblock ~19 ~-2 ~6 yellow_flower 0
fill ~19 ~-2 ~11 ~21 ~-2 ~11 tallgrass 1
setblock ~19 ~-2 ~86 tallgrass 1
fill ~20 ~-2 ~4 ~22 ~-2 ~4 tallgrass 1
fill ~20 ~-2 ~7 ~20 ~-2 ~8 tallgrass 1
setblock ~20 ~-2 ~12 tallgrass 1
fill ~21 ~-2 ~0 ~25 ~-2 ~0 tallgrass 1
setblock ~21 ~-2 ~3 tallgrass 1
setblock ~21 ~-2 ~6 tallgrass 1
setblock ~21 ~-2 ~10 tallgrass 1
fill ~21 ~-2 ~85 ~21 ~-2 ~86 tallgrass 1
fill ~22 ~-2 ~1 ~23 ~-2 ~1 tallgrass 1
fill ~22 ~-2 ~7 ~23 ~-2 ~7 tallgrass 1
setblock ~22 ~-2 ~9 tallgrass 1
fill ~22 ~-2 ~83 ~23 ~-2 ~83 tallgrass 1
fill ~22 ~-2 ~86 ~22 ~-2 ~87 tallgrass 1
fill ~23 ~-2 ~5 ~23 ~-2 ~7 tallgrass 1
fill ~23 ~-2 ~79 ~23 ~-2 ~80 tallgrass 1
fill ~23 ~-2 ~85 ~25 ~-2 ~85 tallgrass 1
fill ~23 ~-2 ~87 ~24 ~-2 ~87 tallgrass 1
setblock ~24 ~-2 ~4 tallgrass 1
setblock ~24 ~-2 ~77 tallgrass 1
fill ~24 ~-2 ~80 ~26 ~-2 ~80 tallgrass 1
fill ~25 ~-2 ~2 ~25 ~-2 ~3 tallgrass 1
setblock ~25 ~-2 ~76 tallgrass 1
fill ~25 ~-2 ~79 ~26 ~-2 ~79 tallgrass 1
fill ~25 ~-2 ~81 ~28 ~-2 ~81 tallgrass 1
fill ~25 ~-2 ~82 ~25 ~-2 ~79 tallgrass 1
setblock ~25 ~-2 ~84 tallgrass 1
setblock ~26 ~-2 ~3 tallgrass 1
fill ~26 ~-2 ~78 ~31 ~-2 ~78 tallgrass 1
fill ~27 ~-2 ~0 ~28 ~-2 ~0 tallgrass 1
fill ~27 ~-2 ~75 ~27 ~-2 ~78 tallgrass 1
fill ~27 ~-2 ~82 ~28 ~-2 ~82 tallgrass 1
fill ~27 ~-2 ~83 ~28 ~-2 ~83 tallgrass 1
fill ~28 ~-2 ~79 ~34 ~-2 ~79 tallgrass 1
fill ~28 ~-2 ~80 ~28 ~-2 ~78 tallgrass 1
fill ~29 ~-2 ~1 ~30 ~-2 ~1 tallgrass 1
fill ~29 ~-2 ~76 ~29 ~-2 ~79 tallgrass 1
fill ~30 ~-2 ~41 ~37 ~-2 ~41 wool 7
fill ~30 ~-2 ~42 ~37 ~-2 ~42 wool 7
fill ~30 ~-2 ~43 ~37 ~-2 ~43 wool 7
fill ~30 ~-2 ~44 ~37 ~-2 ~44 wool 7
fill ~30 ~-2 ~45 ~37 ~-2 ~45 wool 7
fill ~30 ~-2 ~46 ~37 ~-2 ~46 wool 7
fill ~30 ~-2 ~47 ~37 ~-2 ~47 wool 7
fill ~30 ~-2 ~48 ~37 ~-2 ~48 wool 7
fill ~30 ~-2 ~81 ~33 ~-2 ~81 tallgrass 1
fill ~30 ~-2 ~82 ~30 ~-2 ~83 tallgrass 1
fill ~31 ~-2 ~76 ~32 ~-2 ~76 tallgrass 1
setblock ~31 ~-2 ~80 tallgrass 1
fill ~31 ~-2 ~83 ~35 ~-2 ~83 tallgrass 1
fill ~31 ~-2 ~84 ~36 ~-2 ~84 tallgrass 1
fill ~32 ~-2 ~82 ~35 ~-2 ~82 tallgrass 1
setblock ~33 ~-2 ~2 tallgrass 1
fill ~33 ~-2 ~27 ~34 ~-2 ~27 dirt 0
fill ~33 ~-2 ~28 ~34 ~-2 ~28 grass 0
fill ~33 ~-2 ~29 ~33 ~-2 ~31 grass 0
setblock ~33 ~-2 ~80 tallgrass 1
fill ~34 ~-2 ~1 ~35 ~-2 ~1 tallgrass 1
fill ~34 ~-2 ~29 ~57 ~-2 ~29 diamond_block 0
fill ~34 ~-2 ~30 ~57 ~-2 ~30 diamond_block 0
fill ~34 ~-2 ~31 ~57 ~-2 ~31 diamond_block 0
fill ~34 ~-2 ~32 ~34 ~-2 ~34 grass 0
fill ~34 ~-2 ~76 ~34 ~-2 ~79 tallgrass 1
setblock ~35 ~-2 ~0 tallgrass 1
fill ~35 ~-2 ~3 ~36 ~-2 ~3 tallgrass 1
fill ~35 ~-2 ~23 ~63 ~-2 ~23 diamond_block 0
fill ~35 ~-2 ~24 ~63 ~-2 ~24 diamond_block 0
fill ~35 ~-2 ~25 ~66 ~-2 ~25 diamond_block 0
fill ~35 ~-2 ~26 ~67 ~-2 ~26 diamond_block 0
fill ~35 ~-2 ~27 ~68 ~-2 ~27 diamond_block 0
fill ~35 ~-2 ~28 ~68 ~-2 ~28 diamond_block 0
fill ~35 ~-2 ~32 ~45 ~-2 ~32 diamond_block 0
fill ~35 ~-2 ~33 ~46 ~-2 ~33 diamond_block 0
fill ~35 ~-2 ~34 ~66 ~-2 ~34 diamond_block 0
fill ~35 ~-2 ~35 ~65 ~-2 ~35 diamond_block 0
fill ~35 ~-2 ~81 ~37 ~-2 ~81 tallgrass 1
fill ~36 ~-2 ~2 ~38 ~-2 ~2 tallgrass 1
fill ~36 ~-2 ~7 ~36 ~-2 ~8 tallgrass 1
fill ~36 ~-2 ~22 ~62 ~-2 ~22 diamond_block 0
fill ~36 ~-2 ~36 ~65 ~-2 ~36 diamond_block 0
fill ~36 ~-2 ~37 ~66 ~-2 ~37 diamond_block 0
fill ~36 ~-2 ~38 ~66 ~-2 ~38 diamond_block 0
fill ~36 ~-2 ~39 ~66 ~-2 ~39 diamond_block 0
fill ~36 ~-2 ~80 ~37 ~-2 ~80 tallgrass 1
setblock ~37 ~-2 ~5 tallgrass 1
fill ~37 ~-2 ~21 ~61 ~-2 ~21 diamond_block 0
fill ~37 ~-2 ~40 ~65 ~-2 ~40 diamond_block 0
fill ~37 ~-2 ~82 ~37 ~-2 ~83 tallgrass 1
setblock ~37 ~-2 ~87 tallgrass 1
setblock ~38 ~-2 ~4 tallgrass 1
fill ~38 ~-2 ~7 ~39 ~-2 ~7 tallgrass 1
fill ~38 ~-2 ~20 ~59 ~-2 ~20 diamond_block 0
fill ~38 ~-2 ~41 ~64 ~-2 ~41 diamond_block 0
setblock ~38 ~-2 ~85 tallgrass 1
setblock ~39 ~-2 ~5 tallgrass 1
fill ~39 ~-2 ~44 ~64 ~-2 ~44 diamond_block 0
fill ~39 ~-2 ~45 ~63 ~-2 ~45 diamond_block 0
fill ~39 ~-2 ~46 ~62 ~-2 ~46 diamond_block 0
fill ~39 ~-2 ~75 ~39 ~-2 ~76 tallgrass 1
setblock ~39 ~-2 ~80 tallgrass 1
fill ~39 ~-2 ~82 ~42 ~-2 ~82 tallgrass 1
fill ~40 ~-2 ~6 ~41 ~-2 ~6 tallgrass 1
fill ~40 ~-2 ~42 ~64 ~-2 ~42 diamond_block 0
fill ~40 ~-2 ~43 ~64 ~-2 ~43 diamond_block 0
fill ~40 ~-2 ~47 ~61 ~-2 ~47 diamond_block 0
setblock ~40 ~-2 ~79 tallgrass 1
fill ~40 ~-2 ~81 ~41 ~-2 ~81 tallgrass 1
fill ~41 ~-2 ~2 ~41 ~-2 ~3 tallgrass 1
fill ~41 ~-2 ~10 ~41 ~-2 ~12 tallgrass 1
fill ~41 ~-2 ~14 ~41 ~-2 ~17 tallgrass 1
fill ~41 ~-2 ~19 ~58 ~-2 ~19 diamond_block 0
fill ~41 ~-2 ~48 ~61 ~-2 ~48 diamond_block 0
setblock ~41 ~-2 ~67 tallgrass 1
fill ~41 ~-2 ~70 ~41 ~-2 ~71 tallgrass 1
fill ~41 ~-2 ~73 ~41 ~-2 ~78 tallgrass 1
setblock ~41 ~-2 ~85 tallgrass 1
setblock ~42 ~-2 ~5 tallgrass 1
fill ~42 ~-2 ~8 ~43 ~-2 ~8 tallgrass 1
fill ~42 ~-2 ~12 ~43 ~-2 ~12 tallgrass 1
fill ~42 ~-2 ~13 ~45 ~-2 ~13 tallgrass 1
fill ~42 ~-2 ~16 ~43 ~-2 ~16 tallgrass 1
fill ~42 ~-2 ~17 ~43 ~-2 ~17 tallgrass 1
fill ~42 ~-2 ~18 ~42 ~-2 ~16 tallgrass 1
setblock ~42 ~-2 ~64 tallgrass 1
fill ~42 ~-2 ~66 ~43 ~-2 ~66 tallgrass 1
fill ~42 ~-2 ~71 ~43 ~-2 ~71 tallgrass 1
fill ~42 ~-2 ~72 ~42 ~-2 ~71 tallgrass 1
fill ~42 ~-2 ~78 ~43 ~-2 ~78 tallgrass 1
setblock ~42 ~-2 ~80 tallgrass 1
setblock ~43 ~-2 ~1 tallgrass 1
setblock ~43 ~-2 ~6 tallgrass 1
fill ~43 ~-2 ~9 ~49 ~-2 ~9 tallgrass 1
fill ~43 ~-2 ~10 ~44 ~-2 ~10 tallgrass 1
fill ~43 ~-2 ~11 ~47 ~-2 ~11 tallgrass 1
fill ~43 ~-2 ~14 ~43 ~-2 ~17 tallgrass 1
fill ~43 ~-2 ~60 ~45 ~-2 ~60 tallgrass 1
fill ~43 ~-2 ~61 ~43 ~-2 ~60 tallgrass 1
setblock ~43 ~-2 ~63 tallgrass 1
setblock ~43 ~-2 ~67 tallgrass 1
fill ~43 ~-2 ~75 ~44 ~-2 ~75 tallgrass 1
setblock ~43 ~-2 ~77 tallgrass 1
setblock ~44 ~-2 ~0 tallgrass 1
setblock ~44 ~-2 ~4 tallgrass 1
fill ~44 ~-2 ~15 ~45 ~-2 ~15 tallgrass 1
fill ~44 ~-2 ~18 ~49 ~-2 ~18 diamond_block 0
fill ~44 ~-2 ~49 ~50 ~-2 ~49 diamond_block 0
fill ~44 ~-2 ~59 ~48 ~-2 ~59 tallgrass 1
fill ~44 ~-2 ~64 ~44 ~-2 ~65 tallgrass 1
fill ~44 ~-2 ~79 ~45 ~-2 ~79 tallgrass 1
setblock ~44 ~-2 ~86 tallgrass 1
fill ~45 ~-2 ~1 ~46 ~-2 ~1 tallgrass 1
setblock ~45 ~-2 ~6 tallgrass 1
setblock ~45 ~-2 ~12 tallgrass 1
fill ~45 ~-2 ~14 ~46 ~-2 ~14 tallgrass 1
setblock ~45 ~-2 ~16 tallgrass 1
fill ~45 ~-2 ~58 ~46 ~-2 ~58 tallgrass 1
setblock ~45 ~-2 ~63 tallgrass 1
setblock ~45 ~-2 ~67 tallgrass 1
fill ~45 ~-2 ~71 ~45 ~-2 ~72 tallgrass 1
fill ~45 ~-2 ~74 ~46 ~-2 ~74 tallgrass 1
fill ~45 ~-2 ~81 ~46 ~-2 ~81 tallgrass 1
setblock ~45 ~-2 ~85 tallgrass 1
setblock ~45 ~-2 ~87 red_flower 0
fill ~46 ~-2 ~0 ~48 ~-2 ~0 tallgrass 1
fill ~46 ~-2 ~2 ~46 ~-2 ~3 tallgrass 1
fill ~46 ~-2 ~7 ~46 ~-2 ~11 tallgrass 1
fill ~46 ~-2 ~53 ~47 ~-2 ~53 tallgrass 1
fill ~46 ~-2 ~57 ~49 ~-2 ~57 tallgrass 1
fill ~46 ~-2 ~62 ~47 ~-2 ~62 tallgrass 1
fill ~46 ~-2 ~64 ~50 ~-2 ~64 tallgrass 1
setblock ~46 ~-2 ~66 tallgrass 1
fill ~46 ~-2 ~75 ~46 ~-2 ~76 tallgrass 1
fill ~46 ~-2 ~78 ~47 ~-2 ~78 tallgrass 1
setblock ~46 ~-2 ~82 tallgrass 1
setblock ~47 ~-2 ~6 tallgrass 1
fill ~47 ~-2 ~12 ~49 ~-2 ~12 tallgrass 1
fill ~47 ~-2 ~13 ~47 ~-2 ~11 tallgrass 1
fill ~47 ~-2 ~16 ~47 ~-2 ~17 tallgrass 1
fill ~47 ~-2 ~50 ~49 ~-2 ~50 diamond_block 0
setblock ~47 ~-2 ~54 tallgrass 1
fill ~47 ~-2 ~56 ~49 ~-2 ~56 tallgrass 1
fill ~47 ~-2 ~60 ~53 ~-2 ~60 tallgrass 1
setblock ~47 ~-2 ~65 tallgrass 1
fill ~47 ~-2 ~70 ~49 ~-2 ~70 tallgrass 1
fill ~47 ~-2 ~71 ~48 ~-2 ~71 tallgrass 1
fill ~47 ~-2 ~72 ~47 ~-2 ~70 tallgrass 1
setblock ~47 ~-2 ~80 tallgrass 1
setblock ~47 ~-2 ~81 red_flower 0
setblock ~47 ~-2 ~86 tallgrass 1
fill ~48 ~-2 ~1 ~48 ~-2 ~3 tallgrass 1
fill ~48 ~-2 ~7 ~49 ~-2 ~7 tallgrass 1
fill ~48 ~-2 ~10 ~52 ~-2 ~10 tallgrass 1
fill ~48 ~-2 ~32 ~67 ~-2 ~32 diamond_block 0
fill ~48 ~-2 ~33 ~67 ~-2 ~33 diamond_block 0
fill ~48 ~-2 ~51 ~49 ~-2 ~51 tallgrass 1
fill ~48 ~-2 ~52 ~48 ~-2 ~51 tallgrass 1
setblock ~48 ~-2 ~61 tallgrass 1
fill ~48 ~-2 ~66 ~50 ~-2 ~66 tallgrass 1
fill ~48 ~-2 ~67 ~49 ~-2 ~67 tallgrass 1
setblock ~48 ~-2 ~74 red_flower 0
setblock ~48 ~-2 ~83 tallgrass 1
setblock ~49 ~-2 ~2 tallgrass 1
fill ~49 ~-2 ~5 ~51 ~-2 ~5 tallgrass 1
fill ~49 ~-2 ~8 ~51 ~-2 ~8 tallgrass 1
fill ~49 ~-2 ~13 ~49 ~-2 ~15 tallgrass 1
fill ~49 ~-2 ~53 ~49 ~-2 ~54 tallgrass 1
fill ~49 ~-2 ~63 ~50 ~-2 ~63 tallgrass 1
setblock ~49 ~-2 ~77 tallgrass 1
fill ~49 ~-2 ~80 ~50 ~-2 ~80 tallgrass 1
fill ~49 ~-2 ~84 ~58 ~-2 ~84 tallgrass 1
fill ~50 ~-2 ~0 ~51 ~-2 ~0 tallgrass 1
fill ~50 ~-2 ~1 ~51 ~-2 ~1 tallgrass 1
setblock ~50 ~-2 ~4 tallgrass 1
setblock ~50 ~-2 ~6 tallgrass 1
setblock ~50 ~-2 ~14 tallgrass 1
setblock ~50 ~-2 ~17 tallgrass 1
fill ~50 ~-2 ~50 ~53 ~-2 ~50 dirt 0
fill ~50 ~-2 ~55 ~51 ~-2 ~55 tallgrass 1
fill ~50 ~-2 ~58 ~51 ~-2 ~58 tallgrass 1
setblock ~50 ~-2 ~61 yellow_flower 0
fill ~50 ~-2 ~62 ~51 ~-2 ~62 tallgrass 1
fill ~50 ~-2 ~69 ~51 ~-2 ~69 tallgrass 1
fill ~50 ~-2 ~76 ~51 ~-2 ~76 tallgrass 1
fill ~50 ~-2 ~78 ~50 ~-2 ~81 tallgrass 1
fill ~50 ~-2 ~85 ~53 ~-2 ~85 tallgrass 1
setblock ~51 ~-2 ~2 tallgrass 1
fill ~51 ~-2 ~7 ~53 ~-2 ~7 tallgrass 1
setblock ~51 ~-2 ~12 tallgrass 1
setblock ~51 ~-2 ~59 yellow_flower 0
setblock ~51 ~-2 ~61 tallgrass 1
setblock ~51 ~-2 ~68 tallgrass 1
setblock ~51 ~-2 ~72 tallgrass 1
fill ~51 ~-2 ~74 ~51 ~-2 ~76 tallgrass 1
setblock ~51 ~-2 ~77 red_flower 0
setblock ~51 ~-2 ~79 tallgrass 1
fill ~51 ~-2 ~81 ~53 ~-2 ~81 tallgrass 1
fill ~51 ~-2 ~82 ~51 ~-2 ~81 tallgrass 1
setblock ~51 ~-2 ~86 red_flower 0
fill ~51 ~-2 ~87 ~54 ~-2 ~87 tallgrass 1
fill ~52 ~-2 ~4 ~58 ~-2 ~4 tallgrass 1
fill ~52 ~-2 ~6 ~55 ~-2 ~6 tallgrass 1
fill ~52 ~-2 ~18 ~54 ~-2 ~18 diamond_block 0
fill ~52 ~-2 ~49 ~54 ~-2 ~49 diamond_block 0
fill ~52 ~-2 ~53 ~52 ~-2 ~54 tallgrass 1
setblock ~52 ~-2 ~55 yellow_flower 0
setblock ~52 ~-2 ~56 tallgrass 1
fill ~52 ~-2 ~63 ~52 ~-2 ~64 tallgrass 1
fill ~52 ~-2 ~70 ~55 ~-2 ~70 tallgrass 1
fill ~52 ~-2 ~73 ~54 ~-2 ~73 tallgrass 1
setblock ~52 ~-2 ~77 tallgrass 1
setblock ~52 ~-2 ~80 tallgrass 1
setblock ~52 ~-2 ~86 tallgrass 1
fill ~53 ~-2 ~0 ~54 ~-2 ~0 tallgrass 1
fill ~53 ~-2 ~1 ~55 ~-2 ~1 tallgrass 1
fill ~53 ~-2 ~2 ~54 ~-2 ~2 tallgrass 1
fill ~53 ~-2 ~3 ~57 ~-2 ~3 tallgrass 1
setblock ~53 ~-2 ~9 tallgrass 1
setblock ~53 ~-2 ~12 tallgrass 1
setblock ~53 ~-2 ~16 tallgrass 1
fill ~53 ~-2 ~54 ~54 ~-2 ~54 tallgrass 1
fill ~53 ~-2 ~55 ~54 ~-2 ~55 tallgrass 1
setblock ~53 ~-2 ~56 yellow_flower 0
fill ~53 ~-2 ~57 ~53 ~-2 ~58 tallgrass 1
setblock ~53 ~-2 ~61 tallgrass 1
setblock ~53 ~-2 ~64 tallgrass 1
fill ~53 ~-2 ~66 ~53 ~-2 ~67 tallgrass 1
setblock ~53 ~-2 ~69 tallgrass 1
setblock ~53 ~-2 ~71 tallgrass 1
setblock ~53 ~-2 ~74 red_flower 0
setblock ~53 ~-2 ~75 tallgrass 1
setblock ~53 ~-2 ~78 tallgrass 1
fill ~53 ~-2 ~80 ~54 ~-2 ~80 red_flower 0
setblock ~54 ~-2 ~11 tallgrass 1
fill ~54 ~-2 ~50 ~56 ~-2 ~50 grass 0
setblock ~54 ~-2 ~56 tallgrass 1
setblock ~54 ~-2 ~58 tallgrass 1
setblock ~54 ~-2 ~59 yellow_flower 0
fill ~54 ~-2 ~62 ~54 ~-2 ~63 tallgrass 1
fill ~54 ~-2 ~67 ~54 ~-2 ~68 tallgrass 1
fill ~54 ~-2 ~72 ~56 ~-2 ~72 tallgrass 1
setblock ~54 ~-2 ~77 tallgrass 1
setblock ~54 ~-2 ~79 tallgrass 1
fill ~54 ~-2 ~81 ~54 ~-2 ~82 red_flower 0
fill ~54 ~-2 ~86 ~58 ~-2 ~86 tallgrass 1
setblock ~55 ~-2 ~5 tallgrass 1
setblock ~55 ~-2 ~8 tallgrass 1
fill ~55 ~-2 ~14 ~56 ~-2 ~14 tallgrass 1
setblock ~55 ~-2 ~49 grass 0
setblock ~55 ~-2 ~53 tallgrass 1
fill ~55 ~-2 ~57 ~56 ~-2 ~57 tallgrass 1
setblock ~55 ~-2 ~59 tallgrass 1
fill ~55 ~-2 ~61 ~56 ~-2 ~61 tallgrass 1
setblock ~55 ~-2 ~65 tallgrass 1
fill ~55 ~-2 ~75 ~55 ~-2 ~76 tallgrass 1
fill ~55 ~-2 ~78 ~60 ~-2 ~78 tallgrass 1
setblock ~55 ~-2 ~79 red_flower 0
fill ~55 ~-2 ~80 ~55 ~-2 ~81 tallgrass 1
fill ~55 ~-2 ~85 ~57 ~-2 ~85 tallgrass 1
setblock ~56 ~-2 ~2 tallgrass 1
fill ~56 ~-2 ~9 ~56 ~-2 ~10 tallgrass 1
setblock ~56 ~-2 ~15 tallgrass 1
fill ~56 ~-2 ~49 ~60 ~-2 ~49 diamond_block 0
fill ~56 ~-2 ~54 ~58 ~-2 ~54 tallgrass 1
setblock ~56 ~-2 ~62 yellow_flower 0
fill ~56 ~-2 ~63 ~56 ~-2 ~64 tallgrass 1
fill ~56 ~-2 ~66 ~56 ~-2 ~67 tallgrass 1
fill ~56 ~-2 ~69 ~57 ~-2 ~69 tallgrass 1
fill ~56 ~-2 ~74 ~59 ~-2 ~74 tallgrass 1
setblock ~56 ~-2 ~77 red_flower 0
fill ~56 ~-2 ~79 ~59 ~-2 ~79 tallgrass 1
setblock ~56 ~-2 ~82 tallgrass 1
setblock ~56 ~-2 ~87 red_flower 0
fill ~57 ~-2 ~6 ~57 ~-2 ~7 tallgrass 1
fill ~57 ~-2 ~10 ~57 ~-2 ~11 tallgrass 1
setblock ~57 ~-2 ~17 tallgrass 1
fill ~57 ~-2 ~50 ~59 ~-2 ~50 diamond_block 0
setblock ~57 ~-2 ~51 yellow_flower 0
fill ~57 ~-2 ~55 ~58 ~-2 ~55 tallgrass 1
fill ~57 ~-2 ~56 ~61 ~-2 ~56 tallgrass 1
setblock ~57 ~-2 ~60 tallgrass 1
setblock ~57 ~-2 ~68 tallgrass 1
setblock ~57 ~-2 ~70 tallgrass 1
fill ~57 ~-2 ~75 ~57 ~-2 ~76 red_flower 0
setblock ~57 ~-2 ~77 tallgrass 1
fill ~57 ~-2 ~80 ~59 ~-2 ~80 tallgrass 1
fill ~57 ~-2 ~81 ~57 ~-2 ~77 tallgrass 1
setblock ~57 ~-2 ~82 red_flower 0
fill ~57 ~-2 ~87 ~58 ~-2 ~87 tallgrass 1
fill ~58 ~-2 ~2 ~60 ~-2 ~2 tallgrass 1
fill ~58 ~-2 ~7 ~60 ~-2 ~7 tallgrass 1
setblock ~58 ~-2 ~9 tallgrass 1
setblock ~58 ~-2 ~51 tallgrass 1
setblock ~58 ~-2 ~58 tallgrass 1
fill ~58 ~-2 ~65 ~59 ~-2 ~65 tallgrass 1
fill ~58 ~-2 ~66 ~58 ~-2 ~65 tallgrass 1
setblock ~58 ~-2 ~73 tallgrass 1
fill ~58 ~-2 ~75 ~59 ~-2 ~75 tallgrass 1
fill ~58 ~-2 ~76 ~62 ~-2 ~76 tallgrass 1
fill ~58 ~-2 ~82 ~60 ~-2 ~82 tallgrass 1
fill ~59 ~-2 ~0 ~59 ~-2 ~3 tallgrass 1
fill ~59 ~-2 ~10 ~61 ~-2 ~10 tallgrass 1
fill ~59 ~-2 ~17 ~61 ~-2 ~17 tallgrass 1
fill ~59 ~-2 ~18 ~59 ~-2 ~19 tallgrass 1
fill ~59 ~-2 ~30 ~67 ~-2 ~30 diamond_block 0
fill ~59 ~-2 ~31 ~67 ~-2 ~31 diamond_block 0
fill ~59 ~-2 ~70 ~59 ~-2 ~72 tallgrass 1
fill ~59 ~-2 ~83 ~64 ~-2 ~83 tallgrass 1
setblock ~59 ~-2 ~85 tallgrass 1
fill ~60 ~-2 ~3 ~60 ~-2 ~5 tallgrass 1
fill ~60 ~-2 ~14 ~61 ~-2 ~14 tallgrass 1
fill ~60 ~-2 ~16 ~61 ~-2 ~16 tallgrass 1
fill ~60 ~-2 ~19 ~60 ~-2 ~20 tallgrass 1
fill ~60 ~-2 ~29 ~68 ~-2 ~29 diamond_block 0
setblock ~60 ~-2 ~50 grass 0
setblock ~60 ~-2 ~54 tallgrass 1
setblock ~60 ~-2 ~57 tallgrass 1
setblock ~60 ~-2 ~58 yellow_flower 0
fill ~60 ~-2 ~67 ~61 ~-2 ~67 tallgrass 1
fill ~60 ~-2 ~68 ~60 ~-2 ~67 tallgrass 1
fill ~60 ~-2 ~72 ~60 ~-2 ~73 tallgrass 1
setblock ~60 ~-2 ~77 tallgrass 1
setblock ~60 ~-2 ~81 tallgrass 1
fill ~60 ~-2 ~86 ~62 ~-2 ~86 tallgrass 1
fill ~61 ~-2 ~0 ~61 ~-2 ~1 tallgrass 1
fill ~61 ~-2 ~12 ~62 ~-2 ~12 tallgrass 1
fill ~61 ~-2 ~13 ~61 ~-2 ~12 tallgrass 1
setblock ~61 ~-2 ~18 tallgrass 1
setblock ~61 ~-2 ~49 grass 0
setblock ~61 ~-2 ~52 tallgrass 1
setblock ~61 ~-2 ~55 tallgrass 1
fill ~61 ~-2 ~58 ~61 ~-2 ~59 tallgrass 1
fill ~61 ~-2 ~64 ~61 ~-2 ~67 tallgrass 1
fill ~61 ~-2 ~70 ~61 ~-2 ~71 tallgrass 1
setblock ~61 ~-2 ~74 tallgrass 1
fill ~61 ~-2 ~79 ~66 ~-2 ~79 tallgrass 1
fill ~62 ~-2 ~1 ~63 ~-2 ~1 tallgrass 1
fill ~62 ~-2 ~2 ~63 ~-2 ~2 tallgrass 1
fill ~62 ~-2 ~3 ~62 ~-2 ~1 tallgrass 1
setblock ~62 ~-2 ~7 tallgrass 1
setblock ~62 ~-2 ~9 tallgrass 1
setblock ~62 ~-2 ~15 tallgrass 1
fill ~62 ~-2 ~19 ~62 ~-2 ~20 tallgrass 1
fill ~62 ~-2 ~47 ~65 ~-2 ~47 grass 0
fill ~62 ~-2 ~48 ~62 ~-2 ~47 grass 0
fill ~62 ~-2 ~49 ~63 ~-2 ~49 tallgrass 1
fill ~62 ~-2 ~57 ~64 ~-2 ~57 tallgrass 1
fill ~62 ~-2 ~60 ~66 ~-2 ~60 tallgrass 1
fill ~62 ~-2 ~61 ~64 ~-2 ~61 tallgrass 1
setblock ~62 ~-2 ~63 tallgrass 1
fill ~62 ~-2 ~72 ~62 ~-2 ~73 tallgrass 1
fill ~62 ~-2 ~78 ~63 ~-2 ~78 tallgrass 1
fill ~62 ~-2 ~80 ~63 ~-2 ~80 tallgrass 1
fill ~62 ~-2 ~82 ~64 ~-2 ~82 tallgrass 1
fill ~62 ~-2 ~84 ~65 ~-2 ~84 tallgrass 1
fill ~63 ~-2 ~0 ~64 ~-2 ~0 tallgrass 1
setblock ~63 ~-2 ~4 tallgrass 1
setblock ~63 ~-2 ~6 tallgrass 1
setblock ~63 ~-2 ~10 tallgrass 1
fill ~63 ~-2 ~13 ~63 ~-2 ~14 tallgrass 1
setblock ~63 ~-2 ~20 tallgrass 1
fill ~63 ~-2 ~46 ~66 ~-2 ~46 grass 0
setblock ~63 ~-2 ~51 tallgrass 1
fill ~63 ~-2 ~54 ~66 ~-2 ~54 tallgrass 1
fill ~63 ~-2 ~59 ~66 ~-2 ~59 tallgrass 1
fill ~63 ~-2 ~62 ~64 ~-2 ~62 tallgrass 1
setblock ~63 ~-2 ~75 tallgrass 1
fill ~63 ~-2 ~81 ~66 ~-2 ~81 tallgrass 1
setblock ~64 ~-2 ~5 tallgrass 1
setblock ~64 ~-2 ~7 tallgrass 1
setblock ~64 ~-2 ~12 tallgrass 1
setblock ~64 ~-2 ~19 tallgrass 1
setblock ~64 ~-2 ~21 tallgrass 1
fill ~64 ~-2 ~24 ~65 ~-2 ~24 tallgrass 1
fill ~64 ~-2 ~45 ~66 ~-2 ~45 grass 0
fill ~64 ~-2 ~56 ~65 ~-2 ~56 tallgrass 1
setblock ~64 ~-2 ~58 tallgrass 1
fill ~64 ~-2 ~73 ~65 ~-2 ~73 tallgrass 1
fill ~64 ~-2 ~77 ~66 ~-2 ~77 tallgrass 1
fill ~64 ~-2 ~85 ~65 ~-2 ~85 tallgrass 1
fill ~64 ~-2 ~87 ~65 ~-2 ~87 tallgrass 1
fill ~65 ~-2 ~2 ~67 ~-2 ~2 tallgrass 1
fill ~65 ~-2 ~15 ~66 ~-2 ~15 tallgrass 1
fill ~65 ~-2 ~41 ~67 ~-2 ~41 grass 0
fill ~65 ~-2 ~42 ~67 ~-2 ~42 grass 0
fill ~65 ~-2 ~43 ~66 ~-2 ~43 grass 0
fill ~65 ~-2 ~44 ~66 ~-2 ~44 grass 0
setblock ~65 ~-2 ~48 tallgrass 1
fill ~65 ~-2 ~50 ~67 ~-2 ~50 tallgrass 1
fill ~65 ~-2 ~51 ~67 ~-2 ~51 tallgrass 1
fill ~65 ~-2 ~52 ~65 ~-2 ~56 tallgrass 1
setblock ~65 ~-2 ~78 tallgrass 1
setblock ~65 ~-2 ~80 tallgrass 1
fill ~66 ~-2 ~0 ~67 ~-2 ~0 tallgrass 1
fill ~66 ~-2 ~1 ~66 ~-2 ~0 tallgrass 1
fill ~66 ~-2 ~4 ~68 ~-2 ~4 tallgrass 1
setblock ~66 ~-2 ~6 tallgrass 1
fill ~66 ~-2 ~9 ~67 ~-2 ~9 tallgrass 1
setblock ~66 ~-2 ~12 tallgrass 1
fill ~66 ~-2 ~22 ~66 ~-2 ~23 tallgrass 1
fill ~66 ~-2 ~35 ~67 ~-2 ~35 grass 0
fill ~66 ~-2 ~36 ~67 ~-2 ~36 grass 0
fill ~66 ~-2 ~40 ~67 ~-2 ~40 grass 0
fill ~66 ~-2 ~53 ~67 ~-2 ~53 tallgrass 1
setblock ~66 ~-2 ~55 tallgrass 1
fill ~66 ~-2 ~57 ~69 ~-2 ~57 tallgrass 1
fill ~66 ~-2 ~61 ~66 ~-2 ~62 tallgrass 1
fill ~66 ~-2 ~82 ~67 ~-2 ~82 tallgrass 1
setblock ~67 ~-2 ~5 tallgrass 1
fill ~67 ~-2 ~7 ~67 ~-2 ~9 tallgrass 1
setblock ~67 ~-2 ~16 tallgrass 1
fill ~67 ~-2 ~24 ~68 ~-2 ~24 tallgrass 1
fill ~67 ~-2 ~25 ~67 ~-2 ~24 tallgrass 1
setblock ~67 ~-2 ~34 grass 0
fill ~67 ~-2 ~37 ~67 ~-2 ~42 grass 0
fill ~67 ~-2 ~43 ~67 ~-2 ~44 tallgrass 1
fill ~67 ~-2 ~47 ~69 ~-2 ~47 tallgrass 1
fill ~67 ~-2 ~49 ~69 ~-2 ~49 tallgrass 1
fill ~67 ~-2 ~58 ~69 ~-2 ~58 tallgrass 1
fill ~67 ~-2 ~62 ~68 ~-2 ~62 tallgrass 1
fill ~67 ~-2 ~75 ~69 ~-2 ~75 tallgrass 1
fill ~67 ~-2 ~76 ~68 ~-2 ~76 tallgrass 1
setblock ~67 ~-2 ~78 tallgrass 1
setblock ~67 ~-2 ~83 tallgrass 1
setblock ~67 ~-2 ~87 tallgrass 1
setblock ~68 ~-2 ~1 tallgrass 1
setblock ~68 ~-2 ~11 tallgrass 1
fill ~68 ~-2 ~19 ~68 ~-2 ~20 tallgrass 1
setblock ~68 ~-2 ~23 tallgrass 1
fill ~68 ~-2 ~31 ~68 ~-2 ~32 grass 0
fill ~68 ~-2 ~33 ~68 ~-2 ~35 tallgrass 1
fill ~68 ~-2 ~41 ~69 ~-2 ~41 tallgrass 1
fill ~68 ~-2 ~42 ~68 ~-2 ~41 tallgrass 1
fill ~68 ~-2 ~44 ~69 ~-2 ~44 tallgrass 1
fill ~68 ~-2 ~45 ~69 ~-2 ~45 tallgrass 1
fill ~68 ~-2 ~54 ~69 ~-2 ~54 tallgrass 1
fill ~68 ~-2 ~55 ~69 ~-2 ~55 tallgrass 1
fill ~68 ~-2 ~59 ~68 ~-2 ~63 tallgrass 1
setblock ~68 ~-2 ~74 tallgrass 1
fill ~68 ~-2 ~80 ~68 ~-2 ~81 tallgrass 1
setblock ~69 ~-2 ~3 tallgrass 1
setblock ~69 ~-2 ~5 tallgrass 1
setblock ~69 ~-2 ~7 tallgrass 1
setblock ~69 ~-2 ~10 tallgrass 1
fill ~69 ~-2 ~21 ~69 ~-2 ~22 tallgrass 1
setblock ~69 ~-2 ~25 tallgrass 1
setblock ~69 ~-2 ~27 tallgrass 1
setblock ~69 ~-2 ~31 tallgrass 1
setblock ~69 ~-2 ~35 tallgrass 1
setblock ~69 ~-2 ~37 tallgrass 1
setblock ~69 ~-2 ~43 tallgrass 1
setblock ~69 ~-2 ~46 tallgrass 1
setblock ~69 ~-2 ~53 tallgrass 1
fill ~69 ~-2 ~60 ~69 ~-2 ~61 tallgrass 1
fill ~69 ~-2 ~65 ~69 ~-2 ~67 tallgrass 1
setblock ~69 ~-2 ~78 tallgrass 1
setblock ~69 ~-2 ~81 tallgrass 1
setblock ~69 ~-2 ~83 tallgrass 1
fill ~30 ~-1 ~41 ~37 ~-1 ~41 wool 7
fill ~30 ~-1 ~42 ~30 ~3 ~42 wool 7
fill ~30 ~-1 ~43 ~30 ~3 ~43 wool 7
fill ~30 ~-1 ~44 ~30 ~3 ~44 wool 7
fill ~30 ~-1 ~45 ~30 ~3 ~45 wool 7
fill ~30 ~-1 ~46 ~30 ~3 ~46 wool 7
fill ~30 ~-1 ~47 ~30 ~3 ~47 wool 7
fill ~30 ~-1 ~48 ~37 ~-1 ~48 wool 7
fill ~33 ~-1 ~26 ~33 ~-1 ~27 grass 0
fill ~34 ~-1 ~24 ~63 ~-1 ~24 diamond_block 0
fill ~34 ~-1 ~25 ~66 ~-1 ~25 diamond_block 0
fill ~34 ~-1 ~26 ~67 ~-1 ~26 diamond_block 0
setblock ~34 ~-1 ~27 dirt 0
fill ~35 ~-1 ~23 ~63 ~-1 ~23 diamond_block 0
fill ~35 ~-1 ~27 ~68 ~-1 ~27 diamond_block 0
fill ~35 ~-1 ~28 ~68 ~-1 ~28 diamond_block 0
fill ~35 ~-1 ~29 ~68 ~-1 ~29 diamond_block 0
fill ~35 ~-1 ~30 ~67 ~-1 ~30 diamond_block 0
fill ~35 ~-1 ~31 ~67 ~-1 ~31 diamond_block 0
fill ~35 ~-1 ~32 ~45 ~-1 ~32 diamond_block 0
fill ~35 ~-1 ~33 ~45 ~-1 ~33 diamond_block 0
fill ~35 ~-1 ~34 ~65 ~-1 ~34 diamond_block 0
fill ~35 ~-1 ~35 ~65 ~-1 ~35 diamond_block 0
fill ~36 ~-1 ~22 ~62 ~-1 ~22 diamond_block 0
fill ~36 ~-1 ~36 ~65 ~-1 ~36 diamond_block 0
fill ~36 ~-1 ~37 ~66 ~-1 ~37 diamond_block 0
fill ~36 ~-1 ~38 ~47 ~-1 ~38 diamond_block 0
fill ~36 ~-1 ~39 ~65 ~-1 ~39 diamond_block 0
fill ~36 ~-1 ~44 ~36 ~-1 ~45 glowstone 0
fill ~37 ~-1 ~21 ~61 ~-1 ~21 diamond_block 0
fill ~37 ~-1 ~40 ~65 ~-1 ~40 diamond_block 0
fill ~37 ~-1 ~42 ~37 ~1 ~42 wool 7
fill ~37 ~-1 ~43 ~37 ~1 ~43 wool 7
fill ~37 ~-1 ~44 ~37 ~1 ~44 wool 7
fill ~37 ~-1 ~45 ~37 ~1 ~45 wool 7
fill ~37 ~-1 ~46 ~37 ~1 ~46 wool 7
fill ~37 ~-1 ~47 ~37 ~1 ~47 wool 7
fill ~38 ~-1 ~20 ~59 ~-1 ~20 diamond_block 0
fill ~39 ~-1 ~44 ~64 ~-1 ~44 diamond_block 0
fill ~39 ~-1 ~45 ~63 ~-1 ~45 diamond_block 0
fill ~39 ~-1 ~46 ~62 ~-1 ~46 diamond_block 0
fill ~40 ~-1 ~41 ~64 ~-1 ~41 diamond_block 0
fill ~40 ~-1 ~42 ~64 ~-1 ~42 diamond_block 0
fill ~40 ~-1 ~43 ~64 ~-1 ~43 diamond_block 0
fill ~40 ~-1 ~47 ~60 ~-1 ~47 diamond_block 0
fill ~41 ~-1 ~19 ~55 ~-1 ~19 diamond_block 0
fill ~41 ~-1 ~48 ~59 ~-1 ~48 diamond_block 0
fill ~44 ~-1 ~18 ~49 ~-1 ~18 diamond_block 0
fill ~44 ~-1 ~49 ~50 ~-1 ~49 diamond_block 0
fill ~47 ~-1 ~50 ~49 ~-1 ~50 diamond_block 0
fill ~48 ~-1 ~32 ~66 ~-1 ~32 diamond_block 0
fill ~48 ~-1 ~33 ~66 ~-1 ~33 diamond_block 0
fill ~49 ~-1 ~38 ~66 ~-1 ~38 diamond_block 0
fill ~50 ~-1 ~50 ~53 ~-1 ~50 grass 0
setblock ~51 ~-1 ~49 grass 0
fill ~52 ~-1 ~18 ~54 ~-1 ~18 diamond_block 0
fill ~52 ~-1 ~49 ~53 ~-1 ~49 diamond_block 0
setblock ~68 ~-1 ~32 tallgrass 1
fill ~30 ~0 ~41 ~37 ~0 ~41 wool 7
fill ~30 ~0 ~48 ~37 ~0 ~48 wool 7
fill ~34 ~0 ~26 ~67 ~0 ~26 diamond_block 0
setblock ~34 ~0 ~27 grass 0
fill ~35 ~0 ~24 ~62 ~0 ~24 diamond_block 0
fill ~35 ~0 ~25 ~66 ~0 ~25 diamond_block 0
fill ~35 ~0 ~27 ~67 ~0 ~27 diamond_block 0
fill ~35 ~0 ~28 ~67 ~0 ~28 diamond_block 0
fill ~35 ~0 ~29 ~67 ~0 ~29 diamond_block 0
fill ~35 ~0 ~30 ~66 ~0 ~30 diamond_block 0
fill ~35 ~0 ~31 ~64 ~0 ~31 diamond_block 0
fill ~35 ~0 ~32 ~42 ~0 ~32 diamond_block 0
fill ~35 ~0 ~33 ~63 ~0 ~33 diamond_block 0
fill ~36 ~0 ~23 ~62 ~0 ~23 diamond_block 0
fill ~36 ~0 ~34 ~62 ~0 ~34 diamond_block 0
fill ~37 ~0 ~22 ~62 ~0 ~22 diamond_block 0
fill ~37 ~0 ~35 ~63 ~0 ~35 diamond_block 0
fill ~37 ~0 ~36 ~53 ~0 ~36 diamond_block 0
fill ~38 ~0 ~20 ~58 ~0 ~20 diamond_block 0
fill ~38 ~0 ~21 ~60 ~0 ~21 diamond_block 0
fill ~38 ~0 ~37 ~53 ~0 ~37 diamond_block 0
fill ~38 ~0 ~38 ~47 ~0 ~38 diamond_block 0
fill ~38 ~0 ~39 ~46 ~0 ~39 diamond_block 0
setblock ~39 ~0 ~40 diamond_block 0
fill ~40 ~0 ~41 ~63 ~0 ~41 diamond_block 0
fill ~40 ~0 ~42 ~62 ~0 ~42 diamond_block 0
fill ~40 ~0 ~43 ~60 ~0 ~43 diamond_block 0
fill ~40 ~0 ~44 ~60 ~0 ~44 diamond_block 0
fill ~40 ~0 ~45 ~59 ~0 ~45 diamond_block 0
fill ~40 ~0 ~46 ~59 ~0 ~46 diamond_block 0
fill ~40 ~0 ~47 ~55 ~0 ~47 diamond_block 0
fill ~41 ~0 ~40 ~63 ~0 ~40 diamond_block 0
fill ~41 ~0 ~48 ~41 ~-2 ~48 diamond_block 0
fill ~43 ~0 ~19 ~55 ~0 ~19 diamond_block 0
fill ~43 ~0 ~48 ~51 ~0 ~48 diamond_block 0
fill ~44 ~0 ~18 ~46 ~0 ~18 diamond_block 0
fill ~47 ~0 ~32 ~64 ~0 ~32 diamond_block 0
fill ~47 ~0 ~49 ~50 ~0 ~49 diamond_block 0
fill ~49 ~0 ~38 ~63 ~0 ~38 diamond_block 0
fill ~50 ~0 ~39 ~63 ~0 ~39 diamond_block 0
fill ~55 ~0 ~36 ~63 ~0 ~36 diamond_block 0
fill ~55 ~0 ~37 ~63 ~0 ~37 diamond_block 0
fill ~30 ~1 ~41 ~37 ~1 ~41 wool 7
fill ~30 ~1 ~48 ~37 ~1 ~48 wool 7
fill ~36 ~1 ~26 ~63 ~1 ~26 diamond_block 0
fill ~36 ~1 ~27 ~65 ~1 ~27 diamond_block 0
fill ~36 ~1 ~28 ~66 ~1 ~28 diamond_block 0
fill ~36 ~1 ~29 ~65 ~1 ~29 diamond_block 0
fill ~36 ~1 ~30 ~64 ~1 ~30 diamond_block 0
fill ~37 ~1 ~31 ~42 ~1 ~31 diamond_block 0
fill ~37 ~1 ~32 ~42 ~1 ~32 diamond_block 0
fill ~37 ~1 ~33 ~62 ~1 ~33 diamond_block 0
fill ~37 ~1 ~34 ~62 ~1 ~34 diamond_block 0
fill ~37 ~1 ~35 ~63 ~1 ~35 diamond_block 0
fill ~37 ~1 ~36 ~63 ~1 ~36 diamond_block 0
fill ~38 ~1 ~24 ~62 ~1 ~24 diamond_block 0
fill ~38 ~1 ~25 ~62 ~1 ~25 diamond_block 0
fill ~38 ~1 ~37 ~52 ~1 ~37 diamond_block 0
fill ~38 ~1 ~38 ~47 ~1 ~38 diamond_block 0
fill ~39 ~1 ~23 ~61 ~1 ~23 diamond_block 0
fill ~40 ~1 ~21 ~55 ~1 ~21 diamond_block 0
fill ~40 ~1 ~22 ~60 ~1 ~22 diamond_block 0
fill ~40 ~1 ~39 ~47 ~1 ~39 diamond_block 0
fill ~40 ~1 ~40 ~49 ~1 ~40 diamond_block 0
fill ~40 ~1 ~41 ~61 ~1 ~41 diamond_block 0
fill ~40 ~1 ~42 ~61 ~1 ~42 diamond_block 0
fill ~40 ~1 ~43 ~54 ~1 ~43 diamond_block 0
fill ~41 ~1 ~44 ~54 ~1 ~44 diamond_block 0
fill ~41 ~1 ~45 ~54 ~1 ~45 diamond_block 0
fill ~41 ~1 ~46 ~54 ~1 ~46 diamond_block 0
fill ~43 ~1 ~19 ~51 ~1 ~19 diamond_block 0
fill ~43 ~1 ~20 ~54 ~1 ~20 diamond_block 0
fill ~45 ~1 ~31 ~63 ~1 ~31 diamond_block 0
fill ~47 ~1 ~32 ~63 ~1 ~32 diamond_block 0
fill ~47 ~1 ~47 ~49 ~1 ~47 diamond_block 0
fill ~51 ~1 ~38 ~53 ~1 ~38 diamond_block 0
fill ~51 ~1 ~39 ~62 ~1 ~39 diamond_block 0
fill ~51 ~1 ~40 ~61 ~1 ~40 diamond_block 0
fill ~55 ~1 ~37 ~63 ~1 ~37 diamond_block 0
fill ~55 ~1 ~38 ~62 ~1 ~38 diamond_block 0
fill ~60 ~1 ~43 ~60 ~1 ~44 diamond_block 0
fill ~30 ~2 ~41 ~33 ~2 ~41 wool 7
fill ~30 ~2 ~48 ~33 ~2 ~48 wool 7
fill ~34 ~2 ~41 ~37 ~2 ~41 wool 11
fill ~34 ~2 ~48 ~37 ~2 ~48 wool 11
fill ~37 ~2 ~42 ~37 ~4 ~42 wool 11
fill ~37 ~2 ~43 ~37 ~4 ~43 wool 11
fill ~37 ~2 ~44 ~37 ~4 ~44 wool 11
fill ~37 ~2 ~45 ~37 ~4 ~45 wool 11
fill ~37 ~2 ~46 ~37 ~4 ~46 wool 11
fill ~37 ~2 ~47 ~37 ~4 ~47 wool 11
fill ~38 ~2 ~26 ~54 ~2 ~26 diamond_block 0
fill ~38 ~2 ~27 ~61 ~2 ~27 diamond_block 0
fill ~38 ~2 ~28 ~61 ~2 ~28 diamond_block 0
fill ~38 ~2 ~29 ~56 ~2 ~29 diamond_block 0
fill ~38 ~2 ~30 ~42 ~2 ~30 diamond_block 0
fill ~38 ~2 ~31 ~42 ~2 ~31 diamond_block 0
fill ~38 ~2 ~32 ~42 ~2 ~32 diamond_block 0
fill ~38 ~2 ~33 ~62 ~2 ~33 diamond_block 0
fill ~38 ~2 ~34 ~62 ~2 ~34 diamond_block 0
fill ~38 ~2 ~35 ~61 ~2 ~35 diamond_block 0
fill ~38 ~2 ~36 ~61 ~2 ~36 diamond_block 0
fill ~39 ~2 ~25 ~53 ~2 ~25 diamond_block 0
fill ~39 ~2 ~37 ~48 ~2 ~37 diamond_block 0
fill ~40 ~2 ~23 ~51 ~2 ~23 diamond_block 0
fill ~40 ~2 ~24 ~52 ~2 ~24 diamond_block 0
fill ~41 ~2 ~38 ~47 ~2 ~38 diamond_block 0
fill ~41 ~2 ~39 ~47 ~2 ~39 diamond_block 0
fill ~41 ~2 ~40 ~59 ~2 ~40 diamond_block 0
fill ~41 ~2 ~41 ~56 ~2 ~41 diamond_block 0
fill ~41 ~2 ~42 ~51 ~2 ~42 diamond_block 0
fill ~42 ~2 ~22 ~50 ~2 ~22 diamond_block 0
fill ~43 ~2 ~20 ~48 ~2 ~20 diamond_block 0
fill ~43 ~2 ~21 ~49 ~2 ~21 diamond_block 0
fill ~44 ~2 ~30 ~62 ~2 ~30 diamond_block 0
fill ~45 ~2 ~31 ~62 ~2 ~31 diamond_block 0
fill ~45 ~2 ~43 ~50 ~2 ~43 diamond_block 0
fill ~46 ~2 ~44 ~50 ~2 ~44 diamond_block 0
fill ~46 ~2 ~45 ~49 ~2 ~45 diamond_block 0
fill ~47 ~2 ~32 ~63 ~2 ~32 diamond_block 0
fill ~47 ~2 ~46 ~48 ~2 ~46 diamond_block 0
fill ~50 ~2 ~37 ~61 ~2 ~37 diamond_block 0
fill ~50 ~2 ~38 ~60 ~2 ~38 diamond_block 0
fill ~50 ~2 ~39 ~54 ~2 ~39 diamond_block 0
fill ~54 ~2 ~42 ~56 ~2 ~42 diamond_block 0
fill ~56 ~2 ~26 ~61 ~2 ~26 diamond_block 0
fill ~56 ~2 ~39 ~60 ~2 ~39 diamond_block 0
fill ~57 ~2 ~25 ~61 ~2 ~25 diamond_block 0
fill ~58 ~2 ~24 ~60 ~2 ~24 diamond_block 0
fill ~58 ~2 ~29 ~61 ~2 ~29 diamond_block 0
fill ~30 ~3 ~41 ~33 ~3 ~41 wool 7
fill ~30 ~3 ~48 ~33 ~3 ~48 wool 7
fill ~34 ~3 ~41 ~37 ~3 ~41 wool 11
fill ~34 ~3 ~48 ~37 ~3 ~48 wool 11
fill ~39 ~3 ~28 ~55 ~3 ~28 diamond_block 0
fill ~39 ~3 ~29 ~41 ~3 ~29 diamond_block 0
fill ~40 ~3 ~26 ~54 ~3 ~26 diamond_block 0
fill ~40 ~3 ~27 ~55 ~3 ~27 diamond_block 0
fill ~40 ~3 ~30 ~41 ~3 ~30 diamond_block 0
fill ~40 ~3 ~31 ~41 ~3 ~31 diamond_block 0
fill ~40 ~3 ~32 ~42 ~3 ~32 diamond_block 0
fill ~40 ~3 ~33 ~42 ~3 ~33 diamond_block 0
fill ~40 ~3 ~34 ~61 ~3 ~34 diamond_block 0
fill ~40 ~3 ~35 ~59 ~3 ~35 diamond_block 0
fill ~41 ~3 ~25 ~50 ~3 ~25 diamond_block 0
fill ~41 ~3 ~36 ~47 ~3 ~36 diamond_block 0
fill ~41 ~3 ~38 ~47 ~3 ~38 diamond_block 0
fill ~41 ~3 ~39 ~47 ~3 ~39 diamond_block 0
fill ~41 ~3 ~40 ~47 ~3 ~40 diamond_block 0
fill ~42 ~3 ~24 ~50 ~3 ~24 diamond_block 0
fill ~42 ~3 ~37 ~47 ~3 ~37 diamond_block 0
fill ~42 ~3 ~41 ~56 ~3 ~41 diamond_block 0
fill ~42 ~3 ~42 ~56 ~3 ~42 diamond_block 0
fill ~43 ~3 ~23 ~49 ~3 ~23 diamond_block 0
fill ~43 ~3 ~29 ~55 ~3 ~29 diamond_block 0
fill ~44 ~3 ~21 ~46 ~3 ~21 diamond_block 0
fill ~44 ~3 ~22 ~48 ~3 ~22 diamond_block 0
fill ~44 ~3 ~30 ~61 ~3 ~30 diamond_block 0
fill ~45 ~3 ~31 ~62 ~3 ~31 diamond_block 0
fill ~46 ~3 ~43 ~48 ~3 ~43 diamond_block 0
fill ~47 ~3 ~44 ~47 ~4 ~44 diamond_block 0
fill ~48 ~3 ~32 ~62 ~3 ~32 diamond_block 0
fill ~48 ~3 ~33 ~61 ~3 ~33 diamond_block 0
fill ~49 ~3 ~38 ~58 ~3 ~38 diamond_block 0
fill ~49 ~3 ~39 ~56 ~3 ~39 diamond_block 0
fill ~49 ~3 ~40 ~56 ~3 ~40 diamond_block 0
fill ~50 ~3 ~37 ~59 ~3 ~37 diamond_block 0
fill ~51 ~3 ~36 ~59 ~3 ~36 diamond_block 0
fill ~58 ~3 ~29 ~60 ~3 ~29 diamond_block 0
fill ~30 ~4 ~41 ~37 ~4 ~41 wool 11
fill ~30 ~4 ~42 ~30 ~4 ~48 wool 11
fill ~31 ~4 ~48 ~37 ~4 ~48 wool 11
fill ~40 ~4 ~30 ~53 ~4 ~30 diamond_block 0
fill ~40 ~4 ~31 ~54 ~4 ~31 diamond_block 0
fill ~40 ~4 ~33 ~43 ~4 ~33 diamond_block 0
fill ~40 ~4 ~41 ~55 ~4 ~41 diamond_block 0
fill ~41 ~4 ~27 ~53 ~4 ~27 diamond_block 0
fill ~41 ~4 ~34 ~43 ~4 ~34 diamond_block 0
fill ~41 ~4 ~35 ~46 ~4 ~35 diamond_block 0
fill ~41 ~4 ~37 ~46 ~4 ~37 diamond_block 0
fill ~41 ~4 ~38 ~46 ~4 ~38 diamond_block 0
fill ~41 ~4 ~39 ~56 ~4 ~39 diamond_block 0
fill ~41 ~4 ~40 ~56 ~4 ~40 diamond_block 0
fill ~42 ~4 ~29 ~53 ~4 ~29 diamond_block 0
fill ~42 ~4 ~32 ~54 ~4 ~32 diamond_block 0
fill ~42 ~4 ~36 ~46 ~4 ~36 diamond_block 0
fill ~42 ~4 ~42 ~49 ~4 ~42 diamond_block 0
fill ~43 ~4 ~26 ~51 ~4 ~26 diamond_block 0
fill ~44 ~4 ~28 ~53 ~4 ~28 diamond_block 0
fill ~45 ~4 ~24 ~45 ~4 ~32 diamond_block 0
fill ~46 ~4 ~25 ~49 ~4 ~25 diamond_block 0
setblock ~47 ~4 ~35 wool 7
fill ~47 ~4 ~43 ~48 ~4 ~43 diamond_block 0
fill ~49 ~4 ~33 ~58 ~4 ~33 diamond_block 0
fill ~49 ~4 ~34 ~58 ~4 ~34 diamond_block 0
fill ~49 ~4 ~38 ~56 ~4 ~38 diamond_block 0
fill ~50 ~4 ~35 ~58 ~4 ~35 diamond_block 0
fill ~50 ~4 ~36 ~58 ~4 ~36 diamond_block 0
fill ~50 ~4 ~37 ~59 ~4 ~37 diamond_block 0
fill ~51 ~4 ~42 ~52 ~4 ~42 diamond_block 0
fill ~31 ~5 ~41 ~38 ~5 ~41 wool 11
fill ~31 ~5 ~42 ~31 ~9 ~42 wool 11
fill ~31 ~5 ~43 ~31 ~9 ~43 wool 11
fill ~31 ~5 ~44 ~31 ~9 ~44 wool 11
fill ~31 ~5 ~45 ~31 ~9 ~45 wool 11
fill ~31 ~5 ~46 ~31 ~9 ~46 wool 11
fill ~31 ~5 ~47 ~31 ~9 ~47 wool 11
fill ~31 ~5 ~48 ~38 ~5 ~48 wool 11
fill ~37 ~5 ~44 ~37 ~5 ~45 glowstone 0
fill ~38 ~5 ~42 ~38 ~9 ~42 wool 11
fill ~38 ~5 ~43 ~38 ~9 ~43 wool 11
fill ~38 ~5 ~44 ~38 ~9 ~44 wool 11
fill ~38 ~5 ~45 ~38 ~9 ~45 wool 11
fill ~38 ~5 ~46 ~38 ~9 ~46 wool 11
fill ~38 ~5 ~47 ~38 ~9 ~47 wool 11
fill ~43 ~5 ~32 ~50 ~5 ~32 wool 7
fill ~43 ~5 ~33 ~50 ~5 ~33 wool 7
fill ~43 ~5 ~34 ~50 ~5 ~34 wool 7
fill ~43 ~5 ~35 ~46 ~5 ~35 wool 7
fill ~43 ~5 ~36 ~50 ~5 ~36 wool 7
fill ~43 ~5 ~37 ~50 ~5 ~37 wool 7
fill ~43 ~5 ~38 ~43 ~5 ~40 diamond_block 0
fill ~44 ~5 ~38 ~50 ~5 ~38 wool 7
fill ~44 ~5 ~39 ~45 ~5 ~39 diamond_block 0
fill ~44 ~5 ~40 ~45 ~5 ~40 diamond_block 0
fill ~45 ~5 ~27 ~47 ~5 ~27 diamond_block 0
fill ~45 ~5 ~28 ~47 ~5 ~28 diamond_block 0
fill ~45 ~5 ~29 ~47 ~5 ~29 diamond_block 0
fill ~46 ~5 ~39 ~48 ~5 ~39 wool 7
fill ~47 ~5 ~35 ~47 ~20 ~35 water 8
fill ~48 ~5 ~35 ~50 ~5 ~35 wool 7
fill ~49 ~5 ~39 ~49 ~5 ~40 diamond_block 0
fill ~50 ~5 ~39 ~50 ~8 ~39 wool 7
fill ~50 ~5 ~40 ~53 ~5 ~40 diamond_block 0
fill ~50 ~5 ~41 ~50 ~5 ~40 diamond_block 0
fill ~51 ~5 ~32 ~51 ~5 ~40 diamond_block 0
fill ~52 ~5 ~33 ~54 ~5 ~33 diamond_block 0
fill ~52 ~5 ~34 ~54 ~5 ~34 diamond_block 0
fill ~52 ~5 ~35 ~55 ~5 ~35 diamond_block 0
fill ~52 ~5 ~36 ~57 ~5 ~36 diamond_block 0
fill ~52 ~5 ~37 ~57 ~5 ~37 diamond_block 0
fill ~52 ~5 ~38 ~56 ~5 ~38 diamond_block 0
fill ~52 ~5 ~39 ~55 ~5 ~39 diamond_block 0
fill ~31 ~6 ~41 ~38 ~6 ~41 wool 11
fill ~31 ~6 ~48 ~38 ~6 ~48 wool 11
fill ~43 ~6 ~32 ~50 ~6 ~32 wool 7
fill ~43 ~6 ~33 ~44 ~6 ~33 wool 7
fill ~43 ~6 ~34 ~44 ~6 ~34 wool 7
fill ~43 ~6 ~35 ~44 ~6 ~35 wool 7
fill ~43 ~6 ~36 ~44 ~6 ~36 wool 7
fill ~43 ~6 ~37 ~44 ~6 ~37 wool 7
fill ~43 ~6 ~38 ~44 ~6 ~38 wool 7
fill ~43 ~6 ~39 ~50 ~6 ~39 wool 7
fill ~48 ~6 ~37 ~48 ~7 ~37 double_stone_slab 0
setblock ~48 ~6 ~38 stone_slab 8
fill ~49 ~6 ~35 ~49 ~6 ~36 stone_pressure_plate 0
setblock ~49 ~6 ~37 stone_slab 0
setblock ~49 ~6 ~38 double_stone_slab 0
fill ~50 ~6 ~33 ~50 ~8 ~33 wool 7
fill ~50 ~6 ~34 ~50 ~8 ~34 wool 7
fill ~50 ~6 ~35 ~50 ~6 ~36 iron_door 2
fill ~50 ~6 ~37 ~50 ~8 ~37 wool 7
fill ~50 ~6 ~38 ~50 ~8 ~38 wool 7
fill ~31 ~7 ~41 ~38 ~7 ~41 wool 11
fill ~31 ~7 ~48 ~38 ~7 ~48 wool 11
fill ~43 ~7 ~32 ~50 ~7 ~32 wool 7
fill ~43 ~7 ~33 ~44 ~7 ~33 wool 7
fill ~43 ~7 ~34 ~44 ~7 ~34 wool 7
fill ~43 ~7 ~35 ~44 ~7 ~35 wool 7
fill ~43 ~7 ~36 ~44 ~7 ~36 wool 7
fill ~43 ~7 ~37 ~44 ~7 ~37 wool 7
fill ~43 ~7 ~38 ~44 ~7 ~38 wool 7
fill ~43 ~7 ~39 ~50 ~7 ~39 wool 7
setblock ~46 ~7 ~38 stone_slab 8
setblock ~47 ~7 ~37 stone_slab 8
setblock ~47 ~7 ~38 double_stone_slab 0
setblock ~48 ~7 ~38 stone_slab 0
setblock ~49 ~7 ~34 torch 2
setblock ~49 ~7 ~37 torch 2
setblock ~50 ~7 ~35 iron_door 9
setblock ~50 ~7 ~36 iron_door 8
setblock ~51 ~7 ~34 stone_button 1
fill ~31 ~8 ~41 ~38 ~8 ~41 wool 11
fill ~31 ~8 ~48 ~38 ~8 ~48 wool 11
fill ~43 ~8 ~32 ~50 ~8 ~32 wool 7
fill ~43 ~8 ~33 ~44 ~8 ~33 wool 7
fill ~43 ~8 ~34 ~44 ~8 ~34 wool 7
fill ~43 ~8 ~35 ~44 ~8 ~35 wool 7
fill ~43 ~8 ~36 ~44 ~8 ~36 wool 7
fill ~43 ~8 ~37 ~44 ~8 ~37 wool 7
fill ~43 ~8 ~38 ~44 ~8 ~38 wool 7
fill ~43 ~8 ~39 ~50 ~8 ~39 wool 7
setblock ~45 ~8 ~37 stone_slab 8
setblock ~45 ~8 ~38 double_stone_slab 0
fill ~46 ~8 ~37 ~47 ~8 ~37 double_stone_slab 0
setblock ~46 ~8 ~38 stone_slab 0
setblock ~48 ~8 ~37 stone_slab 0
fill ~50 ~8 ~35 ~50 ~8 ~39 wool 7
fill ~31 ~9 ~41 ~38 ~9 ~41 wool 11
fill ~31 ~9 ~48 ~38 ~9 ~48 wool 11
fill ~43 ~9 ~32 ~46 ~9 ~32 wool 7
fill ~43 ~9 ~33 ~44 ~9 ~33 wool 7
fill ~43 ~9 ~34 ~44 ~9 ~34 wool 7
fill ~43 ~9 ~35 ~44 ~9 ~35 wool 7
fill ~43 ~9 ~36 ~44 ~9 ~36 wool 7
fill ~43 ~9 ~37 ~44 ~9 ~37 wool 7
fill ~43 ~9 ~38 ~44 ~9 ~38 wool 7
fill ~43 ~9 ~39 ~46 ~9 ~39 wool 7
setblock ~45 ~9 ~35 stone_slab 8
setblock ~45 ~9 ~36 double_stone_slab 0
setblock ~45 ~9 ~37 stone_slab 0
setblock ~46 ~9 ~36 stone_slab 8
fill ~46 ~9 ~37 ~46 ~8 ~37 double_stone_slab 0
fill ~47 ~9 ~32 ~50 ~9 ~32 wool 11
fill ~47 ~9 ~39 ~50 ~9 ~39 wool 11
fill ~50 ~9 ~33 ~50 ~21 ~33 wool 11
fill ~50 ~9 ~34 ~50 ~21 ~34 wool 11
fill ~50 ~9 ~35 ~50 ~13 ~35 wool 11
fill ~50 ~9 ~36 ~50 ~13 ~36 wool 11
fill ~50 ~9 ~37 ~50 ~21 ~37 wool 11
fill ~50 ~9 ~38 ~50 ~21 ~38 wool 11
fill ~32 ~10 ~41 ~39 ~10 ~41 wool 11
fill ~32 ~10 ~42 ~32 ~18 ~42 wool 11
fill ~32 ~10 ~43 ~32 ~18 ~43 wool 11
fill ~32 ~10 ~44 ~32 ~17 ~44 wool 11
fill ~32 ~10 ~45 ~32 ~17 ~45 wool 11
fill ~32 ~10 ~46 ~32 ~17 ~46 wool 11
fill ~32 ~10 ~47 ~32 ~17 ~47 wool 11
fill ~32 ~10 ~48 ~39 ~10 ~48 wool 11
fill ~38 ~10 ~44 ~38 ~10 ~45 glowstone 0
fill ~39 ~10 ~42 ~39 ~17 ~42 wool 11
fill ~39 ~10 ~43 ~39 ~17 ~43 wool 11
fill ~39 ~10 ~44 ~39 ~17 ~44 wool 11
fill ~39 ~10 ~45 ~39 ~17 ~45 wool 11
fill ~39 ~10 ~46 ~39 ~17 ~46 wool 11
fill ~39 ~10 ~47 ~39 ~17 ~47 wool 11
fill ~43 ~10 ~32 ~46 ~10 ~32 wool 7
fill ~43 ~10 ~33 ~44 ~10 ~33 wool 7
fill ~43 ~10 ~34 ~44 ~10 ~34 wool 7
fill ~43 ~10 ~35 ~44 ~10 ~35 wool 7
fill ~43 ~10 ~36 ~44 ~10 ~36 wool 7
fill ~43 ~10 ~37 ~44 ~10 ~37 wool 7
fill ~43 ~10 ~38 ~44 ~10 ~38 wool 7
fill ~43 ~10 ~39 ~46 ~10 ~39 wool 7
setblock ~45 ~10 ~33 stone_slab 8
setblock ~45 ~10 ~34 double_stone_slab 0
setblock ~45 ~10 ~35 stone_slab 0
setblock ~46 ~10 ~34 stone_slab 8
fill ~46 ~10 ~35 ~46 ~10 ~36 double_stone_slab 0
setblock ~46 ~10 ~37 stone_slab 0
fill ~47 ~10 ~32 ~50 ~10 ~32 wool 11
fill ~47 ~10 ~39 ~50 ~10 ~39 wool 11
fill ~32 ~11 ~41 ~39 ~11 ~41 wool 11
fill ~32 ~11 ~48 ~39 ~11 ~48 wool 11
fill ~43 ~11 ~32 ~50 ~11 ~32 wool 11
fill ~43 ~11 ~33 ~44 ~11 ~33 wool 11
fill ~43 ~11 ~34 ~44 ~11 ~34 wool 11
fill ~43 ~11 ~35 ~44 ~11 ~35 wool 11
fill ~43 ~11 ~36 ~44 ~11 ~36 wool 11
fill ~43 ~11 ~37 ~44 ~11 ~37 wool 11
fill ~43 ~11 ~38 ~44 ~11 ~38 wool 11
fill ~43 ~11 ~39 ~50 ~11 ~39 wool 11
setblock ~45 ~11 ~33 stone_slab 0
fill ~46 ~11 ~33 ~46 ~11 ~34 double_stone_slab 0
setblock ~46 ~11 ~35 stone_slab 0
setblock ~47 ~11 ~33 stone_slab 8
fill ~32 ~12 ~41 ~39 ~12 ~41 wool 11
fill ~32 ~12 ~48 ~39 ~12 ~48 wool 11
fill ~43 ~12 ~32 ~50 ~12 ~32 wool 11
fill ~43 ~12 ~33 ~44 ~12 ~33 wool 11
fill ~43 ~12 ~34 ~44 ~12 ~34 wool 11
fill ~43 ~12 ~35 ~44 ~12 ~35 wool 11
fill ~43 ~12 ~36 ~44 ~12 ~36 wool 11
fill ~43 ~12 ~37 ~44 ~12 ~37 wool 11
fill ~43 ~12 ~38 ~44 ~12 ~38 wool 11
fill ~43 ~12 ~39 ~50 ~12 ~39 wool 11
fill ~46 ~12 ~34 ~47 ~12 ~34 double_stone_slab 0
setblock ~47 ~12 ~33 stone_slab 0
setblock ~48 ~12 ~33 double_stone_slab 0
setblock ~48 ~12 ~34 stone_slab 8
setblock ~49 ~12 ~33 stone_slab 8
fill ~32 ~13 ~41 ~39 ~13 ~41 wool 11
fill ~32 ~13 ~48 ~39 ~13 ~48 wool 11
fill ~43 ~13 ~32 ~50 ~13 ~32 wool 11
fill ~43 ~13 ~33 ~44 ~13 ~33 wool 11
fill ~43 ~13 ~34 ~44 ~13 ~34 wool 11
fill ~43 ~13 ~35 ~43 ~11 ~35 wool 11
fill ~43 ~13 ~36 ~43 ~11 ~36 wool 11
fill ~43 ~13 ~37 ~44 ~13 ~37 wool 11
fill ~43 ~13 ~38 ~44 ~13 ~38 wool 11
fill ~43 ~13 ~39 ~50 ~13 ~39 wool 11
fill ~44 ~13 ~35 ~44 ~13 ~36 glowstone 0
setblock ~47 ~13 ~34 stone_slab 0
fill ~48 ~13 ~34 ~49 ~13 ~34 double_stone_slab 0
setblock ~49 ~13 ~33 stone_slab 0
setblock ~49 ~13 ~35 stone_slab 8
fill ~32 ~14 ~41 ~39 ~14 ~41 wool 11
fill ~32 ~14 ~48 ~39 ~14 ~48 wool 11
fill ~44 ~14 ~32 ~51 ~14 ~32 wool 11
fill ~44 ~14 ~33 ~44 ~24 ~33 wool 11
fill ~44 ~14 ~34 ~44 ~24 ~34 wool 11
fill ~44 ~14 ~35 ~44 ~24 ~35 wool 11
fill ~44 ~14 ~36 ~44 ~24 ~36 wool 11
fill ~44 ~14 ~37 ~44 ~17 ~37 wool 11
fill ~44 ~14 ~38 ~44 ~17 ~38 wool 11
fill ~44 ~14 ~39 ~51 ~14 ~39 wool 11
fill ~48 ~14 ~34 ~48 ~13 ~34 double_stone_slab 0
fill ~48 ~14 ~35 ~48 ~14 ~34 double_stone_slab 0
setblock ~48 ~14 ~36 stone_slab 8
setblock ~49 ~14 ~35 stone_slab 0
setblock ~49 ~14 ~36 double_stone_slab 0
setblock ~49 ~14 ~37 stone_slab 8
fill ~50 ~14 ~35 ~50 ~14 ~36 glowstone 0
fill ~51 ~14 ~33 ~51 ~19 ~33 wool 11
fill ~51 ~14 ~34 ~51 ~19 ~34 wool 11
fill ~51 ~14 ~35 ~51 ~19 ~35 wool 11
fill ~51 ~14 ~36 ~51 ~19 ~36 wool 11
fill ~51 ~14 ~37 ~51 ~19 ~37 wool 11
fill ~51 ~14 ~38 ~51 ~19 ~38 wool 11
fill ~32 ~15 ~41 ~39 ~15 ~41 wool 11
fill ~32 ~15 ~48 ~39 ~15 ~48 wool 11
fill ~44 ~15 ~32 ~51 ~15 ~32 wool 11
fill ~44 ~15 ~39 ~51 ~15 ~39 wool 11
setblock ~48 ~15 ~35 stone_slab 0
fill ~48 ~15 ~36 ~48 ~15 ~37 double_stone_slab 0
setblock ~48 ~15 ~38 stone_slab 8
setblock ~49 ~15 ~37 stone_slab 0
setblock ~49 ~15 ~38 double_stone_slab 0
fill ~50 ~15 ~35 ~50 ~18 ~35 wool 11
fill ~50 ~15 ~36 ~50 ~18 ~36 wool 11
fill ~32 ~16 ~41 ~39 ~16 ~41 wool 11
fill ~32 ~16 ~48 ~39 ~16 ~48 wool 11
fill ~44 ~16 ~32 ~51 ~16 ~32 wool 11
fill ~44 ~16 ~39 ~51 ~16 ~39 wool 11
setblock ~46 ~16 ~38 stone_slab 8
setblock ~47 ~16 ~37 stone_slab 8
setblock ~47 ~16 ~38 double_stone_slab 0
setblock ~48 ~16 ~37 double_stone_slab 0
setblock ~48 ~16 ~38 stone_slab 0
fill ~32 ~17 ~41 ~39 ~17 ~41 wool 11
fill ~32 ~17 ~48 ~39 ~17 ~48 wool 11
fill ~38 ~17 ~32 ~51 ~17 ~32 wool 11
fill ~38 ~17 ~33 ~44 ~17 ~33 wool 11
fill ~38 ~17 ~34 ~44 ~17 ~34 wool 11
fill ~38 ~17 ~35 ~44 ~17 ~35 wool 11
fill ~38 ~17 ~36 ~44 ~17 ~36 wool 11
fill ~38 ~17 ~37 ~44 ~17 ~37 wool 11
fill ~38 ~17 ~38 ~44 ~17 ~38 wool 11
fill ~38 ~17 ~39 ~51 ~17 ~39 wool 11
fill ~38 ~17 ~44 ~38 ~17 ~45 glowstone 0
fill ~45 ~17 ~36 ~48 ~17 ~36 stonebrick 0
setblock ~45 ~17 ~37 stone_slab 8
setblock ~45 ~17 ~38 double_stone_slab 0
fill ~46 ~17 ~37 ~47 ~17 ~37 double_stone_slab 0
setblock ~46 ~17 ~38 stone_slab 0
setblock ~48 ~17 ~37 stone_slab 0
fill ~30 ~18 ~33 ~37 ~18 ~33 wool 11
fill ~30 ~18 ~34 ~37 ~18 ~34 wool 11
fill ~30 ~18 ~35 ~37 ~18 ~35 wool 11
fill ~30 ~18 ~36 ~37 ~18 ~36 wool 11
fill ~30 ~18 ~37 ~37 ~18 ~37 wool 11
fill ~30 ~18 ~38 ~37 ~18 ~38 wool 11
fill ~30 ~18 ~39 ~51 ~18 ~39 wool 11
fill ~30 ~18 ~40 ~37 ~18 ~40 wool 11
fill ~31 ~18 ~41 ~33 ~18 ~41 wool 11
fill ~31 ~18 ~42 ~31 ~22 ~42 wool 11
fill ~31 ~18 ~43 ~31 ~22 ~43 wool 11
fill ~31 ~18 ~44 ~31 ~22 ~44 wool 11
fill ~31 ~18 ~45 ~31 ~22 ~45 wool 11
fill ~31 ~18 ~46 ~31 ~22 ~46 wool 11
fill ~31 ~18 ~47 ~31 ~22 ~47 wool 11
fill ~31 ~18 ~48 ~38 ~18 ~48 wool 11
fill ~32 ~18 ~44 ~32 ~18 ~45 glowstone 0
fill ~33 ~18 ~42 ~36 ~18 ~42 wool 11
fill ~33 ~18 ~43 ~36 ~18 ~43 wool 11
fill ~34 ~18 ~41 ~34 ~19 ~41 stonebrick 0
fill ~35 ~18 ~41 ~38 ~18 ~41 wool 11
setblock ~37 ~18 ~44 stone_slab 8
fill ~38 ~18 ~32 ~51 ~18 ~32 wool 11
fill ~38 ~18 ~35 ~38 ~18 ~36 glowstone 0
fill ~38 ~18 ~37 ~44 ~18 ~37 stone_slab 8
setblock ~38 ~18 ~38 stone_slab 0
fill ~38 ~18 ~42 ~38 ~22 ~42 wool 11
fill ~38 ~18 ~43 ~38 ~22 ~43 wool 11
fill ~38 ~18 ~44 ~38 ~22 ~44 wool 11
fill ~38 ~18 ~45 ~38 ~22 ~45 wool 11
fill ~38 ~18 ~46 ~38 ~22 ~46 wool 11
fill ~38 ~18 ~47 ~38 ~22 ~47 wool 11
fill ~39 ~18 ~36 ~44 ~18 ~36 wool 11
fill ~45 ~18 ~33 ~45 ~18 ~35 stone_slab 8
fill ~45 ~18 ~36 ~48 ~18 ~36 stonebrick 0
setblock ~45 ~18 ~37 double_stone_slab 0
setblock ~46 ~18 ~37 stone_slab 0
setblock ~49 ~18 ~36 stone_brick_stairs 7
fill ~30 ~19 ~33 ~37 ~19 ~33 wool 11
fill ~30 ~19 ~34 ~30 ~25 ~34 wool 11
fill ~30 ~19 ~35 ~30 ~25 ~35 wool 11
fill ~30 ~19 ~36 ~30 ~25 ~36 wool 11
fill ~30 ~19 ~37 ~30 ~25 ~37 wool 11
fill ~30 ~19 ~38 ~31 ~19 ~38 wool 11
fill ~30 ~19 ~39 ~31 ~19 ~39 wool 11
fill ~30 ~19 ~40 ~31 ~19 ~40 wool 11
setblock ~31 ~19 ~36 glowstone 0
fill ~31 ~19 ~37 ~37 ~19 ~37 stone_slab 8
fill ~31 ~19 ~41 ~31 ~22 ~41 wool 11
fill ~31 ~19 ~48 ~38 ~19 ~48 wool 11
fill ~32 ~19 ~36 ~44 ~19 ~36 wool 11
setblock ~32 ~19 ~38 double_stone_slab 0
setblock ~32 ~19 ~39 stone_slab 8
fill ~32 ~19 ~44 ~37 ~19 ~44 stonebrick 0
setblock ~33 ~19 ~38 stone_slab 0
fill ~33 ~19 ~39 ~35 ~19 ~39 glass 0
fill ~33 ~19 ~40 ~33 ~43 ~40 glass 0
fill ~33 ~19 ~41 ~33 ~43 ~41 glass 0
fill ~33 ~19 ~42 ~35 ~19 ~42 glass 0
setblock ~34 ~19 ~40 stonebrick 0
fill ~35 ~19 ~40 ~35 ~43 ~40 glass 0
fill ~35 ~19 ~41 ~35 ~43 ~41 glass 0
fill ~37 ~19 ~39 ~51 ~19 ~39 wool 11
fill ~37 ~19 ~40 ~37 ~25 ~40 wool 11
fill ~37 ~19 ~41 ~38 ~19 ~41 wool 11
fill ~37 ~19 ~42 ~37 ~22 ~42 stonebrick 0
fill ~37 ~19 ~43 ~37 ~22 ~43 stonebrick 0
fill ~38 ~19 ~32 ~51 ~19 ~32 wool 11
fill ~38 ~19 ~37 ~39 ~19 ~37 double_stone_slab 0
fill ~40 ~19 ~37 ~45 ~19 ~37 stone_slab 0
fill ~45 ~19 ~36 ~49 ~19 ~36 stonebrick 0
fill ~50 ~19 ~35 ~50 ~19 ~36 glowstone 0
fill ~30 ~20 ~33 ~37 ~20 ~33 wool 11
fill ~30 ~20 ~38 ~30 ~25 ~38 wool 11
fill ~30 ~20 ~39 ~30 ~23 ~39 wool 11
fill ~30 ~20 ~40 ~30 ~23 ~40 wool 11
fill ~31 ~20 ~36 ~44 ~20 ~36 wool 11
fill ~31 ~20 ~37 ~33 ~20 ~37 double_stone_slab 0
fill ~31 ~20 ~38 ~31 ~47 ~38 stonebrick 0
fill ~31 ~20 ~39 ~31 ~47 ~39 stonebrick 0
fill ~31 ~20 ~40 ~31 ~47 ~40 stonebrick 0
fill ~31 ~20 ~48 ~38 ~20 ~48 wool 11
setblock ~32 ~20 ~39 stone_slab 0
setblock ~32 ~20 ~40 double_stone_slab 0
setblock ~32 ~20 ~41 stone_slab 8
fill ~32 ~20 ~44 ~37 ~20 ~44 stonebrick 0
fill ~33 ~20 ~39 ~35 ~20 ~39 glass 0
fill ~33 ~20 ~42 ~35 ~20 ~42 glass 0
fill ~34 ~20 ~37 ~38 ~20 ~37 stone_slab 0
fill ~34 ~20 ~40 ~34 ~42 ~40 lava 8
fill ~34 ~20 ~41 ~34 ~42 ~41 lava 8
fill ~37 ~20 ~39 ~50 ~20 ~39 wool 11
fill ~37 ~20 ~41 ~38 ~20 ~41 wool 11
fill ~38 ~20 ~32 ~50 ~20 ~32 wool 11
fill ~45 ~20 ~36 ~49 ~20 ~36 stonebrick 0
fill ~50 ~20 ~35 ~50 ~21 ~35 wool 11
fill ~50 ~20 ~36 ~50 ~21 ~36 wool 11
fill ~30 ~21 ~33 ~37 ~21 ~33 wool 11
fill ~31 ~21 ~36 ~44 ~21 ~36 wool 11
fill ~31 ~21 ~37 ~31 ~22 ~37 stonebrick 0
fill ~31 ~21 ~48 ~38 ~21 ~48 wool 11
setblock ~32 ~21 ~37 stone_slab 0
setblock ~32 ~21 ~41 stone_slab 0
setblock ~32 ~21 ~42 double_stone_slab 0
setblock ~32 ~21 ~43 stone_slab 8
fill ~32 ~21 ~44 ~37 ~21 ~44 stonebrick 0
fill ~33 ~21 ~39 ~35 ~21 ~39 glass 0
fill ~33 ~21 ~42 ~35 ~21 ~42 glass 0
fill ~37 ~21 ~39 ~50 ~21 ~39 wool 11
fill ~37 ~21 ~41 ~38 ~21 ~41 wool 11
fill ~38 ~21 ~32 ~50 ~21 ~32 wool 11
fill ~45 ~21 ~36 ~46 ~21 ~36 stonebrick 0
fill ~46 ~21 ~35 ~46 ~22 ~35 double_stone_slab 0
fill ~47 ~21 ~34 ~47 ~22 ~34 double_stone_slab 0
setblock ~47 ~21 ~35 water 0
setblock ~47 ~21 ~36 double_stone_slab 0
setblock ~48 ~21 ~35 double_stone_slab 0
setblock ~48 ~21 ~36 stonebrick 0
fill ~49 ~21 ~35 ~49 ~21 ~36 glowstone 0
fill ~30 ~22 ~33 ~37 ~22 ~33 wool 11
fill ~30 ~22 ~41 ~30 ~45 ~41 wool 9
fill ~30 ~22 ~42 ~30 ~45 ~42 wool 9
fill ~31 ~22 ~36 ~44 ~22 ~36 wool 11
fill ~31 ~22 ~48 ~38 ~22 ~48 wool 11
setblock ~32 ~22 ~43 stone_slab 0
fill ~32 ~22 ~44 ~37 ~22 ~44 stonebrick 0
fill ~33 ~22 ~39 ~35 ~22 ~39 glass 0
fill ~33 ~22 ~42 ~35 ~22 ~42 glass 0
setblock ~33 ~22 ~43 double_stone_slab 0
setblock ~34 ~22 ~43 stone_slab 8
fill ~37 ~22 ~39 ~49 ~22 ~39 wool 11
fill ~37 ~22 ~41 ~38 ~22 ~41 wool 11
setblock ~37 ~22 ~45 glowstone 0
fill ~38 ~22 ~32 ~49 ~22 ~32 wool 11
fill ~45 ~22 ~36 ~46 ~22 ~36 stonebrick 0
fill ~47 ~22 ~35 ~47 ~22 ~36 glowstone 0
fill ~48 ~22 ~33 ~49 ~22 ~33 wool 11
fill ~48 ~22 ~34 ~49 ~22 ~34 wool 11
fill ~48 ~22 ~35 ~49 ~22 ~35 wool 11
fill ~48 ~22 ~36 ~49 ~22 ~36 wool 11
fill ~48 ~22 ~37 ~49 ~22 ~37 wool 11
fill ~48 ~22 ~38 ~49 ~22 ~38 wool 11
fill ~30 ~23 ~33 ~37 ~23 ~33 wool 11
fill ~30 ~23 ~43 ~30 ~23 ~48 wool 11
fill ~31 ~23 ~36 ~31 ~23 ~37 glowstone 0
fill ~31 ~23 ~41 ~31 ~47 ~41 stonebrick 0
fill ~31 ~23 ~42 ~31 ~47 ~42 stonebrick 0
fill ~31 ~23 ~43 ~31 ~47 ~43 stonebrick 0
fill ~31 ~23 ~44 ~36 ~23 ~44 stonebrick 0
setblock ~31 ~23 ~45 glowstone 0
fill ~31 ~23 ~48 ~37 ~23 ~48 wool 11
fill ~32 ~23 ~36 ~44 ~23 ~36 wool 11
fill ~33 ~23 ~39 ~35 ~23 ~39 glass 0
fill ~33 ~23 ~42 ~35 ~23 ~42 glass 0
setblock ~34 ~23 ~43 stone_slab 0
setblock ~35 ~23 ~43 double_stone_slab 0
setblock ~36 ~23 ~43 stone_slab 8
fill ~37 ~23 ~39 ~47 ~23 ~39 wool 11
fill ~37 ~23 ~41 ~37 ~25 ~41 wool 11
fill ~37 ~23 ~42 ~37 ~25 ~42 wool 11
fill ~37 ~23 ~43 ~37 ~25 ~43 wool 11
fill ~37 ~23 ~44 ~37 ~25 ~44 wool 11
fill ~37 ~23 ~45 ~37 ~25 ~45 wool 11
fill ~37 ~23 ~46 ~37 ~25 ~46 wool 11
fill ~37 ~23 ~47 ~37 ~25 ~47 wool 11
fill ~38 ~23 ~32 ~47 ~23 ~32 wool 11
fill ~45 ~23 ~35 ~45 ~23 ~36 glowstone 0
fill ~46 ~23 ~33 ~47 ~23 ~33 wool 11
fill ~46 ~23 ~34 ~47 ~23 ~34 wool 11
fill ~46 ~23 ~35 ~47 ~23 ~35 wool 11
fill ~46 ~23 ~36 ~47 ~23 ~36 wool 11
fill ~46 ~23 ~37 ~47 ~23 ~37 wool 11
fill ~46 ~23 ~38 ~47 ~23 ~38 wool 11
fill ~30 ~24 ~33 ~37 ~24 ~33 wool 11
fill ~30 ~24 ~39 ~30 ~45 ~39 wool 9
fill ~30 ~24 ~40 ~30 ~45 ~40 wool 9
fill ~30 ~24 ~43 ~30 ~45 ~43 wool 9
fill ~30 ~24 ~44 ~30 ~45 ~44 wool 9
fill ~30 ~24 ~45 ~30 ~25 ~45 wool 11
fill ~30 ~24 ~46 ~30 ~25 ~46 wool 11
fill ~30 ~24 ~47 ~30 ~25 ~47 wool 11
fill ~30 ~24 ~48 ~37 ~24 ~48 wool 11
fill ~31 ~24 ~37 ~36 ~24 ~37 wool 11
fill ~31 ~24 ~44 ~36 ~24 ~44 stonebrick 0
fill ~33 ~24 ~39 ~35 ~24 ~39 glass 0
fill ~33 ~24 ~42 ~35 ~24 ~42 glass 0
setblock ~36 ~24 ~41 stone_slab 8
setblock ~36 ~24 ~42 double_stone_slab 0
setblock ~36 ~24 ~43 stone_slab 0
fill ~37 ~24 ~36 ~37 ~24 ~37 glowstone 0
fill ~37 ~24 ~39 ~45 ~24 ~39 wool 11
fill ~38 ~24 ~32 ~40 ~24 ~32 wool 9
fill ~38 ~24 ~33 ~40 ~24 ~33 wool 9
fill ~38 ~24 ~34 ~38 ~24 ~35 wool 9
fill ~38 ~24 ~36 ~45 ~24 ~36 wool 11
fill ~38 ~24 ~37 ~45 ~24 ~37 wool 11
fill ~38 ~24 ~38 ~45 ~24 ~38 wool 11
fill ~39 ~24 ~34 ~45 ~24 ~34 wool 11
fill ~39 ~24 ~35 ~45 ~24 ~35 wool 11
fill ~41 ~24 ~32 ~45 ~24 ~32 wool 11
fill ~41 ~24 ~33 ~45 ~24 ~33 wool 11
fill ~30 ~25 ~33 ~36 ~25 ~33 wool 11
fill ~30 ~25 ~48 ~37 ~25 ~48 wool 11
fill ~31 ~25 ~37 ~37 ~25 ~37 wool 11
fill ~31 ~25 ~44 ~36 ~25 ~44 stonebrick 0
fill ~33 ~25 ~39 ~35 ~25 ~39 glass 0
fill ~33 ~25 ~42 ~35 ~25 ~42 glass 0
setblock ~36 ~25 ~39 stone_slab 8
setblock ~36 ~25 ~40 double_stone_slab 0
setblock ~36 ~25 ~41 stone_slab 0
fill ~37 ~25 ~33 ~37 ~45 ~33 wool 9
fill ~37 ~25 ~34 ~37 ~45 ~34 wool 9
fill ~37 ~25 ~35 ~37 ~45 ~35 wool 9
fill ~37 ~25 ~36 ~37 ~45 ~36 wool 9
fill ~37 ~25 ~38 ~37 ~25 ~48 wool 11
fill ~30 ~26 ~33 ~37 ~26 ~33 wool 9
fill ~30 ~26 ~34 ~30 ~45 ~34 wool 9
fill ~30 ~26 ~35 ~30 ~45 ~35 wool 9
fill ~30 ~26 ~36 ~30 ~45 ~36 wool 9
fill ~30 ~26 ~37 ~30 ~45 ~37 wool 9
fill ~30 ~26 ~38 ~30 ~45 ~38 wool 9
fill ~30 ~26 ~45 ~30 ~45 ~45 wool 9
fill ~30 ~26 ~46 ~30 ~45 ~46 wool 9
fill ~30 ~26 ~47 ~30 ~45 ~47 wool 9
fill ~30 ~26 ~48 ~37 ~26 ~48 wool 9
fill ~31 ~26 ~37 ~36 ~26 ~37 wool 11
fill ~31 ~26 ~44 ~36 ~26 ~44 stonebrick 0
fill ~33 ~26 ~39 ~35 ~26 ~39 glass 0
fill ~33 ~26 ~42 ~35 ~26 ~42 glass 0
setblock ~35 ~26 ~38 stone_slab 8
setblock ~36 ~26 ~38 double_stone_slab 0
setblock ~36 ~26 ~39 stone_slab 0
fill ~37 ~26 ~37 ~37 ~43 ~37 wool 9
fill ~37 ~26 ~38 ~37 ~43 ~38 wool 9
fill ~37 ~26 ~39 ~37 ~41 ~39 wool 9
fill ~37 ~26 ~40 ~37 ~41 ~40 wool 9
fill ~37 ~26 ~41 ~37 ~41 ~41 wool 9
fill ~37 ~26 ~42 ~37 ~41 ~42 wool 9
fill ~37 ~26 ~43 ~37 ~43 ~43 wool 9
fill ~37 ~26 ~44 ~37 ~43 ~44 wool 9
fill ~37 ~26 ~45 ~37 ~45 ~45 wool 9
fill ~37 ~26 ~46 ~37 ~45 ~46 wool 9
fill ~37 ~26 ~47 ~37 ~45 ~47 wool 9
fill ~30 ~27 ~33 ~37 ~27 ~33 wool 9
fill ~30 ~27 ~48 ~37 ~27 ~48 wool 9
fill ~31 ~27 ~37 ~36 ~27 ~37 wool 11
fill ~31 ~27 ~44 ~36 ~27 ~44 stonebrick 0
setblock ~33 ~27 ~38 stone_slab 8
fill ~33 ~27 ~39 ~35 ~27 ~39 glass 0
fill ~33 ~27 ~42 ~35 ~27 ~42 glass 0
setblock ~34 ~27 ~38 double_stone_slab 0
setblock ~35 ~27 ~38 stone_slab 0
fill ~30 ~28 ~33 ~37 ~28 ~33 wool 9
fill ~30 ~28 ~48 ~37 ~28 ~48 wool 9
fill ~31 ~28 ~37 ~36 ~28 ~37 wool 11
fill ~31 ~28 ~44 ~36 ~28 ~44 stonebrick 0
setblock ~32 ~28 ~38 double_stone_slab 0
setblock ~32 ~28 ~39 stone_slab 8
setblock ~33 ~28 ~38 stone_slab 0
fill ~33 ~28 ~39 ~35 ~28 ~39 glass 0
fill ~33 ~28 ~42 ~35 ~28 ~42 glass 0
fill ~30 ~29 ~33 ~37 ~29 ~33 wool 9
fill ~30 ~29 ~48 ~37 ~29 ~48 wool 9
fill ~31 ~29 ~37 ~36 ~29 ~37 wool 11
fill ~31 ~29 ~44 ~36 ~29 ~44 stonebrick 0
setblock ~32 ~29 ~39 stone_slab 0
setblock ~32 ~29 ~40 double_stone_slab 0
setblock ~32 ~29 ~41 stone_slab 8
fill ~33 ~29 ~39 ~35 ~29 ~39 glass 0
fill ~33 ~29 ~42 ~35 ~29 ~42 glass 0
fill ~30 ~30 ~33 ~37 ~30 ~33 wool 9
fill ~30 ~30 ~48 ~37 ~30 ~48 wool 9
fill ~31 ~30 ~37 ~36 ~30 ~37 wool 11
fill ~31 ~30 ~44 ~36 ~30 ~44 stonebrick 0
setblock ~32 ~30 ~41 stone_slab 0
setblock ~32 ~30 ~42 double_stone_slab 0
setblock ~32 ~30 ~43 stone_slab 8
fill ~33 ~30 ~34 ~34 ~30 ~34 glowstone 0
fill ~33 ~30 ~39 ~35 ~30 ~39 glass 0
fill ~33 ~30 ~42 ~35 ~30 ~42 glass 0
fill ~33 ~30 ~47 ~34 ~30 ~47 glowstone 0
fill ~30 ~31 ~33 ~37 ~31 ~33 wool 9
fill ~30 ~31 ~48 ~37 ~31 ~48 wool 9
fill ~31 ~31 ~37 ~36 ~31 ~37 wool 11
fill ~31 ~31 ~44 ~36 ~31 ~44 stonebrick 0
setblock ~32 ~31 ~43 stone_slab 0
fill ~33 ~31 ~39 ~35 ~31 ~39 glass 0
fill ~33 ~31 ~42 ~35 ~31 ~42 glass 0
setblock ~33 ~31 ~43 double_stone_slab 0
setblock ~34 ~31 ~43 stone_slab 8
fill ~30 ~32 ~33 ~37 ~32 ~33 wool 9
fill ~30 ~32 ~48 ~37 ~32 ~48 wool 9
fill ~31 ~32 ~37 ~36 ~32 ~37 wool 11
fill ~31 ~32 ~44 ~36 ~32 ~44 stonebrick 0
fill ~33 ~32 ~39 ~35 ~32 ~39 glass 0
fill ~33 ~32 ~42 ~35 ~32 ~42 glass 0
setblock ~34 ~32 ~43 stone_slab 0
setblock ~35 ~32 ~43 double_stone_slab 0
setblock ~36 ~32 ~43 stone_slab 8
fill ~30 ~33 ~33 ~37 ~33 ~33 wool 9
fill ~30 ~33 ~48 ~37 ~33 ~48 wool 9
fill ~31 ~33 ~37 ~36 ~33 ~37 wool 11
fill ~31 ~33 ~44 ~36 ~33 ~44 stonebrick 0
fill ~33 ~33 ~39 ~35 ~33 ~39 glass 0
fill ~33 ~33 ~42 ~35 ~33 ~42 glass 0
setblock ~36 ~33 ~41 stone_slab 8
setblock ~36 ~33 ~42 double_stone_slab 0
setblock ~36 ~33 ~43 stone_slab 0
fill ~30 ~34 ~33 ~37 ~34 ~33 wool 9
fill ~30 ~34 ~48 ~37 ~34 ~48 wool 9
fill ~31 ~34 ~37 ~36 ~34 ~37 wool 11
fill ~31 ~34 ~44 ~36 ~34 ~44 stonebrick 0
fill ~33 ~34 ~39 ~35 ~34 ~39 glass 0
fill ~33 ~34 ~42 ~35 ~34 ~42 glass 0
setblock ~36 ~34 ~39 stone_slab 8
setblock ~36 ~34 ~40 double_stone_slab 0
setblock ~36 ~34 ~41 stone_slab 0
fill ~30 ~35 ~33 ~37 ~35 ~33 wool 9
fill ~30 ~35 ~48 ~37 ~35 ~48 wool 9
fill ~31 ~35 ~37 ~36 ~35 ~37 wool 11
fill ~31 ~35 ~44 ~36 ~35 ~44 stonebrick 0
fill ~33 ~35 ~39 ~35 ~35 ~39 glass 0
fill ~33 ~35 ~42 ~35 ~35 ~42 glass 0
setblock ~35 ~35 ~38 stone_slab 8
setblock ~36 ~35 ~38 double_stone_slab 0
setblock ~36 ~35 ~39 stone_slab 0
fill ~30 ~36 ~33 ~37 ~36 ~33 wool 9
fill ~30 ~36 ~48 ~37 ~36 ~48 wool 9
fill ~31 ~36 ~37 ~36 ~36 ~37 wool 11
fill ~31 ~36 ~44 ~36 ~36 ~44 stonebrick 0
setblock ~33 ~36 ~38 stone_slab 8
fill ~33 ~36 ~39 ~35 ~36 ~39 glass 0
fill ~33 ~36 ~42 ~35 ~36 ~42 glass 0
setblock ~34 ~36 ~38 double_stone_slab 0
setblock ~35 ~36 ~38 stone_slab 0
fill ~30 ~37 ~33 ~37 ~37 ~33 wool 9
fill ~30 ~37 ~48 ~37 ~37 ~48 wool 9
fill ~31 ~37 ~36 ~31 ~37 ~37 glowstone 0
fill ~31 ~37 ~44 ~36 ~37 ~44 stonebrick 0
setblock ~31 ~37 ~45 glowstone 0
fill ~32 ~37 ~37 ~35 ~37 ~37 wool 11
setblock ~32 ~37 ~38 double_stone_slab 0
setblock ~32 ~37 ~39 stone_slab 8
setblock ~33 ~37 ~38 stone_slab 0
fill ~33 ~37 ~39 ~35 ~37 ~39 glass 0
fill ~33 ~37 ~42 ~35 ~37 ~42 glass 0
fill ~36 ~37 ~36 ~36 ~37 ~37 glowstone 0
setblock ~36 ~37 ~45 glowstone 0
fill ~41 ~37 ~38 ~42 ~37 ~38 wool 12
fill ~41 ~37 ~39 ~42 ~37 ~39 wool 12
fill ~41 ~37 ~40 ~41 ~37 ~41 glowstone 0
fill ~41 ~37 ~42 ~42 ~37 ~42 wool 12
fill ~41 ~37 ~43 ~42 ~37 ~43 wool 12
fill ~42 ~37 ~40 ~42 ~47 ~40 wool 12
fill ~42 ~37 ~41 ~42 ~47 ~41 wool 12
fill ~30 ~38 ~33 ~37 ~38 ~33 wool 9
fill ~30 ~38 ~48 ~37 ~38 ~48 wool 9
fill ~31 ~38 ~37 ~36 ~38 ~37 wool 11
fill ~31 ~38 ~44 ~36 ~38 ~44 stonebrick 0
setblock ~32 ~38 ~39 stone_slab 0
setblock ~32 ~38 ~40 double_stone_slab 0
setblock ~32 ~38 ~41 stone_slab 8
fill ~33 ~38 ~39 ~35 ~38 ~39 glass 0
fill ~33 ~38 ~42 ~35 ~38 ~42 glass 0
fill ~40 ~38 ~38 ~42 ~38 ~38 wool 12
fill ~40 ~38 ~39 ~42 ~38 ~39 wool 12
fill ~40 ~38 ~40 ~40 ~38 ~41 glowstone 0
fill ~40 ~38 ~42 ~42 ~38 ~42 wool 12
fill ~40 ~38 ~43 ~42 ~38 ~43 wool 12
fill ~41 ~38 ~36 ~42 ~38 ~36 wool 12
fill ~41 ~38 ~37 ~42 ~38 ~37 wool 12
fill ~41 ~38 ~40 ~41 ~38 ~45 wool 12
fill ~42 ~38 ~44 ~42 ~50 ~44 wool 12
fill ~42 ~38 ~45 ~42 ~49 ~45 wool 12
fill ~30 ~39 ~33 ~37 ~39 ~33 wool 9
fill ~30 ~39 ~48 ~37 ~39 ~48 wool 9
fill ~31 ~39 ~37 ~36 ~39 ~37 wool 11
fill ~31 ~39 ~44 ~36 ~39 ~44 stonebrick 0
setblock ~32 ~39 ~41 stone_slab 0
setblock ~32 ~39 ~42 double_stone_slab 0
setblock ~32 ~39 ~43 stone_slab 8
fill ~33 ~39 ~39 ~35 ~39 ~39 glass 0
fill ~33 ~39 ~42 ~35 ~39 ~42 glass 0
fill ~39 ~39 ~38 ~39 ~44 ~38 wool 12
fill ~39 ~39 ~39 ~39 ~44 ~39 wool 12
fill ~39 ~39 ~40 ~39 ~40 ~40 glowstone 0
fill ~39 ~39 ~41 ~39 ~40 ~41 glowstone 0
fill ~39 ~39 ~42 ~39 ~44 ~42 wool 12
fill ~39 ~39 ~43 ~39 ~44 ~43 wool 12
fill ~40 ~39 ~37 ~42 ~39 ~37 wool 12
fill ~40 ~39 ~44 ~42 ~39 ~44 wool 12
fill ~41 ~39 ~36 ~42 ~39 ~36 wool 12
fill ~41 ~39 ~45 ~41 ~41 ~45 wool 12
fill ~42 ~39 ~38 ~42 ~47 ~38 wool 12
fill ~42 ~39 ~39 ~42 ~47 ~39 wool 12
fill ~42 ~39 ~42 ~42 ~47 ~42 wool 12
fill ~42 ~39 ~43 ~42 ~47 ~43 wool 12
fill ~30 ~40 ~23 ~37 ~40 ~23 planks 2
fill ~30 ~40 ~24 ~37 ~40 ~24 planks 2
fill ~30 ~40 ~25 ~37 ~40 ~25 wool 9
fill ~30 ~40 ~26 ~37 ~40 ~26 wool 9
fill ~30 ~40 ~27 ~37 ~40 ~27 wool 9
fill ~30 ~40 ~28 ~37 ~40 ~28 wool 9
fill ~30 ~40 ~29 ~37 ~40 ~29 wool 9
fill ~30 ~40 ~30 ~37 ~40 ~30 wool 9
fill ~30 ~40 ~31 ~37 ~40 ~31 wool 9
fill ~30 ~40 ~32 ~37 ~40 ~32 wool 9
fill ~30 ~40 ~33 ~30 ~45 ~33 wool 9
fill ~30 ~40 ~48 ~30 ~45 ~48 wool 9
fill ~30 ~40 ~49 ~37 ~40 ~49 wool 9
fill ~30 ~40 ~50 ~37 ~40 ~50 wool 9
fill ~30 ~40 ~51 ~37 ~40 ~51 wool 9
fill ~30 ~40 ~52 ~37 ~40 ~52 wool 9
fill ~30 ~40 ~53 ~37 ~40 ~53 wool 9
fill ~30 ~40 ~54 ~37 ~40 ~54 wool 9
fill ~30 ~40 ~55 ~37 ~40 ~55 wool 9
fill ~30 ~40 ~56 ~37 ~40 ~56 wool 9
fill ~30 ~40 ~57 ~37 ~40 ~57 planks 2
fill ~30 ~40 ~58 ~37 ~40 ~58 planks 2
fill ~31 ~40 ~37 ~36 ~40 ~37 wool 11
fill ~31 ~40 ~44 ~36 ~40 ~44 wool 11
setblock ~32 ~40 ~43 stone_slab 0
fill ~33 ~40 ~33 ~34 ~40 ~33 glowstone 0
fill ~33 ~40 ~39 ~35 ~40 ~39 glass 0
fill ~33 ~40 ~42 ~35 ~40 ~42 glass 0
setblock ~33 ~40 ~43 double_stone_slab 0
fill ~33 ~40 ~48 ~34 ~40 ~48 glowstone 0
setblock ~34 ~40 ~43 stone_slab 8
fill ~37 ~40 ~48 ~37 ~45 ~48 wool 9
fill ~39 ~40 ~37 ~39 ~44 ~37 wool 12
fill ~39 ~40 ~44 ~39 ~44 ~44 wool 12
fill ~40 ~40 ~36 ~42 ~40 ~36 wool 12
fill ~40 ~40 ~45 ~40 ~41 ~45 wool 12
fill ~41 ~40 ~35 ~42 ~40 ~35 wool 12
fill ~41 ~40 ~46 ~42 ~40 ~46 wool 12
fill ~42 ~40 ~37 ~42 ~50 ~37 wool 12
fill ~30 ~41 ~19 ~37 ~41 ~19 planks 2
fill ~30 ~41 ~20 ~37 ~41 ~20 planks 2
fill ~30 ~41 ~21 ~37 ~41 ~21 planks 2
fill ~30 ~41 ~22 ~37 ~41 ~22 planks 2
fill ~30 ~41 ~23 ~30 ~47 ~23 planks 2
fill ~30 ~41 ~24 ~30 ~47 ~24 planks 2
fill ~30 ~41 ~25 ~30 ~47 ~25 wool 9
fill ~30 ~41 ~26 ~30 ~47 ~26 wool 9
fill ~30 ~41 ~27 ~30 ~47 ~27 wool 9
fill ~30 ~41 ~28 ~30 ~47 ~28 wool 9
fill ~30 ~41 ~29 ~30 ~47 ~29 wool 9
fill ~30 ~41 ~30 ~30 ~47 ~30 wool 9
fill ~30 ~41 ~31 ~30 ~47 ~31 wool 9
fill ~30 ~41 ~32 ~30 ~47 ~32 wool 9
fill ~30 ~41 ~49 ~30 ~47 ~49 wool 9
fill ~30 ~41 ~50 ~30 ~47 ~50 wool 9
fill ~30 ~41 ~51 ~30 ~47 ~51 wool 9
fill ~30 ~41 ~52 ~30 ~47 ~52 wool 9
fill ~30 ~41 ~53 ~30 ~47 ~53 wool 9
fill ~30 ~41 ~54 ~30 ~47 ~54 wool 9
fill ~30 ~41 ~55 ~30 ~47 ~55 wool 9
fill ~30 ~41 ~56 ~30 ~47 ~56 wool 9
fill ~30 ~41 ~57 ~30 ~47 ~57 planks 2
fill ~30 ~41 ~58 ~30 ~47 ~58 planks 2
fill ~30 ~41 ~59 ~37 ~41 ~59 planks 2
fill ~30 ~41 ~60 ~37 ~41 ~60 planks 2
fill ~30 ~41 ~61 ~37 ~41 ~61 planks 2
fill ~30 ~41 ~62 ~37 ~41 ~62 planks 2
fill ~31 ~41 ~37 ~36 ~41 ~37 wool 11
fill ~31 ~41 ~44 ~36 ~41 ~44 wool 11
fill ~33 ~41 ~23 ~34 ~41 ~23 glowstone 0
fill ~33 ~41 ~39 ~35 ~41 ~39 glass 0
fill ~33 ~41 ~42 ~35 ~41 ~42 glass 0
fill ~33 ~41 ~58 ~34 ~41 ~58 glowstone 0
setblock ~34 ~41 ~43 stone_slab 0
setblock ~35 ~41 ~43 double_stone_slab 0
setblock ~36 ~41 ~43 stone_slab 8
fill ~37 ~41 ~23 ~37 ~47 ~23 planks 2
fill ~37 ~41 ~24 ~37 ~47 ~24 planks 2
fill ~37 ~41 ~25 ~37 ~47 ~25 wool 9
fill ~37 ~41 ~26 ~37 ~47 ~26 wool 9
fill ~37 ~41 ~27 ~37 ~47 ~27 wool 9
fill ~37 ~41 ~28 ~37 ~47 ~28 wool 9
fill ~37 ~41 ~29 ~37 ~47 ~29 wool 9
fill ~37 ~41 ~30 ~37 ~47 ~30 wool 9
fill ~37 ~41 ~31 ~37 ~47 ~31 wool 9
fill ~37 ~41 ~32 ~37 ~47 ~32 wool 9
fill ~37 ~41 ~49 ~37 ~47 ~49 wool 9
fill ~37 ~41 ~50 ~37 ~47 ~50 wool 9
fill ~37 ~41 ~51 ~37 ~47 ~51 wool 9
fill ~37 ~41 ~52 ~37 ~47 ~52 wool 9
fill ~37 ~41 ~53 ~37 ~47 ~53 wool 9
fill ~37 ~41 ~54 ~37 ~47 ~54 wool 9
fill ~37 ~41 ~55 ~37 ~47 ~55 wool 9
fill ~37 ~41 ~56 ~37 ~47 ~56 wool 9
fill ~37 ~41 ~57 ~37 ~47 ~57 planks 2
fill ~37 ~41 ~58 ~37 ~47 ~58 planks 2
fill ~38 ~41 ~40 ~38 ~41 ~41 glowstone 0
fill ~39 ~41 ~40 ~39 ~44 ~40 wool 12
fill ~39 ~41 ~41 ~39 ~44 ~41 wool 12
fill ~40 ~41 ~36 ~42 ~41 ~36 wool 12
fill ~41 ~41 ~35 ~42 ~41 ~35 wool 12
fill ~41 ~41 ~46 ~42 ~41 ~46 wool 12
fill ~30 ~42 ~16 ~37 ~42 ~16 planks 2
fill ~30 ~42 ~17 ~37 ~42 ~17 planks 2
fill ~30 ~42 ~18 ~37 ~42 ~18 planks 2
fill ~30 ~42 ~19 ~30 ~48 ~19 planks 2
fill ~30 ~42 ~20 ~30 ~48 ~20 planks 2
fill ~30 ~42 ~21 ~30 ~48 ~21 planks 2
fill ~30 ~42 ~22 ~30 ~48 ~22 planks 2
fill ~30 ~42 ~59 ~30 ~48 ~59 planks 2
fill ~30 ~42 ~60 ~30 ~48 ~60 planks 2
fill ~30 ~42 ~61 ~30 ~48 ~61 planks 2
fill ~30 ~42 ~62 ~30 ~48 ~62 planks 2
fill ~30 ~42 ~63 ~37 ~42 ~63 planks 2
fill ~30 ~42 ~64 ~37 ~42 ~64 planks 2
fill ~30 ~42 ~65 ~37 ~42 ~65 planks 2
fill ~31 ~42 ~37 ~36 ~42 ~37 wool 11
fill ~31 ~42 ~44 ~36 ~42 ~44 wool 11
fill ~33 ~42 ~19 ~34 ~42 ~19 glowstone 0
fill ~33 ~42 ~39 ~35 ~42 ~39 glass 0
fill ~33 ~42 ~42 ~35 ~42 ~42 glass 0
fill ~33 ~42 ~62 ~34 ~42 ~62 glowstone 0
setblock ~36 ~42 ~41 stone_slab 8
setblock ~36 ~42 ~42 double_stone_slab 0
setblock ~36 ~42 ~43 stone_slab 0
fill ~37 ~42 ~19 ~37 ~48 ~19 planks 2
fill ~37 ~42 ~20 ~37 ~48 ~20 planks 2
fill ~37 ~42 ~21 ~37 ~48 ~21 planks 2
fill ~37 ~42 ~22 ~37 ~48 ~22 planks 2
fill ~37 ~42 ~39 ~37 ~46 ~39 planks 2
fill ~37 ~42 ~40 ~37 ~46 ~40 planks 2
fill ~37 ~42 ~41 ~37 ~46 ~41 planks 2
fill ~37 ~42 ~42 ~37 ~46 ~42 planks 2
fill ~37 ~42 ~59 ~37 ~48 ~59 planks 2
fill ~37 ~42 ~60 ~37 ~48 ~60 planks 2
fill ~37 ~42 ~61 ~37 ~48 ~61 planks 2
fill ~37 ~42 ~62 ~37 ~48 ~62 planks 2
fill ~38 ~42 ~39 ~38 ~45 ~39 wool 12
fill ~38 ~42 ~40 ~38 ~45 ~40 wool 12
fill ~38 ~42 ~41 ~38 ~45 ~41 wool 12
fill ~38 ~42 ~42 ~38 ~45 ~42 wool 12
fill ~39 ~42 ~36 ~39 ~44 ~36 wool 12
fill ~39 ~42 ~45 ~39 ~44 ~45 wool 12
fill ~40 ~42 ~35 ~42 ~42 ~35 wool 12
fill ~40 ~42 ~46 ~42 ~42 ~46 wool 12
fill ~41 ~42 ~34 ~42 ~42 ~34 wool 12
fill ~41 ~42 ~47 ~42 ~42 ~47 wool 12
fill ~42 ~42 ~36 ~42 ~49 ~36 wool 12
fill ~30 ~43 ~14 ~37 ~43 ~14 planks 2
fill ~30 ~43 ~15 ~37 ~43 ~15 planks 2
fill ~30 ~43 ~16 ~30 ~49 ~16 planks 2
fill ~30 ~43 ~17 ~30 ~49 ~17 planks 2
fill ~30 ~43 ~18 ~30 ~49 ~18 planks 2
fill ~30 ~43 ~63 ~30 ~49 ~63 planks 2
fill ~30 ~43 ~64 ~30 ~49 ~64 planks 2
fill ~30 ~43 ~65 ~30 ~49 ~65 planks 2
fill ~30 ~43 ~66 ~37 ~43 ~66 planks 2
fill ~30 ~43 ~67 ~37 ~43 ~67 planks 2
fill ~31 ~43 ~37 ~36 ~43 ~37 wool 11
fill ~31 ~43 ~44 ~36 ~43 ~44 wool 11
fill ~33 ~43 ~16 ~34 ~43 ~16 glowstone 0
fill ~33 ~43 ~39 ~35 ~43 ~39 glass 0
fill ~33 ~43 ~42 ~35 ~43 ~42 glass 0
fill ~33 ~43 ~65 ~34 ~43 ~65 glowstone 0
fill ~34 ~43 ~40 ~34 ~43 ~41 lava 0
setblock ~36 ~43 ~39 stone_slab 8
setblock ~36 ~43 ~40 double_stone_slab 0
setblock ~36 ~43 ~41 stone_slab 0
fill ~37 ~43 ~16 ~37 ~49 ~16 planks 2
fill ~37 ~43 ~17 ~37 ~49 ~17 planks 2
fill ~37 ~43 ~18 ~37 ~49 ~18 planks 2
fill ~37 ~43 ~63 ~37 ~49 ~63 planks 2
fill ~37 ~43 ~64 ~37 ~49 ~64 planks 2
fill ~37 ~43 ~65 ~37 ~49 ~65 planks 2
fill ~38 ~43 ~37 ~38 ~45 ~37 wool 12
fill ~38 ~43 ~38 ~38 ~45 ~38 wool 12
fill ~38 ~43 ~43 ~38 ~45 ~43 wool 12
fill ~38 ~43 ~44 ~38 ~45 ~44 wool 12
fill ~40 ~43 ~35 ~42 ~43 ~35 wool 12
fill ~40 ~43 ~46 ~42 ~43 ~46 wool 12
fill ~41 ~43 ~34 ~42 ~43 ~34 wool 12
fill ~41 ~43 ~47 ~42 ~43 ~47 wool 12
fill ~30 ~44 ~12 ~37 ~44 ~12 planks 2
fill ~30 ~44 ~13 ~37 ~44 ~13 planks 2
fill ~30 ~44 ~14 ~30 ~54 ~14 planks 2
fill ~30 ~44 ~15 ~30 ~54 ~15 planks 2
fill ~30 ~44 ~66 ~30 ~54 ~66 planks 2
fill ~30 ~44 ~67 ~30 ~54 ~67 planks 2
fill ~30 ~44 ~68 ~37 ~44 ~68 planks 2
fill ~30 ~44 ~69 ~37 ~44 ~69 planks 2
fill ~31 ~44 ~37 ~36 ~44 ~37 wool 11
fill ~31 ~44 ~44 ~36 ~44 ~44 wool 11
fill ~32 ~44 ~38 ~36 ~44 ~38 double_stone_slab 0
fill ~32 ~44 ~39 ~35 ~44 ~39 double_stone_slab 0
fill ~32 ~44 ~40 ~35 ~44 ~40 stone 0
fill ~32 ~44 ~41 ~35 ~44 ~41 stone 0
fill ~32 ~44 ~42 ~35 ~44 ~42 stone 0
fill ~32 ~44 ~43 ~33 ~44 ~43 stone 0
fill ~33 ~44 ~14 ~34 ~44 ~14 glowstone 0
fill ~33 ~44 ~67 ~34 ~44 ~67 glowstone 0
setblock ~34 ~44 ~43 stone_brick_stairs 5
setblock ~36 ~44 ~39 stone_slab 0
fill ~37 ~44 ~14 ~37 ~54 ~14 planks 2
fill ~37 ~44 ~15 ~37 ~54 ~15 planks 2
fill ~37 ~44 ~37 ~37 ~45 ~37 planks 2
fill ~37 ~44 ~38 ~37 ~46 ~38 planks 2
fill ~37 ~44 ~43 ~37 ~46 ~43 planks 2
fill ~37 ~44 ~44 ~37 ~45 ~44 planks 2
fill ~37 ~44 ~66 ~37 ~54 ~66 planks 2
fill ~37 ~44 ~67 ~37 ~54 ~67 planks 2
fill ~38 ~44 ~35 ~39 ~44 ~35 wool 12
fill ~38 ~44 ~36 ~38 ~45 ~36 wool 12
fill ~38 ~44 ~45 ~38 ~45 ~45 wool 12
fill ~38 ~44 ~46 ~39 ~44 ~46 wool 12
fill ~40 ~44 ~34 ~42 ~44 ~34 wool 12
fill ~40 ~44 ~47 ~42 ~44 ~47 wool 12
fill ~41 ~44 ~32 ~41 ~47 ~32 wool 12
fill ~41 ~44 ~33 ~42 ~44 ~33 wool 12
fill ~41 ~44 ~48 ~42 ~44 ~48 wool 12
fill ~41 ~44 ~49 ~41 ~47 ~49 wool 12
fill ~42 ~44 ~35 ~42 ~48 ~35 wool 12
fill ~42 ~44 ~46 ~42 ~48 ~46 wool 12
fill ~30 ~45 ~10 ~37 ~45 ~10 planks 2
fill ~30 ~45 ~11 ~37 ~45 ~11 planks 2
fill ~30 ~45 ~12 ~30 ~54 ~12 planks 2
fill ~30 ~45 ~13 ~30 ~54 ~13 planks 2
fill ~30 ~45 ~68 ~30 ~54 ~68 planks 2
fill ~30 ~45 ~69 ~30 ~54 ~69 planks 2
fill ~30 ~45 ~70 ~37 ~45 ~70 planks 2
fill ~30 ~45 ~71 ~37 ~45 ~71 planks 2
fill ~31 ~45 ~33 ~37 ~45 ~33 wool 9
setblock ~31 ~45 ~36 glowstone 0
setblock ~31 ~45 ~37 double_stone_slab 0
fill ~31 ~45 ~44 ~31 ~45 ~45 glowstone 0
fill ~31 ~45 ~48 ~37 ~45 ~48 wool 9
fill ~32 ~45 ~37 ~35 ~45 ~37 wool 11
fill ~32 ~45 ~38 ~32 ~49 ~38 stonebrick 0
fill ~32 ~45 ~39 ~32 ~48 ~39 stonebrick 0
fill ~32 ~45 ~44 ~35 ~45 ~44 wool 11
fill ~33 ~45 ~12 ~34 ~45 ~12 glowstone 0
fill ~33 ~45 ~32 ~34 ~45 ~32 glowstone 0
fill ~33 ~45 ~40 ~33 ~48 ~40 stone 0
fill ~33 ~45 ~41 ~33 ~51 ~41 stone 0
fill ~33 ~45 ~42 ~33 ~65 ~42 stone 0
fill ~33 ~45 ~49 ~34 ~45 ~49 glowstone 0
fill ~33 ~45 ~69 ~34 ~45 ~69 glowstone 0
fill ~34 ~45 ~42 ~34 ~70 ~42 ladder 4
fill ~34 ~45 ~43 ~34 ~65 ~43 stone 0
fill ~35 ~45 ~40 ~35 ~48 ~40 stone 0
fill ~35 ~45 ~41 ~35 ~51 ~41 stone 0
fill ~35 ~45 ~42 ~35 ~65 ~42 stone 0
setblock ~35 ~45 ~43 stone_brick_stairs 5
fill ~36 ~45 ~36 ~36 ~45 ~37 glowstone 0
fill ~36 ~45 ~44 ~36 ~45 ~45 glowstone 0
fill ~37 ~45 ~12 ~37 ~54 ~12 planks 2
fill ~37 ~45 ~13 ~37 ~54 ~13 planks 2
fill ~37 ~45 ~68 ~37 ~54 ~68 planks 2
fill ~37 ~45 ~69 ~37 ~54 ~69 planks 2
fill ~38 ~45 ~35 ~39 ~45 ~35 wool 12
fill ~38 ~45 ~46 ~39 ~45 ~46 wool 12
fill ~40 ~45 ~32 ~40 ~47 ~32 wool 12
fill ~40 ~45 ~33 ~42 ~45 ~33 wool 12
fill ~40 ~45 ~34 ~40 ~44 ~34 wool 12
fill ~40 ~45 ~47 ~42 ~45 ~47 wool 12
fill ~40 ~45 ~49 ~40 ~47 ~49 wool 12
fill ~41 ~45 ~48 ~42 ~45 ~48 wool 12
fill ~42 ~45 ~34 ~42 ~48 ~34 wool 12
fill ~25 ~46 ~37 ~25 ~61 ~37 wool 12
fill ~25 ~46 ~38 ~25 ~61 ~38 wool 12
fill ~25 ~46 ~39 ~25 ~61 ~39 wool 12
fill ~25 ~46 ~40 ~25 ~61 ~40 wool 12
fill ~25 ~46 ~41 ~25 ~61 ~41 wool 12
fill ~25 ~46 ~42 ~25 ~61 ~42 wool 12
fill ~25 ~46 ~43 ~25 ~61 ~43 wool 12
fill ~25 ~46 ~44 ~25 ~61 ~44 wool 12
fill ~26 ~46 ~33 ~41 ~46 ~33 planks 2
fill ~26 ~46 ~34 ~29 ~46 ~34 planks 2
fill ~26 ~46 ~35 ~29 ~46 ~35 planks 2
fill ~26 ~46 ~36 ~29 ~46 ~36 planks 2
fill ~26 ~46 ~37 ~29 ~46 ~37 planks 2
fill ~26 ~46 ~38 ~29 ~46 ~38 planks 2
fill ~26 ~46 ~39 ~29 ~46 ~39 planks 2
fill ~26 ~46 ~40 ~29 ~46 ~40 planks 2
fill ~26 ~46 ~41 ~29 ~46 ~41 planks 2
fill ~26 ~46 ~42 ~29 ~46 ~42 planks 2
fill ~26 ~46 ~43 ~29 ~46 ~43 planks 2
fill ~26 ~46 ~44 ~29 ~46 ~44 planks 2
fill ~26 ~46 ~45 ~29 ~46 ~45 planks 2
fill ~26 ~46 ~46 ~29 ~46 ~46 planks 2
fill ~26 ~46 ~47 ~29 ~46 ~47 planks 2
fill ~26 ~46 ~48 ~41 ~46 ~48 planks 2
fill ~29 ~46 ~73 ~29 ~62 ~73 stone 0
fill ~30 ~46 ~9 ~37 ~46 ~9 planks 2
fill ~30 ~46 ~10 ~30 ~52 ~10 planks 2
fill ~30 ~46 ~11 ~30 ~52 ~11 planks 2
fill ~30 ~46 ~36 ~30 ~46 ~37 glowstone 0
fill ~30 ~46 ~42 ~30 ~48 ~42 wool 11
fill ~30 ~46 ~43 ~30 ~48 ~43 wool 11
fill ~30 ~46 ~44 ~30 ~46 ~45 glowstone 0
fill ~30 ~46 ~70 ~30 ~54 ~70 planks 2
fill ~30 ~46 ~71 ~30 ~54 ~71 planks 2
fill ~30 ~46 ~72 ~37 ~46 ~72 planks 2
fill ~31 ~46 ~32 ~37 ~46 ~32 wool 9
fill ~31 ~46 ~37 ~36 ~46 ~37 wool 11
fill ~31 ~46 ~44 ~36 ~46 ~44 wool 11
fill ~31 ~46 ~49 ~37 ~46 ~49 wool 9
fill ~33 ~46 ~10 ~34 ~46 ~10 glowstone 0
fill ~33 ~46 ~31 ~34 ~46 ~31 glowstone 0
fill ~33 ~46 ~50 ~34 ~46 ~50 glowstone 0
setblock ~36 ~46 ~42 stone_brick_stairs 6
setblock ~36 ~46 ~43 stonebrick 0
fill ~37 ~46 ~10 ~37 ~54 ~10 planks 2
fill ~37 ~46 ~11 ~37 ~54 ~11 planks 2
fill ~37 ~46 ~34 ~41 ~46 ~34 planks 2
fill ~37 ~46 ~35 ~41 ~46 ~35 planks 2
fill ~37 ~46 ~36 ~37 ~46 ~37 glowstone 0
fill ~37 ~46 ~44 ~37 ~46 ~45 glowstone 0
fill ~37 ~46 ~46 ~41 ~46 ~46 planks 2
fill ~37 ~46 ~47 ~41 ~46 ~47 planks 2
fill ~37 ~46 ~70 ~37 ~54 ~70 planks 2
fill ~37 ~46 ~71 ~37 ~54 ~71 planks 2
fill ~38 ~46 ~11 ~38 ~62 ~11 stone 0
fill ~38 ~46 ~36 ~41 ~46 ~36 planks 2
fill ~38 ~46 ~37 ~41 ~46 ~37 planks 2
fill ~38 ~46 ~38 ~41 ~46 ~38 planks 2
fill ~38 ~46 ~39 ~41 ~46 ~39 planks 2
fill ~38 ~46 ~40 ~41 ~46 ~40 planks 2
fill ~38 ~46 ~41 ~41 ~46 ~41 planks 2
fill ~38 ~46 ~42 ~41 ~46 ~42 planks 2
fill ~38 ~46 ~43 ~41 ~46 ~43 planks 2
fill ~38 ~46 ~44 ~41 ~46 ~44 planks 2
fill ~38 ~46 ~45 ~41 ~46 ~45 planks 2
fill ~42 ~46 ~33 ~42 ~47 ~33 wool 12
fill ~42 ~46 ~47 ~42 ~48 ~47 wool 12
fill ~42 ~46 ~48 ~42 ~47 ~48 wool 12
fill ~26 ~47 ~33 ~41 ~47 ~33 planks 2
fill ~26 ~47 ~34 ~26 ~46 ~34 planks 2
fill ~26 ~47 ~35 ~26 ~46 ~35 planks 2
fill ~26 ~47 ~36 ~26 ~46 ~36 planks 2
fill ~26 ~47 ~45 ~26 ~46 ~45 planks 2
fill ~26 ~47 ~46 ~26 ~46 ~46 planks 2
fill ~26 ~47 ~47 ~26 ~46 ~47 planks 2
fill ~26 ~47 ~48 ~41 ~47 ~48 planks 2
setblock ~27 ~47 ~16 piston 1
fill ~29 ~47 ~67 ~29 ~61 ~67 stone 0
fill ~30 ~47 ~9 ~37 ~47 ~9 planks 2
fill ~30 ~47 ~44 ~37 ~47 ~44 wool 11
fill ~30 ~47 ~72 ~37 ~47 ~72 planks 2
fill ~31 ~47 ~23 ~37 ~47 ~23 planks 2
fill ~31 ~47 ~24 ~37 ~47 ~24 planks 2
fill ~31 ~47 ~25 ~37 ~47 ~25 wool 9
fill ~31 ~47 ~26 ~37 ~47 ~26 wool 9
fill ~31 ~47 ~27 ~37 ~47 ~27 wool 9
fill ~31 ~47 ~28 ~37 ~47 ~28 wool 9
fill ~31 ~47 ~29 ~37 ~47 ~29 wool 9
fill ~31 ~47 ~30 ~37 ~47 ~30 wool 9
fill ~31 ~47 ~31 ~37 ~47 ~31 wool 9
fill ~31 ~47 ~32 ~37 ~47 ~32 wool 9
fill ~31 ~47 ~37 ~37 ~47 ~37 wool 11
fill ~31 ~47 ~49 ~37 ~47 ~49 wool 9
fill ~31 ~47 ~50 ~37 ~47 ~50 wool 9
fill ~31 ~47 ~51 ~37 ~47 ~51 wool 9
fill ~31 ~47 ~52 ~37 ~47 ~52 wool 9
fill ~31 ~47 ~53 ~37 ~47 ~53 wool 9
fill ~31 ~47 ~54 ~37 ~47 ~54 wool 9
fill ~31 ~47 ~55 ~37 ~47 ~55 wool 9
fill ~31 ~47 ~56 ~37 ~47 ~56 wool 9
fill ~31 ~47 ~57 ~37 ~47 ~57 planks 2
fill ~31 ~47 ~58 ~37 ~47 ~58 planks 2
fill ~33 ~47 ~22 ~34 ~47 ~22 glowstone 0
fill ~33 ~47 ~59 ~34 ~47 ~59 glowstone 0
fill ~34 ~47 ~40 ~34 ~48 ~40 stone 0
fill ~34 ~47 ~41 ~34 ~65 ~41 stone 0
setblock ~36 ~47 ~41 stone_brick_stairs 6
fill ~37 ~47 ~38 ~37 ~48 ~38 wool 11
fill ~37 ~47 ~39 ~37 ~48 ~39 wool 11
fill ~37 ~47 ~40 ~37 ~48 ~40 wool 11
fill ~37 ~47 ~41 ~37 ~48 ~41 wool 11
fill ~37 ~47 ~42 ~37 ~48 ~42 wool 11
fill ~37 ~47 ~43 ~37 ~48 ~43 wool 11
fill ~38 ~47 ~71 ~38 ~62 ~71 stone 0
fill ~39 ~47 ~37 ~41 ~47 ~37 planks 2
fill ~39 ~47 ~38 ~39 ~47 ~44 planks 2
fill ~40 ~47 ~44 ~41 ~47 ~44 planks 2
setblock ~40 ~47 ~76 piston 1
fill ~41 ~47 ~34 ~41 ~55 ~34 planks 2
fill ~41 ~47 ~35 ~41 ~51 ~35 planks 2
fill ~41 ~47 ~36 ~41 ~51 ~36 planks 2
fill ~41 ~47 ~38 ~41 ~47 ~48 planks 2
fill ~25 ~48 ~32 ~31 ~48 ~32 wool 12
fill ~25 ~48 ~33 ~25 ~61 ~33 wool 12
fill ~25 ~48 ~34 ~25 ~61 ~34 wool 12
fill ~25 ~48 ~35 ~25 ~61 ~35 wool 12
fill ~25 ~48 ~36 ~25 ~61 ~36 wool 12
fill ~25 ~48 ~45 ~25 ~60 ~45 wool 12
fill ~25 ~48 ~46 ~25 ~60 ~46 wool 12
fill ~25 ~48 ~47 ~25 ~60 ~47 wool 12
fill ~25 ~48 ~48 ~25 ~60 ~48 wool 12
fill ~25 ~48 ~49 ~31 ~48 ~49 wool 12
setblock ~26 ~48 ~16 trapdoor 14
fill ~26 ~48 ~33 ~26 ~60 ~33 planks 2
fill ~26 ~48 ~48 ~26 ~60 ~48 planks 2
setblock ~27 ~48 ~15 trapdoor 12
setblock ~27 ~48 ~16 glowstone 0
setblock ~27 ~48 ~17 trapdoor 13
setblock ~28 ~48 ~16 trapdoor 15
fill ~29 ~48 ~14 ~29 ~55 ~14 stone 0
fill ~30 ~48 ~8 ~37 ~48 ~8 planks 2
fill ~30 ~48 ~9 ~30 ~52 ~9 planks 2
fill ~30 ~48 ~44 ~37 ~48 ~44 wool 11
fill ~30 ~48 ~72 ~30 ~54 ~72 planks 2
fill ~30 ~48 ~73 ~37 ~48 ~73 planks 2
fill ~31 ~48 ~19 ~37 ~48 ~19 planks 2
fill ~31 ~48 ~20 ~37 ~48 ~20 planks 2
fill ~31 ~48 ~21 ~37 ~48 ~21 planks 2
fill ~31 ~48 ~22 ~37 ~48 ~22 planks 2
fill ~31 ~48 ~37 ~37 ~48 ~37 wool 11
fill ~31 ~48 ~38 ~31 ~48 ~44 wool 11
fill ~31 ~48 ~59 ~37 ~48 ~59 planks 2
fill ~31 ~48 ~60 ~37 ~48 ~60 planks 2
fill ~31 ~48 ~61 ~37 ~48 ~61 planks 2
fill ~31 ~48 ~62 ~37 ~48 ~62 planks 2
fill ~32 ~48 ~33 ~41 ~48 ~33 planks 2
fill ~32 ~48 ~48 ~41 ~48 ~48 planks 2
fill ~33 ~48 ~9 ~34 ~48 ~9 glowstone 0
fill ~33 ~48 ~18 ~34 ~48 ~18 glowstone 0
fill ~33 ~48 ~63 ~34 ~48 ~63 glowstone 0
fill ~33 ~48 ~72 ~34 ~48 ~72 glowstone 0
setblock ~36 ~48 ~40 stone_brick_stairs 6
fill ~37 ~48 ~9 ~37 ~54 ~9 planks 2
fill ~37 ~48 ~72 ~37 ~54 ~72 planks 2
fill ~39 ~48 ~37 ~41 ~48 ~37 planks 2
fill ~39 ~48 ~38 ~39 ~48 ~43 wool 15
fill ~39 ~48 ~44 ~41 ~48 ~44 planks 2
setblock ~39 ~48 ~76 trapdoor 14
setblock ~40 ~48 ~75 trapdoor 12
setblock ~40 ~48 ~76 glowstone 0
setblock ~40 ~48 ~77 trapdoor 13
fill ~41 ~48 ~38 ~41 ~48 ~43 glowstone 0
fill ~41 ~48 ~45 ~41 ~51 ~45 planks 2
fill ~41 ~48 ~46 ~41 ~51 ~46 planks 2
fill ~41 ~48 ~47 ~41 ~55 ~47 planks 2
setblock ~41 ~48 ~76 trapdoor 15
setblock ~44 ~48 ~27 piston 1
setblock ~19 ~49 ~34 piston 1
setblock ~23 ~49 ~69 piston 1
fill ~25 ~49 ~32 ~31 ~49 ~32 wool 12
fill ~25 ~49 ~49 ~31 ~49 ~49 wool 12
setblock ~27 ~49 ~16 piston 0
fill ~30 ~49 ~8 ~37 ~49 ~8 planks 2
fill ~30 ~49 ~73 ~37 ~49 ~73 planks 2
fill ~31 ~49 ~16 ~37 ~49 ~16 planks 2
fill ~31 ~49 ~17 ~37 ~49 ~17 planks 2
fill ~31 ~49 ~18 ~37 ~49 ~18 planks 2
