fill ~38 ~0 ~78 ~39 ~0 ~78 stone 2
setblock ~39 ~0 ~79 glowstone
fill ~105 ~0 ~78 ~106 ~0 ~78 stone 2
setblock ~105 ~0 ~79 glowstone
fill ~37 ~1 ~77 ~37 ~2 ~77 concrete 6
setblock ~37 ~1 ~78 glowstone
setblock ~38 ~1 ~75 stone 2
fill ~38 ~1 ~76 ~39 ~1 ~76 glowstone
setblock ~38 ~1 ~77 stone 2
setblock ~38 ~1 ~79 stone 2
setblock ~39 ~1 ~77 glowstone
fill ~39 ~1 ~80 ~39 ~2 ~80 glowstone
fill ~40 ~1 ~77 ~40 ~3 ~77 stone 2
setblock ~40 ~1 ~78 glowstone
setblock ~40 ~1 ~79 stone 2
fill ~44 ~1 ~78 ~45 ~1 ~78 glowstone
setblock ~44 ~1 ~79 stone 2
setblock ~45 ~1 ~79 glowstone
setblock ~50 ~1 ~74 glowstone
setblock ~50 ~1 ~75 stone 2
setblock ~51 ~1 ~75 glowstone
setblock ~93 ~1 ~75 glowstone
setblock ~94 ~1 ~74 glowstone
setblock ~94 ~1 ~75 stone 2
fill ~99 ~1 ~78 ~100 ~1 ~78 glowstone
fill ~99 ~1 ~79 ~99 ~1 ~78 glowstone
setblock ~100 ~1 ~79 stone 2
fill ~104 ~1 ~77 ~104 ~3 ~77 stone 2
setblock ~104 ~1 ~78 glowstone
setblock ~104 ~1 ~79 stone 2
fill ~105 ~1 ~76 ~106 ~1 ~76 glowstone
fill ~105 ~1 ~77 ~105 ~1 ~76 glowstone
fill ~105 ~1 ~80 ~105 ~2 ~80 glowstone
setblock ~106 ~1 ~75 stone 2
setblock ~106 ~1 ~77 stone 2
setblock ~106 ~1 ~79 stone 2
fill ~107 ~1 ~77 ~107 ~2 ~77 concrete 6
setblock ~107 ~1 ~78 glowstone
setblock ~37 ~2 ~74 planks 3
setblock ~37 ~2 ~75 glowstone
setblock ~37 ~2 ~76 stone 2
setblock ~37 ~2 ~78 concrete 6
fill ~38 ~2 ~73 ~38 ~2 ~74 stone 2
setblock ~38 ~2 ~79 stained_hardened_clay
setblock ~39 ~2 ~74 planks 3
setblock ~39 ~2 ~75 glowstone
fill ~40 ~2 ~75 ~40 ~3 ~75 stone 2
setblock ~40 ~2 ~76 brick_block
setblock ~40 ~2 ~78 stone 2
setblock ~40 ~2 ~79 glowstone
setblock ~43 ~2 ~76 stone 2
setblock ~43 ~2 ~77 glowstone
setblock ~43 ~2 ~78 stone 2
setblock ~43 ~2 ~79 glowstone
setblock ~44 ~2 ~76 brick_block
setblock ~44 ~2 ~77 stone 2
fill ~44 ~2 ~80 ~46 ~2 ~80 stone 2
setblock ~45 ~2 ~76 planks 3
setblock ~45 ~2 ~77 glowstone
fill ~46 ~2 ~78 ~46 ~2 ~80 stone 2
setblock ~48 ~2 ~72 brick_block
fill ~48 ~2 ~73 ~48 ~2 ~74 stone 2
setblock ~49 ~2 ~72 planks 3
setblock ~49 ~2 ~73 glowstone
setblock ~49 ~2 ~74 planks 3
setblock ~49 ~2 ~75 glowstone
fill ~49 ~2 ~76 ~51 ~2 ~76 stone 2
fill ~50 ~2 ~72 ~50 ~2 ~73 stone 2
setblock ~51 ~2 ~73 glowstone
setblock ~51 ~2 ~74 stone 2
setblock ~52 ~2 ~75 glowstone
setblock ~92 ~2 ~75 glowstone
setblock ~93 ~2 ~73 glowstone
setblock ~93 ~2 ~74 stone 2
fill ~93 ~2 ~76 ~95 ~2 ~76 stone 2
fill ~94 ~2 ~72 ~94 ~2 ~73 stone 2
setblock ~95 ~2 ~72 planks 3
setblock ~95 ~2 ~73 glowstone
setblock ~95 ~2 ~74 planks 3
setblock ~95 ~2 ~75 glowstone
setblock ~96 ~2 ~72 brick_block
fill ~96 ~2 ~73 ~96 ~2 ~74 stone 2
fill ~98 ~2 ~78 ~98 ~2 ~80 stone 2
setblock ~99 ~2 ~76 planks 3
setblock ~99 ~2 ~77 glowstone
fill ~99 ~2 ~80 ~100 ~2 ~80 stone 2
setblock ~100 ~2 ~76 brick_block
setblock ~100 ~2 ~77 stone 2
setblock ~101 ~2 ~76 stone 2
setblock ~101 ~2 ~77 glowstone
setblock ~101 ~2 ~78 stone 2
setblock ~101 ~2 ~79 glowstone
fill ~104 ~2 ~75 ~104 ~3 ~75 stone 2
setblock ~104 ~2 ~76 brick_block
setblock ~104 ~2 ~78 stone 2
setblock ~104 ~2 ~79 glowstone
setblock ~105 ~2 ~74 planks 3
setblock ~105 ~2 ~75 glowstone
fill ~106 ~2 ~73 ~106 ~2 ~74 stone 2
setblock ~106 ~2 ~79 stained_hardened_clay
setblock ~107 ~2 ~74 planks 3
setblock ~107 ~2 ~75 glowstone
setblock ~107 ~2 ~76 stone 2
setblock ~107 ~2 ~78 concrete 6
setblock ~33 ~3 ~38 glowstone
setblock ~33 ~3 ~39 concrete 6
setblock ~33 ~3 ~40 glowstone
setblock ~33 ~3 ~41 concrete 6
setblock ~34 ~3 ~37 stone 2
setblock ~34 ~3 ~38 concrete 6
setblock ~34 ~3 ~39 stone 2
setblock ~34 ~3 ~40 concrete 6
setblock ~34 ~3 ~41 planks 3
fill ~34 ~3 ~42 ~36 ~3 ~42 glowstone
setblock ~34 ~3 ~43 stone 2
setblock ~35 ~3 ~36 glowstone
setblock ~35 ~3 ~37 planks 2
fill ~35 ~3 ~38 ~40 ~3 ~38 glowstone
setblock ~35 ~3 ~39 concrete 6
fill ~35 ~3 ~40 ~39 ~3 ~40 glowstone
fill ~35 ~3 ~41 ~35 ~3 ~40 glowstone
setblock ~35 ~3 ~43 concrete 6
setblock ~36 ~3 ~36 concrete 6
setblock ~36 ~3 ~37 planks 3
setblock ~36 ~3 ~39 stone 2
setblock ~36 ~3 ~41 stone 2
setblock ~36 ~3 ~74 glowstone
setblock ~36 ~3 ~75 stone 2
setblock ~36 ~3 ~76 planks 2
fill ~37 ~3 ~36 ~40 ~3 ~36 glowstone
fill ~37 ~3 ~37 ~37 ~3 ~36 glowstone
setblock ~37 ~3 ~39 glowstone
setblock ~37 ~3 ~41 glowstone
setblock ~37 ~3 ~42 stone 2
fill ~37 ~3 ~71 ~37 ~3 ~73 glowstone
fill ~37 ~3 ~77 ~37 ~4 ~77 stained_hardened_clay
fill ~37 ~3 ~78 ~37 ~3 ~77 stained_hardened_clay
setblock ~38 ~3 ~35 stone 2
setblock ~38 ~3 ~37 stone 2
setblock ~38 ~3 ~39 stone 2
setblock ~38 ~3 ~41 brick_block
setblock ~38 ~3 ~70 glowstone
setblock ~38 ~3 ~71 stone 2
fill ~38 ~3 ~72 ~43 ~3 ~72 glowstone
setblock ~38 ~3 ~78 glass
setblock ~39 ~3 ~37 glowstone
setblock ~39 ~3 ~39 glowstone
fill ~39 ~3 ~64 ~43 ~3 ~64 glowstone
fill ~39 ~3 ~65 ~39 ~3 ~64 glowstone
setblock ~39 ~3 ~66 stone 2
fill ~39 ~3 ~67 ~39 ~3 ~69 glowstone
setblock ~39 ~3 ~70 stone 2
setblock ~39 ~3 ~71 glowstone
setblock ~39 ~3 ~73 glowstone
setblock ~39 ~3 ~79 glass
setblock ~40 ~3 ~37 stone 2
setblock ~40 ~3 ~39 stone 2
fill ~40 ~3 ~62 ~41 ~3 ~62 glowstone
setblock ~40 ~3 ~63 stone 2
setblock ~40 ~3 ~65 stone 2
fill ~40 ~3 ~66 ~42 ~3 ~66 glowstone
setblock ~40 ~3 ~67 stone 2
fill ~40 ~3 ~68 ~46 ~3 ~68 glowstone
setblock ~40 ~3 ~69 stone 2
fill ~40 ~3 ~70 ~42 ~3 ~70 glowstone
setblock ~40 ~3 ~71 stone 2
setblock ~40 ~3 ~73 stone 2
setblock ~40 ~3 ~74 glowstone
setblock ~40 ~3 ~76 glowstone
setblock ~40 ~3 ~78 glowstone
setblock ~41 ~3 ~63 glowstone
setblock ~41 ~3 ~65 glowstone
setblock ~41 ~3 ~67 glowstone
setblock ~41 ~3 ~69 glowstone
setblock ~41 ~3 ~71 glowstone
setblock ~42 ~3 ~63 stone 2
setblock ~42 ~3 ~65 stone 2
setblock ~42 ~3 ~67 stone 2
setblock ~42 ~3 ~69 stone 2
setblock ~42 ~3 ~71 stone 2
setblock ~42 ~3 ~76 glowstone
setblock ~42 ~3 ~77 stone 2
setblock ~43 ~3 ~65 glowstone
setblock ~43 ~3 ~66 stone 2
setblock ~43 ~3 ~67 glowstone
setblock ~43 ~3 ~69 glowstone
setblock ~43 ~3 ~70 stone 2
setblock ~43 ~3 ~71 glowstone
setblock ~43 ~3 ~74 stone 2
setblock ~43 ~3 ~75 glowstone
setblock ~43 ~3 ~78 glowstone
setblock ~43 ~3 ~79 planks 2
setblock ~44 ~3 ~66 glowstone
setblock ~44 ~3 ~67 stone 2
setblock ~44 ~3 ~69 stone 2
fill ~44 ~3 ~70 ~46 ~3 ~70 glowstone
setblock ~44 ~3 ~71 stone 2
setblock ~44 ~3 ~74 glowstone
setblock ~44 ~3 ~75 stone 2
setblock ~44 ~3 ~79 concrete 6
setblock ~44 ~3 ~80 wool 6
setblock ~45 ~3 ~67 glowstone
setblock ~45 ~3 ~69 glowstone
setblock ~45 ~3 ~71 glowstone
fill ~45 ~3 ~75 ~45 ~4 ~75 glowstone
fill ~45 ~3 ~76 ~45 ~3 ~75 glowstone
setblock ~45 ~3 ~79 stained_hardened_clay
setblock ~45 ~3 ~80 concrete 6
setblock ~46 ~3 ~69 stone 2
setblock ~46 ~3 ~71 stone 2
fill ~46 ~3 ~72 ~47 ~3 ~72 glowstone
setblock ~46 ~3 ~77 planks 3
setblock ~46 ~3 ~78 concrete 6
setblock ~46 ~3 ~79 glowstone
setblock ~47 ~3 ~69 glowstone
setblock ~47 ~3 ~70 stone 2
setblock ~47 ~3 ~71 glowstone
setblock ~47 ~3 ~73 glowstone
fill ~47 ~3 ~74 ~47 ~4 ~74 stone 2
setblock ~48 ~3 ~70 glowstone
setblock ~48 ~3 ~71 stone 2
setblock ~48 ~3 ~75 stone 2
setblock ~49 ~3 ~71 glowstone
setblock ~49 ~3 ~76 glowstone
setblock ~50 ~3 ~72 glowstone
setblock ~50 ~3 ~76 planks 2
fill ~51 ~3 ~73 ~51 ~4 ~73 concrete 6
fill ~51 ~3 ~74 ~51 ~4 ~74 glowstone
setblock ~51 ~3 ~76 concrete 6
setblock ~52 ~3 ~75 stone 2
setblock ~92 ~3 ~75 stone 2
fill ~93 ~3 ~73 ~93 ~4 ~73 concrete 6
fill ~93 ~3 ~74 ~93 ~4 ~74 glowstone
setblock ~93 ~3 ~76 concrete 6
setblock ~94 ~3 ~72 glowstone
setblock ~94 ~3 ~76 planks 2
setblock ~95 ~3 ~71 glowstone
setblock ~95 ~3 ~76 glowstone
setblock ~96 ~3 ~70 glowstone
setblock ~96 ~3 ~71 stone 2
setblock ~96 ~3 ~75 stone 2
setblock ~97 ~3 ~69 glowstone
setblock ~97 ~3 ~70 stone 2
fill ~97 ~3 ~71 ~97 ~3 ~73 glowstone
fill ~97 ~3 ~74 ~97 ~4 ~74 stone 2
fill ~98 ~3 ~68 ~105 ~3 ~68 glowstone
setblock ~98 ~3 ~69 stone 2
fill ~98 ~3 ~70 ~100 ~3 ~70 glowstone
setblock ~98 ~3 ~71 stone 2
setblock ~98 ~3 ~72 glowstone
setblock ~98 ~3 ~77 planks 3
setblock ~98 ~3 ~78 concrete 6
setblock ~98 ~3 ~79 glowstone
setblock ~99 ~3 ~67 glowstone
setblock ~99 ~3 ~69 glowstone
setblock ~99 ~3 ~71 glowstone
fill ~99 ~3 ~75 ~99 ~4 ~75 glowstone
fill ~99 ~3 ~76 ~99 ~3 ~75 glowstone
setblock ~99 ~3 ~79 stained_hardened_clay
setblock ~99 ~3 ~80 concrete 6
setblock ~100 ~3 ~66 glowstone
setblock ~100 ~3 ~67 stone 2
setblock ~100 ~3 ~69 stone 2
setblock ~100 ~3 ~71 stone 2
setblock ~100 ~3 ~74 glowstone
setblock ~100 ~3 ~75 stone 2
setblock ~100 ~3 ~79 concrete 6
setblock ~100 ~3 ~80 wool 6
fill ~101 ~3 ~64 ~105 ~3 ~64 glowstone
fill ~101 ~3 ~65 ~101 ~3 ~64 glowstone
setblock ~101 ~3 ~66 stone 2
setblock ~101 ~3 ~67 glowstone
setblock ~101 ~3 ~69 glowstone
setblock ~101 ~3 ~70 stone 2
fill ~101 ~3 ~71 ~101 ~3 ~72 glowstone
setblock ~101 ~3 ~74 stone 2
setblock ~101 ~3 ~75 glowstone
setblock ~101 ~3 ~78 glowstone
setblock ~101 ~3 ~79 planks 2
setblock ~102 ~3 ~63 stone 2
setblock ~102 ~3 ~65 stone 2
fill ~102 ~3 ~66 ~104 ~3 ~66 glowstone
setblock ~102 ~3 ~67 stone 2
setblock ~102 ~3 ~69 stone 2
fill ~102 ~3 ~70 ~104 ~3 ~70 glowstone
setblock ~102 ~3 ~71 stone 2
fill ~102 ~3 ~72 ~107 ~3 ~72 glowstone
setblock ~102 ~3 ~76 glowstone
setblock ~102 ~3 ~77 stone 2
fill ~103 ~3 ~62 ~104 ~3 ~62 glowstone
fill ~103 ~3 ~63 ~103 ~3 ~62 glowstone
setblock ~103 ~3 ~65 glowstone
setblock ~103 ~3 ~67 glowstone
setblock ~103 ~3 ~69 glowstone
setblock ~103 ~3 ~71 glowstone
fill ~104 ~3 ~36 ~107 ~3 ~36 glowstone
setblock ~104 ~3 ~37 stone 2
fill ~104 ~3 ~38 ~109 ~3 ~38 glowstone
setblock ~104 ~3 ~39 stone 2
setblock ~104 ~3 ~63 stone 2
setblock ~104 ~3 ~65 stone 2
setblock ~104 ~3 ~67 stone 2
setblock ~104 ~3 ~69 stone 2
setblock ~104 ~3 ~71 stone 2
setblock ~104 ~3 ~73 stone 2
setblock ~104 ~3 ~74 glowstone
setblock ~104 ~3 ~76 glowstone
setblock ~104 ~3 ~78 glowstone
setblock ~105 ~3 ~37 glowstone
fill ~105 ~3 ~39 ~105 ~3 ~40 glowstone
setblock ~105 ~3 ~65 glowstone
setblock ~105 ~3 ~66 stone 2
setblock ~105 ~3 ~67 glowstone
setblock ~105 ~3 ~69 glowstone
setblock ~105 ~3 ~70 stone 2
setblock ~105 ~3 ~71 glowstone
setblock ~105 ~3 ~73 glowstone
setblock ~105 ~3 ~79 glass
setblock ~106 ~3 ~35 stone 2
setblock ~106 ~3 ~37 stone 2
setblock ~106 ~3 ~39 stone 2
fill ~106 ~3 ~40 ~109 ~3 ~40 glowstone
setblock ~106 ~3 ~41 brick_block
setblock ~106 ~3 ~70 glowstone
setblock ~106 ~3 ~71 stone 2
setblock ~106 ~3 ~78 glass
setblock ~107 ~3 ~37 glowstone
setblock ~107 ~3 ~39 glowstone
setblock ~107 ~3 ~41 glowstone
setblock ~107 ~3 ~42 stone 2
setblock ~107 ~3 ~71 glowstone
setblock ~107 ~3 ~73 glowstone
fill ~107 ~3 ~77 ~107 ~4 ~77 stained_hardened_clay
fill ~107 ~3 ~78 ~107 ~3 ~77 stained_hardened_clay
setblock ~108 ~3 ~36 concrete 6
setblock ~108 ~3 ~37 planks 3
setblock ~108 ~3 ~39 stone 2
setblock ~108 ~3 ~41 stone 2
fill ~108 ~3 ~42 ~110 ~3 ~42 glowstone
setblock ~108 ~3 ~74 glowstone
setblock ~108 ~3 ~75 stone 2
setblock ~108 ~3 ~76 planks 2
setblock ~109 ~3 ~36 glowstone
setblock ~109 ~3 ~37 planks 2
setblock ~109 ~3 ~39 concrete 6
setblock ~109 ~3 ~41 glowstone
setblock ~109 ~3 ~43 concrete 6
setblock ~110 ~3 ~37 stone 2
setblock ~110 ~3 ~38 concrete 6
setblock ~110 ~3 ~39 stone 2
setblock ~110 ~3 ~40 concrete 6
setblock ~110 ~3 ~41 planks 3
setblock ~110 ~3 ~43 stone 2
setblock ~111 ~3 ~38 glowstone
setblock ~111 ~3 ~39 concrete 6
setblock ~111 ~3 ~40 glowstone
setblock ~111 ~3 ~41 concrete 6
setblock ~32 ~4 ~38 stone 2
setblock ~32 ~4 ~39 concrete 6
setblock ~32 ~4 ~40 stone 2
setblock ~32 ~4 ~41 glowstone
fill ~32 ~4 ~42 ~33 ~4 ~42 stone 2
fill ~32 ~4 ~43 ~33 ~4 ~43 glowstone
fill ~32 ~4 ~44 ~34 ~4 ~44 stone 2
setblock ~33 ~4 ~37 concrete 6
setblock ~33 ~4 ~45 glowstone
fill ~33 ~4 ~46 ~35 ~4 ~46 stone 2
setblock ~33 ~4 ~47 glowstone
setblock ~33 ~4 ~48 planks 3
setblock ~33 ~4 ~49 glowstone
setblock ~34 ~4 ~36 stone 2
setblock ~34 ~4 ~45 stone 2
fill ~34 ~4 ~47 ~34 ~4 ~49 stone 2
setblock ~34 ~4 ~50 brick_block
fill ~34 ~4 ~51 ~34 ~4 ~53 stone 2
setblock ~34 ~4 ~54 brick_block
fill ~34 ~4 ~55 ~34 ~4 ~57 stone 2
fill ~35 ~4 ~35 ~35 ~6 ~35 concrete 6
setblock ~35 ~4 ~44 planks 3
setblock ~35 ~4 ~45 glowstone
setblock ~35 ~4 ~47 glowstone
setblock ~35 ~4 ~48 stone 2
setblock ~35 ~4 ~49 glowstone
setblock ~35 ~4 ~50 stone 2
setblock ~35 ~4 ~51 glowstone
setblock ~35 ~4 ~52 stone 2
setblock ~35 ~4 ~53 glowstone
setblock ~35 ~4 ~54 stone 2
setblock ~35 ~4 ~55 glowstone
setblock ~35 ~4 ~56 stone 2
setblock ~35 ~4 ~57 glowstone
setblock ~35 ~4 ~58 stone 2
setblock ~35 ~4 ~59 glowstone
setblock ~35 ~4 ~60 stone 2
setblock ~35 ~4 ~61 glowstone
setblock ~35 ~4 ~62 stone 2
fill ~36 ~4 ~35 ~39 ~4 ~35 glowstone
fill ~36 ~4 ~43 ~37 ~4 ~43 glowstone
fill ~36 ~4 ~44 ~36 ~4 ~45 stone 2
setblock ~36 ~4 ~46 brick_block
setblock ~36 ~4 ~47 stone 2
setblock ~36 ~4 ~48 brick_block
setblock ~36 ~4 ~49 stone 2
setblock ~36 ~4 ~50 brick_block
setblock ~36 ~4 ~51 stone 2
setblock ~36 ~4 ~52 brick_block
setblock ~36 ~4 ~53 stone 2
setblock ~36 ~4 ~54 brick_block
setblock ~36 ~4 ~55 stone 2
setblock ~36 ~4 ~56 brick_block
setblock ~36 ~4 ~57 stone 2
setblock ~36 ~4 ~58 brick_block
setblock ~36 ~4 ~59 stone 2
setblock ~36 ~4 ~60 brick_block
setblock ~36 ~4 ~61 stone 2
setblock ~36 ~4 ~62 brick_block
setblock ~36 ~4 ~63 stone 2
setblock ~36 ~4 ~64 brick_block
setblock ~36 ~4 ~65 stone 2
setblock ~36 ~4 ~66 brick_block
setblock ~36 ~4 ~67 stone 2
setblock ~36 ~4 ~68 brick_block
setblock ~36 ~4 ~69 stone 2
setblock ~36 ~4 ~70 brick_block
fill ~36 ~4 ~71 ~36 ~5 ~71 stone 2
setblock ~36 ~4 ~72 brick_block
fill ~36 ~4 ~73 ~36 ~5 ~73 stone 2
fill ~36 ~4 ~74 ~36 ~4 ~73 stone 2
setblock ~36 ~4 ~75 glowstone
setblock ~37 ~4 ~44 planks 3
setblock ~37 ~4 ~45 glowstone
setblock ~37 ~4 ~46 stone 2
setblock ~37 ~4 ~47 glowstone
setblock ~37 ~4 ~48 planks 3
setblock ~37 ~4 ~49 glowstone
setblock ~37 ~4 ~50 stone 2
setblock ~37 ~4 ~51 glowstone
setblock ~37 ~4 ~52 planks 3
setblock ~37 ~4 ~53 glowstone
setblock ~37 ~4 ~54 stone 2
setblock ~37 ~4 ~55 glowstone
setblock ~37 ~4 ~56 planks 3
setblock ~37 ~4 ~57 glowstone
setblock ~37 ~4 ~58 stone 2
setblock ~37 ~4 ~59 glowstone
setblock ~37 ~4 ~60 planks 3
setblock ~37 ~4 ~61 glowstone
setblock ~37 ~4 ~62 stone 2
setblock ~37 ~4 ~63 glowstone
setblock ~37 ~4 ~64 planks 3
setblock ~37 ~4 ~65 glowstone
setblock ~37 ~4 ~66 stone 2
setblock ~37 ~4 ~67 glowstone
setblock ~37 ~4 ~68 planks 3
setblock ~37 ~4 ~69 glowstone
setblock ~37 ~4 ~70 stone 2
setblock ~37 ~4 ~76 concrete 6
setblock ~38 ~4 ~42 stained_hardened_clay 6
setblock ~38 ~4 ~43 stone 2
setblock ~38 ~4 ~44 brick_block
setblock ~38 ~4 ~45 stone 2
setblock ~38 ~4 ~46 brick_block
fill ~38 ~4 ~47 ~38 ~4 ~49 stone 2
setblock ~38 ~4 ~50 brick_block
fill ~38 ~4 ~51 ~38 ~4 ~53 stone 2
setblock ~38 ~4 ~54 brick_block
fill ~38 ~4 ~55 ~38 ~4 ~57 stone 2
setblock ~38 ~4 ~58 brick_block
fill ~38 ~4 ~59 ~38 ~4 ~61 stone 2
setblock ~38 ~4 ~62 brick_block
fill ~38 ~4 ~63 ~38 ~4 ~65 stone 2
setblock ~38 ~4 ~66 brick_block
fill ~38 ~4 ~67 ~38 ~4 ~69 stone 2
setblock ~38 ~4 ~77 stained_hardened_clay
setblock ~39 ~4 ~41 glowstone
setblock ~39 ~4 ~42 stone 2
setblock ~39 ~4 ~43 glowstone
setblock ~39 ~4 ~44 stone 2
setblock ~39 ~4 ~45 glowstone
setblock ~39 ~4 ~46 stone 2
setblock ~39 ~4 ~47 glowstone
setblock ~39 ~4 ~48 stone 2
setblock ~39 ~4 ~49 glowstone
setblock ~39 ~4 ~50 stone 2
setblock ~39 ~4 ~51 glowstone
fill ~39 ~4 ~52 ~40 ~4 ~52 stone 2
setblock ~39 ~4 ~53 glowstone
setblock ~39 ~4 ~54 stone 2
setblock ~39 ~4 ~55 glowstone
setblock ~39 ~4 ~56 stone 2
setblock ~39 ~4 ~57 glowstone
setblock ~39 ~4 ~58 stone 2
setblock ~39 ~4 ~59 glowstone
setblock ~39 ~4 ~60 stone 2
setblock ~39 ~4 ~61 glowstone
setblock ~39 ~4 ~62 stone 2
setblock ~39 ~4 ~63 glowstone
setblock ~39 ~4 ~78 stained_hardened_clay
fill ~40 ~4 ~35 ~40 ~5 ~35 stone 2
setblock ~40 ~4 ~40 stone 2
setblock ~40 ~4 ~41 planks 3
setblock ~40 ~4 ~42 brick_block
setblock ~40 ~4 ~43 stone 2
setblock ~40 ~4 ~50 brick_block
setblock ~40 ~4 ~51 stone 2
setblock ~40 ~4 ~53 stone 2
setblock ~40 ~4 ~54 brick_block
setblock ~40 ~4 ~55 stone 2
setblock ~40 ~4 ~56 brick_block
setblock ~40 ~4 ~57 stone 2
setblock ~40 ~4 ~58 brick_block
setblock ~40 ~4 ~59 stone 2
setblock ~40 ~4 ~60 brick_block
setblock ~40 ~4 ~61 stone 2
setblock ~40 ~4 ~77 concrete 6
setblock ~41 ~4 ~36 stone 2
setblock ~41 ~4 ~37 glowstone
setblock ~41 ~4 ~38 planks 3
setblock ~41 ~4 ~39 glowstone
setblock ~41 ~4 ~54 stone 2
setblock ~41 ~4 ~55 glowstone
setblock ~41 ~4 ~56 planks 3
setblock ~41 ~4 ~57 glowstone
setblock ~41 ~4 ~58 stone 2
setblock ~41 ~4 ~59 glowstone
setblock ~41 ~4 ~60 planks 3
setblock ~41 ~4 ~61 glowstone
setblock ~41 ~4 ~73 glowstone
setblock ~41 ~4 ~74 stone 2
fill ~41 ~4 ~75 ~41 ~4 ~76 glowstone
setblock ~42 ~4 ~57 stone 2
setblock ~42 ~4 ~58 brick_block
fill ~42 ~4 ~59 ~42 ~4 ~61 stone 2
setblock ~42 ~4 ~62 brick_block
setblock ~42 ~4 ~73 stone 2
setblock ~42 ~4 ~74 brick_block
fill ~42 ~4 ~75 ~42 ~4 ~76 stone 2
setblock ~42 ~4 ~77 glowstone
setblock ~43 ~4 ~60 planks 3
setblock ~43 ~4 ~61 glowstone
setblock ~43 ~4 ~62 stone 2
setblock ~43 ~4 ~63 glowstone
setblock ~43 ~4 ~73 glowstone
fill ~43 ~4 ~78 ~45 ~4 ~78 concrete 6
setblock ~44 ~4 ~62 brick_block
setblock ~44 ~4 ~63 stone 2
setblock ~44 ~4 ~64 brick_block
setblock ~44 ~4 ~65 stone 2
setblock ~44 ~4 ~72 brick_block
setblock ~44 ~4 ~73 stone 2
setblock ~45 ~4 ~64 planks 3
setblock ~45 ~4 ~65 glowstone
setblock ~45 ~4 ~66 stone 2
setblock ~45 ~4 ~72 planks 3
setblock ~45 ~4 ~73 glowstone
setblock ~45 ~4 ~74 stone 2
setblock ~45 ~4 ~77 stained_hardened_clay
setblock ~46 ~4 ~66 brick_block
setblock ~46 ~4 ~67 stone 2
fill ~46 ~4 ~73 ~46 ~5 ~73 stone 2
setblock ~46 ~4 ~76 planks 3
setblock ~46 ~4 ~77 concrete 6
setblock ~47 ~4 ~67 glowstone
setblock ~47 ~4 ~68 stone 2
fill ~48 ~4 ~69 ~48 ~5 ~69 stone 2
setblock ~48 ~4 ~75 concrete 6
setblock ~49 ~4 ~70 planks 3
fill ~49 ~4 ~76 ~50 ~4 ~76 concrete 6
setblock ~50 ~4 ~71 glowstone
setblock ~50 ~4 ~72 stone 2
fill ~50 ~4 ~75 ~51 ~4 ~75 concrete 6
fill ~93 ~4 ~75 ~94 ~4 ~75 concrete 6
setblock ~94 ~4 ~71 glowstone
setblock ~94 ~4 ~72 stone 2
fill ~94 ~4 ~76 ~95 ~4 ~76 concrete 6
setblock ~95 ~4 ~70 planks 3
fill ~96 ~4 ~69 ~96 ~5 ~69 stone 2
setblock ~96 ~4 ~75 concrete 6
setblock ~97 ~4 ~67 glowstone
setblock ~97 ~4 ~68 stone 2
setblock ~98 ~4 ~66 brick_block
setblock ~98 ~4 ~67 stone 2
fill ~98 ~4 ~73 ~98 ~5 ~73 stone 2
setblock ~98 ~4 ~76 planks 3
setblock ~98 ~4 ~77 concrete 6
setblock ~99 ~4 ~64 planks 3
setblock ~99 ~4 ~65 glowstone
setblock ~99 ~4 ~66 stone 2
setblock ~99 ~4 ~72 planks 3
setblock ~99 ~4 ~73 glowstone
setblock ~99 ~4 ~74 stone 2
setblock ~99 ~4 ~77 stained_hardened_clay
fill ~99 ~4 ~78 ~101 ~4 ~78 concrete 6
setblock ~100 ~4 ~62 brick_block
setblock ~100 ~4 ~63 stone 2
setblock ~100 ~4 ~64 brick_block
setblock ~100 ~4 ~65 stone 2
setblock ~100 ~4 ~72 brick_block
setblock ~100 ~4 ~73 stone 2
setblock ~101 ~4 ~60 planks 3
setblock ~101 ~4 ~61 glowstone
setblock ~101 ~4 ~62 stone 2
setblock ~101 ~4 ~63 glowstone
setblock ~101 ~4 ~73 glowstone
setblock ~102 ~4 ~57 stone 2
setblock ~102 ~4 ~58 brick_block
fill ~102 ~4 ~59 ~102 ~4 ~61 stone 2
setblock ~102 ~4 ~62 brick_block
setblock ~102 ~4 ~73 stone 2
setblock ~102 ~4 ~74 brick_block
fill ~102 ~4 ~75 ~102 ~4 ~76 stone 2
setblock ~102 ~4 ~77 glowstone
setblock ~103 ~4 ~36 stone 2
setblock ~103 ~4 ~37 glowstone
setblock ~103 ~4 ~38 planks 3
setblock ~103 ~4 ~39 glowstone
setblock ~103 ~4 ~54 stone 2
setblock ~103 ~4 ~55 glowstone
setblock ~103 ~4 ~56 planks 3
setblock ~103 ~4 ~57 glowstone
setblock ~103 ~4 ~58 stone 2
setblock ~103 ~4 ~59 glowstone
setblock ~103 ~4 ~60 planks 3
setblock ~103 ~4 ~61 glowstone
setblock ~103 ~4 ~73 glowstone
setblock ~103 ~4 ~74 stone 2
fill ~103 ~4 ~75 ~103 ~4 ~76 glowstone
fill ~104 ~4 ~35 ~104 ~5 ~35 stone 2
setblock ~104 ~4 ~40 stone 2
setblock ~104 ~4 ~41 planks 3
setblock ~104 ~4 ~42 brick_block
setblock ~104 ~4 ~43 stone 2
setblock ~104 ~4 ~50 brick_block
fill ~104 ~4 ~51 ~104 ~4 ~53 stone 2
setblock ~104 ~4 ~54 brick_block
setblock ~104 ~4 ~55 stone 2
setblock ~104 ~4 ~56 brick_block
setblock ~104 ~4 ~57 stone 2
setblock ~104 ~4 ~58 brick_block
setblock ~104 ~4 ~59 stone 2
setblock ~104 ~4 ~60 brick_block
setblock ~104 ~4 ~61 stone 2
setblock ~104 ~4 ~77 concrete 6
fill ~105 ~4 ~35 ~108 ~4 ~35 glowstone
setblock ~105 ~4 ~41 glowstone
setblock ~105 ~4 ~42 stone 2
setblock ~105 ~4 ~43 glowstone
setblock ~105 ~4 ~44 stone 2
setblock ~105 ~4 ~45 glowstone
setblock ~105 ~4 ~46 stone 2
setblock ~105 ~4 ~47 glowstone
fill ~105 ~4 ~48 ~106 ~4 ~48 stone 2
setblock ~105 ~4 ~49 glowstone
setblock ~105 ~4 ~50 stone 2
setblock ~105 ~4 ~51 glowstone
fill ~105 ~4 ~52 ~106 ~4 ~52 stone 2
setblock ~105 ~4 ~53 glowstone
setblock ~105 ~4 ~54 stone 2
setblock ~105 ~4 ~55 glowstone
fill ~105 ~4 ~56 ~106 ~4 ~56 stone 2
setblock ~105 ~4 ~57 glowstone
setblock ~105 ~4 ~58 stone 2
setblock ~105 ~4 ~59 glowstone
fill ~105 ~4 ~60 ~106 ~4 ~60 stone 2
setblock ~105 ~4 ~61 glowstone
setblock ~105 ~4 ~62 stone 2
setblock ~105 ~4 ~63 glowstone
setblock ~105 ~4 ~78 stained_hardened_clay
setblock ~106 ~4 ~42 stained_hardened_clay 6
setblock ~106 ~4 ~43 stone 2
setblock ~106 ~4 ~44 brick_block
setblock ~106 ~4 ~45 stone 2
setblock ~106 ~4 ~46 brick_block
setblock ~106 ~4 ~47 stone 2
setblock ~106 ~4 ~49 stone 2
setblock ~106 ~4 ~50 brick_block
setblock ~106 ~4 ~51 stone 2
setblock ~106 ~4 ~53 stone 2
setblock ~106 ~4 ~54 brick_block
setblock ~106 ~4 ~55 stone 2
setblock ~106 ~4 ~57 stone 2
setblock ~106 ~4 ~58 brick_block
setblock ~106 ~4 ~59 stone 2
setblock ~106 ~4 ~61 stone 2
setblock ~106 ~4 ~62 brick_block
fill ~106 ~4 ~63 ~106 ~4 ~65 stone 2
setblock ~106 ~4 ~66 brick_block
fill ~106 ~4 ~67 ~106 ~4 ~69 stone 2
setblock ~106 ~4 ~77 stained_hardened_clay
fill ~107 ~4 ~43 ~108 ~4 ~43 glowstone
setblock ~107 ~4 ~44 planks 3
setblock ~107 ~4 ~45 glowstone
setblock ~107 ~4 ~46 stone 2
setblock ~107 ~4 ~47 glowstone
setblock ~107 ~4 ~48 planks 3
setblock ~107 ~4 ~49 glowstone
setblock ~107 ~4 ~50 stone 2
setblock ~107 ~4 ~51 glowstone
setblock ~107 ~4 ~52 planks 3
setblock ~107 ~4 ~53 glowstone
setblock ~107 ~4 ~54 stone 2
setblock ~107 ~4 ~55 glowstone
setblock ~107 ~4 ~56 planks 3
setblock ~107 ~4 ~57 glowstone
setblock ~107 ~4 ~58 stone 2
setblock ~107 ~4 ~59 glowstone
setblock ~107 ~4 ~60 planks 3
setblock ~107 ~4 ~61 glowstone
setblock ~107 ~4 ~62 stone 2
setblock ~107 ~4 ~63 glowstone
setblock ~107 ~4 ~64 planks 3
setblock ~107 ~4 ~65 glowstone
setblock ~107 ~4 ~66 stone 2
setblock ~107 ~4 ~67 glowstone
setblock ~107 ~4 ~68 planks 3
setblock ~107 ~4 ~69 glowstone
setblock ~107 ~4 ~70 stone 2
setblock ~107 ~4 ~76 concrete 6
fill ~108 ~4 ~44 ~108 ~4 ~45 stone 2
setblock ~108 ~4 ~46 brick_block
setblock ~108 ~4 ~47 stone 2
setblock ~108 ~4 ~48 brick_block
setblock ~108 ~4 ~49 stone 2
setblock ~108 ~4 ~50 brick_block
setblock ~108 ~4 ~51 stone 2
setblock ~108 ~4 ~52 brick_block
setblock ~108 ~4 ~53 stone 2
setblock ~108 ~4 ~54 brick_block
setblock ~108 ~4 ~55 stone 2
setblock ~108 ~4 ~56 brick_block
setblock ~108 ~4 ~57 stone 2
setblock ~108 ~4 ~58 brick_block
setblock ~108 ~4 ~59 stone 2
setblock ~108 ~4 ~60 brick_block
setblock ~108 ~4 ~61 stone 2
setblock ~108 ~4 ~62 brick_block
setblock ~108 ~4 ~63 stone 2
setblock ~108 ~4 ~64 brick_block
setblock ~108 ~4 ~65 stone 2
setblock ~108 ~4 ~66 brick_block
setblock ~108 ~4 ~67 stone 2
setblock ~108 ~4 ~68 brick_block
setblock ~108 ~4 ~69 stone 2
setblock ~108 ~4 ~70 brick_block
fill ~108 ~4 ~71 ~108 ~5 ~71 stone 2
setblock ~108 ~4 ~72 brick_block
fill ~108 ~4 ~73 ~108 ~5 ~73 stone 2
fill ~108 ~4 ~74 ~108 ~4 ~73 stone 2
setblock ~108 ~4 ~75 glowstone
fill ~109 ~4 ~35 ~109 ~6 ~35 concrete 6
setblock ~109 ~4 ~44 planks 3
setblock ~109 ~4 ~45 glowstone
fill ~109 ~4 ~46 ~111 ~4 ~46 stone 2
setblock ~109 ~4 ~47 glowstone
fill ~109 ~4 ~48 ~110 ~4 ~48 stone 2
setblock ~109 ~4 ~49 glowstone
setblock ~109 ~4 ~50 stone 2
setblock ~109 ~4 ~51 glowstone
fill ~109 ~4 ~52 ~110 ~4 ~52 stone 2
setblock ~109 ~4 ~53 glowstone
setblock ~109 ~4 ~54 stone 2
setblock ~109 ~4 ~55 glowstone
fill ~109 ~4 ~56 ~110 ~4 ~56 stone 2
setblock ~109 ~4 ~57 glowstone
setblock ~109 ~4 ~58 stone 2
setblock ~109 ~4 ~59 glowstone
setblock ~109 ~4 ~60 stone 2
setblock ~109 ~4 ~61 glowstone
setblock ~109 ~4 ~62 stone 2
setblock ~110 ~4 ~36 stone 2
fill ~110 ~4 ~44 ~112 ~4 ~44 stone 2
fill ~110 ~4 ~45 ~110 ~4 ~44 stone 2
setblock ~110 ~4 ~47 stone 2
setblock ~110 ~4 ~49 stone 2
setblock ~110 ~4 ~50 brick_block
setblock ~110 ~4 ~51 stone 2
setblock ~110 ~4 ~53 stone 2
setblock ~110 ~4 ~54 brick_block
setblock ~110 ~4 ~55 stone 2
setblock ~110 ~4 ~57 stone 2
setblock ~111 ~4 ~37 concrete 6
fill ~111 ~4 ~42 ~112 ~4 ~42 stone 2
fill ~111 ~4 ~43 ~112 ~4 ~43 glowstone
setblock ~111 ~4 ~45 glowstone
setblock ~111 ~4 ~47 glowstone
setblock ~111 ~4 ~48 planks 3
setblock ~111 ~4 ~49 glowstone
setblock ~112 ~4 ~38 stone 2
setblock ~112 ~4 ~39 concrete 6
setblock ~112 ~4 ~40 stone 2
setblock ~112 ~4 ~41 glowstone
setblock ~31 ~5 ~40 glowstone
setblock ~31 ~5 ~41 planks 2
fill ~31 ~5 ~42 ~31 ~6 ~42 glowstone
setblock ~32 ~5 ~38 concrete 6
fill ~32 ~5 ~39 ~32 ~6 ~39 glowstone
setblock ~32 ~5 ~43 stone 2
setblock ~32 ~5 ~44 glowstone
setblock ~32 ~5 ~45 stone 2
setblock ~32 ~5 ~46 glowstone
setblock ~32 ~5 ~47 stone 2
setblock ~32 ~5 ~48 glowstone
fill ~32 ~5 ~49 ~32 ~7 ~49 stone 2
fill ~33 ~5 ~36 ~34 ~5 ~36 concrete 6
setblock ~33 ~5 ~37 planks 2
fill ~33 ~5 ~50 ~33 ~5 ~57 glowstone
setblock ~34 ~5 ~58 glowstone
setblock ~34 ~5 ~59 stone 2
setblock ~34 ~5 ~60 glowstone
setblock ~34 ~5 ~61 stone 2
setblock ~34 ~5 ~62 glowstone
fill ~35 ~5 ~63 ~35 ~5 ~70 glowstone
fill ~36 ~5 ~35 ~36 ~4 ~35 glowstone
setblock ~36 ~5 ~72 glowstone
setblock ~36 ~5 ~74 concrete 6
setblock ~37 ~5 ~34 glowstone
setblock ~37 ~5 ~75 wool 6
setblock ~38 ~5 ~34 concrete 6
fill ~38 ~5 ~76 ~40 ~5 ~76 stained_hardened_clay
setblock ~39 ~5 ~35 planks 2
setblock ~39 ~5 ~77 glass
setblock ~40 ~5 ~44 glowstone
setblock ~40 ~5 ~45 stone 2
setblock ~40 ~5 ~46 glowstone
setblock ~40 ~5 ~47 stone 2
setblock ~40 ~5 ~48 glowstone
setblock ~40 ~5 ~49 stone 2
fill ~41 ~5 ~36 ~41 ~7 ~36 glowstone
setblock ~41 ~5 ~37 concrete 6
setblock ~41 ~5 ~39 concrete 6
setblock ~41 ~5 ~40 glowstone
setblock ~41 ~5 ~41 concrete 6
setblock ~41 ~5 ~42 glowstone
setblock ~41 ~5 ~43 concrete 6
setblock ~41 ~5 ~49 concrete 6
fill ~41 ~5 ~50 ~41 ~5 ~52 glowstone
setblock ~41 ~5 ~53 concrete 6
fill ~41 ~5 ~75 ~41 ~6 ~75 concrete 6
setblock ~42 ~5 ~38 glowstone
setblock ~42 ~5 ~54 glowstone
setblock ~42 ~5 ~55 stone 2
setblock ~42 ~5 ~56 glowstone
setblock ~42 ~5 ~76 concrete 6
fill ~43 ~5 ~57 ~43 ~6 ~57 glowstone
fill ~43 ~5 ~58 ~43 ~5 ~59 glowstone
setblock ~43 ~5 ~77 stained_hardened_clay
setblock ~44 ~5 ~60 glowstone
setblock ~44 ~5 ~61 stone 2
setblock ~44 ~5 ~77 concrete 6
fill ~45 ~5 ~62 ~45 ~5 ~63 glowstone
setblock ~45 ~5 ~74 glowstone
setblock ~45 ~5 ~75 planks 2
setblock ~45 ~5 ~76 stained_hardened_clay
setblock ~46 ~5 ~64 glowstone
setblock ~46 ~5 ~65 stone 2
setblock ~47 ~5 ~66 glowstone
setblock ~47 ~5 ~74 concrete 6
setblock ~48 ~5 ~67 stone 2
setblock ~48 ~5 ~68 glowstone
setblock ~48 ~5 ~74 wool 6
setblock ~49 ~5 ~70 glowstone
fill ~49 ~5 ~71 ~49 ~5 ~72 concrete 6
fill ~49 ~5 ~73 ~49 ~5 ~75 stained_hardened_clay
setblock ~50 ~5 ~73 glowstone
setblock ~50 ~5 ~74 stained_hardened_clay
setblock ~94 ~5 ~73 glowstone
fill ~94 ~5 ~74 ~95 ~5 ~74 stained_hardened_clay
setblock ~95 ~5 ~70 glowstone
fill ~95 ~5 ~71 ~95 ~5 ~72 concrete 6
setblock ~95 ~5 ~73 stained_hardened_clay
setblock ~95 ~5 ~75 stained_hardened_clay
setblock ~96 ~5 ~67 stone 2
setblock ~96 ~5 ~68 glowstone
setblock ~96 ~5 ~74 wool 6
setblock ~97 ~5 ~66 glowstone
setblock ~97 ~5 ~74 concrete 6
setblock ~98 ~5 ~64 glowstone
setblock ~98 ~5 ~65 stone 2
fill ~99 ~5 ~62 ~99 ~5 ~63 glowstone
setblock ~99 ~5 ~74 glowstone
setblock ~99 ~5 ~75 planks 2
setblock ~99 ~5 ~76 stained_hardened_clay
setblock ~100 ~5 ~60 glowstone
setblock ~100 ~5 ~61 stone 2
setblock ~100 ~5 ~77 concrete 6
fill ~101 ~5 ~57 ~101 ~6 ~57 glowstone
fill ~101 ~5 ~58 ~101 ~5 ~59 glowstone
setblock ~101 ~5 ~77 stained_hardened_clay
setblock ~102 ~5 ~38 glowstone
setblock ~102 ~5 ~54 glowstone
setblock ~102 ~5 ~55 stone 2
setblock ~102 ~5 ~56 glowstone
setblock ~102 ~5 ~76 concrete 6
fill ~103 ~5 ~36 ~103 ~7 ~36 glowstone
setblock ~103 ~5 ~37 concrete 6
setblock ~103 ~5 ~39 concrete 6
setblock ~103 ~5 ~40 glowstone
setblock ~103 ~5 ~41 concrete 6
setblock ~103 ~5 ~42 glowstone
setblock ~103 ~5 ~43 concrete 6
setblock ~103 ~5 ~49 concrete 6
fill ~103 ~5 ~50 ~103 ~5 ~52 glowstone
setblock ~103 ~5 ~53 concrete 6
fill ~103 ~5 ~75 ~103 ~6 ~75 concrete 6
setblock ~104 ~5 ~44 glowstone
setblock ~104 ~5 ~45 stone 2
setblock ~104 ~5 ~46 glowstone
setblock ~104 ~5 ~47 stone 2
setblock ~104 ~5 ~48 glowstone
setblock ~104 ~5 ~49 stone 2
fill ~104 ~5 ~76 ~106 ~5 ~76 stained_hardened_clay
setblock ~105 ~5 ~35 planks 2
setblock ~105 ~5 ~77 glass
setblock ~106 ~5 ~34 concrete 6
setblock ~107 ~5 ~34 glowstone
setblock ~107 ~5 ~75 wool 6
setblock ~108 ~5 ~35 glowstone
setblock ~108 ~5 ~72 glowstone
setblock ~108 ~5 ~74 concrete 6
fill ~109 ~5 ~63 ~109 ~5 ~70 glowstone
fill ~110 ~5 ~36 ~111 ~5 ~36 concrete 6
setblock ~110 ~5 ~58 glowstone
setblock ~110 ~5 ~59 stone 2
setblock ~110 ~5 ~60 glowstone
setblock ~110 ~5 ~61 stone 2
setblock ~110 ~5 ~62 glowstone
setblock ~111 ~5 ~37 planks 2
fill ~111 ~5 ~50 ~111 ~5 ~57 glowstone
setblock ~112 ~5 ~38 concrete 6
fill ~112 ~5 ~39 ~112 ~6 ~39 glowstone
setblock ~112 ~5 ~43 stone 2
setblock ~112 ~5 ~44 glowstone
setblock ~112 ~5 ~45 stone 2
setblock ~112 ~5 ~46 glowstone
setblock ~112 ~5 ~47 stone 2
setblock ~112 ~5 ~48 glowstone
fill ~112 ~5 ~49 ~112 ~7 ~49 stone 2
setblock ~113 ~5 ~40 glowstone
setblock ~113 ~5 ~41 planks 2
fill ~113 ~5 ~42 ~113 ~6 ~42 glowstone
setblock ~31 ~6 ~41 concrete 6
setblock ~31 ~6 ~43 glowstone
setblock ~31 ~6 ~44 stone 2
setblock ~31 ~6 ~45 glowstone
setblock ~31 ~6 ~46 stone 2
setblock ~32 ~6 ~40 stone 2
setblock ~32 ~6 ~47 glowstone
setblock ~32 ~6 ~48 stone 2
fill ~32 ~6 ~50 ~32 ~6 ~51 stone 2
setblock ~32 ~6 ~52 brick_block
fill ~32 ~6 ~53 ~32 ~7 ~53 stone 2
fill ~32 ~6 ~54 ~32 ~6 ~53 stone 2
setblock ~33 ~6 ~37 concrete 6
fill ~33 ~6 ~38 ~33 ~7 ~38 glowstone
setblock ~33 ~6 ~55 glowstone
setblock ~33 ~6 ~56 planks 3
fill ~33 ~6 ~57 ~33 ~8 ~57 glowstone
setblock ~33 ~6 ~58 planks 3
fill ~33 ~6 ~59 ~33 ~7 ~59 glowstone
setblock ~33 ~6 ~60 planks 3
fill ~33 ~6 ~61 ~33 ~7 ~61 glowstone
setblock ~34 ~6 ~36 glowstone
fill ~34 ~6 ~62 ~34 ~6 ~65 stone 2
setblock ~35 ~6 ~66 planks 3
fill ~35 ~6 ~67 ~35 ~7 ~67 glowstone
setblock ~35 ~6 ~68 stone 2
setblock ~35 ~6 ~69 glowstone
setblock ~35 ~6 ~70 stone 2
fill ~36 ~6 ~35 ~37 ~6 ~35 concrete 6
setblock ~36 ~6 ~71 glowstone
setblock ~36 ~6 ~72 stone 2
fill ~37 ~6 ~73 ~38 ~6 ~73 concrete 6
fill ~37 ~6 ~74 ~38 ~6 ~74 glowstone
setblock ~38 ~6 ~34 stone 2
fill ~38 ~6 ~75 ~39 ~6 ~75 stained_hardened_clay
fill ~39 ~6 ~35 ~40 ~6 ~35 glowstone
setblock ~39 ~6 ~74 concrete 6
setblock ~40 ~6 ~75 concrete 6
setblock ~41 ~6 ~41 glowstone
setblock ~41 ~6 ~42 stone 2
fill ~41 ~6 ~43 ~41 ~6 ~45 glowstone
setblock ~41 ~6 ~46 stone 2
setblock ~41 ~6 ~47 glowstone
setblock ~41 ~6 ~48 stone 2
setblock ~41 ~6 ~49 glowstone
setblock ~42 ~6 ~37 glowstone
setblock ~42 ~6 ~38 stone 2
setblock ~42 ~6 ~39 glowstone
setblock ~42 ~6 ~40 stone 2
fill ~42 ~6 ~50 ~42 ~6 ~52 stone 2
setblock ~42 ~6 ~53 glowstone
setblock ~42 ~6 ~75 concrete 6
setblock ~43 ~6 ~54 stone 2
fill ~43 ~6 ~55 ~43 ~7 ~55 glowstone
setblock ~43 ~6 ~56 stone 2
fill ~43 ~6 ~75 ~44 ~6 ~75 stained_hardened_clay
fill ~43 ~6 ~76 ~44 ~6 ~76 concrete 6
fill ~44 ~6 ~58 ~44 ~6 ~59 stone 2
setblock ~44 ~6 ~74 concrete 6
setblock ~45 ~6 ~60 planks 3
setblock ~45 ~6 ~61 glowstone
setblock ~45 ~6 ~74 stone 2
fill ~46 ~6 ~62 ~46 ~6 ~63 stone 2
setblock ~46 ~6 ~73 concrete 6
setblock ~47 ~6 ~64 stone 2
setblock ~47 ~6 ~65 glowstone
setblock ~47 ~6 ~66 stone 2
setblock ~47 ~6 ~72 concrete 6
setblock ~47 ~6 ~73 stained_hardened_clay
setblock ~48 ~6 ~67 glowstone
setblock ~48 ~6 ~68 stone 2
setblock ~48 ~6 ~69 concrete 6
setblock ~48 ~6 ~70 glowstone
setblock ~48 ~6 ~71 concrete 6
setblock ~48 ~6 ~72 glowstone
setblock ~48 ~6 ~73 concrete 6
setblock ~96 ~6 ~67 glowstone
setblock ~96 ~6 ~68 stone 2
setblock ~96 ~6 ~69 concrete 6
setblock ~96 ~6 ~70 glowstone
setblock ~96 ~6 ~71 concrete 6
setblock ~96 ~6 ~72 glowstone
setblock ~96 ~6 ~73 concrete 6
setblock ~97 ~6 ~64 stone 2
setblock ~97 ~6 ~65 glowstone
setblock ~97 ~6 ~66 stone 2
setblock ~97 ~6 ~72 concrete 6
setblock ~97 ~6 ~73 stained_hardened_clay
fill ~98 ~6 ~62 ~98 ~6 ~63 stone 2
setblock ~98 ~6 ~73 concrete 6
setblock ~99 ~6 ~60 planks 3
setblock ~99 ~6 ~61 glowstone
setblock ~99 ~6 ~74 stone 2
fill ~100 ~6 ~58 ~100 ~6 ~59 stone 2
setblock ~100 ~6 ~74 concrete 6
fill ~100 ~6 ~75 ~101 ~6 ~75 stained_hardened_clay
fill ~100 ~6 ~76 ~101 ~6 ~76 concrete 6
setblock ~101 ~6 ~54 stone 2
fill ~101 ~6 ~55 ~101 ~7 ~55 glowstone
setblock ~101 ~6 ~56 stone 2
setblock ~102 ~6 ~37 glowstone
setblock ~102 ~6 ~38 stone 2
setblock ~102 ~6 ~39 glowstone
setblock ~102 ~6 ~40 stone 2
fill ~102 ~6 ~50 ~102 ~6 ~52 stone 2
setblock ~102 ~6 ~53 glowstone
setblock ~102 ~6 ~75 concrete 6
setblock ~103 ~6 ~41 glowstone
setblock ~103 ~6 ~42 stone 2
fill ~103 ~6 ~43 ~103 ~6 ~45 glowstone
setblock ~103 ~6 ~46 stone 2
setblock ~103 ~6 ~47 glowstone
setblock ~103 ~6 ~48 stone 2
setblock ~103 ~6 ~49 glowstone
fill ~104 ~6 ~35 ~105 ~6 ~35 glowstone
setblock ~104 ~6 ~75 concrete 6
setblock ~105 ~6 ~74 concrete 6
fill ~105 ~6 ~75 ~106 ~6 ~75 stained_hardened_clay
setblock ~106 ~6 ~34 stone 2
fill ~106 ~6 ~73 ~107 ~6 ~73 concrete 6
fill ~106 ~6 ~74 ~107 ~6 ~74 glowstone
fill ~107 ~6 ~35 ~109 ~6 ~35 concrete 6
setblock ~108 ~6 ~71 glowstone
setblock ~108 ~6 ~72 stone 2
setblock ~109 ~6 ~66 planks 3
fill ~109 ~6 ~67 ~109 ~7 ~67 glowstone
setblock ~109 ~6 ~68 stone 2
setblock ~109 ~6 ~69 glowstone
setblock ~109 ~6 ~70 stone 2
setblock ~110 ~6 ~36 glowstone
fill ~110 ~6 ~62 ~110 ~6 ~65 stone 2
setblock ~111 ~6 ~37 concrete 6
fill ~111 ~6 ~38 ~111 ~7 ~38 glowstone
setblock ~111 ~6 ~55 glowstone
setblock ~111 ~6 ~56 planks 3
fill ~111 ~6 ~57 ~111 ~8 ~57 glowstone
setblock ~111 ~6 ~58 planks 3
fill ~111 ~6 ~59 ~111 ~7 ~59 glowstone
setblock ~111 ~6 ~60 planks 3
fill ~111 ~6 ~61 ~111 ~7 ~61 glowstone
setblock ~112 ~6 ~40 stone 2
setblock ~112 ~6 ~47 glowstone
setblock ~112 ~6 ~48 stone 2
fill ~112 ~6 ~50 ~112 ~6 ~51 stone 2
setblock ~112 ~6 ~52 brick_block
fill ~112 ~6 ~53 ~112 ~7 ~53 stone 2
fill ~112 ~6 ~54 ~112 ~6 ~53 stone 2
setblock ~113 ~6 ~41 concrete 6
setblock ~113 ~6 ~43 glowstone
setblock ~113 ~6 ~44 stone 2
setblock ~113 ~6 ~45 glowstone
setblock ~113 ~6 ~46 stone 2
setblock ~31 ~7 ~48 glowstone
setblock ~32 ~7 ~40 concrete 6
setblock ~32 ~7 ~41 glowstone
setblock ~32 ~7 ~42 concrete 6
setblock ~32 ~7 ~43 glowstone
setblock ~32 ~7 ~44 concrete 6
setblock ~32 ~7 ~45 stone 2
setblock ~32 ~7 ~46 concrete 6
setblock ~32 ~7 ~47 stone 2
setblock ~32 ~7 ~48 concrete 6
setblock ~32 ~7 ~50 glowstone
setblock ~32 ~7 ~51 stone 2
setblock ~32 ~7 ~52 glowstone
setblock ~32 ~7 ~54 glowstone
setblock ~32 ~7 ~55 stone 2
setblock ~32 ~7 ~56 glowstone
setblock ~33 ~7 ~39 planks 2
setblock ~33 ~7 ~58 glowstone
setblock ~33 ~7 ~60 glowstone
setblock ~34 ~7 ~37 glowstone
setblock ~34 ~7 ~62 glowstone
setblock ~34 ~7 ~63 stone 2
setblock ~34 ~7 ~64 glowstone
setblock ~34 ~7 ~65 stone 2
setblock ~35 ~7 ~36 glowstone
setblock ~35 ~7 ~66 glowstone
setblock ~35 ~7 ~68 glowstone
setblock ~36 ~7 ~35 glowstone
setblock ~36 ~7 ~69 stone 2
setblock ~36 ~7 ~70 glowstone
setblock ~37 ~7 ~35 planks 2
setblock ~37 ~7 ~70 concrete 6
setblock ~37 ~7 ~71 planks 2
setblock ~37 ~7 ~72 concrete 6
fill ~38 ~7 ~35 ~38 ~8 ~35 glowstone
setblock ~38 ~7 ~71 concrete 6
fill ~38 ~7 ~72 ~39 ~7 ~72 stained_hardened_clay
fill ~39 ~7 ~35 ~39 ~8 ~35 concrete 6
setblock ~39 ~7 ~73 stained_hardened_clay
setblock ~40 ~7 ~35 stone 2
setblock ~40 ~7 ~72 wool 6
setblock ~40 ~7 ~73 concrete 6
setblock ~40 ~7 ~74 wool 6
setblock ~41 ~7 ~37 concrete 6
setblock ~41 ~7 ~72 planks 2
setblock ~41 ~7 ~73 stained_hardened_clay
setblock ~41 ~7 ~74 concrete 6
setblock ~42 ~7 ~38 concrete 6
setblock ~42 ~7 ~39 stone 2
setblock ~42 ~7 ~40 planks 2
setblock ~42 ~7 ~41 stone 2
setblock ~42 ~7 ~42 concrete 6
setblock ~42 ~7 ~43 stone 2
setblock ~42 ~7 ~44 concrete 6
setblock ~42 ~7 ~45 stone 2
setblock ~42 ~7 ~46 concrete 6
setblock ~42 ~7 ~47 stone 2
setblock ~42 ~7 ~48 concrete 6
setblock ~42 ~7 ~49 planks 3
setblock ~42 ~7 ~50 glowstone
setblock ~42 ~7 ~51 stone 2
setblock ~42 ~7 ~72 wool 6
setblock ~42 ~7 ~73 concrete 6
fill ~42 ~7 ~74 ~43 ~7 ~74 stained_hardened_clay
fill ~43 ~7 ~52 ~43 ~7 ~55 glowstone
fill ~43 ~7 ~72 ~45 ~7 ~72 concrete 6
setblock ~43 ~7 ~73 stained_hardened_clay
setblock ~44 ~7 ~56 glowstone
setblock ~44 ~7 ~57 stone 2
setblock ~44 ~7 ~58 glowstone
setblock ~44 ~7 ~73 glowstone
fill ~45 ~7 ~59 ~45 ~8 ~59 glowstone
fill ~45 ~7 ~60 ~45 ~7 ~59 glowstone
setblock ~45 ~7 ~71 stained_hardened_clay
setblock ~45 ~7 ~73 stained_hardened_clay
setblock ~46 ~7 ~61 stone 2
setblock ~46 ~7 ~62 glowstone
setblock ~46 ~7 ~63 stone 2
setblock ~46 ~7 ~70 stained_hardened_clay
setblock ~46 ~7 ~71 concrete 6
setblock ~46 ~7 ~72 stained_hardened_clay
setblock ~47 ~7 ~64 glowstone
setblock ~47 ~7 ~65 concrete 6
setblock ~47 ~7 ~66 glowstone
setblock ~47 ~7 ~67 planks 2
setblock ~47 ~7 ~68 concrete 6
setblock ~47 ~7 ~69 wool 6
setblock ~47 ~7 ~70 concrete 6
setblock ~47 ~7 ~71 stained_hardened_clay
setblock ~97 ~7 ~64 glowstone
setblock ~97 ~7 ~65 planks 2
setblock ~97 ~7 ~66 glowstone
setblock ~97 ~7 ~67 planks 2
setblock ~97 ~7 ~68 concrete 6
setblock ~97 ~7 ~69 wool 6
setblock ~97 ~7 ~70 concrete 6
setblock ~97 ~7 ~71 stained_hardened_clay
setblock ~98 ~7 ~61 stone 2
setblock ~98 ~7 ~62 glowstone
setblock ~98 ~7 ~63 stone 2
setblock ~98 ~7 ~70 stained_hardened_clay
setblock ~98 ~7 ~71 concrete 6
setblock ~98 ~7 ~72 stained_hardened_clay
fill ~99 ~7 ~59 ~99 ~8 ~59 glowstone
fill ~99 ~7 ~60 ~99 ~7 ~59 glowstone
setblock ~99 ~7 ~71 stained_hardened_clay
fill ~99 ~7 ~72 ~101 ~7 ~72 concrete 6
setblock ~99 ~7 ~73 stained_hardened_clay
setblock ~100 ~7 ~56 glowstone
setblock ~100 ~7 ~57 stone 2
setblock ~100 ~7 ~58 glowstone
setblock ~100 ~7 ~73 glowstone
fill ~101 ~7 ~52 ~101 ~7 ~55 glowstone
fill ~101 ~7 ~73 ~101 ~7 ~74 stained_hardened_clay
setblock ~102 ~7 ~38 concrete 6
setblock ~102 ~7 ~39 stone 2
setblock ~102 ~7 ~40 planks 2
setblock ~102 ~7 ~41 stone 2
setblock ~102 ~7 ~42 concrete 6
setblock ~102 ~7 ~43 stone 2
setblock ~102 ~7 ~44 concrete 6
setblock ~102 ~7 ~45 stone 2
setblock ~102 ~7 ~46 concrete 6
setblock ~102 ~7 ~47 stone 2
setblock ~102 ~7 ~48 concrete 6
setblock ~102 ~7 ~49 planks 3
setblock ~102 ~7 ~50 glowstone
setblock ~102 ~7 ~51 stone 2
setblock ~102 ~7 ~72 wool 6
setblock ~102 ~7 ~73 concrete 6
setblock ~102 ~7 ~74 stained_hardened_clay
setblock ~103 ~7 ~37 concrete 6
setblock ~103 ~7 ~72 planks 2
setblock ~103 ~7 ~73 stained_hardened_clay
setblock ~103 ~7 ~74 concrete 6
setblock ~104 ~7 ~35 stone 2
setblock ~104 ~7 ~72 wool 6
setblock ~104 ~7 ~73 concrete 6
setblock ~104 ~7 ~74 wool 6
fill ~105 ~7 ~35 ~105 ~8 ~35 concrete 6
fill ~105 ~7 ~72 ~106 ~7 ~72 stained_hardened_clay
fill ~105 ~7 ~73 ~105 ~7 ~72 stained_hardened_clay
fill ~106 ~7 ~35 ~106 ~8 ~35 glowstone
setblock ~106 ~7 ~71 concrete 6
setblock ~107 ~7 ~35 planks 2
setblock ~107 ~7 ~70 concrete 6
setblock ~107 ~7 ~71 planks 2
setblock ~107 ~7 ~72 concrete 6
setblock ~108 ~7 ~35 glowstone
setblock ~108 ~7 ~69 stone 2
setblock ~108 ~7 ~70 glowstone
setblock ~109 ~7 ~36 glowstone
setblock ~109 ~7 ~66 glowstone
setblock ~109 ~7 ~68 glowstone
setblock ~110 ~7 ~37 glowstone
setblock ~110 ~7 ~62 glowstone
setblock ~110 ~7 ~63 stone 2
setblock ~110 ~7 ~64 glowstone
setblock ~110 ~7 ~65 stone 2
setblock ~111 ~7 ~39 planks 2
setblock ~111 ~7 ~58 glowstone
setblock ~111 ~7 ~60 glowstone
setblock ~112 ~7 ~40 concrete 6
setblock ~112 ~7 ~41 glowstone
setblock ~112 ~7 ~42 concrete 6
setblock ~112 ~7 ~43 glowstone
setblock ~112 ~7 ~44 concrete 6
setblock ~112 ~7 ~45 stone 2
setblock ~112 ~7 ~46 concrete 6
setblock ~112 ~7 ~47 stone 2
setblock ~112 ~7 ~48 concrete 6
setblock ~112 ~7 ~50 glowstone
setblock ~112 ~7 ~51 stone 2
setblock ~112 ~7 ~52 glowstone
setblock ~112 ~7 ~54 glowstone
setblock ~112 ~7 ~55 stone 2
setblock ~112 ~7 ~56 glowstone
setblock ~113 ~7 ~48 glowstone
setblock ~32 ~8 ~47 glowstone
setblock ~33 ~8 ~39 concrete 6
setblock ~33 ~8 ~40 glowstone
setblock ~33 ~8 ~41 concrete 6
setblock ~33 ~8 ~42 glowstone
fill ~33 ~8 ~43 ~33 ~8 ~45 concrete 6
setblock ~33 ~8 ~46 glowstone
fill ~33 ~8 ~47 ~33 ~8 ~49 concrete 6
fill ~33 ~8 ~50 ~33 ~8 ~53 glowstone
fill ~33 ~8 ~54 ~34 ~8 ~54 stone 2
setblock ~33 ~8 ~55 concrete 6
fill ~33 ~8 ~56 ~34 ~8 ~56 stone 2
fill ~33 ~8 ~58 ~34 ~8 ~58 stone 2
setblock ~34 ~8 ~38 stone 2
fill ~34 ~8 ~47 ~34 ~8 ~49 glowstone
setblock ~34 ~8 ~50 stone 2
setblock ~34 ~8 ~51 glowstone
setblock ~34 ~8 ~52 stone 2
setblock ~34 ~8 ~53 glowstone
setblock ~34 ~8 ~55 glowstone
setblock ~34 ~8 ~57 glowstone
setblock ~34 ~8 ~59 glowstone
fill ~34 ~8 ~60 ~34 ~8 ~62 stone 2
setblock ~35 ~8 ~37 concrete 6
setblock ~35 ~8 ~61 glowstone
setblock ~35 ~8 ~62 stone 2
fill ~35 ~8 ~63 ~35 ~8 ~65 glowstone
setblock ~36 ~8 ~36 stone 2
setblock ~36 ~8 ~65 glowstone
setblock ~36 ~8 ~66 stone 2
setblock ~36 ~8 ~67 glowstone
setblock ~36 ~8 ~68 stone 2
setblock ~37 ~8 ~35 concrete 6
fill ~37 ~8 ~67 ~37 ~8 ~69 concrete 6
setblock ~38 ~8 ~68 glowstone
setblock ~38 ~8 ~69 concrete 6
setblock ~38 ~8 ~70 glowstone
setblock ~39 ~8 ~69 stained_hardened_clay
setblock ~39 ~8 ~70 concrete 6
setblock ~39 ~8 ~71 stained_hardened_clay
setblock ~40 ~8 ~36 stone 2
setblock ~40 ~8 ~69 concrete 6
setblock ~40 ~8 ~70 glowstone
setblock ~40 ~8 ~71 concrete 6
setblock ~41 ~8 ~37 glowstone
setblock ~41 ~8 ~69 wool 6
fill ~41 ~8 ~70 ~42 ~8 ~70 concrete 6
fill ~41 ~8 ~71 ~42 ~8 ~71 stained_hardened_clay
setblock ~42 ~8 ~38 stone 2
fill ~42 ~8 ~39 ~42 ~9 ~39 glowstone
setblock ~42 ~8 ~40 stone 2
setblock ~42 ~8 ~41 glowstone
setblock ~42 ~8 ~42 stone 2
setblock ~42 ~8 ~43 concrete 6
setblock ~42 ~8 ~44 stone 2
setblock ~42 ~8 ~45 glowstone
setblock ~42 ~8 ~46 stone 2
setblock ~42 ~8 ~47 glowstone
setblock ~42 ~8 ~48 stone 2
setblock ~42 ~8 ~49 concrete 6
setblock ~42 ~8 ~69 concrete 6
fill ~43 ~8 ~50 ~43 ~8 ~51 glowstone
setblock ~43 ~8 ~52 stone 2
setblock ~43 ~8 ~53 glowstone
setblock ~43 ~8 ~69 planks 2
fill ~43 ~8 ~70 ~44 ~8 ~70 glowstone
setblock ~43 ~8 ~71 concrete 6
fill ~44 ~8 ~54 ~44 ~8 ~56 stone 2
setblock ~44 ~8 ~68 glowstone
setblock ~44 ~8 ~69 concrete 6
setblock ~44 ~8 ~71 glowstone
setblock ~45 ~8 ~57 glowstone
setblock ~45 ~8 ~58 planks 3
setblock ~45 ~8 ~60 stone 2
fill ~45 ~8 ~67 ~46 ~8 ~67 concrete 6
fill ~45 ~8 ~68 ~45 ~8 ~67 concrete 6
setblock ~45 ~8 ~69 stained_hardened_clay
setblock ~45 ~8 ~70 concrete 6
setblock ~46 ~8 ~61 glowstone
setblock ~46 ~8 ~62 stone 2
setblock ~46 ~8 ~63 glowstone
setblock ~46 ~8 ~64 stone 2
setblock ~46 ~8 ~65 concrete 6
setblock ~46 ~8 ~66 glowstone
setblock ~46 ~8 ~68 glowstone
setblock ~46 ~8 ~69 concrete 6
setblock ~98 ~8 ~61 glowstone
setblock ~98 ~8 ~62 stone 2
setblock ~98 ~8 ~63 glowstone
setblock ~98 ~8 ~64 stone 2
setblock ~98 ~8 ~65 concrete 6
setblock ~98 ~8 ~66 glowstone
fill ~98 ~8 ~67 ~99 ~8 ~67 concrete 6
setblock ~98 ~8 ~68 glowstone
setblock ~98 ~8 ~69 concrete 6
setblock ~99 ~8 ~57 glowstone
setblock ~99 ~8 ~58 planks 3
setblock ~99 ~8 ~60 stone 2
setblock ~99 ~8 ~68 concrete 6
setblock ~99 ~8 ~69 stained_hardened_clay
setblock ~99 ~8 ~70 concrete 6
fill ~100 ~8 ~54 ~100 ~8 ~56 stone 2
setblock ~100 ~8 ~68 glowstone
setblock ~100 ~8 ~69 concrete 6
fill ~100 ~8 ~70 ~101 ~8 ~70 glowstone
fill ~100 ~8 ~71 ~100 ~8 ~70 glowstone
fill ~101 ~8 ~50 ~101 ~8 ~51 glowstone
setblock ~101 ~8 ~52 stone 2
setblock ~101 ~8 ~53 glowstone
setblock ~101 ~8 ~69 planks 2
setblock ~101 ~8 ~71 concrete 6
setblock ~102 ~8 ~38 stone 2
fill ~102 ~8 ~39 ~102 ~9 ~39 glowstone
setblock ~102 ~8 ~40 stone 2
setblock ~102 ~8 ~41 glowstone
setblock ~102 ~8 ~42 stone 2
setblock ~102 ~8 ~43 concrete 6
setblock ~102 ~8 ~44 stone 2
setblock ~102 ~8 ~45 glowstone
setblock ~102 ~8 ~46 stone 2
setblock ~102 ~8 ~47 glowstone
setblock ~102 ~8 ~48 stone 2
setblock ~102 ~8 ~49 concrete 6
fill ~102 ~8 ~69 ~102 ~8 ~70 concrete 6
fill ~102 ~8 ~71 ~103 ~8 ~71 stained_hardened_clay
setblock ~103 ~8 ~37 glowstone
setblock ~103 ~8 ~69 wool 6
setblock ~103 ~8 ~70 concrete 6
setblock ~104 ~8 ~36 stone 2
setblock ~104 ~8 ~69 concrete 6
setblock ~104 ~8 ~70 glowstone
setblock ~104 ~8 ~71 concrete 6
setblock ~105 ~8 ~69 stained_hardened_clay
setblock ~105 ~8 ~70 concrete 6
setblock ~105 ~8 ~71 stained_hardened_clay
setblock ~106 ~8 ~68 glowstone
fill ~106 ~8 ~69 ~107 ~8 ~69 concrete 6
setblock ~106 ~8 ~70 glowstone
setblock ~107 ~8 ~35 concrete 6
fill ~107 ~8 ~67 ~107 ~8 ~69 concrete 6
setblock ~108 ~8 ~36 stone 2
fill ~108 ~8 ~65 ~109 ~8 ~65 glowstone
setblock ~108 ~8 ~66 stone 2
setblock ~108 ~8 ~67 glowstone
setblock ~108 ~8 ~68 stone 2
setblock ~109 ~8 ~37 concrete 6
setblock ~109 ~8 ~61 glowstone
fill ~109 ~8 ~62 ~110 ~8 ~62 stone 2
fill ~109 ~8 ~63 ~109 ~8 ~65 glowstone
setblock ~110 ~8 ~38 stone 2
fill ~110 ~8 ~47 ~110 ~8 ~49 glowstone
setblock ~110 ~8 ~50 stone 2
fill ~110 ~8 ~51 ~111 ~8 ~51 glowstone
setblock ~110 ~8 ~52 stone 2
fill ~110 ~8 ~53 ~111 ~8 ~53 glowstone
fill ~110 ~8 ~54 ~111 ~8 ~54 stone 2
setblock ~110 ~8 ~55 glowstone
fill ~110 ~8 ~56 ~111 ~8 ~56 stone 2
setblock ~110 ~8 ~57 glowstone
fill ~110 ~8 ~58 ~111 ~8 ~58 stone 2
setblock ~110 ~8 ~59 glowstone
fill ~110 ~8 ~60 ~110 ~8 ~62 stone 2
setblock ~111 ~8 ~39 concrete 6
setblock ~111 ~8 ~40 glowstone
setblock ~111 ~8 ~41 concrete 6
setblock ~111 ~8 ~42 glowstone
fill ~111 ~8 ~43 ~111 ~8 ~45 concrete 6
setblock ~111 ~8 ~46 glowstone
fill ~111 ~8 ~47 ~111 ~8 ~49 concrete 6
setblock ~111 ~8 ~50 glowstone
setblock ~111 ~8 ~52 glowstone
setblock ~111 ~8 ~55 concrete 6
setblock ~112 ~8 ~47 glowstone
setblock ~34 ~9 ~39 glowstone
setblock ~34 ~9 ~40 concrete 6
setblock ~34 ~9 ~41 glowstone
setblock ~34 ~9 ~42 concrete 6
setblock ~34 ~9 ~43 glowstone
setblock ~34 ~9 ~44 planks 2
setblock ~34 ~9 ~45 glowstone
fill ~34 ~9 ~46 ~36 ~9 ~46 concrete 6
setblock ~35 ~9 ~37 planks 2
fill ~35 ~9 ~38 ~35 ~10 ~38 glowstone
setblock ~35 ~9 ~45 planks 2
setblock ~35 ~9 ~47 planks 2
fill ~35 ~9 ~48 ~37 ~9 ~48 concrete 6
setblock ~35 ~9 ~49 planks 2
setblock ~35 ~9 ~50 concrete 6
setblock ~35 ~9 ~51 planks 2
fill ~35 ~9 ~52 ~37 ~9 ~52 concrete 6
fill ~35 ~9 ~53 ~35 ~9 ~52 concrete 6
setblock ~35 ~9 ~54 glowstone
setblock ~35 ~9 ~55 planks 2
setblock ~35 ~9 ~56 glowstone
setblock ~35 ~9 ~57 concrete 6
setblock ~35 ~9 ~58 glowstone
setblock ~35 ~9 ~59 concrete 6
setblock ~35 ~9 ~60 glowstone
fill ~36 ~9 ~36 ~38 ~9 ~36 concrete 6
setblock ~36 ~9 ~47 glowstone
setblock ~36 ~9 ~49 glowstone
setblock ~36 ~9 ~50 planks 2
setblock ~36 ~9 ~51 glowstone
setblock ~36 ~9 ~53 glowstone
fill ~36 ~9 ~54 ~37 ~9 ~54 concrete 6
setblock ~36 ~9 ~55 glowstone
fill ~36 ~9 ~56 ~37 ~9 ~56 concrete 6
setblock ~36 ~9 ~57 glowstone
fill ~36 ~9 ~58 ~37 ~9 ~58 concrete 6
setblock ~36 ~9 ~59 glowstone
fill ~36 ~9 ~60 ~37 ~9 ~60 concrete 6
setblock ~36 ~9 ~61 glowstone
fill ~36 ~9 ~62 ~37 ~9 ~62 concrete 6
setblock ~36 ~9 ~63 glowstone
fill ~36 ~9 ~64 ~37 ~9 ~64 concrete 6
setblock ~37 ~9 ~47 planks 2
setblock ~37 ~9 ~49 stained_hardened_clay
setblock ~37 ~9 ~50 concrete 6
setblock ~37 ~9 ~51 stained_hardened_clay
setblock ~37 ~9 ~53 stained_hardened_clay
setblock ~37 ~9 ~55 stained_hardened_clay
setblock ~37 ~9 ~57 wool 6
setblock ~37 ~9 ~59 stained_hardened_clay
setblock ~37 ~9 ~61 wool 6
setblock ~37 ~9 ~63 stained_hardened_clay
setblock ~37 ~9 ~65 stained_hardened_clay
setblock ~37 ~9 ~66 concrete 6
setblock ~38 ~9 ~47 glowstone
setblock ~38 ~9 ~48 planks 2
setblock ~38 ~9 ~49 concrete 6
setblock ~38 ~9 ~50 planks 2
setblock ~38 ~9 ~51 glowstone
setblock ~38 ~9 ~52 stained_hardened_clay
setblock ~38 ~9 ~53 concrete 6
setblock ~38 ~9 ~54 planks 2
setblock ~38 ~9 ~55 glowstone
setblock ~38 ~9 ~56 stained_hardened_clay
setblock ~38 ~9 ~57 glowstone
setblock ~38 ~9 ~58 planks 2
setblock ~38 ~9 ~59 concrete 6
setblock ~38 ~9 ~60 stained_hardened_clay
setblock ~38 ~9 ~61 glowstone
setblock ~38 ~9 ~62 planks 2
setblock ~38 ~9 ~63 glowstone
setblock ~38 ~9 ~64 stained_hardened_clay
setblock ~38 ~9 ~65 glowstone
setblock ~38 ~9 ~66 stained_hardened_clay
setblock ~38 ~9 ~67 concrete 6
fill ~39 ~9 ~36 ~39 ~10 ~36 glowstone
setblock ~39 ~9 ~47 planks 2
fill ~39 ~9 ~48 ~41 ~9 ~48 concrete 6
setblock ~39 ~9 ~49 stained_hardened_clay
setblock ~39 ~9 ~50 concrete 6
setblock ~39 ~9 ~51 stained_hardened_clay
fill ~39 ~9 ~52 ~42 ~9 ~52 concrete 6
setblock ~39 ~9 ~53 stained_hardened_clay
setblock ~39 ~9 ~54 concrete 6
setblock ~39 ~9 ~55 wool 6
fill ~39 ~9 ~56 ~41 ~9 ~56 concrete 6
setblock ~39 ~9 ~57 stained_hardened_clay
setblock ~39 ~9 ~58 concrete 6
setblock ~39 ~9 ~59 stained_hardened_clay
setblock ~39 ~9 ~60 concrete 6
setblock ~39 ~9 ~61 wool 6
setblock ~39 ~9 ~62 concrete 6
setblock ~39 ~9 ~63 stained_hardened_clay
setblock ~39 ~9 ~64 concrete 6
setblock ~39 ~9 ~65 wool 6
setblock ~39 ~9 ~66 concrete 6
setblock ~39 ~9 ~67 stained_hardened_clay
setblock ~39 ~9 ~68 concrete 6
setblock ~40 ~9 ~36 concrete 6
setblock ~40 ~9 ~47 glowstone
setblock ~40 ~9 ~49 glowstone
setblock ~40 ~9 ~50 planks 2
setblock ~40 ~9 ~51 glowstone
setblock ~40 ~9 ~53 glowstone
setblock ~40 ~9 ~54 planks 2
setblock ~40 ~9 ~55 concrete 6
setblock ~40 ~9 ~57 glowstone
setblock ~40 ~9 ~58 stained_hardened_clay
setblock ~40 ~9 ~59 glowstone
setblock ~40 ~9 ~60 planks 2
setblock ~40 ~9 ~61 concrete 6
setblock ~40 ~9 ~62 stained_hardened_clay
setblock ~40 ~9 ~63 glowstone
setblock ~40 ~9 ~64 stained_hardened_clay
setblock ~40 ~9 ~65 concrete 6
setblock ~40 ~9 ~66 wool 6
setblock ~40 ~9 ~67 concrete 6
setblock ~40 ~9 ~68 stained_hardened_clay
setblock ~41 ~9 ~37 concrete 6
fill ~41 ~9 ~38 ~41 ~10 ~38 glowstone
setblock ~41 ~9 ~45 planks 2
setblock ~41 ~9 ~46 glowstone
setblock ~41 ~9 ~47 planks 2
setblock ~41 ~9 ~49 stained_hardened_clay
fill ~41 ~9 ~50 ~42 ~9 ~50 concrete 6
setblock ~41 ~9 ~51 stained_hardened_clay
setblock ~41 ~9 ~53 wool 6
fill ~41 ~9 ~54 ~42 ~9 ~54 concrete 6
setblock ~41 ~9 ~55 stained_hardened_clay
setblock ~41 ~9 ~57 wool 6
setblock ~41 ~9 ~58 concrete 6
setblock ~41 ~9 ~62 concrete 6
setblock ~41 ~9 ~63 stained_hardened_clay
setblock ~41 ~9 ~64 concrete 6
setblock ~41 ~9 ~65 stained_hardened_clay
setblock ~41 ~9 ~66 concrete 6
setblock ~41 ~9 ~67 stained_hardened_clay
setblock ~41 ~9 ~68 planks 2
setblock ~42 ~9 ~40 concrete 6
setblock ~42 ~9 ~41 stone 2
setblock ~42 ~9 ~42 concrete 6
setblock ~42 ~9 ~43 glowstone
setblock ~42 ~9 ~44 concrete 6
setblock ~42 ~9 ~49 glowstone
setblock ~42 ~9 ~51 glowstone
setblock ~42 ~9 ~53 glowstone
setblock ~42 ~9 ~55 glowstone
setblock ~42 ~9 ~56 planks 2
setblock ~42 ~9 ~57 concrete 6
setblock ~42 ~9 ~62 planks 2
setblock ~42 ~9 ~63 glowstone
setblock ~42 ~9 ~64 stained_hardened_clay
setblock ~42 ~9 ~65 concrete 6
setblock ~42 ~9 ~66 stained_hardened_clay
setblock ~42 ~9 ~67 glowstone
setblock ~42 ~9 ~68 stained_hardened_clay
setblock ~43 ~9 ~53 concrete 6
setblock ~43 ~9 ~54 glowstone
setblock ~43 ~9 ~55 planks 2
fill ~43 ~9 ~56 ~44 ~9 ~56 glowstone
setblock ~43 ~9 ~57 planks 2
fill ~43 ~9 ~58 ~44 ~9 ~58 concrete 6
fill ~43 ~9 ~60 ~44 ~9 ~60 concrete 6
setblock ~43 ~9 ~61 stained_hardened_clay
setblock ~43 ~9 ~62 concrete 6
setblock ~43 ~9 ~63 stained_hardened_clay
setblock ~43 ~9 ~64 concrete 6
setblock ~43 ~9 ~65 stained_hardened_clay
setblock ~43 ~9 ~66 concrete 6
setblock ~43 ~9 ~67 stained_hardened_clay
setblock ~43 ~9 ~68 concrete 6
setblock ~44 ~9 ~55 stone 2
setblock ~44 ~9 ~57 stone 2
setblock ~44 ~9 ~59 glowstone
setblock ~44 ~9 ~61 glowstone
setblock ~44 ~9 ~62 planks 2
setblock ~44 ~9 ~63 concrete 6
setblock ~44 ~9 ~64 planks 2
setblock ~44 ~9 ~65 glowstone
setblock ~44 ~9 ~66 stained_hardened_clay
setblock ~44 ~9 ~67 glowstone
setblock ~45 ~9 ~59 concrete 6
setblock ~45 ~9 ~60 glowstone
setblock ~45 ~9 ~61 planks 2
setblock ~45 ~9 ~62 concrete 6
setblock ~45 ~9 ~63 planks 2
setblock ~45 ~9 ~64 concrete 6
setblock ~45 ~9 ~65 wool 6
setblock ~45 ~9 ~66 concrete 6
setblock ~99 ~9 ~59 concrete 6
setblock ~99 ~9 ~60 glowstone
setblock ~99 ~9 ~61 planks 2
setblock ~99 ~9 ~62 concrete 6
setblock ~99 ~9 ~63 planks 2
setblock ~99 ~9 ~64 concrete 6
setblock ~99 ~9 ~65 wool 6
setblock ~99 ~9 ~66 concrete 6
setblock ~100 ~9 ~55 stone 2
fill ~100 ~9 ~56 ~101 ~9 ~56 glowstone
setblock ~100 ~9 ~57 stone 2
fill ~100 ~9 ~58 ~101 ~9 ~58 concrete 6
setblock ~100 ~9 ~59 glowstone
fill ~100 ~9 ~60 ~101 ~9 ~60 concrete 6
setblock ~100 ~9 ~61 glowstone
setblock ~100 ~9 ~62 planks 2
setblock ~100 ~9 ~63 concrete 6
setblock ~100 ~9 ~64 planks 2
setblock ~100 ~9 ~65 glowstone
setblock ~100 ~9 ~66 stained_hardened_clay
setblock ~100 ~9 ~67 glowstone
setblock ~101 ~9 ~53 concrete 6
setblock ~101 ~9 ~54 glowstone
setblock ~101 ~9 ~55 planks 2
setblock ~101 ~9 ~57 planks 2
setblock ~101 ~9 ~61 stained_hardened_clay
setblock ~101 ~9 ~62 concrete 6
setblock ~101 ~9 ~63 stained_hardened_clay
setblock ~101 ~9 ~64 concrete 6
setblock ~101 ~9 ~65 stained_hardened_clay
setblock ~101 ~9 ~66 concrete 6
setblock ~101 ~9 ~67 stained_hardened_clay
setblock ~101 ~9 ~68 concrete 6
setblock ~102 ~9 ~40 concrete 6
setblock ~102 ~9 ~41 stone 2
setblock ~102 ~9 ~42 concrete 6
setblock ~102 ~9 ~43 glowstone
setblock ~102 ~9 ~44 concrete 6
setblock ~102 ~9 ~49 glowstone
fill ~102 ~9 ~50 ~103 ~9 ~50 concrete 6
setblock ~102 ~9 ~51 glowstone
fill ~102 ~9 ~52 ~105 ~9 ~52 concrete 6
setblock ~102 ~9 ~53 glowstone
fill ~102 ~9 ~54 ~103 ~9 ~54 concrete 6
setblock ~102 ~9 ~55 glowstone
setblock ~102 ~9 ~56 planks 2
setblock ~102 ~9 ~57 concrete 6
setblock ~102 ~9 ~62 planks 2
setblock ~102 ~9 ~63 glowstone
setblock ~102 ~9 ~64 stained_hardened_clay
setblock ~102 ~9 ~65 concrete 6
setblock ~102 ~9 ~66 stained_hardened_clay
setblock ~102 ~9 ~67 glowstone
setblock ~102 ~9 ~68 stained_hardened_clay
setblock ~103 ~9 ~37 concrete 6
fill ~103 ~9 ~38 ~103 ~10 ~38 glowstone
setblock ~103 ~9 ~45 planks 2
setblock ~103 ~9 ~46 glowstone
setblock ~103 ~9 ~47 planks 2
fill ~103 ~9 ~48 ~105 ~9 ~48 concrete 6
setblock ~103 ~9 ~49 stained_hardened_clay
setblock ~103 ~9 ~51 stained_hardened_clay
setblock ~103 ~9 ~53 wool 6
setblock ~103 ~9 ~55 stained_hardened_clay
fill ~103 ~9 ~56 ~105 ~9 ~56 concrete 6
setblock ~103 ~9 ~57 wool 6
setblock ~103 ~9 ~58 concrete 6
setblock ~103 ~9 ~62 concrete 6
setblock ~103 ~9 ~63 stained_hardened_clay
setblock ~103 ~9 ~64 concrete 6
setblock ~103 ~9 ~65 stained_hardened_clay
setblock ~103 ~9 ~66 concrete 6
setblock ~103 ~9 ~67 stained_hardened_clay
setblock ~103 ~9 ~68 planks 2
setblock ~104 ~9 ~36 concrete 6
setblock ~104 ~9 ~47 glowstone
setblock ~104 ~9 ~49 glowstone
setblock ~104 ~9 ~50 planks 2
setblock ~104 ~9 ~51 glowstone
setblock ~104 ~9 ~53 glowstone
setblock ~104 ~9 ~54 planks 2
setblock ~104 ~9 ~55 concrete 6
setblock ~104 ~9 ~57 glowstone
setblock ~104 ~9 ~58 stained_hardened_clay
setblock ~104 ~9 ~59 glowstone
setblock ~104 ~9 ~60 planks 2
setblock ~104 ~9 ~61 concrete 6
setblock ~104 ~9 ~62 stained_hardened_clay
setblock ~104 ~9 ~63 glowstone
setblock ~104 ~9 ~64 stained_hardened_clay
setblock ~104 ~9 ~65 concrete 6
setblock ~104 ~9 ~66 wool 6
setblock ~104 ~9 ~67 concrete 6
setblock ~104 ~9 ~68 stained_hardened_clay
fill ~105 ~9 ~36 ~105 ~10 ~36 glowstone
setblock ~105 ~9 ~47 planks 2
setblock ~105 ~9 ~49 stained_hardened_clay
setblock ~105 ~9 ~50 concrete 6
setblock ~105 ~9 ~51 stained_hardened_clay
setblock ~105 ~9 ~53 stained_hardened_clay
setblock ~105 ~9 ~54 concrete 6
setblock ~105 ~9 ~55 wool 6
setblock ~105 ~9 ~57 stained_hardened_clay
setblock ~105 ~9 ~58 concrete 6
setblock ~105 ~9 ~59 stained_hardened_clay
setblock ~105 ~9 ~60 concrete 6
setblock ~105 ~9 ~61 wool 6
setblock ~105 ~9 ~62 concrete 6
setblock ~105 ~9 ~63 stained_hardened_clay
setblock ~105 ~9 ~64 concrete 6
setblock ~105 ~9 ~65 wool 6
setblock ~105 ~9 ~66 concrete 6
setblock ~105 ~9 ~67 stained_hardened_clay
setblock ~105 ~9 ~68 concrete 6
fill ~106 ~9 ~36 ~108 ~9 ~36 concrete 6
setblock ~106 ~9 ~47 glowstone
setblock ~106 ~9 ~48 planks 2
setblock ~106 ~9 ~49 concrete 6
setblock ~106 ~9 ~50 planks 2
setblock ~106 ~9 ~51 glowstone
setblock ~106 ~9 ~52 stained_hardened_clay
setblock ~106 ~9 ~53 concrete 6
setblock ~106 ~9 ~54 planks 2
setblock ~106 ~9 ~55 glowstone
setblock ~106 ~9 ~56 stained_hardened_clay
setblock ~106 ~9 ~57 glowstone
setblock ~106 ~9 ~58 planks 2
setblock ~106 ~9 ~59 concrete 6
setblock ~106 ~9 ~60 stained_hardened_clay
setblock ~106 ~9 ~61 glowstone
setblock ~106 ~9 ~62 planks 2
setblock ~106 ~9 ~63 glowstone
setblock ~106 ~9 ~64 stained_hardened_clay
setblock ~106 ~9 ~65 glowstone
setblock ~106 ~9 ~66 stained_hardened_clay
setblock ~106 ~9 ~67 concrete 6
setblock ~107 ~9 ~47 planks 2
fill ~107 ~9 ~48 ~109 ~9 ~48 concrete 6
setblock ~107 ~9 ~49 stained_hardened_clay
setblock ~107 ~9 ~50 concrete 6
setblock ~107 ~9 ~51 stained_hardened_clay
fill ~107 ~9 ~52 ~109 ~9 ~52 concrete 6
setblock ~107 ~9 ~53 stained_hardened_clay
fill ~107 ~9 ~54 ~108 ~9 ~54 concrete 6
setblock ~107 ~9 ~55 stained_hardened_clay
fill ~107 ~9 ~56 ~108 ~9 ~56 concrete 6
setblock ~107 ~9 ~57 wool 6
fill ~107 ~9 ~58 ~108 ~9 ~58 concrete 6
setblock ~107 ~9 ~59 stained_hardened_clay
fill ~107 ~9 ~60 ~108 ~9 ~60 concrete 6
setblock ~107 ~9 ~61 wool 6
fill ~107 ~9 ~62 ~108 ~9 ~62 concrete 6
setblock ~107 ~9 ~63 stained_hardened_clay
fill ~107 ~9 ~64 ~108 ~9 ~64 concrete 6
setblock ~107 ~9 ~65 stained_hardened_clay
setblock ~107 ~9 ~66 concrete 6
fill ~108 ~9 ~46 ~110 ~9 ~46 concrete 6
setblock ~108 ~9 ~47 glowstone
setblock ~108 ~9 ~49 glowstone
setblock ~108 ~9 ~50 planks 2
setblock ~108 ~9 ~51 glowstone
setblock ~108 ~9 ~53 glowstone
setblock ~108 ~9 ~55 glowstone
setblock ~108 ~9 ~57 glowstone
setblock ~108 ~9 ~59 glowstone
setblock ~108 ~9 ~61 glowstone
setblock ~108 ~9 ~63 glowstone
setblock ~109 ~9 ~37 planks 2
fill ~109 ~9 ~38 ~109 ~11 ~38 glowstone
setblock ~109 ~9 ~45 planks 2
setblock ~109 ~9 ~47 planks 2
setblock ~109 ~9 ~49 planks 2
setblock ~109 ~9 ~50 concrete 6
setblock ~109 ~9 ~51 planks 2
setblock ~109 ~9 ~53 concrete 6
setblock ~109 ~9 ~54 glowstone
setblock ~109 ~9 ~55 planks 2
setblock ~109 ~9 ~56 glowstone
setblock ~109 ~9 ~57 concrete 6
setblock ~109 ~9 ~58 glowstone
setblock ~109 ~9 ~59 concrete 6
setblock ~109 ~9 ~60 glowstone
setblock ~110 ~9 ~39 glowstone
setblock ~110 ~9 ~40 concrete 6
setblock ~110 ~9 ~41 glowstone
setblock ~110 ~9 ~42 concrete 6
setblock ~110 ~9 ~43 glowstone
setblock ~110 ~9 ~44 planks 2
setblock ~110 ~9 ~45 glowstone
setblock ~35 ~10 ~39 concrete 6
fill ~35 ~10 ~40 ~35 ~11 ~40 glowstone
setblock ~35 ~10 ~41 concrete 6
setblock ~35 ~10 ~42 glowstone
setblock ~35 ~10 ~43 concrete 6
setblock ~35 ~10 ~44 glowstone
fill ~36 ~10 ~37 ~36 ~11 ~37 glowstone
setblock ~36 ~10 ~44 stone 2
fill ~36 ~10 ~45 ~36 ~11 ~45 glowstone
fill ~37 ~10 ~36 ~39 ~10 ~36 glowstone
setblock ~37 ~10 ~37 yellow_glazed_terracotta
fill ~37 ~10 ~38 ~41 ~10 ~38 glowstone
fill ~37 ~10 ~39 ~39 ~10 ~39 yellow_glazed_terracotta
fill ~37 ~10 ~40 ~41 ~10 ~40 glowstone
fill ~37 ~10 ~41 ~40 ~10 ~41 yellow_glazed_terracotta
fill ~37 ~10 ~42 ~41 ~10 ~42 glowstone
setblock ~37 ~10 ~45 concrete 6
setblock ~37 ~10 ~46 glowstone
fill ~38 ~10 ~37 ~38 ~11 ~37 glowstone
fill ~38 ~10 ~43 ~40 ~10 ~43 yellow_glazed_terracotta
fill ~38 ~10 ~45 ~38 ~11 ~45 glowstone
setblock ~38 ~10 ~46 stone 2
setblock ~39 ~10 ~37 yellow_glazed_terracotta
fill ~39 ~10 ~44 ~39 ~11 ~44 glowstone
setblock ~39 ~10 ~45 concrete 6
setblock ~39 ~10 ~46 glowstone
setblock ~40 ~10 ~37 glowstone
setblock ~40 ~10 ~39 glowstone
setblock ~40 ~10 ~44 stone 2
fill ~40 ~10 ~45 ~40 ~11 ~45 glowstone
setblock ~40 ~10 ~46 stone 2
setblock ~41 ~10 ~39 planks 2
setblock ~41 ~10 ~41 planks 2
setblock ~41 ~10 ~43 concrete 6
setblock ~41 ~10 ~44 glowstone
fill ~41 ~10 ~59 ~43 ~10 ~59 concrete 6
fill ~41 ~10 ~60 ~41 ~10 ~59 concrete 6
setblock ~41 ~10 ~61 planks 2
setblock ~42 ~10 ~58 glowstone
setblock ~42 ~10 ~60 glowstone
setblock ~42 ~10 ~61 concrete 6
fill ~101 ~10 ~59 ~103 ~10 ~59 concrete 6
setblock ~102 ~10 ~58 glowstone
setblock ~102 ~10 ~60 glowstone
setblock ~102 ~10 ~61 concrete 6
setblock ~103 ~10 ~39 planks 2
fill ~103 ~10 ~40 ~103 ~11 ~40 glowstone
setblock ~103 ~10 ~41 planks 2
setblock ~103 ~10 ~42 glowstone
setblock ~103 ~10 ~43 concrete 6
fill ~103 ~10 ~44 ~103 ~11 ~44 glowstone
setblock ~103 ~10 ~60 concrete 6
setblock ~103 ~10 ~61 planks 2
fill ~104 ~10 ~37 ~104 ~10 ~39 glowstone
fill ~104 ~10 ~40 ~106 ~10 ~40 stained_hardened_clay 4
fill ~104 ~10 ~41 ~105 ~10 ~41 yellow_glazed_terracotta
setblock ~104 ~10 ~42 stained_hardened_clay 4
fill ~104 ~10 ~43 ~104 ~11 ~43 glowstone
setblock ~104 ~10 ~44 stone 2
setblock ~104 ~10 ~45 glowstone
setblock ~104 ~10 ~46 stone 2
setblock ~105 ~10 ~37 yellow_glazed_terracotta
setblock ~105 ~10 ~38 glowstone
setblock ~105 ~10 ~39 yellow_glazed_terracotta
setblock ~105 ~10 ~42 glowstone
setblock ~105 ~10 ~43 yellow_glazed_terracotta
fill ~105 ~10 ~44 ~105 ~11 ~44 glowstone
setblock ~105 ~10 ~45 concrete 6
setblock ~105 ~10 ~46 glowstone
fill ~106 ~10 ~36 ~107 ~10 ~36 glowstone
fill ~106 ~10 ~37 ~106 ~11 ~37 glowstone
setblock ~106 ~10 ~38 stained_hardened_clay 4
setblock ~106 ~10 ~39 glowstone
setblock ~106 ~10 ~41 glowstone
fill ~106 ~10 ~42 ~106 ~10 ~43 stained_hardened_clay 4
setblock ~106 ~10 ~45 glowstone
setblock ~106 ~10 ~46 stone 2
setblock ~107 ~10 ~37 yellow_glazed_terracotta
setblock ~107 ~10 ~38 glowstone
setblock ~107 ~10 ~39 yellow_glazed_terracotta
setblock ~107 ~10 ~40 glowstone
setblock ~107 ~10 ~41 yellow_glazed_terracotta
setblock ~107 ~10 ~42 glowstone
setblock ~107 ~10 ~45 concrete 6
fill ~107 ~10 ~46 ~107 ~11 ~46 glowstone
setblock ~108 ~10 ~37 glowstone
setblock ~108 ~10 ~44 stone 2
setblock ~108 ~10 ~45 glowstone
setblock ~109 ~10 ~39 concrete 6
fill ~109 ~10 ~40 ~109 ~11 ~40 glowstone
setblock ~109 ~10 ~41 concrete 6
setblock ~109 ~10 ~42 glowstone
setblock ~109 ~10 ~43 concrete 6
setblock ~109 ~10 ~44 glowstone
fill ~35 ~11 ~37 ~35 ~11 ~39 yellow_glazed_terracotta
fill ~35 ~11 ~41 ~35 ~11 ~43 yellow_glazed_terracotta
fill ~36 ~11 ~34 ~41 ~11 ~34 yellow_glazed_terracotta
setblock ~36 ~11 ~35 glowstone
fill ~36 ~11 ~36 ~37 ~11 ~36 yellow_glazed_terracotta
setblock ~36 ~11 ~38 concrete 6
setblock ~36 ~11 ~39 glowstone
setblock ~36 ~11 ~40 yellow_glazed_terracotta
setblock ~36 ~11 ~41 glowstone
setblock ~36 ~11 ~42 concrete 6
setblock ~36 ~11 ~43 glowstone
setblock ~36 ~11 ~44 yellow_glazed_terracotta
setblock ~37 ~11 ~33 yellow_glazed_terracotta
setblock ~37 ~11 ~35 yellow_glazed_terracotta
setblock ~37 ~11 ~37 concrete 6
setblock ~37 ~11 ~43 planks 2
setblock ~37 ~11 ~44 glowstone
fill ~37 ~11 ~45 ~37 ~11 ~46 yellow_glazed_terracotta
setblock ~38 ~11 ~33 glowstone
setblock ~38 ~11 ~35 glowstone
setblock ~38 ~11 ~43 glowstone
setblock ~38 ~11 ~44 planks 2
fill ~38 ~11 ~46 ~41 ~11 ~46 yellow_glazed_terracotta
setblock ~39 ~11 ~33 yellow_glazed_terracotta
setblock ~39 ~11 ~35 yellow_glazed_terracotta
setblock ~39 ~11 ~37 concrete 6
setblock ~39 ~11 ~43 planks 2
setblock ~39 ~11 ~45 yellow_glazed_terracotta
setblock ~39 ~11 ~47 yellow_glazed_terracotta
setblock ~40 ~11 ~33 glowstone
setblock ~40 ~11 ~35 glowstone
fill ~40 ~11 ~36 ~42 ~11 ~36 yellow_glazed_terracotta
setblock ~40 ~11 ~38 concrete 6
setblock ~40 ~11 ~39 stone 2
setblock ~40 ~11 ~41 stone 2
setblock ~40 ~11 ~42 concrete 6
setblock ~40 ~11 ~43 glowstone
fill ~40 ~11 ~44 ~43 ~11 ~44 yellow_glazed_terracotta
setblock ~40 ~11 ~47 glowstone
setblock ~41 ~11 ~35 yellow_glazed_terracotta
setblock ~41 ~11 ~37 yellow_glazed_terracotta
setblock ~41 ~11 ~40 glowstone
setblock ~41 ~11 ~41 concrete 6
setblock ~41 ~11 ~43 yellow_glazed_terracotta
setblock ~41 ~11 ~45 yellow_glazed_terracotta
setblock ~42 ~11 ~37 glowstone
setblock ~42 ~11 ~38 yellow_glazed_terracotta
setblock ~42 ~11 ~39 glowstone
fill ~42 ~11 ~40 ~43 ~11 ~40 yellow_glazed_terracotta
setblock ~42 ~11 ~41 glowstone
fill ~42 ~11 ~42 ~43 ~11 ~42 yellow_glazed_terracotta
setblock ~42 ~11 ~43 glowstone
setblock ~42 ~11 ~45 glowstone
setblock ~43 ~11 ~39 yellow_glazed_terracotta
setblock ~43 ~11 ~41 yellow_glazed_terracotta
setblock ~43 ~11 ~43 yellow_glazed_terracotta
fill ~101 ~11 ~39 ~101 ~11 ~43 yellow_glazed_terracotta
setblock ~101 ~11 ~44 glowstone
fill ~102 ~11 ~36 ~104 ~11 ~36 yellow_glazed_terracotta
setblock ~102 ~11 ~37 glowstone
setblock ~102 ~11 ~38 yellow_glazed_terracotta
setblock ~102 ~11 ~39 glowstone
setblock ~102 ~11 ~40 yellow_glazed_terracotta
setblock ~102 ~11 ~41 glowstone
setblock ~102 ~11 ~42 yellow_glazed_terracotta
setblock ~102 ~11 ~43 glowstone
setblock ~102 ~11 ~44 yellow_glazed_terracotta
setblock ~102 ~11 ~45 glowstone
fill ~103 ~11 ~34 ~108 ~11 ~34 yellow_glazed_terracotta
fill ~103 ~11 ~35 ~103 ~11 ~34 yellow_glazed_terracotta
setblock ~103 ~11 ~37 yellow_glazed_terracotta
setblock ~103 ~11 ~41 concrete 6
setblock ~103 ~11 ~43 yellow_glazed_terracotta
fill ~103 ~11 ~45 ~103 ~11 ~46 yellow_glazed_terracotta
setblock ~104 ~11 ~33 glowstone
setblock ~104 ~11 ~35 glowstone
setblock ~104 ~11 ~38 concrete 6
setblock ~104 ~11 ~39 stone 2
setblock ~104 ~11 ~41 stone 2
setblock ~104 ~11 ~42 concrete 6
setblock ~104 ~11 ~44 yellow_glazed_terracotta
setblock ~104 ~11 ~45 stained_hardened_clay 4
fill ~104 ~11 ~46 ~106 ~11 ~46 yellow_glazed_terracotta
setblock ~104 ~11 ~47 stained_hardened_clay 4
setblock ~105 ~11 ~33 yellow_glazed_terracotta
setblock ~105 ~11 ~35 yellow_glazed_terracotta
setblock ~105 ~11 ~37 concrete 6
setblock ~105 ~11 ~43 planks 2
setblock ~105 ~11 ~45 yellow_glazed_terracotta
setblock ~105 ~11 ~47 yellow_glazed_terracotta
setblock ~106 ~11 ~33 glowstone
setblock ~106 ~11 ~35 glowstone
setblock ~106 ~11 ~43 glowstone
setblock ~106 ~11 ~44 planks 2
setblock ~106 ~11 ~45 stained_hardened_clay 4
setblock ~107 ~11 ~33 yellow_glazed_terracotta
fill ~107 ~11 ~35 ~107 ~11 ~36 yellow_glazed_terracotta
setblock ~107 ~11 ~37 concrete 6
setblock ~107 ~11 ~43 planks 2
setblock ~107 ~11 ~44 glowstone
setblock ~107 ~11 ~45 yellow_glazed_terracotta
setblock ~108 ~11 ~35 glowstone
setblock ~108 ~11 ~36 yellow_glazed_terracotta
setblock ~108 ~11 ~37 stained_hardened_clay 4
setblock ~108 ~11 ~38 concrete 6
setblock ~108 ~11 ~39 glowstone
setblock ~108 ~11 ~40 yellow_glazed_terracotta
setblock ~108 ~11 ~41 glowstone
setblock ~108 ~11 ~42 concrete 6
setblock ~108 ~11 ~43 glowstone
setblock ~108 ~11 ~44 yellow_glazed_terracotta
setblock ~108 ~11 ~45 stained_hardened_clay 4
setblock ~109 ~11 ~37 yellow_glazed_terracotta
setblock ~109 ~11 ~39 yellow_glazed_terracotta
setblock ~109 ~11 ~41 yellow_glazed_terracotta
setblock ~109 ~11 ~42 stained_hardened_clay 4
setblock ~109 ~11 ~43 yellow_glazed_terracotta
fill ~34 ~12 ~37 ~34 ~12 ~38 glowstone
setblock ~34 ~12 ~39 yellow_glazed_terracotta
setblock ~34 ~12 ~40 glowstone
setblock ~34 ~12 ~41 yellow_glazed_terracotta
setblock ~34 ~12 ~42 glowstone
setblock ~34 ~12 ~43 yellow_glazed_terracotta
fill ~34 ~12 ~44 ~35 ~12 ~44 glowstone
setblock ~35 ~12 ~33 yellow_glazed_terracotta
setblock ~35 ~12 ~34 glowstone
setblock ~35 ~12 ~35 yellow_glazed_terracotta
setblock ~35 ~12 ~36 glowstone
setblock ~35 ~12 ~45 yellow_glazed_terracotta
setblock ~35 ~12 ~46 glowstone
fill ~36 ~12 ~32 ~36 ~12 ~33 glowstone
setblock ~36 ~12 ~40 stone 2
setblock ~36 ~12 ~46 stained_hardened_clay 4
setblock ~36 ~12 ~47 glowstone
fill ~37 ~12 ~31 ~40 ~12 ~31 yellow_glazed_terracotta
fill ~37 ~12 ~32 ~37 ~12 ~31 yellow_glazed_terracotta
setblock ~37 ~12 ~38 glowstone
setblock ~37 ~12 ~39 concrete 6
setblock ~37 ~12 ~40 glowstone
fill ~37 ~12 ~41 ~39 ~12 ~41 concrete 6
setblock ~37 ~12 ~42 glowstone
fill ~37 ~12 ~47 ~38 ~12 ~47 yellow_glazed_terracotta
fill ~37 ~12 ~48 ~37 ~12 ~47 yellow_glazed_terracotta
setblock ~38 ~12 ~32 glowstone
setblock ~38 ~12 ~38 stone 2
setblock ~38 ~12 ~39 glowstone
setblock ~38 ~12 ~40 stone 2
setblock ~38 ~12 ~42 stone 2
fill ~38 ~12 ~48 ~42 ~12 ~48 glowstone
fill ~38 ~12 ~49 ~41 ~12 ~49 yellow_glazed_terracotta
setblock ~39 ~12 ~32 yellow_glazed_terracotta
setblock ~39 ~12 ~38 glowstone
setblock ~39 ~12 ~39 concrete 6
setblock ~39 ~12 ~40 glowstone
setblock ~39 ~12 ~42 glowstone
setblock ~40 ~12 ~32 glowstone
setblock ~40 ~12 ~39 glowstone
setblock ~40 ~12 ~40 stone 2
fill ~41 ~12 ~32 ~41 ~12 ~33 yellow_glazed_terracotta
fill ~41 ~12 ~47 ~43 ~12 ~47 yellow_glazed_terracotta
setblock ~42 ~12 ~33 yellow_glazed_terracotta
setblock ~42 ~12 ~34 glowstone
fill ~42 ~12 ~35 ~43 ~12 ~35 yellow_glazed_terracotta
fill ~42 ~12 ~46 ~44 ~12 ~46 glowstone
fill ~43 ~12 ~36 ~43 ~12 ~37 yellow_glazed_terracotta
fill ~43 ~12 ~38 ~44 ~12 ~38 glowstone
fill ~43 ~12 ~45 ~44 ~12 ~45 yellow_glazed_terracotta
setblock ~44 ~12 ~39 yellow_glazed_terracotta
setblock ~44 ~12 ~40 stained_hardened_clay 4
setblock ~44 ~12 ~41 yellow_glazed_terracotta
setblock ~44 ~12 ~42 glowstone
setblock ~44 ~12 ~43 yellow_glazed_terracotta
setblock ~44 ~12 ~44 glowstone
fill ~100 ~12 ~38 ~101 ~12 ~38 glowstone
setblock ~100 ~12 ~39 yellow_glazed_terracotta
setblock ~100 ~12 ~40 stained_hardened_clay 4
setblock ~100 ~12 ~41 glowstone
setblock ~100 ~12 ~42 stained_hardened_clay 4
fill ~100 ~12 ~43 ~100 ~12 ~45 glowstone
setblock ~100 ~12 ~46 stained_hardened_clay 4
fill ~101 ~12 ~35 ~102 ~12 ~35 yellow_glazed_terracotta
fill ~101 ~12 ~36 ~101 ~12 ~37 yellow_glazed_terracotta
setblock ~101 ~12 ~45 yellow_glazed_terracotta
setblock ~101 ~12 ~46 glowstone
setblock ~101 ~12 ~47 yellow_glazed_terracotta
fill ~102 ~12 ~33 ~103 ~12 ~33 yellow_glazed_terracotta
setblock ~102 ~12 ~34 glowstone
setblock ~102 ~12 ~46 stained_hardened_clay 4
fill ~102 ~12 ~47 ~102 ~12 ~48 glowstone
setblock ~103 ~12 ~32 yellow_glazed_terracotta
setblock ~103 ~12 ~47 yellow_glazed_terracotta
setblock ~103 ~12 ~48 glowstone
setblock ~103 ~12 ~49 yellow_glazed_terracotta
fill ~104 ~12 ~31 ~107 ~12 ~31 yellow_glazed_terracotta
setblock ~104 ~12 ~32 glowstone
setblock ~104 ~12 ~39 glowstone
setblock ~104 ~12 ~40 stone 2
setblock ~104 ~12 ~48 stained_hardened_clay 4
setblock ~104 ~12 ~49 glowstone
setblock ~105 ~12 ~32 yellow_glazed_terracotta
setblock ~105 ~12 ~38 glowstone
setblock ~105 ~12 ~39 concrete 6
setblock ~105 ~12 ~40 glowstone
fill ~105 ~12 ~41 ~107 ~12 ~41 concrete 6
setblock ~105 ~12 ~42 glowstone
setblock ~105 ~12 ~48 glowstone
setblock ~105 ~12 ~49 yellow_glazed_terracotta
fill ~106 ~12 ~32 ~108 ~12 ~32 glowstone
setblock ~106 ~12 ~38 stone 2
setblock ~106 ~12 ~39 glowstone
setblock ~106 ~12 ~40 stone 2
setblock ~106 ~12 ~42 stone 2
setblock ~106 ~12 ~47 glowstone
setblock ~106 ~12 ~48 stained_hardened_clay 4
setblock ~106 ~12 ~49 glowstone
setblock ~107 ~12 ~38 glowstone
setblock ~107 ~12 ~39 concrete 6
setblock ~107 ~12 ~40 glowstone
setblock ~107 ~12 ~42 glowstone
setblock ~107 ~12 ~47 yellow_glazed_terracotta
setblock ~107 ~12 ~48 glowstone
fill ~108 ~12 ~33 ~109 ~12 ~33 yellow_glazed_terracotta
setblock ~108 ~12 ~40 stone 2
fill ~108 ~12 ~46 ~109 ~12 ~46 stained_hardened_clay 4
fill ~108 ~12 ~47 ~108 ~12 ~46 stained_hardened_clay 4
setblock ~109 ~12 ~34 glowstone
setblock ~109 ~12 ~35 yellow_glazed_terracotta
setblock ~109 ~12 ~36 glowstone
setblock ~109 ~12 ~44 stained_hardened_clay 4
setblock ~109 ~12 ~45 yellow_glazed_terracotta
fill ~110 ~12 ~37 ~110 ~12 ~38 stained_hardened_clay 4
fill ~110 ~12 ~39 ~110 ~12 ~40 glowstone
fill ~110 ~12 ~41 ~110 ~12 ~42 stained_hardened_clay 4
fill ~110 ~12 ~43 ~110 ~12 ~44 glowstone
fill ~33 ~13 ~37 ~33 ~14 ~37 yellow_glazed_terracotta
fill ~33 ~13 ~38 ~33 ~13 ~45 yellow_glazed_terracotta
setblock ~34 ~13 ~33 glowstone
setblock ~34 ~13 ~34 yellow_glazed_terracotta
setblock ~34 ~13 ~35 glowstone
setblock ~34 ~13 ~36 yellow_glazed_terracotta
setblock ~34 ~13 ~45 glowstone
setblock ~34 ~13 ~46 yellow_glazed_terracotta
setblock ~34 ~13 ~47 glowstone
fill ~35 ~13 ~31 ~35 ~13 ~32 yellow_glazed_terracotta
fill ~35 ~13 ~47 ~35 ~13 ~49 yellow_glazed_terracotta
fill ~36 ~13 ~30 ~41 ~13 ~30 yellow_glazed_terracotta
setblock ~36 ~13 ~31 glowstone
setblock ~36 ~13 ~48 yellow_glazed_terracotta
setblock ~36 ~13 ~49 glowstone
fill ~36 ~13 ~50 ~42 ~13 ~50 yellow_glazed_terracotta
setblock ~37 ~13 ~29 yellow_glazed_terracotta
setblock ~37 ~13 ~49 yellow_glazed_terracotta
setblock ~38 ~13 ~29 glowstone
setblock ~39 ~13 ~29 yellow_glazed_terracotta
setblock ~40 ~13 ~29 stained_hardened_clay 4
setblock ~41 ~13 ~31 yellow_glazed_terracotta
setblock ~42 ~13 ~31 glowstone
setblock ~42 ~13 ~32 yellow_glazed_terracotta
setblock ~42 ~13 ~49 glowstone
fill ~43 ~13 ~33 ~43 ~13 ~34 yellow_glazed_terracotta
fill ~43 ~13 ~48 ~44 ~13 ~48 yellow_glazed_terracotta
fill ~43 ~13 ~49 ~43 ~13 ~48 yellow_glazed_terracotta
setblock ~44 ~13 ~35 glowstone
setblock ~44 ~13 ~36 yellow_glazed_terracotta
setblock ~44 ~13 ~37 glowstone
setblock ~44 ~13 ~38 yellow_glazed_terracotta
setblock ~44 ~13 ~47 glowstone
fill ~45 ~13 ~39 ~45 ~14 ~39 yellow_glazed_terracotta
fill ~45 ~13 ~40 ~45 ~13 ~46 yellow_glazed_terracotta
fill ~99 ~13 ~39 ~99 ~14 ~39 yellow_glazed_terracotta
fill ~99 ~13 ~40 ~99 ~13 ~45 yellow_glazed_terracotta
setblock ~99 ~13 ~46 glowstone
setblock ~100 ~13 ~35 glowstone
setblock ~100 ~13 ~36 yellow_glazed_terracotta
setblock ~100 ~13 ~37 glowstone
setblock ~100 ~13 ~38 yellow_glazed_terracotta
setblock ~100 ~13 ~47 glowstone
fill ~100 ~13 ~48 ~101 ~13 ~48 yellow_glazed_terracotta
fill ~101 ~13 ~33 ~101 ~13 ~34 yellow_glazed_terracotta
setblock ~101 ~13 ~49 yellow_glazed_terracotta
fill ~102 ~13 ~31 ~103 ~13 ~31 yellow_glazed_terracotta
fill ~102 ~13 ~32 ~102 ~13 ~31 yellow_glazed_terracotta
setblock ~102 ~13 ~49 glowstone
fill ~102 ~13 ~50 ~108 ~13 ~50 yellow_glazed_terracotta
fill ~103 ~13 ~30 ~108 ~13 ~30 yellow_glazed_terracotta
setblock ~104 ~13 ~29 glowstone
setblock ~105 ~13 ~29 yellow_glazed_terracotta
setblock ~106 ~13 ~29 glowstone
setblock ~107 ~13 ~29 yellow_glazed_terracotta
setblock ~107 ~13 ~49 yellow_glazed_terracotta
setblock ~108 ~13 ~31 glowstone
setblock ~108 ~13 ~48 yellow_glazed_terracotta
setblock ~108 ~13 ~49 stained_hardened_clay 4
fill ~109 ~13 ~31 ~109 ~13 ~32 yellow_glazed_terracotta
setblock ~109 ~13 ~47 yellow_glazed_terracotta
setblock ~109 ~13 ~48 glowstone
setblock ~109 ~13 ~49 yellow_glazed_terracotta
setblock ~110 ~13 ~33 glowstone
setblock ~110 ~13 ~34 yellow_glazed_terracotta
setblock ~110 ~13 ~35 glowstone
setblock ~110 ~13 ~36 yellow_glazed_terracotta
setblock ~110 ~13 ~45 glowstone
setblock ~110 ~13 ~46 yellow_glazed_terracotta
setblock ~110 ~13 ~47 stained_hardened_clay 4
fill ~111 ~13 ~37 ~111 ~14 ~37 yellow_glazed_terracotta
fill ~111 ~13 ~38 ~111 ~13 ~41 yellow_glazed_terracotta
setblock ~111 ~13 ~42 glowstone
fill ~111 ~13 ~43 ~111 ~13 ~45 yellow_glazed_terracotta
fill ~32 ~14 ~38 ~32 ~14 ~40 glowstone
setblock ~32 ~14 ~41 yellow_glazed_terracotta
setblock ~32 ~14 ~42 glowstone
setblock ~32 ~14 ~43 yellow_glazed_terracotta
setblock ~32 ~14 ~44 glowstone
setblock ~32 ~14 ~45 yellow_glazed_terracotta
setblock ~33 ~14 ~34 glowstone
setblock ~33 ~14 ~35 yellow_glazed_terracotta
setblock ~33 ~14 ~36 glowstone
setblock ~33 ~14 ~46 glowstone
fill ~33 ~14 ~47 ~33 ~14 ~48 yellow_glazed_terracotta
setblock ~34 ~14 ~31 yellow_glazed_terracotta
setblock ~34 ~14 ~32 glowstone
setblock ~34 ~14 ~33 yellow_glazed_terracotta
setblock ~34 ~14 ~48 glowstone
setblock ~34 ~14 ~49 yellow_glazed_terracotta
setblock ~35 ~14 ~30 yellow_glazed_terracotta
setblock ~35 ~14 ~50 yellow_glazed_terracotta
setblock ~36 ~14 ~29 yellow_glazed_terracotta
fill ~36 ~14 ~51 ~43 ~14 ~51 yellow_glazed_terracotta
fill ~37 ~14 ~28 ~39 ~14 ~28 glowstone
setblock ~38 ~14 ~27 glowstone
setblock ~38 ~14 ~52 glowstone
setblock ~39 ~14 ~27 yellow_glazed_terracotta
setblock ~39 ~14 ~52 yellow_glazed_terracotta
setblock ~40 ~14 ~27 stained_hardened_clay 4
setblock ~40 ~14 ~28 red_sandstone
fill ~40 ~14 ~52 ~42 ~14 ~52 glowstone
setblock ~41 ~14 ~28 glowstone
fill ~41 ~14 ~29 ~42 ~14 ~29 yellow_glazed_terracotta
fill ~42 ~14 ~30 ~43 ~14 ~30 glowstone
setblock ~43 ~14 ~31 yellow_glazed_terracotta
fill ~43 ~14 ~32 ~44 ~14 ~32 glowstone
setblock ~43 ~14 ~50 yellow_glazed_terracotta
setblock ~44 ~14 ~33 yellow_glazed_terracotta
setblock ~44 ~14 ~34 glowstone
fill ~44 ~14 ~49 ~45 ~14 ~49 yellow_glazed_terracotta
setblock ~44 ~14 ~50 stained_hardened_clay 4
fill ~45 ~14 ~35 ~45 ~15 ~35 yellow_glazed_terracotta
setblock ~45 ~14 ~36 glowstone
setblock ~45 ~14 ~37 yellow_glazed_terracotta
setblock ~45 ~14 ~38 glowstone
setblock ~45 ~14 ~47 yellow_glazed_terracotta
setblock ~45 ~14 ~48 glowstone
fill ~46 ~14 ~40 ~46 ~14 ~41 glowstone
setblock ~46 ~14 ~42 stained_hardened_clay 4
setblock ~46 ~14 ~43 yellow_glazed_terracotta
setblock ~46 ~14 ~44 glowstone
setblock ~46 ~14 ~45 yellow_glazed_terracotta
fill ~46 ~14 ~46 ~46 ~14 ~47 glowstone
setblock ~98 ~14 ~40 glowstone
fill ~98 ~14 ~41 ~98 ~14 ~42 stained_hardened_clay 4
setblock ~98 ~14 ~43 yellow_glazed_terracotta
setblock ~98 ~14 ~44 stained_hardened_clay 4
setblock ~98 ~14 ~45 glowstone
setblock ~98 ~14 ~46 stained_hardened_clay 4
setblock ~98 ~14 ~47 glowstone
fill ~99 ~14 ~35 ~99 ~15 ~35 yellow_glazed_terracotta
fill ~99 ~14 ~36 ~99 ~14 ~37 yellow_glazed_terracotta
setblock ~99 ~14 ~38 glowstone
setblock ~99 ~14 ~47 yellow_glazed_terracotta
setblock ~99 ~14 ~48 glowstone
setblock ~99 ~14 ~49 yellow_glazed_terracotta
fill ~100 ~14 ~32 ~101 ~14 ~32 glowstone
setblock ~100 ~14 ~33 yellow_glazed_terracotta
setblock ~100 ~14 ~34 glowstone
fill ~100 ~14 ~49 ~100 ~14 ~50 glowstone
fill ~101 ~14 ~30 ~101 ~14 ~31 yellow_glazed_terracotta
setblock ~101 ~14 ~50 glowstone
setblock ~101 ~14 ~51 yellow_glazed_terracotta
fill ~102 ~14 ~29 ~103 ~14 ~29 yellow_glazed_terracotta
setblock ~102 ~14 ~30 glowstone
fill ~102 ~14 ~51 ~102 ~14 ~52 glowstone
setblock ~103 ~14 ~28 yellow_glazed_terracotta
setblock ~103 ~14 ~51 yellow_glazed_terracotta
setblock ~103 ~14 ~52 glowstone
fill ~104 ~14 ~27 ~106 ~14 ~27 yellow_glazed_terracotta
setblock ~104 ~14 ~28 glowstone
setblock ~104 ~14 ~51 glowstone
setblock ~104 ~14 ~52 stained_hardened_clay 4
setblock ~105 ~14 ~28 yellow_glazed_terracotta
fill ~105 ~14 ~51 ~108 ~14 ~51 yellow_glazed_terracotta
fill ~105 ~14 ~52 ~106 ~14 ~52 glowstone
setblock ~106 ~14 ~28 glowstone
setblock ~107 ~14 ~28 yellow_glazed_terracotta
setblock ~108 ~14 ~29 yellow_glazed_terracotta
setblock ~109 ~14 ~30 yellow_glazed_terracotta
setblock ~109 ~14 ~50 glowstone
setblock ~110 ~14 ~31 yellow_glazed_terracotta
setblock ~110 ~14 ~32 glowstone
setblock ~110 ~14 ~33 yellow_glazed_terracotta
fill ~110 ~14 ~48 ~110 ~14 ~49 stained_hardened_clay 4
setblock ~111 ~14 ~34 glowstone
setblock ~111 ~14 ~35 yellow_glazed_terracotta
setblock ~111 ~14 ~36 glowstone
fill ~111 ~14 ~46 ~111 ~14 ~48 glowstone
setblock ~112 ~14 ~38 stained_hardened_clay 4
setblock ~112 ~14 ~39 glowstone
setblock ~112 ~14 ~40 stained_hardened_clay 4
setblock ~112 ~14 ~41 glowstone
setblock ~112 ~14 ~42 stained_hardened_clay 4
setblock ~112 ~14 ~43 yellow_glazed_terracotta
setblock ~112 ~14 ~44 stained_hardened_clay 4
setblock ~112 ~14 ~45 yellow_glazed_terracotta
fill ~31 ~15 ~39 ~31 ~16 ~39 yellow_glazed_terracotta
fill ~31 ~15 ~40 ~31 ~16 ~40 yellow_glazed_terracotta
fill ~31 ~15 ~41 ~31 ~16 ~41 yellow_glazed_terracotta
fill ~31 ~15 ~42 ~31 ~15 ~45 yellow_glazed_terracotta
setblock ~32 ~15 ~35 glowstone
setblock ~32 ~15 ~36 yellow_glazed_terracotta
setblock ~32 ~15 ~37 glowstone
setblock ~32 ~15 ~38 yellow_glazed_terracotta
setblock ~32 ~15 ~46 yellow_glazed_terracotta
setblock ~32 ~15 ~47 glowstone
setblock ~32 ~15 ~48 yellow_glazed_terracotta
fill ~33 ~15 ~32 ~33 ~15 ~34 yellow_glazed_terracotta
fill ~33 ~15 ~49 ~33 ~15 ~50 yellow_glazed_terracotta
setblock ~34 ~15 ~30 yellow_glazed_terracotta
setblock ~34 ~15 ~31 glowstone
setblock ~34 ~15 ~50 yellow_glazed_terracotta
setblock ~34 ~15 ~51 glowstone
fill ~35 ~15 ~28 ~36 ~15 ~28 yellow_glazed_terracotta
fill ~35 ~15 ~29 ~35 ~15 ~28 yellow_glazed_terracotta
fill ~35 ~15 ~51 ~35 ~15 ~52 yellow_glazed_terracotta
setblock ~36 ~15 ~27 glowstone
fill ~36 ~15 ~52 ~37 ~15 ~52 yellow_glazed_terracotta
fill ~37 ~15 ~26 ~38 ~15 ~26 yellow_glazed_terracotta
fill ~37 ~15 ~27 ~37 ~15 ~26 yellow_glazed_terracotta
setblock ~37 ~15 ~53 yellow_glazed_terracotta
setblock ~38 ~15 ~53 glowstone
setblock ~39 ~15 ~26 glowstone
setblock ~39 ~15 ~53 yellow_glazed_terracotta
fill ~40 ~15 ~26 ~41 ~15 ~26 yellow_glazed_terracotta
setblock ~40 ~15 ~53 glowstone
setblock ~41 ~15 ~27 yellow_glazed_terracotta
setblock ~41 ~15 ~53 yellow_glazed_terracotta
setblock ~42 ~15 ~27 glowstone
fill ~42 ~15 ~28 ~43 ~15 ~28 yellow_glazed_terracotta
setblock ~42 ~15 ~53 glowstone
setblock ~43 ~15 ~29 yellow_glazed_terracotta
fill ~43 ~15 ~52 ~44 ~15 ~52 yellow_glazed_terracotta
setblock ~44 ~15 ~30 yellow_glazed_terracotta
setblock ~44 ~15 ~31 glowstone
setblock ~44 ~15 ~32 yellow_glazed_terracotta
setblock ~44 ~15 ~51 glowstone
fill ~45 ~15 ~33 ~45 ~15 ~35 yellow_glazed_terracotta
fill ~45 ~15 ~50 ~46 ~15 ~50 yellow_glazed_terracotta
fill ~45 ~15 ~51 ~45 ~15 ~50 yellow_glazed_terracotta
setblock ~46 ~15 ~36 yellow_glazed_terracotta
setblock ~46 ~15 ~37 glowstone
setblock ~46 ~15 ~38 yellow_glazed_terracotta
setblock ~46 ~15 ~39 glowstone
setblock ~46 ~15 ~40 yellow_glazed_terracotta
setblock ~46 ~15 ~41 glowstone
setblock ~46 ~15 ~48 yellow_glazed_terracotta
setblock ~46 ~15 ~49 glowstone
fill ~47 ~15 ~42 ~47 ~15 ~45 yellow_glazed_terracotta
setblock ~47 ~15 ~46 glowstone
fill ~47 ~15 ~47 ~47 ~16 ~47 yellow_glazed_terracotta
fill ~97 ~15 ~42 ~97 ~15 ~45 yellow_glazed_terracotta
fill ~97 ~15 ~46 ~97 ~16 ~46 glowstone
fill ~97 ~15 ~47 ~97 ~16 ~47 yellow_glazed_terracotta
setblock ~98 ~15 ~36 yellow_glazed_terracotta
setblock ~98 ~15 ~37 glowstone
setblock ~98 ~15 ~38 yellow_glazed_terracotta
setblock ~98 ~15 ~39 glowstone
setblock ~98 ~15 ~40 yellow_glazed_terracotta
setblock ~98 ~15 ~41 glowstone
setblock ~98 ~15 ~48 yellow_glazed_terracotta
setblock ~98 ~15 ~49 glowstone
fill ~98 ~15 ~50 ~99 ~15 ~50 yellow_glazed_terracotta
fill ~99 ~15 ~33 ~99 ~15 ~35 yellow_glazed_terracotta
setblock ~99 ~15 ~51 yellow_glazed_terracotta
fill ~100 ~15 ~30 ~100 ~15 ~32 yellow_glazed_terracotta
setblock ~100 ~15 ~51 glowstone
fill ~100 ~15 ~52 ~101 ~15 ~52 yellow_glazed_terracotta
fill ~101 ~15 ~28 ~102 ~15 ~28 yellow_glazed_terracotta
fill ~101 ~15 ~29 ~101 ~15 ~28 yellow_glazed_terracotta
setblock ~102 ~15 ~27 glowstone
setblock ~102 ~15 ~53 glowstone
setblock ~103 ~15 ~26 glowstone
setblock ~103 ~15 ~27 yellow_glazed_terracotta
setblock ~103 ~15 ~53 yellow_glazed_terracotta
fill ~104 ~15 ~26 ~107 ~15 ~26 yellow_glazed_terracotta
setblock ~104 ~15 ~53 glowstone
setblock ~105 ~15 ~53 yellow_glazed_terracotta
setblock ~106 ~15 ~53 glowstone
setblock ~107 ~15 ~27 yellow_glazed_terracotta
fill ~107 ~15 ~52 ~108 ~15 ~52 yellow_glazed_terracotta
fill ~107 ~15 ~53 ~107 ~15 ~52 yellow_glazed_terracotta
setblock ~108 ~15 ~27 glowstone
fill ~108 ~15 ~28 ~109 ~15 ~28 yellow_glazed_terracotta
setblock ~109 ~15 ~29 yellow_glazed_terracotta
setblock ~109 ~15 ~51 yellow_glazed_terracotta
setblock ~109 ~15 ~52 stained_hardened_clay 4
setblock ~110 ~15 ~30 yellow_glazed_terracotta
setblock ~110 ~15 ~31 glowstone
fill ~110 ~15 ~50 ~111 ~15 ~50 yellow_glazed_terracotta
setblock ~110 ~15 ~51 stained_hardened_clay 4
fill ~111 ~15 ~32 ~111 ~15 ~34 yellow_glazed_terracotta
setblock ~111 ~15 ~49 yellow_glazed_terracotta
fill ~112 ~15 ~35 ~112 ~16 ~35 glowstone
setblock ~112 ~15 ~36 yellow_glazed_terracotta
setblock ~112 ~15 ~37 stained_hardened_clay 4
setblock ~112 ~15 ~38 yellow_glazed_terracotta
setblock ~112 ~15 ~46 yellow_glazed_terracotta
setblock ~112 ~15 ~47 stained_hardened_clay 4
setblock ~112 ~15 ~48 yellow_glazed_terracotta
fill ~113 ~15 ~39 ~113 ~16 ~39 yellow_glazed_terracotta
fill ~113 ~15 ~40 ~113 ~15 ~45 yellow_glazed_terracotta
setblock ~30 ~16 ~42 glowstone
setblock ~30 ~16 ~43 yellow_glazed_terracotta
setblock ~30 ~16 ~44 glowstone
setblock ~31 ~16 ~36 glowstone
fill ~31 ~16 ~37 ~31 ~17 ~37 yellow_glazed_terracotta
setblock ~31 ~16 ~38 glowstone
setblock ~31 ~16 ~45 yellow_glazed_terracotta
setblock ~31 ~16 ~46 glowstone
fill ~31 ~16 ~47 ~31 ~16 ~48 yellow_glazed_terracotta
fill ~32 ~16 ~32 ~32 ~16 ~34 glowstone
setblock ~32 ~16 ~35 yellow_glazed_terracotta
setblock ~32 ~16 ~49 yellow_glazed_terracotta
setblock ~32 ~16 ~50 glowstone
setblock ~33 ~16 ~30 glowstone
setblock ~33 ~16 ~31 yellow_glazed_terracotta
setblock ~33 ~16 ~51 yellow_glazed_terracotta
fill ~34 ~16 ~28 ~34 ~16 ~29 glowstone
setblock ~34 ~16 ~52 glowstone
setblock ~35 ~16 ~27 yellow_glazed_terracotta
setblock ~35 ~16 ~53 yellow_glazed_terracotta
setblock ~36 ~16 ~26 stained_hardened_clay 4
setblock ~36 ~16 ~53 glowstone
setblock ~37 ~16 ~25 yellow_glazed_terracotta
fill ~37 ~16 ~54 ~39 ~16 ~54 glowstone
setblock ~38 ~16 ~25 glowstone
setblock ~39 ~16 ~24 glowstone
setblock ~39 ~16 ~25 yellow_glazed_terracotta
setblock ~40 ~16 ~24 stained_hardened_clay 4
setblock ~40 ~16 ~25 glowstone
setblock ~40 ~16 ~54 stained_hardened_clay 4
setblock ~41 ~16 ~25 yellow_glazed_terracotta
setblock ~41 ~16 ~54 glowstone
setblock ~42 ~16 ~25 glowstone
setblock ~42 ~16 ~26 stained_hardened_clay 4
setblock ~42 ~16 ~54 stained_hardened_clay 4
setblock ~43 ~16 ~26 glowstone
setblock ~43 ~16 ~27 yellow_glazed_terracotta
setblock ~43 ~16 ~53 yellow_glazed_terracotta
setblock ~43 ~16 ~54 glowstone
fill ~44 ~16 ~28 ~44 ~16 ~29 stained_hardened_clay 4
setblock ~44 ~16 ~53 glowstone
fill ~45 ~16 ~30 ~45 ~17 ~30 glowstone
setblock ~45 ~16 ~31 yellow_glazed_terracotta
setblock ~45 ~16 ~32 glowstone
setblock ~45 ~16 ~52 glowstone
setblock ~45 ~16 ~53 yellow_glazed_terracotta
setblock ~46 ~16 ~33 glowstone
setblock ~46 ~16 ~34 stained_hardened_clay 4
fill ~46 ~16 ~35 ~46 ~16 ~36 glowstone
setblock ~46 ~16 ~51 glowstone
fill ~47 ~16 ~37 ~47 ~17 ~37 yellow_glazed_terracotta
setblock ~47 ~16 ~38 glowstone
setblock ~47 ~16 ~39 yellow_glazed_terracotta
setblock ~47 ~16 ~40 glowstone
setblock ~47 ~16 ~41 yellow_glazed_terracotta
setblock ~47 ~16 ~42 glowstone
setblock ~47 ~16 ~43 yellow_glazed_terracotta
setblock ~47 ~16 ~44 glowstone
setblock ~47 ~16 ~45 yellow_glazed_terracotta
setblock ~47 ~16 ~46 stained_hardened_clay 4
setblock ~47 ~16 ~48 glowstone
setblock ~47 ~16 ~49 yellow_glazed_terracotta
fill ~47 ~16 ~50 ~47 ~17 ~50 glowstone
fill ~97 ~16 ~37 ~97 ~17 ~37 yellow_glazed_terracotta
fill ~97 ~16 ~38 ~97 ~17 ~38 glowstone
setblock ~97 ~16 ~39 yellow_glazed_terracotta
setblock ~97 ~16 ~40 glowstone
setblock ~97 ~16 ~41 yellow_glazed_terracotta
fill ~97 ~16 ~42 ~97 ~16 ~44 glowstone
setblock ~97 ~16 ~45 yellow_glazed_terracotta
setblock ~97 ~16 ~48 glowstone
setblock ~97 ~16 ~49 yellow_glazed_terracotta
fill ~97 ~16 ~50 ~97 ~17 ~50 glowstone
setblock ~98 ~16 ~33 yellow_glazed_terracotta
setblock ~98 ~16 ~34 stained_hardened_clay 4
setblock ~98 ~16 ~35 glowstone
setblock ~98 ~16 ~36 stained_hardened_clay 4
setblock ~98 ~16 ~51 yellow_glazed_terracotta
fill ~99 ~16 ~30 ~99 ~17 ~30 yellow_glazed_terracotta
fill ~99 ~16 ~31 ~99 ~16 ~30 yellow_glazed_terracotta
setblock ~99 ~16 ~32 glowstone
fill ~99 ~16 ~52 ~99 ~16 ~53 yellow_glazed_terracotta
setblock ~100 ~16 ~28 glowstone
setblock ~100 ~16 ~29 yellow_glazed_terracotta
fill ~100 ~16 ~53 ~101 ~16 ~53 yellow_glazed_terracotta
fill ~101 ~16 ~26 ~102 ~16 ~26 glowstone
setblock ~101 ~16 ~27 yellow_glazed_terracotta
setblock ~101 ~16 ~54 yellow_glazed_terracotta
setblock ~102 ~16 ~25 glowstone
setblock ~102 ~16 ~54 stained_hardened_clay 4
fill ~103 ~16 ~25 ~107 ~16 ~25 yellow_glazed_terracotta
setblock ~103 ~16 ~54 glowstone
setblock ~104 ~16 ~24 stained_hardened_clay 4
setblock ~104 ~16 ~54 stained_hardened_clay 4
setblock ~105 ~16 ~24 yellow_glazed_terracotta
setblock ~105 ~16 ~54 glowstone
setblock ~106 ~16 ~54 stained_hardened_clay 4
setblock ~107 ~16 ~54 glowstone
setblock ~108 ~16 ~26 stained_hardened_clay 4
fill ~108 ~16 ~53 ~109 ~16 ~53 yellow_glazed_terracotta
setblock ~109 ~16 ~27 yellow_glazed_terracotta
setblock ~110 ~16 ~28 stained_hardened_clay 4
setblock ~110 ~16 ~29 yellow_glazed_terracotta
setblock ~110 ~16 ~52 glowstone
setblock ~111 ~16 ~30 stained_hardened_clay 4
setblock ~111 ~16 ~31 yellow_glazed_terracotta
setblock ~111 ~16 ~51 yellow_glazed_terracotta
setblock ~112 ~16 ~32 glowstone
setblock ~112 ~16 ~33 yellow_glazed_terracotta
setblock ~112 ~16 ~34 glowstone
fill ~112 ~16 ~49 ~112 ~16 ~50 stained_hardened_clay 4
fill ~113 ~16 ~36 ~113 ~17 ~36 glowstone
fill ~113 ~16 ~37 ~113 ~17 ~37 yellow_glazed_terracotta
setblock ~113 ~16 ~38 glowstone
setblock ~113 ~16 ~40 glowstone
setblock ~113 ~16 ~41 yellow_glazed_terracotta
setblock ~113 ~16 ~45 yellow_glazed_terracotta
setblock ~113 ~16 ~46 glowstone
setblock ~113 ~16 ~47 yellow_glazed_terracotta
setblock ~113 ~16 ~48 glowstone
setblock ~114 ~16 ~42 glowstone
setblock ~114 ~16 ~43 yellow_glazed_terracotta
setblock ~114 ~16 ~44 glowstone
fill ~30 ~17 ~38 ~30 ~17 ~40 yellow_glazed_terracotta
setblock ~30 ~17 ~41 glowstone
setblock ~30 ~17 ~42 yellow_glazed_terracotta
setblock ~30 ~17 ~43 glowstone
setblock ~30 ~17 ~44 yellow_glazed_terracotta
setblock ~30 ~17 ~45 glowstone
setblock ~30 ~17 ~46 yellow_glazed_terracotta
setblock ~30 ~17 ~47 glowstone
setblock ~30 ~17 ~48 yellow_glazed_terracotta
fill ~31 ~17 ~34 ~31 ~17 ~37 yellow_glazed_terracotta
fill ~31 ~17 ~49 ~31 ~17 ~50 yellow_glazed_terracotta
setblock ~32 ~17 ~31 glowstone
setblock ~32 ~17 ~32 yellow_glazed_terracotta
setblock ~32 ~17 ~33 glowstone
setblock ~32 ~17 ~51 glowstone
fill ~32 ~17 ~52 ~33 ~17 ~52 yellow_glazed_terracotta
fill ~33 ~17 ~29 ~33 ~17 ~30 yellow_glazed_terracotta
setblock ~34 ~17 ~27 glowstone
setblock ~34 ~17 ~28 yellow_glazed_terracotta
setblock ~34 ~17 ~53 glowstone
fill ~35 ~17 ~25 ~35 ~18 ~25 yellow_glazed_terracotta
setblock ~35 ~17 ~26 glowstone
fill ~35 ~17 ~54 ~36 ~17 ~54 yellow_glazed_terracotta
setblock ~36 ~17 ~25 glowstone
fill ~37 ~17 ~24 ~38 ~17 ~24 yellow_glazed_terracotta
setblock ~37 ~17 ~55 yellow_glazed_terracotta
setblock ~38 ~17 ~23 glowstone
setblock ~38 ~17 ~55 glowstone
setblock ~39 ~17 ~23 yellow_glazed_terracotta
setblock ~39 ~17 ~55 yellow_glazed_terracotta
setblock ~40 ~17 ~23 glowstone
setblock ~40 ~17 ~55 glowstone
setblock ~41 ~17 ~23 yellow_glazed_terracotta
setblock ~41 ~17 ~24 glowstone
setblock ~41 ~17 ~55 yellow_glazed_terracotta
setblock ~42 ~17 ~24 yellow_glazed_terracotta
setblock ~42 ~17 ~55 glowstone
setblock ~43 ~17 ~25 yellow_glazed_terracotta
setblock ~43 ~17 ~55 yellow_glazed_terracotta
setblock ~44 ~17 ~26 yellow_glazed_terracotta
setblock ~44 ~17 ~27 glowstone
fill ~44 ~17 ~54 ~45 ~17 ~54 yellow_glazed_terracotta
setblock ~44 ~17 ~55 glowstone
setblock ~45 ~17 ~28 wool 1
setblock ~45 ~17 ~29 yellow_glazed_terracotta
setblock ~46 ~17 ~31 glowstone
setblock ~46 ~17 ~32 yellow_glazed_terracotta
setblock ~46 ~17 ~33 stained_hardened_clay 4
setblock ~46 ~17 ~52 yellow_glazed_terracotta
setblock ~46 ~17 ~53 glowstone
fill ~47 ~17 ~34 ~47 ~17 ~38 yellow_glazed_terracotta
setblock ~47 ~17 ~51 yellow_glazed_terracotta
setblock ~47 ~17 ~52 glowstone
fill ~48 ~17 ~39 ~48 ~18 ~39 glowstone
setblock ~48 ~17 ~40 yellow_glazed_terracotta
fill ~48 ~17 ~41 ~48 ~18 ~41 glowstone
setblock ~48 ~17 ~42 yellow_glazed_terracotta
setblock ~48 ~17 ~43 glowstone
setblock ~48 ~17 ~44 yellow_glazed_terracotta
setblock ~48 ~17 ~45 stained_hardened_clay 4
setblock ~48 ~17 ~46 yellow_glazed_terracotta
setblock ~48 ~17 ~47 glowstone
setblock ~48 ~17 ~48 yellow_glazed_terracotta
fill ~48 ~17 ~49 ~48 ~18 ~49 stained_hardened_clay 4
fill ~96 ~17 ~39 ~96 ~18 ~39 glowstone
setblock ~96 ~17 ~40 yellow_glazed_terracotta
setblock ~96 ~17 ~41 stained_hardened_clay 4
setblock ~96 ~17 ~42 yellow_glazed_terracotta
setblock ~96 ~17 ~43 stained_hardened_clay 4
setblock ~96 ~17 ~44 yellow_glazed_terracotta
setblock ~96 ~17 ~45 stained_hardened_clay 4
setblock ~96 ~17 ~46 yellow_glazed_terracotta
setblock ~96 ~17 ~47 stained_hardened_clay 4
setblock ~96 ~17 ~48 wool 1
setblock ~96 ~17 ~49 red_sandstone
fill ~97 ~17 ~34 ~97 ~18 ~34 stained_hardened_clay 4
fill ~97 ~17 ~35 ~97 ~17 ~37 yellow_glazed_terracotta
setblock ~97 ~17 ~51 yellow_glazed_terracotta
setblock ~97 ~17 ~52 glowstone
setblock ~98 ~17 ~31 glowstone
setblock ~98 ~17 ~32 yellow_glazed_terracotta
setblock ~98 ~17 ~33 stained_hardened_clay 4
setblock ~98 ~17 ~52 yellow_glazed_terracotta
setblock ~98 ~17 ~53 glowstone
fill ~99 ~17 ~28 ~99 ~17 ~30 yellow_glazed_terracotta
fill ~99 ~17 ~54 ~100 ~17 ~54 yellow_glazed_terracotta
setblock ~100 ~17 ~26 yellow_glazed_terracotta
setblock ~100 ~17 ~27 glowstone
fill ~100 ~17 ~55 ~101 ~17 ~55 yellow_glazed_terracotta
setblock ~101 ~17 ~25 yellow_glazed_terracotta
fill ~102 ~17 ~24 ~103 ~17 ~24 yellow_glazed_terracotta
setblock ~102 ~17 ~55 stained_hardened_clay 4
setblock ~103 ~17 ~23 yellow_glazed_terracotta
setblock ~103 ~17 ~55 yellow_glazed_terracotta
setblock ~104 ~17 ~23 glowstone
setblock ~104 ~17 ~55 glowstone
fill ~105 ~17 ~23 ~106 ~17 ~23 yellow_glazed_terracotta
setblock ~105 ~17 ~55 yellow_glazed_terracotta
fill ~106 ~17 ~24 ~107 ~17 ~24 yellow_glazed_terracotta
setblock ~106 ~17 ~55 stained_hardened_clay 4
setblock ~107 ~17 ~55 yellow_glazed_terracotta
setblock ~108 ~17 ~25 glowstone
fill ~108 ~17 ~54 ~109 ~17 ~54 yellow_glazed_terracotta
fill ~109 ~17 ~25 ~109 ~18 ~25 yellow_glazed_terracotta
fill ~109 ~17 ~26 ~109 ~17 ~25 yellow_glazed_terracotta
setblock ~110 ~17 ~27 glowstone
setblock ~110 ~17 ~28 yellow_glazed_terracotta
setblock ~110 ~17 ~53 glowstone
fill ~111 ~17 ~29 ~111 ~17 ~30 yellow_glazed_terracotta
fill ~111 ~17 ~52 ~112 ~17 ~52 yellow_glazed_terracotta
setblock ~112 ~17 ~31 glowstone
setblock ~112 ~17 ~32 yellow_glazed_terracotta
setblock ~112 ~17 ~33 glowstone
setblock ~112 ~17 ~51 glowstone
fill ~113 ~17 ~34 ~113 ~18 ~34 yellow_glazed_terracotta
fill ~113 ~17 ~35 ~113 ~18 ~35 yellow_glazed_terracotta
fill ~113 ~17 ~49 ~113 ~17 ~50 yellow_glazed_terracotta
setblock ~114 ~17 ~38 yellow_glazed_terracotta
setblock ~114 ~17 ~39 glowstone
setblock ~114 ~17 ~40 yellow_glazed_terracotta
setblock ~114 ~17 ~41 glowstone
setblock ~114 ~17 ~42 yellow_glazed_terracotta
setblock ~114 ~17 ~43 glowstone
setblock ~114 ~17 ~44 yellow_glazed_terracotta
setblock ~114 ~17 ~45 glowstone
setblock ~114 ~17 ~46 yellow_glazed_terracotta
setblock ~114 ~17 ~47 glowstone
setblock ~114 ~17 ~48 yellow_glazed_terracotta
fill ~29 ~18 ~40 ~29 ~19 ~40 yellow_glazed_terracotta
fill ~29 ~18 ~41 ~29 ~19 ~41 yellow_glazed_terracotta
fill ~29 ~18 ~42 ~29 ~19 ~42 yellow_glazed_terracotta
fill ~29 ~18 ~43 ~29 ~19 ~43 yellow_glazed_terracotta
fill ~29 ~18 ~44 ~29 ~18 ~45 yellow_glazed_terracotta
setblock ~29 ~18 ~46 glowstone
fill ~29 ~18 ~47 ~29 ~19 ~47 yellow_glazed_terracotta
fill ~29 ~18 ~48 ~29 ~19 ~48 yellow_glazed_terracotta
setblock ~30 ~18 ~36 glowstone
setblock ~30 ~18 ~37 yellow_glazed_terracotta
setblock ~30 ~18 ~38 glowstone
setblock ~30 ~18 ~39 yellow_glazed_terracotta
setblock ~30 ~18 ~49 yellow_glazed_terracotta
setblock ~30 ~18 ~50 glowstone
setblock ~31 ~18 ~32 glowstone
fill ~31 ~18 ~33 ~31 ~19 ~33 yellow_glazed_terracotta
setblock ~31 ~18 ~34 glowstone
setblock ~31 ~18 ~35 yellow_glazed_terracotta
setblock ~31 ~18 ~51 yellow_glazed_terracotta
setblock ~31 ~18 ~52 glowstone
setblock ~32 ~18 ~29 yellow_glazed_terracotta
setblock ~32 ~18 ~30 glowstone
setblock ~32 ~18 ~31 yellow_glazed_terracotta
setblock ~32 ~18 ~53 glowstone
fill ~33 ~18 ~27 ~33 ~19 ~27 yellow_glazed_terracotta
fill ~33 ~18 ~28 ~33 ~18 ~27 yellow_glazed_terracotta
setblock ~33 ~18 ~53 yellow_glazed_terracotta
fill ~33 ~18 ~54 ~34 ~18 ~54 glowstone
setblock ~34 ~18 ~26 stained_hardened_clay 4
fill ~35 ~18 ~24 ~36 ~18 ~24 stained_hardened_clay 4
fill ~35 ~18 ~55 ~36 ~18 ~55 yellow_glazed_terracotta
setblock ~37 ~18 ~23 yellow_glazed_terracotta
fill ~37 ~18 ~56 ~39 ~18 ~56 glowstone
setblock ~38 ~18 ~22 stained_hardened_clay 4
fill ~39 ~18 ~22 ~41 ~18 ~22 glowstone
setblock ~40 ~18 ~56 stained_hardened_clay 4
fill ~41 ~18 ~56 ~44 ~18 ~56 glowstone
setblock ~42 ~18 ~23 glowstone
setblock ~43 ~18 ~24 glowstone
setblock ~44 ~18 ~25 stained_hardened_clay 4
setblock ~45 ~18 ~26 stained_hardened_clay 4
setblock ~45 ~18 ~27 yellow_glazed_terracotta
setblock ~45 ~18 ~55 yellow_glazed_terracotta
setblock ~46 ~18 ~28 glowstone
fill ~46 ~18 ~29 ~46 ~18 ~30 stained_hardened_clay 4
setblock ~46 ~18 ~54 stained_hardened_clay 4
fill ~47 ~18 ~31 ~47 ~19 ~31 yellow_glazed_terracotta
fill ~47 ~18 ~32 ~47 ~19 ~32 stained_hardened_clay 4
setblock ~47 ~18 ~33 yellow_glazed_terracotta
setblock ~47 ~18 ~34 glowstone
setblock ~47 ~18 ~35 yellow_glazed_terracotta
setblock ~47 ~18 ~53 yellow_glazed_terracotta
fill ~48 ~18 ~36 ~48 ~18 ~38 stained_hardened_clay 4
setblock ~48 ~18 ~40 stained_hardened_clay 4
setblock ~48 ~18 ~48 stained_hardened_clay 4
setblock ~48 ~18 ~50 stained_hardened_clay 4
setblock ~48 ~18 ~51 yellow_glazed_terracotta
setblock ~48 ~18 ~52 red_sandstone
fill ~49 ~18 ~42 ~49 ~19 ~42 glowstone
fill ~49 ~18 ~43 ~49 ~19 ~43 yellow_glazed_terracotta
fill ~49 ~18 ~44 ~49 ~18 ~46 glowstone
fill ~49 ~18 ~47 ~49 ~19 ~47 yellow_glazed_terracotta
setblock ~95 ~18 ~42 glowstone
setblock ~95 ~18 ~43 wool 1
fill ~95 ~18 ~44 ~95 ~18 ~46 stained_hardened_clay 4
fill ~95 ~18 ~47 ~95 ~19 ~47 yellow_glazed_terracotta
setblock ~96 ~18 ~36 stained_hardened_clay 4
setblock ~96 ~18 ~37 yellow_glazed_terracotta
setblock ~96 ~18 ~38 stained_hardened_clay 4
fill ~96 ~18 ~40 ~96 ~18 ~41 glowstone
setblock ~96 ~18 ~48 red_sandstone
setblock ~96 ~18 ~49 stained_hardened_clay 4
setblock ~96 ~18 ~50 red_sandstone
fill ~96 ~18 ~51 ~96 ~18 ~52 stained_hardened_clay 4
setblock ~97 ~18 ~31 stained_hardened_clay 4
setblock ~97 ~18 ~32 glowstone
setblock ~97 ~18 ~33 yellow_glazed_terracotta
setblock ~97 ~18 ~35 stained_hardened_clay 4
setblock ~97 ~18 ~53 yellow_glazed_terracotta
setblock ~98 ~18 ~28 glowstone
setblock ~98 ~18 ~29 yellow_glazed_terracotta
setblock ~98 ~18 ~30 glowstone
setblock ~98 ~18 ~54 glowstone
setblock ~99 ~18 ~26 glowstone
setblock ~99 ~18 ~27 yellow_glazed_terracotta
setblock ~99 ~18 ~55 yellow_glazed_terracotta
setblock ~100 ~18 ~25 glowstone
setblock ~100 ~18 ~56 glowstone
setblock ~101 ~18 ~24 glowstone
setblock ~101 ~18 ~56 yellow_glazed_terracotta
setblock ~102 ~18 ~23 glowstone
setblock ~102 ~18 ~56 stained_hardened_clay 4
fill ~103 ~18 ~22 ~106 ~18 ~22 glowstone
setblock ~103 ~18 ~56 yellow_glazed_terracotta
setblock ~104 ~18 ~56 stained_hardened_clay 4
setblock ~105 ~18 ~56 yellow_glazed_terracotta
setblock ~106 ~18 ~56 glowstone
setblock ~107 ~18 ~23 yellow_glazed_terracotta
setblock ~107 ~18 ~56 yellow_glazed_terracotta
setblock ~108 ~18 ~24 yellow_glazed_terracotta
setblock ~108 ~18 ~55 stained_hardened_clay 4
setblock ~109 ~18 ~24 glowstone
setblock ~109 ~18 ~55 yellow_glazed_terracotta
setblock ~110 ~18 ~26 glowstone
setblock ~110 ~18 ~54 stained_hardened_clay 4
fill ~111 ~18 ~27 ~111 ~19 ~27 yellow_glazed_terracotta
fill ~111 ~18 ~28 ~111 ~18 ~27 yellow_glazed_terracotta
fill ~111 ~18 ~53 ~112 ~18 ~53 yellow_glazed_terracotta
setblock ~111 ~18 ~54 glowstone
setblock ~112 ~18 ~29 yellow_glazed_terracotta
setblock ~112 ~18 ~30 glowstone
setblock ~112 ~18 ~31 yellow_glazed_terracotta
setblock ~113 ~18 ~32 glowstone
fill ~113 ~18 ~33 ~113 ~19 ~33 yellow_glazed_terracotta
setblock ~113 ~18 ~51 yellow_glazed_terracotta
setblock ~113 ~18 ~52 glowstone
fill ~114 ~18 ~36 ~114 ~18 ~37 glowstone
setblock ~114 ~18 ~38 stained_hardened_clay 4
setblock ~114 ~18 ~39 yellow_glazed_terracotta
fill ~114 ~18 ~49 ~114 ~18 ~50 stained_hardened_clay 4
setblock ~115 ~18 ~40 glowstone
fill ~115 ~18 ~41 ~115 ~19 ~41 yellow_glazed_terracotta
setblock ~115 ~18 ~42 glowstone
fill ~115 ~18 ~43 ~115 ~19 ~43 yellow_glazed_terracotta
setblock ~115 ~18 ~44 stained_hardened_clay 4
setblock ~115 ~18 ~45 yellow_glazed_terracotta
setblock ~115 ~18 ~46 glowstone
fill ~115 ~18 ~47 ~115 ~19 ~47 yellow_glazed_terracotta
setblock ~115 ~18 ~48 glowstone
setblock ~28 ~19 ~44 yellow_glazed_terracotta
setblock ~28 ~19 ~45 glowstone
fill ~29 ~19 ~37 ~29 ~20 ~37 yellow_glazed_terracotta
