setblock ~131 ~-3 ~146 mycelium 0
fill ~133 ~-3 ~132 ~133 ~-2 ~132 stained_hardened_clay 12
setblock ~137 ~-3 ~138 soul_sand 0
setblock ~257 ~-3 ~70 mycelium 0
fill ~106 ~-2 ~136 ~106 ~-2 ~137 soul_sand 0
setblock ~111 ~-2 ~134 stained_hardened_clay 12
fill ~112 ~-2 ~135 ~113 ~-2 ~135 stained_hardened_clay 12
fill ~114 ~-2 ~136 ~115 ~-2 ~136 stained_hardened_clay 12
setblock ~116 ~-2 ~137 stained_hardened_clay 12
fill ~117 ~-2 ~138 ~118 ~-2 ~138 stained_hardened_clay 12
fill ~119 ~-2 ~139 ~120 ~-2 ~139 stained_hardened_clay 12
setblock ~121 ~-2 ~117 stained_hardened_clay 12
fill ~121 ~-2 ~140 ~122 ~-2 ~140 stained_hardened_clay 12
fill ~122 ~-2 ~118 ~123 ~-2 ~118 stained_hardened_clay 12
fill ~123 ~-2 ~139 ~124 ~-2 ~139 stained_hardened_clay 12
fill ~124 ~-2 ~119 ~125 ~-2 ~119 stained_hardened_clay 12
fill ~125 ~-2 ~139 ~125 ~0 ~139 soul_sand 0
setblock ~126 ~-2 ~120 stained_hardened_clay 12
fill ~126 ~-2 ~138 ~128 ~-2 ~138 soul_sand 0
fill ~127 ~-2 ~121 ~128 ~-2 ~121 stained_hardened_clay 12
fill ~129 ~-2 ~122 ~130 ~-2 ~122 stained_hardened_clay 12
setblock ~129 ~-2 ~137 noteblock 0
setblock ~129 ~-2 ~143 soul_sand 0
fill ~130 ~-2 ~136 ~130 ~-1 ~136 soul_sand 0
setblock ~130 ~-2 ~144 mycelium 0
setblock ~130 ~-2 ~145 soul_sand 0
fill ~131 ~-2 ~123 ~132 ~-2 ~123 stained_hardened_clay 12
setblock ~131 ~-2 ~136 stained_hardened_clay 12
fill ~131 ~-2 ~145 ~131 ~-1 ~145 log2 1
fill ~131 ~-2 ~146 ~131 ~-2 ~145 log2 1
fill ~132 ~-2 ~134 ~132 ~-1 ~134 mycelium 0
fill ~132 ~-2 ~135 ~132 ~-1 ~135 soul_sand 0
setblock ~133 ~-2 ~124 stained_hardened_clay 12
fill ~133 ~-2 ~128 ~133 ~0 ~128 soul_sand 0
fill ~133 ~-2 ~129 ~133 ~0 ~129 soul_sand 0
fill ~133 ~-2 ~130 ~133 ~-1 ~130 soul_sand 0
setblock ~133 ~-2 ~131 stained_hardened_clay 12
setblock ~133 ~-2 ~133 stained_hardened_clay 12
fill ~134 ~-2 ~125 ~134 ~-2 ~126 stained_hardened_clay 12
setblock ~134 ~-2 ~127 noteblock 0
setblock ~134 ~-2 ~136 soul_sand 0
setblock ~135 ~-2 ~136 log2 0
setblock ~135 ~-2 ~137 mycelium 0
fill ~136 ~-2 ~131 ~138 ~-2 ~131 mycelium 0
fill ~136 ~-2 ~137 ~136 ~-2 ~138 soul_sand 0
fill ~137 ~-2 ~137 ~137 ~-2 ~138 log2 1
fill ~138 ~-2 ~132 ~140 ~-2 ~132 soul_sand 0
setblock ~139 ~-2 ~133 log2 1
setblock ~254 ~-2 ~70 mycelium 0
fill ~255 ~-2 ~70 ~256 ~-2 ~70 soul_sand 0
fill ~255 ~-2 ~92 ~256 ~-2 ~92 mycelium 0
setblock ~256 ~-2 ~69 mycelium 0
setblock ~256 ~-2 ~71 soul_sand 0
setblock ~256 ~-2 ~93 mycelium 0
setblock ~257 ~-2 ~70 log2 1
fill ~257 ~-2 ~92 ~257 ~-2 ~93 soul_sand 0
fill ~258 ~-2 ~87 ~259 ~-2 ~87 mycelium 0
setblock ~258 ~-2 ~93 log2 1
fill ~259 ~-2 ~88 ~260 ~-2 ~88 soul_sand 0
setblock ~260 ~-2 ~89 log2 1
fill ~263 ~-2 ~81 ~264 ~-2 ~81 soul_sand 0
setblock ~265 ~-2 ~82 log2 1
fill ~100 ~-1 ~126 ~100 ~-1 ~128 stained_hardened_clay 7
setblock ~101 ~-1 ~125 stained_hardened_clay 7
setblock ~101 ~-1 ~128 stained_hardened_clay 15
fill ~102 ~-1 ~129 ~103 ~-1 ~129 stained_hardened_clay 15
setblock ~104 ~-1 ~130 stained_hardened_clay 15
setblock ~105 ~-1 ~131 stained_hardened_clay 7
fill ~105 ~-1 ~133 ~105 ~-1 ~135 mycelium 0
setblock ~105 ~-1 ~136 stained_hardened_clay 12
fill ~106 ~-1 ~131 ~106 ~0 ~131 soul_sand 0
setblock ~106 ~-1 ~134 soul_sand 0
fill ~106 ~-1 ~135 ~106 ~-1 ~136 log2 1
fill ~107 ~-1 ~132 ~107 ~0 ~132 soul_sand 0
setblock ~108 ~-1 ~112 stained_hardened_clay 7
fill ~108 ~-1 ~132 ~108 ~1 ~132 mycelium 0
fill ~109 ~-1 ~111 ~110 ~-1 ~111 stained_hardened_clay 7
setblock ~109 ~-1 ~133 soul_sand 0
fill ~110 ~-1 ~134 ~111 ~-1 ~134 log2 1
setblock ~111 ~-1 ~111 stained_hardened_clay 15
fill ~112 ~-1 ~112 ~113 ~-1 ~112 stained_hardened_clay 15
fill ~112 ~-1 ~135 ~113 ~-1 ~135 stained_hardened_clay 15
setblock ~114 ~-1 ~113 stained_hardened_clay 15
setblock ~114 ~-1 ~136 stained_hardened_clay 15
setblock ~115 ~-1 ~114 stained_hardened_clay 7
setblock ~115 ~-1 ~136 log2 1
fill ~116 ~-1 ~114 ~116 ~0 ~114 soul_sand 0
setblock ~116 ~-1 ~137 log2 1
setblock ~117 ~-1 ~115 soul_sand 0
fill ~117 ~-1 ~138 ~118 ~-1 ~138 stained_hardened_clay 15
fill ~118 ~-1 ~115 ~118 ~0 ~115 mycelium 0
setblock ~119 ~-1 ~116 soul_sand 0
setblock ~119 ~-1 ~139 stained_hardened_clay 15
fill ~120 ~-1 ~117 ~121 ~-1 ~117 log2 1
setblock ~120 ~-1 ~139 stained_hardened_clay 7
fill ~121 ~-1 ~139 ~125 ~-1 ~139 soul_sand 0
fill ~122 ~-1 ~118 ~123 ~-1 ~118 stained_hardened_clay 15
setblock ~124 ~-1 ~119 stained_hardened_clay 15
setblock ~125 ~-1 ~119 log2 1
setblock ~126 ~-1 ~120 log2 1
fill ~126 ~-1 ~138 ~127 ~-1 ~138 soul_sand 0
setblock ~127 ~-1 ~121 stained_hardened_clay 7
fill ~127 ~-1 ~139 ~127 ~-1 ~140 soul_sand 0
setblock ~128 ~-1 ~121 stained_hardened_clay 15
fill ~128 ~-1 ~137 ~128 ~0 ~137 soul_sand 0
fill ~128 ~-1 ~140 ~128 ~-1 ~142 soul_sand 0
setblock ~128 ~-1 ~143 mycelium 0
fill ~129 ~-1 ~122 ~130 ~-1 ~122 stained_hardened_clay 7
fill ~129 ~-1 ~133 ~130 ~-1 ~133 soul_sand 0
setblock ~129 ~-1 ~136 soul_sand 0
fill ~129 ~-1 ~141 ~129 ~-1 ~142 mycelium 0
fill ~129 ~-1 ~144 ~129 ~-1 ~145 log2 0
fill ~130 ~-1 ~134 ~131 ~-1 ~134 soul_sand 0
setblock ~130 ~-1 ~142 brown_glazed_terracotta 0
setblock ~130 ~-1 ~143 mycelium 0
setblock ~130 ~-1 ~145 stained_hardened_clay 12
setblock ~131 ~-1 ~123 stained_hardened_clay 7
fill ~131 ~-1 ~124 ~132 ~-1 ~124 soul_sand 0
fill ~131 ~-1 ~129 ~133 ~-1 ~129 soul_sand 0
fill ~131 ~-1 ~135 ~131 ~0 ~135 soul_sand 0
fill ~131 ~-1 ~143 ~131 ~0 ~143 log2 1
fill ~131 ~-1 ~144 ~131 ~-1 ~143 log2 1
fill ~132 ~-1 ~125 ~133 ~-1 ~125 soul_sand 0
fill ~132 ~-1 ~130 ~132 ~-1 ~133 soul_sand 0
fill ~132 ~-1 ~136 ~133 ~-1 ~136 soul_sand 0
fill ~133 ~-1 ~126 ~133 ~-1 ~130 soul_sand 0
setblock ~133 ~-1 ~135 soul_sand 0
fill ~134 ~-1 ~130 ~136 ~-1 ~130 soul_sand 0
setblock ~134 ~-1 ~131 mycelium 0
setblock ~134 ~-1 ~135 log2 0
setblock ~134 ~-1 ~137 mycelium 0
setblock ~135 ~-1 ~131 soul_sand 0
fill ~135 ~-1 ~132 ~135 ~0 ~132 brown_glazed_terracotta 0
setblock ~135 ~-1 ~135 mycelium 0
setblock ~135 ~-1 ~138 mycelium 0
setblock ~136 ~-1 ~132 log2 0
setblock ~136 ~-1 ~136 log2 1
setblock ~136 ~-1 ~138 soul_sand 0
setblock ~137 ~-1 ~130 mycelium 0
setblock ~137 ~-1 ~132 mycelium 0
fill ~137 ~-1 ~133 ~138 ~-1 ~133 log2 1
setblock ~137 ~-1 ~137 stained_hardened_clay 12
setblock ~138 ~-1 ~131 brown_glazed_terracotta 0
setblock ~139 ~-1 ~131 soul_sand 0
setblock ~139 ~-1 ~132 log2 1
setblock ~225 ~-1 ~68 gold_ore 0
setblock ~226 ~-1 ~68 wool 8
fill ~231 ~-1 ~67 ~231 ~0 ~67 gold_ore 0
setblock ~232 ~-1 ~67 stained_hardened_clay 0
fill ~236 ~-1 ~66 ~237 ~-1 ~66 gold_ore 0
setblock ~250 ~-1 ~88 soul_sand 0
fill ~251 ~-1 ~70 ~253 ~-1 ~70 soul_sand 0
fill ~251 ~-1 ~89 ~252 ~-1 ~89 soul_sand 0
setblock ~251 ~-1 ~90 gold_ore 0
setblock ~252 ~-1 ~71 mycelium 0
fill ~252 ~-1 ~84 ~253 ~-1 ~84 soul_sand 0
fill ~252 ~-1 ~90 ~253 ~-1 ~90 soul_sand 0
fill ~253 ~-1 ~69 ~254 ~-1 ~69 mycelium 0
setblock ~253 ~-1 ~71 log2 0
fill ~253 ~-1 ~85 ~256 ~-1 ~85 soul_sand 0
fill ~253 ~-1 ~91 ~254 ~-1 ~91 soul_sand 0
fill ~254 ~-1 ~71 ~254 ~1 ~71 soul_sand 0
setblock ~254 ~-1 ~90 mycelium 0
setblock ~254 ~-1 ~92 soul_sand 0
setblock ~255 ~-1 ~69 log2 0
setblock ~255 ~-1 ~71 log2 1
setblock ~255 ~-1 ~86 mycelium 0
setblock ~255 ~-1 ~91 log2 0
fill ~255 ~-1 ~93 ~255 ~0 ~93 brown_glazed_terracotta 0
setblock ~256 ~-1 ~70 stained_hardened_clay 12
setblock ~256 ~-1 ~86 soul_sand 0
setblock ~256 ~-1 ~87 brown_glazed_terracotta 0
setblock ~256 ~-1 ~91 soul_sand 0
setblock ~256 ~-1 ~93 soul_sand 0
setblock ~257 ~-1 ~86 stained_hardened_clay 7
setblock ~257 ~-1 ~87 mycelium 0
fill ~257 ~-1 ~88 ~258 ~-1 ~88 soul_sand 0
fill ~257 ~-1 ~92 ~257 ~-1 ~93 log2 1
fill ~258 ~-1 ~77 ~258 ~0 ~77 stained_hardened_clay 15
setblock ~258 ~-1 ~86 soul_sand 0
setblock ~259 ~-1 ~86 brown_glazed_terracotta 0
fill ~259 ~-1 ~87 ~259 ~0 ~87 mycelium 0
setblock ~259 ~-1 ~89 log2 1
fill ~260 ~-1 ~80 ~261 ~-1 ~80 soul_sand 0
setblock ~260 ~-1 ~88 log2 1
setblock ~261 ~-1 ~79 mycelium 0
fill ~262 ~-1 ~80 ~263 ~-1 ~80 mycelium 0
fill ~262 ~-1 ~81 ~262 ~-1 ~80 mycelium 0
fill ~263 ~-1 ~81 ~263 ~-2 ~81 soul_sand 0
setblock ~264 ~-1 ~80 soul_sand 0
setblock ~264 ~-1 ~81 log2 1
fill ~100 ~0 ~125 ~100 ~0 ~128 soul_sand 0
fill ~101 ~0 ~122 ~101 ~0 ~123 stained_hardened_clay 7
setblock ~101 ~0 ~124 soul_sand 0
fill ~101 ~0 ~128 ~101 ~1 ~128 stained_hardened_clay 7
fill ~102 ~0 ~129 ~103 ~0 ~129 stained_hardened_clay 7
fill ~104 ~0 ~130 ~104 ~1 ~130 soul_sand 0
fill ~104 ~0 ~131 ~106 ~0 ~131 soul_sand 0
fill ~104 ~0 ~132 ~104 ~0 ~133 soul_sand 0
setblock ~104 ~0 ~134 log2 0
setblock ~105 ~0 ~132 log2 0
setblock ~105 ~0 ~135 soul_sand 0
setblock ~106 ~0 ~114 stained_hardened_clay 7
fill ~106 ~0 ~133 ~106 ~1 ~133 log2 1
fill ~106 ~0 ~134 ~106 ~0 ~133 log2 1
setblock ~106 ~0 ~135 stained_hardened_clay 12
fill ~107 ~0 ~113 ~107 ~1 ~113 soul_sand 0
setblock ~108 ~0 ~112 soul_sand 0
fill ~109 ~0 ~111 ~110 ~0 ~111 soul_sand 0
setblock ~109 ~0 ~133 log2 1
fill ~110 ~0 ~134 ~110 ~-1 ~134 log2 1
setblock ~111 ~0 ~111 stained_hardened_clay 7
fill ~111 ~0 ~134 ~111 ~1 ~134 soul_sand 0
fill ~112 ~0 ~112 ~113 ~0 ~112 stained_hardened_clay 7
fill ~112 ~0 ~135 ~113 ~0 ~135 soul_sand 0
fill ~114 ~0 ~113 ~114 ~1 ~113 soul_sand 0
fill ~114 ~0 ~136 ~115 ~0 ~136 stained_hardened_clay 12
fill ~115 ~0 ~114 ~115 ~1 ~114 soul_sand 0
setblock ~116 ~0 ~137 stained_hardened_clay 8
setblock ~117 ~0 ~115 mycelium 0
setblock ~117 ~0 ~138 concrete 8
setblock ~118 ~0 ~138 wool 8
setblock ~119 ~0 ~116 log2 1
setblock ~119 ~0 ~139 mycelium 0
fill ~120 ~0 ~117 ~120 ~-1 ~117 log2 1
setblock ~120 ~0 ~139 soul_sand 0
fill ~121 ~0 ~117 ~121 ~1 ~117 soul_sand 0
fill ~121 ~0 ~139 ~122 ~0 ~139 mycelium 0
fill ~122 ~0 ~118 ~123 ~0 ~118 soul_sand 0
fill ~123 ~0 ~139 ~126 ~0 ~139 soul_sand 0
fill ~124 ~0 ~119 ~125 ~0 ~119 stained_hardened_clay 12
fill ~125 ~0 ~138 ~128 ~0 ~138 soul_sand 0
setblock ~126 ~0 ~120 stained_hardened_clay 8
fill ~126 ~0 ~140 ~126 ~0 ~141 soul_sand 0
setblock ~127 ~0 ~121 stained_hardened_clay 8
fill ~127 ~0 ~141 ~127 ~0 ~142 soul_sand 0
fill ~128 ~0 ~121 ~128 ~0 ~122 iron_ore 0
setblock ~128 ~0 ~134 stained_hardened_clay 7
fill ~128 ~0 ~135 ~128 ~1 ~135 brown_glazed_terracotta 0
setblock ~128 ~0 ~139 mycelium 0
setblock ~128 ~0 ~143 brown_glazed_terracotta 0
setblock ~129 ~0 ~122 soul_sand 0
setblock ~129 ~0 ~123 mycelium 0
fill ~129 ~0 ~134 ~129 ~0 ~135 soul_sand 0
setblock ~129 ~0 ~136 stained_hardened_clay 7
setblock ~129 ~0 ~139 iron_ore 0
setblock ~129 ~0 ~140 brown_glazed_terracotta 0
setblock ~129 ~0 ~144 brown_glazed_terracotta 0
setblock ~130 ~0 ~123 soul_sand 0
setblock ~130 ~0 ~124 mycelium 0
fill ~130 ~0 ~132 ~131 ~0 ~132 soul_sand 0
setblock ~130 ~0 ~135 soul_sand 0
setblock ~130 ~0 ~141 brown_glazed_terracotta 0
fill ~130 ~0 ~142 ~130 ~1 ~142 soul_sand 0
setblock ~130 ~0 ~145 log2 1
setblock ~131 ~0 ~125 soul_sand 0
setblock ~131 ~0 ~130 soul_sand 0
setblock ~131 ~0 ~131 bedrock 0
fill ~131 ~0 ~133 ~131 ~1 ~133 soul_sand 0
fill ~131 ~0 ~134 ~131 ~0 ~132 soul_sand 0
setblock ~131 ~0 ~136 soul_sand 0
setblock ~131 ~0 ~144 soul_sand 0
setblock ~132 ~0 ~126 soul_sand 0
fill ~132 ~0 ~128 ~132 ~2 ~128 soul_sand 0
setblock ~132 ~0 ~130 stained_hardened_clay 7
setblock ~132 ~0 ~131 soul_sand 0
setblock ~132 ~0 ~133 iron_ore 0
fill ~132 ~0 ~137 ~134 ~0 ~137 brown_glazed_terracotta 0
setblock ~133 ~0 ~127 soul_sand 0
setblock ~133 ~0 ~131 brown_glazed_terracotta 0
setblock ~133 ~0 ~134 brown_glazed_terracotta 0
fill ~134 ~0 ~129 ~135 ~0 ~129 soul_sand 0
setblock ~134 ~0 ~132 brown_glazed_terracotta 0
setblock ~134 ~0 ~134 mycelium 0
setblock ~135 ~0 ~135 stained_hardened_clay 12
setblock ~135 ~0 ~138 soul_sand 0
setblock ~136 ~0 ~129 brown_glazed_terracotta 0
fill ~136 ~0 ~132 ~136 ~1 ~132 soul_sand 0
setblock ~136 ~0 ~136 soul_sand 0
setblock ~136 ~0 ~137 log2 1
setblock ~137 ~0 ~130 brown_glazed_terracotta 0
fill ~137 ~0 ~133 ~137 ~-1 ~133 log2 1
setblock ~138 ~0 ~131 mycelium 0
setblock ~138 ~0 ~132 stained_hardened_clay 12
fill ~224 ~0 ~67 ~224 ~1 ~67 gold_ore 0
fill ~224 ~0 ~68 ~224 ~1 ~68 gold_ore 0
setblock ~225 ~0 ~67 wool 8
setblock ~225 ~0 ~69 gold_ore 0
fill ~226 ~0 ~67 ~226 ~1 ~67 gold_ore 0
fill ~226 ~0 ~70 ~226 ~0 ~71 gold_ore 0
setblock ~227 ~0 ~67 wool 8
fill ~227 ~0 ~72 ~227 ~0 ~74 gold_ore 0
fill ~228 ~0 ~67 ~231 ~0 ~67 gold_ore 0
fill ~228 ~0 ~75 ~228 ~2 ~75 gold_ore 0
fill ~228 ~0 ~76 ~228 ~2 ~76 gold_ore 0
fill ~228 ~0 ~77 ~228 ~2 ~77 gold_ore 0
fill ~229 ~0 ~78 ~229 ~1 ~78 gold_ore 0
fill ~229 ~0 ~79 ~229 ~0 ~80 gold_ore 0
fill ~230 ~0 ~81 ~230 ~1 ~81 brown_glazed_terracotta 0
fill ~230 ~0 ~82 ~230 ~1 ~82 gold_ore 0
fill ~231 ~0 ~83 ~231 ~0 ~84 gold_ore 0
fill ~232 ~0 ~66 ~236 ~0 ~66 gold_ore 0
fill ~232 ~0 ~85 ~232 ~2 ~85 mycelium 0
setblock ~233 ~0 ~86 soul_sand 0
setblock ~234 ~0 ~86 log2 0
fill ~235 ~0 ~87 ~236 ~0 ~87 gold_ore 0
setblock ~237 ~0 ~65 gold_ore 0
setblock ~237 ~0 ~88 stained_hardened_clay 8
fill ~238 ~0 ~65 ~239 ~0 ~65 brown_glazed_terracotta 0
fill ~238 ~0 ~89 ~238 ~1 ~89 log2 0
setblock ~239 ~0 ~89 stained_hardened_clay 8
fill ~240 ~0 ~65 ~241 ~0 ~65 gold_ore 0
fill ~240 ~0 ~89 ~242 ~0 ~89 gold_ore 0
fill ~242 ~0 ~65 ~242 ~1 ~65 stained_hardened_clay 8
setblock ~243 ~0 ~66 stained_hardened_clay 8
setblock ~243 ~0 ~90 gold_ore 0
setblock ~244 ~0 ~66 gold_ore 0
setblock ~244 ~0 ~90 brown_glazed_terracotta 0
fill ~245 ~0 ~67 ~246 ~0 ~67 gold_ore 0
setblock ~245 ~0 ~91 gold_ore 0
setblock ~246 ~0 ~92 brown_glazed_terracotta 0
setblock ~247 ~0 ~68 gold_ore 0
fill ~247 ~0 ~92 ~247 ~2 ~92 gold_ore 0
fill ~248 ~0 ~69 ~248 ~2 ~69 brown_glazed_terracotta 0
fill ~248 ~0 ~70 ~248 ~0 ~72 soul_sand 0
setblock ~248 ~0 ~93 gold_ore 0
setblock ~249 ~0 ~69 soul_sand 0
setblock ~249 ~0 ~70 log2 0
setblock ~249 ~0 ~71 soul_sand 0
setblock ~249 ~0 ~72 bedrock 0
setblock ~249 ~0 ~89 stained_hardened_clay 7
fill ~249 ~0 ~90 ~250 ~0 ~90 soul_sand 0
setblock ~249 ~0 ~92 gold_ore 0
setblock ~250 ~0 ~69 stained_hardened_clay 7
setblock ~250 ~0 ~70 soul_sand 0
setblock ~250 ~0 ~71 mycelium 0
fill ~250 ~0 ~72 ~251 ~0 ~72 brown_glazed_terracotta 0
setblock ~250 ~0 ~89 soul_sand 0
setblock ~250 ~0 ~91 gold_ore 0
setblock ~251 ~0 ~69 soul_sand 0
setblock ~251 ~0 ~71 log2 0
fill ~251 ~0 ~87 ~251 ~0 ~88 soul_sand 0
setblock ~251 ~0 ~89 gold_ore 0
setblock ~251 ~0 ~90 log2 0
setblock ~251 ~0 ~91 soul_sand 0
setblock ~252 ~0 ~69 mycelium 0
fill ~252 ~0 ~72 ~252 ~1 ~72 log2 0
setblock ~252 ~0 ~85 soul_sand 0
setblock ~252 ~0 ~86 bedrock 0
setblock ~252 ~0 ~88 mycelium 0
fill ~252 ~0 ~89 ~254 ~0 ~89 brown_glazed_terracotta 0
setblock ~252 ~0 ~91 mycelium 0
setblock ~253 ~0 ~69 brown_glazed_terracotta 0
fill ~253 ~0 ~72 ~253 ~1 ~72 soul_sand 0
fill ~253 ~0 ~73 ~254 ~0 ~73 log2 1
setblock ~253 ~0 ~82 stained_hardened_clay 7
fill ~253 ~0 ~83 ~254 ~0 ~83 soul_sand 0
fill ~253 ~0 ~86 ~254 ~0 ~86 brown_glazed_terracotta 0
setblock ~253 ~0 ~92 iron_ore 0
setblock ~254 ~0 ~69 gold_ore 0
setblock ~254 ~0 ~84 soul_sand 0
fill ~254 ~0 ~87 ~255 ~0 ~87 brown_glazed_terracotta 0
fill ~254 ~0 ~88 ~255 ~0 ~88 log2 0
setblock ~254 ~0 ~92 brown_glazed_terracotta 0
setblock ~255 ~0 ~69 mycelium 0
fill ~255 ~0 ~70 ~255 ~0 ~71 soul_sand 0
setblock ~255 ~0 ~74 stained_hardened_clay 12
fill ~255 ~0 ~79 ~256 ~0 ~79 soul_sand 0
setblock ~255 ~0 ~84 stained_hardened_clay 7
setblock ~255 ~0 ~90 log2 0
setblock ~256 ~0 ~75 soul_sand 0
fill ~256 ~0 ~77 ~256 ~0 ~79 soul_sand 0
fill ~256 ~0 ~80 ~256 ~0 ~81 stained_hardened_clay 15
setblock ~256 ~0 ~84 soul_sand 0
setblock ~256 ~0 ~87 log2 0
fill ~256 ~0 ~88 ~257 ~0 ~88 soul_sand 0
setblock ~256 ~0 ~91 log2 1
setblock ~256 ~0 ~93 stained_hardened_clay 12
setblock ~257 ~0 ~75 stained_hardened_clay 15
setblock ~257 ~0 ~77 bedrock 0
fill ~257 ~0 ~78 ~258 ~0 ~78 stained_hardened_clay 7
fill ~257 ~0 ~79 ~257 ~0 ~78 stained_hardened_clay 7
fill ~257 ~0 ~82 ~257 ~2 ~82 stained_hardened_clay 15
fill ~257 ~0 ~83 ~257 ~2 ~83 stained_hardened_clay 15
setblock ~257 ~0 ~84 coal_block 0
setblock ~257 ~0 ~85 soul_sand 0
fill ~257 ~0 ~86 ~257 ~1 ~86 coal_block 0
setblock ~257 ~0 ~87 brown_glazed_terracotta 0
setblock ~257 ~0 ~92 soul_sand 0
setblock ~258 ~0 ~76 stained_hardened_clay 15
fill ~258 ~0 ~79 ~259 ~0 ~79 soul_sand 0
setblock ~258 ~0 ~80 mycelium 0
fill ~258 ~0 ~86 ~258 ~1 ~86 brown_glazed_terracotta 0
fill ~258 ~0 ~88 ~259 ~0 ~88 stained_hardened_clay 12
setblock ~259 ~0 ~78 soul_sand 0
setblock ~259 ~0 ~80 soul_sand 0
setblock ~260 ~0 ~78 brown_glazed_terracotta 0
setblock ~260 ~0 ~79 mycelium 0
fill ~260 ~0 ~81 ~260 ~1 ~81 brown_glazed_terracotta 0
fill ~261 ~0 ~79 ~262 ~0 ~79 brown_glazed_terracotta 0
setblock ~261 ~0 ~81 mycelium 0
fill ~262 ~0 ~81 ~262 ~1 ~81 log2 1
setblock ~263 ~0 ~79 log2 0
fill ~263 ~0 ~80 ~263 ~0 ~81 stained_hardened_clay 12
fill ~99 ~1 ~126 ~99 ~1 ~127 mycelium 0
setblock ~100 ~1 ~123 soul_sand 0
fill ~100 ~1 ~124 ~100 ~1 ~125 mycelium 0
setblock ~100 ~1 ~128 soul_sand 0
fill ~101 ~1 ~120 ~101 ~1 ~122 soul_sand 0
fill ~102 ~1 ~118 ~102 ~1 ~119 soul_sand 0
fill ~102 ~1 ~129 ~102 ~0 ~129 stained_hardened_clay 7
setblock ~103 ~1 ~117 soul_sand 0
fill ~103 ~1 ~126 ~103 ~1 ~130 soul_sand 0
setblock ~103 ~1 ~131 log2 0
setblock ~103 ~1 ~132 brown_glazed_terracotta 0
setblock ~104 ~1 ~116 soul_sand 0
fill ~104 ~1 ~127 ~104 ~1 ~130 soul_sand 0
fill ~104 ~1 ~133 ~104 ~2 ~133 brown_glazed_terracotta 0
fill ~104 ~1 ~134 ~104 ~1 ~133 brown_glazed_terracotta 0
setblock ~105 ~1 ~115 mycelium 0
fill ~105 ~1 ~129 ~105 ~1 ~130 brown_glazed_terracotta 0
setblock ~105 ~1 ~131 soul_sand 0
setblock ~105 ~1 ~135 stained_hardened_clay 12
setblock ~106 ~1 ~114 mycelium 0
setblock ~106 ~1 ~131 log2 0
fill ~106 ~1 ~132 ~106 ~2 ~132 soul_sand 0
setblock ~106 ~1 ~134 soul_sand 0
setblock ~107 ~1 ~132 brown_glazed_terracotta 0
setblock ~108 ~1 ~112 mycelium 0
fill ~109 ~1 ~111 ~111 ~1 ~111 soul_sand 0
setblock ~109 ~1 ~133 soul_sand 0
setblock ~110 ~1 ~134 stained_hardened_clay 12
fill ~112 ~1 ~112 ~112 ~0 ~112 stained_hardened_clay 7
fill ~112 ~1 ~135 ~113 ~1 ~135 mycelium 0
setblock ~113 ~1 ~112 soul_sand 0
fill ~114 ~1 ~136 ~115 ~1 ~136 soul_sand 0
setblock ~116 ~1 ~114 brown_glazed_terracotta 0
setblock ~116 ~1 ~137 stained_hardened_clay 0
fill ~117 ~1 ~115 ~117 ~2 ~115 brown_glazed_terracotta 0
setblock ~117 ~1 ~138 stained_hardened_clay 0
setblock ~118 ~1 ~115 soul_sand 0
setblock ~118 ~1 ~138 concrete 8
setblock ~119 ~1 ~116 soul_sand 0
fill ~119 ~1 ~138 ~120 ~1 ~138 stained_hardened_clay 8
setblock ~120 ~1 ~117 soul_sand 0
fill ~121 ~1 ~139 ~123 ~1 ~139 mycelium 0
fill ~122 ~1 ~118 ~123 ~1 ~118 mycelium 0
setblock ~124 ~1 ~119 soul_sand 0
setblock ~124 ~1 ~139 soul_sand 0
setblock ~125 ~1 ~119 gold_ore 0
setblock ~125 ~1 ~120 brown_glazed_terracotta 0
fill ~125 ~1 ~138 ~126 ~1 ~138 soul_sand 0
fill ~125 ~1 ~139 ~125 ~2 ~139 brown_glazed_terracotta 0
fill ~125 ~1 ~140 ~125 ~2 ~140 brown_glazed_terracotta 0
fill ~126 ~1 ~120 ~126 ~1 ~121 stained_hardened_clay 0
setblock ~126 ~1 ~141 bedrock 0
setblock ~127 ~1 ~121 concrete 8
setblock ~127 ~1 ~122 iron_ore 0
setblock ~127 ~1 ~137 soul_sand 0
setblock ~127 ~1 ~142 iron_ore 0
setblock ~128 ~1 ~123 stained_hardened_clay 8
setblock ~128 ~1 ~136 soul_sand 0
fill ~128 ~1 ~137 ~128 ~2 ~137 wool 8
setblock ~128 ~1 ~143 concrete 8
setblock ~129 ~1 ~124 mycelium 0
setblock ~129 ~1 ~135 soul_sand 0
setblock ~129 ~1 ~138 double_stone_slab 8
setblock ~129 ~1 ~139 concrete 8
fill ~129 ~1 ~143 ~129 ~1 ~144 mycelium 0
setblock ~130 ~1 ~125 mycelium 0
setblock ~130 ~1 ~134 soul_sand 0
fill ~130 ~1 ~136 ~131 ~1 ~136 brown_glazed_terracotta 0
setblock ~130 ~1 ~140 log2 0
setblock ~130 ~1 ~141 soul_sand 0
fill ~130 ~1 ~143 ~130 ~1 ~144 soul_sand 0
setblock ~131 ~1 ~126 soul_sand 0
setblock ~131 ~1 ~131 brown_glazed_terracotta 0
setblock ~131 ~1 ~132 mycelium 0
setblock ~132 ~1 ~127 mycelium 0
fill ~132 ~1 ~129 ~132 ~2 ~129 soul_sand 0
fill ~132 ~1 ~130 ~132 ~2 ~130 soul_sand 0
setblock ~132 ~1 ~131 concrete 8
setblock ~132 ~1 ~133 concrete 8
fill ~132 ~1 ~137 ~133 ~1 ~137 concrete 8
fill ~133 ~1 ~128 ~134 ~1 ~128 brown_glazed_terracotta 0
setblock ~133 ~1 ~132 gold_ore 0
setblock ~133 ~1 ~133 brown_glazed_terracotta 0
setblock ~134 ~1 ~132 log2 0
fill ~134 ~1 ~134 ~134 ~1 ~135 soul_sand 0
setblock ~134 ~1 ~137 brown_glazed_terracotta 0
setblock ~135 ~1 ~129 concrete 8
setblock ~135 ~1 ~132 soul_sand 0
fill ~135 ~1 ~135 ~135 ~1 ~137 soul_sand 0
setblock ~136 ~1 ~129 concrete 8
setblock ~137 ~1 ~130 concrete 8
setblock ~137 ~1 ~131 mycelium 0
setblock ~137 ~1 ~132 soul_sand 0
setblock ~223 ~1 ~67 gold_ore 0
fill ~224 ~1 ~69 ~224 ~2 ~69 gold_ore 0
setblock ~225 ~1 ~67 gold_ore 0
setblock ~225 ~1 ~70 gold_ore 0
setblock ~226 ~1 ~71 gold_ore 0
setblock ~227 ~1 ~67 gold_ore 0
fill ~227 ~1 ~72 ~227 ~1 ~73 brown_glazed_terracotta 0
fill ~227 ~1 ~74 ~227 ~3 ~74 gold_ore 0
fill ~228 ~1 ~66 ~230 ~1 ~66 gold_ore 0
setblock ~229 ~1 ~79 mycelium 0
setblock ~229 ~1 ~80 stained_hardened_clay 8
setblock ~231 ~1 ~66 brown_glazed_terracotta 0
setblock ~231 ~1 ~83 brown_glazed_terracotta 0
fill ~231 ~1 ~84 ~231 ~3 ~84 mycelium 0
fill ~232 ~1 ~66 ~233 ~1 ~66 gold_ore 0
fill ~233 ~1 ~86 ~233 ~3 ~86 brown_glazed_terracotta 0
fill ~234 ~1 ~65 ~236 ~1 ~65 gold_ore 0
fill ~234 ~1 ~86 ~234 ~3 ~86 gold_ore 0
fill ~235 ~1 ~87 ~236 ~1 ~87 gold_ore 0
setblock ~237 ~1 ~65 log2 0
setblock ~237 ~1 ~88 gold_ore 0
fill ~238 ~1 ~65 ~239 ~1 ~65 stained_hardened_clay 8
fill ~239 ~1 ~89 ~240 ~1 ~89 brown_glazed_terracotta 0
fill ~240 ~1 ~64 ~240 ~4 ~64 brown_glazed_terracotta 0
fill ~241 ~1 ~65 ~241 ~4 ~65 brown_glazed_terracotta 0
setblock ~241 ~1 ~89 gold_ore 0
fill ~242 ~1 ~89 ~242 ~2 ~89 log2 0
fill ~243 ~1 ~66 ~243 ~2 ~66 log2 0
fill ~243 ~1 ~90 ~244 ~1 ~90 log2 0
setblock ~244 ~1 ~66 brown_glazed_terracotta 0
fill ~245 ~1 ~67 ~245 ~0 ~67 gold_ore 0
setblock ~245 ~1 ~91 brown_glazed_terracotta 0
setblock ~246 ~1 ~67 log2 0
setblock ~246 ~1 ~92 gold_ore 0
setblock ~247 ~1 ~68 log2 0
fill ~248 ~1 ~68 ~249 ~1 ~68 brown_glazed_terracotta 0
setblock ~248 ~1 ~73 concrete 8
fill ~248 ~1 ~92 ~248 ~2 ~92 gold_ore 0
fill ~249 ~1 ~70 ~250 ~1 ~70 gold_ore 0
fill ~249 ~1 ~72 ~250 ~1 ~72 concrete 8
fill ~249 ~1 ~90 ~250 ~1 ~90 brown_glazed_terracotta 0
fill ~249 ~1 ~91 ~251 ~1 ~91 brown_glazed_terracotta 0
fill ~250 ~1 ~69 ~251 ~1 ~69 brown_glazed_terracotta 0
setblock ~251 ~1 ~71 brown_glazed_terracotta 0
setblock ~251 ~1 ~72 gold_ore 0
fill ~251 ~1 ~89 ~251 ~2 ~89 brown_glazed_terracotta 0
fill ~252 ~1 ~69 ~253 ~1 ~69 concrete 8
fill ~252 ~1 ~86 ~253 ~1 ~86 concrete 8
setblock ~252 ~1 ~87 wool 8
fill ~252 ~1 ~89 ~253 ~1 ~89 gold_ore 0
setblock ~252 ~1 ~92 iron_ore 0
setblock ~253 ~1 ~70 log2 0
setblock ~253 ~1 ~71 mycelium 0
fill ~253 ~1 ~73 ~254 ~1 ~73 log2 1
setblock ~253 ~1 ~82 concrete 8
setblock ~253 ~1 ~88 stained_hardened_clay 0
setblock ~253 ~1 ~92 concrete 8
setblock ~254 ~1 ~70 soul_sand 0
setblock ~254 ~1 ~82 brown_glazed_terracotta 0
fill ~254 ~1 ~87 ~254 ~1 ~88 gold_ore 0
setblock ~254 ~1 ~89 brown_glazed_terracotta 0
setblock ~254 ~1 ~92 gold_ore 0
fill ~255 ~1 ~74 ~255 ~2 ~74 log2 1
setblock ~255 ~1 ~83 brown_glazed_terracotta 0
setblock ~255 ~1 ~87 log2 0
fill ~255 ~1 ~88 ~255 ~5 ~88 brown_glazed_terracotta 0
fill ~255 ~1 ~90 ~255 ~1 ~92 soul_sand 0
setblock ~256 ~1 ~75 noteblock 0
setblock ~256 ~1 ~76 brown_glazed_terracotta 0
setblock ~256 ~1 ~79 stained_hardened_clay 15
setblock ~256 ~1 ~80 soul_sand 0
setblock ~256 ~1 ~81 stained_hardened_clay 15
setblock ~256 ~1 ~84 brown_glazed_terracotta 0
setblock ~256 ~1 ~86 stained_hardened_clay 15
setblock ~256 ~1 ~87 brown_glazed_terracotta 0
setblock ~256 ~1 ~88 log2 0
setblock ~256 ~1 ~92 soul_sand 0
fill ~257 ~1 ~75 ~257 ~1 ~77 soul_sand 0
setblock ~257 ~1 ~78 stained_hardened_clay 15
setblock ~257 ~1 ~80 mycelium 0
setblock ~257 ~1 ~84 stained_hardened_clay 15
setblock ~257 ~1 ~85 concrete 8
fill ~257 ~1 ~87 ~258 ~1 ~87 soul_sand 0
fill ~257 ~1 ~88 ~257 ~1 ~87 soul_sand 0
fill ~258 ~1 ~77 ~259 ~1 ~77 brown_glazed_terracotta 0
setblock ~258 ~1 ~80 brown_glazed_terracotta 0
fill ~259 ~1 ~81 ~259 ~2 ~81 brown_glazed_terracotta 0
setblock ~260 ~1 ~78 concrete 8
setblock ~261 ~1 ~78 stained_hardened_clay 0
fill ~261 ~1 ~81 ~261 ~2 ~81 soul_sand 0
setblock ~262 ~1 ~79 log2 0
fill ~262 ~1 ~80 ~263 ~1 ~80 soul_sand 0
fill ~99 ~2 ~124 ~99 ~2 ~126 brown_glazed_terracotta 0
setblock ~99 ~2 ~127 stained_hardened_clay 7
setblock ~100 ~2 ~121 mycelium 0
fill ~100 ~2 ~122 ~100 ~2 ~123 brown_glazed_terracotta 0
setblock ~100 ~2 ~127 soul_sand 0
fill ~101 ~2 ~118 ~101 ~3 ~118 soul_sand 0
fill ~101 ~2 ~119 ~101 ~2 ~118 soul_sand 0
setblock ~101 ~2 ~120 bedrock 0
setblock ~101 ~2 ~124 stained_hardened_clay 7
fill ~101 ~2 ~125 ~103 ~2 ~125 soul_sand 0
fill ~101 ~2 ~126 ~102 ~2 ~126 soul_sand 0
fill ~101 ~2 ~128 ~102 ~2 ~128 soul_sand 0
setblock ~102 ~2 ~117 soul_sand 0
setblock ~102 ~2 ~124 soul_sand 0
setblock ~102 ~2 ~127 soul_sand 0
setblock ~102 ~2 ~129 soul_sand 0
setblock ~102 ~2 ~130 bedrock 0
setblock ~103 ~2 ~116 soul_sand 0
setblock ~103 ~2 ~129 brown_glazed_terracotta 0
fill ~103 ~2 ~131 ~103 ~3 ~131 concrete 8
setblock ~103 ~2 ~132 stained_hardened_clay 0
setblock ~104 ~2 ~115 brown_glazed_terracotta 0
setblock ~104 ~2 ~126 soul_sand 0
setblock ~104 ~2 ~130 brown_glazed_terracotta 0
setblock ~105 ~2 ~114 brown_glazed_terracotta 0
fill ~105 ~2 ~126 ~105 ~2 ~127 brown_glazed_terracotta 0
fill ~105 ~2 ~128 ~105 ~3 ~128 gold_ore 0
fill ~105 ~2 ~129 ~105 ~2 ~128 gold_ore 0
setblock ~105 ~2 ~130 bedrock 0
fill ~105 ~2 ~133 ~106 ~2 ~133 soul_sand 0
fill ~105 ~2 ~134 ~105 ~2 ~133 soul_sand 0
setblock ~106 ~2 ~113 brown_glazed_terracotta 0
setblock ~106 ~2 ~130 log2 0
setblock ~106 ~2 ~131 wool 8
setblock ~107 ~2 ~112 mycelium 0
setblock ~107 ~2 ~131 stained_hardened_clay 0
setblock ~108 ~2 ~112 stained_hardened_clay 7
setblock ~108 ~2 ~132 soul_sand 0
fill ~109 ~2 ~111 ~109 ~0 ~111 soul_sand 0
fill ~109 ~2 ~133 ~110 ~2 ~133 log2 0
setblock ~110 ~2 ~111 stained_hardened_clay 7
setblock ~111 ~2 ~112 soul_sand 0
setblock ~111 ~2 ~134 mycelium 0
setblock ~112 ~2 ~112 brown_glazed_terracotta 0
setblock ~112 ~2 ~135 log2 0
fill ~113 ~2 ~113 ~114 ~2 ~113 brown_glazed_terracotta 0
setblock ~113 ~2 ~135 brown_glazed_terracotta 0
fill ~114 ~2 ~136 ~114 ~3 ~136 brown_glazed_terracotta 0
setblock ~115 ~2 ~114 concrete 8
fill ~115 ~2 ~136 ~115 ~3 ~136 soul_sand 0
setblock ~116 ~2 ~115 stained_hardened_clay 0
setblock ~116 ~2 ~137 log2 0
setblock ~117 ~2 ~138 log2 0
fill ~118 ~2 ~116 ~119 ~2 ~116 mycelium 0
fill ~118 ~2 ~138 ~123 ~2 ~138 mycelium 0
setblock ~120 ~2 ~117 log2 0
setblock ~121 ~2 ~117 mycelium 0
setblock ~122 ~2 ~118 log2 0
setblock ~123 ~2 ~118 brown_glazed_terracotta 0
setblock ~124 ~2 ~119 log2 0
setblock ~124 ~2 ~120 soul_sand 0
setblock ~124 ~2 ~138 brown_glazed_terracotta 0
setblock ~125 ~2 ~121 mycelium 0
fill ~125 ~2 ~138 ~125 ~0 ~138 soul_sand 0
setblock ~126 ~2 ~122 brown_glazed_terracotta 0
fill ~126 ~2 ~137 ~126 ~3 ~137 soul_sand 0
fill ~126 ~2 ~141 ~127 ~2 ~141 iron_ore 0
setblock ~127 ~2 ~123 mycelium 0
fill ~127 ~2 ~136 ~127 ~3 ~136 soul_sand 0
setblock ~127 ~2 ~142 concrete 8
setblock ~128 ~2 ~124 mycelium 0
fill ~128 ~2 ~135 ~128 ~3 ~135 soul_sand 0
setblock ~128 ~2 ~142 brown_glazed_terracotta 0
setblock ~129 ~2 ~125 mycelium 0
setblock ~129 ~2 ~134 soul_sand 0
setblock ~129 ~2 ~135 concrete 8
setblock ~129 ~2 ~138 gold_ore 0
setblock ~129 ~2 ~139 log2 0
fill ~129 ~2 ~141 ~129 ~2 ~142 soul_sand 0
setblock ~130 ~2 ~126 mycelium 0
setblock ~130 ~2 ~133 soul_sand 0
setblock ~130 ~2 ~136 concrete 8
setblock ~130 ~2 ~140 soul_sand 0
setblock ~130 ~2 ~141 log2 0
setblock ~131 ~2 ~127 mycelium 0
setblock ~131 ~2 ~131 mycelium 0
fill ~131 ~2 ~132 ~132 ~2 ~132 brown_glazed_terracotta 0
fill ~131 ~2 ~136 ~132 ~2 ~136 wool 8
setblock ~132 ~2 ~127 brown_glazed_terracotta 0
setblock ~132 ~2 ~133 log2 0
fill ~133 ~2 ~128 ~134 ~2 ~128 iron_ore 0
fill ~133 ~2 ~132 ~134 ~2 ~132 soul_sand 0
fill ~133 ~2 ~133 ~133 ~2 ~135 soul_sand 0
setblock ~133 ~2 ~136 brown_glazed_terracotta 0
setblock ~134 ~2 ~134 log2 0
setblock ~134 ~2 ~136 soul_sand 0
setblock ~135 ~2 ~129 concrete 8
setblock ~135 ~2 ~130 brown_glazed_terracotta 0
setblock ~135 ~2 ~131 soul_sand 0
setblock ~135 ~2 ~132 mycelium 0
setblock ~136 ~2 ~130 gold_ore 0
setblock ~136 ~2 ~131 mycelium 0
fill ~221 ~2 ~66 ~222 ~2 ~66 gold_ore 0
setblock ~222 ~2 ~67 gold_ore 0
fill ~223 ~2 ~66 ~224 ~2 ~66 stained_hardened_clay 0
setblock ~223 ~2 ~68 gold_ore 0
fill ~224 ~2 ~70 ~224 ~3 ~70 gold_ore 0
fill ~225 ~2 ~66 ~227 ~2 ~66 gold_ore 0
setblock ~225 ~2 ~71 stained_hardened_clay 0
setblock ~226 ~2 ~72 gold_ore 0
setblock ~227 ~2 ~73 gold_ore 0
setblock ~228 ~2 ~66 stained_hardened_clay 0
setblock ~229 ~2 ~66 gold_ore 0
fill ~229 ~2 ~78 ~229 ~2 ~79 stained_hardened_clay 8
fill ~229 ~2 ~80 ~229 ~5 ~80 mycelium 0
fill ~230 ~2 ~65 ~232 ~2 ~65 gold_ore 0
setblock ~230 ~2 ~81 stained_hardened_clay 8
setblock ~230 ~2 ~82 brown_glazed_terracotta 0
fill ~231 ~2 ~83 ~231 ~3 ~83 log2 0
setblock ~233 ~2 ~65 brown_glazed_terracotta 0
fill ~234 ~2 ~65 ~235 ~2 ~65 gold_ore 0
fill ~235 ~2 ~87 ~236 ~2 ~87 gold_ore 0
setblock ~236 ~2 ~64 iron_ore 0
fill ~237 ~2 ~64 ~237 ~3 ~64 stained_hardened_clay 8
fill ~237 ~2 ~88 ~237 ~5 ~88 brown_glazed_terracotta 0
setblock ~238 ~2 ~64 mycelium 0
setblock ~238 ~2 ~89 brown_glazed_terracotta 0
setblock ~239 ~2 ~64 stained_hardened_clay 8
setblock ~239 ~2 ~88 brown_glazed_terracotta 0
fill ~240 ~2 ~89 ~241 ~2 ~89 mycelium 0
setblock ~242 ~2 ~65 brown_glazed_terracotta 0
fill ~243 ~2 ~90 ~244 ~2 ~90 mycelium 0
setblock ~244 ~2 ~66 log2 0
fill ~245 ~2 ~67 ~246 ~2 ~67 mycelium 0
setblock ~245 ~2 ~91 log2 0
setblock ~246 ~2 ~92 log2 0
fill ~247 ~2 ~68 ~247 ~5 ~68 mycelium 0
setblock ~247 ~2 ~69 iron_ore 0
setblock ~249 ~2 ~69 brown_glazed_terracotta 0
setblock ~249 ~2 ~72 gold_ore 0
fill ~249 ~2 ~90 ~249 ~2 ~91 gold_ore 0
setblock ~250 ~2 ~68 brown_glazed_terracotta 0
setblock ~250 ~2 ~69 concrete 8
setblock ~250 ~2 ~70 gold_ore 0
setblock ~250 ~2 ~72 log2 0
setblock ~250 ~2 ~89 gold_ore 0
setblock ~250 ~2 ~91 concrete 8
setblock ~251 ~2 ~69 wool 8
setblock ~251 ~2 ~71 gold_ore 0
setblock ~251 ~2 ~72 soul_sand 0
setblock ~251 ~2 ~91 wool 8
fill ~252 ~2 ~70 ~252 ~2 ~71 soul_sand 0
setblock ~252 ~2 ~72 mycelium 0
setblock ~252 ~2 ~86 iron_ore 0
setblock ~252 ~2 ~87 concrete 8
fill ~252 ~2 ~89 ~253 ~2 ~89 gold_ore 0
setblock ~252 ~2 ~91 iron_ore 0
setblock ~253 ~2 ~73 mycelium 0
setblock ~253 ~2 ~82 iron_ore 0
fill ~253 ~2 ~87 ~253 ~2 ~88 brown_glazed_terracotta 0
setblock ~253 ~2 ~91 brown_glazed_terracotta 0
setblock ~254 ~2 ~73 gold_ore 0
fill ~254 ~2 ~83 ~255 ~2 ~83 concrete 8
setblock ~254 ~2 ~87 soul_sand 0
setblock ~254 ~2 ~89 log2 0
fill ~254 ~2 ~90 ~254 ~2 ~91 soul_sand 0
setblock ~255 ~2 ~76 wool 8
setblock ~255 ~2 ~90 mycelium 0
fill ~256 ~2 ~75 ~256 ~3 ~75 stained_hardened_clay 7
setblock ~256 ~2 ~76 concrete 8
setblock ~256 ~2 ~78 soul_sand 0
setblock ~256 ~2 ~79 stained_hardened_clay 12
setblock ~256 ~2 ~80 mycelium 0
fill ~256 ~2 ~84 ~256 ~2 ~85 wool 8
setblock ~256 ~2 ~86 soul_sand 0
setblock ~256 ~2 ~87 mycelium 0
setblock ~256 ~2 ~88 brown_glazed_terracotta 0
setblock ~257 ~2 ~76 mycelium 0
setblock ~257 ~2 ~77 soul_sand 0
setblock ~257 ~2 ~80 concrete 8
fill ~257 ~2 ~81 ~257 ~4 ~81 stained_hardened_clay 15
fill ~257 ~2 ~85 ~257 ~3 ~85 stained_hardened_clay 15
setblock ~257 ~2 ~86 brown_glazed_terracotta 0
setblock ~258 ~2 ~77 concrete 8
setblock ~258 ~2 ~81 gold_ore 0
fill ~258 ~2 ~84 ~258 ~4 ~84 stained_hardened_clay 15
setblock ~259 ~2 ~77 wool 8
setblock ~260 ~2 ~78 gold_ore 0
setblock ~260 ~2 ~81 soul_sand 0
setblock ~261 ~2 ~79 mycelium 0
setblock ~261 ~2 ~80 soul_sand 0
fill ~98 ~3 ~125 ~98 ~4 ~125 soul_sand 0
fill ~99 ~3 ~122 ~99 ~3 ~124 soul_sand 0
setblock ~99 ~3 ~126 soul_sand 0
setblock ~99 ~3 ~127 brown_glazed_terracotta 0
fill ~100 ~3 ~119 ~100 ~3 ~120 mycelium 0
setblock ~100 ~3 ~121 soul_sand 0
setblock ~100 ~3 ~123 stained_hardened_clay 7
setblock ~100 ~3 ~124 soul_sand 0
setblock ~100 ~3 ~127 iron_ore 0
setblock ~101 ~3 ~117 bedrock 0
fill ~101 ~3 ~125 ~101 ~4 ~125 brown_glazed_terracotta 0
fill ~101 ~3 ~126 ~101 ~4 ~126 brown_glazed_terracotta 0
fill ~101 ~3 ~127 ~101 ~4 ~127 brown_glazed_terracotta 0
fill ~101 ~3 ~128 ~101 ~2 ~128 soul_sand 0
setblock ~102 ~3 ~116 mycelium 0
setblock ~102 ~3 ~128 iron_ore 0
setblock ~102 ~3 ~129 bedrock 0
setblock ~102 ~3 ~130 brown_glazed_terracotta 0
setblock ~103 ~3 ~115 mycelium 0
fill ~103 ~3 ~129 ~104 ~3 ~129 concrete 8 
setblock ~104 ~3 ~114 soul_sand 0
fill ~104 ~3 ~131 ~104 ~3 ~132 brown_glazed_terracotta 0
setblock ~105 ~3 ~113 soul_sand 0
setblock ~105 ~3 ~127 concrete 8
setblock ~105 ~3 ~130 iron_ore 0
fill ~105 ~3 ~131 ~105 ~3 ~132 soul_sand 0
setblock ~106 ~3 ~112 mycelium 0
setblock ~106 ~3 ~129 log2 0
setblock ~106 ~3 ~130 mycelium 0
setblock ~106 ~3 ~131 log2 0
setblock ~107 ~3 ~111 soul_sand 0
setblock ~107 ~3 ~112 brown_glazed_terracotta 0
setblock ~107 ~3 ~131 mycelium 0
fill ~108 ~3 ~110 ~108 ~3 ~111 mycelium 0
fill ~108 ~3 ~132 ~108 ~4 ~132 brown_glazed_terracotta 0
setblock ~109 ~3 ~111 wool 8
fill ~109 ~3 ~133 ~109 ~2 ~133 log2 0
setblock ~110 ~3 ~111 soul_sand 0
setblock ~110 ~3 ~133 brown_glazed_terracotta 0
setblock ~111 ~3 ~112 concrete 8
setblock ~111 ~3 ~134 stained_hardened_clay 8
setblock ~112 ~3 ~113 iron_ore 0
fill ~112 ~3 ~135 ~113 ~3 ~135 gold_ore 0
fill ~113 ~3 ~113 ~113 ~2 ~113 brown_glazed_terracotta 0
setblock ~114 ~3 ~114 iron_ore 0
setblock ~115 ~3 ~114 wool 8
setblock ~116 ~3 ~115 brown_glazed_terracotta 0
setblock ~116 ~3 ~137 mycelium 0
setblock ~117 ~3 ~115 soul_sand 0
fill ~117 ~3 ~137 ~118 ~3 ~137 brown_glazed_terracotta 0
fill ~118 ~3 ~115 ~118 ~4 ~115 brown_glazed_terracotta 0
setblock ~119 ~3 ~116 log2 0
fill ~119 ~3 ~138 ~123 ~3 ~138 mycelium 0
setblock ~120 ~3 ~117 brown_glazed_terracotta 0
setblock ~121 ~3 ~117 stained_hardened_clay 8
setblock ~122 ~3 ~118 gold_ore 0
setblock ~123 ~3 ~119 gold_ore 0
setblock ~123 ~3 ~137 mycelium 0
setblock ~124 ~3 ~120 log2 0
setblock ~124 ~3 ~121 mycelium 0
setblock ~124 ~3 ~136 mycelium 0
fill ~124 ~3 ~137 ~126 ~3 ~137 soul_sand 0
fill ~124 ~3 ~138 ~124 ~3 ~137 soul_sand 0
setblock ~125 ~3 ~122 log2 0
fill ~125 ~3 ~135 ~128 ~3 ~135 soul_sand 0
fill ~125 ~3 ~136 ~127 ~3 ~136 soul_sand 0
setblock ~125 ~3 ~138 brown_glazed_terracotta 0
setblock ~126 ~3 ~123 brown_glazed_terracotta 0
fill ~126 ~3 ~134 ~128 ~3 ~134 soul_sand 0
setblock ~126 ~3 ~138 iron_ore 0
fill ~126 ~3 ~139 ~126 ~3 ~140 wool 8
setblock ~127 ~3 ~124 mycelium 0
fill ~127 ~3 ~137 ~128 ~3 ~137 iron_ore 0
setblock ~127 ~3 ~140 iron_ore 0
setblock ~128 ~3 ~125 mycelium 0
fill ~128 ~3 ~133 ~129 ~3 ~133 soul_sand 0
fill ~128 ~3 ~138 ~128 ~3 ~139 brown_glazed_terracotta 0
setblock ~128 ~3 ~140 mycelium 0
setblock ~128 ~3 ~141 soul_sand 0
setblock ~129 ~3 ~126 mycelium 0
fill ~129 ~3 ~131 ~130 ~3 ~131 soul_sand 0
fill ~129 ~3 ~132 ~129 ~3 ~131 soul_sand 0
fill ~129 ~3 ~134 ~130 ~3 ~134 brown_glazed_terracotta 0
fill ~129 ~3 ~139 ~129 ~3 ~140 soul_sand 0
setblock ~130 ~3 ~127 mycelium 0
fill ~130 ~3 ~129 ~131 ~3 ~129 soul_sand 0
fill ~130 ~3 ~130 ~130 ~3 ~129 soul_sand 0
fill ~130 ~3 ~132 ~130 ~3 ~134 brown_glazed_terracotta 0
setblock ~130 ~3 ~135 wool 8
setblock ~131 ~3 ~128 mycelium 0
setblock ~131 ~3 ~130 log2 0
setblock ~131 ~3 ~131 brown_glazed_terracotta 0
setblock ~131 ~3 ~133 brown_glazed_terracotta 0
setblock ~131 ~3 ~134 log2 0
setblock ~131 ~3 ~135 concrete 8
fill ~132 ~3 ~128 ~132 ~3 ~129 iron_ore 0
setblock ~132 ~3 ~130 brown_glazed_terracotta 0
setblock ~132 ~3 ~131 mycelium 0
fill ~132 ~3 ~133 ~132 ~3 ~135 soul_sand 0
fill ~133 ~3 ~129 ~134 ~3 ~129 wool 8
setblock ~133 ~3 ~130 log2 0
fill ~133 ~3 ~131 ~134 ~3 ~131 soul_sand 0
setblock ~134 ~3 ~130 mycelium 0
fill ~220 ~3 ~65 ~220 ~3 ~66 stained_hardened_clay 0
fill ~221 ~3 ~65 ~223 ~3 ~65 gold_ore 0
fill ~221 ~3 ~67 ~221 ~4 ~67 gold_ore 0
setblock ~222 ~3 ~68 gold_ore 0
setblock ~223 ~3 ~69 gold_ore 0
setblock ~224 ~3 ~65 stained_hardened_clay 0
fill ~224 ~3 ~71 ~224 ~4 ~71 gold_ore 0
fill ~225 ~3 ~65 ~231 ~3 ~65 gold_ore 0
setblock ~225 ~3 ~72 gold_ore 0
setblock ~226 ~3 ~73 gold_ore 0
fill ~227 ~3 ~75 ~227 ~4 ~75 gold_ore 0
fill ~228 ~3 ~76 ~228 ~3 ~77 stained_hardened_clay 8
fill ~229 ~3 ~78 ~229 ~4 ~78 iron_ore 0
fill ~229 ~3 ~79 ~229 ~4 ~79 iron_ore 0
fill ~230 ~3 ~81 ~230 ~3 ~82 mycelium 0
fill ~232 ~3 ~64 ~234 ~3 ~64 gold_ore 0
setblock ~232 ~3 ~85 log2 0
fill ~235 ~3 ~64 ~237 ~3 ~64 stained_hardened_clay 8
fill ~235 ~3 ~87 ~236 ~3 ~87 gold_ore 0
setblock ~238 ~3 ~63 stained_hardened_clay 8
fill ~238 ~3 ~88 ~238 ~4 ~88 log2 0
setblock ~239 ~3 ~64 gold_ore 0
setblock ~239 ~3 ~88 soul_sand 0
fill ~240 ~3 ~89 ~240 ~4 ~89 soul_sand 0
fill ~241 ~3 ~89 ~242 ~3 ~89 mycelium 0
setblock ~242 ~3 ~65 log2 0
setblock ~243 ~3 ~66 mycelium 0
fill ~243 ~3 ~90 ~244 ~3 ~90 mycelium 0
fill ~244 ~3 ~66 ~244 ~4 ~66 soul_sand 0
fill ~245 ~3 ~67 ~246 ~3 ~67 mycelium 0
fill ~245 ~3 ~91 ~247 ~3 ~91 mycelium 0
setblock ~247 ~3 ~69 wool 8
fill ~247 ~3 ~70 ~249 ~3 ~70 iron_ore 0
setblock ~248 ~3 ~68 gold_ore 0
setblock ~248 ~3 ~69 iron_ore 0
fill ~248 ~3 ~71 ~251 ~3 ~71 brown_glazed_terracotta 0
setblock ~248 ~3 ~72 wool 8
setblock ~248 ~3 ~91 stained_hardened_clay 8
fill ~249 ~3 ~69 ~249 ~4 ~69 gold_ore 0
setblock ~249 ~3 ~72 brown_glazed_terracotta 0
fill ~249 ~3 ~88 ~249 ~3 ~89 brown_glazed_terracotta 0
setblock ~249 ~3 ~90 stained_hardened_clay 8
fill ~250 ~3 ~70 ~251 ~3 ~70 brown_glazed_terracotta 0
setblock ~250 ~3 ~89 iron_ore 0
setblock ~250 ~3 ~90 wool 8
fill ~251 ~3 ~87 ~251 ~3 ~88 concrete 8
setblock ~251 ~3 ~89 gold_ore 0
setblock ~251 ~3 ~90 iron_ore 0
fill ~252 ~3 ~72 ~252 ~4 ~72 soul_sand 0
fill ~252 ~3 ~83 ~253 ~3 ~83 iron_ore 0
setblock ~252 ~3 ~84 brown_glazed_terracotta 0
setblock ~252 ~3 ~85 iron_ore 0
setblock ~252 ~3 ~88 mycelium 0
setblock ~252 ~3 ~89 brown_glazed_terracotta 0
fill ~252 ~3 ~90 ~253 ~3 ~90 soul_sand 0
setblock ~253 ~3 ~73 brown_glazed_terracotta 0
setblock ~253 ~3 ~84 iron_ore 0
setblock ~253 ~3 ~85 brown_glazed_terracotta 0
setblock ~253 ~3 ~86 log2 0
setblock ~253 ~3 ~89 soul_sand 0
setblock ~254 ~3 ~73 stained_hardened_clay 0
fill ~254 ~3 ~84 ~255 ~3 ~84 wool 8
fill ~254 ~3 ~86 ~255 ~3 ~86 mycelium 0
fill ~254 ~3 ~89 ~255 ~3 ~89 gold_ore 0
setblock ~255 ~3 ~74 stained_hardened_clay 8
setblock ~255 ~3 ~77 iron_ore 0
setblock ~255 ~3 ~79 noteblock 0
setblock ~255 ~3 ~85 brown_glazed_terracotta 0
setblock ~255 ~3 ~87 log2 0
fill ~256 ~3 ~76 ~256 ~4 ~76 stained_hardened_clay 15
setblock ~256 ~3 ~77 brown_glazed_terracotta 0
setblock ~256 ~3 ~78 noteblock 0
setblock ~256 ~3 ~80 iron_ore 0
fill ~256 ~3 ~85 ~256 ~4 ~85 stained_hardened_clay 15
setblock ~257 ~3 ~77 concrete 8
setblock ~257 ~3 ~80 gold_ore 0
setblock ~258 ~3 ~77 wool 8
setblock ~258 ~3 ~80 log2 0
fill ~258 ~3 ~82 ~258 ~6 ~82 stained_hardened_clay 15
fill ~258 ~3 ~83 ~258 ~6 ~83 stained_hardened_clay 15
setblock ~259 ~3 ~78 mycelium 0
fill ~259 ~3 ~79 ~259 ~3 ~80 soul_sand 0
fill ~260 ~3 ~79 ~260 ~3 ~80 mycelium 0
setblock ~98 ~4 ~123 mycelium 0
setblock ~98 ~4 ~124 soul_sand 0
fill ~99 ~4 ~120 ~99 ~4 ~121 brown_glazed_terracotta 0
setblock ~99 ~4 ~122 log2 0
fill ~99 ~4 ~126 ~99 ~5 ~126 brown_glazed_terracotta 0
setblock ~100 ~4 ~117 mycelium 0
fill ~100 ~4 ~118 ~100 ~4 ~119 brown_glazed_terracotta 0
setblock ~100 ~4 ~123 soul_sand 0
setblock ~100 ~4 ~127 concrete 8
setblock ~101 ~4 ~116 brown_glazed_terracotta 0
setblock ~101 ~4 ~124 concrete 8
setblock ~102 ~4 ~115 brown_glazed_terracotta 0
setblock ~102 ~4 ~128 brown_glazed_terracotta 0
setblock ~102 ~4 ~129 wool 8
setblock ~103 ~4 ~114 brown_glazed_terracotta 0
setblock ~103 ~4 ~128 iron_ore 0
fill ~103 ~4 ~129 ~103 ~3 ~129 concrete 8
setblock ~103 ~4 ~130 iron_ore 0
setblock ~104 ~4 ~113 mycelium 0
setblock ~104 ~4 ~129 iron_ore 0
setblock ~104 ~4 ~130 soul_sand 0
fill ~105 ~4 ~112 ~106 ~4 ~112 soul_sand 0
fill ~105 ~4 ~129 ~106 ~4 ~129 soul_sand 0
setblock ~105 ~4 ~130 mycelium 0
setblock ~106 ~4 ~111 soul_sand 0
setblock ~106 ~4 ~127 stained_hardened_clay 0
setblock ~106 ~4 ~128 soul_sand 0
setblock ~106 ~4 ~130 brown_glazed_terracotta 0
setblock ~107 ~4 ~110 soul_sand 0
setblock ~107 ~4 ~131 soul_sand 0
setblock ~108 ~4 ~111 stained_hardened_clay 8
setblock ~109 ~4 ~111 concrete 8
setblock ~109 ~4 ~133 brown_glazed_terracotta 0
setblock ~110 ~4 ~112 mycelium 0
fill ~110 ~4 ~133 ~110 ~7 ~133 gold_ore 0
setblock ~111 ~4 ~112 soul_sand 0
fill ~111 ~4 ~134 ~111 ~7 ~134 gold_ore 0
setblock ~112 ~4 ~113 wool 8
fill ~112 ~4 ~135 ~113 ~4 ~135 gold_ore 0
setblock ~113 ~4 ~114 iron_ore 0
setblock ~114 ~4 ~114 wool 8
fill ~114 ~4 ~136 ~114 ~5 ~136 gold_ore 0
setblock ~115 ~4 ~114 brown_glazed_terracotta 0
setblock ~115 ~4 ~136 brown_glazed_terracotta 0
setblock ~116 ~4 ~114 log2 0
setblock ~116 ~4 ~137 soul_sand 0
setblock ~117 ~4 ~115 mycelium 0
setblock ~117 ~4 ~137 log2 0
setblock ~118 ~4 ~137 brown_glazed_terracotta 0
fill ~119 ~4 ~116 ~119 ~5 ~116 gold_ore 0
fill ~119 ~4 ~136 ~119 ~4 ~137 log2 0
setblock ~120 ~4 ~117 gold_ore 0
fill ~120 ~4 ~136 ~123 ~4 ~136 mycelium 0
setblock ~120 ~4 ~137 log2 0
setblock ~121 ~4 ~118 brown_glazed_terracotta 0
fill ~121 ~4 ~135 ~124 ~4 ~135 mycelium 0
fill ~121 ~4 ~137 ~122 ~4 ~137 mycelium 0
setblock ~122 ~4 ~119 gold_ore 0
fill ~123 ~4 ~120 ~123 ~4 ~121 gold_ore 0
fill ~123 ~4 ~134 ~125 ~4 ~134 mycelium 0
setblock ~124 ~4 ~122 mycelium 0
fill ~124 ~4 ~133 ~125 ~4 ~133 mycelium 0
setblock ~125 ~4 ~123 log2 0
setblock ~126 ~4 ~124 brown_glazed_terracotta 0
fill ~126 ~4 ~132 ~128 ~4 ~132 soul_sand 0
fill ~126 ~4 ~133 ~127 ~4 ~133 soul_sand 0
setblock ~127 ~4 ~125 log2 0
setblock ~127 ~4 ~130 mycelium 0
fill ~127 ~4 ~131 ~128 ~4 ~131 soul_sand 0
fill ~127 ~4 ~138 ~127 ~4 ~139 brown_glazed_terracotta 0
fill ~128 ~4 ~126 ~128 ~4 ~128 mycelium 0
fill ~128 ~4 ~129 ~129 ~4 ~129 soul_sand 0
fill ~128 ~4 ~130 ~129 ~4 ~130 soul_sand 0
setblock ~129 ~4 ~127 mycelium 0
fill ~129 ~4 ~128 ~130 ~4 ~128 soul_sand 0
fill ~219 ~4 ~65 ~219 ~5 ~65 brown_glazed_terracotta 0
setblock ~220 ~4 ~65 gold_ore 0
setblock ~220 ~4 ~66 stained_hardened_clay 0
fill ~221 ~4 ~64 ~224 ~4 ~64 gold_ore 0
setblock ~221 ~4 ~68 gold_ore 0
setblock ~222 ~4 ~69 brown_glazed_terracotta 0
setblock ~223 ~4 ~70 gold_ore 0
setblock ~224 ~4 ~72 gold_ore 0
setblock ~225 ~4 ~64 brown_glazed_terracotta 0
setblock ~225 ~4 ~73 brown_glazed_terracotta 0
fill ~226 ~4 ~64 ~229 ~4 ~64 gold_ore 0
setblock ~226 ~4 ~74 brown_glazed_terracotta 0
setblock ~227 ~4 ~76 iron_ore 0
setblock ~228 ~4 ~77 stained_hardened_clay 8
fill ~230 ~4 ~64 ~231 ~4 ~64 brown_glazed_terracotta 0
setblock ~230 ~4 ~81 soul_sand 0
fill ~230 ~4 ~82 ~230 ~5 ~82 mycelium 0
fill ~231 ~4 ~83 ~231 ~5 ~83 mycelium 0
setblock ~231 ~4 ~84 log2 0
fill ~232 ~4 ~64 ~233 ~4 ~64 gold_ore 0
fill ~232 ~4 ~84 ~232 ~5 ~84 brown_glazed_terracotta 0
setblock ~233 ~4 ~85 log2 0
setblock ~234 ~4 ~63 iron_ore 0
setblock ~234 ~4 ~86 log2 0
fill ~235 ~4 ~63 ~236 ~4 ~63 stained_hardened_clay 8
fill ~235 ~4 ~87 ~235 ~0 ~87 gold_ore 0
setblock ~236 ~4 ~87 log2 0
setblock ~237 ~4 ~63 brown_glazed_terracotta 0
setblock ~238 ~4 ~64 mycelium 0
setblock ~239 ~4 ~64 brown_glazed_terracotta 0
fill ~239 ~4 ~89 ~239 ~5 ~89 soul_sand 0
fill ~241 ~4 ~89 ~241 ~2 ~89 mycelium 0
setblock ~242 ~4 ~65 brown_glazed_terracotta 0
fill ~242 ~4 ~89 ~242 ~8 ~89 soul_sand 0
fill ~243 ~4 ~66 ~243 ~6 ~66 soul_sand 0
fill ~243 ~4 ~90 ~244 ~4 ~90 mycelium 0
fill ~245 ~4 ~67 ~246 ~4 ~67 soul_sand 0
fill ~245 ~4 ~91 ~247 ~4 ~91 mycelium 0
setblock ~248 ~4 ~68 mycelium 0
setblock ~248 ~4 ~90 mycelium 0
fill ~249 ~4 ~89 ~250 ~4 ~89 mycelium 0
fill ~250 ~4 ~70 ~250 ~5 ~70 gold_ore 0
setblock ~250 ~4 ~88 log2 0
fill ~251 ~4 ~71 ~251 ~5 ~71 brown_glazed_terracotta 0
setblock ~251 ~4 ~89 brown_glazed_terracotta 0
setblock ~252 ~4 ~89 gold_ore 0
fill ~253 ~4 ~73 ~254 ~4 ~73 log2 0
fill ~253 ~4 ~90 ~253 ~5 ~90 gold_ore 0
setblock ~254 ~4 ~85 brown_glazed_terracotta 0
fill ~254 ~4 ~89 ~254 ~3 ~89 gold_ore 0
setblock ~255 ~4 ~74 concrete 8
fill ~255 ~4 ~75 ~255 ~5 ~75 iron_ore 0
setblock ~255 ~4 ~78 soul_sand 0
fill ~255 ~4 ~79 ~255 ~5 ~79 stained_hardened_clay 7
fill ~255 ~4 ~86 ~255 ~5 ~86 gold_ore 0
fill ~255 ~4 ~87 ~255 ~5 ~87 gold_ore 0
setblock ~255 ~4 ~89 log2 0
setblock ~256 ~4 ~77 stained_hardened_clay 15
fill ~256 ~4 ~78 ~258 ~4 ~78 brown_glazed_terracotta 0
setblock ~256 ~4 ~79 concrete 8
setblock ~256 ~4 ~80 noteblock 0
setblock ~257 ~4 ~79 log2 0
fill ~257 ~4 ~84 ~257 ~5 ~84 stained_hardened_clay 15
setblock ~258 ~4 ~79 soul_sand 0
setblock ~258 ~4 ~80 stained_hardened_clay 12
fill ~98 ~5 ~121 ~98 ~5 ~122 brown_glazed_terracotta 0
setblock ~98 ~5 ~123 log2 0
fill ~98 ~5 ~124 ~98 ~5 ~125 mycelium 0
fill ~99 ~5 ~118 ~99 ~5 ~120 iron_ore 0
fill ~100 ~5 ~116 ~100 ~5 ~117 brown_glazed_terracotta 0
fill ~100 ~5 ~126 ~100 ~6 ~126 stained_hardened_clay 8
setblock ~101 ~5 ~115 iron_ore 0
fill ~101 ~5 ~124 ~101 ~5 ~125 concrete 8
setblock ~101 ~5 ~127 stained_hardened_clay 8
setblock ~102 ~5 ~114 iron_ore 0
fill ~102 ~5 ~125 ~102 ~5 ~126 iron_ore 0
setblock ~102 ~5 ~127 wool 8
setblock ~102 ~5 ~128 gold_ore 0
setblock ~103 ~5 ~113 brown_glazed_terracotta 0
fill ~103 ~5 ~127 ~104 ~5 ~127 brown_glazed_terracotta 0
fill ~103 ~5 ~128 ~104 ~5 ~128 brown_glazed_terracotta 0
setblock ~104 ~5 ~112 mycelium 0
setblock ~104 ~5 ~129 soul_sand 0
setblock ~105 ~5 ~111 mycelium 0
setblock ~105 ~5 ~127 mycelium 0
setblock ~105 ~5 ~128 soul_sand 0
setblock ~105 ~5 ~129 mycelium 0
setblock ~106 ~5 ~110 mycelium 0
setblock ~106 ~5 ~130 log2 0
fill ~107 ~5 ~111 ~108 ~5 ~111 brown_glazed_terracotta 0
fill ~107 ~5 ~131 ~107 ~8 ~131 gold_ore 0
fill ~108 ~5 ~132 ~109 ~5 ~132 gold_ore 0
setblock ~109 ~5 ~112 log2 0
setblock ~110 ~5 ~112 gold_ore 0
fill ~111 ~5 ~113 ~111 ~6 ~113 brown_glazed_terracotta 0
setblock ~112 ~5 ~113 soul_sand 0
setblock ~112 ~5 ~134 brown_glazed_terracotta 0
setblock ~113 ~5 ~114 soul_sand 0
fill ~113 ~5 ~135 ~113 ~6 ~135 gold_ore 0
fill ~114 ~5 ~114 ~115 ~5 ~114 mycelium 0
setblock ~115 ~5 ~136 gold_ore 0
fill ~116 ~5 ~114 ~116 ~7 ~114 gold_ore 0
setblock ~116 ~5 ~136 brown_glazed_terracotta 0
setblock ~117 ~5 ~115 brown_glazed_terracotta 0
setblock ~117 ~5 ~135 brown_glazed_terracotta 0
fill ~117 ~5 ~136 ~118 ~5 ~136 log2 0
setblock ~118 ~5 ~115 gold_ore 0
setblock ~118 ~5 ~135 mycelium 0
setblock ~119 ~5 ~117 gold_ore 0
setblock ~119 ~5 ~134 mycelium 0
fill ~119 ~5 ~135 ~120 ~5 ~135 log2 0
setblock ~120 ~5 ~118 gold_ore 0
setblock ~120 ~5 ~134 log2 0
setblock ~121 ~5 ~119 brown_glazed_terracotta 0
fill ~121 ~5 ~133 ~121 ~5 ~134 mycelium 0
setblock ~122 ~5 ~120 gold_ore 0
fill ~122 ~5 ~133 ~123 ~5 ~133 soul_sand 0
fill ~122 ~5 ~134 ~122 ~5 ~133 soul_sand 0
fill ~123 ~5 ~121 ~123 ~5 ~122 gold_ore 0
fill ~123 ~5 ~132 ~125 ~5 ~132 soul_sand 0
setblock ~124 ~5 ~123 log2 0
setblock ~125 ~5 ~124 log2 0
fill ~125 ~5 ~131 ~126 ~5 ~131 soul_sand 0
fill ~126 ~5 ~125 ~126 ~5 ~126 mycelium 0
fill ~126 ~5 ~127 ~127 ~5 ~127 soul_sand 0
fill ~126 ~5 ~128 ~127 ~5 ~128 soul_sand 0
fill ~126 ~5 ~129 ~127 ~5 ~129 soul_sand 0
fill ~126 ~5 ~130 ~126 ~5 ~127 soul_sand 0
setblock ~127 ~5 ~126 soul_sand 0
setblock ~218 ~5 ~64 brown_glazed_terracotta 0
setblock ~219 ~5 ~64 stained_hardened_clay 8
fill ~219 ~5 ~66 ~219 ~6 ~66 gold_ore 0
fill ~220 ~5 ~64 ~221 ~5 ~64 gold_ore 0
setblock ~220 ~5 ~67 stained_hardened_clay 0
setblock ~221 ~5 ~68 stained_hardened_clay 0
fill ~222 ~5 ~64 ~223 ~5 ~64 concrete 8
setblock ~222 ~5 ~69 stained_hardened_clay 8
setblock ~222 ~5 ~70 brown_glazed_terracotta 0
setblock ~223 ~5 ~71 gold_ore 0
setblock ~224 ~5 ~64 stained_hardened_clay 0
setblock ~224 ~5 ~72 stained_hardened_clay 8
setblock ~224 ~5 ~73 gold_ore 0
fill ~225 ~5 ~64 ~225 ~6 ~64 gold_ore 0
setblock ~225 ~5 ~74 gold_ore 0
fill ~226 ~5 ~63 ~227 ~5 ~63 brown_glazed_terracotta 0
setblock ~226 ~5 ~75 mycelium 0
fill ~227 ~5 ~76 ~227 ~5 ~77 stained_hardened_clay 8
fill ~228 ~5 ~63 ~231 ~5 ~63 gold_ore 0
setblock ~228 ~5 ~78 iron_ore 0
setblock ~229 ~5 ~79 mycelium 0
fill ~230 ~5 ~81 ~230 ~6 ~81 mycelium 0
setblock ~230 ~5 ~83 mycelium 0
setblock ~232 ~5 ~63 brown_glazed_terracotta 0
setblock ~233 ~5 ~63 mycelium 0
setblock ~233 ~5 ~85 gold_ore 0
setblock ~234 ~5 ~63 wool 8
setblock ~234 ~5 ~86 brown_glazed_terracotta 0
fill ~235 ~5 ~63 ~235 ~4 ~63 stained_hardened_clay 8
fill ~235 ~5 ~86 ~235 ~6 ~86 gold_ore 0 
setblock ~236 ~5 ~63 brown_glazed_terracotta 0
fill ~236 ~5 ~87 ~236 ~6 ~87 brown_glazed_terracotta 0
setblock ~237 ~5 ~63 gold_ore 0
fill ~238 ~5 ~64 ~238 ~7 ~64 brown_glazed_terracotta 0
fill ~238 ~5 ~88 ~238 ~6 ~88 soul_sand 0
fill ~239 ~5 ~64 ~239 ~6 ~64 gold_ore 0
setblock ~240 ~5 ~65 brown_glazed_terracotta 0
setblock ~240 ~5 ~89 mycelium 0
setblock ~241 ~5 ~65 gold_ore 0
fill ~241 ~5 ~89 ~241 ~8 ~89 soul_sand 0
setblock ~242 ~5 ~65 soul_sand 0
fill ~243 ~5 ~90 ~244 ~5 ~90 mycelium 0
fill ~244 ~5 ~67 ~245 ~5 ~67 soul_sand 0
fill ~245 ~5 ~91 ~247 ~5 ~91 mycelium 0
setblock ~246 ~5 ~68 mycelium 0
fill ~247 ~5 ~90 ~247 ~6 ~90 mycelium 0
fill ~248 ~5 ~69 ~249 ~5 ~69 mycelium 0
fill ~248 ~5 ~89 ~250 ~5 ~89 mycelium 0
setblock ~251 ~5 ~89 stained_hardened_clay 8
setblock ~252 ~5 ~72 mycelium 0
setblock ~252 ~5 ~90 stained_hardened_clay 8
fill ~253 ~5 ~73 ~253 ~6 ~73 brown_glazed_terracotta 0
setblock ~254 ~5 ~73 stained_hardened_clay 8
fill ~254 ~5 ~74 ~254 ~6 ~74 mycelium 0
setblock ~254 ~5 ~90 brown_glazed_terracotta 0
fill ~255 ~5 ~76 ~255 ~6 ~76 stained_hardened_clay 8
setblock ~255 ~5 ~77 soul_sand 0
setblock ~255 ~5 ~78 stained_hardened_clay 7
setblock ~255 ~5 ~85 soul_sand 0
setblock ~255 ~5 ~89 brown_glazed_terracotta 0
setblock ~256 ~5 ~80 stained_hardened_clay 12
setblock ~256 ~5 ~84 stained_hardened_clay 15
setblock ~257 ~5 ~81 soul_sand 0
fill ~97 ~6 ~121 ~97 ~6 ~122 brown_glazed_terracotta 0
setblock ~98 ~6 ~118 brown_glazed_terracotta 0
setblock ~98 ~6 ~119 gold_ore 0
setblock ~98 ~6 ~120 brown_glazed_terracotta 0
fill ~98 ~6 ~123 ~98 ~6 ~125 brown_glazed_terracotta 0
fill ~99 ~6 ~116 ~99 ~6 ~117 brown_glazed_terracotta 0
setblock ~99 ~6 ~125 brown_glazed_terracotta 0
setblock ~100 ~6 ~115 brown_glazed_terracotta 0
setblock ~101 ~6 ~114 gold_ore 0
setblock ~101 ~6 ~127 gold_ore 0
setblock ~102 ~6 ~113 brown_glazed_terracotta 0
setblock ~102 ~6 ~127 stained_hardened_clay 8
setblock ~103 ~6 ~112 log2 0
fill ~103 ~6 ~126 ~104 ~6 ~126 brown_glazed_terracotta 0
setblock ~103 ~6 ~128 log2 0
fill ~104 ~6 ~110 ~106 ~6 ~110 brown_glazed_terracotta 0
setblock ~104 ~6 ~111 log2 0
setblock ~104 ~6 ~128 brown_glazed_terracotta 0
setblock ~105 ~6 ~129 brown_glazed_terracotta 0
fill ~106 ~6 ~130 ~106 ~9 ~130 gold_ore 0
fill ~107 ~6 ~111 ~107 ~5 ~111 brown_glazed_terracotta 0
setblock ~108 ~6 ~112 log2 0
setblock ~108 ~6 ~132 brown_glazed_terracotta 0
setblock ~109 ~6 ~112 gold_ore 0
setblock ~109 ~6 ~132 gold_ore 0
setblock ~110 ~6 ~113 gold_ore 0
setblock ~112 ~6 ~113 log2 0
fill ~112 ~6 ~134 ~112 ~7 ~134 gold_ore 0
setblock ~113 ~6 ~113 mycelium 0
setblock ~114 ~6 ~113 brown_glazed_terracotta 0
fill ~114 ~6 ~135 ~116 ~6 ~135 gold_ore 0
setblock ~115 ~6 ~114 brown_glazed_terracotta 0
fill ~115 ~6 ~134 ~116 ~6 ~134 gold_ore 0
setblock ~117 ~6 ~115 gold_ore 0
fill ~117 ~6 ~133 ~118 ~6 ~133 brown_glazed_terracotta 0
fill ~117 ~6 ~134 ~117 ~6 ~133 brown_glazed_terracotta 0
fill ~118 ~6 ~116 ~118 ~6 ~117 gold_ore 0
setblock ~118 ~6 ~134 log2 0
setblock ~119 ~6 ~118 gold_ore 0
fill ~119 ~6 ~132 ~119 ~6 ~133 log2 0
setblock ~120 ~6 ~119 gold_ore 0
fill ~120 ~6 ~132 ~122 ~6 ~132 mycelium 0
fill ~120 ~6 ~133 ~120 ~6 ~132 mycelium 0
setblock ~121 ~6 ~120 gold_ore 0
setblock ~121 ~6 ~131 mycelium 0
fill ~122 ~6 ~121 ~122 ~6 ~122 gold_ore 0
fill ~122 ~6 ~131 ~124 ~6 ~131 soul_sand 0
setblock ~123 ~6 ~123 gold_ore 0
fill ~123 ~6 ~130 ~124 ~6 ~130 mycelium 0
setblock ~124 ~6 ~124 log2 0
fill ~124 ~6 ~125 ~125 ~6 ~125 mycelium 0
fill ~124 ~6 ~127 ~125 ~6 ~127 soul_sand 0
fill ~124 ~6 ~128 ~125 ~6 ~128 soul_sand 0
fill ~124 ~6 ~129 ~125 ~6 ~129 soul_sand 0
setblock ~125 ~6 ~126 soul_sand 0
setblock ~125 ~6 ~130 soul_sand 0
setblock ~218 ~6 ~64 iron_ore 0
fill ~218 ~6 ~65 ~218 ~7 ~65 gold_ore 0
fill ~219 ~6 ~64 ~221 ~6 ~64 gold_ore 0
setblock ~220 ~6 ~67 gold_ore 0
setblock ~220 ~6 ~68 stained_hardened_clay 0
fill ~221 ~6 ~69 ~221 ~7 ~69 gold_ore 0
fill ~222 ~6 ~64 ~222 ~5 ~64 concrete 8
setblock ~222 ~6 ~70 gold_ore 0
setblock ~222 ~6 ~71 mycelium 0
fill ~223 ~6 ~64 ~225 ~6 ~64 gold_ore 0
setblock ~223 ~6 ~72 brown_glazed_terracotta 0
setblock ~224 ~6 ~73 brown_glazed_terracotta 0
setblock ~225 ~6 ~74 wool 8
fill ~225 ~6 ~75 ~225 ~7 ~75 stained_hardened_clay 8
setblock ~226 ~6 ~64 brown_glazed_terracotta 0
setblock ~226 ~6 ~76 stained_hardened_clay 8
setblock ~227 ~6 ~63 log2 0
fill ~227 ~6 ~77 ~227 ~6 ~78 stained_hardened_clay 8
fill ~228 ~6 ~63 ~229 ~6 ~63 brown_glazed_terracotta 0
setblock ~228 ~6 ~79 stained_hardened_clay 8
setblock ~229 ~6 ~80 soul_sand 0
setblock ~230 ~6 ~62 stained_hardened_clay 8
setblock ~230 ~6 ~82 soul_sand 0
setblock ~231 ~6 ~62 gold_ore 0
fill ~231 ~6 ~83 ~231 ~7 ~83 stained_hardened_clay 8
setblock ~232 ~6 ~62 iron_ore 0
setblock ~232 ~6 ~84 stained_hardened_clay 8
fill ~233 ~6 ~62 ~235 ~6 ~62 stained_hardened_clay 8
setblock ~233 ~6 ~85 brown_glazed_terracotta 0
setblock ~234 ~6 ~85 log2 0
fill ~236 ~6 ~63 ~236 ~7 ~63 mycelium 0
setblock ~237 ~6 ~63 brown_glazed_terracotta 0
fill ~237 ~6 ~87 ~237 ~8 ~87 soul_sand 0
fill ~239 ~6 ~88 ~239 ~8 ~88 soul_sand 0
setblock ~240 ~6 ~65 log2 0
setblock ~240 ~6 ~89 soul_sand 0
setblock ~241 ~6 ~65 soul_sand 0
fill ~242 ~6 ~66 ~242 ~7 ~66 soul_sand 0
fill ~243 ~6 ~90 ~247 ~6 ~90 mycelium 0
fill ~244 ~6 ~67 ~245 ~6 ~67 soul_sand 0
fill ~246 ~6 ~68 ~246 ~7 ~68 soul_sand 0
fill ~247 ~6 ~69 ~248 ~6 ~69 mycelium 0
fill ~248 ~6 ~89 ~250 ~6 ~89 mycelium 0
fill ~249 ~6 ~70 ~250 ~6 ~70 mycelium 0
fill ~251 ~6 ~71 ~251 ~7 ~71 mycelium 0
fill ~251 ~6 ~90 ~252 ~6 ~90 mycelium 0
setblock ~252 ~6 ~72 log2 0
setblock ~253 ~6 ~90 log2 0
setblock ~254 ~6 ~75 mycelium 0
fill ~254 ~6 ~85 ~255 ~6 ~85 noteblock 0
fill ~254 ~6 ~86 ~254 ~6 ~87 mycelium 0
fill ~254 ~6 ~88 ~254 ~6 ~89 log2 0
setblock ~254 ~6 ~90 mycelium 0
setblock ~255 ~6 ~77 stained_hardened_clay 8
fill ~255 ~6 ~78 ~255 ~9 ~78 mycelium 0
fill ~256 ~6 ~79 ~256 ~8 ~79 soul_sand 0
setblock ~256 ~6 ~84 soul_sand 0
setblock ~257 ~6 ~80 stained_hardened_clay 12
fill ~257 ~6 ~83 ~257 ~7 ~83 stained_hardened_clay 12
setblock ~258 ~6 ~81 soul_sand 0
fill ~97 ~7 ~119 ~97 ~9 ~119 gold_ore 0
fill ~97 ~7 ~120 ~97 ~8 ~120 stained_hardened_clay 8
fill ~97 ~7 ~121 ~97 ~8 ~121 log2 0
fill ~97 ~7 ~122 ~97 ~9 ~122 stained_hardened_clay 8
fill ~97 ~7 ~123 ~97 ~9 ~123 stained_hardened_clay 8
fill ~98 ~7 ~116 ~98 ~8 ~116 gold_ore 0
fill ~98 ~7 ~117 ~98 ~7 ~118 gold_ore 0
fill ~98 ~7 ~124 ~98 ~7 ~125 stained_hardened_clay 8
setblock ~99 ~7 ~115 gold_ore 0
fill ~99 ~7 ~125 ~99 ~8 ~125 stained_hardened_clay 8
setblock ~100 ~7 ~114 gold_ore 0
setblock ~100 ~7 ~126 brown_glazed_terracotta 0
setblock ~101 ~7 ~113 brown_glazed_terracotta 0
setblock ~101 ~7 ~126 gold_ore 0
setblock ~102 ~7 ~112 log2 0
setblock ~102 ~7 ~127 brown_glazed_terracotta 0
fill ~103 ~7 ~110 ~103 ~7 ~111 log2 0
setblock ~103 ~7 ~128 brown_glazed_terracotta 0
fill ~104 ~7 ~110 ~105 ~7 ~110 stained_hardened_clay 8
setblock ~104 ~7 ~129 brown_glazed_terracotta 0
fill ~105 ~7 ~129 ~105 ~10 ~129 gold_ore 0
fill ~106 ~7 ~111 ~107 ~7 ~111 stained_hardened_clay 8
fill ~108 ~7 ~112 ~109 ~7 ~112 brown_glazed_terracotta 0
setblock ~108 ~7 ~132 gold_ore 0
setblock ~109 ~7 ~132 brown_glazed_terracotta 0
fill ~110 ~7 ~112 ~110 ~8 ~112 gold_ore 0
fill ~111 ~7 ~112 ~112 ~7 ~112 brown_glazed_terracotta 0
setblock ~113 ~7 ~113 brown_glazed_terracotta 0
fill ~113 ~7 ~134 ~114 ~7 ~134 stained_hardened_clay 8
fill ~114 ~7 ~113 ~114 ~8 ~113 gold_ore 0
fill ~114 ~7 ~133 ~115 ~7 ~133 stained_hardened_clay 8
fill ~115 ~7 ~114 ~115 ~8 ~114 gold_ore 0
setblock ~115 ~7 ~132 mycelium 0
setblock ~116 ~7 ~115 gold_ore 0
fill ~116 ~7 ~132 ~118 ~7 ~132 stained_hardened_clay 8
setblock ~116 ~7 ~133 gold_ore 0
fill ~117 ~7 ~116 ~117 ~7 ~117 gold_ore 0
fill ~117 ~7 ~131 ~118 ~7 ~131 stained_hardened_clay 8
setblock ~118 ~7 ~118 brown_glazed_terracotta 0
setblock ~119 ~7 ~119 gold_ore 0
fill ~119 ~7 ~130 ~122 ~7 ~130 mycelium 0
fill ~119 ~7 ~131 ~120 ~7 ~131 mycelium 0
setblock ~120 ~7 ~120 gold_ore 0
fill ~121 ~7 ~121 ~121 ~7 ~122 stained_hardened_clay 8
fill ~122 ~7 ~123 ~122 ~7 ~124 stained_hardened_clay 8
fill ~122 ~7 ~127 ~122 ~7 ~130 mycelium 0
fill ~123 ~7 ~124 ~123 ~7 ~126 mycelium 0
setblock ~123 ~7 ~127 soul_sand 0
fill ~123 ~7 ~128 ~123 ~7 ~129 mycelium 0
setblock ~124 ~7 ~126 mycelium 0
fill ~217 ~7 ~63 ~217 ~8 ~63 brown_glazed_terracotta 0
fill ~217 ~7 ~64 ~217 ~8 ~64 brown_glazed_terracotta 0
setblock ~218 ~7 ~63 iron_ore 0
fill ~219 ~7 ~63 ~219 ~8 ~63 gold_ore 0
setblock ~219 ~7 ~66 concrete 8
fill ~219 ~7 ~67 ~219 ~8 ~67 gold_ore 0
setblock ~220 ~7 ~64 concrete 8
setblock ~220 ~7 ~68 gold_ore 0
fill ~221 ~7 ~64 ~222 ~7 ~64 gold_ore 0
fill ~221 ~7 ~70 ~221 ~8 ~70 gold_ore 0
setblock ~222 ~7 ~71 gold_ore 0
setblock ~223 ~7 ~64 brown_glazed_terracotta 0
fill ~223 ~7 ~72 ~223 ~7 ~73 log2 0
setblock ~224 ~7 ~64 gold_ore 0
setblock ~224 ~7 ~74 stained_hardened_clay 8
fill ~225 ~7 ~64 ~225 ~8 ~64 brown_glazed_terracotta 0
setblock ~226 ~7 ~64 stained_hardened_clay 8
fill ~226 ~7 ~76 ~226 ~7 ~77 wool 8
setblock ~227 ~7 ~64 log2 0
fill ~227 ~7 ~78 ~227 ~8 ~78 mycelium 0
fill ~228 ~7 ~63 ~229 ~7 ~63 log2 0
setblock ~228 ~7 ~79 mycelium 0
setblock ~228 ~7 ~80 soul_sand 0
fill ~229 ~7 ~81 ~229 ~8 ~81 soul_sand 0
setblock ~230 ~7 ~63 stained_hardened_clay 8
setblock ~230 ~7 ~82 mycelium 0
setblock ~231 ~7 ~62 stained_hardened_clay 8
fill ~232 ~7 ~62 ~232 ~8 ~62 mycelium 0
setblock ~232 ~7 ~84 mycelium 0
fill ~233 ~7 ~62 ~234 ~7 ~62 stained_hardened_clay 8
setblock ~233 ~7 ~84 log2 0
fill ~234 ~7 ~85 ~234 ~8 ~85 brown_glazed_terracotta 0
setblock ~235 ~7 ~63 log2 0
setblock ~235 ~7 ~86 log2 0
fill ~236 ~7 ~86 ~236 ~8 ~86 soul_sand 0
fill ~237 ~7 ~64 ~237 ~8 ~64 brown_glazed_terracotta 0
fill ~238 ~7 ~87 ~238 ~8 ~87 soul_sand 0
fill ~239 ~7 ~65 ~240 ~7 ~65 soul_sand 0
fill ~240 ~7 ~88 ~240 ~8 ~88 soul_sand 0
fill ~241 ~7 ~66 ~241 ~8 ~66 soul_sand 0
fill ~243 ~7 ~67 ~244 ~7 ~67 soul_sand 0
fill ~243 ~7 ~90 ~246 ~7 ~90 mycelium 0
fill ~245 ~7 ~68 ~245 ~8 ~68 soul_sand 0
fill ~247 ~7 ~69 ~247 ~6 ~69 mycelium 0
fill ~247 ~7 ~89 ~250 ~7 ~89 mycelium 0
fill ~248 ~7 ~70 ~249 ~7 ~70 mycelium 0
fill ~250 ~7 ~71 ~250 ~8 ~71 mycelium 0
fill ~251 ~7 ~90 ~252 ~7 ~90 mycelium 0
setblock ~252 ~7 ~72 mycelium 0
setblock ~253 ~7 ~73 log2 0
setblock ~253 ~7 ~74 brown_glazed_terracotta 0
fill ~253 ~7 ~90 ~254 ~7 ~90 soul_sand 0
setblock ~254 ~7 ~75 log2 0
fill ~254 ~7 ~76 ~254 ~8 ~76 mycelium 0
fill ~254 ~7 ~77 ~254 ~9 ~77 mycelium 0
fill ~254 ~7 ~85 ~254 ~7 ~86 soul_sand 0
fill ~254 ~7 ~87 ~254 ~7 ~88 mycelium 0
setblock ~254 ~7 ~89 soul_sand 0
fill ~255 ~7 ~84 ~256 ~7 ~84 stained_hardened_clay 12
setblock ~257 ~7 ~80 stained_hardened_clay 7
setblock ~258 ~7 ~81 stained_hardened_clay 12
setblock ~258 ~7 ~82 soul_sand 0
fill ~97 ~8 ~117 ~97 ~9 ~117 gold_ore 0
fill ~97 ~8 ~118 ~97 ~8 ~117 gold_ore 0
setblock ~98 ~8 ~115 gold_ore 0
setblock ~98 ~8 ~124 gold_ore 0
setblock ~99 ~8 ~114 gold_ore 0
setblock ~100 ~8 ~113 gold_ore 0
fill ~100 ~8 ~125 ~100 ~11 ~125 gold_ore 0
setblock ~101 ~8 ~112 gold_ore 0
setblock ~101 ~8 ~126 brown_glazed_terracotta 0
fill ~102 ~8 ~110 ~102 ~8 ~111 gold_ore 0
setblock ~102 ~8 ~127 gold_ore 0
setblock ~103 ~8 ~109 log2 0
fill ~103 ~8 ~128 ~103 ~10 ~128 gold_ore 0
fill ~104 ~8 ~110 ~104 ~9 ~110 stained_hardened_clay 8
fill ~104 ~8 ~129 ~104 ~9 ~129 gold_ore 0
fill ~105 ~8 ~111 ~107 ~8 ~111 gold_ore 0
setblock ~108 ~8 ~112 gold_ore 0
setblock ~108 ~8 ~131 gold_ore 0
setblock ~109 ~8 ~112 brown_glazed_terracotta 0
setblock ~109 ~8 ~132 gold_ore 0
setblock ~110 ~8 ~132 brown_glazed_terracotta 0
fill ~111 ~8 ~112 ~111 ~7 ~112 brown_glazed_terracotta 0
fill ~111 ~8 ~133 ~113 ~8 ~133 log2 0
fill ~112 ~8 ~112 ~113 ~8 ~112 gold_ore 0
setblock ~112 ~8 ~132 noteblock 0
fill ~113 ~8 ~132 ~114 ~8 ~132 mycelium 0
fill ~114 ~8 ~131 ~116 ~8 ~131 mycelium 0
setblock ~115 ~8 ~115 gold_ore 0
fill ~116 ~8 ~116 ~116 ~8 ~117 brown_glazed_terracotta 0
setblock ~116 ~8 ~130 soul_sand 0
setblock ~117 ~8 ~118 gold_ore 0
fill ~117 ~8 ~130 ~118 ~8 ~130 mycelium 0
setblock ~118 ~8 ~119 log2 0
fill ~118 ~8 ~129 ~121 ~8 ~129 mycelium 0
setblock ~119 ~8 ~120 mycelium 0
fill ~120 ~8 ~121 ~120 ~8 ~123 mycelium 0
fill ~120 ~8 ~128 ~121 ~8 ~128 mycelium 0
fill ~121 ~8 ~122 ~121 ~8 ~129 mycelium 0
fill ~122 ~8 ~125 ~122 ~8 ~126 mycelium 0
setblock ~216 ~8 ~63 brown_glazed_terracotta 0
fill ~217 ~8 ~65 ~217 ~9 ~65 brown_glazed_terracotta 0
fill ~218 ~8 ~63 ~218 ~9 ~63 brown_glazed_terracotta 0
fill ~218 ~8 ~66 ~218 ~9 ~66 brown_glazed_terracotta 0
fill ~219 ~8 ~68 ~219 ~9 ~68 gold_ore 0
fill ~220 ~8 ~63 ~220 ~9 ~63 brown_glazed_terracotta 0
setblock ~220 ~8 ~69 brown_glazed_terracotta 0
fill ~221 ~8 ~63 ~222 ~8 ~63 gold_ore 0
setblock ~222 ~8 ~71 brown_glazed_terracotta 0
setblock ~222 ~8 ~72 stained_hardened_clay 8
setblock ~223 ~8 ~63 brown_glazed_terracotta 0
fill ~223 ~8 ~73 ~223 ~9 ~73 stained_hardened_clay 8
setblock ~224 ~8 ~64 brown_glazed_terracotta 0
setblock ~224 ~8 ~74 mycelium 0
setblock ~224 ~8 ~75 soul_sand 0
setblock ~225 ~8 ~76 iron_ore 0
fill ~226 ~8 ~64 ~227 ~8 ~64 brown_glazed_terracotta 0
setblock ~226 ~8 ~77 stained_hardened_clay 8
fill ~227 ~8 ~79 ~227 ~9 ~79 mycelium 0
fill ~228 ~8 ~63 ~229 ~8 ~63 stained_hardened_clay 8
setblock ~228 ~8 ~80 mycelium 0
setblock ~230 ~8 ~63 log2 0
setblock ~230 ~8 ~81 iron_ore 0
fill ~231 ~8 ~63 ~231 ~11 ~63 mycelium 0
setblock ~231 ~8 ~82 mycelium 0
setblock ~232 ~8 ~83 brown_glazed_terracotta 0
setblock ~233 ~8 ~62 iron_ore 0
setblock ~233 ~8 ~84 brown_glazed_terracotta 0
setblock ~234 ~8 ~63 mycelium 0
setblock ~235 ~8 ~63 brown_glazed_terracotta 0
setblock ~235 ~8 ~85 soul_sand 0
setblock ~236 ~8 ~64 brown_glazed_terracotta 0
fill ~238 ~8 ~65 ~239 ~8 ~65 soul_sand 0
fill ~240 ~8 ~66 ~240 ~9 ~66 soul_sand 0
setblock ~241 ~8 ~88 soul_sand 0
fill ~242 ~8 ~67 ~243 ~8 ~67 soul_sand 0
fill ~243 ~8 ~89 ~244 ~8 ~89 soul_sand 0
fill ~244 ~8 ~68 ~244 ~9 ~68 soul_sand 0
fill ~245 ~8 ~89 ~253 ~8 ~89 mycelium 0
fill ~246 ~8 ~69 ~247 ~8 ~69 soul_sand 0
fill ~248 ~8 ~70 ~248 ~7 ~70 mycelium 0
fill ~249 ~8 ~71 ~249 ~9 ~71 mycelium 0
fill ~250 ~8 ~90 ~253 ~8 ~90 mycelium 0
setblock ~251 ~8 ~72 mycelium 0
setblock ~252 ~8 ~73 mycelium 0
fill ~253 ~8 ~74 ~253 ~8 ~75 mycelium 0
fill ~253 ~8 ~86 ~253 ~9 ~86 mycelium 0
fill ~253 ~8 ~87 ~253 ~9 ~87 mycelium 0
fill ~253 ~8 ~88 ~253 ~9 ~88 mycelium 0
fill ~254 ~8 ~84 ~255 ~8 ~84 soul_sand 0
setblock ~254 ~8 ~85 mycelium 0
fill ~256 ~8 ~80 ~257 ~8 ~80 soul_sand 0
fill ~256 ~8 ~81 ~258 ~8 ~81 soul_sand 0
setblock ~256 ~8 ~83 soul_sand 0
setblock ~257 ~8 ~82 soul_sand 0
setblock ~258 ~8 ~82 stained_hardened_clay 12
fill ~96 ~9 ~118 ~96 ~12 ~118 gold_ore 0
setblock ~97 ~9 ~115 brown_glazed_terracotta 0
setblock ~97 ~9 ~116 gold_ore 0
fill ~97 ~9 ~120 ~97 ~10 ~120 brown_glazed_terracotta 0
fill ~97 ~9 ~121 ~97 ~9 ~120 brown_glazed_terracotta 0
setblock ~98 ~9 ~114 gold_ore 0
fill ~98 ~9 ~124 ~98 ~10 ~124 stained_hardened_clay 8
setblock ~99 ~9 ~113 gold_ore 0
fill ~99 ~9 ~124 ~99 ~10 ~124 gold_ore 0
fill ~100 ~9 ~111 ~101 ~9 ~111 gold_ore 0
fill ~100 ~9 ~112 ~100 ~9 ~111 gold_ore 0
fill ~101 ~9 ~109 ~102 ~9 ~109 gold_ore 0
fill ~101 ~9 ~110 ~101 ~9 ~109 gold_ore 0
fill ~101 ~9 ~126 ~101 ~10 ~126 gold_ore 0
setblock ~102 ~9 ~127 brown_glazed_terracotta 0
setblock ~103 ~9 ~110 brown_glazed_terracotta 0
setblock ~105 ~9 ~111 stained_hardened_clay 8
fill ~106 ~9 ~111 ~109 ~9 ~111 gold_ore 0
fill ~107 ~9 ~131 ~109 ~9 ~131 brown_glazed_terracotta 0
setblock ~110 ~9 ~111 brown_glazed_terracotta 0
fill ~110 ~9 ~131 ~111 ~9 ~131 log2 0
setblock ~111 ~9 ~111 gold_ore 0
setblock ~111 ~9 ~132 log2 0
fill ~112 ~9 ~112 ~112 ~8 ~112 gold_ore 0
fill ~112 ~9 ~130 ~115 ~9 ~130 mycelium 0
fill ~112 ~9 ~131 ~113 ~9 ~131 mycelium 0
setblock ~113 ~9 ~113 gold_ore 0
fill ~114 ~9 ~114 ~114 ~9 ~115 gold_ore 0
fill ~114 ~9 ~129 ~117 ~9 ~129 mycelium 0
fill ~115 ~9 ~116 ~115 ~9 ~117 gold_ore 0
setblock ~116 ~9 ~118 log2 0
fill ~116 ~9 ~128 ~119 ~9 ~128 mycelium 0
setblock ~117 ~9 ~119 log2 0
setblock ~118 ~9 ~120 log2 0
fill ~118 ~9 ~121 ~119 ~9 ~121 mycelium 0
fill ~118 ~9 ~122 ~119 ~9 ~122 mycelium 0
fill ~118 ~9 ~127 ~120 ~9 ~127 mycelium 0
fill ~119 ~9 ~123 ~119 ~9 ~128 mycelium 0
fill ~120 ~9 ~124 ~120 ~9 ~127 mycelium 0
fill ~215 ~9 ~62 ~215 ~10 ~62 soul_sand 0
fill ~215 ~9 ~63 ~215 ~10 ~63 mycelium 0
fill ~216 ~9 ~62 ~216 ~10 ~62 mycelium 0
setblock ~216 ~9 ~64 brown_glazed_terracotta 0
setblock ~217 ~9 ~63 log2 0
setblock ~218 ~9 ~67 mycelium 0
setblock ~219 ~9 ~63 brown_glazed_terracotta 0
setblock ~220 ~9 ~69 stained_hardened_clay 8
setblock ~220 ~9 ~70 brown_glazed_terracotta 0
setblock ~221 ~9 ~63 log2 0
setblock ~221 ~9 ~71 stained_hardened_clay 8
fill ~222 ~9 ~63 ~223 ~9 ~63 gold_ore 0
setblock ~222 ~9 ~72 iron_ore 0
fill ~223 ~9 ~74 ~223 ~10 ~74 stained_hardened_clay 8
fill ~224 ~9 ~63 ~224 ~10 ~63 brown_glazed_terracotta 0
fill ~224 ~9 ~75 ~224 ~10 ~75 mycelium 0
fill ~225 ~9 ~63 ~226 ~9 ~63 stained_hardened_clay 8
setblock ~225 ~9 ~76 mycelium 0
setblock ~225 ~9 ~77 log2 0
setblock ~226 ~9 ~78 mycelium 0
setblock ~227 ~9 ~64 iron_ore 0
setblock ~228 ~9 ~64 stained_hardened_clay 8
setblock ~228 ~9 ~79 stained_hardened_clay 8
setblock ~229 ~9 ~63 iron_ore 0
setblock ~229 ~9 ~80 soul_sand 0
setblock ~230 ~9 ~63 stained_hardened_clay 8
setblock ~230 ~9 ~81 stained_hardened_clay 8
setblock ~231 ~9 ~81 mycelium 0
setblock ~232 ~9 ~63 soul_sand 0
setblock ~232 ~9 ~82 brown_glazed_terracotta 0
setblock ~233 ~9 ~63 stained_hardened_clay 8
setblock ~233 ~9 ~83 mycelium 0
fill ~234 ~9 ~64 ~235 ~9 ~64 mycelium 0
fill ~234 ~9 ~83 ~234 ~9 ~84 soul_sand 0
setblock ~235 ~9 ~84 soul_sand 0
fill ~236 ~9 ~65 ~236 ~10 ~65 stained_hardened_clay 7
fill ~236 ~9 ~85 ~237 ~9 ~85 soul_sand 0
fill ~237 ~9 ~65 ~238 ~9 ~65 soul_sand 0
fill ~237 ~9 ~86 ~240 ~9 ~86 soul_sand 0
setblock ~239 ~9 ~66 soul_sand 0
fill ~239 ~9 ~87 ~243 ~9 ~87 soul_sand 0
fill ~240 ~9 ~67 ~242 ~9 ~67 soul_sand 0
fill ~242 ~9 ~68 ~244 ~9 ~68 soul_sand 0
fill ~242 ~9 ~88 ~244 ~9 ~88 soul_sand 0
fill ~244 ~9 ~69 ~246 ~9 ~69 soul_sand 0
fill ~245 ~9 ~70 ~246 ~9 ~70 soul_sand 0
fill ~245 ~9 ~88 ~253 ~9 ~88 mycelium 0
fill ~245 ~9 ~89 ~249 ~9 ~89 mycelium 0
fill ~247 ~9 ~70 ~247 ~9 ~71 mycelium 0
fill ~248 ~9 ~71 ~248 ~9 ~72 mycelium 0
fill ~249 ~9 ~72 ~250 ~9 ~72 mycelium 0
fill ~249 ~9 ~73 ~251 ~9 ~73 mycelium 0
fill ~250 ~9 ~87 ~253 ~9 ~87 mycelium 0
fill ~251 ~9 ~74 ~252 ~9 ~74 mycelium 0
fill ~252 ~9 ~75 ~253 ~9 ~75 mycelium 0
fill ~252 ~9 ~76 ~253 ~9 ~76 mycelium 0
setblock ~253 ~9 ~77 mycelium 0
fill ~253 ~9 ~85 ~253 ~10 ~85 mycelium 0
fill ~254 ~9 ~78 ~254 ~9 ~79 mycelium 0
fill ~254 ~9 ~80 ~255 ~9 ~80 soul_sand 0
fill ~254 ~9 ~81 ~254 ~9 ~80 soul_sand 0
setblock ~254 ~9 ~84 mycelium 0
setblock ~255 ~9 ~79 mycelium 0
fill ~255 ~9 ~81 ~255 ~9 ~82 mycelium 0
setblock ~255 ~9 ~83 soul_sand 0
setblock ~256 ~9 ~82 soul_sand 0
setblock ~96 ~10 ~115 brown_glazed_terracotta 0
fill ~96 ~10 ~116 ~96 ~10 ~118 gold_ore 0
fill ~96 ~10 ~119 ~96 ~12 ~119 brown_glazed_terracotta 0
setblock ~97 ~10 ~114 brown_glazed_terracotta 0
fill ~97 ~10 ~121 ~97 ~11 ~121 gold_ore 0
fill ~97 ~10 ~122 ~97 ~12 ~122 gold_ore 0
fill ~97 ~10 ~123 ~97 ~11 ~123 gold_ore 0
setblock ~98 ~10 ~113 gold_ore 0
fill ~99 ~10 ~111 ~99 ~10 ~112 gold_ore 0
fill ~100 ~10 ~109 ~100 ~10 ~110 gold_ore 0
setblock ~101 ~10 ~109 concrete 8
setblock ~102 ~10 ~110 brown_glazed_terracotta 0
setblock ~102 ~10 ~127 log2 0
fill ~103 ~10 ~110 ~104 ~10 ~110 gold_ore 0
setblock ~104 ~10 ~128 brown_glazed_terracotta 0
fill ~105 ~10 ~110 ~106 ~10 ~110 stained_hardened_clay 8
setblock ~106 ~10 ~129 brown_glazed_terracotta 0
fill ~107 ~10 ~110 ~108 ~10 ~110 gold_ore 0
fill ~107 ~10 ~130 ~108 ~10 ~130 gold_ore 0
setblock ~109 ~10 ~111 gold_ore 0
setblock ~109 ~10 ~130 brown_glazed_terracotta 0
fill ~110 ~10 ~111 ~111 ~10 ~111 log2 0
setblock ~110 ~10 ~129 noteblock 0
setblock ~110 ~10 ~130 mycelium 0
setblock ~111 ~10 ~112 brown_glazed_terracotta 0
fill ~111 ~10 ~129 ~113 ~10 ~129 mycelium 0
setblock ~111 ~10 ~130 log2 0
setblock ~112 ~10 ~113 gold_ore 0
setblock ~112 ~10 ~128 log2 0
fill ~113 ~10 ~114 ~113 ~10 ~115 gold_ore 0
setblock ~113 ~10 ~128 mycelium 0
fill ~114 ~10 ~116 ~114 ~10 ~117 gold_ore 0
fill ~114 ~10 ~127 ~117 ~10 ~127 mycelium 0
setblock ~114 ~10 ~128 log2 0
setblock ~115 ~10 ~118 gold_ore 0
setblock ~115 ~10 ~128 mycelium 0
fill ~116 ~10 ~119 ~116 ~10 ~120 mycelium 0
setblock ~116 ~10 ~121 log2 0
fill ~117 ~10 ~120 ~117 ~10 ~127 mycelium 0
fill ~118 ~10 ~123 ~118 ~10 ~126 mycelium 0
fill ~214 ~10 ~62 ~214 ~12 ~62 soul_sand 0
setblock ~216 ~10 ~64 iron_ore 0
setblock ~216 ~10 ~65 brown_glazed_terracotta 0
fill ~217 ~10 ~62 ~219 ~10 ~62 brown_glazed_terracotta 0
setblock ~217 ~10 ~66 brown_glazed_terracotta 0
setblock ~218 ~10 ~67 brown_glazed_terracotta 0
setblock ~219 ~10 ~68 brown_glazed_terracotta 0
setblock ~219 ~10 ~69 log2 0
fill ~220 ~10 ~62 ~220 ~11 ~62 gold_ore 0
setblock ~220 ~10 ~70 log2 0
setblock ~221 ~10 ~63 mycelium 0
fill ~221 ~10 ~71 ~221 ~10 ~72 mycelium 0
fill ~222 ~10 ~63 ~224 ~10 ~63 brown_glazed_terracotta 0
setblock ~222 ~10 ~73 stained_hardened_clay 8
setblock ~224 ~10 ~76 mycelium 0
setblock ~225 ~10 ~63 iron_ore 0
fill ~225 ~10 ~77 ~226 ~10 ~77 mycelium 0
setblock ~226 ~10 ~63 mycelium 0
fill ~227 ~10 ~63 ~229 ~10 ~63 stained_hardened_clay 8
setblock ~227 ~10 ~78 log2 0
setblock ~228 ~10 ~79 mycelium 0
fill ~229 ~10 ~79 ~229 ~12 ~79 soul_sand 0
fill ~230 ~10 ~63 ~230 ~13 ~63 mycelium 0
fill ~230 ~10 ~80 ~231 ~10 ~80 mycelium 0
setblock ~232 ~10 ~63 mycelium 0
setblock ~232 ~10 ~81 soul_sand 0
fill ~233 ~10 ~64 ~234 ~10 ~64 soul_sand 0
fill ~233 ~10 ~82 ~234 ~10 ~82 stained_hardened_clay 7
setblock ~235 ~10 ~65 stained_hardened_clay 7
setblock ~235 ~10 ~82 soul_sand 0
setblock ~235 ~10 ~83 stained_hardened_clay 7
fill ~236 ~10 ~66 ~238 ~10 ~66 soul_sand 0
fill ~236 ~10 ~83 ~238 ~10 ~83 soul_sand 0
fill ~236 ~10 ~84 ~240 ~10 ~84 soul_sand 0
setblock ~237 ~10 ~67 stained_hardened_clay 7
fill ~238 ~10 ~67 ~239 ~10 ~67 soul_sand 0
fill ~238 ~10 ~85 ~247 ~10 ~85 soul_sand 0
fill ~239 ~10 ~68 ~241 ~10 ~68 soul_sand 0
fill ~240 ~10 ~69 ~243 ~10 ~69 soul_sand 0
fill ~241 ~10 ~86 ~246 ~10 ~86 soul_sand 0
fill ~242 ~10 ~70 ~244 ~10 ~70 soul_sand 0
fill ~243 ~10 ~71 ~246 ~10 ~71 soul_sand 0
fill ~244 ~10 ~87 ~245 ~10 ~87 soul_sand 0
setblock ~245 ~10 ~72 soul_sand 0
fill ~246 ~10 ~72 ~247 ~10 ~72 mycelium 0
fill ~246 ~10 ~73 ~248 ~10 ~73 mycelium 0
fill ~246 ~10 ~87 ~249 ~10 ~87 mycelium 0
fill ~247 ~10 ~86 ~252 ~10 ~86 mycelium 0
fill ~248 ~10 ~74 ~250 ~10 ~74 mycelium 0
fill ~248 ~10 ~75 ~251 ~10 ~75 mycelium 0
fill ~248 ~10 ~85 ~253 ~10 ~85 mycelium 0
fill ~249 ~10 ~76 ~251 ~10 ~76 mycelium 0
fill ~249 ~10 ~77 ~252 ~10 ~77 mycelium 0
fill ~250 ~10 ~78 ~253 ~10 ~78 mycelium 0
fill ~250 ~10 ~79 ~253 ~10 ~79 mycelium 0
setblock ~251 ~10 ~80 mycelium 0
fill ~252 ~10 ~80 ~253 ~10 ~80 soul_sand 0
fill ~252 ~10 ~81 ~253 ~10 ~81 soul_sand 0
fill ~252 ~10 ~82 ~254 ~10 ~82 soul_sand 0
fill ~253 ~10 ~83 ~254 ~10 ~83 soul_sand 0
fill ~253 ~10 ~84 ~253 ~10 ~80 soul_sand 0
setblock ~96 ~11 ~114 stained_hardened_clay 8
setblock ~96 ~11 ~115 iron_ore 0
fill ~96 ~11 ~116 ~96 ~12 ~116 concrete 8
fill ~96 ~11 ~117 ~96 ~11 ~116 concrete 8
fill ~96 ~11 ~120 ~96 ~13 ~120 gold_ore 0
setblock ~97 ~11 ~113 iron_ore 0
setblock ~98 ~11 ~111 stained_hardened_clay 8
setblock ~98 ~11 ~112 gold_ore 0
fill ~98 ~11 ~123 ~98 ~12 ~123 gold_ore 0
setblock ~99 ~11 ~109 stained_hardened_clay 8
setblock ~99 ~11 ~110 iron_ore 0
setblock ~99 ~11 ~124 stained_hardened_clay 8
fill ~100 ~11 ~109 ~100 ~12 ~109 concrete 8
fill ~101 ~11 ~109 ~101 ~14 ~109 gold_ore 0
setblock ~101 ~11 ~126 log2 0
fill ~102 ~11 ~109 ~102 ~12 ~109 brown_glazed_terracotta 0
setblock ~102 ~11 ~127 mycelium 0
fill ~103 ~11 ~109 ~103 ~17 ~109 gold_ore 0
setblock ~103 ~11 ~128 brown_glazed_terracotta 0
fill ~104 ~11 ~110 ~106 ~11 ~110 gold_ore 0
setblock ~104 ~11 ~128 stained_hardened_clay 8
fill ~105 ~11 ~128 ~107 ~11 ~128 gold_ore 0
fill ~107 ~11 ~110 ~108 ~11 ~110 stained_hardened_clay 8
fill ~107 ~11 ~129 ~108 ~11 ~129 gold_ore 0
fill ~108 ~11 ~128 ~109 ~11 ~128 brown_glazed_terracotta 0
setblock ~109 ~11 ~110 gold_ore 0
setblock ~109 ~11 ~129 brown_glazed_terracotta 0
fill ~110 ~11 ~111 ~110 ~11 ~112 mycelium 0
setblock ~110 ~11 ~128 log2 0
setblock ~111 ~11 ~113 log2 0
setblock ~111 ~11 ~127 log2 0
setblock ~111 ~11 ~128 mycelium 0
setblock ~112 ~11 ~114 stained_hardened_clay 8
setblock ~112 ~11 ~115 gold_ore 0
fill ~112 ~11 ~127 ~113 ~11 ~127 mycelium 0
setblock ~113 ~11 ~116 gold_ore 0
setblock ~113 ~11 ~126 mycelium 0
fill ~114 ~11 ~117 ~114 ~11 ~118 gold_ore 0
setblock ~114 ~11 ~119 brown_glazed_terracotta 0
setblock ~114 ~11 ~120 log2 0
setblock ~114 ~11 ~126 log2 0
setblock ~115 ~11 ~119 log2 0
fill ~115 ~11 ~120 ~115 ~11 ~126 mycelium 0
setblock ~116 ~11 ~122 mycelium 0
fill ~116 ~11 ~123 ~116 ~11 ~124 log2 0
fill ~116 ~11 ~125 ~116 ~11 ~126 mycelium 0
fill ~214 ~11 ~63 ~214 ~13 ~63 soul_sand 0
fill ~215 ~11 ~61 ~215 ~13 ~61 soul_sand 0
setblock ~215 ~11 ~64 log2 0
setblock ~215 ~11 ~65 brown_glazed_terracotta 0
setblock ~216 ~11 ~61 mycelium 0
setblock ~216 ~11 ~66 brown_glazed_terracotta 0
setblock ~217 ~11 ~61 log2 0
setblock ~217 ~11 ~67 gold_ore 0
fill ~217 ~11 ~68 ~218 ~11 ~68 brown_glazed_terracotta 0
fill ~218 ~11 ~61 ~220 ~11 ~61 brown_glazed_terracotta 0
setblock ~218 ~11 ~69 brown_glazed_terracotta 0
setblock ~219 ~11 ~70 log2 0
fill ~220 ~11 ~71 ~220 ~11 ~72 mycelium 0
fill ~221 ~11 ~62 ~223 ~11 ~62 brown_glazed_terracotta 0
setblock ~221 ~11 ~72 mycelium 0
setblock ~221 ~11 ~73 stained_hardened_clay 8
setblock ~222 ~11 ~74 stained_hardened_clay 8
fill ~223 ~11 ~75 ~223 ~13 ~75 mycelium 0
fill ~224 ~11 ~62 ~225 ~11 ~62 mycelium 0
fill ~224 ~11 ~76 ~225 ~11 ~76 soul_sand 0
fill ~226 ~11 ~62 ~227 ~11 ~62 stained_hardened_clay 8
setblock ~226 ~11 ~77 mycelium 0
fill ~227 ~11 ~78 ~228 ~11 ~78 mycelium 0
fill ~228 ~11 ~62 ~228 ~12 ~62 iron_ore 0
fill ~228 ~11 ~63 ~229 ~11 ~63 stained_hardened_clay 8
fill ~230 ~11 ~80 ~231 ~11 ~80 soul_sand 0
fill ~232 ~11 ~64 ~232 ~12 ~64 soul_sand 0
setblock ~232 ~11 ~80 stained_hardened_clay 7
setblock ~233 ~11 ~64 mycelium 0
fill ~233 ~11 ~81 ~236 ~11 ~81 stained_hardened_clay 7
fill ~234 ~11 ~65 ~234 ~11 ~66 mycelium 0
setblock ~235 ~11 ~66 soul_sand 0
fill ~235 ~11 ~67 ~236 ~11 ~67 stained_hardened_clay 7
fill ~236 ~11 ~68 ~237 ~11 ~68 stained_hardened_clay 7
fill ~236 ~11 ~82 ~238 ~11 ~82 stained_hardened_clay 7
fill ~238 ~11 ~68 ~238 ~11 ~69 soul_sand 0
fill ~239 ~11 ~69 ~239 ~11 ~70 soul_sand 0
fill ~239 ~11 ~83 ~249 ~11 ~83 soul_sand 0
fill ~240 ~11 ~70 ~241 ~11 ~70 soul_sand 0
fill ~241 ~11 ~71 ~242 ~11 ~71 soul_sand 0
fill ~241 ~11 ~84 ~248 ~11 ~84 soul_sand 0
fill ~242 ~11 ~72 ~244 ~11 ~72 soul_sand 0
fill ~243 ~11 ~73 ~245 ~11 ~73 soul_sand 0
fill ~244 ~11 ~74 ~245 ~11 ~74 soul_sand 0
fill ~246 ~11 ~74 ~247 ~11 ~74 mycelium 0
fill ~246 ~11 ~75 ~247 ~11 ~75 mycelium 0
fill ~246 ~11 ~76 ~248 ~11 ~76 mycelium 0
fill ~247 ~11 ~77 ~248 ~11 ~77 mycelium 0
fill ~247 ~11 ~78 ~249 ~11 ~78 mycelium 0
fill ~248 ~11 ~79 ~249 ~11 ~79 mycelium 0
fill ~249 ~11 ~80 ~250 ~11 ~80 mycelium 0
fill ~249 ~11 ~81 ~251 ~11 ~81 mycelium 0
fill ~249 ~11 ~84 ~252 ~11 ~84 mycelium 0
fill ~250 ~11 ~82 ~251 ~11 ~82 mycelium 0
fill ~250 ~11 ~83 ~251 ~11 ~83 mycelium 0
setblock ~252 ~11 ~83 soul_sand 0
fill ~95 ~12 ~114 ~95 ~13 ~114 stained_hardened_clay 8
fill ~95 ~12 ~115 ~95 ~12 ~114 stained_hardened_clay 8
fill ~96 ~12 ~112 ~97 ~12 ~112 stained_hardened_clay 8
fill ~96 ~12 ~113 ~96 ~12 ~112 stained_hardened_clay 8
setblock ~96 ~12 ~117 gold_ore 0
fill ~96 ~12 ~121 ~96 ~13 ~121 gold_ore 0
setblock ~97 ~12 ~111 stained_hardened_clay 8
fill ~98 ~12 ~109 ~98 ~13 ~109 stained_hardened_clay 8
fill ~98 ~12 ~110 ~98 ~12 ~109 stained_hardened_clay 8
setblock ~99 ~12 ~109 concrete 8
setblock ~99 ~12 ~124 gold_ore 0
setblock ~100 ~12 ~125 stained_hardened_clay 8
fill ~101 ~12 ~126 ~102 ~12 ~126 mycelium 0
fill ~103 ~12 ~127 ~105 ~12 ~127 log2 0
fill ~104 ~12 ~109 ~107 ~12 ~109 gold_ore 0
fill ~106 ~12 ~127 ~107 ~12 ~127 stained_hardened_clay 8
setblock ~108 ~12 ~110 gold_ore 0
fill ~108 ~12 ~127 ~109 ~12 ~127 gold_ore 0
setblock ~109 ~12 ~111 log2 0
setblock ~109 ~12 ~112 mycelium 0
fill ~109 ~12 ~126 ~110 ~12 ~126 gold_ore 0
setblock ~110 ~12 ~113 mycelium 0
setblock ~110 ~12 ~127 brown_glazed_terracotta 0
fill ~111 ~12 ~114 ~111 ~12 ~115 log2 0
setblock ~111 ~12 ~126 log2 0
fill ~112 ~12 ~116 ~112 ~12 ~117 gold_ore 0
setblock ~112 ~12 ~118 stained_hardened_clay 8
fill ~112 ~12 ~119 ~113 ~12 ~119 gold_ore 0
fill ~112 ~12 ~125 ~114 ~12 ~125 mycelium 0
fill ~112 ~12 ~126 ~112 ~12 ~125 mycelium 0
fill ~113 ~12 ~117 ~113 ~12 ~121 gold_ore 0
fill ~113 ~12 ~122 ~113 ~15 ~122 log2 0
fill ~113 ~12 ~123 ~114 ~12 ~123 soul_sand 0
setblock ~114 ~12 ~121 log2 0
setblock ~114 ~12 ~122 mycelium 0
setblock ~114 ~12 ~124 mycelium 0
fill ~214 ~12 ~61 ~214 ~14 ~61 soul_sand 0
fill ~214 ~12 ~64 ~214 ~14 ~64 soul_sand 0
fill ~215 ~12 ~65 ~215 ~12 ~67 mycelium 0
fill ~216 ~12 ~61 ~217 ~12 ~61 soul_sand 0
setblock ~216 ~12 ~67 mycelium 0
setblock ~216 ~12 ~68 soul_sand 0
fill ~217 ~12 ~69 ~217 ~12 ~70 log2 0
setblock ~218 ~12 ~61 mycelium 0
fill ~218 ~12 ~70 ~218 ~12 ~71 log2 0
fill ~219 ~12 ~60 ~219 ~13 ~60 log2 0
fill ~219 ~12 ~71 ~219 ~12 ~72 log2 0
fill ~220 ~12 ~60 ~221 ~12 ~60 mycelium 0
setblock ~220 ~12 ~73 mycelium 0
setblock ~221 ~12 ~61 brown_glazed_terracotta 0
setblock ~221 ~12 ~74 iron_ore 0
fill ~222 ~12 ~61 ~227 ~12 ~61 log2 0
fill ~222 ~12 ~74 ~222 ~14 ~74 soul_sand 0
fill ~224 ~12 ~76 ~225 ~12 ~76 soul_sand 0
fill ~226 ~12 ~77 ~226 ~13 ~77 stained_hardened_clay 8
fill ~227 ~12 ~78 ~228 ~12 ~78 soul_sand 0
fill ~229 ~12 ~62 ~229 ~14 ~62 soul_sand 0
setblock ~230 ~12 ~79 soul_sand 0
fill ~231 ~12 ~63 ~231 ~13 ~63 soul_sand 0
fill ~231 ~12 ~79 ~233 ~12 ~79 stained_hardened_clay 7
fill ~233 ~12 ~64 ~233 ~12 ~65 stained_hardened_clay 8
fill ~233 ~12 ~80 ~237 ~12 ~80 stained_hardened_clay 7
fill ~234 ~12 ~66 ~234 ~12 ~67 soul_sand 0
fill ~235 ~12 ~68 ~235 ~12 ~69 soul_sand 0
fill ~236 ~12 ~69 ~237 ~12 ~69 stained_hardened_clay 7
fill ~236 ~12 ~70 ~238 ~12 ~70 stained_hardened_clay 7
fill ~237 ~12 ~81 ~240 ~12 ~81 stained_hardened_clay 7
fill ~238 ~12 ~71 ~240 ~12 ~71 soul_sand 0
fill ~239 ~12 ~72 ~241 ~12 ~72 soul_sand 0
setblock ~239 ~12 ~82 stained_hardened_clay 7
fill ~240 ~12 ~73 ~242 ~12 ~73 soul_sand 0
fill ~240 ~12 ~82 ~249 ~12 ~82 soul_sand 0
fill ~241 ~12 ~74 ~243 ~12 ~74 soul_sand 0
fill ~241 ~12 ~81 ~247 ~12 ~81 soul_sand 0
fill ~242 ~12 ~75 ~245 ~12 ~75 soul_sand 0
fill ~243 ~12 ~76 ~245 ~12 ~76 soul_sand 0
setblock ~245 ~12 ~77 soul_sand 0
fill ~245 ~12 ~78 ~246 ~12 ~78 mycelium 0
setblock ~246 ~12 ~77 mycelium 0
fill ~246 ~12 ~79 ~247 ~12 ~79 mycelium 0
fill ~246 ~12 ~80 ~248 ~12 ~80 mycelium 0
setblock ~248 ~12 ~81 mycelium 0
fill ~95 ~13 ~113 ~95 ~14 ~113 stained_hardened_clay 8
setblock ~95 ~13 ~115 iron_ore 0
setblock ~95 ~13 ~116 wool 8
fill ~95 ~13 ~117 ~95 ~13 ~118 gold_ore 0
fill ~96 ~13 ~111 ~96 ~14 ~111 stained_hardened_clay 8
fill ~96 ~13 ~112 ~96 ~14 ~112 stained_hardened_clay 8
setblock ~96 ~13 ~119 gold_ore 0
fill ~96 ~13 ~122 ~96 ~14 ~122 gold_ore 0
fill ~97 ~13 ~110 ~97 ~14 ~110 stained_hardened_clay 8
fill ~97 ~13 ~123 ~97 ~14 ~123 gold_ore 0
setblock ~98 ~13 ~108 stained_hardened_clay 8
setblock ~98 ~13 ~124 gold_ore 0
setblock ~99 ~13 ~108 iron_ore 0
setblock ~99 ~13 ~125 gold_ore 0
setblock ~100 ~13 ~109 gold_ore 0
fill ~100 ~13 ~126 ~100 ~15 ~126 log2 0
fill ~101 ~13 ~126 ~103 ~13 ~126 mycelium 0
fill ~102 ~13 ~109 ~102 ~15 ~109 gold_ore 0
fill ~104 ~13 ~109 ~107 ~13 ~109 gold_ore 0
fill ~104 ~13 ~127 ~104 ~16 ~127 gold_ore 0
setblock ~105 ~13 ~127 mycelium 0
setblock ~106 ~13 ~127 noteblock 0
setblock ~107 ~13 ~110 gold_ore 0
setblock ~107 ~13 ~127 log2 0
fill ~108 ~13 ~111 ~108 ~14 ~111 gold_ore 0
setblock ~108 ~13 ~126 stained_hardened_clay 8
setblock ~109 ~13 ~112 log2 0
fill ~109 ~13 ~113 ~109 ~15 ~113 mycelium 0
fill ~109 ~13 ~126 ~110 ~13 ~126 brown_glazed_terracotta 0
fill ~110 ~13 ~114 ~110 ~14 ~114 mycelium 0
setblock ~111 ~13 ~115 stained_hardened_clay 8
setblock ~111 ~13 ~116 mycelium 0
setblock ~111 ~13 ~117 noteblock 0
fill ~111 ~13 ~125 ~112 ~13 ~125 mycelium 0
setblock ~112 ~13 ~118 mycelium 0
fill ~112 ~13 ~119 ~112 ~14 ~119 stained_hardened_clay 8
fill ~112 ~13 ~120 ~112 ~13 ~119 stained_hardened_clay 8
setblock ~112 ~13 ~121 brown_glazed_terracotta 0
fill ~113 ~13 ~123 ~113 ~13 ~124 mycelium 0
fill ~213 ~13 ~62 ~213 ~15 ~62 soul_sand 0
fill ~214 ~13 ~65 ~214 ~15 ~65 soul_sand 0
fill ~215 ~13 ~66 ~215 ~13 ~68 log2 0
fill ~216 ~13 ~61 ~216 ~12 ~61 soul_sand 0
fill ~216 ~13 ~69 ~216 ~13 ~70 mycelium 0
fill ~217 ~13 ~60 ~217 ~14 ~60 soul_sand 0
fill ~217 ~13 ~71 ~217 ~15 ~71 mycelium 0
setblock ~218 ~13 ~60 log2 0
setblock ~218 ~13 ~72 mycelium 0
fill ~219 ~13 ~73 ~219 ~14 ~73 mycelium 0
setblock ~220 ~13 ~60 log2 0
setblock ~220 ~13 ~73 brown_glazed_terracotta 0
fill ~221 ~13 ~60 ~223 ~13 ~60 mycelium 0
fill ~221 ~13 ~74 ~221 ~14 ~74 soul_sand 0
setblock ~224 ~13 ~60 log2 0 
fill ~224 ~13 ~76 ~224 ~11 ~76 soul_sand 0
setblock ~225 ~13 ~60 mycelium 0
fill ~225 ~13 ~76 ~225 ~14 ~76 mycelium 0
fill ~226 ~13 ~61 ~226 ~14 ~61 mycelium 0
setblock ~227 ~13 ~61 brown_glazed_terracotta 0
setblock ~227 ~13 ~77 brown_glazed_terracotta 0
fill ~228 ~13 ~62 ~228 ~14 ~62 soul_sand 0
setblock ~228 ~13 ~77 soul_sand 0
fill ~229 ~13 ~78 ~230 ~13 ~78 soul_sand 0
fill ~231 ~13 ~78 ~233 ~13 ~78 stained_hardened_clay 7
setblock ~232 ~13 ~64 mycelium 0
fill ~233 ~13 ~65 ~233 ~13 ~66 stained_hardened_clay 8
setblock ~233 ~13 ~71 soul_sand 0
fill ~233 ~13 ~72 ~237 ~13 ~72 stained_hardened_clay 7
fill ~233 ~13 ~73 ~236 ~13 ~73 stained_hardened_clay 7
fill ~233 ~13 ~74 ~236 ~13 ~74 stained_hardened_clay 7
fill ~234 ~13 ~67 ~234 ~13 ~68 soul_sand 0
setblock ~234 ~13 ~70 soul_sand 0
fill ~234 ~13 ~71 ~237 ~13 ~71 stained_hardened_clay 7
fill ~234 ~13 ~75 ~236 ~13 ~75 stained_hardened_clay 7
fill ~234 ~13 ~76 ~238 ~13 ~76 stained_hardened_clay 7
fill ~234 ~13 ~79 ~241 ~13 ~79 stained_hardened_clay 7
setblock ~235 ~13 ~69 soul_sand 0
setblock ~235 ~13 ~70 stained_hardened_clay 7
fill ~235 ~13 ~77 ~240 ~13 ~77 stained_hardened_clay 7
fill ~235 ~13 ~78 ~242 ~13 ~78 stained_hardened_clay 7
fill ~237 ~13 ~73 ~239 ~13 ~73 soul_sand 0
fill ~237 ~13 ~74 ~240 ~13 ~74 soul_sand 0
fill ~237 ~13 ~75 ~239 ~13 ~75 soul_sand 0
setblock ~238 ~13 ~72 soul_sand 0
fill ~238 ~13 ~80 ~241 ~13 ~80 stained_hardened_clay 7
setblock ~239 ~13 ~76 soul_sand 0
fill ~240 ~13 ~75 ~240 ~13 ~80 stained_hardened_clay 7
fill ~241 ~13 ~75 ~241 ~13 ~77 soul_sand 0
fill ~242 ~13 ~76 ~242 ~13 ~77 soul_sand 0
fill ~242 ~13 ~79 ~245 ~13 ~79 soul_sand 0
fill ~242 ~13 ~80 ~245 ~13 ~80 soul_sand 0
fill ~243 ~13 ~77 ~244 ~13 ~77 soul_sand 0
fill ~243 ~13 ~78 ~244 ~13 ~78 soul_sand 0
setblock ~94 ~14 ~115 iron_ore 0
setblock ~95 ~14 ~114 iron_ore 0
setblock ~95 ~14 ~116 iron_ore 0
setblock ~95 ~14 ~117 concrete 8
fill ~95 ~14 ~118 ~95 ~14 ~121 gold_ore 0
setblock ~97 ~14 ~109 stained_hardened_clay 8
fill ~98 ~14 ~109 ~99 ~14 ~109 iron_ore 0
setblock ~98 ~14 ~124 stained_hardened_clay 8
setblock ~99 ~14 ~125 stained_hardened_clay 8
setblock ~100 ~14 ~109 concrete 8
fill ~101 ~14 ~126 ~101 ~16 ~126 log2 0
fill ~102 ~14 ~126 ~103 ~14 ~126 mycelium 0
fill ~104 ~14 ~109 ~106 ~14 ~109 gold_ore 0
fill ~105 ~14 ~127 ~105 ~15 ~127 gold_ore 0
fill ~106 ~14 ~127 ~107 ~14 ~127 stained_hardened_clay 8
setblock ~107 ~14 ~110 stained_hardened_clay 8
fill ~108 ~14 ~112 ~108 ~15 ~112 log2 0
setblock ~108 ~14 ~127 log2 0
fill ~109 ~14 ~126 ~110 ~14 ~126 log2 0
setblock ~110 ~14 ~115 log2 0
setblock ~111 ~14 ~116 gold_ore 0
setblock ~111 ~14 ~117 stained_hardened_clay 8
setblock ~111 ~14 ~125 log2 0
setblock ~112 ~14 ~118 stained_hardened_clay 8
fill ~112 ~14 ~120 ~112 ~14 ~121 log2 0
fill ~112 ~14 ~125 ~112 ~15 ~125 soul_sand 0
fill ~113 ~14 ~123 ~113 ~15 ~123 soul_sand 0
fill ~113 ~14 ~124 ~113 ~24 ~124 soul_sand 0
fill ~213 ~14 ~61 ~213 ~15 ~61 soul_sand 0
fill ~213 ~14 ~63 ~213 ~16 ~63 soul_sand 0
setblock ~214 ~14 ~66 soul_sand 0
fill ~215 ~14 ~60 ~217 ~14 ~60 soul_sand 0
fill ~215 ~14 ~67 ~215 ~14 ~68 mycelium 0
setblock ~215 ~14 ~69 brown_glazed_terracotta 0
fill ~216 ~14 ~70 ~216 ~14 ~71 brown_glazed_terracotta 0
fill ~218 ~14 ~60 ~219 ~14 ~60 mycelium 0
setblock ~218 ~14 ~72 brown_glazed_terracotta 0
fill ~220 ~14 ~59 ~220 ~15 ~59 mycelium 0
fill ~220 ~14 ~73 ~220 ~15 ~73 mycelium 0
setblock ~221 ~14 ~59 brown_glazed_terracotta 0
setblock ~222 ~14 ~59 log2 0
setblock ~223 ~14 ~59 brown_glazed_terracotta 0
fill ~223 ~14 ~75 ~224 ~14 ~75 soul_sand 0
setblock ~224 ~14 ~60 brown_glazed_terracotta 0
setblock ~225 ~14 ~60 log2 0
setblock ~226 ~14 ~76 log2 0
setblock ~227 ~14 ~61 mycelium 0
setblock ~227 ~14 ~76 soul_sand 0
setblock ~228 ~14 ~76 mycelium 0
setblock ~229 ~14 ~77 soul_sand 0
setblock ~230 ~14 ~63 soul_sand 0
fill ~230 ~14 ~77 ~234 ~14 ~77 stained_hardened_clay 7
setblock ~231 ~14 ~64 soul_sand 0
fill ~231 ~14 ~73 ~232 ~14 ~73 soul_sand 0
fill ~231 ~14 ~74 ~232 ~14 ~74 stained_hardened_clay 7
setblock ~232 ~14 ~65 log2 0
fill ~232 ~14 ~71 ~232 ~15 ~71 soul_sand 0
fill ~232 ~14 ~72 ~232 ~14 ~71 soul_sand 0
fill ~232 ~14 ~75 ~233 ~14 ~75 stained_hardened_clay 7
fill ~232 ~14 ~76 ~233 ~14 ~76 stained_hardened_clay 7
setblock ~233 ~14 ~66 soul_sand 0
setblock ~233 ~14 ~67 mycelium 0
setblock ~233 ~14 ~70 soul_sand 0
fill ~234 ~14 ~68 ~234 ~14 ~69 soul_sand 0
setblock ~234 ~14 ~78 stained_hardened_clay 7
fill ~94 ~15 ~113 ~95 ~15 ~113 gold_ore 0
fill ~94 ~15 ~114 ~94 ~16 ~114 gold_ore 0
fill ~94 ~15 ~115 ~94 ~16 ~115 gold_ore 0
fill ~94 ~15 ~116 ~94 ~15 ~118 gold_ore 0
fill ~95 ~15 ~119 ~95 ~15 ~120 stained_hardened_clay 0
fill ~95 ~15 ~121 ~95 ~15 ~122 gold_ore 0
fill ~96 ~15 ~111 ~96 ~18 ~111 gold_ore 0
fill ~96 ~15 ~112 ~96 ~15 ~111 gold_ore 0
fill ~96 ~15 ~123 ~96 ~16 ~123 gold_ore 0
fill ~97 ~15 ~109 ~100 ~15 ~109 gold_ore 0
fill ~97 ~15 ~110 ~97 ~15 ~109 gold_ore 0
setblock ~97 ~15 ~124 gold_ore 0
setblock ~98 ~15 ~125 gold_ore 0
setblock ~99 ~15 ~126 brown_glazed_terracotta 0
setblock ~101 ~15 ~109 stained_hardened_clay 0
fill ~102 ~15 ~126 ~102 ~12 ~126 mycelium 0
fill ~103 ~15 ~127 ~103 ~17 ~127 mycelium 0
fill ~104 ~15 ~109 ~106 ~15 ~109 gold_ore 0
fill ~106 ~15 ~128 ~106 ~16 ~128 gold_ore 0
fill ~107 ~15 ~110 ~107 ~15 ~111 gold_ore 0
fill ~107 ~15 ~127 ~108 ~15 ~127 brown_glazed_terracotta 0
fill ~109 ~15 ~114 ~109 ~17 ~114 mycelium 0
fill ~109 ~15 ~126 ~109 ~16 ~126 brown_glazed_terracotta 0
setblock ~110 ~15 ~115 mycelium 0
fill ~110 ~15 ~126 ~110 ~16 ~126 log2 0
fill ~111 ~15 ~115 ~111 ~16 ~115 gold_ore 0
setblock ~111 ~15 ~116 concrete 8
fill ~111 ~15 ~117 ~111 ~18 ~117 gold_ore 0
fill ~111 ~15 ~118 ~111 ~19 ~118 gold_ore 0
setblock ~111 ~15 ~125 mycelium 0
fill ~112 ~15 ~119 ~112 ~16 ~119 brown_glazed_terracotta 0
fill ~112 ~15 ~120 ~112 ~16 ~120 brown_glazed_terracotta 0
fill ~112 ~15 ~121 ~112 ~15 ~119 brown_glazed_terracotta 0
fill ~212 ~15 ~61 ~212 ~17 ~61 soul_sand 0
setblock ~213 ~15 ~64 soul_sand 0
fill ~214 ~15 ~60 ~216 ~15 ~60 soul_sand 0
fill ~214 ~15 ~66 ~214 ~16 ~66 mycelium 0
setblock ~214 ~15 ~67 soul_sand 0
setblock ~215 ~15 ~68 mycelium 0
setblock ~215 ~15 ~69 log2 0
fill ~215 ~15 ~70 ~216 ~15 ~70 mycelium 0
setblock ~217 ~15 ~60 mycelium 0
setblock ~218 ~15 ~60 soul_sand 0
setblock ~218 ~15 ~72 mycelium 0
fill ~219 ~15 ~59 ~219 ~16 ~59 soul_sand 0
setblock ~219 ~15 ~72 log2 0
fill ~221 ~15 ~59 ~221 ~16 ~59 log2 0
setblock ~221 ~15 ~74 log2 1
fill ~222 ~15 ~59 ~223 ~15 ~59 mycelium 0
setblock ~222 ~15 ~74 stained_hardened_clay 12
fill ~223 ~15 ~74 ~224 ~15 ~74 soul_sand 0
fill ~224 ~15 ~60 ~225 ~15 ~60 mycelium 0
fill ~225 ~15 ~75 ~226 ~15 ~75 soul_sand 0
setblock ~226 ~15 ~61 brown_glazed_terracotta 0
setblock ~227 ~15 ~62 soul_sand 0
fill ~227 ~15 ~75 ~228 ~15 ~75 mycelium 0
setblock ~228 ~15 ~62 log2 1
setblock ~229 ~15 ~63 soul_sand 0
setblock ~229 ~15 ~76 soul_sand 0
setblock ~230 ~15 ~64 soul_sand 0
setblock ~230 ~15 ~74 soul_sand 0
fill ~230 ~15 ~75 ~231 ~15 ~75 stained_hardened_clay 7
fill ~230 ~15 ~76 ~231 ~15 ~76 stained_hardened_clay 7
setblock ~231 ~15 ~65 soul_sand 0
fill ~231 ~15 ~72 ~231 ~15 ~73 soul_sand 0
setblock ~232 ~15 ~66 mycelium 0
fill ~232 ~15 ~67 ~233 ~15 ~67 brown_glazed_terracotta 0
setblock ~232 ~15 ~70 soul_sand 0
fill ~233 ~15 ~68 ~233 ~15 ~69 soul_sand 0
fill ~94 ~16 ~113 ~94 ~15 ~113 gold_ore 0
setblock ~94 ~16 ~116 stained_hardened_clay 0
fill ~94 ~16 ~117 ~94 ~16 ~121 gold_ore 0
fill ~95 ~16 ~112 ~95 ~18 ~112 gold_ore 0
setblock ~95 ~16 ~122 gold_ore 0
fill ~96 ~16 ~110 ~96 ~23 ~110 gold_ore 0
fill ~96 ~16 ~124 ~96 ~17 ~124 gold_ore 0
fill ~97 ~16 ~109 ~97 ~20 ~109 gold_ore 0
setblock ~97 ~16 ~125 brown_glazed_terracotta 0
fill ~98 ~16 ~109 ~98 ~17 ~109 stained_hardened_clay 0
fill ~98 ~16 ~126 ~99 ~16 ~126 gold_ore 0
fill ~99 ~16 ~109 ~101 ~16 ~109 gold_ore 0
setblock ~100 ~16 ~126 stained_hardened_clay 8
setblock ~102 ~16 ~109 stained_hardened_clay 0
fill ~102 ~16 ~127 ~102 ~18 ~127 mycelium 0
fill ~104 ~16 ~109 ~105 ~16 ~109 gold_ore 0
fill ~105 ~16 ~128 ~105 ~18 ~128 gold_ore 0
setblock ~106 ~16 ~110 brown_glazed_terracotta 0
fill ~107 ~16 ~111 ~107 ~17 ~111 gold_ore 0
fill ~107 ~16 ~127 ~108 ~16 ~127 brown_glazed_terracotta 0
setblock ~108 ~16 ~112 gold_ore 0
fill ~108 ~16 ~113 ~108 ~18 ~113 brown_glazed_terracotta 0
fill ~110 ~16 ~114 ~110 ~18 ~114 mycelium 0
fill ~111 ~16 ~116 ~111 ~18 ~116 gold_ore 0
fill ~111 ~16 ~125 ~111 ~17 ~125 brown_glazed_terracotta 0
setblock ~112 ~16 ~121 log2 0
fill ~112 ~16 ~125 ~112 ~17 ~125 log2 0
fill ~113 ~16 ~122 ~113 ~17 ~122 brown_glazed_terracotta 0
fill ~113 ~16 ~123 ~113 ~17 ~123 log2 0
fill ~212 ~16 ~60 ~214 ~16 ~60 soul_sand 0
fill ~212 ~16 ~62 ~212 ~18 ~62 soul_sand 0
fill ~213 ~16 ~64 ~213 ~16 ~65 mycelium 0
setblock ~214 ~16 ~67 mycelium 0
setblock ~214 ~16 ~68 soul_sand 0
fill ~215 ~16 ~60 ~216 ~16 ~60 mycelium 0
fill ~215 ~16 ~69 ~215 ~18 ~69 mycelium 0
fill ~216 ~16 ~70 ~216 ~18 ~70 mycelium 0
fill ~217 ~16 ~59 ~218 ~16 ~59 mycelium 0
setblock ~217 ~16 ~71 log2 0
setblock ~218 ~16 ~72 soul_sand 0
setblock ~219 ~16 ~72 mycelium 0
setblock ~220 ~16 ~59 soul_sand 0
setblock ~220 ~16 ~72 soul_sand 0
setblock ~221 ~16 ~73 stained_hardened_clay 12
setblock ~222 ~16 ~59 log2 0
fill ~222 ~16 ~73 ~224 ~16 ~73 soul_sand 0
setblock ~223 ~16 ~60 brown_glazed_terracotta 0
setblock ~224 ~16 ~60 log2 0
setblock ~225 ~16 ~61 mycelium 0
setblock ~225 ~16 ~74 soul_sand 0
setblock ~226 ~16 ~61 soul_sand 0
setblock ~226 ~16 ~74 mycelium 0
setblock ~227 ~16 ~62 log2 1
fill ~227 ~16 ~74 ~229 ~16 ~74 soul_sand 0
setblock ~228 ~16 ~63 stained_hardened_clay 12
fill ~229 ~16 ~64 ~229 ~16 ~65 soul_sand 0
setblock ~229 ~16 ~73 soul_sand 0
setblock ~229 ~16 ~75 soul_sand 0
fill ~230 ~16 ~65 ~230 ~16 ~66 soul_sand 0
fill ~230 ~16 ~72 ~231 ~16 ~72 stained_hardened_clay 7
fill ~230 ~16 ~73 ~230 ~16 ~72 stained_hardened_clay 7
setblock ~231 ~16 ~66 mycelium 0
fill ~231 ~16 ~67 ~231 ~17 ~67 soul_sand 0
fill ~231 ~16 ~69 ~232 ~16 ~69 soul_sand 0
fill ~231 ~16 ~70 ~231 ~16 ~72 stained_hardened_clay 7
setblock ~232 ~16 ~68 soul_sand 0
fill ~93 ~17 ~113 ~93 ~19 ~113 gold_ore 0
fill ~93 ~17 ~114 ~93 ~19 ~114 gold_ore 0
fill ~93 ~17 ~115 ~93 ~18 ~115 gold_ore 0
fill ~93 ~17 ~116 ~93 ~18 ~116 gold_ore 0
fill ~93 ~17 ~117 ~93 ~18 ~117 gold_ore 0
fill ~93 ~17 ~118 ~93 ~17 ~119 stained_hardened_clay 0
fill ~94 ~17 ~112 ~94 ~19 ~112 gold_ore 0
fill ~94 ~17 ~120 ~94 ~17 ~122 gold_ore 0
setblock ~95 ~17 ~123 gold_ore 0
setblock ~97 ~17 ~125 gold_ore 0
fill ~98 ~17 ~126 ~99 ~17 ~126 gold_ore 0
fill ~99 ~17 ~109 ~99 ~18 ~109 stained_hardened_clay 0
fill ~100 ~17 ~109 ~103 ~17 ~109 gold_ore 0
fill ~100 ~17 ~126 ~100 ~18 ~126 brown_glazed_terracotta 0
setblock ~101 ~17 ~127 log2 0
fill ~104 ~17 ~110 ~106 ~17 ~110 gold_ore 0
fill ~104 ~17 ~128 ~104 ~18 ~128 gold_ore 0
setblock ~106 ~17 ~128 brown_glazed_terracotta 0
setblock ~107 ~17 ~112 gold_ore 0
fill ~107 ~17 ~127 ~107 ~15 ~127 brown_glazed_terracotta 0
setblock ~108 ~17 ~127 gold_ore 0
fill ~109 ~17 ~127 ~109 ~19 ~127 brown_glazed_terracotta 0
fill ~110 ~17 ~126 ~110 ~18 ~126 brown_glazed_terracotta 0
setblock ~111 ~17 ~115 brown_glazed_terracotta 0
setblock ~112 ~17 ~119 stained_hardened_clay 8
setblock ~112 ~17 ~120 gold_ore 0
setblock ~112 ~17 ~121 brown_glazed_terracotta 0
fill ~212 ~17 ~60 ~215 ~17 ~60 soul_sand 0
fill ~212 ~17 ~63 ~212 ~19 ~63 soul_sand 0
fill ~213 ~17 ~64 ~213 ~17 ~65 soul_sand 0
setblock ~213 ~17 ~66 mycelium 0
fill ~214 ~17 ~67 ~214 ~17 ~68 brown_glazed_terracotta 0
fill ~216 ~17 ~59 ~216 ~18 ~59 soul_sand 0
fill ~217 ~17 ~59 ~217 ~16 ~59 mycelium 0
fill ~217 ~17 ~71 ~218 ~17 ~71 mycelium 0
fill ~218 ~17 ~59 ~219 ~17 ~59 brown_glazed_terracotta 0
setblock ~219 ~17 ~71 soul_sand 0
setblock ~220 ~17 ~58 mycelium 0
setblock ~220 ~17 ~72 mycelium 0
fill ~221 ~17 ~59 ~222 ~17 ~59 mycelium 0
fill ~221 ~17 ~72 ~223 ~17 ~72 soul_sand 0
fill ~223 ~17 ~60 ~224 ~17 ~60 mycelium 0
setblock ~224 ~17 ~73 soul_sand 0
setblock ~225 ~17 ~61 soul_sand 0
setblock ~225 ~17 ~73 mycelium 0
setblock ~226 ~17 ~62 mycelium 0
setblock ~226 ~17 ~73 soul_sand 0
setblock ~227 ~17 ~63 stained_hardened_clay 12
fill ~227 ~17 ~72 ~229 ~17 ~72 stained_hardened_clay 7
fill ~227 ~17 ~73 ~228 ~17 ~73 stained_hardened_clay 7
setblock ~228 ~17 ~64 soul_sand 0
fill ~228 ~17 ~71 ~230 ~17 ~71 stained_hardened_clay 7
setblock ~229 ~17 ~65 soul_sand 0
fill ~229 ~17 ~69 ~230 ~17 ~69 stained_hardened_clay 7
setblock ~230 ~17 ~66 soul_sand 0
fill ~230 ~17 ~67 ~230 ~17 ~71 stained_hardened_clay 7
setblock ~231 ~17 ~68 soul_sand 0
setblock ~93 ~18 ~118 gold_ore 0
fill ~93 ~18 ~119 ~93 ~18 ~120 stained_hardened_clay 0
fill ~93 ~18 ~121 ~93 ~18 ~122 gold_ore 0
setblock ~94 ~18 ~123 gold_ore 0
fill ~95 ~18 ~124 ~95 ~19 ~124 gold_ore 0
fill ~96 ~18 ~125 ~96 ~19 ~125 gold_ore 0
fill ~97 ~18 ~126 ~97 ~21 ~126 gold_ore 0
fill ~98 ~18 ~109 ~98 ~20 ~109 gold_ore 0
fill ~98 ~18 ~126 ~100 ~18 ~126 brown_glazed_terracotta 0
fill ~100 ~18 ~109 ~101 ~18 ~109 gold_ore 0
setblock ~101 ~18 ~127 mycelium 0
fill ~102 ~18 ~110 ~106 ~18 ~110 gold_ore 0
fill ~103 ~18 ~128 ~103 ~20 ~128 mycelium 0
setblock ~106 ~18 ~111 brown_glazed_terracotta 0
setblock ~106 ~18 ~128 gold_ore 0
fill ~107 ~18 ~112 ~107 ~19 ~112 brown_glazed_terracotta 0
fill ~107 ~18 ~113 ~107 ~18 ~112 brown_glazed_terracotta 0
setblock ~107 ~18 ~128 stained_hardened_clay 8
setblock ~108 ~18 ~127 log2 0
setblock ~109 ~18 ~113 log2 0
fill ~110 ~18 ~115 ~110 ~21 ~115 mycelium 0
setblock ~111 ~18 ~125 gold_ore 0
setblock ~112 ~18 ~119 gold_ore 0
fill ~112 ~18 ~120 ~112 ~18 ~121 log2 0
setblock ~112 ~18 ~125 brown_glazed_terracotta 0
fill ~113 ~18 ~122 ~113 ~20 ~122 gold_ore 0
setblock ~113 ~18 ~123 brown_glazed_terracotta 0
fill ~211 ~18 ~60 ~213 ~18 ~60 soul_sand 0
fill ~211 ~18 ~61 ~211 ~20 ~61 soul_sand 0
fill ~212 ~18 ~64 ~212 ~19 ~64 soul_sand 0
fill ~213 ~18 ~65 ~213 ~18 ~67 soul_sand 0
fill ~214 ~18 ~59 ~218 ~18 ~59 soul_sand 0
fill ~214 ~18 ~68 ~214 ~20 ~68 mycelium 0
fill ~217 ~18 ~70 ~218 ~18 ~70 mycelium 0
fill ~219 ~18 ~58 ~219 ~19 ~58 mycelium 0
setblock ~219 ~18 ~71 mycelium 0
setblock ~220 ~18 ~59 mycelium 0
setblock ~220 ~18 ~71 stained_hardened_clay 12
setblock ~221 ~18 ~59 soul_sand 0
fill ~221 ~18 ~71 ~221 ~19 ~71 soul_sand 0
fill ~222 ~18 ~60 ~223 ~18 ~60 mycelium 0
fill ~222 ~18 ~72 ~223 ~18 ~72 mycelium 0
setblock ~224 ~18 ~61 mycelium 0
fill ~224 ~18 ~72 ~225 ~18 ~72 soul_sand 0
setblock ~225 ~18 ~62 soul_sand 0
setblock ~226 ~18 ~63 soul_sand 0
fill ~226 ~18 ~71 ~228 ~18 ~71 stained_hardened_clay 7
fill ~226 ~18 ~72 ~226 ~18 ~71 stained_hardened_clay 7
setblock ~227 ~18 ~64 mycelium 0
setblock ~228 ~18 ~65 mycelium 0
fill ~228 ~18 ~66 ~229 ~18 ~66 soul_sand 0
fill ~228 ~18 ~67 ~228 ~18 ~66 soul_sand 0
fill ~228 ~18 ~68 ~229 ~18 ~68 stained_hardened_clay 7
fill ~228 ~18 ~69 ~228 ~18 ~68 stained_hardened_clay 7
setblock ~229 ~18 ~67 stained_hardened_clay 7
setblock ~229 ~18 ~70 stained_hardened_clay 7
fill ~92 ~19 ~115 ~92 ~21 ~115 gold_ore 0
fill ~92 ~19 ~116 ~92 ~21 ~116 gold_ore 0
fill ~92 ~19 ~117 ~92 ~21 ~117 gold_ore 0
fill ~92 ~19 ~118 ~92 ~20 ~118 gold_ore 0
fill ~92 ~19 ~119 ~92 ~20 ~119 gold_ore 0
fill ~92 ~19 ~120 ~92 ~20 ~120 gold_ore 0
fill ~93 ~19 ~112 ~93 ~20 ~112 gold_ore 0
fill ~93 ~19 ~121 ~93 ~19 ~122 stained_hardened_clay 0
setblock ~94 ~19 ~123 stained_hardened_clay 0
fill ~95 ~19 ~111 ~95 ~21 ~111 gold_ore 0
fill ~98 ~19 ~126 ~98 ~20 ~126 gold_ore 0
setblock ~99 ~19 ~109 gold_ore 0
setblock ~99 ~19 ~126 brown_glazed_terracotta 0
fill ~100 ~19 ~110 ~102 ~19 ~110 stained_hardened_clay 0
setblock ~100 ~19 ~127 stained_hardened_clay 0
fill ~101 ~19 ~127 ~101 ~20 ~127 brown_glazed_terracotta 0
setblock ~102 ~19 ~128 log2 0
fill ~103 ~19 ~110 ~105 ~19 ~110 gold_ore 0
setblock ~104 ~19 ~128 brown_glazed_terracotta 0
setblock ~105 ~19 ~129 gold_ore 0
fill ~106 ~19 ~111 ~106 ~20 ~111 gold_ore 0
setblock ~106 ~19 ~128 brown_glazed_terracotta 0
setblock ~107 ~19 ~113 stained_hardened_clay 0
fill ~107 ~19 ~128 ~107 ~20 ~128 log2 0
fill ~108 ~19 ~113 ~109 ~19 ~113 gold_ore 0
fill ~108 ~19 ~127 ~108 ~20 ~127 brown_glazed_terracotta 0
setblock ~110 ~19 ~114 log2 0
fill ~110 ~19 ~126 ~110 ~20 ~126 gold_ore 0
fill ~111 ~19 ~116 ~111 ~19 ~117 brown_glazed_terracotta 0
fill ~111 ~19 ~125 ~111 ~21 ~125 brown_glazed_terracotta 0
fill ~112 ~19 ~119 ~112 ~20 ~119 log2 0
fill ~112 ~19 ~120 ~112 ~19 ~121 brown_glazed_terracotta 0
setblock ~112 ~19 ~125 log2 0
setblock ~113 ~19 ~123 log2 0
fill ~211 ~19 ~60 ~211 ~18 ~60 soul_sand 0
fill ~211 ~19 ~62 ~211 ~21 ~62 soul_sand 0
fill ~212 ~19 ~59 ~215 ~19 ~59 soul_sand 0
fill ~212 ~19 ~65 ~212 ~21 ~65 mycelium 0
setblock ~213 ~19 ~66 mycelium 0
setblock ~213 ~19 ~67 brown_glazed_terracotta 0
setblock ~215 ~19 ~69 brown_glazed_terracotta 0
setblock ~216 ~19 ~59 mycelium 0
setblock ~216 ~19 ~69 mycelium 0
fill ~217 ~19 ~58 ~217 ~21 ~58 mycelium 0
fill ~217 ~19 ~69 ~217 ~20 ~69 soul_sand 0
setblock ~218 ~19 ~58 brown_glazed_terracotta 0
setblock ~218 ~19 ~70 soul_sand 0
setblock ~219 ~19 ~70 stained_hardened_clay 12 
setblock ~220 ~19 ~59 log2 0
setblock ~220 ~19 ~70 log2 1
setblock ~221 ~19 ~59 mycelium 0
setblock ~222 ~19 ~60 soul_sand 0
fill ~222 ~19 ~71 ~225 ~19 ~71 soul_sand 0
setblock ~223 ~19 ~61 soul_sand 0
setblock ~224 ~19 ~62 stained_hardened_clay 12
setblock ~225 ~19 ~63 log2 1
fill ~225 ~19 ~70 ~225 ~20 ~70 soul_sand 0
setblock ~226 ~19 ~64 soul_sand 0
fill ~226 ~19 ~70 ~227 ~19 ~70 stained_hardened_clay 7
setblock ~227 ~19 ~65 mycelium 0
fill ~227 ~19 ~66 ~227 ~19 ~68 soul_sand 0
fill ~228 ~19 ~69 ~228 ~19 ~70 stained_hardened_clay 15
fill ~92 ~20 ~112 ~92 ~21 ~112 gold_ore 0
fill ~92 ~20 ~113 ~92 ~21 ~113 gold_ore 0
fill ~92 ~20 ~114 ~92 ~21 ~114 gold_ore 0
setblock ~92 ~20 ~121 gold_ore 0
setblock ~92 ~20 ~122 stained_hardened_clay 0
fill ~93 ~20 ~123 ~93 ~21 ~123 stained_hardened_clay 0
fill ~94 ~20 ~111 ~94 ~22 ~111 gold_ore 0
fill ~94 ~20 ~124 ~94 ~21 ~124 stained_hardened_clay 0
fill ~95 ~20 ~125 ~95 ~21 ~125 gold_ore 0
fill ~96 ~20 ~126 ~96 ~22 ~126 gold_ore 0
fill ~99 ~20 ~110 ~103 ~20 ~110 stained_hardened_clay 0
setblock ~99 ~20 ~127 stained_hardened_clay 0
setblock ~100 ~20 ~127 concrete 8
fill ~102 ~20 ~128 ~102 ~21 ~128 mycelium 0
fill ~104 ~20 ~110 ~105 ~20 ~110 gold_ore 0
fill ~104 ~20 ~129 ~105 ~20 ~129 brown_glazed_terracotta 0
fill ~106 ~20 ~112 ~106 ~21 ~112 gold_ore 0
setblock ~106 ~20 ~128 log2 0
setblock ~107 ~20 ~112 stained_hardened_clay 0
setblock ~108 ~20 ~113 concrete 8
fill ~109 ~20 ~113 ~109 ~21 ~113 gold_ore 0
setblock ~109 ~20 ~127 gold_ore 0
fill ~110 ~20 ~114 ~110 ~23 ~114 mycelium 0
setblock ~111 ~20 ~116 log2 0
fill ~111 ~20 ~117 ~111 ~20 ~118 brown_glazed_terracotta 0
setblock ~112 ~20 ~120 log2 0
setblock ~112 ~20 ~121 gold_ore 0
fill ~112 ~20 ~125 ~112 ~21 ~125 mycelium 0
fill ~113 ~20 ~123 ~113 ~21 ~123 mycelium 0
fill ~210 ~20 ~60 ~210 ~21 ~60 soul_sand 0
fill ~211 ~20 ~59 ~213 ~20 ~59 soul_sand 0
setblock ~211 ~20 ~63 mycelium 0
setblock ~212 ~20 ~64 mycelium 0
fill ~212 ~20 ~66 ~212 ~22 ~66 mycelium 0
setblock ~213 ~20 ~67 mycelium 0
