setblock ~41 ~-3 ~50 sandstone 0
fill ~42 ~-3 ~50 ~43 ~-3 ~50 yellow_glazed_terracotta 0
fill ~42 ~-3 ~51 ~44 ~-3 ~51 yellow_glazed_terracotta 0
fill ~112 ~-3 ~51 ~114 ~-3 ~51 yellow_glazed_terracotta 0
fill ~113 ~-3 ~50 ~114 ~-3 ~50 yellow_glazed_terracotta 0
setblock ~115 ~-3 ~50 sandstone 0
fill ~38 ~-2 ~46 ~38 ~-2 ~48 yellow_glazed_terracotta 0
fill ~39 ~-2 ~44 ~45 ~-2 ~44 yellow_glazed_terracotta 0
fill ~39 ~-2 ~45 ~48 ~-2 ~45 yellow_glazed_terracotta 0
setblock ~39 ~-2 ~46 sandstone 0
setblock ~39 ~-2 ~47 yellow_glazed_terracotta 0
setblock ~39 ~-2 ~48 sandstone 1
fill ~39 ~-2 ~49 ~40 ~-2 ~49 sandstone 0
setblock ~39 ~-2 ~50 sandstone 2
setblock ~39 ~-2 ~51 sandstone 0
fill ~40 ~-2 ~42 ~43 ~-2 ~42 yellow_glazed_terracotta 0
fill ~40 ~-2 ~43 ~44 ~-2 ~43 yellow_glazed_terracotta 0
fill ~40 ~-2 ~46 ~45 ~-2 ~46 yellow_glazed_terracotta 0
setblock ~40 ~-2 ~47 sandstone 0
setblock ~40 ~-2 ~48 yellow_glazed_terracotta 0
setblock ~40 ~-2 ~50 yellow_glazed_terracotta 0
setblock ~40 ~-2 ~51 sandstone 1
fill ~41 ~-2 ~41 ~43 ~-2 ~41 yellow_glazed_terracotta 0
fill ~41 ~-2 ~47 ~49 ~-2 ~47 yellow_glazed_terracotta 0
setblock ~41 ~-2 ~48 sandstone 0
setblock ~41 ~-2 ~49 yellow_glazed_terracotta 0
setblock ~41 ~-2 ~51 sandstone 0
setblock ~41 ~-2 ~52 sandstone 2
fill ~42 ~-2 ~40 ~43 ~-2 ~40 yellow_glazed_terracotta 0
setblock ~42 ~-2 ~48 yellow_glazed_terracotta 0
setblock ~42 ~-2 ~49 sandstone 0
setblock ~42 ~-2 ~52 sandstone 0
setblock ~42 ~-2 ~53 yellow_glazed_terracotta 0
fill ~43 ~-2 ~35 ~45 ~-2 ~35 yellow_glazed_terracotta 0
fill ~43 ~-2 ~36 ~45 ~-2 ~36 yellow_glazed_terracotta 0
fill ~43 ~-2 ~37 ~44 ~-2 ~37 yellow_glazed_terracotta 0
fill ~43 ~-2 ~38 ~44 ~-2 ~38 yellow_glazed_terracotta 0
fill ~43 ~-2 ~39 ~43 ~-2 ~35 yellow_glazed_terracotta 0
setblock ~43 ~-2 ~48 sandstone 0
fill ~43 ~-2 ~49 ~49 ~-2 ~49 yellow_glazed_terracotta 0
setblock ~43 ~-2 ~52 sandstone 2
setblock ~43 ~-2 ~53 sandstone 0
fill ~43 ~-2 ~54 ~44 ~-2 ~54 yellow_glazed_terracotta 0
fill ~43 ~-2 ~55 ~43 ~-2 ~54 yellow_glazed_terracotta 0
fill ~44 ~-2 ~32 ~47 ~-2 ~32 yellow_glazed_terracotta 0
fill ~44 ~-2 ~33 ~46 ~-2 ~33 yellow_glazed_terracotta 0
fill ~44 ~-2 ~34 ~46 ~-2 ~34 yellow_glazed_terracotta 0
fill ~44 ~-2 ~48 ~49 ~-2 ~48 yellow_glazed_terracotta 0
setblock ~44 ~-2 ~50 yellow_glazed_terracotta 0
setblock ~44 ~-2 ~52 sandstone 0
setblock ~44 ~-2 ~53 sandstone 2
setblock ~44 ~-2 ~55 end_stone 0
fill ~45 ~-2 ~31 ~47 ~-2 ~31 yellow_glazed_terracotta 0
setblock ~45 ~-2 ~50 sandstone 0
fill ~45 ~-2 ~51 ~48 ~-2 ~51 yellow_glazed_terracotta 0
setblock ~45 ~-2 ~52 sandstone 2
setblock ~45 ~-2 ~53 yellow_glazed_terracotta 0
setblock ~45 ~-2 ~55 yellow_glazed_terracotta 0
setblock ~46 ~-2 ~30 yellow_glazed_terracotta 0
setblock ~46 ~-2 ~46 wool 1
setblock ~46 ~-2 ~50 yellow_glazed_terracotta 0
fill ~46 ~-2 ~52 ~46 ~-2 ~53 sandstone 0
fill ~47 ~-2 ~46 ~49 ~-2 ~46 yellow_glazed_terracotta 0
setblock ~47 ~-2 ~50 sandstone 0
fill ~47 ~-2 ~52 ~48 ~-2 ~52 yellow_glazed_terracotta 0
fill ~47 ~-2 ~53 ~48 ~-2 ~53 sandstone 1
setblock ~47 ~-2 ~54 sandstone 0
fill ~47 ~-2 ~55 ~48 ~-2 ~55 yellow_glazed_terracotta 0
fill ~48 ~-2 ~50 ~49 ~-2 ~50 yellow_glazed_terracotta 0
setblock ~48 ~-2 ~54 yellow_glazed_terracotta 0
fill ~107 ~-2 ~46 ~109 ~-2 ~46 yellow_glazed_terracotta 0
fill ~107 ~-2 ~47 ~115 ~-2 ~47 yellow_glazed_terracotta 0
fill ~107 ~-2 ~48 ~112 ~-2 ~48 yellow_glazed_terracotta 0
fill ~107 ~-2 ~49 ~113 ~-2 ~49 yellow_glazed_terracotta 0
fill ~107 ~-2 ~50 ~108 ~-2 ~50 yellow_glazed_terracotta 0
fill ~108 ~-2 ~45 ~117 ~-2 ~45 yellow_glazed_terracotta 0
fill ~108 ~-2 ~51 ~111 ~-2 ~51 yellow_glazed_terracotta 0
fill ~108 ~-2 ~52 ~109 ~-2 ~52 yellow_glazed_terracotta 0
fill ~108 ~-2 ~53 ~109 ~-2 ~53 sandstone 1
fill ~108 ~-2 ~54 ~108 ~-2 ~55 yellow_glazed_terracotta 0
fill ~109 ~-2 ~31 ~111 ~-2 ~31 yellow_glazed_terracotta 0
fill ~109 ~-2 ~32 ~112 ~-2 ~32 yellow_glazed_terracotta 0
setblock ~109 ~-2 ~50 sandstone 0
setblock ~109 ~-2 ~54 sandstone 0
setblock ~109 ~-2 ~55 yellow_glazed_terracotta 0
setblock ~110 ~-2 ~30 yellow_glazed_terracotta 0
fill ~110 ~-2 ~33 ~112 ~-2 ~33 yellow_glazed_terracotta 0
fill ~110 ~-2 ~34 ~112 ~-2 ~34 yellow_glazed_terracotta 0
setblock ~110 ~-2 ~46 wool 1
setblock ~110 ~-2 ~50 yellow_glazed_terracotta 0
fill ~110 ~-2 ~52 ~110 ~-2 ~53 sandstone 0
fill ~111 ~-2 ~35 ~113 ~-2 ~35 yellow_glazed_terracotta 0
fill ~111 ~-2 ~36 ~113 ~-2 ~36 yellow_glazed_terracotta 0
fill ~111 ~-2 ~44 ~117 ~-2 ~44 yellow_glazed_terracotta 0
fill ~111 ~-2 ~46 ~116 ~-2 ~46 yellow_glazed_terracotta 0
setblock ~111 ~-2 ~50 sandstone 0
setblock ~111 ~-2 ~52 sandstone 2
setblock ~111 ~-2 ~53 yellow_glazed_terracotta 0
setblock ~111 ~-2 ~55 yellow_glazed_terracotta 0
fill ~112 ~-2 ~37 ~113 ~-2 ~37 yellow_glazed_terracotta 0
fill ~112 ~-2 ~38 ~113 ~-2 ~38 yellow_glazed_terracotta 0
fill ~112 ~-2 ~43 ~116 ~-2 ~43 yellow_glazed_terracotta 0
setblock ~112 ~-2 ~50 yellow_glazed_terracotta 0
setblock ~112 ~-2 ~52 sandstone 0
setblock ~112 ~-2 ~53 sandstone 2
fill ~112 ~-2 ~54 ~113 ~-2 ~54 yellow_glazed_terracotta 0
setblock ~112 ~-2 ~55 end_stone 0
fill ~113 ~-2 ~39 ~113 ~-2 ~47 yellow_glazed_terracotta 0
setblock ~113 ~-2 ~48 sandstone 0
setblock ~113 ~-2 ~52 sandstone 2
setblock ~113 ~-2 ~53 sandstone 0
setblock ~113 ~-2 ~55 yellow_glazed_terracotta 0
fill ~114 ~-2 ~40 ~114 ~-2 ~48 yellow_glazed_terracotta 0
setblock ~114 ~-2 ~49 sandstone 0
setblock ~114 ~-2 ~52 sandstone 0
setblock ~114 ~-2 ~53 yellow_glazed_terracotta 0
fill ~115 ~-2 ~41 ~115 ~-2 ~47 yellow_glazed_terracotta 0
setblock ~115 ~-2 ~48 sandstone 0
setblock ~115 ~-2 ~49 yellow_glazed_terracotta 0
setblock ~115 ~-2 ~51 sandstone 0
setblock ~115 ~-2 ~52 sandstone 2
setblock ~116 ~-2 ~42 yellow_glazed_terracotta 0
setblock ~116 ~-2 ~47 sandstone 0
setblock ~116 ~-2 ~48 yellow_glazed_terracotta 0
fill ~116 ~-2 ~49 ~117 ~-2 ~49 sandstone 0
setblock ~116 ~-2 ~50 yellow_glazed_terracotta 0
setblock ~116 ~-2 ~51 sandstone 1
setblock ~117 ~-2 ~46 sandstone 0
fill ~117 ~-2 ~47 ~118 ~-2 ~47 yellow_glazed_terracotta 0
setblock ~117 ~-2 ~48 sandstone 1
setblock ~117 ~-2 ~50 sandstone 2
setblock ~117 ~-2 ~51 sandstone 0
setblock ~118 ~-2 ~46 yellow_glazed_terracotta 0
setblock ~118 ~-2 ~48 yellow_glazed_terracotta 0
fill ~37 ~-1 ~45 ~38 ~-1 ~45 yellow_glazed_terracotta 0
fill ~37 ~-1 ~46 ~37 ~-1 ~48 yellow_glazed_terracotta 0
fill ~38 ~-1 ~42 ~39 ~-1 ~42 yellow_glazed_terracotta 0
fill ~38 ~-1 ~43 ~39 ~-1 ~43 yellow_glazed_terracotta 0
fill ~38 ~-1 ~44 ~38 ~-1 ~42 yellow_glazed_terracotta 0
fill ~38 ~-1 ~49 ~38 ~-1 ~50 wool 1
setblock ~38 ~-1 ~51 red_sandstone 0
fill ~39 ~-1 ~40 ~41 ~-1 ~40 yellow_glazed_terracotta 0
fill ~39 ~-1 ~41 ~40 ~-1 ~41 yellow_glazed_terracotta 0
setblock ~39 ~-1 ~52 wool 1
fill ~40 ~-1 ~39 ~42 ~-1 ~39 yellow_glazed_terracotta 0
setblock ~40 ~-1 ~52 yellow_glazed_terracotta 0
setblock ~40 ~-1 ~53 red_sandstone 0
fill ~41 ~-1 ~36 ~42 ~-1 ~36 yellow_glazed_terracotta 0
fill ~41 ~-1 ~37 ~42 ~-1 ~37 yellow_glazed_terracotta 0
fill ~41 ~-1 ~38 ~42 ~-1 ~38 yellow_glazed_terracotta 0
fill ~41 ~-1 ~53 ~41 ~-1 ~54 yellow_glazed_terracotta 0
fill ~42 ~-1 ~34 ~43 ~-1 ~34 yellow_glazed_terracotta 0
fill ~42 ~-1 ~35 ~42 ~-1 ~34 yellow_glazed_terracotta 0
setblock ~42 ~-1 ~54 sandstone 0
setblock ~42 ~-1 ~55 yellow_glazed_terracotta 0
fill ~43 ~-1 ~31 ~44 ~-1 ~31 yellow_glazed_terracotta 0
fill ~43 ~-1 ~32 ~43 ~-1 ~34 yellow_glazed_terracotta 0
setblock ~43 ~-1 ~56 red_mushroom_block 0
fill ~44 ~-1 ~29 ~49 ~-1 ~29 yellow_glazed_terracotta 0
fill ~44 ~-1 ~30 ~45 ~-1 ~30 yellow_glazed_terracotta 0
fill ~44 ~-1 ~39 ~45 ~-1 ~39 yellow_glazed_terracotta 0
fill ~44 ~-1 ~40 ~45 ~-1 ~40 yellow_glazed_terracotta 0
fill ~44 ~-1 ~41 ~45 ~-1 ~41 yellow_glazed_terracotta 0
fill ~44 ~-1 ~42 ~45 ~-1 ~42 yellow_glazed_terracotta 0
setblock ~44 ~-1 ~56 sandstone 1
fill ~45 ~-1 ~28 ~48 ~-1 ~28 yellow_glazed_terracotta 0
fill ~45 ~-1 ~37 ~45 ~-1 ~42 yellow_glazed_terracotta 0
setblock ~45 ~-1 ~43 wool 1
setblock ~45 ~-1 ~54 yellow_glazed_terracotta 0
setblock ~45 ~-1 ~56 sandstone 0
fill ~46 ~-1 ~35 ~47 ~-1 ~35 yellow_glazed_terracotta 0
fill ~46 ~-1 ~36 ~47 ~-1 ~36 yellow_glazed_terracotta 0
setblock ~46 ~-1 ~37 stained_hardened_clay 4
setblock ~46 ~-1 ~38 yellow_glazed_terracotta 0
fill ~46 ~-1 ~39 ~46 ~-1 ~42 wool 1
setblock ~46 ~-1 ~43 concrete 1
setblock ~46 ~-1 ~44 wool 1
setblock ~46 ~-1 ~54 red_sandstone 0
setblock ~46 ~-1 ~55 stained_hardened_clay 4
fill ~46 ~-1 ~56 ~46 ~1 ~56 red_mushroom_block 0
setblock ~47 ~-1 ~27 yellow_glazed_terracotta 0
fill ~47 ~-1 ~30 ~49 ~-1 ~30 yellow_glazed_terracotta 0
fill ~47 ~-1 ~33 ~48 ~-1 ~33 yellow_glazed_terracotta 0
fill ~47 ~-1 ~34 ~48 ~-1 ~34 yellow_glazed_terracotta 0
setblock ~47 ~-1 ~37 wool 1
fill ~47 ~-1 ~41 ~47 ~-1 ~42 wool 1
setblock ~47 ~-1 ~43 red_sandstone 0
setblock ~47 ~-1 ~44 yellow_glazed_terracotta 0
fill ~47 ~-1 ~56 ~48 ~-1 ~56 yellow_glazed_terracotta 0
fill ~48 ~-1 ~31 ~49 ~-1 ~31 yellow_glazed_terracotta 0
fill ~48 ~-1 ~32 ~48 ~-1 ~28 yellow_glazed_terracotta 0
fill ~48 ~-1 ~42 ~48 ~-1 ~43 wool 1
setblock ~48 ~-1 ~44 concrete 4
setblock ~49 ~-1 ~44 yellow_glazed_terracotta 0
setblock ~49 ~-1 ~45 wool 1
fill ~49 ~-1 ~51 ~49 ~-1 ~55 yellow_glazed_terracotta 0
fill ~50 ~-1 ~46 ~50 ~2 ~46 yellow_glazed_terracotta 0
fill ~50 ~-1 ~47 ~50 ~2 ~47 yellow_glazed_terracotta 0
fill ~50 ~-1 ~48 ~50 ~2 ~48 yellow_glazed_terracotta 0
fill ~50 ~-1 ~49 ~50 ~0 ~49 yellow_glazed_terracotta 0
fill ~50 ~-1 ~50 ~50 ~1 ~50 yellow_glazed_terracotta 0
fill ~106 ~-1 ~46 ~106 ~2 ~46 yellow_glazed_terracotta 0
fill ~106 ~-1 ~47 ~106 ~2 ~47 yellow_glazed_terracotta 0
fill ~106 ~-1 ~48 ~106 ~2 ~48 yellow_glazed_terracotta 0
fill ~106 ~-1 ~49 ~106 ~0 ~49 yellow_glazed_terracotta 0
fill ~106 ~-1 ~50 ~106 ~1 ~50 yellow_glazed_terracotta 0
fill ~107 ~-1 ~29 ~112 ~-1 ~29 yellow_glazed_terracotta 0
fill ~107 ~-1 ~30 ~109 ~-1 ~30 yellow_glazed_terracotta 0
fill ~107 ~-1 ~31 ~108 ~-1 ~31 yellow_glazed_terracotta 0
setblock ~107 ~-1 ~44 yellow_glazed_terracotta 0
setblock ~107 ~-1 ~45 wool 1
fill ~107 ~-1 ~51 ~107 ~-1 ~55 yellow_glazed_terracotta 0
fill ~108 ~-1 ~28 ~111 ~-1 ~28 yellow_glazed_terracotta 0
fill ~108 ~-1 ~32 ~108 ~-1 ~34 yellow_glazed_terracotta 0
fill ~108 ~-1 ~42 ~110 ~-1 ~42 wool 1
fill ~108 ~-1 ~43 ~108 ~-1 ~42 wool 1
setblock ~108 ~-1 ~44 concrete 4
fill ~108 ~-1 ~56 ~109 ~-1 ~56 yellow_glazed_terracotta 0
setblock ~109 ~-1 ~27 yellow_glazed_terracotta 0
fill ~109 ~-1 ~33 ~109 ~-1 ~36 yellow_glazed_terracotta 0
setblock ~109 ~-1 ~37 wool 1
fill ~109 ~-1 ~41 ~110 ~-1 ~41 wool 1
setblock ~109 ~-1 ~43 red_sandstone 0
setblock ~109 ~-1 ~44 yellow_glazed_terracotta 0
fill ~110 ~-1 ~35 ~110 ~-1 ~36 yellow_glazed_terracotta 0
setblock ~110 ~-1 ~37 stained_hardened_clay 4
fill ~110 ~-1 ~38 ~111 ~-1 ~38 yellow_glazed_terracotta 0
fill ~110 ~-1 ~39 ~110 ~-1 ~42 wool 1
setblock ~110 ~-1 ~43 concrete 1
setblock ~110 ~-1 ~44 wool 1
setblock ~110 ~-1 ~54 red_sandstone 0
setblock ~110 ~-1 ~55 stained_hardened_clay 4
fill ~110 ~-1 ~56 ~110 ~1 ~56 red_mushroom_block 0
fill ~111 ~-1 ~30 ~112 ~-1 ~30 yellow_glazed_terracotta 0
setblock ~111 ~-1 ~37 yellow_glazed_terracotta 0
fill ~111 ~-1 ~39 ~112 ~-1 ~39 yellow_glazed_terracotta 0
fill ~111 ~-1 ~40 ~112 ~-1 ~40 yellow_glazed_terracotta 0
fill ~111 ~-1 ~41 ~112 ~-1 ~41 yellow_glazed_terracotta 0
fill ~111 ~-1 ~42 ~112 ~-1 ~42 yellow_glazed_terracotta 0
setblock ~111 ~-1 ~43 wool 1
setblock ~111 ~-1 ~54 yellow_glazed_terracotta 0
setblock ~111 ~-1 ~56 sandstone 0
fill ~112 ~-1 ~31 ~113 ~-1 ~31 yellow_glazed_terracotta 0
setblock ~112 ~-1 ~56 sandstone 1
fill ~113 ~-1 ~32 ~113 ~-1 ~34 yellow_glazed_terracotta 0
setblock ~113 ~-1 ~56 red_mushroom_block 0
fill ~114 ~-1 ~34 ~114 ~-1 ~39 yellow_glazed_terracotta 0
setblock ~114 ~-1 ~54 sandstone 0
setblock ~114 ~-1 ~55 yellow_glazed_terracotta 0
fill ~115 ~-1 ~36 ~115 ~-1 ~40 yellow_glazed_terracotta 0
fill ~115 ~-1 ~53 ~115 ~-1 ~54 yellow_glazed_terracotta 0
fill ~116 ~-1 ~39 ~116 ~-1 ~41 yellow_glazed_terracotta 0
setblock ~116 ~-1 ~52 yellow_glazed_terracotta 0
setblock ~116 ~-1 ~53 red_sandstone 0
fill ~117 ~-1 ~40 ~117 ~-1 ~43 yellow_glazed_terracotta 0
setblock ~117 ~-1 ~52 wool 1
fill ~118 ~-1 ~42 ~118 ~-1 ~45 yellow_glazed_terracotta 0
fill ~118 ~-1 ~49 ~118 ~-1 ~50 wool 1
setblock ~118 ~-1 ~51 red_sandstone 0
fill ~119 ~-1 ~45 ~119 ~0 ~45 yellow_glazed_terracotta 0
fill ~119 ~-1 ~46 ~119 ~-1 ~48 yellow_glazed_terracotta 0
fill ~36 ~0 ~46 ~36 ~1 ~46 yellow_glazed_terracotta 0
fill ~36 ~0 ~47 ~36 ~1 ~47 yellow_glazed_terracotta 0
fill ~37 ~0 ~42 ~37 ~1 ~42 yellow_glazed_terracotta 0
fill ~37 ~0 ~43 ~37 ~2 ~43 yellow_glazed_terracotta 0
fill ~37 ~0 ~44 ~37 ~2 ~44 yellow_glazed_terracotta 0
fill ~37 ~0 ~45 ~37 ~-1 ~45 yellow_glazed_terracotta 0
fill ~37 ~0 ~48 ~37 ~0 ~51 yellow_glazed_terracotta 0
fill ~38 ~0 ~40 ~38 ~1 ~40 yellow_glazed_terracotta 0
fill ~38 ~0 ~41 ~38 ~2 ~41 yellow_glazed_terracotta 0
setblock ~38 ~0 ~51 wool 1
fill ~38 ~0 ~52 ~38 ~1 ~52 yellow_glazed_terracotta 0
fill ~38 ~0 ~53 ~38 ~1 ~53 yellow_glazed_terracotta 0
fill ~39 ~0 ~39 ~39 ~2 ~39 yellow_glazed_terracotta 0
setblock ~39 ~0 ~53 sandstone 0
fill ~39 ~0 ~54 ~39 ~1 ~54 yellow_glazed_terracotta 0
fill ~40 ~0 ~36 ~40 ~1 ~36 yellow_glazed_terracotta 0
fill ~40 ~0 ~37 ~40 ~0 ~38 yellow_glazed_terracotta 0
fill ~40 ~0 ~54 ~40 ~0 ~55 wool 1
fill ~41 ~0 ~34 ~41 ~2 ~34 yellow_glazed_terracotta 0
fill ~41 ~0 ~35 ~41 ~1 ~35 yellow_glazed_terracotta 0
setblock ~41 ~0 ~55 yellow_glazed_terracotta 0
setblock ~41 ~0 ~56 sandstone 0
fill ~42 ~0 ~32 ~42 ~0 ~33 yellow_glazed_terracotta 0
fill ~42 ~0 ~56 ~42 ~1 ~56 yellow_glazed_terracotta 0
fill ~43 ~0 ~30 ~43 ~1 ~30 yellow_glazed_terracotta 0
fill ~43 ~0 ~31 ~43 ~-1 ~31 yellow_glazed_terracotta 0
setblock ~43 ~0 ~57 yellow_glazed_terracotta 0
fill ~44 ~0 ~28 ~44 ~1 ~28 yellow_glazed_terracotta 0
fill ~44 ~0 ~29 ~44 ~-1 ~29 yellow_glazed_terracotta 0
fill ~44 ~0 ~56 ~45 ~0 ~56 yellow_glazed_terracotta 0
fill ~45 ~0 ~27 ~46 ~0 ~27 yellow_glazed_terracotta 0
fill ~46 ~0 ~26 ~48 ~0 ~26 yellow_glazed_terracotta 0
setblock ~47 ~0 ~38 yellow_glazed_terracotta 0
setblock ~47 ~0 ~39 wool 1
setblock ~47 ~0 ~40 yellow_glazed_terracotta 0
fill ~47 ~0 ~57 ~48 ~0 ~57 yellow_glazed_terracotta 0
fill ~48 ~0 ~27 ~49 ~0 ~27 yellow_glazed_terracotta 0
setblock ~48 ~0 ~35 yellow_glazed_terracotta 0
setblock ~48 ~0 ~36 stained_hardened_clay 4
setblock ~48 ~0 ~37 yellow_glazed_terracotta 0
setblock ~48 ~0 ~38 stained_hardened_clay 4
setblock ~48 ~0 ~39 yellow_glazed_terracotta 0
fill ~48 ~0 ~40 ~48 ~0 ~41 wool 1
fill ~49 ~0 ~28 ~50 ~0 ~28 yellow_glazed_terracotta 0
fill ~49 ~0 ~32 ~49 ~0 ~34 yellow_glazed_terracotta 0
fill ~49 ~0 ~41 ~49 ~1 ~41 yellow_glazed_terracotta 0
fill ~49 ~0 ~42 ~49 ~0 ~43 yellow_glazed_terracotta 0
fill ~49 ~0 ~54 ~49 ~2 ~54 yellow_glazed_terracotta 0
fill ~49 ~0 ~55 ~49 ~0 ~56 yellow_glazed_terracotta 0
setblock ~50 ~0 ~29 yellow_glazed_terracotta 0
setblock ~50 ~0 ~30 stained_hardened_clay 4
setblock ~50 ~0 ~31 yellow_glazed_terracotta 0
fill ~50 ~0 ~43 ~50 ~2 ~43 yellow_glazed_terracotta 0
fill ~50 ~0 ~44 ~50 ~2 ~44 yellow_glazed_terracotta 0
fill ~50 ~0 ~45 ~50 ~2 ~45 yellow_glazed_terracotta 0
fill ~50 ~0 ~51 ~50 ~0 ~53 yellow_glazed_terracotta 0
fill ~106 ~0 ~28 ~107 ~0 ~28 yellow_glazed_terracotta 0
fill ~106 ~0 ~29 ~106 ~0 ~28 yellow_glazed_terracotta 0
setblock ~106 ~0 ~30 stained_hardened_clay 4
setblock ~106 ~0 ~31 yellow_glazed_terracotta 0
fill ~106 ~0 ~43 ~107 ~0 ~43 yellow_glazed_terracotta 0
fill ~106 ~0 ~44 ~106 ~2 ~44 yellow_glazed_terracotta 0
fill ~106 ~0 ~45 ~106 ~2 ~45 yellow_glazed_terracotta 0
fill ~106 ~0 ~51 ~106 ~0 ~53 yellow_glazed_terracotta 0
fill ~107 ~0 ~27 ~108 ~0 ~27 yellow_glazed_terracotta 0
fill ~107 ~0 ~32 ~107 ~0 ~34 yellow_glazed_terracotta 0
fill ~107 ~0 ~41 ~107 ~1 ~41 yellow_glazed_terracotta 0
fill ~107 ~0 ~42 ~107 ~0 ~41 yellow_glazed_terracotta 0
fill ~107 ~0 ~54 ~107 ~2 ~54 yellow_glazed_terracotta 0
fill ~107 ~0 ~55 ~107 ~0 ~56 yellow_glazed_terracotta 0
fill ~108 ~0 ~26 ~110 ~0 ~26 yellow_glazed_terracotta 0
setblock ~108 ~0 ~35 yellow_glazed_terracotta 0
setblock ~108 ~0 ~36 stained_hardened_clay 4
setblock ~108 ~0 ~37 yellow_glazed_terracotta 0
setblock ~108 ~0 ~38 stained_hardened_clay 4
setblock ~108 ~0 ~39 yellow_glazed_terracotta 0
fill ~108 ~0 ~40 ~108 ~0 ~41 wool 1
fill ~108 ~0 ~57 ~109 ~0 ~57 yellow_glazed_terracotta 0
setblock ~109 ~0 ~38 yellow_glazed_terracotta 0
setblock ~109 ~0 ~39 wool 1
setblock ~109 ~0 ~40 yellow_glazed_terracotta 0
fill ~110 ~0 ~27 ~111 ~0 ~27 yellow_glazed_terracotta 0
fill ~111 ~0 ~56 ~112 ~0 ~56 yellow_glazed_terracotta 0
fill ~112 ~0 ~28 ~112 ~1 ~28 yellow_glazed_terracotta 0
fill ~112 ~0 ~29 ~112 ~0 ~28 yellow_glazed_terracotta 0
fill ~113 ~0 ~30 ~113 ~1 ~30 yellow_glazed_terracotta 0
fill ~113 ~0 ~31 ~113 ~0 ~30 yellow_glazed_terracotta 0
setblock ~113 ~0 ~57 yellow_glazed_terracotta 0
fill ~114 ~0 ~32 ~114 ~0 ~33 yellow_glazed_terracotta 0
fill ~114 ~0 ~56 ~114 ~1 ~56 yellow_glazed_terracotta 0
fill ~115 ~0 ~34 ~115 ~2 ~34 yellow_glazed_terracotta 0
fill ~115 ~0 ~35 ~115 ~1 ~35 yellow_glazed_terracotta 0
setblock ~115 ~0 ~55 yellow_glazed_terracotta 0
setblock ~115 ~0 ~56 sandstone 0
fill ~116 ~0 ~36 ~116 ~1 ~36 yellow_glazed_terracotta 0
fill ~116 ~0 ~37 ~116 ~0 ~38 yellow_glazed_terracotta 0
fill ~116 ~0 ~54 ~116 ~0 ~55 wool 1
fill ~117 ~0 ~39 ~117 ~2 ~39 yellow_glazed_terracotta 0
setblock ~117 ~0 ~53 sandstone 0
fill ~117 ~0 ~54 ~117 ~1 ~54 yellow_glazed_terracotta 0
fill ~118 ~0 ~40 ~118 ~1 ~40 yellow_glazed_terracotta 0
fill ~118 ~0 ~41 ~118 ~2 ~41 yellow_glazed_terracotta 0
setblock ~118 ~0 ~51 wool 1
fill ~118 ~0 ~52 ~118 ~1 ~52 yellow_glazed_terracotta 0
fill ~118 ~0 ~53 ~118 ~1 ~53 yellow_glazed_terracotta 0
fill ~119 ~0 ~42 ~119 ~1 ~42 yellow_glazed_terracotta 0
fill ~119 ~0 ~43 ~119 ~2 ~43 yellow_glazed_terracotta 0
fill ~119 ~0 ~44 ~119 ~2 ~44 yellow_glazed_terracotta 0
fill ~119 ~0 ~48 ~119 ~0 ~51 yellow_glazed_terracotta 0
fill ~120 ~0 ~46 ~120 ~1 ~46 yellow_glazed_terracotta 0
fill ~120 ~0 ~47 ~120 ~1 ~47 yellow_glazed_terracotta 0
setblock ~36 ~1 ~45 yellow_glazed_terracotta 0
setblock ~36 ~1 ~48 yellow_glazed_terracotta 0
fill ~37 ~1 ~49 ~37 ~2 ~49 yellow_glazed_terracotta 0
fill ~37 ~1 ~50 ~37 ~1 ~49 yellow_glazed_terracotta 0
setblock ~37 ~1 ~51 wool 1
setblock ~39 ~1 ~38 yellow_glazed_terracotta 0
setblock ~39 ~1 ~53 wool 1
setblock ~40 ~1 ~37 stained_hardened_clay 4
fill ~40 ~1 ~53 ~40 ~1 ~54 redstone_block 0
setblock ~40 ~1 ~55 concrete 1
setblock ~41 ~1 ~33 yellow_glazed_terracotta 0
setblock ~41 ~1 ~54 yellow_glazed_terracotta 0
fill ~41 ~1 ~55 ~42 ~1 ~55 wool 1
setblock ~42 ~1 ~31 glowstone 0
fill ~42 ~1 ~32 ~42 ~6 ~32 wool 1
setblock ~43 ~1 ~29 yellow_glazed_terracotta 0
fill ~43 ~1 ~56 ~44 ~1 ~56 yellow_glazed_terracotta 0
fill ~44 ~1 ~27 ~44 ~2 ~27 yellow_glazed_terracotta 0
setblock ~45 ~1 ~26 yellow_glazed_terracotta 0
setblock ~45 ~1 ~56 wool 1
fill ~46 ~1 ~25 ~47 ~1 ~25 wool 1
fill ~47 ~1 ~57 ~47 ~0 ~57 yellow_glazed_terracotta 0
fill ~48 ~1 ~26 ~48 ~2 ~26 wool 1
setblock ~48 ~1 ~56 wool 1
setblock ~49 ~1 ~26 yellow_glazed_terracotta 0
setblock ~49 ~1 ~34 yellow_glazed_terracotta 0
setblock ~49 ~1 ~35 stained_hardened_clay 4
setblock ~49 ~1 ~36 yellow_glazed_terracotta 0
setblock ~49 ~1 ~37 stained_hardened_clay 4
fill ~49 ~1 ~38 ~49 ~2 ~38 yellow_glazed_terracotta 0
setblock ~49 ~1 ~39 wool 1
fill ~49 ~1 ~40 ~49 ~7 ~40 yellow_glazed_terracotta 0
setblock ~49 ~1 ~53 stained_hardened_clay 4
setblock ~49 ~1 ~55 stained_hardened_clay 4
fill ~50 ~1 ~27 ~50 ~1 ~28 wool 1
setblock ~50 ~1 ~31 stained_hardened_clay 4
setblock ~50 ~1 ~32 yellow_glazed_terracotta 0
setblock ~50 ~1 ~33 stained_hardened_clay 4
fill ~50 ~1 ~42 ~50 ~2 ~42 yellow_glazed_terracotta 0
setblock ~50 ~1 ~49 stained_hardened_clay 4
setblock ~50 ~1 ~51 stained_hardened_clay 4
setblock ~50 ~1 ~52 yellow_glazed_terracotta 0
setblock ~51 ~1 ~29 wool 1
fill ~51 ~1 ~30 ~51 ~3 ~30 yellow_glazed_terracotta 0
setblock ~105 ~1 ~29 wool 1
fill ~105 ~1 ~30 ~105 ~3 ~30 yellow_glazed_terracotta 0
fill ~106 ~1 ~27 ~106 ~1 ~28 wool 1
setblock ~106 ~1 ~31 stained_hardened_clay 4
setblock ~106 ~1 ~32 yellow_glazed_terracotta 0
setblock ~106 ~1 ~33 stained_hardened_clay 4
fill ~106 ~1 ~42 ~106 ~2 ~42 yellow_glazed_terracotta 0
fill ~106 ~1 ~43 ~106 ~2 ~43 yellow_glazed_terracotta 0
setblock ~106 ~1 ~49 stained_hardened_clay 4
setblock ~106 ~1 ~51 stained_hardened_clay 4
setblock ~106 ~1 ~52 yellow_glazed_terracotta 0
setblock ~107 ~1 ~26 yellow_glazed_terracotta 0
setblock ~107 ~1 ~34 yellow_glazed_terracotta 0
setblock ~107 ~1 ~35 stained_hardened_clay 4
setblock ~107 ~1 ~36 yellow_glazed_terracotta 0
setblock ~107 ~1 ~37 stained_hardened_clay 4
fill ~107 ~1 ~38 ~107 ~2 ~38 yellow_glazed_terracotta 0
setblock ~107 ~1 ~39 wool 1
fill ~107 ~1 ~40 ~107 ~7 ~40 yellow_glazed_terracotta 0
setblock ~107 ~1 ~53 stained_hardened_clay 4
setblock ~107 ~1 ~55 stained_hardened_clay 4
fill ~108 ~1 ~26 ~108 ~2 ~26 wool 1
setblock ~108 ~1 ~56 wool 1
fill ~109 ~1 ~25 ~110 ~1 ~25 wool 1
setblock ~109 ~1 ~57 yellow_glazed_terracotta 0
setblock ~111 ~1 ~26 yellow_glazed_terracotta 0
setblock ~111 ~1 ~56 wool 1
fill ~112 ~1 ~27 ~112 ~2 ~27 yellow_glazed_terracotta 0
fill ~112 ~1 ~56 ~114 ~1 ~56 yellow_glazed_terracotta 0
setblock ~113 ~1 ~29 yellow_glazed_terracotta 0
setblock ~114 ~1 ~31 glowstone 0
fill ~114 ~1 ~32 ~114 ~6 ~32 wool 1
fill ~114 ~1 ~55 ~115 ~1 ~55 wool 1
setblock ~115 ~1 ~33 yellow_glazed_terracotta 0
setblock ~115 ~1 ~54 yellow_glazed_terracotta 0
setblock ~116 ~1 ~37 stained_hardened_clay 4
fill ~116 ~1 ~53 ~116 ~1 ~54 redstone_block 0
setblock ~116 ~1 ~55 concrete 1
setblock ~117 ~1 ~38 yellow_glazed_terracotta 0
setblock ~117 ~1 ~53 wool 1
fill ~119 ~1 ~49 ~119 ~2 ~49 yellow_glazed_terracotta 0
fill ~119 ~1 ~50 ~119 ~1 ~49 yellow_glazed_terracotta 0
setblock ~119 ~1 ~51 wool 1
setblock ~120 ~1 ~45 yellow_glazed_terracotta 0
setblock ~120 ~1 ~48 yellow_glazed_terracotta 0
fill ~37 ~2 ~45 ~37 ~2 ~49 yellow_glazed_terracotta 0
setblock ~38 ~2 ~42 yellow_glazed_terracotta 0
setblock ~38 ~2 ~49 yellow_glazed_terracotta 0
setblock ~38 ~2 ~50 wool 1
setblock ~38 ~2 ~51 yellow_glazed_terracotta 0
fill ~39 ~2 ~40 ~39 ~3 ~40 yellow_glazed_terracotta 0
fill ~39 ~2 ~52 ~40 ~2 ~52 yellow_glazed_terracotta 0
setblock ~40 ~2 ~36 wool 1
fill ~40 ~2 ~37 ~40 ~2 ~38 yellow_glazed_terracotta 0
fill ~41 ~2 ~35 ~41 ~3 ~35 wool 1
setblock ~41 ~2 ~53 wool 1
fill ~42 ~2 ~31 ~42 ~3 ~31 wool 1
fill ~42 ~2 ~33 ~42 ~3 ~33 wool 1
setblock ~42 ~2 ~54 yellow_glazed_terracotta 0
setblock ~43 ~2 ~28 yellow_glazed_terracotta 0
fill ~43 ~2 ~29 ~43 ~4 ~29 wool 1
fill ~43 ~2 ~30 ~43 ~6 ~30 wool 1
setblock ~43 ~2 ~54 red_mushroom_block 0
setblock ~43 ~2 ~55 wool 1
fill ~44 ~2 ~55 ~45 ~2 ~55 yellow_glazed_terracotta 0
fill ~45 ~2 ~26 ~45 ~3 ~26 wool 1
fill ~46 ~2 ~25 ~47 ~2 ~25 wool 1
setblock ~46 ~2 ~55 red_mushroom_block 0
fill ~47 ~2 ~55 ~48 ~2 ~55 yellow_glazed_terracotta 0
fill ~47 ~2 ~56 ~47 ~2 ~55 yellow_glazed_terracotta 0
setblock ~48 ~2 ~54 yellow_glazed_terracotta 0
fill ~49 ~2 ~26 ~49 ~3 ~26 wool 1
setblock ~49 ~2 ~39 yellow_glazed_terracotta 0
fill ~49 ~2 ~51 ~49 ~2 ~54 yellow_glazed_terracotta 0
setblock ~50 ~2 ~27 yellow_glazed_terracotta 0
setblock ~50 ~2 ~28 wool 1
fill ~50 ~2 ~32 ~50 ~3 ~32 wool 1
setblock ~50 ~2 ~33 yellow_glazed_terracotta 0
fill ~50 ~2 ~34 ~50 ~5 ~34 wool 1
fill ~50 ~2 ~35 ~50 ~2 ~37 yellow_glazed_terracotta 0
setblock ~50 ~2 ~41 yellow_glazed_terracotta 0
setblock ~50 ~2 ~49 yellow_glazed_terracotta 0
setblock ~50 ~2 ~50 stained_hardened_clay 4
setblock ~51 ~2 ~29 yellow_glazed_terracotta 0
setblock ~51 ~2 ~31 wool 1
setblock ~105 ~2 ~29 yellow_glazed_terracotta 0
setblock ~105 ~2 ~31 wool 1
setblock ~106 ~2 ~27 yellow_glazed_terracotta 0
setblock ~106 ~2 ~28 wool 1
fill ~106 ~2 ~32 ~106 ~3 ~32 wool 1
setblock ~106 ~2 ~33 yellow_glazed_terracotta 0
fill ~106 ~2 ~34 ~106 ~5 ~34 wool 1
fill ~106 ~2 ~35 ~106 ~2 ~37 yellow_glazed_terracotta 0
setblock ~106 ~2 ~41 yellow_glazed_terracotta 0
setblock ~106 ~2 ~49 yellow_glazed_terracotta 0
setblock ~106 ~2 ~50 stained_hardened_clay 4
fill ~107 ~2 ~26 ~107 ~3 ~26 wool 1
setblock ~107 ~2 ~39 yellow_glazed_terracotta 0
fill ~107 ~2 ~51 ~107 ~2 ~54 yellow_glazed_terracotta 0
fill ~108 ~2 ~54 ~108 ~2 ~55 yellow_glazed_terracotta 0
fill ~109 ~2 ~25 ~110 ~2 ~25 wool 1
fill ~109 ~2 ~55 ~109 ~2 ~56 yellow_glazed_terracotta 0
setblock ~110 ~2 ~55 red_mushroom_block 0
fill ~111 ~2 ~26 ~111 ~3 ~26 wool 1
fill ~111 ~2 ~55 ~112 ~2 ~55 yellow_glazed_terracotta 0
setblock ~113 ~2 ~28 yellow_glazed_terracotta 0
fill ~113 ~2 ~29 ~113 ~4 ~29 wool 1
fill ~113 ~2 ~30 ~113 ~6 ~30 wool 1
setblock ~113 ~2 ~54 red_mushroom_block 0
setblock ~113 ~2 ~55 wool 1
fill ~114 ~2 ~31 ~114 ~3 ~31 wool 1
fill ~114 ~2 ~33 ~114 ~3 ~33 wool 1
setblock ~114 ~2 ~54 yellow_glazed_terracotta 0
fill ~115 ~2 ~35 ~115 ~3 ~35 wool 1
setblock ~115 ~2 ~53 wool 1
setblock ~116 ~2 ~36 wool 1
fill ~116 ~2 ~37 ~116 ~2 ~38 yellow_glazed_terracotta 0
fill ~116 ~2 ~52 ~117 ~2 ~52 yellow_glazed_terracotta 0
fill ~117 ~2 ~40 ~117 ~3 ~40 yellow_glazed_terracotta 0
setblock ~118 ~2 ~42 yellow_glazed_terracotta 0
setblock ~118 ~2 ~49 yellow_glazed_terracotta 0
setblock ~118 ~2 ~50 wool 1
setblock ~118 ~2 ~51 yellow_glazed_terracotta 0
fill ~119 ~2 ~45 ~119 ~2 ~49 yellow_glazed_terracotta 0
setblock ~38 ~3 ~43 stained_hardened_clay 4
setblock ~38 ~3 ~44 yellow_glazed_terracotta 0
setblock ~38 ~3 ~45 stained_hardened_clay 4
setblock ~38 ~3 ~46 yellow_glazed_terracotta 0
setblock ~38 ~3 ~47 stained_hardened_clay 4
fill ~38 ~3 ~48 ~38 ~3 ~49 wool 1
fill ~39 ~3 ~41 ~39 ~3 ~42 yellow_glazed_terracotta 0
fill ~39 ~3 ~49 ~39 ~3 ~51 wool 1
setblock ~40 ~3 ~37 stained_hardened_clay 4
setblock ~40 ~3 ~38 yellow_glazed_terracotta 0
setblock ~40 ~3 ~39 stained_hardened_clay 4
setblock ~40 ~3 ~51 wool 1
setblock ~41 ~3 ~34 wool 1
fill ~41 ~3 ~36 ~41 ~4 ~36 yellow_glazed_terracotta 0
setblock ~41 ~3 ~52 wool 1
fill ~42 ~3 ~52 ~42 ~3 ~53 yellow_glazed_terracotta 0
setblock ~43 ~3 ~28 wool 1
setblock ~43 ~3 ~53 red_sandstone 0
setblock ~44 ~3 ~27 wool 1
fill ~44 ~3 ~53 ~45 ~3 ~53 yellow_glazed_terracotta 0
fill ~44 ~3 ~54 ~45 ~3 ~54 yellow_glazed_terracotta 0
fill ~45 ~3 ~52 ~46 ~3 ~52 wool 1
fill ~46 ~3 ~25 ~48 ~3 ~25 wool 1
fill ~46 ~3 ~53 ~46 ~3 ~54 wool 1
setblock ~47 ~3 ~51 wool 1
fill ~47 ~3 ~52 ~48 ~3 ~52 yellow_glazed_terracotta 0
fill ~47 ~3 ~53 ~48 ~3 ~53 yellow_glazed_terracotta 0
fill ~47 ~3 ~54 ~47 ~3 ~52 yellow_glazed_terracotta 0
fill ~48 ~3 ~50 ~49 ~3 ~50 yellow_glazed_terracotta 0
setblock ~48 ~3 ~51 stained_hardened_clay 4
setblock ~49 ~3 ~39 stained_hardened_clay 4
fill ~49 ~3 ~41 ~49 ~4 ~41 yellow_glazed_terracotta 0
fill ~49 ~3 ~42 ~49 ~5 ~42 yellow_glazed_terracotta 0
fill ~49 ~3 ~43 ~49 ~4 ~43 yellow_glazed_terracotta 0
fill ~49 ~3 ~44 ~49 ~4 ~44 yellow_glazed_terracotta 0
fill ~49 ~3 ~45 ~49 ~4 ~45 yellow_glazed_terracotta 0
fill ~49 ~3 ~46 ~49 ~4 ~46 yellow_glazed_terracotta 0
fill ~49 ~3 ~47 ~49 ~3 ~50 yellow_glazed_terracotta 0
setblock ~50 ~3 ~27 wool 1
setblock ~50 ~3 ~31 red_sandstone 0
setblock ~50 ~3 ~33 red_sandstone 0
setblock ~50 ~3 ~35 stained_hardened_clay 4
setblock ~50 ~3 ~36 yellow_glazed_terracotta 0
fill ~50 ~3 ~37 ~50 ~3 ~38 stained_hardened_clay 4
fill ~51 ~3 ~28 ~51 ~3 ~29 wool 1
fill ~105 ~3 ~28 ~105 ~3 ~29 wool 1
setblock ~106 ~3 ~27 wool 1
setblock ~106 ~3 ~31 red_sandstone 0
setblock ~106 ~3 ~33 red_sandstone 0
setblock ~106 ~3 ~35 stained_hardened_clay 4
setblock ~106 ~3 ~36 yellow_glazed_terracotta 0
fill ~106 ~3 ~37 ~106 ~3 ~38 stained_hardened_clay 4
setblock ~107 ~3 ~39 stained_hardened_clay 4
fill ~107 ~3 ~41 ~107 ~4 ~41 yellow_glazed_terracotta 0
fill ~107 ~3 ~42 ~107 ~5 ~42 yellow_glazed_terracotta 0
fill ~107 ~3 ~43 ~107 ~4 ~43 yellow_glazed_terracotta 0
fill ~107 ~3 ~44 ~107 ~4 ~44 yellow_glazed_terracotta 0
fill ~107 ~3 ~45 ~107 ~4 ~45 yellow_glazed_terracotta 0
fill ~107 ~3 ~46 ~107 ~4 ~46 yellow_glazed_terracotta 0
fill ~107 ~3 ~47 ~107 ~3 ~50 yellow_glazed_terracotta 0
fill ~108 ~3 ~25 ~110 ~3 ~25 wool 1
setblock ~108 ~3 ~50 yellow_glazed_terracotta 0
setblock ~108 ~3 ~51 stained_hardened_clay 4
fill ~108 ~3 ~52 ~109 ~3 ~52 yellow_glazed_terracotta 0
fill ~108 ~3 ~53 ~109 ~3 ~53 yellow_glazed_terracotta 0
setblock ~109 ~3 ~51 wool 1
setblock ~109 ~3 ~54 yellow_glazed_terracotta 0
fill ~110 ~3 ~52 ~111 ~3 ~52 wool 1
fill ~110 ~3 ~53 ~110 ~3 ~54 wool 1
fill ~111 ~3 ~53 ~112 ~3 ~53 yellow_glazed_terracotta 0
fill ~111 ~3 ~54 ~112 ~3 ~54 yellow_glazed_terracotta 0
setblock ~112 ~3 ~27 wool 1
setblock ~113 ~3 ~28 wool 1
setblock ~113 ~3 ~53 red_sandstone 0
fill ~114 ~3 ~52 ~114 ~3 ~53 yellow_glazed_terracotta 0
setblock ~115 ~3 ~34 wool 1
fill ~115 ~3 ~36 ~115 ~4 ~36 yellow_glazed_terracotta 0
setblock ~115 ~3 ~52 wool 1
setblock ~116 ~3 ~37 stained_hardened_clay 4
setblock ~116 ~3 ~38 yellow_glazed_terracotta 0
setblock ~116 ~3 ~39 stained_hardened_clay 4
fill ~116 ~3 ~51 ~117 ~3 ~51 wool 1
fill ~117 ~3 ~41 ~117 ~3 ~42 yellow_glazed_terracotta 0
fill ~117 ~3 ~49 ~118 ~3 ~49 wool 1
fill ~117 ~3 ~50 ~117 ~3 ~49 wool 1
setblock ~118 ~3 ~43 stained_hardened_clay 4
setblock ~118 ~3 ~44 yellow_glazed_terracotta 0
setblock ~118 ~3 ~45 stained_hardened_clay 4
setblock ~118 ~3 ~46 yellow_glazed_terracotta 0
setblock ~118 ~3 ~47 stained_hardened_clay 4
setblock ~118 ~3 ~48 wool 1
fill ~39 ~4 ~43 ~39 ~4 ~46 yellow_glazed_terracotta 0
setblock ~39 ~4 ~47 wool 1
setblock ~39 ~4 ~48 yellow_glazed_terracotta 0
setblock ~40 ~4 ~40 stained_hardened_clay 4
setblock ~40 ~4 ~41 yellow_glazed_terracotta 0
setblock ~40 ~4 ~42 stained_hardened_clay 4
setblock ~40 ~4 ~45 wool 1
setblock ~40 ~4 ~46 stained_hardened_clay 4
setblock ~40 ~4 ~47 yellow_glazed_terracotta 0
setblock ~40 ~4 ~48 stained_hardened_clay 4
fill ~40 ~4 ~49 ~41 ~4 ~49 yellow_glazed_terracotta 0
setblock ~40 ~4 ~50 wool 1
setblock ~41 ~4 ~37 wool 1
setblock ~41 ~4 ~38 yellow_glazed_terracotta 0
fill ~41 ~4 ~39 ~41 ~5 ~39 wool 1
fill ~41 ~4 ~50 ~41 ~4 ~51 yellow_glazed_terracotta 0
setblock ~42 ~4 ~33 concrete 4
fill ~42 ~4 ~34 ~42 ~5 ~34 wool 1
setblock ~42 ~4 ~35 yellow_glazed_terracotta 0
setblock ~42 ~4 ~50 stained_hardened_clay 4
fill ~42 ~4 ~51 ~44 ~4 ~51 yellow_glazed_terracotta 0
fill ~43 ~4 ~31 ~43 ~6 ~31 wool 1
setblock ~43 ~4 ~50 yellow_glazed_terracotta 0
fill ~43 ~4 ~52 ~44 ~4 ~52 wool 1
setblock ~44 ~4 ~27 yellow_glazed_terracotta 0
fill ~44 ~4 ~28 ~44 ~6 ~28 wool 1
setblock ~44 ~4 ~50 stained_hardened_clay 4
setblock ~45 ~4 ~26 yellow_glazed_terracotta 0
setblock ~45 ~4 ~50 yellow_glazed_terracotta 0
setblock ~45 ~4 ~51 wool 1
setblock ~46 ~4 ~25 concrete 4
setblock ~46 ~4 ~50 stained_hardened_clay 4
setblock ~46 ~4 ~51 yellow_glazed_terracotta 0
setblock ~47 ~4 ~25 wool 1
setblock ~47 ~4 ~49 wool 1
setblock ~47 ~4 ~50 yellow_glazed_terracotta 0
fill ~48 ~4 ~26 ~48 ~6 ~26 wool 1
setblock ~48 ~4 ~46 stained_hardened_clay 4
setblock ~48 ~4 ~47 yellow_glazed_terracotta 0
setblock ~48 ~4 ~48 stained_hardened_clay 4
setblock ~48 ~4 ~49 yellow_glazed_terracotta 0
setblock ~49 ~4 ~26 yellow_glazed_terracotta 0
setblock ~49 ~4 ~39 yellow_glazed_terracotta 0
setblock ~50 ~4 ~27 yellow_glazed_terracotta 0
fill ~50 ~4 ~28 ~50 ~7 ~28 wool 1
setblock ~50 ~4 ~31 wool 1
setblock ~50 ~4 ~32 red_sandstone 0
setblock ~50 ~4 ~33 wool 1
setblock ~50 ~4 ~35 yellow_glazed_terracotta 0
setblock ~50 ~4 ~36 stained_hardened_clay 4
setblock ~50 ~4 ~37 yellow_glazed_terracotta 0
setblock ~50 ~4 ~38 stained_hardened_clay 4
setblock ~51 ~4 ~29 yellow_glazed_terracotta 0
fill ~51 ~4 ~30 ~51 ~5 ~30 wool 1
setblock ~105 ~4 ~29 yellow_glazed_terracotta 0
fill ~105 ~4 ~30 ~105 ~5 ~30 wool 1
setblock ~106 ~4 ~27 yellow_glazed_terracotta 0
fill ~106 ~4 ~28 ~106 ~7 ~28 wool 1
setblock ~106 ~4 ~31 wool 1
setblock ~106 ~4 ~32 red_sandstone 0
setblock ~106 ~4 ~33 wool 1
setblock ~106 ~4 ~35 yellow_glazed_terracotta 0
setblock ~106 ~4 ~36 stained_hardened_clay 4
setblock ~106 ~4 ~37 yellow_glazed_terracotta 0
setblock ~106 ~4 ~38 stained_hardened_clay 4
setblock ~107 ~4 ~26 yellow_glazed_terracotta 0
setblock ~107 ~4 ~39 yellow_glazed_terracotta 0
fill ~108 ~4 ~26 ~108 ~6 ~26 wool 1
setblock ~108 ~4 ~46 stained_hardened_clay 4
setblock ~108 ~4 ~47 yellow_glazed_terracotta 0
setblock ~108 ~4 ~48 stained_hardened_clay 4
setblock ~108 ~4 ~49 yellow_glazed_terracotta 0
setblock ~109 ~4 ~25 wool 1
setblock ~109 ~4 ~49 wool 1
setblock ~109 ~4 ~50 yellow_glazed_terracotta 0
setblock ~110 ~4 ~25 concrete 4
setblock ~110 ~4 ~50 stained_hardened_clay 4
setblock ~110 ~4 ~51 yellow_glazed_terracotta 0
setblock ~111 ~4 ~26 yellow_glazed_terracotta 0
setblock ~111 ~4 ~50 yellow_glazed_terracotta 0
setblock ~111 ~4 ~51 wool 1
setblock ~112 ~4 ~27 yellow_glazed_terracotta 0
fill ~112 ~4 ~28 ~112 ~6 ~28 wool 1
setblock ~112 ~4 ~50 stained_hardened_clay 4
fill ~112 ~4 ~51 ~115 ~4 ~51 yellow_glazed_terracotta 0
fill ~112 ~4 ~52 ~113 ~4 ~52 wool 1
fill ~113 ~4 ~31 ~113 ~6 ~31 wool 1
setblock ~113 ~4 ~50 yellow_glazed_terracotta 0
setblock ~114 ~4 ~33 concrete 4
fill ~114 ~4 ~34 ~114 ~5 ~34 wool 1
setblock ~114 ~4 ~35 yellow_glazed_terracotta 0
setblock ~114 ~4 ~50 stained_hardened_clay 4
setblock ~115 ~4 ~37 wool 1
setblock ~115 ~4 ~38 yellow_glazed_terracotta 0
fill ~115 ~4 ~39 ~115 ~5 ~39 wool 1
fill ~115 ~4 ~49 ~116 ~4 ~49 yellow_glazed_terracotta 0
fill ~115 ~4 ~50 ~115 ~4 ~49 yellow_glazed_terracotta 0
setblock ~116 ~4 ~40 stained_hardened_clay 4
setblock ~116 ~4 ~41 yellow_glazed_terracotta 0
setblock ~116 ~4 ~42 stained_hardened_clay 4
setblock ~116 ~4 ~45 wool 1
setblock ~116 ~4 ~46 stained_hardened_clay 4
setblock ~116 ~4 ~47 yellow_glazed_terracotta 0
setblock ~116 ~4 ~48 stained_hardened_clay 4
setblock ~116 ~4 ~50 wool 1
fill ~117 ~4 ~43 ~117 ~4 ~46 yellow_glazed_terracotta 0
setblock ~117 ~4 ~47 wool 1
setblock ~117 ~4 ~48 yellow_glazed_terracotta 0
setblock ~40 ~5 ~43 stained_hardened_clay 4
setblock ~40 ~5 ~44 wool 1
setblock ~41 ~5 ~38 wool 1
fill ~41 ~5 ~40 ~41 ~5 ~42 wool 1
fill ~41 ~5 ~44 ~41 ~5 ~48 yellow_glazed_terracotta 0
fill ~42 ~5 ~33 ~42 ~6 ~33 wool 1
fill ~42 ~5 ~35 ~42 ~6 ~35 wool 1
fill ~42 ~5 ~36 ~42 ~8 ~36 wool 1
fill ~42 ~5 ~37 ~42 ~7 ~37 wool 1
setblock ~42 ~5 ~47 stained_hardened_clay 4
fill ~42 ~5 ~48 ~43 ~5 ~48 yellow_glazed_terracotta 0
fill ~42 ~5 ~49 ~46 ~5 ~49 stained_hardened_clay 4
setblock ~43 ~5 ~47 yellow_glazed_terracotta 0
setblock ~44 ~5 ~27 wool 1
setblock ~44 ~5 ~29 concrete 1
setblock ~44 ~5 ~48 stained_hardened_clay 4
fill ~45 ~5 ~26 ~49 ~5 ~26 wool 1
setblock ~45 ~5 ~48 yellow_glazed_terracotta 0
setblock ~46 ~5 ~48 stained_hardened_clay 4
setblock ~47 ~5 ~46 wool 1
setblock ~47 ~5 ~47 stained_hardened_clay 4
setblock ~47 ~5 ~48 yellow_glazed_terracotta 0
setblock ~48 ~5 ~43 stained_hardened_clay 4
setblock ~48 ~5 ~44 wool 1
setblock ~48 ~5 ~45 stained_hardened_clay 4
fill ~49 ~5 ~38 ~49 ~6 ~38 yellow_glazed_terracotta 0
setblock ~49 ~5 ~39 stained_hardened_clay 4
setblock ~49 ~5 ~41 stained_hardened_clay 4
setblock ~50 ~5 ~27 wool 1
setblock ~50 ~5 ~31 red_sandstone 0
setblock ~50 ~5 ~35 stained_hardened_clay 4
fill ~50 ~5 ~36 ~50 ~8 ~36 wool 1
setblock ~50 ~5 ~37 stained_hardened_clay 4
setblock ~51 ~5 ~29 wool 1
fill ~51 ~5 ~32 ~51 ~5 ~33 wool 1
setblock ~105 ~5 ~29 wool 1
fill ~105 ~5 ~32 ~105 ~5 ~33 wool 1
setblock ~106 ~5 ~27 wool 1
setblock ~106 ~5 ~31 red_sandstone 0
setblock ~106 ~5 ~35 stained_hardened_clay 4
fill ~106 ~5 ~36 ~106 ~8 ~36 wool 1
setblock ~106 ~5 ~37 stained_hardened_clay 4
setblock ~107 ~5 ~26 wool 1
fill ~107 ~5 ~38 ~107 ~6 ~38 yellow_glazed_terracotta 0
setblock ~107 ~5 ~39 stained_hardened_clay 4
setblock ~107 ~5 ~41 stained_hardened_clay 4
setblock ~108 ~5 ~43 stained_hardened_clay 4
setblock ~108 ~5 ~44 wool 1
setblock ~108 ~5 ~45 stained_hardened_clay 4
fill ~109 ~5 ~26 ~111 ~5 ~26 wool 1
setblock ~109 ~5 ~46 wool 1
setblock ~109 ~5 ~47 stained_hardened_clay 4
setblock ~109 ~5 ~48 yellow_glazed_terracotta 0
fill ~110 ~5 ~48 ~110 ~5 ~49 stained_hardened_clay 4
setblock ~111 ~5 ~48 yellow_glazed_terracotta 0
fill ~111 ~5 ~49 ~114 ~5 ~49 stained_hardened_clay 4
setblock ~112 ~5 ~27 wool 1
setblock ~112 ~5 ~29 concrete 1
setblock ~112 ~5 ~48 stained_hardened_clay 4
fill ~113 ~5 ~47 ~113 ~5 ~48 yellow_glazed_terracotta 0
fill ~114 ~5 ~33 ~114 ~6 ~33 wool 1
fill ~114 ~5 ~35 ~114 ~6 ~35 wool 1
fill ~114 ~5 ~36 ~114 ~8 ~36 wool 1
fill ~114 ~5 ~37 ~114 ~7 ~37 wool 1
setblock ~114 ~5 ~47 stained_hardened_clay 4
fill ~114 ~5 ~48 ~115 ~5 ~48 yellow_glazed_terracotta 0
setblock ~115 ~5 ~38 wool 1
fill ~115 ~5 ~40 ~115 ~5 ~42 wool 1
fill ~115 ~5 ~44 ~115 ~5 ~48 yellow_glazed_terracotta 0
setblock ~116 ~5 ~43 stained_hardened_clay 4
setblock ~116 ~5 ~44 wool 1
fill ~41 ~6 ~42 ~41 ~6 ~43 yellow_glazed_terracotta 0
setblock ~42 ~6 ~34 red_sandstone 0
fill ~42 ~6 ~38 ~42 ~7 ~38 wool 1
fill ~42 ~6 ~39 ~42 ~6 ~40 wool 1
setblock ~42 ~6 ~41 concrete 4
setblock ~42 ~6 ~42 stained_hardened_clay 4
setblock ~42 ~6 ~43 wool 1
setblock ~42 ~6 ~44 stained_hardened_clay 4
fill ~42 ~6 ~45 ~44 ~6 ~45 yellow_glazed_terracotta 0
setblock ~42 ~6 ~46 stained_hardened_clay 4
setblock ~43 ~6 ~46 yellow_glazed_terracotta 0
setblock ~44 ~6 ~29 wool 1
setblock ~44 ~6 ~46 red_sandstone 0
fill ~44 ~6 ~47 ~46 ~6 ~47 yellow_glazed_terracotta 0
fill ~45 ~6 ~27 ~45 ~7 ~27 wool 1
setblock ~45 ~6 ~46 yellow_glazed_terracotta 0
fill ~46 ~6 ~26 ~48 ~6 ~26 wool 1
setblock ~46 ~6 ~45 yellow_glazed_terracotta 0
setblock ~46 ~6 ~46 stained_hardened_clay 4
setblock ~47 ~6 ~44 yellow_glazed_terracotta 0
setblock ~47 ~6 ~45 wool 1
setblock ~48 ~6 ~42 stained_hardened_clay 4
setblock ~48 ~6 ~43 yellow_glazed_terracotta 0
fill ~49 ~6 ~27 ~49 ~7 ~27 wool 1
setblock ~49 ~6 ~39 concrete 4
setblock ~49 ~6 ~41 yellow_glazed_terracotta 0
fill ~50 ~6 ~29 ~50 ~7 ~29 wool 1
setblock ~50 ~6 ~30 red_sandstone 0
setblock ~50 ~6 ~31 wool 1
setblock ~50 ~6 ~35 wool 1
setblock ~50 ~6 ~37 yellow_glazed_terracotta 0
fill ~51 ~6 ~32 ~51 ~10 ~32 yellow_glazed_terracotta 0
fill ~51 ~6 ~33 ~51 ~7 ~33 wool 1
fill ~51 ~6 ~34 ~51 ~16 ~34 yellow_glazed_terracotta 0
fill ~105 ~6 ~32 ~105 ~10 ~32 yellow_glazed_terracotta 0
fill ~105 ~6 ~33 ~105 ~7 ~33 wool 1
fill ~105 ~6 ~34 ~105 ~16 ~34 yellow_glazed_terracotta 0
fill ~106 ~6 ~29 ~106 ~7 ~29 wool 1
setblock ~106 ~6 ~30 red_sandstone 0
setblock ~106 ~6 ~31 wool 1
setblock ~106 ~6 ~35 wool 1
setblock ~106 ~6 ~37 yellow_glazed_terracotta 0
fill ~107 ~6 ~27 ~107 ~7 ~27 wool 1
setblock ~107 ~6 ~39 concrete 4
setblock ~107 ~6 ~41 yellow_glazed_terracotta 0
setblock ~108 ~6 ~42 stained_hardened_clay 4
setblock ~108 ~6 ~43 yellow_glazed_terracotta 0
fill ~109 ~6 ~26 ~110 ~6 ~26 wool 1
setblock ~109 ~6 ~44 yellow_glazed_terracotta 0
setblock ~109 ~6 ~45 wool 1
setblock ~110 ~6 ~45 yellow_glazed_terracotta 0
setblock ~110 ~6 ~46 stained_hardened_clay 4
fill ~110 ~6 ~47 ~112 ~6 ~47 yellow_glazed_terracotta 0
fill ~111 ~6 ~27 ~111 ~7 ~27 wool 1
setblock ~111 ~6 ~46 yellow_glazed_terracotta 0
setblock ~112 ~6 ~29 wool 1
fill ~112 ~6 ~45 ~114 ~6 ~45 yellow_glazed_terracotta 0
setblock ~112 ~6 ~46 red_sandstone 0
setblock ~113 ~6 ~46 yellow_glazed_terracotta 0
setblock ~114 ~6 ~34 red_sandstone 0
fill ~114 ~6 ~38 ~114 ~7 ~38 wool 1
fill ~114 ~6 ~39 ~114 ~6 ~40 wool 1
setblock ~114 ~6 ~41 concrete 4
setblock ~114 ~6 ~42 stained_hardened_clay 4
setblock ~114 ~6 ~43 wool 1
setblock ~114 ~6 ~44 stained_hardened_clay 4
setblock ~114 ~6 ~46 stained_hardened_clay 4
fill ~115 ~6 ~42 ~115 ~6 ~43 yellow_glazed_terracotta 0
setblock ~42 ~7 ~33 stained_hardened_clay 4
fill ~42 ~7 ~34 ~42 ~8 ~34 wool 1
setblock ~42 ~7 ~35 stained_hardened_clay 4
setblock ~42 ~7 ~39 stained_hardened_clay 4
setblock ~42 ~7 ~40 wool 1
fill ~43 ~7 ~31 ~43 ~9 ~31 yellow_glazed_terracotta 0
fill ~43 ~7 ~32 ~43 ~13 ~32 yellow_glazed_terracotta 0
fill ~43 ~7 ~41 ~43 ~7 ~43 wool 1
setblock ~43 ~7 ~44 concrete 4
setblock ~44 ~7 ~29 red_mushroom_block 0
fill ~44 ~7 ~30 ~44 ~9 ~30 wool 1
setblock ~44 ~7 ~44 wool 1
setblock ~45 ~7 ~28 wool 1
setblock ~45 ~7 ~44 concrete 4
setblock ~45 ~7 ~45 stained_hardened_clay 4
fill ~46 ~7 ~27 ~49 ~7 ~27 wool 1
setblock ~46 ~7 ~44 wool 1
setblock ~47 ~7 ~43 wool 1
setblock ~48 ~7 ~41 stained_hardened_clay 4
setblock ~48 ~7 ~42 wool 1
fill ~49 ~7 ~39 ~49 ~8 ~39 wool 1
setblock ~50 ~7 ~30 wool 1
setblock ~50 ~7 ~31 red_sandstone 0
setblock ~50 ~7 ~37 red_sandstone 0
setblock ~50 ~7 ~38 wool 1
setblock ~51 ~7 ~35 wool 1
setblock ~105 ~7 ~35 wool 1
setblock ~106 ~7 ~30 wool 1
setblock ~106 ~7 ~31 red_sandstone 0
setblock ~106 ~7 ~37 red_sandstone 0
setblock ~106 ~7 ~38 wool 1
fill ~107 ~7 ~39 ~107 ~8 ~39 wool 1
fill ~108 ~7 ~27 ~111 ~7 ~27 wool 1
setblock ~108 ~7 ~41 stained_hardened_clay 4
setblock ~108 ~7 ~42 wool 1
setblock ~109 ~7 ~43 wool 1
setblock ~110 ~7 ~44 wool 1
setblock ~111 ~7 ~28 wool 1
setblock ~111 ~7 ~44 concrete 4
setblock ~111 ~7 ~45 stained_hardened_clay 4
setblock ~112 ~7 ~29 red_mushroom_block 0
fill ~112 ~7 ~30 ~112 ~9 ~30 wool 1
setblock ~112 ~7 ~44 wool 1
fill ~113 ~7 ~31 ~113 ~9 ~31 yellow_glazed_terracotta 0
fill ~113 ~7 ~32 ~113 ~13 ~32 yellow_glazed_terracotta 0
fill ~113 ~7 ~41 ~113 ~7 ~43 wool 1
setblock ~113 ~7 ~44 concrete 4
setblock ~114 ~7 ~33 stained_hardened_clay 4
fill ~114 ~7 ~34 ~114 ~8 ~34 wool 1
setblock ~114 ~7 ~35 stained_hardened_clay 4
setblock ~114 ~7 ~39 stained_hardened_clay 4
setblock ~114 ~7 ~40 wool 1
fill ~42 ~8 ~35 ~42 ~9 ~35 wool 1
fill ~43 ~8 ~33 ~43 ~9 ~33 yellow_glazed_terracotta 0
fill ~43 ~8 ~37 ~43 ~17 ~37 wool 1
fill ~43 ~8 ~38 ~43 ~8 ~39 concrete 4
setblock ~43 ~8 ~40 yellow_glazed_terracotta 0
setblock ~43 ~8 ~41 concrete 4
setblock ~44 ~8 ~42 stained_hardened_clay 4
setblock ~44 ~8 ~43 yellow_glazed_terracotta 0
setblock ~45 ~8 ~28 concrete 4
setblock ~45 ~8 ~29 concrete 1
setblock ~45 ~8 ~42 yellow_glazed_terracotta 0
setblock ~45 ~8 ~43 concrete 4
fill ~46 ~8 ~27 ~48 ~8 ~27 wool 1
setblock ~46 ~8 ~42 stained_hardened_clay 4
setblock ~46 ~8 ~43 yellow_glazed_terracotta 0
setblock ~47 ~8 ~42 yellow_glazed_terracotta 0
fill ~48 ~8 ~40 ~48 ~9 ~40 wool 1
setblock ~48 ~8 ~41 concrete 4
setblock ~49 ~8 ~28 yellow_glazed_terracotta 0
fill ~49 ~8 ~38 ~49 ~11 ~38 wool 1
setblock ~50 ~8 ~29 yellow_glazed_terracotta 0
setblock ~50 ~8 ~30 red_sandstone 0
setblock ~50 ~8 ~31 yellow_glazed_terracotta 0
setblock ~50 ~8 ~37 wool 1
fill ~51 ~8 ~33 ~51 ~10 ~33 yellow_glazed_terracotta 0
fill ~51 ~8 ~35 ~51 ~12 ~35 yellow_glazed_terracotta 0
fill ~105 ~8 ~33 ~105 ~10 ~33 yellow_glazed_terracotta 0
fill ~105 ~8 ~35 ~105 ~12 ~35 yellow_glazed_terracotta 0
setblock ~106 ~8 ~29 yellow_glazed_terracotta 0
setblock ~106 ~8 ~30 red_sandstone 0
setblock ~106 ~8 ~31 yellow_glazed_terracotta 0
setblock ~106 ~8 ~37 wool 1
setblock ~107 ~8 ~28 yellow_glazed_terracotta 0
fill ~107 ~8 ~38 ~107 ~11 ~38 wool 1
fill ~108 ~8 ~27 ~110 ~8 ~27 wool 1
fill ~108 ~8 ~40 ~108 ~9 ~40 wool 1
setblock ~108 ~8 ~41 concrete 4
setblock ~109 ~8 ~42 yellow_glazed_terracotta 0
setblock ~110 ~8 ~42 stained_hardened_clay 4
setblock ~110 ~8 ~43 yellow_glazed_terracotta 0
setblock ~111 ~8 ~28 concrete 4
setblock ~111 ~8 ~29 concrete 1
setblock ~111 ~8 ~42 yellow_glazed_terracotta 0
setblock ~111 ~8 ~43 concrete 4
setblock ~112 ~8 ~42 stained_hardened_clay 4
setblock ~112 ~8 ~43 yellow_glazed_terracotta 0
fill ~113 ~8 ~33 ~113 ~9 ~33 yellow_glazed_terracotta 0
fill ~113 ~8 ~37 ~113 ~17 ~37 wool 1
fill ~113 ~8 ~38 ~113 ~8 ~39 concrete 4
setblock ~113 ~8 ~40 yellow_glazed_terracotta 0
setblock ~113 ~8 ~41 concrete 4
fill ~114 ~8 ~35 ~114 ~9 ~35 wool 1
setblock ~43 ~9 ~34 yellow_glazed_terracotta 0
fill ~43 ~9 ~36 ~43 ~13 ~36 wool 1
fill ~43 ~9 ~38 ~43 ~11 ~38 wool 1
fill ~43 ~9 ~39 ~43 ~9 ~36 wool 1
setblock ~44 ~9 ~40 wool 1
setblock ~44 ~9 ~41 stained_hardened_clay 4
fill ~45 ~9 ~28 ~46 ~9 ~28 wool 1
fill ~45 ~9 ~29 ~45 ~11 ~29 wool 1
fill ~45 ~9 ~41 ~46 ~9 ~41 red_sandstone 0
setblock ~47 ~9 ~27 wool 1
setblock ~47 ~9 ~41 wool 1
fill ~48 ~9 ~28 ~49 ~9 ~28 wool 1
setblock ~48 ~9 ~39 red_sandstone 0
fill ~50 ~9 ~29 ~50 ~9 ~30 wool 1
setblock ~50 ~9 ~31 red_sandstone 0
setblock ~50 ~9 ~37 red_sandstone 0
setblock ~51 ~9 ~36 wool 1
setblock ~105 ~9 ~36 wool 1
fill ~106 ~9 ~29 ~106 ~9 ~30 wool 1
setblock ~106 ~9 ~31 red_sandstone 0
setblock ~106 ~9 ~37 red_sandstone 0
fill ~107 ~9 ~28 ~108 ~9 ~28 wool 1
setblock ~108 ~9 ~39 red_sandstone 0
setblock ~109 ~9 ~27 wool 1
setblock ~109 ~9 ~41 wool 1
fill ~110 ~9 ~28 ~111 ~9 ~28 wool 1
fill ~110 ~9 ~41 ~111 ~9 ~41 red_sandstone 0
fill ~111 ~9 ~29 ~111 ~11 ~29 wool 1
setblock ~112 ~9 ~40 wool 1
setblock ~112 ~9 ~41 stained_hardened_clay 4
setblock ~113 ~9 ~34 yellow_glazed_terracotta 0
fill ~113 ~9 ~36 ~113 ~13 ~36 wool 1
fill ~113 ~9 ~38 ~113 ~11 ~38 wool 1
fill ~113 ~9 ~39 ~113 ~9 ~36 wool 1
fill ~42 ~10 ~33 ~42 ~11 ~33 yellow_glazed_terracotta 0
setblock ~42 ~10 ~34 stained_hardened_clay 4
fill ~43 ~10 ~35 ~43 ~11 ~35 wool 1
setblock ~44 ~10 ~30 red_sandstone 0
setblock ~44 ~10 ~31 wool 1
setblock ~44 ~10 ~39 wool 1
fill ~45 ~10 ~40 ~45 ~13 ~40 wool 1
setblock ~46 ~10 ~28 concrete 4
setblock ~46 ~10 ~40 red_sandstone 0
fill ~47 ~10 ~28 ~48 ~10 ~28 wool 1
fill ~47 ~10 ~40 ~47 ~11 ~40 wool 1
setblock ~48 ~10 ~39 wool 1
setblock ~49 ~10 ~28 yellow_glazed_terracotta 0
fill ~49 ~10 ~37 ~50 ~10 ~37 wool 1
setblock ~50 ~10 ~29 yellow_glazed_terracotta 0
setblock ~50 ~10 ~30 red_sandstone 0
setblock ~50 ~10 ~31 wool 1
fill ~51 ~10 ~36 ~51 ~14 ~36 yellow_glazed_terracotta 0
fill ~105 ~10 ~36 ~105 ~14 ~36 yellow_glazed_terracotta 0
setblock ~106 ~10 ~29 yellow_glazed_terracotta 0
setblock ~106 ~10 ~30 red_sandstone 0
setblock ~106 ~10 ~31 wool 1
fill ~106 ~10 ~37 ~107 ~10 ~37 wool 1
setblock ~107 ~10 ~28 yellow_glazed_terracotta 0
fill ~108 ~10 ~28 ~109 ~10 ~28 wool 1
setblock ~108 ~10 ~39 wool 1
fill ~109 ~10 ~40 ~109 ~11 ~40 wool 1
setblock ~110 ~10 ~28 concrete 4
setblock ~110 ~10 ~40 red_sandstone 0
fill ~111 ~10 ~40 ~111 ~13 ~40 wool 1
setblock ~112 ~10 ~30 red_sandstone 0
setblock ~112 ~10 ~31 wool 1
setblock ~112 ~10 ~39 wool 1
fill ~113 ~10 ~35 ~113 ~11 ~35 wool 1
fill ~114 ~10 ~33 ~114 ~11 ~33 yellow_glazed_terracotta 0
setblock ~114 ~10 ~34 stained_hardened_clay 4
setblock ~42 ~11 ~34 yellow_glazed_terracotta 0
setblock ~44 ~11 ~31 red_sandstone 0
setblock ~44 ~11 ~39 stained_hardened_clay 4
setblock ~45 ~11 ~30 wool 1
setblock ~46 ~11 ~28 yellow_glazed_terracotta 0
setblock ~46 ~11 ~40 wool 1
fill ~47 ~11 ~28 ~48 ~11 ~28 wool 1
setblock ~48 ~11 ~39 stained_hardened_clay 4
fill ~49 ~11 ~29 ~49 ~12 ~29 wool 1
fill ~50 ~11 ~30 ~50 ~12 ~30 wool 1
setblock ~50 ~11 ~31 red_sandstone 0
setblock ~50 ~11 ~37 stained_hardened_clay 4
setblock ~51 ~11 ~32 wool 1
setblock ~51 ~11 ~33 stained_hardened_clay 4
setblock ~105 ~11 ~32 wool 1
setblock ~105 ~11 ~33 stained_hardened_clay 4
fill ~106 ~11 ~30 ~106 ~12 ~30 wool 1
setblock ~106 ~11 ~31 red_sandstone 0
setblock ~106 ~11 ~37 stained_hardened_clay 4
fill ~107 ~11 ~29 ~107 ~12 ~29 wool 1
fill ~108 ~11 ~28 ~109 ~11 ~28 wool 1
setblock ~108 ~11 ~39 stained_hardened_clay 4
setblock ~110 ~11 ~28 yellow_glazed_terracotta 0
setblock ~110 ~11 ~40 wool 1
setblock ~111 ~11 ~30 wool 1
setblock ~112 ~11 ~31 red_sandstone 0
setblock ~112 ~11 ~39 stained_hardened_clay 4
setblock ~114 ~11 ~34 yellow_glazed_terracotta 0
setblock ~42 ~12 ~34 stained_hardened_clay 4
fill ~43 ~12 ~33 ~43 ~14 ~33 yellow_glazed_terracotta 0
setblock ~43 ~12 ~35 yellow_glazed_terracotta 0
setblock ~43 ~12 ~38 concrete 4
setblock ~44 ~12 ~31 wool 1
setblock ~44 ~12 ~39 concrete 4
setblock ~45 ~12 ~30 concrete 4
setblock ~46 ~12 ~29 yellow_glazed_terracotta 0
setblock ~46 ~12 ~40 stained_hardened_clay 4
setblock ~47 ~12 ~28 yellow_glazed_terracotta 0
fill ~47 ~12 ~40 ~47 ~14 ~40 concrete 4
setblock ~48 ~12 ~29 yellow_glazed_terracotta 0
fill ~48 ~12 ~39 ~48 ~13 ~39 wool 1
setblock ~49 ~12 ~38 concrete 4
setblock ~50 ~12 ~31 wool 1
setblock ~50 ~12 ~37 concrete 4
fill ~51 ~12 ~32 ~51 ~12 ~36 yellow_glazed_terracotta 0
fill ~105 ~12 ~32 ~105 ~12 ~36 yellow_glazed_terracotta 0
setblock ~106 ~12 ~31 wool 1
setblock ~106 ~12 ~37 concrete 4
setblock ~107 ~12 ~38 concrete 4
setblock ~108 ~12 ~29 yellow_glazed_terracotta 0
fill ~108 ~12 ~39 ~108 ~13 ~39 wool 1
setblock ~109 ~12 ~28 yellow_glazed_terracotta 0
fill ~109 ~12 ~40 ~109 ~14 ~40 concrete 4
setblock ~110 ~12 ~29 yellow_glazed_terracotta 0
setblock ~110 ~12 ~40 stained_hardened_clay 4
setblock ~111 ~12 ~30 concrete 4
setblock ~112 ~12 ~31 wool 1
setblock ~112 ~12 ~39 concrete 4
fill ~113 ~12 ~33 ~113 ~14 ~33 yellow_glazed_terracotta 0
setblock ~113 ~12 ~35 yellow_glazed_terracotta 0
setblock ~113 ~12 ~38 concrete 4
setblock ~114 ~12 ~34 stained_hardened_clay 4
setblock ~42 ~13 ~34 yellow_glazed_terracotta 0
setblock ~43 ~13 ~35 stained_hardened_clay 4
setblock ~43 ~13 ~38 wool 1
setblock ~44 ~13 ~31 stained_hardened_clay 4
setblock ~44 ~13 ~39 stained_hardened_clay 4
setblock ~45 ~13 ~30 wool 1
setblock ~46 ~13 ~29 stained_hardened_clay 4
fill ~46 ~13 ~40 ~46 ~14 ~40 wool 1
fill ~47 ~13 ~29 ~48 ~13 ~29 wool 1
setblock ~49 ~13 ~30 concrete 4
setblock ~49 ~13 ~38 wool 1
setblock ~50 ~13 ~31 stained_hardened_clay 4
setblock ~50 ~13 ~32 wool 1
setblock ~50 ~13 ~37 stained_hardened_clay 4
setblock ~51 ~13 ~33 stained_hardened_clay 4
setblock ~51 ~13 ~35 stained_hardened_clay 4
setblock ~105 ~13 ~33 stained_hardened_clay 4
setblock ~105 ~13 ~35 stained_hardened_clay 4
setblock ~106 ~13 ~31 stained_hardened_clay 4
setblock ~106 ~13 ~32 wool 1
setblock ~106 ~13 ~37 stained_hardened_clay 4
setblock ~107 ~13 ~30 concrete 4
setblock ~107 ~13 ~38 wool 1
fill ~108 ~13 ~29 ~109 ~13 ~29 wool 1
setblock ~110 ~13 ~29 stained_hardened_clay 4
fill ~110 ~13 ~40 ~110 ~14 ~40 wool 1
setblock ~111 ~13 ~30 wool 1
setblock ~112 ~13 ~31 stained_hardened_clay 4
setblock ~112 ~13 ~39 stained_hardened_clay 4
setblock ~113 ~13 ~35 stained_hardened_clay 4
setblock ~113 ~13 ~38 wool 1
setblock ~114 ~13 ~34 yellow_glazed_terracotta 0
fill ~43 ~14 ~34 ~43 ~16 ~34 yellow_glazed_terracotta 0
fill ~43 ~14 ~35 ~43 ~14 ~36 yellow_glazed_terracotta 0
fill ~43 ~14 ~38 ~43 ~15 ~38 concrete 4
fill ~44 ~14 ~32 ~44 ~18 ~32 wool 1
setblock ~44 ~14 ~39 concrete 4
setblock ~45 ~14 ~30 concrete 4
fill ~45 ~14 ~31 ~45 ~17 ~31 wool 1
setblock ~45 ~14 ~40 concrete 4
setblock ~46 ~14 ~29 yellow_glazed_terracotta 0
fill ~47 ~14 ~29 ~47 ~13 ~29 wool 1
setblock ~48 ~14 ~29 yellow_glazed_terracotta 0
fill ~48 ~14 ~40 ~48 ~16 ~40 wool 1
setblock ~49 ~14 ~30 yellow_glazed_terracotta 0
fill ~49 ~14 ~39 ~49 ~15 ~39 wool 1
setblock ~50 ~14 ~31 concrete 4
setblock ~50 ~14 ~32 stained_hardened_clay 4
setblock ~50 ~14 ~37 yellow_glazed_terracotta 0
setblock ~50 ~14 ~38 stained_hardened_clay 4
setblock ~51 ~14 ~33 concrete 4
setblock ~51 ~14 ~35 concrete 4
setblock ~105 ~14 ~33 concrete 4
setblock ~105 ~14 ~35 concrete 4
setblock ~106 ~14 ~31 concrete 4
setblock ~106 ~14 ~32 stained_hardened_clay 4
setblock ~106 ~14 ~37 yellow_glazed_terracotta 0
setblock ~106 ~14 ~38 stained_hardened_clay 4
setblock ~107 ~14 ~30 yellow_glazed_terracotta 0
fill ~107 ~14 ~39 ~107 ~15 ~39 wool 1
setblock ~108 ~14 ~29 yellow_glazed_terracotta 0
fill ~108 ~14 ~40 ~108 ~16 ~40 wool 1
setblock ~109 ~14 ~29 wool 1
setblock ~110 ~14 ~29 yellow_glazed_terracotta 0
setblock ~111 ~14 ~30 concrete 4
fill ~111 ~14 ~31 ~111 ~17 ~31 wool 1
setblock ~111 ~14 ~40 concrete 4
fill ~112 ~14 ~32 ~112 ~18 ~32 wool 1
setblock ~112 ~14 ~39 concrete 4
fill ~113 ~14 ~34 ~113 ~16 ~34 yellow_glazed_terracotta 0
fill ~113 ~14 ~35 ~113 ~14 ~36 yellow_glazed_terracotta 0
fill ~113 ~14 ~38 ~113 ~15 ~38 concrete 4
setblock ~42 ~15 ~35 stained_hardened_clay 4
fill ~43 ~15 ~33 ~43 ~17 ~33 wool 1
fill ~43 ~15 ~36 ~43 ~16 ~36 yellow_glazed_terracotta 0
fill ~44 ~15 ~39 ~44 ~15 ~40 wool 1
setblock ~45 ~15 ~40 wool 1
setblock ~46 ~15 ~30 concrete 4
fill ~46 ~15 ~41 ~47 ~15 ~41 wool 1
fill ~47 ~15 ~30 ~48 ~15 ~30 wool 1
setblock ~49 ~15 ~30 concrete 4
setblock ~50 ~15 ~31 stained_hardened_clay 4
setblock ~50 ~15 ~32 concrete 4
setblock ~50 ~15 ~38 concrete 4
setblock ~51 ~15 ~33 wool 1
fill ~51 ~15 ~35 ~51 ~17 ~35 wool 1
setblock ~51 ~15 ~36 concrete 4
setblock ~51 ~15 ~37 stained_hardened_clay 4
setblock ~105 ~15 ~33 wool 1
fill ~105 ~15 ~35 ~105 ~17 ~35 wool 1
setblock ~105 ~15 ~36 concrete 4
setblock ~105 ~15 ~37 stained_hardened_clay 4
setblock ~106 ~15 ~31 stained_hardened_clay 4
setblock ~106 ~15 ~32 concrete 4
setblock ~106 ~15 ~38 concrete 4
setblock ~107 ~15 ~30 concrete 4
fill ~108 ~15 ~30 ~109 ~15 ~30 wool 1
fill ~109 ~15 ~41 ~110 ~15 ~41 wool 1
setblock ~110 ~15 ~30 concrete 4
fill ~111 ~15 ~40 ~112 ~15 ~40 wool 1
setblock ~112 ~15 ~39 wool 1
fill ~113 ~15 ~33 ~113 ~17 ~33 wool 1
fill ~113 ~15 ~36 ~113 ~16 ~36 yellow_glazed_terracotta 0
setblock ~114 ~15 ~35 stained_hardened_clay 4
setblock ~43 ~16 ~35 concrete 4
setblock ~43 ~16 ~38 yellow_glazed_terracotta 0
setblock ~43 ~16 ~39 concrete 4
fill ~44 ~16 ~40 ~44 ~17 ~40 wool 1
fill ~45 ~16 ~41 ~45 ~17 ~41 wool 1
setblock ~46 ~16 ~30 wool 1
fill ~46 ~16 ~41 ~47 ~16 ~41 concrete 4
setblock ~47 ~16 ~30 yellow_glazed_terracotta 0
setblock ~48 ~16 ~30 wool 1
setblock ~49 ~16 ~31 concrete 4
setblock ~49 ~16 ~40 concrete 4
fill ~50 ~16 ~32 ~50 ~17 ~32 wool 1
setblock ~50 ~16 ~33 concrete 4
setblock ~50 ~16 ~38 stained_hardened_clay 4
setblock ~50 ~16 ~39 yellow_glazed_terracotta 0
setblock ~51 ~16 ~36 yellow_glazed_terracotta 0
setblock ~51 ~16 ~37 concrete 4
setblock ~105 ~16 ~36 yellow_glazed_terracotta 0
setblock ~105 ~16 ~37 concrete 4
fill ~106 ~16 ~32 ~106 ~17 ~32 wool 1
setblock ~106 ~16 ~33 concrete 4
setblock ~106 ~16 ~38 stained_hardened_clay 4
setblock ~106 ~16 ~39 yellow_glazed_terracotta 0
setblock ~107 ~16 ~31 concrete 4
setblock ~107 ~16 ~40 concrete 4
fill ~108 ~16 ~30 ~108 ~15 ~30 wool 1
setblock ~109 ~16 ~30 yellow_glazed_terracotta 0
fill ~109 ~16 ~41 ~110 ~16 ~41 concrete 4
setblock ~110 ~16 ~30 wool 1
fill ~111 ~16 ~41 ~111 ~17 ~41 wool 1
fill ~112 ~16 ~40 ~112 ~17 ~40 wool 1
setblock ~113 ~16 ~35 concrete 4
setblock ~113 ~16 ~38 yellow_glazed_terracotta 0
setblock ~113 ~16 ~39 concrete 4
fill ~42 ~17 ~36 ~42 ~22 ~36 wool 1
setblock ~43 ~17 ~34 concrete 4
fill ~43 ~17 ~35 ~43 ~19 ~35 wool 1
setblock ~43 ~17 ~38 concrete 4
setblock ~43 ~17 ~39 wool 1
setblock ~46 ~17 ~31 wool 1
setblock ~46 ~17 ~42 concrete 4
setblock ~47 ~17 ~30 concrete 4
setblock ~47 ~17 ~41 wool 1
fill ~48 ~17 ~31 ~49 ~17 ~31 wool 1
setblock ~48 ~17 ~41 stained_hardened_clay 4
setblock ~49 ~17 ~40 wool 1
setblock ~50 ~17 ~33 wool 1
setblock ~50 ~17 ~38 wool 1
setblock ~50 ~17 ~39 stained_hardened_clay 4
setblock ~51 ~17 ~34 concrete 4
fill ~51 ~17 ~36 ~51 ~17 ~37 wool 1
setblock ~105 ~17 ~34 concrete 4
fill ~105 ~17 ~36 ~105 ~17 ~37 wool 1
setblock ~106 ~17 ~33 wool 1
setblock ~106 ~17 ~38 wool 1
setblock ~106 ~17 ~39 stained_hardened_clay 4
fill ~107 ~17 ~31 ~108 ~17 ~31 wool 1
setblock ~107 ~17 ~40 wool 1
setblock ~108 ~17 ~41 stained_hardened_clay 4
setblock ~109 ~17 ~30 concrete 4
setblock ~109 ~17 ~41 wool 1
setblock ~110 ~17 ~31 wool 1
setblock ~110 ~17 ~42 concrete 4
setblock ~113 ~17 ~34 concrete 4
fill ~113 ~17 ~35 ~113 ~19 ~35 wool 1
setblock ~113 ~17 ~38 concrete 4
setblock ~113 ~17 ~39 wool 1
fill ~114 ~17 ~36 ~114 ~22 ~36 wool 1
setblock ~42 ~18 ~37 concrete 4
fill ~42 ~18 ~38 ~42 ~23 ~38 wool 1
setblock ~43 ~18 ~34 yellow_glazed_terracotta 0
fill ~43 ~18 ~39 ~43 ~18 ~40 concrete 4
setblock ~44 ~18 ~33 concrete 4
setblock ~44 ~18 ~41 concrete 4
setblock ~45 ~18 ~32 concrete 4
fill ~45 ~18 ~42 ~45 ~19 ~42 concrete 4
setblock ~46 ~18 ~31 yellow_glazed_terracotta 0
setblock ~46 ~18 ~42 stained_hardened_clay 4
fill ~47 ~18 ~31 ~48 ~18 ~31 concrete 4
setblock ~47 ~18 ~42 yellow_glazed_terracotta 0
setblock ~48 ~18 ~41 wool 1
setblock ~49 ~18 ~32 yellow_glazed_terracotta 0
setblock ~49 ~18 ~40 yellow_glazed_terracotta 0
setblock ~50 ~18 ~33 concrete 4
setblock ~50 ~18 ~39 concrete 4
setblock ~50 ~18 ~40 stained_hardened_clay 4
setblock ~51 ~18 ~34 yellow_glazed_terracotta 0
setblock ~51 ~18 ~35 concrete 4
setblock ~51 ~18 ~36 yellow_glazed_terracotta 0
fill ~51 ~18 ~37 ~51 ~22 ~37 wool 1
setblock ~51 ~18 ~38 yellow_glazed_terracotta 0
setblock ~105 ~18 ~34 yellow_glazed_terracotta 0
setblock ~105 ~18 ~35 concrete 4
setblock ~105 ~18 ~36 yellow_glazed_terracotta 0
fill ~105 ~18 ~37 ~105 ~22 ~37 wool 1
setblock ~105 ~18 ~38 yellow_glazed_terracotta 0
setblock ~106 ~18 ~33 concrete 4
setblock ~106 ~18 ~39 concrete 4
setblock ~106 ~18 ~40 stained_hardened_clay 4
setblock ~107 ~18 ~32 yellow_glazed_terracotta 0
setblock ~107 ~18 ~40 yellow_glazed_terracotta 0
fill ~108 ~18 ~31 ~109 ~18 ~31 concrete 4
setblock ~108 ~18 ~41 wool 1
setblock ~109 ~18 ~42 yellow_glazed_terracotta 0
setblock ~110 ~18 ~31 yellow_glazed_terracotta 0
setblock ~110 ~18 ~42 stained_hardened_clay 4
setblock ~111 ~18 ~32 concrete 4
fill ~111 ~18 ~42 ~111 ~19 ~42 concrete 4
setblock ~112 ~18 ~33 concrete 4
setblock ~112 ~18 ~41 concrete 4
setblock ~113 ~18 ~34 yellow_glazed_terracotta 0
fill ~113 ~18 ~39 ~113 ~18 ~40 concrete 4
setblock ~114 ~18 ~37 concrete 4
fill ~114 ~18 ~38 ~114 ~23 ~38 wool 1
setblock ~42 ~19 ~37 stained_hardened_clay 4
setblock ~42 ~19 ~39 stained_hardened_clay 4
setblock ~43 ~19 ~34 concrete 4
setblock ~43 ~19 ~40 concrete 4
setblock ~44 ~19 ~33 wool 1
setblock ~44 ~19 ~41 stained_hardened_clay 4
fill ~45 ~19 ~32 ~45 ~21 ~32 wool 1
setblock ~46 ~19 ~31 stained_hardened_clay 4
setblock ~46 ~19 ~43 stained_hardened_clay 4
fill ~47 ~19 ~31 ~48 ~19 ~31 wool 1
setblock ~47 ~19 ~42 concrete 4
fill ~48 ~19 ~42 ~48 ~20 ~42 wool 1
fill ~49 ~19 ~32 ~49 ~20 ~32 concrete 4
fill ~49 ~19 ~41 ~49 ~20 ~41 wool 1
setblock ~50 ~19 ~33 wool 1
setblock ~50 ~19 ~40 concrete 4
setblock ~51 ~19 ~34 concrete 4
setblock ~51 ~19 ~35 wool 1
setblock ~51 ~19 ~36 concrete 4
fill ~51 ~19 ~38 ~51 ~21 ~38 wool 1
fill ~51 ~19 ~39 ~51 ~21 ~39 wool 1
setblock ~105 ~19 ~34 concrete 4
setblock ~105 ~19 ~35 wool 1
setblock ~105 ~19 ~36 concrete 4
fill ~105 ~19 ~38 ~105 ~21 ~38 wool 1
fill ~105 ~19 ~39 ~105 ~21 ~39 wool 1
setblock ~106 ~19 ~33 wool 1
setblock ~106 ~19 ~40 concrete 4
fill ~107 ~19 ~32 ~107 ~20 ~32 concrete 4
fill ~107 ~19 ~41 ~107 ~20 ~41 wool 1
fill ~108 ~19 ~31 ~109 ~19 ~31 wool 1
fill ~108 ~19 ~42 ~108 ~20 ~42 wool 1
setblock ~109 ~19 ~42 concrete 4
setblock ~110 ~19 ~31 stained_hardened_clay 4
setblock ~110 ~19 ~43 stained_hardened_clay 4
fill ~111 ~19 ~32 ~111 ~21 ~32 wool 1
setblock ~112 ~19 ~33 wool 1
setblock ~112 ~19 ~41 stained_hardened_clay 4
setblock ~113 ~19 ~34 concrete 4
setblock ~113 ~19 ~40 concrete 4
setblock ~114 ~19 ~37 stained_hardened_clay 4
setblock ~114 ~19 ~39 stained_hardened_clay 4
setblock ~42 ~20 ~35 concrete 4
setblock ~42 ~20 ~37 wool 1
setblock ~42 ~20 ~39 concrete 4
setblock ~43 ~20 ~34 yellow_glazed_terracotta 0
setblock ~43 ~20 ~40 yellow_glazed_terracotta 0
fill ~43 ~20 ~41 ~43 ~21 ~41 wool 1
setblock ~44 ~20 ~33 concrete 4
setblock ~44 ~20 ~42 wool 1
setblock ~45 ~20 ~43 concrete 4
fill ~46 ~20 ~32 ~46 ~22 ~32 wool 1
setblock ~46 ~20 ~43 yellow_glazed_terracotta 0
setblock ~47 ~20 ~32 yellow_glazed_terracotta 0
setblock ~47 ~20 ~43 concrete 4
fill ~48 ~20 ~32 ~48 ~22 ~32 wool 1
setblock ~50 ~20 ~33 concrete 4
fill ~50 ~20 ~34 ~50 ~23 ~34 wool 1
setblock ~50 ~20 ~41 concrete 4
setblock ~51 ~20 ~35 concrete 4
setblock ~51 ~20 ~36 yellow_glazed_terracotta 0
setblock ~51 ~20 ~40 yellow_glazed_terracotta 0
setblock ~105 ~20 ~35 concrete 4
setblock ~105 ~20 ~36 yellow_glazed_terracotta 0
setblock ~105 ~20 ~40 yellow_glazed_terracotta 0
setblock ~106 ~20 ~33 concrete 4
fill ~106 ~20 ~34 ~106 ~23 ~34 wool 1
setblock ~106 ~20 ~41 concrete 4
fill ~108 ~20 ~32 ~108 ~22 ~32 wool 1
setblock ~109 ~20 ~32 yellow_glazed_terracotta 0
setblock ~109 ~20 ~43 concrete 4
fill ~110 ~20 ~32 ~110 ~22 ~32 wool 1
setblock ~110 ~20 ~43 yellow_glazed_terracotta 0
setblock ~111 ~20 ~43 concrete 4
setblock ~112 ~20 ~33 concrete 4
setblock ~112 ~20 ~42 wool 1
setblock ~113 ~20 ~34 yellow_glazed_terracotta 0
setblock ~113 ~20 ~40 yellow_glazed_terracotta 0
fill ~113 ~20 ~41 ~113 ~21 ~41 wool 1
setblock ~114 ~20 ~35 concrete 4
setblock ~114 ~20 ~37 wool 1
setblock ~114 ~20 ~39 concrete 4
setblock ~42 ~21 ~35 wool 1
setblock ~42 ~21 ~37 stained_hardened_clay 4
setblock ~42 ~21 ~39 stained_hardened_clay 4
setblock ~42 ~21 ~40 wool 1
setblock ~43 ~21 ~34 concrete 4
setblock ~43 ~21 ~42 wool 1
fill ~44 ~21 ~33 ~44 ~23 ~33 wool 1
setblock ~44 ~21 ~43 stained_hardened_clay 4
setblock ~45 ~21 ~43 wool 1
setblock ~46 ~21 ~44 concrete 4
fill ~47 ~21 ~32 ~47 ~22 ~32 concrete 4
setblock ~47 ~21 ~43 wool 1
setblock ~48 ~21 ~43 stained_hardened_clay 4
setblock ~49 ~21 ~33 wool 1
setblock ~49 ~21 ~42 wool 1
setblock ~50 ~21 ~41 stained_hardened_clay 4
setblock ~51 ~21 ~35 wool 1
setblock ~51 ~21 ~36 concrete 4
setblock ~51 ~21 ~40 wool 1
setblock ~105 ~21 ~35 wool 1
setblock ~105 ~21 ~36 concrete 4
setblock ~105 ~21 ~40 wool 1
setblock ~106 ~21 ~41 stained_hardened_clay 4
setblock ~107 ~21 ~33 wool 1
setblock ~107 ~21 ~42 wool 1
setblock ~108 ~21 ~43 stained_hardened_clay 4
fill ~109 ~21 ~32 ~109 ~22 ~32 concrete 4
setblock ~109 ~21 ~43 wool 1
setblock ~110 ~21 ~44 concrete 4
setblock ~111 ~21 ~43 wool 1
fill ~112 ~21 ~33 ~112 ~23 ~33 wool 1
setblock ~112 ~21 ~43 stained_hardened_clay 4
setblock ~113 ~21 ~34 concrete 4
setblock ~113 ~21 ~42 wool 1
setblock ~114 ~21 ~35 wool 1
setblock ~114 ~21 ~37 stained_hardened_clay 4
setblock ~114 ~21 ~39 stained_hardened_clay 4
setblock ~114 ~21 ~40 wool 1
setblock ~42 ~22 ~35 concrete 4
setblock ~42 ~22 ~37 concrete 4
setblock ~42 ~22 ~39 concrete 4
setblock ~42 ~22 ~40 stained_hardened_clay 4
setblock ~42 ~22 ~41 yellow_glazed_terracotta 0
setblock ~43 ~22 ~34 yellow_glazed_terracotta 0
setblock ~43 ~22 ~42 yellow_glazed_terracotta 0
setblock ~44 ~22 ~43 concrete 4
fill ~45 ~22 ~33 ~45 ~31 ~33 wool 1
setblock ~45 ~22 ~44 yellow_glazed_terracotta 0
setblock ~46 ~22 ~44 stained_hardened_clay 4
setblock ~47 ~22 ~44 yellow_glazed_terracotta 0
setblock ~48 ~22 ~43 concrete 4
setblock ~49 ~22 ~33 concrete 4
fill ~49 ~22 ~43 ~49 ~23 ~43 wool 1
fill ~50 ~22 ~35 ~50 ~24 ~35 wool 1
setblock ~50 ~22 ~42 wool 1
fill ~51 ~22 ~36 ~51 ~27 ~36 wool 1
setblock ~51 ~22 ~40 yellow_glazed_terracotta 0
setblock ~51 ~22 ~41 wool 1
fill ~52 ~22 ~38 ~52 ~25 ~38 wool 1
fill ~52 ~22 ~39 ~52 ~24 ~39 wool 1
fill ~104 ~22 ~38 ~104 ~25 ~38 wool 1
fill ~104 ~22 ~39 ~104 ~24 ~39 wool 1
fill ~105 ~22 ~36 ~105 ~27 ~36 wool 1
setblock ~105 ~22 ~40 yellow_glazed_terracotta 0
setblock ~105 ~22 ~41 wool 1
fill ~106 ~22 ~35 ~106 ~24 ~35 wool 1
setblock ~106 ~22 ~42 wool 1
setblock ~107 ~22 ~33 concrete 4
fill ~107 ~22 ~43 ~107 ~23 ~43 wool 1
setblock ~108 ~22 ~43 concrete 4
setblock ~109 ~22 ~44 yellow_glazed_terracotta 0
setblock ~110 ~22 ~44 stained_hardened_clay 4
fill ~111 ~22 ~33 ~111 ~31 ~33 wool 1
setblock ~111 ~22 ~44 yellow_glazed_terracotta 0
setblock ~112 ~22 ~43 concrete 4
setblock ~113 ~22 ~34 yellow_glazed_terracotta 0
setblock ~113 ~22 ~42 yellow_glazed_terracotta 0
setblock ~114 ~22 ~35 concrete 4
setblock ~114 ~22 ~37 concrete 4
setblock ~114 ~22 ~39 concrete 4
setblock ~114 ~22 ~40 stained_hardened_clay 4
setblock ~114 ~22 ~41 yellow_glazed_terracotta 0
setblock ~42 ~23 ~35 wool 1
setblock ~42 ~23 ~36 concrete 4
fill ~42 ~23 ~37 ~42 ~24 ~37 wool 1
setblock ~42 ~23 ~39 stained_hardened_clay 4
setblock ~42 ~23 ~40 wool 1
setblock ~42 ~23 ~41 stained_hardened_clay 4
setblock ~42 ~23 ~42 wool 1
setblock ~43 ~23 ~34 concrete 4
fill ~43 ~23 ~43 ~43 ~24 ~43 wool 1
setblock ~44 ~23 ~44 wool 1
fill ~45 ~23 ~45 ~45 ~24 ~45 concrete 4
fill ~46 ~23 ~33 ~49 ~23 ~33 wool 1
setblock ~46 ~23 ~45 stained_hardened_clay 4
fill ~47 ~23 ~45 ~47 ~24 ~45 wool 1
setblock ~48 ~23 ~44 wool 1
setblock ~50 ~23 ~43 wool 1
setblock ~51 ~23 ~42 concrete 4
fill ~52 ~23 ~37 ~52 ~29 ~37 wool 1
fill ~52 ~23 ~40 ~52 ~24 ~40 wool 1
fill ~52 ~23 ~41 ~52 ~23 ~37 wool 1
fill ~104 ~23 ~37 ~104 ~29 ~37 wool 1
fill ~104 ~23 ~40 ~104 ~24 ~40 wool 1
fill ~104 ~23 ~41 ~104 ~23 ~37 wool 1
setblock ~105 ~23 ~42 concrete 4
setblock ~106 ~23 ~43 wool 1
fill ~107 ~23 ~33 ~112 ~23 ~33 wool 1
setblock ~108 ~23 ~44 wool 1
fill ~109 ~23 ~45 ~109 ~24 ~45 wool 1
setblock ~110 ~23 ~45 stained_hardened_clay 4
fill ~111 ~23 ~45 ~111 ~24 ~45 concrete 4
setblock ~112 ~23 ~44 wool 1
setblock ~113 ~23 ~34 concrete 4
fill ~113 ~23 ~43 ~113 ~24 ~43 wool 1
setblock ~114 ~23 ~35 wool 1
setblock ~114 ~23 ~36 concrete 4
fill ~114 ~23 ~37 ~114 ~24 ~37 wool 1
setblock ~114 ~23 ~39 stained_hardened_clay 4
setblock ~114 ~23 ~40 wool 1
setblock ~114 ~23 ~41 stained_hardened_clay 4
setblock ~114 ~23 ~42 wool 1
setblock ~41 ~24 ~38 concrete 4
fill ~41 ~24 ~39 ~41 ~26 ~39 wool 1
setblock ~41 ~24 ~40 yellow_glazed_terracotta 0
setblock ~42 ~24 ~35 concrete 4
fill ~42 ~24 ~36 ~42 ~25 ~36 wool 1
setblock ~42 ~24 ~41 concrete 4
setblock ~42 ~24 ~42 stained_hardened_clay 4
setblock ~43 ~24 ~34 yellow_glazed_terracotta 0
setblock ~44 ~24 ~33 concrete 4
setblock ~44 ~24 ~44 stained_hardened_clay 4
fill ~46 ~24 ~33 ~47 ~24 ~33 wool 1
setblock ~46 ~24 ~45 yellow_glazed_terracotta 0
setblock ~48 ~24 ~33 concrete 4
setblock ~48 ~24 ~45 concrete 4
fill ~49 ~24 ~34 ~49 ~29 ~34 wool 1
setblock ~49 ~24 ~44 wool 1
fill ~50 ~24 ~43 ~51 ~24 ~43 concrete 4
setblock ~52 ~24 ~41 concrete 4
fill ~52 ~24 ~42 ~52 ~25 ~42 wool 1
setblock ~104 ~24 ~41 concrete 4
fill ~104 ~24 ~42 ~104 ~25 ~42 wool 1
fill ~105 ~24 ~43 ~106 ~24 ~43 concrete 4
fill ~107 ~24 ~34 ~107 ~29 ~34 wool 1
setblock ~107 ~24 ~44 wool 1
setblock ~108 ~24 ~33 concrete 4
setblock ~108 ~24 ~45 concrete 4
fill ~109 ~24 ~33 ~111 ~24 ~33 wool 1
setblock ~110 ~24 ~45 yellow_glazed_terracotta 0
setblock ~112 ~24 ~33 concrete 4
setblock ~112 ~24 ~44 stained_hardened_clay 4
setblock ~113 ~24 ~34 yellow_glazed_terracotta 0
setblock ~114 ~24 ~35 concrete 4
fill ~114 ~24 ~36 ~114 ~25 ~36 wool 1
setblock ~114 ~24 ~41 concrete 4
setblock ~114 ~24 ~42 stained_hardened_clay 4
setblock ~115 ~24 ~38 concrete 4
fill ~115 ~24 ~39 ~115 ~26 ~39 wool 1
setblock ~115 ~24 ~40 yellow_glazed_terracotta 0
fill ~41 ~25 ~37 ~41 ~25 ~39 wool 1
setblock ~41 ~25 ~40 concrete 4
setblock ~41 ~25 ~41 stained_hardened_clay 4
setblock ~42 ~25 ~35 stained_hardened_clay 4
setblock ~42 ~25 ~42 wool 1
setblock ~42 ~25 ~43 stained_hardened_clay 4
setblock ~43 ~25 ~34 concrete 4
setblock ~43 ~25 ~44 wool 1
setblock ~44 ~25 ~33 stained_hardened_clay 4
setblock ~44 ~25 ~45 stained_hardened_clay 4
fill ~45 ~25 ~46 ~47 ~25 ~46 concrete 4
setblock ~46 ~25 ~33 red_sandstone 0
fill ~47 ~25 ~33 ~48 ~25 ~33 wool 1
setblock ~48 ~25 ~45 stained_hardened_clay 4
fill ~49 ~25 ~45 ~49 ~26 ~45 wool 1
setblock ~50 ~25 ~35 concrete 1
setblock ~50 ~25 ~44 wool 1
setblock ~51 ~25 ~44 concrete 4
setblock ~52 ~25 ~43 wool 1
fill ~53 ~25 ~39 ~53 ~27 ~39 wool 1
fill ~53 ~25 ~40 ~53 ~25 ~41 wool 1
fill ~103 ~25 ~39 ~103 ~27 ~39 wool 1
fill ~103 ~25 ~40 ~103 ~25 ~41 wool 1
setblock ~104 ~25 ~43 wool 1
setblock ~105 ~25 ~44 concrete 4
setblock ~106 ~25 ~35 concrete 1
setblock ~106 ~25 ~44 wool 1
fill ~107 ~25 ~45 ~107 ~26 ~45 wool 1
fill ~108 ~25 ~33 ~109 ~25 ~33 wool 1
setblock ~108 ~25 ~45 stained_hardened_clay 4
fill ~109 ~25 ~46 ~111 ~25 ~46 concrete 4
setblock ~110 ~25 ~33 red_sandstone 0
setblock ~112 ~25 ~33 stained_hardened_clay 4
setblock ~112 ~25 ~45 stained_hardened_clay 4
setblock ~113 ~25 ~34 concrete 4
setblock ~113 ~25 ~44 wool 1
setblock ~114 ~25 ~35 stained_hardened_clay 4
setblock ~114 ~25 ~42 wool 1
setblock ~114 ~25 ~43 stained_hardened_clay 4
fill ~115 ~25 ~37 ~115 ~25 ~39 wool 1
setblock ~115 ~25 ~40 concrete 4
setblock ~115 ~25 ~41 stained_hardened_clay 4
fill ~41 ~26 ~36 ~41 ~33 ~36 yellow_glazed_terracotta 0
fill ~41 ~26 ~37 ~41 ~27 ~37 concrete 4
fill ~41 ~26 ~38 ~41 ~28 ~38 yellow_glazed_terracotta 0
setblock ~41 ~26 ~40 yellow_glazed_terracotta 0
setblock ~41 ~26 ~41 concrete 4
setblock ~41 ~26 ~42 yellow_glazed_terracotta 0
setblock ~42 ~26 ~35 yellow_glazed_terracotta 0
setblock ~42 ~26 ~43 concrete 4
setblock ~42 ~26 ~44 stained_hardened_clay 4
setblock ~43 ~26 ~34 yellow_glazed_terracotta 0
fill ~43 ~26 ~45 ~43 ~27 ~45 wool 1
setblock ~44 ~26 ~33 concrete 4
setblock ~44 ~26 ~46 stained_hardened_clay 4
setblock ~45 ~26 ~46 yellow_glazed_terracotta 0
fill ~46 ~26 ~33 ~47 ~26 ~33 wool 1
setblock ~46 ~26 ~47 yellow_glazed_terracotta 0
setblock ~47 ~26 ~46 yellow_glazed_terracotta 0
setblock ~48 ~26 ~33 concrete 4
setblock ~48 ~26 ~46 stained_hardened_clay 4
setblock ~50 ~26 ~35 wool 1
fill ~50 ~26 ~45 ~50 ~27 ~45 wool 1
setblock ~51 ~26 ~44 yellow_glazed_terracotta 0
setblock ~52 ~26 ~43 yellow_glazed_terracotta 0
fill ~52 ~26 ~44 ~52 ~27 ~44 wool 1
fill ~53 ~26 ~38 ~53 ~33 ~38 yellow_glazed_terracotta 0
fill ~53 ~26 ~40 ~53 ~27 ~40 yellow_glazed_terracotta 0
fill ~53 ~26 ~41 ~53 ~27 ~41 wool 1
fill ~53 ~26 ~42 ~53 ~27 ~42 yellow_glazed_terracotta 0
fill ~103 ~26 ~38 ~103 ~33 ~38 yellow_glazed_terracotta 0
fill ~103 ~26 ~40 ~103 ~27 ~40 yellow_glazed_terracotta 0
fill ~103 ~26 ~41 ~103 ~27 ~41 wool 1
fill ~103 ~26 ~42 ~103 ~27 ~42 yellow_glazed_terracotta 0
setblock ~104 ~26 ~43 yellow_glazed_terracotta 0
fill ~104 ~26 ~44 ~104 ~27 ~44 wool 1
setblock ~105 ~26 ~44 yellow_glazed_terracotta 0
setblock ~106 ~26 ~35 wool 1
fill ~106 ~26 ~45 ~106 ~27 ~45 wool 1
setblock ~108 ~26 ~33 concrete 4
setblock ~108 ~26 ~46 stained_hardened_clay 4
fill ~109 ~26 ~33 ~111 ~26 ~33 wool 1
setblock ~109 ~26 ~46 yellow_glazed_terracotta 0
setblock ~110 ~26 ~47 yellow_glazed_terracotta 0
setblock ~111 ~26 ~46 yellow_glazed_terracotta 0
setblock ~112 ~26 ~33 concrete 4
setblock ~112 ~26 ~46 stained_hardened_clay 4
setblock ~113 ~26 ~34 yellow_glazed_terracotta 0
fill ~113 ~26 ~45 ~113 ~27 ~45 wool 1
setblock ~114 ~26 ~35 yellow_glazed_terracotta 0
setblock ~114 ~26 ~43 concrete 4
setblock ~114 ~26 ~44 stained_hardened_clay 4
fill ~115 ~26 ~36 ~115 ~33 ~36 yellow_glazed_terracotta 0
fill ~115 ~26 ~37 ~115 ~27 ~37 concrete 4
fill ~115 ~26 ~38 ~115 ~28 ~38 yellow_glazed_terracotta 0
setblock ~115 ~26 ~40 yellow_glazed_terracotta 0
setblock ~115 ~26 ~41 concrete 4
setblock ~115 ~26 ~42 yellow_glazed_terracotta 0
setblock ~41 ~27 ~39 stained_hardened_clay 4
setblock ~41 ~27 ~40 concrete 4
fill ~41 ~27 ~41 ~41 ~28 ~41 wool 1
setblock ~41 ~27 ~42 concrete 4
setblock ~41 ~27 ~43 wool 1
setblock ~42 ~27 ~35 stained_hardened_clay 4
setblock ~42 ~27 ~44 wool 1
setblock ~43 ~27 ~34 concrete 4
setblock ~44 ~27 ~33 wool 1
setblock ~44 ~27 ~46 wool 1
fill ~45 ~27 ~47 ~46 ~27 ~47 stained_hardened_clay 4
fill ~46 ~27 ~33 ~48 ~27 ~33 wool 1
fill ~47 ~27 ~47 ~47 ~28 ~47 wool 1
fill ~48 ~27 ~46 ~49 ~27 ~46 wool 1
setblock ~50 ~27 ~35 red_sandstone 0
setblock ~51 ~27 ~45 wool 1
fill ~52 ~27 ~36 ~52 ~30 ~36 wool 1
fill ~53 ~27 ~43 ~53 ~28 ~43 wool 1
fill ~103 ~27 ~43 ~103 ~28 ~43 wool 1
fill ~104 ~27 ~36 ~104 ~30 ~36 wool 1
setblock ~105 ~27 ~45 wool 1
setblock ~106 ~27 ~35 red_sandstone 0
fill ~107 ~27 ~46 ~108 ~27 ~46 wool 1
fill ~108 ~27 ~33 ~112 ~27 ~33 wool 1
fill ~109 ~27 ~47 ~109 ~28 ~47 wool 1
fill ~110 ~27 ~47 ~111 ~27 ~47 stained_hardened_clay 4
setblock ~112 ~27 ~46 wool 1
setblock ~113 ~27 ~34 concrete 4
setblock ~114 ~27 ~35 stained_hardened_clay 4
setblock ~114 ~27 ~44 wool 1
setblock ~115 ~27 ~39 stained_hardened_clay 4
setblock ~115 ~27 ~40 concrete 4
fill ~115 ~27 ~41 ~115 ~28 ~41 wool 1
setblock ~115 ~27 ~42 concrete 4
setblock ~115 ~27 ~43 wool 1
setblock ~41 ~28 ~37 yellow_glazed_terracotta 0
fill ~41 ~28 ~39 ~41 ~28 ~40 yellow_glazed_terracotta 0
setblock ~41 ~28 ~42 yellow_glazed_terracotta 0
setblock ~41 ~28 ~43 concrete 4
setblock ~42 ~28 ~35 yellow_glazed_terracotta 0
setblock ~42 ~28 ~44 stained_hardened_clay 4
setblock ~42 ~28 ~45 concrete 4
fill ~43 ~28 ~34 ~43 ~33 ~34 yellow_glazed_terracotta 0
setblock ~43 ~28 ~46 concrete 4
setblock ~44 ~28 ~33 yellow_glazed_terracotta 0
setblock ~44 ~28 ~47 concrete 4
setblock ~45 ~28 ~48 yellow_glazed_terracotta 0
setblock ~46 ~28 ~33 concrete 4
setblock ~46 ~28 ~48 stained_hardened_clay 4
fill ~47 ~28 ~33 ~48 ~28 ~33 wool 1
setblock ~48 ~28 ~47 yellow_glazed_terracotta 0
fill ~49 ~28 ~47 ~49 ~29 ~47 wool 1
fill ~50 ~28 ~35 ~51 ~28 ~35 wool 1
setblock ~50 ~28 ~46 wool 1
setblock ~51 ~28 ~46 yellow_glazed_terracotta 0
setblock ~52 ~28 ~45 yellow_glazed_terracotta 0
setblock ~53 ~28 ~39 yellow_glazed_terracotta 0
setblock ~53 ~28 ~44 yellow_glazed_terracotta 0
setblock ~54 ~28 ~40 wool 1
setblock ~54 ~28 ~41 yellow_glazed_terracotta 0
setblock ~54 ~28 ~42 wool 1
setblock ~102 ~28 ~40 wool 1
setblock ~102 ~28 ~41 yellow_glazed_terracotta 0
setblock ~102 ~28 ~42 wool 1
setblock ~103 ~28 ~39 yellow_glazed_terracotta 0
setblock ~103 ~28 ~44 yellow_glazed_terracotta 0
setblock ~104 ~28 ~45 yellow_glazed_terracotta 0
fill ~105 ~28 ~35 ~106 ~28 ~35 wool 1
setblock ~105 ~28 ~46 yellow_glazed_terracotta 0
setblock ~106 ~28 ~46 wool 1
fill ~107 ~28 ~47 ~107 ~29 ~47 wool 1
fill ~108 ~28 ~33 ~109 ~28 ~33 wool 1
setblock ~108 ~28 ~47 yellow_glazed_terracotta 0
setblock ~110 ~28 ~33 concrete 4
setblock ~110 ~28 ~48 stained_hardened_clay 4
setblock ~111 ~28 ~48 yellow_glazed_terracotta 0
setblock ~112 ~28 ~33 yellow_glazed_terracotta 0
setblock ~112 ~28 ~47 concrete 4
fill ~113 ~28 ~34 ~113 ~33 ~34 yellow_glazed_terracotta 0
setblock ~113 ~28 ~46 concrete 4
setblock ~114 ~28 ~35 yellow_glazed_terracotta 0
setblock ~114 ~28 ~44 stained_hardened_clay 4
setblock ~114 ~28 ~45 concrete 4
setblock ~115 ~28 ~37 yellow_glazed_terracotta 0
fill ~115 ~28 ~39 ~115 ~28 ~40 yellow_glazed_terracotta 0
setblock ~115 ~28 ~42 yellow_glazed_terracotta 0
setblock ~115 ~28 ~43 concrete 4
setblock ~40 ~29 ~38 concrete 4
setblock ~40 ~29 ~39 stained_hardened_clay 4
setblock ~40 ~29 ~40 wool 1
setblock ~40 ~29 ~41 stained_hardened_clay 4
setblock ~41 ~29 ~37 stained_hardened_clay 4
setblock ~41 ~29 ~42 concrete 4
fill ~41 ~29 ~43 ~41 ~31 ~43 wool 1
setblock ~41 ~29 ~44 concrete 4
setblock ~42 ~29 ~35 stained_hardened_clay 4
setblock ~42 ~29 ~45 stained_hardened_clay 4
setblock ~42 ~29 ~46 wool 1
fill ~43 ~29 ~47 ~43 ~30 ~47 wool 1
setblock ~44 ~29 ~33 stained_hardened_clay 4
fill ~44 ~29 ~48 ~45 ~29 ~48 concrete 4
fill ~46 ~29 ~33 ~48 ~29 ~33 wool 1
fill ~46 ~29 ~48 ~47 ~29 ~48 wool 1
fill ~48 ~29 ~48 ~48 ~30 ~48 concrete 4
fill ~50 ~29 ~35 ~51 ~29 ~35 wool 1
setblock ~50 ~29 ~47 red_sandstone 0
setblock ~51 ~29 ~46 wool 1
setblock ~52 ~29 ~46 concrete 4
fill ~53 ~29 ~44 ~53 ~29 ~45 wool 1
setblock ~54 ~29 ~39 stained_hardened_clay 4
fill ~54 ~29 ~40 ~54 ~33 ~40 yellow_glazed_terracotta 0
setblock ~54 ~29 ~41 stained_hardened_clay 4
setblock ~54 ~29 ~42 yellow_glazed_terracotta 0
setblock ~54 ~29 ~43 stained_hardened_clay 4
setblock ~102 ~29 ~39 stained_hardened_clay 4
fill ~102 ~29 ~40 ~102 ~33 ~40 yellow_glazed_terracotta 0
setblock ~102 ~29 ~41 stained_hardened_clay 4
setblock ~102 ~29 ~42 yellow_glazed_terracotta 0
setblock ~102 ~29 ~43 stained_hardened_clay 4
fill ~103 ~29 ~44 ~103 ~29 ~45 wool 1
setblock ~104 ~29 ~46 concrete 4
fill ~105 ~29 ~35 ~106 ~29 ~35 wool 1
setblock ~105 ~29 ~46 wool 1
setblock ~106 ~29 ~47 red_sandstone 0
fill ~108 ~29 ~33 ~111 ~29 ~33 wool 1
fill ~108 ~29 ~48 ~108 ~30 ~48 concrete 4
fill ~109 ~29 ~48 ~110 ~29 ~48 wool 1
fill ~111 ~29 ~48 ~112 ~29 ~48 concrete 4
setblock ~112 ~29 ~33 stained_hardened_clay 4
fill ~113 ~29 ~47 ~113 ~30 ~47 wool 1
setblock ~114 ~29 ~35 stained_hardened_clay 4
setblock ~114 ~29 ~45 stained_hardened_clay 4
setblock ~114 ~29 ~46 wool 1
setblock ~115 ~29 ~37 stained_hardened_clay 4
setblock ~115 ~29 ~42 concrete 4
fill ~115 ~29 ~43 ~115 ~31 ~43 wool 1
setblock ~115 ~29 ~44 concrete 4
setblock ~116 ~29 ~38 concrete 4
setblock ~116 ~29 ~39 stained_hardened_clay 4
setblock ~116 ~29 ~40 wool 1
setblock ~116 ~29 ~41 stained_hardened_clay 4
setblock ~40 ~30 ~38 stained_hardened_clay 4
setblock ~40 ~30 ~39 yellow_glazed_terracotta 0
setblock ~40 ~30 ~40 stained_hardened_clay 4
setblock ~40 ~30 ~41 yellow_glazed_terracotta 0
setblock ~40 ~30 ~42 stained_hardened_clay 4
setblock ~41 ~30 ~37 yellow_glazed_terracotta 0
setblock ~41 ~30 ~44 yellow_glazed_terracotta 0
setblock ~41 ~30 ~45 concrete 4
setblock ~42 ~30 ~35 yellow_glazed_terracotta 0
setblock ~42 ~30 ~46 stained_hardened_clay 4
setblock ~44 ~30 ~33 yellow_glazed_terracotta 0
setblock ~44 ~30 ~48 stained_hardened_clay 4
fill ~45 ~30 ~49 ~46 ~30 ~49 concrete 4
setblock ~46 ~30 ~33 concrete 4
fill ~47 ~30 ~33 ~47 ~32 ~33 wool 1
fill ~47 ~30 ~49 ~47 ~31 ~49 wool 1
setblock ~48 ~30 ~34 wool 1
fill ~49 ~30 ~34 ~49 ~33 ~34 yellow_glazed_terracotta 0
setblock ~49 ~30 ~48 concrete 4
setblock ~50 ~30 ~35 yellow_glazed_terracotta 0
fill ~50 ~30 ~47 ~51 ~30 ~47 wool 1
setblock ~51 ~30 ~35 concrete 4
setblock ~52 ~30 ~37 yellow_glazed_terracotta 0
setblock ~52 ~30 ~46 wool 1
setblock ~53 ~30 ~45 concrete 4
setblock ~54 ~30 ~39 yellow_glazed_terracotta 0
setblock ~54 ~30 ~41 yellow_glazed_terracotta 0
setblock ~54 ~30 ~42 wool 1
setblock ~54 ~30 ~43 yellow_glazed_terracotta 0
fill ~54 ~30 ~44 ~54 ~36 ~44 wool 1
setblock ~102 ~30 ~39 yellow_glazed_terracotta 0
setblock ~102 ~30 ~41 yellow_glazed_terracotta 0
setblock ~102 ~30 ~42 wool 1
setblock ~102 ~30 ~43 yellow_glazed_terracotta 0
fill ~102 ~30 ~44 ~102 ~36 ~44 wool 1
setblock ~103 ~30 ~45 concrete 4
setblock ~104 ~30 ~37 yellow_glazed_terracotta 0
setblock ~104 ~30 ~46 wool 1
setblock ~105 ~30 ~35 concrete 4
fill ~105 ~30 ~47 ~106 ~30 ~47 wool 1
setblock ~106 ~30 ~35 yellow_glazed_terracotta 0
fill ~107 ~30 ~34 ~107 ~33 ~34 yellow_glazed_terracotta 0
setblock ~107 ~30 ~48 concrete 4
setblock ~108 ~30 ~34 wool 1
fill ~109 ~30 ~33 ~109 ~32 ~33 wool 1
fill ~109 ~30 ~49 ~109 ~31 ~49 wool 1
setblock ~110 ~30 ~33 concrete 4
fill ~110 ~30 ~49 ~111 ~30 ~49 concrete 4
setblock ~112 ~30 ~33 yellow_glazed_terracotta 0
setblock ~112 ~30 ~48 stained_hardened_clay 4
setblock ~114 ~30 ~35 yellow_glazed_terracotta 0
setblock ~114 ~30 ~46 stained_hardened_clay 4
setblock ~115 ~30 ~37 yellow_glazed_terracotta 0
setblock ~115 ~30 ~44 yellow_glazed_terracotta 0
setblock ~115 ~30 ~45 concrete 4
setblock ~116 ~30 ~38 stained_hardened_clay 4
setblock ~116 ~30 ~39 yellow_glazed_terracotta 0
setblock ~116 ~30 ~40 stained_hardened_clay 4
setblock ~116 ~30 ~41 yellow_glazed_terracotta 0
setblock ~116 ~30 ~42 stained_hardened_clay 4
setblock ~40 ~31 ~37 stained_hardened_clay 4
setblock ~40 ~31 ~38 yellow_glazed_terracotta 0
setblock ~40 ~31 ~39 stained_hardened_clay 4
setblock ~40 ~31 ~40 concrete 4
setblock ~40 ~31 ~41 stained_hardened_clay 4
setblock ~40 ~31 ~42 wool 1
fill ~41 ~31 ~44 ~41 ~32 ~44 concrete 4
fill ~41 ~31 ~45 ~41 ~34 ~45 wool 1
setblock ~42 ~31 ~35 stained_hardened_clay 4
setblock ~42 ~31 ~46 wool 1
setblock ~42 ~31 ~47 stained_hardened_clay 4
setblock ~43 ~31 ~48 wool 1
setblock ~44 ~31 ~34 yellow_glazed_terracotta 0
setblock ~44 ~31 ~49 stained_hardened_clay 4
fill ~45 ~31 ~49 ~45 ~30 ~49 concrete 4
setblock ~46 ~31 ~33 wool 1
setblock ~46 ~31 ~49 stained_hardened_clay 4
setblock ~48 ~31 ~34 yellow_glazed_terracotta 0
setblock ~48 ~31 ~49 stained_hardened_clay 4
fill ~49 ~31 ~48 ~50 ~31 ~48 wool 1
fill ~50 ~31 ~35 ~51 ~31 ~35 wool 1
setblock ~51 ~31 ~47 wool 1
setblock ~52 ~31 ~36 concrete 4
setblock ~52 ~31 ~47 stained_hardened_clay 4
setblock ~53 ~31 ~37 wool 1
setblock ~53 ~31 ~45 wool 1
fill ~53 ~31 ~46 ~53 ~32 ~46 yellow_glazed_terracotta 0
setblock ~54 ~31 ~39 stained_hardened_clay 4
setblock ~54 ~31 ~41 stained_hardened_clay 4
fill ~54 ~31 ~42 ~54 ~33 ~42 yellow_glazed_terracotta 0
setblock ~54 ~31 ~43 stained_hardened_clay 4
setblock ~102 ~31 ~39 stained_hardened_clay 4
setblock ~102 ~31 ~41 stained_hardened_clay 4
fill ~102 ~31 ~42 ~102 ~33 ~42 yellow_glazed_terracotta 0
setblock ~102 ~31 ~43 stained_hardened_clay 4
setblock ~103 ~31 ~37 wool 1
setblock ~103 ~31 ~45 wool 1
fill ~103 ~31 ~46 ~103 ~32 ~46 yellow_glazed_terracotta 0
setblock ~104 ~31 ~36 concrete 4
setblock ~104 ~31 ~47 stained_hardened_clay 4
fill ~105 ~31 ~35 ~106 ~31 ~35 wool 1
fill ~105 ~31 ~47 ~105 ~30 ~47 wool 1
fill ~106 ~31 ~48 ~107 ~31 ~48 wool 1
setblock ~108 ~31 ~34 yellow_glazed_terracotta 0
setblock ~108 ~31 ~49 stained_hardened_clay 4
setblock ~110 ~31 ~33 wool 1
setblock ~110 ~31 ~49 stained_hardened_clay 4
setblock ~111 ~31 ~49 concrete 4
setblock ~112 ~31 ~34 yellow_glazed_terracotta 0
setblock ~112 ~31 ~49 stained_hardened_clay 4
setblock ~113 ~31 ~48 wool 1
setblock ~114 ~31 ~35 stained_hardened_clay 4
setblock ~114 ~31 ~46 wool 1
setblock ~114 ~31 ~47 stained_hardened_clay 4
fill ~115 ~31 ~44 ~115 ~32 ~44 concrete 4
fill ~115 ~31 ~45 ~115 ~34 ~45 wool 1
setblock ~116 ~31 ~37 stained_hardened_clay 4
setblock ~116 ~31 ~38 yellow_glazed_terracotta 0
setblock ~116 ~31 ~39 stained_hardened_clay 4
setblock ~116 ~31 ~40 concrete 4
setblock ~116 ~31 ~41 stained_hardened_clay 4
setblock ~116 ~31 ~42 wool 1
setblock ~40 ~32 ~38 stained_hardened_clay 4
setblock ~40 ~32 ~39 yellow_glazed_terracotta 0
setblock ~40 ~32 ~40 stained_hardened_clay 4
setblock ~40 ~32 ~41 yellow_glazed_terracotta 0
setblock ~40 ~32 ~42 stained_hardened_clay 4
setblock ~40 ~32 ~43 concrete 4
setblock ~41 ~32 ~37 yellow_glazed_terracotta 0
fill ~41 ~32 ~46 ~41 ~33 ~46 concrete 4
setblock ~42 ~32 ~35 yellow_glazed_terracotta 0
setblock ~42 ~32 ~47 concrete 4
setblock ~43 ~32 ~48 concrete 4
fill ~43 ~32 ~49 ~43 ~33 ~49 wool 1
setblock ~44 ~32 ~34 concrete 4
setblock ~44 ~32 ~50 stained_hardened_clay 4
fill ~45 ~32 ~33 ~45 ~33 ~33 concrete 4
setblock ~45 ~32 ~50 yellow_glazed_terracotta 0
setblock ~46 ~32 ~33 yellow_glazed_terracotta 0
setblock ~46 ~32 ~50 stained_hardened_clay 4
setblock ~47 ~32 ~50 concrete 4
setblock ~48 ~32 ~34 wool 1
setblock ~48 ~32 ~49 yellow_glazed_terracotta 0
setblock ~49 ~32 ~49 wool 1
fill ~50 ~32 ~35 ~51 ~32 ~35 yellow_glazed_terracotta 0
setblock ~50 ~32 ~48 red_sandstone 0
setblock ~51 ~32 ~48 yellow_glazed_terracotta 0
setblock ~52 ~32 ~36 wool 1
setblock ~52 ~32 ~37 yellow_glazed_terracotta 0
setblock ~52 ~32 ~47 yellow_glazed_terracotta 0
setblock ~54 ~32 ~39 yellow_glazed_terracotta 0
setblock ~54 ~32 ~41 yellow_glazed_terracotta 0
setblock ~54 ~32 ~43 yellow_glazed_terracotta 0
setblock ~54 ~32 ~45 concrete 4
setblock ~102 ~32 ~39 yellow_glazed_terracotta 0
setblock ~102 ~32 ~41 yellow_glazed_terracotta 0
setblock ~102 ~32 ~43 yellow_glazed_terracotta 0
setblock ~102 ~32 ~45 concrete 4
setblock ~104 ~32 ~36 wool 1
setblock ~104 ~32 ~37 yellow_glazed_terracotta 0
setblock ~104 ~32 ~47 yellow_glazed_terracotta 0
fill ~105 ~32 ~35 ~106 ~32 ~35 yellow_glazed_terracotta 0
setblock ~105 ~32 ~48 yellow_glazed_terracotta 0
setblock ~106 ~32 ~48 red_sandstone 0
setblock ~107 ~32 ~49 wool 1
setblock ~108 ~32 ~34 wool 1
setblock ~108 ~32 ~49 yellow_glazed_terracotta 0
setblock ~109 ~32 ~50 concrete 4
setblock ~110 ~32 ~33 yellow_glazed_terracotta 0
setblock ~110 ~32 ~50 stained_hardened_clay 4
fill ~111 ~32 ~33 ~111 ~33 ~33 concrete 4
setblock ~111 ~32 ~50 yellow_glazed_terracotta 0
setblock ~112 ~32 ~34 concrete 4
setblock ~112 ~32 ~50 stained_hardened_clay 4
setblock ~113 ~32 ~48 concrete 4
fill ~113 ~32 ~49 ~113 ~33 ~49 wool 1
setblock ~114 ~32 ~35 yellow_glazed_terracotta 0
setblock ~114 ~32 ~47 concrete 4
setblock ~115 ~32 ~37 yellow_glazed_terracotta 0
fill ~115 ~32 ~46 ~115 ~33 ~46 concrete 4
setblock ~116 ~32 ~38 stained_hardened_clay 4
setblock ~116 ~32 ~39 yellow_glazed_terracotta 0
setblock ~116 ~32 ~40 stained_hardened_clay 4
setblock ~116 ~32 ~41 yellow_glazed_terracotta 0
setblock ~116 ~32 ~42 stained_hardened_clay 4
setblock ~116 ~32 ~43 concrete 4
setblock ~40 ~33 ~38 concrete 4
setblock ~40 ~33 ~39 stained_hardened_clay 4
setblock ~40 ~33 ~40 concrete 4
setblock ~40 ~33 ~41 stained_hardened_clay 4
setblock ~40 ~33 ~42 wool 1
setblock ~40 ~33 ~43 stained_hardened_clay 4
setblock ~40 ~33 ~44 wool 1
setblock ~41 ~33 ~37 stained_hardened_clay 4
setblock ~42 ~33 ~35 stained_hardened_clay 4
setblock ~42 ~33 ~47 stained_hardened_clay 4
setblock ~42 ~33 ~48 wool 1
setblock ~44 ~33 ~34 yellow_glazed_terracotta 0
setblock ~44 ~33 ~50 concrete 4
setblock ~45 ~33 ~51 wool 1
setblock ~46 ~33 ~33 stained_hardened_clay 4
fill ~46 ~33 ~50 ~47 ~33 ~50 wool 1
setblock ~47 ~33 ~33 concrete 4
fill ~48 ~33 ~34 ~48 ~34 ~34 yellow_glazed_terracotta 0
fill ~48 ~33 ~50 ~48 ~34 ~50 concrete 4
setblock ~49 ~33 ~49 red_sandstone 0
setblock ~50 ~33 ~35 stained_hardened_clay 4
setblock ~50 ~33 ~48 wool 1
fill ~51 ~33 ~36 ~51 ~34 ~36 yellow_glazed_terracotta 0
setblock ~51 ~33 ~48 concrete 4
setblock ~52 ~33 ~37 stained_hardened_clay 4
setblock ~52 ~33 ~47 stained_hardened_clay 4
fill ~53 ~33 ~39 ~53 ~34 ~39 yellow_glazed_terracotta 0
setblock ~53 ~33 ~46 wool 1
setblock ~54 ~33 ~41 stained_hardened_clay 4
setblock ~54 ~33 ~43 wool 1
setblock ~54 ~33 ~45 stained_hardened_clay 4
setblock ~102 ~33 ~41 stained_hardened_clay 4
setblock ~102 ~33 ~43 wool 1
setblock ~102 ~33 ~45 stained_hardened_clay 4
fill ~103 ~33 ~39 ~103 ~34 ~39 yellow_glazed_terracotta 0
setblock ~103 ~33 ~46 wool 1
setblock ~104 ~33 ~37 stained_hardened_clay 4
setblock ~104 ~33 ~47 stained_hardened_clay 4
fill ~105 ~33 ~36 ~105 ~34 ~36 yellow_glazed_terracotta 0
setblock ~105 ~33 ~48 concrete 4
setblock ~106 ~33 ~35 stained_hardened_clay 4
setblock ~106 ~33 ~48 wool 1
setblock ~107 ~33 ~49 red_sandstone 0
fill ~108 ~33 ~34 ~108 ~34 ~34 yellow_glazed_terracotta 0
fill ~108 ~33 ~50 ~108 ~34 ~50 concrete 4
setblock ~109 ~33 ~33 concrete 4
fill ~109 ~33 ~50 ~110 ~33 ~50 wool 1
setblock ~110 ~33 ~33 stained_hardened_clay 4
setblock ~111 ~33 ~51 wool 1
setblock ~112 ~33 ~34 yellow_glazed_terracotta 0
setblock ~112 ~33 ~50 concrete 4
setblock ~114 ~33 ~35 stained_hardened_clay 4
setblock ~114 ~33 ~47 stained_hardened_clay 4
setblock ~114 ~33 ~48 wool 1
setblock ~115 ~33 ~37 stained_hardened_clay 4
setblock ~116 ~33 ~38 concrete 4
setblock ~116 ~33 ~39 stained_hardened_clay 4
setblock ~116 ~33 ~40 concrete 4
setblock ~116 ~33 ~41 stained_hardened_clay 4
setblock ~116 ~33 ~42 wool 1
setblock ~116 ~33 ~43 stained_hardened_clay 4
setblock ~116 ~33 ~44 wool 1
setblock ~40 ~34 ~39 yellow_glazed_terracotta 0
setblock ~40 ~34 ~40 stained_hardened_clay 4
setblock ~40 ~34 ~41 yellow_glazed_terracotta 0
setblock ~40 ~34 ~42 stained_hardened_clay 4
setblock ~40 ~34 ~43 yellow_glazed_terracotta 0
setblock ~40 ~34 ~44 stained_hardened_clay 4
fill ~41 ~34 ~37 ~41 ~34 ~38 yellow_glazed_terracotta 0
setblock ~41 ~34 ~46 yellow_glazed_terracotta 0
fill ~41 ~34 ~47 ~41 ~36 ~47 wool 1
fill ~42 ~34 ~35 ~43 ~34 ~35 yellow_glazed_terracotta 0
fill ~42 ~34 ~36 ~42 ~35 ~36 concrete 4
setblock ~42 ~34 ~48 stained_hardened_clay 4
setblock ~42 ~34 ~49 concrete 4
setblock ~43 ~34 ~50 yellow_glazed_terracotta 0
setblock ~44 ~34 ~34 concrete 4
setblock ~44 ~34 ~51 yellow_glazed_terracotta 0
fill ~45 ~34 ~34 ~48 ~34 ~34 yellow_glazed_terracotta 0
fill ~45 ~34 ~51 ~46 ~34 ~51 concrete 4
fill ~47 ~34 ~51 ~47 ~35 ~51 wool 1
fill ~49 ~34 ~35 ~50 ~34 ~35 yellow_glazed_terracotta 0
fill ~49 ~34 ~50 ~49 ~35 ~50 wool 1
setblock ~50 ~34 ~49 wool 1
fill ~51 ~34 ~49 ~51 ~36 ~49 concrete 4
fill ~52 ~34 ~37 ~52 ~34 ~38 yellow_glazed_terracotta 0
fill ~52 ~34 ~48 ~52 ~40 ~48 wool 1
fill ~53 ~34 ~40 ~53 ~35 ~40 yellow_glazed_terracotta 0
setblock ~53 ~34 ~46 yellow_glazed_terracotta 0
fill ~53 ~34 ~47 ~53 ~42 ~47 wool 1
setblock ~54 ~34 ~41 yellow_glazed_terracotta 0
fill ~54 ~34 ~42 ~54 ~35 ~42 concrete 4
setblock ~54 ~34 ~43 yellow_glazed_terracotta 0
setblock ~54 ~34 ~45 concrete 4
setblock ~102 ~34 ~41 yellow_glazed_terracotta 0
fill ~102 ~34 ~42 ~102 ~35 ~42 concrete 4
setblock ~102 ~34 ~43 yellow_glazed_terracotta 0
setblock ~102 ~34 ~45 concrete 4
fill ~103 ~34 ~40 ~103 ~35 ~40 yellow_glazed_terracotta 0
setblock ~103 ~34 ~46 yellow_glazed_terracotta 0
fill ~103 ~34 ~47 ~103 ~42 ~47 wool 1
fill ~104 ~34 ~37 ~104 ~34 ~38 yellow_glazed_terracotta 0
fill ~104 ~34 ~48 ~104 ~40 ~48 wool 1
fill ~105 ~34 ~49 ~105 ~36 ~49 concrete 4
fill ~106 ~34 ~35 ~107 ~34 ~35 yellow_glazed_terracotta 0
setblock ~106 ~34 ~49 wool 1
fill ~107 ~34 ~50 ~107 ~35 ~50 wool 1
fill ~109 ~34 ~34 ~111 ~34 ~34 yellow_glazed_terracotta 0
fill ~109 ~34 ~51 ~109 ~35 ~51 wool 1
fill ~110 ~34 ~51 ~111 ~34 ~51 concrete 4
setblock ~112 ~34 ~34 concrete 4
setblock ~112 ~34 ~51 yellow_glazed_terracotta 0
fill ~113 ~34 ~35 ~114 ~34 ~35 yellow_glazed_terracotta 0
setblock ~113 ~34 ~50 yellow_glazed_terracotta 0
fill ~114 ~34 ~36 ~114 ~35 ~36 concrete 4
setblock ~114 ~34 ~48 stained_hardened_clay 4
setblock ~114 ~34 ~49 concrete 4
fill ~115 ~34 ~37 ~115 ~34 ~38 yellow_glazed_terracotta 0
setblock ~115 ~34 ~46 yellow_glazed_terracotta 0
fill ~115 ~34 ~47 ~115 ~36 ~47 wool 1
setblock ~116 ~34 ~39 yellow_glazed_terracotta 0
setblock ~116 ~34 ~40 stained_hardened_clay 4
setblock ~116 ~34 ~41 yellow_glazed_terracotta 0
setblock ~116 ~34 ~42 stained_hardened_clay 4
setblock ~116 ~34 ~43 yellow_glazed_terracotta 0
setblock ~116 ~34 ~44 stained_hardened_clay 4
setblock ~40 ~35 ~39 stained_hardened_clay 4
setblock ~40 ~35 ~40 concrete 4
setblock ~40 ~35 ~41 stained_hardened_clay 4
setblock ~40 ~35 ~42 concrete 4
setblock ~40 ~35 ~43 stained_hardened_clay 4
fill ~40 ~35 ~44 ~40 ~37 ~44 wool 1
fill ~40 ~35 ~45 ~40 ~35 ~44 wool 1
setblock ~41 ~35 ~37 concrete 4
fill ~41 ~35 ~38 ~41 ~36 ~38 yellow_glazed_terracotta 0
setblock ~41 ~35 ~46 wool 1
fill ~41 ~35 ~48 ~41 ~38 ~48 wool 1
setblock ~42 ~35 ~49 stained_hardened_clay 4
setblock ~43 ~35 ~35 yellow_glazed_terracotta 0
setblock ~43 ~35 ~50 wool 1
setblock ~44 ~35 ~35 concrete 4
setblock ~44 ~35 ~51 stained_hardened_clay 4
fill ~45 ~35 ~34 ~47 ~35 ~34 yellow_glazed_terracotta 0
setblock ~45 ~35 ~52 concrete 4
setblock ~46 ~35 ~51 stained_hardened_clay 4
setblock ~48 ~35 ~35 stained_hardened_clay 4
setblock ~48 ~35 ~51 stained_hardened_clay 4
setblock ~49 ~35 ~35 concrete 4
setblock ~50 ~35 ~36 yellow_glazed_terracotta 0
setblock ~50 ~35 ~49 red_sandstone 0
setblock ~51 ~35 ~37 wool 1
setblock ~52 ~35 ~38 yellow_glazed_terracotta 0
setblock ~53 ~35 ~39 stained_hardened_clay 4
setblock ~53 ~35 ~46 wool 1
setblock ~54 ~35 ~41 wool 1
setblock ~54 ~35 ~43 wool 1
setblock ~54 ~35 ~45 wool 1
setblock ~102 ~35 ~41 wool 1
setblock ~102 ~35 ~43 wool 1
setblock ~102 ~35 ~45 wool 1
setblock ~103 ~35 ~39 stained_hardened_clay 4
setblock ~103 ~35 ~46 wool 1
setblock ~104 ~35 ~38 yellow_glazed_terracotta 0
setblock ~105 ~35 ~37 wool 1
setblock ~106 ~35 ~36 yellow_glazed_terracotta 0
setblock ~106 ~35 ~49 red_sandstone 0
setblock ~107 ~35 ~35 concrete 4
setblock ~108 ~35 ~35 stained_hardened_clay 4
setblock ~108 ~35 ~51 stained_hardened_clay 4
fill ~109 ~35 ~34 ~111 ~35 ~34 yellow_glazed_terracotta 0
setblock ~110 ~35 ~51 stained_hardened_clay 4
setblock ~111 ~35 ~52 concrete 4
setblock ~112 ~35 ~35 concrete 4
setblock ~112 ~35 ~51 stained_hardened_clay 4
fill ~113 ~35 ~35 ~113 ~34 ~35 yellow_glazed_terracotta 0
setblock ~113 ~35 ~50 wool 1
setblock ~114 ~35 ~49 stained_hardened_clay 4
setblock ~115 ~35 ~37 concrete 4
fill ~115 ~35 ~38 ~115 ~36 ~38 yellow_glazed_terracotta 0
setblock ~115 ~35 ~46 wool 1
fill ~115 ~35 ~48 ~115 ~38 ~48 wool 1
setblock ~116 ~35 ~39 stained_hardened_clay 4
setblock ~116 ~35 ~40 concrete 4
setblock ~116 ~35 ~41 stained_hardened_clay 4
setblock ~116 ~35 ~42 concrete 4
setblock ~116 ~35 ~43 stained_hardened_clay 4
fill ~116 ~35 ~44 ~116 ~37 ~44 wool 1
fill ~116 ~35 ~45 ~116 ~35 ~44 wool 1
setblock ~40 ~36 ~40 stained_hardened_clay 4
setblock ~40 ~36 ~41 yellow_glazed_terracotta 0
setblock ~40 ~36 ~42 stained_hardened_clay 4
setblock ~40 ~36 ~43 yellow_glazed_terracotta 0
setblock ~40 ~36 ~45 concrete 4
fill ~40 ~36 ~46 ~40 ~39 ~46 wool 1
setblock ~41 ~36 ~39 yellow_glazed_terracotta 0
setblock ~42 ~36 ~37 yellow_glazed_terracotta 0
fill ~42 ~36 ~49 ~42 ~36 ~50 wool 1
setblock ~43 ~36 ~36 yellow_glazed_terracotta 0
fill ~43 ~36 ~51 ~43 ~37 ~51 wool 1
setblock ~44 ~36 ~35 yellow_glazed_terracotta 0
fill ~44 ~36 ~52 ~46 ~36 ~52 wool 1
setblock ~45 ~36 ~35 concrete 4
fill ~46 ~36 ~35 ~48 ~36 ~35 yellow_glazed_terracotta 0
setblock ~47 ~36 ~52 yellow_glazed_terracotta 0
setblock ~48 ~36 ~52 stained_hardened_clay 4
setblock ~49 ~36 ~36 yellow_glazed_terracotta 0
fill ~49 ~36 ~51 ~49 ~37 ~51 wool 1
setblock ~50 ~36 ~36 wool 1
setblock ~50 ~36 ~50 red_sandstone 0
setblock ~51 ~36 ~37 concrete 4
setblock ~52 ~36 ~38 wool 1
setblock ~52 ~36 ~39 concrete 4
setblock ~53 ~36 ~40 concrete 4
fill ~53 ~36 ~41 ~53 ~37 ~41 wool 1
setblock ~53 ~36 ~42 yellow_glazed_terracotta 0
fill ~53 ~36 ~43 ~53 ~42 ~43 wool 1
fill ~53 ~36 ~45 ~53 ~42 ~45 wool 1
setblock ~53 ~36 ~46 concrete 4
setblock ~103 ~36 ~40 concrete 4
fill ~103 ~36 ~41 ~103 ~37 ~41 wool 1
setblock ~103 ~36 ~42 yellow_glazed_terracotta 0
fill ~103 ~36 ~43 ~103 ~42 ~43 wool 1
fill ~103 ~36 ~45 ~103 ~42 ~45 wool 1
setblock ~103 ~36 ~46 concrete 4
setblock ~104 ~36 ~38 wool 1
setblock ~104 ~36 ~39 concrete 4
setblock ~105 ~36 ~37 concrete 4
setblock ~106 ~36 ~36 wool 1
setblock ~106 ~36 ~50 red_sandstone 0
setblock ~107 ~36 ~36 yellow_glazed_terracotta 0
fill ~107 ~36 ~51 ~107 ~37 ~51 wool 1
fill ~108 ~36 ~35 ~110 ~36 ~35 yellow_glazed_terracotta 0
setblock ~108 ~36 ~52 stained_hardened_clay 4
setblock ~109 ~36 ~52 yellow_glazed_terracotta 0
fill ~110 ~36 ~52 ~112 ~36 ~52 wool 1
setblock ~111 ~36 ~35 concrete 4
setblock ~112 ~36 ~35 yellow_glazed_terracotta 0
setblock ~113 ~36 ~36 yellow_glazed_terracotta 0
fill ~113 ~36 ~51 ~113 ~37 ~51 wool 1
setblock ~114 ~36 ~37 yellow_glazed_terracotta 0
fill ~114 ~36 ~49 ~114 ~36 ~50 wool 1
setblock ~115 ~36 ~39 yellow_glazed_terracotta 0
setblock ~116 ~36 ~40 stained_hardened_clay 4
setblock ~116 ~36 ~41 yellow_glazed_terracotta 0
setblock ~116 ~36 ~42 stained_hardened_clay 4
setblock ~116 ~36 ~43 yellow_glazed_terracotta 0
setblock ~116 ~36 ~45 concrete 4
fill ~116 ~36 ~46 ~116 ~39 ~46 wool 1
setblock ~40 ~37 ~41 stained_hardened_clay 4
setblock ~40 ~37 ~42 concrete 4
setblock ~40 ~37 ~43 stained_hardened_clay 4
setblock ~40 ~37 ~45 wool 1
fill ~40 ~37 ~47 ~40 ~39 ~47 wool 1
setblock ~41 ~37 ~39 concrete 4
fill ~41 ~37 ~40 ~41 ~39 ~40 yellow_glazed_terracotta 0
fill ~41 ~37 ~49 ~41 ~39 ~49 wool 1
setblock ~42 ~37 ~37 stained_hardened_clay 4
setblock ~42 ~37 ~38 concrete 4
setblock ~42 ~37 ~50 wool 1
fill ~43 ~37 ~36 ~45 ~37 ~36 concrete 4
fill ~43 ~37 ~52 ~44 ~37 ~52 wool 1
fill ~45 ~37 ~53 ~45 ~38 ~53 wool 1
setblock ~46 ~37 ~35 wool 1
setblock ~46 ~37 ~53 red_sandstone 0
fill ~47 ~37 ~36 ~49 ~37 ~36 wool 1
fill ~47 ~37 ~52 ~48 ~37 ~52 wool 1
setblock ~50 ~37 ~37 wool 1
setblock ~50 ~37 ~50 wool 1
setblock ~51 ~37 ~38 wool 1
setblock ~51 ~37 ~50 concrete 4
fill ~52 ~37 ~39 ~52 ~37 ~40 wool 1
setblock ~52 ~37 ~49 stained_hardened_clay 4
setblock ~53 ~37 ~42 wool 1
setblock ~53 ~37 ~44 wool 1
setblock ~53 ~37 ~46 wool 1
setblock ~103 ~37 ~42 wool 1
setblock ~103 ~37 ~44 wool 1
setblock ~103 ~37 ~46 wool 1
fill ~104 ~37 ~39 ~104 ~37 ~40 wool 1
setblock ~104 ~37 ~49 stained_hardened_clay 4
setblock ~105 ~37 ~38 wool 1
setblock ~105 ~37 ~50 concrete 4
setblock ~106 ~37 ~37 wool 1
setblock ~106 ~37 ~50 wool 1
fill ~107 ~37 ~36 ~109 ~37 ~36 wool 1
fill ~108 ~37 ~52 ~109 ~37 ~52 wool 1
setblock ~110 ~37 ~35 wool 1
setblock ~110 ~37 ~53 red_sandstone 0
fill ~111 ~37 ~36 ~113 ~37 ~36 concrete 4
fill ~111 ~37 ~53 ~111 ~38 ~53 wool 1
fill ~112 ~37 ~52 ~113 ~37 ~52 wool 1
setblock ~114 ~37 ~37 stained_hardened_clay 4
setblock ~114 ~37 ~38 concrete 4
setblock ~114 ~37 ~50 wool 1
setblock ~115 ~37 ~39 concrete 4
fill ~115 ~37 ~40 ~115 ~39 ~40 yellow_glazed_terracotta 0
fill ~115 ~37 ~49 ~115 ~39 ~49 wool 1
setblock ~116 ~37 ~41 stained_hardened_clay 4
setblock ~116 ~37 ~42 concrete 4
setblock ~116 ~37 ~43 stained_hardened_clay 4
setblock ~116 ~37 ~45 wool 1
fill ~116 ~37 ~47 ~116 ~39 ~47 wool 1
setblock ~40 ~38 ~42 stained_hardened_clay 4
setblock ~40 ~38 ~43 yellow_glazed_terracotta 0
setblock ~40 ~38 ~44 stained_hardened_clay 4
setblock ~40 ~38 ~45 concrete 4
setblock ~41 ~38 ~41 concrete 4
fill ~41 ~38 ~50 ~41 ~39 ~50 wool 1
setblock ~42 ~38 ~39 yellow_glazed_terracotta 0
setblock ~42 ~38 ~51 wool 1
fill ~43 ~38 ~37 ~44 ~38 ~37 concrete 4
setblock ~43 ~38 ~38 yellow_glazed_terracotta 0
setblock ~43 ~38 ~52 yellow_glazed_terracotta 0
setblock ~44 ~38 ~53 wool 1
setblock ~45 ~38 ~36 concrete 4
setblock ~46 ~38 ~36 concrete 1
fill ~46 ~38 ~53 ~47 ~38 ~53 wool 1
fill ~47 ~38 ~36 ~47 ~37 ~36 wool 1
fill ~48 ~38 ~37 ~49 ~38 ~37 wool 1
setblock ~48 ~38 ~53 concrete 4
setblock ~49 ~38 ~52 yellow_glazed_terracotta 0
setblock ~50 ~38 ~38 concrete 1
setblock ~50 ~38 ~51 wool 1
setblock ~51 ~38 ~39 wool 1
setblock ~51 ~38 ~50 yellow_glazed_terracotta 0
setblock ~52 ~38 ~40 concrete 1
setblock ~52 ~38 ~41 wool 1
setblock ~52 ~38 ~42 concrete 1
setblock ~52 ~38 ~49 concrete 4
setblock ~53 ~38 ~44 concrete 4
setblock ~53 ~38 ~46 concrete 4
setblock ~103 ~38 ~44 concrete 4
setblock ~103 ~38 ~46 concrete 4
setblock ~104 ~38 ~40 concrete 1
setblock ~104 ~38 ~41 wool 1
setblock ~104 ~38 ~42 concrete 1
setblock ~104 ~38 ~49 concrete 4
setblock ~105 ~38 ~39 wool 1
setblock ~105 ~38 ~50 yellow_glazed_terracotta 0
setblock ~106 ~38 ~38 concrete 1
setblock ~106 ~38 ~51 wool 1
fill ~107 ~38 ~37 ~108 ~38 ~37 wool 1
setblock ~107 ~38 ~52 yellow_glazed_terracotta 0
setblock ~108 ~38 ~53 concrete 4
setblock ~109 ~38 ~36 wool 1
fill ~109 ~38 ~53 ~112 ~38 ~53 wool 1
setblock ~110 ~38 ~36 concrete 1
fill ~111 ~38 ~36 ~111 ~37 ~36 concrete 4
fill ~112 ~38 ~37 ~113 ~38 ~37 concrete 4
setblock ~113 ~38 ~38 yellow_glazed_terracotta 0
setblock ~113 ~38 ~52 yellow_glazed_terracotta 0
setblock ~114 ~38 ~39 yellow_glazed_terracotta 0
setblock ~114 ~38 ~51 wool 1
setblock ~115 ~38 ~41 concrete 4
fill ~115 ~38 ~50 ~115 ~39 ~50 wool 1
setblock ~116 ~38 ~42 stained_hardened_clay 4
setblock ~116 ~38 ~43 yellow_glazed_terracotta 0
setblock ~116 ~38 ~44 stained_hardened_clay 4
setblock ~116 ~38 ~45 concrete 4
setblock ~40 ~39 ~43 stained_hardened_clay 4
setblock ~40 ~39 ~44 concrete 4
setblock ~40 ~39 ~45 stained_hardened_clay 4
fill ~40 ~39 ~48 ~40 ~45 ~48 wool 1
setblock ~41 ~39 ~41 stained_hardened_clay 4
fill ~41 ~39 ~42 ~41 ~41 ~42 yellow_glazed_terracotta 0
fill ~41 ~39 ~51 ~41 ~46 ~51 wool 1
setblock ~42 ~39 ~39 stained_hardened_clay 4
fill ~42 ~39 ~52 ~42 ~40 ~52 wool 1
fill ~43 ~39 ~39 ~43 ~40 ~39 wool 1
fill ~43 ~39 ~53 ~43 ~40 ~53 wool 1
fill ~44 ~39 ~37 ~45 ~39 ~37 wool 1
fill ~44 ~39 ~38 ~44 ~39 ~37 wool 1
fill ~44 ~39 ~54 ~44 ~46 ~54 wool 1
setblock ~45 ~39 ~54 yellow_glazed_terracotta 0
fill ~46 ~39 ~37 ~48 ~39 ~37 concrete 1
fill ~46 ~39 ~54 ~47 ~39 ~54 wool 1
fill ~48 ~39 ~53 ~49 ~39 ~53 wool 1
setblock ~49 ~39 ~38 concrete 1
fill ~50 ~39 ~39 ~50 ~41 ~39 concrete 1
setblock ~50 ~39 ~52 wool 1
fill ~51 ~39 ~40 ~51 ~41 ~40 wool 1
fill ~51 ~39 ~50 ~51 ~39 ~51 concrete 4
setblock ~52 ~39 ~41 concrete 1
setblock ~52 ~39 ~42 wool 1
setblock ~52 ~39 ~49 stained_hardened_clay 4
fill ~53 ~39 ~44 ~53 ~42 ~44 wool 1
fill ~53 ~39 ~46 ~53 ~41 ~46 wool 1
fill ~103 ~39 ~44 ~103 ~42 ~44 wool 1
fill ~103 ~39 ~46 ~103 ~41 ~46 wool 1
setblock ~104 ~39 ~41 concrete 1
setblock ~104 ~39 ~42 wool 1
setblock ~104 ~39 ~49 stained_hardened_clay 4
fill ~105 ~39 ~40 ~105 ~41 ~40 wool 1
fill ~105 ~39 ~50 ~105 ~39 ~51 concrete 4
fill ~106 ~39 ~39 ~106 ~41 ~39 concrete 1
setblock ~106 ~39 ~52 wool 1
setblock ~107 ~39 ~38 concrete 1
fill ~107 ~39 ~53 ~108 ~39 ~53 wool 1
fill ~108 ~39 ~37 ~110 ~39 ~37 concrete 1
fill ~109 ~39 ~54 ~110 ~39 ~54 wool 1
fill ~111 ~39 ~37 ~112 ~39 ~37 wool 1
setblock ~111 ~39 ~54 yellow_glazed_terracotta 0
setblock ~112 ~39 ~38 wool 1
fill ~112 ~39 ~54 ~112 ~46 ~54 wool 1
fill ~113 ~39 ~39 ~113 ~40 ~39 wool 1
fill ~113 ~39 ~53 ~113 ~40 ~53 wool 1
setblock ~114 ~39 ~39 stained_hardened_clay 4
fill ~114 ~39 ~52 ~114 ~40 ~52 wool 1
setblock ~115 ~39 ~41 stained_hardened_clay 4
fill ~115 ~39 ~42 ~115 ~41 ~42 yellow_glazed_terracotta 0
fill ~115 ~39 ~51 ~115 ~46 ~51 wool 1
setblock ~116 ~39 ~43 stained_hardened_clay 4
setblock ~116 ~39 ~44 concrete 4
setblock ~116 ~39 ~45 stained_hardened_clay 4
fill ~116 ~39 ~48 ~116 ~45 ~48 wool 1
setblock ~40 ~40 ~44 stained_hardened_clay 4
setblock ~40 ~40 ~45 concrete 4
setblock ~40 ~40 ~46 stained_hardened_clay 4
setblock ~40 ~40 ~47 yellow_glazed_terracotta 0
setblock ~40 ~40 ~49 yellow_glazed_terracotta 0
setblock ~41 ~40 ~41 concrete 4
setblock ~41 ~40 ~43 concrete 4
setblock ~41 ~40 ~50 yellow_glazed_terracotta 0
setblock ~42 ~40 ~40 stained_hardened_clay 4
