setblock ~25 ~0 ~78 stained_glass 15
setblock ~26 ~0 ~79 stained_glass 15
setblock ~27 ~0 ~79 concrete 15
setblock ~23 ~1 ~76 stained_glass 15
setblock ~24 ~1 ~77 wool 15
setblock ~25 ~1 ~77 concrete 7
setblock ~26 ~1 ~78 stained_glass 15
setblock ~27 ~1 ~79 stained_glass 15
setblock ~28 ~1 ~80 wool 15
setblock ~29 ~1 ~81 wool 15
fill ~30 ~1 ~82 ~31 ~1 ~82 wool 15
setblock ~32 ~1 ~83 stained_glass 15
fill ~54 ~1 ~83 ~54 ~2 ~83 stained_glass 15
fill ~55 ~1 ~82 ~56 ~1 ~82 stained_glass 15
setblock ~23 ~2 ~76 concrete 15
setblock ~24 ~2 ~76 concrete 7
setblock ~31 ~2 ~82 stained_glass 15
fill ~55 ~2 ~82 ~55 ~3 ~82 concrete 15
fill ~56 ~2 ~81 ~56 ~3 ~81 stained_glass 15
setblock ~22 ~3 ~75 stained_glass 15
setblock ~23 ~3 ~75 obsidian
setblock ~24 ~3 ~76 stained_glass 15
setblock ~70 ~3 ~70 stained_glass 15
fill ~18 ~4 ~71 ~18 ~6 ~71 concrete 15
fill ~19 ~4 ~72 ~19 ~5 ~72 stained_glass 15
setblock ~21 ~4 ~74 stained_glass 15
setblock ~22 ~4 ~74 obsidian
setblock ~35 ~4 ~84 stained_glass 15
fill ~36 ~4 ~85 ~36 ~5 ~85 concrete 15
setblock ~37 ~4 ~85 stained_glass 15
setblock ~54 ~4 ~82 concrete 15
setblock ~55 ~4 ~81 stained_glass 15
setblock ~69 ~4 ~71 stained_glass 15
setblock ~70 ~4 ~70 concrete 15
setblock ~71 ~4 ~70 stained_glass 15
setblock ~21 ~5 ~73 obsidian
setblock ~22 ~5 ~74 stained_glass 15
setblock ~37 ~5 ~85 stained_glass 7
setblock ~53 ~5 ~83 obsidian
setblock ~54 ~5 ~82 wool 15
setblock ~70 ~5 ~70 stained_glass 15
fill ~71 ~5 ~69 ~71 ~6 ~69 concrete 15
setblock ~72 ~5 ~69 stained_glass 15
fill ~19 ~6 ~71 ~19 ~8 ~71 stained_glass 15
setblock ~21 ~6 ~73 concrete 15
setblock ~22 ~6 ~74 concrete 15
setblock ~36 ~6 ~84 stained_glass 15
setblock ~37 ~6 ~85 concrete 15
setblock ~38 ~6 ~86 stained_glass 15
fill ~52 ~6 ~83 ~52 ~7 ~83 stained_glass 15
setblock ~53 ~6 ~82 wool 15
setblock ~67 ~6 ~71 concrete 15
setblock ~68 ~6 ~70 concrete 15
fill ~69 ~6 ~70 ~69 ~7 ~70 stained_glass 15
setblock ~70 ~6 ~69 concrete 15
fill ~18 ~7 ~70 ~18 ~8 ~70 stained_glass 15
fill ~22 ~7 ~73 ~22 ~8 ~73 concrete 15
setblock ~23 ~7 ~74 stained_glass 15
setblock ~37 ~7 ~85 coal_block
setblock ~38 ~7 ~85 concrete 15
setblock ~39 ~7 ~86 stained_glass 15
fill ~53 ~7 ~82 ~53 ~8 ~82 stained_glass 15
setblock ~67 ~7 ~71 obsidian
setblock ~68 ~7 ~70 stained_glass 15
fill ~70 ~7 ~69 ~71 ~7 ~69 stained_glass 15
fill ~23 ~8 ~73 ~23 ~10 ~73 concrete 15
fill ~28 ~8 ~77 ~28 ~10 ~77 concrete 15
setblock ~38 ~8 ~85 stained_glass 15
fill ~39 ~8 ~86 ~41 ~8 ~86 concrete 15
setblock ~52 ~8 ~83 concrete 15
setblock ~65 ~8 ~72 concrete 15
setblock ~66 ~8 ~71 concrete 15
fill ~19 ~9 ~70 ~19 ~10 ~70 concrete 15
setblock ~22 ~9 ~72 stained_glass 15
setblock ~27 ~9 ~76 stained_glass 15
setblock ~39 ~9 ~85 stained_glass 15
fill ~40 ~9 ~86 ~41 ~9 ~86 wool 15
setblock ~42 ~9 ~86 stained_glass 15
setblock ~51 ~9 ~83 stained_glass 15
fill ~52 ~9 ~82 ~52 ~10 ~82 stained_glass 15
setblock ~61 ~9 ~75 stained_glass 15
setblock ~62 ~9 ~74 wool 15
setblock ~63 ~9 ~73 concrete 7
setblock ~64 ~9 ~72 wool 15
setblock ~65 ~9 ~71 obsidian
setblock ~66 ~9 ~71 stained_glass 15
setblock ~22 ~10 ~72 concrete 15
setblock ~24 ~10 ~73 stained_glass 15
setblock ~27 ~10 ~76 concrete 15
setblock ~30 ~10 ~78 stained_glass 15
fill ~38 ~10 ~85 ~38 ~11 ~85 concrete 15
setblock ~41 ~10 ~86 stained_glass 15
setblock ~42 ~10 ~86 obsidian
setblock ~49 ~10 ~84 stained_glass 15
setblock ~51 ~10 ~83 concrete 15
fill ~60 ~10 ~75 ~60 ~11 ~75 concrete 15
setblock ~61 ~10 ~74 obsidian
setblock ~62 ~10 ~74 blue_glazed_terracotta
setblock ~63 ~10 ~73 stained_glass 15
setblock ~64 ~10 ~72 stained_glass 15
setblock ~19 ~11 ~70 stained_glass 15
setblock ~20 ~11 ~70 obsidian
setblock ~21 ~11 ~71 obsidian
setblock ~22 ~11 ~72 obsidian
fill ~23 ~11 ~72 ~23 ~13 ~72 concrete 15
fill ~24 ~11 ~73 ~24 ~12 ~73 concrete 15
setblock ~26 ~11 ~75 stained_glass 15
setblock ~27 ~11 ~75 obsidian
setblock ~39 ~11 ~85 obsidian
setblock ~42 ~11 ~86 wool 15
fill ~49 ~11 ~84 ~49 ~12 ~84 concrete 15
setblock ~50 ~11 ~83 concrete 15
setblock ~51 ~11 ~83 obsidian
setblock ~59 ~11 ~75 obsidian
setblock ~61 ~11 ~74 cyan_glazed_terracotta
setblock ~62 ~11 ~73 stained_glass 15
setblock ~63 ~11 ~72 stained_glass 15
fill ~65 ~11 ~70 ~66 ~11 ~70 stained_glass 15
setblock ~67 ~11 ~69 obsidian
setblock ~68 ~11 ~69 concrete 15
setblock ~69 ~11 ~68 stained_glass 15
setblock ~20 ~12 ~70 concrete 15
fill ~21 ~12 ~71 ~22 ~12 ~71 concrete 15
setblock ~25 ~12 ~73 concrete 15
setblock ~26 ~12 ~74 wool 15
setblock ~27 ~12 ~75 concrete 15
fill ~32 ~12 ~79 ~32 ~13 ~79 concrete 15
fill ~33 ~12 ~80 ~33 ~14 ~80 concrete 15
fill ~38 ~12 ~84 ~38 ~13 ~84 stained_glass 15
fill ~39 ~12 ~85 ~39 ~13 ~85 stained_glass 15
setblock ~42 ~12 ~85 concrete 15
setblock ~45 ~12 ~85 concrete 15
setblock ~48 ~12 ~84 concrete 15
setblock ~50 ~12 ~83 stained_glass 15
setblock ~58 ~12 ~76 obsidian
setblock ~59 ~12 ~75 concrete 15
setblock ~60 ~12 ~74 obsidian
setblock ~61 ~12 ~74 stained_glass 15
setblock ~62 ~12 ~73 concrete 15
setblock ~63 ~12 ~72 stained_hardened_clay 11
setblock ~65 ~12 ~70 concrete 7
fill ~66 ~12 ~69 ~67 ~12 ~69 concrete 15
setblock ~68 ~12 ~68 obsidian
setblock ~69 ~12 ~68 concrete 15
fill ~70 ~12 ~67 ~70 ~13 ~67 concrete 15
setblock ~71 ~12 ~66 stained_glass 15
setblock ~20 ~13 ~70 stained_glass 15
setblock ~21 ~13 ~70 concrete 15
fill ~22 ~13 ~71 ~22 ~14 ~71 concrete 15
setblock ~24 ~13 ~72 wool 15
setblock ~25 ~13 ~73 wool 15
setblock ~26 ~13 ~74 nether_brick
setblock ~27 ~13 ~75 stained_glass 15
fill ~35 ~13 ~82 ~35 ~15 ~82 concrete 15
fill ~36 ~13 ~83 ~36 ~14 ~83 concrete 15
setblock ~37 ~13 ~83 stained_glass 15
fill ~42 ~13 ~85 ~42 ~16 ~85 stained_glass 15
setblock ~43 ~13 ~85 wool 15
fill ~44 ~13 ~85 ~44 ~19 ~85 concrete 15
setblock ~45 ~13 ~85 wool 15
fill ~46 ~13 ~85 ~46 ~15 ~85 concrete 15
setblock ~47 ~13 ~85 stained_glass 15
setblock ~48 ~13 ~84 wool 15
setblock ~57 ~13 ~76 stained_glass 15
setblock ~58 ~13 ~75 obsidian
setblock ~59 ~13 ~75 wool 15
setblock ~60 ~13 ~74 nether_brick
setblock ~61 ~13 ~73 concrete 7
setblock ~62 ~13 ~72 blue_glazed_terracotta
fill ~63 ~13 ~71 ~63 ~14 ~71 wool 15
setblock ~64 ~13 ~70 stained_glass 15
setblock ~65 ~13 ~70 concrete 15
fill ~66 ~13 ~69 ~66 ~14 ~69 stained_glass 15
setblock ~71 ~13 ~66 concrete 15
fill ~72 ~13 ~65 ~72 ~14 ~65 concrete 15
setblock ~73 ~13 ~65 stained_glass 15
fill ~23 ~14 ~71 ~23 ~16 ~71 concrete 15
setblock ~24 ~14 ~72 obsidian
fill ~25 ~14 ~73 ~26 ~14 ~73 concrete 15
fill ~27 ~14 ~74 ~27 ~16 ~74 concrete 15
setblock ~34 ~14 ~81 stained_glass 15
setblock ~37 ~14 ~83 concrete 15
setblock ~38 ~14 ~84 concrete 15
setblock ~39 ~14 ~85 concrete 15
setblock ~43 ~14 ~85 concrete 15
setblock ~45 ~14 ~85 concrete 15
fill ~47 ~14 ~84 ~47 ~19 ~84 concrete 15
setblock ~48 ~14 ~84 obsidian
setblock ~58 ~14 ~75 concrete 15
fill ~59 ~14 ~74 ~60 ~14 ~74 obsidian
setblock ~61 ~14 ~73 concrete 15
setblock ~62 ~14 ~72 obsidian
setblock ~64 ~14 ~70 blue_glazed_terracotta
setblock ~65 ~14 ~69 concrete 15
setblock ~71 ~14 ~65 concrete 15
setblock ~73 ~14 ~65 concrete 15
setblock ~24 ~15 ~72 wool 15
fill ~25 ~15 ~72 ~25 ~17 ~72 concrete 15
fill ~26 ~15 ~73 ~26 ~16 ~73 concrete 15
setblock ~34 ~15 ~81 concrete 15
setblock ~36 ~15 ~82 stained_glass 15
setblock ~37 ~15 ~83 coal_block
setblock ~38 ~15 ~84 wool 15
setblock ~39 ~15 ~85 wool 15
setblock ~43 ~15 ~85 obsidian
setblock ~45 ~15 ~85 obsidian
setblock ~48 ~15 ~84 wool 15
setblock ~58 ~15 ~75 stained_glass 15
fill ~59 ~15 ~74 ~59 ~16 ~74 concrete 15
fill ~60 ~15 ~73 ~60 ~16 ~73 concrete 15
fill ~61 ~15 ~72 ~61 ~16 ~72 concrete 15
setblock ~62 ~15 ~71 obsidian
fill ~63 ~15 ~70 ~63 ~16 ~70 stained_glass 15
fill ~64 ~15 ~69 ~64 ~17 ~69 concrete 15
setblock ~65 ~15 ~69 obsidian
setblock ~69 ~15 ~66 obsidian
setblock ~70 ~15 ~65 concrete 15
fill ~71 ~15 ~65 ~71 ~16 ~65 stained_glass 15
setblock ~21 ~16 ~69 stained_glass 15
fill ~24 ~16 ~71 ~24 ~17 ~71 concrete 15
setblock ~28 ~16 ~74 obsidian
setblock ~29 ~16 ~75 stained_glass 15
setblock ~34 ~16 ~80 stained_glass 15
setblock ~38 ~16 ~84 coal_block
fill ~39 ~16 ~84 ~39 ~17 ~84 concrete 15
setblock ~43 ~16 ~85 concrete 15
setblock ~45 ~16 ~85 concrete 15
setblock ~46 ~16 ~84 concrete 15
fill ~48 ~16 ~83 ~48 ~21 ~83 concrete 15
fill ~58 ~16 ~74 ~58 ~17 ~74 stained_glass 15
setblock ~62 ~16 ~71 concrete 15
setblock ~65 ~16 ~68 stained_glass 15
setblock ~68 ~16 ~66 stained_glass 15
setblock ~69 ~16 ~66 concrete 15
setblock ~70 ~16 ~65 wool 15
fill ~21 ~17 ~69 ~22 ~17 ~69 obsidian
fill ~23 ~17 ~70 ~23 ~18 ~70 concrete 15
setblock ~26 ~17 ~72 wool 15
setblock ~27 ~17 ~73 obsidian
setblock ~28 ~17 ~74 wool 15
setblock ~29 ~17 ~75 obsidian
setblock ~30 ~17 ~76 stained_glass 15
setblock ~38 ~17 ~84 wool 15
setblock ~43 ~17 ~85 obsidian
setblock ~45 ~17 ~85 obsidian
setblock ~46 ~17 ~84 wool 15
setblock ~49 ~17 ~82 stained_glass 15
setblock ~59 ~17 ~73 obsidian
setblock ~60 ~17 ~72 wool 15
setblock ~61 ~17 ~71 obsidian
setblock ~62 ~17 ~70 wool 15
setblock ~63 ~17 ~69 concrete 7
fill ~65 ~17 ~68 ~65 ~18 ~68 concrete 15
setblock ~66 ~17 ~68 wool 15
setblock ~67 ~17 ~67 stained_glass 15
fill ~69 ~17 ~65 ~70 ~17 ~65 obsidian
setblock ~71 ~17 ~64 stained_glass 15
setblock ~21 ~18 ~68 stained_glass 15
fill ~22 ~18 ~69 ~22 ~19 ~69 concrete 15
setblock ~24 ~18 ~70 concrete 15
setblock ~25 ~18 ~71 concrete 15
fill ~26 ~18 ~72 ~26 ~19 ~72 obsidian
setblock ~27 ~18 ~73 concrete 15
setblock ~28 ~18 ~74 obsidian
fill ~29 ~18 ~74 ~29 ~20 ~74 concrete 15
fill ~30 ~18 ~75 ~30 ~19 ~75 concrete 15
setblock ~31 ~18 ~76 stained_glass 15
setblock ~35 ~18 ~81 stained_glass 15
setblock ~38 ~18 ~84 concrete 15
setblock ~39 ~18 ~85 concrete 15
setblock ~43 ~18 ~85 concrete 15
setblock ~45 ~18 ~85 concrete 15
setblock ~46 ~18 ~84 concrete 15
fill ~49 ~18 ~82 ~49 ~22 ~82 concrete 15
setblock ~50 ~18 ~81 concrete 15
fill ~58 ~18 ~73 ~59 ~18 ~73 concrete 15
setblock ~60 ~18 ~72 obsidian
setblock ~61 ~18 ~71 concrete 15
setblock ~62 ~18 ~70 stained_glass 15
setblock ~63 ~18 ~69 concrete 15
setblock ~64 ~18 ~68 concrete 15
setblock ~66 ~18 ~67 concrete 15
fill ~67 ~18 ~66 ~67 ~19 ~66 concrete 15
setblock ~69 ~18 ~65 concrete 15
fill ~70 ~18 ~64 ~70 ~19 ~64 wool 15
setblock ~71 ~18 ~64 concrete 15
setblock ~18 ~19 ~66 stained_glass 15
setblock ~23 ~19 ~69 obsidian
setblock ~24 ~19 ~70 wool 15
setblock ~25 ~19 ~71 obsidian
fill ~27 ~19 ~72 ~27 ~21 ~72 concrete 15
fill ~28 ~19 ~73 ~28 ~21 ~73 concrete 15
setblock ~31 ~19 ~76 concrete 15
setblock ~32 ~19 ~77 obsidian
fill ~33 ~19 ~78 ~33 ~21 ~78 concrete 15
setblock ~34 ~19 ~79 obsidian
setblock ~34 ~19 ~80 wool 15
setblock ~35 ~19 ~81 wool 15
setblock ~36 ~19 ~82 wool 15
fill ~37 ~19 ~83 ~37 ~20 ~83 stained_glass 15
fill ~38 ~19 ~84 ~38 ~20 ~84 stained_glass 15
setblock ~39 ~19 ~85 obsidian
setblock ~40 ~19 ~85 stained_glass 15
setblock ~42 ~19 ~85 stained_glass 15
setblock ~43 ~19 ~85 coal_block
setblock ~45 ~19 ~85 obsidian
setblock ~46 ~19 ~84 wool 15
setblock ~50 ~19 ~81 stained_glass 15
fill ~58 ~19 ~73 ~58 ~18 ~73 concrete 15
fill ~59 ~19 ~72 ~59 ~20 ~72 concrete 15
fill ~60 ~19 ~71 ~60 ~20 ~71 concrete 15
fill ~61 ~19 ~70 ~61 ~20 ~70 stained_glass 15
setblock ~62 ~19 ~69 stained_glass 15
fill ~63 ~19 ~68 ~63 ~21 ~68 concrete 15
setblock ~64 ~19 ~68 obsidian
setblock ~65 ~19 ~67 obsidian
setblock ~66 ~19 ~66 wool 15
fill ~69 ~19 ~64 ~69 ~20 ~64 concrete 15
setblock ~73 ~19 ~61 stained_glass 15
setblock ~18 ~20 ~66 obsidian
fill ~19 ~20 ~66 ~19 ~22 ~66 concrete 15
setblock ~22 ~20 ~68 stained_glass 15
setblock ~23 ~20 ~69 concrete 15
setblock ~24 ~20 ~70 obsidian
fill ~25 ~20 ~71 ~26 ~20 ~71 concrete 15
setblock ~30 ~20 ~74 concrete 15
setblock ~31 ~20 ~75 concrete 15
fill ~32 ~20 ~76 ~32 ~21 ~76 wool 15
setblock ~32 ~20 ~77 concrete 15
setblock ~34 ~20 ~79 concrete 15
setblock ~34 ~20 ~80 obsidian
fill ~35 ~20 ~81 ~35 ~20 ~82 concrete 15
setblock ~36 ~20 ~83 concrete 15
fill ~39 ~20 ~85 ~42 ~20 ~85 concrete 15
fill ~43 ~20 ~85 ~44 ~20 ~85 stained_glass 15
setblock ~45 ~20 ~85 concrete 15
setblock ~46 ~20 ~84 concrete 15
setblock ~47 ~20 ~83 concrete 15
setblock ~51 ~20 ~80 stained_glass 15
fill ~52 ~20 ~79 ~52 ~21 ~79 concrete 15
setblock ~57 ~20 ~73 concrete 15
setblock ~58 ~20 ~72 concrete 15
setblock ~62 ~20 ~69 concrete 15
fill ~64 ~20 ~67 ~65 ~20 ~67 concrete 15
setblock ~66 ~20 ~66 obsidian
setblock ~68 ~20 ~64 obsidian
setblock ~70 ~20 ~63 stained_glass 15
setblock ~18 ~21 ~65 concrete 15
setblock ~20 ~21 ~67 stained_glass 15
setblock ~23 ~21 ~69 obsidian
fill ~24 ~21 ~69 ~24 ~23 ~69 concrete 15
fill ~25 ~21 ~70 ~25 ~23 ~70 concrete 15
fill ~26 ~21 ~71 ~26 ~24 ~71 concrete 15
setblock ~29 ~21 ~73 obsidian
setblock ~30 ~21 ~74 wool 15
setblock ~31 ~21 ~75 wool 15
setblock ~32 ~21 ~77 obsidian
setblock ~34 ~21 ~79 obsidian
fill ~34 ~21 ~80 ~34 ~23 ~80 wool 15
setblock ~35 ~21 ~81 wool 15
setblock ~35 ~21 ~82 concrete 15
fill ~36 ~21 ~83 ~36 ~22 ~83 wool 15
fill ~37 ~21 ~84 ~37 ~22 ~84 stained_glass 15
setblock ~37 ~21 ~115 obsidian
setblock ~38 ~21 ~84 wool 15
fill ~38 ~21 ~113 ~40 ~21 ~113 concrete 15
setblock ~38 ~21 ~114 obsidian
setblock ~38 ~21 ~115 concrete 15
fill ~39 ~21 ~85 ~40 ~21 ~85 concrete 15
setblock ~39 ~21 ~111 obsidian
setblock ~39 ~21 ~112 concrete 15
setblock ~39 ~21 ~114 concrete 15
setblock ~39 ~21 ~115 obsidian
setblock ~39 ~21 ~116 concrete 15
setblock ~40 ~21 ~110 obsidian
setblock ~40 ~21 ~111 concrete 15
setblock ~40 ~21 ~112 obsidian
setblock ~40 ~21 ~114 wool 15
setblock ~40 ~21 ~115 concrete 15
setblock ~41 ~21 ~85 obsidian
setblock ~41 ~21 ~110 concrete 15
setblock ~41 ~21 ~111 coal_block
setblock ~41 ~21 ~112 concrete 15
setblock ~41 ~21 ~113 obsidian
setblock ~41 ~21 ~114 concrete 15
setblock ~41 ~21 ~115 obsidian
fill ~42 ~21 ~85 ~42 ~22 ~85 concrete 15
setblock ~42 ~21 ~110 obsidian
setblock ~42 ~21 ~111 concrete 15
setblock ~42 ~21 ~112 obsidian
setblock ~42 ~21 ~113 concrete 15
setblock ~42 ~21 ~114 obsidian
setblock ~42 ~21 ~115 concrete 15
fill ~43 ~21 ~85 ~44 ~21 ~85 stained_glass 15
setblock ~43 ~21 ~110 concrete 15
setblock ~43 ~21 ~111 obsidian
setblock ~43 ~21 ~112 concrete 15
setblock ~43 ~21 ~113 coal_block
setblock ~43 ~21 ~114 concrete 15
setblock ~43 ~21 ~115 obsidian
setblock ~44 ~21 ~110 obsidian
setblock ~44 ~21 ~111 concrete 15
setblock ~44 ~21 ~112 wool 15
setblock ~44 ~21 ~113 concrete 15
setblock ~44 ~21 ~114 obsidian
setblock ~44 ~21 ~115 concrete 15
setblock ~45 ~21 ~84 stained_glass 15
setblock ~45 ~21 ~110 concrete 15
setblock ~45 ~21 ~111 coal_block
setblock ~45 ~21 ~112 concrete 15
setblock ~45 ~21 ~113 obsidian
setblock ~45 ~21 ~114 concrete 15
setblock ~45 ~21 ~115 coal_block
fill ~46 ~21 ~84 ~46 ~22 ~84 wool 15
setblock ~46 ~21 ~110 obsidian
setblock ~46 ~21 ~111 concrete 15
setblock ~46 ~21 ~112 obsidian
setblock ~46 ~21 ~113 concrete 15
setblock ~46 ~21 ~114 wool 15
setblock ~46 ~21 ~115 concrete 15
setblock ~46 ~21 ~116 obsidian
setblock ~47 ~21 ~83 obsidian
setblock ~47 ~21 ~111 obsidian
setblock ~47 ~21 ~112 concrete 15
setblock ~47 ~21 ~113 coal_block
setblock ~47 ~21 ~114 concrete 15
setblock ~47 ~21 ~115 coal_block
setblock ~47 ~21 ~116 concrete 15
setblock ~48 ~21 ~113 concrete 15
setblock ~48 ~21 ~114 obsidian
setblock ~48 ~21 ~115 concrete 15
setblock ~49 ~21 ~115 coal_block
fill ~50 ~21 ~81 ~50 ~23 ~81 concrete 15
fill ~51 ~21 ~80 ~51 ~22 ~80 concrete 15
setblock ~52 ~21 ~78 obsidian
fill ~56 ~21 ~74 ~56 ~22 ~74 stained_glass 15
setblock ~57 ~21 ~73 obsidian
setblock ~58 ~21 ~72 obsidian
setblock ~59 ~21 ~71 obsidian
setblock ~60 ~21 ~70 stained_glass 15
setblock ~61 ~21 ~69 obsidian
setblock ~64 ~21 ~67 obsidian
setblock ~65 ~21 ~66 concrete 15
setblock ~67 ~21 ~64 stained_glass 15
setblock ~68 ~21 ~64 wool 15
setblock ~69 ~21 ~63 obsidian
setblock ~4 ~22 ~27 stained_glass 15
setblock ~18 ~22 ~65 stained_glass 15
setblock ~20 ~22 ~66 concrete 7
setblock ~21 ~22 ~67 stained_glass 15
setblock ~23 ~22 ~68 concrete 15
setblock ~27 ~22 ~71 concrete 15
setblock ~28 ~22 ~72 obsidian
setblock ~29 ~22 ~73 concrete 15
setblock ~30 ~22 ~74 obsidian
setblock ~31 ~22 ~75 concrete 15
setblock ~32 ~22 ~76 obsidian
setblock ~32 ~22 ~77 concrete 15
setblock ~33 ~22 ~78 obsidian
setblock ~34 ~22 ~79 concrete 15
fill ~34 ~22 ~114 ~35 ~22 ~114 concrete 15
fill ~34 ~22 ~115 ~36 ~22 ~115 concrete 15
setblock ~35 ~22 ~81 concrete 15
setblock ~35 ~22 ~82 obsidian
fill ~35 ~22 ~111 ~38 ~22 ~111 concrete 15
fill ~35 ~22 ~112 ~38 ~22 ~112 concrete 15
fill ~35 ~22 ~113 ~37 ~22 ~113 concrete 15
fill ~35 ~22 ~116 ~37 ~22 ~116 concrete 15
fill ~35 ~22 ~117 ~50 ~22 ~117 concrete 15
fill ~36 ~22 ~109 ~49 ~22 ~109 concrete 15
setblock ~36 ~22 ~110 coal_block
setblock ~36 ~22 ~114 coal_block
fill ~37 ~22 ~107 ~49 ~22 ~107 concrete 15
fill ~37 ~22 ~108 ~43 ~22 ~108 concrete 15
fill ~37 ~22 ~110 ~39 ~22 ~110 concrete 15
setblock ~37 ~22 ~114 concrete 15
setblock ~37 ~22 ~118 concrete 15
fill ~38 ~22 ~85 ~44 ~22 ~85 concrete 15
fill ~38 ~22 ~104 ~45 ~22 ~104 concrete 15
fill ~38 ~22 ~105 ~48 ~22 ~105 concrete 15
fill ~38 ~22 ~106 ~48 ~22 ~106 concrete 15
setblock ~38 ~22 ~116 obsidian
setblock ~38 ~22 ~118 coal_block
fill ~39 ~22 ~86 ~42 ~22 ~86 concrete 15
fill ~39 ~22 ~87 ~43 ~22 ~87 concrete 15
fill ~39 ~22 ~88 ~43 ~22 ~88 concrete 15
fill ~39 ~22 ~89 ~43 ~22 ~89 concrete 15
fill ~39 ~22 ~90 ~43 ~22 ~90 concrete 15
fill ~39 ~22 ~91 ~43 ~22 ~91 concrete 15
fill ~39 ~22 ~92 ~43 ~22 ~92 concrete 15
fill ~39 ~22 ~93 ~43 ~22 ~93 concrete 15
fill ~39 ~22 ~94 ~43 ~22 ~94 concrete 15
fill ~39 ~22 ~95 ~43 ~22 ~95 concrete 15
fill ~39 ~22 ~102 ~45 ~22 ~102 concrete 15
fill ~39 ~22 ~103 ~47 ~22 ~103 concrete 15
fill ~39 ~22 ~118 ~39 ~22 ~119 concrete 15
fill ~40 ~22 ~96 ~43 ~22 ~96 concrete 15
fill ~40 ~22 ~97 ~43 ~22 ~97 concrete 15
fill ~40 ~22 ~98 ~43 ~22 ~98 concrete 15
fill ~40 ~22 ~99 ~44 ~22 ~99 concrete 15
fill ~40 ~22 ~116 ~45 ~22 ~116 concrete 15
setblock ~40 ~22 ~118 obsidian
fill ~41 ~22 ~100 ~43 ~22 ~100 concrete 15
fill ~41 ~22 ~101 ~45 ~22 ~101 concrete 15
fill ~41 ~22 ~118 ~45 ~22 ~118 concrete 15
setblock ~44 ~22 ~100 coal_block
setblock ~44 ~22 ~108 coal_block
fill ~45 ~22 ~108 ~49 ~22 ~108 concrete 15
setblock ~46 ~22 ~102 coal_block
setblock ~46 ~22 ~104 coal_block
setblock ~46 ~22 ~118 coal_block
fill ~47 ~22 ~83 ~47 ~24 ~83 concrete 15
setblock ~47 ~22 ~104 concrete 15
fill ~47 ~22 ~110 ~50 ~22 ~110 concrete 15
fill ~47 ~22 ~118 ~49 ~22 ~118 concrete 15
fill ~47 ~22 ~119 ~47 ~22 ~117 concrete 15
setblock ~48 ~22 ~82 concrete 15
fill ~48 ~22 ~111 ~51 ~22 ~111 concrete 15
fill ~48 ~22 ~112 ~51 ~22 ~112 concrete 15
fill ~48 ~22 ~116 ~51 ~22 ~116 concrete 15
fill ~49 ~22 ~113 ~51 ~22 ~113 concrete 15
fill ~49 ~22 ~114 ~51 ~22 ~114 concrete 15
fill ~50 ~22 ~115 ~51 ~22 ~115 concrete 15
setblock ~51 ~22 ~79 concrete 15
setblock ~52 ~22 ~78 concrete 15
fill ~57 ~22 ~72 ~57 ~25 ~72 concrete 15
fill ~57 ~22 ~73 ~57 ~22 ~72 concrete 15
fill ~58 ~22 ~71 ~59 ~22 ~71 concrete 15
setblock ~60 ~22 ~70 concrete 15
setblock ~61 ~22 ~69 concrete 15
setblock ~62 ~22 ~68 obsidian
setblock ~63 ~22 ~67 concrete 7
setblock ~64 ~22 ~66 obsidian
setblock ~65 ~22 ~65 wool 15
setblock ~66 ~22 ~65 stained_glass 15
setblock ~67 ~22 ~64 blue_glazed_terracotta
setblock ~68 ~22 ~63 concrete 15
setblock ~69 ~22 ~62 concrete 15
setblock ~19 ~23 ~66 stained_glass 15
setblock ~20 ~23 ~66 wool 15
setblock ~21 ~23 ~67 wool 15
fill ~22 ~23 ~68 ~23 ~23 ~68 stained_glass 15
fill ~27 ~23 ~72 ~27 ~27 ~72 concrete 15
setblock ~28 ~23 ~72 wool 15
setblock ~29 ~23 ~73 wool 15
fill ~30 ~23 ~74 ~30 ~25 ~74 wool 15
setblock ~31 ~23 ~75 wool 15
fill ~32 ~23 ~76 ~32 ~25 ~76 wool 15
setblock ~32 ~23 ~77 obsidian
setblock ~33 ~23 ~78 concrete 15
setblock ~33 ~23 ~111 coal_block
setblock ~33 ~23 ~112 concrete 15
setblock ~33 ~23 ~113 obsidian
setblock ~33 ~23 ~114 concrete 15
setblock ~33 ~23 ~115 obsidian
setblock ~34 ~23 ~79 obsidian
setblock ~34 ~23 ~107 concrete 15
setblock ~34 ~23 ~108 obsidian
setblock ~34 ~23 ~109 concrete 15
setblock ~34 ~23 ~110 obsidian
setblock ~34 ~23 ~111 concrete 15
setblock ~34 ~23 ~112 obsidian
setblock ~34 ~23 ~113 concrete 15
setblock ~34 ~23 ~116 wool 15
setblock ~34 ~23 ~117 obsidian
setblock ~35 ~23 ~81 wool 15
fill ~35 ~23 ~82 ~35 ~24 ~82 concrete 15
setblock ~35 ~23 ~104 concrete 15
setblock ~35 ~23 ~105 coal_block
setblock ~35 ~23 ~106 concrete 15
setblock ~35 ~23 ~107 coal_block
setblock ~35 ~23 ~108 concrete 15
setblock ~35 ~23 ~109 coal_block
setblock ~35 ~23 ~110 concrete 15
setblock ~35 ~23 ~118 concrete 15
setblock ~35 ~23 ~119 wool 15
setblock ~36 ~23 ~83 obsidian
setblock ~36 ~23 ~95 concrete 15
setblock ~36 ~23 ~96 obsidian
setblock ~36 ~23 ~97 concrete 15
setblock ~36 ~23 ~98 wool 15
setblock ~36 ~23 ~101 concrete 15
setblock ~36 ~23 ~102 obsidian
setblock ~36 ~23 ~103 concrete 15
setblock ~36 ~23 ~104 obsidian
setblock ~36 ~23 ~105 concrete 15
setblock ~36 ~23 ~106 obsidian
setblock ~36 ~23 ~107 concrete 15
setblock ~36 ~23 ~108 obsidian
setblock ~36 ~23 ~118 wool 15
setblock ~36 ~23 ~119 obsidian
setblock ~36 ~23 ~120 wool 15
setblock ~37 ~23 ~88 concrete 15
setblock ~37 ~23 ~89 obsidian
setblock ~37 ~23 ~90 concrete 15
setblock ~37 ~23 ~91 coal_block
setblock ~37 ~23 ~92 concrete 15
setblock ~37 ~23 ~93 obsidian
setblock ~37 ~23 ~94 concrete 15
setblock ~37 ~23 ~95 coal_block
setblock ~37 ~23 ~96 concrete 15
setblock ~37 ~23 ~97 obsidian
setblock ~37 ~23 ~98 concrete 15
setblock ~37 ~23 ~99 coal_block
setblock ~37 ~23 ~100 concrete 15
setblock ~37 ~23 ~101 coal_block
setblock ~37 ~23 ~102 concrete 15
setblock ~37 ~23 ~103 coal_block
setblock ~37 ~23 ~104 concrete 15
setblock ~37 ~23 ~105 coal_block
setblock ~37 ~23 ~106 concrete 15
setblock ~37 ~23 ~119 wool 15
setblock ~37 ~23 ~120 concrete 15
fill ~38 ~23 ~85 ~38 ~22 ~85 concrete 15
setblock ~38 ~23 ~86 obsidian
setblock ~38 ~23 ~87 concrete 15
setblock ~38 ~23 ~88 obsidian
setblock ~38 ~23 ~89 concrete 15
setblock ~38 ~23 ~90 obsidian
setblock ~38 ~23 ~91 concrete 15
setblock ~38 ~23 ~92 obsidian
setblock ~38 ~23 ~93 concrete 15
setblock ~38 ~23 ~94 obsidian
setblock ~38 ~23 ~95 concrete 15
setblock ~38 ~23 ~96 obsidian
setblock ~38 ~23 ~97 concrete 15
setblock ~38 ~23 ~98 obsidian
setblock ~38 ~23 ~99 concrete 15
setblock ~38 ~23 ~100 obsidian
setblock ~38 ~23 ~101 concrete 15
setblock ~38 ~23 ~102 obsidian
setblock ~38 ~23 ~103 concrete 15
setblock ~38 ~23 ~119 concrete 15
setblock ~38 ~23 ~120 wool 15
setblock ~39 ~23 ~96 concrete 15
setblock ~39 ~23 ~97 coal_block
setblock ~39 ~23 ~98 concrete 15
setblock ~39 ~23 ~99 coal_block
setblock ~39 ~23 ~100 concrete 15
setblock ~39 ~23 ~101 coal_block
setblock ~39 ~23 ~120 concrete 15
setblock ~40 ~23 ~100 obsidian
setblock ~40 ~23 ~101 concrete 15
setblock ~40 ~23 ~119 concrete 15
setblock ~40 ~23 ~120 wool 15
setblock ~41 ~23 ~119 obsidian
setblock ~41 ~23 ~120 concrete 15
setblock ~42 ~23 ~119 concrete 15
setblock ~42 ~23 ~120 wool 15
setblock ~43 ~23 ~86 concrete 15
setblock ~43 ~23 ~119 obsidian
fill ~43 ~23 ~120 ~43 ~24 ~120 concrete 15
setblock ~44 ~23 ~85 concrete 15
setblock ~44 ~23 ~86 coal_block
setblock ~44 ~23 ~87 concrete 15
setblock ~44 ~23 ~88 coal_block
setblock ~44 ~23 ~89 concrete 15
setblock ~44 ~23 ~90 obsidian
setblock ~44 ~23 ~91 concrete 15
setblock ~44 ~23 ~92 coal_block
setblock ~44 ~23 ~93 concrete 15
setblock ~44 ~23 ~94 obsidian
setblock ~44 ~23 ~95 concrete 15
setblock ~44 ~23 ~96 obsidian
setblock ~44 ~23 ~97 concrete 15
setblock ~44 ~23 ~98 obsidian
setblock ~44 ~23 ~119 concrete 15
setblock ~44 ~23 ~120 wool 15
setblock ~45 ~23 ~85 coal_block
setblock ~45 ~23 ~86 concrete 15
setblock ~45 ~23 ~87 coal_block
setblock ~45 ~23 ~88 concrete 15
setblock ~45 ~23 ~89 coal_block
setblock ~45 ~23 ~90 concrete 15
setblock ~45 ~23 ~91 coal_block
setblock ~45 ~23 ~92 concrete 15
setblock ~45 ~23 ~93 coal_block
setblock ~45 ~23 ~94 concrete 15
setblock ~45 ~23 ~95 coal_block
setblock ~45 ~23 ~96 concrete 15
setblock ~45 ~23 ~97 coal_block
setblock ~45 ~23 ~98 concrete 15
setblock ~45 ~23 ~99 coal_block
setblock ~45 ~23 ~100 concrete 15
setblock ~45 ~23 ~119 obsidian
setblock ~45 ~23 ~120 concrete 15
setblock ~46 ~23 ~84 stained_hardened_clay 7
setblock ~46 ~23 ~88 obsidian
setblock ~46 ~23 ~89 concrete 15
setblock ~46 ~23 ~90 obsidian
setblock ~46 ~23 ~91 concrete 15
setblock ~46 ~23 ~92 obsidian
setblock ~46 ~23 ~93 concrete 15
setblock ~46 ~23 ~94 obsidian
setblock ~46 ~23 ~95 concrete 15
setblock ~46 ~23 ~96 obsidian
setblock ~46 ~23 ~97 concrete 15
setblock ~46 ~23 ~98 wool 15
setblock ~46 ~23 ~99 concrete 15
setblock ~46 ~23 ~100 obsidian
setblock ~46 ~23 ~101 concrete 15
setblock ~46 ~23 ~119 concrete 15
setblock ~46 ~23 ~120 wool 15
setblock ~47 ~23 ~90 concrete 15
setblock ~47 ~23 ~91 coal_block
setblock ~47 ~23 ~92 concrete 15
setblock ~47 ~23 ~93 coal_block
setblock ~47 ~23 ~94 concrete 15
setblock ~47 ~23 ~95 coal_block
setblock ~47 ~23 ~96 concrete 15
setblock ~47 ~23 ~97 coal_block
setblock ~47 ~23 ~98 concrete 15
setblock ~47 ~23 ~99 coal_block
setblock ~47 ~23 ~100 concrete 15
setblock ~47 ~23 ~101 coal_block
setblock ~47 ~23 ~102 concrete 15
setblock ~47 ~23 ~120 concrete 15
setblock ~48 ~23 ~82 wool 15
setblock ~48 ~23 ~94 obsidian
setblock ~48 ~23 ~95 concrete 15
setblock ~48 ~23 ~96 obsidian
setblock ~48 ~23 ~97 concrete 15
setblock ~48 ~23 ~98 obsidian
setblock ~48 ~23 ~99 concrete 15
setblock ~48 ~23 ~100 obsidian
setblock ~48 ~23 ~101 concrete 15
setblock ~48 ~23 ~102 obsidian
setblock ~48 ~23 ~103 concrete 15
setblock ~48 ~23 ~104 obsidian
setblock ~48 ~23 ~119 concrete 15
setblock ~48 ~23 ~120 wool 15
setblock ~49 ~23 ~81 obsidian
setblock ~49 ~23 ~98 concrete 15
setblock ~49 ~23 ~99 coal_block
setblock ~49 ~23 ~100 concrete 15
setblock ~49 ~23 ~101 obsidian
setblock ~49 ~23 ~102 concrete 15
setblock ~49 ~23 ~103 coal_block
setblock ~49 ~23 ~104 concrete 15
setblock ~49 ~23 ~105 coal_block
setblock ~49 ~23 ~106 concrete 15
setblock ~49 ~23 ~119 coal_block
setblock ~49 ~23 ~120 concrete 15
setblock ~50 ~23 ~80 wool 15
setblock ~50 ~23 ~102 wool 15
setblock ~50 ~23 ~103 concrete 15
setblock ~50 ~23 ~104 obsidian
setblock ~50 ~23 ~105 concrete 15
setblock ~50 ~23 ~106 obsidian
setblock ~50 ~23 ~107 concrete 15
setblock ~50 ~23 ~108 obsidian
setblock ~50 ~23 ~109 concrete 15
setblock ~50 ~23 ~118 wool 15
setblock ~50 ~23 ~119 concrete 15
setblock ~50 ~23 ~120 obsidian
setblock ~51 ~23 ~79 obsidian
setblock ~51 ~23 ~104 concrete 15
setblock ~51 ~23 ~105 coal_block
setblock ~51 ~23 ~106 concrete 15
setblock ~51 ~23 ~107 coal_block
setblock ~51 ~23 ~108 concrete 15
setblock ~51 ~23 ~109 coal_block
setblock ~51 ~23 ~110 concrete 15
setblock ~51 ~23 ~117 obsidian
setblock ~51 ~23 ~118 concrete 15
setblock ~51 ~23 ~119 coal_block
setblock ~52 ~23 ~78 wool 15
setblock ~52 ~23 ~107 concrete 15
setblock ~52 ~23 ~108 obsidian
setblock ~52 ~23 ~109 concrete 15
setblock ~52 ~23 ~110 wool 15
setblock ~52 ~23 ~111 concrete 15
setblock ~52 ~23 ~112 obsidian
setblock ~52 ~23 ~113 concrete 15
setblock ~52 ~23 ~114 wool 15
setblock ~52 ~23 ~115 concrete 15
setblock ~52 ~23 ~116 obsidian
setblock ~52 ~23 ~117 concrete 15
setblock ~53 ~23 ~77 obsidian
setblock ~53 ~23 ~111 obsidian
setblock ~53 ~23 ~112 concrete 15
setblock ~53 ~23 ~113 obsidian
setblock ~53 ~23 ~114 concrete 15
setblock ~53 ~23 ~115 coal_block
setblock ~56 ~23 ~73 concrete 15
fill ~58 ~23 ~71 ~58 ~24 ~71 concrete 15
fill ~59 ~23 ~70 ~59 ~27 ~70 concrete 15
fill ~60 ~23 ~69 ~60 ~24 ~69 concrete 15
fill ~61 ~23 ~68 ~61 ~25 ~68 concrete 15
setblock ~63 ~23 ~67 cyan_glazed_terracotta
setblock ~64 ~23 ~66 wool 15
setblock ~65 ~23 ~65 cyan_glazed_terracotta
setblock ~66 ~23 ~64 cyan_glazed_terracotta
setblock ~67 ~23 ~63 wool 15
fill ~68 ~23 ~62 ~68 ~24 ~62 lapis_ore
setblock ~69 ~23 ~61 wool 15
setblock ~20 ~24 ~66 obsidian
fill ~21 ~24 ~67 ~22 ~24 ~67 concrete 15
fill ~24 ~24 ~69 ~24 ~25 ~69 stained_glass 15
setblock ~25 ~24 ~70 wool 15
setblock ~28 ~24 ~72 obsidian
setblock ~29 ~24 ~73 concrete 15
setblock ~31 ~24 ~75 concrete 15
fill ~32 ~24 ~77 ~32 ~25 ~77 concrete 15
fill ~32 ~24 ~108 ~33 ~24 ~108 concrete 15
fill ~32 ~24 ~109 ~33 ~24 ~109 concrete 15
setblock ~32 ~24 ~110 coal_block
fill ~32 ~24 ~111 ~32 ~24 ~115 concrete 15
setblock ~33 ~24 ~78 obsidian
setblock ~33 ~24 ~79 concrete 15
fill ~33 ~24 ~103 ~35 ~24 ~103 concrete 15
fill ~33 ~24 ~104 ~34 ~24 ~104 concrete 15
fill ~33 ~24 ~105 ~34 ~24 ~105 concrete 15
fill ~33 ~24 ~106 ~34 ~24 ~106 concrete 15
fill ~33 ~24 ~107 ~33 ~24 ~103 concrete 15
setblock ~33 ~24 ~110 concrete 15
fill ~33 ~24 ~116 ~33 ~24 ~117 concrete 15
setblock ~34 ~24 ~80 obsidian
fill ~34 ~24 ~81 ~34 ~25 ~81 concrete 15
fill ~34 ~24 ~98 ~35 ~24 ~98 concrete 15
fill ~34 ~24 ~99 ~36 ~24 ~99 concrete 15
fill ~34 ~24 ~100 ~36 ~24 ~100 concrete 15
fill ~34 ~24 ~101 ~35 ~24 ~101 concrete 15
fill ~34 ~24 ~102 ~35 ~24 ~102 concrete 15
setblock ~34 ~24 ~118 wool 15
setblock ~34 ~24 ~119 concrete 15
fill ~35 ~24 ~91 ~36 ~24 ~91 concrete 15
fill ~35 ~24 ~92 ~36 ~24 ~92 concrete 15
fill ~35 ~24 ~93 ~36 ~24 ~93 concrete 15
fill ~35 ~24 ~94 ~36 ~24 ~94 concrete 15
fill ~35 ~24 ~95 ~35 ~24 ~103 concrete 15
fill ~35 ~24 ~120 ~35 ~25 ~120 concrete 15
setblock ~36 ~24 ~83 concrete 15
setblock ~36 ~24 ~84 obsidian
fill ~36 ~24 ~85 ~37 ~24 ~85 concrete 15
fill ~36 ~24 ~86 ~37 ~24 ~86 concrete 15
fill ~36 ~24 ~87 ~37 ~24 ~87 concrete 15
fill ~36 ~24 ~88 ~36 ~24 ~94 concrete 15
fill ~36 ~24 ~121 ~41 ~24 ~121 concrete 15
setblock ~37 ~24 ~84 concrete 15
setblock ~42 ~24 ~120 obsidian
fill ~44 ~24 ~121 ~50 ~24 ~121 concrete 15
fill ~46 ~24 ~85 ~47 ~24 ~85 concrete 15
fill ~46 ~24 ~86 ~47 ~24 ~86 concrete 15
fill ~46 ~24 ~87 ~48 ~24 ~87 concrete 15
setblock ~47 ~24 ~84 concrete 15
fill ~47 ~24 ~88 ~48 ~24 ~88 concrete 15
fill ~47 ~24 ~89 ~48 ~24 ~89 concrete 15
setblock ~48 ~24 ~82 concrete 15
fill ~48 ~24 ~90 ~49 ~24 ~90 concrete 15
fill ~48 ~24 ~91 ~49 ~24 ~91 concrete 15
fill ~48 ~24 ~92 ~49 ~24 ~92 concrete 15
fill ~48 ~24 ~93 ~50 ~24 ~93 concrete 15
setblock ~49 ~24 ~81 concrete 15
fill ~49 ~24 ~94 ~50 ~24 ~94 concrete 15
fill ~49 ~24 ~95 ~50 ~24 ~95 concrete 15
fill ~49 ~24 ~96 ~50 ~24 ~96 concrete 15
fill ~49 ~24 ~97 ~51 ~24 ~97 concrete 15
setblock ~50 ~24 ~80 concrete 15
fill ~50 ~24 ~98 ~51 ~24 ~98 concrete 15
fill ~50 ~24 ~99 ~51 ~24 ~99 concrete 15
fill ~50 ~24 ~100 ~52 ~24 ~100 concrete 15
fill ~50 ~24 ~101 ~52 ~24 ~101 concrete 15
setblock ~51 ~24 ~79 concrete 15
fill ~51 ~24 ~102 ~52 ~24 ~102 concrete 15
fill ~51 ~24 ~103 ~53 ~24 ~103 concrete 15
fill ~51 ~24 ~120 ~51 ~26 ~120 concrete 15
setblock ~52 ~24 ~78 obsidian
fill ~52 ~24 ~104 ~53 ~24 ~104 concrete 15
fill ~52 ~24 ~105 ~53 ~24 ~105 concrete 15
fill ~52 ~24 ~106 ~53 ~24 ~106 concrete 15
fill ~52 ~24 ~118 ~52 ~24 ~119 concrete 15
setblock ~53 ~24 ~77 stained_glass 15
fill ~53 ~24 ~107 ~53 ~24 ~110 concrete 15
fill ~53 ~24 ~115 ~53 ~24 ~117 concrete 15
fill ~54 ~24 ~108 ~54 ~24 ~109 concrete 15
setblock ~54 ~24 ~110 coal_block
fill ~54 ~24 ~111 ~54 ~24 ~114 concrete 15
setblock ~56 ~24 ~73 concrete 7
setblock ~62 ~24 ~68 concrete 15
fill ~63 ~24 ~67 ~63 ~25 ~67 obsidian
fill ~64 ~24 ~66 ~64 ~25 ~66 obsidian
setblock ~65 ~24 ~65 concrete 15
setblock ~66 ~24 ~64 lapis_ore
setblock ~67 ~24 ~63 concrete 15
setblock ~69 ~24 ~61 obsidian
setblock ~20 ~25 ~66 wool 15
setblock ~21 ~25 ~67 wool 15
setblock ~22 ~25 ~67 concrete 7
fill ~23 ~25 ~68 ~23 ~28 ~68 concrete 15
fill ~25 ~25 ~70 ~25 ~27 ~70 concrete 15
setblock ~26 ~25 ~71 obsidian
setblock ~28 ~25 ~72 wool 15
setblock ~29 ~25 ~73 wool 15
setblock ~31 ~25 ~75 wool 15
setblock ~31 ~25 ~105 obsidian
setblock ~31 ~25 ~106 concrete 15
setblock ~31 ~25 ~107 obsidian
setblock ~31 ~25 ~108 concrete 15
setblock ~31 ~25 ~109 obsidian
setblock ~31 ~25 ~110 concrete 15
setblock ~31 ~25 ~111 wool 15
setblock ~31 ~25 ~112 concrete 15
setblock ~31 ~25 ~113 wool 15
setblock ~32 ~25 ~78 wool 15
setblock ~32 ~25 ~101 concrete 15
setblock ~32 ~25 ~102 wool 15
setblock ~32 ~25 ~103 concrete 15
setblock ~32 ~25 ~104 obsidian
setblock ~32 ~25 ~105 concrete 15
setblock ~32 ~25 ~106 wool 15
setblock ~32 ~25 ~107 concrete 15
setblock ~32 ~25 ~114 wool 15
setblock ~32 ~25 ~115 concrete 15
fill ~32 ~25 ~116 ~32 ~28 ~116 wool 15
setblock ~33 ~25 ~78 concrete 15
setblock ~33 ~25 ~79 obsidian
setblock ~33 ~25 ~80 concrete 15
setblock ~33 ~25 ~95 coal_block
setblock ~33 ~25 ~96 concrete 15
setblock ~33 ~25 ~97 obsidian
setblock ~33 ~25 ~98 concrete 15
setblock ~33 ~25 ~99 obsidian
setblock ~33 ~25 ~100 concrete 15
setblock ~33 ~25 ~101 obsidian
setblock ~33 ~25 ~102 concrete 15
setblock ~33 ~25 ~117 wool 15
setblock ~33 ~25 ~118 concrete 15
setblock ~34 ~25 ~80 wool 15
setblock ~34 ~25 ~82 obsidian
setblock ~34 ~25 ~83 concrete 15
setblock ~34 ~25 ~88 wool 15
setblock ~34 ~25 ~89 concrete 15
setblock ~34 ~25 ~90 obsidian
setblock ~34 ~25 ~91 concrete 15
setblock ~34 ~25 ~92 wool 15
setblock ~34 ~25 ~93 concrete 15
setblock ~34 ~25 ~94 obsidian
setblock ~34 ~25 ~95 concrete 15
setblock ~34 ~25 ~96 wool 15
setblock ~34 ~25 ~97 concrete 15
setblock ~34 ~25 ~119 wool 15
setblock ~35 ~25 ~83 obsidian
fill ~35 ~25 ~84 ~35 ~25 ~86 concrete 15
setblock ~35 ~25 ~87 obsidian
setblock ~35 ~25 ~88 concrete 15
setblock ~35 ~25 ~89 coal_block
setblock ~35 ~25 ~90 concrete 15
setblock ~35 ~25 ~121 obsidian
fill ~36 ~25 ~121 ~36 ~26 ~121 concrete 15
setblock ~37 ~25 ~121 wool 15
setblock ~38 ~25 ~121 concrete 15
setblock ~39 ~25 ~121 wool 15
setblock ~40 ~25 ~121 obsidian
setblock ~41 ~25 ~121 wool 15
fill ~42 ~25 ~121 ~42 ~26 ~121 concrete 15
setblock ~43 ~25 ~121 wool 15
fill ~44 ~25 ~121 ~44 ~26 ~121 concrete 15
setblock ~45 ~25 ~121 wool 15
setblock ~46 ~25 ~121 concrete 15
fill ~47 ~25 ~122 ~47 ~27 ~122 concrete 15
setblock ~48 ~25 ~82 obsidian
setblock ~48 ~25 ~83 concrete 15
setblock ~48 ~25 ~84 coal_block
setblock ~48 ~25 ~85 concrete 15
setblock ~48 ~25 ~86 coal_block
setblock ~48 ~25 ~121 concrete 15
setblock ~49 ~25 ~81 obsidian
setblock ~49 ~25 ~86 concrete 15
setblock ~49 ~25 ~87 coal_block
setblock ~49 ~25 ~88 concrete 15
setblock ~49 ~25 ~89 obsidian
setblock ~49 ~25 ~121 obsidian
setblock ~50 ~25 ~80 wool 15
setblock ~50 ~25 ~89 concrete 15
setblock ~50 ~25 ~90 obsidian
setblock ~50 ~25 ~91 concrete 15
setblock ~50 ~25 ~92 obsidian
fill ~50 ~25 ~121 ~50 ~26 ~121 concrete 15
setblock ~51 ~25 ~79 obsidian
setblock ~51 ~25 ~92 concrete 15
setblock ~51 ~25 ~93 coal_block
setblock ~51 ~25 ~94 concrete 15
setblock ~51 ~25 ~95 obsidian
setblock ~51 ~25 ~96 concrete 15
setblock ~52 ~25 ~78 coal_block
setblock ~52 ~25 ~95 concrete 15
setblock ~52 ~25 ~96 wool 15
setblock ~52 ~25 ~97 concrete 15
setblock ~52 ~25 ~98 obsidian
setblock ~52 ~25 ~99 concrete 15
fill ~52 ~25 ~119 ~52 ~26 ~119 concrete 15
setblock ~53 ~25 ~76 stained_glass 15
setblock ~53 ~25 ~98 concrete 15
setblock ~53 ~25 ~99 obsidian
setblock ~53 ~25 ~100 concrete 15
setblock ~53 ~25 ~101 obsidian
setblock ~53 ~25 ~102 concrete 15
setblock ~53 ~25 ~117 obsidian
fill ~53 ~25 ~118 ~53 ~30 ~118 concrete 15
setblock ~54 ~25 ~101 concrete 15
setblock ~54 ~25 ~102 wool 15
setblock ~54 ~25 ~103 concrete 15
setblock ~54 ~25 ~104 wool 15
setblock ~54 ~25 ~105 concrete 15
setblock ~54 ~25 ~106 wool 15
setblock ~54 ~25 ~107 concrete 15
setblock ~54 ~25 ~114 wool 15
setblock ~54 ~25 ~115 concrete 15
setblock ~54 ~25 ~116 wool 15
fill ~55 ~25 ~74 ~55 ~27 ~74 stained_glass 15
setblock ~55 ~25 ~104 concrete 15
setblock ~55 ~25 ~105 obsidian
setblock ~55 ~25 ~106 concrete 15
setblock ~55 ~25 ~107 obsidian
setblock ~55 ~25 ~108 concrete 15
setblock ~55 ~25 ~109 obsidian
setblock ~55 ~25 ~110 concrete 15
setblock ~55 ~25 ~111 obsidian
fill ~55 ~25 ~112 ~55 ~26 ~112 concrete 15
setblock ~55 ~25 ~113 obsidian
fill ~56 ~25 ~73 ~56 ~26 ~73 concrete 15
setblock ~58 ~25 ~71 wool 15
setblock ~60 ~25 ~69 wool 15
fill ~62 ~25 ~68 ~62 ~27 ~68 obsidian
setblock ~65 ~25 ~65 wool 15
setblock ~66 ~25 ~64 wool 15
setblock ~67 ~25 ~63 lapis_ore
setblock ~68 ~25 ~62 light_blue_glazed_terracotta
setblock ~69 ~25 ~61 stained_glass 15
setblock ~20 ~26 ~66 obsidian
fill ~21 ~26 ~67 ~22 ~26 ~67 concrete 15
fill ~24 ~26 ~69 ~24 ~28 ~69 concrete 15
setblock ~26 ~26 ~71 concrete 15
setblock ~28 ~26 ~72 obsidian
setblock ~29 ~26 ~73 concrete 15
setblock ~30 ~26 ~74 obsidian
setblock ~30 ~26 ~75 concrete 15
fill ~30 ~26 ~103 ~31 ~26 ~103 concrete 15
fill ~30 ~26 ~104 ~31 ~26 ~104 concrete 15
fill ~30 ~26 ~105 ~30 ~26 ~107 concrete 15
setblock ~30 ~26 ~108 obsidian
setblock ~30 ~26 ~109 concrete 15
setblock ~30 ~26 ~110 wool 15
setblock ~30 ~26 ~111 concrete 15
setblock ~30 ~26 ~112 wool 15
fill ~31 ~26 ~76 ~31 ~26 ~80 concrete 15
fill ~31 ~26 ~98 ~31 ~26 ~104 concrete 15
setblock ~31 ~26 ~113 obsidian
fill ~31 ~26 ~114 ~31 ~27 ~114 wool 15
setblock ~31 ~26 ~115 concrete 15
fill ~32 ~26 ~79 ~32 ~26 ~82 concrete 15
fill ~32 ~26 ~93 ~33 ~26 ~93 concrete 15
setblock ~32 ~26 ~94 coal_block
fill ~32 ~26 ~95 ~32 ~26 ~97 concrete 15
setblock ~32 ~26 ~98 coal_block
fill ~32 ~26 ~99 ~32 ~26 ~100 concrete 15
setblock ~32 ~26 ~117 obsidian
fill ~33 ~26 ~81 ~33 ~26 ~94 concrete 15
setblock ~33 ~26 ~118 obsidian
setblock ~33 ~26 ~119 concrete 15
fill ~34 ~26 ~84 ~34 ~26 ~87 concrete 15
fill ~34 ~26 ~120 ~34 ~30 ~120 wool 15
setblock ~35 ~26 ~121 concrete 15
fill ~37 ~26 ~122 ~39 ~26 ~122 concrete 15
setblock ~40 ~26 ~122 obsidian
fill ~41 ~26 ~122 ~41 ~28 ~122 concrete 15
setblock ~43 ~26 ~121 concrete 15
fill ~45 ~26 ~122 ~49 ~26 ~122 concrete 15
fill ~49 ~26 ~81 ~49 ~26 ~85 concrete 15
setblock ~50 ~26 ~80 concrete 15
fill ~50 ~26 ~85 ~50 ~26 ~88 concrete 15
fill ~51 ~26 ~79 ~51 ~28 ~79 concrete 15
fill ~51 ~26 ~88 ~51 ~26 ~91 concrete 15
fill ~51 ~26 ~121 ~51 ~29 ~121 concrete 15
fill ~52 ~26 ~77 ~52 ~29 ~77 stained_glass 15
fill ~52 ~26 ~78 ~52 ~26 ~77 stained_glass 15
setblock ~52 ~26 ~91 concrete 15
setblock ~52 ~26 ~92 coal_block
fill ~52 ~26 ~93 ~52 ~26 ~94 concrete 15
fill ~53 ~26 ~76 ~53 ~29 ~76 concrete 15
fill ~53 ~26 ~94 ~53 ~26 ~97 concrete 15
setblock ~54 ~26 ~75 stained_glass 15
setblock ~54 ~26 ~96 obsidian
setblock ~54 ~26 ~97 concrete 15
setblock ~54 ~26 ~98 obsidian
fill ~54 ~26 ~99 ~55 ~26 ~99 concrete 15
setblock ~54 ~26 ~100 coal_block
fill ~54 ~26 ~116 ~54 ~26 ~117 concrete 15
fill ~55 ~26 ~100 ~55 ~26 ~103 concrete 15
fill ~55 ~26 ~113 ~55 ~26 ~115 concrete 15
fill ~56 ~26 ~103 ~56 ~26 ~111 concrete 15
setblock ~57 ~26 ~72 obsidian
fill ~58 ~26 ~71 ~58 ~30 ~71 concrete 15
fill ~60 ~26 ~69 ~61 ~26 ~69 concrete 15
setblock ~63 ~26 ~67 concrete 15
setblock ~64 ~26 ~66 concrete 15
setblock ~65 ~26 ~65 concrete 15
fill ~66 ~26 ~64 ~66 ~27 ~64 obsidian
setblock ~67 ~26 ~63 concrete 15
fill ~68 ~26 ~62 ~68 ~27 ~62 wool 15
setblock ~20 ~27 ~66 wool 15
fill ~21 ~27 ~66 ~21 ~28 ~66 concrete 15
fill ~22 ~27 ~67 ~22 ~28 ~67 concrete 15
setblock ~26 ~27 ~71 wool 15
setblock ~28 ~27 ~73 wool 15
setblock ~29 ~27 ~74 concrete 15
setblock ~29 ~27 ~75 wool 15
setblock ~29 ~27 ~103 obsidian
setblock ~29 ~27 ~104 concrete 15
setblock ~29 ~27 ~105 obsidian
fill ~29 ~27 ~106 ~29 ~28 ~106 concrete 15
setblock ~29 ~27 ~107 wool 15
fill ~29 ~27 ~108 ~29 ~28 ~108 concrete 15
setblock ~30 ~27 ~76 obsidian
setblock ~30 ~27 ~77 concrete 15
setblock ~30 ~27 ~78 wool 15
setblock ~30 ~27 ~79 concrete 15
setblock ~30 ~27 ~80 obsidian
setblock ~30 ~27 ~81 concrete 15
setblock ~30 ~27 ~82 obsidian
setblock ~30 ~27 ~96 obsidian
setblock ~30 ~27 ~97 concrete 15
setblock ~30 ~27 ~98 obsidian
setblock ~30 ~27 ~99 concrete 15
setblock ~30 ~27 ~100 obsidian
setblock ~30 ~27 ~101 concrete 15
setblock ~30 ~27 ~102 wool 15
setblock ~30 ~27 ~109 obsidian
setblock ~30 ~27 ~110 concrete 7
fill ~30 ~27 ~111 ~30 ~28 ~111 wool 15
setblock ~30 ~27 ~112 concrete 7
setblock ~30 ~27 ~113 wool 15
setblock ~31 ~27 ~81 obsidian
fill ~31 ~27 ~82 ~31 ~27 ~84 concrete 15
setblock ~31 ~27 ~90 concrete 15
setblock ~31 ~27 ~91 coal_block
setblock ~31 ~27 ~92 concrete 15
setblock ~31 ~27 ~93 obsidian
setblock ~31 ~27 ~94 concrete 15
setblock ~31 ~27 ~95 coal_block
setblock ~31 ~27 ~96 concrete 15
setblock ~31 ~27 ~97 obsidian
setblock ~31 ~27 ~115 wool 15
setblock ~32 ~27 ~83 concrete 15
setblock ~32 ~27 ~84 obsidian
setblock ~32 ~27 ~85 concrete 15
setblock ~32 ~27 ~86 obsidian
setblock ~32 ~27 ~87 concrete 15
setblock ~32 ~27 ~88 obsidian
setblock ~32 ~27 ~89 concrete 15
setblock ~32 ~27 ~90 wool 15
setblock ~32 ~27 ~91 concrete 15
setblock ~32 ~27 ~92 obsidian
fill ~32 ~27 ~117 ~32 ~29 ~117 wool 15
setblock ~33 ~27 ~118 concrete 15
setblock ~33 ~27 ~119 wool 15
setblock ~35 ~27 ~121 obsidian
setblock ~36 ~27 ~122 wool 15
fill ~37 ~27 ~122 ~37 ~29 ~122 concrete 15
setblock ~38 ~27 ~122 wool 15
setblock ~39 ~27 ~122 concrete 15
setblock ~40 ~27 ~122 wool 15
setblock ~42 ~27 ~122 obsidian
fill ~43 ~27 ~122 ~43 ~29 ~122 concrete 15
setblock ~44 ~27 ~122 obsidian
fill ~45 ~27 ~122 ~45 ~28 ~122 concrete 15
setblock ~46 ~27 ~122 wool 15
setblock ~48 ~27 ~122 obsidian
fill ~49 ~27 ~122 ~49 ~29 ~122 concrete 15
setblock ~50 ~27 ~80 obsidian
setblock ~50 ~27 ~81 concrete 15
setblock ~50 ~27 ~82 obsidian
setblock ~50 ~27 ~83 concrete 15
setblock ~50 ~27 ~84 obsidian
setblock ~50 ~27 ~122 obsidian
fill ~51 ~27 ~78 ~51 ~28 ~78 stained_glass 15
setblock ~51 ~27 ~83 coal_block
setblock ~51 ~27 ~84 concrete 15
setblock ~51 ~27 ~85 obsidian
setblock ~51 ~27 ~86 concrete 15
setblock ~51 ~27 ~87 coal_block
setblock ~52 ~27 ~86 obsidian
setblock ~52 ~27 ~87 concrete 15
setblock ~52 ~27 ~88 obsidian
setblock ~52 ~27 ~89 concrete 15
setblock ~52 ~27 ~90 wool 15
setblock ~52 ~27 ~120 obsidian
setblock ~53 ~27 ~89 obsidian
setblock ~53 ~27 ~90 concrete 15
setblock ~53 ~27 ~91 coal_block
setblock ~53 ~27 ~92 concrete 15
setblock ~53 ~27 ~93 obsidian
fill ~53 ~27 ~119 ~53 ~28 ~119 concrete 15
fill ~54 ~27 ~75 ~54 ~28 ~75 concrete 15
setblock ~54 ~27 ~92 obsidian
setblock ~54 ~27 ~93 concrete 15
setblock ~54 ~27 ~94 wool 15
setblock ~54 ~27 ~95 concrete 15
setblock ~54 ~27 ~116 wool 15
fill ~54 ~27 ~117 ~54 ~32 ~117 concrete 15
setblock ~55 ~27 ~95 obsidian
setblock ~55 ~27 ~96 concrete 15
setblock ~55 ~27 ~97 obsidian
setblock ~55 ~27 ~98 concrete 15
setblock ~55 ~27 ~113 obsidian
fill ~55 ~27 ~114 ~55 ~30 ~114 concrete 15
fill ~55 ~27 ~115 ~55 ~28 ~115 concrete 15
setblock ~56 ~27 ~73 obsidian
setblock ~56 ~27 ~97 concrete 15
setblock ~56 ~27 ~98 wool 15
setblock ~56 ~27 ~99 concrete 15
setblock ~56 ~27 ~100 wool 15
setblock ~56 ~27 ~101 concrete 15
setblock ~56 ~27 ~102 wool 15
setblock ~56 ~27 ~109 concrete 15
setblock ~56 ~27 ~110 obsidian
fill ~56 ~27 ~111 ~56 ~30 ~111 concrete 15
setblock ~56 ~27 ~112 obsidian
setblock ~57 ~27 ~72 concrete 15
setblock ~57 ~27 ~103 obsidian
setblock ~57 ~27 ~104 concrete 15
setblock ~57 ~27 ~105 obsidian
fill ~57 ~27 ~106 ~57 ~28 ~106 concrete 15
fill ~57 ~27 ~107 ~57 ~28 ~107 concrete 15
fill ~57 ~27 ~108 ~57 ~30 ~108 concrete 15
fill ~60 ~27 ~69 ~61 ~27 ~69 concrete 15
setblock ~63 ~27 ~67 obsidian
setblock ~64 ~27 ~66 obsidian
setblock ~65 ~27 ~65 coal_block
setblock ~67 ~27 ~63 obsidian
setblock ~69 ~27 ~61 stained_glass 15
setblock ~24 ~28 ~70 concrete 15
setblock ~25 ~28 ~71 concrete 15
setblock ~26 ~28 ~72 wool 15
setblock ~27 ~28 ~73 concrete 15
setblock ~28 ~28 ~74 obsidian
setblock ~28 ~28 ~75 concrete 15
setblock ~28 ~28 ~76 obsidian
setblock ~28 ~28 ~103 concrete 15
setblock ~28 ~28 ~104 obsidian
setblock ~28 ~28 ~105 concrete 15
fill ~29 ~28 ~76 ~29 ~28 ~84 concrete 15
fill ~29 ~28 ~94 ~30 ~28 ~94 concrete 15
fill ~29 ~28 ~95 ~30 ~28 ~95 concrete 15
fill ~29 ~28 ~96 ~29 ~28 ~102 concrete 15
setblock ~29 ~28 ~107 concrete 15
setblock ~29 ~28 ~109 obsidian
fill ~29 ~28 ~110 ~29 ~29 ~110 wool 15
fill ~30 ~28 ~83 ~30 ~28 ~89 concrete 15
setblock ~30 ~28 ~90 coal_block
fill ~30 ~28 ~91 ~30 ~28 ~95 concrete 15
fill ~30 ~28 ~112 ~30 ~32 ~112 wool 15
fill ~30 ~28 ~113 ~30 ~29 ~113 obsidian
fill ~31 ~28 ~85 ~31 ~28 ~89 concrete 15
setblock ~31 ~28 ~114 obsidian
setblock ~31 ~28 ~115 concrete 15
setblock ~33 ~28 ~118 obsidian
setblock ~33 ~28 ~119 concrete 15
setblock ~35 ~28 ~121 concrete 15
setblock ~36 ~28 ~122 obsidian
setblock ~38 ~28 ~122 coal_block
fill ~39 ~28 ~123 ~40 ~28 ~123 concrete 15
setblock ~42 ~28 ~122 concrete 15
setblock ~44 ~28 ~122 concrete 15
fill ~46 ~28 ~123 ~47 ~28 ~123 concrete 15
setblock ~48 ~28 ~122 concrete 15
setblock ~50 ~28 ~122 concrete 15
fill ~51 ~28 ~80 ~52 ~28 ~80 concrete 15
fill ~51 ~28 ~81 ~52 ~28 ~81 concrete 15
fill ~51 ~28 ~82 ~52 ~28 ~82 concrete 15
setblock ~52 ~28 ~79 concrete 15
fill ~52 ~28 ~83 ~52 ~28 ~85 concrete 15
setblock ~52 ~28 ~120 concrete 15
fill ~53 ~28 ~84 ~53 ~28 ~88 concrete 15
setblock ~54 ~28 ~74 obsidian
fill ~54 ~28 ~87 ~54 ~28 ~91 concrete 15
setblock ~54 ~28 ~116 concrete 15
fill ~55 ~28 ~90 ~55 ~28 ~94 concrete 15
fill ~56 ~28 ~72 ~56 ~29 ~72 obsidian
setblock ~56 ~28 ~93 concrete 15
setblock ~56 ~28 ~94 obsidian
fill ~56 ~28 ~95 ~56 ~28 ~96 concrete 15
fill ~56 ~28 ~112 ~56 ~28 ~113 concrete 15
setblock ~57 ~28 ~71 concrete 15
fill ~57 ~28 ~96 ~57 ~28 ~102 concrete 15
fill ~57 ~28 ~109 ~57 ~28 ~110 concrete 15
fill ~58 ~28 ~103 ~58 ~29 ~103 concrete 15
setblock ~58 ~28 ~104 obsidian
setblock ~58 ~28 ~105 concrete 15
setblock ~59 ~28 ~70 wool 15
fill ~60 ~28 ~69 ~61 ~28 ~69 concrete 15
setblock ~62 ~28 ~68 concrete 15
setblock ~63 ~28 ~67 concrete 15
fill ~64 ~28 ~66 ~64 ~30 ~66 concrete 15
setblock ~65 ~28 ~65 concrete 15
setblock ~66 ~28 ~64 concrete 15
setblock ~67 ~28 ~63 concrete 15
setblock ~68 ~28 ~62 obsidian
setblock ~69 ~28 ~61 concrete 15
setblock ~21 ~29 ~66 stained_glass 15
setblock ~21 ~29 ~67 obsidian
setblock ~22 ~29 ~68 wool 15
setblock ~23 ~29 ~69 obsidian
setblock ~24 ~29 ~70 coal_block
setblock ~24 ~29 ~71 concrete 15
setblock ~25 ~29 ~72 concrete 15
setblock ~26 ~29 ~73 obsidian
setblock ~27 ~29 ~74 concrete 15
setblock ~27 ~29 ~75 wool 15
setblock ~27 ~29 ~76 concrete 15
fill ~27 ~29 ~77 ~28 ~29 ~77 obsidian
setblock ~28 ~29 ~78 wool 15
setblock ~28 ~29 ~79 concrete 15
setblock ~28 ~29 ~80 wool 15
setblock ~28 ~29 ~81 concrete 15
setblock ~28 ~29 ~82 wool 15
setblock ~28 ~29 ~83 concrete 15
setblock ~28 ~29 ~84 obsidian
setblock ~28 ~29 ~85 concrete 15
setblock ~28 ~29 ~86 wool 15
setblock ~28 ~29 ~91 concrete 15
setblock ~28 ~29 ~92 wool 15
setblock ~28 ~29 ~93 concrete 15
setblock ~28 ~29 ~94 wool 15
setblock ~28 ~29 ~95 concrete 15
setblock ~28 ~29 ~96 wool 15
setblock ~28 ~29 ~97 concrete 15
setblock ~28 ~29 ~98 wool 15
setblock ~28 ~29 ~99 concrete 15
setblock ~28 ~29 ~100 wool 15
setblock ~28 ~29 ~101 concrete 15
setblock ~28 ~29 ~102 wool 15
setblock ~28 ~29 ~103 obsidian
fill ~28 ~29 ~104 ~28 ~29 ~105 wool 15
fill ~28 ~29 ~106 ~28 ~30 ~106 concrete 7
fill ~28 ~29 ~107 ~28 ~31 ~107 wool 15
setblock ~29 ~29 ~85 obsidian
setblock ~29 ~29 ~86 concrete 15
setblock ~29 ~29 ~87 obsidian
setblock ~29 ~29 ~88 concrete 15
setblock ~29 ~29 ~89 wool 15
setblock ~29 ~29 ~90 concrete 15
setblock ~29 ~29 ~91 obsidian
setblock ~29 ~29 ~92 concrete 15
setblock ~29 ~29 ~93 obsidian
setblock ~29 ~29 ~108 concrete 7
setblock ~29 ~29 ~109 blue_glazed_terracotta
setblock ~29 ~29 ~111 wool 15
fill ~30 ~29 ~114 ~30 ~30 ~114 wool 15
setblock ~31 ~29 ~115 stained_hardened_clay 7
setblock ~31 ~29 ~116 obsidian
fill ~32 ~29 ~118 ~32 ~34 ~118 wool 15
setblock ~33 ~29 ~119 wool 15
setblock ~35 ~29 ~121 wool 15
fill ~35 ~29 ~122 ~35 ~32 ~122 concrete 15
setblock ~36 ~29 ~122 wool 15
fill ~38 ~29 ~123 ~38 ~32 ~123 concrete 15
setblock ~39 ~29 ~123 obsidian
fill ~40 ~29 ~123 ~40 ~31 ~123 concrete 15
setblock ~41 ~29 ~123 obsidian
fill ~42 ~29 ~123 ~42 ~32 ~123 concrete 15
fill ~44 ~29 ~123 ~44 ~31 ~123 concrete 15
setblock ~45 ~29 ~123 obsidian
fill ~46 ~29 ~123 ~46 ~31 ~123 concrete 15
setblock ~47 ~29 ~123 obsidian
fill ~48 ~29 ~123 ~48 ~31 ~123 concrete 15
setblock ~50 ~29 ~122 obsidian
fill ~51 ~29 ~122 ~51 ~32 ~122 concrete 15
setblock ~52 ~29 ~78 stained_glass 15
setblock ~52 ~29 ~120 obsidian
setblock ~53 ~29 ~75 obsidian
setblock ~53 ~29 ~77 obsidian
setblock ~53 ~29 ~78 concrete 15
setblock ~53 ~29 ~79 obsidian
setblock ~53 ~29 ~80 concrete 15
setblock ~53 ~29 ~81 obsidian
setblock ~53 ~29 ~82 concrete 15
setblock ~53 ~29 ~83 obsidian
setblock ~53 ~29 ~119 obsidian
setblock ~54 ~29 ~74 wool 15
setblock ~54 ~29 ~79 concrete 15
setblock ~54 ~29 ~80 wool 15
setblock ~54 ~29 ~81 concrete 15
setblock ~54 ~29 ~82 wool 15
setblock ~54 ~29 ~83 concrete 15
setblock ~54 ~29 ~84 wool 15
setblock ~54 ~29 ~85 concrete 15
setblock ~54 ~29 ~86 wool 15
setblock ~54 ~29 ~116 wool 15
setblock ~55 ~29 ~73 stained_glass 15
setblock ~55 ~29 ~85 obsidian
setblock ~55 ~29 ~86 concrete 15
setblock ~55 ~29 ~87 obsidian
setblock ~55 ~29 ~88 concrete 15
setblock ~55 ~29 ~89 obsidian
setblock ~55 ~29 ~115 obsidian
setblock ~56 ~29 ~88 wool 15
setblock ~56 ~29 ~89 concrete 15
setblock ~56 ~29 ~90 wool 15
setblock ~56 ~29 ~91 concrete 15
setblock ~56 ~29 ~92 wool 15
setblock ~56 ~29 ~112 wool 15
fill ~56 ~29 ~113 ~56 ~34 ~113 concrete 15
fill ~57 ~29 ~72 ~57 ~31 ~72 concrete 15
setblock ~57 ~29 ~91 obsidian
setblock ~57 ~29 ~92 concrete 15
setblock ~57 ~29 ~93 obsidian
setblock ~57 ~29 ~94 concrete 15
setblock ~57 ~29 ~95 obsidian
setblock ~57 ~29 ~109 obsidian
fill ~57 ~29 ~110 ~57 ~36 ~110 concrete 15
setblock ~58 ~29 ~96 wool 15
setblock ~58 ~29 ~97 concrete 15
setblock ~58 ~29 ~98 wool 15
setblock ~58 ~29 ~99 concrete 15
setblock ~58 ~29 ~100 wool 15
setblock ~58 ~29 ~101 concrete 15
setblock ~58 ~29 ~102 wool 15
setblock ~58 ~29 ~104 wool 15
setblock ~58 ~29 ~105 obsidian
setblock ~58 ~29 ~106 wool 15
fill ~58 ~29 ~107 ~58 ~36 ~107 concrete 15
fill ~59 ~29 ~70 ~59 ~30 ~70 concrete 15
setblock ~60 ~29 ~70 wool 7
setblock ~61 ~29 ~69 coal_block
setblock ~62 ~29 ~68 coal_block
setblock ~63 ~29 ~67 wool 15
setblock ~65 ~29 ~65 obsidian
setblock ~66 ~29 ~64 obsidian
setblock ~67 ~29 ~63 obsidian
fill ~68 ~29 ~61 ~68 ~32 ~61 concrete 15
setblock ~68 ~29 ~62 wool 15
fill ~69 ~29 ~60 ~69 ~34 ~60 concrete 15
fill ~21 ~30 ~67 ~21 ~30 ~68 stained_glass 15
setblock ~22 ~30 ~69 concrete 15
fill ~23 ~30 ~70 ~23 ~30 ~71 obsidian
setblock ~24 ~30 ~72 obsidian
setblock ~25 ~30 ~73 concrete 15
fill ~26 ~30 ~74 ~26 ~30 ~77 concrete 15
fill ~27 ~30 ~78 ~27 ~30 ~86 concrete 15
setblock ~27 ~30 ~91 concrete 15
setblock ~27 ~30 ~92 obsidian
fill ~27 ~30 ~93 ~27 ~30 ~101 concrete 15
fill ~27 ~30 ~102 ~27 ~31 ~102 obsidian
fill ~27 ~30 ~103 ~27 ~30 ~102 obsidian
fill ~28 ~30 ~87 ~28 ~30 ~89 concrete 15
setblock ~28 ~30 ~90 obsidian
setblock ~28 ~30 ~104 concrete 7
setblock ~28 ~30 ~105 wool 15
setblock ~28 ~30 ~108 wool 15
setblock ~29 ~30 ~109 concrete 15
setblock ~29 ~30 ~110 obsidian
setblock ~29 ~30 ~111 concrete 15
setblock ~30 ~30 ~113 concrete 15
setblock ~31 ~30 ~115 obsidian
setblock ~31 ~30 ~116 wool 15
fill ~32 ~30 ~117 ~32 ~31 ~117 obsidian
setblock ~33 ~30 ~119 concrete 15
setblock ~34 ~30 ~121 concrete 15
setblock ~36 ~30 ~122 obsidian
setblock ~37 ~30 ~123 concrete 15
setblock ~39 ~30 ~123 concrete 15
setblock ~41 ~30 ~123 concrete 15
fill ~43 ~30 ~123 ~43 ~32 ~123 concrete 15
setblock ~45 ~30 ~123 concrete 15
fill ~47 ~30 ~123 ~47 ~31 ~123 concrete 15
fill ~49 ~30 ~123 ~50 ~30 ~123 concrete 15
fill ~52 ~30 ~120 ~52 ~30 ~121 concrete 15
setblock ~53 ~30 ~119 concrete 15
fill ~54 ~30 ~74 ~55 ~30 ~74 concrete 15
fill ~54 ~30 ~75 ~55 ~30 ~75 concrete 15
fill ~54 ~30 ~76 ~55 ~30 ~76 concrete 15
fill ~54 ~30 ~77 ~55 ~30 ~77 concrete 15
setblock ~54 ~30 ~78 coal_block
setblock ~55 ~30 ~73 concrete 15
fill ~55 ~30 ~78 ~55 ~30 ~84 concrete 15
fill ~55 ~30 ~115 ~55 ~30 ~116 concrete 15
setblock ~56 ~30 ~72 concrete 15
setblock ~56 ~30 ~79 concrete 15
setblock ~56 ~30 ~80 coal_block
fill ~56 ~30 ~81 ~56 ~30 ~83 concrete 15
setblock ~56 ~30 ~84 obsidian
setblock ~56 ~30 ~85 concrete 15
setblock ~56 ~30 ~86 obsidian
fill ~56 ~30 ~87 ~57 ~30 ~87 concrete 15
setblock ~56 ~30 ~112 obsidian
setblock ~57 ~30 ~86 concrete 15
fill ~57 ~30 ~88 ~57 ~30 ~90 concrete 15
setblock ~57 ~30 ~109 concrete 15
setblock ~58 ~30 ~89 concrete 15
setblock ~58 ~30 ~90 obsidian
fill ~58 ~30 ~91 ~58 ~30 ~93 concrete 15
setblock ~58 ~30 ~94 obsidian
setblock ~58 ~30 ~95 concrete 15
setblock ~58 ~30 ~104 obsidian
setblock ~58 ~30 ~105 concrete 15
setblock ~58 ~30 ~106 obsidian
fill ~59 ~30 ~96 ~59 ~30 ~103 concrete 15
setblock ~60 ~30 ~70 obsidian
setblock ~61 ~30 ~69 concrete 15
setblock ~62 ~30 ~68 concrete 15
setblock ~63 ~30 ~67 concrete 7
fill ~65 ~30 ~65 ~65 ~31 ~65 concrete 15
setblock ~66 ~30 ~64 concrete 15
fill ~67 ~30 ~63 ~67 ~32 ~63 concrete 15
fill ~68 ~30 ~62 ~68 ~32 ~62 obsidian
setblock ~69 ~30 ~59 concrete 15
setblock ~19 ~31 ~65 wool 15
setblock ~20 ~31 ~66 wool 15
fill ~20 ~31 ~67 ~20 ~32 ~67 concrete 15
setblock ~21 ~31 ~68 stained_glass 15
setblock ~22 ~31 ~70 obsidian
setblock ~22 ~31 ~71 concrete 15
setblock ~23 ~31 ~72 concrete 7
setblock ~24 ~31 ~73 concrete 15
setblock ~25 ~31 ~74 concrete 15
setblock ~25 ~31 ~75 obsidian
setblock ~25 ~31 ~76 concrete 15
setblock ~25 ~31 ~77 obsidian
setblock ~25 ~31 ~78 concrete 15
fill ~26 ~31 ~78 ~26 ~31 ~79 obsidian
setblock ~26 ~31 ~80 wool 15
setblock ~26 ~31 ~81 concrete 15
setblock ~26 ~31 ~82 wool 15
setblock ~26 ~31 ~83 concrete 15
setblock ~26 ~31 ~84 obsidian
setblock ~26 ~31 ~85 concrete 15
setblock ~26 ~31 ~86 obsidian
setblock ~26 ~31 ~93 obsidian
setblock ~26 ~31 ~94 nether_brick
setblock ~26 ~31 ~95 obsidian
setblock ~26 ~31 ~96 wool 15
fill ~26 ~31 ~97 ~26 ~32 ~97 obsidian
fill ~26 ~31 ~98 ~26 ~32 ~98 concrete 7
setblock ~26 ~31 ~99 wool 15
setblock ~26 ~31 ~100 stained_hardened_clay 7
fill ~27 ~31 ~87 ~27 ~31 ~88 concrete 15
setblock ~27 ~31 ~89 obsidian
setblock ~27 ~31 ~90 concrete 15
setblock ~27 ~31 ~91 obsidian
setblock ~27 ~31 ~92 concrete 15
setblock ~27 ~31 ~101 wool 15
setblock ~27 ~31 ~103 stained_hardened_clay 7
fill ~27 ~31 ~104 ~27 ~32 ~104 wool 15
setblock ~27 ~31 ~105 stained_hardened_clay 7
setblock ~28 ~31 ~106 stained_hardened_clay 7
setblock ~28 ~31 ~108 nether_brick
setblock ~29 ~31 ~109 nether_brick
fill ~29 ~31 ~110 ~29 ~32 ~110 wool 15
fill ~29 ~31 ~111 ~29 ~31 ~110 wool 15
fill ~30 ~31 ~113 ~30 ~32 ~113 obsidian
fill ~30 ~31 ~114 ~30 ~37 ~114 concrete 7
setblock ~31 ~31 ~115 wool 15
setblock ~31 ~31 ~116 concrete 15
setblock ~33 ~31 ~119 wool 15
fill ~33 ~31 ~120 ~33 ~33 ~120 concrete 15
setblock ~34 ~31 ~121 obsidian
fill ~36 ~31 ~123 ~36 ~32 ~123 concrete 15
setblock ~37 ~31 ~123 obsidian
setblock ~39 ~31 ~123 obsidian
setblock ~41 ~31 ~123 obsidian
setblock ~45 ~31 ~123 coal_block
fill ~49 ~31 ~123 ~50 ~31 ~123 concrete 15
fill ~52 ~31 ~121 ~52 ~32 ~121 concrete 15
setblock ~53 ~31 ~119 coal_block
fill ~53 ~31 ~120 ~53 ~35 ~120 concrete 15
setblock ~54 ~31 ~118 wool 15
setblock ~55 ~31 ~115 obsidian
fill ~55 ~31 ~116 ~55 ~35 ~116 concrete 15
setblock ~56 ~31 ~73 concrete 15
setblock ~56 ~31 ~74 obsidian
setblock ~56 ~31 ~75 concrete 15
setblock ~56 ~31 ~76 obsidian
setblock ~56 ~31 ~77 concrete 15
setblock ~56 ~31 ~78 obsidian
setblock ~56 ~31 ~112 wool 15
setblock ~56 ~31 ~114 wool 15
setblock ~57 ~31 ~77 coal_block
setblock ~57 ~31 ~78 concrete 15
setblock ~57 ~31 ~79 coal_block
setblock ~57 ~31 ~80 concrete 15
setblock ~57 ~31 ~81 obsidian
setblock ~57 ~31 ~82 concrete 15
setblock ~57 ~31 ~83 obsidian
setblock ~57 ~31 ~84 concrete 15
setblock ~57 ~31 ~85 obsidian
setblock ~57 ~31 ~109 wool 15
setblock ~57 ~31 ~111 obsidian
setblock ~58 ~31 ~72 obsidian
setblock ~58 ~31 ~83 concrete 15
setblock ~58 ~31 ~84 obsidian
setblock ~58 ~31 ~85 concrete 15
setblock ~58 ~31 ~86 wool 15
setblock ~58 ~31 ~87 concrete 15
setblock ~58 ~31 ~88 obsidian
setblock ~58 ~31 ~106 wool 15
setblock ~58 ~31 ~108 obsidian
setblock ~59 ~31 ~71 concrete 15
setblock ~59 ~31 ~88 concrete 15
setblock ~59 ~31 ~89 obsidian
setblock ~59 ~31 ~90 concrete 15
setblock ~59 ~31 ~91 obsidian
setblock ~59 ~31 ~92 concrete 15
setblock ~59 ~31 ~93 obsidian
setblock ~59 ~31 ~94 concrete 15
setblock ~59 ~31 ~95 obsidian
setblock ~59 ~31 ~101 obsidian
setblock ~59 ~31 ~102 concrete 15
setblock ~59 ~31 ~103 obsidian
fill ~59 ~31 ~104 ~59 ~33 ~104 concrete 15
setblock ~59 ~31 ~105 wool 15
fill ~60 ~31 ~70 ~61 ~31 ~70 wool 15
setblock ~60 ~31 ~95 concrete 15
setblock ~60 ~31 ~96 obsidian
fill ~60 ~31 ~97 ~60 ~32 ~97 concrete 15
setblock ~60 ~31 ~98 wool 15
fill ~60 ~31 ~99 ~60 ~32 ~99 concrete 15
setblock ~60 ~31 ~100 obsidian
setblock ~62 ~31 ~69 concrete 15
setblock ~63 ~31 ~68 concrete 15
setblock ~64 ~31 ~67 concrete 15
setblock ~65 ~31 ~66 concrete 15
setblock ~66 ~31 ~64 obsidian
setblock ~69 ~31 ~59 obsidian
fill ~70 ~31 ~57 ~70 ~33 ~57 concrete 15
setblock ~70 ~31 ~58 wool 15
setblock ~71 ~31 ~55 obsidian
setblock ~71 ~31 ~56 stained_glass 15
fill ~72 ~31 ~52 ~72 ~33 ~52 wool 15
fill ~72 ~31 ~53 ~72 ~31 ~54 stained_glass 15
setblock ~73 ~31 ~50 concrete 15
setblock ~73 ~31 ~51 obsidian
setblock ~18 ~32 ~64 stained_glass 15
setblock ~19 ~32 ~65 concrete 15
fill ~19 ~32 ~66 ~19 ~33 ~66 obsidian
fill ~20 ~32 ~68 ~20 ~32 ~69 concrete 15
setblock ~21 ~32 ~70 stained_glass 15
setblock ~21 ~32 ~71 concrete 15
setblock ~22 ~32 ~72 wool 15
fill ~23 ~32 ~73 ~23 ~32 ~74 concrete 15
fill ~24 ~32 ~74 ~24 ~32 ~79 concrete 15
fill ~25 ~32 ~79 ~25 ~32 ~85 concrete 15
setblock ~25 ~32 ~95 concrete 15
fill ~26 ~32 ~86 ~26 ~32 ~93 concrete 15
setblock ~26 ~32 ~94 obsidian
setblock ~26 ~32 ~96 obsidian
fill ~26 ~32 ~99 ~26 ~32 ~100 concrete 7
fill ~26 ~32 ~101 ~26 ~33 ~101 wool 15
setblock ~26 ~32 ~102 concrete 7
setblock ~27 ~32 ~103 obsidian
setblock ~27 ~32 ~105 obsidian
setblock ~28 ~32 ~106 wool 15
setblock ~28 ~32 ~107 concrete 15
setblock ~28 ~32 ~108 wool 15
setblock ~29 ~32 ~109 obsidian
setblock ~29 ~32 ~111 concrete 15
setblock ~31 ~32 ~115 concrete 15
fill ~31 ~32 ~116 ~31 ~33 ~116 obsidian
setblock ~32 ~32 ~117 concrete 15
setblock ~32 ~32 ~119 concrete 15
setblock ~34 ~32 ~121 concrete 15
setblock ~37 ~32 ~123 concrete 15
fill ~39 ~32 ~124 ~41 ~32 ~124 concrete 15
fill ~44 ~32 ~124 ~48 ~32 ~124 concrete 15
fill ~49 ~32 ~123 ~51 ~32 ~123 concrete 15
setblock ~53 ~32 ~119 concrete 15
setblock ~54 ~32 ~118 concrete 15
setblock ~55 ~32 ~115 concrete 15
setblock ~56 ~32 ~112 obsidian
setblock ~56 ~32 ~114 obsidian
fill ~57 ~32 ~73 ~58 ~32 ~73 concrete 15
fill ~57 ~32 ~74 ~58 ~32 ~74 concrete 15
fill ~57 ~32 ~75 ~58 ~32 ~75 concrete 15
fill ~57 ~32 ~76 ~58 ~32 ~76 concrete 15
setblock ~57 ~32 ~109 concrete 15
setblock ~57 ~32 ~111 concrete 15
fill ~58 ~32 ~77 ~58 ~32 ~82 concrete 15
setblock ~58 ~32 ~106 obsidian
setblock ~58 ~32 ~108 concrete 15
setblock ~59 ~32 ~72 concrete 15
fill ~59 ~32 ~81 ~59 ~32 ~87 concrete 15
setblock ~59 ~32 ~103 concrete 15
setblock ~59 ~32 ~105 concrete 15
setblock ~60 ~32 ~71 concrete 15
fill ~60 ~32 ~87 ~60 ~32 ~94 concrete 15
setblock ~60 ~32 ~96 concrete 15
setblock ~60 ~32 ~98 concrete 15
fill ~60 ~32 ~100 ~60 ~32 ~102 concrete 15
fill ~61 ~32 ~70 ~62 ~32 ~70 wool 15
setblock ~61 ~32 ~95 concrete 15
setblock ~63 ~32 ~69 concrete 15
setblock ~64 ~32 ~68 concrete 15
setblock ~65 ~32 ~67 concrete 15
fill ~66 ~32 ~65 ~66 ~32 ~66 concrete 15
fill ~67 ~32 ~64 ~67 ~33 ~64 concrete 15
setblock ~69 ~32 ~59 concrete 15
setblock ~70 ~32 ~58 obsidian
setblock ~71 ~32 ~54 obsidian
setblock ~71 ~32 ~55 concrete 15
setblock ~71 ~32 ~56 obsidian
setblock ~72 ~32 ~53 wool 15
setblock ~73 ~32 ~50 obsidian
setblock ~73 ~32 ~51 concrete 15
setblock ~74 ~32 ~48 stained_glass 15
setblock ~74 ~32 ~49 concrete 15
setblock ~75 ~32 ~47 stained_glass 15
setblock ~17 ~33 ~63 wool 15
setblock ~18 ~33 ~64 nether_brick
setblock ~18 ~33 ~65 wool 15
setblock ~19 ~33 ~67 wool 15
setblock ~20 ~33 ~68 nether_brick
fill ~20 ~33 ~69 ~20 ~33 ~70 wool 15
setblock ~21 ~33 ~71 obsidian
fill ~21 ~33 ~72 ~21 ~34 ~72 concrete 15
setblock ~22 ~33 ~73 concrete 15
setblock ~22 ~33 ~74 obsidian
setblock ~23 ~33 ~75 obsidian
setblock ~23 ~33 ~76 concrete 15
setblock ~23 ~33 ~77 obsidian
setblock ~23 ~33 ~78 concrete 15
setblock ~24 ~33 ~79 concrete 15
setblock ~24 ~33 ~80 wool 15
setblock ~24 ~33 ~81 concrete 15
setblock ~24 ~33 ~82 wool 15
setblock ~24 ~33 ~83 concrete 15
setblock ~24 ~33 ~84 wool 15
setblock ~25 ~33 ~85 obsidian
setblock ~25 ~33 ~86 concrete 15
setblock ~25 ~33 ~87 obsidian
setblock ~25 ~33 ~88 concrete 15
setblock ~25 ~33 ~89 obsidian
setblock ~25 ~33 ~90 concrete 15
setblock ~25 ~33 ~91 wool 15
setblock ~25 ~33 ~92 concrete 15
setblock ~25 ~33 ~93 wool 15
setblock ~25 ~33 ~94 concrete 15
setblock ~25 ~33 ~95 wool 15
setblock ~25 ~33 ~96 concrete 15
setblock ~25 ~33 ~97 wool 15
setblock ~25 ~33 ~98 concrete 15
setblock ~25 ~33 ~99 wool 15
setblock ~26 ~33 ~100 nether_brick
setblock ~26 ~33 ~102 nether_brick
setblock ~27 ~33 ~103 stained_hardened_clay 7
setblock ~27 ~33 ~104 obsidian
setblock ~27 ~33 ~105 wool 15
setblock ~27 ~33 ~106 concrete 15
setblock ~28 ~33 ~107 wool 15
setblock ~28 ~33 ~108 stained_hardened_clay 7
fill ~28 ~33 ~109 ~28 ~37 ~109 wool 15
fill ~29 ~33 ~110 ~29 ~35 ~110 obsidian
setblock ~29 ~33 ~111 wool 15
setblock ~29 ~33 ~112 obsidian
fill ~30 ~33 ~113 ~30 ~35 ~113 wool 15
setblock ~30 ~33 ~115 wool 15
setblock ~31 ~33 ~117 wool 15
setblock ~32 ~33 ~119 obsidian
setblock ~34 ~33 ~121 obsidian
fill ~34 ~33 ~122 ~34 ~39 ~122 wool 15
setblock ~35 ~33 ~123 wool 15
fill ~36 ~33 ~123 ~37 ~33 ~123 obsidian
setblock ~38 ~33 ~124 wool 15
fill ~39 ~33 ~124 ~39 ~36 ~124 concrete 15
setblock ~40 ~33 ~124 wool 15
fill ~41 ~33 ~124 ~41 ~35 ~124 concrete 15
setblock ~42 ~33 ~124 wool 15
fill ~43 ~33 ~124 ~43 ~34 ~124 concrete 15
setblock ~44 ~33 ~124 wool 15
fill ~45 ~33 ~124 ~45 ~35 ~124 concrete 15
setblock ~46 ~33 ~124 obsidian
fill ~47 ~33 ~124 ~47 ~35 ~124 concrete 15
setblock ~48 ~33 ~124 obsidian
fill ~49 ~33 ~124 ~49 ~41 ~124 concrete 15
fill ~50 ~33 ~123 ~50 ~42 ~123 concrete 15
setblock ~51 ~33 ~123 obsidian
setblock ~52 ~33 ~122 obsidian
setblock ~53 ~33 ~121 obsidian
setblock ~54 ~33 ~118 wool 15
fill ~54 ~33 ~119 ~54 ~38 ~119 concrete 15
setblock ~55 ~33 ~115 wool 15
setblock ~55 ~33 ~117 obsidian
setblock ~56 ~33 ~112 wool 15
setblock ~56 ~33 ~114 wool 15
setblock ~57 ~33 ~109 wool 15
setblock ~57 ~33 ~111 obsidian
setblock ~58 ~33 ~106 wool 15
setblock ~58 ~33 ~108 wool 15
fill ~59 ~33 ~73 ~60 ~33 ~73 concrete 15
fill ~59 ~33 ~74 ~59 ~33 ~73 concrete 15
setblock ~59 ~33 ~75 obsidian
setblock ~59 ~33 ~76 concrete 15
setblock ~59 ~33 ~77 coal_block
setblock ~59 ~33 ~78 concrete 15
setblock ~59 ~33 ~79 obsidian
setblock ~59 ~33 ~80 concrete 15
setblock ~59 ~33 ~103 wool 15
setblock ~59 ~33 ~105 wool 15
setblock ~60 ~33 ~72 obsidian
setblock ~60 ~33 ~74 obsidian
setblock ~60 ~33 ~79 concrete 15
setblock ~60 ~33 ~80 wool 15
setblock ~60 ~33 ~81 concrete 15
setblock ~60 ~33 ~82 obsidian
setblock ~60 ~33 ~83 concrete 15
setblock ~60 ~33 ~84 wool 15
setblock ~60 ~33 ~85 concrete 15
setblock ~60 ~33 ~86 obsidian
fill ~60 ~33 ~100 ~60 ~35 ~100 wool 15
fill ~60 ~33 ~101 ~60 ~37 ~101 concrete 15
setblock ~60 ~33 ~102 wool 15
setblock ~61 ~33 ~71 obsidian
setblock ~61 ~33 ~86 concrete 15
setblock ~61 ~33 ~87 obsidian
setblock ~61 ~33 ~88 concrete 15
setblock ~61 ~33 ~89 obsidian
setblock ~61 ~33 ~90 concrete 15
setblock ~61 ~33 ~91 obsidian
setblock ~61 ~33 ~92 concrete 15
setblock ~61 ~33 ~93 obsidian
setblock ~61 ~33 ~94 concrete 15
setblock ~61 ~33 ~95 obsidian
fill ~61 ~33 ~96 ~61 ~34 ~96 concrete 15
setblock ~61 ~33 ~97 obsidian
fill ~61 ~33 ~98 ~61 ~38 ~98 concrete 15
setblock ~61 ~33 ~99 obsidian
fill ~62 ~33 ~71 ~62 ~34 ~71 concrete 15
setblock ~63 ~33 ~70 concrete 15
setblock ~64 ~33 ~69 concrete 15
setblock ~65 ~33 ~68 concrete 15
setblock ~66 ~33 ~66 wool 15
fill ~66 ~33 ~67 ~66 ~34 ~67 concrete 15
setblock ~67 ~33 ~65 obsidian
setblock ~68 ~33 ~62 wool 15
fill ~68 ~33 ~63 ~68 ~34 ~63 concrete 15
setblock ~69 ~33 ~61 wool 15
setblock ~70 ~33 ~58 wool 15
fill ~70 ~33 ~59 ~70 ~35 ~59 concrete 15
setblock ~71 ~33 ~55 wool 15
fill ~71 ~33 ~56 ~71 ~34 ~56 concrete 15
setblock ~72 ~33 ~53 obsidian
fill ~72 ~33 ~54 ~72 ~35 ~54 wool 15
setblock ~73 ~33 ~50 concrete 15
setblock ~73 ~33 ~51 wool 15
setblock ~74 ~33 ~48 concrete 7
setblock ~74 ~33 ~49 wool 15
setblock ~75 ~33 ~46 concrete 15
setblock ~75 ~33 ~47 obsidian
setblock ~76 ~33 ~43 stained_glass 15
setblock ~76 ~33 ~44 obsidian
fill ~76 ~33 ~45 ~76 ~34 ~45 concrete 15
fill ~16 ~34 ~61 ~16 ~34 ~62 stained_glass 15
setblock ~17 ~34 ~63 concrete 15
setblock ~17 ~34 ~64 obsidian
setblock ~18 ~34 ~65 obsidian
setblock ~18 ~34 ~66 wool 15
setblock ~19 ~34 ~67 concrete 15
setblock ~19 ~34 ~68 wool 15
setblock ~19 ~34 ~69 concrete 15
setblock ~20 ~34 ~70 wool 15
setblock ~20 ~34 ~71 concrete 15
fill ~21 ~34 ~73 ~21 ~34 ~74 concrete 15
setblock ~22 ~34 ~75 concrete 15
setblock ~22 ~34 ~76 obsidian
fill ~22 ~34 ~77 ~22 ~34 ~78 concrete 15
fill ~23 ~34 ~79 ~23 ~34 ~83 concrete 15
setblock ~24 ~34 ~84 obsidian
setblock ~24 ~34 ~85 concrete 15
setblock ~24 ~34 ~86 obsidian
setblock ~24 ~34 ~87 concrete 15
setblock ~24 ~34 ~88 obsidian
setblock ~24 ~34 ~89 concrete 15
setblock ~24 ~34 ~90 wool 15
fill ~24 ~34 ~91 ~24 ~34 ~92 obsidian
setblock ~24 ~34 ~93 concrete 15
setblock ~24 ~34 ~94 obsidian
setblock ~24 ~34 ~95 concrete 15
setblock ~25 ~34 ~96 obsidian
setblock ~25 ~34 ~97 concrete 15
setblock ~25 ~34 ~98 wool 15
setblock ~25 ~34 ~99 obsidian
setblock ~26 ~34 ~100 wool 15
setblock ~26 ~34 ~101 concrete 15
fill ~26 ~34 ~102 ~26 ~34 ~103 wool 15
setblock ~27 ~34 ~104 wool 15
fill ~27 ~34 ~105 ~27 ~34 ~106 obsidian
setblock ~28 ~34 ~107 obsidian
setblock ~28 ~34 ~108 wool 15
setblock ~29 ~34 ~111 concrete 15
setblock ~29 ~34 ~112 wool 15
setblock ~30 ~34 ~115 obsidian
setblock ~31 ~34 ~116 wool 15
setblock ~31 ~34 ~117 obsidian
setblock ~32 ~34 ~119 concrete 15
setblock ~33 ~34 ~120 obsidian
setblock ~34 ~34 ~121 concrete 15
fill ~35 ~34 ~123 ~36 ~34 ~123 concrete 15
fill ~37 ~34 ~124 ~37 ~41 ~124 concrete 15
setblock ~38 ~34 ~120 concrete 15
setblock ~38 ~34 ~124 obsidian
fill ~39 ~34 ~121 ~40 ~34 ~121 concrete 15
setblock ~40 ~34 ~124 obsidian
fill ~41 ~34 ~122 ~45 ~34 ~122 concrete 15
setblock ~42 ~34 ~124 concrete 15
setblock ~44 ~34 ~124 concrete 15
fill ~46 ~34 ~121 ~47 ~34 ~121 concrete 15
setblock ~46 ~34 ~124 concrete 15
setblock ~48 ~34 ~124 concrete 15
fill ~51 ~34 ~123 ~51 ~36 ~123 concrete 15
setblock ~52 ~34 ~122 concrete 15
setblock ~53 ~34 ~121 concrete 15
setblock ~54 ~34 ~118 obsidian
setblock ~55 ~34 ~117 concrete 15
setblock ~56 ~34 ~112 obsidian
setblock ~56 ~34 ~114 obsidian
fill ~56 ~34 ~115 ~56 ~39 ~115 concrete 15
setblock ~57 ~34 ~109 concrete 15
setblock ~57 ~34 ~111 concrete 15
setblock ~58 ~34 ~106 obsidian
setblock ~58 ~34 ~108 obsidian
setblock ~59 ~34 ~103 concrete 15
setblock ~59 ~34 ~104 obsidian
setblock ~59 ~34 ~105 concrete 15
fill ~60 ~34 ~75 ~61 ~34 ~75 concrete 15
setblock ~60 ~34 ~76 coal_block
fill ~60 ~34 ~77 ~61 ~34 ~77 concrete 15
fill ~60 ~34 ~78 ~61 ~34 ~78 concrete 15
setblock ~60 ~34 ~102 concrete 15
fill ~61 ~34 ~72 ~62 ~34 ~72 concrete 15
fill ~61 ~34 ~73 ~61 ~34 ~85 concrete 15
setblock ~61 ~34 ~97 concrete 15
setblock ~61 ~34 ~99 concrete 15
fill ~62 ~34 ~86 ~62 ~34 ~93 concrete 15
setblock ~62 ~34 ~94 obsidian
fill ~62 ~34 ~95 ~62 ~39 ~95 concrete 15
setblock ~63 ~34 ~71 concrete 15
setblock ~64 ~34 ~70 concrete 15
setblock ~65 ~34 ~69 concrete 15
setblock ~66 ~34 ~68 concrete 15
fill ~67 ~34 ~65 ~67 ~34 ~66 concrete 15
setblock ~68 ~34 ~64 concrete 15
fill ~69 ~34 ~61 ~69 ~34 ~62 concrete 15
setblock ~70 ~34 ~58 obsidian
setblock ~71 ~34 ~57 concrete 15
setblock ~72 ~34 ~53 concrete 15
fill ~72 ~34 ~55 ~72 ~36 ~55 concrete 15
setblock ~73 ~34 ~50 wool 15
setblock ~73 ~34 ~51 concrete 15
setblock ~73 ~34 ~52 obsidian
fill ~74 ~34 ~48 ~74 ~35 ~48 wool 15
setblock ~74 ~34 ~49 concrete 15
setblock ~75 ~34 ~46 obsidian
setblock ~75 ~34 ~47 concrete 15
setblock ~76 ~34 ~43 obsidian
fill ~76 ~34 ~44 ~76 ~35 ~44 wool 15
setblock ~77 ~34 ~41 stained_glass 15
fill ~77 ~34 ~42 ~77 ~35 ~42 concrete 15
fill ~13 ~35 ~55 ~13 ~35 ~56 stained_glass 15
fill ~14 ~35 ~57 ~14 ~36 ~57 concrete 15
setblock ~14 ~35 ~58 stained_hardened_clay 7
setblock ~15 ~35 ~59 wool 15
setblock ~15 ~35 ~60 obsidian
setblock ~15 ~35 ~61 wool 15
setblock ~16 ~35 ~62 wool 15
setblock ~16 ~35 ~63 obsidian
fill ~17 ~35 ~64 ~17 ~36 ~64 concrete 15
setblock ~17 ~35 ~65 wool 15
setblock ~18 ~35 ~66 nether_brick
setblock ~18 ~35 ~67 wool 15
setblock ~19 ~35 ~68 concrete 15
setblock ~19 ~35 ~69 wool 15
fill ~19 ~35 ~70 ~19 ~36 ~70 concrete 15
setblock ~20 ~35 ~71 obsidian
setblock ~20 ~35 ~72 wool 15
setblock ~20 ~35 ~73 obsidian
setblock ~21 ~35 ~74 concrete 15
setblock ~21 ~35 ~75 obsidian
setblock ~21 ~35 ~76 concrete 15
setblock ~21 ~35 ~77 obsidian
setblock ~22 ~35 ~78 wool 15
setblock ~22 ~35 ~79 concrete 15
setblock ~22 ~35 ~80 wool 15
setblock ~22 ~35 ~81 concrete 15
setblock ~22 ~35 ~82 wool 15
setblock ~23 ~35 ~83 obsidian
setblock ~23 ~35 ~84 concrete 15
setblock ~23 ~35 ~85 obsidian
setblock ~23 ~35 ~86 concrete 15
setblock ~23 ~35 ~87 obsidian
setblock ~23 ~35 ~88 concrete 15
setblock ~23 ~35 ~89 obsidian
setblock ~23 ~35 ~90 concrete 15
setblock ~24 ~35 ~91 concrete 15
setblock ~24 ~35 ~92 wool 15
setblock ~24 ~35 ~93 obsidian
fill ~24 ~35 ~94 ~24 ~36 ~94 wool 15
fill ~24 ~35 ~95 ~24 ~35 ~96 wool 15
setblock ~25 ~35 ~97 wool 15
setblock ~25 ~35 ~98 obsidian
setblock ~25 ~35 ~99 stained_hardened_clay 7
setblock ~25 ~35 ~100 concrete 15
setblock ~26 ~35 ~101 wool 15
setblock ~26 ~35 ~102 concrete 7
setblock ~26 ~35 ~103 wool 15
setblock ~27 ~35 ~104 obsidian
setblock ~27 ~35 ~105 wool 15
setblock ~27 ~35 ~106 concrete 15
setblock ~28 ~35 ~107 wool 15
setblock ~28 ~35 ~108 nether_brick
setblock ~29 ~35 ~111 wool 15
setblock ~29 ~35 ~112 obsidian
fill ~30 ~35 ~115 ~30 ~36 ~115 wool 15
setblock ~31 ~35 ~116 obsidian
setblock ~31 ~35 ~117 concrete 7
setblock ~32 ~35 ~118 stained_hardened_clay 7
fill ~32 ~35 ~119 ~32 ~36 ~119 obsidian
setblock ~33 ~35 ~120 concrete 15
setblock ~33 ~35 ~121 wool 15
fill ~35 ~35 ~118 ~35 ~36 ~118 concrete 15
setblock ~35 ~35 ~123 wool 15
setblock ~36 ~35 ~119 concrete 15
fill ~36 ~35 ~123 ~36 ~36 ~123 concrete 15
setblock ~37 ~35 ~120 concrete 15
setblock ~38 ~35 ~121 concrete 15
setblock ~38 ~35 ~124 wool 15
fill ~39 ~35 ~122 ~46 ~35 ~122 concrete 15
setblock ~40 ~35 ~124 wool 15
setblock ~42 ~35 ~124 obsidian
setblock ~43 ~35 ~125 coal_block
setblock ~44 ~35 ~124 obsidian
setblock ~46 ~35 ~124 obsidian
fill ~47 ~35 ~121 ~48 ~35 ~121 concrete 15
setblock ~48 ~35 ~124 obsidian
fill ~49 ~35 ~119 ~49 ~35 ~120 concrete 15
setblock ~52 ~35 ~122 obsidian
setblock ~53 ~35 ~121 coal_block
setblock ~54 ~35 ~118 wool 15
setblock ~55 ~35 ~117 obsidian
setblock ~56 ~35 ~113 obsidian
setblock ~56 ~35 ~114 wool 15
setblock ~57 ~35 ~111 obsidian
fill ~57 ~35 ~112 ~57 ~39 ~112 concrete 15
setblock ~58 ~35 ~108 wool 15
fill ~58 ~35 ~109 ~58 ~36 ~109 concrete 15
setblock ~59 ~35 ~103 obsidian
fill ~59 ~35 ~104 ~59 ~37 ~104 concrete 15
setblock ~59 ~35 ~105 obsidian
fill ~59 ~35 ~106 ~59 ~40 ~106 concrete 15
setblock ~60 ~35 ~102 wool 15
setblock ~61 ~35 ~97 wool 15
setblock ~61 ~35 ~99 obsidian
setblock ~62 ~35 ~73 concrete 15
setblock ~62 ~35 ~74 wool 15
setblock ~62 ~35 ~75 concrete 15
setblock ~62 ~35 ~76 wool 15
setblock ~62 ~35 ~77 concrete 15
setblock ~62 ~35 ~78 wool 15
setblock ~62 ~35 ~79 concrete 15
setblock ~62 ~35 ~80 wool 15
setblock ~62 ~35 ~81 concrete 15
setblock ~62 ~35 ~82 wool 15
setblock ~62 ~35 ~83 concrete 15
setblock ~62 ~35 ~84 wool 15
setblock ~62 ~35 ~85 concrete 15
setblock ~62 ~35 ~91 concrete 15
setblock ~62 ~35 ~92 obsidian
setblock ~62 ~35 ~93 concrete 15
setblock ~62 ~35 ~94 wool 15
setblock ~62 ~35 ~96 wool 15
setblock ~63 ~35 ~72 concrete 15
setblock ~63 ~35 ~73 obsidian
setblock ~63 ~35 ~74 concrete 15
setblock ~63 ~35 ~75 coal_block
setblock ~63 ~35 ~85 obsidian
setblock ~63 ~35 ~86 concrete 15
setblock ~63 ~35 ~87 obsidian
fill ~63 ~35 ~88 ~63 ~36 ~88 concrete 15
setblock ~63 ~35 ~89 obsidian
fill ~63 ~35 ~90 ~63 ~36 ~90 concrete 15
setblock ~64 ~35 ~71 concrete 15
setblock ~65 ~35 ~70 concrete 15
setblock ~66 ~35 ~68 obsidian
fill ~66 ~35 ~69 ~66 ~36 ~69 concrete 15
setblock ~67 ~35 ~66 concrete 15
setblock ~67 ~35 ~67 coal_block
setblock ~68 ~35 ~64 obsidian
fill ~68 ~35 ~65 ~68 ~36 ~65 concrete 15
setblock ~69 ~35 ~62 concrete 15
setblock ~69 ~35 ~63 obsidian
setblock ~70 ~35 ~60 wool 15
fill ~70 ~35 ~61 ~70 ~37 ~61 concrete 15
setblock ~71 ~35 ~57 obsidian
fill ~71 ~35 ~58 ~71 ~37 ~58 concrete 15
setblock ~72 ~35 ~56 wool 15
setblock ~73 ~35 ~51 wool 15
setblock ~73 ~35 ~52 concrete 15
setblock ~73 ~35 ~53 wool 15
setblock ~74 ~35 ~49 obsidian
setblock ~74 ~35 ~50 wool 15
setblock ~75 ~35 ~47 wool 15
setblock ~76 ~35 ~43 wool 15
setblock ~76 ~35 ~45 obsidian
setblock ~76 ~35 ~46 wool 15
fill ~77 ~35 ~39 ~77 ~35 ~40 stained_glass 15
setblock ~77 ~35 ~41 obsidian
setblock ~12 ~36 ~52 stained_glass 15
setblock ~13 ~36 ~53 concrete 15
setblock ~13 ~36 ~54 wool 15
fill ~13 ~36 ~55 ~13 ~36 ~56 obsidian
fill ~14 ~36 ~58 ~14 ~37 ~58 wool 15
fill ~14 ~36 ~59 ~14 ~37 ~59 obsidian
setblock ~15 ~36 ~60 wool 15
setblock ~15 ~36 ~61 obsidian
setblock ~16 ~36 ~62 obsidian
setblock ~16 ~36 ~63 concrete 15
setblock ~17 ~36 ~65 concrete 15
setblock ~17 ~36 ~66 obsidian
setblock ~18 ~36 ~67 concrete 15
setblock ~18 ~36 ~68 wool 15
setblock ~18 ~36 ~69 concrete 15
fill ~19 ~36 ~71 ~19 ~36 ~72 concrete 15
setblock ~20 ~36 ~73 concrete 15
setblock ~20 ~36 ~74 obsidian
fill ~20 ~36 ~75 ~20 ~36 ~77 concrete 15
fill ~21 ~36 ~78 ~21 ~36 ~81 concrete 15
setblock ~22 ~36 ~82 obsidian
fill ~22 ~36 ~83 ~22 ~36 ~85 concrete 15
setblock ~22 ~36 ~86 obsidian
setblock ~22 ~36 ~87 concrete 15
setblock ~22 ~36 ~88 obsidian
setblock ~23 ~36 ~89 concrete 15
setblock ~23 ~36 ~90 obsidian
setblock ~23 ~36 ~91 concrete 15
setblock ~23 ~36 ~92 obsidian
setblock ~23 ~36 ~93 concrete 15
setblock ~24 ~36 ~95 concrete 15
fill ~24 ~36 ~96 ~24 ~38 ~96 wool 15
setblock ~24 ~36 ~97 obsidian
setblock ~25 ~36 ~98 wool 15
setblock ~25 ~36 ~99 obsidian
setblock ~25 ~36 ~100 wool 15
setblock ~25 ~36 ~101 obsidian
setblock ~26 ~36 ~102 wool 15
setblock ~26 ~36 ~103 obsidian
setblock ~26 ~36 ~104 wool 15
setblock ~27 ~36 ~105 concrete 15
setblock ~27 ~36 ~106 wool 15
setblock ~27 ~36 ~107 concrete 15
setblock ~28 ~36 ~108 wool 15
fill ~28 ~36 ~110 ~28 ~39 ~110 wool 15
setblock ~29 ~36 ~111 concrete 15
fill ~29 ~36 ~112 ~29 ~38 ~112 wool 15
setblock ~29 ~36 ~113 obsidian
setblock ~31 ~36 ~116 wool 15
setblock ~31 ~36 ~117 concrete 15
setblock ~32 ~36 ~118 wool 15
fill ~33 ~36 ~115 ~33 ~37 ~115 concrete 15
setblock ~33 ~36 ~120 obsidian
setblock ~33 ~36 ~121 concrete 15
fill ~34 ~36 ~116 ~34 ~36 ~117 concrete 15
fill ~35 ~36 ~119 ~35 ~37 ~119 concrete 15
setblock ~35 ~36 ~123 concrete 15
fill ~36 ~36 ~120 ~36 ~37 ~120 concrete 15
fill ~37 ~36 ~121 ~37 ~37 ~121 concrete 15
fill ~38 ~36 ~122 ~39 ~36 ~122 concrete 15
setblock ~38 ~36 ~124 concrete 15
fill ~40 ~36 ~123 ~45 ~36 ~123 concrete 15
fill ~40 ~36 ~124 ~40 ~36 ~123 concrete 15
fill ~41 ~36 ~125 ~45 ~36 ~125 concrete 15
fill ~46 ~36 ~122 ~47 ~36 ~122 concrete 15
setblock ~46 ~36 ~124 concrete 15
setblock ~47 ~36 ~125 concrete 15
setblock ~48 ~36 ~121 concrete 15
setblock ~48 ~36 ~124 concrete 15
setblock ~49 ~36 ~120 concrete 15
setblock ~50 ~36 ~119 concrete 15
fill ~51 ~36 ~117 ~51 ~36 ~118 concrete 15
fill ~52 ~36 ~116 ~52 ~37 ~116 concrete 15
setblock ~52 ~36 ~122 concrete 15
setblock ~53 ~36 ~121 concrete 15
setblock ~54 ~36 ~120 concrete 15
fill ~55 ~36 ~117 ~55 ~38 ~117 concrete 15
fill ~55 ~36 ~118 ~55 ~42 ~118 concrete 15
fill ~56 ~36 ~114 ~56 ~37 ~114 obsidian
fill ~56 ~36 ~116 ~56 ~37 ~116 obsidian
setblock ~57 ~36 ~111 concrete 15
setblock ~57 ~36 ~113 concrete 15
setblock ~58 ~36 ~108 obsidian
setblock ~59 ~36 ~105 concrete 15
setblock ~60 ~36 ~100 obsidian
fill ~60 ~36 ~102 ~60 ~38 ~102 obsidian
setblock ~60 ~36 ~103 concrete 15
setblock ~61 ~36 ~97 concrete 15
setblock ~61 ~36 ~99 concrete 15
setblock ~62 ~36 ~94 concrete 15
setblock ~62 ~36 ~96 concrete 15
fill ~63 ~36 ~76 ~64 ~36 ~76 concrete 15
fill ~63 ~36 ~77 ~63 ~36 ~84 concrete 15
setblock ~63 ~36 ~89 concrete 15
fill ~63 ~36 ~91 ~63 ~36 ~93 concrete 15
fill ~64 ~36 ~72 ~65 ~36 ~72 concrete 15
fill ~64 ~36 ~73 ~65 ~36 ~73 concrete 15
fill ~64 ~36 ~74 ~64 ~36 ~76 concrete 15
fill ~64 ~36 ~84 ~64 ~36 ~87 concrete 15
setblock ~65 ~36 ~71 concrete 15
setblock ~66 ~36 ~70 concrete 15
fill ~67 ~36 ~67 ~67 ~36 ~68 concrete 15
setblock ~68 ~36 ~66 concrete 15
fill ~69 ~36 ~63 ~69 ~36 ~64 concrete 15
setblock ~70 ~36 ~60 obsidian
setblock ~70 ~36 ~62 obsidian
setblock ~71 ~36 ~57 concrete 15
setblock ~71 ~36 ~59 concrete 15
setblock ~72 ~36 ~56 obsidian
setblock ~73 ~36 ~52 obsidian
fill ~73 ~36 ~53 ~73 ~36 ~54 concrete 15
setblock ~74 ~36 ~49 concrete 15
setblock ~74 ~36 ~50 obsidian
fill ~74 ~36 ~51 ~74 ~38 ~51 concrete 15
setblock ~75 ~36 ~47 concrete 15
setblock ~75 ~36 ~48 obsidian
fill ~76 ~36 ~43 ~76 ~36 ~44 obsidian
setblock ~76 ~36 ~45 concrete 15
setblock ~76 ~36 ~46 obsidian
setblock ~77 ~36 ~37 stained_glass 15
fill ~77 ~36 ~38 ~77 ~37 ~38 concrete 15
fill ~77 ~36 ~39 ~77 ~36 ~38 concrete 15
setblock ~77 ~36 ~40 wool 15
setblock ~77 ~36 ~41 concrete 15
setblock ~77 ~36 ~42 obsidian
setblock ~11 ~37 ~49 stained_glass 15
fill ~12 ~37 ~50 ~12 ~37 ~51 stained_glass 15
setblock ~12 ~37 ~52 concrete 7
fill ~12 ~37 ~53 ~12 ~39 ~53 wool 15
fill ~12 ~37 ~54 ~12 ~40 ~54 wool 15
setblock ~13 ~37 ~55 stained_hardened_clay 7
setblock ~13 ~37 ~56 obsidian
setblock ~13 ~37 ~57 wool 15
fill ~14 ~37 ~60 ~14 ~39 ~60 wool 15
setblock ~15 ~37 ~61 wool 15
fill ~15 ~37 ~62 ~15 ~38 ~62 concrete 15
setblock ~16 ~37 ~63 obsidian
fill ~16 ~37 ~64 ~16 ~38 ~64 wool 15
fill ~16 ~37 ~65 ~16 ~37 ~64 wool 15
setblock ~17 ~37 ~66 concrete 15
setblock ~17 ~37 ~67 wool 15
fill ~17 ~37 ~68 ~17 ~38 ~68 obsidian
fill ~18 ~37 ~69 ~18 ~37 ~71 wool 15
setblock ~19 ~37 ~72 concrete 15
setblock ~19 ~37 ~73 wool 15
setblock ~19 ~37 ~74 concrete 15
setblock ~19 ~37 ~75 wool 15
setblock ~20 ~37 ~76 wool 15
setblock ~20 ~37 ~77 obsidian
setblock ~20 ~37 ~78 wool 15
fill ~20 ~37 ~79 ~20 ~38 ~79 concrete 15
setblock ~20 ~37 ~80 wool 15
setblock ~21 ~37 ~81 wool 15
setblock ~21 ~37 ~82 concrete 15
setblock ~21 ~37 ~83 wool 15
setblock ~21 ~37 ~84 concrete 15
setblock ~21 ~37 ~85 wool 15
setblock ~22 ~37 ~86 wool 15
setblock ~22 ~37 ~87 obsidian
fill ~22 ~37 ~88 ~22 ~37 ~89 wool 15
setblock ~22 ~37 ~90 stained_hardened_clay 7
setblock ~22 ~37 ~91 obsidian
setblock ~23 ~37 ~92 concrete 15
setblock ~23 ~37 ~93 wool 15
setblock ~23 ~37 ~94 concrete 15
setblock ~24 ~37 ~95 wool 15
fill ~24 ~37 ~97 ~24 ~39 ~97 wool 15
fill ~24 ~37 ~98 ~24 ~41 ~98 concrete 7
setblock ~25 ~37 ~99 concrete 7
setblock ~25 ~37 ~100 obsidian
setblock ~25 ~37 ~101 concrete 7
setblock ~26 ~37 ~102 nether_brick
setblock ~26 ~37 ~103 wool 15
setblock ~26 ~37 ~104 nether_brick
setblock ~27 ~37 ~105 wool 15
setblock ~27 ~37 ~106 obsidian
setblock ~27 ~37 ~107 concrete 7
setblock ~28 ~37 ~108 concrete 7
setblock ~29 ~37 ~111 concrete 7
setblock ~29 ~37 ~113 concrete 7
fill ~30 ~37 ~115 ~30 ~37 ~116 concrete 7
fill ~31 ~37 ~110 ~31 ~38 ~110 concrete 15
setblock ~31 ~37 ~117 wool 15
fill ~31 ~37 ~118 ~31 ~38 ~118 obsidian
setblock ~32 ~37 ~112 coal_block
setblock ~32 ~37 ~113 concrete 15
setblock ~32 ~37 ~114 coal_block
fill ~32 ~37 ~119 ~32 ~37 ~120 wool 15
fill ~33 ~37 ~116 ~33 ~38 ~116 concrete 15
setblock ~33 ~37 ~121 wool 15
fill ~34 ~37 ~117 ~34 ~37 ~118 concrete 15
setblock ~35 ~37 ~123 wool 15
setblock ~36 ~37 ~123 obsidian
fill ~38 ~37 ~122 ~39 ~37 ~122 concrete 15
setblock ~38 ~37 ~124 wool 15
setblock ~39 ~37 ~125 obsidian
fill ~40 ~37 ~123 ~46 ~37 ~123 concrete 15
fill ~40 ~37 ~125 ~40 ~39 ~125 concrete 15
setblock ~41 ~37 ~125 obsidian
setblock ~42 ~37 ~125 concrete 15
fill ~43 ~37 ~126 ~43 ~42 ~126 concrete 15
setblock ~44 ~37 ~125 concrete 15
setblock ~45 ~37 ~125 obsidian
fill ~46 ~37 ~125 ~46 ~39 ~125 concrete 15
fill ~47 ~37 ~122 ~48 ~37 ~122 concrete 15
setblock ~47 ~37 ~125 coal_block
setblock ~48 ~37 ~124 obsidian
fill ~49 ~37 ~121 ~49 ~39 ~121 concrete 15
fill ~50 ~37 ~120 ~50 ~38 ~120 concrete 15
fill ~51 ~37 ~118 ~51 ~37 ~119 concrete 15
setblock ~51 ~37 ~123 obsidian
fill ~52 ~37 ~117 ~52 ~38 ~117 concrete 15
setblock ~52 ~37 ~122 obsidian
fill ~53 ~37 ~114 ~53 ~37 ~115 concrete 15
setblock ~53 ~37 ~121 obsidian
setblock ~54 ~37 ~120 wool 15
setblock ~57 ~37 ~111 obsidian
setblock ~57 ~37 ~113 obsidian
setblock ~58 ~37 ~108 wool 15
setblock ~58 ~37 ~109 obsidian
setblock ~58 ~37 ~110 wool 15
setblock ~59 ~37 ~105 obsidian
setblock ~59 ~37 ~107 obsidian
fill ~60 ~37 ~103 ~60 ~38 ~103 obsidian
setblock ~61 ~37 ~99 obsidian
fill ~61 ~37 ~100 ~61 ~41 ~100 concrete 15
setblock ~62 ~37 ~94 wool 15
setblock ~62 ~37 ~96 wool 15
fill ~62 ~37 ~97 ~62 ~40 ~97 concrete 15
setblock ~63 ~37 ~91 obsidian
fill ~63 ~37 ~92 ~63 ~39 ~92 concrete 15
setblock ~63 ~37 ~93 obsidian
setblock ~64 ~37 ~77 concrete 15
setblock ~64 ~37 ~78 wool 15
setblock ~64 ~37 ~79 concrete 15
setblock ~64 ~37 ~80 wool 15
setblock ~64 ~37 ~81 concrete 15
setblock ~64 ~37 ~82 obsidian
setblock ~64 ~37 ~83 concrete 15
setblock ~64 ~37 ~84 wool 15
setblock ~64 ~37 ~85 concrete 15
setblock ~64 ~37 ~86 wool 15
setblock ~64 ~37 ~87 concrete 15
setblock ~64 ~37 ~88 wool 15
fill ~64 ~37 ~89 ~64 ~39 ~89 concrete 15
setblock ~64 ~37 ~90 obsidian
setblock ~65 ~37 ~74 concrete 15
setblock ~65 ~37 ~75 obsidian
setblock ~65 ~37 ~76 concrete 15
setblock ~65 ~37 ~77 obsidian
setblock ~65 ~37 ~78 concrete 15
setblock ~65 ~37 ~83 obsidian
setblock ~66 ~37 ~70 wool 15
setblock ~66 ~37 ~71 concrete 15
setblock ~66 ~37 ~72 wool 15
fill ~66 ~37 ~73 ~66 ~38 ~73 concrete 15
setblock ~67 ~37 ~68 concrete 15
setblock ~67 ~37 ~69 obsidian
setblock ~68 ~37 ~66 obsidian
fill ~68 ~37 ~67 ~68 ~38 ~67 concrete 15
setblock ~69 ~37 ~64 concrete 15
setblock ~69 ~37 ~65 obsidian
setblock ~70 ~37 ~62 wool 15
fill ~70 ~37 ~63 ~70 ~38 ~63 concrete 15
setblock ~71 ~37 ~59 wool 15
fill ~71 ~37 ~60 ~71 ~38 ~60 concrete 15
setblock ~72 ~37 ~56 wool 15
fill ~72 ~37 ~57 ~72 ~39 ~57 concrete 15
setblock ~73 ~37 ~52 concrete 15
setblock ~73 ~37 ~53 wool 15
setblock ~73 ~37 ~54 concrete 15
setblock ~73 ~37 ~55 wool 15
setblock ~74 ~37 ~49 obsidian
setblock ~74 ~37 ~50 wool 15
setblock ~75 ~37 ~47 wool 15
fill ~75 ~37 ~48 ~75 ~39 ~48 concrete 15
fill ~76 ~37 ~43 ~76 ~37 ~44 wool 15
setblock ~76 ~37 ~45 obsidian
fill ~76 ~37 ~46 ~76 ~39 ~46 wool 15
setblock ~77 ~37 ~35 stained_glass 15
setblock ~77 ~37 ~36 concrete 15
setblock ~77 ~37 ~37 wool 15
setblock ~77 ~37 ~39 wool 15
setblock ~77 ~37 ~40 concrete 15
setblock ~77 ~37 ~41 wool 15
setblock ~77 ~37 ~42 concrete 15
fill ~9 ~38 ~36 ~9 ~38 ~38 stained_glass 15
setblock ~9 ~38 ~39 concrete 15
fill ~10 ~38 ~41 ~10 ~38 ~42 stained_glass 15
setblock ~10 ~38 ~43 concrete 15
fill ~10 ~38 ~44 ~10 ~39 ~44 wool 15
fill ~10 ~38 ~45 ~10 ~39 ~45 wool 15
fill ~10 ~38 ~46 ~10 ~38 ~44 wool 15
setblock ~11 ~38 ~47 stained_glass 15
setblock ~11 ~38 ~48 obsidian
setblock ~11 ~38 ~49 concrete 15
fill ~11 ~38 ~50 ~11 ~39 ~50 obsidian
setblock ~12 ~38 ~51 obsidian
fill ~12 ~38 ~52 ~12 ~39 ~52 wool 15
setblock ~12 ~38 ~55 obsidian
setblock ~13 ~38 ~56 wool 15
fill ~13 ~38 ~57 ~13 ~38 ~58 obsidian
setblock ~14 ~38 ~59 concrete 15
setblock ~15 ~38 ~61 concrete 15
setblock ~15 ~38 ~63 concrete 15
setblock ~16 ~38 ~65 obsidian
fill ~16 ~38 ~66 ~16 ~39 ~66 wool 15
fill ~16 ~38 ~67 ~16 ~39 ~67 concrete 15
setblock ~17 ~38 ~69 concrete 15
setblock ~17 ~38 ~70 obsidian
setblock ~18 ~38 ~71 concrete 15
setblock ~18 ~38 ~72 obsidian
setblock ~18 ~38 ~73 concrete 15
setblock ~18 ~38 ~74 obsidian
setblock ~19 ~38 ~75 concrete 15
setblock ~19 ~38 ~76 obsidian
fill ~19 ~38 ~77 ~19 ~38 ~78 concrete 15
setblock ~20 ~38 ~80 obsidian
setblock ~20 ~38 ~81 concrete 15
fill ~20 ~38 ~82 ~20 ~39 ~82 wool 15
setblock ~21 ~38 ~83 concrete 15
setblock ~21 ~38 ~84 obsidian
setblock ~21 ~38 ~85 concrete 15
setblock ~21 ~38 ~86 obsidian
fill ~21 ~38 ~87 ~21 ~38 ~88 concrete 15
setblock ~22 ~38 ~89 concrete 15
setblock ~22 ~38 ~90 obsidian
setblock ~22 ~38 ~91 concrete 15
fill ~22 ~38 ~92 ~22 ~40 ~92 wool 15
setblock ~23 ~38 ~93 concrete 15
setblock ~23 ~38 ~94 wool 15
setblock ~23 ~38 ~95 obsidian
fill ~24 ~38 ~99 ~24 ~42 ~99 wool 15
setblock ~25 ~38 ~100 wool 15
setblock ~25 ~38 ~101 obsidian
setblock ~25 ~38 ~102 wool 15
setblock ~26 ~38 ~103 obsidian
fill ~26 ~38 ~104 ~26 ~40 ~104 wool 15
setblock ~26 ~38 ~105 obsidian
fill ~27 ~38 ~106 ~27 ~39 ~106 wool 15
fill ~27 ~38 ~107 ~27 ~38 ~108 wool 15
fill ~28 ~38 ~109 ~28 ~39 ~109 obsidian
fill ~28 ~38 ~111 ~28 ~39 ~111 concrete 7
fill ~29 ~38 ~104 ~29 ~39 ~104 concrete 15
setblock ~29 ~38 ~113 obsidian
setblock ~29 ~38 ~114 wool 15
fill ~30 ~38 ~106 ~30 ~38 ~109 concrete 15
fill ~30 ~38 ~115 ~30 ~39 ~115 wool 15
setblock ~30 ~38 ~116 concrete 7
fill ~31 ~38 ~111 ~31 ~38 ~113 concrete 15
setblock ~31 ~38 ~117 concrete 15
fill ~32 ~38 ~114 ~32 ~38 ~115 concrete 15
setblock ~32 ~38 ~119 obsidian
fill ~32 ~38 ~120 ~32 ~39 ~120 wool 15
fill ~33 ~38 ~117 ~33 ~39 ~117 concrete 15
setblock ~33 ~38 ~121 concrete 15
fill ~34 ~38 ~118 ~34 ~38 ~119 concrete 15
fill ~35 ~38 ~120 ~35 ~39 ~120 concrete 15
fill ~35 ~38 ~123 ~36 ~38 ~123 concrete 15
fill ~36 ~38 ~121 ~36 ~39 ~121 concrete 15
fill ~37 ~38 ~122 ~38 ~38 ~122 concrete 15
setblock ~38 ~38 ~124 obsidian
fill ~39 ~38 ~123 ~41 ~38 ~123 concrete 15
setblock ~39 ~38 ~125 concrete 15
setblock ~41 ~38 ~125 concrete 15
fill ~42 ~38 ~124 ~43 ~38 ~124 concrete 15
setblock ~42 ~38 ~126 concrete 15
fill ~44 ~38 ~123 ~46 ~38 ~123 concrete 15
setblock ~44 ~38 ~126 concrete 15
setblock ~45 ~38 ~125 concrete 15
fill ~47 ~38 ~122 ~48 ~38 ~122 concrete 15
setblock ~47 ~38 ~125 concrete 15
setblock ~48 ~38 ~124 concrete 15
setblock ~51 ~38 ~119 concrete 15
fill ~51 ~38 ~123 ~51 ~40 ~123 concrete 15
fill ~52 ~38 ~118 ~52 ~39 ~118 concrete 15
setblock ~52 ~38 ~122 concrete 15
fill ~53 ~38 ~115 ~53 ~38 ~116 concrete 15
setblock ~53 ~38 ~121 concrete 15
fill ~54 ~38 ~111 ~54 ~38 ~114 concrete 15
setblock ~54 ~38 ~120 concrete 15
fill ~55 ~38 ~109 ~55 ~38 ~110 concrete 15
setblock ~56 ~38 ~116 concrete 15
fill ~57 ~38 ~113 ~57 ~38 ~114 concrete 15
fill ~58 ~38 ~108 ~58 ~38 ~109 concrete 15
setblock ~58 ~38 ~110 obsidian
fill ~58 ~38 ~111 ~58 ~44 ~111 concrete 15
setblock ~59 ~38 ~105 concrete 15
fill ~59 ~38 ~107 ~59 ~40 ~107 concrete 15
setblock ~60 ~38 ~104 concrete 15
setblock ~61 ~38 ~99 concrete 15
setblock ~61 ~38 ~101 concrete 15
setblock ~62 ~38 ~96 obsidian
fill ~63 ~38 ~93 ~63 ~38 ~94 concrete 15
fill ~64 ~38 ~90 ~64 ~38 ~91 concrete 15
fill ~65 ~38 ~79 ~66 ~38 ~79 concrete 15
fill ~65 ~38 ~80 ~65 ~38 ~88 concrete 15
fill ~66 ~38 ~74 ~66 ~38 ~77 concrete 15
setblock ~66 ~38 ~78 obsidian
fill ~67 ~38 ~70 ~67 ~38 ~72 concrete 15
setblock ~68 ~38 ~68 coal_block
fill ~68 ~38 ~69 ~68 ~39 ~69 concrete 15
fill ~69 ~38 ~65 ~69 ~38 ~66 concrete 15
setblock ~70 ~38 ~64 concrete 15
setblock ~71 ~38 ~59 concrete 15
fill ~71 ~38 ~61 ~71 ~38 ~62 concrete 15
fill ~72 ~38 ~58 ~72 ~39 ~58 obsidian
setblock ~73 ~38 ~54 obsidian
fill ~73 ~38 ~55 ~73 ~38 ~56 concrete 15
setblock ~74 ~38 ~50 obsidian
fill ~74 ~38 ~52 ~74 ~40 ~52 wool 15
setblock ~74 ~38 ~53 concrete 15
setblock ~75 ~38 ~47 concrete 15
setblock ~75 ~38 ~49 concrete 15
setblock ~76 ~38 ~43 concrete 15
setblock ~76 ~38 ~44 obsidian
setblock ~76 ~38 ~45 concrete 15
setblock ~77 ~38 ~33 stained_glass 15
fill ~77 ~38 ~34 ~77 ~39 ~34 concrete 15
fill ~77 ~38 ~35 ~77 ~38 ~34 concrete 15
setblock ~77 ~38 ~36 obsidian
setblock ~77 ~38 ~37 concrete 15
setblock ~77 ~38 ~38 obsidian
setblock ~77 ~38 ~39 concrete 15
setblock ~77 ~38 ~40 obsidian
setblock ~77 ~38 ~41 concrete 15
setblock ~77 ~38 ~42 obsidian
setblock ~9 ~39 ~34 stained_glass 15
setblock ~9 ~39 ~35 wool 15
setblock ~9 ~39 ~36 obsidian
setblock ~9 ~39 ~37 wool 15
setblock ~9 ~39 ~38 concrete 15
setblock ~9 ~39 ~39 wool 15
setblock ~9 ~39 ~40 obsidian
setblock ~9 ~39 ~41 wool 15
fill ~9 ~39 ~42 ~9 ~41 ~42 concrete 15
setblock ~10 ~39 ~43 obsidian
setblock ~10 ~39 ~46 nether_brick
setblock ~10 ~39 ~47 wool 15
setblock ~11 ~39 ~48 wool 15
setblock ~11 ~39 ~49 stained_hardened_clay 7
setblock ~11 ~39 ~51 wool 15
fill ~12 ~39 ~55 ~12 ~40 ~55 wool 15
setblock ~12 ~39 ~56 concrete 7
setblock ~13 ~39 ~57 wool 15
fill ~13 ~39 ~58 ~13 ~40 ~58 concrete 15
setblock ~14 ~39 ~59 obsidian
setblock ~14 ~39 ~61 obsidian
setblock ~14 ~39 ~62 wool 15
setblock ~15 ~39 ~63 obsidian
setblock ~15 ~39 ~64 concrete 15
setblock ~15 ~39 ~65 wool 15
setblock ~16 ~39 ~68 wool 15
setblock ~16 ~39 ~69 obsidian
setblock ~17 ~39 ~70 concrete 15
setblock ~17 ~39 ~71 wool 15
setblock ~17 ~39 ~72 concrete 15
setblock ~18 ~39 ~73 obsidian
setblock ~18 ~39 ~74 wool 15
setblock ~18 ~39 ~75 obsidian
fill ~18 ~39 ~76 ~18 ~40 ~76 wool 15
setblock ~18 ~39 ~77 concrete 15
setblock ~19 ~39 ~78 concrete 15
setblock ~19 ~39 ~79 wool 15
fill ~19 ~39 ~80 ~19 ~40 ~80 concrete 15
setblock ~20 ~39 ~81 obsidian
setblock ~20 ~39 ~83 obsidian
fill ~20 ~39 ~84 ~20 ~40 ~84 wool 15
fill ~20 ~39 ~85 ~20 ~40 ~85 obsidian
setblock ~21 ~39 ~86 concrete 15
setblock ~21 ~39 ~87 wool 15
setblock ~21 ~39 ~88 concrete 15
setblock ~21 ~39 ~89 wool 15
setblock ~22 ~39 ~90 wool 15
setblock ~22 ~39 ~91 obsidian
setblock ~23 ~39 ~93 concrete 7
setblock ~23 ~39 ~94 obsidian
setblock ~23 ~39 ~95 wool 15
fill ~23 ~39 ~96 ~23 ~40 ~96 obsidian
setblock ~25 ~39 ~100 obsidian
setblock ~25 ~39 ~101 stained_hardened_clay 7
fill ~25 ~39 ~102 ~25 ~41 ~102 obsidian
setblock ~26 ~39 ~103 wool 15
fill ~26 ~39 ~105 ~26 ~42 ~105 wool 15
fill ~27 ~39 ~95 ~27 ~39 ~98 concrete 15
setblock ~27 ~39 ~107 concrete 7
setblock ~27 ~39 ~108 concrete 15
fill ~28 ~39 ~99 ~28 ~39 ~103 concrete 15
fill ~29 ~39 ~105 ~29 ~39 ~107 concrete 15
setblock ~29 ~39 ~112 obsidian
setblock ~29 ~39 ~113 stained_hardened_clay 11
setblock ~29 ~39 ~114 blue_glazed_terracotta
fill ~30 ~39 ~108 ~30 ~39 ~111 concrete 15
fill ~30 ~39 ~116 ~30 ~40 ~116 wool 15
fill ~31 ~39 ~112 ~31 ~39 ~114 concrete 15
setblock ~31 ~39 ~117 wool 15
setblock ~31 ~39 ~118 concrete 15
setblock ~32 ~39 ~115 concrete 15
setblock ~32 ~39 ~116 coal_block
setblock ~32 ~39 ~119 wool 15
setblock ~33 ~39 ~118 concrete 15
setblock ~33 ~39 ~121 wool 15
setblock ~34 ~39 ~119 concrete 15
setblock ~35 ~39 ~123 wool 15
fill ~36 ~39 ~123 ~36 ~41 ~123 concrete 15
fill ~37 ~39 ~122 ~37 ~38 ~122 concrete 15
fill ~38 ~39 ~123 ~39 ~39 ~123 concrete 15
setblock ~38 ~39 ~124 wool 15
setblock ~39 ~39 ~125 obsidian
setblock ~40 ~39 ~124 coal_block
fill ~41 ~39 ~124 ~45 ~39 ~124 concrete 15
fill ~41 ~39 ~126 ~41 ~41 ~126 concrete 15
setblock ~42 ~39 ~126 obsidian
setblock ~44 ~39 ~126 obsidian
fill ~45 ~39 ~126 ~45 ~41 ~126 concrete 15
fill ~46 ~39 ~123 ~47 ~39 ~123 concrete 15
setblock ~47 ~39 ~125 coal_block
setblock ~48 ~39 ~122 concrete 15
fill ~48 ~39 ~125 ~48 ~41 ~125 concrete 15
fill ~50 ~39 ~121 ~50 ~40 ~121 concrete 15
fill ~51 ~39 ~120 ~51 ~40 ~120 concrete 15
fill ~52 ~39 ~119 ~52 ~42 ~119 concrete 15
setblock ~52 ~39 ~122 obsidian
fill ~53 ~39 ~116 ~53 ~39 ~117 concrete 15
setblock ~53 ~39 ~121 obsidian
fill ~54 ~39 ~113 ~54 ~39 ~115 concrete 15
setblock ~54 ~39 ~120 obsidian
fill ~55 ~39 ~110 ~55 ~39 ~112 concrete 15
setblock ~55 ~39 ~119 obsidian
fill ~56 ~39 ~105 ~56 ~39 ~109 concrete 15
setblock ~56 ~39 ~116 obsidian
fill ~56 ~39 ~117 ~56 ~42 ~117 concrete 15
fill ~57 ~39 ~102 ~57 ~40 ~102 concrete 15
fill ~57 ~39 ~103 ~57 ~40 ~103 concrete 15
fill ~57 ~39 ~104 ~57 ~40 ~104 concrete 15
setblock ~57 ~39 ~113 obsidian
fill ~57 ~39 ~114 ~57 ~43 ~114 concrete 15
fill ~58 ~39 ~98 ~58 ~40 ~98 concrete 15
setblock ~58 ~39 ~109 concrete 15
setblock ~58 ~39 ~110 wool 15
fill ~59 ~39 ~94 ~59 ~40 ~94 concrete 15
fill ~59 ~39 ~108 ~59 ~43 ~108 concrete 15
setblock ~60 ~39 ~102 wool 15
fill ~60 ~39 ~103 ~60 ~41 ~103 concrete 15
setblock ~60 ~39 ~104 obsidian
fill ~60 ~39 ~105 ~60 ~43 ~105 concrete 15
setblock ~61 ~39 ~99 obsidian
setblock ~61 ~39 ~101 wool 15
setblock ~62 ~39 ~96 wool 15
setblock ~62 ~39 ~98 wool 15
setblock ~63 ~39 ~93 obsidian
fill ~63 ~39 ~94 ~63 ~42 ~94 concrete 15
fill ~64 ~39 ~90 ~64 ~41 ~90 obsidian
fill ~64 ~39 ~91 ~64 ~43 ~91 concrete 15
setblock ~65 ~39 ~86 concrete 15
setblock ~65 ~39 ~87 obsidian
fill ~65 ~39 ~88 ~65 ~43 ~88 concrete 15
setblock ~66 ~39 ~79 concrete 15
setblock ~66 ~39 ~80 wool 15
setblock ~66 ~39 ~81 concrete 15
setblock ~66 ~39 ~82 wool 15
fill ~66 ~39 ~83 ~66 ~40 ~83 concrete 15
fill ~66 ~39 ~84 ~66 ~40 ~84 obsidian
fill ~66 ~39 ~85 ~66 ~43 ~85 concrete 15
setblock ~67 ~39 ~72 concrete 15
setblock ~67 ~39 ~73 coal_block
setblock ~67 ~39 ~74 concrete 15
setblock ~67 ~39 ~75 obsidian
setblock ~67 ~39 ~76 concrete 15
setblock ~67 ~39 ~77 coal_block
fill ~67 ~39 ~78 ~67 ~40 ~78 concrete 15
setblock ~68 ~39 ~70 obsidian
fill ~68 ~39 ~71 ~68 ~40 ~71 concrete 15
setblock ~69 ~39 ~67 coal_block
fill ~69 ~39 ~68 ~69 ~40 ~68 concrete 15
setblock ~70 ~39 ~64 obsidian
setblock ~70 ~39 ~65 concrete 15
setblock ~70 ~39 ~66 wool 15
setblock ~71 ~39 ~61 obsidian
setblock ~71 ~39 ~62 concrete 15
setblock ~71 ~39 ~63 obsidian
fill ~72 ~39 ~59 ~72 ~40 ~59 concrete 15
setblock ~72 ~39 ~60 wool 15
setblock ~73 ~39 ~55 wool 15
fill ~73 ~39 ~56 ~73 ~40 ~56 concrete 15
setblock ~74 ~39 ~51 obsidian
fill ~74 ~39 ~53 ~74 ~41 ~53 obsidian
setblock ~74 ~39 ~54 wool 15
setblock ~75 ~39 ~47 obsidian
setblock ~75 ~39 ~49 obsidian
fill ~75 ~39 ~50 ~75 ~41 ~50 concrete 15
setblock ~76 ~39 ~44 wool 15
setblock ~76 ~39 ~45 obsidian
fill ~77 ~39 ~30 ~77 ~39 ~31 stained_glass 15
setblock ~77 ~39 ~32 concrete 15
setblock ~77 ~39 ~33 wool 15
setblock ~77 ~39 ~35 wool 15
setblock ~77 ~39 ~36 concrete 15
setblock ~77 ~39 ~37 wool 15
setblock ~77 ~39 ~38 concrete 15
setblock ~77 ~39 ~39 wool 15
setblock ~77 ~39 ~40 concrete 15
setblock ~77 ~39 ~41 wool 15
setblock ~77 ~39 ~42 concrete 15
setblock ~77 ~39 ~43 wool 15
setblock ~8 ~40 ~31 wool 15
setblock ~8 ~40 ~32 stained_glass 15
setblock ~8 ~40 ~33 obsidian
fill ~9 ~40 ~28 ~9 ~40 ~30 stained_glass 15
setblock ~9 ~40 ~34 obsidian
setblock ~9 ~40 ~35 concrete 15
setblock ~9 ~40 ~36 wool 15
setblock ~9 ~40 ~37 obsidian
setblock ~9 ~40 ~38 wool 15
fill ~9 ~40 ~39 ~9 ~40 ~43 concrete 15
setblock ~9 ~40 ~44 obsidian
setblock ~10 ~40 ~45 obsidian
setblock ~10 ~40 ~46 wool 15
setblock ~10 ~40 ~47 obsidian
setblock ~10 ~40 ~48 wool 15
setblock ~10 ~40 ~49 obsidian
setblock ~11 ~40 ~50 wool 15
setblock ~11 ~40 ~51 obsidian
setblock ~11 ~40 ~52 wool 15
setblock ~11 ~40 ~53 obsidian
fill ~12 ~40 ~56 ~12 ~41 ~56 wool 15
setblock ~12 ~40 ~57 concrete 15
setblock ~13 ~40 ~59 concrete 15
setblock ~13 ~40 ~60 obsidian
setblock ~14 ~40 ~61 concrete 15
setblock ~14 ~40 ~62 obsidian
fill ~14 ~40 ~63 ~14 ~41 ~63 concrete 15
setblock ~14 ~40 ~64 obsidian
fill ~15 ~40 ~65 ~15 ~40 ~67 concrete 15
setblock ~16 ~40 ~68 obsidian
setblock ~16 ~40 ~69 concrete 15
setblock ~16 ~40 ~70 obsidian
fill ~16 ~40 ~71 ~16 ~41 ~71 concrete 15
setblock ~17 ~40 ~72 obsidian
setblock ~17 ~40 ~73 concrete 15
setblock ~17 ~40 ~74 obsidian
setblock ~17 ~40 ~75 concrete 15
setblock ~18 ~40 ~77 obsidian
fill ~18 ~40 ~78 ~18 ~41 ~78 wool 15
setblock ~19 ~40 ~79 concrete 15
fill ~19 ~40 ~81 ~19 ~40 ~83 concrete 15
fill ~20 ~40 ~86 ~20 ~42 ~86 wool 15
fill ~20 ~40 ~87 ~20 ~42 ~87 obsidian
setblock ~21 ~40 ~88 obsidian
setblock ~21 ~40 ~89 concrete 15
fill ~21 ~40 ~90 ~21 ~41 ~90 obsidian
setblock ~22 ~40 ~91 concrete 15
fill ~22 ~40 ~93 ~22 ~41 ~93 wool 15
setblock ~23 ~40 ~94 wool 15
setblock ~23 ~40 ~95 concrete 15
setblock ~23 ~40 ~97 concrete 15
setblock ~24 ~40 ~100 wool 15
setblock ~25 ~40 ~101 obsidian
setblock ~25 ~40 ~103 obsidian
fill ~26 ~40 ~91 ~26 ~40 ~96 concrete 15
fill ~26 ~40 ~106 ~26 ~41 ~106 concrete 7
fill ~27 ~40 ~97 ~27 ~40 ~101 concrete 15
setblock ~27 ~40 ~107 concrete 15
setblock ~27 ~40 ~108 obsidian
setblock ~27 ~40 ~109 concrete 15
fill ~28 ~40 ~102 ~28 ~40 ~105 concrete 15
fill ~28 ~40 ~110 ~28 ~41 ~110 concrete 7
fill ~28 ~40 ~111 ~28 ~43 ~111 wool 15
fill ~28 ~40 ~112 ~28 ~40 ~111 wool 15
fill ~29 ~40 ~106 ~29 ~40 ~109 concrete 15
setblock ~29 ~40 ~113 blue_glazed_terracotta
setblock ~29 ~40 ~114 obsidian
fill ~30 ~40 ~110 ~30 ~40 ~112 concrete 15
fill ~30 ~40 ~115 ~31 ~40 ~115 concrete 15
fill ~31 ~40 ~113 ~31 ~40 ~115 concrete 15
setblock ~31 ~40 ~117 concrete 15
setblock ~31 ~40 ~118 wool 15
fill ~32 ~40 ~116 ~32 ~40 ~117 wool 15
fill ~32 ~40 ~119 ~32 ~41 ~119 obsidian
fill ~32 ~40 ~120 ~32 ~40 ~119 obsidian
setblock ~33 ~40 ~118 wool 15
setblock ~33 ~40 ~121 concrete 15
fill ~34 ~40 ~119 ~34 ~40 ~120 wool 15
setblock ~34 ~40 ~122 obsidian
setblock ~35 ~40 ~121 concrete 15
setblock ~35 ~40 ~123 concrete 15
setblock ~36 ~40 ~122 nether_brick
fill ~37 ~40 ~123 ~38 ~40 ~123 concrete 15
fill ~38 ~40 ~125 ~39 ~40 ~125 concrete 15
fill ~39 ~40 ~124 ~46 ~40 ~124 concrete 15
setblock ~40 ~40 ~126 concrete 15
setblock ~42 ~40 ~126 concrete 15
setblock ~44 ~40 ~126 concrete 15
setblock ~46 ~40 ~126 concrete 15
fill ~47 ~40 ~123 ~48 ~40 ~123 concrete 15
fill ~47 ~40 ~125 ~47 ~42 ~125 concrete 15
fill ~49 ~40 ~122 ~49 ~42 ~122 concrete 15
setblock ~52 ~40 ~122 concrete 15
fill ~53 ~40 ~117 ~53 ~41 ~117 concrete 15
fill ~53 ~40 ~118 ~53 ~42 ~118 concrete 15
setblock ~53 ~40 ~121 concrete 15
fill ~54 ~40 ~115 ~54 ~40 ~116 concrete 15
setblock ~54 ~40 ~120 concrete 15
fill ~55 ~40 ~111 ~55 ~40 ~114 concrete 15
setblock ~55 ~40 ~119 concrete 15
fill ~56 ~40 ~107 ~56 ~40 ~110 concrete 15
setblock ~56 ~40 ~116 concrete 15
fill ~57 ~40 ~105 ~57 ~41 ~105 concrete 15
fill ~57 ~40 ~106 ~57 ~41 ~106 concrete 15
setblock ~57 ~40 ~113 concrete 15
setblock ~57 ~40 ~115 concrete 15
fill ~58 ~40 ~99 ~58 ~40 ~101 concrete 15
setblock ~58 ~40 ~110 obsidian
setblock ~58 ~40 ~112 concrete 15
fill ~59 ~40 ~95 ~59 ~40 ~97 concrete 15
fill ~59 ~40 ~109 ~59 ~42 ~109 concrete 15
fill ~60 ~40 ~90 ~60 ~40 ~93 concrete 15
setblock ~60 ~40 ~104 concrete 15
setblock ~61 ~40 ~99 concrete 15
fill ~61 ~40 ~101 ~61 ~40 ~102 concrete 15
setblock ~62 ~40 ~96 concrete 15
setblock ~62 ~40 ~98 obsidian
setblock ~63 ~40 ~93 concrete 15
setblock ~63 ~40 ~95 concrete 15
setblock ~64 ~40 ~92 obsidian
setblock ~65 ~40 ~87 concrete 15
setblock ~65 ~40 ~89 concrete 15
setblock ~66 ~40 ~86 obsidian
setblock ~67 ~40 ~77 concrete 15
fill ~67 ~40 ~79 ~67 ~40 ~82 concrete 15
fill ~68 ~40 ~72 ~68 ~40 ~76 concrete 15
fill ~69 ~40 ~69 ~69 ~40 ~70 concrete 15
fill ~70 ~40 ~66 ~70 ~40 ~67 concrete 15
fill ~71 ~40 ~63 ~71 ~40 ~65 concrete 15
setblock ~72 ~40 ~60 obsidian
fill ~72 ~40 ~61 ~72 ~40 ~62 concrete 15
fill ~73 ~40 ~57 ~73 ~40 ~58 concrete 15
setblock ~74 ~40 ~54 obsidian
fill ~74 ~40 ~55 ~74 ~42 ~55 concrete 15
setblock ~75 ~40 ~49 concrete 15
setblock ~75 ~40 ~51 concrete 15
fill ~76 ~40 ~26 ~76 ~41 ~26 stained_glass 15
setblock ~76 ~40 ~45 concrete 15
setblock ~76 ~40 ~46 obsidian
setblock ~76 ~40 ~47 concrete 15
setblock ~76 ~40 ~48 obsidian
fill ~77 ~40 ~29 ~77 ~40 ~31 concrete 15
setblock ~77 ~40 ~32 obsidian
setblock ~77 ~40 ~33 concrete 15
setblock ~77 ~40 ~34 obsidian
setblock ~77 ~40 ~39 concrete 15
setblock ~77 ~40 ~40 obsidian
setblock ~77 ~40 ~41 concrete 15
setblock ~77 ~40 ~42 obsidian
setblock ~77 ~40 ~43 concrete 15
setblock ~77 ~40 ~44 obsidian
setblock ~78 ~40 ~35 concrete 15
fill ~78 ~40 ~36 ~78 ~42 ~36 wool 15
fill ~78 ~40 ~37 ~78 ~42 ~37 obsidian
fill ~78 ~40 ~38 ~78 ~40 ~37 obsidian
fill ~8 ~41 ~30 ~8 ~45 ~30 wool 15
setblock ~8 ~41 ~31 obsidian
fill ~8 ~41 ~32 ~8 ~44 ~32 wool 15
fill ~8 ~41 ~33 ~8 ~41 ~32 wool 15
setblock ~8 ~41 ~34 stained_hardened_clay 7
setblock ~8 ~41 ~35 wool 15
setblock ~8 ~41 ~36 nether_brick
setblock ~8 ~41 ~37 wool 15
setblock ~8 ~41 ~38 stained_hardened_clay 7
setblock ~8 ~41 ~39 wool 15
setblock ~8 ~41 ~41 obsidian
fill ~9 ~41 ~26 ~9 ~41 ~27 stained_glass 15
setblock ~9 ~41 ~28 concrete 15
setblock ~9 ~41 ~29 wool 15
setblock ~9 ~41 ~40 obsidian
setblock ~9 ~41 ~43 wool 15
setblock ~9 ~41 ~44 concrete 15
setblock ~9 ~41 ~45 wool 15
setblock ~9 ~41 ~46 obsidian
setblock ~9 ~41 ~47 wool 15
setblock ~10 ~41 ~48 concrete 7
fill ~10 ~41 ~49 ~10 ~41 ~50 wool 15
setblock ~11 ~41 ~51 wool 15
setblock ~11 ~41 ~52 concrete 15
fill ~11 ~41 ~53 ~11 ~41 ~54 wool 15
setblock ~11 ~41 ~55 stained_hardened_clay 7
fill ~12 ~41 ~57 ~12 ~41 ~58 wool 15
setblock ~12 ~41 ~59 obsidian
setblock ~13 ~41 ~60 concrete 15
setblock ~13 ~41 ~61 wool 15
fill ~13 ~41 ~62 ~13 ~42 ~62 concrete 15
setblock ~14 ~41 ~64 wool 15
setblock ~14 ~41 ~65 obsidian
setblock ~14 ~41 ~66 wool 15
