fill ~75 ~-3 ~18 ~81 ~-3 ~18 wool 8
fill ~75 ~-3 ~19 ~75 ~-3 ~36 wool 8
setblock ~76 ~-3 ~19 water 0
fill ~76 ~-3 ~20 ~77 ~-3 ~20 wool 8
fill ~76 ~-3 ~22 ~76 ~-3 ~25 stone_stairs 1
fill ~76 ~-3 ~29 ~76 ~-3 ~32 stone_stairs 1
fill ~76 ~-3 ~34 ~77 ~-3 ~34 wool 8
setblock ~76 ~-3 ~35 water 0
fill ~76 ~-3 ~36 ~93 ~-3 ~36 wool 8
setblock ~77 ~-3 ~19 wool 8
setblock ~77 ~-3 ~35 wool 8
fill ~79 ~-3 ~35 ~82 ~-3 ~35 stone_stairs 2
fill ~80 ~-3 ~23 ~83 ~-3 ~23 wool 8
fill ~80 ~-3 ~24 ~80 ~-3 ~31 wool 8
fill ~81 ~-3 ~17 ~81 ~-1 ~17 wool 8
fill ~81 ~-3 ~31 ~88 ~-3 ~31 wool 8
setblock ~82 ~-3 ~17 stone_pressure_plate 0
setblock ~82 ~-3 ~18 iron_door 1
setblock ~82 ~-3 ~19 stone_pressure_plate 0
fill ~82 ~-3 ~25 ~83 ~-3 ~25 wool 8
fill ~82 ~-3 ~26 ~82 ~3 ~26 wool 8
fill ~82 ~-3 ~27 ~82 ~3 ~27 wool 8
fill ~82 ~-3 ~28 ~82 ~3 ~28 wool 8
fill ~82 ~-3 ~29 ~86 ~-3 ~29 wool 8
fill ~83 ~-3 ~18 ~83 ~-1 ~18 wool 8
setblock ~84 ~-3 ~17 stone_pressure_plate 0
setblock ~84 ~-3 ~18 iron_door 1
setblock ~84 ~-3 ~19 stone_pressure_plate 0
setblock ~84 ~-3 ~23 piston_head 4
fill ~84 ~-3 ~27 ~84 ~36 ~27 ladder 2
fill ~84 ~-3 ~28 ~84 ~37 ~28 wool 8
fill ~85 ~-3 ~18 ~85 ~-1 ~18 wool 8
setblock ~85 ~-3 ~23 piston 12
fill ~85 ~-3 ~25 ~86 ~-3 ~25 wool 8
setblock ~86 ~-3 ~17 stone_pressure_plate 0
setblock ~86 ~-3 ~18 iron_door 1
setblock ~86 ~-3 ~19 stone_pressure_plate 0
fill ~86 ~-3 ~23 ~88 ~-3 ~23 wool 8
fill ~86 ~-3 ~26 ~86 ~3 ~26 wool 8
fill ~86 ~-3 ~27 ~86 ~3 ~27 wool 8
fill ~86 ~-3 ~28 ~86 ~3 ~28 wool 8
fill ~86 ~-3 ~35 ~89 ~-3 ~35 stone_stairs 2
fill ~87 ~-3 ~17 ~87 ~-1 ~17 wool 8
fill ~87 ~-3 ~18 ~93 ~-3 ~18 wool 8
fill ~88 ~-3 ~24 ~88 ~-3 ~31 wool 8
fill ~91 ~-3 ~19 ~91 ~-3 ~20 wool 8
fill ~91 ~-3 ~34 ~93 ~-3 ~34 wool 8
fill ~91 ~-3 ~35 ~91 ~-3 ~34 wool 8
setblock ~92 ~-3 ~19 water 0
fill ~92 ~-3 ~20 ~93 ~-3 ~20 wool 8
fill ~92 ~-3 ~22 ~92 ~-3 ~25 stone_stairs 0
fill ~92 ~-3 ~29 ~92 ~-3 ~32 stone_stairs 0
setblock ~92 ~-3 ~35 water 0
setblock ~93 ~-3 ~19 wool 8
fill ~93 ~-3 ~21 ~93 ~-3 ~36 wool 8
fill ~114 ~-3 ~18 ~120 ~-3 ~18 wool 8
fill ~114 ~-3 ~19 ~114 ~-3 ~36 wool 8
setblock ~115 ~-3 ~19 water 0
fill ~115 ~-3 ~20 ~116 ~-3 ~20 wool 8
fill ~115 ~-3 ~22 ~115 ~-3 ~25 stone_stairs 1
fill ~115 ~-3 ~29 ~115 ~-3 ~32 stone_stairs 1
fill ~115 ~-3 ~34 ~116 ~-3 ~34 wool 8
setblock ~115 ~-3 ~35 water 0
fill ~115 ~-3 ~36 ~132 ~-3 ~36 wool 8
setblock ~116 ~-3 ~19 wool 8
setblock ~116 ~-3 ~35 wool 8
fill ~118 ~-3 ~35 ~121 ~-3 ~35 stone_stairs 2
fill ~119 ~-3 ~23 ~122 ~-3 ~23 wool 8
fill ~119 ~-3 ~24 ~119 ~-3 ~31 wool 8
fill ~120 ~-3 ~17 ~120 ~-1 ~17 wool 8
fill ~120 ~-3 ~31 ~127 ~-3 ~31 wool 8
setblock ~121 ~-3 ~17 stone_pressure_plate 0
setblock ~121 ~-3 ~18 iron_door 1
setblock ~121 ~-3 ~19 stone_pressure_plate 0
fill ~121 ~-3 ~25 ~122 ~-3 ~25 wool 8
fill ~121 ~-3 ~26 ~121 ~3 ~26 wool 8
fill ~121 ~-3 ~27 ~121 ~3 ~27 wool 8
fill ~121 ~-3 ~28 ~121 ~3 ~28 wool 8
fill ~121 ~-3 ~29 ~125 ~-3 ~29 wool 8
fill ~122 ~-3 ~18 ~122 ~-1 ~18 wool 8
setblock ~123 ~-3 ~17 stone_pressure_plate 0
setblock ~123 ~-3 ~18 iron_door 1
setblock ~123 ~-3 ~19 stone_pressure_plate 0
setblock ~123 ~-3 ~23 piston_head 4
fill ~123 ~-3 ~27 ~123 ~52 ~27 ladder 2
fill ~123 ~-3 ~28 ~123 ~53 ~28 wool 8
fill ~124 ~-3 ~18 ~124 ~-1 ~18 wool 8
setblock ~124 ~-3 ~23 piston 12
fill ~124 ~-3 ~25 ~125 ~-3 ~25 wool 8
setblock ~125 ~-3 ~17 stone_pressure_plate 0
setblock ~125 ~-3 ~18 iron_door 1
setblock ~125 ~-3 ~19 stone_pressure_plate 0
fill ~125 ~-3 ~23 ~127 ~-3 ~23 wool 8
fill ~125 ~-3 ~26 ~125 ~3 ~26 wool 8
fill ~125 ~-3 ~27 ~125 ~3 ~27 wool 8
fill ~125 ~-3 ~28 ~125 ~3 ~28 wool 8
fill ~125 ~-3 ~35 ~128 ~-3 ~35 stone_stairs 2
fill ~126 ~-3 ~17 ~126 ~-1 ~17 wool 8
fill ~126 ~-3 ~18 ~132 ~-3 ~18 wool 8
fill ~127 ~-3 ~24 ~127 ~-3 ~31 wool 8
fill ~130 ~-3 ~19 ~130 ~-3 ~20 wool 8
fill ~130 ~-3 ~34 ~132 ~-3 ~34 wool 8
fill ~130 ~-3 ~35 ~130 ~-3 ~34 wool 8
setblock ~131 ~-3 ~19 water 0
fill ~131 ~-3 ~20 ~132 ~-3 ~20 wool 8
fill ~131 ~-3 ~22 ~131 ~-3 ~25 stone_stairs 0
fill ~131 ~-3 ~29 ~131 ~-3 ~32 stone_stairs 0
setblock ~131 ~-3 ~35 water 0
setblock ~132 ~-3 ~19 wool 8
fill ~132 ~-3 ~21 ~132 ~-3 ~36 wool 8
fill ~75 ~-2 ~18 ~75 ~32 ~18 wool 8
fill ~75 ~-2 ~19 ~75 ~1 ~19 glass 0
fill ~75 ~-2 ~20 ~75 ~1 ~20 glass 0
fill ~75 ~-2 ~21 ~75 ~1 ~21 glass 0
fill ~75 ~-2 ~22 ~75 ~1 ~22 glass 0
fill ~75 ~-2 ~23 ~75 ~35 ~23 wool 8
fill ~75 ~-2 ~24 ~75 ~1 ~24 glass 0
fill ~75 ~-2 ~25 ~75 ~1 ~25 glass 0
fill ~75 ~-2 ~26 ~75 ~1 ~26 glass 0
fill ~75 ~-2 ~27 ~75 ~3 ~27 wool 8
fill ~75 ~-2 ~28 ~75 ~1 ~28 glass 0
fill ~75 ~-2 ~29 ~75 ~1 ~29 glass 0
fill ~75 ~-2 ~30 ~75 ~1 ~30 glass 0
fill ~75 ~-2 ~31 ~75 ~52 ~31 wool 8
fill ~75 ~-2 ~32 ~75 ~1 ~32 glass 0
fill ~75 ~-2 ~33 ~75 ~1 ~33 glass 0
fill ~75 ~-2 ~34 ~75 ~1 ~34 glass 0
fill ~75 ~-2 ~35 ~75 ~1 ~35 glass 0
fill ~75 ~-2 ~36 ~75 ~52 ~36 wool 8
fill ~76 ~-2 ~18 ~78 ~-2 ~18 glass 0
fill ~76 ~-2 ~36 ~79 ~-2 ~36 glass 0
fill ~79 ~-2 ~18 ~79 ~3 ~18 wool 8
fill ~80 ~-2 ~18 ~80 ~1 ~18 glass 0
fill ~80 ~-2 ~23 ~80 ~52 ~23 wool 8
fill ~80 ~-2 ~31 ~80 ~52 ~31 wool 8
fill ~80 ~-2 ~36 ~80 ~52 ~36 wool 8
fill ~81 ~-2 ~18 ~81 ~-1 ~18 wool 8
fill ~81 ~-2 ~36 ~83 ~-2 ~36 glass 0
setblock ~82 ~-2 ~18 iron_door 9
fill ~82 ~-2 ~25 ~83 ~-2 ~25 wool 8
fill ~82 ~-2 ~29 ~86 ~-2 ~29 wool 8
setblock ~84 ~-2 ~18 iron_door 9
fill ~84 ~-2 ~36 ~84 ~3 ~36 wool 8
fill ~85 ~-2 ~25 ~86 ~-2 ~25 wool 8
fill ~85 ~-2 ~36 ~87 ~-2 ~36 glass 0
setblock ~86 ~-2 ~18 iron_door 9
setblock ~86 ~-2 ~23 lever 14
fill ~87 ~-2 ~18 ~87 ~-1 ~18 wool 8
fill ~88 ~-2 ~18 ~88 ~1 ~18 glass 0
fill ~88 ~-2 ~23 ~88 ~52 ~23 wool 8
fill ~88 ~-2 ~31 ~88 ~52 ~31 wool 8
fill ~88 ~-2 ~36 ~88 ~52 ~36 wool 8
fill ~89 ~-2 ~18 ~89 ~3 ~18 wool 8
fill ~89 ~-2 ~36 ~92 ~-2 ~36 glass 0
fill ~90 ~-2 ~18 ~92 ~-2 ~18 glass 0
fill ~93 ~-2 ~18 ~93 ~52 ~18 wool 8
fill ~93 ~-2 ~19 ~93 ~1 ~19 glass 0
fill ~93 ~-2 ~20 ~93 ~1 ~20 glass 0
fill ~93 ~-2 ~21 ~93 ~1 ~21 glass 0
fill ~93 ~-2 ~22 ~93 ~1 ~22 glass 0
fill ~93 ~-2 ~23 ~93 ~52 ~23 wool 8
fill ~93 ~-2 ~24 ~93 ~1 ~24 glass 0
fill ~93 ~-2 ~25 ~93 ~1 ~25 glass 0
fill ~93 ~-2 ~26 ~93 ~1 ~26 glass 0
fill ~93 ~-2 ~27 ~93 ~3 ~27 wool 8
fill ~93 ~-2 ~28 ~93 ~1 ~28 glass 0
fill ~93 ~-2 ~29 ~93 ~1 ~29 glass 0
fill ~93 ~-2 ~30 ~93 ~1 ~30 glass 0
fill ~93 ~-2 ~31 ~93 ~52 ~31 wool 8
fill ~93 ~-2 ~32 ~93 ~1 ~32 glass 0
fill ~93 ~-2 ~33 ~93 ~1 ~33 glass 0
fill ~93 ~-2 ~34 ~93 ~1 ~34 glass 0
fill ~93 ~-2 ~35 ~93 ~1 ~35 glass 0
fill ~93 ~-2 ~36 ~93 ~52 ~36 wool 8
fill ~114 ~-2 ~18 ~114 ~52 ~18 wool 8
fill ~114 ~-2 ~19 ~114 ~1 ~19 glass 0
fill ~114 ~-2 ~20 ~114 ~1 ~20 glass 0
fill ~114 ~-2 ~21 ~114 ~1 ~21 glass 0
fill ~114 ~-2 ~22 ~114 ~1 ~22 glass 0
fill ~114 ~-2 ~23 ~114 ~52 ~23 wool 8
fill ~114 ~-2 ~24 ~114 ~1 ~24 glass 0
fill ~114 ~-2 ~25 ~114 ~1 ~25 glass 0
fill ~114 ~-2 ~26 ~114 ~1 ~26 glass 0
fill ~114 ~-2 ~27 ~114 ~3 ~27 wool 8
fill ~114 ~-2 ~28 ~114 ~1 ~28 glass 0
fill ~114 ~-2 ~29 ~114 ~1 ~29 glass 0
fill ~114 ~-2 ~30 ~114 ~1 ~30 glass 0
fill ~114 ~-2 ~31 ~114 ~52 ~31 wool 8
fill ~114 ~-2 ~32 ~114 ~1 ~32 glass 0
fill ~114 ~-2 ~33 ~114 ~1 ~33 glass 0
fill ~114 ~-2 ~34 ~114 ~1 ~34 glass 0
fill ~114 ~-2 ~35 ~114 ~1 ~35 glass 0
fill ~114 ~-2 ~36 ~114 ~52 ~36 wool 8
fill ~115 ~-2 ~18 ~117 ~-2 ~18 glass 0
fill ~115 ~-2 ~36 ~118 ~-2 ~36 glass 0
fill ~118 ~-2 ~18 ~118 ~3 ~18 wool 8
fill ~119 ~-2 ~18 ~119 ~1 ~18 glass 0
fill ~119 ~-2 ~23 ~119 ~52 ~23 wool 8
fill ~119 ~-2 ~31 ~119 ~52 ~31 wool 8
fill ~119 ~-2 ~36 ~119 ~52 ~36 wool 8
fill ~120 ~-2 ~18 ~120 ~-1 ~18 wool 8
fill ~120 ~-2 ~36 ~122 ~-2 ~36 glass 0
setblock ~121 ~-2 ~18 iron_door 9
fill ~121 ~-2 ~25 ~122 ~-2 ~25 wool 8
fill ~121 ~-2 ~29 ~125 ~-2 ~29 wool 8
setblock ~122 ~-2 ~28 wool 8
setblock ~123 ~-2 ~18 iron_door 9
fill ~123 ~-2 ~36 ~123 ~3 ~36 wool 8
fill ~124 ~-2 ~25 ~125 ~-2 ~25 wool 8
fill ~124 ~-2 ~36 ~126 ~-2 ~36 glass 0
setblock ~125 ~-2 ~18 iron_door 9
setblock ~125 ~-2 ~23 lever 14
fill ~126 ~-2 ~18 ~126 ~-1 ~18 wool 8
fill ~127 ~-2 ~18 ~127 ~1 ~18 glass 0
fill ~127 ~-2 ~23 ~127 ~52 ~23 wool 8
fill ~127 ~-2 ~31 ~127 ~52 ~31 wool 8
fill ~127 ~-2 ~36 ~127 ~52 ~36 wool 8
fill ~128 ~-2 ~18 ~128 ~3 ~18 wool 8
fill ~128 ~-2 ~36 ~131 ~-2 ~36 glass 0
fill ~129 ~-2 ~18 ~131 ~-2 ~18 glass 0
fill ~132 ~-2 ~18 ~132 ~52 ~18 wool 8
fill ~132 ~-2 ~19 ~132 ~1 ~19 glass 0
fill ~132 ~-2 ~20 ~132 ~1 ~20 glass 0
fill ~132 ~-2 ~21 ~132 ~1 ~21 glass 0
fill ~132 ~-2 ~22 ~132 ~1 ~22 glass 0
fill ~132 ~-2 ~23 ~132 ~52 ~23 wool 8
fill ~132 ~-2 ~24 ~132 ~1 ~24 glass 0
fill ~132 ~-2 ~25 ~132 ~1 ~25 glass 0
fill ~132 ~-2 ~26 ~132 ~1 ~26 glass 0
fill ~132 ~-2 ~27 ~132 ~3 ~27 wool 8
fill ~132 ~-2 ~28 ~132 ~1 ~28 glass 0
fill ~132 ~-2 ~29 ~132 ~1 ~29 glass 0
fill ~132 ~-2 ~30 ~132 ~1 ~30 glass 0
fill ~132 ~-2 ~31 ~132 ~52 ~31 wool 8
fill ~132 ~-2 ~32 ~132 ~1 ~32 glass 0
fill ~132 ~-2 ~33 ~132 ~1 ~33 glass 0
fill ~132 ~-2 ~34 ~132 ~1 ~34 glass 0
fill ~132 ~-2 ~35 ~132 ~1 ~35 glass 0
fill ~132 ~-2 ~36 ~132 ~52 ~36 wool 8
fill ~76 ~-1 ~18 ~78 ~-1 ~18 glass 0
fill ~76 ~-1 ~36 ~79 ~-1 ~36 glass 0
fill ~81 ~-1 ~36 ~83 ~-1 ~36 glass 0
fill ~82 ~-1 ~17 ~87 ~-1 ~17 wool 8
fill ~82 ~-1 ~18 ~82 ~-1 ~17 wool 8
fill ~82 ~-1 ~25 ~83 ~-1 ~25 wool 8
fill ~82 ~-1 ~29 ~86 ~-1 ~29 wool 8
setblock ~84 ~-1 ~18 wool 8
fill ~85 ~-1 ~25 ~86 ~-1 ~25 wool 8
fill ~85 ~-1 ~36 ~87 ~-1 ~36 glass 0
setblock ~86 ~-1 ~18 wool 8
fill ~89 ~-1 ~36 ~92 ~-1 ~36 glass 0
fill ~90 ~-1 ~18 ~92 ~-1 ~18 glass 0
fill ~115 ~-1 ~18 ~117 ~-1 ~18 glass 0
fill ~115 ~-1 ~36 ~118 ~-1 ~36 glass 0
fill ~120 ~-1 ~36 ~122 ~-1 ~36 glass 0
fill ~121 ~-1 ~17 ~126 ~-1 ~17 wool 8
fill ~121 ~-1 ~18 ~121 ~-1 ~17 wool 8
fill ~121 ~-1 ~25 ~122 ~-1 ~25 wool 8
fill ~121 ~-1 ~29 ~125 ~-1 ~29 wool 8
setblock ~123 ~-1 ~18 wool 8
fill ~124 ~-1 ~25 ~125 ~-1 ~25 wool 8
fill ~124 ~-1 ~36 ~126 ~-1 ~36 glass 0
setblock ~125 ~-1 ~18 wool 8
fill ~128 ~-1 ~36 ~131 ~-1 ~36 glass 0
fill ~129 ~-1 ~18 ~131 ~-1 ~18 glass 0
fill ~76 ~0 ~18 ~78 ~0 ~18 glass 0
fill ~76 ~0 ~36 ~79 ~0 ~36 glass 0
fill ~81 ~0 ~18 ~88 ~0 ~18 glass 0
fill ~81 ~0 ~36 ~83 ~0 ~36 glass 0
fill ~82 ~0 ~25 ~86 ~0 ~25 wool 8
fill ~82 ~0 ~29 ~86 ~0 ~29 wool 8
fill ~85 ~0 ~36 ~87 ~0 ~36 glass 0
fill ~89 ~0 ~36 ~92 ~0 ~36 glass 0
fill ~90 ~0 ~18 ~92 ~0 ~18 glass 0
fill ~115 ~0 ~18 ~117 ~0 ~18 glass 0
fill ~115 ~0 ~36 ~118 ~0 ~36 glass 0
fill ~120 ~0 ~18 ~127 ~0 ~18 glass 0
fill ~120 ~0 ~36 ~122 ~0 ~36 glass 0
fill ~121 ~0 ~25 ~125 ~0 ~25 wool 8
fill ~121 ~0 ~29 ~125 ~0 ~29 wool 8
fill ~124 ~0 ~36 ~126 ~0 ~36 glass 0
fill ~128 ~0 ~36 ~131 ~0 ~36 glass 0
fill ~129 ~0 ~18 ~131 ~0 ~18 glass 0
fill ~76 ~1 ~18 ~78 ~1 ~18 glass 0
fill ~76 ~1 ~36 ~79 ~1 ~36 glass 0
fill ~81 ~1 ~18 ~88 ~1 ~18 glass 0
fill ~81 ~1 ~36 ~83 ~1 ~36 glass 0
fill ~82 ~1 ~25 ~86 ~1 ~25 wool 8
fill ~82 ~1 ~29 ~86 ~1 ~29 wool 8
fill ~85 ~1 ~36 ~87 ~1 ~36 glass 0
fill ~89 ~1 ~36 ~92 ~1 ~36 glass 0
fill ~90 ~1 ~18 ~92 ~1 ~18 glass 0
fill ~115 ~1 ~18 ~117 ~1 ~18 glass 0
fill ~115 ~1 ~36 ~118 ~1 ~36 glass 0
fill ~120 ~1 ~18 ~127 ~1 ~18 glass 0
fill ~120 ~1 ~36 ~122 ~1 ~36 glass 0
fill ~121 ~1 ~25 ~125 ~1 ~25 wool 8
fill ~121 ~1 ~29 ~125 ~1 ~29 wool 8
fill ~124 ~1 ~36 ~126 ~1 ~36 glass 0
fill ~128 ~1 ~36 ~131 ~1 ~36 glass 0
fill ~129 ~1 ~18 ~131 ~1 ~18 glass 0
fill ~75 ~2 ~19 ~93 ~2 ~19 wool 8
fill ~75 ~2 ~20 ~82 ~2 ~20 wool 8
fill ~75 ~2 ~21 ~82 ~2 ~21 wool 8
fill ~75 ~2 ~22 ~77 ~2 ~22 wool 8
fill ~75 ~2 ~24 ~77 ~2 ~24 wool 8
fill ~75 ~2 ~25 ~77 ~2 ~25 wool 8
fill ~75 ~2 ~26 ~82 ~2 ~26 wool 8
fill ~75 ~2 ~28 ~82 ~2 ~28 wool 8
fill ~75 ~2 ~29 ~77 ~2 ~29 wool 8
fill ~75 ~2 ~30 ~77 ~2 ~30 wool 8
fill ~75 ~2 ~32 ~77 ~2 ~32 wool 8
fill ~75 ~2 ~33 ~82 ~2 ~33 wool 8
fill ~75 ~2 ~34 ~82 ~2 ~34 wool 8
fill ~75 ~2 ~35 ~93 ~2 ~35 wool 8
fill ~76 ~2 ~18 ~93 ~2 ~18 wool 8
fill ~76 ~2 ~23 ~77 ~2 ~23 wool 8
fill ~76 ~2 ~27 ~82 ~2 ~27 wool 8
fill ~76 ~2 ~31 ~77 ~2 ~31 wool 8
fill ~76 ~2 ~36 ~93 ~2 ~36 wool 8
fill ~78 ~2 ~22 ~79 ~2 ~22 glowstone 0
fill ~78 ~2 ~23 ~79 ~2 ~23 glowstone 0
fill ~78 ~2 ~24 ~79 ~2 ~24 glowstone 0
fill ~78 ~2 ~25 ~79 ~2 ~25 glowstone 0
fill ~78 ~2 ~29 ~79 ~2 ~29 glowstone 0
fill ~78 ~2 ~30 ~79 ~2 ~30 glowstone 0
fill ~78 ~2 ~31 ~79 ~2 ~31 glowstone 0
fill ~78 ~2 ~32 ~79 ~2 ~32 glowstone 0
fill ~80 ~2 ~22 ~82 ~2 ~22 wool 8
fill ~80 ~2 ~24 ~88 ~2 ~24 wool 8
fill ~80 ~2 ~25 ~88 ~2 ~25 wool 8
fill ~80 ~2 ~29 ~88 ~2 ~29 wool 8
fill ~80 ~2 ~30 ~88 ~2 ~30 wool 8
fill ~80 ~2 ~32 ~82 ~2 ~32 wool 8
fill ~81 ~2 ~23 ~82 ~2 ~23 wool 8
fill ~81 ~2 ~31 ~82 ~2 ~31 wool 8
fill ~83 ~2 ~20 ~85 ~2 ~20 glowstone 0
fill ~83 ~2 ~21 ~85 ~2 ~21 glowstone 0
fill ~83 ~2 ~22 ~85 ~2 ~22 glowstone 0
fill ~83 ~2 ~23 ~85 ~2 ~23 glowstone 0
fill ~83 ~2 ~31 ~85 ~2 ~31 glowstone 0
fill ~83 ~2 ~32 ~85 ~2 ~32 glowstone 0
fill ~83 ~2 ~33 ~85 ~2 ~33 glowstone 0
fill ~83 ~2 ~34 ~85 ~2 ~34 glowstone 0
fill ~86 ~2 ~20 ~93 ~2 ~20 wool 8
fill ~86 ~2 ~21 ~93 ~2 ~21 wool 8
fill ~86 ~2 ~22 ~88 ~2 ~22 wool 8
fill ~86 ~2 ~23 ~88 ~2 ~23 wool 8
fill ~86 ~2 ~31 ~88 ~2 ~31 wool 8
fill ~86 ~2 ~32 ~88 ~2 ~32 wool 8
fill ~86 ~2 ~33 ~93 ~2 ~33 wool 8
fill ~86 ~2 ~34 ~93 ~2 ~34 wool 8
fill ~87 ~2 ~26 ~93 ~2 ~26 wool 8
fill ~87 ~2 ~27 ~93 ~2 ~27 wool 8
fill ~87 ~2 ~28 ~93 ~2 ~28 wool 8
fill ~89 ~2 ~22 ~90 ~2 ~22 glowstone 0
fill ~89 ~2 ~23 ~90 ~2 ~23 glowstone 0
fill ~89 ~2 ~24 ~90 ~2 ~24 glowstone 0
fill ~89 ~2 ~25 ~90 ~2 ~25 glowstone 0
fill ~89 ~2 ~29 ~90 ~2 ~29 glowstone 0
fill ~89 ~2 ~30 ~90 ~2 ~30 glowstone 0
fill ~89 ~2 ~31 ~90 ~2 ~31 glowstone 0
fill ~89 ~2 ~32 ~90 ~2 ~32 glowstone 0
fill ~91 ~2 ~22 ~93 ~2 ~22 wool 8
fill ~91 ~2 ~23 ~93 ~2 ~23 wool 8
fill ~91 ~2 ~24 ~93 ~2 ~24 wool 8
fill ~91 ~2 ~25 ~93 ~2 ~25 wool 8
fill ~91 ~2 ~29 ~93 ~2 ~29 wool 8
fill ~91 ~2 ~30 ~93 ~2 ~30 wool 8
fill ~91 ~2 ~31 ~93 ~2 ~31 wool 8
fill ~91 ~2 ~32 ~93 ~2 ~32 wool 8
fill ~114 ~2 ~19 ~132 ~2 ~19 wool 8
fill ~114 ~2 ~20 ~121 ~2 ~20 wool 8
fill ~114 ~2 ~21 ~121 ~2 ~21 wool 8
fill ~114 ~2 ~22 ~116 ~2 ~22 wool 8
fill ~114 ~2 ~24 ~116 ~2 ~24 wool 8
fill ~114 ~2 ~25 ~116 ~2 ~25 wool 8
fill ~114 ~2 ~26 ~121 ~2 ~26 wool 8
fill ~114 ~2 ~28 ~121 ~2 ~28 wool 8
fill ~114 ~2 ~29 ~116 ~2 ~29 wool 8
fill ~114 ~2 ~30 ~116 ~2 ~30 wool 8
fill ~114 ~2 ~32 ~116 ~2 ~32 wool 8
fill ~114 ~2 ~33 ~121 ~2 ~33 wool 8
fill ~114 ~2 ~34 ~121 ~2 ~34 wool 8
fill ~114 ~2 ~35 ~132 ~2 ~35 wool 8
fill ~115 ~2 ~18 ~132 ~2 ~18 wool 8
fill ~115 ~2 ~23 ~116 ~2 ~23 wool 8
fill ~115 ~2 ~27 ~121 ~2 ~27 wool 8
fill ~115 ~2 ~31 ~116 ~2 ~31 wool 8
fill ~115 ~2 ~36 ~132 ~2 ~36 wool 8
fill ~117 ~2 ~22 ~118 ~2 ~22 glowstone 0
fill ~117 ~2 ~23 ~118 ~2 ~23 glowstone 0
fill ~117 ~2 ~24 ~118 ~2 ~24 glowstone 0
fill ~117 ~2 ~25 ~118 ~2 ~25 glowstone 0
fill ~117 ~2 ~29 ~118 ~2 ~29 glowstone 0
fill ~117 ~2 ~30 ~118 ~2 ~30 glowstone 0
fill ~117 ~2 ~31 ~118 ~2 ~31 glowstone 0
fill ~117 ~2 ~32 ~118 ~2 ~32 glowstone 0
fill ~119 ~2 ~22 ~121 ~2 ~22 wool 8
fill ~119 ~2 ~24 ~127 ~2 ~24 wool 8
fill ~119 ~2 ~25 ~127 ~2 ~25 wool 8
fill ~119 ~2 ~29 ~127 ~2 ~29 wool 8
fill ~119 ~2 ~30 ~127 ~2 ~30 wool 8
fill ~119 ~2 ~32 ~121 ~2 ~32 wool 8
fill ~120 ~2 ~23 ~121 ~2 ~23 wool 8
fill ~120 ~2 ~31 ~121 ~2 ~31 wool 8
fill ~122 ~2 ~20 ~124 ~2 ~20 glowstone 0
fill ~122 ~2 ~21 ~124 ~2 ~21 glowstone 0
fill ~122 ~2 ~22 ~124 ~2 ~22 glowstone 0
fill ~122 ~2 ~23 ~124 ~2 ~23 glowstone 0
fill ~122 ~2 ~31 ~124 ~2 ~31 glowstone 0
fill ~122 ~2 ~32 ~124 ~2 ~32 glowstone 0
fill ~122 ~2 ~33 ~124 ~2 ~33 glowstone 0
fill ~122 ~2 ~34 ~124 ~2 ~34 glowstone 0
fill ~125 ~2 ~20 ~132 ~2 ~20 wool 8
fill ~125 ~2 ~21 ~132 ~2 ~21 wool 8
fill ~125 ~2 ~22 ~127 ~2 ~22 wool 8
fill ~125 ~2 ~23 ~127 ~2 ~23 wool 8
fill ~125 ~2 ~31 ~127 ~2 ~31 wool 8
fill ~125 ~2 ~32 ~127 ~2 ~32 wool 8
fill ~125 ~2 ~33 ~132 ~2 ~33 wool 8
fill ~125 ~2 ~34 ~132 ~2 ~34 wool 8
fill ~126 ~2 ~26 ~132 ~2 ~26 wool 8
fill ~126 ~2 ~27 ~132 ~2 ~27 wool 8
fill ~126 ~2 ~28 ~132 ~2 ~28 wool 8
fill ~128 ~2 ~22 ~129 ~2 ~22 glowstone 0
fill ~128 ~2 ~23 ~129 ~2 ~23 glowstone 0
fill ~128 ~2 ~24 ~129 ~2 ~24 glowstone 0
fill ~128 ~2 ~25 ~129 ~2 ~25 glowstone 0
fill ~128 ~2 ~29 ~129 ~2 ~29 glowstone 0
fill ~128 ~2 ~30 ~129 ~2 ~30 glowstone 0
fill ~128 ~2 ~31 ~129 ~2 ~31 glowstone 0
fill ~128 ~2 ~32 ~129 ~2 ~32 glowstone 0
fill ~130 ~2 ~22 ~132 ~2 ~22 wool 8
fill ~130 ~2 ~23 ~132 ~2 ~23 wool 8
fill ~130 ~2 ~24 ~132 ~2 ~24 wool 8
fill ~130 ~2 ~25 ~132 ~2 ~25 wool 8
fill ~130 ~2 ~29 ~132 ~2 ~29 wool 8
fill ~130 ~2 ~30 ~132 ~2 ~30 wool 8
fill ~130 ~2 ~31 ~132 ~2 ~31 wool 8
fill ~130 ~2 ~32 ~132 ~2 ~32 wool 8
fill ~75 ~3 ~19 ~89 ~3 ~19 wool 8
fill ~75 ~3 ~20 ~77 ~3 ~20 wool 8
fill ~75 ~3 ~21 ~75 ~2 ~21 wool 8
fill ~75 ~3 ~22 ~93 ~3 ~22 wool 8
fill ~75 ~3 ~24 ~93 ~3 ~24 wool 8
fill ~75 ~3 ~25 ~93 ~3 ~25 wool 8
fill ~75 ~3 ~26 ~89 ~3 ~26 wool 8
fill ~75 ~3 ~28 ~77 ~3 ~28 wool 8
fill ~75 ~3 ~29 ~77 ~3 ~29 wool 8
fill ~75 ~3 ~30 ~93 ~3 ~30 wool 8
fill ~75 ~3 ~32 ~93 ~3 ~32 wool 8
fill ~75 ~3 ~33 ~76 ~3 ~33 wool 8
fill ~75 ~3 ~34 ~77 ~3 ~34 wool 8
fill ~75 ~3 ~35 ~77 ~3 ~35 wool 8
fill ~76 ~3 ~18 ~93 ~3 ~18 wool 8
fill ~76 ~3 ~21 ~78 ~3 ~21 wool 14
fill ~76 ~3 ~23 ~93 ~3 ~23 wool 8
fill ~76 ~3 ~27 ~76 ~2 ~27 wool 8
fill ~76 ~3 ~31 ~93 ~3 ~31 wool 8
fill ~76 ~3 ~36 ~93 ~3 ~36 wool 8
fill ~77 ~3 ~27 ~78 ~3 ~27 wool 14
fill ~77 ~3 ~33 ~78 ~3 ~33 wool 14
setblock ~78 ~3 ~20 wool 14
fill ~78 ~3 ~28 ~78 ~3 ~29 wool 14
fill ~78 ~3 ~34 ~78 ~3 ~35 wool 14
fill ~79 ~3 ~20 ~83 ~3 ~20 wool 8
fill ~79 ~3 ~21 ~81 ~3 ~21 wool 8
fill ~79 ~3 ~27 ~83 ~3 ~27 wool 8
fill ~79 ~3 ~28 ~89 ~3 ~28 wool 8
fill ~79 ~3 ~29 ~93 ~3 ~29 wool 8
fill ~79 ~3 ~33 ~83 ~3 ~33 wool 8
fill ~79 ~3 ~34 ~83 ~3 ~34 wool 8
fill ~79 ~3 ~35 ~93 ~3 ~35 wool 8
fill ~82 ~3 ~21 ~84 ~3 ~21 wool 14
setblock ~84 ~3 ~20 wool 14
fill ~84 ~3 ~33 ~86 ~3 ~33 wool 14
fill ~84 ~3 ~34 ~84 ~3 ~33 wool 14
fill ~85 ~3 ~20 ~89 ~3 ~20 wool 8
fill ~85 ~3 ~21 ~89 ~3 ~21 wool 8
setblock ~85 ~3 ~27 wool 8
fill ~85 ~3 ~34 ~89 ~3 ~34 wool 8
fill ~87 ~3 ~27 ~89 ~3 ~27 wool 8
fill ~87 ~3 ~33 ~89 ~3 ~33 wool 8
fill ~90 ~3 ~19 ~90 ~3 ~21 wool 14
fill ~90 ~3 ~26 ~91 ~3 ~26 wool 14
fill ~90 ~3 ~27 ~91 ~3 ~27 wool 14
fill ~90 ~3 ~28 ~91 ~3 ~28 wool 14
fill ~90 ~3 ~33 ~92 ~3 ~33 wool 14
fill ~90 ~3 ~34 ~92 ~3 ~34 wool 14
fill ~91 ~3 ~19 ~93 ~3 ~19 wool 8
fill ~91 ~3 ~20 ~93 ~3 ~20 wool 8
setblock ~91 ~3 ~21 wool 14
fill ~92 ~3 ~21 ~93 ~3 ~21 wool 8
fill ~92 ~3 ~26 ~93 ~3 ~26 wool 8
fill ~92 ~3 ~27 ~92 ~3 ~32 wool 8
setblock ~93 ~3 ~28 wool 8
fill ~93 ~3 ~33 ~93 ~3 ~36 wool 8
fill ~114 ~3 ~19 ~128 ~3 ~19 wool 8
fill ~114 ~3 ~20 ~116 ~3 ~20 wool 8
fill ~114 ~3 ~21 ~114 ~2 ~21 wool 8
fill ~114 ~3 ~22 ~132 ~3 ~22 wool 8
fill ~114 ~3 ~24 ~132 ~3 ~24 wool 8
fill ~114 ~3 ~25 ~132 ~3 ~25 wool 8
fill ~114 ~3 ~26 ~128 ~3 ~26 wool 8
fill ~114 ~3 ~28 ~116 ~3 ~28 wool 8
fill ~114 ~3 ~29 ~116 ~3 ~29 wool 8
fill ~114 ~3 ~30 ~132 ~3 ~30 wool 8
fill ~114 ~3 ~32 ~132 ~3 ~32 wool 8
fill ~114 ~3 ~33 ~115 ~3 ~33 wool 8
fill ~114 ~3 ~34 ~116 ~3 ~34 wool 8
fill ~114 ~3 ~35 ~116 ~3 ~35 wool 8
fill ~115 ~3 ~18 ~132 ~3 ~18 wool 8
fill ~115 ~3 ~21 ~117 ~3 ~21 wool 14
fill ~115 ~3 ~23 ~132 ~3 ~23 wool 8
fill ~115 ~3 ~27 ~115 ~2 ~27 wool 8
fill ~115 ~3 ~31 ~132 ~3 ~31 wool 8
fill ~115 ~3 ~36 ~132 ~3 ~36 wool 8
fill ~116 ~3 ~27 ~117 ~3 ~27 wool 14
fill ~116 ~3 ~33 ~117 ~3 ~33 wool 14
setblock ~117 ~3 ~20 wool 14
fill ~117 ~3 ~28 ~117 ~3 ~29 wool 14
fill ~117 ~3 ~34 ~117 ~3 ~35 wool 14
fill ~118 ~3 ~20 ~122 ~3 ~20 wool 8
fill ~118 ~3 ~21 ~120 ~3 ~21 wool 8
fill ~118 ~3 ~27 ~122 ~3 ~27 wool 8
fill ~118 ~3 ~28 ~128 ~3 ~28 wool 8
fill ~118 ~3 ~29 ~132 ~3 ~29 wool 8
fill ~118 ~3 ~33 ~122 ~3 ~33 wool 8
fill ~118 ~3 ~34 ~122 ~3 ~34 wool 8
fill ~118 ~3 ~35 ~132 ~3 ~35 wool 8
fill ~121 ~3 ~21 ~123 ~3 ~21 wool 14
setblock ~123 ~3 ~20 wool 14
fill ~123 ~3 ~33 ~125 ~3 ~33 wool 14
fill ~123 ~3 ~34 ~123 ~3 ~33 wool 14
fill ~124 ~3 ~20 ~128 ~3 ~20 wool 8
fill ~124 ~3 ~21 ~128 ~3 ~21 wool 8
setblock ~124 ~3 ~27 wool 8
fill ~124 ~3 ~34 ~128 ~3 ~34 wool 8
fill ~126 ~3 ~27 ~128 ~3 ~27 wool 8
fill ~126 ~3 ~33 ~128 ~3 ~33 wool 8
fill ~129 ~3 ~19 ~129 ~3 ~21 wool 14
fill ~129 ~3 ~26 ~130 ~3 ~26 wool 14
fill ~129 ~3 ~27 ~130 ~3 ~27 wool 14
fill ~129 ~3 ~28 ~130 ~3 ~28 wool 14
fill ~129 ~3 ~33 ~131 ~3 ~33 wool 14
fill ~129 ~3 ~34 ~131 ~3 ~34 wool 14
fill ~130 ~3 ~19 ~132 ~3 ~19 wool 8
fill ~130 ~3 ~20 ~132 ~3 ~20 wool 8
setblock ~130 ~3 ~21 wool 14
fill ~131 ~3 ~21 ~132 ~3 ~21 wool 8
fill ~131 ~3 ~26 ~132 ~3 ~26 wool 8
fill ~131 ~3 ~27 ~131 ~3 ~32 wool 8
setblock ~132 ~3 ~28 wool 8
fill ~132 ~3 ~33 ~132 ~3 ~36 wool 8
fill ~75 ~4 ~19 ~75 ~6 ~19 glass 0
fill ~75 ~4 ~20 ~75 ~6 ~20 glass 0
fill ~75 ~4 ~21 ~75 ~6 ~21 glass 0
fill ~75 ~4 ~22 ~75 ~6 ~22 glass 0
fill ~75 ~4 ~24 ~76 ~4 ~24 wool 8
fill ~75 ~4 ~25 ~80 ~4 ~25 wool 8
fill ~75 ~4 ~26 ~75 ~6 ~26 glass 0
fill ~75 ~4 ~27 ~75 ~6 ~27 glass 0
fill ~75 ~4 ~28 ~75 ~6 ~28 glass 0
fill ~75 ~4 ~29 ~75 ~6 ~29 glass 0
fill ~75 ~4 ~30 ~80 ~4 ~30 wool 8
fill ~75 ~4 ~32 ~75 ~6 ~32 glass 0
fill ~75 ~4 ~33 ~75 ~6 ~33 glass 0
fill ~75 ~4 ~34 ~75 ~6 ~34 glass 0
fill ~75 ~4 ~35 ~75 ~6 ~35 glass 0
fill ~76 ~4 ~18 ~79 ~4 ~18 glass 0
setblock ~76 ~4 ~19 stone_stairs 3
fill ~76 ~4 ~20 ~77 ~4 ~20 wool 12
fill ~76 ~4 ~23 ~76 ~35 ~23 wool 8
fill ~76 ~4 ~26 ~76 ~5 ~26 bookshelf 0
setblock ~76 ~4 ~29 stone_stairs 1
fill ~76 ~4 ~31 ~80 ~4 ~31 wool 8
fill ~76 ~4 ~32 ~76 ~5 ~32 bookshelf 0
setblock ~76 ~4 ~35 stone_stairs 1
fill ~76 ~4 ~36 ~79 ~4 ~36 glass 0
setblock ~77 ~4 ~23 wooden_door 3
setblock ~77 ~4 ~24 stone_pressure_plate 0
fill ~77 ~4 ~28 ~77 ~4 ~29 wool 12
fill ~77 ~4 ~34 ~77 ~4 ~35 wool 12
fill ~78 ~4 ~23 ~83 ~4 ~23 wool 8
fill ~79 ~4 ~19 ~79 ~5 ~19 bookshelf 0
fill ~79 ~4 ~22 ~79 ~5 ~22 fence 0
fill ~79 ~4 ~29 ~79 ~5 ~29 fence 0
fill ~79 ~4 ~32 ~79 ~5 ~32 fence 0
fill ~80 ~4 ~18 ~81 ~4 ~18 wool 8
fill ~80 ~4 ~19 ~81 ~4 ~19 wool 8
fill ~80 ~4 ~20 ~81 ~4 ~20 wool 8
fill ~80 ~4 ~21 ~81 ~4 ~21 wool 8
fill ~80 ~4 ~22 ~81 ~4 ~22 wool 8
fill ~80 ~4 ~26 ~80 ~34 ~26 wool 8
setblock ~80 ~4 ~27 wooden_door 2
fill ~80 ~4 ~28 ~80 ~37 ~28 wool 8
fill ~80 ~4 ~29 ~80 ~52 ~29 wool 8
fill ~80 ~4 ~32 ~80 ~52 ~32 wool 8
fill ~80 ~4 ~33 ~80 ~52 ~33 wool 8
setblock ~80 ~4 ~34 wooden_door 2
fill ~80 ~4 ~35 ~82 ~4 ~35 wool 8
setblock ~81 ~4 ~27 stone_pressure_plate 0
setblock ~81 ~4 ~34 stone_pressure_plate 0
fill ~81 ~4 ~36 ~82 ~4 ~36 wool 8
fill ~82 ~4 ~18 ~85 ~4 ~18 glass 0
setblock ~82 ~4 ~19 stone_stairs 3
fill ~82 ~4 ~20 ~83 ~4 ~20 wool 12
fill ~82 ~4 ~22 ~82 ~5 ~22 fence 0
fill ~82 ~4 ~31 ~83 ~4 ~31 wool 8
fill ~82 ~4 ~32 ~82 ~52 ~32 wool 8
fill ~82 ~4 ~33 ~82 ~52 ~33 wool 8
fill ~82 ~4 ~34 ~82 ~52 ~34 wool 8
fill ~83 ~4 ~35 ~83 ~5 ~35 bookshelf 0
fill ~83 ~4 ~36 ~86 ~4 ~36 glass 0
setblock ~84 ~4 ~23 wooden_door 3
setblock ~84 ~4 ~24 stone_pressure_plate 0
setblock ~84 ~4 ~30 stone_pressure_plate 0
setblock ~84 ~4 ~31 wooden_door 1
fill ~85 ~4 ~19 ~85 ~5 ~19 bookshelf 0
fill ~85 ~4 ~23 ~86 ~4 ~23 wool 8
fill ~85 ~4 ~31 ~90 ~4 ~31 wool 8
fill ~85 ~4 ~34 ~86 ~4 ~34 wool 12
fill ~86 ~4 ~18 ~88 ~4 ~18 wool 8
fill ~86 ~4 ~19 ~88 ~4 ~19 wool 8
fill ~86 ~4 ~20 ~86 ~52 ~20 wool 8
fill ~86 ~4 ~21 ~86 ~52 ~21 wool 8
fill ~86 ~4 ~22 ~86 ~52 ~22 wool 8
fill ~86 ~4 ~32 ~86 ~5 ~32 fence 0
setblock ~86 ~4 ~35 stone_stairs 2
setblock ~87 ~4 ~20 stone_pressure_plate 0
setblock ~87 ~4 ~27 stone_pressure_plate 0
fill ~87 ~4 ~32 ~88 ~4 ~32 wool 8
fill ~87 ~4 ~33 ~88 ~4 ~33 wool 8
fill ~87 ~4 ~34 ~88 ~4 ~34 wool 8
fill ~87 ~4 ~35 ~88 ~4 ~35 wool 8
fill ~87 ~4 ~36 ~87 ~52 ~36 wool 8
setblock ~88 ~4 ~20 wooden_door 0
fill ~88 ~4 ~21 ~88 ~52 ~21 wool 8
fill ~88 ~4 ~22 ~88 ~52 ~22 wool 8
fill ~88 ~4 ~24 ~93 ~4 ~24 wool 8
fill ~88 ~4 ~25 ~88 ~37 ~25 wool 8
fill ~88 ~4 ~26 ~88 ~36 ~26 wool 8
setblock ~88 ~4 ~27 wooden_door 0
fill ~88 ~4 ~28 ~88 ~52 ~28 wool 8
fill ~88 ~4 ~29 ~93 ~4 ~29 wool 8
fill ~89 ~4 ~18 ~92 ~4 ~18 glass 0
fill ~89 ~4 ~22 ~89 ~5 ~22 fence 0
fill ~89 ~4 ~23 ~93 ~4 ~23 wool 8
fill ~89 ~4 ~25 ~89 ~5 ~25 fence 0
fill ~89 ~4 ~28 ~89 ~5 ~28 bookshelf 0
fill ~89 ~4 ~32 ~89 ~5 ~32 fence 0
fill ~89 ~4 ~35 ~89 ~5 ~35 bookshelf 0
fill ~89 ~4 ~36 ~92 ~4 ~36 glass 0
fill ~91 ~4 ~19 ~91 ~4 ~20 wool 12
fill ~91 ~4 ~27 ~91 ~4 ~28 wool 12
setblock ~91 ~4 ~30 stone_pressure_plate 0
setblock ~91 ~4 ~31 wooden_door 1
fill ~91 ~4 ~34 ~92 ~4 ~34 wool 12
setblock ~92 ~4 ~19 stone_stairs 0
fill ~92 ~4 ~22 ~92 ~5 ~22 bookshelf 0
setblock ~92 ~4 ~28 stone_stairs 0
fill ~92 ~4 ~30 ~93 ~4 ~30 wool 8
fill ~92 ~4 ~31 ~92 ~52 ~31 wool 8
setblock ~92 ~4 ~35 stone_stairs 2
fill ~93 ~4 ~19 ~93 ~6 ~19 glass 0
fill ~93 ~4 ~20 ~93 ~6 ~20 glass 0
fill ~93 ~4 ~21 ~93 ~6 ~21 glass 0
fill ~93 ~4 ~22 ~93 ~6 ~22 glass 0
fill ~93 ~4 ~25 ~93 ~6 ~25 glass 0
fill ~93 ~4 ~26 ~93 ~6 ~26 glass 0
fill ~93 ~4 ~27 ~93 ~6 ~27 glass 0
fill ~93 ~4 ~28 ~93 ~6 ~28 glass 0
fill ~93 ~4 ~32 ~93 ~6 ~32 glass 0
fill ~93 ~4 ~33 ~93 ~6 ~33 glass 0
fill ~93 ~4 ~34 ~93 ~6 ~34 glass 0
fill ~93 ~4 ~35 ~93 ~6 ~35 glass 0
fill ~114 ~4 ~19 ~114 ~6 ~19 glass 0
fill ~114 ~4 ~20 ~114 ~6 ~20 glass 0
fill ~114 ~4 ~21 ~114 ~6 ~21 glass 0
fill ~114 ~4 ~22 ~114 ~6 ~22 glass 0
fill ~114 ~4 ~24 ~115 ~4 ~24 wool 8
fill ~114 ~4 ~25 ~119 ~4 ~25 wool 8
fill ~114 ~4 ~26 ~114 ~6 ~26 glass 0
fill ~114 ~4 ~27 ~114 ~6 ~27 glass 0
fill ~114 ~4 ~28 ~114 ~6 ~28 glass 0
fill ~114 ~4 ~29 ~114 ~6 ~29 glass 0
fill ~114 ~4 ~30 ~119 ~4 ~30 wool 8
fill ~114 ~4 ~32 ~114 ~6 ~32 glass 0
fill ~114 ~4 ~33 ~114 ~6 ~33 glass 0
fill ~114 ~4 ~34 ~114 ~6 ~34 glass 0
fill ~114 ~4 ~35 ~114 ~6 ~35 glass 0
fill ~115 ~4 ~18 ~118 ~4 ~18 glass 0
setblock ~115 ~4 ~19 stone_stairs 3
fill ~115 ~4 ~20 ~116 ~4 ~20 wool 12
fill ~115 ~4 ~23 ~115 ~52 ~23 wool 8
fill ~115 ~4 ~26 ~115 ~5 ~26 bookshelf 0
setblock ~115 ~4 ~29 stone_stairs 1
fill ~115 ~4 ~31 ~119 ~4 ~31 wool 8
fill ~115 ~4 ~32 ~115 ~5 ~32 bookshelf 0
setblock ~115 ~4 ~35 stone_stairs 1
fill ~115 ~4 ~36 ~118 ~4 ~36 glass 0
setblock ~116 ~4 ~23 wooden_door 3
setblock ~116 ~4 ~24 stone_pressure_plate 0
fill ~116 ~4 ~28 ~116 ~4 ~29 wool 12
fill ~116 ~4 ~34 ~116 ~4 ~35 wool 12
fill ~117 ~4 ~23 ~122 ~4 ~23 wool 8
fill ~118 ~4 ~19 ~118 ~5 ~19 bookshelf 0
fill ~118 ~4 ~22 ~118 ~5 ~22 fence 0
fill ~118 ~4 ~29 ~118 ~5 ~29 fence 0
fill ~118 ~4 ~32 ~118 ~5 ~32 fence 0
fill ~119 ~4 ~18 ~120 ~4 ~18 wool 8
fill ~119 ~4 ~19 ~120 ~4 ~19 wool 8
fill ~119 ~4 ~20 ~120 ~4 ~20 wool 8
fill ~119 ~4 ~21 ~120 ~4 ~21 wool 8
fill ~119 ~4 ~22 ~120 ~4 ~22 wool 8
fill ~119 ~4 ~26 ~119 ~52 ~26 wool 8
setblock ~119 ~4 ~27 wooden_door 2
fill ~119 ~4 ~28 ~119 ~52 ~28 wool 8
fill ~119 ~4 ~29 ~119 ~52 ~29 wool 8
fill ~119 ~4 ~32 ~119 ~52 ~32 wool 8
fill ~119 ~4 ~33 ~119 ~52 ~33 wool 8
setblock ~119 ~4 ~34 wooden_door 2
fill ~119 ~4 ~35 ~121 ~4 ~35 wool 8
setblock ~120 ~4 ~27 stone_pressure_plate 0
setblock ~120 ~4 ~34 stone_pressure_plate 0
fill ~120 ~4 ~36 ~121 ~4 ~36 wool 8
fill ~121 ~4 ~18 ~124 ~4 ~18 glass 0
setblock ~121 ~4 ~19 stone_stairs 3
fill ~121 ~4 ~20 ~122 ~4 ~20 wool 12
fill ~121 ~4 ~22 ~121 ~5 ~22 fence 0
fill ~121 ~4 ~31 ~122 ~4 ~31 wool 8
fill ~121 ~4 ~32 ~121 ~52 ~32 wool 8
fill ~121 ~4 ~33 ~121 ~52 ~33 wool 8
fill ~121 ~4 ~34 ~121 ~52 ~34 wool 8
fill ~122 ~4 ~35 ~122 ~5 ~35 bookshelf 0
fill ~122 ~4 ~36 ~125 ~4 ~36 glass 0
setblock ~123 ~4 ~23 wooden_door 3
setblock ~123 ~4 ~24 stone_pressure_plate 0
setblock ~123 ~4 ~30 stone_pressure_plate 0
setblock ~123 ~4 ~31 wooden_door 1
fill ~124 ~4 ~19 ~124 ~5 ~19 bookshelf 0
fill ~124 ~4 ~23 ~125 ~4 ~23 wool 8
fill ~124 ~4 ~31 ~129 ~4 ~31 wool 8
fill ~124 ~4 ~34 ~125 ~4 ~34 wool 12
fill ~125 ~4 ~18 ~127 ~4 ~18 wool 8
fill ~125 ~4 ~19 ~127 ~4 ~19 wool 8
fill ~125 ~4 ~20 ~125 ~53 ~20 wool 8
fill ~125 ~4 ~21 ~125 ~52 ~21 wool 8
fill ~125 ~4 ~22 ~125 ~52 ~22 wool 8
fill ~125 ~4 ~32 ~125 ~5 ~32 fence 0
setblock ~125 ~4 ~35 stone_stairs 2
setblock ~126 ~4 ~20 stone_pressure_plate 0
setblock ~126 ~4 ~27 stone_pressure_plate 0
fill ~126 ~4 ~32 ~127 ~4 ~32 wool 8
fill ~126 ~4 ~33 ~127 ~4 ~33 wool 8
fill ~126 ~4 ~34 ~127 ~4 ~34 wool 8
fill ~126 ~4 ~35 ~127 ~4 ~35 wool 8
fill ~126 ~4 ~36 ~126 ~52 ~36 wool 8
setblock ~127 ~4 ~20 wooden_door 0
fill ~127 ~4 ~21 ~127 ~52 ~21 wool 8
fill ~127 ~4 ~22 ~127 ~52 ~22 wool 8
fill ~127 ~4 ~24 ~132 ~4 ~24 wool 8
fill ~127 ~4 ~25 ~127 ~52 ~25 wool 8
fill ~127 ~4 ~26 ~127 ~52 ~26 wool 8
setblock ~127 ~4 ~27 wooden_door 0
fill ~127 ~4 ~28 ~127 ~52 ~28 wool 8
fill ~127 ~4 ~29 ~132 ~4 ~29 wool 8
fill ~128 ~4 ~18 ~131 ~4 ~18 glass 0
fill ~128 ~4 ~22 ~128 ~5 ~22 fence 0
fill ~128 ~4 ~23 ~132 ~4 ~23 wool 8
fill ~128 ~4 ~25 ~128 ~5 ~25 fence 0
fill ~128 ~4 ~28 ~128 ~5 ~28 bookshelf 0
fill ~128 ~4 ~32 ~128 ~5 ~32 fence 0
fill ~128 ~4 ~35 ~128 ~5 ~35 bookshelf 0
fill ~128 ~4 ~36 ~131 ~4 ~36 glass 0
fill ~130 ~4 ~19 ~130 ~4 ~20 wool 12
fill ~130 ~4 ~27 ~130 ~4 ~28 wool 12
setblock ~130 ~4 ~30 stone_pressure_plate 0
setblock ~130 ~4 ~31 wooden_door 1
fill ~130 ~4 ~34 ~131 ~4 ~34 wool 12
setblock ~131 ~4 ~19 stone_stairs 0
fill ~131 ~4 ~22 ~131 ~5 ~22 bookshelf 0
setblock ~131 ~4 ~28 stone_stairs 0
fill ~131 ~4 ~30 ~132 ~4 ~30 wool 8
fill ~131 ~4 ~31 ~131 ~52 ~31 wool 8
setblock ~131 ~4 ~35 stone_stairs 2
fill ~132 ~4 ~19 ~132 ~6 ~19 glass 0
fill ~132 ~4 ~20 ~132 ~6 ~20 glass 0
fill ~132 ~4 ~21 ~132 ~6 ~21 glass 0
fill ~132 ~4 ~22 ~132 ~6 ~22 glass 0
fill ~132 ~4 ~25 ~132 ~6 ~25 glass 0
fill ~132 ~4 ~26 ~132 ~6 ~26 glass 0
fill ~132 ~4 ~27 ~132 ~6 ~27 glass 0
fill ~132 ~4 ~28 ~132 ~6 ~28 glass 0
fill ~132 ~4 ~32 ~132 ~6 ~32 glass 0
fill ~132 ~4 ~33 ~132 ~6 ~33 glass 0
fill ~132 ~4 ~34 ~132 ~6 ~34 glass 0
fill ~132 ~4 ~35 ~132 ~6 ~35 glass 0
fill ~75 ~5 ~24 ~76 ~5 ~24 wool 8
fill ~75 ~5 ~25 ~80 ~5 ~25 wool 8
fill ~75 ~5 ~30 ~80 ~5 ~30 wool 8
fill ~76 ~5 ~18 ~79 ~5 ~18 glass 0
fill ~76 ~5 ~31 ~80 ~5 ~31 wool 8
fill ~76 ~5 ~36 ~79 ~5 ~36 glass 0
setblock ~77 ~5 ~23 wooden_door 11
fill ~78 ~5 ~23 ~83 ~5 ~23 wool 8
fill ~80 ~5 ~18 ~81 ~5 ~18 wool 8
fill ~80 ~5 ~19 ~81 ~5 ~19 wool 8
fill ~80 ~5 ~20 ~81 ~5 ~20 wool 8
fill ~80 ~5 ~21 ~81 ~5 ~21 wool 8
fill ~80 ~5 ~22 ~81 ~5 ~22 wool 8
setblock ~80 ~5 ~27 wooden_door 10
setblock ~80 ~5 ~34 wooden_door 10
fill ~80 ~5 ~35 ~82 ~5 ~35 wool 8
fill ~81 ~5 ~36 ~82 ~5 ~36 wool 8
fill ~82 ~5 ~18 ~85 ~5 ~18 glass 0
fill ~82 ~5 ~31 ~83 ~5 ~31 wool 8
setblock ~83 ~5 ~28 wool 8
fill ~83 ~5 ~36 ~86 ~5 ~36 glass 0
setblock ~84 ~5 ~23 wooden_door 11
setblock ~84 ~5 ~31 wooden_door 9
fill ~85 ~5 ~23 ~86 ~5 ~23 wool 8
fill ~85 ~5 ~31 ~90 ~5 ~31 wool 8
fill ~86 ~5 ~18 ~88 ~5 ~18 wool 8
fill ~86 ~5 ~19 ~88 ~5 ~19 wool 8
fill ~87 ~5 ~32 ~88 ~5 ~32 wool 8
fill ~87 ~5 ~33 ~88 ~5 ~33 wool 8
fill ~87 ~5 ~34 ~88 ~5 ~34 wool 8
fill ~87 ~5 ~35 ~88 ~5 ~35 wool 8
setblock ~88 ~5 ~20 wooden_door 8
fill ~88 ~5 ~24 ~93 ~5 ~24 wool 8
setblock ~88 ~5 ~27 wooden_door 8
fill ~88 ~5 ~29 ~93 ~5 ~29 wool 8
fill ~89 ~5 ~18 ~92 ~5 ~18 glass 0
fill ~89 ~5 ~23 ~93 ~5 ~23 wool 8
fill ~89 ~5 ~36 ~92 ~5 ~36 glass 0
setblock ~91 ~5 ~31 wooden_door 9
fill ~92 ~5 ~30 ~93 ~5 ~30 wool 8
fill ~114 ~5 ~24 ~115 ~5 ~24 wool 8
fill ~114 ~5 ~25 ~119 ~5 ~25 wool 8
fill ~114 ~5 ~30 ~119 ~5 ~30 wool 8
fill ~115 ~5 ~18 ~118 ~5 ~18 glass 0
fill ~115 ~5 ~31 ~119 ~5 ~31 wool 8
fill ~115 ~5 ~36 ~118 ~5 ~36 glass 0
setblock ~116 ~5 ~23 wooden_door 11
fill ~117 ~5 ~23 ~122 ~5 ~23 wool 8
fill ~119 ~5 ~18 ~120 ~5 ~18 wool 8
fill ~119 ~5 ~19 ~120 ~5 ~19 wool 8
fill ~119 ~5 ~20 ~120 ~5 ~20 wool 8
fill ~119 ~5 ~21 ~120 ~5 ~21 wool 8
fill ~119 ~5 ~22 ~120 ~5 ~22 wool 8
setblock ~119 ~5 ~27 wooden_door 10
setblock ~119 ~5 ~34 wooden_door 10
fill ~119 ~5 ~35 ~121 ~5 ~35 wool 8
fill ~120 ~5 ~36 ~121 ~5 ~36 wool 8
fill ~121 ~5 ~18 ~124 ~5 ~18 glass 0
fill ~121 ~5 ~31 ~122 ~5 ~31 wool 8
setblock ~122 ~5 ~28 wool 8
fill ~122 ~5 ~36 ~125 ~5 ~36 glass 0
setblock ~123 ~5 ~23 wooden_door 11
setblock ~123 ~5 ~31 wooden_door 9
fill ~124 ~5 ~23 ~125 ~5 ~23 wool 8
fill ~124 ~5 ~31 ~129 ~5 ~31 wool 8
fill ~125 ~5 ~18 ~127 ~5 ~18 wool 8
fill ~125 ~5 ~19 ~127 ~5 ~19 wool 8
fill ~126 ~5 ~32 ~127 ~5 ~32 wool 8
fill ~126 ~5 ~33 ~127 ~5 ~33 wool 8
fill ~126 ~5 ~34 ~127 ~5 ~34 wool 8
fill ~126 ~5 ~35 ~127 ~5 ~35 wool 8
setblock ~127 ~5 ~20 wooden_door 8
fill ~127 ~5 ~24 ~132 ~5 ~24 wool 8
setblock ~127 ~5 ~27 wooden_door 8
fill ~127 ~5 ~29 ~132 ~5 ~29 wool 8
fill ~128 ~5 ~18 ~131 ~5 ~18 glass 0
fill ~128 ~5 ~23 ~132 ~5 ~23 wool 8
fill ~128 ~5 ~36 ~131 ~5 ~36 glass 0
setblock ~130 ~5 ~31 wooden_door 9
fill ~131 ~5 ~30 ~132 ~5 ~30 wool 8
fill ~75 ~6 ~24 ~76 ~6 ~24 wool 8
fill ~75 ~6 ~25 ~80 ~6 ~25 wool 8
fill ~75 ~6 ~30 ~80 ~6 ~30 wool 8
fill ~76 ~6 ~18 ~79 ~6 ~18 glass 0
fill ~76 ~6 ~31 ~93 ~6 ~31 wool 8
fill ~76 ~6 ~36 ~79 ~6 ~36 glass 0
fill ~77 ~6 ~23 ~93 ~6 ~23 wool 8
setblock ~79 ~6 ~22 glowstone 0
setblock ~79 ~6 ~29 glowstone 0
setblock ~79 ~6 ~32 glowstone 0
fill ~80 ~6 ~18 ~81 ~6 ~18 wool 8
fill ~80 ~6 ~19 ~81 ~6 ~19 wool 8
fill ~80 ~6 ~20 ~81 ~6 ~20 wool 8
fill ~80 ~6 ~21 ~81 ~6 ~21 wool 8
fill ~80 ~6 ~22 ~81 ~6 ~22 wool 8
fill ~80 ~6 ~24 ~80 ~8 ~24 wool 8
fill ~80 ~6 ~27 ~80 ~8 ~27 wool 8
fill ~80 ~6 ~34 ~80 ~8 ~34 wool 8
fill ~80 ~6 ~35 ~82 ~6 ~35 wool 8
fill ~81 ~6 ~36 ~82 ~6 ~36 wool 8
fill ~82 ~6 ~18 ~85 ~6 ~18 glass 0
setblock ~82 ~6 ~22 glowstone 0
fill ~83 ~6 ~36 ~86 ~6 ~36 glass 0
fill ~86 ~6 ~18 ~88 ~6 ~18 wool 8
fill ~86 ~6 ~19 ~88 ~6 ~19 wool 8
setblock ~86 ~6 ~32 glowstone 0
fill ~87 ~6 ~32 ~88 ~6 ~32 wool 8
fill ~87 ~6 ~33 ~88 ~6 ~33 wool 8
fill ~87 ~6 ~34 ~88 ~6 ~34 wool 8
fill ~87 ~6 ~35 ~88 ~6 ~35 wool 8
fill ~88 ~6 ~20 ~88 ~8 ~20 wool 8
fill ~88 ~6 ~24 ~93 ~6 ~24 wool 8
fill ~88 ~6 ~27 ~88 ~8 ~27 wool 8
fill ~88 ~6 ~29 ~93 ~6 ~29 wool 8
fill ~88 ~6 ~30 ~88 ~8 ~30 wool 8
fill ~89 ~6 ~18 ~92 ~6 ~18 glass 0
setblock ~89 ~6 ~22 glowstone 0
setblock ~89 ~6 ~25 glowstone 0
setblock ~89 ~6 ~32 glowstone 0
fill ~89 ~6 ~36 ~92 ~6 ~36 glass 0
fill ~92 ~6 ~30 ~93 ~6 ~30 wool 8
fill ~114 ~6 ~24 ~115 ~6 ~24 wool 8
fill ~114 ~6 ~25 ~119 ~6 ~25 wool 8
fill ~114 ~6 ~30 ~119 ~6 ~30 wool 8
fill ~115 ~6 ~18 ~118 ~6 ~18 glass 0
fill ~115 ~6 ~31 ~132 ~6 ~31 wool 8
fill ~115 ~6 ~36 ~118 ~6 ~36 glass 0
fill ~116 ~6 ~23 ~132 ~6 ~23 wool 8
setblock ~118 ~6 ~22 glowstone 0
setblock ~118 ~6 ~29 glowstone 0
setblock ~118 ~6 ~32 glowstone 0
fill ~119 ~6 ~18 ~120 ~6 ~18 wool 8
fill ~119 ~6 ~19 ~120 ~6 ~19 wool 8
fill ~119 ~6 ~20 ~120 ~6 ~20 wool 8
fill ~119 ~6 ~21 ~120 ~6 ~21 wool 8
fill ~119 ~6 ~22 ~120 ~6 ~22 wool 8
fill ~119 ~6 ~24 ~119 ~8 ~24 wool 8
fill ~119 ~6 ~27 ~119 ~8 ~27 wool 8
fill ~119 ~6 ~34 ~119 ~8 ~34 wool 8
fill ~119 ~6 ~35 ~121 ~6 ~35 wool 8
fill ~120 ~6 ~36 ~121 ~6 ~36 wool 8
fill ~121 ~6 ~18 ~124 ~6 ~18 glass 0
setblock ~121 ~6 ~22 glowstone 0
fill ~122 ~6 ~36 ~125 ~6 ~36 glass 0
fill ~125 ~6 ~18 ~127 ~6 ~18 wool 8
fill ~125 ~6 ~19 ~127 ~6 ~19 wool 8
setblock ~125 ~6 ~32 glowstone 0
fill ~126 ~6 ~32 ~127 ~6 ~32 wool 8
fill ~126 ~6 ~33 ~127 ~6 ~33 wool 8
fill ~126 ~6 ~34 ~127 ~6 ~34 wool 8
fill ~126 ~6 ~35 ~127 ~6 ~35 wool 8
fill ~127 ~6 ~20 ~127 ~8 ~20 wool 8
fill ~127 ~6 ~24 ~132 ~6 ~24 wool 8
fill ~127 ~6 ~27 ~127 ~8 ~27 wool 8
fill ~127 ~6 ~29 ~132 ~6 ~29 wool 8
fill ~127 ~6 ~30 ~127 ~8 ~30 wool 8
fill ~128 ~6 ~18 ~131 ~6 ~18 glass 0
setblock ~128 ~6 ~22 glowstone 0
setblock ~128 ~6 ~25 glowstone 0
setblock ~128 ~6 ~32 glowstone 0
fill ~128 ~6 ~36 ~131 ~6 ~36 glass 0
fill ~131 ~6 ~30 ~132 ~6 ~30 wool 8
fill ~75 ~7 ~19 ~93 ~7 ~19 wool 8
fill ~75 ~7 ~20 ~93 ~7 ~20 wool 8
fill ~75 ~7 ~21 ~93 ~7 ~21 wool 8
fill ~75 ~7 ~22 ~93 ~7 ~22 wool 8
fill ~75 ~7 ~24 ~93 ~7 ~24 wool 8
fill ~75 ~7 ~25 ~82 ~7 ~25 wool 8
fill ~75 ~7 ~26 ~81 ~7 ~26 wool 8
fill ~75 ~7 ~27 ~81 ~7 ~27 wool 8
fill ~75 ~7 ~28 ~81 ~7 ~28 wool 8
fill ~75 ~7 ~29 ~82 ~7 ~29 wool 8
fill ~75 ~7 ~30 ~93 ~7 ~30 wool 8
fill ~75 ~7 ~32 ~93 ~7 ~32 wool 8
fill ~75 ~7 ~33 ~93 ~7 ~33 wool 8
fill ~75 ~7 ~34 ~93 ~7 ~34 wool 8
fill ~75 ~7 ~35 ~93 ~7 ~35 wool 8
fill ~76 ~7 ~18 ~93 ~7 ~18 wool 8
fill ~76 ~7 ~31 ~93 ~7 ~31 wool 8
fill ~76 ~7 ~36 ~93 ~7 ~36 wool 8
fill ~77 ~7 ~23 ~93 ~7 ~23 wool 8
fill ~82 ~7 ~26 ~82 ~7 ~28 glowstone 0
fill ~83 ~7 ~25 ~85 ~7 ~25 glowstone 0
fill ~83 ~7 ~26 ~85 ~7 ~26 wool 8
fill ~83 ~7 ~27 ~83 ~8 ~27 wool 8
fill ~83 ~7 ~28 ~83 ~8 ~28 wool 8
fill ~83 ~7 ~29 ~85 ~7 ~29 glowstone 0
fill ~85 ~7 ~27 ~85 ~8 ~27 wool 8
fill ~85 ~7 ~28 ~85 ~8 ~28 wool 8
fill ~86 ~7 ~25 ~93 ~7 ~25 wool 8
fill ~86 ~7 ~26 ~86 ~7 ~28 glowstone 0
fill ~86 ~7 ~29 ~93 ~7 ~29 wool 8
fill ~87 ~7 ~26 ~87 ~8 ~26 wool 8
fill ~87 ~7 ~27 ~87 ~8 ~27 wool 8
fill ~87 ~7 ~28 ~87 ~8 ~28 wool 8
fill ~89 ~7 ~26 ~93 ~7 ~26 wool 8
fill ~89 ~7 ~27 ~93 ~7 ~27 wool 8
fill ~89 ~7 ~28 ~93 ~7 ~28 wool 8
fill ~114 ~7 ~19 ~132 ~7 ~19 wool 8
fill ~114 ~7 ~20 ~132 ~7 ~20 wool 8
fill ~114 ~7 ~21 ~132 ~7 ~21 wool 8
fill ~114 ~7 ~22 ~132 ~7 ~22 wool 8
fill ~114 ~7 ~24 ~132 ~7 ~24 wool 8
fill ~114 ~7 ~25 ~121 ~7 ~25 wool 8
fill ~114 ~7 ~26 ~120 ~7 ~26 wool 8
fill ~114 ~7 ~27 ~120 ~7 ~27 wool 8
fill ~114 ~7 ~28 ~120 ~7 ~28 wool 8
fill ~114 ~7 ~29 ~121 ~7 ~29 wool 8
fill ~114 ~7 ~30 ~132 ~7 ~30 wool 8
fill ~114 ~7 ~32 ~132 ~7 ~32 wool 8
fill ~114 ~7 ~33 ~132 ~7 ~33 wool 8
fill ~114 ~7 ~34 ~132 ~7 ~34 wool 8
fill ~114 ~7 ~35 ~132 ~7 ~35 wool 8
fill ~115 ~7 ~18 ~132 ~7 ~18 wool 8
fill ~115 ~7 ~31 ~132 ~7 ~31 wool 8
fill ~115 ~7 ~36 ~132 ~7 ~36 wool 8
fill ~116 ~7 ~23 ~132 ~7 ~23 wool 8
fill ~121 ~7 ~26 ~121 ~7 ~28 glowstone 0
fill ~122 ~7 ~25 ~124 ~7 ~25 glowstone 0
fill ~122 ~7 ~26 ~124 ~7 ~26 wool 8
fill ~122 ~7 ~27 ~122 ~8 ~27 wool 8
fill ~122 ~7 ~28 ~122 ~8 ~28 wool 8
fill ~122 ~7 ~29 ~124 ~7 ~29 glowstone 0
fill ~124 ~7 ~27 ~124 ~8 ~27 wool 8
fill ~124 ~7 ~28 ~124 ~8 ~28 wool 8
fill ~125 ~7 ~25 ~132 ~7 ~25 wool 8
fill ~125 ~7 ~26 ~125 ~7 ~28 glowstone 0
fill ~125 ~7 ~29 ~132 ~7 ~29 wool 8
fill ~126 ~7 ~26 ~126 ~8 ~26 wool 8
fill ~126 ~7 ~27 ~126 ~8 ~27 wool 8
fill ~126 ~7 ~28 ~126 ~8 ~28 wool 8
fill ~128 ~7 ~26 ~132 ~7 ~26 wool 8
fill ~128 ~7 ~27 ~132 ~7 ~27 wool 8
fill ~128 ~7 ~28 ~132 ~7 ~28 wool 8
fill ~75 ~8 ~19 ~89 ~8 ~19 wool 8
fill ~75 ~8 ~20 ~77 ~8 ~20 wool 8
fill ~75 ~8 ~21 ~75 ~7 ~21 wool 8
fill ~75 ~8 ~22 ~93 ~8 ~22 wool 8
fill ~75 ~8 ~24 ~93 ~8 ~24 wool 8
fill ~75 ~8 ~25 ~93 ~8 ~25 wool 8
fill ~75 ~8 ~26 ~89 ~8 ~26 wool 8
fill ~75 ~8 ~27 ~76 ~8 ~27 wool 8
fill ~75 ~8 ~28 ~77 ~8 ~28 wool 8
fill ~75 ~8 ~29 ~77 ~8 ~29 wool 8
fill ~75 ~8 ~30 ~93 ~8 ~30 wool 8
fill ~75 ~8 ~32 ~93 ~8 ~32 wool 8
fill ~75 ~8 ~33 ~76 ~8 ~33 wool 8
fill ~75 ~8 ~34 ~77 ~8 ~34 wool 8
fill ~75 ~8 ~35 ~77 ~8 ~35 wool 8
fill ~76 ~8 ~18 ~93 ~8 ~18 wool 8
fill ~76 ~8 ~21 ~78 ~8 ~21 wool 14
fill ~76 ~8 ~31 ~93 ~8 ~31 wool 8
fill ~76 ~8 ~36 ~93 ~8 ~36 wool 8
fill ~77 ~8 ~23 ~93 ~8 ~23 wool 8
fill ~77 ~8 ~27 ~78 ~8 ~27 wool 14
fill ~77 ~8 ~33 ~78 ~8 ~33 wool 14
setblock ~78 ~8 ~20 wool 14
fill ~78 ~8 ~28 ~78 ~8 ~29 wool 14
fill ~78 ~8 ~34 ~78 ~8 ~35 wool 14
fill ~79 ~8 ~20 ~83 ~8 ~20 wool 8
fill ~79 ~8 ~21 ~81 ~8 ~21 wool 8
fill ~79 ~8 ~27 ~79 ~8 ~36 wool 8
fill ~80 ~8 ~35 ~93 ~8 ~35 wool 8
fill ~81 ~8 ~27 ~83 ~8 ~27 wool 8
fill ~81 ~8 ~28 ~89 ~8 ~28 wool 8
fill ~81 ~8 ~29 ~93 ~8 ~29 wool 8
fill ~81 ~8 ~33 ~81 ~8 ~36 wool 8
fill ~82 ~8 ~21 ~84 ~8 ~21 wool 14
fill ~83 ~8 ~33 ~83 ~8 ~36 wool 8
setblock ~84 ~8 ~20 wool 14
fill ~84 ~8 ~33 ~86 ~8 ~33 wool 14
fill ~84 ~8 ~34 ~84 ~8 ~33 wool 14
fill ~85 ~8 ~20 ~85 ~8 ~32 wool 8
fill ~85 ~8 ~34 ~89 ~8 ~34 wool 8
setblock ~86 ~8 ~27 wool 8
fill ~87 ~8 ~20 ~87 ~8 ~36 wool 8
fill ~88 ~8 ~33 ~89 ~8 ~33 wool 8
fill ~89 ~8 ~20 ~89 ~8 ~36 wool 8
fill ~90 ~8 ~19 ~90 ~8 ~21 wool 14
fill ~90 ~8 ~26 ~91 ~8 ~26 wool 14
fill ~90 ~8 ~27 ~91 ~8 ~27 wool 14
fill ~90 ~8 ~28 ~91 ~8 ~28 wool 14
fill ~90 ~8 ~33 ~92 ~8 ~33 wool 14
fill ~90 ~8 ~34 ~92 ~8 ~34 wool 14
fill ~91 ~8 ~19 ~93 ~8 ~19 wool 8
fill ~91 ~8 ~20 ~93 ~8 ~20 wool 8
setblock ~91 ~8 ~21 wool 14
fill ~92 ~8 ~21 ~93 ~8 ~21 wool 8
fill ~92 ~8 ~26 ~93 ~8 ~26 wool 8
fill ~92 ~8 ~27 ~93 ~8 ~27 wool 8
fill ~92 ~8 ~28 ~93 ~8 ~28 wool 8
fill ~93 ~8 ~33 ~93 ~8 ~36 wool 8
fill ~114 ~8 ~19 ~128 ~8 ~19 wool 8
fill ~114 ~8 ~20 ~116 ~8 ~20 wool 8
fill ~114 ~8 ~21 ~114 ~7 ~21 wool 8
fill ~114 ~8 ~22 ~132 ~8 ~22 wool 8
fill ~114 ~8 ~24 ~132 ~8 ~24 wool 8
fill ~114 ~8 ~25 ~132 ~8 ~25 wool 8
fill ~114 ~8 ~26 ~128 ~8 ~26 wool 8
fill ~114 ~8 ~27 ~115 ~8 ~27 wool 8
fill ~114 ~8 ~28 ~116 ~8 ~28 wool 8
fill ~114 ~8 ~29 ~116 ~8 ~29 wool 8
fill ~114 ~8 ~30 ~132 ~8 ~30 wool 8
fill ~114 ~8 ~32 ~132 ~8 ~32 wool 8
fill ~114 ~8 ~33 ~115 ~8 ~33 wool 8
fill ~114 ~8 ~34 ~116 ~8 ~34 wool 8
fill ~114 ~8 ~35 ~116 ~8 ~35 wool 8
fill ~115 ~8 ~18 ~132 ~8 ~18 wool 8
fill ~115 ~8 ~21 ~117 ~8 ~21 wool 14
fill ~115 ~8 ~31 ~132 ~8 ~31 wool 8
fill ~115 ~8 ~36 ~132 ~8 ~36 wool 8
fill ~116 ~8 ~23 ~132 ~8 ~23 wool 8
fill ~116 ~8 ~27 ~117 ~8 ~27 wool 14
fill ~116 ~8 ~33 ~117 ~8 ~33 wool 14
setblock ~117 ~8 ~20 wool 14
fill ~117 ~8 ~28 ~117 ~8 ~29 wool 14
fill ~117 ~8 ~34 ~117 ~8 ~35 wool 14
fill ~118 ~8 ~20 ~122 ~8 ~20 wool 8
fill ~118 ~8 ~21 ~120 ~8 ~21 wool 8
fill ~118 ~8 ~27 ~118 ~8 ~36 wool 8
fill ~119 ~8 ~35 ~132 ~8 ~35 wool 8
fill ~120 ~8 ~27 ~122 ~8 ~27 wool 8
fill ~120 ~8 ~28 ~128 ~8 ~28 wool 8
fill ~120 ~8 ~29 ~132 ~8 ~29 wool 8
fill ~120 ~8 ~33 ~120 ~8 ~36 wool 8
fill ~121 ~8 ~21 ~123 ~8 ~21 wool 14
fill ~122 ~8 ~33 ~122 ~8 ~36 wool 8
setblock ~123 ~8 ~20 wool 14
fill ~123 ~8 ~33 ~125 ~8 ~33 wool 14
fill ~123 ~8 ~34 ~123 ~8 ~33 wool 14
fill ~124 ~8 ~20 ~124 ~8 ~32 wool 8
fill ~124 ~8 ~34 ~128 ~8 ~34 wool 8
setblock ~125 ~8 ~27 wool 8
fill ~126 ~8 ~20 ~126 ~8 ~36 wool 8
fill ~127 ~8 ~33 ~128 ~8 ~33 wool 8
fill ~128 ~8 ~20 ~128 ~8 ~36 wool 8
fill ~129 ~8 ~19 ~129 ~8 ~21 wool 14
fill ~129 ~8 ~26 ~130 ~8 ~26 wool 14
fill ~129 ~8 ~27 ~130 ~8 ~27 wool 14
fill ~129 ~8 ~28 ~130 ~8 ~28 wool 14
fill ~129 ~8 ~33 ~131 ~8 ~33 wool 14
fill ~129 ~8 ~34 ~131 ~8 ~34 wool 14
fill ~130 ~8 ~19 ~132 ~8 ~19 wool 8
fill ~130 ~8 ~20 ~132 ~8 ~20 wool 8
setblock ~130 ~8 ~21 wool 14
fill ~131 ~8 ~21 ~132 ~8 ~21 wool 8
fill ~131 ~8 ~26 ~132 ~8 ~26 wool 8
fill ~131 ~8 ~27 ~132 ~8 ~27 wool 8
fill ~131 ~8 ~28 ~132 ~8 ~28 wool 8
fill ~132 ~8 ~33 ~132 ~8 ~36 wool 8
fill ~75 ~9 ~19 ~75 ~11 ~19 glass 0
fill ~75 ~9 ~20 ~75 ~11 ~20 glass 0
fill ~75 ~9 ~21 ~75 ~11 ~21 glass 0
fill ~75 ~9 ~22 ~75 ~11 ~22 glass 0
fill ~75 ~9 ~24 ~76 ~9 ~24 wool 8
fill ~75 ~9 ~25 ~80 ~9 ~25 wool 8
fill ~75 ~9 ~26 ~75 ~11 ~26 glass 0
fill ~75 ~9 ~27 ~75 ~11 ~27 glass 0
fill ~75 ~9 ~28 ~75 ~11 ~28 glass 0
fill ~75 ~9 ~29 ~75 ~11 ~29 glass 0
fill ~75 ~9 ~30 ~80 ~9 ~30 wool 8
fill ~75 ~9 ~32 ~75 ~11 ~32 glass 0
fill ~75 ~9 ~33 ~75 ~11 ~33 glass 0
fill ~75 ~9 ~34 ~75 ~11 ~34 glass 0
fill ~75 ~9 ~35 ~75 ~11 ~35 glass 0
fill ~76 ~9 ~18 ~79 ~9 ~18 glass 0
setblock ~76 ~9 ~19 stone_stairs 3
fill ~76 ~9 ~20 ~77 ~9 ~20 wool 12
fill ~76 ~9 ~26 ~76 ~10 ~26 bookshelf 0
setblock ~76 ~9 ~29 stone_stairs 1
fill ~76 ~9 ~31 ~80 ~9 ~31 wool 8
fill ~76 ~9 ~32 ~76 ~10 ~32 bookshelf 0
setblock ~76 ~9 ~35 stone_stairs 1
fill ~76 ~9 ~36 ~79 ~9 ~36 glass 0
setblock ~77 ~9 ~23 wooden_door 3
setblock ~77 ~9 ~24 stone_pressure_plate 0
fill ~77 ~9 ~28 ~77 ~9 ~29 wool 12
fill ~77 ~9 ~34 ~77 ~9 ~35 wool 12
fill ~78 ~9 ~23 ~83 ~9 ~23 wool 8
fill ~79 ~9 ~19 ~79 ~10 ~19 bookshelf 0
fill ~79 ~9 ~22 ~79 ~10 ~22 fence 0
fill ~79 ~9 ~29 ~79 ~10 ~29 fence 0
fill ~79 ~9 ~32 ~79 ~10 ~32 fence 0
fill ~80 ~9 ~18 ~81 ~9 ~18 wool 8
fill ~80 ~9 ~19 ~81 ~9 ~19 wool 8
fill ~80 ~9 ~20 ~81 ~9 ~20 wool 8
fill ~80 ~9 ~21 ~81 ~9 ~21 wool 8
fill ~80 ~9 ~22 ~81 ~9 ~22 wool 8
setblock ~80 ~9 ~27 wooden_door 2
setblock ~80 ~9 ~34 wooden_door 2
fill ~80 ~9 ~35 ~82 ~9 ~35 wool 8
setblock ~81 ~9 ~27 stone_pressure_plate 0
setblock ~81 ~9 ~34 stone_pressure_plate 0
fill ~81 ~9 ~36 ~82 ~9 ~36 wool 8
fill ~82 ~9 ~18 ~85 ~9 ~18 glass 0
setblock ~82 ~9 ~19 stone_stairs 3
fill ~82 ~9 ~20 ~83 ~9 ~20 wool 12
fill ~82 ~9 ~22 ~82 ~10 ~22 fence 0
fill ~82 ~9 ~31 ~83 ~9 ~31 wool 8
fill ~83 ~9 ~35 ~83 ~10 ~35 bookshelf 0
fill ~83 ~9 ~36 ~86 ~9 ~36 glass 0
setblock ~84 ~9 ~23 wooden_door 3
setblock ~84 ~9 ~24 stone_pressure_plate 0
setblock ~84 ~9 ~30 stone_pressure_plate 0
setblock ~84 ~9 ~31 wooden_door 1
fill ~85 ~9 ~19 ~85 ~10 ~19 bookshelf 0
fill ~85 ~9 ~23 ~86 ~9 ~23 wool 8
fill ~85 ~9 ~31 ~90 ~9 ~31 wool 8
fill ~85 ~9 ~34 ~86 ~9 ~34 wool 12
fill ~86 ~9 ~18 ~88 ~9 ~18 wool 8
fill ~86 ~9 ~19 ~88 ~9 ~19 wool 8
fill ~86 ~9 ~32 ~86 ~10 ~32 fence 0
setblock ~86 ~9 ~35 stone_stairs 2
setblock ~87 ~9 ~20 stone_pressure_plate 0
setblock ~87 ~9 ~27 stone_pressure_plate 0
fill ~87 ~9 ~32 ~88 ~9 ~32 wool 8
fill ~87 ~9 ~33 ~88 ~9 ~33 wool 8
fill ~87 ~9 ~34 ~88 ~9 ~34 wool 8
fill ~87 ~9 ~35 ~88 ~9 ~35 wool 8
setblock ~88 ~9 ~20 wooden_door 0
fill ~88 ~9 ~24 ~93 ~9 ~24 wool 8
setblock ~88 ~9 ~27 wooden_door 0
fill ~88 ~9 ~29 ~93 ~9 ~29 wool 8
fill ~89 ~9 ~18 ~92 ~9 ~18 glass 0
fill ~89 ~9 ~22 ~89 ~10 ~22 fence 0
fill ~89 ~9 ~23 ~93 ~9 ~23 wool 8
fill ~89 ~9 ~25 ~89 ~10 ~25 fence 0
fill ~89 ~9 ~28 ~89 ~10 ~28 bookshelf 0
fill ~89 ~9 ~32 ~89 ~10 ~32 fence 0
fill ~89 ~9 ~35 ~89 ~10 ~35 bookshelf 0
fill ~89 ~9 ~36 ~92 ~9 ~36 glass 0
fill ~91 ~9 ~19 ~91 ~9 ~20 wool 12
fill ~91 ~9 ~27 ~91 ~9 ~28 wool 12
setblock ~91 ~9 ~30 stone_pressure_plate 0
setblock ~91 ~9 ~31 wooden_door 1
fill ~91 ~9 ~34 ~92 ~9 ~34 wool 12
setblock ~92 ~9 ~19 stone_stairs 0
fill ~92 ~9 ~22 ~92 ~10 ~22 bookshelf 0
setblock ~92 ~9 ~28 stone_stairs 0
fill ~92 ~9 ~30 ~93 ~9 ~30 wool 8
setblock ~92 ~9 ~35 stone_stairs 2
fill ~93 ~9 ~19 ~93 ~11 ~19 glass 0
fill ~93 ~9 ~20 ~93 ~11 ~20 glass 0
fill ~93 ~9 ~21 ~93 ~11 ~21 glass 0
fill ~93 ~9 ~22 ~93 ~11 ~22 glass 0
fill ~93 ~9 ~25 ~93 ~11 ~25 glass 0
fill ~93 ~9 ~26 ~93 ~11 ~26 glass 0
fill ~93 ~9 ~27 ~93 ~11 ~27 glass 0
fill ~93 ~9 ~28 ~93 ~11 ~28 glass 0
fill ~93 ~9 ~32 ~93 ~11 ~32 glass 0
fill ~93 ~9 ~33 ~93 ~11 ~33 glass 0
fill ~93 ~9 ~34 ~93 ~11 ~34 glass 0
fill ~93 ~9 ~35 ~93 ~11 ~35 glass 0
fill ~114 ~9 ~19 ~114 ~11 ~19 glass 0
fill ~114 ~9 ~20 ~114 ~11 ~20 glass 0
fill ~114 ~9 ~21 ~114 ~11 ~21 glass 0
fill ~114 ~9 ~22 ~114 ~11 ~22 glass 0
fill ~114 ~9 ~24 ~115 ~9 ~24 wool 8
fill ~114 ~9 ~25 ~119 ~9 ~25 wool 8
fill ~114 ~9 ~26 ~114 ~11 ~26 glass 0
fill ~114 ~9 ~27 ~114 ~11 ~27 glass 0
fill ~114 ~9 ~28 ~114 ~11 ~28 glass 0
fill ~114 ~9 ~29 ~114 ~11 ~29 glass 0
fill ~114 ~9 ~30 ~119 ~9 ~30 wool 8
fill ~114 ~9 ~32 ~114 ~11 ~32 glass 0
fill ~114 ~9 ~33 ~114 ~11 ~33 glass 0
fill ~114 ~9 ~34 ~114 ~11 ~34 glass 0
fill ~114 ~9 ~35 ~114 ~11 ~35 glass 0
fill ~115 ~9 ~18 ~118 ~9 ~18 glass 0
setblock ~115 ~9 ~19 stone_stairs 3
fill ~115 ~9 ~20 ~116 ~9 ~20 wool 12
fill ~115 ~9 ~26 ~115 ~10 ~26 bookshelf 0
setblock ~115 ~9 ~29 stone_stairs 1
fill ~115 ~9 ~31 ~119 ~9 ~31 wool 8
fill ~115 ~9 ~32 ~115 ~10 ~32 bookshelf 0
setblock ~115 ~9 ~35 stone_stairs 1
fill ~115 ~9 ~36 ~118 ~9 ~36 glass 0
setblock ~116 ~9 ~23 wooden_door 3
setblock ~116 ~9 ~24 stone_pressure_plate 0
fill ~116 ~9 ~28 ~116 ~9 ~29 wool 12
fill ~116 ~9 ~34 ~116 ~9 ~35 wool 12
fill ~117 ~9 ~23 ~122 ~9 ~23 wool 8
fill ~118 ~9 ~19 ~118 ~10 ~19 bookshelf 0
fill ~118 ~9 ~22 ~118 ~10 ~22 fence 0
fill ~118 ~9 ~29 ~118 ~10 ~29 fence 0
fill ~118 ~9 ~32 ~118 ~10 ~32 fence 0
fill ~119 ~9 ~18 ~120 ~9 ~18 wool 8
fill ~119 ~9 ~19 ~120 ~9 ~19 wool 8
fill ~119 ~9 ~20 ~120 ~9 ~20 wool 8
fill ~119 ~9 ~21 ~120 ~9 ~21 wool 8
fill ~119 ~9 ~22 ~120 ~9 ~22 wool 8
setblock ~119 ~9 ~27 wooden_door 2
setblock ~119 ~9 ~34 wooden_door 2
fill ~119 ~9 ~35 ~121 ~9 ~35 wool 8
setblock ~120 ~9 ~27 stone_pressure_plate 0
setblock ~120 ~9 ~34 stone_pressure_plate 0
fill ~120 ~9 ~36 ~121 ~9 ~36 wool 8
fill ~121 ~9 ~18 ~124 ~9 ~18 glass 0
setblock ~121 ~9 ~19 stone_stairs 3
fill ~121 ~9 ~20 ~122 ~9 ~20 wool 12
fill ~121 ~9 ~22 ~121 ~10 ~22 fence 0
fill ~121 ~9 ~31 ~122 ~9 ~31 wool 8
fill ~122 ~9 ~35 ~122 ~10 ~35 bookshelf 0
fill ~122 ~9 ~36 ~125 ~9 ~36 glass 0
setblock ~123 ~9 ~23 wooden_door 3
setblock ~123 ~9 ~24 stone_pressure_plate 0
setblock ~123 ~9 ~30 stone_pressure_plate 0
setblock ~123 ~9 ~31 wooden_door 1
fill ~124 ~9 ~19 ~124 ~10 ~19 bookshelf 0
fill ~124 ~9 ~23 ~125 ~9 ~23 wool 8
fill ~124 ~9 ~31 ~129 ~9 ~31 wool 8
fill ~124 ~9 ~34 ~125 ~9 ~34 wool 12
fill ~125 ~9 ~18 ~127 ~9 ~18 wool 8
fill ~125 ~9 ~19 ~127 ~9 ~19 wool 8
fill ~125 ~9 ~32 ~125 ~10 ~32 fence 0
setblock ~125 ~9 ~35 stone_stairs 2
setblock ~126 ~9 ~20 stone_pressure_plate 0
setblock ~126 ~9 ~27 stone_pressure_plate 0
fill ~126 ~9 ~32 ~127 ~9 ~32 wool 8
fill ~126 ~9 ~33 ~127 ~9 ~33 wool 8
fill ~126 ~9 ~34 ~127 ~9 ~34 wool 8
fill ~126 ~9 ~35 ~127 ~9 ~35 wool 8
setblock ~127 ~9 ~20 wooden_door 0
fill ~127 ~9 ~24 ~132 ~9 ~24 wool 8
setblock ~127 ~9 ~27 wooden_door 0
fill ~127 ~9 ~29 ~132 ~9 ~29 wool 8
fill ~128 ~9 ~18 ~131 ~9 ~18 glass 0
fill ~128 ~9 ~22 ~128 ~10 ~22 fence 0
fill ~128 ~9 ~23 ~132 ~9 ~23 wool 8
fill ~128 ~9 ~25 ~128 ~10 ~25 fence 0
fill ~128 ~9 ~28 ~128 ~10 ~28 bookshelf 0
fill ~128 ~9 ~32 ~128 ~10 ~32 fence 0
fill ~128 ~9 ~35 ~128 ~10 ~35 bookshelf 0
fill ~128 ~9 ~36 ~131 ~9 ~36 glass 0
fill ~130 ~9 ~19 ~130 ~9 ~20 wool 12
fill ~130 ~9 ~27 ~130 ~9 ~28 wool 12
setblock ~130 ~9 ~30 stone_pressure_plate 0
setblock ~130 ~9 ~31 wooden_door 1
fill ~130 ~9 ~34 ~131 ~9 ~34 wool 12
setblock ~131 ~9 ~19 stone_stairs 0
fill ~131 ~9 ~22 ~131 ~10 ~22 bookshelf 0
setblock ~131 ~9 ~28 stone_stairs 0
fill ~131 ~9 ~30 ~132 ~9 ~30 wool 8
setblock ~131 ~9 ~35 stone_stairs 2
fill ~132 ~9 ~19 ~132 ~11 ~19 glass 0
fill ~132 ~9 ~20 ~132 ~11 ~20 glass 0
fill ~132 ~9 ~21 ~132 ~11 ~21 glass 0
fill ~132 ~9 ~22 ~132 ~11 ~22 glass 0
fill ~132 ~9 ~25 ~132 ~11 ~25 glass 0
fill ~132 ~9 ~26 ~132 ~11 ~26 glass 0
fill ~132 ~9 ~27 ~132 ~11 ~27 glass 0
fill ~132 ~9 ~28 ~132 ~11 ~28 glass 0
fill ~132 ~9 ~32 ~132 ~11 ~32 glass 0
fill ~132 ~9 ~33 ~132 ~11 ~33 glass 0
fill ~132 ~9 ~34 ~132 ~11 ~34 glass 0
fill ~132 ~9 ~35 ~132 ~11 ~35 glass 0
fill ~75 ~10 ~24 ~76 ~10 ~24 wool 8
fill ~75 ~10 ~25 ~80 ~10 ~25 wool 8
fill ~75 ~10 ~30 ~80 ~10 ~30 wool 8
fill ~76 ~10 ~18 ~79 ~10 ~18 glass 0
fill ~76 ~10 ~31 ~80 ~10 ~31 wool 8
fill ~76 ~10 ~36 ~79 ~10 ~36 glass 0
setblock ~77 ~10 ~23 wooden_door 11
fill ~78 ~10 ~23 ~83 ~10 ~23 wool 8
fill ~80 ~10 ~18 ~81 ~10 ~18 wool 8
fill ~80 ~10 ~19 ~81 ~10 ~19 wool 8
fill ~80 ~10 ~20 ~81 ~10 ~20 wool 8
fill ~80 ~10 ~21 ~81 ~10 ~21 wool 8
fill ~80 ~10 ~22 ~81 ~10 ~22 wool 8
setblock ~80 ~10 ~27 wooden_door 10
setblock ~80 ~10 ~34 wooden_door 10
fill ~80 ~10 ~35 ~82 ~10 ~35 wool 8
fill ~81 ~10 ~36 ~82 ~10 ~36 wool 8
fill ~82 ~10 ~18 ~85 ~10 ~18 glass 0
fill ~82 ~10 ~31 ~83 ~10 ~31 wool 8
setblock ~83 ~10 ~28 wool 8
fill ~83 ~10 ~36 ~86 ~10 ~36 glass 0
setblock ~84 ~10 ~23 wooden_door 11
setblock ~84 ~10 ~31 wooden_door 9
fill ~85 ~10 ~23 ~86 ~10 ~23 wool 8
fill ~85 ~10 ~31 ~90 ~10 ~31 wool 8
fill ~86 ~10 ~18 ~88 ~10 ~18 wool 8
fill ~86 ~10 ~19 ~88 ~10 ~19 wool 8
fill ~87 ~10 ~32 ~88 ~10 ~32 wool 8
fill ~87 ~10 ~33 ~88 ~10 ~33 wool 8
fill ~87 ~10 ~34 ~88 ~10 ~34 wool 8
fill ~87 ~10 ~35 ~88 ~10 ~35 wool 8
setblock ~88 ~10 ~20 wooden_door 8
fill ~88 ~10 ~24 ~93 ~10 ~24 wool 8
setblock ~88 ~10 ~27 wooden_door 8
fill ~88 ~10 ~29 ~93 ~10 ~29 wool 8
fill ~89 ~10 ~18 ~92 ~10 ~18 glass 0
fill ~89 ~10 ~23 ~93 ~10 ~23 wool 8
fill ~89 ~10 ~36 ~92 ~10 ~36 glass 0
setblock ~91 ~10 ~31 wooden_door 9
fill ~92 ~10 ~30 ~93 ~10 ~30 wool 8
fill ~114 ~10 ~24 ~115 ~10 ~24 wool 8
fill ~114 ~10 ~25 ~119 ~10 ~25 wool 8
fill ~114 ~10 ~30 ~119 ~10 ~30 wool 8
fill ~115 ~10 ~18 ~118 ~10 ~18 glass 0
fill ~115 ~10 ~31 ~119 ~10 ~31 wool 8
fill ~115 ~10 ~36 ~118 ~10 ~36 glass 0
setblock ~116 ~10 ~23 wooden_door 11
fill ~117 ~10 ~23 ~122 ~10 ~23 wool 8
fill ~119 ~10 ~18 ~120 ~10 ~18 wool 8
fill ~119 ~10 ~19 ~120 ~10 ~19 wool 8
fill ~119 ~10 ~20 ~120 ~10 ~20 wool 8
fill ~119 ~10 ~21 ~120 ~10 ~21 wool 8
fill ~119 ~10 ~22 ~120 ~10 ~22 wool 8
setblock ~119 ~10 ~27 wooden_door 10
setblock ~119 ~10 ~34 wooden_door 10
fill ~119 ~10 ~35 ~121 ~10 ~35 wool 8
fill ~120 ~10 ~36 ~121 ~10 ~36 wool 8
fill ~121 ~10 ~18 ~124 ~10 ~18 glass 0
fill ~121 ~10 ~31 ~122 ~10 ~31 wool 8
setblock ~122 ~10 ~28 wool 8
fill ~122 ~10 ~36 ~125 ~10 ~36 glass 0
setblock ~123 ~10 ~23 wooden_door 11
setblock ~123 ~10 ~31 wooden_door 9
fill ~124 ~10 ~23 ~125 ~10 ~23 wool 8
fill ~124 ~10 ~31 ~129 ~10 ~31 wool 8
fill ~125 ~10 ~18 ~127 ~10 ~18 wool 8
fill ~125 ~10 ~19 ~127 ~10 ~19 wool 8
fill ~126 ~10 ~32 ~127 ~10 ~32 wool 8
fill ~126 ~10 ~33 ~127 ~10 ~33 wool 8
fill ~126 ~10 ~34 ~127 ~10 ~34 wool 8
fill ~126 ~10 ~35 ~127 ~10 ~35 wool 8
setblock ~127 ~10 ~20 wooden_door 8
fill ~127 ~10 ~24 ~132 ~10 ~24 wool 8
setblock ~127 ~10 ~27 wooden_door 8
fill ~127 ~10 ~29 ~132 ~10 ~29 wool 8
fill ~128 ~10 ~18 ~131 ~10 ~18 glass 0
fill ~128 ~10 ~23 ~132 ~10 ~23 wool 8
fill ~128 ~10 ~36 ~131 ~10 ~36 glass 0
setblock ~130 ~10 ~31 wooden_door 9
fill ~131 ~10 ~30 ~132 ~10 ~30 wool 8
fill ~75 ~11 ~24 ~76 ~11 ~24 wool 8
fill ~75 ~11 ~25 ~80 ~11 ~25 wool 8
fill ~75 ~11 ~30 ~80 ~11 ~30 wool 8
fill ~76 ~11 ~18 ~79 ~11 ~18 glass 0
fill ~76 ~11 ~31 ~93 ~11 ~31 wool 8
fill ~76 ~11 ~36 ~79 ~11 ~36 glass 0
fill ~77 ~11 ~23 ~93 ~11 ~23 wool 8
setblock ~79 ~11 ~22 glowstone 0
setblock ~79 ~11 ~29 glowstone 0
setblock ~79 ~11 ~32 glowstone 0
fill ~80 ~11 ~18 ~81 ~11 ~18 wool 8
fill ~80 ~11 ~19 ~81 ~11 ~19 wool 8
fill ~80 ~11 ~20 ~81 ~11 ~20 wool 8
fill ~80 ~11 ~21 ~81 ~11 ~21 wool 8
fill ~80 ~11 ~22 ~81 ~11 ~22 wool 8
fill ~80 ~11 ~24 ~80 ~13 ~24 wool 8
fill ~80 ~11 ~27 ~80 ~13 ~27 wool 8
fill ~80 ~11 ~34 ~80 ~13 ~34 wool 8
fill ~80 ~11 ~35 ~82 ~11 ~35 wool 8
fill ~81 ~11 ~36 ~82 ~11 ~36 wool 8
fill ~82 ~11 ~18 ~85 ~11 ~18 glass 0
setblock ~82 ~11 ~22 glowstone 0
fill ~83 ~11 ~36 ~86 ~11 ~36 glass 0
fill ~86 ~11 ~18 ~88 ~11 ~18 wool 8
fill ~86 ~11 ~19 ~88 ~11 ~19 wool 8
setblock ~86 ~11 ~32 glowstone 0
fill ~87 ~11 ~32 ~88 ~11 ~32 wool 8
fill ~87 ~11 ~33 ~88 ~11 ~33 wool 8
fill ~87 ~11 ~34 ~88 ~11 ~34 wool 8
fill ~87 ~11 ~35 ~88 ~11 ~35 wool 8
fill ~88 ~11 ~20 ~88 ~13 ~20 wool 8
fill ~88 ~11 ~24 ~93 ~11 ~24 wool 8
fill ~88 ~11 ~27 ~88 ~13 ~27 wool 8
fill ~88 ~11 ~29 ~93 ~11 ~29 wool 8
fill ~88 ~11 ~30 ~88 ~13 ~30 wool 8
fill ~89 ~11 ~18 ~92 ~11 ~18 glass 0
setblock ~89 ~11 ~22 glowstone 0
setblock ~89 ~11 ~25 glowstone 0
setblock ~89 ~11 ~32 glowstone 0
fill ~89 ~11 ~36 ~92 ~11 ~36 glass 0
fill ~92 ~11 ~30 ~93 ~11 ~30 wool 8
fill ~114 ~11 ~24 ~115 ~11 ~24 wool 8
fill ~114 ~11 ~25 ~119 ~11 ~25 wool 8
fill ~114 ~11 ~30 ~119 ~11 ~30 wool 8
fill ~115 ~11 ~18 ~118 ~11 ~18 glass 0
fill ~115 ~11 ~31 ~132 ~11 ~31 wool 8
fill ~115 ~11 ~36 ~118 ~11 ~36 glass 0
fill ~116 ~11 ~23 ~132 ~11 ~23 wool 8
setblock ~118 ~11 ~22 glowstone 0
setblock ~118 ~11 ~29 glowstone 0
setblock ~118 ~11 ~32 glowstone 0
fill ~119 ~11 ~18 ~120 ~11 ~18 wool 8
fill ~119 ~11 ~19 ~120 ~11 ~19 wool 8
fill ~119 ~11 ~20 ~120 ~11 ~20 wool 8
fill ~119 ~11 ~21 ~120 ~11 ~21 wool 8
fill ~119 ~11 ~22 ~120 ~11 ~22 wool 8
fill ~119 ~11 ~24 ~119 ~13 ~24 wool 8
fill ~119 ~11 ~27 ~119 ~13 ~27 wool 8
fill ~119 ~11 ~34 ~119 ~13 ~34 wool 8
fill ~119 ~11 ~35 ~121 ~11 ~35 wool 8
fill ~120 ~11 ~36 ~121 ~11 ~36 wool 8
fill ~121 ~11 ~18 ~124 ~11 ~18 glass 0
setblock ~121 ~11 ~22 glowstone 0
fill ~122 ~11 ~36 ~125 ~11 ~36 glass 0
fill ~125 ~11 ~18 ~127 ~11 ~18 wool 8
fill ~125 ~11 ~19 ~127 ~11 ~19 wool 8
setblock ~125 ~11 ~32 glowstone 0
fill ~126 ~11 ~32 ~127 ~11 ~32 wool 8
fill ~126 ~11 ~33 ~127 ~11 ~33 wool 8
fill ~126 ~11 ~34 ~127 ~11 ~34 wool 8
fill ~126 ~11 ~35 ~127 ~11 ~35 wool 8
fill ~127 ~11 ~20 ~127 ~13 ~20 wool 8
fill ~127 ~11 ~24 ~132 ~11 ~24 wool 8
fill ~127 ~11 ~27 ~127 ~13 ~27 wool 8
fill ~127 ~11 ~29 ~132 ~11 ~29 wool 8
fill ~127 ~11 ~30 ~127 ~13 ~30 wool 8
fill ~128 ~11 ~18 ~131 ~11 ~18 glass 0
setblock ~128 ~11 ~22 glowstone 0
setblock ~128 ~11 ~25 glowstone 0
setblock ~128 ~11 ~32 glowstone 0
fill ~128 ~11 ~36 ~131 ~11 ~36 glass 0
fill ~131 ~11 ~30 ~132 ~11 ~30 wool 8
fill ~75 ~12 ~19 ~93 ~12 ~19 wool 8
fill ~75 ~12 ~20 ~93 ~12 ~20 wool 8
fill ~75 ~12 ~21 ~93 ~12 ~21 wool 8
fill ~75 ~12 ~22 ~93 ~12 ~22 wool 8
fill ~75 ~12 ~24 ~93 ~12 ~24 wool 8
fill ~75 ~12 ~25 ~82 ~12 ~25 wool 8
fill ~75 ~12 ~26 ~81 ~12 ~26 wool 8
fill ~75 ~12 ~27 ~81 ~12 ~27 wool 8
fill ~75 ~12 ~28 ~81 ~12 ~28 wool 8
fill ~75 ~12 ~29 ~82 ~12 ~29 wool 8
fill ~75 ~12 ~30 ~93 ~12 ~30 wool 8
fill ~75 ~12 ~32 ~93 ~12 ~32 wool 8
fill ~75 ~12 ~33 ~93 ~12 ~33 wool 8
fill ~75 ~12 ~34 ~93 ~12 ~34 wool 8
fill ~75 ~12 ~35 ~93 ~12 ~35 wool 8
fill ~76 ~12 ~18 ~93 ~12 ~18 wool 8
fill ~76 ~12 ~31 ~93 ~12 ~31 wool 8
fill ~76 ~12 ~36 ~93 ~12 ~36 wool 8
fill ~77 ~12 ~23 ~93 ~12 ~23 wool 8
fill ~82 ~12 ~26 ~82 ~12 ~28 glowstone 0
fill ~83 ~12 ~25 ~85 ~12 ~25 glowstone 0
fill ~83 ~12 ~26 ~85 ~12 ~26 wool 8
fill ~83 ~12 ~27 ~83 ~13 ~27 wool 8
fill ~83 ~12 ~28 ~83 ~13 ~28 wool 8
fill ~83 ~12 ~29 ~85 ~12 ~29 glowstone 0
fill ~85 ~12 ~27 ~85 ~13 ~27 wool 8
fill ~85 ~12 ~28 ~85 ~13 ~28 wool 8
fill ~86 ~12 ~25 ~93 ~12 ~25 wool 8
fill ~86 ~12 ~26 ~86 ~12 ~28 glowstone 0
fill ~86 ~12 ~29 ~93 ~12 ~29 wool 8
fill ~87 ~12 ~26 ~87 ~13 ~26 wool 8
fill ~87 ~12 ~27 ~87 ~13 ~27 wool 8
fill ~87 ~12 ~28 ~87 ~13 ~28 wool 8
fill ~89 ~12 ~26 ~93 ~12 ~26 wool 8
fill ~89 ~12 ~27 ~93 ~12 ~27 wool 8
fill ~89 ~12 ~28 ~93 ~12 ~28 wool 8
fill ~114 ~12 ~19 ~132 ~12 ~19 wool 8
fill ~114 ~12 ~20 ~132 ~12 ~20 wool 8
fill ~114 ~12 ~21 ~132 ~12 ~21 wool 8
fill ~114 ~12 ~22 ~132 ~12 ~22 wool 8
fill ~114 ~12 ~24 ~132 ~12 ~24 wool 8
fill ~114 ~12 ~25 ~121 ~12 ~25 wool 8
fill ~114 ~12 ~26 ~120 ~12 ~26 wool 8
fill ~114 ~12 ~27 ~120 ~12 ~27 wool 8
fill ~114 ~12 ~28 ~120 ~12 ~28 wool 8
fill ~114 ~12 ~29 ~121 ~12 ~29 wool 8
fill ~114 ~12 ~30 ~132 ~12 ~30 wool 8
fill ~114 ~12 ~32 ~132 ~12 ~32 wool 8
fill ~114 ~12 ~33 ~132 ~12 ~33 wool 8
fill ~114 ~12 ~34 ~132 ~12 ~34 wool 8
fill ~114 ~12 ~35 ~132 ~12 ~35 wool 8
fill ~115 ~12 ~18 ~132 ~12 ~18 wool 8
fill ~115 ~12 ~31 ~132 ~12 ~31 wool 8
fill ~115 ~12 ~36 ~132 ~12 ~36 wool 8
fill ~116 ~12 ~23 ~132 ~12 ~23 wool 8
fill ~121 ~12 ~26 ~121 ~12 ~28 glowstone 0
fill ~122 ~12 ~25 ~124 ~12 ~25 glowstone 0
fill ~122 ~12 ~26 ~124 ~12 ~26 wool 8
fill ~122 ~12 ~27 ~122 ~13 ~27 wool 8
fill ~122 ~12 ~28 ~122 ~13 ~28 wool 8
fill ~122 ~12 ~29 ~124 ~12 ~29 glowstone 0
fill ~124 ~12 ~27 ~124 ~13 ~27 wool 8
fill ~124 ~12 ~28 ~124 ~13 ~28 wool 8
fill ~125 ~12 ~25 ~132 ~12 ~25 wool 8
fill ~125 ~12 ~26 ~125 ~12 ~28 glowstone 0
fill ~125 ~12 ~29 ~132 ~12 ~29 wool 8
fill ~126 ~12 ~26 ~126 ~13 ~26 wool 8
fill ~126 ~12 ~27 ~126 ~13 ~27 wool 8
fill ~126 ~12 ~28 ~126 ~13 ~28 wool 8
fill ~128 ~12 ~26 ~132 ~12 ~26 wool 8
fill ~128 ~12 ~27 ~132 ~12 ~27 wool 8
fill ~128 ~12 ~28 ~132 ~12 ~28 wool 8
fill ~75 ~13 ~19 ~89 ~13 ~19 wool 8
fill ~75 ~13 ~20 ~77 ~13 ~20 wool 8
fill ~75 ~13 ~21 ~75 ~12 ~21 wool 8
fill ~75 ~13 ~22 ~93 ~13 ~22 wool 8
fill ~75 ~13 ~24 ~93 ~13 ~24 wool 8
fill ~75 ~13 ~25 ~93 ~13 ~25 wool 8
fill ~75 ~13 ~26 ~89 ~13 ~26 wool 8
fill ~75 ~13 ~27 ~76 ~13 ~27 wool 8
fill ~75 ~13 ~28 ~77 ~13 ~28 wool 8
fill ~75 ~13 ~29 ~77 ~13 ~29 wool 8
fill ~75 ~13 ~30 ~93 ~13 ~30 wool 8
fill ~75 ~13 ~32 ~93 ~13 ~32 wool 8
fill ~75 ~13 ~33 ~76 ~13 ~33 wool 8
fill ~75 ~13 ~34 ~77 ~13 ~34 wool 8
fill ~75 ~13 ~35 ~77 ~13 ~35 wool 8
fill ~76 ~13 ~18 ~93 ~13 ~18 wool 8
fill ~76 ~13 ~21 ~78 ~13 ~21 wool 14
fill ~76 ~13 ~31 ~93 ~13 ~31 wool 8
fill ~76 ~13 ~36 ~93 ~13 ~36 wool 8
fill ~77 ~13 ~23 ~93 ~13 ~23 wool 8
fill ~77 ~13 ~27 ~78 ~13 ~27 wool 14
fill ~77 ~13 ~33 ~78 ~13 ~33 wool 14
setblock ~78 ~13 ~20 wool 14
fill ~78 ~13 ~28 ~78 ~13 ~29 wool 14
fill ~78 ~13 ~34 ~78 ~13 ~35 wool 14
fill ~79 ~13 ~20 ~83 ~13 ~20 wool 8
fill ~79 ~13 ~21 ~81 ~13 ~21 wool 8
fill ~79 ~13 ~27 ~79 ~13 ~36 wool 8
fill ~80 ~13 ~35 ~93 ~13 ~35 wool 8
fill ~81 ~13 ~27 ~83 ~13 ~27 wool 8
fill ~81 ~13 ~28 ~89 ~13 ~28 wool 8
fill ~81 ~13 ~29 ~93 ~13 ~29 wool 8
fill ~81 ~13 ~33 ~81 ~13 ~36 wool 8
fill ~82 ~13 ~21 ~84 ~13 ~21 wool 14
fill ~83 ~13 ~33 ~83 ~13 ~36 wool 8
setblock ~84 ~13 ~20 wool 14
fill ~84 ~13 ~33 ~86 ~13 ~33 wool 14
fill ~84 ~13 ~34 ~84 ~13 ~33 wool 14
fill ~85 ~13 ~20 ~85 ~13 ~32 wool 8
fill ~85 ~13 ~34 ~89 ~13 ~34 wool 8
setblock ~86 ~13 ~27 wool 8
fill ~87 ~13 ~20 ~87 ~13 ~36 wool 8
fill ~88 ~13 ~33 ~89 ~13 ~33 wool 8
fill ~89 ~13 ~20 ~89 ~13 ~36 wool 8
fill ~90 ~13 ~19 ~90 ~13 ~21 wool 14
fill ~90 ~13 ~26 ~91 ~13 ~26 wool 14
fill ~90 ~13 ~27 ~91 ~13 ~27 wool 14
fill ~90 ~13 ~28 ~91 ~13 ~28 wool 14
fill ~90 ~13 ~33 ~92 ~13 ~33 wool 14
fill ~90 ~13 ~34 ~92 ~13 ~34 wool 14
fill ~91 ~13 ~19 ~93 ~13 ~19 wool 8
fill ~91 ~13 ~20 ~93 ~13 ~20 wool 8
setblock ~91 ~13 ~21 wool 14
fill ~92 ~13 ~21 ~93 ~13 ~21 wool 8
fill ~92 ~13 ~26 ~93 ~13 ~26 wool 8
fill ~92 ~13 ~27 ~93 ~13 ~27 wool 8
fill ~92 ~13 ~28 ~93 ~13 ~28 wool 8
fill ~93 ~13 ~33 ~93 ~13 ~36 wool 8
fill ~114 ~13 ~19 ~128 ~13 ~19 wool 8
fill ~114 ~13 ~20 ~116 ~13 ~20 wool 8
fill ~114 ~13 ~21 ~114 ~12 ~21 wool 8
fill ~114 ~13 ~22 ~132 ~13 ~22 wool 8
fill ~114 ~13 ~24 ~132 ~13 ~24 wool 8
fill ~114 ~13 ~25 ~132 ~13 ~25 wool 8
fill ~114 ~13 ~26 ~128 ~13 ~26 wool 8
fill ~114 ~13 ~27 ~115 ~13 ~27 wool 8
fill ~114 ~13 ~28 ~116 ~13 ~28 wool 8
fill ~114 ~13 ~29 ~116 ~13 ~29 wool 8
fill ~114 ~13 ~30 ~132 ~13 ~30 wool 8
fill ~114 ~13 ~32 ~132 ~13 ~32 wool 8
fill ~114 ~13 ~33 ~115 ~13 ~33 wool 8
fill ~114 ~13 ~34 ~116 ~13 ~34 wool 8
fill ~114 ~13 ~35 ~116 ~13 ~35 wool 8
fill ~115 ~13 ~18 ~132 ~13 ~18 wool 8
fill ~115 ~13 ~21 ~117 ~13 ~21 wool 14
fill ~115 ~13 ~31 ~132 ~13 ~31 wool 8
fill ~115 ~13 ~36 ~132 ~13 ~36 wool 8
fill ~116 ~13 ~23 ~132 ~13 ~23 wool 8
fill ~116 ~13 ~27 ~117 ~13 ~27 wool 14
fill ~116 ~13 ~33 ~117 ~13 ~33 wool 14
setblock ~117 ~13 ~20 wool 14
fill ~117 ~13 ~28 ~117 ~13 ~29 wool 14
fill ~117 ~13 ~34 ~117 ~13 ~35 wool 14
fill ~118 ~13 ~20 ~122 ~13 ~20 wool 8
fill ~118 ~13 ~21 ~120 ~13 ~21 wool 8
fill ~118 ~13 ~27 ~118 ~13 ~36 wool 8
fill ~119 ~13 ~35 ~132 ~13 ~35 wool 8
fill ~120 ~13 ~27 ~122 ~13 ~27 wool 8
fill ~120 ~13 ~28 ~128 ~13 ~28 wool 8
fill ~120 ~13 ~29 ~132 ~13 ~29 wool 8
fill ~120 ~13 ~33 ~120 ~13 ~36 wool 8
fill ~121 ~13 ~21 ~123 ~13 ~21 wool 14
fill ~122 ~13 ~33 ~122 ~13 ~36 wool 8
setblock ~123 ~13 ~20 wool 14
fill ~123 ~13 ~33 ~125 ~13 ~33 wool 14
fill ~123 ~13 ~34 ~123 ~13 ~33 wool 14
fill ~124 ~13 ~20 ~124 ~13 ~32 wool 8
fill ~124 ~13 ~34 ~128 ~13 ~34 wool 8
setblock ~125 ~13 ~27 wool 8
fill ~126 ~13 ~20 ~126 ~13 ~36 wool 8
fill ~127 ~13 ~33 ~128 ~13 ~33 wool 8
fill ~128 ~13 ~20 ~128 ~13 ~36 wool 8
fill ~129 ~13 ~19 ~129 ~13 ~21 wool 14
fill ~129 ~13 ~26 ~130 ~13 ~26 wool 14
fill ~129 ~13 ~27 ~130 ~13 ~27 wool 14
fill ~129 ~13 ~28 ~130 ~13 ~28 wool 14
fill ~129 ~13 ~33 ~131 ~13 ~33 wool 14
fill ~129 ~13 ~34 ~131 ~13 ~34 wool 14
fill ~130 ~13 ~19 ~132 ~13 ~19 wool 8
fill ~130 ~13 ~20 ~132 ~13 ~20 wool 8
setblock ~130 ~13 ~21 wool 14
fill ~131 ~13 ~21 ~132 ~13 ~21 wool 8
fill ~131 ~13 ~26 ~132 ~13 ~26 wool 8
fill ~131 ~13 ~27 ~132 ~13 ~27 wool 8
fill ~131 ~13 ~28 ~132 ~13 ~28 wool 8
fill ~132 ~13 ~33 ~132 ~13 ~36 wool 8
fill ~75 ~14 ~19 ~75 ~16 ~19 glass 0
fill ~75 ~14 ~20 ~75 ~16 ~20 glass 0
fill ~75 ~14 ~21 ~75 ~16 ~21 glass 0
fill ~75 ~14 ~22 ~75 ~16 ~22 glass 0
fill ~75 ~14 ~24 ~76 ~14 ~24 wool 8
fill ~75 ~14 ~25 ~80 ~14 ~25 wool 8
fill ~75 ~14 ~26 ~75 ~16 ~26 glass 0
fill ~75 ~14 ~27 ~75 ~16 ~27 glass 0
fill ~75 ~14 ~28 ~75 ~16 ~28 glass 0
fill ~75 ~14 ~29 ~75 ~16 ~29 glass 0
fill ~75 ~14 ~30 ~80 ~14 ~30 wool 8
fill ~75 ~14 ~32 ~75 ~16 ~32 glass 0
fill ~75 ~14 ~33 ~75 ~16 ~33 glass 0
fill ~75 ~14 ~34 ~75 ~16 ~34 glass 0
fill ~75 ~14 ~35 ~75 ~16 ~35 glass 0
fill ~76 ~14 ~18 ~79 ~14 ~18 glass 0
setblock ~76 ~14 ~19 stone_stairs 3
fill ~76 ~14 ~20 ~77 ~14 ~20 wool 12
fill ~76 ~14 ~26 ~76 ~15 ~26 bookshelf 0
setblock ~76 ~14 ~29 stone_stairs 1
fill ~76 ~14 ~31 ~80 ~14 ~31 wool 8
fill ~76 ~14 ~32 ~76 ~15 ~32 bookshelf 0
setblock ~76 ~14 ~35 stone_stairs 1
fill ~76 ~14 ~36 ~79 ~14 ~36 glass 0
setblock ~77 ~14 ~23 wooden_door 3
setblock ~77 ~14 ~24 stone_pressure_plate 0
fill ~77 ~14 ~28 ~77 ~14 ~29 wool 12
fill ~77 ~14 ~34 ~77 ~14 ~35 wool 12
fill ~78 ~14 ~23 ~83 ~14 ~23 wool 8
fill ~79 ~14 ~19 ~79 ~15 ~19 bookshelf 0
fill ~79 ~14 ~22 ~79 ~15 ~22 fence 0
fill ~79 ~14 ~29 ~79 ~15 ~29 fence 0
fill ~79 ~14 ~32 ~79 ~15 ~32 fence 0
fill ~80 ~14 ~18 ~81 ~14 ~18 wool 8
fill ~80 ~14 ~19 ~81 ~14 ~19 wool 8
fill ~80 ~14 ~20 ~81 ~14 ~20 wool 8
fill ~80 ~14 ~21 ~81 ~14 ~21 wool 8
fill ~80 ~14 ~22 ~81 ~14 ~22 wool 8
setblock ~80 ~14 ~27 wooden_door 2
setblock ~80 ~14 ~34 wooden_door 2
fill ~80 ~14 ~35 ~82 ~14 ~35 wool 8
setblock ~81 ~14 ~27 stone_pressure_plate 0
setblock ~81 ~14 ~34 stone_pressure_plate 0
fill ~81 ~14 ~36 ~82 ~14 ~36 wool 8
fill ~82 ~14 ~18 ~85 ~14 ~18 glass 0
setblock ~82 ~14 ~19 stone_stairs 3
fill ~82 ~14 ~20 ~83 ~14 ~20 wool 12
fill ~82 ~14 ~22 ~82 ~15 ~22 fence 0
fill ~82 ~14 ~31 ~83 ~14 ~31 wool 8
fill ~83 ~14 ~35 ~83 ~15 ~35 bookshelf 0
fill ~83 ~14 ~36 ~86 ~14 ~36 glass 0
setblock ~84 ~14 ~23 wooden_door 3
setblock ~84 ~14 ~24 stone_pressure_plate 0
setblock ~84 ~14 ~30 stone_pressure_plate 0
setblock ~84 ~14 ~31 wooden_door 1
fill ~85 ~14 ~19 ~85 ~15 ~19 bookshelf 0
fill ~85 ~14 ~23 ~86 ~14 ~23 wool 8
fill ~85 ~14 ~31 ~90 ~14 ~31 wool 8
fill ~85 ~14 ~34 ~86 ~14 ~34 wool 12
fill ~86 ~14 ~18 ~88 ~14 ~18 wool 8
fill ~86 ~14 ~19 ~88 ~14 ~19 wool 8
fill ~86 ~14 ~32 ~86 ~15 ~32 fence 0
setblock ~86 ~14 ~35 stone_stairs 2
setblock ~87 ~14 ~20 stone_pressure_plate 0
setblock ~87 ~14 ~27 stone_pressure_plate 0
fill ~87 ~14 ~32 ~88 ~14 ~32 wool 8
fill ~87 ~14 ~33 ~88 ~14 ~33 wool 8
fill ~87 ~14 ~34 ~88 ~14 ~34 wool 8
fill ~87 ~14 ~35 ~88 ~14 ~35 wool 8
setblock ~88 ~14 ~20 wooden_door 0
fill ~88 ~14 ~24 ~93 ~14 ~24 wool 8
setblock ~88 ~14 ~27 wooden_door 0
fill ~88 ~14 ~29 ~93 ~14 ~29 wool 8
fill ~89 ~14 ~18 ~92 ~14 ~18 glass 0
fill ~89 ~14 ~22 ~89 ~15 ~22 fence 0
fill ~89 ~14 ~23 ~93 ~14 ~23 wool 8
fill ~89 ~14 ~25 ~89 ~15 ~25 fence 0
fill ~89 ~14 ~28 ~89 ~15 ~28 bookshelf 0
fill ~89 ~14 ~32 ~89 ~15 ~32 fence 0
fill ~89 ~14 ~35 ~89 ~15 ~35 bookshelf 0
fill ~89 ~14 ~36 ~92 ~14 ~36 glass 0
fill ~91 ~14 ~19 ~91 ~14 ~20 wool 12
fill ~91 ~14 ~27 ~91 ~14 ~28 wool 12
setblock ~91 ~14 ~30 stone_pressure_plate 0
setblock ~91 ~14 ~31 wooden_door 1
fill ~91 ~14 ~34 ~92 ~14 ~34 wool 12
setblock ~92 ~14 ~19 stone_stairs 0
fill ~92 ~14 ~22 ~92 ~15 ~22 bookshelf 0
setblock ~92 ~14 ~28 stone_stairs 0
fill ~92 ~14 ~30 ~93 ~14 ~30 wool 8
setblock ~92 ~14 ~35 stone_stairs 2
fill ~93 ~14 ~19 ~93 ~16 ~19 glass 0
fill ~93 ~14 ~20 ~93 ~16 ~20 glass 0
fill ~93 ~14 ~21 ~93 ~16 ~21 glass 0
fill ~93 ~14 ~22 ~93 ~16 ~22 glass 0
fill ~93 ~14 ~25 ~93 ~16 ~25 glass 0
fill ~93 ~14 ~26 ~93 ~16 ~26 glass 0
fill ~93 ~14 ~27 ~93 ~16 ~27 glass 0
fill ~93 ~14 ~28 ~93 ~16 ~28 glass 0
fill ~93 ~14 ~32 ~93 ~16 ~32 glass 0
fill ~93 ~14 ~33 ~93 ~16 ~33 glass 0
fill ~93 ~14 ~34 ~93 ~16 ~34 glass 0
fill ~93 ~14 ~35 ~93 ~16 ~35 glass 0
fill ~114 ~14 ~19 ~114 ~16 ~19 glass 0
fill ~114 ~14 ~20 ~114 ~16 ~20 glass 0
fill ~114 ~14 ~21 ~114 ~16 ~21 glass 0
fill ~114 ~14 ~22 ~114 ~16 ~22 glass 0
fill ~114 ~14 ~24 ~115 ~14 ~24 wool 8
fill ~114 ~14 ~25 ~119 ~14 ~25 wool 8
fill ~114 ~14 ~26 ~114 ~16 ~26 glass 0
fill ~114 ~14 ~27 ~114 ~16 ~27 glass 0
fill ~114 ~14 ~28 ~114 ~16 ~28 glass 0
fill ~114 ~14 ~29 ~114 ~16 ~29 glass 0
fill ~114 ~14 ~30 ~119 ~14 ~30 wool 8
fill ~114 ~14 ~32 ~114 ~16 ~32 glass 0
fill ~114 ~14 ~33 ~114 ~16 ~33 glass 0
fill ~114 ~14 ~34 ~114 ~16 ~34 glass 0
fill ~114 ~14 ~35 ~114 ~16 ~35 glass 0
fill ~115 ~14 ~18 ~118 ~14 ~18 glass 0
setblock ~115 ~14 ~19 stone_stairs 3
fill ~115 ~14 ~20 ~116 ~14 ~20 wool 12
fill ~115 ~14 ~26 ~115 ~15 ~26 bookshelf 0
setblock ~115 ~14 ~29 stone_stairs 1
fill ~115 ~14 ~31 ~119 ~14 ~31 wool 8
fill ~115 ~14 ~32 ~115 ~15 ~32 bookshelf 0
setblock ~115 ~14 ~35 stone_stairs 1
fill ~115 ~14 ~36 ~118 ~14 ~36 glass 0
setblock ~116 ~14 ~23 wooden_door 3
setblock ~116 ~14 ~24 stone_pressure_plate 0
fill ~116 ~14 ~28 ~116 ~14 ~29 wool 12
fill ~116 ~14 ~34 ~116 ~14 ~35 wool 12
fill ~117 ~14 ~23 ~122 ~14 ~23 wool 8
fill ~118 ~14 ~19 ~118 ~15 ~19 bookshelf 0
fill ~118 ~14 ~22 ~118 ~15 ~22 fence 0
fill ~118 ~14 ~29 ~118 ~15 ~29 fence 0
fill ~118 ~14 ~32 ~118 ~15 ~32 fence 0
fill ~119 ~14 ~18 ~120 ~14 ~18 wool 8
fill ~119 ~14 ~19 ~120 ~14 ~19 wool 8
fill ~119 ~14 ~20 ~120 ~14 ~20 wool 8
fill ~119 ~14 ~21 ~120 ~14 ~21 wool 8
fill ~119 ~14 ~22 ~120 ~14 ~22 wool 8
setblock ~119 ~14 ~27 wooden_door 2
setblock ~119 ~14 ~34 wooden_door 2
fill ~119 ~14 ~35 ~121 ~14 ~35 wool 8
setblock ~120 ~14 ~27 stone_pressure_plate 0
setblock ~120 ~14 ~34 stone_pressure_plate 0
fill ~120 ~14 ~36 ~121 ~14 ~36 wool 8
fill ~121 ~14 ~18 ~124 ~14 ~18 glass 0
setblock ~121 ~14 ~19 stone_stairs 3
fill ~121 ~14 ~20 ~122 ~14 ~20 wool 12
fill ~121 ~14 ~22 ~121 ~15 ~22 fence 0
fill ~121 ~14 ~31 ~122 ~14 ~31 wool 8
fill ~122 ~14 ~35 ~122 ~15 ~35 bookshelf 0
fill ~122 ~14 ~36 ~125 ~14 ~36 glass 0
setblock ~123 ~14 ~23 wooden_door 3
setblock ~123 ~14 ~24 stone_pressure_plate 0
setblock ~123 ~14 ~30 stone_pressure_plate 0
setblock ~123 ~14 ~31 wooden_door 1
fill ~124 ~14 ~19 ~124 ~15 ~19 bookshelf 0
fill ~124 ~14 ~23 ~125 ~14 ~23 wool 8
fill ~124 ~14 ~31 ~129 ~14 ~31 wool 8
fill ~124 ~14 ~34 ~125 ~14 ~34 wool 12
fill ~125 ~14 ~18 ~127 ~14 ~18 wool 8
fill ~125 ~14 ~19 ~127 ~14 ~19 wool 8
fill ~125 ~14 ~32 ~125 ~15 ~32 fence 0
setblock ~125 ~14 ~35 stone_stairs 2
setblock ~126 ~14 ~20 stone_pressure_plate 0
setblock ~126 ~14 ~27 stone_pressure_plate 0
fill ~126 ~14 ~32 ~127 ~14 ~32 wool 8
fill ~126 ~14 ~33 ~127 ~14 ~33 wool 8
fill ~126 ~14 ~34 ~127 ~14 ~34 wool 8
fill ~126 ~14 ~35 ~127 ~14 ~35 wool 8
setblock ~127 ~14 ~20 wooden_door 0
fill ~127 ~14 ~24 ~132 ~14 ~24 wool 8
setblock ~127 ~14 ~27 wooden_door 0
fill ~127 ~14 ~29 ~132 ~14 ~29 wool 8
fill ~128 ~14 ~18 ~131 ~14 ~18 glass 0
fill ~128 ~14 ~22 ~128 ~15 ~22 fence 0
fill ~128 ~14 ~23 ~132 ~14 ~23 wool 8
fill ~128 ~14 ~25 ~128 ~15 ~25 fence 0
fill ~128 ~14 ~28 ~128 ~15 ~28 bookshelf 0
fill ~128 ~14 ~32 ~128 ~15 ~32 fence 0
fill ~128 ~14 ~35 ~128 ~15 ~35 bookshelf 0
fill ~128 ~14 ~36 ~131 ~14 ~36 glass 0
fill ~130 ~14 ~19 ~130 ~14 ~20 wool 12
fill ~130 ~14 ~27 ~130 ~14 ~28 wool 12
setblock ~130 ~14 ~30 stone_pressure_plate 0
setblock ~130 ~14 ~31 wooden_door 1
fill ~130 ~14 ~34 ~131 ~14 ~34 wool 12
setblock ~131 ~14 ~19 stone_stairs 0
fill ~131 ~14 ~22 ~131 ~15 ~22 bookshelf 0
setblock ~131 ~14 ~28 stone_stairs 0
fill ~131 ~14 ~30 ~132 ~14 ~30 wool 8
setblock ~131 ~14 ~35 stone_stairs 2
fill ~132 ~14 ~19 ~132 ~16 ~19 glass 0
fill ~132 ~14 ~20 ~132 ~16 ~20 glass 0
fill ~132 ~14 ~21 ~132 ~16 ~21 glass 0
fill ~132 ~14 ~22 ~132 ~16 ~22 glass 0
fill ~132 ~14 ~25 ~132 ~16 ~25 glass 0
fill ~132 ~14 ~26 ~132 ~16 ~26 glass 0
fill ~132 ~14 ~27 ~132 ~16 ~27 glass 0
fill ~132 ~14 ~28 ~132 ~16 ~28 glass 0
fill ~132 ~14 ~32 ~132 ~16 ~32 glass 0
fill ~132 ~14 ~33 ~132 ~16 ~33 glass 0
fill ~132 ~14 ~34 ~132 ~16 ~34 glass 0
fill ~132 ~14 ~35 ~132 ~16 ~35 glass 0
fill ~75 ~15 ~24 ~76 ~15 ~24 wool 8
fill ~75 ~15 ~25 ~80 ~15 ~25 wool 8
fill ~75 ~15 ~30 ~80 ~15 ~30 wool 8
fill ~76 ~15 ~18 ~79 ~15 ~18 glass 0
fill ~76 ~15 ~31 ~80 ~15 ~31 wool 8
fill ~76 ~15 ~36 ~79 ~15 ~36 glass 0
setblock ~77 ~15 ~23 wooden_door 11
fill ~78 ~15 ~23 ~83 ~15 ~23 wool 8
fill ~80 ~15 ~18 ~81 ~15 ~18 wool 8
fill ~80 ~15 ~19 ~81 ~15 ~19 wool 8
fill ~80 ~15 ~20 ~81 ~15 ~20 wool 8
fill ~80 ~15 ~21 ~81 ~15 ~21 wool 8
fill ~80 ~15 ~22 ~81 ~15 ~22 wool 8
setblock ~80 ~15 ~27 wooden_door 10
setblock ~80 ~15 ~34 wooden_door 10
fill ~80 ~15 ~35 ~82 ~15 ~35 wool 8
fill ~81 ~15 ~36 ~82 ~15 ~36 wool 8
fill ~82 ~15 ~18 ~85 ~15 ~18 glass 0
fill ~82 ~15 ~31 ~83 ~15 ~31 wool 8
setblock ~83 ~15 ~28 wool 8
fill ~83 ~15 ~36 ~86 ~15 ~36 glass 0
setblock ~84 ~15 ~23 wooden_door 11
setblock ~84 ~15 ~31 wooden_door 9
fill ~85 ~15 ~23 ~86 ~15 ~23 wool 8
fill ~85 ~15 ~31 ~90 ~15 ~31 wool 8
fill ~86 ~15 ~18 ~88 ~15 ~18 wool 8
fill ~86 ~15 ~19 ~88 ~15 ~19 wool 8
fill ~87 ~15 ~32 ~88 ~15 ~32 wool 8
fill ~87 ~15 ~33 ~88 ~15 ~33 wool 8
fill ~87 ~15 ~34 ~88 ~15 ~34 wool 8
fill ~87 ~15 ~35 ~88 ~15 ~35 wool 8
setblock ~88 ~15 ~20 wooden_door 8
fill ~88 ~15 ~24 ~93 ~15 ~24 wool 8
setblock ~88 ~15 ~27 wooden_door 8
fill ~88 ~15 ~29 ~93 ~15 ~29 wool 8
fill ~89 ~15 ~18 ~92 ~15 ~18 glass 0
fill ~89 ~15 ~23 ~93 ~15 ~23 wool 8
fill ~89 ~15 ~36 ~92 ~15 ~36 glass 0
setblock ~91 ~15 ~31 wooden_door 9
fill ~92 ~15 ~30 ~93 ~15 ~30 wool 8
fill ~114 ~15 ~24 ~115 ~15 ~24 wool 8
fill ~114 ~15 ~25 ~119 ~15 ~25 wool 8
fill ~114 ~15 ~30 ~119 ~15 ~30 wool 8
fill ~115 ~15 ~18 ~118 ~15 ~18 glass 0
fill ~115 ~15 ~31 ~119 ~15 ~31 wool 8
fill ~115 ~15 ~36 ~118 ~15 ~36 glass 0
setblock ~116 ~15 ~23 wooden_door 11
fill ~117 ~15 ~23 ~122 ~15 ~23 wool 8
fill ~119 ~15 ~18 ~120 ~15 ~18 wool 8
fill ~119 ~15 ~19 ~120 ~15 ~19 wool 8
fill ~119 ~15 ~20 ~120 ~15 ~20 wool 8
fill ~119 ~15 ~21 ~120 ~15 ~21 wool 8
fill ~119 ~15 ~22 ~120 ~15 ~22 wool 8
setblock ~119 ~15 ~27 wooden_door 10
setblock ~119 ~15 ~34 wooden_door 10
fill ~119 ~15 ~35 ~121 ~15 ~35 wool 8
fill ~120 ~15 ~36 ~121 ~15 ~36 wool 8
fill ~121 ~15 ~18 ~124 ~15 ~18 glass 0
fill ~121 ~15 ~31 ~122 ~15 ~31 wool 8
setblock ~122 ~15 ~28 wool 8
fill ~122 ~15 ~36 ~125 ~15 ~36 glass 0
setblock ~123 ~15 ~23 wooden_door 11
setblock ~123 ~15 ~31 wooden_door 9
fill ~124 ~15 ~23 ~125 ~15 ~23 wool 8
fill ~124 ~15 ~31 ~129 ~15 ~31 wool 8
fill ~125 ~15 ~18 ~127 ~15 ~18 wool 8
fill ~125 ~15 ~19 ~127 ~15 ~19 wool 8
fill ~126 ~15 ~32 ~127 ~15 ~32 wool 8
fill ~126 ~15 ~33 ~127 ~15 ~33 wool 8
fill ~126 ~15 ~34 ~127 ~15 ~34 wool 8
fill ~126 ~15 ~35 ~127 ~15 ~35 wool 8
setblock ~127 ~15 ~20 wooden_door 8
fill ~127 ~15 ~24 ~132 ~15 ~24 wool 8
setblock ~127 ~15 ~27 wooden_door 8
fill ~127 ~15 ~29 ~132 ~15 ~29 wool 8
fill ~128 ~15 ~18 ~131 ~15 ~18 glass 0
fill ~128 ~15 ~23 ~132 ~15 ~23 wool 8
fill ~128 ~15 ~36 ~131 ~15 ~36 glass 0
setblock ~130 ~15 ~31 wooden_door 9
fill ~131 ~15 ~30 ~132 ~15 ~30 wool 8
fill ~75 ~16 ~24 ~76 ~16 ~24 wool 8
fill ~75 ~16 ~25 ~80 ~16 ~25 wool 8
fill ~75 ~16 ~30 ~80 ~16 ~30 wool 8
fill ~76 ~16 ~18 ~79 ~16 ~18 glass 0
fill ~76 ~16 ~31 ~93 ~16 ~31 wool 8
fill ~76 ~16 ~36 ~79 ~16 ~36 glass 0
fill ~77 ~16 ~23 ~93 ~16 ~23 wool 8
setblock ~79 ~16 ~22 glowstone 0
setblock ~79 ~16 ~29 glowstone 0
setblock ~79 ~16 ~32 glowstone 0
fill ~80 ~16 ~18 ~81 ~16 ~18 wool 8
fill ~80 ~16 ~19 ~81 ~16 ~19 wool 8
fill ~80 ~16 ~20 ~81 ~16 ~20 wool 8
fill ~80 ~16 ~21 ~81 ~16 ~21 wool 8
fill ~80 ~16 ~22 ~81 ~16 ~22 wool 8
fill ~80 ~16 ~24 ~80 ~18 ~24 wool 8
fill ~80 ~16 ~27 ~80 ~18 ~27 wool 8
fill ~80 ~16 ~34 ~80 ~18 ~34 wool 8
fill ~80 ~16 ~35 ~82 ~16 ~35 wool 8
fill ~81 ~16 ~36 ~82 ~16 ~36 wool 8
fill ~82 ~16 ~18 ~85 ~16 ~18 glass 0
setblock ~82 ~16 ~22 glowstone 0
fill ~83 ~16 ~36 ~86 ~16 ~36 glass 0
fill ~86 ~16 ~18 ~88 ~16 ~18 wool 8
fill ~86 ~16 ~19 ~88 ~16 ~19 wool 8
setblock ~86 ~16 ~32 glowstone 0
fill ~87 ~16 ~32 ~88 ~16 ~32 wool 8
fill ~87 ~16 ~33 ~88 ~16 ~33 wool 8
fill ~87 ~16 ~34 ~88 ~16 ~34 wool 8
fill ~87 ~16 ~35 ~88 ~16 ~35 wool 8
fill ~88 ~16 ~20 ~88 ~18 ~20 wool 8
fill ~88 ~16 ~24 ~93 ~16 ~24 wool 8
fill ~88 ~16 ~27 ~88 ~18 ~27 wool 8
fill ~88 ~16 ~29 ~93 ~16 ~29 wool 8
fill ~88 ~16 ~30 ~88 ~18 ~30 wool 8
fill ~89 ~16 ~18 ~92 ~16 ~18 glass 0
setblock ~89 ~16 ~22 glowstone 0
setblock ~89 ~16 ~25 glowstone 0
setblock ~89 ~16 ~32 glowstone 0
fill ~89 ~16 ~36 ~92 ~16 ~36 glass 0
fill ~92 ~16 ~30 ~93 ~16 ~30 wool 8
fill ~114 ~16 ~24 ~115 ~16 ~24 wool 8
fill ~114 ~16 ~25 ~119 ~16 ~25 wool 8
fill ~114 ~16 ~30 ~119 ~16 ~30 wool 8
fill ~115 ~16 ~18 ~118 ~16 ~18 glass 0
fill ~115 ~16 ~31 ~132 ~16 ~31 wool 8
fill ~115 ~16 ~36 ~118 ~16 ~36 glass 0
fill ~116 ~16 ~23 ~132 ~16 ~23 wool 8
setblock ~118 ~16 ~22 glowstone 0
setblock ~118 ~16 ~29 glowstone 0
setblock ~118 ~16 ~32 glowstone 0
fill ~119 ~16 ~18 ~120 ~16 ~18 wool 8
fill ~119 ~16 ~19 ~120 ~16 ~19 wool 8
fill ~119 ~16 ~20 ~120 ~16 ~20 wool 8
fill ~119 ~16 ~21 ~120 ~16 ~21 wool 8
fill ~119 ~16 ~22 ~120 ~16 ~22 wool 8
fill ~119 ~16 ~24 ~119 ~18 ~24 wool 8
fill ~119 ~16 ~27 ~119 ~18 ~27 wool 8
fill ~119 ~16 ~34 ~119 ~18 ~34 wool 8
fill ~119 ~16 ~35 ~121 ~16 ~35 wool 8
fill ~120 ~16 ~36 ~121 ~16 ~36 wool 8
fill ~121 ~16 ~18 ~124 ~16 ~18 glass 0
setblock ~121 ~16 ~22 glowstone 0
fill ~122 ~16 ~36 ~125 ~16 ~36 glass 0
fill ~125 ~16 ~18 ~127 ~16 ~18 wool 8
fill ~125 ~16 ~19 ~127 ~16 ~19 wool 8
setblock ~125 ~16 ~32 glowstone 0
fill ~126 ~16 ~32 ~127 ~16 ~32 wool 8
fill ~126 ~16 ~33 ~127 ~16 ~33 wool 8
fill ~126 ~16 ~34 ~127 ~16 ~34 wool 8
fill ~126 ~16 ~35 ~127 ~16 ~35 wool 8
fill ~127 ~16 ~20 ~127 ~18 ~20 wool 8
fill ~127 ~16 ~24 ~132 ~16 ~24 wool 8
fill ~127 ~16 ~27 ~127 ~18 ~27 wool 8
fill ~127 ~16 ~29 ~132 ~16 ~29 wool 8
fill ~127 ~16 ~30 ~127 ~18 ~30 wool 8
fill ~128 ~16 ~18 ~131 ~16 ~18 glass 0
setblock ~128 ~16 ~22 glowstone 0
setblock ~128 ~16 ~25 glowstone 0
setblock ~128 ~16 ~32 glowstone 0
fill ~128 ~16 ~36 ~131 ~16 ~36 glass 0
fill ~131 ~16 ~30 ~132 ~16 ~30 wool 8
fill ~75 ~17 ~19 ~93 ~17 ~19 wool 8
fill ~75 ~17 ~20 ~93 ~17 ~20 wool 8
fill ~75 ~17 ~21 ~93 ~17 ~21 wool 8
fill ~75 ~17 ~22 ~93 ~17 ~22 wool 8
fill ~75 ~17 ~24 ~93 ~17 ~24 wool 8
fill ~75 ~17 ~25 ~82 ~17 ~25 wool 8
fill ~75 ~17 ~26 ~81 ~17 ~26 wool 8
fill ~75 ~17 ~27 ~81 ~17 ~27 wool 8
fill ~75 ~17 ~28 ~81 ~17 ~28 wool 8
fill ~75 ~17 ~29 ~82 ~17 ~29 wool 8
fill ~75 ~17 ~30 ~93 ~17 ~30 wool 8
fill ~75 ~17 ~32 ~93 ~17 ~32 wool 8
fill ~75 ~17 ~33 ~93 ~17 ~33 wool 8
fill ~75 ~17 ~34 ~93 ~17 ~34 wool 8
fill ~75 ~17 ~35 ~93 ~17 ~35 wool 8
fill ~76 ~17 ~18 ~93 ~17 ~18 wool 8
fill ~76 ~17 ~31 ~93 ~17 ~31 wool 8
fill ~76 ~17 ~36 ~93 ~17 ~36 wool 8
fill ~77 ~17 ~23 ~93 ~17 ~23 wool 8
fill ~82 ~17 ~26 ~82 ~17 ~28 glowstone 0
fill ~83 ~17 ~25 ~85 ~17 ~25 glowstone 0
fill ~83 ~17 ~26 ~85 ~17 ~26 wool 8
fill ~83 ~17 ~27 ~83 ~18 ~27 wool 8
fill ~83 ~17 ~28 ~83 ~18 ~28 wool 8
fill ~83 ~17 ~29 ~85 ~17 ~29 glowstone 0
fill ~85 ~17 ~27 ~85 ~18 ~27 wool 8
fill ~85 ~17 ~28 ~85 ~18 ~28 wool 8
fill ~86 ~17 ~25 ~93 ~17 ~25 wool 8
fill ~86 ~17 ~26 ~86 ~17 ~28 glowstone 0
fill ~86 ~17 ~29 ~93 ~17 ~29 wool 8
fill ~87 ~17 ~26 ~87 ~18 ~26 wool 8
fill ~87 ~17 ~27 ~87 ~18 ~27 wool 8
fill ~87 ~17 ~28 ~87 ~18 ~28 wool 8
fill ~89 ~17 ~26 ~93 ~17 ~26 wool 8
fill ~89 ~17 ~27 ~93 ~17 ~27 wool 8
fill ~89 ~17 ~28 ~93 ~17 ~28 wool 8
fill ~114 ~17 ~19 ~132 ~17 ~19 wool 8
fill ~114 ~17 ~20 ~132 ~17 ~20 wool 8
fill ~114 ~17 ~21 ~132 ~17 ~21 wool 8
fill ~114 ~17 ~22 ~132 ~17 ~22 wool 8
fill ~114 ~17 ~24 ~132 ~17 ~24 wool 8
fill ~114 ~17 ~25 ~121 ~17 ~25 wool 8
fill ~114 ~17 ~26 ~120 ~17 ~26 wool 8
fill ~114 ~17 ~27 ~120 ~17 ~27 wool 8
fill ~114 ~17 ~28 ~120 ~17 ~28 wool 8
fill ~114 ~17 ~29 ~121 ~17 ~29 wool 8
fill ~114 ~17 ~30 ~132 ~17 ~30 wool 8
fill ~114 ~17 ~32 ~132 ~17 ~32 wool 8
fill ~114 ~17 ~33 ~132 ~17 ~33 wool 8
fill ~114 ~17 ~34 ~132 ~17 ~34 wool 8
fill ~114 ~17 ~35 ~132 ~17 ~35 wool 8
fill ~115 ~17 ~18 ~132 ~17 ~18 wool 8
fill ~115 ~17 ~31 ~132 ~17 ~31 wool 8
fill ~115 ~17 ~36 ~132 ~17 ~36 wool 8
fill ~116 ~17 ~23 ~132 ~17 ~23 wool 8
fill ~121 ~17 ~26 ~121 ~17 ~28 glowstone 0
fill ~122 ~17 ~25 ~124 ~17 ~25 glowstone 0
fill ~122 ~17 ~26 ~124 ~17 ~26 wool 8
fill ~122 ~17 ~27 ~122 ~18 ~27 wool 8
fill ~122 ~17 ~28 ~122 ~18 ~28 wool 8
fill ~122 ~17 ~29 ~124 ~17 ~29 glowstone 0
fill ~124 ~17 ~27 ~124 ~18 ~27 wool 8
fill ~124 ~17 ~28 ~124 ~18 ~28 wool 8
fill ~125 ~17 ~25 ~132 ~17 ~25 wool 8
fill ~125 ~17 ~26 ~125 ~17 ~28 glowstone 0
fill ~125 ~17 ~29 ~132 ~17 ~29 wool 8
fill ~126 ~17 ~26 ~126 ~18 ~26 wool 8
fill ~126 ~17 ~27 ~126 ~18 ~27 wool 8
fill ~126 ~17 ~28 ~126 ~18 ~28 wool 8
fill ~128 ~17 ~26 ~132 ~17 ~26 wool 8
fill ~128 ~17 ~27 ~132 ~17 ~27 wool 8
fill ~128 ~17 ~28 ~132 ~17 ~28 wool 8
fill ~75 ~18 ~19 ~89 ~18 ~19 wool 8
fill ~75 ~18 ~20 ~77 ~18 ~20 wool 8
fill ~75 ~18 ~21 ~75 ~17 ~21 wool 8
fill ~75 ~18 ~22 ~93 ~18 ~22 wool 8
fill ~75 ~18 ~24 ~93 ~18 ~24 wool 8
fill ~75 ~18 ~25 ~93 ~18 ~25 wool 8
fill ~75 ~18 ~26 ~89 ~18 ~26 wool 8
fill ~75 ~18 ~27 ~76 ~18 ~27 wool 8
fill ~75 ~18 ~28 ~77 ~18 ~28 wool 8
fill ~75 ~18 ~29 ~77 ~18 ~29 wool 8
fill ~75 ~18 ~30 ~93 ~18 ~30 wool 8
fill ~75 ~18 ~32 ~93 ~18 ~32 wool 8
fill ~75 ~18 ~33 ~76 ~18 ~33 wool 8
fill ~75 ~18 ~34 ~77 ~18 ~34 wool 8
fill ~75 ~18 ~35 ~77 ~18 ~35 wool 8
fill ~76 ~18 ~18 ~93 ~18 ~18 wool 8
fill ~76 ~18 ~21 ~78 ~18 ~21 wool 14
fill ~76 ~18 ~31 ~93 ~18 ~31 wool 8
fill ~76 ~18 ~36 ~93 ~18 ~36 wool 8
fill ~77 ~18 ~23 ~93 ~18 ~23 wool 8
fill ~77 ~18 ~27 ~78 ~18 ~27 wool 14
fill ~77 ~18 ~33 ~78 ~18 ~33 wool 14
setblock ~78 ~18 ~20 wool 14
fill ~78 ~18 ~28 ~78 ~18 ~29 wool 14
fill ~78 ~18 ~34 ~78 ~18 ~35 wool 14
fill ~79 ~18 ~20 ~83 ~18 ~20 wool 8
fill ~79 ~18 ~21 ~81 ~18 ~21 wool 8
fill ~79 ~18 ~27 ~79 ~18 ~36 wool 8
fill ~80 ~18 ~35 ~93 ~18 ~35 wool 8
fill ~81 ~18 ~27 ~83 ~18 ~27 wool 8
fill ~81 ~18 ~28 ~89 ~18 ~28 wool 8
fill ~81 ~18 ~29 ~93 ~18 ~29 wool 8
fill ~81 ~18 ~33 ~81 ~18 ~36 wool 8
fill ~82 ~18 ~21 ~84 ~18 ~21 wool 14
fill ~83 ~18 ~33 ~83 ~18 ~36 wool 8
setblock ~84 ~18 ~20 wool 14
fill ~84 ~18 ~33 ~86 ~18 ~33 wool 14
fill ~84 ~18 ~34 ~84 ~18 ~33 wool 14
fill ~85 ~18 ~20 ~85 ~18 ~32 wool 8
fill ~85 ~18 ~34 ~89 ~18 ~34 wool 8
setblock ~86 ~18 ~27 wool 8
fill ~87 ~18 ~20 ~87 ~18 ~36 wool 8
fill ~88 ~18 ~33 ~89 ~18 ~33 wool 8
fill ~89 ~18 ~20 ~89 ~18 ~36 wool 8
fill ~90 ~18 ~19 ~90 ~18 ~21 wool 14
fill ~90 ~18 ~26 ~91 ~18 ~26 wool 14
fill ~90 ~18 ~27 ~91 ~18 ~27 wool 14
fill ~90 ~18 ~28 ~91 ~18 ~28 wool 14
fill ~90 ~18 ~33 ~92 ~18 ~33 wool 14
fill ~90 ~18 ~34 ~92 ~18 ~34 wool 14
fill ~91 ~18 ~19 ~93 ~18 ~19 wool 8
fill ~91 ~18 ~20 ~93 ~18 ~20 wool 8
setblock ~91 ~18 ~21 wool 14
fill ~92 ~18 ~21 ~93 ~18 ~21 wool 8
fill ~92 ~18 ~26 ~93 ~18 ~26 wool 8
fill ~92 ~18 ~27 ~93 ~18 ~27 wool 8
fill ~92 ~18 ~28 ~93 ~18 ~28 wool 8
fill ~93 ~18 ~33 ~93 ~18 ~36 wool 8
fill ~114 ~18 ~19 ~128 ~18 ~19 wool 8
fill ~114 ~18 ~20 ~116 ~18 ~20 wool 8
fill ~114 ~18 ~21 ~114 ~17 ~21 wool 8
fill ~114 ~18 ~22 ~132 ~18 ~22 wool 8
fill ~114 ~18 ~24 ~132 ~18 ~24 wool 8
fill ~114 ~18 ~25 ~132 ~18 ~25 wool 8
fill ~114 ~18 ~26 ~128 ~18 ~26 wool 8
fill ~114 ~18 ~27 ~115 ~18 ~27 wool 8
fill ~114 ~18 ~28 ~116 ~18 ~28 wool 8
fill ~114 ~18 ~29 ~116 ~18 ~29 wool 8
fill ~114 ~18 ~30 ~132 ~18 ~30 wool 8
fill ~114 ~18 ~32 ~132 ~18 ~32 wool 8
fill ~114 ~18 ~33 ~115 ~18 ~33 wool 8
fill ~114 ~18 ~34 ~116 ~18 ~34 wool 8
fill ~114 ~18 ~35 ~116 ~18 ~35 wool 8
fill ~115 ~18 ~18 ~132 ~18 ~18 wool 8
fill ~115 ~18 ~21 ~117 ~18 ~21 wool 14
fill ~115 ~18 ~31 ~132 ~18 ~31 wool 8
fill ~115 ~18 ~36 ~132 ~18 ~36 wool 8
fill ~116 ~18 ~23 ~132 ~18 ~23 wool 8
fill ~116 ~18 ~27 ~117 ~18 ~27 wool 14
fill ~116 ~18 ~33 ~117 ~18 ~33 wool 14
setblock ~117 ~18 ~20 wool 14
fill ~117 ~18 ~28 ~117 ~18 ~29 wool 14
fill ~117 ~18 ~34 ~117 ~18 ~35 wool 14
fill ~118 ~18 ~20 ~122 ~18 ~20 wool 8
fill ~118 ~18 ~21 ~120 ~18 ~21 wool 8
fill ~118 ~18 ~27 ~118 ~18 ~36 wool 8
fill ~119 ~18 ~35 ~132 ~18 ~35 wool 8
fill ~120 ~18 ~27 ~122 ~18 ~27 wool 8
fill ~120 ~18 ~28 ~128 ~18 ~28 wool 8
fill ~120 ~18 ~29 ~132 ~18 ~29 wool 8
fill ~120 ~18 ~33 ~120 ~18 ~36 wool 8
fill ~121 ~18 ~21 ~123 ~18 ~21 wool 14
fill ~122 ~18 ~33 ~122 ~18 ~36 wool 8
setblock ~123 ~18 ~20 wool 14
fill ~123 ~18 ~33 ~125 ~18 ~33 wool 14
fill ~123 ~18 ~34 ~123 ~18 ~33 wool 14
fill ~124 ~18 ~20 ~124 ~18 ~32 wool 8
fill ~124 ~18 ~34 ~128 ~18 ~34 wool 8
setblock ~125 ~18 ~27 wool 8
fill ~126 ~18 ~20 ~126 ~18 ~36 wool 8
fill ~127 ~18 ~33 ~128 ~18 ~33 wool 8
fill ~128 ~18 ~20 ~128 ~18 ~36 wool 8
fill ~129 ~18 ~19 ~129 ~18 ~21 wool 14
fill ~129 ~18 ~26 ~130 ~18 ~26 wool 14
fill ~129 ~18 ~27 ~130 ~18 ~27 wool 14
fill ~129 ~18 ~28 ~130 ~18 ~28 wool 14
fill ~129 ~18 ~33 ~131 ~18 ~33 wool 14
fill ~129 ~18 ~34 ~131 ~18 ~34 wool 14
fill ~130 ~18 ~19 ~132 ~18 ~19 wool 8
fill ~130 ~18 ~20 ~132 ~18 ~20 wool 8
setblock ~130 ~18 ~21 wool 14
fill ~131 ~18 ~21 ~132 ~18 ~21 wool 8
fill ~131 ~18 ~26 ~132 ~18 ~26 wool 8
fill ~131 ~18 ~27 ~132 ~18 ~27 wool 8
fill ~131 ~18 ~28 ~132 ~18 ~28 wool 8
fill ~132 ~18 ~33 ~132 ~18 ~36 wool 8
fill ~75 ~19 ~19 ~75 ~21 ~19 glass 0
fill ~75 ~19 ~20 ~75 ~21 ~20 glass 0
fill ~75 ~19 ~21 ~75 ~21 ~21 glass 0
fill ~75 ~19 ~22 ~75 ~21 ~22 glass 0
fill ~75 ~19 ~24 ~76 ~19 ~24 wool 8
fill ~75 ~19 ~25 ~80 ~19 ~25 wool 8
fill ~75 ~19 ~26 ~75 ~21 ~26 glass 0
fill ~75 ~19 ~27 ~75 ~21 ~27 glass 0
fill ~75 ~19 ~28 ~75 ~21 ~28 glass 0
fill ~75 ~19 ~29 ~75 ~21 ~29 glass 0
fill ~75 ~19 ~30 ~80 ~19 ~30 wool 8
fill ~75 ~19 ~32 ~75 ~21 ~32 glass 0
fill ~75 ~19 ~33 ~75 ~21 ~33 glass 0
fill ~75 ~19 ~34 ~75 ~21 ~34 glass 0
fill ~75 ~19 ~35 ~75 ~21 ~35 glass 0
fill ~76 ~19 ~18 ~79 ~19 ~18 glass 0
setblock ~76 ~19 ~19 stone_stairs 3
fill ~76 ~19 ~20 ~77 ~19 ~20 wool 12
fill ~76 ~19 ~26 ~76 ~20 ~26 bookshelf 0
setblock ~76 ~19 ~29 stone_stairs 1
fill ~76 ~19 ~31 ~80 ~19 ~31 wool 8
fill ~76 ~19 ~32 ~76 ~20 ~32 bookshelf 0
setblock ~76 ~19 ~35 stone_stairs 1
fill ~76 ~19 ~36 ~79 ~19 ~36 glass 0
setblock ~77 ~19 ~23 wooden_door 3
setblock ~77 ~19 ~24 stone_pressure_plate 0
fill ~77 ~19 ~28 ~77 ~19 ~29 wool 12
fill ~77 ~19 ~34 ~77 ~19 ~35 wool 12
fill ~78 ~19 ~23 ~83 ~19 ~23 wool 8
fill ~79 ~19 ~19 ~79 ~20 ~19 bookshelf 0
fill ~79 ~19 ~22 ~79 ~20 ~22 fence 0
fill ~79 ~19 ~29 ~79 ~20 ~29 fence 0
fill ~79 ~19 ~32 ~79 ~20 ~32 fence 0
fill ~80 ~19 ~18 ~81 ~19 ~18 wool 8
fill ~80 ~19 ~19 ~81 ~19 ~19 wool 8
fill ~80 ~19 ~20 ~81 ~19 ~20 wool 8
fill ~80 ~19 ~21 ~81 ~19 ~21 wool 8
fill ~80 ~19 ~22 ~81 ~19 ~22 wool 8
setblock ~80 ~19 ~27 wooden_door 2
setblock ~80 ~19 ~34 wooden_door 2
fill ~80 ~19 ~35 ~82 ~19 ~35 wool 8
setblock ~81 ~19 ~27 stone_pressure_plate 0
setblock ~81 ~19 ~34 stone_pressure_plate 0
fill ~81 ~19 ~36 ~82 ~19 ~36 wool 8
fill ~82 ~19 ~18 ~85 ~19 ~18 glass 0
setblock ~82 ~19 ~19 stone_stairs 3
fill ~82 ~19 ~20 ~83 ~19 ~20 wool 12
fill ~82 ~19 ~22 ~82 ~20 ~22 fence 0
fill ~82 ~19 ~31 ~83 ~19 ~31 wool 8
fill ~83 ~19 ~35 ~83 ~20 ~35 bookshelf 0
fill ~83 ~19 ~36 ~86 ~19 ~36 glass 0
setblock ~84 ~19 ~23 wooden_door 3
setblock ~84 ~19 ~24 stone_pressure_plate 0
setblock ~84 ~19 ~30 stone_pressure_plate 0
setblock ~84 ~19 ~31 wooden_door 1
fill ~85 ~19 ~19 ~85 ~20 ~19 bookshelf 0
fill ~85 ~19 ~23 ~86 ~19 ~23 wool 8
fill ~85 ~19 ~31 ~90 ~19 ~31 wool 8
fill ~85 ~19 ~34 ~86 ~19 ~34 wool 12
fill ~86 ~19 ~18 ~88 ~19 ~18 wool 8
fill ~86 ~19 ~19 ~88 ~19 ~19 wool 8
fill ~86 ~19 ~32 ~86 ~20 ~32 fence 0
setblock ~86 ~19 ~35 stone_stairs 2
setblock ~87 ~19 ~20 stone_pressure_plate 0
setblock ~87 ~19 ~27 stone_pressure_plate 0
fill ~87 ~19 ~32 ~88 ~19 ~32 wool 8
fill ~87 ~19 ~33 ~88 ~19 ~33 wool 8
fill ~87 ~19 ~34 ~88 ~19 ~34 wool 8
fill ~87 ~19 ~35 ~88 ~19 ~35 wool 8
setblock ~88 ~19 ~20 wooden_door 0
fill ~88 ~19 ~24 ~93 ~19 ~24 wool 8
setblock ~88 ~19 ~27 wooden_door 0
fill ~88 ~19 ~29 ~93 ~19 ~29 wool 8
fill ~89 ~19 ~18 ~92 ~19 ~18 glass 0
fill ~89 ~19 ~22 ~89 ~20 ~22 fence 0
fill ~89 ~19 ~23 ~93 ~19 ~23 wool 8
fill ~89 ~19 ~25 ~89 ~20 ~25 fence 0
fill ~89 ~19 ~28 ~89 ~20 ~28 bookshelf 0
fill ~89 ~19 ~32 ~89 ~20 ~32 fence 0
fill ~89 ~19 ~35 ~89 ~20 ~35 bookshelf 0
fill ~89 ~19 ~36 ~92 ~19 ~36 glass 0
fill ~91 ~19 ~19 ~91 ~19 ~20 wool 12
fill ~91 ~19 ~27 ~91 ~19 ~28 wool 12
setblock ~91 ~19 ~30 stone_pressure_plate 0
setblock ~91 ~19 ~31 wooden_door 1
fill ~91 ~19 ~34 ~92 ~19 ~34 wool 12
setblock ~92 ~19 ~19 stone_stairs 0
fill ~92 ~19 ~22 ~92 ~20 ~22 bookshelf 0
setblock ~92 ~19 ~28 stone_stairs 0
fill ~92 ~19 ~30 ~93 ~19 ~30 wool 8
setblock ~92 ~19 ~35 stone_stairs 2
fill ~93 ~19 ~19 ~93 ~21 ~19 glass 0
fill ~93 ~19 ~20 ~93 ~21 ~20 glass 0
fill ~93 ~19 ~21 ~93 ~21 ~21 glass 0
fill ~93 ~19 ~22 ~93 ~21 ~22 glass 0
fill ~93 ~19 ~25 ~93 ~21 ~25 glass 0
fill ~93 ~19 ~26 ~93 ~21 ~26 glass 0
fill ~93 ~19 ~27 ~93 ~21 ~27 glass 0
fill ~93 ~19 ~28 ~93 ~21 ~28 glass 0
fill ~93 ~19 ~32 ~93 ~21 ~32 glass 0
fill ~93 ~19 ~33 ~93 ~21 ~33 glass 0
fill ~93 ~19 ~34 ~93 ~21 ~34 glass 0
fill ~93 ~19 ~35 ~93 ~21 ~35 glass 0
fill ~114 ~19 ~19 ~114 ~21 ~19 glass 0
fill ~114 ~19 ~20 ~114 ~21 ~20 glass 0
fill ~114 ~19 ~21 ~114 ~21 ~21 glass 0
fill ~114 ~19 ~22 ~114 ~21 ~22 glass 0
fill ~114 ~19 ~24 ~115 ~19 ~24 wool 8
fill ~114 ~19 ~25 ~119 ~19 ~25 wool 8
fill ~114 ~19 ~26 ~114 ~21 ~26 glass 0
fill ~114 ~19 ~27 ~114 ~21 ~27 glass 0
fill ~114 ~19 ~28 ~114 ~21 ~28 glass 0
fill ~114 ~19 ~29 ~114 ~21 ~29 glass 0
fill ~114 ~19 ~30 ~119 ~19 ~30 wool 8
fill ~114 ~19 ~32 ~114 ~21 ~32 glass 0
fill ~114 ~19 ~33 ~114 ~21 ~33 glass 0
fill ~114 ~19 ~34 ~114 ~21 ~34 glass 0
fill ~114 ~19 ~35 ~114 ~21 ~35 glass 0
fill ~115 ~19 ~18 ~118 ~19 ~18 glass 0
setblock ~115 ~19 ~19 stone_stairs 3
fill ~115 ~19 ~20 ~116 ~19 ~20 wool 12
fill ~115 ~19 ~26 ~115 ~20 ~26 bookshelf 0
setblock ~115 ~19 ~29 stone_stairs 1
fill ~115 ~19 ~31 ~119 ~19 ~31 wool 8
fill ~115 ~19 ~32 ~115 ~20 ~32 bookshelf 0
setblock ~115 ~19 ~35 stone_stairs 1
fill ~115 ~19 ~36 ~118 ~19 ~36 glass 0
setblock ~116 ~19 ~23 wooden_door 3
setblock ~116 ~19 ~24 stone_pressure_plate 0
fill ~116 ~19 ~28 ~116 ~19 ~29 wool 12
fill ~116 ~19 ~34 ~116 ~19 ~35 wool 12
fill ~117 ~19 ~23 ~122 ~19 ~23 wool 8
fill ~118 ~19 ~19 ~118 ~20 ~19 bookshelf 0
fill ~118 ~19 ~22 ~118 ~20 ~22 fence 0
fill ~118 ~19 ~29 ~118 ~20 ~29 fence 0
fill ~118 ~19 ~32 ~118 ~20 ~32 fence 0
fill ~119 ~19 ~18 ~120 ~19 ~18 wool 8
fill ~119 ~19 ~19 ~120 ~19 ~19 wool 8
fill ~119 ~19 ~20 ~120 ~19 ~20 wool 8
fill ~119 ~19 ~21 ~120 ~19 ~21 wool 8
fill ~119 ~19 ~22 ~120 ~19 ~22 wool 8
setblock ~119 ~19 ~27 wooden_door 2
setblock ~119 ~19 ~34 wooden_door 2
fill ~119 ~19 ~35 ~121 ~19 ~35 wool 8
setblock ~120 ~19 ~27 stone_pressure_plate 0
setblock ~120 ~19 ~34 stone_pressure_plate 0
fill ~120 ~19 ~36 ~121 ~19 ~36 wool 8
fill ~121 ~19 ~18 ~124 ~19 ~18 glass 0
setblock ~121 ~19 ~19 stone_stairs 3
fill ~121 ~19 ~20 ~122 ~19 ~20 wool 12
fill ~121 ~19 ~22 ~121 ~20 ~22 fence 0
fill ~121 ~19 ~31 ~122 ~19 ~31 wool 8
fill ~122 ~19 ~35 ~122 ~20 ~35 bookshelf 0
fill ~122 ~19 ~36 ~125 ~19 ~36 glass 0
setblock ~123 ~19 ~23 wooden_door 3
setblock ~123 ~19 ~24 stone_pressure_plate 0
setblock ~123 ~19 ~30 stone_pressure_plate 0
setblock ~123 ~19 ~31 wooden_door 1
fill ~124 ~19 ~19 ~124 ~20 ~19 bookshelf 0
fill ~124 ~19 ~23 ~125 ~19 ~23 wool 8
fill ~124 ~19 ~31 ~129 ~19 ~31 wool 8
fill ~124 ~19 ~34 ~125 ~19 ~34 wool 12
fill ~125 ~19 ~18 ~127 ~19 ~18 wool 8
fill ~125 ~19 ~19 ~127 ~19 ~19 wool 8
fill ~125 ~19 ~32 ~125 ~20 ~32 fence 0
setblock ~125 ~19 ~35 stone_stairs 2
setblock ~126 ~19 ~20 stone_pressure_plate 0
setblock ~126 ~19 ~27 stone_pressure_plate 0
fill ~126 ~19 ~32 ~127 ~19 ~32 wool 8
fill ~126 ~19 ~33 ~127 ~19 ~33 wool 8
fill ~126 ~19 ~34 ~127 ~19 ~34 wool 8
fill ~126 ~19 ~35 ~127 ~19 ~35 wool 8
setblock ~127 ~19 ~20 wooden_door 0
fill ~127 ~19 ~24 ~132 ~19 ~24 wool 8
setblock ~127 ~19 ~27 wooden_door 0
fill ~127 ~19 ~29 ~132 ~19 ~29 wool 8
fill ~128 ~19 ~18 ~131 ~19 ~18 glass 0
fill ~128 ~19 ~22 ~128 ~20 ~22 fence 0
fill ~128 ~19 ~23 ~132 ~19 ~23 wool 8
fill ~128 ~19 ~25 ~128 ~20 ~25 fence 0
fill ~128 ~19 ~28 ~128 ~20 ~28 bookshelf 0
fill ~128 ~19 ~32 ~128 ~20 ~32 fence 0
fill ~128 ~19 ~35 ~128 ~20 ~35 bookshelf 0
fill ~128 ~19 ~36 ~131 ~19 ~36 glass 0
fill ~130 ~19 ~19 ~130 ~19 ~20 wool 12
fill ~130 ~19 ~27 ~130 ~19 ~28 wool 12
setblock ~130 ~19 ~30 stone_pressure_plate 0
setblock ~130 ~19 ~31 wooden_door 1
fill ~130 ~19 ~34 ~131 ~19 ~34 wool 12
setblock ~131 ~19 ~19 stone_stairs 0
fill ~131 ~19 ~22 ~131 ~20 ~22 bookshelf 0
setblock ~131 ~19 ~28 stone_stairs 0
fill ~131 ~19 ~30 ~132 ~19 ~30 wool 8
setblock ~131 ~19 ~35 stone_stairs 2
fill ~132 ~19 ~19 ~132 ~21 ~19 glass 0
fill ~132 ~19 ~20 ~132 ~21 ~20 glass 0
fill ~132 ~19 ~21 ~132 ~21 ~21 glass 0
fill ~132 ~19 ~22 ~132 ~21 ~22 glass 0
fill ~132 ~19 ~25 ~132 ~21 ~25 glass 0
fill ~132 ~19 ~26 ~132 ~21 ~26 glass 0
fill ~132 ~19 ~27 ~132 ~21 ~27 glass 0
fill ~132 ~19 ~28 ~132 ~21 ~28 glass 0
fill ~132 ~19 ~32 ~132 ~21 ~32 glass 0
fill ~132 ~19 ~33 ~132 ~21 ~33 glass 0
fill ~132 ~19 ~34 ~132 ~21 ~34 glass 0
fill ~132 ~19 ~35 ~132 ~21 ~35 glass 0
fill ~75 ~20 ~24 ~76 ~20 ~24 wool 8
fill ~75 ~20 ~25 ~80 ~20 ~25 wool 8
fill ~75 ~20 ~30 ~80 ~20 ~30 wool 8
fill ~76 ~20 ~18 ~79 ~20 ~18 glass 0
fill ~76 ~20 ~31 ~80 ~20 ~31 wool 8
fill ~76 ~20 ~36 ~79 ~20 ~36 glass 0
setblock ~77 ~20 ~23 wooden_door 11
fill ~78 ~20 ~23 ~83 ~20 ~23 wool 8
fill ~80 ~20 ~18 ~81 ~20 ~18 wool 8
fill ~80 ~20 ~19 ~81 ~20 ~19 wool 8
fill ~80 ~20 ~20 ~81 ~20 ~20 wool 8
fill ~80 ~20 ~21 ~81 ~20 ~21 wool 8
fill ~80 ~20 ~22 ~81 ~20 ~22 wool 8
setblock ~80 ~20 ~27 wooden_door 10
setblock ~80 ~20 ~34 wooden_door 10
fill ~80 ~20 ~35 ~82 ~20 ~35 wool 8
fill ~81 ~20 ~36 ~82 ~20 ~36 wool 8
fill ~82 ~20 ~18 ~85 ~20 ~18 glass 0
fill ~82 ~20 ~31 ~83 ~20 ~31 wool 8
setblock ~83 ~20 ~28 wool 8
fill ~83 ~20 ~36 ~86 ~20 ~36 glass 0
setblock ~84 ~20 ~23 wooden_door 11
setblock ~84 ~20 ~31 wooden_door 9
fill ~85 ~20 ~23 ~86 ~20 ~23 wool 8
fill ~85 ~20 ~31 ~90 ~20 ~31 wool 8
fill ~86 ~20 ~18 ~88 ~20 ~18 wool 8
fill ~86 ~20 ~19 ~88 ~20 ~19 wool 8
fill ~87 ~20 ~32 ~88 ~20 ~32 wool 8
fill ~87 ~20 ~33 ~88 ~20 ~33 wool 8
fill ~87 ~20 ~34 ~88 ~20 ~34 wool 8
fill ~87 ~20 ~35 ~88 ~20 ~35 wool 8
setblock ~88 ~20 ~20 wooden_door 8
fill ~88 ~20 ~24 ~93 ~20 ~24 wool 8
setblock ~88 ~20 ~27 wooden_door 8
fill ~88 ~20 ~29 ~93 ~20 ~29 wool 8
fill ~89 ~20 ~18 ~92 ~20 ~18 glass 0
fill ~89 ~20 ~23 ~93 ~20 ~23 wool 8
fill ~89 ~20 ~36 ~92 ~20 ~36 glass 0
setblock ~91 ~20 ~31 wooden_door 9
fill ~92 ~20 ~30 ~93 ~20 ~30 wool 8
fill ~114 ~20 ~24 ~115 ~20 ~24 wool 8
fill ~114 ~20 ~25 ~119 ~20 ~25 wool 8
fill ~114 ~20 ~30 ~119 ~20 ~30 wool 8
fill ~115 ~20 ~18 ~118 ~20 ~18 glass 0
fill ~115 ~20 ~31 ~119 ~20 ~31 wool 8
fill ~115 ~20 ~36 ~118 ~20 ~36 glass 0
setblock ~116 ~20 ~23 wooden_door 11
fill ~117 ~20 ~23 ~122 ~20 ~23 wool 8
fill ~119 ~20 ~18 ~120 ~20 ~18 wool 8
fill ~119 ~20 ~19 ~120 ~20 ~19 wool 8
fill ~119 ~20 ~20 ~120 ~20 ~20 wool 8
fill ~119 ~20 ~21 ~120 ~20 ~21 wool 8
fill ~119 ~20 ~22 ~120 ~20 ~22 wool 8
setblock ~119 ~20 ~27 wooden_door 10
setblock ~119 ~20 ~34 wooden_door 10
fill ~119 ~20 ~35 ~121 ~20 ~35 wool 8
fill ~120 ~20 ~36 ~121 ~20 ~36 wool 8
fill ~121 ~20 ~18 ~124 ~20 ~18 glass 0
fill ~121 ~20 ~31 ~122 ~20 ~31 wool 8
setblock ~122 ~20 ~28 wool 8
fill ~122 ~20 ~36 ~125 ~20 ~36 glass 0
setblock ~123 ~20 ~23 wooden_door 11
setblock ~123 ~20 ~31 wooden_door 9
fill ~124 ~20 ~23 ~125 ~20 ~23 wool 8
fill ~124 ~20 ~31 ~129 ~20 ~31 wool 8
fill ~125 ~20 ~18 ~127 ~20 ~18 wool 8
fill ~125 ~20 ~19 ~127 ~20 ~19 wool 8
fill ~126 ~20 ~32 ~127 ~20 ~32 wool 8
fill ~126 ~20 ~33 ~127 ~20 ~33 wool 8
fill ~126 ~20 ~34 ~127 ~20 ~34 wool 8
fill ~126 ~20 ~35 ~127 ~20 ~35 wool 8
setblock ~127 ~20 ~20 wooden_door 8
fill ~127 ~20 ~24 ~132 ~20 ~24 wool 8
setblock ~127 ~20 ~27 wooden_door 8
fill ~127 ~20 ~29 ~132 ~20 ~29 wool 8
fill ~128 ~20 ~18 ~131 ~20 ~18 glass 0
fill ~128 ~20 ~23 ~132 ~20 ~23 wool 8
fill ~128 ~20 ~36 ~131 ~20 ~36 glass 0
setblock ~130 ~20 ~31 wooden_door 9
fill ~131 ~20 ~30 ~132 ~20 ~30 wool 8
fill ~75 ~21 ~24 ~76 ~21 ~24 wool 8
fill ~75 ~21 ~25 ~80 ~21 ~25 wool 8
fill ~75 ~21 ~30 ~80 ~21 ~30 wool 8
fill ~76 ~21 ~18 ~79 ~21 ~18 glass 0
fill ~76 ~21 ~31 ~93 ~21 ~31 wool 8
fill ~76 ~21 ~36 ~79 ~21 ~36 glass 0
fill ~77 ~21 ~23 ~93 ~21 ~23 wool 8
setblock ~79 ~21 ~22 glowstone 0
setblock ~79 ~21 ~29 glowstone 0
setblock ~79 ~21 ~32 glowstone 0
fill ~80 ~21 ~18 ~81 ~21 ~18 wool 8
fill ~80 ~21 ~19 ~81 ~21 ~19 wool 8
fill ~80 ~21 ~20 ~81 ~21 ~20 wool 8
fill ~80 ~21 ~21 ~81 ~21 ~21 wool 8
fill ~80 ~21 ~22 ~81 ~21 ~22 wool 8
fill ~80 ~21 ~24 ~80 ~23 ~24 wool 8
fill ~80 ~21 ~27 ~80 ~23 ~27 wool 8
fill ~80 ~21 ~34 ~80 ~23 ~34 wool 8
fill ~80 ~21 ~35 ~82 ~21 ~35 wool 8
fill ~81 ~21 ~36 ~82 ~21 ~36 wool 8
fill ~82 ~21 ~18 ~85 ~21 ~18 glass 0
setblock ~82 ~21 ~22 glowstone 0
fill ~83 ~21 ~36 ~86 ~21 ~36 glass 0
fill ~86 ~21 ~18 ~88 ~21 ~18 wool 8
fill ~86 ~21 ~19 ~88 ~21 ~19 wool 8
setblock ~86 ~21 ~32 glowstone 0
fill ~87 ~21 ~32 ~88 ~21 ~32 wool 8
fill ~87 ~21 ~33 ~88 ~21 ~33 wool 8
fill ~87 ~21 ~34 ~88 ~21 ~34 wool 8
fill ~87 ~21 ~35 ~88 ~21 ~35 wool 8
fill ~88 ~21 ~20 ~88 ~23 ~20 wool 8
fill ~88 ~21 ~24 ~93 ~21 ~24 wool 8
fill ~88 ~21 ~27 ~88 ~23 ~27 wool 8
fill ~88 ~21 ~29 ~93 ~21 ~29 wool 8
fill ~88 ~21 ~30 ~88 ~23 ~30 wool 8
fill ~89 ~21 ~18 ~92 ~21 ~18 glass 0
setblock ~89 ~21 ~22 glowstone 0
setblock ~89 ~21 ~25 glowstone 0
setblock ~89 ~21 ~32 glowstone 0
fill ~89 ~21 ~36 ~92 ~21 ~36 glass 0
fill ~92 ~21 ~30 ~93 ~21 ~30 wool 8
fill ~114 ~21 ~24 ~115 ~21 ~24 wool 8
fill ~114 ~21 ~25 ~119 ~21 ~25 wool 8
fill ~114 ~21 ~30 ~119 ~21 ~30 wool 8
fill ~115 ~21 ~18 ~118 ~21 ~18 glass 0
fill ~115 ~21 ~31 ~132 ~21 ~31 wool 8
fill ~115 ~21 ~36 ~118 ~21 ~36 glass 0
fill ~116 ~21 ~23 ~132 ~21 ~23 wool 8
setblock ~118 ~21 ~22 glowstone 0
setblock ~118 ~21 ~29 glowstone 0
setblock ~118 ~21 ~32 glowstone 0
fill ~119 ~21 ~18 ~120 ~21 ~18 wool 8
fill ~119 ~21 ~19 ~120 ~21 ~19 wool 8
fill ~119 ~21 ~20 ~120 ~21 ~20 wool 8
fill ~119 ~21 ~21 ~120 ~21 ~21 wool 8
fill ~119 ~21 ~22 ~120 ~21 ~22 wool 8
fill ~119 ~21 ~24 ~119 ~23 ~24 wool 8
fill ~119 ~21 ~27 ~119 ~23 ~27 wool 8
fill ~119 ~21 ~34 ~119 ~23 ~34 wool 8
fill ~119 ~21 ~35 ~121 ~21 ~35 wool 8
fill ~120 ~21 ~36 ~121 ~21 ~36 wool 8
fill ~121 ~21 ~18 ~124 ~21 ~18 glass 0
setblock ~121 ~21 ~22 glowstone 0
fill ~122 ~21 ~36 ~125 ~21 ~36 glass 0
fill ~125 ~21 ~18 ~127 ~21 ~18 wool 8
fill ~125 ~21 ~19 ~127 ~21 ~19 wool 8
setblock ~125 ~21 ~32 glowstone 0
fill ~126 ~21 ~32 ~127 ~21 ~32 wool 8
fill ~126 ~21 ~33 ~127 ~21 ~33 wool 8
fill ~126 ~21 ~34 ~127 ~21 ~34 wool 8
fill ~126 ~21 ~35 ~127 ~21 ~35 wool 8
fill ~127 ~21 ~20 ~127 ~23 ~20 wool 8
fill ~127 ~21 ~24 ~132 ~21 ~24 wool 8
fill ~127 ~21 ~27 ~127 ~23 ~27 wool 8
fill ~127 ~21 ~29 ~132 ~21 ~29 wool 8
fill ~127 ~21 ~30 ~127 ~23 ~30 wool 8
fill ~128 ~21 ~18 ~131 ~21 ~18 glass 0
setblock ~128 ~21 ~22 glowstone 0
setblock ~128 ~21 ~25 glowstone 0
setblock ~128 ~21 ~32 glowstone 0
fill ~128 ~21 ~36 ~131 ~21 ~36 glass 0
fill ~131 ~21 ~30 ~132 ~21 ~30 wool 8
fill ~75 ~22 ~19 ~93 ~22 ~19 wool 8
fill ~75 ~22 ~20 ~93 ~22 ~20 wool 8
fill ~75 ~22 ~21 ~93 ~22 ~21 wool 8
fill ~75 ~22 ~22 ~93 ~22 ~22 wool 8
fill ~75 ~22 ~24 ~93 ~22 ~24 wool 8
fill ~75 ~22 ~25 ~82 ~22 ~25 wool 8
fill ~75 ~22 ~26 ~81 ~22 ~26 wool 8
fill ~75 ~22 ~27 ~81 ~22 ~27 wool 8
fill ~75 ~22 ~28 ~81 ~22 ~28 wool 8
fill ~75 ~22 ~29 ~82 ~22 ~29 wool 8
fill ~75 ~22 ~30 ~93 ~22 ~30 wool 8
fill ~75 ~22 ~32 ~93 ~22 ~32 wool 8
fill ~75 ~22 ~33 ~93 ~22 ~33 wool 8
fill ~75 ~22 ~34 ~93 ~22 ~34 wool 8
fill ~75 ~22 ~35 ~93 ~22 ~35 wool 8
fill ~76 ~22 ~18 ~93 ~22 ~18 wool 8
fill ~76 ~22 ~31 ~93 ~22 ~31 wool 8
fill ~76 ~22 ~36 ~93 ~22 ~36 wool 8
fill ~77 ~22 ~23 ~93 ~22 ~23 wool 8
fill ~82 ~22 ~26 ~82 ~22 ~28 glowstone 0
fill ~83 ~22 ~25 ~85 ~22 ~25 glowstone 0
fill ~83 ~22 ~26 ~85 ~22 ~26 wool 8
fill ~83 ~22 ~27 ~83 ~23 ~27 wool 8
fill ~83 ~22 ~28 ~83 ~23 ~28 wool 8
fill ~83 ~22 ~29 ~85 ~22 ~29 glowstone 0
fill ~85 ~22 ~27 ~85 ~23 ~27 wool 8
fill ~85 ~22 ~28 ~85 ~23 ~28 wool 8
fill ~86 ~22 ~25 ~93 ~22 ~25 wool 8
fill ~86 ~22 ~26 ~86 ~22 ~28 glowstone 0
fill ~86 ~22 ~29 ~93 ~22 ~29 wool 8
fill ~87 ~22 ~26 ~87 ~23 ~26 wool 8
fill ~87 ~22 ~27 ~87 ~23 ~27 wool 8
fill ~87 ~22 ~28 ~87 ~23 ~28 wool 8
fill ~89 ~22 ~26 ~93 ~22 ~26 wool 8
fill ~89 ~22 ~27 ~93 ~22 ~27 wool 8
fill ~89 ~22 ~28 ~93 ~22 ~28 wool 8
fill ~114 ~22 ~19 ~132 ~22 ~19 wool 8
fill ~114 ~22 ~20 ~132 ~22 ~20 wool 8
fill ~114 ~22 ~21 ~132 ~22 ~21 wool 8
fill ~114 ~22 ~22 ~132 ~22 ~22 wool 8
fill ~114 ~22 ~24 ~132 ~22 ~24 wool 8
fill ~114 ~22 ~25 ~121 ~22 ~25 wool 8
fill ~114 ~22 ~26 ~120 ~22 ~26 wool 8
fill ~114 ~22 ~27 ~120 ~22 ~27 wool 8
fill ~114 ~22 ~28 ~120 ~22 ~28 wool 8
fill ~114 ~22 ~29 ~121 ~22 ~29 wool 8
fill ~114 ~22 ~30 ~132 ~22 ~30 wool 8
fill ~114 ~22 ~32 ~132 ~22 ~32 wool 8
fill ~114 ~22 ~33 ~132 ~22 ~33 wool 8
fill ~114 ~22 ~34 ~132 ~22 ~34 wool 8
fill ~114 ~22 ~35 ~132 ~22 ~35 wool 8
fill ~115 ~22 ~18 ~132 ~22 ~18 wool 8
fill ~115 ~22 ~31 ~132 ~22 ~31 wool 8
fill ~115 ~22 ~36 ~132 ~22 ~36 wool 8
fill ~116 ~22 ~23 ~132 ~22 ~23 wool 8
fill ~121 ~22 ~26 ~121 ~22 ~28 glowstone 0
fill ~122 ~22 ~25 ~124 ~22 ~25 glowstone 0
fill ~122 ~22 ~26 ~124 ~22 ~26 wool 8
fill ~122 ~22 ~27 ~122 ~23 ~27 wool 8
fill ~122 ~22 ~28 ~122 ~23 ~28 wool 8
fill ~122 ~22 ~29 ~124 ~22 ~29 glowstone 0
fill ~124 ~22 ~27 ~124 ~23 ~27 wool 8
fill ~124 ~22 ~28 ~124 ~23 ~28 wool 8
fill ~125 ~22 ~25 ~132 ~22 ~25 wool 8
fill ~125 ~22 ~26 ~125 ~22 ~28 glowstone 0
fill ~125 ~22 ~29 ~132 ~22 ~29 wool 8
fill ~126 ~22 ~26 ~126 ~23 ~26 wool 8
fill ~126 ~22 ~27 ~126 ~23 ~27 wool 8
fill ~126 ~22 ~28 ~126 ~23 ~28 wool 8
fill ~128 ~22 ~26 ~132 ~22 ~26 wool 8
fill ~128 ~22 ~27 ~132 ~22 ~27 wool 8
fill ~128 ~22 ~28 ~132 ~22 ~28 wool 8
fill ~75 ~23 ~19 ~89 ~23 ~19 wool 8
fill ~75 ~23 ~20 ~77 ~23 ~20 wool 8
fill ~75 ~23 ~21 ~75 ~22 ~21 wool 8
fill ~75 ~23 ~22 ~93 ~23 ~22 wool 8
fill ~75 ~23 ~24 ~93 ~23 ~24 wool 8
fill ~75 ~23 ~25 ~93 ~23 ~25 wool 8
fill ~75 ~23 ~26 ~89 ~23 ~26 wool 8
fill ~75 ~23 ~27 ~76 ~23 ~27 wool 8
fill ~75 ~23 ~28 ~77 ~23 ~28 wool 8
fill ~75 ~23 ~29 ~77 ~23 ~29 wool 8
fill ~75 ~23 ~30 ~93 ~23 ~30 wool 8
fill ~75 ~23 ~32 ~93 ~23 ~32 wool 8
fill ~75 ~23 ~33 ~76 ~23 ~33 wool 8
fill ~75 ~23 ~34 ~77 ~23 ~34 wool 8
fill ~75 ~23 ~35 ~77 ~23 ~35 wool 8
fill ~76 ~23 ~18 ~93 ~23 ~18 wool 8
fill ~76 ~23 ~21 ~78 ~23 ~21 wool 14
fill ~76 ~23 ~31 ~93 ~23 ~31 wool 8
fill ~76 ~23 ~36 ~93 ~23 ~36 wool 8
fill ~77 ~23 ~23 ~93 ~23 ~23 wool 8
fill ~77 ~23 ~27 ~78 ~23 ~27 wool 14
fill ~77 ~23 ~33 ~78 ~23 ~33 wool 14
setblock ~78 ~23 ~20 wool 14
fill ~78 ~23 ~28 ~78 ~23 ~29 wool 14
fill ~78 ~23 ~34 ~78 ~23 ~35 wool 14
fill ~79 ~23 ~20 ~83 ~23 ~20 wool 8
