fill ~63~49~8 ~70~49~8
fill ~71~49~8 ~71~49~10
fill ~280 ~-3 ~20 ~282 ~-3 ~20 stained_hardened_clay 9
fill ~281 ~-3 ~19 ~281 ~-2 ~19 stained_hardened_clay 9
fill ~281 ~-3 ~21 ~281 ~-1 ~21 stained_hardened_clay 9
fill ~282 ~-3 ~19 ~283 ~-3 ~19 bedrock 0
fill ~283 ~-3 ~18 ~283 ~-3 ~18 coal_block 0
setblock ~283 ~-3 ~20 coal_block 0
fill ~284 ~-3 ~19 ~284 ~-3 ~19 coal_block 0
setblock ~284 ~-3 ~40 stone 0
fill ~284 ~-3 ~41 ~285 ~-3 ~41 coal_block 0
setblock ~285 ~-3 ~40 coal_block 0
fill ~279 ~-2 ~20 ~280 ~-2 ~20 stained_hardened_clay 9
fill ~279 ~-2 ~21 ~281 ~-2 ~21 stained_hardened_clay 9
fill ~280 ~-2 ~19 ~280 ~-1 ~19 stained_hardened_clay 9
fill ~281 ~-2 ~20 ~282 ~-2 ~20 bedrock 0
fill ~282 ~-2 ~19 ~282 ~-3 ~19 bedrock 0
fill ~283 ~-2 ~40 ~283 ~-1 ~40 stained_hardened_clay 9
fill ~284 ~-2 ~39 ~284 ~0 ~39 stained_hardened_clay 9
fill ~284 ~-2 ~40 ~284 ~0 ~40 bedrock 0
fill ~284 ~-2 ~41 ~284 ~-1 ~41 bedrock 0
setblock ~285 ~-2 ~40 stone 0
setblock ~285 ~-2 ~41 coal_block 0
fill ~264 ~-1 ~13 ~264 ~3 ~13 coal_block 0
fill ~278 ~-1 ~21 ~281 ~-1 ~21 stained_hardened_clay 9
fill ~279 ~-1 ~20 ~280 ~-1 ~20 stained_hardened_clay 9
fill ~279 ~-1 ~22 ~280 ~-1 ~22 stained_hardened_clay 9
fill ~281 ~-1 ~20 ~281 ~0 ~20 bedrock 0
fill ~282 ~-1 ~39 ~284 ~-1 ~39 stained_hardened_clay 9
fill ~283 ~-1 ~41 ~283 ~0 ~41 stained_hardened_clay 9
setblock ~285 ~-1 ~40 stained_hardened_clay 9
setblock ~285 ~-1 ~41 bedrock 0
fill ~220 ~0 ~3 ~222 ~0 ~3 coal_block 0
fill ~220 ~0 ~97 ~222 ~0 ~97 coal_block 0
fill ~221 ~0 ~2 ~223 ~0 ~2 coal_block 0
setblock ~221 ~0 ~4 coal_block 0
setblock ~221 ~0 ~96 coal_block 0
fill ~221 ~0 ~98 ~223 ~0 ~98 coal_block 0
fill ~222 ~0 ~1 ~224 ~0 ~1 coal_block 0
fill ~222 ~0 ~99 ~224 ~0 ~99 coal_block 0
fill ~223 ~0 ~0 ~224 ~0 ~0 coal_block 0
fill ~223 ~0 ~7 ~225 ~0 ~7 coal_block 0
fill ~223 ~0 ~8 ~224 ~0 ~8 coal_block 0
fill ~223 ~0 ~92 ~224 ~0 ~92 coal_block 0
fill ~223 ~0 ~93 ~225 ~0 ~93 coal_block 0
fill ~223 ~0 ~100 ~224 ~0 ~100 coal_block 0
fill ~224 ~0 ~6 ~226 ~0 ~6 coal_block 0
fill ~224 ~0 ~11 ~228 ~0 ~11 coal_block 0
fill ~224 ~0 ~12 ~226 ~0 ~12 coal_block 0
fill ~224 ~0 ~17 ~229 ~0 ~17 coal_block 0
fill ~224 ~0 ~83 ~229 ~0 ~83 coal_block 0
fill ~224 ~0 ~88 ~226 ~0 ~88 coal_block 0
fill ~224 ~0 ~89 ~228 ~0 ~89 coal_block 0
fill ~224 ~0 ~94 ~226 ~0 ~94 coal_block 0
fill ~225 ~0 ~16 ~227 ~0 ~16 coal_block 0
fill ~225 ~0 ~18 ~226 ~0 ~18 coal_block 0
fill ~225 ~0 ~82 ~226 ~0 ~82 coal_block 0
fill ~225 ~0 ~84 ~227 ~0 ~84 coal_block 0
fill ~226 ~0 ~5 ~227 ~0 ~5 coal_block 0
fill ~226 ~0 ~95 ~227 ~0 ~95 coal_block 0
fill ~227 ~0 ~10 ~229 ~0 ~10 coal_block 0
fill ~227 ~0 ~90 ~229 ~0 ~90 coal_block 0
fill ~277 ~0 ~21 ~279 ~0 ~21 bedrock 0
fill ~277 ~0 ~22 ~279 ~0 ~22 bedrock 0
fill ~278 ~0 ~20 ~278 ~2 ~20 bedrock 0
fill ~279 ~0 ~20 ~279 ~-2 ~20 stained_hardened_clay 9
fill ~280 ~0 ~20 ~280 ~1 ~20 bedrock 0
setblock ~280 ~0 ~21 stained_hardened_clay 9
fill ~281 ~0 ~39 ~284 ~0 ~39 stained_hardened_clay 9
fill ~282 ~0 ~38 ~283 ~0 ~38 stained_hardened_clay 9
fill ~282 ~0 ~40 ~282 ~1 ~40 stained_hardened_clay 9
fill ~283 ~0 ~40 ~283 ~1 ~40 bedrock 0
fill ~219 ~1 ~3 ~220 ~1 ~3 stained_hardened_clay 9
fill ~219 ~1 ~4 ~221 ~1 ~4 stained_hardened_clay 9
fill ~219 ~1 ~5 ~220 ~1 ~5 stained_hardened_clay 9
fill ~219 ~1 ~95 ~220 ~1 ~95 stained_hardened_clay 9
fill ~219 ~1 ~96 ~221 ~1 ~96 stained_hardened_clay 9
fill ~219 ~1 ~97 ~220 ~1 ~97 stained_hardened_clay 9
setblock ~221 ~1 ~3 coal_block 0
setblock ~221 ~1 ~97 coal_block 0
setblock ~222 ~1 ~2 coal_block 0
fill ~222 ~1 ~7 ~223 ~1 ~7 stained_hardened_clay 9
fill ~222 ~1 ~8 ~223 ~1 ~8 stained_hardened_clay 9
fill ~222 ~1 ~92 ~223 ~1 ~92 stained_hardened_clay 9
fill ~222 ~1 ~93 ~223 ~1 ~93 stained_hardened_clay 9
setblock ~222 ~1 ~98 coal_block 0
setblock ~223 ~1 ~9 stained_hardened_clay 9
fill ~223 ~1 ~11 ~224 ~1 ~11 stained_hardened_clay 9
fill ~223 ~1 ~12 ~224 ~1 ~12 stained_hardened_clay 9
fill ~223 ~1 ~16 ~224 ~1 ~16 stained_hardened_clay 9
fill ~223 ~1 ~17 ~224 ~1 ~17 stained_hardened_clay 9
fill ~223 ~1 ~18 ~224 ~1 ~18 stained_hardened_clay 9
fill ~223 ~1 ~82 ~224 ~1 ~82 stained_hardened_clay 9
fill ~223 ~1 ~83 ~224 ~1 ~83 stained_hardened_clay 9
fill ~223 ~1 ~84 ~224 ~1 ~84 stained_hardened_clay 9
fill ~223 ~1 ~88 ~224 ~1 ~88 stained_hardened_clay 9
fill ~223 ~1 ~89 ~224 ~1 ~89 stained_hardened_clay 9
setblock ~223 ~1 ~91 stained_hardened_clay 9
setblock ~224 ~1 ~7 coal_block 0
setblock ~224 ~1 ~93 coal_block 0
setblock ~225 ~1 ~11 coal_block 0
setblock ~225 ~1 ~17 coal_block 0
setblock ~225 ~1 ~83 coal_block 0
setblock ~225 ~1 ~89 coal_block 0
fill ~264 ~1 ~14 ~264 ~3 ~14 coal_block 0
fill ~276 ~1 ~21 ~276 ~3 ~21 stained_hardened_clay 9
fill ~276 ~1 ~22 ~276 ~2 ~22 stained_hardened_clay 9
fill ~277 ~1 ~20 ~277 ~1 ~22 bedrock 0
fill ~278 ~1 ~21 ~280 ~1 ~21 bedrock 0
fill ~278 ~1 ~22 ~279 ~1 ~22 bedrock 0
setblock ~279 ~1 ~20 bedrock 0
fill ~280 ~1 ~39 ~282 ~1 ~39 bedrock 0
fill ~281 ~1 ~38 ~281 ~3 ~38 bedrock 0
fill ~281 ~1 ~40 ~281 ~3 ~40 bedrock 0
fill ~282 ~1 ~38 ~282 ~0 ~38 stained_hardened_clay 9
setblock ~283 ~1 ~39 stained_hardened_clay 9
fill ~217 ~2 ~5 ~218 ~2 ~5 stained_hardened_clay 9
fill ~217 ~2 ~6 ~219 ~2 ~6 stained_hardened_clay 9
fill ~217 ~2 ~7 ~218 ~2 ~7 stained_hardened_clay 9
fill ~217 ~2 ~93 ~218 ~2 ~93 stained_hardened_clay 9
fill ~217 ~2 ~94 ~219 ~2 ~94 stained_hardened_clay 9
fill ~217 ~2 ~95 ~218 ~2 ~95 stained_hardened_clay 9
setblock ~218 ~2 ~4 stained_hardened_clay 9
setblock ~218 ~2 ~96 stained_hardened_clay 9
fill ~219 ~2 ~4 ~220 ~2 ~4 bedrock 0
fill ~219 ~2 ~5 ~219 ~2 ~4 bedrock 0
fill ~219 ~2 ~9 ~222 ~2 ~9 stained_hardened_clay 9
fill ~219 ~2 ~91 ~222 ~2 ~91 stained_hardened_clay 9
fill ~219 ~2 ~95 ~219 ~2 ~96 bedrock 0
fill ~220 ~2 ~8 ~221 ~2 ~8 stained_hardened_clay 9
fill ~220 ~2 ~12 ~223 ~2 ~12 stained_hardened_clay 9
fill ~220 ~2 ~13 ~223 ~2 ~13 stained_hardened_clay 9
fill ~220 ~2 ~14 ~220 ~4 ~14 stained_hardened_clay 9
fill ~220 ~2 ~17 ~224 ~2 ~17 stained_hardened_clay 9
fill ~220 ~2 ~83 ~224 ~2 ~83 stained_hardened_clay 9
fill ~220 ~2 ~86 ~220 ~4 ~86 stained_hardened_clay 9
fill ~220 ~2 ~87 ~223 ~2 ~87 stained_hardened_clay 9
fill ~220 ~2 ~88 ~223 ~2 ~88 stained_hardened_clay 9
fill ~220 ~2 ~92 ~221 ~2 ~92 stained_hardened_clay 9
setblock ~220 ~2 ~96 bedrock 0
fill ~221 ~2 ~16 ~223 ~2 ~16 stained_hardened_clay 9
fill ~221 ~2 ~84 ~223 ~2 ~84 stained_hardened_clay 9
setblock ~222 ~2 ~8 bedrock 0
fill ~222 ~2 ~18 ~223 ~2 ~18 stained_hardened_clay 9
fill ~222 ~2 ~82 ~223 ~2 ~82 stained_hardened_clay 9
setblock ~222 ~2 ~92 bedrock 0
fill ~262 ~2 ~42 ~262 ~3 ~42 stained_hardened_clay 9
fill ~263 ~2 ~13 ~263 ~3 ~13 coal_block 0
fill ~263 ~2 ~14 ~263 ~4 ~14 stained_hardened_clay 9
fill ~263 ~2 ~43 ~263 ~3 ~43 stained_hardened_clay 9
fill ~263 ~2 ~44 ~265 ~2 ~44 coal_block 0
fill ~264 ~2 ~43 ~264 ~3 ~43 coal_block 0
fill ~264 ~2 ~45 ~265 ~2 ~45 coal_block 0
fill ~274 ~2 ~22 ~276 ~2 ~22 stained_hardened_clay 9
fill ~274 ~2 ~23 ~276 ~2 ~23 stained_hardened_clay 9
fill ~277 ~2 ~21 ~279 ~2 ~21 bedrock 0
fill ~277 ~2 ~22 ~278 ~2 ~22 bedrock 0
fill ~280 ~2 ~37 ~281 ~2 ~37 stained_hardened_clay 9
fill ~280 ~2 ~38 ~280 ~2 ~40 bedrock 0
fill ~281 ~2 ~39 ~282 ~2 ~39 bedrock 0
setblock ~282 ~2 ~38 bedrock 0
setblock ~282 ~2 ~40 bedrock 0
fill ~216 ~3 ~6 ~216 ~3 ~8 stained_hardened_clay 9
fill ~216 ~3 ~92 ~217 ~3 ~92 stained_hardened_clay 9
fill ~216 ~3 ~93 ~217 ~3 ~93 stained_hardened_clay 9
fill ~216 ~3 ~94 ~216 ~3 ~92 stained_hardened_clay 9
fill ~217 ~3 ~6 ~218 ~3 ~6 bedrock 0
fill ~217 ~3 ~7 ~217 ~2 ~7 stained_hardened_clay 9
fill ~217 ~3 ~8 ~217 ~3 ~7 stained_hardened_clay 9
fill ~217 ~3 ~94 ~218 ~3 ~94 bedrock 0
setblock ~218 ~3 ~5 bedrock 0
fill ~218 ~3 ~10 ~221 ~3 ~10 stained_hardened_clay 9
fill ~218 ~3 ~90 ~221 ~3 ~90 stained_hardened_clay 9
setblock ~218 ~3 ~95 bedrock 0
fill ~219 ~3 ~8 ~219 ~3 ~10 stained_hardened_clay 9
fill ~219 ~3 ~13 ~220 ~3 ~13 stained_hardened_clay 9
fill ~219 ~3 ~17 ~221 ~3 ~17 stained_hardened_clay 9
fill ~219 ~3 ~83 ~221 ~3 ~83 stained_hardened_clay 9
fill ~219 ~3 ~87 ~220 ~3 ~87 stained_hardened_clay 9
fill ~219 ~3 ~91 ~219 ~4 ~91 stained_hardened_clay 9
fill ~219 ~3 ~92 ~219 ~3 ~90 stained_hardened_clay 9
fill ~220 ~3 ~9 ~221 ~3 ~9 bedrock 0
fill ~220 ~3 ~12 ~220 ~2 ~12 stained_hardened_clay 9
fill ~220 ~3 ~16 ~221 ~3 ~16 stained_hardened_clay 9
fill ~220 ~3 ~84 ~221 ~3 ~84 stained_hardened_clay 9
fill ~220 ~3 ~88 ~220 ~2 ~88 stained_hardened_clay 9
fill ~220 ~3 ~91 ~221 ~3 ~91 bedrock 0
setblock ~221 ~3 ~8 bedrock 0
fill ~221 ~3 ~12 ~222 ~3 ~12 bedrock 0
fill ~221 ~3 ~13 ~221 ~4 ~13 bedrock 0
setblock ~221 ~3 ~14 stained_hardened_clay 9
setblock ~221 ~3 ~18 stained_hardened_clay 9
setblock ~221 ~3 ~82 stained_hardened_clay 9
setblock ~221 ~3 ~86 stained_hardened_clay 9
fill ~221 ~3 ~87 ~221 ~4 ~87 bedrock 0
fill ~221 ~3 ~88 ~222 ~3 ~88 bedrock 0
setblock ~221 ~3 ~92 bedrock 0
fill ~222 ~3 ~17 ~223 ~3 ~17 bedrock 0
fill ~222 ~3 ~83 ~223 ~3 ~83 bedrock 0
fill ~260 ~3 ~40 ~260 ~4 ~40 stained_hardened_clay 9
fill ~260 ~3 ~41 ~262 ~3 ~41 stained_hardened_clay 9
fill ~261 ~3 ~42 ~261 ~4 ~42 stained_hardened_clay 9
fill ~262 ~3 ~14 ~262 ~5 ~14 stained_hardened_clay 9
fill ~262 ~3 ~15 ~264 ~3 ~15 stained_hardened_clay 9
setblock ~262 ~3 ~43 stained_hardened_clay 9
fill ~263 ~3 ~42 ~263 ~4 ~42 stained_hardened_clay 9
fill ~263 ~3 ~44 ~264 ~3 ~44 coal_block 0
fill ~272 ~3 ~23 ~276 ~3 ~23 stained_hardened_clay 9
fill ~273 ~3 ~22 ~275 ~3 ~22 stained_hardened_clay 9
fill ~274 ~3 ~24 ~275 ~3 ~24 stained_hardened_clay 9
setblock ~275 ~3 ~21 stained_hardened_clay 9
fill ~276 ~3 ~22 ~277 ~3 ~22 bedrock 0
fill ~277 ~3 ~21 ~277 ~0 ~21 bedrock 0
fill ~278 ~3 ~37 ~281 ~3 ~37 stained_hardened_clay 9
fill ~279 ~3 ~38 ~280 ~3 ~38 stained_hardened_clay 9
setblock ~280 ~3 ~36 stained_hardened_clay 9
fill ~280 ~3 ~39 ~282 ~3 ~39 bedrock 0
fill ~215 ~4 ~6 ~215 ~4 ~7 stained_hardened_clay 9
setblock ~215 ~4 ~8 stone 0
setblock ~215 ~4 ~92 stone 0
fill ~215 ~4 ~93 ~215 ~4 ~94 stained_hardened_clay 9
fill ~216 ~4 ~7 ~217 ~4 ~7 bedrock 0
setblock ~216 ~4 ~8 stained_hardened_clay 9
setblock ~216 ~4 ~92 stained_hardened_clay 9
fill ~216 ~4 ~93 ~217 ~4 ~93 bedrock 0
fill ~217 ~4 ~6 ~217 ~3 ~6 bedrock 0
fill ~217 ~4 ~94 ~217 ~3 ~94 bedrock 0
fill ~218 ~4 ~9 ~219 ~4 ~9 stained_hardened_clay 9
fill ~218 ~4 ~10 ~218 ~5 ~10 stained_hardened_clay 9
fill ~218 ~4 ~90 ~218 ~5 ~90 stained_hardened_clay 9
fill ~218 ~4 ~91 ~218 ~5 ~91 stained_hardened_clay 9
fill ~219 ~4 ~10 ~220 ~4 ~10 bedrock 0
fill ~219 ~4 ~12 ~219 ~4 ~14 stained_hardened_clay 9
fill ~219 ~4 ~17 ~220 ~4 ~17 stained_hardened_clay 9
fill ~219 ~4 ~83 ~220 ~4 ~83 stained_hardened_clay 9
fill ~219 ~4 ~86 ~219 ~4 ~88 stained_hardened_clay 9
fill ~219 ~4 ~90 ~220 ~4 ~90 bedrock 0
fill ~220 ~4 ~9 ~220 ~3 ~9 bedrock 0
fill ~220 ~4 ~13 ~220 ~5 ~13 bedrock 0
fill ~220 ~4 ~16 ~220 ~5 ~16 stained_hardened_clay 9
fill ~220 ~4 ~18 ~220 ~5 ~18 stained_hardened_clay 9
fill ~220 ~4 ~82 ~220 ~5 ~82 stained_hardened_clay 9
fill ~220 ~4 ~84 ~220 ~5 ~84 stained_hardened_clay 9
fill ~220 ~4 ~87 ~220 ~5 ~87 bedrock 0
fill ~220 ~4 ~91 ~220 ~3 ~91 bedrock 0
fill ~221 ~4 ~17 ~222 ~4 ~17 bedrock 0
fill ~221 ~4 ~83 ~222 ~4 ~83 bedrock 0
fill ~258 ~4 ~37 ~258 ~4 ~38 stained_hardened_clay 9
fill ~259 ~4 ~38 ~259 ~5 ~38 stained_hardened_clay 9
fill ~259 ~4 ~39 ~260 ~4 ~39 stained_hardened_clay 9
fill ~259 ~4 ~40 ~259 ~5 ~40 stained_hardened_clay 9
fill ~259 ~4 ~41 ~262 ~4 ~41 stained_hardened_clay 9
setblock ~260 ~4 ~42 stained_hardened_clay 9
fill ~261 ~4 ~15 ~264 ~4 ~15 stained_hardened_clay 9
fill ~261 ~4 ~16 ~263 ~4 ~16 stained_hardened_clay 9
fill ~261 ~4 ~40 ~261 ~5 ~40 stained_hardened_clay 9
fill ~262 ~4 ~42 ~262 ~5 ~42 bedrock 0
fill ~262 ~4 ~43 ~263 ~4 ~43 bedrock 0
setblock ~263 ~4 ~13 stained_hardened_clay 9
fill ~264 ~4 ~13 ~264 ~4 ~14 bedrock 0
fill ~269 ~4 ~24 ~272 ~4 ~24 stained_hardened_clay 9
fill ~270 ~4 ~23 ~271 ~4 ~23 stained_hardened_clay 9
setblock ~272 ~4 ~22 stained_hardened_clay 9
fill ~272 ~4 ~23 ~275 ~4 ~23 bedrock 0
fill ~273 ~4 ~22 ~273 ~6 ~22 bedrock 0
fill ~273 ~4 ~24 ~273 ~6 ~24 bedrock 0
setblock ~274 ~4 ~22 stained_hardened_clay 9
fill ~274 ~4 ~24 ~274 ~3 ~24 stained_hardened_clay 9
fill ~275 ~4 ~22 ~276 ~4 ~22 bedrock 0
fill ~277 ~4 ~36 ~279 ~4 ~36 stained_hardened_clay 9
fill ~277 ~4 ~37 ~280 ~4 ~37 stained_hardened_clay 9
fill ~278 ~4 ~38 ~279 ~4 ~38 stained_hardened_clay 9
fill ~280 ~4 ~38 ~280 ~5 ~38 bedrock 0
fill ~280 ~4 ~39 ~281 ~4 ~39 bedrock 0
fill ~214 ~5 ~7 ~214 ~6 ~7 stained_hardened_clay 9
fill ~214 ~5 ~8 ~214 ~6 ~8 stained_hardened_clay 9
fill ~214 ~5 ~9 ~215 ~5 ~9 stained_hardened_clay 9
fill ~214 ~5 ~91 ~215 ~5 ~91 stained_hardened_clay 9
fill ~214 ~5 ~92 ~214 ~6 ~92 stained_hardened_clay 9
fill ~214 ~5 ~93 ~214 ~6 ~93 stained_hardened_clay 9
fill ~215 ~5 ~8 ~216 ~5 ~8 bedrock 0
fill ~215 ~5 ~92 ~216 ~5 ~92 bedrock 0
fill ~216 ~5 ~7 ~216 ~4 ~7 bedrock 0
fill ~216 ~5 ~93 ~216 ~4 ~93 bedrock 0
fill ~217 ~5 ~10 ~217 ~8 ~10 stained_hardened_clay 9
fill ~217 ~5 ~90 ~217 ~8 ~90 stained_hardened_clay 9
fill ~218 ~5 ~9 ~218 ~4 ~9 stained_hardened_clay 9
fill ~218 ~5 ~13 ~219 ~5 ~13 stained_hardened_clay 9
fill ~218 ~5 ~17 ~219 ~5 ~17 stained_hardened_clay 9
fill ~218 ~5 ~83 ~219 ~5 ~83 stained_hardened_clay 9
fill ~218 ~5 ~87 ~219 ~5 ~87 stained_hardened_clay 9
fill ~219 ~5 ~10 ~219 ~6 ~10 bedrock 0
setblock ~219 ~5 ~11 stained_hardened_clay 9
fill ~219 ~5 ~14 ~220 ~5 ~14 bedrock 0
fill ~219 ~5 ~16 ~219 ~6 ~16 stained_hardened_clay 9
fill ~219 ~5 ~84 ~219 ~6 ~84 stained_hardened_clay 9
fill ~219 ~5 ~86 ~220 ~5 ~86 bedrock 0
setblock ~219 ~5 ~89 stained_hardened_clay 9
fill ~219 ~5 ~90 ~219 ~6 ~90 bedrock 0
fill ~220 ~5 ~17 ~221 ~5 ~17 bedrock 0
fill ~220 ~5 ~83 ~221 ~5 ~83 bedrock 0
fill ~256 ~5 ~35 ~257 ~5 ~35 stained_hardened_clay 9
setblock ~257 ~5 ~36 stained_hardened_clay 9
fill ~257 ~5 ~37 ~259 ~5 ~37 bedrock 0
setblock ~257 ~5 ~38 stained_hardened_clay 9
fill ~258 ~5 ~36 ~258 ~8 ~36 bedrock 0
fill ~258 ~5 ~38 ~258 ~7 ~38 bedrock 0
fill ~258 ~5 ~39 ~260 ~5 ~39 stained_hardened_clay 9
setblock ~260 ~5 ~16 stained_hardened_clay 9
fill ~260 ~5 ~17 ~262 ~5 ~17 bedrock 0
setblock ~260 ~5 ~38 stained_hardened_clay 9
fill ~260 ~5 ~40 ~260 ~6 ~40 bedrock 0
fill ~260 ~5 ~41 ~261 ~5 ~41 bedrock 0
fill ~261 ~5 ~15 ~262 ~5 ~15 stained_hardened_clay 9
fill ~261 ~5 ~16 ~261 ~7 ~16 bedrock 0
fill ~261 ~5 ~18 ~261 ~7 ~18 bedrock 0
setblock ~261 ~5 ~42 bedrock 0
fill ~262 ~5 ~16 ~263 ~5 ~16 stained_hardened_clay 9
fill ~263 ~5 ~14 ~264 ~5 ~14 bedrock 0
fill ~263 ~5 ~15 ~263 ~6 ~15 bedrock 0
fill ~266 ~5 ~24 ~271 ~5 ~24 stained_hardened_clay 9
fill ~268 ~5 ~23 ~271 ~5 ~23 stained_hardened_clay 9
fill ~269 ~5 ~25 ~271 ~5 ~25 stained_hardened_clay 9
setblock ~271 ~5 ~22 stained_hardened_clay 9
fill ~272 ~5 ~22 ~272 ~5 ~24 bedrock 0
fill ~273 ~5 ~23 ~275 ~5 ~23 bedrock 0
setblock ~274 ~5 ~22 bedrock 0
setblock ~274 ~5 ~24 bedrock 0
fill ~275 ~5 ~35 ~278 ~5 ~35 stained_hardened_clay 9
fill ~276 ~5 ~36 ~279 ~5 ~36 stained_hardened_clay 9
fill ~277 ~5 ~37 ~278 ~5 ~37 stained_hardened_clay 9
fill ~278 ~5 ~38 ~278 ~4 ~38 stained_hardened_clay 9
fill ~279 ~5 ~37 ~279 ~6 ~37 bedrock 0
fill ~279 ~5 ~38 ~279 ~5 ~37 bedrock 0
fill ~214 ~6 ~9 ~215 ~6 ~9 stained_hardened_clay 9
fill ~214 ~6 ~10 ~217 ~6 ~10 stained_hardened_clay 9
fill ~214 ~6 ~90 ~217 ~6 ~90 stained_hardened_clay 9
fill ~214 ~6 ~91 ~215 ~6 ~91 stained_hardened_clay 9
fill ~215 ~6 ~8 ~215 ~7 ~8 bedrock 0
fill ~215 ~6 ~11 ~218 ~6 ~11 stained_hardened_clay 9
fill ~215 ~6 ~89 ~218 ~6 ~89 stained_hardened_clay 9
fill ~215 ~6 ~92 ~215 ~7 ~92 bedrock 0
fill ~216 ~6 ~12 ~217 ~6 ~12 stained_hardened_clay 9
fill ~216 ~6 ~88 ~217 ~6 ~88 stained_hardened_clay 9
setblock ~217 ~6 ~9 stained_hardened_clay 9
fill ~217 ~6 ~13 ~218 ~6 ~13 stained_hardened_clay 9
fill ~217 ~6 ~14 ~218 ~6 ~14 stained_hardened_clay 9
fill ~217 ~6 ~16 ~219 ~6 ~16 stained_hardened_clay 9
fill ~217 ~6 ~17 ~218 ~6 ~17 stained_hardened_clay 9
fill ~217 ~6 ~83 ~218 ~6 ~83 stained_hardened_clay 9
fill ~217 ~6 ~84 ~219 ~6 ~84 stained_hardened_clay 9
fill ~217 ~6 ~86 ~218 ~6 ~86 stained_hardened_clay 9
fill ~217 ~6 ~87 ~218 ~6 ~87 stained_hardened_clay 9
setblock ~217 ~6 ~91 stained_hardened_clay 9
fill ~218 ~6 ~10 ~218 ~7 ~10 bedrock 0
fill ~218 ~6 ~90 ~218 ~7 ~90 bedrock 0
fill ~219 ~6 ~14 ~219 ~8 ~14 bedrock 0
fill ~219 ~6 ~17 ~220 ~6 ~17 bedrock 0
fill ~219 ~6 ~18 ~219 ~7 ~18 stained_hardened_clay 9
fill ~219 ~6 ~82 ~219 ~7 ~82 stained_hardened_clay 9
fill ~219 ~6 ~83 ~220 ~6 ~83 bedrock 0
fill ~219 ~6 ~86 ~219 ~8 ~86 bedrock 0
setblock ~255 ~6 ~35 stone 0
fill ~256 ~6 ~33 ~256 ~8 ~33 stone 0
fill ~256 ~6 ~34 ~257 ~6 ~34 stained_hardened_clay 9
fill ~256 ~6 ~35 ~260 ~6 ~35 stained_hardened_clay 9
fill ~256 ~6 ~36 ~256 ~7 ~36 stained_hardened_clay 9
fill ~256 ~6 ~37 ~256 ~6 ~34 stained_hardened_clay 9
fill ~257 ~6 ~36 ~257 ~6 ~38 bedrock 0
fill ~258 ~6 ~20 ~259 ~6 ~20 stained_hardened_clay 9
fill ~258 ~6 ~37 ~259 ~6 ~37 bedrock 0
fill ~259 ~6 ~17 ~259 ~7 ~17 stained_hardened_clay 9
fill ~259 ~6 ~18 ~259 ~7 ~18 stained_hardened_clay 9
fill ~259 ~6 ~19 ~260 ~6 ~19 stained_hardened_clay 9
setblock ~259 ~6 ~36 bedrock 0
fill ~259 ~6 ~38 ~259 ~6 ~40 bedrock 0
fill ~260 ~6 ~16 ~260 ~6 ~18 bedrock 0
fill ~260 ~6 ~34 ~262 ~6 ~34 stained_hardened_clay 9
setblock ~260 ~6 ~36 stained_hardened_clay 9
fill ~261 ~6 ~17 ~262 ~6 ~17 bedrock 0
fill ~262 ~6 ~15 ~262 ~6 ~18 bedrock 0
fill ~262 ~6 ~24 ~271 ~6 ~24 stained_hardened_clay 9
fill ~262 ~6 ~25 ~269 ~6 ~25 stained_hardened_clay 9
fill ~266 ~6 ~23 ~269 ~6 ~23 stained_hardened_clay 9
fill ~270 ~6 ~23 ~274 ~6 ~23 bedrock 0
fill ~270 ~6 ~33 ~272 ~6 ~33 stained_hardened_clay 9
fill ~272 ~6 ~34 ~275 ~6 ~34 stained_hardened_clay 9
fill ~275 ~6 ~35 ~277 ~6 ~35 bedrock 0
fill ~276 ~6 ~34 ~276 ~8 ~34 bedrock 0
fill ~276 ~6 ~36 ~276 ~8 ~36 bedrock 0
setblock ~277 ~6 ~34 stained_hardened_clay 9
fill ~277 ~6 ~36 ~277 ~6 ~37 stained_hardened_clay 9
setblock ~278 ~6 ~35 stained_hardened_clay 9
fill ~278 ~6 ~36 ~278 ~7 ~36 bedrock 0
fill ~278 ~6 ~37 ~278 ~6 ~36 bedrock 0
setblock ~213 ~7 ~8 stained_hardened_clay 9
fill ~213 ~7 ~10 ~214 ~7 ~10 stained_hardened_clay 9
fill ~213 ~7 ~90 ~214 ~7 ~90 stained_hardened_clay 9
setblock ~213 ~7 ~92 stained_hardened_clay 9
fill ~214 ~7 ~8 ~214 ~8 ~8 bedrock 0
fill ~214 ~7 ~9 ~215 ~7 ~9 stained_hardened_clay 9
fill ~214 ~7 ~11 ~215 ~7 ~11 stained_hardened_clay 9
fill ~214 ~7 ~89 ~215 ~7 ~89 stained_hardened_clay 9
fill ~214 ~7 ~91 ~215 ~7 ~91 stained_hardened_clay 9
fill ~214 ~7 ~92 ~214 ~8 ~92 bedrock 0
fill ~215 ~7 ~10 ~216 ~7 ~10 coal_block 0
fill ~215 ~7 ~12 ~216 ~7 ~12 stained_hardened_clay 9
fill ~215 ~7 ~13 ~216 ~7 ~13 stained_hardened_clay 9
fill ~215 ~7 ~14 ~218 ~7 ~14 stained_hardened_clay 9
fill ~215 ~7 ~86 ~218 ~7 ~86 stained_hardened_clay 9
fill ~215 ~7 ~87 ~216 ~7 ~87 stained_hardened_clay 9
fill ~215 ~7 ~88 ~216 ~7 ~88 stained_hardened_clay 9
fill ~215 ~7 ~90 ~216 ~7 ~90 coal_block 0
setblock ~216 ~7 ~11 coal_block 0
fill ~216 ~7 ~15 ~217 ~7 ~15 stained_hardened_clay 9
fill ~216 ~7 ~16 ~216 ~8 ~16 stained_hardened_clay 9
fill ~216 ~7 ~84 ~216 ~8 ~84 stained_hardened_clay 9
fill ~216 ~7 ~85 ~217 ~7 ~85 stained_hardened_clay 9
setblock ~216 ~7 ~89 coal_block 0
fill ~217 ~7 ~11 ~217 ~8 ~11 stained_hardened_clay 9
fill ~217 ~7 ~12 ~217 ~7 ~13 coal_block 0
fill ~217 ~7 ~16 ~217 ~8 ~16 coal_block 0
fill ~217 ~7 ~17 ~218 ~7 ~17 stained_hardened_clay 9
fill ~217 ~7 ~83 ~218 ~7 ~83 stained_hardened_clay 9
fill ~217 ~7 ~84 ~217 ~8 ~84 coal_block 0
fill ~217 ~7 ~87 ~217 ~7 ~88 coal_block 0
fill ~217 ~7 ~89 ~217 ~8 ~89 stained_hardened_clay 9
fill ~218 ~7 ~11 ~218 ~9 ~11 bedrock 0
setblock ~218 ~7 ~13 stained_hardened_clay 9
setblock ~218 ~7 ~18 stained_hardened_clay 9
setblock ~218 ~7 ~82 stained_hardened_clay 9
setblock ~218 ~7 ~87 stained_hardened_clay 9
fill ~218 ~7 ~89 ~218 ~9 ~89 bedrock 0
fill ~219 ~7 ~17 ~219 ~8 ~17 bedrock 0
fill ~219 ~7 ~83 ~219 ~8 ~83 bedrock 0
fill ~255 ~7 ~23 ~256 ~7 ~23 stone 0
fill ~255 ~7 ~30 ~255 ~9 ~30 stone 0
fill ~255 ~7 ~31 ~255 ~8 ~31 stone 0
fill ~255 ~7 ~32 ~256 ~7 ~32 stone 0
fill ~255 ~7 ~33 ~255 ~9 ~33 stone 0
fill ~255 ~7 ~34 ~255 ~8 ~34 stone 0
fill ~255 ~7 ~35 ~257 ~7 ~35 stained_hardened_clay 9
fill ~256 ~7 ~22 ~262 ~7 ~22 stained_hardened_clay 9
fill ~256 ~7 ~24 ~256 ~8 ~24 stone 0
fill ~256 ~7 ~25 ~256 ~8 ~25 stone 0
fill ~256 ~7 ~29 ~256 ~8 ~29 stone 0
fill ~256 ~7 ~34 ~259 ~7 ~34 stained_hardened_clay 9
fill ~257 ~7 ~20 ~261 ~7 ~20 stained_hardened_clay 9
fill ~257 ~7 ~21 ~261 ~7 ~21 stained_hardened_clay 9
fill ~257 ~7 ~23 ~257 ~7 ~25 stained_hardened_clay 9
fill ~257 ~7 ~30 ~258 ~7 ~30 stone 0
fill ~257 ~7 ~33 ~257 ~9 ~33 stained_hardened_clay 9
setblock ~257 ~7 ~36 stained_hardened_clay 9
fill ~257 ~7 ~37 ~259 ~7 ~37 bedrock 0
fill ~258 ~7 ~18 ~258 ~7 ~22 stained_hardened_clay 9
fill ~258 ~7 ~24 ~266 ~7 ~24 stained_hardened_clay 9
fill ~258 ~7 ~25 ~268 ~7 ~25 stained_hardened_clay 9
fill ~259 ~7 ~19 ~260 ~7 ~19 stained_hardened_clay 9
fill ~259 ~7 ~23 ~264 ~7 ~23 stained_hardened_clay 9
fill ~259 ~7 ~26 ~260 ~7 ~26 stained_hardened_clay 9
fill ~259 ~7 ~30 ~259 ~8 ~30 stained_hardened_clay 9
fill ~259 ~7 ~31 ~265 ~7 ~31 stained_hardened_clay 9
fill ~259 ~7 ~33 ~262 ~7 ~33 stained_hardened_clay 9
fill ~260 ~7 ~17 ~262 ~7 ~17 bedrock 0
fill ~260 ~7 ~18 ~260 ~8 ~18 bedrock 0
fill ~260 ~7 ~32 ~260 ~8 ~32 stained_hardened_clay 9
fill ~262 ~7 ~26 ~266 ~7 ~26 stained_hardened_clay 9
fill ~263 ~7 ~32 ~268 ~7 ~32 stained_hardened_clay 9
fill ~264 ~7 ~28 ~264 ~7 ~32 stained_hardened_clay 9
setblock ~265 ~7 ~27 stained_hardened_clay 9
setblock ~265 ~7 ~30 stained_hardened_clay 9
fill ~267 ~7 ~24 ~269 ~7 ~24 bedrock 0
fill ~268 ~7 ~33 ~275 ~7 ~33 stained_hardened_clay 9
fill ~269 ~7 ~23 ~270 ~7 ~23 bedrock 0
fill ~270 ~7 ~32 ~272 ~7 ~32 stained_hardened_clay 9
fill ~270 ~7 ~34 ~274 ~7 ~34 stained_hardened_clay 9
fill ~272 ~7 ~35 ~274 ~7 ~35 stained_hardened_clay 9
fill ~275 ~7 ~34 ~275 ~7 ~36 bedrock 0
fill ~276 ~7 ~35 ~277 ~7 ~35 bedrock 0
setblock ~277 ~7 ~34 bedrock 0
setblock ~277 ~7 ~36 bedrock 0
fill ~213 ~8 ~9 ~213 ~9 ~9 stained_hardened_clay 9
fill ~213 ~8 ~10 ~214 ~8 ~10 stained_hardened_clay 9
fill ~213 ~8 ~11 ~214 ~8 ~11 stained_hardened_clay 9
fill ~213 ~8 ~12 ~217 ~8 ~12 stained_hardened_clay 9
fill ~213 ~8 ~88 ~217 ~8 ~88 stained_hardened_clay 9
fill ~213 ~8 ~89 ~214 ~8 ~89 stained_hardened_clay 9
fill ~213 ~8 ~90 ~214 ~8 ~90 stained_hardened_clay 9
fill ~213 ~8 ~91 ~213 ~9 ~91 stained_hardened_clay 9
fill ~214 ~8 ~9 ~214 ~10 ~9 bedrock 0
fill ~214 ~8 ~13 ~215 ~8 ~13 stained_hardened_clay 9
fill ~214 ~8 ~14 ~217 ~8 ~14 stained_hardened_clay 9
fill ~214 ~8 ~86 ~217 ~8 ~86 stained_hardened_clay 9
fill ~214 ~8 ~87 ~215 ~8 ~87 stained_hardened_clay 9
fill ~214 ~8 ~91 ~214 ~10 ~91 bedrock 0
fill ~215 ~8 ~11 ~215 ~10 ~11 coal_block 0
fill ~215 ~8 ~15 ~217 ~8 ~15 stained_hardened_clay 9
fill ~215 ~8 ~16 ~215 ~9 ~16 stained_hardened_clay 9
fill ~215 ~8 ~84 ~215 ~9 ~84 stained_hardened_clay 9
fill ~215 ~8 ~85 ~217 ~8 ~85 stained_hardened_clay 9
fill ~215 ~8 ~89 ~215 ~10 ~89 coal_block 0
fill ~216 ~8 ~11 ~216 ~10 ~11 stained_hardened_clay 9
fill ~216 ~8 ~13 ~216 ~10 ~13 coal_block 0
fill ~216 ~8 ~87 ~216 ~10 ~87 coal_block 0
fill ~216 ~8 ~89 ~216 ~10 ~89 stained_hardened_clay 9
fill ~217 ~8 ~17 ~218 ~8 ~17 stained_hardened_clay 9
fill ~217 ~8 ~83 ~218 ~8 ~83 stained_hardened_clay 9
fill ~218 ~8 ~14 ~218 ~8 ~15 bedrock 0
fill ~218 ~8 ~18 ~219 ~8 ~18 bedrock 0
fill ~218 ~8 ~82 ~219 ~8 ~82 bedrock 0
fill ~218 ~8 ~85 ~218 ~11 ~85 bedrock 0
fill ~218 ~8 ~86 ~218 ~8 ~85 bedrock 0
fill ~253 ~8 ~25 ~256 ~8 ~25 stone 0
fill ~253 ~8 ~26 ~256 ~8 ~26 stone 0
fill ~253 ~8 ~27 ~256 ~8 ~27 stone 0
fill ~253 ~8 ~28 ~256 ~8 ~28 stone 0
fill ~253 ~8 ~29 ~256 ~8 ~29 stone 0
fill ~253 ~8 ~30 ~257 ~8 ~30 stone 0
fill ~254 ~8 ~23 ~254 ~10 ~23 stone 0
fill ~254 ~8 ~24 ~256 ~8 ~24 stone 0
fill ~254 ~8 ~31 ~254 ~15 ~31 stone 0
fill ~254 ~8 ~32 ~257 ~8 ~32 stone 0
fill ~254 ~8 ~33 ~254 ~8 ~23 stone 0
fill ~255 ~8 ~22 ~255 ~10 ~22 stained_hardened_clay 9
fill ~255 ~8 ~23 ~256 ~8 ~23 stained_hardened_clay 9
setblock ~256 ~8 ~21 stained_hardened_clay 9
fill ~256 ~8 ~22 ~258 ~8 ~22 bedrock 0
fill ~256 ~8 ~31 ~257 ~8 ~31 stone 0
fill ~256 ~8 ~34 ~256 ~6 ~34 stained_hardened_clay 9
fill ~256 ~8 ~35 ~256 ~8 ~34 stained_hardened_clay 9
fill ~257 ~8 ~20 ~259 ~8 ~20 stained_hardened_clay 9
fill ~257 ~8 ~21 ~257 ~10 ~21 bedrock 0
fill ~257 ~8 ~23 ~257 ~10 ~23 bedrock 0
fill ~257 ~8 ~24 ~259 ~8 ~24 stained_hardened_clay 9
fill ~257 ~8 ~25 ~258 ~8 ~25 stained_hardened_clay 9
fill ~257 ~8 ~26 ~259 ~8 ~26 stained_hardened_clay 9
fill ~257 ~8 ~27 ~257 ~14 ~27 stained_hardened_clay 9
fill ~257 ~8 ~28 ~263 ~8 ~28 stained_hardened_clay 9
fill ~257 ~8 ~29 ~263 ~8 ~29 stained_hardened_clay 9
fill ~257 ~8 ~34 ~257 ~9 ~34 bedrock 0
fill ~257 ~8 ~35 ~257 ~8 ~36 bedrock 0
setblock ~258 ~8 ~19 stained_hardened_clay 9
fill ~258 ~8 ~21 ~260 ~8 ~21 stained_hardened_clay 9
fill ~258 ~8 ~23 ~262 ~8 ~23 stained_hardened_clay 9
fill ~258 ~8 ~30 ~258 ~8 ~33 stained_hardened_clay 9
fill ~259 ~8 ~18 ~259 ~8 ~19 bedrock 0
fill ~259 ~8 ~22 ~261 ~8 ~22 stained_hardened_clay 9
fill ~259 ~8 ~25 ~261 ~8 ~25 bedrock 0
fill ~259 ~8 ~27 ~264 ~8 ~27 stained_hardened_clay 9
fill ~259 ~8 ~31 ~268 ~8 ~31 stained_hardened_clay 9
fill ~259 ~8 ~32 ~259 ~9 ~32 stained_hardened_clay 9
fill ~259 ~8 ~33 ~259 ~7 ~33 stained_hardened_clay 9
fill ~260 ~8 ~24 ~260 ~10 ~24 bedrock 0
fill ~260 ~8 ~26 ~260 ~10 ~26 bedrock 0
fill ~260 ~8 ~30 ~264 ~8 ~30 stained_hardened_clay 9
fill ~261 ~8 ~24 ~263 ~8 ~24 stained_hardened_clay 9
fill ~261 ~8 ~26 ~264 ~8 ~26 stained_hardened_clay 9
fill ~261 ~8 ~32 ~270 ~8 ~32 stained_hardened_clay 9
fill ~262 ~8 ~25 ~263 ~8 ~25 stained_hardened_clay 9
fill ~263 ~8 ~33 ~272 ~8 ~33 stained_hardened_clay 9
fill ~264 ~8 ~24 ~267 ~8 ~24 bedrock 0
fill ~264 ~8 ~25 ~264 ~9 ~25 bedrock 0
setblock ~265 ~8 ~25 stained_hardened_clay 9
fill ~268 ~8 ~34 ~270 ~8 ~34 stained_hardened_clay 9
fill ~272 ~8 ~34 ~274 ~8 ~34 bedrock 0
fill ~274 ~8 ~35 ~277 ~8 ~35 bedrock 0
setblock ~275 ~8 ~34 stained_hardened_clay 9
fill ~213 ~9 ~10 ~214 ~9 ~10 stained_hardened_clay 9
fill ~213 ~9 ~11 ~213 ~8 ~11 stained_hardened_clay 9
fill ~213 ~9 ~12 ~217 ~9 ~12 stained_hardened_clay 9
fill ~213 ~9 ~13 ~215 ~9 ~13 stained_hardened_clay 9
fill ~213 ~9 ~14 ~217 ~9 ~14 stained_hardened_clay 9
fill ~213 ~9 ~86 ~217 ~9 ~86 stained_hardened_clay 9
fill ~213 ~9 ~87 ~215 ~9 ~87 stained_hardened_clay 9
fill ~213 ~9 ~88 ~217 ~9 ~88 stained_hardened_clay 9
fill ~213 ~9 ~89 ~213 ~8 ~89 stained_hardened_clay 9
fill ~213 ~9 ~90 ~214 ~9 ~90 stained_hardened_clay 9
fill ~214 ~9 ~11 ~214 ~10 ~11 coal_block 0
fill ~214 ~9 ~15 ~217 ~9 ~15 stained_hardened_clay 9
fill ~214 ~9 ~85 ~217 ~9 ~85 stained_hardened_clay 9
fill ~214 ~9 ~89 ~214 ~10 ~89 coal_block 0
fill ~215 ~9 ~17 ~218 ~9 ~17 stained_hardened_clay 9
fill ~215 ~9 ~83 ~218 ~9 ~83 stained_hardened_clay 9
fill ~216 ~9 ~16 ~216 ~11 ~16 coal_block 0
fill ~216 ~9 ~18 ~217 ~9 ~18 stained_hardened_clay 9
fill ~216 ~9 ~82 ~217 ~9 ~82 stained_hardened_clay 9
fill ~216 ~9 ~84 ~216 ~11 ~84 coal_block 0
fill ~217 ~9 ~11 ~217 ~11 ~11 bedrock 0
fill ~217 ~9 ~89 ~217 ~11 ~89 bedrock 0
fill ~218 ~9 ~15 ~218 ~11 ~15 bedrock 0
fill ~218 ~9 ~18 ~218 ~11 ~18 bedrock 0
fill ~218 ~9 ~82 ~218 ~11 ~82 bedrock 0
fill ~252 ~9 ~25 ~252 ~14 ~25 bedrock 0
fill ~252 ~9 ~26 ~252 ~14 ~26 bedrock 0
fill ~252 ~9 ~27 ~252 ~14 ~27 bedrock 0
fill ~252 ~9 ~28 ~252 ~19 ~28 bedrock 0
fill ~253 ~9 ~24 ~255 ~9 ~24 stone 0
fill ~253 ~9 ~25 ~255 ~9 ~25 stone 0
fill ~253 ~9 ~26 ~255 ~9 ~26 stone 0
fill ~253 ~9 ~27 ~255 ~9 ~27 stone 0
fill ~253 ~9 ~28 ~254 ~9 ~28 stone 0
fill ~253 ~9 ~29 ~253 ~12 ~29 bedrock 0
fill ~253 ~9 ~30 ~255 ~9 ~30 stone 0
fill ~253 ~9 ~31 ~253 ~10 ~31 stone 0
fill ~254 ~9 ~29 ~255 ~9 ~29 stone 0
fill ~254 ~9 ~32 ~255 ~9 ~32 stone 0
fill ~255 ~9 ~23 ~255 ~10 ~23 stained_hardened_clay 9
fill ~255 ~9 ~28 ~261 ~9 ~28 stained_hardened_clay 9
fill ~255 ~9 ~31 ~257 ~9 ~31 bedrock 0
fill ~256 ~9 ~21 ~256 ~9 ~23 bedrock 0
fill ~256 ~9 ~24 ~257 ~9 ~24 stained_hardened_clay 9
fill ~256 ~9 ~25 ~258 ~9 ~25 stained_hardened_clay 9
fill ~256 ~9 ~26 ~258 ~9 ~26 stained_hardened_clay 9
fill ~256 ~9 ~29 ~258 ~9 ~29 stained_hardened_clay 9
fill ~256 ~9 ~30 ~256 ~20 ~30 bedrock 0
fill ~256 ~9 ~32 ~256 ~11 ~32 bedrock 0
fill ~256 ~9 ~33 ~256 ~9 ~34 bedrock 0
fill ~257 ~9 ~20 ~257 ~7 ~20 stained_hardened_clay 9
fill ~257 ~9 ~22 ~258 ~9 ~22 bedrock 0
setblock ~257 ~9 ~30 stone 0
setblock ~257 ~9 ~32 stone 0
fill ~258 ~9 ~19 ~259 ~9 ~19 bedrock 0
fill ~258 ~9 ~20 ~258 ~9 ~24 bedrock 0
fill ~258 ~9 ~27 ~262 ~9 ~27 stained_hardened_clay 9
fill ~258 ~9 ~30 ~260 ~9 ~30 bedrock 0
fill ~258 ~9 ~31 ~258 ~9 ~32 stained_hardened_clay 9
fill ~259 ~9 ~22 ~259 ~7 ~22 stained_hardened_clay 9
fill ~259 ~9 ~23 ~260 ~9 ~23 stained_hardened_clay 9
fill ~259 ~9 ~24 ~259 ~9 ~26 bedrock 0
fill ~259 ~9 ~29 ~259 ~11 ~29 bedrock 0
fill ~259 ~9 ~31 ~259 ~11 ~31 bedrock 0
fill ~260 ~9 ~25 ~264 ~9 ~25 bedrock 0
fill ~260 ~9 ~29 ~261 ~9 ~29 stained_hardened_clay 9
fill ~260 ~9 ~31 ~263 ~9 ~31 stained_hardened_clay 9
setblock ~261 ~9 ~24 bedrock 0
setblock ~261 ~9 ~26 bedrock 0
fill ~261 ~9 ~30 ~262 ~9 ~30 stained_hardened_clay 9
fill ~262 ~9 ~26 ~263 ~9 ~26 stained_hardened_clay 9
fill ~263 ~9 ~32 ~264 ~9 ~32 stained_hardened_clay 9
fill ~265 ~9 ~32 ~267 ~9 ~32 bedrock 0
fill ~267 ~9 ~33 ~270 ~9 ~33 bedrock 0
setblock ~268 ~9 ~32 stained_hardened_clay 9
fill ~270 ~9 ~34 ~272 ~9 ~34 bedrock 0
fill ~212 ~10 ~10 ~214 ~10 ~10 stained_hardened_clay 9
fill ~212 ~10 ~11 ~212 ~13 ~11 stained_hardened_clay 9
fill ~212 ~10 ~89 ~212 ~13 ~89 stained_hardened_clay 9
fill ~212 ~10 ~90 ~214 ~10 ~90 stained_hardened_clay 9
fill ~213 ~10 ~9 ~213 ~11 ~9 bedrock 0
fill ~213 ~10 ~11 ~213 ~11 ~11 coal_block 0
fill ~213 ~10 ~12 ~214 ~10 ~12 stained_hardened_clay 9
fill ~213 ~10 ~13 ~215 ~10 ~13 stained_hardened_clay 9
fill ~213 ~10 ~14 ~214 ~10 ~14 stained_hardened_clay 9
fill ~213 ~10 ~15 ~214 ~10 ~15 stained_hardened_clay 9
fill ~213 ~10 ~16 ~214 ~10 ~16 stained_hardened_clay 9
fill ~213 ~10 ~84 ~214 ~10 ~84 stained_hardened_clay 9
fill ~213 ~10 ~85 ~214 ~10 ~85 stained_hardened_clay 9
fill ~213 ~10 ~86 ~214 ~10 ~86 stained_hardened_clay 9
fill ~213 ~10 ~87 ~215 ~10 ~87 stained_hardened_clay 9
fill ~213 ~10 ~88 ~214 ~10 ~88 stained_hardened_clay 9
fill ~213 ~10 ~89 ~213 ~11 ~89 coal_block 0
fill ~213 ~10 ~91 ~213 ~11 ~91 bedrock 0
fill ~214 ~10 ~17 ~217 ~10 ~17 stained_hardened_clay 9
fill ~214 ~10 ~83 ~217 ~10 ~83 stained_hardened_clay 9
setblock ~215 ~10 ~12 coal_block 0
fill ~215 ~10 ~18 ~217 ~10 ~18 stained_hardened_clay 9
fill ~215 ~10 ~82 ~217 ~10 ~82 stained_hardened_clay 9
setblock ~215 ~10 ~88 coal_block 0
fill ~216 ~10 ~12 ~217 ~10 ~12 stained_hardened_clay 9
fill ~216 ~10 ~14 ~216 ~11 ~14 coal_block 0
fill ~216 ~10 ~86 ~216 ~11 ~86 coal_block 0
fill ~216 ~10 ~88 ~217 ~10 ~88 stained_hardened_clay 9
fill ~217 ~10 ~14 ~217 ~12 ~14 stained_hardened_clay 9
fill ~217 ~10 ~15 ~217 ~10 ~14 stained_hardened_clay 9
fill ~217 ~10 ~85 ~217 ~10 ~86 stained_hardened_clay 9
fill ~251 ~10 ~25 ~251 ~15 ~25 bedrock 0
fill ~251 ~10 ~26 ~251 ~24 ~26 bedrock 0
fill ~251 ~10 ~27 ~251 ~26 ~27 bedrock 0
fill ~252 ~10 ~24 ~255 ~10 ~24 stone 0
fill ~252 ~10 ~29 ~252 ~15 ~29 bedrock 0
fill ~253 ~10 ~25 ~255 ~10 ~25 stone 0
fill ~253 ~10 ~26 ~254 ~10 ~26 stone 0
fill ~253 ~10 ~27 ~254 ~10 ~27 stone 0
fill ~253 ~10 ~28 ~254 ~10 ~28 stained_hardened_clay 0
fill ~253 ~10 ~30 ~254 ~10 ~30 stone 0
setblock ~254 ~10 ~29 stained_hardened_clay 0
fill ~254 ~10 ~32 ~254 ~8 ~32 stone 0
fill ~255 ~10 ~26 ~259 ~10 ~26 stained_hardened_clay 9
fill ~255 ~10 ~27 ~259 ~10 ~27 stained_hardened_clay 9
fill ~255 ~10 ~28 ~257 ~10 ~28 stained_hardened_clay 9
fill ~255 ~10 ~29 ~257 ~10 ~29 stained_hardened_clay 9
fill ~255 ~10 ~30 ~255 ~10 ~32 bedrock 0
fill ~256 ~10 ~22 ~258 ~10 ~22 bedrock 0
fill ~256 ~10 ~23 ~256 ~10 ~29 stained_hardened_clay 9
fill ~256 ~10 ~31 ~263 ~10 ~31 bedrock 0
fill ~257 ~10 ~24 ~257 ~10 ~29 stained_hardened_clay 9
fill ~257 ~10 ~30 ~260 ~10 ~30 bedrock 0
setblock ~257 ~10 ~32 bedrock 0
fill ~258 ~10 ~24 ~258 ~13 ~24 bedrock 0
fill ~258 ~10 ~25 ~261 ~10 ~25 bedrock 0
setblock ~258 ~10 ~29 bedrock 0
fill ~259 ~10 ~28 ~259 ~11 ~28 stained_hardened_clay 9
setblock ~260 ~10 ~29 bedrock 0
fill ~263 ~10 ~32 ~265 ~10 ~32 bedrock 0
fill ~212 ~11 ~10 ~212 ~12 ~10 stained_hardened_clay 9
fill ~212 ~11 ~12 ~212 ~13 ~12 stained_hardened_clay 9
fill ~212 ~11 ~13 ~216 ~11 ~13 stained_hardened_clay 9
fill ~212 ~11 ~87 ~216 ~11 ~87 stained_hardened_clay 9
fill ~212 ~11 ~88 ~212 ~13 ~88 stained_hardened_clay 9
fill ~212 ~11 ~90 ~212 ~12 ~90 stained_hardened_clay 9
fill ~213 ~11 ~10 ~213 ~13 ~10 bedrock 0
fill ~213 ~11 ~12 ~214 ~11 ~12 coal_block 0
fill ~213 ~11 ~14 ~214 ~11 ~14 stained_hardened_clay 9
fill ~213 ~11 ~15 ~214 ~11 ~15 stained_hardened_clay 9
fill ~213 ~11 ~16 ~213 ~14 ~16 stained_hardened_clay 9
fill ~213 ~11 ~84 ~213 ~14 ~84 stained_hardened_clay 9
fill ~213 ~11 ~85 ~214 ~11 ~85 stained_hardened_clay 9
fill ~213 ~11 ~86 ~214 ~11 ~86 stained_hardened_clay 9
fill ~213 ~11 ~88 ~214 ~11 ~88 coal_block 0
fill ~213 ~11 ~90 ~213 ~13 ~90 bedrock 0
fill ~214 ~11 ~17 ~214 ~12 ~17 stained_hardened_clay 9
fill ~214 ~11 ~83 ~214 ~12 ~83 stained_hardened_clay 9
fill ~215 ~11 ~12 ~216 ~11 ~12 stained_hardened_clay 9
fill ~215 ~11 ~16 ~215 ~12 ~16 coal_block 0
fill ~215 ~11 ~17 ~215 ~14 ~17 coal_block 0
fill ~215 ~11 ~18 ~216 ~11 ~18 stained_hardened_clay 9
fill ~215 ~11 ~82 ~216 ~11 ~82 stained_hardened_clay 9
fill ~215 ~11 ~83 ~215 ~14 ~83 coal_block 0
fill ~215 ~11 ~84 ~215 ~12 ~84 coal_block 0
fill ~215 ~11 ~88 ~216 ~11 ~88 stained_hardened_clay 9
fill ~216 ~11 ~15 ~216 ~14 ~15 stained_hardened_clay 9
fill ~216 ~11 ~17 ~217 ~11 ~17 stained_hardened_clay 9
fill ~216 ~11 ~83 ~217 ~11 ~83 stained_hardened_clay 9
fill ~216 ~11 ~85 ~216 ~14 ~85 stained_hardened_clay 9
fill ~217 ~11 ~12 ~217 ~12 ~12 bedrock 0
fill ~217 ~11 ~15 ~217 ~13 ~15 bedrock 0
fill ~217 ~11 ~18 ~217 ~13 ~18 bedrock 0
fill ~217 ~11 ~82 ~217 ~13 ~82 bedrock 0
fill ~217 ~11 ~85 ~217 ~13 ~85 bedrock 0
fill ~217 ~11 ~86 ~217 ~12 ~86 stained_hardened_clay 9
fill ~217 ~11 ~88 ~217 ~12 ~88 bedrock 0
fill ~250 ~11 ~26 ~250 ~25 ~26 bedrock 0
fill ~250 ~11 ~27 ~250 ~29 ~27 bedrock 0
fill ~251 ~11 ~28 ~251 ~13 ~28 stone 0
fill ~252 ~11 ~24 ~255 ~11 ~24 stone 0
fill ~252 ~11 ~30 ~252 ~12 ~30 stone 0
fill ~253 ~11 ~25 ~255 ~11 ~25 stone 0
fill ~253 ~11 ~26 ~254 ~11 ~26 stone 0
fill ~253 ~11 ~27 ~254 ~11 ~27 stone 0
fill ~253 ~11 ~28 ~253 ~10 ~28 stained_hardened_clay 0
fill ~253 ~11 ~30 ~255 ~11 ~30 stained_hardened_clay 9
fill ~254 ~11 ~28 ~259 ~11 ~28 stained_hardened_clay 9
fill ~254 ~11 ~29 ~258 ~11 ~29 stained_hardened_clay 9
fill ~255 ~11 ~23 ~256 ~11 ~23 bedrock 0
fill ~255 ~11 ~26 ~259 ~11 ~26 stained_hardened_clay 9
fill ~255 ~11 ~27 ~258 ~11 ~27 stained_hardened_clay 9
fill ~255 ~11 ~31 ~257 ~11 ~31 bedrock 0
setblock ~255 ~11 ~32 stone 0
fill ~256 ~11 ~24 ~256 ~11 ~29 stained_hardened_clay 9
fill ~257 ~11 ~24 ~257 ~23 ~24 bedrock 0
fill ~257 ~11 ~25 ~257 ~13 ~25 stained_hardened_clay 9
setblock ~257 ~11 ~30 stained_hardened_clay 9
fill ~258 ~11 ~25 ~258 ~14 ~25 bedrock 0
fill ~258 ~11 ~30 ~260 ~11 ~30 bedrock 0
setblock ~258 ~11 ~31 stone 0
fill ~212 ~12 ~13 ~216 ~12 ~13 stained_hardened_clay 9
fill ~212 ~12 ~14 ~213 ~12 ~14 stained_hardened_clay 9
fill ~212 ~12 ~15 ~213 ~12 ~15 stained_hardened_clay 9
fill ~212 ~12 ~85 ~213 ~12 ~85 stained_hardened_clay 9
fill ~212 ~12 ~86 ~213 ~12 ~86 stained_hardened_clay 9
fill ~212 ~12 ~87 ~216 ~12 ~87 stained_hardened_clay 9
fill ~213 ~12 ~11 ~213 ~13 ~11 stained_hardened_clay 9
fill ~213 ~12 ~12 ~214 ~12 ~12 coal_block 0
fill ~213 ~12 ~88 ~214 ~12 ~88 coal_block 0
fill ~213 ~12 ~89 ~213 ~13 ~89 stained_hardened_clay 9
fill ~214 ~12 ~18 ~216 ~12 ~18 stained_hardened_clay 9
fill ~214 ~12 ~82 ~216 ~12 ~82 stained_hardened_clay 9
fill ~215 ~12 ~12 ~215 ~14 ~12 stained_hardened_clay 9
fill ~215 ~12 ~14 ~215 ~14 ~14 coal_block 0
fill ~215 ~12 ~86 ~215 ~14 ~86 coal_block 0
fill ~215 ~12 ~88 ~215 ~14 ~88 stained_hardened_clay 9
fill ~216 ~12 ~12 ~216 ~15 ~12 bedrock 0
fill ~216 ~12 ~17 ~216 ~9 ~17 stained_hardened_clay 9
setblock ~216 ~12 ~19 stained_hardened_clay 9
setblock ~216 ~12 ~81 stained_hardened_clay 9
fill ~216 ~12 ~83 ~216 ~9 ~83 stained_hardened_clay 9
fill ~216 ~12 ~88 ~216 ~15 ~88 bedrock 0
fill ~251 ~12 ~29 ~251 ~20 ~29 stone 0
fill ~252 ~12 ~24 ~256 ~12 ~24 stone 0
fill ~253 ~12 ~25 ~255 ~12 ~25 stone 0
fill ~253 ~12 ~26 ~254 ~12 ~26 stone 0
fill ~253 ~12 ~27 ~254 ~12 ~27 stone 0
fill ~253 ~12 ~28 ~257 ~12 ~28 stained_hardened_clay 9
fill ~253 ~12 ~30 ~255 ~12 ~30 stained_hardened_clay 9
fill ~254 ~12 ~29 ~256 ~12 ~29 stained_hardened_clay 9
fill ~255 ~12 ~23 ~256 ~12 ~23 bedrock 0
fill ~255 ~12 ~26 ~258 ~12 ~26 stained_hardened_clay 9
fill ~255 ~12 ~27 ~258 ~12 ~27 stained_hardened_clay 9
fill ~255 ~12 ~31 ~256 ~12 ~31 bedrock 0
fill ~256 ~12 ~25 ~256 ~13 ~25 stained_hardened_clay 9
fill ~257 ~12 ~29 ~258 ~12 ~29 bedrock 0
fill ~257 ~12 ~30 ~257 ~12 ~29 bedrock 0
fill ~258 ~12 ~28 ~259 ~12 ~28 bedrock 0
fill ~211 ~13 ~11 ~211 ~14 ~11 stained_hardened_clay 9
fill ~211 ~13 ~89 ~211 ~14 ~89 stained_hardened_clay 9
fill ~212 ~13 ~10 ~212 ~14 ~10 bedrock 0
fill ~212 ~13 ~13 ~213 ~13 ~13 stained_hardened_clay 9
fill ~212 ~13 ~14 ~213 ~13 ~14 stained_hardened_clay 9
fill ~212 ~13 ~15 ~213 ~13 ~15 stained_hardened_clay 9
fill ~212 ~13 ~16 ~212 ~16 ~16 stained_hardened_clay 9
fill ~212 ~13 ~84 ~212 ~16 ~84 stained_hardened_clay 9
fill ~212 ~13 ~85 ~213 ~13 ~85 stained_hardened_clay 9
fill ~212 ~13 ~86 ~213 ~13 ~86 stained_hardened_clay 9
fill ~212 ~13 ~87 ~213 ~13 ~87 stained_hardened_clay 9
fill ~212 ~13 ~90 ~212 ~14 ~90 bedrock 0
fill ~213 ~13 ~12 ~214 ~13 ~12 coal_block 0
fill ~213 ~13 ~17 ~213 ~14 ~17 stained_hardened_clay 9
fill ~213 ~13 ~83 ~213 ~14 ~83 stained_hardened_clay 9
fill ~213 ~13 ~88 ~214 ~13 ~88 coal_block 0
fill ~214 ~13 ~18 ~215 ~13 ~18 stained_hardened_clay 9
fill ~214 ~13 ~82 ~215 ~13 ~82 stained_hardened_clay 9
fill ~215 ~13 ~13 ~216 ~13 ~13 stained_hardened_clay 9
fill ~215 ~13 ~87 ~216 ~13 ~87 stained_hardened_clay 9
setblock ~216 ~13 ~16 stained_hardened_clay 9
fill ~216 ~13 ~18 ~216 ~13 ~19 bedrock 0
fill ~216 ~13 ~81 ~216 ~15 ~81 bedrock 0
fill ~216 ~13 ~82 ~216 ~13 ~81 bedrock 0
setblock ~216 ~13 ~84 stained_hardened_clay 9
fill ~217 ~13 ~16 ~217 ~14 ~16 bedrock 0
fill ~217 ~13 ~84 ~217 ~14 ~84 bedrock 0
fill ~250 ~13 ~28 ~250 ~20 ~28 stone 0
fill ~251 ~13 ~30 ~251 ~18 ~30 stone 0
fill ~252 ~13 ~24 ~256 ~13 ~24 stone 0
fill ~252 ~13 ~30 ~255 ~13 ~30 stained_hardened_clay 9
fill ~253 ~13 ~25 ~255 ~13 ~25 stone 0
fill ~253 ~13 ~26 ~255 ~13 ~26 stone 0
fill ~253 ~13 ~27 ~253 ~21 ~27 stone 0
fill ~253 ~13 ~28 ~257 ~13 ~28 stained_hardened_clay 9
fill ~253 ~13 ~29 ~256 ~13 ~29 stained_hardened_clay 9
fill ~254 ~13 ~27 ~258 ~13 ~27 stained_hardened_clay 9
fill ~255 ~13 ~23 ~256 ~13 ~23 bedrock 0
fill ~255 ~13 ~31 ~255 ~15 ~31 bedrock 0
fill ~256 ~13 ~26 ~258 ~13 ~26 stained_hardened_clay 9
fill ~257 ~13 ~29 ~257 ~23 ~29 bedrock 0
fill ~258 ~13 ~28 ~258 ~18 ~28 bedrock 0
fill ~211 ~14 ~12 ~211 ~16 ~12 stained_hardened_clay 9
fill ~211 ~14 ~13 ~211 ~16 ~13 stained_hardened_clay 9
fill ~211 ~14 ~16 ~211 ~19 ~16 stained_hardened_clay 9
fill ~211 ~14 ~84 ~211 ~19 ~84 stained_hardened_clay 9
fill ~211 ~14 ~87 ~211 ~16 ~87 stained_hardened_clay 9
fill ~211 ~14 ~88 ~211 ~16 ~88 stained_hardened_clay 9
fill ~212 ~14 ~11 ~212 ~15 ~11 bedrock 0
fill ~212 ~14 ~12 ~213 ~14 ~12 coal_block 0
fill ~212 ~14 ~13 ~213 ~14 ~13 coal_block 0
fill ~212 ~14 ~14 ~212 ~15 ~14 stained_hardened_clay 9
fill ~212 ~14 ~15 ~213 ~14 ~15 stained_hardened_clay 9
fill ~212 ~14 ~17 ~212 ~17 ~17 stained_hardened_clay 9
fill ~212 ~14 ~83 ~212 ~17 ~83 stained_hardened_clay 9
fill ~212 ~14 ~85 ~213 ~14 ~85 stained_hardened_clay 9
fill ~212 ~14 ~86 ~212 ~15 ~86 stained_hardened_clay 9
fill ~212 ~14 ~87 ~213 ~14 ~87 coal_block 0
fill ~212 ~14 ~88 ~213 ~14 ~88 coal_block 0
fill ~212 ~14 ~89 ~212 ~15 ~89 bedrock 0
fill ~214 ~14 ~12 ~214 ~15 ~12 stained_hardened_clay 9
fill ~214 ~14 ~13 ~215 ~14 ~13 stained_hardened_clay 9
fill ~214 ~14 ~14 ~214 ~15 ~14 coal_block 0
fill ~214 ~14 ~17 ~214 ~17 ~17 coal_block 0
fill ~214 ~14 ~18 ~215 ~14 ~18 stained_hardened_clay 9
fill ~214 ~14 ~82 ~215 ~14 ~82 stained_hardened_clay 9
fill ~214 ~14 ~83 ~214 ~17 ~83 coal_block 0
fill ~214 ~14 ~86 ~214 ~15 ~86 coal_block 0
fill ~214 ~14 ~87 ~215 ~14 ~87 stained_hardened_clay 9
fill ~214 ~14 ~88 ~214 ~15 ~88 stained_hardened_clay 9
setblock ~215 ~14 ~19 stained_hardened_clay 9
setblock ~215 ~14 ~81 stained_hardened_clay 9
fill ~216 ~14 ~16 ~216 ~17 ~16 bedrock 0
fill ~216 ~14 ~19 ~216 ~15 ~19 bedrock 0
fill ~216 ~14 ~84 ~216 ~17 ~84 bedrock 0
fill ~249 ~14 ~26 ~249 ~21 ~26 bedrock 0
fill ~250 ~14 ~25 ~250 ~18 ~25 bedrock 0
fill ~250 ~14 ~29 ~250 ~20 ~29 stone 0
fill ~251 ~14 ~28 ~251 ~24 ~28 bedrock 0
fill ~252 ~14 ~24 ~256 ~14 ~24 stone 0
fill ~252 ~14 ~30 ~255 ~14 ~30 stained_hardened_clay 9
fill ~253 ~14 ~25 ~256 ~14 ~25 stone 0
fill ~253 ~14 ~26 ~256 ~14 ~26 stone 0
fill ~253 ~14 ~28 ~257 ~14 ~28 stained_hardened_clay 9
fill ~253 ~14 ~29 ~256 ~14 ~29 stained_hardened_clay 9
fill ~254 ~14 ~27 ~258 ~14 ~27 stained_hardened_clay 9
fill ~255 ~14 ~23 ~256 ~14 ~23 bedrock 0
fill ~257 ~14 ~25 ~257 ~18 ~25 bedrock 0
setblock ~257 ~14 ~26 stained_hardened_clay 9
fill ~210 ~15 ~12 ~210 ~17 ~12 stained_hardened_clay 9
fill ~210 ~15 ~88 ~210 ~17 ~88 stained_hardened_clay 9
fill ~211 ~15 ~11 ~211 ~17 ~11 bedrock 0
fill ~211 ~15 ~14 ~211 ~17 ~14 stained_hardened_clay 9
fill ~211 ~15 ~15 ~212 ~15 ~15 stained_hardened_clay 9
fill ~211 ~15 ~85 ~212 ~15 ~85 stained_hardened_clay 9
fill ~211 ~15 ~86 ~211 ~17 ~86 stained_hardened_clay 9
fill ~211 ~15 ~89 ~211 ~17 ~89 bedrock 0
setblock ~212 ~15 ~12 stained_hardened_clay 9
fill ~212 ~15 ~18 ~215 ~15 ~18 stained_hardened_clay 9
fill ~212 ~15 ~82 ~215 ~15 ~82 stained_hardened_clay 9
setblock ~212 ~15 ~88 stained_hardened_clay 9
fill ~213 ~15 ~13 ~213 ~16 ~13 coal_block 0
fill ~213 ~15 ~87 ~213 ~16 ~87 coal_block 0
fill ~214 ~15 ~13 ~214 ~17 ~13 stained_hardened_clay 9
fill ~214 ~15 ~87 ~214 ~17 ~87 stained_hardened_clay 9
fill ~215 ~15 ~13 ~216 ~15 ~13 bedrock 0
fill ~215 ~15 ~15 ~215 ~17 ~15 stained_hardened_clay 9
fill ~215 ~15 ~16 ~215 ~16 ~16 stained_hardened_clay 9
fill ~215 ~15 ~19 ~215 ~17 ~19 bedrock 0
fill ~215 ~15 ~81 ~215 ~17 ~81 bedrock 0
fill ~215 ~15 ~84 ~215 ~16 ~84 stained_hardened_clay 9
fill ~215 ~15 ~85 ~215 ~17 ~85 stained_hardened_clay 9
fill ~215 ~15 ~87 ~216 ~15 ~87 bedrock 0
fill ~249 ~15 ~27 ~249 ~22 ~27 bedrock 0
fill ~252 ~15 ~24 ~256 ~15 ~24 stone 0
fill ~252 ~15 ~25 ~256 ~15 ~25 stone 0
fill ~252 ~15 ~26 ~257 ~15 ~26 stone 0
fill ~252 ~15 ~27 ~252 ~21 ~27 stone 0
fill ~252 ~15 ~30 ~254 ~15 ~30 stained_hardened_clay 9
fill ~253 ~15 ~28 ~257 ~15 ~28 stained_hardened_clay 9
fill ~253 ~15 ~29 ~256 ~15 ~29 stained_hardened_clay 9
fill ~254 ~15 ~27 ~256 ~15 ~27 stained_hardened_clay 9
fill ~255 ~15 ~23 ~256 ~15 ~23 bedrock 0
setblock ~255 ~15 ~30 bedrock 0
fill ~257 ~15 ~27 ~258 ~15 ~27 stone 0
fill ~211 ~16 ~15 ~212 ~16 ~15 stained_hardened_clay 9
fill ~211 ~16 ~17 ~211 ~20 ~17 stained_hardened_clay 9
fill ~211 ~16 ~83 ~211 ~20 ~83 stained_hardened_clay 9
fill ~211 ~16 ~85 ~212 ~16 ~85 stained_hardened_clay 9
fill ~212 ~16 ~13 ~212 ~17 ~13 coal_block 0
fill ~212 ~16 ~18 ~212 ~19 ~18 stained_hardened_clay 9
fill ~212 ~16 ~82 ~212 ~19 ~82 stained_hardened_clay 9
fill ~212 ~16 ~87 ~212 ~17 ~87 coal_block 0
fill ~213 ~16 ~18 ~213 ~20 ~18 coal_block 0
fill ~213 ~16 ~19 ~214 ~16 ~19 stained_hardened_clay 9
fill ~213 ~16 ~81 ~214 ~16 ~81 stained_hardened_clay 9
fill ~213 ~16 ~82 ~213 ~20 ~82 coal_block 0
fill ~214 ~16 ~14 ~214 ~18 ~14 stained_hardened_clay 9
fill ~214 ~16 ~18 ~215 ~16 ~18 stained_hardened_clay 9
fill ~214 ~16 ~82 ~215 ~16 ~82 stained_hardened_clay 9
fill ~214 ~16 ~86 ~214 ~18 ~86 stained_hardened_clay 9
fill ~215 ~16 ~13 ~215 ~18 ~13 bedrock 0
fill ~215 ~16 ~87 ~215 ~18 ~87 bedrock 0
fill ~249 ~16 ~28 ~249 ~19 ~28 stone 0
fill ~251 ~16 ~25 ~256 ~16 ~25 stone 0
fill ~252 ~16 ~24 ~256 ~16 ~24 stone 0
fill ~252 ~16 ~26 ~257 ~16 ~26 stone 0
fill ~252 ~16 ~29 ~256 ~16 ~29 stained_hardened_clay 9
fill ~252 ~16 ~30 ~255 ~16 ~30 stained_hardened_clay 9
fill ~253 ~16 ~28 ~257 ~16 ~28 stained_hardened_clay 9
fill ~254 ~16 ~27 ~256 ~16 ~27 stained_hardened_clay 9
fill ~255 ~16 ~23 ~256 ~16 ~23 bedrock 0
setblock ~255 ~16 ~31 stone 0
fill ~257 ~16 ~27 ~258 ~16 ~27 stone 0
fill ~210 ~17 ~13 ~210 ~21 ~13 stained_hardened_clay 9
fill ~210 ~17 ~14 ~210 ~19 ~14 stained_hardened_clay 9
fill ~210 ~17 ~15 ~212 ~17 ~15 stained_hardened_clay 9
fill ~210 ~17 ~16 ~210 ~25 ~16 stained_hardened_clay 9
fill ~210 ~17 ~84 ~210 ~25 ~84 stained_hardened_clay 9
fill ~210 ~17 ~85 ~212 ~17 ~85 stained_hardened_clay 9
fill ~210 ~17 ~86 ~210 ~19 ~86 stained_hardened_clay 9
fill ~210 ~17 ~87 ~210 ~21 ~87 stained_hardened_clay 9
fill ~211 ~17 ~12 ~211 ~18 ~12 bedrock 0
setblock ~211 ~17 ~13 coal_block 0
setblock ~211 ~17 ~87 coal_block 0
fill ~211 ~17 ~88 ~211 ~18 ~88 bedrock 0
fill ~212 ~17 ~14 ~213 ~17 ~14 coal_block 0
fill ~212 ~17 ~86 ~213 ~17 ~86 coal_block 0
fill ~213 ~17 ~13 ~213 ~19 ~13 stained_hardened_clay 9
fill ~213 ~17 ~19 ~213 ~20 ~19 stained_hardened_clay 9
fill ~213 ~17 ~81 ~213 ~20 ~81 stained_hardened_clay 9
fill ~213 ~17 ~87 ~213 ~19 ~87 stained_hardened_clay 9
fill ~214 ~17 ~15 ~214 ~18 ~15 coal_block 0
fill ~214 ~17 ~19 ~214 ~18 ~19 bedrock 0
setblock ~214 ~17 ~20 stained_hardened_clay 9
setblock ~214 ~17 ~80 stained_hardened_clay 9
fill ~214 ~17 ~81 ~214 ~18 ~81 bedrock 0
fill ~214 ~17 ~85 ~214 ~18 ~85 coal_block 0
fill ~215 ~17 ~16 ~215 ~17 ~17 bedrock 0
fill ~215 ~17 ~83 ~215 ~20 ~83 bedrock 0
fill ~215 ~17 ~84 ~215 ~17 ~83 bedrock 0
fill ~251 ~17 ~25 ~256 ~17 ~25 stone 0
fill ~252 ~17 ~24 ~256 ~17 ~24 stone 0
fill ~252 ~17 ~26 ~257 ~17 ~26 stone 0
fill ~252 ~17 ~29 ~256 ~17 ~29 stained_hardened_clay 9
fill ~252 ~17 ~30 ~255 ~17 ~30 stained_hardened_clay 9
fill ~253 ~17 ~28 ~257 ~17 ~28 stained_hardened_clay 9
fill ~254 ~17 ~27 ~256 ~17 ~27 stained_hardened_clay 9
fill ~255 ~17 ~23 ~256 ~17 ~23 bedrock 0
fill ~257 ~17 ~27 ~258 ~17 ~27 stone 0
fill ~209 ~18 ~12 ~209 ~19 ~12 stained_hardened_clay 9
fill ~209 ~18 ~13 ~209 ~20 ~13 stained_hardened_clay 9
fill ~209 ~18 ~14 ~209 ~23 ~14 stained_hardened_clay 9
fill ~209 ~18 ~15 ~211 ~18 ~15 stained_hardened_clay 9
fill ~209 ~18 ~85 ~211 ~18 ~85 stained_hardened_clay 9
fill ~209 ~18 ~86 ~209 ~23 ~86 stained_hardened_clay 9
fill ~209 ~18 ~87 ~209 ~20 ~87 stained_hardened_clay 9
fill ~209 ~18 ~88 ~209 ~19 ~88 stained_hardened_clay 9
fill ~210 ~18 ~12 ~210 ~20 ~12 bedrock 0
fill ~210 ~18 ~17 ~210 ~25 ~17 stained_hardened_clay 9
fill ~210 ~18 ~83 ~210 ~25 ~83 stained_hardened_clay 9
fill ~210 ~18 ~88 ~210 ~20 ~88 bedrock 0
fill ~211 ~18 ~14 ~212 ~18 ~14 coal_block 0
fill ~211 ~18 ~18 ~211 ~20 ~18 stained_hardened_clay 9
fill ~211 ~18 ~82 ~211 ~20 ~82 stained_hardened_clay 9
fill ~211 ~18 ~86 ~212 ~18 ~86 coal_block 0
fill ~212 ~18 ~19 ~212 ~21 ~19 stained_hardened_clay 9
fill ~212 ~18 ~81 ~212 ~21 ~81 stained_hardened_clay 9
fill ~213 ~18 ~14 ~213 ~20 ~14 stained_hardened_clay 9
fill ~213 ~18 ~15 ~213 ~19 ~15 coal_block 0
fill ~213 ~18 ~20 ~213 ~19 ~20 stained_hardened_clay 9
fill ~213 ~18 ~80 ~213 ~19 ~80 stained_hardened_clay 9
fill ~213 ~18 ~85 ~213 ~19 ~85 coal_block 0
fill ~213 ~18 ~86 ~213 ~20 ~86 stained_hardened_clay 9
fill ~214 ~18 ~13 ~214 ~19 ~13 bedrock 0
fill ~214 ~18 ~16 ~215 ~18 ~16 stained_hardened_clay 9
fill ~214 ~18 ~17 ~214 ~19 ~17 stained_hardened_clay 9
fill ~214 ~18 ~20 ~214 ~20 ~20 bedrock 0
fill ~214 ~18 ~80 ~214 ~20 ~80 bedrock 0
fill ~214 ~18 ~83 ~214 ~19 ~83 stained_hardened_clay 9
fill ~214 ~18 ~84 ~215 ~18 ~84 stained_hardened_clay 9
fill ~214 ~18 ~87 ~214 ~19 ~87 bedrock 0
fill ~215 ~18 ~17 ~215 ~20 ~17 bedrock 0
fill ~251 ~18 ~25 ~256 ~18 ~25 stone 0
fill ~252 ~18 ~24 ~256 ~18 ~24 stone 0
fill ~252 ~18 ~26 ~257 ~18 ~26 stone 0
fill ~252 ~18 ~29 ~255 ~18 ~29 stained_hardened_clay 9
fill ~252 ~18 ~30 ~255 ~18 ~30 stained_hardened_clay 9
fill ~253 ~18 ~28 ~257 ~18 ~28 stained_hardened_clay 9
fill ~254 ~18 ~27 ~256 ~18 ~27 stained_hardened_clay 9
fill ~255 ~18 ~23 ~256 ~18 ~23 bedrock 0
setblock ~256 ~18 ~29 bedrock 0
fill ~257 ~18 ~27 ~257 ~27 ~27 stone 0
setblock ~258 ~18 ~29 bedrock 0
fill ~209 ~19 ~15 ~209 ~23 ~15 stained_hardened_clay 9
fill ~209 ~19 ~16 ~209 ~24 ~16 stained_hardened_clay 9
fill ~209 ~19 ~84 ~209 ~24 ~84 stained_hardened_clay 9
fill ~209 ~19 ~85 ~209 ~23 ~85 stained_hardened_clay 9
fill ~210 ~19 ~18 ~210 ~21 ~18 stained_hardened_clay 9
fill ~210 ~19 ~82 ~210 ~21 ~82 stained_hardened_clay 9
setblock ~211 ~19 ~15 stained_hardened_clay 9
fill ~211 ~19 ~19 ~211 ~20 ~19 stained_hardened_clay 9
fill ~211 ~19 ~81 ~211 ~20 ~81 stained_hardened_clay 9
setblock ~211 ~19 ~85 stained_hardened_clay 9
setblock ~212 ~19 ~14 coal_block 0
fill ~212 ~19 ~17 ~213 ~19 ~17 coal_block 0
fill ~212 ~19 ~83 ~213 ~19 ~83 coal_block 0
setblock ~212 ~19 ~86 coal_block 0
fill ~213 ~19 ~16 ~213 ~20 ~16 coal_block 0
fill ~213 ~19 ~84 ~213 ~20 ~84 coal_block 0
fill ~214 ~19 ~14 ~214 ~21 ~14 bedrock 0
fill ~214 ~19 ~16 ~214 ~18 ~16 stained_hardened_clay 9
fill ~214 ~19 ~84 ~214 ~18 ~84 stained_hardened_clay 9
fill ~214 ~19 ~86 ~214 ~21 ~86 bedrock 0
fill ~250 ~19 ~25 ~257 ~19 ~25 stone 0
fill ~252 ~19 ~24 ~254 ~19 ~24 stone 0
fill ~252 ~19 ~26 ~257 ~19 ~26 stone 0
fill ~252 ~19 ~29 ~256 ~19 ~29 stained_hardened_clay 9
fill ~252 ~19 ~30 ~255 ~19 ~30 stained_hardened_clay 9
fill ~253 ~19 ~28 ~257 ~19 ~28 stained_hardened_clay 9
fill ~254 ~19 ~27 ~256 ~19 ~27 stained_hardened_clay 9
fill ~255 ~19 ~23 ~256 ~19 ~23 bedrock 0
fill ~255 ~19 ~24 ~257 ~19 ~24 bedrock 0
fill ~209 ~20 ~12 ~209 ~21 ~12 bedrock 0
fill ~209 ~20 ~17 ~209 ~27 ~17 stained_hardened_clay 9
fill ~209 ~20 ~83 ~209 ~27 ~83 stained_hardened_clay 9
fill ~209 ~20 ~88 ~209 ~21 ~88 bedrock 0
fill ~210 ~20 ~14 ~211 ~20 ~14 coal_block 0
setblock ~210 ~20 ~15 stained_hardened_clay 9
fill ~210 ~20 ~19 ~210 ~25 ~19 stained_hardened_clay 9
fill ~210 ~20 ~81 ~210 ~25 ~81 stained_hardened_clay 9
setblock ~210 ~20 ~85 stained_hardened_clay 9
fill ~210 ~20 ~86 ~211 ~20 ~86 coal_block 0
fill ~212 ~20 ~14 ~212 ~22 ~14 stained_hardened_clay 9
fill ~212 ~20 ~15 ~212 ~20 ~18 coal_block 0
fill ~212 ~20 ~20 ~212 ~21 ~20 stained_hardened_clay 9
fill ~212 ~20 ~80 ~212 ~21 ~80 stained_hardened_clay 9
fill ~212 ~20 ~82 ~212 ~24 ~82 coal_block 0
fill ~212 ~20 ~83 ~213 ~20 ~83 coal_block 0
fill ~212 ~20 ~84 ~212 ~22 ~84 coal_block 0
fill ~212 ~20 ~85 ~212 ~20 ~82 coal_block 0
fill ~212 ~20 ~86 ~212 ~22 ~86 stained_hardened_clay 9
fill ~213 ~20 ~15 ~213 ~21 ~15 stained_hardened_clay 9
setblock ~213 ~20 ~17 coal_block 0
fill ~213 ~20 ~20 ~213 ~22 ~20 bedrock 0
fill ~213 ~20 ~80 ~213 ~22 ~80 bedrock 0
fill ~213 ~20 ~85 ~213 ~21 ~85 stained_hardened_clay 9
fill ~214 ~20 ~17 ~214 ~22 ~17 bedrock 0
setblock ~214 ~20 ~18 stained_hardened_clay 9
setblock ~214 ~20 ~82 stained_hardened_clay 9
fill ~214 ~20 ~83 ~214 ~22 ~83 bedrock 0
fill ~250 ~20 ~25 ~257 ~20 ~25 stone 0
fill ~252 ~20 ~24 ~255 ~20 ~24 stone 0
fill ~252 ~20 ~26 ~257 ~20 ~26 stone 0
fill ~252 ~20 ~28 ~252 ~21 ~28 stone 0
fill ~252 ~20 ~29 ~255 ~20 ~29 stained_hardened_clay 9
fill ~252 ~20 ~30 ~255 ~20 ~30 stained_hardened_clay 9
fill ~253 ~20 ~28 ~257 ~20 ~28 stained_hardened_clay 9
fill ~254 ~20 ~27 ~256 ~20 ~27 stained_hardened_clay 9
fill ~256 ~20 ~24 ~256 ~27 ~24 bedrock 0
setblock ~256 ~20 ~29 bedrock 0
fill ~208 ~21 ~13 ~208 ~22 ~13 stained_hardened_clay 9
fill ~208 ~21 ~14 ~208 ~23 ~14 stained_hardened_clay 9
fill ~208 ~21 ~15 ~208 ~26 ~15 stained_hardened_clay 9
fill ~208 ~21 ~16 ~208 ~26 ~16 stained_hardened_clay 9
fill ~208 ~21 ~84 ~208 ~26 ~84 stained_hardened_clay 9
fill ~208 ~21 ~85 ~208 ~26 ~85 stained_hardened_clay 9
fill ~208 ~21 ~86 ~208 ~23 ~86 stained_hardened_clay 9
fill ~208 ~21 ~87 ~208 ~22 ~87 stained_hardened_clay 9
fill ~209 ~21 ~13 ~209 ~23 ~13 bedrock 0
fill ~209 ~21 ~18 ~209 ~24 ~18 stained_hardened_clay 9
fill ~209 ~21 ~82 ~209 ~24 ~82 stained_hardened_clay 9
fill ~209 ~21 ~87 ~209 ~23 ~87 bedrock 0
fill ~210 ~21 ~15 ~211 ~21 ~15 coal_block 0
fill ~210 ~21 ~85 ~211 ~21 ~85 coal_block 0
fill ~211 ~21 ~16 ~212 ~21 ~16 coal_block 0
fill ~211 ~21 ~20 ~211 ~25 ~20 stained_hardened_clay 9
fill ~211 ~21 ~80 ~211 ~25 ~80 stained_hardened_clay 9
fill ~211 ~21 ~84 ~211 ~24 ~84 coal_block 0
fill ~212 ~21 ~15 ~212 ~23 ~15 stained_hardened_clay 9
fill ~212 ~21 ~17 ~212 ~23 ~17 coal_block 0
fill ~212 ~21 ~18 ~212 ~24 ~18 coal_block 0
fill ~212 ~21 ~21 ~212 ~23 ~21 stained_hardened_clay 9
fill ~212 ~21 ~79 ~212 ~23 ~79 stained_hardened_clay 9
fill ~212 ~21 ~83 ~212 ~23 ~83 coal_block 0
fill ~212 ~21 ~85 ~212 ~23 ~85 stained_hardened_clay 9
fill ~213 ~21 ~14 ~213 ~22 ~14 bedrock 0
fill ~213 ~21 ~17 ~213 ~23 ~17 stained_hardened_clay 9
fill ~213 ~21 ~18 ~213 ~22 ~18 stained_hardened_clay 9
fill ~213 ~21 ~82 ~213 ~22 ~82 stained_hardened_clay 9
fill ~213 ~21 ~83 ~213 ~23 ~83 stained_hardened_clay 9
fill ~213 ~21 ~86 ~213 ~22 ~86 bedrock 0
fill ~250 ~21 ~25 ~254 ~21 ~25 stained_hardened_clay 9
fill ~250 ~21 ~28 ~250 ~31 ~28 stained_hardened_clay 9
fill ~251 ~21 ~29 ~256 ~21 ~29 stained_hardened_clay 9
fill ~252 ~21 ~24 ~254 ~21 ~24 stained_hardened_clay 9
fill ~252 ~21 ~26 ~254 ~21 ~26 stained_hardened_clay 9
fill ~252 ~21 ~30 ~256 ~21 ~30 stained_hardened_clay 9
fill ~253 ~21 ~28 ~257 ~21 ~28 stained_hardened_clay 9
fill ~254 ~21 ~27 ~256 ~21 ~27 stained_hardened_clay 9
fill ~255 ~21 ~24 ~255 ~21 ~26 stone 0
fill ~256 ~21 ~25 ~257 ~21 ~25 stone 0
fill ~256 ~21 ~26 ~257 ~21 ~26 stone 0
fill ~208 ~22 ~17 ~208 ~27 ~17 stained_hardened_clay 9
fill ~208 ~22 ~83 ~208 ~27 ~83 stained_hardened_clay 9
fill ~210 ~22 ~15 ~211 ~22 ~15 coal_block 0
fill ~210 ~22 ~85 ~211 ~22 ~85 coal_block 0
fill ~211 ~22 ~14 ~211 ~24 ~14 stained_hardened_clay 9
fill ~211 ~22 ~16 ~212 ~22 ~16 coal_block 0
fill ~211 ~22 ~86 ~211 ~24 ~86 stained_hardened_clay 9
fill ~212 ~22 ~19 ~212 ~25 ~19 coal_block 0
fill ~212 ~22 ~20 ~212 ~24 ~20 bedrock 0
fill ~212 ~22 ~80 ~212 ~24 ~80 bedrock 0
fill ~212 ~22 ~81 ~212 ~25 ~81 coal_block 0
fill ~213 ~22 ~15 ~213 ~24 ~15 bedrock 0
fill ~213 ~22 ~85 ~213 ~24 ~85 bedrock 0
fill ~214 ~22 ~18 ~214 ~23 ~18 bedrock 0
fill ~214 ~22 ~82 ~214 ~23 ~82 bedrock 0
fill ~250 ~22 ~25 ~255 ~22 ~25 stained_hardened_clay 9
fill ~251 ~22 ~29 ~256 ~22 ~29 stained_hardened_clay 9
fill ~252 ~22 ~24 ~255 ~22 ~24 stained_hardened_clay 9
fill ~252 ~22 ~26 ~255 ~22 ~26 stained_hardened_clay 9
fill ~252 ~22 ~27 ~256 ~22 ~27 stained_hardened_clay 9
fill ~252 ~22 ~28 ~257 ~22 ~28 stained_hardened_clay 9
fill ~252 ~22 ~30 ~256 ~22 ~30 stained_hardened_clay 9
fill ~253 ~22 ~31 ~254 ~22 ~31 stained_hardened_clay 9
fill ~256 ~22 ~25 ~257 ~22 ~25 stone 0
fill ~256 ~22 ~26 ~257 ~22 ~26 stone 0
fill ~207 ~23 ~15 ~207 ~26 ~15 stained_hardened_clay 9
fill ~207 ~23 ~16 ~207 ~29 ~16 stained_hardened_clay 9
fill ~207 ~23 ~84 ~207 ~29 ~84 stained_hardened_clay 9
fill ~207 ~23 ~85 ~207 ~26 ~85 stained_hardened_clay 9
fill ~208 ~23 ~13 ~208 ~24 ~13 bedrock 0
fill ~208 ~23 ~18 ~208 ~29 ~18 stained_hardened_clay 9
fill ~208 ~23 ~82 ~208 ~29 ~82 stained_hardened_clay 9
fill ~208 ~23 ~87 ~208 ~24 ~87 bedrock 0
fill ~209 ~23 ~19 ~209 ~24 ~19 stained_hardened_clay 9
fill ~209 ~23 ~81 ~209 ~24 ~81 stained_hardened_clay 9
fill ~210 ~23 ~15 ~211 ~23 ~15 coal_block 0
fill ~210 ~23 ~20 ~210 ~26 ~20 stained_hardened_clay 9
fill ~210 ~23 ~80 ~210 ~26 ~80 stained_hardened_clay 9
fill ~210 ~23 ~85 ~211 ~23 ~85 coal_block 0
fill ~211 ~23 ~16 ~211 ~24 ~16 coal_block 0
setblock ~211 ~23 ~21 stained_hardened_clay 9
setblock ~211 ~23 ~79 stained_hardened_clay 9
fill ~213 ~23 ~18 ~213 ~26 ~18 bedrock 0
fill ~213 ~23 ~19 ~213 ~25 ~19 stained_hardened_clay 9
fill ~213 ~23 ~81 ~213 ~25 ~81 stained_hardened_clay 9
fill ~213 ~23 ~82 ~213 ~26 ~82 bedrock 0
fill ~251 ~23 ~25 ~256 ~23 ~25 stained_hardened_clay 9
fill ~251 ~23 ~29 ~256 ~23 ~29 stained_hardened_clay 9
fill ~252 ~23 ~26 ~256 ~23 ~26 stained_hardened_clay 9
fill ~252 ~23 ~27 ~256 ~23 ~27 stained_hardened_clay 9
fill ~252 ~23 ~28 ~257 ~23 ~28 stained_hardened_clay 9
fill ~252 ~23 ~30 ~256 ~23 ~30 stained_hardened_clay 9
fill ~253 ~23 ~24 ~255 ~23 ~24 stained_hardened_clay 9
fill ~253 ~23 ~31 ~254 ~23 ~31 stained_hardened_clay 9
fill ~257 ~23 ~25 ~257 ~23 ~27 stone 0
fill ~258 ~23 ~26 ~258 ~27 ~26 stone 0
fill ~258 ~23 ~27 ~258 ~27 ~27 stone 0
fill ~258 ~23 ~28 ~258 ~30 ~28 stone 0
fill ~207 ~24 ~14 ~207 ~25 ~14 stained_hardened_clay 9
fill ~207 ~24 ~17 ~207 ~29 ~17 stained_hardened_clay 9
fill ~207 ~24 ~18 ~207 ~29 ~18 stained_hardened_clay 9
fill ~207 ~24 ~82 ~207 ~29 ~82 stained_hardened_clay 9
fill ~207 ~24 ~83 ~207 ~29 ~83 stained_hardened_clay 9
fill ~207 ~24 ~86 ~207 ~25 ~86 stained_hardened_clay 9
fill ~208 ~24 ~14 ~208 ~26 ~14 bedrock 0
fill ~208 ~24 ~19 ~208 ~30 ~19 stained_hardened_clay 9
fill ~208 ~24 ~81 ~208 ~30 ~81 stained_hardened_clay 9
fill ~208 ~24 ~86 ~208 ~26 ~86 bedrock 0
fill ~209 ~24 ~15 ~210 ~24 ~15 coal_block 0
fill ~209 ~24 ~85 ~210 ~24 ~85 coal_block 0
fill ~211 ~24 ~15 ~211 ~26 ~15 stained_hardened_clay 9
fill ~211 ~24 ~17 ~211 ~27 ~17 coal_block 0
fill ~211 ~24 ~21 ~212 ~24 ~21 bedrock 0
fill ~211 ~24 ~79 ~212 ~24 ~79 bedrock 0
fill ~211 ~24 ~83 ~211 ~27 ~83 coal_block 0
fill ~211 ~24 ~85 ~211 ~26 ~85 stained_hardened_clay 9
fill ~212 ~24 ~15 ~212 ~26 ~15 bedrock 0
setblock ~212 ~24 ~16 stained_hardened_clay 9
setblock ~212 ~24 ~84 stained_hardened_clay 9
fill ~212 ~24 ~85 ~212 ~26 ~85 bedrock 0
fill ~251 ~24 ~25 ~257 ~24 ~25 stained_hardened_clay 9
fill ~251 ~24 ~29 ~257 ~24 ~29 stained_hardened_clay 9
fill ~252 ~24 ~26 ~257 ~24 ~26 stained_hardened_clay 9
fill ~252 ~24 ~27 ~255 ~24 ~27 stained_hardened_clay 9
fill ~252 ~24 ~28 ~257 ~24 ~28 stained_hardened_clay 9
fill ~252 ~24 ~30 ~257 ~24 ~30 stained_hardened_clay 9
fill ~253 ~24 ~24 ~255 ~24 ~24 stained_hardened_clay 9
fill ~253 ~24 ~31 ~253 ~32 ~31 bedrock 0
fill ~254 ~24 ~31 ~256 ~24 ~31 stained_hardened_clay 9
setblock ~256 ~24 ~27 stone 0
fill ~258 ~24 ~29 ~258 ~31 ~29 stone 0
fill ~207 ~25 ~19 ~207 ~30 ~19 stained_hardened_clay 9
fill ~207 ~25 ~81 ~207 ~30 ~81 stained_hardened_clay 9
fill ~209 ~25 ~16 ~209 ~27 ~16 coal_block 0
fill ~209 ~25 ~20 ~209 ~28 ~20 stained_hardened_clay 9
fill ~209 ~25 ~80 ~209 ~28 ~80 stained_hardened_clay 9
fill ~209 ~25 ~84 ~209 ~27 ~84 coal_block 0
fill ~210 ~25 ~15 ~210 ~28 ~15 stained_hardened_clay 9
fill ~210 ~25 ~18 ~210 ~26 ~18 stained_hardened_clay 9
setblock ~210 ~25 ~21 stained_hardened_clay 9
setblock ~210 ~25 ~79 stained_hardened_clay 9
fill ~210 ~25 ~82 ~210 ~26 ~82 stained_hardened_clay 9
fill ~210 ~25 ~85 ~210 ~28 ~85 stained_hardened_clay 9
fill ~211 ~25 ~16 ~211 ~26 ~16 stained_hardened_clay 9
setblock ~211 ~25 ~19 stained_hardened_clay 9
fill ~211 ~25 ~21 ~211 ~26 ~21 bedrock 0
fill ~211 ~25 ~79 ~211 ~26 ~79 bedrock 0
setblock ~211 ~25 ~81 stained_hardened_clay 9
fill ~211 ~25 ~84 ~211 ~26 ~84 stained_hardened_clay 9
setblock ~212 ~25 ~18 stained_hardened_clay 9
setblock ~212 ~25 ~82 stained_hardened_clay 9
fill ~251 ~25 ~25 ~257 ~25 ~25 stained_hardened_clay 9
fill ~251 ~25 ~26 ~257 ~25 ~26 stained_hardened_clay 9
fill ~251 ~25 ~28 ~256 ~25 ~28 stained_hardened_clay 9
fill ~251 ~25 ~29 ~257 ~25 ~29 stained_hardened_clay 9
fill ~252 ~25 ~27 ~256 ~25 ~27 stained_hardened_clay 9
fill ~252 ~25 ~30 ~252 ~33 ~30 bedrock 0
fill ~253 ~25 ~30 ~257 ~25 ~30 stained_hardened_clay 9
fill ~254 ~25 ~24 ~255 ~25 ~24 stained_hardened_clay 9
fill ~254 ~25 ~31 ~256 ~25 ~31 stained_hardened_clay 9
fill ~257 ~25 ~28 ~257 ~28 ~28 stone 0
fill ~314 ~25 ~99 ~314 ~30 ~99 coal_block 0
fill ~206 ~26 ~16 ~206 ~29 ~16 stained_hardened_clay 9
fill ~206 ~26 ~17 ~206 ~29 ~17 stained_hardened_clay 9
fill ~206 ~26 ~18 ~206 ~41 ~18 stained_hardened_clay 9
fill ~206 ~26 ~82 ~206 ~41 ~82 stained_hardened_clay 9
fill ~206 ~26 ~83 ~206 ~29 ~83 stained_hardened_clay 9
fill ~206 ~26 ~84 ~206 ~29 ~84 stained_hardened_clay 9
fill ~207 ~26 ~14 ~207 ~27 ~14 bedrock 0
fill ~207 ~26 ~20 ~210 ~26 ~20 stained_hardened_clay 9
fill ~207 ~26 ~80 ~210 ~26 ~80 stained_hardened_clay 9
fill ~207 ~26 ~86 ~207 ~27 ~86 bedrock 0
fill ~209 ~26 ~18 ~209 ~29 ~18 stained_hardened_clay 9
fill ~209 ~26 ~21 ~209 ~28 ~21 stained_hardened_clay 9
fill ~209 ~26 ~79 ~209 ~28 ~79 stained_hardened_clay 9
fill ~209 ~26 ~82 ~209 ~29 ~82 stained_hardened_clay 9
fill ~210 ~26 ~16 ~210 ~27 ~16 coal_block 0
fill ~210 ~26 ~17 ~210 ~26 ~16 coal_block 0
fill ~210 ~26 ~19 ~211 ~26 ~19 coal_block 0
fill ~210 ~26 ~21 ~210 ~29 ~21 bedrock 0
fill ~210 ~26 ~22 ~210 ~27 ~22 stained_hardened_clay 9
fill ~210 ~26 ~78 ~210 ~27 ~78 stained_hardened_clay 9
fill ~210 ~26 ~79 ~210 ~29 ~79 bedrock 0
fill ~210 ~26 ~81 ~211 ~26 ~81 coal_block 0
fill ~210 ~26 ~83 ~210 ~26 ~84 coal_block 0
fill ~211 ~26 ~18 ~211 ~27 ~18 coal_block 0
fill ~211 ~26 ~82 ~211 ~27 ~82 coal_block 0
fill ~212 ~26 ~16 ~212 ~27 ~16 bedrock 0
fill ~212 ~26 ~18 ~212 ~26 ~19 bedrock 0
fill ~212 ~26 ~81 ~212 ~29 ~81 bedrock 0
fill ~212 ~26 ~82 ~212 ~26 ~81 bedrock 0
fill ~212 ~26 ~84 ~212 ~27 ~84 bedrock 0
fill ~250 ~26 ~29 ~250 ~30 ~29 bedrock 0
fill ~251 ~26 ~26 ~257 ~26 ~26 stained_hardened_clay 9
fill ~251 ~26 ~28 ~256 ~26 ~28 stained_hardened_clay 9
fill ~251 ~26 ~29 ~257 ~26 ~29 stained_hardened_clay 9
fill ~251 ~26 ~30 ~251 ~37 ~30 bedrock 0
fill ~252 ~26 ~25 ~257 ~26 ~25 stained_hardened_clay 9
fill ~252 ~26 ~27 ~256 ~26 ~27 stained_hardened_clay 9
fill ~253 ~26 ~30 ~257 ~26 ~30 stained_hardened_clay 9
fill ~254 ~26 ~24 ~255 ~26 ~24 stained_hardened_clay 9
fill ~254 ~26 ~31 ~257 ~26 ~31 stained_hardened_clay 9
setblock ~206 ~27 ~15 stained_hardened_clay 9
fill ~206 ~27 ~19 ~206 ~41 ~19 stained_hardened_clay 9
fill ~206 ~27 ~81 ~206 ~41 ~81 stained_hardened_clay 9
setblock ~206 ~27 ~85 stained_hardened_clay 9
fill ~207 ~27 ~15 ~207 ~28 ~15 bedrock 0
fill ~207 ~27 ~20 ~209 ~27 ~20 stained_hardened_clay 9
fill ~207 ~27 ~80 ~209 ~27 ~80 stained_hardened_clay 9
fill ~207 ~27 ~85 ~207 ~28 ~85 bedrock 0
setblock ~208 ~27 ~16 coal_block 0
fill ~208 ~27 ~21 ~208 ~42 ~21 stained_hardened_clay 9
fill ~208 ~27 ~79 ~208 ~42 ~79 stained_hardened_clay 9
setblock ~208 ~27 ~84 coal_block 0
fill ~209 ~27 ~19 ~210 ~27 ~19 stained_hardened_clay 9
fill ~209 ~27 ~22 ~209 ~28 ~22 stained_hardened_clay 9
fill ~209 ~27 ~78 ~209 ~28 ~78 stained_hardened_clay 9
fill ~209 ~27 ~81 ~210 ~27 ~81 stained_hardened_clay 9
setblock ~210 ~27 ~17 stone 0
fill ~210 ~27 ~20 ~211 ~27 ~20 coal_block 0
fill ~210 ~27 ~80 ~211 ~27 ~80 coal_block 0
setblock ~210 ~27 ~83 stone 0
setblock ~210 ~27 ~84 coal_block 0
fill ~211 ~27 ~16 ~211 ~30 ~16 bedrock 0
setblock ~211 ~27 ~19 coal_block 0
setblock ~211 ~27 ~81 coal_block 0
fill ~211 ~27 ~84 ~211 ~30 ~84 bedrock 0
setblock ~212 ~27 ~18 stained_hardened_clay 9
fill ~212 ~27 ~19 ~212 ~29 ~19 bedrock 0
fill ~212 ~27 ~20 ~212 ~28 ~20 stained_hardened_clay 9
fill ~212 ~27 ~80 ~212 ~28 ~80 stained_hardened_clay 9
setblock ~212 ~27 ~82 stained_hardened_clay 9
fill ~251 ~27 ~26 ~257 ~27 ~26 stained_hardened_clay 9
fill ~251 ~27 ~27 ~256 ~27 ~27 stained_hardened_clay 9
fill ~251 ~27 ~28 ~256 ~27 ~28 stained_hardened_clay 9
fill ~251 ~27 ~29 ~257 ~27 ~29 stained_hardened_clay 9
fill ~252 ~27 ~25 ~257 ~27 ~25 stained_hardened_clay 9
fill ~253 ~27 ~30 ~258 ~27 ~30 stained_hardened_clay 9
fill ~254 ~27 ~24 ~255 ~27 ~24 stained_hardened_clay 9
fill ~254 ~27 ~31 ~257 ~27 ~31 stained_hardened_clay 9
fill ~313 ~27 ~100 ~313 ~29 ~100 coal_block 0
fill ~205 ~28 ~18 ~205 ~41 ~18 stained_hardened_clay 9
fill ~205 ~28 ~19 ~205 ~42 ~19 stained_hardened_clay 9
fill ~205 ~28 ~81 ~205 ~42 ~81 stained_hardened_clay 9
fill ~205 ~28 ~82 ~205 ~41 ~82 stained_hardened_clay 9
fill ~206 ~28 ~15 ~206 ~30 ~15 bedrock 0
fill ~206 ~28 ~20 ~209 ~28 ~20 stained_hardened_clay 9
fill ~206 ~28 ~80 ~209 ~28 ~80 stained_hardened_clay 9
fill ~206 ~28 ~85 ~206 ~30 ~85 bedrock 0
fill ~208 ~28 ~17 ~209 ~28 ~17 coal_block 0
fill ~208 ~28 ~83 ~209 ~28 ~83 coal_block 0
fill ~209 ~28 ~19 ~209 ~30 ~19 stained_hardened_clay 9
fill ~209 ~28 ~81 ~209 ~30 ~81 stained_hardened_clay 9
fill ~210 ~28 ~16 ~210 ~30 ~16 stained_hardened_clay 9
fill ~210 ~28 ~17 ~210 ~29 ~17 stained_hardened_clay 9
fill ~210 ~28 ~18 ~210 ~30 ~18 coal_block 0
fill ~210 ~28 ~19 ~210 ~32 ~19 coal_block 0
fill ~210 ~28 ~20 ~211 ~28 ~20 coal_block 0
fill ~210 ~28 ~80 ~211 ~28 ~80 coal_block 0
fill ~210 ~28 ~81 ~210 ~32 ~81 coal_block 0
fill ~210 ~28 ~82 ~210 ~30 ~82 coal_block 0
fill ~210 ~28 ~83 ~210 ~29 ~83 stained_hardened_clay 9
fill ~210 ~28 ~84 ~210 ~30 ~84 stained_hardened_clay 9
setblock ~211 ~28 ~19 stained_hardened_clay 9
setblock ~211 ~28 ~81 stained_hardened_clay 9
fill ~251 ~28 ~26 ~258 ~28 ~26 stained_hardened_clay 9
fill ~251 ~28 ~27 ~258 ~28 ~27 stained_hardened_clay 9
fill ~251 ~28 ~28 ~256 ~28 ~28 stained_hardened_clay 9
fill ~251 ~28 ~29 ~257 ~28 ~29 stained_hardened_clay 9
fill ~252 ~28 ~25 ~257 ~28 ~25 stained_hardened_clay 9
fill ~252 ~28 ~31 ~252 ~41 ~31 bedrock 0
fill ~253 ~28 ~30 ~258 ~28 ~30 stained_hardened_clay 9
fill ~254 ~28 ~31 ~257 ~28 ~31 stained_hardened_clay 9
setblock ~255 ~28 ~24 stained_hardened_clay 9
fill ~313 ~28 ~98 ~313 ~29 ~98 coal_block 0
fill ~205 ~29 ~17 ~205 ~40 ~17 stained_hardened_clay 9
fill ~205 ~29 ~83 ~205 ~40 ~83 stained_hardened_clay 9
fill ~206 ~29 ~20 ~208 ~29 ~20 stained_hardened_clay 9
fill ~206 ~29 ~80 ~208 ~29 ~80 stained_hardened_clay 9
fill ~207 ~29 ~21 ~207 ~41 ~21 stained_hardened_clay 9
fill ~207 ~29 ~79 ~207 ~41 ~79 stained_hardened_clay 9
fill ~208 ~29 ~17 ~209 ~29 ~17 coal_block 0
fill ~208 ~29 ~22 ~208 ~30 ~22 stained_hardened_clay 9
fill ~208 ~29 ~78 ~208 ~30 ~78 stained_hardened_clay 9
fill ~208 ~29 ~83 ~209 ~29 ~83 coal_block 0
fill ~209 ~29 ~20 ~210 ~29 ~20 coal_block 0
fill ~209 ~29 ~21 ~209 ~29 ~22 bedrock 0
fill ~209 ~29 ~78 ~209 ~31 ~78 bedrock 0
fill ~209 ~29 ~79 ~209 ~29 ~78 bedrock 0
fill ~209 ~29 ~80 ~210 ~29 ~80 coal_block 0
fill ~211 ~29 ~19 ~211 ~31 ~19 bedrock 0
fill ~211 ~29 ~20 ~211 ~30 ~20 stained_hardened_clay 9
fill ~211 ~29 ~80 ~211 ~30 ~80 stained_hardened_clay 9
fill ~211 ~29 ~81 ~211 ~31 ~81 bedrock 0
fill ~251 ~29 ~26 ~258 ~29 ~26 stained_hardened_clay 9
fill ~251 ~29 ~27 ~252 ~29 ~27 stained_hardened_clay 9
fill ~251 ~29 ~28 ~257 ~29 ~28 stained_hardened_clay 9
fill ~251 ~29 ~29 ~257 ~29 ~29 stained_hardened_clay 9
fill ~253 ~29 ~25 ~257 ~29 ~25 stained_hardened_clay 9
fill ~253 ~29 ~27 ~253 ~43 ~27 stone 0
fill ~253 ~29 ~30 ~258 ~29 ~30 stained_hardened_clay 9
fill ~254 ~29 ~27 ~258 ~29 ~27 stained_hardened_clay 9
fill ~254 ~29 ~31 ~257 ~29 ~31 stained_hardened_clay 9
fill ~313 ~29 ~99 ~313 ~30 ~99 bedrock 0
setblock ~205 ~30 ~16 stained_hardened_clay 9
fill ~205 ~30 ~20 ~208 ~30 ~20 stained_hardened_clay 9
fill ~205 ~30 ~80 ~208 ~30 ~80 stained_hardened_clay 9
setblock ~205 ~30 ~84 stained_hardened_clay 9
fill ~206 ~30 ~16 ~206 ~31 ~16 bedrock 0
fill ~206 ~30 ~17 ~208 ~30 ~17 coal_block 0
fill ~206 ~30 ~21 ~206 ~41 ~21 stained_hardened_clay 9
fill ~206 ~30 ~79 ~206 ~41 ~79 stained_hardened_clay 9
fill ~206 ~30 ~83 ~208 ~30 ~83 coal_block 0
fill ~206 ~30 ~84 ~206 ~31 ~84 bedrock 0
fill ~207 ~30 ~18 ~210 ~30 ~18 coal_block 0
fill ~207 ~30 ~82 ~210 ~30 ~82 coal_block 0
fill ~209 ~30 ~16 ~209 ~31 ~16 stained_hardened_clay 9
fill ~209 ~30 ~17 ~209 ~39 ~17 stained_hardened_clay 9
fill ~209 ~30 ~20 ~210 ~30 ~20 coal_block 0
setblock ~209 ~30 ~21 stained_hardened_clay 9
fill ~209 ~30 ~22 ~209 ~31 ~22 bedrock 0
setblock ~209 ~30 ~79 stained_hardened_clay 9
fill ~209 ~30 ~80 ~210 ~30 ~80 coal_block 0
fill ~209 ~30 ~83 ~209 ~39 ~83 stained_hardened_clay 9
fill ~209 ~30 ~84 ~209 ~31 ~84 stained_hardened_clay 9
fill ~210 ~30 ~17 ~211 ~30 ~17 bedrock 0
fill ~210 ~30 ~83 ~211 ~30 ~83 bedrock 0
fill ~250 ~30 ~27 ~252 ~30 ~27 stained_hardened_clay 9
setblock ~250 ~30 ~30 bedrock 0
fill ~251 ~30 ~26 ~251 ~25 ~26 stained_hardened_clay 9
fill ~251 ~30 ~28 ~253 ~30 ~28 stained_hardened_clay 9
fill ~251 ~30 ~29 ~257 ~30 ~29 stained_hardened_clay 9
fill ~252 ~30 ~26 ~252 ~47 ~26 stone 0
fill ~253 ~30 ~25 ~257 ~30 ~25 stained_hardened_clay 9
fill ~253 ~30 ~26 ~258 ~30 ~26 stained_hardened_clay 9
fill ~253 ~30 ~30 ~257 ~30 ~30 stained_hardened_clay 9
fill ~254 ~30 ~27 ~258 ~30 ~27 stained_hardened_clay 9
setblock ~254 ~30 ~28 stone 0
fill ~254 ~30 ~31 ~257 ~30 ~31 stained_hardened_clay 9
fill ~255 ~30 ~28 ~257 ~30 ~28 stained_hardened_clay 9
setblock ~258 ~30 ~30 stone 0
fill ~313 ~30 ~98 ~313 ~31 ~98 stone 0
fill ~313 ~30 ~100 ~313 ~31 ~100 stone 0
fill ~204 ~31 ~18 ~204 ~42 ~18 stained_hardened_clay 9
fill ~204 ~31 ~19 ~204 ~42 ~19 stained_hardened_clay 9
fill ~204 ~31 ~20 ~206 ~31 ~20 stained_hardened_clay 9
fill ~204 ~31 ~80 ~206 ~31 ~80 stained_hardened_clay 9
fill ~204 ~31 ~81 ~204 ~42 ~81 stained_hardened_clay 9
fill ~204 ~31 ~82 ~204 ~42 ~82 stained_hardened_clay 9
fill ~205 ~31 ~16 ~205 ~32 ~16 bedrock 0
fill ~205 ~31 ~21 ~205 ~41 ~21 stained_hardened_clay 9
fill ~205 ~31 ~79 ~205 ~41 ~79 stained_hardened_clay 9
fill ~205 ~31 ~84 ~205 ~32 ~84 bedrock 0
fill ~206 ~31 ~17 ~206 ~39 ~17 stained_hardened_clay 9
fill ~206 ~31 ~22 ~207 ~31 ~22 stained_hardened_clay 9
fill ~206 ~31 ~78 ~207 ~31 ~78 stained_hardened_clay 9
fill ~206 ~31 ~83 ~206 ~39 ~83 stained_hardened_clay 9
fill ~207 ~31 ~18 ~208 ~31 ~18 coal_block 0
fill ~207 ~31 ~19 ~210 ~31 ~19 coal_block 0
fill ~207 ~31 ~20 ~209 ~31 ~20 coal_block 0
fill ~207 ~31 ~80 ~209 ~31 ~80 coal_block 0
fill ~207 ~31 ~81 ~210 ~31 ~81 coal_block 0
fill ~207 ~31 ~82 ~208 ~31 ~82 coal_block 0
fill ~208 ~31 ~22 ~208 ~32 ~22 bedrock 0
fill ~208 ~31 ~78 ~208 ~32 ~78 bedrock 0
fill ~209 ~31 ~18 ~210 ~31 ~18 stained_hardened_clay 9
fill ~209 ~31 ~82 ~210 ~31 ~82 stained_hardened_clay 9
fill ~210 ~31 ~17 ~210 ~32 ~17 bedrock 0
setblock ~210 ~31 ~20 stained_hardened_clay 9
setblock ~210 ~31 ~80 stained_hardened_clay 9
fill ~210 ~31 ~83 ~210 ~32 ~83 bedrock 0
fill ~211 ~31 ~20 ~211 ~32 ~20 bedrock 0
fill ~211 ~31 ~80 ~211 ~32 ~80 bedrock 0
fill ~250 ~31 ~27 ~253 ~31 ~27 stone 0
fill ~250 ~31 ~29 ~257 ~31 ~29 stained_hardened_clay 9
fill ~251 ~31 ~26 ~251 ~43 ~26 stone 0
fill ~251 ~31 ~28 ~251 ~25 ~28 stained_hardened_clay 9
fill ~252 ~31 ~28 ~253 ~31 ~28 stone 0
fill ~253 ~31 ~25 ~257 ~31 ~25 stained_hardened_clay 9
fill ~253 ~31 ~26 ~258 ~31 ~26 stained_hardened_clay 9
fill ~253 ~31 ~30 ~258 ~31 ~30 stained_hardened_clay 9
fill ~254 ~31 ~27 ~258 ~31 ~27 stained_hardened_clay 9
fill ~254 ~31 ~28 ~258 ~31 ~28 stained_hardened_clay 9
fill ~254 ~31 ~31 ~257 ~31 ~31 stained_hardened_clay 9
fill ~312 ~31 ~99 ~313 ~31 ~99 stone 0
fill ~314 ~31 ~99 ~314 ~37 ~99 bedrock 0
fill ~203 ~32 ~19 ~203 ~42 ~19 stained_hardened_clay 9
fill ~203 ~32 ~20 ~206 ~32 ~20 stained_hardened_clay 9
fill ~203 ~32 ~80 ~206 ~32 ~80 stained_hardened_clay 9
fill ~203 ~32 ~81 ~203 ~42 ~81 stained_hardened_clay 9
fill ~204 ~32 ~17 ~204 ~40 ~17 stained_hardened_clay 9
fill ~204 ~32 ~21 ~204 ~41 ~21 stained_hardened_clay 9
fill ~204 ~32 ~79 ~204 ~41 ~79 stained_hardened_clay 9
fill ~204 ~32 ~83 ~204 ~40 ~83 stained_hardened_clay 9
fill ~206 ~32 ~22 ~207 ~32 ~22 stained_hardened_clay 9
fill ~206 ~32 ~78 ~207 ~32 ~78 stained_hardened_clay 9
fill ~207 ~32 ~18 ~208 ~32 ~18 coal_block 0
fill ~207 ~32 ~19 ~210 ~32 ~19 coal_block 0
fill ~207 ~32 ~20 ~209 ~32 ~20 coal_block 0
fill ~207 ~32 ~80 ~209 ~32 ~80 coal_block 0
fill ~207 ~32 ~81 ~210 ~32 ~81 coal_block 0
fill ~207 ~32 ~82 ~208 ~32 ~82 coal_block 0
fill ~209 ~32 ~18 ~210 ~32 ~18 stained_hardened_clay 9
fill ~209 ~32 ~82 ~210 ~32 ~82 stained_hardened_clay 9
fill ~210 ~32 ~20 ~210 ~33 ~20 bedrock 0
fill ~210 ~32 ~80 ~210 ~33 ~80 bedrock 0
fill ~250 ~32 ~27 ~253 ~32 ~27 stone 0
fill ~250 ~32 ~28 ~253 ~32 ~28 stone 0
fill ~250 ~32 ~29 ~252 ~32 ~29 stone 0
fill ~253 ~32 ~25 ~253 ~40 ~25 stone 0
fill ~253 ~32 ~26 ~253 ~40 ~26 stone 0
fill ~253 ~32 ~29 ~258 ~32 ~29 stained_hardened_clay 9
fill ~253 ~32 ~30 ~258 ~32 ~30 stained_hardened_clay 9
fill ~254 ~32 ~25 ~257 ~32 ~25 stained_hardened_clay 9
fill ~254 ~32 ~26 ~258 ~32 ~26 stained_hardened_clay 9
fill ~254 ~32 ~27 ~258 ~32 ~27 stained_hardened_clay 9
fill ~254 ~32 ~28 ~258 ~32 ~28 stained_hardened_clay 9
fill ~254 ~32 ~31 ~257 ~32 ~31 stained_hardened_clay 9
fill ~312 ~32 ~99 ~312 ~31 ~99 stone 0
fill ~313 ~32 ~98 ~313 ~34 ~98 stained_hardened_clay 9
fill ~313 ~32 ~99 ~313 ~34 ~99 stained_hardened_clay 9
fill ~313 ~32 ~100 ~313 ~34 ~100 stained_hardened_clay 9
fill ~203 ~33 ~18 ~203 ~41 ~18 stained_hardened_clay 9
fill ~203 ~33 ~20 ~209 ~33 ~20 stained_hardened_clay 9
fill ~203 ~33 ~21 ~203 ~33 ~18 stained_hardened_clay 9
fill ~203 ~33 ~79 ~203 ~33 ~82 stained_hardened_clay 9
fill ~204 ~33 ~80 ~209 ~33 ~80 stained_hardened_clay 9
fill ~205 ~33 ~22 ~207 ~33 ~22 stained_hardened_clay 9
fill ~205 ~33 ~78 ~207 ~33 ~78 stained_hardened_clay 9
fill ~207 ~33 ~17 ~209 ~33 ~17 stained_hardened_clay 9
fill ~207 ~33 ~18 ~210 ~33 ~18 stained_hardened_clay 9
fill ~207 ~33 ~19 ~210 ~33 ~19 stained_hardened_clay 9
fill ~207 ~33 ~81 ~210 ~33 ~81 stained_hardened_clay 9
fill ~207 ~33 ~82 ~210 ~33 ~82 stained_hardened_clay 9
fill ~207 ~33 ~83 ~209 ~33 ~83 stained_hardened_clay 9
fill ~209 ~33 ~21 ~209 ~43 ~21 stained_hardened_clay 9
fill ~209 ~33 ~79 ~209 ~43 ~79 stained_hardened_clay 9
fill ~250 ~33 ~27 ~254 ~33 ~27 stone 0
fill ~250 ~33 ~28 ~253 ~33 ~28 stone 0
fill ~250 ~33 ~29 ~252 ~33 ~29 stone 0
setblock ~251 ~33 ~31 bedrock 0
fill ~253 ~33 ~29 ~258 ~33 ~29 stained_hardened_clay 9
fill ~253 ~33 ~30 ~258 ~33 ~30 stained_hardened_clay 9
fill ~253 ~33 ~31 ~257 ~33 ~31 stained_hardened_clay 9
fill ~254 ~33 ~25 ~257 ~33 ~25 stained_hardened_clay 9
fill ~254 ~33 ~26 ~258 ~33 ~26 stained_hardened_clay 9
fill ~254 ~33 ~28 ~258 ~33 ~28 stained_hardened_clay 9
fill ~255 ~33 ~27 ~258 ~33 ~27 stained_hardened_clay 9
fill ~291 ~33 ~104 ~291 ~38 ~104 coal_block 0
fill ~312 ~33 ~99 ~312 ~34 ~99 stained_hardened_clay 9
fill ~202 ~34 ~19 ~202 ~41 ~19 stained_hardened_clay 9
fill ~202 ~34 ~81 ~202 ~41 ~81 stained_hardened_clay 9
fill ~203 ~34 ~20 ~210 ~34 ~20 stained_hardened_clay 9
fill ~203 ~34 ~80 ~210 ~34 ~80 stained_hardened_clay 9
fill ~203 ~34 ~82 ~203 ~41 ~82 stained_hardened_clay 9
fill ~205 ~34 ~22 ~207 ~34 ~22 stained_hardened_clay 9
fill ~205 ~34 ~78 ~207 ~34 ~78 stained_hardened_clay 9
fill ~207 ~34 ~17 ~210 ~34 ~17 stained_hardened_clay 9
fill ~207 ~34 ~18 ~211 ~34 ~18 stained_hardened_clay 9
fill ~207 ~34 ~19 ~211 ~34 ~19 stained_hardened_clay 9
fill ~207 ~34 ~81 ~211 ~34 ~81 stained_hardened_clay 9
fill ~207 ~34 ~82 ~211 ~34 ~82 stained_hardened_clay 9
fill ~207 ~34 ~83 ~210 ~34 ~83 stained_hardened_clay 9
fill ~250 ~34 ~27 ~254 ~34 ~27 stone 0
fill ~250 ~34 ~28 ~253 ~34 ~28 stone 0
fill ~250 ~34 ~29 ~252 ~34 ~29 stone 0
fill ~252 ~34 ~30 ~258 ~34 ~30 stained_hardened_clay 9
fill ~253 ~34 ~29 ~258 ~34 ~29 stained_hardened_clay 9
fill ~253 ~34 ~31 ~257 ~34 ~31 stained_hardened_clay 9
fill ~254 ~34 ~25 ~254 ~35 ~25 stone 0
fill ~254 ~34 ~26 ~254 ~35 ~26 stone 0
fill ~254 ~34 ~28 ~258 ~34 ~28 stained_hardened_clay 9
fill ~255 ~34 ~25 ~257 ~34 ~25 stained_hardened_clay 9
fill ~255 ~34 ~26 ~258 ~34 ~26 stained_hardened_clay 9
fill ~255 ~34 ~27 ~258 ~34 ~27 stained_hardened_clay 9
fill ~319 ~34 ~82 ~319 ~39 ~82 coal_block 0
fill ~202 ~35 ~18 ~202 ~40 ~18 stained_hardened_clay 9
fill ~202 ~35 ~82 ~202 ~40 ~82 stained_hardened_clay 9
fill ~203 ~35 ~20 ~211 ~35 ~20 stained_hardened_clay 9
fill ~203 ~35 ~21 ~203 ~40 ~21 stained_hardened_clay 9
fill ~203 ~35 ~79 ~203 ~40 ~79 stained_hardened_clay 9
fill ~203 ~35 ~80 ~211 ~35 ~80 stained_hardened_clay 9
fill ~204 ~35 ~22 ~208 ~35 ~22 stained_hardened_clay 9
fill ~204 ~35 ~78 ~208 ~35 ~78 stained_hardened_clay 9
fill ~207 ~35 ~17 ~210 ~35 ~17 stained_hardened_clay 9
fill ~207 ~35 ~18 ~211 ~35 ~18 stained_hardened_clay 9
fill ~207 ~35 ~19 ~211 ~35 ~19 stained_hardened_clay 9
fill ~207 ~35 ~81 ~211 ~35 ~81 stained_hardened_clay 9
fill ~207 ~35 ~82 ~211 ~35 ~82 stained_hardened_clay 9
fill ~207 ~35 ~83 ~210 ~35 ~83 stained_hardened_clay 9
fill ~210 ~35 ~21 ~210 ~44 ~21 stained_hardened_clay 9
fill ~210 ~35 ~79 ~210 ~44 ~79 stained_hardened_clay 9
fill ~250 ~35 ~27 ~254 ~35 ~27 stone 0
fill ~250 ~35 ~28 ~253 ~35 ~28 stone 0
fill ~250 ~35 ~29 ~252 ~35 ~29 stone 0
fill ~252 ~35 ~30 ~258 ~35 ~30 stained_hardened_clay 9
fill ~253 ~35 ~29 ~258 ~35 ~29 stained_hardened_clay 9
fill ~253 ~35 ~31 ~257 ~35 ~31 stained_hardened_clay 9
fill ~254 ~35 ~28 ~258 ~35 ~28 stained_hardened_clay 9
fill ~255 ~35 ~25 ~257 ~35 ~25 stained_hardened_clay 9
fill ~255 ~35 ~26 ~258 ~35 ~26 stained_hardened_clay 9
fill ~255 ~35 ~27 ~258 ~35 ~27 stained_hardened_clay 9
fill ~292 ~35 ~103 ~292 ~37 ~103 coal_block 0
fill ~312 ~35 ~99 ~314 ~35 ~99 bedrock 0
fill ~313 ~35 ~98 ~313 ~37 ~98 bedrock 0
fill ~313 ~35 ~100 ~313 ~37 ~100 bedrock 0
fill ~202 ~36 ~20 ~212 ~36 ~20 stained_hardened_clay 9
fill ~202 ~36 ~80 ~212 ~36 ~80 stained_hardened_clay 9
fill ~204 ~36 ~22 ~209 ~36 ~22 stained_hardened_clay 9
fill ~204 ~36 ~78 ~209 ~36 ~78 stained_hardened_clay 9
fill ~207 ~36 ~17 ~210 ~36 ~17 stained_hardened_clay 9
fill ~207 ~36 ~18 ~211 ~36 ~18 stained_hardened_clay 9
fill ~207 ~36 ~19 ~212 ~36 ~19 stained_hardened_clay 9
fill ~207 ~36 ~81 ~212 ~36 ~81 stained_hardened_clay 9
fill ~207 ~36 ~82 ~211 ~36 ~82 stained_hardened_clay 9
fill ~207 ~36 ~83 ~210 ~36 ~83 stained_hardened_clay 9
fill ~211 ~36 ~21 ~211 ~45 ~21 stained_hardened_clay 9
fill ~211 ~36 ~79 ~211 ~45 ~79 stained_hardened_clay 9
fill ~250 ~36 ~27 ~254 ~36 ~27 stone 0
fill ~250 ~36 ~28 ~253 ~36 ~28 stone 0
fill ~250 ~36 ~29 ~252 ~36 ~29 stone 0
fill ~252 ~36 ~30 ~258 ~36 ~30 stained_hardened_clay 9
fill ~253 ~36 ~29 ~258 ~36 ~29 stained_hardened_clay 9
fill ~253 ~36 ~31 ~257 ~36 ~31 stained_hardened_clay 9
fill ~254 ~36 ~25 ~257 ~36 ~25 stained_hardened_clay 9
fill ~254 ~36 ~26 ~258 ~36 ~26 stained_hardened_clay 9
fill ~254 ~36 ~28 ~258 ~36 ~28 stained_hardened_clay 9
fill ~255 ~36 ~27 ~258 ~36 ~27 stained_hardened_clay 9
fill ~290 ~36 ~103 ~290 ~37 ~103 coal_block 0
fill ~291 ~36 ~103 ~291 ~41 ~103 stained_hardened_clay 9
fill ~312 ~36 ~98 ~312 ~36 ~100 bedrock 0
fill ~313 ~36 ~99 ~313 ~39 ~99 bedrock 0
setblock ~314 ~36 ~98 bedrock 0
setblock ~314 ~36 ~100 bedrock 0
fill ~318 ~36 ~82 ~318 ~40 ~82 coal_block 0
fill ~202 ~37 ~20 ~213 ~37 ~20 stained_hardened_clay 9
fill ~202 ~37 ~80 ~213 ~37 ~80 stained_hardened_clay 9
fill ~204 ~37 ~22 ~210 ~37 ~22 stained_hardened_clay 9
fill ~204 ~37 ~78 ~210 ~37 ~78 stained_hardened_clay 9
fill ~207 ~37 ~17 ~210 ~37 ~17 stained_hardened_clay 9
fill ~207 ~37 ~18 ~212 ~37 ~18 stained_hardened_clay 9
fill ~207 ~37 ~19 ~213 ~37 ~19 stained_hardened_clay 9
fill ~207 ~37 ~81 ~213 ~37 ~81 stained_hardened_clay 9
fill ~207 ~37 ~82 ~212 ~37 ~82 stained_hardened_clay 9
fill ~207 ~37 ~83 ~210 ~37 ~83 stained_hardened_clay 9
fill ~212 ~37 ~21 ~212 ~47 ~21 stained_hardened_clay 9
fill ~212 ~37 ~79 ~212 ~47 ~79 stained_hardened_clay 9
fill ~250 ~37 ~27 ~254 ~37 ~27 stone 0
fill ~250 ~37 ~28 ~253 ~37 ~28 stone 0
fill ~250 ~37 ~29 ~252 ~37 ~29 stone 0
setblock ~251 ~37 ~31 bedrock 0
fill ~252 ~37 ~30 ~258 ~37 ~30 stained_hardened_clay 9
fill ~253 ~37 ~29 ~258 ~37 ~29 stained_hardened_clay 9
fill ~253 ~37 ~31 ~257 ~37 ~31 stained_hardened_clay 9
fill ~254 ~37 ~25 ~255 ~37 ~25 stained_hardened_clay 9
fill ~254 ~37 ~26 ~257 ~37 ~26 stained_hardened_clay 9
fill ~254 ~37 ~28 ~258 ~37 ~28 stained_hardened_clay 9
fill ~255 ~37 ~27 ~257 ~37 ~27 stained_hardened_clay 9
fill ~256 ~37 ~25 ~257 ~37 ~25 bedrock 0
fill ~258 ~37 ~26 ~258 ~37 ~27 bedrock 0
fill ~291 ~37 ~102 ~291 ~41 ~102 stained_hardened_clay 9
fill ~311 ~37 ~98 ~312 ~37 ~98 stained_hardened_clay 9
fill ~311 ~37 ~99 ~311 ~38 ~99 stained_hardened_clay 9
setblock ~312 ~37 ~99 bedrock 0
fill ~312 ~37 ~100 ~312 ~38 ~100 stained_hardened_clay 9
fill ~319 ~37 ~83 ~319 ~40 ~83 coal_block 0
fill ~202 ~38 ~20 ~214 ~38 ~20 stained_hardened_clay 9
fill ~202 ~38 ~80 ~214 ~38 ~80 stained_hardened_clay 9
fill ~203 ~38 ~17 ~203 ~40 ~17 stained_hardened_clay 9
fill ~203 ~38 ~22 ~210 ~38 ~22 stained_hardened_clay 9
fill ~203 ~38 ~78 ~210 ~38 ~78 stained_hardened_clay 9
fill ~203 ~38 ~83 ~203 ~40 ~83 stained_hardened_clay 9
fill ~207 ~38 ~17 ~211 ~38 ~17 stained_hardened_clay 9
fill ~207 ~38 ~18 ~213 ~38 ~18 stained_hardened_clay 9
fill ~207 ~38 ~19 ~214 ~38 ~19 stained_hardened_clay 9
fill ~207 ~38 ~81 ~214 ~38 ~81 stained_hardened_clay 9
fill ~207 ~38 ~82 ~213 ~38 ~82 stained_hardened_clay 9
fill ~207 ~38 ~83 ~211 ~38 ~83 stained_hardened_clay 9
setblock ~211 ~38 ~22 stone 0
setblock ~211 ~38 ~78 stone 0
fill ~213 ~38 ~21 ~213 ~48 ~21 stained_hardened_clay 9
fill ~213 ~38 ~79 ~213 ~48 ~79 stained_hardened_clay 9
fill ~250 ~38 ~27 ~254 ~38 ~27 stone 0
fill ~250 ~38 ~28 ~253 ~38 ~28 stone 0
fill ~250 ~38 ~29 ~252 ~38 ~29 stone 0
fill ~251 ~38 ~30 ~251 ~39 ~30 stone 0
fill ~252 ~38 ~30 ~258 ~38 ~30 stained_hardened_clay 9
fill ~253 ~38 ~29 ~258 ~38 ~29 stained_hardened_clay 9
fill ~253 ~38 ~31 ~257 ~38 ~31 stained_hardened_clay 9
fill ~254 ~38 ~25 ~254 ~55 ~25 stained_hardened_clay 9
fill ~254 ~38 ~26 ~255 ~38 ~26 stained_hardened_clay 9
fill ~254 ~38 ~28 ~257 ~38 ~28 stained_hardened_clay 9
fill ~255 ~38 ~25 ~255 ~39 ~25 bedrock 0
fill ~255 ~38 ~27 ~256 ~38 ~27 stained_hardened_clay 9
fill ~256 ~38 ~26 ~257 ~38 ~26 coal_block 0
fill ~257 ~38 ~27 ~257 ~44 ~27 coal_block 0
setblock ~258 ~38 ~28 bedrock 0
fill ~290 ~38 ~103 ~290 ~41 ~103 stained_hardened_clay 9
fill ~292 ~38 ~103 ~292 ~41 ~103 stained_hardened_clay 9
fill ~310 ~38 ~98 ~313 ~38 ~98 stained_hardened_clay 9
fill ~312 ~38 ~97 ~312 ~39 ~97 stained_hardened_clay 9
setblock ~312 ~38 ~99 stained_hardened_clay 9
fill ~318 ~38 ~83 ~318 ~40 ~83 stained_hardened_clay 9
fill ~202 ~39 ~20 ~215 ~39 ~20 stained_hardened_clay 9
fill ~202 ~39 ~80 ~215 ~39 ~80 stained_hardened_clay 9
fill ~203 ~39 ~22 ~212 ~39 ~22 stained_hardened_clay 9
fill ~203 ~39 ~78 ~212 ~39 ~78 stained_hardened_clay 9
fill ~207 ~39 ~17 ~212 ~39 ~17 stained_hardened_clay 9
fill ~207 ~39 ~18 ~214 ~39 ~18 stained_hardened_clay 9
fill ~207 ~39 ~19 ~215 ~39 ~19 stained_hardened_clay 9
fill ~207 ~39 ~81 ~215 ~39 ~81 stained_hardened_clay 9
fill ~207 ~39 ~82 ~214 ~39 ~82 stained_hardened_clay 9
fill ~207 ~39 ~83 ~212 ~39 ~83 stained_hardened_clay 9
fill ~214 ~39 ~21 ~214 ~49 ~21 stained_hardened_clay 9
fill ~214 ~39 ~79 ~214 ~49 ~79 stained_hardened_clay 9
fill ~250 ~39 ~27 ~254 ~39 ~27 stone 0
fill ~250 ~39 ~28 ~253 ~39 ~28 stone 0
fill ~250 ~39 ~29 ~251 ~39 ~29 stone 0
setblock ~251 ~39 ~31 stone 0
fill ~252 ~39 ~29 ~257 ~39 ~29 stained_hardened_clay 9
fill ~252 ~39 ~30 ~258 ~39 ~30 stained_hardened_clay 9
fill ~253 ~39 ~31 ~257 ~39 ~31 stained_hardened_clay 9
fill ~254 ~39 ~26 ~255 ~39 ~26 stained_hardened_clay 9
fill ~254 ~39 ~28 ~256 ~39 ~28 stained_hardened_clay 9
fill ~255 ~39 ~27 ~256 ~39 ~27 stained_hardened_clay 9
fill ~256 ~39 ~26 ~257 ~39 ~26 coal_block 0
fill ~257 ~39 ~28 ~257 ~46 ~28 coal_block 0
fill ~258 ~39 ~29 ~258 ~41 ~29 bedrock 0
fill ~291 ~39 ~104 ~291 ~44 ~104 bedrock 0
fill ~297 ~39 ~78 ~297 ~41 ~78 coal_block 0
fill ~310 ~39 ~98 ~311 ~39 ~98 stained_hardened_clay 9
fill ~312 ~39 ~98 ~312 ~41 ~98 bedrock 0
fill ~312 ~39 ~99 ~312 ~39 ~98 bedrock 0
setblock ~313 ~39 ~98 stained_hardened_clay 9
fill ~317 ~39 ~82 ~317 ~39 ~83 stained_hardened_clay 9
fill ~318 ~39 ~84 ~318 ~42 ~84 stained_hardened_clay 9
fill ~202 ~40 ~20 ~216 ~40 ~20 stained_hardened_clay 9
fill ~202 ~40 ~80 ~216 ~40 ~80 stained_hardened_clay 9
fill ~204 ~40 ~22 ~205 ~40 ~22 stained_hardened_clay 9
fill ~204 ~40 ~78 ~205 ~40 ~78 stained_hardened_clay 9
fill ~207 ~40 ~18 ~208 ~40 ~18 stained_hardened_clay 9
fill ~207 ~40 ~19 ~216 ~40 ~19 stained_hardened_clay 9
fill ~207 ~40 ~81 ~216 ~40 ~81 stained_hardened_clay 9
fill ~207 ~40 ~82 ~208 ~40 ~82 stained_hardened_clay 9
fill ~208 ~40 ~22 ~213 ~40 ~22 stained_hardened_clay 9
fill ~208 ~40 ~78 ~213 ~40 ~78 stained_hardened_clay 9
fill ~209 ~40 ~17 ~210 ~40 ~17 stone 0
fill ~209 ~40 ~18 ~210 ~40 ~18 stone 0
fill ~209 ~40 ~82 ~210 ~40 ~82 stone 0
fill ~209 ~40 ~83 ~210 ~40 ~83 stone 0
fill ~211 ~40 ~17 ~213 ~40 ~17 stained_hardened_clay 9
fill ~211 ~40 ~18 ~215 ~40 ~18 stained_hardened_clay 9
fill ~211 ~40 ~82 ~215 ~40 ~82 stained_hardened_clay 9
fill ~211 ~40 ~83 ~213 ~40 ~83 stained_hardened_clay 9
fill ~215 ~40 ~21 ~215 ~50 ~21 stained_hardened_clay 9
fill ~215 ~40 ~79 ~215 ~50 ~79 stained_hardened_clay 9
fill ~250 ~40 ~27 ~253 ~40 ~27 stone 0
fill ~250 ~40 ~28 ~252 ~40 ~28 stone 0
fill ~250 ~40 ~29 ~251 ~40 ~29 stone 0
fill ~250 ~40 ~30 ~250 ~41 ~30 stone 0
fill ~251 ~40 ~30 ~257 ~40 ~30 stained_hardened_clay 9
fill ~252 ~40 ~25 ~252 ~43 ~25 stone 0
fill ~252 ~40 ~29 ~257 ~40 ~29 stained_hardened_clay 9
fill ~253 ~40 ~28 ~256 ~40 ~28 stained_hardened_clay 9
fill ~253 ~40 ~31 ~257 ~40 ~31 stained_hardened_clay 9
fill ~254 ~40 ~26 ~256 ~40 ~26 stained_hardened_clay 9
fill ~254 ~40 ~27 ~256 ~40 ~27 stained_hardened_clay 9
fill ~255 ~40 ~25 ~255 ~56 ~25 stained_hardened_clay 9
fill ~256 ~40 ~25 ~256 ~41 ~25 bedrock 0
fill ~257 ~40 ~26 ~257 ~41 ~26 coal_block 0
fill ~258 ~40 ~30 ~258 ~41 ~30 stone 0
fill ~297 ~40 ~79 ~297 ~43 ~79 coal_block 0
fill ~309 ~40 ~98 ~311 ~40 ~98 stained_hardened_clay 9
fill ~311 ~40 ~97 ~311 ~41 ~97 stained_hardened_clay 9
fill ~311 ~40 ~99 ~311 ~41 ~99 stained_hardened_clay 9
fill ~317 ~40 ~83 ~317 ~41 ~83 stained_hardened_clay 9
fill ~319 ~40 ~82 ~319 ~41 ~82 bedrock 0
fill ~202 ~41 ~20 ~202 ~43 ~20 coal_block 0
fill ~202 ~41 ~80 ~202 ~43 ~80 coal_block 0
fill ~203 ~41 ~20 ~217 ~41 ~20 stained_hardened_clay 9
setblock ~203 ~41 ~21 coal_block 0
setblock ~203 ~41 ~79 coal_block 0
fill ~203 ~41 ~80 ~217 ~41 ~80 stained_hardened_clay 9
fill ~207 ~41 ~19 ~217 ~41 ~19 stained_hardened_clay 9
fill ~207 ~41 ~81 ~217 ~41 ~81 stained_hardened_clay 9
setblock ~208 ~41 ~18 stained_hardened_clay 9
setblock ~208 ~41 ~82 stained_hardened_clay 9
fill ~209 ~41 ~18 ~211 ~41 ~18 stone 0
fill ~209 ~41 ~22 ~214 ~41 ~22 stained_hardened_clay 9
fill ~209 ~41 ~78 ~214 ~41 ~78 stained_hardened_clay 9
fill ~209 ~41 ~82 ~211 ~41 ~82 stone 0
fill ~210 ~41 ~17 ~211 ~41 ~17 stone 0
fill ~210 ~41 ~83 ~211 ~41 ~83 stone 0
fill ~212 ~41 ~17 ~214 ~41 ~17 stained_hardened_clay 9
fill ~212 ~41 ~18 ~216 ~41 ~18 stained_hardened_clay 9
fill ~212 ~41 ~82 ~216 ~41 ~82 stained_hardened_clay 9
fill ~212 ~41 ~83 ~214 ~41 ~83 stained_hardened_clay 9
fill ~216 ~41 ~21 ~216 ~51 ~21 stained_hardened_clay 9
fill ~216 ~41 ~79 ~216 ~51 ~79 stained_hardened_clay 9
fill ~250 ~41 ~27 ~253 ~41 ~27 stone 0
fill ~250 ~41 ~28 ~250 ~42 ~28 coal_block 0
fill ~250 ~41 ~29 ~251 ~41 ~29 stone 0
fill ~251 ~41 ~28 ~252 ~41 ~28 stone 0
fill ~251 ~41 ~30 ~257 ~41 ~30 stained_hardened_clay 9
fill ~251 ~41 ~31 ~251 ~44 ~31 stained_hardened_clay 9
fill ~252 ~41 ~29 ~256 ~41 ~29 stained_hardened_clay 9
fill ~253 ~41 ~25 ~253 ~52 ~25 stained_hardened_clay 9
fill ~253 ~41 ~26 ~256 ~41 ~26 stained_hardened_clay 9
fill ~253 ~41 ~28 ~256 ~41 ~28 stained_hardened_clay 9
fill ~253 ~41 ~31 ~257 ~41 ~31 stained_hardened_clay 9
fill ~254 ~41 ~27 ~256 ~41 ~27 stained_hardened_clay 9
setblock ~257 ~41 ~29 stone 0
fill ~296 ~41 ~78 ~296 ~42 ~78 coal_block 0
fill ~309 ~41 ~97 ~311 ~41 ~97 stained_hardened_clay 9
fill ~309 ~41 ~98 ~310 ~41 ~98 stained_hardened_clay 9
fill ~310 ~41 ~99 ~310 ~42 ~99 stained_hardened_clay 9
fill ~311 ~41 ~98 ~311 ~42 ~98 bedrock 0
fill ~316 ~41 ~83 ~316 ~42 ~83 stained_hardened_clay 9
fill ~317 ~41 ~82 ~317 ~42 ~82 stained_hardened_clay 9
fill ~317 ~41 ~84 ~317 ~42 ~84 stained_hardened_clay 9
fill ~318 ~41 ~82 ~318 ~41 ~83 bedrock 0
setblock ~319 ~41 ~83 stained_hardened_clay 9
fill ~201 ~42 ~20 ~201 ~43 ~20 coal_block 0
fill ~201 ~42 ~80 ~201 ~43 ~80 coal_block 0
setblock ~202 ~42 ~21 coal_block 0
setblock ~202 ~42 ~79 coal_block 0
fill ~204 ~42 ~20 ~205 ~42 ~20 stained_hardened_clay 9
fill ~204 ~42 ~80 ~205 ~42 ~80 stained_hardened_clay 9
fill ~208 ~42 ~19 ~218 ~42 ~19 stained_hardened_clay 9
fill ~208 ~42 ~20 ~218 ~42 ~20 stained_hardened_clay 9
fill ~208 ~42 ~80 ~218 ~42 ~80 stained_hardened_clay 9
fill ~208 ~42 ~81 ~218 ~42 ~81 stained_hardened_clay 9
fill ~209 ~42 ~18 ~212 ~42 ~18 stone 0
fill ~209 ~42 ~82 ~212 ~42 ~82 stone 0
fill ~210 ~42 ~22 ~215 ~42 ~22 stained_hardened_clay 9
fill ~210 ~42 ~78 ~215 ~42 ~78 stained_hardened_clay 9
fill ~211 ~42 ~17 ~216 ~42 ~17 stone 0
fill ~211 ~42 ~83 ~216 ~42 ~83 stone 0
fill ~213 ~42 ~18 ~217 ~42 ~18 stained_hardened_clay 9
fill ~213 ~42 ~82 ~217 ~42 ~82 stained_hardened_clay 9
fill ~217 ~42 ~21 ~217 ~52 ~21 stained_hardened_clay 9
fill ~217 ~42 ~79 ~217 ~52 ~79 stained_hardened_clay 9
fill ~250 ~42 ~27 ~250 ~45 ~27 coal_block 0
fill ~250 ~42 ~29 ~250 ~46 ~29 coal_block 0
fill ~250 ~42 ~30 ~257 ~42 ~30 stained_hardened_clay 9
fill ~251 ~42 ~27 ~253 ~42 ~27 stone 0
fill ~251 ~42 ~28 ~251 ~54 ~28 stained_hardened_clay 9
fill ~251 ~42 ~29 ~256 ~42 ~29 stained_hardened_clay 9
setblock ~252 ~42 ~28 stone 0
fill ~252 ~42 ~31 ~257 ~42 ~31 stained_hardened_clay 9
fill ~253 ~42 ~26 ~256 ~42 ~26 stained_hardened_clay 9
fill ~253 ~42 ~28 ~256 ~42 ~28 stained_hardened_clay 9
fill ~254 ~42 ~27 ~256 ~42 ~27 stained_hardened_clay 9
fill ~256 ~42 ~25 ~256 ~52 ~25 stained_hardened_clay 9
fill ~257 ~42 ~26 ~257 ~44 ~26 bedrock 0
fill ~257 ~42 ~29 ~257 ~45 ~29 coal_block 0
fill ~258 ~42 ~30 ~258 ~45 ~30 bedrock 0
fill ~290 ~42 ~103 ~292 ~42 ~103 bedrock 0
fill ~291 ~42 ~102 ~291 ~46 ~102 bedrock 0
fill ~296 ~42 ~79 ~296 ~43 ~79 coal_block 0
fill ~296 ~42 ~80 ~296 ~44 ~80 coal_block 0
fill ~307 ~42 ~97 ~309 ~42 ~97 bedrock 0
fill ~308 ~42 ~96 ~308 ~44 ~96 bedrock 0
fill ~308 ~42 ~98 ~308 ~44 ~98 bedrock 0
fill ~309 ~42 ~98 ~310 ~42 ~98 stained_hardened_clay 9
fill ~310 ~42 ~96 ~310 ~43 ~96 stained_hardened_clay 9
fill ~310 ~42 ~97 ~310 ~42 ~96 stained_hardened_clay 9
fill ~311 ~42 ~97 ~311 ~43 ~97 bedrock 0
setblock ~316 ~42 ~84 stained_hardened_clay 9
fill ~317 ~42 ~83 ~318 ~42 ~83 bedrock 0
setblock ~317 ~42 ~85 stained_hardened_clay 9
fill ~201 ~43 ~21 ~201 ~45 ~21 coal_block 0
fill ~201 ~43 ~79 ~201 ~45 ~79 coal_block 0
setblock ~208 ~43 ~19 stone 0
fill ~208 ~43 ~20 ~219 ~43 ~20 stained_hardened_clay 9
fill ~208 ~43 ~80 ~219 ~43 ~80 stained_hardened_clay 9
setblock ~208 ~43 ~81 stone 0
fill ~209 ~43 ~19 ~219 ~43 ~19 stained_hardened_clay 9
fill ~209 ~43 ~81 ~219 ~43 ~81 stained_hardened_clay 9
fill ~210 ~43 ~18 ~215 ~43 ~18 stone 0
fill ~210 ~43 ~82 ~215 ~43 ~82 stone 0
fill ~211 ~43 ~22 ~216 ~43 ~22 stained_hardened_clay 9
fill ~211 ~43 ~78 ~216 ~43 ~78 stained_hardened_clay 9
fill ~212 ~43 ~17 ~217 ~43 ~17 stone 0
fill ~212 ~43 ~83 ~217 ~43 ~83 stone 0
fill ~216 ~43 ~18 ~218 ~43 ~18 stained_hardened_clay 9
fill ~216 ~43 ~82 ~218 ~43 ~82 stained_hardened_clay 9
fill ~218 ~43 ~21 ~218 ~51 ~21 stained_hardened_clay 9
fill ~218 ~43 ~79 ~218 ~51 ~79 stained_hardened_clay 9
fill ~249 ~43 ~28 ~249 ~57 ~28 bedrock 0
fill ~250 ~43 ~28 ~250 ~48 ~28 stained_hardened_clay 9
fill ~251 ~43 ~27 ~252 ~43 ~27 stained_hardened_clay 9
fill ~251 ~43 ~29 ~256 ~43 ~29 stained_hardened_clay 9
fill ~251 ~43 ~30 ~256 ~43 ~30 stained_hardened_clay 9
fill ~252 ~43 ~28 ~256 ~43 ~28 stained_hardened_clay 9
fill ~252 ~43 ~31 ~256 ~43 ~31 stained_hardened_clay 9
fill ~253 ~43 ~26 ~256 ~43 ~26 stained_hardened_clay 9
fill ~254 ~43 ~24 ~255 ~43 ~24 stained_hardened_clay 9
fill ~254 ~43 ~27 ~256 ~43 ~27 stained_hardened_clay 9
fill ~257 ~43 ~30 ~257 ~53 ~30 stone 0
fill ~257 ~43 ~31 ~257 ~53 ~31 stone 0
fill ~290 ~43 ~102 ~290 ~43 ~104 bedrock 0
fill ~291 ~43 ~101 ~291 ~45 ~101 stained_hardened_clay 9
fill ~291 ~43 ~103 ~292 ~43 ~103 bedrock 0
setblock ~292 ~43 ~102 bedrock 0
setblock ~292 ~43 ~104 bedrock 0
fill ~295 ~43 ~79 ~295 ~44 ~79 coal_block 0
fill ~295 ~43 ~80 ~295 ~44 ~80 stained_hardened_clay 9
fill ~307 ~43 ~96 ~307 ~43 ~98 bedrock 0
fill ~308 ~43 ~97 ~311 ~43 ~97 bedrock 0
fill ~309 ~43 ~96 ~309 ~45 ~96 bedrock 0
fill ~309 ~43 ~98 ~309 ~45 ~98 bedrock 0
setblock ~310 ~43 ~98 stained_hardened_clay 9
fill ~315 ~43 ~84 ~317 ~43 ~84 bedrock 0
fill ~316 ~43 ~83 ~317 ~43 ~83 bedrock 0
fill ~316 ~43 ~85 ~316 ~45 ~85 bedrock 0
fill ~209 ~44 ~20 ~220 ~44 ~20 stained_hardened_clay 9
fill ~209 ~44 ~80 ~220 ~44 ~80 stained_hardened_clay 9
setblock ~210 ~44 ~19 stone 0
setblock ~210 ~44 ~81 stone 0
fill ~211 ~44 ~18 ~215 ~44 ~18 stone 0
fill ~211 ~44 ~19 ~219 ~44 ~19 stained_hardened_clay 9
fill ~211 ~44 ~22 ~217 ~44 ~22 stained_hardened_clay 9
fill ~211 ~44 ~78 ~217 ~44 ~78 stained_hardened_clay 9
fill ~211 ~44 ~81 ~219 ~44 ~81 stained_hardened_clay 9
fill ~211 ~44 ~82 ~215 ~44 ~82 stone 0
fill ~213 ~44 ~17 ~217 ~44 ~17 stone 0
fill ~213 ~44 ~83 ~217 ~44 ~83 stone 0
fill ~216 ~44 ~18 ~218 ~44 ~18 stained_hardened_clay 9
fill ~216 ~44 ~82 ~218 ~44 ~82 stained_hardened_clay 9
fill ~219 ~44 ~18 ~219 ~45 ~18 stone 0
fill ~219 ~44 ~21 ~219 ~51 ~21 stained_hardened_clay 9
fill ~219 ~44 ~79 ~219 ~51 ~79 stained_hardened_clay 9
fill ~219 ~44 ~82 ~219 ~45 ~82 stone 0
fill ~220 ~44 ~19 ~220 ~45 ~19 stone 0
fill ~220 ~44 ~81 ~220 ~45 ~81 stone 0
fill ~251 ~44 ~26 ~251 ~44 ~31 stained_hardened_clay 9
fill ~252 ~44 ~25 ~252 ~49 ~25 stained_hardened_clay 9
fill ~252 ~44 ~27 ~256 ~44 ~27 stained_hardened_clay 9
fill ~252 ~44 ~28 ~254 ~44 ~28 stained_hardened_clay 9
fill ~252 ~44 ~29 ~255 ~44 ~29 stained_hardened_clay 9
fill ~252 ~44 ~30 ~256 ~44 ~30 stained_hardened_clay 9
fill ~252 ~44 ~31 ~256 ~44 ~31 stained_hardened_clay 9
fill ~253 ~44 ~26 ~256 ~44 ~26 stained_hardened_clay 9
fill ~254 ~44 ~24 ~255 ~44 ~24 stained_hardened_clay 9
fill ~255 ~44 ~28 ~256 ~44 ~28 stone 0
setblock ~256 ~44 ~29 stone 0
fill ~290 ~44 ~101 ~290 ~46 ~101 stained_hardened_clay 9
fill ~290 ~44 ~102 ~290 ~45 ~102 stained_hardened_clay 9
fill ~290 ~44 ~103 ~292 ~44 ~103 bedrock 0
fill ~291 ~44 ~100 ~291 ~47 ~100 stained_hardened_clay 9
fill ~292 ~44 ~101 ~292 ~46 ~101 stained_hardened_clay 9
fill ~292 ~44 ~102 ~292 ~45 ~102 stained_hardened_clay 9
fill ~294 ~44 ~80 ~294 ~46 ~80 stained_hardened_clay 9
fill ~294 ~44 ~81 ~296 ~44 ~81 stained_hardened_clay 9
fill ~296 ~44 ~79 ~296 ~45 ~79 bedrock 0
fill ~305 ~44 ~96 ~307 ~44 ~96 stained_hardened_clay 9
fill ~305 ~44 ~97 ~306 ~44 ~97 stained_hardened_clay 9
fill ~307 ~44 ~97 ~310 ~44 ~97 bedrock 0
fill ~307 ~44 ~98 ~307 ~45 ~98 stained_hardened_clay 9
setblock ~310 ~44 ~96 bedrock 0
setblock ~310 ~44 ~98 bedrock 0
fill ~314 ~44 ~84 ~314 ~47 ~84 stained_hardened_clay 9
fill ~315 ~44 ~83 ~317 ~44 ~83 bedrock 0
fill ~315 ~44 ~84 ~317 ~44 ~84 bedrock 0
fill ~315 ~44 ~85 ~315 ~44 ~83 bedrock 0
setblock ~317 ~44 ~85 bedrock 0
fill ~210 ~45 ~20 ~221 ~45 ~20 stained_hardened_clay 9
fill ~210 ~45 ~80 ~221 ~45 ~80 stained_hardened_clay 9
setblock ~211 ~45 ~19 stone 0
setblock ~211 ~45 ~81 stone 0
fill ~212 ~45 ~18 ~220 ~45 ~18 stone 0
fill ~212 ~45 ~19 ~219 ~45 ~19 stained_hardened_clay 9
fill ~212 ~45 ~22 ~218 ~45 ~22 stained_hardened_clay 9
fill ~212 ~45 ~78 ~218 ~45 ~78 stained_hardened_clay 9
fill ~212 ~45 ~81 ~219 ~45 ~81 stained_hardened_clay 9
fill ~212 ~45 ~82 ~220 ~45 ~82 stone 0
fill ~214 ~45 ~17 ~217 ~45 ~17 stone 0
fill ~214 ~45 ~83 ~217 ~45 ~83 stone 0
fill ~218 ~45 ~17 ~219 ~45 ~17 bedrock 0
fill ~218 ~45 ~83 ~219 ~45 ~83 bedrock 0
fill ~220 ~45 ~21 ~220 ~52 ~21 stained_hardened_clay 9
fill ~220 ~45 ~79 ~220 ~52 ~79 stained_hardened_clay 9
setblock ~221 ~45 ~19 stone 0
setblock ~221 ~45 ~81 stone 0
fill ~251 ~45 ~26 ~251 ~49 ~26 coal_block 0
fill ~251 ~45 ~27 ~256 ~45 ~27 stained_hardened_clay 9
fill ~251 ~45 ~29 ~255 ~45 ~29 stained_hardened_clay 9
fill ~251 ~45 ~30 ~256 ~45 ~30 stained_hardened_clay 9
fill ~252 ~45 ~28 ~254 ~45 ~28 stained_hardened_clay 9
fill ~252 ~45 ~31 ~256 ~45 ~31 stained_hardened_clay 9
fill ~253 ~45 ~26 ~257 ~45 ~26 stained_hardened_clay 9
fill ~254 ~45 ~24 ~255 ~45 ~24 stained_hardened_clay 9
fill ~255 ~45 ~28 ~256 ~45 ~28 stone 0
setblock ~256 ~45 ~29 coal_block 0
fill ~257 ~45 ~27 ~257 ~53 ~27 stone 0
fill ~258 ~45 ~27 ~258 ~46 ~27 bedrock 0
fill ~290 ~45 ~99 ~291 ~45 ~99 stained_hardened_clay 9
fill ~290 ~45 ~100 ~290 ~46 ~100 stained_hardened_clay 9
setblock ~291 ~45 ~103 bedrock 0
fill ~292 ~45 ~100 ~292 ~46 ~100 stained_hardened_clay 9
fill ~293 ~45 ~81 ~296 ~45 ~81 stained_hardened_clay 9
fill ~294 ~45 ~82 ~295 ~45 ~82 stained_hardened_clay 9
setblock ~295 ~45 ~79 stained_hardened_clay 9
fill ~295 ~45 ~80 ~296 ~45 ~80 bedrock 0
fill ~302 ~45 ~96 ~307 ~45 ~96 stained_hardened_clay 9
fill ~304 ~45 ~97 ~306 ~45 ~97 stained_hardened_clay 9
fill ~305 ~45 ~95 ~306 ~45 ~95 stained_hardened_clay 9
setblock ~306 ~45 ~98 stained_hardened_clay 9
fill ~307 ~45 ~97 ~310 ~45 ~97 bedrock 0
fill ~314 ~45 ~85 ~315 ~45 ~85 stained_hardened_clay 9
setblock ~315 ~45 ~83 stained_hardened_clay 9
fill ~315 ~45 ~84 ~317 ~45 ~84 bedrock 0
fill ~315 ~45 ~86 ~315 ~46 ~86 stained_hardened_clay 9
setblock ~316 ~45 ~83 bedrock 0
fill ~211 ~46 ~20 ~222 ~46 ~20 stained_hardened_clay 9
fill ~211 ~46 ~80 ~222 ~46 ~80 stained_hardened_clay 9
setblock ~212 ~46 ~19 stone 0
setblock ~212 ~46 ~81 stone 0
fill ~213 ~46 ~18 ~217 ~46 ~18 stone 0
fill ~213 ~46 ~19 ~215 ~46 ~19 stained_hardened_clay 9
fill ~213 ~46 ~22 ~219 ~46 ~22 stained_hardened_clay 9
fill ~213 ~46 ~78 ~219 ~46 ~78 stained_hardened_clay 9
fill ~213 ~46 ~81 ~215 ~46 ~81 stained_hardened_clay 9
fill ~213 ~46 ~82 ~217 ~46 ~82 stone 0
fill ~215 ~46 ~17 ~216 ~46 ~17 stone 0
fill ~215 ~46 ~83 ~216 ~46 ~83 stone 0
setblock ~216 ~46 ~19 stone 0
setblock ~216 ~46 ~81 stone 0
fill ~217 ~46 ~17 ~217 ~48 ~17 bedrock 0
fill ~217 ~46 ~19 ~221 ~46 ~19 stained_hardened_clay 9
fill ~217 ~46 ~81 ~221 ~46 ~81 stained_hardened_clay 9
fill ~217 ~46 ~83 ~217 ~48 ~83 bedrock 0
fill ~218 ~46 ~18 ~219 ~46 ~18 coal_block 0
fill ~218 ~46 ~82 ~219 ~46 ~82 coal_block 0
setblock ~220 ~46 ~17 bedrock 0
setblock ~220 ~46 ~18 stone 0
setblock ~220 ~46 ~82 stone 0
setblock ~220 ~46 ~83 bedrock 0
setblock ~221 ~46 ~18 bedrock 0
fill ~221 ~46 ~21 ~221 ~53 ~21 stained_hardened_clay 9
fill ~221 ~46 ~79 ~221 ~53 ~79 stained_hardened_clay 9
setblock ~221 ~46 ~82 bedrock 0
fill ~222 ~46 ~18 ~222 ~46 ~19 stone 0
fill ~222 ~46 ~81 ~222 ~46 ~82 stone 0
fill ~250 ~46 ~27 ~250 ~49 ~27 bedrock 0
fill ~251 ~46 ~27 ~256 ~46 ~27 stained_hardened_clay 9
fill ~251 ~46 ~29 ~255 ~46 ~29 stained_hardened_clay 9
fill ~251 ~46 ~30 ~251 ~49 ~30 coal_block 0
fill ~252 ~46 ~28 ~254 ~46 ~28 stained_hardened_clay 9
fill ~252 ~46 ~30 ~255 ~46 ~30 stained_hardened_clay 9
fill ~252 ~46 ~31 ~255 ~46 ~31 stained_hardened_clay 9
fill ~253 ~46 ~26 ~257 ~46 ~26 stained_hardened_clay 9
fill ~254 ~46 ~24 ~255 ~46 ~24 stained_hardened_clay 9
fill ~255 ~46 ~28 ~256 ~46 ~28 stone 0
fill ~256 ~46 ~29 ~257 ~46 ~29 stone 0
fill ~256 ~46 ~30 ~256 ~57 ~30 stone 0
fill ~256 ~46 ~31 ~256 ~54 ~31 stone 0
setblock ~258 ~46 ~29 bedrock 0
fill ~258 ~46 ~30 ~258 ~53 ~30 stone 0
fill ~289 ~46 ~99 ~291 ~46 ~99 stained_hardened_clay 9
fill ~290 ~46 ~98 ~290 ~48 ~98 stained_hardened_clay 9
fill ~291 ~46 ~101 ~291 ~47 ~101 bedrock 0
fill ~292 ~46 ~83 ~294 ~46 ~83 bedrock 0
fill ~293 ~46 ~81 ~294 ~46 ~81 stained_hardened_clay 9
fill ~293 ~46 ~82 ~293 ~49 ~82 bedrock 0
fill ~293 ~46 ~84 ~293 ~49 ~84 bedrock 0
setblock ~293 ~46 ~100 stained_hardened_clay 9
fill ~294 ~46 ~82 ~295 ~46 ~82 stained_hardened_clay 9
fill ~295 ~46 ~80 ~295 ~45 ~80 bedrock 0
fill ~295 ~46 ~81 ~295 ~47 ~81 bedrock 0
fill ~300 ~46 ~95 ~300 ~47 ~95 stained_hardened_clay 9
fill ~300 ~46 ~96 ~304 ~46 ~96 stained_hardened_clay 9
fill ~303 ~46 ~95 ~305 ~46 ~95 stained_hardened_clay 9
fill ~303 ~46 ~97 ~305 ~46 ~97 stained_hardened_clay 9
fill ~305 ~46 ~96 ~306 ~46 ~96 bedrock 0
fill ~306 ~46 ~97 ~307 ~46 ~97 bedrock 0
fill ~313 ~46 ~85 ~314 ~46 ~85 stained_hardened_clay 9
fill ~313 ~46 ~86 ~315 ~46 ~86 stained_hardened_clay 9
fill ~315 ~46 ~84 ~316 ~46 ~84 bedrock 0
fill ~315 ~46 ~85 ~315 ~47 ~85 bedrock 0
setblock ~316 ~46 ~85 stained_hardened_clay 9
fill ~212 ~47 ~20 ~224 ~47 ~20 stained_hardened_clay 9
fill ~212 ~47 ~80 ~224 ~47 ~80 stained_hardened_clay 9
fill ~213 ~47 ~19 ~223 ~47 ~19 stained_hardened_clay 9
fill ~213 ~47 ~22 ~221 ~47 ~22 stained_hardened_clay 9
fill ~213 ~47 ~78 ~221 ~47 ~78 stained_hardened_clay 9
fill ~213 ~47 ~81 ~223 ~47 ~81 stained_hardened_clay 9
setblock ~214 ~47 ~18 stone 0
