fill ~28~33~24 ~37~33~28 minecraft:obsidian
fill ~28~34~24 ~28~36~35 minecraft:obsidian
fill ~29~36~24 ~37~36~29 minecraft:obsidian
fill ~32~34~24 ~32~35~35 minecraft:obsidian
fill ~37~34~24 ~37~35~34 minecraft:obsidian
fill ~48~33~24 ~57~33~28 minecraft:obsidian
fill ~48~34~24 ~48~36~34 minecraft:obsidian
fill ~49~36~24 ~57~36~29 minecraft:obsidian
fill ~53~34~24 ~53~35~35 minecraft:obsidian
fill ~57~34~24 ~57~35~35 minecraft:obsidian
fill ~28~37~25 ~28~39~35 minecraft:obsidian
fill ~29~39~25 ~37~39~35 minecraft:obsidian
fill ~32~37~25 ~32~38~35 minecraft:obsidian
fill ~37~37~25 ~37~38~35 minecraft:obsidian
fill ~48~37~25 ~48~39~35 minecraft:obsidian
fill ~49~39~25 ~57~39~35 minecraft:obsidian
fill ~53~37~25 ~53~38~35 minecraft:obsidian
fill ~57~37~25 ~57~38~35 minecraft:obsidian
fill ~21~26~26 ~64~27~26 minecraft:wool 15
fill ~25~28~26 ~60~28~26 minecraft:concrete ["color":"silver"]
fill ~28~32~26 ~37~32~27 minecraft:obsidian
fill ~28~40~26 ~28~41~35 minecraft:obsidian
fill ~28~42~26 ~37~42~34 minecraft:obsidian
fill ~32~40~26 ~32~41~35 minecraft:obsidian
fill ~34~25~26 ~51~25~27 minecraft:wool 15
fill ~37~40~26 ~37~41~35 minecraft:obsidian
fill ~48~32~26 ~57~32~27 minecraft:obsidian
fill ~48~40~26 ~48~41~35 minecraft:obsidian
fill ~48~42~26 ~57~42~34 minecraft:obsidian
fill ~53~40~26 ~53~41~35 minecraft:obsidian
fill ~57~40~26 ~57~41~35 minecraft:obsidian
fill ~19~25~27 ~33~25~27 minecraft:wool 15
fill ~19~26~27 ~32~26~27 minecraft:wool 15
fill ~19~27~27 ~28~27~27 minecraft:wool 15
fill ~19~28~27 ~36~28~27 minecraft:concrete ["color":"silver"]
fill ~20~24~27 ~65~24~27 minecraft:wool 15
fill ~20~29~27 ~21~30~28 minecraft:concrete ["color":"silver"]
fill ~21~31~27 ~21~31~30 minecraft:concrete ["color":"silver"]
fill ~22~32~27 ~22~32~28 minecraft:concrete ["color":"silver"]
fill ~23~33~27 ~23~33~28 minecraft:concrete ["color":"silver"]
fill ~24~21~27 ~24~21~28 minecraft:nether_brick_stairs ["upside_down_bit":true,"weirdo_direction":0]
fill ~24~22~27 ~24~22~28 minecraft:nether_brick
setblock ~24~23~27 minecraft:nether_brick_stairs ["upside_down_bit":false,"weirdo_direction":0]
fill ~24~34~27 ~24~34~28 minecraft:concrete ["color":"silver"]
fill ~25~21~27 ~25~21~29 minecraft:nether_brick
setblock ~25~23~27 minecraft:nether_brick
fill ~25~35~27 ~27~35~30 minecraft:concrete ["color":"silver"]
fill ~26~21~27 ~26~21~28 minecraft:nether_brick_stairs ["upside_down_bit":true,"weirdo_direction":1]
fill ~26~22~27 ~26~22~28 minecraft:nether_brick
setblock ~26~23~27 minecraft:nether_brick_stairs ["upside_down_bit":false,"weirdo_direction":1]
fill ~28~43~27 ~28~43~32 minecraft:obsidian
fill ~28~44~27 ~28~44~30 minecraft:obsidian
fill ~28~45~27 ~37~45~28 minecraft:obsidian
fill ~29~35~27 ~31~35~34 minecraft:obsidian
fill ~32~43~27 ~32~43~32 minecraft:obsidian
fill ~32~44~27 ~32~44~30 minecraft:obsidian
fill ~33~35~27 ~36~35~30 minecraft:obsidian
fill ~37~28~27 ~48~28~27 minecraft:stone ["stone_type":"stone"]
fill ~37~29~27 ~48~29~27 minecraft:concrete 15
fill ~37~30~27 ~38~30~28 minecraft:concrete 15
fill ~37~43~27 ~37~43~32 minecraft:obsidian
fill ~37~44~27 ~37~44~30 minecraft:obsidian
fill ~38~35~27 ~47~35~27 minecraft:concrete ["color":"silver"]
fill ~39~30~27 ~46~30~27 minecraft:concrete ["color":"white"]
fill ~39~31~27 ~40~31~27 minecraft:concrete ["color":"white"]
fill ~39~32~27 ~39~33~27 minecraft:concrete ["color":"white"]
fill ~40~32~27 ~42~32~27 minecraft:concrete ["color":"light_blue"]
setblock ~40~33~27 minecraft:concrete ["color":"white"]
setblock ~41~31~27 minecraft:concrete ["color":"light_blue"]
fill ~41~33~27 ~44~33~27 minecraft:concrete ["color":"orange"]
setblock ~42~31~27 minecraft:concrete ["color":"white"]
fill ~43~31~27 ~44~31~27 minecraft:concrete ["color":"light_blue"]
fill ~43~32~27 ~44~32~27 minecraft:concrete ["color":"white"]
fill ~45~31~27 ~46~31~27 minecraft:concrete ["color":"white"]
setblock ~45~32~27 minecraft:concrete ["color":"light_blue"]
fill ~45~33~27 ~46~33~27 minecraft:concrete ["color":"white"]
setblock ~46~32~27 minecraft:concrete ["color":"white"]
fill ~47~30~27 ~48~30~28 minecraft:concrete 15
fill ~48~43~27 ~48~43~32 minecraft:obsidian
fill ~48~44~27 ~48~44~30 minecraft:obsidian
fill ~48~45~27 ~57~45~28 minecraft:obsidian
fill ~49~28~27 ~66~28~27 minecraft:concrete ["color":"silver"]
fill ~49~35~27 ~52~35~30 minecraft:obsidian
fill ~52~25~27 ~66~25~27 minecraft:wool 15
fill ~53~26~27 ~66~26~27 minecraft:wool 15
fill ~53~43~27 ~53~43~32 minecraft:obsidian
fill ~53~44~27 ~53~44~30 minecraft:obsidian
fill ~54~35~27 ~56~35~34 minecraft:obsidian
fill ~57~27~27 ~66~27~27 minecraft:wool 15
fill ~57~43~27 ~57~43~32 minecraft:obsidian
fill ~57~44~27 ~57~44~30 minecraft:obsidian
fill ~58~35~27 ~60~35~30 minecraft:concrete ["color":"silver"]
fill ~59~21~27 ~59~21~28 minecraft:nether_brick_stairs ["upside_down_bit":true,"weirdo_direction":0]
fill ~59~22~27 ~59~22~28 minecraft:nether_brick
setblock ~59~23~27 minecraft:nether_brick_stairs ["upside_down_bit":false,"weirdo_direction":0]
fill ~60~21~27 ~60~21~29 minecraft:nether_brick
setblock ~60~23~27 minecraft:nether_brick
fill ~61~21~27 ~61~21~28 minecraft:nether_brick_stairs ["upside_down_bit":true,"weirdo_direction":1]
fill ~61~22~27 ~61~22~28 minecraft:nether_brick
setblock ~61~23~27 minecraft:nether_brick_stairs ["upside_down_bit":false,"weirdo_direction":1]
fill ~61~34~27 ~61~34~28 minecraft:concrete ["color":"silver"]
fill ~62~33~27 ~62~33~28 minecraft:concrete ["color":"silver"]
fill ~63~32~27 ~63~32~28 minecraft:concrete ["color":"silver"]
fill ~64~29~27 ~65~30~28 minecraft:concrete ["color":"silver"]
fill ~64~31~27 ~64~31~30 minecraft:concrete ["color":"silver"]
fill ~19~24~28 ~19~26~29 minecraft:wool 15
setblock ~19~27~28 minecraft:wool 15
fill ~19~28~28 ~19~28~30 minecraft:concrete ["color":"silver"]
fill ~20~23~28 ~23~24~28 minecraft:stone ["stone_type":"stone"]
setblock ~20~28~28 minecraft:stone ["stone_type":"stone"]
fill ~21~22~28 ~23~22~29 minecraft:stone ["stone_type":"stone"]
fill ~21~32~28 ~21~32~30 minecraft:concrete ["color":"silver"]
fill ~22~28~28 ~36~28~28 minecraft:concrete ["color":"silver"]
fill ~22~29~28 ~23~29~28 minecraft:stained_glass 15
fill ~22~30~28 ~23~30~28 minecraft:stained_glass ["color":"gray"]
fill ~22~31~28 ~23~31~28 minecraft:stained_glass 15
fill ~22~33~28 ~22~33~30 minecraft:concrete ["color":"silver"]
setblock ~23~32~28 minecraft:stained_glass ["color":"gray"]
fill ~23~34~28 ~23~34~30 minecraft:concrete ["color":"silver"]
setblock ~24~23~28 minecraft:nether_brick
fill ~24~24~28 ~65~24~28 minecraft:stone ["stone_type":"stone"]
fill ~24~29~28 ~25~29~28 minecraft:stained_glass ["color":"gray"]
fill ~24~30~28 ~25~30~28 minecraft:stained_glass 15
fill ~24~31~28 ~25~31~28 minecraft:stained_glass ["color":"gray"]
fill ~24~32~28 ~25~32~28 minecraft:stained_glass 15
fill ~24~33~28 ~25~33~28 minecraft:stained_glass ["color":"gray"]
fill ~24~35~28 ~24~35~30 minecraft:concrete ["color":"silver"]
setblock ~25~22~28 minecraft:coal_block
fill ~25~23~28 ~25~23~32 minecraft:stone ["stone_type":"stone"]
setblock ~25~34~28 minecraft:stained_glass 15
setblock ~26~23~28 minecraft:nether_brick
fill ~26~29~28 ~27~29~28 minecraft:stained_glass 15
fill ~26~30~28 ~27~30~28 minecraft:stained_glass ["color":"gray"]
fill ~26~31~28 ~27~31~28 minecraft:stained_glass 15
fill ~26~32~28 ~27~32~28 minecraft:stained_glass ["color":"gray"]
fill ~26~33~28 ~27~33~28 minecraft:stained_glass 15
fill ~26~34~28 ~27~34~28 minecraft:stained_glass ["color":"gray"]
fill ~27~23~28 ~58~23~28 minecraft:stone ["stone_type":"stone"]
fill ~28~29~28 ~29~29~28 minecraft:stained_glass ["color":"gray"]
fill ~28~30~28 ~29~30~28 minecraft:stained_glass 15
fill ~28~31~28 ~29~31~28 minecraft:stained_glass ["color":"gray"]
fill ~28~32~28 ~36~32~28 minecraft:obsidian
fill ~30~29~28 ~31~29~28 minecraft:stained_glass 15
fill ~30~30~28 ~31~30~28 minecraft:stained_glass ["color":"gray"]
fill ~30~31~28 ~31~31~28 minecraft:stained_glass 15
fill ~32~29~28 ~33~29~28 minecraft:stained_glass ["color":"gray"]
fill ~32~30~28 ~33~30~28 minecraft:stained_glass 15
fill ~32~31~28 ~33~31~28 minecraft:stained_glass ["color":"gray"]
fill ~34~29~28 ~35~29~28 minecraft:stained_glass 15
fill ~34~30~28 ~35~30~28 minecraft:stained_glass ["color":"gray"]
fill ~34~31~28 ~35~31~28 minecraft:stained_glass 15
fill ~35~22~28 ~50~22~28 minecraft:wool 15
setblock ~36~29~28 minecraft:stained_glass ["color":"gray"]
setblock ~36~30~28 minecraft:stained_glass 15
setblock ~36~31~28 minecraft:stained_glass ["color":"gray"]
fill ~37~21~28 ~39~21~29 minecraft:wool 15
setblock ~37~29~28 minecraft:concrete 15
fill ~37~31~28 ~48~31~28 minecraft:concrete 15
fill ~37~32~28 ~37~32~32 minecraft:stone ["stone_type":"stone"]
fill ~38~32~28 ~47~34~28 minecraft:concrete 15
fill ~38~35~28 ~47~35~30 minecraft:stone ["stone_type":"stone"]
fill ~38~36~28 ~47~36~28 minecraft:concrete ["color":"silver"]
fill ~39~30~28 ~46~30~28 minecraft:concrete 15
fill ~46~21~28 ~48~21~29 minecraft:wool 15
setblock ~48~29~28 minecraft:concrete 15
fill ~48~32~28 ~48~32~32 minecraft:stone ["stone_type":"stone"]
fill ~49~28~28 ~63~28~28 minecraft:concrete ["color":"silver"]
setblock ~49~29~28 minecraft:stained_glass ["color":"gray"]
setblock ~49~30~28 minecraft:stained_glass 15
setblock ~49~31~28 minecraft:stained_glass ["color":"gray"]
fill ~49~32~28 ~57~32~28 minecraft:obsidian
fill ~50~29~28 ~51~29~28 minecraft:stained_glass 15
fill ~50~30~28 ~51~30~28 minecraft:stained_glass ["color":"gray"]
fill ~50~31~28 ~51~31~28 minecraft:stained_glass 15
fill ~52~29~28 ~53~29~28 minecraft:stained_glass ["color":"gray"]
fill ~52~30~28 ~53~30~28 minecraft:stained_glass 15
fill ~52~31~28 ~53~31~28 minecraft:stained_glass ["color":"gray"]
fill ~54~29~28 ~55~29~28 minecraft:stained_glass 15
fill ~54~30~28 ~55~30~28 minecraft:stained_glass ["color":"gray"]
fill ~54~31~28 ~55~31~28 minecraft:stained_glass 15
fill ~56~29~28 ~57~29~28 minecraft:stained_glass ["color":"gray"]
fill ~56~30~28 ~57~30~28 minecraft:stained_glass 15
fill ~56~31~28 ~57~31~28 minecraft:stained_glass ["color":"gray"]
fill ~58~29~28 ~59~29~28 minecraft:stained_glass 15
fill ~58~30~28 ~59~30~28 minecraft:stained_glass ["color":"gray"]
fill ~58~31~28 ~59~31~28 minecraft:stained_glass 15
fill ~58~32~28 ~59~32~28 minecraft:stained_glass ["color":"gray"]
fill ~58~33~28 ~59~33~28 minecraft:stained_glass 15
fill ~58~34~28 ~59~34~28 minecraft:stained_glass ["color":"gray"]
setblock ~59~23~28 minecraft:nether_brick
setblock ~60~22~28 minecraft:coal_block
fill ~60~23~28 ~60~23~32 minecraft:stone ["stone_type":"stone"]
fill ~60~29~28 ~61~29~28 minecraft:stained_glass ["color":"gray"]
fill ~60~30~28 ~61~30~28 minecraft:stained_glass 15
fill ~60~31~28 ~61~31~28 minecraft:stained_glass ["color":"gray"]
fill ~60~32~28 ~61~32~28 minecraft:stained_glass 15
fill ~60~33~28 ~61~33~28 minecraft:stained_glass ["color":"gray"]
setblock ~60~34~28 minecraft:stained_glass 15
setblock ~61~23~28 minecraft:nether_brick
fill ~61~35~28 ~61~35~30 minecraft:concrete ["color":"silver"]
fill ~62~22~28 ~64~22~29 minecraft:stone ["stone_type":"stone"]
fill ~62~23~28 ~65~23~28 minecraft:stone ["stone_type":"stone"]
fill ~62~29~28 ~63~29~28 minecraft:stained_glass 15
fill ~62~30~28 ~63~30~28 minecraft:stained_glass ["color":"gray"]
fill ~62~31~28 ~63~31~28 minecraft:stained_glass 15
setblock ~62~32~28 minecraft:stained_glass ["color":"gray"]
fill ~62~34~28 ~62~34~30 minecraft:concrete ["color":"silver"]
fill ~63~33~28 ~63~33~30 minecraft:concrete ["color":"silver"]
fill ~64~32~28 ~64~32~30 minecraft:concrete ["color":"silver"]
fill ~65~27~28 ~66~27~28 minecraft:wool 15
setblock ~65~28~28 minecraft:stone ["stone_type":"stone"]
fill ~66~24~28 ~66~26~29 minecraft:wool 15
fill ~66~28~28 ~66~28~30 minecraft:concrete ["color":"silver"]
setblock ~19~27~29 minecraft:obsidian
fill ~19~29~29 ~19~29~30 minecraft:concrete ["color":"silver"]
fill ~20~22~29 ~20~22~32 minecraft:stone ["stone_type":"stone"]
fill ~20~23~29 ~20~23~31 minecraft:stone ["stone_type":"stone"]
setblock ~20~24~29 minecraft:stone ["stone_type":"stone"]
fill ~20~29~29 ~20~29~32 minecraft:stone ["stone_type":"stone"]
fill ~20~30~29 ~20~30~30 minecraft:concrete ["color":"silver"]
setblock ~21~30~29 minecraft:stone ["stone_type":"stone"]
fill ~22~29~29 ~25~31~29 minecraft:stained_hardened_clay ["color":"orange"]
fill ~22~32~29 ~22~32~31 minecraft:stone ["stone_type":"stone"]
fill ~23~21~29 ~23~21~31 minecraft:stone ["stone_type":"stone"]
fill ~23~32~29 ~25~32~29 minecraft:stained_hardened_clay ["color":"orange"]
setblock ~23~33~29 minecraft:stone ["stone_type":"stone"]
setblock ~24~21~29 minecraft:nether_brick
fill ~24~22~29 ~61~22~29 minecraft:stone ["stone_type":"stone"]
fill ~24~23~29 ~24~23~32 minecraft:stone ["stone_type":"stone"]
fill ~24~33~29 ~25~33~29 minecraft:stained_hardened_clay ["color":"orange"]
setblock ~24~34~29 minecraft:stone ["stone_type":"stone"]
setblock ~25~24~29 minecraft:stone ["stone_type":"stone"]
setblock ~25~34~29 minecraft:stained_hardened_clay ["color":"orange"]
setblock ~26~21~29 minecraft:nether_brick
fill ~26~23~29 ~31~23~29 minecraft:stone ["stone_type":"stone"]
fill ~26~29~29 ~33~31~29 minecraft:stained_hardened_clay ["color":"red"]
fill ~26~32~29 ~27~34~29 minecraft:stained_hardened_clay ["color":"red"]
fill ~27~21~29 ~32~21~29 minecraft:stone ["stone_type":"stone"]
fill ~28~32~29 ~36~32~33 minecraft:stone ["stone_type":"stone"]
fill ~28~33~29 ~33~33~29 minecraft:obsidian
fill ~29~34~29 ~31~34~29 minecraft:obsidian
fill ~29~37~29 ~31~37~35 minecraft:obsidian
fill ~29~44~29 ~31~44~30 minecraft:obsidian
fill ~33~21~29 ~36~21~29 minecraft:wool 15
fill ~33~34~29 ~36~34~29 minecraft:obsidian
fill ~33~37~29 ~36~37~35 minecraft:obsidian
fill ~33~44~29 ~36~44~30 minecraft:obsidian
fill ~34~20~29 ~34~20~31 minecraft:wool 15
fill ~34~29~29 ~36~31~29 minecraft:concrete ["color":"white"]
fill ~35~23~29 ~50~23~29 minecraft:stone ["stone_type":"stone"]
fill ~36~33~29 ~37~33~31 minecraft:obsidian
fill ~37~31~29 ~37~31~30 minecraft:stone ["stone_type":"stone"]
fill ~38~33~29 ~47~33~39 minecraft:stone ["stone_type":"stone"]
fill ~38~36~29 ~47~36~35 minecraft:stone ["stone_type":"stone"]
fill ~38~37~29 ~47~38~29 minecraft:stained_hardened_clay ["color":"cyan"]
fill ~40~21~29 ~45~21~29 minecraft:wool 15
fill ~48~31~29 ~48~31~30 minecraft:stone ["stone_type":"stone"]
fill ~48~33~29 ~49~33~31 minecraft:obsidian
fill ~49~21~29 ~52~21~29 minecraft:wool 15
fill ~49~29~29 ~51~31~29 minecraft:concrete ["color":"white"]
fill ~49~32~29 ~57~32~33 minecraft:stone ["stone_type":"stone"]
fill ~49~34~29 ~52~34~29 minecraft:obsidian
fill ~49~37~29 ~52~37~35 minecraft:obsidian
fill ~49~44~29 ~52~44~30 minecraft:obsidian
fill ~51~20~29 ~51~20~31 minecraft:wool 15
fill ~52~29~29 ~59~31~29 minecraft:stained_hardened_clay ["color":"red"]
fill ~52~33~29 ~57~33~29 minecraft:obsidian
fill ~53~21~29 ~58~21~29 minecraft:stone ["stone_type":"stone"]
fill ~54~23~29 ~59~23~29 minecraft:stone ["stone_type":"stone"]
fill ~54~34~29 ~56~34~29 minecraft:obsidian
fill ~54~37~29 ~56~37~35 minecraft:obsidian
fill ~54~44~29 ~56~44~30 minecraft:obsidian
fill ~58~32~29 ~59~34~29 minecraft:stained_hardened_clay ["color":"red"]
setblock ~59~21~29 minecraft:nether_brick
setblock ~60~24~29 minecraft:stone ["stone_type":"stone"]
fill ~60~29~29 ~63~31~29 minecraft:stained_hardened_clay ["color":"orange"]
fill ~60~32~29 ~62~32~29 minecraft:stained_hardened_clay ["color":"orange"]
fill ~60~33~29 ~61~33~29 minecraft:stained_hardened_clay ["color":"orange"]
setblock ~60~34~29 minecraft:stained_hardened_clay ["color":"orange"]
setblock ~61~21~29 minecraft:nether_brick
fill ~61~23~29 ~61~23~32 minecraft:stone ["stone_type":"stone"]
setblock ~61~34~29 minecraft:stone ["stone_type":"stone"]
fill ~62~21~29 ~62~21~31 minecraft:stone ["stone_type":"stone"]
setblock ~62~33~29 minecraft:stone ["stone_type":"stone"]
fill ~63~32~29 ~63~32~31 minecraft:stone ["stone_type":"stone"]
setblock ~64~30~29 minecraft:stone ["stone_type":"stone"]
fill ~65~22~29 ~65~22~32 minecraft:stone ["stone_type":"stone"]
fill ~65~23~29 ~65~23~31 minecraft:stone ["stone_type":"stone"]
setblock ~65~24~29 minecraft:stone ["stone_type":"stone"]
fill ~65~29~29 ~65~29~32 minecraft:stone ["stone_type":"stone"]
fill ~65~30~29 ~65~30~30 minecraft:concrete ["color":"silver"]
setblock ~66~27~29 minecraft:obsidian
fill ~66~29~29 ~66~29~30 minecraft:concrete ["color":"silver"]
fill ~18~26~30 ~19~26~30 minecraft:wool 15
fill ~18~27~30 ~18~27~37 minecraft:obsidian
fill ~19~23~30 ~19~23~34 minecraft:stone ["stone_type":"stone"]
fill ~19~24~30 ~19~24~32 minecraft:stone ["stone_type":"stone"]
setblock ~19~25~30 minecraft:wool 15
setblock ~19~27~30 minecraft:stone ["stone_type":"stone"]
fill ~20~21~30 ~22~21~31 minecraft:stone ["stone_type":"stone"]
setblock ~21~22~30 minecraft:stone ["stone_type":"stone"]
setblock ~23~17~30 minecraft:stone_button ["button_pressed_bit":false,"facing_direction":0]
fill ~23~18~30 ~27~18~35 minecraft:obsidian
fill ~23~19~30 ~27~20~31 minecraft:obsidian
setblock ~23~35~30 minecraft:concrete ["color":"silver"]
fill ~24~21~30 ~30~21~31 minecraft:stone ["stone_type":"stone"]
fill ~24~22~30 ~27~22~30 minecraft:stone ["stone_type":"stone"]
fill ~26~23~30 ~26~23~32 minecraft:stone ["stone_type":"stone"]
setblock ~27~17~30 minecraft:stone_button ["button_pressed_bit":false,"facing_direction":0]
fill ~28~31~30 ~36~31~31 minecraft:stone ["stone_type":"stone"]
fill ~28~33~30 ~28~33~34 minecraft:obsidian
fill ~31~21~30 ~32~21~30 minecraft:wool 15
fill ~32~20~30 ~33~20~31 minecraft:wool 15
fill ~32~33~30 ~32~33~34 minecraft:obsidian
fill ~32~36~30 ~37~36~35 minecraft:obsidian
fill ~33~21~30 ~34~21~31 minecraft:stone ["stone_type":"stone"]
fill ~35~20~30 ~35~21~30 minecraft:wool 15
setblock ~36~21~30 minecraft:wool 15
fill ~37~20~30 ~48~20~33 minecraft:stone ["stone_type":"stone"]
fill ~37~21~30 ~48~21~30 minecraft:stone ["stone_type":"stone"]
setblock ~38~22~30 minecraft:stone ["stone_type":"stone"]
fill ~38~38~30 ~47~38~30 minecraft:stone ["stone_type":"stone"]
fill ~38~39~30 ~47~39~46 minecraft:stained_hardened_clay ["color":"cyan"]
setblock ~47~22~30 minecraft:stone ["stone_type":"stone"]
fill ~49~21~30 ~50~21~30 minecraft:wool 15
fill ~49~31~30 ~57~31~31 minecraft:stone ["stone_type":"stone"]
fill ~49~36~30 ~53~36~35 minecraft:obsidian
setblock ~50~20~30 minecraft:wool 15
fill ~51~21~30 ~52~21~31 minecraft:stone ["stone_type":"stone"]
fill ~52~20~30 ~53~20~31 minecraft:wool 15
fill ~53~21~30 ~54~21~30 minecraft:wool 15
fill ~53~33~30 ~53~33~34 minecraft:obsidian
fill ~55~21~30 ~61~21~31 minecraft:stone ["stone_type":"stone"]
fill ~57~33~30 ~57~33~34 minecraft:obsidian
fill ~57~36~30 ~57~36~35 minecraft:obsidian
setblock ~58~17~30 minecraft:stone_button ["button_pressed_bit":false,"facing_direction":0]
fill ~58~18~30 ~62~18~35 minecraft:obsidian
fill ~58~19~30 ~62~20~31 minecraft:obsidian
fill ~58~22~30 ~61~22~30 minecraft:stone ["stone_type":"stone"]
fill ~59~23~30 ~59~23~32 minecraft:stone ["stone_type":"stone"]
setblock ~62~17~30 minecraft:stone_button ["button_pressed_bit":false,"facing_direction":0]
setblock ~62~35~30 minecraft:concrete ["color":"silver"]
fill ~63~21~30 ~65~21~31 minecraft:stone ["stone_type":"stone"]
setblock ~64~22~30 minecraft:stone ["stone_type":"stone"]
fill ~66~23~30 ~66~23~34 minecraft:stone ["stone_type":"stone"]
fill ~66~24~30 ~66~24~32 minecraft:stone ["stone_type":"stone"]
setblock ~66~25~30 minecraft:wool 15
setblock ~66~27~30 minecraft:stone ["stone_type":"stone"]
setblock ~67~26~30 minecraft:wool 15
fill ~67~27~30 ~67~27~37 minecraft:obsidian
fill ~18~25~31 ~19~25~31 minecraft:stone ["stone_type":"stone"]
fill ~18~26~31 ~18~26~36 minecraft:stone ["stone_type":"stone"]
fill ~19~20~31 ~22~20~31 minecraft:clay
setblock ~19~21~31 minecraft:clay
fill ~19~28~31 ~19~29~34 minecraft:stone ["stone_type":"stone"]
fill ~20~30~31 ~20~31~34 minecraft:stone ["stone_type":"stone"]
fill ~21~19~31 ~22~19~31 minecraft:clay
fill ~21~31~31 ~21~32~32 minecraft:stone ["stone_type":"stone"]
fill ~22~33~31 ~22~34~34 minecraft:stone ["stone_type":"stone"]
fill ~23~34~31 ~23~35~62 minecraft:stone ["stone_type":"stone"]
fill ~24~22~31 ~26~22~32 minecraft:stone ["stone_type":"stone"]
fill ~24~35~31 ~27~35~31 minecraft:stone ["stone_type":"stone"]
fill ~25~36~31 ~27~36~35 minecraft:stone ["stone_type":"stone"]
fill ~28~19~31 ~32~19~31 minecraft:wool 15
fill ~28~20~31 ~31~20~31 minecraft:wool 15
fill ~29~33~31 ~31~33~34 minecraft:obsidian
fill ~29~36~31 ~31~36~35 minecraft:obsidian
fill ~29~43~31 ~31~43~32 minecraft:obsidian
fill ~31~21~31 ~32~21~31 minecraft:stone ["stone_type":"stone"]
fill ~33~33~31 ~35~33~34 minecraft:obsidian
fill ~33~43~31 ~36~43~32 minecraft:obsidian
fill ~35~20~31 ~36~20~33 minecraft:stone ["stone_type":"stone"]
setblock ~35~21~31 minecraft:stone ["stone_type":"stone"]
fill ~49~20~31 ~50~20~33 minecraft:stone ["stone_type":"stone"]
fill ~49~43~31 ~52~43~32 minecraft:obsidian
setblock ~50~21~31 minecraft:stone ["stone_type":"stone"]
fill ~50~33~31 ~52~33~34 minecraft:obsidian
fill ~53~19~31 ~57~19~31 minecraft:wool 15
fill ~53~21~31 ~54~21~31 minecraft:stone ["stone_type":"stone"]
fill ~54~20~31 ~57~20~31 minecraft:wool 15
fill ~54~33~31 ~56~33~34 minecraft:obsidian
fill ~54~36~31 ~56~36~35 minecraft:obsidian
fill ~54~43~31 ~56~43~32 minecraft:obsidian
fill ~58~35~31 ~62~35~31 minecraft:stone ["stone_type":"stone"]
fill ~58~36~31 ~60~36~35 minecraft:stone ["stone_type":"stone"]
fill ~59~22~31 ~61~22~32 minecraft:stone ["stone_type":"stone"]
fill ~62~34~31 ~63~34~56 minecraft:stone ["stone_type":"stone"]
fill ~63~19~31 ~64~20~31 minecraft:clay
fill ~63~33~31 ~63~33~34 minecraft:stone ["stone_type":"stone"]
fill ~64~31~31 ~65~31~32 minecraft:stone ["stone_type":"stone"]
fill ~64~32~31 ~64~32~35 minecraft:stone ["stone_type":"stone"]
fill ~65~20~31 ~66~20~31 minecraft:clay
fill ~65~30~31 ~65~30~34 minecraft:stone ["stone_type":"stone"]
setblock ~66~21~31 minecraft:clay
fill ~66~25~31 ~67~25~31 minecraft:stone ["stone_type":"stone"]
fill ~66~28~31 ~66~29~34 minecraft:stone ["stone_type":"stone"]
fill ~67~26~31 ~67~26~36 minecraft:stone ["stone_type":"stone"]
setblock ~17~23~32 minecraft:clay
fill ~18~21~32 ~19~21~32 minecraft:iron_bars
fill ~18~22~32 ~19~22~32 minecraft:clay
fill ~18~24~32 ~18~25~36 minecraft:stone ["stone_type":"stone"]
fill ~18~28~32 ~18~28~40 minecraft:stone ["stone_type":"stone"]
fill ~19~20~32 ~20~20~32 minecraft:iron_bars
fill ~20~19~32 ~22~19~33 minecraft:iron_bars
fill ~20~21~32 ~21~21~32 minecraft:stone ["stone_type":"stone"]
fill ~21~20~32 ~31~20~33 minecraft:stone ["stone_type":"stone"]
fill ~21~33~32 ~21~33~38 minecraft:stone ["stone_type":"stone"]
fill ~23~19~32 ~25~19~32 minecraft:obsidian
fill ~24~21~32 ~26~21~32 minecraft:stone ["stone_type":"stone"]
fill ~24~35~32 ~25~35~32 minecraft:stone ["stone_type":"stone"]
fill ~24~36~32 ~24~36~38 minecraft:stone ["stone_type":"stone"]
fill ~26~19~32 ~27~19~37 minecraft:stone ["stone_type":"stone"]
fill ~28~19~32 ~31~19~33 minecraft:wool 15
fill ~29~34~32 ~31~34~32 minecraft:obsidian
setblock ~32~20~32 minecraft:wool 15
fill ~33~20~32 ~34~20~33 minecraft:stone ["stone_type":"stone"]
fill ~33~34~32 ~36~35~32 minecraft:obsidian
fill ~36~33~32 ~36~33~34 minecraft:obsidian
fill ~49~33~32 ~49~33~34 minecraft:obsidian
fill ~49~34~32 ~52~35~32 minecraft:obsidian
fill ~51~20~32 ~52~20~33 minecraft:stone ["stone_type":"stone"]
setblock ~53~20~32 minecraft:wool 15
fill ~54~19~32 ~57~19~33 minecraft:wool 15
fill ~54~20~32 ~64~20~33 minecraft:stone ["stone_type":"stone"]
fill ~54~34~32 ~56~34~32 minecraft:obsidian
fill ~58~19~32 ~59~19~37 minecraft:stone ["stone_type":"stone"]
fill ~59~21~32 ~61~21~32 minecraft:stone ["stone_type":"stone"]
fill ~60~19~32 ~62~19~32 minecraft:obsidian
fill ~60~35~32 ~62~35~32 minecraft:stone ["stone_type":"stone"]
fill ~61~36~32 ~61~36~38 minecraft:stone ["stone_type":"stone"]
fill ~63~19~32 ~65~19~33 minecraft:iron_bars
fill ~64~21~32 ~65~21~32 minecraft:stone ["stone_type":"stone"]
fill ~64~33~32 ~64~33~38 minecraft:stone ["stone_type":"stone"]
fill ~65~20~32 ~66~20~32 minecraft:iron_bars
fill ~66~21~32 ~67~21~32 minecraft:iron_bars
fill ~66~22~32 ~67~22~32 minecraft:clay
fill ~67~24~32 ~67~25~36 minecraft:stone ["stone_type":"stone"]
fill ~67~28~32 ~67~28~40 minecraft:stone ["stone_type":"stone"]
setblock ~68~23~32 minecraft:clay
fill ~17~21~33 ~18~22~33 minecraft:iron_bars
fill ~17~23~33 ~17~23~35 minecraft:iron_bars
setblock ~17~24~33 minecraft:clay
fill ~18~20~33 ~19~20~33 minecraft:iron_bars
fill ~18~23~33 ~18~23~38 minecraft:stone ["stone_type":"stone"]
setblock ~19~19~33 minecraft:iron_bars
fill ~19~21~33 ~20~21~33 minecraft:stone ["stone_type":"stone"]
fill ~19~22~33 ~19~22~35 minecraft:stone ["stone_type":"stone"]
fill ~19~30~33 ~19~30~41 minecraft:stone ["stone_type":"stone"]
fill ~20~20~33 ~20~20~34 minecraft:stone ["stone_type":"stone"]
fill ~21~32~33 ~21~32~35 minecraft:stone ["stone_type":"stone"]
setblock ~23~19~33 minecraft:obsidian
fill ~24~19~33 ~25~19~37 minecraft:stone ["stone_type":"stone"]
fill ~24~35~33 ~24~35~65 minecraft:stone ["stone_type":"stone"]
fill ~29~41~33 ~31~41~35 minecraft:obsidian
fill ~32~19~33 ~53~19~37 minecraft:stone ["stone_type":"stone"]
setblock ~32~20~33 minecraft:stone ["stone_type":"stone"]
fill ~33~35~33 ~36~35~34 minecraft:obsidian
fill ~33~41~33 ~36~41~35 minecraft:obsidian
fill ~37~33~33 ~37~33~35 minecraft:obsidian
fill ~40~37~33 ~45~37~35 minecraft:stone ["stone_type":"stone"]
fill ~41~38~33 ~44~38~35 minecraft:stone ["stone_type":"stone"]
fill ~48~33~33 ~48~33~35 minecraft:obsidian
fill ~49~35~33 ~52~35~34 minecraft:obsidian
fill ~49~41~33 ~52~41~35 minecraft:obsidian
setblock ~53~20~33 minecraft:stone ["stone_type":"stone"]
fill ~54~41~33 ~56~41~35 minecraft:obsidian
fill ~60~19~33 ~61~19~37 minecraft:stone ["stone_type":"stone"]
fill ~61~35~33 ~62~35~42 minecraft:stone ["stone_type":"stone"]
setblock ~62~19~33 minecraft:obsidian
fill ~65~20~33 ~65~20~34 minecraft:stone ["stone_type":"stone"]
fill ~65~21~33 ~66~21~33 minecraft:stone ["stone_type":"stone"]
fill ~65~31~33 ~65~31~36 minecraft:stone ["stone_type":"stone"]
fill ~66~19~33 ~66~20~33 minecraft:iron_bars
fill ~66~22~33 ~66~22~35 minecraft:stone ["stone_type":"stone"]
fill ~66~30~33 ~66~30~41 minecraft:stone ["stone_type":"stone"]
fill ~67~20~33 ~67~22~33 minecraft:iron_bars
fill ~67~23~33 ~67~23~38 minecraft:stone ["stone_type":"stone"]
fill ~68~21~33 ~68~23~34 minecraft:iron_bars
setblock ~68~24~33 minecraft:clay
fill ~16~24~34 ~17~24~36 minecraft:iron_bars
fill ~16~25~34 ~17~25~34 minecraft:clay
setblock ~16~26~34 minecraft:clay
fill ~16~27~34 ~17~28~34 minecraft:nether_brick
fill ~17~21~34 ~17~22~34 minecraft:iron_bars
setblock ~18~20~34 minecraft:clay
fill ~18~21~34 ~19~21~34 minecraft:stone ["stone_type":"stone"]
fill ~18~22~34 ~18~22~38 minecraft:stone ["stone_type":"stone"]
fill ~18~29~34 ~18~29~42 minecraft:stone ["stone_type":"stone"]
fill ~19~19~34 ~22~19~34 minecraft:clay
fill ~19~20~34 ~19~20~37 minecraft:stone ["stone_type":"stone"]
fill ~20~32~34 ~20~32~40 minecraft:stone ["stone_type":"stone"]
fill ~21~20~34 ~24~20~34 minecraft:stone ["stone_type":"stone"]
fill ~23~19~34 ~23~19~38 minecraft:stone ["stone_type":"stone"]
fill ~24~34~34 ~27~34~43 minecraft:stone ["stone_type":"stone"]
fill ~25~35~34 ~27~35~34 minecraft:stone ["stone_type":"stone"]
setblock ~26~38~34 minecraft:stone_button ["button_pressed_bit":false,"facing_direction":4]
fill ~27~38~34 ~27~38~35 minecraft:wool 15
fill ~28~19~34 ~29~19~34 minecraft:wool 15
fill ~29~34~34 ~31~34~35 minecraft:obsidian
fill ~29~38~34 ~31~38~35 minecraft:obsidian
fill ~30~19~34 ~31~19~37 minecraft:stone ["stone_type":"stone"]
fill ~33~34~34 ~36~34~35 minecraft:obsidian
fill ~33~38~34 ~36~38~35 minecraft:obsidian
fill ~38~34~34 ~47~34~49 minecraft:stone ["stone_type":"stone"]
fill ~38~35~34 ~47~35~34 minecraft:stone ["stone_type":"stone"]
fill ~39~37~34 ~39~37~35 minecraft:stone ["stone_type":"stone"]
fill ~40~38~34 ~40~38~35 minecraft:stone ["stone_type":"stone"]
fill ~45~38~34 ~45~38~35 minecraft:stone ["stone_type":"stone"]
fill ~46~37~34 ~46~37~35 minecraft:stone ["stone_type":"stone"]
fill ~49~34~34 ~52~34~35 minecraft:obsidian
fill ~49~38~34 ~52~38~35 minecraft:obsidian
fill ~54~19~34 ~55~19~37 minecraft:stone ["stone_type":"stone"]
fill ~54~34~34 ~56~34~35 minecraft:obsidian
fill ~54~38~34 ~56~38~35 minecraft:obsidian
fill ~56~19~34 ~57~19~34 minecraft:wool 15
fill ~58~34~34 ~61~34~43 minecraft:stone ["stone_type":"stone"]
fill ~58~35~34 ~60~35~34 minecraft:stone ["stone_type":"stone"]
fill ~58~38~34 ~58~38~35 minecraft:wool 15
setblock ~59~38~34 minecraft:stone_button ["button_pressed_bit":false,"facing_direction":5]
fill ~61~20~34 ~64~20~34 minecraft:stone ["stone_type":"stone"]
fill ~62~19~34 ~62~19~38 minecraft:stone ["stone_type":"stone"]
fill ~63~19~34 ~66~19~34 minecraft:clay
fill ~65~32~34 ~65~32~40 minecraft:stone ["stone_type":"stone"]
fill ~66~20~34 ~66~20~37 minecraft:stone ["stone_type":"stone"]
fill ~66~21~34 ~67~21~34 minecraft:stone ["stone_type":"stone"]
setblock ~67~20~34 minecraft:clay
fill ~67~22~34 ~67~22~38 minecraft:stone ["stone_type":"stone"]
fill ~67~29~34 ~67~29~42 minecraft:stone ["stone_type":"stone"]
fill ~68~24~34 ~69~24~36 minecraft:iron_bars
fill ~68~25~34 ~69~25~34 minecraft:clay
fill ~68~27~34 ~69~28~34 minecraft:nether_brick
setblock ~69~26~34 minecraft:clay
setblock ~16~23~35 minecraft:iron_bars
fill ~16~25~35 ~17~25~35 minecraft:iron_bars
fill ~16~26~35 ~16~26~37 minecraft:iron_bars
fill ~16~27~35 ~16~28~35 minecraft:clay
fill ~17~21~35 ~18~21~35 minecraft:clay
setblock ~17~22~35 minecraft:clay
fill ~19~19~35 ~22~19~38 minecraft:stone ["stone_type":"stone"]
fill ~19~21~35 ~19~21~36 minecraft:stone ["stone_type":"stone"]
fill ~19~24~35 ~19~25~35 minecraft:stone ["stone_type":"stone"]
fill ~19~29~35 ~19~29~38 minecraft:stone ["stone_type":"stone"]
fill ~20~31~35 ~20~31~36 minecraft:stone ["stone_type":"stone"]
fill ~21~34~35 ~22~34~62 minecraft:stone ["stone_type":"stone"]
setblock ~23~17~35 minecraft:stone_button ["button_pressed_bit":false,"facing_direction":0]
fill ~24~37~35 ~25~37~38 minecraft:stone ["stone_type":"stone"]
fill ~26~35~35 ~27~35~62 minecraft:stone ["stone_type":"stone"]
setblock ~26~40~35 minecraft:stone_button ["button_pressed_bit":false,"facing_direction":4]
setblock ~27~17~35 minecraft:stone_button ["button_pressed_bit":false,"facing_direction":0]
fill ~27~40~35 ~27~40~37 minecraft:wool ["color":"gray"]
fill ~28~19~35 ~29~19~37 minecraft:stone ["stone_type":"stone"]
setblock ~29~35~35 minecraft:obsidian
fill ~29~40~35 ~31~40~35 minecraft:obsidian
fill ~31~18~35 ~54~18~52 minecraft:stone ["stone_type":"stone"]
fill ~33~40~35 ~36~40~35 minecraft:obsidian
setblock ~37~35~35 minecraft:obsidian
fill ~38~35~35 ~38~35~62 minecraft:stone ["stone_type":"stone"]
fill ~38~37~35 ~38~37~36 minecraft:stone ["stone_type":"stone"]
fill ~38~38~35 ~39~38~35 minecraft:stone ["stone_type":"stone"]
fill ~40~35~35 ~45~35~62 minecraft:stone ["stone_type":"stone"]
fill ~46~38~35 ~47~38~35 minecraft:stone ["stone_type":"stone"]
fill ~47~35~35 ~47~35~62 minecraft:stone ["stone_type":"stone"]
setblock ~47~37~35 minecraft:stone ["stone_type":"stone"]
fill ~48~35~35 ~48~36~35 minecraft:obsidian
fill ~49~40~35 ~52~40~35 minecraft:obsidian
fill ~54~40~35 ~56~40~35 minecraft:obsidian
fill ~56~19~35 ~57~19~37 minecraft:stone ["stone_type":"stone"]
setblock ~56~35~35 minecraft:obsidian
setblock ~58~17~35 minecraft:stone_button ["button_pressed_bit":false,"facing_direction":0]
fill ~58~35~35 ~59~35~62 minecraft:stone ["stone_type":"stone"]
fill ~58~40~35 ~58~40~36 minecraft:wool ["color":"gray"]
setblock ~59~40~35 minecraft:stone_button ["button_pressed_bit":false,"facing_direction":5]
fill ~60~37~35 ~61~37~38 minecraft:stone ["stone_type":"stone"]
setblock ~62~17~35 minecraft:stone_button ["button_pressed_bit":false,"facing_direction":0]
fill ~63~19~35 ~66~19~38 minecraft:stone ["stone_type":"stone"]
fill ~64~34~35 ~64~34~56 minecraft:stone ["stone_type":"stone"]
fill ~66~21~35 ~66~21~36 minecraft:stone ["stone_type":"stone"]
fill ~66~24~35 ~66~25~35 minecraft:stone ["stone_type":"stone"]
fill ~66~29~35 ~66~29~38 minecraft:stone ["stone_type":"stone"]
fill ~67~21~35 ~68~21~35 minecraft:clay
setblock ~68~22~35 minecraft:clay
fill ~68~23~35 ~69~23~35 minecraft:iron_bars
fill ~68~25~35 ~69~25~35 minecraft:iron_bars
fill ~69~26~35 ~69~26~37 minecraft:iron_bars
fill ~69~27~35 ~69~28~35 minecraft:clay
fill ~15~25~36 ~16~25~36 minecraft:iron_bars
fill ~15~26~36 ~15~28~37 minecraft:iron_bars
fill ~16~23~36 ~17~23~36 minecraft:clay
fill ~16~27~36 ~16~28~36 minecraft:iron_bars
setblock ~16~29~36 minecraft:clay
fill ~18~21~36 ~18~21~39 minecraft:stone ["stone_type":"stone"]
fill ~19~31~36 ~19~31~45 minecraft:stone ["stone_type":"stone"]
fill ~20~33~36 ~20~33~40 minecraft:stone ["stone_type":"stone"]
fill ~22~35~36 ~22~35~62 minecraft:stone ["stone_type":"stone"]
fill ~23~36~36 ~23~36~38 minecraft:stone ["stone_type":"stone"]
fill ~25~36~36 ~26~36~38 minecraft:stone ["stone_type":"stone"]
fill ~26~38~36 ~26~38~37 minecraft:wool 15
fill ~28~34~36 ~36~35~39 minecraft:stone ["stone_type":"stone"]
fill ~28~36~36 ~28~38~47 minecraft:concrete ["color":"gray"]
fill ~28~39~36 ~28~39~46 minecraft:concrete ["color":"gray"]
fill ~28~40~36 ~37~40~37 minecraft:concrete ["color":"gray"]
fill ~29~37~36 ~37~37~36 minecraft:stone ["stone_type":"stone"]
fill ~33~36~36 ~33~36~46 minecraft:stone ["stone_type":"stone"]
fill ~33~38~36 ~33~38~46 minecraft:stone ["stone_type":"stone"]
fill ~33~39~36 ~33~39~41 minecraft:stone ["stone_type":"stone"]
fill ~36~36~36 ~39~36~36 minecraft:stone ["stone_type":"stone"]
fill ~37~33~36 ~37~33~39 minecraft:stone ["stone_type":"stone"]
fill ~37~35~36 ~37~35~62 minecraft:stone ["stone_type":"stone"]
fill ~37~38~36 ~37~38~37 minecraft:stone ["stone_type":"stone"]
fill ~37~39~36 ~37~39~47 minecraft:stained_hardened_clay ["color":"cyan"]
fill ~38~17~36 ~47~17~45 minecraft:stone ["stone_type":"stone"]
setblock ~38~32~36 minecraft:stone ["stone_type":"stone"]
fill ~39~20~36 ~46~20~36 minecraft:stone ["stone_type":"stone"]
fill ~39~35~36 ~39~35~62 minecraft:stone ["stone_type":"stone"]
fill ~41~21~36 ~44~21~36 minecraft:stone ["stone_type":"stone"]
fill ~41~40~36 ~44~40~37 minecraft:stone ["stone_type":"stone"]
setblock ~41~41~36 minecraft:stone_block_slab ["stone_slab_type":"stone_brick","top_slot_bit":false]
setblock ~44~41~36 minecraft:stone_block_slab ["stone_slab_type":"stone_brick","top_slot_bit":false]
fill ~46~35~36 ~46~35~62 minecraft:stone ["stone_type":"stone"]
setblock ~46~36~36 minecraft:stone ["stone_type":"stone"]
setblock ~47~32~36 minecraft:stone ["stone_type":"stone"]
fill ~48~33~36 ~48~33~39 minecraft:stone ["stone_type":"stone"]
fill ~48~35~36 ~57~35~53 minecraft:stone ["stone_type":"stone"]
fill ~48~36~36 ~49~37~37 minecraft:stone ["stone_type":"stone"]
fill ~48~38~36 ~49~38~36 minecraft:stone ["stone_type":"stone"]
fill ~48~39~36 ~49~39~47 minecraft:stained_hardened_clay ["color":"cyan"]
fill ~48~40~36 ~57~40~37 minecraft:concrete ["color":"gray"]
fill ~49~34~36 ~57~34~39 minecraft:stone ["stone_type":"stone"]
fill ~50~37~36 ~56~37~36 minecraft:stone ["stone_type":"stone"]
fill ~53~36~36 ~53~36~46 minecraft:stone ["stone_type":"stone"]
fill ~53~38~36 ~53~38~46 minecraft:stone ["stone_type":"stone"]
fill ~53~39~36 ~53~39~41 minecraft:stone ["stone_type":"stone"]
fill ~57~36~36 ~57~38~47 minecraft:concrete ["color":"gray"]
fill ~57~39~36 ~57~39~46 minecraft:concrete ["color":"gray"]
fill ~59~36~36 ~60~36~40 minecraft:stone ["stone_type":"stone"]
fill ~59~38~36 ~59~38~37 minecraft:wool 15
fill ~62~36~36 ~62~36~38 minecraft:stone ["stone_type":"stone"]
fill ~63~35~36 ~63~35~42 minecraft:stone ["stone_type":"stone"]
fill ~65~33~36 ~65~33~45 minecraft:stone ["stone_type":"stone"]
fill ~66~31~36 ~66~31~45 minecraft:stone ["stone_type":"stone"]
fill ~67~21~36 ~67~21~39 minecraft:stone ["stone_type":"stone"]
fill ~68~23~36 ~69~23~36 minecraft:clay
fill ~69~25~36 ~70~25~36 minecraft:iron_bars
fill ~69~27~36 ~70~28~36 minecraft:iron_bars
setblock ~69~29~36 minecraft:clay
fill ~70~26~36 ~70~26~37 minecraft:iron_bars
fill ~15~25~37 ~16~25~37 minecraft:clay
fill ~15~29~37 ~16~29~38 minecraft:iron_bars
fill ~15~30~37 ~15~30~40 minecraft:iron_bars
fill ~16~24~37 ~17~24~37 minecraft:clay
setblock ~16~28~37 minecraft:iron_bars
setblock ~16~30~37 minecraft:clay
fill ~17~25~37 ~17~25~43 minecraft:stone ["stone_type":"stone"]
fill ~17~26~37 ~17~26~42 minecraft:stone ["stone_type":"stone"]
fill ~18~20~37 ~18~20~41 minecraft:stone ["stone_type":"stone"]
fill ~18~30~37 ~18~30~45 minecraft:stone ["stone_type":"stone"]
fill ~24~18~37 ~30~18~41 minecraft:stone ["stone_type":"stone"]
fill ~26~37~37 ~26~37~41 minecraft:stone ["stone_type":"stone"]
fill ~33~37~37 ~33~37~46 minecraft:stone ["stone_type":"stone"]
fill ~34~17~37 ~37~17~44 minecraft:stone ["stone_type":"stone"]
fill ~35~36~37 ~37~36~37 minecraft:stone ["stone_type":"stone"]
fill ~36~33~37 ~36~33~39 minecraft:stone ["stone_type":"stone"]
fill ~36~37~37 ~37~37~37 minecraft:stone ["stone_type":"stone"]
fill ~36~38~37 ~36~38~38 minecraft:stone ["stone_type":"stone"]
fill ~36~39~37 ~36~39~47 minecraft:stained_hardened_clay ["color":"cyan"]
fill ~37~34~37 ~37~34~49 minecraft:stone ["stone_type":"stone"]
fill ~39~40~37 ~40~40~44 minecraft:stone ["stone_type":"stone"]
setblock ~39~41~37 minecraft:stone_block_slab ["stone_slab_type":"stone_brick","top_slot_bit":false]
fill ~42~41~37 ~43~41~37 minecraft:stone_block_slab ["stone_slab_type":"stone_brick","top_slot_bit":false]
fill ~45~40~37 ~46~40~38 minecraft:stone ["stone_type":"stone"]
setblock ~46~41~37 minecraft:stone_block_slab ["stone_slab_type":"stone_brick","top_slot_bit":false]
fill ~48~17~37 ~51~17~44 minecraft:stone ["stone_type":"stone"]
fill ~48~34~37 ~48~34~49 minecraft:stone ["stone_type":"stone"]
fill ~49~33~37 ~49~33~39 minecraft:stone ["stone_type":"stone"]
fill ~49~38~37 ~50~38~37 minecraft:stone ["stone_type":"stone"]
fill ~50~36~37 ~50~37~46 minecraft:stone ["stone_type":"stone"]
fill ~50~39~37 ~50~39~47 minecraft:stained_hardened_clay ["color":"cyan"]
fill ~53~37~37 ~53~37~46 minecraft:stone ["stone_type":"stone"]
fill ~55~18~37 ~61~18~41 minecraft:stone ["stone_type":"stone"]
fill ~57~41~37 ~57~41~39 minecraft:wool ["color":"gray"]
fill ~59~37~37 ~59~37~41 minecraft:stone ["stone_type":"stone"]
fill ~67~20~37 ~67~20~41 minecraft:stone ["stone_type":"stone"]
fill ~67~30~37 ~67~30~45 minecraft:stone ["stone_type":"stone"]
fill ~68~24~37 ~69~24~37 minecraft:clay
fill ~68~25~37 ~68~25~43 minecraft:stone ["stone_type":"stone"]
fill ~68~26~37 ~68~26~42 minecraft:stone ["stone_type":"stone"]
fill ~69~25~37 ~70~25~37 minecraft:clay
fill ~69~28~37 ~70~29~37 minecraft:iron_bars
setblock ~69~30~37 minecraft:clay
setblock ~70~27~37 minecraft:iron_bars
fill ~70~30~37 ~70~30~40 minecraft:iron_bars
fill ~15~25~38 ~16~25~38 minecraft:nether_brick
fill ~15~26~38 ~15~27~38 minecraft:clay
setblock ~15~28~38 minecraft:iron_bars
fill ~15~31~38 ~15~31~46 minecraft:iron_bars
fill ~16~30~38 ~16~30~39 minecraft:iron_bars
setblock ~16~31~38 minecraft:clay
fill ~17~23~38 ~17~24~42 minecraft:stone ["stone_type":"stone"]
fill ~17~27~38 ~17~27~41 minecraft:obsidian
fill ~18~19~38 ~18~19~41 minecraft:stone ["stone_type":"stone"]
fill ~18~27~38 ~18~27~39 minecraft:stone ["stone_type":"stone"]
fill ~19~18~38 ~23~18~41 minecraft:stone ["stone_type":"stone"]
fill ~25~35~38 ~25~35~52 minecraft:stone ["stone_type":"stone"]
fill ~25~38~38 ~25~38~45 minecraft:stone ["stone_type":"stone"]
fill ~26~39~38 ~26~39~39 minecraft:wool 15
fill ~28~40~38 ~36~40~38 minecraft:concrete ["color":"gray"]
fill ~28~41~38 ~28~41~40 minecraft:wool ["color":"gray"]
fill ~33~17~38 ~33~17~59 minecraft:stone ["stone_type":"stone"]
fill ~35~33~38 ~35~33~39 minecraft:stone ["stone_type":"stone"]
fill ~35~36~38 ~36~37~43 minecraft:stone ["stone_type":"stone"]
fill ~35~38~38 ~35~38~40 minecraft:stone ["stone_type":"stone"]
fill ~35~39~38 ~35~39~47 minecraft:stained_hardened_clay ["color":"cyan"]
setblock ~37~19~38 minecraft:stone ["stone_type":"stone"]
setblock ~40~41~38 minecraft:stone_block_slab ["stone_slab_type":"stone_brick","top_slot_bit":false]
fill ~41~41~38 ~44~42~38 minecraft:stained_hardened_clay ["color":"cyan"]
fill ~41~43~38 ~44~43~38 minecraft:stone_brick_stairs ["upside_down_bit":false,"weirdo_direction":3]
setblock ~45~41~38 minecraft:stone_block_slab ["stone_slab_type":"stone_brick","top_slot_bit":false]
setblock ~48~19~38 minecraft:stone ["stone_type":"stone"]
fill ~49~36~38 ~49~37~40 minecraft:stone ["stone_type":"stone"]
fill ~49~40~38 ~57~40~38 minecraft:concrete ["color":"gray"]
fill ~50~33~38 ~50~33~39 minecraft:stone ["stone_type":"stone"]
fill ~50~38~38 ~50~38~39 minecraft:stone ["stone_type":"stone"]
fill ~52~17~38 ~52~17~59 minecraft:stone ["stone_type":"stone"]
fill ~59~38~38 ~60~38~44 minecraft:stone ["stone_type":"stone"]
setblock ~59~39~38 minecraft:wool 15
fill ~60~35~38 ~60~35~62 minecraft:stone ["stone_type":"stone"]
fill ~62~18~38 ~66~18~41 minecraft:stone ["stone_type":"stone"]
fill ~67~19~38 ~67~19~41 minecraft:stone ["stone_type":"stone"]
fill ~67~27~38 ~67~27~39 minecraft:stone ["stone_type":"stone"]
fill ~68~23~38 ~68~24~42 minecraft:stone ["stone_type":"stone"]
fill ~68~27~38 ~68~27~41 minecraft:obsidian
fill ~69~25~38 ~70~25~38 minecraft:nether_brick
fill ~69~29~38 ~70~29~38 minecraft:iron_bars
fill ~69~30~38 ~69~30~39 minecraft:iron_bars
setblock ~69~31~38 minecraft:clay
fill ~70~26~38 ~70~27~38 minecraft:clay
setblock ~70~28~38 minecraft:iron_bars
fill ~70~31~38 ~70~31~46 minecraft:iron_bars
fill ~15~26~39 ~16~26~39 minecraft:nether_brick
setblock ~15~28~39 minecraft:clay
setblock ~15~29~39 minecraft:iron_bars
fill ~15~32~39 ~15~32~58 minecraft:iron_bars
fill ~16~31~39 ~16~31~40 minecraft:iron_bars
setblock ~16~32~39 minecraft:clay
fill ~17~21~39 ~17~22~41 minecraft:stone ["stone_type":"stone"]
fill ~17~28~39 ~17~28~46 minecraft:stone ["stone_type":"stone"]
fill ~18~18~39 ~18~18~41 minecraft:stone ["stone_type":"stone"]
fill ~19~32~39 ~19~32~49 minecraft:stone ["stone_type":"stone"]
fill ~24~36~39 ~24~36~41 minecraft:stone_brick_stairs ["upside_down_bit":false,"weirdo_direction":3]
fill ~24~37~39 ~24~37~41 minecraft:stone_brick_stairs ["upside_down_bit":true,"weirdo_direction":3]
fill ~25~37~39 ~25~37~42 minecraft:stone ["stone_type":"stone"]
fill ~26~36~39 ~26~36~40 minecraft:stone ["stone_type":"stone"]
fill ~26~38~39 ~26~38~44 minecraft:stone ["stone_type":"stone"]
fill ~28~40~39 ~35~40~39 minecraft:concrete ["color":"gray"]
setblock ~35~41~39 minecraft:wool 15
setblock ~35~42~39 minecraft:stone_button ["button_pressed_bit":false,"facing_direction":1]
fill ~38~40~39 ~38~40~42 minecraft:stone ["stone_type":"stone"]
setblock ~38~41~39 minecraft:stone_block_slab ["stone_slab_type":"stone_brick","top_slot_bit":false]
fill ~39~16~39 ~46~16~73 minecraft:stone ["stone_type":"stone"]
fill ~40~41~39 ~40~42~42 minecraft:stained_hardened_clay ["color":"cyan"]
setblock ~40~43~39 minecraft:stone_brick_stairs ["upside_down_bit":false,"weirdo_direction":3]
setblock ~41~43~39 minecraft:stone_brick_stairs ["upside_down_bit":false,"weirdo_direction":1]
fill ~42~43~39 ~43~43~42 minecraft:stained_hardened_clay ["color":"yellow"]
setblock ~44~43~39 minecraft:stone_brick_stairs ["upside_down_bit":false,"weirdo_direction":0]
fill ~45~41~39 ~45~42~42 minecraft:stained_hardened_clay ["color":"cyan"]
setblock ~45~43~39 minecraft:stone_brick_stairs ["upside_down_bit":false,"weirdo_direction":3]
fill ~46~40~39 ~47~40~42 minecraft:stone ["stone_type":"stone"]
setblock ~47~41~39 minecraft:stone_block_slab ["stone_slab_type":"stone_brick","top_slot_bit":false]
fill ~50~40~39 ~57~40~39 minecraft:concrete ["color":"gray"]
setblock ~50~41~39 minecraft:wool 15
setblock ~50~42~39 minecraft:stone_button ["button_pressed_bit":false,"facing_direction":1]
fill ~51~36~39 ~51~37~42 minecraft:stone ["stone_type":"stone"]
fill ~51~38~39 ~51~38~40 minecraft:stone ["stone_type":"stone"]
fill ~51~39~39 ~51~39~46 minecraft:stained_hardened_clay ["color":"cyan"]
fill ~60~37~39 ~60~37~42 minecraft:stone ["stone_type":"stone"]
fill ~60~39~39 ~60~39~41 minecraft:wool 15
fill ~61~36~39 ~61~36~41 minecraft:stone_brick_stairs ["upside_down_bit":false,"weirdo_direction":3]
fill ~61~37~39 ~61~37~41 minecraft:stone_brick_stairs ["upside_down_bit":true,"weirdo_direction":3]
fill ~61~38~39 ~61~38~44 minecraft:stone ["stone_type":"stone"]
fill ~66~32~39 ~66~32~49 minecraft:stone ["stone_type":"stone"]
fill ~67~18~39 ~67~18~41 minecraft:stone ["stone_type":"stone"]
fill ~68~21~39 ~68~22~41 minecraft:stone ["stone_type":"stone"]
fill ~68~28~39 ~68~28~46 minecraft:stone ["stone_type":"stone"]
fill ~69~26~39 ~70~26~39 minecraft:nether_brick
fill ~69~31~39 ~69~31~40 minecraft:iron_bars
setblock ~69~32~39 minecraft:clay
setblock ~70~28~39 minecraft:clay
setblock ~70~29~39 minecraft:iron_bars
fill ~70~32~39 ~70~32~58 minecraft:iron_bars
setblock ~15~29~40 minecraft:clay
fill ~16~32~40 ~16~32~50 minecraft:iron_bars
fill ~16~33~40 ~16~33~49 minecraft:clay
fill ~17~20~40 ~17~20~41 minecraft:stone ["stone_type":"stone"]
fill ~17~29~40 ~17~29~44 minecraft:stone ["stone_type":"stone"]
fill ~18~31~40 ~18~31~48 minecraft:stone ["stone_type":"stone"]
setblock ~20~34~40 minecraft:stone ["stone_type":"stone"]
fill ~24~38~40 ~24~38~44 minecraft:stone ["stone_type":"stone"]
fill ~25~36~40 ~25~36~41 minecraft:stone ["stone_type":"stone"]
fill ~25~39~40 ~25~39~41 minecraft:wool 15
fill ~28~34~40 ~29~35~41 minecraft:stone ["stone_type":"stone"]
fill ~28~40~40 ~34~40~40 minecraft:concrete ["color":"gray"]
fill ~29~39~40 ~32~39~41 minecraft:stone ["stone_type":"stone"]
fill ~30~35~40 ~36~35~62 minecraft:stone ["stone_type":"stone"]
fill ~31~34~40 ~36~34~40 minecraft:stone ["stone_type":"stone"]
fill ~34~36~40 ~34~38~45 minecraft:stone ["stone_type":"stone"]
fill ~34~39~40 ~34~39~46 minecraft:stained_hardened_clay ["color":"cyan"]
setblock ~36~40~40 minecraft:wool 15
fill ~38~16~40 ~38~16~78 minecraft:stone ["stone_type":"stone"]
fill ~39~41~40 ~39~41~41 minecraft:stone_block_slab ["stone_slab_type":"stone_brick","top_slot_bit":false]
fill ~40~43~40 ~40~43~42 minecraft:stone_brick_stairs ["upside_down_bit":false,"weirdo_direction":1]
fill ~41~43~40 ~41~43~41 minecraft:stained_hardened_clay ["color":"yellow"]
fill ~44~43~40 ~44~43~41 minecraft:stained_hardened_clay ["color":"yellow"]
fill ~45~43~40 ~45~43~42 minecraft:stone_brick_stairs ["upside_down_bit":false,"weirdo_direction":0]
fill ~46~41~40 ~46~41~41 minecraft:stone_block_slab ["stone_slab_type":"stone_brick","top_slot_bit":false]
fill ~47~16~40 ~47~16~78 minecraft:stone ["stone_type":"stone"]
fill ~49~34~40 ~54~34~40 minecraft:stone ["stone_type":"stone"]
setblock ~49~40~40 minecraft:wool 15
fill ~51~40~40 ~57~40~40 minecraft:concrete ["color":"gray"]
fill ~52~36~40 ~52~38~46 minecraft:stone ["stone_type":"stone"]
fill ~52~39~40 ~52~39~41 minecraft:stone ["stone_type":"stone"]
fill ~54~39~40 ~56~39~41 minecraft:stone ["stone_type":"stone"]
fill ~56~34~40 ~57~34~41 minecraft:stone ["stone_type":"stone"]
fill ~58~40~40 ~58~40~42 minecraft:wool ["color":"gray"]
fill ~65~34~40 ~65~34~66 minecraft:stone ["stone_type":"stone"]
fill ~67~31~40 ~67~31~48 minecraft:stone ["stone_type":"stone"]
fill ~68~20~40 ~68~20~41 minecraft:stone ["stone_type":"stone"]
fill ~68~29~40 ~68~29~44 minecraft:stone ["stone_type":"stone"]
fill ~69~32~40 ~69~32~50 minecraft:iron_bars
fill ~69~33~40 ~69~33~49 minecraft:clay
setblock ~70~29~40 minecraft:clay
fill ~15~30~41 ~15~30~47 minecraft:clay
fill ~16~22~41 ~16~26~42 minecraft:stone ["stone_type":"stone"]
setblock ~17~19~41 minecraft:stone ["stone_type":"stone"]
fill ~18~21~41 ~27~21~41 minecraft:stone ["stone_type":"stone"]
fill ~18~22~41 ~22~22~42 minecraft:stone ["stone_type":"stone"]
fill ~18~23~41 ~21~23~42 minecraft:stone ["stone_type":"stone"]
fill ~19~19~41 ~27~20~41 minecraft:stone ["stone_type":"stone"]
fill ~19~35~41 ~21~37~42 minecraft:stained_hardened_clay ["color":"cyan"]
fill ~20~33~41 ~20~34~41 minecraft:stained_hardened_clay ["color":"cyan"]
fill ~20~38~41 ~21~38~42 minecraft:stained_hardened_clay ["color":"cyan"]
fill ~22~36~41 ~22~37~42 minecraft:stained_hardened_clay ["color":"cyan"]
fill ~27~22~41 ~27~23~60 minecraft:stone ["stone_type":"stone"]
fill ~27~24~41 ~27~25~59 minecraft:stone ["stone_type":"stone"]
fill ~27~26~41 ~27~27~58 minecraft:stone ["stone_type":"stone"]
fill ~27~28~41 ~27~28~56 minecraft:stone ["stone_type":"stone"]
fill ~27~29~41 ~27~30~55 minecraft:stone ["stone_type":"stone"]
fill ~27~40~41 ~27~40~42 minecraft:wool ["color":"gray"]
fill ~28~40~41 ~33~40~41 minecraft:concrete ["color":"gray"]
fill ~28~41~41 ~33~41~41 minecraft:stone_button ["button_pressed_bit":false,"facing_direction":1]
fill ~29~36~41 ~29~38~41 minecraft:stone ["stone_type":"stone"]
fill ~30~37~41 ~32~38~41 minecraft:stone ["stone_type":"stone"]
fill ~33~34~41 ~36~34~46 minecraft:stone ["stone_type":"stone"]
fill ~37~40~41 ~37~40~43 minecraft:wool 15
fill ~48~40~41 ~48~40~43 minecraft:wool 15
fill ~49~34~41 ~52~34~46 minecraft:stone ["stone_type":"stone"]
fill ~52~40~41 ~57~40~41 minecraft:concrete ["color":"gray"]
fill ~52~41~41 ~57~41~41 minecraft:stone_button ["button_pressed_bit":false,"facing_direction":1]
fill ~54~37~41 ~56~38~41 minecraft:stone ["stone_type":"stone"]
fill ~58~19~41 ~66~21~41 minecraft:stone ["stone_type":"stone"]
fill ~58~22~41 ~58~23~60 minecraft:stone ["stone_type":"stone"]
fill ~58~24~41 ~58~24~59 minecraft:stone ["stone_type":"stone"]
fill ~58~25~41 ~58~28~56 minecraft:stone ["stone_type":"stone"]
fill ~58~29~41 ~58~30~55 minecraft:stone ["stone_type":"stone"]
setblock ~60~36~41 minecraft:stone ["stone_type":"stone"]
fill ~63~22~41 ~67~22~42 minecraft:stone ["stone_type":"stone"]
fill ~64~23~41 ~67~23~42 minecraft:stone ["stone_type":"stone"]
setblock ~67~21~41 minecraft:stone ["stone_type":"stone"]
setblock ~68~19~41 minecraft:stone ["stone_type":"stone"]
fill ~69~22~41 ~69~26~42 minecraft:stone ["stone_type":"stone"]
fill ~70~30~41 ~70~30~47 minecraft:clay
fill ~16~27~42 ~17~27~42 minecraft:stone ["stone_type":"stone"]
setblock ~17~22~42 minecraft:stone ["stone_type":"stone"]
fill ~17~30~42 ~17~30~57 minecraft:stone ["stone_type":"stone"]
fill ~18~24~42 ~22~25~43 minecraft:stone ["stone_type":"stone"]
fill ~18~26~42 ~22~26~42 minecraft:stone ["stone_type":"stone"]
fill ~19~33~42 ~20~33~43 minecraft:stone ["stone_type":"stone"]
setblock ~20~34~42 minecraft:stained_hardened_clay ["color":"cyan"]
fill ~22~23~42 ~26~23~42 minecraft:stone ["stone_type":"stone"]
fill ~23~22~42 ~26~22~42 minecraft:stone ["stone_type":"stone"]
fill ~25~40~42 ~25~40~43 minecraft:wool 15
fill ~26~39~42 ~26~39~48 minecraft:stone ["stone_type":"stone"]
fill ~27~18~42 ~30~18~47 minecraft:stone ["stone_type":"stone"]
fill ~27~19~42 ~27~20~62 minecraft:stone ["stone_type":"stone"]
fill ~27~21~42 ~27~21~60 minecraft:stone ["stone_type":"stone"]
fill ~28~34~42 ~28~35~42 minecraft:stone ["stone_type":"stone"]
fill ~29~35~42 ~29~35~62 minecraft:stone ["stone_type":"stone"]
fill ~29~38~42 ~32~38~46 minecraft:stone ["stone_type":"stone"]
fill ~29~39~42 ~33~39~46 minecraft:concrete ["color":"gray"]
fill ~35~38~42 ~35~38~46 minecraft:stone ["stone_type":"stone"]
setblock ~38~41~42 minecraft:stone_block_slab ["stone_slab_type":"stone_brick","top_slot_bit":false]
fill ~41~40~42 ~41~40~45 minecraft:stone ["stone_type":"stone"]
setblock ~41~43~42 minecraft:stone_brick_stairs ["upside_down_bit":false,"weirdo_direction":2]
setblock ~44~43~42 minecraft:stone_brick_stairs ["upside_down_bit":false,"weirdo_direction":2]
setblock ~47~41~42 minecraft:stone_block_slab ["stone_slab_type":"stone_brick","top_slot_bit":false]
fill ~50~38~42 ~51~38~45 minecraft:stone ["stone_type":"stone"]
fill ~52~39~42 ~56~39~46 minecraft:concrete ["color":"gray"]
fill ~54~38~42 ~56~38~46 minecraft:stone ["stone_type":"stone"]
fill ~55~18~42 ~58~18~47 minecraft:stone ["stone_type":"stone"]
setblock ~57~34~42 minecraft:stone ["stone_type":"stone"]
fill ~58~19~42 ~58~20~62 minecraft:stone ["stone_type":"stone"]
fill ~58~21~42 ~58~21~60 minecraft:stone ["stone_type":"stone"]
fill ~59~22~42 ~62~23~42 minecraft:stone ["stone_type":"stone"]
fill ~59~39~42 ~59~39~48 minecraft:stone ["stone_type":"stone"]
fill ~59~40~42 ~59~40~43 minecraft:wool 15
fill ~63~23~42 ~63~26~42 minecraft:stone ["stone_type":"stone"]
fill ~64~24~42 ~67~25~43 minecraft:stone ["stone_type":"stone"]
fill ~64~26~42 ~67~26~42 minecraft:stone ["stone_type":"stone"]
fill ~66~33~42 ~66~33~52 minecraft:stone ["stone_type":"stone"]
setblock ~68~22~42 minecraft:stone ["stone_type":"stone"]
fill ~68~27~42 ~69~27~42 minecraft:stone ["stone_type":"stone"]
fill ~68~30~42 ~68~30~57 minecraft:stone ["stone_type":"stone"]
fill ~15~29~43 ~15~29~44 minecraft:stone_block_slab ["stone_slab_type":"nether_brick","top_slot_bit":true]
fill ~16~19~43 ~21~22~43 minecraft:coal_block
fill ~16~24~43 ~17~24~43 minecraft:stone ["stone_type":"stone"]
fill ~16~25~43 ~16~28~43 minecraft:stone ["stone_type":"stone"]
fill ~16~29~43 ~16~29~44 minecraft:stone_block_slab ["stone_slab_type":"nether_brick","top_slot_bit":false]
fill ~16~34~43 ~16~34~44 minecraft:stone_block_slab ["stone_slab_type":"nether_brick","top_slot_bit":false]
fill ~17~33~43 ~17~33~44 minecraft:stone_block_slab ["stone_slab_type":"nether_brick","top_slot_bit":true]
fill ~18~32~43 ~18~32~53 minecraft:stone ["stone_type":"stone"]
fill ~18~33~43 ~18~33~44 minecraft:stone_block_slab ["stone_slab_type":"nether_brick","top_slot_bit":false]
fill ~20~34~43 ~20~34~63 minecraft:stone ["stone_type":"stone"]
fill ~23~24~43 ~26~25~43 minecraft:stone ["stone_type":"stone"]
fill ~25~39~43 ~25~39~50 minecraft:stone ["stone_type":"stone"]
fill ~27~41~43 ~27~41~46 minecraft:wool ["color":"gray"]
fill ~28~35~43 ~28~35~62 minecraft:stone ["stone_type":"stone"]
fill ~36~38~43 ~36~38~47 minecraft:stone ["stone_type":"stone"]
setblock ~40~41~43 minecraft:stone_block_slab ["stone_slab_type":"stone_brick","top_slot_bit":false]
fill ~41~41~43 ~44~42~43 minecraft:stained_hardened_clay ["color":"cyan"]
setblock ~41~43~43 minecraft:stone_brick_stairs ["upside_down_bit":false,"weirdo_direction":1]
fill ~42~40~43 ~42~40~45 minecraft:stone ["stone_type":"stone"]
fill ~42~43~43 ~43~43~43 minecraft:stone_brick_stairs ["upside_down_bit":false,"weirdo_direction":2]
setblock ~44~43~43 minecraft:stone_brick_stairs ["upside_down_bit":false,"weirdo_direction":0]
fill ~45~40~43 ~46~40~44 minecraft:stone ["stone_type":"stone"]
setblock ~45~41~43 minecraft:stone_block_slab ["stone_slab_type":"stone_brick","top_slot_bit":false]
fill ~58~41~43 ~58~41~48 minecraft:wool ["color":"gray"]
fill ~59~24~43 ~63~25~43 minecraft:stone ["stone_type":"stone"]
fill ~60~36~43 ~60~36~45 minecraft:stone_block_slab ["stone_slab_type":"smooth_stone","top_slot_bit":false]
fill ~60~39~43 ~60~39~50 minecraft:stone ["stone_type":"stone"]
fill ~61~35~43 ~61~35~45 minecraft:double_stone_block_slab ["stone_slab_type":"smooth_stone","top_slot_bit":false]
fill ~62~35~43 ~62~35~62 minecraft:stone ["stone_type":"stone"]
fill ~62~36~43 ~62~36~45 minecraft:stone_block_slab ["stone_slab_type":"smooth_stone","top_slot_bit":false]
fill ~63~35~43 ~64~35~45 minecraft:double_stone_block_slab ["stone_slab_type":"smooth_stone","top_slot_bit":false]
fill ~64~19~43 ~69~22~43 minecraft:coal_block
fill ~64~36~43 ~64~36~45 minecraft:stone_block_slab ["stone_slab_type":"smooth_stone","top_slot_bit":false]
fill ~67~32~43 ~67~32~53 minecraft:stone ["stone_type":"stone"]
fill ~67~33~43 ~67~33~44 minecraft:stone_block_slab ["stone_slab_type":"nether_brick","top_slot_bit":false]
fill ~68~24~43 ~69~24~43 minecraft:stone ["stone_type":"stone"]
fill ~68~33~43 ~68~33~44 minecraft:stone_block_slab ["stone_slab_type":"nether_brick","top_slot_bit":true]
fill ~69~25~43 ~69~28~43 minecraft:stone ["stone_type":"stone"]
fill ~69~29~43 ~69~29~44 minecraft:stone_block_slab ["stone_slab_type":"nether_brick","top_slot_bit":false]
fill ~69~34~43 ~69~34~44 minecraft:stone_block_slab ["stone_slab_type":"nether_brick","top_slot_bit":false]
fill ~70~29~43 ~70~29~44 minecraft:stone_block_slab ["stone_slab_type":"nether_brick","top_slot_bit":true]
fill ~15~19~44 ~15~22~45 minecraft:coal_block
fill ~16~17~44 ~21~18~44 minecraft:coal_block
fill ~16~23~44 ~21~24~44 minecraft:coal_block
fill ~16~26~44 ~26~27~44 minecraft:stone ["stone_type":"stone"]
fill ~16~28~44 ~16~28~46 minecraft:stone ["stone_type":"stone"]
fill ~17~31~44 ~17~31~52 minecraft:stone ["stone_type":"stone"]
fill ~18~35~44 ~21~37~44 minecraft:stained_hardened_clay ["color":"cyan"]
fill ~19~33~44 ~19~34~45 minecraft:stained_hardened_clay ["color":"cyan"]
fill ~19~38~44 ~20~38~45 minecraft:stained_hardened_clay ["color":"cyan"]
fill ~20~33~44 ~20~33~45 minecraft:stone ["stone_type":"stone"]
fill ~22~19~44 ~22~22~45 minecraft:coal_block
fill ~24~34~44 ~25~34~47 minecraft:stone ["stone_type":"stone"]
fill ~24~39~44 ~24~39~48 minecraft:stone ["stone_type":"stone"]
fill ~25~36~44 ~25~37~46 minecraft:clay
fill ~26~19~44 ~26~19~46 minecraft:coal_block
fill ~26~20~44 ~26~21~44 minecraft:coal_block
setblock ~26~40~44 minecraft:wool 15
fill ~28~40~44 ~33~40~44 minecraft:stone_button ["button_pressed_bit":false,"facing_direction":1]
fill ~29~36~44 ~29~37~46 minecraft:stone ["stone_type":"stone"]
fill ~33~16~44 ~37~16~68 minecraft:stone ["stone_type":"stone"]
fill ~36~36~44 ~36~36~47 minecraft:stone ["stone_type":"stone"]
fill ~36~37~44 ~36~37~46 minecraft:stone ["stone_type":"stone"]
fill ~36~40~44 ~36~40~45 minecraft:wool 15
setblock ~39~41~44 minecraft:stone_block_slab ["stone_slab_type":"stone_brick","top_slot_bit":false]
fill ~42~41~44 ~43~41~44 minecraft:stone_block_slab ["stone_slab_type":"stone_brick","top_slot_bit":false]
fill ~43~40~44 ~44~40~45 minecraft:stone ["stone_type":"stone"]
setblock ~46~41~44 minecraft:stone_block_slab ["stone_slab_type":"stone_brick","top_slot_bit":false]
fill ~48~16~44 ~52~16~68 minecraft:stone ["stone_type":"stone"]
fill ~49~40~44 ~49~40~45 minecraft:wool 15
fill ~52~40~44 ~57~40~44 minecraft:stone_button ["button_pressed_bit":false,"facing_direction":1]
fill ~58~40~44 ~58~40~45 minecraft:wool 15
fill ~59~19~44 ~59~19~46 minecraft:coal_block
fill ~59~20~44 ~59~21~44 minecraft:coal_block
fill ~59~26~44 ~69~27~44 minecraft:stone ["stone_type":"stone"]
fill ~60~34~44 ~61~34~47 minecraft:stone ["stone_type":"stone"]
fill ~61~39~44 ~61~39~48 minecraft:stone ["stone_type":"stone"]
fill ~63~19~44 ~63~22~45 minecraft:coal_block
fill ~64~17~44 ~69~18~44 minecraft:coal_block
fill ~64~23~44 ~69~24~44 minecraft:coal_block
fill ~68~31~44 ~68~31~52 minecraft:stone ["stone_type":"stone"]
fill ~69~28~44 ~69~28~46 minecraft:stone ["stone_type":"stone"]
fill ~70~19~44 ~70~22~45 minecraft:coal_block
fill ~15~17~45 ~15~18~46 minecraft:coal_block
fill ~15~23~45 ~15~24~46 minecraft:coal_block
fill ~15~28~45 ~15~28~46 minecraft:stone ["stone_type":"stone"]
fill ~16~15~45 ~21~16~45 minecraft:coal_block
fill ~16~19~45 ~21~22~45 minecraft:stone ["stone_type":"stone"]
fill ~16~25~45 ~21~26~45 minecraft:coal_block
fill ~16~29~45 ~16~29~48 minecraft:stone ["stone_type":"stone"]
fill ~18~28~45 ~26~28~46 minecraft:stone ["stone_type":"stone"]
fill ~18~35~45 ~20~37~45 minecraft:stained_hardened_clay ["color":"cyan"]
fill ~21~35~45 ~21~35~62 minecraft:stone ["stone_type":"stone"]
fill ~21~36~45 ~21~37~45 minecraft:stained_hardened_clay ["color":"cyan"]
fill ~22~17~45 ~22~18~46 minecraft:coal_block
fill ~22~23~45 ~22~24~46 minecraft:coal_block
fill ~24~20~45 ~26~20~45 minecraft:stone ["stone_type":"andesite"]
fill ~24~36~45 ~24~37~45 minecraft:clay
setblock ~24~38~45 minecraft:stone_button ["button_pressed_bit":false,"facing_direction":1]
fill ~26~21~45 ~26~21~46 minecraft:coal_block
fill ~26~36~45 ~26~37~45 minecraft:clay
setblock ~26~38~45 minecraft:stone_button ["button_pressed_bit":false,"facing_direction":1]
setblock ~27~40~45 minecraft:wool 15
setblock ~37~17~45 minecraft:stone ["stone_type":"stone"]
setblock ~41~41~45 minecraft:stone_block_slab ["stone_slab_type":"stone_brick","top_slot_bit":false]
setblock ~44~41~45 minecraft:stone_block_slab ["stone_slab_type":"stone_brick","top_slot_bit":false]
setblock ~48~17~45 minecraft:stone ["stone_type":"stone"]
fill ~59~20~45 ~61~20~45 minecraft:stone ["stone_type":"andesite"]
fill ~59~21~45 ~59~21~46 minecraft:coal_block
fill ~59~28~45 ~67~28~46 minecraft:stone ["stone_type":"stone"]
setblock ~60~38~45 minecraft:stone ["stone_type":"stone"]
fill ~63~17~45 ~63~18~46 minecraft:coal_block
fill ~63~23~45 ~63~24~46 minecraft:coal_block
fill ~64~15~45 ~69~16~45 minecraft:coal_block
fill ~64~19~45 ~69~22~45 minecraft:stone ["stone_type":"stone"]
fill ~64~25~45 ~69~26~45 minecraft:coal_block
fill ~69~29~45 ~69~29~48 minecraft:stone ["stone_type":"stone"]
fill ~70~17~45 ~70~18~46 minecraft:coal_block
fill ~70~23~45 ~70~24~46 minecraft:coal_block
fill ~70~28~45 ~70~28~46 minecraft:stone ["stone_type":"stone"]
fill ~70~33~45 ~70~33~63 minecraft:iron_bars
fill ~15~15~46 ~15~15~49 minecraft:coal_block
fill ~15~16~46 ~15~16~47 minecraft:coal_block
fill ~15~19~46 ~15~22~46 minecraft:stone ["stone_type":"stone"]
fill ~15~25~46 ~15~26~47 minecraft:coal_block
fill ~15~29~46 ~15~29~48 minecraft:stone ["stone_type":"stone"]
fill ~15~33~46 ~15~33~63 minecraft:iron_bars
fill ~16~14~46 ~21~14~47 minecraft:coal_block
fill ~16~17~46 ~21~18~46 minecraft:stone ["stone_type":"stone"]
fill ~16~23~46 ~21~24~46 minecraft:stone ["stone_type":"stone"]
fill ~16~27~46 ~21~27~47 minecraft:coal_block
fill ~16~30~46 ~16~30~51 minecraft:stone ["stone_type":"stone"]
fill ~19~33~46 ~19~34~52 minecraft:stone ["stone_type":"stone"]
fill ~22~15~46 ~22~15~49 minecraft:coal_block
fill ~22~16~46 ~22~16~47 minecraft:coal_block
fill ~22~19~46 ~22~22~46 minecraft:stone ["stone_type":"stone"]
fill ~22~25~46 ~22~26~47 minecraft:coal_block
fill ~24~20~46 ~24~20~48 minecraft:stone ["stone_type":"andesite"]
setblock ~25~38~46 minecraft:stone_button ["button_pressed_bit":false,"facing_direction":1]
setblock ~26~20~46 minecraft:coal_block
fill ~26~40~46 ~26~40~56 minecraft:stone ["stone_type":"stone"]
fill ~28~40~46 ~28~40~47 minecraft:wool 15
setblock ~30~37~46 minecraft:stone ["stone_type":"stone"]
setblock ~32~37~46 minecraft:stone ["stone_type":"stone"]
fill ~34~36~46 ~34~38~46 minecraft:stained_hardened_clay ["color":"cyan"]
fill ~35~36~46 ~35~37~46 minecraft:stone ["stone_type":"stone"]
fill ~35~40~46 ~35~40~47 minecraft:wool 15
fill ~37~38~46 ~50~38~46 minecraft:stone ["stone_type":"stone"]
fill ~39~37~46 ~47~37~46 minecraft:stone ["stone_type":"stone"]
fill ~50~40~46 ~50~40~47 minecraft:wool 15
fill ~51~36~46 ~51~38~46 minecraft:stained_hardened_clay ["color":"cyan"]
setblock ~54~37~46 minecraft:stone ["stone_type":"stone"]
fill ~56~36~46 ~56~37~46 minecraft:stone ["stone_type":"stone"]
fill ~58~39~46 ~58~39~47 minecraft:wool 15
setblock ~59~20~46 minecraft:coal_block
fill ~59~40~46 ~59~40~56 minecraft:stone ["stone_type":"stone"]
fill ~61~20~46 ~61~20~48 minecraft:stone ["stone_type":"andesite"]
fill ~61~35~46 ~61~35~62 minecraft:stone ["stone_type":"stone"]
fill ~63~15~46 ~63~15~49 minecraft:coal_block
fill ~63~16~46 ~63~16~47 minecraft:coal_block
fill ~63~19~46 ~63~22~46 minecraft:stone ["stone_type":"stone"]
fill ~63~25~46 ~63~26~47 minecraft:coal_block
fill ~63~35~46 ~64~35~51 minecraft:stone ["stone_type":"stone"]
fill ~64~14~46 ~69~14~47 minecraft:coal_block
fill ~64~17~46 ~69~18~46 minecraft:stone ["stone_type":"stone"]
fill ~64~23~46 ~69~24~46 minecraft:stone ["stone_type":"stone"]
fill ~64~27~46 ~69~27~47 minecraft:coal_block
fill ~66~34~46 ~66~34~100 minecraft:stone ["stone_type":"stone"]
fill ~69~30~46 ~69~30~51 minecraft:stone ["stone_type":"stone"]
fill ~70~15~46 ~70~15~49 minecraft:coal_block
fill ~70~16~46 ~70~16~47 minecraft:coal_block
fill ~70~19~46 ~70~22~46 minecraft:stone ["stone_type":"stone"]
fill ~70~25~46 ~70~26~47 minecraft:coal_block
fill ~70~29~46 ~70~29~48 minecraft:stone ["stone_type":"stone"]
fill ~15~17~47 ~15~18~47 minecraft:stone ["stone_type":"stone"]
fill ~15~21~47 ~15~21~50 minecraft:stone ["stone_type":"stone"]
fill ~15~23~47 ~15~23~48 minecraft:stone ["stone_type":"stone"]
setblock ~15~24~47 minecraft:stone ["stone_type":"stone"]
fill ~15~31~47 ~15~31~59 minecraft:clay
fill ~16~16~47 ~21~16~47 minecraft:stone ["stone_type":"stone"]
fill ~16~25~47 ~21~25~47 minecraft:stone ["stone_type":"stone"]
fill ~17~29~47 ~26~29~48 minecraft:stone ["stone_type":"stone"]
fill ~18~19~47 ~18~22~47 minecraft:stonebrick ["stone_brick_type":"default"]
fill ~18~30~47 ~25~30~54 minecraft:stone ["stone_type":"stone"]
fill ~18~33~47 ~18~33~66 minecraft:stone ["stone_type":"stone"]
fill ~22~17~47 ~22~18~47 minecraft:stone ["stone_type":"stone"]
fill ~22~23~47 ~22~24~47 minecraft:stone ["stone_type":"stone"]
fill ~26~41~47 ~26~41~49 minecraft:wool ["color":"gray"]
fill ~29~36~47 ~33~38~47 minecraft:concrete ["color":"gray"]
fill ~30~39~47 ~31~39~49 minecraft:double_stone_block_slab ["stone_slab_type":"smooth_stone","top_slot_bit":false]
fill ~35~34~47 ~36~34~57 minecraft:stone ["stone_type":"stone"]
fill ~35~36~47 ~35~38~47 minecraft:stained_hardened_clay ["color":"cyan"]
fill ~37~36~47 ~37~38~48 minecraft:stone ["stone_type":"stone"]
fill ~38~38~47 ~40~38~50 minecraft:stone ["stone_type":"stone"]
fill ~38~39~47 ~42~39~47 minecraft:stained_hardened_clay ["color":"cyan"]
fill ~39~40~47 ~46~40~51 minecraft:stonebrick ["stone_brick_type":"default"]
fill ~40~36~47 ~45~37~47 minecraft:stone ["stone_type":"stone"]
fill ~43~39~47 ~46~39~47 minecraft:stone ["stone_type":"stone"]
fill ~45~38~47 ~45~38~55 minecraft:stone ["stone_type":"stone"]
fill ~47~38~47 ~49~38~47 minecraft:stone ["stone_type":"stone"]
setblock ~47~39~47 minecraft:stained_hardened_clay ["color":"cyan"]
fill ~49~34~47 ~50~34~56 minecraft:stone ["stone_type":"stone"]
fill ~49~36~47 ~49~37~47 minecraft:stone ["stone_type":"stone"]
fill ~50~36~47 ~50~38~47 minecraft:stained_hardened_clay ["color":"cyan"]
fill ~52~36~47 ~56~37~47 minecraft:concrete ["color":"gray"]
fill ~52~38~47 ~53~38~47 minecraft:concrete ["color":"gray"]
fill ~54~38~47 ~55~38~47 minecraft:stone ["stone_type":"stone"]
fill ~54~39~47 ~55~39~49 minecraft:double_stone_block_slab ["stone_slab_type":"smooth_stone","top_slot_bit":false]
setblock ~56~38~47 minecraft:concrete ["color":"gray"]
fill ~59~29~47 ~68~29~48 minecraft:stone ["stone_type":"stone"]
fill ~60~30~47 ~67~30~54 minecraft:stone ["stone_type":"stone"]
fill ~60~36~47 ~60~38~49 minecraft:clay
fill ~63~17~47 ~63~18~47 minecraft:stone ["stone_type":"stone"]
fill ~63~23~47 ~63~24~47 minecraft:stone ["stone_type":"stone"]
fill ~63~36~47 ~65~36~47 minecraft:stone_block_slab ["stone_slab_type":"smooth_stone","top_slot_bit":false]
fill ~64~16~47 ~69~16~47 minecraft:stone ["stone_type":"stone"]
fill ~64~25~47 ~69~25~47 minecraft:stone ["stone_type":"stone"]
fill ~65~35~47 ~65~35~49 minecraft:double_stone_block_slab ["stone_slab_type":"smooth_stone","top_slot_bit":false]
fill ~67~19~47 ~67~22~47 minecraft:stonebrick ["stone_brick_type":"default"]
fill ~67~33~47 ~67~33~115 minecraft:stone ["stone_type":"stone"]
fill ~70~17~47 ~70~18~47 minecraft:stone ["stone_type":"stone"]
fill ~70~21~47 ~70~21~50 minecraft:stone ["stone_type":"stone"]
fill ~70~23~47 ~70~23~48 minecraft:stone ["stone_type":"stone"]
setblock ~70~24~47 minecraft:stone ["stone_type":"stone"]
fill ~70~31~47 ~70~31~59 minecraft:clay
fill ~15~14~48 ~15~14~55 minecraft:coal_block
fill ~15~16~48 ~15~16~49 minecraft:stone ["stone_type":"stone"]
fill ~15~19~48 ~15~19~49 minecraft:stone ["stone_type":"stone"]
fill ~15~25~48 ~15~25~49 minecraft:stone ["stone_type":"stone"]
fill ~15~26~48 ~15~27~49 minecraft:coal_block
fill ~15~30~48 ~15~30~62 minecraft:stone ["stone_type":"stone"]
fill ~16~13~48 ~21~13~49 minecraft:coal_block
fill ~16~15~48 ~21~15~49 minecraft:stone ["stone_type":"stone"]
fill ~16~26~48 ~21~26~49 minecraft:stone ["stone_type":"stone"]
fill ~16~28~48 ~21~28~49 minecraft:coal_block
fill ~17~19~48 ~17~19~55 minecraft:stone ["stone_type":"andesite"]
fill ~17~20~48 ~17~22~50 minecraft:stone ["stone_type":"andesite"]
fill ~17~32~48 ~17~32~99 minecraft:stone ["stone_type":"stone"]
setblock ~18~18~48 minecraft:stonebrick ["stone_brick_type":"default"]
setblock ~18~23~48 minecraft:stonebrick ["stone_brick_type":"default"]
fill ~19~19~48 ~20~19~48 minecraft:stonebrick ["stone_brick_type":"default"]
fill ~19~20~48 ~19~22~50 minecraft:stonebrick ["stone_brick_type":"default"]
setblock ~20~18~48 minecraft:stone_button ["button_pressed_bit":false,"facing_direction":0]
fill ~20~20~48 ~23~20~48 minecraft:stone ["stone_type":"andesite"]
setblock ~20~21~48 minecraft:stonebrick ["stone_brick_type":"default"]
setblock ~20~22~48 minecraft:stone_button ["button_pressed_bit":false,"facing_direction":1]
fill ~22~14~48 ~22~14~55 minecraft:coal_block
fill ~22~16~48 ~22~16~49 minecraft:stone ["stone_type":"stone"]
fill ~22~25~48 ~22~25~49 minecraft:stone ["stone_type":"stone"]
fill ~22~26~48 ~22~27~49 minecraft:coal_block
fill ~24~34~48 ~24~34~60 minecraft:stone ["stone_type":"stone"]
fill ~25~36~48 ~25~37~50 minecraft:clay
setblock ~25~38~48 minecraft:stone_button ["button_pressed_bit":false,"facing_direction":1]
fill ~25~40~48 ~25~40~55 minecraft:stone ["stone_type":"stone"]
fill ~27~18~48 ~29~18~48 minecraft:stone ["stone_type":"andesite"]
fill ~27~40~48 ~27~40~53 minecraft:stone ["stone_type":"stone"]
fill ~28~39~48 ~28~39~49 minecraft:wool 15
fill ~29~36~48 ~29~36~50 minecraft:obsidian
fill ~30~18~48 ~30~18~52 minecraft:stone ["stone_type":"stone"]
fill ~30~38~48 ~31~38~49 minecraft:double_stone_block_slab ["stone_slab_type":"smooth_stone","top_slot_bit":false]
fill ~33~34~48 ~34~34~57 minecraft:stone ["stone_type":"stone"]
setblock ~35~39~48 minecraft:wool 15
fill ~36~36~48 ~36~40~48 minecraft:double_stone_block_slab ["stone_slab_type":"smooth_stone","top_slot_bit":false]
fill ~36~41~48 ~39~41~48 minecraft:stone_block_slab ["stone_slab_type":"smooth_stone","top_slot_bit":false]
fill ~37~39~48 ~41~39~48 minecraft:stone ["stone_type":"stone"]
fill ~37~40~48 ~38~40~48 minecraft:double_stone_block_slab ["stone_slab_type":"smooth_stone","top_slot_bit":false]
fill ~38~36~48 ~40~37~48 minecraft:stone ["stone_type":"stone"]
fill ~41~38~48 ~44~38~48 minecraft:stone ["stone_type":"stone"]
fill ~41~41~48 ~44~41~51 minecraft:clay
fill ~45~36~48 ~45~36~50 minecraft:stone ["stone_type":"stone"]
fill ~45~37~48 ~48~37~48 minecraft:stone ["stone_type":"stone"]
fill ~45~39~48 ~48~39~50 minecraft:stone ["stone_type":"stone"]
fill ~46~38~48 ~48~38~52 minecraft:stone ["stone_type":"stone"]
fill ~46~41~48 ~49~41~48 minecraft:stone_block_slab ["stone_slab_type":"smooth_stone","top_slot_bit":false]
fill ~47~36~48 ~48~36~48 minecraft:stone ["stone_type":"stone"]
fill ~47~40~48 ~49~40~48 minecraft:double_stone_block_slab ["stone_slab_type":"smooth_stone","top_slot_bit":false]
fill ~49~36~48 ~49~39~48 minecraft:double_stone_block_slab ["stone_slab_type":"smooth_stone","top_slot_bit":false]
setblock ~50~39~48 minecraft:wool 15
fill ~51~34~48 ~52~34~56 minecraft:stone ["stone_type":"stone"]
fill ~54~38~48 ~55~38~49 minecraft:double_stone_block_slab ["stone_slab_type":"smooth_stone","top_slot_bit":false]
fill ~55~18~48 ~55~18~52 minecraft:stone ["stone_type":"stone"]
fill ~56~18~48 ~58~18~48 minecraft:stone ["stone_type":"andesite"]
fill ~56~36~48 ~56~36~50 minecraft:obsidian
fill ~58~38~48 ~58~38~50 minecraft:wool 15
fill ~58~40~48 ~58~40~53 minecraft:stone ["stone_type":"stone"]
fill ~59~36~48 ~59~38~48 minecraft:clay
fill ~60~40~48 ~60~40~55 minecraft:stone ["stone_type":"stone"]
fill ~61~34~48 ~61~34~56 minecraft:stone ["stone_type":"stone"]
fill ~61~36~48 ~61~38~48 minecraft:clay
fill ~62~20~48 ~65~20~48 minecraft:stone ["stone_type":"andesite"]
fill ~63~14~48 ~63~14~55 minecraft:coal_block
fill ~63~16~48 ~63~16~49 minecraft:stone ["stone_type":"stone"]
fill ~63~25~48 ~63~25~49 minecraft:stone ["stone_type":"stone"]
fill ~63~26~48 ~63~27~49 minecraft:coal_block
fill ~63~36~48 ~63~36~49 minecraft:stone_block_slab ["stone_slab_type":"smooth_stone","top_slot_bit":false]
fill ~64~13~48 ~69~13~49 minecraft:coal_block
fill ~64~15~48 ~69~15~49 minecraft:stone ["stone_type":"stone"]
fill ~64~26~48 ~69~26~49 minecraft:stone ["stone_type":"stone"]
fill ~64~28~48 ~69~28~49 minecraft:coal_block
setblock ~64~36~48 minecraft:clay
setblock ~64~37~48 minecraft:stone_button ["button_pressed_bit":false,"facing_direction":1]
setblock ~65~18~48 minecraft:stone_button ["button_pressed_bit":false,"facing_direction":0]
fill ~65~19~48 ~66~19~48 minecraft:stonebrick ["stone_brick_type":"default"]
fill ~65~21~48 ~66~21~48 minecraft:stonebrick ["stone_brick_type":"default"]
setblock ~65~22~48 minecraft:stone_button ["button_pressed_bit":false,"facing_direction":1]
fill ~65~36~48 ~65~36~49 minecraft:stone_block_slab ["stone_slab_type":"smooth_stone","top_slot_bit":false]
fill ~66~20~48 ~66~20~50 minecraft:stonebrick ["stone_brick_type":"default"]
fill ~66~22~48 ~66~22~55 minecraft:stonebrick ["stone_brick_type":"default"]
setblock ~67~18~48 minecraft:stonebrick ["stone_brick_type":"default"]
setblock ~67~23~48 minecraft:stonebrick ["stone_brick_type":"default"]
fill ~68~19~48 ~68~19~55 minecraft:stone ["stone_type":"andesite"]
fill ~68~20~48 ~68~22~50 minecraft:stone ["stone_type":"andesite"]
fill ~68~32~48 ~68~32~99 minecraft:stone ["stone_type":"stone"]
fill ~70~14~48 ~70~14~55 minecraft:coal_block
fill ~70~16~48 ~70~16~49 minecraft:stone ["stone_type":"stone"]
fill ~70~19~48 ~70~19~49 minecraft:stone ["stone_type":"stone"]
fill ~70~25~48 ~70~25~49 minecraft:stone ["stone_type":"stone"]
fill ~70~26~48 ~70~27~49 minecraft:coal_block
fill ~70~30~48 ~70~30~62 minecraft:stone ["stone_type":"stone"]
setblock ~15~17~49 minecraft:stone ["stone_type":"stone"]
setblock ~15~22~49 minecraft:stone ["stone_type":"stone"]
fill ~16~31~49 ~16~31~67 minecraft:stone ["stone_type":"stone"]
fill ~17~18~49 ~17~18~54 minecraft:stone ["stone_type":"andesite"]
fill ~17~23~49 ~17~23~54 minecraft:stone ["stone_type":"andesite"]
setblock ~18~17~49 minecraft:stonebrick ["stone_brick_type":"default"]
setblock ~18~24~49 minecraft:stonebrick ["stone_brick_type":"default"]
fill ~18~36~49 ~18~36~54 minecraft:wool ["color":"yellow"]
fill ~19~18~49 ~19~19~54 minecraft:stonebrick ["stone_brick_type":"default"]
fill ~19~23~49 ~19~23~54 minecraft:stonebrick ["stone_brick_type":"default"]
fill ~20~39~49 ~20~39~54 minecraft:wool ["color":"yellow"]
fill ~23~40~49 ~23~40~54 minecraft:wool ["color":"gray"]
fill ~24~17~49 ~26~17~49 minecraft:stone ["stone_type":"andesite"]
fill ~24~25~49 ~26~25~49 minecraft:stone ["stone_type":"andesite"]
fill ~24~36~49 ~24~37~49 minecraft:clay
setblock ~24~38~49 minecraft:stone_button ["button_pressed_bit":false,"facing_direction":1]
fill ~26~30~49 ~26~30~55 minecraft:stone ["stone_type":"stone"]
setblock ~26~37~49 minecraft:clay
setblock ~26~38~49 minecraft:stone_button ["button_pressed_bit":false,"facing_direction":1]
fill ~27~17~49 ~32~17~59 minecraft:stone ["stone_type":"stone"]
fill ~27~18~49 ~29~18~52 minecraft:stone ["stone_type":"stone"]
fill ~31~34~49 ~32~34~57 minecraft:stone ["stone_type":"stone"]
fill ~32~38~49 ~35~39~49 minecraft:double_stone_block_slab ["stone_slab_type":"smooth_stone","top_slot_bit":false]
fill ~34~17~49 ~37~17~52 minecraft:stone ["stone_type":"stone"]
fill ~35~36~49 ~35~37~55 minecraft:stained_hardened_clay ["color":"cyan"]
fill ~35~40~49 ~35~40~55 minecraft:stained_hardened_clay ["color":"cyan"]
fill ~36~37~49 ~36~40~49 minecraft:stone ["stone_type":"stone"]
fill ~36~41~49 ~36~41~51 minecraft:stone_block_slab ["stone_slab_type":"smooth_stone","top_slot_bit":false]
fill ~37~38~49 ~37~40~49 minecraft:stone ["stone_type":"stone"]
fill ~37~41~49 ~38~42~50 minecraft:obsidian
fill ~38~39~49 ~40~39~49 minecraft:stone ["stone_type":"stone"]
fill ~38~40~49 ~38~40~50 minecraft:stone ["stone_type":"stone"]
fill ~38~43~49 ~39~43~50 minecraft:obsidian
fill ~39~17~49 ~41~17~52 minecraft:stone ["stone_type":"stone"]
fill ~39~36~49 ~40~36~50 minecraft:stone ["stone_type":"stone"]
fill ~39~37~49 ~40~37~49 minecraft:stone ["stone_type":"stone"]
fill ~39~41~49 ~39~41~51 minecraft:stone_block_slab ["stone_slab_type":"smooth_stone","top_slot_bit":false]
fill ~39~42~49 ~39~42~50 minecraft:obsidian
fill ~40~42~49 ~45~43~50 minecraft:stone ["stone_type":"stone"]
fill ~42~36~49 ~43~39~50 minecraft:stone ["stone_type":"stone"]
fill ~44~17~49 ~46~17~52 minecraft:stone ["stone_type":"stone"]
fill ~45~37~49 ~46~37~49 minecraft:stone ["stone_type":"stone"]
fill ~46~36~49 ~47~36~50 minecraft:stone ["stone_type":"stone"]
fill ~46~41~49 ~46~41~51 minecraft:stone_block_slab ["stone_slab_type":"smooth_stone","top_slot_bit":false]
fill ~46~42~49 ~48~42~50 minecraft:obsidian
fill ~46~43~49 ~47~43~50 minecraft:obsidian
fill ~47~40~49 ~49~40~50 minecraft:stone ["stone_type":"stone"]
fill ~47~41~49 ~48~41~50 minecraft:obsidian
fill ~48~17~49 ~51~17~52 minecraft:stone ["stone_type":"stone"]
fill ~49~38~49 ~49~39~55 minecraft:stone ["stone_type":"stone"]
fill ~49~41~49 ~49~41~51 minecraft:stone_block_slab ["stone_slab_type":"smooth_stone","top_slot_bit":false]
fill ~50~36~49 ~50~37~55 minecraft:stained_hardened_clay ["color":"cyan"]
fill ~50~38~49 ~53~39~49 minecraft:double_stone_block_slab ["stone_slab_type":"smooth_stone","top_slot_bit":false]
fill ~50~40~49 ~50~40~55 minecraft:stained_hardened_clay ["color":"cyan"]
fill ~53~17~49 ~58~17~59 minecraft:stone ["stone_type":"stone"]
fill ~53~34~49 ~54~34~56 minecraft:stone ["stone_type":"stone"]
fill ~56~18~49 ~58~18~52 minecraft:stone ["stone_type":"stone"]
fill ~57~40~49 ~57~40~51 minecraft:wool ["color":"gray"]
fill ~59~17~49 ~61~17~49 minecraft:stone ["stone_type":"andesite"]
fill ~59~25~49 ~61~25~49 minecraft:stone ["stone_type":"andesite"]
fill ~59~30~49 ~59~30~55 minecraft:stone ["stone_type":"stone"]
setblock ~64~36~49 minecraft:stone_block_slab ["stone_slab_type":"smooth_stone","top_slot_bit":false]
fill ~66~18~49 ~66~19~54 minecraft:stonebrick ["stone_brick_type":"default"]
fill ~66~21~49 ~66~21~50 minecraft:stonebrick ["stone_brick_type":"default"]
fill ~66~23~49 ~66~23~54 minecraft:stonebrick ["stone_brick_type":"default"]
setblock ~67~17~49 minecraft:stonebrick ["stone_brick_type":"default"]
setblock ~67~24~49 minecraft:stonebrick ["stone_brick_type":"default"]
fill ~68~18~49 ~68~18~54 minecraft:stone ["stone_type":"andesite"]
fill ~68~23~49 ~68~23~54 minecraft:stone ["stone_type":"andesite"]
fill ~69~31~49 ~69~31~67 minecraft:stone ["stone_type":"stone"]
setblock ~70~17~49 minecraft:stone ["stone_type":"stone"]
setblock ~70~22~49 minecraft:stone ["stone_type":"stone"]
fill ~15~13~50 ~15~13~53 minecraft:coal_block
fill ~15~15~50 ~15~15~53 minecraft:stone ["stone_type":"stone"]
fill ~15~18~50 ~15~18~51 minecraft:stone ["stone_type":"stone"]
setblock ~15~20~50 minecraft:stone ["stone_type":"stone"]
fill ~15~23~50 ~15~24~50 minecraft:stone ["stone_type":"stone"]
fill ~15~26~50 ~15~26~53 minecraft:stone ["stone_type":"stone"]
fill ~15~27~50 ~15~27~55 minecraft:coal_block
fill ~15~28~50 ~15~28~53 minecraft:coal_block
fill ~16~12~50 ~21~12~53 minecraft:coal_block
fill ~16~14~50 ~21~14~53 minecraft:stone ["stone_type":"stone"]
fill ~16~27~50 ~21~27~53 minecraft:stone ["stone_type":"stone"]
fill ~16~29~50 ~21~29~53 minecraft:coal_block
fill ~16~33~50 ~16~33~57 minecraft:iron_bars
fill ~16~34~50 ~16~34~61 minecraft:clay
fill ~17~17~50 ~17~17~53 minecraft:stone ["stone_type":"andesite"]
fill ~17~24~50 ~17~24~53 minecraft:stone ["stone_type":"andesite"]
fill ~18~16~50 ~18~16~53 minecraft:stonebrick ["stone_brick_type":"default"]
fill ~18~25~50 ~18~25~52 minecraft:stonebrick ["stone_brick_type":"default"]
fill ~19~17~50 ~19~17~53 minecraft:stonebrick ["stone_brick_type":"default"]
fill ~19~24~50 ~19~24~53 minecraft:stonebrick ["stone_brick_type":"default"]
fill ~20~19~50 ~20~19~53 minecraft:coal_block
fill ~20~20~50 ~21~21~50 minecraft:coal_block
fill ~20~22~50 ~20~22~53 minecraft:coal_block
fill ~21~16~50 ~21~16~52 minecraft:stained_hardened_clay ["color":"cyan"]
fill ~21~25~50 ~21~25~52 minecraft:stained_hardened_clay ["color":"cyan"]
fill ~22~13~50 ~22~13~53 minecraft:coal_block
fill ~22~15~50 ~22~15~53 minecraft:stone ["stone_type":"stone"]
fill ~22~16~50 ~23~16~50 minecraft:stone ["stone_type":"andesite"]
fill ~22~25~50 ~23~25~50 minecraft:stone ["stone_type":"andesite"]
fill ~22~26~50 ~22~26~53 minecraft:stone ["stone_type":"stone"]
fill ~22~27~50 ~22~27~55 minecraft:coal_block
fill ~22~28~50 ~22~28~53 minecraft:coal_block
fill ~25~20~50 ~26~21~50 minecraft:coal_block
setblock ~25~38~50 minecraft:stone_button ["button_pressed_bit":false,"facing_direction":1]
fill ~26~19~50 ~26~19~53 minecraft:coal_block
fill ~26~22~50 ~26~22~53 minecraft:coal_block
fill ~27~42~50 ~27~42~51 minecraft:wool ["color":"gray"]
fill ~28~34~50 ~30~34~57 minecraft:stone ["stone_type":"stone"]
fill ~28~36~50 ~28~37~54 minecraft:obsidian
fill ~28~40~50 ~28~40~52 minecraft:wool 15
fill ~29~37~50 ~33~37~51 minecraft:obsidian
fill ~30~36~50 ~33~36~50 minecraft:obsidian
fill ~31~38~50 ~34~39~50 minecraft:double_stone_block_slab ["stone_slab_type":"smooth_stone","top_slot_bit":false]
fill ~35~38~50 ~35~39~51 minecraft:stained_hardened_clay ["color":"cyan"]
fill ~36~38~50 ~36~39~55 minecraft:stone ["stone_type":"stone"]
fill ~36~40~50 ~37~40~50 minecraft:stone ["stone_type":"stone"]
fill ~37~31~50 ~48~33~50 minecraft:stone ["stone_type":"stone"]
fill ~37~36~50 ~38~37~50 minecraft:stone ["stone_type":"stone"]
fill ~37~39~50 ~37~39~55 minecraft:stone ["stone_type":"stone"]
fill ~38~17~50 ~38~17~52 minecraft:stone ["stone_type":"stone"]
fill ~38~30~50 ~47~30~50 minecraft:stone ["stone_type":"stone"]
setblock ~39~37~50 minecraft:stone ["stone_type":"stone"]
fill ~39~39~50 ~39~39~53 minecraft:stone ["stone_type":"stone"]
fill ~41~34~50 ~44~34~51 minecraft:stone ["stone_type":"stone"]
fill ~41~36~50 ~41~39~50 minecraft:stone ["stone_type":"stone"]
fill ~42~17~50 ~43~17~52 minecraft:stone ["stone_type":"stone"]
fill ~44~36~50 ~44~39~50 minecraft:stone ["stone_type":"stone"]
fill ~46~37~50 ~49~37~50 minecraft:stone ["stone_type":"stone"]
fill ~47~17~50 ~47~17~52 minecraft:stone ["stone_type":"stone"]
fill ~48~36~50 ~49~36~50 minecraft:stone ["stone_type":"stone"]
fill ~50~38~50 ~50~39~50 minecraft:stone ["stone_type":"stone"]
fill ~51~38~50 ~54~39~50 minecraft:double_stone_block_slab ["stone_slab_type":"smooth_stone","top_slot_bit":false]
fill ~52~36~50 ~55~37~50 minecraft:obsidian
fill ~55~34~50 ~57~34~56 minecraft:stone ["stone_type":"stone"]
fill ~56~37~50 ~57~37~52 minecraft:obsidian
fill ~57~36~50 ~57~36~54 minecraft:obsidian
fill ~59~19~50 ~59~19~53 minecraft:coal_block
fill ~59~20~50 ~60~21~50 minecraft:coal_block
fill ~59~22~50 ~59~22~53 minecraft:coal_block
fill ~62~16~50 ~63~16~50 minecraft:stone ["stone_type":"andesite"]
fill ~62~25~50 ~63~25~50 minecraft:stone ["stone_type":"andesite"]
fill ~63~13~50 ~63~13~53 minecraft:coal_block
fill ~63~15~50 ~63~15~53 minecraft:stone ["stone_type":"stone"]
fill ~63~26~50 ~63~26~53 minecraft:stone ["stone_type":"stone"]
fill ~63~27~50 ~63~27~55 minecraft:coal_block
fill ~63~28~50 ~63~28~53 minecraft:coal_block
fill ~64~12~50 ~69~12~53 minecraft:coal_block
fill ~64~14~50 ~69~14~53 minecraft:stone ["stone_type":"stone"]
fill ~64~16~50 ~64~16~52 minecraft:stained_hardened_clay ["color":"cyan"]
fill ~64~20~50 ~65~21~50 minecraft:coal_block
fill ~64~25~50 ~64~25~52 minecraft:stained_hardened_clay ["color":"cyan"]
fill ~64~27~50 ~69~27~53 minecraft:stone ["stone_type":"stone"]
fill ~64~29~50 ~69~29~53 minecraft:coal_block
fill ~65~19~50 ~65~19~53 minecraft:coal_block
fill ~65~22~50 ~65~22~53 minecraft:coal_block
setblock ~65~35~50 minecraft:stone ["stone_type":"stone"]
fill ~66~17~50 ~66~17~53 minecraft:stonebrick ["stone_brick_type":"default"]
fill ~66~24~50 ~66~24~53 minecraft:stonebrick ["stone_brick_type":"default"]
fill ~67~16~50 ~67~16~53 minecraft:stonebrick ["stone_brick_type":"default"]
fill ~67~25~50 ~67~25~52 minecraft:stonebrick ["stone_brick_type":"default"]
fill ~68~17~50 ~68~17~53 minecraft:stone ["stone_type":"andesite"]
fill ~68~24~50 ~68~24~53 minecraft:stone ["stone_type":"andesite"]
fill ~69~33~50 ~69~33~57 minecraft:iron_bars
fill ~69~34~50 ~69~34~61 minecraft:clay
fill ~70~13~50 ~70~13~53 minecraft:coal_block
fill ~70~15~50 ~70~15~53 minecraft:stone ["stone_type":"stone"]
fill ~70~18~50 ~70~18~51 minecraft:stone ["stone_type":"stone"]
setblock ~70~20~50 minecraft:stone ["stone_type":"stone"]
fill ~70~23~50 ~70~24~50 minecraft:stone ["stone_type":"stone"]
fill ~70~26~50 ~70~26~53 minecraft:stone ["stone_type":"stone"]
fill ~70~27~50 ~70~27~55 minecraft:coal_block
fill ~70~28~50 ~70~28~53 minecraft:coal_block
fill ~15~16~51 ~15~17~51 minecraft:stone ["stone_type":"stone"]
fill ~15~19~51 ~15~19~52 minecraft:stone ["stone_type":"stone"]
setblock ~15~20~51 minecraft:stone_brick_stairs ["upside_down_bit":true,"weirdo_direction":2]
setblock ~15~21~51 minecraft:stone_brick_stairs ["upside_down_bit":false,"weirdo_direction":2]
fill ~15~22~51 ~15~22~52 minecraft:stone ["stone_type":"stone"]
fill ~16~20~51 ~16~21~52 minecraft:wool ["color":"gray"]
fill ~17~20~51 ~26~21~52 minecraft:stained_hardened_clay ["color":"cyan"]
fill ~17~22~51 ~17~22~55 minecraft:stone ["stone_type":"andesite"]
fill ~17~36~51 ~17~36~56 minecraft:wool ["color":"yellow"]
fill ~18~34~51 ~18~34~66 minecraft:stone ["stone_type":"stone"]
fill ~18~37~51 ~18~37~56 minecraft:wool ["color":"yellow"]
fill ~19~22~51 ~19~22~55 minecraft:stonebrick ["stone_brick_type":"default"]
fill ~19~39~51 ~19~39~56 minecraft:wool ["color":"yellow"]
setblock ~20~15~51 minecraft:stone_button ["button_pressed_bit":false,"facing_direction":0]
setblock ~20~16~51 minecraft:stained_hardened_clay ["color":"cyan"]
setblock ~20~17~51 minecraft:stonebrick ["stone_brick_type":"default"]
setblock ~20~18~51 minecraft:stone_button ["button_pressed_bit":false,"facing_direction":1]
setblock ~20~23~51 minecraft:stone_button ["button_pressed_bit":false,"facing_direction":0]
setblock ~20~24~51 minecraft:stonebrick ["stone_brick_type":"default"]
setblock ~20~25~51 minecraft:stained_hardened_clay ["color":"cyan"]
setblock ~20~26~51 minecraft:stone_button ["button_pressed_bit":false,"facing_direction":1]
fill ~20~35~51 ~20~35~63 minecraft:stone ["stone_type":"stone"]
fill ~20~40~51 ~20~40~56 minecraft:wool ["color":"yellow"]
fill ~21~19~51 ~21~19~52 minecraft:coal_block
fill ~21~22~51 ~21~22~52 minecraft:coal_block
fill ~22~40~51 ~22~40~56 minecraft:wool ["color":"gray"]
fill ~23~41~51 ~23~41~56 minecraft:wool ["color":"gray"]
fill ~25~19~51 ~25~19~52 minecraft:coal_block
fill ~25~22~51 ~25~22~52 minecraft:coal_block
fill ~25~34~51 ~27~34~57 minecraft:stone ["stone_type":"stone"]
fill ~27~41~51 ~27~41~57 minecraft:stone ["stone_type":"stone"]
fill ~32~38~51 ~32~39~51 minecraft:wool ["color":"gray"]
fill ~33~36~51 ~33~36~54 minecraft:obsidian
fill ~36~37~51 ~36~37~53 minecraft:stone ["stone_type":"stone"]
fill ~36~40~51 ~38~40~52 minecraft:stained_hardened_clay ["color":"cyan"]
fill ~37~30~51 ~37~33~57 minecraft:stone ["stone_type":"stone"]
fill ~37~41~51 ~38~41~51 minecraft:stone_block_slab ["stone_slab_type":"smooth_stone","top_slot_bit":false]
fill ~38~34~51 ~40~34~51 minecraft:stone ["stone_type":"stone"]
fill ~38~36~51 ~38~36~53 minecraft:stone ["stone_type":"stone"]
setblock ~38~37~51 minecraft:stone ["stone_type":"stone"]
fill ~39~38~51 ~39~38~52 minecraft:stone ["stone_type":"stone"]
setblock ~44~39~51 minecraft:stonebrick ["stone_brick_type":"default"]
fill ~45~34~51 ~47~34~51 minecraft:stone ["stone_type":"stone"]
fill ~45~37~51 ~46~37~53 minecraft:stone ["stone_type":"stone"]
fill ~45~39~51 ~46~39~55 minecraft:stone ["stone_type":"stone"]
fill ~46~36~51 ~46~36~52 minecraft:stone ["stone_type":"stone"]
fill ~47~40~51 ~49~40~52 minecraft:stained_hardened_clay ["color":"cyan"]
fill ~47~41~51 ~48~41~51 minecraft:stone_block_slab ["stone_slab_type":"smooth_stone","top_slot_bit":false]
fill ~48~30~51 ~48~33~56 minecraft:stone ["stone_type":"stone"]
fill ~48~36~51 ~48~37~55 minecraft:stone ["stone_type":"stone"]
fill ~48~39~51 ~48~39~55 minecraft:stone ["stone_type":"stone"]
fill ~50~38~51 ~50~39~55 minecraft:stained_hardened_clay ["color":"cyan"]
fill ~52~36~51 ~52~37~54 minecraft:obsidian
fill ~53~37~51 ~55~37~51 minecraft:obsidian
fill ~53~38~51 ~53~39~51 minecraft:wool ["color":"gray"]
fill ~57~38~51 ~57~38~53 minecraft:wool 15
fill ~58~34~51 ~60~34~56 minecraft:stone ["stone_type":"stone"]
fill ~58~41~51 ~58~41~57 minecraft:stone ["stone_type":"stone"]
fill ~59~20~51 ~68~21~52 minecraft:stained_hardened_clay ["color":"cyan"]
fill ~60~19~51 ~60~19~52 minecraft:coal_block
fill ~60~22~51 ~60~22~52 minecraft:coal_block
fill ~60~36~51 ~60~38~53 minecraft:clay
setblock ~60~39~51 minecraft:stone_button ["button_pressed_bit":false,"facing_direction":1]
fill ~63~36~51 ~65~36~51 minecraft:stone_block_slab ["stone_slab_type":"smooth_stone","top_slot_bit":false]
fill ~64~19~51 ~64~19~52 minecraft:coal_block
fill ~64~22~51 ~64~22~52 minecraft:coal_block
setblock ~65~15~51 minecraft:stone_button ["button_pressed_bit":false,"facing_direction":0]
setblock ~65~16~51 minecraft:stained_hardened_clay ["color":"cyan"]
setblock ~65~17~51 minecraft:stonebrick ["stone_brick_type":"default"]
setblock ~65~18~51 minecraft:stone_button ["button_pressed_bit":false,"facing_direction":1]
setblock ~65~23~51 minecraft:stone_button ["button_pressed_bit":false,"facing_direction":0]
setblock ~65~24~51 minecraft:stonebrick ["stone_brick_type":"default"]
setblock ~65~25~51 minecraft:stained_hardened_clay ["color":"cyan"]
setblock ~65~26~51 minecraft:stone_button ["button_pressed_bit":false,"facing_direction":1]
fill ~65~35~51 ~65~35~53 minecraft:double_stone_block_slab ["stone_slab_type":"smooth_stone","top_slot_bit":false]
fill ~67~34~51 ~67~34~66 minecraft:stone ["stone_type":"stone"]
fill ~68~22~51 ~68~22~55 minecraft:stone ["stone_type":"andesite"]
fill ~69~20~51 ~69~21~52 minecraft:wool ["color":"gray"]
fill ~70~16~51 ~70~17~51 minecraft:stone ["stone_type":"stone"]
fill ~70~19~51 ~70~19~52 minecraft:stone ["stone_type":"stone"]
setblock ~70~20~51 minecraft:stone_brick_stairs ["upside_down_bit":true,"weirdo_direction":2]
setblock ~70~21~51 minecraft:stone_brick_stairs ["upside_down_bit":false,"weirdo_direction":2]
fill ~70~22~51 ~70~22~52 minecraft:stone ["stone_type":"stone"]
setblock ~15~20~52 minecraft:stone_brick_stairs ["upside_down_bit":true,"weirdo_direction":3]
setblock ~15~21~52 minecraft:stone_brick_stairs ["upside_down_bit":false,"weirdo_direction":3]
fill ~15~23~52 ~15~23~53 minecraft:stone ["stone_type":"stone"]
fill ~15~24~52 ~15~25~52 minecraft:stone ["stone_type":"stone"]
fill ~17~33~52 ~17~33~66 minecraft:stone ["stone_type":"stone"]
fill ~18~35~52 ~19~35~52 minecraft:stained_hardened_clay ["color":"cyan"]
fill ~19~36~52 ~21~36~52 minecraft:stained_hardened_clay ["color":"cyan"]
fill ~20~37~52 ~21~38~52 minecraft:stained_hardened_clay ["color":"cyan"]
fill ~21~39~52 ~22~39~52 minecraft:stained_hardened_clay ["color":"cyan"]
fill ~22~16~52 ~23~16~52 minecraft:stone ["stone_type":"andesite"]
fill ~22~25~52 ~23~25~52 minecraft:stone ["stone_type":"andesite"]
setblock ~22~38~52 minecraft:stained_hardened_clay ["color":"cyan"]
fill ~25~36~52 ~25~38~54 minecraft:clay
setblock ~25~39~52 minecraft:stone_button ["button_pressed_bit":false,"facing_direction":1]
fill ~28~42~52 ~28~42~53 minecraft:wool ["color":"gray"]
setblock ~29~37~52 minecraft:obsidian
fill ~30~37~52 ~31~38~53 minecraft:stained_hardened_clay ["color":"cyan"]
fill ~31~39~52 ~34~39~52 minecraft:stained_hardened_clay ["color":"cyan"]
fill ~32~38~52 ~34~38~53 minecraft:stained_hardened_clay ["color":"cyan"]
fill ~33~37~52 ~33~37~54 minecraft:obsidian
setblock ~33~40~52 minecraft:wool ["color":"gray"]
fill ~35~38~52 ~35~39~53 minecraft:stone ["stone_type":"stone"]
fill ~37~36~52 ~37~36~53 minecraft:stone ["stone_type":"stone"]
fill ~38~34~52 ~38~34~57 minecraft:stone ["stone_type":"stone"]
fill ~39~31~52 ~46~33~52 minecraft:stone ["stone_type":"stone"]
fill ~39~40~52 ~42~40~54 minecraft:stone ["stone_type":"stone"]
fill ~39~41~52 ~40~41~55 minecraft:stonebrick ["stone_brick_type":"default"]
fill ~40~30~52 ~45~30~52 minecraft:stone ["stone_type":"stone"]
fill ~41~36~52 ~45~36~52 minecraft:stone ["stone_type":"stone"]
fill ~41~37~52 ~44~37~52 minecraft:stone ["stone_type":"stone"]
setblock ~41~39~52 minecraft:stone ["stone_type":"stone"]
fill ~41~41~52 ~44~41~52 minecraft:stone ["stone_type":"stone"]
fill ~41~42~52 ~44~42~54 minecraft:clay
setblock ~44~39~52 minecraft:stone ["stone_type":"stone"]
fill ~45~40~52 ~45~40~55 minecraft:stone ["stone_type":"stone"]
fill ~45~41~52 ~46~41~55 minecraft:stonebrick ["stone_brick_type":"default"]
fill ~46~40~52 ~46~40~54 minecraft:stained_hardened_clay ["color":"cyan"]
fill ~47~34~52 ~47~34~56 minecraft:stone ["stone_type":"stone"]
fill ~47~39~52 ~47~39~53 minecraft:stone ["stone_type":"stone"]
fill ~51~38~52 ~55~38~53 minecraft:stained_hardened_clay ["color":"cyan"]
fill ~51~39~52 ~54~39~52 minecraft:stained_hardened_clay ["color":"cyan"]
setblock ~52~40~52 minecraft:wool ["color":"gray"]
fill ~54~37~52 ~55~37~53 minecraft:stained_hardened_clay ["color":"cyan"]
fill ~57~41~52 ~57~41~57 minecraft:wool ["color":"gray"]
fill ~59~36~52 ~59~38~52 minecraft:clay
setblock ~59~39~52 minecraft:stone_button ["button_pressed_bit":false,"facing_direction":1]
fill ~61~36~52 ~61~38~52 minecraft:clay
setblock ~61~39~52 minecraft:stone_button ["button_pressed_bit":false,"facing_direction":1]
fill ~62~16~52 ~63~16~52 minecraft:stone ["stone_type":"andesite"]
fill ~62~25~52 ~63~25~52 minecraft:stone ["stone_type":"andesite"]
fill ~63~35~52 ~63~35~62 minecraft:stone ["stone_type":"stone"]
fill ~63~36~52 ~63~36~53 minecraft:stone_block_slab ["stone_slab_type":"smooth_stone","top_slot_bit":false]
fill ~64~35~52 ~64~36~52 minecraft:clay
setblock ~64~37~52 minecraft:stone_button ["button_pressed_bit":false,"facing_direction":1]
fill ~65~36~52 ~65~36~53 minecraft:stone_block_slab ["stone_slab_type":"smooth_stone","top_slot_bit":false]
fill ~68~33~52 ~68~33~66 minecraft:stone ["stone_type":"stone"]
setblock ~70~20~52 minecraft:stone_brick_stairs ["upside_down_bit":true,"weirdo_direction":3]
setblock ~70~21~52 minecraft:stone_brick_stairs ["upside_down_bit":false,"weirdo_direction":3]
fill ~70~23~52 ~70~23~53 minecraft:stone ["stone_type":"stone"]
fill ~70~24~52 ~70~25~52 minecraft:stone ["stone_type":"stone"]
fill ~15~17~53 ~15~18~53 minecraft:stone ["stone_type":"stone"]
fill ~15~20~53 ~15~20~57 minecraft:stone ["stone_type":"stone"]
setblock ~15~21~53 minecraft:stone ["stone_type":"stone"]
fill ~16~32~53 ~16~32~61 minecraft:stone ["stone_type":"stone"]
fill ~16~35~53 ~19~35~53 minecraft:stone_block_slab ["stone_slab_type":"nether_brick","top_slot_bit":false]
fill ~17~20~53 ~17~21~55 minecraft:stone ["stone_type":"andesite"]
fill ~17~37~53 ~17~37~58 minecraft:wool ["color":"yellow"]
fill ~19~20~53 ~19~21~55 minecraft:stonebrick ["stone_brick_type":"default"]
fill ~19~34~53 ~19~34~66 minecraft:stone ["stone_type":"stone"]
fill ~19~40~53 ~19~40~58 minecraft:wool ["color":"yellow"]
fill ~20~20~53 ~21~21~53 minecraft:coal_block
fill ~22~41~53 ~22~41~58 minecraft:wool ["color":"gray"]
fill ~24~17~53 ~26~17~53 minecraft:stone ["stone_type":"andesite"]
fill ~24~25~53 ~26~25~53 minecraft:stone ["stone_type":"andesite"]
fill ~24~26~53 ~26~26~57 minecraft:stonebrick ["stone_brick_type":"default"]
fill ~24~36~53 ~24~38~53 minecraft:clay
setblock ~24~39~53 minecraft:stone_button ["button_pressed_bit":false,"facing_direction":1]
fill ~25~20~53 ~26~21~53 minecraft:coal_block
setblock ~25~24~53 minecraft:stone_button ["button_pressed_bit":false,"facing_direction":0]
setblock ~25~27~53 minecraft:stone_button ["button_pressed_bit":false,"facing_direction":1]
setblock ~25~35~53 minecraft:clay
fill ~26~36~53 ~26~38~53 minecraft:clay
setblock ~26~39~53 minecraft:stone_button ["button_pressed_bit":false,"facing_direction":1]
fill ~26~41~53 ~26~41~63 minecraft:stone ["stone_type":"stone"]
setblock ~27~18~53 minecraft:stone ["stone_type":"stone"]
fill ~28~41~53 ~28~41~54 minecraft:wool 15
fill ~29~37~53 ~29~38~55 minecraft:stained_hardened_clay ["color":"cyan"]
fill ~32~18~53 ~53~18~53 minecraft:stone ["stone_type":"stone"]
fill ~32~39~53 ~34~39~53 minecraft:stained_hardened_clay ["color":"cyan"]
fill ~34~17~53 ~34~17~59 minecraft:stone ["stone_type":"stone"]
setblock ~34~40~53 minecraft:wool ["color":"gray"]
fill ~36~40~53 ~37~40~54 minecraft:stone ["stone_type":"stone"]
fill ~36~41~53 ~37~41~54 minecraft:obsidian
fill ~36~42~53 ~37~43~54 minecraft:concrete ["color":"purple"]
fill ~37~37~53 ~38~37~53 minecraft:stone ["stone_type":"stone"]
fill ~37~44~53 ~38~44~54 minecraft:concrete ["color":"purple"]
fill ~38~40~53 ~38~40~55 minecraft:stained_hardened_clay ["color":"cyan"]
fill ~38~43~53 ~38~43~54 minecraft:concrete ["color":"purple"]
fill ~39~30~53 ~39~33~57 minecraft:stone ["stone_type":"stone"]
fill ~39~43~53 ~39~44~54 minecraft:stone ["stone_type":"stone"]
fill ~40~34~53 ~45~34~57 minecraft:stone ["stone_type":"stone"]
fill ~40~39~53 ~40~39~55 minecraft:stone ["stone_type":"stone"]
fill ~40~43~53 ~45~44~54 minecraft:obsidian
fill ~41~36~53 ~41~38~53 minecraft:stone ["stone_type":"stone"]
fill ~41~41~53 ~42~41~54 minecraft:stone ["stone_type":"stone"]
fill ~42~38~53 ~44~38~53 minecraft:stone ["stone_type":"stone"]
fill ~43~40~53 ~44~40~54 minecraft:stone ["stone_type":"stone"]
fill ~44~36~53 ~44~37~53 minecraft:stone ["stone_type":"stone"]
fill ~44~41~53 ~44~41~54 minecraft:stone ["stone_type":"stone"]
fill ~46~30~53 ~46~33~57 minecraft:stone ["stone_type":"stone"]
fill ~46~38~53 ~46~38~55 minecraft:stone ["stone_type":"stone"]
fill ~46~43~53 ~46~44~54 minecraft:stone ["stone_type":"stone"]
fill ~47~40~53 ~47~40~55 minecraft:stained_hardened_clay ["color":"cyan"]
fill ~47~43~53 ~49~43~54 minecraft:concrete ["color":"purple"]
fill ~47~44~53 ~48~44~54 minecraft:concrete ["color":"purple"]
fill ~48~38~53 ~48~38~55 minecraft:stone ["stone_type":"stone"]
fill ~48~40~53 ~49~40~54 minecraft:stone ["stone_type":"stone"]
fill ~48~41~53 ~49~41~54 minecraft:obsidian
fill ~48~42~53 ~49~42~54 minecraft:concrete ["color":"purple"]
fill ~51~17~53 ~51~17~59 minecraft:stone ["stone_type":"stone"]
fill ~51~39~53 ~53~39~53 minecraft:stained_hardened_clay ["color":"cyan"]
setblock ~51~40~53 minecraft:wool ["color":"gray"]
fill ~56~37~53 ~56~38~56 minecraft:stained_hardened_clay ["color":"cyan"]
fill ~57~37~53 ~57~37~54 minecraft:obsidian
setblock ~58~18~53 minecraft:stone ["stone_type":"stone"]
fill ~59~17~53 ~61~17~53 minecraft:stone ["stone_type":"andesite"]
fill ~59~20~53 ~60~21~53 minecraft:coal_block
fill ~59~25~53 ~61~25~53 minecraft:stone ["stone_type":"andesite"]
fill ~59~26~53 ~61~26~57 minecraft:stonebrick ["stone_brick_type":"default"]
fill ~59~41~53 ~59~41~62 minecraft:stone ["stone_type":"stone"]
setblock ~60~24~53 minecraft:stone_button ["button_pressed_bit":false,"facing_direction":0]
setblock ~60~27~53 minecraft:stone_button ["button_pressed_bit":false,"facing_direction":1]
setblock ~60~39~53 minecraft:stone_button ["button_pressed_bit":false,"facing_direction":1]
fill ~64~20~53 ~65~21~53 minecraft:coal_block
fill ~64~35~53 ~64~35~63 minecraft:stone ["stone_type":"stone"]
setblock ~64~36~53 minecraft:stone_block_slab ["stone_slab_type":"smooth_stone","top_slot_bit":false]
fill ~66~20~53 ~66~21~55 minecraft:stonebrick ["stone_brick_type":"default"]
setblock ~66~35~53 minecraft:wool ["color":"gray"]
fill ~67~35~53 ~69~35~53 minecraft:stone_block_slab ["stone_slab_type":"nether_brick","top_slot_bit":false]
fill ~68~20~53 ~68~21~55 minecraft:stone ["stone_type":"andesite"]
fill ~69~32~53 ~69~32~61 minecraft:stone ["stone_type":"stone"]
fill ~70~17~53 ~70~18~53 minecraft:stone ["stone_type":"stone"]
fill ~70~20~53 ~70~20~57 minecraft:stone ["stone_type":"stone"]
setblock ~70~21~53 minecraft:stone ["stone_type":"stone"]
