setblock ~8 ~8 ~7 chest 3
setblock ~8 ~9 ~7 chest 3
setblock ~8 ~10 ~7 chest 3
setblock ~8 ~11 ~7 chest 3
setblock ~9 ~8 ~7 chest 3
setblock ~9 ~9 ~7 chest 3
setblock ~9 ~10 ~7 chest 3
setblock ~9 ~11 ~7 chest 3
setblock ~12 ~8 ~7 chest 3
setblock ~12 ~9 ~7 chest 3
setblock ~12 ~10 ~7 chest 3
setblock ~12 ~11 ~7 chest 3
setblock ~13 ~8 ~7 chest 3
setblock ~13 ~9 ~7 chest 3
setblock ~13 ~10 ~7 chest 3
setblock ~13 ~11 ~7 chest 3
setblock ~16 ~8 ~7 chest 3
setblock ~16 ~9 ~7 chest 3
setblock ~16 ~10 ~7 chest 3
setblock ~16 ~11 ~7 chest 3
setblock ~17 ~8 ~7 chest 3
setblock ~17 ~9 ~7 chest 3
setblock ~17 ~10 ~7 chest 3
setblock ~17 ~11 ~7 chest 3
setblock ~19 ~8 ~7 chest 3
setblock ~19 ~9 ~7 chest 3
setblock ~19 ~10 ~7 chest 3
setblock ~19 ~11 ~7 chest 3
setblock ~20 ~8 ~7 chest 3
setblock ~20 ~9 ~7 chest 3
setblock ~20 ~10 ~7 chest 3
setblock ~20 ~11 ~7 chest 3
setblock ~23 ~8 ~7 chest 3
setblock ~23 ~9 ~7 chest 3
setblock ~23 ~10 ~7 chest 3
setblock ~23 ~11 ~7 chest 3
setblock ~8 ~8 ~10 chest 2
setblock ~8 ~8 ~12 chest 3
setblock ~8 ~8 ~15 chest 2
setblock ~8 ~9 ~10 chest 2
setblock ~8 ~9 ~12 chest 3
setblock ~8 ~9 ~15 chest 2
setblock ~8 ~10 ~10 chest 2
setblock ~8 ~10 ~12 chest 3
setblock ~8 ~10 ~15 chest 2
setblock ~8 ~11 ~10 chest 2
setblock ~8 ~11 ~12 chest 3
setblock ~8 ~11 ~15 chest 2
setblock ~8 ~12 ~12 chest 3
setblock ~8 ~12 ~15 chest 2
setblock ~9 ~8 ~10 chest 2
setblock ~9 ~8 ~12 chest 3
setblock ~9 ~8 ~15 chest 2
setblock ~9 ~9 ~10 chest 2
setblock ~9 ~9 ~12 chest 3
setblock ~9 ~9 ~15 chest 2
setblock ~9 ~10 ~10 chest 2
setblock ~9 ~10 ~12 chest 3
setblock ~9 ~10 ~15 chest 2
setblock ~9 ~11 ~10 chest 2
setblock ~9 ~11 ~12 chest 3
setblock ~9 ~11 ~15 chest 2
setblock ~9 ~12 ~12 chest 3
setblock ~9 ~12 ~15 chest 2
setblock ~12 ~8 ~10 chest 2
setblock ~12 ~8 ~12 chest 3
setblock ~12 ~8 ~15 chest 2
setblock ~12 ~9 ~10 chest 2
setblock ~12 ~9 ~12 chest 3
setblock ~12 ~9 ~15 chest 2
setblock ~12 ~10 ~10 chest 2
setblock ~12 ~10 ~12 chest 3
setblock ~12 ~10 ~15 chest 2
setblock ~12 ~11 ~10 chest 2
setblock ~12 ~11 ~12 chest 3
setblock ~12 ~11 ~15 chest 2
setblock ~12 ~12 ~12 chest 3
setblock ~12 ~12 ~15 chest 2
setblock ~13 ~8 ~10 chest 2
setblock ~13 ~8 ~12 chest 3
setblock ~13 ~8 ~15 chest 2
setblock ~13 ~9 ~10 chest 2
setblock ~13 ~9 ~12 chest 3
setblock ~13 ~9 ~15 chest 2
setblock ~13 ~10 ~10 chest 2
setblock ~13 ~10 ~12 chest 3
setblock ~13 ~10 ~15 chest 2
setblock ~13 ~11 ~10 chest 2
setblock ~13 ~11 ~12 chest 3
setblock ~13 ~11 ~15 chest 2
setblock ~13 ~12 ~12 chest 3
setblock ~13 ~12 ~15 chest 2
setblock ~16 ~8 ~10 chest 2
setblock ~16 ~8 ~12 chest 3
setblock ~16 ~8 ~15 chest 2
setblock ~16 ~9 ~10 chest 2
setblock ~16 ~9 ~12 chest 3
setblock ~16 ~9 ~15 chest 2
setblock ~16 ~10 ~10 chest 2
setblock ~16 ~10 ~12 chest 3
setblock ~16 ~10 ~15 chest 2
setblock ~16 ~11 ~10 chest 2
setblock ~16 ~11 ~12 chest 3
setblock ~16 ~11 ~15 chest 2
setblock ~16 ~12 ~12 chest 3
setblock ~16 ~12 ~15 chest 2
setblock ~8 ~8 ~17 chest 3
setblock ~8 ~9 ~17 chest 3
setblock ~8 ~10 ~17 chest 3
setblock ~8 ~11 ~17 chest 3
setblock ~8 ~12 ~17 chest 3
setblock ~9 ~8 ~17 chest 3
setblock ~9 ~9 ~17 chest 3
setblock ~9 ~10 ~17 chest 3
setblock ~9 ~11 ~17 chest 3
setblock ~9 ~12 ~17 chest 3
setblock ~12 ~8 ~17 chest 3
setblock ~12 ~9 ~17 chest 3
setblock ~12 ~10 ~17 chest 3
setblock ~12 ~11 ~17 chest 3
setblock ~12 ~12 ~17 chest 3
setblock ~13 ~8 ~17 chest 3
setblock ~13 ~9 ~17 chest 3
setblock ~13 ~10 ~17 chest 3
setblock ~13 ~11 ~17 chest 3
setblock ~13 ~12 ~17 chest 3
setblock ~16 ~8 ~17 chest 3
setblock ~16 ~9 ~17 chest 3
setblock ~16 ~10 ~17 chest 3
setblock ~16 ~11 ~17 chest 3
setblock ~16 ~12 ~17 chest 3
setblock ~17 ~8 ~10 chest 2
setblock ~17 ~8 ~12 chest 3
setblock ~17 ~8 ~15 chest 2
setblock ~17 ~9 ~10 chest 2
setblock ~17 ~9 ~12 chest 3
setblock ~17 ~9 ~15 chest 2
setblock ~17 ~10 ~10 chest 2
setblock ~17 ~10 ~12 chest 3
setblock ~17 ~10 ~15 chest 2
setblock ~17 ~11 ~10 chest 2
setblock ~17 ~11 ~12 chest 3
setblock ~17 ~11 ~15 chest 2
setblock ~17 ~12 ~12 chest 3
setblock ~17 ~12 ~15 chest 2
setblock ~19 ~8 ~10 chest 2
setblock ~19 ~8 ~12 chest 3
setblock ~19 ~8 ~15 chest 2
setblock ~19 ~9 ~10 chest 2
setblock ~19 ~9 ~12 chest 3
setblock ~19 ~9 ~15 chest 2
setblock ~19 ~10 ~10 chest 2
setblock ~19 ~10 ~12 chest 3
setblock ~19 ~10 ~15 chest 2
setblock ~19 ~11 ~10 chest 2
setblock ~19 ~11 ~12 chest 3
setblock ~19 ~11 ~15 chest 2
setblock ~20 ~8 ~10 chest 2
setblock ~20 ~8 ~12 chest 3
setblock ~20 ~8 ~15 chest 2
setblock ~20 ~9 ~10 chest 2
setblock ~20 ~9 ~12 chest 3
setblock ~20 ~9 ~15 chest 2
setblock ~20 ~10 ~10 chest 2
setblock ~20 ~10 ~12 chest 3
setblock ~20 ~10 ~15 chest 2
setblock ~20 ~11 ~10 chest 2
setblock ~20 ~11 ~12 chest 3
setblock ~20 ~11 ~15 chest 2
setblock ~23 ~8 ~10 chest 2
setblock ~23 ~8 ~12 chest 3
setblock ~23 ~8 ~15 chest 2
setblock ~23 ~9 ~10 chest 2
setblock ~23 ~9 ~12 chest 3
setblock ~23 ~9 ~15 chest 2
setblock ~23 ~10 ~10 chest 2
setblock ~23 ~10 ~12 chest 3
setblock ~23 ~10 ~15 chest 2
setblock ~23 ~11 ~10 chest 2
setblock ~23 ~11 ~12 chest 3
setblock ~23 ~11 ~15 chest 2
setblock ~17 ~8 ~17 chest 3
setblock ~17 ~9 ~17 chest 3
setblock ~17 ~10 ~17 chest 3
setblock ~17 ~11 ~17 chest 3
setblock ~17 ~12 ~17 chest 3
setblock ~19 ~8 ~17 chest 3
setblock ~19 ~9 ~17 chest 3
setblock ~19 ~10 ~17 chest 3
setblock ~19 ~11 ~17 chest 3
setblock ~20 ~8 ~17 chest 3
setblock ~20 ~9 ~17 chest 3
setblock ~20 ~10 ~17 chest 3
setblock ~20 ~11 ~17 chest 3
setblock ~23 ~8 ~17 chest 3
setblock ~23 ~9 ~17 chest 3
setblock ~23 ~10 ~17 chest 3
setblock ~23 ~11 ~17 chest 3
setblock ~9 ~1 ~34 furnace 5
setblock ~9 ~1 ~35 furnace 5
setblock ~9 ~1 ~36 furnace 5
setblock ~9 ~1 ~37 furnace 5
setblock ~9 ~1 ~38 furnace 5
setblock ~9 ~1 ~39 furnace 5
setblock ~9 ~1 ~40 furnace 5
setblock ~9 ~2 ~34 furnace 5
setblock ~9 ~2 ~35 furnace 5
setblock ~9 ~2 ~36 furnace 5
setblock ~9 ~2 ~37 furnace 5
setblock ~9 ~2 ~38 furnace 5
setblock ~9 ~2 ~39 furnace 5
setblock ~9 ~2 ~40 furnace 5
setblock ~9 ~3 ~34 furnace 5
setblock ~9 ~3 ~35 furnace 5
setblock ~9 ~3 ~36 furnace 5
setblock ~9 ~3 ~37 furnace 5
setblock ~9 ~3 ~38 furnace 5
setblock ~9 ~3 ~39 furnace 5
setblock ~9 ~3 ~40 furnace 5
setblock ~9 ~4 ~34 furnace 5
setblock ~9 ~4 ~35 furnace 5
setblock ~9 ~4 ~36 furnace 5
setblock ~9 ~4 ~37 furnace 5
setblock ~9 ~4 ~38 furnace 5
setblock ~9 ~4 ~39 furnace 5
setblock ~9 ~4 ~40 furnace 5
setblock ~9 ~1 ~41 furnace 5
setblock ~9 ~1 ~42 furnace 5
setblock ~9 ~1 ~43 furnace 5
setblock ~9 ~2 ~41 furnace 5
setblock ~9 ~2 ~42 furnace 5
setblock ~9 ~2 ~43 furnace 5
setblock ~9 ~3 ~41 furnace 5
setblock ~9 ~3 ~42 furnace 5
setblock ~9 ~3 ~43 furnace 5
setblock ~9 ~4 ~41 furnace 5
setblock ~9 ~4 ~42 furnace 5
setblock ~9 ~4 ~43 furnace 5
setblock ~24 ~8 ~7 chest 3
setblock ~24 ~9 ~7 chest 3
setblock ~24 ~10 ~7 chest 3
setblock ~24 ~11 ~7 chest 3
setblock ~27 ~8 ~7 chest 3
setblock ~27 ~9 ~7 chest 3
setblock ~27 ~10 ~7 chest 3
setblock ~27 ~11 ~7 chest 3
setblock ~28 ~8 ~7 chest 3
setblock ~28 ~9 ~7 chest 3
setblock ~28 ~10 ~7 chest 3
setblock ~28 ~11 ~7 chest 3
setblock ~30 ~8 ~7 chest 3
setblock ~30 ~9 ~7 chest 3
setblock ~30 ~10 ~7 chest 3
setblock ~30 ~11 ~7 chest 3
setblock ~31 ~8 ~7 chest 3
setblock ~31 ~9 ~7 chest 3
setblock ~31 ~10 ~7 chest 3
setblock ~31 ~11 ~7 chest 3
setblock ~34 ~8 ~7 chest 3
setblock ~34 ~9 ~7 chest 3
setblock ~34 ~10 ~7 chest 3
setblock ~34 ~11 ~7 chest 3
setblock ~35 ~8 ~7 chest 3
setblock ~35 ~9 ~7 chest 3
setblock ~35 ~10 ~7 chest 3
setblock ~35 ~11 ~7 chest 3
setblock ~38 ~8 ~7 chest 3
setblock ~38 ~9 ~7 chest 3
setblock ~38 ~10 ~7 chest 3
setblock ~38 ~11 ~7 chest 3
setblock ~39 ~8 ~7 chest 3
setblock ~39 ~9 ~7 chest 3
setblock ~39 ~10 ~7 chest 3
setblock ~39 ~11 ~7 chest 3
setblock ~24 ~8 ~10 chest 2
setblock ~24 ~8 ~12 chest 3
setblock ~24 ~8 ~15 chest 2
setblock ~24 ~9 ~10 chest 2
setblock ~24 ~9 ~12 chest 3
setblock ~24 ~9 ~15 chest 2
setblock ~24 ~10 ~10 chest 2
setblock ~24 ~10 ~12 chest 3
setblock ~24 ~10 ~15 chest 2
setblock ~24 ~11 ~10 chest 2
setblock ~24 ~11 ~12 chest 3
setblock ~24 ~11 ~15 chest 2
setblock ~27 ~8 ~10 chest 2
setblock ~27 ~8 ~12 chest 3
setblock ~27 ~8 ~15 chest 2
setblock ~27 ~9 ~10 chest 2
setblock ~27 ~9 ~12 chest 3
setblock ~27 ~9 ~15 chest 2
setblock ~27 ~10 ~10 chest 2
setblock ~27 ~10 ~12 chest 3
setblock ~27 ~10 ~15 chest 2
setblock ~27 ~11 ~10 chest 2
setblock ~27 ~11 ~12 chest 3
setblock ~27 ~11 ~15 chest 2
setblock ~28 ~8 ~10 chest 2
setblock ~28 ~8 ~12 chest 3
setblock ~28 ~8 ~15 chest 2
setblock ~28 ~9 ~10 chest 2
setblock ~28 ~9 ~12 chest 3
setblock ~28 ~9 ~15 chest 2
setblock ~28 ~10 ~10 chest 2
setblock ~28 ~10 ~12 chest 3
setblock ~28 ~10 ~15 chest 2
setblock ~28 ~11 ~10 chest 2
setblock ~28 ~11 ~12 chest 3
setblock ~28 ~11 ~15 chest 2
setblock ~30 ~8 ~10 chest 2
setblock ~30 ~8 ~12 chest 3
setblock ~30 ~9 ~10 chest 2
setblock ~30 ~9 ~12 chest 3
setblock ~30 ~10 ~10 chest 2
setblock ~30 ~10 ~12 chest 3
setblock ~30 ~11 ~10 chest 2
setblock ~30 ~11 ~12 chest 3
setblock ~31 ~8 ~10 chest 2
setblock ~31 ~8 ~12 chest 3
setblock ~31 ~9 ~10 chest 2
setblock ~31 ~9 ~12 chest 3
setblock ~31 ~10 ~10 chest 2
setblock ~31 ~10 ~12 chest 3
setblock ~31 ~11 ~10 chest 2
setblock ~31 ~11 ~12 chest 3
setblock ~24 ~8 ~17 chest 3
setblock ~24 ~9 ~17 chest 3
setblock ~24 ~10 ~17 chest 3
setblock ~24 ~11 ~17 chest 3
setblock ~27 ~8 ~17 chest 3
setblock ~27 ~9 ~17 chest 3
setblock ~27 ~10 ~17 chest 3
setblock ~27 ~11 ~17 chest 3
setblock ~28 ~8 ~17 chest 3
setblock ~28 ~9 ~17 chest 3
setblock ~28 ~10 ~17 chest 3
setblock ~28 ~11 ~17 chest 3
setblock ~34 ~8 ~10 chest 2
setblock ~34 ~8 ~12 chest 3
setblock ~34 ~9 ~10 chest 2
setblock ~34 ~9 ~12 chest 3
setblock ~34 ~10 ~10 chest 2
setblock ~34 ~10 ~12 chest 3
setblock ~34 ~11 ~10 chest 2
setblock ~34 ~11 ~12 chest 3
setblock ~35 ~8 ~10 chest 2
setblock ~35 ~8 ~12 chest 3
setblock ~35 ~9 ~10 chest 2
setblock ~35 ~9 ~12 chest 3
setblock ~35 ~10 ~10 chest 2
setblock ~35 ~10 ~12 chest 3
setblock ~35 ~11 ~10 chest 2
setblock ~35 ~11 ~12 chest 3
setblock ~38 ~8 ~10 chest 2
setblock ~38 ~8 ~12 chest 3
setblock ~38 ~9 ~10 chest 2
setblock ~38 ~9 ~12 chest 3
setblock ~38 ~10 ~10 chest 2
setblock ~38 ~10 ~12 chest 3
setblock ~38 ~11 ~10 chest 2
setblock ~38 ~11 ~12 chest 3
setblock ~39 ~8 ~10 chest 2
setblock ~39 ~8 ~12 chest 3
setblock ~39 ~9 ~10 chest 2
setblock ~39 ~9 ~12 chest 3
setblock ~39 ~10 ~10 chest 2
setblock ~39 ~10 ~12 chest 3
setblock ~39 ~11 ~10 chest 2
setblock ~39 ~11 ~12 chest 3
setblock ~38 ~1 ~23 chest 4
setblock ~38 ~1 ~24 chest 4
fill ~1 ~-3 ~0 ~46 ~-3 ~0 stonebrick 0
fill ~1 ~-3 ~1 ~2 ~-3 ~1 stonebrick 0
fill ~1 ~-3 ~2 ~2 ~-3 ~2 stonebrick 0
fill ~1 ~-3 ~3 ~2 ~-3 ~3 stonebrick 0
fill ~1 ~-3 ~4 ~2 ~-3 ~4 stonebrick 0
fill ~1 ~-3 ~5 ~2 ~-3 ~5 stonebrick 0
fill ~1 ~-3 ~6 ~2 ~-3 ~6 stonebrick 0
fill ~1 ~-3 ~7 ~2 ~-3 ~7 stonebrick 0
fill ~1 ~-3 ~8 ~2 ~-3 ~8 stonebrick 0
fill ~1 ~-3 ~9 ~2 ~-3 ~9 stonebrick 0
fill ~1 ~-3 ~10 ~2 ~-3 ~10 stonebrick 0
fill ~1 ~-3 ~11 ~2 ~-3 ~11 stonebrick 0
fill ~1 ~-3 ~12 ~2 ~-3 ~12 stonebrick 0
fill ~1 ~-3 ~13 ~2 ~-3 ~13 stonebrick 0
fill ~1 ~-3 ~14 ~2 ~-3 ~14 stonebrick 0
fill ~1 ~-3 ~15 ~2 ~-3 ~15 stonebrick 0
fill ~1 ~-3 ~16 ~2 ~-3 ~16 stonebrick 0
fill ~1 ~-3 ~17 ~2 ~-3 ~17 stonebrick 0
fill ~1 ~-3 ~18 ~2 ~-3 ~18 stonebrick 0
fill ~1 ~-3 ~19 ~2 ~-3 ~19 stonebrick 0
fill ~1 ~-3 ~20 ~2 ~-3 ~20 stonebrick 0
fill ~1 ~-3 ~21 ~2 ~-3 ~21 stonebrick 0
fill ~1 ~-3 ~22 ~2 ~-3 ~22 stonebrick 0
fill ~1 ~-3 ~23 ~2 ~-3 ~23 stonebrick 0
fill ~1 ~-3 ~24 ~2 ~-3 ~24 stonebrick 0
fill ~1 ~-3 ~25 ~2 ~-3 ~25 stonebrick 0
fill ~1 ~-3 ~26 ~2 ~-3 ~26 stonebrick 0
fill ~1 ~-3 ~27 ~2 ~-3 ~27 stonebrick 0
fill ~1 ~-3 ~28 ~2 ~-3 ~28 stonebrick 0
fill ~1 ~-3 ~29 ~2 ~-3 ~29 stonebrick 0
fill ~1 ~-3 ~30 ~2 ~-3 ~30 stonebrick 0
fill ~1 ~-3 ~31 ~2 ~-3 ~31 stonebrick 0
fill ~1 ~-3 ~32 ~2 ~-3 ~32 stonebrick 0
fill ~1 ~-3 ~33 ~2 ~-3 ~33 stonebrick 0
fill ~1 ~-3 ~34 ~2 ~-3 ~34 stonebrick 0
fill ~1 ~-3 ~35 ~2 ~-3 ~35 stonebrick 0
fill ~1 ~-3 ~36 ~2 ~-3 ~36 stonebrick 0
fill ~1 ~-3 ~37 ~2 ~-3 ~37 stonebrick 0
fill ~1 ~-3 ~38 ~2 ~-3 ~38 stonebrick 0
fill ~1 ~-3 ~39 ~2 ~-3 ~39 stonebrick 0
fill ~1 ~-3 ~40 ~2 ~-3 ~40 stonebrick 0
fill ~1 ~-3 ~41 ~2 ~-3 ~41 stonebrick 0
fill ~1 ~-3 ~42 ~2 ~-3 ~42 stonebrick 0
fill ~1 ~-3 ~43 ~2 ~-3 ~43 stonebrick 0
fill ~1 ~-3 ~44 ~2 ~-3 ~44 stonebrick 0
fill ~1 ~-3 ~45 ~2 ~-3 ~45 stonebrick 0
fill ~1 ~-3 ~46 ~2 ~-3 ~46 stonebrick 0
fill ~1 ~-3 ~47 ~2 ~-3 ~47 stonebrick 0
fill ~1 ~-3 ~48 ~2 ~-3 ~48 stonebrick 0
fill ~1 ~-3 ~49 ~2 ~-3 ~49 stonebrick 0
fill ~1 ~-3 ~50 ~2 ~-3 ~50 stonebrick 0
fill ~1 ~-3 ~51 ~10 ~-3 ~51 stone 0
fill ~3 ~-3 ~1 ~45 ~-3 ~1 obsidian 0
fill ~3 ~-3 ~2 ~45 ~-3 ~2 obsidian 0
fill ~3 ~-3 ~3 ~45 ~-3 ~3 obsidian 0
fill ~3 ~-3 ~4 ~45 ~-3 ~4 obsidian 0
fill ~3 ~-3 ~5 ~45 ~-3 ~5 obsidian 0
fill ~3 ~-3 ~6 ~45 ~-3 ~6 obsidian 0
fill ~3 ~-3 ~7 ~45 ~-3 ~7 obsidian 0
fill ~3 ~-3 ~8 ~45 ~-3 ~8 obsidian 0
fill ~3 ~-3 ~9 ~45 ~-3 ~9 obsidian 0
fill ~3 ~-3 ~10 ~45 ~-3 ~10 obsidian 0
fill ~3 ~-3 ~11 ~45 ~-3 ~11 obsidian 0
fill ~3 ~-3 ~12 ~45 ~-3 ~12 obsidian 0
fill ~3 ~-3 ~13 ~45 ~-3 ~13 obsidian 0
fill ~3 ~-3 ~14 ~45 ~-3 ~14 obsidian 0
fill ~3 ~-3 ~15 ~45 ~-3 ~15 obsidian 0
fill ~3 ~-3 ~16 ~45 ~-3 ~16 obsidian 0
fill ~3 ~-3 ~17 ~45 ~-3 ~17 obsidian 0
fill ~3 ~-3 ~18 ~45 ~-3 ~18 obsidian 0
fill ~3 ~-3 ~19 ~45 ~-3 ~19 obsidian 0
fill ~3 ~-3 ~20 ~45 ~-3 ~20 obsidian 0
fill ~3 ~-3 ~21 ~45 ~-3 ~21 obsidian 0
fill ~3 ~-3 ~22 ~45 ~-3 ~22 obsidian 0
fill ~3 ~-3 ~23 ~45 ~-3 ~23 obsidian 0
fill ~3 ~-3 ~24 ~45 ~-3 ~24 obsidian 0
fill ~3 ~-3 ~25 ~45 ~-3 ~25 obsidian 0
fill ~3 ~-3 ~26 ~45 ~-3 ~26 obsidian 0
fill ~3 ~-3 ~27 ~45 ~-3 ~27 obsidian 0
fill ~3 ~-3 ~28 ~45 ~-3 ~28 obsidian 0
fill ~3 ~-3 ~29 ~45 ~-3 ~29 obsidian 0
fill ~3 ~-3 ~30 ~45 ~-3 ~30 obsidian 0
fill ~3 ~-3 ~31 ~45 ~-3 ~31 obsidian 0
fill ~3 ~-3 ~32 ~45 ~-3 ~32 obsidian 0
fill ~3 ~-3 ~33 ~45 ~-3 ~33 obsidian 0
fill ~3 ~-3 ~34 ~45 ~-3 ~34 obsidian 0
fill ~3 ~-3 ~35 ~45 ~-3 ~35 obsidian 0
fill ~3 ~-3 ~36 ~45 ~-3 ~36 obsidian 0
fill ~3 ~-3 ~37 ~45 ~-3 ~37 obsidian 0
fill ~3 ~-3 ~38 ~45 ~-3 ~38 obsidian 0
fill ~3 ~-3 ~39 ~45 ~-3 ~39 obsidian 0
fill ~3 ~-3 ~40 ~45 ~-3 ~40 obsidian 0
fill ~3 ~-3 ~41 ~45 ~-3 ~41 obsidian 0
fill ~3 ~-3 ~42 ~45 ~-3 ~42 obsidian 0
fill ~3 ~-3 ~43 ~45 ~-3 ~43 obsidian 0
fill ~3 ~-3 ~44 ~45 ~-3 ~44 obsidian 0
fill ~3 ~-3 ~45 ~45 ~-3 ~45 obsidian 0
fill ~3 ~-3 ~46 ~45 ~-3 ~46 obsidian 0
fill ~3 ~-3 ~47 ~45 ~-3 ~47 obsidian 0
fill ~3 ~-3 ~48 ~39 ~-3 ~48 obsidian 0
fill ~3 ~-3 ~49 ~45 ~-3 ~49 obsidian 0
fill ~3 ~-3 ~50 ~45 ~-3 ~50 obsidian 0
fill ~11 ~-3 ~51 ~30 ~-3 ~51 dirt 0
setblock ~31 ~-3 ~51 stone 0
fill ~32 ~-3 ~51 ~34 ~-3 ~51 dirt 0
setblock ~35 ~-3 ~51 grass 0
fill ~40 ~-3 ~48 ~40 ~1 ~48 lava 8
fill ~41 ~-3 ~48 ~45 ~-3 ~48 obsidian 0
fill ~46 ~-3 ~1 ~46 ~-3 ~50 stonebrick 0
fill ~1 ~-2 ~51 ~8 ~-2 ~51 stone 0
fill ~3 ~-2 ~1 ~45 ~-2 ~1 obsidian 0
fill ~3 ~-2 ~2 ~3 ~13 ~2 obsidian 0
fill ~3 ~-2 ~3 ~3 ~13 ~3 obsidian 0
fill ~3 ~-2 ~4 ~3 ~13 ~4 obsidian 0
fill ~3 ~-2 ~5 ~3 ~13 ~5 obsidian 0
fill ~3 ~-2 ~6 ~3 ~13 ~6 obsidian 0
fill ~3 ~-2 ~7 ~3 ~13 ~7 obsidian 0
fill ~3 ~-2 ~8 ~3 ~13 ~8 obsidian 0
fill ~3 ~-2 ~9 ~3 ~13 ~9 obsidian 0
fill ~3 ~-2 ~10 ~3 ~13 ~10 obsidian 0
fill ~3 ~-2 ~11 ~3 ~13 ~11 obsidian 0
fill ~3 ~-2 ~12 ~3 ~13 ~12 obsidian 0
fill ~3 ~-2 ~13 ~3 ~13 ~13 obsidian 0
fill ~3 ~-2 ~14 ~3 ~13 ~14 obsidian 0
fill ~3 ~-2 ~15 ~3 ~13 ~15 obsidian 0
fill ~3 ~-2 ~16 ~3 ~13 ~16 obsidian 0
fill ~3 ~-2 ~17 ~3 ~13 ~17 obsidian 0
fill ~3 ~-2 ~18 ~3 ~13 ~18 obsidian 0
fill ~3 ~-2 ~19 ~3 ~13 ~19 obsidian 0
fill ~3 ~-2 ~20 ~3 ~13 ~20 obsidian 0
fill ~3 ~-2 ~21 ~3 ~13 ~21 obsidian 0
fill ~3 ~-2 ~22 ~3 ~13 ~22 obsidian 0
fill ~3 ~-2 ~23 ~3 ~13 ~23 obsidian 0
fill ~3 ~-2 ~24 ~3 ~13 ~24 obsidian 0
fill ~3 ~-2 ~25 ~3 ~13 ~25 obsidian 0
fill ~3 ~-2 ~26 ~3 ~13 ~26 obsidian 0
fill ~3 ~-2 ~27 ~3 ~13 ~27 obsidian 0
fill ~3 ~-2 ~28 ~3 ~13 ~28 obsidian 0
fill ~3 ~-2 ~29 ~3 ~13 ~29 obsidian 0
fill ~3 ~-2 ~30 ~3 ~13 ~30 obsidian 0
fill ~3 ~-2 ~31 ~3 ~13 ~31 obsidian 0
fill ~3 ~-2 ~32 ~3 ~13 ~32 obsidian 0
fill ~3 ~-2 ~33 ~3 ~13 ~33 obsidian 0
fill ~3 ~-2 ~34 ~3 ~13 ~34 obsidian 0
fill ~3 ~-2 ~35 ~3 ~13 ~35 obsidian 0
fill ~3 ~-2 ~36 ~3 ~13 ~36 obsidian 0
fill ~3 ~-2 ~37 ~3 ~13 ~37 obsidian 0
fill ~3 ~-2 ~38 ~3 ~13 ~38 obsidian 0
fill ~3 ~-2 ~39 ~3 ~13 ~39 obsidian 0
fill ~3 ~-2 ~40 ~3 ~13 ~40 obsidian 0
fill ~3 ~-2 ~41 ~3 ~13 ~41 obsidian 0
fill ~3 ~-2 ~42 ~3 ~13 ~42 obsidian 0
fill ~3 ~-2 ~43 ~3 ~13 ~43 obsidian 0
fill ~3 ~-2 ~44 ~3 ~13 ~44 obsidian 0
fill ~3 ~-2 ~45 ~3 ~13 ~45 obsidian 0
fill ~3 ~-2 ~46 ~3 ~13 ~46 obsidian 0
fill ~3 ~-2 ~47 ~3 ~13 ~47 obsidian 0
fill ~3 ~-2 ~48 ~3 ~13 ~48 obsidian 0
fill ~3 ~-2 ~49 ~3 ~13 ~49 obsidian 0
fill ~3 ~-2 ~50 ~45 ~-2 ~50 obsidian 0
fill ~4 ~-2 ~2 ~44 ~-2 ~2 lava 8
fill ~4 ~-2 ~3 ~44 ~-2 ~3 lava 8
fill ~4 ~-2 ~4 ~4 ~1 ~4 lava 8
fill ~4 ~-2 ~5 ~4 ~1 ~5 lava 8
fill ~4 ~-2 ~6 ~4 ~1 ~6 lava 8
fill ~4 ~-2 ~7 ~4 ~1 ~7 lava 8
fill ~4 ~-2 ~8 ~4 ~1 ~8 lava 8
fill ~4 ~-2 ~9 ~4 ~1 ~9 lava 8
fill ~4 ~-2 ~10 ~4 ~1 ~10 lava 8
fill ~4 ~-2 ~11 ~4 ~1 ~11 lava 8
fill ~4 ~-2 ~12 ~4 ~1 ~12 lava 8
fill ~4 ~-2 ~13 ~4 ~1 ~13 lava 8
fill ~4 ~-2 ~14 ~4 ~1 ~14 lava 8
fill ~4 ~-2 ~15 ~4 ~1 ~15 lava 8
fill ~4 ~-2 ~16 ~4 ~1 ~16 lava 8
fill ~4 ~-2 ~17 ~4 ~1 ~17 lava 8
fill ~4 ~-2 ~18 ~4 ~1 ~18 lava 8
fill ~4 ~-2 ~19 ~4 ~1 ~19 lava 8
fill ~4 ~-2 ~20 ~4 ~1 ~20 lava 8
fill ~4 ~-2 ~21 ~4 ~1 ~21 lava 8
fill ~4 ~-2 ~22 ~4 ~1 ~22 lava 8
fill ~4 ~-2 ~23 ~4 ~1 ~23 lava 8
fill ~4 ~-2 ~24 ~4 ~1 ~24 lava 8
fill ~4 ~-2 ~25 ~4 ~1 ~25 lava 8
fill ~4 ~-2 ~26 ~4 ~1 ~26 lava 8
fill ~4 ~-2 ~27 ~4 ~1 ~27 lava 8
fill ~4 ~-2 ~28 ~4 ~1 ~28 lava 8
fill ~4 ~-2 ~29 ~4 ~1 ~29 lava 8
fill ~4 ~-2 ~30 ~4 ~1 ~30 lava 8
fill ~4 ~-2 ~31 ~4 ~1 ~31 lava 8
fill ~4 ~-2 ~32 ~4 ~1 ~32 lava 8
fill ~4 ~-2 ~33 ~4 ~1 ~33 lava 8
fill ~4 ~-2 ~34 ~4 ~1 ~34 lava 8
fill ~4 ~-2 ~35 ~4 ~1 ~35 lava 8
fill ~4 ~-2 ~36 ~4 ~1 ~36 lava 8
fill ~4 ~-2 ~37 ~4 ~1 ~37 lava 8
fill ~4 ~-2 ~38 ~4 ~1 ~38 lava 8
fill ~4 ~-2 ~39 ~4 ~1 ~39 lava 8
fill ~4 ~-2 ~40 ~4 ~1 ~40 lava 8
fill ~4 ~-2 ~41 ~4 ~1 ~41 lava 8
fill ~4 ~-2 ~42 ~4 ~1 ~42 lava 8
fill ~4 ~-2 ~43 ~4 ~1 ~43 lava 8
fill ~4 ~-2 ~44 ~4 ~1 ~44 lava 8
fill ~4 ~-2 ~45 ~4 ~1 ~45 lava 8
fill ~4 ~-2 ~46 ~4 ~1 ~46 lava 8
fill ~4 ~-2 ~47 ~4 ~1 ~47 lava 8
fill ~4 ~-2 ~48 ~44 ~-2 ~48 lava 8
fill ~4 ~-2 ~49 ~44 ~-2 ~49 lava 8
fill ~5 ~-2 ~4 ~42 ~-2 ~4 obsidian 0
fill ~5 ~-2 ~5 ~5 ~3 ~5 obsidian 0
fill ~5 ~-2 ~6 ~5 ~3 ~6 obsidian 0
fill ~5 ~-2 ~7 ~5 ~3 ~7 obsidian 0
fill ~5 ~-2 ~8 ~5 ~3 ~8 obsidian 0
fill ~5 ~-2 ~9 ~5 ~3 ~9 obsidian 0
fill ~5 ~-2 ~10 ~5 ~3 ~10 obsidian 0
fill ~5 ~-2 ~11 ~5 ~3 ~11 obsidian 0
fill ~5 ~-2 ~12 ~5 ~3 ~12 obsidian 0
fill ~5 ~-2 ~13 ~5 ~3 ~13 obsidian 0
fill ~5 ~-2 ~14 ~5 ~3 ~14 obsidian 0
fill ~5 ~-2 ~15 ~5 ~3 ~15 obsidian 0
fill ~5 ~-2 ~16 ~5 ~3 ~16 obsidian 0
fill ~5 ~-2 ~17 ~5 ~3 ~17 obsidian 0
fill ~5 ~-2 ~18 ~5 ~3 ~18 obsidian 0
fill ~5 ~-2 ~19 ~5 ~3 ~19 obsidian 0
fill ~5 ~-2 ~20 ~5 ~3 ~20 obsidian 0
fill ~5 ~-2 ~21 ~5 ~3 ~21 obsidian 0
fill ~5 ~-2 ~22 ~5 ~3 ~22 obsidian 0
fill ~5 ~-2 ~23 ~5 ~3 ~23 obsidian 0
fill ~5 ~-2 ~24 ~5 ~3 ~24 obsidian 0
fill ~5 ~-2 ~25 ~5 ~3 ~25 obsidian 0
fill ~5 ~-2 ~26 ~5 ~3 ~26 obsidian 0
fill ~5 ~-2 ~27 ~5 ~3 ~27 obsidian 0
fill ~5 ~-2 ~28 ~5 ~3 ~28 obsidian 0
fill ~5 ~-2 ~29 ~5 ~3 ~29 obsidian 0
fill ~5 ~-2 ~30 ~5 ~3 ~30 obsidian 0
fill ~5 ~-2 ~31 ~5 ~3 ~31 obsidian 0
fill ~5 ~-2 ~32 ~5 ~3 ~32 obsidian 0
fill ~5 ~-2 ~33 ~5 ~3 ~33 obsidian 0
fill ~5 ~-2 ~34 ~5 ~3 ~34 obsidian 0
fill ~5 ~-2 ~35 ~5 ~3 ~35 obsidian 0
fill ~5 ~-2 ~36 ~5 ~3 ~36 obsidian 0
fill ~5 ~-2 ~37 ~5 ~3 ~37 obsidian 0
fill ~5 ~-2 ~38 ~5 ~3 ~38 obsidian 0
fill ~5 ~-2 ~39 ~5 ~3 ~39 obsidian 0
fill ~5 ~-2 ~40 ~5 ~3 ~40 obsidian 0
fill ~5 ~-2 ~41 ~5 ~3 ~41 obsidian 0
fill ~5 ~-2 ~42 ~5 ~3 ~42 obsidian 0
fill ~5 ~-2 ~43 ~5 ~3 ~43 obsidian 0
fill ~5 ~-2 ~44 ~5 ~3 ~44 obsidian 0
fill ~5 ~-2 ~45 ~5 ~3 ~45 obsidian 0
fill ~5 ~-2 ~46 ~5 ~3 ~46 obsidian 0
fill ~5 ~-2 ~47 ~42 ~-2 ~47 obsidian 0
fill ~6 ~-2 ~5 ~41 ~-2 ~5 lava 8
fill ~6 ~-2 ~6 ~6 ~1 ~6 lava 8
fill ~6 ~-2 ~7 ~6 ~1 ~7 lava 8
fill ~6 ~-2 ~8 ~6 ~1 ~8 lava 8
fill ~6 ~-2 ~9 ~6 ~1 ~9 lava 8
fill ~6 ~-2 ~10 ~6 ~1 ~10 lava 8
fill ~6 ~-2 ~11 ~6 ~1 ~11 lava 8
fill ~6 ~-2 ~12 ~6 ~1 ~12 lava 8
fill ~6 ~-2 ~13 ~6 ~1 ~13 lava 8
fill ~6 ~-2 ~14 ~6 ~1 ~14 lava 8
fill ~6 ~-2 ~15 ~6 ~1 ~15 lava 8
fill ~6 ~-2 ~16 ~6 ~1 ~16 lava 8
fill ~6 ~-2 ~17 ~6 ~1 ~17 lava 8
fill ~6 ~-2 ~18 ~6 ~1 ~18 lava 8
fill ~6 ~-2 ~19 ~6 ~1 ~19 lava 8
fill ~6 ~-2 ~20 ~6 ~1 ~20 lava 8
fill ~6 ~-2 ~21 ~6 ~1 ~21 lava 8
fill ~6 ~-2 ~22 ~6 ~1 ~22 lava 8
fill ~6 ~-2 ~23 ~6 ~1 ~23 lava 8
fill ~6 ~-2 ~24 ~6 ~1 ~24 lava 8
fill ~6 ~-2 ~25 ~6 ~1 ~25 lava 8
fill ~6 ~-2 ~26 ~6 ~1 ~26 lava 8
fill ~6 ~-2 ~27 ~6 ~1 ~27 lava 8
fill ~6 ~-2 ~28 ~6 ~1 ~28 lava 8
fill ~6 ~-2 ~29 ~6 ~1 ~29 lava 8
fill ~6 ~-2 ~30 ~6 ~1 ~30 lava 8
fill ~6 ~-2 ~31 ~6 ~1 ~31 lava 8
fill ~6 ~-2 ~32 ~6 ~1 ~32 lava 8
fill ~6 ~-2 ~33 ~6 ~1 ~33 lava 8
fill ~6 ~-2 ~34 ~6 ~1 ~34 lava 8
fill ~6 ~-2 ~35 ~6 ~1 ~35 lava 8
fill ~6 ~-2 ~36 ~6 ~1 ~36 lava 8
fill ~6 ~-2 ~37 ~6 ~1 ~37 lava 8
fill ~6 ~-2 ~38 ~6 ~1 ~38 lava 8
fill ~6 ~-2 ~39 ~6 ~1 ~39 lava 8
fill ~6 ~-2 ~40 ~6 ~1 ~40 lava 8
fill ~6 ~-2 ~41 ~6 ~1 ~41 lava 8
fill ~6 ~-2 ~42 ~6 ~1 ~42 lava 8
fill ~6 ~-2 ~43 ~6 ~1 ~43 lava 8
fill ~6 ~-2 ~44 ~6 ~1 ~44 lava 8
fill ~6 ~-2 ~45 ~6 ~1 ~45 lava 8
fill ~6 ~-2 ~46 ~41 ~-2 ~46 lava 8
fill ~7 ~-2 ~6 ~40 ~-2 ~6 obsidian 0
fill ~7 ~-2 ~7 ~7 ~13 ~7 obsidian 0
fill ~7 ~-2 ~8 ~7 ~13 ~8 obsidian 0
fill ~7 ~-2 ~9 ~7 ~13 ~9 obsidian 0
fill ~7 ~-2 ~10 ~7 ~13 ~10 obsidian 0
fill ~7 ~-2 ~11 ~7 ~13 ~11 obsidian 0
fill ~7 ~-2 ~12 ~7 ~13 ~12 obsidian 0
fill ~7 ~-2 ~13 ~7 ~13 ~13 obsidian 0
fill ~7 ~-2 ~14 ~7 ~13 ~14 obsidian 0
fill ~7 ~-2 ~15 ~7 ~13 ~15 obsidian 0
fill ~7 ~-2 ~16 ~7 ~13 ~16 obsidian 0
fill ~7 ~-2 ~17 ~7 ~13 ~17 obsidian 0
fill ~7 ~-2 ~18 ~7 ~13 ~18 obsidian 0
fill ~7 ~-2 ~19 ~7 ~13 ~19 obsidian 0
fill ~7 ~-2 ~20 ~7 ~13 ~20 obsidian 0
fill ~7 ~-2 ~21 ~7 ~13 ~21 obsidian 0
fill ~7 ~-2 ~22 ~7 ~13 ~22 obsidian 0
fill ~7 ~-2 ~23 ~7 ~13 ~23 obsidian 0
fill ~7 ~-2 ~24 ~7 ~13 ~24 obsidian 0
fill ~7 ~-2 ~25 ~7 ~13 ~25 obsidian 0
fill ~7 ~-2 ~26 ~7 ~13 ~26 obsidian 0
fill ~7 ~-2 ~27 ~7 ~13 ~27 obsidian 0
fill ~7 ~-2 ~28 ~7 ~13 ~28 obsidian 0
fill ~7 ~-2 ~29 ~7 ~13 ~29 obsidian 0
fill ~7 ~-2 ~30 ~7 ~13 ~30 obsidian 0
fill ~7 ~-2 ~31 ~7 ~13 ~31 obsidian 0
fill ~7 ~-2 ~32 ~7 ~13 ~32 obsidian 0
fill ~7 ~-2 ~33 ~7 ~13 ~33 obsidian 0
fill ~7 ~-2 ~34 ~7 ~13 ~34 obsidian 0
fill ~7 ~-2 ~35 ~7 ~13 ~35 obsidian 0
fill ~7 ~-2 ~36 ~7 ~13 ~36 obsidian 0
fill ~7 ~-2 ~37 ~7 ~13 ~37 obsidian 0
fill ~7 ~-2 ~38 ~7 ~13 ~38 obsidian 0
fill ~7 ~-2 ~39 ~7 ~13 ~39 obsidian 0
fill ~7 ~-2 ~40 ~7 ~13 ~40 obsidian 0
fill ~7 ~-2 ~41 ~7 ~13 ~41 obsidian 0
fill ~7 ~-2 ~42 ~7 ~13 ~42 obsidian 0
fill ~7 ~-2 ~43 ~7 ~13 ~43 obsidian 0
fill ~7 ~-2 ~44 ~7 ~13 ~44 obsidian 0
fill ~7 ~-2 ~45 ~40 ~-2 ~45 obsidian 0
fill ~8 ~-2 ~7 ~39 ~-2 ~7 lava 8
fill ~8 ~-2 ~8 ~39 ~-2 ~8 lava 8
fill ~8 ~-2 ~9 ~39 ~-2 ~9 lava 8
fill ~8 ~-2 ~10 ~39 ~-2 ~10 lava 8
fill ~8 ~-2 ~11 ~39 ~-2 ~11 lava 8
fill ~8 ~-2 ~12 ~39 ~-2 ~12 lava 8
fill ~8 ~-2 ~13 ~39 ~-2 ~13 lava 8
fill ~8 ~-2 ~14 ~39 ~-2 ~14 lava 8
fill ~8 ~-2 ~15 ~39 ~-2 ~15 lava 8
fill ~8 ~-2 ~16 ~39 ~-2 ~16 lava 8
fill ~8 ~-2 ~17 ~39 ~-2 ~17 lava 8
fill ~8 ~-2 ~18 ~39 ~-2 ~18 lava 8
fill ~8 ~-2 ~19 ~39 ~-2 ~19 lava 8
fill ~8 ~-2 ~20 ~39 ~-2 ~20 lava 8
fill ~8 ~-2 ~21 ~39 ~-2 ~21 lava 8
fill ~8 ~-2 ~22 ~39 ~-2 ~22 lava 8
fill ~8 ~-2 ~23 ~39 ~-2 ~23 lava 8
fill ~8 ~-2 ~24 ~39 ~-2 ~24 lava 8
fill ~8 ~-2 ~25 ~39 ~-2 ~25 lava 8
fill ~8 ~-2 ~26 ~39 ~-2 ~26 lava 8
fill ~8 ~-2 ~27 ~39 ~-2 ~27 lava 8
fill ~8 ~-2 ~28 ~39 ~-2 ~28 lava 8
fill ~8 ~-2 ~29 ~39 ~-2 ~29 lava 8
fill ~8 ~-2 ~30 ~39 ~-2 ~30 lava 8
fill ~8 ~-2 ~31 ~39 ~-2 ~31 lava 8
fill ~8 ~-2 ~32 ~39 ~-2 ~32 lava 8
fill ~8 ~-2 ~33 ~39 ~-2 ~33 lava 8
fill ~8 ~-2 ~34 ~39 ~-2 ~34 lava 8
fill ~8 ~-2 ~35 ~39 ~-2 ~35 lava 8
fill ~8 ~-2 ~36 ~39 ~-2 ~36 lava 8
fill ~8 ~-2 ~37 ~39 ~-2 ~37 lava 8
fill ~8 ~-2 ~38 ~39 ~-2 ~38 lava 8
fill ~8 ~-2 ~39 ~39 ~-2 ~39 lava 8
fill ~8 ~-2 ~40 ~39 ~-2 ~40 lava 8
fill ~8 ~-2 ~41 ~39 ~-2 ~41 lava 8
fill ~8 ~-2 ~42 ~39 ~-2 ~42 lava 8
fill ~8 ~-2 ~43 ~39 ~-2 ~43 lava 8
fill ~8 ~-2 ~44 ~39 ~-2 ~44 lava 8
fill ~9 ~-2 ~51 ~12 ~-2 ~51 dirt 0
fill ~13 ~-2 ~51 ~25 ~-2 ~51 grass 0
fill ~26 ~-2 ~51 ~33 ~-2 ~51 dirt 0
setblock ~34 ~-2 ~51 grass 0
fill ~40 ~-2 ~7 ~40 ~13 ~7 obsidian 0
fill ~40 ~-2 ~8 ~40 ~13 ~8 obsidian 0
fill ~40 ~-2 ~9 ~40 ~13 ~9 obsidian 0
fill ~40 ~-2 ~10 ~40 ~13 ~10 obsidian 0
fill ~40 ~-2 ~11 ~40 ~13 ~11 obsidian 0
fill ~40 ~-2 ~12 ~40 ~13 ~12 obsidian 0
fill ~40 ~-2 ~13 ~40 ~13 ~13 obsidian 0
fill ~40 ~-2 ~14 ~40 ~13 ~14 obsidian 0
fill ~40 ~-2 ~15 ~40 ~13 ~15 obsidian 0
fill ~40 ~-2 ~16 ~40 ~13 ~16 obsidian 0
fill ~40 ~-2 ~17 ~40 ~13 ~17 obsidian 0
fill ~40 ~-2 ~18 ~40 ~13 ~18 obsidian 0
fill ~40 ~-2 ~19 ~40 ~13 ~19 obsidian 0
fill ~40 ~-2 ~20 ~40 ~13 ~20 obsidian 0
fill ~40 ~-2 ~21 ~40 ~13 ~21 obsidian 0
fill ~40 ~-2 ~22 ~40 ~13 ~22 obsidian 0
fill ~40 ~-2 ~23 ~40 ~13 ~23 obsidian 0
fill ~40 ~-2 ~24 ~40 ~13 ~24 obsidian 0
fill ~40 ~-2 ~25 ~40 ~13 ~25 obsidian 0
fill ~40 ~-2 ~26 ~40 ~13 ~26 obsidian 0
fill ~40 ~-2 ~27 ~40 ~13 ~27 obsidian 0
fill ~40 ~-2 ~28 ~40 ~13 ~28 obsidian 0
fill ~40 ~-2 ~29 ~40 ~13 ~29 obsidian 0
fill ~40 ~-2 ~30 ~40 ~13 ~30 obsidian 0
fill ~40 ~-2 ~31 ~40 ~13 ~31 obsidian 0
fill ~40 ~-2 ~32 ~40 ~13 ~32 obsidian 0
fill ~40 ~-2 ~33 ~40 ~13 ~33 obsidian 0
fill ~40 ~-2 ~34 ~40 ~13 ~34 obsidian 0
fill ~40 ~-2 ~35 ~40 ~13 ~35 obsidian 0
fill ~40 ~-2 ~36 ~40 ~13 ~36 obsidian 0
fill ~40 ~-2 ~37 ~40 ~13 ~37 obsidian 0
fill ~40 ~-2 ~38 ~40 ~13 ~38 obsidian 0
fill ~40 ~-2 ~39 ~40 ~13 ~39 obsidian 0
fill ~40 ~-2 ~40 ~40 ~13 ~40 obsidian 0
fill ~40 ~-2 ~41 ~40 ~13 ~41 obsidian 0
fill ~40 ~-2 ~42 ~40 ~13 ~42 obsidian 0
fill ~40 ~-2 ~43 ~40 ~13 ~43 obsidian 0
fill ~40 ~-2 ~44 ~40 ~13 ~44 obsidian 0
fill ~41 ~-2 ~6 ~41 ~1 ~6 lava 8
fill ~41 ~-2 ~7 ~41 ~1 ~7 lava 8
fill ~41 ~-2 ~8 ~41 ~1 ~8 lava 8
fill ~41 ~-2 ~9 ~41 ~1 ~9 lava 8
fill ~41 ~-2 ~10 ~41 ~1 ~10 lava 8
fill ~41 ~-2 ~11 ~41 ~1 ~11 lava 8
fill ~41 ~-2 ~12 ~41 ~1 ~12 lava 8
fill ~41 ~-2 ~13 ~41 ~1 ~13 lava 8
fill ~41 ~-2 ~14 ~41 ~1 ~14 lava 8
fill ~41 ~-2 ~15 ~41 ~1 ~15 lava 8
fill ~41 ~-2 ~16 ~41 ~1 ~16 lava 8
fill ~41 ~-2 ~17 ~41 ~1 ~17 lava 8
fill ~41 ~-2 ~18 ~41 ~1 ~18 lava 8
fill ~41 ~-2 ~19 ~41 ~1 ~19 lava 8
fill ~41 ~-2 ~20 ~41 ~1 ~20 lava 8
fill ~41 ~-2 ~21 ~41 ~1 ~21 lava 8
fill ~41 ~-2 ~22 ~41 ~1 ~22 lava 8
fill ~41 ~-2 ~23 ~41 ~1 ~23 lava 8
fill ~41 ~-2 ~24 ~41 ~1 ~24 lava 8
fill ~41 ~-2 ~25 ~41 ~1 ~25 lava 8
fill ~41 ~-2 ~26 ~41 ~1 ~26 lava 8
fill ~41 ~-2 ~27 ~41 ~1 ~27 lava 8
fill ~41 ~-2 ~28 ~41 ~1 ~28 lava 8
fill ~41 ~-2 ~29 ~41 ~1 ~29 lava 8
fill ~41 ~-2 ~30 ~41 ~1 ~30 lava 8
fill ~41 ~-2 ~31 ~41 ~1 ~31 lava 8
fill ~41 ~-2 ~32 ~41 ~1 ~32 lava 8
fill ~41 ~-2 ~33 ~41 ~1 ~33 lava 8
fill ~41 ~-2 ~34 ~41 ~1 ~34 lava 8
fill ~41 ~-2 ~35 ~41 ~1 ~35 lava 8
fill ~41 ~-2 ~36 ~41 ~1 ~36 lava 8
fill ~41 ~-2 ~37 ~41 ~1 ~37 lava 8
fill ~41 ~-2 ~38 ~41 ~1 ~38 lava 8
fill ~41 ~-2 ~39 ~41 ~1 ~39 lava 8
fill ~41 ~-2 ~40 ~41 ~1 ~40 lava 8
fill ~41 ~-2 ~41 ~41 ~1 ~41 lava 8
fill ~41 ~-2 ~42 ~41 ~1 ~42 lava 8
fill ~41 ~-2 ~43 ~41 ~1 ~43 lava 8
fill ~41 ~-2 ~44 ~41 ~1 ~44 lava 8
fill ~41 ~-2 ~45 ~41 ~1 ~45 lava 8
fill ~42 ~-2 ~5 ~42 ~3 ~5 obsidian 0
fill ~42 ~-2 ~6 ~42 ~3 ~6 obsidian 0
fill ~42 ~-2 ~7 ~42 ~3 ~7 obsidian 0
fill ~42 ~-2 ~8 ~42 ~3 ~8 obsidian 0
fill ~42 ~-2 ~9 ~42 ~3 ~9 obsidian 0
fill ~42 ~-2 ~10 ~42 ~3 ~10 obsidian 0
fill ~42 ~-2 ~11 ~42 ~3 ~11 obsidian 0
fill ~42 ~-2 ~12 ~42 ~3 ~12 obsidian 0
fill ~42 ~-2 ~13 ~42 ~3 ~13 obsidian 0
fill ~42 ~-2 ~14 ~42 ~3 ~14 obsidian 0
fill ~42 ~-2 ~15 ~42 ~3 ~15 obsidian 0
fill ~42 ~-2 ~16 ~42 ~3 ~16 obsidian 0
fill ~42 ~-2 ~17 ~42 ~3 ~17 obsidian 0
fill ~42 ~-2 ~18 ~42 ~3 ~18 obsidian 0
fill ~42 ~-2 ~19 ~42 ~3 ~19 obsidian 0
fill ~42 ~-2 ~20 ~42 ~3 ~20 obsidian 0
fill ~42 ~-2 ~21 ~42 ~3 ~21 obsidian 0
fill ~42 ~-2 ~22 ~42 ~3 ~22 obsidian 0
fill ~42 ~-2 ~23 ~42 ~3 ~23 obsidian 0
fill ~42 ~-2 ~24 ~42 ~3 ~24 obsidian 0
fill ~42 ~-2 ~25 ~42 ~3 ~25 obsidian 0
fill ~42 ~-2 ~26 ~42 ~3 ~26 obsidian 0
fill ~42 ~-2 ~27 ~42 ~3 ~27 obsidian 0
fill ~42 ~-2 ~28 ~42 ~3 ~28 obsidian 0
fill ~42 ~-2 ~29 ~42 ~3 ~29 obsidian 0
fill ~42 ~-2 ~30 ~42 ~3 ~30 obsidian 0
fill ~42 ~-2 ~31 ~42 ~3 ~31 obsidian 0
fill ~42 ~-2 ~32 ~42 ~3 ~32 obsidian 0
fill ~42 ~-2 ~33 ~42 ~3 ~33 obsidian 0
fill ~42 ~-2 ~34 ~42 ~3 ~34 obsidian 0
fill ~42 ~-2 ~35 ~42 ~3 ~35 obsidian 0
fill ~42 ~-2 ~36 ~42 ~3 ~36 obsidian 0
fill ~42 ~-2 ~37 ~42 ~3 ~37 obsidian 0
fill ~42 ~-2 ~38 ~42 ~3 ~38 obsidian 0
fill ~42 ~-2 ~39 ~42 ~3 ~39 obsidian 0
fill ~42 ~-2 ~40 ~42 ~3 ~40 obsidian 0
fill ~42 ~-2 ~41 ~42 ~3 ~41 obsidian 0
fill ~42 ~-2 ~42 ~42 ~3 ~42 obsidian 0
fill ~42 ~-2 ~43 ~42 ~3 ~43 obsidian 0
fill ~42 ~-2 ~44 ~42 ~3 ~44 obsidian 0
fill ~42 ~-2 ~45 ~42 ~3 ~45 obsidian 0
fill ~42 ~-2 ~46 ~42 ~3 ~46 obsidian 0
fill ~43 ~-2 ~4 ~44 ~-2 ~4 lava 8
fill ~43 ~-2 ~5 ~44 ~-2 ~5 lava 8
fill ~43 ~-2 ~6 ~44 ~-2 ~6 lava 8
fill ~43 ~-2 ~7 ~44 ~-2 ~7 lava 8
fill ~43 ~-2 ~8 ~44 ~-2 ~8 lava 8
fill ~43 ~-2 ~9 ~44 ~-2 ~9 lava 8
fill ~43 ~-2 ~10 ~44 ~-2 ~10 lava 8
fill ~43 ~-2 ~11 ~44 ~-2 ~11 lava 8
fill ~43 ~-2 ~12 ~44 ~-2 ~12 lava 8
fill ~43 ~-2 ~13 ~44 ~-2 ~13 lava 8
fill ~43 ~-2 ~14 ~44 ~-2 ~14 lava 8
fill ~43 ~-2 ~15 ~44 ~-2 ~15 lava 8
fill ~43 ~-2 ~16 ~44 ~-2 ~16 lava 8
fill ~43 ~-2 ~17 ~44 ~-2 ~17 lava 8
fill ~43 ~-2 ~18 ~44 ~-2 ~18 lava 8
fill ~43 ~-2 ~19 ~44 ~-2 ~19 lava 8
fill ~43 ~-2 ~20 ~44 ~-2 ~20 lava 8
fill ~43 ~-2 ~21 ~44 ~-2 ~21 lava 8
fill ~43 ~-2 ~22 ~44 ~-2 ~22 lava 8
fill ~43 ~-2 ~23 ~44 ~-2 ~23 lava 8
fill ~43 ~-2 ~24 ~44 ~-2 ~24 lava 8
fill ~43 ~-2 ~25 ~44 ~-2 ~25 lava 8
fill ~43 ~-2 ~26 ~44 ~-2 ~26 lava 8
fill ~43 ~-2 ~27 ~44 ~-2 ~27 lava 8
fill ~43 ~-2 ~28 ~44 ~-2 ~28 lava 8
fill ~43 ~-2 ~29 ~44 ~-2 ~29 lava 8
fill ~43 ~-2 ~30 ~44 ~-2 ~30 lava 8
fill ~43 ~-2 ~31 ~44 ~-2 ~31 lava 8
fill ~43 ~-2 ~32 ~44 ~-2 ~32 lava 8
fill ~43 ~-2 ~33 ~44 ~-2 ~33 lava 8
fill ~43 ~-2 ~34 ~44 ~-2 ~34 lava 8
fill ~43 ~-2 ~35 ~44 ~-2 ~35 lava 8
fill ~43 ~-2 ~36 ~44 ~-2 ~36 lava 8
fill ~43 ~-2 ~37 ~44 ~-2 ~37 lava 8
fill ~43 ~-2 ~38 ~44 ~-2 ~38 lava 8
fill ~43 ~-2 ~39 ~44 ~-2 ~39 lava 8
fill ~43 ~-2 ~40 ~44 ~-2 ~40 lava 8
fill ~43 ~-2 ~41 ~44 ~-2 ~41 lava 8
fill ~43 ~-2 ~42 ~44 ~-2 ~42 lava 8
fill ~43 ~-2 ~43 ~44 ~-2 ~43 lava 8
fill ~43 ~-2 ~44 ~44 ~-2 ~44 lava 8
fill ~43 ~-2 ~45 ~44 ~-2 ~45 lava 8
fill ~43 ~-2 ~46 ~44 ~-2 ~46 lava 8
fill ~43 ~-2 ~47 ~44 ~-2 ~47 lava 8
fill ~45 ~-2 ~2 ~45 ~13 ~2 obsidian 0
fill ~45 ~-2 ~3 ~45 ~13 ~3 obsidian 0
fill ~45 ~-2 ~4 ~45 ~13 ~4 obsidian 0
fill ~45 ~-2 ~5 ~45 ~13 ~5 obsidian 0
fill ~45 ~-2 ~6 ~45 ~13 ~6 obsidian 0
fill ~45 ~-2 ~7 ~45 ~13 ~7 obsidian 0
fill ~45 ~-2 ~8 ~45 ~13 ~8 obsidian 0
fill ~45 ~-2 ~9 ~45 ~13 ~9 obsidian 0
fill ~45 ~-2 ~10 ~45 ~13 ~10 obsidian 0
fill ~45 ~-2 ~11 ~45 ~13 ~11 obsidian 0
fill ~45 ~-2 ~12 ~45 ~13 ~12 obsidian 0
fill ~45 ~-2 ~13 ~45 ~13 ~13 obsidian 0
fill ~45 ~-2 ~14 ~45 ~13 ~14 obsidian 0
fill ~45 ~-2 ~15 ~45 ~13 ~15 obsidian 0
fill ~45 ~-2 ~16 ~45 ~13 ~16 obsidian 0
fill ~45 ~-2 ~17 ~45 ~13 ~17 obsidian 0
fill ~45 ~-2 ~18 ~45 ~13 ~18 obsidian 0
fill ~45 ~-2 ~19 ~45 ~13 ~19 obsidian 0
fill ~45 ~-2 ~20 ~45 ~13 ~20 obsidian 0
fill ~45 ~-2 ~21 ~45 ~13 ~21 obsidian 0
fill ~45 ~-2 ~22 ~45 ~13 ~22 obsidian 0
fill ~45 ~-2 ~23 ~45 ~13 ~23 obsidian 0
fill ~45 ~-2 ~24 ~45 ~13 ~24 obsidian 0
fill ~45 ~-2 ~25 ~45 ~13 ~25 obsidian 0
fill ~45 ~-2 ~26 ~45 ~13 ~26 obsidian 0
fill ~45 ~-2 ~27 ~45 ~13 ~27 obsidian 0
fill ~45 ~-2 ~28 ~45 ~13 ~28 obsidian 0
fill ~45 ~-2 ~29 ~45 ~13 ~29 obsidian 0
fill ~45 ~-2 ~30 ~45 ~13 ~30 obsidian 0
fill ~45 ~-2 ~31 ~45 ~13 ~31 obsidian 0
fill ~45 ~-2 ~32 ~45 ~13 ~32 obsidian 0
fill ~45 ~-2 ~33 ~45 ~13 ~33 obsidian 0
fill ~45 ~-2 ~34 ~45 ~13 ~34 obsidian 0
fill ~45 ~-2 ~35 ~45 ~13 ~35 obsidian 0
fill ~45 ~-2 ~36 ~45 ~13 ~36 obsidian 0
fill ~45 ~-2 ~37 ~45 ~13 ~37 obsidian 0
fill ~45 ~-2 ~38 ~45 ~13 ~38 obsidian 0
fill ~45 ~-2 ~39 ~45 ~13 ~39 obsidian 0
fill ~45 ~-2 ~40 ~45 ~13 ~40 obsidian 0
fill ~45 ~-2 ~41 ~45 ~13 ~41 obsidian 0
fill ~45 ~-2 ~42 ~45 ~13 ~42 obsidian 0
fill ~45 ~-2 ~43 ~45 ~13 ~43 obsidian 0
fill ~45 ~-2 ~44 ~45 ~13 ~44 obsidian 0
fill ~45 ~-2 ~45 ~45 ~13 ~45 obsidian 0
fill ~45 ~-2 ~46 ~45 ~13 ~46 obsidian 0
fill ~45 ~-2 ~47 ~45 ~13 ~47 obsidian 0
fill ~45 ~-2 ~48 ~45 ~13 ~48 obsidian 0
fill ~45 ~-2 ~49 ~45 ~13 ~49 obsidian 0
fill ~1 ~-1 ~51 ~10 ~-1 ~51 dirt 0
fill ~3 ~-1 ~1 ~45 ~-1 ~1 obsidian 0
fill ~3 ~-1 ~50 ~45 ~-1 ~50 obsidian 0
fill ~4 ~-1 ~2 ~44 ~-1 ~2 lava 8
fill ~4 ~-1 ~3 ~44 ~-1 ~3 lava 8
fill ~4 ~-1 ~48 ~44 ~-1 ~48 lava 8
fill ~4 ~-1 ~49 ~44 ~-1 ~49 lava 8
fill ~5 ~-1 ~4 ~42 ~-1 ~4 obsidian 0
fill ~5 ~-1 ~47 ~42 ~-1 ~47 obsidian 0
fill ~6 ~-1 ~5 ~41 ~-1 ~5 lava 8
fill ~6 ~-1 ~46 ~41 ~-1 ~46 lava 8
fill ~7 ~-1 ~6 ~40 ~-1 ~6 obsidian 0
fill ~7 ~-1 ~45 ~40 ~-1 ~45 obsidian 0
fill ~8 ~-1 ~7 ~39 ~-1 ~7 lava 0
fill ~8 ~-1 ~8 ~39 ~-1 ~8 lava 0
fill ~8 ~-1 ~9 ~39 ~-1 ~9 lava 0
fill ~8 ~-1 ~10 ~39 ~-1 ~10 lava 0
fill ~8 ~-1 ~11 ~39 ~-1 ~11 lava 0
fill ~8 ~-1 ~12 ~39 ~-1 ~12 lava 0
fill ~8 ~-1 ~13 ~39 ~-1 ~13 lava 0
fill ~8 ~-1 ~14 ~39 ~-1 ~14 lava 0
fill ~8 ~-1 ~15 ~39 ~-1 ~15 lava 0
fill ~8 ~-1 ~16 ~39 ~-1 ~16 lava 0
fill ~8 ~-1 ~17 ~39 ~-1 ~17 lava 0
fill ~8 ~-1 ~18 ~39 ~-1 ~18 lava 0
fill ~8 ~-1 ~19 ~39 ~-1 ~19 lava 0
fill ~8 ~-1 ~20 ~39 ~-1 ~20 lava 0
fill ~8 ~-1 ~21 ~39 ~-1 ~21 lava 0
fill ~8 ~-1 ~22 ~39 ~-1 ~22 lava 0
fill ~8 ~-1 ~23 ~39 ~-1 ~23 lava 0
fill ~8 ~-1 ~24 ~39 ~-1 ~24 lava 0
fill ~8 ~-1 ~25 ~39 ~-1 ~25 lava 0
fill ~8 ~-1 ~26 ~39 ~-1 ~26 lava 0
fill ~8 ~-1 ~27 ~39 ~-1 ~27 lava 0
fill ~8 ~-1 ~28 ~39 ~-1 ~28 lava 0
fill ~8 ~-1 ~29 ~39 ~-1 ~29 lava 0
fill ~8 ~-1 ~30 ~39 ~-1 ~30 lava 0
fill ~8 ~-1 ~31 ~39 ~-1 ~31 lava 0
fill ~8 ~-1 ~32 ~39 ~-1 ~32 lava 0
fill ~8 ~-1 ~33 ~39 ~-1 ~33 lava 0
fill ~8 ~-1 ~34 ~39 ~-1 ~34 lava 0
fill ~8 ~-1 ~35 ~39 ~-1 ~35 lava 0
fill ~8 ~-1 ~36 ~39 ~-1 ~36 lava 0
fill ~8 ~-1 ~37 ~39 ~-1 ~37 lava 0
fill ~8 ~-1 ~38 ~39 ~-1 ~38 lava 0
fill ~8 ~-1 ~39 ~39 ~-1 ~39 lava 0
fill ~8 ~-1 ~40 ~39 ~-1 ~40 lava 0
fill ~8 ~-1 ~41 ~39 ~-1 ~41 lava 0
fill ~8 ~-1 ~42 ~39 ~-1 ~42 lava 0
fill ~8 ~-1 ~43 ~39 ~-1 ~43 lava 0
fill ~8 ~-1 ~44 ~39 ~-1 ~44 lava 0
fill ~11 ~-1 ~51 ~12 ~-1 ~51 grass 0
setblock ~22 ~-1 ~51 tallgrass 1
setblock ~24 ~-1 ~51 tallgrass 1
fill ~26 ~-1 ~51 ~27 ~-1 ~51 grass 0
fill ~28 ~-1 ~51 ~31 ~-1 ~51 dirt 0
fill ~32 ~-1 ~51 ~33 ~-1 ~51 grass 0
fill ~43 ~-1 ~4 ~44 ~-1 ~4 lava 8
fill ~43 ~-1 ~5 ~44 ~-1 ~5 lava 8
fill ~43 ~-1 ~6 ~44 ~-1 ~6 lava 8
fill ~43 ~-1 ~7 ~44 ~-1 ~7 lava 8
fill ~43 ~-1 ~8 ~44 ~-1 ~8 lava 8
fill ~43 ~-1 ~9 ~44 ~-1 ~9 lava 8
fill ~43 ~-1 ~10 ~44 ~-1 ~10 lava 8
fill ~43 ~-1 ~11 ~44 ~-1 ~11 lava 8
fill ~43 ~-1 ~12 ~44 ~-1 ~12 lava 8
fill ~43 ~-1 ~13 ~44 ~-1 ~13 lava 8
fill ~43 ~-1 ~14 ~44 ~-1 ~14 lava 8
fill ~43 ~-1 ~15 ~44 ~-1 ~15 lava 8
fill ~43 ~-1 ~16 ~44 ~-1 ~16 lava 8
fill ~43 ~-1 ~17 ~44 ~-1 ~17 lava 8
fill ~43 ~-1 ~18 ~44 ~-1 ~18 lava 8
fill ~43 ~-1 ~19 ~44 ~-1 ~19 lava 8
fill ~43 ~-1 ~20 ~44 ~-1 ~20 lava 8
fill ~43 ~-1 ~21 ~44 ~-1 ~21 lava 8
fill ~43 ~-1 ~22 ~44 ~-1 ~22 lava 8
fill ~43 ~-1 ~23 ~44 ~-1 ~23 lava 8
fill ~43 ~-1 ~24 ~44 ~-1 ~24 lava 8
fill ~43 ~-1 ~25 ~44 ~-1 ~25 lava 8
fill ~43 ~-1 ~26 ~44 ~-1 ~26 lava 8
fill ~43 ~-1 ~27 ~44 ~-1 ~27 lava 8
fill ~43 ~-1 ~28 ~44 ~-1 ~28 lava 8
fill ~43 ~-1 ~29 ~44 ~-1 ~29 lava 8
fill ~43 ~-1 ~30 ~44 ~-1 ~30 lava 8
fill ~43 ~-1 ~31 ~44 ~-1 ~31 lava 8
fill ~43 ~-1 ~32 ~44 ~-1 ~32 lava 8
fill ~43 ~-1 ~33 ~44 ~-1 ~33 lava 8
fill ~43 ~-1 ~34 ~44 ~-1 ~34 lava 8
fill ~43 ~-1 ~35 ~44 ~-1 ~35 lava 8
fill ~43 ~-1 ~36 ~44 ~-1 ~36 lava 8
fill ~43 ~-1 ~37 ~44 ~-1 ~37 lava 8
fill ~43 ~-1 ~38 ~44 ~-1 ~38 lava 8
fill ~43 ~-1 ~39 ~44 ~-1 ~39 lava 8
fill ~43 ~-1 ~40 ~44 ~-1 ~40 lava 8
fill ~43 ~-1 ~41 ~44 ~-1 ~41 lava 8
fill ~43 ~-1 ~42 ~44 ~-1 ~42 lava 8
fill ~43 ~-1 ~43 ~44 ~-1 ~43 lava 8
fill ~43 ~-1 ~44 ~44 ~-1 ~44 lava 8
fill ~43 ~-1 ~45 ~44 ~-1 ~45 lava 8
fill ~43 ~-1 ~46 ~44 ~-1 ~46 lava 8
fill ~43 ~-1 ~47 ~44 ~-1 ~47 lava 8
fill ~1 ~0 ~51 ~8 ~0 ~51 dirt 0
fill ~3 ~0 ~1 ~45 ~0 ~1 obsidian 0
fill ~3 ~0 ~50 ~45 ~0 ~50 obsidian 0
fill ~4 ~0 ~2 ~44 ~0 ~2 lava 8
fill ~4 ~0 ~3 ~44 ~0 ~3 lava 8
fill ~4 ~0 ~48 ~44 ~0 ~48 lava 8
fill ~4 ~0 ~49 ~44 ~0 ~49 lava 8
fill ~5 ~0 ~4 ~42 ~0 ~4 obsidian 0
fill ~5 ~0 ~47 ~42 ~0 ~47 obsidian 0
fill ~6 ~0 ~5 ~41 ~0 ~5 lava 8
fill ~6 ~0 ~46 ~41 ~0 ~46 lava 8
fill ~7 ~0 ~6 ~40 ~0 ~6 obsidian 0
fill ~7 ~0 ~45 ~40 ~0 ~45 obsidian 0
fill ~8 ~0 ~7 ~40 ~0 ~7 obsidian 0
fill ~8 ~0 ~8 ~40 ~0 ~8 obsidian 0
fill ~8 ~0 ~9 ~40 ~0 ~9 obsidian 0
fill ~8 ~0 ~10 ~40 ~0 ~10 obsidian 0
fill ~8 ~0 ~11 ~40 ~0 ~11 obsidian 0
fill ~8 ~0 ~12 ~40 ~0 ~12 obsidian 0
fill ~8 ~0 ~13 ~40 ~0 ~13 obsidian 0
fill ~8 ~0 ~14 ~40 ~0 ~14 obsidian 0
fill ~8 ~0 ~15 ~40 ~0 ~15 obsidian 0
fill ~8 ~0 ~16 ~40 ~0 ~16 obsidian 0
fill ~8 ~0 ~17 ~40 ~0 ~17 obsidian 0
fill ~8 ~0 ~18 ~40 ~0 ~18 obsidian 0
fill ~8 ~0 ~19 ~40 ~0 ~19 obsidian 0
fill ~8 ~0 ~20 ~40 ~0 ~20 obsidian 0
fill ~8 ~0 ~21 ~40 ~0 ~21 obsidian 0
fill ~8 ~0 ~22 ~40 ~0 ~22 obsidian 0
fill ~8 ~0 ~23 ~40 ~0 ~23 obsidian 0
fill ~8 ~0 ~24 ~40 ~0 ~24 obsidian 0
fill ~8 ~0 ~25 ~40 ~0 ~25 obsidian 0
fill ~8 ~0 ~26 ~40 ~0 ~26 obsidian 0
fill ~8 ~0 ~27 ~40 ~0 ~27 obsidian 0
fill ~8 ~0 ~28 ~40 ~0 ~28 obsidian 0
fill ~8 ~0 ~29 ~40 ~0 ~29 obsidian 0
fill ~8 ~0 ~30 ~40 ~0 ~30 obsidian 0
fill ~8 ~0 ~31 ~40 ~0 ~31 obsidian 0
fill ~8 ~0 ~32 ~40 ~0 ~32 obsidian 0
fill ~8 ~0 ~33 ~40 ~0 ~33 obsidian 0
fill ~8 ~0 ~34 ~40 ~0 ~34 obsidian 0
fill ~8 ~0 ~35 ~40 ~0 ~35 obsidian 0
fill ~8 ~0 ~36 ~40 ~0 ~36 obsidian 0
fill ~8 ~0 ~37 ~40 ~0 ~37 obsidian 0
fill ~8 ~0 ~38 ~40 ~0 ~38 obsidian 0
fill ~8 ~0 ~39 ~40 ~0 ~39 obsidian 0
fill ~8 ~0 ~40 ~40 ~0 ~40 obsidian 0
fill ~8 ~0 ~41 ~40 ~0 ~41 obsidian 0
fill ~8 ~0 ~42 ~40 ~0 ~42 obsidian 0
fill ~8 ~0 ~43 ~40 ~0 ~43 obsidian 0
fill ~8 ~0 ~44 ~40 ~0 ~44 obsidian 0
fill ~9 ~0 ~51 ~10 ~0 ~51 grass 0
setblock ~26 ~0 ~51 tallgrass 1
fill ~28 ~0 ~51 ~30 ~0 ~51 grass 0
setblock ~31 ~0 ~51 dirt 0
fill ~43 ~0 ~4 ~44 ~0 ~4 lava 8
fill ~43 ~0 ~5 ~44 ~0 ~5 lava 8
fill ~43 ~0 ~6 ~44 ~0 ~6 lava 8
fill ~43 ~0 ~7 ~44 ~0 ~7 lava 8
fill ~43 ~0 ~8 ~44 ~0 ~8 lava 8
fill ~43 ~0 ~9 ~44 ~0 ~9 lava 8
fill ~43 ~0 ~10 ~44 ~0 ~10 lava 8
fill ~43 ~0 ~11 ~44 ~0 ~11 lava 8
fill ~43 ~0 ~12 ~44 ~0 ~12 lava 8
fill ~43 ~0 ~13 ~44 ~0 ~13 lava 8
fill ~43 ~0 ~14 ~44 ~0 ~14 lava 8
fill ~43 ~0 ~15 ~44 ~0 ~15 lava 8
fill ~43 ~0 ~16 ~44 ~0 ~16 lava 8
fill ~43 ~0 ~17 ~44 ~0 ~17 lava 8
fill ~43 ~0 ~18 ~44 ~0 ~18 lava 8
fill ~43 ~0 ~19 ~44 ~0 ~19 lava 8
fill ~43 ~0 ~20 ~44 ~0 ~20 lava 8
fill ~43 ~0 ~21 ~44 ~0 ~21 lava 8
fill ~43 ~0 ~22 ~44 ~0 ~22 lava 8
fill ~43 ~0 ~23 ~44 ~0 ~23 lava 8
fill ~43 ~0 ~24 ~44 ~0 ~24 lava 8
fill ~43 ~0 ~25 ~44 ~0 ~25 lava 8
fill ~43 ~0 ~26 ~44 ~0 ~26 lava 8
fill ~43 ~0 ~27 ~44 ~0 ~27 lava 8
fill ~43 ~0 ~28 ~44 ~0 ~28 lava 8
fill ~43 ~0 ~29 ~44 ~0 ~29 lava 8
fill ~43 ~0 ~30 ~44 ~0 ~30 lava 8
fill ~43 ~0 ~31 ~44 ~0 ~31 lava 8
fill ~43 ~0 ~32 ~44 ~0 ~32 lava 8
fill ~43 ~0 ~33 ~44 ~0 ~33 lava 8
fill ~43 ~0 ~34 ~44 ~0 ~34 lava 8
fill ~43 ~0 ~35 ~44 ~0 ~35 lava 8
fill ~43 ~0 ~36 ~44 ~0 ~36 lava 8
fill ~43 ~0 ~37 ~44 ~0 ~37 lava 8
fill ~43 ~0 ~38 ~44 ~0 ~38 lava 8
fill ~43 ~0 ~39 ~44 ~0 ~39 lava 8
fill ~43 ~0 ~40 ~44 ~0 ~40 lava 8
fill ~43 ~0 ~41 ~44 ~0 ~41 lava 8
fill ~43 ~0 ~42 ~44 ~0 ~42 lava 8
fill ~43 ~0 ~43 ~44 ~0 ~43 lava 8
fill ~43 ~0 ~44 ~44 ~0 ~44 lava 8
fill ~43 ~0 ~45 ~44 ~0 ~45 lava 8
fill ~43 ~0 ~46 ~44 ~0 ~46 lava 8
fill ~43 ~0 ~47 ~44 ~0 ~47 lava 8
fill ~1 ~1 ~51 ~8 ~1 ~51 grass 0
fill ~3 ~1 ~1 ~45 ~1 ~1 obsidian 0
fill ~3 ~1 ~50 ~45 ~1 ~50 obsidian 0
fill ~4 ~1 ~2 ~44 ~1 ~2 lava 8
fill ~4 ~1 ~3 ~44 ~1 ~3 lava 8
fill ~4 ~1 ~48 ~44 ~1 ~48 lava 8
fill ~4 ~1 ~49 ~44 ~1 ~49 lava 8
fill ~5 ~1 ~4 ~42 ~1 ~4 obsidian 0
fill ~5 ~1 ~47 ~42 ~1 ~47 obsidian 0
fill ~6 ~1 ~5 ~41 ~1 ~5 lava 8
fill ~6 ~1 ~46 ~41 ~1 ~46 lava 8
fill ~7 ~1 ~6 ~40 ~1 ~6 obsidian 0
fill ~7 ~1 ~45 ~40 ~1 ~45 obsidian 0
fill ~8 ~1 ~7 ~17 ~1 ~7 glowstone 0
fill ~8 ~1 ~8 ~8 ~7 ~8 glowstone 0
fill ~8 ~1 ~9 ~8 ~7 ~9 glowstone 0
fill ~8 ~1 ~10 ~8 ~6 ~10 glowstone 0
fill ~8 ~1 ~11 ~8 ~6 ~11 glowstone 0
fill ~8 ~1 ~12 ~8 ~6 ~12 glowstone 0
fill ~8 ~1 ~13 ~8 ~7 ~13 glowstone 0
fill ~8 ~1 ~14 ~8 ~7 ~14 glowstone 0
fill ~8 ~1 ~15 ~8 ~6 ~15 glowstone 0
fill ~8 ~1 ~16 ~8 ~6 ~16 glowstone 0
fill ~8 ~1 ~17 ~8 ~6 ~17 glowstone 0
fill ~8 ~1 ~18 ~8 ~6 ~18 glowstone 0
fill ~8 ~1 ~19 ~8 ~6 ~19 glowstone 0
fill ~8 ~1 ~20 ~8 ~6 ~20 glowstone 0
fill ~8 ~1 ~21 ~8 ~6 ~21 glowstone 0
fill ~8 ~1 ~22 ~8 ~6 ~22 glowstone 0
fill ~8 ~1 ~23 ~8 ~6 ~23 glowstone 0
fill ~8 ~1 ~24 ~8 ~6 ~24 glowstone 0
fill ~8 ~1 ~25 ~8 ~6 ~25 glowstone 0
fill ~8 ~1 ~26 ~8 ~6 ~26 glowstone 0
fill ~8 ~1 ~27 ~8 ~6 ~27 glowstone 0
fill ~8 ~1 ~28 ~8 ~6 ~28 glowstone 0
fill ~8 ~1 ~29 ~8 ~6 ~29 glowstone 0
fill ~8 ~1 ~30 ~8 ~6 ~30 glowstone 0
fill ~8 ~1 ~31 ~8 ~6 ~31 glowstone 0
fill ~8 ~1 ~32 ~8 ~6 ~32 glowstone 0
fill ~8 ~1 ~33 ~8 ~6 ~33 glowstone 0
fill ~8 ~1 ~34 ~8 ~6 ~34 glowstone 0
fill ~8 ~1 ~35 ~8 ~6 ~35 glowstone 0
fill ~8 ~1 ~36 ~8 ~6 ~36 glowstone 0
fill ~8 ~1 ~37 ~8 ~6 ~37 glowstone 0
fill ~8 ~1 ~38 ~8 ~6 ~38 glowstone 0
fill ~8 ~1 ~39 ~8 ~6 ~39 glowstone 0
fill ~8 ~1 ~40 ~8 ~6 ~40 glowstone 0
fill ~8 ~1 ~41 ~8 ~6 ~41 glowstone 0
fill ~8 ~1 ~42 ~8 ~6 ~42 glowstone 0
fill ~8 ~1 ~43 ~8 ~6 ~43 glowstone 0
fill ~8 ~1 ~44 ~17 ~1 ~44 glowstone 0
fill ~9 ~1 ~8 ~16 ~1 ~8 anvil 1
fill ~9 ~1 ~9 ~9 ~1 ~19 anvil 0
setblock ~9 ~1 ~20 anvil 2
fill ~9 ~1 ~30 ~9 ~4 ~30 crafting_table 0
fill ~9 ~1 ~31 ~9 ~4 ~31 crafting_table 0
fill ~9 ~1 ~32 ~9 ~4 ~32 crafting_table 0
fill ~9 ~1 ~33 ~9 ~4 ~33 crafting_table 0
fill ~10 ~1 ~20 ~11 ~1 ~20 anvil 1
setblock ~10 ~1 ~51 tallgrass 1
fill ~11 ~1 ~10 ~14 ~1 ~10 anvil 1
fill ~11 ~1 ~11 ~14 ~1 ~11 anvil 1
fill ~11 ~1 ~13 ~14 ~1 ~13 anvil 1
fill ~11 ~1 ~14 ~14 ~1 ~14 anvil 1
fill ~11 ~1 ~16 ~14 ~1 ~16 anvil 1
fill ~11 ~1 ~17 ~14 ~1 ~17 anvil 1
fill ~14 ~1 ~20 ~15 ~1 ~20 anvil 1
fill ~16 ~1 ~9 ~16 ~1 ~20 anvil 2
fill ~16 ~1 ~30 ~16 ~1 ~43 ender_chest 4
fill ~17 ~1 ~8 ~17 ~7 ~8 glowstone 0
fill ~17 ~1 ~9 ~17 ~7 ~9 glowstone 0
fill ~17 ~1 ~10 ~17 ~6 ~10 glowstone 0
fill ~17 ~1 ~11 ~17 ~6 ~11 glowstone 0
fill ~17 ~1 ~12 ~17 ~6 ~12 glowstone 0
fill ~17 ~1 ~13 ~17 ~7 ~13 glowstone 0
fill ~17 ~1 ~14 ~17 ~7 ~14 glowstone 0
fill ~17 ~1 ~15 ~17 ~6 ~15 glowstone 0
fill ~17 ~1 ~16 ~17 ~6 ~16 glowstone 0
fill ~17 ~1 ~17 ~17 ~6 ~17 glowstone 0
fill ~17 ~1 ~18 ~17 ~6 ~18 glowstone 0
fill ~17 ~1 ~19 ~17 ~6 ~19 glowstone 0
fill ~17 ~1 ~20 ~17 ~6 ~20 glowstone 0
fill ~17 ~1 ~30 ~17 ~6 ~30 glowstone 0
fill ~17 ~1 ~31 ~17 ~6 ~31 glowstone 0
fill ~17 ~1 ~32 ~17 ~6 ~32 glowstone 0
fill ~17 ~1 ~33 ~17 ~6 ~33 glowstone 0
fill ~17 ~1 ~34 ~17 ~6 ~34 glowstone 0
fill ~17 ~1 ~35 ~17 ~6 ~35 glowstone 0
fill ~17 ~1 ~36 ~17 ~6 ~36 glowstone 0
fill ~17 ~1 ~37 ~17 ~6 ~37 glowstone 0
fill ~17 ~1 ~38 ~17 ~6 ~38 glowstone 0
fill ~17 ~1 ~39 ~17 ~6 ~39 glowstone 0
fill ~17 ~1 ~40 ~17 ~6 ~40 glowstone 0
fill ~17 ~1 ~41 ~17 ~6 ~41 glowstone 0
fill ~17 ~1 ~42 ~17 ~6 ~42 glowstone 0
fill ~17 ~1 ~43 ~17 ~6 ~43 glowstone 0
fill ~18 ~1 ~7 ~18 ~13 ~7 obsidian 0
fill ~18 ~1 ~8 ~18 ~13 ~8 obsidian 0
fill ~18 ~1 ~9 ~18 ~13 ~9 obsidian 0
fill ~18 ~1 ~10 ~18 ~13 ~10 obsidian 0
fill ~18 ~1 ~11 ~18 ~13 ~11 obsidian 0
fill ~18 ~1 ~12 ~18 ~13 ~12 obsidian 0
fill ~18 ~1 ~13 ~18 ~13 ~13 obsidian 0
fill ~18 ~1 ~14 ~18 ~13 ~14 obsidian 0
fill ~18 ~1 ~15 ~18 ~13 ~15 obsidian 0
fill ~18 ~1 ~16 ~18 ~13 ~16 obsidian 0
fill ~18 ~1 ~17 ~18 ~13 ~17 obsidian 0
fill ~18 ~1 ~18 ~18 ~13 ~18 obsidian 0
fill ~18 ~1 ~19 ~18 ~7 ~19 obsidian 0
fill ~18 ~1 ~20 ~18 ~13 ~20 obsidian 0
fill ~18 ~1 ~21 ~18 ~12 ~21 ladder 3
fill ~18 ~1 ~30 ~18 ~13 ~30 obsidian 0
fill ~18 ~1 ~31 ~18 ~13 ~31 obsidian 0
fill ~18 ~1 ~32 ~18 ~13 ~32 obsidian 0
fill ~18 ~1 ~33 ~18 ~13 ~33 obsidian 0
fill ~18 ~1 ~34 ~18 ~13 ~34 obsidian 0
fill ~18 ~1 ~35 ~18 ~13 ~35 obsidian 0
fill ~18 ~1 ~36 ~18 ~13 ~36 obsidian 0
fill ~18 ~1 ~37 ~18 ~13 ~37 obsidian 0
fill ~18 ~1 ~38 ~18 ~13 ~38 obsidian 0
fill ~18 ~1 ~39 ~18 ~13 ~39 obsidian 0
fill ~18 ~1 ~40 ~18 ~13 ~40 obsidian 0
fill ~18 ~1 ~41 ~18 ~13 ~41 obsidian 0
fill ~18 ~1 ~42 ~18 ~13 ~42 obsidian 0
fill ~18 ~1 ~43 ~18 ~13 ~43 obsidian 0
fill ~18 ~1 ~44 ~18 ~13 ~44 obsidian 0
fill ~19 ~1 ~7 ~28 ~1 ~7 glowstone 0
fill ~19 ~1 ~8 ~19 ~7 ~8 glowstone 0
fill ~19 ~1 ~9 ~19 ~7 ~9 glowstone 0
fill ~19 ~1 ~10 ~19 ~6 ~10 glowstone 0
fill ~19 ~1 ~11 ~19 ~6 ~11 glowstone 0
fill ~19 ~1 ~12 ~19 ~6 ~12 glowstone 0
fill ~19 ~1 ~13 ~19 ~7 ~13 glowstone 0
fill ~19 ~1 ~14 ~19 ~7 ~14 glowstone 0
fill ~19 ~1 ~15 ~19 ~6 ~15 glowstone 0
fill ~19 ~1 ~16 ~19 ~6 ~16 glowstone 0
fill ~19 ~1 ~17 ~19 ~6 ~17 glowstone 0
fill ~19 ~1 ~18 ~19 ~6 ~18 glowstone 0
fill ~19 ~1 ~19 ~19 ~6 ~19 glowstone 0
fill ~19 ~1 ~20 ~19 ~6 ~20 glowstone 0
fill ~19 ~1 ~30 ~19 ~6 ~30 glowstone 0
fill ~19 ~1 ~31 ~19 ~6 ~31 glowstone 0
fill ~19 ~1 ~32 ~19 ~6 ~32 glowstone 0
fill ~19 ~1 ~33 ~19 ~6 ~33 glowstone 0
fill ~19 ~1 ~34 ~19 ~6 ~34 glowstone 0
fill ~19 ~1 ~35 ~19 ~6 ~35 glowstone 0
fill ~19 ~1 ~36 ~19 ~6 ~36 glowstone 0
fill ~19 ~1 ~37 ~19 ~6 ~37 glowstone 0
fill ~19 ~1 ~38 ~19 ~6 ~38 glowstone 0
fill ~19 ~1 ~39 ~19 ~6 ~39 glowstone 0
fill ~19 ~1 ~40 ~19 ~6 ~40 glowstone 0
fill ~19 ~1 ~41 ~19 ~6 ~41 glowstone 0
fill ~19 ~1 ~42 ~19 ~6 ~42 glowstone 0
fill ~19 ~1 ~43 ~19 ~6 ~43 glowstone 0
fill ~19 ~1 ~44 ~28 ~1 ~44 glowstone 0
fill ~20 ~1 ~30 ~27 ~1 ~30 obsidian 0
fill ~20 ~1 ~31 ~27 ~1 ~31 grass 0
fill ~20 ~1 ~32 ~27 ~1 ~32 grass 0
fill ~20 ~1 ~33 ~27 ~1 ~33 grass 0
fill ~20 ~1 ~34 ~27 ~1 ~34 grass 0
fill ~20 ~1 ~35 ~27 ~1 ~35 grass 0
fill ~20 ~1 ~36 ~27 ~1 ~36 grass 0
fill ~20 ~1 ~37 ~27 ~1 ~37 grass 0
fill ~20 ~1 ~38 ~27 ~1 ~38 grass 0
fill ~20 ~1 ~39 ~27 ~1 ~39 grass 0
fill ~20 ~1 ~40 ~27 ~1 ~40 grass 0
fill ~20 ~1 ~41 ~27 ~1 ~41 grass 0
fill ~20 ~1 ~42 ~27 ~1 ~42 grass 0
fill ~20 ~1 ~43 ~27 ~1 ~43 grass 0
fill ~23 ~1 ~29 ~24 ~1 ~29 oak_stairs 2
fill ~28 ~1 ~8 ~28 ~7 ~8 glowstone 0
fill ~28 ~1 ~9 ~28 ~7 ~9 glowstone 0
fill ~28 ~1 ~10 ~28 ~6 ~10 glowstone 0
fill ~28 ~1 ~11 ~28 ~6 ~11 glowstone 0
fill ~28 ~1 ~12 ~28 ~6 ~12 glowstone 0
fill ~28 ~1 ~13 ~28 ~7 ~13 glowstone 0
fill ~28 ~1 ~14 ~28 ~7 ~14 glowstone 0
fill ~28 ~1 ~15 ~28 ~6 ~15 glowstone 0
fill ~28 ~1 ~16 ~28 ~6 ~16 glowstone 0
fill ~28 ~1 ~17 ~28 ~6 ~17 glowstone 0
fill ~28 ~1 ~18 ~28 ~6 ~18 glowstone 0
fill ~28 ~1 ~19 ~28 ~6 ~19 glowstone 0
fill ~28 ~1 ~20 ~28 ~6 ~20 glowstone 0
fill ~28 ~1 ~30 ~28 ~6 ~30 glowstone 0
fill ~28 ~1 ~31 ~28 ~6 ~31 glowstone 0
fill ~28 ~1 ~32 ~28 ~6 ~32 glowstone 0
fill ~28 ~1 ~33 ~28 ~6 ~33 glowstone 0
fill ~28 ~1 ~34 ~28 ~6 ~34 glowstone 0
fill ~28 ~1 ~35 ~28 ~6 ~35 glowstone 0
fill ~28 ~1 ~36 ~28 ~6 ~36 glowstone 0
fill ~28 ~1 ~37 ~28 ~6 ~37 glowstone 0
fill ~28 ~1 ~38 ~28 ~6 ~38 glowstone 0
fill ~28 ~1 ~39 ~28 ~6 ~39 glowstone 0
fill ~28 ~1 ~40 ~28 ~6 ~40 glowstone 0
fill ~28 ~1 ~41 ~28 ~6 ~41 glowstone 0
fill ~28 ~1 ~42 ~28 ~6 ~42 glowstone 0
fill ~28 ~1 ~43 ~28 ~6 ~43 glowstone 0
setblock ~28 ~1 ~51 tallgrass 1
fill ~29 ~1 ~7 ~29 ~13 ~7 obsidian 0
fill ~29 ~1 ~8 ~29 ~13 ~8 obsidian 0
fill ~29 ~1 ~9 ~29 ~13 ~9 obsidian 0
fill ~29 ~1 ~10 ~29 ~13 ~10 obsidian 0
fill ~29 ~1 ~11 ~29 ~13 ~11 obsidian 0
fill ~29 ~1 ~12 ~29 ~13 ~12 obsidian 0
fill ~29 ~1 ~13 ~29 ~13 ~13 obsidian 0
fill ~29 ~1 ~14 ~29 ~13 ~14 obsidian 0
fill ~29 ~1 ~15 ~29 ~13 ~15 obsidian 0
fill ~29 ~1 ~16 ~29 ~13 ~16 obsidian 0
fill ~29 ~1 ~17 ~29 ~13 ~17 obsidian 0
fill ~29 ~1 ~18 ~29 ~13 ~18 obsidian 0
fill ~29 ~1 ~19 ~29 ~7 ~19 obsidian 0
fill ~29 ~1 ~20 ~29 ~13 ~20 obsidian 0
fill ~29 ~1 ~21 ~29 ~12 ~21 ladder 3
fill ~29 ~1 ~30 ~29 ~13 ~30 obsidian 0
fill ~29 ~1 ~31 ~29 ~13 ~31 obsidian 0
fill ~29 ~1 ~32 ~29 ~13 ~32 obsidian 0
fill ~29 ~1 ~33 ~29 ~13 ~33 obsidian 0
fill ~29 ~1 ~34 ~29 ~13 ~34 obsidian 0
fill ~29 ~1 ~35 ~29 ~13 ~35 obsidian 0
fill ~29 ~1 ~36 ~29 ~13 ~36 obsidian 0
fill ~29 ~1 ~37 ~29 ~13 ~37 obsidian 0
fill ~29 ~1 ~38 ~29 ~13 ~38 obsidian 0
fill ~29 ~1 ~39 ~29 ~13 ~39 obsidian 0
fill ~29 ~1 ~40 ~29 ~13 ~40 obsidian 0
fill ~29 ~1 ~41 ~29 ~13 ~41 obsidian 0
fill ~29 ~1 ~42 ~29 ~13 ~42 obsidian 0
fill ~29 ~1 ~43 ~29 ~13 ~43 obsidian 0
fill ~29 ~1 ~44 ~29 ~13 ~44 obsidian 0
fill ~30 ~1 ~7 ~39 ~1 ~7 glowstone 0
fill ~30 ~1 ~8 ~30 ~7 ~8 glowstone 0
fill ~30 ~1 ~9 ~30 ~7 ~9 glowstone 0
fill ~30 ~1 ~10 ~30 ~6 ~10 glowstone 0
fill ~30 ~1 ~11 ~30 ~6 ~11 glowstone 0
fill ~30 ~1 ~12 ~30 ~6 ~12 glowstone 0
fill ~30 ~1 ~13 ~30 ~6 ~13 glowstone 0
fill ~30 ~1 ~14 ~30 ~6 ~14 glowstone 0
fill ~30 ~1 ~15 ~30 ~6 ~15 glowstone 0
fill ~30 ~1 ~16 ~30 ~6 ~16 glowstone 0
fill ~30 ~1 ~17 ~30 ~6 ~17 glowstone 0
fill ~30 ~1 ~18 ~30 ~6 ~18 glowstone 0
fill ~30 ~1 ~19 ~30 ~6 ~19 glowstone 0
fill ~30 ~1 ~20 ~30 ~6 ~20 glowstone 0
fill ~30 ~1 ~30 ~30 ~6 ~30 glowstone 0
fill ~30 ~1 ~31 ~30 ~6 ~31 glowstone 0
fill ~30 ~1 ~32 ~30 ~6 ~32 glowstone 0
fill ~30 ~1 ~33 ~30 ~6 ~33 glowstone 0
fill ~30 ~1 ~34 ~30 ~6 ~34 glowstone 0
fill ~30 ~1 ~35 ~30 ~6 ~35 glowstone 0
fill ~30 ~1 ~36 ~30 ~6 ~36 glowstone 0
fill ~30 ~1 ~37 ~30 ~6 ~37 glowstone 0
fill ~30 ~1 ~38 ~30 ~6 ~38 glowstone 0
fill ~30 ~1 ~39 ~30 ~6 ~39 glowstone 0
fill ~30 ~1 ~40 ~30 ~6 ~40 glowstone 0
fill ~30 ~1 ~41 ~30 ~6 ~41 glowstone 0
fill ~30 ~1 ~42 ~30 ~6 ~42 glowstone 0
fill ~30 ~1 ~43 ~30 ~6 ~43 glowstone 0
fill ~30 ~1 ~44 ~39 ~1 ~44 glowstone 0
fill ~31 ~1 ~8 ~38 ~1 ~8 bookshelf 0
fill ~31 ~1 ~9 ~38 ~1 ~9 bookshelf 0
fill ~31 ~1 ~10 ~38 ~1 ~10 bookshelf 0
fill ~31 ~1 ~11 ~38 ~1 ~11 bookshelf 0
fill ~31 ~1 ~12 ~38 ~1 ~12 bookshelf 0
fill ~31 ~1 ~30 ~38 ~1 ~30 obsidian 0
fill ~31 ~1 ~31 ~38 ~1 ~31 grass 0
fill ~31 ~1 ~32 ~38 ~1 ~32 grass 0
fill ~31 ~1 ~33 ~38 ~1 ~33 grass 0
fill ~31 ~1 ~34 ~38 ~1 ~34 grass 0
fill ~31 ~1 ~35 ~38 ~1 ~35 grass 0
fill ~31 ~1 ~36 ~38 ~1 ~36 grass 0
fill ~31 ~1 ~37 ~38 ~1 ~37 grass 0
fill ~31 ~1 ~38 ~38 ~1 ~38 grass 0
fill ~31 ~1 ~39 ~38 ~1 ~39 grass 0
fill ~31 ~1 ~40 ~38 ~1 ~40 grass 0
fill ~31 ~1 ~41 ~38 ~1 ~41 grass 0
fill ~31 ~1 ~42 ~38 ~1 ~42 grass 0
fill ~31 ~1 ~43 ~38 ~1 ~43 grass 0
setblock ~31 ~1 ~51 grass 0
fill ~34 ~1 ~29 ~35 ~1 ~29 oak_stairs 2
fill ~39 ~1 ~8 ~39 ~7 ~8 glowstone 0
fill ~39 ~1 ~9 ~39 ~7 ~9 glowstone 0
fill ~39 ~1 ~10 ~39 ~6 ~10 glowstone 0
fill ~39 ~1 ~11 ~39 ~6 ~11 glowstone 0
fill ~39 ~1 ~12 ~39 ~6 ~12 glowstone 0
fill ~39 ~1 ~13 ~39 ~6 ~13 glowstone 0
fill ~39 ~1 ~14 ~39 ~6 ~14 glowstone 0
fill ~39 ~1 ~15 ~39 ~6 ~15 glowstone 0
fill ~39 ~1 ~16 ~39 ~6 ~16 glowstone 0
fill ~39 ~1 ~17 ~39 ~6 ~17 glowstone 0
fill ~39 ~1 ~18 ~39 ~6 ~18 glowstone 0
fill ~39 ~1 ~19 ~39 ~6 ~19 glowstone 0
fill ~39 ~1 ~20 ~39 ~6 ~20 glowstone 0
fill ~39 ~1 ~21 ~39 ~6 ~21 glowstone 0
fill ~39 ~1 ~22 ~39 ~6 ~22 glowstone 0
fill ~39 ~1 ~23 ~39 ~6 ~23 glowstone 0
fill ~39 ~1 ~24 ~39 ~6 ~24 glowstone 0
fill ~39 ~1 ~25 ~39 ~6 ~25 glowstone 0
fill ~39 ~1 ~26 ~39 ~6 ~26 glowstone 0
fill ~39 ~1 ~27 ~39 ~6 ~27 glowstone 0
fill ~39 ~1 ~28 ~39 ~6 ~28 glowstone 0
fill ~39 ~1 ~29 ~39 ~6 ~29 glowstone 0
fill ~39 ~1 ~30 ~39 ~6 ~30 glowstone 0
fill ~39 ~1 ~31 ~39 ~6 ~31 glowstone 0
fill ~39 ~1 ~32 ~39 ~6 ~32 glowstone 0
fill ~39 ~1 ~33 ~39 ~6 ~33 glowstone 0
fill ~39 ~1 ~34 ~39 ~6 ~34 glowstone 0
fill ~39 ~1 ~35 ~39 ~6 ~35 glowstone 0
fill ~39 ~1 ~36 ~39 ~6 ~36 glowstone 0
fill ~39 ~1 ~37 ~39 ~6 ~37 glowstone 0
fill ~39 ~1 ~38 ~39 ~6 ~38 glowstone 0
fill ~39 ~1 ~39 ~39 ~6 ~39 glowstone 0
fill ~39 ~1 ~40 ~39 ~6 ~40 glowstone 0
fill ~39 ~1 ~41 ~39 ~6 ~41 glowstone 0
fill ~39 ~1 ~42 ~39 ~6 ~42 glowstone 0
fill ~39 ~1 ~43 ~39 ~6 ~43 glowstone 0
fill ~43 ~1 ~4 ~44 ~1 ~4 lava 8
fill ~43 ~1 ~5 ~44 ~1 ~5 lava 8
fill ~43 ~1 ~6 ~44 ~1 ~6 lava 8
fill ~43 ~1 ~7 ~44 ~1 ~7 lava 8
fill ~43 ~1 ~8 ~44 ~1 ~8 lava 8
fill ~43 ~1 ~9 ~44 ~1 ~9 lava 8
fill ~43 ~1 ~10 ~44 ~1 ~10 lava 8
fill ~43 ~1 ~11 ~44 ~1 ~11 lava 8
fill ~43 ~1 ~12 ~44 ~1 ~12 lava 8
fill ~43 ~1 ~13 ~44 ~1 ~13 lava 8
fill ~43 ~1 ~14 ~44 ~1 ~14 lava 8
fill ~43 ~1 ~15 ~44 ~1 ~15 lava 8
fill ~43 ~1 ~16 ~44 ~1 ~16 lava 8
fill ~43 ~1 ~17 ~44 ~1 ~17 lava 8
fill ~43 ~1 ~18 ~44 ~1 ~18 lava 8
fill ~43 ~1 ~19 ~44 ~1 ~19 lava 8
fill ~43 ~1 ~20 ~44 ~1 ~20 lava 8
fill ~43 ~1 ~21 ~44 ~1 ~21 lava 8
fill ~43 ~1 ~22 ~44 ~1 ~22 lava 8
fill ~43 ~1 ~23 ~44 ~1 ~23 lava 8
fill ~43 ~1 ~24 ~44 ~1 ~24 lava 8
fill ~43 ~1 ~25 ~44 ~1 ~25 lava 8
fill ~43 ~1 ~26 ~44 ~1 ~26 lava 8
fill ~43 ~1 ~27 ~44 ~1 ~27 lava 8
fill ~43 ~1 ~28 ~44 ~1 ~28 lava 8
fill ~43 ~1 ~29 ~44 ~1 ~29 lava 8
fill ~43 ~1 ~30 ~44 ~1 ~30 lava 8
fill ~43 ~1 ~31 ~44 ~1 ~31 lava 8
fill ~43 ~1 ~32 ~44 ~1 ~32 lava 8
fill ~43 ~1 ~33 ~44 ~1 ~33 lava 8
fill ~43 ~1 ~34 ~44 ~1 ~34 lava 8
fill ~43 ~1 ~35 ~44 ~1 ~35 lava 8
fill ~43 ~1 ~36 ~44 ~1 ~36 lava 8
fill ~43 ~1 ~37 ~44 ~1 ~37 lava 8
fill ~43 ~1 ~38 ~44 ~1 ~38 lava 8
fill ~43 ~1 ~39 ~44 ~1 ~39 lava 8
fill ~43 ~1 ~40 ~44 ~1 ~40 lava 8
fill ~43 ~1 ~41 ~44 ~1 ~41 lava 8
fill ~43 ~1 ~42 ~44 ~1 ~42 lava 8
fill ~43 ~1 ~43 ~44 ~1 ~43 lava 8
fill ~43 ~1 ~44 ~44 ~1 ~44 lava 8
fill ~43 ~1 ~45 ~44 ~1 ~45 lava 8
fill ~43 ~1 ~46 ~44 ~1 ~46 lava 8
fill ~43 ~1 ~47 ~44 ~1 ~47 lava 8
fill ~3 ~2 ~1 ~45 ~2 ~1 obsidian 0
fill ~3 ~2 ~50 ~45 ~2 ~50 obsidian 0
fill ~4 ~2 ~2 ~44 ~2 ~2 lava 0
fill ~4 ~2 ~3 ~44 ~2 ~3 lava 0
fill ~4 ~2 ~4 ~4 ~2 ~49 lava 0
setblock ~4 ~2 ~51 tallgrass 1
fill ~5 ~2 ~4 ~42 ~2 ~4 obsidian 0
fill ~5 ~2 ~47 ~42 ~2 ~47 obsidian 0
fill ~5 ~2 ~48 ~44 ~2 ~48 lava 0
fill ~5 ~2 ~49 ~44 ~2 ~49 lava 0
fill ~6 ~2 ~5 ~41 ~2 ~5 lava 0
fill ~6 ~2 ~6 ~6 ~2 ~46 lava 0
fill ~7 ~2 ~6 ~40 ~2 ~6 obsidian 0
fill ~7 ~2 ~45 ~40 ~2 ~45 obsidian 0
fill ~7 ~2 ~46 ~41 ~2 ~46 lava 0
fill ~8 ~2 ~7 ~17 ~2 ~7 glowstone 0
fill ~8 ~2 ~44 ~17 ~2 ~44 glowstone 0
fill ~19 ~2 ~7 ~28 ~2 ~7 glowstone 0
fill ~19 ~2 ~44 ~28 ~2 ~44 glowstone 0
fill ~20 ~2 ~30 ~22 ~2 ~30 fence 0
fill ~23 ~2 ~30 ~24 ~2 ~30 fence_gate 0
fill ~25 ~2 ~30 ~27 ~2 ~30 fence 0
fill ~30 ~2 ~7 ~39 ~2 ~7 glowstone 0
fill ~30 ~2 ~44 ~39 ~2 ~44 glowstone 0
fill ~31 ~2 ~8 ~38 ~2 ~8 bookshelf 0
fill ~31 ~2 ~9 ~33 ~2 ~9 bookshelf 0
fill ~31 ~2 ~10 ~33 ~2 ~10 bookshelf 0
fill ~31 ~2 ~11 ~33 ~2 ~11 bookshelf 0
fill ~31 ~2 ~12 ~34 ~2 ~12 bookshelf 0
fill ~31 ~2 ~30 ~33 ~2 ~30 fence 0
fill ~34 ~2 ~30 ~35 ~2 ~30 fence_gate 0
setblock ~35 ~2 ~10 enchanting_table 0
fill ~36 ~2 ~12 ~38 ~2 ~12 bookshelf 0
fill ~36 ~2 ~30 ~38 ~2 ~30 fence 0
fill ~37 ~2 ~9 ~38 ~2 ~9 bookshelf 0
fill ~37 ~2 ~10 ~38 ~2 ~10 bookshelf 0
fill ~37 ~2 ~11 ~38 ~2 ~11 bookshelf 0
fill ~41 ~2 ~6 ~41 ~2 ~46 lava 0
fill ~43 ~2 ~4 ~44 ~2 ~4 lava 0
fill ~43 ~2 ~5 ~44 ~2 ~5 lava 0
fill ~43 ~2 ~6 ~44 ~2 ~6 lava 0
fill ~43 ~2 ~7 ~44 ~2 ~7 lava 0
fill ~43 ~2 ~8 ~44 ~2 ~8 lava 0
fill ~43 ~2 ~9 ~44 ~2 ~9 lava 0
fill ~43 ~2 ~10 ~44 ~2 ~10 lava 0
fill ~43 ~2 ~11 ~44 ~2 ~11 lava 0
fill ~43 ~2 ~12 ~44 ~2 ~12 lava 0
fill ~43 ~2 ~13 ~44 ~2 ~13 lava 0
fill ~43 ~2 ~14 ~44 ~2 ~14 lava 0
fill ~43 ~2 ~15 ~44 ~2 ~15 lava 0
fill ~43 ~2 ~16 ~44 ~2 ~16 lava 0
fill ~43 ~2 ~17 ~44 ~2 ~17 lava 0
fill ~43 ~2 ~18 ~44 ~2 ~18 lava 0
fill ~43 ~2 ~19 ~44 ~2 ~19 lava 0
fill ~43 ~2 ~20 ~44 ~2 ~20 lava 0
fill ~43 ~2 ~21 ~44 ~2 ~21 lava 0
fill ~43 ~2 ~22 ~44 ~2 ~22 lava 0
fill ~43 ~2 ~23 ~44 ~2 ~23 lava 0
fill ~43 ~2 ~24 ~44 ~2 ~24 lava 0
fill ~43 ~2 ~25 ~44 ~2 ~25 lava 0
fill ~43 ~2 ~26 ~44 ~2 ~26 lava 0
fill ~43 ~2 ~27 ~44 ~2 ~27 lava 0
fill ~43 ~2 ~28 ~44 ~2 ~28 lava 0
fill ~43 ~2 ~29 ~44 ~2 ~29 lava 0
fill ~43 ~2 ~30 ~44 ~2 ~30 lava 0
fill ~43 ~2 ~31 ~44 ~2 ~31 lava 0
fill ~43 ~2 ~32 ~44 ~2 ~32 lava 0
fill ~43 ~2 ~33 ~44 ~2 ~33 lava 0
fill ~43 ~2 ~34 ~44 ~2 ~34 lava 0
fill ~43 ~2 ~35 ~44 ~2 ~35 lava 0
fill ~43 ~2 ~36 ~44 ~2 ~36 lava 0
fill ~43 ~2 ~37 ~44 ~2 ~37 lava 0
fill ~43 ~2 ~38 ~44 ~2 ~38 lava 0
fill ~43 ~2 ~39 ~44 ~2 ~39 lava 0
fill ~43 ~2 ~40 ~44 ~2 ~40 lava 0
fill ~43 ~2 ~41 ~44 ~2 ~41 lava 0
fill ~43 ~2 ~42 ~44 ~2 ~42 lava 0
fill ~43 ~2 ~43 ~44 ~2 ~43 lava 0
fill ~43 ~2 ~44 ~44 ~2 ~44 lava 0
fill ~43 ~2 ~45 ~44 ~2 ~45 lava 0
fill ~43 ~2 ~46 ~44 ~2 ~46 lava 0
fill ~43 ~2 ~47 ~44 ~2 ~47 lava 0
fill ~3 ~3 ~1 ~45 ~3 ~1 obsidian 0
fill ~3 ~3 ~50 ~45 ~3 ~50 obsidian 0
fill ~4 ~3 ~2 ~45 ~3 ~2 obsidian 0
fill ~4 ~3 ~3 ~45 ~3 ~3 obsidian 0
fill ~4 ~3 ~4 ~45 ~3 ~4 obsidian 0
fill ~4 ~3 ~5 ~4 ~3 ~50 obsidian 0
fill ~5 ~3 ~47 ~45 ~3 ~47 obsidian 0
fill ~5 ~3 ~48 ~45 ~3 ~48 obsidian 0
fill ~5 ~3 ~49 ~45 ~3 ~49 obsidian 0
fill ~6 ~3 ~5 ~45 ~3 ~5 obsidian 0
fill ~6 ~3 ~6 ~45 ~3 ~6 obsidian 0
fill ~6 ~3 ~7 ~6 ~3 ~50 obsidian 0
fill ~7 ~3 ~45 ~45 ~3 ~45 obsidian 0
fill ~7 ~3 ~46 ~45 ~3 ~46 obsidian 0
fill ~8 ~3 ~7 ~17 ~3 ~7 glowstone 0
fill ~8 ~3 ~44 ~17 ~3 ~44 glowstone 0
fill ~19 ~3 ~7 ~28 ~3 ~7 glowstone 0
fill ~19 ~3 ~44 ~28 ~3 ~44 glowstone 0
fill ~30 ~3 ~7 ~39 ~3 ~7 glowstone 0
fill ~30 ~3 ~44 ~39 ~3 ~44 glowstone 0
fill ~31 ~3 ~8 ~38 ~3 ~8 bookshelf 0
fill ~31 ~3 ~9 ~33 ~3 ~9 bookshelf 0
fill ~31 ~3 ~10 ~33 ~3 ~10 bookshelf 0
fill ~31 ~3 ~11 ~33 ~3 ~11 bookshelf 0
fill ~31 ~3 ~12 ~34 ~3 ~12 bookshelf 0
fill ~36 ~3 ~12 ~38 ~3 ~12 bookshelf 0
fill ~37 ~3 ~9 ~38 ~3 ~9 bookshelf 0
fill ~37 ~3 ~10 ~38 ~3 ~10 bookshelf 0
fill ~37 ~3 ~11 ~38 ~3 ~11 bookshelf 0
fill ~41 ~3 ~7 ~41 ~3 ~50 obsidian 0
fill ~43 ~3 ~7 ~45 ~3 ~7 obsidian 0
fill ~43 ~3 ~8 ~45 ~3 ~8 obsidian 0
fill ~43 ~3 ~9 ~45 ~3 ~9 obsidian 0
fill ~43 ~3 ~10 ~45 ~3 ~10 obsidian 0
fill ~43 ~3 ~11 ~45 ~3 ~11 obsidian 0
fill ~43 ~3 ~12 ~45 ~3 ~12 obsidian 0
fill ~43 ~3 ~13 ~45 ~3 ~13 obsidian 0
fill ~43 ~3 ~14 ~45 ~3 ~14 obsidian 0
fill ~43 ~3 ~15 ~45 ~3 ~15 obsidian 0
fill ~43 ~3 ~16 ~45 ~3 ~16 obsidian 0
fill ~43 ~3 ~17 ~45 ~3 ~17 obsidian 0
fill ~43 ~3 ~18 ~45 ~3 ~18 obsidian 0
fill ~43 ~3 ~19 ~45 ~3 ~19 obsidian 0
fill ~43 ~3 ~20 ~45 ~3 ~20 obsidian 0
fill ~43 ~3 ~21 ~45 ~3 ~21 obsidian 0
fill ~43 ~3 ~22 ~45 ~3 ~22 obsidian 0
fill ~43 ~3 ~23 ~45 ~3 ~23 obsidian 0
fill ~43 ~3 ~24 ~45 ~3 ~24 obsidian 0
fill ~43 ~3 ~25 ~45 ~3 ~25 obsidian 0
fill ~43 ~3 ~26 ~45 ~3 ~26 obsidian 0
fill ~43 ~3 ~27 ~45 ~3 ~27 obsidian 0
fill ~43 ~3 ~28 ~45 ~3 ~28 obsidian 0
fill ~43 ~3 ~29 ~45 ~3 ~29 obsidian 0
fill ~43 ~3 ~30 ~45 ~3 ~30 obsidian 0
fill ~43 ~3 ~31 ~45 ~3 ~31 obsidian 0
fill ~43 ~3 ~32 ~45 ~3 ~32 obsidian 0
fill ~43 ~3 ~33 ~45 ~3 ~33 obsidian 0
fill ~43 ~3 ~34 ~45 ~3 ~34 obsidian 0
fill ~43 ~3 ~35 ~45 ~3 ~35 obsidian 0
fill ~43 ~3 ~36 ~45 ~3 ~36 obsidian 0
fill ~43 ~3 ~37 ~45 ~3 ~37 obsidian 0
fill ~43 ~3 ~38 ~45 ~3 ~38 obsidian 0
fill ~43 ~3 ~39 ~45 ~3 ~39 obsidian 0
fill ~43 ~3 ~40 ~45 ~3 ~40 obsidian 0
fill ~43 ~3 ~41 ~45 ~3 ~41 obsidian 0
fill ~43 ~3 ~42 ~45 ~3 ~42 obsidian 0
fill ~43 ~3 ~43 ~45 ~3 ~43 obsidian 0
fill ~43 ~3 ~44 ~45 ~3 ~44 obsidian 0
fill ~3 ~4 ~1 ~45 ~4 ~1 obsidian 0
fill ~3 ~4 ~50 ~45 ~4 ~50 obsidian 0
fill ~4 ~4 ~2 ~44 ~4 ~2 lava 8
fill ~4 ~4 ~3 ~44 ~4 ~3 lava 8
fill ~4 ~4 ~4 ~44 ~4 ~4 lava 8
fill ~4 ~4 ~5 ~44 ~4 ~5 lava 8
fill ~4 ~4 ~6 ~6 ~4 ~6 lava 8
fill ~4 ~4 ~7 ~6 ~4 ~7 lava 8
fill ~4 ~4 ~8 ~6 ~4 ~8 lava 8
fill ~4 ~4 ~9 ~6 ~4 ~9 lava 8
fill ~4 ~4 ~10 ~6 ~4 ~10 lava 8
fill ~4 ~4 ~11 ~6 ~4 ~11 lava 8
fill ~4 ~4 ~12 ~6 ~4 ~12 lava 8
fill ~4 ~4 ~13 ~6 ~4 ~13 lava 8
fill ~4 ~4 ~14 ~6 ~4 ~14 lava 8
fill ~4 ~4 ~15 ~6 ~4 ~15 lava 8
fill ~4 ~4 ~16 ~6 ~4 ~16 lava 8
fill ~4 ~4 ~17 ~6 ~4 ~17 lava 8
fill ~4 ~4 ~18 ~6 ~4 ~18 lava 8
fill ~4 ~4 ~19 ~6 ~4 ~19 lava 8
fill ~4 ~4 ~20 ~6 ~4 ~20 lava 8
fill ~4 ~4 ~21 ~6 ~4 ~21 lava 8
fill ~4 ~4 ~22 ~6 ~4 ~22 lava 8
fill ~4 ~4 ~23 ~6 ~4 ~23 lava 8
fill ~4 ~4 ~24 ~6 ~4 ~24 lava 8
fill ~4 ~4 ~25 ~6 ~4 ~25 lava 8
fill ~4 ~4 ~26 ~6 ~4 ~26 lava 8
fill ~4 ~4 ~27 ~6 ~4 ~27 lava 8
fill ~4 ~4 ~28 ~6 ~4 ~28 lava 8
fill ~4 ~4 ~29 ~6 ~4 ~29 lava 8
fill ~4 ~4 ~30 ~6 ~4 ~30 lava 8
fill ~4 ~4 ~31 ~6 ~4 ~31 lava 8
fill ~4 ~4 ~32 ~6 ~4 ~32 lava 8
fill ~4 ~4 ~33 ~6 ~4 ~33 lava 8
fill ~4 ~4 ~34 ~6 ~4 ~34 lava 8
fill ~4 ~4 ~35 ~6 ~4 ~35 lava 8
fill ~4 ~4 ~36 ~6 ~4 ~36 lava 8
fill ~4 ~4 ~37 ~6 ~4 ~37 lava 8
fill ~4 ~4 ~38 ~6 ~4 ~38 lava 8
fill ~4 ~4 ~39 ~6 ~4 ~39 lava 8
fill ~4 ~4 ~40 ~6 ~4 ~40 lava 8
fill ~4 ~4 ~41 ~6 ~4 ~41 lava 8
fill ~4 ~4 ~42 ~6 ~4 ~42 lava 8
fill ~4 ~4 ~43 ~6 ~4 ~43 lava 8
fill ~4 ~4 ~44 ~6 ~4 ~44 lava 8
fill ~4 ~4 ~45 ~6 ~4 ~45 lava 8
fill ~4 ~4 ~46 ~44 ~4 ~46 lava 8
fill ~4 ~4 ~47 ~44 ~4 ~47 lava 8
fill ~4 ~4 ~48 ~44 ~4 ~48 lava 8
fill ~4 ~4 ~49 ~44 ~4 ~49 lava 8
fill ~7 ~4 ~6 ~40 ~4 ~6 obsidian 0
fill ~7 ~4 ~45 ~40 ~4 ~45 obsidian 0
fill ~8 ~4 ~7 ~17 ~4 ~7 glowstone 0
fill ~8 ~4 ~44 ~17 ~4 ~44 glowstone 0
fill ~19 ~4 ~7 ~28 ~4 ~7 glowstone 0
fill ~19 ~4 ~44 ~28 ~4 ~44 glowstone 0
fill ~30 ~4 ~7 ~39 ~4 ~7 glowstone 0
fill ~30 ~4 ~44 ~39 ~4 ~44 glowstone 0
fill ~31 ~4 ~8 ~38 ~4 ~8 bookshelf 0
fill ~31 ~4 ~9 ~33 ~4 ~9 bookshelf 0
fill ~31 ~4 ~10 ~33 ~4 ~10 bookshelf 0
fill ~31 ~4 ~11 ~33 ~4 ~11 bookshelf 0
fill ~31 ~4 ~12 ~38 ~4 ~12 bookshelf 0
fill ~37 ~4 ~9 ~38 ~4 ~9 bookshelf 0
fill ~37 ~4 ~10 ~38 ~4 ~10 bookshelf 0
fill ~37 ~4 ~11 ~38 ~4 ~11 bookshelf 0
fill ~41 ~4 ~6 ~44 ~4 ~6 lava 8
fill ~41 ~4 ~7 ~44 ~4 ~7 lava 8
fill ~41 ~4 ~8 ~44 ~4 ~8 lava 8
fill ~41 ~4 ~9 ~44 ~4 ~9 lava 8
fill ~41 ~4 ~10 ~44 ~4 ~10 lava 8
fill ~41 ~4 ~11 ~44 ~4 ~11 lava 8
fill ~41 ~4 ~12 ~44 ~4 ~12 lava 8
fill ~41 ~4 ~13 ~44 ~4 ~13 lava 8
fill ~41 ~4 ~14 ~44 ~4 ~14 lava 8
fill ~41 ~4 ~15 ~44 ~4 ~15 lava 8
fill ~41 ~4 ~16 ~44 ~4 ~16 lava 8
fill ~41 ~4 ~17 ~44 ~4 ~17 lava 8
fill ~41 ~4 ~18 ~44 ~4 ~18 lava 8
fill ~41 ~4 ~19 ~44 ~4 ~19 lava 8
fill ~41 ~4 ~20 ~44 ~4 ~20 lava 8
fill ~41 ~4 ~21 ~44 ~4 ~21 lava 8
fill ~41 ~4 ~22 ~44 ~4 ~22 lava 8
fill ~41 ~4 ~23 ~44 ~4 ~23 lava 8
fill ~41 ~4 ~24 ~44 ~4 ~24 lava 8
fill ~41 ~4 ~25 ~44 ~4 ~25 lava 8
fill ~41 ~4 ~26 ~44 ~4 ~26 lava 8
fill ~41 ~4 ~27 ~44 ~4 ~27 lava 8
fill ~41 ~4 ~28 ~44 ~4 ~28 lava 8
fill ~41 ~4 ~29 ~44 ~4 ~29 lava 8
fill ~41 ~4 ~30 ~44 ~4 ~30 lava 8
fill ~41 ~4 ~31 ~44 ~4 ~31 lava 8
fill ~41 ~4 ~32 ~44 ~4 ~32 lava 8
fill ~41 ~4 ~33 ~44 ~4 ~33 lava 8
fill ~41 ~4 ~34 ~44 ~4 ~34 lava 8
fill ~41 ~4 ~35 ~44 ~4 ~35 lava 8
fill ~41 ~4 ~36 ~44 ~4 ~36 lava 8
fill ~41 ~4 ~37 ~44 ~4 ~37 lava 8
fill ~41 ~4 ~38 ~44 ~4 ~38 lava 8
fill ~41 ~4 ~39 ~44 ~4 ~39 lava 8
fill ~41 ~4 ~40 ~44 ~4 ~40 lava 8
fill ~41 ~4 ~41 ~44 ~4 ~41 lava 8
fill ~41 ~4 ~42 ~44 ~4 ~42 lava 8
fill ~41 ~4 ~43 ~44 ~4 ~43 lava 8
fill ~41 ~4 ~44 ~44 ~4 ~44 lava 8
fill ~41 ~4 ~45 ~44 ~4 ~45 lava 8
fill ~3 ~5 ~1 ~45 ~5 ~1 obsidian 0
fill ~3 ~5 ~50 ~45 ~5 ~50 obsidian 0
fill ~4 ~5 ~2 ~44 ~5 ~2 lava 8
fill ~4 ~5 ~3 ~44 ~5 ~3 lava 8
fill ~4 ~5 ~4 ~44 ~5 ~4 lava 8
fill ~4 ~5 ~5 ~44 ~5 ~5 lava 8
fill ~4 ~5 ~6 ~6 ~5 ~6 lava 8
fill ~4 ~5 ~7 ~6 ~5 ~7 lava 8
fill ~4 ~5 ~8 ~6 ~5 ~8 lava 8
fill ~4 ~5 ~9 ~6 ~5 ~9 lava 8
fill ~4 ~5 ~10 ~6 ~5 ~10 lava 8
fill ~4 ~5 ~11 ~6 ~5 ~11 lava 8
fill ~4 ~5 ~12 ~6 ~5 ~12 lava 8
fill ~4 ~5 ~13 ~6 ~5 ~13 lava 8
fill ~4 ~5 ~14 ~6 ~5 ~14 lava 8
fill ~4 ~5 ~15 ~6 ~5 ~15 lava 8
fill ~4 ~5 ~16 ~6 ~5 ~16 lava 8
fill ~4 ~5 ~17 ~6 ~5 ~17 lava 8
fill ~4 ~5 ~18 ~6 ~5 ~18 lava 8
fill ~4 ~5 ~19 ~6 ~5 ~19 lava 8
fill ~4 ~5 ~20 ~6 ~5 ~20 lava 8
fill ~4 ~5 ~21 ~6 ~5 ~21 lava 8
fill ~4 ~5 ~22 ~6 ~5 ~22 lava 8
fill ~4 ~5 ~23 ~6 ~5 ~23 lava 8
fill ~4 ~5 ~24 ~6 ~5 ~24 lava 8
fill ~4 ~5 ~25 ~6 ~5 ~25 lava 8
fill ~4 ~5 ~26 ~6 ~5 ~26 lava 8
fill ~4 ~5 ~27 ~6 ~5 ~27 lava 8
fill ~4 ~5 ~28 ~6 ~5 ~28 lava 8
fill ~4 ~5 ~29 ~6 ~5 ~29 lava 8
fill ~4 ~5 ~30 ~6 ~5 ~30 lava 8
fill ~4 ~5 ~31 ~6 ~5 ~31 lava 8
fill ~4 ~5 ~32 ~6 ~5 ~32 lava 8
fill ~4 ~5 ~33 ~6 ~5 ~33 lava 8
fill ~4 ~5 ~34 ~6 ~5 ~34 lava 8
fill ~4 ~5 ~35 ~6 ~5 ~35 lava 8
fill ~4 ~5 ~36 ~6 ~5 ~36 lava 8
fill ~4 ~5 ~37 ~6 ~5 ~37 lava 8
fill ~4 ~5 ~38 ~6 ~5 ~38 lava 8
fill ~4 ~5 ~39 ~6 ~5 ~39 lava 8
fill ~4 ~5 ~40 ~6 ~5 ~40 lava 8
fill ~4 ~5 ~41 ~6 ~5 ~41 lava 8
fill ~4 ~5 ~42 ~6 ~5 ~42 lava 8
fill ~4 ~5 ~43 ~6 ~5 ~43 lava 8
fill ~4 ~5 ~44 ~6 ~5 ~44 lava 8
fill ~4 ~5 ~45 ~6 ~5 ~45 lava 8
fill ~4 ~5 ~46 ~44 ~5 ~46 lava 8
fill ~4 ~5 ~47 ~44 ~5 ~47 lava 8
fill ~4 ~5 ~48 ~44 ~5 ~48 lava 8
fill ~4 ~5 ~49 ~44 ~5 ~49 lava 8
fill ~7 ~5 ~6 ~40 ~5 ~6 obsidian 0
fill ~7 ~5 ~45 ~40 ~5 ~45 obsidian 0
fill ~8 ~5 ~7 ~17 ~5 ~7 glowstone 0
fill ~8 ~5 ~44 ~17 ~5 ~44 glowstone 0
fill ~19 ~5 ~7 ~28 ~5 ~7 glowstone 0
fill ~19 ~5 ~44 ~28 ~5 ~44 glowstone 0
fill ~30 ~5 ~7 ~39 ~5 ~7 glowstone 0
fill ~30 ~5 ~44 ~39 ~5 ~44 glowstone 0
fill ~31 ~5 ~8 ~38 ~5 ~8 bookshelf 0
fill ~31 ~5 ~9 ~38 ~5 ~9 bookshelf 0
fill ~31 ~5 ~10 ~38 ~5 ~10 bookshelf 0
fill ~31 ~5 ~11 ~38 ~5 ~11 bookshelf 0
fill ~31 ~5 ~12 ~38 ~5 ~12 bookshelf 0
fill ~41 ~5 ~6 ~44 ~5 ~6 lava 8
fill ~41 ~5 ~7 ~44 ~5 ~7 lava 8
fill ~41 ~5 ~8 ~44 ~5 ~8 lava 8
fill ~41 ~5 ~9 ~44 ~5 ~9 lava 8
fill ~41 ~5 ~10 ~44 ~5 ~10 lava 8
fill ~41 ~5 ~11 ~44 ~5 ~11 lava 8
fill ~41 ~5 ~12 ~44 ~5 ~12 lava 8
fill ~41 ~5 ~13 ~44 ~5 ~13 lava 8
fill ~41 ~5 ~14 ~44 ~5 ~14 lava 8
fill ~41 ~5 ~15 ~44 ~5 ~15 lava 8
fill ~41 ~5 ~16 ~44 ~5 ~16 lava 8
fill ~41 ~5 ~17 ~44 ~5 ~17 lava 8
fill ~41 ~5 ~18 ~44 ~5 ~18 lava 8
fill ~41 ~5 ~19 ~44 ~5 ~19 lava 8
fill ~41 ~5 ~20 ~44 ~5 ~20 lava 8
fill ~41 ~5 ~21 ~44 ~5 ~21 lava 8
fill ~41 ~5 ~22 ~44 ~5 ~22 lava 8
fill ~41 ~5 ~23 ~44 ~5 ~23 lava 8
fill ~41 ~5 ~24 ~44 ~5 ~24 lava 8
fill ~41 ~5 ~25 ~44 ~5 ~25 lava 8
fill ~41 ~5 ~26 ~44 ~5 ~26 lava 8
fill ~41 ~5 ~27 ~44 ~5 ~27 lava 8
fill ~41 ~5 ~28 ~44 ~5 ~28 lava 8
fill ~41 ~5 ~29 ~44 ~5 ~29 lava 8
fill ~41 ~5 ~30 ~44 ~5 ~30 lava 8
fill ~41 ~5 ~31 ~44 ~5 ~31 lava 8
fill ~41 ~5 ~32 ~44 ~5 ~32 lava 8
fill ~41 ~5 ~33 ~44 ~5 ~33 lava 8
fill ~41 ~5 ~34 ~44 ~5 ~34 lava 8
fill ~41 ~5 ~35 ~44 ~5 ~35 lava 8
fill ~41 ~5 ~36 ~44 ~5 ~36 lava 8
fill ~41 ~5 ~37 ~44 ~5 ~37 lava 8
fill ~41 ~5 ~38 ~44 ~5 ~38 lava 8
fill ~41 ~5 ~39 ~44 ~5 ~39 lava 8
fill ~41 ~5 ~40 ~44 ~5 ~40 lava 8
fill ~41 ~5 ~41 ~44 ~5 ~41 lava 8
fill ~41 ~5 ~42 ~44 ~5 ~42 lava 8
fill ~41 ~5 ~43 ~44 ~5 ~43 lava 8
fill ~41 ~5 ~44 ~44 ~5 ~44 lava 8
fill ~41 ~5 ~45 ~44 ~5 ~45 lava 8
fill ~3 ~6 ~1 ~45 ~6 ~1 obsidian 0
fill ~3 ~6 ~50 ~45 ~6 ~50 obsidian 0
fill ~4 ~6 ~2 ~44 ~6 ~2 lava 8
fill ~4 ~6 ~3 ~44 ~6 ~3 lava 8
fill ~4 ~6 ~4 ~44 ~6 ~4 lava 8
fill ~4 ~6 ~5 ~44 ~6 ~5 lava 8
fill ~4 ~6 ~6 ~6 ~6 ~6 lava 8
fill ~4 ~6 ~7 ~6 ~6 ~7 lava 8
fill ~4 ~6 ~8 ~6 ~6 ~8 lava 8
fill ~4 ~6 ~9 ~6 ~6 ~9 lava 8
fill ~4 ~6 ~10 ~6 ~6 ~10 lava 8
fill ~4 ~6 ~11 ~6 ~6 ~11 lava 8
fill ~4 ~6 ~12 ~6 ~6 ~12 lava 8
fill ~4 ~6 ~13 ~6 ~6 ~13 lava 8
fill ~4 ~6 ~14 ~6 ~6 ~14 lava 8
fill ~4 ~6 ~15 ~6 ~6 ~15 lava 8
fill ~4 ~6 ~16 ~6 ~6 ~16 lava 8
fill ~4 ~6 ~17 ~6 ~6 ~17 lava 8
fill ~4 ~6 ~18 ~6 ~6 ~18 lava 8
fill ~4 ~6 ~19 ~6 ~6 ~19 lava 8
fill ~4 ~6 ~20 ~6 ~6 ~20 lava 8
fill ~4 ~6 ~21 ~6 ~6 ~21 lava 8
fill ~4 ~6 ~22 ~6 ~6 ~22 lava 8
fill ~4 ~6 ~23 ~6 ~6 ~23 lava 8
fill ~4 ~6 ~24 ~6 ~6 ~24 lava 8
fill ~4 ~6 ~25 ~6 ~6 ~25 lava 8
fill ~4 ~6 ~26 ~6 ~6 ~26 lava 8
fill ~4 ~6 ~27 ~6 ~6 ~27 lava 8
fill ~4 ~6 ~28 ~6 ~6 ~28 lava 8
fill ~4 ~6 ~29 ~6 ~6 ~29 lava 8
fill ~4 ~6 ~30 ~6 ~6 ~30 lava 8
fill ~4 ~6 ~31 ~6 ~6 ~31 lava 8
fill ~4 ~6 ~32 ~6 ~6 ~32 lava 8
fill ~4 ~6 ~33 ~6 ~6 ~33 lava 8
fill ~4 ~6 ~34 ~6 ~6 ~34 lava 8
fill ~4 ~6 ~35 ~6 ~6 ~35 lava 8
fill ~4 ~6 ~36 ~6 ~6 ~36 lava 8
fill ~4 ~6 ~37 ~6 ~6 ~37 lava 8
fill ~4 ~6 ~38 ~6 ~6 ~38 lava 8
fill ~4 ~6 ~39 ~6 ~6 ~39 lava 8
fill ~4 ~6 ~40 ~6 ~6 ~40 lava 8
fill ~4 ~6 ~41 ~6 ~6 ~41 lava 8
fill ~4 ~6 ~42 ~6 ~6 ~42 lava 8
fill ~4 ~6 ~43 ~6 ~6 ~43 lava 8
fill ~4 ~6 ~44 ~6 ~6 ~44 lava 8
fill ~4 ~6 ~45 ~6 ~6 ~45 lava 8
fill ~4 ~6 ~46 ~44 ~6 ~46 lava 8
fill ~4 ~6 ~47 ~44 ~6 ~47 lava 8
fill ~4 ~6 ~48 ~44 ~6 ~48 lava 8
fill ~4 ~6 ~49 ~44 ~6 ~49 lava 8
fill ~7 ~6 ~6 ~40 ~6 ~6 obsidian 0
fill ~7 ~6 ~45 ~40 ~6 ~45 obsidian 0
fill ~8 ~6 ~7 ~17 ~6 ~7 glowstone 0
fill ~8 ~6 ~44 ~17 ~6 ~44 glowstone 0
fill ~19 ~6 ~7 ~28 ~6 ~7 glowstone 0
fill ~19 ~6 ~44 ~28 ~6 ~44 glowstone 0
fill ~30 ~6 ~7 ~39 ~6 ~7 glowstone 0
fill ~30 ~6 ~44 ~39 ~6 ~44 glowstone 0
fill ~41 ~6 ~6 ~44 ~6 ~6 lava 8
fill ~41 ~6 ~7 ~44 ~6 ~7 lava 8
fill ~41 ~6 ~8 ~44 ~6 ~8 lava 8
fill ~41 ~6 ~9 ~44 ~6 ~9 lava 8
fill ~41 ~6 ~10 ~44 ~6 ~10 lava 8
fill ~41 ~6 ~11 ~44 ~6 ~11 lava 8
fill ~41 ~6 ~12 ~44 ~6 ~12 lava 8
fill ~41 ~6 ~13 ~44 ~6 ~13 lava 8
fill ~41 ~6 ~14 ~44 ~6 ~14 lava 8
fill ~41 ~6 ~15 ~44 ~6 ~15 lava 8
fill ~41 ~6 ~16 ~44 ~6 ~16 lava 8
fill ~41 ~6 ~17 ~44 ~6 ~17 lava 8
fill ~41 ~6 ~18 ~44 ~6 ~18 lava 8
fill ~41 ~6 ~19 ~44 ~6 ~19 lava 8
fill ~41 ~6 ~20 ~44 ~6 ~20 lava 8
fill ~41 ~6 ~21 ~44 ~6 ~21 lava 8
fill ~41 ~6 ~22 ~44 ~6 ~22 lava 8
fill ~41 ~6 ~23 ~44 ~6 ~23 lava 8
fill ~41 ~6 ~24 ~44 ~6 ~24 lava 8
fill ~41 ~6 ~25 ~44 ~6 ~25 lava 8
fill ~41 ~6 ~26 ~44 ~6 ~26 lava 8
fill ~41 ~6 ~27 ~44 ~6 ~27 lava 8
fill ~41 ~6 ~28 ~44 ~6 ~28 lava 8
fill ~41 ~6 ~29 ~44 ~6 ~29 lava 8
fill ~41 ~6 ~30 ~44 ~6 ~30 lava 8
fill ~41 ~6 ~31 ~44 ~6 ~31 lava 8
fill ~41 ~6 ~32 ~44 ~6 ~32 lava 8
fill ~41 ~6 ~33 ~44 ~6 ~33 lava 8
fill ~41 ~6 ~34 ~44 ~6 ~34 lava 8
fill ~41 ~6 ~35 ~44 ~6 ~35 lava 8
fill ~41 ~6 ~36 ~44 ~6 ~36 lava 8
fill ~41 ~6 ~37 ~44 ~6 ~37 lava 8
fill ~41 ~6 ~38 ~44 ~6 ~38 lava 8
fill ~41 ~6 ~39 ~44 ~6 ~39 lava 8
fill ~41 ~6 ~40 ~44 ~6 ~40 lava 8
fill ~41 ~6 ~41 ~44 ~6 ~41 lava 8
fill ~41 ~6 ~42 ~44 ~6 ~42 lava 8
fill ~41 ~6 ~43 ~44 ~6 ~43 lava 8
fill ~41 ~6 ~44 ~44 ~6 ~44 lava 8
fill ~41 ~6 ~45 ~44 ~6 ~45 lava 8
fill ~3 ~7 ~1 ~45 ~7 ~1 obsidian 0
fill ~3 ~7 ~50 ~45 ~7 ~50 obsidian 0
fill ~4 ~7 ~2 ~44 ~7 ~2 lava 8
fill ~4 ~7 ~3 ~44 ~7 ~3 lava 8
fill ~4 ~7 ~4 ~44 ~7 ~4 lava 8
fill ~4 ~7 ~5 ~44 ~7 ~5 lava 8
fill ~4 ~7 ~6 ~6 ~7 ~6 lava 8
fill ~4 ~7 ~7 ~6 ~7 ~7 lava 8
fill ~4 ~7 ~8 ~6 ~7 ~8 lava 8
fill ~4 ~7 ~9 ~6 ~7 ~9 lava 8
fill ~4 ~7 ~10 ~6 ~7 ~10 lava 8
fill ~4 ~7 ~11 ~6 ~7 ~11 lava 8
fill ~4 ~7 ~12 ~6 ~7 ~12 lava 8
fill ~4 ~7 ~13 ~6 ~7 ~13 lava 8
fill ~4 ~7 ~14 ~6 ~7 ~14 lava 8
fill ~4 ~7 ~15 ~6 ~7 ~15 lava 8
fill ~4 ~7 ~16 ~6 ~7 ~16 lava 8
fill ~4 ~7 ~17 ~6 ~7 ~17 lava 8
fill ~4 ~7 ~18 ~6 ~7 ~18 lava 8
fill ~4 ~7 ~19 ~6 ~7 ~19 lava 8
fill ~4 ~7 ~20 ~6 ~7 ~20 lava 8
fill ~4 ~7 ~21 ~6 ~7 ~21 lava 8
fill ~4 ~7 ~22 ~6 ~7 ~22 lava 8
fill ~4 ~7 ~23 ~6 ~7 ~23 lava 8
fill ~4 ~7 ~24 ~6 ~7 ~24 lava 8
fill ~4 ~7 ~25 ~6 ~7 ~25 lava 8
fill ~4 ~7 ~26 ~6 ~7 ~26 lava 8
fill ~4 ~7 ~27 ~6 ~7 ~27 lava 8
fill ~4 ~7 ~28 ~6 ~7 ~28 lava 8
fill ~4 ~7 ~29 ~6 ~7 ~29 lava 8
fill ~4 ~7 ~30 ~6 ~7 ~30 lava 8
fill ~4 ~7 ~31 ~6 ~7 ~31 lava 8
fill ~4 ~7 ~32 ~6 ~7 ~32 lava 8
fill ~4 ~7 ~33 ~6 ~7 ~33 lava 8
fill ~4 ~7 ~34 ~6 ~7 ~34 lava 8
fill ~4 ~7 ~35 ~6 ~7 ~35 lava 8
fill ~4 ~7 ~36 ~6 ~7 ~36 lava 8
fill ~4 ~7 ~37 ~6 ~7 ~37 lava 8
fill ~4 ~7 ~38 ~6 ~7 ~38 lava 8
fill ~4 ~7 ~39 ~6 ~7 ~39 lava 8
fill ~4 ~7 ~40 ~6 ~7 ~40 lava 8
fill ~4 ~7 ~41 ~6 ~7 ~41 lava 8
fill ~4 ~7 ~42 ~6 ~7 ~42 lava 8
fill ~4 ~7 ~43 ~6 ~7 ~43 lava 8
fill ~4 ~7 ~44 ~6 ~7 ~44 lava 8
fill ~4 ~7 ~45 ~6 ~7 ~45 lava 8
fill ~4 ~7 ~46 ~44 ~7 ~46 lava 8
fill ~4 ~7 ~47 ~44 ~7 ~47 lava 8
fill ~4 ~7 ~48 ~44 ~7 ~48 lava 8
fill ~4 ~7 ~49 ~44 ~7 ~49 lava 8
fill ~7 ~7 ~6 ~40 ~7 ~6 obsidian 0
fill ~7 ~7 ~45 ~40 ~7 ~45 obsidian 0
fill ~8 ~7 ~7 ~9 ~7 ~7 obsidian 0
fill ~8 ~7 ~10 ~9 ~7 ~10 obsidian 0
fill ~8 ~7 ~11 ~40 ~7 ~11 obsidian 0
fill ~8 ~7 ~12 ~9 ~7 ~12 obsidian 0
fill ~8 ~7 ~15 ~9 ~7 ~15 obsidian 0
fill ~8 ~7 ~16 ~40 ~7 ~16 obsidian 0
fill ~8 ~7 ~17 ~9 ~7 ~17 obsidian 0
fill ~8 ~7 ~18 ~40 ~7 ~18 obsidian 0
fill ~8 ~7 ~19 ~40 ~7 ~19 obsidian 0
fill ~8 ~7 ~20 ~40 ~7 ~20 obsidian 0
fill ~8 ~7 ~21 ~17 ~7 ~21 obsidian 0
fill ~8 ~7 ~22 ~40 ~7 ~22 obsidian 0
fill ~8 ~7 ~23 ~40 ~7 ~23 obsidian 0
fill ~8 ~7 ~24 ~40 ~7 ~24 obsidian 0
fill ~8 ~7 ~25 ~40 ~7 ~25 obsidian 0
fill ~8 ~7 ~26 ~40 ~7 ~26 obsidian 0
fill ~8 ~7 ~27 ~40 ~7 ~27 obsidian 0
fill ~8 ~7 ~28 ~40 ~7 ~28 obsidian 0
fill ~8 ~7 ~29 ~40 ~7 ~29 obsidian 0
fill ~8 ~7 ~30 ~40 ~7 ~30 obsidian 0
fill ~8 ~7 ~31 ~40 ~7 ~31 obsidian 0
fill ~8 ~7 ~32 ~40 ~7 ~32 obsidian 0
fill ~8 ~7 ~33 ~40 ~7 ~33 obsidian 0
fill ~8 ~7 ~34 ~40 ~7 ~34 obsidian 0
fill ~8 ~7 ~35 ~40 ~7 ~35 obsidian 0
fill ~8 ~7 ~36 ~40 ~7 ~36 obsidian 0
fill ~8 ~7 ~37 ~40 ~7 ~37 obsidian 0
fill ~8 ~7 ~38 ~40 ~7 ~38 obsidian 0
fill ~8 ~7 ~39 ~40 ~7 ~39 obsidian 0
fill ~8 ~7 ~40 ~40 ~7 ~40 obsidian 0
fill ~8 ~7 ~41 ~40 ~7 ~41 obsidian 0
fill ~8 ~7 ~42 ~40 ~7 ~42 obsidian 0
fill ~8 ~7 ~43 ~40 ~7 ~43 obsidian 0
fill ~8 ~7 ~44 ~40 ~7 ~44 obsidian 0
fill ~9 ~7 ~8 ~16 ~7 ~8 obsidian 0
fill ~9 ~7 ~9 ~16 ~7 ~9 obsidian 0
fill ~9 ~7 ~13 ~16 ~7 ~13 obsidian 0
fill ~9 ~7 ~14 ~16 ~7 ~14 obsidian 0
fill ~10 ~7 ~7 ~11 ~7 ~7 glowstone 0
fill ~10 ~7 ~10 ~11 ~7 ~10 glowstone 0
fill ~10 ~7 ~12 ~11 ~7 ~12 glowstone 0
fill ~10 ~7 ~15 ~11 ~7 ~15 glowstone 0
fill ~10 ~7 ~17 ~11 ~7 ~17 glowstone 0
fill ~12 ~7 ~7 ~13 ~7 ~7 obsidian 0
fill ~12 ~7 ~10 ~13 ~7 ~10 obsidian 0
fill ~12 ~7 ~12 ~13 ~7 ~12 obsidian 0
fill ~12 ~7 ~15 ~13 ~7 ~15 obsidian 0
fill ~12 ~7 ~17 ~13 ~7 ~17 obsidian 0
fill ~14 ~7 ~7 ~15 ~7 ~7 glowstone 0
fill ~14 ~7 ~10 ~15 ~7 ~10 glowstone 0
fill ~14 ~7 ~12 ~15 ~7 ~12 glowstone 0
fill ~14 ~7 ~15 ~15 ~7 ~15 glowstone 0
fill ~14 ~7 ~17 ~15 ~7 ~17 glowstone 0
fill ~16 ~7 ~7 ~20 ~7 ~7 obsidian 0
fill ~16 ~7 ~10 ~20 ~7 ~10 obsidian 0
fill ~16 ~7 ~12 ~20 ~7 ~12 obsidian 0
fill ~16 ~7 ~15 ~20 ~7 ~15 obsidian 0
fill ~16 ~7 ~17 ~20 ~7 ~17 obsidian 0
fill ~19 ~7 ~21 ~28 ~7 ~21 obsidian 0
fill ~20 ~7 ~8 ~22 ~7 ~8 obsidian 0
fill ~20 ~7 ~9 ~22 ~7 ~9 obsidian 0
fill ~20 ~7 ~13 ~27 ~7 ~13 obsidian 0
fill ~20 ~7 ~14 ~27 ~7 ~14 obsidian 0
fill ~21 ~7 ~7 ~22 ~7 ~7 glowstone 0
fill ~21 ~7 ~10 ~22 ~7 ~10 glowstone 0
fill ~21 ~7 ~12 ~22 ~7 ~12 glowstone 0
fill ~21 ~7 ~15 ~22 ~7 ~15 glowstone 0
fill ~21 ~7 ~17 ~22 ~7 ~17 glowstone 0
fill ~23 ~7 ~7 ~24 ~7 ~7 obsidian 0
fill ~23 ~7 ~8 ~24 ~7 ~8 glowstone 0
fill ~23 ~7 ~9 ~24 ~7 ~9 glowstone 0
fill ~23 ~7 ~10 ~24 ~7 ~10 obsidian 0
fill ~23 ~7 ~12 ~24 ~7 ~12 obsidian 0
fill ~23 ~7 ~15 ~24 ~7 ~15 obsidian 0
fill ~23 ~7 ~17 ~24 ~7 ~17 obsidian 0
fill ~25 ~7 ~7 ~26 ~7 ~7 glowstone 0
fill ~25 ~7 ~8 ~27 ~7 ~8 obsidian 0
fill ~25 ~7 ~9 ~27 ~7 ~9 obsidian 0
fill ~25 ~7 ~10 ~26 ~7 ~10 glowstone 0
fill ~25 ~7 ~12 ~26 ~7 ~12 glowstone 0
fill ~25 ~7 ~15 ~26 ~7 ~15 glowstone 0
fill ~25 ~7 ~17 ~26 ~7 ~17 glowstone 0
fill ~27 ~7 ~7 ~31 ~7 ~7 obsidian 0
fill ~27 ~7 ~10 ~31 ~7 ~10 obsidian 0
fill ~27 ~7 ~12 ~31 ~7 ~12 obsidian 0
fill ~27 ~7 ~15 ~40 ~7 ~15 obsidian 0
fill ~27 ~7 ~17 ~40 ~7 ~17 obsidian 0
fill ~30 ~7 ~13 ~40 ~7 ~13 obsidian 0
fill ~30 ~7 ~14 ~40 ~7 ~14 obsidian 0
fill ~30 ~7 ~21 ~40 ~7 ~21 obsidian 0
fill ~31 ~7 ~8 ~38 ~7 ~8 obsidian 0
fill ~31 ~7 ~9 ~38 ~7 ~9 obsidian 0
fill ~32 ~7 ~7 ~33 ~7 ~7 glowstone 0
fill ~32 ~7 ~10 ~33 ~7 ~10 glowstone 0
fill ~32 ~7 ~12 ~33 ~7 ~12 glowstone 0
fill ~34 ~7 ~7 ~35 ~7 ~7 obsidian 0
fill ~34 ~7 ~10 ~35 ~7 ~10 obsidian 0
fill ~34 ~7 ~12 ~35 ~7 ~12 obsidian 0
fill ~36 ~7 ~7 ~37 ~7 ~7 glowstone 0
fill ~36 ~7 ~10 ~37 ~7 ~10 glowstone 0
fill ~36 ~7 ~12 ~37 ~7 ~12 glowstone 0
fill ~38 ~7 ~7 ~40 ~7 ~7 obsidian 0
fill ~38 ~7 ~10 ~40 ~7 ~10 obsidian 0
fill ~38 ~7 ~12 ~40 ~7 ~12 obsidian 0
fill ~41 ~7 ~6 ~44 ~7 ~6 lava 8
fill ~41 ~7 ~7 ~44 ~7 ~7 lava 8
fill ~41 ~7 ~8 ~44 ~7 ~8 lava 8
fill ~41 ~7 ~9 ~44 ~7 ~9 lava 8
fill ~41 ~7 ~10 ~44 ~7 ~10 lava 8
fill ~41 ~7 ~11 ~44 ~7 ~11 lava 8
fill ~41 ~7 ~12 ~44 ~7 ~12 lava 8
fill ~41 ~7 ~13 ~44 ~7 ~13 lava 8
fill ~41 ~7 ~14 ~44 ~7 ~14 lava 8
fill ~41 ~7 ~15 ~44 ~7 ~15 lava 8
fill ~41 ~7 ~16 ~44 ~7 ~16 lava 8
fill ~41 ~7 ~17 ~44 ~7 ~17 lava 8
fill ~41 ~7 ~18 ~44 ~7 ~18 lava 8
fill ~41 ~7 ~19 ~44 ~7 ~19 lava 8
fill ~41 ~7 ~20 ~44 ~7 ~20 lava 8
fill ~41 ~7 ~21 ~44 ~7 ~21 lava 8
fill ~41 ~7 ~22 ~44 ~7 ~22 lava 8
fill ~41 ~7 ~23 ~44 ~7 ~23 lava 8
fill ~41 ~7 ~24 ~44 ~7 ~24 lava 8
fill ~41 ~7 ~25 ~44 ~7 ~25 lava 8
fill ~41 ~7 ~26 ~44 ~7 ~26 lava 8
fill ~41 ~7 ~27 ~44 ~7 ~27 lava 8
fill ~41 ~7 ~28 ~44 ~7 ~28 lava 8
fill ~41 ~7 ~29 ~44 ~7 ~29 lava 8
fill ~41 ~7 ~30 ~44 ~7 ~30 lava 8
fill ~41 ~7 ~31 ~44 ~7 ~31 lava 8
fill ~41 ~7 ~32 ~44 ~7 ~32 lava 8
fill ~41 ~7 ~33 ~44 ~7 ~33 lava 8
fill ~41 ~7 ~34 ~44 ~7 ~34 lava 8
fill ~41 ~7 ~35 ~44 ~7 ~35 lava 8
fill ~41 ~7 ~36 ~44 ~7 ~36 lava 8
fill ~41 ~7 ~37 ~44 ~7 ~37 lava 8
fill ~41 ~7 ~38 ~44 ~7 ~38 lava 8
fill ~41 ~7 ~39 ~44 ~7 ~39 lava 8
fill ~41 ~7 ~40 ~44 ~7 ~40 lava 8
fill ~41 ~7 ~41 ~44 ~7 ~41 lava 8
fill ~41 ~7 ~42 ~44 ~7 ~42 lava 8
fill ~41 ~7 ~43 ~44 ~7 ~43 lava 8
fill ~41 ~7 ~44 ~44 ~7 ~44 lava 8
fill ~41 ~7 ~45 ~44 ~7 ~45 lava 8
fill ~3 ~8 ~1 ~45 ~8 ~1 obsidian 0
fill ~3 ~8 ~50 ~45 ~8 ~50 obsidian 0
fill ~4 ~8 ~2 ~44 ~8 ~2 lava 8
fill ~4 ~8 ~3 ~44 ~8 ~3 lava 8
fill ~4 ~8 ~4 ~44 ~8 ~4 lava 8
fill ~4 ~8 ~5 ~44 ~8 ~5 lava 8
fill ~4 ~8 ~6 ~6 ~8 ~6 lava 8
fill ~4 ~8 ~7 ~6 ~8 ~7 lava 8
fill ~4 ~8 ~8 ~6 ~8 ~8 lava 8
fill ~4 ~8 ~9 ~6 ~8 ~9 lava 8
fill ~4 ~8 ~10 ~6 ~8 ~10 lava 8
fill ~4 ~8 ~11 ~6 ~8 ~11 lava 8
fill ~4 ~8 ~12 ~6 ~8 ~12 lava 8
fill ~4 ~8 ~13 ~6 ~8 ~13 lava 8
fill ~4 ~8 ~14 ~6 ~8 ~14 lava 8
fill ~4 ~8 ~15 ~6 ~8 ~15 lava 8
fill ~4 ~8 ~16 ~6 ~8 ~16 lava 8
fill ~4 ~8 ~17 ~6 ~8 ~17 lava 8
fill ~4 ~8 ~18 ~6 ~8 ~18 lava 8
fill ~4 ~8 ~19 ~6 ~8 ~19 lava 8
fill ~4 ~8 ~20 ~6 ~8 ~20 lava 8
fill ~4 ~8 ~21 ~6 ~8 ~21 lava 8
fill ~4 ~8 ~22 ~6 ~8 ~22 lava 8
fill ~4 ~8 ~23 ~6 ~8 ~23 lava 8
fill ~4 ~8 ~24 ~6 ~8 ~24 lava 8
fill ~4 ~8 ~25 ~6 ~8 ~25 lava 8
fill ~4 ~8 ~26 ~6 ~8 ~26 lava 8
fill ~4 ~8 ~27 ~6 ~8 ~27 lava 8
fill ~4 ~8 ~28 ~6 ~8 ~28 lava 8
fill ~4 ~8 ~29 ~6 ~8 ~29 lava 8
fill ~4 ~8 ~30 ~6 ~8 ~30 lava 8
fill ~4 ~8 ~31 ~6 ~8 ~31 lava 8
fill ~4 ~8 ~32 ~6 ~8 ~32 lava 8
fill ~4 ~8 ~33 ~6 ~8 ~33 lava 8
fill ~4 ~8 ~34 ~6 ~8 ~34 lava 8
fill ~4 ~8 ~35 ~6 ~8 ~35 lava 8
fill ~4 ~8 ~36 ~6 ~8 ~36 lava 8
fill ~4 ~8 ~37 ~6 ~8 ~37 lava 8
fill ~4 ~8 ~38 ~6 ~8 ~38 lava 8
fill ~4 ~8 ~39 ~6 ~8 ~39 lava 8
fill ~4 ~8 ~40 ~6 ~8 ~40 lava 8
fill ~4 ~8 ~41 ~6 ~8 ~41 lava 8
fill ~4 ~8 ~42 ~6 ~8 ~42 lava 8
fill ~4 ~8 ~43 ~6 ~8 ~43 lava 8
fill ~4 ~8 ~44 ~6 ~8 ~44 lava 8
fill ~4 ~8 ~45 ~6 ~8 ~45 lava 8
fill ~4 ~8 ~46 ~44 ~8 ~46 lava 8
fill ~4 ~8 ~47 ~44 ~8 ~47 lava 8
fill ~4 ~8 ~48 ~44 ~8 ~48 lava 8
fill ~4 ~8 ~49 ~44 ~8 ~49 lava 8
fill ~7 ~8 ~6 ~40 ~8 ~6 obsidian 0
fill ~7 ~8 ~45 ~40 ~8 ~45 obsidian 0
fill ~8 ~8 ~11 ~9 ~8 ~11 obsidian 0
fill ~8 ~8 ~16 ~9 ~8 ~16 obsidian 0
fill ~8 ~8 ~22 ~11 ~8 ~22 obsidian 0
fill ~8 ~8 ~23 ~11 ~8 ~23 glowstone 0
fill ~8 ~8 ~24 ~8 ~12 ~24 glowstone 0
fill ~8 ~8 ~25 ~8 ~12 ~25 glowstone 0
fill ~8 ~8 ~26 ~8 ~12 ~26 glowstone 0
fill ~8 ~8 ~27 ~8 ~12 ~27 glowstone 0
fill ~8 ~8 ~28 ~8 ~12 ~28 glowstone 0
fill ~8 ~8 ~29 ~8 ~12 ~29 glowstone 0
fill ~8 ~8 ~30 ~8 ~12 ~30 glowstone 0
fill ~8 ~8 ~31 ~8 ~12 ~31 glowstone 0
fill ~8 ~8 ~32 ~8 ~12 ~32 glowstone 0
fill ~8 ~8 ~33 ~8 ~12 ~33 glowstone 0
fill ~8 ~8 ~34 ~8 ~12 ~34 glowstone 0
fill ~8 ~8 ~35 ~8 ~12 ~35 glowstone 0
fill ~8 ~8 ~36 ~8 ~12 ~36 glowstone 0
fill ~8 ~8 ~37 ~8 ~12 ~37 glowstone 0
fill ~8 ~8 ~38 ~8 ~12 ~38 glowstone 0
fill ~8 ~8 ~39 ~8 ~12 ~39 glowstone 0
fill ~8 ~8 ~40 ~8 ~12 ~40 glowstone 0
fill ~8 ~8 ~41 ~8 ~12 ~41 glowstone 0
fill ~8 ~8 ~42 ~8 ~12 ~42 glowstone 0
fill ~8 ~8 ~43 ~8 ~12 ~43 glowstone 0
fill ~8 ~8 ~44 ~17 ~8 ~44 glowstone 0
fill ~12 ~8 ~11 ~13 ~8 ~11 obsidian 0
fill ~12 ~8 ~16 ~13 ~8 ~16 obsidian 0
fill ~15 ~8 ~22 ~22 ~8 ~22 obsidian 0
fill ~15 ~8 ~23 ~17 ~8 ~23 glowstone 0
fill ~16 ~8 ~11 ~20 ~8 ~11 obsidian 0
fill ~16 ~8 ~16 ~20 ~8 ~16 obsidian 0
fill ~17 ~8 ~24 ~17 ~12 ~24 glowstone 0
fill ~17 ~8 ~25 ~17 ~12 ~25 glowstone 0
fill ~17 ~8 ~26 ~17 ~12 ~26 glowstone 0
fill ~17 ~8 ~27 ~17 ~12 ~27 glowstone 0
fill ~17 ~8 ~28 ~17 ~12 ~28 glowstone 0
fill ~17 ~8 ~29 ~17 ~12 ~29 glowstone 0
fill ~17 ~8 ~30 ~17 ~12 ~30 glowstone 0
fill ~17 ~8 ~31 ~17 ~12 ~31 glowstone 0
fill ~17 ~8 ~32 ~17 ~12 ~32 glowstone 0
fill ~17 ~8 ~33 ~17 ~12 ~33 glowstone 0
fill ~17 ~8 ~34 ~17 ~12 ~34 glowstone 0
fill ~17 ~8 ~35 ~17 ~12 ~35 glowstone 0
fill ~17 ~8 ~36 ~17 ~12 ~36 glowstone 0
fill ~17 ~8 ~37 ~17 ~12 ~37 glowstone 0
fill ~17 ~8 ~38 ~17 ~12 ~38 glowstone 0
fill ~17 ~8 ~39 ~17 ~12 ~39 glowstone 0
fill ~17 ~8 ~40 ~17 ~12 ~40 glowstone 0
fill ~17 ~8 ~41 ~17 ~12 ~41 glowstone 0
fill ~17 ~8 ~42 ~17 ~12 ~42 glowstone 0
fill ~17 ~8 ~43 ~17 ~12 ~43 glowstone 0
fill ~18 ~8 ~19 ~18 ~11 ~19 glowstone 0
fill ~18 ~8 ~23 ~18 ~13 ~23 obsidian 0
fill ~18 ~8 ~24 ~18 ~13 ~24 obsidian 0
fill ~18 ~8 ~25 ~18 ~13 ~25 obsidian 0
fill ~18 ~8 ~26 ~18 ~13 ~26 obsidian 0
fill ~18 ~8 ~27 ~18 ~13 ~27 obsidian 0
fill ~18 ~8 ~28 ~18 ~13 ~28 obsidian 0
fill ~18 ~8 ~29 ~18 ~13 ~29 obsidian 0
fill ~19 ~8 ~23 ~22 ~8 ~23 glowstone 0
fill ~19 ~8 ~24 ~19 ~12 ~24 glowstone 0
fill ~19 ~8 ~25 ~19 ~12 ~25 glowstone 0
fill ~19 ~8 ~26 ~19 ~12 ~26 glowstone 0
fill ~19 ~8 ~27 ~19 ~12 ~27 glowstone 0
fill ~19 ~8 ~28 ~19 ~12 ~28 glowstone 0
fill ~19 ~8 ~29 ~19 ~12 ~29 glowstone 0
fill ~19 ~8 ~30 ~19 ~12 ~30 glowstone 0
fill ~19 ~8 ~31 ~19 ~12 ~31 glowstone 0
fill ~19 ~8 ~32 ~19 ~12 ~32 glowstone 0
fill ~19 ~8 ~33 ~19 ~12 ~33 glowstone 0
fill ~19 ~8 ~34 ~19 ~12 ~34 glowstone 0
fill ~19 ~8 ~35 ~19 ~12 ~35 glowstone 0
fill ~19 ~8 ~36 ~19 ~12 ~36 glowstone 0
fill ~19 ~8 ~37 ~19 ~12 ~37 glowstone 0
fill ~19 ~8 ~38 ~19 ~12 ~38 glowstone 0
fill ~19 ~8 ~39 ~19 ~12 ~39 glowstone 0
fill ~19 ~8 ~40 ~19 ~12 ~40 glowstone 0
fill ~19 ~8 ~41 ~19 ~12 ~41 glowstone 0
fill ~19 ~8 ~42 ~19 ~12 ~42 glowstone 0
fill ~19 ~8 ~43 ~19 ~12 ~43 glowstone 0
fill ~19 ~8 ~44 ~28 ~8 ~44 glowstone 0
fill ~23 ~8 ~11 ~24 ~8 ~11 obsidian 0
fill ~23 ~8 ~16 ~24 ~8 ~16 obsidian 0
fill ~26 ~8 ~22 ~32 ~8 ~22 obsidian 0
fill ~26 ~8 ~23 ~28 ~8 ~23 glowstone 0
fill ~27 ~8 ~11 ~31 ~8 ~11 obsidian 0
fill ~27 ~8 ~16 ~29 ~8 ~16 obsidian 0
fill ~28 ~8 ~24 ~28 ~12 ~24 glowstone 0
fill ~28 ~8 ~25 ~28 ~12 ~25 glowstone 0
fill ~28 ~8 ~26 ~28 ~12 ~26 glowstone 0
fill ~28 ~8 ~27 ~28 ~12 ~27 glowstone 0
fill ~28 ~8 ~28 ~28 ~12 ~28 glowstone 0
fill ~28 ~8 ~29 ~28 ~12 ~29 glowstone 0
fill ~28 ~8 ~30 ~28 ~12 ~30 glowstone 0
fill ~28 ~8 ~31 ~28 ~12 ~31 glowstone 0
fill ~28 ~8 ~32 ~28 ~12 ~32 glowstone 0
fill ~28 ~8 ~33 ~28 ~12 ~33 glowstone 0
fill ~28 ~8 ~34 ~28 ~12 ~34 glowstone 0
fill ~28 ~8 ~35 ~28 ~12 ~35 glowstone 0
fill ~28 ~8 ~36 ~28 ~12 ~36 glowstone 0
fill ~28 ~8 ~37 ~28 ~12 ~37 glowstone 0
fill ~28 ~8 ~38 ~28 ~12 ~38 glowstone 0
fill ~28 ~8 ~39 ~28 ~12 ~39 glowstone 0
fill ~28 ~8 ~40 ~28 ~12 ~40 glowstone 0
fill ~28 ~8 ~41 ~28 ~12 ~41 glowstone 0
fill ~28 ~8 ~42 ~28 ~12 ~42 glowstone 0
fill ~28 ~8 ~43 ~28 ~12 ~43 glowstone 0
fill ~29 ~8 ~19 ~29 ~12 ~19 glowstone 0
fill ~29 ~8 ~23 ~29 ~13 ~23 obsidian 0
fill ~29 ~8 ~24 ~29 ~13 ~24 obsidian 0
fill ~29 ~8 ~25 ~29 ~13 ~25 obsidian 0
fill ~29 ~8 ~26 ~29 ~13 ~26 obsidian 0
fill ~29 ~8 ~27 ~29 ~13 ~27 obsidian 0
fill ~29 ~8 ~28 ~29 ~13 ~28 obsidian 0
fill ~29 ~8 ~29 ~29 ~13 ~29 obsidian 0
fill ~30 ~8 ~23 ~32 ~8 ~23 glowstone 0
fill ~30 ~8 ~24 ~30 ~12 ~24 glowstone 0
fill ~30 ~8 ~25 ~30 ~12 ~25 glowstone 0
fill ~30 ~8 ~26 ~30 ~12 ~26 glowstone 0
fill ~30 ~8 ~27 ~30 ~12 ~27 glowstone 0
fill ~30 ~8 ~28 ~30 ~12 ~28 glowstone 0
fill ~30 ~8 ~29 ~30 ~12 ~29 glowstone 0
fill ~30 ~8 ~30 ~30 ~12 ~30 glowstone 0
fill ~30 ~8 ~31 ~30 ~12 ~31 glowstone 0
fill ~30 ~8 ~32 ~30 ~12 ~32 glowstone 0
fill ~30 ~8 ~33 ~30 ~12 ~33 glowstone 0
fill ~30 ~8 ~34 ~30 ~12 ~34 glowstone 0
fill ~30 ~8 ~35 ~30 ~12 ~35 glowstone 0
fill ~30 ~8 ~36 ~30 ~12 ~36 glowstone 0
fill ~30 ~8 ~37 ~30 ~12 ~37 glowstone 0
fill ~30 ~8 ~38 ~30 ~12 ~38 glowstone 0
fill ~30 ~8 ~39 ~30 ~12 ~39 glowstone 0
fill ~30 ~8 ~40 ~30 ~12 ~40 glowstone 0
fill ~30 ~8 ~41 ~30 ~12 ~41 glowstone 0
fill ~30 ~8 ~42 ~30 ~12 ~42 glowstone 0
fill ~30 ~8 ~43 ~30 ~12 ~43 glowstone 0
fill ~30 ~8 ~44 ~39 ~8 ~44 glowstone 0
fill ~34 ~8 ~11 ~35 ~8 ~11 obsidian 0
fill ~36 ~8 ~22 ~40 ~8 ~22 obsidian 0
fill ~36 ~8 ~23 ~39 ~8 ~23 glowstone 0
fill ~38 ~8 ~11 ~40 ~8 ~11 obsidian 0
fill ~39 ~8 ~24 ~39 ~12 ~24 glowstone 0
fill ~39 ~8 ~25 ~39 ~12 ~25 glowstone 0
fill ~39 ~8 ~26 ~39 ~12 ~26 glowstone 0
fill ~39 ~8 ~27 ~39 ~12 ~27 glowstone 0
fill ~39 ~8 ~28 ~39 ~12 ~28 glowstone 0
fill ~39 ~8 ~29 ~39 ~12 ~29 glowstone 0
fill ~39 ~8 ~30 ~39 ~12 ~30 glowstone 0
fill ~39 ~8 ~31 ~39 ~12 ~31 glowstone 0
fill ~39 ~8 ~32 ~39 ~12 ~32 glowstone 0
fill ~39 ~8 ~33 ~39 ~12 ~33 glowstone 0
fill ~39 ~8 ~34 ~39 ~12 ~34 glowstone 0
fill ~39 ~8 ~35 ~39 ~12 ~35 glowstone 0
fill ~39 ~8 ~36 ~39 ~12 ~36 glowstone 0
fill ~39 ~8 ~37 ~39 ~12 ~37 glowstone 0
fill ~39 ~8 ~38 ~39 ~12 ~38 glowstone 0
fill ~39 ~8 ~39 ~39 ~12 ~39 glowstone 0
fill ~39 ~8 ~40 ~39 ~12 ~40 glowstone 0
fill ~39 ~8 ~41 ~39 ~12 ~41 glowstone 0
fill ~39 ~8 ~42 ~39 ~12 ~42 glowstone 0
fill ~39 ~8 ~43 ~39 ~12 ~43 glowstone 0
fill ~41 ~8 ~6 ~44 ~8 ~6 lava 8
fill ~41 ~8 ~7 ~44 ~8 ~7 lava 8
fill ~41 ~8 ~8 ~44 ~8 ~8 lava 8
fill ~41 ~8 ~9 ~44 ~8 ~9 lava 8
fill ~41 ~8 ~10 ~44 ~8 ~10 lava 8
fill ~41 ~8 ~11 ~44 ~8 ~11 lava 8
fill ~41 ~8 ~12 ~44 ~8 ~12 lava 8
fill ~41 ~8 ~13 ~44 ~8 ~13 lava 8
fill ~41 ~8 ~14 ~44 ~8 ~14 lava 8
fill ~41 ~8 ~15 ~44 ~8 ~15 lava 8
fill ~41 ~8 ~16 ~44 ~8 ~16 lava 8
fill ~41 ~8 ~17 ~44 ~8 ~17 lava 8
fill ~41 ~8 ~18 ~44 ~8 ~18 lava 8
fill ~41 ~8 ~19 ~44 ~8 ~19 lava 8
fill ~41 ~8 ~20 ~44 ~8 ~20 lava 8
fill ~41 ~8 ~21 ~44 ~8 ~21 lava 8
fill ~41 ~8 ~22 ~44 ~8 ~22 lava 8
fill ~41 ~8 ~23 ~44 ~8 ~23 lava 8
fill ~41 ~8 ~24 ~44 ~8 ~24 lava 8
fill ~41 ~8 ~25 ~44 ~8 ~25 lava 8
fill ~41 ~8 ~26 ~44 ~8 ~26 lava 8
fill ~41 ~8 ~27 ~44 ~8 ~27 lava 8
fill ~41 ~8 ~28 ~44 ~8 ~28 lava 8
fill ~41 ~8 ~29 ~44 ~8 ~29 lava 8
fill ~41 ~8 ~30 ~44 ~8 ~30 lava 8
fill ~41 ~8 ~31 ~44 ~8 ~31 lava 8
fill ~41 ~8 ~32 ~44 ~8 ~32 lava 8
fill ~41 ~8 ~33 ~44 ~8 ~33 lava 8
fill ~41 ~8 ~34 ~44 ~8 ~34 lava 8
fill ~41 ~8 ~35 ~44 ~8 ~35 lava 8
fill ~41 ~8 ~36 ~44 ~8 ~36 lava 8
fill ~41 ~8 ~37 ~44 ~8 ~37 lava 8
fill ~41 ~8 ~38 ~44 ~8 ~38 lava 8
fill ~41 ~8 ~39 ~44 ~8 ~39 lava 8
fill ~41 ~8 ~40 ~44 ~8 ~40 lava 8
fill ~41 ~8 ~41 ~44 ~8 ~41 lava 8
fill ~41 ~8 ~42 ~44 ~8 ~42 lava 8
fill ~41 ~8 ~43 ~44 ~8 ~43 lava 8
fill ~41 ~8 ~44 ~44 ~8 ~44 lava 8
fill ~41 ~8 ~45 ~44 ~8 ~45 lava 8
fill ~3 ~9 ~1 ~45 ~9 ~1 obsidian 0
fill ~3 ~9 ~50 ~45 ~9 ~50 obsidian 0
fill ~4 ~9 ~2 ~44 ~9 ~2 lava 8
fill ~4 ~9 ~3 ~44 ~9 ~3 lava 8
fill ~4 ~9 ~4 ~44 ~9 ~4 lava 8
fill ~4 ~9 ~5 ~44 ~9 ~5 lava 8
fill ~4 ~9 ~6 ~6 ~9 ~6 lava 8
fill ~4 ~9 ~7 ~6 ~9 ~7 lava 8
fill ~4 ~9 ~8 ~6 ~9 ~8 lava 8
fill ~4 ~9 ~9 ~6 ~9 ~9 lava 8
fill ~4 ~9 ~10 ~6 ~9 ~10 lava 8
fill ~4 ~9 ~11 ~6 ~9 ~11 lava 8
fill ~4 ~9 ~12 ~6 ~9 ~12 lava 8
fill ~4 ~9 ~13 ~6 ~9 ~13 lava 8
fill ~4 ~9 ~14 ~6 ~9 ~14 lava 8
fill ~4 ~9 ~15 ~6 ~9 ~15 lava 8
fill ~4 ~9 ~16 ~6 ~9 ~16 lava 8
fill ~4 ~9 ~17 ~6 ~9 ~17 lava 8
fill ~4 ~9 ~18 ~6 ~9 ~18 lava 8
fill ~4 ~9 ~19 ~6 ~9 ~19 lava 8
fill ~4 ~9 ~20 ~6 ~9 ~20 lava 8
fill ~4 ~9 ~21 ~6 ~9 ~21 lava 8
fill ~4 ~9 ~22 ~6 ~9 ~22 lava 8
fill ~4 ~9 ~23 ~6 ~9 ~23 lava 8
fill ~4 ~9 ~24 ~6 ~9 ~24 lava 8
fill ~4 ~9 ~25 ~6 ~9 ~25 lava 8
fill ~4 ~9 ~26 ~6 ~9 ~26 lava 8
fill ~4 ~9 ~27 ~6 ~9 ~27 lava 8
fill ~4 ~9 ~28 ~6 ~9 ~28 lava 8
fill ~4 ~9 ~29 ~6 ~9 ~29 lava 8
fill ~4 ~9 ~30 ~6 ~9 ~30 lava 8
fill ~4 ~9 ~31 ~6 ~9 ~31 lava 8
fill ~4 ~9 ~32 ~6 ~9 ~32 lava 8
fill ~4 ~9 ~33 ~6 ~9 ~33 lava 8
fill ~4 ~9 ~34 ~6 ~9 ~34 lava 8
fill ~4 ~9 ~35 ~6 ~9 ~35 lava 8
fill ~4 ~9 ~36 ~6 ~9 ~36 lava 8
fill ~4 ~9 ~37 ~6 ~9 ~37 lava 8
fill ~4 ~9 ~38 ~6 ~9 ~38 lava 8
fill ~4 ~9 ~39 ~6 ~9 ~39 lava 8
fill ~4 ~9 ~40 ~6 ~9 ~40 lava 8
fill ~4 ~9 ~41 ~6 ~9 ~41 lava 8
fill ~4 ~9 ~42 ~6 ~9 ~42 lava 8
fill ~4 ~9 ~43 ~6 ~9 ~43 lava 8
fill ~4 ~9 ~44 ~6 ~9 ~44 lava 8
fill ~4 ~9 ~45 ~6 ~9 ~45 lava 8
fill ~4 ~9 ~46 ~44 ~9 ~46 lava 8
fill ~4 ~9 ~47 ~44 ~9 ~47 lava 8
fill ~4 ~9 ~48 ~44 ~9 ~48 lava 8
fill ~4 ~9 ~49 ~44 ~9 ~49 lava 8
fill ~7 ~9 ~6 ~40 ~9 ~6 obsidian 0
fill ~7 ~9 ~45 ~40 ~9 ~45 obsidian 0
fill ~8 ~9 ~11 ~9 ~9 ~11 obsidian 0
fill ~8 ~9 ~16 ~9 ~9 ~16 obsidian 0
fill ~8 ~9 ~22 ~11 ~9 ~22 obsidian 0
fill ~8 ~9 ~23 ~11 ~9 ~23 glowstone 0
fill ~8 ~9 ~44 ~17 ~9 ~44 glowstone 0
fill ~12 ~9 ~11 ~13 ~9 ~11 obsidian 0
fill ~12 ~9 ~16 ~13 ~9 ~16 obsidian 0
fill ~15 ~9 ~22 ~22 ~9 ~22 obsidian 0
fill ~15 ~9 ~23 ~17 ~9 ~23 glowstone 0
fill ~16 ~9 ~11 ~20 ~9 ~11 obsidian 0
fill ~16 ~9 ~16 ~20 ~9 ~16 obsidian 0
fill ~19 ~9 ~23 ~22 ~9 ~23 glowstone 0
fill ~19 ~9 ~44 ~28 ~9 ~44 glowstone 0
fill ~23 ~9 ~11 ~24 ~9 ~11 obsidian 0
fill ~23 ~9 ~16 ~24 ~9 ~16 obsidian 0
fill ~26 ~9 ~22 ~32 ~9 ~22 obsidian 0
fill ~26 ~9 ~23 ~28 ~9 ~23 glowstone 0
fill ~27 ~9 ~11 ~31 ~9 ~11 obsidian 0
fill ~27 ~9 ~16 ~29 ~9 ~16 obsidian 0
fill ~30 ~9 ~23 ~32 ~9 ~23 glowstone 0
fill ~30 ~9 ~44 ~39 ~9 ~44 glowstone 0
fill ~34 ~9 ~11 ~35 ~9 ~11 obsidian 0
fill ~36 ~9 ~22 ~40 ~9 ~22 obsidian 0
fill ~36 ~9 ~23 ~39 ~9 ~23 glowstone 0
fill ~38 ~9 ~11 ~40 ~9 ~11 obsidian 0
fill ~41 ~9 ~6 ~44 ~9 ~6 lava 8
fill ~41 ~9 ~7 ~44 ~9 ~7 lava 8
fill ~41 ~9 ~8 ~44 ~9 ~8 lava 8
fill ~41 ~9 ~9 ~44 ~9 ~9 lava 8
fill ~41 ~9 ~10 ~44 ~9 ~10 lava 8
fill ~41 ~9 ~11 ~44 ~9 ~11 lava 8
fill ~41 ~9 ~12 ~44 ~9 ~12 lava 8
fill ~41 ~9 ~13 ~44 ~9 ~13 lava 8
fill ~41 ~9 ~14 ~44 ~9 ~14 lava 8
fill ~41 ~9 ~15 ~44 ~9 ~15 lava 8
fill ~41 ~9 ~16 ~44 ~9 ~16 lava 8
fill ~41 ~9 ~17 ~44 ~9 ~17 lava 8
fill ~41 ~9 ~18 ~44 ~9 ~18 lava 8
fill ~41 ~9 ~19 ~44 ~9 ~19 lava 8
fill ~41 ~9 ~20 ~44 ~9 ~20 lava 8
fill ~41 ~9 ~21 ~44 ~9 ~21 lava 8
fill ~41 ~9 ~22 ~44 ~9 ~22 lava 8
fill ~41 ~9 ~23 ~44 ~9 ~23 lava 8
fill ~41 ~9 ~24 ~44 ~9 ~24 lava 8
fill ~41 ~9 ~25 ~44 ~9 ~25 lava 8
fill ~41 ~9 ~26 ~44 ~9 ~26 lava 8
fill ~41 ~9 ~27 ~44 ~9 ~27 lava 8
fill ~41 ~9 ~28 ~44 ~9 ~28 lava 8
fill ~41 ~9 ~29 ~44 ~9 ~29 lava 8
fill ~41 ~9 ~30 ~44 ~9 ~30 lava 8
fill ~41 ~9 ~31 ~44 ~9 ~31 lava 8
fill ~41 ~9 ~32 ~44 ~9 ~32 lava 8
fill ~41 ~9 ~33 ~44 ~9 ~33 lava 8
fill ~41 ~9 ~34 ~44 ~9 ~34 lava 8
fill ~41 ~9 ~35 ~44 ~9 ~35 lava 8
fill ~41 ~9 ~36 ~44 ~9 ~36 lava 8
fill ~41 ~9 ~37 ~44 ~9 ~37 lava 8
fill ~41 ~9 ~38 ~44 ~9 ~38 lava 8
fill ~41 ~9 ~39 ~44 ~9 ~39 lava 8
fill ~41 ~9 ~40 ~44 ~9 ~40 lava 8
fill ~41 ~9 ~41 ~44 ~9 ~41 lava 8
fill ~41 ~9 ~42 ~44 ~9 ~42 lava 8
fill ~41 ~9 ~43 ~44 ~9 ~43 lava 8
fill ~41 ~9 ~44 ~44 ~9 ~44 lava 8
fill ~41 ~9 ~45 ~44 ~9 ~45 lava 8
fill ~3 ~10 ~1 ~45 ~10 ~1 obsidian 0
fill ~3 ~10 ~50 ~45 ~10 ~50 obsidian 0
fill ~4 ~10 ~2 ~44 ~10 ~2 lava 8
fill ~4 ~10 ~3 ~44 ~10 ~3 lava 8
fill ~4 ~10 ~4 ~44 ~10 ~4 lava 8
fill ~4 ~10 ~5 ~44 ~10 ~5 lava 8
fill ~4 ~10 ~6 ~6 ~10 ~6 lava 8
fill ~4 ~10 ~7 ~6 ~10 ~7 lava 8
fill ~4 ~10 ~8 ~6 ~10 ~8 lava 8
fill ~4 ~10 ~9 ~6 ~10 ~9 lava 8
fill ~4 ~10 ~10 ~6 ~10 ~10 lava 8
fill ~4 ~10 ~11 ~6 ~10 ~11 lava 8
fill ~4 ~10 ~12 ~6 ~10 ~12 lava 8
fill ~4 ~10 ~13 ~6 ~10 ~13 lava 8
fill ~4 ~10 ~14 ~6 ~10 ~14 lava 8
fill ~4 ~10 ~15 ~6 ~10 ~15 lava 8
fill ~4 ~10 ~16 ~6 ~10 ~16 lava 8
fill ~4 ~10 ~17 ~6 ~10 ~17 lava 8
fill ~4 ~10 ~18 ~6 ~10 ~18 lava 8
fill ~4 ~10 ~19 ~6 ~10 ~19 lava 8
fill ~4 ~10 ~20 ~6 ~10 ~20 lava 8
fill ~4 ~10 ~21 ~6 ~10 ~21 lava 8
fill ~4 ~10 ~22 ~6 ~10 ~22 lava 8
fill ~4 ~10 ~23 ~6 ~10 ~23 lava 8
fill ~4 ~10 ~24 ~6 ~10 ~24 lava 8
fill ~4 ~10 ~25 ~6 ~10 ~25 lava 8
fill ~4 ~10 ~26 ~6 ~10 ~26 lava 8
fill ~4 ~10 ~27 ~6 ~10 ~27 lava 8
fill ~4 ~10 ~28 ~6 ~10 ~28 lava 8
fill ~4 ~10 ~29 ~6 ~10 ~29 lava 8
fill ~4 ~10 ~30 ~6 ~10 ~30 lava 8
fill ~4 ~10 ~31 ~6 ~10 ~31 lava 8
fill ~4 ~10 ~32 ~6 ~10 ~32 lava 8
fill ~4 ~10 ~33 ~6 ~10 ~33 lava 8
fill ~4 ~10 ~34 ~6 ~10 ~34 lava 8
fill ~4 ~10 ~35 ~6 ~10 ~35 lava 8
fill ~4 ~10 ~36 ~6 ~10 ~36 lava 8
fill ~4 ~10 ~37 ~6 ~10 ~37 lava 8
fill ~4 ~10 ~38 ~6 ~10 ~38 lava 8
fill ~4 ~10 ~39 ~6 ~10 ~39 lava 8
fill ~4 ~10 ~40 ~6 ~10 ~40 lava 8
fill ~4 ~10 ~41 ~6 ~10 ~41 lava 8
fill ~4 ~10 ~42 ~6 ~10 ~42 lava 8
fill ~4 ~10 ~43 ~6 ~10 ~43 lava 8
fill ~4 ~10 ~44 ~6 ~10 ~44 lava 8
fill ~4 ~10 ~45 ~6 ~10 ~45 lava 8
fill ~4 ~10 ~46 ~44 ~10 ~46 lava 8
fill ~4 ~10 ~47 ~44 ~10 ~47 lava 8
fill ~4 ~10 ~48 ~44 ~10 ~48 lava 8
fill ~4 ~10 ~49 ~44 ~10 ~49 lava 8
fill ~7 ~10 ~6 ~40 ~10 ~6 obsidian 0
fill ~7 ~10 ~45 ~40 ~10 ~45 obsidian 0
fill ~8 ~10 ~11 ~9 ~10 ~11 obsidian 0
fill ~8 ~10 ~16 ~9 ~10 ~16 obsidian 0
fill ~8 ~10 ~22 ~11 ~10 ~22 obsidian 0
fill ~8 ~10 ~23 ~11 ~10 ~23 glowstone 0
fill ~8 ~10 ~44 ~17 ~10 ~44 glowstone 0
fill ~12 ~10 ~11 ~13 ~10 ~11 obsidian 0
fill ~12 ~10 ~16 ~13 ~10 ~16 obsidian 0
fill ~15 ~10 ~22 ~22 ~10 ~22 obsidian 0
fill ~15 ~10 ~23 ~17 ~10 ~23 glowstone 0
fill ~16 ~10 ~11 ~20 ~10 ~11 obsidian 0
fill ~16 ~10 ~16 ~20 ~10 ~16 obsidian 0
fill ~19 ~10 ~23 ~22 ~10 ~23 glowstone 0
fill ~19 ~10 ~44 ~28 ~10 ~44 glowstone 0
fill ~23 ~10 ~11 ~24 ~10 ~11 obsidian 0
fill ~23 ~10 ~16 ~24 ~10 ~16 obsidian 0
fill ~26 ~10 ~22 ~32 ~10 ~22 obsidian 0
fill ~26 ~10 ~23 ~28 ~10 ~23 glowstone 0
fill ~27 ~10 ~11 ~31 ~10 ~11 obsidian 0
fill ~27 ~10 ~16 ~29 ~10 ~16 obsidian 0
fill ~30 ~10 ~23 ~32 ~10 ~23 glowstone 0
fill ~30 ~10 ~44 ~39 ~10 ~44 glowstone 0
fill ~34 ~10 ~11 ~35 ~10 ~11 obsidian 0
fill ~36 ~10 ~22 ~40 ~10 ~22 obsidian 0
fill ~36 ~10 ~23 ~39 ~10 ~23 glowstone 0
fill ~38 ~10 ~11 ~40 ~10 ~11 obsidian 0
fill ~41 ~10 ~6 ~44 ~10 ~6 lava 8
fill ~41 ~10 ~7 ~44 ~10 ~7 lava 8
fill ~41 ~10 ~8 ~44 ~10 ~8 lava 8
fill ~41 ~10 ~9 ~44 ~10 ~9 lava 8
fill ~41 ~10 ~10 ~44 ~10 ~10 lava 8
fill ~41 ~10 ~11 ~44 ~10 ~11 lava 8
fill ~41 ~10 ~12 ~44 ~10 ~12 lava 8
fill ~41 ~10 ~13 ~44 ~10 ~13 lava 8
fill ~41 ~10 ~14 ~44 ~10 ~14 lava 8
fill ~41 ~10 ~15 ~44 ~10 ~15 lava 8
fill ~41 ~10 ~16 ~44 ~10 ~16 lava 8
fill ~41 ~10 ~17 ~44 ~10 ~17 lava 8
fill ~41 ~10 ~18 ~44 ~10 ~18 lava 8
fill ~41 ~10 ~19 ~44 ~10 ~19 lava 8
fill ~41 ~10 ~20 ~44 ~10 ~20 lava 8
fill ~41 ~10 ~21 ~44 ~10 ~21 lava 8
fill ~41 ~10 ~22 ~44 ~10 ~22 lava 8
fill ~41 ~10 ~23 ~44 ~10 ~23 lava 8
fill ~41 ~10 ~24 ~44 ~10 ~24 lava 8
fill ~41 ~10 ~25 ~44 ~10 ~25 lava 8
fill ~41 ~10 ~26 ~44 ~10 ~26 lava 8
fill ~41 ~10 ~27 ~44 ~10 ~27 lava 8
fill ~41 ~10 ~28 ~44 ~10 ~28 lava 8
fill ~41 ~10 ~29 ~44 ~10 ~29 lava 8
fill ~41 ~10 ~30 ~44 ~10 ~30 lava 8
fill ~41 ~10 ~31 ~44 ~10 ~31 lava 8
fill ~41 ~10 ~32 ~44 ~10 ~32 lava 8
fill ~41 ~10 ~33 ~44 ~10 ~33 lava 8
fill ~41 ~10 ~34 ~44 ~10 ~34 lava 8
fill ~41 ~10 ~35 ~44 ~10 ~35 lava 8
fill ~41 ~10 ~36 ~44 ~10 ~36 lava 8
fill ~41 ~10 ~37 ~44 ~10 ~37 lava 8
fill ~41 ~10 ~38 ~44 ~10 ~38 lava 8
fill ~41 ~10 ~39 ~44 ~10 ~39 lava 8
fill ~41 ~10 ~40 ~44 ~10 ~40 lava 8
fill ~41 ~10 ~41 ~44 ~10 ~41 lava 8
fill ~41 ~10 ~42 ~44 ~10 ~42 lava 8
fill ~41 ~10 ~43 ~44 ~10 ~43 lava 8
fill ~41 ~10 ~44 ~44 ~10 ~44 lava 8
fill ~41 ~10 ~45 ~44 ~10 ~45 lava 8
fill ~3 ~11 ~1 ~45 ~11 ~1 obsidian 0
fill ~3 ~11 ~50 ~45 ~11 ~50 obsidian 0
fill ~4 ~11 ~2 ~44 ~11 ~2 lava 8
fill ~4 ~11 ~3 ~44 ~11 ~3 lava 8
fill ~4 ~11 ~4 ~44 ~11 ~4 lava 8
fill ~4 ~11 ~5 ~44 ~11 ~5 lava 8
fill ~4 ~11 ~6 ~6 ~11 ~6 lava 8
fill ~4 ~11 ~7 ~6 ~11 ~7 lava 8
fill ~4 ~11 ~8 ~6 ~11 ~8 lava 8
fill ~4 ~11 ~9 ~6 ~11 ~9 lava 8
fill ~4 ~11 ~10 ~6 ~11 ~10 lava 8
fill ~4 ~11 ~11 ~6 ~11 ~11 lava 8
fill ~4 ~11 ~12 ~6 ~11 ~12 lava 8
fill ~4 ~11 ~13 ~6 ~11 ~13 lava 8
fill ~4 ~11 ~14 ~6 ~11 ~14 lava 8
fill ~4 ~11 ~15 ~6 ~11 ~15 lava 8
fill ~4 ~11 ~16 ~6 ~11 ~16 lava 8
fill ~4 ~11 ~17 ~6 ~11 ~17 lava 8
fill ~4 ~11 ~18 ~6 ~11 ~18 lava 8
fill ~4 ~11 ~19 ~6 ~11 ~19 lava 8
fill ~4 ~11 ~20 ~6 ~11 ~20 lava 8
fill ~4 ~11 ~21 ~6 ~11 ~21 lava 8
fill ~4 ~11 ~22 ~6 ~11 ~22 lava 8
fill ~4 ~11 ~23 ~6 ~11 ~23 lava 8
fill ~4 ~11 ~24 ~6 ~11 ~24 lava 8
fill ~4 ~11 ~25 ~6 ~11 ~25 lava 8
fill ~4 ~11 ~26 ~6 ~11 ~26 lava 8
fill ~4 ~11 ~27 ~6 ~11 ~27 lava 8
fill ~4 ~11 ~28 ~6 ~11 ~28 lava 8
fill ~4 ~11 ~29 ~6 ~11 ~29 lava 8
fill ~4 ~11 ~30 ~6 ~11 ~30 lava 8
fill ~4 ~11 ~31 ~6 ~11 ~31 lava 8
fill ~4 ~11 ~32 ~6 ~11 ~32 lava 8
fill ~4 ~11 ~33 ~6 ~11 ~33 lava 8
fill ~4 ~11 ~34 ~6 ~11 ~34 lava 8
fill ~4 ~11 ~35 ~6 ~11 ~35 lava 8
fill ~4 ~11 ~36 ~6 ~11 ~36 lava 8
fill ~4 ~11 ~37 ~6 ~11 ~37 lava 8
fill ~4 ~11 ~38 ~6 ~11 ~38 lava 8
fill ~4 ~11 ~39 ~6 ~11 ~39 lava 8
fill ~4 ~11 ~40 ~6 ~11 ~40 lava 8
fill ~4 ~11 ~41 ~6 ~11 ~41 lava 8
fill ~4 ~11 ~42 ~6 ~11 ~42 lava 8
fill ~4 ~11 ~43 ~6 ~11 ~43 lava 8
fill ~4 ~11 ~44 ~6 ~11 ~44 lava 8
fill ~4 ~11 ~45 ~6 ~11 ~45 lava 8
fill ~4 ~11 ~46 ~44 ~11 ~46 lava 8
fill ~4 ~11 ~47 ~44 ~11 ~47 lava 8
fill ~4 ~11 ~48 ~44 ~11 ~48 lava 8
fill ~4 ~11 ~49 ~44 ~11 ~49 lava 8
fill ~7 ~11 ~6 ~40 ~11 ~6 obsidian 0
fill ~7 ~11 ~45 ~40 ~11 ~45 obsidian 0
fill ~8 ~11 ~11 ~9 ~11 ~11 obsidian 0
fill ~8 ~11 ~16 ~9 ~11 ~16 obsidian 0
fill ~8 ~11 ~22 ~11 ~11 ~22 obsidian 0
fill ~8 ~11 ~23 ~11 ~11 ~23 glowstone 0
fill ~8 ~11 ~44 ~17 ~11 ~44 glowstone 0
fill ~12 ~11 ~11 ~13 ~11 ~11 obsidian 0
fill ~12 ~11 ~16 ~13 ~11 ~16 obsidian 0
fill ~15 ~11 ~22 ~22 ~11 ~22 obsidian 0
fill ~15 ~11 ~23 ~17 ~11 ~23 glowstone 0
fill ~16 ~11 ~11 ~20 ~11 ~11 obsidian 0
fill ~16 ~11 ~16 ~20 ~11 ~16 obsidian 0
fill ~19 ~11 ~23 ~22 ~11 ~23 glowstone 0
fill ~19 ~11 ~44 ~28 ~11 ~44 glowstone 0
fill ~23 ~11 ~11 ~24 ~11 ~11 obsidian 0
fill ~23 ~11 ~16 ~24 ~11 ~16 obsidian 0
fill ~26 ~11 ~22 ~32 ~11 ~22 obsidian 0
fill ~26 ~11 ~23 ~28 ~11 ~23 glowstone 0
fill ~27 ~11 ~11 ~31 ~11 ~11 obsidian 0
fill ~27 ~11 ~16 ~29 ~11 ~16 obsidian 0
fill ~30 ~11 ~23 ~32 ~11 ~23 glowstone 0
fill ~30 ~11 ~44 ~39 ~11 ~44 glowstone 0
fill ~34 ~11 ~11 ~35 ~11 ~11 obsidian 0
fill ~36 ~11 ~22 ~40 ~11 ~22 obsidian 0
fill ~36 ~11 ~23 ~39 ~11 ~23 glowstone 0
fill ~38 ~11 ~11 ~40 ~11 ~11 obsidian 0
fill ~41 ~11 ~6 ~44 ~11 ~6 lava 8
fill ~41 ~11 ~7 ~44 ~11 ~7 lava 8
fill ~41 ~11 ~8 ~44 ~11 ~8 lava 8
fill ~41 ~11 ~9 ~44 ~11 ~9 lava 8
fill ~41 ~11 ~10 ~44 ~11 ~10 lava 8
fill ~41 ~11 ~11 ~44 ~11 ~11 lava 8
fill ~41 ~11 ~12 ~44 ~11 ~12 lava 8
fill ~41 ~11 ~13 ~44 ~11 ~13 lava 8
fill ~41 ~11 ~14 ~44 ~11 ~14 lava 8
fill ~41 ~11 ~15 ~44 ~11 ~15 lava 8
fill ~41 ~11 ~16 ~44 ~11 ~16 lava 8
fill ~41 ~11 ~17 ~44 ~11 ~17 lava 8
fill ~41 ~11 ~18 ~44 ~11 ~18 lava 8
fill ~41 ~11 ~19 ~44 ~11 ~19 lava 8
fill ~41 ~11 ~20 ~44 ~11 ~20 lava 8
fill ~41 ~11 ~21 ~44 ~11 ~21 lava 8
fill ~41 ~11 ~22 ~44 ~11 ~22 lava 8
fill ~41 ~11 ~23 ~44 ~11 ~23 lava 8
fill ~41 ~11 ~24 ~44 ~11 ~24 lava 8
fill ~41 ~11 ~25 ~44 ~11 ~25 lava 8
fill ~41 ~11 ~26 ~44 ~11 ~26 lava 8
fill ~41 ~11 ~27 ~44 ~11 ~27 lava 8
fill ~41 ~11 ~28 ~44 ~11 ~28 lava 8
fill ~41 ~11 ~29 ~44 ~11 ~29 lava 8
fill ~41 ~11 ~30 ~44 ~11 ~30 lava 8
fill ~41 ~11 ~31 ~44 ~11 ~31 lava 8
fill ~41 ~11 ~32 ~44 ~11 ~32 lava 8
fill ~41 ~11 ~33 ~44 ~11 ~33 lava 8
fill ~41 ~11 ~34 ~44 ~11 ~34 lava 8
fill ~41 ~11 ~35 ~44 ~11 ~35 lava 8
fill ~41 ~11 ~36 ~44 ~11 ~36 lava 8
fill ~41 ~11 ~37 ~44 ~11 ~37 lava 8
fill ~41 ~11 ~38 ~44 ~11 ~38 lava 8
fill ~41 ~11 ~39 ~44 ~11 ~39 lava 8
fill ~41 ~11 ~40 ~44 ~11 ~40 lava 8
fill ~41 ~11 ~41 ~44 ~11 ~41 lava 8
fill ~41 ~11 ~42 ~44 ~11 ~42 lava 8
fill ~41 ~11 ~43 ~44 ~11 ~43 lava 8
fill ~41 ~11 ~44 ~44 ~11 ~44 lava 8
fill ~41 ~11 ~45 ~44 ~11 ~45 lava 8
fill ~3 ~12 ~1 ~45 ~12 ~1 obsidian 0
fill ~3 ~12 ~50 ~45 ~12 ~50 obsidian 0
fill ~4 ~12 ~2 ~44 ~12 ~2 lava 0
fill ~4 ~12 ~3 ~44 ~12 ~3 lava 0
fill ~4 ~12 ~4 ~44 ~12 ~4 lava 0
fill ~4 ~12 ~5 ~44 ~12 ~5 lava 0
fill ~4 ~12 ~6 ~6 ~12 ~6 lava 0
fill ~4 ~12 ~7 ~6 ~12 ~7 lava 0
fill ~4 ~12 ~8 ~6 ~12 ~8 lava 0
fill ~4 ~12 ~9 ~6 ~12 ~9 lava 0
fill ~4 ~12 ~10 ~6 ~12 ~10 lava 0
fill ~4 ~12 ~11 ~6 ~12 ~11 lava 0
fill ~4 ~12 ~12 ~6 ~12 ~12 lava 0
fill ~4 ~12 ~13 ~6 ~12 ~13 lava 0
fill ~4 ~12 ~14 ~6 ~12 ~14 lava 0
fill ~4 ~12 ~15 ~6 ~12 ~15 lava 0
fill ~4 ~12 ~16 ~6 ~12 ~16 lava 0
fill ~4 ~12 ~17 ~6 ~12 ~17 lava 0
fill ~4 ~12 ~18 ~6 ~12 ~18 lava 0
fill ~4 ~12 ~19 ~6 ~12 ~19 lava 0
fill ~4 ~12 ~20 ~6 ~12 ~20 lava 0
fill ~4 ~12 ~21 ~6 ~12 ~21 lava 0
fill ~4 ~12 ~22 ~6 ~12 ~22 lava 0
fill ~4 ~12 ~23 ~6 ~12 ~23 lava 0
fill ~4 ~12 ~24 ~6 ~12 ~24 lava 0
fill ~4 ~12 ~25 ~6 ~12 ~25 lava 0
fill ~4 ~12 ~26 ~6 ~12 ~26 lava 0
fill ~4 ~12 ~27 ~6 ~12 ~27 lava 0
fill ~4 ~12 ~28 ~6 ~12 ~28 lava 0
fill ~4 ~12 ~29 ~6 ~12 ~29 lava 0
fill ~4 ~12 ~30 ~6 ~12 ~30 lava 0
fill ~4 ~12 ~31 ~6 ~12 ~31 lava 0
fill ~4 ~12 ~32 ~6 ~12 ~32 lava 0
fill ~4 ~12 ~33 ~6 ~12 ~33 lava 0
fill ~4 ~12 ~34 ~6 ~12 ~34 lava 0
fill ~4 ~12 ~35 ~6 ~12 ~35 lava 0
fill ~4 ~12 ~36 ~6 ~12 ~36 lava 0
fill ~4 ~12 ~37 ~6 ~12 ~37 lava 0
fill ~4 ~12 ~38 ~6 ~12 ~38 lava 0
fill ~4 ~12 ~39 ~6 ~12 ~39 lava 0
fill ~4 ~12 ~40 ~6 ~12 ~40 lava 0
fill ~4 ~12 ~41 ~6 ~12 ~41 lava 0
fill ~4 ~12 ~42 ~6 ~12 ~42 lava 0
fill ~4 ~12 ~43 ~6 ~12 ~43 lava 0
fill ~4 ~12 ~44 ~6 ~12 ~44 lava 0
fill ~4 ~12 ~45 ~6 ~12 ~45 lava 0
fill ~4 ~12 ~46 ~44 ~12 ~46 lava 0
fill ~4 ~12 ~47 ~44 ~12 ~47 lava 0
fill ~4 ~12 ~48 ~44 ~12 ~48 lava 0
fill ~4 ~12 ~49 ~44 ~12 ~49 lava 0
fill ~7 ~12 ~6 ~40 ~12 ~6 obsidian 0
fill ~7 ~12 ~45 ~40 ~12 ~45 obsidian 0
fill ~8 ~12 ~11 ~9 ~12 ~11 obsidian 0
fill ~8 ~12 ~16 ~9 ~12 ~16 obsidian 0
fill ~8 ~12 ~22 ~40 ~12 ~22 obsidian 0
fill ~8 ~12 ~23 ~17 ~12 ~23 glowstone 0
fill ~8 ~12 ~44 ~17 ~12 ~44 glowstone 0
fill ~12 ~12 ~11 ~13 ~12 ~11 obsidian 0
fill ~12 ~12 ~16 ~13 ~12 ~16 obsidian 0
fill ~16 ~12 ~11 ~20 ~12 ~11 obsidian 0
fill ~16 ~12 ~16 ~20 ~12 ~16 obsidian 0
fill ~18 ~12 ~19 ~18 ~13 ~19 obsidian 0
fill ~19 ~12 ~23 ~28 ~12 ~23 glowstone 0
fill ~19 ~12 ~44 ~28 ~12 ~44 glowstone 0
fill ~23 ~12 ~11 ~24 ~12 ~11 obsidian 0
fill ~23 ~12 ~16 ~24 ~12 ~16 obsidian 0
fill ~27 ~12 ~11 ~31 ~12 ~11 obsidian 0
fill ~27 ~12 ~16 ~29 ~12 ~16 obsidian 0
fill ~30 ~12 ~8 ~30 ~12 ~9 glowstone 0
fill ~30 ~12 ~23 ~39 ~12 ~23 glowstone 0
fill ~30 ~12 ~44 ~39 ~12 ~44 glowstone 0
fill ~32 ~12 ~7 ~33 ~12 ~7 glowstone 0
fill ~34 ~12 ~11 ~35 ~12 ~11 obsidian 0
fill ~36 ~12 ~7 ~37 ~12 ~7 glowstone 0
fill ~38 ~12 ~11 ~40 ~12 ~11 obsidian 0
fill ~39 ~12 ~8 ~39 ~12 ~9 glowstone 0
fill ~41 ~12 ~6 ~44 ~12 ~6 lava 0
fill ~41 ~12 ~7 ~44 ~12 ~7 lava 0
fill ~41 ~12 ~8 ~44 ~12 ~8 lava 0
fill ~41 ~12 ~9 ~44 ~12 ~9 lava 0
fill ~41 ~12 ~10 ~44 ~12 ~10 lava 0
fill ~41 ~12 ~11 ~44 ~12 ~11 lava 0
fill ~41 ~12 ~12 ~44 ~12 ~12 lava 0
fill ~41 ~12 ~13 ~44 ~12 ~13 lava 0
fill ~41 ~12 ~14 ~44 ~12 ~14 lava 0
