fill ~63~2~0 ~67~99~0 minecraft:barrier
fill ~61~2~1 ~62~99~1 minecraft:barrier
fill ~1 ~-3 ~0 ~182 ~-3 ~0 bedrock 0
fill ~1 ~-3 ~1 ~182 ~-3 ~1 bedrock 0
fill ~1 ~-3 ~2 ~182 ~-3 ~2 bedrock 0
fill ~1 ~-3 ~3 ~182 ~-3 ~3 bedrock 0
fill ~1 ~-3 ~4 ~182 ~-3 ~4 bedrock 0
fill ~1 ~-3 ~5 ~182 ~-3 ~5 bedrock 0
fill ~1 ~-3 ~6 ~182 ~-3 ~6 bedrock 0
fill ~1 ~-3 ~7 ~182 ~-3 ~7 bedrock 0
fill ~1 ~-3 ~8 ~182 ~-3 ~8 bedrock 0
fill ~1 ~-3 ~9 ~182 ~-3 ~9 bedrock 0
fill ~1 ~-3 ~10 ~182 ~-3 ~10 bedrock 0
fill ~1 ~-3 ~11 ~182 ~-3 ~11 bedrock 0
fill ~1 ~-3 ~12 ~182 ~-3 ~12 bedrock 0
fill ~1 ~-3 ~13 ~182 ~-3 ~13 bedrock 0
fill ~1 ~-3 ~14 ~182 ~-3 ~14 bedrock 0
fill ~1 ~-3 ~15 ~182 ~-3 ~15 bedrock 0
fill ~1 ~-3 ~16 ~182 ~-3 ~16 bedrock 0
fill ~1 ~-3 ~17 ~182 ~-3 ~17 bedrock 0
fill ~1 ~-3 ~18 ~182 ~-3 ~18 bedrock 0
fill ~1 ~-3 ~19 ~182 ~-3 ~19 bedrock 0
fill ~1 ~-3 ~20 ~182 ~-3 ~20 bedrock 0
fill ~1 ~-3 ~21 ~182 ~-3 ~21 bedrock 0
fill ~1 ~-3 ~22 ~182 ~-3 ~22 bedrock 0
fill ~1 ~-3 ~23 ~182 ~-3 ~23 bedrock 0
fill ~1 ~-3 ~24 ~182 ~-3 ~24 bedrock 0
fill ~1 ~-3 ~25 ~182 ~-3 ~25 bedrock 0
fill ~1 ~-3 ~26 ~182 ~-3 ~26 bedrock 0
fill ~1 ~-3 ~27 ~182 ~-3 ~27 bedrock 0
fill ~1 ~-3 ~28 ~182 ~-3 ~28 bedrock 0
fill ~1 ~-3 ~29 ~182 ~-3 ~29 bedrock 0
fill ~1 ~-3 ~30 ~182 ~-3 ~30 bedrock 0
fill ~1 ~-3 ~31 ~182 ~-3 ~31 bedrock 0
fill ~1 ~-3 ~32 ~182 ~-3 ~32 bedrock 0
fill ~1 ~-3 ~33 ~182 ~-3 ~33 bedrock 0
fill ~1 ~-3 ~34 ~182 ~-3 ~34 bedrock 0
fill ~1 ~-3 ~35 ~182 ~-3 ~35 bedrock 0
fill ~1 ~-3 ~36 ~182 ~-3 ~36 bedrock 0
fill ~1 ~-3 ~37 ~182 ~-3 ~37 bedrock 0
fill ~1 ~-3 ~38 ~182 ~-3 ~38 bedrock 0
fill ~1 ~-3 ~39 ~182 ~-3 ~39 bedrock 0
fill ~1 ~-3 ~40 ~182 ~-3 ~40 bedrock 0
fill ~1 ~-3 ~41 ~182 ~-3 ~41 bedrock 0
fill ~1 ~-3 ~42 ~182 ~-3 ~42 bedrock 0
fill ~1 ~-3 ~43 ~182 ~-3 ~43 bedrock 0
fill ~1 ~-3 ~44 ~182 ~-3 ~44 bedrock 0
fill ~1 ~-3 ~45 ~182 ~-3 ~45 bedrock 0
fill ~1 ~-3 ~46 ~182 ~-3 ~46 bedrock 0
fill ~1 ~-3 ~47 ~182 ~-3 ~47 bedrock 0
fill ~1 ~-3 ~48 ~182 ~-3 ~48 bedrock 0
fill ~1 ~-3 ~49 ~182 ~-3 ~49 bedrock 0
fill ~1 ~-3 ~50 ~182 ~-3 ~50 bedrock 0
fill ~1 ~-3 ~51 ~182 ~-3 ~51 bedrock 0
fill ~1 ~-3 ~52 ~182 ~-3 ~52 bedrock 0
fill ~1 ~-3 ~53 ~182 ~-3 ~53 bedrock 0
fill ~1 ~-3 ~54 ~182 ~-3 ~54 bedrock 0
fill ~1 ~-3 ~55 ~182 ~-3 ~55 bedrock 0
fill ~1 ~-3 ~56 ~182 ~-3 ~56 bedrock 0
fill ~1 ~-3 ~57 ~182 ~-3 ~57 bedrock 0
fill ~1 ~-3 ~58 ~182 ~-3 ~58 bedrock 0
fill ~1 ~-3 ~59 ~182 ~-3 ~59 bedrock 0
fill ~1 ~-3 ~60 ~182 ~-3 ~60 bedrock 0
fill ~1 ~-3 ~61 ~182 ~-3 ~61 bedrock 0
fill ~1 ~-3 ~62 ~182 ~-3 ~62 bedrock 0
fill ~1 ~-3 ~63 ~88 ~-3 ~63 bedrock 0
fill ~1 ~-3 ~64 ~89 ~-3 ~64 bedrock 0
fill ~1 ~-3 ~65 ~182 ~-3 ~65 bedrock 0
fill ~1 ~-3 ~66 ~182 ~-3 ~66 bedrock 0
fill ~1 ~-3 ~67 ~182 ~-3 ~67 bedrock 0
fill ~1 ~-3 ~68 ~182 ~-3 ~68 bedrock 0
fill ~1 ~-3 ~69 ~182 ~-3 ~69 bedrock 0
fill ~1 ~-3 ~70 ~182 ~-3 ~70 bedrock 0
fill ~1 ~-3 ~71 ~182 ~-3 ~71 bedrock 0
fill ~1 ~-3 ~72 ~182 ~-3 ~72 bedrock 0
fill ~1 ~-3 ~73 ~182 ~-3 ~73 bedrock 0
fill ~1 ~-3 ~74 ~182 ~-3 ~74 bedrock 0
fill ~1 ~-3 ~75 ~182 ~-3 ~75 bedrock 0
fill ~1 ~-3 ~76 ~182 ~-3 ~76 bedrock 0
fill ~1 ~-3 ~77 ~182 ~-3 ~77 bedrock 0
fill ~1 ~-3 ~78 ~182 ~-3 ~78 bedrock 0
fill ~1 ~-3 ~79 ~182 ~-3 ~79 bedrock 0
fill ~1 ~-3 ~80 ~182 ~-3 ~80 bedrock 0
fill ~1 ~-3 ~81 ~182 ~-3 ~81 bedrock 0
fill ~1 ~-3 ~82 ~182 ~-3 ~82 bedrock 0
fill ~1 ~-3 ~83 ~182 ~-3 ~83 bedrock 0
fill ~1 ~-3 ~84 ~182 ~-3 ~84 bedrock 0
fill ~1 ~-3 ~85 ~182 ~-3 ~85 bedrock 0
fill ~1 ~-3 ~86 ~182 ~-3 ~86 bedrock 0
fill ~1 ~-3 ~87 ~182 ~-3 ~87 bedrock 0
fill ~1 ~-3 ~88 ~182 ~-3 ~88 bedrock 0
fill ~1 ~-3 ~89 ~182 ~-3 ~89 bedrock 0
fill ~1 ~-3 ~90 ~182 ~-3 ~90 bedrock 0
fill ~1 ~-3 ~91 ~182 ~-3 ~91 bedrock 0
fill ~1 ~-3 ~92 ~182 ~-3 ~92 bedrock 0
fill ~1 ~-3 ~93 ~182 ~-3 ~93 bedrock 0
fill ~1 ~-3 ~94 ~182 ~-3 ~94 bedrock 0
fill ~1 ~-3 ~95 ~182 ~-3 ~95 bedrock 0
fill ~1 ~-3 ~96 ~182 ~-3 ~96 bedrock 0
fill ~1 ~-3 ~97 ~182 ~-3 ~97 bedrock 0
fill ~1 ~-3 ~98 ~182 ~-3 ~98 bedrock 0
fill ~1 ~-3 ~99 ~182 ~-3 ~99 bedrock 0
fill ~1 ~-3 ~100 ~182 ~-3 ~100 bedrock 0
fill ~1 ~-3 ~101 ~182 ~-3 ~101 bedrock 0
fill ~1 ~-3 ~102 ~182 ~-3 ~102 bedrock 0
fill ~1 ~-3 ~103 ~182 ~-3 ~103 bedrock 0
fill ~1 ~-3 ~104 ~182 ~-3 ~104 bedrock 0
fill ~1 ~-3 ~105 ~182 ~-3 ~105 bedrock 0
fill ~1 ~-3 ~106 ~182 ~-3 ~106 bedrock 0
fill ~1 ~-3 ~107 ~182 ~-3 ~107 bedrock 0
fill ~1 ~-3 ~108 ~182 ~-3 ~108 bedrock 0
fill ~1 ~-3 ~109 ~182 ~-3 ~109 bedrock 0
fill ~1 ~-3 ~110 ~182 ~-3 ~110 bedrock 0
fill ~1 ~-3 ~111 ~182 ~-3 ~111 bedrock 0
fill ~1 ~-3 ~112 ~182 ~-3 ~112 bedrock 0
fill ~1 ~-3 ~113 ~182 ~-3 ~113 bedrock 0
fill ~1 ~-3 ~114 ~182 ~-3 ~114 bedrock 0
fill ~1 ~-3 ~115 ~182 ~-3 ~115 bedrock 0
fill ~1 ~-3 ~116 ~182 ~-3 ~116 bedrock 0
fill ~1 ~-3 ~117 ~182 ~-3 ~117 bedrock 0
fill ~1 ~-3 ~118 ~182 ~-3 ~118 bedrock 0
fill ~1 ~-3 ~119 ~182 ~-3 ~119 bedrock 0
fill ~1 ~-3 ~120 ~182 ~-3 ~120 bedrock 0
fill ~1 ~-3 ~121 ~182 ~-3 ~121 bedrock 0
fill ~1 ~-3 ~122 ~182 ~-3 ~122 bedrock 0
fill ~1 ~-3 ~123 ~182 ~-3 ~123 bedrock 0
fill ~1 ~-3 ~124 ~182 ~-3 ~124 bedrock 0
fill ~1 ~-3 ~125 ~182 ~-3 ~125 bedrock 0
fill ~1 ~-3 ~126 ~182 ~-3 ~126 bedrock 0
fill ~1 ~-3 ~127 ~182 ~-3 ~127 bedrock 0
fill ~1 ~-3 ~128 ~182 ~-3 ~128 bedrock 0
fill ~1 ~-3 ~129 ~182 ~-3 ~129 bedrock 0
fill ~1 ~-3 ~130 ~182 ~-3 ~130 bedrock 0
fill ~1 ~-3 ~131 ~182 ~-3 ~131 bedrock 0
fill ~1 ~-3 ~132 ~182 ~-3 ~132 bedrock 0
fill ~1 ~-3 ~133 ~182 ~-3 ~133 bedrock 0
fill ~1 ~-3 ~134 ~182 ~-3 ~134 bedrock 0
fill ~1 ~-3 ~135 ~182 ~-3 ~135 bedrock 0
fill ~1 ~-3 ~136 ~182 ~-3 ~136 bedrock 0
fill ~1 ~-3 ~137 ~182 ~-3 ~137 bedrock 0
fill ~1 ~-3 ~138 ~182 ~-3 ~138 bedrock 0
fill ~1 ~-3 ~139 ~182 ~-3 ~139 bedrock 0
fill ~1 ~-3 ~140 ~182 ~-3 ~140 bedrock 0
fill ~1 ~-3 ~141 ~182 ~-3 ~141 bedrock 0
fill ~1 ~-3 ~142 ~182 ~-3 ~142 bedrock 0
fill ~1 ~-3 ~143 ~182 ~-3 ~143 bedrock 0
fill ~1 ~-3 ~144 ~182 ~-3 ~144 bedrock 0
fill ~1 ~-3 ~145 ~182 ~-3 ~145 bedrock 0
fill ~1 ~-3 ~146 ~182 ~-3 ~146 bedrock 0
fill ~1 ~-3 ~147 ~182 ~-3 ~147 bedrock 0
fill ~1 ~-3 ~148 ~182 ~-3 ~148 bedrock 0
fill ~1 ~-3 ~149 ~182 ~-3 ~149 bedrock 0
fill ~1 ~-3 ~150 ~182 ~-3 ~150 bedrock 0
fill ~1 ~-3 ~151 ~182 ~-3 ~151 bedrock 0
fill ~89 ~-3 ~63 ~93 ~-3 ~63 stained_hardened_clay 13
fill ~90 ~-3 ~64 ~110 ~-3 ~64 stained_hardened_clay 13
setblock ~94 ~-3 ~63 bedrock 0
fill ~95 ~-3 ~63 ~101 ~-3 ~63 stained_hardened_clay 13
fill ~102 ~-3 ~63 ~103 ~-3 ~63 bedrock 0
fill ~104 ~-3 ~63 ~110 ~-3 ~63 stained_hardened_clay 13
fill ~111 ~-3 ~63 ~182 ~-3 ~63 bedrock 0
fill ~111 ~-3 ~64 ~182 ~-3 ~64 bedrock 0
fill ~85 ~-2 ~62 ~86 ~-2 ~62 stained_hardened_clay 13
fill ~85 ~-2 ~63 ~114 ~-2 ~63 stained_hardened_clay 13
fill ~88 ~-2 ~64 ~112 ~-2 ~64 stained_hardened_clay 13
fill ~95 ~-2 ~62 ~98 ~-2 ~62 stained_hardened_clay 13
fill ~111 ~-2 ~62 ~114 ~-2 ~62 stained_hardened_clay 13
fill ~83 ~-1 ~61 ~83 ~2 ~61 stained_hardened_clay 13
fill ~83 ~-1 ~62 ~116 ~-1 ~62 stained_hardened_clay 13
fill ~84 ~-1 ~63 ~95 ~-1 ~63 stained_hardened_clay 13
fill ~86 ~-1 ~64 ~113 ~-1 ~64 stained_hardened_clay 13
fill ~89 ~-1 ~65 ~91 ~-1 ~65 stained_hardened_clay 13
fill ~94 ~-1 ~61 ~96 ~-1 ~61 stained_hardened_clay 13
fill ~98 ~-1 ~63 ~115 ~-1 ~63 stained_hardened_clay 13
fill ~108 ~-1 ~65 ~111 ~-1 ~65 stained_hardened_clay 13
fill ~115 ~-1 ~61 ~116 ~-1 ~61 stained_hardened_clay 13
fill ~82 ~0 ~60 ~82 ~3 ~60 stained_hardened_clay 13
fill ~82 ~0 ~61 ~82 ~1 ~61 stained_hardened_clay 13
fill ~82 ~0 ~62 ~117 ~0 ~62 stained_hardened_clay 13
fill ~83 ~0 ~63 ~86 ~0 ~63 stained_hardened_clay 13
fill ~84 ~0 ~61 ~117 ~0 ~61 stained_hardened_clay 13
fill ~85 ~0 ~64 ~89 ~0 ~64 stained_hardened_clay 13
fill ~87 ~0 ~65 ~93 ~0 ~65 stained_hardened_clay 13
fill ~88 ~0 ~66 ~92 ~0 ~66 stained_hardened_clay 13
fill ~91 ~0 ~64 ~108 ~0 ~64 stained_hardened_clay 13
fill ~99 ~0 ~63 ~100 ~0 ~63 stained_hardened_clay 13
fill ~106 ~0 ~65 ~112 ~0 ~65 stained_hardened_clay 13
fill ~107 ~0 ~66 ~111 ~0 ~66 stained_hardened_clay 13
fill ~110 ~0 ~64 ~114 ~0 ~64 stained_hardened_clay 13
fill ~113 ~0 ~63 ~116 ~0 ~63 stained_hardened_clay 13
fill ~117 ~0 ~60 ~117 ~2 ~60 stained_hardened_clay 13
fill ~81 ~1 ~59 ~81 ~5 ~59 stained_hardened_clay 13
fill ~81 ~1 ~60 ~81 ~3 ~60 stained_hardened_clay 13
fill ~81 ~1 ~61 ~81 ~3 ~61 stained_hardened_clay 13
fill ~81 ~1 ~62 ~83 ~1 ~62 stained_hardened_clay 13
fill ~82 ~1 ~63 ~85 ~1 ~63 stained_hardened_clay 13
fill ~83 ~1 ~60 ~83 ~3 ~60 stained_hardened_clay 13
fill ~84 ~1 ~61 ~118 ~1 ~61 stained_hardened_clay 13
fill ~84 ~1 ~64 ~87 ~1 ~64 stained_hardened_clay 13
fill ~85 ~1 ~65 ~88 ~1 ~65 stained_hardened_clay 13
fill ~86 ~1 ~66 ~94 ~1 ~66 stained_hardened_clay 13
fill ~87 ~1 ~67 ~94 ~1 ~67 stained_hardened_clay 13
fill ~88 ~1 ~62 ~90 ~1 ~62 stained_hardened_clay 13
fill ~88 ~1 ~68 ~94 ~1 ~68 stained_hardened_clay 13
fill ~90 ~1 ~60 ~93 ~1 ~60 stained_hardened_clay 13
fill ~92 ~1 ~65 ~95 ~1 ~65 stained_hardened_clay 13
fill ~93 ~1 ~64 ~106 ~1 ~64 stained_hardened_clay 13
fill ~95 ~1 ~62 ~97 ~1 ~62 stained_hardened_clay 13
fill ~99 ~1 ~63 ~100 ~1 ~63 stained_hardened_clay 13
fill ~102 ~1 ~60 ~118 ~1 ~60 stained_hardened_clay 13
fill ~104 ~1 ~65 ~107 ~1 ~65 stained_hardened_clay 13
fill ~105 ~1 ~66 ~113 ~1 ~66 stained_hardened_clay 13
fill ~105 ~1 ~67 ~112 ~1 ~67 stained_hardened_clay 13
fill ~105 ~1 ~68 ~111 ~1 ~68 stained_hardened_clay 13
fill ~111 ~1 ~65 ~114 ~1 ~65 stained_hardened_clay 13
fill ~112 ~1 ~64 ~115 ~1 ~64 stained_hardened_clay 13
fill ~114 ~1 ~63 ~117 ~1 ~63 stained_hardened_clay 13
fill ~116 ~1 ~62 ~118 ~1 ~62 stained_hardened_clay 13
fill ~118 ~1 ~59 ~118 ~3 ~59 stained_hardened_clay 13
fill ~80 ~2 ~59 ~80 ~5 ~59 stained_hardened_clay 13
fill ~80 ~2 ~60 ~80 ~5 ~60 stained_hardened_clay 13
fill ~81 ~2 ~62 ~82 ~2 ~62 stained_hardened_clay 13
fill ~82 ~2 ~63 ~84 ~2 ~63 stained_hardened_clay 13
fill ~84 ~2 ~60 ~119 ~2 ~60 stained_hardened_clay 13
fill ~84 ~2 ~61 ~90 ~2 ~61 stained_hardened_clay 13
fill ~84 ~2 ~64 ~85 ~2 ~64 stained_hardened_clay 13
fill ~84 ~2 ~65 ~86 ~2 ~65 stained_hardened_clay 13
fill ~85 ~2 ~66 ~87 ~2 ~66 stained_hardened_clay 13
fill ~85 ~2 ~67 ~88 ~2 ~67 stained_hardened_clay 13
fill ~86 ~2 ~68 ~97 ~2 ~68 stained_hardened_clay 13
fill ~88 ~2 ~69 ~97 ~2 ~69 stained_hardened_clay 13
fill ~89 ~2 ~59 ~90 ~2 ~59 stained_hardened_clay 13
fill ~89 ~2 ~70 ~96 ~2 ~70 stained_hardened_clay 13
fill ~91 ~2 ~71 ~92 ~2 ~71 stained_hardened_clay 13
fill ~92 ~2 ~61 ~103 ~2 ~61 stained_hardened_clay 13
fill ~94 ~2 ~65 ~105 ~2 ~65 stained_hardened_clay 13
fill ~94 ~2 ~66 ~97 ~2 ~66 stained_hardened_clay 13
fill ~94 ~2 ~67 ~97 ~2 ~67 stained_hardened_clay 13
fill ~95 ~2 ~64 ~104 ~2 ~64 stained_hardened_clay 13
fill ~102 ~2 ~67 ~105 ~2 ~67 stained_hardened_clay 13
fill ~102 ~2 ~68 ~113 ~2 ~68 stained_hardened_clay 13
fill ~102 ~2 ~69 ~111 ~2 ~69 stained_hardened_clay 13
fill ~103 ~2 ~66 ~105 ~2 ~66 stained_hardened_clay 13
fill ~103 ~2 ~70 ~110 ~2 ~70 stained_hardened_clay 13
fill ~107 ~2 ~59 ~119 ~2 ~59 stained_hardened_clay 13
fill ~107 ~2 ~71 ~108 ~2 ~71 stained_hardened_clay 13
fill ~111 ~2 ~67 ~114 ~2 ~67 stained_hardened_clay 13
fill ~112 ~2 ~66 ~114 ~2 ~66 stained_hardened_clay 13
fill ~113 ~2 ~65 ~115 ~2 ~65 stained_hardened_clay 13
fill ~114 ~2 ~64 ~115 ~2 ~64 stained_hardened_clay 13
fill ~115 ~2 ~63 ~117 ~2 ~63 stained_hardened_clay 13
fill ~117 ~2 ~62 ~118 ~2 ~62 stained_hardened_clay 13
fill ~118 ~2 ~61 ~119 ~2 ~61 stained_hardened_clay 13
fill ~79 ~3 ~58 ~80 ~3 ~58 stained_hardened_clay 13
fill ~79 ~3 ~59 ~79 ~7 ~59 stained_hardened_clay 13
fill ~80 ~3 ~61 ~80 ~5 ~61 stained_hardened_clay 13
fill ~80 ~3 ~62 ~82 ~3 ~62 stained_hardened_clay 13
fill ~81 ~3 ~63 ~84 ~3 ~63 stained_hardened_clay 13
fill ~82 ~3 ~59 ~119 ~3 ~59 stained_hardened_clay 13
fill ~83 ~3 ~64 ~85 ~3 ~64 stained_hardened_clay 13
fill ~84 ~3 ~60 ~107 ~3 ~60 stained_hardened_clay 13
fill ~84 ~3 ~65 ~85 ~3 ~65 stained_hardened_clay 13
fill ~84 ~3 ~66 ~86 ~3 ~66 stained_hardened_clay 13
fill ~85 ~3 ~67 ~86 ~3 ~67 stained_hardened_clay 13
fill ~85 ~3 ~68 ~88 ~3 ~68 stained_hardened_clay 13
fill ~86 ~3 ~69 ~89 ~3 ~69 stained_hardened_clay 13
fill ~87 ~3 ~70 ~112 ~3 ~70 stained_hardened_clay 13
fill ~88 ~3 ~71 ~97 ~3 ~71 stained_hardened_clay 13
fill ~90 ~3 ~72 ~94 ~3 ~72 stained_hardened_clay 13
fill ~96 ~3 ~65 ~103 ~3 ~65 stained_hardened_clay 13
fill ~96 ~3 ~66 ~103 ~3 ~66 stained_hardened_clay 13
fill ~96 ~3 ~67 ~103 ~3 ~67 stained_hardened_clay 13
fill ~96 ~3 ~69 ~103 ~3 ~69 stained_hardened_clay 13
fill ~97 ~3 ~64 ~98 ~3 ~64 stained_hardened_clay 13
fill ~97 ~3 ~68 ~102 ~3 ~68 stained_hardened_clay 13
fill ~101 ~3 ~64 ~102 ~3 ~64 stained_hardened_clay 13
fill ~102 ~3 ~71 ~111 ~3 ~71 stained_hardened_clay 13
fill ~105 ~3 ~72 ~110 ~3 ~72 stained_hardened_clay 13
fill ~108 ~3 ~58 ~120 ~3 ~58 stained_hardened_clay 13
fill ~110 ~3 ~69 ~113 ~3 ~69 stained_hardened_clay 13
fill ~111 ~3 ~68 ~114 ~3 ~68 stained_hardened_clay 13
fill ~113 ~3 ~67 ~115 ~3 ~67 stained_hardened_clay 13
fill ~114 ~3 ~65 ~115 ~3 ~65 stained_hardened_clay 13
fill ~114 ~3 ~66 ~115 ~3 ~66 stained_hardened_clay 13
fill ~115 ~3 ~63 ~118 ~3 ~63 stained_hardened_clay 13
fill ~115 ~3 ~64 ~116 ~3 ~64 stained_hardened_clay 13
fill ~117 ~3 ~62 ~119 ~3 ~62 stained_hardened_clay 13
fill ~118 ~3 ~61 ~119 ~3 ~61 stained_hardened_clay 13
fill ~119 ~3 ~60 ~119 ~4 ~60 stained_hardened_clay 13
fill ~78 ~4 ~57 ~79 ~4 ~57 stained_hardened_clay 13
fill ~78 ~4 ~58 ~82 ~4 ~58 stained_hardened_clay 13
fill ~78 ~4 ~59 ~78 ~4 ~57 stained_hardened_clay 13
fill ~79 ~4 ~60 ~79 ~7 ~60 stained_hardened_clay 13
fill ~79 ~4 ~61 ~79 ~7 ~61 stained_hardened_clay 13
fill ~80 ~4 ~62 ~81 ~4 ~62 stained_hardened_clay 13
fill ~80 ~4 ~63 ~83 ~4 ~63 stained_hardened_clay 13
fill ~82 ~4 ~59 ~108 ~4 ~59 stained_hardened_clay 13
fill ~82 ~4 ~64 ~84 ~4 ~64 stained_hardened_clay 13
fill ~83 ~4 ~65 ~84 ~4 ~65 stained_hardened_clay 13
fill ~83 ~4 ~66 ~85 ~4 ~66 stained_hardened_clay 13
fill ~84 ~4 ~67 ~85 ~4 ~67 stained_hardened_clay 13
fill ~84 ~4 ~68 ~86 ~4 ~68 stained_hardened_clay 13
fill ~85 ~4 ~58 ~87 ~4 ~58 stained_hardened_clay 13
fill ~85 ~4 ~69 ~87 ~4 ~69 stained_hardened_clay 13
fill ~86 ~4 ~70 ~88 ~4 ~70 stained_hardened_clay 13
fill ~87 ~4 ~71 ~90 ~4 ~71 stained_hardened_clay 13
fill ~88 ~4 ~72 ~97 ~4 ~72 stained_hardened_clay 13
fill ~90 ~4 ~73 ~94 ~4 ~73 stained_hardened_clay 13
fill ~91 ~4 ~58 ~120 ~4 ~58 stained_hardened_clay 13
fill ~94 ~4 ~71 ~105 ~4 ~71 stained_hardened_clay 13
fill ~97 ~4 ~70 ~102 ~4 ~70 stained_hardened_clay 13
fill ~102 ~4 ~72 ~112 ~4 ~72 stained_hardened_clay 13
fill ~105 ~4 ~73 ~110 ~4 ~73 stained_hardened_clay 13
fill ~109 ~4 ~57 ~121 ~4 ~57 stained_hardened_clay 13
fill ~109 ~4 ~71 ~113 ~4 ~71 stained_hardened_clay 13
fill ~111 ~4 ~70 ~113 ~4 ~70 stained_hardened_clay 13
fill ~112 ~4 ~69 ~114 ~4 ~69 stained_hardened_clay 13
fill ~113 ~4 ~68 ~115 ~4 ~68 stained_hardened_clay 13
fill ~114 ~4 ~67 ~115 ~4 ~67 stained_hardened_clay 13
fill ~115 ~4 ~64 ~117 ~4 ~64 stained_hardened_clay 13
fill ~115 ~4 ~65 ~116 ~4 ~65 stained_hardened_clay 13
fill ~115 ~4 ~66 ~116 ~4 ~66 stained_hardened_clay 13
fill ~116 ~4 ~63 ~119 ~4 ~63 stained_hardened_clay 13
fill ~118 ~4 ~62 ~120 ~4 ~62 stained_hardened_clay 13
fill ~119 ~4 ~59 ~120 ~4 ~59 stained_hardened_clay 13
fill ~119 ~4 ~61 ~120 ~4 ~61 stained_hardened_clay 13
fill ~120 ~4 ~60 ~120 ~7 ~60 stained_hardened_clay 13
fill ~76 ~5 ~56 ~78 ~5 ~56 stained_hardened_clay 13
fill ~77 ~5 ~57 ~79 ~5 ~57 stained_hardened_clay 13
fill ~77 ~5 ~58 ~109 ~5 ~58 stained_hardened_clay 13
fill ~79 ~5 ~62 ~80 ~5 ~62 stained_hardened_clay 13
fill ~80 ~5 ~63 ~82 ~5 ~63 stained_hardened_clay 13
fill ~81 ~5 ~64 ~83 ~5 ~64 stained_hardened_clay 13
fill ~82 ~5 ~59 ~85 ~5 ~59 stained_hardened_clay 13
fill ~82 ~5 ~65 ~83 ~5 ~65 stained_hardened_clay 13
fill ~83 ~5 ~66 ~84 ~5 ~66 stained_hardened_clay 13
fill ~83 ~5 ~67 ~84 ~5 ~67 stained_hardened_clay 13
fill ~84 ~5 ~57 ~85 ~5 ~57 stained_hardened_clay 13
fill ~84 ~5 ~68 ~85 ~5 ~68 stained_hardened_clay 13
fill ~84 ~5 ~69 ~86 ~5 ~69 stained_hardened_clay 13
fill ~85 ~5 ~70 ~87 ~5 ~70 stained_hardened_clay 13
fill ~86 ~5 ~71 ~88 ~5 ~71 stained_hardened_clay 13
fill ~86 ~5 ~72 ~90 ~5 ~72 stained_hardened_clay 13
fill ~87 ~5 ~59 ~94 ~5 ~59 stained_hardened_clay 13
fill ~88 ~5 ~73 ~96 ~5 ~73 stained_hardened_clay 13
fill ~90 ~5 ~74 ~94 ~5 ~74 stained_hardened_clay 13
fill ~94 ~5 ~72 ~105 ~5 ~72 stained_hardened_clay 13
fill ~97 ~5 ~71 ~103 ~5 ~71 stained_hardened_clay 13
fill ~98 ~5 ~57 ~122 ~5 ~57 stained_hardened_clay 13
fill ~103 ~5 ~73 ~112 ~5 ~73 stained_hardened_clay 13
fill ~105 ~5 ~74 ~109 ~5 ~74 stained_hardened_clay 13
fill ~109 ~5 ~72 ~113 ~5 ~72 stained_hardened_clay 13
fill ~110 ~5 ~56 ~123 ~5 ~56 stained_hardened_clay 13
fill ~112 ~5 ~70 ~114 ~5 ~70 stained_hardened_clay 13
fill ~112 ~5 ~71 ~113 ~5 ~71 stained_hardened_clay 13
fill ~113 ~5 ~69 ~115 ~5 ~69 stained_hardened_clay 13
fill ~114 ~5 ~68 ~116 ~5 ~68 stained_hardened_clay 13
fill ~115 ~5 ~66 ~116 ~5 ~66 stained_hardened_clay 13
fill ~115 ~5 ~67 ~116 ~5 ~67 stained_hardened_clay 13
fill ~116 ~5 ~64 ~118 ~5 ~64 stained_hardened_clay 13
fill ~116 ~5 ~65 ~117 ~5 ~65 stained_hardened_clay 13
fill ~117 ~5 ~63 ~120 ~5 ~63 stained_hardened_clay 13
fill ~119 ~5 ~62 ~120 ~5 ~62 stained_hardened_clay 13
fill ~120 ~5 ~58 ~121 ~5 ~58 stained_hardened_clay 13
fill ~120 ~5 ~59 ~120 ~7 ~59 stained_hardened_clay 13
fill ~120 ~5 ~61 ~120 ~7 ~61 stained_hardened_clay 13
fill ~74 ~6 ~56 ~77 ~6 ~56 stained_hardened_clay 13
fill ~76 ~6 ~57 ~111 ~6 ~57 stained_hardened_clay 13
fill ~77 ~6 ~58 ~98 ~6 ~58 stained_hardened_clay 13
fill ~78 ~6 ~59 ~78 ~9 ~59 stained_hardened_clay 13
fill ~79 ~6 ~62 ~80 ~6 ~62 stained_hardened_clay 13
fill ~79 ~6 ~63 ~81 ~6 ~63 stained_hardened_clay 13
fill ~81 ~6 ~64 ~82 ~6 ~64 stained_hardened_clay 13
fill ~82 ~6 ~65 ~83 ~6 ~65 stained_hardened_clay 13
fill ~82 ~6 ~66 ~83 ~6 ~66 stained_hardened_clay 13
fill ~82 ~6 ~67 ~84 ~6 ~67 stained_hardened_clay 13
fill ~83 ~6 ~68 ~85 ~6 ~68 stained_hardened_clay 13
fill ~84 ~6 ~69 ~85 ~6 ~69 stained_hardened_clay 13
fill ~85 ~6 ~70 ~86 ~6 ~70 stained_hardened_clay 13
fill ~85 ~6 ~71 ~86 ~6 ~71 stained_hardened_clay 13
fill ~86 ~6 ~72 ~88 ~6 ~72 stained_hardened_clay 13
fill ~87 ~6 ~73 ~91 ~6 ~73 stained_hardened_clay 13
fill ~88 ~6 ~74 ~95 ~6 ~74 stained_hardened_clay 13
fill ~94 ~6 ~73 ~98 ~6 ~73 stained_hardened_clay 13
fill ~96 ~6 ~72 ~103 ~6 ~72 stained_hardened_clay 13
fill ~99 ~6 ~56 ~125 ~6 ~56 stained_hardened_clay 13
fill ~102 ~6 ~73 ~106 ~6 ~73 stained_hardened_clay 13
fill ~104 ~6 ~74 ~111 ~6 ~74 stained_hardened_clay 13
fill ~109 ~6 ~73 ~112 ~6 ~73 stained_hardened_clay 13
fill ~111 ~6 ~72 ~113 ~6 ~72 stained_hardened_clay 13
fill ~113 ~6 ~70 ~115 ~6 ~70 stained_hardened_clay 13
fill ~113 ~6 ~71 ~114 ~6 ~71 stained_hardened_clay 13
fill ~114 ~6 ~69 ~115 ~6 ~69 stained_hardened_clay 13
fill ~115 ~6 ~68 ~116 ~6 ~68 stained_hardened_clay 13
fill ~116 ~6 ~65 ~117 ~6 ~65 stained_hardened_clay 13
fill ~116 ~6 ~66 ~117 ~6 ~66 stained_hardened_clay 13
fill ~116 ~6 ~67 ~117 ~6 ~67 stained_hardened_clay 13
fill ~117 ~6 ~64 ~118 ~6 ~64 stained_hardened_clay 13
fill ~118 ~6 ~63 ~120 ~6 ~63 stained_hardened_clay 13
fill ~119 ~6 ~62 ~120 ~6 ~62 stained_hardened_clay 13
fill ~120 ~6 ~58 ~121 ~6 ~58 stained_hardened_clay 13
fill ~121 ~6 ~57 ~123 ~6 ~57 stained_hardened_clay 13
fill ~121 ~6 ~59 ~121 ~9 ~59 stained_hardened_clay 13
fill ~121 ~6 ~60 ~121 ~9 ~60 stained_hardened_clay 13
fill ~72 ~7 ~56 ~78 ~7 ~56 stained_hardened_clay 13
fill ~73 ~7 ~55 ~76 ~7 ~55 stained_hardened_clay 13
fill ~73 ~7 ~57 ~99 ~7 ~57 stained_hardened_clay 13
fill ~77 ~7 ~58 ~78 ~7 ~58 stained_hardened_clay 13
fill ~78 ~7 ~60 ~78 ~9 ~60 stained_hardened_clay 13
fill ~78 ~7 ~61 ~78 ~10 ~61 stained_hardened_clay 13
fill ~78 ~7 ~62 ~79 ~7 ~62 stained_hardened_clay 13
fill ~79 ~7 ~63 ~81 ~7 ~63 stained_hardened_clay 13
fill ~80 ~7 ~56 ~127 ~7 ~56 stained_hardened_clay 13
fill ~80 ~7 ~64 ~82 ~7 ~64 stained_hardened_clay 13
fill ~82 ~7 ~65 ~82 ~8 ~65 stained_hardened_clay 13
fill ~82 ~7 ~66 ~82 ~8 ~66 stained_hardened_clay 13
fill ~82 ~7 ~67 ~83 ~7 ~67 stained_hardened_clay 13
fill ~82 ~7 ~68 ~84 ~7 ~68 stained_hardened_clay 13
fill ~83 ~7 ~69 ~85 ~7 ~69 stained_hardened_clay 13
fill ~84 ~7 ~70 ~85 ~7 ~70 stained_hardened_clay 13
fill ~85 ~7 ~71 ~86 ~7 ~71 stained_hardened_clay 13
fill ~85 ~7 ~72 ~87 ~7 ~72 stained_hardened_clay 13
fill ~86 ~7 ~73 ~88 ~7 ~73 stained_hardened_clay 13
fill ~87 ~7 ~74 ~96 ~7 ~74 stained_hardened_clay 13
fill ~90 ~7 ~75 ~94 ~7 ~75 stained_hardened_clay 13
fill ~95 ~7 ~73 ~104 ~7 ~73 stained_hardened_clay 13
fill ~97 ~7 ~72 ~102 ~7 ~72 stained_hardened_clay 13
fill ~100 ~7 ~55 ~117 ~7 ~55 stained_hardened_clay 13
fill ~103 ~7 ~74 ~112 ~7 ~74 stained_hardened_clay 13
fill ~105 ~7 ~75 ~110 ~7 ~75 stained_hardened_clay 13
fill ~111 ~7 ~73 ~113 ~7 ~73 stained_hardened_clay 13
fill ~112 ~7 ~72 ~114 ~7 ~72 stained_hardened_clay 13
fill ~113 ~7 ~71 ~115 ~7 ~71 stained_hardened_clay 13
fill ~114 ~7 ~70 ~115 ~7 ~70 stained_hardened_clay 13
fill ~115 ~7 ~68 ~117 ~7 ~68 stained_hardened_clay 13
fill ~115 ~7 ~69 ~116 ~7 ~69 stained_hardened_clay 13
fill ~116 ~7 ~67 ~117 ~7 ~67 stained_hardened_clay 13
fill ~117 ~7 ~64 ~119 ~7 ~64 stained_hardened_clay 13
fill ~117 ~7 ~65 ~118 ~7 ~65 stained_hardened_clay 13
fill ~117 ~7 ~66 ~117 ~8 ~66 stained_hardened_clay 13
fill ~118 ~7 ~63 ~120 ~7 ~63 stained_hardened_clay 13
fill ~120 ~7 ~62 ~121 ~7 ~62 stained_hardened_clay 13
fill ~121 ~7 ~57 ~126 ~7 ~57 stained_hardened_clay 13
fill ~121 ~7 ~58 ~122 ~7 ~58 stained_hardened_clay 13
fill ~121 ~7 ~61 ~121 ~10 ~61 stained_hardened_clay 13
fill ~72 ~8 ~55 ~75 ~8 ~55 stained_hardened_clay 13
fill ~72 ~8 ~56 ~101 ~8 ~56 stained_hardened_clay 13
fill ~73 ~8 ~57 ~84 ~8 ~57 stained_hardened_clay 13
fill ~76 ~8 ~58 ~78 ~8 ~58 stained_hardened_clay 13
fill ~77 ~8 ~59 ~77 ~10 ~59 stained_hardened_clay 13
fill ~78 ~8 ~62 ~79 ~8 ~62 stained_hardened_clay 13
fill ~79 ~8 ~55 ~79 ~10 ~55 stained_hardened_clay 13
fill ~79 ~8 ~63 ~80 ~8 ~63 stained_hardened_clay 13
fill ~80 ~8 ~64 ~82 ~8 ~64 stained_hardened_clay 13
fill ~81 ~8 ~65 ~81 ~11 ~65 stained_hardened_clay 13
fill ~81 ~8 ~66 ~81 ~11 ~66 stained_hardened_clay 13
fill ~81 ~8 ~67 ~82 ~8 ~67 stained_hardened_clay 13
fill ~82 ~8 ~68 ~83 ~8 ~68 stained_hardened_clay 13
fill ~82 ~8 ~69 ~84 ~8 ~69 stained_hardened_clay 13
fill ~83 ~8 ~70 ~85 ~8 ~70 stained_hardened_clay 13
fill ~84 ~8 ~71 ~85 ~8 ~71 stained_hardened_clay 13
fill ~85 ~8 ~72 ~86 ~8 ~72 stained_hardened_clay 13
fill ~85 ~8 ~73 ~87 ~8 ~73 stained_hardened_clay 13
fill ~86 ~8 ~74 ~90 ~8 ~74 stained_hardened_clay 13
fill ~88 ~8 ~75 ~95 ~8 ~75 stained_hardened_clay 13
fill ~89 ~8 ~55 ~128 ~8 ~55 stained_hardened_clay 13
fill ~94 ~8 ~74 ~97 ~8 ~74 stained_hardened_clay 13
fill ~96 ~8 ~73 ~103 ~8 ~73 stained_hardened_clay 13
fill ~102 ~8 ~74 ~105 ~8 ~74 stained_hardened_clay 13
fill ~104 ~8 ~75 ~111 ~8 ~75 stained_hardened_clay 13
fill ~109 ~8 ~74 ~113 ~8 ~74 stained_hardened_clay 13
fill ~112 ~8 ~73 ~114 ~8 ~73 stained_hardened_clay 13
fill ~113 ~8 ~72 ~115 ~8 ~72 stained_hardened_clay 13
fill ~114 ~8 ~70 ~116 ~8 ~70 stained_hardened_clay 13
fill ~114 ~8 ~71 ~115 ~8 ~71 stained_hardened_clay 13
fill ~115 ~8 ~69 ~117 ~8 ~69 stained_hardened_clay 13
fill ~116 ~8 ~68 ~118 ~8 ~68 stained_hardened_clay 13
fill ~117 ~8 ~56 ~127 ~8 ~56 stained_hardened_clay 13
fill ~117 ~8 ~65 ~118 ~8 ~65 stained_hardened_clay 13
fill ~117 ~8 ~67 ~118 ~8 ~67 stained_hardened_clay 13
fill ~118 ~8 ~64 ~119 ~8 ~64 stained_hardened_clay 13
fill ~118 ~8 ~66 ~118 ~11 ~66 stained_hardened_clay 13
fill ~119 ~8 ~63 ~120 ~8 ~63 stained_hardened_clay 13
fill ~120 ~8 ~62 ~121 ~8 ~62 stained_hardened_clay 13
fill ~121 ~8 ~58 ~123 ~8 ~58 stained_hardened_clay 13
fill ~122 ~8 ~57 ~126 ~8 ~57 stained_hardened_clay 13
fill ~122 ~8 ~59 ~122 ~10 ~59 stained_hardened_clay 13
fill ~71 ~9 ~54 ~74 ~9 ~54 stained_hardened_clay 13
fill ~71 ~9 ~55 ~128 ~9 ~55 stained_hardened_clay 13
fill ~72 ~9 ~56 ~89 ~9 ~56 stained_hardened_clay 13
fill ~73 ~9 ~57 ~76 ~9 ~57 stained_hardened_clay 13
fill ~74 ~9 ~58 ~77 ~9 ~58 stained_hardened_clay 13
fill ~76 ~9 ~59 ~76 ~11 ~59 stained_hardened_clay 13
fill ~77 ~9 ~60 ~77 ~11 ~60 stained_hardened_clay 13
fill ~77 ~9 ~61 ~77 ~12 ~61 stained_hardened_clay 13
fill ~78 ~9 ~62 ~79 ~9 ~62 stained_hardened_clay 13
fill ~78 ~9 ~63 ~80 ~9 ~63 stained_hardened_clay 13
fill ~80 ~9 ~64 ~81 ~9 ~64 stained_hardened_clay 13
fill ~81 ~9 ~67 ~82 ~9 ~67 stained_hardened_clay 13
fill ~81 ~9 ~68 ~82 ~9 ~68 stained_hardened_clay 13
fill ~82 ~9 ~69 ~83 ~9 ~69 stained_hardened_clay 13
fill ~83 ~9 ~70 ~84 ~9 ~70 stained_hardened_clay 13
fill ~83 ~9 ~71 ~85 ~9 ~71 stained_hardened_clay 13
fill ~84 ~9 ~72 ~85 ~9 ~72 stained_hardened_clay 13
fill ~85 ~9 ~73 ~86 ~9 ~73 stained_hardened_clay 13
fill ~86 ~9 ~74 ~88 ~9 ~74 stained_hardened_clay 13
fill ~87 ~9 ~75 ~96 ~9 ~75 stained_hardened_clay 13
fill ~90 ~9 ~54 ~106 ~9 ~54 stained_hardened_clay 13
fill ~90 ~9 ~76 ~94 ~9 ~76 stained_hardened_clay 13
fill ~95 ~9 ~74 ~99 ~9 ~74 stained_hardened_clay 13
fill ~97 ~9 ~73 ~102 ~9 ~73 stained_hardened_clay 13
fill ~101 ~9 ~74 ~104 ~9 ~74 stained_hardened_clay 13
fill ~103 ~9 ~75 ~112 ~9 ~75 stained_hardened_clay 13
fill ~106 ~9 ~76 ~109 ~9 ~76 stained_hardened_clay 13
fill ~110 ~9 ~54 ~128 ~9 ~54 stained_hardened_clay 13
fill ~111 ~9 ~74 ~113 ~9 ~74 stained_hardened_clay 13
fill ~113 ~9 ~73 ~114 ~9 ~73 stained_hardened_clay 13
fill ~114 ~9 ~72 ~115 ~9 ~72 stained_hardened_clay 13
fill ~115 ~9 ~70 ~117 ~9 ~70 stained_hardened_clay 13
fill ~115 ~9 ~71 ~116 ~9 ~71 stained_hardened_clay 13
fill ~116 ~9 ~69 ~117 ~9 ~69 stained_hardened_clay 13
fill ~117 ~9 ~68 ~118 ~9 ~68 stained_hardened_clay 13
fill ~118 ~9 ~64 ~119 ~9 ~64 stained_hardened_clay 13
fill ~118 ~9 ~65 ~119 ~9 ~65 stained_hardened_clay 13
fill ~118 ~9 ~67 ~118 ~11 ~67 stained_hardened_clay 13
fill ~119 ~9 ~63 ~121 ~9 ~63 stained_hardened_clay 13
fill ~120 ~9 ~62 ~121 ~9 ~62 stained_hardened_clay 13
fill ~122 ~9 ~58 ~125 ~9 ~58 stained_hardened_clay 13
fill ~122 ~9 ~60 ~122 ~11 ~60 stained_hardened_clay 13
fill ~122 ~9 ~61 ~122 ~11 ~61 stained_hardened_clay 13
fill ~123 ~9 ~57 ~127 ~9 ~57 stained_hardened_clay 13
fill ~123 ~9 ~59 ~123 ~11 ~59 stained_hardened_clay 13
fill ~126 ~9 ~56 ~127 ~9 ~56 stained_hardened_clay 13
fill ~70 ~10 ~53 ~70 ~15 ~53 stained_hardened_clay 13
fill ~70 ~10 ~54 ~129 ~10 ~54 stained_hardened_clay 13
fill ~71 ~10 ~55 ~91 ~10 ~55 stained_hardened_clay 13
fill ~72 ~10 ~56 ~73 ~10 ~56 stained_hardened_clay 13
fill ~72 ~10 ~57 ~74 ~10 ~57 stained_hardened_clay 13
fill ~73 ~10 ~58 ~76 ~10 ~58 stained_hardened_clay 13
fill ~75 ~10 ~59 ~75 ~12 ~59 stained_hardened_clay 13
fill ~76 ~10 ~60 ~76 ~12 ~60 stained_hardened_clay 13
fill ~77 ~10 ~62 ~79 ~10 ~62 stained_hardened_clay 13
fill ~78 ~10 ~63 ~80 ~10 ~63 stained_hardened_clay 13
fill ~80 ~10 ~64 ~81 ~10 ~64 stained_hardened_clay 13
fill ~80 ~10 ~65 ~80 ~15 ~65 stained_hardened_clay 13
fill ~81 ~10 ~67 ~81 ~12 ~67 stained_hardened_clay 13
fill ~81 ~10 ~68 ~82 ~10 ~68 stained_hardened_clay 13
fill ~81 ~10 ~69 ~83 ~10 ~69 stained_hardened_clay 13
fill ~82 ~10 ~70 ~83 ~10 ~70 stained_hardened_clay 13
fill ~83 ~10 ~71 ~84 ~10 ~71 stained_hardened_clay 13
fill ~83 ~10 ~72 ~85 ~10 ~72 stained_hardened_clay 13
fill ~84 ~10 ~73 ~86 ~10 ~73 stained_hardened_clay 13
fill ~85 ~10 ~74 ~87 ~10 ~74 stained_hardened_clay 13
fill ~86 ~10 ~75 ~90 ~10 ~75 stained_hardened_clay 13
fill ~89 ~10 ~76 ~94 ~10 ~76 stained_hardened_clay 13
fill ~93 ~10 ~75 ~97 ~10 ~75 stained_hardened_clay 13
fill ~96 ~10 ~74 ~103 ~10 ~74 stained_hardened_clay 13
fill ~98 ~10 ~73 ~101 ~10 ~73 stained_hardened_clay 13
fill ~103 ~10 ~75 ~106 ~10 ~75 stained_hardened_clay 13
fill ~105 ~10 ~76 ~111 ~10 ~76 stained_hardened_clay 13
fill ~106 ~10 ~55 ~111 ~10 ~55 stained_hardened_clay 13
fill ~109 ~10 ~75 ~113 ~10 ~75 stained_hardened_clay 13
fill ~112 ~10 ~74 ~114 ~10 ~74 stained_hardened_clay 13
fill ~113 ~10 ~73 ~115 ~10 ~73 stained_hardened_clay 13
fill ~114 ~10 ~72 ~116 ~10 ~72 stained_hardened_clay 13
fill ~115 ~10 ~71 ~116 ~10 ~71 stained_hardened_clay 13
fill ~116 ~10 ~69 ~118 ~10 ~69 stained_hardened_clay 13
fill ~116 ~10 ~70 ~117 ~10 ~70 stained_hardened_clay 13
fill ~117 ~10 ~53 ~129 ~10 ~53 stained_hardened_clay 13
fill ~117 ~10 ~68 ~118 ~10 ~68 stained_hardened_clay 13
fill ~118 ~10 ~64 ~120 ~10 ~64 stained_hardened_clay 13
fill ~118 ~10 ~65 ~119 ~10 ~65 stained_hardened_clay 13
fill ~119 ~10 ~63 ~121 ~10 ~63 stained_hardened_clay 13
fill ~119 ~10 ~66 ~119 ~15 ~66 stained_hardened_clay 13
fill ~121 ~10 ~62 ~122 ~10 ~62 stained_hardened_clay 13
fill ~123 ~10 ~58 ~126 ~10 ~58 stained_hardened_clay 13
fill ~123 ~10 ~60 ~123 ~12 ~60 stained_hardened_clay 13
fill ~124 ~10 ~59 ~124 ~12 ~59 stained_hardened_clay 13
fill ~125 ~10 ~57 ~127 ~10 ~57 stained_hardened_clay 13
fill ~126 ~10 ~56 ~127 ~10 ~56 stained_hardened_clay 13
fill ~127 ~10 ~55 ~128 ~10 ~55 stained_hardened_clay 13
fill ~69 ~11 ~53 ~69 ~29 ~53 stained_hardened_clay 13
fill ~70 ~11 ~54 ~121 ~11 ~54 stained_hardened_clay 13
fill ~71 ~11 ~53 ~72 ~11 ~53 stained_hardened_clay 13
fill ~71 ~11 ~55 ~72 ~11 ~55 stained_hardened_clay 13
fill ~72 ~11 ~56 ~72 ~13 ~56 stained_hardened_clay 13
fill ~72 ~11 ~57 ~73 ~11 ~57 stained_hardened_clay 13
fill ~73 ~11 ~58 ~75 ~11 ~58 stained_hardened_clay 13
fill ~74 ~11 ~55 ~77 ~11 ~55 stained_hardened_clay 13
fill ~74 ~11 ~59 ~74 ~12 ~59 stained_hardened_clay 13
fill ~75 ~11 ~60 ~75 ~13 ~60 stained_hardened_clay 13
fill ~76 ~11 ~61 ~76 ~13 ~61 stained_hardened_clay 13
fill ~77 ~11 ~62 ~78 ~11 ~62 stained_hardened_clay 13
fill ~78 ~11 ~63 ~80 ~11 ~63 stained_hardened_clay 13
fill ~79 ~11 ~64 ~80 ~11 ~64 stained_hardened_clay 13
fill ~80 ~11 ~53 ~131 ~11 ~53 stained_hardened_clay 13
fill ~80 ~11 ~66 ~80 ~16 ~66 stained_hardened_clay 13
fill ~80 ~11 ~67 ~80 ~19 ~67 stained_hardened_clay 13
fill ~81 ~11 ~68 ~81 ~19 ~68 stained_hardened_clay 13
fill ~81 ~11 ~69 ~82 ~11 ~69 stained_hardened_clay 13
fill ~82 ~11 ~70 ~83 ~11 ~70 stained_hardened_clay 13
fill ~82 ~11 ~71 ~83 ~11 ~71 stained_hardened_clay 13
fill ~83 ~11 ~72 ~84 ~11 ~72 stained_hardened_clay 13
fill ~84 ~11 ~73 ~85 ~11 ~73 stained_hardened_clay 13
fill ~84 ~11 ~74 ~86 ~11 ~74 stained_hardened_clay 13
fill ~85 ~11 ~75 ~89 ~11 ~75 stained_hardened_clay 13
fill ~87 ~11 ~76 ~95 ~11 ~76 stained_hardened_clay 13
fill ~91 ~11 ~77 ~93 ~11 ~77 stained_hardened_clay 13
fill ~94 ~11 ~75 ~98 ~11 ~75 stained_hardened_clay 13
fill ~96 ~11 ~74 ~103 ~11 ~74 stained_hardened_clay 13
fill ~101 ~11 ~75 ~105 ~11 ~75 stained_hardened_clay 13
fill ~104 ~11 ~76 ~112 ~11 ~76 stained_hardened_clay 13
fill ~106 ~11 ~77 ~109 ~11 ~77 stained_hardened_clay 13
fill ~110 ~11 ~75 ~114 ~11 ~75 stained_hardened_clay 13
fill ~113 ~11 ~74 ~115 ~11 ~74 stained_hardened_clay 13
fill ~114 ~11 ~73 ~115 ~11 ~73 stained_hardened_clay 13
fill ~115 ~11 ~72 ~116 ~11 ~72 stained_hardened_clay 13
fill ~116 ~11 ~70 ~117 ~11 ~70 stained_hardened_clay 13
fill ~116 ~11 ~71 ~117 ~11 ~71 stained_hardened_clay 13
fill ~117 ~11 ~69 ~118 ~11 ~69 stained_hardened_clay 13
fill ~118 ~11 ~68 ~119 ~11 ~68 stained_hardened_clay 13
fill ~119 ~11 ~63 ~122 ~11 ~63 stained_hardened_clay 13
fill ~119 ~11 ~64 ~120 ~11 ~64 stained_hardened_clay 13
fill ~119 ~11 ~65 ~119 ~14 ~65 stained_hardened_clay 13
fill ~119 ~11 ~67 ~119 ~18 ~67 stained_hardened_clay 13 summon ArmorStand ~ ~-3 ~ {CustomName:STRCMD,NoGravity:1,Marker:1,Invisible:1}} summon Skeleton ~57.0 ~191.0 ~96.0 summon Creeper ~66.9784986921 ~154.0 ~100.722817201 summon Skeleton ~69.0 ~199.0 ~101.0 summon Zombie ~64.0 ~191.0 ~97.0 summon Skeleton ~63.0 ~191.0 ~97.0 summon Creeper ~60.0 ~138.0 ~106.0 summon Bat ~78.7271188076 ~57.0889563613 ~101.83659678 summon Zombie ~80.3007613151 ~182.0 ~98.2113392741 summon Skeleton ~73.0 ~163.0 ~107.0 summon Creeper ~73.0 ~200.0 ~106.0 summon Creeper ~78.4142489208 ~177.0 ~109.256187417 summon Zombie ~75.3976534478 ~180.0 ~103.95162178 summon Zombie ~82.9102492577 ~178.0 ~108.974430091 summon Zombie ~86.0 ~178.0 ~108.0 summon Skeleton ~79.0 ~113.0 ~119.0 summon Skeleton ~84.0 ~111.0 ~119.0 summon Zombie ~79.1934367152 ~170.0 ~114.3133595 summon Creeper ~75.0 ~182.0 ~132.0 summon Zombie ~78.0433950847 ~207.0 ~132.446000243 summon Skeleton ~77.1398718813 ~211.0 ~133.285406553 summon Skeleton ~83.8298644664 ~144.0 ~121.31408725 summon Skeleton ~85.0527084798 ~143.0 ~122.199999988 summon Skeleton ~85.9903164872 ~143.0 ~121.299367981 summon Creeper ~83.0 ~212.0 ~133.0 summon Zombie ~79.0 ~212.0 ~139.0 summon Zombie ~85.0 ~193.0 ~144.0 summon Zombie ~88.0 ~172.0 ~73.0 summon Zombie ~87.0064301094 ~179.0 ~92.710077616 summon Bat ~95.0752084644 ~57.0442387157 ~96.6757877163 summon Zombie ~93.2959267831 ~175.0 ~107.036617463 summon Creeper ~100.412463046 ~125.0 ~111.922240374 summon Creeper ~97.0 ~92.0 ~118.0 summon Creeper ~97.5166210513 ~182.0 ~114.896804552 summon Skeleton ~87.0041201347 ~142.0 ~121.381284514 summon Creeper ~89.0 ~142.0 ~129.0 summon Zombie ~88.0172053874 ~185.0 ~134.59452702 summon Zombie ~92.0 ~163.0 ~131.0 summon Skeleton ~94.0784687487 ~168.0 ~131.370595901 summon Creeper ~99.0 ~135.0 ~122.0 summon Zombie ~98.6205996449 ~162.0 ~133.949599514 summon Creeper ~87.0 ~204.0 ~143.0 summon Enderman ~93.7153071006 ~166.0 ~138.158852029 summon Creeper ~90.0 ~172.0 ~137.0 summon Skeleton ~94.0 ~193.0 ~142.0 summon Creeper ~88.0 ~168.0 ~144.0 summon Zombie ~89.0 ~145.0 ~145.0 summon Zombie ~90.0 ~193.0 ~145.0 summon Creeper ~99.0 ~191.0 ~138.0 summon Zombie ~102.427784748 ~201.0 ~147.866249261 summon Skeleton ~99.9184957208 ~213.0 ~150.341184822 summon Skeleton ~92.0 ~152.0 ~159.0 summon Skeleton ~92.1271418821 ~183.0 ~151.800000012 summon Zombie ~104.849999994 ~176.0 ~101.849999994 summon Bat ~113.130484154 ~58.1726253158 ~95.7738697609 summon Creeper ~104.0 ~183.0 ~116.0 summon Bat ~115.400917159 ~58.2184375158 ~105.216362391 summon Bat ~112.148583917 ~61.0240108844 ~114.25 summon Creeper ~103.979212432 ~186.0 ~126.512950063 summon Creeper ~105.0 ~183.0 ~123.0 summon Skeleton ~109.0 ~186.0 ~120.0 summon Creeper ~106.0 ~183.0 ~123.0 summon Skeleton ~106.071307029 ~188.0 ~121.333766267 summon Zombie ~107.934658099 ~212.0 ~126.693151947 summon Skeleton ~109.0 ~193.0 ~130.0 summon Creeper ~109.0 ~214.0 ~132.0 summon Creeper ~107.456141851 ~216.0 ~133.957392649 summon Skeleton ~114.0 ~210.0 ~124.0 summon Creeper ~116.517138147 ~211.0 ~122.03051657 summon Zombie ~115.0 ~214.0 ~133.0 summon Spider ~108.793675068 ~209.0 ~145.205541159 summon Zombie ~113.028144536 ~183.0 ~142.07856694 summon Creeper ~116.0 ~187.0 ~150.0 summon Zombie ~103.474453817 ~194.0 ~151.927114873 summon Creeper ~106.0 ~164.0 ~157.0 summon Creeper ~105.456658859 ~145.0 ~159.847474015 summon Skeleton ~114.000562659 ~195.0 ~155.380508435 summon Bat ~134.311593443 ~58.0 ~99.3115934435 summon Bat ~119.707948293 ~53.9590148388 ~104.883913139 summon Bat ~120.958365654 ~53.7269722845 ~105.097912404 summon Bat ~123.25 ~58.027984346 ~108.25 summon Zombie ~122.849999994 ~149.0 ~109.849999994 summon Skeleton ~122.0 ~214.0 ~126.0 summon Creeper ~129.845592915 ~190.0 ~125.437235116 summon Skeleton ~126.976861936 ~203.0 ~128.367911761 summon Skeleton ~121.406966485 ~201.0 ~138.964346341 summon Creeper ~122.0 ~174.0 ~136.0 summon Zombie ~125.926912206 ~197.0 ~139.089419109 summon Skeleton ~138.0 ~132.0 ~106.0 summon Skeleton ~135.0 ~186.0 ~115.0


execute @e[type=ArmorStand,name=STRCMD] ~ ~ ~

fill ~121 ~11 ~62 ~123 ~11 ~62 stained_hardened_clay 13
fill ~123 ~11 ~61 ~123 ~13 ~61 stained_hardened_clay 13
fill ~124 ~11 ~58 ~127 ~11 ~58 stained_hardened_clay 13
fill ~124 ~11 ~60 ~124 ~13 ~60 stained_hardened_clay 13
fill ~125 ~11 ~59 ~125 ~12 ~59 stained_hardened_clay 13
fill ~126 ~11 ~57 ~127 ~11 ~57 stained_hardened_clay 13
fill ~127 ~11 ~55 ~128 ~11 ~55 stained_hardened_clay 13
fill ~127 ~11 ~56 ~127 ~13 ~56 stained_hardened_clay 13
fill ~128 ~11 ~54 ~130 ~11 ~54 stained_hardened_clay 13
fill ~68 ~12 ~52 ~69 ~12 ~52 stained_hardened_clay 13
fill ~68 ~12 ~53 ~68 ~19 ~53 stained_hardened_clay 13
fill ~70 ~12 ~54 ~81 ~12 ~54 stained_hardened_clay 13
fill ~71 ~12 ~53 ~131 ~12 ~53 stained_hardened_clay 13
fill ~71 ~12 ~55 ~72 ~12 ~55 stained_hardened_clay 13
fill ~72 ~12 ~57 ~73 ~12 ~57 stained_hardened_clay 13
fill ~72 ~12 ~58 ~74 ~12 ~58 stained_hardened_clay 13
fill ~73 ~12 ~59 ~73 ~13 ~59 stained_hardened_clay 13
fill ~73 ~12 ~60 ~76 ~12 ~60 stained_hardened_clay 13
fill ~75 ~12 ~61 ~75 ~14 ~61 stained_hardened_clay 13
fill ~76 ~12 ~62 ~78 ~12 ~62 stained_hardened_clay 13
fill ~77 ~12 ~63 ~79 ~12 ~63 stained_hardened_clay 13
fill ~79 ~12 ~64 ~80 ~12 ~64 stained_hardened_clay 13
fill ~80 ~12 ~68 ~80 ~22 ~68 stained_hardened_clay 13
fill ~81 ~12 ~69 ~82 ~12 ~69 stained_hardened_clay 13
fill ~82 ~12 ~70 ~82 ~21 ~70 stained_hardened_clay 13
fill ~82 ~12 ~71 ~83 ~12 ~71 stained_hardened_clay 13
fill ~83 ~12 ~72 ~84 ~12 ~72 stained_hardened_clay 13
fill ~83 ~12 ~73 ~85 ~12 ~73 stained_hardened_clay 13
fill ~84 ~12 ~74 ~85 ~12 ~74 stained_hardened_clay 13
fill ~85 ~12 ~75 ~87 ~12 ~75 stained_hardened_clay 13
fill ~86 ~12 ~76 ~91 ~12 ~76 stained_hardened_clay 13
fill ~89 ~12 ~77 ~94 ~12 ~77 stained_hardened_clay 13
fill ~93 ~12 ~76 ~96 ~12 ~76 stained_hardened_clay 13
fill ~95 ~12 ~75 ~104 ~12 ~75 stained_hardened_clay 13
fill ~97 ~12 ~52 ~113 ~12 ~52 stained_hardened_clay 13
fill ~98 ~12 ~74 ~102 ~12 ~74 stained_hardened_clay 13
fill ~103 ~12 ~76 ~106 ~12 ~76 stained_hardened_clay 13
fill ~105 ~12 ~77 ~110 ~12 ~77 stained_hardened_clay 13
fill ~108 ~12 ~76 ~113 ~12 ~76 stained_hardened_clay 13
fill ~112 ~12 ~75 ~114 ~12 ~75 stained_hardened_clay 13
fill ~114 ~12 ~74 ~115 ~12 ~74 stained_hardened_clay 13
fill ~115 ~12 ~72 ~116 ~12 ~72 stained_hardened_clay 13
fill ~115 ~12 ~73 ~116 ~12 ~73 stained_hardened_clay 13
fill ~116 ~12 ~71 ~117 ~12 ~71 stained_hardened_clay 13
fill ~117 ~12 ~69 ~118 ~12 ~69 stained_hardened_clay 13
fill ~117 ~12 ~70 ~118 ~12 ~70 stained_hardened_clay 13
fill ~118 ~12 ~68 ~119 ~12 ~68 stained_hardened_clay 13
fill ~119 ~12 ~64 ~120 ~12 ~64 stained_hardened_clay 13
fill ~120 ~12 ~63 ~122 ~12 ~63 stained_hardened_clay 13
fill ~121 ~12 ~62 ~123 ~12 ~62 stained_hardened_clay 13
fill ~124 ~12 ~61 ~124 ~14 ~61 stained_hardened_clay 13
fill ~125 ~12 ~58 ~127 ~12 ~58 stained_hardened_clay 13
fill ~125 ~12 ~60 ~126 ~12 ~60 stained_hardened_clay 13
fill ~126 ~12 ~52 ~131 ~12 ~52 stained_hardened_clay 13
fill ~126 ~12 ~59 ~126 ~13 ~59 stained_hardened_clay 13
fill ~127 ~12 ~55 ~128 ~12 ~55 stained_hardened_clay 13
fill ~127 ~12 ~57 ~127 ~13 ~57 stained_hardened_clay 13
fill ~128 ~12 ~54 ~130 ~12 ~54 stained_hardened_clay 13
fill ~67 ~13 ~52 ~132 ~13 ~52 stained_hardened_clay 13
fill ~70 ~13 ~54 ~71 ~13 ~54 stained_hardened_clay 13
fill ~71 ~13 ~53 ~105 ~13 ~53 stained_hardened_clay 13
fill ~71 ~13 ~55 ~72 ~13 ~55 stained_hardened_clay 13
fill ~71 ~13 ~56 ~71 ~16 ~56 stained_hardened_clay 13
fill ~71 ~13 ~57 ~72 ~13 ~57 stained_hardened_clay 13
fill ~72 ~13 ~58 ~73 ~13 ~58 stained_hardened_clay 13
fill ~72 ~13 ~59 ~72 ~15 ~59 stained_hardened_clay 13
fill ~72 ~13 ~60 ~75 ~13 ~60 stained_hardened_clay 13
fill ~73 ~13 ~61 ~76 ~13 ~61 stained_hardened_clay 13
fill ~75 ~13 ~62 ~77 ~13 ~62 stained_hardened_clay 13
fill ~76 ~13 ~63 ~79 ~13 ~63 stained_hardened_clay 13
fill ~79 ~13 ~64 ~80 ~13 ~64 stained_hardened_clay 13
fill ~79 ~13 ~65 ~79 ~17 ~65 stained_hardened_clay 13
fill ~81 ~13 ~69 ~82 ~13 ~69 stained_hardened_clay 13
fill ~82 ~13 ~71 ~83 ~13 ~71 stained_hardened_clay 13
fill ~83 ~13 ~72 ~83 ~20 ~72 stained_hardened_clay 13
fill ~83 ~13 ~73 ~84 ~13 ~73 stained_hardened_clay 13
fill ~84 ~13 ~74 ~85 ~13 ~74 stained_hardened_clay 13
fill ~84 ~13 ~75 ~86 ~13 ~75 stained_hardened_clay 13
fill ~85 ~13 ~76 ~89 ~13 ~76 stained_hardened_clay 13
fill ~88 ~13 ~77 ~95 ~13 ~77 stained_hardened_clay 13
fill ~91 ~13 ~78 ~92 ~13 ~78 stained_hardened_clay 13
fill ~94 ~13 ~76 ~97 ~13 ~76 stained_hardened_clay 13
fill ~96 ~13 ~75 ~103 ~13 ~75 stained_hardened_clay 13
fill ~99 ~13 ~74 ~100 ~13 ~74 stained_hardened_clay 13
fill ~102 ~13 ~76 ~105 ~13 ~76 stained_hardened_clay 13
fill ~104 ~13 ~77 ~111 ~13 ~77 stained_hardened_clay 13
fill ~107 ~13 ~78 ~108 ~13 ~78 stained_hardened_clay 13
fill ~110 ~13 ~76 ~114 ~13 ~76 stained_hardened_clay 13
fill ~111 ~13 ~53 ~131 ~13 ~53 stained_hardened_clay 13
fill ~113 ~13 ~75 ~115 ~13 ~75 stained_hardened_clay 13
fill ~114 ~13 ~74 ~116 ~13 ~74 stained_hardened_clay 13
fill ~115 ~13 ~73 ~116 ~13 ~73 stained_hardened_clay 13
fill ~116 ~13 ~71 ~117 ~13 ~71 stained_hardened_clay 13
fill ~116 ~13 ~72 ~117 ~13 ~72 stained_hardened_clay 13
fill ~117 ~13 ~70 ~118 ~13 ~70 stained_hardened_clay 13
fill ~118 ~13 ~68 ~119 ~13 ~68 stained_hardened_clay 13
fill ~118 ~13 ~69 ~118 ~22 ~69 stained_hardened_clay 13
fill ~119 ~13 ~64 ~121 ~13 ~64 stained_hardened_clay 13
fill ~120 ~13 ~63 ~123 ~13 ~63 stained_hardened_clay 13
fill ~120 ~13 ~65 ~120 ~17 ~65 stained_hardened_clay 13
fill ~122 ~13 ~62 ~125 ~13 ~62 stained_hardened_clay 13
fill ~125 ~13 ~60 ~127 ~13 ~60 stained_hardened_clay 13
fill ~125 ~13 ~61 ~126 ~13 ~61 stained_hardened_clay 13
fill ~126 ~13 ~58 ~128 ~13 ~58 stained_hardened_clay 13
fill ~127 ~13 ~55 ~128 ~13 ~55 stained_hardened_clay 13
fill ~127 ~13 ~59 ~127 ~15 ~59 stained_hardened_clay 13
fill ~128 ~13 ~54 ~129 ~13 ~54 stained_hardened_clay 13
fill ~128 ~13 ~56 ~128 ~15 ~56 stained_hardened_clay 13
fill ~128 ~13 ~57 ~128 ~16 ~57 stained_hardened_clay 13
fill ~67 ~14 ~51 ~67 ~22 ~51 stained_hardened_clay 13
fill ~67 ~14 ~52 ~132 ~14 ~52 stained_hardened_clay 13
fill ~70 ~14 ~54 ~71 ~14 ~54 stained_hardened_clay 13
fill ~71 ~14 ~55 ~71 ~16 ~55 stained_hardened_clay 13
fill ~71 ~14 ~57 ~72 ~14 ~57 stained_hardened_clay 13
fill ~71 ~14 ~58 ~72 ~14 ~58 stained_hardened_clay 13
fill ~71 ~14 ~59 ~71 ~17 ~59 stained_hardened_clay 13
fill ~72 ~14 ~60 ~73 ~14 ~60 stained_hardened_clay 13
fill ~72 ~14 ~61 ~75 ~14 ~61 stained_hardened_clay 13
fill ~73 ~14 ~62 ~76 ~14 ~62 stained_hardened_clay 13
fill ~75 ~14 ~63 ~79 ~14 ~63 stained_hardened_clay 13
fill ~76 ~14 ~51 ~132 ~14 ~51 stained_hardened_clay 13
fill ~78 ~14 ~64 ~79 ~14 ~64 stained_hardened_clay 13
fill ~81 ~14 ~69 ~82 ~14 ~69 stained_hardened_clay 13
fill ~82 ~14 ~71 ~83 ~14 ~71 stained_hardened_clay 13
fill ~82 ~14 ~72 ~82 ~23 ~72 stained_hardened_clay 13
fill ~83 ~14 ~73 ~84 ~14 ~73 stained_hardened_clay 13
fill ~83 ~14 ~74 ~84 ~14 ~74 stained_hardened_clay 13
fill ~84 ~14 ~75 ~85 ~14 ~75 stained_hardened_clay 13
fill ~85 ~14 ~76 ~88 ~14 ~76 stained_hardened_clay 13
fill ~86 ~14 ~77 ~96 ~14 ~77 stained_hardened_clay 13
fill ~89 ~14 ~78 ~94 ~14 ~78 stained_hardened_clay 13
fill ~95 ~14 ~76 ~104 ~14 ~76 stained_hardened_clay 13
fill ~97 ~14 ~75 ~102 ~14 ~75 stained_hardened_clay 13
fill ~103 ~14 ~77 ~113 ~14 ~77 stained_hardened_clay 13
fill ~106 ~14 ~78 ~110 ~14 ~78 stained_hardened_clay 13
fill ~111 ~14 ~76 ~115 ~14 ~76 stained_hardened_clay 13
fill ~114 ~14 ~75 ~115 ~14 ~75 stained_hardened_clay 13
fill ~115 ~14 ~73 ~116 ~14 ~73 stained_hardened_clay 13
fill ~115 ~14 ~74 ~116 ~14 ~74 stained_hardened_clay 13
fill ~116 ~14 ~72 ~117 ~14 ~72 stained_hardened_clay 13
fill ~117 ~14 ~70 ~118 ~14 ~70 stained_hardened_clay 13
fill ~117 ~14 ~71 ~117 ~22 ~71 stained_hardened_clay 13
fill ~118 ~14 ~68 ~119 ~14 ~68 stained_hardened_clay 13
fill ~120 ~14 ~63 ~124 ~14 ~63 stained_hardened_clay 13
fill ~120 ~14 ~64 ~121 ~14 ~64 stained_hardened_clay 13
fill ~120 ~14 ~66 ~120 ~18 ~66 stained_hardened_clay 13
fill ~123 ~14 ~62 ~126 ~14 ~62 stained_hardened_clay 13
fill ~125 ~14 ~61 ~127 ~14 ~61 stained_hardened_clay 13
fill ~126 ~14 ~60 ~127 ~14 ~60 stained_hardened_clay 13
fill ~127 ~14 ~58 ~128 ~14 ~58 stained_hardened_clay 13
fill ~128 ~14 ~54 ~130 ~14 ~54 stained_hardened_clay 13
fill ~128 ~14 ~55 ~129 ~14 ~55 stained_hardened_clay 13
fill ~128 ~14 ~59 ~128 ~17 ~59 stained_hardened_clay 13
fill ~129 ~14 ~53 ~131 ~14 ~53 stained_hardened_clay 13
fill ~67 ~15 ~52 ~96 ~15 ~52 stained_hardened_clay 13
fill ~68 ~15 ~51 ~132 ~15 ~51 stained_hardened_clay 13
fill ~69 ~15 ~54 ~71 ~15 ~54 stained_hardened_clay 13
fill ~70 ~15 ~55 ~70 ~18 ~55 stained_hardened_clay 13
fill ~71 ~15 ~57 ~71 ~16 ~57 stained_hardened_clay 13
fill ~71 ~15 ~58 ~71 ~16 ~58 stained_hardened_clay 13
fill ~71 ~15 ~60 ~72 ~15 ~60 stained_hardened_clay 13
fill ~71 ~15 ~61 ~73 ~15 ~61 stained_hardened_clay 13
fill ~72 ~15 ~62 ~75 ~15 ~62 stained_hardened_clay 13
fill ~73 ~15 ~63 ~78 ~15 ~63 stained_hardened_clay 13
fill ~77 ~15 ~64 ~79 ~15 ~64 stained_hardened_clay 13
fill ~79 ~15 ~66 ~79 ~18 ~66 stained_hardened_clay 13
fill ~81 ~15 ~69 ~82 ~15 ~69 stained_hardened_clay 13
fill ~82 ~15 ~71 ~83 ~15 ~71 stained_hardened_clay 13
fill ~83 ~15 ~73 ~83 ~20 ~73 stained_hardened_clay 13
fill ~83 ~15 ~74 ~84 ~15 ~74 stained_hardened_clay 13
fill ~83 ~15 ~75 ~85 ~15 ~75 stained_hardened_clay 13
fill ~84 ~15 ~76 ~87 ~15 ~76 stained_hardened_clay 13
fill ~85 ~15 ~77 ~89 ~15 ~77 stained_hardened_clay 13
fill ~87 ~15 ~78 ~95 ~15 ~78 stained_hardened_clay 13
fill ~90 ~15 ~79 ~92 ~15 ~79 stained_hardened_clay 13
fill ~94 ~15 ~77 ~97 ~15 ~77 stained_hardened_clay 13
fill ~96 ~15 ~76 ~103 ~15 ~76 stained_hardened_clay 13
fill ~102 ~15 ~77 ~106 ~15 ~77 stained_hardened_clay 13
fill ~105 ~15 ~78 ~112 ~15 ~78 stained_hardened_clay 13
fill ~107 ~15 ~79 ~109 ~15 ~79 stained_hardened_clay 13
fill ~110 ~15 ~77 ~114 ~15 ~77 stained_hardened_clay 13
fill ~113 ~15 ~76 ~115 ~15 ~76 stained_hardened_clay 13
fill ~114 ~15 ~75 ~116 ~15 ~75 stained_hardened_clay 13
fill ~115 ~15 ~74 ~116 ~15 ~74 stained_hardened_clay 13
fill ~116 ~15 ~72 ~117 ~15 ~72 stained_hardened_clay 13
fill ~116 ~15 ~73 ~116 ~19 ~73 stained_hardened_clay 13
fill ~117 ~15 ~70 ~118 ~15 ~70 stained_hardened_clay 13
fill ~118 ~15 ~68 ~119 ~15 ~68 stained_hardened_clay 13
fill ~120 ~15 ~64 ~122 ~15 ~64 stained_hardened_clay 13
fill ~120 ~15 ~67 ~120 ~20 ~67 stained_hardened_clay 13
fill ~121 ~15 ~63 ~126 ~15 ~63 stained_hardened_clay 13
fill ~124 ~15 ~62 ~127 ~15 ~62 stained_hardened_clay 13
fill ~126 ~15 ~61 ~128 ~15 ~61 stained_hardened_clay 13
fill ~127 ~15 ~60 ~128 ~15 ~60 stained_hardened_clay 13
fill ~128 ~15 ~55 ~129 ~15 ~55 stained_hardened_clay 13
fill ~128 ~15 ~58 ~128 ~16 ~58 stained_hardened_clay 13
fill ~129 ~15 ~54 ~130 ~15 ~54 stained_hardened_clay 13
fill ~129 ~15 ~56 ~129 ~17 ~56 stained_hardened_clay 13
fill ~129 ~15 ~57 ~129 ~17 ~57 stained_hardened_clay 13
fill ~130 ~15 ~53 ~131 ~15 ~53 stained_hardened_clay 13
fill ~131 ~15 ~52 ~132 ~15 ~52 stained_hardened_clay 13
fill ~66 ~16 ~51 ~66 ~17 ~51 stained_hardened_clay 13
fill ~67 ~16 ~50 ~84 ~16 ~50 stained_hardened_clay 13
fill ~67 ~16 ~52 ~68 ~16 ~52 stained_hardened_clay 13
fill ~68 ~16 ~51 ~133 ~16 ~51 stained_hardened_clay 13
fill ~69 ~16 ~54 ~70 ~16 ~54 stained_hardened_clay 13
fill ~70 ~16 ~56 ~70 ~18 ~56 stained_hardened_clay 13
fill ~70 ~16 ~57 ~70 ~18 ~57 stained_hardened_clay 13
fill ~70 ~16 ~58 ~70 ~18 ~58 stained_hardened_clay 13
fill ~70 ~16 ~59 ~70 ~19 ~59 stained_hardened_clay 13
fill ~71 ~16 ~60 ~71 ~17 ~60 stained_hardened_clay 13
fill ~71 ~16 ~61 ~72 ~16 ~61 stained_hardened_clay 13
fill ~71 ~16 ~62 ~73 ~16 ~62 stained_hardened_clay 13
fill ~72 ~16 ~63 ~77 ~16 ~63 stained_hardened_clay 13
fill ~73 ~16 ~64 ~79 ~16 ~64 stained_hardened_clay 13
fill ~78 ~16 ~65 ~78 ~19 ~65 stained_hardened_clay 13
fill ~79 ~16 ~67 ~79 ~20 ~67 stained_hardened_clay 13
fill ~81 ~16 ~69 ~82 ~16 ~69 stained_hardened_clay 13
fill ~82 ~16 ~71 ~82 ~22 ~71 stained_hardened_clay 13
fill ~83 ~16 ~74 ~84 ~16 ~74 stained_hardened_clay 13
fill ~83 ~16 ~75 ~84 ~16 ~75 stained_hardened_clay 13
fill ~84 ~16 ~76 ~86 ~16 ~76 stained_hardened_clay 13
fill ~85 ~16 ~77 ~88 ~16 ~77 stained_hardened_clay 13
fill ~86 ~16 ~78 ~95 ~16 ~78 stained_hardened_clay 13
fill ~88 ~16 ~79 ~93 ~16 ~79 stained_hardened_clay 13
fill ~95 ~16 ~77 ~105 ~16 ~77 stained_hardened_clay 13
fill ~97 ~16 ~76 ~102 ~16 ~76 stained_hardened_clay 13
fill ~104 ~16 ~78 ~113 ~16 ~78 stained_hardened_clay 13
fill ~106 ~16 ~79 ~111 ~16 ~79 stained_hardened_clay 13
fill ~112 ~16 ~77 ~114 ~16 ~77 stained_hardened_clay 13
fill ~114 ~16 ~76 ~115 ~16 ~76 stained_hardened_clay 13
fill ~115 ~16 ~75 ~116 ~16 ~75 stained_hardened_clay 13
fill ~116 ~16 ~72 ~117 ~16 ~72 stained_hardened_clay 13
fill ~116 ~16 ~74 ~116 ~20 ~74 stained_hardened_clay 13
fill ~117 ~16 ~69 ~117 ~19 ~69 stained_hardened_clay 13
fill ~117 ~16 ~70 ~118 ~16 ~70 stained_hardened_clay 13
fill ~118 ~16 ~68 ~119 ~16 ~68 stained_hardened_clay 13
fill ~120 ~16 ~64 ~126 ~16 ~64 stained_hardened_clay 13
fill ~121 ~16 ~65 ~121 ~18 ~65 stained_hardened_clay 13
fill ~122 ~16 ~63 ~127 ~16 ~63 stained_hardened_clay 13
fill ~126 ~16 ~62 ~128 ~16 ~62 stained_hardened_clay 13
fill ~127 ~16 ~61 ~128 ~16 ~61 stained_hardened_clay 13
fill ~128 ~16 ~60 ~128 ~17 ~60 stained_hardened_clay 13
fill ~129 ~16 ~54 ~130 ~16 ~54 stained_hardened_clay 13
fill ~129 ~16 ~55 ~129 ~18 ~55 stained_hardened_clay 13
fill ~129 ~16 ~58 ~129 ~18 ~58 stained_hardened_clay 13
fill ~129 ~16 ~59 ~129 ~19 ~59 stained_hardened_clay 13
fill ~130 ~16 ~53 ~131 ~16 ~53 stained_hardened_clay 13
fill ~131 ~16 ~52 ~132 ~16 ~52 stained_hardened_clay 13
fill ~66 ~17 ~50 ~133 ~17 ~50 stained_hardened_clay 13
fill ~67 ~17 ~52 ~68 ~17 ~52 stained_hardened_clay 13
fill ~69 ~17 ~54 ~70 ~17 ~54 stained_hardened_clay 13
fill ~69 ~17 ~56 ~69 ~20 ~56 stained_hardened_clay 13
fill ~69 ~17 ~57 ~69 ~20 ~57 stained_hardened_clay 13
fill ~69 ~17 ~58 ~69 ~20 ~58 stained_hardened_clay 13
fill ~70 ~17 ~60 ~70 ~20 ~60 stained_hardened_clay 13
fill ~70 ~17 ~61 ~71 ~17 ~61 stained_hardened_clay 13
fill ~71 ~17 ~62 ~72 ~17 ~62 stained_hardened_clay 13
fill ~71 ~17 ~63 ~73 ~17 ~63 stained_hardened_clay 13
fill ~72 ~17 ~64 ~78 ~17 ~64 stained_hardened_clay 13
fill ~77 ~17 ~51 ~133 ~17 ~51 stained_hardened_clay 13
fill ~77 ~17 ~65 ~77 ~20 ~65 stained_hardened_clay 13
fill ~78 ~17 ~66 ~78 ~20 ~66 stained_hardened_clay 13
fill ~81 ~17 ~69 ~82 ~17 ~69 stained_hardened_clay 13
fill ~83 ~17 ~74 ~83 ~22 ~74 stained_hardened_clay 13
fill ~83 ~17 ~75 ~84 ~17 ~75 stained_hardened_clay 13
fill ~83 ~17 ~76 ~85 ~17 ~76 stained_hardened_clay 13
fill ~84 ~17 ~77 ~86 ~17 ~77 stained_hardened_clay 13
fill ~85 ~17 ~78 ~89 ~17 ~78 stained_hardened_clay 13
fill ~87 ~17 ~79 ~94 ~17 ~79 stained_hardened_clay 13
fill ~90 ~17 ~80 ~91 ~17 ~80 stained_hardened_clay 13
fill ~93 ~17 ~78 ~96 ~17 ~78 stained_hardened_clay 13
fill ~95 ~17 ~77 ~104 ~17 ~77 stained_hardened_clay 13
fill ~99 ~17 ~76 ~100 ~17 ~76 stained_hardened_clay 13
fill ~103 ~17 ~78 ~106 ~17 ~78 stained_hardened_clay 13
fill ~105 ~17 ~79 ~112 ~17 ~79 stained_hardened_clay 13
fill ~108 ~17 ~80 ~110 ~17 ~80 stained_hardened_clay 13
fill ~111 ~17 ~78 ~114 ~17 ~78 stained_hardened_clay 13
fill ~113 ~17 ~77 ~115 ~17 ~77 stained_hardened_clay 13
fill ~114 ~17 ~76 ~116 ~17 ~76 stained_hardened_clay 13
fill ~115 ~17 ~75 ~116 ~17 ~75 stained_hardened_clay 13
fill ~116 ~17 ~72 ~117 ~17 ~72 stained_hardened_clay 13
fill ~117 ~17 ~70 ~118 ~17 ~70 stained_hardened_clay 13
fill ~118 ~17 ~68 ~119 ~17 ~68 stained_hardened_clay 13
fill ~121 ~17 ~64 ~127 ~17 ~64 stained_hardened_clay 13
fill ~121 ~17 ~66 ~121 ~20 ~66 stained_hardened_clay 13
fill ~122 ~17 ~65 ~122 ~20 ~65 stained_hardened_clay 13
fill ~126 ~17 ~63 ~128 ~17 ~63 stained_hardened_clay 13
fill ~127 ~17 ~62 ~128 ~17 ~62 stained_hardened_clay 13
fill ~128 ~17 ~61 ~129 ~17 ~61 stained_hardened_clay 13
fill ~129 ~17 ~54 ~130 ~17 ~54 stained_hardened_clay 13
fill ~129 ~17 ~60 ~129 ~19 ~60 stained_hardened_clay 13
fill ~130 ~17 ~53 ~131 ~17 ~53 stained_hardened_clay 13
fill ~130 ~17 ~55 ~130 ~21 ~55 stained_hardened_clay 13
fill ~130 ~17 ~56 ~130 ~20 ~56 stained_hardened_clay 13
fill ~130 ~17 ~57 ~130 ~19 ~57 stained_hardened_clay 13
fill ~130 ~17 ~58 ~130 ~20 ~58 stained_hardened_clay 13
fill ~131 ~17 ~52 ~132 ~17 ~52 stained_hardened_clay 13
fill ~66 ~18 ~49 ~107 ~18 ~49 stained_hardened_clay 13
fill ~66 ~18 ~50 ~133 ~18 ~50 stained_hardened_clay 13
fill ~67 ~18 ~52 ~68 ~18 ~52 stained_hardened_clay 13
fill ~68 ~18 ~51 ~68 ~25 ~51 stained_hardened_clay 13
fill ~69 ~18 ~54 ~70 ~18 ~54 stained_hardened_clay 13
fill ~69 ~18 ~55 ~69 ~22 ~55 stained_hardened_clay 13
fill ~69 ~18 ~59 ~69 ~21 ~59 stained_hardened_clay 13
fill ~70 ~18 ~61 ~71 ~18 ~61 stained_hardened_clay 13
fill ~70 ~18 ~62 ~71 ~18 ~62 stained_hardened_clay 13
fill ~71 ~18 ~63 ~72 ~18 ~63 stained_hardened_clay 13
fill ~71 ~18 ~64 ~77 ~18 ~64 stained_hardened_clay 13
fill ~72 ~18 ~65 ~73 ~18 ~65 stained_hardened_clay 13
fill ~76 ~18 ~65 ~76 ~21 ~65 stained_hardened_clay 13
fill ~78 ~18 ~67 ~78 ~22 ~67 stained_hardened_clay 13
fill ~79 ~18 ~68 ~79 ~23 ~68 stained_hardened_clay 13
fill ~81 ~18 ~69 ~82 ~18 ~69 stained_hardened_clay 13
fill ~83 ~18 ~71 ~83 ~19 ~71 stained_hardened_clay 13
fill ~83 ~18 ~75 ~83 ~23 ~75 stained_hardened_clay 13
fill ~83 ~18 ~76 ~84 ~18 ~76 stained_hardened_clay 13
fill ~84 ~18 ~77 ~86 ~18 ~77 stained_hardened_clay 13
fill ~85 ~18 ~78 ~87 ~18 ~78 stained_hardened_clay 13
fill ~86 ~18 ~79 ~94 ~18 ~79 stained_hardened_clay 13
fill ~88 ~18 ~80 ~92 ~18 ~80 stained_hardened_clay 13
fill ~94 ~18 ~78 ~98 ~18 ~78 stained_hardened_clay 13
fill ~96 ~18 ~77 ~103 ~18 ~77 stained_hardened_clay 13
fill ~101 ~18 ~78 ~105 ~18 ~78 stained_hardened_clay 13
fill ~105 ~18 ~79 ~113 ~18 ~79 stained_hardened_clay 13
fill ~107 ~18 ~80 ~111 ~18 ~80 stained_hardened_clay 13
fill ~112 ~18 ~78 ~114 ~18 ~78 stained_hardened_clay 13
fill ~114 ~18 ~77 ~115 ~18 ~77 stained_hardened_clay 13
fill ~115 ~18 ~76 ~116 ~18 ~76 stained_hardened_clay 13
fill ~116 ~18 ~72 ~117 ~18 ~72 stained_hardened_clay 13
fill ~116 ~18 ~75 ~116 ~23 ~75 stained_hardened_clay 13
fill ~117 ~18 ~70 ~118 ~18 ~70 stained_hardened_clay 13
fill ~117 ~18 ~73 ~117 ~23 ~73 stained_hardened_clay 13
fill ~118 ~18 ~68 ~120 ~18 ~68 stained_hardened_clay 13
fill ~121 ~18 ~67 ~121 ~21 ~67 stained_hardened_clay 13
fill ~122 ~18 ~64 ~128 ~18 ~64 stained_hardened_clay 13
fill ~122 ~18 ~66 ~122 ~21 ~66 stained_hardened_clay 13
fill ~123 ~18 ~65 ~123 ~21 ~65 stained_hardened_clay 13
fill ~127 ~18 ~63 ~128 ~18 ~63 stained_hardened_clay 13
fill ~127 ~18 ~65 ~127 ~24 ~65 stained_hardened_clay 13
fill ~128 ~18 ~61 ~129 ~18 ~61 stained_hardened_clay 13
fill ~128 ~18 ~62 ~129 ~18 ~62 stained_hardened_clay 13
fill ~129 ~18 ~54 ~130 ~18 ~54 stained_hardened_clay 13
fill ~130 ~18 ~53 ~131 ~18 ~53 stained_hardened_clay 13
fill ~130 ~18 ~59 ~130 ~21 ~59 stained_hardened_clay 13
fill ~131 ~18 ~52 ~132 ~18 ~52 stained_hardened_clay 13
fill ~132 ~18 ~51 ~133 ~18 ~51 stained_hardened_clay 13
fill ~66 ~19 ~49 ~133 ~19 ~49 stained_hardened_clay 13
fill ~66 ~19 ~50 ~67 ~19 ~50 stained_hardened_clay 13
fill ~67 ~19 ~48 ~69 ~19 ~48 stained_hardened_clay 13
fill ~67 ~19 ~52 ~69 ~19 ~52 stained_hardened_clay 13
fill ~68 ~19 ~56 ~68 ~25 ~56 stained_hardened_clay 13
fill ~68 ~19 ~57 ~68 ~23 ~57 stained_hardened_clay 13
fill ~68 ~19 ~58 ~68 ~23 ~58 stained_hardened_clay 13
fill ~69 ~19 ~54 ~69 ~26 ~54 stained_hardened_clay 13
fill ~69 ~19 ~60 ~69 ~22 ~60 stained_hardened_clay 13
fill ~70 ~19 ~61 ~70 ~20 ~61 stained_hardened_clay 13
fill ~70 ~19 ~62 ~71 ~19 ~62 stained_hardened_clay 13
fill ~70 ~19 ~63 ~71 ~19 ~63 stained_hardened_clay 13
fill ~70 ~19 ~64 ~76 ~19 ~64 stained_hardened_clay 13
fill ~71 ~19 ~48 ~74 ~19 ~48 stained_hardened_clay 13
fill ~71 ~19 ~65 ~78 ~19 ~65 stained_hardened_clay 13
fill ~77 ~19 ~66 ~77 ~21 ~66 stained_hardened_clay 13
fill ~80 ~19 ~69 ~82 ~19 ~69 stained_hardened_clay 13
fill ~81 ~19 ~70 ~81 ~23 ~70 stained_hardened_clay 13
fill ~82 ~19 ~73 ~82 ~24 ~73 stained_hardened_clay 13
fill ~83 ~19 ~76 ~84 ~19 ~76 stained_hardened_clay 13
fill ~84 ~19 ~77 ~85 ~19 ~77 stained_hardened_clay 13
fill ~84 ~19 ~78 ~86 ~19 ~78 stained_hardened_clay 13
fill ~85 ~19 ~79 ~88 ~19 ~79 stained_hardened_clay 13
fill ~87 ~19 ~80 ~93 ~19 ~80 stained_hardened_clay 13
fill ~92 ~19 ~79 ~95 ~19 ~79 stained_hardened_clay 13
fill ~94 ~19 ~78 ~105 ~19 ~78 stained_hardened_clay 13
fill ~98 ~19 ~77 ~101 ~19 ~77 stained_hardened_clay 13
fill ~102 ~19 ~50 ~133 ~19 ~50 stained_hardened_clay 13
fill ~104 ~19 ~79 ~107 ~19 ~79 stained_hardened_clay 13
fill ~107 ~19 ~80 ~112 ~19 ~80 stained_hardened_clay 13
fill ~111 ~19 ~79 ~114 ~19 ~79 stained_hardened_clay 13
fill ~113 ~19 ~78 ~115 ~19 ~78 stained_hardened_clay 13
fill ~114 ~19 ~77 ~116 ~19 ~77 stained_hardened_clay 13
fill ~115 ~19 ~76 ~116 ~19 ~76 stained_hardened_clay 13
fill ~116 ~19 ~72 ~117 ~19 ~72 stained_hardened_clay 13
fill ~117 ~19 ~70 ~118 ~19 ~70 stained_hardened_clay 13
fill ~117 ~19 ~74 ~117 ~25 ~74 stained_hardened_clay 13
fill ~118 ~19 ~68 ~120 ~19 ~68 stained_hardened_clay 13
fill ~119 ~19 ~69 ~119 ~23 ~69 stained_hardened_clay 13
fill ~123 ~19 ~64 ~129 ~19 ~64 stained_hardened_clay 13
fill ~124 ~19 ~65 ~128 ~19 ~65 stained_hardened_clay 13
fill ~128 ~19 ~62 ~129 ~19 ~62 stained_hardened_clay 13
fill ~128 ~19 ~63 ~129 ~19 ~63 stained_hardened_clay 13
fill ~129 ~19 ~61 ~130 ~19 ~61 stained_hardened_clay 13
fill ~130 ~19 ~52 ~132 ~19 ~52 stained_hardened_clay 13
fill ~130 ~19 ~53 ~131 ~19 ~53 stained_hardened_clay 13
fill ~130 ~19 ~54 ~130 ~24 ~54 stained_hardened_clay 13
fill ~130 ~19 ~60 ~130 ~21 ~60 stained_hardened_clay 13
fill ~131 ~19 ~51 ~132 ~19 ~51 stained_hardened_clay 13
fill ~131 ~19 ~56 ~131 ~24 ~56 stained_hardened_clay 13
fill ~131 ~19 ~57 ~131 ~22 ~57 stained_hardened_clay 13
fill ~131 ~19 ~58 ~131 ~23 ~58 stained_hardened_clay 13
fill ~66 ~20 ~48 ~132 ~20 ~48 stained_hardened_clay 13
fill ~66 ~20 ~49 ~71 ~20 ~49 stained_hardened_clay 13
fill ~66 ~20 ~50 ~67 ~20 ~50 stained_hardened_clay 13
fill ~68 ~20 ~52 ~69 ~20 ~52 stained_hardened_clay 13
fill ~68 ~20 ~55 ~68 ~28 ~55 stained_hardened_clay 13
fill ~68 ~20 ~59 ~68 ~23 ~59 stained_hardened_clay 13
fill ~69 ~20 ~61 ~69 ~22 ~61 stained_hardened_clay 13
fill ~69 ~20 ~62 ~70 ~20 ~62 stained_hardened_clay 13
fill ~70 ~20 ~63 ~70 ~21 ~63 stained_hardened_clay 13
fill ~70 ~20 ~64 ~71 ~20 ~64 stained_hardened_clay 13
fill ~70 ~20 ~65 ~77 ~20 ~65 stained_hardened_clay 13
fill ~74 ~20 ~49 ~133 ~20 ~49 stained_hardened_clay 13
setblock ~74 ~20 ~64 stained_hardened_clay 13
fill ~76 ~20 ~66 ~76 ~22 ~66 stained_hardened_clay 13
fill ~77 ~20 ~67 ~77 ~23 ~67 stained_hardened_clay 13
fill ~78 ~20 ~68 ~78 ~24 ~68 stained_hardened_clay 13
fill ~80 ~20 ~69 ~81 ~20 ~69 stained_hardened_clay 13
fill ~82 ~20 ~74 ~82 ~25 ~74 stained_hardened_clay 13
fill ~83 ~20 ~76 ~84 ~20 ~76 stained_hardened_clay 13
fill ~83 ~20 ~77 ~84 ~20 ~77 stained_hardened_clay 13
fill ~84 ~20 ~78 ~85 ~20 ~78 stained_hardened_clay 13
fill ~85 ~20 ~79 ~87 ~20 ~79 stained_hardened_clay 13
fill ~86 ~20 ~80 ~93 ~20 ~80 stained_hardened_clay 13
fill ~88 ~20 ~81 ~91 ~20 ~81 stained_hardened_clay 13
fill ~93 ~20 ~79 ~96 ~20 ~79 stained_hardened_clay 13
fill ~95 ~20 ~78 ~104 ~20 ~78 stained_hardened_clay 13
fill ~103 ~20 ~79 ~107 ~20 ~79 stained_hardened_clay 13
fill ~106 ~20 ~80 ~113 ~20 ~80 stained_hardened_clay 13
fill ~108 ~20 ~81 ~111 ~20 ~81 stained_hardened_clay 13
fill ~112 ~20 ~79 ~115 ~20 ~79 stained_hardened_clay 13
fill ~114 ~20 ~78 ~115 ~20 ~78 stained_hardened_clay 13
fill ~115 ~20 ~77 ~116 ~20 ~77 stained_hardened_clay 13
fill ~116 ~20 ~76 ~116 ~23 ~76 stained_hardened_clay 13
fill ~117 ~20 ~70 ~118 ~20 ~70 stained_hardened_clay 13
fill ~117 ~20 ~72 ~117 ~22 ~72 stained_hardened_clay 13
fill ~117 ~20 ~75 ~117 ~27 ~75 stained_hardened_clay 13
fill ~119 ~20 ~68 ~121 ~20 ~68 stained_hardened_clay 13
fill ~122 ~20 ~67 ~122 ~22 ~67 stained_hardened_clay 13
fill ~123 ~20 ~66 ~123 ~22 ~66 stained_hardened_clay 13
fill ~124 ~20 ~65 ~129 ~20 ~65 stained_hardened_clay 13
setblock ~125 ~20 ~64 stained_hardened_clay 13
fill ~128 ~20 ~64 ~129 ~20 ~64 stained_hardened_clay 13
fill ~129 ~20 ~61 ~130 ~20 ~61 stained_hardened_clay 13
fill ~129 ~20 ~62 ~130 ~20 ~62 stained_hardened_clay 13
fill ~129 ~20 ~63 ~130 ~20 ~63 stained_hardened_clay 13
fill ~130 ~20 ~52 ~131 ~20 ~52 stained_hardened_clay 13
fill ~130 ~20 ~53 ~131 ~20 ~53 stained_hardened_clay 13
fill ~131 ~20 ~51 ~132 ~20 ~51 stained_hardened_clay 13
fill ~131 ~20 ~55 ~131 ~27 ~55 stained_hardened_clay 13
fill ~131 ~20 ~59 ~131 ~23 ~59 stained_hardened_clay 13
fill ~132 ~20 ~50 ~133 ~20 ~50 stained_hardened_clay 13
fill ~66 ~21 ~47 ~70 ~21 ~47 stained_hardened_clay 13
fill ~66 ~21 ~48 ~134 ~21 ~48 stained_hardened_clay 13
fill ~66 ~21 ~49 ~67 ~21 ~49 stained_hardened_clay 13
fill ~66 ~21 ~50 ~67 ~21 ~50 stained_hardened_clay 13
fill ~68 ~21 ~52 ~69 ~21 ~52 stained_hardened_clay 13
fill ~68 ~21 ~60 ~68 ~24 ~60 stained_hardened_clay 13
fill ~69 ~21 ~62 ~70 ~21 ~62 stained_hardened_clay 13
fill ~69 ~21 ~63 ~69 ~23 ~63 stained_hardened_clay 13
fill ~69 ~21 ~64 ~70 ~21 ~64 stained_hardened_clay 13
fill ~69 ~21 ~65 ~76 ~21 ~65 stained_hardened_clay 13
fill ~73 ~21 ~47 ~99 ~21 ~47 stained_hardened_clay 13
fill ~75 ~21 ~66 ~75 ~23 ~66 stained_hardened_clay 13
fill ~76 ~21 ~67 ~76 ~24 ~67 stained_hardened_clay 13
fill ~77 ~21 ~68 ~77 ~25 ~68 stained_hardened_clay 13
fill ~79 ~21 ~69 ~81 ~21 ~69 stained_hardened_clay 13
fill ~81 ~21 ~71 ~81 ~24 ~71 stained_hardened_clay 13
fill ~82 ~21 ~75 ~82 ~27 ~75 stained_hardened_clay 13
fill ~83 ~21 ~76 ~83 ~25 ~76 stained_hardened_clay 13
fill ~83 ~21 ~77 ~84 ~21 ~77 stained_hardened_clay 13
fill ~83 ~21 ~78 ~85 ~21 ~78 stained_hardened_clay 13
fill ~84 ~21 ~79 ~86 ~21 ~79 stained_hardened_clay 13
fill ~85 ~21 ~80 ~88 ~21 ~80 stained_hardened_clay 13
fill ~87 ~21 ~81 ~91 ~21 ~81 stained_hardened_clay 13
fill ~91 ~21 ~80 ~93 ~21 ~80 stained_hardened_clay 13
fill ~92 ~21 ~79 ~97 ~21 ~79 stained_hardened_clay 13
fill ~96 ~21 ~78 ~103 ~21 ~78 stained_hardened_clay 13
fill ~102 ~21 ~79 ~107 ~21 ~79 stained_hardened_clay 13
fill ~106 ~21 ~80 ~108 ~21 ~80 stained_hardened_clay 13
fill ~108 ~21 ~81 ~112 ~21 ~81 stained_hardened_clay 13
fill ~111 ~21 ~80 ~114 ~21 ~80 stained_hardened_clay 13
fill ~113 ~21 ~79 ~115 ~21 ~79 stained_hardened_clay 13
fill ~114 ~21 ~78 ~116 ~21 ~78 stained_hardened_clay 13
fill ~115 ~21 ~77 ~116 ~21 ~77 stained_hardened_clay 13
fill ~117 ~21 ~70 ~118 ~21 ~70 stained_hardened_clay 13
fill ~118 ~21 ~71 ~118 ~24 ~71 stained_hardened_clay 13
fill ~119 ~21 ~68 ~122 ~21 ~68 stained_hardened_clay 13
fill ~120 ~21 ~69 ~120 ~25 ~69 stained_hardened_clay 13
fill ~123 ~21 ~67 ~123 ~23 ~67 stained_hardened_clay 13
fill ~124 ~21 ~65 ~130 ~21 ~65 stained_hardened_clay 13
fill ~124 ~21 ~66 ~125 ~21 ~66 stained_hardened_clay 13
fill ~127 ~21 ~49 ~133 ~21 ~49 stained_hardened_clay 13
fill ~129 ~21 ~62 ~130 ~21 ~62 stained_hardened_clay 13
fill ~129 ~21 ~63 ~130 ~21 ~63 stained_hardened_clay 13
fill ~129 ~21 ~64 ~130 ~21 ~64 stained_hardened_clay 13
fill ~130 ~21 ~52 ~131 ~21 ~52 stained_hardened_clay 13
fill ~130 ~21 ~53 ~130 ~28 ~53 stained_hardened_clay 13
fill ~130 ~21 ~61 ~131 ~21 ~61 stained_hardened_clay 13
fill ~131 ~21 ~51 ~132 ~21 ~51 stained_hardened_clay 13
fill ~131 ~21 ~54 ~131 ~29 ~54 stained_hardened_clay 13
fill ~131 ~21 ~60 ~131 ~23 ~60 stained_hardened_clay 13
fill ~132 ~21 ~50 ~133 ~21 ~50 stained_hardened_clay 13
fill ~66 ~22 ~47 ~134 ~22 ~47 stained_hardened_clay 13
fill ~66 ~22 ~48 ~66 ~25 ~48 stained_hardened_clay 13
fill ~66 ~22 ~49 ~67 ~22 ~49 stained_hardened_clay 13
fill ~67 ~22 ~50 ~68 ~22 ~50 stained_hardened_clay 13
fill ~68 ~22 ~46 ~69 ~22 ~46 stained_hardened_clay 13
fill ~68 ~22 ~52 ~69 ~22 ~52 stained_hardened_clay 13
fill ~68 ~22 ~54 ~68 ~30 ~54 stained_hardened_clay 13
fill ~68 ~22 ~61 ~68 ~24 ~61 stained_hardened_clay 13
fill ~68 ~22 ~62 ~69 ~22 ~62 stained_hardened_clay 13
fill ~68 ~22 ~63 ~68 ~24 ~63 stained_hardened_clay 13
fill ~69 ~22 ~64 ~69 ~23 ~64 stained_hardened_clay 13
fill ~69 ~22 ~65 ~75 ~22 ~65 stained_hardened_clay 13
fill ~70 ~22 ~48 ~73 ~22 ~48 stained_hardened_clay 13
fill ~73 ~22 ~66 ~76 ~22 ~66 stained_hardened_clay 13
fill ~75 ~22 ~46 ~78 ~22 ~46 stained_hardened_clay 13
fill ~75 ~22 ~67 ~75 ~24 ~67 stained_hardened_clay 13
fill ~76 ~22 ~68 ~76 ~26 ~68 stained_hardened_clay 13
fill ~79 ~22 ~69 ~81 ~22 ~69 stained_hardened_clay 13
fill ~80 ~22 ~70 ~80 ~25 ~70 stained_hardened_clay 13
fill ~81 ~22 ~72 ~81 ~25 ~72 stained_hardened_clay 13
fill ~83 ~22 ~77 ~83 ~27 ~77 stained_hardened_clay 13
fill ~83 ~22 ~78 ~84 ~22 ~78 stained_hardened_clay 13
fill ~84 ~22 ~79 ~85 ~22 ~79 stained_hardened_clay 13
fill ~84 ~22 ~80 ~87 ~22 ~80 stained_hardened_clay 13
fill ~86 ~22 ~81 ~91 ~22 ~81 stained_hardened_clay 13
fill ~88 ~22 ~82 ~89 ~22 ~82 stained_hardened_clay 13
fill ~91 ~22 ~80 ~93 ~22 ~80 stained_hardened_clay 13
fill ~93 ~22 ~79 ~107 ~22 ~79 stained_hardened_clay 13
fill ~97 ~22 ~78 ~102 ~22 ~78 stained_hardened_clay 13
fill ~98 ~22 ~48 ~134 ~22 ~48 stained_hardened_clay 13
fill ~106 ~22 ~80 ~108 ~22 ~80 stained_hardened_clay 13
fill ~108 ~22 ~81 ~113 ~22 ~81 stained_hardened_clay 13
fill ~110 ~22 ~82 ~111 ~22 ~82 stained_hardened_clay 13
fill ~112 ~22 ~80 ~115 ~22 ~80 stained_hardened_clay 13
fill ~114 ~22 ~79 ~116 ~22 ~79 stained_hardened_clay 13
fill ~115 ~22 ~78 ~116 ~22 ~78 stained_hardened_clay 13
fill ~116 ~22 ~77 ~116 ~26 ~77 stained_hardened_clay 13
fill ~117 ~22 ~76 ~117 ~29 ~76 stained_hardened_clay 13
fill ~118 ~22 ~70 ~119 ~22 ~70 stained_hardened_clay 13
fill ~118 ~22 ~72 ~118 ~24 ~72 stained_hardened_clay 13
fill ~118 ~22 ~73 ~118 ~25 ~73 stained_hardened_clay 13
fill ~120 ~22 ~68 ~123 ~22 ~68 stained_hardened_clay 13
fill ~124 ~22 ~65 ~130 ~22 ~65 stained_hardened_clay 13
fill ~124 ~22 ~66 ~126 ~22 ~66 stained_hardened_clay 13
fill ~124 ~22 ~67 ~124 ~24 ~67 stained_hardened_clay 13
fill ~130 ~22 ~52 ~131 ~22 ~52 stained_hardened_clay 13
fill ~130 ~22 ~61 ~131 ~22 ~61 stained_hardened_clay 13
fill ~130 ~22 ~62 ~131 ~22 ~62 stained_hardened_clay 13
fill ~130 ~22 ~63 ~131 ~22 ~63 stained_hardened_clay 13
fill ~130 ~22 ~64 ~130 ~23 ~64 stained_hardened_clay 13
fill ~131 ~22 ~50 ~133 ~22 ~50 stained_hardened_clay 13
fill ~131 ~22 ~51 ~132 ~22 ~51 stained_hardened_clay 13
fill ~132 ~22 ~49 ~133 ~22 ~49 stained_hardened_clay 13
fill ~132 ~22 ~56 ~132 ~28 ~56 stained_hardened_clay 13
fill ~132 ~22 ~57 ~132 ~27 ~57 stained_hardened_clay 13
fill ~132 ~22 ~58 ~132 ~26 ~58 stained_hardened_clay 13
fill ~132 ~22 ~59 ~132 ~25 ~59 stained_hardened_clay 13
fill ~65 ~23 ~47 ~134 ~23 ~47 stained_hardened_clay 13
fill ~66 ~23 ~46 ~72 ~23 ~46 stained_hardened_clay 13
fill ~66 ~23 ~49 ~67 ~23 ~49 stained_hardened_clay 13
fill ~67 ~23 ~50 ~68 ~23 ~50 stained_hardened_clay 13
fill ~67 ~23 ~56 ~67 ~29 ~56 stained_hardened_clay 13
fill ~67 ~23 ~57 ~67 ~27 ~57 stained_hardened_clay 13
fill ~67 ~23 ~58 ~67 ~26 ~58 stained_hardened_clay 13
fill ~67 ~23 ~59 ~67 ~26 ~59 stained_hardened_clay 13
fill ~67 ~23 ~60 ~67 ~25 ~60 stained_hardened_clay 13
fill ~67 ~23 ~61 ~67 ~25 ~61 stained_hardened_clay 13
fill ~68 ~23 ~52 ~69 ~23 ~52 stained_hardened_clay 13
fill ~68 ~23 ~62 ~68 ~24 ~62 stained_hardened_clay 13
fill ~68 ~23 ~64 ~68 ~25 ~64 stained_hardened_clay 13
fill ~68 ~23 ~65 ~73 ~23 ~65 stained_hardened_clay 13
fill ~69 ~23 ~51 ~69 ~34 ~51 stained_hardened_clay 13
fill ~69 ~23 ~66 ~75 ~23 ~66 stained_hardened_clay 13
fill ~74 ~23 ~46 ~121 ~23 ~46 stained_hardened_clay 13
fill ~74 ~23 ~67 ~74 ~26 ~67 stained_hardened_clay 13
fill ~75 ~23 ~68 ~75 ~26 ~68 stained_hardened_clay 13
fill ~78 ~23 ~69 ~80 ~23 ~69 stained_hardened_clay 13
fill ~79 ~23 ~70 ~79 ~26 ~70 stained_hardened_clay 13
fill ~80 ~23 ~71 ~80 ~26 ~71 stained_hardened_clay 13
fill ~81 ~23 ~73 ~81 ~26 ~73 stained_hardened_clay 13
fill ~82 ~23 ~76 ~82 ~30 ~76 stained_hardened_clay 13
fill ~83 ~23 ~78 ~84 ~23 ~78 stained_hardened_clay 13
fill ~83 ~23 ~79 ~84 ~23 ~79 stained_hardened_clay 13
fill ~84 ~23 ~80 ~86 ~23 ~80 stained_hardened_clay 13
fill ~85 ~23 ~81 ~91 ~23 ~81 stained_hardened_clay 13
fill ~88 ~23 ~82 ~90 ~23 ~82 stained_hardened_clay 13
fill ~91 ~23 ~80 ~94 ~23 ~80 stained_hardened_clay 13
fill ~93 ~23 ~79 ~106 ~23 ~79 stained_hardened_clay 13
fill ~99 ~23 ~78 ~100 ~23 ~78 stained_hardened_clay 13
fill ~105 ~23 ~80 ~108 ~23 ~80 stained_hardened_clay 13
fill ~108 ~23 ~81 ~114 ~23 ~81 stained_hardened_clay 13
fill ~109 ~23 ~82 ~111 ~23 ~82 stained_hardened_clay 13
fill ~113 ~23 ~80 ~115 ~23 ~80 stained_hardened_clay 13
fill ~115 ~23 ~78 ~116 ~23 ~78 stained_hardened_clay 13
fill ~115 ~23 ~79 ~116 ~23 ~79 stained_hardened_clay 13
fill ~117 ~23 ~77 ~117 ~31 ~77 stained_hardened_clay 13
fill ~118 ~23 ~70 ~120 ~23 ~70 stained_hardened_clay 13
fill ~118 ~23 ~74 ~118 ~27 ~74 stained_hardened_clay 13
fill ~119 ~23 ~71 ~119 ~25 ~71 stained_hardened_clay 13
fill ~120 ~23 ~68 ~124 ~23 ~68 stained_hardened_clay 13
fill ~121 ~23 ~69 ~121 ~26 ~69 stained_hardened_clay 13
fill ~124 ~23 ~66 ~127 ~23 ~66 stained_hardened_clay 13
fill ~125 ~23 ~67 ~125 ~25 ~67 stained_hardened_clay 13
setblock ~126 ~23 ~65 stained_hardened_clay 13
fill ~128 ~23 ~65 ~131 ~23 ~65 stained_hardened_clay 13
fill ~129 ~23 ~66 ~130 ~23 ~66 stained_hardened_clay 13
fill ~130 ~23 ~51 ~131 ~23 ~51 stained_hardened_clay 13
fill ~130 ~23 ~52 ~131 ~23 ~52 stained_hardened_clay 13
fill ~130 ~23 ~63 ~131 ~23 ~63 stained_hardened_clay 13
fill ~131 ~23 ~50 ~132 ~23 ~50 stained_hardened_clay 13
fill ~131 ~23 ~53 ~131 ~32 ~53 stained_hardened_clay 13
fill ~131 ~23 ~61 ~132 ~23 ~61 stained_hardened_clay 13
fill ~131 ~23 ~62 ~132 ~23 ~62 stained_hardened_clay 13
fill ~131 ~23 ~64 ~131 ~25 ~64 stained_hardened_clay 13
fill ~132 ~23 ~49 ~133 ~23 ~49 stained_hardened_clay 13
fill ~132 ~23 ~60 ~132 ~25 ~60 stained_hardened_clay 13
fill ~133 ~23 ~48 ~133 ~26 ~48 stained_hardened_clay 13
fill ~65 ~24 ~46 ~134 ~24 ~46 stained_hardened_clay 13
fill ~65 ~24 ~47 ~66 ~24 ~47 stained_hardened_clay 13
fill ~66 ~24 ~49 ~68 ~24 ~49 stained_hardened_clay 13
fill ~67 ~24 ~45 ~72 ~24 ~45 stained_hardened_clay 13
fill ~67 ~24 ~48 ~67 ~28 ~48 stained_hardened_clay 13
fill ~67 ~24 ~50 ~68 ~24 ~50 stained_hardened_clay 13
fill ~67 ~24 ~62 ~67 ~25 ~62 stained_hardened_clay 13
fill ~67 ~24 ~63 ~67 ~26 ~63 stained_hardened_clay 13
fill ~67 ~24 ~64 ~67 ~26 ~64 stained_hardened_clay 13
fill ~68 ~24 ~65 ~72 ~24 ~65 stained_hardened_clay 13
fill ~68 ~24 ~66 ~74 ~24 ~66 stained_hardened_clay 13
fill ~69 ~24 ~52 ~69 ~32 ~52 stained_hardened_clay 13
fill ~72 ~24 ~47 ~74 ~24 ~47 stained_hardened_clay 13
fill ~73 ~24 ~67 ~73 ~27 ~67 stained_hardened_clay 13
fill ~74 ~24 ~68 ~74 ~27 ~68 stained_hardened_clay 13
fill ~76 ~24 ~45 ~91 ~24 ~45 stained_hardened_clay 13
fill ~77 ~24 ~69 ~79 ~24 ~69 stained_hardened_clay 13
fill ~80 ~24 ~72 ~80 ~26 ~72 stained_hardened_clay 13
fill ~81 ~24 ~74 ~81 ~27 ~74 stained_hardened_clay 13
fill ~82 ~24 ~77 ~82 ~31 ~77 stained_hardened_clay 13
fill ~83 ~24 ~78 ~83 ~30 ~78 stained_hardened_clay 13
fill ~83 ~24 ~79 ~84 ~24 ~79 stained_hardened_clay 13
fill ~84 ~24 ~80 ~85 ~24 ~80 stained_hardened_clay 13
fill ~85 ~24 ~81 ~88 ~24 ~81 stained_hardened_clay 13
fill ~88 ~24 ~82 ~90 ~24 ~82 stained_hardened_clay 13
fill ~90 ~24 ~81 ~92 ~24 ~81 stained_hardened_clay 13
fill ~91 ~24 ~80 ~95 ~24 ~80 stained_hardened_clay 13
fill ~94 ~24 ~79 ~105 ~24 ~79 stained_hardened_clay 13
fill ~95 ~24 ~45 ~103 ~24 ~45 stained_hardened_clay 13
fill ~104 ~24 ~80 ~108 ~24 ~80 stained_hardened_clay 13
fill ~107 ~24 ~81 ~109 ~24 ~81 stained_hardened_clay 13
fill ~109 ~24 ~82 ~111 ~24 ~82 stained_hardened_clay 13
fill ~111 ~24 ~81 ~114 ~24 ~81 stained_hardened_clay 13
fill ~114 ~24 ~80 ~115 ~24 ~80 stained_hardened_clay 13
fill ~115 ~24 ~79 ~116 ~24 ~79 stained_hardened_clay 13
fill ~116 ~24 ~78 ~116 ~30 ~78 stained_hardened_clay 13
fill ~117 ~24 ~47 ~134 ~24 ~47 stained_hardened_clay 13
fill ~119 ~24 ~70 ~121 ~24 ~70 stained_hardened_clay 13
fill ~119 ~24 ~72 ~119 ~26 ~72 stained_hardened_clay 13
fill ~119 ~24 ~73 ~119 ~27 ~73 stained_hardened_clay 13
fill ~121 ~24 ~68 ~125 ~24 ~68 stained_hardened_clay 13
fill ~122 ~24 ~69 ~123 ~24 ~69 stained_hardened_clay 13
fill ~125 ~24 ~66 ~131 ~24 ~66 stained_hardened_clay 13
fill ~126 ~24 ~67 ~126 ~27 ~67 stained_hardened_clay 13
fill ~128 ~24 ~65 ~131 ~24 ~65 stained_hardened_clay 13
fill ~130 ~24 ~51 ~131 ~24 ~51 stained_hardened_clay 13
fill ~130 ~24 ~52 ~130 ~31 ~52 stained_hardened_clay 13
fill ~131 ~24 ~49 ~133 ~24 ~49 stained_hardened_clay 13
fill ~131 ~24 ~50 ~132 ~24 ~50 stained_hardened_clay 13
fill ~131 ~24 ~61 ~132 ~24 ~61 stained_hardened_clay 13
fill ~131 ~24 ~62 ~132 ~24 ~62 stained_hardened_clay 13
fill ~131 ~24 ~63 ~132 ~24 ~63 stained_hardened_clay 13
fill ~132 ~24 ~48 ~132 ~28 ~48 stained_hardened_clay 13
fill ~132 ~24 ~55 ~132 ~30 ~55 stained_hardened_clay 13
fill ~132 ~24 ~64 ~132 ~26 ~64 stained_hardened_clay 13
fill ~66 ~25 ~45 ~134 ~25 ~45 stained_hardened_clay 13
fill ~66 ~25 ~46 ~67 ~25 ~46 stained_hardened_clay 13
fill ~66 ~25 ~47 ~67 ~25 ~47 stained_hardened_clay 13
fill ~66 ~25 ~58 ~66 ~28 ~58 stained_hardened_clay 13
fill ~66 ~25 ~59 ~66 ~27 ~59 stained_hardened_clay 13
fill ~66 ~25 ~60 ~66 ~27 ~60 stained_hardened_clay 13
fill ~66 ~25 ~61 ~66 ~27 ~61 stained_hardened_clay 13
fill ~66 ~25 ~62 ~66 ~27 ~62 stained_hardened_clay 13
fill ~66 ~25 ~63 ~66 ~27 ~63 stained_hardened_clay 13
fill ~67 ~25 ~49 ~68 ~25 ~49 stained_hardened_clay 13
fill ~67 ~25 ~55 ~67 ~30 ~55 stained_hardened_clay 13
fill ~67 ~25 ~65 ~68 ~25 ~65 stained_hardened_clay 13
fill ~67 ~25 ~66 ~73 ~25 ~66 stained_hardened_clay 13
fill ~68 ~25 ~50 ~69 ~25 ~50 stained_hardened_clay 13
fill ~68 ~25 ~53 ~68 ~32 ~53 stained_hardened_clay 13
fill ~69 ~25 ~44 ~70 ~25 ~44 stained_hardened_clay 13
fill ~71 ~25 ~46 ~76 ~25 ~46 stained_hardened_clay 13
fill ~72 ~25 ~67 ~72 ~28 ~67 stained_hardened_clay 13
fill ~75 ~25 ~69 ~79 ~25 ~69 stained_hardened_clay 13
fill ~78 ~25 ~70 ~78 ~28 ~70 stained_hardened_clay 13
fill ~79 ~25 ~71 ~79 ~27 ~71 stained_hardened_clay 13
fill ~80 ~25 ~73 ~80 ~27 ~73 stained_hardened_clay 13
fill ~81 ~25 ~44 ~83 ~25 ~44 stained_hardened_clay 13
fill ~81 ~25 ~75 ~81 ~30 ~75 stained_hardened_clay 13
fill ~83 ~25 ~79 ~84 ~25 ~79 stained_hardened_clay 13
fill ~84 ~25 ~80 ~85 ~25 ~80 stained_hardened_clay 13
fill ~85 ~25 ~81 ~88 ~25 ~81 stained_hardened_clay 13
fill ~87 ~25 ~82 ~90 ~25 ~82 stained_hardened_clay 13
fill ~89 ~25 ~46 ~99 ~25 ~46 stained_hardened_clay 13
fill ~90 ~25 ~81 ~95 ~25 ~81 stained_hardened_clay 13
fill ~92 ~25 ~80 ~97 ~25 ~80 stained_hardened_clay 13
fill ~93 ~25 ~82 ~94 ~25 ~82 stained_hardened_clay 13
fill ~95 ~25 ~79 ~104 ~25 ~79 stained_hardened_clay 13
fill ~101 ~25 ~46 ~134 ~25 ~46 stained_hardened_clay 13
fill ~102 ~25 ~80 ~107 ~25 ~80 stained_hardened_clay 13
fill ~104 ~25 ~81 ~109 ~25 ~81 stained_hardened_clay 13
fill ~106 ~25 ~82 ~106 ~27 ~82 stained_hardened_clay 13
fill ~109 ~25 ~82 ~112 ~25 ~82 stained_hardened_clay 13
fill ~111 ~25 ~81 ~114 ~25 ~81 stained_hardened_clay 13
fill ~114 ~25 ~80 ~115 ~25 ~80 stained_hardened_clay 13
fill ~115 ~25 ~79 ~116 ~25 ~79 stained_hardened_clay 13
fill ~118 ~25 ~75 ~118 ~30 ~75 stained_hardened_clay 13
fill ~119 ~25 ~70 ~121 ~25 ~70 stained_hardened_clay 13
fill ~119 ~25 ~74 ~119 ~28 ~74 stained_hardened_clay 13
fill ~120 ~25 ~71 ~120 ~27 ~71 stained_hardened_clay 13
fill ~120 ~25 ~72 ~120 ~27 ~72 stained_hardened_clay 13
fill ~122 ~25 ~68 ~126 ~25 ~68 stained_hardened_clay 13
fill ~122 ~25 ~69 ~124 ~25 ~69 stained_hardened_clay 13
fill ~126 ~25 ~66 ~132 ~25 ~66 stained_hardened_clay 13
fill ~127 ~25 ~67 ~127 ~27 ~67 stained_hardened_clay 13
fill ~130 ~25 ~50 ~131 ~25 ~50 stained_hardened_clay 13
fill ~130 ~25 ~51 ~131 ~25 ~51 stained_hardened_clay 13
fill ~131 ~25 ~49 ~132 ~25 ~49 stained_hardened_clay 13
fill ~131 ~25 ~65 ~132 ~25 ~65 stained_hardened_clay 13
fill ~132 ~25 ~61 ~133 ~25 ~61 stained_hardened_clay 13
fill ~132 ~25 ~62 ~133 ~25 ~62 stained_hardened_clay 13
fill ~132 ~25 ~63 ~133 ~25 ~63 stained_hardened_clay 13
fill ~133 ~25 ~47 ~133 ~27 ~47 stained_hardened_clay 13
fill ~133 ~25 ~58 ~133 ~28 ~58 stained_hardened_clay 13
fill ~133 ~25 ~59 ~133 ~27 ~59 stained_hardened_clay 13
fill ~133 ~25 ~60 ~133 ~27 ~60 stained_hardened_clay 13
fill ~65 ~26 ~45 ~134 ~26 ~45 stained_hardened_clay 13
fill ~66 ~26 ~44 ~73 ~26 ~44 stained_hardened_clay 13
fill ~66 ~26 ~46 ~66 ~29 ~46 stained_hardened_clay 13
fill ~66 ~26 ~47 ~67 ~26 ~47 stained_hardened_clay 13
fill ~66 ~26 ~57 ~66 ~29 ~57 stained_hardened_clay 13
fill ~66 ~26 ~64 ~66 ~27 ~64 stained_hardened_clay 13
fill ~66 ~26 ~65 ~67 ~26 ~65 stained_hardened_clay 13
fill ~66 ~26 ~66 ~72 ~26 ~66 stained_hardened_clay 13
fill ~67 ~26 ~49 ~69 ~26 ~49 stained_hardened_clay 13
fill ~68 ~26 ~48 ~68 ~30 ~48 stained_hardened_clay 13
fill ~68 ~26 ~50 ~69 ~26 ~50 stained_hardened_clay 13
fill ~70 ~26 ~67 ~74 ~26 ~67 stained_hardened_clay 13
fill ~73 ~26 ~68 ~73 ~28 ~68 stained_hardened_clay 13
fill ~74 ~26 ~46 ~75 ~26 ~46 stained_hardened_clay 13
fill ~74 ~26 ~69 ~78 ~26 ~69 stained_hardened_clay 13
fill ~77 ~26 ~70 ~77 ~29 ~70 stained_hardened_clay 13
fill ~78 ~26 ~44 ~122 ~26 ~44 stained_hardened_clay 13
fill ~78 ~26 ~71 ~78 ~28 ~71 stained_hardened_clay 13
fill ~79 ~26 ~72 ~79 ~27 ~72 stained_hardened_clay 13
fill ~79 ~26 ~73 ~79 ~28 ~73 stained_hardened_clay 13
fill ~80 ~26 ~74 ~80 ~29 ~74 stained_hardened_clay 13
fill ~83 ~26 ~79 ~84 ~26 ~79 stained_hardened_clay 13
fill ~84 ~26 ~80 ~85 ~26 ~80 stained_hardened_clay 13
fill ~85 ~26 ~81 ~87 ~26 ~81 stained_hardened_clay 13
fill ~87 ~26 ~82 ~96 ~26 ~82 stained_hardened_clay 13
fill ~90 ~26 ~81 ~97 ~26 ~81 stained_hardened_clay 13
fill ~95 ~26 ~80 ~104 ~26 ~80 stained_hardened_clay 13
fill ~97 ~26 ~79 ~102 ~26 ~79 stained_hardened_clay 13
fill ~102 ~26 ~81 ~109 ~26 ~81 stained_hardened_clay 13
fill ~104 ~26 ~82 ~112 ~26 ~82 stained_hardened_clay 13
fill ~112 ~26 ~81 ~114 ~26 ~81 stained_hardened_clay 13
fill ~114 ~26 ~80 ~116 ~26 ~80 stained_hardened_clay 13
fill ~115 ~26 ~79 ~116 ~26 ~79 stained_hardened_clay 13
fill ~117 ~26 ~78 ~117 ~32 ~78 stained_hardened_clay 13
fill ~118 ~26 ~76 ~118 ~32 ~76 stained_hardened_clay 13
fill ~120 ~26 ~70 ~122 ~26 ~70 stained_hardened_clay 13
fill ~120 ~26 ~73 ~120 ~28 ~73 stained_hardened_clay 13
fill ~121 ~26 ~71 ~121 ~28 ~71 stained_hardened_clay 13
fill ~122 ~26 ~69 ~125 ~26 ~69 stained_hardened_clay 13
fill ~124 ~26 ~68 ~127 ~26 ~68 stained_hardened_clay 13
fill ~127 ~26 ~66 ~133 ~26 ~66 stained_hardened_clay 13
fill ~128 ~26 ~67 ~129 ~26 ~67 stained_hardened_clay 13
fill ~130 ~26 ~50 ~131 ~26 ~50 stained_hardened_clay 13
fill ~130 ~26 ~51 ~130 ~34 ~51 stained_hardened_clay 13
fill ~131 ~26 ~48 ~131 ~30 ~48 stained_hardened_clay 13
fill ~131 ~26 ~49 ~132 ~26 ~49 stained_hardened_clay 13
fill ~132 ~26 ~47 ~132 ~30 ~47 stained_hardened_clay 13
fill ~132 ~26 ~63 ~133 ~26 ~63 stained_hardened_clay 13
fill ~132 ~26 ~65 ~133 ~26 ~65 stained_hardened_clay 13
fill ~133 ~26 ~46 ~134 ~26 ~46 stained_hardened_clay 13
fill ~133 ~26 ~57 ~133 ~29 ~57 stained_hardened_clay 13
fill ~133 ~26 ~61 ~133 ~27 ~61 stained_hardened_clay 13
fill ~133 ~26 ~62 ~133 ~27 ~62 stained_hardened_clay 13
fill ~133 ~26 ~64 ~133 ~27 ~64 stained_hardened_clay 13
fill ~65 ~27 ~45 ~66 ~27 ~45 stained_hardened_clay 13
fill ~65 ~27 ~58 ~65 ~30 ~58 stained_hardened_clay 13
fill ~65 ~27 ~59 ~65 ~29 ~59 stained_hardened_clay 13
fill ~65 ~27 ~60 ~65 ~29 ~60 stained_hardened_clay 13
fill ~65 ~27 ~61 ~65 ~28 ~61 stained_hardened_clay 13
fill ~65 ~27 ~62 ~65 ~28 ~62 stained_hardened_clay 13
fill ~65 ~27 ~63 ~65 ~28 ~63 stained_hardened_clay 13
fill ~65 ~27 ~64 ~65 ~28 ~64 stained_hardened_clay 13
fill ~65 ~27 ~65 ~66 ~27 ~65 stained_hardened_clay 13
fill ~65 ~27 ~66 ~71 ~27 ~66 stained_hardened_clay 13
fill ~66 ~27 ~44 ~134 ~27 ~44 stained_hardened_clay 13
fill ~66 ~27 ~47 ~67 ~27 ~47 stained_hardened_clay 13
fill ~66 ~27 ~56 ~66 ~30 ~56 stained_hardened_clay 13
fill ~67 ~27 ~46 ~67 ~31 ~46 stained_hardened_clay 13
fill ~68 ~27 ~49 ~69 ~27 ~49 stained_hardened_clay 13
fill ~68 ~27 ~50 ~69 ~27 ~50 stained_hardened_clay 13
fill ~69 ~27 ~43 ~72 ~27 ~43 stained_hardened_clay 13
fill ~69 ~27 ~67 ~73 ~27 ~67 stained_hardened_clay 13
fill ~72 ~27 ~68 ~72 ~29 ~68 stained_hardened_clay 13
fill ~73 ~27 ~45 ~78 ~27 ~45 stained_hardened_clay 13
fill ~73 ~27 ~69 ~77 ~27 ~69 stained_hardened_clay 13
fill ~76 ~27 ~70 ~76 ~30 ~70 stained_hardened_clay 13
fill ~78 ~27 ~72 ~78 ~28 ~72 stained_hardened_clay 13
fill ~78 ~27 ~73 ~78 ~29 ~73 stained_hardened_clay 13
fill ~79 ~27 ~74 ~79 ~30 ~74 stained_hardened_clay 13
fill ~80 ~27 ~43 ~88 ~27 ~43 stained_hardened_clay 13
fill ~80 ~27 ~75 ~80 ~31 ~75 stained_hardened_clay 13
fill ~81 ~27 ~76 ~81 ~32 ~76 stained_hardened_clay 13
fill ~82 ~27 ~78 ~82 ~32 ~78 stained_hardened_clay 13
fill ~83 ~27 ~79 ~84 ~27 ~79 stained_hardened_clay 13
fill ~83 ~27 ~80 ~85 ~27 ~80 stained_hardened_clay 13
fill ~84 ~27 ~81 ~87 ~27 ~81 stained_hardened_clay 13
fill ~87 ~27 ~82 ~97 ~27 ~82 stained_hardened_clay 13
fill ~90 ~27 ~81 ~91 ~27 ~81 stained_hardened_clay 13
fill ~92 ~27 ~83 ~95 ~27 ~83 stained_hardened_clay 13
fill ~95 ~27 ~81 ~99 ~27 ~81 stained_hardened_clay 13
fill ~97 ~27 ~80 ~103 ~27 ~80 stained_hardened_clay 13
fill ~101 ~27 ~81 ~104 ~27 ~81 stained_hardened_clay 13
fill ~103 ~27 ~82 ~112 ~27 ~82 stained_hardened_clay 13
fill ~104 ~27 ~83 ~107 ~27 ~83 stained_hardened_clay 13
fill ~108 ~27 ~81 ~109 ~27 ~81 stained_hardened_clay 13
fill ~112 ~27 ~81 ~115 ~27 ~81 stained_hardened_clay 13
fill ~114 ~27 ~80 ~116 ~27 ~80 stained_hardened_clay 13
fill ~115 ~27 ~79 ~116 ~27 ~79 stained_hardened_clay 13
fill ~119 ~27 ~75 ~119 ~31 ~75 stained_hardened_clay 13
fill ~120 ~27 ~74 ~120 ~29 ~74 stained_hardened_clay 13
fill ~121 ~27 ~45 ~134 ~27 ~45 stained_hardened_clay 13
fill ~121 ~27 ~70 ~123 ~27 ~70 stained_hardened_clay 13
fill ~121 ~27 ~72 ~121 ~28 ~72 stained_hardened_clay 13
fill ~121 ~27 ~73 ~121 ~29 ~73 stained_hardened_clay 13
fill ~122 ~27 ~69 ~126 ~27 ~69 stained_hardened_clay 13
fill ~122 ~27 ~71 ~122 ~30 ~71 stained_hardened_clay 13
fill ~125 ~27 ~68 ~128 ~27 ~68 stained_hardened_clay 13
fill ~128 ~27 ~67 ~130 ~27 ~67 stained_hardened_clay 13
fill ~129 ~27 ~66 ~134 ~27 ~66 stained_hardened_clay 13
fill ~130 ~27 ~49 ~131 ~27 ~49 stained_hardened_clay 13
fill ~130 ~27 ~50 ~131 ~27 ~50 stained_hardened_clay 13
fill ~132 ~27 ~46 ~133 ~27 ~46 stained_hardened_clay 13
fill ~132 ~27 ~54 ~132 ~32 ~54 stained_hardened_clay 13
fill ~133 ~27 ~56 ~133 ~30 ~56 stained_hardened_clay 13
fill ~133 ~27 ~63 ~134 ~27 ~63 stained_hardened_clay 13
fill ~133 ~27 ~65 ~134 ~27 ~65 stained_hardened_clay 13
fill ~134 ~27 ~58 ~134 ~29 ~58 stained_hardened_clay 13
fill ~134 ~27 ~59 ~134 ~29 ~59 stained_hardened_clay 13
fill ~134 ~27 ~60 ~134 ~28 ~60 stained_hardened_clay 13
fill ~134 ~27 ~61 ~134 ~28 ~61 stained_hardened_clay 13
fill ~134 ~27 ~62 ~134 ~28 ~62 stained_hardened_clay 13
fill ~134 ~27 ~64 ~134 ~28 ~64 stained_hardened_clay 13
fill ~64 ~28 ~60 ~64 ~30 ~60 stained_hardened_clay 13
fill ~64 ~28 ~61 ~64 ~30 ~61 stained_hardened_clay 13
fill ~64 ~28 ~62 ~64 ~29 ~62 stained_hardened_clay 13
fill ~64 ~28 ~63 ~64 ~29 ~63 stained_hardened_clay 13
fill ~64 ~28 ~64 ~64 ~29 ~64 stained_hardened_clay 13
fill ~64 ~28 ~65 ~65 ~28 ~65 stained_hardened_clay 13
fill ~64 ~28 ~66 ~69 ~28 ~66 stained_hardened_clay 13
fill ~65 ~28 ~57 ~65 ~31 ~57 stained_hardened_clay 13
fill ~65 ~28 ~67 ~72 ~28 ~67 stained_hardened_clay 13
fill ~66 ~28 ~43 ~75 ~28 ~43 stained_hardened_clay 13
fill ~66 ~28 ~44 ~69 ~28 ~44 stained_hardened_clay 13
fill ~66 ~28 ~45 ~67 ~28 ~45 stained_hardened_clay 13
fill ~66 ~28 ~55 ~66 ~32 ~55 stained_hardened_clay 13
fill ~67 ~28 ~47 ~68 ~28 ~47 stained_hardened_clay 13
fill ~67 ~28 ~54 ~67 ~32 ~54 stained_hardened_clay 13
fill ~68 ~28 ~49 ~69 ~28 ~49 stained_hardened_clay 13
fill ~69 ~28 ~48 ~69 ~37 ~48 stained_hardened_clay 13
fill ~69 ~28 ~50 ~69 ~35 ~50 stained_hardened_clay 13
fill ~71 ~28 ~68 ~71 ~30 ~68 stained_hardened_clay 13
fill ~72 ~28 ~44 ~80 ~28 ~44 stained_hardened_clay 13
fill ~72 ~28 ~69 ~76 ~28 ~69 stained_hardened_clay 13
fill ~75 ~28 ~70 ~75 ~31 ~70 stained_hardened_clay 13
fill ~76 ~28 ~45 ~77 ~28 ~45 stained_hardened_clay 13
fill ~77 ~28 ~71 ~77 ~30 ~71 stained_hardened_clay 13
fill ~77 ~28 ~72 ~77 ~30 ~72 stained_hardened_clay 13
fill ~77 ~28 ~73 ~77 ~29 ~73 stained_hardened_clay 13
fill ~78 ~28 ~74 ~78 ~30 ~74 stained_hardened_clay 13
fill ~79 ~28 ~43 ~133 ~28 ~43 stained_hardened_clay 13
fill ~79 ~28 ~75 ~79 ~32 ~75 stained_hardened_clay 13
fill ~83 ~28 ~79 ~84 ~28 ~79 stained_hardened_clay 13
fill ~83 ~28 ~80 ~84 ~28 ~80 stained_hardened_clay 13
fill ~84 ~28 ~81 ~87 ~28 ~81 stained_hardened_clay 13
fill ~86 ~28 ~82 ~92 ~28 ~82 stained_hardened_clay 13
fill ~88 ~28 ~44 ~134 ~28 ~44 stained_hardened_clay 13
fill ~91 ~28 ~83 ~96 ~28 ~83 stained_hardened_clay 13
fill ~92 ~28 ~84 ~95 ~28 ~84 stained_hardened_clay 13
fill ~95 ~28 ~82 ~98 ~28 ~82 stained_hardened_clay 13
fill ~97 ~28 ~81 ~103 ~28 ~81 stained_hardened_clay 13
fill ~98 ~28 ~80 ~101 ~28 ~80 stained_hardened_clay 13
fill ~101 ~28 ~82 ~104 ~28 ~82 stained_hardened_clay 13
fill ~103 ~28 ~83 ~108 ~28 ~83 stained_hardened_clay 13
fill ~104 ~28 ~84 ~107 ~28 ~84 stained_hardened_clay 13
fill ~107 ~28 ~82 ~113 ~28 ~82 stained_hardened_clay 13
fill ~112 ~28 ~81 ~115 ~28 ~81 stained_hardened_clay 13
fill ~115 ~28 ~80 ~116 ~28 ~80 stained_hardened_clay 13
fill ~116 ~28 ~79 ~116 ~31 ~79 stained_hardened_clay 13
fill ~120 ~28 ~75 ~120 ~32 ~75 stained_hardened_clay 13
fill ~121 ~28 ~70 ~124 ~28 ~70 stained_hardened_clay 13
fill ~121 ~28 ~74 ~121 ~30 ~74 stained_hardened_clay 13
fill ~122 ~28 ~72 ~122 ~30 ~72 stained_hardened_clay 13
fill ~122 ~28 ~73 ~122 ~29 ~73 stained_hardened_clay 13
fill ~123 ~28 ~69 ~127 ~28 ~69 stained_hardened_clay 13
fill ~126 ~28 ~68 ~129 ~28 ~68 stained_hardened_clay 13
fill ~128 ~28 ~67 ~134 ~28 ~67 stained_hardened_clay 13
fill ~130 ~28 ~48 ~130 ~36 ~48 stained_hardened_clay 13
fill ~130 ~28 ~49 ~131 ~28 ~49 stained_hardened_clay 13
fill ~130 ~28 ~50 ~130 ~35 ~50 stained_hardened_clay 13
fill ~130 ~28 ~66 ~135 ~28 ~66 stained_hardened_clay 13
fill ~131 ~28 ~47 ~131 ~32 ~47 stained_hardened_clay 13
fill ~131 ~28 ~52 ~131 ~34 ~52 stained_hardened_clay 13
fill ~132 ~28 ~46 ~133 ~28 ~46 stained_hardened_clay 13
fill ~133 ~28 ~45 ~133 ~30 ~45 stained_hardened_clay 13
fill ~133 ~28 ~55 ~133 ~32 ~55 stained_hardened_clay 13
fill ~134 ~28 ~57 ~134 ~30 ~57 stained_hardened_clay 13
fill ~134 ~28 ~63 ~135 ~28 ~63 stained_hardened_clay 13
fill ~134 ~28 ~65 ~135 ~28 ~65 stained_hardened_clay 13
fill ~135 ~28 ~59 ~135 ~30 ~59 stained_hardened_clay 13
fill ~135 ~28 ~60 ~135 ~30 ~60 stained_hardened_clay 13
fill ~135 ~28 ~61 ~135 ~29 ~61 stained_hardened_clay 13
fill ~135 ~28 ~62 ~135 ~29 ~62 stained_hardened_clay 13
fill ~135 ~28 ~64 ~135 ~29 ~64 stained_hardened_clay 13
fill ~63 ~29 ~60 ~63 ~31 ~60 stained_hardened_clay 13
fill ~63 ~29 ~61 ~63 ~31 ~61 stained_hardened_clay 13
fill ~63 ~29 ~62 ~63 ~30 ~62 stained_hardened_clay 13
fill ~63 ~29 ~63 ~63 ~30 ~63 stained_hardened_clay 13
fill ~63 ~29 ~64 ~63 ~30 ~64 stained_hardened_clay 13
fill ~63 ~29 ~65 ~64 ~29 ~65 stained_hardened_clay 13
fill ~63 ~29 ~66 ~65 ~29 ~66 stained_hardened_clay 13
fill ~64 ~29 ~58 ~64 ~31 ~58 stained_hardened_clay 13
fill ~64 ~29 ~59 ~64 ~30 ~59 stained_hardened_clay 13
fill ~64 ~29 ~67 ~71 ~29 ~67 stained_hardened_clay 13
fill ~65 ~29 ~56 ~65 ~32 ~56 stained_hardened_clay 13
fill ~66 ~29 ~42 ~74 ~29 ~42 stained_hardened_clay 13
fill ~66 ~29 ~43 ~133 ~29 ~43 stained_hardened_clay 13
fill ~66 ~29 ~44 ~66 ~31 ~44 stained_hardened_clay 13
fill ~66 ~29 ~45 ~67 ~29 ~45 stained_hardened_clay 13
fill ~67 ~29 ~47 ~68 ~29 ~47 stained_hardened_clay 13
fill ~68 ~29 ~46 ~68 ~34 ~46 stained_hardened_clay 13
fill ~68 ~29 ~52 ~68 ~34 ~52 stained_hardened_clay 13
fill ~69 ~29 ~49 ~69 ~36 ~49 stained_hardened_clay 13
fill ~69 ~29 ~68 ~72 ~29 ~68 stained_hardened_clay 13
fill ~71 ~29 ~69 ~75 ~29 ~69 stained_hardened_clay 13
fill ~74 ~29 ~70 ~74 ~32 ~70 stained_hardened_clay 13
fill ~75 ~29 ~44 ~79 ~29 ~44 stained_hardened_clay 13
fill ~76 ~29 ~71 ~76 ~31 ~71 stained_hardened_clay 13
fill ~76 ~29 ~72 ~76 ~31 ~72 stained_hardened_clay 13
fill ~76 ~29 ~73 ~76 ~30 ~73 stained_hardened_clay 13
fill ~76 ~29 ~74 ~80 ~29 ~74 stained_hardened_clay 13
fill ~78 ~29 ~75 ~78 ~33 ~75 stained_hardened_clay 13
fill ~81 ~29 ~42 ~125 ~29 ~42 stained_hardened_clay 13
fill ~83 ~29 ~79 ~83 ~31 ~79 stained_hardened_clay 13
fill ~83 ~29 ~80 ~84 ~29 ~80 stained_hardened_clay 13
fill ~84 ~29 ~81 ~86 ~29 ~81 stained_hardened_clay 13
fill ~86 ~29 ~82 ~91 ~29 ~82 stained_hardened_clay 13
fill ~90 ~29 ~83 ~92 ~29 ~83 stained_hardened_clay 13
fill ~91 ~29 ~84 ~96 ~29 ~84 stained_hardened_clay 13
fill ~95 ~29 ~83 ~97 ~29 ~83 stained_hardened_clay 13
fill ~96 ~29 ~82 ~103 ~29 ~82 stained_hardened_clay 13
fill ~98 ~29 ~81 ~101 ~29 ~81 stained_hardened_clay 13
fill ~102 ~29 ~83 ~104 ~29 ~83 stained_hardened_clay 13
fill ~103 ~29 ~84 ~108 ~29 ~84 stained_hardened_clay 13
fill ~107 ~29 ~83 ~109 ~29 ~83 stained_hardened_clay 13
fill ~108 ~29 ~82 ~113 ~29 ~82 stained_hardened_clay 13
fill ~113 ~29 ~81 ~115 ~29 ~81 stained_hardened_clay 13
fill ~115 ~29 ~80 ~116 ~29 ~80 stained_hardened_clay 13
fill ~118 ~29 ~77 ~118 ~33 ~77 stained_hardened_clay 13
fill ~121 ~29 ~75 ~121 ~33 ~75 stained_hardened_clay 13
fill ~122 ~29 ~70 ~126 ~29 ~70 stained_hardened_clay 13
fill ~122 ~29 ~74 ~123 ~29 ~74 stained_hardened_clay 13
fill ~123 ~29 ~71 ~123 ~30 ~71 stained_hardened_clay 13
fill ~123 ~29 ~72 ~123 ~30 ~72 stained_hardened_clay 13
fill ~123 ~29 ~73 ~123 ~30 ~73 stained_hardened_clay 13
fill ~124 ~29 ~69 ~128 ~29 ~69 stained_hardened_clay 13
fill ~127 ~29 ~68 ~130 ~29 ~68 stained_hardened_clay 13
fill ~129 ~29 ~67 ~135 ~29 ~67 stained_hardened_clay 13
fill ~130 ~29 ~49 ~130 ~36 ~49 stained_hardened_clay 13
fill ~132 ~29 ~45 ~132 ~32 ~45 stained_hardened_clay 13
fill ~132 ~29 ~46 ~133 ~29 ~46 stained_hardened_clay 13
fill ~132 ~29 ~53 ~132 ~34 ~53 stained_hardened_clay 13
fill ~133 ~29 ~44 ~133 ~31 ~44 stained_hardened_clay 13
fill ~134 ~29 ~56 ~134 ~32 ~56 stained_hardened_clay 13
fill ~134 ~29 ~66 ~136 ~29 ~66 stained_hardened_clay 13
fill ~135 ~29 ~57 ~135 ~32 ~57 stained_hardened_clay 13
fill ~135 ~29 ~58 ~135 ~31 ~58 stained_hardened_clay 13
fill ~135 ~29 ~63 ~136 ~29 ~63 stained_hardened_clay 13
fill ~135 ~29 ~65 ~136 ~29 ~65 stained_hardened_clay 13
fill ~136 ~29 ~60 ~136 ~31 ~60 stained_hardened_clay 13
fill ~136 ~29 ~61 ~136 ~30 ~61 stained_hardened_clay 13
fill ~136 ~29 ~62 ~136 ~30 ~62 stained_hardened_clay 13
fill ~136 ~29 ~64 ~136 ~30 ~64 stained_hardened_clay 13
fill ~62 ~30 ~61 ~62 ~32 ~61 stained_hardened_clay 13
fill ~62 ~30 ~62 ~62 ~31 ~62 stained_hardened_clay 13
fill ~62 ~30 ~63 ~62 ~31 ~63 stained_hardened_clay 13
fill ~62 ~30 ~64 ~62 ~31 ~64 stained_hardened_clay 13
fill ~62 ~30 ~65 ~64 ~30 ~65 stained_hardened_clay 13
fill ~63 ~30 ~58 ~63 ~32 ~58 stained_hardened_clay 13
fill ~63 ~30 ~59 ~63 ~31 ~59 stained_hardened_clay 13
fill ~63 ~30 ~66 ~64 ~30 ~66 stained_hardened_clay 13
fill ~63 ~30 ~67 ~69 ~30 ~67 stained_hardened_clay 13
fill ~64 ~30 ~57 ~64 ~32 ~57 stained_hardened_clay 13
fill ~65 ~30 ~55 ~65 ~33 ~55 stained_hardened_clay 13
fill ~66 ~30 ~42 ~77 ~30 ~42 stained_hardened_clay 13
fill ~66 ~30 ~43 ~67 ~30 ~43 stained_hardened_clay 13
fill ~66 ~30 ~45 ~67 ~30 ~45 stained_hardened_clay 13
fill ~66 ~30 ~54 ~66 ~34 ~54 stained_hardened_clay 13
fill ~67 ~30 ~44 ~67 ~33 ~44 stained_hardened_clay 13
fill ~67 ~30 ~53 ~67 ~34 ~53 stained_hardened_clay 13
fill ~67 ~30 ~68 ~71 ~30 ~68 stained_hardened_clay 13
fill ~68 ~30 ~47 ~69 ~30 ~47 stained_hardened_clay 13
fill ~69 ~30 ~69 ~74 ~30 ~69 stained_hardened_clay 13
fill ~70 ~30 ~41 ~73 ~30 ~41 stained_hardened_clay 13
fill ~71 ~30 ~70 ~76 ~30 ~70 stained_hardened_clay 13
fill ~74 ~30 ~43 ~81 ~30 ~43 stained_hardened_clay 13
fill ~75 ~30 ~71 ~75 ~31 ~71 stained_hardened_clay 13
fill ~75 ~30 ~72 ~75 ~32 ~72 stained_hardened_clay 13
fill ~75 ~30 ~73 ~75 ~31 ~73 stained_hardened_clay 13
fill ~75 ~30 ~74 ~79 ~30 ~74 stained_hardened_clay 13
fill ~75 ~30 ~75 ~81 ~30 ~75 stained_hardened_clay 13
fill ~80 ~30 ~42 ~133 ~30 ~42 stained_hardened_clay 13
fill ~80 ~30 ~76 ~80 ~33 ~76 stained_hardened_clay 13
fill ~81 ~30 ~77 ~81 ~33 ~77 stained_hardened_clay 13
fill ~82 ~30 ~79 ~82 ~33 ~79 stained_hardened_clay 13
fill ~83 ~30 ~80 ~84 ~30 ~80 stained_hardened_clay 13
fill ~83 ~30 ~81 ~86 ~30 ~81 stained_hardened_clay 13
fill ~84 ~30 ~41 ~92 ~30 ~41 stained_hardened_clay 13
fill ~85 ~30 ~82 ~90 ~30 ~82 stained_hardened_clay 13
fill ~89 ~30 ~83 ~91 ~30 ~83 stained_hardened_clay 13
fill ~90 ~30 ~84 ~97 ~30 ~84 stained_hardened_clay 13
fill ~91 ~30 ~85 ~96 ~30 ~85 stained_hardened_clay 13
fill ~96 ~30 ~83 ~99 ~30 ~83 stained_hardened_clay 13
fill ~97 ~30 ~82 ~102 ~30 ~82 stained_hardened_clay 13
fill ~101 ~30 ~83 ~103 ~30 ~83 stained_hardened_clay 13
fill ~102 ~30 ~84 ~109 ~30 ~84 stained_hardened_clay 13
fill ~104 ~30 ~85 ~108 ~30 ~85 stained_hardened_clay 13
fill ~105 ~30 ~43 ~109 ~30 ~43 stained_hardened_clay 13
fill ~108 ~30 ~83 ~110 ~30 ~83 stained_hardened_clay 13
fill ~109 ~30 ~82 ~114 ~30 ~82 stained_hardened_clay 13
fill ~113 ~30 ~81 ~116 ~30 ~81 stained_hardened_clay 13
fill ~115 ~30 ~80 ~116 ~30 ~80 stained_hardened_clay 13
fill ~117 ~30 ~79 ~117 ~33 ~79 stained_hardened_clay 13
fill ~119 ~30 ~76 ~119 ~33 ~76 stained_hardened_clay 13
fill ~122 ~30 ~74 ~124 ~30 ~74 stained_hardened_clay 13
fill ~122 ~30 ~75 ~124 ~30 ~75 stained_hardened_clay 13
fill ~123 ~30 ~70 ~128 ~30 ~70 stained_hardened_clay 13
fill ~124 ~30 ~43 ~133 ~30 ~43 stained_hardened_clay 13
fill ~124 ~30 ~71 ~124 ~31 ~71 stained_hardened_clay 13
fill ~124 ~30 ~72 ~124 ~31 ~72 stained_hardened_clay 13
fill ~124 ~30 ~73 ~124 ~31 ~73 stained_hardened_clay 13
fill ~125 ~30 ~69 ~130 ~30 ~69 stained_hardened_clay 13
fill ~128 ~30 ~68 ~132 ~30 ~68 stained_hardened_clay 13
fill ~130 ~30 ~47 ~130 ~36 ~47 stained_hardened_clay 13
fill ~130 ~30 ~67 ~136 ~30 ~67 stained_hardened_clay 13
fill ~131 ~30 ~46 ~132 ~30 ~46 stained_hardened_clay 13
fill ~132 ~30 ~44 ~132 ~33 ~44 stained_hardened_clay 13
fill ~133 ~30 ~54 ~133 ~33 ~54 stained_hardened_clay 13
fill ~134 ~30 ~55 ~134 ~33 ~55 stained_hardened_clay 13
fill ~135 ~30 ~56 ~135 ~33 ~56 stained_hardened_clay 13
fill ~135 ~30 ~66 ~137 ~30 ~66 stained_hardened_clay 13
fill ~136 ~30 ~58 ~136 ~32 ~58 stained_hardened_clay 13
fill ~136 ~30 ~59 ~136 ~31 ~59 stained_hardened_clay 13
fill ~136 ~30 ~63 ~137 ~30 ~63 stained_hardened_clay 13
fill ~136 ~30 ~65 ~137 ~30 ~65 stained_hardened_clay 13
fill ~137 ~30 ~60 ~137 ~32 ~60 stained_hardened_clay 13
fill ~137 ~30 ~61 ~137 ~31 ~61 stained_hardened_clay 13
fill ~137 ~30 ~62 ~137 ~31 ~62 stained_hardened_clay 13
fill ~137 ~30 ~64 ~137 ~31 ~64 stained_hardened_clay 13
fill ~61 ~31 ~60 ~63 ~31 ~60 stained_hardened_clay 13
fill ~61 ~31 ~61 ~61 ~32 ~61 stained_hardened_clay 13
fill ~61 ~31 ~62 ~61 ~32 ~62 stained_hardened_clay 13
fill ~61 ~31 ~63 ~61 ~32 ~63 stained_hardened_clay 13
fill ~61 ~31 ~64 ~61 ~32 ~64 stained_hardened_clay 13
fill ~61 ~31 ~65 ~63 ~31 ~65 stained_hardened_clay 13
fill ~62 ~31 ~58 ~62 ~33 ~58 stained_hardened_clay 13
fill ~62 ~31 ~59 ~62 ~32 ~59 stained_hardened_clay 13
fill ~62 ~31 ~66 ~63 ~31 ~66 stained_hardened_clay 13
fill ~62 ~31 ~67 ~68 ~31 ~67 stained_hardened_clay 13
fill ~63 ~31 ~57 ~63 ~33 ~57 stained_hardened_clay 13
fill ~64 ~31 ~56 ~64 ~33 ~56 stained_hardened_clay 13
fill ~66 ~31 ~41 ~76 ~31 ~41 stained_hardened_clay 13
fill ~66 ~31 ~42 ~70 ~31 ~42 stained_hardened_clay 13
fill ~66 ~31 ~43 ~67 ~31 ~43 stained_hardened_clay 13
fill ~66 ~31 ~68 ~69 ~31 ~68 stained_hardened_clay 13
fill ~67 ~31 ~45 ~68 ~31 ~45 stained_hardened_clay 13
fill ~67 ~31 ~69 ~72 ~31 ~69 stained_hardened_clay 13
fill ~68 ~31 ~47 ~69 ~31 ~47 stained_hardened_clay 13
fill ~69 ~31 ~70 ~75 ~31 ~70 stained_hardened_clay 13
fill ~73 ~31 ~42 ~85 ~31 ~42 stained_hardened_clay 13
fill ~73 ~31 ~74 ~75 ~31 ~74 stained_hardened_clay 13
fill ~73 ~31 ~75 ~80 ~31 ~75 stained_hardened_clay 13
fill ~74 ~31 ~71 ~74 ~32 ~71 stained_hardened_clay 13
fill ~74 ~31 ~72 ~74 ~32 ~72 stained_hardened_clay 13
fill ~74 ~31 ~73 ~74 ~32 ~73 stained_hardened_clay 13
fill ~77 ~31 ~43 ~81 ~31 ~43 stained_hardened_clay 13
fill ~79 ~31 ~76 ~79 ~34 ~76 stained_hardened_clay 13
fill ~81 ~31 ~78 ~81 ~34 ~78 stained_hardened_clay 13
fill ~82 ~31 ~80 ~83 ~31 ~80 stained_hardened_clay 13
fill ~83 ~31 ~41 ~133 ~31 ~41 stained_hardened_clay 13
fill ~83 ~31 ~81 ~86 ~31 ~81 stained_hardened_clay 13
fill ~85 ~31 ~82 ~89 ~31 ~82 stained_hardened_clay 13
fill ~87 ~31 ~83 ~90 ~31 ~83 stained_hardened_clay 13
fill ~89 ~31 ~84 ~91 ~31 ~84 stained_hardened_clay 13
fill ~90 ~31 ~85 ~96 ~31 ~85 stained_hardened_clay 13
fill ~91 ~31 ~86 ~94 ~31 ~86 stained_hardened_clay 13
fill ~92 ~31 ~42 ~133 ~31 ~42 stained_hardened_clay 13
fill ~95 ~31 ~84 ~98 ~31 ~84 stained_hardened_clay 13
fill ~97 ~31 ~83 ~102 ~31 ~83 stained_hardened_clay 13
fill ~98 ~31 ~82 ~101 ~31 ~82 stained_hardened_clay 13
fill ~101 ~31 ~84 ~104 ~31 ~84 stained_hardened_clay 13
fill ~103 ~31 ~85 ~109 ~31 ~85 stained_hardened_clay 13
fill ~105 ~31 ~86 ~108 ~31 ~86 stained_hardened_clay 13
fill ~108 ~31 ~84 ~110 ~31 ~84 stained_hardened_clay 13
fill ~109 ~31 ~83 ~112 ~31 ~83 stained_hardened_clay 13
fill ~110 ~31 ~82 ~114 ~31 ~82 stained_hardened_clay 13
fill ~114 ~31 ~81 ~116 ~31 ~81 stained_hardened_clay 13
fill ~116 ~31 ~80 ~117 ~31 ~80 stained_hardened_clay 13
fill ~118 ~31 ~78 ~118 ~34 ~78 stained_hardened_clay 13
fill ~120 ~31 ~76 ~120 ~34 ~76 stained_hardened_clay 13
fill ~122 ~31 ~75 ~126 ~31 ~75 stained_hardened_clay 13
fill ~124 ~31 ~70 ~130 ~31 ~70 stained_hardened_clay 13
fill ~124 ~31 ~74 ~126 ~31 ~74 stained_hardened_clay 13
fill ~125 ~31 ~71 ~126 ~31 ~71 stained_hardened_clay 13
fill ~125 ~31 ~72 ~125 ~32 ~72 stained_hardened_clay 13
fill ~125 ~31 ~73 ~125 ~32 ~73 stained_hardened_clay 13
fill ~127 ~31 ~69 ~132 ~31 ~69 stained_hardened_clay 13
fill ~130 ~31 ~68 ~134 ~31 ~68 stained_hardened_clay 13
fill ~131 ~31 ~45 ~131 ~39 ~45 stained_hardened_clay 13
fill ~131 ~31 ~46 ~132 ~31 ~46 stained_hardened_clay 13
fill ~131 ~31 ~51 ~131 ~36 ~51 stained_hardened_clay 13
fill ~132 ~31 ~43 ~133 ~31 ~43 stained_hardened_clay 13
fill ~132 ~31 ~67 ~137 ~31 ~67 stained_hardened_clay 13
fill ~136 ~31 ~57 ~136 ~33 ~57 stained_hardened_clay 13
fill ~136 ~31 ~66 ~138 ~31 ~66 stained_hardened_clay 13
fill ~137 ~31 ~58 ~137 ~33 ~58 stained_hardened_clay 13
fill ~137 ~31 ~59 ~137 ~32 ~59 stained_hardened_clay 13
fill ~137 ~31 ~63 ~138 ~31 ~63 stained_hardened_clay 13
fill ~137 ~31 ~65 ~138 ~31 ~65 stained_hardened_clay 13
fill ~138 ~31 ~60 ~138 ~33 ~60 stained_hardened_clay 13
fill ~138 ~31 ~61 ~138 ~32 ~61 stained_hardened_clay 13
fill ~138 ~31 ~62 ~138 ~32 ~62 stained_hardened_clay 13
fill ~138 ~31 ~64 ~138 ~32 ~64 stained_hardened_clay 13
fill ~60 ~32 ~60 ~62 ~32 ~60 stained_hardened_clay 13
fill ~60 ~32 ~61 ~60 ~33 ~61 stained_hardened_clay 13
fill ~60 ~32 ~62 ~60 ~33 ~62 stained_hardened_clay 13
fill ~60 ~32 ~63 ~60 ~33 ~63 stained_hardened_clay 13
fill ~60 ~32 ~64 ~60 ~33 ~64 stained_hardened_clay 13
fill ~60 ~32 ~65 ~62 ~32 ~65 stained_hardened_clay 13
fill ~61 ~32 ~58 ~61 ~34 ~58 stained_hardened_clay 13
fill ~61 ~32 ~59 ~61 ~33 ~59 stained_hardened_clay 13
fill ~61 ~32 ~66 ~62 ~32 ~66 stained_hardened_clay 13
fill ~61 ~32 ~67 ~66 ~32 ~67 stained_hardened_clay 13
fill ~62 ~32 ~57 ~62 ~34 ~57 stained_hardened_clay 13
fill ~63 ~32 ~56 ~63 ~34 ~56 stained_hardened_clay 13
fill ~63 ~32 ~68 ~67 ~32 ~68 stained_hardened_clay 13
fill ~64 ~32 ~55 ~64 ~34 ~55 stained_hardened_clay 13
fill ~65 ~32 ~54 ~65 ~35 ~54 stained_hardened_clay 13
fill ~66 ~32 ~41 ~78 ~32 ~41 stained_hardened_clay 13
fill ~66 ~32 ~42 ~67 ~32 ~42 stained_hardened_clay 13
fill ~66 ~32 ~53 ~66 ~35 ~53 stained_hardened_clay 13
fill ~66 ~32 ~69 ~69 ~32 ~69 stained_hardened_clay 13
fill ~66 ~32 ~70 ~74 ~32 ~70 stained_hardened_clay 13
fill ~67 ~32 ~43 ~67 ~34 ~43 stained_hardened_clay 13
fill ~67 ~32 ~45 ~68 ~32 ~45 stained_hardened_clay 13
fill ~67 ~32 ~52 ~67 ~36 ~52 stained_hardened_clay 13
fill ~68 ~32 ~44 ~68 ~39 ~44 stained_hardened_clay 13
fill ~68 ~32 ~47 ~69 ~32 ~47 stained_hardened_clay 13
fill ~68 ~32 ~51 ~68 ~36 ~51 stained_hardened_clay 13
fill ~69 ~32 ~46 ~69 ~37 ~46 stained_hardened_clay 13
fill ~70 ~32 ~40 ~75 ~32 ~40 stained_hardened_clay 13
fill ~71 ~32 ~71 ~74 ~32 ~71 stained_hardened_clay 13
fill ~71 ~32 ~75 ~79 ~32 ~75 stained_hardened_clay 13
fill ~71 ~32 ~76 ~81 ~32 ~76 stained_hardened_clay 13
