fill ~1 ~-3 ~1 ~2 ~-3 ~1 gravel 0
fill ~1 ~-3 ~2 ~2 ~-3 ~2 planks 0
fill ~1 ~-3 ~3 ~2 ~-3 ~3 planks 0
setblock ~1 ~-3 ~4 gravel 0
fill ~1 ~-3 ~5 ~2 ~-3 ~5 grass 0
fill ~1 ~-3 ~6 ~2 ~-3 ~6 grass 0
fill ~1 ~-3 ~7 ~2 ~-3 ~7 grass 0
fill ~1 ~-3 ~8 ~2 ~-3 ~8 grass 0
fill ~1 ~-3 ~9 ~2 ~-3 ~9 grass 0
fill ~1 ~-3 ~10 ~2 ~-3 ~10 grass 0
fill ~1 ~-3 ~11 ~2 ~-3 ~11 grass 0
fill ~1 ~-3 ~12 ~2 ~-3 ~12 grass 0
fill ~1 ~-3 ~13 ~2 ~-3 ~13 grass 0
fill ~1 ~-3 ~14 ~2 ~-3 ~14 grass 0
fill ~1 ~-3 ~15 ~2 ~-3 ~15 grass 0
fill ~1 ~-3 ~16 ~2 ~-3 ~16 grass 0
fill ~1 ~-3 ~17 ~2 ~-3 ~17 grass 0
fill ~1 ~-3 ~18 ~2 ~-3 ~18 grass 0
fill ~1 ~-3 ~19 ~2 ~-3 ~19 grass 0
fill ~1 ~-3 ~20 ~2 ~-3 ~20 grass 0
fill ~1 ~-3 ~21 ~2 ~-3 ~21 grass 0
fill ~1 ~-3 ~22 ~2 ~-3 ~22 grass 0
fill ~1 ~-3 ~23 ~2 ~-3 ~23 grass 0
fill ~1 ~-3 ~24 ~2 ~-3 ~24 grass 0
fill ~1 ~-3 ~25 ~2 ~-3 ~25 grass 0
fill ~1 ~-3 ~26 ~2 ~-3 ~26 grass 0
fill ~1 ~-3 ~27 ~2 ~-3 ~27 grass 0
fill ~1 ~-3 ~28 ~2 ~-3 ~28 grass 0
fill ~1 ~-3 ~29 ~2 ~-3 ~29 grass 0
fill ~1 ~-3 ~30 ~2 ~-3 ~30 grass 0
fill ~1 ~-3 ~31 ~2 ~-3 ~31 grass 0
fill ~1 ~-3 ~32 ~2 ~-3 ~32 grass 0
fill ~1 ~-3 ~33 ~1 ~-3 ~5 grass 0
fill ~1 ~-3 ~34 ~1 ~-3 ~35 cobblestone 0
setblock ~1 ~-3 ~36 grass 0
setblock ~2 ~-3 ~4 grass 0
setblock ~2 ~-3 ~33 cobblestone 0
fill ~2 ~-3 ~34 ~2 ~-3 ~35 planks 0
setblock ~2 ~-3 ~36 gravel 0
setblock ~3 ~-3 ~0 gravel 0
fill ~3 ~-3 ~1 ~7 ~-3 ~1 planks 0
fill ~3 ~-3 ~2 ~10 ~-3 ~2 mycelium 0
fill ~3 ~-3 ~3 ~3 ~-3 ~6 mycelium 0
setblock ~3 ~-3 ~7 stonebrick 0
fill ~3 ~-3 ~8 ~3 ~-3 ~9 gravel 0
setblock ~3 ~-3 ~10 monster_egg 3
fill ~3 ~-3 ~11 ~3 ~-3 ~17 mycelium 0
setblock ~3 ~-3 ~18 gravel 0
fill ~3 ~-3 ~19 ~6 ~-3 ~19 mycelium 0
fill ~3 ~-3 ~20 ~4 ~-3 ~20 mycelium 0
fill ~3 ~-3 ~21 ~10 ~-3 ~21 mycelium 0
setblock ~3 ~-3 ~22 stonebrick 2
fill ~3 ~-3 ~23 ~5 ~-3 ~23 mycelium 0
fill ~3 ~-3 ~24 ~3 ~-3 ~28 mycelium 0
setblock ~3 ~-3 ~29 gravel 0
fill ~3 ~-3 ~30 ~4 ~-3 ~30 mycelium 0
fill ~3 ~-3 ~31 ~4 ~-3 ~31 mycelium 0
fill ~3 ~-3 ~32 ~3 ~-3 ~33 mycelium 0
fill ~3 ~-3 ~34 ~33 ~-3 ~34 grass 0
fill ~3 ~-3 ~35 ~5 ~-3 ~35 planks 0
fill ~3 ~-3 ~36 ~3 ~-3 ~35 planks 0
fill ~4 ~-3 ~0 ~5 ~-3 ~0 planks 0
fill ~4 ~-3 ~3 ~6 ~-3 ~3 dirt 0
fill ~4 ~-3 ~4 ~4 ~-3 ~4 dirt 0
setblock ~4 ~-3 ~5 dirt 2
setblock ~4 ~-3 ~6 mycelium 0
fill ~4 ~-3 ~7 ~5 ~-3 ~7 gravel 0
setblock ~4 ~-3 ~8 stonebrick 0
fill ~4 ~-3 ~9 ~4 ~-3 ~10 gravel 0
fill ~4 ~-3 ~11 ~4 ~-3 ~12 dirt 2
fill ~4 ~-3 ~13 ~6 ~-3 ~13 mycelium 0
fill ~4 ~-3 ~14 ~5 ~-3 ~14 mycelium 0
fill ~4 ~-3 ~15 ~4 ~-3 ~15 dirt 0
fill ~4 ~-3 ~16 ~4 ~-3 ~16 dirt 0
setblock ~4 ~-3 ~17 mycelium 0
setblock ~4 ~-3 ~18 stonebrick 0
setblock ~4 ~-3 ~22 gravel 0
fill ~4 ~-3 ~24 ~4 ~-3 ~24 dirt 0
fill ~4 ~-3 ~25 ~4 ~-3 ~26 mycelium 0
fill ~4 ~-3 ~27 ~4 ~-3 ~27 dirt 0
fill ~4 ~-3 ~28 ~5 ~-3 ~28 mycelium 0
setblock ~4 ~-3 ~29 monster_egg 3
fill ~4 ~-3 ~32 ~4 ~-3 ~32 dirt 0
fill ~4 ~-3 ~33 ~5 ~-3 ~33 mycelium 0
fill ~4 ~-3 ~36 ~32 ~-3 ~36 grass 0
fill ~5 ~-3 ~4 ~8 ~-3 ~4 mycelium 0
fill ~5 ~-3 ~5 ~6 ~-3 ~5 mycelium 0
setblock ~5 ~-3 ~6 dirt 2
fill ~5 ~-3 ~8 ~8 ~-3 ~8 gravel 0
setblock ~5 ~-3 ~9 stonebrick 2
fill ~5 ~-3 ~10 ~6 ~-3 ~10 gravel 0
fill ~5 ~-3 ~11 ~6 ~-3 ~11 gravel 0
fill ~5 ~-3 ~12 ~8 ~-3 ~12 mycelium 0
fill ~5 ~-3 ~15 ~5 ~-3 ~16 mycelium 0
fill ~5 ~-3 ~17 ~5 ~-3 ~18 monster_egg 3
setblock ~5 ~-3 ~20 dirt 2
fill ~5 ~-3 ~22 ~6 ~-3 ~22 monster_egg 3
fill ~5 ~-3 ~24 ~6 ~-3 ~24 mycelium 0
setblock ~5 ~-3 ~25 dirt 2
fill ~5 ~-3 ~26 ~5 ~-3 ~28 mycelium 0
fill ~5 ~-3 ~29 ~8 ~-3 ~29 gravel 0
fill ~5 ~-3 ~30 ~5 ~-3 ~31 dirt 2
setblock ~5 ~-3 ~32 mycelium 0
fill ~6 ~-3 ~0 ~31 ~-3 ~0 grass 0
fill ~6 ~-3 ~6 ~6 ~-3 ~7 mycelium 0
setblock ~6 ~-3 ~9 stonebrick 0
setblock ~6 ~-3 ~14 vine 7
setblock ~6 ~-3 ~15 dirt 2
fill ~6 ~-3 ~16 ~7 ~-3 ~16 mycelium 0
setblock ~6 ~-3 ~17 gravel 0
fill ~6 ~-3 ~18 ~9 ~-3 ~18 mycelium 0
fill ~6 ~-3 ~20 ~9 ~-3 ~20 mycelium 0
fill ~6 ~-3 ~23 ~7 ~-3 ~23 gravel 0
setblock ~6 ~-3 ~26 vine 2
fill ~6 ~-3 ~27 ~7 ~-3 ~27 mycelium 0
setblock ~6 ~-3 ~28 gravel 0
setblock ~6 ~-3 ~30 mycelium 0
setblock ~6 ~-3 ~31 dirt 2
fill ~6 ~-3 ~32 ~7 ~-3 ~32 gravel 0
setblock ~6 ~-3 ~33 stonebrick 0
fill ~6 ~-3 ~35 ~35 ~-3 ~35 grass 0
setblock ~7 ~-3 ~3 mycelium 0
fill ~7 ~-3 ~5 ~7 ~-3 ~5 dirt 0
fill ~7 ~-3 ~6 ~7 ~-2 ~6 vine 4
setblock ~7 ~-3 ~7 vine 3
fill ~7 ~-3 ~9 ~10 ~-3 ~9 gravel 0
setblock ~7 ~-3 ~10 stonebrick 0
setblock ~7 ~-3 ~11 mycelium 0
setblock ~7 ~-3 ~13 dirt 2
setblock ~7 ~-3 ~14 vine 1
fill ~7 ~-3 ~15 ~9 ~-3 ~15 mycelium 0
setblock ~7 ~-3 ~17 stonebrick 2
fill ~7 ~-3 ~19 ~7 ~-3 ~19 dirt 0
fill ~7 ~-3 ~22 ~8 ~-3 ~22 mycelium 0
setblock ~7 ~-3 ~24 gravel 0
fill ~7 ~-3 ~25 ~7 ~-3 ~27 mycelium 0
setblock ~7 ~-3 ~28 stonebrick 2
setblock ~7 ~-3 ~30 vine 2
setblock ~7 ~-3 ~31 stonebrick 2
fill ~7 ~-3 ~33 ~8 ~-3 ~33 gravel 0
fill ~8 ~-3 ~1 ~30 ~-3 ~1 grass 0
setblock ~8 ~-3 ~5 dirt 2
fill ~8 ~-3 ~6 ~8 ~-3 ~7 mycelium 0
fill ~8 ~-3 ~10 ~8 ~-3 ~11 gravel 0
fill ~8 ~-3 ~13 ~9 ~-3 ~13 mycelium 0
fill ~8 ~-3 ~14 ~9 ~-3 ~14 mycelium 0
fill ~8 ~-3 ~16 ~9 ~-3 ~16 gravel 0
fill ~8 ~-3 ~17 ~8 ~-3 ~16 gravel 0
fill ~8 ~-3 ~19 ~8 ~-2 ~19 vine 2
fill ~8 ~-3 ~23 ~10 ~-3 ~23 mycelium 0
setblock ~8 ~-3 ~24 stonebrick 0
fill ~8 ~-3 ~25 ~10 ~-3 ~25 gravel 0
fill ~8 ~-3 ~26 ~10 ~-3 ~26 mycelium 0
setblock ~8 ~-3 ~27 vine 2
fill ~8 ~-3 ~28 ~10 ~-3 ~28 gravel 0
fill ~8 ~-3 ~30 ~8 ~-3 ~31 gravel 0
setblock ~8 ~-3 ~32 stonebrick 0
setblock ~9 ~-3 ~3 mycelium 0
setblock ~9 ~-3 ~4 dirt 2
fill ~9 ~-3 ~5 ~9 ~-3 ~5 dirt 0
setblock ~9 ~-3 ~6 dirt 2
setblock ~9 ~-3 ~7 mycelium 0
setblock ~9 ~-3 ~8 stonebrick 2
fill ~9 ~-3 ~10 ~10 ~-3 ~10 mycelium 0
setblock ~9 ~-3 ~11 stonebrick 2
fill ~9 ~-3 ~12 ~11 ~-3 ~12 gravel 0
fill ~9 ~-3 ~17 ~10 ~-3 ~17 mycelium 0
setblock ~9 ~-3 ~19 vine 1
setblock ~9 ~-3 ~22 vine 1
setblock ~9 ~-3 ~24 mycelium 0
setblock ~9 ~-3 ~27 vine 4
setblock ~9 ~-3 ~29 mycelium 0
fill ~9 ~-3 ~30 ~10 ~-3 ~30 dirt 2
fill ~9 ~-3 ~31 ~11 ~-3 ~31 mycelium 0
fill ~9 ~-3 ~32 ~10 ~-3 ~32 mycelium 0
fill ~9 ~-3 ~33 ~12 ~-3 ~33 mycelium 0
setblock ~10 ~-3 ~3 dirt 2
fill ~10 ~-3 ~4 ~11 ~-3 ~4 mycelium 0
setblock ~10 ~-3 ~5 vine 7
fill ~10 ~-3 ~6 ~11 ~-3 ~6 mycelium 0
setblock ~10 ~-3 ~7 dirt 2
setblock ~10 ~-3 ~8 gravel 0
setblock ~10 ~-3 ~11 mycelium 0
setblock ~10 ~-3 ~13 stonebrick 2
fill ~10 ~-3 ~14 ~11 ~-3 ~14 gravel 0
fill ~10 ~-3 ~15 ~11 ~-3 ~15 gravel 0
setblock ~10 ~-3 ~16 stonebrick 0
fill ~10 ~-3 ~18 ~11 ~-3 ~18 gravel 0
fill ~10 ~-3 ~19 ~11 ~-3 ~19 gravel 0
fill ~10 ~-3 ~20 ~11 ~-3 ~20 gravel 0
setblock ~10 ~-3 ~22 vine 4
fill ~10 ~-3 ~24 ~11 ~-3 ~24 gravel 0
setblock ~10 ~-3 ~27 stonebrick 2
fill ~10 ~-3 ~29 ~11 ~-3 ~29 dirt 2
fill ~11 ~-3 ~2 ~12 ~-3 ~2 gravel 0
setblock ~11 ~-3 ~3 monster_egg 3
fill ~11 ~-3 ~7 ~12 ~-3 ~7 gravel 0
setblock ~11 ~-3 ~8 stonebrick 0
fill ~11 ~-3 ~9 ~12 ~-3 ~9 mycelium 0
setblock ~11 ~-3 ~10 vine 5
fill ~11 ~-3 ~11 ~16 ~-3 ~11 gravel 0
setblock ~11 ~-3 ~13 gravel 0
fill ~11 ~-3 ~16 ~11 ~-3 ~24 gravel 0
setblock ~11 ~-3 ~25 stonebrick 2
fill ~11 ~-3 ~26 ~11 ~-3 ~27 gravel 0
fill ~11 ~-3 ~28 ~12 ~-3 ~28 mycelium 0
setblock ~11 ~-3 ~30 mycelium 0
fill ~11 ~-3 ~32 ~11 ~-3 ~32 dirt 0
setblock ~12 ~-3 ~3 stonebrick 0
fill ~12 ~-3 ~4 ~12 ~-3 ~5 gravel 0
setblock ~12 ~-3 ~6 stonebrick 2
fill ~12 ~-3 ~8 ~14 ~-3 ~8 gravel 0
fill ~12 ~-3 ~10 ~13 ~-3 ~10 mycelium 0
fill ~12 ~-3 ~12 ~18 ~-3 ~12 mycelium 0
fill ~12 ~-3 ~13 ~12 ~-3 ~15 mycelium 0
fill ~12 ~-3 ~16 ~25 ~-3 ~16 dirt 0
setblock ~12 ~-3 ~17 mycelium 0
setblock ~12 ~-3 ~18 dirt 2
fill ~12 ~-3 ~19 ~12 ~-3 ~21 mycelium 0
setblock ~12 ~-3 ~22 stonebrick 0
fill ~12 ~-3 ~23 ~15 ~-3 ~23 gravel 0
fill ~12 ~-3 ~24 ~13 ~-3 ~24 dirt 2
fill ~12 ~-3 ~26 ~12 ~-3 ~29 mycelium 0
setblock ~12 ~-3 ~31 vine 1
setblock ~12 ~-3 ~32 mycelium 0
fill ~13 ~-3 ~2 ~21 ~-3 ~2 mycelium 0
fill ~13 ~-3 ~3 ~14 ~-3 ~3 mycelium 0
setblock ~13 ~-3 ~4 stonebrick 0
fill ~13 ~-3 ~5 ~13 ~-3 ~6 gravel 0
setblock ~13 ~-3 ~7 stonebrick 2
fill ~13 ~-3 ~9 ~14 ~-3 ~9 gravel 0
fill ~13 ~-3 ~13 ~13 ~-3 ~13 dirt 0
setblock ~13 ~-3 ~14 mycelium 0
fill ~13 ~-3 ~15 ~25 ~-3 ~15 dirt 0
fill ~13 ~-3 ~17 ~25 ~-3 ~17 dirt 0
fill ~13 ~-3 ~18 ~26 ~-3 ~18 dirt 0
fill ~13 ~-3 ~19 ~26 ~-3 ~19 dirt 0
fill ~13 ~-3 ~20 ~25 ~-3 ~20 dirt 0
fill ~13 ~-3 ~21 ~13 ~-3 ~22 mycelium 0
fill ~13 ~-3 ~25 ~15 ~-3 ~25 mycelium 0
setblock ~13 ~-3 ~26 vine 4
setblock ~13 ~-3 ~27 vine 1
fill ~13 ~-3 ~28 ~13 ~-3 ~28 dirt 0
setblock ~13 ~-3 ~29 mycelium 0
fill ~13 ~-3 ~30 ~13 ~-3 ~31 gravel 0
setblock ~13 ~-3 ~32 stonebrick 0
setblock ~13 ~-3 ~33 gravel 0
fill ~14 ~-3 ~4 ~15 ~-3 ~4 mycelium 0
fill ~14 ~-3 ~5 ~16 ~-3 ~5 mycelium 0
fill ~14 ~-3 ~6 ~14 ~-3 ~11 gravel 0
setblock ~14 ~-3 ~13 dirt 2
fill ~14 ~-3 ~14 ~24 ~-3 ~14 dirt 0
fill ~14 ~-3 ~21 ~16 ~-3 ~21 dirt 0
setblock ~14 ~-3 ~22 mycelium 0
setblock ~14 ~-3 ~24 vine 1
fill ~14 ~-3 ~26 ~14 ~-3 ~28 mycelium 0
fill ~14 ~-3 ~29 ~15 ~-3 ~29 gravel 0
setblock ~14 ~-3 ~30 stonebrick 0
setblock ~14 ~-3 ~31 stonebrick 2
setblock ~14 ~-3 ~32 gravel 0
setblock ~14 ~-3 ~33 stonebrick 0
fill ~15 ~-3 ~3 ~15 ~-3 ~3 dirt 0
fill ~15 ~-3 ~7 ~15 ~-3 ~9 mycelium 0
setblock ~15 ~-3 ~10 dirt 2
fill ~15 ~-3 ~13 ~16 ~-3 ~13 mycelium 0
fill ~15 ~-3 ~22 ~17 ~-3 ~22 dirt 0
setblock ~15 ~-3 ~24 mycelium 0
setblock ~15 ~-3 ~26 stonebrick 2
fill ~15 ~-3 ~27 ~15 ~-3 ~29 gravel 0
fill ~15 ~-3 ~30 ~17 ~-3 ~30 mycelium 0
fill ~15 ~-3 ~31 ~16 ~-3 ~31 mycelium 0
setblock ~15 ~-3 ~32 dirt 2
fill ~15 ~-3 ~33 ~23 ~-3 ~33 mycelium 0
fill ~16 ~-3 ~3 ~18 ~-3 ~3 mycelium 0
setblock ~16 ~-3 ~4 vine 8
setblock ~16 ~-3 ~6 vine 8
setblock ~16 ~-3 ~7 dirt 2
fill ~16 ~-3 ~8 ~16 ~-3 ~10 mycelium 0
setblock ~16 ~-3 ~23 stonebrick 0
fill ~16 ~-3 ~24 ~16 ~-3 ~26 gravel 0
fill ~16 ~-3 ~27 ~17 ~-3 ~27 mycelium 0
setblock ~16 ~-3 ~28 dirt 2
fill ~16 ~-3 ~29 ~17 ~-3 ~29 mycelium 0
fill ~16 ~-3 ~32 ~17 ~-3 ~32 mycelium 0
fill ~17 ~-3 ~4 ~18 ~-3 ~4 mycelium 0
setblock ~17 ~-3 ~5 dirt 2
fill ~17 ~-3 ~6 ~17 ~-3 ~6 dirt 0
fill ~17 ~-3 ~7 ~17 ~-3 ~7 dirt 0
setblock ~17 ~-3 ~8 vine 8
setblock ~17 ~-3 ~9 vine 2
fill ~17 ~-3 ~10 ~19 ~-3 ~10 mycelium 0
setblock ~17 ~-3 ~11 stonebrick 0
setblock ~17 ~-3 ~13 dirt 2
setblock ~17 ~-3 ~21 dirt 2
fill ~17 ~-3 ~23 ~18 ~-3 ~23 stonebrick 2
fill ~17 ~-3 ~24 ~19 ~-3 ~24 mycelium 0
fill ~17 ~-3 ~25 ~17 ~-3 ~24 mycelium 0
setblock ~17 ~-3 ~26 dirt 2
setblock ~17 ~-3 ~28 mycelium 0
fill ~17 ~-3 ~31 ~17 ~-3 ~31 dirt 0
fill ~18 ~-3 ~5 ~19 ~-3 ~5 mycelium 0
fill ~18 ~-3 ~6 ~19 ~-3 ~6 dirt 2
fill ~18 ~-3 ~7 ~18 ~-3 ~6 dirt 2
fill ~18 ~-3 ~8 ~18 ~-3 ~10 mycelium 0
fill ~18 ~-3 ~11 ~21 ~-3 ~11 gravel 0
fill ~18 ~-3 ~13 ~19 ~-3 ~13 mycelium 0
fill ~18 ~-3 ~21 ~20 ~-3 ~21 dirt 0
setblock ~18 ~-3 ~22 vine 15
fill ~18 ~-3 ~25 ~18 ~-3 ~25 soul_sand 0
fill ~18 ~-3 ~26 ~18 ~-3 ~26 soul_sand 0
fill ~18 ~-3 ~27 ~18 ~-3 ~27 soul_sand 0
fill ~18 ~-3 ~28 ~18 ~-3 ~28 soul_sand 0
fill ~18 ~-3 ~29 ~18 ~-3 ~29 dirt 0
setblock ~18 ~-3 ~30 dirt 2
fill ~18 ~-3 ~31 ~23 ~-3 ~31 mycelium 0
fill ~18 ~-3 ~32 ~18 ~-3 ~32 dirt 0
fill ~19 ~-3 ~3 ~20 ~-3 ~3 dirt 0
fill ~19 ~-3 ~4 ~19 ~-3 ~4 dirt 0
fill ~19 ~-3 ~7 ~20 ~-3 ~7 gravel 0
setblock ~19 ~-3 ~8 stonebrick 0
fill ~19 ~-3 ~9 ~20 ~-3 ~9 gravel 0
fill ~19 ~-3 ~12 ~19 ~-2 ~12 stonebrick 0
fill ~19 ~-3 ~22 ~26 ~-3 ~22 mycelium 0
fill ~19 ~-3 ~23 ~21 ~-3 ~23 gravel 0
setblock ~19 ~-3 ~25 stonebrick 2
setblock ~19 ~-3 ~26 vine 14
setblock ~19 ~-3 ~27 vine 10
setblock ~19 ~-3 ~28 vine 3
fill ~19 ~-3 ~29 ~19 ~-3 ~29 soul_sand 0
fill ~19 ~-3 ~30 ~20 ~-3 ~30 mycelium 0
fill ~19 ~-3 ~32 ~21 ~-3 ~32 mycelium 0
setblock ~20 ~-3 ~4 mycelium 0
fill ~20 ~-3 ~5 ~21 ~-3 ~5 gravel 0
fill ~20 ~-3 ~6 ~20 ~-3 ~5 gravel 0
fill ~20 ~-3 ~8 ~21 ~-3 ~8 mycelium 0
setblock ~20 ~-3 ~10 stonebrick 2
fill ~20 ~-3 ~12 ~26 ~-3 ~12 mycelium 0
fill ~20 ~-3 ~13 ~21 ~-3 ~13 dirt 2
setblock ~20 ~-3 ~24 dirt 2
fill ~20 ~-3 ~25 ~20 ~-3 ~25 soul_sand 0
fill ~20 ~-3 ~26 ~20 ~-3 ~26 soul_sand 0
fill ~20 ~-3 ~27 ~20 ~-3 ~27 soul_sand 0
fill ~20 ~-3 ~28 ~20 ~-3 ~28 soul_sand 0
fill ~20 ~-3 ~29 ~20 ~-3 ~29 dirt 0
fill ~21 ~-3 ~3 ~21 ~-3 ~4 monster_egg 3
fill ~21 ~-3 ~7 ~23 ~-3 ~7 mycelium 0
fill ~21 ~-3 ~9 ~24 ~-3 ~9 mycelium 0
fill ~21 ~-3 ~10 ~21 ~-3 ~7 mycelium 0
fill ~21 ~-3 ~21 ~22 ~-3 ~21 dirt 2
fill ~21 ~-3 ~24 ~21 ~-3 ~26 mycelium 0
setblock ~21 ~-3 ~27 dirt 2
fill ~21 ~-3 ~28 ~22 ~-3 ~28 mycelium 0
fill ~21 ~-3 ~29 ~21 ~-3 ~28 mycelium 0
setblock ~21 ~-3 ~30 dirt 2
fill ~22 ~-3 ~2 ~23 ~-3 ~2 gravel 0
fill ~22 ~-3 ~3 ~22 ~-3 ~4 gravel 0
setblock ~22 ~-3 ~5 dirt 2
fill ~22 ~-3 ~6 ~23 ~-3 ~6 mycelium 0
setblock ~22 ~-3 ~10 dirt 2
setblock ~22 ~-3 ~11 stonebrick 2
fill ~22 ~-3 ~13 ~23 ~-3 ~13 mycelium 0
setblock ~22 ~-3 ~23 stonebrick 0
fill ~22 ~-3 ~24 ~23 ~-3 ~24 dirt 2
fill ~22 ~-3 ~25 ~22 ~-3 ~24 dirt 2
fill ~22 ~-3 ~26 ~22 ~-3 ~28 mycelium 0
setblock ~22 ~-3 ~29 dirt 2
setblock ~22 ~-3 ~30 mycelium 0
fill ~22 ~-3 ~32 ~22 ~-3 ~32 dirt 0
setblock ~23 ~-3 ~3 stonebrick 2
fill ~23 ~-3 ~4 ~23 ~-3 ~7 mycelium 0
setblock ~23 ~-3 ~8 vine 8
setblock ~23 ~-3 ~10 mycelium 0
fill ~23 ~-3 ~11 ~27 ~-3 ~11 gravel 0
fill ~23 ~-3 ~21 ~24 ~-3 ~21 dirt 0
fill ~23 ~-3 ~23 ~25 ~-3 ~23 gravel 0
setblock ~23 ~-3 ~25 mycelium 0
fill ~23 ~-3 ~26 ~24 ~-3 ~26 gravel 0
fill ~23 ~-3 ~27 ~23 ~-3 ~30 gravel 0
setblock ~23 ~-3 ~32 mycelium 0
fill ~24 ~-3 ~2 ~27 ~-3 ~2 mycelium 0
fill ~24 ~-3 ~3 ~25 ~-3 ~3 mycelium 0
fill ~24 ~-3 ~4 ~24 ~-3 ~4 dirt 0
setblock ~24 ~-3 ~5 vine 4
setblock ~24 ~-3 ~6 vine 8
setblock ~24 ~-3 ~7 dirt 2
fill ~24 ~-3 ~8 ~24 ~-3 ~8 dirt 0
fill ~24 ~-3 ~10 ~25 ~-3 ~10 gravel 0
setblock ~24 ~-3 ~13 dirt 2
fill ~24 ~-3 ~24 ~24 ~-3 ~26 gravel 0
fill ~24 ~-3 ~27 ~24 ~-3 ~28 mycelium 0
setblock ~24 ~-3 ~29 gravel 0
setblock ~24 ~-3 ~30 stonebrick 2
fill ~24 ~-3 ~31 ~25 ~-3 ~31 gravel 0
fill ~24 ~-3 ~32 ~24 ~-3 ~31 gravel 0
setblock ~24 ~-3 ~33 stonebrick 0
setblock ~25 ~-3 ~4 dirt 2
fill ~25 ~-3 ~5 ~26 ~-3 ~5 mycelium 0
fill ~25 ~-3 ~6 ~25 ~-3 ~8 mycelium 0
setblock ~25 ~-3 ~9 stonebrick 0
fill ~25 ~-3 ~13 ~27 ~-3 ~13 mycelium 0
fill ~25 ~-3 ~14 ~27 ~-3 ~14 mycelium 0
setblock ~25 ~-3 ~21 vine 15
fill ~25 ~-3 ~24 ~26 ~-3 ~24 mycelium 0
fill ~25 ~-3 ~25 ~25 ~-3 ~25 dirt 0
fill ~25 ~-3 ~26 ~25 ~-2 ~26 vine 4
setblock ~25 ~-3 ~27 vine 8
fill ~25 ~-3 ~28 ~25 ~-3 ~29 dirt 2
setblock ~25 ~-3 ~30 gravel 0
setblock ~25 ~-3 ~32 stonebrick 0
setblock ~25 ~-3 ~33 gravel 0
fill ~26 ~-3 ~3 ~26 ~-3 ~3 dirt 0
fill ~26 ~-3 ~4 ~27 ~-3 ~4 mycelium 0
fill ~26 ~-3 ~6 ~27 ~-3 ~6 gravel 0
fill ~26 ~-3 ~7 ~29 ~-3 ~7 gravel 0
fill ~26 ~-3 ~8 ~26 ~-3 ~9 gravel 0
setblock ~26 ~-3 ~10 stonebrick 2
fill ~26 ~-3 ~15 ~27 ~-3 ~15 mycelium 0
fill ~26 ~-3 ~16 ~26 ~-3 ~17 dirt 2
fill ~26 ~-3 ~20 ~27 ~-3 ~20 mycelium 0
fill ~26 ~-3 ~21 ~27 ~-3 ~21 mycelium 0
setblock ~26 ~-3 ~23 stonebrick 2
fill ~26 ~-3 ~25 ~26 ~-3 ~28 mycelium 0
setblock ~26 ~-3 ~29 dirt 2
fill ~26 ~-3 ~30 ~27 ~-3 ~30 mycelium 0
setblock ~26 ~-3 ~31 monster_egg 3
setblock ~26 ~-3 ~32 gravel 0
setblock ~26 ~-3 ~33 stonebrick 2
setblock ~27 ~-3 ~3 mycelium 0
setblock ~27 ~-3 ~5 stonebrick 2
fill ~27 ~-3 ~8 ~28 ~-3 ~8 mycelium 0
setblock ~27 ~-3 ~9 vine 8
fill ~27 ~-3 ~10 ~32 ~-3 ~10 mycelium 0
setblock ~27 ~-3 ~12 gravel 0
fill ~27 ~-3 ~16 ~27 ~-3 ~17 mycelium 0
fill ~27 ~-3 ~18 ~28 ~-3 ~18 gravel 0
fill ~27 ~-3 ~19 ~27 ~-3 ~18 gravel 0
fill ~27 ~-3 ~22 ~28 ~-3 ~22 gravel 0
fill ~27 ~-3 ~23 ~29 ~-3 ~23 gravel 0
setblock ~27 ~-3 ~24 vine 4
setblock ~27 ~-3 ~25 vine 2
fill ~27 ~-3 ~26 ~27 ~-3 ~30 mycelium 0
fill ~27 ~-3 ~31 ~27 ~-3 ~31 dirt 0
fill ~27 ~-3 ~32 ~29 ~-3 ~32 mycelium 0
fill ~27 ~-3 ~33 ~31 ~-3 ~33 mycelium 0
fill ~28 ~-3 ~2 ~29 ~-3 ~2 gravel 0
setblock ~28 ~-3 ~3 stonebrick 0
fill ~28 ~-3 ~4 ~28 ~-3 ~5 gravel 0
setblock ~28 ~-3 ~6 monster_egg 3
setblock ~28 ~-3 ~9 mycelium 0
setblock ~28 ~-3 ~11 mycelium 0
setblock ~28 ~-3 ~12 stonebrick 2
fill ~28 ~-3 ~13 ~28 ~-3 ~18 gravel 0
fill ~28 ~-3 ~19 ~28 ~-3 ~20 stonebrick 0
setblock ~28 ~-3 ~21 gravel 0
fill ~28 ~-3 ~24 ~28 ~-3 ~25 mycelium 0
setblock ~28 ~-3 ~26 dirt 2
fill ~28 ~-3 ~27 ~28 ~-3 ~29 mycelium 0
setblock ~28 ~-3 ~30 dirt 2
fill ~28 ~-3 ~31 ~30 ~-3 ~31 mycelium 0
setblock ~29 ~-3 ~3 gravel 0
setblock ~29 ~-3 ~4 mycelium 0
setblock ~29 ~-3 ~5 dirt 2
fill ~29 ~-3 ~6 ~34 ~-3 ~6 mycelium 0
fill ~29 ~-3 ~8 ~30 ~-3 ~8 gravel 0
setblock ~29 ~-3 ~9 stonebrick 0
setblock ~29 ~-3 ~11 vine 2
fill ~29 ~-3 ~12 ~30 ~-3 ~12 mycelium 0
fill ~29 ~-3 ~13 ~30 ~-3 ~13 dirt 2
fill ~29 ~-3 ~14 ~34 ~-3 ~14 mycelium 0
setblock ~29 ~-3 ~15 vine 4
fill ~29 ~-3 ~16 ~31 ~-3 ~16 mycelium 0
fill ~29 ~-3 ~17 ~29 ~-3 ~17 dirt 0
fill ~29 ~-3 ~18 ~34 ~-3 ~18 mycelium 0
fill ~29 ~-3 ~19 ~30 ~-3 ~19 mycelium 0
setblock ~29 ~-3 ~20 vine 1
fill ~29 ~-3 ~21 ~34 ~-3 ~21 mycelium 0
setblock ~29 ~-3 ~22 dirt 2
fill ~29 ~-3 ~24 ~30 ~-3 ~24 gravel 0
setblock ~29 ~-3 ~25 stonebrick 0
fill ~29 ~-3 ~26 ~29 ~-3 ~28 gravel 0
setblock ~29 ~-3 ~29 dirt 2
setblock ~29 ~-3 ~30 mycelium 0
fill ~30 ~-3 ~2 ~34 ~-3 ~2 mycelium 0
fill ~30 ~-3 ~3 ~32 ~-3 ~3 mycelium 0
setblock ~30 ~-3 ~4 dirt 2
setblock ~30 ~-3 ~5 mycelium 0
fill ~30 ~-3 ~7 ~31 ~-3 ~7 mycelium 0
fill ~30 ~-3 ~9 ~31 ~-3 ~9 gravel 0
setblock ~30 ~-3 ~15 vine 1
setblock ~30 ~-3 ~20 vine 12
fill ~30 ~-3 ~22 ~30 ~-3 ~23 mycelium 0
setblock ~30 ~-3 ~25 gravel 0
fill ~30 ~-3 ~26 ~30 ~-3 ~27 mycelium 0
setblock ~30 ~-3 ~28 stonebrick 2
fill ~30 ~-3 ~29 ~31 ~-3 ~29 gravel 0
setblock ~30 ~-3 ~30 dirt 2
fill ~30 ~-3 ~32 ~30 ~-3 ~32 dirt 0
fill ~31 ~-3 ~1 ~35 ~-3 ~1 planks 0
fill ~31 ~-3 ~4 ~34 ~-3 ~4 mycelium 0
fill ~31 ~-3 ~5 ~32 ~-3 ~5 dirt 2
setblock ~31 ~-3 ~8 monster_egg 3
fill ~31 ~-3 ~11 ~32 ~-3 ~11 mycelium 0
setblock ~31 ~-3 ~12 dirt 2
setblock ~31 ~-3 ~13 mycelium 0
setblock ~31 ~-3 ~15 mycelium 0
setblock ~31 ~-3 ~17 vine 1
setblock ~31 ~-3 ~19 dirt 2
fill ~31 ~-3 ~20 ~31 ~-3 ~20 dirt 0
setblock ~31 ~-3 ~22 vine 2
fill ~31 ~-3 ~24 ~31 ~-3 ~24 dirt 0
fill ~31 ~-3 ~25 ~32 ~-3 ~25 mycelium 0
setblock ~31 ~-3 ~26 vine 4
fill ~31 ~-3 ~27 ~34 ~-3 ~27 mycelium 0
fill ~31 ~-3 ~28 ~34 ~-3 ~28 mycelium 0
fill ~31 ~-3 ~30 ~31 ~-3 ~31 monster_egg 3
setblock ~31 ~-3 ~32 mycelium 0
fill ~32 ~-3 ~0 ~33 ~-3 ~0 planks 0
setblock ~32 ~-3 ~7 monster_egg 3
fill ~32 ~-3 ~8 ~33 ~-3 ~8 gravel 0
setblock ~32 ~-3 ~9 monster_egg 3
fill ~32 ~-3 ~12 ~34 ~-3 ~12 mycelium 0
setblock ~32 ~-3 ~13 vine 4
fill ~32 ~-3 ~15 ~32 ~-3 ~15 dirt 0
setblock ~32 ~-3 ~16 dirt 2
fill ~32 ~-3 ~17 ~34 ~-3 ~17 mycelium 0
fill ~32 ~-3 ~19 ~32 ~-3 ~22 mycelium 0
fill ~32 ~-3 ~23 ~32 ~-3 ~24 dirt 2
setblock ~32 ~-3 ~26 vine 1
fill ~32 ~-3 ~29 ~32 ~-3 ~30 mycelium 0
setblock ~32 ~-3 ~31 gravel 0
setblock ~32 ~-3 ~32 monster_egg 3
setblock ~32 ~-3 ~33 gravel 0
fill ~33 ~-3 ~3 ~33 ~-3 ~3 dirt 0
fill ~33 ~-3 ~5 ~33 ~-3 ~5 dirt 0
setblock ~33 ~-3 ~7 stonebrick 2
fill ~33 ~-3 ~9 ~34 ~-3 ~9 mycelium 0
fill ~33 ~-3 ~10 ~33 ~-3 ~10 dirt 0
fill ~33 ~-3 ~11 ~33 ~-3 ~11 dirt 0
setblock ~33 ~-3 ~13 vine 8
fill ~33 ~-3 ~15 ~34 ~-3 ~15 mycelium 0
fill ~33 ~-3 ~16 ~34 ~-3 ~16 mycelium 0
fill ~33 ~-3 ~19 ~33 ~-3 ~19 dirt 0
fill ~33 ~-3 ~20 ~33 ~-3 ~20 dirt 0
setblock ~33 ~-3 ~22 vine 8
fill ~33 ~-3 ~23 ~34 ~-3 ~23 mycelium 0
fill ~33 ~-3 ~24 ~33 ~-3 ~24 dirt 0
fill ~33 ~-3 ~25 ~33 ~-3 ~25 dirt 0
fill ~33 ~-3 ~26 ~34 ~-3 ~26 mycelium 0
fill ~33 ~-3 ~29 ~33 ~-3 ~29 dirt 0
fill ~33 ~-3 ~30 ~34 ~-3 ~30 mycelium 0
fill ~33 ~-3 ~31 ~33 ~-3 ~32 dirt 2
fill ~33 ~-3 ~33 ~34 ~-3 ~33 mycelium 0
fill ~33 ~-3 ~36 ~34 ~-3 ~36 planks 0
fill ~34 ~-3 ~0 ~37 ~-3 ~0 grass 0
setblock ~34 ~-3 ~3 mycelium 0
setblock ~34 ~-3 ~5 mycelium 0
setblock ~34 ~-3 ~7 gravel 0
setblock ~34 ~-3 ~8 mycelium 0
fill ~34 ~-3 ~10 ~34 ~-3 ~33 mycelium 0
fill ~34 ~-3 ~34 ~36 ~-3 ~34 planks 0
fill ~35 ~-3 ~2 ~35 ~-3 ~3 planks 0
setblock ~35 ~-3 ~4 grass 0
fill ~35 ~-3 ~5 ~35 ~-3 ~6 planks 0
fill ~35 ~-3 ~7 ~37 ~-3 ~7 grass 0
fill ~35 ~-3 ~8 ~37 ~-3 ~8 grass 0
fill ~35 ~-3 ~9 ~37 ~-3 ~9 grass 0
fill ~35 ~-3 ~10 ~37 ~-3 ~10 grass 0
fill ~35 ~-3 ~11 ~37 ~-3 ~11 grass 0
fill ~35 ~-3 ~12 ~37 ~-3 ~12 grass 0
fill ~35 ~-3 ~13 ~37 ~-3 ~13 grass 0
fill ~35 ~-3 ~14 ~37 ~-3 ~14 grass 0
fill ~35 ~-3 ~15 ~37 ~-3 ~15 grass 0
fill ~35 ~-3 ~16 ~37 ~-3 ~16 grass 0
fill ~35 ~-3 ~17 ~37 ~-3 ~17 grass 0
fill ~35 ~-3 ~18 ~37 ~-3 ~18 grass 0
fill ~35 ~-3 ~19 ~37 ~-3 ~19 grass 0
fill ~35 ~-3 ~20 ~37 ~-3 ~20 grass 0
fill ~35 ~-3 ~21 ~37 ~-3 ~21 grass 0
fill ~35 ~-3 ~22 ~37 ~-3 ~22 grass 0
fill ~35 ~-3 ~23 ~37 ~-3 ~23 grass 0
fill ~35 ~-3 ~24 ~37 ~-3 ~24 grass 0
fill ~35 ~-3 ~25 ~37 ~-3 ~25 grass 0
fill ~35 ~-3 ~26 ~37 ~-3 ~26 grass 0
fill ~35 ~-3 ~27 ~37 ~-3 ~27 grass 0
fill ~35 ~-3 ~28 ~37 ~-3 ~28 grass 0
fill ~35 ~-3 ~29 ~37 ~-3 ~29 grass 0
fill ~35 ~-3 ~30 ~37 ~-3 ~30 grass 0
fill ~35 ~-3 ~31 ~37 ~-3 ~31 grass 0
fill ~35 ~-3 ~32 ~35 ~-3 ~34 planks 0
fill ~35 ~-3 ~36 ~36 ~-3 ~36 grass 0
fill ~36 ~-3 ~1 ~37 ~-3 ~1 grass 0
fill ~36 ~-3 ~2 ~37 ~-3 ~2 grass 0
fill ~36 ~-3 ~3 ~36 ~-3 ~4 planks 0
fill ~36 ~-3 ~5 ~37 ~-3 ~5 grass 0
fill ~36 ~-3 ~6 ~37 ~-3 ~6 grass 0
fill ~36 ~-3 ~32 ~37 ~-3 ~32 grass 0
fill ~36 ~-3 ~33 ~37 ~-3 ~33 grass 0
setblock ~36 ~-3 ~35 planks 0
fill ~37 ~-3 ~3 ~37 ~-3 ~35 grass 0
setblock ~37 ~-3 ~36 planks 0
fill ~2 ~-2 ~2 ~2 ~-2 ~3 fence 0
fill ~2 ~-2 ~34 ~2 ~-2 ~35 fence 0
fill ~3 ~-2 ~1 ~5 ~-2 ~1 fence 0
fill ~3 ~-2 ~2 ~7 ~-2 ~2 cobblestone_wall 1
fill ~3 ~-2 ~3 ~3 ~-2 ~4 cobblestone_wall 1
fill ~3 ~-2 ~5 ~3 ~-2 ~6 cobblestone_wall 0
fill ~3 ~-2 ~11 ~3 ~-2 ~15 cobblestone_wall 1
fill ~3 ~-2 ~16 ~3 ~-2 ~17 cobblestone_wall 0
fill ~3 ~-2 ~19 ~3 ~-2 ~21 cobblestone_wall 0
fill ~3 ~-2 ~23 ~3 ~-2 ~25 cobblestone_wall 1
fill ~3 ~-2 ~26 ~3 ~-2 ~28 cobblestone_wall 0
fill ~3 ~-2 ~30 ~3 ~-1 ~30 cobblestone_wall 0
fill ~3 ~-2 ~31 ~4 ~-2 ~31 cobblestone_wall 0
fill ~3 ~-2 ~32 ~3 ~-2 ~30 cobblestone_wall 0
fill ~3 ~-2 ~33 ~5 ~-2 ~33 cobblestone_wall 1
fill ~3 ~-2 ~35 ~5 ~-2 ~35 fence 0
fill ~4 ~-2 ~3 ~6 ~-2 ~3 mossy_cobblestone 0
fill ~4 ~-2 ~4 ~4 ~-2 ~3 mossy_cobblestone 0
setblock ~4 ~-2 ~5 double_plant 2
setblock ~4 ~-2 ~11 tallgrass 1
setblock ~4 ~-2 ~12 double_plant 3
setblock ~4 ~-2 ~13 cobblestone_wall 1
setblock ~4 ~-2 ~14 stone_slab 3
fill ~4 ~-2 ~15 ~4 ~-2 ~16 mossy_cobblestone 0
setblock ~4 ~-2 ~17 cobblestone_wall 0
setblock ~4 ~-2 ~20 leaves 13
setblock ~4 ~-2 ~24 mossy_cobblestone 0
setblock ~4 ~-2 ~25 cobblestone_wall 1
setblock ~4 ~-2 ~26 leaves 13
setblock ~4 ~-2 ~27 cobblestone 0
setblock ~4 ~-2 ~28 leaves 13
setblock ~4 ~-2 ~30 stone_slab 3
setblock ~4 ~-2 ~32 mossy_cobblestone 0
setblock ~5 ~-2 ~4 stone_slab 3
setblock ~5 ~-2 ~5 leaves 5
setblock ~5 ~-2 ~6 double_plant 2
fill ~5 ~-2 ~12 ~8 ~-2 ~12 iron_bars 0
setblock ~5 ~-2 ~13 stone_slab 3
fill ~5 ~-2 ~14 ~5 ~-1 ~14 cobblestone_wall 0
setblock ~5 ~-2 ~15 vine 2
setblock ~5 ~-2 ~16 leaves 13
fill ~5 ~-2 ~17 ~5 ~2 ~17 vine 1
setblock ~5 ~-2 ~19 leaves 13
fill ~5 ~-2 ~20 ~5 ~0 ~20 log2 0
fill ~5 ~-2 ~21 ~7 ~-2 ~21 leaves 13
setblock ~5 ~-2 ~24 stone_slab 3
setblock ~5 ~-2 ~25 double_plant 2
setblock ~5 ~-2 ~26 stone_slab 3
setblock ~5 ~-2 ~27 leaves 13
setblock ~5 ~-2 ~30 tallgrass 1
setblock ~5 ~-2 ~31 double_plant 2
setblock ~5 ~-2 ~32 stone_slab 3
setblock ~6 ~-2 ~4 leaves 5
fill ~6 ~-2 ~6 ~6 ~-2 ~7 stone_slab 3
setblock ~6 ~-2 ~15 tallgrass 1
fill ~6 ~-2 ~20 ~6 ~-1 ~20 leaves 13
fill ~6 ~-2 ~23 ~7 ~-2 ~23 vine 4
setblock ~6 ~-2 ~24 stone_stairs 3
setblock ~6 ~-2 ~31 tallgrass 1
setblock ~7 ~-2 ~1 fence 0
fill ~7 ~-2 ~3 ~7 ~-2 ~4 vine 2
setblock ~7 ~-2 ~5 mossy_cobblestone 0
setblock ~7 ~-2 ~11 iron_bars 0
setblock ~7 ~-2 ~13 double_plant 2
setblock ~7 ~-2 ~15 stone_slab 3
setblock ~7 ~-2 ~19 mossy_cobblestone 0
fill ~7 ~-2 ~25 ~7 ~-2 ~26 stone_slab 3
setblock ~7 ~-2 ~27 stone_stairs 1
fill ~8 ~-2 ~2 ~10 ~-2 ~2 cobblestone_wall 0
setblock ~8 ~-2 ~5 double_plant 3
fill ~8 ~-2 ~6 ~8 ~-2 ~7 stone_slab 3
setblock ~8 ~-2 ~13 stone_slab 3
fill ~8 ~-2 ~16 ~8 ~1 ~16 vine 2
fill ~8 ~-2 ~18 ~9 ~-2 ~18 stone_slab 3
fill ~8 ~-2 ~20 ~9 ~-2 ~20 stone_slab 3
fill ~8 ~-2 ~21 ~8 ~1 ~21 vine 2
setblock ~8 ~-2 ~22 leaves 13
fill ~8 ~-2 ~23 ~8 ~3 ~23 vine 2
fill ~8 ~-2 ~26 ~9 ~-2 ~26 stone_slab 3
fill ~8 ~-2 ~32 ~9 ~-2 ~32 leaves 5
setblock ~9 ~-2 ~3 cobblestone_wall 0
setblock ~9 ~-2 ~4 double_plant 2
setblock ~9 ~-2 ~5 mossy_cobblestone 0
setblock ~9 ~-2 ~6 tallgrass 1
setblock ~9 ~-2 ~23 stone_slab 0
setblock ~9 ~-2 ~30 double_plant 2
fill ~9 ~-2 ~31 ~9 ~0 ~31 cobblestone_wall 0
fill ~9 ~-2 ~33 ~12 ~-2 ~33 cobblestone_wall 1
setblock ~10 ~-2 ~3 tallgrass 1
fill ~10 ~-2 ~4 ~11 ~-2 ~4 stone_slab 3
fill ~10 ~-2 ~6 ~11 ~-2 ~6 stone_slab 3
setblock ~10 ~-2 ~7 tallgrass 1
setblock ~10 ~-2 ~23 stone_slab 3
fill ~10 ~-2 ~29 ~10 ~-2 ~30 tallgrass 1
fill ~10 ~-2 ~31 ~10 ~-2 ~33 cobblestone_wall 1
fill ~11 ~-2 ~13 ~12 ~-2 ~13 iron_bars 0
fill ~11 ~-2 ~15 ~11 ~-2 ~18 iron_bars 0
setblock ~11 ~-2 ~29 double_plant 3
setblock ~11 ~-2 ~30 stone_slab 3
setblock ~11 ~-2 ~31 vine 1
setblock ~11 ~-2 ~32 mossy_cobblestone 0
fill ~12 ~-2 ~12 ~14 ~-2 ~12 iron_bars 0
fill ~12 ~-2 ~16 ~12 ~-2 ~17 stone_slab 5
setblock ~12 ~-2 ~18 double_plant 2
setblock ~12 ~-2 ~19 stone_slab 5
fill ~12 ~-2 ~20 ~12 ~-2 ~21 iron_bars 0
fill ~12 ~-2 ~24 ~13 ~-2 ~24 tallgrass 1
fill ~12 ~-2 ~26 ~12 ~-2 ~27 stone_slab 3
setblock ~12 ~-2 ~29 stone_stairs 3
setblock ~12 ~-2 ~32 stone_slab 3
fill ~13 ~-2 ~2 ~16 ~-2 ~2 cobblestone_wall 0
setblock ~13 ~-2 ~13 bedrock 0
setblock ~13 ~-2 ~14 stone_slab 5
setblock ~13 ~-2 ~15 stonebrick 2
fill ~13 ~-2 ~16 ~18 ~-2 ~16 stonebrick 0
setblock ~13 ~-2 ~17 stonebrick 2
fill ~13 ~-2 ~18 ~14 ~-2 ~18 stonebrick 0
fill ~13 ~-2 ~19 ~13 ~-2 ~20 bedrock 0
fill ~13 ~-2 ~21 ~13 ~-2 ~22 iron_bars 0
setblock ~13 ~-2 ~28 cobblestone 0
setblock ~14 ~-2 ~3 cobblestone_wall 0
setblock ~14 ~-2 ~13 tallgrass 1
fill ~14 ~-2 ~14 ~14 ~-2 ~20 stonebrick 0
fill ~14 ~-2 ~21 ~22 ~-2 ~21 bedrock 0
setblock ~14 ~-2 ~22 iron_bars 0
fill ~14 ~-2 ~26 ~14 ~-2 ~27 stone_slab 3
setblock ~15 ~-2 ~3 cobblestone 0
fill ~15 ~-2 ~4 ~15 ~-1 ~4 iron_bars 0
fill ~15 ~-2 ~5 ~16 ~-2 ~5 stone_slab 3
setblock ~15 ~-2 ~7 stone_slab 3
setblock ~15 ~-2 ~10 tallgrass 1
fill ~15 ~-2 ~13 ~16 ~-2 ~13 stone_slab 5
fill ~15 ~-2 ~14 ~17 ~-2 ~14 stonebrick 2
fill ~15 ~-2 ~15 ~16 ~-2 ~15 stonebrick 0
fill ~15 ~-2 ~17 ~15 ~-2 ~18 stonebrick 2
fill ~15 ~-2 ~19 ~25 ~-2 ~19 stonebrick 0
fill ~15 ~-2 ~20 ~15 ~-2 ~19 stonebrick 0
fill ~15 ~-2 ~22 ~17 ~-2 ~22 bedrock 0
setblock ~15 ~-2 ~32 double_plant 2
fill ~15 ~-2 ~33 ~16 ~-2 ~33 cobblestone_wall 0
setblock ~16 ~-2 ~3 stone_slab 3
setblock ~16 ~-2 ~7 tallgrass 1
fill ~16 ~-2 ~8 ~16 ~-2 ~9 stone_slab 3
fill ~16 ~-2 ~12 ~17 ~-2 ~12 iron_bars 0
fill ~16 ~-2 ~17 ~17 ~-2 ~17 stonebrick 0
fill ~16 ~-2 ~18 ~19 ~-2 ~18 stonebrick 0
fill ~16 ~-2 ~20 ~18 ~-2 ~20 stonebrick 2
setblock ~16 ~-2 ~28 tallgrass 1
setblock ~16 ~-2 ~31 leaves 5
setblock ~16 ~-2 ~32 stone_slab 3
fill ~17 ~-2 ~2 ~21 ~-2 ~2 cobblestone_wall 1
setblock ~17 ~-2 ~3 leaves 5
fill ~17 ~-2 ~4 ~18 ~-2 ~4 cobblestone_wall 1
setblock ~17 ~-2 ~5 double_plant 3
setblock ~17 ~-2 ~6 stonebrick 2
setblock ~17 ~-2 ~7 cobblestone 0
setblock ~17 ~-2 ~15 stonebrick 2
setblock ~17 ~-2 ~23 vine 4
setblock ~17 ~-2 ~25 stone_slab 3
setblock ~17 ~-2 ~26 double_plant 3
fill ~17 ~-2 ~27 ~17 ~-2 ~28 stone_slab 3
setblock ~17 ~-2 ~29 leaves 5
setblock ~17 ~-2 ~30 stone_slab 3
setblock ~17 ~-2 ~31 mossy_cobblestone 0
fill ~17 ~-2 ~32 ~17 ~-2 ~33 cobblestone_wall 1
setblock ~18 ~-2 ~3 cobblestone_wall 1
setblock ~18 ~-2 ~5 leaves 5
setblock ~18 ~-2 ~6 double_plant 2
setblock ~18 ~-2 ~7 tallgrass 1
setblock ~18 ~-2 ~8 stone_slab 3
setblock ~18 ~-2 ~9 stone_slab 0
setblock ~18 ~-2 ~12 stone_brick_stairs 0
fill ~18 ~-2 ~14 ~19 ~-2 ~14 stonebrick 0
fill ~18 ~-2 ~15 ~24 ~-2 ~15 stonebrick 0
setblock ~18 ~-2 ~17 stonebrick 2
setblock ~18 ~-2 ~22 vine 6
setblock ~18 ~-2 ~25 monster_egg 5
setblock ~18 ~-2 ~26 stonebrick 1
setblock ~18 ~-2 ~27 stonebrick 2
setblock ~18 ~-2 ~28 monster_egg 5
setblock ~18 ~-2 ~29 stonebrick 1
setblock ~18 ~-2 ~30 double_plant 2
setblock ~18 ~-2 ~31 stone_slab 3
setblock ~18 ~-2 ~32 mossy_cobblestone 0
fill ~18 ~-2 ~33 ~19 ~-2 ~33 cobblestone_wall 1
fill ~19 ~-2 ~3 ~20 ~-2 ~3 mossy_cobblestone 0
fill ~19 ~-2 ~4 ~19 ~-2 ~3 mossy_cobblestone 0
fill ~19 ~-2 ~5 ~20 ~-2 ~5 vine 4
setblock ~19 ~-2 ~6 tallgrass 1
setblock ~19 ~-2 ~16 stonebrick 2
fill ~19 ~-2 ~17 ~21 ~-2 ~17 stonebrick 0
fill ~19 ~-2 ~20 ~20 ~-2 ~20 stonebrick 0
fill ~19 ~-2 ~22 ~25 ~-2 ~22 iron_bars 0
setblock ~19 ~-2 ~24 stone_pressure_plate 0
setblock ~19 ~-2 ~25 iron_door 1
fill ~19 ~-2 ~29 ~20 ~-2 ~29 monster_egg 5
fill ~19 ~-2 ~30 ~20 ~-2 ~30 stone_slab 3
setblock ~19 ~-2 ~32 leaves 5
setblock ~20 ~-2 ~4 leaves 5
setblock ~20 ~-2 ~12 stone_brick_stairs 1
setblock ~20 ~-2 ~13 monster_egg 5
fill ~20 ~-2 ~14 ~21 ~-2 ~14 stonebrick 2
fill ~20 ~-2 ~16 ~25 ~-2 ~16 stonebrick 0
setblock ~20 ~-2 ~18 stonebrick 2
setblock ~20 ~-2 ~24 tallgrass 1
fill ~20 ~-2 ~25 ~20 ~-2 ~26 monster_egg 5
setblock ~20 ~-2 ~27 stonebrick 1
fill ~20 ~-2 ~28 ~20 ~-1 ~28 monster_egg 5
fill ~20 ~-2 ~31 ~21 ~-2 ~31 cobblestone_wall 0
setblock ~20 ~-2 ~32 stone_slab 3
fill ~20 ~-2 ~33 ~23 ~-2 ~33 cobblestone_wall 0
fill ~21 ~-2 ~3 ~21 ~-1 ~3 vine 2
fill ~21 ~-2 ~12 ~26 ~-2 ~12 iron_bars 0
setblock ~21 ~-2 ~13 tallgrass 1
fill ~21 ~-2 ~18 ~22 ~-2 ~18 stonebrick 0
fill ~21 ~-2 ~20 ~22 ~-2 ~20 stonebrick 2
fill ~21 ~-2 ~25 ~21 ~-2 ~26 stone_slab 3
setblock ~21 ~-2 ~27 double_plant 2
fill ~21 ~-2 ~28 ~21 ~-2 ~29 stone_slab 3
setblock ~21 ~-2 ~30 tallgrass 1
setblock ~21 ~-2 ~32 cobblestone_wall 0
setblock ~22 ~-2 ~5 tallgrass 1
fill ~22 ~-2 ~9 ~23 ~-2 ~9 stone_slab 3
setblock ~22 ~-2 ~10 tallgrass 1
fill ~22 ~-2 ~13 ~23 ~-2 ~13 stone_slab 5
fill ~22 ~-2 ~14 ~24 ~-2 ~14 stonebrick 0
setblock ~22 ~-2 ~17 stonebrick 2
setblock ~22 ~-2 ~25 tallgrass 1
setblock ~22 ~-2 ~29 tallgrass 1
setblock ~22 ~-2 ~31 stone_slab 3
setblock ~22 ~-2 ~32 cobblestone 0
setblock ~23 ~-2 ~5 stone_slab 3
setblock ~23 ~-2 ~6 stone_slab 0
setblock ~23 ~-2 ~7 stone_slab 3
fill ~23 ~-2 ~17 ~25 ~-2 ~17 stonebrick 0
fill ~23 ~-2 ~18 ~24 ~-2 ~18 stonebrick 2
setblock ~23 ~-2 ~20 stonebrick 0
setblock ~23 ~-2 ~21 stone_slab 5
setblock ~23 ~-2 ~24 double_plant 3
setblock ~23 ~-2 ~32 stone_slab 3
fill ~24 ~-2 ~2 ~27 ~-2 ~2 cobblestone_wall 0
fill ~24 ~-2 ~3 ~24 ~-2 ~2 cobblestone_wall 0
setblock ~24 ~-2 ~4 cobblestone 0
setblock ~24 ~-2 ~7 double_plant 3
setblock ~24 ~-2 ~8 cobblestone 0
setblock ~24 ~-2 ~11 iron_bars 0
setblock ~24 ~-2 ~13 tallgrass 1
setblock ~24 ~-2 ~20 stonebrick 2
setblock ~24 ~-2 ~21 bedrock 0
setblock ~24 ~-2 ~27 stone_slab 3
fill ~24 ~-2 ~31 ~24 ~2 ~31 vine 8
setblock ~25 ~-2 ~3 stone_slab 3
setblock ~25 ~-2 ~4 double_plant 2
fill ~25 ~-2 ~5 ~25 ~-2 ~6 stone_slab 3
setblock ~25 ~-2 ~14 stone_slab 5
setblock ~25 ~-2 ~15 stonebrick 2
setblock ~25 ~-2 ~18 stonebrick 0
setblock ~25 ~-2 ~20 stone_slab 5
setblock ~25 ~-2 ~21 vine 4
setblock ~25 ~-2 ~25 cobblestone 0
fill ~25 ~-2 ~28 ~25 ~-2 ~29 tallgrass 1
fill ~25 ~-2 ~32 ~25 ~2 ~32 vine 8
setblock ~26 ~-2 ~3 cobblestone 0
setblock ~26 ~-2 ~4 stone_slab 3
fill ~26 ~-2 ~5 ~27 ~-2 ~5 vine 8
fill ~26 ~-2 ~13 ~27 ~-2 ~13 iron_bars 0
setblock ~26 ~-2 ~15 stone_slab 5
setblock ~26 ~-2 ~16 tallgrass 1
setblock ~26 ~-2 ~17 double_plant 2
setblock ~26 ~-2 ~18 bedrock 0
setblock ~26 ~-2 ~19 stone_slab 5
fill ~26 ~-2 ~21 ~27 ~-2 ~21 iron_bars 0
fill ~26 ~-2 ~24 ~26 ~-2 ~25 stone_slab 3
setblock ~26 ~-2 ~27 stone_slab 3
fill ~26 ~-2 ~28 ~26 ~1 ~28 vine 8
setblock ~26 ~-2 ~29 double_plant 2
fill ~26 ~-2 ~30 ~27 ~-2 ~30 leaves 5
fill ~26 ~-2 ~33 ~26 ~2 ~33 vine 4
fill ~27 ~-2 ~4 ~27 ~4 ~4 vine 1
fill ~27 ~-2 ~6 ~27 ~2 ~6 vine 12
setblock ~27 ~-2 ~14 iron_bars 0
fill ~27 ~-2 ~16 ~27 ~-2 ~18 iron_bars 0
setblock ~27 ~-2 ~20 iron_bars 0
setblock ~27 ~-2 ~26 stone_stairs 2
fill ~27 ~-2 ~28 ~28 ~-2 ~28 leaves 5
setblock ~27 ~-2 ~31 stone_slab 3
fill ~27 ~-2 ~32 ~28 ~-2 ~32 cobblestone_wall 0
fill ~27 ~-2 ~33 ~28 ~-2 ~33 cobblestone_wall 0
fill ~28 ~-2 ~6 ~28 ~1 ~6 vine 8
fill ~28 ~-2 ~24 ~28 ~-2 ~25 stone_slab 3
setblock ~28 ~-2 ~26 tallgrass 1
fill ~28 ~-2 ~29 ~28 ~-1 ~29 leaves 13
fill ~28 ~-2 ~30 ~28 ~0 ~30 log2 0
setblock ~28 ~-2 ~31 leaves 5
fill ~29 ~-2 ~2 ~29 ~2 ~2 vine 8
setblock ~29 ~-2 ~5 tallgrass 1
setblock ~29 ~-2 ~6 leaves 5
fill ~29 ~-2 ~8 ~30 ~-2 ~8 vine 4
fill ~29 ~-2 ~10 ~30 ~-2 ~10 stone_slab 3
fill ~29 ~-2 ~12 ~30 ~-2 ~12 stone_slab 3
fill ~29 ~-2 ~13 ~30 ~-2 ~13 tallgrass 1
fill ~29 ~-2 ~14 ~30 ~-2 ~14 stone_slab 3
setblock ~29 ~-2 ~16 stone_slab 3
setblock ~29 ~-2 ~17 cobblestone 0
fill ~29 ~-2 ~19 ~30 ~-2 ~19 stone_slab 3
setblock ~29 ~-2 ~22 tallgrass 1
setblock ~29 ~-2 ~29 tallgrass 1
setblock ~29 ~-2 ~30 leaves 5
fill ~29 ~-2 ~31 ~29 ~0 ~31 vine 4
setblock ~29 ~-2 ~32 leaves 13
fill ~29 ~-2 ~33 ~31 ~-2 ~33 cobblestone_wall 1
fill ~30 ~-2 ~2 ~31 ~-2 ~2 cobblestone_wall 0
setblock ~30 ~-2 ~3 leaves 13
setblock ~30 ~-2 ~4 tallgrass 1
setblock ~30 ~-2 ~5 leaves 13
setblock ~30 ~-2 ~17 vine 2
fill ~30 ~-2 ~18 ~31 ~-2 ~18 stone_slab 3
setblock ~30 ~-2 ~20 vine 8
setblock ~30 ~-2 ~21 stone_slab 3
setblock ~30 ~-2 ~23 stone_slab 3
setblock ~30 ~-2 ~26 stone_stairs 1
fill ~30 ~-2 ~28 ~30 ~2 ~28 vine 1
fill ~30 ~-2 ~29 ~30 ~0 ~29 vine 2
setblock ~30 ~-2 ~30 tallgrass 1
setblock ~30 ~-2 ~31 leaves 13
setblock ~30 ~-2 ~32 mossy_cobblestone 0
setblock ~31 ~-2 ~3 cobblestone_wall 0
setblock ~31 ~-2 ~4 leaves 5
fill ~31 ~-2 ~5 ~31 ~-1 ~5 log2 0
fill ~31 ~-2 ~6 ~32 ~-2 ~6 leaves 5
fill ~31 ~-2 ~7 ~31 ~-2 ~6 leaves 5
fill ~31 ~-2 ~9 ~31 ~3 ~9 vine 4
setblock ~31 ~-2 ~11 stone_stairs 0
setblock ~31 ~-2 ~12 double_plant 2
setblock ~31 ~-2 ~15 vine 8
setblock ~31 ~-2 ~16 stone_slab 0
setblock ~31 ~-2 ~19 double_plant 2
setblock ~31 ~-2 ~20 mossy_cobblestone 0
fill ~31 ~-2 ~21 ~34 ~-2 ~21 cobblestone_wall 1
setblock ~31 ~-2 ~24 cobblestone 0
setblock ~31 ~-2 ~27 stone_slab 3
fill ~31 ~-2 ~31 ~31 ~2 ~31 vine 4
setblock ~31 ~-2 ~32 cobblestone_wall 1
fill ~32 ~-2 ~1 ~35 ~-2 ~1 fence 0
fill ~32 ~-2 ~2 ~34 ~-2 ~2 cobblestone_wall 1
setblock ~32 ~-2 ~3 vine 8
fill ~32 ~-2 ~4 ~33 ~-2 ~4 leaves 13
setblock ~32 ~-2 ~5 vine 10
setblock ~32 ~-2 ~10 leaves 13
fill ~32 ~-2 ~11 ~32 ~-1 ~11 cobblestone_wall 0
fill ~32 ~-2 ~12 ~34 ~-2 ~12 cobblestone_wall 0
fill ~32 ~-2 ~14 ~34 ~-2 ~14 cobblestone_wall 1
setblock ~32 ~-2 ~15 mossy_cobblestone 0
setblock ~32 ~-2 ~16 double_plant 3
setblock ~32 ~-2 ~19 leaves 5
setblock ~32 ~-2 ~20 cobblestone_wall 1
setblock ~32 ~-2 ~23 tallgrass 1
setblock ~32 ~-2 ~24 double_plant 2
setblock ~32 ~-2 ~25 stone_slab 3
fill ~32 ~-2 ~28 ~34 ~-2 ~28 cobblestone_wall 1
fill ~32 ~-2 ~29 ~32 ~-2 ~28 cobblestone_wall 1
setblock ~32 ~-2 ~30 leaves 5
setblock ~33 ~-2 ~3 mossy_cobblestone 0
setblock ~33 ~-2 ~5 mossy_cobblestone 0
fill ~33 ~-2 ~6 ~34 ~-2 ~6 cobblestone_wall 0
setblock ~33 ~-2 ~9 leaves 13
setblock ~33 ~-2 ~10 mossy_cobblestone 0
setblock ~33 ~-2 ~11 cobblestone 0
fill ~33 ~-2 ~15 ~33 ~-2 ~16 leaves 5
setblock ~33 ~-2 ~17 cobblestone_wall 0
setblock ~33 ~-2 ~18 leaves 5
fill ~33 ~-2 ~19 ~33 ~-2 ~20 mossy_cobblestone 0
setblock ~33 ~-2 ~23 stone_slab 3
fill ~33 ~-2 ~24 ~33 ~-2 ~25 cobblestone 0
setblock ~33 ~-2 ~26 stone_slab 3
setblock ~33 ~-2 ~27 leaves 5
setblock ~33 ~-2 ~29 mossy_cobblestone 0
setblock ~33 ~-2 ~30 stone_slab 3
setblock ~33 ~-2 ~31 tallgrass 1
setblock ~33 ~-2 ~32 double_plant 3
fill ~33 ~-2 ~33 ~34 ~-2 ~33 cobblestone_wall 0
fill ~33 ~-2 ~34 ~36 ~-2 ~34 fence 0
fill ~34 ~-2 ~3 ~34 ~-2 ~5 cobblestone_wall 1
fill ~34 ~-2 ~8 ~34 ~-1 ~8 cobblestone_wall 0
fill ~34 ~-2 ~9 ~34 ~-2 ~10 cobblestone_wall 1
setblock ~34 ~-2 ~11 cobblestone_wall 0
setblock ~34 ~-2 ~13 cobblestone_wall 0
fill ~34 ~-2 ~15 ~34 ~-2 ~16 cobblestone_wall 0
fill ~34 ~-2 ~17 ~34 ~0 ~17 cobblestone_wall 1
fill ~34 ~-2 ~18 ~34 ~-2 ~22 cobblestone_wall 1
fill ~34 ~-2 ~23 ~34 ~-2 ~26 cobblestone_wall 0
fill ~34 ~-2 ~27 ~34 ~-1 ~27 cobblestone_wall 1
setblock ~34 ~-2 ~29 cobblestone_wall 1
fill ~34 ~-2 ~30 ~34 ~-2 ~33 cobblestone_wall 0
fill ~35 ~-2 ~2 ~35 ~-2 ~3 fence 0
fill ~35 ~-2 ~5 ~35 ~-2 ~6 fence 0
fill ~35 ~-2 ~32 ~35 ~-2 ~34 fence 0
fill ~36 ~-2 ~25 ~37 ~-2 ~25 tallgrass 1
setblock ~37 ~-2 ~28 tallgrass 1
setblock ~2 ~-1 ~3 torch 5
fill ~3 ~-1 ~2 ~3 ~-2 ~2 cobblestone_wall 1
setblock ~3 ~-1 ~6 cobblestone_wall 0
setblock ~3 ~-1 ~12 cobblestone_wall 1
fill ~3 ~-1 ~13 ~3 ~-1 ~14 iron_bars 0
setblock ~3 ~-1 ~16 vine 8
fill ~3 ~-1 ~19 ~3 ~-1 ~20 iron_bars 0
setblock ~3 ~-1 ~21 cobblestone_wall 0
fill ~3 ~-1 ~24 ~4 ~-1 ~24 iron_bars 0
setblock ~3 ~-1 ~25 cobblestone_wall 1
fill ~3 ~-1 ~27 ~3 ~0 ~27 cobblestone_wall 0
fill ~3 ~-1 ~31 ~3 ~-1 ~32 iron_bars 0
fill ~3 ~-1 ~33 ~3 ~-2 ~33 cobblestone_wall 1
setblock ~3 ~-1 ~35 torch 5
setblock ~4 ~-1 ~1 torch 5
fill ~4 ~-1 ~2 ~5 ~-1 ~2 vine 1
fill ~4 ~-1 ~3 ~4 ~-1 ~4 leaves 5
setblock ~4 ~-1 ~5 double_plant 8
setblock ~4 ~-1 ~12 double_plant 10
setblock ~4 ~-1 ~15 vine 1
setblock ~4 ~-1 ~16 mossy_cobblestone 0
setblock ~4 ~-1 ~17 vine 5
fill ~4 ~-1 ~20 ~4 ~0 ~20 vine 8
fill ~4 ~-1 ~25 ~4 ~1 ~25 vine 4
setblock ~4 ~-1 ~27 leaves 13
fill ~4 ~-1 ~32 ~4 ~-1 ~33 iron_bars 0
setblock ~5 ~-1 ~3 mossy_cobblestone 0
setblock ~5 ~-1 ~4 vine 4
setblock ~5 ~-1 ~6 double_plant 8
setblock ~5 ~-1 ~13 cobblestone_wall 0
setblock ~5 ~-1 ~15 cobblestone_wall 0
setblock ~5 ~-1 ~16 vine 2
setblock ~5 ~-1 ~19 vine 1
fill ~5 ~-1 ~21 ~5 ~-2 ~21 leaves 13
setblock ~5 ~-1 ~25 double_plant 11
setblock ~5 ~-1 ~31 double_plant 11
setblock ~5 ~-1 ~33 cobblestone_wall 1
setblock ~6 ~-1 ~3 leaves 5
setblock ~6 ~-1 ~21 web 0
fill ~6 ~-1 ~23 ~7 ~-1 ~23 vine 4
fill ~7 ~-1 ~2 ~9 ~-1 ~2 iron_bars 0
setblock ~7 ~-1 ~13 double_plant 11
fill ~7 ~-1 ~19 ~7 ~1 ~19 vine 2
setblock ~8 ~-1 ~5 double_plant 8
fill ~8 ~-1 ~17 ~8 ~0 ~17 web 0
fill ~8 ~-1 ~22 ~8 ~2 ~22 vine 2
setblock ~9 ~-1 ~4 double_plant 11
setblock ~9 ~-1 ~30 double_plant 10
setblock ~9 ~-1 ~32 leaves 5
fill ~9 ~-1 ~33 ~10 ~-1 ~33 cobblestone_wall 1
fill ~10 ~-1 ~2 ~10 ~0 ~2 cobblestone_wall 0
fill ~10 ~-1 ~31 ~10 ~-1 ~32 iron_bars 0
setblock ~11 ~-1 ~29 double_plant 9
fill ~11 ~-1 ~32 ~11 ~-1 ~33 iron_bars 0
setblock ~12 ~-1 ~17 bedrock 0
setblock ~12 ~-1 ~18 double_plant 10
setblock ~12 ~-1 ~33 cobblestone_wall 1
fill ~13 ~-1 ~16 ~13 ~0 ~16 bedrock 0
setblock ~14 ~-1 ~2 cobblestone_wall 0
fill ~14 ~-1 ~14 ~16 ~-1 ~14 bedrock 0
fill ~14 ~-1 ~18 ~15 ~-1 ~18 bedrock 0
fill ~14 ~-1 ~19 ~15 ~-1 ~19 bedrock 0
fill ~14 ~-1 ~20 ~23 ~-1 ~20 bedrock 0
fill ~15 ~-1 ~2 ~17 ~-1 ~2 iron_bars 0
fill ~15 ~-1 ~3 ~15 ~-1 ~2 iron_bars 0
fill ~15 ~-1 ~16 ~15 ~-1 ~21 bedrock 0
setblock ~15 ~-1 ~32 double_plant 10
fill ~15 ~-1 ~33 ~15 ~-2 ~33 cobblestone_wall 0
setblock ~16 ~-1 ~17 bedrock 0
fill ~16 ~-1 ~21 ~16 ~2 ~21 bedrock 0
fill ~17 ~-1 ~4 ~17 ~1 ~4 cobblestone_wall 1
setblock ~17 ~-1 ~5 double_plant 9
setblock ~17 ~-1 ~14 coal_block 0
fill ~17 ~-1 ~15 ~17 ~0 ~15 bedrock 0
fill ~17 ~-1 ~16 ~17 ~2 ~16 bedrock 0
fill ~17 ~-1 ~22 ~17 ~1 ~22 bedrock 0
setblock ~17 ~-1 ~25 stone_button 2
setblock ~17 ~-1 ~26 double_plant 10
setblock ~17 ~-1 ~28 vine 8
setblock ~17 ~-1 ~29 stone_button 2
setblock ~17 ~-1 ~31 leaves 5
fill ~17 ~-1 ~33 ~17 ~0 ~33 cobblestone_wall 1
setblock ~18 ~-1 ~2 cobblestone_wall 1
setblock ~18 ~-1 ~6 double_plant 8
fill ~18 ~-1 ~15 ~18 ~0 ~15 coal_block 0
fill ~18 ~-1 ~16 ~20 ~-1 ~16 coal_block 0
fill ~18 ~-1 ~17 ~23 ~-1 ~17 coal_block 0
fill ~18 ~-1 ~18 ~23 ~-1 ~18 coal_block 0
setblock ~18 ~-1 ~24 stone_button 4
fill ~18 ~-1 ~25 ~18 ~-1 ~26 stone 0
setblock ~18 ~-1 ~27 stone_stairs 2
setblock ~18 ~-1 ~28 stonebrick 1
setblock ~18 ~-1 ~29 monster_egg 5
setblock ~18 ~-1 ~30 double_plant 9
setblock ~18 ~-1 ~32 leaves 5
fill ~19 ~-1 ~3 ~19 ~-1 ~4 leaves 5
setblock ~19 ~-1 ~12 stone_brick_stairs 2
fill ~19 ~-1 ~13 ~19 ~0 ~13 monster_egg 5
setblock ~19 ~-1 ~25 iron_door 8
setblock ~19 ~-1 ~26 stone_button 1
setblock ~19 ~-1 ~29 stone 0
setblock ~19 ~-1 ~30 stone_brick_stairs 7
fill ~19 ~-1 ~33 ~20 ~-1 ~33 iron_bars 0
setblock ~20 ~-1 ~3 mossy_cobblestone 0
setblock ~20 ~-1 ~4 vine 4
setblock ~20 ~-1 ~24 stone_button 4
setblock ~20 ~-1 ~25 stonebrick 2
setblock ~20 ~-1 ~26 stone_stairs 3
setblock ~20 ~-1 ~27 stone 0
setblock ~20 ~-1 ~29 stonebrick 2
fill ~20 ~-1 ~31 ~20 ~-2 ~31 cobblestone_wall 0
setblock ~21 ~-1 ~2 cobblestone_wall 1
fill ~21 ~-1 ~15 ~21 ~1 ~15 coal_block 0
fill ~21 ~-1 ~16 ~21 ~3 ~16 bedrock 0
fill ~21 ~-1 ~21 ~21 ~0 ~21 bedrock 0
setblock ~21 ~-1 ~25 stone_button 1
setblock ~21 ~-1 ~27 double_plant 11
fill ~21 ~-1 ~28 ~21 ~-1 ~29 stone_button 1
fill ~21 ~-1 ~31 ~21 ~-1 ~32 iron_bars 0
setblock ~21 ~-1 ~33 cobblestone_wall 0
fill ~22 ~-1 ~14 ~22 ~0 ~14 bedrock 0
fill ~22 ~-1 ~15 ~22 ~2 ~15 bedrock 0
setblock ~22 ~-1 ~16 coal_block 0
fill ~22 ~-1 ~32 ~22 ~-1 ~33 iron_bars 0
setblock ~23 ~-1 ~13 bedrock 0
fill ~23 ~-1 ~19 ~24 ~-1 ~19 bedrock 0
setblock ~23 ~-1 ~24 double_plant 11
fill ~23 ~-1 ~33 ~23 ~0 ~33 cobblestone_wall 0
fill ~24 ~-1 ~2 ~24 ~0 ~2 cobblestone_wall 0
setblock ~24 ~-1 ~7 double_plant 9
setblock ~24 ~-1 ~14 bedrock 0
fill ~24 ~-1 ~16 ~24 ~-1 ~17 bedrock 0
fill ~25 ~-1 ~2 ~26 ~-1 ~2 iron_bars 0
setblock ~25 ~-1 ~4 double_plant 8
fill ~25 ~-1 ~17 ~25 ~-1 ~18 bedrock 0
setblock ~26 ~-1 ~3 iron_bars 0
fill ~26 ~-1 ~5 ~27 ~-1 ~5 vine 8
setblock ~26 ~-1 ~17 double_plant 11
setblock ~26 ~-1 ~29 double_plant 9
fill ~26 ~-1 ~30 ~27 ~-1 ~30 vine 8
setblock ~27 ~-1 ~2 cobblestone_wall 0
setblock ~27 ~-1 ~29 web 0
fill ~27 ~-1 ~32 ~28 ~-1 ~32 iron_bars 0
fill ~27 ~-1 ~33 ~27 ~-2 ~33 cobblestone_wall 0
fill ~28 ~-1 ~26 ~28 ~1 ~26 vine 1
setblock ~28 ~-1 ~31 vine 4
fill ~28 ~-1 ~33 ~29 ~-1 ~33 iron_bars 0
fill ~29 ~-1 ~8 ~30 ~-1 ~8 vine 4
setblock ~29 ~-1 ~30 vine 2
fill ~30 ~-1 ~2 ~30 ~-2 ~2 cobblestone_wall 0
fill ~30 ~-1 ~4 ~30 ~1 ~4 vine 8
fill ~30 ~-1 ~5 ~30 ~-1 ~4 vine 8
setblock ~30 ~-1 ~6 leaves 13
fill ~30 ~-1 ~30 ~30 ~0 ~30 web 0
setblock ~30 ~-1 ~32 leaves 13
fill ~31 ~-1 ~2 ~31 ~-1 ~3 iron_bars 0
setblock ~31 ~-1 ~4 vine 1
fill ~31 ~-1 ~6 ~31 ~0 ~6 vine 2
setblock ~31 ~-1 ~12 double_plant 9
setblock ~31 ~-1 ~19 double_plant 9
setblock ~31 ~-1 ~33 cobblestone_wall 1
fill ~32 ~-1 ~2 ~33 ~-1 ~2 vine 1
setblock ~32 ~-1 ~3 vine 0
setblock ~32 ~-1 ~5 vine 2
fill ~32 ~-1 ~6 ~32 ~1 ~6 vine 4
fill ~32 ~-1 ~14 ~34 ~-1 ~14 iron_bars 0
fill ~32 ~-1 ~15 ~32 ~2 ~15 cobblestone_wall 1
setblock ~32 ~-1 ~16 double_plant 9
setblock ~32 ~-1 ~21 cobblestone_wall 1
setblock ~32 ~-1 ~24 double_plant 9
fill ~32 ~-1 ~28 ~34 ~-1 ~28 iron_bars 0
fill ~32 ~-1 ~29 ~32 ~-1 ~28 iron_bars 0
fill ~32 ~-1 ~30 ~32 ~2 ~30 vine 2
setblock ~33 ~-1 ~3 leaves 13
setblock ~33 ~-1 ~5 cobblestone_wall 1
setblock ~33 ~-1 ~10 leaves 13
fill ~33 ~-1 ~11 ~34 ~-1 ~11 iron_bars 0
fill ~33 ~-1 ~19 ~33 ~-1 ~20 leaves 5
fill ~33 ~-1 ~21 ~34 ~-1 ~21 iron_bars 0
fill ~33 ~-1 ~24 ~33 ~-1 ~25 iron_bars 0
setblock ~33 ~-1 ~29 cobblestone_wall 1
setblock ~33 ~-1 ~32 double_plant 9
fill ~33 ~-1 ~33 ~33 ~-2 ~33 cobblestone_wall 0
fill ~34 ~-1 ~2 ~34 ~0 ~2 cobblestone_wall 1
fill ~34 ~-1 ~3 ~34 ~1 ~3 vine 1
setblock ~34 ~-1 ~6 cobblestone_wall 0
setblock ~34 ~-1 ~12 cobblestone_wall 0
setblock ~34 ~-1 ~13 iron_bars 0
fill ~34 ~-1 ~15 ~34 ~-1 ~16 iron_bars 0
fill ~34 ~-1 ~22 ~34 ~-1 ~23 iron_bars 0
fill ~34 ~-1 ~24 ~34 ~0 ~24 cobblestone_wall 0
fill ~34 ~-1 ~25 ~34 ~-1 ~26 iron_bars 0
fill ~34 ~-1 ~29 ~34 ~-1 ~30 iron_bars 0
fill ~34 ~-1 ~31 ~34 ~0 ~31 cobblestone_wall 0
setblock ~35 ~-1 ~1 torch 5
setblock ~35 ~-1 ~5 torch 5
setblock ~35 ~-1 ~34 torch 5
setblock ~3 ~0 ~19 leaves 5
fill ~3 ~0 ~24 ~3 ~1 ~24 vine 4
setblock ~4 ~0 ~17 vine 1
setblock ~4 ~0 ~18 leaves 5
setblock ~4 ~0 ~19 log2 0
setblock ~4 ~0 ~21 leaves 5
setblock ~4 ~0 ~22 web 0
setblock ~4 ~0 ~23 leaves 5
setblock ~5 ~0 ~3 leaves 5
setblock ~5 ~0 ~14 cobblestone 0
setblock ~5 ~0 ~18 web 0
setblock ~5 ~0 ~19 leaves 5
setblock ~5 ~0 ~21 vine 4
setblock ~6 ~0 ~20 vine 2
setblock ~6 ~0 ~21 leaves 5
fill ~6 ~0 ~23 ~7 ~0 ~23 vine 4
setblock ~7 ~0 ~17 leaves 5
setblock ~7 ~0 ~21 web 0
setblock ~8 ~0 ~31 cobblestone_wall 0
setblock ~10 ~0 ~31 cobblestone_wall 0
setblock ~10 ~0 ~33 cobblestone_wall 1
setblock ~12 ~0 ~19 bedrock 0
setblock ~13 ~0 ~18 bedrock 0
setblock ~14 ~0 ~16 bedrock 0
fill ~14 ~0 ~20 ~22 ~0 ~20 bedrock 0
fill ~15 ~0 ~17 ~15 ~0 ~20 bedrock 0
setblock ~16 ~0 ~4 cobblestone_wall 1
fill ~16 ~0 ~14 ~16 ~1 ~14 bedrock 0
setblock ~16 ~0 ~16 bedrock 0
setblock ~18 ~0 ~4 cobblestone_wall 1
fill ~18 ~0 ~16 ~18 ~1 ~16 coal_block 0
fill ~18 ~0 ~17 ~22 ~0 ~17 coal_block 0
fill ~18 ~0 ~18 ~22 ~0 ~18 coal_block 0
fill ~18 ~0 ~25 ~18 ~0 ~26 stone_brick_stairs 0
setblock ~18 ~0 ~27 stone_stairs 0
setblock ~18 ~0 ~28 stone_brick_stairs 0
setblock ~18 ~0 ~29 stone 0
setblock ~19 ~0 ~25 stone_stairs 2
setblock ~19 ~0 ~26 stone_slab 13
setblock ~19 ~0 ~27 stone_slab 11
setblock ~19 ~0 ~28 stone_slab 13
fill ~19 ~0 ~29 ~20 ~0 ~29 cobblestone 0
fill ~19 ~0 ~30 ~19 ~1 ~30 cobblestone_wall 0
setblock ~20 ~0 ~3 leaves 5
fill ~20 ~0 ~16 ~20 ~3 ~16 coal_block 0
fill ~20 ~0 ~25 ~20 ~0 ~26 stone_stairs 1
fill ~20 ~0 ~27 ~20 ~0 ~28 stone_brick_stairs 1
fill ~23 ~0 ~16 ~23 ~2 ~16 bedrock 0
fill ~23 ~0 ~19 ~23 ~1 ~19 bedrock 0
fill ~24 ~0 ~17 ~24 ~0 ~18 bedrock 0
fill ~25 ~0 ~31 ~25 ~1 ~31 web 0
fill ~26 ~0 ~5 ~27 ~0 ~5 vine 8
fill ~26 ~0 ~30 ~27 ~0 ~30 vine 8
setblock ~27 ~0 ~28 web 0
setblock ~27 ~0 ~29 leaves 5
fill ~27 ~0 ~31 ~28 ~0 ~31 leaves 5
setblock ~27 ~0 ~32 vine 4
setblock ~28 ~0 ~28 leaves 5
setblock ~28 ~0 ~29 log2 0
setblock ~29 ~0 ~6 leaves 5
fill ~29 ~0 ~7 ~29 ~1 ~7 web 0
fill ~29 ~0 ~8 ~30 ~0 ~8 vine 4
fill ~29 ~0 ~29 ~29 ~1 ~29 leaves 5
fill ~29 ~0 ~30 ~29 ~0 ~29 leaves 5
fill ~30 ~0 ~6 ~30 ~1 ~6 log2 0
fill ~30 ~0 ~7 ~30 ~1 ~7 leaves 5
fill ~30 ~0 ~32 ~30 ~2 ~32 vine 2
fill ~31 ~0 ~4 ~31 ~1 ~4 leaves 13
setblock ~31 ~0 ~5 web 0
fill ~32 ~0 ~2 ~33 ~0 ~2 vine 1
setblock ~32 ~0 ~3 leaves 5
fill ~32 ~0 ~4 ~32 ~1 ~4 log2 0
fill ~32 ~0 ~5 ~32 ~1 ~5 leaves 5
fill ~33 ~0 ~4 ~33 ~1 ~4 leaves 5
fill ~33 ~0 ~6 ~33 ~1 ~6 web 0
setblock ~34 ~0 ~5 leaves 13
fill ~34 ~0 ~8 ~34 ~2 ~8 vine 4
setblock ~2 ~1 ~19 leaves 5
setblock ~3 ~1 ~18 leaves 13
setblock ~3 ~1 ~19 log2 0
fill ~3 ~1 ~20 ~4 ~1 ~20 leaves 5
setblock ~3 ~1 ~21 leaves 13
fill ~3 ~1 ~22 ~4 ~1 ~22 leaves 5
fill ~3 ~1 ~23 ~3 ~1 ~22 leaves 5
fill ~4 ~1 ~18 ~4 ~2 ~18 vine 8
setblock ~4 ~1 ~19 leaves 13
setblock ~4 ~1 ~21 log2 0
setblock ~4 ~1 ~23 log2 0
setblock ~4 ~1 ~24 leaves 5
fill ~5 ~1 ~18 ~7 ~1 ~18 leaves 5
setblock ~5 ~1 ~19 log2 0
setblock ~5 ~1 ~20 leaves 13
setblock ~5 ~1 ~23 leaves 5
fill ~6 ~1 ~17 ~6 ~2 ~17 leaves 5
fill ~6 ~1 ~19 ~6 ~1 ~20 leaves 5
fill ~6 ~1 ~21 ~6 ~2 ~21 log2 0
fill ~6 ~1 ~22 ~6 ~2 ~22 leaves 5
fill ~6 ~1 ~23 ~7 ~1 ~23 vine 4
setblock ~7 ~1 ~16 leaves 5
setblock ~7 ~1 ~17 log2 0
fill ~7 ~1 ~21 ~7 ~3 ~21 leaves 5
setblock ~8 ~1 ~17 leaves 5
setblock ~9 ~1 ~31 cobblestone 0
setblock ~12 ~1 ~20 bedrock 0
fill ~13 ~1 ~17 ~14 ~1 ~17 bedrock 0
fill ~15 ~1 ~16 ~15 ~2 ~16 bedrock 0
fill ~15 ~1 ~18 ~15 ~1 ~20 bedrock 0
fill ~16 ~1 ~17 ~16 ~2 ~17 bedrock 0
fill ~16 ~1 ~20 ~17 ~1 ~20 bedrock 0
setblock ~17 ~1 ~14 bedrock 0
fill ~18 ~1 ~13 ~18 ~2 ~13 stone 0
fill ~18 ~1 ~17 ~22 ~1 ~17 coal_block 0
fill ~18 ~1 ~18 ~22 ~1 ~18 coal_block 0
fill ~18 ~1 ~21 ~20 ~1 ~21 bedrock 0
setblock ~18 ~1 ~29 stone_brick_stairs 0
setblock ~19 ~1 ~28 stone_button 4
fill ~19 ~1 ~29 ~19 ~4 ~29 stonebrick 2
setblock ~20 ~1 ~29 stone_stairs 1
fill ~21 ~1 ~20 ~22 ~1 ~20 bedrock 0
fill ~23 ~1 ~17 ~23 ~3 ~17 bedrock 0
setblock ~24 ~1 ~18 bedrock 0
fill ~26 ~1 ~5 ~27 ~1 ~5 vine 8
fill ~26 ~1 ~30 ~26 ~-1 ~30 vine 8
setblock ~26 ~1 ~31 leaves 5
setblock ~27 ~1 ~28 leaves 5
fill ~27 ~1 ~30 ~28 ~1 ~30 leaves 5
setblock ~27 ~1 ~31 log2 0
fill ~27 ~1 ~32 ~28 ~1 ~32 leaves 13
setblock ~28 ~1 ~27 leaves 5
setblock ~28 ~1 ~28 log2 0
setblock ~28 ~1 ~29 leaves 5
fill ~28 ~1 ~31 ~29 ~1 ~31 leaves 5
setblock ~29 ~1 ~6 leaves 13
fill ~29 ~1 ~8 ~29 ~2 ~8 vine 4
setblock ~29 ~1 ~28 leaves 5
setblock ~29 ~1 ~30 log2 0
setblock ~29 ~1 ~32 web 0
setblock ~30 ~1 ~3 web 0
setblock ~30 ~1 ~5 leaves 13
setblock ~30 ~1 ~30 leaves 5
fill ~31 ~1 ~3 ~32 ~1 ~3 leaves 13
setblock ~31 ~1 ~6 leaves 13
fill ~32 ~1 ~7 ~32 ~2 ~7 web 0
setblock ~32 ~1 ~14 cobblestone_wall 1
setblock ~32 ~1 ~16 cobblestone_wall 1
fill ~33 ~1 ~2 ~33 ~2 ~2 vine 1
fill ~33 ~1 ~5 ~33 ~2 ~5 leaves 5
fill ~34 ~1 ~4 ~34 ~2 ~4 leaves 5
setblock ~34 ~1 ~5 log2 0
setblock ~34 ~1 ~6 leaves 13
setblock ~35 ~1 ~5 leaves 13
setblock ~2 ~2 ~22 leaves 5
setblock ~3 ~2 ~19 leaves 13
setblock ~3 ~2 ~22 log2 0
fill ~3 ~2 ~23 ~4 ~2 ~23 leaves 13
setblock ~4 ~2 ~19 web 0
setblock ~4 ~2 ~21 leaves 13
setblock ~4 ~2 ~22 web 0
fill ~5 ~2 ~18 ~5 ~1 ~18 leaves 5
setblock ~5 ~2 ~19 leaves 13
setblock ~5 ~2 ~20 web 0
setblock ~6 ~2 ~18 log2 0
setblock ~6 ~2 ~19 web 0
setblock ~6 ~2 ~20 leaves 5
fill ~6 ~2 ~23 ~7 ~2 ~23 vine 4
setblock ~7 ~2 ~17 leaves 13
setblock ~7 ~2 ~18 leaves 5
setblock ~7 ~2 ~22 leaves 5
fill ~13 ~2 ~18 ~13 ~3 ~18 bedrock 0
fill ~13 ~2 ~19 ~13 ~2 ~18 bedrock 0
setblock ~14 ~2 ~17 bedrock 0
setblock ~14 ~2 ~23 bedrock 0
fill ~16 ~2 ~18 ~17 ~2 ~18 bedrock 0
fill ~16 ~2 ~19 ~16 ~4 ~19 bedrock 0
fill ~16 ~2 ~20 ~17 ~2 ~20 bedrock 0
fill ~17 ~2 ~15 ~17 ~3 ~15 bedrock 0
setblock ~17 ~2 ~17 bedrock 0
fill ~17 ~2 ~21 ~20 ~2 ~21 bedrock 0
fill ~18 ~2 ~16 ~18 ~6 ~16 bedrock 0
fill ~18 ~2 ~17 ~22 ~2 ~17 coal_block 0
fill ~18 ~2 ~18 ~22 ~2 ~18 coal_block 0
fill ~21 ~2 ~20 ~21 ~3 ~20 bedrock 0
fill ~22 ~2 ~19 ~22 ~3 ~19 bedrock 0
fill ~23 ~2 ~18 ~23 ~3 ~18 bedrock 0
setblock ~25 ~2 ~31 leaves 5
fill ~26 ~2 ~5 ~27 ~2 ~5 vine 8
setblock ~26 ~2 ~30 leaves 5
setblock ~26 ~2 ~31 log2 0
fill ~26 ~2 ~32 ~27 ~2 ~32 leaves 13
fill ~27 ~2 ~31 ~28 ~2 ~31 leaves 5
fill ~28 ~2 ~4 ~28 ~3 ~4 web 0
setblock ~28 ~2 ~6 leaves 5
setblock ~28 ~2 ~28 leaves 5
setblock ~28 ~2 ~32 log2 0
setblock ~28 ~2 ~33 leaves 5
setblock ~29 ~2 ~5 leaves 5
setblock ~29 ~2 ~6 log2 0
setblock ~29 ~2 ~7 leaves 5
setblock ~29 ~2 ~29 web 0
setblock ~29 ~2 ~30 leaves 5
setblock ~29 ~2 ~31 web 0
fill ~29 ~2 ~32 ~29 ~3 ~32 leaves 13
fill ~29 ~2 ~33 ~29 ~2 ~32 leaves 13
fill ~30 ~2 ~2 ~31 ~2 ~2 leaves 13
fill ~30 ~2 ~3 ~30 ~3 ~3 leaves 5
setblock ~30 ~2 ~6 leaves 13
setblock ~30 ~2 ~29 leaves 5
setblock ~30 ~2 ~30 log2 0
setblock ~30 ~2 ~31 leaves 5
setblock ~31 ~2 ~3 log2 0
fill ~31 ~2 ~4 ~31 ~2 ~5 leaves 5
setblock ~31 ~2 ~6 log2 0
setblock ~31 ~2 ~7 leaves 5
setblock ~31 ~2 ~30 leaves 5
setblock ~32 ~2 ~3 leaves 5
setblock ~32 ~2 ~4 leaves 13
setblock ~32 ~2 ~5 web 0
fill ~32 ~2 ~6 ~33 ~2 ~6 leaves 5
setblock ~33 ~2 ~3 leaves 13
setblock ~33 ~2 ~4 log2 0
setblock ~34 ~2 ~5 leaves 13
setblock ~34 ~2 ~6 log2 0
setblock ~34 ~2 ~7 leaves 13
setblock ~35 ~2 ~5 leaves 5
fill ~35 ~2 ~6 ~35 ~3 ~6 leaves 13
setblock ~3 ~3 ~22 leaves 13
setblock ~6 ~3 ~18 leaves 13
setblock ~6 ~3 ~21 leaves 13
setblock ~6 ~3 ~22 web 0
setblock ~7 ~3 ~22 log2 0
setblock ~7 ~3 ~23 leaves 5
setblock ~8 ~3 ~22 leaves 5
setblock ~12 ~3 ~22 bedrock 0
fill ~14 ~3 ~18 ~15 ~3 ~18 bedrock 0
setblock ~14 ~3 ~20 bedrock 0
fill ~15 ~3 ~17 ~15 ~4 ~17 bedrock 0
setblock ~15 ~3 ~19 bedrock 0
setblock ~15 ~3 ~22 bedrock 0
fill ~16 ~3 ~16 ~16 ~4 ~16 bedrock 0
fill ~17 ~3 ~13 ~17 ~6 ~13 stone 0
fill ~17 ~3 ~20 ~17 ~4 ~20 bedrock 0
fill ~18 ~3 ~15 ~18 ~6 ~15 bedrock 0
fill ~18 ~3 ~17 ~22 ~3 ~17 coal_block 0
fill ~18 ~3 ~18 ~22 ~3 ~18 coal_block 0
fill ~18 ~3 ~21 ~20 ~3 ~21 bedrock 0
setblock ~18 ~3 ~29 stonebrick 2
fill ~19 ~3 ~16 ~19 ~19 ~16 coal_block 0
setblock ~20 ~3 ~29 stonebrick 2
fill ~21 ~3 ~15 ~21 ~5 ~15 bedrock 0
fill ~22 ~3 ~16 ~22 ~5 ~16 bedrock 0
fill ~26 ~3 ~5 ~27 ~3 ~5 vine 8
setblock ~26 ~3 ~31 leaves 5
fill ~27 ~3 ~6 ~27 ~4 ~6 vine 4
setblock ~28 ~3 ~5 leaves 13
fill ~28 ~3 ~32 ~28 ~3 ~33 leaves 13
setblock ~29 ~3 ~2 leaves 13
setblock ~29 ~3 ~4 leaves 5
setblock ~29 ~3 ~5 log2 0
setblock ~29 ~3 ~6 leaves 5
setblock ~29 ~3 ~33 log2 0
fill ~29 ~3 ~34 ~29 ~4 ~34 leaves 5
setblock ~30 ~3 ~1 leaves 5
setblock ~30 ~3 ~2 log2 0
setblock ~30 ~3 ~6 web 0
setblock ~30 ~3 ~7 leaves 5
setblock ~30 ~3 ~30 leaves 5
setblock ~30 ~3 ~33 leaves 5
fill ~31 ~3 ~2 ~31 ~3 ~3 leaves 13
setblock ~31 ~3 ~6 leaves 5
setblock ~31 ~3 ~7 log2 0
setblock ~31 ~3 ~8 leaves 5
setblock ~32 ~3 ~7 leaves 5
setblock ~33 ~3 ~4 leaves 13
setblock ~34 ~3 ~6 leaves 13
setblock ~35 ~3 ~7 leaves 5
setblock ~36 ~3 ~6 leaves 13
setblock ~7 ~4 ~22 leaves 13
setblock ~13 ~4 ~21 bedrock 0
fill ~15 ~4 ~18 ~16 ~4 ~18 bedrock 0
fill ~16 ~4 ~17 ~16 ~5 ~17 bedrock 0
fill ~17 ~4 ~16 ~17 ~6 ~16 bedrock 0
fill ~18 ~4 ~17 ~21 ~4 ~17 coal_block 0
fill ~18 ~4 ~18 ~21 ~4 ~18 coal_block 0
fill ~18 ~4 ~20 ~20 ~4 ~20 bedrock 0
fill ~20 ~4 ~16 ~20 ~6 ~16 bedrock 0
fill ~20 ~4 ~23 ~20 ~5 ~23 iron_bars 0
setblock ~21 ~4 ~16 coal_block 0
fill ~21 ~4 ~19 ~21 ~5 ~19 bedrock 0
fill ~22 ~4 ~17 ~22 ~5 ~17 bedrock 0
fill ~22 ~4 ~18 ~22 ~5 ~18 bedrock 0
fill ~26 ~4 ~5 ~26 ~-2 ~5 vine 8
setblock ~27 ~4 ~5 leaves 5
setblock ~28 ~4 ~4 leaves 13
setblock ~28 ~4 ~5 log2 0
setblock ~28 ~4 ~6 leaves 13
setblock ~29 ~4 ~5 leaves 5
setblock ~29 ~4 ~33 leaves 13
setblock ~29 ~4 ~35 leaves 5
setblock ~30 ~4 ~2 leaves 13
setblock ~30 ~4 ~34 leaves 5
setblock ~31 ~4 ~3 web 0
setblock ~31 ~4 ~7 leaves 5
fill ~16 ~5 ~18 ~17 ~5 ~18 bedrock 0
fill ~17 ~5 ~17 ~17 ~6 ~17 bedrock 0
setblock ~17 ~5 ~19 bedrock 0
fill ~18 ~5 ~17 ~21 ~5 ~17 coal_block 0
fill ~18 ~5 ~18 ~21 ~5 ~18 coal_block 0
fill ~18 ~5 ~20 ~20 ~5 ~20 bedrock 0
fill ~21 ~5 ~16 ~21 ~6 ~16 bedrock 0
fill ~25 ~5 ~18 ~25 ~6 ~18 iron_bars 0
setblock ~28 ~5 ~5 leaves 13
fill ~16 ~6 ~13 ~16 ~8 ~13 stone 0
setblock ~17 ~6 ~18 bedrock 0
fill ~18 ~6 ~17 ~20 ~6 ~17 coal_block 0
fill ~18 ~6 ~18 ~20 ~6 ~18 coal_block 0
fill ~18 ~6 ~19 ~20 ~6 ~19 bedrock 0
fill ~19 ~6 ~15 ~20 ~6 ~15 bedrock 0
fill ~20 ~6 ~23 ~20 ~8 ~23 bedrock 0
fill ~21 ~6 ~17 ~21 ~6 ~18 bedrock 0
fill ~22 ~6 ~23 ~22 ~7 ~23 iron_bars 0
fill ~26 ~6 ~19 ~26 ~6 ~21 coal_block 0
fill ~28 ~6 ~19 ~28 ~7 ~19 iron_bars 0
fill ~17 ~7 ~16 ~17 ~7 ~18 obsidian 0
fill ~18 ~7 ~15 ~20 ~7 ~15 obsidian 0
fill ~18 ~7 ~16 ~18 ~15 ~16 coal_block 0
fill ~18 ~7 ~17 ~20 ~7 ~17 coal_block 0
fill ~18 ~7 ~18 ~20 ~7 ~18 coal_block 0
fill ~18 ~7 ~19 ~20 ~7 ~19 obsidian 0
fill ~20 ~7 ~16 ~20 ~15 ~16 coal_block 0
fill ~21 ~7 ~16 ~21 ~7 ~18 obsidian 0
fill ~21 ~7 ~23 ~21 ~9 ~23 bedrock 0
setblock ~25 ~7 ~18 bedrock 0
setblock ~25 ~7 ~21 bedrock 0
setblock ~26 ~7 ~22 iron_bars 0
setblock ~27 ~7 ~17 iron_bars 0
fill ~27 ~7 ~19 ~27 ~8 ~19 coal_block 0
fill ~27 ~7 ~20 ~27 ~8 ~20 coal_block 0
fill ~27 ~7 ~21 ~27 ~8 ~21 coal_block 0
fill ~15 ~8 ~12 ~15 ~10 ~12 stone 0
fill ~17 ~8 ~16 ~17 ~16 ~16 bedrock 0
fill ~17 ~8 ~17 ~17 ~16 ~17 bedrock 0
fill ~17 ~8 ~18 ~17 ~16 ~18 bedrock 0
fill ~18 ~8 ~15 ~20 ~8 ~15 bedrock 0
fill ~18 ~8 ~17 ~20 ~8 ~17 coal_block 0
fill ~18 ~8 ~18 ~20 ~8 ~18 coal_block 0
fill ~18 ~8 ~19 ~20 ~8 ~19 bedrock 0
fill ~21 ~8 ~16 ~21 ~15 ~16 bedrock 0
fill ~21 ~8 ~17 ~21 ~16 ~17 bedrock 0
fill ~21 ~8 ~18 ~21 ~16 ~18 bedrock 0
fill ~22 ~8 ~23 ~22 ~10 ~23 bedrock 0
fill ~23 ~8 ~22 ~23 ~10 ~22 iron_bars 0
fill ~24 ~8 ~18 ~24 ~9 ~18 bedrock 0
fill ~24 ~8 ~21 ~24 ~9 ~21 bedrock 0
fill ~26 ~8 ~18 ~26 ~9 ~18 coal_block 0
fill ~26 ~8 ~22 ~26 ~10 ~22 bedrock 0
setblock ~27 ~8 ~17 bedrock 0
setblock ~28 ~8 ~19 bedrock 0
fill ~28 ~8 ~21 ~28 ~9 ~21 bedrock 0
fill ~9 ~9 ~16 ~10 ~9 ~16 bedrock 0
fill ~9 ~9 ~17 ~10 ~9 ~17 iron_bars 0
fill ~9 ~9 ~18 ~9 ~9 ~17 iron_bars 0
fill ~10 ~9 ~15 ~10 ~10 ~15 bedrock 0
fill ~16 ~9 ~17 ~16 ~11 ~17 bedrock 0
fill ~18 ~9 ~15 ~20 ~9 ~15 bedrock 0
fill ~18 ~9 ~17 ~18 ~15 ~17 coal_block 0
fill ~18 ~9 ~18 ~20 ~9 ~18 coal_block 0
fill ~18 ~9 ~19 ~21 ~9 ~19 bedrock 0
fill ~19 ~9 ~17 ~19 ~15 ~17 stone 0
fill ~20 ~9 ~17 ~20 ~15 ~17 coal_block 0
setblock ~20 ~9 ~20 bedrock 0
fill ~22 ~9 ~17 ~22 ~11 ~17 bedrock 0
fill ~22 ~9 ~22 ~22 ~11 ~22 bedrock 0
fill ~26 ~9 ~17 ~26 ~10 ~17 bedrock 0
fill ~26 ~9 ~19 ~26 ~10 ~19 coal_block 0
fill ~26 ~9 ~20 ~26 ~10 ~20 coal_block 0
fill ~26 ~9 ~21 ~26 ~10 ~21 coal_block 0
setblock ~28 ~9 ~18 bedrock 0
setblock ~11 ~10 ~15 bedrock 0
fill ~11 ~10 ~16 ~11 ~10 ~17 iron_bars 0
fill ~14 ~10 ~12 ~14 ~13 ~12 stone 0
fill ~16 ~10 ~16 ~16 ~11 ~16 bedrock 0
fill ~16 ~10 ~18 ~16 ~11 ~18 bedrock 0
fill ~17 ~10 ~19 ~21 ~10 ~19 bedrock 0
fill ~18 ~10 ~15 ~18 ~8 ~15 bedrock 0
fill ~18 ~10 ~18 ~20 ~10 ~18 coal_block 0
fill ~19 ~10 ~20 ~19 ~13 ~20 bedrock 0
fill ~20 ~10 ~15 ~21 ~10 ~15 bedrock 0
fill ~22 ~10 ~16 ~22 ~13 ~16 bedrock 0
fill ~22 ~10 ~18 ~22 ~13 ~18 bedrock 0
fill ~25 ~10 ~19 ~25 ~15 ~19 bedrock 0
fill ~25 ~10 ~20 ~25 ~14 ~20 bedrock 0
fill ~25 ~10 ~21 ~25 ~12 ~21 bedrock 0
fill ~26 ~10 ~18 ~27 ~10 ~18 bedrock 0
fill ~27 ~10 ~19 ~27 ~10 ~21 bedrock 0
setblock ~28 ~10 ~20 bedrock 0
fill ~9 ~11 ~14 ~9 ~11 ~15 iron_bars 0
fill ~10 ~11 ~14 ~11 ~11 ~14 bedrock 0
setblock ~17 ~11 ~15 bedrock 0
fill ~17 ~11 ~19 ~22 ~11 ~19 bedrock 0
fill ~18 ~11 ~18 ~20 ~11 ~18 coal_block 0
fill ~20 ~11 ~20 ~21 ~11 ~20 bedrock 0
fill ~21 ~11 ~15 ~21 ~13 ~15 bedrock 0
fill ~23 ~11 ~17 ~23 ~12 ~17 bedrock 0
fill ~23 ~11 ~22 ~23 ~13 ~22 bedrock 0
fill ~24 ~11 ~20 ~24 ~15 ~20 bedrock 0
fill ~26 ~11 ~19 ~26 ~12 ~19 bedrock 0
fill ~26 ~11 ~20 ~27 ~11 ~20 bedrock 0
fill ~26 ~11 ~21 ~26 ~11 ~19 bedrock 0
fill ~10 ~12 ~14 ~12 ~12 ~14 bedrock 0
fill ~17 ~12 ~19 ~22 ~12 ~19 bedrock 0
fill ~18 ~12 ~15 ~18 ~16 ~15 bedrock 0
fill ~18 ~12 ~18 ~20 ~12 ~18 coal_block 0
fill ~20 ~12 ~20 ~20 ~11 ~20 bedrock 0
fill ~26 ~12 ~20 ~26 ~13 ~20 bedrock 0
fill ~9 ~13 ~14 ~12 ~13 ~14 bedrock 0
fill ~10 ~13 ~15 ~11 ~13 ~15 bedrock 0
fill ~10 ~13 ~16 ~10 ~13 ~17 iron_bars 0
fill ~13 ~13 ~11 ~13 ~14 ~11 stone 0
setblock ~15 ~13 ~14 bedrock 0
fill ~16 ~13 ~13 ~17 ~13 ~13 bedrock 0
fill ~17 ~13 ~19 ~21 ~13 ~19 bedrock 0
fill ~18 ~13 ~18 ~20 ~13 ~18 coal_block 0
setblock ~18 ~13 ~20 bedrock 0
fill ~20 ~13 ~15 ~20 ~16 ~15 bedrock 0
fill ~22 ~13 ~17 ~22 ~16 ~17 bedrock 0
fill ~23 ~13 ~21 ~24 ~13 ~21 bedrock 0
fill ~24 ~13 ~18 ~24 ~15 ~18 bedrock 0
fill ~24 ~13 ~19 ~24 ~16 ~19 bedrock 0
fill ~9 ~14 ~14 ~9 ~13 ~14 bedrock 0
fill ~10 ~14 ~12 ~10 ~14 ~13 bedrock 0
fill ~10 ~14 ~15 ~11 ~14 ~15 bedrock 0
fill ~11 ~14 ~13 ~11 ~19 ~13 bedrock 0
fill ~12 ~14 ~14 ~12 ~17 ~14 bedrock 0
fill ~13 ~14 ~16 ~13 ~15 ~16 iron_bars 0
setblock ~14 ~14 ~18 iron_bars 0
fill ~16 ~14 ~17 ~16 ~16 ~17 bedrock 0
fill ~17 ~14 ~19 ~21 ~14 ~19 bedrock 0
setblock ~18 ~14 ~13 bedrock 0
fill ~18 ~14 ~18 ~20 ~14 ~18 coal_block 0
fill ~19 ~14 ~14 ~19 ~15 ~14 bedrock 0
fill ~19 ~14 ~15 ~19 ~15 ~15 bedrock 0
fill ~19 ~14 ~22 ~19 ~15 ~22 bedrock 0
fill ~23 ~14 ~21 ~24 ~14 ~21 bedrock 0
fill ~9 ~15 ~12 ~9 ~17 ~12 bedrock 0
fill ~9 ~15 ~13 ~11 ~15 ~13 bedrock 0
fill ~10 ~15 ~12 ~11 ~15 ~12 coal_block 0
fill ~10 ~15 ~14 ~10 ~18 ~14 bedrock 0
fill ~11 ~15 ~15 ~11 ~15 ~16 bedrock 0
fill ~12 ~15 ~11 ~12 ~17 ~11 stone 0
setblock ~12 ~15 ~17 iron_bars 0
fill ~14 ~15 ~17 ~17 ~15 ~17 bedrock 0
fill ~14 ~15 ~18 ~17 ~15 ~18 bedrock 0
setblock ~16 ~15 ~16 bedrock 0
fill ~18 ~15 ~18 ~20 ~15 ~18 coal_block 0
fill ~18 ~15 ~19 ~21 ~15 ~19 bedrock 0
fill ~19 ~15 ~20 ~19 ~19 ~20 bedrock 0
fill ~19 ~15 ~23 ~19 ~18 ~23 bedrock 0
setblock ~22 ~15 ~16 bedrock 0
fill ~22 ~15 ~18 ~24 ~15 ~18 bedrock 0
fill ~23 ~15 ~17 ~23 ~17 ~17 bedrock 0
setblock ~23 ~15 ~19 bedrock 0
fill ~9 ~16 ~13 ~12 ~16 ~13 bedrock 0
fill ~10 ~16 ~12 ~11 ~16 ~12 coal_block 0
fill ~10 ~16 ~15 ~10 ~17 ~15 bedrock 0
fill ~10 ~16 ~16 ~14 ~16 ~16 bedrock 0
fill ~11 ~16 ~10 ~12 ~16 ~10 coal_block 0
fill ~11 ~16 ~11 ~11 ~16 ~10 coal_block 0
fill ~12 ~16 ~15 ~13 ~16 ~15 bedrock 0
fill ~12 ~16 ~17 ~17 ~16 ~17 bedrock 0
fill ~13 ~16 ~18 ~17 ~16 ~18 bedrock 0
setblock ~18 ~16 ~14 bedrock 0
fill ~18 ~16 ~16 ~18 ~17 ~16 bedrock 0
fill ~18 ~16 ~18 ~19 ~16 ~18 coal_block 0
fill ~18 ~16 ~19 ~20 ~16 ~19 bedrock 0
fill ~19 ~16 ~15 ~19 ~19 ~15 coal_block 0
fill ~19 ~16 ~17 ~19 ~19 ~17 coal_block 0
setblock ~20 ~16 ~14 bedrock 0
fill ~20 ~16 ~16 ~20 ~17 ~16 bedrock 0
fill ~20 ~16 ~17 ~20 ~17 ~17 bedrock 0
fill ~20 ~16 ~18 ~20 ~17 ~18 bedrock 0
fill ~22 ~16 ~18 ~23 ~16 ~18 bedrock 0
fill ~10 ~17 ~10 ~12 ~17 ~10 coal_block 0
fill ~10 ~17 ~11 ~10 ~18 ~11 coal_block 0
fill ~10 ~17 ~12 ~11 ~17 ~12 coal_block 0
fill ~10 ~17 ~13 ~10 ~18 ~13 bedrock 0
fill ~11 ~17 ~11 ~11 ~19 ~11 stone 0
fill ~11 ~17 ~14 ~11 ~19 ~14 bedrock 0
fill ~11 ~17 ~15 ~13 ~17 ~15 bedrock 0
fill ~12 ~17 ~12 ~12 ~18 ~12 bedrock 0
fill ~12 ~17 ~13 ~12 ~18 ~13 bedrock 0
fill ~12 ~17 ~16 ~14 ~17 ~16 bedrock 0
fill ~14 ~17 ~17 ~15 ~17 ~17 bedrock 0
fill ~15 ~17 ~18 ~16 ~17 ~18 bedrock 0
fill ~17 ~17 ~14 ~17 ~18 ~14 bedrock 0
fill ~17 ~17 ~15 ~17 ~18 ~15 bedrock 0
fill ~17 ~17 ~19 ~21 ~17 ~19 bedrock 0
fill ~18 ~17 ~15 ~18 ~18 ~15 coal_block 0
fill ~18 ~17 ~17 ~18 ~17 ~20 bedrock 0
fill ~18 ~17 ~22 ~20 ~17 ~22 bedrock 0
fill ~19 ~17 ~18 ~19 ~19 ~18 coal_block 0
fill ~19 ~17 ~21 ~19 ~19 ~21 bedrock 0
fill ~20 ~17 ~15 ~20 ~18 ~15 coal_block 0
fill ~20 ~17 ~20 ~20 ~18 ~20 bedrock 0
fill ~21 ~17 ~14 ~21 ~18 ~14 bedrock 0
fill ~21 ~17 ~15 ~21 ~18 ~15 bedrock 0
fill ~22 ~17 ~18 ~23 ~17 ~18 bedrock 0
fill ~10 ~18 ~10 ~12 ~18 ~10 coal_block 0
setblock ~10 ~18 ~12 bedrock 0
setblock ~11 ~18 ~12 coal_block 0
fill ~11 ~18 ~15 ~12 ~18 ~15 bedrock 0
fill ~12 ~18 ~11 ~12 ~19 ~11 coal_block 0
setblock ~13 ~18 ~16 bedrock 0
fill ~17 ~18 ~16 ~17 ~19 ~16 bedrock 0
fill ~17 ~18 ~17 ~17 ~18 ~18 bedrock 0
fill ~18 ~18 ~16 ~18 ~18 ~17 coal_block 0
fill ~18 ~18 ~18 ~18 ~19 ~18 bedrock 0
fill ~18 ~18 ~19 ~18 ~18 ~21 bedrock 0
setblock ~19 ~18 ~19 coal_block 0
setblock ~19 ~18 ~22 bedrock 0
fill ~20 ~18 ~16 ~20 ~18 ~18 coal_block 0
setblock ~20 ~18 ~19 bedrock 0
setblock ~20 ~18 ~21 bedrock 0
fill ~21 ~18 ~16 ~21 ~19 ~16 bedrock 0
fill ~21 ~18 ~17 ~21 ~18 ~18 bedrock 0
setblock ~10 ~19 ~11 stone 0
setblock ~11 ~19 ~10 coal_block 0
setblock ~11 ~19 ~12 bedrock 0
fill ~18 ~19 ~14 ~18 ~19 ~18 bedrock 0
setblock ~19 ~19 ~19 bedrock 0
fill ~20 ~19 ~14 ~20 ~19 ~18 bedrock 0
setblock ~7 ~20 ~11 stone_brick_stairs 5
setblock ~10 ~20 ~11 monster_egg 5
fill ~18 ~20 ~16 ~20 ~20 ~16 bedrock 0
fill ~19 ~20 ~14 ~19 ~20 ~18 bedrock 0
setblock ~6 ~21 ~11 stone_brick_stairs 4
setblock ~7 ~21 ~11 stonebrick 0
setblock ~8 ~21 ~11 double_stone_slab 5
setblock ~9 ~21 ~11 stone_slab 13
setblock ~10 ~21 ~11 stonebrick 0
setblock ~11 ~21 ~11 stone_brick_stairs 4
fill ~19 ~21 ~15 ~19 ~21 ~17 bedrock 0
setblock ~7 ~22 ~11 stone_brick_stairs 0
setblock ~8 ~22 ~11 stonebrick 0
setblock ~9 ~22 ~11 monster_egg 5
fill ~10 ~22 ~11 ~10 ~23 ~11 iron_bars 0
fill ~11 ~22 ~11 ~11 ~23 ~11 monster_egg 5
setblock ~12 ~22 ~11 stone_stairs 5
setblock ~8 ~23 ~11 stone_brick_stairs 0
fill ~9 ~23 ~11 ~9 ~24 ~11 stonebrick 0
fill ~12 ~23 ~11 ~12 ~24 ~11 stone 0
setblock ~13 ~23 ~11 stone_stairs 5
setblock ~10 ~24 ~11 monster_egg 5
setblock ~11 ~24 ~11 stone 0
fill ~13 ~24 ~11 ~14 ~24 ~11 stone 0
setblock ~15 ~24 ~11 stone_slab 11
setblock ~9 ~25 ~11 stone_brick_stairs 1
setblock ~11 ~25 ~11 stone_slab 3
setblock ~12 ~25 ~11 stone_stairs 0
fill ~13 ~25 ~11 ~15 ~25 ~11 stone 0
setblock ~16 ~25 ~11 stone_stairs 5
setblock ~13 ~26 ~11 stone_slab 3
fill ~14 ~26 ~11 ~18 ~26 ~11 stone 0
setblock ~19 ~26 ~11 stone_slab 11
setblock ~23 ~26 ~11 stone_slab 11
setblock ~24 ~26 ~11 stone_stairs 4
fill ~15 ~27 ~11 ~16 ~27 ~11 stone_slab 3
setblock ~17 ~27 ~11 stone_stairs 0
fill ~18 ~27 ~11 ~21 ~27 ~11 stone 0
setblock ~22 ~27 ~11 stone_stairs 1
setblock ~23 ~27 ~11 stone_slab 3
fill ~19 ~28 ~11 ~20 ~28 ~11 stone_slab 3
setblock ~1 ~34 ~0 stone 0
setblock ~8 ~-3 ~3 skull 1
setblock ~11 ~-3 ~5 skull 12
setblock ~15 ~-3 ~6 skull 1
setblock ~8 ~-2 ~15 skull 1
setblock ~6 ~-3 ~25 skull 1
setblock ~12 ~-3 ~25 skull 1
setblock ~15 ~-2 ~25 skull 1
setblock ~16 ~7 ~16 skull 4
setblock ~16 ~7 ~17 skull 4
setblock ~16 ~7 ~18 skull 4
setblock ~17 ~7 ~15 skull 4
setblock ~17 ~7 ~19 skull 4
setblock ~12 ~-3 ~30 skull 1
setblock ~21 ~-3 ~6 skull 11
setblock ~22 ~-3 ~8 skull 1
setblock ~30 ~-3 ~11 skull 1
setblock ~18 ~7 ~14 skull 2
setblock ~19 ~7 ~14 skull 2
setblock ~20 ~7 ~14 skull 2
setblock ~21 ~7 ~15 skull 5
setblock ~27 ~-2 ~15 skull 1
setblock ~18 ~7 ~20 skull 3
setblock ~19 ~7 ~20 skull 3
setblock ~20 ~7 ~20 skull 3
setblock ~21 ~7 ~19 skull 5
setblock ~22 ~7 ~16 skull 5
setblock ~22 ~7 ~17 skull 5
setblock ~22 ~7 ~18 skull 5
setblock ~25 ~-1 ~25 skull 1
setblock ~30 ~-3 ~17 skull 1
setblock ~31 ~-3 ~23 skull 1
setblock ~32 ~-2 ~27 skull 1