fill ~20 ~46 ~22 ~23 ~46 ~22 stonebrick 3
fill ~20 ~46 ~23 ~22 ~46 ~23 stonebrick 3
fill ~20 ~46 ~24 ~22 ~46 ~24 stonebrick 3
fill ~20 ~46 ~25 ~22 ~46 ~25 stonebrick 3
fill ~20 ~46 ~26 ~23 ~46 ~26 stonebrick 3
fill ~21 ~46 ~21 ~29 ~46 ~21 stonebrick 3
fill ~21 ~46 ~27 ~29 ~46 ~27 stonebrick 3
fill ~22 ~46 ~20 ~28 ~46 ~20 stonebrick 3
fill ~22 ~46 ~28 ~28 ~46 ~28 stonebrick 3
fill ~23 ~46 ~19 ~27 ~46 ~19 stonebrick 3
fill ~23 ~46 ~29 ~27 ~46 ~29 stonebrick 3
fill ~27 ~46 ~22 ~30 ~46 ~22 stonebrick 3
fill ~27 ~46 ~26 ~30 ~46 ~26 stonebrick 3
fill ~28 ~46 ~23 ~30 ~46 ~23 stonebrick 3
fill ~28 ~46 ~24 ~30 ~46 ~24 stonebrick 3
fill ~28 ~46 ~25 ~30 ~46 ~25 stonebrick 3
fill ~18 ~47 ~22 ~18 ~47 ~26 obsidian 0
fill ~19 ~47 ~20 ~20 ~47 ~20 obsidian 0
fill ~19 ~47 ~21 ~19 ~47 ~20 obsidian 0
fill ~19 ~47 ~22 ~19 ~47 ~26 stone 0
fill ~19 ~47 ~27 ~19 ~47 ~28 obsidian 0
fill ~20 ~47 ~19 ~21 ~47 ~19 obsidian 0
setblock ~20 ~47 ~21 stone 0
setblock ~20 ~47 ~27 stone 0
fill ~20 ~47 ~28 ~20 ~47 ~29 obsidian 0
fill ~21 ~47 ~18 ~22 ~47 ~18 obsidian 0
setblock ~21 ~47 ~20 stone 0
setblock ~21 ~47 ~28 stone 0
fill ~21 ~47 ~29 ~21 ~47 ~30 obsidian 0
setblock ~22 ~47 ~19 stone 0
fill ~22 ~47 ~23 ~28 ~47 ~23 glowstone 0
fill ~22 ~47 ~24 ~28 ~47 ~24 glowstone 0
fill ~22 ~47 ~25 ~28 ~47 ~25 glowstone 0
fill ~22 ~47 ~26 ~28 ~47 ~26 glowstone 0
setblock ~22 ~47 ~29 stone 0
setblock ~22 ~47 ~30 obsidian 0
fill ~23 ~47 ~17 ~27 ~47 ~17 obsidian 0
fill ~23 ~47 ~18 ~27 ~47 ~18 stone 0
fill ~23 ~47 ~22 ~27 ~47 ~22 glowstone 0
fill ~23 ~47 ~30 ~27 ~47 ~30 stone 0
fill ~23 ~47 ~31 ~27 ~47 ~31 obsidian 0
fill ~24 ~47 ~21 ~26 ~47 ~21 glowstone 0
fill ~24 ~47 ~27 ~27 ~47 ~27 glowstone 0
fill ~28 ~47 ~18 ~29 ~47 ~18 obsidian 0
setblock ~28 ~47 ~19 stone 0
setblock ~28 ~47 ~29 stone 0
fill ~28 ~47 ~30 ~29 ~47 ~30 obsidian 0
fill ~29 ~47 ~19 ~30 ~47 ~19 obsidian 0
setblock ~29 ~47 ~20 stone 0
setblock ~29 ~47 ~28 stone 0
fill ~29 ~47 ~29 ~30 ~47 ~29 obsidian 0
fill ~30 ~47 ~20 ~31 ~47 ~20 obsidian 0
setblock ~30 ~47 ~21 stone 0
setblock ~30 ~47 ~27 stone 0
fill ~30 ~47 ~28 ~31 ~47 ~28 obsidian 0
setblock ~31 ~47 ~21 obsidian 0
fill ~31 ~47 ~22 ~31 ~47 ~26 stone 0
setblock ~31 ~47 ~27 obsidian 0
fill ~32 ~47 ~22 ~32 ~47 ~26 obsidian 0
fill ~14 ~48 ~21 ~15 ~48 ~21 stone_slab 8
fill ~14 ~48 ~22 ~14 ~48 ~27 stone_slab 8
fill ~15 ~48 ~19 ~15 ~48 ~21 stone_slab 8
fill ~15 ~48 ~22 ~15 ~48 ~26 double_stone_slab 0
fill ~15 ~48 ~27 ~15 ~48 ~29 stone_slab 8
fill ~16 ~48 ~17 ~17 ~48 ~17 stone_slab 8
fill ~16 ~48 ~18 ~16 ~48 ~17 stone_slab 8
fill ~16 ~48 ~19 ~16 ~48 ~21 double_stone_slab 0
fill ~16 ~48 ~22 ~16 ~48 ~26 stone 0
fill ~16 ~48 ~27 ~16 ~48 ~29 double_stone_slab 0
fill ~16 ~48 ~30 ~16 ~48 ~31 stone_slab 8
fill ~17 ~48 ~16 ~18 ~48 ~16 stone_slab 8
setblock ~17 ~48 ~18 double_stone_slab 0
fill ~17 ~48 ~19 ~18 ~48 ~19 stone 0
fill ~17 ~48 ~20 ~17 ~48 ~21 stone 0
fill ~17 ~48 ~22 ~17 ~48 ~26 bedrock 0
fill ~17 ~48 ~27 ~17 ~48 ~29 stone 0
setblock ~17 ~48 ~30 double_stone_slab 0
fill ~17 ~48 ~31 ~17 ~48 ~32 stone_slab 8
fill ~18 ~48 ~15 ~19 ~48 ~15 stone_slab 8
setblock ~18 ~48 ~17 double_stone_slab 0
fill ~18 ~48 ~18 ~19 ~48 ~18 stone 0
fill ~18 ~48 ~20 ~18 ~48 ~21 bedrock 0
fill ~18 ~48 ~27 ~18 ~48 ~28 bedrock 0
fill ~18 ~48 ~29 ~18 ~48 ~30 stone 0
setblock ~18 ~48 ~31 double_stone_slab 0
fill ~18 ~48 ~32 ~18 ~48 ~33 stone_slab 8
setblock ~19 ~48 ~16 double_stone_slab 0
fill ~19 ~48 ~17 ~20 ~48 ~17 stone 0
setblock ~19 ~48 ~19 bedrock 0
setblock ~19 ~48 ~29 bedrock 0
fill ~19 ~48 ~30 ~19 ~48 ~31 stone 0
setblock ~19 ~48 ~32 double_stone_slab 0
setblock ~19 ~48 ~33 stone_slab 8
fill ~20 ~48 ~14 ~22 ~48 ~14 stone_slab 8
fill ~20 ~48 ~15 ~22 ~48 ~15 double_stone_slab 0
fill ~20 ~48 ~16 ~22 ~48 ~16 stone 0
setblock ~20 ~48 ~18 bedrock 0
setblock ~20 ~48 ~30 bedrock 0
fill ~20 ~48 ~31 ~20 ~48 ~32 stone 0
fill ~20 ~48 ~33 ~22 ~48 ~33 double_stone_slab 0
fill ~20 ~48 ~34 ~22 ~48 ~34 stone_slab 8
fill ~21 ~48 ~17 ~22 ~48 ~17 bedrock 0
fill ~21 ~48 ~31 ~22 ~48 ~31 bedrock 0
fill ~21 ~48 ~32 ~22 ~48 ~32 stone 0
fill ~22 ~48 ~13 ~28 ~48 ~13 stone_slab 8
fill ~22 ~48 ~35 ~28 ~48 ~35 stone_slab 8
fill ~23 ~48 ~14 ~27 ~48 ~14 double_stone_slab 0
fill ~23 ~48 ~15 ~27 ~48 ~15 stone 0
fill ~23 ~48 ~16 ~27 ~48 ~16 bedrock 0
fill ~23 ~48 ~32 ~27 ~48 ~32 bedrock 0
fill ~23 ~48 ~33 ~27 ~48 ~33 stone 0
fill ~23 ~48 ~34 ~27 ~48 ~34 double_stone_slab 0
fill ~28 ~48 ~14 ~30 ~48 ~14 stone_slab 8
fill ~28 ~48 ~15 ~30 ~48 ~15 double_stone_slab 0
fill ~28 ~48 ~16 ~30 ~48 ~16 stone 0
fill ~28 ~48 ~17 ~29 ~48 ~17 bedrock 0
fill ~28 ~48 ~31 ~29 ~48 ~31 bedrock 0
fill ~28 ~48 ~32 ~30 ~48 ~32 stone 0
fill ~28 ~48 ~33 ~30 ~48 ~33 double_stone_slab 0
fill ~28 ~48 ~34 ~30 ~48 ~34 stone_slab 8
fill ~30 ~48 ~17 ~31 ~48 ~17 stone 0
setblock ~30 ~48 ~18 bedrock 0
setblock ~30 ~48 ~30 bedrock 0
fill ~30 ~48 ~31 ~31 ~48 ~31 stone 0
fill ~31 ~48 ~15 ~32 ~48 ~15 stone_slab 8
setblock ~31 ~48 ~16 double_stone_slab 0
fill ~31 ~48 ~18 ~32 ~48 ~18 stone 0
setblock ~31 ~48 ~19 bedrock 0
setblock ~31 ~48 ~29 bedrock 0
fill ~31 ~48 ~30 ~32 ~48 ~30 stone 0
setblock ~31 ~48 ~32 double_stone_slab 0
fill ~31 ~48 ~33 ~32 ~48 ~33 stone_slab 8
fill ~32 ~48 ~16 ~33 ~48 ~16 stone_slab 8
setblock ~32 ~48 ~17 double_stone_slab 0
fill ~32 ~48 ~19 ~33 ~48 ~19 stone 0
fill ~32 ~48 ~20 ~32 ~48 ~21 bedrock 0
fill ~32 ~48 ~27 ~32 ~48 ~28 bedrock 0
fill ~32 ~48 ~29 ~33 ~48 ~29 stone 0
setblock ~32 ~48 ~31 double_stone_slab 0
fill ~32 ~48 ~32 ~33 ~48 ~32 stone_slab 8
fill ~33 ~48 ~17 ~34 ~48 ~17 stone_slab 8
setblock ~33 ~48 ~18 double_stone_slab 0
fill ~33 ~48 ~20 ~33 ~48 ~21 stone 0
fill ~33 ~48 ~22 ~33 ~48 ~26 bedrock 0
fill ~33 ~48 ~27 ~33 ~48 ~29 stone 0
setblock ~33 ~48 ~30 double_stone_slab 0
fill ~33 ~48 ~31 ~34 ~48 ~31 stone_slab 8
setblock ~34 ~48 ~18 stone_slab 8
fill ~34 ~48 ~19 ~34 ~48 ~21 double_stone_slab 0
fill ~34 ~48 ~22 ~34 ~48 ~26 stone 0
fill ~34 ~48 ~27 ~34 ~48 ~29 double_stone_slab 0
setblock ~34 ~48 ~30 stone_slab 8
fill ~35 ~48 ~19 ~35 ~48 ~21 stone_slab 8
fill ~35 ~48 ~22 ~35 ~48 ~26 double_stone_slab 0
fill ~35 ~48 ~27 ~36 ~48 ~27 stone_slab 8
fill ~35 ~48 ~28 ~35 ~48 ~29 stone_slab 8
fill ~36 ~48 ~21 ~36 ~48 ~27 stone_slab 8
fill ~11 ~49 ~21 ~11 ~49 ~27 double_stone_slab 0
fill ~12 ~49 ~18 ~13 ~49 ~18 double_stone_slab 0
fill ~12 ~49 ~19 ~12 ~49 ~20 double_stone_slab 0
fill ~12 ~49 ~21 ~15 ~49 ~21 stone_slab 0
fill ~12 ~49 ~22 ~14 ~49 ~22 stone_slab 0
fill ~12 ~49 ~23 ~14 ~49 ~23 stone_slab 0
fill ~12 ~49 ~24 ~14 ~49 ~24 stone_slab 0
fill ~12 ~49 ~25 ~14 ~49 ~25 stone_slab 0
fill ~12 ~49 ~26 ~14 ~49 ~26 stone_slab 0
fill ~12 ~49 ~27 ~15 ~49 ~27 stone_slab 0
fill ~12 ~49 ~28 ~12 ~49 ~30 double_stone_slab 0
fill ~13 ~49 ~16 ~14 ~49 ~16 double_stone_slab 0
fill ~13 ~49 ~17 ~13 ~49 ~16 double_stone_slab 0
fill ~13 ~49 ~19 ~15 ~49 ~19 stone_slab 0
fill ~13 ~49 ~20 ~15 ~49 ~20 stone_slab 0
fill ~13 ~49 ~28 ~15 ~49 ~28 stone_slab 0
fill ~13 ~49 ~29 ~15 ~49 ~29 stone_slab 0
fill ~13 ~49 ~30 ~13 ~49 ~32 double_stone_slab 0
fill ~14 ~49 ~15 ~15 ~49 ~15 double_stone_slab 0
fill ~14 ~49 ~17 ~17 ~49 ~17 stone_slab 0
fill ~14 ~49 ~18 ~16 ~49 ~18 stone_slab 0
fill ~14 ~49 ~30 ~16 ~49 ~30 stone_slab 0
fill ~14 ~49 ~31 ~17 ~49 ~31 stone_slab 0
fill ~14 ~49 ~32 ~14 ~49 ~33 double_stone_slab 0
fill ~15 ~49 ~14 ~16 ~49 ~14 double_stone_slab 0
fill ~15 ~49 ~16 ~18 ~49 ~16 stone_slab 0
fill ~15 ~49 ~32 ~18 ~49 ~32 stone_slab 0
fill ~15 ~49 ~33 ~15 ~49 ~34 double_stone_slab 0
fill ~16 ~49 ~13 ~17 ~49 ~13 double_stone_slab 0
fill ~16 ~49 ~15 ~19 ~49 ~15 stone_slab 0
fill ~16 ~49 ~33 ~19 ~49 ~33 stone_slab 0
fill ~16 ~49 ~34 ~16 ~49 ~35 double_stone_slab 0
fill ~17 ~49 ~12 ~19 ~49 ~12 double_stone_slab 0
fill ~17 ~49 ~14 ~22 ~49 ~14 stone_slab 0
fill ~17 ~49 ~34 ~22 ~49 ~34 stone_slab 0
fill ~17 ~49 ~35 ~17 ~49 ~36 double_stone_slab 0
fill ~18 ~49 ~13 ~32 ~49 ~13 stone_slab 0
fill ~18 ~49 ~35 ~32 ~49 ~35 stone_slab 0
fill ~18 ~49 ~36 ~19 ~49 ~36 double_stone_slab 0
fill ~19 ~49 ~11 ~21 ~49 ~11 double_stone_slab 0
fill ~19 ~49 ~37 ~21 ~49 ~37 double_stone_slab 0
fill ~20 ~49 ~12 ~30 ~49 ~12 stone_slab 0
fill ~20 ~49 ~36 ~30 ~49 ~36 stone_slab 0
fill ~22 ~49 ~10 ~28 ~49 ~10 double_stone_slab 0
fill ~22 ~49 ~11 ~28 ~49 ~11 stone_slab 0
fill ~22 ~49 ~37 ~28 ~49 ~37 stone_slab 0
fill ~22 ~49 ~38 ~28 ~49 ~38 double_stone_slab 0
fill ~28 ~49 ~14 ~33 ~49 ~14 stone_slab 0
fill ~28 ~49 ~34 ~33 ~49 ~34 stone_slab 0
fill ~29 ~49 ~11 ~31 ~49 ~11 double_stone_slab 0
fill ~29 ~49 ~37 ~31 ~49 ~37 double_stone_slab 0
fill ~31 ~49 ~12 ~33 ~49 ~12 double_stone_slab 0
fill ~31 ~49 ~15 ~34 ~49 ~15 stone_slab 0
fill ~31 ~49 ~33 ~34 ~49 ~33 stone_slab 0
fill ~31 ~49 ~36 ~33 ~49 ~36 double_stone_slab 0
fill ~32 ~49 ~16 ~35 ~49 ~16 stone_slab 0
fill ~32 ~49 ~32 ~35 ~49 ~32 stone_slab 0
fill ~33 ~49 ~13 ~34 ~49 ~13 double_stone_slab 0
fill ~33 ~49 ~17 ~36 ~49 ~17 stone_slab 0
fill ~33 ~49 ~31 ~36 ~49 ~31 stone_slab 0
fill ~33 ~49 ~35 ~34 ~49 ~35 double_stone_slab 0
fill ~34 ~49 ~14 ~35 ~49 ~14 double_stone_slab 0
fill ~34 ~49 ~18 ~36 ~49 ~18 stone_slab 0
fill ~34 ~49 ~30 ~36 ~49 ~30 stone_slab 0
fill ~34 ~49 ~34 ~35 ~49 ~34 double_stone_slab 0
fill ~35 ~49 ~15 ~36 ~49 ~15 double_stone_slab 0
fill ~35 ~49 ~19 ~37 ~49 ~19 stone_slab 0
fill ~35 ~49 ~20 ~37 ~49 ~20 stone_slab 0
fill ~35 ~49 ~21 ~38 ~49 ~21 stone_slab 0
fill ~35 ~49 ~27 ~38 ~49 ~27 stone_slab 0
fill ~35 ~49 ~28 ~37 ~49 ~28 stone_slab 0
fill ~35 ~49 ~29 ~37 ~49 ~29 stone_slab 0
fill ~35 ~49 ~33 ~36 ~49 ~33 double_stone_slab 0
fill ~36 ~49 ~16 ~37 ~49 ~16 double_stone_slab 0
fill ~36 ~49 ~22 ~38 ~49 ~22 stone_slab 0
fill ~36 ~49 ~23 ~38 ~49 ~23 stone_slab 0
fill ~36 ~49 ~24 ~38 ~49 ~24 stone_slab 0
fill ~36 ~49 ~25 ~38 ~49 ~25 stone_slab 0
fill ~36 ~49 ~26 ~38 ~49 ~26 stone_slab 0
fill ~36 ~49 ~32 ~37 ~49 ~32 double_stone_slab 0
fill ~37 ~49 ~17 ~37 ~49 ~18 double_stone_slab 0
fill ~37 ~49 ~30 ~38 ~49 ~30 double_stone_slab 0
fill ~37 ~49 ~31 ~37 ~49 ~30 double_stone_slab 0
fill ~38 ~49 ~18 ~38 ~49 ~20 double_stone_slab 0
fill ~38 ~49 ~28 ~38 ~49 ~30 double_stone_slab 0
fill ~39 ~49 ~21 ~39 ~49 ~27 double_stone_slab 0
fill ~10 ~50 ~20 ~12 ~50 ~20 obsidian 0
fill ~10 ~50 ~21 ~11 ~50 ~21 obsidian 0
fill ~10 ~50 ~22 ~11 ~50 ~22 obsidian 0
fill ~10 ~50 ~23 ~11 ~50 ~23 obsidian 0
fill ~10 ~50 ~24 ~11 ~50 ~24 obsidian 0
fill ~10 ~50 ~25 ~11 ~50 ~25 obsidian 0
fill ~10 ~50 ~26 ~11 ~50 ~26 obsidian 0
fill ~10 ~50 ~27 ~11 ~50 ~27 obsidian 0
fill ~10 ~50 ~28 ~12 ~50 ~28 obsidian 0
fill ~11 ~50 ~18 ~13 ~50 ~18 obsidian 0
fill ~11 ~50 ~19 ~12 ~50 ~19 obsidian 0
fill ~11 ~50 ~29 ~12 ~50 ~29 obsidian 0
fill ~11 ~50 ~30 ~13 ~50 ~30 obsidian 0
fill ~12 ~50 ~16 ~14 ~50 ~16 obsidian 0
fill ~12 ~50 ~17 ~13 ~50 ~17 obsidian 0
fill ~12 ~50 ~31 ~13 ~50 ~31 obsidian 0
fill ~12 ~50 ~32 ~14 ~50 ~32 obsidian 0
fill ~13 ~50 ~15 ~15 ~50 ~15 obsidian 0
fill ~13 ~50 ~33 ~15 ~50 ~33 obsidian 0
fill ~14 ~50 ~13 ~17 ~50 ~13 obsidian 0
fill ~14 ~50 ~14 ~16 ~50 ~14 obsidian 0
fill ~14 ~50 ~34 ~16 ~50 ~34 obsidian 0
fill ~14 ~50 ~35 ~17 ~50 ~35 obsidian 0
fill ~16 ~50 ~12 ~19 ~50 ~12 obsidian 0
fill ~16 ~50 ~36 ~19 ~50 ~36 obsidian 0
fill ~17 ~50 ~11 ~21 ~50 ~11 obsidian 0
fill ~17 ~50 ~37 ~21 ~50 ~37 obsidian 0
fill ~19 ~50 ~10 ~31 ~50 ~10 obsidian 0
fill ~19 ~50 ~38 ~31 ~50 ~38 obsidian 0
fill ~21 ~50 ~9 ~29 ~50 ~9 obsidian 0
fill ~21 ~50 ~39 ~29 ~50 ~39 obsidian 0
fill ~29 ~50 ~11 ~33 ~50 ~11 obsidian 0
fill ~29 ~50 ~37 ~33 ~50 ~37 obsidian 0
fill ~31 ~50 ~12 ~34 ~50 ~12 obsidian 0
fill ~31 ~50 ~36 ~34 ~50 ~36 obsidian 0
fill ~33 ~50 ~13 ~36 ~50 ~13 obsidian 0
fill ~33 ~50 ~35 ~36 ~50 ~35 obsidian 0
fill ~34 ~50 ~14 ~36 ~50 ~14 obsidian 0
fill ~34 ~50 ~34 ~36 ~50 ~34 obsidian 0
fill ~35 ~50 ~15 ~37 ~50 ~15 obsidian 0
fill ~35 ~50 ~33 ~37 ~50 ~33 obsidian 0
fill ~36 ~50 ~16 ~38 ~50 ~16 obsidian 0
fill ~36 ~50 ~32 ~38 ~50 ~32 obsidian 0
fill ~37 ~50 ~17 ~38 ~50 ~17 obsidian 0
fill ~37 ~50 ~18 ~39 ~50 ~18 obsidian 0
fill ~37 ~50 ~30 ~39 ~50 ~30 obsidian 0
fill ~37 ~50 ~31 ~38 ~50 ~31 obsidian 0
fill ~38 ~50 ~19 ~39 ~50 ~19 obsidian 0
fill ~38 ~50 ~20 ~40 ~50 ~20 obsidian 0
fill ~38 ~50 ~28 ~40 ~50 ~28 obsidian 0
fill ~38 ~50 ~29 ~39 ~50 ~29 obsidian 0
fill ~39 ~50 ~21 ~40 ~50 ~21 obsidian 0
fill ~39 ~50 ~22 ~40 ~50 ~22 obsidian 0
fill ~39 ~50 ~23 ~40 ~50 ~23 obsidian 0
fill ~39 ~50 ~24 ~40 ~50 ~24 obsidian 0
fill ~39 ~50 ~25 ~40 ~50 ~25 obsidian 0
fill ~39 ~50 ~26 ~40 ~50 ~26 obsidian 0
fill ~39 ~50 ~27 ~40 ~50 ~27 obsidian 0
fill ~9 ~51 ~20 ~11 ~51 ~20 obsidian 0
fill ~9 ~51 ~21 ~10 ~51 ~21 obsidian 0
fill ~9 ~51 ~22 ~10 ~51 ~22 obsidian 0
fill ~9 ~51 ~23 ~10 ~51 ~23 obsidian 0
fill ~9 ~51 ~24 ~10 ~51 ~24 obsidian 0
fill ~9 ~51 ~25 ~10 ~51 ~25 obsidian 0
fill ~9 ~51 ~26 ~10 ~51 ~26 obsidian 0
fill ~9 ~51 ~27 ~10 ~51 ~27 obsidian 0
fill ~9 ~51 ~28 ~11 ~51 ~28 obsidian 0
fill ~10 ~51 ~18 ~11 ~51 ~18 obsidian 0
fill ~10 ~51 ~19 ~11 ~51 ~19 obsidian 0
fill ~10 ~51 ~29 ~11 ~51 ~29 obsidian 0
fill ~10 ~51 ~30 ~11 ~51 ~30 obsidian 0
fill ~11 ~51 ~15 ~13 ~51 ~15 obsidian 0
fill ~11 ~51 ~16 ~13 ~51 ~16 obsidian 0
fill ~11 ~51 ~17 ~12 ~51 ~17 obsidian 0
fill ~11 ~51 ~31 ~12 ~51 ~31 obsidian 0
fill ~11 ~51 ~32 ~13 ~51 ~32 obsidian 0
fill ~11 ~51 ~33 ~13 ~51 ~33 obsidian 0
fill ~12 ~51 ~14 ~14 ~51 ~14 obsidian 0
fill ~12 ~51 ~34 ~14 ~51 ~34 obsidian 0
fill ~13 ~51 ~13 ~15 ~51 ~13 obsidian 0
fill ~13 ~51 ~35 ~15 ~51 ~35 obsidian 0
fill ~14 ~51 ~12 ~17 ~51 ~12 obsidian 0
fill ~14 ~51 ~36 ~17 ~51 ~36 obsidian 0
fill ~15 ~51 ~11 ~18 ~51 ~11 obsidian 0
fill ~15 ~51 ~37 ~18 ~51 ~37 obsidian 0
fill ~16 ~51 ~10 ~21 ~51 ~10 obsidian 0
fill ~16 ~51 ~38 ~21 ~51 ~38 obsidian 0
fill ~19 ~51 ~9 ~31 ~51 ~9 obsidian 0
fill ~19 ~51 ~39 ~31 ~51 ~39 obsidian 0
fill ~21 ~51 ~8 ~29 ~51 ~8 obsidian 0
fill ~21 ~51 ~40 ~29 ~51 ~40 obsidian 0
fill ~29 ~51 ~10 ~34 ~51 ~10 obsidian 0
fill ~29 ~51 ~38 ~34 ~51 ~38 obsidian 0
fill ~32 ~51 ~11 ~35 ~51 ~11 obsidian 0
fill ~32 ~51 ~37 ~35 ~51 ~37 obsidian 0
fill ~33 ~51 ~12 ~36 ~51 ~12 obsidian 0
fill ~33 ~51 ~36 ~36 ~51 ~36 obsidian 0
fill ~35 ~51 ~13 ~37 ~51 ~13 obsidian 0
fill ~35 ~51 ~35 ~37 ~51 ~35 obsidian 0
fill ~36 ~51 ~14 ~38 ~51 ~14 obsidian 0
fill ~36 ~51 ~34 ~38 ~51 ~34 obsidian 0
fill ~37 ~51 ~15 ~39 ~51 ~15 obsidian 0
fill ~37 ~51 ~16 ~39 ~51 ~16 obsidian 0
fill ~37 ~51 ~32 ~39 ~51 ~32 obsidian 0
fill ~37 ~51 ~33 ~39 ~51 ~33 obsidian 0
fill ~38 ~51 ~17 ~39 ~51 ~17 obsidian 0
fill ~38 ~51 ~31 ~39 ~51 ~31 obsidian 0
fill ~39 ~51 ~18 ~40 ~51 ~18 obsidian 0
fill ~39 ~51 ~19 ~40 ~51 ~19 obsidian 0
fill ~39 ~51 ~20 ~41 ~51 ~20 obsidian 0
fill ~39 ~51 ~28 ~41 ~51 ~28 obsidian 0
fill ~39 ~51 ~29 ~40 ~51 ~29 obsidian 0
fill ~39 ~51 ~30 ~40 ~51 ~30 obsidian 0
fill ~40 ~51 ~21 ~41 ~51 ~21 obsidian 0
fill ~40 ~51 ~22 ~41 ~51 ~22 obsidian 0
fill ~40 ~51 ~23 ~41 ~51 ~23 obsidian 0
fill ~40 ~51 ~24 ~41 ~51 ~24 obsidian 0
fill ~40 ~51 ~25 ~41 ~51 ~25 obsidian 0
fill ~40 ~51 ~26 ~41 ~51 ~26 obsidian 0
fill ~40 ~51 ~27 ~41 ~51 ~27 obsidian 0
fill ~4 ~52 ~20 ~4 ~52 ~28 double_stone_slab 0
fill ~5 ~52 ~16 ~6 ~52 ~16 double_stone_slab 0
fill ~5 ~52 ~17 ~5 ~52 ~19 double_stone_slab 0
fill ~5 ~52 ~20 ~6 ~52 ~20 redstone_block 0
fill ~5 ~52 ~21 ~6 ~52 ~21 redstone_block 0
fill ~5 ~52 ~22 ~6 ~52 ~22 redstone_block 0
fill ~5 ~52 ~23 ~6 ~52 ~23 redstone_block 0
fill ~5 ~52 ~24 ~6 ~52 ~24 redstone_block 0
fill ~5 ~52 ~25 ~6 ~52 ~25 redstone_block 0
fill ~5 ~52 ~26 ~6 ~52 ~26 redstone_block 0
fill ~5 ~52 ~27 ~6 ~52 ~27 redstone_block 0
fill ~5 ~52 ~28 ~6 ~52 ~28 redstone_block 0
fill ~5 ~52 ~29 ~5 ~52 ~32 double_stone_slab 0
fill ~6 ~52 ~14 ~7 ~52 ~14 double_stone_slab 0
fill ~6 ~52 ~15 ~6 ~52 ~14 double_stone_slab 0
fill ~6 ~52 ~17 ~7 ~52 ~17 redstone_block 0
fill ~6 ~52 ~18 ~7 ~52 ~18 redstone_block 0
fill ~6 ~52 ~19 ~7 ~52 ~19 redstone_block 0
fill ~6 ~52 ~29 ~7 ~52 ~29 redstone_block 0
fill ~6 ~52 ~30 ~7 ~52 ~30 redstone_block 0
fill ~6 ~52 ~31 ~7 ~52 ~31 redstone_block 0
fill ~6 ~52 ~32 ~6 ~52 ~34 double_stone_slab 0
fill ~7 ~52 ~12 ~8 ~52 ~12 double_stone_slab 0
fill ~7 ~52 ~13 ~7 ~52 ~12 double_stone_slab 0
fill ~7 ~52 ~15 ~8 ~52 ~15 redstone_block 0
fill ~7 ~52 ~16 ~8 ~52 ~16 redstone_block 0
fill ~7 ~52 ~20 ~9 ~52 ~20 bedrock 0
fill ~7 ~52 ~21 ~8 ~52 ~21 bedrock 0
fill ~7 ~52 ~22 ~8 ~52 ~22 bedrock 0
fill ~7 ~52 ~23 ~8 ~52 ~23 bedrock 0
fill ~7 ~52 ~24 ~8 ~52 ~24 bedrock 0
fill ~7 ~52 ~25 ~8 ~52 ~25 bedrock 0
fill ~7 ~52 ~26 ~8 ~52 ~26 bedrock 0
fill ~7 ~52 ~27 ~8 ~52 ~27 bedrock 0
fill ~7 ~52 ~28 ~9 ~52 ~28 bedrock 0
fill ~7 ~52 ~32 ~8 ~52 ~32 redstone_block 0
fill ~7 ~52 ~33 ~8 ~52 ~33 redstone_block 0
fill ~7 ~52 ~34 ~7 ~52 ~36 double_stone_slab 0
fill ~8 ~52 ~11 ~9 ~52 ~11 double_stone_slab 0
fill ~8 ~52 ~13 ~10 ~52 ~13 redstone_block 0
fill ~8 ~52 ~14 ~9 ~52 ~14 redstone_block 0
fill ~8 ~52 ~17 ~10 ~52 ~17 bedrock 0
fill ~8 ~52 ~18 ~9 ~52 ~18 bedrock 0
fill ~8 ~52 ~19 ~9 ~52 ~19 bedrock 0
fill ~8 ~52 ~29 ~9 ~52 ~29 bedrock 0
fill ~8 ~52 ~30 ~9 ~52 ~30 bedrock 0
fill ~8 ~52 ~31 ~10 ~52 ~31 bedrock 0
fill ~8 ~52 ~34 ~9 ~52 ~34 redstone_block 0
fill ~8 ~52 ~35 ~10 ~52 ~35 redstone_block 0
fill ~8 ~52 ~36 ~8 ~52 ~37 double_stone_slab 0
fill ~9 ~52 ~10 ~10 ~52 ~10 double_stone_slab 0
fill ~9 ~52 ~12 ~11 ~52 ~12 redstone_block 0
fill ~9 ~52 ~15 ~11 ~52 ~15 bedrock 0
fill ~9 ~52 ~16 ~10 ~52 ~16 bedrock 0
fill ~9 ~52 ~21 ~9 ~51 ~21 obsidian 0
fill ~9 ~52 ~22 ~9 ~51 ~22 obsidian 0
fill ~9 ~52 ~23 ~9 ~51 ~23 obsidian 0
fill ~9 ~52 ~24 ~9 ~51 ~24 obsidian 0
fill ~9 ~52 ~25 ~9 ~51 ~25 obsidian 0
fill ~9 ~52 ~26 ~9 ~51 ~26 obsidian 0
fill ~9 ~52 ~27 ~9 ~51 ~27 obsidian 0
fill ~9 ~52 ~32 ~10 ~52 ~32 bedrock 0
fill ~9 ~52 ~33 ~11 ~52 ~33 bedrock 0
fill ~9 ~52 ~36 ~11 ~52 ~36 redstone_block 0
fill ~9 ~52 ~37 ~9 ~52 ~38 double_stone_slab 0
fill ~10 ~52 ~9 ~11 ~52 ~9 double_stone_slab 0
fill ~10 ~52 ~11 ~12 ~52 ~11 redstone_block 0
fill ~10 ~52 ~14 ~11 ~52 ~14 bedrock 0
fill ~10 ~52 ~18 ~10 ~51 ~18 obsidian 0
fill ~10 ~52 ~19 ~10 ~51 ~19 obsidian 0
fill ~10 ~52 ~20 ~10 ~52 ~18 obsidian 0
fill ~10 ~52 ~28 ~10 ~52 ~30 obsidian 0
fill ~10 ~52 ~34 ~11 ~52 ~34 bedrock 0
fill ~10 ~52 ~37 ~12 ~52 ~37 redstone_block 0
fill ~10 ~52 ~38 ~10 ~52 ~39 double_stone_slab 0
fill ~11 ~52 ~8 ~12 ~52 ~8 double_stone_slab 0
fill ~11 ~52 ~10 ~13 ~52 ~10 redstone_block 0
fill ~11 ~52 ~13 ~12 ~52 ~13 bedrock 0
fill ~11 ~52 ~16 ~11 ~51 ~16 obsidian 0
fill ~11 ~52 ~17 ~11 ~51 ~17 obsidian 0
fill ~11 ~52 ~31 ~11 ~51 ~31 obsidian 0
fill ~11 ~52 ~32 ~11 ~51 ~32 obsidian 0
fill ~11 ~52 ~35 ~12 ~52 ~35 bedrock 0
fill ~11 ~52 ~38 ~13 ~52 ~38 redstone_block 0
fill ~11 ~52 ~39 ~11 ~52 ~40 double_stone_slab 0
fill ~12 ~52 ~7 ~13 ~52 ~7 double_stone_slab 0
fill ~12 ~52 ~9 ~14 ~52 ~9 redstone_block 0
fill ~12 ~52 ~12 ~13 ~52 ~12 bedrock 0
fill ~12 ~52 ~14 ~13 ~52 ~14 obsidian 0
fill ~12 ~52 ~15 ~12 ~52 ~14 obsidian 0
fill ~12 ~52 ~33 ~12 ~52 ~34 obsidian 0
fill ~12 ~52 ~36 ~13 ~52 ~36 bedrock 0
fill ~12 ~52 ~39 ~14 ~52 ~39 redstone_block 0
fill ~12 ~52 ~40 ~12 ~52 ~41 double_stone_slab 0
fill ~13 ~52 ~6 ~15 ~52 ~6 double_stone_slab 0
fill ~13 ~52 ~8 ~15 ~52 ~8 redstone_block 0
fill ~13 ~52 ~11 ~14 ~52 ~11 bedrock 0
fill ~13 ~52 ~13 ~14 ~52 ~13 obsidian 0
fill ~13 ~52 ~34 ~13 ~52 ~35 obsidian 0
fill ~13 ~52 ~37 ~14 ~52 ~37 bedrock 0
fill ~13 ~52 ~40 ~15 ~52 ~40 redstone_block 0
fill ~13 ~52 ~41 ~13 ~52 ~42 double_stone_slab 0
fill ~14 ~52 ~7 ~17 ~52 ~7 redstone_block 0
fill ~14 ~52 ~10 ~16 ~52 ~10 bedrock 0
fill ~14 ~52 ~12 ~15 ~52 ~12 obsidian 0
fill ~14 ~52 ~35 ~14 ~52 ~36 obsidian 0
fill ~14 ~52 ~38 ~16 ~52 ~38 bedrock 0
fill ~14 ~52 ~41 ~17 ~52 ~41 redstone_block 0
fill ~14 ~52 ~42 ~15 ~52 ~42 double_stone_slab 0
fill ~15 ~52 ~5 ~17 ~52 ~5 double_stone_slab 0
fill ~15 ~52 ~9 ~18 ~52 ~9 bedrock 0
fill ~15 ~52 ~11 ~16 ~52 ~11 obsidian 0
fill ~15 ~52 ~36 ~15 ~52 ~37 obsidian 0
fill ~15 ~52 ~39 ~18 ~52 ~39 bedrock 0
fill ~15 ~52 ~43 ~17 ~52 ~43 double_stone_slab 0
fill ~16 ~52 ~6 ~20 ~52 ~6 redstone_block 0
fill ~16 ~52 ~8 ~21 ~52 ~8 bedrock 0
setblock ~16 ~52 ~37 obsidian 0
fill ~16 ~52 ~40 ~21 ~52 ~40 bedrock 0
fill ~16 ~52 ~42 ~20 ~52 ~42 redstone_block 0
fill ~17 ~52 ~4 ~20 ~52 ~4 double_stone_slab 0
fill ~17 ~52 ~10 ~18 ~52 ~10 obsidian 0
fill ~17 ~52 ~38 ~18 ~52 ~38 obsidian 0
fill ~17 ~52 ~44 ~20 ~52 ~44 double_stone_slab 0
fill ~18 ~52 ~5 ~32 ~52 ~5 redstone_block 0
fill ~18 ~52 ~7 ~32 ~52 ~7 bedrock 0
fill ~18 ~52 ~41 ~32 ~52 ~41 bedrock 0
fill ~18 ~52 ~43 ~32 ~52 ~43 redstone_block 0
fill ~19 ~52 ~9 ~21 ~52 ~9 obsidian 0
fill ~19 ~52 ~39 ~21 ~52 ~39 obsidian 0
fill ~21 ~52 ~3 ~29 ~52 ~3 double_stone_slab 0
fill ~21 ~52 ~4 ~29 ~52 ~4 redstone_block 0
fill ~21 ~52 ~6 ~29 ~52 ~6 bedrock 0
fill ~21 ~52 ~42 ~29 ~52 ~42 bedrock 0
fill ~21 ~52 ~44 ~29 ~52 ~44 redstone_block 0
fill ~21 ~52 ~45 ~29 ~52 ~45 double_stone_slab 0
fill ~22 ~52 ~8 ~28 ~52 ~8 obsidian 0
fill ~22 ~52 ~40 ~28 ~52 ~40 obsidian 0
fill ~29 ~52 ~8 ~34 ~52 ~8 bedrock 0
fill ~29 ~52 ~9 ~31 ~52 ~9 obsidian 0
fill ~29 ~52 ~39 ~31 ~52 ~39 obsidian 0
fill ~29 ~52 ~40 ~34 ~52 ~40 bedrock 0
fill ~30 ~52 ~4 ~33 ~52 ~4 double_stone_slab 0
fill ~30 ~52 ~6 ~34 ~52 ~6 redstone_block 0
fill ~30 ~52 ~42 ~34 ~52 ~42 redstone_block 0
fill ~30 ~52 ~44 ~33 ~52 ~44 double_stone_slab 0
fill ~32 ~52 ~9 ~35 ~52 ~9 bedrock 0
fill ~32 ~52 ~10 ~33 ~52 ~10 obsidian 0
fill ~32 ~52 ~38 ~33 ~52 ~38 obsidian 0
fill ~32 ~52 ~39 ~35 ~52 ~39 bedrock 0
fill ~33 ~52 ~5 ~35 ~52 ~5 double_stone_slab 0
fill ~33 ~52 ~7 ~36 ~52 ~7 redstone_block 0
fill ~33 ~52 ~41 ~36 ~52 ~41 redstone_block 0
fill ~33 ~52 ~43 ~35 ~52 ~43 double_stone_slab 0
fill ~34 ~52 ~10 ~36 ~52 ~10 bedrock 0
fill ~34 ~52 ~11 ~35 ~52 ~11 obsidian 0
fill ~34 ~52 ~37 ~35 ~52 ~37 obsidian 0
fill ~34 ~52 ~38 ~36 ~52 ~38 bedrock 0
fill ~35 ~52 ~6 ~37 ~52 ~6 double_stone_slab 0
fill ~35 ~52 ~8 ~37 ~52 ~8 redstone_block 0
fill ~35 ~52 ~12 ~36 ~52 ~12 obsidian 0
fill ~35 ~52 ~36 ~36 ~52 ~36 obsidian 0
fill ~35 ~52 ~40 ~37 ~52 ~40 redstone_block 0
fill ~35 ~52 ~42 ~37 ~52 ~42 double_stone_slab 0
fill ~36 ~52 ~9 ~38 ~52 ~9 redstone_block 0
fill ~36 ~52 ~11 ~37 ~52 ~11 bedrock 0
fill ~36 ~52 ~13 ~37 ~52 ~13 obsidian 0
fill ~36 ~52 ~35 ~37 ~52 ~35 obsidian 0
fill ~36 ~52 ~37 ~37 ~52 ~37 bedrock 0
fill ~36 ~52 ~39 ~38 ~52 ~39 redstone_block 0
fill ~37 ~52 ~7 ~38 ~52 ~7 double_stone_slab 0
fill ~37 ~52 ~10 ~39 ~52 ~10 redstone_block 0
fill ~37 ~52 ~12 ~38 ~52 ~12 bedrock 0
fill ~37 ~52 ~14 ~38 ~52 ~14 obsidian 0
fill ~37 ~52 ~34 ~38 ~52 ~34 obsidian 0
fill ~37 ~52 ~36 ~38 ~52 ~36 bedrock 0
fill ~37 ~52 ~38 ~39 ~52 ~38 redstone_block 0
fill ~37 ~52 ~41 ~38 ~52 ~41 double_stone_slab 0
fill ~38 ~52 ~8 ~39 ~52 ~8 double_stone_slab 0
fill ~38 ~52 ~11 ~40 ~52 ~11 redstone_block 0
fill ~38 ~52 ~13 ~39 ~52 ~13 bedrock 0
setblock ~38 ~52 ~15 obsidian 0
setblock ~38 ~52 ~33 obsidian 0
fill ~38 ~52 ~35 ~39 ~52 ~35 bedrock 0
fill ~38 ~52 ~37 ~40 ~52 ~37 redstone_block 0
fill ~38 ~52 ~40 ~39 ~52 ~40 double_stone_slab 0
fill ~39 ~52 ~9 ~40 ~52 ~9 double_stone_slab 0
fill ~39 ~52 ~12 ~41 ~52 ~12 redstone_block 0
fill ~39 ~52 ~14 ~40 ~52 ~14 bedrock 0
fill ~39 ~52 ~15 ~41 ~52 ~15 bedrock 0
fill ~39 ~52 ~16 ~39 ~52 ~17 obsidian 0
fill ~39 ~52 ~31 ~39 ~52 ~32 obsidian 0
fill ~39 ~52 ~33 ~41 ~52 ~33 bedrock 0
fill ~39 ~52 ~34 ~40 ~52 ~34 bedrock 0
fill ~39 ~52 ~36 ~41 ~52 ~36 redstone_block 0
fill ~39 ~52 ~39 ~40 ~52 ~39 double_stone_slab 0
fill ~40 ~52 ~10 ~41 ~52 ~10 double_stone_slab 0
fill ~40 ~52 ~13 ~42 ~52 ~13 redstone_block 0
fill ~40 ~52 ~16 ~41 ~52 ~16 bedrock 0
fill ~40 ~52 ~17 ~42 ~52 ~17 bedrock 0
fill ~40 ~52 ~18 ~40 ~52 ~20 obsidian 0
fill ~40 ~52 ~28 ~40 ~52 ~30 obsidian 0
fill ~40 ~52 ~31 ~42 ~52 ~31 bedrock 0
fill ~40 ~52 ~32 ~41 ~52 ~32 bedrock 0
fill ~40 ~52 ~35 ~42 ~52 ~35 redstone_block 0
fill ~40 ~52 ~38 ~41 ~52 ~38 double_stone_slab 0
fill ~41 ~52 ~11 ~42 ~52 ~11 double_stone_slab 0
fill ~41 ~52 ~14 ~42 ~52 ~14 redstone_block 0
fill ~41 ~52 ~18 ~42 ~52 ~18 bedrock 0
fill ~41 ~52 ~19 ~42 ~52 ~19 bedrock 0
fill ~41 ~52 ~20 ~43 ~52 ~20 bedrock 0
fill ~41 ~52 ~21 ~41 ~52 ~27 obsidian 0
fill ~41 ~52 ~28 ~43 ~52 ~28 bedrock 0
fill ~41 ~52 ~29 ~42 ~52 ~29 bedrock 0
fill ~41 ~52 ~30 ~42 ~52 ~30 bedrock 0
fill ~41 ~52 ~34 ~42 ~52 ~34 redstone_block 0
fill ~41 ~52 ~37 ~42 ~52 ~37 double_stone_slab 0
fill ~42 ~52 ~12 ~43 ~52 ~12 double_stone_slab 0
fill ~42 ~52 ~15 ~43 ~52 ~15 redstone_block 0
fill ~42 ~52 ~16 ~43 ~52 ~16 redstone_block 0
fill ~42 ~52 ~21 ~43 ~52 ~21 bedrock 0
fill ~42 ~52 ~22 ~43 ~52 ~22 bedrock 0
fill ~42 ~52 ~23 ~43 ~52 ~23 bedrock 0
fill ~42 ~52 ~24 ~43 ~52 ~24 bedrock 0
fill ~42 ~52 ~25 ~43 ~52 ~25 bedrock 0
fill ~42 ~52 ~26 ~43 ~52 ~26 bedrock 0
fill ~42 ~52 ~27 ~43 ~52 ~27 bedrock 0
fill ~42 ~52 ~32 ~43 ~52 ~32 redstone_block 0
fill ~42 ~52 ~33 ~43 ~52 ~33 redstone_block 0
fill ~42 ~52 ~36 ~43 ~52 ~36 double_stone_slab 0
fill ~43 ~52 ~13 ~43 ~52 ~14 double_stone_slab 0
fill ~43 ~52 ~17 ~44 ~52 ~17 redstone_block 0
fill ~43 ~52 ~18 ~44 ~52 ~18 redstone_block 0
fill ~43 ~52 ~19 ~44 ~52 ~19 redstone_block 0
fill ~43 ~52 ~29 ~44 ~52 ~29 redstone_block 0
fill ~43 ~52 ~30 ~44 ~52 ~30 redstone_block 0
fill ~43 ~52 ~31 ~44 ~52 ~31 redstone_block 0
fill ~43 ~52 ~34 ~44 ~52 ~34 double_stone_slab 0
fill ~43 ~52 ~35 ~43 ~52 ~34 double_stone_slab 0
fill ~44 ~52 ~14 ~44 ~52 ~16 double_stone_slab 0
fill ~44 ~52 ~20 ~45 ~52 ~20 redstone_block 0
fill ~44 ~52 ~21 ~45 ~52 ~21 redstone_block 0
fill ~44 ~52 ~22 ~45 ~52 ~22 redstone_block 0
fill ~44 ~52 ~23 ~45 ~52 ~23 redstone_block 0
fill ~44 ~52 ~24 ~45 ~52 ~24 redstone_block 0
fill ~44 ~52 ~25 ~45 ~52 ~25 redstone_block 0
fill ~44 ~52 ~26 ~45 ~52 ~26 redstone_block 0
fill ~44 ~52 ~27 ~45 ~52 ~27 redstone_block 0
fill ~44 ~52 ~28 ~45 ~52 ~28 redstone_block 0
fill ~44 ~52 ~32 ~45 ~52 ~32 double_stone_slab 0
fill ~44 ~52 ~33 ~44 ~52 ~32 double_stone_slab 0
fill ~45 ~52 ~16 ~45 ~52 ~19 double_stone_slab 0
fill ~45 ~52 ~29 ~45 ~52 ~32 double_stone_slab 0
fill ~46 ~52 ~20 ~46 ~52 ~28 double_stone_slab 0
fill ~1 ~53 ~19 ~3 ~53 ~19 nether_brick_fence 0
fill ~1 ~53 ~20 ~2 ~53 ~20 nether_brick_fence 0
fill ~1 ~53 ~21 ~2 ~53 ~21 nether_brick_fence 0
fill ~1 ~53 ~22 ~2 ~53 ~22 nether_brick_fence 0
fill ~1 ~53 ~23 ~2 ~53 ~23 nether_brick_fence 0
fill ~1 ~53 ~24 ~2 ~53 ~24 nether_brick_fence 0
fill ~1 ~53 ~25 ~2 ~53 ~25 nether_brick_fence 0
fill ~1 ~53 ~26 ~2 ~53 ~26 nether_brick_fence 0
fill ~1 ~53 ~27 ~2 ~53 ~27 nether_brick_fence 0
fill ~1 ~53 ~28 ~2 ~53 ~28 nether_brick_fence 0
fill ~1 ~53 ~29 ~3 ~53 ~29 nether_brick_fence 0
fill ~2 ~53 ~16 ~4 ~53 ~16 nether_brick_fence 0
fill ~2 ~53 ~17 ~3 ~53 ~17 nether_brick_fence 0
fill ~2 ~53 ~18 ~3 ~53 ~18 nether_brick_fence 0
fill ~2 ~53 ~30 ~3 ~53 ~30 nether_brick_fence 0
fill ~2 ~53 ~31 ~3 ~53 ~31 nether_brick_fence 0
fill ~2 ~53 ~32 ~4 ~53 ~32 nether_brick_fence 0
fill ~3 ~53 ~13 ~5 ~53 ~13 nether_brick_fence 0
fill ~3 ~53 ~14 ~4 ~53 ~14 nether_brick_fence 0
fill ~3 ~53 ~15 ~4 ~53 ~15 nether_brick_fence 0
fill ~3 ~53 ~20 ~4 ~53 ~20 redstone_block 0
fill ~3 ~53 ~21 ~4 ~53 ~21 redstone_block 0
fill ~3 ~53 ~22 ~4 ~53 ~22 redstone_block 0
fill ~3 ~53 ~23 ~4 ~53 ~23 redstone_block 0
fill ~3 ~53 ~24 ~4 ~53 ~24 redstone_block 0
fill ~3 ~53 ~25 ~4 ~53 ~25 redstone_block 0
fill ~3 ~53 ~26 ~4 ~53 ~26 redstone_block 0
fill ~3 ~53 ~27 ~4 ~53 ~27 redstone_block 0
fill ~3 ~53 ~28 ~4 ~53 ~28 redstone_block 0
fill ~3 ~53 ~33 ~4 ~53 ~33 nether_brick_fence 0
fill ~3 ~53 ~34 ~4 ~53 ~34 nether_brick_fence 0
fill ~3 ~53 ~35 ~5 ~53 ~35 nether_brick_fence 0
fill ~4 ~53 ~12 ~6 ~53 ~12 nether_brick_fence 0
fill ~4 ~53 ~17 ~5 ~53 ~17 redstone_block 0
fill ~4 ~53 ~18 ~5 ~53 ~18 redstone_block 0
fill ~4 ~53 ~19 ~5 ~53 ~19 redstone_block 0
fill ~4 ~53 ~29 ~5 ~53 ~29 redstone_block 0
fill ~4 ~53 ~30 ~5 ~53 ~30 redstone_block 0
fill ~4 ~53 ~31 ~5 ~53 ~31 redstone_block 0
fill ~4 ~53 ~36 ~6 ~53 ~36 nether_brick_fence 0
fill ~5 ~53 ~10 ~7 ~53 ~10 nether_brick_fence 0
fill ~5 ~53 ~11 ~6 ~53 ~11 nether_brick_fence 0
fill ~5 ~53 ~14 ~7 ~53 ~14 redstone_block 0
fill ~5 ~53 ~15 ~6 ~53 ~15 redstone_block 0
fill ~5 ~53 ~16 ~6 ~53 ~16 redstone_block 0
fill ~5 ~53 ~20 ~5 ~54 ~20 obsidian 0
fill ~5 ~53 ~21 ~5 ~54 ~21 obsidian 0
fill ~5 ~53 ~22 ~5 ~54 ~22 obsidian 0
fill ~5 ~53 ~23 ~5 ~54 ~23 obsidian 0
fill ~5 ~53 ~24 ~5 ~54 ~24 obsidian 0
fill ~5 ~53 ~25 ~5 ~54 ~25 obsidian 0
fill ~5 ~53 ~26 ~5 ~54 ~26 obsidian 0
fill ~5 ~53 ~27 ~5 ~54 ~27 obsidian 0
fill ~5 ~53 ~28 ~5 ~54 ~28 obsidian 0
fill ~5 ~53 ~32 ~6 ~53 ~32 redstone_block 0
fill ~5 ~53 ~33 ~6 ~53 ~33 redstone_block 0
fill ~5 ~53 ~34 ~7 ~53 ~34 redstone_block 0
fill ~5 ~53 ~37 ~6 ~53 ~37 nether_brick_fence 0
fill ~5 ~53 ~38 ~7 ~53 ~38 nether_brick_fence 0
fill ~6 ~53 ~9 ~8 ~53 ~9 nether_brick_fence 0
fill ~6 ~53 ~13 ~7 ~53 ~13 redstone_block 0
fill ~6 ~53 ~17 ~6 ~54 ~17 obsidian 0
fill ~6 ~53 ~18 ~6 ~54 ~18 obsidian 0
fill ~6 ~53 ~19 ~6 ~54 ~19 obsidian 0
fill ~6 ~53 ~29 ~6 ~54 ~29 obsidian 0
fill ~6 ~53 ~30 ~6 ~54 ~30 obsidian 0
fill ~6 ~53 ~31 ~6 ~54 ~31 obsidian 0
fill ~6 ~53 ~35 ~7 ~53 ~35 redstone_block 0
fill ~6 ~53 ~39 ~8 ~53 ~39 nether_brick_fence 0
fill ~7 ~53 ~8 ~9 ~53 ~8 nether_brick_fence 0
fill ~7 ~53 ~11 ~9 ~53 ~11 redstone_block 0
fill ~7 ~53 ~12 ~8 ~53 ~12 redstone_block 0
fill ~7 ~53 ~15 ~7 ~54 ~15 obsidian 0
fill ~7 ~53 ~16 ~7 ~54 ~16 obsidian 0
fill ~7 ~53 ~32 ~7 ~54 ~32 obsidian 0
fill ~7 ~53 ~33 ~7 ~54 ~33 obsidian 0
fill ~7 ~53 ~36 ~8 ~53 ~36 redstone_block 0
fill ~7 ~53 ~37 ~9 ~53 ~37 redstone_block 0
fill ~7 ~53 ~40 ~9 ~53 ~40 nether_brick_fence 0
fill ~8 ~53 ~7 ~10 ~53 ~7 nether_brick_fence 0
fill ~8 ~53 ~10 ~10 ~53 ~10 redstone_block 0
fill ~8 ~53 ~13 ~9 ~53 ~13 obsidian 0
fill ~8 ~53 ~14 ~8 ~54 ~14 obsidian 0
fill ~8 ~53 ~34 ~8 ~54 ~34 obsidian 0
fill ~8 ~53 ~35 ~9 ~53 ~35 obsidian 0
fill ~8 ~53 ~38 ~10 ~53 ~38 redstone_block 0
fill ~8 ~53 ~41 ~10 ~53 ~41 nether_brick_fence 0
fill ~9 ~53 ~6 ~11 ~53 ~6 nether_brick_fence 0
fill ~9 ~53 ~9 ~11 ~53 ~9 redstone_block 0
fill ~9 ~53 ~12 ~9 ~54 ~12 obsidian 0
fill ~9 ~53 ~36 ~9 ~54 ~36 obsidian 0
fill ~9 ~53 ~39 ~11 ~53 ~39 redstone_block 0
fill ~9 ~53 ~42 ~11 ~53 ~42 nether_brick_fence 0
fill ~10 ~53 ~5 ~13 ~53 ~5 nether_brick_fence 0
fill ~10 ~53 ~8 ~12 ~53 ~8 redstone_block 0
fill ~10 ~53 ~11 ~10 ~54 ~11 obsidian 0
fill ~10 ~53 ~37 ~10 ~54 ~37 obsidian 0
fill ~10 ~53 ~40 ~12 ~53 ~40 redstone_block 0
fill ~10 ~53 ~43 ~13 ~53 ~43 nether_brick_fence 0
fill ~11 ~53 ~4 ~14 ~53 ~4 nether_brick_fence 0
fill ~11 ~53 ~7 ~13 ~53 ~7 redstone_block 0
fill ~11 ~53 ~10 ~11 ~54 ~10 obsidian 0
fill ~11 ~53 ~38 ~11 ~54 ~38 obsidian 0
fill ~11 ~53 ~41 ~13 ~53 ~41 redstone_block 0
fill ~11 ~53 ~44 ~14 ~53 ~44 nether_brick_fence 0
fill ~12 ~53 ~6 ~15 ~53 ~6 redstone_block 0
fill ~12 ~53 ~9 ~12 ~54 ~9 obsidian 0
fill ~12 ~53 ~39 ~12 ~54 ~39 obsidian 0
fill ~12 ~53 ~42 ~15 ~53 ~42 redstone_block 0
fill ~13 ~53 ~3 ~17 ~53 ~3 nether_brick_fence 0
fill ~13 ~53 ~8 ~14 ~53 ~8 obsidian 0
fill ~13 ~53 ~40 ~14 ~53 ~40 obsidian 0
fill ~13 ~53 ~45 ~17 ~53 ~45 nether_brick_fence 0
fill ~14 ~53 ~2 ~20 ~53 ~2 nether_brick_fence 0
fill ~14 ~53 ~5 ~17 ~53 ~5 redstone_block 0
fill ~14 ~53 ~7 ~15 ~53 ~7 obsidian 0
fill ~14 ~53 ~41 ~15 ~53 ~41 obsidian 0
fill ~14 ~53 ~43 ~17 ~53 ~43 redstone_block 0
fill ~14 ~53 ~46 ~20 ~53 ~46 nether_brick_fence 0
fill ~15 ~53 ~4 ~20 ~53 ~4 redstone_block 0
fill ~15 ~53 ~44 ~20 ~53 ~44 redstone_block 0
fill ~16 ~53 ~6 ~17 ~53 ~6 obsidian 0
fill ~16 ~53 ~42 ~17 ~53 ~42 obsidian 0
fill ~17 ~53 ~1 ~33 ~53 ~1 nether_brick_fence 0
fill ~17 ~53 ~47 ~33 ~53 ~47 nether_brick_fence 0
fill ~18 ~53 ~3 ~32 ~53 ~3 redstone_block 0
fill ~18 ~53 ~5 ~20 ~53 ~5 obsidian 0
fill ~18 ~53 ~43 ~20 ~53 ~43 obsidian 0
fill ~18 ~53 ~45 ~32 ~53 ~45 redstone_block 0
fill ~20 ~53 ~0 ~30 ~53 ~0 nether_brick_fence 0
fill ~20 ~53 ~48 ~30 ~53 ~48 nether_brick_fence 0
fill ~21 ~53 ~2 ~29 ~53 ~2 redstone_block 0
fill ~21 ~53 ~4 ~29 ~53 ~4 obsidian 0
fill ~21 ~53 ~44 ~29 ~53 ~44 obsidian 0
fill ~21 ~53 ~46 ~29 ~53 ~46 redstone_block 0
fill ~30 ~53 ~2 ~36 ~53 ~2 nether_brick_fence 0
fill ~30 ~53 ~4 ~35 ~53 ~4 redstone_block 0
fill ~30 ~53 ~5 ~32 ~53 ~5 obsidian 0
fill ~30 ~53 ~43 ~32 ~53 ~43 obsidian 0
fill ~30 ~53 ~44 ~35 ~53 ~44 redstone_block 0
fill ~30 ~53 ~46 ~36 ~53 ~46 nether_brick_fence 0
fill ~33 ~53 ~3 ~37 ~53 ~3 nether_brick_fence 0
fill ~33 ~53 ~5 ~36 ~53 ~5 redstone_block 0
fill ~33 ~53 ~6 ~34 ~53 ~6 obsidian 0
fill ~33 ~53 ~42 ~34 ~53 ~42 obsidian 0
fill ~33 ~53 ~43 ~36 ~53 ~43 redstone_block 0
fill ~33 ~53 ~45 ~37 ~53 ~45 nether_brick_fence 0
fill ~35 ~53 ~6 ~38 ~53 ~6 redstone_block 0
fill ~35 ~53 ~7 ~36 ~53 ~7 obsidian 0
fill ~35 ~53 ~41 ~36 ~53 ~41 obsidian 0
fill ~35 ~53 ~42 ~38 ~53 ~42 redstone_block 0
fill ~36 ~53 ~4 ~39 ~53 ~4 nether_brick_fence 0
fill ~36 ~53 ~8 ~37 ~53 ~8 obsidian 0
fill ~36 ~53 ~40 ~37 ~53 ~40 obsidian 0
fill ~36 ~53 ~44 ~39 ~53 ~44 nether_brick_fence 0
fill ~37 ~53 ~5 ~40 ~53 ~5 nether_brick_fence 0
fill ~37 ~53 ~7 ~39 ~53 ~7 redstone_block 0
fill ~37 ~53 ~41 ~39 ~53 ~41 redstone_block 0
fill ~37 ~53 ~43 ~40 ~53 ~43 nether_brick_fence 0
fill ~38 ~53 ~8 ~40 ~53 ~8 redstone_block 0
fill ~38 ~53 ~9 ~38 ~54 ~9 obsidian 0
fill ~38 ~53 ~39 ~38 ~54 ~39 obsidian 0
fill ~38 ~53 ~40 ~40 ~53 ~40 redstone_block 0
fill ~39 ~53 ~6 ~41 ~53 ~6 nether_brick_fence 0
fill ~39 ~53 ~9 ~41 ~53 ~9 redstone_block 0
fill ~39 ~53 ~10 ~39 ~54 ~10 obsidian 0
fill ~39 ~53 ~38 ~39 ~54 ~38 obsidian 0
fill ~39 ~53 ~39 ~41 ~53 ~39 redstone_block 0
fill ~39 ~53 ~42 ~41 ~53 ~42 nether_brick_fence 0
fill ~40 ~53 ~7 ~42 ~53 ~7 nether_brick_fence 0
fill ~40 ~53 ~10 ~42 ~53 ~10 redstone_block 0
fill ~40 ~53 ~11 ~40 ~54 ~11 obsidian 0
fill ~40 ~53 ~37 ~40 ~54 ~37 obsidian 0
fill ~40 ~53 ~38 ~42 ~53 ~38 redstone_block 0
fill ~40 ~53 ~41 ~42 ~53 ~41 nether_brick_fence 0
fill ~41 ~53 ~8 ~43 ~53 ~8 nether_brick_fence 0
fill ~41 ~53 ~11 ~43 ~53 ~11 redstone_block 0
fill ~41 ~53 ~12 ~41 ~54 ~12 obsidian 0
fill ~41 ~53 ~13 ~42 ~53 ~13 obsidian 0
fill ~41 ~53 ~35 ~42 ~53 ~35 obsidian 0
fill ~41 ~53 ~36 ~41 ~54 ~36 obsidian 0
fill ~41 ~53 ~37 ~43 ~53 ~37 redstone_block 0
fill ~41 ~53 ~40 ~43 ~53 ~40 nether_brick_fence 0
fill ~42 ~53 ~9 ~44 ~53 ~9 nether_brick_fence 0
fill ~42 ~53 ~12 ~43 ~53 ~12 redstone_block 0
fill ~42 ~53 ~14 ~42 ~54 ~14 obsidian 0
fill ~42 ~53 ~34 ~42 ~54 ~34 obsidian 0
fill ~42 ~53 ~36 ~43 ~53 ~36 redstone_block 0
fill ~42 ~53 ~39 ~44 ~53 ~39 nether_brick_fence 0
fill ~43 ~53 ~10 ~45 ~53 ~10 nether_brick_fence 0
fill ~43 ~53 ~13 ~44 ~53 ~13 redstone_block 0
fill ~43 ~53 ~14 ~45 ~53 ~14 redstone_block 0
fill ~43 ~53 ~15 ~43 ~54 ~15 obsidian 0
fill ~43 ~53 ~16 ~43 ~54 ~16 obsidian 0
fill ~43 ~53 ~32 ~43 ~54 ~32 obsidian 0
fill ~43 ~53 ~33 ~43 ~54 ~33 obsidian 0
fill ~43 ~53 ~34 ~45 ~53 ~34 redstone_block 0
fill ~43 ~53 ~35 ~44 ~53 ~35 redstone_block 0
fill ~43 ~53 ~38 ~45 ~53 ~38 nether_brick_fence 0
fill ~44 ~53 ~11 ~45 ~53 ~11 nether_brick_fence 0
fill ~44 ~53 ~12 ~46 ~53 ~12 nether_brick_fence 0
fill ~44 ~53 ~15 ~45 ~53 ~15 redstone_block 0
fill ~44 ~53 ~16 ~45 ~53 ~16 redstone_block 0
fill ~44 ~53 ~17 ~44 ~54 ~17 obsidian 0
fill ~44 ~53 ~18 ~44 ~54 ~18 obsidian 0
fill ~44 ~53 ~19 ~44 ~54 ~19 obsidian 0
fill ~44 ~53 ~29 ~44 ~54 ~29 obsidian 0
fill ~44 ~53 ~30 ~44 ~54 ~30 obsidian 0
fill ~44 ~53 ~31 ~44 ~54 ~31 obsidian 0
fill ~44 ~53 ~32 ~45 ~53 ~32 redstone_block 0
fill ~44 ~53 ~33 ~45 ~53 ~33 redstone_block 0
fill ~44 ~53 ~36 ~46 ~53 ~36 nether_brick_fence 0
fill ~44 ~53 ~37 ~45 ~53 ~37 nether_brick_fence 0
fill ~45 ~53 ~13 ~47 ~53 ~13 nether_brick_fence 0
fill ~45 ~53 ~17 ~46 ~53 ~17 redstone_block 0
fill ~45 ~53 ~18 ~46 ~53 ~18 redstone_block 0
fill ~45 ~53 ~19 ~46 ~53 ~19 redstone_block 0
fill ~45 ~53 ~20 ~45 ~54 ~20 obsidian 0
fill ~45 ~53 ~21 ~45 ~54 ~21 obsidian 0
fill ~45 ~53 ~22 ~45 ~54 ~22 obsidian 0
fill ~45 ~53 ~23 ~45 ~54 ~23 obsidian 0
fill ~45 ~53 ~24 ~45 ~54 ~24 obsidian 0
fill ~45 ~53 ~25 ~45 ~54 ~25 obsidian 0
fill ~45 ~53 ~26 ~45 ~54 ~26 obsidian 0
fill ~45 ~53 ~27 ~45 ~54 ~27 obsidian 0
fill ~45 ~53 ~28 ~45 ~54 ~28 obsidian 0
fill ~45 ~53 ~29 ~46 ~53 ~29 redstone_block 0
fill ~45 ~53 ~30 ~46 ~53 ~30 redstone_block 0
fill ~45 ~53 ~31 ~46 ~53 ~31 redstone_block 0
fill ~45 ~53 ~35 ~47 ~53 ~35 nether_brick_fence 0
fill ~46 ~53 ~14 ~47 ~53 ~14 nether_brick_fence 0
fill ~46 ~53 ~15 ~47 ~53 ~15 nether_brick_fence 0
fill ~46 ~53 ~16 ~48 ~53 ~16 nether_brick_fence 0
fill ~46 ~53 ~20 ~47 ~53 ~20 redstone_block 0
fill ~46 ~53 ~21 ~47 ~53 ~21 redstone_block 0
fill ~46 ~53 ~22 ~47 ~53 ~22 redstone_block 0
fill ~46 ~53 ~23 ~47 ~53 ~23 redstone_block 0
fill ~46 ~53 ~24 ~47 ~53 ~24 redstone_block 0
fill ~46 ~53 ~25 ~47 ~53 ~25 redstone_block 0
fill ~46 ~53 ~26 ~47 ~53 ~26 redstone_block 0
fill ~46 ~53 ~27 ~47 ~53 ~27 redstone_block 0
fill ~46 ~53 ~28 ~47 ~53 ~28 redstone_block 0
fill ~46 ~53 ~32 ~48 ~53 ~32 nether_brick_fence 0
fill ~46 ~53 ~33 ~47 ~53 ~33 nether_brick_fence 0
fill ~46 ~53 ~34 ~47 ~53 ~34 nether_brick_fence 0
fill ~47 ~53 ~17 ~48 ~53 ~17 nether_brick_fence 0
fill ~47 ~53 ~18 ~48 ~53 ~18 nether_brick_fence 0
fill ~47 ~53 ~19 ~49 ~53 ~19 nether_brick_fence 0
fill ~47 ~53 ~29 ~49 ~53 ~29 nether_brick_fence 0
fill ~47 ~53 ~30 ~48 ~53 ~30 nether_brick_fence 0
fill ~47 ~53 ~31 ~48 ~53 ~31 nether_brick_fence 0
fill ~48 ~53 ~20 ~49 ~53 ~20 nether_brick_fence 0
fill ~48 ~53 ~21 ~49 ~53 ~21 nether_brick_fence 0
fill ~48 ~53 ~22 ~49 ~53 ~22 nether_brick_fence 0
fill ~48 ~53 ~23 ~49 ~53 ~23 nether_brick_fence 0
fill ~48 ~53 ~24 ~49 ~53 ~24 nether_brick_fence 0
fill ~48 ~53 ~25 ~49 ~53 ~25 nether_brick_fence 0
fill ~48 ~53 ~26 ~49 ~53 ~26 nether_brick_fence 0
fill ~48 ~53 ~27 ~49 ~53 ~27 nether_brick_fence 0
fill ~48 ~53 ~28 ~49 ~53 ~28 nether_brick_fence 0
fill ~6 ~54 ~20 ~6 ~55 ~20 redstone_block 0
fill ~6 ~54 ~21 ~6 ~55 ~21 redstone_block 0
fill ~6 ~54 ~22 ~6 ~55 ~22 redstone_block 0
fill ~6 ~54 ~23 ~6 ~55 ~23 redstone_block 0
fill ~6 ~54 ~24 ~6 ~55 ~24 redstone_block 0
fill ~6 ~54 ~25 ~6 ~55 ~25 redstone_block 0
fill ~6 ~54 ~26 ~6 ~55 ~26 redstone_block 0
fill ~6 ~54 ~27 ~6 ~55 ~27 redstone_block 0
fill ~6 ~54 ~28 ~6 ~55 ~28 redstone_block 0
fill ~7 ~54 ~17 ~7 ~55 ~17 redstone_block 0
fill ~7 ~54 ~18 ~7 ~55 ~18 redstone_block 0
fill ~7 ~54 ~19 ~7 ~55 ~19 redstone_block 0
fill ~7 ~54 ~29 ~7 ~55 ~29 redstone_block 0
fill ~7 ~54 ~30 ~7 ~55 ~30 redstone_block 0
fill ~7 ~54 ~31 ~7 ~55 ~31 redstone_block 0
fill ~8 ~54 ~13 ~9 ~54 ~13 obsidian 0
fill ~8 ~54 ~15 ~8 ~55 ~15 redstone_block 0
fill ~8 ~54 ~16 ~8 ~55 ~16 redstone_block 0
fill ~8 ~54 ~32 ~8 ~55 ~32 redstone_block 0
fill ~8 ~54 ~33 ~8 ~55 ~33 redstone_block 0
fill ~8 ~54 ~35 ~9 ~54 ~35 obsidian 0
fill ~9 ~54 ~14 ~9 ~55 ~14 redstone_block 0
fill ~9 ~54 ~34 ~9 ~55 ~34 redstone_block 0
setblock ~10 ~54 ~10 obsidian 0
fill ~10 ~54 ~12 ~11 ~54 ~12 redstone_block 0
fill ~10 ~54 ~13 ~10 ~55 ~13 redstone_block 0
fill ~10 ~54 ~35 ~10 ~55 ~35 redstone_block 0
fill ~10 ~54 ~36 ~11 ~54 ~36 redstone_block 0
setblock ~10 ~54 ~38 obsidian 0
setblock ~11 ~54 ~9 obsidian 0
fill ~11 ~54 ~11 ~12 ~54 ~11 redstone_block 0
fill ~11 ~54 ~37 ~12 ~54 ~37 redstone_block 0
setblock ~11 ~54 ~39 obsidian 0
fill ~12 ~54 ~10 ~13 ~54 ~10 redstone_block 0
fill ~12 ~54 ~38 ~13 ~54 ~38 redstone_block 0
fill ~13 ~54 ~8 ~14 ~54 ~8 obsidian 0
fill ~13 ~54 ~9 ~14 ~54 ~9 redstone_block 0
fill ~13 ~54 ~39 ~14 ~54 ~39 redstone_block 0
fill ~13 ~54 ~40 ~14 ~54 ~40 obsidian 0
fill ~14 ~54 ~7 ~15 ~54 ~7 obsidian 0
fill ~14 ~54 ~41 ~15 ~54 ~41 obsidian 0
fill ~15 ~54 ~8 ~15 ~55 ~8 redstone_block 0
fill ~15 ~54 ~40 ~15 ~55 ~40 redstone_block 0
fill ~16 ~54 ~6 ~17 ~54 ~6 obsidian 0
fill ~16 ~54 ~7 ~17 ~54 ~7 redstone_block 0
fill ~16 ~54 ~41 ~17 ~54 ~41 redstone_block 0
fill ~16 ~54 ~42 ~17 ~54 ~42 obsidian 0
fill ~18 ~54 ~5 ~20 ~54 ~5 obsidian 0
fill ~18 ~54 ~6 ~20 ~54 ~6 redstone_block 0
fill ~18 ~54 ~42 ~20 ~54 ~42 redstone_block 0
fill ~18 ~54 ~43 ~20 ~54 ~43 obsidian 0
fill ~21 ~54 ~4 ~29 ~54 ~4 obsidian 0
fill ~21 ~54 ~5 ~29 ~54 ~5 redstone_block 0
fill ~21 ~54 ~43 ~29 ~54 ~43 redstone_block 0
fill ~21 ~54 ~44 ~29 ~54 ~44 obsidian 0
fill ~30 ~54 ~5 ~32 ~54 ~5 obsidian 0
fill ~30 ~54 ~6 ~32 ~54 ~6 redstone_block 0
fill ~30 ~54 ~42 ~32 ~54 ~42 redstone_block 0
fill ~30 ~54 ~43 ~32 ~54 ~43 obsidian 0
fill ~33 ~54 ~6 ~34 ~54 ~6 obsidian 0
fill ~33 ~54 ~7 ~34 ~54 ~7 redstone_block 0
fill ~33 ~54 ~41 ~34 ~54 ~41 redstone_block 0
fill ~33 ~54 ~42 ~34 ~54 ~42 obsidian 0
fill ~35 ~54 ~7 ~36 ~54 ~7 obsidian 0
fill ~35 ~54 ~8 ~35 ~55 ~8 redstone_block 0
fill ~35 ~54 ~40 ~35 ~55 ~40 redstone_block 0
fill ~35 ~54 ~41 ~36 ~54 ~41 obsidian 0
fill ~36 ~54 ~8 ~37 ~54 ~8 obsidian 0
fill ~36 ~54 ~9 ~37 ~54 ~9 redstone_block 0
fill ~36 ~54 ~39 ~37 ~54 ~39 redstone_block 0
fill ~36 ~54 ~40 ~37 ~54 ~40 obsidian 0
fill ~37 ~54 ~10 ~38 ~54 ~10 redstone_block 0
fill ~37 ~54 ~38 ~38 ~54 ~38 redstone_block 0
fill ~38 ~54 ~11 ~39 ~54 ~11 redstone_block 0
fill ~38 ~54 ~37 ~39 ~54 ~37 redstone_block 0
setblock ~39 ~54 ~9 obsidian 0
fill ~39 ~54 ~12 ~40 ~54 ~12 redstone_block 0
fill ~39 ~54 ~36 ~40 ~54 ~36 redstone_block 0
setblock ~39 ~54 ~39 obsidian 0
setblock ~40 ~54 ~10 obsidian 0
fill ~40 ~54 ~13 ~40 ~55 ~13 redstone_block 0
fill ~40 ~54 ~35 ~40 ~55 ~35 redstone_block 0
setblock ~40 ~54 ~38 obsidian 0
fill ~41 ~54 ~13 ~42 ~54 ~13 obsidian 0
fill ~41 ~54 ~14 ~41 ~55 ~14 redstone_block 0
fill ~41 ~54 ~34 ~41 ~55 ~34 redstone_block 0
fill ~41 ~54 ~35 ~42 ~54 ~35 obsidian 0
fill ~42 ~54 ~15 ~42 ~55 ~15 redstone_block 0
fill ~42 ~54 ~16 ~42 ~55 ~16 redstone_block 0
fill ~42 ~54 ~32 ~42 ~55 ~32 redstone_block 0
fill ~42 ~54 ~33 ~42 ~55 ~33 redstone_block 0
fill ~43 ~54 ~17 ~43 ~55 ~17 redstone_block 0
fill ~43 ~54 ~18 ~43 ~55 ~18 redstone_block 0
fill ~43 ~54 ~19 ~43 ~55 ~19 redstone_block 0
fill ~43 ~54 ~29 ~43 ~55 ~29 redstone_block 0
fill ~43 ~54 ~30 ~43 ~55 ~30 redstone_block 0
fill ~43 ~54 ~31 ~43 ~55 ~31 redstone_block 0
fill ~44 ~54 ~20 ~44 ~55 ~20 redstone_block 0
fill ~44 ~54 ~21 ~44 ~55 ~21 redstone_block 0
fill ~44 ~54 ~22 ~44 ~55 ~22 redstone_block 0
fill ~44 ~54 ~23 ~44 ~55 ~23 redstone_block 0
fill ~44 ~54 ~24 ~44 ~55 ~24 redstone_block 0
fill ~44 ~54 ~25 ~44 ~55 ~25 redstone_block 0
fill ~44 ~54 ~26 ~44 ~55 ~26 redstone_block 0
fill ~44 ~54 ~27 ~44 ~55 ~27 redstone_block 0
fill ~44 ~54 ~28 ~44 ~55 ~28 redstone_block 0
fill ~7 ~55 ~20 ~9 ~55 ~20 redstone_block 0
fill ~7 ~55 ~21 ~8 ~55 ~21 redstone_block 0
fill ~7 ~55 ~22 ~8 ~55 ~22 redstone_block 0
fill ~7 ~55 ~23 ~8 ~55 ~23 redstone_block 0
fill ~7 ~55 ~24 ~8 ~55 ~24 redstone_block 0
fill ~7 ~55 ~25 ~8 ~55 ~25 redstone_block 0
fill ~7 ~55 ~26 ~8 ~55 ~26 redstone_block 0
fill ~7 ~55 ~27 ~8 ~55 ~27 redstone_block 0
fill ~7 ~55 ~28 ~9 ~55 ~28 redstone_block 0
fill ~8 ~55 ~17 ~10 ~55 ~17 redstone_block 0
fill ~8 ~55 ~18 ~9 ~55 ~18 redstone_block 0
fill ~8 ~55 ~19 ~9 ~55 ~19 redstone_block 0
fill ~8 ~55 ~29 ~9 ~55 ~29 redstone_block 0
fill ~8 ~55 ~30 ~9 ~55 ~30 redstone_block 0
fill ~8 ~55 ~31 ~10 ~55 ~31 redstone_block 0
setblock ~9 ~55 ~13 redstone_block 0
fill ~9 ~55 ~15 ~11 ~55 ~15 redstone_block 0
fill ~9 ~55 ~16 ~10 ~55 ~16 redstone_block 0
fill ~9 ~55 ~32 ~10 ~55 ~32 redstone_block 0
fill ~9 ~55 ~33 ~11 ~55 ~33 redstone_block 0
setblock ~9 ~55 ~35 redstone_block 0
fill ~10 ~55 ~12 ~13 ~55 ~12 redstone_block 0
fill ~10 ~55 ~14 ~11 ~55 ~14 redstone_block 0
fill ~10 ~55 ~34 ~11 ~55 ~34 redstone_block 0
fill ~10 ~55 ~36 ~13 ~55 ~36 redstone_block 0
fill ~11 ~55 ~11 ~14 ~55 ~11 redstone_block 0
fill ~11 ~55 ~13 ~12 ~55 ~13 redstone_block 0
fill ~11 ~55 ~35 ~12 ~55 ~35 redstone_block 0
fill ~11 ~55 ~37 ~14 ~55 ~37 redstone_block 0
fill ~12 ~55 ~10 ~16 ~55 ~10 redstone_block 0
fill ~12 ~55 ~38 ~16 ~55 ~38 redstone_block 0
fill ~13 ~55 ~9 ~18 ~55 ~9 redstone_block 0
fill ~13 ~55 ~39 ~18 ~55 ~39 redstone_block 0
setblock ~14 ~55 ~8 redstone_block 0
setblock ~14 ~55 ~40 redstone_block 0
fill ~16 ~55 ~7 ~34 ~55 ~7 redstone_block 0
fill ~16 ~55 ~8 ~21 ~55 ~8 redstone_block 0
fill ~16 ~55 ~40 ~21 ~55 ~40 redstone_block 0
fill ~16 ~55 ~41 ~34 ~55 ~41 redstone_block 0
fill ~18 ~55 ~6 ~32 ~55 ~6 redstone_block 0
fill ~18 ~55 ~42 ~32 ~55 ~42 redstone_block 0
fill ~21 ~55 ~5 ~29 ~55 ~5 redstone_block 0
fill ~21 ~55 ~43 ~29 ~55 ~43 redstone_block 0
fill ~29 ~55 ~8 ~36 ~55 ~8 redstone_block 0
fill ~29 ~55 ~40 ~36 ~55 ~40 redstone_block 0
fill ~32 ~55 ~9 ~37 ~55 ~9 redstone_block 0
fill ~32 ~55 ~39 ~37 ~55 ~39 redstone_block 0
fill ~34 ~55 ~10 ~38 ~55 ~10 redstone_block 0
fill ~34 ~55 ~38 ~38 ~55 ~38 redstone_block 0
fill ~36 ~55 ~11 ~39 ~55 ~11 redstone_block 0
fill ~36 ~55 ~37 ~39 ~55 ~37 redstone_block 0
fill ~37 ~55 ~12 ~40 ~55 ~12 redstone_block 0
fill ~37 ~55 ~36 ~40 ~55 ~36 redstone_block 0
fill ~38 ~55 ~13 ~41 ~55 ~13 redstone_block 0
fill ~38 ~55 ~35 ~41 ~55 ~35 redstone_block 0
fill ~39 ~55 ~14 ~41 ~55 ~14 redstone_block 0
fill ~39 ~55 ~15 ~42 ~55 ~15 redstone_block 0
fill ~39 ~55 ~33 ~42 ~55 ~33 redstone_block 0
fill ~39 ~55 ~34 ~41 ~55 ~34 redstone_block 0
fill ~40 ~55 ~16 ~42 ~55 ~16 redstone_block 0
fill ~40 ~55 ~17 ~43 ~55 ~17 redstone_block 0
fill ~40 ~55 ~31 ~43 ~55 ~31 redstone_block 0
fill ~40 ~55 ~32 ~42 ~55 ~32 redstone_block 0
fill ~41 ~55 ~18 ~43 ~55 ~18 redstone_block 0
fill ~41 ~55 ~19 ~43 ~55 ~19 redstone_block 0
fill ~41 ~55 ~20 ~44 ~55 ~20 redstone_block 0
fill ~41 ~55 ~28 ~44 ~55 ~28 redstone_block 0
fill ~41 ~55 ~29 ~43 ~55 ~29 redstone_block 0
fill ~41 ~55 ~30 ~43 ~55 ~30 redstone_block 0
fill ~42 ~55 ~21 ~44 ~55 ~21 redstone_block 0
fill ~42 ~55 ~22 ~44 ~55 ~22 redstone_block 0
fill ~42 ~55 ~23 ~44 ~55 ~23 redstone_block 0
fill ~42 ~55 ~24 ~44 ~55 ~24 redstone_block 0
fill ~42 ~55 ~25 ~44 ~55 ~25 redstone_block 0
fill ~42 ~55 ~26 ~44 ~55 ~26 redstone_block 0
fill ~42 ~55 ~27 ~44 ~55 ~27 redstone_block 0
fill ~8 ~56 ~20 ~12 ~56 ~20 bedrock 0
fill ~8 ~56 ~21 ~11 ~56 ~21 bedrock 0
fill ~8 ~56 ~22 ~11 ~56 ~22 bedrock 0
fill ~8 ~56 ~23 ~11 ~56 ~23 bedrock 0
fill ~8 ~56 ~24 ~11 ~56 ~24 bedrock 0
fill ~8 ~56 ~25 ~11 ~56 ~25 bedrock 0
fill ~8 ~56 ~26 ~11 ~56 ~26 bedrock 0
fill ~8 ~56 ~27 ~11 ~56 ~27 bedrock 0
fill ~8 ~56 ~28 ~12 ~56 ~28 bedrock 0
fill ~9 ~56 ~17 ~13 ~56 ~17 bedrock 0
fill ~9 ~56 ~18 ~13 ~56 ~18 bedrock 0
fill ~9 ~56 ~19 ~12 ~56 ~19 bedrock 0
fill ~9 ~56 ~29 ~12 ~56 ~29 bedrock 0
fill ~9 ~56 ~30 ~13 ~56 ~30 bedrock 0
fill ~9 ~56 ~31 ~13 ~56 ~31 bedrock 0
fill ~10 ~56 ~15 ~15 ~56 ~15 bedrock 0
fill ~10 ~56 ~16 ~14 ~56 ~16 bedrock 0
fill ~10 ~56 ~32 ~14 ~56 ~32 bedrock 0
fill ~10 ~56 ~33 ~15 ~56 ~33 bedrock 0
fill ~11 ~56 ~14 ~16 ~56 ~14 bedrock 0
fill ~11 ~56 ~34 ~16 ~56 ~34 bedrock 0
fill ~12 ~56 ~13 ~17 ~56 ~13 bedrock 0
fill ~12 ~56 ~35 ~17 ~56 ~35 bedrock 0
fill ~13 ~56 ~12 ~19 ~56 ~12 bedrock 0
fill ~13 ~56 ~36 ~19 ~56 ~36 bedrock 0
fill ~14 ~56 ~11 ~21 ~56 ~11 bedrock 0
fill ~14 ~56 ~37 ~21 ~56 ~37 bedrock 0
fill ~15 ~56 ~10 ~35 ~56 ~10 bedrock 0
fill ~15 ~56 ~38 ~35 ~56 ~38 bedrock 0
fill ~16 ~56 ~9 ~34 ~56 ~9 bedrock 0
fill ~16 ~56 ~39 ~34 ~56 ~39 bedrock 0
fill ~18 ~56 ~8 ~32 ~56 ~8 bedrock 0
fill ~18 ~56 ~40 ~32 ~56 ~40 bedrock 0
fill ~21 ~56 ~7 ~29 ~56 ~7 bedrock 0
fill ~21 ~56 ~41 ~29 ~56 ~41 bedrock 0
fill ~29 ~56 ~11 ~36 ~56 ~11 bedrock 0
fill ~29 ~56 ~37 ~36 ~56 ~37 bedrock 0
fill ~31 ~56 ~12 ~37 ~56 ~12 bedrock 0
fill ~31 ~56 ~36 ~37 ~56 ~36 bedrock 0
fill ~33 ~56 ~13 ~38 ~56 ~13 bedrock 0
fill ~33 ~56 ~35 ~38 ~56 ~35 bedrock 0
fill ~34 ~56 ~14 ~39 ~56 ~14 bedrock 0
fill ~34 ~56 ~34 ~39 ~56 ~34 bedrock 0
fill ~35 ~56 ~15 ~40 ~56 ~15 bedrock 0
fill ~35 ~56 ~33 ~40 ~56 ~33 bedrock 0
fill ~36 ~56 ~16 ~40 ~56 ~16 bedrock 0
fill ~36 ~56 ~32 ~40 ~56 ~32 bedrock 0
fill ~37 ~56 ~17 ~41 ~56 ~17 bedrock 0
fill ~37 ~56 ~18 ~41 ~56 ~18 bedrock 0
fill ~37 ~56 ~30 ~41 ~56 ~30 bedrock 0
fill ~37 ~56 ~31 ~41 ~56 ~31 bedrock 0
fill ~38 ~56 ~19 ~41 ~56 ~19 bedrock 0
fill ~38 ~56 ~20 ~42 ~56 ~20 bedrock 0
fill ~38 ~56 ~28 ~42 ~56 ~28 bedrock 0
fill ~38 ~56 ~29 ~41 ~56 ~29 bedrock 0
fill ~39 ~56 ~21 ~42 ~56 ~21 bedrock 0
fill ~39 ~56 ~22 ~42 ~56 ~22 bedrock 0
fill ~39 ~56 ~23 ~42 ~56 ~23 bedrock 0
fill ~39 ~56 ~24 ~42 ~56 ~24 bedrock 0
fill ~39 ~56 ~25 ~42 ~56 ~25 bedrock 0
fill ~39 ~56 ~26 ~42 ~56 ~26 bedrock 0
fill ~39 ~56 ~27 ~42 ~56 ~27 bedrock 0
fill ~10 ~57 ~20 ~11 ~57 ~20 stone_slab 0
fill ~10 ~57 ~21 ~10 ~57 ~28 stone_slab 0
fill ~11 ~57 ~18 ~11 ~57 ~20 stone_slab 0
fill ~11 ~57 ~21 ~11 ~57 ~27 double_stone_slab 0
fill ~11 ~57 ~28 ~11 ~57 ~30 stone_slab 0
fill ~12 ~57 ~16 ~13 ~57 ~16 stone_slab 0
fill ~12 ~57 ~17 ~12 ~57 ~16 stone_slab 0
fill ~12 ~57 ~18 ~13 ~57 ~18 double_stone_slab 0
fill ~12 ~57 ~19 ~12 ~57 ~20 double_stone_slab 0
fill ~12 ~57 ~21 ~12 ~57 ~27 stone_slab 8
fill ~12 ~57 ~28 ~12 ~57 ~30 double_stone_slab 0
fill ~12 ~57 ~31 ~12 ~57 ~32 stone_slab 0
setblock ~13 ~57 ~15 stone_slab 0
setblock ~13 ~57 ~17 double_stone_slab 0
fill ~13 ~57 ~19 ~13 ~57 ~20 stone_slab 8
fill ~13 ~57 ~28 ~13 ~57 ~29 stone_slab 8
fill ~13 ~57 ~30 ~13 ~57 ~31 double_stone_slab 0
fill ~13 ~57 ~32 ~13 ~57 ~33 stone_slab 0
fill ~14 ~57 ~13 ~15 ~57 ~13 stone_slab 0
fill ~14 ~57 ~14 ~14 ~57 ~13 stone_slab 0
fill ~14 ~57 ~15 ~15 ~57 ~15 double_stone_slab 0
fill ~14 ~57 ~16 ~14 ~57 ~15 double_stone_slab 0
fill ~14 ~57 ~17 ~14 ~57 ~18 stone_slab 8
fill ~14 ~57 ~30 ~14 ~57 ~31 stone_slab 8
fill ~14 ~57 ~32 ~14 ~57 ~33 double_stone_slab 0
fill ~14 ~57 ~34 ~14 ~57 ~35 stone_slab 0
fill ~15 ~57 ~14 ~16 ~57 ~14 double_stone_slab 0
setblock ~15 ~57 ~16 stone_slab 8
setblock ~15 ~57 ~32 stone_slab 8
fill ~15 ~57 ~33 ~15 ~57 ~34 double_stone_slab 0
setblock ~15 ~57 ~35 stone_slab 0
fill ~16 ~57 ~12 ~17 ~57 ~12 stone_slab 0
fill ~16 ~57 ~13 ~17 ~57 ~13 double_stone_slab 0
setblock ~16 ~57 ~15 stone_slab 8
setblock ~16 ~57 ~33 stone_slab 8
fill ~16 ~57 ~34 ~16 ~57 ~35 double_stone_slab 0
fill ~16 ~57 ~36 ~17 ~57 ~36 stone_slab 0
fill ~17 ~57 ~11 ~18 ~57 ~11 stone_slab 0
setblock ~17 ~57 ~14 stone_slab 8
setblock ~17 ~57 ~34 stone_slab 8
setblock ~17 ~57 ~35 double_stone_slab 0
fill ~17 ~57 ~37 ~18 ~57 ~37 stone_slab 0
fill ~18 ~57 ~12 ~19 ~57 ~12 double_stone_slab 0
fill ~18 ~57 ~13 ~19 ~57 ~13 stone_slab 8
fill ~18 ~57 ~35 ~19 ~57 ~35 stone_slab 8
fill ~18 ~57 ~36 ~19 ~57 ~36 double_stone_slab 0
fill ~19 ~57 ~10 ~21 ~57 ~10 stone_slab 0
fill ~19 ~57 ~11 ~21 ~57 ~11 double_stone_slab 0
fill ~19 ~57 ~37 ~21 ~57 ~37 double_stone_slab 0
fill ~19 ~57 ~38 ~21 ~57 ~38 stone_slab 0
fill ~20 ~57 ~12 ~21 ~57 ~12 stone_slab 8
fill ~20 ~57 ~36 ~21 ~57 ~36 stone_slab 8
fill ~21 ~57 ~9 ~29 ~57 ~9 stone_slab 0
fill ~21 ~57 ~39 ~29 ~57 ~39 stone_slab 0
fill ~22 ~57 ~10 ~28 ~57 ~10 double_stone_slab 0
fill ~22 ~57 ~11 ~28 ~57 ~11 stone_slab 8
fill ~22 ~57 ~37 ~28 ~57 ~37 stone_slab 8
fill ~22 ~57 ~38 ~28 ~57 ~38 double_stone_slab 0
fill ~29 ~57 ~10 ~31 ~57 ~10 stone_slab 0
fill ~29 ~57 ~11 ~31 ~57 ~11 double_stone_slab 0
fill ~29 ~57 ~12 ~30 ~57 ~12 stone_slab 8
fill ~29 ~57 ~36 ~30 ~57 ~36 stone_slab 8
fill ~29 ~57 ~37 ~31 ~57 ~37 double_stone_slab 0
fill ~29 ~57 ~38 ~31 ~57 ~38 stone_slab 0
fill ~31 ~57 ~12 ~32 ~57 ~12 double_stone_slab 0
fill ~31 ~57 ~13 ~32 ~57 ~13 stone_slab 8
fill ~31 ~57 ~35 ~32 ~57 ~35 stone_slab 8
fill ~31 ~57 ~36 ~32 ~57 ~36 double_stone_slab 0
fill ~32 ~57 ~11 ~33 ~57 ~11 stone_slab 0
fill ~32 ~57 ~37 ~33 ~57 ~37 stone_slab 0
fill ~33 ~57 ~12 ~34 ~57 ~12 stone_slab 0
fill ~33 ~57 ~13 ~34 ~57 ~13 double_stone_slab 0
setblock ~33 ~57 ~14 stone_slab 8
setblock ~33 ~57 ~34 stone_slab 8
fill ~33 ~57 ~35 ~34 ~57 ~35 double_stone_slab 0
fill ~33 ~57 ~36 ~34 ~57 ~36 stone_slab 0
fill ~34 ~57 ~14 ~35 ~57 ~14 double_stone_slab 0
setblock ~34 ~57 ~15 stone_slab 8
setblock ~34 ~57 ~33 stone_slab 8
fill ~34 ~57 ~34 ~35 ~57 ~34 double_stone_slab 0
fill ~35 ~57 ~13 ~36 ~57 ~13 stone_slab 0
fill ~35 ~57 ~15 ~36 ~57 ~15 double_stone_slab 0
setblock ~35 ~57 ~16 stone_slab 8
setblock ~35 ~57 ~32 stone_slab 8
fill ~35 ~57 ~33 ~36 ~57 ~33 double_stone_slab 0
fill ~35 ~57 ~35 ~36 ~57 ~35 stone_slab 0
setblock ~36 ~57 ~14 stone_slab 0
setblock ~36 ~57 ~16 double_stone_slab 0
fill ~36 ~57 ~17 ~36 ~57 ~18 stone_slab 8
fill ~36 ~57 ~30 ~36 ~57 ~31 stone_slab 8
setblock ~36 ~57 ~32 double_stone_slab 0
setblock ~36 ~57 ~34 stone_slab 0
fill ~37 ~57 ~15 ~37 ~57 ~16 stone_slab 0
fill ~37 ~57 ~17 ~37 ~57 ~18 double_stone_slab 0
fill ~37 ~57 ~19 ~37 ~57 ~20 stone_slab 8
fill ~37 ~57 ~28 ~37 ~57 ~29 stone_slab 8
fill ~37 ~57 ~30 ~38 ~57 ~30 double_stone_slab 0
fill ~37 ~57 ~31 ~37 ~57 ~30 double_stone_slab 0
fill ~37 ~57 ~32 ~38 ~57 ~32 stone_slab 0
fill ~37 ~57 ~33 ~37 ~57 ~32 stone_slab 0
fill ~38 ~57 ~16 ~38 ~57 ~17 stone_slab 0
fill ~38 ~57 ~18 ~38 ~57 ~20 double_stone_slab 0
fill ~38 ~57 ~21 ~38 ~57 ~27 stone_slab 8
fill ~38 ~57 ~28 ~38 ~57 ~30 double_stone_slab 0
setblock ~38 ~57 ~31 stone_slab 0
fill ~39 ~57 ~18 ~39 ~57 ~20 stone_slab 0
fill ~39 ~57 ~21 ~39 ~57 ~27 double_stone_slab 0
fill ~39 ~57 ~28 ~40 ~57 ~28 stone_slab 0
fill ~39 ~57 ~29 ~39 ~57 ~30 stone_slab 0
fill ~40 ~57 ~20 ~40 ~57 ~28 stone_slab 0
fill ~12 ~58 ~21 ~14 ~58 ~21 stone_slab 0
fill ~12 ~58 ~22 ~13 ~58 ~22 stone_slab 0
fill ~12 ~58 ~23 ~13 ~58 ~23 stone_slab 0
fill ~12 ~58 ~24 ~13 ~58 ~24 stone_slab 0
fill ~12 ~58 ~25 ~13 ~58 ~25 stone_slab 0
fill ~12 ~58 ~26 ~13 ~58 ~26 stone_slab 0
fill ~12 ~58 ~27 ~14 ~58 ~27 stone_slab 0
fill ~13 ~58 ~18 ~15 ~58 ~18 stone_slab 0
fill ~13 ~58 ~19 ~14 ~58 ~19 stone_slab 0
fill ~13 ~58 ~20 ~14 ~58 ~20 stone_slab 0
fill ~13 ~58 ~28 ~14 ~58 ~28 stone_slab 0
fill ~13 ~58 ~29 ~14 ~58 ~29 stone_slab 0
fill ~13 ~58 ~30 ~15 ~58 ~30 stone_slab 0
fill ~14 ~58 ~17 ~15 ~58 ~17 stone_slab 0
fill ~14 ~58 ~22 ~14 ~58 ~26 double_stone_slab 0
fill ~14 ~58 ~31 ~15 ~58 ~31 stone_slab 0
fill ~15 ~58 ~15 ~17 ~58 ~15 stone_slab 0
fill ~15 ~58 ~16 ~17 ~58 ~16 stone_slab 0
fill ~15 ~58 ~19 ~15 ~58 ~21 double_stone_slab 0
fill ~15 ~58 ~22 ~16 ~58 ~22 obsidian 0
fill ~15 ~58 ~23 ~16 ~58 ~23 obsidian 0
fill ~15 ~58 ~24 ~16 ~58 ~24 obsidian 0
fill ~15 ~58 ~25 ~16 ~58 ~25 obsidian 0
fill ~15 ~58 ~26 ~16 ~58 ~26 obsidian 0
fill ~15 ~58 ~27 ~15 ~58 ~29 double_stone_slab 0
fill ~15 ~58 ~32 ~17 ~58 ~32 stone_slab 0
fill ~15 ~58 ~33 ~17 ~58 ~33 stone_slab 0
fill ~16 ~58 ~14 ~19 ~58 ~14 stone_slab 0
fill ~16 ~58 ~17 ~17 ~58 ~17 double_stone_slab 0
fill ~16 ~58 ~18 ~16 ~58 ~17 double_stone_slab 0
fill ~16 ~58 ~19 ~18 ~58 ~19 obsidian 0
fill ~16 ~58 ~20 ~17 ~58 ~20 obsidian 0
fill ~16 ~58 ~21 ~17 ~58 ~21 obsidian 0
fill ~16 ~58 ~27 ~17 ~58 ~27 obsidian 0
fill ~16 ~58 ~28 ~17 ~58 ~28 obsidian 0
fill ~16 ~58 ~29 ~18 ~58 ~29 obsidian 0
fill ~16 ~58 ~30 ~16 ~58 ~31 double_stone_slab 0
fill ~16 ~58 ~34 ~19 ~58 ~34 stone_slab 0
fill ~17 ~58 ~18 ~19 ~58 ~18 obsidian 0
fill ~17 ~58 ~30 ~19 ~58 ~30 obsidian 0
setblock ~17 ~58 ~31 double_stone_slab 0
fill ~18 ~58 ~13 ~22 ~58 ~13 stone_slab 0
fill ~18 ~58 ~15 ~19 ~58 ~15 double_stone_slab 0
fill ~18 ~58 ~16 ~18 ~58 ~15 double_stone_slab 0
fill ~18 ~58 ~17 ~20 ~58 ~17 obsidian 0
fill ~18 ~58 ~31 ~20 ~58 ~31 obsidian 0
fill ~18 ~58 ~32 ~18 ~58 ~33 double_stone_slab 0
fill ~18 ~58 ~35 ~22 ~58 ~35 stone_slab 0
fill ~19 ~58 ~12 ~31 ~58 ~12 stone_slab 0
fill ~19 ~58 ~16 ~22 ~58 ~16 obsidian 0
fill ~19 ~58 ~32 ~22 ~58 ~32 obsidian 0
setblock ~19 ~58 ~33 double_stone_slab 0
fill ~19 ~58 ~36 ~31 ~58 ~36 stone_slab 0
fill ~20 ~58 ~14 ~22 ~58 ~14 double_stone_slab 0
fill ~20 ~58 ~15 ~30 ~58 ~15 obsidian 0
fill ~20 ~58 ~33 ~30 ~58 ~33 obsidian 0
fill ~20 ~58 ~34 ~22 ~58 ~34 double_stone_slab 0
fill ~22 ~58 ~11 ~28 ~58 ~11 stone_slab 0
fill ~22 ~58 ~37 ~28 ~58 ~37 stone_slab 0
fill ~23 ~58 ~13 ~27 ~58 ~13 double_stone_slab 0
fill ~23 ~58 ~14 ~27 ~58 ~14 obsidian 0
fill ~23 ~58 ~34 ~27 ~58 ~34 obsidian 0
fill ~23 ~58 ~35 ~27 ~58 ~35 double_stone_slab 0
fill ~28 ~58 ~13 ~32 ~58 ~13 stone_slab 0
fill ~28 ~58 ~14 ~30 ~58 ~14 double_stone_slab 0
fill ~28 ~58 ~16 ~31 ~58 ~16 obsidian 0
fill ~28 ~58 ~32 ~31 ~58 ~32 obsidian 0
fill ~28 ~58 ~34 ~30 ~58 ~34 double_stone_slab 0
fill ~28 ~58 ~35 ~32 ~58 ~35 stone_slab 0
fill ~30 ~58 ~17 ~32 ~58 ~17 obsidian 0
fill ~30 ~58 ~31 ~32 ~58 ~31 obsidian 0
fill ~31 ~58 ~14 ~34 ~58 ~14 stone_slab 0
fill ~31 ~58 ~15 ~32 ~58 ~15 double_stone_slab 0
fill ~31 ~58 ~18 ~33 ~58 ~18 obsidian 0
fill ~31 ~58 ~30 ~33 ~58 ~30 obsidian 0
fill ~31 ~58 ~33 ~32 ~58 ~33 double_stone_slab 0
fill ~31 ~58 ~34 ~34 ~58 ~34 stone_slab 0
setblock ~32 ~58 ~16 double_stone_slab 0
fill ~32 ~58 ~19 ~34 ~58 ~19 obsidian 0
fill ~32 ~58 ~29 ~34 ~58 ~29 obsidian 0
setblock ~32 ~58 ~32 double_stone_slab 0
fill ~33 ~58 ~15 ~35 ~58 ~15 stone_slab 0
fill ~33 ~58 ~16 ~35 ~58 ~16 stone_slab 0
fill ~33 ~58 ~17 ~34 ~58 ~17 double_stone_slab 0
fill ~33 ~58 ~20 ~34 ~58 ~20 obsidian 0
fill ~33 ~58 ~21 ~34 ~58 ~21 obsidian 0
fill ~33 ~58 ~27 ~34 ~58 ~27 obsidian 0
fill ~33 ~58 ~28 ~34 ~58 ~28 obsidian 0
fill ~33 ~58 ~31 ~34 ~58 ~31 double_stone_slab 0
fill ~33 ~58 ~32 ~35 ~58 ~32 stone_slab 0
fill ~33 ~58 ~33 ~35 ~58 ~33 stone_slab 0
setblock ~34 ~58 ~18 double_stone_slab 0
fill ~34 ~58 ~22 ~35 ~58 ~22 obsidian 0
fill ~34 ~58 ~23 ~35 ~58 ~23 obsidian 0
fill ~34 ~58 ~24 ~35 ~58 ~24 obsidian 0
fill ~34 ~58 ~25 ~35 ~58 ~25 obsidian 0
fill ~34 ~58 ~26 ~35 ~58 ~26 obsidian 0
setblock ~34 ~58 ~30 double_stone_slab 0
fill ~35 ~58 ~17 ~36 ~58 ~17 stone_slab 0
fill ~35 ~58 ~18 ~37 ~58 ~18 stone_slab 0
fill ~35 ~58 ~19 ~35 ~58 ~21 double_stone_slab 0
fill ~35 ~58 ~27 ~35 ~58 ~29 double_stone_slab 0
fill ~35 ~58 ~30 ~37 ~58 ~30 stone_slab 0
fill ~35 ~58 ~31 ~36 ~58 ~31 stone_slab 0
fill ~36 ~58 ~19 ~37 ~58 ~19 stone_slab 0
fill ~36 ~58 ~20 ~37 ~58 ~20 stone_slab 0
fill ~36 ~58 ~21 ~38 ~58 ~21 stone_slab 0
fill ~36 ~58 ~22 ~36 ~58 ~26 double_stone_slab 0
fill ~36 ~58 ~27 ~38 ~58 ~27 stone_slab 0
fill ~36 ~58 ~28 ~37 ~58 ~28 stone_slab 0
fill ~36 ~58 ~29 ~37 ~58 ~29 stone_slab 0
fill ~37 ~58 ~22 ~38 ~58 ~22 stone_slab 0
fill ~37 ~58 ~23 ~38 ~58 ~23 stone_slab 0
fill ~37 ~58 ~24 ~38 ~58 ~24 stone_slab 0
fill ~37 ~58 ~25 ~38 ~58 ~25 stone_slab 0
fill ~37 ~58 ~26 ~38 ~58 ~26 stone_slab 0
fill ~16 ~59 ~21 ~19 ~59 ~21 stonebrick 3
fill ~16 ~59 ~22 ~18 ~59 ~22 stonebrick 3
fill ~16 ~59 ~23 ~18 ~59 ~23 stonebrick 3
fill ~16 ~59 ~24 ~18 ~59 ~24 stonebrick 3
fill ~16 ~59 ~25 ~18 ~59 ~25 stonebrick 3
fill ~16 ~59 ~26 ~18 ~59 ~26 stonebrick 3
fill ~16 ~59 ~27 ~19 ~59 ~27 stonebrick 3
fill ~17 ~59 ~19 ~21 ~59 ~19 stonebrick 3
fill ~17 ~59 ~20 ~20 ~59 ~20 stonebrick 3
fill ~17 ~59 ~28 ~20 ~59 ~28 stonebrick 3
fill ~17 ~59 ~29 ~21 ~59 ~29 stonebrick 3
fill ~18 ~59 ~18 ~22 ~59 ~18 stonebrick 3
fill ~18 ~59 ~30 ~22 ~59 ~30 stonebrick 3
fill ~19 ~59 ~17 ~31 ~59 ~17 stonebrick 3
fill ~19 ~59 ~22 ~19 ~59 ~26 obsidian 0
fill ~19 ~59 ~31 ~31 ~59 ~31 stonebrick 3
fill ~20 ~59 ~16 ~30 ~59 ~16 stonebrick 3
setblock ~20 ~59 ~21 obsidian 0
fill ~20 ~59 ~23 ~31 ~59 ~23 obsidian 0
fill ~20 ~59 ~24 ~31 ~59 ~24 obsidian 0
fill ~20 ~59 ~25 ~31 ~59 ~25 obsidian 0
setblock ~20 ~59 ~27 obsidian 0
fill ~20 ~59 ~32 ~30 ~59 ~32 stonebrick 3
setblock ~21 ~59 ~20 obsidian 0
setblock ~21 ~59 ~28 obsidian 0
fill ~22 ~59 ~15 ~28 ~59 ~15 stonebrick 3
setblock ~22 ~59 ~19 obsidian 0
fill ~22 ~59 ~21 ~28 ~59 ~21 obsidian 0
fill ~22 ~59 ~22 ~28 ~59 ~22 obsidian 0
fill ~22 ~59 ~26 ~28 ~59 ~26 obsidian 0
fill ~22 ~59 ~27 ~28 ~59 ~27 obsidian 0
setblock ~22 ~59 ~29 obsidian 0
fill ~22 ~59 ~33 ~28 ~59 ~33 stonebrick 3
fill ~23 ~59 ~18 ~27 ~59 ~18 obsidian 0
fill ~23 ~59 ~30 ~27 ~59 ~30 obsidian 0
fill ~24 ~59 ~19 ~26 ~59 ~19 obsidian 0
fill ~24 ~59 ~20 ~26 ~59 ~20 obsidian 0
fill ~24 ~59 ~28 ~26 ~59 ~28 obsidian 0
fill ~24 ~59 ~29 ~26 ~59 ~29 obsidian 0
fill ~28 ~59 ~18 ~32 ~59 ~18 stonebrick 3
setblock ~28 ~59 ~19 obsidian 0
setblock ~28 ~59 ~29 obsidian 0
fill ~28 ~59 ~30 ~32 ~59 ~30 stonebrick 3
fill ~29 ~59 ~19 ~33 ~59 ~19 stonebrick 3
setblock ~29 ~59 ~20 obsidian 0
setblock ~29 ~59 ~28 obsidian 0
fill ~29 ~59 ~29 ~33 ~59 ~29 stonebrick 3
fill ~30 ~59 ~20 ~33 ~59 ~20 stonebrick 3
setblock ~30 ~59 ~21 obsidian 0
setblock ~30 ~59 ~27 obsidian 0
fill ~30 ~59 ~28 ~33 ~59 ~28 stonebrick 3
fill ~31 ~59 ~21 ~34 ~59 ~21 stonebrick 3
setblock ~31 ~59 ~22 obsidian 0
setblock ~31 ~59 ~26 obsidian 0
fill ~31 ~59 ~27 ~34 ~59 ~27 stonebrick 3
fill ~32 ~59 ~22 ~34 ~59 ~22 stonebrick 3
fill ~32 ~59 ~23 ~34 ~59 ~23 stonebrick 3
fill ~32 ~59 ~24 ~34 ~59 ~24 stonebrick 3
fill ~32 ~59 ~25 ~34 ~59 ~25 stonebrick 3
fill ~32 ~59 ~26 ~34 ~59 ~26 stonebrick 3
fill ~20 ~60 ~22 ~21 ~60 ~22 bedrock 0
fill ~20 ~60 ~23 ~20 ~60 ~26 bedrock 0
fill ~21 ~60 ~20 ~23 ~60 ~20 bedrock 0
fill ~21 ~60 ~21 ~21 ~60 ~20 bedrock 0
fill ~21 ~60 ~26 ~21 ~60 ~28 bedrock 0
fill ~22 ~60 ~28 ~23 ~60 ~28 bedrock 0
fill ~23 ~60 ~19 ~27 ~60 ~19 bedrock 0
fill ~23 ~60 ~29 ~27 ~60 ~29 bedrock 0
fill ~27 ~60 ~20 ~29 ~60 ~20 bedrock 0
fill ~27 ~60 ~28 ~29 ~60 ~28 bedrock 0
fill ~29 ~60 ~21 ~29 ~60 ~22 bedrock 0
fill ~29 ~60 ~26 ~30 ~60 ~26 bedrock 0
fill ~29 ~60 ~27 ~29 ~60 ~26 bedrock 0
fill ~30 ~60 ~22 ~30 ~60 ~26 bedrock 0
fill ~20 ~61 ~22 ~21 ~61 ~22 glass 0
fill ~20 ~61 ~23 ~20 ~61 ~26 glass 0
fill ~21 ~61 ~20 ~23 ~61 ~20 glass 0
fill ~21 ~61 ~21 ~21 ~61 ~20 glass 0
fill ~21 ~61 ~26 ~21 ~62 ~26 glass 0
fill ~21 ~61 ~27 ~21 ~61 ~28 glass 0
fill ~22 ~61 ~28 ~23 ~61 ~28 glass 0
fill ~23 ~61 ~19 ~27 ~61 ~19 glass 0
fill ~23 ~61 ~29 ~27 ~61 ~29 glass 0
fill ~27 ~61 ~20 ~29 ~61 ~20 glass 0
fill ~27 ~61 ~28 ~29 ~61 ~28 glass 0
fill ~29 ~61 ~21 ~29 ~61 ~22 glass 0
fill ~29 ~61 ~26 ~30 ~61 ~26 glass 0
fill ~29 ~61 ~27 ~29 ~61 ~26 glass 0
fill ~30 ~61 ~22 ~30 ~61 ~26 glass 0
fill ~21 ~62 ~22 ~22 ~62 ~22 glass 0
fill ~21 ~62 ~23 ~21 ~62 ~26 glass 0
fill ~22 ~62 ~21 ~23 ~62 ~21 glass 0
fill ~22 ~62 ~26 ~22 ~62 ~27 glass 0
fill ~23 ~62 ~20 ~27 ~62 ~20 glass 0
fill ~23 ~62 ~27 ~23 ~62 ~28 glass 0
fill ~24 ~62 ~28 ~27 ~62 ~28 glass 0
fill ~27 ~62 ~21 ~28 ~62 ~21 glass 0
fill ~27 ~62 ~27 ~28 ~62 ~27 glass 0
fill ~28 ~62 ~22 ~29 ~62 ~22 glass 0
fill ~28 ~62 ~26 ~29 ~62 ~26 glass 0
fill ~29 ~62 ~23 ~29 ~62 ~26 glass 0
fill ~22 ~63 ~23 ~28 ~63 ~23 glass 0
fill ~22 ~63 ~24 ~28 ~63 ~24 glass 0
fill ~22 ~63 ~25 ~28 ~63 ~25 glass 0
fill ~23 ~63 ~22 ~27 ~63 ~22 glass 0
fill ~23 ~63 ~26 ~27 ~63 ~26 glass 0
fill ~24 ~63 ~21 ~26 ~63 ~21 glass 0
fill ~24 ~63 ~27 ~26 ~63 ~27 glass 0