fill ~34 ~0 ~80 ~35 ~0 ~80 coal_block
fill ~35 ~0 ~81 ~38 ~0 ~81 coal_block
setblock ~39 ~0 ~81 concrete 7
fill ~40 ~0 ~81 ~42 ~0 ~81 coal_block
setblock ~43 ~0 ~81 concrete 7
fill ~44 ~0 ~81 ~47 ~0 ~81 coal_ore
fill ~48 ~0 ~80 ~49 ~0 ~80 coal_ore
fill ~49 ~0 ~79 ~50 ~0 ~79 coal_block
setblock ~50 ~0 ~80 cyan_glazed_terracotta
setblock ~51 ~0 ~79 wool 15
fill ~51 ~0 ~80 ~52 ~0 ~80 concrete 7
setblock ~52 ~0 ~79 stone
fill ~53 ~0 ~79 ~54 ~0 ~79 coal_ore
setblock ~55 ~0 ~79 concrete 7
fill ~2 ~1 ~35 ~3 ~1 ~35 concrete 15
fill ~2 ~1 ~36 ~3 ~1 ~36 coal_block
setblock ~2 ~1 ~37 wool 15
fill ~2 ~1 ~38 ~2 ~3 ~38 coal_block
fill ~2 ~1 ~39 ~2 ~3 ~39 coal_block
fill ~3 ~1 ~31 ~5 ~1 ~31 concrete 15
fill ~3 ~1 ~32 ~3 ~1 ~35 concrete 15
fill ~3 ~1 ~37 ~3 ~6 ~37 coal_block
setblock ~3 ~1 ~38 concrete 7
setblock ~3 ~1 ~39 coal_ore
fill ~4 ~1 ~28 ~4 ~2 ~28 concrete 15
fill ~4 ~1 ~29 ~5 ~1 ~29 coal_block
fill ~4 ~1 ~30 ~5 ~1 ~30 coal_block
fill ~4 ~1 ~32 ~4 ~5 ~32 coal_block
fill ~4 ~1 ~33 ~4 ~9 ~33 coal_block
fill ~4 ~1 ~34 ~4 ~4 ~34 coal_block
fill ~4 ~1 ~35 ~4 ~9 ~35 coal_block
fill ~5 ~1 ~26 ~7 ~1 ~26 coal_block
fill ~5 ~1 ~27 ~6 ~1 ~27 coal_block
fill ~5 ~1 ~28 ~6 ~1 ~28 coal_block
fill ~6 ~1 ~23 ~8 ~1 ~23 coal_block
fill ~6 ~1 ~24 ~7 ~1 ~24 coal_block
fill ~6 ~1 ~25 ~7 ~1 ~25 coal_block
fill ~7 ~1 ~21 ~9 ~1 ~21 coal_block
fill ~7 ~1 ~22 ~8 ~1 ~22 coal_block
fill ~8 ~1 ~20 ~8 ~7 ~20 coal_block
fill ~9 ~1 ~19 ~11 ~1 ~19 coal_block
fill ~10 ~1 ~17 ~10 ~4 ~17 coal_block
fill ~10 ~1 ~18 ~11 ~1 ~18 coal_block
fill ~10 ~1 ~20 ~10 ~2 ~20 coal_block
fill ~11 ~1 ~16 ~11 ~16 ~16 coal_block
fill ~12 ~1 ~15 ~12 ~21 ~15 coal_block
fill ~12 ~1 ~17 ~12 ~9 ~17 coal_block
fill ~13 ~1 ~14 ~13 ~17 ~14 coal_block
fill ~13 ~1 ~16 ~13 ~12 ~16 coal_block
fill ~14 ~1 ~13 ~14 ~13 ~13 coal_block
fill ~14 ~1 ~15 ~14 ~2 ~15 coal_block
fill ~15 ~1 ~12 ~15 ~10 ~12 coal_block
fill ~15 ~1 ~14 ~15 ~10 ~14 coal_block
fill ~16 ~1 ~11 ~16 ~10 ~11 coal_block
fill ~16 ~1 ~13 ~16 ~4 ~13 coal_block
fill ~17 ~1 ~10 ~20 ~1 ~10 coal_block
fill ~17 ~1 ~12 ~17 ~8 ~12 coal_block
fill ~18 ~1 ~11 ~18 ~32 ~11 coal_block
fill ~19 ~1 ~9 ~19 ~2 ~9 coal_block
setblock ~20 ~1 ~9 concrete 7
setblock ~24 ~1 ~76 wool 15
setblock ~24 ~1 ~77 concrete 7
setblock ~25 ~1 ~76 concrete 7
fill ~25 ~1 ~77 ~28 ~1 ~77 coal_block
fill ~25 ~1 ~78 ~31 ~1 ~78 coal_block
fill ~28 ~1 ~79 ~32 ~1 ~79 coal_block
fill ~31 ~1 ~80 ~39 ~1 ~80 coal_block
setblock ~33 ~1 ~79 wool 15
setblock ~34 ~1 ~79 concrete 7
setblock ~35 ~1 ~79 stone
fill ~35 ~1 ~81 ~45 ~1 ~81 coal_block
setblock ~40 ~1 ~80 stone
fill ~41 ~1 ~80 ~46 ~1 ~80 coal_block
fill ~46 ~1 ~81 ~47 ~1 ~81 concrete 7
setblock ~47 ~1 ~80 stone
fill ~48 ~1 ~79 ~51 ~1 ~79 coal_block
fill ~48 ~1 ~80 ~52 ~1 ~80 coal_block
fill ~52 ~1 ~78 ~56 ~1 ~78 coal_block
fill ~53 ~1 ~79 ~55 ~1 ~79 coal_block
fill ~55 ~1 ~77 ~57 ~1 ~77 coal_block
setblock ~57 ~1 ~78 wool 15
fill ~58 ~1 ~76 ~58 ~1 ~77 concrete 7
fill ~58 ~1 ~78 ~58 ~12 ~78 coal_block
setblock ~59 ~1 ~76 coal_ore
setblock ~59 ~1 ~77 concrete 7
setblock ~63 ~1 ~9 concrete 7
fill ~63 ~1 ~10 ~66 ~1 ~10 coal_block
fill ~64 ~1 ~9 ~65 ~1 ~9 coal_block
fill ~65 ~1 ~11 ~65 ~14 ~11 coal_block
setblock ~66 ~1 ~12 concrete 15
fill ~67 ~1 ~11 ~67 ~7 ~11 coal_block
fill ~67 ~1 ~13 ~67 ~2 ~13 concrete 15
fill ~68 ~1 ~12 ~68 ~14 ~12 coal_block
fill ~68 ~1 ~14 ~68 ~10 ~14 coal_block
fill ~69 ~1 ~13 ~69 ~4 ~13 coal_block
fill ~69 ~1 ~15 ~69 ~4 ~15 coal_block
setblock ~70 ~1 ~14 coal_block
fill ~70 ~1 ~16 ~70 ~2 ~16 coal_block
setblock ~71 ~1 ~15 coal_block
fill ~71 ~1 ~17 ~71 ~2 ~17 coal_block
setblock ~72 ~1 ~16 coal_block
setblock ~72 ~1 ~18 concrete 15
setblock ~72 ~1 ~19 coal_block
fill ~73 ~1 ~17 ~73 ~1 ~18 coal_block
fill ~73 ~1 ~20 ~73 ~2 ~20 coal_block
fill ~74 ~1 ~19 ~74 ~20 ~19 coal_block
fill ~74 ~1 ~21 ~74 ~5 ~21 coal_block
fill ~75 ~1 ~20 ~75 ~6 ~20 coal_block
fill ~75 ~1 ~22 ~76 ~1 ~22 coal_block
fill ~75 ~1 ~23 ~77 ~1 ~23 coal_block
fill ~76 ~1 ~21 ~76 ~16 ~21 coal_block
fill ~76 ~1 ~24 ~76 ~2 ~24 coal_block
fill ~76 ~1 ~25 ~76 ~2 ~25 coal_block
setblock ~77 ~1 ~24 concrete 7
setblock ~77 ~1 ~25 wool 15
fill ~77 ~1 ~26 ~78 ~1 ~26 coal_block
fill ~77 ~1 ~27 ~78 ~1 ~27 coal_block
fill ~77 ~1 ~28 ~77 ~1 ~26 coal_block
fill ~78 ~1 ~29 ~78 ~2 ~29 concrete 15
fill ~78 ~1 ~30 ~78 ~1 ~31 coal_block
fill ~79 ~1 ~28 ~79 ~32 ~28 coal_block
fill ~79 ~1 ~29 ~79 ~12 ~29 coal_block
setblock ~79 ~1 ~30 concrete 7
fill ~79 ~1 ~32 ~79 ~4 ~32 coal_block
fill ~79 ~1 ~33 ~79 ~2 ~33 coal_block
fill ~79 ~1 ~34 ~79 ~2 ~34 coal_block
fill ~79 ~1 ~35 ~79 ~2 ~35 concrete 7
fill ~80 ~1 ~31 ~80 ~12 ~31 coal_block
setblock ~80 ~1 ~32 wool 15
fill ~80 ~1 ~33 ~80 ~1 ~34 concrete 7
fill ~80 ~1 ~35 ~81 ~1 ~35 coal_block
fill ~80 ~1 ~36 ~80 ~1 ~38 concrete 7
setblock ~80 ~1 ~39 wool 15
fill ~81 ~1 ~36 ~81 ~32 ~36 coal_block
fill ~81 ~1 ~37 ~81 ~1 ~39 concrete 7
fill ~2 ~2 ~35 ~2 ~32 ~35 coal_block
fill ~2 ~2 ~36 ~2 ~3 ~36 concrete 15
fill ~2 ~2 ~37 ~2 ~5 ~37 coal_block
fill ~2 ~2 ~40 ~2 ~3 ~40 concrete 7
fill ~3 ~2 ~31 ~4 ~2 ~31 coal_block
fill ~3 ~2 ~32 ~3 ~5 ~32 coal_block
fill ~3 ~2 ~33 ~3 ~2 ~35 concrete 15
fill ~3 ~2 ~36 ~3 ~3 ~36 coal_block
setblock ~3 ~2 ~38 stone
fill ~3 ~2 ~39 ~3 ~4 ~39 coal_block
setblock ~3 ~2 ~40 prismarine 2
fill ~4 ~2 ~29 ~5 ~2 ~29 coal_block
fill ~4 ~2 ~30 ~5 ~2 ~30 coal_block
fill ~5 ~2 ~26 ~5 ~19 ~26 coal_block
fill ~5 ~2 ~27 ~6 ~2 ~27 coal_block
fill ~5 ~2 ~28 ~6 ~2 ~28 coal_block
setblock ~5 ~2 ~31 stone
fill ~6 ~2 ~23 ~6 ~20 ~23 coal_block
fill ~6 ~2 ~24 ~7 ~2 ~24 coal_block
fill ~6 ~2 ~25 ~6 ~18 ~25 coal_block
setblock ~6 ~2 ~26 stone
fill ~7 ~2 ~21 ~7 ~32 ~21 coal_block
fill ~7 ~2 ~22 ~8 ~2 ~22 coal_block
setblock ~7 ~2 ~23 stone
setblock ~7 ~2 ~25 stone
fill ~7 ~2 ~26 ~7 ~6 ~26 coal_block
setblock ~8 ~2 ~21 stone
fill ~8 ~2 ~23 ~8 ~8 ~23 coal_block
fill ~9 ~2 ~19 ~9 ~7 ~19 coal_block
fill ~9 ~2 ~21 ~9 ~13 ~21 coal_block
fill ~10 ~2 ~18 ~11 ~2 ~18 coal_block
setblock ~10 ~2 ~19 stone
fill ~11 ~2 ~19 ~11 ~6 ~19 coal_block
fill ~17 ~2 ~10 ~18 ~2 ~10 coal_block
setblock ~19 ~2 ~10 stone
fill ~20 ~2 ~8 ~21 ~2 ~8 concrete 7
fill ~20 ~2 ~10 ~20 ~32 ~10 coal_block
setblock ~21 ~2 ~9 concrete 7
setblock ~23 ~2 ~75 coal_block
setblock ~23 ~2 ~76 concrete 7
fill ~23 ~2 ~77 ~24 ~2 ~77 coal_block
setblock ~24 ~2 ~75 coal_ore
setblock ~24 ~2 ~76 stone
fill ~25 ~2 ~76 ~25 ~32 ~76 coal_block
setblock ~25 ~2 ~77 stone
fill ~25 ~2 ~78 ~29 ~2 ~78 coal_block
fill ~26 ~2 ~77 ~28 ~2 ~77 coal_block
fill ~28 ~2 ~79 ~30 ~2 ~79 coal_block
setblock ~30 ~2 ~78 stone
setblock ~31 ~2 ~78 concrete 15
fill ~31 ~2 ~80 ~34 ~2 ~80 coal_block
fill ~32 ~2 ~79 ~35 ~2 ~79 coal_block
setblock ~35 ~2 ~80 stone
fill ~35 ~2 ~81 ~47 ~2 ~81 coal_block
fill ~36 ~2 ~80 ~43 ~2 ~80 coal_block
setblock ~44 ~2 ~80 stone
fill ~45 ~2 ~80 ~52 ~2 ~80 coal_block
fill ~48 ~2 ~79 ~49 ~2 ~79 coal_block
setblock ~50 ~2 ~79 stone
fill ~51 ~2 ~79 ~51 ~6 ~79 coal_block
fill ~52 ~2 ~78 ~54 ~2 ~78 coal_block
fill ~53 ~2 ~79 ~55 ~2 ~79 coal_block
fill ~55 ~2 ~77 ~57 ~2 ~77 coal_block
setblock ~55 ~2 ~78 stone
fill ~56 ~2 ~78 ~58 ~2 ~78 coal_block
fill ~58 ~2 ~76 ~58 ~3 ~76 concrete 15
setblock ~58 ~2 ~77 stone
setblock ~59 ~2 ~75 coal_block
setblock ~59 ~2 ~76 wool 15
fill ~59 ~2 ~77 ~59 ~14 ~77 coal_block
setblock ~60 ~2 ~75 concrete 7
setblock ~60 ~2 ~76 coal_ore
setblock ~62 ~2 ~8 concrete 7
fill ~62 ~2 ~9 ~62 ~5 ~9 coal_block
fill ~63 ~2 ~8 ~63 ~32 ~8 coal_block
fill ~63 ~2 ~10 ~64 ~2 ~10 coal_block
fill ~64 ~2 ~9 ~65 ~2 ~9 concrete 15
setblock ~65 ~2 ~10 stone
fill ~66 ~2 ~10 ~66 ~7 ~10 coal_block
fill ~66 ~2 ~12 ~66 ~14 ~12 coal_block
setblock ~70 ~2 ~14 concrete 15
fill ~71 ~2 ~15 ~71 ~5 ~15 concrete 15
fill ~72 ~2 ~16 ~72 ~3 ~16 concrete 15
fill ~72 ~2 ~18 ~72 ~4 ~18 coal_block
setblock ~72 ~2 ~19 concrete 15
fill ~73 ~2 ~17 ~73 ~3 ~17 concrete 15
fill ~73 ~2 ~18 ~73 ~2 ~17 concrete 15
fill ~75 ~2 ~22 ~76 ~2 ~22 coal_block
fill ~75 ~2 ~23 ~75 ~7 ~23 concrete 15
setblock ~76 ~2 ~23 stone
fill ~77 ~2 ~23 ~77 ~15 ~23 coal_block
fill ~77 ~2 ~24 ~77 ~19 ~24 coal_block
fill ~77 ~2 ~25 ~77 ~19 ~25 coal_block
fill ~77 ~2 ~26 ~77 ~3 ~26 concrete 15
fill ~77 ~2 ~27 ~77 ~5 ~27 concrete 15
fill ~77 ~2 ~28 ~77 ~2 ~26 concrete 15
fill ~78 ~2 ~26 ~78 ~20 ~26 coal_block
fill ~78 ~2 ~27 ~78 ~30 ~27 coal_block
fill ~78 ~2 ~30 ~78 ~3 ~30 concrete 15
fill ~78 ~2 ~31 ~78 ~7 ~31 coal_block
fill ~79 ~2 ~30 ~79 ~12 ~30 coal_block
fill ~80 ~2 ~32 ~80 ~3 ~32 concrete 7
setblock ~80 ~2 ~33 coal_block
setblock ~80 ~2 ~34 concrete 7
fill ~80 ~2 ~35 ~81 ~2 ~35 coal_block
fill ~80 ~2 ~36 ~80 ~3 ~36 coal_block
fill ~80 ~2 ~37 ~80 ~3 ~37 concrete 7
setblock ~80 ~2 ~38 stone
fill ~80 ~2 ~39 ~80 ~2 ~40 concrete 7
fill ~81 ~2 ~37 ~81 ~10 ~37 coal_block
fill ~81 ~2 ~38 ~81 ~9 ~38 coal_block
fill ~81 ~2 ~39 ~81 ~10 ~39 coal_block
fill ~81 ~2 ~40 ~81 ~3 ~40 coal_ore
fill ~2 ~3 ~41 ~2 ~4 ~41 concrete 7
fill ~3 ~3 ~31 ~3 ~5 ~31 coal_block
fill ~3 ~3 ~33 ~3 ~30 ~33 coal_block
fill ~3 ~3 ~34 ~3 ~30 ~34 coal_block
setblock ~3 ~3 ~35 stone
fill ~3 ~3 ~38 ~3 ~14 ~38 coal_block
setblock ~3 ~3 ~40 concrete 7
setblock ~3 ~3 ~41 coal_ore
fill ~4 ~3 ~28 ~4 ~6 ~28 coal_block
fill ~4 ~3 ~29 ~5 ~3 ~29 coal_block
fill ~4 ~3 ~30 ~5 ~3 ~30 coal_block
fill ~4 ~3 ~31 ~5 ~3 ~31 concrete 15
fill ~5 ~3 ~27 ~5 ~15 ~27 coal_block
setblock ~5 ~3 ~28 stone
fill ~6 ~3 ~24 ~7 ~3 ~24 coal_block
setblock ~6 ~3 ~26 coal_block
setblock ~6 ~3 ~27 concrete 15
setblock ~6 ~3 ~28 coal_block
fill ~7 ~3 ~22 ~8 ~3 ~22 coal_block
fill ~7 ~3 ~23 ~7 ~3 ~21 coal_block
fill ~7 ~3 ~25 ~7 ~10 ~25 coal_block
setblock ~8 ~3 ~21 coal_block
fill ~10 ~3 ~18 ~11 ~3 ~18 coal_block
fill ~10 ~3 ~19 ~10 ~3 ~17 coal_block
setblock ~10 ~3 ~20 stone
setblock ~14 ~3 ~15 stone
fill ~17 ~3 ~10 ~20 ~3 ~10 coal_block
setblock ~19 ~3 ~9 concrete 15
fill ~20 ~3 ~8 ~21 ~3 ~8 coal_block
setblock ~21 ~3 ~9 stone
setblock ~22 ~3 ~9 concrete 7
setblock ~23 ~3 ~75 concrete 7
fill ~23 ~3 ~76 ~25 ~3 ~76 coal_block
fill ~23 ~3 ~77 ~28 ~3 ~77 coal_block
fill ~25 ~3 ~78 ~27 ~3 ~78 coal_block
setblock ~28 ~3 ~78 stone
fill ~28 ~3 ~79 ~30 ~3 ~79 coal_block
fill ~29 ~3 ~78 ~31 ~3 ~78 coal_block
fill ~31 ~3 ~80 ~37 ~3 ~80 coal_block
setblock ~32 ~3 ~79 stone
fill ~33 ~3 ~79 ~35 ~3 ~79 coal_block
fill ~35 ~3 ~81 ~47 ~3 ~81 coal_block
setblock ~38 ~3 ~80 stone
fill ~39 ~3 ~80 ~52 ~3 ~80 coal_block
fill ~48 ~3 ~79 ~48 ~17 ~79 coal_block
setblock ~49 ~3 ~79 concrete 15
fill ~50 ~3 ~79 ~50 ~11 ~79 coal_block
fill ~52 ~3 ~78 ~58 ~3 ~78 coal_block
fill ~53 ~3 ~79 ~55 ~3 ~79 coal_block
setblock ~55 ~3 ~77 concrete 15
setblock ~56 ~3 ~77 stone
fill ~57 ~3 ~77 ~59 ~3 ~77 coal_block
setblock ~59 ~3 ~76 stone
fill ~60 ~3 ~75 ~60 ~14 ~75 coal_block
setblock ~60 ~3 ~76 concrete 7
fill ~61 ~3 ~9 ~61 ~14 ~9 coal_block
fill ~62 ~3 ~8 ~62 ~4 ~8 coal_block
fill ~63 ~3 ~10 ~63 ~8 ~10 coal_block
fill ~64 ~3 ~9 ~65 ~3 ~9 coal_block
setblock ~64 ~3 ~10 stone
setblock ~65 ~3 ~10 coal_block
fill ~67 ~3 ~13 ~67 ~4 ~13 coal_block
setblock ~70 ~3 ~14 coal_block
setblock ~70 ~3 ~16 stone
fill ~71 ~3 ~17 ~71 ~7 ~17 concrete 15
fill ~72 ~3 ~19 ~72 ~5 ~19 coal_block
setblock ~73 ~3 ~18 coal_block
setblock ~73 ~3 ~20 stone
fill ~75 ~3 ~22 ~76 ~3 ~22 coal_block
setblock ~76 ~3 ~23 coal_block
setblock ~76 ~3 ~24 stone
fill ~76 ~3 ~25 ~76 ~9 ~25 concrete 15
fill ~77 ~3 ~28 ~77 ~7 ~28 coal_block
setblock ~78 ~3 ~29 coal_block
setblock ~79 ~3 ~33 concrete 15
setblock ~79 ~3 ~34 stone
fill ~79 ~3 ~35 ~79 ~9 ~35 coal_block
setblock ~80 ~3 ~33 concrete 7
setblock ~80 ~3 ~34 wool 15
setblock ~80 ~3 ~35 stone
fill ~80 ~3 ~38 ~80 ~3 ~39 concrete 15
fill ~80 ~3 ~40 ~80 ~5 ~40 coal_block
fill ~80 ~3 ~41 ~80 ~6 ~41 coal_block
setblock ~81 ~3 ~35 coal_block
setblock ~81 ~3 ~41 coal_ore
setblock ~2 ~4 ~36 coal_block
fill ~2 ~4 ~38 ~2 ~4 ~39 concrete 15
fill ~2 ~4 ~40 ~3 ~4 ~40 coal_block
setblock ~3 ~4 ~35 coal_block
setblock ~3 ~4 ~36 stone
fill ~3 ~4 ~41 ~3 ~6 ~41 concrete 7
fill ~4 ~4 ~29 ~5 ~4 ~29 coal_block
fill ~4 ~4 ~30 ~5 ~4 ~30 coal_block
setblock ~4 ~4 ~31 stone
setblock ~5 ~4 ~28 coal_block
setblock ~5 ~4 ~31 coal_block
fill ~6 ~4 ~24 ~7 ~4 ~24 coal_block
setblock ~6 ~4 ~26 stone
fill ~6 ~4 ~27 ~6 ~9 ~27 coal_block
setblock ~6 ~4 ~28 stone
fill ~7 ~4 ~22 ~8 ~4 ~22 coal_block
setblock ~7 ~4 ~23 stone
setblock ~8 ~4 ~21 stone
fill ~10 ~4 ~18 ~10 ~7 ~18 coal_block
setblock ~10 ~4 ~19 stone
fill ~10 ~4 ~20 ~10 ~19 ~20 coal_block
setblock ~11 ~4 ~18 stone
fill ~14 ~4 ~15 ~14 ~6 ~15 coal_block
fill ~17 ~4 ~10 ~20 ~4 ~10 coal_block
fill ~19 ~4 ~9 ~19 ~7 ~9 coal_block
fill ~20 ~4 ~8 ~21 ~4 ~8 coal_block
fill ~21 ~4 ~9 ~22 ~4 ~9 coal_block
fill ~22 ~4 ~8 ~22 ~5 ~8 concrete 7
fill ~22 ~4 ~76 ~22 ~23 ~76 coal_block
fill ~23 ~4 ~75 ~23 ~32 ~75 coal_block
setblock ~23 ~4 ~76 stone
fill ~23 ~4 ~77 ~24 ~4 ~77 coal_block
fill ~24 ~4 ~76 ~24 ~5 ~76 coal_block
setblock ~25 ~4 ~77 stone
fill ~25 ~4 ~78 ~31 ~4 ~78 coal_block
fill ~26 ~4 ~77 ~26 ~6 ~77 coal_block
setblock ~27 ~4 ~77 stone
fill ~28 ~4 ~77 ~28 ~32 ~77 coal_block
fill ~28 ~4 ~79 ~30 ~4 ~79 coal_block
fill ~31 ~4 ~80 ~34 ~4 ~80 coal_block
fill ~32 ~4 ~79 ~35 ~4 ~79 coal_block
setblock ~35 ~4 ~80 stone
fill ~35 ~4 ~81 ~39 ~4 ~81 coal_block
fill ~36 ~4 ~80 ~40 ~4 ~80 coal_block
fill ~40 ~4 ~81 ~41 ~4 ~81 concrete 7
setblock ~41 ~4 ~80 stone
fill ~42 ~4 ~80 ~45 ~4 ~80 coal_block
fill ~42 ~4 ~81 ~46 ~4 ~81 coal_block
setblock ~46 ~4 ~80 stone
fill ~47 ~4 ~80 ~52 ~4 ~80 coal_block
setblock ~47 ~4 ~81 wool 15
setblock ~49 ~4 ~79 coal_block
fill ~52 ~4 ~78 ~52 ~7 ~78 coal_block
setblock ~53 ~4 ~78 stone
fill ~53 ~4 ~79 ~55 ~4 ~79 coal_block
fill ~54 ~4 ~78 ~54 ~6 ~78 coal_block
fill ~55 ~4 ~77 ~57 ~4 ~77 coal_block
setblock ~55 ~4 ~78 stone
fill ~56 ~4 ~78 ~58 ~4 ~78 coal_block
fill ~58 ~4 ~76 ~60 ~4 ~76 coal_block
setblock ~58 ~4 ~77 stone
fill ~61 ~4 ~8 ~61 ~6 ~8 coal_block
setblock ~61 ~4 ~76 concrete 7
fill ~64 ~4 ~9 ~65 ~4 ~9 coal_block
fill ~64 ~4 ~10 ~64 ~6 ~10 coal_block
setblock ~65 ~4 ~10 stone
setblock ~70 ~4 ~14 concrete 15
fill ~70 ~4 ~16 ~70 ~9 ~16 concrete 15
setblock ~72 ~4 ~16 coal_block
fill ~73 ~4 ~17 ~73 ~15 ~17 coal_block
setblock ~73 ~4 ~18 concrete 15
fill ~73 ~4 ~20 ~73 ~6 ~20 coal_block
fill ~75 ~4 ~22 ~76 ~4 ~22 coal_block
setblock ~76 ~4 ~23 stone
fill ~76 ~4 ~24 ~76 ~6 ~24 concrete 15
setblock ~77 ~4 ~26 stone
setblock ~78 ~4 ~29 stone
fill ~78 ~4 ~30 ~78 ~5 ~30 coal_block
fill ~79 ~4 ~33 ~80 ~4 ~33 coal_block
fill ~79 ~4 ~34 ~80 ~4 ~34 coal_block
fill ~80 ~4 ~32 ~80 ~5 ~32 coal_block
setblock ~80 ~4 ~35 coal_block
setblock ~80 ~4 ~36 stone
fill ~80 ~4 ~37 ~80 ~6 ~37 coal_block
fill ~80 ~4 ~38 ~80 ~14 ~38 coal_block
fill ~80 ~4 ~39 ~80 ~4 ~37 coal_block
setblock ~81 ~4 ~35 concrete 7
setblock ~81 ~4 ~40 coal_block
setblock ~81 ~4 ~41 concrete 7
setblock ~2 ~5 ~36 concrete 15
setblock ~2 ~5 ~38 coal_block
setblock ~2 ~5 ~39 concrete 15
fill ~2 ~5 ~40 ~3 ~5 ~40 coal_block
fill ~2 ~5 ~41 ~2 ~32 ~41 coal_block
setblock ~3 ~5 ~35 stone
fill ~3 ~5 ~36 ~3 ~17 ~36 coal_block
setblock ~3 ~5 ~39 stone
fill ~4 ~5 ~29 ~4 ~8 ~29 concrete 15
fill ~4 ~5 ~30 ~4 ~9 ~30 concrete 15
fill ~4 ~5 ~31 ~5 ~5 ~31 concrete 15
setblock ~4 ~5 ~34 stone
setblock ~5 ~5 ~28 stone
fill ~5 ~5 ~29 ~5 ~10 ~29 coal_block
fill ~5 ~5 ~30 ~5 ~5 ~29 coal_block
fill ~6 ~5 ~24 ~6 ~19 ~24 coal_block
setblock ~6 ~5 ~26 coal_block
fill ~6 ~5 ~28 ~6 ~9 ~28 coal_block
fill ~7 ~5 ~22 ~8 ~5 ~22 coal_block
fill ~7 ~5 ~23 ~7 ~6 ~23 coal_block
setblock ~7 ~5 ~24 stone
setblock ~8 ~5 ~21 coal_block
setblock ~10 ~5 ~17 wool 15
setblock ~10 ~5 ~19 coal_block
fill ~11 ~5 ~18 ~11 ~11 ~18 coal_block
setblock ~16 ~5 ~13 stone
fill ~17 ~5 ~10 ~20 ~5 ~10 coal_block
fill ~20 ~5 ~8 ~21 ~5 ~8 coal_block
fill ~21 ~5 ~7 ~22 ~5 ~7 coal_block
fill ~21 ~5 ~9 ~21 ~6 ~9 coal_block
setblock ~22 ~5 ~9 wool 15
setblock ~22 ~5 ~75 concrete 15
fill ~23 ~5 ~76 ~23 ~6 ~76 coal_block
fill ~23 ~5 ~77 ~28 ~5 ~77 coal_block
fill ~25 ~5 ~78 ~27 ~5 ~78 coal_block
setblock ~28 ~5 ~78 stone
fill ~28 ~5 ~79 ~30 ~5 ~79 coal_block
fill ~29 ~5 ~78 ~31 ~5 ~78 coal_block
fill ~31 ~5 ~80 ~52 ~5 ~80 coal_block
fill ~32 ~5 ~79 ~33 ~5 ~79 coal_block
setblock ~34 ~5 ~79 stone
fill ~35 ~5 ~79 ~35 ~18 ~79 coal_block
fill ~35 ~5 ~81 ~39 ~5 ~81 coal_block
fill ~40 ~5 ~81 ~41 ~5 ~81 concrete 7
fill ~42 ~5 ~81 ~47 ~5 ~81 coal_block
setblock ~49 ~5 ~79 stone
fill ~53 ~5 ~78 ~53 ~7 ~78 coal_block
fill ~53 ~5 ~79 ~55 ~5 ~79 coal_block
fill ~55 ~5 ~77 ~59 ~5 ~77 coal_block
fill ~55 ~5 ~78 ~58 ~5 ~78 coal_block
fill ~58 ~5 ~76 ~61 ~5 ~76 coal_block
fill ~61 ~5 ~7 ~62 ~5 ~7 coal_block
setblock ~61 ~5 ~75 concrete 7
setblock ~62 ~5 ~8 stone
fill ~64 ~5 ~9 ~65 ~5 ~9 coal_block
setblock ~65 ~5 ~10 coal_block
setblock ~67 ~5 ~13 stone
fill ~69 ~5 ~13 ~69 ~7 ~13 concrete 15
setblock ~69 ~5 ~15 concrete 15
setblock ~70 ~5 ~14 coal_block
setblock ~72 ~5 ~16 concrete 15
setblock ~72 ~5 ~18 concrete 15
fill ~73 ~5 ~18 ~73 ~19 ~18 coal_block
setblock ~75 ~5 ~22 stone
fill ~76 ~5 ~22 ~76 ~32 ~22 coal_block
fill ~76 ~5 ~23 ~76 ~5 ~21 coal_block
fill ~77 ~5 ~26 ~77 ~6 ~26 concrete 15
fill ~78 ~5 ~29 ~78 ~7 ~29 coal_block
setblock ~79 ~5 ~32 stone
fill ~79 ~5 ~33 ~80 ~5 ~33 coal_block
fill ~79 ~5 ~34 ~80 ~5 ~34 coal_block
setblock ~80 ~5 ~35 stone
fill ~80 ~5 ~36 ~80 ~8 ~36 coal_block
setblock ~80 ~5 ~39 stone
fill ~81 ~5 ~35 ~81 ~32 ~35 coal_block
setblock ~81 ~5 ~40 wool 15
fill ~81 ~5 ~41 ~81 ~6 ~41 coal_ore
setblock ~2 ~6 ~36 coal_block
fill ~2 ~6 ~37 ~2 ~7 ~37 concrete 15
fill ~2 ~6 ~38 ~2 ~7 ~38 concrete 15
fill ~2 ~6 ~39 ~3 ~6 ~39 coal_block
fill ~2 ~6 ~40 ~2 ~7 ~40 concrete 15
fill ~3 ~6 ~31 ~3 ~7 ~31 concrete 15
fill ~3 ~6 ~32 ~4 ~6 ~32 concrete 15
setblock ~3 ~6 ~35 coal_block
fill ~3 ~6 ~40 ~3 ~12 ~40 coal_block
setblock ~4 ~6 ~31 stone
setblock ~4 ~6 ~34 concrete 15
setblock ~5 ~6 ~28 coal_block
fill ~5 ~6 ~30 ~5 ~6 ~31 concrete 15
setblock ~6 ~6 ~26 stone
fill ~7 ~6 ~22 ~8 ~6 ~22 coal_block
fill ~7 ~6 ~24 ~7 ~8 ~24 coal_block
setblock ~8 ~6 ~21 stone
fill ~10 ~6 ~17 ~10 ~7 ~17 coal_block
setblock ~10 ~6 ~19 stone
fill ~16 ~6 ~13 ~16 ~10 ~13 coal_block
fill ~17 ~6 ~10 ~17 ~9 ~10 coal_block
setblock ~18 ~6 ~10 concrete 15
setblock ~19 ~6 ~10 stone
fill ~20 ~6 ~8 ~20 ~13 ~8 coal_block
fill ~21 ~6 ~7 ~22 ~6 ~7 coal_block
setblock ~21 ~6 ~8 stone
setblock ~22 ~6 ~8 prismarine 2
fill ~22 ~6 ~9 ~22 ~32 ~9 coal_block
fill ~22 ~6 ~75 ~22 ~7 ~75 coal_block
fill ~23 ~6 ~77 ~24 ~6 ~77 coal_block
setblock ~24 ~6 ~76 stone
setblock ~25 ~6 ~77 stone
fill ~25 ~6 ~78 ~29 ~6 ~78 coal_block
fill ~27 ~6 ~77 ~27 ~18 ~77 coal_block
fill ~28 ~6 ~79 ~30 ~6 ~79 coal_block
setblock ~30 ~6 ~78 stone
fill ~31 ~6 ~78 ~31 ~24 ~78 coal_block
fill ~31 ~6 ~80 ~36 ~6 ~80 coal_block
fill ~32 ~6 ~79 ~35 ~6 ~79 coal_block
fill ~35 ~6 ~81 ~47 ~6 ~81 coal_block
setblock ~37 ~6 ~80 stone
fill ~38 ~6 ~80 ~43 ~6 ~80 coal_block
setblock ~44 ~6 ~80 stone
fill ~45 ~6 ~80 ~52 ~6 ~80 coal_block
fill ~49 ~6 ~79 ~49 ~8 ~79 coal_block
fill ~53 ~6 ~79 ~54 ~6 ~79 coal_block
fill ~55 ~6 ~77 ~55 ~7 ~77 concrete 15
setblock ~55 ~6 ~78 stone
setblock ~55 ~6 ~79 concrete 7
fill ~56 ~6 ~77 ~56 ~7 ~77 coal_block
fill ~56 ~6 ~78 ~58 ~6 ~78 coal_block
setblock ~57 ~6 ~77 stone
fill ~58 ~6 ~76 ~61 ~6 ~76 coal_block
fill ~58 ~6 ~77 ~58 ~6 ~76 coal_block
fill ~61 ~6 ~7 ~62 ~6 ~7 coal_block
fill ~61 ~6 ~75 ~61 ~7 ~75 coal_block
fill ~62 ~6 ~8 ~62 ~32 ~8 coal_block
setblock ~62 ~6 ~9 stone
fill ~64 ~6 ~9 ~65 ~6 ~9 concrete 15
setblock ~65 ~6 ~10 stone
fill ~67 ~6 ~13 ~67 ~8 ~13 coal_block
setblock ~69 ~6 ~15 coal_block
setblock ~70 ~6 ~14 concrete 15
fill ~71 ~6 ~15 ~71 ~12 ~15 coal_block
fill ~72 ~6 ~16 ~72 ~12 ~16 coal_block
setblock ~72 ~6 ~18 stone
setblock ~72 ~6 ~19 concrete 15
fill ~74 ~6 ~21 ~74 ~7 ~21 concrete 15
fill ~75 ~6 ~22 ~75 ~8 ~22 coal_block
setblock ~76 ~6 ~23 stone
setblock ~77 ~6 ~27 coal_block
setblock ~78 ~6 ~30 concrete 15
fill ~79 ~6 ~32 ~79 ~8 ~32 coal_block
fill ~79 ~6 ~33 ~80 ~6 ~33 coal_block
fill ~79 ~6 ~34 ~80 ~6 ~34 coal_block
setblock ~80 ~6 ~32 concrete 7
setblock ~80 ~6 ~35 coal_block
fill ~80 ~6 ~39 ~80 ~7 ~39 concrete 15
fill ~80 ~6 ~40 ~80 ~7 ~40 concrete 15
fill ~81 ~6 ~40 ~81 ~32 ~40 coal_block
setblock ~2 ~7 ~36 concrete 15
setblock ~2 ~7 ~39 concrete 15
fill ~2 ~7 ~42 ~2 ~17 ~42 coal_block
fill ~3 ~7 ~32 ~4 ~7 ~32 coal_block
setblock ~3 ~7 ~35 stone
setblock ~3 ~7 ~37 stone
fill ~3 ~7 ~39 ~3 ~9 ~39 coal_block
setblock ~3 ~7 ~41 stone
fill ~3 ~7 ~42 ~3 ~8 ~42 concrete 7
setblock ~4 ~7 ~28 concrete 15
setblock ~4 ~7 ~31 coal_block
fill ~4 ~7 ~34 ~4 ~8 ~34 coal_block
setblock ~5 ~7 ~28 stone
fill ~5 ~7 ~30 ~5 ~10 ~30 coal_block
setblock ~5 ~7 ~31 stone
setblock ~6 ~7 ~26 coal_block
fill ~7 ~7 ~22 ~7 ~18 ~22 coal_block
setblock ~7 ~7 ~23 stone
setblock ~7 ~7 ~26 stone
fill ~8 ~7 ~21 ~8 ~8 ~21 coal_block
setblock ~8 ~7 ~22 stone
fill ~10 ~7 ~19 ~10 ~8 ~19 coal_block
setblock ~11 ~7 ~19 stone
setblock ~14 ~7 ~15 stone
fill ~18 ~7 ~10 ~20 ~7 ~10 coal_block
fill ~21 ~7 ~8 ~21 ~32 ~8 coal_block
setblock ~21 ~7 ~9 stone
fill ~22 ~7 ~7 ~22 ~28 ~7 coal_block
fill ~23 ~7 ~8 ~23 ~10 ~8 concrete 7
setblock ~23 ~7 ~76 stone
fill ~23 ~7 ~77 ~25 ~7 ~77 coal_block
fill ~24 ~7 ~76 ~24 ~13 ~76 coal_block
fill ~25 ~7 ~78 ~27 ~7 ~78 coal_block
setblock ~26 ~7 ~77 stone
setblock ~28 ~7 ~78 stone
fill ~28 ~7 ~79 ~30 ~7 ~79 coal_block
fill ~29 ~7 ~78 ~31 ~7 ~78 coal_block
fill ~31 ~7 ~80 ~34 ~7 ~80 coal_block
setblock ~32 ~7 ~79 stone
fill ~33 ~7 ~79 ~35 ~7 ~79 coal_block
setblock ~35 ~7 ~80 stone
fill ~35 ~7 ~81 ~47 ~7 ~81 coal_block
fill ~36 ~7 ~80 ~39 ~7 ~80 coal_block
setblock ~40 ~7 ~80 stone
fill ~41 ~7 ~80 ~46 ~7 ~80 coal_block
setblock ~47 ~7 ~80 stone
fill ~48 ~7 ~80 ~52 ~7 ~80 coal_block
setblock ~51 ~7 ~79 stone
fill ~53 ~7 ~79 ~54 ~7 ~79 coal_block
setblock ~54 ~7 ~78 stone
setblock ~55 ~7 ~78 concrete 15
setblock ~55 ~7 ~79 wool 15
fill ~56 ~7 ~78 ~58 ~7 ~78 coal_block
fill ~57 ~7 ~77 ~57 ~8 ~77 concrete 15
fill ~58 ~7 ~76 ~58 ~16 ~76 coal_block
setblock ~58 ~7 ~77 stone
setblock ~59 ~7 ~76 stone
fill ~60 ~7 ~8 ~60 ~32 ~8 coal_block
fill ~60 ~7 ~76 ~61 ~7 ~76 coal_block
fill ~61 ~7 ~7 ~61 ~17 ~7 coal_block
fill ~62 ~7 ~9 ~62 ~9 ~9 coal_block
fill ~64 ~7 ~9 ~64 ~6 ~9 concrete 15
setblock ~64 ~7 ~10 stone
setblock ~65 ~7 ~9 coal_block
setblock ~65 ~7 ~10 concrete 15
setblock ~69 ~7 ~15 stone
fill ~70 ~7 ~14 ~70 ~13 ~14 coal_block
setblock ~72 ~7 ~18 concrete 15
fill ~72 ~7 ~19 ~72 ~11 ~19 coal_block
setblock ~73 ~7 ~20 stone
setblock ~75 ~7 ~20 wool 15
fill ~76 ~7 ~23 ~76 ~8 ~23 coal_block
setblock ~76 ~7 ~24 stone
setblock ~77 ~7 ~26 coal_block
setblock ~77 ~7 ~27 stone
setblock ~78 ~7 ~30 stone
fill ~79 ~7 ~33 ~79 ~4 ~33 coal_block
setblock ~79 ~7 ~34 stone
fill ~80 ~7 ~32 ~80 ~10 ~32 coal_block
setblock ~80 ~7 ~33 concrete 7
fill ~80 ~7 ~34 ~80 ~20 ~34 coal_block
setblock ~80 ~7 ~35 stone
setblock ~80 ~7 ~37 stone
setblock ~80 ~7 ~41 stone
setblock ~80 ~7 ~42 concrete 7
setblock ~81 ~7 ~41 concrete 7
setblock ~81 ~7 ~42 coal_ore
fill ~2 ~8 ~36 ~2 ~12 ~36 coal_block
fill ~2 ~8 ~37 ~2 ~21 ~37 coal_block
fill ~2 ~8 ~38 ~2 ~20 ~38 coal_block
fill ~2 ~8 ~39 ~2 ~32 ~39 coal_block
fill ~2 ~8 ~40 ~2 ~32 ~40 coal_block
fill ~3 ~8 ~31 ~3 ~8 ~36 coal_block
setblock ~3 ~8 ~37 concrete 15
fill ~3 ~8 ~41 ~3 ~11 ~41 coal_block
fill ~4 ~8 ~28 ~6 ~8 ~28 coal_block
setblock ~4 ~8 ~31 stone
fill ~4 ~8 ~32 ~4 ~10 ~32 coal_block
fill ~5 ~8 ~31 ~5 ~9 ~31 coal_block
setblock ~6 ~8 ~26 stone
setblock ~7 ~8 ~23 coal_block
fill ~7 ~8 ~26 ~7 ~9 ~26 coal_block
fill ~8 ~8 ~20 ~8 ~11 ~20 concrete 15
fill ~8 ~8 ~22 ~8 ~17 ~22 coal_block
fill ~9 ~8 ~19 ~9 ~11 ~19 concrete 15
fill ~10 ~8 ~17 ~10 ~8 ~18 concrete 15
fill ~11 ~8 ~19 ~11 ~11 ~19 coal_block
fill ~14 ~8 ~15 ~14 ~16 ~15 coal_block
setblock ~18 ~8 ~10 concrete 15
fill ~19 ~8 ~9 ~19 ~9 ~9 concrete 15
fill ~19 ~8 ~10 ~19 ~10 ~10 coal_block
fill ~21 ~8 ~9 ~21 ~13 ~9 coal_block
fill ~21 ~8 ~75 ~21 ~32 ~75 coal_block
setblock ~21 ~8 ~76 concrete 15
fill ~22 ~8 ~74 ~22 ~9 ~74 coal_block
setblock ~22 ~8 ~75 stone
fill ~23 ~8 ~76 ~23 ~9 ~76 coal_block
fill ~23 ~8 ~77 ~24 ~8 ~77 coal_block
setblock ~25 ~8 ~77 stone
fill ~25 ~8 ~78 ~31 ~8 ~78 coal_block
fill ~26 ~8 ~77 ~26 ~10 ~77 coal_block
fill ~28 ~8 ~79 ~30 ~8 ~79 coal_block
fill ~31 ~8 ~80 ~52 ~8 ~80 coal_block
fill ~32 ~8 ~79 ~35 ~8 ~79 coal_block
fill ~35 ~8 ~81 ~47 ~8 ~81 coal_block
setblock ~51 ~8 ~79 concrete 15
fill ~52 ~8 ~78 ~53 ~8 ~78 concrete 15
fill ~53 ~8 ~79 ~55 ~8 ~79 coal_block
fill ~54 ~8 ~78 ~58 ~8 ~78 coal_block
fill ~55 ~8 ~77 ~55 ~19 ~77 coal_block
setblock ~56 ~8 ~77 concrete 15
fill ~58 ~8 ~77 ~58 ~9 ~77 coal_block
fill ~59 ~8 ~76 ~62 ~8 ~76 coal_block
setblock ~61 ~8 ~8 stone
setblock ~61 ~8 ~74 concrete 7
setblock ~61 ~8 ~75 stone
fill ~62 ~8 ~75 ~62 ~11 ~75 concrete 7
fill ~64 ~8 ~9 ~64 ~8 ~10 coal_block
setblock ~65 ~8 ~9 concrete 15
setblock ~65 ~8 ~10 stone
fill ~66 ~8 ~10 ~66 ~9 ~10 concrete 15
fill ~67 ~8 ~11 ~67 ~10 ~11 concrete 15
fill ~69 ~8 ~13 ~69 ~13 ~13 coal_block
fill ~69 ~8 ~15 ~69 ~10 ~15 concrete 15
fill ~71 ~8 ~17 ~71 ~32 ~17 coal_block
fill ~72 ~8 ~18 ~72 ~9 ~18 coal_block
fill ~73 ~8 ~20 ~73 ~10 ~20 coal_block
fill ~74 ~8 ~21 ~74 ~10 ~21 coal_block
fill ~75 ~8 ~20 ~75 ~21 ~20 coal_block
fill ~75 ~8 ~23 ~75 ~18 ~23 coal_block
setblock ~76 ~8 ~24 concrete 15
fill ~77 ~8 ~26 ~77 ~10 ~26 concrete 15
fill ~77 ~8 ~27 ~77 ~10 ~27 concrete 15
fill ~77 ~8 ~28 ~77 ~11 ~28 concrete 15
fill ~78 ~8 ~29 ~78 ~10 ~29 concrete 15
fill ~78 ~8 ~30 ~78 ~10 ~30 concrete 15
fill ~78 ~8 ~31 ~78 ~10 ~31 concrete 15
fill ~79 ~8 ~33 ~79 ~8 ~34 concrete 15
fill ~80 ~8 ~33 ~80 ~20 ~33 coal_block
setblock ~80 ~8 ~35 coal_block
fill ~80 ~8 ~37 ~80 ~11 ~37 coal_block
fill ~80 ~8 ~39 ~80 ~9 ~39 coal_block
fill ~80 ~8 ~40 ~80 ~12 ~40 coal_block
fill ~80 ~8 ~41 ~81 ~8 ~41 coal_block
fill ~80 ~8 ~42 ~80 ~10 ~42 coal_block
setblock ~81 ~8 ~42 prismarine 2
setblock ~3 ~9 ~31 concrete 15
fill ~3 ~9 ~32 ~3 ~32 ~32 coal_block
setblock ~3 ~9 ~35 coal_block
fill ~3 ~9 ~37 ~3 ~11 ~37 coal_block
setblock ~3 ~9 ~42 wool 15
fill ~4 ~9 ~28 ~4 ~20 ~28 coal_block
fill ~4 ~9 ~29 ~4 ~14 ~29 coal_block
setblock ~4 ~9 ~31 coal_block
setblock ~4 ~9 ~34 stone
setblock ~5 ~9 ~28 stone
setblock ~6 ~9 ~26 coal_block
setblock ~7 ~9 ~23 stone
fill ~7 ~9 ~24 ~7 ~10 ~24 concrete 15
setblock ~8 ~9 ~21 stone
fill ~8 ~9 ~23 ~8 ~10 ~23 concrete 15
fill ~10 ~9 ~17 ~10 ~19 ~17 coal_block
fill ~10 ~9 ~18 ~10 ~9 ~17 coal_block
setblock ~10 ~9 ~19 stone
setblock ~17 ~9 ~12 stone
fill ~18 ~9 ~10 ~18 ~15 ~10 coal_block
setblock ~22 ~9 ~75 coal_block
fill ~23 ~9 ~7 ~23 ~10 ~7 concrete 7
fill ~23 ~9 ~77 ~28 ~9 ~77 coal_block
fill ~25 ~9 ~78 ~31 ~9 ~78 coal_block
fill ~28 ~9 ~79 ~30 ~9 ~79 coal_block
fill ~31 ~9 ~80 ~52 ~9 ~80 coal_block
fill ~32 ~9 ~79 ~35 ~9 ~79 coal_block
fill ~35 ~9 ~81 ~47 ~9 ~81 coal_block
setblock ~49 ~9 ~79 stone
setblock ~51 ~9 ~79 coal_block
fill ~52 ~9 ~78 ~53 ~9 ~78 concrete 15
fill ~53 ~9 ~79 ~55 ~9 ~79 coal_block
fill ~54 ~9 ~78 ~54 ~13 ~78 coal_block
setblock ~55 ~9 ~78 stone
fill ~56 ~9 ~77 ~59 ~9 ~77 coal_block
fill ~56 ~9 ~78 ~58 ~9 ~78 coal_block
fill ~59 ~9 ~76 ~61 ~9 ~76 coal_block
fill ~60 ~9 ~7 ~60 ~10 ~7 coal_block
setblock ~61 ~9 ~8 coal_block
fill ~61 ~9 ~74 ~61 ~10 ~74 coal_block
fill ~61 ~9 ~75 ~61 ~9 ~74 coal_block
setblock ~63 ~9 ~10 concrete 15
setblock ~64 ~9 ~9 concrete 15
fill ~64 ~9 ~10 ~65 ~9 ~10 coal_block
fill ~65 ~9 ~9 ~65 ~15 ~9 coal_block
setblock ~67 ~9 ~13 stone
fill ~75 ~9 ~22 ~75 ~10 ~22 concrete 15
setblock ~76 ~9 ~23 stone
fill ~76 ~9 ~24 ~76 ~13 ~24 coal_block
setblock ~79 ~9 ~32 stone
fill ~79 ~9 ~33 ~79 ~22 ~33 coal_block
fill ~79 ~9 ~34 ~79 ~10 ~34 coal_block
setblock ~80 ~9 ~35 stone
fill ~80 ~9 ~36 ~80 ~12 ~36 concrete 15
fill ~80 ~9 ~41 ~81 ~9 ~41 coal_block
setblock ~81 ~9 ~42 concrete 7
fill ~2 ~10 ~43 ~2 ~13 ~43 coal_block
fill ~3 ~10 ~31 ~3 ~22 ~31 coal_block
setblock ~3 ~10 ~35 stone
setblock ~3 ~10 ~39 stone
setblock ~3 ~10 ~42 concrete 7
setblock ~3 ~10 ~43 prismarine 2
fill ~4 ~10 ~30 ~4 ~18 ~30 coal_block
setblock ~4 ~10 ~31 stone
fill ~4 ~10 ~33 ~4 ~10 ~35 concrete 15
setblock ~5 ~10 ~28 coal_block
fill ~5 ~10 ~31 ~5 ~11 ~31 concrete 15
setblock ~6 ~10 ~26 stone
fill ~6 ~10 ~27 ~6 ~12 ~27 concrete 15
setblock ~6 ~10 ~28 stone
fill ~7 ~10 ~23 ~7 ~12 ~23 coal_block
fill ~7 ~10 ~26 ~7 ~12 ~26 concrete 15
setblock ~8 ~10 ~21 coal_block
setblock ~10 ~10 ~18 concrete 15
setblock ~10 ~10 ~19 coal_block
setblock ~12 ~10 ~17 concrete 15
setblock ~17 ~10 ~10 concrete 15
setblock ~17 ~10 ~12 coal_block
fill ~19 ~10 ~9 ~19 ~19 ~9 coal_block
fill ~21 ~10 ~74 ~21 ~13 ~74 coal_block
setblock ~22 ~10 ~74 concrete 15
setblock ~22 ~10 ~75 stone
setblock ~23 ~10 ~76 stone
fill ~23 ~10 ~77 ~24 ~10 ~77 coal_block
setblock ~25 ~10 ~77 stone
fill ~25 ~10 ~78 ~27 ~10 ~78 coal_block
setblock ~28 ~10 ~78 stone
fill ~28 ~10 ~79 ~30 ~10 ~79 coal_block
fill ~29 ~10 ~78 ~31 ~10 ~78 coal_block
fill ~31 ~10 ~80 ~34 ~10 ~80 coal_block
fill ~32 ~10 ~79 ~35 ~10 ~79 coal_block
setblock ~35 ~10 ~80 stone
fill ~35 ~10 ~81 ~47 ~10 ~81 coal_block
fill ~36 ~10 ~80 ~38 ~10 ~80 coal_block
setblock ~39 ~10 ~80 stone
fill ~40 ~10 ~80 ~42 ~10 ~80 coal_block
setblock ~43 ~10 ~80 stone
fill ~44 ~10 ~80 ~48 ~10 ~80 coal_block
fill ~49 ~10 ~79 ~49 ~12 ~79 coal_block
setblock ~49 ~10 ~80 concrete 15
fill ~50 ~10 ~80 ~52 ~10 ~80 coal_block
setblock ~51 ~10 ~79 concrete 15
setblock ~52 ~10 ~78 coal_block
setblock ~53 ~10 ~78 stone
fill ~53 ~10 ~79 ~55 ~10 ~79 coal_block
fill ~55 ~10 ~78 ~58 ~10 ~78 coal_block
fill ~56 ~10 ~77 ~57 ~10 ~77 coal_block
setblock ~58 ~10 ~77 stone
fill ~59 ~10 ~76 ~61 ~10 ~76 coal_block
setblock ~61 ~10 ~8 stone
setblock ~61 ~10 ~75 stone
setblock ~62 ~10 ~9 stone
setblock ~62 ~10 ~74 coal_block
setblock ~63 ~10 ~10 coal_block
fill ~64 ~10 ~9 ~64 ~15 ~9 coal_block
setblock ~64 ~10 ~10 concrete 15
setblock ~65 ~10 ~10 stone
setblock ~66 ~10 ~10 coal_block
fill ~67 ~10 ~13 ~67 ~11 ~13 coal_block
fill ~70 ~10 ~16 ~70 ~19 ~16 coal_block
setblock ~72 ~10 ~18 concrete 15
setblock ~76 ~10 ~23 coal_block
fill ~76 ~10 ~25 ~76 ~19 ~25 coal_block
fill ~79 ~10 ~32 ~79 ~12 ~32 coal_block
fill ~79 ~10 ~35 ~79 ~12 ~35 concrete 15
setblock ~80 ~10 ~35 coal_block
setblock ~80 ~10 ~39 stone
fill ~80 ~10 ~41 ~81 ~10 ~41 coal_block
fill ~80 ~10 ~43 ~80 ~11 ~43 concrete 7
fill ~81 ~10 ~38 ~81 ~12 ~38 concrete 7
setblock ~81 ~10 ~42 coal_ore
setblock ~3 ~11 ~35 coal_block
fill ~3 ~11 ~39 ~3 ~31 ~39 coal_block
setblock ~3 ~11 ~42 stone
fill ~3 ~11 ~43 ~3 ~13 ~43 concrete 7
setblock ~4 ~11 ~31 coal_block
setblock ~4 ~11 ~32 stone
fill ~4 ~11 ~33 ~4 ~16 ~33 coal_block
fill ~4 ~11 ~34 ~4 ~12 ~34 coal_block
setblock ~4 ~11 ~35 concrete 15
setblock ~5 ~11 ~28 stone
fill ~5 ~11 ~29 ~5 ~13 ~29 concrete 15
fill ~5 ~11 ~30 ~5 ~11 ~29 concrete 15
setblock ~6 ~11 ~26 concrete 15
fill ~6 ~11 ~28 ~6 ~12 ~28 concrete 15
setblock ~7 ~11 ~24 stone
fill ~7 ~11 ~25 ~7 ~12 ~25 concrete 15
setblock ~8 ~11 ~21 stone
fill ~8 ~11 ~23 ~8 ~18 ~23 coal_block
fill ~10 ~11 ~18 ~10 ~19 ~18 coal_block
setblock ~10 ~11 ~19 stone
fill ~12 ~11 ~17 ~12 ~15 ~17 coal_block
fill ~15 ~11 ~12 ~15 ~16 ~12 concrete 15
setblock ~15 ~11 ~14 stone
fill ~16 ~11 ~11 ~16 ~12 ~11 concrete 15
setblock ~16 ~11 ~13 concrete 15
setblock ~17 ~11 ~10 coal_block
setblock ~17 ~11 ~12 concrete 15
setblock ~19 ~11 ~10 stone
setblock ~22 ~11 ~74 stone
setblock ~22 ~11 ~75 coal_block
setblock ~23 ~11 ~6 concrete 7
setblock ~23 ~11 ~7 stone
fill ~23 ~11 ~8 ~23 ~12 ~8 coal_block
fill ~23 ~11 ~76 ~23 ~12 ~76 coal_block
fill ~23 ~11 ~77 ~25 ~11 ~77 coal_block
setblock ~24 ~11 ~7 concrete 7
fill ~24 ~11 ~8 ~24 ~12 ~8 prismarine 2
fill ~25 ~11 ~78 ~28 ~11 ~78 coal_block
setblock ~26 ~11 ~77 stone
fill ~28 ~11 ~79 ~30 ~11 ~79 coal_block
setblock ~29 ~11 ~78 stone
fill ~30 ~11 ~78 ~30 ~13 ~78 coal_block
fill ~31 ~11 ~80 ~35 ~11 ~80 coal_block
fill ~32 ~11 ~79 ~35 ~11 ~79 coal_block
fill ~35 ~11 ~81 ~47 ~11 ~81 coal_block
setblock ~36 ~11 ~80 stone
setblock ~37 ~11 ~80 concrete 7
fill ~38 ~11 ~80 ~52 ~11 ~80 coal_block
setblock ~51 ~11 ~79 stone
setblock ~52 ~11 ~78 concrete 15
fill ~53 ~11 ~78 ~53 ~15 ~78 coal_block
fill ~53 ~11 ~79 ~55 ~11 ~79 coal_block
setblock ~55 ~11 ~78 stone
fill ~56 ~11 ~77 ~56 ~17 ~77 coal_block
fill ~56 ~11 ~78 ~58 ~11 ~78 coal_block
setblock ~57 ~11 ~77 stone
setblock ~58 ~11 ~77 coal_block
fill ~59 ~11 ~7 ~59 ~17 ~7 coal_block
fill ~59 ~11 ~8 ~59 ~11 ~7 coal_block
fill ~59 ~11 ~76 ~61 ~11 ~76 coal_block
setblock ~60 ~11 ~6 concrete 7
setblock ~60 ~11 ~7 stone
setblock ~61 ~11 ~8 coal_block
setblock ~61 ~11 ~74 stone
setblock ~61 ~11 ~75 coal_block
fill ~62 ~11 ~9 ~62 ~13 ~9 concrete 15
setblock ~62 ~11 ~74 concrete 7
fill ~63 ~11 ~10 ~63 ~14 ~10 concrete 15
setblock ~64 ~11 ~10 stone
setblock ~65 ~11 ~10 coal_block
setblock ~66 ~11 ~10 concrete 15
fill ~67 ~11 ~11 ~67 ~14 ~11 coal_block
fill ~68 ~11 ~14 ~68 ~13 ~14 concrete 15
setblock ~69 ~11 ~15 stone
setblock ~72 ~11 ~18 stone
fill ~73 ~11 ~20 ~73 ~13 ~20 concrete 15
setblock ~74 ~11 ~21 concrete 15
setblock ~75 ~11 ~22 stone
setblock ~76 ~11 ~23 stone
setblock ~77 ~11 ~26 stone
fill ~77 ~11 ~27 ~77 ~13 ~27 coal_block
setblock ~78 ~11 ~29 stone
fill ~78 ~11 ~30 ~78 ~13 ~30 coal_block
fill ~78 ~11 ~31 ~78 ~32 ~31 coal_block
setblock ~79 ~11 ~34 stone
setblock ~80 ~11 ~32 concrete 15
setblock ~80 ~11 ~35 stone
fill ~80 ~11 ~39 ~80 ~17 ~39 coal_block
fill ~80 ~11 ~41 ~81 ~11 ~41 coal_block
setblock ~80 ~11 ~42 stone
setblock ~81 ~11 ~37 concrete 7
fill ~81 ~11 ~39 ~81 ~12 ~39 concrete 7
setblock ~81 ~11 ~42 concrete 7
fill ~81 ~11 ~43 ~81 ~13 ~43 coal_ore
setblock ~3 ~12 ~35 stone
setblock ~3 ~12 ~37 stone
setblock ~3 ~12 ~41 concrete 15
fill ~3 ~12 ~42 ~3 ~19 ~42 coal_block
setblock ~4 ~12 ~31 stone
fill ~4 ~12 ~32 ~4 ~18 ~32 coal_block
fill ~4 ~12 ~35 ~4 ~17 ~35 coal_block
setblock ~5 ~12 ~28 concrete 15
fill ~5 ~12 ~30 ~5 ~16 ~30 coal_block
fill ~5 ~12 ~31 ~5 ~14 ~31 coal_block
setblock ~6 ~12 ~26 stone
setblock ~7 ~12 ~24 concrete 15
fill ~8 ~12 ~20 ~8 ~16 ~20 coal_block
fill ~8 ~12 ~21 ~8 ~12 ~20 coal_block
fill ~9 ~12 ~19 ~10 ~12 ~19 coal_block
fill ~11 ~12 ~18 ~11 ~15 ~18 concrete 15
setblock ~11 ~12 ~19 stone
fill ~15 ~12 ~14 ~15 ~14 ~14 coal_block
fill ~16 ~12 ~13 ~16 ~15 ~13 coal_block
setblock ~17 ~12 ~10 concrete 15
setblock ~17 ~12 ~12 coal_block
fill ~19 ~12 ~10 ~19 ~14 ~10 coal_block
fill ~20 ~12 ~75 ~20 ~28 ~75 coal_block
fill ~22 ~12 ~74 ~22 ~32 ~74 coal_block
setblock ~22 ~12 ~75 stone
fill ~23 ~12 ~6 ~23 ~32 ~6 coal_block
fill ~23 ~12 ~7 ~23 ~12 ~6 coal_block
fill ~23 ~12 ~77 ~28 ~12 ~77 coal_block
setblock ~24 ~12 ~7 coal_ore
fill ~25 ~12 ~78 ~31 ~12 ~78 coal_block
fill ~28 ~12 ~79 ~30 ~12 ~79 coal_block
fill ~31 ~12 ~80 ~40 ~12 ~80 coal_block
fill ~32 ~12 ~79 ~33 ~12 ~79 coal_block
setblock ~34 ~12 ~79 stone
fill ~35 ~12 ~81 ~47 ~12 ~81 coal_block
setblock ~41 ~12 ~80 stone
fill ~42 ~12 ~80 ~44 ~12 ~80 coal_block
setblock ~45 ~12 ~80 stone
fill ~46 ~12 ~80 ~52 ~12 ~80 coal_block
fill ~50 ~12 ~79 ~51 ~12 ~79 concrete 15
fill ~52 ~12 ~78 ~52 ~14 ~78 coal_block
fill ~53 ~12 ~79 ~55 ~12 ~79 coal_block
fill ~55 ~12 ~78 ~58 ~12 ~78 coal_block
fill ~57 ~12 ~77 ~57 ~14 ~77 coal_block
setblock ~58 ~12 ~77 stone
fill ~59 ~12 ~76 ~61 ~12 ~76 coal_block
fill ~60 ~12 ~6 ~60 ~22 ~6 coal_block
setblock ~61 ~12 ~8 stone
setblock ~61 ~12 ~74 concrete 15
setblock ~61 ~12 ~75 stone
fill ~62 ~12 ~74 ~62 ~13 ~74 coal_block
fill ~62 ~12 ~75 ~62 ~12 ~74 coal_block
fill ~63 ~12 ~75 ~63 ~13 ~75 concrete 7
fill ~64 ~12 ~10 ~64 ~13 ~10 coal_block
setblock ~65 ~12 ~10 stone
fill ~66 ~12 ~10 ~66 ~32 ~10 coal_block
setblock ~67 ~12 ~13 concrete 15
fill ~69 ~12 ~15 ~69 ~13 ~15 concrete 15
fill ~72 ~12 ~18 ~72 ~20 ~18 coal_block
fill ~72 ~12 ~19 ~72 ~13 ~19 concrete 15
fill ~74 ~12 ~21 ~74 ~13 ~21 coal_block
fill ~75 ~12 ~22 ~75 ~13 ~22 coal_block
setblock ~76 ~12 ~23 coal_block
fill ~77 ~12 ~26 ~77 ~15 ~26 coal_block
fill ~77 ~12 ~28 ~77 ~33 ~28 coal_block
fill ~78 ~12 ~29 ~78 ~18 ~29 coal_block
setblock ~79 ~12 ~34 concrete 15
setblock ~80 ~12 ~32 coal_block
setblock ~80 ~12 ~35 wool 15
setblock ~80 ~12 ~37 stone
fill ~80 ~12 ~41 ~81 ~12 ~41 coal_block
setblock ~80 ~12 ~42 concrete 15
setblock ~80 ~12 ~43 wool 15
fill ~81 ~12 ~37 ~81 ~32 ~37 coal_block
setblock ~81 ~12 ~42 coal_block
fill ~2 ~13 ~36 ~2 ~14 ~36 concrete 15
setblock ~3 ~13 ~35 coal_block
fill ~3 ~13 ~37 ~3 ~23 ~37 coal_block
setblock ~3 ~13 ~40 stone
fill ~3 ~13 ~41 ~3 ~17 ~41 coal_block
setblock ~4 ~13 ~31 coal_block
setblock ~4 ~13 ~34 stone
setblock ~5 ~13 ~28 stone
fill ~6 ~13 ~26 ~6 ~14 ~26 coal_block
fill ~6 ~13 ~27 ~6 ~18 ~27 coal_block
fill ~6 ~13 ~28 ~6 ~31 ~28 coal_block
setblock ~7 ~13 ~23 stone
fill ~7 ~13 ~24 ~7 ~18 ~24 coal_block
fill ~7 ~13 ~25 ~7 ~15 ~25 coal_block
setblock ~7 ~13 ~26 stone
setblock ~8 ~13 ~21 stone
fill ~9 ~13 ~19 ~9 ~19 ~19 coal_block
setblock ~10 ~13 ~19 stone
fill ~11 ~13 ~19 ~11 ~31 ~19 coal_block
setblock ~13 ~13 ~16 stone
setblock ~16 ~13 ~11 coal_block
fill ~17 ~13 ~10 ~17 ~20 ~10 coal_block
setblock ~17 ~13 ~12 stone
setblock ~20 ~13 ~74 coal_block
setblock ~22 ~13 ~75 coal_block
setblock ~23 ~13 ~8 stone
setblock ~23 ~13 ~76 stone
fill ~23 ~13 ~77 ~24 ~13 ~77 coal_block
fill ~24 ~13 ~7 ~24 ~17 ~7 coal_block
setblock ~25 ~13 ~77 stone
fill ~25 ~13 ~78 ~27 ~13 ~78 coal_block
fill ~26 ~13 ~77 ~26 ~14 ~77 coal_block
setblock ~28 ~13 ~78 stone
fill ~28 ~13 ~79 ~30 ~13 ~79 coal_block
fill ~29 ~13 ~78 ~29 ~32 ~78 coal_block
fill ~31 ~13 ~80 ~34 ~13 ~80 coal_block
fill ~32 ~13 ~79 ~35 ~13 ~79 coal_block
setblock ~35 ~13 ~80 stone
fill ~35 ~13 ~81 ~47 ~13 ~81 coal_block
fill ~36 ~13 ~80 ~37 ~13 ~80 coal_block
setblock ~38 ~13 ~80 stone
fill ~39 ~13 ~80 ~52 ~13 ~80 coal_block
setblock ~49 ~13 ~79 stone
fill ~50 ~13 ~79 ~51 ~13 ~79 concrete 15
fill ~53 ~13 ~79 ~55 ~13 ~79 coal_block
setblock ~55 ~13 ~78 stone
fill ~56 ~13 ~78 ~57 ~13 ~78 coal_block
fill ~58 ~13 ~77 ~58 ~13 ~78 concrete 15
fill ~59 ~13 ~76 ~59 ~8 ~76 coal_block
fill ~60 ~13 ~76 ~60 ~14 ~76 concrete 15
setblock ~61 ~13 ~8 coal_block
fill ~61 ~13 ~74 ~61 ~14 ~74 coal_block
fill ~61 ~13 ~75 ~61 ~13 ~76 coal_block
fill ~62 ~13 ~75 ~62 ~14 ~75 concrete 15
setblock ~63 ~13 ~74 coal_block
setblock ~65 ~13 ~10 coal_block
setblock ~67 ~13 ~13 stone
fill ~71 ~13 ~15 ~71 ~14 ~15 concrete 7
setblock ~72 ~13 ~16 wool 15
setblock ~76 ~13 ~23 stone
fill ~79 ~13 ~29 ~79 ~13 ~30 concrete 15
setblock ~79 ~13 ~32 stone
fill ~79 ~13 ~34 ~79 ~14 ~34 coal_block
fill ~79 ~13 ~35 ~79 ~18 ~35 coal_block
fill ~80 ~13 ~31 ~80 ~14 ~31 concrete 15
fill ~80 ~13 ~32 ~80 ~13 ~31 concrete 15
setblock ~80 ~13 ~35 stone
fill ~80 ~13 ~36 ~80 ~18 ~36 coal_block
fill ~80 ~13 ~37 ~80 ~14 ~37 concrete 15
setblock ~80 ~13 ~40 stone
fill ~80 ~13 ~41 ~80 ~14 ~41 concrete 15
fill ~80 ~13 ~42 ~80 ~13 ~43 coal_block
fill ~81 ~13 ~38 ~81 ~32 ~38 coal_block
fill ~81 ~13 ~39 ~81 ~32 ~39 coal_block
fill ~81 ~13 ~41 ~81 ~32 ~41 coal_block
setblock ~81 ~13 ~42 wool 15
setblock ~2 ~14 ~43 concrete 15
fill ~2 ~14 ~44 ~2 ~32 ~44 coal_block
fill ~2 ~14 ~45 ~3 ~14 ~45 coal_block
setblock ~3 ~14 ~35 stone
fill ~3 ~14 ~40 ~3 ~17 ~40 coal_block
setblock ~3 ~14 ~43 stone
setblock ~3 ~14 ~44 concrete 7
setblock ~4 ~14 ~31 stone
fill ~4 ~14 ~34 ~4 ~16 ~34 coal_block
fill ~5 ~14 ~28 ~5 ~14 ~31 coal_block
setblock ~7 ~14 ~23 coal_block
fill ~7 ~14 ~26 ~7 ~15 ~26 coal_block
fill ~8 ~14 ~21 ~8 ~15 ~21 coal_block
setblock ~9 ~14 ~21 stone
setblock ~10 ~14 ~19 coal_block
fill ~13 ~14 ~16 ~13 ~16 ~16 coal_block
fill ~14 ~14 ~13 ~14 ~16 ~13 concrete 15
setblock ~16 ~14 ~11 concrete 15
fill ~17 ~14 ~12 ~17 ~16 ~12 coal_block
fill ~19 ~14 ~74 ~19 ~27 ~74 coal_block
fill ~20 ~14 ~8 ~20 ~15 ~8 concrete 15
setblock ~20 ~14 ~73 prismarine 2
setblock ~21 ~14 ~9 stone
setblock ~21 ~14 ~74 stone
setblock ~22 ~14 ~75 stone
fill ~23 ~14 ~8 ~23 ~31 ~8 coal_block
fill ~23 ~14 ~76 ~23 ~26 ~76 coal_block
fill ~23 ~14 ~77 ~28 ~14 ~77 coal_block
fill ~24 ~14 ~6 ~25 ~14 ~6 coal_block
setblock ~24 ~14 ~76 stone
fill ~25 ~14 ~7 ~25 ~32 ~7 coal_block
fill ~25 ~14 ~78 ~29 ~14 ~78 coal_block
fill ~28 ~14 ~79 ~30 ~14 ~79 coal_block
setblock ~30 ~14 ~78 stone
fill ~31 ~14 ~80 ~46 ~14 ~80 coal_block
fill ~32 ~14 ~79 ~35 ~14 ~79 coal_block
fill ~35 ~14 ~81 ~47 ~14 ~81 coal_block
setblock ~47 ~14 ~80 stone
fill ~48 ~14 ~80 ~52 ~14 ~80 coal_block
fill ~49 ~14 ~79 ~49 ~19 ~79 coal_block
fill ~50 ~14 ~79 ~51 ~14 ~79 concrete 15
fill ~53 ~14 ~79 ~55 ~14 ~79 coal_block
setblock ~54 ~14 ~78 stone
fill ~55 ~14 ~78 ~58 ~14 ~78 coal_block
fill ~58 ~14 ~6 ~60 ~14 ~6 coal_block
fill ~58 ~14 ~7 ~58 ~21 ~7 coal_block
setblock ~58 ~14 ~77 stone
setblock ~59 ~14 ~76 stone
setblock ~61 ~14 ~8 stone
setblock ~61 ~14 ~75 stone
setblock ~61 ~14 ~76 concrete 15
setblock ~62 ~14 ~9 stone
setblock ~62 ~14 ~74 stone
setblock ~63 ~14 ~73 concrete 7
fill ~63 ~14 ~75 ~63 ~32 ~75 coal_block
setblock ~64 ~14 ~10 concrete 15
fill ~64 ~14 ~74 ~64 ~17 ~74 coal_block
setblock ~65 ~14 ~10 stone
fill ~67 ~14 ~13 ~67 ~15 ~13 concrete 15
fill ~68 ~14 ~14 ~68 ~20 ~14 coal_block
fill ~69 ~14 ~13 ~69 ~15 ~13 concrete 7
setblock ~69 ~14 ~15 coal_block
setblock ~70 ~14 ~14 concrete 7
fill ~72 ~14 ~16 ~72 ~15 ~16 coal_block
setblock ~72 ~14 ~19 stone
setblock ~73 ~14 ~20 coal_block
setblock ~74 ~14 ~21 concrete 15
setblock ~75 ~14 ~22 concrete 15
setblock ~76 ~14 ~23 coal_block
setblock ~76 ~14 ~24 stone
setblock ~77 ~14 ~27 stone
setblock ~78 ~14 ~30 stone
fill ~79 ~14 ~29 ~79 ~32 ~29 coal_block
fill ~79 ~14 ~30 ~79 ~25 ~30 coal_block
fill ~79 ~14 ~32 ~80 ~14 ~32 coal_block
setblock ~80 ~14 ~35 coal_block
fill ~80 ~14 ~40 ~80 ~17 ~40 coal_block
setblock ~80 ~14 ~42 concrete 15
setblock ~80 ~14 ~43 stone
fill ~80 ~14 ~44 ~80 ~15 ~44 coal_block
fill ~80 ~14 ~45 ~80 ~23 ~45 coal_block
fill ~81 ~14 ~42 ~81 ~32 ~42 coal_block
fill ~81 ~14 ~43 ~81 ~14 ~45 concrete 7
fill ~2 ~15 ~36 ~2 ~30 ~36 coal_block
fill ~2 ~15 ~43 ~3 ~15 ~43 coal_block
fill ~2 ~15 ~45 ~3 ~15 ~45 coal_block
fill ~2 ~15 ~46 ~3 ~15 ~46 coal_block
fill ~2 ~15 ~47 ~3 ~15 ~47 coal_block
fill ~3 ~15 ~35 ~3 ~16 ~35 coal_block
setblock ~3 ~15 ~38 stone
fill ~3 ~15 ~44 ~3 ~32 ~44 coal_block
fill ~3 ~15 ~48 ~3 ~15 ~49 coal_block
fill ~3 ~15 ~50 ~3 ~16 ~50 concrete 7
setblock ~4 ~15 ~29 concrete 15
setblock ~4 ~15 ~31 coal_block
fill ~4 ~15 ~47 ~4 ~15 ~48 concrete 7
setblock ~4 ~15 ~49 prismarine 2
setblock ~4 ~15 ~50 coal_ore
setblock ~5 ~15 ~28 stone
fill ~5 ~15 ~29 ~5 ~21 ~29 coal_block
setblock ~5 ~15 ~31 stone
setblock ~6 ~15 ~26 stone
setblock ~7 ~15 ~23 stone
fill ~9 ~15 ~21 ~9 ~32 ~21 coal_block
setblock ~10 ~15 ~19 stone
setblock ~15 ~15 ~14 stone
setblock ~15 ~15 ~71 concrete 7
setblock ~16 ~15 ~11 coal_block
fill ~16 ~15 ~70 ~16 ~15 ~71 coal_block
setblock ~16 ~15 ~72 wool 15
setblock ~17 ~15 ~71 wool 15
fill ~17 ~15 ~72 ~19 ~15 ~72 coal_block
fill ~17 ~15 ~73 ~20 ~15 ~73 coal_block
setblock ~19 ~15 ~10 stone
fill ~21 ~15 ~9 ~21 ~19 ~9 coal_block
fill ~21 ~15 ~74 ~21 ~17 ~74 coal_block
setblock ~22 ~15 ~8 coal_block
setblock ~22 ~15 ~75 coal_block
fill ~24 ~15 ~6 ~28 ~15 ~6 coal_block
fill ~24 ~15 ~76 ~24 ~19 ~76 coal_block
fill ~24 ~15 ~77 ~25 ~15 ~77 coal_block
fill ~25 ~15 ~5 ~27 ~15 ~5 coal_block
fill ~25 ~15 ~78 ~27 ~15 ~78 coal_block
setblock ~26 ~15 ~77 stone
fill ~28 ~15 ~4 ~30 ~15 ~4 coal_block
setblock ~28 ~15 ~5 concrete 15
setblock ~28 ~15 ~78 stone
fill ~28 ~15 ~79 ~30 ~15 ~79 coal_block
fill ~29 ~15 ~5 ~30 ~15 ~5 concrete 7
fill ~30 ~15 ~78 ~30 ~17 ~78 coal_block
fill ~31 ~15 ~80 ~34 ~15 ~80 coal_block
fill ~32 ~15 ~79 ~32 ~23 ~79 coal_block
setblock ~33 ~15 ~79 stone
fill ~34 ~15 ~79 ~34 ~25 ~79 coal_block
setblock ~35 ~15 ~80 stone
fill ~35 ~15 ~81 ~46 ~15 ~81 coal_block
fill ~36 ~15 ~80 ~39 ~15 ~80 coal_block
setblock ~40 ~15 ~80 stone
fill ~41 ~15 ~80 ~43 ~15 ~80 coal_block
setblock ~44 ~15 ~80 stone
fill ~45 ~15 ~80 ~47 ~15 ~80 coal_block
setblock ~47 ~15 ~81 concrete 15
setblock ~48 ~15 ~80 concrete 15
fill ~49 ~15 ~80 ~52 ~15 ~80 coal_block
fill ~50 ~15 ~79 ~50 ~17 ~79 coal_block
setblock ~51 ~15 ~79 stone
fill ~52 ~15 ~78 ~52 ~16 ~78 concrete 15
fill ~53 ~15 ~4 ~53 ~32 ~4 coal_block
fill ~53 ~15 ~5 ~54 ~15 ~5 concrete 7
fill ~53 ~15 ~79 ~55 ~15 ~79 coal_block
fill ~54 ~15 ~4 ~55 ~15 ~4 concrete 7
fill ~54 ~15 ~78 ~54 ~18 ~78 coal_block
fill ~55 ~15 ~5 ~58 ~15 ~5 coal_block
fill ~55 ~15 ~6 ~57 ~15 ~6 coal_block
setblock ~55 ~15 ~78 stone
fill ~56 ~15 ~78 ~56 ~32 ~78 coal_block
setblock ~57 ~15 ~77 stone
setblock ~57 ~15 ~78 concrete 15
setblock ~58 ~15 ~6 stone
fill ~58 ~15 ~77 ~58 ~15 ~78 coal_block
fill ~59 ~15 ~6 ~59 ~28 ~6 coal_block
fill ~59 ~15 ~76 ~59 ~16 ~76 coal_block
setblock ~59 ~15 ~77 concrete 15
fill ~60 ~15 ~75 ~61 ~15 ~75 concrete 15
setblock ~60 ~15 ~76 stone
fill ~60 ~15 ~77 ~60 ~32 ~77 coal_block
setblock ~61 ~15 ~9 concrete 15
fill ~61 ~15 ~74 ~61 ~17 ~74 concrete 15
fill ~61 ~15 ~76 ~61 ~32 ~76 coal_block
fill ~62 ~15 ~9 ~62 ~17 ~9 coal_block
fill ~62 ~15 ~74 ~62 ~15 ~75 coal_block
fill ~63 ~15 ~10 ~63 ~32 ~10 coal_block
fill ~63 ~15 ~73 ~66 ~15 ~73 coal_block
setblock ~64 ~15 ~10 stone
fill ~64 ~15 ~72 ~65 ~15 ~72 coal_block
fill ~65 ~15 ~10 ~65 ~32 ~10 coal_block
setblock ~65 ~15 ~11 concrete 15
setblock ~66 ~15 ~12 concrete 15
fill ~66 ~15 ~71 ~66 ~15 ~72 wool 15
fill ~67 ~15 ~11 ~67 ~16 ~11 concrete 7
fill ~67 ~15 ~70 ~68 ~15 ~70 coal_block
fill ~67 ~15 ~71 ~67 ~15 ~72 coal_block
fill ~68 ~15 ~12 ~68 ~17 ~12 concrete 7
setblock ~68 ~15 ~71 concrete 7
setblock ~69 ~15 ~15 stone
setblock ~70 ~15 ~14 wool 15
fill ~71 ~15 ~15 ~71 ~22 ~15 coal_block
fill ~72 ~15 ~19 ~72 ~17 ~19 coal_block
setblock ~73 ~15 ~20 concrete 15
setblock ~74 ~15 ~21 coal_block
setblock ~75 ~15 ~22 stone
setblock ~76 ~15 ~23 stone
fill ~76 ~15 ~24 ~76 ~18 ~24 coal_block
fill ~77 ~15 ~27 ~77 ~17 ~27 coal_block
fill ~78 ~15 ~30 ~78 ~32 ~30 coal_block
fill ~79 ~15 ~32 ~80 ~15 ~32 coal_block
setblock ~79 ~15 ~34 stone
fill ~79 ~15 ~47 ~80 ~15 ~47 coal_block
fill ~79 ~15 ~48 ~80 ~15 ~48 concrete 7
fill ~79 ~15 ~49 ~80 ~15 ~49 concrete 7
fill ~79 ~15 ~50 ~80 ~15 ~50 concrete 7
fill ~80 ~15 ~31 ~80 ~24 ~31 coal_block
setblock ~80 ~15 ~35 stone
fill ~80 ~15 ~37 ~80 ~18 ~37 coal_block
setblock ~80 ~15 ~38 stone
fill ~80 ~15 ~41 ~80 ~20 ~41 coal_block
fill ~80 ~15 ~42 ~80 ~19 ~42 coal_block
fill ~80 ~15 ~43 ~81 ~15 ~43 coal_block
setblock ~80 ~15 ~46 coal_block
fill ~81 ~15 ~44 ~81 ~32 ~44 coal_block
setblock ~81 ~15 ~45 wool 15
fill ~81 ~15 ~46 ~81 ~15 ~47 concrete 7
fill ~2 ~16 ~43 ~3 ~16 ~43 coal_block
fill ~2 ~16 ~45 ~3 ~16 ~45 coal_block
fill ~2 ~16 ~46 ~3 ~16 ~46 coal_block
setblock ~2 ~16 ~47 concrete 15
fill ~3 ~16 ~38 ~3 ~20 ~38 coal_block
fill ~3 ~16 ~47 ~4 ~16 ~47 coal_block
setblock ~3 ~16 ~48 concrete 15
setblock ~3 ~16 ~49 concrete 7
fill ~3 ~16 ~51 ~4 ~16 ~51 concrete 7
fill ~3 ~16 ~52 ~3 ~17 ~52 concrete 7
fill ~4 ~16 ~29 ~4 ~26 ~29 coal_block
fill ~4 ~16 ~48 ~4 ~20 ~48 coal_block
setblock ~4 ~16 ~49 stone
setblock ~4 ~16 ~50 concrete 7
setblock ~4 ~16 ~52 wool 15
setblock ~4 ~16 ~53 coal_block
setblock ~4 ~16 ~54 wool 15
setblock ~4 ~16 ~55 concrete 7
fill ~5 ~16 ~27 ~5 ~17 ~27 concrete 7
fill ~5 ~16 ~31 ~5 ~32 ~31 coal_block
fill ~5 ~16 ~52 ~5 ~22 ~52 coal_block
fill ~5 ~16 ~53 ~5 ~16 ~54 concrete 7
setblock ~5 ~16 ~55 coal_block
fill ~5 ~16 ~56 ~6 ~16 ~56 concrete 7
fill ~5 ~16 ~57 ~5 ~16 ~58 concrete 7
fill ~6 ~16 ~26 ~6 ~17 ~26 coal_block
fill ~6 ~16 ~55 ~6 ~17 ~55 concrete 7
fill ~6 ~16 ~57 ~6 ~18 ~57 coal_block
fill ~6 ~16 ~58 ~6 ~17 ~58 concrete 7
fill ~6 ~16 ~59 ~7 ~16 ~59 coal_block
fill ~6 ~16 ~60 ~7 ~16 ~60 coal_block
fill ~7 ~16 ~23 ~7 ~17 ~23 coal_block
fill ~7 ~16 ~25 ~7 ~17 ~25 concrete 15
setblock ~7 ~16 ~58 wool 15
fill ~7 ~16 ~61 ~7 ~32 ~61 coal_block
setblock ~8 ~16 ~60 concrete 7
setblock ~8 ~16 ~61 wool 15
fill ~8 ~16 ~62 ~8 ~32 ~62 coal_block
setblock ~8 ~16 ~63 wool 15
setblock ~9 ~16 ~62 wool 15
fill ~9 ~16 ~63 ~9 ~16 ~64 coal_block
setblock ~10 ~16 ~63 concrete 7
fill ~10 ~16 ~64 ~10 ~16 ~66 coal_block
fill ~11 ~16 ~18 ~11 ~17 ~18 coal_block
setblock ~11 ~16 ~64 concrete 7
setblock ~11 ~16 ~65 wool 15
fill ~11 ~16 ~66 ~12 ~16 ~66 coal_block
fill ~11 ~16 ~67 ~13 ~16 ~67 coal_block
fill ~12 ~16 ~17 ~12 ~18 ~17 concrete 15
fill ~12 ~16 ~68 ~12 ~29 ~68 coal_block
setblock ~13 ~16 ~68 concrete 7
fill ~13 ~16 ~69 ~13 ~29 ~69 coal_block
fill ~14 ~16 ~68 ~14 ~32 ~68 coal_block
setblock ~14 ~16 ~69 wool 15
fill ~14 ~16 ~70 ~15 ~16 ~70 coal_block
fill ~15 ~16 ~14 ~15 ~17 ~14 concrete 15
fill ~15 ~16 ~69 ~15 ~20 ~69 coal_block
fill ~15 ~16 ~71 ~15 ~30 ~71 coal_block
setblock ~16 ~16 ~11 concrete 15
fill ~16 ~16 ~13 ~16 ~17 ~13 concrete 15
setblock ~16 ~16 ~70 stone
fill ~16 ~16 ~72 ~16 ~26 ~72 coal_block
fill ~17 ~16 ~71 ~17 ~22 ~71 coal_block
fill ~17 ~16 ~73 ~18 ~16 ~73 coal_block
fill ~18 ~16 ~9 ~18 ~17 ~9 coal_block
setblock ~18 ~16 ~10 stone
fill ~18 ~16 ~72 ~19 ~16 ~72 coal_block
fill ~19 ~16 ~10 ~19 ~17 ~10 coal_block
fill ~20 ~16 ~8 ~20 ~29 ~8 coal_block
fill ~20 ~16 ~73 ~20 ~32 ~73 coal_block
setblock ~22 ~16 ~8 stone
setblock ~22 ~16 ~75 stone
fill ~24 ~16 ~6 ~24 ~32 ~6 coal_block
fill ~24 ~16 ~77 ~24 ~30 ~77 coal_block
fill ~25 ~16 ~5 ~27 ~16 ~5 coal_block
setblock ~25 ~16 ~6 stone
fill ~25 ~16 ~78 ~31 ~16 ~78 coal_block
fill ~26 ~16 ~6 ~26 ~18 ~6 coal_block
fill ~26 ~16 ~77 ~26 ~32 ~77 coal_block
setblock ~27 ~16 ~6 stone
fill ~28 ~16 ~4 ~29 ~16 ~4 coal_block
fill ~28 ~16 ~6 ~28 ~32 ~6 coal_block
fill ~28 ~16 ~79 ~30 ~16 ~79 coal_block
fill ~29 ~16 ~5 ~31 ~16 ~5 coal_block
setblock ~30 ~16 ~4 concrete 15
fill ~31 ~16 ~3 ~32 ~16 ~3 coal_block
fill ~31 ~16 ~4 ~36 ~16 ~4 coal_block
fill ~31 ~16 ~80 ~52 ~16 ~80 coal_block
fill ~33 ~16 ~3 ~33 ~17 ~3 concrete 15
fill ~33 ~16 ~79 ~33 ~18 ~79 coal_block
fill ~34 ~16 ~3 ~52 ~16 ~3 coal_block
fill ~36 ~16 ~2 ~45 ~16 ~2 coal_block
fill ~36 ~16 ~81 ~48 ~16 ~81 coal_block
fill ~46 ~16 ~2 ~47 ~16 ~2 concrete 7
fill ~47 ~16 ~4 ~48 ~16 ~4 coal_block
setblock ~49 ~16 ~4 wool 15
fill ~50 ~16 ~4 ~55 ~16 ~4 coal_block
fill ~51 ~16 ~79 ~51 ~19 ~79 coal_block
fill ~52 ~16 ~5 ~54 ~16 ~5 coal_block
setblock ~53 ~16 ~78 concrete 15
fill ~53 ~16 ~79 ~55 ~16 ~79 coal_block
fill ~55 ~16 ~6 ~56 ~16 ~6 coal_block
setblock ~55 ~16 ~78 coal_block
fill ~56 ~16 ~5 ~58 ~16 ~5 coal_block
setblock ~57 ~16 ~6 stone
fill ~57 ~16 ~77 ~57 ~18 ~77 concrete 15
fill ~57 ~16 ~78 ~58 ~16 ~78 coal_block
setblock ~58 ~16 ~6 coal_block
setblock ~58 ~16 ~77 stone
fill ~59 ~16 ~77 ~59 ~32 ~77 coal_block
fill ~60 ~16 ~75 ~60 ~22 ~75 coal_block
fill ~60 ~16 ~76 ~60 ~16 ~75 coal_block
fill ~61 ~16 ~9 ~61 ~32 ~9 coal_block
setblock ~61 ~16 ~75 concrete 15
fill ~62 ~16 ~74 ~62 ~17 ~74 concrete 15
fill ~62 ~16 ~75 ~62 ~32 ~75 coal_block
fill ~63 ~16 ~73 ~63 ~15 ~73 coal_block
setblock ~64 ~16 ~9 concrete 7
setblock ~64 ~16 ~10 coal_block
fill ~64 ~16 ~72 ~65 ~16 ~72 coal_block
fill ~65 ~16 ~11 ~65 ~32 ~11 coal_block
fill ~65 ~16 ~73 ~66 ~16 ~73 coal_block
fill ~66 ~16 ~12 ~66 ~28 ~12 coal_block
fill ~66 ~16 ~71 ~66 ~18 ~71 coal_block
setblock ~67 ~16 ~13 coal_block
fill ~67 ~16 ~70 ~67 ~18 ~70 coal_block
fill ~67 ~16 ~72 ~67 ~32 ~72 coal_block
fill ~68 ~16 ~69 ~70 ~16 ~69 coal_block
setblock ~68 ~16 ~70 stone
fill ~68 ~16 ~71 ~68 ~32 ~71 coal_block
setblock ~69 ~16 ~13 wool 15
fill ~69 ~16 ~15 ~69 ~19 ~15 coal_block
fill ~69 ~16 ~68 ~71 ~16 ~68 coal_block
fill ~69 ~16 ~70 ~69 ~18 ~70 coal_block
setblock ~70 ~16 ~14 coal_block
fill ~70 ~16 ~67 ~70 ~29 ~67 coal_block
fill ~71 ~16 ~66 ~73 ~16 ~66 coal_block
setblock ~71 ~16 ~67 concrete 7
setblock ~72 ~16 ~16 concrete 7
fill ~72 ~16 ~64 ~73 ~16 ~64 coal_block
fill ~72 ~16 ~65 ~73 ~16 ~65 coal_block
fill ~72 ~16 ~67 ~72 ~25 ~67 coal_block
setblock ~73 ~16 ~17 concrete 7
fill ~73 ~16 ~19 ~73 ~16 ~20 coal_block
fill ~73 ~16 ~63 ~73 ~21 ~63 coal_block
fill ~74 ~16 ~21 ~74 ~17 ~21 concrete 15
fill ~74 ~16 ~62 ~74 ~30 ~62 coal_block
fill ~74 ~16 ~63 ~75 ~16 ~63 concrete 7
fill ~74 ~16 ~64 ~74 ~16 ~63 concrete 7
setblock ~75 ~16 ~21 coal_block
fill ~75 ~16 ~22 ~75 ~17 ~22 concrete 15
fill ~75 ~16 ~60 ~77 ~16 ~60 coal_block
fill ~75 ~16 ~61 ~75 ~16 ~60 coal_block
setblock ~75 ~16 ~62 concrete 7
fill ~76 ~16 ~23 ~76 ~17 ~23 coal_block
fill ~76 ~16 ~26 ~76 ~17 ~26 coal_block
setblock ~76 ~16 ~58 wool 15
fill ~76 ~16 ~59 ~76 ~20 ~59 coal_block
setblock ~76 ~16 ~61 concrete 7
setblock ~77 ~16 ~23 concrete 15
setblock ~77 ~16 ~26 stone
fill ~77 ~16 ~55 ~78 ~16 ~55 coal_block
fill ~77 ~16 ~56 ~77 ~20 ~56 coal_block
fill ~77 ~16 ~57 ~78 ~16 ~57 concrete 7
fill ~77 ~16 ~58 ~78 ~16 ~58 coal_block
setblock ~77 ~16 ~59 concrete 7
setblock ~78 ~16 ~28 stone
fill ~78 ~16 ~52 ~79 ~16 ~52 coal_block
fill ~78 ~16 ~53 ~78 ~19 ~53 coal_block
fill ~78 ~16 ~54 ~78 ~16 ~52 coal_block
setblock ~78 ~16 ~56 concrete 7
fill ~79 ~16 ~31 ~79 ~18 ~31 coal_block
fill ~79 ~16 ~32 ~80 ~16 ~32 coal_block
fill ~79 ~16 ~34 ~79 ~19 ~34 coal_block
fill ~79 ~16 ~47 ~81 ~16 ~47 coal_block
fill ~79 ~16 ~48 ~79 ~32 ~48 coal_block
fill ~79 ~16 ~49 ~80 ~16 ~49 coal_block
setblock ~79 ~16 ~50 stone
fill ~79 ~16 ~51 ~79 ~18 ~51 coal_block
fill ~79 ~16 ~53 ~79 ~16 ~55 concrete 7
fill ~80 ~16 ~35 ~80 ~17 ~35 coal_block
fill ~80 ~16 ~38 ~80 ~23 ~38 coal_block
fill ~80 ~16 ~43 ~81 ~16 ~43 coal_block
setblock ~80 ~16 ~44 concrete 15
setblock ~80 ~16 ~46 stone
setblock ~80 ~16 ~48 concrete 15
fill ~80 ~16 ~50 ~80 ~19 ~50 coal_block
fill ~80 ~16 ~51 ~80 ~16 ~52 concrete 7
fill ~81 ~16 ~45 ~81 ~31 ~45 coal_block
fill ~81 ~16 ~46 ~81 ~19 ~46 coal_block
fill ~2 ~17 ~43 ~3 ~17 ~43 coal_block
fill ~2 ~17 ~45 ~3 ~17 ~45 coal_block
fill ~2 ~17 ~46 ~3 ~17 ~46 coal_block
fill ~2 ~17 ~47 ~2 ~19 ~47 coal_block
setblock ~3 ~17 ~35 stone
setblock ~3 ~17 ~47 stone
fill ~3 ~17 ~48 ~3 ~30 ~48 coal_block
fill ~3 ~17 ~49 ~4 ~17 ~49 coal_block
fill ~3 ~17 ~50 ~4 ~17 ~50 coal_block
fill ~3 ~17 ~51 ~4 ~17 ~51 coal_block
setblock ~4 ~17 ~33 concrete 15
setblock ~4 ~17 ~34 stone
setblock ~4 ~17 ~47 coal_block
setblock ~4 ~17 ~52 stone
setblock ~4 ~17 ~53 concrete 7
fill ~4 ~17 ~54 ~5 ~17 ~54 coal_block
fill ~4 ~17 ~55 ~4 ~24 ~55 coal_block
setblock ~5 ~17 ~30 concrete 15
setblock ~5 ~17 ~53 stone
fill ~5 ~17 ~56 ~6 ~17 ~56 coal_block
fill ~5 ~17 ~57 ~5 ~20 ~57 coal_block
setblock ~5 ~17 ~58 concrete 7
setblock ~6 ~17 ~59 concrete 7
fill ~6 ~17 ~60 ~6 ~32 ~60 coal_block
fill ~7 ~17 ~29 ~7 ~25 ~29 coal_block
fill ~7 ~17 ~58 ~7 ~24 ~58 coal_block
fill ~7 ~17 ~59 ~7 ~20 ~59 coal_block
setblock ~8 ~17 ~20 concrete 15
fill ~8 ~17 ~26 ~9 ~17 ~26 coal_block
fill ~8 ~17 ~27 ~8 ~26 ~27 coal_block
fill ~8 ~17 ~28 ~8 ~26 ~28 coal_block
fill ~8 ~17 ~60 ~8 ~32 ~60 coal_block
fill ~8 ~17 ~61 ~8 ~18 ~61 concrete 15
fill ~8 ~17 ~63 ~8 ~32 ~63 coal_block
fill ~9 ~17 ~24 ~10 ~17 ~24 coal_block
fill ~9 ~17 ~25 ~9 ~21 ~25 coal_block
setblock ~9 ~17 ~62 stone
fill ~9 ~17 ~64 ~9 ~32 ~64 coal_block
fill ~10 ~17 ~23 ~10 ~20 ~23 coal_block
fill ~10 ~17 ~63 ~10 ~21 ~63 coal_block
setblock ~10 ~17 ~64 stone
fill ~10 ~17 ~65 ~10 ~32 ~65 coal_block
fill ~10 ~17 ~66 ~10 ~32 ~66 coal_block
setblock ~11 ~17 ~16 concrete 15
fill ~11 ~17 ~21 ~11 ~20 ~21 coal_block
fill ~11 ~17 ~22 ~11 ~23 ~22 coal_block
fill ~11 ~17 ~64 ~11 ~19 ~64 coal_block
setblock ~11 ~17 ~65 stone
fill ~11 ~17 ~67 ~11 ~32 ~67 coal_block
fill ~12 ~17 ~20 ~12 ~33 ~20 coal_block
fill ~12 ~17 ~66 ~12 ~22 ~66 coal_block
fill ~13 ~17 ~16 ~13 ~18 ~16 concrete 15
fill ~13 ~17 ~18 ~13 ~17 ~19 coal_block
fill ~13 ~17 ~67 ~13 ~18 ~67 coal_block
fill ~14 ~17 ~13 ~14 ~18 ~13 coal_block
fill ~14 ~17 ~15 ~14 ~18 ~15 concrete 15
setblock ~14 ~17 ~18 stone
fill ~14 ~17 ~70 ~14 ~32 ~70 coal_block
fill ~15 ~17 ~12 ~15 ~18 ~12 coal_block
fill ~16 ~17 ~11 ~16 ~19 ~11 coal_block
fill ~16 ~17 ~70 ~16 ~26 ~70 coal_block
setblock ~17 ~17 ~12 stone
fill ~17 ~17 ~73 ~18 ~17 ~73 coal_block
setblock ~18 ~17 ~10 coal_block
fill ~18 ~17 ~72 ~19 ~17 ~72 coal_block
setblock ~22 ~17 ~8 coal_block
setblock ~22 ~17 ~75 coal_block
fill ~25 ~17 ~5 ~27 ~17 ~5 coal_block
fill ~25 ~17 ~6 ~25 ~17 ~5 coal_block
fill ~25 ~17 ~78 ~31 ~17 ~78 coal_block
fill ~27 ~17 ~6 ~27 ~21 ~6 coal_block
fill ~28 ~17 ~4 ~30 ~17 ~4 coal_block
fill ~28 ~17 ~79 ~30 ~17 ~79 coal_block
fill ~29 ~17 ~5 ~31 ~17 ~5 coal_block
fill ~29 ~17 ~29 ~58 ~17 ~29 tnt
fill ~29 ~17 ~30 ~58 ~17 ~30 tnt
fill ~29 ~17 ~31 ~58 ~17 ~31 tnt
fill ~29 ~17 ~32 ~58 ~17 ~32 tnt
fill ~29 ~17 ~33 ~58 ~17 ~33 tnt
fill ~29 ~17 ~34 ~58 ~17 ~34 tnt
fill ~29 ~17 ~35 ~58 ~17 ~35 tnt
fill ~29 ~17 ~36 ~58 ~17 ~36 tnt
fill ~29 ~17 ~37 ~58 ~17 ~37 tnt
fill ~29 ~17 ~38 ~58 ~17 ~38 tnt
fill ~29 ~17 ~39 ~58 ~17 ~39 tnt
fill ~29 ~17 ~40 ~58 ~17 ~40 tnt
fill ~29 ~17 ~41 ~58 ~17 ~41 tnt
fill ~29 ~17 ~42 ~58 ~17 ~42 tnt
fill ~29 ~17 ~43 ~58 ~17 ~43 tnt
fill ~29 ~17 ~44 ~58 ~17 ~44 tnt
fill ~29 ~17 ~45 ~58 ~17 ~45 tnt
fill ~29 ~17 ~46 ~58 ~17 ~46 tnt
fill ~29 ~17 ~47 ~58 ~17 ~47 tnt
fill ~29 ~17 ~48 ~58 ~17 ~48 tnt
fill ~29 ~17 ~49 ~58 ~17 ~49 tnt
fill ~29 ~17 ~50 ~58 ~17 ~50 tnt
fill ~29 ~17 ~51 ~58 ~17 ~51 tnt
fill ~29 ~17 ~52 ~58 ~17 ~52 tnt
fill ~29 ~17 ~53 ~58 ~17 ~53 tnt
fill ~29 ~17 ~54 ~58 ~17 ~54 tnt
fill ~29 ~17 ~55 ~58 ~17 ~55 tnt
fill ~29 ~17 ~56 ~58 ~17 ~56 tnt
fill ~29 ~17 ~57 ~58 ~17 ~57 tnt
fill ~29 ~17 ~58 ~58 ~17 ~58 tnt
setblock ~31 ~17 ~3 concrete 15
setblock ~31 ~17 ~4 stone
fill ~31 ~17 ~80 ~38 ~17 ~80 coal_block
fill ~32 ~17 ~3 ~32 ~32 ~3 coal_block
fill ~32 ~17 ~4 ~36 ~17 ~4 coal_block
fill ~34 ~17 ~3 ~36 ~17 ~3 coal_block
fill ~35 ~17 ~77 ~35 ~17 ~80 coal_block
fill ~36 ~17 ~2 ~47 ~17 ~2 coal_block
setblock ~36 ~17 ~77 stone
fill ~36 ~17 ~78 ~40 ~17 ~78 coal_block
fill ~36 ~17 ~81 ~39 ~17 ~81 coal_block
setblock ~37 ~17 ~3 stone
fill ~38 ~17 ~3 ~41 ~17 ~3 coal_block
setblock ~39 ~17 ~80 concrete 15
fill ~40 ~17 ~80 ~47 ~17 ~80 coal_block
setblock ~40 ~17 ~81 concrete 15
setblock ~41 ~17 ~78 concrete 15
fill ~41 ~17 ~81 ~48 ~17 ~81 coal_block
setblock ~42 ~17 ~3 stone
fill ~42 ~17 ~78 ~48 ~17 ~78 coal_block
fill ~43 ~17 ~3 ~46 ~17 ~3 coal_block
setblock ~47 ~17 ~3 stone
fill ~47 ~17 ~4 ~51 ~17 ~4 coal_block
setblock ~47 ~17 ~77 stone
fill ~48 ~17 ~3 ~52 ~17 ~3 coal_block
setblock ~48 ~17 ~77 coal_block
setblock ~48 ~17 ~80 stone
fill ~49 ~17 ~80 ~52 ~17 ~80 coal_block
setblock ~52 ~17 ~4 stone
fill ~52 ~17 ~5 ~54 ~17 ~5 coal_block
fill ~52 ~17 ~78 ~54 ~17 ~78 coal_block
fill ~53 ~17 ~79 ~55 ~17 ~79 coal_block
fill ~54 ~17 ~4 ~55 ~17 ~4 coal_block
fill ~55 ~17 ~6 ~57 ~17 ~6 coal_block
setblock ~55 ~17 ~78 stone
fill ~56 ~17 ~5 ~57 ~17 ~5 concrete 15
fill ~57 ~17 ~78 ~58 ~17 ~78 coal_block
fill ~58 ~17 ~5 ~58 ~19 ~5 coal_block
setblock ~58 ~17 ~6 stone
fill ~58 ~17 ~76 ~59 ~17 ~76 concrete 15
setblock ~58 ~17 ~77 coal_block
setblock ~60 ~17 ~76 stone
setblock ~61 ~17 ~75 stone
fill ~63 ~17 ~73 ~63 ~18 ~73 concrete 15
fill ~64 ~17 ~9 ~64 ~32 ~9 coal_block
setblock ~64 ~17 ~10 concrete 15
fill ~64 ~17 ~72 ~65 ~17 ~72 coal_block
fill ~65 ~17 ~73 ~66 ~17 ~73 coal_block
setblock ~67 ~17 ~11 wool 15
setblock ~67 ~17 ~13 stone
fill ~68 ~17 ~69 ~68 ~23 ~69 coal_block
setblock ~69 ~17 ~13 concrete 7
fill ~69 ~17 ~18 ~70 ~17 ~18 coal_block
setblock ~69 ~17 ~68 stone
fill ~70 ~17 ~14 ~70 ~18 ~14 concrete 7
fill ~70 ~17 ~19 ~70 ~33 ~19 coal_block
fill ~70 ~17 ~69 ~70 ~32 ~69 coal_block
fill ~71 ~17 ~20 ~71 ~25 ~20 coal_block
fill ~71 ~17 ~66 ~71 ~20 ~66 coal_block
fill ~71 ~17 ~68 ~71 ~31 ~68 coal_block
fill ~72 ~17 ~16 ~72 ~19 ~16 coal_block
fill ~72 ~17 ~21 ~72 ~18 ~21 coal_block
fill ~72 ~17 ~22 ~72 ~26 ~22 coal_block
fill ~72 ~17 ~64 ~72 ~19 ~64 coal_block
setblock ~72 ~17 ~65 stone
fill ~73 ~17 ~17 ~73 ~19 ~17 coal_block
setblock ~73 ~17 ~19 stone
fill ~73 ~17 ~20 ~73 ~20 ~20 coal_block
fill ~73 ~17 ~23 ~73 ~20 ~23 coal_block
setblock ~73 ~17 ~24 stone
fill ~73 ~17 ~65 ~73 ~32 ~65 coal_block
fill ~73 ~17 ~66 ~73 ~21 ~66 coal_block
fill ~74 ~17 ~24 ~74 ~18 ~24 coal_block
fill ~74 ~17 ~25 ~74 ~21 ~25 coal_block
fill ~74 ~17 ~26 ~74 ~17 ~24 coal_block
fill ~74 ~17 ~64 ~74 ~31 ~64 coal_block
setblock ~75 ~17 ~21 stone
setblock ~75 ~17 ~26 stone
fill ~75 ~17 ~27 ~75 ~17 ~28 coal_block
fill ~75 ~17 ~60 ~75 ~27 ~60 coal_block
setblock ~75 ~17 ~61 stone
fill ~75 ~17 ~62 ~75 ~31 ~62 coal_block
fill ~75 ~17 ~63 ~75 ~18 ~63 coal_block
setblock ~76 ~17 ~21 concrete 15
fill ~76 ~17 ~29 ~76 ~33 ~29 coal_block
setblock ~76 ~17 ~58 coal_block
fill ~76 ~17 ~61 ~76 ~31 ~61 coal_block
fill ~77 ~17 ~23 ~77 ~20 ~23 coal_block
fill ~77 ~17 ~26 ~77 ~18 ~26 coal_block
fill ~77 ~17 ~55 ~77 ~25 ~55 coal_block
fill ~77 ~17 ~57 ~78 ~17 ~57 coal_block
setblock ~77 ~17 ~58 stone
fill ~77 ~17 ~59 ~77 ~23 ~59 coal_block
fill ~77 ~17 ~60 ~77 ~32 ~60 coal_block
setblock ~78 ~17 ~28 coal_block
fill ~78 ~17 ~52 ~80 ~17 ~52 coal_block
setblock ~78 ~17 ~54 stone
fill ~78 ~17 ~56 ~78 ~20 ~56 coal_block
fill ~78 ~17 ~58 ~78 ~32 ~58 coal_block
setblock ~79 ~17 ~32 stone
fill ~79 ~17 ~47 ~79 ~19 ~47 coal_block
fill ~79 ~17 ~49 ~80 ~17 ~49 coal_block
fill ~79 ~17 ~50 ~79 ~21 ~50 coal_block
fill ~79 ~17 ~53 ~79 ~31 ~53 coal_block
fill ~79 ~17 ~54 ~79 ~19 ~54 coal_block
fill ~79 ~17 ~55 ~79 ~20 ~55 coal_block
fill ~80 ~17 ~32 ~80 ~24 ~32 coal_block
fill ~80 ~17 ~43 ~81 ~17 ~43 coal_block
fill ~80 ~17 ~44 ~80 ~17 ~31 coal_block
fill ~80 ~17 ~46 ~80 ~22 ~46 coal_block
setblock ~80 ~17 ~47 stone
fill ~80 ~17 ~48 ~80 ~30 ~48 coal_block
fill ~80 ~17 ~51 ~80 ~31 ~51 coal_block
fill ~81 ~17 ~47 ~81 ~32 ~47 coal_block
setblock ~2 ~18 ~42 concrete 15
fill ~2 ~18 ~43 ~3 ~18 ~43 coal_block
fill ~2 ~18 ~45 ~2 ~19 ~45 concrete 15
fill ~2 ~18 ~46 ~3 ~18 ~46 coal_block
setblock ~3 ~18 ~35 coal_block
setblock ~3 ~18 ~36 stone
setblock ~3 ~18 ~40 stone
setblock ~3 ~18 ~41 concrete 15
fill ~3 ~18 ~45 ~3 ~32 ~45 coal_block
setblock ~3 ~18 ~47 coal_block
fill ~3 ~18 ~49 ~4 ~18 ~49 coal_block
fill ~3 ~18 ~50 ~4 ~18 ~50 coal_block
fill ~3 ~18 ~51 ~4 ~18 ~51 coal_block
setblock ~3 ~18 ~52 wool 15
fill ~4 ~18 ~33 ~4 ~23 ~33 coal_block
fill ~4 ~18 ~34 ~4 ~18 ~35 concrete 15
setblock ~4 ~18 ~47 stone
fill ~4 ~18 ~52 ~4 ~18 ~55 coal_block
fill ~5 ~18 ~27 ~5 ~19 ~27 coal_block
fill ~5 ~18 ~30 ~5 ~23 ~30 coal_block
fill ~5 ~18 ~53 ~5 ~22 ~53 coal_block
fill ~5 ~18 ~54 ~5 ~19 ~54 coal_block
setblock ~5 ~18 ~56 concrete 7
setblock ~5 ~18 ~58 coal_block
setblock ~6 ~18 ~26 stone
setblock ~6 ~18 ~29 stone
fill ~6 ~18 ~55 ~6 ~32 ~55 coal_block
fill ~6 ~18 ~56 ~6 ~21 ~56 coal_block
setblock ~6 ~18 ~58 stone
fill ~6 ~18 ~59 ~6 ~23 ~59 concrete 15
setblock ~7 ~18 ~23 stone
fill ~7 ~18 ~25 ~7 ~19 ~25 coal_block
fill ~7 ~18 ~26 ~9 ~18 ~26 coal_block
setblock ~7 ~18 ~27 stone
setblock ~7 ~18 ~28 coal_block
fill ~8 ~18 ~20 ~8 ~19 ~20 coal_block
setblock ~8 ~18 ~22 stone
fill ~8 ~18 ~24 ~9 ~18 ~24 coal_block
setblock ~8 ~18 ~25 stone
fill ~9 ~18 ~22 ~11 ~18 ~22 coal_block
setblock ~9 ~18 ~23 stone
fill ~9 ~18 ~62 ~9 ~21 ~62 concrete 15
fill ~10 ~18 ~21 ~10 ~19 ~21 coal_block
setblock ~10 ~18 ~24 stone
setblock ~10 ~18 ~64 coal_block
fill ~11 ~18 ~16 ~11 ~21 ~16 coal_block
setblock ~11 ~18 ~18 stone
setblock ~11 ~18 ~20 stone
fill ~11 ~18 ~65 ~11 ~23 ~65 coal_block
fill ~12 ~18 ~18 ~12 ~18 ~20 coal_block
fill ~13 ~18 ~14 ~13 ~20 ~14 concrete 15
setblock ~13 ~18 ~17 coal_block
setblock ~13 ~18 ~18 stone
fill ~13 ~18 ~19 ~13 ~26 ~19 coal_block
fill ~14 ~18 ~18 ~14 ~33 ~18 coal_block
fill ~15 ~18 ~14 ~15 ~30 ~14 coal_block
fill ~16 ~18 ~13 ~16 ~20 ~13 coal_block
fill ~17 ~18 ~12 ~17 ~28 ~12 coal_block
fill ~17 ~18 ~73 ~18 ~18 ~73 coal_block
fill ~18 ~18 ~9 ~18 ~19 ~9 concrete 15
setblock ~18 ~18 ~10 stone
fill ~18 ~18 ~72 ~19 ~18 ~72 coal_block
setblock ~19 ~18 ~10 concrete 15
setblock ~21 ~18 ~74 stone
setblock ~22 ~18 ~8 stone
setblock ~22 ~18 ~75 stone
setblock ~24 ~18 ~7 stone
fill ~25 ~18 ~5 ~27 ~18 ~5 coal_block
setblock ~25 ~18 ~6 stone
fill ~25 ~18 ~78 ~27 ~18 ~78 coal_block
fill ~28 ~18 ~4 ~32 ~18 ~4 coal_block
setblock ~28 ~18 ~78 stone
fill ~28 ~18 ~79 ~30 ~18 ~79 coal_block
setblock ~29 ~18 ~5 stone
fill ~29 ~18 ~29 ~58 ~18 ~29 tnt
fill ~29 ~18 ~30 ~58 ~18 ~30 tnt
fill ~29 ~18 ~31 ~58 ~18 ~31 tnt
fill ~29 ~18 ~32 ~58 ~18 ~32 tnt
fill ~29 ~18 ~33 ~58 ~18 ~33 tnt
fill ~29 ~18 ~34 ~58 ~18 ~34 tnt
fill ~29 ~18 ~35 ~58 ~18 ~35 tnt
fill ~29 ~18 ~36 ~58 ~18 ~36 tnt
fill ~29 ~18 ~37 ~58 ~18 ~37 tnt
fill ~29 ~18 ~38 ~58 ~18 ~38 tnt
fill ~29 ~18 ~39 ~58 ~18 ~39 tnt
fill ~29 ~18 ~40 ~58 ~18 ~40 tnt
fill ~29 ~18 ~41 ~58 ~18 ~41 tnt
fill ~29 ~18 ~42 ~58 ~18 ~42 tnt
fill ~29 ~18 ~43 ~58 ~18 ~43 tnt
fill ~29 ~18 ~44 ~58 ~18 ~44 tnt
fill ~29 ~18 ~45 ~58 ~18 ~45 tnt
fill ~29 ~18 ~46 ~58 ~18 ~46 tnt
fill ~29 ~18 ~47 ~58 ~18 ~47 tnt
fill ~29 ~18 ~48 ~58 ~18 ~48 tnt
fill ~29 ~18 ~49 ~58 ~18 ~49 tnt
fill ~29 ~18 ~50 ~58 ~18 ~50 tnt
fill ~29 ~18 ~51 ~58 ~18 ~51 tnt
fill ~29 ~18 ~52 ~58 ~18 ~52 tnt
fill ~29 ~18 ~53 ~58 ~18 ~53 tnt
fill ~29 ~18 ~54 ~58 ~18 ~54 tnt
fill ~29 ~18 ~55 ~58 ~18 ~55 tnt
fill ~29 ~18 ~56 ~58 ~18 ~56 tnt
fill ~29 ~18 ~57 ~58 ~18 ~57 tnt
fill ~29 ~18 ~58 ~58 ~18 ~58 tnt
fill ~30 ~18 ~5 ~31 ~18 ~5 coal_block
setblock ~30 ~18 ~78 stone
fill ~31 ~18 ~3 ~31 ~32 ~3 coal_block
fill ~31 ~18 ~80 ~36 ~18 ~80 coal_block
fill ~33 ~18 ~3 ~35 ~18 ~3 coal_block
setblock ~33 ~18 ~4 stone
fill ~34 ~18 ~4 ~36 ~18 ~4 coal_block
fill ~35 ~18 ~78 ~40 ~18 ~78 coal_block
fill ~36 ~18 ~2 ~47 ~18 ~2 coal_block
setblock ~36 ~18 ~3 stone
fill ~36 ~18 ~79 ~37 ~18 ~79 coal_block
fill ~36 ~18 ~81 ~41 ~18 ~81 coal_block
fill ~37 ~18 ~3 ~52 ~18 ~3 coal_block
setblock ~37 ~18 ~80 stone
setblock ~38 ~18 ~79 stone
setblock ~38 ~18 ~80 coal_block
fill ~39 ~18 ~79 ~40 ~18 ~79 coal_block
setblock ~39 ~18 ~80 stone
fill ~40 ~18 ~80 ~40 ~16 ~80 coal_block
setblock ~41 ~18 ~78 stone
setblock ~41 ~18 ~79 concrete 15
setblock ~41 ~18 ~80 stone
fill ~42 ~18 ~78 ~48 ~18 ~78 coal_block
setblock ~42 ~18 ~79 stone
setblock ~42 ~18 ~80 coal_block
fill ~42 ~18 ~81 ~45 ~18 ~81 concrete 15
fill ~43 ~18 ~79 ~45 ~18 ~79 coal_block
setblock ~43 ~18 ~80 stone
setblock ~44 ~18 ~80 coal_block
setblock ~45 ~18 ~80 stone
setblock ~46 ~18 ~79 stone
fill ~46 ~18 ~80 ~46 ~18 ~81 coal_block
fill ~47 ~18 ~4 ~48 ~18 ~4 coal_block
setblock ~47 ~18 ~79 coal_block
setblock ~47 ~18 ~80 stone
fill ~47 ~18 ~81 ~48 ~18 ~81 coal_block
setblock ~48 ~18 ~79 stone
fill ~48 ~18 ~80 ~52 ~18 ~80 coal_block
setblock ~49 ~18 ~4 stone
fill ~50 ~18 ~4 ~55 ~18 ~4 coal_block
setblock ~50 ~18 ~79 stone
fill ~52 ~18 ~5 ~53 ~18 ~5 coal_block
fill ~52 ~18 ~78 ~52 ~19 ~78 coal_block
setblock ~53 ~18 ~78 stone
fill ~53 ~18 ~79 ~55 ~18 ~79 coal_block
setblock ~54 ~18 ~5 stone
fill ~55 ~18 ~6 ~60 ~18 ~6 coal_block
setblock ~55 ~18 ~78 coal_block
fill ~56 ~18 ~5 ~58 ~18 ~5 coal_block
setblock ~56 ~18 ~77 stone
fill ~57 ~18 ~78 ~58 ~18 ~78 coal_block
fill ~58 ~18 ~76 ~58 ~21 ~76 concrete 15
setblock ~58 ~18 ~77 stone
setblock ~59 ~18 ~7 stone
setblock ~59 ~18 ~76 stone
setblock ~60 ~18 ~76 coal_block
setblock ~61 ~18 ~7 concrete 7
fill ~61 ~18 ~74 ~62 ~18 ~74 coal_block
fill ~61 ~18 ~75 ~61 ~18 ~74 coal_block
setblock ~62 ~18 ~9 stone
setblock ~64 ~18 ~10 coal_block
fill ~64 ~18 ~72 ~64 ~20 ~72 coal_block
fill ~64 ~18 ~74 ~64 ~19 ~74 concrete 15
setblock ~65 ~18 ~72 stone
fill ~65 ~18 ~73 ~66 ~18 ~73 coal_block
setblock ~67 ~18 ~11 concrete 7
fill ~67 ~18 ~13 ~67 ~32 ~13 coal_block
fill ~68 ~18 ~12 ~68 ~31 ~12 coal_block
fill ~69 ~18 ~13 ~69 ~31 ~13 coal_block
fill ~69 ~18 ~18 ~70 ~18 ~18 coal_block
setblock ~69 ~18 ~68 coal_block
setblock ~70 ~18 ~17 stone
setblock ~71 ~18 ~18 stone
setblock ~71 ~18 ~19 coal_block
setblock ~71 ~18 ~21 stone
setblock ~72 ~18 ~19 stone
setblock ~72 ~18 ~20 coal_block
fill ~72 ~18 ~65 ~72 ~20 ~65 coal_block
fill ~73 ~18 ~19 ~73 ~19 ~19 coal_block
setblock ~73 ~18 ~21 stone
setblock ~73 ~18 ~22 concrete 15
fill ~73 ~18 ~24 ~73 ~21 ~24 coal_block
fill ~74 ~18 ~21 ~76 ~18 ~21 coal_block
fill ~74 ~18 ~22 ~74 ~20 ~22 coal_block
fill ~74 ~18 ~23 ~74 ~23 ~23 coal_block
setblock ~75 ~18 ~22 stone
fill ~75 ~18 ~24 ~75 ~19 ~24 coal_block
fill ~75 ~18 ~25 ~75 ~18 ~26 coal_block
setblock ~75 ~18 ~27 stone
fill ~75 ~18 ~28 ~77 ~18 ~28 coal_block
fill ~75 ~18 ~61 ~75 ~23 ~61 coal_block
setblock ~76 ~18 ~23 stone
setblock ~76 ~18 ~26 stone
setblock ~76 ~18 ~27 coal_block
setblock ~76 ~18 ~58 stone
setblock ~77 ~18 ~27 stone
setblock ~77 ~18 ~29 stone
fill ~77 ~18 ~57 ~78 ~18 ~57 coal_block
fill ~77 ~18 ~58 ~77 ~18 ~55 coal_block
setblock ~78 ~18 ~28 stone
fill ~78 ~18 ~52 ~78 ~32 ~52 coal_block
fill ~78 ~18 ~54 ~78 ~22 ~54 coal_block
fill ~79 ~18 ~32 ~79 ~19 ~32 concrete 15
fill ~79 ~18 ~49 ~80 ~18 ~49 coal_block
setblock ~79 ~18 ~52 stone
setblock ~80 ~18 ~35 stone
setblock ~80 ~18 ~39 concrete 15
setblock ~80 ~18 ~40 stone
fill ~80 ~18 ~43 ~81 ~18 ~43 coal_block
setblock ~80 ~18 ~44 stone
setblock ~80 ~18 ~47 coal_block
fill ~80 ~18 ~52 ~80 ~31 ~52 coal_block
fill ~2 ~19 ~42 ~2 ~32 ~42 coal_block
fill ~2 ~19 ~43 ~2 ~32 ~43 coal_block
fill ~2 ~19 ~46 ~2 ~21 ~46 concrete 15
setblock ~3 ~19 ~35 stone
fill ~3 ~19 ~36 ~3 ~32 ~36 coal_block
fill ~3 ~19 ~40 ~3 ~24 ~40 coal_block
fill ~3 ~19 ~41 ~3 ~21 ~41 coal_block
setblock ~3 ~19 ~43 stone
fill ~3 ~19 ~46 ~3 ~21 ~46 coal_block
setblock ~3 ~19 ~47 stone
fill ~3 ~19 ~49 ~4 ~19 ~49 coal_block
fill ~3 ~19 ~50 ~3 ~17 ~50 coal_block
fill ~3 ~19 ~51 ~4 ~19 ~51 coal_block
setblock ~3 ~19 ~52 concrete 7
setblock ~4 ~19 ~30 concrete 7
setblock ~4 ~19 ~32 stone
fill ~4 ~19 ~34 ~4 ~20 ~34 coal_block
setblock ~4 ~19 ~35 concrete 15
fill ~4 ~19 ~47 ~4 ~25 ~47 coal_block
setblock ~4 ~19 ~50 stone
setblock ~4 ~19 ~52 stone
fill ~4 ~19 ~53 ~4 ~19 ~55 coal_block
fill ~5 ~19 ~56 ~5 ~26 ~56 coal_block
setblock ~5 ~19 ~58 concrete 15
setblock ~6 ~19 ~25 concrete 7
setblock ~6 ~19 ~26 coal_block
setblock ~6 ~19 ~27 stone
fill ~6 ~19 ~29 ~6 ~22 ~29 coal_block
setblock ~6 ~19 ~57 stone
setblock ~6 ~19 ~58 coal_block
setblock ~7 ~19 ~22 concrete 15
setblock ~7 ~19 ~23 coal_block
setblock ~7 ~19 ~24 stone
setblock ~7 ~19 ~26 stone
fill ~7 ~19 ~27 ~7 ~21 ~27 coal_block
fill ~8 ~19 ~22 ~9 ~19 ~22 coal_block
setblock ~8 ~19 ~23 stone
fill ~8 ~19 ~24 ~8 ~22 ~24 coal_block
fill ~8 ~19 ~25 ~8 ~22 ~25 coal_block
fill ~8 ~19 ~61 ~8 ~20 ~61 coal_block
setblock ~9 ~19 ~23 coal_block
fill ~9 ~19 ~26 ~9 ~26 ~26 coal_block
fill ~10 ~19 ~24 ~10 ~22 ~24 coal_block
setblock ~10 ~19 ~64 stone
setblock ~11 ~19 ~18 coal_block
setblock ~11 ~19 ~20 coal_block
fill ~12 ~19 ~17 ~12 ~29 ~17 coal_block
setblock ~12 ~19 ~18 stone
fill ~13 ~19 ~16 ~13 ~32 ~16 coal_block
setblock ~13 ~19 ~17 concrete 15
setblock ~13 ~19 ~18 coal_block
setblock ~13 ~19 ~67 stone
fill ~14 ~19 ~13 ~14 ~20 ~13 concrete 15
fill ~14 ~19 ~15 ~14 ~32 ~15 coal_block
fill ~15 ~19 ~12 ~15 ~21 ~12 concrete 15
fill ~17 ~19 ~73 ~18 ~19 ~73 coal_block
setblock ~18 ~19 ~10 concrete 15
fill ~18 ~19 ~72 ~19 ~19 ~72 coal_block
setblock ~19 ~19 ~10 stone
fill ~21 ~19 ~74 ~21 ~23 ~74 coal_block
setblock ~22 ~19 ~8 coal_block
setblock ~22 ~19 ~75 coal_block
fill ~24 ~19 ~7 ~24 ~22 ~7 coal_block
fill ~25 ~19 ~5 ~27 ~19 ~5 coal_block
fill ~25 ~19 ~6 ~25 ~20 ~6 coal_block
fill ~25 ~19 ~78 ~31 ~19 ~78 coal_block
setblock ~26 ~19 ~6 stone
setblock ~27 ~19 ~77 stone
fill ~28 ~19 ~4 ~30 ~19 ~4 coal_block
fill ~28 ~19 ~79 ~30 ~19 ~79 coal_block
fill ~29 ~19 ~5 ~31 ~19 ~5 coal_block
fill ~29 ~19 ~29 ~58 ~19 ~29 tnt
fill ~29 ~19 ~30 ~58 ~19 ~30 tnt
fill ~29 ~19 ~31 ~58 ~19 ~31 tnt
fill ~29 ~19 ~32 ~58 ~19 ~32 tnt
fill ~29 ~19 ~33 ~58 ~19 ~33 tnt
fill ~29 ~19 ~34 ~58 ~19 ~34 tnt
fill ~29 ~19 ~35 ~58 ~19 ~35 tnt
fill ~29 ~19 ~36 ~58 ~19 ~36 tnt
fill ~29 ~19 ~37 ~58 ~19 ~37 tnt
fill ~29 ~19 ~38 ~58 ~19 ~38 tnt
fill ~29 ~19 ~39 ~58 ~19 ~39 tnt
fill ~29 ~19 ~40 ~58 ~19 ~40 tnt
fill ~29 ~19 ~41 ~58 ~19 ~41 tnt
fill ~29 ~19 ~42 ~58 ~19 ~42 tnt
fill ~29 ~19 ~43 ~58 ~19 ~43 tnt
fill ~29 ~19 ~44 ~58 ~19 ~44 tnt
fill ~29 ~19 ~45 ~58 ~19 ~45 tnt
fill ~29 ~19 ~46 ~58 ~19 ~46 tnt
fill ~29 ~19 ~47 ~58 ~19 ~47 tnt
fill ~29 ~19 ~48 ~58 ~19 ~48 tnt
fill ~29 ~19 ~49 ~58 ~19 ~49 tnt
fill ~29 ~19 ~50 ~58 ~19 ~50 tnt
fill ~29 ~19 ~51 ~58 ~19 ~51 tnt
fill ~29 ~19 ~52 ~58 ~19 ~52 tnt
fill ~29 ~19 ~53 ~58 ~19 ~53 tnt
fill ~29 ~19 ~54 ~58 ~19 ~54 tnt
fill ~29 ~19 ~55 ~58 ~19 ~55 tnt
fill ~29 ~19 ~56 ~58 ~19 ~56 tnt
fill ~29 ~19 ~57 ~58 ~19 ~57 tnt
fill ~29 ~19 ~58 ~58 ~19 ~58 tnt
setblock ~31 ~19 ~4 stone
fill ~31 ~19 ~80 ~35 ~19 ~80 coal_block
fill ~32 ~19 ~4 ~36 ~19 ~4 coal_block
fill ~33 ~19 ~3 ~38 ~19 ~3 coal_block
setblock ~33 ~19 ~79 stone
fill ~35 ~19 ~78 ~37 ~19 ~78 coal_block
setblock ~35 ~19 ~79 stone
fill ~36 ~19 ~2 ~40 ~19 ~2 coal_block
fill ~36 ~19 ~79 ~36 ~18 ~79 coal_block
setblock ~36 ~19 ~80 stone
fill ~36 ~19 ~81 ~36 ~20 ~81 coal_block
setblock ~37 ~19 ~79 stone
setblock ~37 ~19 ~80 coal_block
setblock ~37 ~19 ~81 concrete 15
setblock ~38 ~19 ~78 concrete 15
setblock ~38 ~19 ~79 coal_block
setblock ~38 ~19 ~80 stone
fill ~38 ~19 ~81 ~41 ~19 ~81 coal_block
setblock ~39 ~19 ~3 stone
fill ~39 ~19 ~78 ~40 ~19 ~78 coal_block
setblock ~39 ~19 ~79 stone
setblock ~39 ~19 ~80 coal_block
fill ~40 ~19 ~3 ~46 ~19 ~3 coal_block
setblock ~40 ~19 ~79 coal_block
setblock ~40 ~19 ~80 stone
setblock ~41 ~19 ~2 concrete 15
setblock ~41 ~19 ~78 concrete 15
setblock ~41 ~19 ~79 stone
setblock ~41 ~19 ~80 coal_block
fill ~42 ~19 ~2 ~47 ~19 ~2 coal_block
fill ~42 ~19 ~78 ~47 ~19 ~78 coal_block
fill ~42 ~19 ~79 ~42 ~19 ~78 coal_block
setblock ~42 ~19 ~80 stone
fill ~42 ~19 ~81 ~45 ~19 ~81 concrete 15
setblock ~43 ~19 ~79 stone
setblock ~43 ~19 ~80 coal_block
setblock ~44 ~19 ~79 coal_block
setblock ~44 ~19 ~80 stone
setblock ~45 ~19 ~79 stone
setblock ~45 ~19 ~80 coal_block
setblock ~46 ~19 ~79 concrete 15
setblock ~46 ~19 ~80 stone
fill ~46 ~19 ~81 ~48 ~19 ~81 coal_block
setblock ~47 ~19 ~3 stone
fill ~47 ~19 ~4 ~51 ~19 ~4 coal_block
setblock ~47 ~19 ~79 stone
setblock ~47 ~19 ~80 coal_block
fill ~48 ~19 ~3 ~52 ~19 ~3 coal_block
setblock ~48 ~19 ~78 concrete 15
setblock ~48 ~19 ~79 coal_block
setblock ~48 ~19 ~80 stone
fill ~49 ~19 ~80 ~52 ~19 ~80 coal_block
fill ~50 ~19 ~79 ~50 ~20 ~79 coal_block
setblock ~52 ~19 ~4 stone
fill ~52 ~19 ~5 ~54 ~19 ~5 coal_block
fill ~53 ~19 ~78 ~54 ~19 ~78 concrete 15
fill ~53 ~19 ~79 ~55 ~19 ~79 coal_block
fill ~54 ~19 ~4 ~55 ~19 ~4 coal_block
fill ~55 ~19 ~6 ~55 ~21 ~6 concrete 15
setblock ~55 ~19 ~78 stone
fill ~56 ~19 ~5 ~58 ~19 ~5 coal_block
setblock ~56 ~19 ~6 stone
fill ~56 ~19 ~77 ~60 ~19 ~77 coal_block
fill ~57 ~19 ~6 ~57 ~21 ~6 coal_block
fill ~57 ~19 ~78 ~58 ~19 ~78 coal_block
setblock ~58 ~19 ~6 stone
fill ~59 ~19 ~7 ~59 ~22 ~7 coal_block
setblock ~59 ~19 ~76 concrete 15
setblock ~60 ~19 ~76 stone
fill ~61 ~19 ~7 ~61 ~32 ~7 coal_block
fill ~61 ~19 ~74 ~61 ~32 ~74 coal_block
setblock ~61 ~19 ~75 stone
fill ~62 ~19 ~9 ~62 ~21 ~9 coal_block
setblock ~62 ~19 ~74 stone
fill ~63 ~19 ~73 ~63 ~29 ~73 coal_block
setblock ~64 ~19 ~10 stone
fill ~65 ~19 ~72 ~65 ~32 ~72 coal_block
fill ~65 ~19 ~73 ~66 ~19 ~73 concrete 15
fill ~66 ~19 ~71 ~66 ~20 ~71 concrete 15
fill ~67 ~19 ~11 ~67 ~32 ~11 coal_block
setblock ~67 ~19 ~70 concrete 15
fill ~69 ~19 ~18 ~69 ~27 ~18 coal_block
setblock ~69 ~19 ~68 concrete 15
setblock ~69 ~19 ~70 concrete 15
fill ~70 ~19 ~14 ~70 ~23 ~14 coal_block
setblock ~70 ~19 ~17 coal_block
setblock ~70 ~19 ~18 stone
fill ~71 ~19 ~18 ~71 ~21 ~18 coal_block
fill ~71 ~19 ~21 ~71 ~31 ~21 coal_block
fill ~72 ~19 ~19 ~72 ~33 ~19 coal_block
setblock ~72 ~19 ~20 stone
fill ~73 ~19 ~21 ~74 ~19 ~21 coal_block
fill ~74 ~19 ~26 ~76 ~19 ~26 coal_block
setblock ~75 ~19 ~21 stone
setblock ~75 ~19 ~22 coal_block
setblock ~75 ~19 ~23 stone
setblock ~75 ~19 ~25 stone
fill ~75 ~19 ~27 ~75 ~33 ~27 coal_block
fill ~75 ~19 ~28 ~75 ~26 ~28 coal_block
setblock ~75 ~19 ~63 concrete 7
fill ~76 ~19 ~21 ~76 ~32 ~21 coal_block
fill ~76 ~19 ~23 ~76 ~20 ~23 coal_block
setblock ~76 ~19 ~24 stone
setblock ~76 ~19 ~27 stone
fill ~76 ~19 ~58 ~76 ~23 ~58 coal_block
setblock ~77 ~19 ~26 stone
setblock ~77 ~19 ~27 coal_block
fill ~77 ~19 ~29 ~77 ~21 ~29 coal_block
fill ~77 ~19 ~57 ~78 ~19 ~57 coal_block
setblock ~77 ~19 ~58 stone
setblock ~78 ~19 ~28 coal_block
setblock ~78 ~19 ~29 stone
setblock ~79 ~19 ~31 stone
setblock ~79 ~19 ~35 concrete 15
fill ~79 ~19 ~49 ~80 ~19 ~49 coal_block
setblock ~79 ~19 ~51 stone
setblock ~79 ~19 ~52 coal_block
setblock ~80 ~19 ~35 coal_block
setblock ~80 ~19 ~36 stone
fill ~80 ~19 ~37 ~80 ~22 ~37 concrete 15
fill ~80 ~19 ~39 ~80 ~20 ~39 coal_block
fill ~80 ~19 ~40 ~80 ~21 ~40 coal_block
fill ~80 ~19 ~43 ~81 ~19 ~43 coal_block
fill ~80 ~19 ~44 ~80 ~21 ~44 coal_block
setblock ~80 ~19 ~47 stone
fill ~2 ~20 ~45 ~2 ~32 ~45 coal_block
fill ~2 ~20 ~47 ~2 ~21 ~47 concrete 15
fill ~3 ~20 ~35 ~4 ~20 ~35 coal_block
setblock ~3 ~20 ~42 concrete 15
fill ~3 ~20 ~43 ~3 ~23 ~43 coal_block
setblock ~3 ~20 ~47 coal_block
fill ~3 ~20 ~49 ~4 ~20 ~49 coal_block
fill ~3 ~20 ~50 ~3 ~23 ~50 concrete 7
fill ~3 ~20 ~51 ~4 ~20 ~51 coal_block
fill ~3 ~20 ~52 ~5 ~20 ~52 coal_block
fill ~4 ~20 ~30 ~4 ~22 ~30 coal_block
fill ~4 ~20 ~32 ~4 ~23 ~32 coal_block
fill ~4 ~20 ~50 ~4 ~24 ~50 coal_block
setblock ~4 ~20 ~53 concrete 15
fill ~4 ~20 ~54 ~4 ~23 ~54 coal_block
fill ~5 ~20 ~26 ~5 ~22 ~26 cyan_glazed_terracotta
setblock ~5 ~20 ~27 concrete 7
setblock ~5 ~20 ~54 stone
setblock ~5 ~20 ~58 coal_block
fill ~6 ~20 ~24 ~6 ~23 ~24 cyan_glazed_terracotta
setblock ~6 ~20 ~25 coal_ore
setblock ~6 ~20 ~26 stone
setblock ~6 ~20 ~27 wool 15
fill ~6 ~20 ~57 ~6 ~32 ~57 coal_block
setblock ~6 ~20 ~58 stone
fill ~7 ~20 ~22 ~9 ~20 ~22 coal_block
setblock ~7 ~20 ~23 stone
setblock ~7 ~20 ~24 coal_block
setblock ~7 ~20 ~25 stone
fill ~7 ~20 ~26 ~7 ~22 ~26 coal_block
fill ~8 ~20 ~20 ~8 ~21 ~20 concrete 7
setblock ~8 ~20 ~23 coal_block
setblock ~9 ~20 ~19 cyan_glazed_terracotta
setblock ~9 ~20 ~23 stone
setblock ~10 ~20 ~17 concrete 7
fill ~10 ~20 ~18 ~10 ~21 ~18 coal_ore
fill ~10 ~20 ~20 ~10 ~21 ~20 concrete 7
setblock ~10 ~20 ~21 stone
setblock ~10 ~20 ~64 coal_block
setblock ~11 ~20 ~18 wool 15
setblock ~11 ~20 ~20 stone
setblock ~11 ~20 ~64 stone
fill ~12 ~20 ~18 ~12 ~22 ~18 coal_block
setblock ~12 ~20 ~21 stone
setblock ~13 ~20 ~17 coal_block
setblock ~13 ~20 ~18 stone
fill ~13 ~20 ~67 ~13 ~22 ~67 coal_block
fill ~16 ~20 ~11 ~16 ~21 ~11 concrete 15
fill ~17 ~20 ~73 ~18 ~20 ~73 coal_block
fill ~18 ~20 ~9 ~18 ~32 ~9 coal_block
setblock ~18 ~20 ~10 stone
fill ~18 ~20 ~72 ~18 ~32 ~72 coal_block
setblock ~19 ~20 ~9 concrete 15
fill ~19 ~20 ~10 ~19 ~22 ~10 coal_block
setblock ~19 ~20 ~72 stone
setblock ~21 ~20 ~9 stone
setblock ~22 ~20 ~8 stone
setblock ~22 ~20 ~75 stone
setblock ~24 ~20 ~76 stone
fill ~25 ~20 ~5 ~27 ~20 ~5 coal_block
fill ~25 ~20 ~78 ~27 ~20 ~78 coal_block
fill ~26 ~20 ~6 ~26 ~32 ~6 coal_block
fill ~27 ~20 ~77 ~27 ~22 ~77 coal_block
fill ~28 ~20 ~4 ~34 ~20 ~4 coal_block
setblock ~28 ~20 ~78 stone
fill ~28 ~20 ~79 ~30 ~20 ~79 coal_block
fill ~29 ~20 ~5 ~31 ~20 ~5 coal_block
fill ~29 ~20 ~29 ~58 ~20 ~29 tnt
fill ~29 ~20 ~30 ~58 ~20 ~30 tnt
fill ~29 ~20 ~31 ~58 ~20 ~31 tnt
fill ~29 ~20 ~32 ~58 ~20 ~32 tnt
fill ~29 ~20 ~33 ~58 ~20 ~33 tnt
fill ~29 ~20 ~34 ~58 ~20 ~34 tnt
fill ~29 ~20 ~35 ~58 ~20 ~35 tnt
fill ~29 ~20 ~36 ~58 ~20 ~36 tnt
fill ~29 ~20 ~37 ~58 ~20 ~37 tnt
fill ~29 ~20 ~38 ~58 ~20 ~38 tnt
fill ~29 ~20 ~39 ~58 ~20 ~39 tnt
fill ~29 ~20 ~40 ~58 ~20 ~40 tnt
fill ~29 ~20 ~41 ~58 ~20 ~41 tnt
fill ~29 ~20 ~42 ~58 ~20 ~42 tnt
fill ~29 ~20 ~43 ~58 ~20 ~43 tnt
fill ~29 ~20 ~44 ~58 ~20 ~44 tnt
fill ~29 ~20 ~45 ~58 ~20 ~45 tnt
fill ~29 ~20 ~46 ~58 ~20 ~46 tnt
fill ~29 ~20 ~47 ~58 ~20 ~47 tnt
fill ~29 ~20 ~48 ~58 ~20 ~48 tnt
fill ~29 ~20 ~49 ~58 ~20 ~49 tnt
fill ~29 ~20 ~50 ~58 ~20 ~50 tnt
fill ~29 ~20 ~51 ~58 ~20 ~51 tnt
fill ~29 ~20 ~52 ~58 ~20 ~52 tnt
fill ~29 ~20 ~53 ~58 ~20 ~53 tnt
fill ~29 ~20 ~54 ~58 ~20 ~54 tnt
fill ~29 ~20 ~55 ~58 ~20 ~55 tnt
fill ~29 ~20 ~56 ~58 ~20 ~56 tnt
fill ~29 ~20 ~57 ~58 ~20 ~57 tnt
fill ~29 ~20 ~58 ~58 ~20 ~58 tnt
fill ~30 ~20 ~78 ~30 ~21 ~78 coal_block
fill ~31 ~20 ~80 ~36 ~20 ~80 coal_block
fill ~33 ~20 ~3 ~34 ~20 ~3 coal_block
fill ~33 ~20 ~79 ~33 ~32 ~79 coal_block
setblock ~35 ~20 ~3 concrete 15
setblock ~35 ~20 ~4 stone
fill ~35 ~20 ~78 ~44 ~20 ~78 coal_block
fill ~35 ~20 ~79 ~35 ~20 ~78 coal_block
fill ~36 ~20 ~2 ~47 ~20 ~2 coal_block
setblock ~36 ~20 ~3 stone
fill ~36 ~20 ~4 ~36 ~31 ~4 coal_block
setblock ~36 ~20 ~79 stone
fill ~37 ~20 ~3 ~45 ~20 ~3 coal_block
setblock ~37 ~20 ~79 coal_block
setblock ~37 ~20 ~80 stone
setblock ~37 ~20 ~81 coal_block
setblock ~38 ~20 ~79 stone
setblock ~38 ~20 ~80 coal_block
setblock ~38 ~20 ~81 concrete 15
setblock ~39 ~20 ~79 coal_block
setblock ~39 ~20 ~80 stone
fill ~39 ~20 ~81 ~41 ~20 ~81 coal_block
setblock ~40 ~20 ~79 stone
setblock ~40 ~20 ~80 coal_block
setblock ~41 ~20 ~79 coal_block
setblock ~41 ~20 ~80 stone
setblock ~42 ~20 ~79 stone
setblock ~42 ~20 ~80 coal_block
fill ~42 ~20 ~81 ~43 ~20 ~81 concrete 15
setblock ~43 ~20 ~79 concrete 15
setblock ~43 ~20 ~80 stone
setblock ~44 ~20 ~79 stone
fill ~44 ~20 ~80 ~44 ~20 ~81 coal_block
setblock ~45 ~20 ~78 stone
setblock ~45 ~20 ~79 coal_block
setblock ~45 ~20 ~80 stone
fill ~45 ~20 ~81 ~48 ~20 ~81 coal_block
setblock ~46 ~20 ~3 stone
fill ~46 ~20 ~78 ~48 ~20 ~78 coal_block
setblock ~46 ~20 ~79 stone
setblock ~46 ~20 ~80 concrete 15
fill ~47 ~20 ~3 ~52 ~20 ~3 coal_block
fill ~47 ~20 ~4 ~55 ~20 ~4 coal_block
setblock ~47 ~20 ~79 concrete 15
setblock ~47 ~20 ~80 stone
setblock ~48 ~20 ~79 stone
fill ~48 ~20 ~80 ~52 ~20 ~80 coal_block
fill ~49 ~20 ~79 ~49 ~24 ~79 concrete 15
setblock ~51 ~20 ~79 concrete 15
setblock ~52 ~20 ~5 stone
fill ~52 ~20 ~78 ~55 ~20 ~78 concrete 15
fill ~53 ~20 ~5 ~53 ~32 ~5 coal_block
fill ~53 ~20 ~79 ~55 ~20 ~79 coal_block
setblock ~54 ~20 ~5 concrete 15
fill ~55 ~20 ~77 ~57 ~20 ~77 concrete 15
fill ~56 ~20 ~5 ~57 ~20 ~5 coal_block
fill ~56 ~20 ~6 ~56 ~20 ~5 coal_block
fill ~57 ~20 ~78 ~58 ~20 ~78 coal_block
setblock ~58 ~20 ~5 concrete 15
setblock ~58 ~20 ~6 coal_block
setblock ~58 ~20 ~77 stone
fill ~59 ~20 ~76 ~61 ~20 ~76 coal_block
setblock ~61 ~20 ~75 coal_block
fill ~62 ~20 ~74 ~62 ~22 ~74 coal_block
fill ~64 ~20 ~10 ~64 ~22 ~10 coal_block
fill ~64 ~20 ~74 ~64 ~32 ~74 coal_block
fill ~65 ~20 ~73 ~66 ~20 ~73 coal_block
setblock ~67 ~20 ~70 coal_block
setblock ~69 ~20 ~15 concrete 15
setblock ~69 ~20 ~68 coal_block
fill ~69 ~20 ~70 ~69 ~32 ~70 coal_block
fill ~70 ~20 ~16 ~70 ~21 ~16 concrete 15
fill ~70 ~20 ~17 ~70 ~20 ~16 concrete 15
setblock ~70 ~20 ~18 coal_block
fill ~72 ~20 ~16 ~72 ~27 ~16 concrete 7
fill ~72 ~20 ~20 ~72 ~22 ~20 coal_block
setblock ~72 ~20 ~64 stone
setblock ~73 ~20 ~17 wool 15
setblock ~73 ~20 ~18 concrete 7
setblock ~73 ~20 ~19 stone
fill ~73 ~20 ~21 ~76 ~20 ~21 coal_block
fill ~74 ~20 ~26 ~74 ~33 ~26 coal_block
setblock ~75 ~20 ~22 stone
fill ~75 ~20 ~23 ~75 ~21 ~23 coal_block
setblock ~75 ~20 ~24 stone
setblock ~75 ~20 ~25 coal_block
fill ~75 ~20 ~63 ~75 ~31 ~63 coal_block
fill ~76 ~20 ~24 ~76 ~21 ~24 coal_block
setblock ~76 ~20 ~25 stone
fill ~76 ~20 ~26 ~78 ~20 ~26 coal_block
fill ~76 ~20 ~27 ~76 ~22 ~27 coal_block
setblock ~77 ~20 ~24 concrete 7
setblock ~77 ~20 ~25 wool 15
setblock ~77 ~20 ~27 stone
fill ~77 ~20 ~57 ~78 ~20 ~57 coal_block
fill ~77 ~20 ~58 ~77 ~20 ~55 coal_block
setblock ~78 ~20 ~28 stone
setblock ~78 ~20 ~29 coal_block
setblock ~78 ~20 ~53 stone
fill ~79 ~20 ~31 ~79 ~20 ~33 coal_block
setblock ~79 ~20 ~34 stone
fill ~79 ~20 ~35 ~79 ~22 ~35 coal_block
setblock ~79 ~20 ~47 stone
fill ~79 ~20 ~49 ~80 ~20 ~49 coal_block
fill ~79 ~20 ~51 ~79 ~24 ~51 coal_block
setblock ~79 ~20 ~52 stone
fill ~79 ~20 ~54 ~79 ~21 ~54 concrete 15
setblock ~80 ~20 ~35 stone
fill ~80 ~20 ~36 ~80 ~22 ~36 coal_block
setblock ~80 ~20 ~42 stone
fill ~80 ~20 ~43 ~81 ~20 ~43 coal_block
setblock ~80 ~20 ~47 coal_block
setblock ~80 ~20 ~50 concrete 15
setblock ~81 ~20 ~46 concrete 15
setblock ~2 ~21 ~38 concrete 15
setblock ~3 ~21 ~35 stone
setblock ~3 ~21 ~38 stone
fill ~3 ~21 ~42 ~3 ~27 ~42 coal_block
setblock ~3 ~21 ~47 stone
setblock ~3 ~21 ~49 concrete 7
setblock ~3 ~21 ~51 concrete 7
fill ~3 ~21 ~52 ~3 ~32 ~52 coal_block
fill ~4 ~21 ~28 ~4 ~23 ~28 concrete 15
setblock ~4 ~21 ~34 stone
fill ~4 ~21 ~35 ~4 ~26 ~35 coal_block
setblock ~4 ~21 ~48 stone
fill ~4 ~21 ~49 ~4 ~23 ~49 coal_block
setblock ~4 ~21 ~51 coal_block
setblock ~4 ~21 ~52 stone
fill ~4 ~21 ~53 ~4 ~31 ~53 coal_block
setblock ~5 ~21 ~27 coal_block
fill ~5 ~21 ~54 ~5 ~25 ~54 coal_block
fill ~5 ~21 ~57 ~5 ~21 ~58 concrete 15
fill ~6 ~21 ~23 ~7 ~21 ~23 concrete 7
setblock ~6 ~21 ~25 cyan_glazed_terracotta
setblock ~6 ~21 ~26 concrete 7
setblock ~6 ~21 ~27 stone
setblock ~6 ~21 ~58 coal_block
fill ~7 ~21 ~22 ~9 ~21 ~22 coal_block
setblock ~7 ~21 ~24 stone
setblock ~7 ~21 ~25 concrete 7
setblock ~7 ~21 ~59 stone
setblock ~8 ~21 ~23 stone
setblock ~8 ~21 ~61 concrete 15
setblock ~9 ~21 ~19 stained_hardened_clay 11
fill ~9 ~21 ~23 ~9 ~23 ~23 coal_block
setblock ~10 ~21 ~17 cyan_glazed_terracotta
fill ~10 ~21 ~21 ~10 ~23 ~21 coal_block
setblock ~10 ~21 ~64 stone
setblock ~11 ~21 ~18 concrete 7
fill ~11 ~21 ~20 ~11 ~23 ~20 coal_block
fill ~11 ~21 ~23 ~11 ~22 ~23 coal_block
setblock ~11 ~21 ~64 coal_block
fill ~12 ~21 ~21 ~12 ~23 ~21 coal_block
setblock ~13 ~21 ~14 coal_block
setblock ~13 ~21 ~17 stone
setblock ~13 ~21 ~18 coal_block
fill ~14 ~21 ~13 ~14 ~32 ~13 coal_block
setblock ~15 ~21 ~69 stone
setblock ~16 ~21 ~13 stone
setblock ~17 ~21 ~10 concrete 15
fill ~17 ~21 ~73 ~18 ~21 ~73 coal_block
setblock ~18 ~21 ~10 coal_block
fill ~19 ~21 ~9 ~19 ~32 ~9 coal_block
fill ~19 ~21 ~72 ~19 ~25 ~72 coal_block
fill ~21 ~21 ~9 ~21 ~23 ~9 coal_block
setblock ~22 ~21 ~8 coal_block
setblock ~22 ~21 ~75 coal_block
fill ~24 ~21 ~76 ~24 ~23 ~76 coal_block
fill ~25 ~21 ~5 ~27 ~21 ~5 coal_block
setblock ~25 ~21 ~6 stone
fill ~25 ~21 ~78 ~31 ~21 ~78 coal_block
fill ~28 ~21 ~4 ~30 ~21 ~4 coal_block
fill ~28 ~21 ~79 ~28 ~23 ~79 coal_block
fill ~29 ~21 ~5 ~29 ~32 ~5 coal_block
fill ~29 ~21 ~29 ~58 ~21 ~29 tnt
fill ~29 ~21 ~30 ~58 ~21 ~30 tnt
fill ~29 ~21 ~31 ~58 ~21 ~31 tnt
fill ~29 ~21 ~32 ~58 ~21 ~32 tnt
fill ~29 ~21 ~33 ~58 ~21 ~33 tnt
fill ~29 ~21 ~34 ~58 ~21 ~34 tnt
fill ~29 ~21 ~35 ~58 ~21 ~35 tnt
fill ~29 ~21 ~36 ~58 ~21 ~36 tnt
fill ~29 ~21 ~37 ~58 ~21 ~37 tnt
fill ~29 ~21 ~38 ~58 ~21 ~38 tnt
fill ~29 ~21 ~39 ~58 ~21 ~39 tnt
fill ~29 ~21 ~40 ~58 ~21 ~40 tnt
fill ~29 ~21 ~41 ~58 ~21 ~41 tnt
fill ~29 ~21 ~42 ~58 ~21 ~42 tnt
fill ~29 ~21 ~43 ~58 ~21 ~43 tnt
fill ~29 ~21 ~44 ~58 ~21 ~44 tnt
fill ~29 ~21 ~45 ~58 ~21 ~45 tnt
fill ~29 ~21 ~46 ~58 ~21 ~46 tnt
fill ~29 ~21 ~47 ~58 ~21 ~47 tnt
fill ~29 ~21 ~48 ~58 ~21 ~48 tnt
fill ~29 ~21 ~49 ~58 ~21 ~49 tnt
fill ~29 ~21 ~50 ~58 ~21 ~50 tnt
fill ~29 ~21 ~51 ~58 ~21 ~51 tnt
fill ~29 ~21 ~52 ~58 ~21 ~52 tnt
fill ~29 ~21 ~53 ~58 ~21 ~53 tnt
fill ~29 ~21 ~54 ~58 ~21 ~54 tnt
fill ~29 ~21 ~55 ~58 ~21 ~55 tnt
fill ~29 ~21 ~56 ~58 ~21 ~56 tnt
fill ~29 ~21 ~57 ~58 ~21 ~57 tnt
fill ~29 ~21 ~58 ~58 ~21 ~58 tnt
setblock ~29 ~21 ~79 concrete 15
setblock ~30 ~21 ~5 stone
fill ~30 ~21 ~79 ~30 ~32 ~79 coal_block
setblock ~31 ~21 ~4 stone
fill ~31 ~21 ~5 ~31 ~31 ~5 coal_block
fill ~31 ~21 ~80 ~32 ~21 ~80 coal_block
fill ~32 ~21 ~4 ~36 ~21 ~4 coal_block
fill ~33 ~21 ~3 ~36 ~21 ~3 coal_block
fill ~33 ~21 ~80 ~34 ~21 ~80 concrete 15
fill ~35 ~21 ~78 ~37 ~21 ~78 coal_block
setblock ~35 ~21 ~79 stone
fill ~35 ~21 ~80 ~35 ~22 ~80 coal_block
fill ~36 ~21 ~2 ~36 ~32 ~2 coal_block
setblock ~36 ~21 ~79 coal_block
setblock ~36 ~21 ~80 stone
setblock ~36 ~21 ~81 concrete 7
fill ~37 ~21 ~2 ~38 ~21 ~2 concrete 15
setblock ~37 ~21 ~3 stone
setblock ~37 ~21 ~79 stone
setblock ~37 ~21 ~80 coal_block
fill ~37 ~21 ~81 ~37 ~22 ~81 cyan_glazed_terracotta
fill ~38 ~21 ~3 ~42 ~21 ~3 coal_block
fill ~38 ~21 ~78 ~39 ~21 ~78 concrete 15
setblock ~38 ~21 ~79 coal_block
setblock ~38 ~21 ~80 stone
setblock ~38 ~21 ~81 concrete 7
fill ~39 ~21 ~2 ~47 ~21 ~2 coal_block
setblock ~39 ~21 ~79 stone
fill ~39 ~21 ~80 ~39 ~21 ~81 coal_block
fill ~40 ~21 ~78 ~41 ~21 ~78 coal_block
fill ~40 ~21 ~79 ~40 ~21 ~78 coal_block
setblock ~40 ~21 ~80 stone
fill ~40 ~21 ~81 ~42 ~21 ~81 concrete 15
setblock ~41 ~21 ~79 stone
setblock ~41 ~21 ~80 coal_block
setblock ~42 ~21 ~78 stone
setblock ~42 ~21 ~79 concrete 15
setblock ~42 ~21 ~80 stone
setblock ~43 ~21 ~3 stone
fill ~43 ~21 ~78 ~48 ~21 ~78 coal_block
setblock ~43 ~21 ~79 stone
setblock ~43 ~21 ~80 wool 15
setblock ~43 ~21 ~81 concrete 7
fill ~44 ~21 ~3 ~46 ~21 ~3 coal_block
setblock ~44 ~21 ~79 coal_block
setblock ~44 ~21 ~80 stone
fill ~44 ~21 ~81 ~44 ~24 ~81 cyan_glazed_terracotta
setblock ~45 ~21 ~79 stone
setblock ~45 ~21 ~80 wool 15
setblock ~45 ~21 ~81 coal_ore
setblock ~46 ~21 ~79 coal_block
setblock ~46 ~21 ~80 stone
setblock ~46 ~21 ~81 concrete 7
setblock ~47 ~21 ~3 stone
fill ~47 ~21 ~4 ~47 ~24 ~4 coal_block
setblock ~47 ~21 ~79 stone
fill ~47 ~21 ~80 ~47 ~21 ~81 coal_block
fill ~48 ~21 ~3 ~52 ~21 ~3 coal_block
setblock ~48 ~21 ~4 stone
setblock ~48 ~21 ~79 concrete 15
setblock ~48 ~21 ~80 stone
fill ~48 ~21 ~81 ~48 ~22 ~81 coal_block
fill ~49 ~21 ~4 ~51 ~21 ~4 coal_block
fill ~49 ~21 ~80 ~52 ~21 ~80 coal_block
fill ~50 ~21 ~79 ~50 ~24 ~79 concrete 15
setblock ~51 ~21 ~79 stone
setblock ~52 ~21 ~4 stone
fill ~52 ~21 ~5 ~52 ~31 ~5 coal_block
fill ~52 ~21 ~78 ~53 ~21 ~78 concrete 15
fill ~53 ~21 ~79 ~55 ~21 ~79 coal_block
fill ~54 ~21 ~4 ~55 ~21 ~4 coal_block
fill ~54 ~21 ~5 ~54 ~22 ~5 coal_block
setblock ~54 ~21 ~78 stone
fill ~55 ~21 ~77 ~56 ~21 ~77 concrete 15
fill ~55 ~21 ~78 ~55 ~22 ~78 concrete 15
fill ~56 ~21 ~5 ~58 ~21 ~5 coal_block
setblock ~56 ~21 ~6 concrete 15
setblock ~57 ~21 ~77 stone
fill ~57 ~21 ~78 ~58 ~21 ~78 coal_block
setblock ~58 ~21 ~6 stone
setblock ~58 ~21 ~77 coal_block
fill ~59 ~21 ~76 ~59 ~20 ~76 coal_block
setblock ~60 ~21 ~76 stone
setblock ~61 ~21 ~75 stone
setblock ~64 ~21 ~72 stone
fill ~65 ~21 ~73 ~66 ~21 ~73 coal_block
fill ~66 ~21 ~71 ~66 ~22 ~71 coal_block
setblock ~67 ~21 ~70 concrete 15
setblock ~68 ~21 ~14 stone
fill ~69 ~21 ~15 ~69 ~32 ~15 coal_block
setblock ~69 ~21 ~68 stone
fill ~70 ~21 ~17 ~70 ~22 ~17 coal_block
setblock ~70 ~21 ~18 stone
setblock ~71 ~21 ~66 concrete 15
setblock ~72 ~21 ~18 stone
fill ~72 ~21 ~23 ~72 ~22 ~23 coal_block
setblock ~72 ~21 ~64 coal_block
fill ~72 ~21 ~65 ~72 ~22 ~65 concrete 15
setblock ~73 ~21 ~17 coal_ore
setblock ~73 ~21 ~18 cyan_glazed_terracotta
setblock ~73 ~21 ~19 concrete 7
setblock ~73 ~21 ~20 stone
fill ~73 ~21 ~21 ~76 ~21 ~21 coal_block
fill ~74 ~21 ~19 ~74 ~22 ~19 cyan_glazed_terracotta
setblock ~74 ~21 ~22 stone
fill ~75 ~21 ~22 ~75 ~22 ~22 coal_block
fill ~75 ~21 ~24 ~75 ~33 ~24 coal_block
setblock ~75 ~21 ~25 stone
setblock ~76 ~21 ~23 stone
fill ~76 ~21 ~25 ~76 ~22 ~25 concrete 7
fill ~76 ~21 ~26 ~76 ~33 ~26 coal_block
setblock ~76 ~21 ~59 stone
setblock ~77 ~21 ~23 concrete 7
setblock ~77 ~21 ~24 coal_ore
setblock ~77 ~21 ~25 cyan_glazed_terracotta
setblock ~77 ~21 ~26 stone
setblock ~77 ~21 ~27 coal_block
setblock ~77 ~21 ~56 stone
fill ~77 ~21 ~57 ~78 ~21 ~57 coal_block
setblock ~77 ~21 ~58 stone
fill ~78 ~21 ~26 ~78 ~23 ~26 concrete 7
setblock ~78 ~21 ~28 coal_block
setblock ~78 ~21 ~29 stone
setblock ~78 ~21 ~53 concrete 15
setblock ~78 ~21 ~56 concrete 15
setblock ~79 ~21 ~31 stone
setblock ~79 ~21 ~32 coal_block
fill ~79 ~21 ~34 ~80 ~21 ~34 concrete 15
fill ~79 ~21 ~47 ~79 ~23 ~47 coal_block
fill ~79 ~21 ~49 ~80 ~21 ~49 coal_block
setblock ~79 ~21 ~52 coal_block
setblock ~79 ~21 ~55 concrete 15
fill ~80 ~21 ~33 ~80 ~22 ~33 concrete 15
setblock ~80 ~21 ~35 coal_block
setblock ~80 ~21 ~39 concrete 15
fill ~80 ~21 ~41 ~80 ~22 ~41 concrete 15
fill ~80 ~21 ~42 ~80 ~23 ~42 concrete 15
fill ~80 ~21 ~43 ~80 ~23 ~43 concrete 15
setblock ~80 ~21 ~47 stone
fill ~80 ~21 ~50 ~80 ~29 ~50 coal_block
fill ~81 ~21 ~43 ~81 ~32 ~43 coal_block
fill ~81 ~21 ~46 ~81 ~32 ~46 coal_block
setblock ~2 ~22 ~37 concrete 15
fill ~2 ~22 ~38 ~3 ~22 ~38 coal_block
fill ~2 ~22 ~46 ~2 ~32 ~46 coal_block
fill ~2 ~22 ~47 ~4 ~22 ~47 coal_block
setblock ~3 ~22 ~35 coal_block
setblock ~3 ~22 ~41 stone
setblock ~3 ~22 ~46 stone
fill ~3 ~22 ~49 ~3 ~32 ~49 coal_block
setblock ~3 ~22 ~51 coal_block
fill ~4 ~22 ~34 ~4 ~30 ~34 coal_block
fill ~4 ~22 ~48 ~4 ~31 ~48 coal_block
setblock ~4 ~22 ~51 stone
setblock ~4 ~22 ~52 coal_block
fill ~5 ~22 ~27 ~5 ~23 ~27 concrete 15
setblock ~5 ~22 ~29 stone
fill ~5 ~22 ~57 ~5 ~23 ~57 coal_block
fill ~5 ~22 ~58 ~5 ~25 ~58 concrete 15
fill ~6 ~22 ~23 ~6 ~21 ~23 concrete 7
setblock ~6 ~22 ~25 stained_hardened_clay 11
setblock ~6 ~22 ~26 stone
setblock ~6 ~22 ~27 concrete 7
setblock ~6 ~22 ~56 stone
setblock ~6 ~22 ~58 stone
fill ~7 ~22 ~22 ~7 ~32 ~22 coal_block
setblock ~7 ~22 ~23 stone
setblock ~7 ~22 ~24 concrete 7
setblock ~7 ~22 ~25 stone
setblock ~7 ~22 ~27 stone
fill ~7 ~22 ~59 ~7 ~27 ~59 coal_block
setblock ~8 ~22 ~20 coal_block
setblock ~8 ~22 ~22 stone
setblock ~8 ~22 ~23 coal_block
fill ~8 ~22 ~61 ~8 ~26 ~61 coal_block
fill ~9 ~22 ~19 ~9 ~23 ~19 cyan_glazed_terracotta
fill ~9 ~22 ~22 ~9 ~23 ~22 coal_block
setblock ~9 ~22 ~62 stone
setblock ~10 ~22 ~17 coal_ore
setblock ~10 ~22 ~18 cyan_glazed_terracotta
setblock ~10 ~22 ~20 stone
setblock ~10 ~22 ~25 coal_block
fill ~10 ~22 ~63 ~10 ~24 ~63 concrete 15
fill ~10 ~22 ~64 ~11 ~22 ~64 concrete 15
setblock ~11 ~22 ~16 concrete 7
setblock ~11 ~22 ~18 stone
setblock ~12 ~22 ~15 concrete 15
setblock ~13 ~22 ~14 concrete 15
fill ~13 ~22 ~17 ~13 ~24 ~17 coal_block
setblock ~13 ~22 ~18 stone
fill ~15 ~22 ~12 ~15 ~32 ~12 coal_block
fill ~15 ~22 ~69 ~15 ~30 ~69 coal_block
fill ~16 ~22 ~11 ~16 ~32 ~11 coal_block
fill ~16 ~22 ~13 ~16 ~24 ~13 coal_block
fill ~17 ~22 ~10 ~17 ~32 ~10 coal_block
fill ~17 ~22 ~73 ~18 ~22 ~73 coal_block
setblock ~18 ~22 ~10 stone
setblock ~22 ~22 ~8 stone
setblock ~22 ~22 ~75 stone
fill ~25 ~22 ~5 ~27 ~22 ~5 coal_block
fill ~25 ~22 ~6 ~25 ~22 ~5 coal_block
fill ~25 ~22 ~78 ~27 ~22 ~78 coal_block
setblock ~27 ~22 ~6 stone
fill ~28 ~22 ~4 ~32 ~22 ~4 coal_block
setblock ~28 ~22 ~78 stone
fill ~29 ~22 ~29 ~58 ~22 ~29 tnt
fill ~29 ~22 ~30 ~58 ~22 ~30 tnt
fill ~29 ~22 ~31 ~58 ~22 ~31 tnt
fill ~29 ~22 ~32 ~58 ~22 ~32 tnt
fill ~29 ~22 ~33 ~58 ~22 ~33 tnt
fill ~29 ~22 ~34 ~58 ~22 ~34 tnt
fill ~29 ~22 ~35 ~58 ~22 ~35 tnt
fill ~29 ~22 ~36 ~58 ~22 ~36 tnt
fill ~29 ~22 ~37 ~58 ~22 ~37 tnt
fill ~29 ~22 ~38 ~58 ~22 ~38 tnt
fill ~29 ~22 ~39 ~58 ~22 ~39 tnt
fill ~29 ~22 ~40 ~58 ~22 ~40 tnt
fill ~29 ~22 ~41 ~58 ~22 ~41 tnt
fill ~29 ~22 ~42 ~58 ~22 ~42 tnt
fill ~29 ~22 ~43 ~58 ~22 ~43 tnt
fill ~29 ~22 ~44 ~58 ~22 ~44 tnt
fill ~29 ~22 ~45 ~58 ~22 ~45 tnt
fill ~29 ~22 ~46 ~58 ~22 ~46 tnt
fill ~29 ~22 ~47 ~58 ~22 ~47 tnt
fill ~29 ~22 ~48 ~58 ~22 ~48 tnt
fill ~29 ~22 ~49 ~58 ~22 ~49 tnt
fill ~29 ~22 ~50 ~58 ~22 ~50 tnt
fill ~29 ~22 ~51 ~58 ~22 ~51 tnt
fill ~29 ~22 ~52 ~58 ~22 ~52 tnt
fill ~29 ~22 ~53 ~58 ~22 ~53 tnt
fill ~29 ~22 ~54 ~58 ~22 ~54 tnt
fill ~29 ~22 ~55 ~58 ~22 ~55 tnt
fill ~29 ~22 ~56 ~58 ~22 ~56 tnt
fill ~29 ~22 ~57 ~58 ~22 ~57 tnt
fill ~29 ~22 ~58 ~58 ~22 ~58 tnt
fill ~29 ~22 ~79 ~29 ~32 ~79 coal_block
fill ~30 ~22 ~5 ~30 ~24 ~5 coal_block
setblock ~30 ~22 ~78 stone
fill ~31 ~22 ~80 ~31 ~32 ~80 coal_block
fill ~32 ~22 ~80 ~34 ~22 ~80 concrete 15
fill ~33 ~22 ~3 ~35 ~22 ~3 coal_block
setblock ~33 ~22 ~4 stone
fill ~34 ~22 ~4 ~36 ~22 ~4 coal_block
setblock ~35 ~22 ~78 stone
setblock ~35 ~22 ~79 coal_block
setblock ~36 ~22 ~3 stone
fill ~36 ~22 ~78 ~38 ~22 ~78 coal_block
setblock ~36 ~22 ~79 stone
setblock ~36 ~22 ~80 concrete 7
setblock ~36 ~22 ~81 coal_ore
fill ~37 ~22 ~2 ~47 ~22 ~2 coal_block
fill ~37 ~22 ~3 ~52 ~22 ~3 coal_block
setblock ~37 ~22 ~79 coal_block
setblock ~37 ~22 ~80 stone
setblock ~38 ~22 ~79 stone
setblock ~38 ~22 ~80 concrete 7
fill ~38 ~22 ~81 ~39 ~22 ~81 coal_ore
setblock ~39 ~22 ~78 stone
setblock ~39 ~22 ~79 coal_block
setblock ~39 ~22 ~80 stone
setblock ~40 ~22 ~78 concrete 15
setblock ~40 ~22 ~79 stone
fill ~40 ~22 ~80 ~40 ~22 ~81 coal_block
fill ~41 ~22 ~78 ~48 ~22 ~78 coal_block
fill ~41 ~22 ~79 ~41 ~24 ~79 coal_block
setblock ~41 ~22 ~80 stone
fill ~41 ~22 ~81 ~41 ~23 ~81 concrete 15
setblock ~42 ~22 ~79 stone
setblock ~42 ~22 ~80 wool 15
fill ~42 ~22 ~81 ~42 ~23 ~81 coal_block
setblock ~43 ~22 ~79 coal_block
setblock ~43 ~22 ~80 stone
fill ~43 ~22 ~81 ~43 ~23 ~81 cyan_glazed_terracotta
setblock ~44 ~22 ~79 stone
setblock ~44 ~22 ~80 concrete 7
setblock ~45 ~22 ~79 coal_block
setblock ~45 ~22 ~80 stone
fill ~45 ~22 ~81 ~46 ~22 ~81 cyan_glazed_terracotta
setblock ~46 ~22 ~79 stone
setblock ~46 ~22 ~80 concrete 7
setblock ~47 ~22 ~79 concrete 15
setblock ~47 ~22 ~80 stone
setblock ~47 ~22 ~81 concrete 7
fill ~48 ~22 ~4 ~55 ~22 ~4 coal_block
setblock ~48 ~22 ~79 stone
fill ~48 ~22 ~80 ~52 ~22 ~80 coal_block
fill ~51 ~22 ~79 ~51 ~25 ~79 concrete 15
fill ~52 ~22 ~78 ~55 ~22 ~78 concrete 15
fill ~53 ~22 ~79 ~55 ~22 ~79 coal_block
fill ~55 ~22 ~6 ~56 ~22 ~6 coal_block
fill ~55 ~22 ~77 ~55 ~20 ~77 concrete 15
fill ~56 ~22 ~5 ~58 ~22 ~5 coal_block
fill ~56 ~22 ~77 ~57 ~22 ~77 coal_block
setblock ~57 ~22 ~6 stone
fill ~57 ~22 ~78 ~58 ~22 ~78 coal_block
setblock ~58 ~22 ~6 coal_block
fill ~58 ~22 ~7 ~58 ~25 ~7 concrete 15
setblock ~58 ~22 ~76 coal_block
setblock ~58 ~22 ~77 stone
setblock ~59 ~22 ~76 stone
setblock ~60 ~22 ~76 coal_block
setblock ~61 ~22 ~75 coal_block
setblock ~62 ~22 ~9 stone
fill ~64 ~22 ~72 ~64 ~24 ~72 coal_block
fill ~65 ~22 ~73 ~66 ~22 ~73 coal_block
setblock ~67 ~22 ~70 coal_block
fill ~68 ~22 ~14 ~68 ~24 ~14 coal_block
fill ~69 ~22 ~68 ~69 ~24 ~68 coal_block
fill ~70 ~22 ~16 ~70 ~32 ~16 coal_block
fill ~70 ~22 ~18 ~70 ~24 ~18 coal_block
setblock ~71 ~22 ~18 stone
setblock ~71 ~22 ~66 coal_block
fill ~72 ~22 ~18 ~72 ~26 ~18 coal_block
fill ~72 ~22 ~64 ~72 ~26 ~64 concrete 15
setblock ~73 ~22 ~17 cyan_glazed_terracotta
setblock ~73 ~22 ~18 stained_hardened_clay 11
setblock ~73 ~22 ~19 stone
fill ~73 ~22 ~20 ~73 ~23 ~20 concrete 7
fill ~73 ~22 ~21 ~74 ~22 ~21 coal_block
setblock ~73 ~22 ~24 concrete 15
fill ~73 ~22 ~25 ~73 ~25 ~25 coal_block
fill ~73 ~22 ~63 ~73 ~25 ~63 concrete 15
setblock ~73 ~22 ~66 concrete 15
fill ~74 ~22 ~22 ~74 ~33 ~22 coal_block
setblock ~75 ~22 ~20 wool 15
setblock ~75 ~22 ~21 stone
setblock ~75 ~22 ~23 stone
fill ~75 ~22 ~25 ~75 ~25 ~25 coal_block
setblock ~76 ~22 ~23 cyan_glazed_terracotta
setblock ~76 ~22 ~24 stone
fill ~76 ~22 ~59 ~76 ~26 ~59 coal_block
fill ~77 ~22 ~23 ~77 ~23 ~23 coal_ore
setblock ~77 ~22 ~24 stained_hardened_clay 11
setblock ~77 ~22 ~25 coal_ore
fill ~77 ~22 ~26 ~77 ~23 ~26 concrete 7
setblock ~77 ~22 ~27 stone
setblock ~77 ~22 ~29 stone
fill ~77 ~22 ~56 ~78 ~22 ~56 coal_block
fill ~77 ~22 ~57 ~78 ~22 ~57 coal_block
fill ~77 ~22 ~58 ~77 ~22 ~55 coal_block
setblock ~78 ~22 ~28 stone
setblock ~78 ~22 ~29 coal_block
fill ~78 ~22 ~53 ~78 ~27 ~53 coal_block
setblock ~79 ~22 ~31 coal_block
setblock ~79 ~22 ~32 concrete 15
fill ~79 ~22 ~34 ~80 ~22 ~34 concrete 15
fill ~79 ~22 ~49 ~80 ~22 ~49 coal_block
setblock ~79 ~22 ~50 stone
setblock ~79 ~22 ~52 stone
fill ~79 ~22 ~54 ~79 ~32 ~54 coal_block
fill ~79 ~22 ~55 ~79 ~32 ~55 coal_block
setblock ~80 ~22 ~35 stone
setblock ~80 ~22 ~39 stone
fill ~80 ~22 ~40 ~80 ~24 ~40 concrete 15
setblock ~80 ~22 ~44 stone
setblock ~80 ~22 ~47 coal_block
fill ~2 ~23 ~37 ~2 ~32 ~37 coal_block
fill ~2 ~23 ~38 ~3 ~23 ~38 coal_block
fill ~2 ~23 ~47 ~2 ~30 ~47 coal_block
fill ~3 ~23 ~31 ~3 ~24 ~31 concrete 15
setblock ~3 ~23 ~35 stone
fill ~3 ~23 ~41 ~3 ~32 ~41 coal_block
fill ~3 ~23 ~46 ~3 ~25 ~46 coal_block
setblock ~3 ~23 ~47 stone
setblock ~3 ~23 ~51 wool 15
setblock ~4 ~23 ~30 concrete 15
fill ~4 ~23 ~51 ~4 ~25 ~51 coal_block
setblock ~4 ~23 ~52 stone
setblock ~5 ~23 ~26 stained_hardened_clay 11
fill ~5 ~23 ~29 ~5 ~26 ~29 coal_block
setblock ~5 ~23 ~52 concrete 15
setblock ~5 ~23 ~53 stone
setblock ~6 ~23 ~23 wool 15
fill ~6 ~23 ~25 ~6 ~24 ~25 cyan_glazed_terracotta
setblock ~6 ~23 ~26 concrete 7
setblock ~6 ~23 ~27 stone
setblock ~6 ~23 ~29 stone
fill ~6 ~23 ~56 ~6 ~27 ~56 coal_block
setblock ~6 ~23 ~58 concrete 15
setblock ~7 ~23 ~23 concrete 7
setblock ~7 ~23 ~24 coal_block
setblock ~7 ~23 ~25 concrete 7
setblock ~7 ~23 ~26 stone
fill ~7 ~23 ~27 ~7 ~25 ~27 coal_block
fill ~8 ~23 ~20 ~8 ~24 ~20 concrete 7
fill ~8 ~23 ~22 ~8 ~26 ~22 coal_block
setblock ~8 ~23 ~23 stone
fill ~8 ~23 ~24 ~8 ~25 ~24 concrete 15
fill ~8 ~23 ~25 ~8 ~23 ~24 concrete 15
fill ~9 ~23 ~62 ~9 ~30 ~62 coal_block
fill ~10 ~23 ~17 ~10 ~23 ~18 stained_hardened_clay 11
setblock ~10 ~23 ~20 wool 15
setblock ~10 ~23 ~25 concrete 15
setblock ~10 ~23 ~64 stone
fill ~11 ~23 ~16 ~11 ~26 ~16 coal_block
setblock ~11 ~23 ~18 concrete 7
fill ~11 ~23 ~24 ~12 ~23 ~24 coal_block
fill ~11 ~23 ~25 ~11 ~24 ~25 coal_block
setblock ~11 ~23 ~64 coal_block
fill ~12 ~23 ~15 ~12 ~30 ~15 coal_block
setblock ~12 ~23 ~18 stone
fill ~12 ~23 ~23 ~12 ~32 ~23 coal_block
fill ~12 ~23 ~66 ~12 ~26 ~66 concrete 15
fill ~13 ~23 ~14 ~13 ~30 ~14 coal_block
setblock ~13 ~23 ~18 concrete 15
setblock ~13 ~23 ~67 stone
setblock ~17 ~23 ~71 stone
fill ~17 ~23 ~73 ~18 ~23 ~73 coal_block
setblock ~18 ~23 ~10 coal_block
setblock ~19 ~23 ~10 stone
setblock ~22 ~23 ~8 coal_block
setblock ~22 ~23 ~75 coal_block
setblock ~24 ~23 ~7 stone
fill ~25 ~23 ~5 ~27 ~23 ~5 coal_block
setblock ~25 ~23 ~6 stone
