setblock ~9 ~0 ~101 stained_glass
fill ~16 ~0 ~8 ~42 ~0 ~8 log 1
fill ~16 ~0 ~9 ~16 ~46 ~9 log 1
fill ~16 ~0 ~10 ~16 ~0 ~94 log 1
fill ~17 ~0 ~9 ~17 ~0 ~68 log 9
fill ~17 ~0 ~69 ~101 ~0 ~69 log 5
fill ~17 ~0 ~70 ~17 ~0 ~74 log 9
fill ~17 ~0 ~75 ~101 ~0 ~75 log 5
fill ~17 ~0 ~76 ~17 ~0 ~80 log 9
fill ~17 ~0 ~81 ~101 ~0 ~81 log 5
fill ~17 ~0 ~82 ~17 ~0 ~86 log 9
fill ~17 ~0 ~87 ~101 ~0 ~87 log 5
fill ~17 ~0 ~88 ~17 ~0 ~92 log 9
fill ~17 ~0 ~93 ~101 ~0 ~93 log 5
fill ~17 ~0 ~94 ~102 ~0 ~94 log 1
fill ~18 ~0 ~9 ~41 ~0 ~9 log 5
fill ~18 ~0 ~10 ~22 ~0 ~10 wool
fill ~18 ~0 ~11 ~22 ~0 ~11 wool
fill ~18 ~0 ~12 ~22 ~0 ~12 wool
fill ~18 ~0 ~13 ~22 ~0 ~13 wool
fill ~18 ~0 ~14 ~22 ~0 ~14 wool
fill ~18 ~0 ~15 ~22 ~0 ~15 log 5
fill ~18 ~0 ~16 ~22 ~0 ~16 wool
fill ~18 ~0 ~17 ~22 ~0 ~17 wool
fill ~18 ~0 ~18 ~22 ~0 ~18 wool
fill ~18 ~0 ~19 ~22 ~0 ~19 wool
fill ~18 ~0 ~20 ~22 ~0 ~20 wool
fill ~18 ~0 ~21 ~22 ~0 ~21 log 5
fill ~18 ~0 ~22 ~22 ~0 ~22 wool
fill ~18 ~0 ~23 ~22 ~0 ~23 wool
fill ~18 ~0 ~24 ~22 ~0 ~24 wool
fill ~18 ~0 ~25 ~22 ~0 ~25 wool
fill ~18 ~0 ~26 ~22 ~0 ~26 wool
fill ~18 ~0 ~27 ~22 ~0 ~27 log 5
fill ~18 ~0 ~28 ~22 ~0 ~28 wool
fill ~18 ~0 ~29 ~22 ~0 ~29 wool
fill ~18 ~0 ~30 ~22 ~0 ~30 wool
fill ~18 ~0 ~31 ~22 ~0 ~31 wool
fill ~18 ~0 ~32 ~22 ~0 ~32 wool
fill ~18 ~0 ~33 ~22 ~0 ~33 log 5
fill ~18 ~0 ~34 ~22 ~0 ~34 wool
fill ~18 ~0 ~35 ~22 ~0 ~35 wool
fill ~18 ~0 ~36 ~22 ~0 ~36 wool
fill ~18 ~0 ~37 ~22 ~0 ~37 wool
fill ~18 ~0 ~38 ~22 ~0 ~38 wool
fill ~18 ~0 ~39 ~22 ~0 ~39 log 5
fill ~18 ~0 ~40 ~22 ~0 ~40 wool
fill ~18 ~0 ~41 ~22 ~0 ~41 wool
fill ~18 ~0 ~42 ~22 ~0 ~42 wool
fill ~18 ~0 ~43 ~22 ~0 ~43 wool
fill ~18 ~0 ~44 ~22 ~0 ~44 wool
fill ~18 ~0 ~45 ~22 ~0 ~45 log 5
fill ~18 ~0 ~46 ~22 ~0 ~46 wool
fill ~18 ~0 ~47 ~22 ~0 ~47 wool
fill ~18 ~0 ~48 ~22 ~0 ~48 wool
fill ~18 ~0 ~49 ~22 ~0 ~49 wool
fill ~18 ~0 ~50 ~22 ~0 ~50 wool
fill ~18 ~0 ~51 ~22 ~0 ~51 log 5
fill ~18 ~0 ~52 ~22 ~0 ~52 wool
fill ~18 ~0 ~53 ~22 ~0 ~53 wool
fill ~18 ~0 ~54 ~22 ~0 ~54 wool
fill ~18 ~0 ~55 ~22 ~0 ~55 wool
fill ~18 ~0 ~56 ~22 ~0 ~56 wool
fill ~18 ~0 ~57 ~22 ~0 ~57 log 5
fill ~18 ~0 ~58 ~22 ~0 ~58 wool
fill ~18 ~0 ~59 ~22 ~0 ~59 wool
fill ~18 ~0 ~60 ~22 ~0 ~60 wool
fill ~18 ~0 ~61 ~22 ~0 ~61 wool
fill ~18 ~0 ~62 ~22 ~0 ~62 wool
fill ~18 ~0 ~63 ~22 ~0 ~63 log 5
fill ~18 ~0 ~64 ~22 ~0 ~64 wool
fill ~18 ~0 ~65 ~22 ~0 ~65 wool
fill ~18 ~0 ~66 ~22 ~0 ~66 wool
fill ~18 ~0 ~67 ~22 ~0 ~67 wool
fill ~18 ~0 ~68 ~22 ~0 ~68 wool
fill ~18 ~0 ~70 ~22 ~0 ~70 wool
fill ~18 ~0 ~71 ~22 ~0 ~71 wool
fill ~18 ~0 ~72 ~22 ~0 ~72 wool
fill ~18 ~0 ~73 ~22 ~0 ~73 wool
fill ~18 ~0 ~74 ~22 ~0 ~74 wool
fill ~18 ~0 ~76 ~22 ~0 ~76 wool
fill ~18 ~0 ~77 ~22 ~0 ~77 wool
fill ~18 ~0 ~78 ~22 ~0 ~78 wool
fill ~18 ~0 ~79 ~22 ~0 ~79 wool
fill ~18 ~0 ~80 ~22 ~0 ~80 wool
fill ~18 ~0 ~82 ~22 ~0 ~82 wool
fill ~18 ~0 ~83 ~22 ~0 ~83 wool
fill ~18 ~0 ~84 ~22 ~0 ~84 wool
fill ~18 ~0 ~85 ~22 ~0 ~85 wool
fill ~18 ~0 ~86 ~22 ~0 ~86 wool
fill ~18 ~0 ~88 ~22 ~0 ~88 wool
fill ~18 ~0 ~89 ~22 ~0 ~89 wool
fill ~18 ~0 ~90 ~22 ~0 ~90 wool
fill ~18 ~0 ~91 ~22 ~0 ~91 wool
fill ~18 ~0 ~92 ~22 ~0 ~92 wool
fill ~23 ~0 ~10 ~23 ~0 ~68 log 9
fill ~23 ~0 ~70 ~23 ~0 ~74 log 9
fill ~23 ~0 ~76 ~23 ~0 ~80 log 9
fill ~23 ~0 ~82 ~23 ~0 ~86 log 9
fill ~23 ~0 ~88 ~23 ~0 ~92 log 9
fill ~24 ~0 ~10 ~28 ~0 ~10 wool
fill ~24 ~0 ~11 ~28 ~0 ~11 wool
fill ~24 ~0 ~12 ~28 ~0 ~12 wool
fill ~24 ~0 ~13 ~28 ~0 ~13 wool
fill ~24 ~0 ~14 ~28 ~0 ~14 wool
fill ~24 ~0 ~15 ~28 ~0 ~15 log 5
fill ~24 ~0 ~16 ~28 ~0 ~16 wool
fill ~24 ~0 ~17 ~28 ~0 ~17 wool
fill ~24 ~0 ~18 ~28 ~0 ~18 wool
fill ~24 ~0 ~19 ~28 ~0 ~19 wool
fill ~24 ~0 ~20 ~28 ~0 ~20 wool
fill ~24 ~0 ~21 ~28 ~0 ~21 log 5
fill ~24 ~0 ~22 ~28 ~0 ~22 wool
fill ~24 ~0 ~23 ~28 ~0 ~23 wool
fill ~24 ~0 ~24 ~28 ~0 ~24 wool
fill ~24 ~0 ~25 ~28 ~0 ~25 wool
fill ~24 ~0 ~26 ~28 ~0 ~26 wool
fill ~24 ~0 ~27 ~28 ~0 ~27 log 5
fill ~24 ~0 ~28 ~28 ~0 ~28 wool
fill ~24 ~0 ~29 ~28 ~0 ~29 wool
fill ~24 ~0 ~30 ~28 ~0 ~30 wool
fill ~24 ~0 ~31 ~28 ~0 ~31 wool
fill ~24 ~0 ~32 ~28 ~0 ~32 wool
fill ~24 ~0 ~33 ~28 ~0 ~33 log 5
fill ~24 ~0 ~34 ~28 ~0 ~34 wool
fill ~24 ~0 ~35 ~28 ~0 ~35 wool
fill ~24 ~0 ~36 ~28 ~0 ~36 wool
fill ~24 ~0 ~37 ~28 ~0 ~37 wool
fill ~24 ~0 ~38 ~28 ~0 ~38 wool
fill ~24 ~0 ~39 ~28 ~0 ~39 log 5
fill ~24 ~0 ~40 ~28 ~0 ~40 wool
fill ~24 ~0 ~41 ~28 ~0 ~41 wool
fill ~24 ~0 ~42 ~28 ~0 ~42 wool
fill ~24 ~0 ~43 ~28 ~0 ~43 wool
fill ~24 ~0 ~44 ~28 ~0 ~44 wool
fill ~24 ~0 ~45 ~28 ~0 ~45 log 5
fill ~24 ~0 ~46 ~28 ~0 ~46 wool
fill ~24 ~0 ~47 ~28 ~0 ~47 wool
fill ~24 ~0 ~48 ~28 ~0 ~48 wool
fill ~24 ~0 ~49 ~28 ~0 ~49 wool
fill ~24 ~0 ~50 ~28 ~0 ~50 wool
fill ~24 ~0 ~51 ~28 ~0 ~51 log 5
fill ~24 ~0 ~52 ~28 ~0 ~52 wool
fill ~24 ~0 ~53 ~28 ~0 ~53 wool
fill ~24 ~0 ~54 ~28 ~0 ~54 wool
fill ~24 ~0 ~55 ~28 ~0 ~55 wool
fill ~24 ~0 ~56 ~28 ~0 ~56 wool
fill ~24 ~0 ~57 ~28 ~0 ~57 log 5
fill ~24 ~0 ~58 ~28 ~0 ~58 wool
fill ~24 ~0 ~59 ~28 ~0 ~59 wool
fill ~24 ~0 ~60 ~28 ~0 ~60 wool
fill ~24 ~0 ~61 ~28 ~0 ~61 wool
fill ~24 ~0 ~62 ~28 ~0 ~62 wool
fill ~24 ~0 ~63 ~28 ~0 ~63 log 5
fill ~24 ~0 ~64 ~28 ~0 ~64 wool
fill ~24 ~0 ~65 ~28 ~0 ~65 wool
fill ~24 ~0 ~66 ~28 ~0 ~66 wool
fill ~24 ~0 ~67 ~28 ~0 ~67 wool
fill ~24 ~0 ~68 ~28 ~0 ~68 wool
fill ~24 ~0 ~70 ~28 ~0 ~70 wool
fill ~24 ~0 ~71 ~28 ~0 ~71 wool
fill ~24 ~0 ~72 ~28 ~0 ~72 wool
fill ~24 ~0 ~73 ~28 ~0 ~73 wool
fill ~24 ~0 ~74 ~28 ~0 ~74 wool
fill ~24 ~0 ~76 ~28 ~0 ~76 wool
fill ~24 ~0 ~77 ~28 ~0 ~77 wool
fill ~24 ~0 ~78 ~28 ~0 ~78 wool
fill ~24 ~0 ~79 ~28 ~0 ~79 wool
fill ~24 ~0 ~80 ~28 ~0 ~80 wool
fill ~24 ~0 ~82 ~28 ~0 ~82 wool
fill ~24 ~0 ~83 ~28 ~0 ~83 wool
fill ~24 ~0 ~84 ~28 ~0 ~84 wool
fill ~24 ~0 ~85 ~28 ~0 ~85 wool
fill ~24 ~0 ~86 ~28 ~0 ~86 wool
fill ~24 ~0 ~88 ~28 ~0 ~88 wool
fill ~24 ~0 ~89 ~28 ~0 ~89 wool
fill ~24 ~0 ~90 ~28 ~0 ~90 wool
fill ~24 ~0 ~91 ~28 ~0 ~91 wool
fill ~24 ~0 ~92 ~28 ~0 ~92 wool
fill ~29 ~0 ~10 ~29 ~0 ~68 log 9
fill ~29 ~0 ~70 ~29 ~0 ~74 log 9
fill ~29 ~0 ~76 ~29 ~1 ~76 log 9
fill ~29 ~0 ~77 ~29 ~1 ~77 log 9
fill ~29 ~0 ~78 ~29 ~1 ~78 log 9
fill ~29 ~0 ~79 ~29 ~1 ~79 log 9
fill ~29 ~0 ~80 ~29 ~1 ~80 log 9
fill ~29 ~0 ~82 ~29 ~1 ~82 log 9
fill ~29 ~0 ~83 ~29 ~1 ~83 log 9
fill ~29 ~0 ~84 ~29 ~1 ~84 log 9
fill ~29 ~0 ~85 ~29 ~1 ~85 log 9
fill ~29 ~0 ~86 ~29 ~0 ~82 log 9
fill ~29 ~0 ~88 ~29 ~0 ~92 log 9
fill ~30 ~0 ~10 ~34 ~0 ~10 wool
fill ~30 ~0 ~11 ~34 ~0 ~11 wool
fill ~30 ~0 ~12 ~34 ~0 ~12 wool
fill ~30 ~0 ~13 ~34 ~0 ~13 wool
fill ~30 ~0 ~14 ~34 ~0 ~14 wool
fill ~30 ~0 ~15 ~34 ~0 ~15 log 5
fill ~30 ~0 ~16 ~34 ~0 ~16 wool
fill ~30 ~0 ~17 ~34 ~0 ~17 wool
fill ~30 ~0 ~18 ~34 ~0 ~18 wool
fill ~30 ~0 ~19 ~34 ~0 ~19 wool
fill ~30 ~0 ~20 ~34 ~0 ~20 wool
fill ~30 ~0 ~21 ~34 ~0 ~21 log 5
fill ~30 ~0 ~22 ~34 ~0 ~22 wool
fill ~30 ~0 ~23 ~34 ~0 ~23 wool
fill ~30 ~0 ~24 ~34 ~0 ~24 wool
fill ~30 ~0 ~25 ~34 ~0 ~25 wool
fill ~30 ~0 ~26 ~34 ~0 ~26 wool
fill ~30 ~0 ~27 ~34 ~0 ~27 log 5
fill ~30 ~0 ~28 ~34 ~0 ~28 wool
fill ~30 ~0 ~29 ~34 ~0 ~29 wool
fill ~30 ~0 ~30 ~34 ~0 ~30 wool
fill ~30 ~0 ~31 ~34 ~0 ~31 wool
fill ~30 ~0 ~32 ~34 ~0 ~32 wool
fill ~30 ~0 ~33 ~34 ~0 ~33 log 5
fill ~30 ~0 ~34 ~34 ~0 ~34 wool
fill ~30 ~0 ~35 ~34 ~0 ~35 wool
fill ~30 ~0 ~36 ~34 ~0 ~36 wool
fill ~30 ~0 ~37 ~34 ~0 ~37 wool
fill ~30 ~0 ~38 ~34 ~0 ~38 wool
fill ~30 ~0 ~39 ~34 ~0 ~39 log 5
fill ~30 ~0 ~40 ~34 ~0 ~40 wool
fill ~30 ~0 ~41 ~34 ~0 ~41 wool
fill ~30 ~0 ~42 ~34 ~0 ~42 wool
fill ~30 ~0 ~43 ~34 ~0 ~43 wool
fill ~30 ~0 ~44 ~34 ~0 ~44 wool
fill ~30 ~0 ~45 ~34 ~0 ~45 log 5
fill ~30 ~0 ~46 ~34 ~0 ~46 wool
fill ~30 ~0 ~47 ~34 ~0 ~47 wool
fill ~30 ~0 ~48 ~34 ~0 ~48 wool
fill ~30 ~0 ~49 ~34 ~0 ~49 wool
fill ~30 ~0 ~50 ~34 ~0 ~50 wool
fill ~30 ~0 ~51 ~34 ~0 ~51 log 5
fill ~30 ~0 ~52 ~34 ~0 ~52 wool
fill ~30 ~0 ~53 ~34 ~0 ~53 wool
fill ~30 ~0 ~54 ~34 ~0 ~54 wool
fill ~30 ~0 ~55 ~34 ~0 ~55 wool
fill ~30 ~0 ~56 ~34 ~0 ~56 wool
fill ~30 ~0 ~57 ~34 ~0 ~57 log 5
fill ~30 ~0 ~58 ~34 ~0 ~58 wool
fill ~30 ~0 ~59 ~34 ~0 ~59 wool
fill ~30 ~0 ~60 ~34 ~0 ~60 wool
fill ~30 ~0 ~61 ~34 ~0 ~61 wool
fill ~30 ~0 ~62 ~34 ~0 ~62 wool
fill ~30 ~0 ~63 ~34 ~0 ~63 log 5
fill ~30 ~0 ~64 ~34 ~0 ~64 wool
fill ~30 ~0 ~65 ~34 ~0 ~65 wool
fill ~30 ~0 ~66 ~34 ~0 ~66 wool
fill ~30 ~0 ~67 ~34 ~0 ~67 wool
fill ~30 ~0 ~68 ~34 ~0 ~68 wool
fill ~30 ~0 ~70 ~34 ~0 ~70 wool
fill ~30 ~0 ~71 ~34 ~0 ~71 wool
fill ~30 ~0 ~72 ~34 ~0 ~72 wool
fill ~30 ~0 ~73 ~34 ~0 ~73 wool
fill ~30 ~0 ~74 ~34 ~0 ~74 wool
fill ~30 ~0 ~76 ~34 ~0 ~76 wool
fill ~30 ~0 ~77 ~34 ~0 ~77 wool
fill ~30 ~0 ~78 ~34 ~0 ~78 wool
fill ~30 ~0 ~79 ~34 ~0 ~79 wool
fill ~30 ~0 ~80 ~34 ~0 ~80 wool
fill ~30 ~0 ~82 ~34 ~0 ~82 wool
fill ~30 ~0 ~83 ~34 ~0 ~83 wool
fill ~30 ~0 ~84 ~34 ~0 ~84 wool
fill ~30 ~0 ~85 ~34 ~0 ~85 wool
fill ~30 ~0 ~86 ~34 ~0 ~86 wool
fill ~30 ~0 ~88 ~34 ~0 ~88 wool
fill ~30 ~0 ~89 ~34 ~0 ~89 wool
fill ~30 ~0 ~90 ~34 ~0 ~90 wool
fill ~30 ~0 ~91 ~34 ~0 ~91 wool
fill ~30 ~0 ~92 ~34 ~0 ~92 wool
fill ~35 ~0 ~10 ~35 ~0 ~68 log 9
fill ~35 ~0 ~70 ~35 ~0 ~74 log 9
fill ~35 ~0 ~76 ~35 ~1 ~76 log 9
fill ~35 ~0 ~77 ~35 ~1 ~77 log 9
fill ~35 ~0 ~78 ~35 ~1 ~78 log 9
fill ~35 ~0 ~79 ~35 ~1 ~79 log 9
fill ~35 ~0 ~80 ~35 ~1 ~80 log 9
fill ~35 ~0 ~82 ~35 ~1 ~82 log 9
fill ~35 ~0 ~83 ~35 ~1 ~83 log 9
fill ~35 ~0 ~84 ~35 ~1 ~84 log 9
fill ~35 ~0 ~85 ~35 ~1 ~85 log 9
fill ~35 ~0 ~86 ~35 ~1 ~86 log 9
fill ~35 ~0 ~88 ~35 ~0 ~92 log 9
fill ~36 ~0 ~10 ~40 ~0 ~10 wool
fill ~36 ~0 ~11 ~40 ~0 ~11 wool
fill ~36 ~0 ~12 ~40 ~0 ~12 wool
fill ~36 ~0 ~13 ~40 ~0 ~13 wool
fill ~36 ~0 ~14 ~40 ~0 ~14 wool
fill ~36 ~0 ~15 ~40 ~0 ~15 log 5
fill ~36 ~0 ~16 ~40 ~0 ~16 wool
fill ~36 ~0 ~17 ~40 ~0 ~17 wool
fill ~36 ~0 ~18 ~40 ~0 ~18 wool
fill ~36 ~0 ~19 ~40 ~0 ~19 wool
fill ~36 ~0 ~20 ~40 ~0 ~20 wool
fill ~36 ~0 ~21 ~40 ~0 ~21 log 5
fill ~36 ~0 ~22 ~40 ~0 ~22 wool
fill ~36 ~0 ~23 ~40 ~0 ~23 wool
fill ~36 ~0 ~24 ~40 ~0 ~24 wool
fill ~36 ~0 ~25 ~40 ~0 ~25 wool
fill ~36 ~0 ~26 ~40 ~0 ~26 wool
fill ~36 ~0 ~27 ~40 ~0 ~27 log 5
fill ~36 ~0 ~28 ~40 ~0 ~28 wool
fill ~36 ~0 ~29 ~40 ~0 ~29 wool
fill ~36 ~0 ~30 ~40 ~0 ~30 wool
fill ~36 ~0 ~31 ~40 ~0 ~31 wool
fill ~36 ~0 ~32 ~40 ~0 ~32 wool
fill ~36 ~0 ~33 ~40 ~0 ~33 log 5
fill ~36 ~0 ~34 ~40 ~0 ~34 wool
fill ~36 ~0 ~35 ~40 ~0 ~35 wool
fill ~36 ~0 ~36 ~40 ~0 ~36 wool
fill ~36 ~0 ~37 ~40 ~0 ~37 wool
fill ~36 ~0 ~38 ~40 ~0 ~38 wool
fill ~36 ~0 ~39 ~40 ~0 ~39 log 5
fill ~36 ~0 ~40 ~40 ~0 ~40 wool
fill ~36 ~0 ~41 ~40 ~0 ~41 wool
fill ~36 ~0 ~42 ~40 ~0 ~42 wool
fill ~36 ~0 ~43 ~40 ~0 ~43 wool
fill ~36 ~0 ~44 ~40 ~0 ~44 wool
fill ~36 ~0 ~45 ~40 ~0 ~45 log 5
fill ~36 ~0 ~46 ~40 ~0 ~46 wool
fill ~36 ~0 ~47 ~40 ~0 ~47 wool
fill ~36 ~0 ~48 ~40 ~0 ~48 wool
fill ~36 ~0 ~49 ~40 ~0 ~49 wool
fill ~36 ~0 ~50 ~40 ~0 ~50 wool
fill ~36 ~0 ~51 ~40 ~0 ~51 log 5
fill ~36 ~0 ~52 ~40 ~0 ~52 wool
fill ~36 ~0 ~53 ~40 ~0 ~53 wool
fill ~36 ~0 ~54 ~40 ~0 ~54 wool
fill ~36 ~0 ~55 ~40 ~0 ~55 wool
fill ~36 ~0 ~56 ~40 ~0 ~56 wool
fill ~36 ~0 ~57 ~40 ~0 ~57 log 5
fill ~36 ~0 ~58 ~40 ~0 ~58 wool
fill ~36 ~0 ~59 ~40 ~0 ~59 wool
fill ~36 ~0 ~60 ~40 ~0 ~60 wool
fill ~36 ~0 ~61 ~40 ~0 ~61 wool
fill ~36 ~0 ~62 ~40 ~0 ~62 wool
fill ~36 ~0 ~63 ~40 ~0 ~63 log 5
fill ~36 ~0 ~64 ~40 ~0 ~64 wool
fill ~36 ~0 ~65 ~40 ~0 ~65 wool
fill ~36 ~0 ~66 ~40 ~0 ~66 wool
fill ~36 ~0 ~67 ~40 ~0 ~67 wool
fill ~36 ~0 ~68 ~40 ~0 ~68 wool
fill ~36 ~0 ~70 ~40 ~0 ~70 wool
fill ~36 ~0 ~71 ~40 ~0 ~71 wool
fill ~36 ~0 ~72 ~40 ~0 ~72 wool
fill ~36 ~0 ~73 ~40 ~0 ~73 wool
fill ~36 ~0 ~74 ~40 ~0 ~74 wool
fill ~36 ~0 ~76 ~40 ~0 ~76 wool
fill ~36 ~0 ~77 ~40 ~0 ~77 wool
fill ~36 ~0 ~78 ~40 ~0 ~78 wool
fill ~36 ~0 ~79 ~40 ~0 ~79 wool
fill ~36 ~0 ~80 ~40 ~0 ~80 wool
fill ~36 ~0 ~82 ~40 ~0 ~82 wool
fill ~36 ~0 ~83 ~40 ~0 ~83 wool
fill ~36 ~0 ~84 ~40 ~0 ~84 wool
fill ~36 ~0 ~85 ~40 ~0 ~85 wool
fill ~36 ~0 ~86 ~40 ~0 ~86 wool
fill ~36 ~0 ~88 ~40 ~0 ~88 wool
fill ~36 ~0 ~89 ~40 ~0 ~89 wool
fill ~36 ~0 ~90 ~40 ~0 ~90 wool
fill ~36 ~0 ~91 ~40 ~0 ~91 wool
fill ~36 ~0 ~92 ~40 ~0 ~92 wool
fill ~41 ~0 ~10 ~41 ~0 ~68 log 9
fill ~41 ~0 ~70 ~41 ~0 ~74 log 9
fill ~41 ~0 ~76 ~41 ~0 ~80 log 9
fill ~41 ~0 ~82 ~41 ~0 ~86 log 9
fill ~41 ~0 ~88 ~41 ~0 ~92 log 9
fill ~42 ~0 ~9 ~42 ~0 ~67 log 1
fill ~42 ~0 ~70 ~46 ~0 ~70 wool
fill ~42 ~0 ~71 ~46 ~0 ~71 wool
fill ~42 ~0 ~72 ~46 ~0 ~72 wool
fill ~42 ~0 ~73 ~46 ~0 ~73 wool
fill ~42 ~0 ~74 ~46 ~0 ~74 wool
fill ~42 ~0 ~76 ~46 ~0 ~76 wool
fill ~42 ~0 ~77 ~46 ~0 ~77 wool
fill ~42 ~0 ~78 ~46 ~0 ~78 wool
fill ~42 ~0 ~79 ~46 ~0 ~79 wool
fill ~42 ~0 ~80 ~46 ~0 ~80 wool
fill ~42 ~0 ~82 ~46 ~0 ~82 wool
fill ~42 ~0 ~83 ~46 ~0 ~83 wool
fill ~42 ~0 ~84 ~46 ~0 ~84 wool
fill ~42 ~0 ~85 ~46 ~0 ~85 wool
fill ~42 ~0 ~86 ~46 ~0 ~86 wool
fill ~42 ~0 ~88 ~46 ~0 ~88 wool
fill ~42 ~0 ~89 ~46 ~0 ~89 wool
fill ~42 ~0 ~90 ~46 ~0 ~90 wool
fill ~42 ~0 ~91 ~46 ~0 ~91 wool
fill ~42 ~0 ~92 ~46 ~0 ~92 wool
fill ~43 ~0 ~68 ~102 ~0 ~68 log 1
fill ~47 ~0 ~70 ~47 ~0 ~74 log 9
fill ~47 ~0 ~76 ~47 ~0 ~80 log 9
fill ~47 ~0 ~82 ~47 ~0 ~86 log 9
fill ~47 ~0 ~88 ~47 ~0 ~92 log 9
fill ~48 ~0 ~70 ~52 ~0 ~70 wool
fill ~48 ~0 ~71 ~52 ~0 ~71 wool
fill ~48 ~0 ~72 ~52 ~0 ~72 wool
fill ~48 ~0 ~73 ~52 ~0 ~73 wool
fill ~48 ~0 ~74 ~52 ~0 ~74 wool
fill ~48 ~0 ~76 ~52 ~0 ~76 wool
fill ~48 ~0 ~77 ~52 ~0 ~77 wool
fill ~48 ~0 ~78 ~52 ~0 ~78 wool
fill ~48 ~0 ~79 ~52 ~0 ~79 wool
fill ~48 ~0 ~80 ~52 ~0 ~80 wool
fill ~48 ~0 ~82 ~52 ~0 ~82 wool
fill ~48 ~0 ~83 ~52 ~0 ~83 wool
fill ~48 ~0 ~84 ~52 ~0 ~84 wool
fill ~48 ~0 ~85 ~52 ~0 ~85 wool
fill ~48 ~0 ~86 ~52 ~0 ~86 wool
fill ~48 ~0 ~88 ~52 ~0 ~88 wool
fill ~48 ~0 ~89 ~52 ~0 ~89 wool
fill ~48 ~0 ~90 ~52 ~0 ~90 wool
fill ~48 ~0 ~91 ~52 ~0 ~91 wool
fill ~48 ~0 ~92 ~52 ~0 ~92 wool
fill ~53 ~0 ~70 ~53 ~1 ~70 log 9
fill ~53 ~0 ~71 ~53 ~1 ~71 log 9
fill ~53 ~0 ~72 ~53 ~1 ~72 log 9
fill ~53 ~0 ~73 ~53 ~1 ~73 log 9
fill ~53 ~0 ~74 ~53 ~1 ~74 log 9
fill ~53 ~0 ~76 ~53 ~0 ~80 log 9
fill ~53 ~0 ~82 ~53 ~0 ~86 log 9
fill ~53 ~0 ~88 ~53 ~0 ~92 log 9
fill ~54 ~0 ~70 ~58 ~0 ~70 wool
fill ~54 ~0 ~71 ~58 ~0 ~71 wool
fill ~54 ~0 ~72 ~58 ~0 ~72 wool
fill ~54 ~0 ~73 ~58 ~0 ~73 wool
fill ~54 ~0 ~74 ~58 ~0 ~74 wool
fill ~54 ~0 ~76 ~58 ~0 ~76 wool
fill ~54 ~0 ~77 ~58 ~0 ~77 wool
fill ~54 ~0 ~78 ~58 ~0 ~78 wool
fill ~54 ~0 ~79 ~58 ~0 ~79 wool
fill ~54 ~0 ~80 ~58 ~0 ~80 wool
fill ~54 ~0 ~82 ~58 ~0 ~82 wool
fill ~54 ~0 ~83 ~58 ~0 ~83 wool
fill ~54 ~0 ~84 ~58 ~0 ~84 wool
fill ~54 ~0 ~85 ~58 ~0 ~85 wool
fill ~54 ~0 ~86 ~58 ~0 ~86 wool
fill ~54 ~0 ~88 ~58 ~0 ~88 wool
fill ~54 ~0 ~89 ~58 ~0 ~89 wool
fill ~54 ~0 ~90 ~58 ~0 ~90 wool
fill ~54 ~0 ~91 ~58 ~0 ~91 wool
fill ~54 ~0 ~92 ~58 ~0 ~92 wool
fill ~59 ~0 ~70 ~59 ~0 ~74 log 9
fill ~59 ~0 ~76 ~59 ~0 ~80 log 9
fill ~59 ~0 ~82 ~59 ~0 ~86 log 9
fill ~59 ~0 ~88 ~59 ~0 ~92 log 9
fill ~60 ~0 ~70 ~64 ~0 ~70 wool
fill ~60 ~0 ~71 ~64 ~0 ~71 wool
fill ~60 ~0 ~72 ~64 ~0 ~72 wool
fill ~60 ~0 ~73 ~64 ~0 ~73 wool
fill ~60 ~0 ~74 ~64 ~0 ~74 wool
fill ~60 ~0 ~76 ~64 ~0 ~76 wool
fill ~60 ~0 ~77 ~64 ~0 ~77 wool
fill ~60 ~0 ~78 ~64 ~0 ~78 wool
fill ~60 ~0 ~79 ~64 ~0 ~79 wool
fill ~60 ~0 ~80 ~64 ~0 ~80 wool
fill ~60 ~0 ~82 ~64 ~0 ~82 wool
fill ~60 ~0 ~83 ~64 ~0 ~83 wool
fill ~60 ~0 ~84 ~64 ~0 ~84 wool
fill ~60 ~0 ~85 ~64 ~0 ~85 wool
fill ~60 ~0 ~86 ~64 ~0 ~86 wool
fill ~60 ~0 ~88 ~64 ~0 ~88 wool
fill ~60 ~0 ~89 ~64 ~0 ~89 wool
fill ~60 ~0 ~90 ~64 ~0 ~90 wool
fill ~60 ~0 ~91 ~64 ~0 ~91 wool
fill ~60 ~0 ~92 ~64 ~0 ~92 wool
fill ~65 ~0 ~70 ~65 ~0 ~74 log 9
fill ~65 ~0 ~76 ~65 ~0 ~80 log 9
fill ~65 ~0 ~82 ~65 ~0 ~86 log 9
fill ~65 ~0 ~88 ~65 ~0 ~92 log 9
fill ~66 ~0 ~70 ~70 ~0 ~70 wool
fill ~66 ~0 ~71 ~70 ~0 ~71 wool
fill ~66 ~0 ~72 ~70 ~0 ~72 wool
fill ~66 ~0 ~73 ~70 ~0 ~73 wool
fill ~66 ~0 ~74 ~70 ~0 ~74 wool
fill ~66 ~0 ~76 ~70 ~0 ~76 wool
fill ~66 ~0 ~77 ~70 ~0 ~77 wool
fill ~66 ~0 ~78 ~70 ~0 ~78 wool
fill ~66 ~0 ~79 ~70 ~0 ~79 wool
fill ~66 ~0 ~80 ~70 ~0 ~80 wool
fill ~66 ~0 ~82 ~70 ~0 ~82 wool
fill ~66 ~0 ~83 ~70 ~0 ~83 wool
fill ~66 ~0 ~84 ~70 ~0 ~84 wool
fill ~66 ~0 ~85 ~70 ~0 ~85 wool
fill ~66 ~0 ~86 ~70 ~0 ~86 wool
fill ~66 ~0 ~88 ~70 ~0 ~88 wool
fill ~66 ~0 ~89 ~70 ~0 ~89 wool
fill ~66 ~0 ~90 ~70 ~0 ~90 wool
fill ~66 ~0 ~91 ~70 ~0 ~91 wool
fill ~66 ~0 ~92 ~70 ~0 ~92 wool
fill ~71 ~0 ~70 ~71 ~0 ~74 log 9
fill ~71 ~0 ~76 ~71 ~0 ~80 log 9
fill ~71 ~0 ~82 ~71 ~0 ~86 log 9
fill ~71 ~0 ~88 ~71 ~0 ~92 log 9
fill ~72 ~0 ~70 ~76 ~0 ~70 wool
fill ~72 ~0 ~71 ~76 ~0 ~71 wool
fill ~72 ~0 ~72 ~76 ~0 ~72 wool
fill ~72 ~0 ~73 ~76 ~0 ~73 wool
fill ~72 ~0 ~74 ~76 ~0 ~74 wool
fill ~72 ~0 ~76 ~76 ~0 ~76 wool
fill ~72 ~0 ~77 ~76 ~0 ~77 wool
fill ~72 ~0 ~78 ~76 ~0 ~78 wool
fill ~72 ~0 ~79 ~76 ~0 ~79 wool
fill ~72 ~0 ~80 ~76 ~0 ~80 wool
fill ~72 ~0 ~82 ~76 ~0 ~82 wool
fill ~72 ~0 ~83 ~76 ~0 ~83 wool
fill ~72 ~0 ~84 ~76 ~0 ~84 wool
fill ~72 ~0 ~85 ~76 ~0 ~85 wool
fill ~72 ~0 ~86 ~76 ~0 ~86 wool
fill ~72 ~0 ~88 ~76 ~0 ~88 wool
fill ~72 ~0 ~89 ~76 ~0 ~89 wool
fill ~72 ~0 ~90 ~76 ~0 ~90 wool
fill ~72 ~0 ~91 ~76 ~0 ~91 wool
fill ~72 ~0 ~92 ~76 ~0 ~92 wool
fill ~77 ~0 ~70 ~77 ~0 ~74 log 9
fill ~77 ~0 ~76 ~77 ~0 ~80 log 9
fill ~77 ~0 ~82 ~77 ~0 ~86 log 9
fill ~77 ~0 ~88 ~77 ~0 ~92 log 9
fill ~78 ~0 ~70 ~82 ~0 ~70 wool
fill ~78 ~0 ~71 ~82 ~0 ~71 wool
fill ~78 ~0 ~72 ~82 ~0 ~72 wool
fill ~78 ~0 ~73 ~82 ~0 ~73 wool
fill ~78 ~0 ~74 ~82 ~0 ~74 wool
fill ~78 ~0 ~76 ~82 ~0 ~76 wool
fill ~78 ~0 ~77 ~82 ~0 ~77 wool
fill ~78 ~0 ~78 ~82 ~0 ~78 wool
fill ~78 ~0 ~79 ~82 ~0 ~79 wool
fill ~78 ~0 ~80 ~82 ~0 ~80 wool
fill ~78 ~0 ~82 ~82 ~0 ~82 wool
fill ~78 ~0 ~83 ~82 ~0 ~83 wool
fill ~78 ~0 ~84 ~82 ~0 ~84 wool
fill ~78 ~0 ~85 ~82 ~0 ~85 wool
fill ~78 ~0 ~86 ~82 ~0 ~86 wool
fill ~78 ~0 ~88 ~82 ~0 ~88 wool
fill ~78 ~0 ~89 ~82 ~0 ~89 wool
fill ~78 ~0 ~90 ~82 ~0 ~90 wool
fill ~78 ~0 ~91 ~82 ~0 ~91 wool
fill ~78 ~0 ~92 ~82 ~0 ~92 wool
fill ~83 ~0 ~70 ~83 ~0 ~74 log 9
fill ~83 ~0 ~76 ~83 ~0 ~80 log 9
fill ~83 ~0 ~82 ~83 ~1 ~82 log 9
fill ~83 ~0 ~83 ~83 ~0 ~86 log 9
fill ~83 ~0 ~88 ~83 ~0 ~92 log 9
fill ~84 ~0 ~70 ~88 ~0 ~70 wool
fill ~84 ~0 ~71 ~88 ~0 ~71 wool
fill ~84 ~0 ~72 ~88 ~0 ~72 wool
fill ~84 ~0 ~73 ~88 ~0 ~73 wool
fill ~84 ~0 ~74 ~88 ~0 ~74 wool
fill ~84 ~0 ~76 ~88 ~0 ~76 wool
fill ~84 ~0 ~77 ~88 ~0 ~77 wool
fill ~84 ~0 ~78 ~88 ~0 ~78 wool
fill ~84 ~0 ~79 ~88 ~0 ~79 wool
fill ~84 ~0 ~80 ~88 ~0 ~80 wool
fill ~84 ~0 ~82 ~88 ~0 ~82 wool
fill ~84 ~0 ~83 ~88 ~0 ~83 wool
fill ~84 ~0 ~84 ~88 ~0 ~84 wool
fill ~84 ~0 ~85 ~88 ~0 ~85 wool
fill ~84 ~0 ~86 ~88 ~0 ~86 wool
fill ~84 ~0 ~88 ~88 ~0 ~88 wool
fill ~84 ~0 ~89 ~88 ~0 ~89 wool
fill ~84 ~0 ~90 ~88 ~0 ~90 wool
fill ~84 ~0 ~91 ~88 ~0 ~91 wool
fill ~84 ~0 ~92 ~88 ~0 ~92 wool
fill ~89 ~0 ~70 ~89 ~0 ~74 log 9
fill ~89 ~0 ~76 ~89 ~0 ~80 log 9
fill ~89 ~0 ~82 ~89 ~1 ~82 log 9
fill ~89 ~0 ~83 ~89 ~1 ~83 log 9
fill ~89 ~0 ~84 ~89 ~1 ~84 log 9
fill ~89 ~0 ~85 ~89 ~1 ~85 log 9
fill ~89 ~0 ~86 ~89 ~0 ~82 log 9
fill ~89 ~0 ~88 ~89 ~0 ~92 log 9
fill ~90 ~0 ~70 ~94 ~0 ~70 wool
fill ~90 ~0 ~71 ~94 ~0 ~71 wool
fill ~90 ~0 ~72 ~94 ~0 ~72 wool
fill ~90 ~0 ~73 ~94 ~0 ~73 wool
fill ~90 ~0 ~74 ~94 ~0 ~74 wool
fill ~90 ~0 ~76 ~94 ~0 ~76 wool
fill ~90 ~0 ~77 ~94 ~0 ~77 wool
fill ~90 ~0 ~78 ~94 ~0 ~78 wool
fill ~90 ~0 ~79 ~94 ~0 ~79 wool
fill ~90 ~0 ~80 ~94 ~0 ~80 wool
fill ~90 ~0 ~82 ~94 ~0 ~82 wool
fill ~90 ~0 ~83 ~94 ~0 ~83 wool
fill ~90 ~0 ~84 ~94 ~0 ~84 wool
fill ~90 ~0 ~85 ~94 ~0 ~85 wool
fill ~90 ~0 ~86 ~94 ~0 ~86 wool
fill ~90 ~0 ~88 ~94 ~0 ~88 wool
fill ~90 ~0 ~89 ~94 ~0 ~89 wool
fill ~90 ~0 ~90 ~94 ~0 ~90 wool
fill ~90 ~0 ~91 ~94 ~0 ~91 wool
fill ~90 ~0 ~92 ~94 ~0 ~92 wool
fill ~95 ~0 ~70 ~95 ~0 ~74 log 9
fill ~95 ~0 ~76 ~95 ~0 ~80 log 9
fill ~95 ~0 ~82 ~95 ~0 ~86 log 9
fill ~95 ~0 ~88 ~95 ~0 ~92 log 9
fill ~96 ~0 ~70 ~100 ~0 ~70 wool
fill ~96 ~0 ~71 ~100 ~0 ~71 wool
fill ~96 ~0 ~72 ~100 ~0 ~72 wool
fill ~96 ~0 ~73 ~100 ~0 ~73 wool
fill ~96 ~0 ~74 ~100 ~0 ~74 wool
fill ~96 ~0 ~76 ~100 ~0 ~76 wool
fill ~96 ~0 ~77 ~100 ~0 ~77 wool
fill ~96 ~0 ~78 ~100 ~0 ~78 wool
fill ~96 ~0 ~79 ~100 ~0 ~79 wool
fill ~96 ~0 ~80 ~100 ~0 ~80 wool
fill ~96 ~0 ~82 ~100 ~0 ~82 wool
fill ~96 ~0 ~83 ~100 ~0 ~83 wool
fill ~96 ~0 ~84 ~100 ~0 ~84 wool
fill ~96 ~0 ~85 ~100 ~0 ~85 wool
fill ~96 ~0 ~86 ~100 ~0 ~86 wool
fill ~96 ~0 ~88 ~100 ~0 ~88 wool
fill ~96 ~0 ~89 ~100 ~0 ~89 wool
fill ~96 ~0 ~90 ~100 ~0 ~90 wool
fill ~96 ~0 ~91 ~100 ~0 ~91 wool
fill ~96 ~0 ~92 ~100 ~0 ~92 wool
fill ~101 ~0 ~70 ~101 ~0 ~74 log 9
fill ~101 ~0 ~76 ~101 ~0 ~80 log 9
fill ~101 ~0 ~82 ~101 ~0 ~86 log 9
fill ~101 ~0 ~88 ~101 ~0 ~92 log 9
fill ~102 ~0 ~69 ~102 ~80 ~69 log 1
fill ~102 ~0 ~70 ~102 ~0 ~94 log 1
setblock ~108 ~0 ~2 stained_glass
fill ~16 ~1 ~8 ~17 ~1 ~8 log 1
fill ~16 ~1 ~10 ~16 ~5 ~10 planks 5
fill ~16 ~1 ~11 ~16 ~5 ~11 planks 5
fill ~16 ~1 ~12 ~16 ~5 ~12 planks 5
fill ~16 ~1 ~13 ~16 ~5 ~13 planks 5
fill ~16 ~1 ~14 ~16 ~5 ~14 planks 5
fill ~16 ~1 ~15 ~21 ~1 ~15 log 1
fill ~16 ~1 ~16 ~16 ~5 ~16 planks 3
fill ~16 ~1 ~17 ~16 ~5 ~17 planks 3
fill ~16 ~1 ~18 ~16 ~5 ~18 planks 3
fill ~16 ~1 ~19 ~16 ~5 ~19 planks 3
fill ~16 ~1 ~20 ~16 ~5 ~20 planks 3
fill ~16 ~1 ~21 ~28 ~1 ~21 log 1
fill ~16 ~1 ~22 ~16 ~5 ~22 planks 5
fill ~16 ~1 ~23 ~16 ~5 ~23 planks 5
fill ~16 ~1 ~24 ~16 ~5 ~24 planks 5
fill ~16 ~1 ~25 ~16 ~5 ~25 planks 5
fill ~16 ~1 ~26 ~16 ~5 ~26 planks 5
fill ~16 ~1 ~27 ~17 ~1 ~27 log 1
fill ~16 ~1 ~28 ~16 ~5 ~28 planks 1
fill ~16 ~1 ~29 ~16 ~5 ~29 planks 1
fill ~16 ~1 ~30 ~16 ~5 ~30 planks 1
fill ~16 ~1 ~31 ~16 ~5 ~31 planks 1
fill ~16 ~1 ~32 ~16 ~5 ~32 planks 1
fill ~16 ~1 ~33 ~17 ~1 ~33 log 1
fill ~16 ~1 ~34 ~16 ~5 ~34 hay_block
fill ~16 ~1 ~35 ~16 ~5 ~35 hay_block
fill ~16 ~1 ~36 ~16 ~5 ~36 hay_block
fill ~16 ~1 ~37 ~16 ~5 ~37 hay_block
fill ~16 ~1 ~38 ~16 ~5 ~38 hay_block
fill ~16 ~1 ~39 ~23 ~1 ~39 log 1
fill ~16 ~1 ~40 ~16 ~5 ~40 planks 5
fill ~16 ~1 ~41 ~16 ~5 ~41 planks 5
fill ~16 ~1 ~42 ~16 ~5 ~42 planks 5
fill ~16 ~1 ~43 ~16 ~5 ~43 planks 5
fill ~16 ~1 ~44 ~16 ~5 ~44 planks 5
fill ~16 ~1 ~45 ~17 ~1 ~45 log 1
fill ~16 ~1 ~46 ~16 ~5 ~46 planks 3
fill ~16 ~1 ~47 ~16 ~5 ~47 planks 3
fill ~16 ~1 ~48 ~16 ~5 ~48 planks 3
fill ~16 ~1 ~49 ~16 ~5 ~49 planks 3
fill ~16 ~1 ~50 ~16 ~5 ~50 planks 3
fill ~16 ~1 ~51 ~16 ~46 ~51 log 1
fill ~16 ~1 ~52 ~16 ~5 ~52 planks 5
fill ~16 ~1 ~53 ~16 ~5 ~53 planks 5
fill ~16 ~1 ~54 ~16 ~5 ~54 planks 5
fill ~16 ~1 ~55 ~16 ~5 ~55 planks 5
fill ~16 ~1 ~56 ~16 ~5 ~56 planks 5
fill ~16 ~1 ~57 ~16 ~80 ~57 log 1
fill ~16 ~1 ~58 ~16 ~5 ~58 planks 1
fill ~16 ~1 ~59 ~16 ~5 ~59 planks 1
fill ~16 ~1 ~60 ~16 ~5 ~60 planks 1
fill ~16 ~1 ~61 ~16 ~5 ~61 planks 1
fill ~16 ~1 ~62 ~16 ~5 ~62 planks 1
fill ~16 ~1 ~63 ~17 ~1 ~63 log 1
fill ~16 ~1 ~64 ~16 ~5 ~64 planks 5
fill ~16 ~1 ~65 ~16 ~5 ~65 planks 5
fill ~16 ~1 ~66 ~16 ~5 ~66 planks 5
fill ~16 ~1 ~67 ~16 ~5 ~67 planks 5
fill ~16 ~1 ~68 ~16 ~5 ~68 planks 5
fill ~16 ~1 ~69 ~17 ~1 ~69 log 1
fill ~16 ~1 ~70 ~16 ~5 ~70 planks 3
fill ~16 ~1 ~71 ~16 ~5 ~71 planks 3
fill ~16 ~1 ~72 ~16 ~5 ~72 planks 3
fill ~16 ~1 ~73 ~16 ~5 ~73 planks 3
fill ~16 ~1 ~74 ~16 ~5 ~74 planks 3
fill ~16 ~1 ~75 ~17 ~1 ~75 log 1
fill ~16 ~1 ~76 ~16 ~5 ~76 planks 5
fill ~16 ~1 ~77 ~16 ~5 ~77 planks 5
fill ~16 ~1 ~78 ~16 ~5 ~78 planks 5
fill ~16 ~1 ~79 ~16 ~5 ~79 planks 5
fill ~16 ~1 ~80 ~16 ~5 ~80 planks 5
fill ~16 ~1 ~81 ~17 ~1 ~81 log 1
fill ~16 ~1 ~82 ~16 ~5 ~82 planks 1
fill ~16 ~1 ~83 ~16 ~5 ~83 planks 1
fill ~16 ~1 ~84 ~16 ~5 ~84 planks 1
fill ~16 ~1 ~85 ~16 ~5 ~85 planks 1
fill ~16 ~1 ~86 ~16 ~5 ~86 planks 1
fill ~16 ~1 ~87 ~17 ~1 ~87 log 1
fill ~16 ~1 ~88 ~16 ~5 ~88 planks 3
fill ~16 ~1 ~89 ~16 ~5 ~89 planks 3
fill ~16 ~1 ~90 ~16 ~5 ~90 planks 3
fill ~16 ~1 ~91 ~16 ~5 ~91 planks 3
fill ~16 ~1 ~92 ~16 ~5 ~92 planks 3
fill ~16 ~1 ~93 ~62 ~1 ~93 log 1
fill ~16 ~1 ~94 ~17 ~1 ~94 log 1
fill ~17 ~1 ~9 ~41 ~1 ~9 log 1
fill ~17 ~1 ~10 ~17 ~3 ~10 log 1
fill ~17 ~1 ~11 ~17 ~3 ~11 log 1
fill ~17 ~1 ~12 ~17 ~3 ~12 log 1
fill ~17 ~1 ~13 ~17 ~3 ~13 log 1
fill ~17 ~1 ~14 ~17 ~3 ~14 log 1
fill ~17 ~1 ~16 ~20 ~1 ~16 log 5
fill ~17 ~1 ~17 ~17 ~1 ~19 log 9
fill ~17 ~1 ~20 ~20 ~1 ~20 log 5
fill ~17 ~1 ~22 ~17 ~1 ~48 log 1
fill ~17 ~1 ~49 ~17 ~1 ~61 log 9
fill ~17 ~1 ~62 ~23 ~1 ~62 log 1
fill ~17 ~1 ~64 ~17 ~2 ~64 log 1
fill ~17 ~1 ~65 ~17 ~2 ~65 log 1
fill ~17 ~1 ~66 ~17 ~2 ~66 log 1
fill ~17 ~1 ~67 ~17 ~2 ~67 log 1
fill ~17 ~1 ~68 ~17 ~2 ~68 log 1
fill ~17 ~1 ~70 ~17 ~2 ~70 log 1
fill ~17 ~1 ~71 ~17 ~2 ~71 log 1
fill ~17 ~1 ~72 ~17 ~2 ~72 log 1
fill ~17 ~1 ~73 ~17 ~2 ~73 log 1
fill ~17 ~1 ~74 ~17 ~2 ~74 log 1
fill ~17 ~1 ~76 ~25 ~1 ~76 log 1
fill ~17 ~1 ~77 ~25 ~1 ~77 log 1
fill ~17 ~1 ~78 ~17 ~3 ~78 log 1
fill ~17 ~1 ~79 ~17 ~3 ~79 log 1
fill ~17 ~1 ~80 ~17 ~3 ~80 log 1
fill ~17 ~1 ~82 ~17 ~3 ~82 log 1
fill ~17 ~1 ~83 ~17 ~3 ~83 log 1
fill ~17 ~1 ~84 ~17 ~3 ~84 log 1
fill ~17 ~1 ~85 ~17 ~3 ~85 log 1
fill ~17 ~1 ~86 ~17 ~3 ~86 log 1
fill ~17 ~1 ~88 ~17 ~3 ~88 log 1
fill ~17 ~1 ~89 ~17 ~3 ~89 log 1
fill ~17 ~1 ~90 ~17 ~3 ~90 log 1
fill ~17 ~1 ~91 ~17 ~3 ~91 log 1
fill ~17 ~1 ~92 ~17 ~3 ~92 log 1
fill ~18 ~1 ~8 ~22 ~1 ~8 planks 3
fill ~18 ~1 ~10 ~19 ~1 ~10 planks 1
fill ~18 ~1 ~11 ~19 ~1 ~11 planks 1
fill ~18 ~1 ~12 ~19 ~1 ~12 planks 1
fill ~18 ~1 ~13 ~19 ~1 ~13 planks 1
fill ~18 ~1 ~14 ~19 ~1 ~14 planks 1
fill ~18 ~1 ~17 ~19 ~1 ~17 wool
fill ~18 ~1 ~18 ~19 ~1 ~18 wool 11
fill ~18 ~1 ~19 ~19 ~1 ~19 wool 11
fill ~18 ~1 ~22 ~27 ~1 ~22 planks 5
fill ~18 ~1 ~23 ~25 ~1 ~23 planks 5
fill ~18 ~1 ~24 ~27 ~1 ~24 planks 5
fill ~18 ~1 ~25 ~24 ~1 ~25 planks 5
fill ~18 ~1 ~26 ~24 ~1 ~26 planks 5
fill ~18 ~1 ~27 ~24 ~1 ~27 planks 5
fill ~18 ~1 ~28 ~26 ~1 ~28 log 1
fill ~18 ~1 ~29 ~26 ~1 ~29 log 1
fill ~18 ~1 ~30 ~24 ~1 ~30 planks 1
fill ~18 ~1 ~31 ~24 ~1 ~31 planks 1
fill ~18 ~1 ~32 ~22 ~1 ~32 planks 1
fill ~18 ~1 ~33 ~22 ~1 ~33 planks 1
fill ~18 ~1 ~34 ~22 ~1 ~34 planks 1
fill ~18 ~1 ~35 ~22 ~1 ~35 planks 1
fill ~18 ~1 ~36 ~22 ~1 ~36 planks 1
fill ~18 ~1 ~37 ~22 ~1 ~37 planks 1
fill ~18 ~1 ~38 ~22 ~1 ~38 planks 1
fill ~18 ~1 ~40 ~29 ~1 ~40 log 1
fill ~18 ~1 ~41 ~28 ~1 ~41 planks 3
fill ~18 ~1 ~42 ~28 ~1 ~42 planks 3
fill ~18 ~1 ~43 ~28 ~1 ~43 planks 3
fill ~18 ~1 ~44 ~28 ~1 ~44 planks 3
fill ~18 ~1 ~45 ~28 ~1 ~45 planks 3
fill ~18 ~1 ~46 ~28 ~1 ~46 planks 3
fill ~18 ~1 ~47 ~21 ~1 ~47 planks 3
fill ~18 ~1 ~48 ~30 ~1 ~48 log 1
fill ~18 ~1 ~49 ~21 ~1 ~49 log 5
fill ~18 ~1 ~50 ~20 ~1 ~50 wool 11
fill ~18 ~1 ~51 ~20 ~1 ~51 wool 11
fill ~18 ~1 ~52 ~21 ~1 ~52 log 5
fill ~18 ~1 ~53 ~20 ~1 ~53 wool 11
fill ~18 ~1 ~54 ~20 ~1 ~54 wool 11
fill ~18 ~1 ~55 ~21 ~1 ~55 log 5
fill ~18 ~1 ~56 ~20 ~1 ~56 wool 11
fill ~18 ~1 ~57 ~20 ~1 ~57 wool 11
fill ~18 ~1 ~58 ~21 ~1 ~58 log 5
fill ~18 ~1 ~59 ~20 ~1 ~59 wool 11
fill ~18 ~1 ~60 ~20 ~1 ~60 wool 11
fill ~18 ~1 ~61 ~21 ~1 ~61 log 5
fill ~18 ~1 ~63 ~21 ~1 ~63 planks 2
fill ~18 ~1 ~64 ~21 ~1 ~64 planks 2
fill ~18 ~1 ~65 ~21 ~1 ~65 planks 2
fill ~18 ~1 ~66 ~21 ~1 ~66 planks 2
fill ~18 ~1 ~67 ~21 ~1 ~67 planks 2
fill ~18 ~1 ~68 ~24 ~1 ~68 planks 2
fill ~18 ~1 ~69 ~24 ~1 ~69 planks 2
fill ~18 ~1 ~70 ~24 ~1 ~70 planks 2
fill ~18 ~1 ~71 ~24 ~1 ~71 planks 2
fill ~18 ~1 ~72 ~24 ~1 ~72 planks 2
fill ~18 ~1 ~73 ~24 ~1 ~73 planks 2
fill ~18 ~1 ~74 ~24 ~1 ~74 planks 2
fill ~18 ~1 ~75 ~24 ~1 ~75 planks 2
fill ~18 ~1 ~78 ~24 ~1 ~78 planks 5
fill ~18 ~1 ~79 ~24 ~1 ~79 planks 5
fill ~18 ~1 ~80 ~24 ~1 ~80 planks 5
fill ~18 ~1 ~81 ~24 ~1 ~81 planks 5
fill ~18 ~1 ~82 ~24 ~1 ~82 planks 5
fill ~18 ~1 ~83 ~24 ~1 ~83 planks 5
fill ~18 ~1 ~84 ~24 ~1 ~84 planks 5
fill ~18 ~1 ~85 ~24 ~1 ~85 planks 5
fill ~18 ~1 ~86 ~21 ~1 ~86 planks 5
fill ~18 ~1 ~87 ~21 ~1 ~87 planks 5
fill ~18 ~1 ~88 ~21 ~1 ~88 planks 5
fill ~18 ~1 ~89 ~21 ~1 ~89 planks 5
fill ~18 ~1 ~90 ~21 ~1 ~90 planks 5
fill ~18 ~1 ~91 ~21 ~1 ~91 planks 5
fill ~18 ~1 ~92 ~21 ~1 ~92 planks 5
fill ~18 ~1 ~94 ~22 ~1 ~94 planks 5
fill ~20 ~1 ~10 ~21 ~1 ~10 log 1
fill ~20 ~1 ~11 ~21 ~1 ~11 log 1
fill ~20 ~1 ~12 ~21 ~1 ~12 log 1
fill ~20 ~1 ~13 ~21 ~1 ~13 log 1
fill ~20 ~1 ~14 ~21 ~1 ~14 log 1
fill ~20 ~1 ~17 ~20 ~1 ~19 log 9
fill ~21 ~1 ~16 ~21 ~2 ~16 log 1
fill ~21 ~1 ~17 ~21 ~2 ~17 log 1
fill ~21 ~1 ~18 ~21 ~2 ~18 log 1
fill ~21 ~1 ~19 ~21 ~2 ~19 log 1
fill ~21 ~1 ~20 ~28 ~1 ~20 log 1
fill ~21 ~1 ~50 ~21 ~1 ~51 wool
fill ~21 ~1 ~53 ~21 ~1 ~54 wool
fill ~21 ~1 ~56 ~21 ~1 ~57 wool
fill ~21 ~1 ~59 ~21 ~1 ~60 wool
fill ~22 ~1 ~10 ~30 ~1 ~10 planks 3
fill ~22 ~1 ~11 ~30 ~1 ~11 planks 3
fill ~22 ~1 ~12 ~30 ~1 ~12 planks 3
fill ~22 ~1 ~13 ~30 ~1 ~13 planks 3
fill ~22 ~1 ~14 ~27 ~1 ~14 planks 3
fill ~22 ~1 ~15 ~27 ~1 ~15 planks 3
fill ~22 ~1 ~16 ~27 ~1 ~16 planks 3
fill ~22 ~1 ~17 ~27 ~1 ~17 planks 3
fill ~22 ~1 ~18 ~27 ~1 ~18 planks 3
fill ~22 ~1 ~19 ~27 ~1 ~19 planks 3
fill ~22 ~1 ~47 ~37 ~1 ~47 log 1
fill ~22 ~1 ~49 ~22 ~1 ~61 log 9
fill ~22 ~1 ~63 ~23 ~1 ~63 log 1
fill ~22 ~1 ~64 ~23 ~1 ~64 log 1
fill ~22 ~1 ~65 ~23 ~1 ~65 log 1
fill ~22 ~1 ~66 ~30 ~1 ~66 log 1
fill ~22 ~1 ~67 ~30 ~1 ~67 log 1
fill ~22 ~1 ~86 ~25 ~1 ~86 log 1
fill ~22 ~1 ~87 ~36 ~1 ~87 log 1
fill ~22 ~1 ~88 ~23 ~1 ~88 log 1
fill ~22 ~1 ~89 ~23 ~1 ~89 log 1
fill ~22 ~1 ~90 ~23 ~1 ~90 log 1
fill ~22 ~1 ~91 ~23 ~1 ~91 log 1
fill ~22 ~1 ~92 ~23 ~1 ~92 log 1
fill ~23 ~1 ~8 ~23 ~5 ~8 log 1
fill ~23 ~1 ~32 ~37 ~1 ~32 log 1
fill ~23 ~1 ~33 ~23 ~3 ~33 log 1
fill ~23 ~1 ~34 ~23 ~1 ~40 log 1
fill ~23 ~1 ~49 ~23 ~3 ~49 log 1
fill ~23 ~1 ~50 ~23 ~1 ~67 log 1
fill ~23 ~1 ~94 ~23 ~46 ~94 log 1
fill ~24 ~1 ~8 ~28 ~1 ~8 planks 5
fill ~24 ~1 ~33 ~35 ~1 ~33 log 5
fill ~24 ~1 ~34 ~24 ~1 ~39 log 9
fill ~24 ~1 ~49 ~28 ~1 ~49 planks 1
fill ~24 ~1 ~50 ~28 ~1 ~50 planks 1
fill ~24 ~1 ~51 ~28 ~1 ~51 planks 1
fill ~24 ~1 ~52 ~28 ~1 ~52 planks 1
fill ~24 ~1 ~53 ~28 ~1 ~53 planks 1
fill ~24 ~1 ~54 ~28 ~1 ~54 planks 1
fill ~24 ~1 ~55 ~28 ~1 ~55 planks 1
fill ~24 ~1 ~56 ~28 ~1 ~56 planks 1
fill ~24 ~1 ~57 ~28 ~1 ~57 planks 1
fill ~24 ~1 ~58 ~28 ~1 ~58 planks 1
fill ~24 ~1 ~59 ~30 ~1 ~59 log 1
fill ~24 ~1 ~60 ~30 ~1 ~60 log 1
fill ~24 ~1 ~61 ~28 ~1 ~61 planks 5
fill ~24 ~1 ~62 ~28 ~1 ~62 planks 5
fill ~24 ~1 ~63 ~25 ~1 ~63 planks 5
fill ~24 ~1 ~64 ~28 ~1 ~64 planks 5
fill ~24 ~1 ~65 ~28 ~1 ~65 planks 5
fill ~24 ~1 ~88 ~30 ~1 ~88 planks 1
fill ~24 ~1 ~89 ~30 ~1 ~89 planks 1
fill ~24 ~1 ~90 ~30 ~1 ~90 planks 1
fill ~24 ~1 ~91 ~30 ~1 ~91 planks 1
fill ~24 ~1 ~92 ~30 ~1 ~92 planks 1
fill ~24 ~1 ~94 ~28 ~1 ~94 planks 3
fill ~25 ~1 ~25 ~28 ~1 ~25 log 1
fill ~25 ~1 ~26 ~36 ~1 ~26 log 1
fill ~25 ~1 ~27 ~26 ~1 ~27 log 1
fill ~25 ~1 ~30 ~26 ~1 ~30 log 1
fill ~25 ~1 ~31 ~26 ~1 ~31 log 1
fill ~25 ~1 ~34 ~26 ~1 ~34 wool
fill ~25 ~1 ~35 ~26 ~1 ~35 wool 11
fill ~25 ~1 ~36 ~26 ~1 ~36 wool 11
fill ~25 ~1 ~37 ~32 ~1 ~37 log 5
fill ~25 ~1 ~38 ~26 ~1 ~38 wool
fill ~25 ~1 ~39 ~26 ~1 ~39 wool 11
fill ~25 ~1 ~68 ~26 ~1 ~68 log 1
fill ~25 ~1 ~69 ~26 ~1 ~69 log 1
fill ~25 ~1 ~70 ~26 ~1 ~70 log 1
fill ~25 ~1 ~71 ~43 ~1 ~71 log 1
fill ~25 ~1 ~72 ~25 ~2 ~72 log 1
fill ~25 ~1 ~73 ~25 ~2 ~73 log 1
fill ~25 ~1 ~74 ~25 ~2 ~74 log 1
fill ~25 ~1 ~75 ~25 ~2 ~75 log 1
fill ~25 ~1 ~78 ~25 ~1 ~87 log 1
setblock ~26 ~1 ~23 glowstone
setblock ~26 ~1 ~63 glowstone
fill ~26 ~1 ~72 ~37 ~1 ~72 log 5
fill ~26 ~1 ~73 ~26 ~1 ~85 log 9
fill ~26 ~1 ~86 ~34 ~1 ~86 log 5
setblock ~27 ~1 ~23 planks 5
fill ~27 ~1 ~27 ~33 ~1 ~27 planks 5
fill ~27 ~1 ~28 ~33 ~1 ~28 planks 5
fill ~27 ~1 ~29 ~33 ~1 ~29 planks 5
fill ~27 ~1 ~30 ~33 ~1 ~30 planks 5
fill ~27 ~1 ~31 ~33 ~1 ~31 planks 5
fill ~27 ~1 ~34 ~27 ~1 ~36 log 9
fill ~27 ~1 ~38 ~27 ~1 ~39 log 9
fill ~27 ~1 ~63 ~28 ~1 ~63 planks 5
fill ~27 ~1 ~68 ~29 ~1 ~68 planks 1
fill ~27 ~1 ~69 ~29 ~1 ~69 planks 1
fill ~27 ~1 ~70 ~29 ~1 ~70 planks 1
fill ~27 ~1 ~73 ~28 ~1 ~73 wool
fill ~27 ~1 ~74 ~28 ~1 ~74 wool 11
fill ~27 ~1 ~75 ~28 ~1 ~75 wool 11
fill ~27 ~1 ~76 ~28 ~1 ~76 log 5
fill ~27 ~1 ~77 ~28 ~1 ~77 wool
fill ~27 ~1 ~78 ~28 ~1 ~78 wool 11
fill ~27 ~1 ~79 ~28 ~1 ~79 wool 11
fill ~27 ~1 ~80 ~28 ~1 ~80 wool 11
fill ~27 ~1 ~81 ~28 ~1 ~81 log 5
fill ~27 ~1 ~82 ~28 ~1 ~82 wool 11
fill ~27 ~1 ~83 ~28 ~1 ~83 wool 11
fill ~27 ~1 ~84 ~28 ~1 ~84 wool 11
fill ~27 ~1 ~85 ~28 ~1 ~85 wool
fill ~28 ~1 ~14 ~42 ~1 ~14 log 1
fill ~28 ~1 ~15 ~28 ~2 ~15 log 1
fill ~28 ~1 ~16 ~28 ~2 ~16 log 1
fill ~28 ~1 ~17 ~28 ~2 ~17 log 1
fill ~28 ~1 ~18 ~28 ~2 ~18 log 1
fill ~28 ~1 ~19 ~28 ~2 ~19 log 1
fill ~28 ~1 ~22 ~28 ~1 ~26 log 1
fill ~28 ~1 ~34 ~29 ~1 ~34 wool
fill ~28 ~1 ~35 ~29 ~1 ~35 wool 11
fill ~28 ~1 ~36 ~29 ~1 ~36 wool 11
fill ~28 ~1 ~38 ~29 ~1 ~38 wool
fill ~28 ~1 ~39 ~29 ~1 ~39 wool 11
fill ~29 ~1 ~8 ~29 ~54 ~8 log 1
fill ~29 ~1 ~15 ~29 ~1 ~24 log 9
fill ~29 ~1 ~25 ~35 ~1 ~25 log 5
fill ~29 ~1 ~41 ~41 ~1 ~41 log 1
fill ~29 ~1 ~42 ~30 ~1 ~42 log 1
fill ~29 ~1 ~43 ~30 ~1 ~43 log 1
fill ~29 ~1 ~44 ~30 ~1 ~44 log 1
fill ~29 ~1 ~45 ~30 ~1 ~45 log 1
fill ~29 ~1 ~46 ~37 ~1 ~46 log 1
fill ~29 ~1 ~49 ~30 ~1 ~49 log 1
fill ~29 ~1 ~50 ~30 ~1 ~50 log 1
fill ~29 ~1 ~51 ~30 ~1 ~51 log 1
fill ~29 ~1 ~52 ~30 ~1 ~52 log 1
fill ~29 ~1 ~53 ~30 ~1 ~53 log 1
fill ~29 ~1 ~54 ~37 ~1 ~54 log 1
fill ~29 ~1 ~55 ~37 ~1 ~55 log 1
fill ~29 ~1 ~56 ~30 ~1 ~56 log 1
fill ~29 ~1 ~57 ~30 ~1 ~57 log 1
fill ~29 ~1 ~58 ~30 ~1 ~58 log 1
fill ~29 ~1 ~61 ~30 ~1 ~61 log 1
fill ~29 ~1 ~62 ~30 ~1 ~62 log 1
fill ~29 ~1 ~63 ~41 ~1 ~63 log 1
fill ~29 ~1 ~64 ~41 ~1 ~64 log 1
fill ~29 ~1 ~65 ~30 ~1 ~65 log 1
fill ~29 ~1 ~73 ~29 ~1 ~85 log 9
fill ~29 ~1 ~94 ~29 ~80 ~94 log 1
fill ~30 ~1 ~8 ~34 ~1 ~8 planks 1
fill ~30 ~1 ~15 ~34 ~1 ~15 log 5
fill ~30 ~1 ~16 ~31 ~1 ~16 wool 11
fill ~30 ~1 ~17 ~31 ~1 ~17 wool 11
fill ~30 ~1 ~18 ~31 ~1 ~18 wool 11
fill ~30 ~1 ~19 ~31 ~1 ~19 wool
fill ~30 ~1 ~20 ~31 ~1 ~20 log 5
fill ~30 ~1 ~21 ~31 ~1 ~21 wool 11
fill ~30 ~1 ~22 ~31 ~1 ~22 wool 11
fill ~30 ~1 ~23 ~31 ~1 ~23 wool 11
fill ~30 ~1 ~24 ~31 ~1 ~24 wool
fill ~30 ~1 ~34 ~30 ~1 ~36 log 9
fill ~30 ~1 ~38 ~30 ~1 ~39 log 9
fill ~30 ~1 ~40 ~36 ~1 ~40 log 5
fill ~30 ~1 ~68 ~30 ~4 ~68 log 1
fill ~30 ~1 ~69 ~30 ~1 ~71 log 1
fill ~30 ~1 ~73 ~31 ~1 ~73 wool
fill ~30 ~1 ~74 ~31 ~1 ~74 wool 11
fill ~30 ~1 ~75 ~31 ~1 ~75 wool 11
fill ~30 ~1 ~76 ~31 ~1 ~76 log 5
fill ~30 ~1 ~77 ~31 ~1 ~77 wool
fill ~30 ~1 ~78 ~31 ~1 ~78 wool 11
fill ~30 ~1 ~79 ~31 ~1 ~79 wool 11
fill ~30 ~1 ~80 ~31 ~1 ~80 wool 11
fill ~30 ~1 ~81 ~31 ~1 ~81 log 5
fill ~30 ~1 ~82 ~31 ~1 ~82 wool 11
fill ~30 ~1 ~83 ~31 ~1 ~83 wool 11
fill ~30 ~1 ~84 ~31 ~1 ~84 wool 11
fill ~30 ~1 ~85 ~31 ~1 ~85 wool
fill ~30 ~1 ~94 ~34 ~1 ~94 planks 1
fill ~31 ~1 ~10 ~32 ~1 ~10 log 1
fill ~31 ~1 ~11 ~32 ~1 ~11 log 1
fill ~31 ~1 ~12 ~32 ~1 ~12 log 1
fill ~31 ~1 ~13 ~32 ~1 ~13 log 1
fill ~31 ~1 ~34 ~32 ~1 ~34 wool
fill ~31 ~1 ~35 ~32 ~1 ~35 wool 11
fill ~31 ~1 ~36 ~32 ~1 ~36 wool 11
fill ~31 ~1 ~38 ~32 ~1 ~38 wool
fill ~31 ~1 ~39 ~32 ~1 ~39 wool 11
fill ~31 ~1 ~42 ~40 ~1 ~42 planks 5
fill ~31 ~1 ~43 ~40 ~1 ~43 planks 5
fill ~31 ~1 ~44 ~40 ~1 ~44 planks 5
fill ~31 ~1 ~45 ~40 ~1 ~45 planks 5
fill ~31 ~1 ~48 ~35 ~1 ~48 planks 2
fill ~31 ~1 ~49 ~35 ~1 ~49 planks 2
fill ~31 ~1 ~50 ~35 ~1 ~50 planks 2
fill ~31 ~1 ~51 ~35 ~1 ~51 planks 2
fill ~31 ~1 ~52 ~35 ~1 ~52 planks 2
fill ~31 ~1 ~53 ~35 ~1 ~53 planks 2
fill ~31 ~1 ~56 ~40 ~1 ~56 planks 1
fill ~31 ~1 ~57 ~40 ~1 ~57 planks 1
fill ~31 ~1 ~58 ~40 ~1 ~58 planks 1
fill ~31 ~1 ~59 ~40 ~1 ~59 planks 1
fill ~31 ~1 ~60 ~40 ~1 ~60 planks 1
fill ~31 ~1 ~61 ~40 ~1 ~61 planks 1
fill ~31 ~1 ~62 ~40 ~1 ~62 planks 1
fill ~31 ~1 ~65 ~41 ~1 ~65 planks 3
fill ~31 ~1 ~66 ~41 ~1 ~66 planks 3
fill ~31 ~1 ~67 ~41 ~1 ~67 planks 3
fill ~31 ~1 ~68 ~41 ~1 ~68 planks 3
fill ~31 ~1 ~69 ~41 ~1 ~69 planks 3
fill ~31 ~1 ~70 ~37 ~1 ~70 planks 3
fill ~31 ~1 ~88 ~32 ~1 ~88 log 1
fill ~31 ~1 ~89 ~32 ~1 ~89 log 1
fill ~31 ~1 ~90 ~32 ~1 ~90 log 1
fill ~31 ~1 ~91 ~32 ~1 ~91 log 1
fill ~31 ~1 ~92 ~32 ~1 ~92 log 1
fill ~32 ~1 ~16 ~32 ~1 ~24 log 9
fill ~32 ~1 ~73 ~32 ~1 ~85 log 9
fill ~33 ~1 ~10 ~40 ~1 ~10 planks 5
fill ~33 ~1 ~11 ~40 ~1 ~11 planks 5
fill ~33 ~1 ~12 ~40 ~1 ~12 planks 5
fill ~33 ~1 ~13 ~40 ~1 ~13 planks 5
fill ~33 ~1 ~16 ~34 ~1 ~16 wool 11
fill ~33 ~1 ~17 ~34 ~1 ~17 wool 11
fill ~33 ~1 ~18 ~34 ~1 ~18 wool 11
fill ~33 ~1 ~19 ~34 ~1 ~19 wool
fill ~33 ~1 ~20 ~34 ~1 ~20 log 5
fill ~33 ~1 ~21 ~34 ~1 ~21 wool 11
fill ~33 ~1 ~22 ~34 ~1 ~22 wool 11
fill ~33 ~1 ~23 ~34 ~1 ~23 wool 11
fill ~33 ~1 ~24 ~34 ~1 ~24 wool
fill ~33 ~1 ~34 ~33 ~1 ~39 log 9
fill ~33 ~1 ~73 ~34 ~1 ~73 wool
fill ~33 ~1 ~74 ~34 ~1 ~74 wool 11
fill ~33 ~1 ~75 ~34 ~1 ~75 wool 11
fill ~33 ~1 ~76 ~34 ~1 ~76 log 5
fill ~33 ~1 ~77 ~34 ~1 ~77 wool
fill ~33 ~1 ~78 ~34 ~1 ~78 wool 11
fill ~33 ~1 ~79 ~34 ~1 ~79 wool 11
fill ~33 ~1 ~80 ~34 ~1 ~80 wool 11
fill ~33 ~1 ~81 ~34 ~1 ~81 log 5
fill ~33 ~1 ~82 ~34 ~1 ~82 wool 11
fill ~33 ~1 ~83 ~34 ~1 ~83 wool 11
fill ~33 ~1 ~84 ~34 ~1 ~84 wool 11
fill ~33 ~1 ~85 ~34 ~1 ~85 wool
fill ~33 ~1 ~88 ~35 ~1 ~88 planks 5
fill ~33 ~1 ~89 ~40 ~1 ~89 planks 5
fill ~33 ~1 ~90 ~40 ~1 ~90 planks 5
fill ~33 ~1 ~91 ~40 ~1 ~91 planks 5
fill ~33 ~1 ~92 ~40 ~1 ~92 planks 5
fill ~34 ~1 ~27 ~35 ~1 ~27 log 1
fill ~34 ~1 ~28 ~35 ~1 ~28 log 1
fill ~34 ~1 ~29 ~35 ~1 ~29 log 1
fill ~34 ~1 ~30 ~35 ~1 ~30 log 1
fill ~34 ~1 ~31 ~35 ~1 ~31 log 1
fill ~34 ~1 ~34 ~35 ~1 ~34 wool
fill ~34 ~1 ~35 ~35 ~1 ~35 wool 11
fill ~34 ~1 ~36 ~35 ~1 ~36 wool 11
fill ~34 ~1 ~37 ~35 ~1 ~37 log 5
fill ~34 ~1 ~38 ~35 ~1 ~38 wool
fill ~34 ~1 ~39 ~35 ~1 ~39 wool 11
fill ~35 ~1 ~8 ~35 ~59 ~8 log 1
fill ~35 ~1 ~15 ~35 ~1 ~24 log 9
fill ~35 ~1 ~73 ~35 ~1 ~86 log 9
fill ~35 ~1 ~94 ~35 ~46 ~94 log 1
fill ~36 ~1 ~8 ~40 ~1 ~8 planks 5
fill ~36 ~1 ~15 ~41 ~1 ~15 log 1
fill ~36 ~1 ~16 ~36 ~2 ~16 log 1
fill ~36 ~1 ~17 ~36 ~2 ~17 log 1
fill ~36 ~1 ~18 ~36 ~2 ~18 log 1
fill ~36 ~1 ~19 ~36 ~2 ~19 log 1
fill ~36 ~1 ~20 ~36 ~2 ~20 log 1
fill ~36 ~1 ~21 ~36 ~2 ~21 log 1
fill ~36 ~1 ~22 ~41 ~1 ~22 log 1
fill ~36 ~1 ~23 ~41 ~1 ~23 log 1
fill ~36 ~1 ~24 ~36 ~1 ~26 log 1
fill ~36 ~1 ~27 ~40 ~1 ~27 planks 2
fill ~36 ~1 ~28 ~40 ~1 ~28 planks 2
fill ~36 ~1 ~29 ~40 ~1 ~29 planks 2
fill ~36 ~1 ~30 ~40 ~1 ~30 planks 2
fill ~36 ~1 ~31 ~40 ~1 ~31 planks 2
fill ~36 ~1 ~33 ~36 ~1 ~39 log 9
fill ~36 ~1 ~48 ~37 ~1 ~48 log 1
fill ~36 ~1 ~49 ~37 ~1 ~49 log 1
fill ~36 ~1 ~50 ~42 ~1 ~50 log 1
fill ~36 ~1 ~51 ~41 ~1 ~51 log 1
fill ~36 ~1 ~52 ~37 ~1 ~52 log 1
fill ~36 ~1 ~53 ~37 ~1 ~53 log 1
fill ~36 ~1 ~73 ~37 ~1 ~73 wool
fill ~36 ~1 ~74 ~37 ~1 ~74 wool 11
fill ~36 ~1 ~75 ~37 ~1 ~75 wool 11
fill ~36 ~1 ~76 ~37 ~1 ~76 log 5
fill ~36 ~1 ~77 ~37 ~1 ~77 wool
fill ~36 ~1 ~78 ~37 ~1 ~78 wool 11
fill ~36 ~1 ~79 ~37 ~1 ~79 wool 11
fill ~36 ~1 ~80 ~37 ~1 ~80 log 5
fill ~36 ~1 ~81 ~44 ~1 ~81 log 1
fill ~36 ~1 ~82 ~36 ~2 ~82 log 1
fill ~36 ~1 ~83 ~36 ~2 ~83 log 1
fill ~36 ~1 ~84 ~36 ~2 ~84 log 1
fill ~36 ~1 ~85 ~36 ~2 ~85 log 1
fill ~36 ~1 ~86 ~36 ~2 ~86 log 1
fill ~36 ~1 ~88 ~44 ~1 ~88 log 1
fill ~36 ~1 ~94 ~40 ~1 ~94 planks 5
fill ~37 ~1 ~16 ~40 ~1 ~16 planks 1
fill ~37 ~1 ~17 ~40 ~1 ~17 planks 1
fill ~37 ~1 ~18 ~40 ~1 ~18 planks 1
fill ~37 ~1 ~19 ~40 ~1 ~19 planks 1
fill ~37 ~1 ~20 ~40 ~1 ~20 planks 1
fill ~37 ~1 ~21 ~40 ~1 ~21 planks 1
fill ~37 ~1 ~24 ~40 ~1 ~24 planks 2
fill ~37 ~1 ~25 ~40 ~1 ~25 planks 2
fill ~37 ~1 ~26 ~40 ~1 ~26 planks 2
fill ~37 ~1 ~33 ~41 ~1 ~33 log 1
fill ~37 ~1 ~34 ~41 ~1 ~34 log 1
fill ~37 ~1 ~35 ~37 ~2 ~35 log 1
fill ~37 ~1 ~36 ~37 ~2 ~36 log 1
fill ~37 ~1 ~37 ~37 ~2 ~37 log 1
fill ~37 ~1 ~38 ~37 ~2 ~38 log 1
fill ~37 ~1 ~39 ~37 ~2 ~39 log 1
fill ~37 ~1 ~40 ~41 ~1 ~40 log 1
fill ~37 ~1 ~82 ~43 ~1 ~82 planks 3
fill ~37 ~1 ~83 ~43 ~1 ~83 planks 3
fill ~37 ~1 ~84 ~43 ~1 ~84 planks 3
fill ~37 ~1 ~85 ~43 ~1 ~85 planks 3
fill ~37 ~1 ~86 ~43 ~1 ~86 planks 3
fill ~37 ~1 ~87 ~43 ~1 ~87 planks 3
fill ~38 ~1 ~32 ~40 ~1 ~32 planks 2
fill ~38 ~1 ~35 ~42 ~1 ~35 planks 1
fill ~38 ~1 ~36 ~42 ~1 ~36 planks 1
fill ~38 ~1 ~37 ~42 ~1 ~37 planks 1
fill ~38 ~1 ~38 ~41 ~1 ~38 planks 1
fill ~38 ~1 ~39 ~41 ~1 ~39 planks 1
fill ~38 ~1 ~46 ~40 ~1 ~46 planks 5
fill ~38 ~1 ~47 ~40 ~1 ~47 planks 5
fill ~38 ~1 ~48 ~38 ~1 ~49 planks 5
fill ~38 ~1 ~52 ~40 ~1 ~52 planks 1
fill ~38 ~1 ~53 ~40 ~1 ~53 planks 1
fill ~38 ~1 ~54 ~40 ~1 ~54 planks 1
fill ~38 ~1 ~55 ~40 ~1 ~55 planks 1
fill ~38 ~1 ~70 ~43 ~1 ~70 log 1
fill ~38 ~1 ~72 ~38 ~1 ~80 log 9
setblock ~39 ~1 ~48 glowstone
fill ~39 ~1 ~49 ~40 ~1 ~49 planks 5
fill ~39 ~1 ~72 ~39 ~1 ~81 log 1
setblock ~40 ~1 ~48 planks 5
fill ~40 ~1 ~72 ~42 ~1 ~72 planks 5
fill ~40 ~1 ~73 ~48 ~1 ~73 planks 5
fill ~40 ~1 ~74 ~48 ~1 ~74 planks 5
fill ~40 ~1 ~75 ~48 ~1 ~75 planks 5
fill ~40 ~1 ~76 ~48 ~1 ~76 planks 5
fill ~40 ~1 ~77 ~43 ~1 ~77 planks 5
fill ~40 ~1 ~78 ~43 ~1 ~78 planks 5
fill ~40 ~1 ~79 ~43 ~1 ~79 planks 5
fill ~40 ~1 ~80 ~44 ~1 ~80 log 1
fill ~41 ~1 ~8 ~42 ~1 ~8 log 1
fill ~41 ~1 ~10 ~41 ~3 ~10 log 1
fill ~41 ~1 ~11 ~41 ~3 ~11 log 1
fill ~41 ~1 ~12 ~41 ~3 ~12 log 1
fill ~41 ~1 ~13 ~41 ~3 ~13 log 1
fill ~41 ~1 ~16 ~41 ~2 ~16 log 1
fill ~41 ~1 ~17 ~41 ~2 ~17 log 1
fill ~41 ~1 ~18 ~41 ~2 ~18 log 1
fill ~41 ~1 ~19 ~41 ~2 ~19 log 1
fill ~41 ~1 ~20 ~42 ~1 ~20 log 1
fill ~41 ~1 ~21 ~41 ~2 ~21 log 1
fill ~41 ~1 ~24 ~41 ~3 ~24 log 1
fill ~41 ~1 ~25 ~41 ~3 ~25 log 1
fill ~41 ~1 ~26 ~42 ~1 ~26 log 1
fill ~41 ~1 ~27 ~41 ~3 ~27 log 1
fill ~41 ~1 ~28 ~41 ~3 ~28 log 1
fill ~41 ~1 ~29 ~41 ~3 ~29 log 1
fill ~41 ~1 ~30 ~41 ~3 ~30 log 1
fill ~41 ~1 ~31 ~41 ~3 ~31 log 1
fill ~41 ~1 ~32 ~42 ~1 ~32 log 1
fill ~41 ~1 ~42 ~41 ~1 ~64 log 1
fill ~41 ~1 ~89 ~41 ~1 ~94 log 1
fill ~42 ~1 ~9 ~42 ~5 ~9 planks 1
fill ~42 ~1 ~10 ~42 ~5 ~10 planks 1
fill ~42 ~1 ~11 ~42 ~5 ~11 planks 1
fill ~42 ~1 ~12 ~42 ~5 ~12 planks 1
fill ~42 ~1 ~13 ~42 ~5 ~13 planks 1
fill ~42 ~1 ~15 ~42 ~5 ~15 planks 1
fill ~42 ~1 ~16 ~42 ~5 ~16 planks 1
fill ~42 ~1 ~17 ~42 ~5 ~17 planks 1
fill ~42 ~1 ~18 ~42 ~5 ~18 planks 1
fill ~42 ~1 ~19 ~42 ~4 ~19 planks 1
fill ~42 ~1 ~21 ~42 ~2 ~21 bookshelf
fill ~42 ~1 ~22 ~42 ~2 ~22 bookshelf
fill ~42 ~1 ~23 ~42 ~2 ~23 bookshelf
fill ~42 ~1 ~24 ~42 ~2 ~24 bookshelf
fill ~42 ~1 ~25 ~42 ~2 ~25 bookshelf
fill ~42 ~1 ~27 ~42 ~5 ~27 planks 5
fill ~42 ~1 ~28 ~42 ~5 ~28 planks 5
fill ~42 ~1 ~29 ~42 ~5 ~29 planks 5
fill ~42 ~1 ~30 ~42 ~5 ~30 planks 5
fill ~42 ~1 ~31 ~42 ~5 ~31 planks 5
fill ~42 ~1 ~33 ~42 ~5 ~33 planks 1
fill ~42 ~1 ~34 ~42 ~5 ~34 planks 1
fill ~42 ~1 ~38 ~42 ~46 ~38 log 1
fill ~42 ~1 ~39 ~42 ~5 ~39 hay_block
fill ~42 ~1 ~40 ~42 ~5 ~40 hay_block
fill ~42 ~1 ~41 ~42 ~5 ~41 hay_block
fill ~42 ~1 ~42 ~42 ~5 ~42 hay_block
fill ~42 ~1 ~43 ~42 ~5 ~43 hay_block
fill ~42 ~1 ~44 ~42 ~33 ~44 log 1
fill ~42 ~1 ~45 ~42 ~5 ~45 planks 1
fill ~42 ~1 ~46 ~42 ~5 ~46 planks 1
fill ~42 ~1 ~47 ~42 ~5 ~47 planks 1
fill ~42 ~1 ~48 ~42 ~5 ~48 planks 1
fill ~42 ~1 ~49 ~42 ~5 ~49 planks 1
fill ~42 ~1 ~51 ~42 ~2 ~51 bookshelf
fill ~42 ~1 ~52 ~42 ~2 ~52 bookshelf
fill ~42 ~1 ~53 ~42 ~2 ~53 bookshelf
fill ~42 ~1 ~54 ~42 ~2 ~54 bookshelf
fill ~42 ~1 ~55 ~42 ~2 ~55 bookshelf
fill ~42 ~1 ~56 ~42 ~12 ~56 log 1
fill ~42 ~1 ~57 ~42 ~5 ~57 planks 1
fill ~42 ~1 ~58 ~42 ~5 ~58 planks 1
fill ~42 ~1 ~59 ~42 ~5 ~59 planks 1
fill ~42 ~1 ~60 ~42 ~5 ~60 planks 1
fill ~42 ~1 ~61 ~42 ~5 ~61 planks 1
fill ~42 ~1 ~62 ~42 ~11 ~62 log 1
fill ~42 ~1 ~63 ~42 ~5 ~63 planks 5
fill ~42 ~1 ~64 ~42 ~5 ~64 planks 5
fill ~42 ~1 ~65 ~42 ~5 ~65 planks 5
fill ~42 ~1 ~66 ~42 ~5 ~66 planks 5
fill ~42 ~1 ~67 ~42 ~5 ~67 planks 5
fill ~42 ~1 ~68 ~42 ~63 ~68 log 1
fill ~42 ~1 ~69 ~43 ~1 ~69 log 1
fill ~42 ~1 ~89 ~43 ~1 ~89 log 5
fill ~42 ~1 ~90 ~56 ~1 ~90 log 1
fill ~42 ~1 ~91 ~42 ~1 ~93 log 1
fill ~42 ~1 ~94 ~46 ~1 ~94 planks 5
fill ~43 ~1 ~68 ~47 ~1 ~68 bookshelf
fill ~43 ~1 ~72 ~49 ~1 ~72 log 1
fill ~43 ~1 ~91 ~54 ~1 ~91 planks 1
fill ~43 ~1 ~92 ~54 ~1 ~92 planks 1
fill ~44 ~1 ~69 ~48 ~1 ~69 planks 2
fill ~44 ~1 ~70 ~48 ~1 ~70 planks 2
fill ~44 ~1 ~71 ~48 ~1 ~71 planks 2
fill ~44 ~1 ~77 ~49 ~1 ~77 log 1
fill ~44 ~1 ~78 ~44 ~1 ~90 log 1
fill ~45 ~1 ~78 ~48 ~1 ~78 planks 5
fill ~45 ~1 ~79 ~48 ~1 ~79 planks 5
fill ~45 ~1 ~80 ~48 ~1 ~80 planks 5
fill ~45 ~1 ~81 ~48 ~1 ~81 planks 5
fill ~45 ~1 ~82 ~54 ~1 ~82 planks 5
fill ~45 ~1 ~83 ~54 ~1 ~83 planks 5
fill ~45 ~1 ~84 ~54 ~1 ~84 planks 5
fill ~45 ~1 ~85 ~54 ~1 ~85 planks 5
fill ~45 ~1 ~86 ~54 ~1 ~86 planks 5
fill ~45 ~1 ~87 ~54 ~1 ~87 planks 5
fill ~45 ~1 ~88 ~54 ~1 ~88 planks 5
fill ~45 ~1 ~89 ~56 ~1 ~89 log 1
fill ~47 ~1 ~94 ~47 ~46 ~94 log 1
fill ~48 ~1 ~68 ~48 ~80 ~68 log 1
fill ~48 ~1 ~94 ~52 ~1 ~94 planks 3
fill ~49 ~1 ~68 ~53 ~1 ~68 planks 3
fill ~49 ~1 ~69 ~49 ~2 ~69 log 1
fill ~49 ~1 ~70 ~49 ~2 ~70 log 1
fill ~49 ~1 ~71 ~49 ~2 ~71 log 1
fill ~49 ~1 ~73 ~49 ~1 ~81 log 1
fill ~50 ~1 ~69 ~57 ~1 ~69 log 5
fill ~50 ~1 ~70 ~50 ~1 ~80 log 9
fill ~50 ~1 ~81 ~70 ~1 ~81 log 1
fill ~51 ~1 ~70 ~52 ~1 ~70 wool
fill ~51 ~1 ~71 ~52 ~1 ~71 wool
fill ~51 ~1 ~72 ~52 ~1 ~72 wool 11
fill ~51 ~1 ~73 ~52 ~1 ~73 wool 11
fill ~51 ~1 ~74 ~52 ~1 ~74 wool 11
fill ~51 ~1 ~75 ~52 ~1 ~75 wool 11
fill ~51 ~1 ~76 ~63 ~1 ~76 log 5
fill ~51 ~1 ~77 ~52 ~1 ~77 wool 11
fill ~51 ~1 ~78 ~52 ~1 ~78 wool 11
fill ~51 ~1 ~79 ~52 ~1 ~79 wool
fill ~51 ~1 ~80 ~63 ~1 ~80 log 5
setblock ~53 ~1 ~75 log 9
fill ~53 ~1 ~77 ~53 ~1 ~79 log 9
fill ~53 ~1 ~94 ~53 ~80 ~94 log 1
fill ~54 ~1 ~68 ~54 ~5 ~68 log 1
fill ~54 ~1 ~70 ~56 ~1 ~70 wool
fill ~54 ~1 ~71 ~56 ~1 ~71 wool
fill ~54 ~1 ~72 ~56 ~1 ~72 wool 11
fill ~54 ~1 ~73 ~56 ~1 ~73 wool 11
fill ~54 ~1 ~74 ~56 ~1 ~74 wool 11
fill ~54 ~1 ~75 ~56 ~1 ~75 wool 11
fill ~54 ~1 ~77 ~56 ~1 ~77 wool 11
fill ~54 ~1 ~78 ~56 ~1 ~78 wool 11
fill ~54 ~1 ~79 ~56 ~1 ~79 wool
fill ~54 ~1 ~94 ~58 ~1 ~94 planks 1
fill ~55 ~1 ~68 ~59 ~1 ~68 hay_block
fill ~55 ~1 ~82 ~56 ~1 ~82 log 1
fill ~55 ~1 ~83 ~56 ~1 ~83 log 1
fill ~55 ~1 ~84 ~56 ~1 ~84 log 1
fill ~55 ~1 ~85 ~56 ~1 ~85 log 1
fill ~55 ~1 ~86 ~56 ~1 ~86 log 1
fill ~55 ~1 ~87 ~56 ~1 ~87 log 1
fill ~55 ~1 ~88 ~56 ~1 ~88 log 1
fill ~55 ~1 ~91 ~56 ~1 ~91 log 1
fill ~55 ~1 ~92 ~56 ~1 ~92 log 1
fill ~57 ~1 ~70 ~57 ~1 ~75 log 9
fill ~57 ~1 ~77 ~57 ~1 ~79 log 9
fill ~57 ~1 ~82 ~62 ~1 ~82 planks 3
fill ~57 ~1 ~83 ~62 ~1 ~83 planks 3
fill ~57 ~1 ~84 ~62 ~1 ~84 planks 3
fill ~57 ~1 ~85 ~62 ~1 ~85 planks 3
fill ~57 ~1 ~86 ~62 ~1 ~86 planks 3
fill ~57 ~1 ~87 ~62 ~1 ~87 planks 3
fill ~57 ~1 ~88 ~60 ~1 ~88 planks 3
fill ~57 ~1 ~89 ~60 ~1 ~89 planks 3
fill ~57 ~1 ~90 ~60 ~1 ~90 planks 3
fill ~57 ~1 ~91 ~60 ~1 ~91 planks 3
fill ~57 ~1 ~92 ~60 ~1 ~92 planks 3
fill ~58 ~1 ~69 ~58 ~2 ~69 log 1
fill ~58 ~1 ~70 ~58 ~2 ~70 log 1
fill ~58 ~1 ~71 ~58 ~2 ~71 log 1
fill ~58 ~1 ~72 ~58 ~2 ~72 log 1
fill ~58 ~1 ~73 ~58 ~2 ~73 log 1
fill ~58 ~1 ~74 ~58 ~2 ~74 log 1
fill ~58 ~1 ~75 ~64 ~1 ~75 log 1
fill ~58 ~1 ~77 ~59 ~1 ~77 wool 11
fill ~58 ~1 ~78 ~59 ~1 ~78 wool 11
fill ~58 ~1 ~79 ~59 ~1 ~79 wool
fill ~59 ~1 ~69 ~68 ~1 ~69 planks 1
fill ~59 ~1 ~70 ~68 ~1 ~70 planks 1
fill ~59 ~1 ~71 ~68 ~1 ~71 planks 1
fill ~59 ~1 ~72 ~62 ~1 ~72 planks 1
fill ~59 ~1 ~73 ~62 ~1 ~73 planks 1
fill ~59 ~1 ~74 ~62 ~1 ~74 planks 1
fill ~59 ~1 ~94 ~59 ~46 ~94 log 1
fill ~60 ~1 ~68 ~60 ~46 ~68 log 1
fill ~60 ~1 ~77 ~60 ~1 ~79 log 9
fill ~60 ~1 ~94 ~64 ~1 ~94 planks 5
fill ~61 ~1 ~68 ~65 ~1 ~68 planks 5
fill ~61 ~1 ~77 ~62 ~1 ~77 wool 11
fill ~61 ~1 ~78 ~62 ~1 ~78 wool 11
fill ~61 ~1 ~79 ~62 ~1 ~79 wool
fill ~61 ~1 ~88 ~64 ~1 ~88 log 1
fill ~61 ~1 ~89 ~64 ~1 ~89 log 1
fill ~61 ~1 ~90 ~62 ~1 ~90 log 1
fill ~61 ~1 ~91 ~62 ~1 ~91 log 1
fill ~61 ~1 ~92 ~62 ~1 ~92 log 1
fill ~63 ~1 ~72 ~69 ~1 ~72 log 1
fill ~63 ~1 ~73 ~69 ~1 ~73 log 1
fill ~63 ~1 ~74 ~64 ~1 ~74 log 1
fill ~63 ~1 ~77 ~63 ~1 ~79 log 9
fill ~63 ~1 ~82 ~64 ~1 ~82 log 1
fill ~63 ~1 ~83 ~64 ~1 ~83 log 1
fill ~63 ~1 ~84 ~64 ~1 ~84 log 1
fill ~63 ~1 ~85 ~64 ~1 ~85 log 1
fill ~63 ~1 ~86 ~64 ~1 ~86 log 1
fill ~63 ~1 ~87 ~64 ~1 ~87 log 1
fill ~63 ~1 ~90 ~69 ~1 ~90 planks 2
fill ~63 ~1 ~91 ~69 ~1 ~91 planks 2
fill ~63 ~1 ~92 ~69 ~1 ~92 planks 2
fill ~63 ~1 ~93 ~69 ~1 ~93 planks 2
fill ~64 ~1 ~76 ~64 ~1 ~89 log 1
fill ~65 ~1 ~74 ~68 ~1 ~74 planks 5
fill ~65 ~1 ~75 ~68 ~1 ~75 planks 5
fill ~65 ~1 ~76 ~68 ~1 ~76 planks 5
fill ~65 ~1 ~77 ~68 ~1 ~77 planks 5
fill ~65 ~1 ~78 ~68 ~1 ~78 planks 5
fill ~65 ~1 ~79 ~68 ~1 ~79 planks 5
fill ~65 ~1 ~80 ~70 ~1 ~80 log 1
fill ~65 ~1 ~82 ~68 ~1 ~82 planks 2
fill ~65 ~1 ~83 ~68 ~1 ~83 planks 2
fill ~65 ~1 ~84 ~68 ~1 ~84 planks 2
fill ~65 ~1 ~85 ~68 ~1 ~85 planks 2
fill ~65 ~1 ~86 ~69 ~1 ~86 planks 2
fill ~65 ~1 ~87 ~69 ~1 ~87 planks 2
fill ~65 ~1 ~88 ~69 ~1 ~88 planks 2
fill ~65 ~1 ~89 ~69 ~1 ~89 planks 2
fill ~65 ~1 ~94 ~65 ~80 ~94 log 1
fill ~66 ~1 ~68 ~66 ~46 ~68 log 1
fill ~66 ~1 ~94 ~70 ~1 ~94 planks 1
fill ~67 ~1 ~68 ~71 ~1 ~68 planks 5
fill ~69 ~1 ~69 ~69 ~2 ~69 log 1
fill ~69 ~1 ~70 ~69 ~2 ~70 log 1
fill ~69 ~1 ~71 ~69 ~2 ~71 log 1
fill ~69 ~1 ~74 ~69 ~1 ~85 log 1
fill ~70 ~1 ~69 ~81 ~1 ~69 log 5
fill ~70 ~1 ~70 ~70 ~1 ~74 log 9
fill ~70 ~1 ~75 ~81 ~1 ~75 log 5
fill ~70 ~1 ~76 ~79 ~1 ~76 log 1
fill ~70 ~1 ~77 ~70 ~2 ~77 log 1
fill ~70 ~1 ~78 ~70 ~2 ~78 log 1
fill ~70 ~1 ~79 ~70 ~2 ~79 log 1
fill ~70 ~1 ~82 ~70 ~2 ~82 log 1
fill ~70 ~1 ~83 ~70 ~2 ~83 log 1
fill ~70 ~1 ~84 ~79 ~1 ~84 log 1
fill ~70 ~1 ~85 ~79 ~1 ~85 log 1
fill ~70 ~1 ~86 ~71 ~1 ~86 log 1
fill ~70 ~1 ~87 ~71 ~1 ~87 log 1
fill ~70 ~1 ~88 ~71 ~1 ~88 log 1
fill ~70 ~1 ~89 ~71 ~1 ~89 log 1
fill ~70 ~1 ~90 ~71 ~1 ~90 log 1
fill ~70 ~1 ~91 ~71 ~1 ~91 log 1
fill ~70 ~1 ~92 ~71 ~1 ~92 log 1
fill ~70 ~1 ~93 ~88 ~1 ~93 log 1
fill ~71 ~1 ~70 ~73 ~1 ~70 wool 11
fill ~71 ~1 ~71 ~73 ~1 ~71 wool 11
fill ~71 ~1 ~72 ~73 ~1 ~72 wool 11
fill ~71 ~1 ~73 ~73 ~1 ~73 wool 11
fill ~71 ~1 ~74 ~73 ~1 ~74 wool
fill ~71 ~1 ~77 ~78 ~1 ~77 planks 3
fill ~71 ~1 ~78 ~78 ~1 ~78 planks 3
fill ~71 ~1 ~79 ~78 ~1 ~79 planks 3
fill ~71 ~1 ~80 ~78 ~1 ~80 planks 3
fill ~71 ~1 ~81 ~78 ~1 ~81 planks 3
fill ~71 ~1 ~82 ~78 ~1 ~82 planks 3
fill ~71 ~1 ~83 ~78 ~1 ~83 planks 3
fill ~71 ~1 ~94 ~71 ~46 ~94 log 1
fill ~72 ~1 ~68 ~72 ~20 ~68 log 1
fill ~72 ~1 ~86 ~78 ~1 ~86 planks 5
fill ~72 ~1 ~87 ~78 ~1 ~87 planks 5
fill ~72 ~1 ~88 ~78 ~1 ~88 planks 5
fill ~72 ~1 ~89 ~78 ~1 ~89 planks 5
fill ~72 ~1 ~90 ~78 ~1 ~90 planks 5
fill ~72 ~1 ~91 ~78 ~1 ~91 planks 5
fill ~72 ~1 ~92 ~78 ~1 ~92 planks 5
fill ~72 ~1 ~94 ~76 ~1 ~94 planks 1
fill ~73 ~1 ~68 ~77 ~1 ~68 planks 3
fill ~74 ~1 ~70 ~74 ~1 ~74 log 9
fill ~75 ~1 ~70 ~77 ~1 ~70 wool 11
fill ~75 ~1 ~71 ~77 ~1 ~71 wool 11
fill ~75 ~1 ~72 ~77 ~1 ~72 wool 11
fill ~75 ~1 ~73 ~77 ~1 ~73 wool 11
fill ~75 ~1 ~74 ~77 ~1 ~74 wool
fill ~77 ~1 ~94 ~77 ~11 ~94 log 1
fill ~78 ~1 ~68 ~78 ~73 ~68 log 1
fill ~78 ~1 ~70 ~78 ~1 ~74 log 9
fill ~78 ~1 ~94 ~82 ~1 ~94 hay_block
fill ~79 ~1 ~68 ~83 ~1 ~68 bookshelf
fill ~79 ~1 ~70 ~80 ~1 ~70 wool 11
fill ~79 ~1 ~71 ~80 ~1 ~71 wool 11
fill ~79 ~1 ~72 ~80 ~1 ~72 wool 11
fill ~79 ~1 ~73 ~80 ~1 ~73 wool 11
fill ~79 ~1 ~74 ~80 ~1 ~74 wool
fill ~79 ~1 ~77 ~79 ~2 ~77 log 1
fill ~79 ~1 ~78 ~79 ~2 ~78 log 1
fill ~79 ~1 ~79 ~79 ~2 ~79 log 1
fill ~79 ~1 ~80 ~79 ~2 ~80 log 1
fill ~79 ~1 ~81 ~79 ~2 ~81 log 1
fill ~79 ~1 ~82 ~79 ~2 ~82 log 1
fill ~79 ~1 ~83 ~79 ~2 ~83 log 1
fill ~79 ~1 ~86 ~79 ~1 ~93 log 1
fill ~80 ~1 ~76 ~86 ~1 ~76 log 5
fill ~80 ~1 ~77 ~80 ~1 ~85 log 9
fill ~80 ~1 ~86 ~89 ~1 ~86 log 5
fill ~80 ~1 ~87 ~90 ~1 ~87 log 1
fill ~80 ~1 ~88 ~80 ~2 ~88 log 1
fill ~80 ~1 ~89 ~80 ~2 ~89 log 1
fill ~80 ~1 ~90 ~80 ~2 ~90 log 1
fill ~80 ~1 ~91 ~80 ~2 ~91 log 1
fill ~80 ~1 ~92 ~80 ~2 ~92 log 1
fill ~81 ~1 ~70 ~81 ~1 ~74 log 9
fill ~81 ~1 ~77 ~82 ~1 ~77 wool
fill ~81 ~1 ~78 ~82 ~1 ~78 wool 11
fill ~81 ~1 ~79 ~82 ~1 ~79 wool 11
fill ~81 ~1 ~80 ~89 ~1 ~80 log 5
fill ~81 ~1 ~81 ~82 ~1 ~81 wool
fill ~81 ~1 ~82 ~82 ~1 ~82 wool
fill ~81 ~1 ~83 ~88 ~1 ~83 log 5
fill ~81 ~1 ~84 ~82 ~1 ~84 wool
fill ~81 ~1 ~85 ~82 ~1 ~85 wool
fill ~81 ~1 ~88 ~85 ~1 ~88 planks 2
fill ~81 ~1 ~89 ~85 ~1 ~89 planks 2
fill ~81 ~1 ~90 ~85 ~1 ~90 planks 2
fill ~81 ~1 ~91 ~85 ~1 ~91 planks 2
fill ~81 ~1 ~92 ~86 ~1 ~92 planks 2
fill ~82 ~1 ~69 ~102 ~1 ~69 log 1
fill ~82 ~1 ~70 ~82 ~1 ~75 log 1
fill ~83 ~1 ~70 ~91 ~1 ~70 planks 1
fill ~83 ~1 ~71 ~91 ~1 ~71 planks 1
fill ~83 ~1 ~72 ~84 ~1 ~72 planks 1
fill ~83 ~1 ~73 ~91 ~1 ~73 planks 1
fill ~83 ~1 ~74 ~91 ~1 ~74 planks 1
fill ~83 ~1 ~75 ~87 ~1 ~75 log 1
fill ~83 ~1 ~77 ~83 ~1 ~79 log 9
setblock ~83 ~1 ~81 log 9
fill ~83 ~1 ~84 ~83 ~1 ~85 log 9
fill ~83 ~1 ~94 ~83 ~46 ~94 log 1
fill ~84 ~1 ~68 ~84 ~46 ~68 log 1
fill ~84 ~1 ~77 ~85 ~1 ~77 wool
fill ~84 ~1 ~78 ~85 ~1 ~78 wool 11
fill ~84 ~1 ~79 ~85 ~1 ~79 wool 11
fill ~84 ~1 ~81 ~87 ~1 ~81 wool 11
fill ~84 ~1 ~82 ~87 ~1 ~82 wool 11
fill ~84 ~1 ~84 ~87 ~1 ~84 wool 11
fill ~84 ~1 ~85 ~87 ~1 ~85 wool 11
fill ~84 ~1 ~94 ~88 ~1 ~94 planks 5
fill ~85 ~1 ~68 ~89 ~1 ~68 planks 5
setblock ~85 ~1 ~72 glowstone
fill ~86 ~1 ~72 ~91 ~1 ~72 planks 1
fill ~86 ~1 ~77 ~86 ~1 ~79 log 9
fill ~86 ~1 ~88 ~87 ~1 ~88 log 1
fill ~86 ~1 ~89 ~87 ~1 ~89 log 1
fill ~86 ~1 ~90 ~95 ~1 ~90 log 1
fill ~86 ~1 ~91 ~95 ~1 ~91 log 1
fill ~87 ~1 ~76 ~87 ~1 ~79 log 1
fill ~87 ~1 ~92 ~88 ~1 ~92 log 1
fill ~88 ~1 ~75 ~91 ~1 ~75 planks 1
fill ~88 ~1 ~76 ~89 ~1 ~76 planks 1
fill ~88 ~1 ~77 ~89 ~1 ~77 planks 1
fill ~88 ~1 ~78 ~89 ~1 ~78 planks 1
fill ~88 ~1 ~79 ~90 ~1 ~79 log 1
fill ~88 ~1 ~81 ~88 ~1 ~82 wool
fill ~88 ~1 ~84 ~88 ~1 ~85 wool
fill ~88 ~1 ~88 ~93 ~1 ~88 planks 5
fill ~88 ~1 ~89 ~93 ~1 ~89 planks 5
setblock ~89 ~1 ~81 log 9
fill ~89 ~1 ~92 ~100 ~1 ~92 planks 1
fill ~89 ~1 ~93 ~100 ~1 ~93 planks 1
fill ~89 ~1 ~94 ~89 ~80 ~94 log 1
fill ~90 ~1 ~68 ~90 ~80 ~68 log 1
fill ~90 ~1 ~76 ~90 ~2 ~76 log 1
fill ~90 ~1 ~77 ~90 ~2 ~77 log 1
fill ~90 ~1 ~78 ~90 ~2 ~78 log 1
fill ~90 ~1 ~80 ~90 ~2 ~80 log 1
fill ~90 ~1 ~81 ~90 ~2 ~81 log 1
fill ~90 ~1 ~82 ~90 ~2 ~82 log 1
fill ~90 ~1 ~83 ~101 ~1 ~83 log 1
fill ~90 ~1 ~84 ~101 ~1 ~84 log 1
fill ~90 ~1 ~85 ~90 ~1 ~87 log 1
fill ~90 ~1 ~94 ~94 ~1 ~94 planks 3
fill ~91 ~1 ~68 ~95 ~1 ~68 planks 1
fill ~91 ~1 ~76 ~92 ~1 ~76 planks 5
fill ~91 ~1 ~77 ~100 ~1 ~77 planks 5
fill ~91 ~1 ~78 ~100 ~1 ~78 planks 5
fill ~91 ~1 ~79 ~100 ~1 ~79 planks 5
fill ~91 ~1 ~80 ~100 ~1 ~80 planks 5
fill ~91 ~1 ~81 ~100 ~1 ~81 planks 5
fill ~91 ~1 ~82 ~100 ~1 ~82 planks 5
fill ~91 ~1 ~85 ~93 ~1 ~85 planks 5
fill ~91 ~1 ~86 ~93 ~1 ~86 planks 5
fill ~91 ~1 ~87 ~93 ~1 ~87 planks 5
fill ~92 ~1 ~70 ~93 ~1 ~70 log 1
fill ~92 ~1 ~71 ~93 ~1 ~71 log 1
fill ~92 ~1 ~72 ~93 ~1 ~72 log 1
fill ~92 ~1 ~73 ~93 ~1 ~73 log 1
fill ~92 ~1 ~74 ~93 ~1 ~74 log 1
fill ~92 ~1 ~75 ~93 ~1 ~75 log 1
fill ~93 ~1 ~76 ~101 ~1 ~76 log 1
fill ~94 ~1 ~70 ~100 ~1 ~70 planks 2
fill ~94 ~1 ~71 ~100 ~1 ~71 planks 2
fill ~94 ~1 ~72 ~100 ~1 ~72 planks 2
fill ~94 ~1 ~73 ~100 ~1 ~73 planks 2
fill ~94 ~1 ~74 ~100 ~1 ~74 planks 2
fill ~94 ~1 ~75 ~100 ~1 ~75 planks 2
fill ~94 ~1 ~85 ~95 ~1 ~85 log 1
fill ~94 ~1 ~86 ~95 ~1 ~86 log 1
fill ~94 ~1 ~87 ~95 ~1 ~87 log 1
fill ~94 ~1 ~88 ~95 ~1 ~88 log 1
fill ~94 ~1 ~89 ~95 ~1 ~89 log 1
fill ~95 ~1 ~94 ~95 ~46 ~94 log 1
fill ~96 ~1 ~68 ~96 ~46 ~68 log 1
fill ~96 ~1 ~85 ~100 ~1 ~85 planks 1
fill ~96 ~1 ~86 ~100 ~1 ~86 planks 1
fill ~96 ~1 ~87 ~100 ~1 ~87 planks 1
fill ~96 ~1 ~88 ~100 ~1 ~88 planks 1
fill ~96 ~1 ~89 ~100 ~1 ~89 planks 1
fill ~96 ~1 ~90 ~100 ~1 ~90 planks 1
fill ~96 ~1 ~91 ~100 ~1 ~91 planks 1
fill ~96 ~1 ~94 ~100 ~1 ~94 planks 1
fill ~97 ~1 ~68 ~101 ~1 ~68 planks 1
fill ~101 ~1 ~70 ~101 ~3 ~70 log 1
fill ~101 ~1 ~71 ~101 ~3 ~71 log 1
fill ~101 ~1 ~72 ~101 ~3 ~72 log 1
fill ~101 ~1 ~73 ~101 ~3 ~73 log 1
fill ~101 ~1 ~74 ~101 ~3 ~74 log 1
fill ~101 ~1 ~75 ~102 ~1 ~75 log 1
fill ~101 ~1 ~77 ~101 ~2 ~77 log 1
fill ~101 ~1 ~78 ~101 ~2 ~78 log 1
fill ~101 ~1 ~79 ~101 ~2 ~79 log 1
fill ~101 ~1 ~80 ~101 ~2 ~80 log 1
fill ~101 ~1 ~81 ~102 ~1 ~81 log 1
fill ~101 ~1 ~82 ~101 ~2 ~82 log 1
fill ~101 ~1 ~85 ~101 ~3 ~85 log 1
fill ~101 ~1 ~86 ~101 ~2 ~86 log 1
fill ~101 ~1 ~87 ~102 ~1 ~87 log 1
fill ~101 ~1 ~88 ~101 ~2 ~88 log 1
fill ~101 ~1 ~89 ~101 ~2 ~89 log 1
fill ~101 ~1 ~90 ~101 ~2 ~90 log 1
fill ~101 ~1 ~91 ~101 ~2 ~91 log 1
fill ~101 ~1 ~92 ~101 ~2 ~92 log 1
fill ~101 ~1 ~93 ~102 ~1 ~93 log 1
fill ~101 ~1 ~94 ~102 ~1 ~94 log 1
fill ~102 ~1 ~68 ~102 ~46 ~68 log 1
fill ~102 ~1 ~70 ~102 ~5 ~70 planks 5
fill ~102 ~1 ~71 ~102 ~5 ~71 planks 5
fill ~102 ~1 ~72 ~102 ~5 ~72 planks 5
fill ~102 ~1 ~73 ~102 ~5 ~73 planks 5
fill ~102 ~1 ~74 ~102 ~5 ~74 planks 5
fill ~102 ~1 ~76 ~102 ~5 ~76 planks 1
fill ~102 ~1 ~77 ~102 ~5 ~77 planks 1
fill ~102 ~1 ~78 ~102 ~5 ~78 planks 1
fill ~102 ~1 ~79 ~102 ~5 ~79 planks 1
fill ~102 ~1 ~80 ~102 ~5 ~80 planks 1
fill ~102 ~1 ~82 ~102 ~5 ~82 planks 5
fill ~102 ~1 ~83 ~102 ~5 ~83 planks 5
fill ~102 ~1 ~84 ~102 ~5 ~84 planks 5
fill ~102 ~1 ~85 ~102 ~5 ~85 planks 5
fill ~102 ~1 ~86 ~102 ~5 ~86 planks 5
fill ~102 ~1 ~88 ~102 ~5 ~88 planks 3
fill ~102 ~1 ~89 ~102 ~5 ~89 planks 3
fill ~102 ~1 ~90 ~102 ~5 ~90 planks 3
fill ~102 ~1 ~91 ~102 ~5 ~91 planks 3
fill ~102 ~1 ~92 ~102 ~5 ~92 planks 3
fill ~16 ~2 ~8 ~17 ~2 ~8 log 1
fill ~16 ~2 ~15 ~17 ~2 ~15 log 1
fill ~16 ~2 ~21 ~16 ~80 ~21 log 1
fill ~16 ~2 ~27 ~16 ~46 ~27 log 1
fill ~16 ~2 ~33 ~17 ~2 ~33 log 1
fill ~16 ~2 ~39 ~23 ~2 ~39 log 1
fill ~16 ~2 ~45 ~17 ~2 ~45 log 1
fill ~16 ~2 ~63 ~17 ~2 ~63 log 1
fill ~16 ~2 ~69 ~17 ~2 ~69 log 1
fill ~16 ~2 ~75 ~17 ~2 ~75 log 1
fill ~16 ~2 ~81 ~17 ~2 ~81 log 1
fill ~16 ~2 ~87 ~17 ~2 ~87 log 1
fill ~16 ~2 ~93 ~31 ~2 ~93 log 1
fill ~16 ~2 ~94 ~17 ~2 ~94 log 1
fill ~17 ~2 ~9 ~41 ~2 ~9 log 1
fill ~17 ~2 ~29 ~17 ~3 ~29 log 1
fill ~17 ~2 ~30 ~17 ~3 ~30 log 1
fill ~17 ~2 ~31 ~17 ~3 ~31 log 1
fill ~17 ~2 ~32 ~17 ~3 ~32 log 1
fill ~17 ~2 ~34 ~17 ~3 ~34 log 1
fill ~17 ~2 ~35 ~17 ~3 ~35 log 1
fill ~17 ~2 ~36 ~17 ~3 ~36 log 1
fill ~17 ~2 ~37 ~17 ~3 ~37 log 1
fill ~17 ~2 ~38 ~17 ~3 ~38 log 1
fill ~17 ~2 ~40 ~29 ~2 ~40 log 1
fill ~17 ~2 ~41 ~17 ~2 ~48 log 1
fill ~17 ~2 ~62 ~22 ~2 ~62 log 1
fill ~17 ~2 ~76 ~25 ~2 ~76 log 1
fill ~17 ~2 ~77 ~25 ~2 ~77 log 1
fill ~18 ~2 ~8 ~22 ~2 ~8 planks 3
fill ~18 ~2 ~10 ~19 ~2 ~10 planks 1
fill ~18 ~2 ~11 ~19 ~2 ~11 planks 1
fill ~18 ~2 ~12 ~19 ~2 ~12 planks 1
fill ~18 ~2 ~13 ~19 ~2 ~13 planks 1
fill ~18 ~2 ~14 ~19 ~2 ~14 planks 1
fill ~18 ~2 ~15 ~19 ~2 ~15 bookshelf
fill ~18 ~2 ~27 ~19 ~2 ~27 spruce_stairs 2
fill ~18 ~2 ~28 ~19 ~2 ~28 spruce_stairs 7
fill ~18 ~2 ~29 ~20 ~2 ~29 wool
fill ~18 ~2 ~30 ~24 ~2 ~30 planks 1
fill ~18 ~2 ~31 ~24 ~2 ~31 planks 1
fill ~18 ~2 ~32 ~22 ~2 ~32 planks 1
fill ~18 ~2 ~33 ~22 ~2 ~33 planks 1
fill ~18 ~2 ~34 ~22 ~2 ~34 planks 1
fill ~18 ~2 ~35 ~22 ~2 ~35 planks 1
fill ~18 ~2 ~36 ~22 ~2 ~36 planks 1
fill ~18 ~2 ~37 ~22 ~2 ~37 planks 1
fill ~18 ~2 ~38 ~22 ~2 ~38 planks 1
fill ~18 ~2 ~41 ~28 ~2 ~41 planks 3
fill ~18 ~2 ~42 ~28 ~2 ~42 planks 3
fill ~18 ~2 ~43 ~28 ~2 ~43 planks 3
fill ~18 ~2 ~44 ~28 ~2 ~44 planks 3
fill ~18 ~2 ~45 ~28 ~2 ~45 planks 3
fill ~18 ~2 ~46 ~28 ~2 ~46 planks 3
fill ~18 ~2 ~47 ~21 ~2 ~47 planks 3
fill ~18 ~2 ~48 ~30 ~2 ~48 log 1
fill ~18 ~2 ~63 ~21 ~2 ~63 planks 2
fill ~18 ~2 ~64 ~21 ~2 ~64 planks 2
fill ~18 ~2 ~65 ~21 ~2 ~65 planks 2
fill ~18 ~2 ~66 ~21 ~2 ~66 planks 2
fill ~18 ~2 ~67 ~21 ~2 ~67 planks 2
fill ~18 ~2 ~68 ~24 ~2 ~68 planks 2
fill ~18 ~2 ~69 ~24 ~2 ~69 planks 2
fill ~18 ~2 ~70 ~24 ~2 ~70 planks 2
fill ~18 ~2 ~71 ~24 ~2 ~71 planks 2
fill ~18 ~2 ~72 ~24 ~2 ~72 planks 2
fill ~18 ~2 ~73 ~24 ~2 ~73 planks 2
fill ~18 ~2 ~74 ~24 ~2 ~74 planks 2
fill ~18 ~2 ~75 ~24 ~2 ~75 planks 2
fill ~18 ~2 ~78 ~24 ~2 ~78 planks 5
fill ~18 ~2 ~79 ~24 ~2 ~79 planks 5
fill ~18 ~2 ~80 ~24 ~2 ~80 planks 5
fill ~18 ~2 ~81 ~24 ~2 ~81 planks 5
fill ~18 ~2 ~82 ~24 ~2 ~82 planks 5
fill ~18 ~2 ~83 ~24 ~2 ~83 planks 5
fill ~18 ~2 ~84 ~24 ~2 ~84 planks 5
fill ~18 ~2 ~85 ~24 ~2 ~85 planks 5
fill ~18 ~2 ~86 ~21 ~2 ~86 planks 5
fill ~18 ~2 ~87 ~21 ~2 ~87 planks 5
fill ~18 ~2 ~88 ~21 ~2 ~88 planks 5
fill ~18 ~2 ~89 ~21 ~2 ~89 planks 5
fill ~18 ~2 ~90 ~21 ~2 ~90 planks 5
fill ~18 ~2 ~91 ~21 ~2 ~91 planks 5
fill ~18 ~2 ~92 ~21 ~2 ~92 planks 5
fill ~18 ~2 ~94 ~22 ~2 ~94 planks 5
fill ~20 ~2 ~10 ~21 ~2 ~10 log 1
fill ~20 ~2 ~11 ~21 ~2 ~11 log 1
fill ~20 ~2 ~12 ~21 ~2 ~12 log 1
fill ~20 ~2 ~13 ~21 ~2 ~13 log 1
fill ~20 ~2 ~14 ~21 ~2 ~14 log 1
fill ~20 ~2 ~15 ~21 ~2 ~15 log 1
fill ~21 ~2 ~20 ~28 ~2 ~20 log 1
fill ~21 ~2 ~28 ~21 ~3 ~28 trapdoor 4
fill ~21 ~2 ~29 ~21 ~3 ~29 log 1
fill ~22 ~2 ~10 ~30 ~2 ~10 planks 3
fill ~22 ~2 ~11 ~30 ~2 ~11 planks 3
fill ~22 ~2 ~12 ~30 ~2 ~12 planks 3
fill ~22 ~2 ~13 ~30 ~2 ~13 planks 3
fill ~22 ~2 ~14 ~27 ~2 ~14 planks 3
fill ~22 ~2 ~15 ~27 ~2 ~15 planks 3
fill ~22 ~2 ~16 ~27 ~2 ~16 planks 3
fill ~22 ~2 ~17 ~27 ~2 ~17 planks 3
fill ~22 ~2 ~18 ~27 ~2 ~18 planks 3
fill ~22 ~2 ~19 ~27 ~2 ~19 planks 3
fill ~22 ~2 ~29 ~24 ~2 ~29 bookshelf
fill ~22 ~2 ~47 ~30 ~2 ~47 log 1
fill ~22 ~2 ~50 ~22 ~2 ~52 trapdoor 6
fill ~22 ~2 ~63 ~22 ~1 ~63 log 1
fill ~22 ~2 ~64 ~22 ~1 ~64 log 1
fill ~22 ~2 ~65 ~22 ~1 ~65 log 1
fill ~22 ~2 ~66 ~22 ~1 ~66 log 1
fill ~22 ~2 ~67 ~26 ~2 ~67 log 1
fill ~22 ~2 ~86 ~25 ~2 ~86 log 1
fill ~22 ~2 ~87 ~31 ~2 ~87 log 1
fill ~22 ~2 ~88 ~23 ~2 ~88 log 1
fill ~22 ~2 ~89 ~23 ~2 ~89 log 1
fill ~22 ~2 ~90 ~23 ~2 ~90 log 1
fill ~22 ~2 ~91 ~23 ~2 ~91 log 1
fill ~22 ~2 ~92 ~23 ~2 ~92 log 1
fill ~23 ~2 ~32 ~23 ~3 ~32 log 1
fill ~23 ~2 ~34 ~23 ~2 ~35 wool
fill ~23 ~2 ~36 ~23 ~3 ~36 log 1
fill ~23 ~2 ~37 ~23 ~2 ~38 planks 5
fill ~23 ~2 ~50 ~23 ~2 ~52 glowstone
fill ~23 ~2 ~53 ~23 ~3 ~53 log 1
fill ~23 ~2 ~54 ~23 ~2 ~55 wool
fill ~23 ~2 ~56 ~23 ~3 ~56 log 1
fill ~23 ~2 ~57 ~23 ~2 ~58 bookshelf
fill ~23 ~2 ~59 ~23 ~3 ~59 log 1
fill ~24 ~2 ~8 ~28 ~2 ~8 planks 5
setblock ~24 ~2 ~32 bookshelf
fill ~24 ~2 ~49 ~28 ~2 ~49 planks 1
fill ~24 ~2 ~50 ~28 ~2 ~50 planks 1
fill ~24 ~2 ~51 ~28 ~2 ~51 planks 1
fill ~24 ~2 ~52 ~28 ~2 ~52 planks 1
fill ~24 ~2 ~53 ~28 ~2 ~53 planks 1
fill ~24 ~2 ~54 ~28 ~2 ~54 planks 1
fill ~24 ~2 ~55 ~28 ~2 ~55 planks 1
fill ~24 ~2 ~56 ~28 ~2 ~56 planks 1
fill ~24 ~2 ~57 ~28 ~2 ~57 planks 1
fill ~24 ~2 ~58 ~28 ~2 ~58 planks 1
fill ~24 ~2 ~59 ~25 ~2 ~59 planks 5
fill ~24 ~2 ~60 ~25 ~2 ~60 ladder 3
fill ~24 ~2 ~88 ~30 ~2 ~88 planks 1
fill ~24 ~2 ~89 ~30 ~2 ~89 planks 1
fill ~24 ~2 ~90 ~26 ~2 ~90 planks 1
fill ~24 ~2 ~91 ~30 ~2 ~91 planks 1
fill ~24 ~2 ~92 ~30 ~2 ~92 planks 1
fill ~24 ~2 ~94 ~28 ~2 ~94 planks 3
fill ~25 ~2 ~29 ~26 ~2 ~29 log 1
fill ~25 ~2 ~30 ~26 ~2 ~30 log 1
fill ~25 ~2 ~31 ~26 ~2 ~31 log 1
fill ~25 ~2 ~32 ~35 ~2 ~32 log 1
fill ~25 ~2 ~68 ~26 ~2 ~68 log 1
fill ~25 ~2 ~69 ~26 ~2 ~69 log 1
fill ~25 ~2 ~70 ~26 ~2 ~70 log 1
fill ~25 ~2 ~71 ~26 ~2 ~71 log 1
fill ~25 ~2 ~78 ~25 ~2 ~79 wool
fill ~25 ~2 ~80 ~25 ~3 ~80 log 1
fill ~25 ~2 ~81 ~25 ~2 ~82 wool
fill ~25 ~2 ~83 ~25 ~3 ~83 log 1
fill ~25 ~2 ~84 ~25 ~2 ~85 bookshelf
fill ~26 ~2 ~26 ~36 ~2 ~26 log 1
fill ~26 ~2 ~27 ~26 ~2 ~32 log 1
fill ~26 ~2 ~59 ~26 ~3 ~59 log 1
fill ~26 ~2 ~80 ~26 ~3 ~80 trapdoor 7
fill ~26 ~2 ~83 ~26 ~3 ~83 trapdoor 7
fill ~27 ~2 ~27 ~33 ~2 ~27 planks 5
fill ~27 ~2 ~28 ~33 ~2 ~28 planks 5
fill ~27 ~2 ~29 ~29 ~2 ~29 planks 5
fill ~27 ~2 ~30 ~33 ~2 ~30 planks 5
fill ~27 ~2 ~31 ~33 ~2 ~31 planks 5
fill ~27 ~2 ~59 ~28 ~2 ~59 wool
fill ~27 ~2 ~67 ~29 ~2 ~67 bookshelf
fill ~27 ~2 ~68 ~29 ~2 ~68 planks 1
fill ~27 ~2 ~69 ~29 ~2 ~69 planks 1
fill ~27 ~2 ~70 ~29 ~2 ~70 planks 1
fill ~27 ~2 ~71 ~29 ~2 ~71 bookshelf
setblock ~27 ~2 ~90 glowstone
fill ~28 ~2 ~14 ~32 ~2 ~14 log 1
fill ~28 ~2 ~90 ~30 ~2 ~90 planks 1
fill ~29 ~2 ~41 ~29 ~1 ~41 log 1
fill ~29 ~2 ~42 ~29 ~1 ~42 log 1
fill ~29 ~2 ~43 ~29 ~1 ~43 log 1
fill ~29 ~2 ~44 ~29 ~1 ~44 log 1
fill ~29 ~2 ~45 ~29 ~1 ~45 log 1
fill ~29 ~2 ~46 ~29 ~1 ~46 log 1
fill ~29 ~2 ~49 ~30 ~2 ~49 log 1
fill ~29 ~2 ~50 ~30 ~2 ~50 log 1
fill ~29 ~2 ~51 ~30 ~2 ~51 log 1
fill ~29 ~2 ~52 ~30 ~2 ~52 log 1
fill ~29 ~2 ~53 ~30 ~2 ~53 log 1
fill ~29 ~2 ~54 ~37 ~2 ~54 log 1
fill ~29 ~2 ~55 ~37 ~2 ~55 log 1
fill ~29 ~2 ~56 ~30 ~2 ~56 log 1
fill ~29 ~2 ~57 ~30 ~2 ~57 log 1
fill ~29 ~2 ~58 ~30 ~2 ~58 log 1
fill ~29 ~2 ~59 ~30 ~2 ~59 log 1
fill ~30 ~2 ~8 ~34 ~2 ~8 planks 1
setblock ~30 ~2 ~29 glowstone
fill ~30 ~2 ~60 ~30 ~2 ~64 log 1
fill ~30 ~2 ~65 ~30 ~2 ~67 wool
fill ~30 ~2 ~69 ~30 ~2 ~70 wool
fill ~30 ~2 ~71 ~30 ~4 ~71 log 1
fill ~30 ~2 ~94 ~34 ~2 ~94 planks 1
fill ~31 ~2 ~10 ~32 ~2 ~10 log 1
fill ~31 ~2 ~11 ~32 ~2 ~11 log 1
fill ~31 ~2 ~12 ~32 ~2 ~12 log 1
fill ~31 ~2 ~13 ~32 ~2 ~13 log 1
fill ~31 ~2 ~29 ~33 ~2 ~29 planks 5
fill ~31 ~2 ~46 ~32 ~2 ~46 trapdoor 4
fill ~31 ~2 ~47 ~32 ~2 ~47 glowstone
fill ~31 ~2 ~48 ~35 ~2 ~48 planks 2
fill ~31 ~2 ~49 ~35 ~2 ~49 planks 2
fill ~31 ~2 ~50 ~35 ~2 ~50 planks 2
fill ~31 ~2 ~51 ~35 ~2 ~51 planks 2
fill ~31 ~2 ~52 ~35 ~2 ~52 planks 2
fill ~31 ~2 ~53 ~35 ~2 ~53 planks 2
fill ~31 ~2 ~56 ~40 ~2 ~56 planks 1
fill ~31 ~2 ~57 ~40 ~2 ~57 planks 1
fill ~31 ~2 ~58 ~40 ~2 ~58 planks 1
fill ~31 ~2 ~59 ~40 ~2 ~59 planks 1
fill ~31 ~2 ~60 ~40 ~2 ~60 planks 1
fill ~31 ~2 ~61 ~40 ~2 ~61 planks 1
fill ~31 ~2 ~62 ~40 ~2 ~62 planks 1
fill ~31 ~2 ~63 ~41 ~2 ~63 log 1
fill ~31 ~2 ~64 ~40 ~2 ~64 planks 5
fill ~31 ~2 ~65 ~41 ~2 ~65 planks 3
fill ~31 ~2 ~66 ~41 ~2 ~66 planks 3
fill ~31 ~2 ~67 ~41 ~2 ~67 planks 3
fill ~31 ~2 ~68 ~41 ~2 ~68 planks 3
fill ~31 ~2 ~69 ~41 ~2 ~69 planks 3
fill ~31 ~2 ~70 ~37 ~2 ~70 planks 3
fill ~31 ~2 ~71 ~32 ~2 ~71 wool
fill ~31 ~2 ~88 ~31 ~1 ~88 log 1
fill ~31 ~2 ~89 ~31 ~1 ~89 log 1
fill ~31 ~2 ~90 ~31 ~1 ~90 log 1
fill ~31 ~2 ~91 ~31 ~1 ~91 log 1
fill ~31 ~2 ~92 ~31 ~1 ~92 log 1
fill ~32 ~2 ~72 ~33 ~2 ~72 spruce_stairs 6
fill ~32 ~2 ~73 ~33 ~2 ~73 spruce_stairs 3
fill ~33 ~2 ~10 ~40 ~2 ~10 planks 5
fill ~33 ~2 ~11 ~40 ~2 ~11 planks 5
fill ~33 ~2 ~12 ~40 ~2 ~12 planks 5
fill ~33 ~2 ~13 ~40 ~2 ~13 planks 5
fill ~33 ~2 ~14 ~35 ~2 ~14 glowstone
fill ~33 ~2 ~15 ~35 ~2 ~15 trapdoor 5
fill ~33 ~2 ~44 ~34 ~2 ~44 spruce_stairs 2
fill ~33 ~2 ~45 ~34 ~2 ~45 spruce_stairs 7
fill ~33 ~2 ~47 ~33 ~4 ~47 log 1
fill ~33 ~2 ~71 ~34 ~2 ~71 log 1
fill ~34 ~2 ~27 ~35 ~2 ~27 log 1
fill ~34 ~2 ~28 ~35 ~2 ~28 log 1
fill ~34 ~2 ~29 ~35 ~2 ~29 log 1
fill ~34 ~2 ~30 ~35 ~2 ~30 log 1
fill ~34 ~2 ~31 ~35 ~2 ~31 log 1
fill ~34 ~2 ~47 ~35 ~2 ~47 bookshelf
fill ~35 ~2 ~71 ~37 ~2 ~71 glowstone
fill ~35 ~2 ~72 ~37 ~2 ~72 trapdoor 5
fill ~36 ~2 ~8 ~40 ~2 ~8 planks 5
fill ~36 ~2 ~14 ~42 ~2 ~14 log 1
fill ~36 ~2 ~15 ~41 ~2 ~15 log 1
fill ~36 ~2 ~22 ~41 ~2 ~22 log 1
fill ~36 ~2 ~23 ~41 ~2 ~23 log 1
fill ~36 ~2 ~24 ~36 ~2 ~25 wool
fill ~36 ~2 ~27 ~40 ~2 ~27 planks 2
fill ~36 ~2 ~28 ~40 ~2 ~28 planks 2
fill ~36 ~2 ~29 ~40 ~2 ~29 planks 2
fill ~36 ~2 ~30 ~40 ~2 ~30 planks 2
fill ~36 ~2 ~31 ~40 ~2 ~31 planks 2
setblock ~36 ~2 ~32 wool
fill ~36 ~2 ~47 ~36 ~4 ~47 log 1
fill ~36 ~2 ~48 ~36 ~2 ~49 wool 11
fill ~36 ~2 ~50 ~36 ~4 ~50 log 1
fill ~36 ~2 ~51 ~41 ~2 ~51 log 1
fill ~36 ~2 ~52 ~37 ~2 ~52 log 1
fill ~36 ~2 ~53 ~37 ~2 ~53 log 1
fill ~36 ~2 ~81 ~44 ~2 ~81 log 1
fill ~36 ~2 ~87 ~36 ~2 ~88 log 1
fill ~36 ~2 ~94 ~40 ~2 ~94 planks 5
fill ~37 ~2 ~16 ~40 ~2 ~16 planks 1
fill ~37 ~2 ~17 ~40 ~2 ~17 planks 1
fill ~37 ~2 ~18 ~40 ~2 ~18 planks 1
fill ~37 ~2 ~19 ~40 ~2 ~19 planks 1
fill ~37 ~2 ~20 ~40 ~2 ~20 planks 1
fill ~37 ~2 ~21 ~40 ~2 ~21 planks 1
fill ~37 ~2 ~24 ~40 ~2 ~24 planks 2
fill ~37 ~2 ~25 ~40 ~2 ~25 planks 2
fill ~37 ~2 ~26 ~40 ~2 ~26 planks 2
fill ~37 ~2 ~32 ~37 ~3 ~32 log 1
fill ~37 ~2 ~33 ~41 ~2 ~33 log 1
fill ~37 ~2 ~34 ~41 ~2 ~34 log 1
fill ~37 ~2 ~40 ~41 ~2 ~40 log 1
fill ~37 ~2 ~82 ~43 ~2 ~82 planks 3
fill ~37 ~2 ~83 ~43 ~2 ~83 planks 3
fill ~37 ~2 ~84 ~43 ~2 ~84 planks 3
fill ~37 ~2 ~85 ~43 ~2 ~85 planks 3
fill ~37 ~2 ~86 ~43 ~2 ~86 planks 3
fill ~37 ~2 ~87 ~43 ~2 ~87 planks 3
fill ~37 ~2 ~88 ~44 ~2 ~88 log 1
fill ~38 ~2 ~32 ~40 ~2 ~32 planks 2
fill ~38 ~2 ~35 ~42 ~2 ~35 planks 1
fill ~38 ~2 ~36 ~42 ~2 ~36 planks 1
fill ~38 ~2 ~37 ~42 ~2 ~37 planks 1
fill ~38 ~2 ~38 ~41 ~2 ~38 planks 1
fill ~38 ~2 ~39 ~41 ~2 ~39 planks 1
fill ~38 ~2 ~52 ~40 ~2 ~52 planks 1
fill ~38 ~2 ~53 ~40 ~2 ~53 planks 1
fill ~38 ~2 ~54 ~40 ~2 ~54 planks 1
fill ~38 ~2 ~55 ~40 ~2 ~55 planks 1
fill ~38 ~2 ~70 ~39 ~2 ~70 log 1
fill ~38 ~2 ~71 ~38 ~3 ~71 log 1
fill ~39 ~2 ~71 ~40 ~2 ~71 spruce_fence
fill ~39 ~2 ~72 ~39 ~2 ~73 spruce_fence
fill ~39 ~2 ~93 ~41 ~2 ~93 spruce_fence
fill ~40 ~2 ~70 ~41 ~2 ~70 wool
fill ~41 ~2 ~8 ~42 ~2 ~8 log 1
fill ~41 ~2 ~20 ~42 ~2 ~20 log 1
fill ~41 ~2 ~26 ~42 ~2 ~26 log 1
fill ~41 ~2 ~32 ~42 ~2 ~32 log 1
setblock ~41 ~2 ~41 trapdoor 6
fill ~41 ~2 ~52 ~41 ~2 ~64 log 1
setblock ~41 ~2 ~92 spruce_fence
fill ~41 ~2 ~94 ~41 ~27 ~94 log 1
fill ~42 ~2 ~50 ~42 ~46 ~50 log 1
fill ~42 ~2 ~69 ~43 ~2 ~69 log 1
fill ~42 ~2 ~70 ~43 ~2 ~70 log 1
setblock ~42 ~2 ~89 spruce_stairs
fill ~42 ~2 ~90 ~56 ~2 ~90 log 1
fill ~42 ~2 ~91 ~42 ~2 ~93 wool 11
fill ~42 ~2 ~94 ~46 ~2 ~94 planks 5
fill ~43 ~2 ~68 ~47 ~2 ~68 bookshelf
fill ~43 ~2 ~71 ~43 ~2 ~72 log 1
setblock ~43 ~2 ~89 log 5
fill ~43 ~2 ~91 ~54 ~2 ~91 planks 1
fill ~43 ~2 ~92 ~54 ~2 ~92 planks 1
fill ~43 ~2 ~93 ~62 ~2 ~93 log 1
fill ~44 ~2 ~69 ~48 ~2 ~69 planks 2
fill ~44 ~2 ~70 ~45 ~2 ~70 planks 2
fill ~44 ~2 ~71 ~48 ~2 ~71 planks 2
fill ~44 ~2 ~72 ~49 ~2 ~72 log 1
fill ~44 ~2 ~77 ~44 ~3 ~77 log 1
fill ~44 ~2 ~78 ~44 ~2 ~80 bookshelf
fill ~44 ~2 ~82 ~44 ~3 ~82 log 1
fill ~44 ~2 ~83 ~44 ~3 ~83 log 1
fill ~44 ~2 ~84 ~44 ~3 ~84 log 1
fill ~44 ~2 ~85 ~44 ~3 ~85 log 1
fill ~44 ~2 ~86 ~44 ~3 ~86 log 1
fill ~44 ~2 ~87 ~44 ~3 ~87 log 1
fill ~44 ~2 ~89 ~56 ~2 ~89 log 1
fill ~45 ~2 ~77 ~48 ~2 ~77 wool
fill ~45 ~2 ~78 ~48 ~2 ~78 planks 5
fill ~45 ~2 ~79 ~48 ~2 ~79 planks 5
fill ~45 ~2 ~80 ~48 ~2 ~80 planks 5
fill ~45 ~2 ~81 ~48 ~2 ~81 planks 5
fill ~45 ~2 ~82 ~54 ~2 ~82 planks 5
fill ~45 ~2 ~83 ~54 ~2 ~83 planks 5
fill ~45 ~2 ~84 ~54 ~2 ~84 planks 5
fill ~45 ~2 ~85 ~54 ~2 ~85 planks 5
fill ~45 ~2 ~86 ~54 ~2 ~86 planks 5
fill ~45 ~2 ~87 ~54 ~2 ~87 planks 5
fill ~45 ~2 ~88 ~54 ~2 ~88 planks 5
setblock ~46 ~2 ~70 glowstone
fill ~46 ~2 ~75 ~47 ~2 ~75 spruce_stairs 2
fill ~46 ~2 ~76 ~47 ~2 ~76 spruce_stairs 7
fill ~47 ~2 ~70 ~48 ~2 ~70 planks 2
fill ~48 ~2 ~94 ~52 ~2 ~94 planks 3
fill ~49 ~2 ~68 ~53 ~2 ~68 planks 3
fill ~49 ~2 ~77 ~49 ~3 ~77 log 1
setblock ~49 ~2 ~78 wool
setblock ~49 ~2 ~79 glowstone
setblock ~49 ~2 ~80 wool
fill ~49 ~2 ~81 ~49 ~3 ~81 log 1
setblock ~50 ~2 ~79 trapdoor 7
setblock ~50 ~2 ~81 wool
setblock ~51 ~2 ~80 trapdoor 4
setblock ~51 ~2 ~81 glowstone
setblock ~52 ~2 ~81 wool
fill ~53 ~2 ~81 ~54 ~2 ~81 bookshelf
fill ~54 ~2 ~94 ~58 ~2 ~94 planks 1
fill ~55 ~2 ~68 ~59 ~2 ~68 hay_block
fill ~55 ~2 ~81 ~64 ~2 ~81 log 1
fill ~55 ~2 ~82 ~56 ~2 ~82 log 1
fill ~55 ~2 ~83 ~56 ~2 ~83 log 1
fill ~55 ~2 ~84 ~56 ~2 ~84 log 1
fill ~55 ~2 ~85 ~56 ~2 ~85 log 1
fill ~55 ~2 ~86 ~56 ~2 ~86 log 1
fill ~55 ~2 ~87 ~56 ~2 ~87 log 1
fill ~55 ~2 ~88 ~56 ~2 ~88 log 1
fill ~55 ~2 ~91 ~56 ~2 ~91 log 1
fill ~55 ~2 ~92 ~56 ~2 ~92 log 1
fill ~57 ~2 ~69 ~57 ~4 ~69 trapdoor 5
fill ~57 ~2 ~82 ~62 ~2 ~82 planks 3
fill ~57 ~2 ~83 ~62 ~2 ~83 planks 3
fill ~57 ~2 ~84 ~62 ~2 ~84 planks 3
fill ~57 ~2 ~85 ~62 ~2 ~85 planks 3
fill ~57 ~2 ~86 ~62 ~2 ~86 planks 3
fill ~57 ~2 ~87 ~62 ~2 ~87 planks 3
fill ~57 ~2 ~88 ~60 ~2 ~88 planks 3
fill ~57 ~2 ~89 ~60 ~2 ~89 planks 3
fill ~57 ~2 ~90 ~60 ~2 ~90 planks 3
fill ~57 ~2 ~91 ~60 ~2 ~91 planks 3
fill ~57 ~2 ~92 ~60 ~2 ~92 planks 3
fill ~58 ~2 ~75 ~63 ~2 ~75 log 1
fill ~59 ~2 ~69 ~68 ~2 ~69 planks 1
fill ~59 ~2 ~70 ~68 ~2 ~70 planks 1
fill ~59 ~2 ~71 ~68 ~2 ~71 planks 1
fill ~59 ~2 ~72 ~62 ~2 ~72 planks 1
fill ~59 ~2 ~73 ~62 ~2 ~73 planks 1
fill ~59 ~2 ~74 ~62 ~2 ~74 planks 1
fill ~60 ~2 ~94 ~64 ~2 ~94 planks 5
fill ~61 ~2 ~68 ~65 ~2 ~68 planks 5
fill ~61 ~2 ~88 ~64 ~2 ~88 log 1
fill ~61 ~2 ~89 ~64 ~2 ~89 log 1
fill ~61 ~2 ~90 ~62 ~2 ~90 log 1
fill ~61 ~2 ~91 ~62 ~2 ~91 log 1
fill ~61 ~2 ~92 ~62 ~2 ~92 log 1
fill ~63 ~2 ~72 ~69 ~2 ~72 log 1
fill ~63 ~2 ~73 ~63 ~1 ~73 log 1
fill ~63 ~2 ~74 ~63 ~1 ~74 log 1
fill ~63 ~2 ~82 ~64 ~2 ~82 log 1
fill ~63 ~2 ~83 ~64 ~2 ~83 log 1
fill ~63 ~2 ~84 ~64 ~2 ~84 log 1
fill ~63 ~2 ~85 ~64 ~2 ~85 log 1
fill ~63 ~2 ~86 ~64 ~2 ~86 log 1
fill ~63 ~2 ~87 ~64 ~2 ~87 log 1
fill ~63 ~2 ~90 ~69 ~2 ~90 planks 2
fill ~63 ~2 ~91 ~69 ~2 ~91 planks 2
fill ~63 ~2 ~92 ~69 ~2 ~92 planks 2
fill ~63 ~2 ~93 ~69 ~2 ~93 planks 2
fill ~65 ~2 ~80 ~68 ~2 ~80 trapdoor 4
fill ~65 ~2 ~81 ~68 ~2 ~81 glowstone
fill ~65 ~2 ~82 ~68 ~2 ~82 planks 2
fill ~65 ~2 ~83 ~68 ~2 ~83 planks 2
fill ~65 ~2 ~84 ~68 ~2 ~84 planks 2
fill ~65 ~2 ~85 ~68 ~2 ~85 planks 2
fill ~65 ~2 ~86 ~69 ~2 ~86 planks 2
fill ~65 ~2 ~87 ~69 ~2 ~87 planks 2
fill ~65 ~2 ~88 ~69 ~2 ~88 planks 2
fill ~65 ~2 ~89 ~69 ~2 ~89 planks 2
fill ~66 ~2 ~94 ~70 ~2 ~94 planks 1
fill ~67 ~2 ~68 ~71 ~2 ~68 planks 5
fill ~69 ~2 ~81 ~70 ~2 ~81 log 1
fill ~69 ~2 ~82 ~69 ~3 ~82 log 1
fill ~69 ~2 ~83 ~69 ~3 ~83 log 1
fill ~69 ~2 ~84 ~79 ~2 ~84 log 1
fill ~69 ~2 ~85 ~79 ~2 ~85 log 1
fill ~70 ~2 ~76 ~79 ~2 ~76 log 1
setblock ~70 ~2 ~80 log 1
fill ~70 ~2 ~86 ~71 ~2 ~86 log 1
fill ~70 ~2 ~87 ~71 ~2 ~87 log 1
fill ~70 ~2 ~88 ~71 ~2 ~88 log 1
fill ~70 ~2 ~89 ~71 ~2 ~89 log 1
fill ~70 ~2 ~90 ~71 ~2 ~90 log 1
fill ~70 ~2 ~91 ~71 ~2 ~91 log 1
fill ~70 ~2 ~92 ~71 ~2 ~92 log 1
fill ~70 ~2 ~93 ~88 ~2 ~93 log 1
fill ~71 ~2 ~77 ~78 ~2 ~77 planks 3
fill ~71 ~2 ~78 ~78 ~2 ~78 planks 3
fill ~71 ~2 ~79 ~78 ~2 ~79 planks 3
fill ~71 ~2 ~80 ~78 ~2 ~80 planks 3
fill ~71 ~2 ~81 ~78 ~2 ~81 planks 3
fill ~71 ~2 ~82 ~78 ~2 ~82 planks 3
fill ~71 ~2 ~83 ~78 ~2 ~83 planks 3
fill ~72 ~2 ~86 ~78 ~2 ~86 planks 5
fill ~72 ~2 ~87 ~78 ~2 ~87 planks 5
fill ~72 ~2 ~88 ~78 ~2 ~88 planks 5
fill ~72 ~2 ~89 ~78 ~2 ~89 planks 5
fill ~72 ~2 ~90 ~78 ~2 ~90 planks 5
fill ~72 ~2 ~91 ~78 ~2 ~91 planks 5
fill ~72 ~2 ~92 ~78 ~2 ~92 planks 5
fill ~72 ~2 ~94 ~76 ~2 ~94 planks 1
fill ~73 ~2 ~68 ~77 ~2 ~68 planks 3
fill ~78 ~2 ~94 ~82 ~2 ~94 hay_block
fill ~79 ~2 ~68 ~83 ~2 ~68 bookshelf
setblock ~79 ~2 ~86 wool 11
fill ~79 ~2 ~87 ~86 ~2 ~87 log 1
fill ~79 ~2 ~88 ~79 ~4 ~88 log 1
fill ~79 ~2 ~89 ~79 ~4 ~89 log 1
fill ~79 ~2 ~90 ~79 ~4 ~90 log 1
fill ~79 ~2 ~91 ~79 ~2 ~93 log 1
fill ~81 ~2 ~88 ~85 ~2 ~88 planks 2
fill ~81 ~2 ~89 ~85 ~2 ~89 planks 2
fill ~81 ~2 ~90 ~82 ~2 ~90 planks 2
fill ~81 ~2 ~91 ~85 ~2 ~91 planks 2
fill ~81 ~2 ~92 ~85 ~2 ~92 planks 2
setblock ~83 ~2 ~90 glowstone
fill ~84 ~2 ~90 ~85 ~2 ~90 planks 2
fill ~84 ~2 ~94 ~88 ~2 ~94 planks 5
fill ~85 ~2 ~68 ~89 ~2 ~68 planks 5
fill ~86 ~2 ~88 ~86 ~1 ~88 log 1
fill ~86 ~2 ~89 ~86 ~1 ~89 log 1
fill ~86 ~2 ~90 ~86 ~1 ~90 log 1
fill ~86 ~2 ~91 ~87 ~2 ~91 log 1
fill ~86 ~2 ~92 ~88 ~2 ~92 log 1
fill ~88 ~2 ~91 ~89 ~2 ~91 bookshelf
fill ~89 ~2 ~92 ~100 ~2 ~92 planks 1
fill ~89 ~2 ~93 ~100 ~2 ~93 planks 1
fill ~90 ~2 ~75 ~93 ~2 ~75 log 1
setblock ~90 ~2 ~79 log 1
fill ~90 ~2 ~83 ~101 ~2 ~83 log 1
setblock ~90 ~2 ~90 trapdoor 4
fill ~90 ~2 ~91 ~90 ~3 ~91 log 1
fill ~90 ~2 ~94 ~94 ~2 ~94 planks 3
fill ~91 ~2 ~68 ~95 ~2 ~68 planks 1
fill ~91 ~2 ~71 ~91 ~2 ~72 spruce_stairs
fill ~91 ~2 ~76 ~92 ~2 ~76 planks 5
fill ~91 ~2 ~77 ~100 ~2 ~77 planks 5
fill ~91 ~2 ~78 ~100 ~2 ~78 planks 5
fill ~91 ~2 ~79 ~100 ~2 ~79 planks 5
fill ~91 ~2 ~80 ~100 ~2 ~80 planks 5
fill ~91 ~2 ~81 ~100 ~2 ~81 planks 5
fill ~91 ~2 ~82 ~100 ~2 ~82 planks 5
fill ~91 ~2 ~91 ~93 ~2 ~91 bookshelf
fill ~92 ~2 ~71 ~92 ~2 ~72 spruce_stairs 5
fill ~93 ~2 ~69 ~102 ~2 ~69 log 1
fill ~93 ~2 ~70 ~93 ~2 ~71 wool
fill ~93 ~2 ~72 ~93 ~3 ~72 log 1
fill ~93 ~2 ~73 ~93 ~2 ~74 wool
fill ~93 ~2 ~76 ~101 ~2 ~76 log 1
fill ~93 ~2 ~88 ~93 ~2 ~89 spruce_stairs
fill ~94 ~2 ~70 ~100 ~2 ~70 planks 2
fill ~94 ~2 ~71 ~100 ~2 ~71 planks 2
fill ~94 ~2 ~72 ~100 ~2 ~72 planks 2
fill ~94 ~2 ~73 ~100 ~2 ~73 planks 2
fill ~94 ~2 ~74 ~100 ~2 ~74 planks 2
fill ~94 ~2 ~75 ~100 ~2 ~75 planks 2
fill ~94 ~2 ~85 ~94 ~2 ~87 trapdoor 6
fill ~94 ~2 ~88 ~94 ~2 ~89 spruce_stairs 5
fill ~94 ~2 ~91 ~95 ~2 ~91 log 1
fill ~95 ~2 ~84 ~101 ~2 ~84 log 1
fill ~95 ~2 ~85 ~95 ~2 ~87 glowstone
fill ~95 ~2 ~88 ~95 ~3 ~88 log 1
fill ~95 ~2 ~89 ~95 ~3 ~89 log 1
fill ~95 ~2 ~90 ~95 ~3 ~90 log 1
fill ~96 ~2 ~85 ~100 ~2 ~85 planks 1
fill ~96 ~2 ~86 ~100 ~2 ~86 planks 1
fill ~96 ~2 ~87 ~100 ~2 ~87 planks 1
fill ~96 ~2 ~88 ~100 ~2 ~88 planks 1
fill ~96 ~2 ~89 ~100 ~2 ~89 planks 1
fill ~96 ~2 ~90 ~100 ~2 ~90 planks 1
fill ~96 ~2 ~91 ~100 ~2 ~91 planks 1
fill ~96 ~2 ~94 ~100 ~2 ~94 planks 1
fill ~97 ~2 ~68 ~101 ~2 ~68 planks 1
fill ~101 ~2 ~75 ~102 ~2 ~75 log 1
fill ~101 ~2 ~81 ~102 ~2 ~81 log 1
fill ~101 ~2 ~87 ~102 ~2 ~87 log 1
fill ~101 ~2 ~93 ~102 ~2 ~93 log 1
fill ~101 ~2 ~94 ~102 ~2 ~94 log 1
fill ~16 ~3 ~8 ~17 ~3 ~8 log 1
fill ~16 ~3 ~15 ~20 ~3 ~15 log 1
fill ~16 ~3 ~33 ~17 ~3 ~33 log 1
fill ~16 ~3 ~39 ~23 ~3 ~39 log 1
fill ~16 ~3 ~45 ~16 ~80 ~45 log 1
fill ~16 ~3 ~63 ~16 ~6 ~63 log 1
fill ~16 ~3 ~69 ~16 ~80 ~69 log 1
fill ~16 ~3 ~75 ~16 ~46 ~75 log 1
fill ~16 ~3 ~81 ~17 ~3 ~81 log 1
fill ~16 ~3 ~87 ~17 ~3 ~87 log 1
fill ~16 ~3 ~93 ~22 ~3 ~93 log 1
fill ~16 ~3 ~94 ~17 ~3 ~94 log 1
fill ~17 ~3 ~9 ~20 ~3 ~9 log 1
fill ~17 ~3 ~47 ~17 ~3 ~48 spruce_fence
fill ~17 ~3 ~77 ~25 ~3 ~77 log 1
fill ~18 ~3 ~8 ~22 ~3 ~8 planks 3
fill ~18 ~3 ~10 ~19 ~3 ~10 planks 1
fill ~18 ~3 ~11 ~19 ~3 ~11 planks 1
fill ~18 ~3 ~12 ~19 ~3 ~12 planks 1
fill ~18 ~3 ~13 ~19 ~3 ~13 planks 1
fill ~18 ~3 ~14 ~19 ~3 ~14 planks 1
fill ~18 ~3 ~16 ~19 ~3 ~16 trapdoor 5
fill ~18 ~3 ~28 ~19 ~3 ~28 spruce_stairs 2
fill ~18 ~3 ~29 ~25 ~3 ~29 log 1
fill ~18 ~3 ~30 ~24 ~3 ~30 planks 1
fill ~18 ~3 ~31 ~24 ~3 ~31 planks 1
fill ~18 ~3 ~32 ~22 ~3 ~32 planks 1
fill ~18 ~3 ~33 ~22 ~3 ~33 planks 1
fill ~18 ~3 ~34 ~22 ~3 ~34 planks 1
fill ~18 ~3 ~35 ~22 ~3 ~35 planks 1
fill ~18 ~3 ~36 ~19 ~3 ~36 planks 1
fill ~18 ~3 ~37 ~22 ~3 ~37 planks 1
fill ~18 ~3 ~38 ~22 ~3 ~38 planks 1
fill ~18 ~3 ~48 ~19 ~3 ~48 spruce_fence
fill ~18 ~3 ~78 ~24 ~3 ~78 planks 5
fill ~18 ~3 ~79 ~24 ~3 ~79 planks 5
fill ~18 ~3 ~80 ~24 ~3 ~80 planks 5
fill ~18 ~3 ~81 ~24 ~3 ~81 planks 5
fill ~18 ~3 ~82 ~24 ~3 ~82 planks 5
fill ~18 ~3 ~83 ~24 ~3 ~83 planks 5
fill ~18 ~3 ~84 ~24 ~3 ~84 planks 5
fill ~18 ~3 ~85 ~24 ~3 ~85 planks 5
fill ~18 ~3 ~86 ~21 ~3 ~86 planks 5
fill ~18 ~3 ~87 ~21 ~3 ~87 planks 5
fill ~18 ~3 ~88 ~21 ~3 ~88 planks 5
fill ~18 ~3 ~89 ~21 ~3 ~89 planks 5
fill ~18 ~3 ~90 ~21 ~3 ~90 planks 5
fill ~18 ~3 ~91 ~21 ~3 ~91 planks 5
fill ~18 ~3 ~92 ~21 ~3 ~92 planks 5
fill ~18 ~3 ~94 ~22 ~3 ~94 planks 5
fill ~20 ~3 ~10 ~20 ~1 ~10 log 1
fill ~20 ~3 ~11 ~20 ~1 ~11 log 1
fill ~20 ~3 ~12 ~20 ~1 ~12 log 1
fill ~20 ~3 ~13 ~20 ~1 ~13 log 1
fill ~20 ~3 ~14 ~20 ~1 ~14 log 1
setblock ~20 ~3 ~36 glowstone
fill ~21 ~3 ~19 ~21 ~3 ~20 spruce_fence
fill ~21 ~3 ~36 ~22 ~3 ~36 planks 1
fill ~21 ~3 ~62 ~22 ~3 ~62 spruce_fence
setblock ~22 ~3 ~9 spruce_stairs 4
fill ~22 ~3 ~20 ~23 ~3 ~20 spruce_fence
setblock ~22 ~3 ~51 ladder 4
fill ~22 ~3 ~63 ~22 ~3 ~64 spruce_fence
fill ~22 ~3 ~86 ~25 ~3 ~86 log 1
fill ~22 ~3 ~87 ~22 ~1 ~87 log 1
fill ~22 ~3 ~88 ~22 ~1 ~88 log 1
fill ~22 ~3 ~89 ~22 ~1 ~89 log 1
fill ~22 ~3 ~90 ~22 ~1 ~90 log 1
fill ~22 ~3 ~91 ~22 ~1 ~91 log 1
fill ~22 ~3 ~92 ~22 ~1 ~92 log 1
setblock ~23 ~3 ~9 spruce_stairs 1
fill ~23 ~3 ~34 ~23 ~3 ~39 log 1
fill ~23 ~3 ~48 ~30 ~3 ~48 log 1
fill ~23 ~3 ~50 ~23 ~3 ~59 log 1
fill ~24 ~3 ~8 ~28 ~3 ~8 planks 5
fill ~24 ~3 ~32 ~25 ~3 ~32 log 1
fill ~24 ~3 ~49 ~28 ~3 ~49 planks 1
fill ~24 ~3 ~50 ~28 ~3 ~50 planks 1
fill ~24 ~3 ~51 ~28 ~3 ~51 planks 1
fill ~24 ~3 ~52 ~28 ~3 ~52 planks 1
fill ~24 ~3 ~53 ~28 ~3 ~53 planks 1
fill ~24 ~3 ~54 ~28 ~3 ~54 planks 1
fill ~24 ~3 ~55 ~28 ~3 ~55 planks 1
fill ~24 ~3 ~56 ~28 ~3 ~56 planks 1
fill ~24 ~3 ~57 ~28 ~3 ~57 planks 1
fill ~24 ~3 ~58 ~28 ~3 ~58 planks 1
fill ~24 ~3 ~59 ~29 ~3 ~59 log 1
fill ~24 ~3 ~94 ~28 ~3 ~94 planks 3
fill ~25 ~3 ~30 ~25 ~1 ~30 log 1
fill ~25 ~3 ~31 ~25 ~1 ~31 log 1
fill ~25 ~3 ~68 ~25 ~3 ~70 trapdoor 6
fill ~25 ~3 ~78 ~25 ~3 ~86 log 1
fill ~26 ~3 ~26 ~28 ~3 ~26 spruce_fence
fill ~26 ~3 ~27 ~26 ~3 ~26 spruce_fence
fill ~26 ~3 ~67 ~26 ~4 ~67 log 1
fill ~26 ~3 ~68 ~26 ~3 ~70 glowstone
fill ~26 ~3 ~71 ~26 ~4 ~71 log 1
fill ~27 ~3 ~67 ~29 ~3 ~67 bookshelf
fill ~27 ~3 ~68 ~29 ~3 ~68 planks 1
fill ~27 ~3 ~69 ~29 ~3 ~69 planks 1
fill ~27 ~3 ~70 ~29 ~3 ~70 planks 1
fill ~27 ~3 ~71 ~29 ~3 ~71 bookshelf
fill ~29 ~3 ~49 ~30 ~3 ~49 log 1
fill ~29 ~3 ~50 ~30 ~3 ~50 log 1
fill ~29 ~3 ~51 ~30 ~3 ~51 log 1
fill ~29 ~3 ~52 ~30 ~3 ~52 log 1
fill ~29 ~3 ~53 ~30 ~3 ~53 log 1
fill ~29 ~3 ~54 ~30 ~3 ~54 log 1
fill ~29 ~3 ~55 ~29 ~1 ~55 log 1
fill ~29 ~3 ~56 ~29 ~1 ~56 log 1
fill ~29 ~3 ~57 ~29 ~1 ~57 log 1
fill ~29 ~3 ~58 ~29 ~1 ~58 log 1
fill ~29 ~3 ~87 ~31 ~3 ~87 spruce_fence
fill ~30 ~3 ~8 ~34 ~3 ~8 planks 1
fill ~30 ~3 ~47 ~30 ~4 ~47 log 1
fill ~30 ~3 ~64 ~41 ~3 ~64 log 1
fill ~30 ~3 ~65 ~30 ~3 ~71 log 1
fill ~30 ~3 ~94 ~34 ~3 ~94 planks 1
fill ~31 ~3 ~46 ~32 ~3 ~46 trapdoor 4
fill ~31 ~3 ~47 ~32 ~3 ~47 glowstone
fill ~31 ~3 ~48 ~35 ~3 ~48 planks 2
fill ~31 ~3 ~49 ~35 ~3 ~49 planks 2
fill ~31 ~3 ~50 ~35 ~3 ~50 planks 2
fill ~31 ~3 ~51 ~35 ~3 ~51 planks 2
fill ~31 ~3 ~52 ~35 ~3 ~52 planks 2
fill ~31 ~3 ~53 ~35 ~3 ~53 planks 2
fill ~31 ~3 ~54 ~32 ~3 ~54 wool
fill ~31 ~3 ~65 ~41 ~3 ~65 planks 3
fill ~31 ~3 ~66 ~41 ~3 ~66 planks 3
fill ~31 ~3 ~67 ~38 ~3 ~67 planks 3
fill ~31 ~3 ~68 ~41 ~3 ~68 planks 3
fill ~31 ~3 ~69 ~41 ~3 ~69 planks 3
fill ~31 ~3 ~70 ~37 ~3 ~70 planks 3
fill ~31 ~3 ~71 ~38 ~3 ~71 log 1
setblock ~31 ~3 ~88 spruce_fence
fill ~32 ~3 ~9 ~41 ~3 ~9 log 1
fill ~32 ~3 ~10 ~32 ~3 ~14 log 1
fill ~32 ~3 ~72 ~33 ~3 ~72 spruce_stairs 3
fill ~33 ~3 ~10 ~40 ~3 ~10 planks 5
fill ~33 ~3 ~11 ~40 ~3 ~11 planks 5
fill ~33 ~3 ~12 ~40 ~3 ~12 planks 5
fill ~33 ~3 ~13 ~40 ~3 ~13 planks 5
fill ~33 ~3 ~14 ~42 ~3 ~14 log 1
fill ~33 ~3 ~45 ~34 ~3 ~45 spruce_stairs 2
fill ~33 ~3 ~46 ~34 ~3 ~46 spruce_stairs 7
fill ~33 ~3 ~54 ~33 ~4 ~54 log 1
setblock ~34 ~3 ~15 ladder 3
fill ~34 ~3 ~47 ~35 ~3 ~47 bookshelf
fill ~34 ~3 ~54 ~35 ~3 ~54 glowstone
fill ~34 ~3 ~55 ~35 ~3 ~55 trapdoor 5
fill ~35 ~3 ~26 ~36 ~3 ~26 log 1
fill ~35 ~3 ~27 ~35 ~3 ~32 log 1
fill ~36 ~3 ~8 ~40 ~3 ~8 planks 5
fill ~36 ~3 ~23 ~42 ~3 ~23 log 1
fill ~36 ~3 ~24 ~36 ~3 ~26 log 1
fill ~36 ~3 ~27 ~40 ~3 ~27 planks 2
fill ~36 ~3 ~28 ~40 ~3 ~28 planks 2
fill ~36 ~3 ~29 ~40 ~3 ~29 planks 2
fill ~36 ~3 ~30 ~40 ~3 ~30 planks 2
fill ~36 ~3 ~31 ~40 ~3 ~31 planks 2
setblock ~36 ~3 ~32 log 1
fill ~36 ~3 ~48 ~36 ~3 ~49 wool
fill ~36 ~3 ~51 ~36 ~3 ~52 wool
setblock ~36 ~3 ~53 bookshelf
fill ~36 ~3 ~54 ~36 ~4 ~54 log 1
setblock ~36 ~3 ~72 ladder 3
fill ~36 ~3 ~81 ~38 ~3 ~81 spruce_fence
fill ~36 ~3 ~82 ~36 ~3 ~81 spruce_fence
fill ~36 ~3 ~94 ~40 ~3 ~94 planks 5
fill ~37 ~3 ~24 ~40 ~3 ~24 planks 2
fill ~37 ~3 ~25 ~40 ~3 ~25 planks 2
fill ~37 ~3 ~26 ~40 ~3 ~26 planks 2
fill ~37 ~3 ~33 ~41 ~3 ~33 log 1
fill ~38 ~3 ~32 ~40 ~3 ~32 planks 2
fill ~38 ~3 ~70 ~42 ~3 ~70 log 1
setblock ~39 ~3 ~67 glowstone
fill ~40 ~3 ~67 ~41 ~3 ~67 planks 3
fill ~41 ~3 ~8 ~42 ~3 ~8 log 1
setblock ~41 ~3 ~20 dark_oak_stairs 2
setblock ~41 ~3 ~21 dark_oak_stairs 7
fill ~41 ~3 ~26 ~42 ~3 ~26 log 1
fill ~41 ~3 ~32 ~42 ~3 ~32 log 1
setblock ~41 ~3 ~41 trapdoor 14
fill ~42 ~3 ~20 ~42 ~5 ~20 log 1
fill ~42 ~3 ~21 ~42 ~3 ~26 log 1
fill ~42 ~3 ~35 ~42 ~5 ~35 planks 1
fill ~42 ~3 ~36 ~42 ~5 ~36 planks 1
fill ~42 ~3 ~37 ~42 ~5 ~37 planks 1
fill ~42 ~3 ~51 ~42 ~3 ~56 log 1
fill ~42 ~3 ~69 ~42 ~1 ~69 log 1
fill ~42 ~3 ~90 ~55 ~3 ~90 log 1
fill ~42 ~3 ~91 ~42 ~3 ~93 wool
fill ~42 ~3 ~94 ~46 ~3 ~94 planks 5
fill ~43 ~3 ~68 ~48 ~3 ~68 log 1
setblock ~43 ~3 ~81 spruce_fence
setblock ~43 ~3 ~89 spruce_stairs
fill ~43 ~3 ~91 ~54 ~3 ~91 planks 1
fill ~43 ~3 ~92 ~54 ~3 ~92 planks 1
fill ~43 ~3 ~93 ~55 ~3 ~93 log 1
fill ~44 ~3 ~78 ~44 ~3 ~90 log 1
fill ~45 ~3 ~77 ~49 ~3 ~77 log 1
fill ~45 ~3 ~78 ~48 ~3 ~78 planks 5
fill ~45 ~3 ~79 ~48 ~3 ~79 planks 5
fill ~45 ~3 ~80 ~48 ~3 ~80 planks 5
fill ~45 ~3 ~81 ~48 ~3 ~81 planks 5
fill ~45 ~3 ~82 ~54 ~3 ~82 planks 5
fill ~45 ~3 ~83 ~54 ~3 ~83 planks 5
fill ~45 ~3 ~84 ~54 ~3 ~84 planks 5
fill ~45 ~3 ~85 ~54 ~3 ~85 planks 5
fill ~45 ~3 ~86 ~46 ~3 ~86 planks 5
fill ~45 ~3 ~87 ~54 ~3 ~87 planks 5
fill ~45 ~3 ~88 ~54 ~3 ~88 planks 5
fill ~45 ~3 ~89 ~55 ~3 ~89 log 1
fill ~46 ~3 ~76 ~47 ~3 ~76 spruce_stairs 2
setblock ~47 ~3 ~86 glowstone
fill ~48 ~3 ~86 ~54 ~3 ~86 planks 5
fill ~48 ~3 ~94 ~52 ~3 ~94 planks 3
fill ~49 ~3 ~68 ~53 ~3 ~68 planks 3
fill ~49 ~3 ~69 ~49 ~3 ~70 spruce_fence
fill ~49 ~3 ~78 ~49 ~3 ~81 log 1
setblock ~50 ~3 ~79 ladder 5
fill ~50 ~3 ~81 ~55 ~3 ~81 log 1
setblock ~51 ~3 ~80 ladder 2
fill ~54 ~3 ~94 ~58 ~3 ~94 planks 1
fill ~55 ~3 ~68 ~59 ~3 ~68 hay_block
fill ~55 ~3 ~82 ~55 ~1 ~82 log 1
fill ~55 ~3 ~83 ~55 ~1 ~83 log 1
fill ~55 ~3 ~84 ~55 ~1 ~84 log 1
fill ~55 ~3 ~85 ~55 ~1 ~85 log 1
fill ~55 ~3 ~86 ~55 ~1 ~86 log 1
fill ~55 ~3 ~87 ~55 ~1 ~87 log 1
fill ~55 ~3 ~88 ~55 ~1 ~88 log 1
fill ~55 ~3 ~91 ~55 ~4 ~91 log 1
fill ~55 ~3 ~92 ~55 ~4 ~92 log 1
fill ~56 ~3 ~91 ~56 ~3 ~92 spruce_stairs 4
fill ~56 ~3 ~93 ~58 ~3 ~93 spruce_fence
fill ~57 ~3 ~91 ~57 ~3 ~92 spruce_stairs 1
fill ~58 ~3 ~69 ~58 ~3 ~70 spruce_fence
fill ~58 ~3 ~73 ~58 ~3 ~75 spruce_fence
setblock ~59 ~3 ~75 spruce_fence
setblock ~60 ~3 ~69 dark_oak_stairs 4
fill ~60 ~3 ~94 ~64 ~3 ~94 planks 5
fill ~61 ~3 ~68 ~65 ~3 ~68 planks 5
setblock ~61 ~3 ~69 dark_oak_stairs 1
fill ~62 ~3 ~89 ~64 ~3 ~89 log 1
fill ~62 ~3 ~90 ~62 ~3 ~93 log 1
fill ~63 ~3 ~72 ~65 ~3 ~72 spruce_fence
fill ~63 ~3 ~73 ~63 ~3 ~72 spruce_fence
fill ~63 ~3 ~90 ~69 ~3 ~90 planks 2
fill ~63 ~3 ~91 ~69 ~3 ~91 planks 2
fill ~63 ~3 ~92 ~69 ~3 ~92 planks 2
fill ~63 ~3 ~93 ~69 ~3 ~93 planks 2
fill ~64 ~3 ~81 ~69 ~3 ~81 log 1
fill ~64 ~3 ~82 ~64 ~3 ~89 log 1
fill ~65 ~3 ~82 ~68 ~3 ~82 planks 2
fill ~65 ~3 ~83 ~68 ~3 ~83 planks 2
fill ~65 ~3 ~84 ~68 ~3 ~84 planks 2
fill ~65 ~3 ~85 ~68 ~3 ~85 planks 2
fill ~65 ~3 ~86 ~69 ~3 ~86 planks 2
fill ~65 ~3 ~87 ~69 ~3 ~87 planks 2
fill ~65 ~3 ~88 ~69 ~3 ~88 planks 2
fill ~65 ~3 ~89 ~69 ~3 ~89 planks 2
fill ~66 ~3 ~80 ~67 ~3 ~80 ladder 2
fill ~66 ~3 ~94 ~70 ~3 ~94 planks 1
fill ~67 ~3 ~68 ~71 ~3 ~68 planks 5
fill ~69 ~3 ~69 ~69 ~3 ~71 spruce_fence
fill ~69 ~3 ~84 ~69 ~1 ~84 log 1
fill ~69 ~3 ~85 ~71 ~3 ~85 log 1
fill ~70 ~3 ~86 ~71 ~3 ~86 log 1
fill ~70 ~3 ~87 ~71 ~3 ~87 log 1
fill ~70 ~3 ~88 ~71 ~3 ~88 log 1
fill ~70 ~3 ~89 ~71 ~3 ~89 log 1
fill ~70 ~3 ~90 ~71 ~3 ~90 log 1
fill ~70 ~3 ~91 ~71 ~3 ~91 log 1
fill ~70 ~3 ~92 ~71 ~3 ~92 log 1
fill ~70 ~3 ~93 ~79 ~3 ~93 log 1
fill ~72 ~3 ~85 ~75 ~3 ~85 wool
fill ~72 ~3 ~86 ~78 ~3 ~86 planks 5
fill ~72 ~3 ~87 ~78 ~3 ~87 planks 5
fill ~72 ~3 ~88 ~78 ~3 ~88 planks 5
fill ~72 ~3 ~89 ~78 ~3 ~89 planks 5
fill ~72 ~3 ~90 ~78 ~3 ~90 planks 5
fill ~72 ~3 ~91 ~78 ~3 ~91 planks 5
fill ~72 ~3 ~92 ~78 ~3 ~92 planks 5
fill ~72 ~3 ~94 ~76 ~3 ~94 planks 1
fill ~73 ~3 ~68 ~77 ~3 ~68 planks 3
fill ~73 ~3 ~83 ~74 ~3 ~83 spruce_stairs 2
fill ~73 ~3 ~84 ~74 ~3 ~84 spruce_stairs 7
fill ~76 ~3 ~84 ~78 ~3 ~84 trapdoor 4
fill ~76 ~3 ~85 ~78 ~3 ~85 glowstone
fill ~77 ~3 ~76 ~79 ~3 ~76 spruce_fence
fill ~78 ~3 ~94 ~82 ~3 ~94 hay_block
fill ~79 ~3 ~68 ~84 ~3 ~68 log 1
setblock ~79 ~3 ~77 spruce_fence
fill ~79 ~3 ~85 ~79 ~4 ~85 log 1
fill ~79 ~3 ~86 ~79 ~3 ~87 wool
fill ~79 ~3 ~91 ~79 ~3 ~92 bookshelf
fill ~80 ~3 ~87 ~81 ~3 ~87 spruce_fence
fill ~80 ~3 ~89 ~80 ~3 ~90 spruce_stairs 4
setblock ~80 ~3 ~93 trapdoor 4
fill ~81 ~3 ~89 ~81 ~3 ~90 spruce_stairs 1
fill ~84 ~3 ~94 ~88 ~3 ~94 planks 5
fill ~85 ~3 ~68 ~89 ~3 ~68 planks 5
fill ~87 ~3 ~91 ~95 ~3 ~91 log 1
fill ~87 ~3 ~92 ~87 ~3 ~93 log 1
fill ~88 ~3 ~92 ~100 ~3 ~92 planks 1
fill ~88 ~3 ~93 ~100 ~3 ~93 planks 1
fill ~90 ~3 ~81 ~90 ~3 ~83 spruce_fence
fill ~90 ~3 ~94 ~94 ~3 ~94 planks 3
fill ~91 ~3 ~68 ~95 ~3 ~68 planks 1
setblock ~91 ~3 ~83 spruce_fence
fill ~92 ~3 ~71 ~92 ~3 ~72 spruce_stairs
fill ~93 ~3 ~69 ~102 ~3 ~69 log 1
fill ~93 ~3 ~70 ~93 ~3 ~76 log 1
fill ~94 ~3 ~70 ~100 ~3 ~70 planks 2
fill ~94 ~3 ~71 ~100 ~3 ~71 planks 2
fill ~94 ~3 ~72 ~100 ~3 ~72 planks 2
fill ~94 ~3 ~73 ~100 ~3 ~73 planks 2
fill ~94 ~3 ~74 ~100 ~3 ~74 planks 2
fill ~94 ~3 ~75 ~100 ~3 ~75 planks 2
fill ~94 ~3 ~76 ~101 ~3 ~76 log 1
fill ~94 ~3 ~85 ~94 ~3 ~87 ladder 4
fill ~94 ~3 ~88 ~94 ~3 ~89 spruce_stairs
fill ~95 ~3 ~84 ~101 ~3 ~84 log 1
fill ~95 ~3 ~85 ~95 ~3 ~91 log 1
fill ~96 ~3 ~85 ~100 ~3 ~85 planks 1
fill ~96 ~3 ~86 ~100 ~3 ~86 planks 1
fill ~96 ~3 ~87 ~100 ~3 ~87 planks 1
fill ~96 ~3 ~88 ~100 ~3 ~88 planks 1
fill ~96 ~3 ~89 ~100 ~3 ~89 planks 1
fill ~96 ~3 ~90 ~100 ~3 ~90 planks 1
fill ~96 ~3 ~91 ~100 ~3 ~91 planks 1
fill ~96 ~3 ~94 ~100 ~3 ~94 planks 1
fill ~97 ~3 ~68 ~101 ~3 ~68 planks 1
fill ~99 ~3 ~83 ~101 ~3 ~83 spruce_fence
fill ~101 ~3 ~75 ~102 ~3 ~75 log 1
setblock ~101 ~3 ~82 spruce_fence
setblock ~101 ~3 ~86 log 5
fill ~101 ~3 ~87 ~101 ~3 ~88 wool
setblock ~101 ~3 ~89 log 5
fill ~101 ~3 ~90 ~101 ~3 ~91 wool
setblock ~101 ~3 ~92 log 5
fill ~101 ~3 ~93 ~102 ~3 ~93 log 1
fill ~101 ~3 ~94 ~102 ~3 ~94 log 1
fill ~102 ~3 ~81 ~102 ~10 ~81 log 1
fill ~102 ~3 ~87 ~102 ~80 ~87 log 1
fill ~16 ~4 ~8 ~17 ~4 ~8 log 1
fill ~16 ~4 ~15 ~16 ~46 ~15 log 1
fill ~16 ~4 ~33 ~16 ~80 ~33 log 1
fill ~16 ~4 ~39 ~16 ~26 ~39 log 1
fill ~16 ~4 ~81 ~16 ~80 ~81 log 1
fill ~16 ~4 ~87 ~16 ~46 ~87 log 1
fill ~16 ~4 ~93 ~16 ~46 ~93 log 1
fill ~16 ~4 ~94 ~17 ~4 ~94 log 1
fill ~17 ~4 ~36 ~17 ~5 ~36 trapdoor 15
fill ~18 ~4 ~8 ~22 ~4 ~8 planks 3
fill ~18 ~4 ~77 ~20 ~4 ~77 spruce_fence
fill ~18 ~4 ~94 ~22 ~4 ~94 planks 5
fill ~20 ~4 ~9 ~20 ~4 ~10 spruce_fence
setblock ~21 ~4 ~9 spruce_stairs 4
setblock ~22 ~4 ~9 spruce_stairs 1
fill ~22 ~4 ~39 ~23 ~4 ~39 spruce_fence
setblock ~23 ~4 ~38 spruce_fence
fill ~24 ~4 ~8 ~28 ~4 ~8 planks 5
fill ~24 ~4 ~94 ~28 ~4 ~94 planks 3
fill ~26 ~4 ~68 ~26 ~4 ~71 log 1
fill ~27 ~4 ~9 ~36 ~4 ~9 log 9
fill ~27 ~4 ~10 ~36 ~4 ~10 spruce_fence
fill ~27 ~4 ~67 ~30 ~4 ~67 log 1
fill ~27 ~4 ~68 ~29 ~4 ~68 planks 1
fill ~27 ~4 ~69 ~27 ~1 ~69 planks 1
fill ~27 ~4 ~70 ~29 ~4 ~70 planks 1
fill ~27 ~4 ~71 ~30 ~4 ~71 log 1
fill ~28 ~4 ~59 ~29 ~4 ~59 spruce_fence
setblock ~28 ~4 ~69 glowstone
setblock ~29 ~4 ~58 spruce_fence
setblock ~29 ~4 ~69 planks 1
fill ~30 ~4 ~8 ~34 ~4 ~8 planks 1
fill ~30 ~4 ~48 ~30 ~4 ~54 log 1
fill ~30 ~4 ~69 ~30 ~4 ~71 log 1
fill ~30 ~4 ~94 ~34 ~4 ~94 planks 1
fill ~31 ~4 ~46 ~32 ~4 ~46 ladder 2
fill ~31 ~4 ~47 ~36 ~4 ~47 log 1
fill ~31 ~4 ~48 ~35 ~4 ~48 planks 2
fill ~31 ~4 ~49 ~35 ~4 ~49 planks 2
fill ~31 ~4 ~50 ~35 ~4 ~50 planks 2
fill ~31 ~4 ~51 ~35 ~4 ~51 planks 2
fill ~31 ~4 ~52 ~35 ~4 ~52 planks 2
fill ~31 ~4 ~53 ~35 ~4 ~53 planks 2
fill ~31 ~4 ~54 ~36 ~4 ~54 log 1
fill ~32 ~4 ~13 ~32 ~4 ~14 spruce_fence
fill ~33 ~4 ~14 ~34 ~4 ~14 spruce_fence
fill ~33 ~4 ~46 ~34 ~4 ~46 spruce_stairs 2
fill ~34 ~4 ~55 ~35 ~4 ~55 ladder 3
fill ~36 ~4 ~8 ~40 ~4 ~8 planks 5
fill ~36 ~4 ~32 ~37 ~4 ~32 spruce_fence
fill ~36 ~4 ~48 ~36 ~4 ~54 log 1
fill ~36 ~4 ~94 ~40 ~4 ~94 planks 5
fill ~37 ~4 ~33 ~38 ~4 ~33 spruce_fence
fill ~39 ~4 ~64 ~41 ~4 ~64 spruce_fence
fill ~41 ~4 ~8 ~42 ~4 ~8 log 1
setblock ~41 ~4 ~21 dark_oak_stairs 2
setblock ~41 ~4 ~22 dark_oak_stairs 7
fill ~41 ~4 ~41 ~41 ~5 ~41 trapdoor 6
fill ~42 ~4 ~14 ~42 ~46 ~14 log 1
fill ~42 ~4 ~21 ~42 ~4 ~25 planks 5
fill ~42 ~4 ~26 ~42 ~6 ~26 log 1
fill ~42 ~4 ~32 ~42 ~63 ~32 log 1
fill ~42 ~4 ~51 ~42 ~5 ~51 planks 3
fill ~42 ~4 ~52 ~42 ~5 ~52 planks 3
fill ~42 ~4 ~53 ~42 ~5 ~53 planks 3
fill ~42 ~4 ~54 ~42 ~5 ~54 planks 3
fill ~42 ~4 ~55 ~42 ~5 ~55 planks 3
fill ~42 ~4 ~90 ~55 ~4 ~90 log 1
fill ~42 ~4 ~91 ~42 ~4 ~93 log 1
fill ~42 ~4 ~94 ~46 ~4 ~94 planks 5
fill ~43 ~4 ~68 ~47 ~4 ~68 planks 5
fill ~43 ~4 ~91 ~54 ~4 ~91 planks 1
fill ~43 ~4 ~92 ~54 ~4 ~92 planks 1
fill ~43 ~4 ~93 ~55 ~4 ~93 log 1
fill ~48 ~4 ~94 ~52 ~4 ~94 planks 3
fill ~49 ~4 ~68 ~53 ~4 ~68 planks 3
fill ~49 ~4 ~80 ~49 ~4 ~81 spruce_fence
fill ~50 ~4 ~81 ~51 ~4 ~81 spruce_fence
fill ~54 ~4 ~94 ~58 ~4 ~94 planks 1
fill ~55 ~4 ~68 ~59 ~4 ~68 hay_block
fill ~56 ~4 ~91 ~56 ~4 ~92 spruce_stairs 1
setblock ~59 ~4 ~69 dark_oak_stairs 4
setblock ~60 ~4 ~69 dark_oak_stairs 1
fill ~60 ~4 ~94 ~64 ~4 ~94 planks 5
fill ~61 ~4 ~68 ~65 ~4 ~68 planks 5
fill ~62 ~4 ~92 ~62 ~4 ~93 spruce_fence
fill ~64 ~4 ~81 ~66 ~4 ~81 spruce_fence
fill ~64 ~4 ~82 ~64 ~4 ~81 spruce_fence
fill ~66 ~4 ~94 ~70 ~4 ~94 planks 1
fill ~67 ~4 ~68 ~71 ~4 ~68 planks 5
fill ~71 ~4 ~85 ~79 ~4 ~85 log 1
fill ~71 ~4 ~86 ~71 ~4 ~94 log 1
fill ~72 ~4 ~86 ~78 ~4 ~86 planks 5
fill ~72 ~4 ~87 ~78 ~4 ~87 planks 5
fill ~72 ~4 ~88 ~78 ~4 ~88 planks 5
fill ~72 ~4 ~89 ~74 ~4 ~89 planks 5
fill ~72 ~4 ~90 ~78 ~4 ~90 planks 5
fill ~72 ~4 ~91 ~78 ~4 ~91 planks 5
fill ~72 ~4 ~92 ~78 ~4 ~92 planks 5
fill ~72 ~4 ~93 ~79 ~4 ~93 log 1
fill ~72 ~4 ~94 ~76 ~4 ~94 planks 1
fill ~73 ~4 ~68 ~77 ~4 ~68 planks 3
fill ~73 ~4 ~84 ~74 ~4 ~84 spruce_stairs 2
setblock ~75 ~4 ~89 glowstone
fill ~76 ~4 ~84 ~78 ~4 ~84 ladder 2
fill ~76 ~4 ~89 ~78 ~4 ~89 planks 5
fill ~78 ~4 ~94 ~82 ~4 ~94 hay_block
fill ~79 ~4 ~68 ~83 ~4 ~68 planks 1
fill ~79 ~4 ~86 ~79 ~4 ~93 log 1
fill ~80 ~4 ~89 ~80 ~4 ~90 spruce_stairs 1
fill ~80 ~4 ~93 ~80 ~5 ~93 trapdoor 12
fill ~84 ~4 ~94 ~88 ~4 ~94 planks 5
fill ~85 ~4 ~68 ~89 ~4 ~68 planks 5
fill ~87 ~4 ~92 ~87 ~4 ~93 spruce_fence
fill ~90 ~4 ~94 ~94 ~4 ~94 planks 3
fill ~91 ~4 ~68 ~95 ~4 ~68 planks 1
fill ~93 ~4 ~75 ~93 ~4 ~76 spruce_fence
fill ~94 ~4 ~76 ~95 ~4 ~76 spruce_fence
fill ~96 ~4 ~94 ~100 ~4 ~94 planks 1
fill ~97 ~4 ~68 ~101 ~4 ~68 planks 1
fill ~99 ~4 ~69 ~101 ~4 ~69 spruce_fence
fill ~99 ~4 ~86 ~99 ~9 ~86 spruce_fence
fill ~99 ~4 ~92 ~99 ~9 ~92 spruce_fence
fill ~100 ~4 ~86 ~100 ~9 ~86 log 5
fill ~100 ~4 ~87 ~101 ~4 ~87 planks 3
fill ~100 ~4 ~88 ~102 ~4 ~88 planks 3
fill ~100 ~4 ~89 ~102 ~4 ~89 planks 3
fill ~100 ~4 ~90 ~102 ~4 ~90 planks 3
fill ~100 ~4 ~91 ~102 ~4 ~91 planks 3
fill ~100 ~4 ~92 ~100 ~9 ~92 log 5
setblock ~101 ~4 ~70 spruce_fence
fill ~101 ~4 ~86 ~101 ~5 ~86 wool
fill ~101 ~4 ~92 ~101 ~5 ~92 wool
fill ~101 ~4 ~94 ~102 ~4 ~94 log 1
fill ~102 ~4 ~75 ~102 ~80 ~75 log 1
fill ~102 ~4 ~93 ~102 ~80 ~93 log 1
fill ~16 ~5 ~8 ~24 ~5 ~8 log 1
fill ~16 ~5 ~94 ~17 ~5 ~94 log 1
fill ~17 ~5 ~52 ~17 ~5 ~54 trapdoor 11
fill ~18 ~5 ~94 ~22 ~5 ~94 planks 5
setblock ~21 ~5 ~9 spruce_stairs 1
fill ~24 ~5 ~94 ~28 ~5 ~94 planks 3
fill ~25 ~5 ~8 ~28 ~5 ~8 planks 5
fill ~27 ~5 ~9 ~27 ~12 ~9 log 9
fill ~27 ~5 ~10 ~27 ~12 ~10 spruce_fence
fill ~28 ~5 ~9 ~35 ~5 ~9 planks 5
fill ~29 ~5 ~71 ~30 ~5 ~71 spruce_fence
fill ~30 ~5 ~8 ~34 ~5 ~8 planks 1
fill ~30 ~5 ~69 ~30 ~5 ~71 spruce_fence
fill ~30 ~5 ~94 ~34 ~5 ~94 planks 1
fill ~31 ~5 ~92 ~39 ~5 ~92 spruce_fence
fill ~31 ~5 ~93 ~39 ~5 ~93 log 9
fill ~34 ~5 ~47 ~36 ~5 ~47 spruce_fence
fill ~36 ~5 ~8 ~40 ~5 ~8 planks 5
fill ~36 ~5 ~9 ~36 ~8 ~9 log 9
fill ~36 ~5 ~10 ~36 ~8 ~10 spruce_fence
setblock ~36 ~5 ~48 spruce_fence
fill ~36 ~5 ~94 ~40 ~5 ~94 planks 5
fill ~41 ~5 ~8 ~42 ~5 ~8 log 1
setblock ~41 ~5 ~22 dark_oak_stairs 2
setblock ~41 ~5 ~23 dark_oak_stairs 7
fill ~42 ~5 ~19 ~42 ~12 ~19 log 1
fill ~42 ~5 ~21 ~42 ~5 ~26 log 1
fill ~42 ~5 ~92 ~42 ~5 ~93 spruce_fence
fill ~42 ~5 ~94 ~46 ~5 ~94 planks 5
fill ~43 ~5 ~68 ~47 ~5 ~68 planks 5
fill ~48 ~5 ~94 ~52 ~5 ~94 planks 3
fill ~49 ~5 ~68 ~52 ~5 ~68 planks 3
fill ~53 ~5 ~68 ~53 ~6 ~68 log 1
fill ~54 ~5 ~94 ~58 ~5 ~94 planks 1
fill ~55 ~5 ~68 ~60 ~5 ~68 log 1
setblock ~58 ~5 ~69 dark_oak_stairs 4
setblock ~59 ~5 ~69 dark_oak_stairs 1
fill ~60 ~5 ~94 ~64 ~5 ~94 planks 5
fill ~61 ~5 ~68 ~65 ~5 ~68 planks 5
fill ~66 ~5 ~94 ~70 ~5 ~94 planks 1
fill ~67 ~5 ~68 ~71 ~5 ~68 planks 5
fill ~71 ~5 ~85 ~72 ~5 ~85 spruce_fence
fill ~71 ~5 ~86 ~71 ~5 ~87 spruce_fence
setblock ~72 ~5 ~92 dark_oak_stairs 4
fill ~72 ~5 ~94 ~76 ~5 ~94 planks 1
fill ~73 ~5 ~68 ~77 ~5 ~68 planks 3
setblock ~73 ~5 ~92 dark_oak_stairs 1
fill ~78 ~5 ~94 ~82 ~5 ~94 hay_block
fill ~79 ~5 ~68 ~83 ~5 ~68 planks 1
fill ~84 ~5 ~94 ~88 ~5 ~94 planks 5
fill ~85 ~5 ~68 ~89 ~5 ~68 planks 5
fill ~90 ~5 ~94 ~94 ~5 ~94 planks 3
fill ~91 ~5 ~68 ~95 ~5 ~68 planks 1
fill ~96 ~5 ~94 ~100 ~5 ~94 planks 1
fill ~97 ~5 ~68 ~101 ~5 ~68 planks 1
fill ~100 ~5 ~87 ~101 ~5 ~87 planks 3
fill ~100 ~5 ~88 ~102 ~5 ~88 planks 3
fill ~100 ~5 ~89 ~102 ~5 ~89 planks 3
fill ~100 ~5 ~90 ~102 ~5 ~90 planks 3
fill ~100 ~5 ~91 ~102 ~5 ~91 planks 3
fill ~101 ~5 ~94 ~102 ~5 ~94 log 1
fill ~16 ~6 ~8 ~17 ~6 ~8 log 1
fill ~16 ~6 ~10 ~16 ~6 ~94 log 1
fill ~17 ~6 ~9 ~17 ~7 ~9 ladder 3
fill ~17 ~6 ~11 ~17 ~14 ~11 log 5
fill ~17 ~6 ~12 ~17 ~6 ~19 log 5
fill ~17 ~6 ~28 ~17 ~17 ~28 log 5
fill ~17 ~6 ~29 ~17 ~6 ~32 log 5
fill ~17 ~6 ~51 ~18 ~6 ~51 log 5
fill ~17 ~6 ~52 ~17 ~6 ~54 glowstone
fill ~17 ~6 ~55 ~18 ~6 ~55 log 5
fill ~17 ~6 ~56 ~17 ~6 ~57 wool
fill ~17 ~6 ~58 ~18 ~6 ~58 log 5
fill ~17 ~6 ~59 ~17 ~6 ~60 wool
fill ~17 ~6 ~61 ~18 ~6 ~61 log 5
fill ~17 ~6 ~94 ~102 ~6 ~94 log 1
fill ~18 ~6 ~11 ~18 ~14 ~11 spruce_fence
fill ~18 ~6 ~12 ~18 ~6 ~19 spruce_fence
fill ~18 ~6 ~28 ~18 ~17 ~28 spruce_fence
fill ~18 ~6 ~29 ~18 ~6 ~32 spruce_fence
fill ~18 ~6 ~52 ~18 ~6 ~61 log 5
setblock ~18 ~6 ~84 trapdoor 8
fill ~19 ~6 ~51 ~19 ~17 ~51 spruce_fence
fill ~19 ~6 ~52 ~19 ~6 ~61 spruce_fence
fill ~24 ~6 ~8 ~42 ~6 ~8 log 1
fill ~24 ~6 ~9 ~24 ~7 ~9 ladder 3
fill ~28 ~6 ~9 ~33 ~6 ~9 planks 5
fill ~31 ~6 ~92 ~31 ~15 ~92 spruce_fence
fill ~31 ~6 ~93 ~31 ~15 ~93 log 9
fill ~32 ~6 ~93 ~38 ~6 ~93 planks 1
setblock ~34 ~6 ~9 glowstone
fill ~35 ~6 ~9 ~35 ~7 ~9 planks 5
fill ~39 ~6 ~26 ~39 ~12 ~26 spruce_fence
fill ~39 ~6 ~27 ~39 ~6 ~32 spruce_fence
fill ~39 ~6 ~92 ~39 ~11 ~92 spruce_fence
fill ~39 ~6 ~93 ~39 ~12 ~93 log 9
fill ~40 ~6 ~26 ~41 ~6 ~26 log 5
fill ~40 ~6 ~27 ~40 ~6 ~32 log 5
fill ~41 ~6 ~19 ~41 ~7 ~19 ladder 4
fill ~41 ~6 ~27 ~41 ~6 ~31 hay_block 4
setblock ~41 ~6 ~32 log 5
fill ~41 ~6 ~58 ~41 ~6 ~60 trapdoor 10
fill ~42 ~6 ~9 ~42 ~6 ~19 log 1
fill ~42 ~6 ~27 ~42 ~6 ~68 log 1
fill ~43 ~6 ~68 ~47 ~6 ~68 planks 5
fill ~49 ~6 ~68 ~53 ~6 ~68 log 1
fill ~60 ~6 ~69 ~60 ~7 ~69 ladder 3
fill ~61 ~6 ~68 ~78 ~6 ~68 log 1
setblock ~71 ~6 ~92 dark_oak_stairs 4
setblock ~72 ~6 ~92 dark_oak_stairs 1
fill ~79 ~6 ~68 ~83 ~6 ~68 planks 1
fill ~85 ~6 ~68 ~102 ~6 ~68 log 1
fill ~100 ~6 ~71 ~100 ~17 ~71 spruce_fence
fill ~100 ~6 ~72 ~100 ~6 ~81 spruce_fence
fill ~100 ~6 ~87 ~101 ~6 ~87 planks 3
fill ~100 ~6 ~88 ~101 ~6 ~88 planks 3
setblock ~100 ~6 ~89 glowstone
fill ~100 ~6 ~90 ~101 ~6 ~90 planks 3
fill ~100 ~6 ~91 ~101 ~6 ~91 planks 3
fill ~101 ~6 ~71 ~101 ~17 ~71 log 5
fill ~101 ~6 ~72 ~101 ~6 ~81 log 5
setblock ~101 ~6 ~86 log 5
fill ~101 ~6 ~89 ~101 ~8 ~89 planks 3
setblock ~101 ~6 ~92 log 5
fill ~102 ~6 ~70 ~102 ~6 ~94 log 1
fill ~16 ~7 ~8 ~17 ~7 ~8 log 1
fill ~16 ~7 ~10 ~16 ~11 ~10 planks 1
fill ~16 ~7 ~11 ~16 ~11 ~11 planks 1
fill ~16 ~7 ~12 ~16 ~11 ~12 planks 1
fill ~16 ~7 ~13 ~16 ~11 ~13 planks 1
fill ~16 ~7 ~14 ~16 ~11 ~14 planks 1
fill ~16 ~7 ~16 ~17 ~7 ~16 planks 5
fill ~16 ~7 ~17 ~17 ~7 ~17 planks 5
fill ~16 ~7 ~18 ~17 ~7 ~18 planks 5
fill ~16 ~7 ~19 ~16 ~11 ~19 planks 5
fill ~16 ~7 ~20 ~16 ~11 ~20 planks 5
fill ~16 ~7 ~22 ~16 ~11 ~22 planks 1
fill ~16 ~7 ~23 ~16 ~11 ~23 planks 1
fill ~16 ~7 ~24 ~16 ~11 ~24 planks 1
fill ~16 ~7 ~25 ~16 ~11 ~25 planks 1
fill ~16 ~7 ~26 ~16 ~11 ~26 planks 1
fill ~16 ~7 ~28 ~16 ~11 ~28 planks 5
fill ~16 ~7 ~29 ~17 ~7 ~29 planks 5
fill ~16 ~7 ~30 ~17 ~7 ~30 planks 5
fill ~16 ~7 ~31 ~17 ~7 ~31 planks 5
fill ~16 ~7 ~32 ~16 ~11 ~32 planks 5
fill ~16 ~7 ~34 ~16 ~11 ~34 planks 3
fill ~16 ~7 ~35 ~16 ~11 ~35 planks 3
fill ~16 ~7 ~36 ~16 ~11 ~36 planks 3
fill ~16 ~7 ~37 ~16 ~11 ~37 planks 3
fill ~16 ~7 ~38 ~16 ~11 ~38 planks 3
fill ~16 ~7 ~40 ~16 ~11 ~40 planks 5
fill ~16 ~7 ~41 ~16 ~11 ~41 planks 5
fill ~16 ~7 ~42 ~16 ~11 ~42 planks 5
fill ~16 ~7 ~43 ~16 ~11 ~43 planks 5
fill ~16 ~7 ~44 ~16 ~11 ~44 planks 5
fill ~16 ~7 ~46 ~16 ~11 ~46 planks 1
fill ~16 ~7 ~47 ~16 ~11 ~47 planks 1
fill ~16 ~7 ~48 ~16 ~11 ~48 planks 1
fill ~16 ~7 ~49 ~16 ~11 ~49 planks 1
fill ~16 ~7 ~50 ~16 ~11 ~50 planks 1
fill ~16 ~7 ~52 ~16 ~11 ~52 planks 1
fill ~16 ~7 ~53 ~16 ~11 ~53 planks 1
fill ~16 ~7 ~54 ~16 ~11 ~54 planks 1
fill ~16 ~7 ~55 ~16 ~11 ~55 planks 1
fill ~16 ~7 ~56 ~16 ~11 ~56 planks 1
fill ~16 ~7 ~58 ~18 ~7 ~58 planks 5
fill ~16 ~7 ~59 ~18 ~7 ~59 planks 5
fill ~16 ~7 ~60 ~18 ~7 ~60 planks 5
fill ~16 ~7 ~61 ~16 ~11 ~61 planks 5
fill ~16 ~7 ~62 ~16 ~13 ~62 log 1
fill ~16 ~7 ~70 ~16 ~11 ~70 planks 5
fill ~16 ~7 ~71 ~16 ~11 ~71 planks 5
fill ~16 ~7 ~72 ~16 ~11 ~72 planks 5
fill ~16 ~7 ~73 ~16 ~11 ~73 planks 5
fill ~16 ~7 ~74 ~16 ~11 ~74 planks 5
fill ~16 ~7 ~76 ~16 ~11 ~76 planks 1
fill ~16 ~7 ~77 ~16 ~11 ~77 planks 1
fill ~16 ~7 ~78 ~16 ~11 ~78 planks 1
fill ~16 ~7 ~79 ~16 ~11 ~79 planks 1
fill ~16 ~7 ~80 ~16 ~11 ~80 planks 1
fill ~16 ~7 ~82 ~16 ~8 ~82 bookshelf
fill ~16 ~7 ~83 ~16 ~8 ~83 bookshelf
fill ~16 ~7 ~84 ~16 ~8 ~84 bookshelf
fill ~16 ~7 ~85 ~16 ~8 ~85 bookshelf
fill ~16 ~7 ~86 ~16 ~8 ~86 bookshelf
fill ~16 ~7 ~88 ~16 ~11 ~88 hay_block
fill ~16 ~7 ~89 ~16 ~11 ~89 hay_block
fill ~16 ~7 ~90 ~16 ~11 ~90 hay_block
fill ~16 ~7 ~91 ~16 ~11 ~91 hay_block
fill ~16 ~7 ~92 ~16 ~11 ~92 hay_block
fill ~16 ~7 ~94 ~17 ~7 ~94 log 1
fill ~17 ~7 ~12 ~17 ~13 ~12 planks 5
fill ~17 ~7 ~13 ~17 ~11 ~13 planks 5
fill ~17 ~7 ~14 ~17 ~13 ~14 planks 5
fill ~17 ~7 ~15 ~17 ~9 ~15 planks 5
fill ~17 ~7 ~19 ~17 ~10 ~19 log 5
fill ~17 ~7 ~32 ~17 ~11 ~32 log 5
fill ~17 ~7 ~51 ~17 ~8 ~51 wool
fill ~17 ~7 ~52 ~18 ~7 ~52 planks 5
fill ~17 ~7 ~53 ~18 ~7 ~53 planks 5
fill ~17 ~7 ~54 ~18 ~7 ~54 planks 5
fill ~17 ~7 ~55 ~18 ~7 ~55 planks 5
fill ~17 ~7 ~56 ~18 ~7 ~56 planks 5
fill ~17 ~7 ~57 ~18 ~7 ~57 planks 5
fill ~17 ~7 ~61 ~17 ~8 ~61 wool
fill ~17 ~7 ~62 ~17 ~8 ~62 ladder 5
fill ~17 ~7 ~69 ~17 ~8 ~69 ladder 5
fill ~17 ~7 ~70 ~17 ~11 ~70 log 5
fill ~17 ~7 ~71 ~17 ~7 ~74 log 5
setblock ~17 ~7 ~84 trapdoor 6
fill ~17 ~7 ~90 ~17 ~11 ~90 trapdoor 15
fill ~18 ~7 ~19 ~18 ~10 ~19 spruce_fence
fill ~18 ~7 ~32 ~18 ~11 ~32 spruce_fence
fill ~18 ~7 ~51 ~18 ~17 ~51 log 5
fill ~18 ~7 ~61 ~18 ~12 ~61 log 5
fill ~18 ~7 ~70 ~18 ~11 ~70 spruce_fence
fill ~18 ~7 ~71 ~18 ~7 ~74 spruce_fence
setblock ~18 ~7 ~83 trapdoor 4
setblock ~18 ~7 ~84 glowstone
setblock ~18 ~7 ~85 trapdoor 5
fill ~18 ~7 ~94 ~22 ~7 ~94 planks 1
fill ~19 ~7 ~61 ~19 ~12 ~61 spruce_fence
setblock ~19 ~7 ~84 trapdoor 7
fill ~24 ~7 ~8 ~24 ~12 ~8 log 1
fill ~24 ~7 ~94 ~28 ~7 ~94 planks 5
fill ~25 ~7 ~8 ~28 ~7 ~8 hay_block
fill ~26 ~7 ~9 ~26 ~9 ~9 trapdoor 5
fill ~28 ~7 ~9 ~35 ~7 ~9 planks 5
fill ~30 ~7 ~8 ~34 ~7 ~8 planks 3
fill ~30 ~7 ~94 ~34 ~7 ~94 planks 1
fill ~32 ~7 ~93 ~38 ~7 ~93 planks 1
fill ~36 ~7 ~8 ~40 ~7 ~8 planks 1
fill ~36 ~7 ~94 ~40 ~7 ~94 planks 5
fill ~39 ~7 ~32 ~39 ~9 ~32 spruce_fence
setblock ~39 ~7 ~37 trapdoor 10
