   
setblock ~36 ~61 ~21 sponge 0 
setblock ~35 ~78 ~37 wool 8  
fill ~35 ~78 ~38 ~36 ~78 ~38 stone 0 
setblock ~35 ~78 ~39 stone 5 
setblock ~35 ~78 ~40 double_stone_slab 8 
setblock ~35 ~78 ~41 wool 8 
setblock ~35 ~78 ~42 double_stone_slab 8 
setblock ~35 ~78 ~43 wool 8 
setblock ~36 ~78 ~36 wool 8  
fill ~36 ~78 ~37 ~37 ~78 ~37 concrete 8  
fill ~36 ~78 ~39 ~38 ~78 ~39 double_stone_slab 8  
fill ~36 ~78 ~40 ~36 ~78 ~41 clay 0  
fill ~36 ~78 ~42 ~37 ~78 ~42 wool 8  
fill ~36 ~78 ~43 ~36 ~78 ~44 double_stone_slab 8  
fill ~37 ~78 ~35 ~38 ~78 ~35 concrete 8 
setblock ~37 ~78 ~36 double_stone_slab 8 
setblock ~37 ~78 ~38 wool 8  
fill ~37 ~78 ~40 ~39 ~78 ~40 double_stone_slab 8  
fill ~37 ~78 ~41 ~37 ~78 ~39 double_stone_slab 8 
setblock ~37 ~78 ~43 coal_ore 0 
setblock ~37 ~78 ~44 double_stone_slab 8 
setblock ~37 ~78 ~45 wool 8 
setblock ~38 ~78 ~36 clay 0  
fill ~38 ~78 ~37 ~40 ~78 ~37 wool 8 
setblock ~38 ~78 ~38 stone 0 
setblock ~38 ~78 ~41 stone 5 
setblock ~38 ~78 ~42 stone 0 
setblock ~38 ~78 ~43 double_stone_slab 8 
setblock ~38 ~78 ~44 clay 0 
setblock ~38 ~78 ~45 concrete 8  
fill ~39 ~78 ~35 ~39 ~78 ~36 stone 5 
setblock ~39 ~78 ~38 double_stone_slab 8 
setblock ~39 ~78 ~39 stone 0  
fill ~39 ~78 ~41 ~40 ~78 ~41 wool 8 
setblock ~39 ~78 ~42 double_stone_slab 8 
setblock ~39 ~78 ~43 stone 3 
setblock ~39 ~78 ~44 stone 0 
setblock ~39 ~78 ~45 coal_ore 0 
setblock ~40 ~78 ~35 stone 0 
setblock ~40 ~78 ~36 double_stone_slab 8 
setblock ~40 ~78 ~38 stone 5 
setblock ~40 ~78 ~39 concrete 8 
setblock ~40 ~78 ~40 stone 0 
setblock ~40 ~78 ~42 wool 8 
setblock ~40 ~78 ~43 stone 0 
setblock ~40 ~78 ~44 concrete 8  
fill ~40 ~78 ~45 ~41 ~78 ~45 clay 0  
fill ~41 ~78 ~35 ~42 ~78 ~35 double_stone_slab 8 
setblock ~41 ~78 ~36 clay 0  
fill ~41 ~78 ~37 ~42 ~78 ~37 double_stone_slab 8 
setblock ~41 ~78 ~38 wool 8 
setblock ~41 ~78 ~39 double_stone_slab 8  
fill ~41 ~78 ~40 ~42 ~78 ~40 stone 3 
setblock ~41 ~78 ~41 concrete 8 
setblock ~41 ~78 ~42 stone 5  
fill ~41 ~78 ~43 ~41 ~78 ~44 stone 3 
setblock ~42 ~78 ~36 stone 0  
fill ~42 ~78 ~38 ~43 ~78 ~38 double_stone_slab 8 
setblock ~42 ~78 ~39 stone 3 
setblock ~42 ~78 ~41 stone 0 
setblock ~42 ~78 ~42 coal_ore 0 
setblock ~42 ~78 ~43 stone 0  
fill ~42 ~78 ~44 ~43 ~78 ~44 wool 8 
setblock ~42 ~78 ~45 stone 0 
setblock ~43 ~78 ~35 stone 5 
setblock ~43 ~78 ~36 stone 3 
setblock ~43 ~78 ~37 stonebrick 2  
fill ~43 ~78 ~39 ~44 ~78 ~39 wool 8 
setblock ~43 ~78 ~40 clay 0 
setblock ~43 ~78 ~41 stained_hardened_clay 9 
setblock ~43 ~78 ~42 clay 0 
setblock ~43 ~78 ~43 coal_ore 0 
setblock ~43 ~78 ~45 stained_hardened_clay 9 
setblock ~44 ~78 ~36 clay 0 
setblock ~44 ~78 ~37 stone 5 
setblock ~44 ~78 ~38 stone 0 
setblock ~44 ~78 ~40 concrete 8 
setblock ~44 ~78 ~41 wool 8  
fill ~44 ~78 ~42 ~44 ~78 ~43 stone 3 
setblock ~44 ~78 ~44 double_stone_slab 8 
setblock ~45 ~78 ~37 stone 0 
setblock ~45 ~78 ~38 coal_ore 0 
setblock ~45 ~78 ~39 stone 5 
setblock ~45 ~78 ~40 double_stone_slab 8 
setblock ~45 ~78 ~41 clay 0 
setblock ~45 ~78 ~42 double_stone_slab 8 
setblock ~45 ~78 ~43 wool 8 
setblock ~30 ~79 ~37 stone 5 
setblock ~30 ~79 ~38 coal_ore 0  
fill ~30 ~79 ~39 ~30 ~79 ~40 wool 8 
setblock ~30 ~79 ~41 concrete 8  
fill ~30 ~79 ~42 ~31 ~79 ~42 stone 0 
setblock ~30 ~79 ~43 concrete 8 
setblock ~31 ~79 ~35 clay 0 
setblock ~31 ~79 ~36 wool 8  
fill ~31 ~79 ~37 ~31 ~79 ~38 double_stone_slab 8 
setblock ~31 ~79 ~39 coal_ore 0 
setblock ~31 ~79 ~40 wool 8  
fill ~31 ~79 ~41 ~33 ~79 ~41 stone 0 
setblock ~31 ~79 ~43 wool 8 
setblock ~31 ~79 ~44 concrete 8  
fill ~31 ~79 ~45 ~32 ~79 ~45 coal_ore 0 
setblock ~32 ~79 ~33 stonebrick 2 
setblock ~32 ~79 ~34 double_stone_slab 8 
setblock ~32 ~79 ~35 wool 8 
setblock ~32 ~79 ~36 stone 3 
setblock ~32 ~79 ~37 stone 0 
setblock ~32 ~79 ~38 wool 8 
setblock ~32 ~79 ~39 concrete 8 
setblock ~32 ~79 ~40 double_stone_slab 8 
setblock ~32 ~79 ~42 stonebrick 2 
setblock ~32 ~79 ~43 stone 5 
setblock ~32 ~79 ~44 coal_ore 0 
setblock ~32 ~79 ~46 stonebrick 2 
setblock ~32 ~79 ~47 stained_hardened_clay 9  
fill ~33 ~79 ~32 ~34 ~79 ~32 concrete 8 
setblock ~33 ~79 ~33 stone 0 
setblock ~33 ~79 ~34 stained_hardened_clay 9 
setblock ~33 ~79 ~35 concrete 8 
setblock ~33 ~79 ~36 double_stone_slab 8 
setblock ~33 ~79 ~37 concrete 8  
fill ~33 ~79 ~38 ~34 ~79 ~38 clay 0 
setblock ~33 ~79 ~39 stone 0  
fill ~33 ~79 ~40 ~34 ~79 ~40 clay 0  
fill ~33 ~79 ~42 ~34 ~79 ~42 stained_hardened_clay 9 
setblock ~33 ~79 ~43 coal_ore 0 
setblock ~33 ~79 ~44 wool 8 
setblock ~33 ~79 ~45 double_stone_slab 8 
setblock ~33 ~79 ~46 stained_hardened_clay 9 
setblock ~33 ~79 ~47 double_stone_slab 8  
fill ~33 ~79 ~48 ~34 ~79 ~48 stained_hardened_clay 9 
setblock ~34 ~79 ~33 stained_hardened_clay 9 
setblock ~34 ~79 ~34 concrete 8  
fill ~34 ~79 ~35 ~35 ~79 ~35 wool 8 
setblock ~34 ~79 ~36 concrete 8 
setblock ~34 ~79 ~37 clay 0 
setblock ~34 ~79 ~39 double_stone_slab 8 
setblock ~34 ~79 ~41 concrete 8 
setblock ~34 ~79 ~43 stonebrick 2  
fill ~34 ~79 ~44 ~34 ~79 ~45 concrete 8 
setblock ~34 ~79 ~46 wool 8 
setblock ~34 ~79 ~47 concrete 8  
fill ~35 ~79 ~31 ~36 ~79 ~31 coal_ore 0  
fill ~35 ~79 ~32 ~35 ~79 ~31 coal_ore 0 
setblock ~35 ~79 ~33 concrete 8  
fill ~35 ~79 ~34 ~36 ~79 ~34 stone 0 
setblock ~35 ~79 ~36 stonebrick 2  
fill ~35 ~79 ~44 ~35 ~79 ~45 wool 8 
setblock ~35 ~79 ~46 concrete 8 
setblock ~35 ~79 ~47 stone 0 
setblock ~35 ~79 ~48 double_stone_slab 8 
setblock ~35 ~79 ~49 stained_hardened_clay 9 
setblock ~36 ~79 ~32 stonebrick 2 
setblock ~36 ~79 ~33 wool 8 
setblock ~36 ~79 ~35 concrete 8 
setblock ~36 ~79 ~45 stone 3 
setblock ~36 ~79 ~46 wool 8 
setblock ~36 ~79 ~47 coal_ore 0 
setblock ~36 ~79 ~48 wool 8 
setblock ~36 ~79 ~49 coal_ore 0 
setblock ~37 ~79 ~30 double_stone_slab 8 
setblock ~37 ~79 ~31 wool 8  
fill ~37 ~79 ~32 ~39 ~79 ~32 double_stone_slab 8 
setblock ~37 ~79 ~33 concrete 8 
setblock ~37 ~79 ~34 double_stone_slab 8  
fill ~37 ~79 ~46 ~37 ~79 ~48 concrete 8 
setblock ~37 ~79 ~49 stone 0 
setblock ~37 ~79 ~50 wool 8 
setblock ~38 ~79 ~30 stone 4  
fill ~38 ~79 ~31 ~39 ~79 ~31 double_stone_slab 8 
setblock ~38 ~79 ~33 wool 8 
setblock ~38 ~79 ~34 stone 0  
fill ~38 ~79 ~46 ~39 ~79 ~46 stone 0 
setblock ~38 ~79 ~47 double_stone_slab 8 
setblock ~38 ~79 ~48 wool 8 
setblock ~38 ~79 ~49 concrete 8 
setblock ~38 ~79 ~50 stone 0 
setblock ~39 ~79 ~30 clay 0 
setblock ~39 ~79 ~33 stone 0 
setblock ~39 ~79 ~34 wool 8 
setblock ~39 ~79 ~47 stone 0  
fill ~39 ~79 ~48 ~39 ~79 ~49 double_stone_slab 8 
setblock ~39 ~79 ~50 stone 5 
setblock ~40 ~79 ~30 stonebrick 2 
setblock ~40 ~79 ~31 stone 0  
fill ~40 ~79 ~32 ~40 ~79 ~33 wool 8 
setblock ~40 ~79 ~34 double_stone_slab 8 
setblock ~40 ~79 ~46 clay 0 
setblock ~40 ~79 ~47 wool 8 
setblock ~40 ~79 ~48 stone 5  
fill ~40 ~79 ~49 ~40 ~79 ~50 stone 0 
setblock ~41 ~79 ~30 coal_ore 0 
setblock ~41 ~79 ~31 wool 8 
setblock ~41 ~79 ~32 double_stone_slab 8 
setblock ~41 ~79 ~33 stone 5 
setblock ~41 ~79 ~34 stone 0  
fill ~41 ~79 ~46 ~42 ~79 ~46 wool 8 
setblock ~41 ~79 ~47 stone 0 
setblock ~41 ~79 ~48 wool 8  
fill ~41 ~79 ~49 ~43 ~79 ~49 double_stone_slab 8 
setblock ~41 ~79 ~50 clay 0 
setblock ~42 ~79 ~30 concrete 8 
setblock ~42 ~79 ~31 stone 0  
fill ~42 ~79 ~32 ~42 ~79 ~33 wool 8 
setblock ~42 ~79 ~34 double_stone_slab 8 
setblock ~42 ~79 ~47 wool 8 
setblock ~42 ~79 ~48 double_stone_slab 8 
setblock ~42 ~79 ~50 stone 5  
fill ~43 ~79 ~30 ~43 ~79 ~31 wool 8 
setblock ~43 ~79 ~32 stone 0  
fill ~43 ~79 ~33 ~43 ~79 ~34 wool 8  
fill ~43 ~79 ~46 ~44 ~79 ~46 concrete 8  
fill ~43 ~79 ~47 ~44 ~79 ~47 double_stone_slab 8 
setblock ~43 ~79 ~48 concrete 8 
setblock ~43 ~79 ~50 wool 8 
setblock ~44 ~79 ~31 stone 0  
fill ~44 ~79 ~32 ~44 ~79 ~33 double_stone_slab 8 
setblock ~44 ~79 ~34 clay 0 
setblock ~44 ~79 ~35 double_stone_slab 8 
setblock ~44 ~79 ~45 clay 0 
setblock ~44 ~79 ~48 double_stone_slab 8 
setblock ~44 ~79 ~49 concrete 8 
setblock ~45 ~79 ~31 wool 8 
setblock ~45 ~79 ~32 concrete 8  
fill ~45 ~79 ~33 ~46 ~79 ~33 clay 0 
setblock ~45 ~79 ~34 stone 3 
setblock ~45 ~79 ~35 stone 4 
setblock ~45 ~79 ~36 wool 8 
setblock ~45 ~79 ~44 wool 8 
setblock ~45 ~79 ~45 double_stone_slab 8 
setblock ~45 ~79 ~46 wool 8 
setblock ~45 ~79 ~47 coal_ore 0  
fill ~45 ~79 ~48 ~46 ~79 ~48 clay 0  
fill ~45 ~79 ~49 ~45 ~79 ~48 clay 0 
setblock ~46 ~79 ~32 stained_hardened_clay 9 
setblock ~46 ~79 ~34 double_stone_slab 8 
setblock ~46 ~79 ~35 stone 5 
setblock ~46 ~79 ~36 stonebrick 2 
setblock ~46 ~79 ~37 stone 3  
fill ~46 ~79 ~38 ~46 ~79 ~39 wool 8 
setblock ~46 ~79 ~40 stone 3 
setblock ~46 ~79 ~41 clay 0 
setblock ~46 ~79 ~42 coal_ore 0  
fill ~46 ~79 ~43 ~47 ~79 ~43 clay 0 
setblock ~46 ~79 ~44 concrete 8 
setblock ~46 ~79 ~45 clay 0 
setblock ~46 ~79 ~46 double_stone_slab 8 
setblock ~46 ~79 ~47 clay 0 
setblock ~47 ~79 ~32 concrete 8 
setblock ~47 ~79 ~33 stone 0 
setblock ~47 ~79 ~34 clay 0 
setblock ~47 ~79 ~35 wool 8 
setblock ~47 ~79 ~36 double_stone_slab 8 
setblock ~47 ~79 ~37 stone 0  
fill ~47 ~79 ~38 ~48 ~79 ~38 double_stone_slab 8  
fill ~47 ~79 ~39 ~47 ~79 ~40 stone 0 
setblock ~47 ~79 ~41 stone 5 
setblock ~47 ~79 ~42 double_stone_slab 8  
fill ~47 ~79 ~44 ~48 ~79 ~44 wool 8 
setblock ~47 ~79 ~45 stone 0 
setblock ~47 ~79 ~46 wool 8 
setblock ~47 ~79 ~47 stone 3 
setblock ~47 ~79 ~48 wool 8 
setblock ~48 ~79 ~33 double_stone_slab 8 
setblock ~48 ~79 ~34 stone 0  
fill ~48 ~79 ~35 ~49 ~79 ~35 clay 0 
setblock ~48 ~79 ~36 stone 5 
setblock ~48 ~79 ~37 double_stone_slab 8  
fill ~48 ~79 ~39 ~48 ~79 ~40 double_stone_slab 8 
setblock ~48 ~79 ~41 coal_ore 0 
setblock ~48 ~79 ~42 stone 3 
setblock ~48 ~79 ~43 concrete 8 
setblock ~48 ~79 ~45 wool 8  
fill ~48 ~79 ~46 ~48 ~79 ~47 stone 0 
setblock ~49 ~79 ~36 concrete 8 
setblock ~49 ~79 ~37 stone 3  
fill ~49 ~79 ~38 ~49 ~79 ~39 clay 0 
setblock ~49 ~79 ~40 double_stone_slab 8 
setblock ~49 ~79 ~41 stone 0  
fill ~49 ~79 ~42 ~50 ~79 ~42 clay 0 
setblock ~49 ~79 ~43 wool 8 
setblock ~49 ~79 ~44 clay 0 
setblock ~49 ~79 ~45 double_stone_slab 8 
setblock ~50 ~79 ~37 clay 0 
setblock ~50 ~79 ~38 stone 4 
setblock ~50 ~79 ~39 stone 3 
setblock ~50 ~79 ~40 stonebrick 2 
setblock ~50 ~79 ~41 wool 8 
setblock ~50 ~79 ~43 double_stone_slab 8 
setblock ~27 ~80 ~36 clay 0  
fill ~27 ~80 ~37 ~29 ~80 ~37 stone 0 
setblock ~27 ~80 ~38 concrete 8 
setblock ~27 ~80 ~39 stonebrick 2  
fill ~27 ~80 ~40 ~28 ~80 ~40 concrete 8 
setblock ~27 ~80 ~41 concrete 7 
setblock ~27 ~80 ~42 stained_hardened_clay 9 
setblock ~27 ~80 ~43 stonebrick 2 
setblock ~27 ~80 ~44 concrete 8 
setblock ~28 ~80 ~34 stone 0 
setblock ~28 ~80 ~35 double_stone_slab 8 
setblock ~28 ~80 ~36 stone 0 
setblock ~28 ~80 ~38 wool 8 
setblock ~28 ~80 ~39 coal_ore 0 
setblock ~28 ~80 ~41 wool 7  
fill ~28 ~80 ~42 ~29 ~80 ~42 coal_ore 0 
setblock ~28 ~80 ~43 stone 5 
setblock ~28 ~80 ~44 wool 7 
setblock ~28 ~80 ~45 stone 5  
fill ~28 ~80 ~46 ~29 ~80 ~46 coal_ore 0 
setblock ~29 ~80 ~32 stone 0 
setblock ~29 ~80 ~33 double_stone_slab 8 
setblock ~29 ~80 ~34 wool 8 
setblock ~29 ~80 ~35 concrete 8 
setblock ~29 ~80 ~36 stone 5 
setblock ~29 ~80 ~38 stone 5 
setblock ~29 ~80 ~39 stained_hardened_clay 9 
setblock ~29 ~80 ~40 coal_ore 0 
setblock ~29 ~80 ~41 stained_hardened_clay 9 
setblock ~29 ~80 ~43 stone 0 
setblock ~29 ~80 ~44 coal_ore 0 
setblock ~29 ~80 ~45 concrete 8 
setblock ~29 ~80 ~47 stained_hardened_clay 9 
setblock ~29 ~80 ~48 concrete 8 
setblock ~30 ~80 ~31 coal_ore 0 
setblock ~30 ~80 ~32 concrete 8  
fill ~30 ~80 ~33 ~31 ~80 ~33 stone 0 
setblock ~30 ~80 ~34 double_stone_slab 8 
setblock ~30 ~80 ~35 wool 8 
setblock ~30 ~80 ~36 double_stone_slab 8 
setblock ~30 ~80 ~44 double_stone_slab 8 
setblock ~30 ~80 ~45 stonebrick 2  
fill ~30 ~80 ~46 ~31 ~80 ~46 stained_hardened_clay 9 
setblock ~30 ~80 ~47 concrete 8 
setblock ~30 ~80 ~48 stone 0 
setblock ~30 ~80 ~49 concrete 8 
setblock ~31 ~80 ~30 double_stone_slab 8  
fill ~31 ~80 ~31 ~31 ~80 ~32 stained_hardened_clay 9 
setblock ~31 ~80 ~34 coal_ore 0 
setblock ~31 ~80 ~47 wool 8  
fill ~31 ~80 ~48 ~32 ~80 ~48 concrete 8 
setblock ~31 ~80 ~49 stained_hardened_clay 9 
setblock ~31 ~80 ~50 coal_ore 0 
setblock ~32 ~80 ~29 wool 8  
fill ~32 ~80 ~30 ~32 ~80 ~31 stone 0 
setblock ~32 ~80 ~32 stonebrick 2 
setblock ~32 ~80 ~49 coal_ore 0  
fill ~32 ~80 ~50 ~33 ~80 ~50 concrete 8 
setblock ~32 ~80 ~51 double_stone_slab 8 
setblock ~33 ~80 ~29 double_stone_slab 8 
setblock ~33 ~80 ~30 stone 5  
fill ~33 ~80 ~31 ~34 ~80 ~31 concrete 8 
setblock ~33 ~80 ~49 stained_hardened_clay 9 
setblock ~33 ~80 ~51 stained_hardened_clay 9 
setblock ~34 ~80 ~28 double_stone_slab 8  
fill ~34 ~80 ~29 ~35 ~80 ~29 wool 8 
setblock ~34 ~80 ~30 double_stone_slab 8 
setblock ~34 ~80 ~49 clay 0 
setblock ~34 ~80 ~50 stone 5 
setblock ~34 ~80 ~51 wool 8 
setblock ~34 ~80 ~52 stained_hardened_clay 9 
setblock ~35 ~80 ~28 wool 8 
setblock ~35 ~80 ~30 stone 0 
setblock ~35 ~80 ~50 stone 0  
fill ~35 ~80 ~51 ~35 ~80 ~52 concrete 8  
fill ~36 ~80 ~27 ~36 ~80 ~29 double_stone_slab 8 
setblock ~36 ~80 ~30 wool 8 
setblock ~36 ~80 ~50 coal_ore 0 
setblock ~36 ~80 ~51 stone 0 
setblock ~36 ~80 ~52 concrete 8 
setblock ~36 ~80 ~53 coal_ore 0  
fill ~37 ~80 ~27 ~39 ~80 ~27 wool 8 
setblock ~37 ~80 ~28 double_stone_slab 8 
setblock ~37 ~80 ~29 clay 0 
setblock ~37 ~80 ~51 stone 5  
fill ~37 ~80 ~52 ~38 ~80 ~52 wool 8 
setblock ~37 ~80 ~53 concrete 8  
fill ~38 ~80 ~28 ~38 ~80 ~29 wool 8 
setblock ~38 ~80 ~51 wool 8 
setblock ~38 ~80 ~53 stone 0  
fill ~39 ~80 ~28 ~39 ~80 ~29 double_stone_slab 8  
fill ~39 ~80 ~51 ~40 ~80 ~51 clay 0  
fill ~39 ~80 ~52 ~40 ~80 ~52 double_stone_slab 8 
setblock ~39 ~80 ~53 clay 0  
fill ~40 ~80 ~27 ~40 ~80 ~29 concrete 8 
setblock ~40 ~80 ~53 wool 8  
fill ~41 ~80 ~27 ~41 ~80 ~29 double_stone_slab 8  
fill ~41 ~80 ~51 ~41 ~80 ~52 wool 8 
setblock ~41 ~80 ~53 stone 5 
setblock ~42 ~80 ~27 wool 8 
setblock ~42 ~80 ~28 concrete 8 
setblock ~42 ~80 ~29 stone 0 
setblock ~42 ~80 ~51 stone 5 
setblock ~42 ~80 ~52 concrete 8 
setblock ~42 ~80 ~53 stone 0 
setblock ~43 ~80 ~27 double_stone_slab 8 
setblock ~43 ~80 ~28 wool 8 
setblock ~43 ~80 ~29 concrete 8 
setblock ~43 ~80 ~51 wool 8 
setblock ~43 ~80 ~52 stone 0  
fill ~43 ~80 ~53 ~44 ~80 ~53 wool 8 
setblock ~44 ~80 ~27 stone 0 
setblock ~44 ~80 ~28 double_stone_slab 8 
setblock ~44 ~80 ~29 stone 5 
setblock ~44 ~80 ~30 wool 8  
fill ~44 ~80 ~50 ~44 ~80 ~51 clay 0  
fill ~44 ~80 ~52 ~45 ~80 ~52 wool 8 
setblock ~45 ~80 ~28 wool 8 
setblock ~45 ~80 ~29 stone 0 
setblock ~45 ~80 ~30 stone 3 
setblock ~45 ~80 ~50 stone 0  
fill ~45 ~80 ~51 ~47 ~80 ~51 double_stone_slab 8  
fill ~46 ~80 ~28 ~46 ~80 ~29 stone 5  
fill ~46 ~80 ~30 ~46 ~80 ~31 double_stone_slab 8  
fill ~46 ~80 ~49 ~49 ~80 ~49 double_stone_slab 8  
fill ~46 ~80 ~50 ~47 ~80 ~50 double_stone_slab 8 
setblock ~46 ~80 ~52 clay 0  
fill ~47 ~80 ~29 ~48 ~80 ~29 double_stone_slab 8 
setblock ~47 ~80 ~30 wool 8 
setblock ~47 ~80 ~31 stone 5 
setblock ~48 ~80 ~30 clay 0 
setblock ~48 ~80 ~31 wool 8  
fill ~48 ~80 ~32 ~50 ~80 ~32 double_stone_slab 8  
fill ~48 ~80 ~48 ~49 ~80 ~48 double_stone_slab 8  
fill ~48 ~80 ~50 ~48 ~80 ~51 clay 0 
setblock ~49 ~80 ~30 double_stone_slab 8 
setblock ~49 ~80 ~31 clay 0  
fill ~49 ~80 ~33 ~51 ~80 ~33 double_stone_slab 8 
setblock ~49 ~80 ~34 stone 3 
setblock ~49 ~80 ~46 stone 0 
setblock ~49 ~80 ~47 concrete 8 
setblock ~49 ~80 ~50 double_stone_slab 8 
setblock ~50 ~80 ~31 wool 8 
setblock ~50 ~80 ~34 wool 8 
setblock ~50 ~80 ~35 clay 0  
fill ~50 ~80 ~36 ~52 ~80 ~36 double_stone_slab 8 
setblock ~50 ~80 ~44 stone 3 
setblock ~50 ~80 ~45 clay 0  
fill ~50 ~80 ~46 ~52 ~80 ~46 wool 8  
fill ~50 ~80 ~47 ~50 ~80 ~48 wool 8 
setblock ~50 ~80 ~49 clay 0 
setblock ~51 ~80 ~32 wool 8  
fill ~51 ~80 ~34 ~51 ~80 ~36 double_stone_slab 8 
setblock ~51 ~80 ~37 wool 8 
setblock ~51 ~80 ~38 double_stone_slab 8  
fill ~51 ~80 ~39 ~52 ~80 ~39 clay 0  
fill ~51 ~80 ~40 ~52 ~80 ~40 double_stone_slab 8  
fill ~51 ~80 ~41 ~51 ~80 ~40 double_stone_slab 8 
setblock ~51 ~80 ~42 stone 5 
setblock ~51 ~80 ~43 wool 8 
setblock ~51 ~80 ~44 double_stone_slab 8 
setblock ~51 ~80 ~45 stone 0 
setblock ~51 ~80 ~47 double_stone_slab 8 
setblock ~51 ~80 ~48 clay 0 
setblock ~52 ~80 ~34 clay 0 
setblock ~52 ~80 ~35 double_stone_slab 8 
setblock ~52 ~80 ~37 stone 4  
fill ~52 ~80 ~38 ~53 ~80 ~38 clay 0 
setblock ~52 ~80 ~41 stone 0 
setblock ~52 ~80 ~42 concrete 8 
setblock ~52 ~80 ~43 double_stone_slab 8 
setblock ~52 ~80 ~44 clay 0 
setblock ~52 ~80 ~45 wool 8 
setblock ~53 ~80 ~36 clay 0 
setblock ~53 ~80 ~37 stone 3 
setblock ~53 ~80 ~39 double_stone_slab 8 
setblock ~53 ~80 ~40 clay 0 
setblock ~53 ~80 ~41 wool 8 
setblock ~53 ~80 ~42 double_stone_slab 8 
setblock ~53 ~80 ~43 clay 0 
setblock ~53 ~80 ~44 double_stone_slab 8  
fill ~24 ~81 ~39 ~26 ~81 ~39 stained_hardened_clay 9  
fill ~24 ~81 ~40 ~24 ~81 ~39 stained_hardened_clay 9 
setblock ~24 ~81 ~41 concrete 8 
setblock ~25 ~81 ~35 stone 0  
fill ~25 ~81 ~36 ~25 ~81 ~37 stonebrick 2 
setblock ~25 ~81 ~38 stone 0 
setblock ~25 ~81 ~40 stone 0  
fill ~25 ~81 ~41 ~25 ~81 ~42 coal_ore 0  
fill ~25 ~81 ~43 ~25 ~81 ~44 concrete 8 
setblock ~25 ~81 ~45 stonebrick 2 
setblock ~26 ~81 ~33 stone 0  
fill ~26 ~81 ~34 ~26 ~81 ~35 concrete 8  
fill ~26 ~81 ~36 ~26 ~81 ~37 stone 0 
setblock ~26 ~81 ~38 stonebrick 2 
setblock ~26 ~81 ~40 wool 8  
fill ~26 ~81 ~41 ~26 ~81 ~42 stained_hardened_clay 9  
fill ~26 ~81 ~43 ~26 ~81 ~45 coal_ore 0  
fill ~26 ~81 ~46 ~27 ~81 ~46 stained_hardened_clay 9  
fill ~26 ~81 ~47 ~26 ~81 ~46 stained_hardened_clay 9 
setblock ~27 ~81 ~31 concrete 8 
setblock ~27 ~81 ~32 stone 0 
setblock ~27 ~81 ~33 stone 5 
setblock ~27 ~81 ~34 stonebrick 2 
setblock ~27 ~81 ~35 clay 0 
setblock ~27 ~81 ~45 coal_ore 0 
setblock ~27 ~81 ~47 concrete 8  
fill ~27 ~81 ~48 ~28 ~81 ~48 stained_hardened_clay 9 
setblock ~27 ~81 ~49 stonebrick 2  
fill ~28 ~81 ~30 ~29 ~81 ~30 wool 8 
setblock ~28 ~81 ~31 clay 0 
setblock ~28 ~81 ~32 double_stone_slab 8 
setblock ~28 ~81 ~33 stained_hardened_clay 9 
setblock ~28 ~81 ~47 coal_ore 0 
setblock ~28 ~81 ~49 coal_ore 0 
setblock ~28 ~81 ~50 stone 5 
setblock ~29 ~81 ~29 stone 3 
setblock ~29 ~81 ~31 stonebrick 2 
setblock ~29 ~81 ~49 concrete 8 
setblock ~29 ~81 ~50 stonebrick 2 
setblock ~29 ~81 ~51 concrete 8 
setblock ~30 ~81 ~28 wool 8 
setblock ~30 ~81 ~29 double_stone_slab 8 
setblock ~30 ~81 ~30 concrete 8  
fill ~30 ~81 ~50 ~30 ~81 ~51 coal_ore 0 
setblock ~30 ~81 ~52 concrete 8 
setblock ~31 ~81 ~27 wool 8 
setblock ~31 ~81 ~28 clay 0 
setblock ~31 ~81 ~29 wool 8  
fill ~31 ~81 ~51 ~31 ~81 ~52 stone 0 
setblock ~31 ~81 ~53 coal_ore 0  
fill ~32 ~81 ~27 ~32 ~81 ~28 double_stone_slab 8  
fill ~32 ~81 ~52 ~32 ~81 ~53 concrete 8 
setblock ~33 ~81 ~26 double_stone_slab 8 
setblock ~33 ~81 ~27 stone 0 
setblock ~33 ~81 ~28 clay 0 
setblock ~33 ~81 ~52 wool 8 
setblock ~33 ~81 ~53 stone 5 
setblock ~33 ~81 ~54 wool 8  
fill ~34 ~81 ~26 ~35 ~81 ~26 wool 8 
setblock ~34 ~81 ~27 concrete 8 
setblock ~34 ~81 ~53 coal_ore 0 
setblock ~34 ~81 ~54 stone 5 
setblock ~35 ~81 ~25 stone 5 
setblock ~35 ~81 ~27 wool 8 
setblock ~35 ~81 ~53 clay 0 
setblock ~35 ~81 ~54 stone 0 
setblock ~35 ~81 ~55 double_stone_slab 8 
setblock ~36 ~81 ~25 clay 0 
setblock ~36 ~81 ~26 stone 5 
setblock ~36 ~81 ~54 wool 8 
setblock ~36 ~81 ~55 clay 0 
setblock ~37 ~81 ~25 double_stone_slab 8 
setblock ~37 ~81 ~26 wool 8 
setblock ~37 ~81 ~54 stone 0 
setblock ~37 ~81 ~55 wool 8 
setblock ~38 ~81 ~25 clay 0 
setblock ~38 ~81 ~26 double_stone_slab 8  
fill ~38 ~81 ~54 ~38 ~81 ~55 concrete 8  
fill ~39 ~81 ~24 ~39 ~81 ~25 double_stone_slab 8  
fill ~39 ~81 ~26 ~40 ~81 ~26 wool 8  
fill ~39 ~81 ~54 ~40 ~81 ~54 double_stone_slab 8 
setblock ~39 ~81 ~55 wool 8 
setblock ~39 ~81 ~56 clay 0  
fill ~40 ~81 ~24 ~41 ~81 ~24 wool 8 
setblock ~40 ~81 ~25 clay 0  
fill ~40 ~81 ~55 ~40 ~81 ~56 stone 0 
setblock ~41 ~81 ~25 coal_ore 0 
setblock ~41 ~81 ~26 stained_hardened_clay 9 
setblock ~41 ~81 ~54 wool 8 
setblock ~41 ~81 ~55 double_stone_slab 8 
setblock ~41 ~81 ~56 stone 0  
fill ~42 ~81 ~25 ~43 ~81 ~25 double_stone_slab 8 
setblock ~42 ~81 ~26 concrete 8 
setblock ~42 ~81 ~54 stone 5  
fill ~42 ~81 ~55 ~44 ~81 ~55 wool 8 
setblock ~43 ~81 ~26 double_stone_slab 8 
setblock ~43 ~81 ~54 wool 8  
fill ~44 ~81 ~25 ~44 ~81 ~26 wool 8 
setblock ~44 ~81 ~54 concrete 8 
setblock ~45 ~81 ~25 double_stone_slab 8 
setblock ~45 ~81 ~26 coal_ore 0 
setblock ~45 ~81 ~27 clay 0 
setblock ~45 ~81 ~53 wool 8 
setblock ~45 ~81 ~54 stone 5 
setblock ~45 ~81 ~55 stone 0  
fill ~46 ~81 ~26 ~47 ~81 ~26 stone 5 
setblock ~46 ~81 ~27 concrete 8  
fill ~46 ~81 ~53 ~46 ~81 ~54 double_stone_slab 8 
setblock ~47 ~81 ~27 stone 5  
fill ~47 ~81 ~28 ~49 ~81 ~28 double_stone_slab 8 
setblock ~47 ~81 ~52 double_stone_slab 8 
setblock ~47 ~81 ~53 wool 8 
setblock ~47 ~81 ~54 stone 0 
setblock ~48 ~81 ~27 wool 8 
setblock ~48 ~81 ~52 stone 4  
fill ~48 ~81 ~53 ~49 ~81 ~53 double_stone_slab 8 
setblock ~49 ~81 ~27 clay 0 
setblock ~49 ~81 ~29 double_stone_slab 8 
setblock ~49 ~81 ~51 wool 8 
setblock ~49 ~81 ~52 clay 0  
fill ~50 ~81 ~28 ~50 ~81 ~29 stone 3 
setblock ~50 ~81 ~30 stone 5  
fill ~50 ~81 ~50 ~51 ~81 ~50 double_stone_slab 8 
setblock ~50 ~81 ~51 clay 0 
setblock ~50 ~81 ~52 double_stone_slab 8 
setblock ~51 ~81 ~29 double_stone_slab 8 
setblock ~51 ~81 ~30 wool 8 
setblock ~51 ~81 ~31 clay 0 
setblock ~51 ~81 ~49 stone 0 
setblock ~51 ~81 ~51 double_stone_slab 8 
setblock ~52 ~81 ~30 clay 0 
setblock ~52 ~81 ~31 double_stone_slab 8 
setblock ~52 ~81 ~32 stone 0 
setblock ~52 ~81 ~33 wool 8 
setblock ~52 ~81 ~47 stonebrick 2 
setblock ~52 ~81 ~48 concrete 8  
fill ~52 ~81 ~49 ~52 ~81 ~50 wool 8 
setblock ~53 ~81 ~31 clay 0 
setblock ~53 ~81 ~32 double_stone_slab 8 
setblock ~53 ~81 ~33 clay 0 
setblock ~53 ~81 ~34 double_stone_slab 8 
setblock ~53 ~81 ~35 clay 0 
setblock ~53 ~81 ~45 clay 0  
fill ~53 ~81 ~46 ~54 ~81 ~46 double_stone_slab 8  
fill ~53 ~81 ~47 ~54 ~81 ~47 double_stone_slab 8 
setblock ~53 ~81 ~48 clay 0 
setblock ~53 ~81 ~49 double_stone_slab 8  
fill ~54 ~81 ~33 ~54 ~81 ~35 wool 8 
setblock ~54 ~81 ~36 stone 3 
setblock ~54 ~81 ~37 clay 0 
setblock ~54 ~81 ~38 double_stone_slab 8 
setblock ~54 ~81 ~39 stone 3  
fill ~54 ~81 ~40 ~54 ~81 ~41 double_stone_slab 8 
setblock ~54 ~81 ~42 stone 0  
fill ~54 ~81 ~43 ~55 ~81 ~43 double_stone_slab 8 
setblock ~54 ~81 ~44 stone 0 
setblock ~54 ~81 ~45 wool 8  
fill ~55 ~81 ~35 ~55 ~81 ~36 double_stone_slab 8 
setblock ~55 ~81 ~37 wool 8 
setblock ~55 ~81 ~38 stone 3 
setblock ~55 ~81 ~39 double_stone_slab 8 
setblock ~55 ~81 ~40 wool 8  
fill ~55 ~81 ~41 ~56 ~81 ~41 double_stone_slab 8 
setblock ~55 ~81 ~42 stone 3  
fill ~55 ~81 ~44 ~55 ~81 ~45 clay 0 
setblock ~56 ~81 ~39 wool 8 
setblock ~56 ~81 ~40 clay 0  
fill ~22 ~82 ~38 ~23 ~82 ~38 coal_ore 0 
setblock ~22 ~82 ~39 concrete 8  
fill ~22 ~82 ~40 ~23 ~82 ~40 coal_ore 0 
setblock ~22 ~82 ~41 stone 0  
fill ~22 ~82 ~42 ~24 ~82 ~42 stained_hardened_clay 9 
setblock ~23 ~82 ~34 stained_hardened_clay 9 
setblock ~23 ~82 ~35 coal_ore 0  
fill ~23 ~82 ~36 ~24 ~82 ~36 stained_hardened_clay 9 
setblock ~23 ~82 ~37 coal_ore 0 
setblock ~23 ~82 ~39 coal_ore 0 
setblock ~23 ~82 ~41 wool 8  
fill ~23 ~82 ~43 ~23 ~82 ~44 coal_ore 0  
fill ~23 ~82 ~45 ~24 ~82 ~45 stained_hardened_clay 9  
fill ~23 ~82 ~46 ~24 ~82 ~46 stained_hardened_clay 9  
fill ~24 ~82 ~32 ~26 ~82 ~32 concrete 8  
fill ~24 ~82 ~33 ~24 ~82 ~34 coal_ore 0 
setblock ~24 ~82 ~35 stone 0 
setblock ~24 ~82 ~37 stone 5 
setblock ~24 ~82 ~38 stained_hardened_clay 9 
setblock ~24 ~82 ~43 stained_hardened_clay 9 
setblock ~24 ~82 ~44 coal_ore 0 
setblock ~24 ~82 ~47 wool 7  
fill ~24 ~82 ~48 ~25 ~82 ~48 stained_hardened_clay 9 
setblock ~25 ~82 ~30 stone 0  
fill ~25 ~82 ~31 ~26 ~82 ~31 coal_ore 0 
setblock ~25 ~82 ~33 stone 0 
setblock ~25 ~82 ~34 double_stone_slab 8 
setblock ~25 ~82 ~46 wool 7 
setblock ~25 ~82 ~47 stained_hardened_clay 9 
setblock ~25 ~82 ~49 coal_ore 0 
setblock ~25 ~82 ~50 stained_hardened_clay 9  
fill ~26 ~82 ~29 ~28 ~82 ~29 stone 5  
fill ~26 ~82 ~30 ~27 ~82 ~30 double_stone_slab 8 
setblock ~26 ~82 ~48 concrete 8 
setblock ~26 ~82 ~49 stained_hardened_clay 9  
fill ~26 ~82 ~50 ~27 ~82 ~50 concrete 8 
setblock ~26 ~82 ~51 stained_hardened_clay 9 
setblock ~27 ~82 ~28 double_stone_slab 8 
setblock ~27 ~82 ~51 concrete 8  
fill ~27 ~82 ~52 ~28 ~82 ~52 coal_ore 0  
fill ~28 ~82 ~27 ~28 ~82 ~28 wool 8 
setblock ~28 ~82 ~51 wool 7 
setblock ~28 ~82 ~53 concrete 8  
fill ~29 ~82 ~26 ~30 ~82 ~26 double_stone_slab 8  
fill ~29 ~82 ~27 ~29 ~82 ~26 double_stone_slab 8 
setblock ~29 ~82 ~28 clay 0  
fill ~29 ~82 ~52 ~29 ~82 ~53 stained_hardened_clay 9  
fill ~29 ~82 ~54 ~31 ~82 ~54 coal_ore 0  
fill ~30 ~82 ~25 ~31 ~82 ~25 stone 5 
setblock ~30 ~82 ~27 coal_ore 0 
setblock ~30 ~82 ~53 concrete 8 
setblock ~30 ~82 ~55 wool 7 
setblock ~31 ~82 ~26 stone 5 
setblock ~31 ~82 ~55 stone 5  
fill ~32 ~82 ~24 ~32 ~82 ~25 double_stone_slab 8 
setblock ~32 ~82 ~26 clay 0 
setblock ~32 ~82 ~54 concrete 8 
setblock ~32 ~82 ~55 stone 0  
fill ~32 ~82 ~56 ~33 ~82 ~56 wool 8  
fill ~33 ~82 ~24 ~35 ~82 ~24 wool 8  
fill ~33 ~82 ~25 ~33 ~82 ~24 wool 8 
setblock ~33 ~82 ~55 concrete 8  
fill ~34 ~82 ~23 ~35 ~82 ~23 wool 8 
setblock ~34 ~82 ~25 stone 5 
setblock ~34 ~82 ~55 wool 8  
fill ~34 ~82 ~56 ~35 ~82 ~56 concrete 8  
fill ~34 ~82 ~57 ~34 ~82 ~56 concrete 8 
setblock ~35 ~82 ~57 double_stone_slab 8  
fill ~36 ~82 ~23 ~36 ~82 ~24 double_stone_slab 8 
setblock ~36 ~82 ~56 stained_hardened_clay 9 
setblock ~36 ~82 ~57 concrete 8 
setblock ~37 ~82 ~23 wool 8 
setblock ~37 ~82 ~24 double_stone_slab 8  
fill ~37 ~82 ~56 ~37 ~82 ~57 wool 8 
setblock ~38 ~82 ~22 double_stone_slab 8  
fill ~38 ~82 ~23 ~38 ~82 ~24 clay 0 
setblock ~38 ~82 ~56 double_stone_slab 8 
setblock ~38 ~82 ~57 wool 8 
setblock ~38 ~82 ~58 clay 0 
setblock ~39 ~82 ~22 wool 8 
setblock ~39 ~82 ~23 double_stone_slab 8 
setblock ~39 ~82 ~57 double_stone_slab 8 
setblock ~39 ~82 ~58 wool 8  
fill ~40 ~82 ~22 ~41 ~82 ~22 concrete 8 
setblock ~40 ~82 ~23 wool 8 
setblock ~40 ~82 ~57 concrete 8 
setblock ~40 ~82 ~58 stone 0 
setblock ~41 ~82 ~23 concrete 8 
setblock ~41 ~82 ~57 wool 8 
setblock ~41 ~82 ~58 concrete 8 
setblock ~42 ~82 ~22 wool 8 
setblock ~42 ~82 ~23 coal_ore 0  
fill ~42 ~82 ~24 ~43 ~82 ~24 wool 8 
setblock ~42 ~82 ~56 clay 0 
setblock ~42 ~82 ~57 double_stone_slab 8 
setblock ~42 ~82 ~58 stone 0 
setblock ~43 ~82 ~23 wool 8 
setblock ~43 ~82 ~56 double_stone_slab 8 
setblock ~43 ~82 ~57 clay 0 
setblock ~44 ~82 ~23 concrete 8 
setblock ~44 ~82 ~24 coal_ore 0  
fill ~44 ~82 ~56 ~45 ~82 ~56 wool 8 
setblock ~44 ~82 ~57 double_stone_slab 8 
setblock ~45 ~82 ~23 clay 0 
setblock ~45 ~82 ~24 double_stone_slab 8  
fill ~45 ~82 ~57 ~46 ~82 ~57 wool 8  
fill ~46 ~82 ~23 ~46 ~82 ~24 wool 8 
setblock ~46 ~82 ~25 concrete 8  
fill ~46 ~82 ~55 ~47 ~82 ~55 wool 8 
setblock ~46 ~82 ~56 stone 0  
fill ~47 ~82 ~24 ~47 ~82 ~25 wool 8 
setblock ~47 ~82 ~56 wool 8 
setblock ~48 ~82 ~24 concrete 8  
fill ~48 ~82 ~25 ~48 ~82 ~26 wool 8  
fill ~48 ~82 ~54 ~48 ~82 ~55 double_stone_slab 8 
setblock ~48 ~82 ~56 clay 0  
fill ~49 ~82 ~25 ~50 ~82 ~25 clay 0  
fill ~49 ~82 ~26 ~50 ~82 ~26 double_stone_slab 8  
fill ~49 ~82 ~54 ~49 ~82 ~55 clay 0 
setblock ~50 ~82 ~27 stone 3  
fill ~50 ~82 ~53 ~50 ~82 ~54 double_stone_slab 8 
setblock ~50 ~82 ~55 wool 8 
setblock ~51 ~82 ~26 wool 8 
setblock ~51 ~82 ~27 double_stone_slab 8 
setblock ~51 ~82 ~28 clay 0 
setblock ~51 ~82 ~52 wool 8 
setblock ~51 ~82 ~53 clay 0 
setblock ~51 ~82 ~54 double_stone_slab 8 
setblock ~52 ~82 ~27 stone 5 
setblock ~52 ~82 ~28 wool 8  
fill ~52 ~82 ~29 ~54 ~82 ~29 double_stone_slab 8 
setblock ~52 ~82 ~51 stone 3  
fill ~52 ~82 ~52 ~53 ~82 ~52 double_stone_slab 8  
fill ~52 ~82 ~53 ~52 ~82 ~52 double_stone_slab 8 
setblock ~53 ~82 ~28 clay 0  
fill ~53 ~82 ~30 ~54 ~82 ~30 wool 8  
fill ~53 ~82 ~50 ~53 ~82 ~51 wool 8  
fill ~54 ~82 ~31 ~55 ~82 ~31 double_stone_slab 8 
setblock ~54 ~82 ~32 clay 0  
fill ~54 ~82 ~48 ~54 ~82 ~49 wool 8  
fill ~54 ~82 ~50 ~54 ~82 ~51 double_stone_slab 8 
setblock ~55 ~82 ~30 double_stone_slab 8  
fill ~55 ~82 ~32 ~55 ~82 ~34 double_stone_slab 8  
fill ~55 ~82 ~46 ~56 ~82 ~46 wool 8 
setblock ~55 ~82 ~47 clay 0 
setblock ~55 ~82 ~48 double_stone_slab 8  
fill ~55 ~82 ~49 ~55 ~82 ~50 wool 8 
setblock ~56 ~82 ~32 clay 0  
fill ~56 ~82 ~33 ~56 ~82 ~37 double_stone_slab 8 
setblock ~56 ~82 ~38 clay 0  
fill ~56 ~82 ~42 ~57 ~82 ~42 wool 8  
fill ~56 ~82 ~43 ~57 ~82 ~43 wool 8  
fill ~56 ~82 ~44 ~56 ~82 ~45 double_stone_slab 8 
setblock ~56 ~82 ~47 wool 8 
setblock ~56 ~82 ~48 stone 3 
setblock ~57 ~82 ~34 wool 8 
setblock ~57 ~82 ~35 clay 0  
fill ~57 ~82 ~36 ~57 ~82 ~41 double_stone_slab 8 
setblock ~57 ~82 ~44 clay 0  
fill ~57 ~82 ~45 ~57 ~82 ~46 double_stone_slab 8 
setblock ~58 ~82 ~38 stone 5 
setblock ~58 ~82 ~39 clay 0 
setblock ~58 ~82 ~40 double_stone_slab 8 
setblock ~58 ~82 ~41 wool 8 
setblock ~58 ~82 ~42 stone 0 
setblock ~20 ~83 ~39 stonebrick 2 
setblock ~20 ~83 ~40 coal_ore 0 
setblock ~20 ~83 ~41 stone 0  
fill ~21 ~83 ~34 ~22 ~83 ~34 stained_hardened_clay 9  
fill ~21 ~83 ~35 ~21 ~83 ~40 stained_hardened_clay 9 
setblock ~21 ~83 ~41 wool 8 
setblock ~21 ~83 ~42 coal_ore 0  
fill ~21 ~83 ~43 ~22 ~83 ~43 stained_hardened_clay 9  
fill ~21 ~83 ~44 ~22 ~83 ~44 stained_hardened_clay 9  
fill ~21 ~83 ~45 ~22 ~83 ~45 stained_hardened_clay 9  
fill ~21 ~83 ~46 ~22 ~83 ~46 coal_ore 0  
fill ~22 ~83 ~32 ~23 ~83 ~32 coal_ore 0  
fill ~22 ~83 ~33 ~22 ~83 ~32 coal_ore 0 
setblock ~22 ~83 ~35 coal_ore 0 
setblock ~22 ~83 ~36 stained_hardened_clay 9 
setblock ~22 ~83 ~37 coal_ore 0  
fill ~22 ~83 ~47 ~23 ~83 ~47 stained_hardened_clay 9  
fill ~22 ~83 ~48 ~23 ~83 ~48 stained_hardened_clay 9  
fill ~23 ~83 ~30 ~23 ~83 ~31 concrete 8 
setblock ~23 ~83 ~33 concrete 8 
setblock ~23 ~83 ~49 concrete 8 
setblock ~23 ~83 ~50 wool 7 
setblock ~24 ~83 ~28 stone 5 
setblock ~24 ~83 ~29 concrete 8 
setblock ~24 ~83 ~30 stone 0 
setblock ~24 ~83 ~31 concrete 8 
setblock ~24 ~83 ~49 wool 7 
setblock ~24 ~83 ~50 stained_hardened_clay 9 
setblock ~24 ~83 ~51 stonebrick 2  
fill ~24 ~83 ~52 ~25 ~83 ~52 stained_hardened_clay 9 
setblock ~25 ~83 ~27 stone 0  
fill ~25 ~83 ~28 ~25 ~83 ~29 wool 8 
setblock ~25 ~83 ~51 stone 0 
setblock ~25 ~83 ~53 stained_hardened_clay 9 
setblock ~26 ~83 ~26 stonebrick 2 
setblock ~26 ~83 ~27 concrete 8 
setblock ~26 ~83 ~28 double_stone_slab 8 
setblock ~26 ~83 ~52 coal_ore 0 
setblock ~26 ~83 ~53 concrete 8 
setblock ~26 ~83 ~54 stonebrick 2  
fill ~27 ~83 ~25 ~28 ~83 ~25 wool 8 
setblock ~27 ~83 ~26 concrete 8 
setblock ~27 ~83 ~27 stone 5  
fill ~27 ~83 ~53 ~27 ~83 ~54 coal_ore 0 
setblock ~27 ~83 ~55 stone 0 
setblock ~28 ~83 ~24 stone 5 
setblock ~28 ~83 ~26 stone 0 
setblock ~28 ~83 ~54 coal_ore 0  
fill ~28 ~83 ~55 ~28 ~83 ~56 stained_hardened_clay 9  
fill ~29 ~83 ~24 ~29 ~83 ~25 double_stone_slab 8 
setblock ~29 ~83 ~55 coal_ore 0 
setblock ~29 ~83 ~56 concrete 8  
fill ~30 ~83 ~23 ~32 ~83 ~23 stone 5 
setblock ~30 ~83 ~24 wool 8 
setblock ~30 ~83 ~56 stone 5  
fill ~30 ~83 ~57 ~32 ~83 ~57 concrete 8 
setblock ~31 ~83 ~24 stone 5 
setblock ~31 ~83 ~56 concrete 8  
fill ~32 ~83 ~22 ~33 ~83 ~22 double_stone_slab 8 
setblock ~32 ~83 ~58 concrete 8 
setblock ~33 ~83 ~23 double_stone_slab 8 
setblock ~33 ~83 ~57 wool 8 
setblock ~33 ~83 ~58 stone 5 
setblock ~34 ~83 ~21 stone 5 
setblock ~34 ~83 ~22 wool 8  
fill ~34 ~83 ~58 ~35 ~83 ~58 double_stone_slab 8  
fill ~34 ~83 ~59 ~35 ~83 ~59 double_stone_slab 8  
fill ~35 ~83 ~21 ~36 ~83 ~21 concrete 8 
setblock ~35 ~83 ~22 stone 5 
setblock ~36 ~83 ~22 double_stone_slab 8 
setblock ~36 ~83 ~58 wool 8 
setblock ~36 ~83 ~59 stone 5 
setblock ~37 ~83 ~21 stone 0 
setblock ~37 ~83 ~22 concrete 8  
fill ~37 ~83 ~58 ~37 ~83 ~59 double_stone_slab 8 
setblock ~38 ~83 ~21 coal_ore 0   

KittysCommands:  
setblock ~38 ~83 ~59 double_stone_slab 8  
fill ~39 ~83 ~20 ~40 ~83 ~20 wool 8  
fill ~39 ~83 ~21 ~39 ~83 ~20 wool 8 
setblock ~39 ~83 ~59 clay 0 
setblock ~39 ~83 ~60 wool 8 
setblock ~40 ~83 ~21 stone 0 
setblock ~40 ~83 ~59 stone 0 
setblock ~40 ~83 ~60 clay 0 
setblock ~41 ~83 ~20 concrete 8 
setblock ~41 ~83 ~21 double_stone_slab 8  
fill ~41 ~83 ~59 ~42 ~83 ~59 wool 8 
setblock ~41 ~83 ~60 double_stone_slab 8 
setblock ~42 ~83 ~21 stone 0 
setblock ~43 ~83 ~21 concrete 8 
setblock ~43 ~83 ~22 stone 5 
setblock ~43 ~83 ~58 double_stone_slab 8  
fill ~43 ~83 ~59 ~44 ~83 ~59 clay 0  
fill ~44 ~83 ~21 ~44 ~83 ~22 wool 8 
setblock ~44 ~83 ~58 clay 0 
setblock ~45 ~83 ~21 double_stone_slab 8 
setblock ~45 ~83 ~22 wool 8 
setblock ~45 ~83 ~58 double_stone_slab 8 
setblock ~45 ~83 ~59 stone 3 
setblock ~46 ~83 ~21 stone 3 
setblock ~46 ~83 ~22 double_stone_slab 8  
fill ~46 ~83 ~58 ~48 ~83 ~58 clay 0 
setblock ~46 ~83 ~59 stone 4 
setblock ~47 ~83 ~22 concrete 8 
setblock ~47 ~83 ~23 double_stone_slab 8 
setblock ~47 ~83 ~57 clay 0 
setblock ~48 ~83 ~22 clay 0  
fill ~48 ~83 ~23 ~50 ~83 ~23 wool 8 
setblock ~48 ~83 ~57 double_stone_slab 8 
setblock ~49 ~83 ~24 wool 8  
fill ~49 ~83 ~56 ~51 ~83 ~56 double_stone_slab 8 
setblock ~49 ~83 ~57 wool 8  
fill ~50 ~83 ~24 ~51 ~83 ~24 double_stone_slab 8 
setblock ~50 ~83 ~57 double_stone_slab 8  
fill ~51 ~83 ~25 ~53 ~83 ~25 double_stone_slab 8 
setblock ~51 ~83 ~55 double_stone_slab 8 
setblock ~52 ~83 ~24 wool 8 
setblock ~52 ~83 ~26 wool 8 
setblock ~52 ~83 ~54 stone 0  
fill ~52 ~83 ~55 ~52 ~83 ~56 wool 8  
fill ~53 ~83 ~26 ~54 ~83 ~26 double_stone_slab 8  
fill ~53 ~83 ~27 ~54 ~83 ~27 double_stone_slab 8 
setblock ~53 ~83 ~53 clay 0  
fill ~53 ~83 ~54 ~53 ~83 ~55 double_stone_slab 8  
fill ~54 ~83 ~28 ~55 ~83 ~28 wool 8  
fill ~54 ~83 ~52 ~56 ~83 ~52 double_stone_slab 8  
fill ~54 ~83 ~53 ~54 ~83 ~52 double_stone_slab 8 
setblock ~54 ~83 ~54 stone 0 
setblock ~55 ~83 ~27 wool 8 
setblock ~55 ~83 ~29 stone 5 
setblock ~55 ~83 ~51 double_stone_slab 8 
setblock ~55 ~83 ~53 stone 5 
setblock ~56 ~83 ~28 stone 5 
setblock ~56 ~83 ~29 wool 8 
setblock ~56 ~83 ~30 double_stone_slab 8  
fill ~56 ~83 ~31 ~57 ~83 ~31 wool 8  
fill ~56 ~83 ~49 ~57 ~83 ~49 double_stone_slab 8  
fill ~56 ~83 ~50 ~56 ~83 ~49 double_stone_slab 8 
setblock ~56 ~83 ~51 wool 8 
setblock ~57 ~83 ~30 wool 8  
fill ~57 ~83 ~32 ~57 ~83 ~33 double_stone_slab 8  
fill ~57 ~83 ~47 ~58 ~83 ~47 double_stone_slab 8  
fill ~57 ~83 ~48 ~58 ~83 ~48 double_stone_slab 8 
setblock ~57 ~83 ~50 stone 0 
setblock ~58 ~83 ~32 wool 8  
fill ~58 ~83 ~33 ~58 ~83 ~35 double_stone_slab 8  
fill ~58 ~83 ~36 ~59 ~83 ~36 clay 0  
fill ~58 ~83 ~37 ~59 ~83 ~37 double_stone_slab 8  
fill ~58 ~83 ~43 ~59 ~83 ~43 clay 0  
fill ~58 ~83 ~44 ~58 ~83 ~43 clay 0 
setblock ~58 ~83 ~45 double_stone_slab 8 
setblock ~58 ~83 ~46 stone 0 
setblock ~59 ~83 ~34 double_stone_slab 8 
setblock ~59 ~83 ~35 clay 0 
setblock ~59 ~83 ~38 clay 0  
fill ~59 ~83 ~39 ~60 ~83 ~39 double_stone_slab 8 
setblock ~59 ~83 ~40 wool 8  
fill ~59 ~83 ~41 ~60 ~83 ~41 double_stone_slab 8  
fill ~59 ~83 ~42 ~59 ~83 ~41 double_stone_slab 8 
setblock ~59 ~83 ~44 stone 5 
setblock ~59 ~83 ~45 wool 8 
setblock ~59 ~83 ~46 coal_ore 0 
setblock ~60 ~83 ~40 stone 0 
setblock ~19 ~84 ~36 wool 7 
setblock ~19 ~84 ~37 concrete 8 
setblock ~19 ~84 ~38 stonebrick 2 
setblock ~19 ~84 ~39 coal_ore 0 
setblock ~19 ~84 ~40 stonebrick 2  
fill ~19 ~84 ~41 ~19 ~84 ~44 stained_hardened_clay 9 
setblock ~20 ~84 ~32 stained_hardened_clay 9 
setblock ~20 ~84 ~33 wool 7 
setblock ~20 ~84 ~34 stained_hardened_clay 9 
setblock ~20 ~84 ~35 coal_ore 0  
fill ~20 ~84 ~36 ~20 ~84 ~37 stained_hardened_clay 9 
setblock ~20 ~84 ~38 concrete 8 
setblock ~20 ~84 ~42 coal_ore 0  
fill ~20 ~84 ~43 ~20 ~84 ~47 stained_hardened_clay 9 
setblock ~20 ~84 ~48 wool 7 
setblock ~21 ~84 ~30 wool 8 
setblock ~21 ~84 ~31 coal_ore 0 
setblock ~21 ~84 ~32 stonebrick 2 
setblock ~21 ~84 ~33 stained_hardened_clay 9  
fill ~21 ~84 ~47 ~21 ~84 ~49 stained_hardened_clay 9 
setblock ~21 ~84 ~50 wool 7 
setblock ~22 ~84 ~29 concrete 8 
setblock ~22 ~84 ~30 stone 0 
setblock ~22 ~84 ~31 concrete 8  
fill ~22 ~84 ~49 ~22 ~84 ~51 stained_hardened_clay 9 
setblock ~23 ~84 ~27 concrete 8 
setblock ~23 ~84 ~28 double_stone_slab 8 
setblock ~23 ~84 ~29 coal_ore 0 
setblock ~23 ~84 ~51 stone 0 
setblock ~23 ~84 ~52 stained_hardened_clay 9 
setblock ~23 ~84 ~53 stonebrick 2 
setblock ~24 ~84 ~26 stone 0 
setblock ~24 ~84 ~27 coal_ore 0 
setblock ~24 ~84 ~53 coal_ore 0 
setblock ~24 ~84 ~54 stained_hardened_clay 9  
fill ~25 ~84 ~25 ~26 ~84 ~25 coal_ore 0 
setblock ~25 ~84 ~26 concrete 8 
setblock ~25 ~84 ~54 stonebrick 2  
fill ~25 ~84 ~55 ~26 ~84 ~55 stained_hardened_clay 9 
setblock ~26 ~84 ~24 wool 8 
setblock ~26 ~84 ~56 stained_hardened_clay 9 
setblock ~27 ~84 ~23 stone 0 
setblock ~27 ~84 ~24 stone 5 
setblock ~27 ~84 ~56 coal_ore 0  
fill ~27 ~84 ~57 ~28 ~84 ~57 concrete 8 
setblock ~28 ~84 ~23 clay 0  
fill ~29 ~84 ~22 ~30 ~84 ~22 clay 0 
setblock ~29 ~84 ~23 double_stone_slab 8 
setblock ~29 ~84 ~57 stained_hardened_clay 9 
setblock ~29 ~84 ~58 stone 0 
setblock ~30 ~84 ~21 double_stone_slab 8 
setblock ~30 ~84 ~58 wool 8 
setblock ~30 ~84 ~59 stone 5  
fill ~31 ~84 ~21 ~32 ~84 ~21 stone 5 
setblock ~31 ~84 ~22 double_stone_slab 8 
setblock ~31 ~84 ~58 concrete 8 
setblock ~31 ~84 ~59 stone 0 
setblock ~32 ~84 ~20 clay 0 
setblock ~32 ~84 ~59 concrete 8 
setblock ~32 ~84 ~60 stone 5  
fill ~33 ~84 ~20 ~33 ~84 ~21 double_stone_slab 8 
setblock ~33 ~84 ~59 stone 0 
setblock ~33 ~84 ~60 wool 8 
setblock ~34 ~84 ~20 stone 0 
setblock ~34 ~84 ~60 clay 0 
setblock ~35 ~84 ~20 concrete 8  
fill ~35 ~84 ~60 ~36 ~84 ~60 double_stone_slab 8 
setblock ~36 ~84 ~19 stone 0 
setblock ~36 ~84 ~20 coal_ore 0  
fill ~36 ~84 ~61 ~39 ~84 ~61 double_stone_slab 8  
fill ~37 ~84 ~19 ~37 ~84 ~20 concrete 8 
setblock ~37 ~84 ~60 clay 0  
fill ~38 ~84 ~19 ~39 ~84 ~19 wool 8 
setblock ~38 ~84 ~20 concrete 8 
setblock ~38 ~84 ~60 double_stone_slab 8 
setblock ~40 ~84 ~19 concrete 8  
fill ~40 ~84 ~61 ~42 ~84 ~61 wool 8  
fill ~41 ~84 ~19 ~44 ~84 ~19 wool 8 
setblock ~42 ~84 ~20 double_stone_slab 8 
setblock ~42 ~84 ~60 clay 0  
fill ~43 ~84 ~20 ~44 ~84 ~20 wool 8  
fill ~43 ~84 ~60 ~44 ~84 ~60 double_stone_slab 8  
fill ~43 ~84 ~61 ~44 ~84 ~61 double_stone_slab 8 
setblock ~45 ~84 ~20 clay 0  
fill ~45 ~84 ~60 ~46 ~84 ~60 wool 8 
setblock ~46 ~84 ~20 stone 0  
fill ~47 ~84 ~20 ~48 ~84 ~20 wool 8  
fill ~47 ~84 ~21 ~49 ~84 ~21 wool 8  
fill ~47 ~84 ~59 ~49 ~84 ~59 double_stone_slab 8  
fill ~47 ~84 ~60 ~47 ~84 ~59 double_stone_slab 8 
setblock ~48 ~84 ~60 wool 8 
setblock ~49 ~84 ~22 stone 0 
setblock ~49 ~84 ~58 wool 8  
fill ~50 ~84 ~21 ~50 ~84 ~22 double_stone_slab 8  
fill ~50 ~84 ~58 ~51 ~84 ~58 double_stone_slab 8 
setblock ~50 ~84 ~59 wool 8  
fill ~51 ~84 ~22 ~51 ~84 ~23 double_stone_slab 8  
fill ~51 ~84 ~57 ~53 ~84 ~57 double_stone_slab 8 
setblock ~52 ~84 ~23 wool 8 
setblock ~53 ~84 ~23 stone 5 
setblock ~53 ~84 ~24 wool 8 
setblock ~53 ~84 ~56 double_stone_slab 8 
setblock ~54 ~84 ~24 double_stone_slab 8 
setblock ~54 ~84 ~25 stone 0 
setblock ~54 ~84 ~55 double_stone_slab 8 
setblock ~54 ~84 ~56 stone 5 
setblock ~55 ~84 ~25 wool 8 
setblock ~55 ~84 ~26 double_stone_slab 8  
fill ~55 ~84 ~54 ~56 ~84 ~54 wool 8 
setblock ~55 ~84 ~55 concrete 8 
setblock ~56 ~84 ~26 concrete 8 
setblock ~56 ~84 ~27 double_stone_slab 8 
setblock ~56 ~84 ~53 wool 8 
setblock ~57 ~84 ~27 stone 0  
fill ~57 ~84 ~28 ~57 ~84 ~29 double_stone_slab 8  
fill ~57 ~84 ~51 ~58 ~84 ~51 wool 8  
fill ~57 ~84 ~52 ~57 ~84 ~53 stone 5  
fill ~58 ~84 ~29 ~58 ~84 ~31 wool 8 
setblock ~58 ~84 ~49 double_stone_slab 8 
setblock ~58 ~84 ~50 wool 8  
fill ~59 ~84 ~30 ~59 ~84 ~32 double_stone_slab 8 
setblock ~59 ~84 ~33 wool 8  
fill ~59 ~84 ~47 ~60 ~84 ~47 stone 0  
fill ~59 ~84 ~48 ~60 ~84 ~48 double_stone_slab 8 
setblock ~59 ~84 ~49 wool 8 
setblock ~59 ~84 ~50 stone 0 
setblock ~60 ~84 ~32 wool 8  
fill ~60 ~84 ~33 ~60 ~84 ~34 double_stone_slab 8  
fill ~60 ~84 ~35 ~60 ~84 ~36 wool 8  
fill ~60 ~84 ~37 ~61 ~84 ~37 double_stone_slab 8  
fill ~60 ~84 ~38 ~61 ~84 ~38 double_stone_slab 8  
fill ~60 ~84 ~42 ~61 ~84 ~42 double_stone_slab 8 
setblock ~60 ~84 ~43 stone 3 
setblock ~60 ~84 ~44 stone 0 
setblock ~60 ~84 ~45 stonebrick 2 
setblock ~60 ~84 ~46 wool 8 
setblock ~61 ~84 ~36 wool 8  
fill ~61 ~84 ~39 ~61 ~84 ~42 double_stone_slab 8 
setblock ~61 ~84 ~43 clay 0 
setblock ~61 ~84 ~44 wool 8 
setblock ~17 ~85 ~39 coal_ore 0 
setblock ~17 ~85 ~40 concrete 8 
setblock ~17 ~85 ~41 stonebrick 2  
fill ~18 ~85 ~34 ~19 ~85 ~34 stained_hardened_clay 9  
fill ~18 ~85 ~35 ~19 ~85 ~35 stained_hardened_clay 9  
fill ~18 ~85 ~36 ~18 ~85 ~34 stained_hardened_clay 9 
setblock ~18 ~85 ~37 stone 0 
setblock ~18 ~85 ~38 coal_ore 0  
fill ~18 ~85 ~39 ~18 ~85 ~46 stained_hardened_clay 9  
fill ~19 ~85 ~31 ~20 ~85 ~31 stained_hardened_clay 9 
setblock ~19 ~85 ~32 concrete 8 
setblock ~19 ~85 ~33 stonebrick 2 
setblock ~19 ~85 ~45 coal_ore 0  
fill ~19 ~85 ~46 ~19 ~85 ~48 stained_hardened_clay 9 
setblock ~19 ~85 ~49 wool 7 
setblock ~20 ~85 ~29 stone 0 
setblock ~20 ~85 ~30 concrete 8  
fill ~20 ~85 ~49 ~20 ~85 ~51 stained_hardened_clay 9 
setblock ~21 ~85 ~27 stone 5 
setblock ~21 ~85 ~28 concrete 8 
setblock ~21 ~85 ~29 coal_ore 0 
setblock ~21 ~85 ~51 stained_hardened_clay 9 
setblock ~21 ~85 ~52 coal_ore 0  
fill ~21 ~85 ~53 ~22 ~85 ~53 stained_hardened_clay 9 
setblock ~22 ~85 ~26 double_stone_slab 8  
fill ~22 ~85 ~27 ~22 ~85 ~28 wool 8 
setblock ~22 ~85 ~52 stained_hardened_clay 9 
setblock ~22 ~85 ~54 stained_hardened_clay 9  
fill ~23 ~85 ~25 ~24 ~85 ~25 concrete 8  
fill ~23 ~85 ~26 ~23 ~85 ~25 concrete 8  
fill ~23 ~85 ~54 ~23 ~85 ~55 coal_ore 0 
setblock ~24 ~85 ~24 coal_ore 0 
setblock ~24 ~85 ~55 concrete 8 
setblock ~24 ~85 ~56 coal_ore 0 
setblock ~25 ~85 ~23 wool 8 
setblock ~25 ~85 ~24 stone 0  
fill ~25 ~85 ~56 ~25 ~85 ~57 stained_hardened_clay 9 
setblock ~26 ~85 ~22 stone 5 
setblock ~26 ~85 ~23 concrete 8 
setblock ~26 ~85 ~57 stained_hardened_clay 9 
setblock ~26 ~85 ~58 coal_ore 0  
fill ~27 ~85 ~21 ~29 ~85 ~21 double_stone_slab 8 
setblock ~27 ~85 ~22 wool 8  
fill ~27 ~85 ~58 ~27 ~85 ~59 concrete 8 
setblock ~28 ~85 ~22 stone 0 
setblock ~28 ~85 ~58 coal_ore 0  
fill ~28 ~85 ~59 ~29 ~85 ~59 concrete 8 
setblock ~29 ~85 ~20 wool 8 
setblock ~29 ~85 ~60 wool 8  
fill ~30 ~85 ~20 ~31 ~85 ~20 double_stone_slab 8 
setblock ~30 ~85 ~60 concrete 8 
setblock ~31 ~85 ~19 stone 5 
setblock ~31 ~85 ~60 stone 5  
fill ~31 ~85 ~61 ~32 ~85 ~61 concrete 8  
fill ~32 ~85 ~19 ~33 ~85 ~19 double_stone_slab 8  
fill ~33 ~85 ~61 ~35 ~85 ~61 double_stone_slab 8  
fill ~34 ~85 ~18 ~35 ~85 ~18 stone 5  
fill ~34 ~85 ~19 ~34 ~85 ~18 stone 5 
setblock ~34 ~85 ~62 clay 0 
setblock ~35 ~85 ~19 concrete 8 
setblock ~35 ~85 ~62 wool 8  
fill ~36 ~85 ~18 ~37 ~85 ~18 wool 8  
fill ~36 ~85 ~62 ~39 ~85 ~62 double_stone_slab 8 
setblock ~38 ~85 ~18 concrete 8 
setblock ~39 ~85 ~17 wool 8 
setblock ~39 ~85 ~18 stone 5  
fill ~39 ~85 ~63 ~41 ~85 ~63 double_stone_slab 8  
fill ~40 ~85 ~17 ~41 ~85 ~17 concrete 8  
fill ~40 ~85 ~18 ~41 ~85 ~18 concrete 8  
fill ~40 ~85 ~62 ~41 ~85 ~62 wool 8 
setblock ~42 ~85 ~18 wool 8  
fill ~42 ~85 ~62 ~45 ~85 ~62 double_stone_slab 8 
setblock ~43 ~85 ~18 double_stone_slab 8 
setblock ~44 ~85 ~18 stone 5 
setblock ~45 ~85 ~18 stained_hardened_clay 9 
setblock ~45 ~85 ~19 stone 5 
setblock ~45 ~85 ~61 double_stone_slab 8  
fill ~46 ~85 ~18 ~46 ~85 ~19 coal_ore 0  
fill ~46 ~85 ~61 ~46 ~85 ~62 wool 8 
setblock ~47 ~85 ~19 stonebrick 2  
fill ~47 ~85 ~61 ~48 ~85 ~61 double_stone_slab 8 
setblock ~48 ~85 ~19 stone 5 
setblock ~49 ~85 ~19 concrete 8 
setblock ~49 ~85 ~20 stone 5  
fill ~49 ~85 ~60 ~50 ~85 ~60 wool 8  
fill ~49 ~85 ~61 ~49 ~85 ~60 wool 8 
setblock ~50 ~85 ~20 wool 8 
setblock ~51 ~85 ~20 double_stone_slab 8  
fill ~51 ~85 ~21 ~53 ~85 ~21 wool 8  
fill ~51 ~85 ~59 ~53 ~85 ~59 wool 8 
setblock ~51 ~85 ~60 double_stone_slab 8 
setblock ~52 ~85 ~22 wool 8 
setblock ~52 ~85 ~58 double_stone_slab 8  
fill ~53 ~85 ~22 ~54 ~85 ~22 stone 0 
setblock ~53 ~85 ~58 stone 0 
setblock ~54 ~85 ~23 wool 8 
setblock ~54 ~85 ~57 wool 8 
setblock ~54 ~85 ~58 stone 5 
setblock ~55 ~85 ~23 double_stone_slab 8 
setblock ~55 ~85 ~24 wool 8 
setblock ~55 ~85 ~56 wool 8 
setblock ~55 ~85 ~57 stone 0  
fill ~56 ~85 ~24 ~56 ~85 ~25 stone 5 
setblock ~56 ~85 ~55 concrete 8 
setblock ~56 ~85 ~56 stonebrick 2 
setblock ~57 ~85 ~25 stone 5 
setblock ~57 ~85 ~26 double_stone_slab 8  
fill ~57 ~85 ~54 ~57 ~85 ~55 stone 5 
setblock ~58 ~85 ~26 stone 0  
fill ~58 ~85 ~27 ~59 ~85 ~27 clay 0  
fill ~58 ~85 ~28 ~59 ~85 ~28 wool 8  
fill ~58 ~85 ~52 ~59 ~85 ~52 wool 8  
fill ~58 ~85 ~53 ~58 ~85 ~54 double_stone_slab 8 
setblock ~59 ~85 ~29 concrete 8 
setblock ~59 ~85 ~51 stone 5 
setblock ~59 ~85 ~53 concrete 8  
fill ~60 ~85 ~29 ~60 ~85 ~30 double_stone_slab 8 
setblock ~60 ~85 ~31 wool 8  
fill ~60 ~85 ~49 ~61 ~85 ~49 double_stone_slab 8  
fill ~60 ~85 ~50 ~60 ~85 ~49 double_stone_slab 8 
setblock ~60 ~85 ~51 wool 8 
setblock ~61 ~85 ~31 double_stone_slab 8 
setblock ~61 ~85 ~32 wool 8 
setblock ~61 ~85 ~33 double_stone_slab 8 
setblock ~61 ~85 ~34 wool 8 
setblock ~61 ~85 ~35 stone 0 
setblock ~61 ~85 ~45 coal_ore 0 
setblock ~61 ~85 ~46 wool 8 
setblock ~61 ~85 ~47 clay 0 
setblock ~61 ~85 ~48 double_stone_slab 8 
setblock ~62 ~85 ~34 double_stone_slab 8 
setblock ~62 ~85 ~35 wool 8 
setblock ~62 ~85 ~36 double_stone_slab 8 
setblock ~62 ~85 ~37 clay 0  
fill ~62 ~85 ~38 ~62 ~85 ~39 double_stone_slab 8 
setblock ~62 ~85 ~40 wool 8 
setblock ~62 ~85 ~41 double_stone_slab 8 
setblock ~62 ~85 ~42 clay 0  
fill ~62 ~85 ~43 ~62 ~85 ~45 double_stone_slab 8 
setblock ~62 ~85 ~46 clay 0 
setblock ~63 ~85 ~39 clay 0 
setblock ~63 ~85 ~40 stone 5 
setblock ~63 ~85 ~41 clay 0  
fill ~16 ~86 ~36 ~17 ~86 ~36 stonebrick 2  
fill ~16 ~86 ~37 ~17 ~86 ~37 stained_hardened_clay 9 
setblock ~16 ~86 ~38 stonebrick 2 
setblock ~16 ~86 ~39 stained_hardened_clay 9 
setblock ~16 ~86 ~40 coal_ore 0 
setblock ~16 ~86 ~41 stained_hardened_clay 9 
setblock ~16 ~86 ~42 coal_ore 0  
fill ~16 ~86 ~43 ~17 ~86 ~43 stained_hardened_clay 9  
fill ~16 ~86 ~44 ~17 ~86 ~44 stained_hardened_clay 9 
setblock ~17 ~86 ~32 stone 0 
setblock ~17 ~86 ~33 stonebrick 2  
fill ~17 ~86 ~34 ~17 ~86 ~35 coal_ore 0 
setblock ~17 ~86 ~38 stained_hardened_clay 9 
setblock ~17 ~86 ~42 stained_hardened_clay 9 
setblock ~17 ~86 ~45 coal_ore 0  
fill ~17 ~86 ~46 ~17 ~86 ~48 stained_hardened_clay 9 
setblock ~18 ~86 ~30 concrete 8 
setblock ~18 ~86 ~31 stained_hardened_clay 9  
fill ~18 ~86 ~32 ~18 ~86 ~33 coal_ore 0  
fill ~18 ~86 ~47 ~18 ~86 ~48 stained_hardened_clay 9 
setblock ~18 ~86 ~49 wool 7  
fill ~18 ~86 ~50 ~19 ~86 ~50 stained_hardened_clay 9  
fill ~19 ~86 ~28 ~20 ~86 ~28 coal_ore 0 
setblock ~19 ~86 ~29 stone 5 
setblock ~19 ~86 ~30 wool 8 
setblock ~19 ~86 ~51 wool 7 
setblock ~19 ~86 ~52 stained_hardened_clay 9  
fill ~20 ~86 ~26 ~20 ~86 ~27 stone 0 
setblock ~20 ~86 ~52 stone 5 
setblock ~20 ~86 ~53 wool 7 
setblock ~20 ~86 ~54 stained_hardened_clay 9 
setblock ~21 ~86 ~25 double_stone_slab 8 
setblock ~21 ~86 ~26 stone 5 
setblock ~21 ~86 ~54 coal_ore 0 
setblock ~21 ~86 ~55 wool 7  
fill ~22 ~86 ~24 ~22 ~86 ~25 wool 8  
fill ~22 ~86 ~55 ~22 ~86 ~56 stained_hardened_clay 9  
fill ~23 ~86 ~23 ~24 ~86 ~23 coal_ore 0 
setblock ~23 ~86 ~24 concrete 8 
setblock ~23 ~86 ~56 wool 7  
fill ~23 ~86 ~57 ~24 ~86 ~57 coal_ore 0 
setblock ~24 ~86 ~22 stone 5 
setblock ~24 ~86 ~58 coal_ore 0  
fill ~25 ~86 ~21 ~26 ~86 ~21 wool 8  
fill ~25 ~86 ~22 ~25 ~86 ~21 wool 8  
fill ~25 ~86 ~58 ~25 ~86 ~59 concrete 8 
setblock ~26 ~86 ~20 stone 0 
setblock ~26 ~86 ~59 coal_ore 0 
setblock ~26 ~86 ~60 stonebrick 2 
setblock ~27 ~86 ~20 wool 8 
setblock ~27 ~86 ~60 concrete 8 
setblock ~28 ~86 ~19 double_stone_slab 8 
setblock ~28 ~86 ~20 clay 0 
setblock ~28 ~86 ~60 stone 0 
setblock ~28 ~86 ~61 wool 8 
setblock ~29 ~86 ~19 wool 8 
setblock ~29 ~86 ~61 stone 0 
setblock ~30 ~86 ~18 concrete 8 
setblock ~30 ~86 ~19 stone 0  
fill ~30 ~86 ~61 ~30 ~86 ~62 wool 8 
setblock ~31 ~86 ~18 double_stone_slab 8 
setblock ~31 ~86 ~62 stone 5  
fill ~32 ~86 ~17 ~32 ~86 ~18 wool 8 
setblock ~32 ~86 ~62 double_stone_slab 8 
setblock ~32 ~86 ~63 clay 0 
setblock ~33 ~86 ~17 stone 0 
setblock ~33 ~86 ~18 double_stone_slab 8 
setblock ~33 ~86 ~62 wool 8 
setblock ~33 ~86 ~63 double_stone_slab 8 
setblock ~34 ~86 ~17 stone 5 
setblock ~34 ~86 ~63 wool 8 
setblock ~35 ~86 ~17 stone 0 
setblock ~35 ~86 ~63 clay 0  
fill ~36 ~86 ~16 ~36 ~86 ~17 wool 8 
setblock ~36 ~86 ~63 stone 0 
setblock ~36 ~86 ~64 double_stone_slab 8 
setblock ~37 ~86 ~16 concrete 8 
setblock ~37 ~86 ~17 wool 8  
fill ~37 ~86 ~63 ~37 ~86 ~64 wool 8 
setblock ~38 ~86 ~16 double_stone_slab 8 
setblock ~38 ~86 ~17 concrete 8  
fill ~38 ~86 ~63 ~38 ~86 ~64 double_stone_slab 8 
setblock ~39 ~86 ~16 wool 8 
setblock ~39 ~86 ~64 stone 0 
setblock ~40 ~86 ~16 concrete 8  
fill ~40 ~86 ~64 ~41 ~86 ~64 wool 8 
setblock ~41 ~86 ~16 wool 8  
fill ~42 ~86 ~16 ~43 ~86 ~16 concrete 8 
setblock ~42 ~86 ~17 wool 8 
setblock ~42 ~86 ~63 clay 0  
fill ~42 ~86 ~64 ~43 ~86 ~64 double_stone_slab 8  
fill ~43 ~86 ~17 ~44 ~86 ~17 coal_ore 0  
fill ~43 ~86 ~63 ~44 ~86 ~63 double_stone_slab 8 
setblock ~44 ~86 ~16 stone 0 
setblock ~44 ~86 ~64 wool 8  
fill ~45 ~86 ~17 ~46 ~86 ~17 stained_hardened_clay 9  
fill ~45 ~86 ~63 ~46 ~86 ~63 wool 8 
setblock ~47 ~86 ~17 wool 7 
setblock ~47 ~86 ~18 coal_ore 0  
fill ~47 ~86 ~62 ~48 ~86 ~62 double_stone_slab 8  
fill ~47 ~86 ~63 ~48 ~86 ~63 double_stone_slab 8 
setblock ~48 ~86 ~17 concrete 8 
setblock ~48 ~86 ~18 stone 0 
setblock ~49 ~86 ~18 stone 5 
setblock ~49 ~86 ~62 wool 8 
setblock ~50 ~86 ~18 coal_ore 0 
setblock ~50 ~86 ~19 concrete 8 
setblock ~50 ~86 ~61 wool 8 
setblock ~50 ~86 ~62 concrete 8 
setblock ~51 ~86 ~19 wool 8 
setblock ~51 ~86 ~61 stone 5 
setblock ~52 ~86 ~19 stone 0  
fill ~52 ~86 ~20 ~53 ~86 ~20 wool 8 
setblock ~52 ~86 ~60 stone 5 
setblock ~52 ~86 ~61 concrete 8 
setblock ~53 ~86 ~60 concrete 8 
setblock ~54 ~86 ~20 double_stone_slab 8 
setblock ~54 ~86 ~21 stone 0 
setblock ~54 ~86 ~59 stone 5 
setblock ~54 ~86 ~60 double_stone_slab 8 
setblock ~55 ~86 ~21 wool 8 
setblock ~55 ~86 ~22 stone 0  
fill ~55 ~86 ~58 ~56 ~86 ~58 concrete 8  
fill ~55 ~86 ~59 ~55 ~86 ~58 concrete 8 
setblock ~56 ~86 ~22 wool 8 
setblock ~56 ~86 ~23 stone 0 
setblock ~56 ~86 ~57 stonebrick 2 
setblock ~57 ~86 ~23 wool 8 
setblock ~57 ~86 ~24 double_stone_slab 8  
fill ~57 ~86 ~56 ~58 ~86 ~56 concrete 8 
setblock ~57 ~86 ~57 coal_ore 0 
setblock ~58 ~86 ~24 wool 8  
fill ~58 ~86 ~25 ~59 ~86 ~25 double_stone_slab 8 
setblock ~58 ~86 ~55 concrete 8 
setblock ~59 ~86 ~26 stone 5 
setblock ~59 ~86 ~54 wool 8 
setblock ~59 ~86 ~55 stone 5  
fill ~60 ~86 ~26 ~60 ~86 ~27 double_stone_slab 8 
setblock ~60 ~86 ~28 wool 8 
setblock ~60 ~86 ~52 double_stone_slab 8 
setblock ~60 ~86 ~53 stone 5 
setblock ~60 ~86 ~54 stone 0  
fill ~61 ~86 ~28 ~61 ~86 ~30 double_stone_slab 8  
fill ~61 ~86 ~50 ~61 ~86 ~52 wool 8 
setblock ~62 ~86 ~30 double_stone_slab 8 
setblock ~62 ~86 ~31 stone 5  
fill ~62 ~86 ~32 ~62 ~86 ~33 double_stone_slab 8 
setblock ~62 ~86 ~47 clay 0 
setblock ~62 ~86 ~48 wool 8  
fill ~62 ~86 ~49 ~62 ~86 ~50 double_stone_slab 8  
fill ~63 ~86 ~32 ~63 ~86 ~34 wool 8  
fill ~63 ~86 ~35 ~63 ~86 ~36 double_stone_slab 8 
setblock ~63 ~86 ~37 clay 0 
setblock ~63 ~86 ~38 double_stone_slab 8 
setblock ~63 ~86 ~42 wool 8  
fill ~63 ~86 ~43 ~64 ~86 ~43 clay 0  
fill ~63 ~86 ~44 ~64 ~86 ~44 clay 0  
fill ~63 ~86 ~45 ~63 ~86 ~46 clay 0 
setblock ~63 ~86 ~47 double_stone_slab 8 
setblock ~63 ~86 ~48 clay 0 
setblock ~64 ~86 ~36 wool 8 
setblock ~64 ~86 ~37 double_stone_slab 8  
fill ~64 ~86 ~38 ~64 ~86 ~40 clay 0 
setblock ~64 ~86 ~41 double_stone_slab 8 
setblock ~64 ~86 ~42 clay 0  
fill ~15 ~87 ~35 ~15 ~87 ~36 stone 0 
setblock ~15 ~87 ~37 stonebrick 2 
setblock ~15 ~87 ~38 coal_ore 0 
setblock ~15 ~87 ~39 concrete 8 
setblock ~15 ~87 ~40 coal_ore 0  
fill ~15 ~87 ~41 ~15 ~87 ~42 stonebrick 2  
fill ~15 ~87 ~43 ~15 ~87 ~44 coal_ore 0 
setblock ~15 ~87 ~45 stained_hardened_clay 9  
fill ~16 ~87 ~32 ~16 ~87 ~33 concrete 8 
setblock ~16 ~87 ~34 stone 0 
setblock ~16 ~87 ~35 coal_ore 0 
setblock ~16 ~87 ~45 wool 7 
setblock ~16 ~87 ~46 stonebrick 2 
setblock ~16 ~87 ~47 coal_ore 0 
setblock ~16 ~87 ~48 stained_hardened_clay 9  
fill ~17 ~87 ~29 ~18 ~87 ~29 concrete 8 
setblock ~17 ~87 ~30 stone 0 
setblock ~17 ~87 ~31 stained_hardened_clay 9  
fill ~17 ~87 ~49 ~17 ~87 ~50 stained_hardened_clay 9 
setblock ~17 ~87 ~51 stonebrick 2 
setblock ~18 ~87 ~27 concrete 8 
setblock ~18 ~87 ~28 stone 0 
setblock ~18 ~87 ~51 coal_ore 0  
fill ~18 ~87 ~52 ~18 ~87 ~53 stained_hardened_clay 9 
setblock ~19 ~87 ~26 coal_ore 0 
setblock ~19 ~87 ~27 stonebrick 2 
setblock ~19 ~87 ~53 stained_hardened_clay 9 
setblock ~19 ~87 ~54 coal_ore 0 
setblock ~20 ~87 ~25 concrete 8 
setblock ~20 ~87 ~55 coal_ore 0  
fill ~21 ~87 ~23 ~21 ~87 ~24 wool 8 
setblock ~21 ~87 ~56 coal_ore 0  
fill ~21 ~87 ~57 ~22 ~87 ~57 stained_hardened_clay 9  
fill ~22 ~87 ~22 ~22 ~87 ~23 double_stone_slab 8  
fill ~22 ~87 ~58 ~23 ~87 ~58 stained_hardened_clay 9 
setblock ~23 ~87 ~21 double_stone_slab 8 
setblock ~23 ~87 ~22 wool 8 
setblock ~23 ~87 ~59 stone 0 
setblock ~24 ~87 ~21 stone 0 
setblock ~24 ~87 ~59 stone 5 
setblock ~25 ~87 ~20 stone 5 
setblock ~25 ~87 ~60 concrete 8  
fill ~26 ~87 ~19 ~27 ~87 ~19 double_stone_slab 8 
setblock ~26 ~87 ~61 wool 8 
setblock ~27 ~87 ~18 concrete 8 
setblock ~27 ~87 ~61 stone 5  
fill ~27 ~87 ~62 ~28 ~87 ~62 wool 8  
fill ~28 ~87 ~18 ~29 ~87 ~18 wool 8 
setblock ~29 ~87 ~17 concrete 8 
setblock ~29 ~87 ~62 stone 5 
setblock ~29 ~87 ~63 wool 8 
setblock ~30 ~87 ~17 wool 8  
fill ~30 ~87 ~63 ~31 ~87 ~63 clay 0 
setblock ~31 ~87 ~17 stone 5 
setblock ~32 ~87 ~16 double_stone_slab 8 
setblock ~32 ~87 ~64 double_stone_slab 8  
fill ~33 ~87 ~16 ~35 ~87 ~16 wool 8 
setblock ~33 ~87 ~64 wool 8 
setblock ~34 ~87 ~64 double_stone_slab 8 
setblock ~35 ~87 ~15 double_stone_slab 8 
setblock ~35 ~87 ~64 wool 8  
fill ~35 ~87 ~65 ~36 ~87 ~65 double_stone_slab 8  
fill ~36 ~87 ~15 ~37 ~87 ~15 wool 8  
fill ~37 ~87 ~65 ~38 ~87 ~65 stone 5 
setblock ~38 ~87 ~15 double_stone_slab 8  
fill ~39 ~87 ~15 ~40 ~87 ~15 concrete 8 
setblock ~39 ~87 ~65 concrete 8  
fill ~40 ~87 ~65 ~42 ~87 ~65 wool 8 
setblock ~41 ~87 ~15 stone 0  
fill ~42 ~87 ~15 ~43 ~87 ~15 stained_hardened_clay 9 
setblock ~43 ~87 ~65 double_stone_slab 8 
setblock ~44 ~87 ~15 coal_ore 0 
setblock ~44 ~87 ~65 wool 8 
setblock ~45 ~87 ~15 stone 5  
fill ~45 ~87 ~16 ~46 ~87 ~16 coal_ore 0 
setblock ~45 ~87 ~64 clay 0 
setblock ~45 ~87 ~65 stone 0  
fill ~46 ~87 ~64 ~48 ~87 ~64 double_stone_slab 8 
setblock ~47 ~87 ~16 concrete 8 
setblock ~48 ~87 ~16 coal_ore 0 
setblock ~49 ~87 ~17 stone 0  
fill ~49 ~87 ~63 ~51 ~87 ~63 wool 8 
setblock ~50 ~87 ~17 concrete 8 
setblock ~51 ~87 ~17 wool 8 
setblock ~51 ~87 ~18 concrete 8  
fill ~51 ~87 ~62 ~53 ~87 ~62 wool 8 
setblock ~52 ~87 ~18 double_stone_slab 8 
setblock ~53 ~87 ~18 wool 8 
setblock ~53 ~87 ~19 double_stone_slab 8 
setblock ~53 ~87 ~61 stone 5 
setblock ~54 ~87 ~19 wool 8 
setblock ~54 ~87 ~61 wool 8 
setblock ~55 ~87 ~20 stone 0 
setblock ~55 ~87 ~60 stone 5 
setblock ~56 ~87 ~21 wool 8 
setblock ~56 ~87 ~59 concrete 8 
setblock ~57 ~87 ~21 double_stone_slab 8 
setblock ~57 ~87 ~22 stone 5  
fill ~57 ~87 ~58 ~58 ~87 ~58 concrete 8 
setblock ~57 ~87 ~59 stone 0 
setblock ~58 ~87 ~22 double_stone_slab 8 
setblock ~58 ~87 ~23 wool 8 
setblock ~58 ~87 ~57 stone 0  
fill ~59 ~87 ~23 ~59 ~87 ~24 double_stone_slab 8 
setblock ~59 ~87 ~56 stonebrick 2 
setblock ~59 ~87 ~57 concrete 8 
setblock ~60 ~87 ~25 wool 8 
setblock ~60 ~87 ~55 stone 5  
fill ~61 ~87 ~26 ~61 ~87 ~27 double_stone_slab 8  
fill ~61 ~87 ~53 ~61 ~87 ~54 wool 8 
setblock ~62 ~87 ~27 double_stone_slab 8  
fill ~62 ~87 ~28 ~62 ~87 ~29 wool 8  
fill ~62 ~87 ~51 ~63 ~87 ~51 double_stone_slab 8  
fill ~62 ~87 ~52 ~62 ~87 ~51 double_stone_slab 8 
setblock ~62 ~87 ~53 stone 5  
fill ~63 ~87 ~29 ~63 ~87 ~31 wool 8 
setblock ~63 ~87 ~49 clay 0 
setblock ~63 ~87 ~50 wool 8 
setblock ~64 ~87 ~32 concrete 8  
fill ~64 ~87 ~33 ~64 ~87 ~34 double_stone_slab 8 
setblock ~64 ~87 ~35 wool 8  
fill ~64 ~87 ~45 ~64 ~87 ~46 stone 3  
fill ~64 ~87 ~47 ~64 ~87 ~48 clay 0 
setblock ~65 ~87 ~35 double_stone_slab 8 
setblock ~65 ~87 ~36 wool 8 
setblock ~65 ~87 ~37 clay 0 
setblock ~65 ~87 ~38 double_stone_slab 8  
fill ~65 ~87 ~39 ~65 ~87 ~41 clay 0  
fill ~65 ~87 ~42 ~65 ~87 ~44 double_stone_slab 8 
setblock ~65 ~87 ~45 stone 0 
setblock ~14 ~88 ~34 concrete 8 
setblock ~14 ~88 ~35 stone 0 
setblock ~14 ~88 ~36 stained_hardened_clay 9 
setblock ~14 ~88 ~37 concrete 8  
fill ~14 ~88 ~38 ~14 ~88 ~39 coal_ore 0 
setblock ~14 ~88 ~40 concrete 8 
setblock ~14 ~88 ~41 stained_hardened_clay 9 
setblock ~14 ~88 ~42 stone 5 
setblock ~14 ~88 ~43 coal_ore 0  
fill ~14 ~88 ~44 ~14 ~88 ~45 stained_hardened_clay 9 
setblock ~14 ~88 ~46 stonebrick 2 
setblock ~15 ~88 ~31 concrete 8 
setblock ~15 ~88 ~32 stone 0 
setblock ~15 ~88 ~33 stonebrick 2 
setblock ~15 ~88 ~34 coal_ore 0 
setblock ~15 ~88 ~46 coal_ore 0 
setblock ~15 ~88 ~47 stained_hardened_clay 9 
setblock ~15 ~88 ~48 stonebrick 2 
setblock ~15 ~88 ~49 stained_hardened_clay 9 
setblock ~16 ~88 ~29 stone 5 
setblock ~16 ~88 ~30 stonebrick 2 
setblock ~16 ~88 ~31 wool 8 
setblock ~16 ~88 ~49 coal_ore 0  
fill ~16 ~88 ~50 ~16 ~88 ~51 stained_hardened_clay 9 
setblock ~17 ~88 ~27 concrete 8 
setblock ~17 ~88 ~28 stone 0  
fill ~17 ~88 ~52 ~17 ~88 ~53 stained_hardened_clay 9 
setblock ~18 ~88 ~25 wool 8 
setblock ~18 ~88 ~26 concrete 8  
fill ~18 ~88 ~54 ~18 ~88 ~55 stained_hardened_clay 9 
setblock ~19 ~88 ~24 wool 8 
setblock ~19 ~88 ~25 stone 0  
fill ~19 ~88 ~55 ~19 ~88 ~56 coal_ore 0 
setblock ~20 ~88 ~23 double_stone_slab 8 
setblock ~20 ~88 ~24 stone 5 
setblock ~20 ~88 ~56 coal_ore 0 
setblock ~20 ~88 ~57 stained_hardened_clay 9 
setblock ~21 ~88 ~22 wool 8 
setblock ~21 ~88 ~58 coal_ore 0 
setblock ~22 ~88 ~21 double_stone_slab 8 
setblock ~22 ~88 ~59 stone 0  
fill ~23 ~88 ~20 ~24 ~88 ~20 wool 8 
setblock ~23 ~88 ~60 wool 8 
setblock ~24 ~88 ~19 double_stone_slab 8 
setblock ~24 ~88 ~60 concrete 8 
setblock ~24 ~88 ~61 wool 8 
setblock ~25 ~88 ~18 clay 0 
setblock ~25 ~88 ~19 wool 8 
setblock ~25 ~88 ~61 stone 0 
setblock ~25 ~88 ~62 wool 8 
setblock ~26 ~88 ~18 wool 8 
setblock ~26 ~88 ~62 concrete 8 
setblock ~27 ~88 ~17 wool 8 
setblock ~27 ~88 ~63 wool 8 
setblock ~28 ~88 ~17 double_stone_slab 8 
setblock ~28 ~88 ~63 stone 5 
setblock ~29 ~88 ~16 concrete 8 
setblock ~29 ~88 ~64 wool 8 
setblock ~30 ~88 ~16 wool 8 
setblock ~30 ~88 ~64 double_stone_slab 8 
setblock ~31 ~88 ~15 stone 0 
setblock ~31 ~88 ~16 concrete 8 
setblock ~31 ~88 ~64 stone 5 
setblock ~31 ~88 ~65 wool 8 
setblock ~32 ~88 ~15 double_stone_slab 8 
setblock ~32 ~88 ~65 concrete 8 
setblock ~33 ~88 ~15 stone 0  
fill ~33 ~88 ~65 ~34 ~88 ~65 double_stone_slab 8  
fill ~34 ~88 ~14 ~36 ~88 ~14 wool 8  
fill ~34 ~88 ~15 ~34 ~88 ~14 wool 8  
fill ~34 ~88 ~66 ~35 ~88 ~66 double_stone_slab 8  
fill ~36 ~88 ~66 ~37 ~88 ~66 wool 8 
setblock ~37 ~88 ~14 concrete 8 
setblock ~38 ~88 ~14 stone 5  
fill ~38 ~88 ~66 ~39 ~88 ~66 stone 5 
setblock ~39 ~88 ~14 wool 8  
fill ~40 ~88 ~14 ~41 ~88 ~14 stone 5  
fill ~40 ~88 ~66 ~41 ~88 ~66 double_stone_slab 8  
fill ~42 ~88 ~14 ~43 ~88 ~14 coal_ore 0 
setblock ~42 ~88 ~66 wool 8  
fill ~43 ~88 ~66 ~46 ~88 ~66 double_stone_slab 8 
setblock ~44 ~88 ~14 wool 8 
setblock ~45 ~88 ~14 stone 0 
setblock ~46 ~88 ~14 stonebrick 2 
setblock ~46 ~88 ~15 coal_ore 0 
setblock ~46 ~88 ~65 double_stone_slab 8 
setblock ~47 ~88 ~15 stained_hardened_clay 9 
setblock ~47 ~88 ~65 wool 8 
setblock ~48 ~88 ~15 coal_ore 0  
fill ~48 ~88 ~65 ~49 ~88 ~65 double_stone_slab 8 
setblock ~49 ~88 ~15 concrete 8  
fill ~49 ~88 ~16 ~51 ~88 ~16 stone 0 
setblock ~49 ~88 ~64 double_stone_slab 8  
fill ~50 ~88 ~64 ~51 ~88 ~64 wool 8 
setblock ~52 ~88 ~17 double_stone_slab 8 
setblock ~52 ~88 ~63 wool 8 
setblock ~53 ~88 ~17 wool 8 
setblock ~53 ~88 ~63 double_stone_slab 8  
fill ~54 ~88 ~18 ~55 ~88 ~18 wool 8 
setblock ~54 ~88 ~62 double_stone_slab 8 
setblock ~55 ~88 ~19 double_stone_slab 8 
setblock ~55 ~88 ~61 stone 0 
setblock ~55 ~88 ~62 wool 8 
setblock ~56 ~88 ~19 wool 8 
setblock ~56 ~88 ~20 double_stone_slab 8  
fill ~56 ~88 ~60 ~56 ~88 ~61 stone 5 
setblock ~57 ~88 ~20 wool 8 
setblock ~57 ~88 ~60 concrete 8 
setblock ~58 ~88 ~21 wool 8 
setblock ~58 ~88 ~59 stone 0 
setblock ~59 ~88 ~22 clay 0 
setblock ~59 ~88 ~58 stone 5  
fill ~60 ~88 ~23 ~60 ~88 ~24 double_stone_slab 8  
fill ~60 ~88 ~56 ~60 ~88 ~57 stone 0  
fill ~61 ~88 ~24 ~61 ~88 ~25 double_stone_slab 8  
fill ~61 ~88 ~55 ~61 ~88 ~56 wool 8  
fill ~62 ~88 ~25 ~62 ~88 ~26 double_stone_slab 8  
fill ~62 ~88 ~54 ~62 ~88 ~55 double_stone_slab 8 
setblock ~63 ~88 ~27 double_stone_slab 8 
setblock ~63 ~88 ~28 wool 8  
fill ~63 ~88 ~52 ~63 ~88 ~53 wool 8 
setblock ~64 ~88 ~29 wool 8 
setblock ~64 ~88 ~30 stone 5 
setblock ~64 ~88 ~31 stone 0 
setblock ~64 ~88 ~49 wool 8 
setblock ~64 ~88 ~50 stone 5 
setblock ~64 ~88 ~51 concrete 8 
setblock ~65 ~88 ~31 wool 8  
fill ~65 ~88 ~32 ~65 ~88 ~33 double_stone_slab 8 
setblock ~65 ~88 ~34 wool 8  
fill ~65 ~88 ~46 ~66 ~88 ~46 clay 0  
fill ~65 ~88 ~47 ~65 ~88 ~48 clay 0 
setblock ~65 ~88 ~49 double_stone_slab 8 
setblock ~66 ~88 ~34 concrete 8 
setblock ~66 ~88 ~35 double_stone_slab 8 
setblock ~66 ~88 ~36 stone 5  
fill ~66 ~88 ~37 ~66 ~88 ~38 double_stone_slab 8 
setblock ~66 ~88 ~39 clay 0 
setblock ~66 ~88 ~40 stone 3 
setblock ~66 ~88 ~41 clay 0 
setblock ~66 ~88 ~42 stone 3 
setblock ~66 ~88 ~43 double_stone_slab 8 
setblock ~66 ~88 ~44 stone 3 
setblock ~66 ~88 ~45 clay 0 
setblock ~13 ~89 ~34 stone 5 
setblock ~13 ~89 ~35 wool 8  
fill ~13 ~89 ~36 ~13 ~89 ~38 stained_hardened_clay 9 
setblock ~13 ~89 ~39 concrete 8 
setblock ~13 ~89 ~40 stone 5 
setblock ~13 ~89 ~41 coal_ore 0 
setblock ~13 ~89 ~42 stonebrick 2 
setblock ~13 ~89 ~43 coal_ore 0 
setblock ~13 ~89 ~44 stonebrick 2  
fill ~13 ~89 ~45 ~13 ~89 ~46 stained_hardened_clay 9  
fill ~14 ~89 ~31 ~14 ~89 ~32 stained_hardened_clay 9 
setblock ~14 ~89 ~33 stonebrick 2 
setblock ~14 ~89 ~47 stained_hardened_clay 9 
setblock ~14 ~89 ~48 coal_ore 0 
setblock ~14 ~89 ~49 stained_hardened_clay 9 
setblock ~15 ~89 ~28 stonebrick 2  
fill ~15 ~89 ~29 ~15 ~89 ~30 concrete 8  
fill ~15 ~89 ~50 ~15 ~89 ~52 stained_hardened_clay 9 
setblock ~16 ~89 ~26 double_stone_slab 8 
setblock ~16 ~89 ~27 wool 8 
setblock ~16 ~89 ~28 concrete 8  
fill ~16 ~89 ~52 ~16 ~89 ~54 stained_hardened_clay 9 
setblock ~17 ~89 ~25 stone 5 
setblock ~17 ~89 ~26 concrete 8 
setblock ~17 ~89 ~54 stone 0 
setblock ~17 ~89 ~55 stained_hardened_clay 9  
fill ~18 ~89 ~23 ~18 ~89 ~24 double_stone_slab 8  
fill ~18 ~89 ~56 ~18 ~89 ~57 stained_hardened_clay 9  
fill ~19 ~89 ~22 ~19 ~89 ~23 stone 5 
setblock ~19 ~89 ~57 stained_hardened_clay 9 
setblock ~19 ~89 ~58 coal_ore 0 
setblock ~20 ~89 ~21 wool 8 
setblock ~20 ~89 ~22 double_stone_slab 8 
setblock ~20 ~89 ~58 stained_hardened_clay 9 
setblock ~20 ~89 ~59 coal_ore 0  
fill ~21 ~89 ~20 ~21 ~89 ~21 double_stone_slab 8 
setblock ~21 ~89 ~59 concrete 8  
fill ~21 ~89 ~60 ~22 ~89 ~60 wool 8  
fill ~22 ~89 ~19 ~23 ~89 ~19 double_stone_slab 8 
setblock ~22 ~89 ~20 wool 8 
setblock ~22 ~89 ~61 stonebrick 2 
setblock ~23 ~89 ~18 stone 0 
setblock ~23 ~89 ~61 concrete 8  
fill ~23 ~89 ~62 ~24 ~89 ~62 stone 0 
setblock ~24 ~89 ~18 wool 8  
fill ~25 ~89 ~17 ~26 ~89 ~17 double_stone_slab 8 
setblock ~25 ~89 ~63 wool 8 
setblock ~26 ~89 ~16 double_stone_slab 8 
setblock ~26 ~89 ~63 double_stone_slab 8   

KittysCommands:  
setblock ~26 ~89 ~64 coal_ore 0  
fill ~27 ~89 ~16 ~28 ~89 ~16 clay 0 
setblock ~27 ~89 ~64 concrete 8  
fill ~28 ~89 ~15 ~29 ~89 ~15 double_stone_slab 8 
setblock ~28 ~89 ~64 stone 5 
setblock ~28 ~89 ~65 wool 8  
fill ~29 ~89 ~65 ~30 ~89 ~65 double_stone_slab 8 
setblock ~30 ~89 ~15 stone 5 
setblock ~31 ~89 ~14 stone 5 
setblock ~31 ~89 ~66 wool 8 
setblock ~32 ~89 ~14 concrete 8  
fill ~32 ~89 ~66 ~33 ~89 ~66 double_stone_slab 8 
setblock ~33 ~89 ~14 stone 5 
setblock ~34 ~89 ~13 stone 5 
setblock ~34 ~89 ~67 wool 8 
setblock ~35 ~89 ~13 stone 0 
setblock ~35 ~89 ~67 stone 0 
setblock ~36 ~89 ~13 wool 8 
setblock ~36 ~89 ~67 wool 8  
fill ~37 ~89 ~13 ~38 ~89 ~13 concrete 8 
setblock ~37 ~89 ~67 stone 5  
fill ~38 ~89 ~67 ~40 ~89 ~67 double_stone_slab 8 
setblock ~39 ~89 ~13 wool 8 
setblock ~40 ~89 ~13 stone 5 
setblock ~41 ~89 ~13 stone 0 
setblock ~41 ~89 ~67 clay 0 
setblock ~42 ~89 ~13 stone 5  
fill ~42 ~89 ~67 ~45 ~89 ~67 double_stone_slab 8 
setblock ~43 ~89 ~13 concrete 8 
setblock ~44 ~89 ~13 stonebrick 2  
fill ~45 ~89 ~13 ~46 ~89 ~13 concrete 8 
setblock ~46 ~89 ~67 wool 8 
setblock ~47 ~89 ~14 stained_hardened_clay 9  
fill ~47 ~89 ~66 ~49 ~89 ~66 double_stone_slab 8 
setblock ~48 ~89 ~14 wool 8 
setblock ~49 ~89 ~14 stone 5 
setblock ~50 ~89 ~15 double_stone_slab 8  
fill ~50 ~89 ~65 ~52 ~89 ~65 wool 8 
setblock ~51 ~89 ~15 concrete 8 
setblock ~52 ~89 ~15 double_stone_slab 8  
fill ~52 ~89 ~16 ~54 ~89 ~16 wool 8 
setblock ~52 ~89 ~64 wool 8  
fill ~53 ~89 ~64 ~54 ~89 ~64 double_stone_slab 8 
setblock ~54 ~89 ~17 stone 0 
setblock ~54 ~89 ~63 wool 8 
setblock ~55 ~89 ~17 stone 5 
setblock ~55 ~89 ~63 concrete 8 
setblock ~56 ~89 ~18 wool 8 
setblock ~56 ~89 ~62 stone 5 
setblock ~57 ~89 ~18 stone 5 
setblock ~57 ~89 ~19 wool 8 
setblock ~57 ~89 ~61 wool 8 
setblock ~57 ~89 ~62 coal_ore 0 
setblock ~58 ~89 ~19 double_stone_slab 8 
setblock ~58 ~89 ~20 wool 8 
setblock ~58 ~89 ~60 stone 5 
setblock ~58 ~89 ~61 concrete 8 
setblock ~59 ~89 ~20 double_stone_slab 8  
fill ~59 ~89 ~21 ~60 ~89 ~21 stone 3 
setblock ~59 ~89 ~59 coal_ore 0 
setblock ~59 ~89 ~60 stone 0 
setblock ~60 ~89 ~22 double_stone_slab 8  
fill ~60 ~89 ~58 ~61 ~89 ~58 stone 5  
fill ~60 ~89 ~59 ~60 ~89 ~58 stone 5 
setblock ~61 ~89 ~22 stone 0 
setblock ~61 ~89 ~23 double_stone_slab 8  
fill ~61 ~89 ~57 ~62 ~89 ~57 stone 0 
setblock ~62 ~89 ~23 wool 8 
setblock ~62 ~89 ~24 double_stone_slab 8 
setblock ~62 ~89 ~56 wool 8 
setblock ~63 ~89 ~25 clay 0 
setblock ~63 ~89 ~26 double_stone_slab 8 
setblock ~63 ~89 ~54 double_stone_slab 8 
setblock ~63 ~89 ~55 wool 8 
setblock ~64 ~89 ~26 clay 0  
fill ~64 ~89 ~27 ~64 ~89 ~28 double_stone_slab 8  
fill ~64 ~89 ~52 ~65 ~89 ~52 wool 8  
fill ~64 ~89 ~53 ~64 ~89 ~54 wool 8  
fill ~65 ~89 ~28 ~65 ~89 ~30 wool 8  
fill ~65 ~89 ~50 ~65 ~89 ~51 clay 0 
setblock ~66 ~89 ~31 wool 8 
setblock ~66 ~89 ~32 stone 5 
setblock ~66 ~89 ~33 wool 8  
fill ~66 ~89 ~47 ~66 ~89 ~48 clay 0 
setblock ~66 ~89 ~49 stone 3  
fill ~67 ~89 ~34 ~67 ~89 ~35 wool 8 
setblock ~67 ~89 ~36 clay 0 
setblock ~67 ~89 ~37 double_stone_slab 8 
setblock ~67 ~89 ~38 stone 3  
fill ~67 ~89 ~39 ~67 ~89 ~41 clay 0 
setblock ~67 ~89 ~42 stone 3 
setblock ~67 ~89 ~43 clay 0 
setblock ~67 ~89 ~44 wool 8 
setblock ~67 ~89 ~45 clay 0 
setblock ~67 ~89 ~46 double_stone_slab 8 
setblock ~12 ~90 ~34 concrete 8 
setblock ~12 ~90 ~35 stone 0 
setblock ~12 ~90 ~36 stonebrick 2 
setblock ~12 ~90 ~37 stained_hardened_clay 9  
fill ~12 ~90 ~38 ~12 ~90 ~39 concrete 8 
setblock ~12 ~90 ~40 stone 5 
setblock ~12 ~90 ~41 concrete 8 
setblock ~12 ~90 ~42 stonebrick 2 
setblock ~12 ~90 ~43 stone 0 
setblock ~12 ~90 ~44 concrete 8  
fill ~12 ~90 ~45 ~12 ~90 ~46 stained_hardened_clay 9 
setblock ~13 ~90 ~31 stonebrick 2 
setblock ~13 ~90 ~32 concrete 8 
setblock ~13 ~90 ~33 coal_ore 0 
setblock ~13 ~90 ~47 stained_hardened_clay 9  
fill ~13 ~90 ~48 ~13 ~90 ~49 coal_ore 0 
setblock ~14 ~90 ~28 stone 5 
setblock ~14 ~90 ~29 double_stone_slab 8 
setblock ~14 ~90 ~30 stone 5 
setblock ~14 ~90 ~50 coal_ore 0 
setblock ~14 ~90 ~51 stained_hardened_clay 9 
setblock ~14 ~90 ~52 wool 7 
setblock ~15 ~90 ~26 double_stone_slab 8 
setblock ~15 ~90 ~27 stone 0 
setblock ~15 ~90 ~53 stained_hardened_clay 9 
setblock ~15 ~90 ~54 coal_ore 0 
setblock ~16 ~90 ~25 wool 8 
setblock ~16 ~90 ~55 stonebrick 2 
setblock ~17 ~90 ~23 stone 4 
setblock ~17 ~90 ~24 clay 0 
setblock ~17 ~90 ~56 coal_ore 0 
setblock ~17 ~90 ~57 concrete 8 
setblock ~18 ~90 ~22 double_stone_slab 8 
setblock ~18 ~90 ~58 coal_ore 0 
setblock ~19 ~90 ~21 wool 8 
setblock ~19 ~90 ~59 stone 5 
setblock ~20 ~90 ~20 concrete 8 
setblock ~20 ~90 ~60 concrete 8 
setblock ~21 ~90 ~19 wool 8 
setblock ~21 ~90 ~61 wool 8 
setblock ~22 ~90 ~18 wool 8 
setblock ~22 ~90 ~62 double_stone_slab 8  
fill ~23 ~90 ~17 ~24 ~90 ~17 wool 8 
setblock ~23 ~90 ~63 concrete 8 
setblock ~24 ~90 ~63 stone 0 
setblock ~25 ~90 ~16 clay 0 
setblock ~25 ~90 ~64 wool 8  
fill ~26 ~90 ~15 ~27 ~90 ~15 double_stone_slab 8 
setblock ~26 ~90 ~65 stone 5 
setblock ~27 ~90 ~65 double_stone_slab 8  
fill ~28 ~90 ~14 ~29 ~90 ~14 double_stone_slab 8  
fill ~28 ~90 ~66 ~30 ~90 ~66 wool 8 
setblock ~30 ~90 ~14 wool 8 
setblock ~31 ~90 ~13 stone 0  
fill ~31 ~90 ~67 ~33 ~90 ~67 double_stone_slab 8 
setblock ~32 ~90 ~13 double_stone_slab 8 
setblock ~33 ~90 ~13 stone 5  
fill ~34 ~90 ~12 ~36 ~90 ~12 wool 8 
setblock ~34 ~90 ~68 wool 8  
fill ~35 ~90 ~68 ~36 ~90 ~68 double_stone_slab 8 
setblock ~37 ~90 ~12 concrete 8 
setblock ~37 ~90 ~68 stone 0 
setblock ~38 ~90 ~12 coal_ore 0 
setblock ~38 ~90 ~68 double_stone_slab 8 
setblock ~39 ~90 ~12 stonebrick 2 
setblock ~39 ~90 ~68 wool 8 
setblock ~40 ~90 ~12 stained_hardened_clay 9 
setblock ~40 ~90 ~68 clay 0 
setblock ~41 ~90 ~12 coal_ore 0  
fill ~41 ~90 ~68 ~46 ~90 ~68 double_stone_slab 8  
fill ~42 ~90 ~12 ~45 ~90 ~12 concrete 8 
setblock ~46 ~90 ~12 stone 5  
fill ~47 ~90 ~13 ~48 ~90 ~13 concrete 8 
setblock ~47 ~90 ~67 double_stone_slab 8 
setblock ~48 ~90 ~67 clay 0 
setblock ~49 ~90 ~13 stone 0 
setblock ~49 ~90 ~67 double_stone_slab 8 
setblock ~50 ~90 ~14 stone 0 
setblock ~50 ~90 ~66 double_stone_slab 8 
setblock ~51 ~90 ~14 wool 8 
setblock ~51 ~90 ~66 wool 8 
setblock ~52 ~90 ~14 stone 0 
setblock ~52 ~90 ~66 double_stone_slab 8  
fill ~53 ~90 ~15 ~54 ~90 ~15 stone 0  
fill ~53 ~90 ~65 ~54 ~90 ~65 double_stone_slab 8 
setblock ~55 ~90 ~16 stone 5 
setblock ~55 ~90 ~64 concrete 8  
fill ~56 ~90 ~17 ~57 ~90 ~17 wool 8  
fill ~56 ~90 ~63 ~57 ~90 ~63 stone 0 
setblock ~58 ~90 ~18 wool 8 
setblock ~58 ~90 ~62 wool 8 
setblock ~59 ~90 ~19 double_stone_slab 8 
setblock ~59 ~90 ~61 stone 5 
setblock ~60 ~90 ~20 double_stone_slab 8 
setblock ~60 ~90 ~60 concrete 8 
setblock ~61 ~90 ~21 double_stone_slab 8 
setblock ~61 ~90 ~59 wool 8 
setblock ~62 ~90 ~22 double_stone_slab 8 
setblock ~62 ~90 ~58 double_stone_slab 8  
fill ~63 ~90 ~23 ~63 ~90 ~24 double_stone_slab 8  
fill ~63 ~90 ~56 ~63 ~90 ~57 wool 8 
setblock ~64 ~90 ~25 wool 8 
setblock ~64 ~90 ~55 wool 8  
fill ~65 ~90 ~26 ~65 ~90 ~27 wool 8 
setblock ~65 ~90 ~53 double_stone_slab 8 
setblock ~65 ~90 ~54 wool 8  
fill ~66 ~90 ~28 ~66 ~90 ~29 double_stone_slab 8 
setblock ~66 ~90 ~30 wool 8  
fill ~66 ~90 ~50 ~66 ~90 ~51 double_stone_slab 8 
setblock ~66 ~90 ~52 clay 0 
setblock ~67 ~90 ~31 double_stone_slab 8 
setblock ~67 ~90 ~32 concrete 8 
setblock ~67 ~90 ~33 wool 8 
setblock ~67 ~90 ~47 double_stone_slab 8  
fill ~67 ~90 ~48 ~67 ~90 ~49 clay 0 
setblock ~68 ~90 ~34 wool 8  
fill ~68 ~90 ~35 ~68 ~90 ~36 double_stone_slab 8  
fill ~68 ~90 ~37 ~68 ~90 ~38 clay 0 
setblock ~68 ~90 ~39 stone 3  
fill ~68 ~90 ~40 ~68 ~90 ~41 clay 0  
fill ~68 ~90 ~42 ~68 ~90 ~43 stone 3 
setblock ~68 ~90 ~44 double_stone_slab 8 
setblock ~68 ~90 ~45 stone 4 
setblock ~68 ~90 ~46 clay 0  
fill ~11 ~91 ~34 ~11 ~91 ~35 concrete 8  
fill ~11 ~91 ~36 ~11 ~91 ~37 stone 0 
setblock ~11 ~91 ~38 stonebrick 2 
setblock ~11 ~91 ~39 stone 5 
setblock ~11 ~91 ~40 wool 8 
setblock ~11 ~91 ~41 stonebrick 2  
fill ~11 ~91 ~42 ~11 ~91 ~43 concrete 8 
setblock ~11 ~91 ~44 wool 8 
setblock ~11 ~91 ~45 coal_ore 0 
setblock ~11 ~91 ~46 stained_hardened_clay 9  
fill ~12 ~91 ~31 ~12 ~91 ~32 concrete 8 
setblock ~12 ~91 ~33 stone 5  
fill ~12 ~91 ~47 ~12 ~91 ~49 coal_ore 0 
setblock ~13 ~91 ~28 stone 5 
setblock ~13 ~91 ~29 concrete 8 
setblock ~13 ~91 ~30 stone 5 
setblock ~13 ~91 ~50 coal_ore 0 
setblock ~13 ~91 ~51 stained_hardened_clay 9 
setblock ~13 ~91 ~52 wool 7 
setblock ~14 ~91 ~26 clay 0 
setblock ~14 ~91 ~27 wool 8 
setblock ~14 ~91 ~53 coal_ore 0 
setblock ~14 ~91 ~54 stained_hardened_clay 9 
setblock ~15 ~91 ~25 wool 8 
setblock ~15 ~91 ~55 stained_hardened_clay 9 
setblock ~16 ~91 ~23 clay 0 
setblock ~16 ~91 ~24 double_stone_slab 8 
setblock ~16 ~91 ~56 stained_hardened_clay 9 
setblock ~16 ~91 ~57 coal_ore 0 
setblock ~17 ~91 ~22 stone 3 
setblock ~17 ~91 ~58 concrete 8 
setblock ~18 ~91 ~21 double_stone_slab 8 
setblock ~18 ~91 ~59 coal_ore 0 
setblock ~19 ~91 ~20 double_stone_slab 8 
setblock ~19 ~91 ~60 wool 8 
setblock ~20 ~91 ~19 wool 8 
setblock ~20 ~91 ~61 wool 8 
setblock ~21 ~91 ~18 stone 0 
setblock ~21 ~91 ~62 double_stone_slab 8 
setblock ~22 ~91 ~17 double_stone_slab 8 
setblock ~22 ~91 ~63 stone 5  
fill ~23 ~91 ~16 ~24 ~91 ~16 double_stone_slab 8 
setblock ~23 ~91 ~64 concrete 8 
setblock ~24 ~91 ~64 stone 0 
setblock ~25 ~91 ~15 double_stone_slab 8 
setblock ~25 ~91 ~65 wool 8 
setblock ~26 ~91 ~14 wool 8 
setblock ~26 ~91 ~66 stone 5 
setblock ~27 ~91 ~14 double_stone_slab 8 
setblock ~27 ~91 ~66 clay 0 
setblock ~28 ~91 ~13 clay 0 
setblock ~28 ~91 ~67 stone 5 
setblock ~29 ~91 ~13 double_stone_slab 8 
setblock ~29 ~91 ~67 concrete 8 
setblock ~30 ~91 ~13 wool 8 
setblock ~30 ~91 ~67 double_stone_slab 8 
setblock ~31 ~91 ~12 wool 8  
fill ~31 ~91 ~68 ~32 ~91 ~68 double_stone_slab 8 
setblock ~32 ~91 ~12 stone 5 
setblock ~33 ~91 ~12 stone 0 
setblock ~33 ~91 ~68 wool 8 
setblock ~34 ~91 ~11 coal_ore 0  
fill ~34 ~91 ~69 ~34 ~92 ~69 double_stone_slab 8 
setblock ~35 ~91 ~11 concrete 8 
setblock ~35 ~91 ~69 wool 8 
setblock ~36 ~91 ~11 stone 5 
setblock ~36 ~91 ~69 double_stone_slab 8  
fill ~37 ~91 ~11 ~38 ~91 ~11 stone 0  
fill ~37 ~91 ~69 ~38 ~91 ~69 wool 8 
setblock ~39 ~91 ~11 coal_ore 0  
fill ~39 ~91 ~69 ~43 ~91 ~69 double_stone_slab 8 
setblock ~40 ~91 ~11 stained_hardened_clay 9  
fill ~41 ~91 ~11 ~42 ~91 ~11 concrete 8 
setblock ~43 ~91 ~11 coal_ore 0 
setblock ~44 ~91 ~11 concrete 8 
setblock ~44 ~91 ~69 wool 8 
setblock ~45 ~91 ~11 coal_ore 0  
fill ~45 ~91 ~69 ~46 ~91 ~69 double_stone_slab 8 
setblock ~46 ~91 ~11 concrete 8 
setblock ~47 ~91 ~12 coal_ore 0  
fill ~47 ~91 ~68 ~49 ~91 ~68 double_stone_slab 8 
setblock ~48 ~91 ~12 wool 8 
setblock ~49 ~91 ~12 stone 0  
fill ~50 ~91 ~13 ~51 ~91 ~13 concrete 8 
setblock ~50 ~91 ~67 double_stone_slab 8 
setblock ~51 ~91 ~67 wool 8 
setblock ~52 ~91 ~13 wool 8 
setblock ~52 ~91 ~67 clay 0 
setblock ~53 ~91 ~14 wool 8  
fill ~53 ~91 ~66 ~54 ~91 ~66 double_stone_slab 8 
setblock ~54 ~91 ~14 concrete 8 
setblock ~55 ~91 ~15 wool 8 
setblock ~55 ~91 ~65 stone 0 
setblock ~56 ~91 ~16 wool 8 
setblock ~56 ~91 ~64 stonebrick 2 
setblock ~57 ~91 ~16 stone 5 
setblock ~57 ~91 ~64 concrete 8 
setblock ~58 ~91 ~17 wool 8 
setblock ~58 ~91 ~63 stone 5 
setblock ~59 ~91 ~18 double_stone_slab 8 
setblock ~59 ~91 ~62 stone 0 
setblock ~60 ~91 ~19 double_stone_slab 8 
setblock ~60 ~91 ~61 wool 8 
setblock ~61 ~91 ~20 clay 0 
setblock ~61 ~91 ~60 stone 0 
setblock ~62 ~91 ~21 wool 8 
setblock ~62 ~91 ~59 wool 8 
setblock ~63 ~91 ~22 wool 8 
setblock ~63 ~91 ~58 wool 8  
fill ~64 ~91 ~23 ~64 ~91 ~24 double_stone_slab 8  
fill ~64 ~91 ~56 ~64 ~91 ~57 wool 8 
setblock ~65 ~91 ~25 double_stone_slab 8 
setblock ~65 ~91 ~55 wool 8 
setblock ~66 ~91 ~26 double_stone_slab 8 
setblock ~66 ~91 ~27 wool 8  
fill ~66 ~91 ~53 ~66 ~91 ~54 wool 8  
fill ~67 ~91 ~28 ~67 ~91 ~30 double_stone_slab 8 
setblock ~67 ~91 ~50 double_stone_slab 8 
setblock ~67 ~91 ~51 wool 8 
setblock ~67 ~91 ~52 double_stone_slab 8 
setblock ~68 ~91 ~31 clay 0 
setblock ~68 ~91 ~32 stone 3 
setblock ~68 ~91 ~33 double_stone_slab 8 
setblock ~68 ~91 ~47 clay 0  
fill ~68 ~91 ~48 ~68 ~91 ~49 double_stone_slab 8 
setblock ~69 ~91 ~34 stone 0 
setblock ~69 ~91 ~35 stone 3 
setblock ~69 ~91 ~36 double_stone_slab 8  
fill ~69 ~91 ~37 ~69 ~91 ~38 clay 0 
setblock ~69 ~91 ~39 double_stone_slab 8  
fill ~69 ~91 ~40 ~69 ~91 ~41 clay 0 
setblock ~69 ~91 ~42 double_stone_slab 8  
fill ~69 ~91 ~43 ~69 ~91 ~44 clay 0 
setblock ~69 ~91 ~45 stone 4 
setblock ~69 ~91 ~46 clay 0 
setblock ~10 ~92 ~35 stone 5  
fill ~10 ~92 ~36 ~10 ~92 ~37 double_stone_slab 8 
setblock ~10 ~92 ~38 coal_ore 0 
setblock ~10 ~92 ~39 stone 0 
setblock ~10 ~92 ~40 coal_ore 0 
setblock ~10 ~92 ~41 stained_hardened_clay 9  
fill ~10 ~92 ~42 ~10 ~92 ~44 concrete 8 
setblock ~10 ~92 ~45 stained_hardened_clay 9 
setblock ~11 ~92 ~31 concrete 8  
fill ~11 ~92 ~32 ~11 ~92 ~34 stonebrick 2 
setblock ~11 ~92 ~46 concrete 7 
setblock ~11 ~92 ~47 stained_hardened_clay 9  
fill ~11 ~92 ~48 ~11 ~92 ~49 concrete 8  
fill ~12 ~92 ~28 ~12 ~92 ~29 stone 5 
setblock ~12 ~92 ~30 concrete 8 
setblock ~12 ~92 ~50 coal_ore 0 
setblock ~12 ~92 ~51 stained_hardened_clay 9 
setblock ~12 ~92 ~52 coal_ore 0 
setblock ~13 ~92 ~26 wool 8 
setblock ~13 ~92 ~27 double_stone_slab 8 
setblock ~13 ~92 ~53 wool 7 
setblock ~13 ~92 ~54 coal_ore 0 
setblock ~14 ~92 ~25 double_stone_slab 8 
setblock ~14 ~92 ~55 stained_hardened_clay 9  
fill ~15 ~92 ~23 ~15 ~92 ~24 double_stone_slab 8  
fill ~15 ~92 ~56 ~15 ~92 ~57 stained_hardened_clay 9 
setblock ~16 ~92 ~22 clay 0 
setblock ~16 ~92 ~58 stained_hardened_clay 9  
fill ~17 ~92 ~20 ~17 ~92 ~21 double_stone_slab 8 
setblock ~17 ~92 ~59 concrete 8  
fill ~17 ~92 ~60 ~18 ~92 ~60 wool 8  
fill ~18 ~92 ~19 ~19 ~92 ~19 wool 8  
fill ~18 ~92 ~20 ~18 ~92 ~19 wool 8 
setblock ~18 ~92 ~61 wool 8 
setblock ~19 ~92 ~18 stone 5 
setblock ~19 ~92 ~61 double_stone_slab 8 
setblock ~19 ~92 ~62 clay 0 
setblock ~20 ~92 ~17 stone 0 
setblock ~20 ~92 ~18 double_stone_slab 8  
fill ~20 ~92 ~62 ~20 ~92 ~63 wool 8 
setblock ~21 ~92 ~17 stone 5 
setblock ~21 ~92 ~63 wool 8 
setblock ~22 ~92 ~16 clay 0 
setblock ~22 ~92 ~64 coal_ore 0 
setblock ~23 ~92 ~15 double_stone_slab 8 
setblock ~23 ~92 ~65 double_stone_slab 8 
setblock ~24 ~92 ~15 wool 8 
setblock ~24 ~92 ~65 wool 8 
setblock ~25 ~92 ~14 clay 0 
setblock ~25 ~92 ~66 stone 5  
fill ~26 ~92 ~13 ~27 ~92 ~13 double_stone_slab 8  
fill ~26 ~92 ~67 ~27 ~92 ~67 double_stone_slab 8  
fill ~28 ~92 ~12 ~30 ~92 ~12 double_stone_slab 8  
fill ~28 ~92 ~68 ~30 ~92 ~68 double_stone_slab 8 
setblock ~31 ~92 ~11 wool 8 
setblock ~31 ~92 ~69 wool 8 
setblock ~32 ~92 ~11 concrete 8 
setblock ~32 ~92 ~69 clay 0 
setblock ~33 ~92 ~11 stone 0 
setblock ~33 ~92 ~69 wool 8 
setblock ~34 ~92 ~11 concrete 8  
fill ~35 ~92 ~10 ~39 ~92 ~10 concrete 8 
setblock ~35 ~92 ~70 wool 8  
fill ~36 ~92 ~70 ~42 ~92 ~70 double_stone_slab 8 
setblock ~40 ~92 ~10 stained_hardened_clay 9 
setblock ~41 ~92 ~10 coal_ore 0  
fill ~42 ~92 ~10 ~43 ~92 ~10 concrete 8 
setblock ~43 ~92 ~70 clay 0  
fill ~44 ~92 ~10 ~45 ~92 ~10 coal_ore 0 
setblock ~44 ~92 ~70 wool 8 
setblock ~45 ~92 ~70 double_stone_slab 8 
setblock ~46 ~92 ~11 wool 8  
fill ~46 ~92 ~69 ~48 ~92 ~69 double_stone_slab 8 
setblock ~47 ~92 ~11 concrete 8  
fill ~48 ~92 ~11 ~49 ~92 ~11 wool 8 
setblock ~49 ~92 ~69 wool 8 
setblock ~50 ~92 ~12 concrete 8  
fill ~50 ~92 ~68 ~51 ~92 ~68 wool 8  
fill ~51 ~92 ~12 ~52 ~92 ~12 wool 8 
setblock ~52 ~92 ~68 double_stone_slab 8 
setblock ~53 ~92 ~13 wool 8 
setblock ~53 ~92 ~67 double_stone_slab 8 
setblock ~54 ~92 ~13 stone 5 
setblock ~54 ~92 ~67 wool 8 
setblock ~55 ~92 ~14 wool 8 
setblock ~55 ~92 ~66 double_stone_slab 8  
fill ~56 ~92 ~15 ~57 ~92 ~15 wool 8 
setblock ~56 ~92 ~65 wool 8 
setblock ~57 ~92 ~65 concrete 8 
setblock ~58 ~92 ~16 wool 8 
setblock ~58 ~92 ~64 stone 5 
setblock ~59 ~92 ~17 double_stone_slab 8  
fill ~59 ~92 ~63 ~60 ~92 ~63 stone 5 
setblock ~60 ~92 ~17 clay 0 
setblock ~60 ~92 ~18 double_stone_slab 8  
fill ~60 ~92 ~62 ~61 ~92 ~62 wool 8  
fill ~61 ~92 ~18 ~61 ~92 ~19 clay 0 
setblock ~61 ~92 ~61 stone 5  
fill ~62 ~92 ~19 ~62 ~92 ~20 double_stone_slab 8  
fill ~62 ~92 ~60 ~63 ~92 ~60 wool 8  
fill ~62 ~92 ~61 ~62 ~92 ~60 wool 8 
setblock ~63 ~92 ~20 clay 0 
setblock ~63 ~92 ~21 double_stone_slab 8 
setblock ~63 ~92 ~59 wool 8 
setblock ~64 ~92 ~22 double_stone_slab 8 
setblock ~64 ~92 ~58 wool 8  
fill ~65 ~92 ~23 ~65 ~92 ~24 double_stone_slab 8 
setblock ~65 ~92 ~56 double_stone_slab 8 
setblock ~65 ~92 ~57 wool 8 
setblock ~66 ~92 ~25 double_stone_slab 8 
setblock ~66 ~92 ~55 double_stone_slab 8 
setblock ~67 ~92 ~26 clay 0 
setblock ~67 ~92 ~27 double_stone_slab 8 
setblock ~67 ~92 ~53 stone 5 
setblock ~67 ~92 ~54 wool 8  
fill ~68 ~92 ~28 ~68 ~92 ~30 double_stone_slab 8  
fill ~68 ~92 ~50 ~68 ~92 ~51 clay 0 
setblock ~68 ~92 ~52 wool 8  
fill ~69 ~92 ~31 ~69 ~92 ~33 double_stone_slab 8 
setblock ~69 ~92 ~34 stonebrick 2  
fill ~69 ~92 ~46 ~69 ~92 ~48 stone 3 
setblock ~69 ~92 ~49 clay 0 
setblock ~70 ~92 ~35 double_stone_slab 8 
setblock ~70 ~92 ~36 clay 0  
fill ~70 ~92 ~37 ~70 ~92 ~38 double_stone_slab 8 
setblock ~70 ~92 ~39 stone 3 
setblock ~70 ~92 ~40 clay 0 
setblock ~70 ~92 ~41 stone 3 
setblock ~70 ~92 ~42 clay 0 
setblock ~70 ~92 ~43 double_stone_slab 8 
setblock ~70 ~92 ~44 stone 3 
setblock ~70 ~92 ~45 clay 0 
setblock ~9 ~93 ~35 concrete 8 
setblock ~9 ~93 ~36 stone 5 
setblock ~9 ~93 ~37 coal_ore 0 
setblock ~9 ~93 ~38 stained_hardened_clay 9 
setblock ~9 ~93 ~39 stonebrick 2 
setblock ~9 ~93 ~40 stained_hardened_clay 9 
setblock ~9 ~93 ~41 wool 7 
setblock ~9 ~93 ~42 stonebrick 2 
setblock ~9 ~93 ~43 stained_hardened_clay 9 
setblock ~9 ~93 ~44 stonebrick 2  
fill ~9 ~93 ~45 ~9 ~94 ~45 coal_ore 0  
fill ~10 ~93 ~31 ~10 ~94 ~31 concrete 8  
fill ~10 ~93 ~32 ~10 ~93 ~33 concrete 8 
setblock ~10 ~93 ~34 stone 5  
fill ~10 ~93 ~46 ~10 ~93 ~48 stained_hardened_clay 9 
setblock ~10 ~93 ~49 stonebrick 2  
fill ~11 ~93 ~28 ~11 ~93 ~29 wool 8 
setblock ~11 ~93 ~30 coal_ore 0 
setblock ~11 ~93 ~50 coal_ore 0 
setblock ~11 ~93 ~51 stained_hardened_clay 9  
fill ~11 ~93 ~52 ~11 ~94 ~52 coal_ore 0 
setblock ~12 ~93 ~26 clay 0 
setblock ~12 ~93 ~27 stone 0  
fill ~12 ~93 ~53 ~12 ~93 ~54 coal_ore 0 
setblock ~13 ~93 ~25 stone 0 
setblock ~13 ~93 ~55 stained_hardened_clay 9  
fill ~14 ~93 ~23 ~14 ~93 ~24 wool 8 
setblock ~14 ~93 ~56 stained_hardened_clay 9 
setblock ~14 ~93 ~57 coal_ore 0 
setblock ~15 ~93 ~22 stone 5 
setblock ~15 ~93 ~58 stained_hardened_clay 9  
fill ~16 ~93 ~20 ~16 ~93 ~21 double_stone_slab 8 
setblock ~16 ~93 ~59 concrete 8 
setblock ~16 ~93 ~60 wool 8 
setblock ~17 ~93 ~19 wool 8 
setblock ~17 ~93 ~61 double_stone_slab 8 
setblock ~18 ~93 ~18 wool 8 
setblock ~18 ~93 ~62 double_stone_slab 8 
setblock ~19 ~93 ~17 wool 8 
setblock ~19 ~93 ~63 wool 8  
fill ~20 ~93 ~16 ~21 ~93 ~16 double_stone_slab 8  
fill ~20 ~93 ~64 ~21 ~93 ~64 concrete 8 
setblock ~22 ~93 ~15 wool 8 
setblock ~22 ~93 ~65 double_stone_slab 8 
setblock ~23 ~93 ~14 wool 8 
setblock ~23 ~93 ~66 double_stone_slab 8 
setblock ~24 ~93 ~14 double_stone_slab 8 
setblock ~24 ~93 ~66 clay 0 
setblock ~25 ~93 ~13 stone 0 
setblock ~25 ~93 ~67 double_stone_slab 8 
setblock ~26 ~93 ~12 clay 0  
fill ~26 ~93 ~68 ~27 ~93 ~68 wool 8 
setblock ~27 ~93 ~12 double_stone_slab 8 
setblock ~28 ~93 ~11 stone 0  
fill ~28 ~93 ~69 ~29 ~93 ~69 double_stone_slab 8 
setblock ~29 ~93 ~11 clay 0 
setblock ~30 ~93 ~11 double_stone_slab 8 
setblock ~30 ~93 ~69 wool 8 
setblock ~31 ~93 ~10 stone 5  
fill ~31 ~93 ~70 ~33 ~93 ~70 wool 8 
setblock ~32 ~93 ~10 concrete 8 
setblock ~33 ~93 ~10 wool 8 
setblock ~34 ~93 ~10 stone 0 
setblock ~34 ~93 ~70 double_stone_slab 8  
fill ~35 ~93 ~9 ~39 ~93 ~9 concrete 8  
fill ~35 ~93 ~71 ~35 ~94 ~71 clay 0  
fill ~36 ~93 ~71 ~38 ~93 ~71 double_stone_slab 8 
setblock ~39 ~93 ~71 clay 0 
setblock ~40 ~93 ~9 stonebrick 2  
fill ~40 ~93 ~71 ~41 ~93 ~71 double_stone_slab 8 
setblock ~41 ~93 ~9 coal_ore 0  
fill ~42 ~93 ~9 ~45 ~93 ~9 concrete 8  
fill ~42 ~93 ~71 ~43 ~93 ~71 clay 0  
fill ~44 ~93 ~71 ~45 ~93 ~71 double_stone_slab 8 
setblock ~46 ~93 ~10 stonebrick 2 
setblock ~46 ~93 ~70 double_stone_slab 8 
setblock ~47 ~93 ~10 stone 0 
setblock ~47 ~93 ~70 wool 8 
setblock ~48 ~93 ~10 concrete 8 
setblock ~48 ~93 ~70 double_stone_slab 8 
setblock ~49 ~93 ~10 double_stone_slab 8 
setblock ~49 ~93 ~70 wool 8 
setblock ~50 ~93 ~11 wool 8  
fill ~50 ~93 ~69 ~52 ~93 ~69 wool 8 
setblock ~51 ~93 ~11 double_stone_slab 8 
setblock ~52 ~93 ~11 wool 8 
setblock ~53 ~93 ~12 wool 8  
fill ~53 ~93 ~68 ~54 ~93 ~68 wool 8 
setblock ~54 ~93 ~12 double_stone_slab 8 
setblock ~55 ~93 ~13 wool 8 
setblock ~55 ~93 ~67 clay 0 
setblock ~56 ~93 ~14 double_stone_slab 8 
setblock ~56 ~93 ~66 wool 8 
setblock ~57 ~93 ~14 clay 0 
setblock ~57 ~93 ~66 stone 0 
setblock ~58 ~93 ~15 double_stone_slab 8 
setblock ~58 ~93 ~65 wool 8 
setblock ~59 ~93 ~16 clay 0  
fill ~59 ~93 ~64 ~60 ~93 ~64 stone 0 
setblock ~60 ~93 ~16 double_stone_slab 8 
setblock ~61 ~93 ~17 double_stone_slab 8 
setblock ~61 ~93 ~63 stone 0 
setblock ~62 ~93 ~18 double_stone_slab 8 
setblock ~62 ~93 ~62 stone 5 
setblock ~63 ~93 ~19 double_stone_slab 8 
setblock ~63 ~93 ~61 stone 0  
fill ~64 ~93 ~20 ~64 ~93 ~21 wool 8 
setblock ~64 ~93 ~59 wool 8 
setblock ~64 ~93 ~60 stone 5 
setblock ~65 ~93 ~22 double_stone_slab 8 
setblock ~65 ~93 ~58 wool 8 
setblock ~66 ~93 ~23 double_stone_slab 8 
setblock ~66 ~93 ~24 wool 8 
setblock ~66 ~93 ~56 stone 5 
setblock ~66 ~93 ~57 wool 8 
setblock ~67 ~93 ~25 double_stone_slab 8 
setblock ~67 ~93 ~55 wool 8 
setblock ~68 ~93 ~26 clay 0 
setblock ~68 ~93 ~27 double_stone_slab 8  
fill ~68 ~93 ~53 ~68 ~93 ~54 double_stone_slab 8  
fill ~69 ~93 ~28 ~69 ~93 ~30 double_stone_slab 8  
fill ~69 ~93 ~50 ~69 ~93 ~51 wool 8  
fill ~69 ~93 ~52 ~69 ~94 ~52 double_stone_slab 8  
fill ~70 ~93 ~31 ~70 ~94 ~31 double_stone_slab 8  
fill ~70 ~93 ~32 ~70 ~93 ~33 double_stone_slab 8 
setblock ~70 ~93 ~34 wool 8 
setblock ~70 ~93 ~46 clay 0 
setblock ~70 ~93 ~47 stone 3  
fill ~70 ~93 ~48 ~70 ~93 ~49 clay 0  
fill ~71 ~93 ~35 ~71 ~94 ~35 clay 0  
fill ~71 ~93 ~36 ~71 ~93 ~40 clay 0  
fill ~71 ~93 ~41 ~71 ~93 ~42 stone 3 
setblock ~71 ~93 ~43 clay 0  
fill ~71 ~93 ~44 ~71 ~94 ~44 stone 3 
setblock ~71 ~93 ~45 clay 0 
setblock ~8 ~94 ~37 coal_ore 0  
fill ~8 ~94 ~38 ~8 ~94 ~39 stained_hardened_clay 9 
setblock ~8 ~94 ~40 concrete 7 
setblock ~8 ~94 ~41 wool 7  
fill ~8 ~94 ~42 ~8 ~94 ~43 coal_ore 0  
fill ~9 ~94 ~32 ~9 ~94 ~33 coal_ore 0 
setblock ~9 ~94 ~34 stonebrick 2 
setblock ~9 ~94 ~35 stone 5 
setblock ~9 ~94 ~36 concrete 8 
setblock ~9 ~94 ~44 coal_ore 0 
setblock ~9 ~94 ~46 coal_ore 0 
setblock ~9 ~94 ~47 stained_hardened_clay 9 
setblock ~9 ~94 ~48 coal_ore 0 
setblock ~10 ~94 ~29 stone 5 
setblock ~10 ~94 ~30 concrete 8 
setblock ~10 ~94 ~49 coal_ore 0 
setblock ~10 ~94 ~50 concrete 8 
setblock ~10 ~94 ~51 stained_hardened_clay 9 
setblock ~11 ~94 ~27 wool 8 
setblock ~11 ~94 ~28 double_stone_slab 8 
setblock ~11 ~94 ~53 stained_hardened_clay 9  
fill ~12 ~94 ~25 ~12 ~94 ~26 double_stone_slab 8 
setblock ~12 ~94 ~54 stained_hardened_clay 9 
setblock ~12 ~94 ~55 concrete 7 
setblock ~13 ~94 ~23 concrete 8 
setblock ~13 ~94 ~24 wool 8  
fill ~13 ~94 ~56 ~13 ~94 ~57 stained_hardened_clay 9 
setblock ~14 ~94 ~22 wool 8 
setblock ~14 ~94 ~58 concrete 8  
fill ~15 ~94 ~20 ~15 ~94 ~21 wool 8 
setblock ~15 ~94 ~59 stonebrick 2 
setblock ~15 ~94 ~60 stone 0 
setblock ~16 ~94 ~19 double_stone_slab 8 
setblock ~16 ~94 ~61 wool 8 
setblock ~17 ~94 ~18 wool 8 
setblock ~17 ~94 ~62 double_stone_slab 8 
setblock ~18 ~94 ~17 wool 8 
setblock ~18 ~94 ~63 clay 0 
setblock ~19 ~94 ~16 wool 8 
setblock ~19 ~94 ~64 double_stone_slab 8  
fill ~20 ~94 ~15 ~20 ~95 ~15 wool 8 
setblock ~20 ~94 ~65 double_stone_slab 8 
setblock ~21 ~94 ~15 double_stone_slab 8 
setblock ~21 ~94 ~65 clay 0 
setblock ~22 ~94 ~14 double_stone_slab 8 
setblock ~22 ~94 ~66 double_stone_slab 8 
setblock ~23 ~94 ~13 double_stone_slab 8  
fill ~23 ~94 ~67 ~24 ~94 ~67 double_stone_slab 8 
setblock ~24 ~94 ~13 wool 8 
setblock ~25 ~94 ~12 clay 0 
setblock ~25 ~94 ~68 double_stone_slab 8 
setblock ~26 ~94 ~12 double_stone_slab 8  
fill ~26 ~94 ~68 ~26 ~93 ~68 wool 8 
setblock ~27 ~94 ~11 clay 0 
setblock ~27 ~94 ~69 stone 0 
setblock ~28 ~94 ~11 double_stone_slab 8 
setblock ~28 ~94 ~69 wool 8  
fill ~29 ~94 ~10 ~29 ~95 ~10 double_stone_slab 8  
fill ~29 ~94 ~70 ~29 ~95 ~70 double_stone_slab 8  
fill ~30 ~94 ~10 ~31 ~94 ~10 wool 8 
setblock ~30 ~94 ~70 wool 8 
setblock ~31 ~94 ~70 double_stone_slab 8  
fill ~32 ~94 ~9 ~34 ~94 ~9 concrete 8 
setblock ~32 ~94 ~71 wool 8 
setblock ~33 ~94 ~71 double_stone_slab 8 
setblock ~34 ~94 ~71 clay 0 
setblock ~35 ~94 ~9 coal_ore 0 
setblock ~36 ~94 ~9 concrete 8  
fill ~36 ~94 ~71 ~36 ~93 ~71 double_stone_slab 8  
fill ~37 ~94 ~8 ~38 ~94 ~8 stone 0  
fill ~37 ~94 ~72 ~38 ~94 ~72 double_stone_slab 8  
fill ~39 ~94 ~8 ~40 ~94 ~8 coal_ore 0  
fill ~39 ~94 ~72 ~40 ~94 ~72 clay 0  
fill ~41 ~94 ~8 ~41 ~95 ~8 stained_hardened_clay 9  
fill ~41 ~94 ~72 ~42 ~94 ~72 double_stone_slab 8 
setblock ~42 ~94 ~8 stone 5 
setblock ~43 ~94 ~8 concrete 8  
fill ~43 ~94 ~72 ~43 ~95 ~72 clay 0 
setblock ~44 ~94 ~9 stone 0 
setblock ~44 ~94 ~71 clay 0 
setblock ~45 ~94 ~9 wool 8  
fill ~45 ~94 ~71 ~48 ~94 ~71 double_stone_slab 8 
setblock ~46 ~94 ~9 stone 0 
setblock ~47 ~94 ~9 wool 8  
fill ~48 ~94 ~9 ~48 ~95 ~9 stone 5  
fill ~49 ~94 ~10 ~51 ~94 ~10 wool 8 
setblock ~49 ~94 ~70 clay 0 
setblock ~50 ~94 ~70 wool 8 
setblock ~51 ~94 ~70 stone 0 
setblock ~52 ~94 ~11 double_stone_slab 8 
setblock ~52 ~94 ~69 stone 5 
setblock ~53 ~94 ~11 wool 8 
setblock ~53 ~94 ~69 wool 8 
setblock ~54 ~94 ~12 wool 8 
setblock ~54 ~94 ~68 wool 8 
setblock ~55 ~94 ~12 double_stone_slab 8 
setblock ~55 ~94 ~68 double_stone_slab 8 
setblock ~56 ~94 ~13 wool 8  
fill ~56 ~94 ~67 ~57 ~94 ~67 double_stone_slab 8 
setblock ~57 ~94 ~13 double_stone_slab 8 
setblock ~58 ~94 ~14 clay 0 
setblock ~58 ~94 ~66 wool 8  
fill ~59 ~94 ~15 ~60 ~94 ~15 clay 0  
fill ~59 ~94 ~65 ~60 ~94 ~65 wool 8 
setblock ~61 ~94 ~16 double_stone_slab 8 
setblock ~61 ~94 ~64 double_stone_slab 8 
setblock ~62 ~94 ~17 wool 8 
setblock ~62 ~94 ~63 stone 5 
setblock ~63 ~94 ~18 double_stone_slab 8 
setblock ~63 ~94 ~62 coal_ore 0 
setblock ~64 ~94 ~19 double_stone_slab 8 
setblock ~64 ~94 ~61 concrete 8  
fill ~65 ~94 ~20 ~65 ~95 ~20 double_stone_slab 8 
setblock ~65 ~94 ~21 clay 0 
setblock ~65 ~94 ~59 stone 5  
fill ~65 ~94 ~60 ~65 ~95 ~60 concrete 8 
setblock ~66 ~94 ~22 clay 0 
setblock ~66 ~94 ~58 stonebrick 2 
setblock ~67 ~94 ~23 wool 8 
setblock ~67 ~94 ~24 double_stone_slab 8  
fill ~67 ~94 ~56 ~67 ~94 ~57 wool 8 
setblock ~68 ~94 ~25 wool 8 
setblock ~68 ~94 ~26 stone 0 
setblock ~68 ~94 ~54 stone 5 
setblock ~68 ~94 ~55 stone 0 
setblock ~69 ~94 ~27 double_stone_slab 8 
setblock ~69 ~94 ~28 wool 8 
setblock ~69 ~94 ~53 wool 8  
fill ~70 ~94 ~29 ~70 ~95 ~29 double_stone_slab 8  
fill ~70 ~94 ~30 ~70 ~94 ~29 double_stone_slab 8  
fill ~70 ~94 ~49 ~70 ~94 ~51 double_stone_slab 8 
setblock ~71 ~94 ~32 wool 8  
fill ~71 ~94 ~33 ~71 ~94 ~34 double_stone_slab 8 
setblock ~71 ~94 ~36 double_stone_slab 8 
setblock ~71 ~94 ~45 stone 3  
fill ~71 ~94 ~46 ~71 ~94 ~48 clay 0  
fill ~72 ~94 ~37 ~72 ~95 ~37 clay 0  
fill ~72 ~94 ~38 ~72 ~94 ~39 clay 0 
setblock ~72 ~94 ~40 double_stone_slab 8  
fill ~72 ~94 ~41 ~72 ~95 ~41 clay 0 
setblock ~72 ~94 ~42 stone 4  
fill ~72 ~94 ~43 ~72 ~95 ~43 stone 3  
fill ~8 ~95 ~33 ~8 ~96 ~33 stained_hardened_clay 9  
fill ~8 ~95 ~34 ~8 ~95 ~35 concrete 8  
fill ~8 ~95 ~36 ~8 ~95 ~37 stone 0 
setblock ~8 ~95 ~38 stone 5 
setblock ~8 ~95 ~39 coal_ore 0  
fill ~8 ~95 ~40 ~8 ~95 ~41 stained_hardened_clay 9 
setblock ~8 ~95 ~42 stonebrick 2 
setblock ~8 ~95 ~43 stained_hardened_clay 9 
setblock ~8 ~95 ~44 coal_ore 0 
setblock ~8 ~95 ~45 stained_hardened_clay 9  
fill ~8 ~95 ~46 ~8 ~96 ~46 coal_ore 0  
fill ~8 ~95 ~47 ~8 ~96 ~47 wool 7  
fill ~9 ~95 ~30 ~9 ~95 ~31 stonebrick 2 
setblock ~9 ~95 ~32 stained_hardened_clay 9  
fill ~9 ~95 ~48 ~9 ~95 ~49 stained_hardened_clay 9 
setblock ~9 ~95 ~50 stonebrick 2  
fill ~10 ~95 ~27 ~10 ~95 ~28 double_stone_slab 8 
setblock ~10 ~95 ~29 wool 8 
setblock ~10 ~95 ~51 coal_ore 0  
fill ~10 ~95 ~52 ~10 ~95 ~53 stained_hardened_clay 9 
setblock ~11 ~95 ~25 stone 5 
setblock ~11 ~95 ~26 wool 8  
fill ~11 ~95 ~54 ~11 ~95 ~55 stained_hardened_clay 9 
setblock ~12 ~95 ~23 concrete 8 
setblock ~12 ~95 ~24 wool 8 
setblock ~12 ~95 ~56 stained_hardened_clay 9  
fill ~12 ~95 ~57 ~12 ~96 ~57 coal_ore 0 
setblock ~13 ~95 ~22 coal_ore 0 
setblock ~13 ~95 ~58 coal_ore 0 
setblock ~14 ~95 ~21 wool 8 
setblock ~14 ~95 ~59 concrete 8  
fill ~15 ~95 ~19 ~15 ~95 ~20 clay 0 
setblock ~15 ~95 ~60 concrete 8 
setblock ~15 ~95 ~61 double_stone_slab 8 
setblock ~16 ~95 ~18 double_stone_slab 8 
setblock ~16 ~95 ~62 double_stone_slab 8 
setblock ~17 ~95 ~17 double_stone_slab 8 
setblock ~17 ~95 ~63 clay 0 
setblock ~18 ~95 ~16 wool 8 
setblock ~18 ~95 ~64 double_stone_slab 8 
setblock ~19 ~95 ~15 wool 8 
setblock ~19 ~95 ~65 double_stone_slab 8 
setblock ~20 ~95 ~65 wool 8 
setblock ~21 ~95 ~14 wool 8 
setblock ~21 ~95 ~66 double_stone_slab 8 
setblock ~22 ~95 ~13 double_stone_slab 8 
setblock ~22 ~95 ~67 concrete 8  
fill ~23 ~95 ~12 ~24 ~95 ~12 double_stone_slab 8 
setblock ~23 ~95 ~68 double_stone_slab 8 
setblock ~24 ~95 ~68 wool 8  
fill ~25 ~95 ~11 ~25 ~96 ~11 double_stone_slab 8  
fill ~25 ~95 ~69 ~26 ~95 ~69 double_stone_slab 8 
setblock ~26 ~95 ~11 stone 3  
fill ~27 ~95 ~10 ~28 ~95 ~10 clay 0  
fill ~27 ~95 ~70 ~29 ~95 ~70 double_stone_slab 8 
setblock ~30 ~95 ~9 double_stone_slab 8  
fill ~30 ~95 ~71 ~32 ~95 ~71 double_stone_slab 8  
fill ~31 ~95 ~9 ~32 ~95 ~9 wool 8 
setblock ~33 ~95 ~8 concrete 8 
setblock ~33 ~95 ~72 clay 0  
fill ~34 ~95 ~8 ~34 ~96 ~8 wool 8  
fill ~34 ~95 ~72 ~38 ~95 ~72 double_stone_slab 8 
setblock ~35 ~95 ~8 stone 0 
setblock ~36 ~95 ~8 concrete 8 
setblock ~37 ~95 ~8 stone 5  
fill ~38 ~95 ~8 ~39 ~95 ~8 concrete 8  
fill ~39 ~95 ~72 ~44 ~95 ~72 clay 0 
setblock ~40 ~95 ~8 stonebrick 2  
fill ~42 ~95 ~8 ~43 ~95 ~8 stained_hardened_clay 9 
setblock ~44 ~95 ~8 stone 0  
fill ~45 ~95 ~8 ~46 ~95 ~8 stone 5  
fill ~45 ~95 ~72 ~46 ~95 ~72 double_stone_slab 8 
setblock ~47 ~95 ~8 wool 8 
setblock ~47 ~95 ~72 wool 8 
setblock ~48 ~95 ~71 wool 8  
fill ~49 ~95 ~9 ~50 ~95 ~9 wool 8  
fill ~49 ~95 ~71 ~50 ~95 ~71 double_stone_slab 8  
fill ~51 ~95 ~10 ~52 ~95 ~10 wool 8  
fill ~51 ~95 ~70 ~53 ~95 ~70 double_stone_slab 8  
fill ~53 ~95 ~10 ~53 ~96 ~10 double_stone_slab 8  
fill ~54 ~95 ~11 ~55 ~95 ~11 clay 0  
fill ~54 ~95 ~69 ~55 ~95 ~69 wool 8 
setblock ~56 ~95 ~12 double_stone_slab 8 
setblock ~56 ~95 ~68 double_stone_slab 8 
setblock ~57 ~95 ~12 stone 3 
setblock ~57 ~95 ~68 wool 8 
setblock ~58 ~95 ~13 stone 3 
setblock ~58 ~95 ~67 wool 8 
setblock ~59 ~95 ~14 stone 3 
setblock ~59 ~95 ~66 double_stone_slab 8 
setblock ~60 ~95 ~15 double_stone_slab 8 
setblock ~60 ~95 ~65 wool 8 
setblock ~61 ~95 ~15 clay 0 
setblock ~61 ~95 ~65 double_stone_slab 8 
setblock ~62 ~95 ~16 double_stone_slab 8 
setblock ~62 ~95 ~64 wool 8 
setblock ~63 ~95 ~17 double_stone_slab 8 
setblock ~63 ~95 ~63 stone 0 
setblock ~64 ~95 ~18 double_stone_slab 8 
setblock ~64 ~95 ~62 concrete 8 
setblock ~65 ~95 ~19 double_stone_slab 8 
setblock ~65 ~95 ~61 stone 0 
setblock ~66 ~95 ~21 double_stone_slab 8 
setblock ~66 ~95 ~59 concrete 8 
setblock ~67 ~95 ~22 double_stone_slab 8 
setblock ~67 ~95 ~58 stone 5 
setblock ~68 ~95 ~23 double_stone_slab 8 
setblock ~68 ~95 ~24 wool 8 
setblock ~68 ~95 ~56 stone 0 
setblock ~68 ~95 ~57 stained_hardened_clay 9 
setblock ~69 ~95 ~25 clay 0   

KittysCommands:  
setblock ~69 ~95 ~26 wool 8 
setblock ~69 ~95 ~54 concrete 8 
setblock ~69 ~95 ~55 stone 5  
fill ~70 ~95 ~27 ~70 ~95 ~29 double_stone_slab 8 
setblock ~70 ~95 ~51 double_stone_slab 8  
fill ~70 ~95 ~52 ~70 ~95 ~53 stone 5 
setblock ~71 ~95 ~30 double_stone_slab 8 
setblock ~71 ~95 ~31 clay 0 
setblock ~71 ~95 ~32 double_stone_slab 8  
fill ~71 ~95 ~48 ~71 ~95 ~49 clay 0  
fill ~71 ~95 ~50 ~71 ~96 ~50 double_stone_slab 8  
fill ~72 ~95 ~33 ~72 ~95 ~34 double_stone_slab 8  
fill ~72 ~95 ~35 ~72 ~95 ~37 clay 0 
setblock ~72 ~95 ~38 double_stone_slab 8  
fill ~72 ~95 ~39 ~72 ~95 ~41 clay 0 
setblock ~72 ~95 ~42 stone 3  
fill ~72 ~95 ~44 ~72 ~95 ~46 clay 0  
fill ~72 ~95 ~47 ~72 ~96 ~47 double_stone_slab 8  
fill ~7 ~96 ~35 ~7 ~97 ~35 stone 5  
fill ~7 ~96 ~36 ~7 ~97 ~36 concrete 8  
fill ~7 ~96 ~37 ~7 ~96 ~38 stone 0 
setblock ~7 ~96 ~39 stonebrick 2 
setblock ~7 ~96 ~40 coal_ore 0 
setblock ~7 ~96 ~41 stained_hardened_clay 9 
setblock ~7 ~96 ~42 coal_ore 0  
fill ~7 ~96 ~43 ~7 ~96 ~45 stained_hardened_clay 9  
fill ~8 ~96 ~31 ~8 ~97 ~31 stonebrick 2 
setblock ~8 ~96 ~32 stained_hardened_clay 9 
setblock ~8 ~96 ~34 stone 5  
fill ~8 ~96 ~48 ~8 ~96 ~49 coal_ore 0  
fill ~9 ~96 ~28 ~9 ~97 ~28 wool 8  
fill ~9 ~96 ~29 ~9 ~96 ~28 wool 8 
setblock ~9 ~96 ~30 stained_hardened_clay 9 
setblock ~9 ~96 ~50 stone 5 
setblock ~9 ~96 ~51 concrete 8 
setblock ~9 ~96 ~52 coal_ore 0 
setblock ~10 ~96 ~26 wool 8 
setblock ~10 ~96 ~27 clay 0 
setblock ~10 ~96 ~53 concrete 8 
setblock ~10 ~96 ~54 coal_ore 0 
setblock ~11 ~96 ~24 double_stone_slab 8 
setblock ~11 ~96 ~25 clay 0 
setblock ~11 ~96 ~55 coal_ore 0 
setblock ~11 ~96 ~56 stonebrick 2  
fill ~12 ~96 ~22 ~12 ~96 ~23 stone 5 
setblock ~12 ~96 ~58 concrete 8 
setblock ~13 ~96 ~21 stone 0 
setblock ~13 ~96 ~59 concrete 8  
fill ~14 ~96 ~19 ~14 ~97 ~19 double_stone_slab 8  
fill ~14 ~96 ~20 ~14 ~96 ~19 double_stone_slab 8 
setblock ~14 ~96 ~60 concrete 8 
setblock ~14 ~96 ~61 double_stone_slab 8 
setblock ~15 ~96 ~18 double_stone_slab 8 
setblock ~15 ~96 ~62 double_stone_slab 8 
setblock ~16 ~96 ~17 wool 8 
setblock ~16 ~96 ~63 clay 0 
setblock ~17 ~96 ~16 double_stone_slab 8 
setblock ~17 ~96 ~64 wool 8 
setblock ~18 ~96 ~15 double_stone_slab 8 
setblock ~18 ~96 ~65 wool 8  
fill ~19 ~96 ~14 ~20 ~96 ~14 double_stone_slab 8  
fill ~19 ~96 ~66 ~20 ~96 ~66 clay 0 
setblock ~21 ~96 ~13 wool 8 
setblock ~21 ~96 ~67 wool 8  
fill ~22 ~96 ~12 ~23 ~96 ~12 double_stone_slab 8 
setblock ~22 ~96 ~68 double_stone_slab 8 
setblock ~23 ~96 ~68 wool 8 
setblock ~24 ~96 ~11 double_stone_slab 8  
fill ~24 ~96 ~69 ~25 ~96 ~69 double_stone_slab 8  
fill ~26 ~96 ~10 ~27 ~96 ~10 clay 0  
fill ~26 ~96 ~70 ~27 ~96 ~70 double_stone_slab 8  
fill ~28 ~96 ~9 ~29 ~96 ~9 double_stone_slab 8  
fill ~28 ~96 ~71 ~30 ~96 ~71 double_stone_slab 8 
setblock ~30 ~96 ~9 wool 8  
fill ~31 ~96 ~8 ~32 ~96 ~8 wool 8  
fill ~31 ~96 ~72 ~33 ~96 ~72 double_stone_slab 8 
setblock ~33 ~96 ~8 stone 0 
setblock ~34 ~96 ~72 wool 8 
setblock ~35 ~96 ~7 stone 0  
fill ~35 ~96 ~73 ~35 ~97 ~73 double_stone_slab 8 
setblock ~36 ~96 ~7 double_stone_slab 8 
setblock ~36 ~96 ~73 wool 8 
setblock ~37 ~96 ~7 concrete 8  
fill ~37 ~96 ~73 ~43 ~96 ~73 clay 0 
setblock ~38 ~96 ~7 coal_ore 0 
setblock ~39 ~96 ~7 stained_hardened_clay 9 
setblock ~40 ~96 ~7 concrete 8 
setblock ~41 ~96 ~7 stone 0 
setblock ~42 ~96 ~7 concrete 8 
setblock ~43 ~96 ~7 coal_ore 0 
setblock ~44 ~96 ~7 stained_hardened_clay 8 
setblock ~44 ~96 ~73 double_stone_slab 8 
setblock ~45 ~96 ~7 concrete 8  
fill ~45 ~96 ~73 ~45 ~97 ~73 clay 0  
fill ~46 ~96 ~8 ~47 ~96 ~8 double_stone_slab 8  
fill ~46 ~96 ~72 ~49 ~96 ~72 double_stone_slab 8 
setblock ~48 ~96 ~8 wool 8 
setblock ~49 ~96 ~8 stone 0  
fill ~50 ~96 ~9 ~52 ~96 ~9 double_stone_slab 8  
fill ~50 ~96 ~71 ~51 ~96 ~71 wool 8  
fill ~52 ~96 ~71 ~52 ~97 ~71 double_stone_slab 8  
fill ~53 ~96 ~70 ~54 ~96 ~70 double_stone_slab 8 
setblock ~54 ~96 ~10 double_stone_slab 8 
setblock ~55 ~96 ~11 clay 0 
setblock ~55 ~96 ~69 double_stone_slab 8 
setblock ~56 ~96 ~11 double_stone_slab 8 
setblock ~56 ~96 ~69 wool 8  
fill ~57 ~96 ~12 ~58 ~96 ~12 stone 4 
setblock ~57 ~96 ~68 stone 5  
fill ~58 ~96 ~68 ~58 ~97 ~68 double_stone_slab 8 
setblock ~59 ~96 ~13 clay 0 
setblock ~59 ~96 ~67 double_stone_slab 8 
setblock ~60 ~96 ~14 stone 3 
setblock ~60 ~96 ~66 double_stone_slab 8 
setblock ~61 ~96 ~14 clay 0 
setblock ~61 ~96 ~66 wool 8 
setblock ~62 ~96 ~15 double_stone_slab 8 
setblock ~62 ~96 ~65 clay 0 
setblock ~63 ~96 ~16 double_stone_slab 8 
setblock ~63 ~96 ~64 double_stone_slab 8 
setblock ~64 ~96 ~17 wool 8 
setblock ~64 ~96 ~63 concrete 8 
setblock ~65 ~96 ~18 double_stone_slab 8 
