fill ~74 ~0 ~51 ~74 ~2 ~51 concrete 6  
fill ~74 ~0 ~52 ~76 ~0 ~52 concrete 6  
fill ~75 ~0 ~53 ~77 ~0 ~53 concrete 6  
fill ~58 ~1 ~57 ~64 ~1 ~57 stained_hardened_clay 0  
fill ~59 ~1 ~56 ~64 ~1 ~56 stained_hardened_clay 0  
fill ~70 ~1 ~51 ~76 ~1 ~51 concrete 6  
fill ~72 ~1 ~50 ~72 ~2 ~50 concrete 6  
fill ~72 ~1 ~52 ~73 ~1 ~52 concrete 6  
fill ~74 ~1 ~53 ~75 ~1 ~53 concrete 6  
fill ~76 ~1 ~54 ~78 ~1 ~54 concrete 6  
fill ~77 ~1 ~52 ~77 ~2 ~52 concrete 6 
setblock ~78 ~1 ~53 concrete 6  
fill ~46 ~2 ~61 ~51 ~2 ~61 concrete 6  
fill ~51 ~2 ~57 ~53 ~2 ~57 gold_block 0 
setblock ~65 ~2 ~57 stained_hardened_clay 0 
setblock ~66 ~2 ~56 stained_hardened_clay 0 
setblock ~66 ~2 ~57 gold_block 0  
fill ~67 ~2 ~56 ~68 ~2 ~56 gold_block 0  
fill ~68 ~2 ~51 ~69 ~2 ~51 concrete 6  
fill ~69 ~2 ~52 ~77 ~2 ~52 concrete 6  
fill ~70 ~2 ~50 ~72 ~2 ~50 concrete 6  
fill ~72 ~2 ~51 ~75 ~2 ~51 concrete 6  
fill ~75 ~2 ~53 ~77 ~2 ~53 concrete 6 
setblock ~42 ~3 ~59 magenta_glazed_terracotta 0  
fill ~43 ~3 ~59 ~43 ~4 ~59 concrete 6  
fill ~43 ~3 ~60 ~44 ~3 ~60 concrete 6 
setblock ~44 ~3 ~59 purpur_pillar 0 
setblock ~45 ~3 ~60 purpur_pillar 0 
setblock ~45 ~3 ~61 magenta_glazed_terracotta 0  
fill ~46 ~3 ~60 ~48 ~3 ~60 concrete 6  
fill ~46 ~3 ~61 ~47 ~3 ~61 concrete 6  
fill ~47 ~3 ~62 ~53 ~3 ~62 concrete 6  
fill ~49 ~3 ~56 ~49 ~3 ~57 gold_block 0  
fill ~49 ~3 ~61 ~54 ~3 ~61 concrete 6  
fill ~50 ~3 ~57 ~51 ~3 ~57 gold_block 0 
setblock ~52 ~3 ~58 gold_block 0  
fill ~52 ~3 ~60 ~55 ~3 ~60 concrete 6 
setblock ~66 ~3 ~52 concrete 6  
fill ~67 ~3 ~51 ~71 ~3 ~51 concrete 6  
fill ~67 ~3 ~52 ~67 ~4 ~52 magenta_glazed_terracotta 0  
fill ~68 ~3 ~52 ~69 ~3 ~52 concrete 6  
fill ~68 ~3 ~57 ~69 ~3 ~57 gold_block 0  
fill ~69 ~3 ~56 ~70 ~3 ~56 gold_block 0 
setblock ~41 ~4 ~58 concrete 6 
setblock ~42 ~4 ~59 concrete 6 
setblock ~44 ~4 ~60 concrete 6  
fill ~47 ~4 ~56 ~47 ~4 ~57 stained_hardened_clay 0 
setblock ~48 ~4 ~56 gold_block 0 
setblock ~48 ~4 ~57 stained_hardened_clay 0  
fill ~48 ~4 ~61 ~52 ~4 ~61 concrete 6 
setblock ~49 ~4 ~57 gold_block 0  
fill ~50 ~4 ~62 ~54 ~4 ~62 concrete 6  
fill ~52 ~4 ~60 ~54 ~4 ~60 concrete 6  
fill ~55 ~4 ~59 ~56 ~4 ~59 concrete 6  
fill ~55 ~4 ~61 ~56 ~4 ~61 concrete 6  
fill ~56 ~4 ~60 ~57 ~4 ~60 concrete 6  
fill ~64 ~4 ~53 ~65 ~4 ~53 concrete 6 
setblock ~65 ~4 ~52 concrete 6 
setblock ~66 ~4 ~52 purpur_pillar 0 
setblock ~70 ~4 ~57 gold_block 0  
fill ~71 ~4 ~56 ~72 ~4 ~56 gold_block 0 
setblock ~81 ~4 ~55 concrete 6  
fill ~46 ~5 ~56 ~46 ~5 ~57 stained_hardened_clay 0  
fill ~53 ~5 ~61 ~56 ~5 ~61 concrete 6 
setblock ~54 ~5 ~60 concrete 6  
fill ~55 ~5 ~59 ~57 ~5 ~59 concrete 6  
fill ~57 ~5 ~60 ~57 ~6 ~60 concrete 6  
fill ~63 ~5 ~53 ~63 ~5 ~54 concrete 6 
setblock ~64 ~5 ~53 magenta_glazed_terracotta 0 
setblock ~71 ~5 ~57 gold_block 0 
setblock ~82 ~5 ~55 concrete 6  
fill ~45 ~6 ~56 ~45 ~6 ~57 stained_hardened_clay 0  
fill ~55 ~6 ~60 ~57 ~6 ~60 concrete 6  
fill ~56 ~6 ~59 ~57 ~6 ~59 concrete 6 
setblock ~56 ~6 ~61 concrete 6 
setblock ~61 ~6 ~55 concrete 6  
fill ~83 ~6 ~55 ~83 ~7 ~55 concrete 6  
fill ~44 ~7 ~56 ~44 ~7 ~57 stained_hardened_clay 0 
setblock ~60 ~7 ~56 concrete 2  
fill ~84 ~7 ~55 ~84 ~8 ~55 concrete 6  
fill ~84 ~7 ~56 ~84 ~9 ~56 concrete 6  
fill ~24 ~8 ~63 ~30 ~8 ~63 stained_hardened_clay 3  
fill ~24 ~8 ~64 ~30 ~8 ~64 stained_hardened_clay 3  
fill ~25 ~8 ~61 ~29 ~8 ~61 stained_hardened_clay 3  
fill ~25 ~8 ~62 ~30 ~8 ~62 stained_hardened_clay 3  
fill ~25 ~8 ~65 ~30 ~8 ~65 stained_hardened_clay 3  
fill ~26 ~8 ~60 ~27 ~8 ~60 stained_hardened_clay 3  
fill ~26 ~8 ~66 ~31 ~8 ~66 stained_hardened_clay 3  
fill ~26 ~8 ~67 ~31 ~8 ~67 stained_hardened_clay 3  
fill ~27 ~8 ~52 ~27 ~8 ~53 stained_hardened_clay 3  
fill ~27 ~8 ~68 ~31 ~8 ~68 stained_hardened_clay 3  
fill ~27 ~8 ~69 ~31 ~8 ~69 stained_hardened_clay 3  
fill ~30 ~8 ~70 ~31 ~8 ~70 stained_hardened_clay 3  
fill ~43 ~8 ~56 ~43 ~8 ~57 stained_hardened_clay 0  
fill ~21 ~9 ~63 ~23 ~9 ~63 stained_hardened_clay 3  
fill ~21 ~9 ~64 ~23 ~9 ~64 stained_hardened_clay 3  
fill ~21 ~9 ~65 ~24 ~9 ~65 stained_hardened_clay 3  
fill ~22 ~9 ~61 ~24 ~9 ~61 stained_hardened_clay 3  
fill ~22 ~9 ~62 ~24 ~9 ~62 stained_hardened_clay 3  
fill ~22 ~9 ~66 ~25 ~9 ~66 stained_hardened_clay 3  
fill ~22 ~9 ~67 ~25 ~9 ~67 stained_hardened_clay 3  
fill ~23 ~9 ~52 ~26 ~9 ~52 stained_hardened_clay 3  
fill ~23 ~9 ~53 ~26 ~9 ~53 stained_hardened_clay 3  
fill ~23 ~9 ~59 ~31 ~9 ~59 stained_hardened_clay 3  
fill ~23 ~9 ~60 ~25 ~9 ~60 stained_hardened_clay 3  
fill ~23 ~9 ~68 ~26 ~9 ~68 stained_hardened_clay 3  
fill ~24 ~9 ~48 ~32 ~9 ~48 stained_hardened_clay 3  
fill ~24 ~9 ~49 ~32 ~9 ~49 stained_hardened_clay 3  
fill ~24 ~9 ~50 ~32 ~9 ~50 stained_hardened_clay 3  
fill ~24 ~9 ~51 ~32 ~9 ~51 stained_hardened_clay 3  
fill ~24 ~9 ~54 ~31 ~9 ~54 stained_hardened_clay 3  
fill ~24 ~9 ~57 ~28 ~9 ~57 stained_hardened_clay 3  
fill ~24 ~9 ~58 ~30 ~9 ~58 stained_hardened_clay 3  
fill ~24 ~9 ~69 ~26 ~9 ~69 stained_hardened_clay 3  
fill ~24 ~9 ~70 ~29 ~9 ~70 stained_hardened_clay 3  
fill ~25 ~9 ~47 ~32 ~9 ~47 stained_hardened_clay 3  
fill ~25 ~9 ~55 ~30 ~9 ~55 stained_hardened_clay 3  
fill ~25 ~9 ~56 ~28 ~9 ~56 stained_hardened_clay 3  
fill ~25 ~9 ~71 ~33 ~9 ~71 stained_hardened_clay 3  
fill ~26 ~9 ~46 ~30 ~9 ~46 stained_hardened_clay 3  
fill ~26 ~9 ~72 ~33 ~9 ~72 stained_hardened_clay 3  
fill ~27 ~9 ~45 ~28 ~9 ~45 stained_hardened_clay 3  
fill ~28 ~9 ~52 ~32 ~9 ~52 stained_hardened_clay 3  
fill ~28 ~9 ~53 ~32 ~9 ~53 stained_hardened_clay 3  
fill ~28 ~9 ~60 ~31 ~9 ~60 stained_hardened_clay 3  
fill ~30 ~9 ~61 ~31 ~9 ~61 stained_hardened_clay 3  
fill ~31 ~9 ~62 ~32 ~9 ~62 stained_hardened_clay 3  
fill ~31 ~9 ~63 ~32 ~9 ~63 stained_hardened_clay 3  
fill ~31 ~9 ~64 ~32 ~9 ~64 stained_hardened_clay 3  
fill ~31 ~9 ~65 ~33 ~9 ~65 stained_hardened_clay 3  
fill ~32 ~9 ~66 ~33 ~9 ~66 stained_hardened_clay 3  
fill ~32 ~9 ~67 ~33 ~9 ~67 stained_hardened_clay 3  
fill ~32 ~9 ~68 ~34 ~9 ~68 stained_hardened_clay 3  
fill ~32 ~9 ~69 ~33 ~9 ~69 stained_hardened_clay 3  
fill ~32 ~9 ~70 ~33 ~9 ~70 stained_hardened_clay 3 
setblock ~77 ~9 ~55 stained_hardened_clay 0  
fill ~85 ~9 ~55 ~85 ~9 ~56 magenta_glazed_terracotta 0  
fill ~20 ~10 ~59 ~22 ~10 ~59 stained_hardened_clay 3  
fill ~20 ~10 ~60 ~22 ~10 ~60 stained_hardened_clay 3  
fill ~20 ~10 ~61 ~21 ~10 ~61 stained_hardened_clay 3  
fill ~20 ~10 ~62 ~21 ~10 ~62 stained_hardened_clay 3  
fill ~20 ~10 ~63 ~20 ~10 ~67 stained_hardened_clay 3  
fill ~21 ~10 ~51 ~23 ~10 ~51 stained_hardened_clay 3  
fill ~21 ~10 ~52 ~22 ~10 ~52 stained_hardened_clay 3  
fill ~21 ~10 ~53 ~22 ~10 ~53 stained_hardened_clay 3  
fill ~21 ~10 ~54 ~28 ~10 ~54 stained_hardened_clay 3  
fill ~21 ~10 ~57 ~25 ~10 ~57 stained_hardened_clay 3  
fill ~21 ~10 ~58 ~31 ~10 ~58 stained_hardened_clay 3  
fill ~21 ~10 ~66 ~21 ~10 ~69 stained_hardened_clay 3  
fill ~22 ~10 ~46 ~25 ~10 ~46 stained_hardened_clay 3  
fill ~22 ~10 ~47 ~24 ~10 ~47 stained_hardened_clay 3  
fill ~22 ~10 ~48 ~23 ~10 ~48 stained_hardened_clay 3  
fill ~22 ~10 ~49 ~23 ~10 ~49 stained_hardened_clay 3  
fill ~22 ~10 ~50 ~23 ~10 ~50 stained_hardened_clay 3  
fill ~22 ~10 ~55 ~32 ~10 ~55 stained_hardened_clay 3  
fill ~22 ~10 ~56 ~25 ~10 ~56 stained_hardened_clay 3  
fill ~22 ~10 ~68 ~22 ~10 ~70 stained_hardened_clay 3  
fill ~23 ~10 ~45 ~26 ~10 ~45 stained_hardened_clay 3  
fill ~23 ~10 ~69 ~23 ~10 ~72 stained_hardened_clay 3  
fill ~24 ~10 ~71 ~24 ~10 ~72 stained_hardened_clay 3  
fill ~25 ~10 ~44 ~32 ~10 ~44 stained_hardened_clay 3  
fill ~25 ~10 ~59 ~29 ~10 ~59 stained_hardened_clay 3  
fill ~25 ~10 ~72 ~25 ~10 ~73 stained_hardened_clay 3  
fill ~26 ~10 ~43 ~31 ~10 ~43 stained_hardened_clay 3 
setblock ~26 ~10 ~60 stained_hardened_clay 3  
fill ~26 ~10 ~73 ~35 ~10 ~73 stained_hardened_clay 3  
fill ~27 ~10 ~42 ~29 ~10 ~42 stained_hardened_clay 3  
fill ~27 ~10 ~56 ~31 ~10 ~56 stained_hardened_clay 3  
fill ~27 ~10 ~57 ~31 ~10 ~57 stained_hardened_clay 3  
fill ~27 ~10 ~74 ~34 ~10 ~74 stained_hardened_clay 3  
fill ~29 ~10 ~45 ~33 ~10 ~45 stained_hardened_clay 3  
fill ~29 ~10 ~75 ~33 ~10 ~75 stained_hardened_clay 3  
fill ~31 ~10 ~46 ~33 ~10 ~46 stained_hardened_clay 3  
fill ~31 ~10 ~59 ~31 ~12 ~59 stained_hardened_clay 3 
setblock ~32 ~10 ~54 stained_hardened_clay 3  
fill ~32 ~10 ~60 ~32 ~10 ~62 stained_hardened_clay 3  
fill ~33 ~10 ~47 ~34 ~10 ~47 stained_hardened_clay 3  
fill ~33 ~10 ~48 ~34 ~10 ~48 stained_hardened_clay 3  
fill ~33 ~10 ~49 ~34 ~10 ~49 stained_hardened_clay 3  
fill ~33 ~10 ~50 ~33 ~11 ~50 stained_hardened_clay 3  
fill ~33 ~10 ~51 ~33 ~11 ~51 stained_hardened_clay 3  
fill ~33 ~10 ~52 ~33 ~11 ~52 stained_hardened_clay 3  
fill ~33 ~10 ~53 ~40 ~10 ~53 stained_hardened_clay 3  
fill ~33 ~10 ~63 ~33 ~10 ~65 stained_hardened_clay 3  
fill ~34 ~10 ~54 ~37 ~10 ~54 stained_hardened_clay 3  
fill ~34 ~10 ~55 ~37 ~10 ~55 stained_hardened_clay 3  
fill ~34 ~10 ~56 ~37 ~10 ~56 stained_hardened_clay 3  
fill ~34 ~10 ~57 ~37 ~10 ~57 stained_hardened_clay 3  
fill ~34 ~10 ~66 ~34 ~10 ~67 stained_hardened_clay 3  
fill ~34 ~10 ~69 ~34 ~10 ~74 stained_hardened_clay 3  
fill ~35 ~10 ~58 ~37 ~10 ~58 stained_hardened_clay 3  
fill ~35 ~10 ~68 ~35 ~10 ~70 stained_hardened_clay 9  
fill ~35 ~10 ~71 ~35 ~10 ~73 stained_hardened_clay 3  
fill ~36 ~10 ~59 ~38 ~10 ~59 stained_hardened_clay 3  
fill ~38 ~10 ~54 ~41 ~10 ~54 concrete 8  
fill ~38 ~10 ~55 ~41 ~10 ~55 concrete 8  
fill ~38 ~10 ~56 ~40 ~10 ~56 concrete 8  
fill ~38 ~10 ~57 ~40 ~10 ~57 concrete 8  
fill ~38 ~10 ~58 ~40 ~10 ~58 concrete 8 
setblock ~38 ~10 ~60 stained_hardened_clay 3  
fill ~39 ~10 ~59 ~40 ~10 ~59 concrete 8  
fill ~39 ~10 ~60 ~40 ~10 ~60 concrete 8  
fill ~41 ~10 ~56 ~41 ~10 ~57 stained_hardened_clay 8  
fill ~78 ~10 ~54 ~78 ~11 ~54 stained_hardened_clay 0  
fill ~78 ~10 ~55 ~78 ~10 ~54 stained_hardened_clay 0  
fill ~85 ~10 ~56 ~86 ~10 ~56 concrete 6 
setblock ~18 ~11 ~62 concrete 8  
fill ~18 ~11 ~63 ~19 ~11 ~63 stained_hardened_clay 3  
fill ~18 ~11 ~64 ~19 ~11 ~64 stained_hardened_clay 3  
fill ~18 ~11 ~65 ~19 ~11 ~65 stained_hardened_clay 3  
fill ~18 ~11 ~66 ~19 ~11 ~66 stained_hardened_clay 3  
fill ~18 ~11 ~67 ~19 ~11 ~67 stained_hardened_clay 3  
fill ~19 ~11 ~57 ~22 ~11 ~57 stained_hardened_clay 3  
fill ~19 ~11 ~58 ~20 ~11 ~58 stained_hardened_clay 3  
fill ~19 ~11 ~59 ~19 ~11 ~69 stained_hardened_clay 3 
setblock ~20 ~11 ~48 concrete 8  
fill ~20 ~11 ~49 ~21 ~11 ~49 stained_hardened_clay 3  
fill ~20 ~11 ~50 ~21 ~11 ~50 stained_hardened_clay 3  
fill ~20 ~11 ~51 ~20 ~11 ~58 stained_hardened_clay 3  
fill ~20 ~11 ~68 ~20 ~11 ~70 stained_hardened_clay 3  
fill ~21 ~11 ~45 ~22 ~11 ~45 stained_hardened_clay 3  
fill ~21 ~11 ~46 ~21 ~11 ~50 stained_hardened_clay 3  
fill ~21 ~11 ~55 ~22 ~11 ~55 stained_hardened_clay 3  
fill ~21 ~11 ~56 ~21 ~11 ~55 stained_hardened_clay 3  
fill ~21 ~11 ~70 ~21 ~11 ~72 stained_hardened_clay 3  
fill ~22 ~11 ~44 ~24 ~11 ~44 stained_hardened_clay 3  
fill ~22 ~11 ~54 ~23 ~11 ~54 stained_hardened_clay 3  
fill ~22 ~11 ~58 ~23 ~11 ~58 stained_hardened_clay 3  
fill ~22 ~11 ~59 ~24 ~11 ~59 stained_hardened_clay 3  
fill ~22 ~11 ~71 ~22 ~11 ~73 stained_hardened_clay 3  
fill ~23 ~11 ~43 ~25 ~11 ~43 stained_hardened_clay 3  
fill ~23 ~11 ~53 ~34 ~11 ~53 stained_hardened_clay 3  
fill ~23 ~11 ~60 ~25 ~11 ~60 stained_hardened_clay 3  
fill ~23 ~11 ~73 ~24 ~11 ~73 stained_hardened_clay 3  
fill ~24 ~11 ~42 ~26 ~11 ~42 stained_hardened_clay 3  
fill ~24 ~11 ~52 ~29 ~11 ~52 stained_hardened_clay 3  
fill ~24 ~11 ~74 ~26 ~11 ~74 stained_hardened_clay 3  
fill ~25 ~11 ~41 ~32 ~11 ~41 stained_hardened_clay 3 
setblock ~25 ~11 ~51 stained_hardened_clay 3  
fill ~25 ~11 ~61 ~29 ~11 ~61 stained_hardened_clay 3  
fill ~26 ~11 ~75 ~28 ~11 ~75 stained_hardened_clay 3  
fill ~27 ~11 ~40 ~30 ~11 ~40 stained_hardened_clay 3  
fill ~27 ~11 ~60 ~30 ~11 ~60 stained_hardened_clay 3  
fill ~28 ~11 ~76 ~35 ~11 ~76 stained_hardened_clay 3  
fill ~29 ~11 ~54 ~31 ~11 ~54 stained_hardened_clay 3  
fill ~30 ~11 ~42 ~34 ~11 ~42 stained_hardened_clay 3  
fill ~30 ~11 ~59 ~30 ~12 ~59 stained_hardened_clay 3  
fill ~30 ~11 ~77 ~31 ~11 ~77 stained_hardened_clay 3  
fill ~31 ~11 ~52 ~42 ~11 ~52 stained_hardened_clay 3  
fill ~31 ~11 ~55 ~31 ~11 ~57 stained_hardened_clay 3  
fill ~32 ~11 ~43 ~34 ~11 ~43 stained_hardened_clay 3 
setblock ~32 ~11 ~51 stained_hardened_clay 3  
fill ~32 ~11 ~54 ~32 ~11 ~55 coal_ore 0  
fill ~32 ~11 ~56 ~33 ~11 ~56 stained_hardened_clay 3  
fill ~32 ~11 ~57 ~33 ~11 ~57 stained_hardened_clay 3  
fill ~32 ~11 ~58 ~34 ~11 ~58 stained_hardened_clay 3  
fill ~32 ~11 ~59 ~35 ~11 ~59 stained_hardened_clay 3  
fill ~33 ~11 ~44 ~34 ~11 ~44 stained_hardened_clay 3  
fill ~33 ~11 ~54 ~34 ~11 ~54 stained_hardened_clay 3  
fill ~33 ~11 ~55 ~33 ~11 ~50 stained_hardened_clay 3  
fill ~33 ~11 ~60 ~33 ~11 ~62 stained_hardened_clay 3  
fill ~34 ~11 ~45 ~34 ~11 ~46 stained_hardened_clay 3  
fill ~34 ~11 ~49 ~35 ~11 ~49 stained_hardened_clay 3  
fill ~34 ~11 ~50 ~35 ~11 ~50 stained_hardened_clay 3  
fill ~34 ~11 ~51 ~35 ~11 ~51 stained_hardened_clay 3  
fill ~34 ~11 ~60 ~34 ~14 ~60 stained_hardened_clay 9  
fill ~34 ~11 ~61 ~35 ~11 ~61 stained_hardened_clay 9  
fill ~34 ~11 ~62 ~36 ~11 ~62 stained_hardened_clay 9 
setblock ~34 ~11 ~63 stained_hardened_clay 3  
fill ~34 ~11 ~64 ~34 ~12 ~64 stained_hardened_clay 9  
fill ~34 ~11 ~65 ~34 ~12 ~65 stained_hardened_clay 9  
fill ~34 ~11 ~75 ~36 ~11 ~75 stained_hardened_clay 3  
fill ~35 ~11 ~46 ~35 ~11 ~52 stained_hardened_clay 3  
fill ~35 ~11 ~60 ~37 ~11 ~60 stained_hardened_clay 3  
fill ~35 ~11 ~63 ~39 ~11 ~63 stained_hardened_clay 9  
fill ~35 ~11 ~66 ~35 ~12 ~66 stained_hardened_clay 9  
fill ~35 ~11 ~67 ~35 ~11 ~66 stained_hardened_clay 9  
fill ~35 ~11 ~74 ~36 ~11 ~74 stained_hardened_clay 3  
fill ~36 ~11 ~49 ~41 ~11 ~49 stained_hardened_clay 9  
fill ~36 ~11 ~50 ~41 ~11 ~50 stained_hardened_clay 9  
fill ~36 ~11 ~51 ~37 ~11 ~51 stained_hardened_clay 9  
fill ~36 ~11 ~61 ~40 ~11 ~61 stained_hardened_clay 3  
fill ~36 ~11 ~68 ~36 ~13 ~68 stained_hardened_clay 9  
fill ~36 ~11 ~69 ~36 ~11 ~73 stained_hardened_clay 9  
fill ~37 ~11 ~62 ~42 ~11 ~62 stained_hardened_clay 3  
fill ~37 ~11 ~64 ~39 ~11 ~64 stained_hardened_clay 9  
fill ~37 ~11 ~71 ~37 ~11 ~73 stained_hardened_clay 9  
fill ~38 ~11 ~51 ~42 ~11 ~51 stained_hardened_clay 3  
fill ~40 ~11 ~63 ~42 ~11 ~63 stained_hardened_clay 3  
fill ~40 ~11 ~64 ~41 ~11 ~64 stained_hardened_clay 3  
fill ~41 ~11 ~53 ~43 ~11 ~53 concrete 8  
fill ~41 ~11 ~58 ~42 ~11 ~58 stained_hardened_clay 8  
fill ~41 ~11 ~59 ~44 ~11 ~59 concrete 8  
fill ~41 ~11 ~60 ~43 ~11 ~60 concrete 8  
fill ~41 ~11 ~61 ~41 ~11 ~59 concrete 8  
fill ~42 ~11 ~54 ~44 ~11 ~54 concrete 8  
fill ~42 ~11 ~55 ~44 ~11 ~55 concrete 8  
fill ~42 ~11 ~56 ~42 ~11 ~57 brown_mushroom_block 0  
fill ~42 ~11 ~61 ~43 ~11 ~61 stained_hardened_clay 3  
fill ~43 ~11 ~56 ~45 ~11 ~56 concrete 8  
fill ~43 ~11 ~57 ~44 ~11 ~57 concrete 8  
fill ~43 ~11 ~58 ~44 ~11 ~58 concrete 8  
fill ~53 ~11 ~41 ~60 ~11 ~41 stained_hardened_clay 3  
fill ~53 ~11 ~42 ~60 ~11 ~42 stained_hardened_clay 3  
fill ~53 ~11 ~43 ~53 ~11 ~52 stained_hardened_clay 9  
fill ~54 ~11 ~39 ~60 ~11 ~39 stained_hardened_clay 3  
fill ~54 ~11 ~40 ~60 ~11 ~40 stained_hardened_clay 3  
fill ~54 ~11 ~43 ~60 ~11 ~43 stained_hardened_clay 3  
fill ~54 ~11 ~44 ~60 ~11 ~44 stained_hardened_clay 3  
fill ~54 ~11 ~45 ~60 ~11 ~45 stained_hardened_clay 3  
fill ~54 ~11 ~46 ~54 ~11 ~55 stained_hardened_clay 9  
fill ~55 ~11 ~36 ~60 ~11 ~36 stained_hardened_clay 3  
fill ~55 ~11 ~37 ~60 ~11 ~37 stained_hardened_clay 3  
fill ~55 ~11 ~38 ~60 ~11 ~38 stained_hardened_clay 3  
fill ~55 ~11 ~46 ~60 ~11 ~46 stained_hardened_clay 3  
fill ~55 ~11 ~47 ~60 ~11 ~47 stained_hardened_clay 3  
fill ~55 ~11 ~48 ~55 ~11 ~55 stained_hardened_clay 9  
fill ~56 ~11 ~48 ~59 ~11 ~48 stained_hardened_clay 3  
fill ~56 ~11 ~49 ~56 ~11 ~55 stained_hardened_clay 9  
fill ~57 ~11 ~49 ~59 ~11 ~49 stained_hardened_clay 3  
fill ~57 ~11 ~50 ~58 ~11 ~50 stained_hardened_clay 3  
fill ~57 ~11 ~51 ~57 ~11 ~53 stained_hardened_clay 9  
fill ~58 ~11 ~35 ~60 ~11 ~35 stained_hardened_clay 3 
setblock ~58 ~11 ~51 stained_hardened_clay 3  
fill ~79 ~11 ~54 ~79 ~12 ~54 stained_hardened_clay 0  
fill ~85 ~11 ~56 ~86 ~11 ~56 concrete 6  
fill ~85 ~11 ~57 ~86 ~11 ~57 concrete 6  
fill ~17 ~12 ~58 ~18 ~12 ~58 concrete 8  
fill ~17 ~12 ~59 ~18 ~12 ~59 concrete 8  
fill ~17 ~12 ~60 ~18 ~12 ~60 concrete 8  
fill ~17 ~12 ~61 ~18 ~12 ~61 concrete 8  
fill ~17 ~12 ~62 ~17 ~12 ~65 concrete 8  
fill ~17 ~12 ~66 ~17 ~12 ~68 stained_hardened_clay 3  
fill ~18 ~12 ~56 ~19 ~12 ~56 concrete 8  
fill ~18 ~12 ~57 ~18 ~12 ~56 concrete 8  
fill ~18 ~12 ~68 ~18 ~12 ~70 stained_hardened_clay 3  
fill ~19 ~12 ~47 ~20 ~12 ~47 concrete 8  
fill ~19 ~12 ~48 ~19 ~12 ~56 concrete 8  
fill ~19 ~12 ~70 ~19 ~12 ~72 stained_hardened_clay 3  
fill ~20 ~12 ~45 ~20 ~12 ~47 concrete 8  
fill ~20 ~12 ~53 ~22 ~12 ~53 stained_hardened_clay 3  
fill ~20 ~12 ~54 ~21 ~12 ~54 stained_hardened_clay 3  
fill ~20 ~12 ~55 ~20 ~12 ~58 stained_hardened_clay 3  
fill ~20 ~12 ~71 ~20 ~12 ~73 stained_hardened_clay 3  
fill ~21 ~12 ~43 ~22 ~12 ~43 stained_hardened_clay 3  
fill ~21 ~12 ~44 ~21 ~12 ~43 stained_hardened_clay 3  
fill ~21 ~12 ~52 ~23 ~12 ~52 stained_hardened_clay 3  
fill ~21 ~12 ~58 ~21 ~12 ~60 stained_hardened_clay 3  
fill ~21 ~12 ~73 ~21 ~12 ~74 stained_hardened_clay 3  
fill ~22 ~12 ~41 ~24 ~12 ~41 stained_hardened_clay 3  
fill ~22 ~12 ~42 ~23 ~12 ~42 stained_hardened_clay 3  
fill ~22 ~12 ~51 ~24 ~12 ~51 stained_hardened_clay 3  
fill ~22 ~12 ~60 ~22 ~12 ~61 stained_hardened_clay 3  
fill ~22 ~12 ~74 ~23 ~12 ~74 stained_hardened_clay 3  
fill ~23 ~12 ~40 ~26 ~12 ~40 stained_hardened_clay 3  
fill ~23 ~12 ~61 ~24 ~12 ~61 stained_hardened_clay 3  
fill ~23 ~12 ~62 ~30 ~12 ~62 stained_hardened_clay 3  
fill ~23 ~12 ~75 ~25 ~12 ~75 stained_hardened_clay 3  
fill ~24 ~12 ~50 ~32 ~12 ~50 stained_hardened_clay 3 
setblock ~25 ~12 ~49 stained_hardened_clay 3  
fill ~25 ~12 ~63 ~28 ~12 ~63 stained_hardened_clay 3  
fill ~25 ~12 ~76 ~27 ~12 ~76 stained_hardened_clay 3  
fill ~26 ~12 ~39 ~31 ~12 ~39 stained_hardened_clay 3  
fill ~26 ~12 ~51 ~31 ~12 ~51 stained_hardened_clay 3  
fill ~26 ~12 ~77 ~29 ~12 ~77 stained_hardened_clay 3  
fill ~28 ~12 ~38 ~29 ~12 ~38 stained_hardened_clay 3  
fill ~28 ~12 ~52 ~31 ~12 ~52 stained_hardened_clay 3  
fill ~28 ~12 ~53 ~32 ~12 ~53 stained_hardened_clay 3  
fill ~28 ~12 ~54 ~29 ~12 ~54 stained_hardened_clay 3  
fill ~28 ~12 ~55 ~30 ~12 ~55 stained_hardened_clay 3  
fill ~29 ~12 ~56 ~30 ~12 ~56 stained_hardened_clay 3  
fill ~29 ~12 ~57 ~30 ~12 ~57 stained_hardened_clay 3  
fill ~29 ~12 ~58 ~31 ~12 ~58 stained_hardened_clay 3  
fill ~30 ~12 ~49 ~33 ~12 ~49 stained_hardened_clay 3  
fill ~30 ~12 ~60 ~32 ~12 ~60 stained_hardened_clay 3  
fill ~30 ~12 ~61 ~32 ~12 ~61 stained_hardened_clay 3  
fill ~30 ~12 ~78 ~34 ~12 ~78 stained_hardened_clay 3  
fill ~31 ~12 ~40 ~34 ~12 ~40 stained_hardened_clay 3  
fill ~31 ~12 ~48 ~35 ~12 ~48 stained_hardened_clay 3  
fill ~32 ~12 ~54 ~32 ~12 ~55 stained_hardened_clay 3  
fill ~32 ~12 ~59 ~32 ~11 ~59 stained_hardened_clay 3  
fill ~32 ~12 ~62 ~33 ~12 ~62 stained_hardened_clay 3  
fill ~32 ~12 ~77 ~37 ~12 ~77 stained_hardened_clay 3  
fill ~33 ~12 ~41 ~34 ~12 ~41 stained_hardened_clay 3  
fill ~33 ~12 ~47 ~35 ~12 ~47 stained_hardened_clay 3  
fill ~33 ~12 ~56 ~34 ~12 ~56 stained_hardened_clay 3  
fill ~33 ~12 ~57 ~34 ~12 ~57 stained_hardened_clay 3  
fill ~33 ~12 ~58 ~34 ~12 ~58 stained_hardened_clay 3  
fill ~33 ~12 ~63 ~33 ~12 ~64 stained_hardened_clay 3  
fill ~34 ~12 ~55 ~35 ~12 ~55 stained_hardened_clay 3  
fill ~34 ~12 ~59 ~34 ~14 ~59 stained_hardened_clay 9  
fill ~34 ~12 ~61 ~34 ~15 ~61 stained_hardened_clay 9  
fill ~34 ~12 ~62 ~34 ~16 ~62 stained_hardened_clay 9  
fill ~34 ~12 ~63 ~34 ~17 ~63 stained_hardened_clay 9  
fill ~35 ~12 ~42 ~35 ~12 ~45 stained_hardened_clay 3  
fill ~35 ~12 ~53 ~35 ~12 ~55 stained_hardened_clay 3  
fill ~35 ~12 ~64 ~36 ~12 ~64 stained_hardened_clay 9  
fill ~35 ~12 ~65 ~40 ~12 ~65 stained_hardened_clay 9  
fill ~36 ~12 ~44 ~36 ~12 ~46 stained_hardened_clay 3  
fill ~36 ~12 ~47 ~41 ~12 ~47 stained_hardened_clay 9  
fill ~36 ~12 ~48 ~42 ~12 ~48 stained_hardened_clay 9  
fill ~36 ~12 ~49 ~37 ~12 ~49 stained_hardened_clay 9  
fill ~36 ~12 ~50 ~36 ~11 ~50 stained_hardened_clay 9  
fill ~36 ~12 ~51 ~36 ~11 ~51 stained_hardened_clay 9  
fill ~36 ~12 ~52 ~36 ~12 ~53 stained_hardened_clay 9  
fill ~36 ~12 ~66 ~41 ~12 ~66 stained_hardened_clay 9  
fill ~36 ~12 ~67 ~36 ~13 ~67 stained_hardened_clay 9 
setblock ~36 ~12 ~76 stained_hardened_clay 3  
fill ~37 ~12 ~69 ~37 ~13 ~69 stained_hardened_clay 9  
fill ~37 ~12 ~70 ~37 ~12 ~69 stained_hardened_clay 9  
fill ~37 ~12 ~74 ~38 ~12 ~74 stained_hardened_clay 9  
fill ~37 ~12 ~75 ~38 ~12 ~75 stained_hardened_clay 9  
fill ~37 ~12 ~76 ~37 ~12 ~74 stained_hardened_clay 9  
fill ~38 ~12 ~71 ~38 ~12 ~75 stained_hardened_clay 9  
fill ~39 ~12 ~67 ~40 ~12 ~67 stained_hardened_clay 9 
setblock ~41 ~12 ~65 stained_hardened_clay 3  
fill ~42 ~12 ~49 ~44 ~12 ~49 stained_hardened_clay 9  
fill ~42 ~12 ~50 ~45 ~12 ~50 stained_hardened_clay 9  
fill ~42 ~12 ~64 ~43 ~12 ~64 stained_hardened_clay 3  
fill ~42 ~12 ~65 ~43 ~12 ~65 stained_hardened_clay 9  
fill ~43 ~12 ~51 ~45 ~12 ~51 stained_hardened_clay 3  
fill ~43 ~12 ~52 ~44 ~12 ~52 stained_hardened_clay 3  
fill ~43 ~12 ~62 ~44 ~12 ~62 stained_hardened_clay 3  
fill ~43 ~12 ~63 ~44 ~12 ~63 stained_hardened_clay 3  
fill ~44 ~12 ~53 ~45 ~12 ~53 concrete 8 
setblock ~44 ~12 ~60 concrete 8  
fill ~44 ~12 ~61 ~45 ~12 ~61 stained_hardened_clay 3 
setblock ~44 ~12 ~64 stained_hardened_clay 9 
setblock ~45 ~12 ~52 concrete 8  
fill ~45 ~12 ~54 ~45 ~12 ~55 concrete 8  
fill ~45 ~12 ~57 ~46 ~12 ~57 concrete 8  
fill ~45 ~12 ~58 ~45 ~12 ~57 concrete 8  
fill ~45 ~12 ~59 ~45 ~13 ~59 stained_hardened_clay 3  
fill ~45 ~12 ~60 ~45 ~13 ~60 stained_hardened_clay 3  
fill ~46 ~12 ~55 ~46 ~12 ~57 concrete 8 
setblock ~47 ~12 ~60 stained_hardened_clay 3  
fill ~47 ~12 ~61 ~54 ~12 ~61 stained_hardened_clay 9  
fill ~47 ~12 ~62 ~54 ~12 ~62 stained_hardened_clay 9  
fill ~47 ~12 ~63 ~54 ~12 ~63 stained_hardened_clay 9  
fill ~47 ~12 ~64 ~54 ~12 ~64 stained_hardened_clay 9  
fill ~48 ~12 ~56 ~49 ~12 ~56 stained_hardened_clay 3  
fill ~48 ~12 ~57 ~48 ~12 ~59 stained_hardened_clay 3  
fill ~48 ~12 ~60 ~54 ~12 ~60 stained_hardened_clay 9  
fill ~48 ~12 ~65 ~53 ~12 ~65 stained_hardened_clay 9  
fill ~48 ~12 ~66 ~52 ~12 ~66 stained_hardened_clay 9  
fill ~49 ~12 ~47 ~52 ~12 ~47 stained_hardened_clay 9  
fill ~49 ~12 ~48 ~52 ~12 ~48 stained_hardened_clay 9  
fill ~49 ~12 ~49 ~52 ~12 ~49 stained_hardened_clay 9  
fill ~49 ~12 ~50 ~52 ~12 ~50 stained_hardened_clay 9  
fill ~49 ~12 ~51 ~52 ~12 ~51 stained_hardened_clay 9  
fill ~49 ~12 ~52 ~52 ~12 ~52 stained_hardened_clay 9  
fill ~49 ~12 ~53 ~53 ~12 ~53 stained_hardened_clay 9  
fill ~49 ~12 ~57 ~52 ~12 ~57 stained_hardened_clay 9  
fill ~49 ~12 ~58 ~53 ~12 ~58 stained_hardened_clay 9  
fill ~49 ~12 ~59 ~53 ~12 ~59 stained_hardened_clay 9  
fill ~49 ~12 ~67 ~50 ~12 ~67 stained_hardened_clay 9  
fill ~50 ~12 ~42 ~52 ~12 ~42 stained_hardened_clay 9  
fill ~50 ~12 ~43 ~52 ~12 ~43 stained_hardened_clay 9  
fill ~50 ~12 ~44 ~52 ~12 ~44 stained_hardened_clay 9  
fill ~50 ~12 ~45 ~52 ~12 ~45 stained_hardened_clay 9  
fill ~50 ~12 ~46 ~52 ~12 ~46 stained_hardened_clay 9  
fill ~50 ~12 ~54 ~53 ~12 ~54 stained_hardened_clay 9  
fill ~50 ~12 ~56 ~52 ~12 ~56 stained_hardened_clay 9  
fill ~51 ~12 ~38 ~52 ~12 ~38 stained_hardened_clay 9  
fill ~51 ~12 ~39 ~52 ~12 ~39 stained_hardened_clay 9  
fill ~51 ~12 ~40 ~52 ~12 ~40 stained_hardened_clay 9  
fill ~51 ~12 ~41 ~52 ~12 ~41 stained_hardened_clay 9  
fill ~52 ~12 ~35 ~52 ~13 ~35 stained_hardened_clay 9  
fill ~52 ~12 ~36 ~52 ~12 ~54 stained_hardened_clay 9  
fill ~53 ~12 ~32 ~61 ~12 ~32 stained_hardened_clay 3  
fill ~53 ~12 ~33 ~61 ~12 ~33 stained_hardened_clay 3  
fill ~53 ~12 ~34 ~62 ~12 ~34 stained_hardened_clay 3  
fill ~53 ~12 ~35 ~57 ~12 ~35 stained_hardened_clay 3  
fill ~53 ~12 ~36 ~54 ~12 ~36 stained_hardened_clay 3  
fill ~53 ~12 ~37 ~54 ~12 ~37 stained_hardened_clay 3  
fill ~53 ~12 ~38 ~54 ~12 ~38 stained_hardened_clay 3  
fill ~53 ~12 ~39 ~53 ~12 ~40 stained_hardened_clay 3  
fill ~53 ~12 ~55 ~53 ~13 ~55 stained_hardened_clay 9  
fill ~54 ~12 ~30 ~59 ~12 ~30 stained_hardened_clay 3  
fill ~54 ~12 ~31 ~60 ~12 ~31 stained_hardened_clay 3  
fill ~55 ~12 ~29 ~58 ~12 ~29 stained_hardened_clay 3  
fill ~57 ~12 ~54 ~58 ~12 ~54 stained_hardened_clay 9  
fill ~57 ~12 ~55 ~58 ~12 ~55 stained_hardened_clay 9  
fill ~57 ~12 ~56 ~58 ~12 ~56 stained_hardened_clay 9  
fill ~58 ~12 ~52 ~62 ~12 ~52 stained_hardened_clay 3  
fill ~58 ~12 ~53 ~58 ~13 ~53 stained_hardened_clay 9  
fill ~59 ~12 ~50 ~62 ~12 ~50 stained_hardened_clay 3  
fill ~59 ~12 ~51 ~62 ~12 ~51 stained_hardened_clay 3  
fill ~59 ~12 ~53 ~63 ~12 ~53 stained_hardened_clay 3  
fill ~59 ~12 ~54 ~64 ~12 ~54 stained_hardened_clay 3  
fill ~59 ~12 ~55 ~64 ~12 ~55 stained_hardened_clay 3  
fill ~59 ~12 ~56 ~65 ~12 ~56 stained_hardened_clay 3  
fill ~60 ~12 ~30 ~60 ~13 ~30 concrete 8  
fill ~60 ~12 ~48 ~62 ~12 ~48 stained_hardened_clay 3  
fill ~60 ~12 ~49 ~62 ~12 ~49 stained_hardened_clay 3  
fill ~60 ~12 ~57 ~65 ~12 ~57 stained_hardened_clay 3  
fill ~60 ~12 ~58 ~60 ~12 ~60 stained_hardened_clay 9 
setblock ~61 ~12 ~31 concrete 8  
fill ~61 ~12 ~35 ~62 ~12 ~35 stained_hardened_clay 3  
fill ~61 ~12 ~36 ~63 ~12 ~36 stained_hardened_clay 3  
fill ~61 ~12 ~37 ~63 ~12 ~37 stained_hardened_clay 3  
fill ~61 ~12 ~38 ~63 ~12 ~38 stained_hardened_clay 3  
fill ~61 ~12 ~39 ~63 ~12 ~39 stained_hardened_clay 3  
fill ~61 ~12 ~40 ~63 ~12 ~40 stained_hardened_clay 3  
fill ~61 ~12 ~41 ~63 ~12 ~41 stained_hardened_clay 3  
fill ~61 ~12 ~42 ~63 ~12 ~42 stained_hardened_clay 3  
fill ~61 ~12 ~43 ~63 ~12 ~43 stained_hardened_clay 3  
fill ~61 ~12 ~44 ~63 ~12 ~44 stained_hardened_clay 3  
fill ~61 ~12 ~45 ~63 ~12 ~45 stained_hardened_clay 3  
fill ~61 ~12 ~46 ~63 ~12 ~46 stained_hardened_clay 3  
fill ~61 ~12 ~47 ~63 ~12 ~47 stained_hardened_clay 3  
fill ~61 ~12 ~58 ~65 ~12 ~58 stained_hardened_clay 3  
fill ~61 ~12 ~59 ~66 ~12 ~59 stained_hardened_clay 3  
fill ~61 ~12 ~60 ~66 ~12 ~60 stained_hardened_clay 3  
fill ~61 ~12 ~61 ~66 ~12 ~61 stained_hardened_clay 3  
fill ~61 ~12 ~62 ~66 ~12 ~62 stained_hardened_clay 3  
fill ~61 ~12 ~63 ~66 ~12 ~63 stained_hardened_clay 3 
setblock ~62 ~12 ~33 concrete 8  
fill ~62 ~12 ~64 ~65 ~12 ~64 stained_hardened_clay 3  
fill ~62 ~12 ~65 ~64 ~12 ~65 stained_hardened_clay 3  
fill ~62 ~12 ~66 ~62 ~12 ~34 stained_hardened_clay 3  
fill ~80 ~12 ~54 ~80 ~13 ~54 stained_hardened_clay 0  
fill ~85 ~12 ~56 ~86 ~12 ~56 concrete 6  
fill ~85 ~12 ~57 ~86 ~12 ~57 concrete 6  
fill ~15 ~13 ~62 ~16 ~13 ~62 concrete 8  
fill ~15 ~13 ~63 ~17 ~13 ~63 concrete 8  
fill ~15 ~13 ~65 ~16 ~13 ~65 concrete 8  
fill ~15 ~13 ~66 ~16 ~13 ~66 concrete 8  
fill ~16 ~13 ~58 ~16 ~13 ~67 concrete 8 
setblock ~16 ~13 ~68 stained_hardened_clay 3  
fill ~17 ~13 ~55 ~19 ~13 ~55 concrete 8  
fill ~17 ~13 ~56 ~17 ~13 ~57 concrete 8  
fill ~17 ~13 ~69 ~17 ~13 ~70 stained_hardened_clay 3  
fill ~18 ~13 ~47 ~18 ~13 ~55 concrete 8  
fill ~18 ~13 ~71 ~18 ~13 ~72 stained_hardened_clay 3  
fill ~19 ~13 ~45 ~19 ~13 ~46 concrete 8  
fill ~19 ~13 ~52 ~19 ~13 ~53 concrete 8 
setblock ~19 ~13 ~56 concrete 8  
fill ~19 ~13 ~57 ~19 ~13 ~58 stained_hardened_clay 3 
setblock ~19 ~13 ~73 stained_hardened_clay 3 
setblock ~20 ~13 ~43 stained_hardened_clay 3 
setblock ~20 ~13 ~44 concrete 8  
fill ~20 ~13 ~51 ~21 ~13 ~51 stained_hardened_clay 3  
fill ~20 ~13 ~52 ~20 ~13 ~51 stained_hardened_clay 3  
fill ~20 ~13 ~59 ~20 ~13 ~60 stained_hardened_clay 3 
setblock ~20 ~13 ~74 stained_hardened_clay 3  
fill ~21 ~13 ~41 ~21 ~13 ~42 stained_hardened_clay 3  
fill ~21 ~13 ~50 ~23 ~13 ~50 stained_hardened_clay 3 
setblock ~21 ~13 ~61 stained_hardened_clay 3  
fill ~21 ~13 ~75 ~22 ~13 ~75 stained_hardened_clay 3 
setblock ~22 ~13 ~40 stained_hardened_clay 3  
fill ~22 ~13 ~49 ~24 ~13 ~49 stained_hardened_clay 3  
fill ~22 ~13 ~62 ~22 ~13 ~63 stained_hardened_clay 3  
fill ~23 ~13 ~39 ~25 ~13 ~39 stained_hardened_clay 3  
fill ~23 ~13 ~48 ~30 ~13 ~48 stained_hardened_clay 3  
fill ~23 ~13 ~63 ~24 ~13 ~63 stained_hardened_clay 3  
fill ~23 ~13 ~76 ~24 ~13 ~76 stained_hardened_clay 3  
fill ~24 ~13 ~64 ~30 ~13 ~64 stained_hardened_clay 3  
fill ~24 ~13 ~77 ~25 ~13 ~77 stained_hardened_clay 3  
fill ~25 ~13 ~38 ~27 ~13 ~38 stained_hardened_clay 3 
setblock ~25 ~13 ~47 stained_hardened_clay 3  
fill ~26 ~13 ~49 ~31 ~13 ~49 stained_hardened_clay 3  
fill ~26 ~13 ~52 ~27 ~13 ~52 stained_hardened_clay 3  
fill ~26 ~13 ~53 ~27 ~13 ~53 stained_hardened_clay 3  
fill ~26 ~13 ~54 ~27 ~13 ~54 stained_hardened_clay 3  
fill ~26 ~13 ~65 ~27 ~13 ~65 stained_hardened_clay 3  
fill ~26 ~13 ~78 ~29 ~13 ~78 stained_hardened_clay 3  
fill ~27 ~13 ~37 ~31 ~13 ~37 stained_hardened_clay 3  
fill ~27 ~13 ~50 ~28 ~13 ~50 stained_hardened_clay 3  
fill ~27 ~13 ~51 ~28 ~13 ~51 stained_hardened_clay 3  
fill ~27 ~13 ~55 ~27 ~13 ~57 stained_hardened_clay 3  
fill ~28 ~13 ~56 ~28 ~13 ~59 stained_hardened_clay 3  
fill ~29 ~13 ~47 ~32 ~13 ~47 stained_hardened_clay 3  
fill ~29 ~13 ~59 ~29 ~13 ~60 stained_hardened_clay 3  
fill ~29 ~13 ~63 ~32 ~13 ~63 stained_hardened_clay 3  
fill ~30 ~13 ~38 ~33 ~13 ~38 stained_hardened_clay 3  
fill ~30 ~13 ~61 ~30 ~12 ~61 stained_hardened_clay 3  
fill ~30 ~13 ~62 ~31 ~13 ~62 stained_hardened_clay 3  
fill ~30 ~13 ~79 ~36 ~13 ~79 stained_hardened_clay 3  
fill ~31 ~13 ~46 ~36 ~13 ~46 stained_hardened_clay 3 
setblock ~31 ~13 ~50 stained_hardened_clay 3  
fill ~32 ~13 ~39 ~35 ~13 ~39 stained_hardened_clay 3  
fill ~32 ~13 ~51 ~32 ~13 ~52 stained_hardened_clay 3 
setblock ~32 ~13 ~61 stained_hardened_clay 3 
setblock ~32 ~13 ~64 stained_hardened_clay 3  
fill ~32 ~13 ~65 ~33 ~13 ~65 stained_hardened_clay 9  
fill ~33 ~13 ~52 ~33 ~13 ~55 stained_hardened_clay 3  
fill ~33 ~13 ~59 ~33 ~13 ~60 stained_hardened_clay 3  
fill ~33 ~13 ~66 ~34 ~13 ~66 stained_hardened_clay 9  
fill ~34 ~13 ~45 ~36 ~13 ~45 stained_hardened_clay 3  
fill ~34 ~13 ~54 ~34 ~13 ~63 stained_hardened_clay 9  
fill ~34 ~13 ~67 ~38 ~13 ~67 stained_hardened_clay 9  
fill ~35 ~13 ~40 ~35 ~13 ~41 stained_hardened_clay 3  
fill ~35 ~13 ~55 ~35 ~15 ~55 stained_hardened_clay 9  
fill ~35 ~13 ~56 ~35 ~15 ~56 stained_hardened_clay 9  
fill ~35 ~13 ~57 ~35 ~15 ~57 stained_hardened_clay 9  
fill ~35 ~13 ~64 ~35 ~14 ~64 stained_hardened_clay 9  
fill ~35 ~13 ~65 ~35 ~16 ~65 stained_hardened_clay 9 
setblock ~35 ~13 ~68 stained_hardened_clay 9  
fill ~35 ~13 ~78 ~37 ~13 ~78 stained_hardened_clay 3  
fill ~36 ~13 ~41 ~36 ~13 ~43 stained_hardened_clay 3  
fill ~36 ~13 ~53 ~36 ~13 ~54 stained_hardened_clay 9  
fill ~36 ~13 ~66 ~36 ~16 ~66 stained_hardened_clay 9 
setblock ~36 ~13 ~69 stained_hardened_clay 9  
fill ~37 ~13 ~43 ~37 ~14 ~43 stained_hardened_clay 3  
fill ~37 ~13 ~44 ~37 ~14 ~44 stained_hardened_clay 3  
fill ~37 ~13 ~45 ~41 ~13 ~45 stained_hardened_clay 9  
fill ~37 ~13 ~46 ~42 ~13 ~46 stained_hardened_clay 9  
fill ~37 ~13 ~47 ~38 ~13 ~47 stained_hardened_clay 9  
fill ~37 ~13 ~49 ~37 ~13 ~52 stained_hardened_clay 9  
fill ~37 ~13 ~68 ~42 ~13 ~68 stained_hardened_clay 9  
fill ~38 ~13 ~48 ~38 ~14 ~48 stained_hardened_clay 9  
fill ~38 ~13 ~69 ~40 ~13 ~69 stained_hardened_clay 9  
fill ~38 ~13 ~70 ~38 ~14 ~70 stained_hardened_clay 9  
fill ~38 ~13 ~76 ~39 ~13 ~76 stained_hardened_clay 9  
fill ~38 ~13 ~77 ~39 ~13 ~77 stained_hardened_clay 9  
fill ~38 ~13 ~78 ~38 ~13 ~76 stained_hardened_clay 9  
fill ~39 ~13 ~71 ~39 ~14 ~71 stained_hardened_clay 9  
fill ~39 ~13 ~72 ~39 ~13 ~77 stained_hardened_clay 9  
fill ~40 ~13 ~15 ~42 ~13 ~15 stained_hardened_clay 3
fill ~40 ~13 ~16 ~43 ~13 ~16 stained_hardened_clay 3 
setblock ~40 ~13 ~74 stained_hardened_clay 9  
fill ~41 ~13 ~14 ~42 ~13 ~14 stained_hardened_clay 3  
fill ~41 ~13 ~67 ~43 ~13 ~67 stained_hardened_clay 9  
fill ~42 ~13 ~47 ~44 ~13 ~47 stained_hardened_clay 9  
fill ~42 ~13 ~66 ~47 ~13 ~66 stained_hardened_clay 9  
fill ~43 ~13 ~17 ~43 ~13 ~18 stained_hardened_clay 3  
fill ~43 ~13 ~48 ~45 ~13 ~48 stained_hardened_clay 9 
setblock ~44 ~13 ~18 stained_hardened_clay 3  
fill ~44 ~13 ~65 ~47 ~13 ~65 stained_hardened_clay 9  
fill ~45 ~13 ~49 ~46 ~13 ~49 stained_hardened_clay 9  
fill ~45 ~13 ~58 ~47 ~13 ~58 stained_hardened_clay 3 
setblock ~45 ~13 ~61 stained_hardened_clay 3  
fill ~45 ~13 ~62 ~46 ~13 ~62 stained_hardened_clay 9  
fill ~45 ~13 ~63 ~46 ~13 ~63 stained_hardened_clay 9  
fill ~45 ~13 ~64 ~46 ~13 ~64 stained_hardened_clay 9  
fill ~46 ~13 ~50 ~48 ~13 ~50 stained_hardened_clay 9  
fill ~46 ~13 ~51 ~46 ~13 ~52 stained_hardened_clay 3  
fill ~46 ~13 ~53 ~46 ~13 ~54 concrete 8  
fill ~46 ~13 ~56 ~47 ~13 ~56 stained_hardened_clay 3  
fill ~46 ~13 ~57 ~47 ~13 ~57 stained_hardened_clay 3  
fill ~46 ~13 ~59 ~47 ~13 ~59 stained_hardened_clay 3  
fill ~46 ~13 ~60 ~46 ~13 ~56 stained_hardened_clay 3 
setblock ~46 ~13 ~61 stained_hardened_clay 9  
fill ~46 ~13 ~67 ~48 ~13 ~67 stained_hardened_clay 9  
fill ~47 ~13 ~51 ~48 ~13 ~51 stained_hardened_clay 9  
fill ~47 ~13 ~52 ~52 ~13 ~52 stained_hardened_clay 9  
fill ~47 ~13 ~53 ~48 ~13 ~53 stained_hardened_clay 3  
fill ~47 ~13 ~54 ~49 ~13 ~54 stained_hardened_clay 3  
fill ~47 ~13 ~55 ~49 ~13 ~55 stained_hardened_clay 3  
fill ~47 ~13 ~68 ~52 ~13 ~68 stained_hardened_clay 9  
fill ~47 ~13 ~69 ~51 ~13 ~69 stained_hardened_clay 9  
fill ~48 ~13 ~34 ~52 ~13 ~34 stained_hardened_clay 9  
fill ~48 ~13 ~35 ~52 ~13 ~35 stained_hardened_clay 9  
fill ~48 ~13 ~36 ~51 ~13 ~36 stained_hardened_clay 9  
fill ~48 ~13 ~37 ~51 ~13 ~37 stained_hardened_clay 9  
fill ~48 ~13 ~38 ~50 ~13 ~38 stained_hardened_clay 9  
fill ~48 ~13 ~39 ~50 ~13 ~39 stained_hardened_clay 9  
fill ~48 ~13 ~40 ~50 ~13 ~40 stained_hardened_clay 9  
fill ~48 ~13 ~41 ~54 ~13 ~41 stained_hardened_clay 9  
fill ~48 ~13 ~45 ~49 ~13 ~45 stained_hardened_clay 9  
fill ~48 ~13 ~46 ~49 ~13 ~46 stained_hardened_clay 9  
fill ~48 ~13 ~47 ~48 ~13 ~52 stained_hardened_clay 9  
fill ~48 ~13 ~70 ~51 ~13 ~70 stained_hardened_clay 9  
fill ~49 ~13 ~33 ~52 ~13 ~33 stained_hardened_clay 9  
fill ~49 ~13 ~42 ~49 ~15 ~42 stained_hardened_clay 9  
fill ~49 ~13 ~43 ~49 ~13 ~46 stained_hardened_clay 9  
fill ~49 ~13 ~53 ~52 ~13 ~53 stained_hardened_clay 9  
fill ~50 ~13 ~32 ~51 ~13 ~32 stained_hardened_clay 9  
fill ~50 ~13 ~54 ~53 ~13 ~54 stained_hardened_clay 9  
fill ~50 ~13 ~55 ~54 ~13 ~55 stained_hardened_clay 9  
fill ~51 ~13 ~30 ~53 ~13 ~30 stained_hardened_clay 3  
fill ~51 ~13 ~31 ~54 ~13 ~31 stained_hardened_clay 3  
fill ~51 ~13 ~38 ~53 ~13 ~38 coal_ore 0  
fill ~51 ~13 ~39 ~53 ~13 ~39 coal_ore 0  
fill ~51 ~13 ~40 ~52 ~13 ~40 coal_ore 0  
fill ~51 ~13 ~67 ~54 ~13 ~67 stained_hardened_clay 9 
setblock ~52 ~13 ~32 stained_hardened_clay 3  
fill ~52 ~13 ~36 ~54 ~13 ~36 coal_ore 0  
fill ~52 ~13 ~37 ~54 ~13 ~37 coal_ore 0  
fill ~52 ~13 ~69 ~53 ~13 ~69 stained_hardened_clay 3  
fill ~53 ~13 ~28 ~57 ~13 ~28 stained_hardened_clay 3  
fill ~53 ~13 ~29 ~54 ~13 ~29 stained_hardened_clay 3 
setblock ~53 ~13 ~32 stained_hardened_clay 9  
fill ~53 ~13 ~33 ~54 ~13 ~33 coal_ore 0  
fill ~53 ~13 ~34 ~54 ~13 ~34 coal_ore 0  
fill ~53 ~13 ~35 ~55 ~13 ~35 coal_ore 0 
setblock ~53 ~13 ~40 stained_hardened_clay 9  
fill ~53 ~13 ~56 ~54 ~13 ~56 stained_hardened_clay 9  
fill ~53 ~13 ~57 ~54 ~13 ~57 stained_hardened_clay 9  
fill ~53 ~13 ~66 ~55 ~13 ~66 stained_hardened_clay 9  
fill ~53 ~13 ~68 ~54 ~13 ~68 stained_hardened_clay 3  
fill ~54 ~13 ~26 ~58 ~13 ~26 stained_hardened_clay 3  
fill ~54 ~13 ~27 ~56 ~13 ~27 stained_hardened_clay 3 
setblock ~54 ~13 ~32 coal_ore 0  
fill ~54 ~13 ~38 ~63 ~13 ~38 stained_hardened_clay 3  
fill ~54 ~13 ~39 ~64 ~13 ~39 stained_hardened_clay 3  
fill ~54 ~13 ~40 ~61 ~13 ~40 stained_hardened_clay 3  
fill ~54 ~13 ~58 ~59 ~13 ~58 stained_hardened_clay 9  
fill ~54 ~13 ~59 ~55 ~13 ~59 stained_hardened_clay 9  
fill ~54 ~13 ~65 ~55 ~13 ~65 stained_hardened_clay 9  
fill ~55 ~13 ~25 ~57 ~13 ~25 stained_hardened_clay 3  
fill ~55 ~13 ~32 ~55 ~14 ~32 stained_hardened_clay 3  
fill ~55 ~13 ~33 ~55 ~14 ~33 stained_hardened_clay 3  
fill ~55 ~13 ~34 ~55 ~14 ~34 stained_hardened_clay 3  
fill ~55 ~13 ~36 ~62 ~13 ~36 stained_hardened_clay 3  
fill ~55 ~13 ~37 ~63 ~13 ~37 stained_hardened_clay 3  
fill ~55 ~13 ~41 ~59 ~13 ~41 stained_hardened_clay 3 
setblock ~55 ~13 ~57 stained_hardened_clay 3  
fill ~55 ~13 ~60 ~55 ~13 ~66 stained_hardened_clay 9 
setblock ~55 ~13 ~67 stained_hardened_clay 3  
fill ~56 ~13 ~35 ~63 ~13 ~35 stained_hardened_clay 3  
fill ~56 ~13 ~50 ~56 ~13 ~53 stained_hardened_clay 9 
setblock ~56 ~13 ~56 stained_hardened_clay 3  
fill ~56 ~13 ~57 ~59 ~13 ~57 stained_hardened_clay 9  
fill ~57 ~13 ~27 ~61 ~13 ~27 concrete 8  
fill ~57 ~13 ~33 ~57 ~14 ~33 stained_hardened_clay 3  
fill ~57 ~13 ~34 ~57 ~14 ~34 stained_hardened_clay 3  
fill ~57 ~13 ~48 ~64 ~13 ~48 stained_hardened_clay 3  
fill ~57 ~13 ~49 ~64 ~13 ~49 stained_hardened_clay 3  
fill ~57 ~13 ~50 ~59 ~13 ~50 stained_hardened_clay 3  
fill ~57 ~13 ~51 ~57 ~13 ~54 stained_hardened_clay 9 
setblock ~57 ~13 ~55 stained_hardened_clay 3  
fill ~57 ~13 ~56 ~59 ~13 ~56 stained_hardened_clay 9 
setblock ~57 ~13 ~59 stained_hardened_clay 3  
fill ~58 ~13 ~28 ~62 ~13 ~28 concrete 8  
fill ~58 ~13 ~32 ~60 ~13 ~32 stained_hardened_clay 3 
setblock ~58 ~13 ~33 stonebrick 3 
setblock ~58 ~13 ~34 stonebrick 2  
fill ~58 ~13 ~47 ~61 ~13 ~47 stained_hardened_clay 3  
fill ~58 ~13 ~51 ~60 ~13 ~51 stained_hardened_clay 3 
setblock ~58 ~13 ~52 stained_hardened_clay 9  
fill ~58 ~13 ~54 ~59 ~13 ~54 stained_hardened_clay 3 
setblock ~58 ~13 ~55 stained_hardened_clay 9  
fill ~58 ~13 ~59 ~59 ~13 ~59 stained_hardened_clay 9  
fill ~58 ~13 ~60 ~58 ~13 ~62 stained_hardened_clay 9  
fill ~59 ~13 ~26 ~60 ~13 ~26 concrete 8  
fill ~59 ~13 ~29 ~62 ~13 ~29 concrete 8  
fill ~59 ~13 ~31 ~60 ~13 ~31 concrete 8  
fill ~59 ~13 ~33 ~61 ~13 ~33 stained_hardened_clay 3  
fill ~59 ~13 ~34 ~62 ~13 ~34 stained_hardened_clay 3  
fill ~59 ~13 ~52 ~59 ~14 ~52 stained_hardened_clay 3  
fill ~59 ~13 ~53 ~59 ~14 ~53 stained_hardened_clay 3  
fill ~59 ~13 ~55 ~59 ~12 ~55 stained_hardened_clay 3 
setblock ~59 ~13 ~60 stained_hardened_clay 3  
fill ~59 ~13 ~61 ~59 ~13 ~63 stained_hardened_clay 9  
fill ~59 ~13 ~64 ~61 ~13 ~64 stained_hardened_clay 3  
fill ~59 ~13 ~65 ~61 ~13 ~65 stained_hardened_clay 3 
setblock ~60 ~13 ~46 stained_hardened_clay 3 
setblock ~60 ~13 ~50 coal_ore 0  
fill ~60 ~13 ~61 ~60 ~13 ~68 stained_hardened_clay 3  
fill ~61 ~13 ~30 ~62 ~13 ~30 concrete 8  
fill ~61 ~13 ~32 ~63 ~13 ~32 concrete 8  
fill ~61 ~13 ~50 ~64 ~13 ~50 stained_hardened_clay 3  
fill ~61 ~13 ~55 ~61 ~14 ~55 stained_hardened_clay 3  
fill ~61 ~13 ~56 ~62 ~13 ~56 stained_hardened_clay 3  
fill ~61 ~13 ~66 ~61 ~13 ~70 stained_hardened_clay 3  
fill ~62 ~13 ~31 ~63 ~13 ~31 concrete 8  
fill ~62 ~13 ~51 ~64 ~13 ~51 stained_hardened_clay 3  
fill ~62 ~13 ~52 ~65 ~13 ~52 stained_hardened_clay 3  
fill ~62 ~13 ~53 ~66 ~13 ~53 stained_hardened_clay 3  
fill ~62 ~13 ~54 ~63 ~13 ~54 stained_hardened_clay 3 
setblock ~62 ~13 ~55 stonebrick 2  
fill ~62 ~13 ~57 ~62 ~14 ~57 stained_hardened_clay 3  
fill ~62 ~13 ~67 ~70 ~13 ~67 stained_hardened_clay 3  
fill ~62 ~13 ~68 ~70 ~13 ~68 stained_hardened_clay 3  
fill ~62 ~13 ~69 ~70 ~13 ~69 stained_hardened_clay 3  
fill ~62 ~13 ~70 ~70 ~13 ~70 stained_hardened_clay 3  
fill ~63 ~13 ~33 ~63 ~13 ~34 concrete 8 
setblock ~63 ~13 ~55 stained_hardened_clay 3  
fill ~63 ~13 ~66 ~70 ~13 ~66 stained_hardened_clay 3  
fill ~64 ~13 ~34 ~64 ~13 ~38 concrete 8  
fill ~64 ~13 ~40 ~65 ~13 ~40 stained_hardened_clay 3  
fill ~64 ~13 ~41 ~65 ~13 ~41 stained_hardened_clay 3  
fill ~64 ~13 ~42 ~64 ~14 ~42 stained_hardened_clay 3  
fill ~64 ~13 ~43 ~64 ~13 ~53 stained_hardened_clay 3  
fill ~64 ~13 ~74 ~67 ~13 ~74 stained_hardened_clay 3  
fill ~64 ~13 ~75 ~66 ~13 ~75 stained_hardened_clay 3  
fill ~64 ~13 ~76 ~65 ~13 ~76 stained_hardened_clay 3  
fill ~65 ~13 ~36 ~65 ~13 ~39 concrete 8  
fill ~65 ~13 ~42 ~65 ~13 ~48 concrete 8  
fill ~65 ~13 ~54 ~67 ~13 ~54 stained_hardened_clay 3  
fill ~65 ~13 ~55 ~67 ~13 ~55 stained_hardened_clay 3  
fill ~65 ~13 ~65 ~69 ~13 ~65 stained_hardened_clay 3  
fill ~65 ~13 ~71 ~70 ~13 ~71 stained_hardened_clay 3  
fill ~65 ~13 ~72 ~69 ~13 ~72 stained_hardened_clay 3  
fill ~65 ~13 ~73 ~68 ~13 ~73 stained_hardened_clay 3  
fill ~66 ~13 ~56 ~67 ~13 ~56 stained_hardened_clay 3  
fill ~66 ~13 ~57 ~68 ~13 ~57 stained_hardened_clay 3  
fill ~66 ~13 ~58 ~68 ~13 ~58 stained_hardened_clay 3  
fill ~66 ~13 ~64 ~68 ~13 ~64 stained_hardened_clay 3  
fill ~67 ~13 ~59 ~68 ~13 ~59 stained_hardened_clay 3  
fill ~67 ~13 ~60 ~68 ~13 ~60 stained_hardened_clay 3  
fill ~67 ~13 ~61 ~68 ~13 ~61 stained_hardened_clay 3  
fill ~67 ~13 ~62 ~68 ~13 ~62 stained_hardened_clay 3  
fill ~67 ~13 ~63 ~68 ~13 ~63 stained_hardened_clay 3  
fill ~80 ~13 ~53 ~81 ~13 ~53 stained_hardened_clay 0  
fill ~85 ~13 ~57 ~85 ~17 ~57 concrete 6  
fill ~86 ~13 ~56 ~86 ~14 ~56 concrete 6  
fill ~86 ~13 ~58 ~86 ~14 ~58 concrete 6  
fill ~87 ~13 ~57 ~87 ~14 ~57 concrete 6  
fill ~13 ~14 ~63 ~16 ~14 ~63 concrete 8  
fill ~13 ~14 ~64 ~15 ~14 ~64 concrete 8  
fill ~13 ~14 ~65 ~15 ~14 ~65 concrete 8  
fill ~13 ~14 ~66 ~15 ~14 ~66 concrete 8  
fill ~13 ~14 ~67 ~15 ~14 ~67 concrete 8  
fill ~14 ~14 ~60 ~15 ~14 ~60 concrete 8  
fill ~14 ~14 ~61 ~17 ~14 ~61 concrete 8  
fill ~14 ~14 ~62 ~18 ~14 ~62 concrete 8  
fill ~14 ~14 ~68 ~15 ~14 ~68 concrete 8  
fill ~15 ~14 ~57 ~16 ~14 ~57 concrete 8  
fill ~15 ~14 ~58 ~15 ~14 ~69 concrete 8  
fill ~16 ~14 ~55 ~17 ~14 ~55 concrete 8  
fill ~16 ~14 ~56 ~16 ~14 ~55 concrete 8 
setblock ~16 ~14 ~69 stained_hardened_clay 3  
fill ~16 ~14 ~70 ~16 ~14 ~71 concrete 8  
fill ~17 ~14 ~47 ~17 ~15 ~47 concrete 8  
fill ~17 ~14 ~48 ~17 ~16 ~48 concrete 8  
fill ~17 ~14 ~49 ~17 ~16 ~49 concrete 8  
fill ~17 ~14 ~50 ~17 ~15 ~50 concrete 8  
fill ~17 ~14 ~51 ~19 ~14 ~51 concrete 8  
fill ~17 ~14 ~52 ~18 ~14 ~52 concrete 8  
fill ~17 ~14 ~53 ~17 ~15 ~53 concrete 8  
fill ~17 ~14 ~54 ~17 ~15 ~54 concrete 8 
setblock ~17 ~14 ~71 stained_hardened_clay 3 
setblock ~17 ~14 ~72 concrete 8  
fill ~18 ~14 ~44 ~19 ~14 ~44 concrete 8  
fill ~18 ~14 ~45 ~18 ~14 ~46 concrete 8  
fill ~18 ~14 ~56 ~18 ~14 ~58 concrete 8  
fill ~18 ~14 ~61 ~20 ~14 ~61 stained_hardened_clay 3  
fill ~18 ~14 ~73 ~18 ~14 ~74 concrete 8  
fill ~19 ~14 ~42 ~20 ~14 ~42 stained_hardened_clay 3 
setblock ~19 ~14 ~43 concrete 8  
fill ~19 ~14 ~49 ~19 ~14 ~51 concrete 8  
fill ~19 ~14 ~59 ~19 ~14 ~61 stained_hardened_clay 3 
setblock ~19 ~14 ~74 stained_hardened_clay 3 
setblock ~20 ~14 ~41 stained_hardened_clay 3  
fill ~20 ~14 ~49 ~21 ~14 ~49 stained_hardened_clay 3  
fill ~20 ~14 ~50 ~20 ~14 ~49 stained_hardened_clay 3 
setblock ~20 ~14 ~75 stained_hardened_clay 3 
setblock ~21 ~14 ~40 stained_hardened_clay 3  
fill ~21 ~14 ~48 ~22 ~14 ~48 stained_hardened_clay 3  
fill ~21 ~14 ~62 ~21 ~14 ~63 stained_hardened_clay 3  
fill ~21 ~14 ~76 ~22 ~14 ~76 stained_hardened_clay 3  
fill ~22 ~14 ~38 ~24 ~14 ~38 stained_hardened_clay 3  
fill ~22 ~14 ~39 ~22 ~14 ~38 stained_hardened_clay 3  
fill ~22 ~14 ~47 ~24 ~14 ~47 stained_hardened_clay 3  
fill ~22 ~14 ~64 ~23 ~14 ~64 stained_hardened_clay 3  
fill ~23 ~14 ~37 ~26 ~14 ~37 stained_hardened_clay 3  
fill ~23 ~14 ~65 ~25 ~14 ~65 stained_hardened_clay 3 
setblock ~23 ~14 ~77 stained_hardened_clay 3  
fill ~24 ~14 ~46 ~30 ~14 ~46 stained_hardened_clay 3  
fill ~24 ~14 ~66 ~28 ~14 ~66 stained_hardened_clay 3  
fill ~24 ~14 ~78 ~25 ~14 ~78 stained_hardened_clay 3  
fill ~25 ~14 ~49 ~26 ~14 ~49 stained_hardened_clay 3  
fill ~25 ~14 ~50 ~26 ~14 ~50 stained_hardened_clay 3  
fill ~25 ~14 ~51 ~26 ~14 ~51 stained_hardened_clay 3  
fill ~25 ~14 ~52 ~25 ~14 ~55 stained_hardened_clay 3  
fill ~26 ~14 ~36 ~32 ~14 ~36 stained_hardened_clay 3  
fill ~26 ~14 ~47 ~31 ~14 ~47 stained_hardened_clay 3  
fill ~26 ~14 ~48 ~27 ~14 ~48 stained_hardened_clay 3  
fill ~26 ~14 ~55 ~26 ~14 ~57 stained_hardened_clay 3  
fill ~26 ~14 ~79 ~29 ~14 ~79 stained_hardened_clay 3  
fill ~27 ~14 ~58 ~27 ~14 ~59 stained_hardened_clay 3 
setblock ~28 ~14 ~60 stained_hardened_clay 3  
fill ~28 ~14 ~65 ~30 ~14 ~65 stained_hardened_clay 3  
fill ~29 ~14 ~35 ~30 ~14 ~35 stained_hardened_clay 3  
fill ~29 ~14 ~61 ~29 ~14 ~62 stained_hardened_clay 3  
fill ~29 ~14 ~75 ~31 ~14 ~75 stained_hardened_clay 3  
fill ~30 ~14 ~45 ~33 ~14 ~45 stained_hardened_clay 3  
fill ~30 ~14 ~63 ~30 ~14 ~64 stained_hardened_clay 9  
fill ~30 ~14 ~76 ~31 ~14 ~76 stained_hardened_clay 3  
fill ~30 ~14 ~77 ~32 ~14 ~77 stained_hardened_clay 3  
fill ~30 ~14 ~80 ~38 ~14 ~80 stained_hardened_clay 3  
fill ~31 ~14 ~48 ~32 ~14 ~48 stained_hardened_clay 3  
fill ~31 ~14 ~64 ~31 ~14 ~66 stained_hardened_clay 9  
fill ~31 ~14 ~78 ~32 ~14 ~78 stained_hardened_clay 3  
fill ~32 ~14 ~37 ~34 ~14 ~37 stained_hardened_clay 3  
fill ~32 ~14 ~44 ~37 ~14 ~44 stained_hardened_clay 3  
fill ~32 ~14 ~49 ~32 ~14 ~50 stained_hardened_clay 3  
fill ~32 ~14 ~62 ~34 ~14 ~62 stained_hardened_clay 9  
fill ~32 ~14 ~63 ~32 ~14 ~62 stained_hardened_clay 9  
fill ~32 ~14 ~66 ~32 ~14 ~67 stained_hardened_clay 9 
setblock ~32 ~14 ~79 stained_hardened_clay 3  
fill ~33 ~14 ~50 ~33 ~14 ~51 stained_hardened_clay 9 
setblock ~33 ~14 ~61 stained_hardened_clay 9  
fill ~33 ~14 ~67 ~33 ~14 ~68 stained_hardened_clay 9  
fill ~34 ~14 ~38 ~35 ~14 ~38 stained_hardened_clay 3  
fill ~34 ~14 ~43 ~38 ~14 ~43 stained_hardened_clay 3  
fill ~34 ~14 ~51 ~34 ~14 ~53 stained_hardened_clay 9  
fill ~34 ~14 ~68 ~34 ~14 ~69 stained_hardened_clay 9  
fill ~35 ~14 ~53 ~35 ~15 ~53 stained_hardened_clay 9  
fill ~35 ~14 ~54 ~36 ~14 ~54 stained_hardened_clay 9  
fill ~35 ~14 ~58 ~35 ~15 ~58 stained_hardened_clay 9  
fill ~35 ~14 ~59 ~35 ~16 ~59 stained_hardened_clay 9  
fill ~35 ~14 ~69 ~35 ~14 ~70 stained_hardened_clay 9  
fill ~36 ~14 ~39 ~36 ~14 ~40 stained_hardened_clay 3  
fill ~36 ~14 ~55 ~36 ~16 ~55 stained_hardened_clay 9  
fill ~36 ~14 ~56 ~36 ~16 ~56 stained_hardened_clay 9  
fill ~36 ~14 ~70 ~42 ~14 ~70 stained_hardened_clay 9  
fill ~36 ~14 ~71 ~41 ~14 ~71 stained_hardened_clay 9  
fill ~37 ~14 ~41 ~37 ~14 ~44 stained_hardened_clay 3  
fill ~37 ~14 ~51 ~37 ~14 ~53 stained_hardened_clay 9  
fill ~37 ~14 ~67 ~37 ~16 ~67 stained_hardened_clay 9  
fill ~37 ~14 ~79 ~38 ~14 ~79 stained_hardened_clay 3  
fill ~38 ~14 ~14 ~40 ~14 ~14 stained_hardened_clay 3  
fill ~38 ~14 ~15 ~39 ~14 ~15 stained_hardened_clay 3  
fill ~38 ~14 ~16 ~39 ~14 ~16 stained_hardened_clay 3  
fill ~38 ~14 ~17 ~42 ~14 ~17 stained_hardened_clay 3  
fill ~38 ~14 ~18 ~42 ~14 ~18 stained_hardened_clay 3  
fill ~38 ~14 ~44 ~42 ~14 ~44 stained_hardened_clay 9  
fill ~38 ~14 ~45 ~39 ~14 ~45 stained_hardened_clay 9  
fill ~38 ~14 ~46 ~38 ~14 ~50 stained_hardened_clay 9  
fill ~38 ~14 ~68 ~38 ~15 ~68 stained_hardened_clay 9  
fill ~39 ~14 ~13 ~45 ~14 ~13 stained_hardened_clay 3  
fill ~39 ~14 ~19 ~47 ~14 ~19 stained_hardened_clay 3  
fill ~39 ~14 ~43 ~40 ~14 ~43 stained_hardened_clay 9  
fill ~39 ~14 ~69 ~39 ~15 ~69 stained_hardened_clay 9  
fill ~39 ~14 ~78 ~40 ~14 ~78 stained_hardened_clay 9  
fill ~39 ~14 ~79 ~40 ~14 ~79 stained_hardened_clay 9  
fill ~40 ~14 ~12 ~44 ~14 ~12 stained_hardened_clay 3  
fill ~40 ~14 ~72 ~40 ~15 ~72 stained_hardened_clay 9  
fill ~40 ~14 ~73 ~40 ~15 ~73 stained_hardened_clay 9  
fill ~40 ~14 ~75 ~41 ~14 ~75 stained_hardened_clay 9  
fill ~40 ~14 ~76 ~41 ~14 ~76 stained_hardened_clay 9  
fill ~40 ~14 ~77 ~40 ~14 ~75 stained_hardened_clay 9  
fill ~41 ~14 ~69 ~43 ~14 ~69 stained_hardened_clay 9 
setblock ~41 ~14 ~74 stained_hardened_clay 9  
fill ~42 ~14 ~45 ~44 ~14 ~45 stained_hardened_clay 9  
fill ~42 ~14 ~82 ~47 ~14 ~82 stained_hardened_clay 9  
fill ~42 ~14 ~83 ~47 ~14 ~83 stained_hardened_clay 9  
fill ~42 ~14 ~84 ~46 ~14 ~84 stained_hardened_clay 9  
fill ~42 ~14 ~85 ~45 ~14 ~85 stained_hardened_clay 9  
fill ~43 ~14 ~14 ~46 ~14 ~14 stained_hardened_clay 3  
fill ~43 ~14 ~15 ~46 ~14 ~15 stained_hardened_clay 3  
fill ~43 ~14 ~46 ~45 ~14 ~46 stained_hardened_clay 9  
fill ~43 ~14 ~68 ~46 ~14 ~68 stained_hardened_clay 9  
fill ~43 ~14 ~78 ~49 ~14 ~78 stained_hardened_clay 9  
fill ~43 ~14 ~79 ~49 ~14 ~79 stained_hardened_clay 9  
fill ~43 ~14 ~80 ~48 ~14 ~80 stained_hardened_clay 9  
fill ~43 ~14 ~81 ~48 ~14 ~81 stained_hardened_clay 9  
fill ~43 ~14 ~86 ~44 ~14 ~86 stained_hardened_clay 9  
fill ~43 ~14 ~87 ~43 ~14 ~78 stained_hardened_clay 9  
fill ~44 ~14 ~16 ~46 ~14 ~16 stained_hardened_clay 3  
fill ~44 ~14 ~17 ~47 ~14 ~17 stained_hardened_clay 3  
fill ~44 ~14 ~20 ~46 ~14 ~20 stained_hardened_clay 3  
fill ~44 ~14 ~21 ~44 ~15 ~21 stained_hardened_clay 3  
fill ~44 ~14 ~56 ~44 ~14 ~58 stained_hardened_clay 9  
fill ~44 ~14 ~59 ~44 ~14 ~61 stained_hardened_clay 3  
fill ~44 ~14 ~62 ~44 ~14 ~68 stained_hardened_clay 9  
fill ~44 ~14 ~77 ~48 ~14 ~77 stained_hardened_clay 9  
fill ~44 ~14 ~87 ~46 ~14 ~87 stained_hardened_clay 3  
fill ~44 ~14 ~88 ~47 ~14 ~88 stained_hardened_clay 9  
fill ~45 ~14 ~18 ~47 ~14 ~18 stained_hardened_clay 3  
fill ~45 ~14 ~47 ~47 ~14 ~47 stained_hardened_clay 9 
setblock ~45 ~14 ~54 stained_hardened_clay 9  
fill ~45 ~14 ~55 ~46 ~14 ~55 stained_hardened_clay 3  
fill ~45 ~14 ~56 ~45 ~14 ~57 stained_hardened_clay 3  
fill ~45 ~14 ~65 ~45 ~14 ~70 stained_hardened_clay 9  
fill ~45 ~14 ~86 ~47 ~14 ~86 stained_hardened_clay 3  
fill ~46 ~14 ~35 ~47 ~14 ~35 stained_hardened_clay 9  
fill ~46 ~14 ~36 ~47 ~14 ~36 stained_hardened_clay 9  
fill ~46 ~14 ~37 ~47 ~14 ~37 stained_hardened_clay 9  
fill ~46 ~14 ~38 ~49 ~14 ~38 stained_hardened_clay 9  
fill ~46 ~14 ~39 ~49 ~14 ~39 stained_hardened_clay 9  
fill ~46 ~14 ~40 ~48 ~14 ~40 stained_hardened_clay 9  
fill ~46 ~14 ~41 ~48 ~14 ~41 stained_hardened_clay 9  
fill ~46 ~14 ~48 ~47 ~14 ~48 stained_hardened_clay 9  
fill ~46 ~14 ~49 ~51 ~14 ~49 stained_hardened_clay 9  
fill ~46 ~14 ~50 ~47 ~14 ~50 stained_hardened_clay 9  
fill ~46 ~14 ~51 ~47 ~14 ~51 stained_hardened_clay 9  
fill ~46 ~14 ~52 ~48 ~14 ~52 stained_hardened_clay 9  
fill ~46 ~14 ~53 ~47 ~14 ~53 stained_hardened_clay 3  
fill ~46 ~14 ~54 ~48 ~14 ~54 stained_hardened_clay 3  
fill ~46 ~14 ~62 ~47 ~14 ~62 stained_hardened_clay 9  
fill ~46 ~14 ~63 ~46 ~14 ~64 stained_hardened_clay 9  
fill ~46 ~14 ~69 ~46 ~14 ~71 stained_hardened_clay 9  
fill ~46 ~14 ~85 ~47 ~14 ~85 stained_hardened_clay 3  
fill ~47 ~14 ~30 ~51 ~14 ~30 stained_hardened_clay 3  
fill ~47 ~14 ~31 ~51 ~14 ~31 stained_hardened_clay 3  
fill ~47 ~14 ~32 ~47 ~14 ~30 stained_hardened_clay 3  
fill ~47 ~14 ~33 ~48 ~14 ~33 stained_hardened_clay 9  
fill ~47 ~14 ~34 ~47 ~14 ~33 stained_hardened_clay 9  
fill ~47 ~14 ~42 ~54 ~14 ~42 stained_hardened_clay 9  
fill ~47 ~14 ~43 ~48 ~14 ~43 stained_hardened_clay 9  
fill ~47 ~14 ~44 ~48 ~14 ~44 stained_hardened_clay 9  
fill ~47 ~14 ~45 ~50 ~14 ~45 stained_hardened_clay 9  
fill ~47 ~14 ~46 ~47 ~14 ~33 stained_hardened_clay 9  
fill ~47 ~14 ~58 ~48 ~14 ~58 stained_hardened_clay 3  
fill ~47 ~14 ~59 ~47 ~14 ~62 stained_hardened_clay 9  
fill ~47 ~14 ~70 ~47 ~14 ~71 stained_hardened_clay 9  
fill ~47 ~14 ~84 ~48 ~14 ~84 stained_hardened_clay 3  
fill ~47 ~14 ~87 ~49 ~14 ~87 stained_hardened_clay 9  
fill ~48 ~14 ~29 ~56 ~14 ~29 stained_hardened_clay 3  
fill ~48 ~14 ~32 ~49 ~14 ~32 stained_hardened_clay 9  
fill ~48 ~14 ~50 ~48 ~14 ~51 coal_ore 0 
setblock ~48 ~14 ~53 stained_hardened_clay 9  
fill ~48 ~14 ~55 ~48 ~14 ~58 stained_hardened_clay 3  
fill ~48 ~14 ~71 ~52 ~14 ~71 stained_hardened_clay 9  
fill ~48 ~14 ~72 ~52 ~14 ~72 stained_hardened_clay 9 
setblock ~48 ~14 ~76 stained_hardened_clay 9  
fill ~48 ~14 ~82 ~49 ~14 ~82 stained_hardened_clay 3  
fill ~48 ~14 ~83 ~48 ~14 ~82 stained_hardened_clay 3  
fill ~48 ~14 ~85 ~49 ~14 ~85 stained_hardened_clay 9  
fill ~48 ~14 ~86 ~49 ~14 ~86 stained_hardened_clay 9  
fill ~49 ~14 ~28 ~54 ~14 ~28 stained_hardened_clay 3 
setblock ~49 ~14 ~33 stained_hardened_clay 3  
fill ~49 ~14 ~34 ~50 ~14 ~34 stained_hardened_clay 9  
fill ~49 ~14 ~35 ~50 ~14 ~35 stained_hardened_clay 9  
fill ~49 ~14 ~36 ~49 ~14 ~39 stained_hardened_clay 9  
fill ~49 ~14 ~43 ~49 ~14 ~44 coal_ore 0  
fill ~49 ~14 ~50 ~52 ~14 ~50 stained_hardened_clay 9  
fill ~49 ~14 ~51 ~53 ~14 ~51 stained_hardened_clay 9  
fill ~49 ~14 ~80 ~50 ~14 ~80 stained_hardened_clay 3  
fill ~49 ~14 ~81 ~49 ~14 ~80 stained_hardened_clay 3  
fill ~49 ~14 ~83 ~50 ~14 ~83 stained_hardened_clay 9  
fill ~49 ~14 ~84 ~50 ~14 ~84 stained_hardened_clay 9 
setblock ~50 ~14 ~27 concrete 8  
fill ~50 ~14 ~32 ~51 ~14 ~32 stained_hardened_clay 3 
setblock ~50 ~14 ~33 stained_hardened_clay 9  
fill ~50 ~14 ~43 ~54 ~14 ~43 stained_hardened_clay 9  
fill ~50 ~14 ~44 ~54 ~14 ~44 stained_hardened_clay 9  
fill ~50 ~14 ~81 ~50 ~14 ~84 stained_hardened_clay 9  
fill ~51 ~14 ~27 ~53 ~14 ~27 stained_hardened_clay 3  
fill ~51 ~14 ~38 ~53 ~14 ~38 stained_hardened_clay 9  
fill ~51 ~14 ~39 ~53 ~14 ~39 stained_hardened_clay 9  
fill ~51 ~14 ~40 ~52 ~14 ~40 stained_hardened_clay 9  
fill ~51 ~14 ~41 ~53 ~14 ~41 stained_hardened_clay 9  
fill ~52 ~14 ~26 ~53 ~14 ~26 stained_hardened_clay 3  
fill ~52 ~14 ~36 ~53 ~14 ~36 stained_hardened_clay 9  
fill ~52 ~14 ~37 ~53 ~14 ~37 stained_hardened_clay 9 
setblock ~52 ~14 ~70 stained_hardened_clay 9  
fill ~53 ~14 ~24 ~60 ~14 ~24 stained_hardened_clay 3  
fill ~53 ~14 ~25 ~54 ~14 ~25 stained_hardened_clay 3  
fill ~53 ~14 ~33 ~58 ~14 ~33 stained_hardened_clay 3  
fill ~53 ~14 ~34 ~58 ~14 ~34 stained_hardened_clay 3 
setblock ~53 ~14 ~35 stained_hardened_clay 9  
fill ~53 ~14 ~52 ~55 ~14 ~52 stained_hardened_clay 9  
fill ~53 ~14 ~53 ~55 ~14 ~53 stained_hardened_clay 9  
fill ~53 ~14 ~70 ~55 ~14 ~70 stained_hardened_clay 3  
fill ~53 ~14 ~71 ~53 ~14 ~70 stained_hardened_clay 3  
fill ~54 ~14 ~23 ~58 ~14 ~23 stained_hardened_clay 3  
fill ~54 ~14 ~30 ~56 ~14 ~30 stained_hardened_clay 3 
setblock ~54 ~14 ~32 stained_hardened_clay 3  
fill ~54 ~14 ~35 ~58 ~14 ~35 stained_hardened_clay 3  
fill ~54 ~14 ~36 ~54 ~14 ~37 stained_hardened_clay 3 
setblock ~54 ~14 ~41 stained_hardened_clay 3  
fill ~54 ~14 ~45 ~54 ~15 ~45 stained_hardened_clay 9  
fill ~54 ~14 ~46 ~55 ~14 ~46 stained_hardened_clay 9  
fill ~54 ~14 ~47 ~55 ~14 ~47 stained_hardened_clay 9  
fill ~54 ~14 ~54 ~56 ~14 ~54 stained_hardened_clay 9  
fill ~54 ~14 ~69 ~55 ~14 ~69 stained_hardened_clay 3  
fill ~55 ~14 ~22 ~56 ~14 ~22 stained_hardened_clay 3  
fill ~55 ~14 ~31 ~57 ~14 ~31 stained_hardened_clay 3  
fill ~55 ~14 ~40 ~56 ~14 ~40 stained_hardened_clay 3 
setblock ~55 ~14 ~41 coal_ore 0  
fill ~55 ~14 ~42 ~64 ~14 ~42 stained_hardened_clay 3  
fill ~55 ~14 ~43 ~62 ~14 ~43 stained_hardened_clay 3  
fill ~55 ~14 ~44 ~60 ~14 ~44 stained_hardened_clay 3  
fill ~55 ~14 ~45 ~61 ~14 ~45 stained_hardened_clay 3  
fill ~55 ~14 ~48 ~55 ~14 ~57 stained_hardened_clay 9  
fill ~55 ~14 ~68 ~56 ~14 ~68 stained_hardened_clay 3  
fill ~56 ~14 ~32 ~57 ~14 ~32 stained_hardened_clay 3  
fill ~56 ~14 ~36 ~58 ~14 ~36 stained_hardened_clay 3  
fill ~56 ~14 ~37 ~58 ~14 ~37 stained_hardened_clay 3  
fill ~56 ~14 ~38 ~57 ~14 ~38 stained_hardened_clay 3  
fill ~56 ~14 ~39 ~57 ~14 ~39 stained_hardened_clay 3  
fill ~56 ~14 ~41 ~56 ~15 ~41 stained_hardened_clay 3  
fill ~56 ~14 ~46 ~59 ~14 ~46 stained_hardened_clay 3  
fill ~56 ~14 ~47 ~57 ~14 ~47 stained_hardened_clay 3  
fill ~56 ~14 ~48 ~56 ~14 ~29 stained_hardened_clay 3 
setblock ~56 ~14 ~49 stained_hardened_clay 9  
fill ~56 ~14 ~55 ~56 ~14 ~66 stained_hardened_clay 9  
fill ~56 ~14 ~67 ~56 ~15 ~67 stained_hardened_clay 3 
setblock ~57 ~14 ~29 clay 0  
fill ~57 ~14 ~30 ~59 ~14 ~30 concrete 8  
fill ~57 ~14 ~58 ~57 ~14 ~64 stained_hardened_clay 9  
fill ~57 ~14 ~65 ~58 ~14 ~65 stained_hardened_clay 3  
fill ~57 ~14 ~66 ~59 ~14 ~66 stained_hardened_clay 3  
fill ~58 ~14 ~25 ~59 ~14 ~25 stained_hardened_clay 3  
fill ~58 ~14 ~28 ~59 ~14 ~28 wool 8  
fill ~58 ~14 ~29 ~58 ~14 ~28 wool 8 
setblock ~58 ~14 ~31 concrete 8  
fill ~58 ~14 ~63 ~58 ~15 ~63 stained_hardened_clay 9 
setblock ~58 ~14 ~64 stained_hardened_clay 3  
fill ~58 ~14 ~67 ~59 ~14 ~67 stained_hardened_clay 3  
fill ~58 ~14 ~68 ~59 ~14 ~68 stained_hardened_clay 3  
fill ~59 ~14 ~29 ~59 ~13 ~29 concrete 8  
fill ~59 ~14 ~54 ~59 ~14 ~56 stained_hardened_clay 9  
fill ~59 ~14 ~69 ~60 ~14 ~69 stained_hardened_clay 3  
fill ~59 ~14 ~70 ~60 ~14 ~70 stained_hardened_clay 3  
fill ~59 ~14 ~71 ~68 ~14 ~71 stained_hardened_clay 3  
fill ~60 ~14 ~25 ~61 ~14 ~25 concrete 8  
fill ~60 ~14 ~41 ~64 ~14 ~41 stained_hardened_clay 3  
fill ~60 ~14 ~50 ~60 ~14 ~56 stained_hardened_clay 3  
fill ~60 ~14 ~57 ~60 ~14 ~60 stained_hardened_clay 9  
fill ~60 ~14 ~72 ~66 ~14 ~72 stained_hardened_clay 3  
fill ~60 ~14 ~73 ~66 ~14 ~73 stained_hardened_clay 3  
fill ~61 ~14 ~26 ~62 ~14 ~26 concrete 8  
fill ~61 ~14 ~46 ~63 ~14 ~46 stained_hardened_clay 3  
fill ~61 ~14 ~52 ~61 ~14 ~62 stained_hardened_clay 3  
fill ~62 ~14 ~27 ~63 ~14 ~27 concrete 8  
fill ~62 ~14 ~40 ~63 ~14 ~40 stained_hardened_clay 3  
fill ~62 ~14 ~47 ~64 ~14 ~47 stained_hardened_clay 3  
fill ~62 ~14 ~54 ~62 ~12 ~54 stained_hardened_clay 3  
fill ~62 ~14 ~55 ~62 ~14 ~61 stained_hardened_clay 3  
fill ~62 ~14 ~69 ~65 ~14 ~69 stained_hardened_clay 3  
fill ~62 ~14 ~70 ~64 ~14 ~70 stained_hardened_clay 3  
fill ~62 ~14 ~74 ~65 ~14 ~74 stained_hardened_clay 3  
fill ~62 ~14 ~75 ~63 ~14 ~75 stained_hardened_clay 3  
fill ~62 ~14 ~76 ~63 ~14 ~76 stained_hardened_clay 3  
fill ~62 ~14 ~77 ~69 ~14 ~77 stained_hardened_clay 3  
fill ~62 ~14 ~78 ~69 ~14 ~78 stained_hardened_clay 3 
setblock ~62 ~14 ~79 stained_hardened_clay 9  
fill ~63 ~14 ~28 ~63 ~14 ~30 concrete 8 
setblock ~63 ~14 ~48 stained_hardened_clay 3  
fill ~63 ~14 ~56 ~64 ~14 ~56 stained_hardened_clay 3  
fill ~63 ~14 ~57 ~63 ~14 ~58 stained_hardened_clay 3  
fill ~63 ~14 ~67 ~65 ~14 ~67 stained_hardened_clay 3  
fill ~63 ~14 ~68 ~65 ~14 ~68 stained_hardened_clay 3  
fill ~63 ~14 ~79 ~68 ~14 ~79 stained_hardened_clay 3  
fill ~64 ~14 ~29 ~64 ~14 ~33 concrete 8  
fill ~64 ~14 ~48 ~66 ~14 ~48 concrete 8 
setblock ~64 ~14 ~49 stained_hardened_clay 3  
fill ~64 ~14 ~53 ~65 ~14 ~53 stained_hardened_clay 3  
fill ~64 ~14 ~54 ~64 ~15 ~54 stained_hardened_clay 3  
fill ~64 ~14 ~55 ~64 ~15 ~55 stained_hardened_clay 3  
fill ~64 ~14 ~65 ~72 ~14 ~65 stained_hardened_clay 3  
fill ~64 ~14 ~66 ~66 ~14 ~66 stained_hardened_clay 3  
fill ~65 ~14 ~32 ~65 ~14 ~35 concrete 8  
fill ~65 ~14 ~49 ~66 ~14 ~49 concrete 8  
fill ~65 ~14 ~50 ~66 ~14 ~50 concrete 8  
fill ~65 ~14 ~51 ~66 ~14 ~51 stained_hardened_clay 3  
fill ~65 ~14 ~52 ~67 ~14 ~52 stained_hardened_clay 3  
fill ~65 ~14 ~63 ~72 ~14 ~63 stained_hardened_clay 3  
fill ~65 ~14 ~64 ~72 ~14 ~64 stained_hardened_clay 3  
fill ~66 ~14 ~34 ~66 ~14 ~41 concrete 8  
fill ~66 ~14 ~42 ~66 ~14 ~47 wool 8  
fill ~66 ~14 ~62 ~71 ~14 ~62 stained_hardened_clay 3  
fill ~66 ~14 ~76 ~70 ~14 ~76 stained_hardened_clay 3 
setblock ~67 ~14 ~37 concrete 8  
fill ~67 ~14 ~38 ~67 ~14 ~41 wool 8 
setblock ~67 ~14 ~53 stained_hardened_clay 3  
fill ~67 ~14 ~61 ~71 ~14 ~61 stained_hardened_clay 3  
fill ~67 ~14 ~70 ~68 ~14 ~70 stained_hardened_clay 3 
setblock ~67 ~14 ~72 concrete 8  
fill ~67 ~14 ~75 ~71 ~14 ~75 stained_hardened_clay 3  
fill ~68 ~14 ~54 ~68 ~14 ~56 stained_hardened_clay 3  
fill ~68 ~14 ~67 ~68 ~14 ~71 stained_hardened_clay 3  
fill ~68 ~14 ~74 ~71 ~14 ~74 stained_hardened_clay 3  
fill ~69 ~14 ~56 ~69 ~14 ~66 stained_hardened_clay 3  
fill ~69 ~14 ~67 ~69 ~14 ~68 concrete 8 
setblock ~69 ~14 ~73 stained_hardened_clay 3  
fill ~70 ~14 ~72 ~72 ~14 ~72 concrete 8  
fill ~70 ~14 ~73 ~72 ~14 ~73 concrete 8  
fill ~71 ~14 ~66 ~72 ~14 ~66 stained_hardened_clay 3  
fill ~71 ~14 ~67 ~72 ~14 ~67 stained_hardened_clay 3  
fill ~71 ~14 ~68 ~71 ~14 ~70 stained_hardened_clay 3  
fill ~71 ~14 ~71 ~72 ~14 ~71 concrete 8  
fill ~72 ~14 ~68 ~72 ~14 ~73 concrete 8 
setblock ~73 ~14 ~70 concrete 8  
fill ~81 ~14 ~53 ~81 ~15 ~53 stained_hardened_clay 0  
fill ~81 ~14 ~54 ~81 ~15 ~54 stained_hardened_clay 0  
fill ~11 ~15 ~62 ~14 ~15 ~62 concrete 8  
fill ~11 ~15 ~63 ~12 ~15 ~63 concrete 8  
fill ~12 ~15 ~60 ~17 ~15 ~60 concrete 8  
fill ~12 ~15 ~61 ~14 ~15 ~61 concrete 8  
fill ~12 ~15 ~64 ~12 ~15 ~69 concrete 8  
fill ~13 ~15 ~58 ~14 ~15 ~58 concrete 8  
fill ~13 ~15 ~59 ~18 ~15 ~59 concrete 8  
fill ~13 ~15 ~68 ~14 ~15 ~68 concrete 8  
fill ~13 ~15 ~69 ~14 ~15 ~69 concrete 8  
fill ~13 ~15 ~70 ~13 ~16 ~70 concrete 8  
fill ~14 ~15 ~57 ~14 ~16 ~57 concrete 8  
fill ~14 ~15 ~63 ~14 ~15 ~69 concrete 8  
fill ~15 ~15 ~55 ~15 ~15 ~56 concrete 8  
fill ~15 ~15 ~70 ~15 ~15 ~71 concrete 8  
fill ~16 ~15 ~52 ~17 ~15 ~52 concrete 8  
fill ~16 ~15 ~53 ~16 ~17 ~53 concrete 8  
fill ~16 ~15 ~54 ~16 ~18 ~54 concrete 8  
fill ~16 ~15 ~72 ~16 ~15 ~73 concrete 8  
fill ~17 ~15 ~44 ~17 ~16 ~44 concrete 8  
fill ~17 ~15 ~45 ~17 ~16 ~45 concrete 8  
fill ~17 ~15 ~46 ~17 ~15 ~44 concrete 8  
fill ~17 ~15 ~51 ~17 ~14 ~51 concrete 8  
fill ~17 ~15 ~55 ~17 ~16 ~55 concrete 8  
fill ~17 ~15 ~56 ~17 ~17 ~56 concrete 8  
fill ~17 ~15 ~57 ~17 ~17 ~57 concrete 8  
fill ~17 ~15 ~73 ~17 ~15 ~74 concrete 8 
setblock ~18 ~15 ~42 stained_hardened_clay 3 
setblock ~18 ~15 ~43 concrete 8  
fill ~18 ~15 ~49 ~18 ~15 ~50 concrete 8 
setblock ~18 ~15 ~58 concrete 8  
fill ~18 ~15 ~60 ~20 ~15 ~60 stained_hardened_clay 3  
fill ~18 ~15 ~75 ~19 ~15 ~75 concrete 8 
setblock ~19 ~15 ~41 stained_hardened_clay 3 
setblock ~19 ~15 ~48 concrete 8 
setblock ~19 ~15 ~61 stained_hardened_clay 3  
fill ~20 ~15 ~39 ~21 ~15 ~39 stained_hardened_clay 3  
fill ~20 ~15 ~40 ~20 ~15 ~39 stained_hardened_clay 3  
fill ~20 ~15 ~47 ~21 ~15 ~47 stained_hardened_clay 3  
fill ~20 ~15 ~48 ~20 ~15 ~47 stained_hardened_clay 3  
fill ~20 ~15 ~62 ~20 ~15 ~63 stained_hardened_clay 3 
setblock ~20 ~15 ~76 concrete 8 
setblock ~21 ~15 ~38 stained_hardened_clay 3  
fill ~21 ~15 ~46 ~23 ~15 ~46 stained_hardened_clay 3 
setblock ~21 ~15 ~64 stained_hardened_clay 3  
fill ~21 ~15 ~77 ~22 ~15 ~77 stained_hardened_clay 3 
setblock ~22 ~15 ~37 stained_hardened_clay 3  
fill ~22 ~15 ~65 ~22 ~15 ~66 stained_hardened_clay 3  
fill ~23 ~15 ~36 ~25 ~15 ~36 stained_hardened_clay 3  
fill ~23 ~15 ~45 ~31 ~15 ~45 stained_hardened_clay 3  
fill ~23 ~15 ~50 ~24 ~15 ~50 stained_hardened_clay 3  
fill ~23 ~15 ~51 ~24 ~15 ~51 stained_hardened_clay 3  
fill ~23 ~15 ~52 ~24 ~15 ~52 stained_hardened_clay 3  
fill ~23 ~15 ~53 ~24 ~15 ~53 stained_hardened_clay 3 
setblock ~23 ~15 ~66 stained_hardened_clay 3  
fill ~23 ~15 ~78 ~23 ~16 ~78 stained_hardened_clay 3 
setblock ~24 ~15 ~49 stained_hardened_clay 3  
fill ~24 ~15 ~54 ~24 ~15 ~55 stained_hardened_clay 3  
fill ~24 ~15 ~67 ~29 ~15 ~67 stained_hardened_clay 3  
fill ~24 ~15 ~75 ~28 ~15 ~75 stained_hardened_clay 3  
fill ~24 ~15 ~79 ~31 ~15 ~79 stained_hardened_clay 3  
fill ~25 ~15 ~35 ~28 ~15 ~35 stained_hardened_clay 3  
fill ~25 ~15 ~44 ~26 ~15 ~44 stained_hardened_clay 3 
setblock ~25 ~15 ~48 stained_hardened_clay 3  
fill ~25 ~15 ~56 ~25 ~15 ~57 stained_hardened_clay 3  
fill ~25 ~15 ~76 ~29 ~15 ~76 stained_hardened_clay 3  
fill ~25 ~15 ~77 ~29 ~15 ~77 stained_hardened_clay 3  
fill ~25 ~15 ~78 ~30 ~15 ~78 stained_hardened_clay 3  
fill ~26 ~15 ~47 ~26 ~14 ~47 stained_hardened_clay 3 
setblock ~26 ~15 ~58 stained_hardened_clay 3  
fill ~26 ~15 ~80 ~32 ~15 ~80 stained_hardened_clay 3 
setblock ~27 ~15 ~46 stained_hardened_clay 3 
setblock ~27 ~15 ~59 stained_hardened_clay 3 
setblock ~27 ~15 ~60 stained_hardened_clay 9  
fill ~27 ~15 ~81 ~38 ~15 ~81 stained_hardened_clay 3  
fill ~28 ~15 ~34 ~31 ~15 ~34 stained_hardened_clay 3
fill ~28 ~15 ~61 ~28 ~15 ~62 stained_hardened_clay 9  
fill ~29 ~15 ~44 ~31 ~15 ~44 stained_hardened_clay 3  
fill ~29 ~15 ~46 ~32 ~15 ~46 stained_hardened_clay 3  
fill ~29 ~15 ~63 ~29 ~15 ~64 stained_hardened_clay 9  
fill ~29 ~15 ~66 ~30 ~15 ~66 stained_hardened_clay 3  
fill ~30 ~15 ~65 ~31 ~15 ~65 stained_hardened_clay 9  
fill ~30 ~15 ~82 ~33 ~15 ~82 stained_hardened_clay 3  
fill ~31 ~15 ~35 ~33 ~15 ~35 stained_hardened_clay 3  
fill ~31 ~15 ~43 ~33 ~15 ~43 stained_hardened_clay 3  
fill ~31 ~15 ~67 ~31 ~17 ~67 stained_hardened_clay 9 
setblock ~32 ~15 ~47 stained_hardened_clay 3 
setblock ~32 ~15 ~64 stained_hardened_clay 9  
fill ~32 ~15 ~68 ~32 ~15 ~69 stained_hardened_clay 9  
fill ~33 ~15 ~36 ~35 ~15 ~36 stained_hardened_clay 3  
fill ~33 ~15 ~42 ~39 ~15 ~42 stained_hardened_clay 3 
setblock ~33 ~15 ~48 stained_hardened_clay 3  
fill ~33 ~15 ~49 ~34 ~15 ~49 stained_hardened_clay 9 
setblock ~33 ~15 ~63 stained_hardened_clay 9 
setblock ~33 ~15 ~69 stained_hardened_clay 9  
fill ~34 ~15 ~50 ~35 ~15 ~50 stained_hardened_clay 9 
setblock ~34 ~15 ~64 stained_hardened_clay 9 
setblock ~34 ~15 ~70 stained_hardened_clay 9  
fill ~35 ~15 ~37 ~36 ~15 ~37 stained_hardened_clay 3 
setblock ~35 ~15 ~41 stained_hardened_clay 3  
fill ~35 ~15 ~51 ~35 ~15 ~61 stained_hardened_clay 9 
setblock ~35 ~15 ~71 stained_hardened_clay 9  
fill ~36 ~15 ~12 ~39 ~15 ~12 stained_hardened_clay 3  
fill ~36 ~15 ~13 ~38 ~15 ~13 stained_hardened_clay 3  
fill ~36 ~15 ~14 ~37 ~15 ~14 stained_hardened_clay 3  
fill ~36 ~15 ~15 ~37 ~15 ~15 stained_hardened_clay 3  
fill ~36 ~15 ~16 ~37 ~15 ~16 stained_hardened_clay 3  
fill ~36 ~15 ~17 ~37 ~15 ~17 stained_hardened_clay 3  
fill ~36 ~15 ~38 ~37 ~15 ~38 stained_hardened_clay 3  
fill ~36 ~15 ~57 ~36 ~16 ~57 stained_hardened_clay 9  
fill ~36 ~15 ~72 ~42 ~15 ~72 stained_hardened_clay 9  
fill ~37 ~15 ~18 ~37 ~15 ~19 stained_hardened_clay 3  
fill ~37 ~15 ~39 ~37 ~15 ~40 stained_hardened_clay 3  
fill ~37 ~15 ~53 ~37 ~15 ~54 stained_hardened_clay 9  
fill ~38 ~15 ~11 ~45 ~15 ~11 stained_hardened_clay 3  
fill ~38 ~15 ~19 ~38 ~15 ~20 stained_hardened_clay 3  
fill ~38 ~15 ~40 ~38 ~15 ~42 stained_hardened_clay 3  
fill ~38 ~15 ~50 ~38 ~15 ~52 stained_hardened_clay 9  
fill ~39 ~15 ~20 ~43 ~15 ~20 stained_hardened_clay 3  
fill ~39 ~15 ~21 ~44 ~15 ~21 stained_hardened_clay 3 
setblock ~39 ~15 ~43 stained_hardened_clay 3  
fill ~39 ~15 ~44 ~39 ~15 ~49 stained_hardened_clay 9 
setblock ~39 ~15 ~73 stained_hardened_clay 9  
fill ~39 ~15 ~80 ~41 ~15 ~80 stained_hardened_clay 3  
fill ~40 ~15 ~42 ~42 ~15 ~42 stained_hardened_clay 9 
setblock ~40 ~15 ~70 stained_hardened_clay 9  
fill ~40 ~15 ~81 ~41 ~15 ~81 stained_hardened_clay 3  
fill ~40 ~15 ~82 ~41 ~15 ~82 stained_hardened_clay 3  
fill ~40 ~15 ~83 ~41 ~15 ~83 stained_hardened_clay 3  
fill ~40 ~15 ~84 ~40 ~15 ~86 stained_hardened_clay 3  
fill ~41 ~15 ~43 ~43 ~15 ~43 stained_hardened_clay 9  
fill ~41 ~15 ~71 ~45 ~15 ~71 stained_hardened_clay 9  
fill ~41 ~15 ~73 ~41 ~16 ~73 stained_hardened_clay 9  
fill ~41 ~15 ~77 ~43 ~15 ~77 stained_hardened_clay 9  
fill ~41 ~15 ~78 ~42 ~15 ~78 stained_hardened_clay 9  
fill ~41 ~15 ~79 ~42 ~15 ~79 stained_hardened_clay 9  
fill ~41 ~15 ~84 ~41 ~15 ~85 stained_hardened_clay 9  
fill ~41 ~15 ~86 ~41 ~15 ~88 stained_hardened_clay 3  
fill ~42 ~15 ~74 ~42 ~15 ~81 stained_hardened_clay 9  
fill ~42 ~15 ~86 ~42 ~15 ~89 stained_hardened_clay 9  
fill ~43 ~15 ~22 ~47 ~15 ~22 concrete 8  
fill ~43 ~15 ~40 ~47 ~15 ~40 stained_hardened_clay 9  
fill ~43 ~15 ~44 ~47 ~15 ~44 stained_hardened_clay 9  
fill ~43 ~15 ~56 ~43 ~16 ~56 stained_hardened_clay 9  
fill ~43 ~15 ~57 ~43 ~16 ~57 stained_hardened_clay 9  
fill ~43 ~15 ~58 ~43 ~15 ~68 stained_hardened_clay 9  
fill ~43 ~15 ~70 ~44 ~15 ~70 stained_hardened_clay 9  
fill ~43 ~15 ~76 ~47 ~15 ~76 stained_hardened_clay 9  
fill ~43 ~15 ~88 ~43 ~15 ~89 stained_hardened_clay 9  
fill ~43 ~15 ~90 ~45 ~15 ~90 stained_hardened_clay 3  
fill ~44 ~15 ~23 ~44 ~17 ~23 concrete 8 
setblock ~44 ~15 ~24 stained_hardened_clay 3  
fill ~44 ~15 ~36 ~44 ~16 ~36 stained_hardened_clay 3  
fill ~44 ~15 ~37 ~44 ~16 ~37 stained_hardened_clay 3  
fill ~44 ~15 ~38 ~44 ~16 ~38 stained_hardened_clay 3  
fill ~44 ~15 ~39 ~45 ~15 ~39 stained_hardened_clay 9  
fill ~44 ~15 ~41 ~45 ~15 ~41 stained_hardened_clay 9  
fill ~44 ~15 ~42 ~46 ~15 ~42 stained_hardened_clay 9  
fill ~44 ~15 ~52 ~45 ~15 ~52 stained_hardened_clay 9  
fill ~44 ~15 ~53 ~45 ~15 ~53 stained_hardened_clay 9  
fill ~44 ~15 ~54 ~44 ~15 ~55 stained_hardened_clay 9  
fill ~44 ~15 ~69 ~45 ~15 ~69 stained_hardened_clay 9  
fill ~44 ~15 ~75 ~50 ~15 ~75 stained_hardened_clay 9  
fill ~44 ~15 ~89 ~45 ~15 ~89 stained_hardened_clay 3  
fill ~45 ~15 ~12 ~47 ~15 ~12 stained_hardened_clay 3  
fill ~45 ~15 ~21 ~46 ~15 ~21 concrete 8 
setblock ~45 ~15 ~23 stained_hardened_clay 3  
fill ~45 ~15 ~34 ~46 ~15 ~34 stained_hardened_clay 3  
fill ~45 ~15 ~35 ~45 ~16 ~35 stained_hardened_clay 3  
fill ~45 ~15 ~36 ~45 ~15 ~53 stained_hardened_clay 9  
fill ~45 ~15 ~67 ~45 ~15 ~69 stained_hardened_clay 9  
fill ~45 ~15 ~72 ~47 ~15 ~72 stained_hardened_clay 9  
fill ~45 ~15 ~74 ~52 ~15 ~74 stained_hardened_clay 9  
fill ~46 ~15 ~13 ~48 ~15 ~13 stained_hardened_clay 3  
fill ~46 ~15 ~29 ~47 ~15 ~29 stained_hardened_clay 3  
fill ~46 ~15 ~30 ~46 ~16 ~30 stained_hardened_clay 3  
fill ~46 ~15 ~31 ~46 ~16 ~31 stained_hardened_clay 3  
fill ~46 ~15 ~32 ~46 ~16 ~32 stained_hardened_clay 3  
fill ~46 ~15 ~33 ~46 ~16 ~33 stained_hardened_clay 3  
fill ~46 ~15 ~41 ~46 ~16 ~41 coal_ore 0  
fill ~46 ~15 ~43 ~46 ~16 ~43 stained_hardened_clay 9  
fill ~46 ~15 ~45 ~47 ~15 ~45 stained_hardened_clay 9  
fill ~46 ~15 ~46 ~46 ~17 ~46 stained_hardened_clay 9  
fill ~46 ~15 ~47 ~47 ~15 ~47 coal_ore 0  
fill ~46 ~15 ~48 ~47 ~15 ~48 coal_ore 0  
fill ~46 ~15 ~49 ~48 ~15 ~49 stained_hardened_clay 9  
fill ~46 ~15 ~50 ~46 ~13 ~50 stained_hardened_clay 9  
fill ~46 ~15 ~51 ~46 ~14 ~51 stained_hardened_clay 9  
fill ~46 ~15 ~65 ~46 ~15 ~66 stained_hardened_clay 9  
fill ~46 ~15 ~73 ~53 ~15 ~73 stained_hardened_clay 9  
fill ~46 ~15 ~89 ~50 ~15 ~89 stained_hardened_clay 9  
fill ~46 ~15 ~90 ~48 ~15 ~90 stained_hardened_clay 9  
fill ~47 ~15 ~14 ~48 ~15 ~14 stained_hardened_clay 3  
fill ~47 ~15 ~15 ~48 ~15 ~15 stained_hardened_clay 3  
fill ~47 ~15 ~16 ~49 ~15 ~16 stained_hardened_clay 3  
fill ~47 ~15 ~20 ~49 ~15 ~20 stained_hardened_clay 3  
fill ~47 ~15 ~21 ~48 ~15 ~21 stained_hardened_clay 3  
fill ~47 ~15 ~28 ~50 ~15 ~28 stained_hardened_clay 3 
setblock ~47 ~15 ~36 stained_hardened_clay 3  
fill ~47 ~15 ~37 ~48 ~15 ~37 stained_hardened_clay 9  
fill ~47 ~15 ~38 ~47 ~15 ~41 stained_hardened_clay 9 
setblock ~47 ~15 ~46 coal_ore 0  
fill ~47 ~15 ~62 ~47 ~15 ~64 stained_hardened_clay 9  
fill ~48 ~15 ~17 ~49 ~15 ~17 stained_hardened_clay 3  
fill ~48 ~15 ~18 ~49 ~15 ~18 stained_hardened_clay 3  
fill ~48 ~15 ~19 ~49 ~15 ~19 stained_hardened_clay 3  
fill ~48 ~15 ~26 ~49 ~15 ~26 concrete 8  
fill ~48 ~15 ~27 ~49 ~15 ~27 concrete 8  
fill ~48 ~15 ~32 ~49 ~15 ~32 stained_hardened_clay 3  
fill ~48 ~15 ~33 ~48 ~16 ~33 stained_hardened_clay 3  
fill ~48 ~15 ~34 ~48 ~15 ~32 stained_hardened_clay 3  
fill ~48 ~15 ~35 ~48 ~15 ~37 stained_hardened_clay 9  
fill ~48 ~15 ~46 ~54 ~15 ~46 stained_hardened_clay 9  
fill ~48 ~15 ~47 ~53 ~15 ~47 stained_hardened_clay 9  
fill ~48 ~15 ~48 ~54 ~15 ~48 stained_hardened_clay 9  
fill ~48 ~15 ~50 ~48 ~15 ~51 stained_hardened_clay 9  
fill ~48 ~15 ~55 ~48 ~15 ~56 stained_hardened_clay 9 
setblock ~48 ~15 ~57 stained_hardened_clay 3  
fill ~48 ~15 ~58 ~48 ~19 ~58 stained_hardened_clay 9  
fill ~48 ~15 ~59 ~48 ~20 ~59 stained_hardened_clay 9  
fill ~48 ~15 ~60 ~48 ~20 ~60 stained_hardened_clay 9  
fill ~48 ~15 ~61 ~48 ~20 ~61 stained_hardened_clay 9  
fill ~48 ~15 ~88 ~50 ~15 ~88 stained_hardened_clay 9  
fill ~49 ~15 ~25 ~50 ~15 ~25 concrete 8  
fill ~49 ~15 ~29 ~50 ~15 ~29 stained_hardened_clay 3  
fill ~49 ~15 ~30 ~49 ~15 ~32 stained_hardened_clay 3  
fill ~49 ~15 ~38 ~50 ~15 ~38 stained_hardened_clay 9  
fill ~49 ~15 ~39 ~50 ~15 ~39 stained_hardened_clay 9  
fill ~49 ~15 ~40 ~50 ~15 ~40 stained_hardened_clay 9  
fill ~49 ~15 ~41 ~50 ~15 ~41 stained_hardened_clay 9  
fill ~49 ~15 ~43 ~50 ~15 ~43 stained_hardened_clay 9  
fill ~49 ~15 ~44 ~49 ~15 ~38 stained_hardened_clay 9  
fill ~49 ~15 ~52 ~49 ~17 ~52 stained_hardened_clay 9  
fill ~49 ~15 ~53 ~49 ~18 ~53 stained_hardened_clay 9  
fill ~49 ~15 ~54 ~49 ~20 ~54 stained_hardened_clay 9  
fill ~49 ~15 ~76 ~50 ~15 ~76 stained_hardened_clay 9  
fill ~49 ~15 ~77 ~51 ~15 ~77 stained_hardened_clay 9  
fill ~50 ~15 ~26 ~51 ~15 ~26 stained_hardened_clay 3  
fill ~50 ~15 ~27 ~50 ~15 ~26 stained_hardened_clay 3  
fill ~50 ~15 ~35 ~51 ~15 ~35 stained_hardened_clay 3  
fill ~50 ~15 ~36 ~51 ~15 ~36 stained_hardened_clay 9  
fill ~50 ~15 ~37 ~51 ~15 ~37 stained_hardened_clay 9 
setblock ~50 ~15 ~42 stained_hardened_clay 9 
setblock ~50 ~15 ~44 coal_ore 0  
fill ~50 ~15 ~45 ~55 ~15 ~45 stained_hardened_clay 9  
fill ~50 ~15 ~78 ~51 ~15 ~78 stained_hardened_clay 9  
fill ~50 ~15 ~79 ~51 ~15 ~79 stained_hardened_clay 3  
fill ~50 ~15 ~85 ~52 ~15 ~85 stained_hardened_clay 9  
fill ~50 ~15 ~86 ~51 ~15 ~86 stained_hardened_clay 9  
fill ~50 ~15 ~87 ~51 ~15 ~87 stained_hardened_clay 9  
fill ~51 ~15 ~23 ~53 ~15 ~23 stained_hardened_clay 3  
fill ~51 ~15 ~24 ~52 ~15 ~24 stained_hardened_clay 3  
fill ~51 ~15 ~25 ~54 ~15 ~25 stained_hardened_clay 3  
fill ~51 ~15 ~33 ~52 ~15 ~33 stained_hardened_clay 3  
fill ~51 ~15 ~34 ~52 ~15 ~34 stained_hardened_clay 3  
fill ~51 ~15 ~44 ~54 ~15 ~44 stained_hardened_clay 9  
fill ~51 ~15 ~80 ~52 ~15 ~80 stained_hardened_clay 9  
fill ~51 ~15 ~81 ~52 ~15 ~81 stained_hardened_clay 9  
fill ~51 ~15 ~82 ~52 ~15 ~82 stained_hardened_clay 9  
fill ~51 ~15 ~83 ~52 ~15 ~83 stained_hardened_clay 9  
fill ~51 ~15 ~84 ~52 ~15 ~84 stained_hardened_clay 9  
fill ~52 ~15 ~22 ~54 ~15 ~22 stained_hardened_clay 3  
fill ~52 ~15 ~26 ~53 ~15 ~26 concrete 8  
fill ~52 ~15 ~32 ~53 ~15 ~32 stained_hardened_clay 3 
setblock ~52 ~15 ~35 stained_hardened_clay 9  
fill ~52 ~15 ~49 ~54 ~15 ~49 stained_hardened_clay 9 
setblock ~52 ~15 ~79 stained_hardened_clay 9  
fill ~53 ~15 ~21 ~58 ~15 ~21 stained_hardened_clay 3 
setblock ~53 ~15 ~31 concrete 8  
fill ~53 ~15 ~41 ~54 ~15 ~41 stained_hardened_clay 9  
fill ~53 ~15 ~42 ~54 ~15 ~42 stained_hardened_clay 9  
fill ~53 ~15 ~43 ~54 ~15 ~43 stained_hardened_clay 9  
fill ~53 ~15 ~50 ~54 ~15 ~50 stained_hardened_clay 9  
fill ~53 ~15 ~51 ~55 ~15 ~51 stained_hardened_clay 9 
setblock ~53 ~15 ~72 stained_hardened_clay 9 
setblock ~54 ~15 ~26 stained_hardened_clay 3  
fill ~54 ~15 ~27 ~56 ~15 ~27 concrete 8 
setblock ~54 ~15 ~30 concrete 8 
setblock ~54 ~15 ~31 stained_hardened_clay 3 
setblock ~54 ~15 ~47 coal_ore 0  
fill ~54 ~15 ~52 ~56 ~15 ~52 stained_hardened_clay 9  
fill ~54 ~15 ~53 ~54 ~15 ~56 stained_hardened_clay 9  
fill ~54 ~15 ~71 ~58 ~15 ~71 stained_hardened_clay 3  
fill ~54 ~15 ~72 ~56 ~15 ~72 stained_hardened_clay 3  
fill ~54 ~15 ~73 ~54 ~15 ~71 stained_hardened_clay 3  
fill ~55 ~15 ~20 ~57 ~15 ~20 stained_hardened_clay 3 
setblock ~55 ~15 ~26 concrete 8 
setblock ~55 ~15 ~28 stained_hardened_clay 3  
fill ~55 ~15 ~29 ~55 ~15 ~30 wool 8  
fill ~55 ~15 ~40 ~58 ~15 ~40 stained_hardened_clay 3  
fill ~55 ~15 ~41 ~55 ~15 ~44 stained_hardened_clay 3 
setblock ~55 ~15 ~46 coal_ore 0 
setblock ~55 ~15 ~47 stained_hardened_clay 9  
fill ~55 ~15 ~55 ~55 ~15 ~59 stained_hardened_clay 9  
fill ~56 ~15 ~28 ~57 ~15 ~28 wool 8 
setblock ~56 ~15 ~29 clay 0  
fill ~56 ~15 ~42 ~60 ~15 ~42 stained_hardened_clay 3  
fill ~56 ~15 ~43 ~57 ~15 ~43 stained_hardened_clay 3  
fill ~56 ~15 ~44 ~56 ~15 ~40 stained_hardened_clay 3  
fill ~56 ~15 ~46 ~58 ~15 ~46 stained_hardened_clay 3  
fill ~56 ~15 ~53 ~56 ~15 ~54 stained_hardened_clay 9  
fill ~56 ~15 ~60 ~56 ~15 ~64 stained_hardened_clay 9  
fill ~56 ~15 ~65 ~56 ~15 ~72 stained_hardened_clay 3  
fill ~57 ~15 ~22 ~60 ~15 ~22 stained_hardened_clay 3  
fill ~57 ~15 ~27 ~58 ~15 ~27 clay 0  
fill ~57 ~15 ~29 ~58 ~15 ~29 concrete 8  
fill ~57 ~15 ~41 ~59 ~15 ~41 stained_hardened_clay 3  
fill ~57 ~15 ~55 ~57 ~16 ~55 stained_hardened_clay 9  
fill ~57 ~15 ~56 ~57 ~15 ~57 stained_hardened_clay 9  
fill ~57 ~15 ~66 ~58 ~15 ~66 stained_hardened_clay 3  
fill ~57 ~15 ~67 ~58 ~15 ~67 stained_hardened_clay 3  
fill ~57 ~15 ~68 ~57 ~15 ~71 stained_hardened_clay 3 
setblock ~58 ~15 ~26 clay 0  
fill ~58 ~15 ~30 ~58 ~15 ~32 stained_hardened_clay 3  
fill ~58 ~15 ~38 ~59 ~15 ~38 stained_hardened_clay 3  
fill ~58 ~15 ~39 ~59 ~15 ~39 stained_hardened_clay 3  
fill ~58 ~15 ~58 ~58 ~16 ~58 stained_hardened_clay 9  
fill ~58 ~15 ~59 ~58 ~15 ~64 stained_hardened_clay 9 
setblock ~58 ~15 ~65 stained_hardened_clay 3  
fill ~58 ~15 ~69 ~58 ~16 ~69 stained_hardened_clay 3  
fill ~58 ~15 ~70 ~58 ~16 ~70 stained_hardened_clay 3  
fill ~58 ~15 ~72 ~61 ~15 ~72 stained_hardened_clay 3  
fill ~58 ~15 ~73 ~61 ~15 ~73 stained_hardened_clay 3  
fill ~58 ~15 ~74 ~62 ~15 ~74 stained_hardened_clay 3  
fill ~59 ~15 ~23 ~61 ~15 ~23 stained_hardened_clay 3  
fill ~59 ~15 ~33 ~59 ~15 ~39 stained_hardened_clay 3  
fill ~59 ~15 ~45 ~60 ~15 ~45 stained_hardened_clay 3  
fill ~59 ~15 ~75 ~66 ~15 ~75 stained_hardened_clay 3  
fill ~59 ~15 ~76 ~65 ~15 ~76 stained_hardened_clay 3  
fill ~59 ~15 ~77 ~61 ~15 ~77 stained_hardened_clay 3  
fill ~59 ~15 ~78 ~61 ~15 ~78 stained_hardened_clay 3  
fill ~59 ~15 ~79 ~61 ~15 ~79 stained_hardened_clay 9  
fill ~59 ~15 ~80 ~62 ~15 ~80 stained_hardened_clay 9  
fill ~59 ~15 ~81 ~62 ~15 ~81 stained_hardened_clay 9  
fill ~60 ~15 ~43 ~64 ~15 ~43 stained_hardened_clay 3  
fill ~60 ~15 ~71 ~61 ~15 ~71 stained_hardened_clay 3  
fill ~60 ~15 ~82 ~61 ~15 ~82 stained_hardened_clay 9  
fill ~61 ~15 ~24 ~62 ~15 ~24 concrete 8  
fill ~61 ~15 ~44 ~63 ~15 ~44 stained_hardened_clay 3  
fill ~61 ~15 ~48 ~61 ~15 ~51 stained_hardened_clay 3  
fill ~61 ~15 ~69 ~61 ~15 ~78 stained_hardened_clay 3 
setblock ~62 ~15 ~25 concrete 8  
fill ~62 ~15 ~45 ~64 ~15 ~45 stained_hardened_clay 3  
fill ~62 ~15 ~49 ~62 ~15 ~53 stained_hardened_clay 3  
fill ~62 ~15 ~62 ~65 ~15 ~62 stained_hardened_clay 3  
fill ~62 ~15 ~63 ~64 ~15 ~63 stained_hardened_clay 3  
fill ~62 ~15 ~66 ~63 ~15 ~66 stained_hardened_clay 3  
fill ~62 ~15 ~67 ~62 ~15 ~68 stained_hardened_clay 3  
fill ~62 ~15 ~82 ~66 ~15 ~82 stained_hardened_clay 3 
setblock ~63 ~15 ~26 concrete 8  
fill ~63 ~15 ~50 ~63 ~15 ~56 stained_hardened_clay 3  
fill ~63 ~15 ~59 ~64 ~15 ~59 stained_hardened_clay 3  
fill ~63 ~15 ~60 ~71 ~15 ~60 stained_hardened_clay 3  
fill ~63 ~15 ~61 ~63 ~16 ~61 stained_hardened_clay 3  
fill ~63 ~15 ~64 ~64 ~15 ~64 stained_hardened_clay 3  
fill ~63 ~15 ~65 ~63 ~15 ~59 stained_hardened_clay 3  
fill ~63 ~15 ~80 ~69 ~15 ~80 stained_hardened_clay 3  
fill ~63 ~15 ~81 ~68 ~15 ~81 stained_hardened_clay 3  
fill ~63 ~15 ~83 ~65 ~15 ~83 stained_hardened_clay 3  
fill ~64 ~15 ~27 ~64 ~15 ~28 wool 8 
setblock ~64 ~15 ~46 stained_hardened_clay 3  
fill ~64 ~15 ~52 ~64 ~15 ~60 stained_hardened_clay 3 
setblock ~64 ~15 ~77 stained_hardened_clay 3  
fill ~65 ~15 ~29 ~65 ~15 ~30 wool 8 
setblock ~65 ~15 ~31 concrete 8  
fill ~65 ~15 ~46 ~65 ~15 ~47 concrete 8  
fill ~65 ~15 ~54 ~66 ~15 ~54 stained_hardened_clay 3  
fill ~65 ~15 ~55 ~65 ~15 ~57 stained_hardened_clay 3  
fill ~65 ~15 ~61 ~66 ~15 ~61 stained_hardened_clay 3  
fill ~66 ~15 ~31 ~66 ~15 ~33 wool 8  
fill ~66 ~15 ~47 ~67 ~15 ~47 concrete 8  
fill ~66 ~15 ~48 ~67 ~15 ~48 concrete 8  
fill ~66 ~15 ~50 ~67 ~15 ~50 concrete 8  
fill ~66 ~15 ~51 ~66 ~16 ~51 concrete 8  
fill ~66 ~15 ~52 ~66 ~16 ~52 stained_hardened_clay 3  
fill ~66 ~15 ~53 ~66 ~16 ~53 stained_hardened_clay 3  
fill ~66 ~15 ~58 ~70 ~15 ~58 stained_hardened_clay 3  
fill ~66 ~15 ~59 ~70 ~15 ~59 stained_hardened_clay 3  
fill ~66 ~15 ~74 ~67 ~15 ~74 stained_hardened_clay 3  
fill ~67 ~15 ~33 ~67 ~15 ~35 wool 8 
setblock ~67 ~15 ~36 concrete 8  
fill ~67 ~15 ~42 ~67 ~15 ~46 wool 8  
fill ~67 ~15 ~49 ~67 ~16 ~49 concrete 8 
setblock ~67 ~15 ~51 stained_hardened_clay 3 
setblock ~67 ~15 ~57 stained_hardened_clay 3 
setblock ~67 ~15 ~73 stained_hardened_clay 3 
setblock ~68 ~15 ~37 concrete 8  
fill ~68 ~15 ~38 ~68 ~15 ~41 wool 8  
fill ~68 ~15 ~42 ~68 ~15 ~43 concrete 8  
fill ~68 ~15 ~52 ~68 ~15 ~53 stained_hardened_clay 3  
fill ~68 ~15 ~72 ~69 ~15 ~72 concrete 8  
fill ~68 ~15 ~73 ~68 ~15 ~72 concrete 8  
fill ~69 ~15 ~54 ~69 ~15 ~55 stained_hardened_clay 3  
fill ~69 ~15 ~69 ~70 ~15 ~69 concrete 8  
fill ~69 ~15 ~70 ~70 ~15 ~70 concrete 8  
fill ~69 ~15 ~71 ~69 ~15 ~69 concrete 8  
fill ~69 ~15 ~79 ~70 ~15 ~79 stained_hardened_clay 3  
fill ~70 ~15 ~56 ~70 ~15 ~61 stained_hardened_clay 3  
fill ~70 ~15 ~66 ~71 ~15 ~66 concrete 8  
fill ~70 ~15 ~67 ~71 ~15 ~67 concrete 8  
fill ~70 ~15 ~68 ~70 ~15 ~66 concrete 8  
fill ~70 ~15 ~77 ~71 ~15 ~77 stained_hardened_clay 3  
fill ~70 ~15 ~78 ~70 ~15 ~77 stained_hardened_clay 3  
fill ~71 ~15 ~58 ~71 ~16 ~58 concrete 8  
fill ~71 ~15 ~59 ~72 ~15 ~59 concrete 8  
fill ~71 ~15 ~61 ~73 ~15 ~61 concrete 8  
fill ~71 ~15 ~62 ~72 ~15 ~62 stained_hardened_clay 3  
fill ~71 ~15 ~63 ~71 ~15 ~64 stained_hardened_clay 3 
setblock ~71 ~15 ~65 concrete 8 
setblock ~71 ~15 ~76 stained_hardened_clay 3  
fill ~72 ~15 ~60 ~72 ~17 ~60 concrete 8  
fill ~72 ~15 ~74 ~73 ~15 ~74 concrete 8  
fill ~72 ~15 ~75 ~72 ~15 ~74 concrete 8  
fill ~73 ~15 ~62 ~73 ~15 ~69 concrete 8  
fill ~73 ~15 ~71 ~73 ~15 ~74 concrete 8  
fill ~74 ~15 ~64 ~74 ~15 ~70 concrete 8 
setblock ~82 ~15 ~53 stained_hardened_clay 0  
fill ~85 ~15 ~58 ~85 ~16 ~58 concrete 6  
fill ~86 ~15 ~57 ~86 ~17 ~57 concrete 6  
fill ~86 ~15 ~59 ~86 ~19 ~59 concrete 6  
fill ~87 ~15 ~58 ~87 ~16 ~58 concrete 6  
fill ~10 ~16 ~59 ~13 ~16 ~59 concrete 8  
fill ~10 ~16 ~60 ~11 ~16 ~60 concrete 8  
fill ~10 ~16 ~61 ~11 ~16 ~61 concrete 8  
fill ~10 ~16 ~62 ~10 ~16 ~64 concrete 8  
fill ~11 ~16 ~57 ~17 ~16 ~57 concrete 8  
fill ~11 ~16 ~58 ~13 ~16 ~58 concrete 8  
fill ~11 ~16 ~64 ~11 ~16 ~68 concrete 8  
fill ~12 ~16 ~56 ~14 ~16 ~56 concrete 8  
fill ~12 ~16 ~69 ~13 ~16 ~69 concrete 8  
fill ~12 ~16 ~70 ~12 ~18 ~70 concrete 8  
fill ~13 ~16 ~60 ~13 ~17 ~60 concrete 8  
fill ~13 ~16 ~61 ~13 ~17 ~61 concrete 8  
fill ~13 ~16 ~62 ~13 ~17 ~62 concrete 8  
fill ~13 ~16 ~63 ~13 ~17 ~63 concrete 8  
fill ~13 ~16 ~64 ~13 ~17 ~64 concrete 8  
fill ~13 ~16 ~65 ~13 ~17 ~65 concrete 8  
fill ~13 ~16 ~66 ~13 ~17 ~66 concrete 8  
fill ~13 ~16 ~67 ~13 ~16 ~71 concrete 8  
fill ~14 ~16 ~54 ~16 ~16 ~54 concrete 8  
fill ~14 ~16 ~55 ~14 ~17 ~55 concrete 8  
fill ~14 ~16 ~70 ~14 ~17 ~70 concrete 8  
fill ~14 ~16 ~71 ~14 ~17 ~71 concrete 8  
fill ~15 ~16 ~52 ~16 ~16 ~52 concrete 8  
fill ~15 ~16 ~53 ~15 ~16 ~52 concrete 8  
fill ~15 ~16 ~58 ~17 ~16 ~58 concrete 8  
fill ~15 ~16 ~72 ~15 ~17 ~72 concrete 8  
fill ~15 ~16 ~73 ~15 ~17 ~73 concrete 8  
fill ~16 ~16 ~46 ~16 ~17 ~46 concrete 8  
fill ~16 ~16 ~47 ~16 ~18 ~47 concrete 8  
fill ~16 ~16 ~48 ~16 ~17 ~48 concrete 8  
fill ~16 ~16 ~49 ~16 ~17 ~49 concrete 8  
fill ~16 ~16 ~50 ~16 ~17 ~50 concrete 8  
fill ~16 ~16 ~51 ~16 ~17 ~51 concrete 8 
setblock ~16 ~16 ~74 concrete 8  
fill ~17 ~16 ~42 ~17 ~17 ~42 stained_hardened_clay 3 
setblock ~17 ~16 ~43 concrete 8  
fill ~17 ~16 ~59 ~17 ~18 ~59 concrete 8 
setblock ~17 ~16 ~75 concrete 8 
setblock ~18 ~16 ~41 stained_hardened_clay 3  
fill ~18 ~16 ~47 ~18 ~16 ~48 concrete 8 
setblock ~18 ~16 ~58 stained_hardened_clay 3  
fill ~18 ~16 ~60 ~18 ~15 ~60 stained_hardened_clay 3  
fill ~18 ~16 ~61 ~18 ~17 ~61 stained_hardened_clay 3  
fill ~18 ~16 ~76 ~19 ~16 ~76 concrete 8  
fill ~19 ~16 ~39 ~19 ~16 ~40 stained_hardened_clay 3  
fill ~19 ~16 ~46 ~20 ~16 ~46 stained_hardened_clay 3  
fill ~19 ~16 ~47 ~19 ~16 ~46 stained_hardened_clay 3  
fill ~19 ~16 ~59 ~20 ~16 ~59 stained_hardened_clay 3  
fill ~19 ~16 ~62 ~19 ~16 ~63 stained_hardened_clay 3 
setblock ~19 ~16 ~72 stained_hardened_clay 3 
setblock ~20 ~16 ~38 stained_hardened_clay 3  
fill ~20 ~16 ~45 ~22 ~16 ~45 stained_hardened_clay 3 
setblock ~20 ~16 ~64 stained_hardened_clay 3  
fill ~20 ~16 ~73 ~20 ~16 ~74 stained_hardened_clay 3 
setblock ~20 ~16 ~75 concrete 8  
fill ~20 ~16 ~76 ~24 ~16 ~76 stained_hardened_clay 3  
fill ~20 ~16 ~77 ~20 ~16 ~78 concrete 8 
setblock ~21 ~16 ~37 stained_hardened_clay 3  
fill ~21 ~16 ~65 ~21 ~16 ~66 stained_hardened_clay 3  
fill ~21 ~16 ~74 ~22 ~16 ~74 stained_hardened_clay 3  
fill ~21 ~16 ~75 ~23 ~16 ~75 stained_hardened_clay 3  
fill ~21 ~16 ~77 ~24 ~16 ~77 stained_hardened_clay 3  
fill ~21 ~16 ~78 ~24 ~16 ~78 stained_hardened_clay 3 
setblock ~21 ~16 ~79 concrete 8 
setblock ~22 ~16 ~36 stained_hardened_clay 3  
fill ~22 ~16 ~44 ~24 ~16 ~44 stained_hardened_clay 3  
fill ~22 ~16 ~49 ~23 ~16 ~49 stained_hardened_clay 3  
fill ~22 ~16 ~50 ~22 ~16 ~49 stained_hardened_clay 3  
fill ~22 ~16 ~67 ~23 ~16 ~67 stained_hardened_clay 3  
fill ~22 ~16 ~79 ~25 ~16 ~79 stained_hardened_clay 3  
fill ~22 ~16 ~80 ~27 ~16 ~80 stained_hardened_clay 3  
fill ~23 ~16 ~35 ~24 ~16 ~35 stained_hardened_clay 3  
fill ~23 ~16 ~48 ~24 ~16 ~48 stained_hardened_clay 3  
fill ~23 ~16 ~81 ~26 ~16 ~81 stained_hardened_clay 3  
fill ~24 ~16 ~34 ~27 ~16 ~34 stained_hardened_clay 3  
fill ~24 ~16 ~43 ~30 ~16 ~43 stained_hardened_clay 3  
fill ~24 ~16 ~47 ~25 ~16 ~47 stained_hardened_clay 3  
fill ~24 ~16 ~68 ~29 ~16 ~68 stained_hardened_clay 3  
fill ~25 ~16 ~46 ~26 ~16 ~46 stained_hardened_clay 3  
fill ~25 ~16 ~82 ~29 ~16 ~82 stained_hardened_clay 3  
fill ~26 ~16 ~45 ~27 ~16 ~45 stained_hardened_clay 3 
setblock ~26 ~16 ~59 stained_hardened_clay 3  
fill ~27 ~16 ~33 ~31 ~16 ~33 stained_hardened_clay 3  
fill ~27 ~16 ~44 ~31 ~16 ~44 stained_hardened_clay 3  
fill ~27 ~16 ~61 ~27 ~16 ~62 stained_hardened_clay 9  
fill ~27 ~16 ~83 ~33 ~16 ~83 stained_hardened_clay 3 
setblock ~28 ~16 ~63 stained_hardened_clay 9  
fill ~28 ~16 ~81 ~30 ~16 ~81 stained_hardened_clay 3  
fill ~29 ~16 ~64 ~29 ~16 ~65 stained_hardened_clay 3  
fill ~30 ~16 ~42 ~32 ~16 ~42 stained_hardened_clay 3  
fill ~30 ~16 ~66 ~31 ~16 ~66 stained_hardened_clay 9  
fill ~30 ~16 ~67 ~30 ~16 ~66 stained_hardened_clay 9  
fill ~31 ~16 ~68 ~31 ~17 ~68 stained_hardened_clay 9  
fill ~31 ~16 ~82 ~39 ~16 ~82 stained_hardened_clay 3  
fill ~32 ~16 ~34 ~34 ~16 ~34 stained_hardened_clay 3 
setblock ~32 ~16 ~45 stained_hardened_clay 3 
setblock ~32 ~16 ~65 stained_hardened_clay 9 
setblock ~32 ~16 ~69 stained_hardened_clay 9  
fill ~32 ~16 ~70 ~32 ~17 ~70 stained_hardened_clay 3  
fill ~32 ~16 ~84 ~34 ~16 ~84 stained_hardened_clay 3  
fill ~33 ~16 ~41 ~34 ~16 ~41 stained_hardened_clay 3  
fill ~33 ~16 ~46 ~33 ~16 ~47 stained_hardened_clay 3 
setblock ~33 ~16 ~64 stained_hardened_clay 9  
fill ~33 ~16 ~70 ~33 ~16 ~71 stained_hardened_clay 9  
fill ~34 ~16 ~15 ~35 ~16 ~15 stained_hardened_clay 3  
fill ~34 ~16 ~16 ~35 ~16 ~16 stained_hardened_clay 3  
fill ~34 ~16 ~17 ~35 ~16 ~17 stained_hardened_clay 3  
fill ~34 ~16 ~18 ~36 ~16 ~18 stained_hardened_clay 3  
fill ~34 ~16 ~35 ~36 ~16 ~35 stained_hardened_clay 3 
setblock ~34 ~16 ~47 stained_hardened_clay 3  
fill ~34 ~16 ~48 ~35 ~16 ~48 stained_hardened_clay 9 
setblock ~34 ~16 ~71 stained_hardened_clay 9 
setblock ~34 ~16 ~72 stained_hardened_clay 3  
fill ~35 ~16 ~12 ~36 ~16 ~12 stained_hardened_clay 3  
fill ~35 ~16 ~13 ~35 ~16 ~19 stained_hardened_clay 3  
fill ~35 ~16 ~40 ~36 ~16 ~40 stained_hardened_clay 3 
setblock ~35 ~16 ~49 stained_hardened_clay 9  
fill ~35 ~16 ~60 ~36 ~16 ~60 stained_hardened_clay 9  
fill ~35 ~16 ~61 ~35 ~18 ~61 stained_hardened_clay 9  
fill ~35 ~16 ~62 ~35 ~16 ~64 stained_hardened_clay 3 
setblock ~35 ~16 ~72 stained_hardened_clay 9 
setblock ~35 ~16 ~73 stained_hardened_clay 3  
fill ~36 ~16 ~19 ~36 ~16 ~21 stained_hardened_clay 3  
fill ~36 ~16 ~36 ~37 ~16 ~36 stained_hardened_clay 3  
fill ~36 ~16 ~41 ~43 ~16 ~41 stained_hardened_clay 3  
fill ~36 ~16 ~50 ~36 ~16 ~60 stained_hardened_clay 9 
setblock ~36 ~16 ~61 stained_hardened_clay 3  
fill ~36 ~16 ~73 ~38 ~16 ~73 stained_hardened_clay 9  
fill ~36 ~16 ~74 ~41 ~16 ~74 stained_hardened_clay 9 
setblock ~37 ~16 ~11 stained_hardened_clay 3  
fill ~37 ~16 ~20 ~37 ~16 ~21 stained_hardened_clay 3  
fill ~37 ~16 ~37 ~37 ~17 ~37 stained_hardened_clay 3  
fill ~37 ~16 ~54 ~37 ~16 ~55 stained_hardened_clay 3  
fill ~37 ~16 ~56 ~37 ~17 ~56 stained_hardened_clay 9 
setblock ~37 ~16 ~66 stained_hardened_clay 9  
fill ~38 ~16 ~10 ~45 ~16 ~10 stained_hardened_clay 3  
fill ~38 ~16 ~21 ~38 ~16 ~22 stained_hardened_clay 3  
fill ~38 ~16 ~38 ~44 ~16 ~38 stained_hardened_clay 3  
fill ~38 ~16 ~39 ~44 ~16 ~39 stained_hardened_clay 3 
setblock ~38 ~16 ~52 stained_hardened_clay 9 
setblock ~38 ~16 ~53 stained_hardened_clay 3  
fill ~38 ~16 ~67 ~38 ~17 ~67 stained_hardened_clay 9  
fill ~38 ~16 ~83 ~39 ~16 ~83 stained_hardened_clay 3  
fill ~38 ~16 ~84 ~39 ~16 ~84 stained_hardened_clay 3  
fill ~38 ~16 ~85 ~39 ~16 ~85 stained_hardened_clay 3  
fill ~38 ~16 ~86 ~39 ~16 ~86 stained_hardened_clay 3  
fill ~38 ~16 ~87 ~40 ~16 ~87 stained_hardened_clay 3  
fill ~39 ~16 ~9 ~41 ~16 ~9 stained_hardened_clay 3  
fill ~39 ~16 ~22 ~42 ~16 ~22 stained_hardened_clay 3  
fill ~39 ~16 ~23 ~42 ~16 ~23 stained_hardened_clay 3  
fill ~39 ~16 ~30 ~48 ~16 ~30 stained_hardened_clay 3  
fill ~39 ~16 ~31 ~48 ~16 ~31 stained_hardened_clay 3  
fill ~39 ~16 ~32 ~49 ~16 ~32 stained_hardened_clay 3  
fill ~39 ~16 ~33 ~50 ~16 ~33 stained_hardened_clay 3  
fill ~39 ~16 ~34 ~45 ~16 ~34 stained_hardened_clay 3  
fill ~39 ~16 ~35 ~49 ~16 ~35 stained_hardened_clay 3  
fill ~39 ~16 ~36 ~46 ~16 ~36 stained_hardened_clay 3  
fill ~39 ~16 ~37 ~46 ~16 ~37 stained_hardened_clay 3  
fill ~39 ~16 ~40 ~42 ~16 ~40 stained_hardened_clay 3 
setblock ~39 ~16 ~42 stained_hardened_clay 3  
fill ~39 ~16 ~48 ~39 ~16 ~50 stained_hardened_clay 9 
setblock ~39 ~16 ~51 stained_hardened_clay 3  
fill ~39 ~16 ~68 ~39 ~17 ~68 stained_hardened_clay 9  
fill ~39 ~16 ~79 ~40 ~16 ~79 stained_hardened_clay 3  
fill ~39 ~16 ~80 ~41 ~16 ~80 stained_hardened_clay 3  
fill ~39 ~16 ~81 ~40 ~16 ~81 stained_hardened_clay 3  
fill ~39 ~16 ~88 ~40 ~16 ~88 stained_hardened_clay 3  
fill ~39 ~16 ~89 ~41 ~16 ~89 stained_hardened_clay 3  
fill ~40 ~16 ~28 ~46 ~16 ~28 stained_hardened_clay 3  
fill ~40 ~16 ~29 ~48 ~16 ~29 stained_hardened_clay 3 
setblock ~40 ~16 ~42 coal_ore 0  
fill ~40 ~16 ~43 ~46 ~16 ~43 stained_hardened_clay 9  
fill ~40 ~16 ~44 ~40 ~16 ~47 stained_hardened_clay 9  
fill ~40 ~16 ~69 ~40 ~18 ~69 stained_hardened_clay 9  
fill ~40 ~16 ~78 ~41 ~16 ~78 stained_hardened_clay 3  
fill ~40 ~16 ~90 ~41 ~16 ~90 stained_hardened_clay 3 
setblock ~41 ~16 ~42 stained_hardened_clay 3  
fill ~41 ~16 ~70 ~41 ~17 ~70 stained_hardened_clay 9  
fill ~41 ~16 ~71 ~41 ~14 ~71 stained_hardened_clay 9  
fill ~41 ~16 ~76 ~43 ~16 ~76 stained_hardened_clay 9  
fill ~41 ~16 ~77 ~41 ~15 ~77 stained_hardened_clay 9 
setblock ~41 ~16 ~91 stained_hardened_clay 3 
setblock ~42 ~16 ~42 stained_hardened_clay 9  
fill ~42 ~16 ~58 ~42 ~17 ~58 stained_hardened_clay 9  
fill ~42 ~16 ~59 ~42 ~16 ~69 stained_hardened_clay 9  
fill ~42 ~16 ~72 ~44 ~16 ~72 stained_hardened_clay 9  
fill ~42 ~16 ~73 ~50 ~16 ~73 stained_hardened_clay 9  
fill ~42 ~16 ~75 ~43 ~16 ~75 stained_hardened_clay 9  
fill ~42 ~16 ~78 ~43 ~16 ~78 stained_hardened_clay 9  
fill ~42 ~16 ~79 ~42 ~16 ~80 stained_hardened_clay 9  
fill ~42 ~16 ~90 ~42 ~16 ~91 stained_hardened_clay 9  
fill ~43 ~16 ~22 ~44 ~16 ~22 concrete 8  
fill ~43 ~16 ~23 ~43 ~17 ~23 concrete 8  
fill ~43 ~16 ~24 ~43 ~17 ~24 concrete 8 
setblock ~43 ~16 ~40 coal_ore 0 
setblock ~43 ~16 ~42 stained_hardened_clay 3  
fill ~43 ~16 ~44 ~43 ~17 ~44 stained_hardened_clay 9 
setblock ~43 ~16 ~50 stained_hardened_clay 3  
fill ~43 ~16 ~51 ~44 ~16 ~51 stained_hardened_clay 9  
fill ~43 ~16 ~52 ~43 ~17 ~52 stained_hardened_clay 9  
fill ~43 ~16 ~53 ~43 ~16 ~57 stained_hardened_clay 9  
fill ~43 ~16 ~69 ~43 ~16 ~78 stained_hardened_clay 9  
fill ~43 ~16 ~91 ~43 ~16 ~92 stained_hardened_clay 9  
fill ~44 ~16 ~21 ~44 ~17 ~21 concrete 8  
fill ~44 ~16 ~25 ~48 ~16 ~25 concrete 8  
fill ~44 ~16 ~27 ~46 ~16 ~27 stained_hardened_clay 3 
setblock ~44 ~16 ~40 stained_hardened_clay 3  
fill ~44 ~16 ~41 ~44 ~16 ~42 coal_ore 0  
fill ~44 ~16 ~44 ~45 ~16 ~44 coal_ore 0  
fill ~44 ~16 ~45 ~45 ~16 ~45 stained_hardened_clay 9  
fill ~44 ~16 ~46 ~44 ~16 ~45 stained_hardened_clay 9  
fill ~44 ~16 ~47 ~44 ~16 ~48 stained_hardened_clay 3  
fill ~44 ~16 ~49 ~45 ~16 ~49 stained_hardened_clay 9  
fill ~44 ~16 ~50 ~44 ~16 ~49 stained_hardened_clay 9  
fill ~44 ~16 ~74 ~48 ~16 ~74 stained_hardened_clay 9  
fill ~44 ~16 ~91 ~45 ~16 ~91 stained_hardened_clay 3  
fill ~44 ~16 ~92 ~48 ~16 ~92 stained_hardened_clay 3  
fill ~45 ~16 ~24 ~48 ~16 ~24 concrete 8  
fill ~45 ~16 ~26 ~45 ~17 ~26 stained_hardened_clay 3  
fill ~45 ~16 ~38 ~45 ~16 ~40 coal_ore 0 
setblock ~45 ~16 ~41 stained_hardened_clay 9  
fill ~45 ~16 ~42 ~46 ~16 ~42 coal_ore 0  
fill ~45 ~16 ~46 ~45 ~16 ~48 coal_ore 0  
fill ~45 ~16 ~70 ~45 ~17 ~70 stained_hardened_clay 9  
fill ~45 ~16 ~71 ~45 ~17 ~71 stained_hardened_clay 9 
setblock ~45 ~16 ~72 coal_ore 0  
fill ~46 ~16 ~11 ~47 ~16 ~11 stained_hardened_clay 3  
fill ~46 ~16 ~23 ~49 ~16 ~23 concrete 8  
fill ~46 ~16 ~26 ~47 ~16 ~26 concrete 8 
setblock ~46 ~16 ~34 coal_ore 0  
fill ~46 ~16 ~38 ~46 ~16 ~39 stained_hardened_clay 3  
fill ~46 ~16 ~40 ~47 ~16 ~40 coal_ore 0  
fill ~46 ~16 ~44 ~48 ~16 ~44 stained_hardened_clay 9  
fill ~46 ~16 ~47 ~46 ~15 ~47 coal_ore 0  
fill ~46 ~16 ~48 ~50 ~16 ~48 stained_hardened_clay 9  
fill ~46 ~16 ~67 ~46 ~16 ~69 stained_hardened_clay 9  
fill ~46 ~16 ~72 ~49 ~16 ~72 stained_hardened_clay 9  
fill ~46 ~16 ~91 ~49 ~16 ~91 stained_hardened_clay 9  
fill ~47 ~16 ~27 ~47 ~16 ~28 concrete 8 
setblock ~47 ~16 ~34 stained_hardened_clay 3  
fill ~47 ~16 ~36 ~47 ~16 ~41 coal_ore 0  
fill ~47 ~16 ~42 ~48 ~16 ~42 stained_hardened_clay 9  
fill ~47 ~16 ~45 ~49 ~16 ~45 stained_hardened_clay 9  
fill ~47 ~16 ~46 ~47 ~16 ~49 stained_hardened_clay 9  
fill ~47 ~16 ~64 ~47 ~16 ~66 stained_hardened_clay 9  
fill ~47 ~16 ~71 ~48 ~16 ~71 stained_hardened_clay 9  
fill ~47 ~16 ~75 ~52 ~16 ~75 stained_hardened_clay 9  
fill ~48 ~16 ~12 ~49 ~16 ~12 stained_hardened_clay 3  
fill ~48 ~16 ~22 ~49 ~16 ~22 concrete 8 
setblock ~48 ~16 ~28 concrete 8 
setblock ~48 ~16 ~34 coal_ore 0  
fill ~48 ~16 ~36 ~49 ~16 ~36 stained_hardened_clay 3  
fill ~48 ~16 ~37 ~49 ~16 ~37 stained_hardened_clay 3  
fill ~48 ~16 ~38 ~48 ~16 ~45 stained_hardened_clay 9 
setblock ~48 ~16 ~46 coal_ore 0  
fill ~48 ~16 ~47 ~48 ~15 ~47 stained_hardened_clay 9  
fill ~48 ~16 ~49 ~52 ~16 ~49 stained_hardened_clay 9  
fill ~48 ~16 ~56 ~48 ~17 ~56 stained_hardened_clay 9  
fill ~48 ~16 ~57 ~48 ~19 ~57 stained_hardened_clay 9  
fill ~48 ~16 ~62 ~48 ~19 ~62 stained_hardened_clay 9  
fill ~48 ~16 ~63 ~48 ~18 ~63 stained_hardened_clay 9  
fill ~49 ~16 ~13 ~50 ~16 ~13 stained_hardened_clay 3  
fill ~49 ~16 ~14 ~50 ~16 ~14 stained_hardened_clay 3  
fill ~49 ~16 ~15 ~50 ~16 ~15 stained_hardened_clay 3  
fill ~49 ~16 ~21 ~52 ~16 ~21 stained_hardened_clay 3  
fill ~49 ~16 ~24 ~49 ~16 ~27 stained_hardened_clay 3  
fill ~49 ~16 ~34 ~50 ~16 ~34 stained_hardened_clay 3  
fill ~49 ~16 ~46 ~53 ~16 ~46 stained_hardened_clay 9  
fill ~49 ~16 ~50 ~49 ~17 ~50 stained_hardened_clay 9  
fill ~49 ~16 ~51 ~49 ~16 ~48 stained_hardened_clay 9  
fill ~49 ~16 ~55 ~49 ~19 ~55 stained_hardened_clay 9  
fill ~49 ~16 ~90 ~51 ~16 ~90 stained_hardened_clay 9  
fill ~50 ~16 ~16 ~50 ~16 ~23 stained_hardened_clay 3  
fill ~50 ~16 ~24 ~50 ~17 ~24 concrete 8  
fill ~50 ~16 ~44 ~50 ~17 ~44 stained_hardened_clay 9 
setblock ~50 ~16 ~45 coal_ore 0  
fill ~50 ~16 ~74 ~51 ~16 ~74 stained_hardened_clay 9  
fill ~50 ~16 ~91 ~50 ~17 ~91 stained_hardened_clay 3  
fill ~51 ~16 ~17 ~51 ~16 ~24 stained_hardened_clay 3  
fill ~51 ~16 ~31 ~52 ~16 ~31 concrete 8  
fill ~51 ~16 ~32 ~51 ~16 ~31 concrete 8
fill ~51 ~16 ~41 ~52 ~16 ~41 stained_hardened_clay 9  
fill ~51 ~16 ~42 ~52 ~16 ~42 stained_hardened_clay 9  
fill ~51 ~16 ~43 ~52 ~16 ~43 stained_hardened_clay 9 
setblock ~51 ~16 ~44 coal_ore 0  
fill ~51 ~16 ~45 ~52 ~16 ~45 stained_hardened_clay 9  
fill ~51 ~16 ~47 ~54 ~16 ~47 stained_hardened_clay 9 
setblock ~51 ~16 ~48 coal_ore 0  
fill ~51 ~16 ~76 ~53 ~16 ~76 stained_hardened_clay 9  
fill ~51 ~16 ~88 ~52 ~16 ~88 stained_hardened_clay 9  
fill ~51 ~16 ~89 ~51 ~16 ~88 stained_hardened_clay 9  
fill ~52 ~16 ~19 ~58 ~16 ~19 stained_hardened_clay 3  
fill ~52 ~16 ~20 ~54 ~16 ~20 stained_hardened_clay 3  
fill ~52 ~16 ~23 ~54 ~16 ~23 stained_hardened_clay 3  
fill ~52 ~16 ~24 ~55 ~16 ~24 stained_hardened_clay 3  
fill ~52 ~16 ~30 ~53 ~16 ~30 wool 8  
fill ~52 ~16 ~40 ~54 ~16 ~40 stained_hardened_clay 3  
fill ~52 ~16 ~44 ~52 ~17 ~44 stained_hardened_clay 9  
fill ~52 ~16 ~48 ~56 ~16 ~48 stained_hardened_clay 9  
fill ~52 ~16 ~50 ~52 ~17 ~50 stained_hardened_clay 9  
fill ~52 ~16 ~51 ~52 ~16 ~52 stained_hardened_clay 9  
fill ~52 ~16 ~77 ~53 ~16 ~77 stained_hardened_clay 9  
fill ~52 ~16 ~78 ~53 ~16 ~78 stained_hardened_clay 9  
fill ~52 ~16 ~86 ~53 ~16 ~86 stained_hardened_clay 9  
fill ~52 ~16 ~87 ~53 ~16 ~87 stained_hardened_clay 9  
fill ~53 ~16 ~29 ~54 ~16 ~29 wool 8  
fill ~53 ~16 ~52 ~53 ~16 ~55 stained_hardened_clay 9  
fill ~53 ~16 ~74 ~54 ~16 ~74 stained_hardened_clay 9 
setblock ~53 ~16 ~79 stained_hardened_clay 3  
fill ~53 ~16 ~80 ~53 ~16 ~87 stained_hardened_clay 9  
fill ~54 ~16 ~28 ~55 ~16 ~28 clay 0  
fill ~54 ~16 ~49 ~55 ~16 ~49 stained_hardened_clay 9  
fill ~54 ~16 ~56 ~54 ~16 ~59 stained_hardened_clay 9  
fill ~54 ~16 ~80 ~54 ~19 ~80 stained_hardened_clay 3  
fill ~54 ~16 ~81 ~54 ~16 ~80 stained_hardened_clay 3  
fill ~54 ~16 ~82 ~54 ~16 ~85 stained_hardened_clay 9  
fill ~55 ~16 ~18 ~56 ~16 ~18 stained_hardened_clay 3 
setblock ~55 ~16 ~25 stained_hardened_clay 3  
fill ~55 ~16 ~27 ~56 ~16 ~27 clay 0  
fill ~55 ~16 ~46 ~56 ~16 ~46 stained_hardened_clay 9 
setblock ~55 ~16 ~47 coal_ore 0 
setblock ~55 ~16 ~50 stained_hardened_clay 9  
fill ~55 ~16 ~60 ~55 ~16 ~63 stained_hardened_clay 9  
fill ~55 ~16 ~64 ~55 ~17 ~64 stained_hardened_clay 3  
fill ~55 ~16 ~65 ~55 ~17 ~65 stained_hardened_clay 3  
fill ~55 ~16 ~66 ~55 ~17 ~66 stained_hardened_clay 3  
fill ~55 ~16 ~67 ~55 ~17 ~67 stained_hardened_clay 3  
fill ~55 ~16 ~68 ~55 ~17 ~68 stained_hardened_clay 3  
fill ~55 ~16 ~69 ~56 ~16 ~69 stained_hardened_clay 3  
fill ~55 ~16 ~73 ~57 ~16 ~73 stained_hardened_clay 3 
setblock ~56 ~16 ~25 concrete 8 
setblock ~56 ~16 ~26 wool 8  
fill ~56 ~16 ~45 ~57 ~16 ~45 stained_hardened_clay 3  
fill ~56 ~16 ~47 ~56 ~17 ~47 stained_hardened_clay 9  
fill ~56 ~16 ~51 ~56 ~16 ~52 stained_hardened_clay 9  
fill ~56 ~16 ~70 ~58 ~16 ~70 stained_hardened_clay 3  
fill ~56 ~16 ~71 ~57 ~16 ~71 stained_hardened_clay 3  
fill ~56 ~16 ~72 ~57 ~16 ~72 stained_hardened_clay 3 
setblock ~57 ~16 ~25 wool 8 
setblock ~57 ~16 ~26 clay 0 
setblock ~57 ~16 ~27 concrete 8  
fill ~57 ~16 ~44 ~58 ~16 ~44 stained_hardened_clay 3  
fill ~57 ~16 ~47 ~59 ~16 ~47 stained_hardened_clay 3  
fill ~57 ~16 ~53 ~57 ~16 ~55 stained_hardened_clay 9  
fill ~57 ~16 ~74 ~58 ~16 ~74 stained_hardened_clay 3  
fill ~57 ~16 ~75 ~58 ~16 ~75 stained_hardened_clay 3  
fill ~57 ~16 ~76 ~59 ~16 ~76 stained_hardened_clay 3  
fill ~57 ~16 ~77 ~57 ~16 ~80 stained_hardened_clay 9  
fill ~58 ~16 ~20 ~59 ~16 ~20 stained_hardened_clay 3 
setblock ~58 ~16 ~28 concrete 8  
fill ~58 ~16 ~42 ~59 ~16 ~42 stained_hardened_clay 3  
fill ~58 ~16 ~43 ~59 ~16 ~43 stained_hardened_clay 3  
fill ~58 ~16 ~56 ~58 ~16 ~58 stained_hardened_clay 9  
fill ~58 ~16 ~68 ~61 ~16 ~68 stained_hardened_clay 3  
fill ~58 ~16 ~77 ~63 ~16 ~77 stained_hardened_clay 3  
fill ~58 ~16 ~78 ~58 ~16 ~84 stained_hardened_clay 9  
fill ~59 ~16 ~21 ~61 ~16 ~21 stained_hardened_clay 3  
fill ~59 ~16 ~29 ~59 ~16 ~31 concrete 8 
setblock ~59 ~16 ~32 stained_hardened_clay 3  
fill ~59 ~16 ~39 ~60 ~16 ~39 stained_hardened_clay 3  
fill ~59 ~16 ~40 ~60 ~16 ~40 stained_hardened_clay 3  
fill ~59 ~16 ~41 ~62 ~16 ~41 stained_hardened_clay 3  
fill ~59 ~16 ~46 ~61 ~16 ~46 stained_hardened_clay 3  
fill ~59 ~16 ~59 ~59 ~17 ~59 stained_hardened_clay 9  
fill ~59 ~16 ~60 ~59 ~16 ~63 stained_hardened_clay 9  
fill ~59 ~16 ~64 ~59 ~16 ~68 stained_hardened_clay 3  
fill ~59 ~16 ~71 ~59 ~16 ~73 stained_hardened_clay 3  
fill ~59 ~16 ~78 ~65 ~16 ~78 stained_hardened_clay 3  
fill ~59 ~16 ~82 ~59 ~16 ~84 stained_hardened_clay 9  
fill ~60 ~16 ~32 ~60 ~16 ~33 concrete 8  
fill ~60 ~16 ~34 ~60 ~16 ~41 stained_hardened_clay 3  
fill ~60 ~16 ~69 ~60 ~16 ~70 stained_hardened_clay 3  
fill ~60 ~16 ~83 ~60 ~16 ~84 stained_hardened_clay 9  
