setblock ~49 ~60 ~27 sponge 0 
setblock ~52 ~78 ~61 stained_hardened_clay 9 
setblock ~53 ~78 ~61 wool 7 
setblock ~50 ~79 ~60 wool 7 
setblock ~50 ~79 ~61 coal_ore 0 
setblock ~51 ~79 ~60 coal_ore 0 
setblock ~51 ~79 ~61 wool 7  
fill ~51 ~79 ~62 ~52 ~79 ~62 stained_hardened_clay 9 
setblock ~52 ~79 ~60 wool 7  
fill ~52 ~79 ~63 ~52 ~80 ~63 stained_hardened_clay 9 
setblock ~53 ~79 ~60 stained_hardened_clay 9 
setblock ~53 ~79 ~62 wool 7  
fill ~54 ~79 ~60 ~54 ~79 ~61 wool 7 
setblock ~47 ~80 ~83 stonebrick 2  
fill ~48 ~80 ~83 ~49 ~80 ~83 stained_hardened_clay 9 
setblock ~49 ~80 ~60 stained_hardened_clay 9 
setblock ~49 ~80 ~61 stonebrick 2 
setblock ~49 ~80 ~82 wool 7 
setblock ~50 ~80 ~59 concrete 7  
fill ~50 ~80 ~62 ~50 ~80 ~63 stained_hardened_clay 9 
setblock ~50 ~80 ~82 concrete 7 
setblock ~50 ~80 ~83 wool 7  
fill ~51 ~80 ~58 ~52 ~80 ~58 stained_hardened_clay 9 
setblock ~51 ~80 ~59 wool 7 
setblock ~51 ~80 ~63 stained_hardened_clay 9 
setblock ~51 ~80 ~82 stained_hardened_clay 9 
setblock ~51 ~80 ~83 concrete 7  
fill ~52 ~80 ~59 ~53 ~80 ~59 stained_hardened_clay 9 
setblock ~52 ~80 ~71 concrete 7 
setblock ~52 ~80 ~72 stained_hardened_clay 7 
setblock ~52 ~80 ~81 soul_sand 0 
setblock ~52 ~80 ~82 wool 7 
setblock ~52 ~80 ~83 soul_sand 0  
fill ~53 ~80 ~58 ~54 ~80 ~58 wool 7 
setblock ~53 ~80 ~63 soul_sand 0  
fill ~53 ~80 ~82 ~55 ~80 ~82 concrete 7  
fill ~53 ~80 ~83 ~56 ~80 ~83 concrete 7 
setblock ~54 ~80 ~59 wool 7  
fill ~54 ~80 ~62 ~55 ~80 ~62 concrete 7 
setblock ~54 ~80 ~63 wool 7 
setblock ~54 ~80 ~71 stained_hardened_clay 9 
setblock ~55 ~80 ~60 soul_sand 0 
setblock ~55 ~80 ~61 wool 7 
setblock ~57 ~80 ~83 stained_hardened_clay 9  
fill ~46 ~81 ~68 ~47 ~81 ~68 stained_hardened_clay 9 
setblock ~46 ~81 ~71 stained_hardened_clay 9  
fill ~46 ~81 ~83 ~46 ~81 ~84 coal_ore 0 
setblock ~47 ~81 ~69 coal_ore 0  
fill ~47 ~81 ~70 ~48 ~81 ~70 stained_hardened_clay 9  
fill ~47 ~81 ~71 ~48 ~81 ~71 concrete 8 
setblock ~47 ~81 ~72 coal_ore 0 
setblock ~47 ~81 ~82 coal_ore 0 
setblock ~47 ~81 ~84 stained_hardened_clay 9  
fill ~48 ~81 ~60 ~48 ~81 ~61 stained_hardened_clay 9 
setblock ~48 ~81 ~67 stained_hardened_clay 9  
fill ~48 ~81 ~68 ~49 ~81 ~68 coal_ore 0  
fill ~48 ~81 ~69 ~49 ~81 ~69 stained_hardened_clay 9 
setblock ~48 ~81 ~72 stonebrick 2 
setblock ~48 ~81 ~73 coal_ore 0  
fill ~48 ~81 ~81 ~50 ~81 ~81 stained_hardened_clay 9  
fill ~48 ~81 ~82 ~48 ~81 ~81 stained_hardened_clay 9 
setblock ~48 ~81 ~84 stonebrick 2  
fill ~49 ~81 ~58 ~49 ~82 ~58 soul_sand 0 
setblock ~49 ~81 ~59 wool 7 
setblock ~49 ~81 ~62 stained_hardened_clay 9 
setblock ~49 ~81 ~63 wool 7 
setblock ~49 ~81 ~67 wool 7  
fill ~49 ~81 ~70 ~49 ~81 ~71 coal_ore 0  
fill ~49 ~81 ~72 ~49 ~81 ~73 stained_hardened_clay 9 
setblock ~49 ~81 ~74 wool 7 
setblock ~49 ~81 ~84 concrete 7 
setblock ~50 ~81 ~57 wool 7 
setblock ~50 ~81 ~58 stained_hardened_clay 9 
setblock ~50 ~81 ~63 soul_sand 0 
setblock ~50 ~81 ~68 stained_hardened_clay 9  
fill ~50 ~81 ~69 ~51 ~81 ~69 wool 7  
fill ~50 ~81 ~70 ~51 ~81 ~70 stained_hardened_clay 9  
fill ~50 ~81 ~71 ~50 ~81 ~70 stained_hardened_clay 9 
setblock ~50 ~81 ~72 wool 7  
fill ~50 ~81 ~73 ~50 ~81 ~74 stained_hardened_clay 9  
fill ~50 ~81 ~80 ~51 ~81 ~80 wool 7  
fill ~50 ~81 ~84 ~50 ~81 ~85 wool 7  
fill ~51 ~81 ~57 ~54 ~81 ~57 concrete 7  
fill ~51 ~81 ~64 ~52 ~81 ~64 wool 7 
setblock ~51 ~81 ~68 concrete 7 
setblock ~51 ~81 ~71 wool 7  
fill ~51 ~81 ~72 ~51 ~81 ~73 concrete 7 
setblock ~51 ~81 ~81 wool 7  
fill ~51 ~81 ~84 ~52 ~81 ~84 concrete 7 
setblock ~51 ~81 ~85 wool 7 
setblock ~52 ~81 ~56 soul_sand 0 
setblock ~52 ~81 ~70 soul_sand 0  
fill ~52 ~81 ~73 ~54 ~81 ~73 concrete 7 
setblock ~52 ~81 ~80 concrete 7 
setblock ~53 ~81 ~56 concrete 7 
setblock ~53 ~81 ~64 stained_hardened_clay 9 
setblock ~53 ~81 ~68 concrete 7 
setblock ~53 ~81 ~69 soul_sand 0 
setblock ~53 ~81 ~70 stained_hardened_clay 9 
setblock ~53 ~81 ~71 wool 7  
fill ~53 ~81 ~72 ~54 ~81 ~72 concrete 7  
fill ~53 ~81 ~80 ~53 ~81 ~81 soul_sand 0  
fill ~53 ~81 ~84 ~54 ~81 ~84 soul_sand 0 
setblock ~53 ~81 ~85 concrete 7 
setblock ~54 ~81 ~63 soul_sand 0 
setblock ~54 ~81 ~67 wool 7  
fill ~54 ~81 ~68 ~55 ~81 ~68 stained_hardened_clay 9  
fill ~54 ~81 ~69 ~55 ~81 ~69 wool 7  
fill ~54 ~81 ~70 ~54 ~81 ~69 wool 7 
setblock ~54 ~81 ~74 concrete 7 
setblock ~54 ~81 ~80 wool 7 
setblock ~54 ~81 ~81 soul_sand 0 
setblock ~54 ~81 ~85 wool 7  
fill ~55 ~81 ~58 ~55 ~81 ~59 wool 7 
setblock ~55 ~81 ~63 stained_hardened_clay 7  
fill ~55 ~81 ~67 ~57 ~81 ~67 stained_hardened_clay 9  
fill ~55 ~81 ~70 ~56 ~81 ~70 stained_hardened_clay 9  
fill ~55 ~81 ~71 ~58 ~81 ~71 stained_hardened_clay 9  
fill ~55 ~81 ~72 ~55 ~81 ~73 stained_hardened_clay 9 
setblock ~55 ~81 ~74 wool 7  
fill ~55 ~81 ~80 ~55 ~81 ~81 concrete 7  
fill ~55 ~81 ~84 ~56 ~81 ~84 concrete 7 
setblock ~56 ~81 ~60 stained_hardened_clay 7  
fill ~56 ~81 ~61 ~56 ~82 ~61 concrete 7  
fill ~56 ~81 ~62 ~56 ~82 ~62 concrete 7  
fill ~56 ~81 ~68 ~57 ~81 ~68 coal_ore 0  
fill ~56 ~81 ~69 ~57 ~81 ~69 stained_hardened_clay 9 
setblock ~56 ~81 ~72 wool 7 
setblock ~56 ~81 ~73 stonebrick 2 
setblock ~56 ~81 ~74 stained_hardened_clay 9 
setblock ~56 ~81 ~81 concrete 7 
setblock ~56 ~81 ~82 stained_hardened_clay 7 
setblock ~57 ~81 ~70 coal_ore 0  
fill ~57 ~81 ~72 ~57 ~81 ~73 stained_hardened_clay 9 
setblock ~57 ~81 ~82 wool 7 
setblock ~57 ~81 ~84 wool 7 
setblock ~58 ~81 ~68 stained_hardened_clay 9 
setblock ~58 ~81 ~70 stained_hardened_clay 9 
setblock ~58 ~81 ~72 coal_ore 0  
fill ~58 ~81 ~83 ~58 ~81 ~84 stained_hardened_clay 9 
setblock ~38 ~82 ~53 stained_hardened_clay 9 
setblock ~39 ~82 ~52 wool 7 
setblock ~39 ~82 ~53 concrete 7  
fill ~40 ~82 ~51 ~40 ~82 ~52 concrete 7  
fill ~42 ~82 ~61 ~43 ~82 ~61 stained_hardened_clay 9  
fill ~42 ~82 ~62 ~43 ~82 ~62 stained_hardened_clay 9  
fill ~42 ~82 ~63 ~42 ~82 ~61 stained_hardened_clay 9 
setblock ~42 ~82 ~64 coal_ore 0 
setblock ~43 ~82 ~63 soul_sand 0 
setblock ~43 ~82 ~67 stained_hardened_clay 9 
setblock ~43 ~82 ~68 stonebrick 2  
fill ~43 ~82 ~69 ~46 ~82 ~69 coal_ore 0 
setblock ~43 ~82 ~70 stained_hardened_clay 9  
fill ~43 ~82 ~71 ~45 ~82 ~71 coal_ore 0  
fill ~43 ~82 ~72 ~44 ~82 ~72 concrete 7  
fill ~44 ~82 ~67 ~45 ~82 ~67 coal_ore 0  
fill ~44 ~82 ~68 ~44 ~82 ~67 coal_ore 0  
fill ~44 ~82 ~70 ~45 ~82 ~70 coal_ore 0 
setblock ~44 ~82 ~73 stained_hardened_clay 9 
setblock ~44 ~82 ~85 coal_ore 0 
setblock ~45 ~82 ~66 stained_hardened_clay 9 
setblock ~45 ~82 ~68 stained_hardened_clay 9  
fill ~45 ~82 ~72 ~45 ~82 ~75 wool 7 
setblock ~45 ~82 ~83 coal_ore 0  
fill ~45 ~82 ~84 ~45 ~82 ~85 stained_hardened_clay 9  
fill ~46 ~82 ~67 ~47 ~82 ~67 stained_hardened_clay 9 
setblock ~46 ~82 ~70 stained_hardened_clay 9  
fill ~46 ~82 ~72 ~46 ~82 ~73 stained_hardened_clay 9  
fill ~46 ~82 ~74 ~47 ~82 ~74 concrete 7  
fill ~46 ~82 ~75 ~46 ~82 ~76 concrete 7 
setblock ~46 ~82 ~82 stained_hardened_clay 9  
fill ~46 ~82 ~85 ~46 ~82 ~86 stained_hardened_clay 9 
setblock ~47 ~82 ~66 stained_hardened_clay 9 
setblock ~47 ~82 ~73 stained_hardened_clay 9  
fill ~47 ~82 ~75 ~47 ~82 ~76 wool 7 
setblock ~47 ~82 ~80 coal_ore 0 
setblock ~47 ~82 ~81 stained_hardened_clay 9  
fill ~47 ~82 ~85 ~47 ~82 ~86 stonebrick 2 
setblock ~47 ~82 ~87 coal_ore 0 
setblock ~48 ~82 ~59 wool 7 
setblock ~48 ~82 ~60 soul_sand 0 
setblock ~48 ~82 ~61 wool 7 
setblock ~48 ~82 ~62 soul_sand 0  
fill ~48 ~82 ~63 ~48 ~83 ~63 wool 7  
fill ~48 ~82 ~66 ~49 ~82 ~66 soul_sand 0 
setblock ~48 ~82 ~74 stained_hardened_clay 9  
fill ~48 ~82 ~75 ~51 ~82 ~75 concrete 7  
fill ~48 ~82 ~76 ~48 ~82 ~77 concrete 7  
fill ~48 ~82 ~78 ~48 ~82 ~79 wool 7  
fill ~48 ~82 ~80 ~49 ~82 ~80 stained_hardened_clay 9 
setblock ~48 ~82 ~85 coal_ore 0 
setblock ~48 ~82 ~86 concrete 8  
fill ~48 ~82 ~87 ~49 ~82 ~87 stained_hardened_clay 9 
setblock ~48 ~82 ~88 coal_ore 0 
setblock ~49 ~82 ~57 concrete 7 
setblock ~49 ~82 ~64 stained_hardened_clay 12  
fill ~49 ~82 ~76 ~51 ~82 ~76 stained_hardened_clay 9 
setblock ~49 ~82 ~77 wool 7 
setblock ~49 ~82 ~78 concrete 7 
setblock ~49 ~82 ~79 stained_hardened_clay 9 
setblock ~49 ~82 ~85 stained_hardened_clay 9 
setblock ~49 ~82 ~86 stonebrick 2 
setblock ~49 ~82 ~88 wool 7  
fill ~50 ~82 ~56 ~51 ~82 ~56 concrete 7 
setblock ~50 ~82 ~64 concrete 7  
fill ~50 ~82 ~65 ~51 ~82 ~65 soul_sand 0 
setblock ~50 ~82 ~66 wool 7  
fill ~50 ~82 ~67 ~51 ~82 ~67 concrete 7 
setblock ~50 ~82 ~77 concrete 7 
setblock ~50 ~82 ~78 stained_hardened_clay 7  
fill ~50 ~82 ~79 ~51 ~82 ~79 concrete 7  
fill ~50 ~82 ~86 ~51 ~82 ~86 concrete 7 
setblock ~50 ~82 ~87 wool 7  
fill ~50 ~82 ~88 ~51 ~82 ~88 coal_ore 0  
fill ~51 ~82 ~64 ~51 ~81 ~64 wool 7 
setblock ~51 ~82 ~66 soul_sand 0 
setblock ~51 ~82 ~74 wool 7  
fill ~51 ~82 ~77 ~52 ~82 ~77 wool 7  
fill ~51 ~82 ~78 ~51 ~82 ~77 wool 7 
setblock ~51 ~82 ~87 concrete 7 
setblock ~52 ~82 ~56 wool 7  
fill ~52 ~82 ~65 ~53 ~82 ~65 stained_hardened_clay 9  
fill ~52 ~82 ~66 ~53 ~82 ~66 stained_hardened_clay 9  
fill ~52 ~82 ~67 ~53 ~82 ~67 wool 7  
fill ~52 ~82 ~68 ~52 ~82 ~67 wool 7 
setblock ~52 ~82 ~69 concrete 7 
setblock ~52 ~82 ~74 concrete 7 
setblock ~52 ~82 ~78 concrete 7  
fill ~52 ~82 ~79 ~54 ~82 ~79 wool 7 
setblock ~52 ~82 ~85 concrete 7  
fill ~52 ~82 ~86 ~52 ~82 ~88 stained_hardened_clay 9 
setblock ~53 ~82 ~56 soul_sand 0 
setblock ~53 ~82 ~64 wool 7 
setblock ~53 ~82 ~74 wool 7  
fill ~53 ~82 ~75 ~54 ~82 ~75 concrete 7  
fill ~53 ~82 ~76 ~53 ~82 ~75 concrete 7 
setblock ~53 ~82 ~77 soul_sand 0 
setblock ~53 ~82 ~78 wool 7 
setblock ~53 ~82 ~86 concrete 7  
fill ~53 ~82 ~87 ~54 ~82 ~87 wool 7  
fill ~53 ~82 ~88 ~55 ~82 ~88 stained_hardened_clay 9 
setblock ~54 ~82 ~56 stained_hardened_clay 9 
setblock ~54 ~82 ~64 soul_sand 0 
setblock ~54 ~82 ~66 wool 7  
fill ~54 ~82 ~76 ~57 ~82 ~76 stained_hardened_clay 9  
fill ~54 ~82 ~77 ~55 ~82 ~77 stained_hardened_clay 9 
setblock ~54 ~82 ~78 concrete 7 
setblock ~54 ~82 ~86 wool 7 
setblock ~55 ~82 ~56 soul_sand 0 
setblock ~55 ~82 ~57 wool 7 
setblock ~55 ~82 ~58 soul_sand 0 
setblock ~55 ~82 ~64 concrete 7 
setblock ~55 ~82 ~66 concrete 7  
fill ~55 ~82 ~75 ~56 ~82 ~75 wool 7 
setblock ~55 ~82 ~78 stained_hardened_clay 9  
fill ~55 ~82 ~79 ~56 ~82 ~79 concrete 7 
setblock ~55 ~82 ~85 wool 7  
fill ~55 ~82 ~86 ~56 ~82 ~86 concrete 7  
fill ~55 ~82 ~87 ~55 ~82 ~86 concrete 7  
fill ~56 ~82 ~59 ~56 ~82 ~63 concrete 7 
setblock ~56 ~82 ~66 wool 7  
fill ~56 ~82 ~77 ~57 ~82 ~77 wool 7 
setblock ~56 ~82 ~78 concrete 7 
setblock ~56 ~82 ~80 wool 7  
fill ~56 ~82 ~85 ~58 ~82 ~85 stained_hardened_clay 9 
setblock ~56 ~82 ~87 wool 7 
setblock ~56 ~82 ~88 concrete 7 
setblock ~57 ~82 ~66 stained_hardened_clay 9 
setblock ~57 ~82 ~74 stained_hardened_clay 9  
fill ~57 ~82 ~75 ~58 ~82 ~75 concrete 7 
setblock ~57 ~82 ~80 concrete 7 
setblock ~57 ~82 ~81 wool 7 
setblock ~57 ~82 ~86 wool 7 
setblock ~57 ~82 ~87 stained_hardened_clay 7  
fill ~58 ~82 ~66 ~59 ~82 ~66 wool 7  
fill ~58 ~82 ~67 ~58 ~82 ~66 wool 7  
fill ~58 ~82 ~69 ~59 ~82 ~69 stained_hardened_clay 9 
setblock ~58 ~82 ~73 stonebrick 2 
setblock ~58 ~82 ~74 concrete 7 
setblock ~58 ~82 ~76 wool 7 
setblock ~58 ~82 ~82 stained_hardened_clay 9  
fill ~58 ~82 ~86 ~59 ~82 ~86 concrete 7  
fill ~59 ~82 ~67 ~61 ~82 ~67 stained_hardened_clay 9 
setblock ~59 ~82 ~68 coal_ore 0 
setblock ~59 ~82 ~70 stained_hardened_clay 9  
fill ~59 ~82 ~71 ~59 ~82 ~73 coal_ore 0  
fill ~59 ~82 ~74 ~60 ~82 ~74 stained_hardened_clay 9  
fill ~59 ~82 ~75 ~59 ~82 ~74 stained_hardened_clay 9  
fill ~59 ~82 ~83 ~59 ~82 ~84 stained_hardened_clay 9 
setblock ~59 ~82 ~85 soul_sand 0  
fill ~60 ~82 ~68 ~61 ~82 ~68 wool 7 
setblock ~60 ~82 ~69 concrete 8 
setblock ~60 ~82 ~70 coal_ore 0 
setblock ~60 ~82 ~71 stonebrick 2  
fill ~60 ~82 ~72 ~60 ~82 ~73 coal_ore 0 
setblock ~60 ~82 ~85 stained_hardened_clay 9 
setblock ~61 ~82 ~62 stained_hardened_clay 9 
setblock ~61 ~82 ~63 concrete 7 
setblock ~61 ~82 ~69 coal_ore 0 
setblock ~61 ~82 ~70 stonebrick 2  
fill ~61 ~82 ~71 ~61 ~82 ~72 concrete 8 
setblock ~62 ~82 ~61 stained_hardened_clay 9 
setblock ~62 ~82 ~62 coal_ore 0 
setblock ~62 ~82 ~63 stained_hardened_clay 9 
setblock ~62 ~82 ~64 stonebrick 2 
setblock ~63 ~82 ~62 stonebrick 2 
setblock ~63 ~82 ~63 coal_ore 0 
setblock ~65 ~82 ~52 stonebrick 2 
setblock ~65 ~82 ~53 stained_hardened_clay 9 
setblock ~66 ~82 ~53 coal_ore 0 
setblock ~37 ~83 ~53 coal_ore 0  
fill ~37 ~83 ~54 ~37 ~83 ~55 stained_hardened_clay 9 
setblock ~38 ~83 ~52 concrete 7  
fill ~38 ~83 ~54 ~39 ~83 ~54 wool 7  
fill ~38 ~83 ~55 ~40 ~83 ~55 wool 7 
setblock ~39 ~83 ~50 concrete 7 
setblock ~39 ~83 ~51 wool 7 
setblock ~40 ~83 ~48 coal_ore 0  
fill ~40 ~83 ~49 ~41 ~83 ~49 stained_hardened_clay 9 
setblock ~40 ~83 ~50 wool 7  
fill ~40 ~83 ~53 ~41 ~83 ~53 concrete 7  
fill ~40 ~83 ~54 ~41 ~83 ~54 concrete 7  
fill ~40 ~83 ~60 ~41 ~83 ~60 concrete 7 
setblock ~40 ~83 ~61 stained_hardened_clay 9 
setblock ~40 ~83 ~62 concrete 7  
fill ~40 ~83 ~63 ~41 ~83 ~63 stained_hardened_clay 9  
fill ~40 ~83 ~64 ~41 ~83 ~64 stained_hardened_clay 9  
fill ~40 ~83 ~71 ~40 ~83 ~73 stained_hardened_clay 9  
fill ~40 ~83 ~74 ~41 ~83 ~74 coal_ore 0  
fill ~41 ~83 ~44 ~41 ~83 ~50 stained_hardened_clay 9  
fill ~41 ~83 ~51 ~41 ~83 ~56 concrete 7 
setblock ~41 ~83 ~59 wool 7 
setblock ~41 ~83 ~61 coal_ore 0 
setblock ~41 ~83 ~62 stonebrick 2 
setblock ~41 ~83 ~65 soul_sand 0  
fill ~41 ~83 ~66 ~43 ~83 ~66 wool 7  
fill ~41 ~83 ~67 ~41 ~83 ~66 wool 7  
fill ~41 ~83 ~68 ~41 ~83 ~70 stained_hardened_clay 9  
fill ~41 ~83 ~71 ~42 ~83 ~71 concrete 8 
setblock ~41 ~83 ~72 stonebrick 2  
fill ~41 ~83 ~73 ~42 ~83 ~73 coal_ore 0 
setblock ~41 ~83 ~75 coal_ore 0  
fill ~42 ~83 ~46 ~42 ~83 ~47 stained_hardened_clay 9  
fill ~42 ~83 ~48 ~42 ~83 ~49 wool 7 
setblock ~42 ~83 ~50 stained_hardened_clay 9 
setblock ~42 ~83 ~51 soul_sand 0 
setblock ~42 ~83 ~55 concrete 7 
setblock ~42 ~83 ~56 stained_hardened_clay 7  
fill ~42 ~83 ~57 ~42 ~83 ~59 stained_hardened_clay 9 
setblock ~42 ~83 ~60 coal_ore 0  
fill ~42 ~83 ~65 ~45 ~83 ~65 stained_hardened_clay 9 
setblock ~42 ~83 ~67 soul_sand 0 
setblock ~42 ~83 ~68 wool 7  
fill ~42 ~83 ~69 ~42 ~83 ~70 stained_hardened_clay 9 
setblock ~42 ~83 ~72 stained_hardened_clay 9 
setblock ~42 ~83 ~74 stained_hardened_clay 9 
setblock ~42 ~83 ~75 concrete 8  
fill ~42 ~83 ~86 ~42 ~83 ~87 stonebrick 2  
fill ~42 ~83 ~88 ~42 ~83 ~89 coal_ore 0 
setblock ~42 ~83 ~90 stained_hardened_clay 9 
setblock ~43 ~83 ~56 wool 7 
setblock ~43 ~83 ~57 concrete 7  
fill ~43 ~83 ~58 ~44 ~83 ~58 stained_hardened_clay 9  
fill ~43 ~83 ~59 ~43 ~83 ~60 stained_hardened_clay 9 
setblock ~43 ~83 ~64 soul_sand 0  
fill ~43 ~83 ~73 ~43 ~83 ~74 concrete 7 
setblock ~43 ~83 ~75 stained_hardened_clay 9  
fill ~43 ~83 ~76 ~45 ~83 ~76 wool 7 
setblock ~43 ~83 ~84 stained_hardened_clay 9  
fill ~43 ~83 ~85 ~43 ~83 ~86 coal_ore 0 
setblock ~43 ~83 ~87 stained_hardened_clay 9 
setblock ~43 ~83 ~88 stonebrick 2  
fill ~43 ~83 ~89 ~44 ~83 ~89 stained_hardened_clay 9 
setblock ~44 ~83 ~55 soul_sand 0 
setblock ~44 ~83 ~56 stained_hardened_clay 9  
fill ~44 ~83 ~57 ~45 ~83 ~57 wool 7 
setblock ~44 ~83 ~59 coal_ore 0 
setblock ~44 ~83 ~60 concrete 7 
setblock ~44 ~83 ~61 soul_sand 0  
fill ~44 ~83 ~62 ~44 ~83 ~65 stained_hardened_clay 9 
setblock ~44 ~83 ~66 soul_sand 0 
setblock ~44 ~83 ~74 stained_hardened_clay 9 
setblock ~44 ~83 ~75 concrete 7 
setblock ~44 ~83 ~83 stained_hardened_clay 9 
setblock ~44 ~83 ~84 coal_ore 0  
fill ~44 ~83 ~86 ~44 ~83 ~87 wool 7 
setblock ~44 ~83 ~88 coal_ore 0  
fill ~45 ~83 ~53 ~46 ~83 ~53 concrete 7  
fill ~45 ~83 ~54 ~45 ~83 ~55 wool 7 
setblock ~45 ~83 ~56 concrete 7 
setblock ~45 ~83 ~58 stonebrick 2  
fill ~45 ~83 ~59 ~46 ~83 ~59 stained_hardened_clay 9 
setblock ~45 ~83 ~60 stained_hardened_clay 7 
setblock ~45 ~83 ~61 wool 7  
fill ~45 ~83 ~62 ~47 ~83 ~62 concrete 7  
fill ~45 ~83 ~63 ~46 ~83 ~63 soul_sand 0 
setblock ~45 ~83 ~64 wool 7 
setblock ~45 ~83 ~77 concrete 7 
setblock ~45 ~83 ~81 coal_ore 0 
setblock ~45 ~83 ~82 stained_hardened_clay 9 
setblock ~45 ~83 ~86 concrete 7  
fill ~45 ~83 ~87 ~46 ~83 ~87 stained_hardened_clay 9  
fill ~45 ~83 ~88 ~45 ~83 ~87 stained_hardened_clay 9  
fill ~45 ~83 ~89 ~45 ~83 ~90 wool 7 
setblock ~46 ~83 ~52 wool 7 
setblock ~46 ~83 ~54 soul_sand 0  
fill ~46 ~83 ~55 ~46 ~83 ~56 wool 7  
fill ~46 ~83 ~57 ~46 ~83 ~59 stained_hardened_clay 9  
fill ~46 ~83 ~60 ~47 ~83 ~60 concrete 7  
fill ~46 ~83 ~61 ~47 ~83 ~61 concrete 7  
fill ~46 ~83 ~64 ~47 ~83 ~64 stained_hardened_clay 9  
fill ~46 ~83 ~65 ~49 ~83 ~65 soul_sand 0 
setblock ~46 ~83 ~66 concrete 7  
fill ~46 ~83 ~77 ~47 ~83 ~77 wool 7 
setblock ~46 ~83 ~78 concrete 7  
fill ~46 ~83 ~79 ~47 ~83 ~79 stained_hardened_clay 9 
setblock ~46 ~83 ~80 coal_ore 0 
setblock ~46 ~83 ~81 stained_hardened_clay 9  
fill ~46 ~83 ~88 ~47 ~83 ~88 coal_ore 0  
fill ~46 ~83 ~89 ~48 ~83 ~89 coal_ore 0 
setblock ~46 ~83 ~90 stonebrick 2 
setblock ~47 ~83 ~51 stained_hardened_clay 9 
setblock ~47 ~83 ~52 soul_sand 0  
fill ~47 ~83 ~53 ~47 ~83 ~54 stained_hardened_clay 9 
setblock ~47 ~83 ~55 stonebrick 2  
fill ~47 ~83 ~56 ~48 ~83 ~56 stained_hardened_clay 9  
fill ~47 ~83 ~57 ~47 ~83 ~59 soul_sand 0 
setblock ~47 ~83 ~63 wool 7 
setblock ~47 ~83 ~66 soul_sand 0 
setblock ~47 ~83 ~78 wool 7 
setblock ~47 ~83 ~90 concrete 7 
setblock ~47 ~83 ~91 wool 7 
setblock ~48 ~83 ~50 stonebrick 2  
fill ~48 ~83 ~51 ~48 ~83 ~52 coal_ore 0  
fill ~48 ~83 ~53 ~49 ~83 ~53 wool 7 
setblock ~48 ~83 ~54 coal_ore 0 
setblock ~48 ~83 ~55 wool 7 
setblock ~48 ~83 ~57 wool 7  
fill ~48 ~83 ~58 ~48 ~83 ~59 concrete 7 
setblock ~48 ~83 ~64 wool 7  
fill ~48 ~83 ~90 ~49 ~83 ~90 coal_ore 0  
fill ~48 ~83 ~91 ~48 ~83 ~89 coal_ore 0 
setblock ~49 ~83 ~52 stained_hardened_clay 9  
fill ~49 ~83 ~54 ~50 ~83 ~54 wool 7  
fill ~49 ~83 ~55 ~50 ~83 ~55 concrete 7  
fill ~49 ~83 ~56 ~49 ~83 ~55 concrete 7 
setblock ~49 ~83 ~89 stained_hardened_clay 9 
setblock ~49 ~83 ~91 stonebrick 2 
setblock ~50 ~83 ~53 coal_ore 0 
setblock ~50 ~83 ~89 wool 7  
fill ~50 ~83 ~90 ~51 ~83 ~90 stained_hardened_clay 9  
fill ~50 ~83 ~91 ~51 ~83 ~91 stained_hardened_clay 9 
setblock ~50 ~83 ~92 stonebrick 2 
setblock ~51 ~83 ~53 wool 7 
setblock ~51 ~83 ~55 stained_hardened_clay 7  
fill ~51 ~83 ~89 ~54 ~83 ~89 stained_hardened_clay 9  
fill ~51 ~83 ~92 ~52 ~83 ~92 coal_ore 0 
setblock ~52 ~83 ~53 soul_sand 0 
setblock ~52 ~83 ~55 stained_hardened_clay 9 
setblock ~52 ~83 ~75 stained_hardened_clay 7 
setblock ~52 ~83 ~76 soul_sand 0  
fill ~52 ~83 ~90 ~54 ~83 ~90 wool 7  
fill ~52 ~83 ~91 ~52 ~83 ~90 wool 7  
fill ~53 ~83 ~53 ~55 ~83 ~53 concrete 7 
setblock ~53 ~83 ~55 soul_sand 0  
fill ~53 ~83 ~91 ~54 ~83 ~91 stonebrick 2  
fill ~53 ~83 ~92 ~55 ~83 ~92 stained_hardened_clay 9  
fill ~54 ~83 ~54 ~55 ~83 ~54 concrete 7  
fill ~54 ~83 ~55 ~56 ~83 ~55 concrete 7 
setblock ~54 ~83 ~65 wool 7 
setblock ~55 ~83 ~52 wool 7  
fill ~55 ~83 ~65 ~56 ~83 ~65 concrete 7 
setblock ~55 ~83 ~89 wool 7  
fill ~55 ~83 ~90 ~56 ~83 ~90 concrete 7 
setblock ~55 ~83 ~91 wool 7 
setblock ~56 ~83 ~49 coal_ore 0 
setblock ~56 ~83 ~50 stained_hardened_clay 9 
setblock ~56 ~83 ~51 wool 7  
fill ~56 ~83 ~52 ~57 ~83 ~52 stained_hardened_clay 9 
setblock ~56 ~83 ~53 coal_ore 0  
fill ~56 ~83 ~54 ~57 ~83 ~54 wool 7 
setblock ~56 ~83 ~56 wool 7  
fill ~56 ~83 ~57 ~57 ~83 ~57 stained_hardened_clay 9 
setblock ~56 ~83 ~58 wool 7 
setblock ~56 ~83 ~64 soul_sand 0 
setblock ~56 ~83 ~89 concrete 7  
fill ~56 ~83 ~91 ~57 ~83 ~91 concrete 7 
setblock ~57 ~83 ~51 concrete 7 
setblock ~57 ~83 ~53 stained_hardened_clay 9  
fill ~57 ~83 ~55 ~59 ~83 ~55 stained_hardened_clay 9  
fill ~57 ~83 ~56 ~59 ~83 ~56 concrete 7 
setblock ~57 ~83 ~58 concrete 7 
setblock ~57 ~83 ~59 soul_sand 0 
setblock ~57 ~83 ~60 concrete 7 
setblock ~57 ~83 ~61 soul_sand 0 
setblock ~57 ~83 ~62 stained_hardened_clay 9  
fill ~57 ~83 ~63 ~58 ~83 ~63 concrete 7  
fill ~57 ~83 ~64 ~57 ~83 ~65 wool 7 
setblock ~57 ~83 ~66 concrete 7 
setblock ~57 ~83 ~78 soul_sand 0 
setblock ~57 ~83 ~79 wool 7 
setblock ~57 ~83 ~88 concrete 7 
setblock ~57 ~83 ~89 stained_hardened_clay 7  
fill ~57 ~83 ~90 ~58 ~83 ~90 stained_hardened_clay 9 
setblock ~58 ~83 ~52 concrete 7  
fill ~58 ~83 ~53 ~59 ~83 ~53 wool 7 
setblock ~58 ~83 ~54 stained_hardened_clay 9  
fill ~58 ~83 ~57 ~59 ~83 ~57 concrete 7  
fill ~58 ~83 ~58 ~58 ~83 ~59 wool 7 
setblock ~58 ~83 ~60 soul_sand 0  
fill ~58 ~83 ~61 ~58 ~83 ~62 wool 7 
setblock ~58 ~83 ~64 concrete 7 
setblock ~58 ~83 ~65 soul_sand 0 
setblock ~58 ~83 ~66 stained_hardened_clay 12  
fill ~58 ~83 ~77 ~58 ~83 ~79 concrete 7 
setblock ~58 ~83 ~80 stained_hardened_clay 7 
setblock ~58 ~83 ~81 concrete 7 
setblock ~58 ~83 ~87 concrete 7 
setblock ~58 ~83 ~88 stained_hardened_clay 7 
setblock ~58 ~83 ~89 concrete 7  
fill ~59 ~83 ~54 ~60 ~83 ~54 concrete 7 
setblock ~59 ~83 ~58 stained_hardened_clay 9 
setblock ~59 ~83 ~59 concrete 7 
setblock ~59 ~83 ~60 wool 7 
setblock ~59 ~83 ~61 concrete 7  
fill ~59 ~83 ~62 ~60 ~83 ~62 stained_hardened_clay 9  
fill ~59 ~83 ~63 ~59 ~83 ~62 stained_hardened_clay 9 
setblock ~59 ~83 ~64 wool 7 
setblock ~59 ~83 ~65 stained_hardened_clay 9  
fill ~59 ~83 ~76 ~61 ~83 ~76 stained_hardened_clay 9 
setblock ~59 ~83 ~77 soul_sand 0  
fill ~59 ~83 ~81 ~59 ~83 ~82 stained_hardened_clay 9 
setblock ~59 ~83 ~87 soul_sand 0 
setblock ~59 ~83 ~88 concrete 7  
fill ~59 ~83 ~89 ~60 ~83 ~89 wool 7  
fill ~59 ~83 ~90 ~59 ~83 ~89 wool 7  
fill ~60 ~83 ~55 ~62 ~83 ~55 wool 7  
fill ~60 ~83 ~56 ~61 ~83 ~56 stained_hardened_clay 9  
fill ~60 ~83 ~57 ~62 ~83 ~57 stained_hardened_clay 9  
fill ~60 ~83 ~58 ~60 ~83 ~59 wool 7 
setblock ~60 ~83 ~60 concrete 7 
setblock ~60 ~83 ~61 soul_sand 0 
setblock ~60 ~83 ~63 wool 7  
fill ~60 ~83 ~64 ~60 ~83 ~66 soul_sand 0 
setblock ~60 ~83 ~75 coal_ore 0 
setblock ~60 ~83 ~83 stained_hardened_clay 13  
fill ~60 ~83 ~84 ~61 ~83 ~84 stained_hardened_clay 9  
fill ~60 ~83 ~86 ~62 ~83 ~86 stained_hardened_clay 9 
setblock ~60 ~83 ~87 concrete 7 
setblock ~60 ~83 ~88 stained_hardened_clay 9  
fill ~61 ~83 ~58 ~62 ~83 ~58 stained_hardened_clay 9  
fill ~61 ~83 ~59 ~63 ~83 ~59 stained_hardened_clay 9  
fill ~61 ~83 ~60 ~61 ~83 ~61 wool 7 
setblock ~61 ~83 ~64 wool 7  
fill ~61 ~83 ~65 ~63 ~83 ~65 stained_hardened_clay 9  
fill ~61 ~83 ~66 ~62 ~83 ~66 concrete 7  
fill ~61 ~83 ~73 ~63 ~83 ~73 coal_ore 0 
setblock ~61 ~83 ~74 concrete 8 
setblock ~61 ~83 ~75 stonebrick 2 
setblock ~61 ~83 ~85 stained_hardened_clay 9 
setblock ~61 ~83 ~87 wool 7  
fill ~61 ~83 ~88 ~61 ~83 ~89 concrete 7  
fill ~62 ~83 ~47 ~63 ~83 ~47 stained_hardened_clay 9  
fill ~62 ~83 ~48 ~63 ~83 ~48 stained_hardened_clay 9 
setblock ~62 ~83 ~49 soul_sand 0  
fill ~62 ~83 ~50 ~64 ~83 ~50 wool 7  
fill ~62 ~83 ~51 ~62 ~83 ~50 wool 7  
fill ~62 ~83 ~60 ~63 ~83 ~60 stained_hardened_clay 9 
setblock ~62 ~83 ~67 wool 7  
fill ~62 ~83 ~68 ~63 ~83 ~68 coal_ore 0  
fill ~62 ~83 ~69 ~63 ~83 ~69 coal_ore 0 
setblock ~62 ~83 ~70 stonebrick 2 
setblock ~62 ~83 ~71 concrete 8  
fill ~62 ~83 ~72 ~63 ~83 ~72 coal_ore 0 
setblock ~62 ~83 ~74 stonebrick 2 
setblock ~62 ~83 ~75 concrete 8  
fill ~62 ~83 ~87 ~62 ~83 ~89 stained_hardened_clay 9 
setblock ~62 ~83 ~90 concrete 7  
fill ~63 ~83 ~44 ~63 ~83 ~48 stained_hardened_clay 9 
setblock ~63 ~83 ~49 wool 7 
setblock ~63 ~83 ~51 stained_hardened_clay 9  
fill ~63 ~83 ~52 ~63 ~83 ~54 wool 7 
setblock ~63 ~83 ~55 stained_hardened_clay 9 
setblock ~63 ~83 ~58 coal_ore 0  
fill ~63 ~83 ~61 ~64 ~83 ~61 stonebrick 2 
setblock ~63 ~83 ~64 stonebrick 2  
fill ~63 ~83 ~66 ~63 ~83 ~67 stained_hardened_clay 9  
fill ~63 ~83 ~70 ~64 ~83 ~70 coal_ore 0  
fill ~63 ~83 ~71 ~64 ~83 ~71 coal_ore 0 
setblock ~63 ~83 ~74 stained_hardened_clay 9 
setblock ~63 ~83 ~75 coal_ore 0  
fill ~64 ~83 ~45 ~64 ~83 ~46 coal_ore 0 
setblock ~64 ~83 ~48 wool 7 
setblock ~64 ~83 ~49 stained_hardened_clay 9 
setblock ~64 ~83 ~51 concrete 7 
setblock ~64 ~83 ~52 stained_hardened_clay 9 
setblock ~64 ~83 ~53 wool 7  
fill ~64 ~83 ~54 ~65 ~83 ~54 stained_hardened_clay 9 
setblock ~64 ~83 ~55 stonebrick 2 
setblock ~64 ~83 ~60 coal_ore 0  
fill ~64 ~83 ~62 ~64 ~83 ~64 coal_ore 0  
fill ~64 ~83 ~72 ~64 ~83 ~73 stonebrick 2 
setblock ~64 ~83 ~74 coal_ore 0  
fill ~65 ~83 ~50 ~65 ~83 ~51 stained_hardened_clay 9 
setblock ~65 ~83 ~55 coal_ore 0  
fill ~66 ~83 ~51 ~66 ~83 ~52 stained_hardened_clay 9 
setblock ~66 ~83 ~54 wool 7  
fill ~66 ~83 ~55 ~67 ~83 ~55 stained_hardened_clay 9  
fill ~67 ~83 ~53 ~67 ~83 ~55 stained_hardened_clay 9 
setblock ~35 ~84 ~56 stained_hardened_clay 9 
setblock ~36 ~84 ~53 coal_ore 0  
fill ~36 ~84 ~54 ~36 ~84 ~55 stained_hardened_clay 9 
setblock ~36 ~84 ~56 coal_ore 0 
setblock ~36 ~84 ~57 stained_hardened_clay 9 
setblock ~37 ~84 ~51 concrete 7 
setblock ~37 ~84 ~52 stained_hardened_clay 9 
setblock ~37 ~84 ~56 stained_hardened_clay 9 
setblock ~37 ~84 ~57 coal_ore 0 
setblock ~38 ~84 ~49 coal_ore 0  
fill ~38 ~84 ~50 ~38 ~84 ~51 wool 7 
setblock ~38 ~84 ~56 wool 7  
fill ~38 ~84 ~57 ~40 ~84 ~57 stained_hardened_clay 9 
setblock ~38 ~84 ~58 coal_ore 0  
fill ~38 ~84 ~59 ~38 ~84 ~60 stained_hardened_clay 9 
setblock ~38 ~84 ~61 concrete 7 
setblock ~38 ~84 ~62 stained_hardened_clay 9 
setblock ~38 ~84 ~72 wool 7  
fill ~38 ~84 ~73 ~39 ~84 ~73 stained_hardened_clay 9  
fill ~38 ~84 ~74 ~39 ~84 ~74 coal_ore 0 
setblock ~39 ~84 ~41 stained_hardened_clay 9 
setblock ~39 ~84 ~42 wool 7 
setblock ~39 ~84 ~43 soul_sand 0  
fill ~39 ~84 ~46 ~40 ~84 ~46 stained_hardened_clay 9  
fill ~39 ~84 ~47 ~40 ~84 ~47 stained_hardened_clay 9  
fill ~39 ~84 ~48 ~39 ~84 ~49 stained_hardened_clay 9 
setblock ~39 ~84 ~56 concrete 7  
fill ~39 ~84 ~58 ~41 ~84 ~58 stained_hardened_clay 9 
setblock ~39 ~84 ~59 wool 7 
setblock ~39 ~84 ~60 concrete 7 
setblock ~39 ~84 ~61 wool 7 
setblock ~39 ~84 ~62 concrete 7 
setblock ~39 ~84 ~63 wool 7  
fill ~39 ~84 ~64 ~39 ~84 ~69 stained_hardened_clay 9  
fill ~39 ~84 ~70 ~39 ~84 ~71 coal_ore 0 
setblock ~39 ~84 ~72 stained_hardened_clay 9 
setblock ~39 ~84 ~75 wool 7 
setblock ~40 ~84 ~41 concrete 7  
fill ~40 ~84 ~42 ~40 ~84 ~43 stained_hardened_clay 9  
fill ~40 ~84 ~44 ~40 ~84 ~45 coal_ore 0 
setblock ~40 ~84 ~56 coal_ore 0 
setblock ~40 ~84 ~59 concrete 7 
setblock ~40 ~84 ~65 stained_hardened_clay 9  
fill ~40 ~84 ~66 ~40 ~84 ~68 coal_ore 0 
setblock ~40 ~84 ~69 wool 7 
setblock ~40 ~84 ~70 stained_hardened_clay 9 
setblock ~40 ~84 ~75 stained_hardened_clay 9 
setblock ~40 ~84 ~76 wool 7 
setblock ~40 ~84 ~77 concrete 7 
setblock ~41 ~84 ~43 stained_hardened_clay 9 
setblock ~41 ~84 ~57 wool 7 
setblock ~41 ~84 ~76 concrete 7 
setblock ~41 ~84 ~77 stained_hardened_clay 9 
setblock ~41 ~84 ~86 coal_ore 0  
fill ~41 ~84 ~87 ~41 ~84 ~88 stained_hardened_clay 9 
setblock ~41 ~84 ~89 coal_ore 0 
setblock ~41 ~84 ~90 stained_hardened_clay 9  
fill ~42 ~84 ~44 ~42 ~84 ~45 stained_hardened_clay 9  
fill ~42 ~84 ~52 ~42 ~84 ~53 wool 7  
fill ~42 ~84 ~54 ~44 ~84 ~54 concrete 7 
setblock ~42 ~84 ~76 stained_hardened_clay 9 
setblock ~42 ~84 ~77 wool 7  
fill ~42 ~84 ~78 ~43 ~84 ~78 stained_hardened_clay 9 
setblock ~42 ~84 ~83 coal_ore 0 
setblock ~42 ~84 ~84 stained_hardened_clay 9 
setblock ~42 ~84 ~85 coal_ore 0  
fill ~42 ~84 ~91 ~43 ~84 ~91 stained_hardened_clay 9  
fill ~42 ~84 ~92 ~42 ~84 ~91 stained_hardened_clay 9 
setblock ~43 ~84 ~46 stained_hardened_clay 9 
setblock ~43 ~84 ~47 wool 7  
fill ~43 ~84 ~48 ~45 ~84 ~48 soul_sand 0  
fill ~43 ~84 ~49 ~43 ~84 ~48 soul_sand 0  
fill ~43 ~84 ~50 ~43 ~84 ~51 wool 7  
fill ~43 ~84 ~52 ~43 ~84 ~54 concrete 7 
setblock ~43 ~84 ~55 stained_hardened_clay 9 
setblock ~43 ~84 ~77 stained_hardened_clay 9  
fill ~43 ~84 ~79 ~44 ~84 ~79 wool 7 
setblock ~43 ~84 ~80 concrete 7  
fill ~43 ~84 ~81 ~44 ~84 ~81 stained_hardened_clay 9  
fill ~43 ~84 ~82 ~44 ~84 ~82 stained_hardened_clay 9 
setblock ~43 ~84 ~83 concrete 8  
fill ~43 ~84 ~90 ~44 ~84 ~90 stained_hardened_clay 9 
setblock ~43 ~84 ~92 coal_ore 0 
setblock ~44 ~84 ~47 stained_hardened_clay 9 
setblock ~44 ~84 ~49 wool 7 
setblock ~44 ~84 ~50 soul_sand 0 
setblock ~44 ~84 ~51 wool 7  
fill ~44 ~84 ~52 ~45 ~84 ~52 soul_sand 0 
setblock ~44 ~84 ~53 stained_hardened_clay 9 
setblock ~44 ~84 ~77 concrete 7 
setblock ~44 ~84 ~78 wool 7 
setblock ~44 ~84 ~80 wool 7 
setblock ~44 ~84 ~91 wool 7 
setblock ~44 ~84 ~92 stained_hardened_clay 9 
setblock ~45 ~84 ~49 coal_ore 0 
setblock ~45 ~84 ~50 wool 7 
setblock ~45 ~84 ~51 soul_sand 0 
setblock ~45 ~84 ~78 stained_hardened_clay 7 
setblock ~45 ~84 ~79 concrete 7 
setblock ~45 ~84 ~80 stained_hardened_clay 9  
fill ~45 ~84 ~91 ~46 ~84 ~91 stained_hardened_clay 9 
setblock ~45 ~84 ~92 coal_ore 0 
setblock ~46 ~84 ~47 soul_sand 0  
fill ~46 ~84 ~48 ~46 ~84 ~50 stained_hardened_clay 9 
setblock ~46 ~84 ~51 wool 7 
setblock ~46 ~84 ~92 stained_hardened_clay 9 
setblock ~47 ~84 ~46 stained_hardened_clay 9  
fill ~47 ~84 ~47 ~47 ~84 ~50 coal_ore 0  
fill ~47 ~84 ~92 ~48 ~84 ~92 wool 7 
setblock ~48 ~84 ~46 coal_ore 0 
setblock ~48 ~84 ~47 stained_hardened_clay 9  
fill ~48 ~84 ~48 ~49 ~84 ~48 coal_ore 0  
fill ~48 ~84 ~49 ~48 ~84 ~48 coal_ore 0 
setblock ~48 ~84 ~93 coal_ore 0 
setblock ~49 ~84 ~46 stained_hardened_clay 9  
fill ~49 ~84 ~47 ~50 ~84 ~47 coal_ore 0  
fill ~49 ~84 ~49 ~49 ~84 ~50 stained_hardened_clay 9 
setblock ~49 ~84 ~51 wool 7 
setblock ~49 ~84 ~92 coal_ore 0  
fill ~49 ~84 ~93 ~50 ~84 ~93 concrete 8 
setblock ~50 ~84 ~45 stained_hardened_clay 9 
setblock ~50 ~84 ~46 coal_ore 0 
setblock ~50 ~84 ~48 stained_hardened_clay 9 
setblock ~50 ~84 ~49 concrete 7 
setblock ~50 ~84 ~50 stained_hardened_clay 7  
fill ~50 ~84 ~51 ~50 ~84 ~52 concrete 7 
setblock ~50 ~84 ~94 stained_hardened_clay 9  
fill ~51 ~84 ~46 ~51 ~84 ~47 concrete 8 
setblock ~51 ~84 ~48 stonebrick 2 
setblock ~51 ~84 ~52 concrete 7  
fill ~51 ~84 ~54 ~52 ~84 ~54 stained_hardened_clay 7 
setblock ~51 ~84 ~93 stained_hardened_clay 9 
setblock ~51 ~84 ~94 coal_ore 0 
setblock ~52 ~84 ~47 stonebrick 2 
setblock ~52 ~84 ~48 stained_hardened_clay 9 
setblock ~52 ~84 ~52 soul_sand 0 
setblock ~52 ~84 ~93 concrete 8 
setblock ~52 ~84 ~94 stonebrick 2 
setblock ~52 ~84 ~95 coal_ore 0  
fill ~53 ~84 ~46 ~54 ~84 ~46 stained_hardened_clay 9  
fill ~53 ~84 ~47 ~57 ~84 ~47 coal_ore 0 
setblock ~53 ~84 ~48 concrete 8 
setblock ~53 ~84 ~52 concrete 7 
setblock ~53 ~84 ~54 concrete 7 
setblock ~53 ~84 ~93 stonebrick 2 
setblock ~53 ~84 ~94 stained_hardened_clay 9 
setblock ~54 ~84 ~48 stained_hardened_clay 9 
setblock ~54 ~84 ~49 concrete 7  
fill ~54 ~84 ~50 ~55 ~84 ~50 wool 7 
setblock ~54 ~84 ~52 stained_hardened_clay 7 
setblock ~54 ~84 ~93 concrete 7 
setblock ~54 ~84 ~94 soul_sand 0  
fill ~55 ~84 ~46 ~56 ~84 ~46 coal_ore 0 
setblock ~55 ~84 ~48 concrete 7 
setblock ~55 ~84 ~49 stained_hardened_clay 9 
setblock ~55 ~84 ~51 concrete 7  
fill ~55 ~84 ~93 ~56 ~84 ~93 stained_hardened_clay 9 
setblock ~56 ~84 ~48 wool 7  
fill ~56 ~84 ~92 ~57 ~84 ~92 wool 7 
setblock ~57 ~84 ~46 wool 7 
setblock ~57 ~84 ~48 stained_hardened_clay 9 
setblock ~57 ~84 ~49 coal_ore 0 
setblock ~57 ~84 ~50 stained_hardened_clay 9 
setblock ~57 ~84 ~93 concrete 7 
setblock ~58 ~84 ~47 stained_hardened_clay 9 
setblock ~58 ~84 ~48 coal_ore 0  
fill ~58 ~84 ~49 ~58 ~84 ~50 wool 7 
setblock ~58 ~84 ~51 stained_hardened_clay 7 
setblock ~58 ~84 ~91 stained_hardened_clay 9  
fill ~58 ~84 ~92 ~62 ~84 ~92 concrete 7  
fill ~59 ~84 ~47 ~59 ~84 ~48 wool 7  
fill ~59 ~84 ~49 ~60 ~84 ~49 stained_hardened_clay 9 
setblock ~59 ~84 ~50 soul_sand 0  
fill ~59 ~84 ~51 ~59 ~84 ~52 concrete 7  
fill ~59 ~84 ~78 ~59 ~84 ~80 concrete 7  
fill ~59 ~84 ~91 ~60 ~84 ~91 stained_hardened_clay 7  
fill ~60 ~84 ~47 ~61 ~84 ~47 stained_hardened_clay 9  
fill ~60 ~84 ~48 ~61 ~84 ~48 wool 7  
fill ~60 ~84 ~50 ~60 ~84 ~51 wool 7  
fill ~60 ~84 ~52 ~60 ~84 ~53 concrete 7 
setblock ~60 ~84 ~77 soul_sand 0  
fill ~60 ~84 ~78 ~62 ~84 ~78 stained_hardened_clay 9
fill ~60 ~84 ~79 ~61 ~84 ~79 stained_hardened_clay 9  
fill ~60 ~84 ~80 ~60 ~84 ~78 stained_hardened_clay 9 
setblock ~60 ~84 ~81 concrete 8 
setblock ~60 ~84 ~82 wool 7 
setblock ~60 ~84 ~90 wool 7 
setblock ~61 ~84 ~46 concrete 7  
fill ~61 ~84 ~49 ~61 ~84 ~50 concrete 7 
setblock ~61 ~84 ~51 wool 7 
setblock ~61 ~84 ~52 stained_hardened_clay 9  
fill ~61 ~84 ~53 ~61 ~84 ~54 concrete 7  
fill ~61 ~84 ~77 ~62 ~84 ~77 coal_ore 0  
fill ~61 ~84 ~80 ~61 ~84 ~81 coal_ore 0  
fill ~61 ~84 ~82 ~61 ~84 ~83 stained_hardened_clay 9 
setblock ~61 ~84 ~90 concrete 7  
fill ~61 ~84 ~91 ~62 ~84 ~91 wool 7  
fill ~62 ~84 ~44 ~62 ~84 ~45 stained_hardened_clay 9 
setblock ~62 ~84 ~46 wool 7 
setblock ~62 ~84 ~52 concrete 7 
setblock ~62 ~84 ~53 soul_sand 0 
setblock ~62 ~84 ~54 stained_hardened_clay 9 
setblock ~62 ~84 ~56 concrete 7  
fill ~62 ~84 ~76 ~63 ~84 ~76 stained_hardened_clay 9  
fill ~62 ~84 ~83 ~62 ~84 ~85 stained_hardened_clay 9 
setblock ~63 ~84 ~43 wool 7  
fill ~63 ~84 ~56 ~65 ~84 ~56 coal_ore 0  
fill ~63 ~84 ~57 ~64 ~84 ~57 stained_hardened_clay 9 
setblock ~63 ~84 ~77 stained_hardened_clay 9 
setblock ~63 ~84 ~86 coal_ore 0  
fill ~63 ~84 ~87 ~63 ~84 ~88 stained_hardened_clay 9 
setblock ~63 ~84 ~89 concrete 7 
setblock ~63 ~84 ~90 wool 7 
setblock ~63 ~84 ~91 stained_hardened_clay 9 
setblock ~64 ~84 ~42 coal_ore 0  
fill ~64 ~84 ~43 ~65 ~84 ~43 stained_hardened_clay 9 
setblock ~64 ~84 ~44 coal_ore 0  
fill ~64 ~84 ~45 ~64 ~84 ~46 stained_hardened_clay 9 
setblock ~64 ~84 ~47 wool 7  
fill ~64 ~84 ~58 ~66 ~84 ~58 stained_hardened_clay 9  
fill ~64 ~84 ~59 ~65 ~84 ~59 coal_ore 0 
setblock ~64 ~84 ~65 stained_hardened_clay 9 
setblock ~64 ~84 ~66 coal_ore 0 
setblock ~64 ~84 ~67 stonebrick 2  
fill ~64 ~84 ~68 ~64 ~84 ~69 coal_ore 0 
setblock ~64 ~84 ~75 concrete 8  
fill ~64 ~84 ~76 ~65 ~84 ~76 coal_ore 0  
fill ~65 ~84 ~41 ~65 ~85 ~41 coal_ore 0 
setblock ~65 ~84 ~42 stained_hardened_clay 9 
setblock ~65 ~84 ~45 stonebrick 2 
setblock ~65 ~84 ~46 coal_ore 0  
fill ~65 ~84 ~47 ~65 ~84 ~48 stained_hardened_clay 9  
fill ~65 ~84 ~49 ~66 ~84 ~49 coal_ore 0 
setblock ~65 ~84 ~57 coal_ore 0  
fill ~65 ~84 ~60 ~66 ~84 ~60 wool 7  
fill ~65 ~84 ~61 ~65 ~84 ~60 wool 7  
fill ~65 ~84 ~62 ~66 ~84 ~62 stained_hardened_clay 9  
fill ~65 ~84 ~63 ~65 ~84 ~64 coal_ore 0  
fill ~65 ~84 ~65 ~65 ~84 ~66 concrete 8 
setblock ~65 ~84 ~67 coal_ore 0  
fill ~65 ~84 ~68 ~65 ~84 ~70 stained_hardened_clay 9 
setblock ~65 ~84 ~71 stonebrick 2  
fill ~65 ~84 ~72 ~66 ~84 ~72 concrete 8 
setblock ~65 ~84 ~73 stonebrick 2 
setblock ~65 ~84 ~74 stained_hardened_clay 9 
setblock ~65 ~84 ~75 stonebrick 2 
setblock ~66 ~84 ~50 coal_ore 0  
fill ~66 ~84 ~56 ~68 ~84 ~56 stained_hardened_clay 9  
fill ~66 ~84 ~57 ~68 ~84 ~57 stained_hardened_clay 9 
setblock ~66 ~84 ~59 concrete 7 
setblock ~66 ~84 ~61 concrete 7 
setblock ~66 ~84 ~71 coal_ore 0 
setblock ~66 ~84 ~73 concrete 8 
setblock ~66 ~84 ~74 coal_ore 0 
setblock ~67 ~84 ~51 stained_hardened_clay 9 
setblock ~67 ~84 ~52 coal_ore 0 
setblock ~68 ~84 ~52 stonebrick 2 
setblock ~68 ~84 ~53 stained_hardened_clay 9  
fill ~68 ~84 ~54 ~68 ~84 ~55 concrete 7 
setblock ~69 ~84 ~55 concrete 7 
setblock ~69 ~84 ~56 wool 7  
fill ~34 ~85 ~54 ~35 ~85 ~54 coal_ore 0  
fill ~34 ~85 ~55 ~34 ~85 ~56 stained_hardened_clay 9  
fill ~34 ~85 ~57 ~35 ~85 ~57 coal_ore 0 
setblock ~34 ~85 ~73 coal_ore 0 
setblock ~34 ~85 ~74 stonebrick 2  
fill ~34 ~85 ~75 ~34 ~85 ~76 coal_ore 0 
setblock ~34 ~85 ~77 stonebrick 2 
setblock ~34 ~85 ~78 coal_ore 0 
setblock ~35 ~85 ~52 stained_hardened_clay 9 
setblock ~35 ~85 ~53 wool 7 
setblock ~35 ~85 ~55 coal_ore 0 
setblock ~35 ~85 ~58 stained_hardened_clay 9 
setblock ~35 ~85 ~71 stonebrick 2 
setblock ~35 ~85 ~72 stained_hardened_clay 9 
setblock ~35 ~85 ~73 stonebrick 2 
setblock ~35 ~85 ~74 concrete 8  
fill ~35 ~85 ~75 ~37 ~85 ~75 stained_hardened_clay 9  
fill ~35 ~85 ~76 ~38 ~85 ~76 stained_hardened_clay 9  
fill ~35 ~85 ~77 ~36 ~85 ~77 coal_ore 0  
fill ~36 ~85 ~51 ~36 ~85 ~52 wool 7  
fill ~36 ~85 ~58 ~36 ~85 ~59 wool 7  
fill ~36 ~85 ~60 ~36 ~85 ~61 stained_hardened_clay 9  
fill ~36 ~85 ~62 ~37 ~85 ~62 concrete 7 
setblock ~36 ~85 ~66 stained_hardened_clay 9 
setblock ~36 ~85 ~69 concrete 8 
setblock ~36 ~85 ~70 stained_hardened_clay 9  
fill ~36 ~85 ~71 ~36 ~85 ~73 coal_ore 0 
setblock ~36 ~85 ~74 wool 7 
setblock ~37 ~85 ~40 stained_hardened_clay 9  
fill ~37 ~85 ~48 ~37 ~85 ~49 coal_ore 0 
setblock ~37 ~85 ~50 wool 7 
setblock ~37 ~85 ~58 stained_hardened_clay 9 
setblock ~37 ~85 ~59 wool 7 
setblock ~37 ~85 ~60 coal_ore 0 
setblock ~37 ~85 ~61 stained_hardened_clay 9  
fill ~37 ~85 ~63 ~38 ~85 ~63 wool 7 
setblock ~37 ~85 ~64 concrete 7  
fill ~37 ~85 ~65 ~38 ~85 ~65 stained_hardened_clay 9 
setblock ~37 ~85 ~66 coal_ore 0  
fill ~37 ~85 ~67 ~38 ~85 ~67 stained_hardened_clay 9 
setblock ~37 ~85 ~68 stonebrick 2  
fill ~37 ~85 ~69 ~37 ~85 ~70 coal_ore 0 
setblock ~37 ~85 ~71 stained_hardened_clay 9 
setblock ~37 ~85 ~72 wool 7 
setblock ~37 ~85 ~73 concrete 7 
setblock ~37 ~85 ~74 stained_hardened_clay 9  
fill ~37 ~85 ~77 ~38 ~85 ~77 wool 7 
setblock ~37 ~85 ~78 coal_ore 0  
fill ~38 ~85 ~39 ~38 ~85 ~40 coal_ore 0  
fill ~38 ~85 ~41 ~38 ~85 ~45 stained_hardened_clay 9 
setblock ~38 ~85 ~46 coal_ore 0  
fill ~38 ~85 ~47 ~38 ~85 ~48 stained_hardened_clay 9 
setblock ~38 ~85 ~64 stained_hardened_clay 9 
setblock ~38 ~85 ~66 stained_hardened_clay 9  
fill ~38 ~85 ~68 ~38 ~85 ~69 stained_hardened_clay 9  
fill ~38 ~85 ~70 ~38 ~85 ~71 wool 7 
setblock ~38 ~85 ~75 coal_ore 0 
setblock ~38 ~85 ~78 stained_hardened_clay 9  
fill ~38 ~85 ~79 ~39 ~85 ~79 coal_ore 0  
fill ~39 ~85 ~40 ~41 ~85 ~40 coal_ore 0 
setblock ~39 ~85 ~43 wool 7 
setblock ~39 ~85 ~44 stained_hardened_clay 9 
setblock ~39 ~85 ~45 coal_ore 0 
setblock ~39 ~85 ~76 coal_ore 0 
setblock ~39 ~85 ~77 stained_hardened_clay 9 
setblock ~39 ~85 ~78 wool 7  
fill ~39 ~85 ~80 ~40 ~85 ~80 coal_ore 0  
fill ~39 ~85 ~81 ~40 ~85 ~81 stained_hardened_clay 9  
fill ~39 ~85 ~82 ~42 ~85 ~82 stained_hardened_clay 9  
fill ~40 ~85 ~78 ~41 ~85 ~78 stained_hardened_clay 9 
setblock ~40 ~85 ~79 wool 7 
setblock ~40 ~85 ~83 stonebrick 2  
fill ~40 ~85 ~85 ~41 ~85 ~85 stained_hardened_clay 9 
setblock ~40 ~85 ~86 wool 7 
setblock ~40 ~85 ~87 coal_ore 0  
fill ~40 ~85 ~88 ~40 ~85 ~90 stained_hardened_clay 9  
fill ~41 ~85 ~41 ~45 ~85 ~41 stained_hardened_clay 9  
fill ~41 ~85 ~42 ~43 ~85 ~42 wool 7 
setblock ~41 ~85 ~79 stained_hardened_clay 9  
fill ~41 ~85 ~80 ~42 ~85 ~80 wool 7  
fill ~41 ~85 ~81 ~41 ~85 ~80 wool 7 
setblock ~41 ~85 ~83 wool 7 
setblock ~41 ~85 ~84 coal_ore 0 
setblock ~41 ~85 ~91 stained_hardened_clay 9 
setblock ~41 ~85 ~92 wool 7  
fill ~42 ~85 ~43 ~43 ~85 ~43 stained_hardened_clay 9 
setblock ~42 ~85 ~79 wool 7 
setblock ~42 ~85 ~81 stained_hardened_clay 9 
setblock ~42 ~85 ~93 stained_hardened_clay 9 
setblock ~42 ~85 ~94 coal_ore 0 
setblock ~43 ~85 ~44 stained_hardened_clay 9  
fill ~43 ~85 ~45 ~44 ~85 ~45 coal_ore 0  
fill ~43 ~85 ~93 ~44 ~85 ~93 wool 7 
setblock ~43 ~85 ~94 concrete 7 
setblock ~44 ~85 ~38 stonebrick 2 
setblock ~44 ~85 ~39 coal_ore 0 
setblock ~44 ~85 ~40 stained_hardened_clay 9 
setblock ~44 ~85 ~42 stained_hardened_clay 9 
setblock ~44 ~85 ~43 concrete 7 
setblock ~44 ~85 ~44 stonebrick 2  
fill ~44 ~85 ~46 ~45 ~85 ~46 stained_hardened_clay 9 
setblock ~44 ~85 ~94 wool 7 
setblock ~45 ~85 ~38 stained_hardened_clay 9 
setblock ~45 ~85 ~40 coal_ore 0 
setblock ~45 ~85 ~42 concrete 7 
setblock ~45 ~85 ~43 stained_hardened_clay 9 
setblock ~45 ~85 ~44 wool 7 
setblock ~45 ~85 ~45 stained_hardened_clay 9 
setblock ~45 ~85 ~47 soul_sand 0 
setblock ~45 ~85 ~93 coal_ore 0 
setblock ~45 ~85 ~94 concrete 8  
fill ~45 ~85 ~95 ~46 ~85 ~95 stained_hardened_clay 9 
setblock ~46 ~85 ~37 stained_hardened_clay 9 
setblock ~46 ~85 ~38 coal_ore 0 
setblock ~46 ~85 ~42 stained_hardened_clay 9  
fill ~46 ~85 ~43 ~47 ~85 ~43 coal_ore 0  
fill ~46 ~85 ~44 ~46 ~85 ~45 coal_ore 0 
setblock ~46 ~85 ~46 wool 7  
fill ~46 ~85 ~93 ~47 ~85 ~93 wool 7 
setblock ~46 ~85 ~94 stained_hardened_clay 9  
fill ~47 ~85 ~36 ~48 ~85 ~36 stained_hardened_clay 9  
fill ~47 ~85 ~37 ~48 ~85 ~37 coal_ore 0 
setblock ~47 ~85 ~44 stained_hardened_clay 9  
fill ~47 ~85 ~45 ~48 ~85 ~45 coal_ore 0 
setblock ~47 ~85 ~94 wool 7 
setblock ~47 ~85 ~95 stonebrick 2 
setblock ~48 ~85 ~43 stonebrick 2 
setblock ~48 ~85 ~44 coal_ore 0 
setblock ~48 ~85 ~94 stained_hardened_clay 9 
setblock ~48 ~85 ~95 coal_ore 0  
fill ~49 ~85 ~43 ~50 ~85 ~43 stained_hardened_clay 9  
fill ~49 ~85 ~44 ~50 ~85 ~44 stained_hardened_clay 9  
fill ~49 ~85 ~45 ~49 ~85 ~43 stained_hardened_clay 9  
fill ~49 ~85 ~94 ~49 ~85 ~95 stonebrick 2  
fill ~49 ~85 ~96 ~50 ~85 ~96 coal_ore 0 
setblock ~50 ~85 ~95 stonebrick 2  
fill ~51 ~85 ~43 ~51 ~85 ~44 coal_ore 0 
setblock ~51 ~85 ~45 stained_hardened_clay 9 
setblock ~51 ~85 ~49 stained_hardened_clay 9 
setblock ~51 ~85 ~50 stained_hardened_clay 7 
setblock ~51 ~85 ~51 wool 7 
setblock ~51 ~85 ~95 wool 7 
setblock ~51 ~85 ~96 stained_hardened_clay 9 
setblock ~52 ~85 ~43 concrete 7 
setblock ~52 ~85 ~44 stained_hardened_clay 9 
setblock ~52 ~85 ~45 stonebrick 2 
setblock ~52 ~85 ~46 stained_hardened_clay 9 
setblock ~52 ~85 ~49 wool 7  
fill ~52 ~85 ~50 ~52 ~85 ~51 concrete 7 
setblock ~52 ~85 ~96 wool 7 
setblock ~52 ~85 ~101 stained_hardened_clay 9  
fill ~53 ~85 ~43 ~54 ~85 ~43 wool 7  
fill ~53 ~85 ~44 ~53 ~85 ~43 wool 7  
fill ~53 ~85 ~45 ~54 ~85 ~45 stained_hardened_clay 9 
setblock ~53 ~85 ~49 coal_ore 0 
setblock ~53 ~85 ~50 stained_hardened_clay 7 
setblock ~53 ~85 ~51 concrete 7 
setblock ~53 ~85 ~95 coal_ore 0  
fill ~53 ~85 ~96 ~54 ~85 ~96 stained_hardened_clay 9  
fill ~54 ~85 ~44 ~57 ~85 ~44 stained_hardened_clay 9 
setblock ~54 ~85 ~51 stained_hardened_clay 7 
setblock ~54 ~85 ~95 stained_hardened_clay 9  
fill ~54 ~85 ~97 ~54 ~86 ~97 concrete 7  
fill ~55 ~85 ~43 ~58 ~85 ~43 stained_hardened_clay 9 
setblock ~55 ~85 ~45 wool 7 
setblock ~55 ~85 ~94 wool 7  
fill ~55 ~85 ~95 ~56 ~85 ~95 concrete 7 
setblock ~55 ~85 ~96 coal_ore 0 
setblock ~56 ~85 ~37 stained_hardened_clay 9 
setblock ~56 ~85 ~45 stained_hardened_clay 9 
setblock ~56 ~85 ~94 concrete 7 
setblock ~57 ~85 ~36 coal_ore 0 
setblock ~57 ~85 ~37 stonebrick 2 
setblock ~57 ~85 ~42 stained_hardened_clay 9 
setblock ~57 ~85 ~45 coal_ore 0 
setblock ~57 ~85 ~94 soul_sand 0 
setblock ~57 ~85 ~95 wool 7 
setblock ~58 ~85 ~42 coal_ore 0  
fill ~58 ~85 ~44 ~58 ~85 ~45 wool 7  
fill ~58 ~85 ~46 ~60 ~85 ~46 stained_hardened_clay 9 
setblock ~58 ~85 ~93 stained_hardened_clay 9  
fill ~58 ~85 ~94 ~58 ~85 ~95 concrete 7 
setblock ~59 ~85 ~37 coal_ore 0 
setblock ~59 ~85 ~38 stonebrick 2 
setblock ~59 ~85 ~39 coal_ore 0  
fill ~59 ~85 ~40 ~61 ~85 ~40 concrete 8  
fill ~59 ~85 ~41 ~60 ~85 ~41 stonebrick 2 
setblock ~59 ~85 ~42 stained_hardened_clay 9 
setblock ~59 ~85 ~43 coal_ore 0 
setblock ~59 ~85 ~44 stained_hardened_clay 9 
setblock ~59 ~85 ~45 wool 7  
fill ~59 ~85 ~93 ~61 ~85 ~93 stained_hardened_clay 7  
fill ~59 ~85 ~94 ~60 ~85 ~94 stained_hardened_clay 9  
fill ~59 ~85 ~95 ~59 ~85 ~94 stained_hardened_clay 9 
setblock ~60 ~85 ~38 concrete 8 
setblock ~60 ~85 ~39 stonebrick 2  
fill ~60 ~85 ~42 ~61 ~85 ~42 coal_ore 0 
setblock ~60 ~85 ~43 wool 7  
fill ~60 ~85 ~44 ~60 ~85 ~45 stonebrick 2 
setblock ~61 ~85 ~41 coal_ore 0  
fill ~61 ~85 ~43 ~61 ~85 ~45 stained_hardened_clay 9 
setblock ~61 ~85 ~94 wool 7 
setblock ~61 ~85 ~95 soul_sand 0 
setblock ~62 ~85 ~40 coal_ore 0  
fill ~62 ~85 ~41 ~62 ~85 ~42 stained_hardened_clay 9 
setblock ~62 ~85 ~43 wool 7 
setblock ~62 ~85 ~79 concrete 7  
fill ~62 ~85 ~80 ~62 ~85 ~81 wool 7  
fill ~62 ~85 ~82 ~63 ~85 ~82 stained_hardened_clay 9 
setblock ~62 ~85 ~93 wool 7  
fill ~63 ~85 ~40 ~65 ~85 ~40 stonebrick 2  
fill ~63 ~85 ~41 ~66 ~85 ~41 coal_ore 0 
setblock ~63 ~85 ~42 stained_hardened_clay 9  
fill ~63 ~85 ~78 ~63 ~85 ~79 wool 7  
fill ~63 ~85 ~80 ~63 ~85 ~82 stained_hardened_clay 9 
setblock ~63 ~85 ~83 soul_sand 0  
fill ~63 ~85 ~84 ~63 ~85 ~85 stained_hardened_clay 9  
fill ~63 ~85 ~91 ~63 ~85 ~92 wool 7 
setblock ~64 ~85 ~77 coal_ore 0  
fill ~64 ~85 ~78 ~65 ~85 ~78 stained_hardened_clay 9  
fill ~64 ~85 ~79 ~64 ~85 ~78 stained_hardened_clay 9  
fill ~64 ~85 ~80 ~65 ~85 ~80 coal_ore 0  
fill ~64 ~85 ~81 ~64 ~85 ~80 coal_ore 0 
setblock ~64 ~85 ~83 coal_ore 0 
setblock ~64 ~85 ~84 wool 7  
fill ~64 ~85 ~85 ~64 ~85 ~86 stained_hardened_clay 9 
setblock ~64 ~85 ~87 coal_ore 0  
fill ~64 ~85 ~88 ~64 ~85 ~90 stained_hardened_clay 9  
fill ~65 ~85 ~44 ~66 ~85 ~44 stonebrick 2  
fill ~65 ~85 ~77 ~67 ~85 ~77 stained_hardened_clay 9 
setblock ~65 ~85 ~79 coal_ore 0  
fill ~66 ~85 ~39 ~67 ~85 ~39 concrete 8 
setblock ~66 ~85 ~40 coal_ore 0 
setblock ~66 ~85 ~42 coal_ore 0 
setblock ~66 ~85 ~43 stonebrick 2  
fill ~66 ~85 ~45 ~66 ~85 ~46 stained_hardened_clay 9 
setblock ~66 ~85 ~47 wool 7  
fill ~66 ~85 ~48 ~67 ~85 ~48 stained_hardened_clay 9  
fill ~66 ~85 ~63 ~66 ~85 ~64 coal_ore 0  
fill ~66 ~85 ~65 ~68 ~85 ~65 stained_hardened_clay 9 
setblock ~66 ~85 ~66 coal_ore 0 
setblock ~66 ~85 ~67 concrete 8 
setblock ~66 ~85 ~68 stained_hardened_clay 9 
setblock ~66 ~85 ~69 wool 7 
setblock ~66 ~85 ~70 stained_hardened_clay 9  
fill ~66 ~85 ~75 ~68 ~85 ~75 coal_ore 0  
fill ~66 ~85 ~76 ~68 ~85 ~76 stained_hardened_clay 9  
fill ~66 ~85 ~78 ~67 ~85 ~78 stonebrick 2 
setblock ~66 ~85 ~79 stained_hardened_clay 9 
setblock ~67 ~85 ~40 stained_hardened_clay 9 
setblock ~67 ~85 ~49 coal_ore 0  
fill ~67 ~85 ~50 ~68 ~85 ~50 stained_hardened_clay 9  
fill ~67 ~85 ~58 ~67 ~85 ~59 wool 7 
setblock ~67 ~85 ~60 concrete 7  
fill ~67 ~85 ~61 ~68 ~85 ~61 wool 7  
fill ~67 ~85 ~62 ~67 ~85 ~66 stained_hardened_clay 9  
fill ~67 ~85 ~67 ~67 ~85 ~70 coal_ore 0  
fill ~67 ~85 ~71 ~69 ~85 ~71 wool 7  
fill ~67 ~85 ~72 ~69 ~85 ~72 concrete 7 
setblock ~67 ~85 ~73 wool 7 
setblock ~67 ~85 ~74 coal_ore 0 
setblock ~68 ~85 ~51 wool 7  
fill ~68 ~85 ~58 ~68 ~85 ~59 concrete 7 
setblock ~68 ~85 ~60 stained_hardened_clay 9 
setblock ~68 ~85 ~62 wool 7 
setblock ~68 ~85 ~66 wool 7 
setblock ~68 ~85 ~68 concrete 7  
fill ~68 ~85 ~69 ~68 ~85 ~70 stained_hardened_clay 9 
setblock ~68 ~85 ~73 concrete 7 
setblock ~68 ~85 ~74 wool 7 
setblock ~68 ~85 ~77 coal_ore 0  
fill ~69 ~85 ~52 ~69 ~85 ~54 stained_hardened_clay 9  
fill ~69 ~85 ~57 ~69 ~85 ~58 stained_hardened_clay 9 
setblock ~69 ~85 ~73 stained_hardened_clay 9 
setblock ~69 ~85 ~74 coal_ore 0 
setblock ~69 ~85 ~75 concrete 8 
setblock ~69 ~85 ~76 coal_ore 0  
fill ~69 ~85 ~77 ~70 ~85 ~77 concrete 8 
setblock ~69 ~85 ~78 coal_ore 0  
fill ~70 ~85 ~54 ~70 ~85 ~55 stained_hardened_clay 9 
setblock ~70 ~85 ~56 concrete 7 
setblock ~70 ~85 ~57 coal_ore 0 
setblock ~70 ~85 ~73 concrete 7  
fill ~70 ~85 ~74 ~70 ~85 ~75 stained_hardened_clay 9 
setblock ~70 ~85 ~76 stonebrick 2 
setblock ~70 ~85 ~78 stonebrick 2 
setblock ~31 ~86 ~75 concrete 7  
fill ~31 ~86 ~76 ~32 ~86 ~76 wool 7  
fill ~31 ~86 ~77 ~32 ~86 ~77 stained_hardened_clay 9 
setblock ~31 ~86 ~78 coal_ore 0 
setblock ~31 ~86 ~79 concrete 8 
setblock ~31 ~86 ~80 stained_hardened_clay 9  
fill ~31 ~86 ~81 ~31 ~86 ~83 concrete 8  
fill ~31 ~86 ~84 ~36 ~86 ~84 stonebrick 2  
fill ~31 ~86 ~85 ~31 ~86 ~84 stonebrick 2  
fill ~31 ~86 ~86 ~31 ~86 ~87 concrete 8 
setblock ~32 ~86 ~56 stonebrick 2 
setblock ~32 ~86 ~71 coal_ore 0 
setblock ~32 ~86 ~72 stained_hardened_clay 9  
fill ~32 ~86 ~73 ~32 ~86 ~74 wool 7 
setblock ~32 ~86 ~75 stained_hardened_clay 9 
setblock ~32 ~86 ~78 wool 7  
fill ~32 ~86 ~79 ~34 ~86 ~79 coal_ore 0  
fill ~32 ~86 ~80 ~33 ~86 ~80 coal_ore 0  
fill ~32 ~86 ~81 ~33 ~86 ~81 stonebrick 2  
fill ~32 ~86 ~82 ~36 ~86 ~82 coal_ore 0  
fill ~32 ~86 ~83 ~32 ~86 ~82 coal_ore 0 
setblock ~32 ~86 ~85 concrete 8  
fill ~32 ~86 ~86 ~32 ~86 ~87 stonebrick 2 
setblock ~32 ~86 ~88 coal_ore 0 
setblock ~33 ~86 ~53 concrete 7 
setblock ~33 ~86 ~54 stained_hardened_clay 9 
setblock ~33 ~86 ~55 concrete 8 
setblock ~33 ~86 ~56 coal_ore 0 
setblock ~33 ~86 ~57 stonebrick 2  
fill ~33 ~86 ~58 ~34 ~86 ~58 coal_ore 0  
fill ~33 ~86 ~68 ~34 ~86 ~68 stained_hardened_clay 9  
fill ~33 ~86 ~69 ~34 ~86 ~69 stained_hardened_clay 9 
setblock ~33 ~86 ~70 coal_ore 0  
fill ~33 ~86 ~71 ~34 ~86 ~71 stonebrick 2 
setblock ~33 ~86 ~72 coal_ore 0  
fill ~33 ~86 ~73 ~33 ~86 ~74 stained_hardened_clay 9  
fill ~33 ~86 ~75 ~33 ~86 ~77 coal_ore 0 
setblock ~33 ~86 ~78 stained_hardened_clay 9  
fill ~33 ~86 ~83 ~35 ~86 ~83 stonebrick 2  
fill ~33 ~86 ~85 ~33 ~86 ~87 coal_ore 0 
setblock ~33 ~86 ~88 stonebrick 2  
fill ~34 ~86 ~51 ~34 ~86 ~52 coal_ore 0 
setblock ~34 ~86 ~53 stained_hardened_clay 9  
fill ~34 ~86 ~54 ~34 ~85 ~54 coal_ore 0  
fill ~34 ~86 ~59 ~35 ~86 ~59 stained_hardened_clay 9 
setblock ~34 ~86 ~61 concrete 8 
setblock ~34 ~86 ~62 coal_ore 0  
fill ~34 ~86 ~63 ~35 ~86 ~63 stained_hardened_clay 9 
setblock ~34 ~86 ~66 coal_ore 0  
fill ~34 ~86 ~67 ~36 ~86 ~67 stained_hardened_clay 9 
setblock ~34 ~86 ~70 stained_hardened_clay 9 
setblock ~34 ~86 ~72 stonebrick 2 
setblock ~34 ~86 ~80 stonebrick 2 
setblock ~34 ~86 ~81 concrete 8  
fill ~34 ~86 ~85 ~34 ~86 ~87 stonebrick 2  
fill ~34 ~86 ~88 ~35 ~86 ~88 coal_ore 0  
fill ~35 ~86 ~49 ~36 ~86 ~49 coal_ore 0 
setblock ~35 ~86 ~50 stained_hardened_clay 9 
setblock ~35 ~86 ~51 stonebrick 2 
setblock ~35 ~86 ~60 coal_ore 0  
fill ~35 ~86 ~61 ~35 ~86 ~67 stained_hardened_clay 9 
setblock ~35 ~86 ~68 wool 7  
fill ~35 ~86 ~69 ~35 ~86 ~70 concrete 7 
setblock ~35 ~86 ~78 coal_ore 0  
fill ~35 ~86 ~79 ~36 ~86 ~79 stained_hardened_clay 9  
fill ~35 ~86 ~80 ~35 ~86 ~82 coal_ore 0 
setblock ~35 ~86 ~85 stained_hardened_clay 9 
setblock ~35 ~86 ~86 stonebrick 2 
setblock ~35 ~86 ~87 coal_ore 0  
fill ~36 ~86 ~39 ~38 ~86 ~39 stained_hardened_clay 9  
fill ~36 ~86 ~40 ~36 ~86 ~39 stained_hardened_clay 9  
fill ~36 ~86 ~46 ~37 ~86 ~46 stained_hardened_clay 9  
fill ~36 ~86 ~47 ~37 ~86 ~47 stained_hardened_clay 9  
fill ~36 ~86 ~48 ~36 ~86 ~46 stained_hardened_clay 9 
setblock ~36 ~86 ~50 wool 7 
setblock ~36 ~86 ~63 concrete 7 
setblock ~36 ~86 ~64 wool 7 
setblock ~36 ~86 ~65 coal_ore 0 
setblock ~36 ~86 ~68 stained_hardened_clay 9 
setblock ~36 ~86 ~78 stained_hardened_clay 9  
fill ~36 ~86 ~80 ~36 ~86 ~81 stained_hardened_clay 9 
setblock ~36 ~86 ~83 coal_ore 0 
setblock ~36 ~86 ~85 stonebrick 2 
setblock ~36 ~86 ~86 coal_ore 0 
setblock ~36 ~86 ~87 stained_hardened_clay 9  
fill ~36 ~86 ~88 ~37 ~86 ~88 wool 7  
fill ~37 ~86 ~41 ~37 ~86 ~42 coal_ore 0  
fill ~37 ~86 ~43 ~37 ~86 ~47 stained_hardened_clay 9  
fill ~37 ~86 ~79 ~37 ~86 ~80 coal_ore 0  
fill ~37 ~86 ~81 ~37 ~86 ~82 stonebrick 2  
fill ~37 ~86 ~83 ~38 ~86 ~83 stained_hardened_clay 9 
setblock ~37 ~86 ~84 coal_ore 0  
fill ~37 ~86 ~85 ~38 ~86 ~85 stained_hardened_clay 9 
setblock ~37 ~86 ~86 wool 7 
setblock ~37 ~86 ~87 concrete 7  
fill ~38 ~86 ~80 ~38 ~86 ~81 coal_ore 0 
setblock ~38 ~86 ~82 stonebrick 2  
fill ~38 ~86 ~84 ~39 ~86 ~84 stained_hardened_clay 9 
setblock ~38 ~86 ~86 concrete 7 
setblock ~38 ~86 ~87 stained_hardened_clay 9  
fill ~38 ~86 ~88 ~39 ~86 ~88 coal_ore 0  
fill ~39 ~86 ~39 ~40 ~86 ~39 coal_ore 0 
setblock ~39 ~86 ~83 stonebrick 2 
setblock ~39 ~86 ~85 concrete 7 
setblock ~39 ~86 ~86 stonebrick 2 
setblock ~39 ~86 ~87 coal_ore 0  
fill ~39 ~86 ~89 ~39 ~86 ~90 stained_hardened_clay 9 
setblock ~40 ~86 ~84 concrete 7  
fill ~40 ~86 ~90 ~40 ~86 ~91 stained_hardened_clay 9 
setblock ~40 ~86 ~92 coal_ore 0  
fill ~41 ~86 ~38 ~41 ~86 ~39 stained_hardened_clay 9  
fill ~41 ~86 ~92 ~41 ~86 ~93 stained_hardened_clay 9 
setblock ~42 ~86 ~38 coal_ore 0  
fill ~42 ~86 ~39 ~43 ~86 ~39 stained_hardened_clay 9 
setblock ~42 ~86 ~40 coal_ore 0  
fill ~42 ~86 ~94 ~42 ~86 ~95 stained_hardened_clay 9  
fill ~43 ~86 ~37 ~45 ~86 ~37 coal_ore 0 
setblock ~43 ~86 ~38 stonebrick 2 
setblock ~43 ~86 ~40 stained_hardened_clay 9  
fill ~43 ~86 ~95 ~43 ~86 ~96 stained_hardened_clay 9 
setblock ~44 ~86 ~36 coal_ore 0 
setblock ~44 ~86 ~95 concrete 7 
setblock ~44 ~86 ~96 stained_hardened_clay 9 
setblock ~44 ~86 ~97 coal_ore 0 
setblock ~45 ~86 ~36 stonebrick 2  
fill ~45 ~86 ~39 ~46 ~86 ~39 stained_hardened_clay 9  
fill ~45 ~86 ~96 ~46 ~86 ~96 wool 7  
fill ~45 ~86 ~97 ~47 ~86 ~97 stained_hardened_clay 9 
setblock ~45 ~86 ~98 coal_ore 0  
fill ~46 ~86 ~35 ~47 ~86 ~35 coal_ore 0 
setblock ~46 ~86 ~36 stained_hardened_clay 9  
fill ~46 ~86 ~40 ~46 ~86 ~41 stained_hardened_clay 9  
fill ~47 ~86 ~34 ~48 ~86 ~34 coal_ore 0  
fill ~47 ~86 ~38 ~49 ~86 ~38 coal_ore 0  
fill ~47 ~86 ~39 ~47 ~86 ~40 stonebrick 2  
fill ~47 ~86 ~41 ~49 ~86 ~41 coal_ore 0  
fill ~47 ~86 ~42 ~48 ~86 ~42 stonebrick 2 
setblock ~47 ~86 ~96 coal_ore 0 
setblock ~48 ~86 ~35 stained_hardened_clay 9 
setblock ~48 ~86 ~39 coal_ore 0 
setblock ~48 ~86 ~40 wool 7 
setblock ~48 ~86 ~96 wool 7 
setblock ~49 ~86 ~35 stonebrick 2 
setblock ~49 ~86 ~36 stained_hardened_clay 9 
setblock ~49 ~86 ~37 coal_ore 0  
fill ~49 ~86 ~39 ~49 ~86 ~40 stained_hardened_clay 9  
fill ~49 ~86 ~42 ~51 ~86 ~42 stained_hardened_clay 9 
setblock ~49 ~86 ~97 soul_sand 0  
fill ~50 ~86 ~37 ~50 ~86 ~38 stained_hardened_clay 9 
setblock ~50 ~86 ~39 concrete 7 
setblock ~50 ~86 ~40 wool 7  
fill ~50 ~86 ~41 ~51 ~86 ~41 stonebrick 2  
fill ~50 ~86 ~97 ~51 ~86 ~97 concrete 7 
setblock ~50 ~86 ~100 soul_sand 0 
setblock ~51 ~86 ~38 stained_hardened_clay 9  
fill ~51 ~86 ~100 ~53 ~86 ~100 stained_hardened_clay 9  
fill ~51 ~86 ~101 ~51 ~86 ~100 stained_hardened_clay 9  
fill ~51 ~86 ~102 ~51 ~87 ~102 wool 7  
fill ~52 ~86 ~38 ~53 ~86 ~38 coal_ore 0  
fill ~52 ~86 ~41 ~53 ~86 ~41 stained_hardened_clay 9 
setblock ~52 ~86 ~42 coal_ore 0 
setblock ~52 ~86 ~96 soul_sand 0 
setblock ~52 ~86 ~97 wool 7 
setblock ~52 ~86 ~102 concrete 7 
setblock ~53 ~86 ~42 stained_hardened_clay 9 
setblock ~53 ~86 ~97 concrete 7  
fill ~53 ~86 ~101 ~53 ~86 ~102 stained_hardened_clay 9 
setblock ~54 ~86 ~36 stonebrick 2  
fill ~54 ~86 ~37 ~55 ~86 ~37 stained_hardened_clay 9  
fill ~54 ~86 ~38 ~56 ~86 ~38 stained_hardened_clay 9  
fill ~54 ~86 ~39 ~56 ~86 ~39 stained_hardened_clay 9 
setblock ~54 ~86 ~41 concrete 8 
setblock ~54 ~86 ~42 concrete 7  
fill ~54 ~86 ~100 ~54 ~86 ~101 wool 7 
setblock ~55 ~86 ~35 stonebrick 2 
setblock ~55 ~86 ~36 coal_ore 0 
setblock ~55 ~86 ~40 concrete 7  
fill ~55 ~86 ~41 ~55 ~86 ~42 coal_ore 0 
setblock ~55 ~86 ~97 wool 7 
setblock ~56 ~86 ~35 coal_ore 0 
setblock ~56 ~86 ~36 stonebrick 2  
fill ~56 ~86 ~40 ~56 ~86 ~41 stained_hardened_clay 9 
setblock ~56 ~86 ~42 concrete 7 
setblock ~56 ~86 ~96 wool 7 
setblock ~57 ~86 ~34 coal_ore 0 
setblock ~57 ~86 ~35 stonebrick 2  
fill ~57 ~86 ~38 ~58 ~86 ~38 concrete 8  
fill ~57 ~86 ~39 ~57 ~86 ~40 coal_ore 0 
setblock ~57 ~86 ~41 concrete 7  
fill ~57 ~86 ~96 ~58 ~86 ~96 stained_hardened_clay 9 
setblock ~58 ~86 ~35 coal_ore 0 
setblock ~58 ~86 ~36 stained_hardened_clay 9 
setblock ~58 ~86 ~37 stonebrick 2  
fill ~58 ~86 ~39 ~58 ~86 ~40 stonebrick 2 
setblock ~58 ~86 ~41 stained_hardened_clay 9 
setblock ~58 ~86 ~97 soul_sand 0 
setblock ~59 ~86 ~36 stonebrick 2 
setblock ~59 ~86 ~96 soul_sand 0  
fill ~59 ~86 ~97 ~59 ~86 ~98 wool 7 
setblock ~60 ~86 ~36 concrete 8 
setblock ~60 ~86 ~37 coal_ore 0 
setblock ~60 ~86 ~95 soul_sand 0  
fill ~60 ~86 ~96 ~60 ~86 ~97 stained_hardened_clay 9  
fill ~61 ~86 ~37 ~61 ~86 ~38 concrete 8  
fill ~61 ~86 ~39 ~62 ~86 ~39 stonebrick 2 
setblock ~61 ~86 ~96 soul_sand 0 
setblock ~62 ~86 ~38 stonebrick 2  
fill ~62 ~86 ~94 ~62 ~86 ~95 wool 7 
setblock ~63 ~86 ~38 coal_ore 0 
setblock ~63 ~86 ~39 stained_hardened_clay 9 
setblock ~63 ~86 ~92 stained_hardened_clay 9 
setblock ~63 ~86 ~93 wool 7  
fill ~64 ~86 ~39 ~65 ~86 ~39 concrete 8 
setblock ~64 ~86 ~82 stained_hardened_clay 9  
fill ~64 ~86 ~91 ~64 ~86 ~92 wool 7  
fill ~65 ~86 ~81 ~65 ~86 ~83 coal_ore 0  
fill ~65 ~86 ~84 ~66 ~86 ~84 stained_hardened_clay 9  
fill ~65 ~86 ~85 ~65 ~86 ~86 stained_hardened_clay 9  
fill ~65 ~86 ~87 ~66 ~86 ~87 coal_ore 0  
fill ~65 ~86 ~88 ~67 ~86 ~88 stained_hardened_clay 9  
fill ~65 ~86 ~89 ~65 ~86 ~90 wool 7 
setblock ~66 ~86 ~39 coal_ore 0 
setblock ~66 ~86 ~80 stained_hardened_clay 9 
setblock ~66 ~86 ~81 stonebrick 2 
setblock ~66 ~86 ~82 concrete 8  
fill ~66 ~86 ~83 ~67 ~86 ~83 coal_ore 0 
setblock ~66 ~86 ~85 stonebrick 2  
fill ~66 ~86 ~86 ~67 ~86 ~86 stained_hardened_clay 9 
setblock ~67 ~86 ~39 stonebrick 2  
fill ~67 ~86 ~41 ~67 ~86 ~42 stonebrick 2 
setblock ~67 ~86 ~43 concrete 8 
setblock ~67 ~86 ~44 coal_ore 0  
fill ~67 ~86 ~45 ~68 ~86 ~45 stonebrick 2  
fill ~67 ~86 ~46 ~67 ~86 ~45 stonebrick 2 
setblock ~67 ~86 ~47 concrete 8  
fill ~67 ~86 ~79 ~67 ~86 ~85 coal_ore 0  
fill ~67 ~86 ~87 ~68 ~86 ~87 stained_hardened_clay 9 
setblock ~68 ~86 ~39 stained_hardened_clay 9 
setblock ~68 ~86 ~40 coal_ore 0 
setblock ~68 ~86 ~46 coal_ore 0  
fill ~68 ~86 ~47 ~68 ~86 ~49 stained_hardened_clay 9 
setblock ~68 ~86 ~63 stained_hardened_clay 9 
setblock ~68 ~86 ~64 wool 7 
setblock ~68 ~86 ~67 stained_hardened_clay 9 
setblock ~68 ~86 ~78 stained_hardened_clay 9 
setblock ~68 ~86 ~79 wool 7 
setblock ~68 ~86 ~80 concrete 7  
fill ~68 ~86 ~81 ~68 ~86 ~82 coal_ore 0 
setblock ~68 ~86 ~83 stained_hardened_clay 9 
setblock ~68 ~86 ~84 stonebrick 2 
setblock ~68 ~86 ~85 concrete 8 
setblock ~68 ~86 ~86 coal_ore 0 
setblock ~68 ~86 ~88 wool 7 
setblock ~69 ~86 ~49 coal_ore 0 
setblock ~69 ~86 ~50 concrete 8 
setblock ~69 ~86 ~51 stained_hardened_clay 9  
fill ~69 ~86 ~59 ~70 ~86 ~59 stained_hardened_clay 9 
setblock ~69 ~86 ~60 stonebrick 2 
setblock ~69 ~86 ~61 wool 7  
fill ~69 ~86 ~62 ~70 ~86 ~62 concrete 7 
setblock ~69 ~86 ~63 coal_ore 0  
fill ~69 ~86 ~64 ~69 ~86 ~66 stained_hardened_clay 9  
fill ~69 ~86 ~67 ~70 ~86 ~67 coal_ore 0  
fill ~69 ~86 ~68 ~70 ~86 ~68 coal_ore 0  
fill ~69 ~86 ~69 ~69 ~86 ~70 wool 7  
fill ~69 ~86 ~79 ~69 ~86 ~80 stonebrick 2  
fill ~69 ~86 ~81 ~69 ~86 ~82 concrete 8  
fill ~69 ~86 ~83 ~69 ~86 ~84 coal_ore 0  
fill ~69 ~86 ~85 ~69 ~86 ~86 stained_hardened_clay 9  
fill ~69 ~86 ~87 ~69 ~86 ~88 stonebrick 2 
setblock ~70 ~86 ~51 coal_ore 0 
setblock ~70 ~86 ~52 wool 7  
fill ~70 ~86 ~53 ~71 ~86 ~53 stained_hardened_clay 9 
setblock ~70 ~86 ~58 coal_ore 0 
setblock ~70 ~86 ~61 concrete 7 
setblock ~70 ~86 ~63 stained_hardened_clay 9 
setblock ~70 ~86 ~66 coal_ore 0 
setblock ~70 ~86 ~69 stained_hardened_clay 9  
fill ~70 ~86 ~70 ~70 ~86 ~71 wool 7 
setblock ~70 ~86 ~72 concrete 7  
fill ~70 ~86 ~79 ~71 ~86 ~79 concrete 8  
fill ~70 ~86 ~80 ~70 ~86 ~79 concrete 8  
fill ~70 ~86 ~81 ~70 ~86 ~82 coal_ore 0  
fill ~70 ~86 ~83 ~70 ~86 ~85 stonebrick 2 
setblock ~70 ~86 ~86 concrete 8  
fill ~70 ~86 ~87 ~73 ~86 ~87 coal_ore 0  
fill ~70 ~86 ~88 ~71 ~86 ~88 coal_ore 0 
setblock ~71 ~86 ~54 coal_ore 0  
fill ~71 ~86 ~55 ~71 ~86 ~57 stained_hardened_clay 9 
setblock ~71 ~86 ~58 stonebrick 2 
setblock ~71 ~86 ~68 concrete 8 
setblock ~71 ~86 ~69 concrete 7  
fill ~71 ~86 ~70 ~71 ~86 ~72 stained_hardened_clay 9  
fill ~71 ~86 ~73 ~72 ~86 ~73 coal_ore 0 
setblock ~71 ~86 ~74 stained_hardened_clay 9  
fill ~71 ~86 ~75 ~72 ~86 ~75 coal_ore 0  
fill ~71 ~86 ~76 ~71 ~86 ~77 concrete 8 
setblock ~71 ~86 ~78 stonebrick 2  
fill ~71 ~86 ~80 ~72 ~86 ~80 stonebrick 2  
fill ~71 ~86 ~81 ~72 ~86 ~81 stonebrick 2  
fill ~71 ~86 ~82 ~71 ~86 ~80 stonebrick 2  
fill ~71 ~86 ~83 ~71 ~86 ~88 coal_ore 0 
setblock ~72 ~86 ~56 wool 7 
setblock ~72 ~86 ~57 coal_ore 0 
setblock ~72 ~86 ~71 stained_hardened_clay 9 
setblock ~72 ~86 ~72 coal_ore 0  
fill ~72 ~86 ~74 ~73 ~86 ~74 stonebrick 2  
fill ~72 ~86 ~76 ~73 ~86 ~76 coal_ore 0 
setblock ~72 ~86 ~77 stained_hardened_clay 9 
setblock ~72 ~86 ~78 coal_ore 0 
setblock ~72 ~86 ~79 stonebrick 2  
fill ~72 ~86 ~82 ~73 ~86 ~82 coal_ore 0 
setblock ~72 ~86 ~83 stained_hardened_clay 9 
setblock ~72 ~86 ~84 coal_ore 0  
fill ~72 ~86 ~85 ~73 ~86 ~85 stained_hardened_clay 9 
setblock ~72 ~86 ~86 stonebrick 2 
setblock ~72 ~86 ~88 stained_hardened_clay 9 
setblock ~73 ~86 ~75 stonebrick 2  
fill ~73 ~86 ~77 ~74 ~86 ~77 coal_ore 0 
setblock ~73 ~86 ~78 concrete 8 
setblock ~73 ~86 ~79 stained_hardened_clay 9  
fill ~73 ~86 ~80 ~73 ~86 ~83 coal_ore 0 
setblock ~73 ~86 ~84 stained_hardened_clay 9 
setblock ~73 ~86 ~86 coal_ore 0 
setblock ~74 ~86 ~78 stonebrick 2 
setblock ~25 ~87 ~82 stained_hardened_clay 9  
fill ~25 ~87 ~83 ~26 ~87 ~83 coal_ore 0  
fill ~25 ~87 ~84 ~25 ~87 ~85 stonebrick 2  
fill ~25 ~87 ~90 ~26 ~87 ~90 stonebrick 2 
setblock ~26 ~87 ~84 coal_ore 0  
fill ~26 ~87 ~89 ~28 ~87 ~89 coal_ore 0 
setblock ~27 ~87 ~90 coal_ore 0  
fill ~29 ~87 ~72 ~31 ~87 ~72 stained_hardened_clay 9  
fill ~29 ~87 ~73 ~30 ~87 ~73 coal_ore 0 
setblock ~29 ~87 ~74 stonebrick 2 
setblock ~29 ~87 ~75 coal_ore 0  
fill ~29 ~87 ~76 ~30 ~87 ~76 stained_hardened_clay 9  
fill ~29 ~87 ~77 ~29 ~87 ~78 stained_hardened_clay 9  
fill ~29 ~87 ~79 ~29 ~87 ~80 stonebrick 2 
setblock ~29 ~87 ~81 coal_ore 0 
setblock ~29 ~87 ~82 stonebrick 2  
fill ~29 ~87 ~83 ~30 ~87 ~83 coal_ore 0 
setblock ~29 ~87 ~84 stonebrick 2  
fill ~29 ~87 ~85 ~30 ~87 ~85 coal_ore 0  
fill ~29 ~87 ~86 ~29 ~87 ~85 coal_ore 0 
setblock ~30 ~87 ~71 stained_hardened_clay 9 
setblock ~30 ~87 ~74 coal_ore 0 
setblock ~30 ~87 ~75 wool 7  
fill ~30 ~87 ~77 ~30 ~87 ~78 coal_ore 0 
setblock ~30 ~87 ~79 stained_hardened_clay 9 
setblock ~30 ~87 ~80 coal_ore 0 
setblock ~30 ~87 ~81 stonebrick 2 
setblock ~30 ~87 ~82 coal_ore 0 
setblock ~30 ~87 ~84 coal_ore 0 
setblock ~30 ~87 ~86 concrete 7 
setblock ~30 ~87 ~87 stained_hardened_clay 7 
setblock ~31 ~87 ~54 concrete 8  
fill ~31 ~87 ~55 ~31 ~87 ~57 stonebrick 2  
fill ~31 ~87 ~68 ~32 ~87 ~68 stonebrick 2  
fill ~31 ~87 ~69 ~31 ~87 ~68 stonebrick 2  
fill ~31 ~87 ~70 ~32 ~87 ~70 coal_ore 0 
setblock ~31 ~87 ~71 stonebrick 2 
setblock ~31 ~87 ~73 stonebrick 2 
setblock ~31 ~87 ~74 stained_hardened_clay 9 
setblock ~31 ~87 ~88 stained_hardened_clay 9  
fill ~32 ~87 ~52 ~33 ~87 ~52 coal_ore 0  
fill ~32 ~87 ~53 ~32 ~87 ~52 coal_ore 0 
setblock ~32 ~87 ~54 stonebrick 2 
setblock ~32 ~87 ~55 concrete 8 
setblock ~32 ~87 ~57 stonebrick 2 
setblock ~32 ~87 ~58 coal_ore 0 
setblock ~32 ~87 ~59 stained_hardened_clay 9 
setblock ~32 ~87 ~63 concrete 8 
setblock ~32 ~87 ~65 concrete 8  
fill ~32 ~87 ~66 ~33 ~87 ~66 stonebrick 2 
setblock ~32 ~87 ~67 concrete 8 
setblock ~32 ~87 ~69 wool 7 
setblock ~32 ~87 ~89 stonebrick 2  
fill ~33 ~87 ~50 ~34 ~87 ~50 coal_ore 0 
setblock ~33 ~87 ~51 stained_hardened_clay 9 
setblock ~33 ~87 ~59 coal_ore 0  
fill ~33 ~87 ~60 ~34 ~87 ~60 concrete 8 
setblock ~33 ~87 ~61 coal_ore 0 
setblock ~33 ~87 ~62 concrete 8 
setblock ~33 ~87 ~63 stained_hardened_clay 9  
fill ~33 ~87 ~64 ~33 ~87 ~65 coal_ore 0 
setblock ~33 ~87 ~67 stained_hardened_clay 9 
setblock ~33 ~87 ~89 concrete 8 
setblock ~33 ~87 ~90 coal_ore 0  
fill ~34 ~87 ~47 ~35 ~87 ~47 stonebrick 2  
fill ~34 ~87 ~48 ~35 ~87 ~48 coal_ore 0  
fill ~34 ~87 ~49 ~34 ~87 ~48 coal_ore 0 
setblock ~34 ~87 ~64 stained_hardened_clay 9 
setblock ~34 ~87 ~65 coal_ore 0  
fill ~34 ~87 ~89 ~35 ~87 ~89 coal_ore 0 
setblock ~34 ~87 ~90 stained_hardened_clay 9  
fill ~35 ~87 ~38 ~35 ~87 ~39 wool 7 
setblock ~35 ~87 ~40 coal_ore 0  
fill ~35 ~87 ~41 ~36 ~87 ~41 stained_hardened_clay 9  
fill ~35 ~87 ~42 ~35 ~87 ~43 stained_hardened_clay 9  
fill ~35 ~87 ~44 ~35 ~87 ~46 coal_ore 0 
setblock ~35 ~87 ~90 soul_sand 0  
fill ~36 ~87 ~38 ~40 ~87 ~38 stained_hardened_clay 9  
fill ~36 ~87 ~39 ~36 ~87 ~38 stained_hardened_clay 9  
fill ~36 ~87 ~42 ~36 ~87 ~43 coal_ore 0 
setblock ~36 ~87 ~44 stained_hardened_clay 9 
setblock ~36 ~87 ~45 coal_ore 0  
fill ~36 ~87 ~89 ~37 ~87 ~89 wool 7  
fill ~36 ~87 ~90 ~38 ~87 ~90 stained_hardened_clay 9  
fill ~37 ~87 ~91 ~39 ~87 ~91 stained_hardened_clay 9 
setblock ~37 ~87 ~92 wool 7 
setblock ~38 ~87 ~89 concrete 7 
setblock ~38 ~87 ~92 concrete 7 
setblock ~39 ~87 ~92 wool 7 
setblock ~40 ~87 ~93 coal_ore 0  
fill ~41 ~87 ~37 ~42 ~87 ~37 stained_hardened_clay 9   

KittysCommands:  
setblock ~41 ~87 ~94 stained_hardened_clay 9 
setblock ~42 ~87 ~95 stained_hardened_clay 9 
setblock ~43 ~87 ~36 concrete 8  
fill ~43 ~87 ~96 ~43 ~87 ~97 stained_hardened_clay 9  
fill ~44 ~87 ~35 ~45 ~87 ~35 coal_ore 0 
setblock ~44 ~87 ~98 coal_ore 0  
fill ~45 ~87 ~34 ~46 ~87 ~34 coal_ore 0  
fill ~45 ~87 ~99 ~45 ~89 ~99 stained_hardened_clay 9  
fill ~46 ~87 ~98 ~47 ~87 ~98 coal_ore 0  
fill ~46 ~87 ~99 ~46 ~87 ~98 coal_ore 0 
setblock ~47 ~87 ~33 concrete 8  
fill ~47 ~87 ~99 ~48 ~87 ~99 wool 7 
setblock ~48 ~87 ~33 coal_ore 0  
fill ~48 ~87 ~97 ~49 ~87 ~97 concrete 7 
setblock ~48 ~87 ~98 wool 7 
setblock ~49 ~87 ~34 coal_ore 0  
fill ~49 ~87 ~98 ~49 ~87 ~99 soul_sand 0 
setblock ~49 ~87 ~100 stained_hardened_clay 9  
fill ~50 ~87 ~35 ~50 ~87 ~36 stained_hardened_clay 9  
fill ~50 ~87 ~98 ~50 ~87 ~99 stained_hardened_clay 9 
setblock ~50 ~87 ~101 stained_hardened_clay 9 
setblock ~51 ~87 ~35 concrete 7 
setblock ~51 ~87 ~36 stained_hardened_clay 9  
fill ~51 ~87 ~37 ~53 ~87 ~37 wool 7  
fill ~51 ~87 ~39 ~52 ~87 ~39 stained_hardened_clay 9 
setblock ~51 ~87 ~40 wool 7 
setblock ~51 ~87 ~98 wool 7 
setblock ~51 ~87 ~99 concrete 7  
fill ~52 ~87 ~36 ~53 ~87 ~36 coal_ore 0 
setblock ~52 ~87 ~40 stained_hardened_clay 9  
fill ~52 ~87 ~98 ~52 ~87 ~99 stained_hardened_clay 9  
fill ~52 ~87 ~102 ~53 ~87 ~102 stained_hardened_clay 9 
setblock ~53 ~87 ~39 wool 7 
setblock ~53 ~87 ~40 concrete 7 
setblock ~53 ~87 ~98 soul_sand 0  
fill ~53 ~87 ~99 ~54 ~87 ~99 stained_hardened_clay 9 
setblock ~54 ~87 ~35 coal_ore 0 
setblock ~54 ~87 ~40 stained_hardened_clay 9 
setblock ~54 ~87 ~98 wool 7 
setblock ~54 ~87 ~101 stained_hardened_clay 9  
fill ~55 ~87 ~34 ~56 ~87 ~34 stained_hardened_clay 9  
fill ~55 ~87 ~97 ~56 ~87 ~97 concrete 7  
fill ~55 ~87 ~98 ~55 ~87 ~97 concrete 7  
fill ~55 ~87 ~99 ~56 ~87 ~99 wool 7 
setblock ~55 ~87 ~100 stained_hardened_clay 9 
setblock ~55 ~87 ~101 coal_ore 0 
setblock ~56 ~87 ~33 concrete 7 
setblock ~56 ~87 ~98 wool 7 
setblock ~56 ~87 ~100 wool 7 
setblock ~57 ~87 ~33 wool 7 
setblock ~57 ~87 ~97 stained_hardened_clay 9 
setblock ~57 ~87 ~98 coal_ore 0 
setblock ~57 ~87 ~99 stained_hardened_clay 9  
fill ~58 ~87 ~34 ~59 ~87 ~34 coal_ore 0 
setblock ~58 ~87 ~98 stained_hardened_clay 9 
setblock ~58 ~87 ~99 stonebrick 2 
setblock ~59 ~87 ~35 concrete 8 
setblock ~59 ~87 ~99 wool 7 
setblock ~60 ~87 ~35 stonebrick 2 
setblock ~60 ~87 ~98 stained_hardened_clay 9 
setblock ~61 ~87 ~36 concrete 8 
setblock ~61 ~87 ~96 wool 7  
fill ~61 ~87 ~97 ~61 ~88 ~97 stained_hardened_clay 9  
fill ~62 ~87 ~37 ~63 ~87 ~37 concrete 8 
setblock ~62 ~87 ~95 wool 7 
setblock ~63 ~87 ~94 concrete 7 
setblock ~64 ~87 ~38 stonebrick 2 
setblock ~64 ~87 ~93 wool 7 
setblock ~65 ~87 ~38 coal_ore 0 
setblock ~65 ~87 ~91 wool 7  
fill ~65 ~87 ~92 ~66 ~87 ~92 soul_sand 0 
setblock ~66 ~87 ~38 concrete 8 
setblock ~66 ~87 ~89 soul_sand 0 
setblock ~66 ~87 ~90 wool 7  
fill ~66 ~87 ~91 ~67 ~87 ~91 stained_hardened_clay 9 
setblock ~67 ~87 ~38 coal_ore 0  
fill ~67 ~87 ~89 ~69 ~87 ~89 wool 7 
setblock ~67 ~87 ~90 concrete 7 
setblock ~67 ~87 ~92 coal_ore 0  
fill ~68 ~87 ~38 ~68 ~88 ~38 stained_hardened_clay 9  
fill ~68 ~87 ~41 ~68 ~87 ~43 stonebrick 2 
setblock ~68 ~87 ~44 concrete 8 
setblock ~68 ~87 ~90 stained_hardened_clay 9 
setblock ~69 ~87 ~38 coal_ore 0  
fill ~69 ~87 ~39 ~69 ~87 ~41 stained_hardened_clay 9 
setblock ~69 ~87 ~42 concrete 8 
setblock ~69 ~87 ~43 stonebrick 2 
setblock ~69 ~87 ~44 coal_ore 0 
setblock ~69 ~87 ~45 stained_hardened_clay 9  
fill ~69 ~87 ~46 ~70 ~87 ~46 stonebrick 2 
setblock ~69 ~87 ~47 wool 7 
setblock ~69 ~87 ~48 stained_hardened_clay 9 
setblock ~69 ~87 ~90 wool 7 
setblock ~70 ~87 ~47 coal_ore 0  
fill ~70 ~87 ~48 ~70 ~87 ~50 stonebrick 2  
fill ~70 ~87 ~60 ~71 ~87 ~60 stained_hardened_clay 9  
fill ~70 ~87 ~64 ~71 ~87 ~64 coal_ore 0 
setblock ~70 ~87 ~65 stone 0 
setblock ~70 ~87 ~89 coal_ore 0 
setblock ~70 ~87 ~90 stained_hardened_clay 9 
setblock ~71 ~87 ~49 wool 7 
setblock ~71 ~87 ~50 stained_hardened_clay 9 
setblock ~71 ~87 ~51 stonebrick 2 
setblock ~71 ~87 ~52 coal_ore 0 
setblock ~71 ~87 ~59 stained_hardened_clay 9  
fill ~71 ~87 ~61 ~71 ~87 ~62 wool 7 
setblock ~71 ~87 ~63 stained_hardened_clay 9  
fill ~71 ~87 ~65 ~72 ~87 ~65 concrete 8 
setblock ~71 ~87 ~66 stonebrick 2 
setblock ~71 ~87 ~67 concrete 7  
fill ~71 ~87 ~89 ~72 ~87 ~89 stained_hardened_clay 9 
setblock ~72 ~87 ~52 stained_hardened_clay 9 
setblock ~72 ~87 ~53 coal_ore 0  
fill ~72 ~87 ~54 ~73 ~87 ~54 stained_hardened_clay 9  
fill ~72 ~87 ~55 ~73 ~87 ~55 concrete 7  
fill ~72 ~87 ~58 ~72 ~87 ~59 wool 7 
setblock ~72 ~87 ~66 concrete 7 
setblock ~72 ~87 ~67 coal_ore 0  
fill ~72 ~87 ~68 ~73 ~87 ~68 stained_hardened_clay 9 
setblock ~72 ~87 ~69 coal_ore 0  
fill ~72 ~87 ~70 ~73 ~87 ~70 stained_hardened_clay 9 
setblock ~73 ~87 ~56 concrete 7 
setblock ~73 ~87 ~57 wool 7 
setblock ~73 ~87 ~69 stained_hardened_clay 9 
setblock ~73 ~87 ~71 stonebrick 2  
fill ~73 ~87 ~72 ~73 ~87 ~73 stained_hardened_clay 9 
setblock ~73 ~87 ~88 wool 7 
setblock ~74 ~87 ~71 stained_hardened_clay 9 
setblock ~74 ~87 ~72 coal_ore 0 
setblock ~74 ~87 ~73 wool 7 
setblock ~74 ~87 ~74 stained_hardened_clay 9  
fill ~74 ~87 ~75 ~74 ~87 ~76 coal_ore 0 
setblock ~74 ~87 ~79 stained_hardened_clay 9 
setblock ~74 ~87 ~80 stonebrick 2  
fill ~74 ~87 ~81 ~74 ~87 ~82 coal_ore 0 
setblock ~74 ~87 ~83 wool 7  
fill ~74 ~87 ~84 ~74 ~87 ~85 stained_hardened_clay 9  
fill ~74 ~87 ~86 ~74 ~87 ~87 soul_sand 0 
setblock ~75 ~87 ~73 stained_hardened_clay 9 
setblock ~75 ~87 ~74 concrete 8 
setblock ~75 ~87 ~75 stonebrick 2 
setblock ~75 ~87 ~76 coal_ore 0  
fill ~75 ~87 ~77 ~75 ~87 ~79 stonebrick 2 
setblock ~75 ~87 ~80 coal_ore 0  
fill ~75 ~87 ~81 ~75 ~87 ~83 stained_hardened_clay 9 
setblock ~75 ~87 ~84 coal_ore 0 
setblock ~75 ~87 ~85 stained_hardened_clay 9 
setblock ~76 ~87 ~89 stained_hardened_clay 9  
fill ~77 ~87 ~89 ~77 ~87 ~90 stonebrick 2  
fill ~78 ~87 ~83 ~79 ~87 ~83 stained_hardened_clay 9 
setblock ~78 ~87 ~84 soul_sand 0  
fill ~78 ~87 ~89 ~78 ~87 ~90 coal_ore 0 
setblock ~79 ~87 ~82 stained_hardened_clay 9  
fill ~79 ~87 ~84 ~79 ~87 ~85 stained_hardened_clay 9  
fill ~24 ~88 ~82 ~24 ~88 ~83 coal_ore 0 
setblock ~24 ~88 ~84 concrete 8  
fill ~25 ~88 ~81 ~26 ~88 ~81 stained_hardened_clay 9 
setblock ~25 ~88 ~85 concrete 8 
setblock ~25 ~88 ~86 stained_hardened_clay 9  
fill ~25 ~88 ~89 ~25 ~89 ~89 stained_hardened_clay 9  
fill ~25 ~88 ~90 ~25 ~88 ~91 concrete 8  
fill ~26 ~88 ~82 ~27 ~88 ~82 stained_hardened_clay 9 
setblock ~26 ~88 ~85 stained_hardened_clay 9 
setblock ~26 ~88 ~88 soul_sand 0  
fill ~26 ~88 ~91 ~27 ~88 ~91 coal_ore 0 
setblock ~27 ~88 ~81 concrete 7  
fill ~27 ~88 ~83 ~27 ~88 ~84 stained_hardened_clay 9 
setblock ~27 ~88 ~85 soul_sand 0  
fill ~27 ~88 ~88 ~29 ~88 ~88 stained_hardened_clay 9 
setblock ~28 ~88 ~71 concrete 7  
fill ~28 ~88 ~73 ~28 ~88 ~74 stained_hardened_clay 9 
setblock ~28 ~88 ~75 coal_ore 0 
setblock ~28 ~88 ~76 stained_hardened_clay 9 
setblock ~28 ~88 ~77 coal_ore 0  
fill ~28 ~88 ~78 ~28 ~88 ~79 stained_hardened_clay 9  
fill ~28 ~88 ~80 ~28 ~88 ~82 coal_ore 0 
setblock ~28 ~88 ~83 stonebrick 2  
fill ~28 ~88 ~84 ~28 ~88 ~88 stained_hardened_clay 9  
fill ~28 ~88 ~90 ~28 ~88 ~91 stonebrick 2  
fill ~29 ~88 ~67 ~31 ~88 ~67 stonebrick 2  
fill ~29 ~88 ~68 ~29 ~88 ~69 concrete 8 
setblock ~29 ~88 ~70 stonebrick 2 
setblock ~29 ~88 ~71 stained_hardened_clay 9 
setblock ~29 ~88 ~72 wool 7  
fill ~29 ~88 ~87 ~30 ~88 ~87 stained_hardened_clay 9  
fill ~29 ~88 ~89 ~31 ~88 ~89 stained_hardened_clay 9 
setblock ~29 ~88 ~90 coal_ore 0  
fill ~30 ~88 ~53 ~31 ~88 ~53 coal_ore 0  
fill ~30 ~88 ~54 ~30 ~88 ~56 coal_ore 0 
setblock ~30 ~88 ~57 stonebrick 2 
setblock ~30 ~88 ~65 concrete 8 
setblock ~30 ~88 ~66 coal_ore 0 
setblock ~30 ~88 ~68 coal_ore 0 
setblock ~30 ~88 ~69 stonebrick 2 
setblock ~30 ~88 ~70 coal_ore 0 
setblock ~30 ~88 ~88 wool 7  
fill ~30 ~88 ~90 ~31 ~88 ~90 stained_hardened_clay 9  
fill ~31 ~88 ~51 ~31 ~88 ~52 stained_hardened_clay 9 
setblock ~31 ~88 ~58 stonebrick 2 
setblock ~31 ~88 ~59 stained_hardened_clay 9  
fill ~31 ~88 ~60 ~31 ~88 ~67 stonebrick 2  
fill ~32 ~88 ~48 ~33 ~88 ~48 coal_ore 0  
fill ~32 ~88 ~49 ~33 ~88 ~49 coal_ore 0 
setblock ~32 ~88 ~50 stained_hardened_clay 9 
setblock ~32 ~88 ~51 stonebrick 2 
setblock ~32 ~88 ~60 stained_hardened_clay 9  
fill ~32 ~88 ~61 ~32 ~88 ~62 coal_ore 0 
setblock ~32 ~88 ~64 concrete 8 
setblock ~32 ~88 ~90 concrete 7 
setblock ~32 ~88 ~91 stained_hardened_clay 9  
fill ~33 ~88 ~39 ~34 ~88 ~39 wool 7  
fill ~33 ~88 ~40 ~34 ~88 ~40 stained_hardened_clay 9  
fill ~33 ~88 ~45 ~34 ~88 ~45 coal_ore 0  
fill ~33 ~88 ~46 ~34 ~88 ~46 coal_ore 0 
setblock ~33 ~88 ~47 stained_hardened_clay 9 
setblock ~33 ~88 ~91 coal_ore 0  
fill ~34 ~88 ~41 ~34 ~88 ~44 stained_hardened_clay 9 
setblock ~34 ~88 ~91 stained_hardened_clay 9 
setblock ~34 ~88 ~92 wool 7  
fill ~34 ~88 ~93 ~35 ~88 ~93 stained_hardened_clay 9 
setblock ~35 ~88 ~38 stained_hardened_clay 9 
setblock ~35 ~88 ~91 coal_ore 0 
setblock ~35 ~88 ~92 concrete 7 
setblock ~36 ~88 ~38 wool 7 
setblock ~36 ~88 ~91 wool 7 
setblock ~36 ~88 ~92 stained_hardened_clay 9  
fill ~36 ~88 ~93 ~37 ~88 ~93 wool 7  
fill ~37 ~88 ~38 ~38 ~88 ~38 stained_hardened_clay 9  
fill ~38 ~88 ~93 ~38 ~88 ~94 stained_hardened_clay 9 
setblock ~39 ~88 ~38 coal_ore 0 
setblock ~39 ~88 ~93 concrete 7 
setblock ~39 ~88 ~94 wool 7 
setblock ~40 ~88 ~37 wool 7  
fill ~40 ~88 ~94 ~40 ~88 ~95 stained_hardened_clay 9  
fill ~41 ~88 ~36 ~42 ~88 ~36 stained_hardened_clay 9 
setblock ~41 ~88 ~95 stained_hardened_clay 9 
setblock ~42 ~88 ~96 stained_hardened_clay 9 
setblock ~43 ~88 ~35 coal_ore 0 
setblock ~43 ~88 ~97 stained_hardened_clay 9 
setblock ~43 ~88 ~98 wool 7 
setblock ~44 ~88 ~34 stained_hardened_clay 9 
setblock ~44 ~88 ~99 concrete 7  
fill ~45 ~88 ~34 ~45 ~87 ~34 coal_ore 0 
setblock ~46 ~88 ~33 coal_ore 0 
setblock ~46 ~88 ~99 stained_hardened_clay 9  
fill ~47 ~88 ~32 ~48 ~88 ~32 stained_hardened_clay 9 
setblock ~47 ~88 ~100 coal_ore 0 
setblock ~48 ~88 ~100 wool 7 
setblock ~49 ~88 ~33 coal_ore 0  
fill ~49 ~88 ~101 ~49 ~89 ~101 stained_hardened_clay 9 
setblock ~50 ~88 ~34 stained_hardened_clay 9 
setblock ~50 ~88 ~101 wool 7 
setblock ~51 ~88 ~34 concrete 7  
fill ~51 ~88 ~101 ~51 ~89 ~101 concrete 7 
setblock ~52 ~88 ~35 stained_hardened_clay 9  
fill ~52 ~88 ~101 ~54 ~88 ~101 wool 7 
setblock ~53 ~88 ~34 stained_hardened_clay 9 
setblock ~53 ~88 ~35 concrete 7 
setblock ~54 ~88 ~34 wool 7 
setblock ~55 ~88 ~33 concrete 7  
fill ~55 ~88 ~101 ~55 ~91 ~101 stained_hardened_clay 9 
setblock ~56 ~88 ~32 concrete 7 
setblock ~56 ~88 ~100 soul_sand 0 
setblock ~57 ~88 ~32 wool 7 
setblock ~57 ~88 ~100 wool 7 
setblock ~58 ~88 ~33 stained_hardened_clay 9  
fill ~58 ~88 ~99 ~60 ~88 ~99 stained_hardened_clay 9 
setblock ~59 ~88 ~33 stonebrick 2 
setblock ~60 ~88 ~34 coal_ore 0 
setblock ~61 ~88 ~35 concrete 8  
fill ~61 ~88 ~98 ~61 ~89 ~98 stained_hardened_clay 9 
setblock ~62 ~88 ~36 concrete 8 
setblock ~62 ~88 ~96 soul_sand 0 
setblock ~63 ~88 ~36 stonebrick 2  
fill ~63 ~88 ~95 ~64 ~88 ~95 wool 7  
fill ~64 ~88 ~37 ~65 ~88 ~37 coal_ore 0 
setblock ~64 ~88 ~94 soul_sand 0 
setblock ~65 ~88 ~93 soul_sand 0 
setblock ~65 ~88 ~94 wool 7 
setblock ~66 ~88 ~38 stonebrick 2 
setblock ~66 ~88 ~93 concrete 7 
setblock ~67 ~88 ~38 stained_hardened_clay 9 
setblock ~67 ~88 ~93 stained_hardened_clay 9  
fill ~68 ~88 ~91 ~70 ~88 ~91 stained_hardened_clay 9  
fill ~68 ~88 ~92 ~69 ~88 ~92 stained_hardened_clay 9 
setblock ~68 ~88 ~93 wool 7  
fill ~69 ~88 ~38 ~69 ~89 ~38 stained_hardened_clay 9 
setblock ~69 ~88 ~93 stained_hardened_clay 9  
fill ~70 ~88 ~39 ~70 ~88 ~40 wool 7 
setblock ~70 ~88 ~41 stained_hardened_clay 9 
setblock ~70 ~88 ~42 concrete 7 
setblock ~70 ~88 ~43 stained_hardened_clay 9 
setblock ~70 ~88 ~44 stonebrick 2 
setblock ~70 ~88 ~45 coal_ore 0 
setblock ~70 ~88 ~92 concrete 7 
setblock ~70 ~88 ~93 coal_ore 0 
setblock ~71 ~88 ~40 concrete 7 
setblock ~71 ~88 ~41 wool 7  
fill ~71 ~88 ~45 ~71 ~88 ~46 stained_hardened_clay 9 
setblock ~71 ~88 ~47 wool 7  
fill ~71 ~88 ~48 ~72 ~88 ~48 concrete 7 
setblock ~71 ~88 ~90 stained_hardened_clay 9 
setblock ~71 ~88 ~91 coal_ore 0 
setblock ~72 ~88 ~47 concrete 7 
setblock ~72 ~88 ~49 stained_hardened_clay 9 
setblock ~72 ~88 ~50 concrete 8  
fill ~72 ~88 ~51 ~73 ~88 ~51 coal_ore 0 
setblock ~72 ~88 ~60 wool 7 
setblock ~72 ~88 ~61 coal_ore 0 
setblock ~72 ~88 ~62 stonebrick 2 
setblock ~72 ~88 ~63 stained_hardened_clay 9 
setblock ~72 ~88 ~64 coal_ore 0  
fill ~72 ~88 ~90 ~73 ~88 ~90 concrete 7 
setblock ~72 ~88 ~91 stained_hardened_clay 9 
setblock ~73 ~88 ~50 coal_ore 0  
fill ~73 ~88 ~52 ~73 ~88 ~53 coal_ore 0 
setblock ~73 ~88 ~58 concrete 7 
setblock ~73 ~88 ~59 stained_hardened_clay 9 
setblock ~73 ~88 ~60 coal_ore 0 
setblock ~73 ~88 ~61 stonebrick 2  
fill ~73 ~88 ~62 ~73 ~88 ~66 concrete 8 
setblock ~73 ~88 ~67 concrete 7 
setblock ~73 ~88 ~89 concrete 7 
setblock ~74 ~88 ~53 stained_hardened_clay 9  
fill ~74 ~88 ~54 ~74 ~88 ~55 concrete 7  
fill ~74 ~88 ~56 ~74 ~88 ~57 wool 7 
setblock ~74 ~88 ~65 concrete 8 
setblock ~74 ~88 ~66 stonebrick 2 
setblock ~74 ~88 ~67 coal_ore 0  
fill ~74 ~88 ~68 ~75 ~88 ~68 stained_hardened_clay 9  
fill ~74 ~88 ~69 ~75 ~88 ~69 wool 7  
fill ~74 ~88 ~70 ~75 ~88 ~70 stained_hardened_clay 9 
setblock ~74 ~88 ~88 soul_sand 0  
fill ~74 ~88 ~89 ~74 ~88 ~90 wool 7 
setblock ~75 ~88 ~67 concrete 8 
setblock ~75 ~88 ~71 stained_hardened_clay 9 
setblock ~75 ~88 ~72 coal_ore 0 
setblock ~75 ~88 ~86 stained_hardened_clay 9  
fill ~75 ~88 ~87 ~75 ~88 ~88 wool 7 
setblock ~75 ~88 ~89 soul_sand 0  
fill ~75 ~88 ~90 ~76 ~88 ~90 stained_hardened_clay 9  
fill ~76 ~88 ~72 ~76 ~88 ~75 stained_hardened_clay 9 
setblock ~76 ~88 ~76 concrete 8  
fill ~76 ~88 ~77 ~76 ~88 ~79 coal_ore 0  
fill ~76 ~88 ~80 ~77 ~88 ~80 stained_hardened_clay 9  
fill ~76 ~88 ~81 ~76 ~88 ~80 stained_hardened_clay 9 
setblock ~76 ~88 ~82 wool 7 
setblock ~76 ~88 ~83 stained_hardened_clay 9  
fill ~76 ~88 ~84 ~77 ~88 ~84 soul_sand 0  
fill ~76 ~88 ~85 ~76 ~88 ~86 wool 7 
setblock ~76 ~88 ~87 concrete 7  
fill ~76 ~88 ~88 ~77 ~88 ~88 wool 7  
fill ~77 ~88 ~81 ~77 ~88 ~85 soul_sand 0  
fill ~77 ~88 ~91 ~78 ~88 ~91 stained_hardened_clay 9  
fill ~78 ~88 ~81 ~79 ~88 ~81 stained_hardened_clay 9  
fill ~78 ~88 ~82 ~78 ~88 ~81 stained_hardened_clay 9 
setblock ~78 ~88 ~85 wool 7 
setblock ~78 ~88 ~88 stained_hardened_clay 9 
setblock ~79 ~88 ~85 stained_hardened_clay 9 
setblock ~79 ~88 ~89 stained_hardened_clay 9  
fill ~79 ~88 ~90 ~79 ~89 ~90 coal_ore 0  
fill ~79 ~88 ~91 ~79 ~88 ~90 coal_ore 0  
fill ~80 ~88 ~82 ~80 ~89 ~82 stained_hardened_clay 9  
fill ~80 ~88 ~83 ~80 ~89 ~83 stained_hardened_clay 9  
fill ~80 ~88 ~84 ~80 ~90 ~84 stained_hardened_clay 9  
fill ~24 ~89 ~81 ~24 ~89 ~82 stained_hardened_clay 9 
setblock ~24 ~89 ~83 log2 0 
setblock ~24 ~89 ~84 stained_hardened_clay 9 
setblock ~24 ~89 ~85 concrete 8  
fill ~25 ~89 ~80 ~26 ~89 ~80 stained_hardened_clay 9 
setblock ~25 ~89 ~86 log2 0 
setblock ~25 ~89 ~90 log2 0 
setblock ~25 ~89 ~91 stained_hardened_clay 9 
setblock ~26 ~89 ~79 soul_sand 0 
setblock ~26 ~89 ~86 wool 7  
fill ~26 ~89 ~87 ~27 ~89 ~87 stained_hardened_clay 9  
fill ~26 ~89 ~88 ~26 ~90 ~88 wool 7 
setblock ~26 ~89 ~92 concrete 8 
setblock ~27 ~89 ~73 wool 7 
setblock ~27 ~89 ~74 coal_ore 0  
fill ~27 ~89 ~75 ~27 ~89 ~77 stained_hardened_clay 9 
setblock ~27 ~89 ~78 coal_ore 0 
setblock ~27 ~89 ~79 stained_hardened_clay 9 
setblock ~27 ~89 ~80 coal_ore 0 
setblock ~27 ~89 ~86 stained_hardened_clay 9  
fill ~27 ~89 ~92 ~28 ~89 ~92 coal_ore 0  
fill ~28 ~89 ~54 ~29 ~89 ~54 stained_hardened_clay 9  
fill ~28 ~89 ~55 ~29 ~89 ~55 stained_hardened_clay 9  
fill ~28 ~89 ~56 ~28 ~89 ~54 stained_hardened_clay 9  
fill ~28 ~89 ~66 ~29 ~89 ~66 concrete 8  
fill ~28 ~89 ~67 ~28 ~89 ~68 stonebrick 2 
setblock ~28 ~89 ~69 coal_ore 0  
fill ~28 ~89 ~70 ~28 ~89 ~71 stained_hardened_clay 9 
setblock ~28 ~89 ~72 concrete 7 
setblock ~28 ~89 ~91 stained_hardened_clay 9  
fill ~29 ~89 ~52 ~30 ~89 ~52 stained_hardened_clay 9 
setblock ~29 ~89 ~53 coal_ore 0  
fill ~29 ~89 ~56 ~29 ~89 ~58 coal_ore 0 
setblock ~29 ~89 ~63 coal_ore 0  
fill ~29 ~89 ~64 ~30 ~89 ~64 stonebrick 2 
setblock ~29 ~89 ~65 concrete 8 
setblock ~29 ~89 ~91 coal_ore 0  
fill ~30 ~89 ~48 ~31 ~89 ~48 stained_hardened_clay 9  
fill ~30 ~89 ~49 ~30 ~89 ~48 stained_hardened_clay 9  
fill ~30 ~89 ~50 ~30 ~89 ~51 coal_ore 0 
setblock ~30 ~89 ~58 coal_ore 0 
setblock ~30 ~89 ~59 stained_hardened_clay 9 
setblock ~30 ~89 ~60 stonebrick 2 
setblock ~30 ~89 ~61 stained_hardened_clay 9 
setblock ~30 ~89 ~62 coal_ore 0 
setblock ~30 ~89 ~63 stonebrick 2  
fill ~30 ~89 ~91 ~30 ~89 ~92 stained_hardened_clay 9 
setblock ~31 ~89 ~39 wool 7  
fill ~31 ~89 ~46 ~32 ~89 ~46 stained_hardened_clay 9  
fill ~31 ~89 ~47 ~31 ~89 ~46 stained_hardened_clay 9 
setblock ~31 ~89 ~49 concrete 7 
setblock ~31 ~89 ~50 wool 7 
setblock ~31 ~89 ~91 coal_ore 0  
fill ~31 ~89 ~92 ~33 ~89 ~92 stained_hardened_clay 9 
setblock ~32 ~89 ~39 concrete 7  
fill ~32 ~89 ~40 ~32 ~89 ~41 stained_hardened_clay 9  
fill ~32 ~89 ~42 ~32 ~89 ~43 wool 7  
fill ~32 ~89 ~44 ~32 ~89 ~45 coal_ore 0 
setblock ~32 ~89 ~47 coal_ore 0 
setblock ~32 ~89 ~93 coal_ore 0  
fill ~33 ~89 ~39 ~33 ~88 ~39 wool 7 
setblock ~33 ~89 ~41 wool 7 
setblock ~33 ~89 ~42 stained_hardened_clay 9 
setblock ~33 ~89 ~43 wool 7 
setblock ~33 ~89 ~44 stained_hardened_clay 9  
fill ~33 ~89 ~93 ~34 ~89 ~93 stained_hardened_clay 9 
setblock ~34 ~89 ~38 wool 7  
fill ~35 ~89 ~38 ~35 ~90 ~38 concrete 7  
fill ~35 ~89 ~94 ~37 ~89 ~94 stained_hardened_clay 9 
setblock ~36 ~89 ~38 soul_sand 0 
setblock ~37 ~89 ~38 wool 7 
setblock ~38 ~89 ~37 coal_ore 0 
setblock ~38 ~89 ~95 wool 7 
setblock ~39 ~89 ~37 stained_hardened_clay 9 
setblock ~39 ~89 ~95 stained_hardened_clay 9 
setblock ~40 ~89 ~36 stained_hardened_clay 9 
setblock ~40 ~89 ~96 stained_hardened_clay 9 
setblock ~41 ~89 ~35 stained_hardened_clay 9 
setblock ~41 ~89 ~96 concrete 7 
setblock ~42 ~89 ~35 stonebrick 2 
setblock ~42 ~89 ~97 concrete 7 
setblock ~43 ~89 ~34 coal_ore 0 
setblock ~43 ~89 ~98 stained_hardened_clay 9 
setblock ~44 ~89 ~33 stained_hardened_clay 9 
setblock ~44 ~89 ~99 stained_hardened_clay 9  
fill ~45 ~89 ~32 ~47 ~89 ~32 stained_hardened_clay 9 
setblock ~45 ~89 ~33 stonebrick 2 
setblock ~46 ~89 ~100 coal_ore 0  
fill ~47 ~89 ~100 ~47 ~90 ~100 stained_hardened_clay 9 
setblock ~48 ~89 ~32 coal_ore 0 
setblock ~48 ~89 ~100 soul_sand 0 
setblock ~49 ~89 ~32 stained_hardened_clay 9 
setblock ~50 ~89 ~33 concrete 7 
setblock ~50 ~89 ~101 stained_hardened_clay 9 
setblock ~51 ~89 ~33 stained_hardened_clay 7  
fill ~51 ~89 ~34 ~52 ~89 ~34 stained_hardened_clay 9  
fill ~52 ~89 ~33 ~53 ~89 ~33 concrete 7 
setblock ~52 ~89 ~101 stained_hardened_clay 9 
setblock ~53 ~89 ~34 wool 7  
fill ~53 ~89 ~101 ~53 ~90 ~101 wool 7 
setblock ~54 ~89 ~33 stained_hardened_clay 7 
setblock ~54 ~89 ~101 stained_hardened_clay 9  
fill ~55 ~89 ~32 ~56 ~89 ~32 wool 7 
setblock ~56 ~89 ~100 concrete 7  
fill ~57 ~89 ~31 ~57 ~91 ~31 stained_hardened_clay 9  
fill ~57 ~89 ~100 ~57 ~90 ~100 stained_hardened_clay 9 
setblock ~58 ~89 ~32 stained_hardened_clay 9  
fill ~58 ~89 ~100 ~58 ~90 ~100 coal_ore 0 
setblock ~59 ~89 ~32 stonebrick 2 
setblock ~59 ~89 ~99 coal_ore 0 
setblock ~60 ~89 ~33 stonebrick 2  
fill ~60 ~89 ~99 ~60 ~90 ~99 stained_hardened_clay 9 
setblock ~61 ~89 ~34 stonebrick 2 
setblock ~62 ~89 ~35 stained_hardened_clay 9 
setblock ~62 ~89 ~97 stained_hardened_clay 9 
setblock ~63 ~89 ~35 stonebrick 2 
setblock ~63 ~89 ~96 concrete 7 
setblock ~64 ~89 ~36 stonebrick 2 
setblock ~64 ~89 ~96 soul_sand 0  
fill ~65 ~89 ~37 ~66 ~89 ~37 coal_ore 0  
fill ~65 ~89 ~95 ~66 ~89 ~95 stained_hardened_clay 9  
fill ~66 ~89 ~94 ~68 ~89 ~94 stained_hardened_clay 9 
setblock ~67 ~89 ~38 coal_ore 0  
fill ~68 ~89 ~38 ~68 ~90 ~38 wool 7 
setblock ~69 ~89 ~94 coal_ore 0  
fill ~70 ~89 ~38 ~70 ~90 ~38 stained_hardened_clay 9 
setblock ~70 ~89 ~93 concrete 7  
fill ~70 ~89 ~94 ~70 ~90 ~94 stained_hardened_clay 9 
setblock ~71 ~89 ~39 stained_hardened_clay 9  
fill ~71 ~89 ~42 ~71 ~89 ~43 wool 7  
fill ~71 ~89 ~44 ~72 ~89 ~44 stained_hardened_clay 9  
fill ~71 ~89 ~92 ~71 ~89 ~93 wool 7 
setblock ~72 ~89 ~40 stained_hardened_clay 9 
setblock ~72 ~89 ~41 wool 7 
setblock ~72 ~89 ~42 concrete 7 
setblock ~72 ~89 ~43 wool 7  
fill ~72 ~89 ~45 ~72 ~89 ~46 coal_ore 0  
fill ~72 ~89 ~92 ~73 ~89 ~92 stained_hardened_clay 9 
setblock ~73 ~89 ~46 stonebrick 2 
setblock ~73 ~89 ~47 wool 7  
fill ~73 ~89 ~48 ~73 ~89 ~49 concrete 7  
fill ~73 ~89 ~91 ~76 ~89 ~91 stained_hardened_clay 9 
setblock ~74 ~89 ~48 wool 7  
fill ~74 ~89 ~49 ~74 ~89 ~50 concrete 7 
setblock ~74 ~89 ~51 stained_hardened_clay 9  
fill ~74 ~89 ~52 ~75 ~89 ~52 coal_ore 0 
setblock ~74 ~89 ~58 wool 7 
setblock ~74 ~89 ~59 stained_hardened_clay 9  
fill ~74 ~89 ~60 ~74 ~89 ~61 coal_ore 0 
setblock ~74 ~89 ~62 concrete 8  
fill ~74 ~89 ~63 ~75 ~89 ~63 coal_ore 0 
setblock ~74 ~89 ~64 stone 0 
setblock ~75 ~89 ~51 coal_ore 0 
setblock ~75 ~89 ~53 coal_ore 0  
fill ~75 ~89 ~54 ~75 ~89 ~56 concrete 7 
setblock ~75 ~89 ~57 wool 7 
setblock ~75 ~89 ~58 concrete 7 
setblock ~75 ~89 ~64 coal_ore 0  
fill ~75 ~89 ~65 ~75 ~89 ~66 concrete 8 
setblock ~76 ~89 ~55 coal_ore 0 
setblock ~76 ~89 ~56 wool 7 
setblock ~76 ~89 ~66 stone 0 
setblock ~76 ~89 ~67 concrete 8 
setblock ~76 ~89 ~68 coal_ore 0 
setblock ~76 ~89 ~69 stained_hardened_clay 9 
setblock ~76 ~89 ~70 coal_ore 0 
setblock ~76 ~89 ~71 wool 7 
setblock ~77 ~89 ~72 concrete 7 
setblock ~77 ~89 ~73 wool 7  
fill ~77 ~89 ~74 ~77 ~89 ~75 stained_hardened_clay 9 
setblock ~77 ~89 ~76 stonebrick 2 
setblock ~77 ~89 ~77 concrete 8  
fill ~77 ~89 ~78 ~77 ~89 ~79 stained_hardened_clay 9  
fill ~77 ~89 ~86 ~78 ~89 ~86 soul_sand 0  
fill ~77 ~89 ~87 ~77 ~89 ~86 soul_sand 0  
fill ~77 ~89 ~92 ~77 ~90 ~92 stained_hardened_clay 9 
setblock ~78 ~89 ~79 wool 7  
fill ~78 ~89 ~80 ~79 ~89 ~80 stained_hardened_clay 9 
setblock ~78 ~89 ~88 wool 7 
setblock ~78 ~89 ~92 coal_ore 0 
setblock ~79 ~89 ~86 wool 7 
setblock ~79 ~89 ~89 soul_sand 0  
fill ~79 ~89 ~91 ~79 ~90 ~91 wool 7 
setblock ~80 ~89 ~81 stained_hardened_clay 9  
fill ~80 ~89 ~85 ~80 ~90 ~85 stained_hardened_clay 9 
setblock ~24 ~90 ~80 stained_hardened_clay 9 
setblock ~24 ~90 ~81 wool 7  
fill ~24 ~90 ~82 ~24 ~90 ~83 stained_hardened_clay 9 
setblock ~24 ~90 ~84 concrete 8  
fill ~24 ~90 ~85 ~24 ~91 ~85 coal_ore 0 
setblock ~24 ~90 ~86 stonebrick 2 
setblock ~25 ~90 ~79 concrete 7 
setblock ~25 ~90 ~86 concrete 7  
fill ~25 ~90 ~89 ~25 ~91 ~89 wool 7 
setblock ~25 ~90 ~90 stained_hardened_clay 9  
fill ~26 ~90 ~52 ~28 ~90 ~52 coal_ore 0 
setblock ~26 ~90 ~53 stonebrick 2 
setblock ~26 ~90 ~73 stained_hardened_clay 9 
setblock ~26 ~90 ~74 coal_ore 0 
setblock ~26 ~90 ~75 wool 7  
fill ~26 ~90 ~76 ~26 ~90 ~77 concrete 7 
setblock ~26 ~90 ~78 stained_hardened_clay 9 
setblock ~26 ~90 ~87 concrete 7  
fill ~26 ~90 ~91 ~26 ~90 ~92 stained_hardened_clay 9 
setblock ~27 ~90 ~51 coal_ore 0 
setblock ~27 ~90 ~53 stained_hardened_clay 9 
setblock ~27 ~90 ~54 coal_ore 0  
fill ~27 ~90 ~55 ~27 ~90 ~56 stained_hardened_clay 9  
fill ~27 ~90 ~67 ~27 ~91 ~67 coal_ore 0  
fill ~27 ~90 ~68 ~27 ~91 ~68 coal_ore 0  
fill ~27 ~90 ~69 ~27 ~90 ~72 stained_hardened_clay 9 
setblock ~27 ~90 ~93 concrete 8 
setblock ~28 ~90 ~50 wool 7 
setblock ~28 ~90 ~51 stained_hardened_clay 9 
setblock ~28 ~90 ~53 coal_ore 0 
setblock ~28 ~90 ~57 coal_ore 0 
setblock ~28 ~90 ~58 stonebrick 2  
fill ~28 ~90 ~59 ~29 ~90 ~59 coal_ore 0 
setblock ~28 ~90 ~60 stained_hardened_clay 9 
setblock ~28 ~90 ~61 stonebrick 2  
fill ~28 ~90 ~62 ~29 ~90 ~62 stained_hardened_clay 9 
setblock ~28 ~90 ~63 stonebrick 2 
setblock ~28 ~90 ~64 concrete 8 
setblock ~28 ~90 ~65 stonebrick 2 
setblock ~28 ~90 ~66 stained_hardened_clay 9  
fill ~28 ~90 ~93 ~30 ~90 ~93 coal_ore 0 
setblock ~29 ~90 ~46 stonebrick 2  
fill ~29 ~90 ~47 ~30 ~90 ~47 coal_ore 0 
setblock ~29 ~90 ~48 concrete 8 
setblock ~29 ~90 ~49 stonebrick 2 
setblock ~29 ~90 ~50 stained_hardened_clay 9 
setblock ~29 ~90 ~51 coal_ore 0  
fill ~29 ~90 ~60 ~29 ~90 ~61 coal_ore 0 
setblock ~29 ~90 ~92 stonebrick 2 
setblock ~30 ~90 ~40 wool 7  
fill ~30 ~90 ~41 ~30 ~90 ~43 stained_hardened_clay 9  
fill ~30 ~90 ~44 ~31 ~90 ~44 coal_ore 0 
setblock ~30 ~90 ~45 stained_hardened_clay 9 
setblock ~30 ~90 ~46 coal_ore 0  
fill ~31 ~90 ~39 ~31 ~91 ~39 stained_hardened_clay 9 
setblock ~31 ~90 ~40 concrete 7  
fill ~31 ~90 ~41 ~31 ~90 ~42 coal_ore 0 
setblock ~31 ~90 ~43 stained_hardened_clay 9 
setblock ~31 ~90 ~45 coal_ore 0 
setblock ~31 ~90 ~93 stained_hardened_clay 9 
setblock ~32 ~90 ~39 wool 7  
fill ~32 ~90 ~94 ~33 ~90 ~94 coal_ore 0 
setblock ~33 ~90 ~38 stained_hardened_clay 7 
setblock ~33 ~90 ~95 stained_hardened_clay 9 
setblock ~34 ~90 ~38 concrete 7 
setblock ~34 ~90 ~94 stained_hardened_clay 9 
setblock ~35 ~90 ~95 wool 7 
setblock ~36 ~90 ~38 stained_hardened_clay 9 
setblock ~36 ~90 ~95 stained_hardened_clay 9 
setblock ~36 ~90 ~96 wool 7 
setblock ~36 ~90 ~98 stained_hardened_clay 9 
setblock ~37 ~90 ~37 wool 7  
fill ~37 ~90 ~95 ~37 ~90 ~96 concrete 7 
setblock ~37 ~90 ~99 wool 7 
setblock ~38 ~90 ~37 stained_hardened_clay 9 
setblock ~38 ~90 ~96 stonebrick 2 
setblock ~38 ~90 ~97 stained_hardened_clay 7 
setblock ~39 ~90 ~36 wool 7 
setblock ~39 ~90 ~96 coal_ore 0 
setblock ~39 ~90 ~97 stained_hardened_clay 9 
setblock ~40 ~90 ~35 concrete 7  
fill ~40 ~90 ~97 ~41 ~90 ~97 wool 7 
setblock ~41 ~90 ~34 stained_hardened_clay 9 
setblock ~42 ~90 ~34 coal_ore 0 
setblock ~42 ~90 ~98 coal_ore 0 
setblock ~43 ~90 ~33 stained_hardened_clay 9 
setblock ~43 ~90 ~99 wool 7 
setblock ~44 ~90 ~32 wool 7 
setblock ~44 ~90 ~99 coal_ore 0  
fill ~45 ~90 ~31 ~47 ~90 ~31 stained_hardened_clay 9 
setblock ~45 ~90 ~100 stonebrick 2 
setblock ~46 ~90 ~100 concrete 8 
setblock ~48 ~90 ~31 wool 7 
setblock ~48 ~90 ~100 concrete 7  
fill ~49 ~90 ~32 ~50 ~90 ~32 concrete 7  
fill ~49 ~90 ~101 ~50 ~90 ~101 concrete 7  
fill ~51 ~90 ~32 ~52 ~90 ~32 stained_hardened_clay 9 
setblock ~51 ~90 ~101 stained_hardened_clay 9 
setblock ~52 ~90 ~101 wool 7  
fill ~53 ~90 ~32 ~54 ~90 ~32 wool 7  
fill ~54 ~90 ~101 ~54 ~91 ~101 wool 7 
setblock ~55 ~90 ~32 concrete 7  
fill ~56 ~90 ~31 ~56 ~91 ~31 concrete 7 
setblock ~56 ~90 ~100 stained_hardened_clay 7 
setblock ~58 ~90 ~31 stonebrick 2 
setblock ~59 ~90 ~31 wool 7 
setblock ~59 ~90 ~100 coal_ore 0  
fill ~60 ~90 ~32 ~61 ~90 ~32 stained_hardened_clay 9 
setblock ~61 ~90 ~33 stained_hardened_clay 9 
setblock ~61 ~90 ~99 stained_hardened_clay 9 
setblock ~62 ~90 ~33 concrete 7 
setblock ~62 ~90 ~34 stained_hardened_clay 9 
setblock ~62 ~90 ~98 stained_hardened_clay 9 
setblock ~63 ~90 ~34 stonebrick 2 
setblock ~63 ~90 ~97 stained_hardened_clay 9 
setblock ~64 ~90 ~35 concrete 8  
fill ~64 ~90 ~97 ~65 ~90 ~97 wool 7 
setblock ~65 ~90 ~36 coal_ore 0  
fill ~65 ~90 ~96 ~66 ~90 ~96 stained_hardened_clay 9  
fill ~66 ~90 ~36 ~66 ~91 ~36 stained_hardened_clay 9 
setblock ~66 ~90 ~97 concrete 7 
setblock ~67 ~90 ~37 stained_hardened_clay 9  
fill ~67 ~90 ~95 ~67 ~90 ~96 wool 7 
setblock ~68 ~90 ~95 stained_hardened_clay 9 
setblock ~69 ~90 ~38 wool 7  
fill ~69 ~90 ~95 ~69 ~91 ~95 wool 7  
fill ~71 ~90 ~38 ~71 ~91 ~38 stained_hardened_clay 9 
setblock ~71 ~90 ~94 stained_hardened_clay 9 
setblock ~72 ~90 ~39 stained_hardened_clay 9 
setblock ~72 ~90 ~93 stained_hardened_clay 9 
setblock ~72 ~90 ~94 coal_ore 0 
setblock ~73 ~90 ~39 coal_ore 0  
fill ~73 ~90 ~40 ~74 ~90 ~40 stained_hardened_clay 9  
fill ~73 ~90 ~41 ~74 ~90 ~41 stained_hardened_clay 9  
fill ~73 ~90 ~42 ~73 ~90 ~45 stained_hardened_clay 9 
setblock ~73 ~90 ~93 stonebrick 2  
fill ~74 ~90 ~42 ~74 ~90 ~43 wool 7 
setblock ~74 ~90 ~44 stained_hardened_clay 9  
fill ~74 ~90 ~45 ~74 ~90 ~46 coal_ore 0  
fill ~74 ~90 ~47 ~75 ~90 ~47 stained_hardened_clay 9 
setblock ~74 ~90 ~92 soul_sand 0  
fill ~74 ~90 ~93 ~74 ~91 ~93 stained_hardened_clay 9 
setblock ~75 ~90 ~46 coal_ore 0 
setblock ~75 ~90 ~48 coal_ore 0  
fill ~75 ~90 ~49 ~76 ~90 ~49 stonebrick 2 
setblock ~75 ~90 ~50 coal_ore 0  
fill ~75 ~90 ~59 ~76 ~90 ~59 stained_hardened_clay 9  
fill ~75 ~90 ~60 ~76 ~90 ~60 coal_ore 0  
fill ~75 ~90 ~61 ~76 ~90 ~61 coal_ore 0  
fill ~75 ~90 ~62 ~76 ~90 ~62 coal_ore 0 
setblock ~75 ~90 ~92 wool 7  
fill ~76 ~90 ~50 ~76 ~90 ~52 stained_hardened_clay 9  
fill ~76 ~90 ~53 ~78 ~90 ~53 coal_ore 0  
fill ~76 ~90 ~54 ~77 ~90 ~54 coal_ore 0  
fill ~76 ~90 ~57 ~76 ~90 ~58 wool 7 
setblock ~76 ~90 ~63 stained_hardened_clay 9  
fill ~76 ~90 ~64 ~76 ~90 ~65 coal_ore 0 
setblock ~76 ~90 ~92 stained_hardened_clay 9 
setblock ~77 ~90 ~51 stained_hardened_clay 9 
setblock ~77 ~90 ~52 coal_ore 0  
fill ~77 ~90 ~55 ~77 ~90 ~56 coal_ore 0  
fill ~77 ~90 ~66 ~77 ~90 ~67 stained_hardened_clay 9  
fill ~77 ~90 ~68 ~77 ~90 ~71 wool 7 
setblock ~77 ~90 ~72 coal_ore 0 
setblock ~78 ~90 ~52 stained_hardened_clay 9 
setblock ~78 ~90 ~54 stonebrick 2 
setblock ~78 ~90 ~73 concrete 7 
setblock ~78 ~90 ~74 stained_hardened_clay 9 
setblock ~78 ~90 ~75 wool 7  
fill ~78 ~90 ~76 ~78 ~90 ~77 coal_ore 0 
setblock ~78 ~90 ~78 stained_hardened_clay 9 
setblock ~78 ~90 ~87 stained_hardened_clay 7 
setblock ~78 ~90 ~88 soul_sand 0 
setblock ~78 ~90 ~92 stained_hardened_clay 9 
setblock ~79 ~90 ~79 soul_sand 0 
setblock ~79 ~90 ~86 stained_hardened_clay 9 
setblock ~79 ~90 ~89 stained_hardened_clay 7  
fill ~79 ~90 ~90 ~79 ~91 ~90 concrete 7 
setblock ~80 ~90 ~80 stained_hardened_clay 9 
setblock ~80 ~90 ~81 wool 7 
setblock ~80 ~90 ~83 wool 7 
setblock ~81 ~90 ~82 stained_hardened_clay 9  
fill ~23 ~91 ~81 ~23 ~91 ~82 wool 7 
setblock ~23 ~91 ~83 stained_hardened_clay 9 
setblock ~23 ~91 ~84 coal_ore 0 
setblock ~24 ~91 ~79 concrete 7 
setblock ~24 ~91 ~80 wool 7 
setblock ~24 ~91 ~86 stained_hardened_clay 9 
setblock ~25 ~91 ~49 stained_hardened_clay 9 
setblock ~25 ~91 ~50 stonebrick 2  
fill ~25 ~91 ~51 ~25 ~91 ~53 stained_hardened_clay 9 
setblock ~25 ~91 ~74 coal_ore 0  
fill ~25 ~91 ~75 ~25 ~91 ~76 stained_hardened_clay 9 
setblock ~25 ~91 ~77 coal_ore 0 
setblock ~25 ~91 ~78 wool 7 
setblock ~25 ~91 ~87 wool 7 
setblock ~25 ~91 ~88 stained_hardened_clay 9 
setblock ~25 ~91 ~90 concrete 7  
fill ~26 ~91 ~48 ~26 ~91 ~51 coal_ore 0  
fill ~26 ~91 ~54 ~26 ~91 ~55 stained_hardened_clay 9  
fill ~26 ~91 ~69 ~26 ~91 ~70 stained_hardened_clay 9 
setblock ~26 ~91 ~71 coal_ore 0 
setblock ~26 ~91 ~72 wool 7 
setblock ~26 ~91 ~73 coal_ore 0 
setblock ~26 ~91 ~91 wool 7 
setblock ~26 ~91 ~92 stained_hardened_clay 9  
fill ~27 ~91 ~43 ~29 ~91 ~43 stained_hardened_clay 9  
fill ~27 ~91 ~48 ~28 ~91 ~48 stained_hardened_clay 9 
setblock ~27 ~91 ~49 coal_ore 0 
setblock ~27 ~91 ~50 stained_hardened_clay 9 
setblock ~27 ~91 ~56 wool 7 
setblock ~27 ~91 ~57 coal_ore 0 
setblock ~27 ~91 ~58 stained_hardened_clay 9  
fill ~27 ~91 ~59 ~27 ~91 ~68 coal_ore 0 
setblock ~27 ~91 ~93 concrete 7  
fill ~28 ~91 ~40 ~30 ~91 ~40 stained_hardened_clay 9  
fill ~28 ~91 ~41 ~29 ~91 ~41 wool 7  
fill ~28 ~91 ~42 ~29 ~91 ~42 wool 7  
fill ~28 ~91 ~44 ~29 ~91 ~44 stained_hardened_clay 9  
fill ~28 ~91 ~45 ~28 ~91 ~43 stained_hardened_clay 9  
fill ~28 ~91 ~46 ~28 ~91 ~47 coal_ore 0 
setblock ~28 ~91 ~49 wool 7  
fill ~28 ~91 ~93 ~28 ~92 ~93 stained_hardened_clay 9 
setblock ~29 ~91 ~45 coal_ore 0 
setblock ~29 ~91 ~93 concrete 8  
fill ~30 ~91 ~39 ~30 ~92 ~39 wool 7 
setblock ~30 ~91 ~94 wool 7 
setblock ~31 ~91 ~94 stained_hardened_clay 9  
fill ~31 ~91 ~95 ~32 ~91 ~95 coal_ore 0  
fill ~32 ~91 ~38 ~32 ~92 ~38 wool 7 
setblock ~32 ~91 ~96 stonebrick 2 
setblock ~33 ~91 ~38 concrete 7 
setblock ~33 ~91 ~96 coal_ore 0  
fill ~33 ~91 ~97 ~35 ~91 ~97 stained_hardened_clay 9
fill ~33 ~91 ~98 ~35 ~91 ~98 stained_hardened_clay 9 
setblock ~34 ~91 ~38 stained_hardened_clay 7 
setblock ~34 ~91 ~95 stained_hardened_clay 9 
setblock ~34 ~91 ~96 wool 7  
fill ~35 ~91 ~37 ~37 ~91 ~37 stained_hardened_clay 7 
setblock ~35 ~91 ~96 concrete 7  
fill ~36 ~91 ~97 ~37 ~91 ~97 wool 7 
setblock ~36 ~91 ~99 stained_hardened_clay 9  
fill ~37 ~91 ~98 ~37 ~91 ~99 soul_sand 0 
setblock ~38 ~91 ~36 wool 7 
setblock ~38 ~91 ~98 wool 7 
setblock ~38 ~91 ~99 stained_hardened_clay 9 
setblock ~38 ~91 ~100 coal_ore 0 
setblock ~39 ~91 ~35 stained_hardened_clay 9 
setblock ~39 ~91 ~98 soul_sand 0 
setblock ~39 ~91 ~99 concrete 7 
setblock ~39 ~91 ~100 stained_hardened_clay 9 
setblock ~40 ~91 ~34 wool 7  
fill ~40 ~91 ~98 ~41 ~91 ~98 stained_hardened_clay 7  
fill ~40 ~91 ~99 ~40 ~91 ~98 stained_hardened_clay 7 
setblock ~41 ~91 ~33 stained_hardened_clay 9 
setblock ~41 ~91 ~99 concrete 7 
setblock ~42 ~91 ~32 wool 7 
setblock ~42 ~91 ~33 stonebrick 2 
setblock ~42 ~91 ~99 stained_hardened_clay 9 
setblock ~43 ~91 ~32 stained_hardened_clay 9 
setblock ~43 ~91 ~99 coal_ore 0 
setblock ~44 ~91 ~31 coal_ore 0 
setblock ~44 ~91 ~100 soul_sand 0  
fill ~45 ~91 ~30 ~46 ~91 ~30 wool 7 
setblock ~45 ~91 ~100 coal_ore 0 
setblock ~46 ~91 ~100 stained_hardened_clay 9 
setblock ~47 ~91 ~31 wool 7 
setblock ~47 ~91 ~100 coal_ore 0 
setblock ~48 ~91 ~31 soul_sand 0 
setblock ~48 ~91 ~101 stained_hardened_clay 9 
setblock ~49 ~91 ~31 stained_hardened_clay 9 
setblock ~49 ~91 ~101 coal_ore 0 
setblock ~50 ~91 ~31 coal_ore 0  
fill ~50 ~91 ~101 ~50 ~93 ~101 concrete 7  
fill ~51 ~91 ~31 ~53 ~91 ~31 stained_hardened_clay 9  
fill ~51 ~91 ~101 ~51 ~92 ~101 stained_hardened_clay 7 
setblock ~52 ~91 ~101 concrete 7 
setblock ~53 ~91 ~101 soul_sand 0  
fill ~54 ~91 ~31 ~55 ~91 ~31 wool 7 
setblock ~56 ~91 ~101 soul_sand 0 
setblock ~57 ~91 ~100 coal_ore 0  
fill ~58 ~91 ~30 ~58 ~92 ~30 wool 7  
fill ~58 ~91 ~100 ~60 ~91 ~100 stained_hardened_clay 9 
setblock ~59 ~91 ~30 stained_hardened_clay 9  
fill ~60 ~91 ~31 ~60 ~92 ~31 stained_hardened_clay 9 
setblock ~61 ~91 ~31 coal_ore 0 
setblock ~61 ~91 ~99 coal_ore 0 
setblock ~62 ~91 ~32 wool 7 
setblock ~62 ~91 ~99 stained_hardened_clay 9 
setblock ~63 ~91 ~33 stained_hardened_clay 9  
fill ~63 ~91 ~98 ~64 ~91 ~98 stained_hardened_clay 9 
setblock ~63 ~91 ~99 coal_ore 0 
setblock ~64 ~91 ~34 concrete 8  
fill ~64 ~91 ~99 ~68 ~91 ~99 soul_sand 0 
setblock ~65 ~91 ~35 coal_ore 0 
setblock ~65 ~91 ~98 wool 7  
fill ~66 ~91 ~98 ~67 ~91 ~98 concrete 7  
fill ~66 ~91 ~100 ~66 ~92 ~100 stained_hardened_clay 9 
setblock ~67 ~91 ~36 wool 7  
fill ~67 ~91 ~97 ~69 ~91 ~97 concrete 7 
setblock ~68 ~91 ~37 concrete 7 
setblock ~68 ~91 ~96 stained_hardened_clay 7 
setblock ~68 ~91 ~98 soul_sand 0 
setblock ~69 ~91 ~37 stained_hardened_clay 9 
setblock ~69 ~91 ~96 concrete 7 
setblock ~69 ~91 ~98 stained_hardened_clay 9 
setblock ~70 ~91 ~38 wool 7 
setblock ~70 ~91 ~95 soul_sand 0  
fill ~70 ~91 ~96 ~72 ~91 ~96 stained_hardened_clay 9  
fill ~70 ~91 ~97 ~70 ~91 ~96 stained_hardened_clay 9  
fill ~71 ~91 ~95 ~73 ~91 ~95 stained_hardened_clay 9 
setblock ~71 ~91 ~97 wool 7 
setblock ~72 ~91 ~38 wool 7  
fill ~73 ~91 ~39 ~74 ~91 ~39 stained_hardened_clay 9 
setblock ~73 ~91 ~94 wool 7 
setblock ~75 ~91 ~40 coal_ore 0  
fill ~75 ~91 ~41 ~76 ~91 ~41 stained_hardened_clay 9  
fill ~75 ~91 ~42 ~77 ~91 ~42 stained_hardened_clay 9  
fill ~75 ~91 ~43 ~75 ~91 ~44 stained_hardened_clay 9 
setblock ~75 ~91 ~45 coal_ore 0  
fill ~75 ~91 ~93 ~76 ~91 ~93 stained_hardened_clay 9  
fill ~76 ~91 ~43 ~77 ~91 ~43 wool 7 
setblock ~76 ~91 ~44 stained_hardened_clay 9 
setblock ~76 ~91 ~45 stonebrick 2 
setblock ~76 ~91 ~46 coal_ore 0  
fill ~76 ~91 ~47 ~76 ~91 ~48 stonebrick 2 
setblock ~77 ~91 ~45 coal_ore 0 
setblock ~77 ~91 ~47 coal_ore 0 
setblock ~77 ~91 ~48 stained_hardened_clay 9  
fill ~77 ~91 ~49 ~78 ~91 ~49 coal_ore 0  
fill ~77 ~91 ~50 ~78 ~91 ~50 coal_ore 0 
setblock ~77 ~91 ~56 wool 7 
setblock ~77 ~91 ~57 stained_hardened_clay 9  
fill ~77 ~91 ~58 ~77 ~91 ~61 coal_ore 0 
setblock ~77 ~91 ~62 stained_hardened_clay 9 
setblock ~77 ~91 ~63 coal_ore 0 
setblock ~77 ~91 ~64 stained_hardened_clay 9  
fill ~77 ~91 ~65 ~77 ~91 ~66 coal_ore 0 
setblock ~77 ~91 ~67 wool 7  
fill ~77 ~91 ~93 ~77 ~92 ~93 concrete 7 
setblock ~78 ~91 ~48 coal_ore 0 
setblock ~78 ~91 ~51 coal_ore 0 
setblock ~78 ~91 ~54 coal_ore 0 
setblock ~78 ~91 ~55 stained_hardened_clay 9 
setblock ~78 ~91 ~67 stained_hardened_clay 9 
setblock ~78 ~91 ~68 concrete 7  
fill ~78 ~91 ~69 ~78 ~91 ~71 stained_hardened_clay 9 
setblock ~78 ~91 ~72 wool 7  
fill ~78 ~91 ~91 ~78 ~91 ~92 concrete 7  
fill ~79 ~91 ~49 ~79 ~91 ~53 stained_hardened_clay 9 
setblock ~79 ~91 ~73 concrete 7 
