fill ~42 ~0 ~2 ~42 ~1 ~2 stained_hardened_clay 9  
fill ~47 ~0 ~1 ~47 ~1 ~1 stained_hardened_clay 15  
fill ~52 ~0 ~2 ~52 ~1 ~2 stained_hardened_clay 9  
fill ~33 ~1 ~4 ~34 ~1 ~4 stained_hardened_clay 9 
setblock ~35 ~1 ~4 concrete 8 
setblock ~36 ~1 ~3 concrete 8 
setblock ~37 ~1 ~3 wool 8  
fill ~38 ~1 ~3 ~39 ~1 ~3 concrete 8 
setblock ~40 ~1 ~3 stained_hardened_clay 9 
setblock ~41 ~1 ~2 stained_hardened_clay 9 
setblock ~43 ~1 ~2 concrete 7  
fill ~44 ~1 ~2 ~46 ~1 ~2 stained_hardened_clay 15  
fill ~48 ~1 ~2 ~50 ~1 ~2 stained_hardened_clay 15 
setblock ~51 ~1 ~2 concrete 7 
setblock ~53 ~1 ~2 stained_hardened_clay 9 
setblock ~54 ~1 ~3 stained_hardened_clay 9  
fill ~55 ~1 ~3 ~56 ~1 ~3 concrete 8 
setblock ~57 ~1 ~3 wool 8 
setblock ~58 ~1 ~3 concrete 8 
setblock ~59 ~1 ~4 concrete 8  
fill ~60 ~1 ~4 ~61 ~1 ~4 stained_hardened_clay 9  
fill ~22 ~2 ~34 ~22 ~3 ~34 concrete 15  
fill ~24 ~2 ~61 ~25 ~2 ~61 concrete 15  
fill ~25 ~2 ~29 ~25 ~3 ~29 concrete 15  
fill ~26 ~2 ~6 ~27 ~2 ~6 concrete 15 
setblock ~26 ~2 ~27 concrete 15  
fill ~26 ~2 ~62 ~26 ~3 ~62 concrete 15  
fill ~27 ~2 ~25 ~28 ~2 ~25 concrete 15  
fill ~27 ~2 ~26 ~27 ~3 ~26 concrete 15  
fill ~27 ~2 ~63 ~27 ~3 ~63 concrete 15 
setblock ~28 ~2 ~5 stained_hardened_clay 15  
fill ~28 ~2 ~64 ~30 ~2 ~64 concrete 15 
setblock ~29 ~2 ~5 stained_hardened_clay 11  
fill ~29 ~2 ~24 ~32 ~2 ~24 concrete 15 
setblock ~30 ~2 ~5 stained_hardened_clay 9 
setblock ~31 ~2 ~5 concrete 7  
fill ~31 ~2 ~65 ~33 ~2 ~65 concrete 15 
setblock ~32 ~2 ~5 stained_hardened_clay 7 
setblock ~33 ~2 ~4 stained_hardened_clay 15  
fill ~33 ~2 ~23 ~35 ~2 ~23 concrete 15 
setblock ~34 ~2 ~4 concrete 7  
fill ~34 ~2 ~66 ~36 ~2 ~66 concrete 15 
setblock ~35 ~2 ~4 stained_hardened_clay 9 
setblock ~36 ~2 ~4 stained_hardened_clay 11  
fill ~36 ~2 ~22 ~38 ~2 ~22 concrete 15 
setblock ~37 ~2 ~4 concrete 7  
fill ~37 ~2 ~67 ~40 ~2 ~67 concrete 15 
setblock ~38 ~2 ~4 stained_hardened_clay 9 
setblock ~39 ~2 ~3 concrete 7 
setblock ~39 ~2 ~22 stained_hardened_clay 15 
setblock ~40 ~2 ~3 stained_hardened_clay 7  
fill ~40 ~2 ~21 ~42 ~2 ~21 stained_hardened_clay 7  
fill ~41 ~2 ~3 ~43 ~2 ~3 stained_hardened_clay 15  
fill ~41 ~2 ~68 ~43 ~2 ~68 concrete 15 
setblock ~43 ~2 ~21 concrete 7  
fill ~44 ~2 ~2 ~50 ~2 ~2 stained_hardened_clay 15  
fill ~44 ~2 ~20 ~46 ~2 ~20 concrete 7  
fill ~44 ~2 ~69 ~45 ~2 ~69 concrete 15 
setblock ~46 ~2 ~69 stained_hardened_clay 15 
setblock ~47 ~2 ~19 stained_hardened_clay 15 
setblock ~47 ~2 ~70 stained_hardened_clay 15  
fill ~48 ~2 ~20 ~50 ~2 ~20 concrete 7 
setblock ~48 ~2 ~69 stained_hardened_clay 15  
fill ~49 ~2 ~69 ~50 ~2 ~69 concrete 15  
fill ~51 ~2 ~3 ~53 ~2 ~3 stained_hardened_clay 15  
fill ~51 ~2 ~21 ~54 ~2 ~21 stained_hardened_clay 7  
fill ~51 ~2 ~68 ~53 ~2 ~68 concrete 15 
setblock ~54 ~2 ~3 stained_hardened_clay 7  
fill ~54 ~2 ~67 ~57 ~2 ~67 concrete 15 
setblock ~55 ~2 ~3 concrete 7 
setblock ~55 ~2 ~22 stained_hardened_clay 15 
setblock ~56 ~2 ~4 stained_hardened_clay 9  
fill ~56 ~2 ~22 ~58 ~2 ~22 concrete 15 
setblock ~57 ~2 ~4 concrete 7 
setblock ~58 ~2 ~4 stained_hardened_clay 11  
fill ~58 ~2 ~66 ~60 ~2 ~66 concrete 15 
setblock ~59 ~2 ~4 stained_hardened_clay 9  
fill ~59 ~2 ~23 ~61 ~2 ~23 concrete 15 
setblock ~60 ~2 ~4 concrete 7 
setblock ~61 ~2 ~4 stained_hardened_clay 15  
fill ~61 ~2 ~65 ~63 ~2 ~65 concrete 15 
setblock ~62 ~2 ~5 stained_hardened_clay 7  
fill ~62 ~2 ~24 ~65 ~2 ~24 concrete 15 
setblock ~63 ~2 ~5 concrete 7 
setblock ~64 ~2 ~5 stained_hardened_clay 9  
fill ~64 ~2 ~64 ~66 ~2 ~64 concrete 15 
setblock ~65 ~2 ~5 stained_hardened_clay 11 
setblock ~66 ~2 ~5 stained_hardened_clay 15  
fill ~66 ~2 ~25 ~67 ~2 ~25 concrete 15  
fill ~67 ~2 ~6 ~68 ~2 ~6 concrete 15  
fill ~67 ~2 ~26 ~67 ~3 ~26 concrete 15  
fill ~67 ~2 ~63 ~67 ~3 ~63 concrete 15 
setblock ~68 ~2 ~27 concrete 15  
fill ~68 ~2 ~62 ~68 ~3 ~62 concrete 15  
fill ~69 ~2 ~29 ~69 ~3 ~29 concrete 15  
fill ~69 ~2 ~61 ~70 ~2 ~61 concrete 15  
fill ~72 ~2 ~34 ~72 ~3 ~34 concrete 15  
fill ~12 ~3 ~51 ~12 ~4 ~51 concrete 15  
fill ~14 ~3 ~53 ~14 ~4 ~53 concrete 15  
fill ~15 ~3 ~46 ~15 ~4 ~46 concrete 15 
setblock ~15 ~3 ~54 concrete 15  
fill ~16 ~3 ~44 ~16 ~3 ~45 concrete 15  
fill ~16 ~3 ~55 ~17 ~3 ~55 concrete 15  
fill ~17 ~3 ~42 ~17 ~3 ~43 concrete 15  
fill ~18 ~3 ~41 ~18 ~4 ~41 concrete 15  
fill ~18 ~3 ~56 ~18 ~4 ~56 concrete 15  
fill ~19 ~3 ~39 ~19 ~3 ~40 concrete 15  
fill ~19 ~3 ~57 ~20 ~3 ~57 concrete 15  
fill ~20 ~3 ~37 ~20 ~3 ~38 concrete 15  
fill ~21 ~3 ~36 ~21 ~4 ~36 concrete 15  
fill ~21 ~3 ~58 ~21 ~5 ~58 concrete 15  
fill ~22 ~3 ~35 ~22 ~4 ~35 concrete 15  
fill ~22 ~3 ~59 ~22 ~4 ~59 concrete 15  
fill ~23 ~3 ~32 ~23 ~3 ~33 concrete 15  
fill ~23 ~3 ~60 ~24 ~3 ~60 concrete 15  
fill ~24 ~3 ~7 ~25 ~3 ~7 stained_hardened_clay 15 
setblock ~24 ~3 ~31 concrete 15  
fill ~25 ~3 ~30 ~25 ~4 ~30 concrete 15  
fill ~25 ~3 ~61 ~25 ~4 ~61 concrete 15  
fill ~26 ~3 ~6 ~30 ~3 ~6 stained_hardened_clay 15  
fill ~26 ~3 ~28 ~26 ~4 ~28 concrete 15  
fill ~27 ~3 ~27 ~27 ~5 ~27 concrete 15  
fill ~28 ~3 ~25 ~30 ~3 ~25 concrete 15  
fill ~28 ~3 ~63 ~28 ~5 ~63 concrete 15  
fill ~29 ~3 ~64 ~30 ~3 ~64 concrete 15 
setblock ~31 ~3 ~5 stained_hardened_clay 15  
fill ~31 ~3 ~24 ~33 ~3 ~24 concrete 15  
fill ~31 ~3 ~65 ~34 ~3 ~65 concrete 15  
fill ~32 ~3 ~5 ~34 ~3 ~5 concrete 15  
fill ~34 ~3 ~23 ~37 ~3 ~23 concrete 15 
setblock ~35 ~3 ~5 stained_hardened_clay 15  
fill ~35 ~3 ~66 ~37 ~3 ~66 concrete 15 
setblock ~36 ~3 ~4 stained_hardened_clay 15 
setblock ~37 ~3 ~4 concrete 15  
fill ~38 ~3 ~4 ~41 ~3 ~4 stained_hardened_clay 15  
fill ~38 ~3 ~22 ~41 ~3 ~22 concrete 15  
fill ~38 ~3 ~67 ~40 ~3 ~67 concrete 15  
fill ~41 ~3 ~68 ~44 ~3 ~68 concrete 15  
fill ~42 ~3 ~3 ~46 ~3 ~3 stained_hardened_clay 15  
fill ~42 ~3 ~21 ~43 ~3 ~21 concrete 15 
setblock ~44 ~3 ~21 stained_hardened_clay 15 
setblock ~45 ~3 ~20 stained_hardened_clay 15  
fill ~45 ~3 ~69 ~49 ~3 ~69 concrete 15 
setblock ~46 ~3 ~20 concrete 7 
setblock ~47 ~3 ~2 stained_hardened_clay 7 
setblock ~47 ~3 ~20 stained_hardened_clay 15  
fill ~48 ~3 ~3 ~52 ~3 ~3 stained_hardened_clay 15  
fill ~48 ~3 ~20 ~48 ~2 ~20 concrete 7 
setblock ~49 ~3 ~20 stained_hardened_clay 15 
setblock ~50 ~3 ~21 stained_hardened_clay 15  
fill ~50 ~3 ~68 ~53 ~3 ~68 concrete 15  
fill ~51 ~3 ~21 ~52 ~3 ~21 concrete 15  
fill ~53 ~3 ~4 ~56 ~3 ~4 stained_hardened_clay 15  
fill ~53 ~3 ~22 ~56 ~3 ~22 concrete 15  
fill ~54 ~3 ~67 ~56 ~3 ~67 concrete 15 
setblock ~57 ~3 ~4 concrete 15  
fill ~57 ~3 ~23 ~60 ~3 ~23 concrete 15  
fill ~57 ~3 ~66 ~59 ~3 ~66 concrete 15 
setblock ~58 ~3 ~4 stained_hardened_clay 15 
setblock ~59 ~3 ~5 stained_hardened_clay 15  
fill ~60 ~3 ~5 ~62 ~3 ~5 concrete 15  
fill ~60 ~3 ~65 ~63 ~3 ~65 concrete 15  
fill ~61 ~3 ~24 ~63 ~3 ~24 concrete 15 
setblock ~63 ~3 ~5 stained_hardened_clay 15  
fill ~64 ~3 ~6 ~68 ~3 ~6 stained_hardened_clay 15  
fill ~64 ~3 ~25 ~66 ~3 ~25 concrete 15  
fill ~64 ~3 ~64 ~65 ~3 ~64 concrete 15  
fill ~66 ~3 ~63 ~66 ~5 ~63 concrete 15  
fill ~67 ~3 ~27 ~67 ~5 ~27 concrete 15  
fill ~68 ~3 ~28 ~68 ~4 ~28 concrete 15  
fill ~69 ~3 ~7 ~70 ~3 ~7 stained_hardened_clay 15  
fill ~69 ~3 ~30 ~69 ~4 ~30 concrete 15  
fill ~69 ~3 ~61 ~69 ~4 ~61 concrete 15 
setblock ~70 ~3 ~31 concrete 15  
fill ~70 ~3 ~60 ~71 ~3 ~60 concrete 15  
fill ~71 ~3 ~32 ~71 ~3 ~33 concrete 15  
fill ~72 ~3 ~35 ~72 ~4 ~35 concrete 15  
fill ~72 ~3 ~59 ~72 ~4 ~59 concrete 15  
fill ~73 ~3 ~36 ~73 ~4 ~36 concrete 15  
fill ~73 ~3 ~58 ~73 ~5 ~58 concrete 15  
fill ~74 ~3 ~37 ~74 ~3 ~38 concrete 15  
fill ~74 ~3 ~57 ~75 ~3 ~57 concrete 15  
fill ~75 ~3 ~39 ~75 ~3 ~40 concrete 15  
fill ~76 ~3 ~41 ~76 ~4 ~41 concrete 15  
fill ~76 ~3 ~56 ~76 ~4 ~56 concrete 15  
fill ~77 ~3 ~42 ~77 ~3 ~43 concrete 15  
fill ~77 ~3 ~55 ~78 ~3 ~55 concrete 15 
setblock ~78 ~3 ~44 concrete 15  
fill ~79 ~3 ~45 ~79 ~3 ~46 concrete 15 
setblock ~79 ~3 ~54 concrete 15  
fill ~80 ~3 ~53 ~80 ~4 ~53 concrete 15  
fill ~82 ~3 ~51 ~82 ~4 ~51 concrete 15  
fill ~13 ~4 ~49 ~13 ~4 ~50 concrete 15  
fill ~13 ~4 ~52 ~13 ~5 ~52 concrete 15 
setblock ~14 ~4 ~48 concrete 15  
fill ~15 ~4 ~47 ~15 ~5 ~47 concrete 15  
fill ~15 ~4 ~53 ~15 ~6 ~53 concrete 15  
fill ~16 ~4 ~45 ~16 ~5 ~45 concrete 15  
fill ~16 ~4 ~54 ~16 ~6 ~54 concrete 15  
fill ~17 ~4 ~43 ~17 ~4 ~44 concrete 15  
fill ~17 ~4 ~55 ~17 ~5 ~55 concrete 15  
fill ~18 ~4 ~42 ~18 ~5 ~42 concrete 15  
fill ~19 ~4 ~40 ~19 ~5 ~40 concrete 15  
fill ~19 ~4 ~56 ~19 ~6 ~56 concrete 15  
fill ~20 ~4 ~38 ~20 ~4 ~39 concrete 15  
fill ~20 ~4 ~57 ~20 ~5 ~57 concrete 15  
fill ~21 ~4 ~8 ~23 ~4 ~8 stained_hardened_clay 15  
fill ~21 ~4 ~37 ~21 ~5 ~37 concrete 15  
fill ~23 ~4 ~33 ~23 ~4 ~34 concrete 15  
fill ~23 ~4 ~59 ~23 ~6 ~59 concrete 15  
fill ~24 ~4 ~7 ~24 ~3 ~7 stained_hardened_clay 15  
fill ~24 ~4 ~32 ~24 ~5 ~32 concrete 15  
fill ~24 ~4 ~60 ~24 ~5 ~60 concrete 15  
fill ~25 ~4 ~7 ~27 ~4 ~7 stained_hardened_clay 7  
fill ~25 ~4 ~31 ~25 ~6 ~31 concrete 15  
fill ~26 ~4 ~29 ~26 ~5 ~29 concrete 15  
fill ~26 ~4 ~61 ~26 ~6 ~61 concrete 15  
fill ~27 ~4 ~62 ~27 ~6 ~62 concrete 15  
fill ~28 ~4 ~7 ~28 ~5 ~7 stained_hardened_clay 15  
fill ~28 ~4 ~26 ~28 ~5 ~26 concrete 15  
fill ~29 ~4 ~6 ~33 ~4 ~6 stained_hardened_clay 15  
fill ~29 ~4 ~25 ~31 ~4 ~25 concrete 15  
fill ~29 ~4 ~64 ~31 ~4 ~64 concrete 15  
fill ~32 ~4 ~24 ~35 ~4 ~24 concrete 15  
fill ~32 ~4 ~65 ~34 ~4 ~65 concrete 15 
setblock ~34 ~4 ~5 stained_hardened_clay 15 
setblock ~35 ~4 ~5 concrete 15  
fill ~35 ~4 ~66 ~38 ~4 ~66 concrete 15  
fill ~36 ~4 ~5 ~38 ~4 ~5 stained_hardened_clay 15  
fill ~36 ~4 ~23 ~39 ~4 ~23 concrete 15  
fill ~39 ~4 ~4 ~44 ~4 ~4 stained_hardened_clay 15  
fill ~39 ~4 ~67 ~39 ~5 ~67 concrete 15  
fill ~40 ~4 ~22 ~42 ~4 ~22 concrete 15 
setblock ~40 ~4 ~67 stained_hardened_clay 15  
fill ~41 ~4 ~67 ~41 ~7 ~67 concrete 15  
fill ~42 ~4 ~68 ~45 ~4 ~68 concrete 15  
fill ~43 ~4 ~21 ~46 ~4 ~21 concrete 15 
setblock ~45 ~4 ~3 stained_hardened_clay 15  
fill ~46 ~4 ~3 ~48 ~4 ~3 stained_hardened_clay 7  
fill ~46 ~4 ~69 ~48 ~4 ~69 concrete 15 
setblock ~47 ~4 ~20 concrete 15  
fill ~48 ~4 ~21 ~51 ~4 ~21 concrete 15 
setblock ~49 ~4 ~3 stained_hardened_clay 15  
fill ~49 ~4 ~68 ~52 ~4 ~68 concrete 15  
fill ~50 ~4 ~4 ~55 ~4 ~4 stained_hardened_clay 15  
fill ~52 ~4 ~22 ~54 ~4 ~22 concrete 15  
fill ~53 ~4 ~67 ~53 ~7 ~67 concrete 15 
setblock ~54 ~4 ~67 stained_hardened_clay 15  
fill ~55 ~4 ~23 ~58 ~4 ~23 concrete 15  
fill ~55 ~4 ~67 ~55 ~5 ~67 concrete 15  
fill ~56 ~4 ~5 ~58 ~4 ~5 stained_hardened_clay 15  
fill ~56 ~4 ~66 ~59 ~4 ~66 concrete 15 
setblock ~59 ~4 ~5 concrete 15  
fill ~59 ~4 ~24 ~62 ~4 ~24 concrete 15 
setblock ~60 ~4 ~5 stained_hardened_clay 15  
fill ~60 ~4 ~65 ~62 ~4 ~65 concrete 15  
fill ~61 ~4 ~6 ~65 ~4 ~6 stained_hardened_clay 15  
fill ~63 ~4 ~25 ~65 ~4 ~25 concrete 15  
fill ~63 ~4 ~64 ~65 ~4 ~64 concrete 15  
fill ~66 ~4 ~7 ~66 ~5 ~7 stained_hardened_clay 15  
fill ~66 ~4 ~26 ~66 ~5 ~26 concrete 15  
fill ~67 ~4 ~7 ~68 ~4 ~7 stained_hardened_clay 7  
fill ~67 ~4 ~62 ~67 ~6 ~62 concrete 15  
fill ~68 ~4 ~29 ~68 ~5 ~29 concrete 15  
fill ~68 ~4 ~61 ~68 ~6 ~61 concrete 15  
fill ~69 ~4 ~7 ~70 ~4 ~7 stained_hardened_clay 15  
fill ~69 ~4 ~31 ~69 ~6 ~31 concrete 15  
fill ~70 ~4 ~32 ~70 ~5 ~32 concrete 15  
fill ~70 ~4 ~60 ~70 ~5 ~60 concrete 15  
fill ~71 ~4 ~8 ~73 ~4 ~8 stained_hardened_clay 15  
fill ~71 ~4 ~33 ~71 ~4 ~34 concrete 15  
fill ~71 ~4 ~59 ~71 ~6 ~59 concrete 15  
fill ~73 ~4 ~37 ~73 ~5 ~37 concrete 15  
fill ~74 ~4 ~38 ~74 ~4 ~39 concrete 15  
fill ~74 ~4 ~57 ~74 ~5 ~57 concrete 15  
fill ~75 ~4 ~40 ~75 ~5 ~40 concrete 15  
fill ~75 ~4 ~56 ~75 ~6 ~56 concrete 15  
fill ~76 ~4 ~42 ~76 ~5 ~42 concrete 15  
fill ~77 ~4 ~43 ~77 ~4 ~44 concrete 15  
fill ~77 ~4 ~55 ~77 ~5 ~55 concrete 15  
fill ~78 ~4 ~45 ~78 ~5 ~45 concrete 15  
fill ~78 ~4 ~54 ~78 ~6 ~54 concrete 15  
fill ~79 ~4 ~46 ~79 ~4 ~47 concrete 15  
fill ~79 ~4 ~53 ~79 ~6 ~53 concrete 15 
setblock ~80 ~4 ~48 concrete 15  
fill ~81 ~4 ~49 ~81 ~4 ~50 concrete 15  
fill ~81 ~4 ~52 ~81 ~5 ~52 concrete 15  
fill ~13 ~5 ~50 ~13 ~5 ~52 concrete 15  
fill ~14 ~5 ~49 ~14 ~6 ~49 concrete 15  
fill ~14 ~5 ~52 ~14 ~7 ~52 concrete 15  
fill ~15 ~5 ~48 ~15 ~7 ~48 concrete 15  
fill ~16 ~5 ~46 ~16 ~6 ~46 concrete 15  
fill ~17 ~5 ~44 ~17 ~6 ~44 concrete 15  
fill ~18 ~5 ~43 ~18 ~7 ~43 concrete 15  
fill ~18 ~5 ~55 ~18 ~7 ~55 concrete 15  
fill ~19 ~5 ~9 ~21 ~5 ~9 concrete 15  
fill ~19 ~5 ~41 ~19 ~6 ~41 concrete 15  
fill ~20 ~5 ~39 ~20 ~6 ~39 concrete 15  
fill ~21 ~5 ~38 ~21 ~6 ~38 concrete 15  
fill ~22 ~5 ~8 ~23 ~5 ~8 stained_hardened_clay 15  
fill ~22 ~5 ~36 ~22 ~6 ~36 concrete 15  
fill ~22 ~5 ~58 ~22 ~7 ~58 concrete 15  
fill ~23 ~5 ~34 ~23 ~5 ~35 concrete 15  
fill ~24 ~5 ~8 ~25 ~5 ~8 stained_hardened_clay 7  
fill ~24 ~5 ~33 ~24 ~6 ~33 concrete 15  
fill ~25 ~5 ~60 ~25 ~7 ~60 concrete 15  
fill ~26 ~5 ~7 ~27 ~5 ~7 stained_hardened_clay 7  
fill ~26 ~5 ~30 ~26 ~7 ~30 concrete 15  
fill ~27 ~5 ~28 ~27 ~6 ~28 concrete 15  
fill ~29 ~5 ~7 ~30 ~5 ~7 stained_hardened_clay 15  
fill ~29 ~5 ~26 ~29 ~6 ~26 concrete 15  
fill ~29 ~5 ~63 ~29 ~7 ~63 concrete 15  
fill ~30 ~5 ~25 ~33 ~5 ~25 concrete 15  
fill ~30 ~5 ~64 ~32 ~5 ~64 concrete 15  
fill ~31 ~5 ~6 ~36 ~5 ~6 stained_hardened_clay 15  
fill ~33 ~5 ~65 ~35 ~5 ~65 concrete 15  
fill ~34 ~5 ~24 ~36 ~5 ~24 concrete 15  
fill ~36 ~5 ~66 ~38 ~5 ~66 concrete 15  
fill ~37 ~5 ~5 ~41 ~5 ~5 stained_hardened_clay 15  
fill ~37 ~5 ~23 ~40 ~5 ~23 concrete 15  
fill ~40 ~5 ~67 ~40 ~6 ~67 concrete 15  
fill ~41 ~5 ~22 ~44 ~5 ~22 concrete 15  
fill ~42 ~5 ~4 ~44 ~5 ~4 stained_hardened_clay 15  
fill ~42 ~5 ~67 ~42 ~9 ~67 concrete 15  
fill ~43 ~5 ~68 ~45 ~5 ~68 concrete 15  
fill ~45 ~5 ~4 ~49 ~5 ~4 stained_hardened_clay 7  
fill ~45 ~5 ~21 ~49 ~5 ~21 concrete 15  
fill ~46 ~5 ~69 ~48 ~5 ~69 concrete 15  
fill ~49 ~5 ~68 ~51 ~5 ~68 concrete 15  
fill ~50 ~5 ~4 ~52 ~5 ~4 stained_hardened_clay 15  
fill ~50 ~5 ~22 ~53 ~5 ~22 concrete 15  
fill ~52 ~5 ~67 ~52 ~9 ~67 concrete 15  
fill ~53 ~5 ~5 ~57 ~5 ~5 stained_hardened_clay 15  
fill ~54 ~5 ~23 ~57 ~5 ~23 concrete 15  
fill ~54 ~5 ~67 ~54 ~6 ~67 concrete 15  
fill ~56 ~5 ~66 ~58 ~5 ~66 concrete 15  
fill ~58 ~5 ~6 ~63 ~5 ~6 stained_hardened_clay 15  
fill ~58 ~5 ~24 ~60 ~5 ~24 concrete 15  
fill ~59 ~5 ~65 ~61 ~5 ~65 concrete 15  
fill ~61 ~5 ~25 ~64 ~5 ~25 concrete 15  
fill ~62 ~5 ~64 ~64 ~5 ~64 concrete 15  
fill ~64 ~5 ~7 ~66 ~5 ~7 stained_hardened_clay 15  
fill ~65 ~5 ~26 ~65 ~6 ~26 concrete 15  
fill ~65 ~5 ~63 ~65 ~7 ~63 concrete 15  
fill ~67 ~5 ~7 ~68 ~5 ~7 stained_hardened_clay 7  
fill ~67 ~5 ~28 ~67 ~6 ~28 concrete 15  
fill ~68 ~5 ~30 ~68 ~7 ~30 concrete 15  
fill ~69 ~5 ~8 ~70 ~5 ~8 stained_hardened_clay 7  
fill ~69 ~5 ~60 ~69 ~7 ~60 concrete 15  
fill ~70 ~5 ~33 ~70 ~6 ~33 concrete 15  
fill ~71 ~5 ~8 ~72 ~5 ~8 stained_hardened_clay 15  
fill ~71 ~5 ~34 ~71 ~5 ~35 concrete 15  
fill ~72 ~5 ~36 ~72 ~6 ~36 concrete 15  
fill ~72 ~5 ~58 ~72 ~7 ~58 concrete 15  
fill ~73 ~5 ~9 ~75 ~5 ~9 concrete 15  
fill ~73 ~5 ~38 ~73 ~6 ~38 concrete 15  
fill ~74 ~5 ~39 ~74 ~6 ~39 concrete 15  
fill ~75 ~5 ~41 ~75 ~6 ~41 concrete 15  
fill ~76 ~5 ~43 ~76 ~7 ~43 concrete 15  
fill ~76 ~5 ~55 ~76 ~7 ~55 concrete 15  
fill ~77 ~5 ~44 ~77 ~6 ~44 concrete 15  
fill ~78 ~5 ~46 ~78 ~6 ~46 concrete 15  
fill ~79 ~5 ~47 ~79 ~5 ~48 concrete 15  
fill ~80 ~5 ~49 ~80 ~6 ~49 concrete 15  
fill ~80 ~5 ~52 ~80 ~7 ~52 concrete 15  
fill ~81 ~5 ~50 ~81 ~5 ~52 concrete 15 
setblock ~13 ~6 ~51 concrete 15  
fill ~14 ~6 ~50 ~14 ~7 ~50 concrete 15  
fill ~16 ~6 ~47 ~16 ~8 ~47 concrete 15  
fill ~17 ~6 ~10 ~19 ~6 ~10 concrete 15  
fill ~17 ~6 ~45 ~17 ~7 ~45 concrete 15  
fill ~17 ~6 ~54 ~17 ~8 ~54 concrete 15  
fill ~19 ~6 ~42 ~19 ~7 ~42 concrete 15  
fill ~20 ~6 ~9 ~21 ~6 ~9 concrete 15  
fill ~20 ~6 ~40 ~20 ~7 ~40 concrete 15  
fill ~20 ~6 ~56 ~20 ~8 ~56 concrete 15  
fill ~21 ~6 ~57 ~21 ~8 ~57 concrete 15  
fill ~22 ~6 ~9 ~23 ~6 ~9 stained_hardened_clay 15  
fill ~22 ~6 ~37 ~22 ~7 ~37 concrete 15  
fill ~23 ~6 ~35 ~23 ~7 ~35 concrete 15  
fill ~24 ~6 ~8 ~28 ~6 ~8 stained_hardened_clay 7  
fill ~24 ~6 ~34 ~24 ~8 ~34 concrete 15  
fill ~24 ~6 ~59 ~24 ~8 ~59 concrete 15  
fill ~25 ~6 ~32 ~25 ~7 ~32 concrete 15  
fill ~27 ~6 ~29 ~27 ~8 ~29 concrete 15  
fill ~28 ~6 ~27 ~28 ~7 ~27 concrete 15  
fill ~28 ~6 ~62 ~28 ~8 ~62 concrete 15  
fill ~29 ~6 ~7 ~32 ~6 ~7 stained_hardened_clay 15  
fill ~30 ~6 ~26 ~31 ~6 ~26 concrete 15  
fill ~30 ~6 ~64 ~32 ~6 ~64 concrete 15  
fill ~32 ~6 ~25 ~34 ~6 ~25 concrete 15  
fill ~33 ~6 ~7 ~33 ~7 ~7 stained_hardened_clay 7  
fill ~33 ~6 ~65 ~36 ~6 ~65 concrete 15  
fill ~34 ~6 ~6 ~39 ~6 ~6 stained_hardened_clay 15  
fill ~35 ~6 ~24 ~38 ~6 ~24 concrete 15  
fill ~37 ~6 ~66 ~39 ~6 ~66 concrete 15  
fill ~39 ~6 ~23 ~42 ~6 ~23 concrete 15  
fill ~40 ~6 ~5 ~41 ~6 ~5 stained_hardened_clay 7  
fill ~42 ~6 ~5 ~43 ~6 ~5 stained_hardened_clay 15  
fill ~43 ~6 ~22 ~45 ~6 ~22 concrete 15  
fill ~43 ~6 ~67 ~43 ~10 ~67 concrete 15  
fill ~44 ~6 ~5 ~44 ~7 ~5 stained_hardened_clay 7  
fill ~44 ~6 ~68 ~46 ~6 ~68 concrete 15  
fill ~45 ~6 ~4 ~49 ~6 ~4 stained_hardened_clay 7  
fill ~46 ~6 ~21 ~48 ~6 ~21 concrete 15 
setblock ~47 ~6 ~69 concrete 15  
fill ~48 ~6 ~68 ~50 ~6 ~68 concrete 15  
fill ~49 ~6 ~22 ~51 ~6 ~22 concrete 15  
fill ~50 ~6 ~5 ~50 ~7 ~5 stained_hardened_clay 7  
fill ~51 ~6 ~5 ~52 ~6 ~5 stained_hardened_clay 15  
fill ~51 ~6 ~67 ~51 ~10 ~67 concrete 15  
fill ~52 ~6 ~23 ~55 ~6 ~23 concrete 15  
fill ~53 ~6 ~5 ~54 ~6 ~5 stained_hardened_clay 7  
fill ~55 ~6 ~6 ~60 ~6 ~6 stained_hardened_clay 15  
fill ~55 ~6 ~66 ~57 ~6 ~66 concrete 15  
fill ~56 ~6 ~24 ~59 ~6 ~24 concrete 15  
fill ~58 ~6 ~65 ~61 ~6 ~65 concrete 15  
fill ~60 ~6 ~25 ~62 ~6 ~25 concrete 15  
fill ~61 ~6 ~7 ~65 ~6 ~7 stained_hardened_clay 15  
fill ~62 ~6 ~64 ~64 ~6 ~64 concrete 15  
fill ~63 ~6 ~26 ~65 ~6 ~26 concrete 15  
fill ~66 ~6 ~8 ~70 ~6 ~8 stained_hardened_clay 7  
fill ~66 ~6 ~27 ~66 ~7 ~27 concrete 15  
fill ~66 ~6 ~62 ~66 ~8 ~62 concrete 15  
fill ~67 ~6 ~29 ~67 ~8 ~29 concrete 15  
fill ~69 ~6 ~32 ~69 ~7 ~32 concrete 15  
fill ~70 ~6 ~34 ~70 ~8 ~34 concrete 15  
fill ~70 ~6 ~59 ~70 ~8 ~59 concrete 15  
fill ~71 ~6 ~9 ~72 ~6 ~9 stained_hardened_clay 15  
fill ~71 ~6 ~35 ~71 ~7 ~35 concrete 15  
fill ~72 ~6 ~37 ~72 ~7 ~37 concrete 15  
fill ~73 ~6 ~9 ~74 ~6 ~9 concrete 15  
fill ~73 ~6 ~57 ~73 ~8 ~57 concrete 15  
fill ~74 ~6 ~40 ~74 ~7 ~40 concrete 15  
fill ~74 ~6 ~56 ~74 ~8 ~56 concrete 15  
fill ~75 ~6 ~10 ~77 ~6 ~10 concrete 15  
fill ~75 ~6 ~42 ~75 ~7 ~42 concrete 15  
fill ~77 ~6 ~45 ~77 ~7 ~45 concrete 15  
fill ~77 ~6 ~54 ~77 ~8 ~54 concrete 15  
fill ~78 ~6 ~47 ~78 ~8 ~47 concrete 15  
fill ~79 ~6 ~48 ~79 ~7 ~48 concrete 15  
fill ~80 ~6 ~50 ~80 ~7 ~50 concrete 15 
setblock ~81 ~6 ~51 concrete 15  
fill ~14 ~7 ~51 ~14 ~8 ~51 concrete 15 
setblock ~15 ~7 ~11 stained_hardened_clay 15  
fill ~15 ~7 ~49 ~15 ~8 ~49 concrete 15  
fill ~15 ~7 ~52 ~15 ~10 ~52 concrete 15  
fill ~16 ~7 ~11 ~17 ~7 ~11 concrete 15  
fill ~16 ~7 ~53 ~16 ~9 ~53 concrete 15  
fill ~17 ~7 ~46 ~17 ~9 ~46 concrete 15 
setblock ~18 ~7 ~10 concrete 15  
fill ~18 ~7 ~44 ~18 ~8 ~44 concrete 15  
fill ~19 ~7 ~10 ~21 ~7 ~10 stained_hardened_clay 15  
fill ~19 ~7 ~55 ~19 ~9 ~55 concrete 15  
fill ~20 ~7 ~41 ~20 ~8 ~41 concrete 15  
fill ~21 ~7 ~39 ~21 ~8 ~39 concrete 15  
fill ~22 ~7 ~9 ~23 ~7 ~9 stained_hardened_clay 15  
fill ~22 ~7 ~38 ~22 ~9 ~38 concrete 15  
fill ~23 ~7 ~36 ~23 ~8 ~36 concrete 15  
fill ~23 ~7 ~58 ~23 ~9 ~58 concrete 15  
fill ~24 ~7 ~9 ~26 ~7 ~9 stained_hardened_clay 7  
fill ~25 ~7 ~33 ~25 ~9 ~33 concrete 15  
fill ~26 ~7 ~31 ~26 ~8 ~31 concrete 15  
fill ~26 ~7 ~60 ~26 ~9 ~60 concrete 15 
setblock ~27 ~7 ~8 stained_hardened_clay 7  
fill ~27 ~7 ~61 ~27 ~8 ~61 concrete 15  
fill ~28 ~7 ~8 ~31 ~7 ~8 stained_hardened_clay 15  
fill ~28 ~7 ~28 ~28 ~8 ~28 concrete 15  
fill ~29 ~7 ~27 ~29 ~9 ~27 concrete 15  
fill ~30 ~7 ~26 ~32 ~7 ~26 concrete 15  
fill ~30 ~7 ~63 ~30 ~10 ~63 concrete 15  
fill ~31 ~7 ~64 ~33 ~7 ~64 concrete 15 
setblock ~32 ~7 ~7 stained_hardened_clay 7  
fill ~33 ~7 ~25 ~36 ~7 ~25 concrete 15  
fill ~34 ~7 ~7 ~36 ~7 ~7 stained_hardened_clay 7  
fill ~34 ~7 ~65 ~36 ~7 ~65 concrete 15 
setblock ~37 ~7 ~6 stained_hardened_clay 7  
fill ~37 ~7 ~24 ~40 ~7 ~24 concrete 15  
fill ~37 ~7 ~66 ~40 ~7 ~66 concrete 15  
fill ~38 ~7 ~6 ~39 ~7 ~6 stained_hardened_clay 15  
fill ~40 ~7 ~6 ~41 ~7 ~6 stained_hardened_clay 7  
fill ~41 ~7 ~23 ~43 ~7 ~23 concrete 15  
fill ~42 ~7 ~5 ~52 ~7 ~5 stained_hardened_clay 7  
fill ~44 ~7 ~22 ~50 ~7 ~22 concrete 15  
fill ~44 ~7 ~68 ~50 ~7 ~68 concrete 15  
fill ~51 ~7 ~23 ~53 ~7 ~23 concrete 15  
fill ~53 ~7 ~6 ~54 ~7 ~6 stained_hardened_clay 7  
fill ~54 ~7 ~24 ~57 ~7 ~24 concrete 15  
fill ~54 ~7 ~66 ~57 ~7 ~66 concrete 15  
fill ~55 ~7 ~6 ~56 ~7 ~6 stained_hardened_clay 15 
setblock ~57 ~7 ~6 stained_hardened_clay 7  
fill ~58 ~7 ~7 ~62 ~7 ~7 stained_hardened_clay 7  
fill ~58 ~7 ~25 ~61 ~7 ~25 concrete 15  
fill ~58 ~7 ~65 ~60 ~7 ~65 concrete 15  
fill ~61 ~7 ~64 ~63 ~7 ~64 concrete 15  
fill ~62 ~7 ~26 ~64 ~7 ~26 concrete 15  
fill ~63 ~7 ~8 ~66 ~7 ~8 stained_hardened_clay 15  
fill ~64 ~7 ~63 ~64 ~10 ~63 concrete 15  
fill ~65 ~7 ~27 ~65 ~9 ~27 concrete 15  
fill ~66 ~7 ~28 ~66 ~8 ~28 concrete 15 
setblock ~67 ~7 ~8 stained_hardened_clay 7  
fill ~67 ~7 ~61 ~67 ~8 ~61 concrete 15  
fill ~68 ~7 ~9 ~70 ~7 ~9 stained_hardened_clay 7  
fill ~68 ~7 ~31 ~68 ~8 ~31 concrete 15  
fill ~68 ~7 ~60 ~68 ~9 ~60 concrete 15  
fill ~69 ~7 ~33 ~69 ~9 ~33 concrete 15  
fill ~71 ~7 ~9 ~72 ~7 ~9 stained_hardened_clay 15  
fill ~71 ~7 ~36 ~71 ~8 ~36 concrete 15  
fill ~71 ~7 ~58 ~71 ~9 ~58 concrete 15  
fill ~72 ~7 ~38 ~72 ~9 ~38 concrete 15  
fill ~73 ~7 ~10 ~75 ~7 ~10 stained_hardened_clay 15  
fill ~73 ~7 ~39 ~73 ~8 ~39 concrete 15  
fill ~74 ~7 ~41 ~74 ~8 ~41 concrete 15  
fill ~75 ~7 ~55 ~75 ~9 ~55 concrete 15 
setblock ~76 ~7 ~10 concrete 15  
fill ~76 ~7 ~44 ~76 ~8 ~44 concrete 15  
fill ~77 ~7 ~11 ~78 ~7 ~11 concrete 15  
fill ~77 ~7 ~46 ~77 ~9 ~46 concrete 15  
fill ~78 ~7 ~53 ~78 ~9 ~53 concrete 15 
setblock ~79 ~7 ~11 stained_hardened_clay 15  
fill ~79 ~7 ~49 ~79 ~8 ~49 concrete 15  
fill ~79 ~7 ~52 ~79 ~10 ~52 concrete 15  
fill ~80 ~7 ~51 ~80 ~8 ~51 concrete 15  
fill ~12 ~8 ~12 ~15 ~8 ~12 stained_hardened_clay 15  
fill ~15 ~8 ~50 ~15 ~9 ~50 concrete 15 
setblock ~16 ~8 ~11 stained_hardened_clay 15  
fill ~16 ~8 ~48 ~16 ~9 ~48 concrete 15 
setblock ~17 ~8 ~11 concrete 15  
fill ~18 ~8 ~11 ~19 ~8 ~11 stained_hardened_clay 15  
fill ~18 ~8 ~45 ~18 ~9 ~45 concrete 15  
fill ~18 ~8 ~54 ~18 ~10 ~54 concrete 15  
fill ~19 ~8 ~43 ~19 ~9 ~43 concrete 15  
fill ~20 ~8 ~10 ~22 ~8 ~10 stained_hardened_clay 15  
fill ~20 ~8 ~42 ~20 ~10 ~42 concrete 15  
fill ~21 ~8 ~40 ~21 ~9 ~40 concrete 15  
fill ~22 ~8 ~57 ~22 ~10 ~57 concrete 15  
fill ~23 ~8 ~10 ~24 ~8 ~10 stained_hardened_clay 7  
fill ~23 ~8 ~37 ~23 ~10 ~37 concrete 15  
fill ~24 ~8 ~35 ~24 ~9 ~35 concrete 15  
fill ~24 ~8 ~64 ~24 ~9 ~64 concrete 15  
fill ~25 ~8 ~9 ~27 ~8 ~9 stained_hardened_clay 7  
fill ~25 ~8 ~59 ~25 ~10 ~59 concrete 15 
setblock ~25 ~8 ~65 concrete 15  
fill ~26 ~8 ~32 ~26 ~9 ~32 concrete 15  
fill ~26 ~8 ~66 ~28 ~8 ~66 concrete 15  
fill ~27 ~8 ~30 ~27 ~9 ~30 concrete 15  
fill ~28 ~8 ~9 ~29 ~8 ~9 stained_hardened_clay 15  
fill ~29 ~8 ~62 ~29 ~11 ~62 concrete 15  
fill ~29 ~8 ~67 ~31 ~8 ~67 concrete 15  
fill ~30 ~8 ~8 ~31 ~8 ~8 stained_hardened_clay 15  
fill ~30 ~8 ~27 ~30 ~9 ~27 concrete 15  
fill ~31 ~8 ~26 ~34 ~8 ~26 concrete 15  
fill ~31 ~8 ~64 ~34 ~8 ~64 concrete 15  
fill ~32 ~8 ~8 ~34 ~8 ~8 stained_hardened_clay 7  
fill ~32 ~8 ~68 ~35 ~8 ~68 concrete 15  
fill ~35 ~8 ~7 ~37 ~8 ~7 stained_hardened_clay 7  
fill ~35 ~8 ~25 ~37 ~8 ~25 concrete 15  
fill ~35 ~8 ~65 ~37 ~8 ~65 concrete 15  
fill ~36 ~8 ~69 ~38 ~8 ~69 concrete 15  
fill ~38 ~8 ~7 ~39 ~8 ~7 stained_hardened_clay 15  
fill ~38 ~8 ~24 ~41 ~8 ~24 concrete 15  
fill ~38 ~8 ~66 ~41 ~8 ~66 concrete 15  
fill ~39 ~8 ~70 ~42 ~8 ~70 concrete 15  
fill ~40 ~8 ~6 ~44 ~8 ~6 stained_hardened_clay 7  
fill ~42 ~8 ~23 ~45 ~8 ~23 concrete 15  
fill ~43 ~8 ~71 ~45 ~8 ~71 concrete 15 
setblock ~44 ~8 ~67 stained_hardened_clay 15  
fill ~45 ~8 ~5 ~49 ~8 ~5 stained_hardened_clay 7 
setblock ~45 ~8 ~68 stained_hardened_clay 15  
fill ~46 ~8 ~22 ~48 ~8 ~22 concrete 15  
fill ~46 ~8 ~68 ~48 ~8 ~68 concrete 15  
fill ~46 ~8 ~72 ~48 ~8 ~72 concrete 15  
fill ~49 ~8 ~23 ~52 ~8 ~23 concrete 15 
setblock ~49 ~8 ~68 stained_hardened_clay 15  
fill ~49 ~8 ~71 ~51 ~8 ~71 concrete 15  
fill ~50 ~8 ~6 ~54 ~8 ~6 stained_hardened_clay 7  
fill ~50 ~8 ~67 ~50 ~12 ~67 concrete 15  
fill ~52 ~8 ~70 ~55 ~8 ~70 concrete 15  
fill ~53 ~8 ~24 ~56 ~8 ~24 concrete 15  
fill ~53 ~8 ~66 ~56 ~8 ~66 concrete 15  
fill ~55 ~8 ~7 ~56 ~8 ~7 stained_hardened_clay 15  
fill ~56 ~8 ~69 ~58 ~8 ~69 concrete 15  
fill ~57 ~8 ~7 ~59 ~8 ~7 stained_hardened_clay 7  
fill ~57 ~8 ~25 ~59 ~8 ~25 concrete 15  
fill ~57 ~8 ~65 ~59 ~8 ~65 concrete 15  
fill ~59 ~8 ~68 ~62 ~8 ~68 concrete 15  
fill ~60 ~8 ~8 ~62 ~8 ~8 stained_hardened_clay 7  
fill ~60 ~8 ~26 ~63 ~8 ~26 concrete 15  
fill ~60 ~8 ~64 ~63 ~8 ~64 concrete 15  
fill ~63 ~8 ~8 ~64 ~8 ~8 stained_hardened_clay 15  
fill ~63 ~8 ~67 ~65 ~8 ~67 concrete 15  
fill ~64 ~8 ~27 ~64 ~9 ~27 concrete 15  
fill ~65 ~8 ~9 ~66 ~8 ~9 stained_hardened_clay 15  
fill ~65 ~8 ~62 ~65 ~10 ~62 concrete 15  
fill ~66 ~8 ~66 ~68 ~8 ~66 concrete 15  
fill ~67 ~8 ~9 ~69 ~8 ~9 stained_hardened_clay 7  
fill ~67 ~8 ~30 ~67 ~9 ~30 concrete 15  
fill ~68 ~8 ~32 ~68 ~9 ~32 concrete 15  
fill ~69 ~8 ~59 ~69 ~10 ~59 concrete 15 
setblock ~69 ~8 ~65 concrete 15  
fill ~70 ~8 ~10 ~71 ~8 ~10 stained_hardened_clay 7  
fill ~70 ~8 ~35 ~70 ~9 ~35 concrete 15  
fill ~70 ~8 ~64 ~70 ~9 ~64 concrete 15  
fill ~71 ~8 ~37 ~71 ~10 ~37 concrete 15  
fill ~72 ~8 ~10 ~74 ~8 ~10 stained_hardened_clay 15  
fill ~72 ~8 ~57 ~72 ~10 ~57 concrete 15  
fill ~73 ~8 ~40 ~73 ~9 ~40 concrete 15  
fill ~74 ~8 ~42 ~74 ~10 ~42 concrete 15  
fill ~75 ~8 ~11 ~76 ~8 ~11 stained_hardened_clay 15  
fill ~75 ~8 ~43 ~75 ~9 ~43 concrete 15  
fill ~76 ~8 ~45 ~76 ~9 ~45 concrete 15  
fill ~76 ~8 ~54 ~76 ~10 ~54 concrete 15  
fill ~77 ~8 ~11 ~77 ~7 ~11 concrete 15 
setblock ~78 ~8 ~11 stained_hardened_clay 15  
fill ~78 ~8 ~48 ~78 ~9 ~48 concrete 15  
fill ~79 ~8 ~12 ~82 ~8 ~12 stained_hardened_clay 15  
fill ~79 ~8 ~50 ~79 ~9 ~50 concrete 15  
fill ~10 ~9 ~13 ~13 ~9 ~13 stained_hardened_clay 15 
setblock ~14 ~9 ~12 stained_hardened_clay 15 
setblock ~15 ~9 ~12 stained_hardened_clay 7  
fill ~15 ~9 ~51 ~15 ~10 ~51 concrete 15  
fill ~16 ~9 ~12 ~17 ~9 ~12 stained_hardened_clay 15  
fill ~16 ~9 ~49 ~16 ~10 ~49 concrete 15  
fill ~16 ~9 ~58 ~17 ~9 ~58 concrete 15  
fill ~17 ~9 ~47 ~17 ~10 ~47 concrete 15  
fill ~17 ~9 ~53 ~17 ~11 ~53 concrete 15  
fill ~18 ~9 ~11 ~19 ~9 ~11 stained_hardened_clay 15  
fill ~18 ~9 ~59 ~18 ~10 ~59 concrete 15  
fill ~19 ~9 ~44 ~19 ~10 ~44 concrete 15 
setblock ~19 ~9 ~60 concrete 15  
fill ~20 ~9 ~11 ~21 ~9 ~11 stained_hardened_clay 7  
fill ~20 ~9 ~55 ~20 ~11 ~55 concrete 15  
fill ~20 ~9 ~61 ~21 ~9 ~61 concrete 15  
fill ~21 ~9 ~41 ~21 ~11 ~41 concrete 15  
fill ~21 ~9 ~56 ~21 ~11 ~56 concrete 15 
setblock ~22 ~9 ~11 stained_hardened_clay 15  
fill ~22 ~9 ~39 ~22 ~10 ~39 concrete 15  
fill ~22 ~9 ~62 ~22 ~10 ~62 concrete 15  
fill ~23 ~9 ~10 ~27 ~9 ~10 stained_hardened_clay 7  
fill ~23 ~9 ~28 ~23 ~10 ~28 concrete 15 
setblock ~23 ~9 ~63 concrete 15  
fill ~24 ~9 ~36 ~24 ~11 ~36 concrete 15  
fill ~24 ~9 ~58 ~24 ~11 ~58 concrete 15  
fill ~25 ~9 ~24 ~26 ~9 ~24 concrete 15  
fill ~25 ~9 ~34 ~25 ~10 ~34 concrete 15  
fill ~25 ~9 ~64 ~25 ~10 ~64 concrete 15  
fill ~26 ~9 ~65 ~26 ~10 ~65 concrete 15  
fill ~27 ~9 ~31 ~27 ~10 ~31 concrete 15 
setblock ~27 ~9 ~61 stained_hardened_clay 15  
fill ~27 ~9 ~66 ~29 ~9 ~66 concrete 15 
setblock ~28 ~9 ~9 stained_hardened_clay 7  
fill ~28 ~9 ~29 ~28 ~10 ~29 concrete 15 
setblock ~28 ~9 ~61 concrete 15  
fill ~29 ~9 ~9 ~30 ~9 ~9 stained_hardened_clay 15  
fill ~29 ~9 ~28 ~29 ~10 ~28 concrete 15  
fill ~30 ~9 ~23 ~30 ~10 ~23 concrete 15  
fill ~30 ~9 ~67 ~32 ~9 ~67 concrete 15  
fill ~31 ~9 ~9 ~31 ~10 ~9 stained_hardened_clay 7  
fill ~31 ~9 ~27 ~32 ~9 ~27 concrete 15  
fill ~31 ~9 ~63 ~31 ~12 ~63 concrete 15  
fill ~32 ~9 ~8 ~36 ~9 ~8 stained_hardened_clay 7  
fill ~32 ~9 ~64 ~34 ~9 ~64 concrete 15  
fill ~33 ~9 ~26 ~35 ~9 ~26 concrete 15  
fill ~33 ~9 ~68 ~36 ~9 ~68 concrete 15  
fill ~35 ~9 ~65 ~37 ~9 ~65 concrete 15  
fill ~36 ~9 ~25 ~39 ~9 ~25 concrete 15  
fill ~37 ~9 ~7 ~42 ~9 ~7 stained_hardened_clay 7 
setblock ~37 ~9 ~21 stained_hardened_clay 7  
fill ~37 ~9 ~69 ~39 ~9 ~69 concrete 15  
fill ~38 ~9 ~65 ~38 ~13 ~65 stained_hardened_clay 15  
fill ~39 ~9 ~66 ~40 ~9 ~66 concrete 15  
fill ~40 ~9 ~24 ~43 ~9 ~24 concrete 15  
fill ~40 ~9 ~70 ~43 ~9 ~70 concrete 15  
fill ~41 ~9 ~66 ~41 ~12 ~66 stained_hardened_clay 15  
fill ~43 ~9 ~6 ~51 ~9 ~6 stained_hardened_clay 7  
fill ~44 ~9 ~23 ~46 ~9 ~23 concrete 15  
fill ~44 ~9 ~67 ~44 ~12 ~67 concrete 15  
fill ~44 ~9 ~71 ~46 ~9 ~71 concrete 15  
fill ~45 ~9 ~67 ~45 ~13 ~67 stained_hardened_clay 15 
setblock ~46 ~9 ~68 stained_hardened_clay 15 
setblock ~47 ~9 ~22 concrete 15  
fill ~47 ~9 ~68 ~48 ~9 ~68 concrete 15 
setblock ~47 ~9 ~72 concrete 15  
fill ~48 ~9 ~23 ~50 ~9 ~23 concrete 15  
fill ~48 ~9 ~71 ~50 ~9 ~71 concrete 15  
fill ~49 ~9 ~67 ~49 ~13 ~67 stained_hardened_clay 15  
fill ~51 ~9 ~24 ~54 ~9 ~24 concrete 15  
fill ~51 ~9 ~70 ~54 ~9 ~70 concrete 15  
fill ~52 ~9 ~7 ~57 ~9 ~7 stained_hardened_clay 7  
fill ~53 ~9 ~66 ~53 ~12 ~66 stained_hardened_clay 15  
fill ~54 ~9 ~66 ~55 ~9 ~66 concrete 15  
fill ~55 ~9 ~25 ~58 ~9 ~25 concrete 15  
fill ~55 ~9 ~69 ~57 ~9 ~69 concrete 15  
fill ~56 ~9 ~65 ~56 ~13 ~65 stained_hardened_clay 15 
setblock ~57 ~9 ~21 stained_hardened_clay 12  
fill ~57 ~9 ~65 ~59 ~9 ~65 concrete 15  
fill ~58 ~9 ~8 ~62 ~9 ~8 stained_hardened_clay 7  
fill ~58 ~9 ~68 ~61 ~9 ~68 concrete 15  
fill ~59 ~9 ~26 ~61 ~9 ~26 concrete 15  
fill ~60 ~9 ~64 ~62 ~9 ~64 concrete 15  
fill ~62 ~9 ~27 ~65 ~9 ~27 concrete 15  
fill ~62 ~9 ~67 ~64 ~9 ~67 concrete 15  
fill ~63 ~9 ~9 ~63 ~10 ~9 stained_hardened_clay 7  
fill ~63 ~9 ~63 ~63 ~12 ~63 concrete 15  
fill ~64 ~9 ~9 ~65 ~9 ~9 stained_hardened_clay 15  
fill ~64 ~9 ~23 ~64 ~10 ~23 concrete 15  
fill ~65 ~9 ~28 ~65 ~10 ~28 concrete 15  
fill ~65 ~9 ~66 ~67 ~9 ~66 concrete 15 
setblock ~66 ~9 ~9 stained_hardened_clay 7  
fill ~66 ~9 ~29 ~66 ~10 ~29 concrete 15 
setblock ~66 ~9 ~61 concrete 15  
fill ~67 ~9 ~10 ~71 ~9 ~10 stained_hardened_clay 7  
fill ~67 ~9 ~31 ~67 ~10 ~31 concrete 15 
setblock ~67 ~9 ~61 stained_hardened_clay 15  
fill ~68 ~9 ~24 ~69 ~9 ~24 concrete 15  
fill ~68 ~9 ~65 ~68 ~10 ~65 concrete 15  
fill ~69 ~9 ~34 ~69 ~10 ~34 concrete 15  
fill ~69 ~9 ~64 ~69 ~10 ~64 concrete 15  
fill ~70 ~9 ~36 ~70 ~11 ~36 concrete 15  
fill ~70 ~9 ~58 ~70 ~11 ~58 concrete 15  
fill ~71 ~9 ~28 ~71 ~10 ~28 concrete 15 
setblock ~71 ~9 ~63 concrete 15 
setblock ~72 ~9 ~11 stained_hardened_clay 15  
fill ~72 ~9 ~39 ~72 ~10 ~39 concrete 15  
fill ~72 ~9 ~62 ~72 ~10 ~62 concrete 15  
fill ~73 ~9 ~11 ~74 ~9 ~11 stained_hardened_clay 7  
fill ~73 ~9 ~41 ~73 ~11 ~41 concrete 15  
fill ~73 ~9 ~56 ~73 ~11 ~56 concrete 15  
fill ~73 ~9 ~61 ~74 ~9 ~61 concrete 15  
fill ~74 ~9 ~55 ~74 ~11 ~55 concrete 15  
fill ~75 ~9 ~11 ~76 ~9 ~11 stained_hardened_clay 15  
fill ~75 ~9 ~44 ~75 ~10 ~44 concrete 15 
setblock ~75 ~9 ~60 concrete 15  
fill ~76 ~9 ~59 ~76 ~10 ~59 concrete 15  
fill ~77 ~9 ~12 ~78 ~9 ~12 stained_hardened_clay 15  
fill ~77 ~9 ~47 ~77 ~10 ~47 concrete 15  
fill ~77 ~9 ~53 ~77 ~11 ~53 concrete 15  
fill ~77 ~9 ~58 ~78 ~9 ~58 concrete 15  
fill ~78 ~9 ~49 ~78 ~10 ~49 concrete 15 
setblock ~79 ~9 ~12 stained_hardened_clay 7  
fill ~79 ~9 ~51 ~79 ~10 ~51 concrete 15 
setblock ~80 ~9 ~12 stained_hardened_clay 15
fill ~81 ~9 ~13 ~84 ~9 ~13 stained_hardened_clay 15  
fill ~9 ~10 ~14 ~11 ~10 ~14 stained_hardened_clay 15  
fill ~9 ~10 ~51 ~9 ~10 ~52 concrete 15  
fill ~10 ~10 ~49 ~10 ~10 ~50 concrete 15  
fill ~10 ~10 ~53 ~11 ~10 ~53 concrete 15  
fill ~11 ~10 ~48 ~11 ~11 ~48 concrete 15  
fill ~12 ~10 ~13 ~14 ~10 ~13 stained_hardened_clay 15  
fill ~12 ~10 ~46 ~12 ~10 ~47 concrete 15  
fill ~12 ~10 ~54 ~12 ~11 ~54 concrete 15  
fill ~13 ~10 ~44 ~13 ~10 ~45 concrete 15 
setblock ~13 ~10 ~55 concrete 15 
setblock ~14 ~10 ~43 concrete 15  
fill ~14 ~10 ~56 ~15 ~10 ~56 concrete 15  
fill ~15 ~10 ~13 ~15 ~11 ~13 stained_hardened_clay 7  
fill ~15 ~10 ~41 ~15 ~10 ~42 concrete 15 
setblock ~16 ~10 ~12 stained_hardened_clay 7  
fill ~16 ~10 ~40 ~16 ~11 ~40 concrete 15  
fill ~16 ~10 ~50 ~16 ~11 ~50 concrete 15  
fill ~16 ~10 ~52 ~16 ~12 ~52 concrete 15  
fill ~16 ~10 ~57 ~16 ~11 ~57 concrete 15  
fill ~17 ~10 ~12 ~19 ~10 ~12 stained_hardened_clay 15  
fill ~17 ~10 ~38 ~17 ~10 ~39 concrete 15  
fill ~17 ~10 ~48 ~17 ~11 ~48 concrete 15 
setblock ~17 ~10 ~58 concrete 15  
fill ~18 ~10 ~36 ~18 ~10 ~37 concrete 15 
setblock ~18 ~10 ~46 concrete 15 
setblock ~19 ~10 ~35 concrete 15 
setblock ~19 ~10 ~45 concrete 15  
fill ~19 ~10 ~54 ~19 ~12 ~54 concrete 15  
fill ~19 ~10 ~59 ~19 ~11 ~59 concrete 15  
fill ~20 ~10 ~12 ~20 ~11 ~12 stained_hardened_clay 7  
fill ~20 ~10 ~33 ~20 ~10 ~34 concrete 15  
fill ~20 ~10 ~43 ~20 ~11 ~43 concrete 15  
fill ~20 ~10 ~60 ~20 ~11 ~60 concrete 15  
fill ~21 ~10 ~11 ~25 ~10 ~11 stained_hardened_clay 7  
fill ~21 ~10 ~32 ~21 ~11 ~32 concrete 15 
setblock ~21 ~10 ~61 concrete 15  
fill ~22 ~10 ~30 ~22 ~10 ~31 concrete 15  
fill ~22 ~10 ~40 ~22 ~12 ~40 concrete 15  
fill ~23 ~10 ~29 ~23 ~11 ~29 concrete 15  
fill ~23 ~10 ~38 ~23 ~11 ~38 concrete 15  
fill ~23 ~10 ~57 ~23 ~12 ~57 concrete 15  
fill ~23 ~10 ~62 ~23 ~11 ~62 concrete 15 
setblock ~24 ~10 ~27 concrete 15  
fill ~24 ~10 ~63 ~24 ~11 ~63 concrete 15  
fill ~25 ~10 ~25 ~25 ~10 ~26 concrete 15  
fill ~25 ~10 ~35 ~25 ~11 ~35 concrete 15  
fill ~26 ~10 ~10 ~29 ~10 ~10 stained_hardened_clay 7  
fill ~26 ~10 ~24 ~29 ~10 ~24 concrete 15  
fill ~26 ~10 ~33 ~26 ~11 ~33 concrete 15  
fill ~26 ~10 ~59 ~26 ~13 ~59 concrete 15  
fill ~27 ~10 ~32 ~27 ~12 ~32 concrete 15  
fill ~27 ~10 ~60 ~27 ~12 ~60 stained_hardened_clay 15  
fill ~27 ~10 ~65 ~27 ~11 ~65 concrete 15  
fill ~28 ~10 ~30 ~28 ~11 ~30 concrete 15  
fill ~28 ~10 ~61 ~28 ~11 ~61 stained_hardened_clay 15  
fill ~28 ~10 ~66 ~30 ~10 ~66 concrete 15 
setblock ~30 ~10 ~9 stained_hardened_clay 7  
fill ~30 ~10 ~28 ~30 ~12 ~28 concrete 15  
fill ~31 ~10 ~23 ~32 ~10 ~23 concrete 15  
fill ~31 ~10 ~27 ~33 ~10 ~27 concrete 15  
fill ~31 ~10 ~67 ~33 ~10 ~67 concrete 15  
fill ~32 ~10 ~9 ~34 ~10 ~9 stained_hardened_clay 7  
fill ~32 ~10 ~63 ~32 ~14 ~63 concrete 15 
setblock ~33 ~10 ~22 concrete 15  
fill ~33 ~10 ~64 ~35 ~10 ~64 concrete 15 
setblock ~34 ~10 ~22 stained_hardened_clay 7  
fill ~34 ~10 ~26 ~37 ~10 ~26 concrete 15 
setblock ~34 ~10 ~68 concrete 15  
fill ~35 ~10 ~8 ~39 ~10 ~8 stained_hardened_clay 7 
setblock ~35 ~10 ~22 stained_hardened_clay 15  
fill ~35 ~10 ~68 ~35 ~11 ~68 stained_hardened_clay 15  
fill ~36 ~10 ~22 ~36 ~11 ~22 concrete 15  
fill ~36 ~10 ~65 ~37 ~10 ~65 concrete 15  
fill ~36 ~10 ~68 ~37 ~10 ~68 concrete 15  
fill ~37 ~10 ~21 ~39 ~10 ~21 concrete 15  
fill ~38 ~10 ~25 ~40 ~10 ~25 concrete 15  
fill ~38 ~10 ~69 ~40 ~10 ~69 concrete 15  
fill ~39 ~10 ~65 ~39 ~11 ~65 concrete 15  
fill ~40 ~10 ~7 ~45 ~10 ~7 stained_hardened_clay 7 
setblock ~40 ~10 ~21 concrete 12 
setblock ~40 ~10 ~66 concrete 15 
setblock ~41 ~10 ~20 stained_hardened_clay 7 
setblock ~41 ~10 ~25 stained_hardened_clay 15 
setblock ~41 ~10 ~70 stained_hardened_clay 15  
fill ~42 ~10 ~20 ~43 ~10 ~20 concrete 15  
fill ~42 ~10 ~24 ~44 ~10 ~24 concrete 15  
fill ~42 ~10 ~66 ~42 ~13 ~66 concrete 15  
fill ~42 ~10 ~70 ~44 ~10 ~70 concrete 15  
fill ~44 ~10 ~19 ~45 ~10 ~19 stained_hardened_clay 12  
fill ~45 ~10 ~23 ~46 ~10 ~23 concrete 15  
fill ~45 ~10 ~71 ~49 ~10 ~71 concrete 15  
fill ~46 ~10 ~6 ~48 ~10 ~6 stained_hardened_clay 7  
fill ~46 ~10 ~19 ~48 ~10 ~19 concrete 15  
fill ~46 ~10 ~68 ~48 ~10 ~68 concrete 15  
fill ~47 ~10 ~23 ~47 ~11 ~23 stained_hardened_clay 15  
fill ~48 ~10 ~23 ~49 ~10 ~23 concrete 15  
fill ~49 ~10 ~7 ~54 ~10 ~7 stained_hardened_clay 7 
setblock ~49 ~10 ~19 stained_hardened_clay 7 
setblock ~50 ~10 ~19 concrete 12  
fill ~50 ~10 ~24 ~52 ~10 ~24 concrete 15  
fill ~50 ~10 ~70 ~53 ~10 ~70 concrete 15 
setblock ~51 ~10 ~20 stained_hardened_clay 15  
fill ~52 ~10 ~20 ~52 ~11 ~20 concrete 15  
fill ~52 ~10 ~66 ~52 ~13 ~66 concrete 15 
setblock ~53 ~10 ~20 stained_hardened_clay 15  
fill ~53 ~10 ~25 ~53 ~12 ~25 stained_hardened_clay 15 
setblock ~54 ~10 ~21 stained_hardened_clay 12  
fill ~54 ~10 ~25 ~56 ~10 ~25 concrete 15  
fill ~54 ~10 ~66 ~54 ~7 ~66 concrete 15  
fill ~54 ~10 ~69 ~56 ~10 ~69 concrete 15  
fill ~55 ~10 ~8 ~59 ~10 ~8 stained_hardened_clay 7 
setblock ~55 ~10 ~21 stained_hardened_clay 15  
fill ~55 ~10 ~65 ~55 ~11 ~65 concrete 15  
fill ~56 ~10 ~21 ~57 ~10 ~21 concrete 15  
fill ~57 ~10 ~26 ~60 ~10 ~26 concrete 15  
fill ~57 ~10 ~65 ~58 ~10 ~65 concrete 15  
fill ~57 ~10 ~68 ~58 ~10 ~68 concrete 15  
fill ~58 ~10 ~22 ~59 ~10 ~22 stained_hardened_clay 15  
fill ~59 ~10 ~64 ~61 ~10 ~64 concrete 15  
fill ~59 ~10 ~68 ~59 ~11 ~68 stained_hardened_clay 15  
fill ~60 ~10 ~9 ~64 ~10 ~9 stained_hardened_clay 7 
setblock ~60 ~10 ~22 stained_hardened_clay 7 
setblock ~60 ~10 ~68 concrete 15 
setblock ~61 ~10 ~22 stained_hardened_clay 15 
setblock ~61 ~10 ~27 stained_hardened_clay 15  
fill ~61 ~10 ~67 ~63 ~10 ~67 concrete 15  
fill ~62 ~10 ~23 ~64 ~10 ~23 concrete 15  
fill ~62 ~10 ~27 ~63 ~10 ~27 concrete 15  
fill ~62 ~10 ~63 ~62 ~14 ~63 concrete 15  
fill ~64 ~10 ~28 ~64 ~12 ~28 concrete 15  
fill ~64 ~10 ~66 ~66 ~10 ~66 concrete 15  
fill ~65 ~10 ~10 ~68 ~10 ~10 stained_hardened_clay 7  
fill ~65 ~10 ~24 ~68 ~10 ~24 concrete 15  
fill ~66 ~10 ~30 ~66 ~11 ~30 concrete 15  
fill ~66 ~10 ~61 ~66 ~11 ~61 stained_hardened_clay 15  
fill ~67 ~10 ~32 ~67 ~12 ~32 concrete 15  
fill ~67 ~10 ~60 ~67 ~12 ~60 stained_hardened_clay 15  
fill ~67 ~10 ~65 ~67 ~12 ~65 concrete 15  
fill ~68 ~10 ~33 ~68 ~11 ~33 concrete 15  
fill ~68 ~10 ~59 ~68 ~13 ~59 concrete 15  
fill ~69 ~10 ~11 ~73 ~10 ~11 stained_hardened_clay 7  
fill ~69 ~10 ~25 ~69 ~10 ~26 concrete 15  
fill ~69 ~10 ~35 ~69 ~11 ~35 concrete 15 
setblock ~70 ~10 ~27 concrete 15  
fill ~70 ~10 ~63 ~70 ~11 ~63 concrete 15  
fill ~71 ~10 ~29 ~71 ~11 ~29 concrete 15  
fill ~71 ~10 ~38 ~71 ~11 ~38 concrete 15  
fill ~71 ~10 ~57 ~71 ~12 ~57 concrete 15  
fill ~71 ~10 ~62 ~71 ~11 ~62 concrete 15  
fill ~72 ~10 ~30 ~72 ~10 ~31 concrete 15  
fill ~72 ~10 ~40 ~72 ~12 ~40 concrete 15  
fill ~73 ~10 ~32 ~73 ~11 ~32 concrete 15  
fill ~73 ~10 ~61 ~73 ~9 ~61 concrete 15  
fill ~74 ~10 ~12 ~74 ~11 ~12 stained_hardened_clay 7  
fill ~74 ~10 ~33 ~74 ~10 ~34 concrete 15  
fill ~74 ~10 ~43 ~74 ~11 ~43 concrete 15  
fill ~74 ~10 ~60 ~74 ~11 ~60 concrete 15  
fill ~75 ~10 ~12 ~77 ~10 ~12 stained_hardened_clay 15 
setblock ~75 ~10 ~35 concrete 15 
setblock ~75 ~10 ~45 concrete 15  
fill ~75 ~10 ~54 ~75 ~12 ~54 concrete 15  
fill ~75 ~10 ~59 ~75 ~11 ~59 concrete 15  
fill ~76 ~10 ~36 ~76 ~10 ~37 concrete 15 
setblock ~76 ~10 ~46 concrete 15  
fill ~77 ~10 ~38 ~77 ~10 ~39 concrete 15  
fill ~77 ~10 ~48 ~77 ~11 ~48 concrete 15  
fill ~77 ~10 ~58 ~77 ~9 ~58 concrete 15 
setblock ~78 ~10 ~12 stained_hardened_clay 7  
fill ~78 ~10 ~40 ~78 ~11 ~40 concrete 15  
fill ~78 ~10 ~50 ~78 ~11 ~50 concrete 15  
fill ~78 ~10 ~52 ~78 ~12 ~52 concrete 15  
fill ~78 ~10 ~57 ~78 ~11 ~57 concrete 15  
fill ~79 ~10 ~13 ~79 ~11 ~13 stained_hardened_clay 7  
fill ~79 ~10 ~41 ~79 ~10 ~42 concrete 15  
fill ~79 ~10 ~56 ~80 ~10 ~56 concrete 15  
fill ~80 ~10 ~13 ~82 ~10 ~13 stained_hardened_clay 15 
setblock ~80 ~10 ~43 concrete 15  
fill ~81 ~10 ~44 ~81 ~10 ~45 concrete 15 
setblock ~81 ~10 ~55 concrete 15  
fill ~82 ~10 ~46 ~82 ~10 ~47 concrete 15  
fill ~82 ~10 ~54 ~82 ~11 ~54 concrete 15  
fill ~83 ~10 ~14 ~85 ~10 ~14 stained_hardened_clay 15  
fill ~83 ~10 ~48 ~83 ~11 ~48 concrete 15  
fill ~83 ~10 ~53 ~84 ~10 ~53 concrete 15  
fill ~84 ~10 ~49 ~84 ~10 ~50 concrete 15  
fill ~85 ~10 ~51 ~85 ~10 ~52 concrete 15 
setblock ~9 ~11 ~15 stained_hardened_clay 15  
fill ~10 ~11 ~14 ~13 ~11 ~14 stained_hardened_clay 15  
fill ~10 ~11 ~50 ~10 ~11 ~52 concrete 15  
fill ~11 ~11 ~49 ~11 ~12 ~49 concrete 15 
setblock ~11 ~11 ~53 concrete 15 
setblock ~12 ~11 ~47 concrete 15  
fill ~13 ~11 ~45 ~13 ~11 ~46 concrete 15  
fill ~13 ~11 ~54 ~13 ~12 ~54 concrete 15 
setblock ~14 ~11 ~13 stained_hardened_clay 15 
setblock ~14 ~11 ~44 concrete 15  
fill ~14 ~11 ~55 ~14 ~12 ~55 concrete 15  
fill ~15 ~11 ~42 ~15 ~11 ~43 concrete 15 
setblock ~15 ~11 ~56 concrete 15  
fill ~16 ~11 ~13 ~17 ~11 ~13 stained_hardened_clay 7  
fill ~16 ~11 ~41 ~16 ~12 ~41 concrete 15  
fill ~16 ~11 ~51 ~16 ~12 ~51 concrete 15 
setblock ~17 ~11 ~39 concrete 15  
fill ~17 ~11 ~49 ~17 ~12 ~49 concrete 15  
fill ~17 ~11 ~57 ~17 ~12 ~57 concrete 15 
setblock ~18 ~11 ~13 stained_hardened_clay 15  
fill ~18 ~11 ~37 ~18 ~11 ~38 concrete 15 
setblock ~18 ~11 ~46 stained_hardened_clay 15  
fill ~18 ~11 ~47 ~18 ~12 ~47 concrete 15  
fill ~18 ~11 ~53 ~18 ~12 ~53 concrete 15  
fill ~18 ~11 ~58 ~18 ~12 ~58 concrete 15 
setblock ~19 ~11 ~12 stained_hardened_clay 15 
setblock ~19 ~11 ~36 concrete 15  
fill ~19 ~11 ~45 ~19 ~12 ~45 stained_hardened_clay 15  
fill ~20 ~11 ~34 ~20 ~11 ~35 concrete 15  
fill ~20 ~11 ~44 ~20 ~13 ~44 concrete 15  
fill ~21 ~11 ~12 ~23 ~11 ~12 stained_hardened_clay 7  
fill ~21 ~11 ~33 ~21 ~12 ~33 concrete 15  
fill ~21 ~11 ~42 ~21 ~12 ~42 concrete 15  
fill ~21 ~11 ~60 ~21 ~12 ~60 concrete 15 
setblock ~22 ~11 ~31 concrete 15  
fill ~22 ~11 ~56 ~22 ~13 ~56 concrete 15  
fill ~22 ~11 ~61 ~22 ~12 ~61 concrete 15  
fill ~23 ~11 ~30 ~23 ~12 ~30 concrete 15  
fill ~23 ~11 ~39 ~23 ~12 ~39 concrete 15  
fill ~24 ~11 ~11 ~27 ~11 ~11 stained_hardened_clay 7 
setblock ~24 ~11 ~28 concrete 15  
fill ~24 ~11 ~37 ~24 ~12 ~37 concrete 15 
setblock ~25 ~11 ~26 concrete 15 
setblock ~25 ~11 ~27 stained_hardened_clay 15  
fill ~25 ~11 ~58 ~25 ~13 ~58 concrete 15  
fill ~25 ~11 ~63 ~25 ~12 ~63 stained_hardened_clay 15  
fill ~26 ~11 ~25 ~27 ~11 ~25 concrete 15  
fill ~26 ~11 ~34 ~26 ~12 ~34 concrete 15  
fill ~26 ~11 ~64 ~26 ~12 ~64 concrete 15  
fill ~28 ~11 ~10 ~32 ~11 ~10 stained_hardened_clay 7  
fill ~28 ~11 ~24 ~31 ~11 ~24 concrete 15  
fill ~28 ~11 ~31 ~28 ~13 ~31 concrete 15 
setblock ~28 ~11 ~65 concrete 15  
fill ~29 ~11 ~29 ~29 ~12 ~29 concrete 15  
fill ~29 ~11 ~66 ~31 ~11 ~66 concrete 15  
fill ~30 ~11 ~62 ~30 ~13 ~62 concrete 15  
fill ~31 ~11 ~28 ~31 ~12 ~28 concrete 15  
fill ~32 ~11 ~23 ~34 ~11 ~23 concrete 15  
fill ~32 ~11 ~27 ~35 ~11 ~27 concrete 15  
fill ~32 ~11 ~67 ~33 ~11 ~67 concrete 15  
fill ~33 ~11 ~9 ~37 ~11 ~9 stained_hardened_clay 7  
fill ~33 ~11 ~63 ~33 ~15 ~63 concrete 15  
fill ~34 ~11 ~64 ~36 ~11 ~64 concrete 15  
fill ~34 ~11 ~67 ~34 ~13 ~67 stained_hardened_clay 15 
setblock ~35 ~11 ~22 concrete 15  
fill ~36 ~11 ~26 ~39 ~11 ~26 concrete 15  
fill ~36 ~11 ~68 ~36 ~9 ~68 concrete 15  
fill ~37 ~11 ~22 ~38 ~11 ~22 concrete 15 
setblock ~37 ~11 ~65 concrete 15  
fill ~37 ~11 ~68 ~37 ~13 ~68 stained_hardened_clay 15  
fill ~38 ~11 ~8 ~41 ~11 ~8 stained_hardened_clay 7  
fill ~38 ~11 ~68 ~38 ~13 ~68 concrete 15  
fill ~39 ~11 ~21 ~41 ~11 ~21 concrete 15  
fill ~39 ~11 ~69 ~40 ~11 ~69 concrete 15  
fill ~40 ~11 ~25 ~42 ~11 ~25 concrete 15 
setblock ~40 ~11 ~66 stained_hardened_clay 15  
fill ~41 ~11 ~69 ~41 ~13 ~69 stained_hardened_clay 15  
fill ~42 ~11 ~8 ~42 ~12 ~8 concrete 7  
fill ~42 ~11 ~20 ~45 ~11 ~20 concrete 15  
fill ~42 ~11 ~70 ~45 ~11 ~70 concrete 15 
setblock ~43 ~11 ~7 concrete 7  
fill ~43 ~11 ~24 ~46 ~11 ~24 concrete 15  
fill ~43 ~11 ~66 ~43 ~15 ~66 concrete 15  
fill ~44 ~11 ~7 ~50 ~11 ~7 stained_hardened_clay 7  
fill ~46 ~11 ~19 ~46 ~10 ~19 concrete 15  
fill ~46 ~11 ~67 ~46 ~14 ~67 concrete 15  
fill ~46 ~11 ~71 ~48 ~11 ~71 concrete 15 
setblock ~47 ~11 ~19 stained_hardened_clay 15 
setblock ~47 ~11 ~68 concrete 15 
setblock ~48 ~11 ~19 concrete 15  
fill ~48 ~11 ~24 ~51 ~11 ~24 concrete 15  
fill ~48 ~11 ~67 ~48 ~14 ~67 concrete 15  
fill ~49 ~11 ~20 ~52 ~11 ~20 concrete 15  
fill ~49 ~11 ~70 ~52 ~11 ~70 concrete 15 
setblock ~51 ~11 ~7 concrete 7  
fill ~51 ~11 ~66 ~51 ~15 ~66 concrete 15  
fill ~52 ~11 ~8 ~52 ~12 ~8 concrete 7  
fill ~52 ~11 ~25 ~52 ~12 ~25 concrete 15  
fill ~53 ~11 ~8 ~56 ~11 ~8 stained_hardened_clay 7  
fill ~53 ~11 ~21 ~55 ~11 ~21 concrete 15  
fill ~53 ~11 ~69 ~53 ~13 ~69 stained_hardened_clay 15  
fill ~54 ~11 ~25 ~54 ~10 ~25 concrete 15 
setblock ~54 ~11 ~66 stained_hardened_clay 15  
fill ~54 ~11 ~69 ~55 ~11 ~69 concrete 15  
fill ~55 ~11 ~26 ~58 ~11 ~26 concrete 15  
fill ~56 ~11 ~22 ~59 ~11 ~22 concrete 15  
fill ~56 ~11 ~68 ~56 ~13 ~68 concrete 15  
fill ~57 ~11 ~9 ~61 ~11 ~9 stained_hardened_clay 7  
fill ~57 ~11 ~65 ~57 ~8 ~65 concrete 15  
fill ~57 ~11 ~68 ~57 ~13 ~68 stained_hardened_clay 15  
fill ~58 ~11 ~64 ~61 ~11 ~64 concrete 15  
fill ~58 ~11 ~68 ~58 ~12 ~68 concrete 15  
fill ~59 ~11 ~27 ~62 ~11 ~27 concrete 15  
fill ~60 ~11 ~23 ~62 ~11 ~23 concrete 15  
fill ~60 ~11 ~67 ~60 ~13 ~67 stained_hardened_clay 15  
fill ~61 ~11 ~67 ~62 ~11 ~67 concrete 15  
fill ~62 ~11 ~10 ~66 ~11 ~10 stained_hardened_clay 7  
fill ~63 ~11 ~24 ~66 ~11 ~24 concrete 15  
fill ~63 ~11 ~28 ~63 ~12 ~28 concrete 15  
fill ~63 ~11 ~66 ~65 ~11 ~66 concrete 15  
fill ~64 ~11 ~62 ~64 ~13 ~62 concrete 15  
fill ~65 ~11 ~29 ~65 ~12 ~29 concrete 15 
setblock ~65 ~11 ~62 stained_hardened_clay 15  
fill ~66 ~11 ~31 ~66 ~13 ~31 concrete 15  
fill ~66 ~11 ~65 ~66 ~14 ~65 stained_hardened_clay 15  
fill ~67 ~11 ~11 ~70 ~11 ~11 stained_hardened_clay 7  
fill ~67 ~11 ~25 ~68 ~11 ~25 concrete 15  
fill ~68 ~11 ~34 ~68 ~12 ~34 concrete 15  
fill ~68 ~11 ~64 ~68 ~12 ~64 concrete 15  
fill ~69 ~11 ~26 ~69 ~11 ~27 concrete 15  
fill ~69 ~11 ~58 ~69 ~13 ~58 concrete 15  
fill ~69 ~11 ~63 ~69 ~12 ~63 stained_hardened_clay 15 
setblock ~70 ~11 ~28 concrete 15  
fill ~70 ~11 ~37 ~70 ~12 ~37 concrete 15  
fill ~71 ~11 ~12 ~75 ~11 ~12 stained_hardened_clay 7  
fill ~71 ~11 ~30 ~71 ~12 ~30 concrete 15  
fill ~71 ~11 ~39 ~71 ~12 ~39 concrete 15 
setblock ~72 ~11 ~31 concrete 15 
setblock ~72 ~11 ~56 concrete 15  
fill ~72 ~11 ~61 ~72 ~12 ~61 concrete 15  
fill ~73 ~11 ~33 ~73 ~12 ~33 concrete 15  
fill ~73 ~11 ~42 ~73 ~12 ~42 concrete 15  
fill ~73 ~11 ~60 ~73 ~12 ~60 concrete 15  
fill ~74 ~11 ~34 ~74 ~11 ~35 concrete 15  
fill ~74 ~11 ~44 ~74 ~13 ~44 concrete 15 
setblock ~75 ~11 ~36 concrete 15  
fill ~75 ~11 ~45 ~75 ~12 ~45 stained_hardened_clay 15 
setblock ~76 ~11 ~13 stained_hardened_clay 15  
fill ~76 ~11 ~37 ~76 ~11 ~38 concrete 15 
setblock ~76 ~11 ~46 stained_hardened_clay 15  
fill ~76 ~11 ~47 ~76 ~12 ~47 concrete 15  
fill ~76 ~11 ~53 ~76 ~12 ~53 concrete 15  
fill ~76 ~11 ~58 ~76 ~12 ~58 concrete 15  
fill ~77 ~11 ~13 ~79 ~11 ~13 stained_hardened_clay 7 
setblock ~77 ~11 ~39 concrete 15  
fill ~77 ~11 ~49 ~77 ~12 ~49 concrete 15  
fill ~77 ~11 ~57 ~77 ~12 ~57 concrete 15  
fill ~78 ~11 ~41 ~78 ~12 ~41 concrete 15  
fill ~78 ~11 ~51 ~78 ~12 ~51 concrete 15  
fill ~79 ~11 ~42 ~79 ~11 ~43 concrete 15  
fill ~79 ~11 ~56 ~79 ~10 ~56 concrete 15  
fill ~80 ~11 ~13 ~80 ~10 ~13 stained_hardened_clay 15 
setblock ~80 ~11 ~44 concrete 15  
fill ~80 ~11 ~55 ~80 ~12 ~55 concrete 15  
fill ~81 ~11 ~14 ~84 ~11 ~14 stained_hardened_clay 15  
fill ~81 ~11 ~45 ~81 ~11 ~46 concrete 15  
fill ~81 ~11 ~54 ~81 ~12 ~54 concrete 15 
setblock ~82 ~11 ~47 concrete 15  
fill ~83 ~11 ~49 ~83 ~12 ~49 concrete 15  
fill ~83 ~11 ~53 ~83 ~10 ~53 concrete 15  
fill ~84 ~11 ~50 ~84 ~11 ~52 concrete 15 
setblock ~85 ~11 ~15 stained_hardened_clay 15  
fill ~10 ~12 ~15 ~12 ~12 ~15 stained_hardened_clay 15  
fill ~10 ~12 ~51 ~10 ~12 ~52 concrete 15  
fill ~11 ~12 ~50 ~11 ~13 ~50 concrete 15  
fill ~11 ~12 ~52 ~11 ~13 ~52 concrete 15 
setblock ~12 ~12 ~48 concrete 15  
fill ~12 ~12 ~53 ~12 ~13 ~53 concrete 15  
fill ~13 ~12 ~14 ~14 ~12 ~14 stained_hardened_clay 15  
fill ~13 ~12 ~46 ~13 ~12 ~47 concrete 15 
setblock ~14 ~12 ~45 concrete 15  
fill ~15 ~12 ~14 ~16 ~12 ~14 stained_hardened_clay 7  
fill ~15 ~12 ~43 ~15 ~12 ~44 concrete 15  
fill ~15 ~12 ~55 ~15 ~13 ~55 concrete 15  
fill ~16 ~12 ~42 ~16 ~13 ~42 concrete 15  
fill ~16 ~12 ~56 ~16 ~13 ~56 concrete 15  
fill ~17 ~12 ~13 ~21 ~12 ~13 stained_hardened_clay 7 
setblock ~17 ~12 ~40 concrete 15  
fill ~17 ~12 ~50 ~17 ~13 ~50 concrete 15  
fill ~17 ~12 ~52 ~17 ~14 ~52 stained_hardened_clay 15  
fill ~18 ~12 ~38 ~18 ~12 ~39 concrete 15  
fill ~18 ~12 ~48 ~18 ~13 ~48 concrete 15  
fill ~19 ~12 ~37 ~19 ~13 ~37 concrete 15  
fill ~19 ~12 ~46 ~19 ~13 ~46 stained_hardened_clay 15  
fill ~19 ~12 ~58 ~19 ~13 ~58 stained_hardened_clay 15  
fill ~20 ~12 ~35 ~20 ~12 ~36 concrete 15  
fill ~20 ~12 ~54 ~20 ~14 ~54 concrete 15  
fill ~20 ~12 ~59 ~20 ~13 ~59 concrete 15  
fill ~21 ~12 ~34 ~21 ~13 ~34 concrete 15  
fill ~21 ~12 ~43 ~21 ~14 ~43 concrete 15  
fill ~21 ~12 ~55 ~21 ~14 ~55 concrete 15  
fill ~22 ~12 ~12 ~25 ~12 ~12 stained_hardened_clay 7 
setblock ~22 ~12 ~32 concrete 15  
fill ~22 ~12 ~41 ~22 ~13 ~41 concrete 15  
fill ~23 ~12 ~31 ~23 ~13 ~31 concrete 15  
fill ~23 ~12 ~61 ~23 ~13 ~61 concrete 15  
fill ~24 ~12 ~29 ~24 ~13 ~29 concrete 15  
fill ~24 ~12 ~38 ~24 ~13 ~38 concrete 15  
fill ~24 ~12 ~57 ~24 ~14 ~57 concrete 15  
fill ~24 ~12 ~62 ~24 ~13 ~62 stained_hardened_clay 15  
fill ~25 ~12 ~27 ~25 ~12 ~28 concrete 15  
fill ~25 ~12 ~36 ~25 ~13 ~36 concrete 15  
fill ~26 ~12 ~11 ~27 ~12 ~11 concrete 7  
fill ~26 ~12 ~26 ~26 ~13 ~26 concrete 15  
fill ~26 ~12 ~35 ~26 ~14 ~35 concrete 15 
setblock ~27 ~12 ~25 concrete 15  
fill ~27 ~12 ~33 ~27 ~13 ~33 concrete 15  
fill ~27 ~12 ~65 ~28 ~12 ~65 stained_hardened_clay 15  
fill ~28 ~12 ~11 ~30 ~12 ~11 stained_hardened_clay 7  
fill ~28 ~12 ~25 ~29 ~12 ~25 stained_hardened_clay 15  
fill ~28 ~12 ~60 ~28 ~14 ~60 stained_hardened_clay 15  
fill ~29 ~12 ~30 ~29 ~14 ~30 concrete 15  
fill ~29 ~12 ~61 ~29 ~14 ~61 stained_hardened_clay 15  
fill ~29 ~12 ~65 ~29 ~15 ~65 concrete 15  
fill ~30 ~12 ~24 ~33 ~12 ~24 concrete 15 
setblock ~30 ~12 ~66 concrete 15  
fill ~31 ~12 ~10 ~35 ~12 ~10 stained_hardened_clay 7  
fill ~31 ~12 ~66 ~31 ~13 ~66 stained_hardened_clay 15  
fill ~32 ~12 ~28 ~33 ~12 ~28 concrete 15  
fill ~32 ~12 ~66 ~32 ~14 ~66 concrete 15 
setblock ~33 ~12 ~67 stained_hardened_clay 15  
fill ~34 ~12 ~23 ~36 ~12 ~23 concrete 15  
fill ~34 ~12 ~27 ~36 ~12 ~27 concrete 15  
fill ~34 ~12 ~64 ~36 ~12 ~64 concrete 15 
setblock ~35 ~12 ~67 concrete 15  
fill ~36 ~12 ~9 ~40 ~12 ~9 stained_hardened_clay 7 
setblock ~36 ~12 ~68 stained_hardened_clay 15  
fill ~37 ~12 ~22 ~40 ~12 ~22 concrete 15  
fill ~37 ~12 ~26 ~40 ~12 ~26 concrete 15  
fill ~37 ~12 ~64 ~37 ~16 ~64 stained_hardened_clay 15  
fill ~39 ~12 ~65 ~40 ~12 ~65 stained_hardened_clay 15  
fill ~39 ~12 ~68 ~39 ~13 ~68 concrete 15 
setblock ~40 ~12 ~69 stained_hardened_clay 15 
setblock ~41 ~12 ~8 stained_hardened_clay 7  
fill ~41 ~12 ~21 ~43 ~12 ~21 concrete 15 
setblock ~41 ~12 ~25 stained_hardened_clay 15  
fill ~42 ~12 ~25 ~44 ~12 ~25 concrete 15  
fill ~42 ~12 ~69 ~42 ~14 ~69 stained_hardened_clay 15  
fill ~43 ~12 ~8 ~44 ~12 ~8 concrete 7  
fill ~43 ~12 ~70 ~45 ~12 ~70 concrete 15  
fill ~44 ~12 ~20 ~46 ~12 ~20 concrete 15 
setblock ~45 ~12 ~8 stained_hardened_clay 7  
fill ~45 ~12 ~24 ~46 ~12 ~24 concrete 15  
fill ~46 ~12 ~7 ~48 ~12 ~7 stained_hardened_clay 7  
fill ~46 ~12 ~71 ~48 ~12 ~71 concrete 15  
fill ~47 ~12 ~20 ~47 ~13 ~20 stained_hardened_clay 15  
fill ~47 ~12 ~24 ~47 ~13 ~24 stained_hardened_clay 15  
fill ~47 ~12 ~67 ~47 ~16 ~67 concrete 15  
fill ~48 ~12 ~20 ~50 ~12 ~20 concrete 15  
fill ~48 ~12 ~24 ~49 ~12 ~24 concrete 15  
fill ~49 ~12 ~8 ~49 ~13 ~8 stained_hardened_clay 7  
fill ~49 ~12 ~70 ~51 ~12 ~70 concrete 15  
fill ~50 ~12 ~8 ~52 ~12 ~8 concrete 7  
fill ~50 ~12 ~25 ~52 ~12 ~25 concrete 15  
fill ~51 ~12 ~21 ~53 ~12 ~21 concrete 15 
setblock ~52 ~12 ~69 concrete 15  
fill ~53 ~12 ~8 ~53 ~11 ~8 stained_hardened_clay 7  
fill ~54 ~12 ~9 ~58 ~12 ~9 stained_hardened_clay 7  
fill ~54 ~12 ~22 ~57 ~12 ~22 concrete 15  
fill ~54 ~12 ~26 ~57 ~12 ~26 concrete 15  
fill ~54 ~12 ~65 ~56 ~12 ~65 stained_hardened_clay 15 
setblock ~54 ~12 ~69 stained_hardened_clay 15  
fill ~55 ~12 ~68 ~55 ~13 ~68 concrete 15  
fill ~57 ~12 ~64 ~57 ~16 ~64 stained_hardened_clay 15  
fill ~58 ~12 ~23 ~60 ~12 ~23 concrete 15  
fill ~58 ~12 ~27 ~60 ~12 ~27 concrete 15  
fill ~58 ~12 ~64 ~60 ~12 ~64 concrete 15  
fill ~59 ~12 ~10 ~63 ~12 ~10 stained_hardened_clay 7  
fill ~59 ~12 ~67 ~59 ~14 ~67 stained_hardened_clay 15  
fill ~61 ~12 ~24 ~64 ~12 ~24 concrete 15  
fill ~61 ~12 ~28 ~64 ~12 ~28 concrete 15  
fill ~61 ~12 ~63 ~61 ~15 ~63 concrete 15  
fill ~61 ~12 ~67 ~61 ~10 ~67 concrete 15  
fill ~62 ~12 ~66 ~62 ~14 ~66 concrete 15  
fill ~63 ~12 ~66 ~63 ~13 ~66 stained_hardened_clay 15  
fill ~64 ~12 ~11 ~66 ~12 ~11 stained_hardened_clay 7 
setblock ~64 ~12 ~66 concrete 15  
fill ~65 ~12 ~25 ~66 ~12 ~25 stained_hardened_clay 15  
fill ~65 ~12 ~30 ~65 ~14 ~30 concrete 15  
fill ~65 ~12 ~61 ~65 ~14 ~61 stained_hardened_clay 15  
fill ~65 ~12 ~65 ~65 ~15 ~65 concrete 15  
fill ~66 ~12 ~60 ~66 ~14 ~60 stained_hardened_clay 15  
fill ~67 ~12 ~11 ~68 ~12 ~11 concrete 7  
fill ~67 ~12 ~25 ~67 ~11 ~25 concrete 15  
fill ~67 ~12 ~33 ~67 ~13 ~33 concrete 15  
fill ~68 ~12 ~26 ~68 ~13 ~26 concrete 15  
fill ~68 ~12 ~35 ~68 ~14 ~35 concrete 15  
fill ~69 ~12 ~12 ~72 ~12 ~12 stained_hardened_clay 7  
fill ~69 ~12 ~27 ~69 ~12 ~28 concrete 15  
fill ~69 ~12 ~36 ~69 ~13 ~36 concrete 15  
fill ~70 ~12 ~29 ~70 ~13 ~29 concrete 15  
fill ~70 ~12 ~38 ~70 ~13 ~38 concrete 15  
fill ~70 ~12 ~57 ~70 ~14 ~57 concrete 15  
fill ~70 ~12 ~62 ~70 ~13 ~62 stained_hardened_clay 15  
fill ~71 ~12 ~31 ~71 ~13 ~31 concrete 15  
fill ~71 ~12 ~61 ~71 ~13 ~61 concrete 15 
setblock ~72 ~12 ~32 concrete 15  
fill ~72 ~12 ~41 ~72 ~13 ~41 concrete 15 
setblock ~72 ~12 ~56 stained_hardened_clay 15  
fill ~73 ~12 ~13 ~77 ~12 ~13 stained_hardened_clay 7  
fill ~73 ~12 ~34 ~73 ~13 ~34 concrete 15  
fill ~73 ~12 ~43 ~73 ~14 ~43 concrete 15  
fill ~73 ~12 ~55 ~73 ~14 ~55 concrete 15  
fill ~74 ~12 ~35 ~74 ~12 ~36 concrete 15  
fill ~74 ~12 ~54 ~74 ~14 ~54 concrete 15  
fill ~74 ~12 ~59 ~74 ~13 ~59 concrete 15  
fill ~75 ~12 ~37 ~75 ~13 ~37 concrete 15  
fill ~75 ~12 ~46 ~75 ~13 ~46 stained_hardened_clay 15  
fill ~75 ~12 ~58 ~75 ~13 ~58 stained_hardened_clay 15  
fill ~76 ~12 ~38 ~76 ~12 ~39 concrete 15  
fill ~76 ~12 ~48 ~76 ~13 ~48 concrete 15 
setblock ~77 ~12 ~40 concrete 15  
fill ~77 ~12 ~50 ~77 ~13 ~50 concrete 15  
fill ~77 ~12 ~52 ~77 ~14 ~52 stained_hardened_clay 15  
fill ~78 ~12 ~14 ~78 ~13 ~14 stained_hardened_clay 7  
fill ~78 ~12 ~42 ~78 ~13 ~42 concrete 15  
fill ~78 ~12 ~56 ~78 ~13 ~56 concrete 15  
fill ~79 ~12 ~14 ~81 ~12 ~14 stained_hardened_clay 15  
fill ~79 ~12 ~43 ~79 ~12 ~44 concrete 15  
fill ~79 ~12 ~55 ~79 ~13 ~55 concrete 15 
setblock ~80 ~12 ~45 concrete 15  
fill ~81 ~12 ~46 ~81 ~12 ~47 concrete 15  
fill ~82 ~12 ~15 ~84 ~12 ~15 stained_hardened_clay 15 
setblock ~82 ~12 ~48 concrete 15  
fill ~82 ~12 ~53 ~82 ~13 ~53 concrete 15  
fill ~83 ~12 ~50 ~83 ~13 ~50 concrete 15  
fill ~83 ~12 ~52 ~84 ~12 ~52 concrete 15 
setblock ~84 ~12 ~51 concrete 15 
setblock ~10 ~13 ~16 stained_hardened_clay 15  
fill ~11 ~13 ~15 ~14 ~13 ~15 stained_hardened_clay 15 
setblock ~11 ~13 ~51 concrete 15 
setblock ~12 ~13 ~49 concrete 15  
fill ~13 ~13 ~47 ~13 ~13 ~48 concrete 15  
fill ~13 ~13 ~53 ~13 ~14 ~53 concrete 15  
fill ~14 ~13 ~46 ~14 ~14 ~46 concrete 15  
fill ~14 ~13 ~54 ~14 ~14 ~54 concrete 15 
setblock ~15 ~13 ~14 stained_hardened_clay 15 
setblock ~15 ~13 ~44 concrete 15  
fill ~15 ~13 ~45 ~15 ~14 ~45 stained_hardened_clay 15  
fill ~16 ~13 ~14 ~19 ~13 ~14 stained_hardened_clay 7  
fill ~16 ~13 ~43 ~16 ~14 ~43 concrete 15 
setblock ~17 ~13 ~41 concrete 15  
fill ~17 ~13 ~51 ~17 ~15 ~51 concrete 15  
fill ~17 ~13 ~56 ~17 ~14 ~56 concrete 15 
setblock ~18 ~13 ~39 stained_hardened_clay 15  
fill ~18 ~13 ~40 ~18 ~14 ~40 concrete 15  
fill ~18 ~13 ~49 ~18 ~14 ~49 concrete 15 
setblock ~18 ~13 ~53 stained_hardened_clay 15  
fill ~18 ~13 ~57 ~18 ~14 ~57 concrete 15 
setblock ~19 ~13 ~38 concrete 15  
fill ~19 ~13 ~47 ~19 ~14 ~47 concrete 15  
fill ~19 ~13 ~53 ~19 ~15 ~53 concrete 15  
fill ~20 ~13 ~13 ~23 ~13 ~13 stained_hardened_clay 7 
setblock ~20 ~13 ~36 concrete 15  
fill ~20 ~13 ~45 ~20 ~14 ~45 stained_hardened_clay 15  
fill ~21 ~13 ~35 ~21 ~14 ~35 concrete 15  
fill ~21 ~13 ~59 ~21 ~14 ~59 concrete 15 
setblock ~22 ~13 ~33 concrete 15  
fill ~22 ~13 ~42 ~22 ~14 ~42 concrete 15  
fill ~22 ~13 ~60 ~22 ~14 ~60 concrete 15  
fill ~23 ~13 ~32 ~23 ~14 ~32 concrete 15  
fill ~23 ~13 ~40 ~23 ~14 ~40 concrete 15 
setblock ~23 ~13 ~56 stained_hardened_clay 15  
fill ~24 ~13 ~12 ~25 ~13 ~12 stained_hardened_clay 7 
setblock ~24 ~13 ~30 concrete 15  
fill ~24 ~13 ~39 ~24 ~15 ~39 concrete 15 
setblock ~25 ~13 ~28 stained_hardened_clay 15  
fill ~25 ~13 ~37 ~25 ~14 ~37 concrete 15  
fill ~25 ~13 ~62 ~25 ~14 ~62 stained_hardened_clay 15  
fill ~26 ~13 ~12 ~28 ~13 ~12 concrete 7  
fill ~26 ~13 ~27 ~26 ~14 ~27 concrete 15  
fill ~26 ~13 ~63 ~26 ~14 ~63 stained_hardened_clay 15  
fill ~27 ~13 ~26 ~27 ~14 ~26 concrete 15  
fill ~27 ~13 ~34 ~27 ~15 ~34 concrete 15  
fill ~27 ~13 ~59 ~27 ~15 ~59 concrete 15  
fill ~27 ~13 ~64 ~27 ~14 ~64 stained_hardened_clay 15  
fill ~28 ~13 ~25 ~29 ~13 ~25 stained_hardened_clay 15  
fill ~28 ~13 ~32 ~28 ~14 ~32 concrete 15 
setblock ~28 ~13 ~65 concrete 15  
fill ~29 ~13 ~11 ~33 ~13 ~11 stained_hardened_clay 7  
fill ~30 ~13 ~25 ~31 ~13 ~25 concrete 15  
fill ~30 ~13 ~29 ~31 ~13 ~29 concrete 15  
fill ~30 ~13 ~65 ~30 ~16 ~65 stained_hardened_clay 15  
fill ~31 ~13 ~62 ~31 ~16 ~62 concrete 15  
fill ~32 ~13 ~24 ~35 ~13 ~24 concrete 15  
fill ~32 ~13 ~28 ~34 ~13 ~28 concrete 15  
fill ~33 ~13 ~66 ~33 ~16 ~66 stained_hardened_clay 15  
fill ~34 ~13 ~10 ~38 ~13 ~10 stained_hardened_clay 7  
fill ~34 ~13 ~63 ~34 ~17 ~63 concrete 15  
fill ~35 ~13 ~27 ~38 ~13 ~27 concrete 15  
fill ~35 ~13 ~64 ~36 ~13 ~64 concrete 15  
fill ~35 ~13 ~67 ~36 ~13 ~67 stained_hardened_clay 15  
fill ~36 ~13 ~23 ~38 ~13 ~23 concrete 15  
fill ~39 ~13 ~9 ~41 ~13 ~9 stained_hardened_clay 7  
fill ~39 ~13 ~22 ~42 ~13 ~22 concrete 15  
fill ~39 ~13 ~26 ~40 ~13 ~26 concrete 15  
fill ~39 ~13 ~65 ~41 ~13 ~65 stained_hardened_clay 15  
fill ~40 ~13 ~68 ~40 ~16 ~68 stained_hardened_clay 15  
fill ~41 ~13 ~26 ~42 ~13 ~26 stained_hardened_clay 15  
fill ~42 ~13 ~9 ~43 ~13 ~9 concrete 7  
fill ~43 ~13 ~21 ~45 ~13 ~21 concrete 15  
fill ~43 ~13 ~25 ~45 ~13 ~25 concrete 15  
fill ~43 ~13 ~69 ~43 ~15 ~69 stained_hardened_clay 15  
fill ~44 ~13 ~8 ~45 ~13 ~8 concrete 7  
fill ~44 ~13 ~66 ~44 ~16 ~66 concrete 15 
setblock ~44 ~13 ~70 stained_hardened_clay 15  
fill ~45 ~13 ~70 ~46 ~13 ~70 concrete 15  
fill ~46 ~13 ~8 ~49 ~13 ~8 stained_hardened_clay 7 
setblock ~46 ~13 ~20 stained_hardened_clay 15 
setblock ~46 ~13 ~24 concrete 15 
setblock ~47 ~13 ~71 concrete 15 
setblock ~48 ~13 ~20 stained_hardened_clay 15  
fill ~48 ~13 ~24 ~48 ~11 ~24 concrete 15  
fill ~48 ~13 ~70 ~50 ~13 ~70 concrete 15  
fill ~49 ~13 ~21 ~51 ~13 ~21 concrete 15  
fill ~49 ~13 ~25 ~51 ~13 ~25 concrete 15  
fill ~50 ~13 ~8 ~50 ~12 ~8 concrete 7  
fill ~50 ~13 ~66 ~50 ~16 ~66 concrete 15  
fill ~51 ~13 ~9 ~52 ~13 ~9 concrete 7  
fill ~51 ~13 ~69 ~53 ~13 ~69 stained_hardened_clay 15  
fill ~52 ~13 ~22 ~52 ~14 ~22 stained_hardened_clay 15  
fill ~52 ~13 ~26 ~53 ~13 ~26 stained_hardened_clay 15  
fill ~53 ~13 ~9 ~55 ~13 ~9 stained_hardened_clay 7  
fill ~53 ~13 ~22 ~55 ~13 ~22 concrete 15  
fill ~53 ~13 ~65 ~56 ~13 ~65 stained_hardened_clay 15  
fill ~54 ~13 ~26 ~55 ~13 ~26 concrete 15  
fill ~54 ~13 ~68 ~54 ~16 ~68 stained_hardened_clay 15  
fill ~56 ~13 ~10 ~60 ~13 ~10 stained_hardened_clay 7  
fill ~56 ~13 ~23 ~58 ~13 ~23 concrete 15  
fill ~56 ~13 ~27 ~59 ~13 ~27 concrete 15  
fill ~58 ~13 ~64 ~59 ~13 ~64 concrete 15  
fill ~58 ~13 ~67 ~58 ~15 ~67 stained_hardened_clay 15  
fill ~59 ~13 ~24 ~62 ~13 ~24 concrete 15  
fill ~60 ~13 ~28 ~62 ~13 ~28 concrete 15  
fill ~60 ~13 ~63 ~60 ~17 ~63 concrete 15  
fill ~61 ~13 ~11 ~65 ~13 ~11 stained_hardened_clay 7  
fill ~61 ~13 ~66 ~61 ~16 ~66 stained_hardened_clay 15  
fill ~63 ~13 ~25 ~64 ~13 ~25 concrete 15  
fill ~63 ~13 ~29 ~64 ~13 ~29 concrete 15  
fill ~63 ~13 ~62 ~63 ~16 ~62 concrete 15  
fill ~64 ~13 ~65 ~64 ~16 ~65 stained_hardened_clay 15  
fill ~65 ~13 ~25 ~66 ~13 ~25 stained_hardened_clay 15  
fill ~66 ~13 ~12 ~68 ~13 ~12 concrete 7  
fill ~66 ~13 ~32 ~66 ~14 ~32 concrete 15  
fill ~67 ~13 ~26 ~67 ~14 ~26 concrete 15  
fill ~67 ~13 ~34 ~67 ~15 ~34 concrete 15  
fill ~67 ~13 ~59 ~67 ~15 ~59 concrete 15  
fill ~67 ~13 ~64 ~67 ~14 ~64 stained_hardened_clay 15  
fill ~68 ~13 ~27 ~68 ~14 ~27 concrete 15  
fill ~68 ~13 ~63 ~68 ~14 ~63 stained_hardened_clay 15  
fill ~69 ~13 ~12 ~70 ~13 ~12 stained_hardened_clay 7 
setblock ~69 ~13 ~28 stained_hardened_clay 15  
fill ~69 ~13 ~37 ~69 ~14 ~37 concrete 15  
fill ~69 ~13 ~62 ~69 ~14 ~62 stained_hardened_clay 15 
setblock ~70 ~13 ~30 concrete 15  
fill ~70 ~13 ~39 ~70 ~15 ~39 concrete 15  
fill ~71 ~13 ~13 ~74 ~13 ~13 stained_hardened_clay 7  
fill ~71 ~13 ~32 ~71 ~14 ~32 concrete 15  
fill ~71 ~13 ~40 ~71 ~14 ~40 concrete 15 
setblock ~71 ~13 ~56 stained_hardened_clay 15 
setblock ~72 ~13 ~33 concrete 15  
fill ~72 ~13 ~42 ~72 ~14 ~42 concrete 15 
setblock ~72 ~13 ~56 concrete 15  
fill ~72 ~13 ~60 ~72 ~14 ~60 concrete 15  
fill ~73 ~13 ~35 ~73 ~14 ~35 concrete 15  
fill ~73 ~13 ~59 ~73 ~14 ~59 concrete 15 
setblock ~74 ~13 ~36 concrete 15  
fill ~74 ~13 ~45 ~74 ~14 ~45 stained_hardened_clay 15  
fill ~75 ~13 ~14 ~78 ~13 ~14 stained_hardened_clay 7  
fill ~75 ~13 ~38 ~75 ~14 ~38 concrete 15  
fill ~75 ~13 ~47 ~75 ~14 ~47 concrete 15  
fill ~75 ~13 ~53 ~75 ~15 ~53 concrete 15 
setblock ~76 ~13 ~39 stained_hardened_clay 15  
fill ~76 ~13 ~40 ~76 ~14 ~40 concrete 15  
fill ~76 ~13 ~49 ~76 ~14 ~49 concrete 15 
setblock ~76 ~13 ~53 stained_hardened_clay 15 
setblock ~76 ~13 ~57 concrete 15 
setblock ~77 ~13 ~41 concrete 15  
fill ~77 ~13 ~51 ~77 ~15 ~51 concrete 15  
fill ~77 ~13 ~56 ~77 ~14 ~56 concrete 15  
fill ~78 ~13 ~43 ~78 ~14 ~43 concrete 15  
fill ~79 ~13 ~14 ~79 ~12 ~14 stained_hardened_clay 15  
fill ~79 ~13 ~44 ~79 ~13 ~45 concrete 15  
fill ~80 ~13 ~15 ~83 ~13 ~15 stained_hardened_clay 15  
fill ~80 ~13 ~46 ~80 ~14 ~46 concrete 15  
fill ~80 ~13 ~54 ~80 ~14 ~54 concrete 15  
fill ~81 ~13 ~47 ~81 ~13 ~48 concrete 15  
fill ~81 ~13 ~53 ~81 ~14 ~53 concrete 15 
setblock ~82 ~13 ~49 concrete 15  
fill ~83 ~13 ~51 ~83 ~13 ~52 concrete 15 
setblock ~84 ~13 ~16 stained_hardened_clay 15  
fill ~11 ~14 ~16 ~13 ~14 ~16 stained_hardened_clay 15  
fill ~12 ~14 ~50 ~12 ~14 ~52 concrete 15  
fill ~13 ~14 ~48 ~13 ~14 ~49 concrete 15  
fill ~14 ~14 ~15 ~15 ~14 ~15 stained_hardened_clay 15 
setblock ~14 ~14 ~47 concrete 15  
fill ~15 ~14 ~54 ~15 ~15 ~54 concrete 15  
fill ~16 ~14 ~15 ~16 ~15 ~15 stained_hardened_clay 7  
fill ~16 ~14 ~44 ~16 ~15 ~44 concrete 15  
fill ~16 ~14 ~55 ~16 ~15 ~55 concrete 15 
setblock ~17 ~14 ~15 concrete 7 
setblock ~17 ~14 ~42 concrete 15  
fill ~18 ~14 ~14 ~21 ~14 ~14 stained_hardened_clay 7  
fill ~18 ~14 ~41 ~18 ~15 ~41 concrete 15  
fill ~18 ~14 ~50 ~18 ~16 ~50 concrete 15  
fill ~18 ~14 ~52 ~18 ~15 ~52 stained_hardened_clay 15  
fill ~19 ~14 ~38 ~19 ~14 ~39 stained_hardened_clay 15  
fill ~19 ~14 ~48 ~19 ~15 ~48 concrete 15  
fill ~19 ~14 ~57 ~19 ~15 ~57 stained_hardened_clay 15 
setblock ~20 ~14 ~37 concrete 15
fill ~20 ~14 ~46 ~20 ~15 ~46 stained_hardened_clay 15  
fill ~20 ~14 ~58 ~20 ~15 ~58 stained_hardened_clay 15  
fill ~21 ~14 ~36 ~21 ~15 ~36 concrete 15  
fill ~21 ~14 ~44 ~21 ~15 ~44 concrete 15  
fill ~22 ~14 ~13 ~25 ~14 ~13 stained_hardened_clay 7 
setblock ~22 ~14 ~34 concrete 15  
fill ~22 ~14 ~55 ~22 ~16 ~55 concrete 15  
fill ~23 ~14 ~33 ~23 ~15 ~33 concrete 15  
fill ~23 ~14 ~41 ~23 ~15 ~41 concrete 15  
fill ~23 ~14 ~56 ~23 ~15 ~56 concrete 15  
fill ~23 ~14 ~60 ~23 ~15 ~60 concrete 15 
setblock ~24 ~14 ~30 stained_hardened_clay 15 
setblock ~24 ~14 ~31 concrete 15  
fill ~24 ~14 ~61 ~24 ~15 ~61 stained_hardened_clay 15 
setblock ~25 ~14 ~29 stained_hardened_clay 15  
fill ~25 ~14 ~38 ~25 ~16 ~38 concrete 15  
fill ~25 ~14 ~57 ~25 ~16 ~57 concrete 15  
fill ~26 ~14 ~13 ~26 ~15 ~13 concrete 7  
fill ~26 ~14 ~28 ~26 ~15 ~28 concrete 15  
fill ~26 ~14 ~36 ~26 ~15 ~36 concrete 15  
fill ~26 ~14 ~58 ~26 ~16 ~58 concrete 15  
fill ~27 ~14 ~12 ~28 ~14 ~12 concrete 7  
fill ~28 ~14 ~26 ~29 ~14 ~26 stained_hardened_clay 15  
fill ~28 ~14 ~33 ~28 ~15 ~33 concrete 15 
setblock ~28 ~14 ~65 stained_hardened_clay 15  
fill ~29 ~14 ~12 ~31 ~14 ~12 stained_hardened_clay 7  
fill ~29 ~14 ~31 ~29 ~15 ~31 concrete 15 
setblock ~30 ~14 ~25 stained_hardened_clay 15  
fill ~30 ~14 ~29 ~32 ~14 ~29 concrete 15 
setblock ~30 ~14 ~61 stained_hardened_clay 15  
fill ~31 ~14 ~25 ~33 ~14 ~25 concrete 15  
fill ~31 ~14 ~65 ~31 ~17 ~65 stained_hardened_clay 15  
fill ~32 ~14 ~11 ~35 ~14 ~11 stained_hardened_clay 7  
fill ~33 ~14 ~28 ~36 ~14 ~28 concrete 15 
setblock ~34 ~14 ~24 stained_hardened_clay 15  
fill ~34 ~14 ~66 ~34 ~17 ~66 stained_hardened_clay 15  
fill ~35 ~14 ~24 ~36 ~14 ~24 concrete 15  
fill ~35 ~14 ~63 ~35 ~18 ~63 concrete 15  
fill ~35 ~14 ~67 ~37 ~14 ~67 stained_hardened_clay 15  
fill ~36 ~14 ~10 ~40 ~14 ~10 stained_hardened_clay 7  
fill ~36 ~14 ~64 ~36 ~15 ~64 concrete 15 
setblock ~37 ~14 ~23 concrete 15  
fill ~37 ~14 ~27 ~40 ~14 ~27 concrete 15  
fill ~38 ~14 ~23 ~39 ~14 ~23 stained_hardened_clay 15  
fill ~38 ~14 ~64 ~38 ~18 ~64 stained_hardened_clay 15  
fill ~38 ~14 ~68 ~41 ~14 ~68 stained_hardened_clay 15  
fill ~39 ~14 ~65 ~41 ~14 ~65 stained_hardened_clay 15  
fill ~40 ~14 ~23 ~40 ~15 ~23 concrete 15 
setblock ~41 ~14 ~9 stained_hardened_clay 7 
setblock ~41 ~14 ~22 concrete 15  
fill ~41 ~14 ~26 ~41 ~13 ~26 stained_hardened_clay 15  
fill ~42 ~14 ~9 ~45 ~14 ~9 concrete 7  
fill ~42 ~14 ~22 ~44 ~14 ~22 stained_hardened_clay 15  
fill ~42 ~14 ~26 ~43 ~14 ~26 concrete 15 
setblock ~42 ~14 ~66 stained_hardened_clay 15  
fill ~44 ~14 ~25 ~46 ~14 ~25 concrete 15  
fill ~44 ~14 ~69 ~44 ~17 ~69 concrete 15  
fill ~45 ~14 ~21 ~49 ~14 ~21 stained_hardened_clay 15  
fill ~45 ~14 ~66 ~45 ~18 ~66 stained_hardened_clay 15  
fill ~45 ~14 ~70 ~49 ~14 ~70 concrete 15 
setblock ~46 ~14 ~9 stained_hardened_clay 7 
setblock ~47 ~14 ~8 stained_hardened_clay 7  
fill ~47 ~14 ~25 ~47 ~16 ~25 stained_hardened_clay 15 
setblock ~48 ~14 ~9 stained_hardened_clay 7  
fill ~48 ~14 ~25 ~50 ~14 ~25 concrete 15  
fill ~49 ~14 ~9 ~52 ~14 ~9 concrete 7  
fill ~49 ~14 ~66 ~49 ~18 ~66 stained_hardened_clay 15  
fill ~50 ~14 ~22 ~52 ~14 ~22 stained_hardened_clay 15  
fill ~50 ~14 ~69 ~50 ~17 ~69 concrete 15  
fill ~51 ~14 ~26 ~52 ~14 ~26 concrete 15  
fill ~51 ~14 ~69 ~52 ~14 ~69 stained_hardened_clay 15 
setblock ~52 ~14 ~66 stained_hardened_clay 15  
fill ~53 ~14 ~9 ~53 ~13 ~9 stained_hardened_clay 7  
fill ~53 ~14 ~22 ~53 ~13 ~22 concrete 15 
setblock ~53 ~14 ~26 stained_hardened_clay 15  
fill ~53 ~14 ~65 ~55 ~14 ~65 stained_hardened_clay 15  
fill ~53 ~14 ~68 ~53 ~17 ~68 stained_hardened_clay 15  
fill ~54 ~14 ~10 ~58 ~14 ~10 stained_hardened_clay 7  
fill ~54 ~14 ~23 ~55 ~14 ~23 concrete 15  
fill ~54 ~14 ~27 ~57 ~14 ~27 concrete 15  
fill ~55 ~14 ~68 ~56 ~14 ~68 stained_hardened_clay 15  
fill ~56 ~14 ~23 ~57 ~14 ~23 stained_hardened_clay 15  
fill ~56 ~14 ~64 ~56 ~18 ~64 stained_hardened_clay 15  
fill ~57 ~14 ~67 ~57 ~16 ~67 stained_hardened_clay 15  
fill ~58 ~14 ~24 ~59 ~14 ~24 concrete 15  
fill ~58 ~14 ~28 ~61 ~14 ~28 concrete 15  
fill ~58 ~14 ~64 ~58 ~15 ~64 concrete 15  
fill ~59 ~14 ~11 ~63 ~14 ~11 stained_hardened_clay 7  
fill ~59 ~14 ~63 ~59 ~18 ~63 concrete 15 
setblock ~60 ~14 ~24 stained_hardened_clay 15  
fill ~60 ~14 ~66 ~60 ~17 ~66 stained_hardened_clay 15  
fill ~61 ~14 ~25 ~63 ~14 ~25 concrete 15  
fill ~62 ~14 ~29 ~64 ~14 ~29 concrete 15  
fill ~63 ~14 ~65 ~63 ~17 ~65 stained_hardened_clay 15  
fill ~64 ~14 ~12 ~65 ~14 ~12 stained_hardened_clay 7 
setblock ~64 ~14 ~25 stained_hardened_clay 15 
setblock ~64 ~14 ~61 stained_hardened_clay 15  
fill ~65 ~14 ~26 ~66 ~14 ~26 stained_hardened_clay 15 
setblock ~65 ~14 ~31 concrete 15  
fill ~66 ~14 ~12 ~67 ~14 ~12 concrete 7  
fill ~66 ~14 ~33 ~66 ~15 ~33 concrete 15  
fill ~68 ~14 ~13 ~68 ~15 ~13 concrete 7  
fill ~68 ~14 ~28 ~68 ~15 ~28 concrete 15  
fill ~68 ~14 ~36 ~68 ~15 ~36 concrete 15  
fill ~68 ~14 ~58 ~68 ~16 ~58 concrete 15  
fill ~69 ~14 ~13 ~72 ~14 ~13 stained_hardened_clay 7 
setblock ~69 ~14 ~29 stained_hardened_clay 15  
fill ~69 ~14 ~38 ~69 ~16 ~38 concrete 15  
fill ~69 ~14 ~57 ~69 ~16 ~57 concrete 15 
setblock ~70 ~14 ~30 stained_hardened_clay 15 
setblock ~70 ~14 ~31 concrete 15  
fill ~70 ~14 ~61 ~70 ~15 ~61 stained_hardened_clay 15  
fill ~71 ~14 ~33 ~71 ~15 ~33 concrete 15  
fill ~71 ~14 ~41 ~71 ~15 ~41 concrete 15  
fill ~71 ~14 ~56 ~71 ~15 ~56 concrete 15  
fill ~71 ~14 ~60 ~71 ~15 ~60 concrete 15 
setblock ~72 ~14 ~34 concrete 15  
fill ~72 ~14 ~55 ~72 ~16 ~55 concrete 15  
fill ~73 ~14 ~14 ~76 ~14 ~14 stained_hardened_clay 7  
fill ~73 ~14 ~36 ~73 ~15 ~36 concrete 15  
fill ~73 ~14 ~44 ~73 ~15 ~44 concrete 15 
setblock ~74 ~14 ~37 concrete 15  
fill ~74 ~14 ~46 ~74 ~15 ~46 stained_hardened_clay 15  
fill ~74 ~14 ~58 ~74 ~15 ~58 stained_hardened_clay 15  
fill ~75 ~14 ~39 ~75 ~15 ~39 stained_hardened_clay 15  
fill ~75 ~14 ~48 ~75 ~15 ~48 concrete 15  
fill ~75 ~14 ~57 ~76 ~14 ~57 stained_hardened_clay 15  
fill ~76 ~14 ~41 ~76 ~15 ~41 concrete 15  
fill ~76 ~14 ~50 ~76 ~16 ~50 concrete 15  
fill ~76 ~14 ~52 ~76 ~15 ~52 stained_hardened_clay 15 
setblock ~77 ~14 ~15 concrete 7 
setblock ~77 ~14 ~42 concrete 15  
fill ~78 ~14 ~15 ~78 ~15 ~15 stained_hardened_clay 7  
fill ~78 ~14 ~44 ~78 ~15 ~44 concrete 15  
fill ~78 ~14 ~55 ~78 ~15 ~55 concrete 15  
fill ~79 ~14 ~15 ~80 ~14 ~15 stained_hardened_clay 15 
setblock ~79 ~14 ~45 stained_hardened_clay 15  
fill ~79 ~14 ~54 ~79 ~15 ~54 concrete 15 
setblock ~80 ~14 ~47 concrete 15  
fill ~81 ~14 ~16 ~83 ~14 ~16 stained_hardened_clay 15  
fill ~81 ~14 ~48 ~81 ~14 ~49 concrete 15  
fill ~82 ~14 ~50 ~82 ~14 ~52 concrete 15 
setblock ~11 ~15 ~17 stained_hardened_clay 15  
fill ~12 ~15 ~16 ~15 ~15 ~16 stained_hardened_clay 15  
fill ~12 ~15 ~51 ~12 ~15 ~52 concrete 15  
fill ~13 ~15 ~49 ~13 ~15 ~50 concrete 15 
setblock ~13 ~15 ~52 concrete 15 
setblock ~14 ~15 ~47 stained_hardened_clay 15  
fill ~14 ~15 ~48 ~14 ~16 ~48 concrete 15  
fill ~14 ~15 ~53 ~14 ~16 ~53 stained_hardened_clay 15 
setblock ~15 ~15 ~46 stained_hardened_clay 15  
fill ~16 ~15 ~45 ~16 ~16 ~45 stained_hardened_clay 15  
fill ~17 ~15 ~15 ~19 ~15 ~15 stained_hardened_clay 7  
fill ~17 ~15 ~43 ~17 ~16 ~43 concrete 15  
fill ~17 ~15 ~55 ~17 ~16 ~55 concrete 15  
fill ~18 ~15 ~42 ~18 ~16 ~42 concrete 15  
fill ~18 ~15 ~56 ~18 ~16 ~56 concrete 15  
fill ~19 ~15 ~39 ~19 ~15 ~40 stained_hardened_clay 15  
fill ~19 ~15 ~49 ~19 ~17 ~49 concrete 15  
fill ~20 ~15 ~14 ~24 ~15 ~14 stained_hardened_clay 7 
setblock ~20 ~15 ~38 stained_hardened_clay 15  
fill ~20 ~15 ~47 ~20 ~16 ~47 concrete 15  
fill ~20 ~15 ~53 ~20 ~17 ~53 concrete 15 
setblock ~21 ~15 ~37 concrete 15  
fill ~21 ~15 ~45 ~21 ~16 ~45 stained_hardened_clay 15  
fill ~21 ~15 ~54 ~21 ~17 ~54 concrete 15 
setblock ~21 ~15 ~58 concrete 15  
fill ~22 ~15 ~35 ~22 ~16 ~35 stained_hardened_clay 15  
fill ~22 ~15 ~43 ~22 ~16 ~43 concrete 15  
fill ~22 ~15 ~59 ~22 ~16 ~59 stained_hardened_clay 15  
fill ~23 ~15 ~34 ~23 ~16 ~34 concrete 15  
fill ~23 ~15 ~42 ~23 ~17 ~42 concrete 15 
setblock ~24 ~15 ~31 stained_hardened_clay 15  
fill ~24 ~15 ~32 ~24 ~16 ~32 concrete 15  
fill ~24 ~15 ~40 ~24 ~16 ~40 concrete 15  
fill ~24 ~15 ~56 ~24 ~17 ~56 concrete 15 
setblock ~25 ~15 ~13 stained_hardened_clay 7 
setblock ~25 ~15 ~30 stained_hardened_clay 15  
fill ~25 ~15 ~61 ~25 ~17 ~61 stained_hardened_clay 15  
fill ~26 ~15 ~29 ~26 ~16 ~29 stained_hardened_clay 15  
fill ~26 ~15 ~37 ~26 ~17 ~37 concrete 15  
fill ~26 ~15 ~62 ~26 ~16 ~62 stained_hardened_clay 15  
fill ~27 ~15 ~13 ~28 ~15 ~13 concrete 7 
setblock ~27 ~15 ~27 concrete 15  
fill ~27 ~15 ~35 ~27 ~16 ~35 concrete 15  
fill ~27 ~15 ~63 ~27 ~16 ~63 stained_hardened_clay 15  
fill ~28 ~15 ~27 ~28 ~16 ~27 stained_hardened_clay 15 
setblock ~28 ~15 ~59 stained_hardened_clay 15  
fill ~28 ~15 ~64 ~28 ~16 ~64 stained_hardened_clay 15  
fill ~29 ~15 ~12 ~33 ~15 ~12 stained_hardened_clay 7  
fill ~29 ~15 ~26 ~30 ~15 ~26 stained_hardened_clay 15  
fill ~29 ~15 ~32 ~29 ~16 ~32 concrete 15 
setblock ~29 ~15 ~60 stained_hardened_clay 15 
setblock ~30 ~15 ~30 stained_hardened_clay 15  
fill ~30 ~15 ~61 ~30 ~16 ~61 concrete 15 
setblock ~31 ~15 ~26 concrete 15  
fill ~31 ~15 ~29 ~34 ~15 ~29 concrete 15  
fill ~32 ~15 ~25 ~33 ~15 ~25 concrete 15  
fill ~32 ~15 ~62 ~32 ~18 ~62 concrete 15 
setblock ~32 ~15 ~66 stained_hardened_clay 15  
fill ~34 ~15 ~11 ~38 ~15 ~11 stained_hardened_clay 7  
fill ~34 ~15 ~25 ~34 ~16 ~25 stained_hardened_clay 15  
fill ~35 ~15 ~25 ~35 ~16 ~25 concrete 15  
fill ~35 ~15 ~28 ~37 ~15 ~28 concrete 15  
fill ~35 ~15 ~66 ~35 ~18 ~66 stained_hardened_clay 15 
setblock ~36 ~15 ~24 concrete 15  
fill ~36 ~15 ~67 ~38 ~15 ~67 stained_hardened_clay 15  
fill ~37 ~15 ~24 ~38 ~15 ~24 stained_hardened_clay 15  
fill ~38 ~15 ~27 ~41 ~15 ~27 concrete 15  
fill ~39 ~15 ~10 ~40 ~15 ~10 stained_hardened_clay 7 
setblock ~39 ~15 ~23 stained_hardened_clay 15  
fill ~39 ~15 ~64 ~39 ~19 ~64 stained_hardened_clay 15 
setblock ~39 ~15 ~68 stained_hardened_clay 15  
fill ~40 ~15 ~65 ~42 ~15 ~65 stained_hardened_clay 15  
fill ~41 ~15 ~10 ~43 ~15 ~10 concrete 7  
fill ~41 ~15 ~23 ~41 ~16 ~23 concrete 15  
fill ~41 ~15 ~68 ~42 ~15 ~68 stained_hardened_clay 15 
setblock ~42 ~15 ~23 stained_hardened_clay 15  
fill ~42 ~15 ~26 ~45 ~15 ~26 concrete 15  
fill ~43 ~15 ~22 ~45 ~15 ~22 stained_hardened_clay 15  
fill ~44 ~15 ~9 ~46 ~15 ~9 concrete 7  
fill ~45 ~15 ~69 ~45 ~18 ~69 concrete 15  
fill ~46 ~15 ~21 ~48 ~15 ~21 stained_hardened_clay 15 
setblock ~46 ~15 ~25 concrete 15  
fill ~46 ~15 ~66 ~46 ~19 ~66 concrete 15  
fill ~46 ~15 ~70 ~48 ~15 ~70 concrete 15 
setblock ~47 ~15 ~9 stained_hardened_clay 7  
fill ~48 ~15 ~9 ~50 ~15 ~9 concrete 7  
fill ~48 ~15 ~25 ~48 ~14 ~25 concrete 15  
fill ~48 ~15 ~66 ~48 ~19 ~66 concrete 15  
fill ~49 ~15 ~22 ~51 ~15 ~22 stained_hardened_clay 15  
fill ~49 ~15 ~26 ~52 ~15 ~26 concrete 15  
fill ~49 ~15 ~69 ~49 ~18 ~69 concrete 15  
fill ~51 ~15 ~10 ~53 ~15 ~10 concrete 7  
fill ~51 ~15 ~69 ~51 ~13 ~69 stained_hardened_clay 15  
fill ~52 ~15 ~23 ~54 ~15 ~23 concrete 15  
fill ~52 ~15 ~65 ~54 ~15 ~65 stained_hardened_clay 15  
fill ~52 ~15 ~68 ~52 ~18 ~68 stained_hardened_clay 15  
fill ~53 ~15 ~27 ~56 ~15 ~27 concrete 15  
fill ~54 ~15 ~10 ~55 ~15 ~10 stained_hardened_clay 7 
setblock ~55 ~15 ~23 stained_hardened_clay 15  
fill ~55 ~15 ~64 ~55 ~19 ~64 stained_hardened_clay 15  
fill ~55 ~15 ~68 ~55 ~14 ~68 stained_hardened_clay 15  
fill ~56 ~15 ~11 ~60 ~15 ~11 stained_hardened_clay 7  
fill ~56 ~15 ~24 ~57 ~15 ~24 stained_hardened_clay 15  
fill ~56 ~15 ~67 ~56 ~17 ~67 stained_hardened_clay 15  
fill ~57 ~15 ~28 ~59 ~15 ~28 concrete 15  
fill ~58 ~15 ~24 ~58 ~14 ~24 concrete 15  
fill ~59 ~15 ~25 ~59 ~16 ~25 concrete 15  
fill ~59 ~15 ~66 ~59 ~18 ~66 stained_hardened_clay 15  
fill ~60 ~15 ~25 ~61 ~15 ~25 stained_hardened_clay 15  
fill ~60 ~15 ~29 ~63 ~15 ~29 concrete 15  
fill ~61 ~15 ~12 ~65 ~15 ~12 stained_hardened_clay 7 
setblock ~62 ~15 ~25 concrete 15  
fill ~62 ~15 ~62 ~62 ~19 ~62 concrete 15 
setblock ~62 ~15 ~66 stained_hardened_clay 15 
setblock ~63 ~15 ~26 concrete 15  
fill ~64 ~15 ~26 ~65 ~15 ~26 stained_hardened_clay 15 
setblock ~64 ~15 ~30 stained_hardened_clay 15  
fill ~64 ~15 ~61 ~64 ~16 ~61 concrete 15 
setblock ~65 ~15 ~31 stained_hardened_clay 15  
fill ~65 ~15 ~32 ~65 ~16 ~32 concrete 15 
setblock ~65 ~15 ~60 stained_hardened_clay 15  
fill ~66 ~15 ~13 ~68 ~15 ~13 concrete 7  
fill ~66 ~15 ~27 ~66 ~16 ~27 stained_hardened_clay 15 
setblock ~66 ~15 ~59 stained_hardened_clay 15  
fill ~66 ~15 ~64 ~66 ~16 ~64 stained_hardened_clay 15 
setblock ~67 ~15 ~27 concrete 15  
fill ~67 ~15 ~35 ~67 ~16 ~35 concrete 15  
fill ~67 ~15 ~63 ~67 ~16 ~63 stained_hardened_clay 15  
fill ~68 ~15 ~29 ~68 ~16 ~29 stained_hardened_clay 15  
fill ~68 ~15 ~37 ~68 ~17 ~37 concrete 15  
fill ~68 ~15 ~62 ~68 ~16 ~62 stained_hardened_clay 15  
fill ~69 ~15 ~13 ~69 ~14 ~13 stained_hardened_clay 7 
setblock ~69 ~15 ~30 stained_hardened_clay 15  
fill ~69 ~15 ~61 ~69 ~17 ~61 stained_hardened_clay 15  
fill ~70 ~15 ~14 ~74 ~15 ~14 stained_hardened_clay 7 
setblock ~70 ~15 ~31 stained_hardened_clay 15  
fill ~70 ~15 ~32 ~70 ~16 ~32 concrete 15  
fill ~70 ~15 ~40 ~70 ~16 ~40 concrete 15  
fill ~70 ~15 ~56 ~70 ~17 ~56 concrete 15  
fill ~71 ~15 ~34 ~71 ~16 ~34 concrete 15  
fill ~71 ~15 ~42 ~71 ~17 ~42 concrete 15  
fill ~72 ~15 ~35 ~72 ~16 ~35 stained_hardened_clay 15  
fill ~72 ~15 ~43 ~72 ~16 ~43 concrete 15  
fill ~72 ~15 ~59 ~72 ~16 ~59 stained_hardened_clay 15  
fill ~73 ~15 ~37 ~73 ~16 ~37 concrete 15  
fill ~73 ~15 ~45 ~73 ~16 ~45 stained_hardened_clay 15  
fill ~73 ~15 ~54 ~73 ~17 ~54 concrete 15 
setblock ~73 ~15 ~58 concrete 15 
setblock ~74 ~15 ~38 stained_hardened_clay 15  
fill ~74 ~15 ~47 ~74 ~16 ~47 concrete 15  
fill ~74 ~15 ~53 ~74 ~17 ~53 concrete 15  
fill ~75 ~15 ~15 ~78 ~15 ~15 stained_hardened_clay 7  
fill ~75 ~15 ~40 ~75 ~16 ~40 stained_hardened_clay 15  
fill ~75 ~15 ~49 ~75 ~17 ~49 concrete 15  
fill ~75 ~15 ~57 ~75 ~14 ~57 stained_hardened_clay 15  
fill ~76 ~15 ~42 ~76 ~16 ~42 concrete 15  
fill ~76 ~15 ~56 ~76 ~16 ~56 concrete 15  
fill ~77 ~15 ~43 ~77 ~16 ~43 concrete 15  
fill ~77 ~15 ~55 ~77 ~16 ~55 concrete 15  
fill ~78 ~15 ~45 ~78 ~16 ~45 stained_hardened_clay 15  
fill ~79 ~15 ~16 ~82 ~15 ~16 stained_hardened_clay 15 
setblock ~79 ~15 ~46 stained_hardened_clay 15 
setblock ~80 ~15 ~47 stained_hardened_clay 15  
fill ~80 ~15 ~48 ~80 ~16 ~48 concrete 15  
fill ~80 ~15 ~53 ~80 ~16 ~53 stained_hardened_clay 15  
fill ~81 ~15 ~49 ~81 ~15 ~50 concrete 15  
fill ~81 ~15 ~52 ~82 ~15 ~52 concrete 15 
setblock ~82 ~15 ~51 concrete 15 
setblock ~83 ~15 ~17 stained_hardened_clay 15  
fill ~12 ~16 ~17 ~14 ~16 ~17 stained_hardened_clay 15  
fill ~13 ~16 ~50 ~13 ~16 ~51 concrete 15 
setblock ~13 ~16 ~52 stained_hardened_clay 15 
setblock ~14 ~16 ~49 concrete 15  
fill ~15 ~16 ~16 ~16 ~16 ~16 stained_hardened_clay 15 
setblock ~15 ~16 ~47 stained_hardened_clay 15  
fill ~15 ~16 ~53 ~15 ~18 ~53 stained_hardened_clay 15  
fill ~16 ~16 ~46 ~16 ~17 ~46 stained_hardened_clay 15  
fill ~16 ~16 ~54 ~16 ~17 ~54 stained_hardened_clay 15 
setblock ~17 ~16 ~16 stained_hardened_clay 7  
fill ~17 ~16 ~44 ~17 ~17 ~44 concrete 15  
fill ~18 ~16 ~16 ~18 ~17 ~16 concrete 7  
fill ~18 ~16 ~51 ~18 ~17 ~51 concrete 15  
fill ~18 ~16 ~52 ~18 ~16 ~50 concrete 15  
fill ~19 ~16 ~15 ~22 ~16 ~15 stained_hardened_clay 7  
fill ~19 ~16 ~40 ~19 ~16 ~41 stained_hardened_clay 15 
setblock ~19 ~16 ~52 stained_hardened_clay 15  
fill ~19 ~16 ~56 ~19 ~17 ~56 stained_hardened_clay 15 
setblock ~20 ~16 ~39 concrete 15  
fill ~20 ~16 ~48 ~20 ~18 ~48 concrete 15  
fill ~20 ~16 ~57 ~20 ~17 ~57 stained_hardened_clay 15  
fill ~21 ~16 ~37 ~21 ~16 ~38 stained_hardened_clay 15  
fill ~21 ~16 ~46 ~21 ~17 ~46 stained_hardened_clay 15  
fill ~21 ~16 ~58 ~21 ~17 ~58 stained_hardened_clay 15 
setblock ~22 ~16 ~36 concrete 15  
fill ~22 ~16 ~44 ~22 ~17 ~44 concrete 15  
fill ~23 ~16 ~14 ~25 ~16 ~14 stained_hardened_clay 7  
fill ~23 ~16 ~55 ~23 ~18 ~55 concrete 15  
fill ~23 ~16 ~59 ~23 ~17 ~59 concrete 15  
fill ~24 ~16 ~33 ~24 ~17 ~33 concrete 15  
fill ~24 ~16 ~41 ~24 ~18 ~41 concrete 15  
fill ~24 ~16 ~60 ~24 ~17 ~60 concrete 15 
setblock ~25 ~16 ~31 stained_hardened_clay 15  
fill ~25 ~16 ~39 ~25 ~17 ~39 concrete 15 
setblock ~26 ~16 ~14 concrete 7  
fill ~26 ~16 ~30 ~26 ~17 ~30 stained_hardened_clay 15 
setblock ~27 ~16 ~13 stained_hardened_clay 11 
setblock ~27 ~16 ~28 concrete 15  
fill ~27 ~16 ~36 ~27 ~17 ~36 concrete 15  
fill ~27 ~16 ~58 ~27 ~18 ~58 concrete 15  
fill ~28 ~16 ~13 ~29 ~16 ~13 concrete 7  
fill ~28 ~16 ~34 ~28 ~17 ~34 concrete 15  
fill ~28 ~16 ~59 ~28 ~17 ~59 concrete 15  
fill ~29 ~16 ~27 ~30 ~16 ~27 stained_hardened_clay 15  
fill ~29 ~16 ~33 ~29 ~18 ~33 concrete 15  
fill ~29 ~16 ~60 ~29 ~17 ~60 concrete 15  
fill ~29 ~16 ~64 ~29 ~18 ~64 stained_hardened_clay 15  
fill ~30 ~16 ~13 ~31 ~16 ~13 stained_hardened_clay 7 
setblock ~30 ~16 ~31 stained_hardened_clay 15 
setblock ~31 ~16 ~26 stained_hardened_clay 15  
fill ~31 ~16 ~30 ~32 ~16 ~30 concrete 15 
setblock ~32 ~16 ~12 stained_hardened_clay 7  
fill ~32 ~16 ~26 ~33 ~16 ~26 concrete 15  
fill ~32 ~16 ~65 ~32 ~18 ~65 stained_hardened_clay 15  
fill ~33 ~16 ~12 ~34 ~16 ~12 concrete 7  
fill ~33 ~16 ~29 ~35 ~16 ~29 concrete 15  
fill ~33 ~16 ~62 ~33 ~19 ~62 concrete 15  
fill ~35 ~16 ~12 ~36 ~16 ~12 stained_hardened_clay 7  
fill ~36 ~16 ~25 ~36 ~17 ~25 concrete 15  
fill ~36 ~16 ~28 ~39 ~16 ~28 concrete 15  
fill ~36 ~16 ~63 ~36 ~20 ~63 concrete 15  
fill ~36 ~16 ~66 ~36 ~19 ~66 stained_hardened_clay 15  
fill ~37 ~16 ~11 ~40 ~16 ~11 stained_hardened_clay 7 
setblock ~37 ~16 ~25 stained_hardened_clay 15  
fill ~37 ~16 ~67 ~39 ~16 ~67 stained_hardened_clay 15  
fill ~38 ~16 ~24 ~40 ~16 ~24 stained_hardened_clay 15  
fill ~40 ~16 ~27 ~43 ~16 ~27 concrete 15  
fill ~40 ~16 ~65 ~42 ~16 ~65 stained_hardened_clay 15  
fill ~41 ~16 ~11 ~41 ~17 ~11 concrete 7  
fill ~41 ~16 ~68 ~43 ~16 ~68 stained_hardened_clay 15  
fill ~42 ~16 ~10 ~46 ~16 ~10 concrete 7 
setblock ~42 ~16 ~23 concrete 15  
fill ~43 ~16 ~23 ~44 ~16 ~23 stained_hardened_clay 15  
fill ~43 ~16 ~65 ~43 ~18 ~65 concrete 15  
fill ~44 ~16 ~26 ~46 ~16 ~26 concrete 15  
fill ~45 ~16 ~22 ~49 ~16 ~22 stained_hardened_clay 15  
fill ~46 ~16 ~69 ~46 ~19 ~69 concrete 15 
setblock ~47 ~16 ~9 concrete 7 
setblock ~47 ~16 ~70 concrete 15  
fill ~48 ~16 ~10 ~52 ~16 ~10 concrete 7  
fill ~48 ~16 ~26 ~50 ~16 ~26 concrete 15  
fill ~48 ~16 ~69 ~48 ~19 ~69 concrete 15  
fill ~50 ~16 ~23 ~51 ~16 ~23 stained_hardened_clay 15  
fill ~51 ~16 ~27 ~54 ~16 ~27 concrete 15  
fill ~51 ~16 ~65 ~51 ~18 ~65 concrete 15  
fill ~51 ~16 ~68 ~51 ~19 ~68 stained_hardened_clay 15  
fill ~52 ~16 ~23 ~53 ~16 ~23 concrete 15  
fill ~52 ~16 ~65 ~54 ~16 ~65 stained_hardened_clay 15  
fill ~53 ~16 ~11 ~53 ~17 ~11 concrete 7  
fill ~54 ~16 ~11 ~57 ~16 ~11 stained_hardened_clay 7  
fill ~54 ~16 ~24 ~56 ~16 ~24 stained_hardened_clay 15  
fill ~55 ~16 ~28 ~58 ~16 ~28 concrete 15  
fill ~55 ~16 ~67 ~55 ~18 ~67 stained_hardened_clay 15 
setblock ~57 ~16 ~25 stained_hardened_clay 15  
fill ~58 ~16 ~12 ~59 ~16 ~12 stained_hardened_clay 7  
fill ~58 ~16 ~25 ~58 ~17 ~25 concrete 15  
fill ~58 ~16 ~63 ~58 ~20 ~63 concrete 15  
fill ~58 ~16 ~66 ~58 ~19 ~66 stained_hardened_clay 15  
fill ~59 ~16 ~29 ~61 ~16 ~29 concrete 15  
fill ~60 ~16 ~12 ~61 ~16 ~12 concrete 7  
fill ~60 ~16 ~25 ~60 ~15 ~25 stained_hardened_clay 15  
fill ~61 ~16 ~26 ~62 ~16 ~26 concrete 15  
fill ~61 ~16 ~62 ~61 ~18 ~62 concrete 15 
setblock ~62 ~16 ~12 stained_hardened_clay 7  
fill ~62 ~16 ~30 ~63 ~16 ~30 concrete 15  
fill ~62 ~16 ~65 ~62 ~18 ~65 stained_hardened_clay 15  
fill ~63 ~16 ~13 ~65 ~16 ~13 stained_hardened_clay 7 
setblock ~63 ~16 ~26 stained_hardened_clay 15  
fill ~64 ~16 ~27 ~66 ~16 ~27 stained_hardened_clay 15 
setblock ~64 ~16 ~31 stained_hardened_clay 15  
fill ~65 ~16 ~33 ~65 ~18 ~33 concrete 15  
fill ~65 ~16 ~60 ~65 ~17 ~60 concrete 15  
fill ~65 ~16 ~64 ~65 ~18 ~64 stained_hardened_clay 15  
fill ~66 ~16 ~13 ~66 ~15 ~13 concrete 7  
fill ~66 ~16 ~34 ~66 ~17 ~34 concrete 15  
fill ~66 ~16 ~59 ~66 ~17 ~59 concrete 15 
setblock ~67 ~16 ~13 stained_hardened_clay 11 
setblock ~67 ~16 ~28 concrete 15  
fill ~67 ~16 ~36 ~67 ~17 ~36 concrete 15  
fill ~67 ~16 ~58 ~67 ~18 ~58 concrete 15 
setblock ~68 ~16 ~14 concrete 7  
fill ~68 ~16 ~30 ~68 ~17 ~30 stained_hardened_clay 15  
fill ~69 ~16 ~14 ~71 ~16 ~14 stained_hardened_clay 7 
setblock ~69 ~16 ~31 stained_hardened_clay 15  
fill ~69 ~16 ~39 ~69 ~17 ~39 concrete 15  
fill ~70 ~16 ~33 ~70 ~17 ~33 concrete 15  
fill ~70 ~16 ~41 ~70 ~18 ~41 concrete 15  
fill ~70 ~16 ~60 ~70 ~17 ~60 concrete 15  
fill ~71 ~16 ~55 ~71 ~18 ~55 concrete 15  
fill ~71 ~16 ~59 ~71 ~17 ~59 concrete 15  
fill ~72 ~16 ~15 ~75 ~16 ~15 stained_hardened_clay 7 
setblock ~72 ~16 ~36 concrete 15  
fill ~72 ~16 ~44 ~72 ~17 ~44 concrete 15 
setblock ~73 ~16 ~38 stained_hardened_clay 15  
fill ~73 ~16 ~46 ~73 ~17 ~46 stained_hardened_clay 15  
fill ~73 ~16 ~58 ~73 ~17 ~58 stained_hardened_clay 15 
setblock ~74 ~16 ~39 concrete 15  
fill ~74 ~16 ~48 ~74 ~18 ~48 concrete 15  
fill ~74 ~16 ~57 ~74 ~17 ~57 stained_hardened_clay 15  
fill ~75 ~16 ~41 ~75 ~17 ~41 stained_hardened_clay 15 
setblock ~75 ~16 ~52 stained_hardened_clay 15 
setblock ~75 ~16 ~56 stained_hardened_clay 15  
fill ~76 ~16 ~16 ~76 ~17 ~16 concrete 7  
fill ~76 ~16 ~51 ~76 ~17 ~51 concrete 15  
fill ~76 ~16 ~52 ~76 ~16 ~50 concrete 15  
fill ~77 ~16 ~16 ~78 ~16 ~16 stained_hardened_clay 7  
fill ~77 ~16 ~44 ~77 ~17 ~44 concrete 15  
fill ~78 ~16 ~46 ~78 ~17 ~46 stained_hardened_clay 15  
fill ~78 ~16 ~54 ~78 ~17 ~54 stained_hardened_clay 15  
fill ~79 ~16 ~16 ~79 ~15 ~16 stained_hardened_clay 15 
setblock ~79 ~16 ~47 stained_hardened_clay 15  
fill ~79 ~16 ~53 ~79 ~18 ~53 stained_hardened_clay 15  
fill ~80 ~16 ~17 ~82 ~16 ~17 stained_hardened_clay 15 
setblock ~80 ~16 ~49 concrete 15  
fill ~81 ~16 ~50 ~81 ~16 ~51 concrete 15 
setblock ~81 ~16 ~52 stained_hardened_clay 15  
fill ~3 ~17 ~67 ~4 ~17 ~67 stained_hardened_clay 7  
fill ~12 ~17 ~18 ~13 ~17 ~18 stained_hardened_clay 15 
setblock ~13 ~17 ~51 concrete 15  
fill ~14 ~17 ~17 ~16 ~17 ~17 stained_hardened_clay 15 
setblock ~14 ~17 ~50 concrete 15  
fill ~14 ~17 ~52 ~14 ~18 ~52 stained_hardened_clay 15 
setblock ~15 ~17 ~48 stained_hardened_clay 15  
fill ~15 ~17 ~49 ~15 ~18 ~49 concrete 15  
fill ~16 ~17 ~47 ~16 ~18 ~47 stained_hardened_clay 15  
fill ~17 ~17 ~17 ~17 ~18 ~17 stained_hardened_clay 7  
fill ~17 ~17 ~45 ~17 ~18 ~45 stained_hardened_clay 15 
setblock ~17 ~17 ~54 concrete 15 
setblock ~18 ~17 ~43 concrete 15  
fill ~18 ~17 ~55 ~18 ~18 ~55 concrete 15 
setblock ~19 ~17 ~16 concrete 7 
setblock ~19 ~17 ~41 stained_hardened_clay 15  
fill ~19 ~17 ~42 ~19 ~18 ~42 concrete 15  
fill ~19 ~17 ~50 ~19 ~18 ~50 concrete 15  
fill ~19 ~17 ~52 ~19 ~18 ~52 concrete 15  
fill ~20 ~17 ~16 ~21 ~17 ~16 stained_hardened_clay 7 
setblock ~20 ~17 ~40 stained_hardened_clay 15  
fill ~21 ~17 ~38 ~21 ~17 ~39 concrete 15  
fill ~21 ~17 ~47 ~21 ~18 ~47 concrete 15  
fill ~22 ~17 ~15 ~25 ~17 ~15 stained_hardened_clay 7 
setblock ~22 ~17 ~36 stained_hardened_clay 15  
fill ~22 ~17 ~37 ~22 ~18 ~37 concrete 15  
fill ~22 ~17 ~45 ~22 ~18 ~45 stained_hardened_clay 15  
fill ~22 ~17 ~54 ~22 ~19 ~54 concrete 15  
fill ~22 ~17 ~58 ~22 ~18 ~58 stained_hardened_clay 15 
setblock ~23 ~17 ~35 concrete 15  
fill ~23 ~17 ~43 ~23 ~18 ~43 concrete 15  
fill ~24 ~17 ~34 ~24 ~18 ~34 concrete 15  
fill ~25 ~17 ~32 ~25 ~18 ~32 stained_hardened_clay 15  
fill ~25 ~17 ~40 ~25 ~18 ~40 concrete 15  
fill ~25 ~17 ~56 ~25 ~19 ~56 concrete 15 
setblock ~26 ~17 ~14 stained_hardened_clay 7  
fill ~26 ~17 ~31 ~26 ~18 ~31 stained_hardened_clay 15  
fill ~26 ~17 ~38 ~26 ~18 ~38 concrete 15  
fill ~26 ~17 ~57 ~26 ~19 ~57 concrete 15  
fill ~26 ~17 ~61 ~26 ~18 ~61 stained_hardened_clay 15  
fill ~27 ~17 ~14 ~29 ~17 ~14 concrete 7  
fill ~27 ~17 ~28 ~28 ~17 ~28 stained_hardened_clay 15  
fill ~27 ~17 ~29 ~27 ~18 ~29 stained_hardened_clay 15  
fill ~27 ~17 ~62 ~27 ~18 ~62 stained_hardened_clay 15  
fill ~28 ~17 ~35 ~28 ~18 ~35 concrete 15  
fill ~28 ~17 ~63 ~28 ~18 ~63 stained_hardened_clay 15  
fill ~29 ~17 ~27 ~29 ~16 ~27 stained_hardened_clay 15  
fill ~30 ~17 ~13 ~32 ~17 ~13 stained_hardened_clay 7 
setblock ~30 ~17 ~27 concrete 15  
fill ~30 ~17 ~31 ~30 ~17 ~32 concrete 15  
fill ~30 ~17 ~60 ~30 ~19 ~60 concrete 15  
fill ~30 ~17 ~64 ~30 ~19 ~64 stained_hardened_clay 15  
fill ~31 ~17 ~27 ~31 ~18 ~27 stained_hardened_clay 15  
fill ~31 ~17 ~30 ~33 ~17 ~30 concrete 15  
fill ~31 ~17 ~61 ~31 ~19 ~61 concrete 15  
fill ~32 ~17 ~26 ~33 ~17 ~26 concrete 15  
fill ~33 ~17 ~13 ~34 ~17 ~13 concrete 7  
fill ~33 ~17 ~65 ~33 ~19 ~65 stained_hardened_clay 15 
setblock ~34 ~17 ~26 stained_hardened_clay 15  
fill ~34 ~17 ~29 ~37 ~17 ~29 concrete 15  
fill ~35 ~17 ~12 ~39 ~17 ~12 stained_hardened_clay 7 
setblock ~35 ~17 ~26 concrete 15 
setblock ~37 ~17 ~25 concrete 15  
fill ~37 ~17 ~63 ~37 ~21 ~63 concrete 15  
fill ~37 ~17 ~66 ~37 ~20 ~66 stained_hardened_clay 15  
fill ~38 ~17 ~25 ~39 ~17 ~25 stained_hardened_clay 15  
fill ~38 ~17 ~28 ~41 ~17 ~28 concrete 15  
fill ~38 ~17 ~67 ~40 ~17 ~67 stained_hardened_clay 15 
setblock ~40 ~17 ~11 concrete 7  
fill ~40 ~17 ~24 ~42 ~17 ~24 stained_hardened_clay 15  
fill ~40 ~17 ~64 ~40 ~20 ~64 stained_hardened_clay 15  
fill ~41 ~17 ~65 ~42 ~17 ~65 stained_hardened_clay 15  
fill ~41 ~17 ~68 ~43 ~17 ~68 stained_hardened_clay 15  
fill ~42 ~17 ~11 ~44 ~17 ~11 concrete 7  
fill ~42 ~17 ~27 ~44 ~17 ~27 concrete 15  
fill ~43 ~17 ~23 ~46 ~17 ~23 stained_hardened_clay 15  
fill ~44 ~17 ~65 ~44 ~21 ~65 concrete 15  
fill ~45 ~17 ~10 ~49 ~17 ~10 concrete 7  
fill ~45 ~17 ~26 ~46 ~17 ~26 concrete 15 
setblock ~47 ~17 ~22 stained_hardened_clay 15  
fill ~47 ~17 ~26 ~47 ~18 ~26 stained_hardened_clay 15  
fill ~47 ~17 ~66 ~47 ~20 ~66 concrete 15  
fill ~47 ~17 ~69 ~47 ~20 ~69 concrete 15  
fill ~48 ~17 ~23 ~51 ~17 ~23 stained_hardened_clay 15  
fill ~48 ~17 ~26 ~49 ~17 ~26 concrete 15  
fill ~50 ~17 ~11 ~54 ~17 ~11 concrete 7  
fill ~50 ~17 ~27 ~52 ~17 ~27 concrete 15  
fill ~50 ~17 ~65 ~50 ~21 ~65 concrete 15  
fill ~52 ~17 ~24 ~54 ~17 ~24 stained_hardened_clay 15  
fill ~52 ~17 ~65 ~53 ~17 ~65 stained_hardened_clay 15  
fill ~53 ~17 ~28 ~56 ~17 ~28 concrete 15  
fill ~54 ~17 ~64 ~54 ~20 ~64 stained_hardened_clay 15  
fill ~54 ~17 ~67 ~54 ~19 ~67 stained_hardened_clay 15  
fill ~55 ~17 ~12 ~59 ~17 ~12 stained_hardened_clay 7  
fill ~55 ~17 ~25 ~56 ~17 ~25 stained_hardened_clay 15 
setblock ~57 ~17 ~25 concrete 15  
fill ~57 ~17 ~29 ~60 ~17 ~29 concrete 15  
fill ~57 ~17 ~63 ~57 ~21 ~63 concrete 15  
fill ~57 ~17 ~66 ~57 ~20 ~66 stained_hardened_clay 15  
fill ~59 ~17 ~26 ~62 ~17 ~26 concrete 15  
fill ~60 ~17 ~13 ~61 ~17 ~13 concrete 7  
fill ~61 ~17 ~30 ~63 ~17 ~30 concrete 15  
fill ~61 ~17 ~65 ~61 ~19 ~65 stained_hardened_clay 15  
fill ~62 ~17 ~13 ~64 ~17 ~13 stained_hardened_clay 7  
fill ~63 ~17 ~27 ~63 ~18 ~27 stained_hardened_clay 15  
fill ~63 ~17 ~61 ~63 ~19 ~61 concrete 15 
setblock ~64 ~17 ~27 concrete 15  
fill ~64 ~17 ~31 ~64 ~17 ~32 concrete 15  
fill ~64 ~17 ~60 ~64 ~20 ~60 concrete 15  
fill ~64 ~17 ~64 ~64 ~19 ~64 stained_hardened_clay 15  
fill ~65 ~17 ~14 ~67 ~17 ~14 concrete 7 
setblock ~65 ~17 ~27 stained_hardened_clay 15  
fill ~66 ~17 ~28 ~67 ~17 ~28 stained_hardened_clay 15  
fill ~66 ~17 ~35 ~66 ~18 ~35 concrete 15  
fill ~66 ~17 ~63 ~66 ~18 ~63 stained_hardened_clay 15  
fill ~67 ~17 ~29 ~67 ~18 ~29 stained_hardened_clay 15  
fill ~67 ~17 ~62 ~67 ~18 ~62 stained_hardened_clay 15 
setblock ~68 ~17 ~14 stained_hardened_clay 7  
fill ~68 ~17 ~31 ~68 ~18 ~31 stained_hardened_clay 15  
fill ~68 ~17 ~38 ~68 ~18 ~38 concrete 15  
fill ~68 ~17 ~57 ~68 ~19 ~57 concrete 15  
fill ~68 ~17 ~61 ~68 ~18 ~61 stained_hardened_clay 15  
fill ~69 ~17 ~15 ~72 ~17 ~15 stained_hardened_clay 7  
fill ~69 ~17 ~32 ~69 ~18 ~32 stained_hardened_clay 15  
fill ~69 ~17 ~40 ~69 ~18 ~40 concrete 15  
fill ~69 ~17 ~56 ~69 ~19 ~56 concrete 15  
fill ~70 ~17 ~34 ~70 ~18 ~34 concrete 15 
setblock ~71 ~17 ~35 concrete 15  
fill ~71 ~17 ~43 ~71 ~18 ~43 concrete 15 
setblock ~72 ~17 ~36 stained_hardened_clay 15  
fill ~72 ~17 ~37 ~72 ~18 ~37 concrete 15  
fill ~72 ~17 ~45 ~72 ~18 ~45 stained_hardened_clay 15  
fill ~72 ~17 ~54 ~72 ~19 ~54 concrete 15  
fill ~72 ~17 ~58 ~72 ~18 ~58 stained_hardened_clay 15  
fill ~73 ~17 ~16 ~74 ~17 ~16 stained_hardened_clay 7  
fill ~73 ~17 ~38 ~73 ~17 ~39 concrete 15  
fill ~73 ~17 ~47 ~73 ~18 ~47 concrete 15  
fill ~74 ~17 ~40 ~74 ~18 ~40 stained_hardened_clay 15 
setblock ~75 ~17 ~16 concrete 7  
fill ~75 ~17 ~42 ~75 ~18 ~42 concrete 15  
fill ~75 ~17 ~50 ~75 ~18 ~50 concrete 15  
fill ~75 ~17 ~52 ~75 ~18 ~52 concrete 15  
fill ~75 ~17 ~56 ~75 ~18 ~56 concrete 15 
setblock ~76 ~17 ~43 concrete 15  
fill ~76 ~17 ~55 ~76 ~18 ~55 concrete 15  
fill ~77 ~17 ~17 ~77 ~18 ~17 stained_hardened_clay 7  
fill ~77 ~17 ~45 ~77 ~18 ~45 stained_hardened_clay 15 
setblock ~77 ~17 ~54 concrete 15  
fill ~78 ~17 ~17 ~80 ~17 ~17 stained_hardened_clay 15  
fill ~78 ~17 ~47 ~78 ~18 ~47 stained_hardened_clay 15 
setblock ~79 ~17 ~48 stained_hardened_clay 15  
fill ~79 ~17 ~49 ~79 ~18 ~49 concrete 15 
setblock ~80 ~17 ~50 concrete 15  
fill ~80 ~17 ~52 ~80 ~18 ~52 stained_hardened_clay 15  
fill ~81 ~17 ~18 ~82 ~17 ~18 stained_hardened_clay 15 
setblock ~81 ~17 ~51 concrete 15 
setblock ~3 ~18 ~62 stained_hardened_clay 7  
fill ~3 ~18 ~67 ~3 ~19 ~67 stained_hardened_clay 7 
setblock ~4 ~18 ~63 stained_hardened_clay 12  
fill ~4 ~18 ~68 ~4 ~19 ~68 stained_hardened_clay 7 
setblock ~5 ~18 ~64 stained_hardened_clay 7  
fill ~5 ~18 ~66 ~5 ~18 ~67 stained_hardened_clay 12 
setblock ~6 ~18 ~64 stained_hardened_clay 9  
fill ~6 ~18 ~65 ~6 ~19 ~65 stained_hardened_clay 13  
fill ~13 ~18 ~18 ~15 ~18 ~18 stained_hardened_clay 15 
setblock ~14 ~18 ~51 concrete 15 
setblock ~15 ~18 ~50 stained_hardened_clay 15 
setblock ~16 ~18 ~17 stained_hardened_clay 15  
fill ~16 ~18 ~48 ~16 ~19 ~48 stained_hardened_clay 15  
fill ~16 ~18 ~53 ~16 ~19 ~53 stained_hardened_clay 15  
fill ~17 ~18 ~46 ~17 ~19 ~46 stained_hardened_clay 15  
fill ~17 ~18 ~54 ~17 ~19 ~54 stained_hardened_clay 15 
setblock ~18 ~18 ~17 stained_hardened_clay 7 
setblock ~18 ~18 ~44 concrete 15  
fill ~19 ~18 ~17 ~19 ~19 ~17 concrete 7  
fill ~19 ~18 ~43 ~19 ~19 ~43 concrete 15  
fill ~19 ~18 ~51 ~19 ~19 ~51 concrete 15 
setblock ~19 ~18 ~56 concrete 15  
fill ~20 ~18 ~16 ~23 ~18 ~16 stained_hardened_clay 7  
fill ~20 ~18 ~41 ~20 ~19 ~41 stained_hardened_clay 15  
fill ~20 ~18 ~49 ~20 ~19 ~49 concrete 15 
setblock ~20 ~18 ~53 stained_hardened_clay 15  
fill ~20 ~18 ~56 ~20 ~19 ~56 stained_hardened_clay 15 
setblock ~21 ~18 ~39 concrete 15 
setblock ~21 ~18 ~40 stained_hardened_clay 15  
fill ~21 ~18 ~53 ~21 ~19 ~53 concrete 15  
fill ~21 ~18 ~57 ~21 ~19 ~57 stained_hardened_clay 15 
setblock ~22 ~18 ~38 concrete 15 
setblock ~22 ~18 ~46 concrete 15 
setblock ~23 ~18 ~36 stained_hardened_clay 15  
fill ~23 ~18 ~44 ~23 ~19 ~44 concrete 15 
setblock ~23 ~18 ~59 stained_hardened_clay 15  
fill ~24 ~18 ~15 ~26 ~18 ~15 stained_hardened_clay 7  
fill ~24 ~18 ~35 ~24 ~19 ~35 stained_hardened_clay 15  
fill ~24 ~18 ~42 ~24 ~19 ~42 concrete 15  
fill ~24 ~18 ~55 ~24 ~20 ~55 concrete 15 
setblock ~24 ~18 ~59 concrete 15  
fill ~25 ~18 ~33 ~25 ~19 ~33 concrete 15  
fill ~25 ~18 ~60 ~25 ~19 ~60 stained_hardened_clay 15  
fill ~26 ~18 ~39 ~26 ~19 ~39 concrete 15  
fill ~27 ~18 ~15 ~27 ~19 ~15 stained_hardened_clay 11  
fill ~27 ~18 ~30 ~27 ~19 ~30 stained_hardened_clay 15  
fill ~27 ~18 ~37 ~27 ~19 ~37 concrete 15  
fill ~28 ~18 ~14 ~29 ~18 ~14 stained_hardened_clay 11  
fill ~28 ~18 ~28 ~30 ~18 ~28 stained_hardened_clay 15  
fill ~28 ~18 ~36 ~28 ~20 ~36 concrete 15
fill ~28 ~18 ~58 ~28 ~20 ~58 concrete 15  
fill ~29 ~18 ~34 ~29 ~19 ~34 concrete 15  
fill ~29 ~18 ~59 ~29 ~20 ~59 concrete 15  
fill ~30 ~18 ~14 ~31 ~18 ~14 stained_hardened_clay 7  
fill ~30 ~18 ~32 ~30 ~19 ~32 concrete 15  
fill ~31 ~18 ~31 ~31 ~19 ~31 concrete 15  
fill ~31 ~18 ~64 ~31 ~20 ~64 stained_hardened_clay 15 
setblock ~32 ~18 ~14 concrete 7 
setblock ~32 ~18 ~27 stained_hardened_clay 15  
fill ~32 ~18 ~30 ~35 ~18 ~30 concrete 15  
fill ~33 ~18 ~13 ~35 ~18 ~13 concrete 7 
setblock ~33 ~18 ~27 concrete 15 
setblock ~34 ~18 ~26 concrete 15  
fill ~34 ~18 ~62 ~34 ~21 ~62 concrete 15  
fill ~34 ~18 ~65 ~34 ~20 ~65 stained_hardened_clay 15 
setblock ~35 ~18 ~26 stained_hardened_clay 15  
fill ~36 ~18 ~13 ~37 ~18 ~13 stained_hardened_clay 7  
fill ~36 ~18 ~26 ~37 ~18 ~26 concrete 15  
fill ~36 ~18 ~29 ~38 ~18 ~29 concrete 15  
fill ~38 ~18 ~12 ~40 ~18 ~12 stained_hardened_clay 7  
fill ~38 ~18 ~25 ~41 ~18 ~25 stained_hardened_clay 15  
fill ~38 ~18 ~66 ~38 ~21 ~66 stained_hardened_clay 15  
fill ~39 ~18 ~28 ~42 ~18 ~28 concrete 15  
fill ~39 ~18 ~67 ~41 ~18 ~67 stained_hardened_clay 15  
fill ~41 ~18 ~12 ~41 ~19 ~12 concrete 7  
fill ~41 ~18 ~64 ~41 ~21 ~64 stained_hardened_clay 15  
fill ~42 ~18 ~11 ~46 ~18 ~11 concrete 7  
fill ~42 ~18 ~24 ~44 ~18 ~24 stained_hardened_clay 15 
setblock ~42 ~18 ~65 stained_hardened_clay 15  
fill ~42 ~18 ~68 ~43 ~18 ~68 stained_hardened_clay 15  
fill ~43 ~18 ~27 ~45 ~18 ~27 concrete 15  
fill ~44 ~18 ~68 ~44 ~20 ~68 concrete 15  
fill ~45 ~18 ~23 ~49 ~18 ~23 stained_hardened_clay 15 
setblock ~46 ~18 ~26 concrete 15 
setblock ~47 ~18 ~10 concrete 7  
fill ~48 ~18 ~11 ~52 ~18 ~11 concrete 7  
fill ~48 ~18 ~26 ~48 ~16 ~26 concrete 15  
fill ~49 ~18 ~27 ~51 ~18 ~27 concrete 15  
fill ~50 ~18 ~24 ~52 ~18 ~24 stained_hardened_clay 15  
fill ~50 ~18 ~68 ~50 ~20 ~68 concrete 15  
fill ~52 ~18 ~28 ~55 ~18 ~28 concrete 15  
fill ~52 ~18 ~65 ~52 ~15 ~65 stained_hardened_clay 15  
fill ~53 ~18 ~12 ~54 ~18 ~12 concrete 7  
fill ~53 ~18 ~25 ~56 ~18 ~25 stained_hardened_clay 15  
fill ~53 ~18 ~64 ~53 ~21 ~64 stained_hardened_clay 15  
fill ~53 ~18 ~67 ~53 ~20 ~67 stained_hardened_clay 15  
fill ~55 ~18 ~12 ~56 ~18 ~12 stained_hardened_clay 7  
fill ~56 ~18 ~29 ~58 ~18 ~29 concrete 15  
fill ~56 ~18 ~66 ~56 ~21 ~66 stained_hardened_clay 15  
fill ~57 ~18 ~13 ~58 ~18 ~13 stained_hardened_clay 7  
fill ~57 ~18 ~26 ~58 ~18 ~26 concrete 15  
fill ~59 ~18 ~13 ~61 ~18 ~13 concrete 7 
setblock ~59 ~18 ~26 stained_hardened_clay 15  
fill ~59 ~18 ~30 ~62 ~18 ~30 concrete 15 
setblock ~60 ~18 ~26 concrete 15  
fill ~60 ~18 ~62 ~60 ~20 ~62 concrete 15  
fill ~60 ~18 ~65 ~60 ~20 ~65 stained_hardened_clay 15 
setblock ~61 ~18 ~27 concrete 15  
fill ~62 ~18 ~14 ~62 ~19 ~14 concrete 7 
setblock ~62 ~18 ~27 stained_hardened_clay 15  
fill ~63 ~18 ~14 ~64 ~18 ~14 stained_hardened_clay 7  
fill ~63 ~18 ~31 ~63 ~19 ~31 concrete 15  
fill ~63 ~18 ~64 ~63 ~20 ~64 stained_hardened_clay 15  
fill ~64 ~18 ~28 ~66 ~18 ~28 stained_hardened_clay 15  
fill ~64 ~18 ~32 ~64 ~19 ~32 concrete 15  
fill ~65 ~18 ~14 ~66 ~18 ~14 stained_hardened_clay 11  
fill ~65 ~18 ~34 ~65 ~19 ~34 concrete 15  
fill ~65 ~18 ~59 ~65 ~20 ~59 concrete 15  
fill ~66 ~18 ~36 ~66 ~20 ~36 concrete 15  
fill ~66 ~18 ~58 ~66 ~20 ~58 concrete 15  
fill ~67 ~18 ~15 ~67 ~19 ~15 stained_hardened_clay 11  
fill ~67 ~18 ~30 ~67 ~19 ~30 stained_hardened_clay 15  
fill ~67 ~18 ~37 ~67 ~19 ~37 concrete 15  
fill ~68 ~18 ~15 ~70 ~18 ~15 stained_hardened_clay 7  
fill ~68 ~18 ~39 ~68 ~19 ~39 concrete 15  
fill ~69 ~18 ~33 ~69 ~19 ~33 concrete 15  
fill ~69 ~18 ~60 ~69 ~19 ~60 stained_hardened_clay 15  
fill ~70 ~18 ~35 ~70 ~19 ~35 stained_hardened_clay 15  
fill ~70 ~18 ~42 ~70 ~19 ~42 concrete 15  
fill ~70 ~18 ~55 ~70 ~20 ~55 concrete 15 
setblock ~70 ~18 ~59 concrete 15  
fill ~71 ~18 ~16 ~74 ~18 ~16 stained_hardened_clay 7 
setblock ~71 ~18 ~36 stained_hardened_clay 15  
fill ~71 ~18 ~44 ~71 ~19 ~44 concrete 15 
setblock ~71 ~18 ~59 stained_hardened_clay 15 
setblock ~72 ~18 ~38 concrete 15 
setblock ~72 ~18 ~46 concrete 15 
setblock ~73 ~18 ~39 concrete 15  
fill ~73 ~18 ~53 ~73 ~19 ~53 concrete 15  
fill ~73 ~18 ~57 ~73 ~19 ~57 stained_hardened_clay 15  
fill ~74 ~18 ~41 ~74 ~19 ~41 stained_hardened_clay 15  
fill ~74 ~18 ~49 ~74 ~19 ~49 concrete 15 
setblock ~74 ~18 ~53 stained_hardened_clay 15  
fill ~74 ~18 ~56 ~74 ~19 ~56 stained_hardened_clay 15  
fill ~75 ~18 ~17 ~75 ~19 ~17 concrete 7  
fill ~75 ~18 ~43 ~75 ~19 ~43 concrete 15  
fill ~75 ~18 ~51 ~75 ~19 ~51 concrete 15 
setblock ~76 ~18 ~17 stained_hardened_clay 7 
setblock ~76 ~18 ~44 concrete 15  
fill ~77 ~18 ~46 ~77 ~19 ~46 stained_hardened_clay 15  
fill ~77 ~18 ~54 ~77 ~19 ~54 stained_hardened_clay 15  
fill ~78 ~18 ~17 ~78 ~17 ~17 stained_hardened_clay 15  
